File: data/Raman/poly_smoothed/Mb_00_13_19_1x_45s_532 nm_x100_100%_600 gr_mm_01.txt
#Acq. time (s)=	45
#Accumulations=	2
#Range (cm-¹)=	200...3150
#Windows=	2
#Auto scanning=	Off
#Autofocus=	Off
#Macrospot=	Off
#AutoExposure=	Off
#Spike filter=	Multiple accum.
#Delay time (s)=	0
#Binning=	1
#Readout mode=	Signal
#DeNoise=	Off
#ICS correction=	On
#Dark correction=	Off
#Inst. Process=	Off
#Detector Gain=	Best Dynamic Range
#Detector ADC=	20 kHz
#Detector temperature (°C)=	-69.85
#Instrument=	LabRAM HR Evol
#Detector=	Synapse
#Objective=	x100
#Grating=	600 gr/mm
#ND Filter=	100%
#Laser (nm)=	532
#Hole=	100.021
#Range=	Auto
#Laser Pol.=	No
#Raman. Pol.=	No
#Laser Pol. (°)=	-0.0007625
#Raman Pol. (°)=	89.9995
#Collection=	Microscope
#StageXY=	Marzhauser
#StageZ=	Marzhauser
#X (µm)=	-964.4
#Y (µm)=	-2827.1
#Z (µm)=	528.2
#Full time(mm:ss)=	3:18
#Project=
#Sample=
#Site=
#Title=	Mb_00_13_19_2x_45s_532 nm_x100_100%_600 gr_mm
#Remark=
#Date=	06.07.2022 11:05
#Acquired=	06.07.2022 11:05:31
#Base:Fit=	10.08.2022 10:16:56
#Base:Sub=	10.08.2022 10:17:24
#Filter:Polynom=	16.08.2022 10:36:38
#AxisType[0]=Intens
#AxisUnit[0]=Cnt
#AxisType[1]=Spectr
#AxisUnit[1]=1/cm
200.398	24.8542
204.027	9.50681
207.657	-0.472707
211.283	-8.04753
214.909	-8.54626
218.533	3.89956
222.157	23.1288
225.777	47.7714
229.396	71.6963
233.016	95.2583
236.632	115.934
240.247	135.499
243.86	151.296
247.474	164.304
251.085	178.672
254.694	186.962
258.301	192.911
261.908	196.454
265.513	192.419
269.116	186.998
272.718	175.169
276.319	160.441
279.918	143.535
283.516	123.73
287.113	101.598
290.708	84.6036
294.302	68.056
297.894	51.0684
301.485	41.2961
305.073	37.6488
308.661	35.7376
312.247	33.1957
315.833	31.4172
319.415	29.2073
322.997	26.9851
326.579	27.2851
330.156	26.4292
333.735	24.5474
337.31	20.2512
340.885	18.1734
344.458	14.7952
348.03	12.9971
351.6	11.5407
355.17	8.3547
358.737	7.46708
362.304	8.26987
365.868	13.0254
369.431	24.5016
372.994	33.322
376.554	43.3705
380.112	58.2092
383.669	79.3741
387.225	100.665
390.781	126.602
394.334	149.327
397.885	167.787
401.436	181.044
404.984	193.997
408.532	201.344
412.078	204.041
415.623	204.973
419.166	200.932
422.708	191.349
426.248	176.835
429.788	160.422
433.326	141.056
436.86	120.713
440.395	99.2438
443.929	80.8709
447.461	63.9513
450.99	49.289
454.52	39.9415
458.048	26.9873
461.573	16.3489
465.099	14.852
468.623	16.9068
472.144	20.6038
475.666	23.8609
479.184	27.7849
482.703	29.6865
486.218	31.4507
489.734	34.1046
493.247	37.5787
496.759	43.141
500.271	45.3967
503.779	48.5815
507.287	51.4287
510.795	51.6967
514.299	53.2892
517.803	57.1673
521.305	60.3662
524.805	64.0369
528.307	68.9718
531.805	69.539
535.301	70.1532
538.797	70.6846
542.291	67.8787
545.783	65.3647
549.275	61.678
552.765	55.8183
556.253	49.3795
559.738	46.2761
563.224	41.5107
566.709	36.3023
570.192	33.0841
573.674	29.0655
577.153	23.8196
580.632	19.9585
584.11	16.4586
587.587	12.4172
591.06	13.6653
594.534	10.962
598.005	9.06342
601.476	11.9662
604.944	15.2646
608.413	17.5997
611.878	20.2749
615.344	22.1655
618.807	23.6153
622.27	28.5528
625.73	30.6366
629.189	35.2295
632.648	39.8916
636.105	43.8286
639.559	48.4941
643.013	52.5755
646.467	54.5647
649.918	56.3447
653.368	52.9745
656.816	49.3705
660.263	47.6554
663.708	43.0836
667.153	38.8216
670.596	35.7907
674.037	30.8318
677.478	28.7977
680.917	23.9889
684.355	18.5922
687.791	17.0336
691.224	11.9353
694.658	7.80121
698.091	4.85001
701.522	1.35911
704.95	-0.0403695
708.379	1.72147
711.806	4.27943
715.23	5.27747
718.655	5.85569
722.078	8.55261
725.498	9.03989
728.919	9.80248
732.337	7.22816
735.755	7.88574
739.17	10.3298
742.584	13.6758
745.998	16.7673
749.409	18.8815
752.819	24.6278
756.23	28.8125
759.637	34.2957
763.043	38.5173
766.448	40.1334
769.853	42.9559
773.255	44.7217
776.656	46.1517
780.056	45.8029
783.454	48.7062
786.851	48.5871
790.247	51.6863
793.641	54.2195
797.034	54.4986
800.426	53.4827
803.817	53.1716
807.206	51.2779
810.592	50.2669
813.979	48.5631
817.364	48.605
820.748	48.3618
824.129	49.5712
827.511	51.2424
830.891	53.738
834.269	53.4609
837.646	54.1454
841.023	51.766
844.396	49.1206
847.77	43.9535
851.141	39.7803
854.513	37.9125
857.881	34.3449
861.248	32.5278
864.616	30.5248
867.98	27.8071
871.343	23.2393
874.707	18.4024
878.068	15.8629
881.428	14.1213
884.786	9.94016
888.143	8.12792
891.498	8.48116
894.855	10.5137
898.208	11.3074
901.56	10.0237
904.91	11.1269
908.26	11.9833
911.608	12.2666
914.955	12.6431
918.298	13.549
921.643	14.2383
924.986	13.7693
928.328	15.3462
931.668	16.5582
935.006	16.9675
938.344	17.9206
941.681	14.9753
945.014	16.4021
948.349	16.2983
951.682	13.7328
955.012	9.21329
958.343	7.82826
961.67	7.66263
964.998	12.1753
968.323	20.0565
971.649	34.707
974.971	51.7517
978.293	68.412
981.615	75.2688
984.933	83.3793
988.251	98.0402
991.567	109.061
994.884	122.609
998.198	131.432
1001.51	140.283
1004.82	140.589
1008.13	139.082
1011.44	135.253
1014.75	134.853
1018.06	138.241
1021.36	146.104
1024.66	159.753
1027.97	171.675
1031.27	178.322
1034.57	182.572
1037.87	183.7
1041.16	187.692
1044.46	191.998
1047.76	196.775
1051.05	196.861
1054.34	196.093
1057.63	189.6
1060.92	177.769
1064.21	163.749
1067.5	157.317
1070.78	144.027
1074.07	125.057
1077.35	104.542
1080.63	81.9941
1083.91	56.5058
1087.19	34.6707
1090.47	19.6625
1093.75	15.0017
1097.03	15.7832
1100.3	17.9167
1103.57	23.561
1106.84	25.5249
1110.11	24.913
1113.38	23.5831
1116.65	19.1316
1119.92	18.0694
1123.19	17.3059
1126.45	17.6056
1129.71	18.3398
1132.97	18.7849
1136.23	19.0935
1139.49	22.1381
1142.75	24.1882
1146.01	24.0115
1149.26	21.8962
1152.52	21.2181
1155.77	18.668
1159.02	16.8839
1162.27	14.848
1165.52	15.9995
1168.77	20.2415
1172.02	22.0267
1175.26	22.7473
1178.51	22.5285
1181.75	24.5458
1184.99	25.3042
1188.23	25.4618
1191.47	31.2733
1194.71	36.6286
1197.94	40.6978
1201.18	48.9021
1204.41	55.2212
1207.65	64.5908
1210.88	71.1009
1214.11	79.1295
1217.34	88.2963
1220.57	97.3979
1223.79	102.562
1227.02	108.041
1230.24	111.861
1233.47	113.763
1236.69	116.685
1239.91	120.303
1243.13	123.199
1246.34	122.439
1249.56	120.61
1252.78	116.898
1255.99	114.714
1259.2	112.435
1262.42	112.589
1265.63	111.665
1268.84	112.644
1272.04	114.512
1275.25	113.942
1278.46	115.237
1281.66	117.947
1284.86	119.697
1288.07	124.297
1291.27	124.769
1294.47	129.403
1297.66	132.902
1300.86	135.964
1304.06	138.669
1307.25	142.379
1310.44	143.579
1313.64	145.318
1316.83	149.366
1320.02	150.315
1323.2	151.366
1326.39	148.308
1329.58	148.363
1332.76	147.712
1335.95	148.109
1339.13	147.731
1342.31	146.69
1345.49	144.313
1348.67	140.614
1351.85	138.317
1355.02	133.556
1358.2	129.418
1361.37	124.329
1364.54	119.956
1367.71	113.981
1370.88	105.232
1374.05	91.523
1377.22	91.3903
1380.39	94.597
1383.55	94.6054
1386.72	96.6688
1389.88	96.6686
1393.04	96.9959
1396.2	100.91
1399.36	102.362
1402.52	106.378
1405.68	112.217
1408.83	120.424
1411.98	129.274
1415.14	141.798
1418.29	156.093
1421.44	171.28
1424.59	186.909
1427.74	203.169
1430.89	217.92
1434.03	228.27
1437.18	237.786
1440.32	245.024
1443.46	246.084
1446.6	245.803
1449.74	238.276
1452.88	238.357
1456.02	237.169
1459.16	225.946
1462.29	213.298
1465.43	198.719
1468.56	179.966
1471.69	162.411
1474.82	144.31
1477.95	127.842
1481.08	113.18
1484.2	97.2291
1487.33	86.9936
1490.46	78.4237
1493.58	70.5946
1496.7	65.6132
1499.82	64.1047
1502.94	59.8925
1506.06	57.3134
1509.18	55.7332
1512.29	53.3952
1515.41	54.0758
1518.52	53.7056
1521.63	55.014
1524.75	54.2517
1527.85	52.4423
1530.96	54.2221
1534.07	56.2558
1537.18	59.6175
1540.28	60.5748
1543.39	62.6427
1546.49	63.0299
1549.59	65.5938
1552.69	68.9987
1555.79	72.1381
1558.89	77.3225
1561.99	80.0823
1565.08	81.2651
1568.18	86.7438
1571.27	91.2709
1574.37	98.5287
1577.46	106.293
1580.55	111.407
1583.64	117.209
1586.73	122.43
1589.81	126.109
1592.9	131.116
1595.98	135.255
1599.06	135.306
1602.15	138.014
1605.23	139.149
1608.31	140.489
1611.39	139.904
1614.46	137.903
1617.54	137.551
1620.61	137.848
1623.69	139.925
1626.76	143.645
1629.83	146.845
1632.9	149.504
1635.97	155.119
1639.04	158.6
1642.11	164.851
1645.17	170.122
1648.24	175.023
1651.3	179.616
1654.36	179.792
1657.42	179.005
1660.48	179.561
1663.54	175.156
1666.6	171.083
1669.66	163.576
1672.71	155.703
1675.77	146.424
1678.82	135.319
1681.87	121.821
1684.92	107.159
1687.97	93.452
1691.02	81.0616
1694.07	71.0419
1697.11	59.8153
1700.16	49.7294
1703.2	40.7647
1706.25	33.9743
1709.29	29.0706
1712.33	23.4345
1715.37	17.4197
1718.41	14.7408
1721.44	11.7767
1724.48	10.2121
1727.51	10.5656
1730.55	10.486
1733.58	11.5215
1736.61	11.5354
1739.64	10.6006
1742.67	11.3123
1745.7	10.7637
1748.72	9.78091
1751.75	7.66508
1754.77	6.99294
1757.8	6.10109
1760.82	5.86122
1763.84	4.75638
1766.86	2.42131
1769.88	2.10638
1772.9	0.722769
1775.91	0.976652
1778.93	1.5371
1781.94	0.688621
1784.96	-0.660774
1787.97	0.672456
1790.98	1.53478
1793.99	4.33115
1797	5.38271
1800.01	7.51031
1803.01	7.62159
1806.02	8.34371
1809.02	8.15654
1812.02	9.23638
1815.02	8.15606
1818.03	9.14879
1821.02	9.22674
1824.02	9.48156
1827.02	10.7146
1830.02	11.4651
1833.01	11.023
1836.01	10.0409
1839	10.3884
1841.99	10.6391
1844.98	9.71837
1847.97	10.2199
1850.96	8.24849
1853.95	7.16393
1856.93	8.63666
1859.92	7.51666
1862.9	8.42543
1865.88	5.64539
1868.87	5.85976
1871.85	4.65874
1874.83	3.46096
1877.81	3.28707
1880.78	2.39666
1882.53	2.61619
1885.52	2.16896
1888.51	1.07976
1891.5	1.90793
1894.48	2.33908
1897.47	2.48039
1900.45	5.1449
1903.43	6.24514
1906.41	5.873
1909.39	7.70715
1912.37	8.99268
1915.35	8.57031
1918.33	9.24617
1921.3	9.22874
1924.28	9.89981
1927.25	12.1635
1930.22	8.52619
1933.19	8.24875
1936.16	6.10874
1939.13	6.15951
1942.1	7.53903
1945.07	7.91603
1948.03	8.177
1951	8.05521
1953.96	8.86261
1956.92	7.88482
1959.88	7.01965
1962.84	9.27059
1965.8	8.7855
1968.76	10.0494
1971.72	10.4455
1974.67	11.2342
1977.63	10.2959
1980.58	9.79705
1983.54	9.49516
1986.49	6.689
1989.44	4.98377
1992.39	5.45463
1995.33	4.88741
1998.28	5.46529
2001.23	3.9289
2004.17	5.63118
2007.12	5.24062
2010.06	6.62763
2013	6.82799
2015.94	7.65599
2018.88	6.87419
2021.82	7.76499
2024.76	8.36646
2027.69	8.23382
2030.63	7.1534
2033.56	8.13561
2036.5	9.23037
2039.43	9.69503
2042.36	8.47942
2045.29	8.22617
2048.22	7.77783
2051.15	5.48779
2054.07	5.62446
2057	5.05325
2059.92	6.33615
2062.85	8.08137
2065.77	7.70775
2068.69	8.2514
2071.61	6.86703
2074.53	8.38328
2077.45	7.98081
2080.37	7.5865
2083.28	7.51509
2086.2	8.27073
2089.11	7.70674
2092.02	8.62698
2094.94	8.23548
2097.85	7.78809
2100.76	7.59062
2103.66	6.17816
2106.57	6.43061
2109.48	6.31627
2112.38	3.91076
2115.29	3.90413
2118.19	3.20993
2121.09	3.82677
2123.99	3.32178
2126.89	5.11233
2129.79	4.52927
2132.69	4.96579
2135.59	2.92838
2138.48	3.63349
2141.38	5.02709
2144.27	4.99298
2147.17	6.06723
2150.06	6.49891
2152.95	7.83353
2155.84	10.007
2158.73	12.2102
2161.61	13.7663
2164.5	15.2264
2167.38	14.1265
2170.27	15.7766
2173.15	14.222
2176.03	15.6936
2178.91	16.3416
2181.8	15.0918
2184.67	15.3324
2187.55	14.3943
2190.43	14.1819
2193.3	13.3239
2196.18	12.1799
2199.05	9.49216
2201.93	8.26126
2204.8	8.08812
2207.67	7.21754
2210.54	5.97861
2213.41	4.26579
2216.27	4.76781
2219.14	5.10403
2222.01	8.22954
2224.87	9.78419
2227.73	11.353
2230.6	11.2606
2233.46	12.3732
2236.32	12.4374
2239.18	13.3642
2242.03	14.2217
2244.89	16.0948
2247.75	18.2037
2250.6	16.9465
2253.46	16.6301
2256.31	17.6295
2259.16	18.2634
2262.01	19.3472
2264.86	20.1677
2267.71	18.2497
2270.56	18.5292
2273.4	16.7647
2276.25	16.5587
2279.09	17.0268
2281.94	14.962
2284.78	15.7178
2287.62	15.9318
2290.46	13.0965
2293.3	11.704
2296.14	10.3917
2298.98	8.59546
2301.82	7.15501
2304.65	6.55681
2307.49	6.28054
2310.32	6.7648
2313.15	6.24299
2315.98	7.87446
2318.81	7.35349
2321.64	6.72397
2324.47	6.96295
2327.3	7.50361
2330.12	9.46825
2332.95	10.1812
2335.77	9.28976
2338.6	7.54327
2341.42	7.3717
2344.24	8.40573
2347.06	7.84503
2349.88	7.82198
2352.7	5.41345
2355.51	2.6315
2358.33	2.94345
2361.14	0.110218
2363.96	0.412256
2366.77	-0.16355
2369.58	0.17676
2372.39	0.891377
2375.2	0.155733
2378.01	0.764301
2380.82	1.77571
2383.63	1.86005
2386.43	2.64415
2389.24	3.03109
2392.04	2.17714
2394.84	4.45874
2397.65	7.04596
2400.45	6.57432
2403.25	6.11859
2406.05	6.884
2408.84	9.42736
2411.64	11.0387
2414.44	11.005
2417.23	12.6422
2420.02	12.1026
2422.82	11.3617
2425.61	11.0692
2428.4	10.0325
2431.19	10.3401
2433.98	9.8005
2436.77	7.95674
2439.55	6.25345
2442.34	4.61414
2445.12	4.49523
2447.91	4.94433
2450.69	3.31855
2453.47	2.20947
2456.25	2.96012
2459.03	2.88954
2461.81	4.0345
2464.59	4.22001
2467.36	2.57364
2470.14	3.25896
2472.92	4.5365
2475.69	6.4504
2478.46	8.33587
2481.23	9.54022
2484	9.07753
2486.77	9.21226
2489.54	8.25198
2492.31	8.85651
2495.08	8.78421
2497.84	8.67962
2500.61	7.65197
2503.37	6.13561
2506.13	4.4335
2508.9	5.31207
2511.66	5.36575
2514.42	6.46432
2517.18	6.53808
2519.93	6.39174
2522.69	7.66484
2525.45	9.44948
2528.2	10.3733
2530.95	10.3757
2533.71	10.3105
2536.46	11.8479
2539.21	13.5056
2541.96	13.4557
2544.71	13.2639
2547.46	13.4784
2550.2	14.0228
2552.95	13.1732
2555.7	12.5531
2558.44	14.21
2561.18	14.7215
2563.93	14.2275
2566.67	12.8165
2569.41	11.6332
2572.15	11.1606
2574.88	10.3618
2577.62	10.3203
2580.36	10.4455
2583.09	9.9841
2585.83	10.2079
2588.56	12.1574
2591.29	12.5719
2594.02	14.6371
2596.75	13.8588
2599.48	14.163
2602.21	14.9664
2604.94	14.9486
2607.67	13.7192
2610.39	13.0891
2613.12	12.683
2615.84	14.2719
2618.56	14.4614
2621.28	15.4899
2624.01	16.969
2626.72	17.5711
2629.44	17.8295
2632.16	18.0886
2634.88	17.4387
2637.59	18.9725
2640.31	18.8631
2643.02	18.9782
2645.74	18.4726
2648.45	19.6573
2651.16	19.3705
2653.87	19.5394
2656.58	20.9298
2659.29	19.6596
2661.99	18.5891
2664.7	18.6094
2667.41	18.8544
2670.11	16.2446
2672.81	14.2674
2675.51	12.3867
2678.22	12.0712
2680.92	12.4632
2683.62	12.2236
2686.31	12.3448
2689.01	12.1365
2691.71	13.5051
2694.4	14.1324
2697.1	16.4937
2699.79	18.7875
2702.49	20.122
2705.18	22.9258
2707.87	25.1139
2710.56	26.402
2713.25	26.9088
2715.94	29.6018
2718.62	29.5787
2721.31	29.9001
2723.99	29.6066
2726.68	29.5107
2729.36	28.6649
2732.04	28.3363
2734.73	26.2883
2737.41	23.5479
2740.08	22.5152
2742.76	19.4883
2745.44	17.5725
2748.12	15.1965
2750.79	12.5868
2753.47	10.4301
2756.14	9.21296
2758.81	7.81363
2761.49	8.47817
2764.16	7.20575
2766.83	5.52322
2769.5	4.84529
2772.16	3.02935
2774.83	2.26378
2777.5	1.36037
2780.16	-0.0128643
2782.83	-0.289406
2785.49	-0.639354
2788.15	-1.61827
2790.82	-0.874066
2793.48	-0.775055
2796.14	-1.27878
2798.79	-0.409355
2801.45	0.416024
2804.11	-0.619875
2806.76	-2.82501
2809.42	-5.24098
2812.07	-4.82102
2814.73	-0.650602
2817.38	6.15394
2820.03	16.2733
2822.68	27.8355
2825.33	42.4963
2827.98	58.9494
2830.63	75.8393
2833.27	93.336
2835.92	111.547
2838.56	132.935
2841.21	156.441
2843.85	180.263
2846.49	209.177
2849.13	241.029
2851.77	274.736
2854.41	308.219
2857.05	340.997
2859.69	371.406
2862.32	397.06
2864.96	420.845
2867.59	439.884
2870.23	453.524
2872.86	467.352
2875.49	479.711
2878.12	490.761
2880.75	499.987
2883.38	507.822
2886.01	514.15
2888.63	520.42
2891.26	526.429
2893.89	530.145
2896.51	536.553
2899.13	543.403
2901.76	555.702
2904.38	572.109
2907	593.099
2909.62	618.479
2912.24	648.885
2914.85	678.203
2917.47	703.935
2920.09	725.579
2922.7	743.259
2925.32	752.613
2927.93	758.801
2930.54	758.746
2933.15	752.257
2935.76	741.176
2938.37	725.205
2940.98	705.144
2943.59	679.818
2946.2	651.729
2948.8	623.596
2951.41	592.376
2954.01	562.333
2956.62	530.792
2959.22	500.593
2961.82	470.791
2964.42	443.027
2967.02	418.346
2969.62	395.051
2972.22	372.066
2974.81	351.012
2977.41	328.791
2980	304.848
2982.6	282.01
2985.19	257.082
2987.78	233.199
2990.38	208.14
2992.97	183.384
2995.56	160.835
2998.14	139.576
3000.73	120.695
3003.32	100.909
3005.91	82.7819
3008.49	67.2126
3011.07	53.4358
3013.66	43.402
3016.24	33.3406
3018.82	24.8925
3021.4	16.9727
3023.98	9.37526
3026.56	4.07278
3029.14	0.947761
3031.71	-1.29418
3034.29	-1.66835
3036.87	-0.346798
3039.44	2.30451
3042.01	5.03426
3044.59	7.5095
3047.16	10.201
3049.73	13.1786
3052.3	16.2934
3054.87	17.8807
3057.43	19.8236
3060	21.2668
3062.57	21.864
3065.13	21.8794
3067.7	21.8332
3070.26	21.0377
3072.82	19.3355
3075.39	16.6032
3077.95	12.6213
3080.51	9.85643
3083.07	6.38343
3085.63	3.77714
3088.18	3.34265
3090.74	2.56834
3093.29	2.54966
3095.85	5.33629
3098.4	7.5248
3100.95	10.3831
3103.51	13.6481
3106.06	16.6227
3108.61	20.5311
3111.16	26.0032
3113.71	30.9322
3116.25	35.7278
3118.8	40.3293
3121.35	45.6149
3123.89	50.8762
3126.44	56.5651
3128.98	61.5854
3131.52	65.9223
3134.06	69.0941
3136.6	72.2791
3139.14	76.3974
3141.68	82.1658
3144.22	86.5977
3146.76	92.2305
3149.29	96.3735