File: data/Raman/poly_smoothed/Mb_00_13_12_1x_45s_532 nm_x100_100%_600 gr_mm_01.txt
#Acq. time (s)=	45
#Accumulations=	2
#Range (cm-¹)=	200...3150
#Windows=	2
#Auto scanning=	Off
#Autofocus=	Off
#Macrospot=	Off
#AutoExposure=	Off
#Spike filter=	Multiple accum.
#Delay time (s)=	0
#Binning=	1
#Readout mode=	Signal
#DeNoise=	Off
#ICS correction=	On
#Dark correction=	Off
#Inst. Process=	Off
#Detector Gain=	Best Dynamic Range
#Detector ADC=	20 kHz
#Detector temperature (°C)=	-69.85
#Instrument=	LabRAM HR Evol
#Detector=	Synapse
#Objective=	x100
#Grating=	600 gr/mm
#ND Filter=	100%
#Laser (nm)=	532
#Hole=	100.021
#Range=	Auto
#Laser Pol.=	No
#Raman. Pol.=	No
#Laser Pol. (°)=	-0.0007625
#Raman Pol. (°)=	89.9995
#Collection=	Microscope
#StageXY=	Marzhauser
#StageZ=	Marzhauser
#X (µm)=	-1005.4
#Y (µm)=	-2957.1
#Z (µm)=	527.8
#Full time(mm:ss)=	3:18
#Project=
#Sample=
#Site=
#Title=	Mb_00_13_12_2x_45s_532 nm_x100_100%_600 gr_mm
#Remark=
#Date=	06.07.2022 10:29
#Acquired=	06.07.2022 10:29:28
#Base:Fit=	10.08.2022 10:16:56
#Base:Sub=	10.08.2022 10:17:24
#Filter:Polynom=	16.08.2022 10:36:38
#AxisType[0]=Intens
#AxisUnit[0]=Cnt
#AxisType[1]=Spectr
#AxisUnit[1]=1/cm
200.398	3.73352
204.027	0.513306
207.657	-2.01207
211.283	-2.89887
214.909	0.307393
218.533	5.78121
222.157	14.996
225.777	23.2893
229.396	35.6504
233.016	43.9803
236.632	50.0655
240.247	56.4333
243.86	60.7111
247.474	65.0687
251.085	70.3889
254.694	75.7324
258.301	78.7239
261.908	79.1284
265.513	78.2809
269.116	75.1721
272.718	69.5706
276.319	62.2255
279.918	55.3298
283.516	49.4993
287.113	42.2447
290.708	36.3407
294.302	30.5516
297.894	26.7207
301.485	24.5613
305.073	23.6627
308.661	20.9441
312.247	18.9369
315.833	17.121
319.415	15.9842
322.997	13.9946
326.579	14.0506
330.156	12.3981
333.735	12.0357
337.31	12.317
340.885	13.5165
344.458	11.9717
348.03	11.346
351.6	8.24058
355.17	5.73223
358.737	3.69809
362.304	3.94327
365.868	6.70464
369.431	11.7105
372.994	16.8291
376.554	22.8137
380.112	27.004
383.669	32.4774
387.225	38.8339
390.781	46.9701
394.334	53.2364
397.885	57.9083
401.436	63.755
404.984	67.6663
408.532	71.5817
412.078	73.8467
415.623	73.6027
419.166	72.846
422.708	71.518
426.248	66.0734
429.788	60.9143
433.326	54.8568
436.86	47.4635
440.395	40.6125
443.929	34.851
447.461	30.1067
450.99	26.5709
454.52	23.205
458.048	18.8586
461.573	15.5164
465.099	13.2623
468.623	13.6041
472.144	14.2793
475.666	14.3802
479.184	14.7584
482.703	15.5285
486.218	18.5744
489.734	20.3692
493.247	24.4648
496.759	27.7626
500.271	30.5599
503.779	33.8813
507.287	35.0307
510.795	34.8784
514.299	36.5048
517.803	38.7647
521.305	39.0481
524.805	40.7701
528.307	42.4053
531.805	42.9836
535.301	41.4241
538.797	39.7753
542.291	38.9743
545.783	38.5994
549.275	35.5205
552.765	34.1757
556.253	31.0031
559.738	27.9408
563.224	25.779
566.709	23.3997
570.192	21.0947
573.674	18.7791
577.153	16.2915
580.632	14.7937
584.11	13.3729
587.587	11.2757
591.06	9.97607
594.534	6.70199
598.005	3.30572
601.476	4.51169
604.944	3.76454
608.413	4.20935
611.878	5.16228
615.344	5.13134
618.807	5.54638
622.27	7.17238
625.73	10.1745
629.189	12.2793
632.648	15.5057
636.105	17.0671
639.559	19.0144
643.013	20.7862
646.467	23.1209
649.918	23.4021
653.368	22.5317
656.816	24.1222
660.263	23.9121
663.708	24.4282
667.153	24.5437
670.596	24.4331
674.037	23.5732
677.478	22.9957
680.917	21.4669
684.355	21.9302
687.791	23.1633
691.224	24.2533
694.658	23.7887
698.091	23.7877
701.522	24.4733
704.95	24.5636
708.379	25.5889
711.806	25.3256
715.23	26.6132
718.655	27.1256
722.078	27.8304
725.498	29.1762
728.919	29.0208
732.337	28.1395
735.755	26.2775
739.17	26.221
742.584	28.966
745.998	30.7001
749.409	30.8467
752.819	35.3925
756.23	37.8459
759.637	39.8847
763.043	41.0344
766.448	43.4994
769.853	44.8033
773.255	48.3106
776.656	50.1691
780.056	51.8756
783.454	53.5163
786.851	55.2367
790.247	57.154
793.641	59.477
797.034	62.2222
800.426	62.407
803.817	64.0979
807.206	65.911
810.592	64.4283
813.979	63.3171
817.364	62.9892
820.748	63.1005
824.129	63.7433
827.511	63.9691
830.891	63.628
834.269	62.591
837.646	61.9572
841.023	59.097
844.396	56.1557
847.77	52.5127
851.141	50.4975
854.513	47.8703
857.881	45.6325
861.248	43.4038
864.616	40.7231
867.98	40.4599
871.343	37.8374
874.707	37.5742
878.068	36.9338
881.428	35.1536
884.786	34.6151
888.143	33.2346
891.498	32.4631
894.855	31.4507
898.208	30.809
901.56	30.9958
904.91	29.8255
908.26	28.9285
911.608	29.0848
914.955	28.3347
918.298	26.9086
921.643	26.3394
924.986	25.1064
928.328	27.3566
931.668	25.8934
935.006	27.4432
938.344	27.5618
941.681	27.1449
945.014	28.4091
948.349	27.1349
951.682	27.3092
955.012	26.3164
958.343	25.2557
961.67	23.3845
964.998	27.0118
968.323	29.0689
971.649	32.3426
974.971	37.7213
978.293	40.7926
981.615	44.4546
984.933	49.1009
988.251	50.9907
991.567	53.9409
994.884	54.9368
998.198	55.1361
1001.51	56.9777
1004.82	56.0086
1008.13	56.2053
1011.44	54.8588
1014.75	54.3083
1018.06	57.4158
1021.36	59.1412
1024.66	62.1671
1027.97	62.9012
1031.27	62.4678
1034.57	61.8685
1037.87	61.4298
1041.16	61.2995
1044.46	64.8321
1047.76	65.4899
1051.05	64.9397
1054.34	64.203
1057.63	64.1425
1060.92	62.2893
1064.21	58.1769
1067.5	52.0647
1070.78	46.7055
1074.07	40.237
1077.35	32.7714
1080.63	25.822
1083.91	18.1475
1087.19	13.4213
1090.47	11.4445
1093.75	11.9572
1097.03	13.7175
1100.3	15.3085
1103.57	13.9531
1106.84	13.7062
1110.11	11.6086
1113.38	11.0162
1116.65	11.2239
1119.92	10.9105
1123.19	10.2682
1126.45	9.06542
1129.71	6.81641
1132.97	7.69342
1136.23	7.03389
1139.49	6.23523
1142.75	5.52471
1146.01	4.91371
1149.26	5.78678
1152.52	3.17845
1155.77	2.36637
1159.02	2.76297
1162.27	2.76482
1165.52	2.78193
1168.77	4.93584
1172.02	6.11165
1175.26	6.7374
1178.51	9.84714
1181.75	10.9111
1184.99	12.011
1188.23	13.3647
1191.47	15.4214
1194.71	18.9266
1197.94	20.0784
1201.18	22.8686
1204.41	26.0671
1207.65	28.2253
1210.88	33.4402
1214.11	37.0365
1217.34	42.4698
1220.57	45.3847
1223.79	49.3063
1227.02	51.7468
1230.24	52.8564
1233.47	53.5919
1236.69	55.1709
1239.91	56.1474
1243.13	57.9933
1246.34	59.1458
1249.56	60.3436
1252.78	59.8538
1255.99	58.648
1259.2	57.2321
1262.42	55.0889
1265.63	53.5506
1268.84	52.0974
1272.04	53.0191
1275.25	53.498
1278.46	55.0785
1281.66	55.7517
1284.86	57.2512
1288.07	59.7954
1291.27	62.5247
1294.47	65.4184
1297.66	65.4897
1300.86	67.9507
1304.06	70.4721
1307.25	73.4925
1310.44	76.5509
1313.64	80.5916
1316.83	83.8061
1320.02	85.6051
1323.2	85.4321
1326.39	85.5298
1329.58	83.9784
1332.76	82.856
1335.95	81.226
1339.13	79.8361
1342.31	77.6734
1345.49	75.2503
1348.67	71.9861
1351.85	71.5933
1355.02	70.2537
1358.2	67.527
1361.37	66.2362
1364.54	62.4335
1367.71	59.4088
1370.88	58.3215
1374.05	56.711
1377.22	55.4314
1380.39	53.9352
1383.55	53.9488
1386.72	53.2725
1389.88	52.43
1393.04	49.7659
1396.2	47.4464
1399.36	46.45
1402.52	47.5087
1405.68	48.9031
1408.83	51.6822
1411.98	54.5132
1415.14	60.8879
1418.29	67.5164
1421.44	73.4655
1424.59	81.5665
1427.74	90.9794
1430.89	100.391
1434.03	107.88
1437.18	115.024
1440.32	120.345
1443.46	124.969
1446.6	128.763
1449.74	130.255
1452.88	128.607
1456.02	124.453
1459.16	119.017
1462.29	113.188
1465.43	104.759
1468.56	94.7179
1471.69	83.318
1474.82	74.6395
1477.95	66.2829
1481.08	56.2223
1484.2	47.9707
1487.33	40.9337
1490.46	36.6416
1493.58	32.5446
1496.7	27.0536
1499.82	25.1917
1502.94	22.929
1506.06	23.279
1509.18	21.9231
1512.29	22.8631
1515.41	24.0305
1518.52	24.8012
1521.63	26.5381
1524.75	28.0666
1527.85	28.4856
1530.96	30.172
1534.07	31.9352
1537.18	33.032
1540.28	35.7072
1543.39	36.0438
1546.49	37.171
1549.59	38.7619
1552.69	39.4038
1555.79	39.1344
1558.89	39.2482
1561.99	40.2663
1565.08	41.4816
1568.18	43.2706
1571.27	46.1775
1574.37	48.9436
1577.46	52.2507
1580.55	53.636
1583.64	56.2881
1586.73	58.4993
1589.81	60.9435
1592.9	62.041
1595.98	64.8297
1599.06	65.9257
1602.15	66.481
1605.23	66.6488
1608.31	67.9937
1611.39	67.1136
1614.46	67.6975
1617.54	67.6551
1620.61	66.7748
1623.69	66.8416
1626.76	66.3624
1629.83	66.5606
1632.9	67.295
1635.97	68.1946
1639.04	71.1597
1642.11	73.95
1645.17	78.1784
1648.24	81.481
1651.3	83.0598
1654.36	83.3453
1657.42	81.535
1660.48	81.2751
1663.54	80.1703
1666.6	79.5103
1669.66	76.1343
1672.71	72.124
1675.77	65.8331
1678.82	61.6873
1681.87	56.0662
1684.92	49.5951
1687.97	43.6996
1691.02	37.8913
1694.07	32.4569
1697.11	26.5562
1700.16	22.5397
1703.2	18.0913
1706.25	15.6781
1709.29	12.6923
1712.33	12.1675
1715.37	9.46466
1718.41	8.07747
1721.44	7.73634
1724.48	6.77875
1727.51	5.37004
1730.55	4.44826
1733.58	4.93147
1736.61	4.69163
1739.64	4.72497
1742.67	3.6288
1745.7	2.77127
1748.72	2.44955
1751.75	3.57208
1754.77	2.20363
1757.8	1.56358
1760.82	1.4821
1763.84	0.838295
1766.86	0.6356
1769.88	1.52172
1772.9	0.768996
1775.91	1.1837
1778.93	1.68379
1781.94	2.56463
1784.96	2.10748
1787.97	1.99173
1790.98	2.54904
1793.99	3.49605
1797	4.31069
1800.01	4.03264
1803.01	3.32779
1806.02	3.57297
1809.02	3.50241
1812.02	3.39886
1815.02	3.39649
1818.03	4.48253
1821.02	5.8114
1824.02	4.76363
1827.02	4.65672
1830.02	5.14036
1833.01	4.99651
1836.01	4.60427
1839	4.0757
1841.99	4.17016
1844.98	4.44233
1847.97	3.76937
1850.96	2.87065
1853.95	3.01076
1856.93	4.06012
1859.92	3.93859
1862.9	4.30629
1865.88	5.29508
1868.87	5.67123
1871.85	5.28632
1874.83	5.26369
1877.81	5.83099
1880.78	6.12023
1882.53	6.84135
1885.52	6.01663
1888.51	6.65745
1891.5	6.76386
1894.48	4.9075
1897.47	4.47372
1900.45	6.34225
1903.43	5.36957
1906.41	5.57421
1909.39	4.72307
1912.37	3.63825
1915.35	2.49982
1918.33	1.58036
1921.3	-0.537637
1924.28	-0.173317
1927.25	0.321604
1930.22	1.52938
1933.19	1.90581
1936.16	2.74394
1939.13	4.01003
1942.1	2.80626
1945.07	4.19382
1948.03	5.50582
1951	5.52398
1953.96	4.63586
1956.92	4.91775
1959.88	3.69046
1962.84	3.52543
1965.8	4.07398
1968.76	4.30494
1971.72	4.62977
1974.67	4.47951
1977.63	4.21079
1980.58	3.24473
1983.54	2.54734
1986.49	2.63538
1989.44	2.66929
1992.39	3.8252
1995.33	3.59864
1998.28	4.10339
2001.23	4.29865
2004.17	4.80113
2007.12	5.72685
2010.06	5.38398
2013	5.60027
2015.94	6.4304
2018.88	7.06636
2021.82	6.23324
2024.76	5.14864
2027.69	4.46412
2030.63	3.78086
2033.56	2.42909
2036.5	2.14363
2039.43	1.62699
2042.36	2.02363
2045.29	2.45328
2048.22	3.1143
2051.15	2.96335
2054.07	3.25927
2057	3.83349
2059.92	3.70444
2062.85	4.14806
2065.77	4.04814
2068.69	4.77429
2071.61	5.2477
2074.53	5.89768
2077.45	6.72167
2080.37	5.97923
2083.28	6.0339
2086.2	6.39328
2089.11	6.88522
2092.02	7.28637
2094.94	7.58586
2097.85	8.21415
2100.76	7.90404
2103.66	7.99669
2106.57	8.26664
2109.48	7.88045
2112.38	7.54586
2115.29	8.09242
2118.19	7.32859
2121.09	7.52944
2123.99	6.6893
2126.89	5.51485
2129.79	5.31631
2132.69	4.09053
2135.59	3.46069
2138.48	2.87023
2141.38	2.34483
2144.27	1.1238
2147.17	0.399009
2150.06	-0.94956
2152.95	-0.181501
2155.84	1.81566
2158.73	3.84755
2161.61	4.91541
2164.5	5.86179
2167.38	8.08234
2170.27	8.36601
2173.15	8.71111
2176.03	9.3806
2178.91	9.74355
2181.8	9.2529
2184.67	9.75085
2187.55	10.3623
2190.43	8.74203
2193.3	9.68431
2196.18	8.49137
2199.05	8.25553
2201.93	7.25099
2204.8	6.69488
2207.67	5.74692
2210.54	5.18763
2213.41	5.24374
2216.27	5.34398
2219.14	4.97607
2222.01	6.53185
2224.87	8.35626
2227.73	9.00599
2230.6	9.23619
2233.46	10.1072
2236.32	10.0446
2239.18	10.9463
2242.03	11.1318
2244.89	10.8949
2247.75	10.7599
2250.6	10.1337
2253.46	9.55163
2256.31	8.12006
2259.16	8.22426
2262.01	7.81688
2264.86	6.63948
2267.71	5.94831
2270.56	5.55455
2273.4	4.06695
2276.25	2.59074
2279.09	2.59331
2281.94	1.73938
2284.78	2.1966
2287.62	2.37786
2290.46	1.55503
2293.3	1.56686
2296.14	1.96384
2298.98	1.7852
2301.82	3.45853
2304.65	3.02966
2307.49	3.47332
2310.32	3.84807
2313.15	4.20656
2315.98	3.9944
2318.81	4.54282
2321.64	4.07714
2324.47	4.68019
2327.3	4.87936
2330.12	4.59595
2332.95	3.03958
2335.77	2.56981
2338.6	1.82674
2341.42	1.36594
2344.24	0.136825
2347.06	-0.34236
2349.88	-0.789669
2352.7	-1.15063
2355.51	-0.82389
2358.33	-1.56603
2361.14	-1.38186
2363.96	0.056189
2366.77	0.0211112
2369.58	-0.165028
2372.39	0.998229
2375.2	1.11372
2378.01	1.92956
2380.82	2.96036
2383.63	3.56402
2386.43	4.04959
2389.24	5.71664
2392.04	6.88678
2394.84	7.09237
2397.65	7.33882
2400.45	7.02249
2403.25	7.89108
2406.05	7.12762
2408.84	7.27598
2411.64	7.40762
2414.44	7.39946
2417.23	7.62142
2420.02	7.36464
2422.82	7.42432
2425.61	8.10089
2428.4	7.85534
2431.19	7.84031
2433.98	7.78154
2436.77	7.73084
2439.55	7.14683
2442.34	6.88032
2445.12	5.60471
2447.91	4.83743
2450.69	4.17006
2453.47	3.44938
2456.25	3.6865
2459.03	3.76296
2461.81	3.34186
2464.59	3.06346
2467.36	2.45333
2470.14	2.18664
2472.92	1.82959
2475.69	1.07933
2478.46	1.0858
2481.23	0.990973
2484	0.602839
2486.77	0.924066
2489.54	1.21672
2492.31	1.99845
2495.08	2.89381
2497.84	4.13853
2500.61	4.01541
2503.37	5.06457
2506.13	4.05753
2508.9	4.30059
2511.66	4.67776
2514.42	4.95545
2517.18	6.66868
2519.93	6.62641
2522.69	7.13477
2525.45	8.51093
2528.2	8.56268
2530.95	8.52511
2533.71	9.14305
2536.46	10.1097
2539.21	9.89235
2541.96	9.1131
2544.71	7.92395
2547.46	9.47756
2550.2	9.62129
2552.95	10.2073
2555.7	10.4349
2558.44	10.4063
2561.18	10.4483
2563.93	10.2021
2566.67	10.2922
2569.41	9.74224
2572.15	9.15695
2574.88	9.39344
2577.62	9.62912
2580.36	9.6876
2583.09	8.46647
2585.83	9.09874
2588.56	9.37151
2591.29	9.16036
2594.02	8.99175
2596.75	10.0533
2599.48	9.13314
2602.21	9.3872
2604.94	8.89927
2607.67	7.52463
2610.39	7.61947
2613.12	8.16857
2615.84	9.06027
2618.56	8.93984
2621.28	8.7513
2624.01	8.06499
2626.72	8.70768
2629.44	9.23652
2632.16	9.94114
2634.88	10.817
2637.59	9.6872
2640.31	10.6302
2643.02	12.0043
2645.74	12.287
2648.45	13.0494
2651.16	14.4901
2653.87	15.3088
2656.58	15.8772
2659.29	15.7956
2661.99	16.1654
2664.7	16.3209
2667.41	15.9276
2670.11	15.98
2672.81	15.4925
2675.51	15.728
2678.22	15.578
2680.92	16.1206
2683.62	16.6126
2686.31	16.7037
2689.01	16.702
2691.71	16.7456
2694.4	17.7444
2697.1	18.0764
2699.79	17.2746
2702.49	16.6877
2705.18	17.0135
2707.87	18.4525
2710.56	19.916
2713.25	21.3512
2715.94	23.13
2718.62	23.0029
2721.31	22.8156
2723.99	22.6599
2726.68	22.0384
2729.36	22.4074
2732.04	22.4506
2734.73	21.0294
2737.41	19.7523
2740.08	20.2224
2742.76	18.9838
2745.44	19.2229
2748.12	19.2735
2750.79	19.5871
2753.47	18.9469
2756.14	18.2637
2758.81	17.0551
2761.49	16.6535
2764.16	15.3044
2766.83	14.5955
2769.5	14.0176
2772.16	13.3735
2774.83	12.2193
2777.5	11.7524
2780.16	10.6932
2782.83	10.21
2785.49	8.56832
2788.15	8.28953
2790.82	7.06294
2793.48	6.25427
2796.14	6.07061
2798.79	4.78858
2801.45	4.00234
2804.11	4.1864
2806.76	3.33496
2809.42	3.0381
2812.07	3.9302
2814.73	6.5846
2817.38	9.36416
2820.03	12.334
2822.68	17.0294
2825.33	23.6862
2827.98	30.8953
2830.63	37.5612
2833.27	44.5285
2835.92	51.7477
2838.56	60.5834
2841.21	71.9253
2843.85	85.3679
2846.49	99.1716
2849.13	113.617
2851.77	128.148
2854.41	141.832
2857.05	156.039
2859.69	170.214
2862.32	181.824
2864.96	192.725
2867.59	203.482
2870.23	210.045
2872.86	218.169
2875.49	225.321
2878.12	231.852
2880.75	236.684
2883.38	241.616
2886.01	246.766
2888.63	251.841
2891.26	256.004
2893.89	260.98
2896.51	266.144
2899.13	273.927
2901.76	281.92
2904.38	292.492
2907	304.368
2909.62	316.631
2912.24	329.499
2914.85	341.887
2917.47	352.912
2920.09	362.946
2922.7	370.537
2925.32	375.325
2927.93	377.604
2930.54	376.565
2933.15	371.901
2935.76	367.589
2938.37	359.631
2940.98	350.073
2943.59	339.222
2946.2	326.543
2948.8	312.849
2951.41	299.813
2954.01	286.689
2956.62	271.954
2959.22	258.699
2961.82	245.318
2964.42	233.239
2967.02	221.343
2969.62	210.479
2972.22	200.175
2974.81	189.598
2977.41	178.219
2980	166.919
2982.6	154.168
2985.19	141.871
2987.78	129.244
2990.38	116.345
2992.97	103.685
2995.56	91.9012
2998.14	81.9385
3000.73	71.5761
3003.32	61.7016
3005.91	52.88
3008.49	45.0874
3011.07	38.1132
3013.66	31.6969
3016.24	26.5117
3018.82	21.5311
3021.4	16.107
3023.98	12.6235
3026.56	9.412
3029.14	6.70934
3031.71	5.90393
3034.29	3.81237
3036.87	2.8359
3039.44	3.20801
3042.01	3.75152
3044.59	4.73984
3047.16	5.12878
3049.73	5.84801
3052.3	6.19205
3054.87	7.59934
3057.43	8.16035
3060	9.29355
3062.57	9.8184
3065.13	9.61785
3067.7	10.1163
3070.26	9.85534
3072.82	9.96089
3075.39	9.44626
3077.95	7.9072
3080.51	5.68985
3083.07	4.39288
3085.63	3.39451
3088.18	1.65691
3090.74	1.65619
3093.29	1.17974
3095.85	2.46827
3098.4	3.0658
3100.95	3.8748
3103.51	3.76847
3106.06	4.21416
3108.61	4.97612
3111.16	6.29097
3113.71	7.24429
3116.25	8.88774
3118.8	10.0776
3121.35	11.97
3123.89	14.0905
3126.44	15.4542
3128.98	17.3133
3131.52	17.8288
3134.06	19.7043
3136.6	21.7861
3139.14	22.9788
3141.68	24.8947
3144.22	27.5021
3146.76	30.8259
3149.29	33.0788