File: data/Raman/poly_smoothed/Mb_00_13_08_1x_45s_532 nm_x100_100%_600 gr_mm_01.txt
#Acq. time (s)=	45
#Accumulations=	2
#Range (cm-¹)=	200...3150
#Windows=	2
#Auto scanning=	Off
#Autofocus=	Off
#Macrospot=	Off
#AutoExposure=	Off
#Spike filter=	Multiple accum.
#Delay time (s)=	0
#Binning=	1
#Readout mode=	Signal
#DeNoise=	Off
#ICS correction=	On
#Dark correction=	Off
#Inst. Process=	Off
#Detector Gain=	Best Dynamic Range
#Detector ADC=	20 kHz
#Detector temperature (°C)=	-69.85
#Instrument=	LabRAM HR Evol
#Detector=	Synapse
#Objective=	x100
#Grating=	600 gr/mm
#ND Filter=	100%
#Laser (nm)=	532
#Hole=	100.021
#Range=	Auto
#Laser Pol.=	No
#Raman. Pol.=	No
#Laser Pol. (°)=	-0.0007625
#Raman Pol. (°)=	89.9995
#Collection=	Microscope
#StageXY=	Marzhauser
#StageZ=	Marzhauser
#X (µm)=	-994.5
#Y (µm)=	-2944.9
#Z (µm)=	527.85
#Full time(mm:ss)=	3:18
#Project=
#Sample=
#Site=
#Title=	Mb_00_13_08_2x_45s_532 nm_x100_100%_600 gr_mm
#Remark=
#Date=	06.07.2022 10:13
#Acquired=	06.07.2022 10:13:48
#Base:Fit=	10.08.2022 10:16:36
#Base:Fit=	10.08.2022 10:16:56
#Base:Sub=	10.08.2022 10:17:24
#Filter:Polynom=	16.08.2022 10:36:38
#AxisType[0]=Intens
#AxisUnit[0]=Cnt
#AxisType[1]=Spectr
#AxisUnit[1]=1/cm
200.398	47.7999
204.027	30.9774
207.657	16.0822
211.283	4.83113
214.909	-0.742281
218.533	3.58822
222.157	13.7834
225.777	30.1399
229.396	46.2569
233.016	63.6099
236.632	80.2783
240.247	94.4947
243.86	107.724
247.474	118.96
251.085	131.992
254.694	140.197
258.301	147.672
261.908	151.589
265.513	150.743
269.116	148.392
272.718	143.406
276.319	131.024
279.918	117.036
283.516	102.939
287.113	85.0141
290.708	69.1733
294.302	54.7131
297.894	42.3536
301.485	33.1228
305.073	26.5007
308.661	23.006
312.247	19.0869
315.833	15.9771
319.415	13.6051
322.997	13.7389
326.579	11.6455
330.156	10.5918
333.735	10.8651
337.31	8.74141
340.885	7.59007
344.458	6.49812
348.03	6.38637
351.6	6.80418
355.17	6.36392
358.737	6.85031
362.304	8.08775
365.868	11.9929
369.431	16.8149
372.994	22.7258
376.554	30.6666
380.112	40.3645
383.669	53.6867
387.225	70.0257
390.781	84.7658
394.334	99.4403
397.885	111.362
401.436	119.985
404.984	125.754
408.532	129.5
412.078	131.092
415.623	130.369
419.166	128.09
422.708	121.333
426.248	111.503
429.788	101.128
433.326	89.2549
436.86	75.0021
440.395	61.5494
443.929	48.2031
447.461	35.9932
450.99	25.1948
454.52	15.8245
458.048	7.69945
461.573	0.166614
465.099	-2.51981
468.623	-0.215809
472.144	4.48546
475.666	4.75803
479.184	8.27163
482.703	10.2903
486.218	12.3688
489.734	14.4179
493.247	17.8049
496.759	23.6569
500.271	27.3278
503.779	29.9704
507.287	31.6469
510.795	34.0108
514.299	37.9078
517.803	40.7328
521.305	42.552
524.805	44.2851
528.307	43.7817
531.805	45.3963
535.301	45.8268
538.797	44.7554
542.291	43.0891
545.783	39.5913
549.275	36.0221
552.765	34.255
556.253	29.8552
559.738	24.9736
563.224	20.6685
566.709	17.5968
570.192	12.6854
573.674	10.4377
577.153	6.75314
580.632	6.93044
584.11	4.93245
587.587	2.42973
591.06	-0.132861
594.534	-0.776573
598.005	-1.79709
601.476	-2.56914
604.944	-2.48164
608.413	-1.46767
611.878	-0.125773
615.344	0.836851
618.807	4.3935
622.27	4.25867
625.73	6.37517
629.189	9.45477
632.648	11.778
636.105	14.9619
639.559	17.401
643.013	21.2336
646.467	21.2296
649.918	23.494
653.368	24.8575
656.816	24.5508
660.263	24.3047
663.708	25.7163
667.153	24.5916
670.596	23.4811
674.037	21.1026
677.478	19.0613
680.917	19.1875
684.355	16.6243
687.791	16.745
691.224	14.3896
694.658	12.1124
698.091	10.7293
701.522	9.97158
704.95	7.4888
708.379	7.09677
711.806	8.59436
715.23	5.21917
718.655	5.88618
722.078	6.53215
725.498	7.23484
728.919	6.87834
732.337	6.1583
735.755	6.32494
739.17	8.34817
742.584	10.2374
745.998	13.4216
749.409	14.8857
752.819	19.4103
756.23	23.4901
759.637	27.7899
763.043	32.404
766.448	34.9323
769.853	36.1625
773.255	39.9778
776.656	42.0989
780.056	43.9615
783.454	46.7454
786.851	47.5865
790.247	48.2509
793.641	50.2487
797.034	49.6912
800.426	49.8767
803.817	51.6589
807.206	50.3964
810.592	49.6226
813.979	47.6239
817.364	45.9861
820.748	47.0613
824.129	46.3493
827.511	44.0791
830.891	41.9355
834.269	43.0407
837.646	42.0331
841.023	41.2303
844.396	37.4144
847.77	34.5949
851.141	33.6298
854.513	30.6217
857.881	29.102
861.248	27.1846
864.616	23.9909
867.98	22.5947
871.343	21.9959
874.707	21.1601
878.068	20.635
881.428	18.9754
884.786	18.4138
888.143	17.2478
891.498	16.1625
894.855	16.0119
898.208	17.0508
901.56	16.1815
904.91	15.6407
908.26	14.9552
911.608	15.6502
914.955	15.4811
918.298	16.4869
921.643	15.4164
924.986	14.5523
928.328	14.0431
931.668	15.0667
935.006	15.6486
938.344	13.5575
941.681	13.8225
945.014	15.2487
948.349	13.8694
951.682	14.7471
955.012	13.6111
958.343	9.33998
961.67	10.6951
964.998	14.615
968.323	18.9377
971.649	22.5217
974.971	27.2131
978.293	31.4021
981.615	33.6007
984.933	34.208
988.251	37.2094
991.567	38.4398
994.884	39.4243
998.198	40.8686
1001.51	38.3695
1004.82	36.3876
1008.13	36.0259
1011.44	34.8286
1014.75	34.8643
1018.06	39.1683
1021.36	47.4193
1024.66	59.4174
1027.97	70.1589
1031.27	79.0872
1034.57	89.2058
1037.87	98.2333
1041.16	105.85
1044.46	114.216
1047.76	120.885
1051.05	124.921
1054.34	127.704
1057.63	125.847
1060.92	120.322
1064.21	114.148
1067.5	107.238
1070.78	97.5856
1074.07	86.239
1077.35	71.2699
1080.63	55.3293
1083.91	39.2589
1087.19	26.1904
1090.47	13.9452
1093.75	9.15394
1097.03	8.57704
1100.3	7.81536
1103.57	10.7244
1106.84	11.3242
1110.11	9.46659
1113.38	8.82287
1116.65	6.45944
1119.92	5.81637
1123.19	5.60119
1126.45	5.75134
1129.71	7.35201
1132.97	7.14987
1136.23	6.32905
1139.49	7.05424
1142.75	7.63131
1146.01	8.89129
1149.26	7.21462
1152.52	5.17018
1155.77	4.03186
1159.02	2.36468
1162.27	0.459603
1165.52	1.93751
1168.77	3.06645
1172.02	4.77996
1175.26	6.88334
1178.51	7.35867
1181.75	9.22957
1184.99	12.0582
1188.23	13.2459
1191.47	15.5944
1194.71	19.2828
1197.94	25.5965
1201.18	32.3605
1204.41	39.0824
1207.65	44.3324
1210.88	49.3798
1214.11	56.6845
1217.34	63.3149
1220.57	68.6713
1223.79	72.265
1227.02	76.4465
1230.24	79.2362
1233.47	82.1678
1236.69	85.1429
1239.91	87.6411
1243.13	89.8394
1246.34	90.8466
1249.56	91.906
1252.78	91.5078
1255.99	90.5767
1259.2	87.3204
1262.42	85.3455
1265.63	82.5167
1268.84	82.8441
1272.04	82.4965
1275.25	83.3122
1278.46	86.0836
1281.66	87.2595
1284.86	90.0057
1288.07	91.2495
1291.27	95.455
1294.47	99.9252
1297.66	100.58
1300.86	103.814
1304.06	108.63
1307.25	112.139
1310.44	118.324
1313.64	125.407
1316.83	125.932
1320.02	128.902
1323.2	129.629
1326.39	130.928
1329.58	129.687
1332.76	127.789
1335.95	124.459
1339.13	121.85
1342.31	120.381
1345.49	118.776
1348.67	116.074
1351.85	114.017
1355.02	110.991
1358.2	107.207
1361.37	105.15
1364.54	100.56
1367.71	93.9008
1370.88	90.9164
1374.05	90.8835
1377.22	90.3999
1380.39	91.978
1383.55	94.2669
1386.72	94.4285
1389.88	96.4747
1393.04	96.0336
1396.2	95.6774
1399.36	97.1738
1402.52	98.6859
1405.68	102.934
1408.83	107.657
1411.98	112.026
1415.14	118.834
1418.29	127.08
1421.44	137.897
1424.59	145.68
1427.74	154.521
1430.89	164.402
1434.03	171.819
1437.18	178.436
1440.32	182.866
1443.46	185.856
1446.6	188.189
1449.74	191.458
1452.88	190.008
1456.02	188.516
1459.16	183.98
1462.29	176.666
1465.43	163.234
1468.56	152.464
1471.69	140.057
1474.82	126.984
1477.95	113.732
1481.08	104.594
1484.2	92.9963
1487.33	86.2403
1490.46	79.0474
1493.58	72.9151
1496.7	67.7222
1499.82	62.7782
1502.94	59.6788
1506.06	61.0891
1509.18	61.0048
1512.29	58.4456
1515.41	58.6694
1518.52	57.7852
1521.63	58.1416
1524.75	59.105
1527.85	60.9307
1530.96	62.3035
1534.07	62.3878
1537.18	63.9397
1540.28	63.4501
1543.39	67.307
1546.49	71.3247
1549.59	73.6476
1552.69	74.3597
1555.79	79.0643
1558.89	81.8652
1561.99	81.9654
1565.08	84.9081
1568.18	87.2773
1571.27	87.6434
1574.37	91.4089
1577.46	95.5827
1580.55	99.979
1583.64	102.807
1586.73	105.497
1589.81	106.749
1592.9	108.014
1595.98	110.548
1599.06	110.994
1602.15	112.431
1605.23	111.026
1608.31	111.169
1611.39	111.015
1614.46	109.694
1617.54	111.454
1620.61	113.14
1623.69	111.476
1626.76	110.633
1629.83	112.179
1632.9	112.673
1635.97	112.922
1639.04	113.401
1642.11	117.644
1645.17	120.318
1648.24	122.154
1651.3	125.22
1654.36	125.804
1657.42	125.705
1660.48	125.114
1663.54	123.29
1666.6	118.967
1669.66	114.414
1672.71	109.436
1675.77	103.952
1678.82	95.6597
1681.87	90.6557
1684.92	83.7637
1687.97	75.3389
1691.02	69.481
1694.07	65.1089
1697.11	59.9355
1700.16	53.8331
1703.2	51.6699
1706.25	49.1303
1709.29	46.094
1712.33	43.1591
1715.37	41.0705
1718.41	39.0907
1721.44	35.7722
1724.48	32.3591
1727.51	29.0132
1730.55	25.8213
1733.58	23.2018
1736.61	21.6803
1739.64	18.1165
1742.67	15.056
1745.7	12.6562
1748.72	12.3752
1751.75	12.5166
1754.77	11.6105
1757.8	11.3832
1760.82	9.86299
1763.84	11.1917
1766.86	13.3528
1769.88	14.8797
1772.9	16.1994
1775.91	18.5537
1778.93	20.2256
1781.94	21.9311
1784.96	22.4154
1787.97	22.3376
1790.98	23.5704
1793.99	23.2702
1797	22.544
1800.01	21.8526
1803.01	21.3248
1806.02	21.2263
1809.02	20.3846
1812.02	19.8998
1815.02	18.8454
1818.03	19.2288
1821.02	19.6407
1824.02	19.2932
1827.02	18.8747
1830.02	18.503
1833.01	19.076
1836.01	20.0563
1839	19.8189
1841.99	19.9717
1844.98	20.3418
1847.97	19.922
1850.96	20.5464
1853.95	19.2502
1856.93	17.9299
1859.92	16.8822
1862.9	16.3775
1865.88	15.8658
1868.87	16.7052
1871.85	16.3055
1874.83	15.2093
1877.81	15.2905
1880.78	14.4383
1882.53	13.6227
1885.52	13.4278
1888.51	15.9416
1891.5	16.414
1894.48	15.8104
1897.47	16.0442
1900.45	17.7864
1903.43	18.8965
1906.41	19.6244
1909.39	19.1252
1912.37	18.1436
1915.35	15.9803
1918.33	13.7865
1921.3	11.8792
1924.28	9.39425
1927.25	5.58841
1930.22	4.03552
1933.19	4.12281
1936.16	4.33717
1939.13	3.03662
1942.1	1.55863
1945.07	0.301158
1948.03	0.0849675
1951	2.06869
1953.96	2.31881
1956.92	4.27657
1959.88	5.18735
1962.84	7.7067
1965.8	5.93815
1968.76	7.9422
1971.72	7.24827
1974.67	8.26351
1977.63	10.5052
1980.58	9.03761
1983.54	7.83828
1986.49	5.82725
1989.44	5.4948
1992.39	5.34799
1995.33	5.2774
1998.28	7.93469
2001.23	9.68602
2004.17	10.3733
2007.12	10.6965
2010.06	11.0765
2013	9.79718
2015.94	11.9755
2018.88	13.1175
2021.82	14.5178
2024.76	13.788
2027.69	12.0531
2030.63	13.4896
2033.56	13.1161
2036.5	11.0116
2039.43	8.20058
2042.36	8.07163
2045.29	7.11179
2048.22	7.85755
2051.15	5.8247
2054.07	3.87031
2057	3.82364
2059.92	4.45076
2062.85	6.02466
2065.77	8.88412
2068.69	9.79254
2071.61	10.3094
2074.53	11.045
2077.45	11.0716
2080.37	11.2899
2083.28	10.7511
2086.2	12.6596
2089.11	13.3147
2092.02	12.9394
2094.94	12.4932
2097.85	12.8345
2100.76	12.4616
2103.66	13.6508
2106.57	12.8139
2109.48	11.9373
2112.38	12.1951
2115.29	12.1008
2118.19	11.052
2121.09	9.95646
2123.99	10.3793
2126.89	8.26529
2129.79	8.96288
2132.69	9.32533
2135.59	8.01138
2138.48	7.25113
2141.38	5.62479
2144.27	4.90738
2147.17	5.78786
2150.06	6.02512
2152.95	8.06054
2155.84	7.67629
2158.73	10.7126
2161.61	12.2424
2164.5	12.5756
2167.38	13.4297
2170.27	13.5285
2173.15	14.1405
2176.03	13.7074
2178.91	12.4652
2181.8	10.5926
2184.67	10.74
2187.55	10.5491
2190.43	9.83619
2193.3	10.2424
2196.18	7.89715
2199.05	8.19223
2201.93	7.99902
2204.8	7.54712
2207.67	6.70043
2210.54	7.63907
2213.41	7.66833
2216.27	7.09568
2219.14	10.7023
2222.01	10.6521
2224.87	12.6505
2227.73	14.8348
2230.6	16.0237
2233.46	13.4469
2236.32	12.1559
2239.18	12.5314
2242.03	11.8239
2244.89	10.9799
2247.75	10.742
2250.6	8.60325
2253.46	7.84683
2256.31	6.54688
2259.16	6.89256
2262.01	7.2426
2264.86	7.02667
2267.71	6.64463
2270.56	6.67337
2273.4	5.71377
2276.25	6.99382
2279.09	7.29893
2281.94	5.76605
2284.78	8.00164
2287.62	8.75476
2290.46	7.14487
2293.3	7.84678
2296.14	9.42732
2298.98	11.135
2301.82	11.4987
2304.65	13.3778
2307.49	14.5715
2310.32	15.6914
2313.15	18.0969
2315.98	18.3267
2318.81	17.7541
2321.64	16.3695
2324.47	14.417
2327.3	15.9661
2330.12	14.2821
2332.95	16.2034
2335.77	15.3094
2338.6	12.5402
2341.42	11.8673
2344.24	11.6302
2347.06	10.1699
2349.88	6.30558
2352.7	4.38553
2355.51	2.61518
2358.33	1.32664
2361.14	1.66517
2363.96	3.22537
2366.77	5.16025
2369.58	6.16315
2372.39	8.43038
2375.2	9.79343
2378.01	10.0805
2380.82	10.8041
2383.63	13.3917
2386.43	10.805
2389.24	9.84785
2392.04	9.72703
2394.84	10.6028
2397.65	10.0659
2400.45	10.6973
2403.25	9.48659
2406.05	8.3676
2408.84	7.63976
2411.64	7.07864
2414.44	6.73256
2417.23	4.15353
2420.02	2.59811
2422.82	3.93365
2425.61	3.96341
2428.4	5.29621
2431.19	7.26196
2433.98	8.17157
2436.77	7.63604
2439.55	7.91399
2442.34	7.24411
2445.12	7.66061
2447.91	7.13642
2450.69	7.89855
2453.47	7.80357
2456.25	7.1085
2459.03	6.81733
2461.81	7.41095
2464.59	6.38712
2467.36	6.77933
2470.14	7.22166
2472.92	9.04338
2475.69	8.80648
2478.46	9.34979
2481.23	8.64031
2484	7.80081
2486.77	8.12096
2489.54	10.0502
2492.31	11.3562
2495.08	12.6384
2497.84	15.5555
2500.61	14.6892
2503.37	12.5098
2506.13	10.4678
2508.9	10.9954
2511.66	12.2795
2514.42	11.0798
2517.18	12.0436
2519.93	9.1292
2522.69	9.97267
2525.45	10.0961
2528.2	9.88798
2530.95	11.441
2533.71	10.9802
2536.46	10.7244
2539.21	10.6259
2541.96	10.7423
2544.71	9.98723
2547.46	9.76767
2550.2	11.8035
2552.95	14.2805
2555.7	16.0176
2558.44	17.9673
2561.18	19.6996
2563.93	21.8671
2566.67	20.5001
2569.41	19.8103
2572.15	19.9441
2574.88	19.7085
2577.62	20.9838
2580.36	20.4432
2583.09	23.033
2585.83	24.7353
2588.56	25.6197
2591.29	26.9937
2594.02	25.5475
2596.75	25.0311
2599.48	23.3894
2602.21	21.4384
2604.94	20.0487
2607.67	22.0099
2610.39	21.9136
2613.12	21.1699
2615.84	20.8024
2618.56	19.0685
2621.28	19.5016
2624.01	19.755
2626.72	19.438
2629.44	18.2026
2632.16	17.7604
2634.88	17.1788
2637.59	17.6773
2640.31	18.404
2643.02	17.8233
2645.74	20.6452
2648.45	22.2994
2651.16	25.3567
2653.87	25.1736
2656.58	26.3627
2659.29	25.2177
2661.99	26.1213
2664.7	27.9057
2667.41	29.182
2670.11	31.1453
2672.81	33.1402
2675.51	31.676
2678.22	29.7275
2680.92	30.0526
2683.62	28.9775
2686.31	28.6162
2689.01	30.2427
2691.71	28.7927
2694.4	27.4534
2697.1	27.2057
2699.79	28.9462
2702.49	28.6844
2705.18	27.1649
2707.87	28.3877
2710.56	29.3446
2713.25	31.1816
2715.94	32.9709
2718.62	34.301
2721.31	34.1884
2723.99	33.508
2726.68	34.0696
2729.36	35.5467
2732.04	34.4506
2734.73	34.4069
2737.41	33.7737
2740.08	30.186
2742.76	27.9911
2745.44	27.9079
2748.12	27.6404
2750.79	25.8571
2753.47	25.2192
2756.14	24.1989
2758.81	22.7203
2761.49	21.1912
2764.16	18.8796
2766.83	17.0641
2769.5	14.4193
2772.16	13.7852
2774.83	12.5208
2777.5	10.7079
2780.16	10.0262
2782.83	9.20025
2785.49	6.81185
2788.15	7.02419
2790.82	5.87309
2793.48	6.53993
2796.14	8.07345
2798.79	9.89177
2801.45	9.86287
2804.11	11.4062
2806.76	12.8518
2809.42	13.2759
2812.07	14.6016
2814.73	17.335
2817.38	20.0377
2820.03	24.6651
2822.68	29.0679
2825.33	35.0916
2827.98	42.5423
2830.63	49.7399
2833.27	57.5518
2835.92	67.1216
2838.56	77.1594
2841.21	88.2925
2843.85	102.914
2846.49	119.441
2849.13	133.809
2851.77	150.32
2854.41	167.337
2857.05	184.815
2859.69	200.909
2862.32	216.992
2864.96	227.764
2867.59	240.216
2870.23	249.653
2872.86	258.535
2875.49	266.759
2878.12	274.447
2880.75	281.577
2883.38	288.218
2886.01	294.556
2888.63	299.264
2891.26	306.019
2893.89	310.735
2896.51	317.872
2899.13	327.347
2901.76	338.613
2904.38	350.186
2907	362.783
2909.62	378.925
2912.24	396.99
2914.85	414.238
2917.47	428.128
2920.09	438.538
2922.7	448.056
2925.32	454.635
2927.93	456.476
2930.54	456.672
2933.15	451.663
2935.76	445.297
2938.37	436.901
2940.98	425.459
2943.59	412.033
2946.2	395.318
2948.8	378.705
2951.41	361.311
2954.01	342.727
2956.62	325.368
2959.22	307.154
2961.82	291.343
2964.42	274.22
2967.02	258.804
2969.62	244.462
2972.22	231.677
2974.81	219.14
2977.41	204.92
2980	190.478
2982.6	173.564
2985.19	156.766
2987.78	141.127
2990.38	123.39
2992.97	106.65
2995.56	92.2357
2998.14	76.5568
3000.73	63.7963
3003.32	51.9502
3005.91	39.8116
3008.49	28.6093
3011.07	21.9231
3013.66	16.1972
3016.24	9.47014
3018.82	5.36403
3021.4	0.0723
3023.98	-1.60558
3026.56	-3.67129
3029.14	-3.77385
3031.71	-3.55256
3034.29	-3.71355
3036.87	-1.2002
3039.44	0.216845
3042.01	3.13236
3044.59	5.65524
3047.16	6.56596
3049.73	9.15812
3052.3	9.11157
3054.87	9.38928
3057.43	11.1443
3060	10.613
3062.57	10.9912
3065.13	10.2661
3067.7	9.50188
3070.26	8.53134
3072.82	8.89855
3075.39	8.91383
3077.95	7.13222
3080.51	5.67156
3083.07	6.53572
3085.63	4.95517
3088.18	4.85958
3090.74	6.77665
3093.29	8.31733
3095.85	10.4881
3098.4	13.0658
3100.95	16.5901
3103.51	20.3916
3106.06	24.8551
3108.61	30.3419
3111.16	35.6014
3113.71	38.8204
3116.25	43.2423
3118.8	48.6039
3121.35	53.5634
3123.89	57.2785
3126.44	61.8548
3128.98	65.1445
3131.52	70.2781
3134.06	74.6171
3136.6	79.3553
3139.14	83.4595
3141.68	87.1305
3144.22	89.8925
3146.76	91.9361
3149.29	94.3863