File: data/Raman/poly_smoothed/Mb_00_13_11_1x_45s_532 nm_x100_100%_600 gr_mm_01.txt
#Acq. time (s)=	45
#Accumulations=	2
#Range (cm-¹)=	200...3150
#Windows=	2
#Auto scanning=	Off
#Autofocus=	Off
#Macrospot=	Off
#AutoExposure=	Off
#Spike filter=	Multiple accum.
#Delay time (s)=	0
#Binning=	1
#Readout mode=	Signal
#DeNoise=	Off
#ICS correction=	On
#Dark correction=	Off
#Inst. Process=	Off
#Detector Gain=	Best Dynamic Range
#Detector ADC=	20 kHz
#Detector temperature (°C)=	-69.85
#Instrument=	LabRAM HR Evol
#Detector=	Synapse
#Objective=	x100
#Grating=	600 gr/mm
#ND Filter=	100%
#Laser (nm)=	532
#Hole=	100.021
#Range=	Auto
#Laser Pol.=	No
#Raman. Pol.=	No
#Laser Pol. (°)=	-0.0007625
#Raman Pol. (°)=	89.9995
#Collection=	Microscope
#StageXY=	Marzhauser
#StageZ=	Marzhauser
#X (µm)=	-1007.8
#Y (µm)=	-2957.5
#Z (µm)=	528.15
#Full time(mm:ss)=	3:18
#Project=
#Sample=
#Site=
#Title=	Mb_00_13_11_2x_45s_532 nm_x100_100%_600 gr_mm
#Remark=
#Date=	06.07.2022 10:25
#Acquired=	06.07.2022 10:25:40
#Base:Fit=	10.08.2022 10:16:56
#Base:Sub=	10.08.2022 10:17:24
#Filter:Polynom=	16.08.2022 10:36:38
#AxisType[0]=Intens
#AxisUnit[0]=Cnt
#AxisType[1]=Spectr
#AxisUnit[1]=1/cm
200.398	5.75495
204.027	2.74137
207.657	1.36915
211.283	1.20503
214.909	1.94003
218.533	5.63318
222.157	10.5399
225.777	13.988
229.396	18.2847
233.016	22.2544
236.632	26.4967
240.247	31.1644
243.86	33.5647
247.474	36.491
251.085	38.6748
254.694	41.0916
258.301	41.7108
261.908	43.8747
265.513	44.0155
269.116	43.7016
272.718	42.3264
276.319	39.481
279.918	36.4727
283.516	32.6214
287.113	28.1871
290.708	24.8841
294.302	21.6696
297.894	20.4682
301.485	16.032
305.073	15.5739
308.661	13.8797
312.247	12.4269
315.833	9.93265
319.415	10.1695
322.997	9.96314
326.579	10.3973
330.156	9.11503
333.735	8.3808
337.31	8.28771
340.885	6.39258
344.458	6.13214
348.03	5.18398
351.6	5.36302
355.17	3.63086
358.737	3.25049
362.304	3.38669
365.868	3.3018
369.431	4.4035
372.994	4.65819
376.554	4.90873
380.112	8.05925
383.669	11.8588
387.225	15.4578
390.781	19.7505
394.334	24.4778
397.885	27.6867
401.436	32.0826
404.984	34.6928
408.532	37.2213
412.078	39.1883
415.623	38.7579
419.166	37.8985
422.708	37.658
426.248	35.9238
429.788	33.5033
433.326	29.6738
436.86	24.555
440.395	20.9421
443.929	17.1327
447.461	15.3547
450.99	12.4841
454.52	9.56233
458.048	7.04957
461.573	4.6
465.099	2.63937
468.623	3.44301
472.144	4.22355
475.666	5.69515
479.184	6.63422
482.703	7.44862
486.218	8.64904
489.734	8.6016
493.247	9.67042
496.759	11.5569
500.271	12.2985
503.779	13.4003
507.287	15.0102
510.795	16.681
514.299	16.7335
517.803	17.2381
521.305	18.6739
524.805	21.646
528.307	22.6939
531.805	24.6127
535.301	25.36
538.797	24.3015
542.291	24.1896
545.783	23.0952
549.275	22.2847
552.765	20.3302
556.253	20.8073
559.738	19.2768
563.224	17.6611
566.709	16.3519
570.192	13.5209
573.674	10.7776
577.153	9.48596
580.632	9.59031
584.11	5.98997
587.587	3.44399
591.06	3.73244
594.534	5.11909
598.005	4.40769
601.476	4.16537
604.944	4.60609
608.413	4.79785
611.878	4.95362
615.344	4.10943
618.807	3.74475
622.27	2.94792
625.73	5.17939
629.189	5.82646
632.648	7.0373
636.105	8.39011
639.559	9.26862
643.013	11.704
646.467	12.4761
649.918	13.2784
653.368	14.2291
656.816	13.9616
660.263	15.4932
663.708	15.2208
667.153	15.7839
670.596	14.9348
674.037	15.3434
677.478	17.1224
680.917	16.9855
684.355	17.6797
687.791	16.2874
691.224	16.3131
694.658	14.7521
698.091	14.6928
701.522	16.0212
704.95	16.7147
708.379	18.2102
711.806	18.7519
715.23	20.3483
718.655	22.546
722.078	22.9426
725.498	24.5424
728.919	25.4671
732.337	27.3386
735.755	30.8569
739.17	34.562
742.584	37.4007
745.998	40.3155
749.409	42.0679
752.819	45.7821
756.23	48.9405
759.637	52.1036
763.043	55.6084
766.448	58.2019
769.853	60.5757
773.255	63.8326
776.656	65.9884
780.056	68.8164
783.454	71.9825
786.851	73.5682
790.247	74.3051
793.641	75.0112
797.034	75.4365
800.426	75.7236
803.817	75.3675
807.206	74.2436
810.592	74.4636
813.979	73.9424
817.364	74.4445
820.748	74.6831
824.129	73.7076
827.511	70.9538
830.891	69.9987
834.269	68.1131
837.646	66.7295
841.023	63.8021
844.396	61.2045
847.77	56.4327
851.141	53.8832
854.513	51.7962
857.881	49.8029
861.248	47.2763
864.616	44.5931
867.98	43.3263
871.343	42.55
874.707	41.3486
878.068	42.0071
881.428	39.0258
884.786	39.466
888.143	39.9796
891.498	39.8996
894.855	38.5271
898.208	39.7836
901.56	40.9286
904.91	41.6431
908.26	40.6233
911.608	42.2282
914.955	43.2945
918.298	43.3755
921.643	42.0279
924.986	41.1692
928.328	40.4954
931.668	40.2684
935.006	38.8369
938.344	37.0849
941.681	36.1193
945.014	35.981
948.349	35.638
951.682	36.5603
955.012	35.8078
958.343	35.9274
961.67	34.5339
964.998	34.8583
968.323	36.4518
971.649	37.4822
974.971	38.4065
978.293	41.0678
981.615	41.7678
984.933	42.1051
988.251	43.4115
991.567	43.4667
994.884	43.58
998.198	43.3704
1001.51	42.1787
1004.82	41.4968
1008.13	40.2066
1011.44	38.8409
1014.75	39.2906
1018.06	38.923
1021.36	40.9106
1024.66	44.996
1027.97	48.1528
1031.27	52.1898
1034.57	53.743
1037.87	56.0808
1041.16	56.9812
1044.46	58.0065
1047.76	59.1046
1051.05	60.1681
1054.34	61.7974
1057.63	61.9655
1060.92	61.5656
1064.21	58.3718
1067.5	55.2034
1070.78	50.5825
1074.07	44.9689
1077.35	42.174
1080.63	36.2757
1083.91	31.0692
1087.19	27.5668
1090.47	23.7858
1093.75	19.5952
1097.03	19.1193
1100.3	18.5777
1103.57	20.7537
1106.84	19.3147
1110.11	19.5394
1113.38	18.2565
1116.65	16.6143
1119.92	16.9221
1123.19	16.4874
1126.45	17.2129
1129.71	16.7708
1132.97	18.1846
1136.23	21.1839
1139.49	21.9819
1142.75	21.7298
1146.01	20.5069
1149.26	18.3368
1152.52	18.4039
1155.77	18.3691
1159.02	17.2838
1162.27	15.3066
1165.52	15.2356
1168.77	15.5713
1172.02	16.1841
1175.26	17.9754
1178.51	19.8034
1181.75	19.919
1184.99	18.9306
1188.23	20.8156
1191.47	21.9578
1194.71	22.0729
1197.94	24.3535
1201.18	25.6197
1204.41	26.8759
1207.65	28.3174
1210.88	29.8848
1214.11	33.8545
1217.34	37.3101
1220.57	38.4174
1223.79	39.1967
1227.02	40.483
1230.24	40.8533
1233.47	43.0387
1236.69	44.0245
1239.91	43.5088
1243.13	44.5056
1246.34	44.3485
1249.56	44.4694
1252.78	43.4263
1255.99	41.1317
1259.2	39.6679
1262.42	38.6369
1265.63	39.4277
1268.84	39.0975
1272.04	38.5141
1275.25	40.5081
1278.46	41.8175
1281.66	42.4782
1284.86	43.4403
1288.07	46.7566
1291.27	47.3955
1294.47	49.8489
1297.66	52.2625
1300.86	54.772
1304.06	56.751
1307.25	58.7968
1310.44	61.2251
1313.64	62.8269
1316.83	64.3157
1320.02	65.2532
1323.2	65.2194
1326.39	64.8204
1329.58	64.3875
1332.76	65.6698
1335.95	65.3476
1339.13	67.0249
1342.31	68.9109
1345.49	68.4057
1348.67	69.6685
1351.85	68.5355
1355.02	69.3934
1358.2	69.049
1361.37	69.1413
1364.54	68.6791
1367.71	68.2556
1370.88	65.8802
1374.05	64.5951
1377.22	63.2195
1380.39	62.5554
1383.55	62.2249
1386.72	59.6067
1389.88	57.7474
1393.04	54.7484
1396.2	52.8042
1399.36	50.7389
1402.52	47.5863
1405.68	48.3075
1408.83	49.4507
1411.98	53.051
1415.14	55.1226
1418.29	58.0301
1421.44	60.3961
1424.59	63.4031
1427.74	67.9099
1430.89	71.9902
1434.03	76.1755
1437.18	78.8836
1440.32	81.2715
1443.46	83.2651
1446.6	84.1535
1449.74	82.591
1452.88	81.5797
1456.02	80.8014
1459.16	76.9354
1462.29	73.7526
1465.43	68.3359
1468.56	64.2253
1471.69	59.405
1474.82	55.4324
1477.95	50.8156
1481.08	48.9439
1484.2	46.8032
1487.33	43.697
1490.46	42.4461
1493.58	38.6801
1496.7	36.5991
1499.82	35.4456
1502.94	33.4029
1506.06	32.8131
1509.18	31.5371
1512.29	28.5365
1515.41	28.0486
1518.52	29.0945
1521.63	29.1046
1524.75	29.3357
1527.85	28.7831
1530.96	29.9208
1534.07	30.9146
1537.18	32.5181
1540.28	33.6867
1543.39	34.3859
1546.49	36.645
1549.59	37.8792
1552.69	40.2817
1555.79	42.3785
1558.89	42.6133
1561.99	43.2076
1565.08	44.1736
1568.18	44.8858
1571.27	44.3718
1574.37	45.0527
1577.46	46.9833
1580.55	46.5714
1583.64	47.328
1586.73	47.9655
1589.81	49.8778
1592.9	51.0945
1595.98	51.938
1599.06	50.9301
1602.15	51.0239
1605.23	48.801
1608.31	48.1236
1611.39	47.8144
1614.46	45.655
1617.54	45.6934
1620.61	45.4419
1623.69	44.3582
1626.76	44.5925
1629.83	44.2435
1632.9	43.4953
1635.97	42.5016
1639.04	43.837
1642.11	44.941
1645.17	46.6809
1648.24	49.1203
1651.3	48.9685
1654.36	48.8259
1657.42	49.6199
1660.48	49.1135
1663.54	49.3572
1666.6	48.0853
1669.66	45.4158
1672.71	41.7533
1675.77	39.2519
1678.82	36.8182
1681.87	33.1275
1684.92	29.3718
1687.97	28.2677
1691.02	25.4635
1694.07	23.5017
1697.11	20.0556
1700.16	18.3423
1703.2	17.1252
1706.25	14.4318
1709.29	12.7584
1712.33	13.3634
1715.37	12.5397
1718.41	11.6428
1721.44	10.5539
1724.48	8.65123
1727.51	8.57217
1730.55	8.47
1733.58	6.62441
1736.61	5.86083
1739.64	5.70396
1742.67	5.98768
1745.7	5.30771
1748.72	5.03883
1751.75	4.33804
1754.77	4.04477
1757.8	4.18453
1760.82	4.24678
1763.84	3.49635
1766.86	3.26993
1769.88	3.55704
1772.9	3.24941
1775.91	3.43654
1778.93	2.793
1781.94	2.47367
1784.96	2.62919
1787.97	2.67825
1790.98	1.75264
1793.99	1.58465
1797	1.43878
1800.01	1.40257
1803.01	2.21484
1806.02	1.57696
1809.02	2.73208
1812.02	3.62088
1815.02	3.87919
1818.03	3.81367
1821.02	4.0528
1824.02	3.24827
1827.02	3.14817
1830.02	3.13184
1833.01	3.61832
1836.01	3.0522
1839	4.10208
1841.99	5.4833
1844.98	6.20889
1847.97	6.61831
1850.96	6.32258
1853.95	6.27391
1856.93	5.93993
1859.92	5.74818
1862.9	5.17554
1865.88	6.66101
1868.87	7.60492
1871.85	8.25266
1874.83	8.1943
1877.81	8.56984
1880.78	8.31374
1882.53	8.63582
1885.52	7.88094
1888.51	7.17022
1891.5	6.83895
1894.48	5.64296
1897.47	4.82202
1900.45	4.93547
1903.43	4.9968
1906.41	4.41735
1909.39	4.13856
1912.37	4.56058
1915.35	4.50862
1918.33	4.2814
1921.3	4.232
1924.28	4.14799
1927.25	4.47158
1930.22	4.96631
1933.19	5.34927
1936.16	6.17471
1939.13	6.6319
1942.1	5.77466
1945.07	4.50475
1948.03	4.74427
1951	4.64944
1953.96	4.65158
1956.92	3.32477
1959.88	3.02435
1962.84	1.98034
1965.8	2.42065
1968.76	1.99903
1971.72	1.38885
1974.67	0.378628
1977.63	0.0534491
1980.58	-0.354088
1983.54	-0.0852553
1986.49	0.741032
1989.44	0.866074
1992.39	2.02118
1995.33	2.30474
1998.28	3.32525
2001.23	3.54569
2004.17	4.12655
2007.12	5.15986
2010.06	5.3886
2013	5.73487
2015.94	6.84233
2018.88	6.55738
2021.82	7.12238
2024.76	6.61594
2027.69	6.03005
2030.63	5.53042
2033.56	4.86363
2036.5	5.93722
2039.43	6.05286
2042.36	4.86658
2045.29	4.4498
2048.22	5.22608
2051.15	5.17059
2054.07	4.65949
2057	5.11159
2059.92	5.57959
2062.85	4.95564
2065.77	5.35882
2068.69	5.53781
2071.61	6.33207
2074.53	7.81962
2077.45	7.3808
2080.37	7.48106
2083.28	7.31042
2086.2	6.84221
2089.11	5.77208
2092.02	5.2145
2094.94	5.02168
2097.85	5.38064
2100.76	6.44363
2103.66	6.74382
2106.57	6.82451
2109.48	6.846
2112.38	6.62386
2115.29	6.63574
2118.19	5.57631
2121.09	6.89271
2123.99	6.07126
2126.89	5.97808
2129.79	6.33456
2132.69	6.95061
2135.59	6.75494
2138.48	7.77551
2141.38	8.97021
2144.27	10.0043
2147.17	9.45468
2150.06	9.84952
2152.95	9.26918
2155.84	8.80961
2158.73	9.95292
2161.61	9.33657
2164.5	9.41987
2167.38	9.59149
2170.27	10.4668
2173.15	9.98108
2176.03	8.84494
2178.91	7.72552
2181.8	6.84098
2184.67	6.35113
2187.55	6.09752
2190.43	5.88141
2193.3	5.16841
2196.18	5.77404
2199.05	5.6551
2201.93	5.99456
2204.8	6.59673
2207.67	6.34655
2210.54	7.01005
2213.41	6.83297
2216.27	6.87448
2219.14	6.3303
2222.01	5.58435
2224.87	6.21108
2227.73	6.3938
2230.6	5.92148
2233.46	6.17147
2236.32	7.56259
2239.18	7.87873
2242.03	8.96891
2244.89	9.40865
2247.75	10.0604
2250.6	10.6354
2253.46	11.544
2256.31	12.6298
2259.16	13.1445
2262.01	13.2811
2264.86	13.9741
2267.71	14.4101
2270.56	15.0244
2273.4	14.8659
2276.25	14.809
2279.09	12.4825
2281.94	12.396
2284.78	11.1147
2287.62	9.95104
2290.46	7.9487
2293.3	6.07642
2296.14	6.39161
2298.98	7.05835
2301.82	7.08433
2304.65	7.5985
2307.49	6.79919
2310.32	7.14944
2313.15	7.97281
2315.98	7.20632
2318.81	7.05633
2321.64	5.90435
2324.47	5.00204
2327.3	4.10843
2330.12	3.1182
2332.95	2.93904
2335.77	2.88993
2338.6	2.88366
2341.42	1.46219
2344.24	1.96044
2347.06	2.36987
2349.88	1.42925
2352.7	2.34284
2355.51	1.91375
2358.33	1.89169
2361.14	2.32787
2363.96	3.56683
2366.77	6.65274
2369.58	6.72764
2372.39	7.15548
2375.2	8.29482
2378.01	9.31891
2380.82	9.70041
2383.63	8.83457
2386.43	8.36362
2389.24	7.8312
2392.04	6.14648
2394.84	6.40586
2397.65	6.25399
2400.45	5.04434
2403.25	4.94546
2406.05	4.78705
2408.84	3.09064
2411.64	2.50603
2414.44	3.85531
2417.23	2.54916
2420.02	3.82673
2422.82	4.14873
2425.61	3.90659
2428.4	5.06369
2431.19	5.72631
2433.98	7.09139
2436.77	7.45341
2439.55	7.66445
2442.34	8.20317
2445.12	8.76437
2447.91	8.0306
2450.69	7.38045
2453.47	6.68998
2456.25	7.16142
2459.03	5.15468
2461.81	5.40557
2464.59	5.72849
2467.36	3.38594
2470.14	2.7186
2472.92	2.31752
2475.69	1.23124
2478.46	-0.41964
2481.23	0.930646
2484	0.253386
2486.77	1.33822
2489.54	1.99045
2492.31	0.614373
2495.08	1.90338
2497.84	2.16052
2500.61	2.13958
2503.37	1.73178
2506.13	1.86365
2508.9	2.10145
2511.66	2.38529
2514.42	1.78674
2517.18	1.94158
2519.93	2.23851
2522.69	2.18572
2525.45	1.68515
2528.2	3.12319
2530.95	2.6566
2533.71	2.23739
2536.46	1.51762
2539.21	1.79579
2541.96	2.04542
2544.71	1.88877
2547.46	3.4038
2550.2	3.41942
2552.95	4.12686
2555.7	4.4783
2558.44	3.84401
2561.18	4.32796
2563.93	5.08232
2566.67	6.08549
2569.41	5.46457
2572.15	6.34426
2574.88	6.61218
2577.62	7.14819
2580.36	7.5013
2583.09	7.493
2585.83	8.77354
2588.56	9.22353
2591.29	8.81206
2594.02	9.88164
2596.75	8.90951
2599.48	8.81381
2602.21	9.9909
2604.94	9.64309
2607.67	9.25284
2610.39	10.5678
2613.12	11.6721
2615.84	10.8355
2618.56	10.0073
2621.28	9.67993
2624.01	9.69418
2626.72	9.11045
2629.44	8.23359
2632.16	7.77804
2634.88	7.74229
2637.59	7.25454
2640.31	6.02803
2643.02	5.66569
2645.74	5.65198
2648.45	5.39944
2651.16	6.2718
2653.87	6.06548
2656.58	6.43268
2659.29	6.13305
2661.99	5.96807
2664.7	6.83643
2667.41	7.56097
2670.11	7.94738
2672.81	7.68323
2675.51	6.45532
2678.22	6.98628
2680.92	6.90594
2683.62	6.47957
2686.31	7.80246
2689.01	6.39433
2691.71	5.63508
2694.4	5.31356
2697.1	6.21497
2699.79	6.90261
2702.49	6.12424
2705.18	5.0223
2707.87	4.5912
2710.56	6.36961
2713.25	5.33653
2715.94	6.14686
2718.62	7.72489
2721.31	7.98045
2723.99	7.94133
2726.68	8.79473
2729.36	8.81876
2732.04	8.76312
2734.73	8.004
2737.41	7.96479
2740.08	6.80102
2742.76	6.62131
2745.44	6.10612
2748.12	6.08428
2750.79	5.36182
2753.47	3.61586
2756.14	2.45393
2758.81	2.37565
2761.49	0.955998
2764.16	0.431505
2766.83	-1.15039
2769.5	-2.19074
2772.16	-1.6089
2774.83	-1.64474
2777.5	0.220638
2780.16	1.01968
2782.83	2.14047
2785.49	1.88086
2788.15	2.44093
2790.82	4.61666
2793.48	5.8703
2796.14	5.81214
2798.79	6.61692
2801.45	7.41566
2804.11	8.29838
2806.76	7.58692
2809.42	6.58351
2812.07	6.43802
2814.73	7.296
2817.38	8.34273
2820.03	9.6564
2822.68	12.2173
2825.33	15.1515
2827.98	18.026
2830.63	21.5095
2833.27	26.2262
2835.92	30.932
2838.56	36.9281
2841.21	43.5754
2843.85	50.9163
2846.49	58.4883
2849.13	66.3631
2851.77	75.0996
2854.41	84.2627
2857.05	91.8063
2859.69	98.2738
2862.32	104.131
2864.96	108.642
2867.59	113.731
2870.23	116.643
2872.86	118.95
2875.49	121.616
2878.12	124.336
2880.75	127.588
2883.38	131.323
2886.01	133.941
2888.63	135.934
2891.26	138.846
2893.89	142.792
2896.51	146.516
2899.13	150.478
2901.76	155.531
2904.38	162.291
2907	168.141
2909.62	176.477
2912.24	184.887
2914.85	191.851
2917.47	197.406
2920.09	201.749
2922.7	204.768
2925.32	206.002
2927.93	205.97
2930.54	204.061
2933.15	201.82
2935.76	197.518
2938.37	193.081
2940.98	187.155
2943.59	181.402
2946.2	175.317
2948.8	166.977
2951.41	158.541
2954.01	150.431
2956.62	143.539
2959.22	135.265
2961.82	126.336
2964.42	118.488
2967.02	111.835
2969.62	105.271
2972.22	101.095
2974.81	96.1384
2977.41	90.0361
2980	82.8199
2982.6	76.5051
2985.19	70.5451
2987.78	63.4822
2990.38	56.2712
2992.97	48.677
2995.56	42.3731
2998.14	37.5235
3000.73	33.4941
3003.32	28.731
3005.91	24.4114
3008.49	20.9209
3011.07	17.4633
3013.66	14.9672
3016.24	12.3095
3018.82	8.60706
3021.4	7.22669
3023.98	4.38926
3026.56	3.1457
3029.14	2.39706
3031.71	1.75803
3034.29	2.58406
3036.87	4.13152
3039.44	2.697
3042.01	3.22504
3044.59	3.79501
3047.16	3.85526
3049.73	3.78925
3052.3	4.1654
3054.87	3.76076
3057.43	4.2033
3060	5.59789
3062.57	6.07822
3065.13	6.28779
3067.7	5.89395
3070.26	6.1627
3072.82	7.15823
3075.39	6.06514
3077.95	6.09152
3080.51	4.7528
3083.07	3.57544
3085.63	3.31599
3088.18	2.6435
3090.74	1.85771
3093.29	1.12662
3095.85	1.53253
3098.4	1.88177
3100.95	1.63743
3103.51	1.86978
3106.06	3.73254
3108.61	4.26345
3111.16	5.80182
3113.71	7.37975
3116.25	8.86941
3118.8	9.86624
3121.35	11.3001
3123.89	13.0058
3126.44	13.9425
3128.98	15.9488
3131.52	17.9966
3134.06	20.1718
3136.6	21.9324
3139.14	23.0028
3141.68	23.8299
3144.22	24.2672
3146.76	24.8789
3149.29	24.36