File: data/Raman/poly_smoothed/Mb_00_13_27_1x_45s_532 nm_x100_100%_600 gr_mm_01.txt
#Acq. time (s)=	45
#Accumulations=	2
#Range (cm-¹)=	200...3150
#Windows=	2
#Auto scanning=	Off
#Autofocus=	Off
#Macrospot=	Off
#AutoExposure=	Off
#Spike filter=	Multiple accum.
#Delay time (s)=	0
#Binning=	1
#Readout mode=	Signal
#DeNoise=	Off
#ICS correction=	On
#Dark correction=	Off
#Inst. Process=	Off
#Detector Gain=	Best Dynamic Range
#Detector ADC=	20 kHz
#Detector temperature (°C)=	-69.85
#Instrument=	LabRAM HR Evol
#Detector=	Synapse
#Objective=	x100
#Grating=	600 gr/mm
#ND Filter=	100%
#Laser (nm)=	532
#Hole=	100.021
#Range=	Auto
#Laser Pol.=	No
#Raman. Pol.=	No
#Laser Pol. (°)=	-0.0007625
#Raman Pol. (°)=	89.9995
#Collection=	Microscope
#StageXY=	Marzhauser
#StageZ=	Marzhauser
#X (µm)=	-969.9
#Y (µm)=	-2859.5
#Z (µm)=	528.25
#Full time(mm:ss)=	3:18
#Project=
#Sample=
#Site=
#Title=	Mb_00_13_27_2x_45s_532 nm_x100_100%_600 gr_mm
#Remark=
#Date=	06.07.2022 11:48
#Acquired=	06.07.2022 11:48:06
#Edit:Spike=	06.07.2022 11:55:06
#Base:Fit=	10.08.2022 10:16:56
#Base:Sub=	10.08.2022 10:17:24
#Filter:Polynom=	16.08.2022 10:36:38
#AxisType[0]=Intens
#AxisUnit[0]=Cnt
#AxisType[1]=Spectr
#AxisUnit[1]=1/cm
200.398	48.161
204.027	30.8808
207.657	17.5451
211.283	8.9533
214.909	5.84987
218.533	8.13725
222.157	16.5938
225.777	28.2031
229.396	39.5091
233.016	52.881
236.632	63.9558
240.247	73.9639
243.86	80.5986
247.474	88.3764
251.085	97.1117
254.694	101.699
258.301	105.998
261.908	105.779
265.513	104.635
269.116	100.524
272.718	94.4479
276.319	84.161
279.918	73.7359
283.516	62.9028
287.113	52.6591
290.708	40.9228
294.302	31.6318
297.894	25.71
301.485	22.6518
305.073	20.0266
308.661	19.9408
312.247	20.2064
315.833	21.6717
319.415	21.3648
322.997	22.084
326.579	22.7417
330.156	21.3885
333.735	20.4633
337.31	19.1716
340.885	16.3425
344.458	15.1727
348.03	13.6785
351.6	9.7037
355.17	9.9991
358.737	7.5725
362.304	8.64208
365.868	13.4461
369.431	20.0069
372.994	23.8969
376.554	29.3169
380.112	37.849
383.669	51.3205
387.225	65.3498
390.781	77.4695
394.334	89.7143
397.885	97.5829
401.436	106.428
404.984	112.677
408.532	115.576
412.078	116.166
415.623	115.374
419.166	110.391
422.708	104.297
426.248	95.0562
429.788	88.267
433.326	78.9517
436.86	68.41
440.395	56.153
443.929	45.2197
447.461	36.2036
450.99	29.1016
454.52	20.8742
458.048	13.1699
461.573	9.16176
465.099	7.38512
468.623	8.56843
472.144	11.2807
475.666	12.3278
479.184	13.6341
482.703	16.6226
486.218	20.362
489.734	24.8732
493.247	29.8662
496.759	32.5607
500.271	38.6581
503.779	44.0953
507.287	46.9651
510.795	50.767
514.299	55.9379
517.803	61.1026
521.305	61.7709
524.805	62.7949
528.307	62.9231
531.805	62.5984
535.301	63.1024
538.797	60.5199
542.291	56.503
545.783	53.4885
549.275	49.0772
552.765	42.8551
556.253	35.4777
559.738	30.9583
563.224	26.4484
566.709	23.6354
570.192	19.9794
573.674	16.874
577.153	15.6774
580.632	13.8778
584.11	12.9601
587.587	13.7284
591.06	10.7239
594.534	9.47942
598.005	10.738
601.476	9.25956
604.944	9.8511
608.413	10.8769
611.878	11.2305
615.344	11.2149
618.807	11.991
622.27	10.945
625.73	11.9847
629.189	14.2518
632.648	17.5869
636.105	19.3482
639.559	22.0493
643.013	24.6646
646.467	27.086
649.918	28.2518
653.368	27.2544
656.816	27.3413
660.263	27.7125
663.708	27.732
667.153	27.2277
670.596	23.8533
674.037	20.6361
677.478	18.6889
680.917	16.1232
684.355	14.9423
687.791	13.1028
691.224	12.367
694.658	9.73484
698.091	8.92734
701.522	9.04744
704.95	11.3058
708.379	12.2664
711.806	15.3624
715.23	16.6601
718.655	19.2091
722.078	21.9978
725.498	22.9883
728.919	23.2841
732.337	23.1136
735.755	24.0871
739.17	26.3148
742.584	30.4217
745.998	33.5627
749.409	40.3479
752.819	45.3357
756.23	51.3245
759.637	57.0675
763.043	61.2266
766.448	64.5083
769.853	68.6545
773.255	72.3717
776.656	74.0629
780.056	75.9369
783.454	76.6923
786.851	77.3416
790.247	77.5723
793.641	74.5525
797.034	72.8166
800.426	72.2729
803.817	69.3198
807.206	64.3321
810.592	61.59
813.979	59.4655
817.364	58.8537
820.748	58.2887
824.129	56.9482
827.511	59.9241
830.891	59.6888
834.269	58.7814
837.646	58.9356
841.023	56.1179
844.396	53.1047
847.77	50.3033
851.141	47.9991
854.513	47.3759
857.881	42.3691
861.248	40.0291
864.616	37.8096
867.98	36.6824
871.343	35.2388
874.707	33.7703
878.068	31.9126
881.428	29.2721
884.786	26.5747
888.143	22.7397
891.498	22.1505
894.855	22.5802
898.208	20.4412
901.56	21.4695
904.91	20.2171
908.26	20.7531
911.608	20.6296
914.955	19.5896
918.298	21.3307
921.643	20.7538
924.986	21.0468
928.328	22.1087
931.668	21.9147
935.006	23.4952
938.344	25.1126
941.681	26.1029
945.014	26.6025
948.349	26.0793
951.682	25.8839
955.012	23.6021
958.343	20.4728
961.67	18.2907
964.998	18.6135
968.323	19.3286
971.649	23.4253
974.971	28.5684
978.293	32.6825
981.615	35.746
984.933	38.2549
988.251	41.6813
991.567	45.1265
994.884	47.8697
998.198	52.7356
1001.51	54.7075
1004.82	55.8744
1008.13	57.2877
1011.44	57.4958
1014.75	60.4486
1018.06	65.5981
1021.36	74.0196
1024.66	81.98
1027.97	88.3399
1031.27	94.0081
1034.57	98.308
1037.87	99.5121
1041.16	103.603
1044.46	105.953
1047.76	106.46
1051.05	106.969
1054.34	108.383
1057.63	105.716
1060.92	101.025
1064.21	95.7992
1067.5	91.7478
1070.78	86.0187
1074.07	78.1867
1077.35	70.0344
1080.63	60.3474
1083.91	50.7649
1087.19	39.9845
1090.47	34.9327
1093.75	32.5114
1097.03	35.1757
1100.3	35.9063
1103.57	37.0577
1106.84	35.8531
1110.11	33.3135
1113.38	28.639
1116.65	23.85
1119.92	21.2878
1123.19	17.9495
1126.45	15.9126
1129.71	14.4985
1132.97	13.0279
1136.23	11.3063
1139.49	11.0627
1142.75	12.7399
1146.01	12.5685
1149.26	13.3047
1152.52	12.9799
1155.77	13.008
1159.02	11.3344
1162.27	9.79894
1165.52	8.17585
1168.77	9.85515
1172.02	11.031
1175.26	12.2913
1178.51	14.4302
1181.75	13.4989
1184.99	16.5054
1188.23	18.9203
1191.47	22.3726
1194.71	26.9251
1197.94	33.2359
1201.18	38.7326
1204.41	45.6284
1207.65	50.3173
1210.88	56.8766
1214.11	64.3329
1217.34	71.6451
1220.57	80.7567
1223.79	87.0373
1227.02	92.747
1230.24	97.2373
1233.47	100.396
1236.69	101.917
1239.91	101.464
1243.13	101.388
1246.34	100.796
1249.56	99.695
1252.78	97.9727
1255.99	97.0632
1259.2	95.7696
1262.42	94.9109
1265.63	93.845
1268.84	92.9168
1272.04	93.1267
1275.25	92.0259
1278.46	90.5692
1281.66	91.951
1284.86	94.8919
1288.07	97.3585
1291.27	100.792
1294.47	102.921
1297.66	107.039
1300.86	110.541
1304.06	114.593
1307.25	117.767
1310.44	121.402
1313.64	126.701
1316.83	127.205
1320.02	128.783
1323.2	128.919
1326.39	130.997
1329.58	128.947
1332.76	129.887
1335.95	130.07
1339.13	128.502
1342.31	126.199
1345.49	125.325
1348.67	122.398
1351.85	118.223
1355.02	114.915
1358.2	111.545
1361.37	109.547
1364.54	105.436
1367.71	101.018
1370.88	98.0823
1374.05	95.5566
1377.22	91.3181
1380.39	88.2759
1383.55	85.9799
1386.72	82.7741
1389.88	84.1813
1393.04	81.1897
1396.2	78.798
1399.36	77.5972
1402.52	78.5368
1405.68	80.1893
1408.83	83.3095
1411.98	89.8288
1415.14	96.9988
1418.29	104.612
1421.44	113.852
1424.59	124.157
1427.74	134.026
1430.89	146.643
1434.03	155.247
1437.18	164.94
1440.32	171.153
1443.46	175.057
1446.6	177.956
1449.74	178.869
1452.88	177.926
1456.02	174.326
1459.16	168.044
1462.29	161.035
1465.43	151.889
1468.56	141.551
1471.69	129.688
1474.82	117.841
1477.95	105.381
1481.08	95.2553
1484.2	85.3173
1487.33	76.8057
1490.46	68.5803
1493.58	61.3049
1496.7	55.4749
1499.82	52.5052
1502.94	49.7651
1506.06	47.3664
1509.18	44.5392
1512.29	43.7855
1515.41	43.5243
1518.52	44.3247
1521.63	44.7615
1524.75	45.3005
1527.85	47.5302
1530.96	48.6231
1534.07	47.7112
1537.18	48.2015
1540.28	49.4935
1543.39	53.9005
1546.49	56.3559
1549.59	58.3956
1552.69	60.2791
1555.79	62.329
1558.89	65.8734
1561.99	67.1335
1565.08	68.6569
1568.18	70.9904
1571.27	73.3471
1574.37	77.0038
1577.46	78.9851
1580.55	82.1863
1583.64	86.4418
1586.73	91.2248
1589.81	93.8102
1592.9	95.4732
1595.98	96.7202
1599.06	94.8901
1602.15	94.0653
1605.23	92.7735
1608.31	92.3591
1611.39	88.9834
1614.46	88.6141
1617.54	90.8988
1620.61	93.0674
1623.69	93.3979
1626.76	93.0443
1629.83	94.4782
1632.9	98.3896
1635.97	101.063
1639.04	103.666
1642.11	108.681
1645.17	111.866
1648.24	116.339
1651.3	119.116
1654.36	120.952
1657.42	122.195
1660.48	120.82
1663.54	116.404
1666.6	112.159
1669.66	106.229
1672.71	98.8476
1675.77	90.3997
1678.82	82.8323
1681.87	73.4174
1684.92	63.7383
1687.97	56.2089
1691.02	50.4423
1694.07	44.1055
1697.11	36.0566
1700.16	28.5907
1703.2	23.8615
1706.25	19.6961
1709.29	17.513
1712.33	14.6806
1715.37	11.2548
1718.41	9.89482
1721.44	9.83871
1724.48	9.40503
1727.51	6.77271
1730.55	6.30315
1733.58	4.93985
1736.61	3.97663
1739.64	3.8335
1742.67	4.20204
1745.7	3.53038
1748.72	4.34413
1751.75	4.2745
1754.77	3.15387
1757.8	3.38293
1760.82	4.32667
1763.84	4.37257
1766.86	4.12401
1769.88	4.24347
1772.9	3.88443
1775.91	5.23629
1778.93	3.94086
1781.94	3.54595
1784.96	4.2917
1787.97	2.3352
1790.98	2.97019
1793.99	2.48188
1797	1.65232
1800.01	0.865265
1803.01	0.156272
1806.02	-0.48408
1809.02	-0.410354
1812.02	-0.23055
1815.02	0.61329
1818.03	1.53302
1821.02	1.95156
1824.02	1.88154
1827.02	2.11046
1830.02	2.07776
1833.01	2.77855
1836.01	2.36333
1839	4.02132
1841.99	3.7574
1844.98	3.02947
1847.97	3.69449
1850.96	4.50652
1853.95	5.12199
1856.93	7.20189
1859.92	7.63321
1862.9	7.70452
1865.88	8.17639
1868.87	7.87258
1871.85	8.34975
1874.83	7.0102
1877.81	6.85423
1880.78	8.26964
1882.53	8.80989
1885.52	9.08763
1888.51	10.0736
1891.5	8.63986
1894.48	8.64587
1897.47	8.28392
1900.45	7.108
1903.43	7.01507
1906.41	5.58438
1909.39	6.40885
1912.37	5.20158
1915.35	6.2667
1918.33	8.05028
1921.3	7.4639
1924.28	8.14266
1927.25	7.3758
1930.22	7.90857
1933.19	7.86493
1936.16	6.36122
1939.13	6.90222
1942.1	6.31258
1945.07	5.66562
1948.03	5.29989
1951	5.24317
1953.96	5.01953
1956.92	4.87835
1959.88	4.44894
1962.84	4.01927
1965.8	2.42743
1968.76	2.79361
1971.72	2.99031
1974.67	3.37856
1977.63	2.80693
1980.58	2.9725
1983.54	4.08498
1986.49	5.8828
1989.44	6.66206
1992.39	6.50097
1995.33	7.07705
1998.28	5.93994
2001.23	7.1781
2004.17	7.0978
2007.12	7.13381
2010.06	7.66323
2013	9.25454
2015.94	8.91702
2018.88	8.61678
2021.82	9.24214
2024.76	10.1354
2027.69	10.9675
2030.63	10.7762
2033.56	12.4475
2036.5	12.7144
2039.43	12.7396
2042.36	12.8105
2045.29	12.9839
2048.22	11.8474
2051.15	9.98378
2054.07	11.4365
2057	11.681
2059.92	11.2188
2062.85	10.3364
2065.77	8.51708
2068.69	6.8641
2071.61	5.63006
2074.53	3.24184
2077.45	1.84925
2080.37	2.56165
2083.28	3.01708
2086.2	2.16108
2089.11	2.3866
2092.02	2.46507
2094.94	3.64507
2097.85	4.12184
2100.76	3.83192
2103.66	4.53727
2106.57	5.70795
2109.48	5.53621
2112.38	5.07141
2115.29	5.43106
2118.19	6.55222
2121.09	5.082
2123.99	5.9522
2126.89	6.40027
2129.79	7.03827
2132.69	6.28716
2135.59	6.64353
2138.48	6.8147
2141.38	6.71182
2144.27	6.23795
2147.17	6.24764
2150.06	7.13019
2152.95	7.28491
2155.84	7.54821
2158.73	7.83879
2161.61	8.64277
2164.5	7.11357
2167.38	7.25354
2170.27	7.28749
2173.15	7.55749
2176.03	8.48545
2178.91	7.62917
2181.8	7.95189
2184.67	7.98
2187.55	7.07702
2190.43	6.62879
2193.3	5.90727
2196.18	7.46466
2199.05	7.43527
2201.93	6.60859
2204.8	6.26651
2207.67	6.37629
2210.54	5.7445
2213.41	4.03981
2216.27	3.85683
2219.14	3.15737
2222.01	4.34003
2224.87	4.65635
2227.73	6.24573
2230.6	5.35832
2233.46	5.80688
2236.32	6.57207
2239.18	8.57953
2242.03	8.52877
2244.89	9.34632
2247.75	10.636
2250.6	12.2464
2253.46	13.6423
2256.31	13.1755
2259.16	13.6382
2262.01	14.4874
2264.86	14.5868
2267.71	14.0449
2270.56	13.8973
2273.4	12.6077
2276.25	10.8305
2279.09	10.4374
2281.94	9.80448
2284.78	9.36421
2287.62	8.63663
2290.46	7.71829
2293.3	6.25463
2296.14	5.94138
2298.98	3.82797
2301.82	3.60002
2304.65	4.13345
2307.49	4.93156
2310.32	5.52855
2313.15	6.10309
2315.98	7.26622
2318.81	9.02524
2321.64	7.85321
2324.47	7.11375
2327.3	6.81426
2330.12	8.14808
2332.95	7.69473
2335.77	6.3619
2338.6	4.9693
2341.42	5.00006
2344.24	4.31643
2347.06	3.08218
2349.88	1.88743
2352.7	2.51268
2355.51	-0.377374
2358.33	-1.95955
2361.14	-1.79161
2363.96	-0.729476
2366.77	-1.12455
2369.58	-0.251537
2372.39	0.539917
2375.2	1.10391
2378.01	1.78268
2380.82	3.19845
2383.63	3.04882
2386.43	4.02642
2389.24	3.65514
2392.04	2.90149
2394.84	4.08766
2397.65	3.85024
2400.45	3.94793
2403.25	2.53475
2406.05	2.85143
2408.84	3.24251
2411.64	3.52728
2414.44	3.02376
2417.23	3.21531
2420.02	5.52901
2422.82	6.57488
2425.61	5.87353
2428.4	6.17842
2431.19	6.65219
2433.98	7.75695
2436.77	6.56446
2439.55	7.19365
2442.34	6.89198
2445.12	7.6732
2447.91	7.30699
2450.69	7.98743
2453.47	8.77303
2456.25	9.11892
2459.03	8.53256
2461.81	7.91981
2464.59	8.31179
2467.36	7.86836
2470.14	6.66048
2472.92	7.25111
2475.69	6.57713
2478.46	7.98208
2481.23	8.26628
2484	8.72066
2486.77	9.28
2489.54	9.21891
2492.31	7.4226
2495.08	6.25531
2497.84	6.87574
2500.61	5.96795
2503.37	4.56794
2506.13	5.65938
2508.9	6.45686
2511.66	7.70944
2514.42	8.45491
2517.18	8.09713
2519.93	9.39624
2522.69	9.58111
2525.45	10.3101
2528.2	10.7073
2530.95	11.7996
2533.71	12.1271
2536.46	11.8288
2539.21	11.8768
2541.96	11.1625
2544.71	11.4459
2547.46	13.265
2550.2	12.8587
2552.95	11.9548
2555.7	11.6765
2558.44	10.5034
2561.18	11.4255
2563.93	11.0049
2566.67	11.3484
2569.41	9.87753
2572.15	9.85878
2574.88	10.4625
2577.62	10.74
2580.36	10.5484
2583.09	7.72314
2585.83	7.85316
2588.56	7.0215
2591.29	7.4321
2594.02	7.02226
2596.75	5.88467
2599.48	4.54897
2602.21	3.16276
2604.94	2.83702
2607.67	1.93964
2610.39	2.18517
2613.12	3.84308
2615.84	4.38867
2618.56	3.82105
2621.28	4.81726
2624.01	5.24138
2626.72	7.07402
2629.44	8.27029
2632.16	9.71686
2634.88	11.7757
2637.59	12.5961
2640.31	13.5374
2643.02	15.6854
2645.74	14.5522
2648.45	14.0737
2651.16	13.4674
2653.87	13.8805
2656.58	13.4424
2659.29	13.6904
2661.99	12.0983
2664.7	11.9075
2667.41	10.4511
2670.11	9.53756
2672.81	8.57522
2675.51	7.59352
2678.22	7.50208
2680.92	7.54644
2683.62	7.76484
2686.31	7.80607
2689.01	7.93228
2691.71	8.24985
2694.4	9.33729
2697.1	11.3418
2699.79	11.2516
2702.49	14.3871
2705.18	14.7088
2707.87	16.5494
2710.56	19.6447
2713.25	21.84
2715.94	23.8274
2718.62	26.1693
2721.31	27.5983
2723.99	28.2127
2726.68	27.9937
2729.36	27.9134
2732.04	26.4361
2734.73	25.1261
2737.41	24.3736
2740.08	23.8631
2742.76	22.8268
2745.44	22.4955
2748.12	20.7576
2750.79	19.7361
2753.47	17.1789
2756.14	15.7842
2758.81	14.5653
2761.49	13.1991
2764.16	12.4362
2766.83	11.9479
2769.5	11.6695
2772.16	11.251
2774.83	11.0878
2777.5	10.4268
2780.16	9.60442
2782.83	9.393
2785.49	7.77041
2788.15	5.74265
2790.82	3.97131
2793.48	2.69597
2796.14	1.43712
2798.79	-0.244746
2801.45	-1.62362
2804.11	-2.22669
2806.76	-2.68467
2809.42	-3.34129
2812.07	-3.45851
2814.73	-2.81818
2817.38	-1.44034
2820.03	2.1121
2822.68	6.92466
2825.33	13.537
2827.98	20.6787
2830.63	27.723
2833.27	36.4825
2835.92	46.7767
2838.56	59.2779
2841.21	71.9237
2843.85	87.5647
2846.49	103.876
2849.13	121.316
2851.77	139.017
2854.41	156.985
2857.05	174.689
2859.69	190.309
2862.32	205.665
2864.96	220.357
2867.59	232.699
2870.23	243.904
2872.86	253.209
2875.49	262.887
2878.12	269.496
2880.75	276.672
2883.38	284.118
2886.01	289.345
2888.63	293.049
2891.26	298.026
2893.89	303.493
2896.51	310.408
2899.13	319.589
2901.76	331.858
2904.38	343.554
2907	357.451
2909.62	373.165
2912.24	389.281
2914.85	405.797
2917.47	420.772
2920.09	433.423
2922.7	442.905
2925.32	449.819
2927.93	453.619
2930.54	454.349
2933.15	451.555
2935.76	445.14
2938.37	437.854
2940.98	427.391
2943.59	414.804
2946.2	400.131
2948.8	383.962
2951.41	367.339
2954.01	350.581
2956.62	334.792
2959.22	319.227
2961.82	302.915
2964.42	287.824
2967.02	273.678
2969.62	259.687
2972.22	246.131
2974.81	231.558
2977.41	219.252
2980	205.226
2982.6	189.202
2985.19	173.537
2987.78	156.238
2990.38	141.055
2992.97	125.239
2995.56	111.723
2998.14	97.2191
3000.73	83.4167
3003.32	71.345
3005.91	58.7741
3008.49	48.4583
3011.07	39.1857
3013.66	32.1031
3016.24	25.6191
3018.82	18.3268
3021.4	13.883
3023.98	8.56232
3026.56	4.57677
3029.14	3.8036
3031.71	2.60469
3034.29	1.7111
3036.87	0.691963
3039.44	2.428
3042.01	4.15231
3044.59	5.82108
3047.16	6.66979
3049.73	8.77644
3052.3	9.56502
3054.87	11.8694
3057.43	12.6816
3060	12.8387
3062.57	12.5546
3065.13	12.1174
3067.7	11.6307
3070.26	11.2718
3072.82	10.8014
3075.39	7.52781
3077.95	6.41488
3080.51	4.87613
3083.07	2.53185
3085.63	2.56812
3088.18	1.97775
3090.74	1.62569
3093.29	2.06454
3095.85	2.47066
3098.4	3.08323
3100.95	5.50045
3103.51	7.45599
3106.06	8.46739
3108.61	10.522
3111.16	12.8772
3113.71	15.1766
3116.25	16.5742
3118.8	19.6355
3121.35	21.8414
3123.89	24.629
3126.44	27.9468
3128.98	31.0373
3131.52	32.766
3134.06	35.6084
3136.6	38.1033
3139.14	42.8111
3141.68	46.4701
3144.22	51.905
3146.76	58.3587
3149.29	61.5986