File: data/Raman/poly_smoothed/Mb_00_13_41_1x_45s_532 nm_x100_100%_600 gr_mm_01.txt
#Acq. time (s)=	45
#Accumulations=	2
#Range (cm-¹)=	200...3150
#Windows=	2
#Auto scanning=	Off
#Autofocus=	Off
#Macrospot=	Off
#AutoExposure=	Off
#Spike filter=	Multiple accum.
#Delay time (s)=	0
#Binning=	1
#Readout mode=	Signal
#DeNoise=	Off
#ICS correction=	On
#Dark correction=	Off
#Inst. Process=	Off
#Detector Gain=	Best Dynamic Range
#Detector ADC=	20 kHz
#Detector temperature (°C)=	-69.85
#Instrument=	LabRAM HR Evol
#Detector=	Synapse
#Objective=	x100
#Grating=	600 gr/mm
#ND Filter=	100%
#Laser (nm)=	532
#Hole=	100.021
#Range=	Auto
#Laser Pol.=	No
#Raman. Pol.=	No
#Laser Pol. (°)=	-0.0007625
#Raman Pol. (°)=	89.9995
#Collection=	Microscope
#StageXY=	Marzhauser
#StageZ=	Marzhauser
#X (µm)=	-1038.3
#Y (µm)=	-2880.1
#Z (µm)=	528.8
#Full time(mm:ss)=	3:18
#Project=
#Sample=
#Site=
#Title=	Mb_00_13_41_2x_45s_532 nm_x100_100%_600 gr_mm
#Remark=
#Date=	06.07.2022 13:01
#Acquired=	06.07.2022 13:01:15
#Base:Fit=	10.08.2022 10:16:56
#Base:Sub=	10.08.2022 10:17:24
#Filter:Polynom=	16.08.2022 10:36:38
#AxisType[0]=Intens
#AxisUnit[0]=Cnt
#AxisType[1]=Spectr
#AxisUnit[1]=1/cm
200.398	24.1018
204.027	13.5363
207.657	3.55274
211.283	-2.14757
214.909	-1.3213
218.533	6.10808
222.157	20.7196
225.777	36.9125
229.396	54.3091
233.016	72.8515
236.632	89.479
240.247	102.464
243.86	114.53
247.474	124.741
251.085	135.163
254.694	143.127
258.301	147.768
261.908	151.361
265.513	148.712
269.116	144.499
272.718	135.712
276.319	126.714
279.918	112.298
283.516	98.4243
287.113	84.277
290.708	68.7291
294.302	54.5735
297.894	45.0215
301.485	37.4365
305.073	30.4667
308.661	25.9903
312.247	23.1388
315.833	21.3563
319.415	20.3468
322.997	20.5049
326.579	17.9671
330.156	17.2039
333.735	15.1605
337.31	12.5375
340.885	10.8651
344.458	8.25238
348.03	4.77918
351.6	3.35298
355.17	1.09076
358.737	-1.94054
362.304	-0.00975711
365.868	4.96945
369.431	11.3765
372.994	19.8917
376.554	28.1755
380.112	38.3267
383.669	53.7194
387.225	71.7061
390.781	88.5668
394.334	106.746
397.885	121.996
401.436	134.268
404.984	145.669
408.532	151.556
412.078	155.771
415.623	155.361
419.166	151.333
422.708	145.936
426.248	137.049
429.788	124.75
433.326	111.017
436.86	94.974
440.395	78.9628
443.929	63.3542
447.461	50.1432
450.99	38.5752
454.52	28.0612
458.048	18.6492
461.573	11.7739
465.099	6.81434
468.623	8.56624
472.144	13.1843
475.666	15.7299
479.184	17.8312
482.703	22.0566
486.218	23.8351
489.734	27.5364
493.247	32.4696
496.759	35.9652
500.271	38.6915
503.779	41.6732
507.287	46.7246
510.795	51.9898
514.299	55.3771
517.803	58.8055
521.305	59.9237
524.805	58.7436
528.307	59.11
531.805	59.2945
535.301	57.7622
538.797	56.3801
542.291	53.4297
545.783	50.3729
549.275	46.3206
552.765	42.6501
556.253	39.2868
559.738	36.3845
563.224	31.7055
566.709	29.2951
570.192	26.0662
573.674	22.8315
577.153	19.2105
580.632	15.566
584.11	12.7435
587.587	11.1485
591.06	11.7392
594.534	11.1168
598.005	10.6776
601.476	10.1316
604.944	10.2396
608.413	9.37014
611.878	9.14424
615.344	10.689
618.807	10.4396
622.27	11.8394
625.73	14.9921
629.189	17.8495
632.648	20.9713
636.105	24.644
639.559	28.2216
643.013	31.7446
646.467	35.7633
649.918	37.6051
653.368	39.1747
656.816	39.8635
660.263	37.6966
663.708	38.1508
667.153	38.2297
670.596	36.7657
674.037	33.9754
677.478	33.6429
680.917	31.8521
684.355	28.9294
687.791	25.7636
691.224	23.643
694.658	17.9021
698.091	16.3824
701.522	15.3822
704.95	14.7548
708.379	16.4807
711.806	15.9589
715.23	19.3153
718.655	19.6368
722.078	19.7822
725.498	22.0018
728.919	24.6471
732.337	26.7508
735.755	27.5424
739.17	28.8876
742.584	31.0251
745.998	33.3923
749.409	38.8907
752.819	40.8658
756.23	43.5118
759.637	45.5433
763.043	50.1872
766.448	52.1301
769.853	54.6347
773.255	57.4601
776.656	59.289
780.056	61.4402
783.454	63.937
786.851	63.6753
790.247	64.2959
793.641	65.3336
797.034	65.9565
800.426	66.2504
803.817	65.2376
807.206	66.1499
810.592	64.2625
813.979	62.21
817.364	61.641
820.748	61.7992
824.129	61.2838
827.511	61.3396
830.891	61.9624
834.269	62.1325
837.646	59.8456
841.023	58.8897
844.396	56.1959
847.77	55.6472
851.141	51.5445
854.513	49.8785
857.881	45.4597
861.248	43.1564
864.616	39.3822
867.98	36.9503
871.343	34.1278
874.707	31.6264
878.068	30.2976
881.428	28.9262
884.786	27.058
888.143	24.8457
891.498	22.577
894.855	21.589
898.208	21.0556
901.56	19.4584
904.91	20.9338
908.26	20.9536
911.608	20.9274
914.955	20.3918
918.298	20.3717
921.643	20.2667
924.986	19.2035
928.328	18.1087
931.668	18.8522
935.006	17.744
938.344	17.121
941.681	16.5112
945.014	15.6573
948.349	15.1413
951.682	15.4391
955.012	12.0292
958.343	10.3662
961.67	9.12194
964.998	10.8307
968.323	12.0648
971.649	14.13
974.971	16.968
978.293	19.2618
981.615	22.8187
984.933	28.5156
988.251	32.1085
991.567	36.5935
994.884	41.212
998.198	42.7773
1001.51	45.3644
1004.82	46.2536
1008.13	45.4321
1011.44	44.6166
1014.75	44.7725
1018.06	47.5853
1021.36	55.8794
1024.66	67.7512
1027.97	80.1128
1031.27	92.4359
1034.57	101.986
1037.87	108.399
1041.16	114.52
1044.46	119.83
1047.76	125.572
1051.05	125.717
1054.34	124.63
1057.63	120.208
1060.92	117.534
1064.21	112.071
1067.5	104.6
1070.78	94.6553
1074.07	83.0425
1077.35	68.6012
1080.63	53.678
1083.91	39.3857
1087.19	24.4127
1090.47	12.8508
1093.75	7.58269
1097.03	4.89306
1100.3	6.38993
1103.57	9.53778
1106.84	11.9373
1110.11	12.5674
1113.38	11.5394
1116.65	10.9118
1119.92	9.30627
1123.19	8.60947
1126.45	8.3981
1129.71	5.73055
1132.97	6.41393
1136.23	6.62386
1139.49	9.12944
1142.75	9.53206
1146.01	8.31326
1149.26	7.79955
1152.52	7.93078
1155.77	8.74288
1159.02	8.16762
1162.27	8.7037
1165.52	9.01598
1168.77	9.34096
1172.02	12.4387
1175.26	11.7434
1178.51	11.2991
1181.75	11.1687
1184.99	13.4906
1188.23	14.4558
1191.47	15.6821
1194.71	17.3007
1197.94	17.6954
1201.18	20.2837
1204.41	23.442
1207.65	26.6242
1210.88	32.4896
1214.11	38.7879
1217.34	43.9824
1220.57	48.7318
1223.79	54.3101
1227.02	59.4329
1230.24	63.9354
1233.47	68.1213
1236.69	71.7631
1239.91	74.1956
1243.13	77.4009
1246.34	78.9404
1249.56	80.8183
1252.78	81.1233
1255.99	80.0261
1259.2	80.6208
1262.42	78.0406
1265.63	77.0523
1268.84	73.7533
1272.04	71.3921
1275.25	68.8833
1278.46	67.7129
1281.66	69.4067
1284.86	70.6212
1288.07	72.4848
1291.27	74.4512
1294.47	76.9432
1297.66	81.5389
1300.86	84.5997
1304.06	87.9689
1307.25	92.5066
1310.44	95.7685
1313.64	99.5461
1316.83	101.6
1320.02	102.774
1323.2	103.995
1326.39	103.577
1329.58	102.861
1332.76	101.19
1335.95	99.1645
1339.13	96.7434
1342.31	93.6022
1345.49	90.3313
1348.67	86.9423
1351.85	82.1011
1355.02	78.3241
1358.2	76.0607
1361.37	74.8115
1364.54	70.4119
1367.71	67.9209
1370.88	65.8079
1374.05	64.2115
1377.22	62.7632
1380.39	60.4975
1383.55	58.8462
1386.72	59.9777
1389.88	58.506
1393.04	58.1712
1396.2	58.271
1399.36	57.8738
1402.52	60.7076
1405.68	61.5934
1408.83	66.8782
1411.98	73.6268
1415.14	79.8667
1418.29	88.1004
1421.44	96.4148
1424.59	104.868
1427.74	114.931
1430.89	126.534
1434.03	135.135
1437.18	145.979
1440.32	153.316
1443.46	158.229
1446.6	163.043
1449.74	163.844
1452.88	162.5
1456.02	160.706
1459.16	156.273
1462.29	152.929
1465.43	145.831
1468.56	138.07
1471.69	130.116
1474.82	119.287
1477.95	108.983
1481.08	99.7423
1484.2	91.3757
1487.33	85.0904
1490.46	75.3898
1493.58	67.4078
1496.7	60.8052
1499.82	55.5231
1502.94	50.1795
1506.06	47.1427
1509.18	44.2266
1512.29	41.5637
1515.41	39.6399
1518.52	37.4295
1521.63	36.2167
1524.75	34.2034
1527.85	34.2422
1530.96	34.2744
1534.07	35.3634
1537.18	36.8045
1540.28	40.2792
1543.39	42.6181
1546.49	45.9897
1549.59	48.0535
1552.69	49.1731
1555.79	52.7581
1558.89	55.5715
1561.99	59.1727
1565.08	61.4087
1568.18	64.1389
1571.27	67.7981
1574.37	72.5504
1577.46	75.9014
1580.55	80.1717
1583.64	83.666
1586.73	84.8122
1589.81	87.588
1592.9	90.3327
1595.98	91.9355
1599.06	91.3888
1602.15	90.1321
1605.23	88.6446
1608.31	86.2717
1611.39	84.6368
1614.46	82.0963
1617.54	78.8443
1620.61	74.3202
1623.69	71.6703
1626.76	70.6527
1629.83	68.104
1632.9	68.8481
1635.97	70.1543
1639.04	71.4202
1642.11	72.8872
1645.17	74.2019
1648.24	75.7609
1651.3	78.215
1654.36	79.0483
1657.42	79.4846
1660.48	77.7557
1663.54	77.4827
1666.6	76.5161
1669.66	74.7335
1672.71	70.9923
1675.77	66.0981
1678.82	62.0716
1681.87	56.6865
1684.92	49.6583
1687.97	43.0891
1691.02	37.3162
1694.07	32.5657
1697.11	28.8405
1700.16	25.4825
1703.2	21.7798
1706.25	18.8708
1709.29	15.8061
1712.33	14.2291
1715.37	11.7759
1718.41	11.7056
1721.44	10.7598
1724.48	10.5159
1727.51	10.5885
1730.55	10.0933
1733.58	8.83197
1736.61	9.74501
1739.64	10.6282
1742.67	10.6331
1745.7	11.125
1748.72	10.6537
1751.75	9.90941
1754.77	9.04583
1757.8	8.45125
1760.82	7.07292
1763.84	7.29027
1766.86	5.80394
1769.88	5.55714
1772.9	3.77459
1775.91	2.90603
1778.93	1.48791
1781.94	1.33485
1784.96	1.01272
1787.97	2.12485
1790.98	2.84403
1793.99	3.66688
1797	3.61198
1800.01	3.6233
1803.01	4.34405
1806.02	3.82999
1809.02	4.96583
1812.02	5.0415
1815.02	4.92369
1818.03	4.06294
1821.02	4.67327
1824.02	4.547
1827.02	3.61575
1830.02	3.6319
1833.01	3.64007
1836.01	2.84227
1839	2.52386
1841.99	1.50091
1844.98	0.333068
1847.97	-0.381034
1850.96	-0.668613
1853.95	-2.14628
1856.93	-0.061164
1859.92	-0.121899
1862.9	1.02308
1865.88	1.52196
1868.87	2.29114
1871.85	1.55805
1874.83	1.99938
1877.81	2.65834
1880.78	2.28379
1882.53	3.28806
1885.52	1.95332
1888.51	2.15685
1891.5	2.06788
1894.48	4.14542
1897.47	3.86983
1900.45	4.73226
1903.43	5.96508
1906.41	5.66151
1909.39	5.65328
1912.37	4.59974
1915.35	4.53931
1918.33	3.98446
1921.3	3.33948
1924.28	2.97495
1927.25	3.98244
1930.22	3.44828
1933.19	2.6834
1936.16	2.30116
1939.13	2.22474
1942.1	0.99285
1945.07	1.55762
1948.03	1.21949
1951	0.219616
1953.96	-0.00906391
1956.92	0.255601
1959.88	-0.385304
1962.84	0.387257
1965.8	1.39204
1968.76	1.46439
1971.72	1.24335
1974.67	1.10051
1977.63	1.58359
1980.58	1.92289
1983.54	1.59583
1986.49	1.30492
1989.44	3.35069
1992.39	3.78055
1995.33	3.91424
1998.28	5.31465
2001.23	6.55516
2004.17	6.60786
2007.12	7.67373
2010.06	8.92517
2013	8.95454
2015.94	10.5396
2018.88	10.4082
2021.82	10.3519
2024.76	11.3549
2027.69	10.6805
2030.63	10.6185
2033.56	10.3598
2036.5	11.2536
2039.43	9.85948
2042.36	8.03687
2045.29	7.38685
2048.22	6.44585
2051.15	7.62618
2054.07	5.79876
2057	5.59231
2059.92	6.65087
2062.85	7.29206
2065.77	6.76672
2068.69	6.93235
2071.61	6.29915
2074.53	6.23889
2077.45	7.26751
2080.37	8.00462
2083.28	7.28656
2086.2	7.39118
2089.11	7.18686
2092.02	7.80529
2094.94	7.77408
2097.85	7.36622
2100.76	8.46397
2103.66	7.68766
2106.57	7.23062
2109.48	6.54346
2112.38	5.6139
2115.29	6.20203
2118.19	6.62641
2121.09	6.15651
2123.99	6.22116
2126.89	4.60383
2129.79	5.13166
2132.69	6.09408
2135.59	4.58995
2138.48	3.81655
2141.38	5.09713
2144.27	4.98188
2147.17	7.19641
2150.06	7.64665
2152.95	6.60303
2155.84	6.41091
2158.73	6.47833
2161.61	7.66001
2164.5	7.53272
2167.38	7.96092
2170.27	7.14593
2173.15	4.81946
2176.03	5.19249
2178.91	5.21448
2181.8	4.67746
2184.67	5.16982
2187.55	5.11075
2190.43	4.22211
2193.3	2.92237
2196.18	3.33305
2199.05	3.26412
2201.93	3.66257
2204.8	2.54827
2207.67	2.67331
2210.54	3.29077
2213.41	5.12934
2216.27	5.79492
2219.14	5.28126
2222.01	5.29399
2224.87	5.08855
2227.73	6.5566
2230.6	6.30013
2233.46	6.25463
2236.32	7.66783
2239.18	7.79284
2242.03	7.31934
2244.89	7.54785
2247.75	9.97848
2250.6	9.41799
2253.46	9.20017
2256.31	10.0742
2259.16	9.50213
2262.01	10.307
2264.86	11.0042
2267.71	10.2113
2270.56	9.36861
2273.4	8.80993
2276.25	8.95004
2279.09	9.34877
2281.94	8.95742
2284.78	7.89352
2287.62	7.63725
2290.46	8.12175
2293.3	5.73886
2296.14	5.67663
2298.98	6.40798
2301.82	7.42898
2304.65	9.12667
2307.49	8.76213
2310.32	8.99728
2313.15	9.45409
2315.98	9.17373
2318.81	8.29415
2321.64	7.61123
2324.47	8.89064
2327.3	7.49447
2330.12	8.05642
2332.95	8.41041
2335.77	6.31631
2338.6	6.34639
2341.42	4.01422
2344.24	4.5016
2347.06	3.91208
2349.88	2.37407
2352.7	1.62841
2355.51	0.994465
2358.33	0.825406
2361.14	0.0108424
2363.96	-0.453268
2366.77	0.529137
2369.58	0.529645
2372.39	0.591165
2375.2	-0.0128323
2378.01	1.94596
2380.82	1.9052
2383.63	-0.21315
2386.43	0.162737
2389.24	0.950637
2392.04	1.43846
2394.84	1.64142
2397.65	2.54229
2400.45	2.31815
2403.25	2.06179
2406.05	2.20598
2408.84	2.85728
2411.64	3.20307
2414.44	3.83919
2417.23	3.84982
2420.02	4.30129
2422.82	4.76962
2425.61	5.38019
2428.4	5.91064
2431.19	6.49282
2433.98	6.18437
2436.77	6.55152
2439.55	7.18235
2442.34	7.21757
2445.12	7.35133
2447.91	8.6168
2450.69	7.96728
2453.47	6.5479
2456.25	8.62401
2459.03	8.75718
2461.81	9.34385
2464.59	8.73208
2467.36	7.86142
2470.14	6.8856
2472.92	7.53121
2475.69	7.37931
2478.46	7.25992
2481.23	7.35406
2484	7.34439
2486.77	7.30765
2489.54	6.68975
2492.31	6.63109
2495.08	6.11612
2497.84	6.09485
2500.61	6.42363
2503.37	5.58782
2506.13	5.0592
2508.9	6.2866
2511.66	6.39757
2514.42	7.09959
2517.18	8.23001
2519.93	9.35151
2522.69	10.7659
2525.45	12.142
2528.2	12.85
2530.95	12.0731
2533.71	10.9622
2536.46	10.8681
2539.21	10.4824
2541.96	10.31
2544.71	9.45547
2547.46	9.34246
2550.2	9.11105
2552.95	8.02734
2555.7	7.52699
2558.44	6.64089
2561.18	6.94615
2563.93	7.04299
2566.67	7.37023
2569.41	8.63809
2572.15	8.77874
2574.88	9.77275
2577.62	10.261
2580.36	10.1682
2583.09	10.9252
2585.83	12.6844
2588.56	11.5582
2591.29	10.7397
2594.02	9.08781
2596.75	8.20372
2599.48	5.80003
2602.21	4.59698
2604.94	2.83398
2607.67	2.19998
2610.39	1.68482
2613.12	1.01915
2615.84	1.96163
2618.56	2.36031
2621.28	4.41485
2624.01	4.68931
2626.72	6.66664
2629.44	8.33691
2632.16	10.8587
2634.88	12.2764
2637.59	13.0559
2640.31	13.941
2643.02	14.1849
2645.74	13.6355
2648.45	13.7579
2651.16	13.1824
2653.87	12.9523
2656.58	11.7445
2659.29	11.5376
2661.99	10.7598
2664.7	9.68812
2667.41	10.4092
2670.11	9.70931
2672.81	8.60283
2675.51	8.19608
2678.22	8.08059
2680.92	8.45273
2683.62	9.65413
2686.31	10.9379
2689.01	11.6091
2691.71	12.7143
2694.4	14.9366
2697.1	16.3623
2699.79	18.3355
2702.49	19.297
2705.18	20.4542
2707.87	20.7307
2710.56	21.821
2713.25	22.3888
2715.94	24.4089
2718.62	24.7651
2721.31	25.6077
2723.99	26.8728
2726.68	26.9046
2729.36	26.2298
2732.04	25.5374
2734.73	23.8804
2737.41	21.5186
2740.08	20.6245
2742.76	17.9408
2745.44	16.6926
2748.12	15.386
2750.79	13.7317
2753.47	11.861
2756.14	11.009
2758.81	10.6813
2761.49	9.12972
2764.16	7.30537
2766.83	5.28831
2769.5	4.18549
2772.16	3.23469
2774.83	2.49288
2777.5	0.729641
2780.16	1.51757
2782.83	1.58381
2785.49	0.838691
2788.15	1.07456
2790.82	1.57802
2793.48	1.21657
2796.14	0.0503479
2798.79	0.0664723
2801.45	-0.646987
2804.11	-0.913552
2806.76	-3.00072
2809.42	-3.28787
2812.07	-2.84099
2814.73	-2.58264
2817.38	-0.128173
2820.03	3.52483
2822.68	8.52836
2825.33	15.1833
2827.98	22.5501
2830.63	30.9261
2833.27	40.1239
2835.92	51.2865
2838.56	63.5048
2841.21	77.4509
2843.85	92.6297
2846.49	110.377
2849.13	127.408
2851.77	144.294
2854.41	161.149
2857.05	177.528
2859.69	193.658
2862.32	208.549
2864.96	220.582
2867.59	232.859
2870.23	242.658
2872.86	251.898
2875.49	260.354
2878.12	266.864
2880.75	272.612
2883.38	279.24
2886.01	283.917
2888.63	288.723
2891.26	293.197
2893.89	298.858
2896.51	304.345
2899.13	312.143
2901.76	321.669
2904.38	332.444
2907	345.146
2909.62	358.609
2912.24	373.182
2914.85	387.568
2917.47	399.625
2920.09	412.287
2922.7	421.789
2925.32	427.771
2927.93	432.114
2930.54	430.921
2933.15	429.675
2935.76	424.016
2938.37	415.709
2940.98	405.145
2943.59	391.953
2946.2	378.585
2948.8	362.774
2951.41	346.791
2954.01	329.837
2956.62	313.184
2959.22	298.913
2961.82	283.064
2964.42	268.544
2967.02	254.846
2969.62	241.537
2972.22	228.937
2974.81	217.027
2977.41	203.841
2980	191.04
2982.6	177.6
2985.19	163.05
2987.78	147.748
2990.38	134.002
2992.97	119.735
2995.56	104.974
2998.14	92.675
3000.73	79.4879
3003.32	67.6348
3005.91	57.4337
3008.49	47.1277
3011.07	38.281
3013.66	30.2349
3016.24	24.4836
3018.82	19.5868
3021.4	13.7293
3023.98	8.1686
3026.56	4.52993
3029.14	2.28275
3031.71	0.927984
3034.29	-0.247281
3036.87	0.212386
3039.44	1.14778
3042.01	1.48637
3044.59	2.31022
3047.16	3.30654
3049.73	5.62643
3052.3	7.80302
3054.87	9.12014
3057.43	9.67203
3060	10.4568
3062.57	11.299
3065.13	10.7799
3067.7	10.5768
3070.26	10.9901
3072.82	10.1975
3075.39	10.992
3077.95	11.2952
3080.51	10.9012
3083.07	9.61916
3085.63	8.99111
3088.18	9.01543
3090.74	10.1503
3093.29	11.388
3095.85	12.4243
3098.4	14.856
3100.95	17.1143
3103.51	19.6059
3106.06	22.733
3108.61	25.976
3111.16	30.5144
3113.71	33.4555
3116.25	36.87
3118.8	39.0798
3121.35	42.497
3123.89	45.4907
3126.44	48.6754
3128.98	52.5679
3131.52	57.0916
3134.06	61.042
3136.6	65.0206
3139.14	68.9614
3141.68	72.3175
3144.22	75.4409
3146.76	79.3076
3149.29	82.8229