File: data/Raman/poly_smoothed/Mb_00_13_29_1x_45s_532 nm_x100_100%_600 gr_mm_01.txt
#Acq. time (s)=	45
#Accumulations=	2
#Range (cm-¹)=	200...3150
#Windows=	2
#Auto scanning=	Off
#Autofocus=	Off
#Macrospot=	Off
#AutoExposure=	Off
#Spike filter=	Multiple accum.
#Delay time (s)=	0
#Binning=	1
#Readout mode=	Signal
#DeNoise=	Off
#ICS correction=	On
#Dark correction=	Off
#Inst. Process=	Off
#Detector Gain=	Best Dynamic Range
#Detector ADC=	20 kHz
#Detector temperature (°C)=	-69.85
#Instrument=	LabRAM HR Evol
#Detector=	Synapse
#Objective=	x100
#Grating=	600 gr/mm
#ND Filter=	100%
#Laser (nm)=	532
#Hole=	100.021
#Range=	Auto
#Laser Pol.=	No
#Raman. Pol.=	No
#Laser Pol. (°)=	-0.0007625
#Raman Pol. (°)=	89.9995
#Collection=	Microscope
#StageXY=	Marzhauser
#StageZ=	Marzhauser
#X (µm)=	-986.9
#Y (µm)=	-2859.9
#Z (µm)=	528.65
#Full time(mm:ss)=	3:18
#Project=
#Sample=
#Site=
#Title=	Mb_00_13_29_2x_45s_532 nm_x100_100%_600 gr_mm
#Remark=
#Date=	06.07.2022 11:55
#Acquired=	06.07.2022 11:55:52
#Base:Fit=	10.08.2022 10:16:56
#Base:Sub=	10.08.2022 10:17:24
#Filter:Polynom=	16.08.2022 10:36:38
#AxisType[0]=Intens
#AxisUnit[0]=Cnt
#AxisType[1]=Spectr
#AxisUnit[1]=1/cm
200.398	4.97042
204.027	4.35717
207.657	4.64459
211.283	5.76647
214.909	7.99182
218.533	10.8103
222.157	16.3647
225.777	22.4972
229.396	28.6752
233.016	35.2174
236.632	39.3032
240.247	41.8878
243.86	45.2009
247.474	48.5421
251.085	51.6405
254.694	54.7046
258.301	56.6761
261.908	54.3543
265.513	51.5838
269.116	49.553
272.718	45.2092
276.319	42.999
279.918	39.1605
283.516	35.1618
287.113	30.8122
290.708	27.0703
294.302	23.6074
297.894	20.7793
301.485	19.7987
305.073	18.7505
308.661	19.8996
312.247	19.8519
315.833	19.5427
319.415	20.115
322.997	20.7953
326.579	22.1523
330.156	23.0469
333.735	25.019
337.31	24.3867
340.885	23.2051
344.458	21.7518
348.03	18.4298
351.6	16.3032
355.17	15.1609
358.737	11.226
362.304	11.0231
365.868	10.7449
369.431	11.3897
372.994	11.3398
376.554	12.6602
380.112	14.0772
383.669	16.5886
387.225	22.2274
390.781	27.3084
394.334	32.1967
397.885	34.2095
401.436	38.5719
404.984	41.9608
408.532	44.996
412.078	48.2753
415.623	46.9214
419.166	45.9538
422.708	44.7962
426.248	41.1987
429.788	38.9615
433.326	35.3092
436.86	31.8523
440.395	26.3385
443.929	19.4943
447.461	17.0417
450.99	14.4707
454.52	10.9479
458.048	7.16138
461.573	3.75794
465.099	3.18565
468.623	2.71156
472.144	3.87624
475.666	4.99428
479.184	5.12197
482.703	5.00422
486.218	5.31594
489.734	7.55671
493.247	7.76813
496.759	10.2408
500.271	12.6048
503.779	14.4042
507.287	16.8853
510.795	18.5146
514.299	19.8265
517.803	20.844
521.305	21.0972
524.805	20.402
528.307	20.6576
531.805	22.0677
535.301	22.3307
538.797	21.2447
542.291	19.8572
545.783	18.4872
549.275	17.1091
552.765	15.2827
556.253	15.2499
559.738	13.7131
563.224	10.9267
566.709	8.98601
570.192	7.54614
573.674	5.98557
577.153	5.56472
580.632	5.74704
584.11	6.91365
587.587	4.24402
591.06	2.90653
594.534	0.785124
598.005	0.399736
601.476	0.939911
604.944	0.0705148
608.413	-0.399902
611.878	0.263607
615.344	-0.857694
618.807	-1.2997
622.27	-1.36532
625.73	0.20191
629.189	1.57023
632.648	3.37857
636.105	6.70532
639.559	9.76712
643.013	12.0942
646.467	13.1491
649.918	13.889
653.368	15.37
656.816	17.0026
660.263	17.449
663.708	17.6119
667.153	16.2109
670.596	16.2857
674.037	14.117
677.478	13.6754
680.917	14.0844
684.355	11.7957
687.791	10.6044
691.224	9.69161
694.658	8.54037
698.091	6.95996
701.522	6.81471
704.95	7.41233
708.379	8.0562
711.806	11.9223
715.23	14.0458
718.655	17.9397
722.078	20.241
725.498	21.7684
728.919	23.9721
732.337	26.9831
735.755	29.7118
739.17	30.9727
742.584	31.7557
745.998	33.8085
749.409	35.7136
752.819	38.0858
756.23	42.0342
759.637	42.9212
763.043	46.4244
766.448	49.4891
769.853	50.5907
773.255	54.315
776.656	57.0536
780.056	57.8357
783.454	57.5195
786.851	57.0941
790.247	56.3527
793.641	58.2013
797.034	58.948
800.426	60.5901
803.817	59.5368
807.206	58.1665
810.592	58.152
813.979	58.9522
817.364	57.2613
820.748	56.3027
824.129	54.8349
827.511	55.6027
830.891	55.2105
834.269	56.4065
837.646	56.1118
841.023	55.8905
844.396	56.6393
847.77	56.8634
851.141	54.4061
854.513	54.1193
857.881	53.415
861.248	50.0228
864.616	47.3444
867.98	45.8555
871.343	41.8641
874.707	40.4603
878.068	39.3354
881.428	38.3679
884.786	38.8168
888.143	41.5552
891.498	46.3764
894.855	49.6045
898.208	51.9
901.56	53.504
904.91	55.4746
908.26	58.288
911.608	59.8328
914.955	60.1194
918.298	59.9339
921.643	59.9567
924.986	58.645
928.328	55.3213
931.668	52.1337
935.006	47.6628
938.344	45.198
941.681	40.7703
945.014	36.2826
948.349	32.5687
951.682	26.7187
955.012	22.7718
958.343	20.6278
961.67	20.441
964.998	22.6489
968.323	29.2122
971.649	31.1733
974.971	35.2751
978.293	35.645
981.615	37.3201
984.933	39.2361
988.251	41.0086
991.567	41.6392
994.884	40.8739
998.198	38.5138
1001.51	38.7639
1004.82	37.2099
1008.13	33.9288
1011.44	32.8452
1014.75	32.6216
1018.06	32.1999
1021.36	34.3017
1024.66	36.5411
1027.97	38.7262
1031.27	39.0796
1034.57	41.6532
1037.87	44.9198
1041.16	47.0102
1044.46	50.5234
1047.76	52.5952
1051.05	53.2283
1054.34	53.1428
1057.63	53.3767
1060.92	51.4953
1064.21	50.4024
1067.5	47.4896
1070.78	45.547
1074.07	40.6308
1077.35	35.8739
1080.63	33.3997
1083.91	29.0562
1087.19	25.2091
1090.47	24.1118
1093.75	24.5649
1097.03	24.3117
1100.3	24.7747
1103.57	25.6525
1106.84	25.2554
1110.11	22.8647
1113.38	21.4574
1116.65	21.1752
1119.92	19.6175
1123.19	16.9339
1126.45	16.0122
1129.71	14.4008
1132.97	13.3869
1136.23	13.0721
1139.49	12.8786
1142.75	12.3726
1146.01	13.3218
1149.26	12.9361
1152.52	13.3555
1155.77	12.3051
1159.02	11.5066
1162.27	12.114
1165.52	12.8275
1168.77	14.8554
1172.02	17.0821
1175.26	18.7872
1178.51	18.6538
1181.75	17.8394
1184.99	20.6598
1188.23	21.5408
1191.47	23.2545
1194.71	26.2702
1197.94	29.0053
1201.18	31.9553
1204.41	34.3895
1207.65	37.8551
1210.88	40.0591
1214.11	43.5205
1217.34	48.5857
1220.57	51.7289
1223.79	54.7337
1227.02	56.7096
1230.24	59.0144
1233.47	59.0836
1236.69	60.4093
1239.91	60.7646
1243.13	61.0177
1246.34	59.6119
1249.56	58.2801
1252.78	57.5143
1255.99	56.0075
1259.2	54.538
1262.42	54.8349
1265.63	54.3699
1268.84	53.1166
1272.04	54.6863
1275.25	55.7563
1278.46	57.5165
1281.66	58.3889
1284.86	61.6131
1288.07	64.3396
1291.27	68.622
1294.47	71.1656
1297.66	75.4806
1300.86	78.2803
1304.06	80.5641
1307.25	83.903
1310.44	86.5668
1313.64	90.5742
1316.83	91.113
1320.02	90.4561
1323.2	90.2245
1326.39	88.9888
1329.58	89.5648
1332.76	89.3861
1335.95	87.6448
1339.13	86.4782
1342.31	84.1037
1345.49	82.5124
1348.67	79.6829
1351.85	78.8247
1355.02	76.4495
1358.2	73.573
1361.37	69.9221
1364.54	67.8955
1367.71	65.6738
1370.88	63.4371
1374.05	61.7303
1377.22	60.0962
1380.39	60.035
1383.55	60.35
1386.72	60.7285
1389.88	61.1254
1393.04	59.6111
1396.2	57.6914
1399.36	57.8885
1402.52	58.31
1405.68	60.2287
1408.83	63.8528
1411.98	67.1516
1415.14	70.3515
1418.29	74.9848
1421.44	79.1686
1424.59	84.4884
1427.74	89.8221
1430.89	93.7373
1434.03	97.048
1437.18	100.841
1440.32	104.254
1443.46	106.444
1446.6	106.601
1449.74	108.238
1452.88	107.797
1456.02	106.331
1459.16	103.007
1462.29	99.1217
1465.43	93.3832
1468.56	87.3536
1471.69	82.0048
1474.82	74.7971
1477.95	69.3024
1481.08	64.3211
1484.2	60.4539
1487.33	56.5412
1490.46	52.4583
1493.58	49.0634
1496.7	45.496
1499.82	44.9802
1502.94	43.4854
1506.06	42.1835
1509.18	40.7164
1512.29	40.7059
1515.41	40.6673
1518.52	40.3542
1521.63	40.7614
1524.75	42.3769
1527.85	43.7721
1530.96	43.4394
1534.07	42.9953
1537.18	44.2747
1540.28	46.0571
1543.39	47.4615
1546.49	48.6841
1549.59	49.427
1552.69	51.0069
1555.79	51.9695
1558.89	53.9678
1561.99	54.4116
1565.08	54.3
1568.18	54.7486
1571.27	56.0839
1574.37	58.2645
1577.46	59.1383
1580.55	60.0771
1583.64	61.9748
1586.73	64.3716
1589.81	64.9346
1592.9	66.638
1595.98	67.8668
1599.06	68.3394
1602.15	66.7328
1605.23	67.689
1608.31	66.5252
1611.39	66.5121
1614.46	67.8417
1617.54	68.2426
1620.61	69.2703
1623.69	70.005
1626.76	72.3024
1629.83	75.4
1632.9	75.6017
1635.97	78.0802
1639.04	79.2392
1642.11	80.0081
1645.17	81.0359
1648.24	82.7298
1651.3	83.2114
1654.36	84.2238
1657.42	85.4974
1660.48	84.8225
1663.54	81.5371
1666.6	78.4148
1669.66	74.9328
1672.71	68.744
1675.77	64.9768
1678.82	60.8537
1681.87	54.8801
1684.92	47.4513
1687.97	43.1049
1691.02	38.754
1694.07	35.2713
1697.11	30.9396
1700.16	27.5469
1703.2	26.0441
1706.25	23.124
1709.29	20.7815
1712.33	19.2484
1715.37	17.9058
1718.41	16.3489
1721.44	15.6419
1724.48	16.7557
1727.51	16.8893
1730.55	17.6649
1733.58	16.6852
1736.61	15.3907
1739.64	15.3803
1742.67	14.6756
1745.7	16.0967
1748.72	16.9687
1751.75	16.2865
1754.77	15.6205
1757.8	13.9257
1760.82	14.1281
1763.84	15.732
1766.86	15.5344
1769.88	14.5446
1772.9	13.8156
1775.91	13.3656
1778.93	13.6069
1781.94	12.3799
1784.96	13.1415
1787.97	13.211
1790.98	13.5333
1793.99	12.7199
1797	11.9361
1800.01	12.2648
1803.01	10.8798
1806.02	10.4796
1809.02	10.013
1812.02	9.59135
1815.02	8.45995
1818.03	8.62767
1821.02	8.23237
1824.02	7.54937
1827.02	6.86097
1830.02	6.34852
1833.01	6.77164
1836.01	5.97265
1839	5.98392
1841.99	5.42417
1844.98	5.03949
1847.97	4.27153
1850.96	3.6877
1853.95	4.20672
1856.93	4.93426
1859.92	4.84153
1862.9	4.93698
1865.88	4.81506
1868.87	4.59986
1871.85	3.44181
1874.83	2.74579
1877.81	1.88276
1880.78	2.15334
1882.53	1.5638
1885.52	0.674649
1888.51	-0.0774278
1891.5	0.698509
1894.48	-0.0788858
1897.47	-0.128391
1900.45	0.327341
1903.43	1.77959
1906.41	1.75469
1909.39	1.6438
1912.37	1.59157
1915.35	2.40456
1918.33	2.67014
1921.3	2.4592
1924.28	3.43608
1927.25	3.9856
1930.22	4.9099
1933.19	5.69903
1936.16	6.54276
1939.13	5.85796
1942.1	4.93252
1945.07	4.85167
1948.03	5.38534
1951	4.55402
1953.96	4.20843
1956.92	4.18779
1959.88	3.65071
1962.84	2.98471
1965.8	2.50816
1968.76	1.29078
1971.72	2.28063
1974.67	2.11251
1977.63	1.48808
1980.58	1.65564
1983.54	1.29414
1986.49	1.41536
1989.44	2.07849
1992.39	3.07623
1995.33	3.54435
1998.28	3.58578
2001.23	5.40609
2004.17	6.80046
2007.12	6.83041
2010.06	7.69067
2013	8.6928
2015.94	8.28153
2018.88	8.96798
2021.82	8.84713
2024.76	9.14978
2027.69	8.81736
2030.63	8.93863
2033.56	7.546
2036.5	7.07152
2039.43	6.64425
2042.36	7.22927
2045.29	5.68656
2048.22	4.32825
2051.15	5.06181
2054.07	4.41832
2057	3.35035
2059.92	3.1685
2062.85	2.23376
2065.77	1.6375
2068.69	1.41608
2071.61	2.02173
2074.53	1.30768
2077.45	1.52928
2080.37	1.02717
2083.28	0.640273
2086.2	-0.230008
2089.11	0.185758
2092.02	0.804812
2094.94	0.0901461
2097.85	0.761342
2100.76	1.02854
2103.66	1.58672
2106.57	1.61578
2109.48	2.40266
2112.38	2.82553
2115.29	2.94935
2118.19	3.35666
2121.09	3.69551
2123.99	3.34932
2126.89	3.45947
2129.79	4.16976
2132.69	4.21536
2135.59	5.02402
2138.48	5.37562
2141.38	4.42862
2144.27	4.82875
2147.17	5.32243
2150.06	5.84605
2152.95	6.49203
2155.84	7.70395
2158.73	7.87102
2161.61	8.44522
2164.5	8.578
2167.38	8.6133
2170.27	8.97332
2173.15	8.85961
2176.03	8.50658
2178.91	8.80599
2181.8	8.24902
2184.67	9.06661
2187.55	8.63931
2190.43	7.72886
2193.3	7.24703
2196.18	6.74097
2199.05	5.75934
2201.93	5.64292
2204.8	6.02273
2207.67	6.35718
2210.54	6.01347
2213.41	5.89122
2216.27	6.07008
2219.14	6.16256
2222.01	7.15472
2224.87	6.58435
2227.73	5.94199
2230.6	5.45998
2233.46	5.38783
2236.32	5.75419
2239.18	6.4735
2242.03	5.17649
2244.89	4.53605
2247.75	4.54369
2250.6	4.51481
2253.46	4.7983
2256.31	4.35943
2259.16	3.4065
2262.01	4.55138
2264.86	4.46537
2267.71	4.9883
2270.56	5.65789
2273.4	5.91967
2276.25	7.18199
2279.09	7.79505
2281.94	7.76431
2284.78	7.72845
2287.62	6.34195
2290.46	6.05577
2293.3	5.49785
2296.14	5.52221
2298.98	5.71324
2301.82	7.04316
2304.65	7.41612
2307.49	8.13394
2310.32	8.54147
2313.15	8.22182
2315.98	7.21101
2318.81	6.63783
2321.64	7.03221
2324.47	6.71631
2327.3	7.70551
2330.12	8.90913
2332.95	9.6338
2335.77	8.90493
2338.6	8.53172
2341.42	8.72558
2344.24	8.82498
2347.06	9.21008
2349.88	8.05114
2352.7	5.9551
2355.51	5.71672
2358.33	5.45182
2361.14	5.52442
2363.96	7.09954
2366.77	7.38824
2369.58	7.59196
2372.39	7.00101
2375.2	7.46958
2378.01	8.21027
2380.82	8.46146
2383.63	8.13408
2386.43	8.70363
2389.24	9.05208
2392.04	10.3987
2394.84	10.8761
2397.65	10.5577
2400.45	9.07944
2403.25	8.99217
2406.05	8.72283
2408.84	8.13432
2411.64	8.71027
2414.44	8.27041
2417.23	8.15503
2420.02	7.49913
2422.82	7.42924
2425.61	7.83013
2428.4	7.26776
2431.19	8.33134
2433.98	7.51363
2436.77	7.83334
2439.55	7.46199
2442.34	7.53261
2445.12	6.87984
2447.91	6.86342
2450.69	7.08894
2453.47	6.89379
2456.25	7.06729
2459.03	6.4464
2461.81	6.40597
2464.59	5.12208
2467.36	4.63441
2470.14	5.43917
2472.92	5.74492
2475.69	5.62602
2478.46	4.91034
2481.23	5.24951
2484	5.64012
2486.77	4.89679
2489.54	4.33165
2492.31	3.85075
2495.08	2.8513
2497.84	2.44951
2500.61	1.04022
2503.37	1.12781
2506.13	0.369009
2508.9	0.0264932
2511.66	-0.123296
2514.42	0.204566
2517.18	1.04499
2519.93	1.42865
2522.69	1.79498
2525.45	1.81244
2528.2	2.59833
2530.95	3.56215
2533.71	3.52489
2536.46	4.21871
2539.21	5.70828
2541.96	7.07861
2544.71	7.77667
2547.46	9.33248
2550.2	10.1925
2552.95	9.95028
2555.7	10.0845
2558.44	9.54969
2561.18	8.98487
2563.93	9.06961
2566.67	10.5154
2569.41	12.3846
2572.15	13.2807
2574.88	13.0116
2577.62	14.3994
2580.36	13.9754
2583.09	14.2453
2585.83	13.2566
2588.56	11.4828
2591.29	11.585
2594.02	9.6958
2596.75	9.84393
2599.48	9.77789
2602.21	10.0958
2604.94	9.90088
2607.67	10.0525
2610.39	9.3944
2613.12	10.3045
2615.84	10.0186
2618.56	9.66124
2621.28	11.2397
2624.01	11.8896
2626.72	12.5476
2629.44	13.2091
2632.16	15.2996
2634.88	16.2038
2637.59	15.8518
2640.31	16.3772
2643.02	16.9728
2645.74	16.3428
2648.45	16.5208
2651.16	15.6094
2653.87	14.757
2656.58	14.9805
2659.29	14.9165
2661.99	14.7177
2664.7	14.2755
2667.41	14.5433
2670.11	13.8013
2672.81	13.8804
2675.51	14.5396
2678.22	15.1568
2680.92	15.9644
2683.62	14.9935
2686.31	15.0857
2689.01	15.2609
2691.71	14.8518
2694.4	14.7393
2697.1	15.291
2699.79	15.347
2702.49	14.7307
2705.18	15.3628
2707.87	16.1516
2710.56	15.1096
2713.25	14.4247
2715.94	14.3362
2718.62	14.8612
2721.31	16.2612
2723.99	16.0706
2726.68	16.0948
2729.36	15.2605
2732.04	15.5973
2734.73	16.5416
2737.41	16.4477
2740.08	16.3748
2742.76	15.6266
2745.44	14.0492
2748.12	12.8181
2750.79	11.1112
2753.47	11.5078
2756.14	10.5453
2758.81	9.54662
2761.49	8.26922
2764.16	7.80053
2766.83	6.65812
2769.5	6.40208
2772.16	5.81545
2774.83	4.48352
2777.5	3.50915
2780.16	3.58143
2782.83	2.92091
2785.49	3.65928
2788.15	2.73527
2790.82	1.64331
2793.48	1.72303
2796.14	2.52502
2798.79	3.19783
2801.45	2.5546
2804.11	3.16394
2806.76	2.49612
2809.42	2.47694
2812.07	3.96594
2814.73	4.41729
2817.38	5.36251
2820.03	7.83778
2822.68	8.8063
2825.33	11.2142
2827.98	14.2217
2830.63	17.9679
2833.27	20.907
2835.92	24.9938
2838.56	28.9425
2841.21	34.2937
2843.85	40.8978
2846.49	47.9217
2849.13	55.6153
2851.77	64.7319
2854.41	73.0102
2857.05	81.1684
2859.69	89.8068
2862.32	97.8416
2864.96	106.03
2867.59	113.968
2870.23	121.647
2872.86	127.875
2875.49	133.976
2878.12	138.095
2880.75	143.1
2883.38	148.471
2886.01	151.962
2888.63	154.325
2891.26	158.727
2893.89	162.942
2896.51	166.462
2899.13	170.912
2901.76	176.256
2904.38	183.48
2907	191.291
2909.62	199.511
2912.24	208.703
2914.85	216.423
2917.47	223.883
2920.09	229.68
2922.7	234.209
2925.32	237.946
2927.93	239.154
2930.54	239.325
2933.15	238.473
2935.76	234.449
2938.37	229.469
2940.98	224.404
2943.59	217.054
2946.2	209.483
2948.8	199.805
2951.41	189.99
2954.01	181.94
2956.62	173.224
2959.22	164.031
2961.82	156.576
2964.42	148.962
2967.02	142.284
2969.62	136.021
2972.22	129.404
2974.81	122.297
2977.41	116.099
2980	108.965
2982.6	101.66
2985.19	92.6421
2987.78	83.5469
2990.38	75.9791
2992.97	66.4983
2995.56	58.3583
2998.14	52.5082
3000.73	45.298
3003.32	38.4458
3005.91	32.1947
3008.49	25.2993
3011.07	19.5877
3013.66	14.9634
3016.24	12.0587
3018.82	9.24562
3021.4	6.96915
3023.98	4.35911
3026.56	3.38453
3029.14	2.64991
3031.71	3.06851
3034.29	2.90289
3036.87	4.83771
3039.44	6.444
3042.01	8.74718
3044.59	9.14088
3047.16	10.4146
3049.73	10.1827
3052.3	10.7491
3054.87	11.6036
3057.43	13.2441
3060	14.7409
3062.57	14.2312
3065.13	12.8648
3067.7	11.2767
3070.26	10.1815
3072.82	9.35552
3075.39	9.51265
3077.95	8.43607
3080.51	7.79811
3083.07	5.2204
3085.63	4.37752
3088.18	3.30316
3090.74	3.77461
3093.29	3.61933
3095.85	4.84405
3098.4	5.73528
3100.95	6.75853
3103.51	7.30026
3106.06	9.19099
3108.61	9.78636
3111.16	11.2181
3113.71	13.0979
3116.25	16.05
3118.8	17.5686
3121.35	18.675
3123.89	19.7999
3126.44	21.8146
3128.98	23.4307
3131.52	25.2274
3134.06	27.8998
3136.6	30.8721
3139.14	31.535
3141.68	32.3783
3144.22	33.251
3146.76	34.6804
3149.29	35.0427