File: data/Raman/poly_smoothed/Mb_00_13_43_1x_45s_532 nm_x100_100%_600 gr_mm_01.txt
#Acq. time (s)=	45
#Accumulations=	2
#Range (cm-¹)=	200...3150
#Windows=	2
#Auto scanning=	Off
#Autofocus=	Off
#Macrospot=	Off
#AutoExposure=	Off
#Spike filter=	Multiple accum.
#Delay time (s)=	0
#Binning=	1
#Readout mode=	Signal
#DeNoise=	Off
#ICS correction=	On
#Dark correction=	Off
#Inst. Process=	Off
#Detector Gain=	Best Dynamic Range
#Detector ADC=	20 kHz
#Detector temperature (°C)=	-69.85
#Instrument=	LabRAM HR Evol
#Detector=	Synapse
#Objective=	x100
#Grating=	600 gr/mm
#ND Filter=	100%
#Laser (nm)=	532
#Hole=	100.021
#Range=	Auto
#Laser Pol.=	No
#Raman. Pol.=	No
#Laser Pol. (°)=	-0.0007625
#Raman Pol. (°)=	89.9995
#Collection=	Microscope
#StageXY=	Marzhauser
#StageZ=	Marzhauser
#X (µm)=	-1042.6
#Y (µm)=	-2896.4
#Z (µm)=	528.25
#Full time(mm:ss)=	3:18
#Project=
#Sample=
#Site=
#Title=	Mb_00_13_43_2x_45s_532 nm_x100_100%_600 gr_mm
#Remark=
#Date=	06.07.2022 13:10
#Acquired=	06.07.2022 13:10:01
#Base:Fit=	10.08.2022 10:16:56
#Base:Sub=	10.08.2022 10:17:24
#Filter:Polynom=	16.08.2022 10:36:38
#AxisType[0]=Intens
#AxisUnit[0]=Cnt
#AxisType[1]=Spectr
#AxisUnit[1]=1/cm
200.398	9.17566
204.027	9.09323
207.657	1.79733
211.283	-3.63379
214.909	-4.07786
218.533	1.1701
222.157	13.5185
225.777	29.7037
229.396	48.5855
233.016	67.4799
236.632	83.3196
240.247	102.01
243.86	114.836
247.474	127.461
251.085	142.32
254.694	152.966
258.301	160.76
261.908	164.968
265.513	164.402
269.116	162.505
272.718	156.891
276.319	149.014
279.918	136.279
283.516	121.369
287.113	105.057
290.708	87.8487
294.302	72.0019
297.894	59.0212
301.485	51.2686
305.073	42.5547
308.661	37.0566
312.247	32.3571
315.833	31.4075
319.415	27.7312
322.997	25.6973
326.579	23.5623
330.156	20.837
333.735	20.6441
337.31	17.0494
340.885	18.8509
344.458	16.049
348.03	13.4688
351.6	8.97445
355.17	4.78079
358.737	1.73891
362.304	0.777508
365.868	5.46396
369.431	9.46944
372.994	15.5559
376.554	24.7142
380.112	33.0974
383.669	45.9203
387.225	64.0784
390.781	80.4222
394.334	96.225
397.885	111.685
401.436	126.768
404.984	136.08
408.532	142.885
412.078	146.037
415.623	147.44
419.166	146.47
422.708	140.23
426.248	133.545
429.788	121.564
433.326	106.916
436.86	92.2658
440.395	76.5062
443.929	59.361
447.461	45.3089
450.99	35.4302
454.52	24.1826
458.048	14.2573
461.573	6.82552
465.099	3.96754
468.623	2.23822
472.144	7.64908
475.666	12.2219
479.184	17.9926
482.703	21.4342
486.218	28.656
489.734	33.4153
493.247	41.0766
496.759	48.5187
500.271	55.655
503.779	58.9807
507.287	64.4914
510.795	68.3952
514.299	70.9639
517.803	72.7563
521.305	76.5716
524.805	78.7092
528.307	79.2344
531.805	80.7842
535.301	80.4917
538.797	76.7516
542.291	73.264
545.783	68.5664
549.275	67.5505
552.765	63.9072
556.253	60.4455
559.738	58.0944
563.224	52.6698
566.709	47.0887
570.192	42.6666
573.674	39.7171
577.153	36.3391
580.632	32.9779
584.11	30.4972
587.587	27.752
591.06	25.4477
594.534	21.2727
598.005	18.551
601.476	19.0518
604.944	18.8294
608.413	19.4542
611.878	19.5981
615.344	18.9668
618.807	18.4531
622.27	17.0807
625.73	17.0427
629.189	20.8211
632.648	25.5745
636.105	29.998
639.559	33.0155
643.013	33.0009
646.467	34.3826
649.918	33.8177
653.368	34.1772
656.816	34.3557
660.263	32.106
663.708	32.1827
667.153	31.5626
670.596	29.8964
674.037	24.8235
677.478	21.2195
680.917	18.3443
684.355	16.4116
687.791	11.7775
691.224	9.7559
694.658	8.47038
698.091	5.64991
701.522	3.36447
704.95	3.01991
708.379	3.20364
711.806	5.07929
715.23	5.75585
718.655	6.53688
722.078	4.28306
725.498	3.00874
728.919	3.65296
732.337	5.48754
735.755	6.99698
739.17	9.33095
742.584	10.2669
745.998	15.7753
749.409	17.8086
752.819	20.8414
756.23	24.7834
759.637	26.7053
763.043	27.5944
766.448	30.6819
769.853	34.7111
773.255	39.0384
776.656	41.6698
780.056	43.5576
783.454	44.1314
786.851	47.2314
790.247	48.374
793.641	49.9763
797.034	49.7076
800.426	49.5035
803.817	47.2636
807.206	46.3175
810.592	46.1973
813.979	46.7795
817.364	47.3738
820.748	47.5429
824.129	50.4399
827.511	52.7615
830.891	52.2001
834.269	49.3028
837.646	49.6023
841.023	47.5083
844.396	43.2731
847.77	42.1853
851.141	42.1915
854.513	38.7978
857.881	35.2111
861.248	32.5853
864.616	29.0137
867.98	26.4232
871.343	24.6995
874.707	22.2906
878.068	20.3621
881.428	17.2761
884.786	15.9218
888.143	14.2945
891.498	11.4016
894.855	8.38402
898.208	6.95108
901.56	6.58044
904.91	6.05813
908.26	5.24181
911.608	3.80488
914.955	4.12573
918.298	7.51834
921.643	8.07776
924.986	10.6271
928.328	14.5828
931.668	17.6207
935.006	15.6574
938.344	15.4655
941.681	16.123
945.014	15.8309
948.349	15.4742
951.682	14.4055
955.012	12.3685
958.343	9.7676
961.67	8.30298
964.998	12.0901
968.323	17.0254
971.649	22.1695
974.971	27.3862
978.293	34.7925
981.615	40.7511
984.933	47.0674
988.251	49.8158
991.567	54.34
994.884	60.0841
998.198	65.4661
1001.51	68.5404
1004.82	73.1419
1008.13	74.6715
1011.44	73.8456
1014.75	74.7004
1018.06	78.0275
1021.36	90.4385
1024.66	103.592
1027.97	116.516
1031.27	129.338
1034.57	139.943
1037.87	146.747
1041.16	154.805
1044.46	164.74
1047.76	170.469
1051.05	173.132
1054.34	172.934
1057.63	170.117
1060.92	163.322
1064.21	153.639
1067.5	142.449
1070.78	127.214
1074.07	113.801
1077.35	98.4922
1080.63	78.7789
1083.91	62.8438
1087.19	46.8634
1090.47	34.4726
1093.75	29.6936
1097.03	29.0553
1100.3	31.9629
1103.57	34.7336
1106.84	35.2377
1110.11	34.8515
1113.38	32.8797
1116.65	30.4094
1119.92	26.2563
1123.19	25.241
1126.45	22.7053
1129.71	19.7504
1132.97	17.4634
1136.23	18.5049
1139.49	15.6011
1142.75	15.9144
1146.01	13.2348
1149.26	12.0619
1152.52	9.12957
1155.77	9.74111
1159.02	8.91828
1162.27	8.26155
1165.52	8.12606
1168.77	10.056
1172.02	13.0031
1175.26	12.4917
1178.51	16.0512
1181.75	17.524
1184.99	18.5642
1188.23	21.1521
1191.47	23.7057
1194.71	27.7245
1197.94	33.3368
1201.18	38.7256
1204.41	47.1548
1207.65	54.5025
1210.88	59.5653
1214.11	67.9731
1217.34	74.739
1220.57	83.3863
1223.79	91.9098
1227.02	100.236
1230.24	108.359
1233.47	116.366
1236.69	120.402
1239.91	125.275
1243.13	128.001
1246.34	130.557
1249.56	132.715
1252.78	133.149
1255.99	135.216
1259.2	134.573
1262.42	132.742
1265.63	129.814
1268.84	131.249
1272.04	132.365
1275.25	133.777
1278.46	133.949
1281.66	136.014
1284.86	137.892
1288.07	139.607
1291.27	144.252
1294.47	148.388
1297.66	153.215
1300.86	161.886
1304.06	168.439
1307.25	173.872
1310.44	178.037
1313.64	181.243
1316.83	184.568
1320.02	188.992
1323.2	188.292
1326.39	190.398
1329.58	190.925
1332.76	188.147
1335.95	186.08
1339.13	181.356
1342.31	174.534
1345.49	170.661
1348.67	166.208
1351.85	159.374
1355.02	151.851
1358.2	147.804
1361.37	140.592
1364.54	135.569
1367.71	129.685
1370.88	123.914
1374.05	120.688
1377.22	119.535
1380.39	116.542
1383.55	113.163
1386.72	111.314
1389.88	111.832
1393.04	112.586
1396.2	113.046
1399.36	114.251
1402.52	117.263
1405.68	122.31
1408.83	129.051
1411.98	134.146
1415.14	146.218
1418.29	159.743
1421.44	176.769
1424.59	194.335
1427.74	212.061
1430.89	233.738
1434.03	250.146
1437.18	264.977
1440.32	279.128
1443.46	291.19
1446.6	295.118
1449.74	300.416
1452.88	299.156
1456.02	292.453
1459.16	281.951
1462.29	267.093
1465.43	252.167
1468.56	233.138
1471.69	210.903
1474.82	186.308
1477.95	163.295
1481.08	143.152
1484.2	121.881
1487.33	105.479
1490.46	88.941
1493.58	77.9629
1496.7	69.6016
1499.82	62.2399
1502.94	57.299
1506.06	53.4251
1509.18	52.7348
1512.29	49.88
1515.41	49.6594
1518.52	50.4914
1521.63	49.0351
1524.75	51.222
1527.85	53.2138
1530.96	54.7311
1534.07	55.782
1537.18	58.9165
1540.28	63.9662
1543.39	67.3091
1546.49	72.0469
1549.59	78.583
1552.69	84.0705
1555.79	89.146
1558.89	93.4161
1561.99	97.0893
1565.08	102.587
1568.18	110.074
1571.27	120.745
1574.37	128.352
1577.46	138.058
1580.55	147.421
1583.64	156.011
1586.73	161.771
1589.81	164.945
1592.9	170.874
1595.98	172.702
1599.06	175.373
1602.15	175.171
1605.23	172.982
1608.31	173.245
1611.39	170.463
1614.46	167.898
1617.54	165.824
1620.61	163.738
1623.69	163.311
1626.76	160.891
1629.83	159.045
1632.9	158.001
1635.97	158.042
1639.04	156.89
1642.11	160.043
1645.17	175.327
1648.24	187.662
1651.3	198.161
1654.36	209.822
1657.42	216.652
1660.48	218.255
1663.54	216.81
1666.6	213.876
1669.66	209.77
1672.71	201.806
1675.77	191.643
1678.82	181.536
1681.87	167.82
1684.92	152.87
1687.97	135.675
1691.02	121.598
1694.07	104.557
1697.11	89.7779
1700.16	73.4375
1703.2	56.9418
1706.25	41.7878
1709.29	28.933
1712.33	15.7893
1715.37	12.7874
1718.41	13.736
1721.44	16.2815
1724.48	12.8885
1727.51	12.1948
1730.55	10.7736
1733.58	7.16621
1736.61	5.24448
1739.64	6.5536
1742.67	4.71646
1745.7	3.93847
1748.72	4.598
1751.75	6.34428
1754.77	4.64145
1757.8	3.33508
1760.82	2.67977
1763.84	3.9703
1766.86	4.22779
1769.88	4.6718
1772.9	4.50236
1775.91	3.31957
1778.93	3.41981
1781.94	2.96954
1784.96	3.18786
1787.97	3.56664
1790.98	4.00855
1793.99	4.59337
1797	3.6356
1800.01	3.65148
1803.01	3.77116
1806.02	5.56111
1809.02	6.31015
1812.02	6.66795
1815.02	6.13205
1818.03	5.26231
1821.02	4.57484
1824.02	4.49181
1827.02	4.8276
1830.02	4.98827
1833.01	5.79588
1836.01	5.5102
1839	6.42049
1841.99	7.66159
1844.98	8.16058
1847.97	7.09677
1850.96	5.72688
1853.95	5.68111
1856.93	6.35308
1859.92	6.51354
1862.9	6.8487
1865.88	7.00572
1868.87	6.9643
1871.85	8.08188
1874.83	9.14353
1877.81	9.74559
1880.78	9.89889
1882.53	9.51907
1885.52	9.57193
1888.51	10.5677
1891.5	9.12707
1894.48	10.9886
1897.47	13.8468
1900.45	12.8585
1903.43	11.7658
1906.41	10.4216
1909.39	10.7098
1912.37	10.496
1915.35	11.9287
1918.33	12.0203
1921.3	11.5046
1924.28	10.1207
1927.25	10.0921
1930.22	6.9619
1933.19	6.74653
1936.16	5.06353
1939.13	4.25881
1942.1	3.88847
1945.07	4.18029
1948.03	3.92081
1951	4.6714
1953.96	3.51889
1956.92	3.41945
1959.88	4.88583
1962.84	5.42015
1965.8	5.99152
1968.76	8.469
1971.72	8.08976
1974.67	7.51874
1977.63	9.39804
1980.58	12.6009
1983.54	12.6892
1986.49	14.1738
1989.44	15.2263
1992.39	14.91
1995.33	12.9712
1998.28	10.946
2001.23	9.34945
2004.17	9.09917
2007.12	8.08204
2010.06	6.54608
2013	6.20026
2015.94	6.3488
2018.88	4.98959
2021.82	3.72117
2024.76	3.74785
2027.69	4.51493
2030.63	5.59876
2033.56	8.46784
2036.5	9.30639
2039.43	11.1274
2042.36	12.1515
2045.29	12.0527
2048.22	13.3038
2051.15	15.5908
2054.07	17.4247
2057	16.7731
2059.92	18.7876
2062.85	20.7923
2065.77	20.4067
2068.69	20.9574
2071.61	22.209
2074.53	21.9989
2077.45	21.3051
2080.37	20.1503
2083.28	21.8077
2086.2	22.0371
2089.11	22.1192
2092.02	21.3113
2094.94	24.1268
2097.85	24.6782
2100.76	25.8464
2103.66	25.7891
2106.57	27.5167
2109.48	26.9053
2112.38	24.9338
2115.29	23.2066
2118.19	21.805
2121.09	20.988
2123.99	21.4792
2126.89	18.7609
2129.79	17.1517
2132.69	15.806
2135.59	14.4011
2138.48	13.7503
2141.38	13.2121
2144.27	11.3471
2147.17	10.7311
2150.06	11.2814
2152.95	12.1551
2155.84	13.0852
2158.73	12.936
2161.61	16.1023
2164.5	18.5906
2167.38	20.6629
2170.27	23.288
2173.15	25.5485
2176.03	26.9767
2178.91	27.2978
2181.8	26.863
2184.67	26.3829
2187.55	26.2616
2190.43	25.4579
2193.3	25.9029
2196.18	25.1935
2199.05	23.6088
2201.93	22.2018
2204.8	22.1249
2207.67	21.1645
2210.54	19.7741
2213.41	17.5671
2216.27	16.4285
2219.14	16.6957
2222.01	16.5765
2224.87	15.4013
2227.73	15.002
2230.6	16.5164
2233.46	14.9277
2236.32	14.3677
2239.18	15.8381
2242.03	15.4658
2244.89	16.4435
2247.75	16.1281
2250.6	15.3026
2253.46	14.548
2256.31	13.9359
2259.16	15.2389
2262.01	14.8512
2264.86	15.753
2267.71	16.9263
2270.56	16.3583
2273.4	18.0091
2276.25	19.1008
2279.09	17.5679
2281.94	18.0589
2284.78	18.9805
2287.62	18.1138
2290.46	18.1318
2293.3	17.8331
2296.14	16.5727
2298.98	17.358
2301.82	17.0258
2304.65	16.3472
2307.49	15.9795
2310.32	17.0261
2313.15	16.9013
2315.98	14.371
2318.81	15.211
2321.64	14.1472
2324.47	14.3729
2327.3	13.2181
2330.12	10.9613
2332.95	12.0553
2335.77	12.3554
2338.6	11.7992
2341.42	10.3737
2344.24	9.67709
2347.06	8.12264
2349.88	6.79543
2352.7	6.67382
2355.51	5.57314
2358.33	6.50523
2361.14	5.47938
2363.96	5.94489
2366.77	5.32653
2369.58	6.28972
2372.39	5.00975
2375.2	3.95941
2378.01	4.74732
2380.82	5.46332
2383.63	4.56825
2386.43	4.34373
2389.24	5.61107
2392.04	5.34524
2394.84	4.92716
2397.65	4.59343
2400.45	5.77904
2403.25	6.06335
2406.05	5.78962
2408.84	4.4737
2411.64	5.28066
2414.44	5.40996
2417.23	7.01273
2420.02	6.60264
2422.82	8.00576
2425.61	9.21089
2428.4	8.61447
2431.19	7.65911
2433.98	6.44405
2436.77	4.58234
2439.55	3.89263
2442.34	2.77093
2445.12	1.89027
2447.91	0.240811
2450.69	-0.232746
2453.47	-0.239816
2456.25	-0.874881
2459.03	-2.04181
2461.81	-2.0531
2464.59	-3.09296
2467.36	-0.959447
2470.14	0.695496
2472.92	1.29974
2475.69	1.58869
2478.46	1.82943
2481.23	3.09307
2484	3.38571
2486.77	4.13378
2489.54	4.95799
2492.31	4.98286
2495.08	5.1681
2497.84	4.23389
2500.61	6.06429
2503.37	5.21869
2506.13	5.16074
2508.9	5.20796
2511.66	6.17875
2514.42	4.96123
2517.18	6.01178
2519.93	7.45571
2522.69	8.44828
2525.45	9.41735
2528.2	10.3658
2530.95	12.4029
2533.71	13.1844
2536.46	14.8804
2539.21	14.5642
2541.96	15.0813
2544.71	16.2593
2547.46	17.9812
2550.2	18.5042
2552.95	18.3678
2555.7	18.8304
2558.44	17.8767
2561.18	17.0354
2563.93	16.7419
2566.67	16.0265
2569.41	14.2232
2572.15	10.5582
2574.88	9.97589
2577.62	9.46409
2580.36	9.09882
2583.09	6.60379
2585.83	7.07326
2588.56	7.14782
2591.29	5.21912
2594.02	2.87682
2596.75	4.3307
2599.48	2.54081
2602.21	4.39757
2604.94	5.50625
2607.67	5.2586
2610.39	6.2124
2613.12	6.80918
2615.84	8.44783
2618.56	9.73571
2621.28	10.1578
2624.01	9.42654
2626.72	9.54381
2629.44	9.28968
2632.16	9.08798
2634.88	10.4938
2637.59	11.293
2640.31	11.2963
2643.02	13.6501
2645.74	13.1117
2648.45	11.373
2651.16	13.3858
2653.87	12.975
2656.58	12.3501
2659.29	13.0728
2661.99	12.5901
2664.7	12.0987
2667.41	11.1882
2670.11	11.614
2672.81	8.85193
2675.51	9.68276
2678.22	8.96168
2680.92	7.98717
2683.62	8.5731
2686.31	8.43851
2689.01	7.90289
2691.71	8.79886
2694.4	9.33875
2697.1	10.0216
2699.79	11.7545
2702.49	15.6511
2705.18	17.1427
2707.87	19.3545
2710.56	21.5328
2713.25	23.2349
2715.94	25.8147
2718.62	28.5036
2721.31	29.346
2723.99	30.6913
2726.68	31.6412
2729.36	30.4735
2732.04	30.6966
2734.73	30.4208
2737.41	28.3484
2740.08	27.1731
2742.76	25.7171
2745.44	22.161
2748.12	19.6082
2750.79	17.7642
2753.47	17.1352
2756.14	14.5996
2758.81	11.8989
2761.49	9.90767
2764.16	9.46555
2766.83	8.01234
2769.5	7.71325
2772.16	6.58285
2774.83	4.79506
2777.5	4.3396
2780.16	3.1865
2782.83	2.83423
2785.49	0.922806
2788.15	0.678464
2790.82	-0.0580236
2793.48	-0.642866
2796.14	-1.06434
2798.79	-1.0424
2801.45	-1.80393
2804.11	-2.51368
2806.76	-3.55079
2809.42	-5.11766
2812.07	-4.53867
2814.73	-2.35395
2817.38	4.24936
2820.03	12.1513
2822.68	20.4901
2825.33	31.3356
2827.98	43.7282
2830.63	55.7535
2833.27	69.6322
2835.92	83.6312
2838.56	101.874
2841.21	120.165
2843.85	143.781
2846.49	169.942
2849.13	197.346
2851.77	225.419
2854.41	256.401
2857.05	286.165
2859.69	315.165
2862.32	340.723
2864.96	365.964
2867.59	387.197
2870.23	407.554
2872.86	425.827
2875.49	442.915
2878.12	458.014
2880.75	472.35
2883.38	482.017
2886.01	493.067
2888.63	502.733
2891.26	511.964
2893.89	519.816
2896.51	528.982
2899.13	541.587
2901.76	558.726
2904.38	579.389
2907	603.833
2909.62	632.842
2912.24	661.866
2914.85	690.314
2917.47	719.258
2920.09	744.065
2922.7	764.124
2925.32	780.305
2927.93	789.061
2930.54	792.517
2933.15	792.626
2935.76	787.155
2938.37	772.125
2940.98	753.706
2943.59	729.253
2946.2	700.903
2948.8	672.129
2951.41	639.8
2954.01	606.329
2956.62	574.296
2959.22	541.28
2961.82	510.193
2964.42	482.204
2967.02	456.072
2969.62	431.084
2972.22	407.17
2974.81	385.558
2977.41	364.344
2980	342.164
2982.6	318.2
2985.19	294.014
2987.78	269.571
2990.38	243.972
2992.97	218.864
2995.56	196.549
2998.14	173.286
3000.73	149.897
3003.32	127.58
3005.91	107.464
3008.49	88.4268
3011.07	70.587
3013.66	54.55
3016.24	42.888
3018.82	31.9232
3021.4	23.0238
3023.98	14.3879
3026.56	9.30871
3029.14	6.02314
3031.71	3.135
3034.29	2.69444
3036.87	4.62423
3039.44	7.64835
3042.01	10.6983
3044.59	13.0062
3047.16	14.3751
3049.73	17.7485
3052.3	18.6801
3054.87	20.5395
3057.43	21.8855
3060	22.8328
3062.57	21.9714
3065.13	22.3489
3067.7	20.7812
3070.26	18.5581
3072.82	17.5075
3075.39	13.8322
3077.95	12.1245
3080.51	8.28036
3083.07	4.52049
3085.63	1.50765
3088.18	-0.508297
3090.74	-1.2692
3093.29	-1.32278
3095.85	-1.09416
3098.4	-0.366398
3100.95	2.11058
3103.51	2.9647
3106.06	5.45948
3108.61	6.78993
3111.16	9.32876
3113.71	11.17
3116.25	13.5194
3118.8	17.737
3121.35	20.8997
3123.89	24.2296
3126.44	27.7596
3128.98	31.2219
3131.52	34.1092
3134.06	37.4022
3136.6	40.3915
3139.14	43.8874
3141.68	46.961
3144.22	50.7277
3146.76	54.4925
3149.29	57.1244