File: data/Raman/poly_smoothed/Mb_00_13_37_1x_45s_532 nm_x100_100%_600 gr_mm_01.txt
#Acq. time (s)=	45
#Accumulations=	2
#Range (cm-¹)=	200...3150
#Windows=	2
#Auto scanning=	Off
#Autofocus=	Off
#Macrospot=	Off
#AutoExposure=	Off
#Spike filter=	Multiple accum.
#Delay time (s)=	0
#Binning=	1
#Readout mode=	Signal
#DeNoise=	Off
#ICS correction=	On
#Dark correction=	Off
#Inst. Process=	Off
#Detector Gain=	Best Dynamic Range
#Detector ADC=	20 kHz
#Detector temperature (°C)=	-69.85
#Instrument=	LabRAM HR Evol
#Detector=	Synapse
#Objective=	x100
#Grating=	600 gr/mm
#ND Filter=	100%
#Laser (nm)=	532
#Hole=	100.021
#Range=	Auto
#Laser Pol.=	No
#Raman. Pol.=	No
#Laser Pol. (°)=	-0.0007625
#Raman Pol. (°)=	89.9995
#Collection=	Microscope
#StageXY=	Marzhauser
#StageZ=	Marzhauser
#X (µm)=	-1019.8
#Y (µm)=	-2895.7
#Z (µm)=	528.75
#Full time(mm:ss)=	3:18
#Project=
#Sample=
#Site=
#Title=	Mb_00_13_37_2x_45s_532 nm_x100_100%_600 gr_mm
#Remark=
#Date=	06.07.2022 12:43
#Acquired=	06.07.2022 12:43:36
#Base:Fit=	10.08.2022 10:16:56
#Base:Sub=	10.08.2022 10:17:24
#Filter:Polynom=	16.08.2022 10:36:38
#AxisType[0]=Intens
#AxisUnit[0]=Cnt
#AxisType[1]=Spectr
#AxisUnit[1]=1/cm
200.398	14.2835
204.027	5.17124
207.657	-2.68265
211.283	-8.59238
214.909	-6.67549
218.533	0.393903
222.157	15.704
225.777	36.0691
229.396	58.5112
233.016	82.9715
236.632	107.74
240.247	126.226
243.86	143.324
247.474	161.056
251.085	176.051
254.694	191.201
258.301	203.037
261.908	207.73
265.513	208.356
269.116	206.781
272.718	201.729
276.319	193.302
279.918	179.633
283.516	160.47
287.113	141.11
290.708	121.867
294.302	103.692
297.894	87.5583
301.485	76.4726
305.073	66.2534
308.661	58.7343
312.247	52.6553
315.833	48.5887
319.415	45.584
322.997	42.774
326.579	40.1824
330.156	37.5387
333.735	36.5571
337.31	34.4624
340.885	30.0716
344.458	26.2724
348.03	21.584
351.6	16.6675
355.17	11.2731
358.737	7.26384
362.304	2.33777
365.868	-0.678476
369.431	-0.782724
372.994	4.20253
376.554	10.2221
380.112	16.5945
383.669	30.5157
387.225	45.6557
390.781	67.8516
394.334	86.7811
397.885	105.803
401.436	121.564
404.984	133.832
408.532	144.048
412.078	150.989
415.623	155.878
419.166	156.451
422.708	153.038
426.248	144.976
429.788	134.305
433.326	120.531
436.86	105.471
440.395	87.5529
443.929	70.1892
447.461	55.61
450.99	41.6711
454.52	29.2687
458.048	18.0854
461.573	8.58641
465.099	2.91795
468.623	4.11296
472.144	7.53126
475.666	12.6806
479.184	17.4029
482.703	18.1853
486.218	20.1741
489.734	22.1679
493.247	24.6226
496.759	27.7774
500.271	28.5758
503.779	30.6091
507.287	32.4858
510.795	33.5605
514.299	35.4529
517.803	36.3116
521.305	39.0205
524.805	40.3117
528.307	41.5231
531.805	41.4575
535.301	40.5316
538.797	36.9279
542.291	34.5146
545.783	31.8754
549.275	28.8231
552.765	27.0879
556.253	22.9542
559.738	20.774
563.224	18.5529
566.709	14.9505
570.192	12.3448
573.674	11.1932
577.153	7.11568
580.632	5.47561
584.11	3.57632
587.587	3.68701
591.06	1.84605
594.534	1.50064
598.005	2.7903
601.476	3.04625
604.944	2.77581
608.413	4.21305
611.878	3.73748
615.344	3.91281
618.807	3.87392
622.27	4.52621
625.73	5.44188
629.189	8.37941
632.648	13.7888
636.105	17.7804
639.559	23.1822
643.013	29.0412
646.467	34.8413
649.918	38.5676
653.368	41.3273
656.816	41.4193
660.263	41.1503
663.708	40.7303
667.153	40.0249
670.596	38.844
674.037	37.5924
677.478	33.928
680.917	30.3554
684.355	28.9109
687.791	24.9717
691.224	21.023
694.658	16.6679
698.091	11.6742
701.522	9.67197
704.95	6.9208
708.379	5.75857
711.806	4.15948
715.23	5.70118
718.655	7.50788
722.078	8.01751
725.498	8.64873
728.919	9.63888
732.337	11.749
735.755	11.2986
739.17	11.8039
742.584	15.0779
745.998	18.9667
749.409	24.6587
752.819	29.6067
756.23	32.0397
759.637	35.3164
763.043	40.9541
766.448	44.3405
769.853	50.3002
773.255	53.0924
776.656	57.1786
780.056	60.3036
783.454	62.4587
786.851	65.0989
790.247	66.4741
793.641	67.1652
797.034	65.9255
800.426	65.8476
803.817	65.2446
807.206	64.9945
810.592	61.9748
813.979	62.2494
817.364	60.4855
820.748	59.1066
824.129	59.1271
827.511	57.9312
830.891	56.856
834.269	54.9106
837.646	51.4697
841.023	47.8492
844.396	43.9994
847.77	41.3718
851.141	38.3698
854.513	35.7872
857.881	33.2696
861.248	32.9729
864.616	29.3694
867.98	25.8792
871.343	25.7966
874.707	25.4038
878.068	23.568
881.428	22.4421
884.786	23.6053
888.143	24.8335
891.498	25.5551
894.855	27.1196
898.208	27.8495
901.56	30.0303
904.91	33.1527
908.26	35.341
911.608	36.5693
914.955	38.5219
918.298	36.7738
921.643	35.6889
924.986	36.41
928.328	37.8188
931.668	36.8954
935.006	35.0478
938.344	31.9417
941.681	30.762
945.014	29.985
948.349	29.1158
951.682	28.0455
955.012	26.7475
958.343	26.2532
961.67	27.7022
964.998	31.049
968.323	35.3908
971.649	36.9954
974.971	38.7163
978.293	40.4146
981.615	43.8694
984.933	46.2053
988.251	50.4679
991.567	51.6887
994.884	54.4208
998.198	55.7979
1001.51	55.3666
1004.82	57.4784
1008.13	58.2846
1011.44	54.9035
1014.75	50.7265
1018.06	52.8232
1021.36	60.374
1024.66	75.0711
1027.97	92.2833
1031.27	108.068
1034.57	124.744
1037.87	141.962
1041.16	157.398
1044.46	168.661
1047.76	175.712
1051.05	179.492
1054.34	181.245
1057.63	182.09
1060.92	180.79
1064.21	177.018
1067.5	168.662
1070.78	156.586
1074.07	141.754
1077.35	125.227
1080.63	105.495
1083.91	84.3817
1087.19	65.7648
1090.47	47.5849
1093.75	32.6449
1097.03	21.8797
1100.3	16.058
1103.57	16.7746
1106.84	18.9851
1110.11	17.5673
1113.38	16.0649
1116.65	14.3277
1119.92	12.1765
1123.19	10.2195
1126.45	8.24449
1129.71	6.61014
1132.97	6.29184
1136.23	6.26895
1139.49	7.44068
1142.75	7.14999
1146.01	6.15474
1149.26	6.62389
1152.52	6.63778
1155.77	7.07275
1159.02	7.09365
1162.27	8.07132
1165.52	11.0825
1168.77	12.6793
1172.02	14.1943
1175.26	13.0228
1178.51	13.2755
1181.75	12.9226
1184.99	16.2067
1188.23	16.0014
1191.47	17.9637
1194.71	21.3565
1197.94	23.8575
1201.18	24.685
1204.41	28.3629
1207.65	31.0791
1210.88	32.5087
1214.11	34.6749
1217.34	38.1258
1220.57	39.4204
1223.79	42.9304
1227.02	46.0657
1230.24	49.2961
1233.47	48.8702
1236.69	50.8613
1239.91	50.7754
1243.13	51.3405
1246.34	47.9568
1249.56	48.0607
1252.78	45.146
1255.99	42.2144
1259.2	40.6234
1262.42	40.1948
1265.63	40.2065
1268.84	41.1215
1272.04	41.596
1275.25	42.2637
1278.46	43.0784
1281.66	45.951
1284.86	46.4544
1288.07	47.6406
1291.27	51.0867
1294.47	53.3596
1297.66	56.3042
1300.86	59.6229
1304.06	61.5507
1307.25	61.6129
1310.44	61.9429
1313.64	62.3813
1316.83	62.9275
1320.02	62.2847
1323.2	60.9075
1326.39	60.0065
1329.58	57.9923
1332.76	55.6463
1335.95	53.8414
1339.13	53.2538
1342.31	51.8611
1345.49	52.5886
1348.67	51.6503
1351.85	52.8972
1355.02	51.339
1358.2	50.2085
1361.37	51.8088
1364.54	52.3745
1367.71	54.1705
1370.88	54.5876
1374.05	58.0038
1377.22	58.0941
1380.39	60.5283
1383.55	60.8251
1386.72	63.6456
1389.88	64.4335
1393.04	65.3223
1396.2	67.5704
1399.36	68.6853
1402.52	70.1739
1405.68	73.7984
1408.83	76.4012
1411.98	79.8839
1415.14	84.3859
1418.29	89.0133
1421.44	93.4357
1424.59	100.586
1427.74	104.411
1430.89	109.236
1434.03	114.295
1437.18	119.94
1440.32	122.538
1443.46	124.922
1446.6	125.619
1449.74	125.941
1452.88	124.188
1456.02	123.148
1459.16	118.092
1462.29	112.304
1465.43	104.873
1468.56	98.3134
1471.69	91.2198
1474.82	85.5408
1477.95	78.4497
1481.08	71.6782
1484.2	66.1654
1487.33	61.0567
1490.46	54.5209
1493.58	49.542
1496.7	47.7919
1499.82	43.9974
1502.94	42.7758
1506.06	42.9789
1509.18	43.2629
1512.29	44.245
1515.41	43.9393
1518.52	44.6338
1521.63	46.5358
1524.75	45.5172
1527.85	46.5538
1530.96	49.4739
1534.07	50.222
1537.18	53.2615
1540.28	54.7867
1543.39	56.884
1546.49	58.874
1549.59	61.4179
1552.69	62.7979
1555.79	64.4727
1558.89	67.6228
1561.99	69.9241
1565.08	70.3571
1568.18	71.6312
1571.27	73.2994
1574.37	75.0765
1577.46	76.0133
1580.55	79.14
1583.64	79.9689
1586.73	79.0369
1589.81	78.9232
1592.9	78.3538
1595.98	75.9337
1599.06	74.1513
1602.15	71.0552
1605.23	69.5128
1608.31	67.6132
1611.39	63.6115
1614.46	60.0817
1617.54	55.3002
1620.61	51.4407
1623.69	47.9362
1626.76	43.8626
1629.83	40.2704
1632.9	36.8447
1635.97	34.0626
1639.04	31.6426
1642.11	30.0203
1645.17	28.9717
1648.24	26.8613
1651.3	25.3675
1654.36	24.2461
1657.42	22.4631
1660.48	20.7261
1663.54	21.1365
1666.6	20.0292
1669.66	18.2097
1672.71	16.1266
1675.77	15.062
1678.82	13.9688
1681.87	12.5187
1684.92	10.9613
1687.97	9.44758
1691.02	9.47749
1694.07	7.69375
1697.11	7.3409
1700.16	6.22427
1703.2	5.56801
1706.25	4.3048
1709.29	4.16903
1712.33	2.79551
1715.37	2.76327
1718.41	2.12133
1721.44	2.04267
1724.48	2.0482
1727.51	2.96081
1730.55	3.11423
1733.58	3.34581
1736.61	4.70002
1739.64	4.77834
1742.67	4.53518
1745.7	3.29881
1748.72	3.528
1751.75	3.97491
1754.77	3.70638
1757.8	3.49397
1760.82	2.45459
1763.84	2.63957
1766.86	3.96022
1769.88	3.45555
1772.9	3.79596
1775.91	2.36294
1778.93	1.94389
1781.94	1.73893
1784.96	2.4547
1787.97	2.7613
1790.98	2.10255
1793.99	1.98175
1797	2.35036
1800.01	1.73472
1803.01	2.0752
1806.02	2.43839
1809.02	3.27098
1812.02	3.88668
1815.02	4.11764
1818.03	3.43798
1821.02	2.60824
1824.02	2.255
1827.02	3.26034
1830.02	3.83425
1833.01	3.73285
1836.01	4.82632
1839	6.0333
1841.99	6.2233
1844.98	6.26058
1847.97	4.24012
1850.96	5.29172
1853.95	5.19055
1856.93	4.90095
1859.92	3.89212
1862.9	2.24756
1865.88	2.19884
1868.87	1.35973
1871.85	1.58824
1874.83	1.25163
1877.81	1.9824
1880.78	3.6393
1882.53	5.07749
1885.52	5.94324
1888.51	6.22098
1891.5	7.12625
1894.48	8.08711
1897.47	10.4539
1900.45	11.8365
1903.43	13.329
1906.41	12.4479
1909.39	14.1896
1912.37	12.7804
1915.35	12.6471
1918.33	10.2148
1921.3	10.1541
1924.28	9.1807
1927.25	8.66717
1930.22	7.69973
1933.19	6.39523
1936.16	6.82596
1939.13	4.91511
1942.1	6.39893
1945.07	6.76946
1948.03	7.62473
1951	10.3611
1953.96	11.1355
1956.92	11.7741
1959.88	11.2762
1962.84	12.5462
1965.8	13.1859
1968.76	13.9692
1971.72	13.1704
1974.67	11.0272
1977.63	9.84334
1980.58	8.36167
1983.54	8.73246
1986.49	8.13176
1989.44	8.24163
1992.39	8.29328
1995.33	6.97633
1998.28	7.11873
2001.23	7.01955
2004.17	5.48334
2007.12	6.58167
2010.06	7.76038
2013	8.28632
2015.94	9.07951
2018.88	8.44053
2021.82	10.7345
2024.76	10.9725
2027.69	11.446
2030.63	10.266
2033.56	10.8646
2036.5	10.1425
2039.43	10.0756
2042.36	8.83755
2045.29	9.15315
2048.22	8.69162
2051.15	10.3095
2054.07	11.0194
2057	10.2876
2059.92	11.0873
2062.85	9.97828
2065.77	7.1151
2068.69	6.09134
2071.61	6.30223
2074.53	6.27959
2077.45	6.56614
2080.37	7.03261
2083.28	7.00157
2086.2	5.50516
2089.11	6.23319
2092.02	7.68985
2094.94	6.74454
2097.85	6.41998
2100.76	7.45625
2103.66	7.46463
2106.57	8.37967
2109.48	9.69245
2112.38	10.0959
2115.29	12.0099
2118.19	12.9035
2121.09	13.3451
2123.99	13.9222
2126.89	14.5341
2129.79	13.8654
2132.69	14.0066
2135.59	14.7228
2138.48	14.4345
2141.38	14.7697
2144.27	14.4648
2147.17	15.0795
2150.06	14.49
2152.95	14.6191
2155.84	13.146
2158.73	11.6853
2161.61	11.5462
2164.5	10.3501
2167.38	10.7179
2170.27	10.1513
2173.15	8.85096
2176.03	8.29497
2178.91	8.63417
2181.8	8.25739
2184.67	7.83419
2187.55	9.47329
2190.43	9.80072
2193.3	9.71465
2196.18	11.7574
2199.05	11.8475
2201.93	11.3858
2204.8	12.0177
2207.67	12.3599
2210.54	10.9443
2213.41	11.9153
2216.27	12.2352
2219.14	11.3096
2222.01	10.9298
2224.87	11.2796
2227.73	11.1218
2230.6	11.6607
2233.46	11.857
2236.32	12.781
2239.18	11.9379
2242.03	11.0597
2244.89	11.8635
2247.75	13.7276
2250.6	14.3885
2253.46	13.4159
2256.31	13.3679
2259.16	14.3363
2262.01	12.7636
2264.86	11.52
2267.71	9.30149
2270.56	9.12385
2273.4	10.4196
2276.25	10.811
2279.09	9.83363
2281.94	10.5031
2284.78	10.7737
2287.62	11.5454
2290.46	13.0215
2293.3	12.7255
2296.14	14.0959
2298.98	15.3364
2301.82	14.8327
2304.65	16.7934
2307.49	16.8813
2310.32	16.3861
2313.15	16.7902
2315.98	18.7069
2318.81	18.3294
2321.64	17.2188
2324.47	15.7581
2327.3	15.3701
2330.12	13.973
2332.95	12.4753
2335.77	9.97425
2338.6	9.54212
2341.42	10.9224
2344.24	9.9754
2347.06	6.52194
2349.88	6.54977
2352.7	6.5641
2355.51	6.10456
2358.33	5.87418
2361.14	4.07099
2363.96	4.24035
2366.77	4.68668
2369.58	2.12173
2372.39	0.751817
2375.2	1.08817
2378.01	0.601522
2380.82	0.744725
2383.63	1.26147
2386.43	2.1446
2389.24	1.78682
2392.04	2.96291
2394.84	2.12307
2397.65	1.56984
2400.45	1.43621
2403.25	3.71041
2406.05	2.45913
2408.84	4.35861
2411.64	6.29844
2414.44	7.17964
2417.23	10.1132
2420.02	12.7061
2422.82	13.5286
2425.61	13.4017
2428.4	13.5098
2431.19	14.8874
2433.98	13.9339
2436.77	13.6765
2439.55	14.4983
2442.34	15.3473
2445.12	15.6389
2447.91	15.2355
2450.69	16.2323
2453.47	13.9175
2456.25	13.311
2459.03	10.6091
2461.81	10.2521
2464.59	8.16426
2467.36	8.45883
2470.14	8.30235
2472.92	7.90195
2475.69	8.11855
2478.46	8.12376
2481.23	8.41279
2484	8.62582
2486.77	6.72833
2489.54	6.01983
2492.31	3.81642
2495.08	5.76476
2497.84	6.77053
2500.61	5.68512
2503.37	3.24236
2506.13	4.8307
2508.9	3.59404
2511.66	3.18184
2514.42	4.4344
2517.18	6.37063
2519.93	5.64993
2522.69	5.63914
2525.45	7.3477
2528.2	8.00873
2530.95	9.47619
2533.71	10.7673
2536.46	13.0756
2539.21	13.8462
2541.96	13.9275
2544.71	14.397
2547.46	13.5724
2550.2	15.4958
2552.95	15.1811
2555.7	15.9455
2558.44	16.0222
2561.18	15.9473
2563.93	17.4645
2566.67	16.1676
2569.41	15.6014
2572.15	16.4402
2574.88	16.3666
2577.62	16.8102
2580.36	16.8657
2583.09	19.6532
2585.83	20.1449
2588.56	18.7719
2591.29	18.4516
2594.02	16.8756
2596.75	15.8039
2599.48	15.8094
2602.21	16.9848
2604.94	16.0201
2607.67	13.9756
2610.39	12.0771
2613.12	11.4498
2615.84	8.37923
2618.56	7.94352
2621.28	7.3701
2624.01	7.28365
2626.72	8.01929
2629.44	7.46631
2632.16	6.51722
2634.88	7.6489
2637.59	7.56202
2640.31	8.22745
2643.02	6.87045
2645.74	6.62177
2648.45	6.50171
2651.16	6.9406
2653.87	7.22736
2656.58	7.38396
2659.29	7.62052
2661.99	9.68564
2664.7	12.1092
2667.41	14.1973
2670.11	14.6116
2672.81	15.1437
2675.51	15.8399
2678.22	16.738
2680.92	16.8321
2683.62	17.3557
2686.31	19.4533
2689.01	19.8601
2691.71	21.2994
2694.4	21.0375
2697.1	18.9988
2699.79	19.5262
2702.49	21.3533
2705.18	21.5475
2707.87	20.6652
2710.56	21.3791
2713.25	21.7528
2715.94	22.5247
2718.62	23.0437
2721.31	23.7458
2723.99	22.1272
2726.68	22.9585
2729.36	22.2427
2732.04	21.0811
2734.73	19.9616
2737.41	18.4858
2740.08	16.645
2742.76	15.1501
2745.44	13.5858
2748.12	12.1782
2750.79	11.4554
2753.47	9.58839
2756.14	8.17653
2758.81	7.09715
2761.49	5.45498
2764.16	5.81622
2766.83	7.82473
2769.5	8.37757
2772.16	7.54682
2774.83	8.05932
2777.5	7.99218
2780.16	8.74061
2782.83	7.34913
2785.49	6.65532
2788.15	5.34044
2790.82	3.3915
2793.48	2.36204
2796.14	0.920074
2798.79	1.62865
2801.45	-0.227363
2804.11	-1.05595
2806.76	-2.94968
2809.42	-2.5717
2812.07	-3.56323
2814.73	-1.48058
2817.38	0.455156
2820.03	7.09333
2822.68	15.2503
2825.33	22.6743
2827.98	32.8984
2830.63	42.9615
2833.27	54.2873
2835.92	61.5554
2838.56	70.657
2841.21	80.6123
2843.85	89.6102
2846.49	96.6137
2849.13	104.136
2851.77	113.037
2854.41	120.569
2857.05	127.488
2859.69	132.423
2862.32	138.77
2864.96	141.679
2867.59	144.111
2870.23	146.058
2872.86	146.574
2875.49	148.351
2878.12	150.305
2880.75	152.913
2883.38	155.384
2886.01	157.162
2888.63	155.176
2891.26	155.541
2893.89	154.809
2896.51	151.55
2899.13	149.992
2901.76	147.849
2904.38	146.465
2907	146.282
2909.62	146.901
2912.24	147.99
2914.85	150.043
2917.47	152.175
2920.09	153.226
2922.7	153.677
2925.32	154.553
2927.93	153.452
2930.54	153.744
2933.15	152.079
2935.76	148.839
2938.37	145.828
2940.98	140.974
2943.59	136.369
2946.2	130.656
2948.8	123
2951.41	114.369
2954.01	104.735
2956.62	98.1669
2959.22	88.9914
2961.82	82.0974
2964.42	74.4545
2967.02	67.6031
2969.62	62.9666
2972.22	57.4235
2974.81	51.5495
2977.41	46.54
2980	41.9538
2982.6	38.0139
2985.19	33.3637
2987.78	30.4467
2990.38	27.3272
2992.97	23.58
2995.56	21.6424
2998.14	19.1492
3000.73	16.5724
3003.32	14.6423
3005.91	11.9502
3008.49	10.4607
3011.07	8.24978
3013.66	7.1848
3016.24	6.46201
3018.82	4.34252
3021.4	3.94144
3023.98	3.2291
3026.56	2.73918
3029.14	2.37776
3031.71	2.44495
3034.29	1.3312
3036.87	1.64161
3039.44	2.46276
3042.01	1.42094
3044.59	3.04959
3047.16	4.13189
3049.73	5.87339
3052.3	6.71394
3054.87	7.3276
3057.43	9.04217
3060	8.14101
3062.57	9.15154
3065.13	10.4058
3067.7	12.2067
3070.26	13.9232
3072.82	16.4033
3075.39	19.0643
3077.95	21.9384
3080.51	23.6137
3083.07	25.7054
3085.63	29.4265
3088.18	31.9027
3090.74	34.9341
3093.29	36.9478
3095.85	40.8053
3098.4	43.4098
3100.95	47.5866
3103.51	49.9628
3106.06	55.1385
3108.61	58.6548
3111.16	61.8761
3113.71	65.8603
3116.25	70.1524
3118.8	73.4844
3121.35	76.0395
3123.89	80.8655
3126.44	86.1686
3128.98	91.1098
3131.52	96.1078
3134.06	100.008
3136.6	104.893
3139.14	110.472
3141.68	115.235
3144.22	120.316
3146.76	125.56
3149.29	131.667