File: data/Raman/poly_smoothed/Mb_00_13_32_1x_45s_532 nm_x100_100%_600 gr_mm_03.txt
#Acq. time (s)=	45
#Accumulations=	2
#Range (cm-¹)=	200...3150
#Windows=	2
#Auto scanning=	Off
#Autofocus=	Off
#Macrospot=	Off
#AutoExposure=	Off
#Spike filter=	Multiple accum.
#Delay time (s)=	0
#Binning=	1
#Readout mode=	Signal
#DeNoise=	Off
#ICS correction=	On
#Dark correction=	Off
#Inst. Process=	Off
#Detector Gain=	Best Dynamic Range
#Detector ADC=	20 kHz
#Detector temperature (°C)=	-69.85
#Instrument=	LabRAM HR Evol
#Detector=	Synapse
#Objective=	x100
#Grating=	600 gr/mm
#ND Filter=	100%
#Laser (nm)=	532
#Hole=	100.021
#Range=	Auto
#Laser Pol.=	No
#Raman. Pol.=	No
#Laser Pol. (°)=	-0.0007625
#Raman Pol. (°)=	89.9995
#Collection=	Microscope
#StageXY=	Marzhauser
#StageZ=	Marzhauser
#X (µm)=	-1003
#Y (µm)=	-2827.3
#Z (µm)=	528.3
#Full time(mm:ss)=	3:18
#Project=
#Sample=
#Site=
#Title=	Mb_00_13_32_2x_45s_532 nm_x100_100%_600 gr_mm
#Remark=
#Date=	06.07.2022 12:19
#Acquired=	06.07.2022 12:19:00
#Base:Fit=	10.08.2022 10:16:56
#Base:Sub=	10.08.2022 10:17:24
#Filter:Polynom=	16.08.2022 10:36:38
#AxisType[0]=Intens
#AxisUnit[0]=Cnt
#AxisType[1]=Spectr
#AxisUnit[1]=1/cm
200.398	29.9968
204.027	18.0303
207.657	3.69925
211.283	-6.6615
214.909	-9.93438
218.533	-6.28619
222.157	8.55386
225.777	26.0711
229.396	44.9462
233.016	61.2908
236.632	79.2374
240.247	95.3817
243.86	109.086
247.474	122.515
251.085	134.981
254.694	147.314
258.301	154.079
261.908	159.262
265.513	161.165
269.116	160.305
272.718	156.869
276.319	149.099
279.918	137.24
283.516	120.345
287.113	104.916
290.708	88.4805
294.302	72.3555
297.894	60.1231
301.485	49.8864
305.073	43.1949
308.661	38.1276
312.247	32.9922
315.833	28.1753
319.415	23.1452
322.997	20.6301
326.579	19.5592
330.156	13.7882
333.735	11.7231
337.31	8.3605
340.885	6.53762
344.458	5.7335
348.03	5.45599
351.6	5.30047
355.17	4.14403
358.737	1.68122
362.304	2.53474
365.868	8.4062
369.431	15.4494
372.994	21.7476
376.554	30.5797
380.112	40.2769
383.669	56.7882
387.225	75.4195
390.781	97.1063
394.334	113.223
397.885	126.887
401.436	138.225
404.984	148.784
408.532	156.258
412.078	157.813
415.623	156.939
419.166	154.313
422.708	148.52
426.248	141.549
429.788	130.812
433.326	116.325
436.86	100.344
440.395	81.8492
443.929	66.3057
447.461	54.3166
450.99	44.0673
454.52	35.048
458.048	25.285
461.573	22.2063
465.099	20.6601
468.623	24.1129
472.144	29.467
475.666	33.9133
479.184	38.2723
482.703	39.1057
486.218	43.8354
489.734	49.4697
493.247	53.7289
496.759	56.224
500.271	61.5072
503.779	66.3005
507.287	67.6699
510.795	67.9434
514.299	69.3507
517.803	70.0098
521.305	71.9462
524.805	72.0745
528.307	73.5575
531.805	74.4535
535.301	73.1219
538.797	71.2894
542.291	67.9218
545.783	63.9442
549.275	57.8731
552.765	52.5356
556.253	49.2227
559.738	45.2617
563.224	41.7881
566.709	37.588
570.192	34.9293
573.674	30.283
577.153	27.893
580.632	23.3831
584.11	20.2017
587.587	18.2252
591.06	12.6835
594.534	11.8863
598.005	9.98311
601.476	11.0813
604.944	9.53367
608.413	8.89579
611.878	8.08327
615.344	6.20345
618.807	4.69776
622.27	5.7947
625.73	7.12429
629.189	7.90406
632.648	9.66521
636.105	17.67
639.559	23.8543
643.013	28.9609
646.467	31.5103
649.918	36.0543
653.368	35.3653
656.816	36.469
660.263	34.8984
663.708	34.5714
667.153	32.3845
670.596	33.1596
674.037	30.6054
677.478	27.1776
680.917	24.6843
684.355	19.9696
687.791	12.8696
691.224	9.55545
694.658	5.37241
698.091	3.07664
701.522	2.52335
704.95	3.68802
708.379	4.97091
711.806	5.75957
715.23	8.24088
718.655	10.3998
722.078	14.0838
725.498	13.3392
728.919	13.6314
732.337	14.7608
735.755	15.8214
739.17	18.3016
742.584	19.9786
745.998	21.8855
749.409	24.8939
752.819	27.9457
756.23	31.2281
759.637	31.592
763.043	32.9281
766.448	33.3615
769.853	35.7673
773.255	38.0201
776.656	41.0047
780.056	42.7365
783.454	45.6269
786.851	43.6555
790.247	43.5442
793.641	40.9728
797.034	41.1748
800.426	40.9112
803.817	40.8505
807.206	39.5475
810.592	36.7748
813.979	36.6996
817.364	38.6175
820.748	40.5115
824.129	40.4416
827.511	41.3767
830.891	41.6908
834.269	42.1589
837.646	42.4015
841.023	41.5898
844.396	41.8406
847.77	39.1463
851.141	38.7151
854.513	35.3928
857.881	34.4446
861.248	30.0946
864.616	27.5971
867.98	24.3875
871.343	23.8267
874.707	20.5535
878.068	20.4347
881.428	19.1505
884.786	16.959
888.143	12.6825
891.498	11.1207
894.855	12.6148
898.208	14.2245
901.56	14.2742
904.91	12.0669
908.26	9.71351
911.608	9.65652
914.955	9.0677
918.298	9.13292
921.643	10.1386
924.986	11.2461
928.328	11.4612
931.668	11.8642
935.006	12.4405
938.344	11.4709
941.681	11.5413
945.014	10.0119
948.349	12.1157
951.682	12.2459
955.012	12.9645
958.343	9.08054
961.67	11.3995
964.998	14.889
968.323	19.5557
971.649	28.8707
974.971	39.6695
978.293	50.5793
981.615	59.9087
984.933	64.9324
988.251	70.8399
991.567	78.3882
994.884	82.6744
998.198	86.3469
1001.51	90.9082
1004.82	92.6711
1008.13	92.4959
1011.44	90.3573
1014.75	89.7378
1018.06	91.2706
1021.36	100.497
1024.66	110.667
1027.97	120.463
1031.27	130.321
1034.57	136.872
1037.87	139.043
1041.16	142.133
1044.46	147.573
1047.76	153.59
1051.05	155.743
1054.34	157.037
1057.63	158.66
1060.92	152.324
1064.21	144.584
1067.5	134.173
1070.78	123.581
1074.07	112.791
1077.35	97.3936
1080.63	80.5661
1083.91	63.901
1087.19	47.8405
1090.47	35.8794
1093.75	31.8042
1097.03	30.901
1100.3	33.671
1103.57	36.031
1106.84	33.574
1110.11	32.5214
1113.38	29.248
1116.65	24.1458
1119.92	21.1536
1123.19	19.0887
1126.45	17.2887
1129.71	18.3724
1132.97	18.4002
1136.23	19.6147
1139.49	17.4498
1142.75	14.6824
1146.01	15.2985
1149.26	13.5532
1152.52	12.5334
1155.77	11.2848
1159.02	9.12949
1162.27	7.64219
1165.52	7.56025
1168.77	10.0251
1172.02	14.025
1175.26	18.7295
1178.51	20.6253
1181.75	20.8193
1184.99	25.2661
1188.23	28.1376
1191.47	33.0431
1194.71	37.8939
1197.94	45.9274
1201.18	51.6251
1204.41	59.9721
1207.65	70.5166
1210.88	80.8093
1214.11	90.2948
1217.34	98.5011
1220.57	106.42
1223.79	113.144
1227.02	120.576
1230.24	126.144
1233.47	133.377
1236.69	136.641
1239.91	139.605
1243.13	139.248
1246.34	140.334
1249.56	141.972
1252.78	140.087
1255.99	137.038
1259.2	133.456
1262.42	128.881
1265.63	126.73
1268.84	124.98
1272.04	124.397
1275.25	123.854
1278.46	125.737
1281.66	131.024
1284.86	135.285
1288.07	140.788
1291.27	145.436
1294.47	152.52
1297.66	158.267
1300.86	164.665
1304.06	171.669
1307.25	178.12
1310.44	186.324
1313.64	192.055
1316.83	198.9
1320.02	200.829
1323.2	201.888
1326.39	200.934
1329.58	201.828
1332.76	199.766
1335.95	198.929
1339.13	194.828
1342.31	192.086
1345.49	189.422
1348.67	183.829
1351.85	179.659
1355.02	176.271
1358.2	170.845
1361.37	165.193
1364.54	156.196
1367.71	149.257
1370.88	144.52
1374.05	139.783
1377.22	134.776
1380.39	132.472
1383.55	130.497
1386.72	130.708
1389.88	129.247
1393.04	128.741
1396.2	126.382
1399.36	123.979
1402.52	124.867
1405.68	128.008
1408.83	135.077
1411.98	144.765
1415.14	153.759
1418.29	165.707
1421.44	180.754
1424.59	193.853
1427.74	209.239
1430.89	225.28
1434.03	241.009
1437.18	250.65
1440.32	260.551
1443.46	266.878
1446.6	271.767
1449.74	274.139
1452.88	272.364
1456.02	271.258
1459.16	263.781
1462.29	251.773
1465.43	238.871
1468.56	222.909
1471.69	206.295
1474.82	190.712
1477.95	175.593
1481.08	160.721
1484.2	146.875
1487.33	136.288
1490.46	124.284
1493.58	115.606
1496.7	106.432
1499.82	102.776
1502.94	100.009
1506.06	96.7868
1509.18	94.3564
1512.29	90.7928
1515.41	84.9787
1518.52	82.1193
1521.63	81.224
1524.75	82.6509
1527.85	82.5362
1530.96	85.5557
1534.07	85.8996
1537.18	86.4467
1540.28	87.3208
1543.39	92.2441
1546.49	95.7185
1549.59	98.2337
1552.69	102.573
1555.79	107.071
1558.89	109.716
1561.99	112.407
1565.08	114.555
1568.18	118.549
1571.27	126.101
1574.37	132.371
1577.46	138.65
1580.55	142.522
1583.64	147.242
1586.73	150.884
1589.81	152.521
1592.9	156.446
1595.98	159.518
1599.06	159.854
1602.15	163.465
1605.23	163.025
1608.31	163.892
1611.39	162.815
1614.46	162.329
1617.54	159.684
1620.61	161.678
1623.69	160.134
1626.76	163.543
1629.83	165.275
1632.9	168.212
1635.97	168.965
1639.04	175.666
1642.11	181.791
1645.17	188.567
1648.24	192.791
1651.3	197.864
1654.36	198.318
1657.42	197.788
1660.48	196.996
1663.54	193.759
1666.6	185.805
1669.66	178.615
1672.71	168.352
1675.77	157.711
1678.82	145.41
1681.87	131.452
1684.92	117.387
1687.97	102.85
1691.02	88.6042
1694.07	78.6313
1697.11	67.1781
1700.16	59.2826
1703.2	51.6101
1706.25	43.4861
1709.29	37.3154
1712.33	35.3822
1715.37	31.8499
1718.41	28.2237
1721.44	27.9858
1724.48	26.0053
1727.51	25.0967
1730.55	23.6772
1733.58	23.8324
1736.61	23.6392
1739.64	21.5901
1742.67	20.4529
1745.7	17.7096
1748.72	16.0902
1751.75	14.9969
1754.77	12.045
1757.8	10.7489
1760.82	8.54181
1763.84	4.86752
1766.86	4.35786
1769.88	2.40218
1772.9	2.82992
1775.91	0.330223
1778.93	-0.798193
1781.94	-2.16698
1784.96	-1.69223
1787.97	-0.77741
1790.98	-0.683555
1793.99	0.344133
1797	1.87011
1800.01	2.42742
1803.01	3.86448
1806.02	3.64174
1809.02	3.1441
1812.02	4.3075
1815.02	6.18116
1818.03	5.41
1821.02	5.07945
1824.02	6.29612
1827.02	5.51847
1830.02	5.84119
1833.01	7.3825
1836.01	5.9918
1839	6.41171
1841.99	6.83892
1844.98	7.64211
1847.97	8.64061
1850.96	7.83197
1853.95	7.9456
1856.93	7.72189
1859.92	7.95685
1862.9	7.43701
1865.88	7.90189
1868.87	9.96762
1871.85	9.66146
1874.83	10.9531
1877.81	9.6665
1880.78	9.81923
1882.53	10.6112
1885.52	11.7102
1888.51	11.644
1891.5	10.7862
1894.48	13.4998
1897.47	14.0938
1900.45	16.8308
1903.43	20.5897
1906.41	20.2648
1909.39	21.12
1912.37	22.2104
1915.35	21.1169
1918.33	20.5244
1921.3	17.7917
1924.28	17.3967
1927.25	16.2323
1930.22	14.7826
1933.19	12.1338
1936.16	8.6702
1939.13	6.24734
1942.1	4.48627
1945.07	3.47043
1948.03	1.55999
1951	0.0625246
1953.96	0.33639
1956.92	-0.345316
1959.88	0.188296
1962.84	0.705184
1965.8	1.47104
1968.76	4.05237
1971.72	6.45235
1974.67	7.84672
1977.63	7.96968
1980.58	8.5934
1983.54	9.52736
1986.49	10.5281
1989.44	10.8505
1992.39	9.93609
1995.33	10.2389
1998.28	10.6378
2001.23	8.12844
2004.17	7.95106
2007.12	5.14948
2010.06	5.67536
2013	5.53337
2015.94	5.21574
2018.88	6.60536
2021.82	7.09708
2024.76	8.23677
2027.69	11.0487
2030.63	12.8013
2033.56	12.5106
2036.5	14.4666
2039.43	15.5563
2042.36	18.4129
2045.29	19.6651
2048.22	21.0119
2051.15	21.2396
2054.07	21.1591
2057	20.6241
2059.92	20.7114
2062.85	18.7934
2065.77	16.7254
2068.69	15.6381
2071.61	15.6171
2074.53	14.4722
2077.45	12.342
2080.37	9.6959
2083.28	8.40376
2086.2	6.95903
2089.11	7.19194
2092.02	9.86929
2094.94	9.73137
2097.85	8.51118
2100.76	9.70056
2103.66	10.0523
2106.57	10.6728
2109.48	12.614
2112.38	13.7295
2115.29	16.2235
2118.19	16.0924
2121.09	16.6558
2123.99	15.7774
2126.89	14.3864
2129.79	15.2599
2132.69	14.5544
2135.59	14.8292
2138.48	15.6979
2141.38	17.5853
2144.27	18.1522
2147.17	19.0771
2150.06	17.5659
2152.95	18.3953
2155.84	21.1609
2158.73	20.1046
2161.61	19.3482
2164.5	19.5254
2167.38	19.4593
2170.27	21.0563
2173.15	22.2844
2176.03	23.1565
2178.91	22.0293
2181.8	22.7557
2184.67	22.3789
2187.55	22.3502
2190.43	19.7494
2193.3	17.8632
2196.18	14.4799
2199.05	14.9192
2201.93	13.0999
2204.8	13.358
2207.67	13.9014
2210.54	14.7095
2213.41	14.3924
2216.27	15.1791
2219.14	15.3536
2222.01	17.3519
2224.87	18.8625
2227.73	19.7843
2230.6	18.7399
2233.46	20.1048
2236.32	19.2977
2239.18	21.3936
2242.03	22.7385
2244.89	21.1707
2247.75	20.2231
2250.6	18.9534
2253.46	20.689
2256.31	20.0598
2259.16	18.3184
2262.01	17.9928
2264.86	17.3748
2267.71	20.3578
2270.56	18.8179
2273.4	17.7321
2276.25	18.3231
2279.09	18.8763
2281.94	16.8226
2284.78	17.8192
2287.62	16.5601
2290.46	15.0016
2293.3	13.6852
2296.14	13.9283
2298.98	13.5493
2301.82	13.2575
2304.65	10.0014
2307.49	8.91591
2310.32	9.46098
2313.15	7.41179
2315.98	5.2016
2318.81	6.15552
2321.64	6.67332
2324.47	6.17339
2327.3	4.4628
2330.12	6.20796
2332.95	5.81344
2335.77	4.79622
2338.6	4.35037
2341.42	4.52815
2344.24	4.49615
2347.06	3.20518
2349.88	2.17636
2352.7	2.79004
2355.51	3.00126
2358.33	1.99486
2361.14	2.27041
2363.96	3.35936
2366.77	4.5925
2369.58	4.70983
2372.39	3.35144
2375.2	3.06096
2378.01	3.69348
2380.82	4.98879
2383.63	3.1155
2386.43	4.69876
2389.24	4.9567
2392.04	6.02463
2394.84	5.18484
2397.65	5.71658
2400.45	4.59342
2403.25	3.89724
2406.05	2.81503
2408.84	4.86834
2411.64	5.62204
2414.44	4.86435
2417.23	6.42935
2420.02	8.26618
2422.82	9.6818
2425.61	9.71637
2428.4	8.83916
2431.19	9.86927
2433.98	10.2305
2436.77	10.0152
2439.55	9.97657
2442.34	9.87246
2445.12	10.7465
2447.91	11.8951
2450.69	11.8465
2453.47	12.0039
2456.25	12.4799
2459.03	12.0167
2461.81	12.1914
2464.59	11.3034
2467.36	10.6644
2470.14	8.83419
2472.92	8.57619
2475.69	7.96298
2478.46	6.82855
2481.23	5.34954
2484	4.39249
2486.77	3.1547
2489.54	2.205
2492.31	1.20555
2495.08	-0.282966
2497.84	0.142491
2500.61	1.3452
2503.37	0.596978
2506.13	2.56856
2508.9	3.14489
2511.66	4.38585
2514.42	5.06081
2517.18	4.43599
2519.93	5.5916
2522.69	5.75018
2525.45	6.91992
2528.2	9.00602
2530.95	10.5556
2533.71	10.3207
2536.46	8.34803
2539.21	8.60877
2541.96	8.62752
2544.71	7.77924
2547.46	7.97245
2550.2	7.05769
2552.95	7.34243
2555.7	7.75219
2558.44	8.78738
2561.18	8.56974
2563.93	8.81977
2566.67	10.5422
2569.41	12.5761
2572.15	11.8335
2574.88	11.4446
2577.62	10.6385
2580.36	10.2415
2583.09	10.3909
2585.83	11.5691
2588.56	13.0244
2591.29	13.1705
2594.02	15.272
2596.75	15.1233
2599.48	14.9917
2602.21	15.5403
2604.94	15.3638
2607.67	15.6735
2610.39	17.9198
2613.12	17.6366
2615.84	18.0545
2618.56	19.6759
2621.28	19.1283
2624.01	19.0598
2626.72	20.1338
2629.44	20.8429
2632.16	21.7218
2634.88	21.8922
2637.59	21.493
2640.31	21.4456
2643.02	21.6249
2645.74	22.2706
2648.45	23.0825
2651.16	23.092
2653.87	20.6208
2656.58	21.1737
2659.29	20.4158
2661.99	20.0269
2664.7	19.1079
2667.41	17.6732
2670.11	17.5737
2672.81	16.8437
2675.51	15.8084
2678.22	15.8893
2680.92	17.1903
2683.62	17.3312
2686.31	17.8319
2689.01	19.2764
2691.71	23.0254
2694.4	25.5811
2697.1	25.5524
2699.79	26.5291
2702.49	28.2192
2705.18	30.7106
2707.87	32.4847
2710.56	35.7696
2713.25	36.749
2715.94	36.6356
2718.62	37.9169
2721.31	38.1569
2723.99	37.7751
2726.68	37.0813
2729.36	36.4507
2732.04	33.4007
2734.73	32.7398
2737.41	30.0784
2740.08	28.4986
2742.76	27.4533
2745.44	26.9132
2748.12	25.5724
2750.79	22.5891
2753.47	20.7876
2756.14	20.2187
2758.81	18.7976
2761.49	16.416
2764.16	13.9235
2766.83	13.4606
2769.5	11.0831
2772.16	8.55518
2774.83	8.18404
2777.5	7.34419
2780.16	7.18221
2782.83	6.78813
2785.49	6.05406
2788.15	5.01763
2790.82	4.58478
2793.48	2.40238
2796.14	0.75093
2798.79	0.801695
2801.45	-0.0915588
2804.11	-0.154145
2806.76	0.104038
2809.42	-1.95932
2812.07	-1.12998
2814.73	0.0829797
2817.38	4.17997
2820.03	11.3912
2822.68	19.7941
2825.33	27.326
2827.98	39.1755
2830.63	49.7815
2833.27	62.5903
2835.92	78.2051
2838.56	95.9592
2841.21	116.267
2843.85	140.117
2846.49	166.601
2849.13	192.859
2851.77	220.432
2854.41	249.177
2857.05	276.322
2859.69	300.786
2862.32	322.544
2864.96	345.221
2867.59	365.32
2870.23	382.493
2872.86	397.11
2875.49	410.505
2878.12	423.484
2880.75	436.006
2883.38	446.847
2886.01	454.391
2888.63	461.235
2891.26	470.81
2893.89	481.404
2896.51	492.844
2899.13	505.254
2901.76	524.981
2904.38	545.68
2907	570.618
2909.62	598.278
2912.24	628.989
2914.85	655.604
2917.47	681.257
2920.09	701.696
2922.7	718.149
2925.32	729.525
2927.93	735.435
2930.54	738.583
2933.15	733.651
2935.76	724.667
2938.37	708.16
2940.98	690.26
2943.59	667.292
2946.2	641.078
2948.8	613.326
2951.41	583.893
2954.01	554.981
2956.62	526.597
2959.22	497.268
2961.82	469.715
2964.42	444.651
2967.02	422.921
2969.62	400.52
2972.22	380.139
2974.81	359.484
2977.41	338.802
2980	315.433
2982.6	294.987
2985.19	270.837
2987.78	246.79
2990.38	222.553
2992.97	198.815
2995.56	176.286
2998.14	154.047
3000.73	132.389
3003.32	113.568
3005.91	95.6004
3008.49	79.7621
3011.07	66.4421
3013.66	52.5626
3016.24	39.6692
3018.82	30.3736
3021.4	21.9625
3023.98	15.5787
3026.56	8.65211
3029.14	3.89071
3031.71	1.76328
3034.29	0.885747
3036.87	-0.324425
3039.44	2.78346
3042.01	4.36929
3044.59	7.56895
3047.16	10.4112
3049.73	12.3528
3052.3	15.4734
3054.87	15.7997
3057.43	16.5143
3060	16.891
3062.57	17.2771
3065.13	18.518
3067.7	17.4819
3070.26	16.8263
3072.82	16.4422
3075.39	13.7397
3077.95	12.2597
3080.51	10.6141
3083.07	7.97888
3085.63	7.28187
3088.18	6.13406
3090.74	6.85323
3093.29	8.423
3095.85	11.9019
3098.4	14.9785
3100.95	17.9911
3103.51	21.1938
3106.06	23.6005
3108.61	25.4045
3111.16	27.104
3113.71	31.3376
3116.25	34.4813
3118.8	37.2545
3121.35	41.163
3123.89	44.907
3126.44	48.9141
3128.98	51.4309
3131.52	55.1395
3134.06	59.1318
3136.6	63.3722
3139.14	66.4294
3141.68	71.3355
3144.22	76.6209
3146.76	81.9602
3149.29	86.5053