File: data/Raman/poly_smoothed/Mb_00_13_49_1x_45s_532 nm_x100_100%_600 gr_mm_03.txt
#Acq. time (s)=	45
#Accumulations=	2
#Range (cm-¹)=	200...3150
#Windows=	2
#Auto scanning=	Off
#Autofocus=	Off
#Macrospot=	Off
#AutoExposure=	Off
#Spike filter=	Multiple accum.
#Delay time (s)=	0
#Binning=	1
#Readout mode=	Signal
#DeNoise=	Off
#ICS correction=	On
#Dark correction=	Off
#Inst. Process=	Off
#Detector Gain=	Best Dynamic Range
#Detector ADC=	20 kHz
#Detector temperature (°C)=	-69.85
#Instrument=	LabRAM HR Evol
#Detector=	Synapse
#Objective=	x100
#Grating=	600 gr/mm
#ND Filter=	100%
#Laser (nm)=	532
#Hole=	100.021
#Range=	Auto
#Laser Pol.=	No
#Raman. Pol.=	No
#Laser Pol. (°)=	-0.0007625
#Raman Pol. (°)=	89.9995
#Collection=	Microscope
#StageXY=	Marzhauser
#StageZ=	Marzhauser
#X (µm)=	-1076.7
#Y (µm)=	-2876.3
#Z (µm)=	528.6
#Full time(mm:ss)=	3:18
#Project=
#Sample=
#Site=
#Title=	Mb_00_13_49_2x_45s_532 nm_x100_100%_600 gr_mm
#Remark=
#Date=	06.07.2022 13:51
#Acquired=	06.07.2022 13:51:42
#Base:Fit=	10.08.2022 10:16:56
#Base:Sub=	10.08.2022 10:17:24
#Filter:Polynom=	16.08.2022 10:36:38
#AxisType[0]=Intens
#AxisUnit[0]=Cnt
#AxisType[1]=Spectr
#AxisUnit[1]=1/cm
200.398	8.59249
204.027	8.75838
207.657	6.55195
211.283	4.10395
214.909	3.66766
218.533	6.33837
222.157	9.9751
225.777	15.9026
229.396	22.7404
233.016	31.5785
236.632	38.0317
240.247	43.8483
243.86	49.0001
247.474	53.0162
251.085	57.8828
254.694	60.1462
258.301	64.1796
261.908	65.9745
265.513	68.4961
269.116	67.8459
272.718	64.3584
276.319	61.1894
279.918	59.567
283.516	54.2423
287.113	47.8257
290.708	42.2117
294.302	35.7762
297.894	33.216
301.485	29.8125
305.073	25.8838
308.661	24.0822
312.247	23.2461
315.833	21.636
319.415	21.4484
322.997	18.0947
326.579	15.8961
330.156	14.6995
333.735	12.5269
337.31	12.4478
340.885	13.0296
344.458	13.9156
348.03	12.1388
351.6	11.1947
355.17	8.93595
358.737	9.66893
362.304	9.20998
365.868	12.4295
369.431	16.4735
372.994	18.6111
376.554	21.5488
380.112	24.406
383.669	28.9554
387.225	32.8773
390.781	37.9344
394.334	45.1818
397.885	50.8141
401.436	53.4554
404.984	54.9095
408.532	55.5223
412.078	56.1122
415.623	57.0187
419.166	56.0811
422.708	54.898
426.248	53.0709
429.788	49.8293
433.326	45.4361
436.86	39.7333
440.395	35.6295
443.929	31.919
447.461	28.3005
450.99	25.6091
454.52	22.9125
458.048	20.3116
461.573	16.874
465.099	16.0052
468.623	15.9284
472.144	16.3501
475.666	18.8094
479.184	19.6164
482.703	19.525
486.218	19.8084
489.734	19.2736
493.247	18.6384
496.759	19.0575
500.271	18.3777
503.779	18.6476
507.287	19.1234
510.795	19.6208
514.299	20.1149
517.803	19.3402
521.305	19.5355
524.805	18.9253
528.307	18.2376
531.805	18.2603
535.301	17.8874
538.797	18.0944
542.291	18.375
545.783	17.9164
549.275	16.0243
552.765	16.1521
556.253	12.9601
559.738	11.5432
563.224	9.61797
566.709	8.30906
570.192	7.3945
573.674	6.31399
577.153	4.75788
580.632	5.18542
584.11	6.48865
587.587	6.56502
591.06	6.98628
594.534	5.45701
598.005	5.92468
601.476	5.83851
604.944	6.12333
608.413	7.82007
611.878	8.95439
615.344	9.57184
618.807	11.1527
622.27	13.1689
625.73	13.7839
629.189	14.3273
632.648	15.6026
636.105	15.4385
639.559	15.2535
643.013	16.0541
646.467	16.0261
649.918	16.8527
653.368	15.9559
656.816	17.64
660.263	18.3991
663.708	19.0434
667.153	20.2672
670.596	19.3893
674.037	18.7697
677.478	16.2279
680.917	15.4734
684.355	16.1994
687.791	17.0094
691.224	19.0397
694.658	21.6741
698.091	21.9489
701.522	22.5361
704.95	24.2132
708.379	25.3965
711.806	26.7501
715.23	29.1775
718.655	28.8116
722.078	28.2881
725.498	29.843
728.919	29.7253
732.337	29.6167
735.755	29.9617
739.17	30.8736
742.584	31.854
745.998	32.5069
749.409	34.5212
752.819	36.3647
756.23	37.354
759.637	37.0928
763.043	36.6378
766.448	39.9491
769.853	42.6608
773.255	45.3916
776.656	49.3474
780.056	51.4628
783.454	52.5515
786.851	55.1138
790.247	57.7624
793.641	59.2498
797.034	58.5963
800.426	60.1057
803.817	60.3823
807.206	60.3872
810.592	61.5395
813.979	64.5303
817.364	65.5323
820.748	65.2313
824.129	65.2211
827.511	66.8379
830.891	69.0349
834.269	70.3949
837.646	71.2222
841.023	65.8662
844.396	63.8994
847.77	63.1131
851.141	63.8769
854.513	62.1279
857.881	58.5859
861.248	56.685
864.616	53.3788
867.98	48.445
871.343	45.1244
874.707	42.4146
878.068	39.7918
881.428	38.0719
884.786	37.9445
888.143	36.0498
891.498	35.5405
894.855	36.4413
898.208	36.0699
901.56	35.4281
904.91	34.8406
908.26	34.7581
911.608	35.4295
914.955	34.8291
918.298	34.7356
921.643	34.8373
924.986	32.5471
928.328	33.8473
931.668	34.5291
935.006	32.8763
938.344	31.1197
941.681	30.4895
945.014	26.5102
948.349	23.8871
951.682	21.9392
955.012	24.7342
958.343	23.2159
961.67	22.8422
964.998	23.8001
968.323	25.9713
971.649	28.7923
974.971	31.0899
978.293	35.4229
981.615	40.0524
984.933	42.8325
988.251	43.1623
991.567	44.096
994.884	46.9714
998.198	49.6503
1001.51	50.1911
1004.82	50.2827
1008.13	47.4304
1011.44	45.8207
1014.75	44.8038
1018.06	47.9287
1021.36	48.9599
1024.66	49.2158
1027.97	50.1492
1031.27	52.373
1034.57	54.7453
1037.87	54.6279
1041.16	53.2749
1044.46	54.9605
1047.76	56.2498
1051.05	56.23
1054.34	56.5041
1057.63	55.1194
1060.92	54.7827
1064.21	51.0075
1067.5	48.0551
1070.78	46.3424
1074.07	41.0548
1077.35	37.9995
1080.63	31.8801
1083.91	25.611
1087.19	18.8999
1090.47	15.8976
1093.75	14.7702
1097.03	16.2118
1100.3	16.9781
1103.57	16.0949
1106.84	15.521
1110.11	14.7975
1113.38	12.7871
1116.65	11.6435
1119.92	12.6496
1123.19	12.5487
1126.45	14.5732
1129.71	13.5269
1132.97	12.8465
1136.23	12.3552
1139.49	14.8328
1142.75	16.6887
1146.01	18.0633
1149.26	19.7711
1152.52	19.7376
1155.77	19.4868
1159.02	18.1481
1162.27	15.7147
1165.52	15.0046
1168.77	15.3115
1172.02	16.9261
1175.26	18.1653
1178.51	18.6755
1181.75	19.22
1184.99	17.7176
1188.23	16.2337
1191.47	17.1253
1194.71	20.1804
1197.94	24.3163
1201.18	27.3816
1204.41	29.0187
1207.65	30.5433
1210.88	32.746
1214.11	38.4585
1217.34	42.6417
1220.57	46.0964
1223.79	50.2286
1227.02	51.5522
1230.24	55.5545
1233.47	57.5315
1236.69	58.5256
1239.91	58.8223
1243.13	60.4483
1246.34	62.3434
1249.56	62.7898
1252.78	62.8437
1255.99	62.7655
1259.2	62.3517
1262.42	62.5112
1265.63	61.9481
1268.84	62.5677
1272.04	64.3788
1275.25	64.7185
1278.46	64.8558
1281.66	66.8081
1284.86	67.979
1288.07	71.2089
1291.27	74.1487
1294.47	76.0305
1297.66	78.9419
1300.86	81.5731
1304.06	82.6177
1307.25	85.2539
1310.44	89.5881
1313.64	90.364
1316.83	90.3372
1320.02	92.1953
1323.2	91.3913
1326.39	90.336
1329.58	89.5851
1332.76	89.0346
1335.95	87.1224
1339.13	86.1106
1342.31	85.0955
1345.49	83.6649
1348.67	78.9055
1351.85	76.424
1355.02	75.5187
1358.2	73.672
1361.37	71.7483
1364.54	68.1144
1367.71	66.4331
1370.88	65.9662
1374.05	64.0544
1377.22	62.247
1380.39	61.836
1383.55	61.5845
1386.72	60.9859
1389.88	60.5292
1393.04	60.9624
1396.2	60.4046
1399.36	60.4336
1402.52	59.6238
1405.68	61.1926
1408.83	64.1289
1411.98	67.3387
1415.14	70.4192
1418.29	72.9306
1421.44	77.9891
1424.59	82.1279
1427.74	86.635
1430.89	93.7907
1434.03	99.7298
1437.18	103.031
1440.32	107.698
1443.46	109.524
1446.6	110.381
1449.74	111.666
1452.88	112.301
1456.02	111.06
1459.16	108.162
1462.29	104.734
1465.43	101.028
1468.56	96.8085
1471.69	91.1428
1474.82	83.5082
1477.95	77.6613
1481.08	72.4659
1484.2	68.6394
1487.33	64.3756
1490.46	59.5178
1493.58	54.894
1496.7	51.832
1499.82	48.8926
1502.94	46.8798
1506.06	43.7877
1509.18	36.6817
1512.29	35.9814
1515.41	36.9937
1518.52	39.2859
1521.63	40.4019
1524.75	41.9368
1527.85	43.3815
1530.96	45.4941
1534.07	46.3136
1537.18	46.7418
1540.28	46.7178
1543.39	48.7833
1546.49	51.0388
1549.59	51.3868
1552.69	53.8889
1555.79	56.5537
1558.89	58.3705
1561.99	60.0268
1565.08	60.1526
1568.18	60.226
1571.27	62.4718
1574.37	63.4414
1577.46	63.4868
1580.55	62.2609
1583.64	61.8838
1586.73	64.8223
1589.81	72.3772
1592.9	75.0532
1595.98	77.3115
1599.06	75.8236
1602.15	74.7287
1605.23	74.5975
1608.31	73.7644
1611.39	73.9842
1614.46	73.2013
1617.54	72.2479
1620.61	71.1541
1623.69	70.805
1626.76	72.718
1629.83	73.8736
1632.9	72.9233
1635.97	72.3454
1639.04	72.2795
1642.11	73.3612
1645.17	74.6127
1648.24	75.6277
1651.3	76.0411
1654.36	75.8481
1657.42	76.2737
1660.48	76.1587
1663.54	75.8842
1666.6	74.4575
1669.66	72.4535
1672.71	69.2495
1675.77	63.7083
1678.82	60.0221
1681.87	56.7119
1684.92	51.2954
1687.97	47.4954
1691.02	40.9637
1694.07	35.8074
1697.11	33.2526
1700.16	28.4756
1703.2	26.0665
1706.25	21.7856
1709.29	18.3362
1712.33	15.7943
1715.37	12.4188
1718.41	11.1121
1721.44	8.89351
1724.48	6.99255
1727.51	6.29058
1730.55	4.76722
1733.58	4.73406
1736.61	4.13327
1739.64	3.08014
1742.67	2.52994
1745.7	2.34586
1748.72	1.28399
1751.75	0.572645
1754.77	1.09328
1757.8	0.0896622
1760.82	0.515907
1763.84	0.743357
1766.86	0.782002
1769.88	1.67726
1772.9	1.89606
1775.91	1.76515
1778.93	2.26967
1781.94	2.19872
1784.96	2.7965
1787.97	2.97146
1790.98	3.75115
1793.99	4.20828
1797	4.35958
1800.01	3.95457
1803.01	3.39919
1806.02	3.52406
1809.02	4.11204
1812.02	3.96902
1815.02	4.0403
1818.03	3.42837
1821.02	3.45187
1824.02	3.74752
1827.02	4.05474
1830.02	3.47614
1833.01	3.5673
1836.01	4.18037
1839	5.09922
1841.99	5.02819
1844.98	4.46552
1847.97	3.52223
1850.96	3.36111
1853.95	2.53071
1856.93	2.25606
1859.92	2.56538
1862.9	2.90041
1865.88	2.58419
1868.87	2.8412
1871.85	2.54893
1874.83	3.85356
1877.81	5.7524
1880.78	7.01052
1882.53	8.19619
1885.52	7.45986
1888.51	8.05948
1891.5	9.37959
1894.48	10.6941
1897.47	11.3023
1900.45	11.2232
1903.43	11.4122
1906.41	12.2361
1909.39	12.1557
1912.37	11.8658
1915.35	11.9805
1918.33	10.8455
1921.3	9.43572
1924.28	8.29243
1927.25	7.30997
1930.22	7.24147
1933.19	6.19378
1936.16	5.41726
1939.13	5.45002
1942.1	4.71859
1945.07	5.31623
1948.03	4.48097
1951	4.16311
1953.96	2.00177
1956.92	1.27911
1959.88	0.898621
1962.84	0.489485
1965.8	0.160965
1968.76	0.296798
1971.72	1.31595
1974.67	1.74596
1977.63	2.47181
1980.58	3.81934
1983.54	5.31326
1986.49	7.05239
1989.44	8.4186
1992.39	8.4598
1995.33	9.15839
1998.28	9.24684
2001.23	10.3882
2004.17	11.2011
2007.12	11.2784
2010.06	11.4958
2013	10.0241
2015.94	10.0416
2018.88	9.59794
2021.82	9.40737
2024.76	8.6797
2027.69	9.06715
2030.63	8.65098
2033.56	8.88461
2036.5	8.79713
2039.43	8.9783
2042.36	9.22756
2045.29	8.72523
2048.22	9.14299
2051.15	10.3703
2054.07	11.8848
2057	12.0595
2059.92	11.1034
2062.85	10.7486
2065.77	11.538
2068.69	11.5528
2071.61	11.999
2074.53	11.7171
2077.45	10.5516
2080.37	11.0855
2083.28	11.5663
2086.2	10.9474
2089.11	12.2239
2092.02	13.3221
2094.94	13.8425
2097.85	12.5746
2100.76	13.014
2103.66	12.0531
2106.57	9.53708
2109.48	10.4534
2112.38	10.8073
2115.29	11.361
2118.19	12.6075
2121.09	14.5123
2123.99	14.5358
2126.89	14.9252
2129.79	14.512
2132.69	15.36
2135.59	16.8395
2138.48	16.5557
2141.38	16.024
2144.27	16.1983
2147.17	14.903
2150.06	14.6162
2152.95	14.6841
2155.84	14.1977
2158.73	13.1099
2161.61	12.6346
2164.5	12.0641
2167.38	10.4844
2170.27	9.3339
2173.15	8.9861
2176.03	9.29934
2178.91	10.0008
2181.8	9.91322
2184.67	9.09783
2187.55	10.5534
2190.43	11.9954
2193.3	11.8233
2196.18	12.1081
2199.05	12.6954
2201.93	13.2335
2204.8	14.2535
2207.67	14.1925
2210.54	14.4051
2213.41	15.5797
2216.27	14.9367
2219.14	15.6862
2222.01	16.5215
2224.87	15.907
2227.73	15.9305
2230.6	15.1272
2233.46	15.2654
2236.32	15.6336
2239.18	14.9044
2242.03	14.369
2244.89	15.7559
2247.75	14.8867
2250.6	13.8278
2253.46	13.4605
2256.31	15.7686
2259.16	14.6667
2262.01	14.4644
2264.86	15.0172
2267.71	15.3414
2270.56	14.8632
2273.4	14.4161
2276.25	14.648
2279.09	14.1003
2281.94	13.8449
2284.78	14.1588
2287.62	14.1135
2290.46	12.2928
2293.3	10.6961
2296.14	10.1745
2298.98	10.4879
2301.82	11.1877
2304.65	11.5428
2307.49	11.5743
2310.32	12.5137
2313.15	12.9029
2315.98	12.7611
2318.81	11.6995
2321.64	11.4339
2324.47	12.6087
2327.3	11.3363
2330.12	9.93758
2332.95	9.77034
2335.77	8.9747
2338.6	7.08751
2341.42	6.19565
2344.24	5.2074
2347.06	3.95883
2349.88	2.87737
2352.7	1.82097
2355.51	0.0179463
2358.33	-1.05588
2361.14	-1.64187
2363.96	0.217515
2366.77	1.51514
2369.58	1.87121
2372.39	2.08604
2375.2	4.07897
2378.01	4.00128
2380.82	5.16705
2383.63	4.40099
2386.43	4.61906
2389.24	5.92549
2392.04	7.14944
2394.84	7.68016
2397.65	8.0462
2400.45	7.76842
2403.25	8.20835
2406.05	7.73003
2408.84	8.77036
2411.64	8.69613
2414.44	7.72207
2417.23	7.26117
2420.02	8.05384
2422.82	6.61343
2425.61	5.42751
2428.4	5.25484
2431.19	3.82839
2433.98	2.90014
2436.77	2.66261
2439.55	3.19898
2442.34	3.21484
2445.12	3.08166
2447.91	3.19766
2450.69	3.18865
2453.47	1.32126
2456.25	2.69578
2459.03	2.86147
2461.81	3.32484
2464.59	2.68758
2467.36	2.89647
2470.14	3.05391
2472.92	2.57919
2475.69	2.79467
2478.46	2.87834
2481.23	2.36008
2484	3.3856
2486.77	2.81652
2489.54	2.50044
2492.31	1.36112
2495.08	2.29524
2497.84	2.90093
2500.61	2.65722
2503.37	3.62426
2506.13	4.64185
2508.9	5.35335
2511.66	4.78045
2514.42	5.12196
2517.18	4.82296
2519.93	4.56907
2522.69	4.97995
2525.45	5.35752
2528.2	5.76932
2530.95	6.02579
2533.71	5.26603
2536.46	4.97581
2539.21	4.20708
2541.96	3.49952
2544.71	2.52196
2547.46	3.13335
2550.2	2.77283
2552.95	1.93408
2555.7	1.69213
2558.44	2.25851
2561.18	1.66531
2563.93	2.54071
2566.67	2.98698
2569.41	2.70645
2572.15	4.04785
2574.88	2.81805
2577.62	2.82548
2580.36	3.05761
2583.09	3.54246
2585.83	4.59362
2588.56	5.75294
2591.29	6.21432
2594.02	7.43596
2596.75	7.53655
2599.48	7.06317
2602.21	7.25575
2604.94	6.80625
2607.67	6.73074
2610.39	6.26193
2613.12	5.46853
2615.84	5.67987
2618.56	5.69912
2621.28	4.79586
2624.01	5.76137
2626.72	6.37586
2629.44	6.78794
2632.16	6.19343
2634.88	5.22679
2637.59	5.59746
2640.31	5.65822
2643.02	5.74156
2645.74	6.10887
2648.45	7.38746
2651.16	8.60281
2653.87	9.45866
2656.58	8.81126
2659.29	9.45414
2661.99	8.19125
2664.7	8.60921
2667.41	8.94992
2670.11	8.89909
2672.81	8.69285
2675.51	7.7544
2678.22	6.60583
2680.92	6.40246
2683.62	6.31871
2686.31	6.84845
2689.01	7.31434
2691.71	7.5349
2694.4	7.0691
2697.1	6.32254
2699.79	6.00995
2702.49	6.47628
2705.18	7.5294
2707.87	8.35014
2710.56	8.67715
2713.25	8.77104
2715.94	9.95916
2718.62	10.4031
2721.31	10.809
2723.99	10.3828
2726.68	11.1784
2729.36	10.4242
2732.04	10.2487
2734.73	9.97453
2737.41	8.61831
2740.08	7.4745
2742.76	6.55371
2745.44	6.08431
2748.12	7.17812
2750.79	7.56492
2753.47	6.15198
2756.14	5.47919
2758.81	5.42361
2761.49	4.83574
2764.16	4.28339
2766.83	3.90122
2769.5	3.92854
2772.16	2.41551
2774.83	2.60021
2777.5	1.42208
2780.16	1.45937
2782.83	1.41312
2785.49	0.389744
2788.15	0.281822
2790.82	0.407537
2793.48	-0.429892
2796.14	-0.728027
2798.79	-1.78592
2801.45	-1.75975
2804.11	-2.47952
2806.76	-2.05601
2809.42	-1.98435
2812.07	-1.4162
2814.73	0.119947
2817.38	0.810042
2820.03	2.28041
2822.68	5.72898
2825.33	8.43423
2827.98	10.7488
2830.63	13.4228
2833.27	16.8457
2835.92	20.8768
2838.56	25.5475
2841.21	31.596
2843.85	37.7011
2846.49	44.8961
2849.13	53.208
2851.77	61.1758
2854.41	69.0321
2857.05	77.2152
2859.69	84.3264
2862.32	91.6673
2864.96	98.4818
2867.59	104.982
2870.23	112.193
2872.86	119.341
2875.49	124.564
2878.12	129.478
2880.75	133.484
2883.38	137.055
2886.01	141.955
2888.63	144.306
2891.26	147.001
2893.89	148.676
2896.51	151.517
2899.13	155.549
2901.76	161.472
2904.38	167.318
2907	174.401
2909.62	183.325
2912.24	192.143
2914.85	201.69
2917.47	208.692
2920.09	215.707
2922.7	221.658
2925.32	227.386
2927.93	229.619
2930.54	232.191
2933.15	233.149
2935.76	232.591
2938.37	228.758
2940.98	224.74
2943.59	219.233
2946.2	213.576
2948.8	206.741
2951.41	198.535
2954.01	189.963
2956.62	180.881
2959.22	171.644
2961.82	164.151
2964.42	156.435
2967.02	149.516
2969.62	142.46
2972.22	136.18
2974.81	128.654
2977.41	122.269
2980	114.23
2982.6	106.425
2985.19	99.2686
2987.78	91.4954
2990.38	83.213
2992.97	75.4217
2995.56	67.6622
2998.14	60.1253
3000.73	52.194
3003.32	45.8662
3005.91	39.5005
3008.49	33.6172
3011.07	29.7442
3013.66	23.7788
3016.24	19.662
3018.82	15.5367
3021.4	12.2818
3023.98	9.65178
3026.56	7.08494
3029.14	4.90654
3031.71	3.57292
3034.29	3.16341
3036.87	1.98296
3039.44	2.95407
3042.01	3.6867
3044.59	4.91618
3047.16	5.48683
3049.73	6.17724
3052.3	7.43052
3054.87	6.7885
3057.43	6.81679
3060	6.71601
3062.57	5.95366
3065.13	5.68101
3067.7	6.18513
3070.26	5.61383
3072.82	5.17722
3075.39	4.77773
3077.95	2.89782
3080.51	2.68138
3083.07	1.60306
3085.63	0.171922
3088.18	-0.0335057
3090.74	-0.903811
3093.29	-1.03126
3095.85	-0.239584
3098.4	-0.275033
3100.95	0.524683
3103.51	1.44783
3106.06	1.49856
3108.61	2.73783
3111.16	3.27116
3113.71	4.80448
3116.25	5.23284
3118.8	5.47727
3121.35	7.17507
3123.89	7.9289
3126.44	9.57383
3128.98	10.3968
3131.52	11.7723
3134.06	11.8601
3136.6	13.2567
3139.14	13.5946
3141.68	14.0825
3144.22	14.5541
3146.76	15.0714
3149.29	15.7254