File: data/Raman/poly_smoothed/Mb_00_13_34_1x_45s_532 nm_x100_100%_600 gr_mm_01.txt
#Acq. time (s)=	45
#Accumulations=	2
#Range (cm-¹)=	200...3150
#Windows=	2
#Auto scanning=	Off
#Autofocus=	Off
#Macrospot=	Off
#AutoExposure=	Off
#Spike filter=	Multiple accum.
#Delay time (s)=	0
#Binning=	1
#Readout mode=	Signal
#DeNoise=	Off
#ICS correction=	On
#Dark correction=	Off
#Inst. Process=	Off
#Detector Gain=	Best Dynamic Range
#Detector ADC=	20 kHz
#Detector temperature (°C)=	-69.85
#Instrument=	LabRAM HR Evol
#Detector=	Synapse
#Objective=	x100
#Grating=	600 gr/mm
#ND Filter=	100%
#Laser (nm)=	532
#Hole=	100.021
#Range=	Auto
#Laser Pol.=	No
#Raman. Pol.=	No
#Laser Pol. (°)=	-0.0007625
#Raman Pol. (°)=	89.9995
#Collection=	Microscope
#StageXY=	Marzhauser
#StageZ=	Marzhauser
#X (µm)=	-1024.4
#Y (µm)=	-2901.7
#Z (µm)=	528.6
#Full time(mm:ss)=	3:18
#Project=
#Sample=
#Site=
#Title=	Mb_00_13_34_2x_45s_532 nm_x100_100%_600 gr_mm
#Remark=
#Date=	06.07.2022 12:29
#Acquired=	06.07.2022 12:29:45
#Base:Fit=	10.08.2022 10:16:56
#Base:Sub=	10.08.2022 10:17:24
#Filter:Polynom=	16.08.2022 10:36:38
#AxisType[0]=Intens
#AxisUnit[0]=Cnt
#AxisType[1]=Spectr
#AxisUnit[1]=1/cm
200.398	22.1453
204.027	12.8282
207.657	9.14864
211.283	5.34303
214.909	5.33669
218.533	11.599
222.157	23.4057
225.777	39.7883
229.396	57.3195
233.016	74.7302
236.632	88.7848
240.247	99.4003
243.86	108.211
247.474	115.701
251.085	125.228
254.694	131.089
258.301	136.581
261.908	140.584
265.513	139.872
269.116	138.337
272.718	130.957
276.319	121.9
279.918	109.197
283.516	95.4649
287.113	83.2826
290.708	69.5068
294.302	57.4852
297.894	46.427
301.485	39.3227
305.073	35.5191
308.661	31.3664
312.247	30.4556
315.833	28.1367
319.415	26.3895
322.997	22.8671
326.579	20.0137
330.156	16.4393
333.735	16.8937
337.31	17.6167
340.885	15.4511
344.458	10.4797
348.03	9.96249
351.6	9.28773
355.17	5.32159
358.737	5.01427
362.304	6.82352
365.868	10.4187
369.431	13.1933
372.994	19.014
376.554	25.8909
380.112	35.1881
383.669	47.4774
387.225	59.8265
390.781	73.9904
394.334	84.0662
397.885	94.6295
401.436	103.651
404.984	110.657
408.532	114.492
412.078	115.407
415.623	115.312
419.166	114.544
422.708	108.136
426.248	101.435
429.788	91.4725
433.326	81.5806
436.86	70.9859
440.395	57.9761
443.929	46.1589
447.461	34.3527
450.99	24.0402
454.52	14.7249
458.048	6.75446
461.573	0.699009
465.099	-2.68875
468.623	-1.69914
472.144	1.86837
475.666	3.92183
479.184	5.24986
482.703	7.48967
486.218	10.827
489.734	14.7131
493.247	19.2739
496.759	23.3094
500.271	28.2319
503.779	31.5406
507.287	36.7685
510.795	42.4321
514.299	47.3346
517.803	50.3373
521.305	55.7596
524.805	57.2629
528.307	56.451
531.805	56.2373
535.301	54.2621
538.797	53.8192
542.291	52.0727
545.783	47.5067
549.275	44.3692
552.765	40.5455
556.253	39.2383
559.738	33.8992
563.224	28.2669
566.709	24.2748
570.192	21.4112
573.674	20.4407
577.153	17.8287
580.632	16.1032
584.11	14.3508
587.587	13.758
591.06	11.4315
594.534	12.2068
598.005	12.736
601.476	11.9919
604.944	13.7057
608.413	13.4385
611.878	13.312
615.344	13.7879
618.807	14.9129
622.27	14.7189
625.73	14.3667
629.189	15.1125
632.648	16.7058
636.105	21.4729
639.559	23.0294
643.013	25.4284
646.467	25.6273
649.918	26.9991
653.368	27.9682
656.816	27.1239
660.263	26.7765
663.708	23.9574
667.153	22.7484
670.596	20.559
674.037	17.6414
677.478	15.8005
680.917	14.2335
684.355	9.88092
687.791	7.19924
691.224	5.12673
694.658	2.42894
698.091	1.33061
701.522	-0.466647
704.95	-0.336854
708.379	-0.765815
711.806	-0.29364
715.23	2.75411
718.655	4.86686
722.078	3.93624
725.498	3.57719
728.919	5.00596
732.337	5.03125
735.755	6.60972
739.17	8.63695
742.584	10.7608
745.998	13.4977
749.409	15.1658
752.819	19.5514
756.23	23.5041
759.637	26.0054
763.043	28.0383
766.448	33.4066
769.853	35.3505
773.255	37.5971
776.656	42.2786
780.056	45.9027
783.454	48.2654
786.851	49.4978
790.247	52.2688
793.641	52.9064
797.034	52.8528
800.426	53.4561
803.817	52.2404
807.206	51.1563
810.592	49.4663
813.979	49.2835
817.364	48.7034
820.748	48.6788
824.129	49.6694
827.511	49.7103
830.891	49.2983
834.269	48.5632
837.646	47.7468
841.023	45.9654
844.396	43.8665
847.77	42.693
851.141	40.0039
854.513	36.4439
857.881	32.9768
861.248	31.1033
864.616	28.985
867.98	24.8553
871.343	22.4502
874.707	21.6347
878.068	19.5071
881.428	18.3002
884.786	15.6616
888.143	13.4887
891.498	11.1843
894.855	10.7752
898.208	10.0636
901.56	8.36161
904.91	9.51921
908.26	8.55714
911.608	11.0692
914.955	8.77623
918.298	10.8345
921.643	11.3724
924.986	10.7385
928.328	9.58671
931.668	10.2117
935.006	10.1603
938.344	8.77906
941.681	8.44233
945.014	10.5141
948.349	11.4648
951.682	12.0891
955.012	12.8941
958.343	12.284
961.67	13.5314
964.998	15.7714
968.323	22.7076
971.649	30.8829
974.971	36.367
978.293	42.1682
981.615	46.3113
984.933	51.5468
988.251	55.6321
991.567	60.954
994.884	64.7798
998.198	67.4734
1001.51	69.4465
1004.82	71.3933
1008.13	70.8502
1011.44	71.1193
1014.75	72.4423
1018.06	75.7871
1021.36	83.3268
1024.66	95.9888
1027.97	106.798
1031.27	115.014
1034.57	119.81
1037.87	125.996
1041.16	133.74
1044.46	139.961
1047.76	145.298
1051.05	145.279
1054.34	143.12
1057.63	138.856
1060.92	131.236
1064.21	123.584
1067.5	112.983
1070.78	104.154
1074.07	89.5249
1077.35	75.3109
1080.63	59.2348
1083.91	45.7273
1087.19	32.5043
1090.47	23.7999
1093.75	18.9477
1097.03	16.553
1100.3	20.0222
1103.57	21.634
1106.84	22.4366
1110.11	22.1032
1113.38	19.5407
1116.65	18.8717
1119.92	18.185
1123.19	15.9979
1126.45	13.9487
1129.71	11.2925
1132.97	10.9358
1136.23	11.8451
1139.49	11.4554
1142.75	10.2735
1146.01	8.41745
1149.26	8.35719
1152.52	6.87751
1155.77	3.94613
1159.02	3.18633
1162.27	4.13052
1165.52	4.33748
1168.77	7.36346
1172.02	10.7727
1175.26	11.3987
1178.51	15.1309
1181.75	15.33
1184.99	18.8284
1188.23	22.3115
1191.47	24.9447
1194.71	31.0229
1197.94	37.5044
1201.18	43.8043
1204.41	50.3
1207.65	57.1452
1210.88	66.2248
1214.11	75.0339
1217.34	82.9782
1220.57	90.4658
1223.79	97.9962
1227.02	103.663
1230.24	108.962
1233.47	111.674
1236.69	113.677
1239.91	117.146
1243.13	117.289
1246.34	116.408
1249.56	117.852
1252.78	116.681
1255.99	114.902
1259.2	111.852
1262.42	107.789
1265.63	103.958
1268.84	104.802
1272.04	103.659
1275.25	103.8
1278.46	103.163
1281.66	105.282
1284.86	107.592
1288.07	112.01
1291.27	116.107
1294.47	120.271
1297.66	126.898
1300.86	131.69
1304.06	135.347
1307.25	139.719
1310.44	145.344
1313.64	150.546
1316.83	154.568
1320.02	156.499
1323.2	156.694
1326.39	157.456
1329.58	157.998
1332.76	155.367
1335.95	151.98
1339.13	146.501
1342.31	141.605
1345.49	136.247
1348.67	132.53
1351.85	128.221
1355.02	122.209
1358.2	117.752
1361.37	113.12
1364.54	105.883
1367.71	104.615
1370.88	100.713
1374.05	99.5945
1377.22	97.8531
1380.39	97.4445
1383.55	97.2589
1386.72	98.4313
1389.88	99.7785
1393.04	99.029
1396.2	97.3984
1399.36	98.512
1402.52	102.436
1405.68	105.931
1408.83	110.219
1411.98	116.344
1415.14	121.934
1418.29	131.6
1421.44	142.817
1424.59	153.4
1427.74	167.113
1430.89	178.917
1434.03	189.007
1437.18	200.707
1440.32	209.793
1443.46	214.726
1446.6	219.136
1449.74	221.856
1452.88	219.005
1456.02	213.665
1459.16	205.178
1462.29	196.809
1465.43	184.337
1468.56	171.227
1471.69	158.106
1474.82	143.311
1477.95	130.408
1481.08	116.178
1484.2	104.344
1487.33	93.8479
1490.46	85.2235
1493.58	81.6617
1496.7	76.673
1499.82	73.1867
1502.94	71.3596
1506.06	70.4161
1509.18	68.64
1512.29	70.4809
1515.41	70.1738
1518.52	70.9228
1521.63	70.8448
1524.75	71.8631
1527.85	72.1636
1530.96	71.9189
1534.07	72.0509
1537.18	72.1716
1540.28	74.3439
1543.39	73.1397
1546.49	75.9407
1549.59	78.1651
1552.69	77.2831
1555.79	79.9376
1558.89	81.6726
1561.99	84.6244
1565.08	85.8371
1568.18	89.3284
1571.27	95.7706
1574.37	99.4082
1577.46	104.072
1580.55	108.655
1583.64	112.506
1586.73	117.326
1589.81	122.1
1592.9	126.076
1595.98	128.115
1599.06	129.28
1602.15	131.389
1605.23	132.66
1608.31	132.309
1611.39	129.932
1614.46	129.404
1617.54	130.493
1620.61	132.361
1623.69	133.664
1626.76	132.173
1629.83	133.83
1632.9	135.746
1635.97	137.635
1639.04	140.96
1642.11	145.019
1645.17	149.556
1648.24	153.542
1651.3	156.496
1654.36	155.497
1657.42	156.062
1660.48	155.311
1663.54	154.287
1666.6	151.265
1669.66	146.562
1672.71	139.525
1675.77	131.767
1678.82	122.571
1681.87	111.382
1684.92	101.707
1687.97	91.4272
1691.02	82.2475
1694.07	72.7569
1697.11	64.581
1700.16	56.6819
1703.2	47.4398
1706.25	41.7433
1709.29	34.6245
1712.33	29.3726
1715.37	26.2996
1718.41	23.6344
1721.44	20.8703
1724.48	18.412
1727.51	15.073
1730.55	14.2428
1733.58	13.2433
1736.61	12.5434
1739.64	12.077
1742.67	10.5804
1745.7	7.79382
1748.72	5.93116
1751.75	5.55318
1754.77	4.73148
1757.8	5.03072
1760.82	3.85696
1763.84	4.1118
1766.86	3.652
1769.88	2.43545
1772.9	1.60068
1775.91	-0.541783
1778.93	-0.0232911
1781.94	-0.292424
1784.96	0.840796
1787.97	2.07709
1790.98	2.60174
1793.99	2.73416
1797	2.98631
1800.01	3.10514
1803.01	2.75277
1806.02	3.87085
1809.02	3.76637
1812.02	4.64711
1815.02	3.46095
1818.03	2.71874
1821.02	3.6202
1824.02	3.87435
1827.02	4.5221
1830.02	4.2856
1833.01	3.54166
1836.01	3.04895
1839	2.27314
1841.99	0.55188
1844.98	-0.726333
1847.97	-1.29001
1850.96	-1.45708
1853.95	-0.756187
1856.93	-0.542172
1859.92	0.248812
1862.9	0.316645
1865.88	1.02971
1868.87	2.5461
1871.85	4.46353
1874.83	5.05066
1877.81	6.40771
1880.78	8.50084
1882.53	8.0156
1885.52	9.65176
1888.51	10.5275
1891.5	11.2283
1894.48	10.757
1897.47	9.88558
1900.45	10.4192
1903.43	10.3958
1906.41	10.2668
1909.39	9.19419
1912.37	8.09741
1915.35	8.3541
1918.33	8.11534
1921.3	7.95939
1924.28	7.08668
1927.25	7.43945
1930.22	5.53979
1933.19	6.64727
1936.16	7.47166
1939.13	7.18813
1942.1	6.50514
1945.07	7.22621
1948.03	6.39649
1951	7.10687
1953.96	6.39675
1956.92	7.26592
1959.88	7.09857
1962.84	6.54242
1965.8	5.41186
1968.76	4.1387
1971.72	3.74869
1974.67	4.27966
1977.63	4.7566
1980.58	5.09768
1983.54	3.85101
1986.49	3.41283
1989.44	4.17047
1992.39	3.5403
1995.33	3.20656
1998.28	3.85838
2001.23	3.02881
2004.17	4.17556
2007.12	5.18421
2010.06	4.26463
2013	3.43659
2015.94	5.28469
2018.88	7.26888
2021.82	9.41976
2024.76	8.92278
2027.69	9.96689
2030.63	10.6383
2033.56	11.8539
2036.5	10.446
2039.43	9.48208
2042.36	10.664
2045.29	11.1021
2048.22	11.5988
2051.15	11.6469
2054.07	10.1542
2057	9.20132
2059.92	8.97273
2062.85	7.67129
2065.77	7.8635
2068.69	7.39052
2071.61	7.45375
2074.53	7.03463
2077.45	6.28468
2080.37	4.49735
2083.28	5.7013
2086.2	8.22212
2089.11	8.88181
2092.02	9.83573
2094.94	10.9769
2097.85	11.9407
2100.76	13.6377
2103.66	14.4946
2106.57	15.0027
2109.48	14.7301
2112.38	16.2309
2115.29	16.3092
2118.19	14.5894
2121.09	13.1413
2123.99	12.443
2126.89	9.54833
2129.79	7.09819
2132.69	6.19175
2135.59	4.68634
2138.48	3.37037
2141.38	2.60187
2144.27	2.4217
2147.17	1.7563
2150.06	1.84166
2152.95	2.71576
2155.84	2.82653
2158.73	3.15065
2161.61	2.81618
2164.5	5.79545
2167.38	6.80176
2170.27	8.10876
2173.15	10.6962
2176.03	12.0211
2178.91	12.1118
2181.8	12.2877
2184.67	11.3259
2187.55	10.7628
2190.43	9.44053
2193.3	10.0258
2196.18	7.85154
2199.05	7.9289
2201.93	7.04726
2204.8	5.87224
2207.67	6.68709
2210.54	6.46986
2213.41	7.53995
2216.27	6.85375
2219.14	8.11581
2222.01	8.69591
2224.87	8.41883
2227.73	8.14935
2230.6	8.57294
2233.46	9.80444
2236.32	13.5552
2239.18	14.6048
2242.03	16.6868
2244.89	17.1161
2247.75	17.2928
2250.6	15.7696
2253.46	16.5947
2256.31	16.9575
2259.16	16.1885
2262.01	14.565
2264.86	14.2213
2267.71	13.2705
2270.56	12.5551
2273.4	11.587
2276.25	11.1872
2279.09	10.6449
2281.94	10.0896
2284.78	9.29915
2287.62	9.66187
2290.46	8.80646
2293.3	8.03243
2296.14	8.62199
2298.98	8.02808
2301.82	9.35436
2304.65	12.1745
2307.49	12.3378
2310.32	12.9502
2313.15	12.5171
2315.98	13.9357
2318.81	13.6604
2321.64	13.1809
2324.47	15.397
2327.3	14.2736
2330.12	15.0551
2332.95	14.8649
2335.77	15.2183
2338.6	15.5076
2341.42	14.6916
2344.24	14.5614
2347.06	12.6996
2349.88	11.3889
2352.7	10.8202
2355.51	8.1905
2358.33	7.56506
2361.14	7.387
2363.96	7.03662
2366.77	6.0862
2369.58	5.78621
2372.39	4.64913
2375.2	5.348
2378.01	6.49883
2380.82	5.5661
2383.63	5.0978
2386.43	4.88884
2389.24	3.0269
2392.04	3.27051
2394.84	4.73424
2397.65	3.0885
2400.45	2.83786
2403.25	3.40789
2406.05	3.08391
2408.84	3.46585
2411.64	4.01214
2414.44	4.05477
2417.23	3.25929
2420.02	4.00787
2422.82	3.58631
2425.61	5.50243
2428.4	5.78011
2431.19	6.53386
2433.98	6.5944
2436.77	7.48095
2439.55	10.391
2442.34	12.2049
2445.12	14.2775
2447.91	14.3106
2450.69	15.0248
2453.47	14.7427
2456.25	14.8945
2459.03	14.4724
2461.81	14.4475
2464.59	15.1469
2467.36	14.4538
2470.14	14.1682
2472.92	14.7319
2475.69	13.4483
2478.46	12.5447
2481.23	11.4803
2484	9.19026
2486.77	7.11869
2489.54	5.50765
2492.31	4.78324
2495.08	3.78203
2497.84	2.16133
2500.61	3.52933
2503.37	3.69001
2506.13	5.25191
2508.9	5.80448
2511.66	6.9427
2514.42	8.48927
2517.18	9.78533
2519.93	10.6054
2522.69	11.6591
2525.45	12.1076
2528.2	14.8047
2530.95	16.2784
2533.71	17.9509
2536.46	18.4314
2539.21	19.7841
2541.96	18.6903
2544.71	18.8044
2547.46	18.2728
2550.2	18.6821
2552.95	18.6348
2555.7	17.6521
2558.44	19.0139
2561.18	19.6933
2563.93	19.8927
2566.67	20.0465
2569.41	19.2812
2572.15	19.4294
2574.88	19.5493
2577.62	20.1879
2580.36	19.7454
2583.09	19.895
2585.83	19.8154
2588.56	19.1143
2591.29	20.6318
2594.02	19.2832
2596.75	17.1297
2599.48	17.3385
2602.21	18.3102
2604.94	18.317
2607.67	19.5059
2610.39	19.4486
2613.12	20.9366
2615.84	22.4589
2618.56	23.359
2621.28	23.7371
2624.01	23.8278
2626.72	24.3488
2629.44	24.188
2632.16	24.1553
2634.88	23.892
2637.59	24.3838
2640.31	25.216
2643.02	25.1384
2645.74	24.1713
2648.45	23.0756
2651.16	22.0873
2653.87	19.7314
2656.58	18.3004
2659.29	16.2412
2661.99	15.4923
2664.7	15.8231
2667.41	17.4382
2670.11	16.8459
2672.81	18.0829
2675.51	18.958
2678.22	18.5248
2680.92	19.2621
2683.62	19.1428
2686.31	17.7401
2689.01	17.4573
2691.71	19.5434
2694.4	20.825
2697.1	23.3035
2699.79	22.8015
2702.49	25.0435
2705.18	26.0775
2707.87	26.8602
2710.56	26.6474
2713.25	27.218
2715.94	27.8481
2718.62	27.7762
2721.31	28.012
2723.99	28.26
2726.68	27.9658
2729.36	27.2652
2732.04	26.4003
2734.73	24.4891
2737.41	23.8428
2740.08	23.2883
2742.76	20.7546
2745.44	19.088
2748.12	15.6871
2750.79	12.9415
2753.47	12.1613
2756.14	10.5592
2758.81	10.9334
2761.49	8.40221
2764.16	8.32351
2766.83	6.83015
2769.5	5.78606
2772.16	4.08348
2774.83	2.76677
2777.5	2.20042
2780.16	3.04462
2782.83	3.01738
2785.49	1.67801
2788.15	1.95044
2790.82	1.35891
2793.48	1.99721
2796.14	1.62636
2798.79	1.1107
2801.45	1.27177
2804.11	1.37365
2806.76	0.460967
2809.42	-0.635885
2812.07	-1.29494
2814.73	-0.182929
2817.38	4.58507
2820.03	9.87534
2822.68	16.8898
2825.33	25.1289
2827.98	33.2245
2830.63	43.1411
2833.27	51.0145
2835.92	62.3453
2838.56	75.8532
2841.21	91.4625
2843.85	109.655
2846.49	127.381
2849.13	147.148
2851.77	169.878
2854.41	192.144
2857.05	216.268
2859.69	235.992
2862.32	253.537
2864.96	270.644
2867.59	286.383
2870.23	299.807
2872.86	312.261
2875.49	323.38
2878.12	333.949
2880.75	344.754
2883.38	354.42
2886.01	363.007
2888.63	370.451
2891.26	376.734
2893.89	381.42
2896.51	387.939
2899.13	397.924
2901.76	409.808
2904.38	425.542
2907	442.649
2909.62	462.373
2912.24	484.432
2914.85	506.572
2917.47	526.765
2920.09	541.986
2922.7	554.335
2925.32	562.261
2927.93	567.031
2930.54	567.455
2933.15	563.853
2935.76	556.034
2938.37	543.942
2940.98	528.466
2943.59	509.583
2946.2	490.108
2948.8	468.664
2951.41	445.708
2954.01	421.44
2956.62	397.391
2959.22	373.547
2961.82	352.153
2964.42	331.798
2967.02	314.363
2969.62	296.135
2972.22	280.716
2974.81	265.895
2977.41	252.945
2980	235.94
2982.6	219.418
2985.19	200.98
2987.78	183.34
2990.38	165.018
2992.97	147.643
2995.56	130.099
2998.14	113.815
3000.73	97.7551
3003.32	82.6696
3005.91	68.4362
3008.49	56.8445
3011.07	45.9558
3013.66	35.6485
3016.24	26.9336
3018.82	19.4962
3021.4	12.8795
3023.98	6.08912
3026.56	1.04718
3029.14	-1.74954
3031.71	-2.72311
3034.29	-1.38212
3036.87	-0.360413
3039.44	2.25348
3042.01	4.10411
3044.59	6.99502
3047.16	9.14475
3049.73	12.8722
3052.3	15.5583
3054.87	18.3132
3057.43	20.1355
3060	23.2337
3062.57	25.4761
3065.13	26.3467
3067.7	27.4531
3070.26	27.4462
3072.82	26.4354
3075.39	26.8265
3077.95	26.9206
3080.51	25.7244
3083.07	24.5557
3085.63	24.1189
3088.18	23.3517
3090.74	22.9838
3093.29	24.6518
3095.85	25.1977
3098.4	27.4087
3100.95	29.0998
3103.51	31.737
3106.06	35.1254
3108.61	38.1709
3111.16	41.8042
3113.71	46.273
3116.25	50.7381
3118.8	53.82
3121.35	59.259
3123.89	63.8031
3126.44	68.6919
3128.98	72.5332
3131.52	77.1264
3134.06	82.5248
3136.6	89.175
3139.14	95.8254
3141.68	100.526
3144.22	105.464
3146.76	109.674
3149.29	112.25