File: data/Raman/poly_smoothed/Mb_00_13_25_1x_45s_532 nm_x100_100%_600 gr_mm_01.txt
#Acq. time (s)=	45
#Accumulations=	2
#Range (cm-¹)=	200...3150
#Windows=	2
#Auto scanning=	Off
#Autofocus=	Off
#Macrospot=	Off
#AutoExposure=	Off
#Spike filter=	Multiple accum.
#Delay time (s)=	0
#Binning=	1
#Readout mode=	Signal
#DeNoise=	Off
#ICS correction=	On
#Dark correction=	Off
#Inst. Process=	Off
#Detector Gain=	Best Dynamic Range
#Detector ADC=	20 kHz
#Detector temperature (°C)=	-69.85
#Instrument=	LabRAM HR Evol
#Detector=	Synapse
#Objective=	x100
#Grating=	600 gr/mm
#ND Filter=	100%
#Laser (nm)=	532
#Hole=	100.021
#Range=	Auto
#Laser Pol.=	No
#Raman. Pol.=	No
#Laser Pol. (°)=	-0.0007625
#Raman Pol. (°)=	89.9995
#Collection=	Microscope
#StageXY=	Marzhauser
#StageZ=	Marzhauser
#X (µm)=	-984.8
#Y (µm)=	-2824
#Z (µm)=	528.1
#Full time(mm:ss)=	3:18
#Project=
#Sample=
#Site=
#Title=	Mb_00_13_25_2x_45s_532 nm_x100_100%_600 gr_mm
#Remark=
#Date=	06.07.2022 11:39
#Acquired=	06.07.2022 11:39:04
#Base:Fit=	10.08.2022 10:16:56
#Base:Sub=	10.08.2022 10:17:24
#Filter:Polynom=	16.08.2022 10:36:38
#AxisType[0]=Intens
#AxisUnit[0]=Cnt
#AxisType[1]=Spectr
#AxisUnit[1]=1/cm
200.398	75.4913
204.027	50.2753
207.657	27.6367
211.283	11.6582
214.909	6.2562
218.533	12.8043
222.157	28.5856
225.777	52.0578
229.396	75.7929
233.016	98.2537
236.632	118.494
240.247	134.409
243.86	146.332
247.474	160.408
251.085	174.005
254.694	183.276
258.301	190.151
261.908	196.072
265.513	193.424
269.116	186.77
272.718	175.557
276.319	161.331
279.918	142.196
283.516	120.831
287.113	98.7474
290.708	74.1485
294.302	55.1138
297.894	39.5827
301.485	29.3486
305.073	22.2703
308.661	17.4119
312.247	14.7209
315.833	11.739
319.415	9.1916
322.997	6.77478
326.579	5.80824
330.156	3.49432
333.735	2.6302
337.31	2.45199
340.885	-1.91564
344.458	-2.48252
348.03	-1.6625
351.6	-5.93847
355.17	-6.21787
358.737	-4.8847
362.304	-4.00267
365.868	4.6608
369.431	12.2838
372.994	22.6399
376.554	31.9915
380.112	44.9985
383.669	61.347
387.225	84.8043
390.781	105.938
394.334	128.679
397.885	146.45
401.436	161.427
404.984	172.527
408.532	179.893
412.078	181.814
415.623	179.568
419.166	173.47
422.708	164.175
426.248	151.005
429.788	133.716
433.326	116.231
436.86	97.1568
440.395	75.8084
443.929	57.285
447.461	41.25
450.99	25.8923
454.52	11.6411
458.048	-0.0762054
461.573	-10.2657
465.099	-14.85
468.623	-11.9226
472.144	-7.34605
475.666	-1.14187
479.184	6.08047
482.703	11.4945
486.218	15.5669
489.734	20.0746
493.247	24.0407
496.759	30.5415
500.271	32.9743
503.779	37.8851
507.287	43.9194
510.795	46.376
514.299	48.7578
517.803	52.0598
521.305	54.6667
524.805	55.8515
528.307	54.8318
531.805	53.2552
535.301	51.0515
538.797	48.8817
542.291	45.3063
545.783	41.3356
549.275	37.6049
552.765	33.6071
556.253	29.2218
559.738	24.9614
563.224	24.0852
566.709	20.7633
570.192	17.6634
573.674	14.4573
577.153	12.292
580.632	11.2386
584.11	9.34181
587.587	7.57921
591.06	8.4807
594.534	6.76748
598.005	7.13135
601.476	6.38666
604.944	8.47819
608.413	9.3057
611.878	8.16581
615.344	8.03585
618.807	9.03708
622.27	10.379
625.73	12.5065
629.189	12.4941
632.648	17.6807
636.105	19.5807
639.559	22.7146
643.013	27.2405
646.467	28.0337
649.918	30.0128
653.368	28.5047
656.816	26.072
660.263	24.4496
663.708	24.238
667.153	23.1687
670.596	22.4803
674.037	20.7045
677.478	18.1537
680.917	14.0366
684.355	11.7079
687.791	7.77065
691.224	6.10019
694.658	3.53455
698.091	1.57432
701.522	2.20132
704.95	4.01305
708.379	5.31826
711.806	6.8006
715.23	9.11173
718.655	12.1161
722.078	10.6971
725.498	12.1483
728.919	11.8871
732.337	13.9221
735.755	14.467
739.17	14.3658
742.584	17.2346
745.998	20.6475
749.409	24.8458
752.819	28.6223
756.23	30.8284
759.637	31.9751
763.043	34.9087
766.448	36.4959
769.853	37.2235
773.255	40.5594
776.656	42.6028
780.056	43.9286
783.454	46.1219
786.851	50.9904
790.247	52.3975
793.641	51.0182
797.034	52.3087
800.426	51.9575
803.817	50.2843
807.206	52.35
810.592	52.8895
813.979	53.4128
817.364	54.3501
820.748	54.1623
824.129	55.7271
827.511	58.9069
830.891	58.9256
834.269	59.0089
837.646	56.7099
841.023	53.7028
844.396	51.9815
847.77	47.7096
851.141	46.9478
854.513	45.1951
857.881	44.0158
861.248	40.9373
864.616	40.6049
867.98	42.058
871.343	41.4893
874.707	38.0527
878.068	34.6072
881.428	32.5749
884.786	28.6519
888.143	26.6927
891.498	24.5881
894.855	22.1957
898.208	22.9524
901.56	21.8535
904.91	20.249
908.26	19.7232
911.608	18.4284
914.955	17.4116
918.298	17.1978
921.643	16.8838
924.986	15.9553
928.328	17.0509
931.668	19.0446
935.006	19.5969
938.344	19.896
941.681	23.3037
945.014	23.7041
948.349	21.9758
951.682	18.273
955.012	16.4347
958.343	12.1368
961.67	8.02431
964.998	6.2756
968.323	9.29494
971.649	14.5123
974.971	19.5287
978.293	24.5006
981.615	28.9221
984.933	34.6052
988.251	40.8696
991.567	45.2638
994.884	52.0594
998.198	56.8173
1001.51	60.6944
1004.82	60.3944
1008.13	58.4441
1011.44	55.0131
1014.75	51.65
1018.06	53.898
1021.36	66.784
1024.66	90.816
1027.97	115.405
1031.27	139.777
1034.57	165.976
1037.87	184.733
1041.16	201.713
1044.46	216.627
1047.76	231.665
1051.05	239.629
1054.34	245.165
1057.63	242.312
1060.92	238.665
1064.21	231.546
1067.5	219.735
1070.78	203.827
1074.07	183.164
1077.35	158.014
1080.63	126.271
1083.91	91.5587
1087.19	58.3871
1090.47	38.3891
1093.75	28.8822
1097.03	29.6696
1100.3	41.8819
1103.57	58.1007
1106.84	72.1505
1110.11	76.5189
1113.38	80.0411
1116.65	80.1372
1119.92	80.1806
1123.19	78.2194
1126.45	73.4633
1129.71	68.5108
1132.97	61.3107
1136.23	57.7083
1139.49	52.6808
1142.75	46.5977
1146.01	39.0659
1149.26	31.1665
1152.52	22.2904
1155.77	11.5453
1159.02	1.47634
1162.27	-7.16835
1165.52	-8.1994
1168.77	-0.903095
1172.02	6.48534
1175.26	8.54555
1178.51	9.80261
1181.75	13.109
1184.99	14.3355
1188.23	14.1035
1191.47	13.208
1194.71	14.5292
1197.94	18.0681
1201.18	19.2102
1204.41	21.8512
1207.65	25.9712
1210.88	30.8745
1214.11	34.936
1217.34	42.2627
1220.57	49.138
1223.79	51.5976
1227.02	58.0679
1230.24	62.1105
1233.47	66.6684
1236.69	71.4972
1239.91	73.7261
1243.13	78.1459
1246.34	79.9932
1249.56	74.95
1252.78	70.4507
1255.99	74.3262
1259.2	84.9453
1262.42	98.1672
1265.63	109.391
1268.84	120.195
1272.04	131.903
1275.25	142.809
1278.46	155.108
1281.66	165.698
1284.86	175.549
1288.07	181.002
1291.27	184.355
1294.47	183.69
1297.66	186.038
1300.86	182.251
1304.06	177.577
1307.25	172.751
1310.44	166.611
1313.64	158.47
1316.83	147.186
1320.02	135.222
1323.2	119.859
1326.39	103.42
1329.58	91.6917
1332.76	91.8665
1335.95	98.056
1339.13	99.4292
1342.31	99.5845
1345.49	97.5662
1348.67	97.2513
1351.85	94.7804
1355.02	95.4104
1358.2	97.6179
1361.37	96.2163
1364.54	93.4405
1367.71	90.0033
1370.88	85.0964
1374.05	80.1829
1377.22	76.307
1380.39	72.8866
1383.55	72.3674
1386.72	71.5633
1389.88	71.7818
1393.04	68.988
1396.2	66.304
1399.36	69.5904
1402.52	79.2537
1405.68	100.016
1408.83	124.156
1411.98	152.944
1415.14	182.617
1418.29	210.154
1421.44	239.914
1424.59	270.124
1427.74	301.011
1430.89	332.096
1434.03	361.367
1437.18	383.169
1440.32	399.915
1443.46	413.158
1446.6	418.819
1449.74	415.574
1452.88	406.181
1456.02	390.139
1459.16	372.179
1462.29	345.946
1465.43	313.925
1468.56	279.095
1471.69	244.035
1474.82	214.482
1477.95	190.589
1481.08	167.668
1484.2	142.405
1487.33	120.009
1490.46	100.005
1493.58	81.45
1496.7	67.2676
1499.82	56.2997
1502.94	49.3915
1506.06	44.8986
1509.18	41.5564
1512.29	37.1302
1515.41	33.6833
1518.52	33.2039
1521.63	32.991
1524.75	31.6652
1527.85	30.0392
1530.96	28.8389
1534.07	30.3272
1537.18	32.2229
1540.28	35.0976
1543.39	37.7546
1546.49	40.3462
1549.59	44.3109
1552.69	47.4528
1555.79	51.2675
1558.89	55.0488
1561.99	58.7723
1565.08	62.5882
1568.18	66.2826
1571.27	71.8584
1574.37	77.3719
1577.46	80.4587
1580.55	84.5803
1583.64	88.7315
1586.73	89.8137
1589.81	93.5767
1592.9	95.9497
1595.98	98.7671
1599.06	99.5984
1602.15	100.479
1605.23	98.6023
1608.31	97.229
1611.39	97.5047
1614.46	96.3397
1617.54	93.6908
1620.61	93.5557
1623.69	91.1188
1626.76	89.2299
1629.83	87.2594
1632.9	85.8284
1635.97	81.2572
1639.04	79.4543
1642.11	77.886
1645.17	80.4812
1648.24	79.7402
1651.3	78.5917
1654.36	79.1589
1657.42	79.74
1660.48	80.5459
1663.54	79.0453
1666.6	79.1433
1669.66	78.1408
1672.71	73.2063
1675.77	70.7761
1678.82	66.243
1681.87	62.7278
1684.92	58.0822
1687.97	52.5443
1691.02	45.1926
1694.07	40.6055
1697.11	36.2943
1700.16	31.9788
1703.2	27.5084
1706.25	22.1693
1709.29	15.5987
1712.33	11.3926
1715.37	10.1957
1718.41	6.97577
1721.44	4.79942
1724.48	3.05534
1727.51	1.72464
1730.55	1.87851
1733.58	1.58121
1736.61	0.471667
1739.64	3.25842
1742.67	4.34105
1745.7	5.26716
1748.72	6.61393
1751.75	8.3277
1754.77	11.1621
1757.8	13.3803
1760.82	13.385
1763.84	15.3116
1766.86	16.5516
1769.88	19.0779
1772.9	16.8086
1775.91	15.6948
1778.93	15.0194
1781.94	14.1224
1784.96	12.558
1787.97	13.3465
1790.98	12.5477
1793.99	9.97184
1797	9.92461
1800.01	9.01199
1803.01	6.50885
1806.02	6.59076
1809.02	6.69627
1812.02	7.93554
1815.02	9.92997
1818.03	9.79666
1821.02	9.86052
1824.02	11.6665
1827.02	12.8943
1830.02	12.5867
1833.01	12.7752
1836.01	11.8442
1839	13.1741
1841.99	12.457
1844.98	11.5779
1847.97	9.92216
1850.96	10.3901
1853.95	10.1936
1856.93	11.665
1859.92	10.4996
1862.9	10.3148
1865.88	8.68505
1868.87	7.61815
1871.85	7.52479
1874.83	6.63912
1877.81	5.14395
1880.78	4.86071
1882.53	3.74416
1885.52	3.13262
1888.51	3.34216
1891.5	4.39885
1894.48	4.01402
1897.47	3.01724
1900.45	3.82033
1903.43	1.98476
1906.41	1.26021
1909.39	0.673
1912.37	1.56693
1915.35	1.24569
1918.33	3.51122
1921.3	3.17351
1924.28	6.26161
1927.25	8.68065
1930.22	7.62798
1933.19	2.19067
1936.16	5.30186
1939.13	8.26567
1942.1	13.0765
1945.07	15.793
1948.03	17.4291
1951	17.4685
1953.96	18.2702
1956.92	18.6164
1959.88	20.0564
1962.84	21.8351
1965.8	23.3707
1968.76	21.5648
1971.72	19.8333
1974.67	18.5483
1977.63	17.5823
1980.58	15.4246
1983.54	14.1674
1986.49	12.2346
1989.44	13.2868
1992.39	9.04889
1995.33	8.02029
1998.28	7.02606
2001.23	3.92957
2004.17	0.781418
2007.12	3.91844
2010.06	7.33095
2013	7.23497
2015.94	7.80834
2018.88	9.26035
2021.82	7.90153
2024.76	9.35263
2027.69	10.0412
2030.63	10.675
2033.56	11.9554
2036.5	13.0474
2039.43	11.559
2042.36	11.4173
2045.29	11.4083
2048.22	13.8215
2051.15	14.1252
2054.07	15.0221
2057	17.1236
2059.92	16.3559
2062.85	18.3927
2065.77	17.289
2068.69	17.4696
2071.61	17.8354
2074.53	15.3699
2077.45	14.5377
2080.37	14.1612
2083.28	13.4065
2086.2	14.92
2089.11	14.2108
2092.02	14.4526
2094.94	13.4061
2097.85	12.4121
2100.76	10.7251
2103.66	10.4458
2106.57	11.3211
2109.48	10.368
2112.38	9.07631
2115.29	9.61177
2118.19	8.88018
2121.09	9.38006
2123.99	8.28422
2126.89	6.43289
2129.79	4.55196
2132.69	4.91802
2135.59	5.92316
2138.48	6.0965
2141.38	6.51212
2144.27	6.55457
2147.17	5.52364
2150.06	5.8176
2152.95	6.67464
2155.84	8.84224
2158.73	9.80475
2161.61	10.2989
2164.5	13.3138
2167.38	13.8526
2170.27	16.4918
2173.15	19.1304
2176.03	24.0493
2178.91	23.6584
2181.8	24.1723
2184.67	25.6447
2187.55	27.118
2190.43	26.4654
2193.3	26.888
2196.18	27.3182
2199.05	28.1211
2201.93	29.9956
2204.8	28.8718
2207.67	27.4269
2210.54	25.2022
2213.41	22.1795
2216.27	20.1428
2219.14	20.0818
2222.01	18.0265
2224.87	18.3924
2227.73	19.336
2230.6	19.7527
2233.46	19.146
2236.32	19.8664
2239.18	23.2446
2242.03	24.2226
2244.89	24.5229
2247.75	23.3913
2250.6	21.076
2253.46	22.1079
2256.31	22.3624
2259.16	22.9893
2262.01	23.4832
2264.86	24.365
2267.71	23.8728
2270.56	22.8244
2273.4	19.0155
2276.25	17.0506
2279.09	13.5022
2281.94	12.4888
2284.78	14.5494
2287.62	14.5559
2290.46	13.1166
2293.3	11.8606
2296.14	11.6905
2298.98	13.1227
2301.82	14.4387
2304.65	14.7263
2307.49	14.8347
2310.32	15.1148
2313.15	13.6818
2315.98	12.8841
2318.81	13.2305
2321.64	15.0759
2324.47	16.0646
2327.3	13.9254
2330.12	14.3241
2332.95	13.8212
2335.77	14.3853
2338.6	13.4695
2341.42	12.062
2344.24	9.2173
2347.06	7.91206
2349.88	7.621
2352.7	6.61574
2355.51	5.95749
2358.33	5.19921
2361.14	5.08256
2363.96	4.87279
2366.77	4.67456
2369.58	5.02264
2372.39	4.46563
2375.2	3.36315
2378.01	4.1124
2380.82	4.3121
2383.63	3.83104
2386.43	4.97573
2389.24	4.50683
2392.04	2.63365
2394.84	2.47794
2397.65	2.28805
2400.45	5.56661
2403.25	6.26548
2406.05	7.44216
2408.84	8.24416
2411.64	9.23766
2414.44	10.0946
2417.23	12.3744
2420.02	12.4513
2422.82	13.8887
2425.61	14.2593
2428.4	14.134
2431.19	12.6618
2433.98	10.0423
2436.77	10.1176
2439.55	9.69449
2442.34	10.2328
2445.12	8.48196
2447.91	8.33397
2450.69	8.28601
2453.47	7.96844
2456.25	7.93468
2459.03	8.45286
2461.81	8.72568
2464.59	11.427
2467.36	13.3394
2470.14	12.9159
2472.92	14.5025
2475.69	14.4728
2478.46	15.1759
2481.23	15.7036
2484	15.9728
2486.77	14.6233
2489.54	11.9275
2492.31	11.2666
2495.08	10.2968
2497.84	9.00465
2500.61	8.09544
2503.37	8.97046
2506.13	8.46105
2508.9	7.44002
2511.66	9.15899
2514.42	10.4229
2517.18	13.2554
2519.93	14.3111
2522.69	14.0763
2525.45	13.7714
2528.2	15.3004
2530.95	16.3588
2533.71	18.1791
2536.46	19.3545
2539.21	20.6668
2541.96	20.2755
2544.71	20.745
2547.46	22.8109
2550.2	24.8122
2552.95	24.0622
2555.7	24.9391
2558.44	25.7897
2561.18	26.0714
2563.93	25.5534
2566.67	26.6905
2569.41	25.1701
2572.15	24.9996
2574.88	26.2254
2577.62	27.7716
2580.36	26.2565
2583.09	27.1881
2585.83	25.6644
2588.56	24.3858
2591.29	24.0464
2594.02	24.7296
2596.75	26.1394
2599.48	25.9509
2602.21	27.4319
2604.94	28.2811
2607.67	28.6726
2610.39	28.1155
2613.12	28.63
2615.84	28.5888
2618.56	27.8527
2621.28	27.4903
2624.01	27.7267
2626.72	27.057
2629.44	26.771
2632.16	27.717
2634.88	25.9189
2637.59	26.7481
2640.31	25.7762
2643.02	27.1653
2645.74	27.3624
2648.45	27.1595
2651.16	28.5872
2653.87	28.6873
2656.58	28.5068
2659.29	29.6949
2661.99	28.7505
2664.7	29.4436
2667.41	32.344
2670.11	32.8461
2672.81	34.236
2675.51	33.2512
2678.22	33.7966
2680.92	33.4248
2683.62	33.7709
2686.31	34.6468
2689.01	37.1958
2691.71	39.2074
2694.4	44.3752
2697.1	50.016
2699.79	56.7291
2702.49	63.1559
2705.18	70.3957
2707.87	76.4764
2710.56	82.9352
2713.25	86.7029
2715.94	90.7593
2718.62	92.7194
2721.31	94.355
2723.99	91.5377
2726.68	90.6427
2729.36	87.3446
2732.04	84.0477
2734.73	77.1143
2737.41	70.7709
2740.08	63.4596
2742.76	54.6543
2745.44	45.329
2748.12	36.7785
2750.79	28.671
2753.47	21.8171
2756.14	16.4247
2758.81	12.8457
2761.49	9.27612
2764.16	7.34997
2766.83	4.6686
2769.5	2.12114
2772.16	0.362577
2774.83	0.852144
2777.5	0.136049
2780.16	-0.867857
2782.83	0.261352
2785.49	-1.55817
2788.15	-2.06836
2790.82	-3.12345
2793.48	-3.08782
2796.14	-4.58489
2798.79	-6.83413
2801.45	-9.85536
2804.11	-17.878
2806.76	-29.2248
2809.42	-34.4357
2812.07	-27.6884
2814.73	-1.82787
2817.38	42.3772
2820.03	101.717
2822.68	169.328
2825.33	243.982
2827.98	322.579
2830.63	403.496
2833.27	484.472
2835.92	562.684
2838.56	637.572
2841.21	703.385
2843.85	757.775
2846.49	811.527
2849.13	880.212
2851.77	960.878
2854.41	1042.32
2857.05	1111.49
2859.69	1167.44
2862.32	1206.73
2864.96	1227.43
2867.59	1235.13
2870.23	1235.1
2872.86	1233.44
2875.49	1237.6
2878.12	1243.5
2880.75	1248.09
2883.38	1241.65
2886.01	1226.86
2888.63	1203.45
2891.26	1169.92
2893.89	1127.82
2896.51	1080.57
2899.13	1028.88
2901.76	975.273
2904.38	923.411
2907	880.635
2909.62	857.459
2912.24	855.451
2914.85	873.482
2917.47	880.846
2920.09	876.987
2922.7	866.01
2925.32	850.962
2927.93	832.115
2930.54	811.233
2933.15	788.488
2935.76	763.666
2938.37	735.317
2940.98	706.284
2943.59	669.548
2946.2	629.391
2948.8	590.479
2951.41	549.477
2954.01	508.398
2956.62	467.793
2959.22	427.74
2961.82	391.693
2964.42	358.509
2967.02	327.552
2969.62	302.301
2972.22	279.753
2974.81	256.268
2977.41	232.685
2980	207.775
2982.6	183.959
2985.19	160.422
2987.78	137.373
2990.38	118
2992.97	99.6791
2995.56	83.9981
2998.14	71.8267
3000.73	58.4594
3003.32	47.5533
3005.91	37.2294
3008.49	27.6368
3011.07	20.5273
3013.66	15.3639
3016.24	10.4816
3018.82	7.34807
3021.4	4.7385
3023.98	1.44668
3026.56	-0.799646
3029.14	-3.18266
3031.71	-3.05115
3034.29	-2.02434
3036.87	-1.69948
3039.44	0.000817775
3042.01	2.89171
3044.59	6.39423
3047.16	10.3483
3049.73	13.0523
3052.3	15.7443
3054.87	19.3374
3057.43	21.5148
3060	24.1706
3062.57	26.4421
3065.13	28.7565
3067.7	32.6474
3070.26	34.9325
3072.82	38.7939
3075.39	42.895
3077.95	47.4042
3080.51	49.2409
3083.07	52.3287
3085.63	54.9885
3088.18	56.799
3090.74	58.0325
3093.29	61.3815
3095.85	67.5623
3098.4	74.0524
3100.95	79.5995
3103.51	85.591
3106.06	91.6204
3108.61	98.3951
3111.16	103.99
3113.71	111.431
3116.25	119.553
3118.8	127.474
3121.35	134.679
3123.89	144.376
3126.44	152.594
3128.98	162.456
3131.52	172.28
3134.06	181.881
3136.6	193.979
3139.14	202.849
3141.68	210.949
3144.22	219.251
3146.76	226.379
3149.29	234.608