File: data/Raman/poly_smoothed/Mb_00_13_04_1x_45s_532 nm_x100_100%_600 gr_mm_01.txt
#Acq. time (s)=	45
#Accumulations=	2
#Range (cm-¹)=	200...3150
#Windows=	2
#Auto scanning=	Off
#Autofocus=	Off
#Macrospot=	Off
#AutoExposure=	Off
#Spike filter=	Multiple accum.
#Delay time (s)=	0
#Binning=	1
#Readout mode=	Signal
#DeNoise=	Off
#ICS correction=	On
#Dark correction=	Off
#Inst. Process=	Off
#Detector Gain=	Best Dynamic Range
#Detector ADC=	20 kHz
#Detector temperature (°C)=	-69.85
#Instrument=	LabRAM HR Evol
#Detector=	Synapse
#Objective=	x100
#Grating=	600 gr/mm
#ND Filter=	100%
#Laser (nm)=	532
#Hole=	100.021
#Range=	Auto
#Laser Pol.=	No
#Raman. Pol.=	No
#Laser Pol. (°)=	-0.0007625
#Raman Pol. (°)=	89.9995
#Collection=	Microscope
#StageXY=	Marzhauser
#StageZ=	Marzhauser
#X (µm)=	-975.8
#Y (µm)=	-2926.5
#Z (µm)=	527.5
#Full time(mm:ss)=	3:18
#Project=
#Sample=
#Site=
#Title=	Mb_00_13_04_2x_45s_532 nm_x100_100%_600 gr_mm
#Remark=
#Date=	06.07.2022 09:58
#Acquired=	06.07.2022 09:58:13
#Base:Fit=	10.08.2022 10:16:36
#Base:Fit=	10.08.2022 10:16:56
#Base:Sub=	10.08.2022 10:17:24
#Filter:Polynom=	16.08.2022 10:36:38
#AxisType[0]=Intens
#AxisUnit[0]=Cnt
#AxisType[1]=Spectr
#AxisUnit[1]=1/cm
200.398	15.9916
204.027	8.61577
207.657	2.92871
211.283	-0.741456
214.909	-0.426448
218.533	3.70008
222.157	9.27472
225.777	17.1535
229.396	24.2888
233.016	30.5514
236.632	36.4175
240.247	40.9938
243.86	45.3156
247.474	48.893
251.085	53.8607
254.694	57.7069
258.301	60.0904
261.908	60.5946
265.513	59.968
269.116	59.0647
272.718	56.5736
276.319	53.9829
279.918	47.9379
283.516	42.4622
287.113	36.5754
290.708	30.8477
294.302	27.7605
297.894	24.9044
301.485	23.4568
305.073	21.4355
308.661	20.4049
312.247	20.5983
315.833	18.6664
319.415	17.7534
322.997	15.6203
326.579	14.5338
330.156	12.9756
333.735	12.3933
337.31	10.6853
340.885	8.52996
344.458	6.65068
348.03	4.29872
351.6	1.71306
355.17	-0.851105
358.737	0.354758
362.304	2.56203
365.868	3.97549
369.431	5.90341
372.994	8.99264
376.554	10.9042
380.112	16.1464
383.669	21.998
387.225	29.7415
390.781	36.6109
394.334	44.2017
397.885	49.1456
401.436	54.6531
404.984	57.4015
408.532	59.2359
412.078	58.2606
415.623	58.7249
419.166	56.6028
422.708	52.3235
426.248	47.9026
429.788	42.3093
433.326	37.7085
436.86	29.7516
440.395	24.3842
443.929	19.6954
447.461	15.9738
450.99	12.2118
454.52	7.81831
458.048	4.31022
461.573	1.74866
465.099	1.73332
468.623	4.3723
472.144	7.71442
475.666	9.73985
479.184	13.6953
482.703	14.9636
486.218	15.5913
489.734	16.0625
493.247	17.2583
496.759	18.7457
500.271	21.8287
503.779	21.4225
507.287	21.5405
510.795	21.0397
514.299	23.116
517.803	22.3927
521.305	21.4315
524.805	22.3018
528.307	21.6658
531.805	21.6751
535.301	20.1902
538.797	19.7287
542.291	19.4864
545.783	19.2804
549.275	18.1167
552.765	15.8831
556.253	15.3424
559.738	15.4743
563.224	14.6805
566.709	13.0227
570.192	11.8344
573.674	10.4713
577.153	10.0858
580.632	9.94541
584.11	8.72528
587.587	8.57901
591.06	6.3
594.534	3.32495
598.005	2.85147
601.476	4.21475
604.944	3.10458
608.413	3.00046
611.878	3.46692
615.344	2.20857
618.807	2.27899
622.27	4.42703
625.73	4.71631
629.189	5.13518
632.648	4.92648
636.105	5.57702
639.559	7.1127
643.013	9.03735
646.467	12.9055
649.918	12.6513
653.368	15.0949
656.816	18.1457
660.263	18.9802
663.708	19.8943
667.153	21.9655
670.596	23.052
674.037	22.2172
677.478	20.1737
680.917	20.2674
684.355	21.271
687.791	21.9464
691.224	19.6022
694.658	17.7991
698.091	16.6767
701.522	16.4384
704.95	16.3851
708.379	15.9204
711.806	13.8491
715.23	15.1457
718.655	15.0099
722.078	14.7383
725.498	16.5061
728.919	16.3278
732.337	16.9448
735.755	19.0333
739.17	23.5458
742.584	25.5613
745.998	28.1682
749.409	29.8149
752.819	33.0772
756.23	35.3528
759.637	38.8645
763.043	44.4372
766.448	47.5746
769.853	51.1425
773.255	53.5345
776.656	55.4012
780.056	58.3854
783.454	61.841
786.851	63.4595
790.247	66.149
793.641	66.2184
797.034	66.2161
800.426	64.8453
803.817	62.9644
807.206	61.9373
810.592	61.4276
813.979	60.491
817.364	61.7522
820.748	60.8557
824.129	60.3614
827.511	57.6858
830.891	56.4323
834.269	55.0298
837.646	54.171
841.023	52.6868
844.396	53.0211
847.77	52.266
851.141	49.5836
854.513	48.3853
857.881	47.9355
861.248	47.1515
864.616	46.5615
867.98	43.5746
871.343	41.2019
874.707	37.8506
878.068	34.4863
881.428	33.6811
884.786	30.8368
888.143	28.4201
891.498	29.5302
894.855	30.1084
898.208	29.8649
901.56	30.2267
904.91	30.0623
908.26	29.8518
911.608	29.892
914.955	30.3273
918.298	30.1501
921.643	30.8158
924.986	33.0611
928.328	34.7644
931.668	35.3974
935.006	35.8035
938.344	36.1834
941.681	34.4109
945.014	34.3339
948.349	35.6317
951.682	34.7611
955.012	32.8863
958.343	31.0983
961.67	29.529
964.998	31.1733
968.323	32.3373
971.649	33.8847
974.971	35.9012
978.293	36.2461
981.615	35.6023
984.933	34.8745
988.251	33.4165
991.567	33.3747
994.884	33.2992
998.198	32.6468
1001.51	32.2852
1004.82	30.6733
1008.13	29.0223
1011.44	28.5934
1014.75	29.711
1018.06	32.2696
1021.36	37.5462
1024.66	43.3745
1027.97	50.841
1031.27	54.6007
1034.57	59.4836
1037.87	62.0387
1041.16	64.5168
1044.46	68.7826
1047.76	71.864
1051.05	72.1855
1054.34	71.3968
1057.63	70.5434
1060.92	67.6081
1064.21	62.0246
1067.5	56.0486
1070.78	51.5522
1074.07	46.1811
1077.35	39.4934
1080.63	33.993
1083.91	28.2457
1087.19	23.7956
1090.47	21.8316
1093.75	21.2478
1097.03	22.1333
1100.3	22.7934
1103.57	23.5567
1106.84	22.0529
1110.11	19.6223
1113.38	18.3477
1116.65	16.9622
1119.92	15.2619
1123.19	13.2465
1126.45	11.6166
1129.71	11.2215
1132.97	11.0059
1136.23	11.4214
1139.49	10.4679
1142.75	9.75706
1146.01	10.1815
1149.26	10.8859
1152.52	11.0834
1155.77	9.90014
1159.02	10.6904
1162.27	11.935
1165.52	13.3229
1168.77	14.6145
1172.02	17.6005
1175.26	18.3356
1178.51	19.2164
1181.75	19.8857
1184.99	20.8184
1188.23	21.0754
1191.47	23.4774
1194.71	26.5006
1197.94	29.3161
1201.18	30.3687
1204.41	33.3095
1207.65	36.4277
1210.88	40.5508
1214.11	43.7965
1217.34	47.0834
1220.57	50.1181
1223.79	53.4206
1227.02	53.8241
1230.24	54.3187
1233.47	55.1236
1236.69	56.8932
1239.91	57.0955
1243.13	55.8429
1246.34	56.6337
1249.56	59.2823
1252.78	57.6803
1255.99	56.4193
1259.2	55.9637
1262.42	54.4729
1265.63	53.9551
1268.84	55.7578
1272.04	57.1675
1275.25	58.2708
1278.46	57.8359
1281.66	59.0179
1284.86	61.0441
1288.07	64.4346
1291.27	67.433
1294.47	69.3539
1297.66	71.7483
1300.86	72.672
1304.06	75.8459
1307.25	76.9365
1310.44	79.1469
1313.64	80.7569
1316.83	80.4002
1320.02	80.6517
1323.2	81.512
1326.39	81.7934
1329.58	82.1683
1332.76	81.2039
1335.95	80.6085
1339.13	79.6378
1342.31	78.6622
1345.49	77.6348
1348.67	75.864
1351.85	74.5449
1355.02	73.6024
1358.2	72.6908
1361.37	72.819
1364.54	69.7504
1367.71	67.3034
1370.88	67.0919
1374.05	64.1589
1377.22	61.12
1380.39	61.1007
1383.55	59.4717
1386.72	57.2187
1389.88	56.7845
1393.04	56.9512
1396.2	56.505
1399.36	56.6
1402.52	58.0612
1405.68	60.0285
1408.83	61.3271
1411.98	65.9167
1415.14	69.9601
1418.29	73.6143
1421.44	79.0062
1424.59	84.5359
1427.74	92.5941
1430.89	98.8192
1434.03	102.54
1437.18	107.452
1440.32	110.268
1443.46	112.697
1446.6	113.062
1449.74	113.187
1452.88	111.538
1456.02	109.86
1459.16	106.939
1462.29	102.562
1465.43	98.3237
1468.56	93.096
1471.69	87.0681
1474.82	80.7081
1477.95	75.9954
1481.08	69.7472
1484.2	64.8689
1487.33	60.2663
1490.46	56.2622
1493.58	51.8898
1496.7	48.1949
1499.82	45.5341
1502.94	42.8654
1506.06	41.9826
1509.18	38.0902
1512.29	37.3583
1515.41	35.2738
1518.52	34.544
1521.63	32.2138
1524.75	33.4774
1527.85	34.4309
1530.96	34.7247
1534.07	36.0884
1537.18	37.031
1540.28	38.1032
1543.39	39.917
1546.49	41.7796
1549.59	45.6219
1552.69	47.9589
1555.79	49.5149
1558.89	50.9358
1561.99	52.1407
1565.08	53.6557
1568.18	53.5057
1571.27	54.7321
1574.37	56.8261
1577.46	57.0047
1580.55	58.8834
1583.64	60.6521
1586.73	60.7882
1589.81	62.1922
1592.9	64.346
1595.98	64.138
1599.06	63.4891
1602.15	63.7718
1605.23	63.3401
1608.31	63.3021
1611.39	62.3619
1614.46	61.8053
1617.54	62.2609
1620.61	62.3157
1623.69	61.5803
1626.76	61.671
1629.83	61.8809
1632.9	62.5823
1635.97	62.5478
1639.04	64.0026
1642.11	64.6194
1645.17	66.0194
1648.24	67.1845
1651.3	69.1283
1654.36	70.6661
1657.42	70.838
1660.48	71.9095
1663.54	72.6239
1666.6	72.5769
1669.66	70.4735
1672.71	67.1793
1675.77	64.2948
1678.82	59.8877
1681.87	56.2361
1684.92	50.8781
1687.97	46.3256
1691.02	40.4328
1694.07	36.8349
1697.11	32.5582
1700.16	27.8409
1703.2	24.1784
1706.25	20.2493
1709.29	18.3613
1712.33	14.8555
1715.37	11.6768
1718.41	10.3109
1721.44	9.72266
1724.48	9.36764
1727.51	9.35473
1730.55	8.2219
1733.58	9.38535
1736.61	10.2198
1739.64	11.4454
1742.67	10.7227
1745.7	10.0748
1748.72	8.69252
1751.75	8.3102
1754.77	6.99373
1757.8	6.78229
1760.82	6.75064
1763.84	7.09495
1766.86	5.7087
1769.88	5.12338
1772.9	4.82167
1775.91	3.61189
1778.93	3.48309
1781.94	3.51219
1784.96	3.82718
1787.97	2.74804
1790.98	2.20291
1793.99	3.02736
1797	3.04981
1800.01	2.98764
1803.01	4.96731
1806.02	5.52889
1809.02	7.06167
1812.02	7.21856
1815.02	5.93503
1818.03	5.60897
1821.02	5.38022
1824.02	4.43727
1827.02	4.50246
1830.02	5.45486
1833.01	6.03744
1836.01	5.71851
1839	5.40356
1841.99	4.98331
1844.98	6.06174
1847.97	4.94559
1850.96	5.0172
1853.95	4.59349
1856.93	5.22949
1859.92	4.97968
1862.9	4.65368
1865.88	5.62027
1868.87	6.46416
1871.85	6.13197
1874.83	6.3038
1877.81	6.45182
1880.78	6.15815
1882.53	6.82967
1885.52	5.48648
1888.51	5.74661
1891.5	7.23125
1894.48	8.03247
1897.47	8.10904
1900.45	8.5464
1903.43	8.80653
1906.41	8.95726
1909.39	8.60671
1912.37	8.76571
1915.35	9.00387
1918.33	8.72305
1921.3	8.045
1924.28	6.81094
1927.25	6.12743
1930.22	5.48266
1933.19	4.82362
1936.16	4.59028
1939.13	4.63889
1942.1	3.07325
1945.07	3.9319
1948.03	4.37759
1951	5.78643
1953.96	6.78314
1956.92	7.34479
1959.88	7.5273
1962.84	8.32467
1965.8	7.98579
1968.76	7.68444
1971.72	8.16775
1974.67	10.5154
1977.63	10.3106
1980.58	10.7076
1983.54	10.6044
1986.49	11.6545
1989.44	10.8213
1992.39	10.8442
1995.33	8.72382
1998.28	9.74944
2001.23	8.93125
2004.17	9.81828
2007.12	10.2494
2010.06	10.7705
2013	10.677
2015.94	10.1743
2018.88	10.8381
2021.82	11.0498
2024.76	11.2407
2027.69	10.6193
2030.63	10.7503
2033.56	9.80873
2036.5	9.89919
2039.43	9.72768
2042.36	10.4638
2045.29	11.9878
2048.22	11.9722
2051.15	11.8563
2054.07	11.9345
2057	12.4731
2059.92	12.7796
2062.85	12.636
2065.77	12.167
2068.69	11.6841
2071.61	11.935
2074.53	11.4326
2077.45	11.5849
2080.37	11.2435
2083.28	10.7714
2086.2	8.66043
2089.11	7.99714
2092.02	8.23537
2094.94	8.34415
2097.85	7.38589
2100.76	6.2852
2103.66	5.25554
2106.57	3.96517
2109.48	3.47215
2112.38	2.92151
2115.29	2.56923
2118.19	4.18265
2121.09	2.74542
2123.99	2.53558
2126.89	2.94386
2129.79	3.06686
2132.69	3.87581
2135.59	3.42304
2138.48	3.80463
2141.38	3.78768
2144.27	4.28225
2147.17	6.02046
2150.06	7.11768
2152.95	8.24392
2155.84	8.82561
2158.73	8.86595
2161.61	11.1384
2164.5	11.4729
2167.38	10.1337
2170.27	9.1078
2173.15	9.18342
2176.03	8.88778
2178.91	8.08677
2181.8	7.47481
2184.67	6.62778
2187.55	7.18274
2190.43	7.05946
2193.3	6.09346
2196.18	7.16702
2199.05	7.44085
2201.93	7.20506
2204.8	7.26703
2207.67	7.65961
2210.54	9.13696
2213.41	7.93299
2216.27	9.36066
2219.14	10.9196
2222.01	12.4603
2224.87	11.9531
2227.73	11.2904
2230.6	11.6704
2233.46	9.97989
2236.32	9.58301
2239.18	8.12335
2242.03	7.55289
2244.89	8.20497
2247.75	7.43913
2250.6	8.6402
2253.46	8.34402
2256.31	8.22885
2259.16	9.20619
2262.01	9.3155
2264.86	9.34389
2267.71	10.4491
2270.56	10.104
2273.4	10.4465
2276.25	10.3228
2279.09	11.6787
2281.94	10.013
2284.78	8.55152
2287.62	8.79999
2290.46	7.74078
2293.3	5.60105
2296.14	5.01646
2298.98	4.61879
2301.82	4.29694
2304.65	3.83905
2307.49	3.81275
2310.32	2.57749
2313.15	3.38916
2315.98	4.28381
2318.81	4.56902
2321.64	4.30868
2324.47	2.26891
2327.3	2.07709
2330.12	3.95665
2332.95	3.89498
2335.77	4.45539
2338.6	4.58137
2341.42	5.41345
2344.24	5.5415
2347.06	4.4811
2349.88	5.12133
2352.7	3.58625
2355.51	4.15079
2358.33	4.62009
2361.14	3.85268
2363.96	4.17465
2366.77	5.48087
2369.58	4.87404
2372.39	3.83939
2375.2	4.40425
2378.01	3.22064
2380.82	2.82059
2383.63	4.1429
2386.43	4.11364
2389.24	4.95503
2392.04	3.49968
2394.84	3.89293
2397.65	5.02694
2400.45	5.20131
2403.25	5.1239
2406.05	4.76834
2408.84	5.47259
2411.64	5.0644
2414.44	5.07324
2417.23	4.54857
2420.02	3.93348
2422.82	4.4446
2425.61	4.55645
2428.4	4.03288
2431.19	3.84434
2433.98	3.26975
2436.77	3.11041
2439.55	1.93688
2442.34	1.98578
2445.12	2.59265
2447.91	2.22001
2450.69	2.80676
2453.47	2.21666
2456.25	2.33067
2459.03	2.16937
2461.81	2.3511
2464.59	1.47671
2467.36	1.11769
2470.14	0.716219
2472.92	1.23901
2475.69	1.38988
2478.46	2.29117
2481.23	2.2672
2484	2.23374
2486.77	2.16193
2489.54	2.30531
2492.31	2.16575
2495.08	1.58439
2497.84	1.75606
2500.61	1.91069
2503.37	1.74326
2506.13	1.00198
2508.9	1.0083
2511.66	1.19515
2514.42	0.439153
2517.18	0.252874
2519.93	-0.299433
2522.69	-0.745423
2525.45	-0.528057
2528.2	0.205192
2530.95	1.09902
2533.71	0.592976
2536.46	1.56898
2539.21	1.26596
2541.96	2.44102
2544.71	1.79413
2547.46	3.18892
2550.2	3.06964
2552.95	3.20421
2555.7	4.09297
2558.44	3.16244
2561.18	3.86771
2563.93	4.55932
2566.67	4.79389
2569.41	4.93984
2572.15	3.99686
2574.88	3.16211
2577.62	1.29657
2580.36	2.17489
2583.09	3.33405
2585.83	3.44587
2588.56	3.44496
2591.29	4.0339
2594.02	4.96319
2596.75	5.67406
2599.48	5.36311
2602.21	4.94191
2604.94	4.86323
2607.67	4.72409
2610.39	5.73117
2613.12	5.51467
2615.84	6.14935
2618.56	6.25801
2621.28	6.42256
2624.01	7.06213
2626.72	6.61171
2629.44	7.1528
2632.16	6.91341
2634.88	6.8337
2637.59	6.56393
2640.31	4.85788
2643.02	4.3952
2645.74	5.5979
2648.45	5.57406
2651.16	5.46365
2653.87	5.46423
2656.58	5.53407
2659.29	6.15509
2661.99	6.658
2664.7	7.29183
2667.41	7.72624
2670.11	7.99356
2672.81	8.21267
2675.51	7.90274
2678.22	8.30328
2680.92	8.87585
2683.62	9.78538
2686.31	10.007
2689.01	11.0234
2691.71	10.3709
2694.4	11.0881
2697.1	13.4238
2699.79	13.839
2702.49	13.9963
2705.18	14.0212
2707.87	14.6189
2710.56	15.2271
2713.25	15.3732
2715.94	16.1332
2718.62	16.4606
2721.31	16.4356
2723.99	16.3323
2726.68	17.0704
2729.36	16.6356
2732.04	15.3605
2734.73	13.3568
2737.41	11.4248
2740.08	10.6551
2742.76	9.28696
2745.44	8.196
2748.12	7.43753
2750.79	6.32692
2753.47	4.4045
2756.14	5.02613
2758.81	4.34983
2761.49	4.08287
2764.16	3.69387
2766.83	2.77707
2769.5	3.36566
2772.16	2.2087
2774.83	2.57351
2777.5	2.49869
2780.16	2.08779
2782.83	2.18947
2785.49	1.72677
2788.15	1.23482
2790.82	1.11074
2793.48	0.345819
2796.14	-0.0931649
2798.79	-0.0586459
2801.45	-0.109079
2804.11	0.258015
2806.76	0.848727
2809.42	-0.253757
2812.07	0.799275
2814.73	2.97841
2817.38	6.08611
2820.03	10.5498
2822.68	14.9496
2825.33	20.6338
2827.98	26.2388
2830.63	33.0957
2833.27	39.0095
2835.92	46.2495
2838.56	54.4021
2841.21	63.6952
2843.85	74.0652
2846.49	85.4665
2849.13	97.1379
2851.77	108.729
2854.41	119.977
2857.05	131.237
2859.69	141.472
2862.32	151.183
2864.96	160.473
2867.59	168.118
2870.23	174.842
2872.86	180.441
2875.49	186.589
2878.12	191.784
2880.75	196.114
2883.38	200.196
2886.01	204.069
2888.63	207.745
2891.26	209.875
2893.89	213.907
2896.51	218.074
2899.13	223.7
2901.76	229.98
2904.38	237.193
2907	246.338
2909.62	254.559
2912.24	263.269
2914.85	272.132
2917.47	279.32
2920.09	285.236
2922.7	289.437
2925.32	291.827
2927.93	292.958
2930.54	292.262
2933.15	288.666
2935.76	284.626
2938.37	277.603
2940.98	270.408
2943.59	262.2
2946.2	252.209
2948.8	242.762
2951.41	232.891
2954.01	221.91
2956.62	210.505
2959.22	200.414
2961.82	190.463
2964.42	181.139
2967.02	172.037
2969.62	162.901
2972.22	153.142
2974.81	143.767
2977.41	134.457
2980	124.096
2982.6	113.362
2985.19	103.416
2987.78	93.9738
2990.38	84.3004
2992.97	74.299
2995.56	65.2318
2998.14	56.7962
3000.73	48.3223
3003.32	41.041
3005.91	33.9084
3008.49	27.3653
3011.07	21.7861
3013.66	16.1547
3016.24	11.8733
3018.82	8.20163
3021.4	4.66932
3023.98	2.83062
3026.56	1.17565
3029.14	0.667129
3031.71	0.0289034
3034.29	-0.424403
3036.87	0.86393
3039.44	1.27404
3042.01	1.90242
3044.59	2.96619
3047.16	4.99815
3049.73	5.91674
3052.3	7.2203
3054.87	7.02258
3057.43	6.873
3060	7.72981
3062.57	6.29764
3065.13	6.77704
3067.7	7.97589
3070.26	7.38309
3072.82	6.80146
3075.39	6.6312
3077.95	5.0389
3080.51	4.05738
3083.07	3.32025
3085.63	2.94744
3088.18	2.38377
3090.74	2.8944
3093.29	3.15093
3095.85	3.77361
3098.4	4.08311
3100.95	4.11295
3103.51	5.51056
3106.06	6.04561
3108.61	7.35656
3111.16	8.34817
3113.71	9.7293
3116.25	11.9771
3118.8	12.4506
3121.35	13.995
3123.89	15.9218
3126.44	17.7897
3128.98	20.735
3131.52	22.4595
3134.06	23.6517
3136.6	24.4984
3139.14	24.9299
3141.68	25.2925
3144.22	25.5715
3146.76	24.9452
3149.29	23.6925