File: data/Raman/poly_smoothed/Mb_00_13_44_1x_45s_532 nm_x100_100%_600 gr_mm_01.txt
#Acq. time (s)=	45
#Accumulations=	2
#Range (cm-¹)=	200...3150
#Windows=	2
#Auto scanning=	Off
#Autofocus=	Off
#Macrospot=	Off
#AutoExposure=	Off
#Spike filter=	Multiple accum.
#Delay time (s)=	0
#Binning=	1
#Readout mode=	Signal
#DeNoise=	Off
#ICS correction=	On
#Dark correction=	Off
#Inst. Process=	Off
#Detector Gain=	Best Dynamic Range
#Detector ADC=	20 kHz
#Detector temperature (°C)=	-69.85
#Instrument=	LabRAM HR Evol
#Detector=	Synapse
#Objective=	x100
#Grating=	600 gr/mm
#ND Filter=	100%
#Laser (nm)=	532
#Hole=	100.021
#Range=	Auto
#Laser Pol.=	No
#Raman. Pol.=	No
#Laser Pol. (°)=	-0.0007625
#Raman Pol. (°)=	89.9995
#Collection=	Microscope
#StageXY=	Marzhauser
#StageZ=	Marzhauser
#X (µm)=	-1049.2
#Y (µm)=	-2900.2
#Z (µm)=	528.4
#Full time(mm:ss)=	3:18
#Project=
#Sample=
#Site=
#Title=	Mb_00_13_44_2x_45s_532 nm_x100_100%_600 gr_mm
#Remark=
#Date=	06.07.2022 13:14
#Acquired=	06.07.2022 13:14:08
#Base:Fit=	10.08.2022 10:16:56
#Base:Sub=	10.08.2022 10:17:24
#Filter:Polynom=	16.08.2022 10:36:38
#AxisType[0]=Intens
#AxisUnit[0]=Cnt
#AxisType[1]=Spectr
#AxisUnit[1]=1/cm
200.398	16.1048
204.027	6.7124
207.657	1.39514
211.283	-2.30969
214.909	-2.05205
218.533	1.60619
222.157	11.0956
225.777	22.4028
229.396	34.7627
233.016	45.4075
236.632	55.5161
240.247	64.1181
243.86	72.4908
247.474	79.7179
251.085	87.0223
254.694	94.0926
258.301	98.7931
261.908	100.453
265.513	100.753
269.116	97.478
272.718	93.4657
276.319	89.3825
279.918	81.559
283.516	70.7684
287.113	59.4113
290.708	52.6003
294.302	44.2553
297.894	35.0086
301.485	27.8204
305.073	25.5285
308.661	20.9735
312.247	17.8995
315.833	14.4111
319.415	12.2301
322.997	11.4382
326.579	13.0463
330.156	10.3607
333.735	9.99353
337.31	8.48256
340.885	7.6971
344.458	5.67716
348.03	4.49193
351.6	2.05806
355.17	0.538974
358.737	-0.325981
362.304	1.82492
365.868	3.1294
369.431	7.78104
372.994	9.29347
376.554	15.3855
380.112	21.6905
383.669	27.2848
387.225	39.3242
390.781	49.9212
394.334	60.1141
397.885	68.7365
401.436	77.3506
404.984	86.9233
408.532	93.3631
412.078	95.1038
415.623	93.976
419.166	92.9481
422.708	91.3372
426.248	86.3673
429.788	80.2856
433.326	73.2054
436.86	63.4028
440.395	52.9268
443.929	42.9522
447.461	34.694
450.99	27.7382
454.52	20.112
458.048	12.3492
461.573	4.5273
465.099	3.26553
468.623	1.66062
472.144	4.17532
475.666	5.65523
479.184	8.14067
482.703	9.1021
486.218	9.57605
489.734	13.8524
493.247	18.4471
496.759	20.3949
500.271	23.8905
503.779	30.4606
507.287	35.3557
510.795	39.0966
514.299	42.8784
517.803	46.4891
521.305	48.9629
524.805	49.8177
528.307	50.6777
531.805	51.9055
535.301	51.7099
538.797	49.5659
542.291	46.9614
545.783	45.4612
549.275	41.922
552.765	38.2402
556.253	33.5069
559.738	29.9995
563.224	27.0848
566.709	24.0785
570.192	18.7243
573.674	15.2763
577.153	14.0814
580.632	12.5456
584.11	13.2479
587.587	12.7974
591.06	13.4052
594.534	11.7891
598.005	12.3722
601.476	13.1131
604.944	14.529
608.413	15.3244
611.878	13.4804
615.344	14.7455
618.807	15.8782
622.27	16.7998
625.73	18.1239
629.189	20.6327
632.648	23.251
636.105	24.5201
639.559	26.1487
643.013	26.0074
646.467	27.3186
649.918	26.5821
653.368	24.3775
656.816	24.2345
660.263	23.0638
663.708	24.021
667.153	21.824
670.596	18.7617
674.037	17.158
677.478	13.251
680.917	10.5971
684.355	8.89844
687.791	6.40257
691.224	5.95669
694.658	3.27257
698.091	3.34489
701.522	4.52956
704.95	4.51415
708.379	6.647
711.806	7.24313
715.23	8.79083
718.655	12.0988
722.078	13.8147
725.498	16.5516
728.919	18.4194
732.337	20.0177
735.755	22.3068
739.17	22.7542
742.584	24.4599
745.998	26.6907
749.409	29.5838
752.819	32.3185
756.23	36.3367
759.637	38.8162
763.043	41.506
766.448	43.7587
769.853	45.2021
773.255	47.4112
776.656	49.8153
780.056	51.2728
783.454	52.1007
786.851	54.368
790.247	57.0853
793.641	57.2639
797.034	59.4284
800.426	60.9051
803.817	62.5938
807.206	61.5554
810.592	60.266
813.979	62.8114
817.364	60.7331
820.748	61.3583
824.129	60.4156
827.511	62.0608
830.891	62.1706
834.269	63.6799
837.646	63.4468
841.023	61.5288
844.396	57.9972
847.77	55.0688
851.141	51.342
854.513	49.0864
857.881	46.4991
861.248	44.9094
864.616	43.7837
867.98	42.8897
871.343	42.3966
874.707	38.3089
878.068	37.8317
881.428	35.2258
884.786	33.8497
888.143	32.0737
891.498	29.6372
894.855	28.0336
898.208	26.2742
901.56	25.1052
904.91	25.461
908.26	27.5775
911.608	29.115
914.955	29.3778
918.298	29.7171
921.643	29.9244
924.986	31.6428
928.328	31.6761
931.668	33.5193
935.006	32.9424
938.344	34.4601
941.681	35.7332
945.014	35.8918
948.349	36.0712
951.682	34.0862
955.012	32.3155
958.343	29.8199
961.67	26.7079
964.998	28.3475
968.323	33.7681
971.649	38.3094
974.971	43.7472
978.293	49.8386
981.615	55.9204
984.933	62.8466
988.251	70.676
991.567	76.6677
994.884	79.5293
998.198	82.4434
1001.51	86.7326
1004.82	90.438
1008.13	90.0664
1011.44	86.4496
1014.75	85.7358
1018.06	89.7981
1021.36	95.2022
1024.66	102.283
1027.97	107.943
1031.27	113.823
1034.57	116.822
1037.87	118.218
1041.16	122.161
1044.46	126.991
1047.76	130.87
1051.05	132.631
1054.34	132.045
1057.63	132.239
1060.92	127.246
1064.21	121.363
1067.5	116.235
1070.78	107.41
1074.07	98.2637
1077.35	86.9164
1080.63	78.0565
1083.91	65.0686
1087.19	54.8811
1090.47	45.8614
1093.75	40.7649
1097.03	42.5817
1100.3	43.4415
1103.57	43.1544
1106.84	42.3251
1110.11	38.9564
1113.38	37.4992
1116.65	33.1688
1119.92	28.8001
1123.19	23.5499
1126.45	19.6214
1129.71	18.0984
1132.97	16.2495
1136.23	12.7911
1139.49	13.2274
1142.75	11.9003
1146.01	11.0408
1149.26	8.75292
1152.52	8.86276
1155.77	9.1499
1159.02	9.79531
1162.27	11.7455
1165.52	11.3848
1168.77	17.1093
1172.02	19.8175
1175.26	23.2602
1178.51	24.2053
1181.75	25.8492
1184.99	28.4908
1188.23	31.454
1191.47	35.864
1194.71	38.6381
1197.94	40.7169
1201.18	45.3754
1204.41	51.1503
1207.65	57.8918
1210.88	65.2024
1214.11	72.5441
1217.34	79.8178
1220.57	87.2816
1223.79	93.0648
1227.02	98.3076
1230.24	103.514
1233.47	110.151
1236.69	113.82
1239.91	118.439
1243.13	120.388
1246.34	121.249
1249.56	123.259
1252.78	120.628
1255.99	119.631
1259.2	117.631
1262.42	114.546
1265.63	111.473
1268.84	110.909
1272.04	109.778
1275.25	106.857
1278.46	107.158
1281.66	108.731
1284.86	109.515
1288.07	113.086
1291.27	117.257
1294.47	121.15
1297.66	124.089
1300.86	128.432
1304.06	133.248
1307.25	138.955
1310.44	142.81
1313.64	147.765
1316.83	149.685
1320.02	152.672
1323.2	152.845
1326.39	154.529
1329.58	155.203
1332.76	154.093
1335.95	152.745
1339.13	149.526
1342.31	146.946
1345.49	145.663
1348.67	143.576
1351.85	139.996
1355.02	136.164
1358.2	132.29
1361.37	129.456
1364.54	123.203
1367.71	118.579
1370.88	114.497
1374.05	112.102
1377.22	109.14
1380.39	106.157
1383.55	102.094
1386.72	99.691
1389.88	98.0089
1393.04	95.9668
1396.2	95.4828
1399.36	95.4388
1402.52	96.6567
1405.68	100.476
1408.83	104.141
1411.98	111.431
1415.14	119.644
1418.29	130.895
1421.44	145.002
1424.59	156.273
1427.74	168.259
1430.89	179.226
1434.03	189.842
1437.18	202.17
1440.32	208.883
1443.46	215.273
1446.6	220.854
1449.74	222.418
1452.88	221.654
1456.02	216.695
1459.16	211.373
1462.29	202.552
1465.43	191.573
1468.56	179.477
1471.69	164.462
1474.82	151.085
1477.95	136.226
1481.08	122.139
1484.2	109.561
1487.33	97.0339
1490.46	87.1501
1493.58	77.7877
1496.7	70.3802
1499.82	62.2224
1502.94	55.3049
1506.06	52.0687
1509.18	48.5128
1512.29	46.4274
1515.41	44.6059
1518.52	42.012
1521.63	42.9251
1524.75	42.862
1527.85	45.2344
1530.96	49.0806
1534.07	51.3601
1537.18	55.3671
1540.28	57.234
1543.39	62.8932
1546.49	66.9133
1549.59	72.4192
1552.69	78.7727
1555.79	81.5802
1558.89	85.6861
1561.99	90.9273
1565.08	95.7782
1568.18	103.39
1571.27	109.608
1574.37	114.656
1577.46	122.814
1580.55	127.754
1583.64	133.203
1586.73	138.125
1589.81	141.936
1592.9	146.342
1595.98	147.486
1599.06	149.719
1602.15	148.503
1605.23	148.396
1608.31	145.043
1611.39	144.013
1614.46	140.754
1617.54	140.612
1620.61	138.52
1623.69	136.003
1626.76	135.019
1629.83	134.515
1632.9	132.858
1635.97	134.464
1639.04	135.827
1642.11	137.86
1645.17	141.442
1648.24	144.285
1651.3	146.35
1654.36	149.245
1657.42	150.964
1660.48	150.409
1663.54	148.62
1666.6	143.942
1669.66	137.522
1672.71	132.2
1675.77	125.851
1678.82	119.962
1681.87	112.082
1684.92	102.266
1687.97	93.6151
1691.02	84.6714
1694.07	76.2434
1697.11	67.3687
1700.16	60.0912
1703.2	53.3254
1706.25	46.9919
1709.29	40.7555
1712.33	35.8636
1715.37	31.1743
1718.41	27.091
1721.44	23.6366
1724.48	19.7235
1727.51	16.5503
1730.55	13.4515
1733.58	11.4457
1736.61	8.78348
1739.64	7.92501
1742.67	6.77909
1745.7	7.71873
1748.72	8.96248
1751.75	8.44915
1754.77	7.5254
1757.8	5.24149
1760.82	5.24004
1763.84	5.30216
1766.86	5.99778
1769.88	5.65451
1772.9	5.4392
1775.91	6.81035
1778.93	7.41011
1781.94	7.84248
1784.96	7.34222
1787.97	7.73703
1790.98	7.45792
1793.99	6.8177
1797	6.63236
1800.01	6.28767
1803.01	6.49686
1806.02	7.04467
1809.02	8.21473
1812.02	9.16736
1815.02	10.1106
1818.03	10.0806
1821.02	10.2886
1824.02	11.1382
1827.02	10.7168
1830.02	9.56093
1833.01	9.55165
1836.01	11.6555
1839	11.7824
1841.99	11.514
1844.98	11.3299
1847.97	10.4798
1850.96	9.83941
1853.95	7.17777
1856.93	6.71025
1859.92	7.71402
1862.9	9.06336
1865.88	8.77934
1868.87	7.84073
1871.85	6.89713
1874.83	6.2084
1877.81	5.38576
1880.78	5.42198
1882.53	6.80749
1885.52	6.85633
1888.51	7.37083
1891.5	9.09961
1894.48	8.56624
1897.47	9.2849
1900.45	8.53851
1903.43	9.88168
1906.41	11.4873
1909.39	11.5131
1912.37	11.0259
1915.35	10.1301
1918.33	10.4028
1921.3	9.91328
1924.28	9.35834
1927.25	8.63104
1930.22	9.326
1933.19	9.86035
1936.16	7.62532
1939.13	4.56528
1942.1	3.65071
1945.07	3.36226
1948.03	2.81401
1951	2.83167
1953.96	2.76231
1956.92	2.44362
1959.88	2.73002
1962.84	3.42669
1965.8	4.64596
1968.76	3.30465
1971.72	2.51255
1974.67	4.03726
1977.63	6.24016
1980.58	6.63003
1983.54	6.65873
1986.49	8.17766
1989.44	10.0705
1992.39	11.1229
1995.33	12.1515
1998.28	11.6863
2001.23	12.3796
2004.17	12.7565
2007.12	11.1807
2010.06	9.80854
2013	11.0117
2015.94	10.6275
2018.88	9.47432
2021.82	7.71272
2024.76	9.27237
2027.69	10.0979
2030.63	10.3419
2033.56	9.53852
2036.5	9.63522
2039.43	8.25984
2042.36	7.99547
2045.29	9.3723
2048.22	9.87839
2051.15	9.62207
2054.07	10.191
2057	13.2584
2059.92	15.1339
2062.85	15.975
2065.77	15.9041
2068.69	15.3016
2071.61	15.4729
2074.53	14.3084
2077.45	12.7605
2080.37	11.9766
2083.28	10.1091
2086.2	9.81454
2089.11	9.19147
2092.02	9.21732
2094.94	8.76859
2097.85	8.82431
2100.76	7.30602
2103.66	6.62796
2106.57	6.80763
2109.48	5.49391
2112.38	4.05777
2115.29	3.61407
2118.19	3.10984
2121.09	3.9027
2123.99	5.27953
2126.89	5.25749
2129.79	5.20871
2132.69	5.45093
2135.59	4.48447
2138.48	4.90341
2141.38	5.16002
2144.27	5.38205
2147.17	5.86412
2150.06	7.28474
2152.95	6.96313
2155.84	9.56577
2158.73	11.4405
2161.61	11.6551
2164.5	12.5489
2167.38	13.2619
2170.27	13.3709
2173.15	14.761
2176.03	15.8058
2178.91	15.866
2181.8	15.4368
2184.67	14.1576
2187.55	14.0362
2190.43	15.6863
2193.3	15.7603
2196.18	14.0966
2199.05	14.0874
2201.93	13.823
2204.8	12.752
2207.67	11.4235
2210.54	10.7071
2213.41	11.2412
2216.27	10.3495
2219.14	11.7189
2222.01	12.4582
2224.87	12.6787
2227.73	13.145
2230.6	12.422
2233.46	13.2281
2236.32	14.3067
2239.18	14.5506
2242.03	15.8616
2244.89	17.5571
2247.75	17.7744
2250.6	17.396
2253.46	17.2992
2256.31	17.6713
2259.16	19.3249
2262.01	19.3957
2264.86	18.0178
2267.71	16.7113
2270.56	14.7532
2273.4	12.7134
2276.25	11.7689
2279.09	11.0941
2281.94	10.1075
2284.78	8.78255
2287.62	7.84578
2290.46	6.23065
2293.3	4.60784
2296.14	4.48156
2298.98	4.32027
2301.82	4.00518
2304.65	3.82046
2307.49	4.81254
2310.32	4.30423
2313.15	4.04779
2315.98	4.33999
2318.81	5.88664
2321.64	5.48286
2324.47	7.16847
2327.3	7.67443
2330.12	7.03799
2332.95	7.0598
2335.77	5.60783
2338.6	4.65955
2341.42	2.57652
2344.24	3.8999
2347.06	2.62001
2349.88	1.91679
2352.7	2.17204
2355.51	1.49879
2358.33	1.52697
2361.14	1.57092
2363.96	2.37676
2366.77	3.22314
2369.58	1.87577
2372.39	1.69017
2375.2	1.39408
2378.01	2.37482
2380.82	4.71542
2383.63	6.34855
2386.43	5.56422
2389.24	6.32299
2392.04	7.90976
2394.84	8.51472
2397.65	8.25545
2400.45	8.08536
2403.25	7.35302
2406.05	7.41931
2408.84	8.05947
2411.64	7.56439
2414.44	7.76263
2417.23	8.95344
2420.02	9.48871
2422.82	9.17649
2425.61	9.00198
2428.4	8.51812
2431.19	7.95604
2433.98	6.93439
2436.77	6.11863
2439.55	5.85646
2442.34	6.34129
2445.12	7.32209
2447.91	8.50289
2450.69	7.70837
2453.47	7.51635
2456.25	7.22375
2459.03	8.88296
2461.81	10.9351
2464.59	11.4843
2467.36	11.7984
2470.14	11.585
2472.92	11.1941
2475.69	10.9231
2478.46	11.1041
2481.23	9.64183
2484	8.98006
2486.77	7.74418
2489.54	7.54784
2492.31	5.87236
2495.08	4.59543
2497.84	3.75338
2500.61	3.36769
2503.37	2.61765
2506.13	2.27536
2508.9	1.2014
2511.66	2.18573
2514.42	1.15048
2517.18	0.160768
2519.93	1.59881
2522.69	0.963122
2525.45	1.88636
2528.2	2.47863
2530.95	3.57277
2533.71	3.34237
2536.46	3.96094
2539.21	3.04382
2541.96	4.88294
2544.71	6.67686
2547.46	6.90551
2550.2	7.00107
2552.95	7.72221
2555.7	8.24796
2558.44	7.99637
2561.18	8.2062
2563.93	9.58051
2566.67	10.6723
2569.41	11.8627
2572.15	11.1866
2574.88	11.2585
2577.62	11.1434
2580.36	11.3109
2583.09	10.4468
2585.83	10.3704
2588.56	8.14017
2591.29	8.00685
2594.02	7.29007
2596.75	7.99015
2599.48	7.42873
2602.21	7.81605
2604.94	8.6492
2607.67	10.4329
2610.39	10.9426
2613.12	9.42508
2615.84	8.842
2618.56	9.69386
2621.28	9.61193
2624.01	10.4966
2626.72	11.1921
2629.44	12.1902
2632.16	12.696
2634.88	12.3308
2637.59	13.2579
2640.31	11.4787
2643.02	11.3109
2645.74	11.1859
2648.45	9.84212
2651.16	9.83743
2653.87	9.3611
2656.58	8.11737
2659.29	8.55361
2661.99	10.3858
2664.7	10.4207
2667.41	10.5456
2670.11	11.5739
2672.81	10.718
2675.51	9.47492
2678.22	9.07948
2680.92	9.47191
2683.62	10.0799
2686.31	11.7364
2689.01	11.2
2691.71	11.7439
2694.4	11.9599
2697.1	12.4008
2699.79	13.9977
2702.49	15.4343
2705.18	15.9494
2707.87	17.4895
2710.56	19.5269
2713.25	20.9541
2715.94	22.3747
2718.62	23.3101
2721.31	24.6545
2723.99	25.813
2726.68	26.6134
2729.36	27.068
2732.04	25.7878
2734.73	25.3533
2737.41	22.5873
2740.08	20.5927
2742.76	19.8975
2745.44	17.7593
2748.12	15.1465
2750.79	14.4017
2753.47	11.6274
2756.14	8.91152
2758.81	7.77749
2761.49	5.65746
2764.16	3.44727
2766.83	3.12805
2769.5	2.49945
2772.16	1.77644
2774.83	2.87083
2777.5	1.40762
2780.16	2.42038
2782.83	2.28129
2785.49	2.11289
2788.15	2.36557
2790.82	1.47825
2793.48	1.06015
2796.14	0.355357
2798.79	-0.643858
2801.45	-1.24778
2804.11	-2.37892
2806.76	-2.19117
2809.42	-3.46716
2812.07	-4.47624
2814.73	-3.28338
2817.38	-0.60644
2820.03	2.93794
2822.68	7.37432
2825.33	13.5803
2827.98	19.2702
2830.63	27.3931
2833.27	37
2835.92	46.5523
2838.56	58.246
2841.21	72.2714
2843.85	88.2398
2846.49	106.525
2849.13	126.059
2851.77	147.41
2854.41	167.884
2857.05	189.649
2859.69	209.522
2862.32	227.743
2864.96	245.446
2867.59	262.618
2870.23	277.638
2872.86	289.293
2875.49	301.205
2878.12	312.099
2880.75	321.942
2883.38	329.451
2886.01	336.469
2888.63	341.825
2891.26	348.706
2893.89	353.622
2896.51	361.873
2899.13	370.933
2901.76	383.841
2904.38	399.365
2907	416.626
2909.62	436.139
2912.24	456.783
2914.85	478.435
2917.47	497.963
2920.09	515.798
2922.7	530.9
2925.32	541.201
2927.93	547.461
2930.54	550.443
2933.15	549.23
2935.76	543.578
2938.37	534.73
2940.98	521.056
2943.59	504.471
2946.2	486.823
2948.8	467.378
2951.41	446.172
2954.01	425.36
2956.62	403.497
2959.22	382.333
2961.82	362.089
2964.42	341.157
2967.02	324.618
2969.62	308.179
2972.22	291.328
2974.81	275.122
2977.41	260.4
2980	243.421
2982.6	225.913
2985.19	207.689
2987.78	190.046
2990.38	171.143
2992.97	152.756
2995.56	136.074
2998.14	119.449
3000.73	102.388
3003.32	88.2595
3005.91	73.7062
3008.49	60.3101
3011.07	49.5747
3013.66	39.7544
3016.24	30.6682
3018.82	23.6967
3021.4	16.4229
3023.98	12.3929
3026.56	8.7628
3029.14	6.64646
3031.71	5.21697
3034.29	3.5399
3036.87	4.16387
3039.44	5.23033
3042.01	6.85846
3044.59	9.10004
3047.16	11.5473
3049.73	13.3207
3052.3	14.1056
3054.87	17.064
3057.43	18.0003
3060	17.0458
3062.57	17.5073
3065.13	17.6308
3067.7	17.4976
3070.26	15.3655
3072.82	14.1944
3075.39	13.1364
3077.95	11.4157
3080.51	9.34158
3083.07	6.8453
3085.63	5.29335
3088.18	3.37345
3090.74	0.67821
3093.29	-1.06657
3095.85	-1.97605
3098.4	-2.15526
3100.95	-2.06394
3103.51	-1.75352
3106.06	-1.08456
3108.61	-0.141643
3111.16	1.38692
3113.71	2.49086
3116.25	4.34715
3118.8	7.41585
3121.35	8.80156
3123.89	12.4385
3126.44	15.267
3128.98	19.1281
3131.52	22.881
3134.06	26.4962
3136.6	31.2557
3139.14	36.7537
3141.68	40.1356
3144.22	43.4255
3146.76	45.986
3149.29	48.0148