File: data/Raman/poly_smoothed/Mb_00_13_40_1x_45s_532 nm_x100_100%_600 gr_mm_01.txt
#Acq. time (s)=	45
#Accumulations=	2
#Range (cm-¹)=	200...3150
#Windows=	2
#Auto scanning=	Off
#Autofocus=	Off
#Macrospot=	Off
#AutoExposure=	Off
#Spike filter=	Multiple accum.
#Delay time (s)=	0
#Binning=	1
#Readout mode=	Signal
#DeNoise=	Off
#ICS correction=	On
#Dark correction=	Off
#Inst. Process=	Off
#Detector Gain=	Best Dynamic Range
#Detector ADC=	20 kHz
#Detector temperature (°C)=	-69.62
#Instrument=	LabRAM HR Evol
#Detector=	Synapse
#Objective=	x100
#Grating=	600 gr/mm
#ND Filter=	100%
#Laser (nm)=	532
#Hole=	100.021
#Range=	Auto
#Laser Pol.=	No
#Raman. Pol.=	No
#Laser Pol. (°)=	-0.0007625
#Raman Pol. (°)=	89.9995
#Collection=	Microscope
#StageXY=	Marzhauser
#StageZ=	Marzhauser
#X (µm)=	-1026.6
#Y (µm)=	-2874.1
#Z (µm)=	528.85
#Full time(mm:ss)=	3:18
#Project=
#Sample=
#Site=
#Title=	Mb_00_13_40_2x_45s_532 nm_x100_100%_600 gr_mm
#Remark=
#Date=	06.07.2022 12:56
#Acquired=	06.07.2022 12:56:45
#Base:Fit=	10.08.2022 10:16:56
#Base:Sub=	10.08.2022 10:17:24
#Filter:Polynom=	16.08.2022 10:36:38
#AxisType[0]=Intens
#AxisUnit[0]=Cnt
#AxisType[1]=Spectr
#AxisUnit[1]=1/cm
200.398	20.1934
204.027	7.83251
207.657	-2.48782
211.283	-8.28858
214.909	-7.47229
218.533	4.35419
222.157	24.7097
225.777	48.649
229.396	74.6309
233.016	100.145
236.632	119.829
240.247	138.313
243.86	154.524
247.474	168.517
251.085	182.151
254.694	193.328
258.301	199.045
261.908	202.603
265.513	203.754
269.116	200.023
272.718	195.102
276.319	186.709
279.918	171.552
283.516	153.211
287.113	135.136
290.708	116.385
294.302	102.195
297.894	88.2088
301.485	77.609
305.073	71.985
308.661	67.2782
312.247	59.489
315.833	55.3167
319.415	50.2127
322.997	46.0473
326.579	40.4703
330.156	37.4925
333.735	33.9174
337.31	29.8176
340.885	26.7286
344.458	23.503
348.03	24.1811
351.6	22.5385
355.17	24.045
358.737	26.0912
362.304	33.0006
365.868	42.8423
369.431	51.1374
372.994	60.3442
376.554	71.8594
380.112	85.667
383.669	105.093
387.225	128.732
390.781	149.727
394.334	169.379
397.885	183.366
401.436	196.749
404.984	206.205
408.532	212.228
412.078	216.557
415.623	215.443
419.166	213.599
422.708	206.405
426.248	194.95
429.788	180.717
433.326	165.829
436.86	147.599
440.395	128.251
443.929	111.598
447.461	96.875
450.99	82.3897
454.52	70.5742
458.048	58.5371
461.573	51.6197
465.099	48.1127
468.623	52.2798
472.144	57.0126
475.666	61.0828
479.184	62.6813
482.703	64.9852
486.218	65.3326
489.734	68.1421
493.247	71.4809
496.759	75.5525
500.271	78.3951
503.779	79.8398
507.287	82.4094
510.795	84.8101
514.299	85.572
517.803	89.247
521.305	89.8138
524.805	92.4669
528.307	93.2357
531.805	95.7544
535.301	96.0731
538.797	94.1208
542.291	93.9172
545.783	91.94
549.275	86.7174
552.765	85.7039
556.253	83.4592
559.738	80.4975
563.224	76.6832
566.709	74.908
570.192	71.8807
573.674	67.0295
577.153	67.6016
580.632	63.856
584.11	59.8473
587.587	57.0907
591.06	54.2381
594.534	51.38
598.005	49.1323
601.476	48.9488
604.944	49.8797
608.413	50.6885
611.878	47.4907
615.344	44.3547
618.807	44.0468
622.27	40.94
625.73	41.0247
629.189	41.8186
632.648	41.3768
636.105	43.5256
639.559	46.18
643.013	46.893
646.467	49.1341
649.918	51.1603
653.368	48.7058
656.816	48.0723
660.263	45.7419
663.708	42.2587
667.153	38.6368
670.596	34.9745
674.037	31.5181
677.478	29.611
680.917	26.9826
684.355	26.6544
687.791	23.665
691.224	21.2592
694.658	19.5886
698.091	15.0976
701.522	13.1857
704.95	14.0138
708.379	13.9095
711.806	14.3175
715.23	15.6263
718.655	17.5126
722.078	17.8392
725.498	17.9706
728.919	17.0852
732.337	16.4452
735.755	12.9794
739.17	10.6636
742.584	10.6942
745.998	10.815
749.409	12.8402
752.819	13.8376
756.23	14.7922
759.637	19.2125
763.043	18.8995
766.448	21.5471
769.853	21.7688
773.255	22.0352
776.656	25.2211
780.056	25.3406
783.454	25.6916
786.851	27.8945
790.247	29.7782
793.641	29.8565
797.034	32.3036
800.426	33.5685
803.817	31.3439
807.206	31.2598
810.592	35.5435
813.979	35.4538
817.364	35.217
820.748	40.1899
824.129	39.7099
827.511	43.8777
830.891	42.3572
834.269	44.3633
837.646	43.9033
841.023	43.1588
844.396	40.799
847.77	38.1773
851.141	32.4418
854.513	30.17
857.881	27.7468
861.248	22.5661
864.616	17.4629
867.98	13.6299
871.343	11.1721
874.707	8.6377
878.068	7.36136
881.428	4.2118
884.786	1.13191
888.143	0.163911
891.498	1.48455
894.855	1.92451
898.208	2.18894
901.56	2.64682
904.91	2.52175
908.26	1.32255
911.608	4.75847
914.955	6.25634
918.298	10.343
921.643	12.1988
924.986	12.8455
928.328	13.0135
931.668	15.8861
935.006	16.7724
938.344	20.2444
941.681	20.3881
945.014	24.3495
948.349	25.0018
951.682	27.2208
955.012	25.2918
958.343	23.2183
961.67	25.1376
964.998	26.4073
968.323	31.4441
971.649	38.3637
974.971	46.8679
978.293	57.7035
981.615	66.1976
984.933	73.7069
988.251	80.7783
991.567	88.2138
994.884	96.5555
998.198	100.074
1001.51	101.829
1004.82	99.2883
1008.13	95.8499
1011.44	92.5402
1014.75	92.6111
1018.06	97.6005
1021.36	107.839
1024.66	119.562
1027.97	131.859
1031.27	139.701
1034.57	146.266
1037.87	153.31
1041.16	157.21
1044.46	163.723
1047.76	167.383
1051.05	170.1
1054.34	169.251
1057.63	168.679
1060.92	161.108
1064.21	152.602
1067.5	141.858
1070.78	126.596
1074.07	108.291
1077.35	89.4677
1080.63	67.2802
1083.91	43.0459
1087.19	24.6326
1090.47	11.8083
1093.75	5.78951
1097.03	10.7427
1100.3	17.7104
1103.57	26.4638
1106.84	29.4522
1110.11	31.9402
1113.38	34.6665
1116.65	36.5663
1119.92	37.915
1123.19	37.9689
1126.45	37.3427
1129.71	35.6115
1132.97	34.0282
1136.23	32.0831
1139.49	31.2699
1142.75	29.5523
1146.01	29.0341
1149.26	25.3199
1152.52	21.0419
1155.77	15.5282
1159.02	11.7458
1162.27	6.89463
1165.52	5.22657
1168.77	5.78315
1172.02	10.8427
1175.26	14.4598
1178.51	18.7952
1181.75	23.5266
1184.99	24.7659
1188.23	27.6696
1191.47	32.9355
1194.71	37.9167
1197.94	45.3022
1201.18	50.1682
1204.41	58.2285
1207.65	66.1817
1210.88	72.6421
1214.11	80.4611
1217.34	90.6956
1220.57	99.1899
1223.79	106.412
1227.02	110.711
1230.24	118.663
1233.47	121.197
1236.69	122.309
1239.91	126.423
1243.13	127.864
1246.34	132.575
1249.56	131.651
1252.78	132.202
1255.99	131.261
1259.2	130.998
1262.42	132.477
1265.63	132.454
1268.84	136.858
1272.04	139.818
1275.25	143.551
1278.46	146.805
1281.66	149.644
1284.86	155.026
1288.07	159.553
1291.27	163.273
1294.47	171.436
1297.66	174.731
1300.86	181.284
1304.06	185.293
1307.25	189.218
1310.44	194.581
1313.64	195.36
1316.83	199.889
1320.02	202.352
1323.2	202.511
1326.39	200.396
1329.58	196.514
1332.76	197.454
1335.95	198.296
1339.13	199.4
1342.31	198.247
1345.49	195.484
1348.67	190.481
1351.85	184.792
1355.02	180.008
1358.2	175.177
1361.37	170.005
1364.54	165.844
1367.71	161.353
1370.88	155.446
1374.05	149.845
1377.22	142.589
1380.39	140.815
1383.55	137.994
1386.72	137.604
1389.88	135.095
1393.04	131.565
1396.2	127.798
1399.36	125.957
1402.52	127.161
1405.68	130.464
1408.83	144.381
1411.98	157.202
1415.14	171.603
1418.29	188.641
1421.44	203.864
1424.59	220.512
1427.74	241.036
1430.89	261.6
1434.03	280.73
1437.18	296.661
1440.32	306.899
1443.46	314.885
1446.6	318.62
1449.74	319.165
1452.88	315.93
1456.02	309.499
1459.16	299.184
1462.29	283.822
1465.43	263.57
1468.56	243.74
1471.69	221.55
1474.82	200.294
1477.95	182.397
1481.08	164.41
1484.2	149.785
1487.33	134.611
1490.46	118.936
1493.58	107.453
1496.7	98.6361
1499.82	91.5041
1502.94	86.2144
1506.06	87.0823
1509.18	87.0955
1512.29	87.5596
1515.41	89.8064
1518.52	91.7876
1521.63	98.0171
1524.75	102.185
1527.85	108.015
1530.96	109.545
1534.07	112.1
1537.18	117.627
1540.28	119.266
1543.39	124.732
1546.49	127.303
1549.59	127.13
1552.69	131.17
1555.79	132.081
1558.89	131.272
1561.99	128.705
1565.08	128.997
1568.18	129.32
1571.27	131.281
1574.37	134.687
1577.46	137.893
1580.55	146.02
1583.64	154.48
1586.73	162.325
1589.81	167.765
1592.9	172.236
1595.98	179.314
1599.06	183.134
1602.15	182.671
1605.23	182.235
1608.31	180.241
1611.39	177.44
1614.46	176.026
1617.54	173.644
1620.61	174.428
1623.69	171.275
1626.76	169.19
1629.83	168.154
1632.9	164.151
1635.97	161.274
1639.04	160.551
1642.11	162.516
1645.17	163.934
1648.24	165.104
1651.3	167.186
1654.36	169.548
1657.42	172.557
1660.48	171.952
1663.54	171.694
1666.6	165.78
1669.66	161.229
1672.71	154.91
1675.77	145.513
1678.82	137.291
1681.87	126.692
1684.92	118.945
1687.97	110.247
1691.02	101.208
1694.07	92.6419
1697.11	82.762
1700.16	71.6956
1703.2	62.6884
1706.25	55.6458
1709.29	47.4498
1712.33	42.2513
1715.37	39.1184
1718.41	35.3179
1721.44	31.3932
1724.48	28.9098
1727.51	28.3309
1730.55	27.275
1733.58	24.6701
1736.61	22.9611
1739.64	19.0104
1742.67	15.5028
1745.7	13.9646
1748.72	12.4663
1751.75	10.5569
1754.77	9.88497
1757.8	8.86983
1760.82	7.14632
1763.84	4.59927
1766.86	2.7287
1769.88	-0.965294
1772.9	-2.17875
1775.91	-1.66245
1778.93	-0.698549
1781.94	-0.74255
1784.96	-0.434202
1787.97	0.246849
1790.98	0.301007
1793.99	0.796448
1797	2.40598
1800.01	2.55295
1803.01	3.15572
1806.02	2.80673
1809.02	1.34447
1812.02	1.77627
1815.02	2.58502
1818.03	2.15382
1821.02	1.66491
1824.02	1.49607
1827.02	1.91518
1830.02	3.21956
1833.01	1.83692
1836.01	2.0881
1839	1.44736
1841.99	2.78241
1844.98	3.90168
1847.97	5.38232
1850.96	6.68389
1853.95	7.68499
1856.93	8.23901
1859.92	7.56271
1862.9	7.27642
1865.88	8.21434
1868.87	8.21163
1871.85	7.83464
1874.83	8.20506
1877.81	7.79704
1880.78	7.45303
1882.53	9.26311
1885.52	10.1794
1888.51	10.9818
1891.5	9.51508
1894.48	10.2806
1897.47	10.4587
1900.45	9.65609
1903.43	9.42852
1906.41	9.43648
1909.39	9.84627
1912.37	11.4312
1915.35	13.3297
1918.33	12.1149
1921.3	12.5267
1924.28	12.2356
1927.25	13.0785
1930.22	12.5043
1933.19	12.5286
1936.16	12.6958
1939.13	12.2186
1942.1	12.053
1945.07	11.5633
1948.03	11.6477
1951	11.2724
1953.96	10.5109
1956.92	13.3371
1959.88	12.8682
1962.84	13.3735
1965.8	12.5212
1968.76	12.7055
1971.72	11.3277
1974.67	10.7661
1977.63	10.4413
1980.58	11.359
1983.54	11.325
1986.49	11.1901
1989.44	10.6995
1992.39	8.65372
1995.33	8.32714
1998.28	6.72257
2001.23	7.18138
2004.17	7.63428
2007.12	7.24757
2010.06	5.48785
2013	2.50115
2015.94	1.93713
2018.88	2.76017
2021.82	3.81331
2024.76	3.61808
2027.69	5.85743
2030.63	8.73305
2033.56	10.7975
2036.5	12.3885
2039.43	14.4105
2042.36	14.413
2045.29	14.7803
2048.22	16.7067
2051.15	18.2113
2054.07	20.9511
2057	23.8082
2059.92	23.853
2062.85	24.0964
2065.77	25.039
2068.69	23.6808
2071.61	24.8797
2074.53	24.3152
2077.45	23.9356
2080.37	20.7737
2083.28	19.1948
2086.2	17.7177
2089.11	16.2761
2092.02	16.2978
2094.94	15.6696
2097.85	14.8159
2100.76	16.2136
2103.66	16.5702
2106.57	15.7308
2109.48	14.263
2112.38	13.7385
2115.29	12.1632
2118.19	12.4835
2121.09	12.6345
2123.99	13.6522
2126.89	13.3482
2129.79	12.7491
2132.69	12.1501
2135.59	12.1236
2138.48	12.3919
2141.38	12.2763
2144.27	12.91
2147.17	13.7127
2150.06	14.3724
2152.95	14.6993
2155.84	17.7338
2158.73	17.6498
2161.61	18.8376
2164.5	21.4818
2167.38	23.2516
2170.27	24.5819
2173.15	24.3232
2176.03	23.9839
2178.91	22.7627
2181.8	22.5558
2184.67	21.4877
2187.55	21.5581
2190.43	22.5626
2193.3	21.231
2196.18	21.1525
2199.05	21.0043
2201.93	21.7175
2204.8	22.1073
2207.67	21.3
2210.54	21.0139
2213.41	22.3317
2216.27	22.7275
2219.14	26.9391
2222.01	29.1309
2224.87	29.6101
2227.73	28.9791
2230.6	30.1353
2233.46	29.8495
2236.32	29.3011
2239.18	27.1005
2242.03	23.191
2244.89	19.8413
2247.75	19.9627
2250.6	19.358
2253.46	20.236
2256.31	19.3285
2259.16	18.9766
2262.01	18.3233
2264.86	17.0568
2267.71	16.5768
2270.56	16.7654
2273.4	17.2385
2276.25	17.3811
2279.09	16.3215
2281.94	18.4039
2284.78	21.6684
2287.62	23.0204
2290.46	24.1592
2293.3	24.2472
2296.14	23.685
2298.98	24.8198
2301.82	24.3096
2304.65	24.8201
2307.49	24.3078
2310.32	23.5746
2313.15	22.9625
2315.98	25.395
2318.81	26.5625
2321.64	24.5912
2324.47	24.1149
2327.3	21.4211
2330.12	20.0834
2332.95	18.4044
2335.77	17.1065
2338.6	16.0284
2341.42	12.4995
2344.24	11.1477
2347.06	8.62106
2349.88	6.60242
2352.7	4.78776
2355.51	3.50151
2358.33	1.85635
2361.14	1.4062
2363.96	2.16145
2366.77	1.67402
2369.58	3.37668
2372.39	3.94678
2375.2	4.96044
2378.01	4.08523
2380.82	4.67528
2383.63	6.19125
2386.43	7.11573
2389.24	5.55024
2392.04	6.12029
2394.84	5.54948
2397.65	3.64702
2400.45	4.85076
2403.25	3.53251
2406.05	2.76408
2408.84	0.822995
2411.64	0.794518
2414.44	0.724144
2417.23	1.69494
2420.02	1.7488
2422.82	2.48276
2425.61	4.44876
2428.4	4.88027
2431.19	5.05378
2433.98	5.47021
2436.77	6.68077
2439.55	8.90168
2442.34	7.27293
2445.12	7.69744
2447.91	8.17183
2450.69	8.07911
2453.47	6.51732
2456.25	5.46479
2459.03	4.78697
2461.81	3.97071
2464.59	2.94982
2467.36	4.27649
2470.14	4.63246
2472.92	5.66375
2475.69	5.0509
2478.46	3.67423
2481.23	5.98979
2484	5.9456
2486.77	6.23452
2489.54	3.39775
2492.31	5.32983
2495.08	4.7337
2497.84	3.06602
2500.61	2.04777
2503.37	2.47279
2506.13	1.25829
2508.9	0.500881
2511.66	0.353128
2514.42	-0.722222
2517.18	0.479903
2519.93	-0.465987
2522.69	0.257468
2525.45	0.538205
2528.2	2.0168
2530.95	3.66097
2533.71	5.90549
2536.46	7.11959
2539.21	9.0963
2541.96	10.2782
2544.71	11.6309
2547.46	13.9776
2550.2	15.4849
2552.95	15.6537
2555.7	14.8449
2558.44	14.7129
2561.18	12.982
2563.93	12.4628
2566.67	10.6766
2569.41	11.0835
2572.15	9.35717
2574.88	9.53591
2577.62	11.3175
2580.36	11.695
2583.09	11.7601
2585.83	11.0172
2588.56	12.3961
2591.29	11.6085
2594.02	11.3821
2596.75	12.188
2599.48	12.5521
2602.21	13.9844
2604.94	16.2729
2607.67	16.217
2610.39	17.4308
2613.12	17.243
2615.84	16.6002
2618.56	16.3908
2621.28	14.6294
2624.01	13.9323
2626.72	12.9535
2629.44	15.1167
2632.16	13.8364
2634.88	13.2859
2637.59	14.3146
2640.31	14.3548
2643.02	15.4109
2645.74	16.4883
2648.45	14.9242
2651.16	14.729
2653.87	14.7684
2656.58	14.8385
2659.29	14.4871
2661.99	15.532
2664.7	17.0115
2667.41	17.1323
2670.11	18.4125
2672.81	16.1936
2675.51	16.0888
2678.22	15.3182
2680.92	15.8474
2683.62	15.7116
2686.31	16.9864
2689.01	16.3488
2691.71	18.8271
2694.4	21.8788
2697.1	23.5045
2699.79	26.4064
2702.49	29.5005
2705.18	33.0877
2707.87	35.6475
2710.56	38.5393
2713.25	41.2323
2715.94	43.176
2718.62	45.9095
2721.31	45.7984
2723.99	46.3275
2726.68	46.8648
2729.36	46.4416
2732.04	44.7941
2734.73	42.8186
2737.41	39.6859
2740.08	36.7964
2742.76	35.1181
2745.44	33.1585
2748.12	30.6529
2750.79	26.7056
2753.47	24.3835
2756.14	22.4808
2758.81	21.3683
2761.49	18.8202
2764.16	17.552
2766.83	16.3041
2769.5	15.9513
2772.16	14.1206
2774.83	12.9795
2777.5	9.69302
2780.16	9.46552
2782.83	7.64451
2785.49	6.33472
2788.15	6.25344
2790.82	6.13645
2793.48	5.40772
2796.14	4.72057
2798.79	5.20847
2801.45	5.1958
2804.11	3.52591
2806.76	0.317842
2809.42	-2.30966
2812.07	-2.24345
2814.73	3.77958
2817.38	15.2615
2820.03	30.9229
2822.68	50.6507
2825.33	73.98
2827.98	98.1209
2830.63	125.948
2833.27	153.655
2835.92	179.816
2838.56	205.039
2841.21	231.946
2843.85	260.209
2846.49	290.194
2849.13	322.674
2851.77	360.314
2854.41	398.771
2857.05	432.027
2859.69	462.216
2862.32	487.188
2864.96	508.168
2867.59	523.799
2870.23	535.65
2872.86	544.301
2875.49	556.42
2878.12	566.273
2880.75	574.546
2883.38	581.29
2886.01	585.091
2888.63	587.341
2891.26	586.316
2893.89	583.704
2896.51	579.492
2899.13	575.689
2901.76	571.42
2904.38	573.523
2907	580.212
2909.62	591.862
2912.24	608.439
2914.85	627.341
2917.47	645.464
2920.09	654.984
2922.7	659.723
2925.32	663.41
2927.93	661.931
2930.54	658.111
2933.15	650.855
2935.76	636.891
2938.37	621.485
2940.98	602.711
2943.59	578.238
2946.2	556.644
2948.8	530.146
2951.41	502.62
2954.01	476.395
2956.62	447.582
2959.22	422.086
2961.82	395.998
2964.42	373.871
2967.02	353.046
2969.62	334.05
2972.22	315.029
2974.81	296.596
2977.41	276.111
2980	255.881
2982.6	233.851
2985.19	210.548
2987.78	189.854
2990.38	168.616
2992.97	148.629
2995.56	130.428
2998.14	112.125
3000.73	95.9433
3003.32	80.1553
3005.91	66.069
3008.49	54.3037
3011.07	44.6629
3013.66	35.056
3016.24	28.199
3018.82	20.9555
3021.4	15.2721
3023.98	10.907
3026.56	6.39306
3029.14	3.11147
3031.71	1.36949
3034.29	-0.353905
3036.87	-0.906008
3039.44	0.32167
3042.01	1.21586
3044.59	2.5588
3047.16	3.81703
3049.73	5.17856
3052.3	7.19039
3054.87	8.82078
3057.43	11.1929
3060	11.4392
3062.57	12.3367
3065.13	13.0459
3067.7	12.1656
3070.26	13.0865
3072.82	11.8281
3075.39	10.4174
3077.95	9.85046
3080.51	8.01832
3083.07	6.18511
3085.63	5.31832
3088.18	3.00381
3090.74	2.34811
3093.29	3.51783
3095.85	4.34273
3098.4	4.28294
3100.95	6.29785
3103.51	7.50398
3106.06	9.65279
3108.61	12.4921
3111.16	14.3207
3113.71	18.2921
3116.25	22.9125
3118.8	26.3584
3121.35	29.6816
3123.89	34.2039
3126.44	38.6053
3128.98	42.7957
3131.52	46.356
3134.06	50.4408
3136.6	55.0709
3139.14	61.3344
3141.68	65.6165
3144.22	69.2509
3146.76	71.9456
3149.29	73.3622