File: data/Raman/poly_smoothed/Mb_00_13_21_1x_45s_532 nm_x100_100%_600 gr_mm_01.txt
#Acq. time (s)=	45
#Accumulations=	2
#Range (cm-¹)=	200...3150
#Windows=	2
#Auto scanning=	Off
#Autofocus=	Off
#Macrospot=	Off
#AutoExposure=	Off
#Spike filter=	Multiple accum.
#Delay time (s)=	0
#Binning=	1
#Readout mode=	Signal
#DeNoise=	Off
#ICS correction=	On
#Dark correction=	Off
#Inst. Process=	Off
#Detector Gain=	Best Dynamic Range
#Detector ADC=	20 kHz
#Detector temperature (°C)=	-69.85
#Instrument=	LabRAM HR Evol
#Detector=	Synapse
#Objective=	x100
#Grating=	600 gr/mm
#ND Filter=	100%
#Laser (nm)=	532
#Hole=	100.021
#Range=	Auto
#Laser Pol.=	No
#Raman. Pol.=	No
#Laser Pol. (°)=	-0.0007625
#Raman Pol. (°)=	89.9995
#Collection=	Microscope
#StageXY=	Marzhauser
#StageZ=	Marzhauser
#X (µm)=	-954.8
#Y (µm)=	-2840.6
#Z (µm)=	528.2
#Full time(mm:ss)=	3:18
#Project=
#Sample=
#Site=
#Title=	Mb_00_13_21_2x_45s_532 nm_x100_100%_600 gr_mm
#Remark=
#Date=	06.07.2022 11:20
#Acquired=	06.07.2022 11:20:44
#Base:Fit=	10.08.2022 10:16:56
#Base:Sub=	10.08.2022 10:17:24
#Filter:Polynom=	16.08.2022 10:36:38
#AxisType[0]=Intens
#AxisUnit[0]=Cnt
#AxisType[1]=Spectr
#AxisUnit[1]=1/cm
200.398	11.589
204.027	9.18037
207.657	0.691418
211.283	-6.19993
214.909	-5.9746
218.533	1.15845
222.157	13.9352
225.777	27.1466
229.396	45.0567
233.016	60.6422
236.632	79.4936
240.247	93.7234
243.86	106.769
247.474	116.539
251.085	125.994
254.694	135.502
258.301	143.28
261.908	148.662
265.513	148.303
269.116	146.095
272.718	138.427
276.319	128.555
279.918	119.221
283.516	106.597
287.113	91.9896
290.708	75.0695
294.302	60.7859
297.894	49.2629
301.485	40.9504
305.073	33.3797
308.661	26.8551
312.247	22.236
315.833	18.5208
319.415	16.8606
322.997	15.6288
326.579	14.826
330.156	12.3354
333.735	9.48266
337.31	6.25969
340.885	3.994
344.458	4.18171
348.03	3.95972
351.6	1.3798
355.17	1.23831
358.737	1.86924
362.304	4.99396
365.868	11.7932
369.431	19.7865
372.994	27.8597
376.554	35.7181
380.112	47.1257
383.669	60.3464
387.225	78.56
390.781	95.7799
394.334	111.41
397.885	127.401
401.436	136.575
404.984	144.486
408.532	150.279
412.078	152.28
415.623	152.566
419.166	149.059
422.708	142.108
426.248	131.609
429.788	120.8
433.326	106.245
436.86	90.5343
440.395	72.921
443.929	57.2243
447.461	43.1731
450.99	30.7149
454.52	20.3703
458.048	10.9518
461.573	2.96974
465.099	-0.502593
468.623	0.60369
472.144	3.24358
475.666	7.35148
479.184	8.67734
482.703	11.8828
486.218	15.1462
489.734	19.7296
493.247	27.3054
496.759	35.8226
500.271	41.1589
503.779	46.548
507.287	52.72
510.795	57.975
514.299	62.6571
517.803	65.5908
521.305	67.5765
524.805	68.6407
528.307	69.2143
531.805	70.9542
535.301	70.2455
538.797	68.1958
542.291	64.0009
545.783	58.4909
549.275	52.4546
552.765	46.7306
556.253	41.3373
559.738	36.0204
563.224	29.7109
566.709	26.0673
570.192	20.8222
573.674	16.7046
577.153	13.8599
580.632	10.6944
584.11	7.94022
587.587	5.73366
591.06	5.05825
594.534	3.99428
598.005	2.77825
601.476	3.0351
604.944	4.00361
608.413	4.13349
611.878	4.68462
615.344	5.69649
618.807	6.0567
622.27	7.06515
625.73	11.3459
629.189	15.1742
632.648	16.6945
636.105	20.2265
639.559	24.3574
643.013	26.7351
646.467	30.7507
649.918	32.3897
653.368	33.6753
656.816	33.0989
660.263	34.4867
663.708	32.246
667.153	29.1966
670.596	28.1951
674.037	25.4016
677.478	24.2542
680.917	21.0246
684.355	18.7988
687.791	16.8624
691.224	12.8026
694.658	9.46465
698.091	8.02693
701.522	6.51559
704.95	4.1549
708.379	5.52354
711.806	6.39158
715.23	6.59467
718.655	10.8233
722.078	11.4982
725.498	11.492
728.919	13.8283
732.337	16.0251
735.755	17.5242
739.17	18.0696
742.584	19.7375
745.998	21.9131
749.409	24.0238
752.819	28.2045
756.23	33.4635
759.637	36.0936
763.043	38.6715
766.448	39.1114
769.853	41.9054
773.255	42.5433
776.656	44.355
780.056	47.3242
783.454	48.1191
786.851	49.4808
790.247	52.5871
793.641	54.7656
797.034	55.4169
800.426	57.5379
803.817	55.5384
807.206	53.7524
810.592	52.1469
813.979	51.5704
817.364	51.6948
820.748	50.7357
824.129	51.1487
827.511	51.0713
830.891	52.9993
834.269	51.8323
837.646	48.7439
841.023	45.7822
844.396	42.4986
847.77	37.5728
851.141	33.2677
854.513	31.4483
857.881	29.3258
861.248	26.5559
864.616	23.4277
867.98	21.5412
871.343	20.9258
874.707	19.1049
878.068	16.5616
881.428	12.7587
884.786	12.0221
888.143	8.96286
891.498	7.84214
894.855	5.50083
898.208	5.79198
901.56	8.02907
904.91	9.44024
908.26	9.09409
911.608	8.84928
914.955	10.0493
918.298	10.0181
921.643	11.8528
924.986	12.2173
928.328	12.5429
931.668	12.1648
935.006	12.7808
938.344	13.379
941.681	13.5944
945.014	11.9096
948.349	11.6154
951.682	16.0135
955.012	16.2812
958.343	12.891
961.67	14.775
964.998	19.8926
968.323	25.2001
971.649	31.8928
974.971	36.1595
978.293	43.4158
981.615	50.7785
984.933	55.8276
988.251	56.2894
991.567	60.838
994.884	65.5992
998.198	70.7458
1001.51	73.0831
1004.82	71.7248
1008.13	70.433
1011.44	68.1831
1014.75	68.1478
1018.06	74.2852
1021.36	82.873
1024.66	94.2572
1027.97	108.611
1031.27	120.719
1034.57	131.512
1037.87	138.726
1041.16	147.707
1044.46	158.06
1047.76	162.497
1051.05	163.757
1054.34	163.997
1057.63	160.04
1060.92	155.993
1064.21	149.145
1067.5	136.573
1070.78	125.062
1074.07	113.028
1077.35	96.8117
1080.63	78.2783
1083.91	60.4729
1087.19	43.7585
1090.47	30.6736
1093.75	23.5271
1097.03	22.3881
1100.3	23.2314
1103.57	23.5745
1106.84	24.3576
1110.11	22.7144
1113.38	19.5222
1116.65	16.6148
1119.92	13.4408
1123.19	10.7339
1126.45	8.47299
1129.71	7.54853
1132.97	5.45632
1136.23	3.98797
1139.49	4.77468
1142.75	5.43804
1146.01	4.85283
1149.26	4.15431
1152.52	2.85472
1155.77	1.61533
1159.02	0.0201316
1162.27	-0.278477
1165.52	-0.376851
1168.77	3.59922
1172.02	6.47417
1175.26	10.3648
1178.51	12.7918
1181.75	17.3262
1184.99	20.8328
1188.23	27.5937
1191.47	32.4348
1194.71	40.3815
1197.94	47.5214
1201.18	56.0658
1204.41	66.7758
1207.65	76.9319
1210.88	85.7859
1214.11	95.0321
1217.34	103.681
1220.57	112.905
1223.79	118.688
1227.02	125.463
1230.24	128.408
1233.47	132.887
1236.69	137.12
1239.91	139.135
1243.13	141.701
1246.34	144.171
1249.56	143.85
1252.78	141.471
1255.99	138.148
1259.2	135.29
1262.42	133.935
1265.63	132.494
1268.84	131.98
1272.04	130.962
1275.25	132.888
1278.46	133.452
1281.66	136.448
1284.86	141.247
1288.07	142.447
1291.27	144.399
1294.47	148.111
1297.66	150.607
1300.86	154.469
1304.06	159.281
1307.25	164.551
1310.44	170.844
1313.64	176.74
1316.83	181.976
1320.02	186.209
1323.2	189.021
1326.39	188.635
1329.58	189.644
1332.76	186.205
1335.95	183.753
1339.13	182.569
1342.31	179.887
1345.49	176.474
1348.67	171.698
1351.85	169.218
1355.02	164.669
1358.2	158.8
1361.37	151.934
1364.54	146.457
1367.71	141.34
1370.88	134.67
1374.05	128.544
1377.22	125.571
1380.39	122.544
1383.55	120.921
1386.72	120.452
1389.88	120.085
1393.04	116.582
1396.2	114.883
1399.36	113.332
1402.52	114.048
1405.68	117.37
1408.83	120.608
1411.98	128.012
1415.14	138.447
1418.29	150.986
1421.44	163.268
1424.59	176.52
1427.74	191.401
1430.89	203.824
1434.03	215.591
1437.18	225.68
1440.32	232.853
1443.46	236.822
1446.6	237.813
1449.74	237.602
1452.88	236.903
1456.02	232.933
1459.16	226.392
1462.29	217.321
1465.43	204.632
1468.56	189.134
1471.69	174.049
1474.82	159.418
1477.95	146.413
1481.08	133.476
1484.2	123.615
1487.33	114.317
1490.46	107.029
1493.58	98.8574
1496.7	93.8252
1499.82	89.1571
1502.94	85.8752
1506.06	83.4979
1509.18	80.8024
1512.29	79.2881
1515.41	74.5816
1518.52	72.0766
1521.63	73.1306
1524.75	73.0578
1527.85	73.6324
1530.96	75.4942
1534.07	77.321
1537.18	78.9102
1540.28	81.7898
1543.39	83.9646
1546.49	87.4009
1549.59	93.131
1552.69	97.8322
1555.79	101.294
1558.89	106.026
1561.99	110.732
1565.08	111.677
1568.18	116.687
1571.27	119.6
1574.37	127.354
1577.46	133.406
1580.55	139.698
1583.64	145.542
1586.73	149.846
1589.81	153.825
1592.9	157.561
1595.98	160.319
1599.06	161.632
1602.15	162.233
1605.23	163.15
1608.31	161.889
1611.39	161.127
1614.46	160.798
1617.54	160.487
1620.61	160.679
1623.69	163.75
1626.76	165.75
1629.83	165.289
1632.9	167.83
1635.97	168.84
1639.04	171.352
1642.11	176.434
1645.17	183.783
1648.24	188.471
1651.3	193.458
1654.36	195.84
1657.42	195.211
1660.48	192.166
1663.54	189.243
1666.6	184.066
1669.66	175.037
1672.71	165.775
1675.77	155.533
1678.82	141.77
1681.87	128.867
1684.92	116.175
1687.97	102.988
1691.02	89.6278
1694.07	76.2305
1697.11	67.0455
1700.16	56.6173
1703.2	46.3759
1706.25	39.2495
1709.29	33.6106
1712.33	29.6571
1715.37	26.8061
1718.41	23.5886
1721.44	20.9852
1724.48	20.603
1727.51	18.7552
1730.55	16.9783
1733.58	14.5847
1736.61	14.4463
1739.64	14.9512
1742.67	13.8278
1745.7	11.5774
1748.72	11.2533
1751.75	10.5328
1754.77	11.1789
1757.8	10.1883
1760.82	10.6569
1763.84	9.36131
1766.86	8.16887
1769.88	7.11724
1772.9	7.52457
1775.91	6.11016
1778.93	5.72323
1781.94	4.90571
1784.96	4.86944
1787.97	4.34234
1790.98	3.29642
1793.99	2.5621
1797	2.64842
1800.01	1.98442
1803.01	-0.388987
1806.02	-1.76536
1809.02	-1.51666
1812.02	-1.13798
1815.02	-1.76052
1818.03	-2.145
1821.02	-0.470999
1824.02	1.10361
1827.02	2.59228
1830.02	1.68893
1833.01	4.2836
1836.01	6.4936
1839	6.95875
1841.99	8.29053
1844.98	10.1725
1847.97	10.7583
1850.96	10.9554
1853.95	12.1223
1856.93	12.9088
1859.92	12.9039
1862.9	11.7982
1865.88	10.3329
1868.87	9.09445
1871.85	8.56279
1874.83	8.51786
1877.81	8.64913
1880.78	9.04164
1882.53	8.48018
1885.52	8.36755
1888.51	7.95333
1891.5	7.47651
1894.48	7.64501
1897.47	8.40266
1900.45	6.99193
1903.43	8.75986
1906.41	10.5749
1909.39	10.3507
1912.37	8.98112
1915.35	10.762
1918.33	10.4028
1921.3	10.0845
1924.28	10.1766
1927.25	10.1938
1930.22	9.31495
1933.19	8.26502
1936.16	9.43381
1939.13	8.95507
1942.1	10.7441
1945.07	12.0112
1948.03	11.8197
1951	12.1086
1953.96	9.92701
1956.92	9.21634
1959.88	9.6264
1962.84	9.63934
1965.8	8.57553
1968.76	9.03978
1971.72	7.31179
1974.67	7.12662
1977.63	5.91756
1980.58	6.23147
1983.54	6.73123
1986.49	7.27239
1989.44	6.64406
1992.39	7.22674
1995.33	7.93029
1998.28	5.32604
2001.23	5.19876
2004.17	5.74203
2007.12	5.21356
2010.06	6.70565
2013	6.92116
2015.94	6.22086
2018.88	5.87075
2021.82	5.75171
2024.76	4.78347
2027.69	4.8035
2030.63	7.37236
2033.56	8.01507
2036.5	6.42836
2039.43	6.15342
2042.36	4.5713
2045.29	4.08439
2048.22	3.47447
2051.15	4.16695
2054.07	5.00354
2057	6.09788
2059.92	4.43077
2062.85	4.60527
2065.77	5.68917
2068.69	5.42303
2071.61	6.09929
2074.53	6.80718
2077.45	7.57343
2080.37	8.45736
2083.28	10.0065
2086.2	9.89232
2089.11	12.1397
2092.02	13.0244
2094.94	15.628
2097.85	17.3646
2100.76	18.3425
2103.66	18.051
2106.57	16.8955
2109.48	16.3593
2112.38	17.661
2115.29	16.6941
2118.19	17.4213
2121.09	16.1994
2123.99	15.533
2126.89	14.4393
2129.79	14.4917
2132.69	11.664
2135.59	10.5277
2138.48	10.8005
2141.38	8.94675
2144.27	8.30321
2147.17	7.60379
2150.06	6.82638
2152.95	7.60547
2155.84	7.71113
2158.73	7.18406
2161.61	8.03412
2164.5	8.79881
2167.38	10.1428
2170.27	9.72784
2173.15	9.67588
2176.03	10.788
2178.91	12.0198
2181.8	14.8695
2184.67	16.6144
2187.55	15.9706
2190.43	17.9805
2193.3	17.0481
2196.18	16.7962
2199.05	17.12
2201.93	18.4789
2204.8	17.678
2207.67	18.0446
2210.54	17.7348
2213.41	18.5815
2216.27	20.1006
2219.14	18.8348
2222.01	19.874
2224.87	21.6342
2227.73	22.1203
2230.6	20.2119
2233.46	20.1982
2236.32	19.7926
2239.18	18.8273
2242.03	18.0937
2244.89	18.5073
2247.75	19.3168
2250.6	19.6378
2253.46	19.3402
2256.31	18.568
2259.16	18.7594
2262.01	18.5393
2264.86	17.4258
2267.71	19.6483
2270.56	19.6717
2273.4	18.6832
2276.25	20.2364
2279.09	18.9109
2281.94	19.1745
2284.78	19.125
2287.62	18.0878
2290.46	16.9352
2293.3	16.279
2296.14	15.8465
2298.98	16.3665
2301.82	14.2584
2304.65	14.5196
2307.49	14.6859
2310.32	14.5525
2313.15	13.5875
2315.98	14.5763
2318.81	15.0487
2321.64	13.9266
2324.47	15.5808
2327.3	16.3675
2330.12	18.963
2332.95	19.4256
2335.77	18.6957
2338.6	18.1853
2341.42	18.2047
2344.24	18.4695
2347.06	16.9712
2349.88	14.1858
2352.7	13.4531
2355.51	10.551
2358.33	7.8706
2361.14	5.59761
2363.96	4.67714
2366.77	4.66016
2369.58	1.15192
2372.39	0.955617
2375.2	0.61562
2378.01	-1.13181
2380.82	-1.88273
2383.63	-0.724131
2386.43	0.247149
2389.24	0.746442
2392.04	2.88327
2394.84	5.16349
2397.65	6.34901
2400.45	7.47748
2403.25	7.84323
2406.05	8.91218
2408.84	12.0836
2411.64	15.263
2414.44	15.5815
2417.23	17.3451
2420.02	18.1337
2422.82	18.9918
2425.61	18.3619
2428.4	19.7994
2431.19	19.2717
2433.98	17.0108
2436.77	16.29
2439.55	15.5388
2442.34	16.3766
2445.12	14.7081
2447.91	14.6691
2450.69	13.8689
2453.47	11.9694
2456.25	11.3581
2459.03	10.4234
2461.81	8.83351
2464.59	8.57055
2467.36	6.32499
2470.14	4.89957
2472.92	3.92553
2475.69	4.88269
2478.46	4.46886
2481.23	3.53931
2484	3.45618
2486.77	3.02799
2489.54	3.43517
2492.31	3.75293
2495.08	5.02713
2497.84	4.5238
2500.61	2.32443
2503.37	5.21384
2506.13	7.59602
2508.9	10.1504
2511.66	10.2743
2514.42	10.6499
2517.18	12.851
2519.93	14.3083
2522.69	15.742
2525.45	18.1743
2528.2	18.2617
2530.95	18.3749
2533.71	18.9385
2536.46	17.6347
2539.21	17.7323
2541.96	19.7001
2544.71	19.4317
2547.46	20.1727
2550.2	20.6391
2552.95	20.7079
2555.7	22.0686
2558.44	22.6056
2561.18	22.0254
2563.93	20.407
2566.67	20.4249
2569.41	21.6292
2572.15	23.0974
2574.88	22.7034
2577.62	22.0715
2580.36	22.2115
2583.09	24.9944
2585.83	25.418
2588.56	26.0967
2591.29	25.0485
2594.02	25.9469
2596.75	24.5509
2599.48	24.6276
2602.21	24.4403
2604.94	24.2778
2607.67	25.6286
2610.39	25.765
2613.12	24.7072
2615.84	22.8384
2618.56	22.895
2621.28	20.9449
2624.01	19.9233
2626.72	18.4086
2629.44	17.0171
2632.16	17.2343
2634.88	17.712
2637.59	18.3265
2640.31	19.3045
2643.02	20.5048
2645.74	21.902
2648.45	21.9066
2651.16	22.4013
2653.87	22.3727
2656.58	22.4061
2659.29	22.135
2661.99	24.1334
2664.7	24.6374
2667.41	24.496
2670.11	23.8726
2672.81	25.664
2675.51	25.3055
2678.22	23.2812
2680.92	22.4313
2683.62	22.2542
2686.31	21.7357
2689.01	21.5732
2691.71	19.9148
2694.4	21.2898
2697.1	21.0739
2699.79	22.4381
2702.49	25.1544
2705.18	26.5196
2707.87	26.8711
2710.56	28.6285
2713.25	30.4154
2715.94	30.873
2718.62	32.4426
2721.31	34.1661
2723.99	34.8174
2726.68	35.4439
2729.36	34.7631
2732.04	35.0551
2734.73	34.5075
2737.41	34.1632
2740.08	33.0351
2742.76	31.6986
2745.44	31.0202
2748.12	28.6789
2750.79	27.2877
2753.47	24.7216
2756.14	23.1146
2758.81	19.3811
2761.49	18.7114
2764.16	15.5574
2766.83	14.1601
2769.5	12.812
2772.16	11.008
2774.83	9.04742
2777.5	8.25889
2780.16	5.60784
2782.83	4.44243
2785.49	2.68921
2788.15	2.42815
2790.82	-0.0894597
2793.48	1.04273
2796.14	0.804533
2798.79	-0.0753595
2801.45	0.759587
2804.11	0.46523
2806.76	-0.462427
2809.42	-0.542113
2812.07	0.0273993
2814.73	2.80324
2817.38	7.46534
2820.03	13.5877
2822.68	21.2708
2825.33	30.3166
2827.98	38.7397
2830.63	48.2604
2833.27	58.6153
2835.92	70.2856
2838.56	83.4651
2841.21	97.0201
2843.85	116.683
2846.49	137.729
2849.13	160.116
2851.77	184.159
2854.41	209.07
2857.05	234.838
2859.69	256.068
2862.32	277.231
2864.96	297.496
2867.59	315.68
2870.23	329.449
2872.86	343.088
2875.49	356.144
2878.12	366.775
2880.75	375.077
2883.38	384.959
2886.01	395.354
2888.63	402.296
2891.26	408.08
2893.89	414.077
2896.51	421.82
2899.13	431.021
2901.76	441.993
2904.38	457.621
2907	478.245
2909.62	500.643
2912.24	523.175
2914.85	547.044
2917.47	568.536
2920.09	587.805
2922.7	603.482
2925.32	614.226
2927.93	621.535
2930.54	622.536
2933.15	619.284
2935.76	611.25
2938.37	599.126
2940.98	581.983
2943.59	562.531
2946.2	541.362
2948.8	520.348
2951.41	496.695
2954.01	470.355
2956.62	445.272
2959.22	419.773
2961.82	394.923
2964.42	370.173
2967.02	349.148
2969.62	332.715
2972.22	313.008
2974.81	294.99
2977.41	276.346
2980	257.067
2982.6	237.297
2985.19	219.616
2987.78	200.101
2990.38	180.088
2992.97	159.504
2995.56	140.863
2998.14	122.351
3000.73	105.59
3003.32	88.275
3005.91	73.2419
3008.49	61.4119
3011.07	50.183
3013.66	40.8714
3016.24	31.2504
3018.82	23.6245
3021.4	16.2229
3023.98	10.0317
3026.56	4.99854
3029.14	2.22959
3031.71	0.577323
3034.29	1.1372
3036.87	1.03604
3039.44	2.37106
3042.01	4.15058
3044.59	6.07819
3047.16	8.21277
3049.73	9.95675
3052.3	9.80709
3054.87	10.8236
3057.43	11.2561
3060	12.7436
3062.57	11.3258
3065.13	11.6981
3067.7	11.4902
3070.26	11.3261
3072.82	10.4515
3075.39	8.18162
3077.95	7.37367
3080.51	6.9366
3083.07	5.98877
3085.63	4.56698
3088.18	4.89219
3090.74	5.43217
3093.29	5.62756
3095.85	8.64139
3098.4	12.4613
3100.95	13.6007
3103.51	15.4293
3106.06	16.0646
3108.61	17.0542
3111.16	19.5471
3113.71	19.9978
3116.25	23.6915
3118.8	26.5513
3121.35	29.443
3123.89	31.6125
3126.44	34.2461
3128.98	37.0615
3131.52	40.2901
3134.06	43.9303
3136.6	46.9866
3139.14	53.0277
3141.68	57.7027
3144.22	62.1384
3146.76	66.8836
3149.29	71.8683