File: data/Raman/poly_smoothed/Mb_00_13_28_1x_45s_532 nm_x100_100%_600 gr_mm_01.txt
#Acq. time (s)=	45
#Accumulations=	2
#Range (cm-¹)=	200...3150
#Windows=	2
#Auto scanning=	Off
#Autofocus=	Off
#Macrospot=	Off
#AutoExposure=	Off
#Spike filter=	Multiple accum.
#Delay time (s)=	0
#Binning=	1
#Readout mode=	Signal
#DeNoise=	Off
#ICS correction=	On
#Dark correction=	Off
#Inst. Process=	Off
#Detector Gain=	Best Dynamic Range
#Detector ADC=	20 kHz
#Detector temperature (°C)=	-69.85
#Instrument=	LabRAM HR Evol
#Detector=	Synapse
#Objective=	x100
#Grating=	600 gr/mm
#ND Filter=	100%
#Laser (nm)=	532
#Hole=	100.021
#Range=	Auto
#Laser Pol.=	No
#Raman. Pol.=	No
#Laser Pol. (°)=	-0.0007625
#Raman Pol. (°)=	89.9995
#Collection=	Microscope
#StageXY=	Marzhauser
#StageZ=	Marzhauser
#X (µm)=	-973.2
#Y (µm)=	-2856.8
#Z (µm)=	529.05
#Full time(mm:ss)=	3:18
#Project=
#Sample=
#Site=
#Title=	Mb_00_13_28_2x_45s_532 nm_x100_100%_600 gr_mm
#Remark=
#Date=	06.07.2022 11:52
#Acquired=	06.07.2022 11:52:00
#Base:Fit=	10.08.2022 10:16:56
#Base:Sub=	10.08.2022 10:17:24
#Filter:Polynom=	16.08.2022 10:36:38
#AxisType[0]=Intens
#AxisUnit[0]=Cnt
#AxisType[1]=Spectr
#AxisUnit[1]=1/cm
200.398	9.51891
204.027	6.16771
207.657	2.09001
211.283	-0.717206
214.909	0.969425
218.533	7.79857
222.157	20.9576
225.777	37.9724
229.396	54.2208
233.016	65.7139
236.632	76.858
240.247	88.5679
243.86	100.342
247.474	107.508
251.085	117.557
254.694	123.576
258.301	127.294
261.908	128.008
265.513	127.545
269.116	125.58
272.718	119.632
276.319	111.48
279.918	102.294
283.516	92.3034
287.113	79.8682
290.708	68.1999
294.302	57.3656
297.894	49.1952
301.485	43.2723
305.073	41.9537
308.661	37.969
312.247	36.2442
315.833	32.4421
319.415	26.8858
322.997	25.9341
326.579	25.1037
330.156	25.2426
333.735	21.838
337.31	18.845
340.885	16.2288
344.458	14.3265
348.03	11.0363
351.6	8.88974
355.17	7.06808
358.737	6.34676
362.304	8.14656
365.868	10.6481
369.431	16.5375
372.994	21.8274
376.554	30.7836
380.112	41.5
383.669	54.5006
387.225	69.2587
390.781	84.529
394.334	97.4982
397.885	108.746
401.436	115.281
404.984	121.078
408.532	126.35
412.078	127.348
415.623	125.57
419.166	123.348
422.708	115.406
426.248	106.71
429.788	98.2241
433.326	86.7739
436.86	74.1361
440.395	61.8603
443.929	51.1615
447.461	41.6055
450.99	32.3041
454.52	27.2949
458.048	21.3988
461.573	17.8394
465.099	17.2432
468.623	17.0239
472.144	20.3897
475.666	22.3005
479.184	23.0413
482.703	26.824
486.218	28.4499
489.734	29.6313
493.247	32.6564
496.759	34.0989
500.271	36.6704
503.779	40.1757
507.287	41.8365
510.795	45.9343
514.299	50.5956
517.803	53.2551
521.305	55.9193
524.805	57.8549
528.307	59.106
531.805	59.3276
535.301	61.1891
538.797	60.9464
542.291	59.6348
545.783	55.2406
549.275	51.7452
552.765	47.5419
556.253	40.6163
559.738	34.7548
563.224	30.6166
566.709	28.556
570.192	26.9223
573.674	25.8246
577.153	24.4196
580.632	23.2966
584.11	24.0694
587.587	25.2016
591.06	24.8847
594.534	26.8278
598.005	25.8825
601.476	24.9195
604.944	24.1009
608.413	23.7106
611.878	22.2052
615.344	22.6191
618.807	23.9575
622.27	25.2747
625.73	24.9961
629.189	25.1392
632.648	25.3633
636.105	24.622
639.559	23.1175
643.013	20.9129
646.467	21.9542
649.918	22.4467
653.368	22.6476
656.816	23.518
660.263	22.5197
663.708	23.0722
667.153	23.5029
670.596	22.4209
674.037	18.7654
677.478	17.606
680.917	14.1595
684.355	10.9172
687.791	9.70099
691.224	9.30275
694.658	8.43121
698.091	6.14753
701.522	6.13972
704.95	3.69615
708.379	3.79906
711.806	5.01792
715.23	7.248
718.655	6.18328
722.078	4.65652
725.498	6.3651
728.919	4.61547
732.337	4.13188
735.755	4.60976
739.17	4.91937
742.584	7.85637
745.998	9.82249
749.409	15.1025
752.819	18.2805
756.23	21.5304
759.637	22.8042
763.043	29.5396
766.448	33.1661
769.853	37.2086
773.255	40.0475
776.656	40.9695
780.056	40.3168
783.454	39.4416
786.851	38.6337
790.247	40.0506
793.641	41.0361
797.034	42.4031
800.426	42.4259
803.817	41.6788
807.206	42.1991
810.592	41.7717
813.979	39.4208
817.364	39.0621
820.748	39.2225
824.129	39.515
827.511	41.7813
830.891	42.686
834.269	41.0468
837.646	39.3877
841.023	38.6728
844.396	37.8133
847.77	36.3409
851.141	34.2549
854.513	30.5065
857.881	25.09
861.248	20.4923
864.616	19.8209
867.98	17.5579
871.343	16.3482
874.707	16.1098
878.068	15.6701
881.428	16.4287
884.786	16.7022
888.143	15.1686
891.498	15.2912
894.855	15.0595
898.208	15.3581
901.56	18.1159
904.91	21.2712
908.26	23.5279
911.608	25.7903
914.955	26.3763
918.298	28.0376
921.643	28.7701
924.986	28.798
928.328	27.6185
931.668	27.2108
935.006	24.1795
938.344	22.6645
941.681	21.4779
945.014	20.9825
948.349	19.7037
951.682	19.4049
955.012	16.8922
958.343	11.3891
961.67	9.95848
964.998	13.2162
968.323	18.0117
971.649	22.7335
974.971	30.6496
978.293	38.5184
981.615	47.5817
984.933	55.2422
988.251	60.6181
991.567	63.7861
994.884	67.65
998.198	71.2132
1001.51	73.1651
1004.82	69.5587
1008.13	66.3471
1011.44	62.4986
1014.75	64.1702
1018.06	67.8129
1021.36	75.3389
1024.66	83.3296
1027.97	89.6382
1031.27	94.3102
1034.57	96.7707
1037.87	97.2712
1041.16	100.789
1044.46	106.628
1047.76	109.869
1051.05	111.638
1054.34	110.713
1057.63	107.867
1060.92	106.235
1064.21	97.5043
1067.5	88.9144
1070.78	77.629
1074.07	66.5768
1077.35	56.394
1080.63	42.0571
1083.91	27.3429
1087.19	16.6254
1090.47	10.1755
1093.75	10.7735
1097.03	14.5629
1100.3	16.9365
1103.57	16.5956
1106.84	18.8246
1110.11	16.9084
1113.38	14.8255
1116.65	13.4561
1119.92	13.5065
1123.19	11.8629
1126.45	13.1572
1129.71	11.4543
1132.97	10.4333
1136.23	12.0055
1139.49	13.2921
1142.75	11.009
1146.01	8.59762
1149.26	8.82815
1152.52	6.41625
1155.77	5.96969
1159.02	4.2004
1162.27	2.15994
1165.52	0.910761
1168.77	1.58843
1172.02	4.40249
1175.26	5.09904
1178.51	6.25151
1181.75	8.04418
1184.99	10.5849
1188.23	11.7174
1191.47	16.102
1194.71	23.0037
1197.94	28.2692
1201.18	36.6001
1204.41	43.5093
1207.65	50.6713
1210.88	60.1727
1214.11	67.9562
1217.34	77.1244
1220.57	83.7756
1223.79	88.864
1227.02	98.1466
1230.24	105.681
1233.47	111.84
1236.69	115.811
1239.91	118.029
1243.13	119.825
1246.34	123.113
1249.56	126.306
1252.78	126.798
1255.99	128.593
1259.2	127.454
1262.42	126.344
1265.63	125.188
1268.84	124.573
1272.04	127.066
1275.25	126.054
1278.46	130.176
1281.66	130.628
1284.86	133.044
1288.07	138.05
1291.27	140.556
1294.47	143.906
1297.66	147.948
1300.86	153.219
1304.06	160.319
1307.25	168.6
1310.44	173.962
1313.64	177.149
1316.83	179.809
1320.02	181.489
1323.2	184.073
1326.39	183.013
1329.58	181.647
1332.76	180.496
1335.95	178.204
1339.13	173.832
1342.31	168.805
1345.49	166.441
1348.67	160.517
1351.85	154.464
1355.02	148.968
1358.2	144.095
1361.37	138.574
1364.54	134.454
1367.71	128.524
1370.88	123.94
1374.05	121.437
1377.22	116.984
1380.39	116.082
1383.55	114.662
1386.72	115.116
1389.88	112.086
1393.04	108.461
1396.2	105.729
1399.36	105.235
1402.52	105.344
1405.68	107.356
1408.83	113.92
1411.98	119.665
1415.14	128.038
1418.29	137.32
1421.44	149.939
1424.59	163.241
1427.74	176.478
1430.89	190.806
1434.03	203.973
1437.18	215.783
1440.32	224.235
1443.46	231.55
1446.6	234.806
1449.74	235.823
1452.88	234.354
1456.02	228.585
1459.16	222.297
1462.29	212.002
1465.43	197.941
1468.56	181.548
1471.69	166.782
1474.82	150.37
1477.95	134.485
1481.08	121.823
1484.2	107.861
1487.33	97.6952
1490.46	89.378
1493.58	84.1862
1496.7	77.2526
1499.82	70.5633
1502.94	67.5153
1506.06	65.698
1509.18	64.1889
1512.29	64.1565
1515.41	64.6046
1518.52	63.0165
1521.63	64.8484
1524.75	65.0351
1527.85	66.9711
1530.96	69.1254
1534.07	70.5301
1537.18	73.4325
1540.28	77.5907
1543.39	80.3945
1546.49	84.2359
1549.59	88.1714
1552.69	91.9872
1555.79	95.2289
1558.89	98.8623
1561.99	102.63
1565.08	106.345
1568.18	111.873
1571.27	116.068
1574.37	118.691
1577.46	124.913
1580.55	130.935
1583.64	135.429
1586.73	141.317
1589.81	143.512
1592.9	145.517
1595.98	145.851
1599.06	147.49
1602.15	146.728
1605.23	145.099
1608.31	143.247
1611.39	141.92
1614.46	141.659
1617.54	138.669
1620.61	137.706
1623.69	138.843
1626.76	139.684
1629.83	140.367
1632.9	142.904
1635.97	147.523
1639.04	152.515
1642.11	158.363
1645.17	163.362
1648.24	167.615
1651.3	170.958
1654.36	175.014
1657.42	176.838
1660.48	177.506
1663.54	174.406
1666.6	169.803
1669.66	161.461
1672.71	152.908
1675.77	143.387
1678.82	132.527
1681.87	121.329
1684.92	109.711
1687.97	97.6981
1691.02	86.0416
1694.07	76.1393
1697.11	67.9121
1700.16	59.4034
1703.2	51.7093
1706.25	45.338
1709.29	39.8781
1712.33	34.4641
1715.37	30.6436
1718.41	25.4891
1721.44	22.3456
1724.48	20.0104
1727.51	18.8634
1730.55	16.1651
1733.58	14.4615
1736.61	11.7883
1739.64	10.6789
1742.67	9.09112
1745.7	8.75712
1748.72	6.78541
1751.75	6.53997
1754.77	5.41878
1757.8	4.82232
1760.82	4.21568
1763.84	4.19803
1766.86	3.5207
1769.88	3.03692
1772.9	2.94654
1775.91	3.40183
1778.93	3.49963
1781.94	2.91703
1784.96	1.62839
1787.97	1.43448
1790.98	0.970816
1793.99	0.24893
1797	-0.074045
1800.01	0.033245
1803.01	-1.08177
1806.02	-0.752667
1809.02	0.243407
1812.02	1.21238
1815.02	2.39735
1818.03	2.94418
1821.02	2.72938
1824.02	2.33423
1827.02	2.99419
1830.02	3.59784
1833.01	4.09814
1836.01	4.71974
1839	4.61777
1841.99	3.96057
1844.98	4.82591
1847.97	4.06561
1850.96	3.34918
1853.95	3.18648
1856.93	3.92916
1859.92	3.53169
1862.9	3.91051
1865.88	3.75467
1868.87	5.11284
1871.85	4.89054
1874.83	5.10196
1877.81	3.71079
1880.78	3.60026
1882.53	3.2652
1885.52	3.99955
1888.51	2.75371
1891.5	1.55945
1894.48	2.09839
1897.47	0.912651
1900.45	2.37583
1903.43	2.86301
1906.41	2.6686
1909.39	4.26297
1912.37	4.28026
1915.35	5.2705
1918.33	5.45483
1921.3	5.49039
1924.28	7.90884
1927.25	9.22723
1930.22	9.94272
1933.19	9.68631
1936.16	11.3355
1939.13	11.616
1942.1	11.6007
1945.07	11.6672
1948.03	10.5842
1951	10.3109
1953.96	9.8545
1956.92	9.47034
1959.88	8.88126
1962.84	8.01871
1965.8	6.77505
1968.76	6.32951
1971.72	6.64373
1974.67	7.69349
1977.63	7.34603
1980.58	8.50378
1983.54	9.03663
1986.49	8.62465
1989.44	8.59083
1992.39	8.69968
1995.33	9.48673
1998.28	9.86054
2001.23	11.6114
2004.17	11.5988
2007.12	10.9743
2010.06	11.79
2013	11.7949
2015.94	10.967
2018.88	9.54359
2021.82	8.86902
2024.76	8.57063
2027.69	7.24891
2030.63	8.90279
2033.56	7.87992
2036.5	6.00027
2039.43	5.34796
2042.36	5.59506
2045.29	5.54407
2048.22	5.5862
2051.15	6.61333
2054.07	7.27268
2057	7.75501
2059.92	8.70202
2062.85	9.78894
2065.77	12.3856
2068.69	13.6865
2071.61	15.0749
2074.53	16.0416
2077.45	14.6416
2080.37	15.4777
2083.28	15.2892
2086.2	16.4176
2089.11	16.4364
2092.02	16.6352
2094.94	17.0842
2097.85	16.7405
2100.76	16.4545
2103.66	15.5453
2106.57	13.2367
2109.48	12.6234
2112.38	11.5133
2115.29	10.5716
2118.19	9.36445
2121.09	8.4791
2123.99	7.50133
2126.89	6.62954
2129.79	5.44181
2132.69	5.99823
2135.59	6.38387
2138.48	7.16848
2141.38	6.95998
2144.27	6.15143
2147.17	5.9862
2150.06	5.88006
2152.95	6.3586
2155.84	7.82986
2158.73	8.65555
2161.61	7.91664
2164.5	7.90514
2167.38	8.52884
2170.27	8.95481
2173.15	10.0901
2176.03	9.78603
2178.91	11.0874
2181.8	11.0542
2184.67	10.6544
2187.55	10.3726
2190.43	9.76995
2193.3	10.4552
2196.18	11.5736
2199.05	12.6136
2201.93	12.9741
2204.8	14.544
2207.67	14.4181
2210.54	13.1954
2213.41	12.6462
2216.27	12.9541
2219.14	12.2722
2222.01	10.9804
2224.87	10.6611
2227.73	8.90778
2230.6	6.474
2233.46	6.82198
2236.32	8.01532
2239.18	8.59685
2242.03	7.0663
2244.89	6.26045
2247.75	5.86177
2250.6	4.88255
2253.46	5.25372
2256.31	5.109
2259.16	6.91882
2262.01	7.59082
2264.86	8.51102
2267.71	8.24726
2270.56	7.72199
2273.4	7.37423
2276.25	7.00414
2279.09	7.08379
2281.94	8.3763
2284.78	7.57239
2287.62	6.01971
2290.46	4.57915
2293.3	4.16995
2296.14	6.07595
2298.98	6.60549
2301.82	8.26226
2304.65	9.37588
2307.49	9.7157
2310.32	8.44092
2313.15	7.63321
2315.98	8.24033
2318.81	7.58762
2321.64	7.94816
2324.47	8.10525
2327.3	7.53005
2330.12	8.00794
2332.95	7.84777
2335.77	7.47
2338.6	5.63765
2341.42	5.31722
2344.24	4.79295
2347.06	4.70424
2349.88	4.81841
2352.7	3.64859
2355.51	2.41363
2358.33	2.83636
2361.14	3.75441
2363.96	4.39596
2366.77	4.63785
2369.58	2.5022
2372.39	2.43127
2375.2	1.08681
2378.01	1.80576
2380.82	1.96497
2383.63	2.38069
2386.43	2.43859
2389.24	3.19916
2392.04	5.24162
2394.84	6.4041
2397.65	6.84603
2400.45	7.00577
2403.25	8.00753
2406.05	8.02286
2408.84	8.57101
2411.64	9.61845
2414.44	9.40931
2417.23	9.00637
2420.02	8.69481
2422.82	7.48701
2425.61	6.45984
2428.4	5.0242
2431.19	3.60535
2433.98	2.09376
2436.77	1.383
2439.55	0.883216
2442.34	0.644437
2445.12	0.301306
2447.91	0.59928
2450.69	0.21137
2453.47	0.0348243
2456.25	0.419599
2459.03	1.08957
2461.81	1.13648
2464.59	0.965927
2467.36	1.03765
2470.14	1.34974
2472.92	1.8531
2475.69	0.555319
2478.46	0.745964
2481.23	1.14077
2484	1.74731
2486.77	0.793522
2489.54	1.82521
2492.31	1.70873
2495.08	1.63326
2497.84	2.907
2500.61	3.73599
2503.37	4.40953
2506.13	3.5261
2508.9	2.61699
2511.66	2.81406
2514.42	2.97838
2517.18	4.12205
2519.93	5.03211
2522.69	4.73812
2525.45	5.76144
2528.2	5.28199
2530.95	5.55522
2533.71	6.35604
2536.46	6.14507
2539.21	5.48262
2541.96	5.181
2544.71	6.6548
2547.46	6.98717
2550.2	8.73869
2552.95	8.72916
2555.7	8.72316
2558.44	8.06404
2561.18	9.39557
2563.93	9.74756
2566.67	9.41487
2569.41	8.50642
2572.15	7.4378
2574.88	8.23448
2577.62	9.16568
2580.36	9.02257
2583.09	9.52097
2585.83	10.6546
2588.56	10.4425
2591.29	9.93365
2594.02	9.2642
2596.75	9.02502
2599.48	8.83797
2602.21	8.22551
2604.94	8.48432
2607.67	9.02207
2610.39	9.25258
2613.12	9.55863
2615.84	10.8697
2618.56	11.6198
2621.28	11.9362
2624.01	11.9779
2626.72	13.6435
2629.44	13.7324
2632.16	14.0715
2634.88	14.1248
2637.59	14.5238
2640.31	15.957
2643.02	17.276
2645.74	17.2049
2648.45	17.8405
2651.16	17.3986
2653.87	15.9627
2656.58	14.1006
2659.29	13.6666
2661.99	13.2277
2664.7	12.1321
2667.41	12.4909
2670.11	12.9038
2672.81	12.3078
2675.51	11.4519
2678.22	10.9112
2680.92	11.3886
2683.62	11.9603
2686.31	11.8266
2689.01	10.9794
2691.71	11.7912
2694.4	12.5675
2697.1	13.1413
2699.79	13.7105
2702.49	15.0028
2705.18	17.0552
2707.87	20.2702
2710.56	21.0404
2713.25	21.4483
2715.94	22.6925
2718.62	23.5579
2721.31	23.9682
2723.99	23.9967
2726.68	23.6254
2729.36	22.3258
2732.04	22.9172
2734.73	22.0619
2737.41	21.3643
2740.08	19.1082
2742.76	18.4137
2745.44	17.5603
2748.12	15.8863
2750.79	14.7629
2753.47	13.8646
2756.14	12.728
2758.81	12.1627
2761.49	11.4153
2764.16	11.6569
2766.83	10.6847
2769.5	11.2336
2772.16	11.6265
2774.83	11.5188
2777.5	10.937
2780.16	11.3492
2782.83	10.7569
2785.49	9.88042
2788.15	7.37163
2790.82	5.89569
2793.48	4.43841
2796.14	4.23943
2798.79	3.4486
2801.45	2.89162
2804.11	2.66366
2806.76	1.82033
2809.42	2.05939
2812.07	2.21342
2814.73	3.86626
2817.38	6.49714
2820.03	9.44317
2822.68	13.6577
2825.33	18.6716
2827.98	24.0186
2830.63	30.0551
2833.27	37.4242
2835.92	46.1746
2838.56	56.9193
2841.21	71.0088
2843.85	86.3227
2846.49	102.269
2849.13	120.565
2851.77	138.931
2854.41	159.214
2857.05	178.003
2859.69	196.548
2862.32	214.434
2864.96	231.087
2867.59	245.424
2870.23	259.619
2872.86	271.454
2875.49	283.152
2878.12	292.341
2880.75	300.842
2883.38	307.337
2886.01	315.037
2888.63	320.893
2891.26	326.341
2893.89	332.254
2896.51	341.386
2899.13	351.37
2901.76	363.966
2904.38	380.633
2907	398.451
2909.62	417.566
2912.24	437.986
2914.85	459.803
2917.47	476.759
2920.09	490.76
2922.7	501.373
2925.32	509.67
2927.93	513.319
2930.54	513.602
2933.15	510.1
2935.76	503.401
2938.37	492.326
2940.98	479.374
2943.59	463.36
2946.2	445.741
2948.8	427.198
2951.41	406.99
2954.01	385.837
2956.62	365.273
2959.22	346.408
2961.82	328.345
2964.42	309.84
2967.02	294.026
2969.62	279.37
2972.22	265.372
2974.81	251.909
2977.41	237.149
2980	220.956
2982.6	205.102
2985.19	187.908
2987.78	171.133
2990.38	153.722
2992.97	137.51
2995.56	122.098
2998.14	105.968
3000.73	92.4222
3003.32	80.2507
3005.91	67.1001
3008.49	54.7301
3011.07	44.4027
3013.66	35.3903
3016.24	27.0987
3018.82	19.6011
3021.4	13.3827
3023.98	9.92653
3026.56	4.93155
3029.14	2.13946
3031.71	0.829396
3034.29	0.204936
3036.87	-0.175768
3039.44	-0.551374
3042.01	0.189315
3044.59	1.68688
3047.16	2.72594
3049.73	4.37692
3052.3	4.88462
3054.87	6.37232
3057.43	6.58145
3060	7.58897
3062.57	8.1156
3065.13	8.3329
3067.7	7.21943
3070.26	6.50963
3072.82	5.49583
3075.39	5.58689
3077.95	4.4452
3080.51	3.83051
3083.07	2.78416
3085.63	2.98655
3088.18	2.3536
3090.74	2.57787
3093.29	2.99805
3095.85	4.50033
3098.4	5.37198
3100.95	5.54217
3103.51	7.37826
3106.06	8.58608
3108.61	10.5392
3111.16	11.9456
3113.71	13.4139
3116.25	15.4135
3118.8	18.0332
3121.35	20.4913
3123.89	22.2059
3126.44	24.4596
3128.98	26.4424
3131.52	28.3704
3134.06	30.4681
3136.6	33.1992
3139.14	36.4091
3141.68	39.2804
3144.22	41.2798
3146.76	42.6045
3149.29	43.6764