File: data/Raman/poly_smoothed/Mb_00_13_17_1x_45s_532 nm_x100_100%_600 gr_mm_02.txt
#Acq. time (s)=	45
#Accumulations=	2
#Range (cm-¹)=	200...3150
#Windows=	2
#Auto scanning=	Off
#Autofocus=	Off
#Macrospot=	Off
#AutoExposure=	Off
#Spike filter=	Multiple accum.
#Delay time (s)=	0
#Binning=	1
#Readout mode=	Signal
#DeNoise=	Off
#ICS correction=	On
#Dark correction=	Off
#Inst. Process=	Off
#Detector Gain=	Best Dynamic Range
#Detector ADC=	20 kHz
#Detector temperature (°C)=	-69.85
#Instrument=	LabRAM HR Evol
#Detector=	Synapse
#Objective=	x100
#Grating=	600 gr/mm
#ND Filter=	100%
#Laser (nm)=	532
#Hole=	100.021
#Range=	Auto
#Laser Pol.=	No
#Raman. Pol.=	No
#Laser Pol. (°)=	-0.0007625
#Raman Pol. (°)=	89.9995
#Collection=	Microscope
#StageXY=	Marzhauser
#StageZ=	Marzhauser
#X (µm)=	-1031
#Y (µm)=	-2917.4
#Z (µm)=	527.85
#Full time(mm:ss)=	3:18
#Project=
#Sample=
#Site=
#Title=	Mb_00_13_17_2x_45s_532 nm_x100_100%_600 gr_mm
#Remark=
#Date=	06.07.2022 10:54
#Acquired=	06.07.2022 10:54:19
#Base:Fit=	06.07.2022 10:56:24
#Base:Fit=	06.07.2022 10:56:30
#Base:Fit=	06.07.2022 10:56:33
#Base:Fit=	06.07.2022 10:56:36
#Edit:Spike=	06.07.2022 10:57:31
#Edit:Spike=	06.07.2022 10:57:32
#Base:Fit=	10.08.2022 10:16:56
#Base:Sub=	10.08.2022 10:17:24
#Filter:Polynom=	16.08.2022 10:36:38
#AxisType[0]=Intens
#AxisUnit[0]=Cnt
#AxisType[1]=Spectr
#AxisUnit[1]=1/cm
200.398	29.0628
204.027	13.5828
207.657	1.42041
211.283	-6.07758
214.909	-6.66702
218.533	1.21408
222.157	17.6304
225.777	38.9052
229.396	64.3159
233.016	87.7915
236.632	110.178
240.247	135.503
243.86	157.092
247.474	177.419
251.085	199.909
254.694	216.173
258.301	223.138
261.908	231.284
265.513	232.383
269.116	229.832
272.718	218.719
276.319	203.363
279.918	185.054
283.516	164.338
287.113	143.721
290.708	123.109
294.302	99.7322
297.894	82.1553
301.485	62.7213
305.073	46.6689
308.661	37.5694
312.247	28.395
315.833	23.4113
319.415	19.6944
322.997	18.2055
326.579	20.6144
330.156	20.3073
333.735	19.2569
337.31	18.1381
340.885	16.9659
344.458	12.7288
348.03	9.78525
351.6	10.4877
355.17	7.12978
358.737	5.85452
362.304	5.91272
365.868	12.3955
369.431	22.0033
372.994	29.2057
376.554	40.9283
380.112	52.6056
383.669	71.8321
387.225	91.1814
390.781	112.012
394.334	137.231
397.885	160.813
401.436	180.874
404.984	197.433
408.532	209.228
412.078	215.333
415.623	218.307
419.166	214.78
422.708	207.49
426.248	196.909
429.788	178.754
433.326	160.32
436.86	138.428
440.395	114.484
443.929	92.4692
447.461	71.3595
450.99	51.2987
454.52	35.7403
458.048	17.5998
461.573	4.03923
465.099	-2.51283
468.623	-5.92981
472.144	-3.50005
475.666	0.0550563
479.184	4.03355
482.703	9.52467
486.218	14.6624
489.734	19.9482
493.247	29.6669
496.759	36.5427
500.271	45.1976
503.779	52.5899
507.287	56.2746
510.795	61.594
514.299	64.1743
517.803	67.4146
521.305	71.0021
524.805	72.5636
528.307	71.8103
531.805	72.215
535.301	69.3823
538.797	64.2965
542.291	56.1213
545.783	48.3681
549.275	41.6568
552.765	33.0911
556.253	25.7269
559.738	21.5117
563.224	18.2347
566.709	13.9814
570.192	7.73833
573.674	6.57796
577.153	4.64197
580.632	7.32796
584.11	6.85469
587.587	5.58219
591.06	4.40357
594.534	1.0323
598.005	0.50788
601.476	4.35576
604.944	10.4894
608.413	13.3711
611.878	15.9468
615.344	17.6618
618.807	21.0362
622.27	22.2451
625.73	24.5282
629.189	30.2239
632.648	41.6536
636.105	48.8009
639.559	57.3868
643.013	64.6553
646.467	73.4952
649.918	76.5953
653.368	74.2571
656.816	71.3896
660.263	68.9564
663.708	70.3151
667.153	68.2198
670.596	59.7447
674.037	51.5686
677.478	47.341
680.917	40.3565
684.355	34.7719
687.791	29.071
691.224	21.5525
694.658	11.7862
698.091	5.98045
701.522	3.72851
704.95	1.48752
708.379	-0.17046
711.806	3.26829
715.23	8.76766
718.655	10.3301
722.078	8.37355
725.498	8.91367
728.919	10.3305
732.337	9.93151
735.755	8.58143
739.17	12.8186
742.584	18.4594
745.998	27.0649
749.409	31.3947
752.819	35.6995
756.23	42.6494
759.637	47.5645
763.043	51.0089
766.448	52.902
769.853	54.9978
773.255	57.7388
776.656	59.4823
780.056	63.2772
783.454	65.581
786.851	67.2587
790.247	68.3246
793.641	67.6756
797.034	68.1461
800.426	66.4619
803.817	65.0603
807.206	63.955
810.592	62.0986
813.979	61.7005
817.364	58.7859
820.748	59.6379
824.129	59.4078
827.511	62.1802
830.891	62.6375
834.269	57.87
837.646	57.7256
841.023	55.1248
844.396	48.9003
847.77	46.312
851.141	44.1141
854.513	40.0374
857.881	34.7535
861.248	30.8814
864.616	25.4993
867.98	22.5834
871.343	19.7753
874.707	19.3817
878.068	17.3944
881.428	19.5805
884.786	16.3852
888.143	11.6436
891.498	12.3812
894.855	10.6007
898.208	12.4601
901.56	12.5376
904.91	15.1743
908.26	19.5608
911.608	22.0848
914.955	19.9945
918.298	23.0774
921.643	26.4408
924.986	26.0967
928.328	29.8311
931.668	31.3708
935.006	34.5054
938.344	35.2562
941.681	34.0862
945.014	31.7922
948.349	32.2076
951.682	35.091
955.012	34.2169
958.343	28.9158
961.67	28.2876
964.998	29.5447
968.323	33.7207
971.649	41.5703
974.971	51.23
978.293	58.2967
981.615	61.0371
984.933	66.9579
988.251	70.3288
991.567	70.9967
994.884	71.7128
998.198	78.2558
1001.51	82.5731
1004.82	84.8515
1008.13	84.3257
1011.44	85.3311
1014.75	88.5616
1018.06	95.6716
1021.36	108.053
1024.66	125.264
1027.97	142.65
1031.27	157.661
1034.57	169.35
1037.87	178.218
1041.16	187.181
1044.46	195.739
1047.76	201.306
1051.05	203.73
1054.34	200.864
1057.63	190.158
1060.92	177.34
1064.21	161.802
1067.5	146.983
1070.78	133.003
1074.07	115.102
1077.35	97.405
1080.63	76.7856
1083.91	53.8066
1087.19	33.1939
1090.47	19.2663
1093.75	11.2538
1097.03	9.77606
1100.3	12.058
1103.57	17.7613
1106.84	18.3457
1110.11	19.2024
1113.38	18.3124
1116.65	16.5933
1119.92	15.3974
1123.19	15.8162
1126.45	18.4487
1129.71	19.3952
1132.97	21.9344
1136.23	19.4195
1139.49	19.7208
1142.75	22.0744
1146.01	28.3544
1149.26	29.826
1152.52	30.0152
1155.77	25.839
1159.02	27.4492
1162.27	25.3948
1165.52	26.24
1168.77	30.8829
1172.02	34.4145
1175.26	39.9682
1178.51	43.8409
1181.75	50.0459
1184.99	59.5168
1188.23	65.3348
1191.47	79.3475
1194.71	88.6277
1197.94	100.217
1201.18	115.471
1204.41	127.16
1207.65	140.389
1210.88	155.935
1214.11	168.048
1217.34	181.563
1220.57	194.463
1223.79	205.959
1227.02	214.618
1230.24	221.473
1233.47	228.55
1236.69	235.311
1239.91	244.161
1243.13	250.438
1246.34	257.129
1249.56	261.465
1252.78	264.851
1255.99	268.551
1259.2	273.591
1262.42	279.884
1265.63	283.398
1268.84	287.735
1272.04	292.051
1275.25	299.414
1278.46	306.671
1281.66	315.147
1284.86	330.171
1288.07	342.549
1291.27	355.7
1294.47	367.215
1297.66	377.004
1300.86	389.555
1304.06	402.567
1307.25	415.058
1310.44	428.256
1313.64	441.685
1316.83	454.406
1320.02	460.261
1323.2	469.96
1326.39	474.554
1329.58	473.592
1332.76	475.289
1335.95	476.442
1339.13	476.771
1342.31	471.99
1345.49	469.625
1348.67	463.79
1351.85	460.873
1355.02	454.995
1358.2	447.896
1361.37	442.861
1364.54	433.256
1367.71	424.169
1370.88	414.225
1374.05	409.617
1377.22	400.88
1380.39	395.778
1383.55	391.954
1386.72	388.798
1389.88	381.099
1393.04	376.123
1396.2	368.834
1399.36	360.485
1402.52	356.216
1405.68	352.135
1408.83	349.207
1411.98	354.068
1415.14	358.088
1418.29	363.113
1421.44	374.631
1424.59	384.095
1427.74	395.101
1430.89	406.567
1434.03	415.838
1437.18	423.665
1440.32	429.625
1443.46	433.371
1446.6	432.785
1449.74	429.02
1452.88	423.838
1456.02	416.537
1459.16	403.853
1462.29	392.477
1465.43	373.849
1468.56	352.236
1471.69	326.958
1474.82	303.359
1477.95	283.494
1481.08	262.372
1484.2	246.704
1487.33	228.38
1490.46	220.707
1493.58	214.601
1496.7	211.027
1499.82	211.938
1502.94	210.152
1506.06	211.648
1509.18	213.92
1512.29	218.053
1515.41	222.449
1518.52	227.778
1521.63	234.894
1524.75	241.104
1527.85	248.24
1530.96	257.564
1534.07	265.214
1537.18	276.639
1540.28	286.437
1543.39	295.274
1546.49	307.655
1549.59	315.457
1552.69	329.904
1555.79	341.004
1558.89	351.979
1561.99	362.536
1565.08	373.013
1568.18	386.545
1571.27	397.593
1574.37	410.183
1577.46	423.803
1580.55	434.304
1583.64	444.046
1586.73	450.611
1589.81	458.963
1592.9	462.734
1595.98	461.354
1599.06	457.244
1602.15	451.081
1605.23	442.277
1608.31	428.765
1611.39	414.458
1614.46	399.357
1617.54	379.755
1620.61	362.692
1623.69	345.346
1626.76	327.174
1629.83	307.032
1632.9	287.525
1635.97	268.68
1639.04	248.825
1642.11	235.791
1645.17	224.626
1648.24	217.397
1651.3	210.228
1654.36	204.497
1657.42	198.324
1660.48	191.671
1663.54	182.455
1666.6	174.096
1669.66	164.738
1672.71	149.985
1675.77	139.078
1678.82	125.047
1681.87	111.881
1684.92	98.0627
1687.97	84.7924
1691.02	70.3562
1694.07	57.9739
1697.11	48.7371
1700.16	37.553
1703.2	27.0569
1706.25	16.8699
1709.29	10.7596
1712.33	3.13678
1715.37	-0.414454
1718.41	-0.723081
1721.44	0.458772
1724.48	0.437114
1727.51	3.03102
1730.55	5.67089
1733.58	11.1869
1736.61	14.5554
1739.64	19.1318
1742.67	23.5195
1745.7	27.8218
1748.72	34.529
1751.75	42.0881
1754.77	47.5195
1757.8	52.8441
1760.82	57.7017
1763.84	62.9578
1766.86	68.158
1769.88	73.9535
1772.9	80.5239
1775.91	81.4335
1778.93	85.7629
1781.94	88.6517
1784.96	91.3067
1787.97	92.9222
1790.98	93.3966
1793.99	94.5464
1797	94.1301
1800.01	96.6015
1803.01	95.7731
1806.02	93.9741
1809.02	93.1351
1812.02	92.3385
1815.02	91.9634
1818.03	88.8287
1821.02	89.6729
1824.02	88.4205
1827.02	84.739
1830.02	83.6638
1833.01	84.4863
1836.01	86.8023
1839	87.2068
1841.99	86.5389
1844.98	88.1114
1847.97	85.6956
1850.96	80.6829
1853.95	80.327
1856.93	77.2689
1859.92	73.6728
1862.9	68.9889
1865.88	64.1492
1868.87	59.8365
1871.85	56.9952
1874.83	51.6507
1877.81	46.5609
1880.78	45.6478
1882.53	43.4958
1885.52	42.2612
1888.51	39.8157
1891.5	37.4165
1894.48	34.3509
1897.47	32.9641
1900.45	31.1839
1903.43	30.0165
1906.41	32.7951
1909.39	31.7187
1912.37	27.5836
1915.35	26.0126
1918.33	23.63
1921.3	20.3551
1924.28	20.1601
1927.25	15.3786
1930.22	12.9017
1933.19	9.31151
1936.16	9.57182
1939.13	7.93932
1942.1	8.48216
1945.07	7.42703
1948.03	8.08585
1951	8.80768
1953.96	7.61094
1956.92	5.47482
1959.88	4.97386
1962.84	2.3885
1965.8	2.99879
1968.76	0.244839
1971.72	-1.79267
1974.67	-1.95912
1977.63	1.74203
1980.58	1.07226
1983.54	1.84684
1986.49	5.58407
1989.44	9.42223
1992.39	11.7248
1995.33	14.8033
1998.28	16.4808
2001.23	16.3708
2004.17	22.0956
2007.12	27.3301
2010.06	30.3997
2013	32.4937
2015.94	37.2943
2018.88	38.5545
2021.82	41.645
2024.76	38.8171
2027.69	38.7273
2030.63	38.8402
2033.56	37.9084
2036.5	35.7606
2039.43	29.8775
2042.36	29.3315
2045.29	26.4582
2048.22	29.1484
2051.15	30.7371
2054.07	32.1502
2057	31.789
2059.92	31.4121
2062.85	33.1221
2065.77	34.8627
2068.69	34.6377
2071.61	31.3383
2074.53	31.9277
2077.45	34.1107
2080.37	31.902
2083.28	33.6737
2086.2	29.5686
2089.11	32.8511
2092.02	32.7454
2094.94	27.9539
2097.85	26.1185
2100.76	21.2083
2103.66	21.8982
2106.57	20.183
2109.48	17.4015
2112.38	17.8704
2115.29	16.8302
2118.19	19.5157
2121.09	22.2534
2123.99	21.5823
2126.89	18.9795
2129.79	21.2541
2132.69	24.6379
2135.59	25.8032
2138.48	27.8835
2141.38	28.0106
2144.27	31.2049
2147.17	35.5561
2150.06	34.9753
2152.95	35.0295
2155.84	33.6038
2158.73	34.6009
2161.61	37.9886
2164.5	36.0798
2167.38	34.4861
2170.27	35.5401
2173.15	34.0822
2176.03	37.4849
2178.91	35.1545
2181.8	35.6015
2184.67	33.5547
2187.55	34.3754
2190.43	34.7763
2193.3	35.8057
2196.18	35.4935
2199.05	39.4029
2201.93	40.6867
2204.8	45.2061
2207.67	44.5835
2210.54	48.4083
2213.41	52.2801
2216.27	53.0141
2219.14	54.1359
2222.01	55.4142
2224.87	57.2787
2227.73	60.2305
2230.6	61.2957
2233.46	64.5158
2236.32	65.5626
2239.18	62.7752
2242.03	59.0296
2244.89	57.2926
2247.75	58.5332
2250.6	57.0736
2253.46	54.1916
2256.31	50.9994
2259.16	48.4898
2262.01	48.0835
2264.86	44.0562
2267.71	44.9951
2270.56	44.1518
2273.4	42.4622
2276.25	41.9538
2279.09	40.3975
2281.94	38.329
2284.78	36.4133
2287.62	37.9722
2290.46	38.4457
2293.3	40.2664
2296.14	42.1895
2298.98	44.7592
2301.82	46.0575
2304.65	47.8787
2307.49	45.6437
2310.32	40.9284
2313.15	38.5942
2315.98	34.5891
2318.81	32.3327
2321.64	28.1725
2324.47	24.4343
2327.3	19.2363
2330.12	18.2162
2332.95	18.2877
2335.77	13.7588
2338.6	10.6535
2341.42	9.29995
2344.24	6.07715
2347.06	6.32773
2349.88	2.5966
2352.7	-1.2657
2355.51	0.735511
2358.33	4.69283
2361.14	5.74031
2363.96	9.35707
2366.77	11.1542
2369.58	14.7088
2372.39	13.0204
2375.2	12.3152
2378.01	13.5822
2380.82	14.4129
2383.63	14.2206
2386.43	14.3068
2389.24	16.9828
2392.04	20.5194
2394.84	19.0082
2397.65	16.5055
2400.45	17.8686
2403.25	17.399
2406.05	19.5587
2408.84	22.437
2411.64	23.9638
2414.44	21.3377
2417.23	19.0797
2420.02	15.5566
2422.82	16.4068
2425.61	16.305
2428.4	16.7744
2431.19	14.3107
2433.98	13.4498
2436.77	10.6312
2439.55	9.66936
2442.34	5.34789
2445.12	6.27961
2447.91	5.46698
2450.69	4.83073
2453.47	3.63748
2456.25	1.94545
2459.03	2.8028
2461.81	0.218778
2464.59	-1.2847
2467.36	-0.655042
2470.14	2.56707
2472.92	5.23125
2475.69	4.65228
2478.46	1.20094
2481.23	1.39165
2484	-0.918033
2486.77	0.310284
2489.54	0.888923
2492.31	2.7345
2495.08	2.68717
2497.84	1.31548
2500.61	-0.13338
2503.37	-0.251411
2506.13	1.08305
2508.9	2.91616
2511.66	6.39471
2514.42	10.7805
2517.18	16.0674
2519.93	17.2116
2522.69	20.5908
2525.45	22.7811
2528.2	29.9258
2530.95	34.1641
2533.71	39.107
2536.46	43.8601
2539.21	45.6539
2541.96	51.1096
2544.71	49.5136
2547.46	50.6859
2550.2	52.8994
2552.95	51.6744
2555.7	51.081
2558.44	47.4958
2561.18	45.2261
2563.93	44.9291
2566.67	46.3927
2569.41	46.6101
2572.15	46.7743
2574.88	44.6121
2577.62	44.1021
2580.36	42.5659
2583.09	42.4309
2585.83	42.5336
2588.56	43.9438
2591.29	44.2113
2594.02	45.4654
2596.75	45.257
2599.48	42.4943
2602.21	42.0665
2604.94	40.4044
2607.67	43.4002
2610.39	39.7064
2613.12	38.6203
2615.84	42.8593
2618.56	38.6426
2621.28	38.7365
2624.01	40.0226
2626.72	39.6782
2629.44	42.3702
2632.16	43.1495
2634.88	44.0702
2637.59	45.4495
2640.31	42.6902
2643.02	42.3524
2645.74	44.4735
2648.45	44.9202
2651.16	47.249
2653.87	44.8792
2656.58	44.7946
2659.29	38.552
2661.99	35.6504
2664.7	30.2671
2667.41	31.6242
2670.11	36.7215
2672.81	38.9567
2675.51	41.9215
2678.22	42.7685
2680.92	44.7001
2683.62	44.6739
2686.31	45.9895
2689.01	48.7045
2691.71	49.6195
2694.4	50.9919
2697.1	53.5718
2699.79	57.8074
2702.49	56.8573
2705.18	58.5121
2707.87	57.28
2710.56	59.2478
2713.25	59.1261
2715.94	58.9691
2718.62	58.9045
2721.31	58.7537
2723.99	58.5522
2726.68	52.0284
2729.36	51.9718
2732.04	50.5984
2734.73	55.7429
2737.41	53.7219
2740.08	49.8307
2742.76	47.9152
2745.44	45.5747
2748.12	44.7198
2750.79	47.1781
2753.47	45.2833
2756.14	40.5665
2758.81	37.4712
2761.49	36.8129
2764.16	35.4449
2766.83	34.1351
2769.5	33.2796
2772.16	27.6806
2774.83	25.8603
2777.5	24.8794
2780.16	23.6192
2782.83	20.9767
2785.49	19.0948
2788.15	16.4516
2790.82	14.2111
2793.48	12.9741
2796.14	9.59004
2798.79	5.50088
2801.45	3.8501
2804.11	-0.294992
2806.76	-3.10701
2809.42	-3.52445
2812.07	-1.77383
2814.73	0.590049
2817.38	3.14812
2820.03	5.69233
2822.68	12.766
2825.33	22.9384
2827.98	37.0254
2830.63	48.8094
2833.27	63.1807
2835.92	79.5824
2838.56	102.431
2841.21	123.692
2843.85	148.175
2846.49	172.49
2849.13	200.679
2851.77	224.669
2854.41	250.373
2857.05	272.166
2859.69	288.837
2862.32	304.483
2864.96	321.21
2867.59	335.432
2870.23	347.752
2872.86	355.594
2875.49	360.478
2878.12	367.735
2880.75	373.411
2883.38	380.999
2886.01	390.23
2888.63	399.122
2891.26	409.867
2893.89	418.265
2896.51	432.431
2899.13	446.546
2901.76	465.487
2904.38	485.141
2907	506.684
2909.62	533.062
2912.24	560.604
2914.85	583.544
2917.47	602.852
2920.09	619.719
2922.7	632.648
2925.32	635.258
2927.93	639.184
2930.54	639.548
2933.15	630.536
2935.76	617.967
2938.37	605.238
2940.98	589.07
2943.59	567.61
2946.2	543.795
2948.8	521.085
2951.41	496.407
2954.01	471.512
2956.62	445.779
2959.22	421.772
2961.82	395.417
2964.42	373.756
2967.02	350.619
2969.62	331.588
2972.22	317.223
2974.81	296.286
2977.41	277.535
2980	255.821
2982.6	235.824
2985.19	213.536
2987.78	189.032
2990.38	166.009
2992.97	147.394
2995.56	126.887
2998.14	108.814
3000.73	90.8054
3003.32	73.8679
3005.91	57.6127
3008.49	44.2993
3011.07	32.7472
3013.66	25.1656
3016.24	17.2258
3018.82	11.8922
3021.4	4.6879
3023.98	-0.37839
3026.56	-4.11213
3029.14	-3.93625
3031.71	-1.18727
3034.29	-0.142266
3036.87	-0.20615
3039.44	2.57485
3042.01	6.82133
3044.59	7.09523
3047.16	8.86578
3049.73	11.6547
3052.3	13.0338
3054.87	13.8105
3057.43	12.6161
3060	15.6176
3062.57	15.7405
3065.13	17.6895
3067.7	16.5553
3070.26	17.6606
3072.82	20.5294
3075.39	19.7739
3077.95	24.6651
3080.51	26.3338
3083.07	28.9556
3085.63	31.5871
3088.18	35.2471
3090.74	41.0005
3093.29	43.394
3095.85	46.9727
3098.4	49.654
3100.95	55.2976
3103.51	59.2322
3106.06	63.6745
3108.61	66.7023
3111.16	73.2086
3113.71	79.321
3116.25	85.6064
3118.8	88.828
3121.35	95.8933
3123.89	100.622
3126.44	106.838
3128.98	112.792
3131.52	118.352
3134.06	127.154
3136.6	132.247
3139.14	139.95
3141.68	145.215
3144.22	148.279
3146.76	149.168
3149.29	151.312