File: data/Raman/poly_smoothed/Mb_00_13_07_1x_45s_532 nm_x100_100%_600 gr_mm_01.txt
#Acq. time (s)=	45
#Accumulations=	2
#Range (cm-¹)=	200...3150
#Windows=	2
#Auto scanning=	Off
#Autofocus=	Off
#Macrospot=	Off
#AutoExposure=	Off
#Spike filter=	Multiple accum.
#Delay time (s)=	0
#Binning=	1
#Readout mode=	Signal
#DeNoise=	Off
#ICS correction=	On
#Dark correction=	Off
#Inst. Process=	Off
#Detector Gain=	Best Dynamic Range
#Detector ADC=	20 kHz
#Detector temperature (°C)=	-69.85
#Instrument=	LabRAM HR Evol
#Detector=	Synapse
#Objective=	x100
#Grating=	600 gr/mm
#ND Filter=	100%
#Laser (nm)=	532
#Hole=	100.021
#Range=	Auto
#Laser Pol.=	No
#Raman. Pol.=	No
#Laser Pol. (°)=	-0.0007625
#Raman Pol. (°)=	89.9995
#Collection=	Microscope
#StageXY=	Marzhauser
#StageZ=	Marzhauser
#X (µm)=	-987.9
#Y (µm)=	-2937.5
#Z (µm)=	527.85
#Full time(mm:ss)=	3:18
#Project=
#Sample=
#Site=
#Title=	Mb_00_13_07_2x_45s_532 nm_x100_100%_600 gr_mm
#Remark=
#Date=	06.07.2022 10:09
#Acquired=	06.07.2022 10:09:56
#Base:Fit=	10.08.2022 10:16:36
#Base:Fit=	10.08.2022 10:16:56
#Base:Sub=	10.08.2022 10:17:24
#Filter:Polynom=	16.08.2022 10:36:38
#AxisType[0]=Intens
#AxisUnit[0]=Cnt
#AxisType[1]=Spectr
#AxisUnit[1]=1/cm
200.398	18.0247
204.027	15.388
207.657	12.1609
211.283	10.5196
214.909	12.5549
218.533	18.2105
222.157	27.1168
225.777	35.9038
229.396	45.9624
233.016	54.3123
236.632	62.6541
240.247	67.5856
243.86	72.874
247.474	76.4865
251.085	80.7877
254.694	83.0051
258.301	87.693
261.908	89.7727
265.513	87.0181
269.116	85.0563
272.718	80.3944
276.319	73.288
279.918	66.451
283.516	56.6712
287.113	47.7412
290.708	40.962
294.302	35.2312
297.894	30.7794
301.485	29.3666
305.073	27.9786
308.661	27.0349
312.247	25.5492
315.833	24.4637
319.415	24.3961
322.997	23.7305
326.579	23.7752
330.156	22.2833
333.735	20.6439
337.31	19.4998
340.885	19.1651
344.458	18.2628
348.03	17.294
351.6	14.3322
355.17	10.5911
358.737	10.1459
362.304	9.44853
365.868	11.9456
369.431	12.7237
372.994	15.9274
376.554	19.6092
380.112	25.1072
383.669	33.3201
387.225	41.9028
390.781	50.2609
394.334	59.3042
397.885	65.5887
401.436	72.367
404.984	76.7697
408.532	78.4311
412.078	80.1537
415.623	79.1106
419.166	77.0985
422.708	74.394
426.248	71.0468
429.788	63.4108
433.326	55.283
436.86	47.8982
440.395	39.2011
443.929	32.3266
447.461	27.1835
450.99	20.6582
454.52	16.656
458.048	10.9367
461.573	9.23065
465.099	7.11586
468.623	7.26862
472.144	9.94007
475.666	10.7735
479.184	14.1169
482.703	16.3285
486.218	18.9265
489.734	19.5005
493.247	22.2893
496.759	25.6966
500.271	29.3573
503.779	31.3974
507.287	33.4985
510.795	34.7023
514.299	33.0828
517.803	33.8266
521.305	34.7048
524.805	34.4528
528.307	34.0666
531.805	32.4986
535.301	31.8581
538.797	30.2648
542.291	26.5155
545.783	23.6612
549.275	18.8263
552.765	14.9672
556.253	11.7136
559.738	10.1381
563.224	9.06688
566.709	8.37022
570.192	6.04717
573.674	4.52142
577.153	2.11993
580.632	2.87175
584.11	3.62884
587.587	3.48078
591.06	3.72155
594.534	3.75894
598.005	5.02482
601.476	6.10438
604.944	6.87747
608.413	6.88693
611.878	8.10329
615.344	7.59988
618.807	7.40058
622.27	8.78069
625.73	7.48789
629.189	7.86009
632.648	10.5674
636.105	12.2823
639.559	13.5977
643.013	14.4603
646.467	15.0151
649.918	15.6794
653.368	15.6824
656.816	13.5381
660.263	13.9458
663.708	16.1301
667.153	16.7619
670.596	16.6887
674.037	15.3748
677.478	15.9987
680.917	15.9236
684.355	15.344
687.791	15.0565
691.224	15.0715
694.658	12.7824
698.091	12.4146
701.522	11.9286
704.95	11.4567
708.379	12.6067
711.806	13.5087
715.23	17.3943
718.655	19.7058
722.078	19.2484
725.498	20.4001
728.919	22.0521
732.337	25.4112
735.755	26.8439
739.17	27.4665
742.584	29.547
745.998	33.9655
749.409	36.1151
752.819	39.0602
756.23	40.9709
759.637	44.1517
763.043	45.7221
766.448	48.7797
769.853	52.1852
773.255	52.8509
776.656	52.5681
780.056	54.3296
783.454	55.8378
786.851	57.8596
790.247	58.559
793.641	60.5544
797.034	60.381
800.426	62.6988
803.817	62.0725
807.206	61.2121
810.592	61.7826
813.979	61.0697
817.364	60.7841
820.748	60.048
824.129	61.5943
827.511	60.2754
830.891	60.6824
834.269	60.3063
837.646	60.0195
841.023	58.6483
844.396	57.3381
847.77	55.8979
851.141	53.9442
854.513	49.9053
857.881	47.6364
861.248	46.5923
864.616	45.2292
867.98	43.5319
871.343	42.0692
874.707	39.1567
878.068	36.9634
881.428	34.2826
884.786	32.2454
888.143	28.1572
891.498	26.7159
894.855	25.9693
898.208	24.0137
901.56	23.8697
904.91	23.5183
908.26	24.9106
911.608	25.5886
914.955	27.1347
918.298	27.1644
921.643	27.6036
924.986	27.6652
928.328	27.9229
931.668	28.8171
935.006	28.1159
938.344	29.3962
941.681	29.4803
945.014	30.9405
948.349	31.5323
951.682	31.4144
955.012	29.4782
958.343	26.8892
961.67	25.6088
964.998	28.4341
968.323	31.6533
971.649	32.3425
974.971	36.4524
978.293	40.1512
981.615	43.3806
984.933	47.4947
988.251	50.4797
991.567	51.9511
994.884	52.8349
998.198	52.5173
1001.51	52.3248
1004.82	52.7824
1008.13	51.5047
1011.44	51.4949
1014.75	55.1277
1018.06	59.1501
1021.36	64.1833
1024.66	72.0177
1027.97	79.2472
1031.27	82.9934
1034.57	85.7422
1037.87	88.1996
1041.16	92.4031
1044.46	95.0216
1047.76	97.3201
1051.05	96.3475
1054.34	94.477
1057.63	92.3032
1060.92	88.7016
1064.21	83.34
1067.5	77.1688
1070.78	67.9392
1074.07	59.3374
1077.35	51.6541
1080.63	43.1134
1083.91	33.995
1087.19	26.8958
1090.47	22.7034
1093.75	22.2596
1097.03	25.8507
1100.3	28.7933
1103.57	30.6965
1106.84	33
1110.11	31.5671
1113.38	29.4863
1116.65	27.2347
1119.92	27.153
1123.19	23.1235
1126.45	19.9767
1129.71	19.7149
1132.97	16.973
1136.23	17.0541
1139.49	14.842
1142.75	14.5381
1146.01	13.7112
1149.26	13.8067
1152.52	14.1483
1155.77	13.4322
1159.02	12.3167
1162.27	9.70317
1165.52	9.59827
1168.77	12.3395
1172.02	13.7273
1175.26	17.7393
1178.51	19.538
1181.75	19.2413
1184.99	23.0957
1188.23	24.0961
1191.47	24.5502
1194.71	28.3247
1197.94	32.7222
1201.18	34.4133
1204.41	36.9511
1207.65	41.8473
1210.88	46.8051
1214.11	50.9681
1217.34	57.9116
1220.57	63.9311
1223.79	69.7971
1227.02	74.9191
1230.24	77.335
1233.47	80.3706
1236.69	81.7949
1239.91	82.469
1243.13	85.4326
1246.34	86.7675
1249.56	87.2918
1252.78	87.6918
1255.99	87.5661
1259.2	87.6441
1262.42	87.8819
1265.63	88.7299
1268.84	88.4362
1272.04	89.3714
1275.25	88.5754
1278.46	89.6299
1281.66	91.6989
1284.86	93.8002
1288.07	95.5561
1291.27	97.2697
1294.47	99.685
1297.66	103.696
1300.86	105.689
1304.06	108.606
1307.25	109.972
1310.44	113.121
1313.64	116.756
1316.83	120.93
1320.02	122.496
1323.2	123.02
1326.39	125.814
1329.58	126.163
1332.76	124.366
1335.95	124.702
1339.13	123.681
1342.31	121.53
1345.49	121.082
1348.67	119.223
1351.85	115.306
1355.02	112.998
1358.2	109.068
1361.37	106.085
1364.54	101.515
1367.71	100.094
1370.88	96.4458
1374.05	93.1239
1377.22	92.0129
1380.39	89.3103
1383.55	87.4098
1386.72	87.1409
1389.88	85.0053
1393.04	84.1258
1396.2	83.0483
1399.36	79.92
1402.52	81.1327
1405.68	82.5805
1408.83	86.5793
1411.98	93.845
1415.14	103.504
1418.29	111.058
1421.44	120.558
1424.59	130.792
1427.74	140.033
1430.89	149.961
1434.03	158.966
1437.18	168.663
1440.32	174.949
1443.46	179.639
1446.6	180.785
1449.74	180.629
1452.88	179.727
1456.02	175.056
1459.16	167.715
1462.29	160.981
1465.43	150.038
1468.56	140.325
1471.69	127.548
1474.82	117.02
1477.95	106.582
1481.08	98.717
1484.2	92.9784
1487.33	86.1889
1490.46	80.5264
1493.58	74.5198
1496.7	70.6219
1499.82	68.341
1502.94	66.4153
1506.06	65.705
1509.18	65.1389
1512.29	65.185
1515.41	65.8749
1518.52	66.2344
1521.63	66.6876
1524.75	66.9875
1527.85	67.3266
1530.96	68.716
1534.07	68.6358
1537.18	68.0871
1540.28	70.3211
1543.39	70.5321
1546.49	72.6783
1549.59	74.2215
1552.69	76.7628
1555.79	77.4962
1558.89	79.3801
1561.99	81.7133
1565.08	83.2089
1568.18	84.8906
1571.27	87.7038
1574.37	90.5477
1577.46	94.6946
1580.55	97.8256
1583.64	99.769
1586.73	102.373
1589.81	104.163
1592.9	104.506
1595.98	105.977
1599.06	106.096
1602.15	106.372
1605.23	105.881
1608.31	105.493
1611.39	103.82
1614.46	103.173
1617.54	103.419
1620.61	103.165
1623.69	103.201
1626.76	103.823
1629.83	103.75
1632.9	105.73
1635.97	106.927
1639.04	109.89
1642.11	113.51
1645.17	112.384
1648.24	113.29
1651.3	116.522
1654.36	116.003
1657.42	115.443
1660.48	112.824
1663.54	110.859
1666.6	108.671
1669.66	105.288
1672.71	101.127
1675.77	95.8171
1678.82	89.2583
1681.87	81.5362
1684.92	73.4121
1687.97	67.5523
1691.02	59.3134
1694.07	51.9669
1697.11	45.7174
1700.16	38.2882
1703.2	33.878
1706.25	28.8682
1709.29	26.0918
1712.33	23.0482
1715.37	19.4515
1718.41	16.6099
1721.44	14.4141
1724.48	13.8974
1727.51	12.6877
1730.55	10.6637
1733.58	9.67403
1736.61	9.05601
1739.64	9.63256
1742.67	9.21002
1745.7	9.91726
1748.72	9.23157
1751.75	7.6877
1754.77	7.12118
1757.8	6.72982
1760.82	7.86788
1763.84	6.4039
1766.86	4.95488
1769.88	5.5335
1772.9	4.88741
1775.91	5.94658
1778.93	6.21558
1781.94	7.71479
1784.96	8.54889
1787.97	8.09224
1790.98	8.377
1793.99	9.38549
1797	8.70397
1800.01	9.37489
1803.01	8.69244
1806.02	8.35339
1809.02	8.43777
1812.02	8.64304
1815.02	9.4612
1818.03	9.79858
1821.02	10.14
1824.02	8.67177
1827.02	7.93852
1830.02	7.75074
1833.01	7.14344
1836.01	5.86518
1839	6.60638
1841.99	6.41497
1844.98	6.56915
1847.97	6.62462
1850.96	6.23907
1853.95	7.85222
1856.93	6.7918
1859.92	6.49338
1862.9	6.99258
1865.88	5.91843
1868.87	5.68409
1871.85	5.53714
1874.83	4.63301
1877.81	3.74521
1880.78	2.20685
1882.53	1.52568
1885.52	1.78681
1888.51	1.5198
1891.5	2.11411
1894.48	2.17021
1897.47	1.10802
1900.45	1.94028
1903.43	2.14755
1906.41	3.31528
1909.39	4.12087
1912.37	4.72268
1915.35	4.20939
1918.33	4.56715
1921.3	6.97738
1924.28	9.64249
1927.25	11.1918
1930.22	10.804
1933.19	11.3028
1936.16	11.5632
1939.13	11.2278
1942.1	12.7743
1945.07	11.2052
1948.03	11.3035
1951	8.67313
1953.96	8.12397
1956.92	7.06587
1959.88	6.12055
1962.84	5.51557
1965.8	5.38778
1968.76	4.31596
1971.72	2.40556
1974.67	1.53953
1977.63	0.127307
1980.58	0.225891
1983.54	-1.43624
1986.49	-1.01178
1989.44	-0.0667707
1992.39	1.71043
1995.33	1.97062
1998.28	4.23726
2001.23	4.61011
2004.17	3.3023
2007.12	4.6337
2010.06	5.66736
2013	5.06999
2015.94	4.25374
2018.88	4.89637
2021.82	4.1287
2024.76	3.5492
2027.69	4.88101
2030.63	6.57701
2033.56	6.19716
2036.5	6.95026
2039.43	7.41147
2042.36	7.06022
2045.29	7.50327
2048.22	9.77628
2051.15	9.34438
2054.07	8.74006
2057	10.1249
2059.92	11.8834
2062.85	11.9961
2065.77	12.5871
2068.69	13.6554
2071.61	12.6244
2074.53	12.4199
2077.45	11.7168
2080.37	11.8654
2083.28	10.5648
2086.2	9.85317
2089.11	9.88535
2092.02	8.40435
2094.94	8.60953
2097.85	9.57373
2100.76	9.5123
2103.66	8.60933
2106.57	7.61206
2109.48	7.99539
2112.38	6.54515
2115.29	7.13897
2118.19	8.36298
2121.09	7.97789
2123.99	7.85107
2126.89	7.29625
2129.79	7.874
2132.69	7.49607
2135.59	6.4424
2138.48	7.54903
2141.38	6.61402
2144.27	5.45905
2147.17	5.46549
2150.06	5.9421
2152.95	5.85751
2155.84	5.50137
2158.73	5.07672
2161.61	4.61586
2164.5	4.89036
2167.38	5.54339
2170.27	5.64808
2173.15	5.33358
2176.03	5.8672
2178.91	7.88302
2181.8	9.40128
2184.67	10.9103
2187.55	13.271
2190.43	12.9927
2193.3	12.7736
2196.18	12.4511
2199.05	13.8053
2201.93	13.1961
2204.8	12.32
2207.67	11.1903
2210.54	9.24454
2213.41	6.96456
2216.27	7.06383
2219.14	8.07821
2222.01	8.45811
2224.87	8.07342
2227.73	7.64677
2230.6	7.51305
2233.46	7.39006
2236.32	8.24827
2239.18	7.55103
2242.03	6.73153
2244.89	6.62447
2247.75	8.07703
2250.6	7.6955
2253.46	8.88933
2256.31	8.29991
2259.16	7.9093
2262.01	7.41684
2264.86	8.59866
2267.71	7.50641
2270.56	7.80851
2273.4	6.08562
2276.25	6.19306
2279.09	5.62304
2281.94	5.72159
2284.78	8.73058
2287.62	9.46221
2290.46	9.90264
2293.3	10.4486
2296.14	11.1248
2298.98	12.7831
2301.82	14.6074
2304.65	14.6947
2307.49	15.4611
2310.32	14.8967
2313.15	14.5591
2315.98	14.9411
2318.81	14.0589
2321.64	13.3916
2324.47	12.556
2327.3	11.0729
2330.12	10.0879
2332.95	9.23389
2335.77	8.55771
2338.6	7.01335
2341.42	5.53617
2344.24	4.49752
2347.06	4.1237
2349.88	2.09261
2352.7	1.99551
2355.51	0.332938
2358.33	0.415391
2361.14	0.537698
2363.96	2.14899
2366.77	3.5115
2369.58	4.03351
2372.39	3.26467
2375.2	2.55988
2378.01	2.79892
2380.82	2.62822
2383.63	4.8111
2386.43	4.57296
2389.24	5.50869
2392.04	5.77114
2394.84	6.30286
2397.65	7.18714
2400.45	7.90699
2403.25	8.39729
2406.05	8.06812
2408.84	7.73547
2411.64	7.33033
2414.44	7.79884
2417.23	7.97566
2420.02	8.31497
2422.82	10.5763
2425.61	10.7265
2428.4	11.4732
2431.19	10.91
2433.98	10.3562
2436.77	9.15663
2439.55	8.53029
2442.34	8.26032
2445.12	8.79201
2447.91	8.21098
2450.69	7.26781
2453.47	6.75474
2456.25	6.40698
2459.03	5.33412
2461.81	4.66768
2464.59	4.10754
2467.36	3.46153
2470.14	2.13261
2472.92	1.19259
2475.69	0.442501
2478.46	-0.0647609
2481.23	0.803815
2484	1.33025
2486.77	1.46972
2489.54	1.75616
2492.31	3.96173
2495.08	4.98806
2497.84	3.78157
2500.61	2.93151
2503.37	3.1177
2506.13	2.91478
2508.9	2.01926
2511.66	2.10449
2514.42	0.886968
2517.18	1.09229
2519.93	0.132219
2522.69	0.694784
2525.45	0.834095
2528.2	1.5873
2530.95	1.14755
2533.71	0.53169
2536.46	0.783639
2539.21	1.03064
2541.96	0.352084
2544.71	2.62702
2547.46	2.86498
2550.2	3.33419
2552.95	4.65498
2555.7	5.1399
2558.44	5.02353
2561.18	6.70109
2563.93	5.51711
2566.67	4.65495
2569.41	4.74929
2572.15	6.13
2574.88	4.83052
2577.62	5.12168
2580.36	4.97465
2583.09	4.35297
2585.83	4.00474
2588.56	3.77025
2591.29	5.03339
2594.02	5.83345
2596.75	6.72712
2599.48	6.98941
2602.21	9.23135
2604.94	10.3212
2607.67	9.95598
2610.39	11.818
2613.12	12.1507
2615.84	12.1474
2618.56	12.0046
2621.28	10.6618
2624.01	10.1581
2626.72	9.60068
2629.44	9.67246
2632.16	8.33768
2634.88	7.80839
2637.59	6.52801
2640.31	5.62483
2643.02	4.36659
2645.74	4.1373
2648.45	3.55143
2651.16	2.3424
2653.87	1.5116
2656.58	3.09109
2659.29	3.17615
2661.99	5.10789
2664.7	5.49123
2667.41	6.87816
2670.11	7.92675
2672.81	7.5547
2675.51	9.25672
2678.22	10.3135
2680.92	11.078
2683.62	12.271
2686.31	13.436
2689.01	14.5464
2691.71	15.2245
2694.4	15.1433
2697.1	15.0452
2699.79	15.2805
2702.49	16.1557
2705.18	17.0561
2707.87	17.9918
2710.56	18.8206
2713.25	20.0011
2715.94	20.2852
2718.62	19.4876
2721.31	20.4945
2723.99	21.3797
2726.68	21.5493
2729.36	21.9234
2732.04	20.2087
2734.73	19.6935
2737.41	18.4354
2740.08	18.1803
2742.76	17.9114
2745.44	17.7304
2748.12	17.3846
2750.79	17.4076
2753.47	16.271
2756.14	15.1877
2758.81	12.8756
2761.49	11.4058
2764.16	9.92578
2766.83	9.44893
2769.5	8.45528
2772.16	7.75594
2774.83	6.58506
2777.5	5.98634
2780.16	6.26036
2782.83	5.77123
2785.49	4.49964
2788.15	4.52002
2790.82	4.63551
2793.48	4.5694
2796.14	2.99283
2798.79	4.17991
2801.45	3.63127
2804.11	4.11915
2806.76	3.85883
2809.42	2.98251
2812.07	3.88134
2814.73	6.88712
2817.38	12.3182
2820.03	18.8017
2822.68	26.2749
2825.33	35.1696
2827.98	44.6835
2830.63	55.8029
2833.27	68.4429
2835.92	80.5527
2838.56	92.5252
2841.21	105.725
2843.85	120.408
2846.49	136.544
2849.13	154.988
2851.77	174.558
2854.41	194.71
2857.05	213.262
2859.69	229.803
2862.32	244.943
2864.96	256.619
2867.59	266.091
2870.23	274.944
2872.86	282.386
2875.49	288.411
2878.12	295.048
2880.75	299.883
2883.38	305.056
2886.01	307.624
2888.63	310.574
2891.26	311.786
2893.89	316.035
2896.51	319.112
2899.13	321.79
2901.76	326.739
2904.38	332.861
2907	342.57
2909.62	355.138
2912.24	370.001
2914.85	384.323
2917.47	397.373
2920.09	407.281
2922.7	414.985
2925.32	420.775
2927.93	422.788
2930.54	421.243
2933.15	418.122
2935.76	411.449
2938.37	401.367
2940.98	389.783
2943.59	377.192
2946.2	362.086
2948.8	345.571
2951.41	330.16
2954.01	313.91
2956.62	298.503
2959.22	283.872
2961.82	268.167
2964.42	253.661
2967.02	240.641
2969.62	229.393
2972.22	217.396
2974.81	205.911
2977.41	195.194
2980	183.103
2982.6	169.473
2985.19	156.017
2987.78	142.996
2990.38	131.336
2992.97	116.086
2995.56	102.911
2998.14	90.4809
3000.73	79.6272
3003.32	68.9062
3005.91	58.4871
3008.49	49.0005
3011.07	39.5565
3013.66	32.1582
3016.24	25.1763
3018.82	19.5195
3021.4	15.8572
3023.98	13.0539
3026.56	10.3487
3029.14	7.8379
3031.71	6.43624
3034.29	6.42652
3036.87	6.4619
3039.44	8.73054
3042.01	10.1858
3044.59	11.4528
3047.16	12.3156
3049.73	14.2941
3052.3	16.2803
3054.87	17.1579
3057.43	18.402
3060	19.1589
3062.57	19.1654
3065.13	18.2756
3067.7	17.3331
3070.26	14.9551
3072.82	12.6599
3075.39	10.2961
3077.95	9.13066
3080.51	6.95048
3083.07	6.12738
3085.63	5.28252
3088.18	3.83632
3090.74	2.2856
3093.29	1.93025
3095.85	2.45337
3098.4	4.61639
3100.95	5.80074
3103.51	6.28813
3106.06	7.62554
3108.61	9.21035
3111.16	11.3422
3113.71	12.97
3116.25	13.6134
3118.8	14.5511
3121.35	16.0978
3123.89	16.5541
3126.44	17.4096
3128.98	19.2999
3131.52	18.9657
3134.06	20.0297
3136.6	21.0857
3139.14	22.7
3141.68	24.5848
3144.22	26.6185
3146.76	28.905
3149.29	33.6877