File: data/Raman/poly_smoothed/Mb_00_13_01_1x_45s_532 nm_x100_100%_600 gr_mm_01.txt
#Acq. time (s)=	45
#Accumulations=	2
#Range (cm-¹)=	200...3150
#Windows=	2
#Auto scanning=	Off
#Autofocus=	Off
#Macrospot=	Off
#AutoExposure=	Off
#Spike filter=	Multiple accum.
#Delay time (s)=	0
#Binning=	1
#Readout mode=	Signal
#DeNoise=	Off
#ICS correction=	On
#Dark correction=	Off
#Inst. Process=	Off
#Detector Gain=	Best Dynamic Range
#Detector ADC=	20 kHz
#Detector temperature (°C)=	-69.85
#Instrument=	LabRAM HR Evol
#Detector=	Synapse
#Objective=	x100
#Grating=	600 gr/mm
#ND Filter=	100%
#Laser (nm)=	532
#Hole=	100.021
#Range=	Auto
#Laser Pol.=	No
#Raman. Pol.=	No
#Laser Pol. (°)=	-0.0007625
#Raman Pol. (°)=	89.9995
#Collection=	Microscope
#StageXY=	Marzhauser
#StageZ=	Marzhauser
#X (µm)=	-979.8
#Y (µm)=	-2944.6
#Z (µm)=	527.55
#Full time(mm:ss)=	3:19
#Project=
#Sample=
#Site=
#Title=	Mb_00_13_01_2x_45s_532 nm_x100_100%_600 gr_mm
#Remark=
#Date=	06.07.2022 09:46
#Acquired=	06.07.2022 09:46:24
#Base:Fit=	10.08.2022 10:16:36
#Base:Fit=	10.08.2022 10:16:56
#Base:Sub=	10.08.2022 10:17:24
#Filter:Polynom=	16.08.2022 10:36:38
#AxisType[0]=Intens
#AxisUnit[0]=Cnt
#AxisType[1]=Spectr
#AxisUnit[1]=1/cm
200.398	12.7819
204.027	9.5401
207.657	3.3528
211.283	-2.36496
214.909	-4.64555
218.533	-1.9117
222.157	5.12554
225.777	10.7627
229.396	16.7209
233.016	24.3515
236.632	32.0473
240.247	37.9407
243.86	42.7724
247.474	47.1765
251.085	53.2855
254.694	56.6663
258.301	59.6635
261.908	60.0639
265.513	60.1904
269.116	57.9749
272.718	54.6712
276.319	51.1273
279.918	45.3105
283.516	38.0298
287.113	30.3324
290.708	22.8833
294.302	16.8387
297.894	12.6828
301.485	9.13234
305.073	8.63326
308.661	6.31771
312.247	3.93384
315.833	3.73599
319.415	3.68333
322.997	4.81866
326.579	5.33215
330.156	3.71875
333.735	4.79998
337.31	3.82745
340.885	3.67351
344.458	1.43614
348.03	0.0907366
351.6	-0.0636156
355.17	-0.679741
358.737	-2.32264
362.304	-0.295553
365.868	1.58584
369.431	5.66618
372.994	7.73786
376.554	12.403
380.112	18.1669
383.669	27.193
387.225	35.3573
390.781	44.5669
394.334	53.4094
397.885	58.9905
401.436	66.821
404.984	70.4365
408.532	73.4318
412.078	75.0349
415.623	73.9074
419.166	71.6981
422.708	69.5695
426.248	64.3822
429.788	60.5572
433.326	53.8901
436.86	48.2234
440.395	41.7247
443.929	34.1984
447.461	27.9577
450.99	21.4317
454.52	16.6231
458.048	12.2118
461.573	7.61235
465.099	8.45479
468.623	9.29968
472.144	11.5175
475.666	12.1045
479.184	13.0956
482.703	15.0309
486.218	16.9205
489.734	18.8744
493.247	20.4358
496.759	24.7325
500.271	28.7894
503.779	32.8147
507.287	37.6612
510.795	40.7029
514.299	42.1395
517.803	45.3886
521.305	48.0293
524.805	48.8438
528.307	48.3381
531.805	46.8222
535.301	46.4952
538.797	45.5564
542.291	43.3931
545.783	40.9112
549.275	37.0599
552.765	34.8873
556.253	34.268
559.738	31.8207
563.224	29.8733
566.709	27.8229
570.192	25.2649
573.674	20.7383
577.153	19.2655
580.632	18.5906
584.11	19.604
587.587	19.9753
591.06	19.7836
594.534	19.651
598.005	18.1173
601.476	16.7239
604.944	18.1233
608.413	17.1563
611.878	17.4105
615.344	19.5997
618.807	18.5027
622.27	19.0848
625.73	21.0119
629.189	24.0215
632.648	28.1747
636.105	31.5058
639.559	36.2201
643.013	37.7141
646.467	37.6993
649.918	36.9791
653.368	35.5399
656.816	35.5891
660.263	36.0257
663.708	35.2787
667.153	35.3677
670.596	34.2367
674.037	32.6602
677.478	30.6313
680.917	28.9618
684.355	27.1025
687.791	27.0404
691.224	27.4745
694.658	27.2056
698.091	28.7628
701.522	27.1279
704.95	28.1039
708.379	30.7662
711.806	34.9472
715.23	37.1529
718.655	38.1785
722.078	39.5243
725.498	40.3503
728.919	40.1337
732.337	39.7474
735.755	38.5593
739.17	37.7012
742.584	39.2298
745.998	41.565
749.409	43.0327
752.819	45.7122
756.23	48.3124
759.637	50.5305
763.043	52.6134
766.448	54.6487
769.853	56.2205
773.255	57.2879
776.656	60.4947
780.056	62.4456
783.454	62.9025
786.851	65.6622
790.247	67.9814
793.641	70.4264
797.034	69.6627
800.426	69.5735
803.817	69.3512
807.206	67.9069
810.592	68.3556
813.979	69.024
817.364	68.0472
820.748	67.6953
824.129	70.3526
827.511	73.586
830.891	74.7951
834.269	73.2482
837.646	71.2065
841.023	68.9699
844.396	66.0604
847.77	62.808
851.141	58.0765
854.513	54.7932
857.881	52.2644
861.248	49.9205
864.616	47.4422
867.98	46.1534
871.343	43.6278
874.707	40.7923
878.068	38.676
881.428	37.0482
884.786	36.9739
888.143	36.4182
891.498	35.9157
894.855	37.171
898.208	35.5185
901.56	36.7197
904.91	36.5979
908.26	39.4928
911.608	40.661
914.955	42.2633
918.298	39.8981
921.643	40.3242
924.986	40.1994
928.328	40.2931
931.668	40.0459
935.006	39.5913
938.344	39.5038
941.681	40.0143
945.014	41.0243
948.349	39.7365
951.682	40.1395
955.012	36.4046
958.343	34.4545
961.67	31.478
964.998	32.7635
968.323	35.4367
971.649	35.7912
974.971	37.4619
978.293	41.8548
981.615	43.6837
984.933	45.753
988.251	48.183
991.567	51.2513
994.884	52.3575
998.198	55.9973
1001.51	56.5069
1004.82	57.5992
1008.13	59.2421
1011.44	58.6081
1014.75	60.9179
1018.06	63.4765
1021.36	69.5808
1024.66	76.174
1027.97	80.632
1031.27	84.7804
1034.57	85.6186
1037.87	84.4959
1041.16	85.8723
1044.46	89.2726
1047.76	91.2151
1051.05	91.7152
1054.34	88.7792
1057.63	84.7434
1060.92	81.1233
1064.21	73.3813
1067.5	66.5793
1070.78	58.816
1074.07	49.2859
1077.35	41.7986
1080.63	34.0453
1083.91	23.8105
1087.19	17.1631
1090.47	12.6067
1093.75	11.3776
1097.03	13.1052
1100.3	14.9279
1103.57	17.1215
1106.84	18.593
1110.11	17.5853
1113.38	16.3134
1116.65	14.3141
1119.92	13.1124
1123.19	12.4834
1126.45	12.0848
1129.71	12.6901
1132.97	11.264
1136.23	12.1157
1139.49	12.9899
1142.75	11.9007
1146.01	12.4512
1149.26	11.2462
1152.52	10.3483
1155.77	11.6866
1159.02	12.4686
1162.27	10.942
1165.52	12.2389
1168.77	13.0973
1172.02	16.2912
1175.26	17.2318
1178.51	17.505
1181.75	17.5913
1184.99	18.7011
1188.23	19.466
1191.47	19.1411
1194.71	20.2973
1197.94	22.8885
1201.18	27.643
1204.41	31.6674
1207.65	37.4688
1210.88	40.9809
1214.11	46.1491
1217.34	51.0713
1220.57	55.5255
1223.79	60.8246
1227.02	63.6092
1230.24	67.5883
1233.47	70.4589
1236.69	74.1759
1239.91	76.5617
1243.13	78.5165
1246.34	79.2085
1249.56	79.4548
1252.78	77.7861
1255.99	76.8034
1259.2	75.3316
1262.42	73.0632
1265.63	73.0155
1268.84	71.9147
1272.04	73.5618
1275.25	72.6539
1278.46	74.3483
1281.66	76.1899
1284.86	77.2982
1288.07	78.3426
1291.27	79.0053
1294.47	83.7999
1297.66	88.0697
1300.86	91.325
1304.06	95.6681
1307.25	99.4825
1310.44	102.352
1313.64	107.52
1316.83	110.518
1320.02	114.75
1323.2	114.993
1326.39	115.522
1329.58	113.95
1332.76	112.991
1335.95	112.617
1339.13	110.279
1342.31	107.621
1345.49	104.068
1348.67	99.5418
1351.85	96.3143
1355.02	92.7854
1358.2	88.9625
1361.37	85.6142
1364.54	80.8837
1367.71	77.7716
1370.88	74.3624
1374.05	71.1264
1377.22	67.8821
1380.39	66.2682
1383.55	65.7249
1386.72	62.9533
1389.88	63.6671
1393.04	64.9117
1396.2	64.5744
1399.36	64.584
1402.52	66.1206
1405.68	67.0552
1408.83	72.8922
1411.98	79.7429
1415.14	85.9366
1418.29	93.4026
1421.44	104.106
1424.59	114.596
1427.74	126.859
1430.89	138.172
1434.03	148.025
1437.18	158.025
1440.32	163.262
1443.46	169.101
1446.6	171.322
1449.74	171.167
1452.88	171.946
1456.02	167.265
1459.16	160.691
1462.29	153.948
1465.43	145.071
1468.56	134.007
1471.69	120.457
1474.82	106.475
1477.95	94.409
1481.08	84.2598
1484.2	75.7108
1487.33	66.8043
1490.46	62.5146
1493.58	57.1872
1496.7	55.044
1499.82	52.631
1502.94	50.2321
1506.06	49.1331
1509.18	49.7444
1512.29	48.929
1515.41	49.2978
1518.52	49.0247
1521.63	49.2193
1524.75	51.1101
1527.85	53.2637
1530.96	53.1736
1534.07	55.1228
1537.18	55.2102
1540.28	55.7272
1543.39	57.9172
1546.49	57.4871
1549.59	59.6456
1552.69	62.0574
1555.79	66.5039
1558.89	68.6047
1561.99	71.3123
1565.08	74.3908
1568.18	79.7469
1571.27	81.0129
1574.37	80.5319
1577.46	84.4933
1580.55	88.3308
1583.64	92.8753
1586.73	97.4723
1589.81	101.498
1592.9	104.704
1595.98	107.545
1599.06	111.035
1602.15	112.638
1605.23	113.601
1608.31	114.42
1611.39	113.4
1614.46	113.511
1617.54	115.841
1620.61	118.695
1623.69	121.27
1626.76	125.234
1629.83	128.578
1632.9	130.897
1635.97	135.075
1639.04	140.075
1642.11	144.232
1645.17	149.098
1648.24	150.848
1651.3	154.622
1654.36	158.217
1657.42	161.911
1660.48	164.669
1663.54	163.501
1666.6	161.91
1669.66	157.663
1672.71	152.077
1675.77	144.683
1678.82	135.747
1681.87	127.243
1684.92	118.508
1687.97	109.34
1691.02	102.727
1694.07	95.2776
1697.11	90.1056
1700.16	83.7373
1703.2	78.2774
1706.25	72.6863
1709.29	66.9697
1712.33	63.9626
1715.37	60.1615
1718.41	56.8383
1721.44	54.6542
1724.48	52.5104
1727.51	50.8873
1730.55	51.6742
1733.58	50.4123
1736.61	50.989
1739.64	49.2114
1742.67	46.7541
1745.7	44.927
1748.72	43.2827
1751.75	42.4684
1754.77	42.0576
1757.8	41.8819
1760.82	41.365
1763.84	40.7866
1766.86	39.5653
1769.88	38.7959
1772.9	37.9249
1775.91	35.2734
1778.93	33.9073
1781.94	31.7595
1784.96	30.5299
1787.97	28.31
1790.98	27.2957
1793.99	28.0412
1797	27.6035
1800.01	25.8978
1803.01	24.7189
1806.02	24.2338
1809.02	23.6693
1812.02	22.2292
1815.02	20.4013
1818.03	19.4567
1821.02	19.8436
1824.02	19.7835
1827.02	20.7223
1830.02	19.7285
1833.01	19.5786
1836.01	19.2772
1839	17.7724
1841.99	17.5872
1844.98	17.0182
1847.97	17.2503
1850.96	16.0776
1853.95	14.6696
1856.93	14.5616
1859.92	12.9174
1862.9	11.5806
1865.88	11.7836
1868.87	9.06057
1871.85	8.30538
1874.83	6.49715
1877.81	5.59331
1880.78	4.36607
1882.53	4.61592
1885.52	4.69506
1888.51	5.53477
1891.5	5.46232
1894.48	7.06486
1897.47	9.12853
1900.45	9.51848
1903.43	10.0264
1906.41	11.9298
1909.39	12.783
1912.37	12.8275
1915.35	14.4097
1918.33	13.6458
1921.3	12.1078
1924.28	10.6384
1927.25	9.64602
1930.22	8.83138
1933.19	7.13807
1936.16	5.53194
1939.13	4.65888
1942.1	4.52731
1945.07	2.21679
1948.03	0.859026
1951	0.471273
1953.96	-0.200724
1956.92	0.260107
1959.88	0.188025
1962.84	0.399789
1965.8	2.3976
1968.76	2.92994
1971.72	2.79129
1974.67	4.25046
1977.63	6.91222
1980.58	6.639
1983.54	6.67095
1986.49	6.87079
1989.44	8.48563
1992.39	9.1794
1995.33	9.85375
1998.28	10.4106
2001.23	12.2442
2004.17	13.4125
2007.12	15.0612
2010.06	16.1975
2013	16.5908
2015.94	15.7314
2018.88	16.431
2021.82	16.3888
2024.76	16.9094
2027.69	17.6861
2030.63	18.8901
2033.56	18.6213
2036.5	18.5771
2039.43	18.238
2042.36	19.0429
2045.29	18.3876
2048.22	18.064
2051.15	16.168
2054.07	15.3263
2057	14.1458
2059.92	14.0001
2062.85	15.1341
2065.77	14.4537
2068.69	14.6289
2071.61	14.6236
2074.53	13.7844
2077.45	13.3355
2080.37	12.3545
2083.28	12.0165
2086.2	12.5717
2089.11	13.6388
2092.02	14.6104
2094.94	16.0071
2097.85	18.4901
2100.76	19.4559
2103.66	19.0327
2106.57	18.7344
2109.48	19.0739
2112.38	17.0242
2115.29	16.9936
2118.19	15.3906
2121.09	13.8952
2123.99	11.6971
2126.89	10.3276
2129.79	10.2321
2132.69	10.1658
2135.59	9.55385
2138.48	8.08743
2141.38	7.29961
2144.27	8.44273
2147.17	7.33476
2150.06	8.02619
2152.95	7.75982
2155.84	8.5071
2158.73	8.13916
2161.61	8.6902
2164.5	7.70194
2167.38	9.555
2170.27	11.0014
2173.15	12.3465
2176.03	11.7531
2178.91	12.527
2181.8	12.205
2184.67	12.1363
2187.55	12.9336
2190.43	13.0364
2193.3	11.8861
2196.18	11.132
2199.05	12.805
2201.93	13.4045
2204.8	13.7271
2207.67	15.1327
2210.54	14.6707
2213.41	16.397
2216.27	16.1381
2219.14	16.7058
2222.01	15.8342
2224.87	14.3064
2227.73	13.3729
2230.6	13.2485
2233.46	13.3577
2236.32	14.2053
2239.18	15.2674
2242.03	15.8716
2244.89	15.8337
2247.75	15.9101
2250.6	15.4749
2253.46	14.8988
2256.31	14.317
2259.16	12.1567
2262.01	10.9621
2264.86	10.5323
2267.71	10.384
2270.56	10.1326
2273.4	10.0648
2276.25	9.53103
2279.09	9.49156
2281.94	9.35554
2284.78	8.9015
2287.62	7.83057
2290.46	5.50878
2293.3	5.52799
2296.14	5.92014
2298.98	7.1654
2301.82	8.01322
2304.65	8.09555
2307.49	7.44031
2310.32	8.52977
2313.15	9.74117
2315.98	9.83546
2318.81	9.77467
2321.64	9.95105
2324.47	9.8139
2327.3	10.3121
2330.12	10.6874
2332.95	11.8607
2335.77	11.9309
2338.6	12.9307
2341.42	12.3257
2344.24	11.1836
2347.06	10.4992
2349.88	10.0466
2352.7	9.33607
2355.51	7.6404
2358.33	7.25681
2361.14	7.26978
2363.96	7.6822
2366.77	7.05532
2369.58	6.50614
2372.39	5.32931
2375.2	5.06696
2378.01	6.08235
2380.82	5.53977
2383.63	6.91
2386.43	6.12623
2389.24	6.80596
2392.04	5.42006
2394.84	5.33047
2397.65	4.03687
2400.45	4.6968
2403.25	4.67651
2406.05	4.48945
2408.84	3.79681
2411.64	3.77588
2414.44	4.87832
2417.23	6.18604
2420.02	7.23221
2422.82	7.00002
2425.61	8.46584
2428.4	8.07225
2431.19	8.55119
2433.98	8.31019
2436.77	8.10353
2439.55	7.5341
2442.34	7.30221
2445.12	7.19941
2447.91	6.0852
2450.69	5.9325
2453.47	4.12704
2456.25	2.76198
2459.03	1.23892
2461.81	1.44972
2464.59	-0.60933
2467.36	0.678488
2470.14	0.0296362
2472.92	-1.08764
2475.69	-1.06546
2478.46	-0.375282
2481.23	1.16941
2484	1.36928
2486.77	1.87237
2489.54	2.34651
2492.31	2.66553
2495.08	4.30336
2497.84	4.9145
2500.61	4.95255
2503.37	3.03136
2506.13	3.9308
2508.9	3.52711
2511.66	2.41222
2514.42	3.2446
2517.18	2.46061
2519.93	1.67545
2522.69	2.39871
2525.45	1.12745
2528.2	1.02384
2530.95	-0.120601
2533.71	0.759983
2536.46	1.76149
2539.21	0.871247
2541.96	1.63831
2544.71	0.688326
2547.46	1.18765
2550.2	1.97411
2552.95	3.09635
2555.7	4.67219
2558.44	5.35069
2561.18	7.47368
2563.93	8.60518
2566.67	8.15302
2569.41	8.9514
2572.15	10.0271
2574.88	11.4207
2577.62	11.2102
2580.36	11.3697
2583.09	10.5461
2585.83	10.632
2588.56	9.93545
2591.29	9.9531
2594.02	8.93619
2596.75	9.34029
2599.48	9.55197
2602.21	9.66553
2604.94	7.59579
2607.67	5.42683
2610.39	5.21585
2613.12	4.69122
2615.84	6.13821
2618.56	6.52857
2621.28	6.93575
2624.01	7.33302
2626.72	7.18129
2629.44	6.54155
2632.16	7.2901
2634.88	8.87807
2637.59	8.67946
2640.31	10.0344
2643.02	10.2107
2645.74	9.89219
2648.45	9.42544
2651.16	9.91238
2653.87	9.81078
2656.58	11.2635
2659.29	11.768
2661.99	11.068
2664.7	12.5927
2667.41	11.1643
2670.11	9.63013
2672.81	7.67977
2675.51	7.39234
2678.22	8.0076
2680.92	7.95672
2683.62	8.53246
2686.31	8.19019
2689.01	7.79399
2691.71	7.45753
2694.4	7.16434
2697.1	8.4132
2699.79	10.3129
2702.49	11.8682
2705.18	12.3678
2707.87	12.874
2710.56	15.1675
2713.25	15.9268
2715.94	17.0318
2718.62	18.566
2721.31	18.2686
2723.99	18.6908
2726.68	19.6134
2729.36	18.995
2732.04	18.5631
2734.73	17.7046
2737.41	16.1122
2740.08	15.6591
2742.76	14.5555
2745.44	12.7801
2748.12	11.7677
2750.79	9.66133
2753.47	7.34686
2756.14	7.71914
2758.81	6.58325
2761.49	6.39496
2764.16	4.98052
2766.83	4.55854
2769.5	3.15326
2772.16	2.50692
2774.83	2.11205
2777.5	1.99809
2780.16	1.19725
2782.83	1.99306
2785.49	1.23789
2788.15	0.627754
2790.82	0.727232
2793.48	0.660626
2796.14	1.17798
2798.79	1.17632
2801.45	-0.0891504
2804.11	-1.49674
2806.76	-1.59357
2809.42	-3.27158
2812.07	-3.20514
2814.73	-2.19646
2817.38	-0.259784
2820.03	2.93961
2822.68	7.81441
2825.33	11.6436
2827.98	17.5888
2830.63	24.9054
2833.27	32.9181
2835.92	41.5053
2838.56	52.9806
2841.21	66.2931
2843.85	81.0611
2846.49	98.3527
2849.13	116.559
2851.77	135.884
2854.41	155.28
2857.05	174.262
2859.69	191.795
2862.32	208.707
2864.96	223.249
2867.59	236.506
2870.23	249.515
2872.86	261.904
2875.49	270.262
2878.12	278.425
2880.75	285.817
2883.38	291.918
2886.01	298.656
2888.63	304.616
2891.26	310.532
2893.89	318.136
2896.51	326.196
2899.13	334.106
2901.76	344.982
2904.38	360.134
2907	376.184
2909.62	396.022
2912.24	416.035
2914.85	435.417
2917.47	452.6
2920.09	467.638
2922.7	480.126
2925.32	488.241
2927.93	492.755
2930.54	494.538
2933.15	493.864
2935.76	487.17
2938.37	476.481
2940.98	462.213
2943.59	447.744
2946.2	430.705
2948.8	413.138
2951.41	395.999
2954.01	377.595
2956.62	358.4
2959.22	339.001
2961.82	317.939
2964.42	300.671
2967.02	284.496
2969.62	271.57
2972.22	258.636
2974.81	245.117
2977.41	229.649
2980	214.889
2982.6	198.911
2985.19	183.364
2987.78	165.78
2990.38	149.47
2992.97	133.178
2995.56	117.238
2998.14	102.874
3000.73	87.4875
3003.32	75.0719
3005.91	62.7447
3008.49	51.7711
3011.07	41.6014
3013.66	34.5418
3016.24	27.2868
3018.82	20.4848
3021.4	15.8086
3023.98	12.0446
3026.56	8.84139
3029.14	7.63902
3031.71	7.45605
3034.29	7.26473
3036.87	6.59504
3039.44	6.66959
3042.01	7.28595
3044.59	6.93855
3047.16	7.43968
3049.73	8.63097
3052.3	8.93191
3054.87	8.21091
3057.43	7.74714
3060	7.52705
3062.57	7.57058
3065.13	6.38727
3067.7	5.28156
3070.26	4.09798
3072.82	2.73116
3075.39	2.31274
3077.95	0.754694
3080.51	0.392563
3083.07	0.288961
3085.63	-0.15478
3088.18	-2.07795
3090.74	-1.63535
3093.29	-0.768068
3095.85	-0.54885
3098.4	0.206114
3100.95	1.28691
3103.51	2.13149
3106.06	3.46553
3108.61	4.01341
3111.16	5.18969
3113.71	7.22563
3116.25	8.77604
3118.8	10.2125
3121.35	12.4901
3123.89	15.17
3126.44	18.3239
3128.98	20.9135
3131.52	23.7869
3134.06	26.9351
3136.6	30.9445
3139.14	33.5202
3141.68	36.5753
3144.22	39.0854
3146.76	41.8508
3149.29	45.3598