File: data/Raman/poly_smoothed/Mb_00_13_48_1x_45s_532 nm_x100_100%_600 gr_mm_01.txt
#Acq. time (s)=	45
#Accumulations=	2
#Range (cm-¹)=	200...3150
#Windows=	2
#Auto scanning=	Off
#Autofocus=	Off
#Macrospot=	Off
#AutoExposure=	Off
#Spike filter=	Multiple accum.
#Delay time (s)=	0
#Binning=	1
#Readout mode=	Signal
#DeNoise=	Off
#ICS correction=	On
#Dark correction=	Off
#Inst. Process=	Off
#Detector Gain=	Best Dynamic Range
#Detector ADC=	20 kHz
#Detector temperature (°C)=	-69.85
#Instrument=	LabRAM HR Evol
#Detector=	Synapse
#Objective=	x100
#Grating=	600 gr/mm
#ND Filter=	100%
#Laser (nm)=	532
#Hole=	100.021
#Range=	Auto
#Laser Pol.=	No
#Raman. Pol.=	No
#Laser Pol. (°)=	-0.0007625
#Raman Pol. (°)=	89.9995
#Collection=	Microscope
#StageXY=	Marzhauser
#StageZ=	Marzhauser
#X (µm)=	-1056.9
#Y (µm)=	-2874.6
#Z (µm)=	528.35
#Full time(mm:ss)=	3:18
#Project=
#Sample=
#Site=
#Title=	Mb_00_13_48_2x_45s_532 nm_x100_100%_600 gr_mm
#Remark=
#Date=	06.07.2022 13:39
#Acquired=	06.07.2022 13:39:38
#Base:Fit=	10.08.2022 10:16:56
#Base:Sub=	10.08.2022 10:17:24
#Filter:Polynom=	16.08.2022 10:36:38
#AxisType[0]=Intens
#AxisUnit[0]=Cnt
#AxisType[1]=Spectr
#AxisUnit[1]=1/cm
200.398	20.5047
204.027	6.49106
207.657	-3.08526
211.283	-8.41665
214.909	-7.05984
218.533	1.89137
222.157	18.0811
225.777	37.9197
229.396	59.4778
233.016	80.9638
236.632	100.685
240.247	115.18
243.86	128.864
247.474	140.957
251.085	152.346
254.694	160.034
258.301	163.791
261.908	164.133
265.513	162.892
269.116	156.791
272.718	148.846
276.319	135.922
279.918	121.912
283.516	103.083
287.113	85.1558
290.708	71.0725
294.302	55.6317
297.894	42.656
301.485	36.1388
305.073	30.9503
308.661	29.1942
312.247	29.5435
315.833	30.9038
319.415	32.6084
322.997	31.9671
326.579	32.0887
330.156	30.9498
333.735	28.0428
337.31	24.7371
340.885	22.6606
344.458	19.3176
348.03	16.6633
351.6	15.232
355.17	12.3479
358.737	9.93642
362.304	11.2717
365.868	15.5988
369.431	21.8326
372.994	29.6116
376.554	40.7682
380.112	52.5133
383.669	69.1474
387.225	91.158
390.781	113.89
394.334	133.211
397.885	151.348
401.436	165.259
404.984	174.474
408.532	179.767
412.078	181.048
415.623	180.894
419.166	174.738
422.708	166.814
426.248	156.244
429.788	141.28
433.326	125.074
436.86	105.981
440.395	87.7364
443.929	68.2613
447.461	51.0146
450.99	37.9156
454.52	26.9654
458.048	15.5119
461.573	7.76432
465.099	4.55016
468.623	6.12299
472.144	10.9682
475.666	11.797
479.184	13.9081
482.703	16.1276
486.218	19.5818
489.734	22.9833
493.247	28.5316
496.759	34.085
500.271	39.3038
503.779	43.2832
507.287	47.6378
510.795	52.4261
514.299	57.5125
517.803	60.7503
521.305	63.6084
524.805	64.553
528.307	66.2425
531.805	63.5784
535.301	63.7612
538.797	62.7016
542.291	60.7211
545.783	57.1324
549.275	54.0159
552.765	48.3028
556.253	42.9842
559.738	39.0141
563.224	33.4113
566.709	32.2422
570.192	29.5733
573.674	27.364
577.153	24.6615
580.632	23.6623
584.11	23.4131
587.587	22.4692
591.06	22.0573
594.534	20.9302
598.005	20.2424
601.476	20.086
604.944	19.0844
608.413	21.0823
611.878	21.2601
615.344	20.7826
618.807	20.3849
622.27	21.4576
625.73	21.5949
629.189	24.3252
632.648	27.4348
636.105	32.9178
639.559	38.1478
643.013	41.0437
646.467	43.9865
649.918	46.7741
653.368	47.9721
656.816	47.2172
660.263	45.6196
663.708	43.9926
667.153	43.8289
670.596	40.6259
674.037	35.5622
677.478	32.2852
680.917	25.5491
684.355	20.805
687.791	17.8319
691.224	16.3438
694.658	14.0723
698.091	8.88189
701.522	4.53457
704.95	1.95529
708.379	0.49477
711.806	1.14301
715.23	4.36124
718.655	6.16558
722.078	9.84215
725.498	12.2239
728.919	14.5316
732.337	17.8191
735.755	19.8513
739.17	22.5107
742.584	26.1619
745.998	29.8312
749.409	35.5864
752.819	40.4953
756.23	43.6009
759.637	46.8536
763.043	48.8005
766.448	51.3467
769.853	55.8206
773.255	60.168
776.656	62.3508
780.056	63.984
783.454	62.7723
786.851	64.5914
790.247	63.7324
793.641	63.4202
797.034	63.7965
800.426	67.5448
803.817	67.2706
807.206	67.0424
810.592	64.3656
813.979	63.0303
817.364	63.0415
820.748	60.939
824.129	62.1113
827.511	60.0824
830.891	60.4691
834.269	59.0519
837.646	55.6681
841.023	52.644
844.396	48.1264
847.77	44.1292
851.141	40.8976
854.513	38.7244
857.881	35.938
861.248	31.0461
864.616	28.2634
867.98	27.6762
871.343	23.5174
874.707	21.4662
878.068	22.4422
881.428	21.6013
884.786	19.6722
888.143	17.0425
891.498	15.1931
894.855	15.9669
898.208	18.0379
901.56	16.4036
904.91	19.2469
908.26	21.1158
911.608	23.5751
914.955	24.9704
918.298	27.0814
921.643	28.639
924.986	29.999
928.328	30.2239
931.668	31.9928
935.006	29.7945
938.344	28.8491
941.681	26.169
945.014	24.0414
948.349	21.6352
951.682	21.0352
955.012	16.2271
958.343	11.4947
961.67	9.12171
964.998	7.77556
968.323	7.58364
971.649	9.5863
974.971	11.9013
978.293	13.8428
981.615	14.0539
984.933	16.944
988.251	18.8223
991.567	20.5997
994.884	25.7278
998.198	28.729
1001.51	35.384
1004.82	40.3582
1008.13	42.8473
1011.44	43.6933
1014.75	47.8063
1018.06	54.9483
1021.36	67.4681
1024.66	85.0305
1027.97	102.121
1031.27	118.729
1034.57	132.389
1037.87	143.646
1041.16	153.357
1044.46	163.131
1047.76	169.601
1051.05	172.441
1054.34	171.12
1057.63	165.702
1060.92	157.688
1064.21	148.048
1067.5	135.71
1070.78	123.855
1074.07	110.671
1077.35	94.0308
1080.63	76.7054
1083.91	61.1882
1087.19	42.6282
1090.47	26.0715
1093.75	16.8671
1097.03	14.7038
1100.3	16.7061
1103.57	19.328
1106.84	20.0839
1110.11	17.9188
1113.38	17.1418
1116.65	16.7781
1119.92	15.3125
1123.19	12.3862
1126.45	11.5451
1129.71	11.8147
1132.97	11.5978
1136.23	9.37137
1139.49	9.7055
1142.75	7.97825
1146.01	7.70357
1149.26	6.7824
1152.52	5.62252
1155.77	4.11577
1159.02	2.06866
1162.27	1.36696
1165.52	1.96763
1168.77	3.41788
1172.02	7.19147
1175.26	12.1717
1178.51	15.9383
1181.75	20.1735
1184.99	23.353
1188.23	27.2523
1191.47	31.4291
1194.71	38.0078
1197.94	41.7075
1201.18	47.3233
1204.41	51.3182
1207.65	58.1293
1210.88	63.7567
1214.11	67.7492
1217.34	73.7081
1220.57	78.6301
1223.79	81.5301
1227.02	84.7306
1230.24	87.458
1233.47	89.108
1236.69	90.905
1239.91	91.7839
1243.13	93.1182
1246.34	94.4418
1249.56	96.2612
1252.78	95.6001
1255.99	96.4697
1259.2	96.0195
1262.42	94.0157
1265.63	91.3064
1268.84	91.6685
1272.04	91.2633
1275.25	92.6402
1278.46	92.6738
1281.66	95.537
1284.86	95.2708
1288.07	97.9712
1291.27	100.589
1294.47	103.849
1297.66	108.128
1300.86	112.518
1304.06	116.496
1307.25	120.852
1310.44	122.785
1313.64	125.296
1316.83	127.439
1320.02	127.166
1323.2	126.995
1326.39	129.727
1329.58	130.143
1332.76	129.467
1335.95	128.628
1339.13	124.683
1342.31	123.183
1345.49	116.402
1348.67	115.182
1351.85	115.1
1355.02	113.844
1358.2	110.527
1361.37	106.374
1364.54	101.86
1367.71	100.035
1370.88	95.5987
1374.05	95.2172
1377.22	93.0312
1380.39	90.9922
1383.55	88.4151
1386.72	86.8952
1389.88	85.0912
1393.04	83.0142
1396.2	81.8341
1399.36	79.7687
1402.52	82.289
1405.68	86.7864
1408.83	88.213
1411.98	94.0607
1415.14	99.4615
1418.29	108.016
1421.44	118.624
1424.59	132.146
1427.74	147.896
1430.89	162.059
1434.03	173.433
1437.18	183.94
1440.32	192.138
1443.46	198.921
1446.6	203.079
1449.74	203.282
1452.88	201.57
1456.02	197.622
1459.16	193.437
1462.29	183.406
1465.43	172.276
1468.56	158.758
1471.69	144.365
1474.82	129.973
1477.95	118.33
1481.08	103.589
1484.2	91.6997
1487.33	81.9159
1490.46	71.4582
1493.58	62.5529
1496.7	55.4577
1499.82	49.8746
1502.94	46.6263
1506.06	45.2255
1509.18	45.01
1512.29	42.455
1515.41	41.9
1518.52	42.6696
1521.63	41.9791
1524.75	42.5199
1527.85	44.4001
1530.96	46.7625
1534.07	50.6887
1537.18	53.6573
1540.28	55.4286
1543.39	59.0931
1546.49	60.7656
1549.59	64.8433
1552.69	69.058
1555.79	71.1714
1558.89	72.4705
1561.99	73.0511
1565.08	75.181
1568.18	76.4922
1571.27	80.9864
1574.37	83.6336
1577.46	85.5843
1580.55	91.6825
1583.64	95.3366
1586.73	95.7748
1589.81	100.327
1592.9	102.876
1595.98	101.961
1599.06	100.466
1602.15	101.853
1605.23	100.674
1608.31	100.974
1611.39	100.857
1614.46	99.8317
1617.54	98.1595
1620.61	95.2946
1623.69	95.7298
1626.76	94.2051
1629.83	92.454
1632.9	90.048
1635.97	90.7255
1639.04	91.2588
1642.11	93.7934
1645.17	95.3356
1648.24	97.0768
1651.3	97.6197
1654.36	99.7263
1657.42	100.458
1660.48	97.8419
1663.54	95.6044
1666.6	92.9156
1669.66	90.5004
1672.71	84.961
1675.77	80.4799
1678.82	75.9106
1681.87	69.0016
1684.92	64.2314
1687.97	58.4314
1691.02	51.5526
1694.07	45.1858
1697.11	40.0308
1700.16	36.3311
1703.2	31.3554
1706.25	26.2342
1709.29	23.4908
1712.33	20.9147
1715.37	18.5627
1718.41	16.5543
1721.44	14.3964
1724.48	15.757
1727.51	13.2321
1730.55	10.8027
1733.58	9.65696
1736.61	8.57583
1739.64	6.39982
1742.67	6.63859
1745.7	5.02559
1748.72	2.02906
1751.75	1.70095
1754.77	1.53372
1757.8	0.583951
1760.82	1.09872
1763.84	1.08682
1766.86	0.0146918
1769.88	1.10381
1772.9	1.10465
1775.91	1.77485
1778.93	1.93756
1781.94	2.07252
1784.96	3.74234
1787.97	5.47531
1790.98	4.8827
1793.99	4.68715
1797	5.98049
1800.01	6.6021
1803.01	4.85847
1806.02	4.30211
1809.02	3.43393
1812.02	1.87715
1815.02	2.8
1818.03	3.54866
1821.02	2.99144
1824.02	3.05619
1827.02	3.3538
1830.02	3.02932
1833.01	4.22242
1836.01	5.64366
1839	6.4428
1841.99	7.26961
1844.98	9.54733
1847.97	12.1851
1850.96	11.9663
1853.95	12.9808
1856.93	12.7879
1859.92	13.6108
1862.9	13.5619
1865.88	13.862
1868.87	13.265
1871.85	13.8817
1874.83	12.7363
1877.81	10.4067
1880.78	11.823
1882.53	11.337
1885.52	11.6916
1888.51	11.5423
1891.5	10.975
1894.48	10.4099
1897.47	10.5722
1900.45	9.57523
1903.43	11.0978
1906.41	12.4934
1909.39	11.4015
1912.37	11.6373
1915.35	10.3248
1918.33	10.4289
1921.3	9.03486
1924.28	8.46364
1927.25	9.5823
1930.22	11.3649
1933.19	10.5936
1936.16	9.63278
1939.13	7.91841
1942.1	6.61155
1945.07	6.15806
1948.03	6.0697
1951	6.71802
1953.96	6.73458
1956.92	7.14152
1959.88	6.06017
1962.84	4.91757
1965.8	6.94404
1968.76	7.70937
1971.72	7.60159
1974.67	7.00117
1977.63	9.55599
1980.58	9.92861
1983.54	10.4067
1986.49	11.0829
1989.44	12.3667
1992.39	14.7214
1995.33	17.6244
1998.28	17.8982
2001.23	20.6008
2004.17	21.8563
2007.12	21.7743
2010.06	20.857
2013	19.5578
2015.94	21.3393
2018.88	20.7735
2021.82	19.1494
2024.76	18.6876
2027.69	18.2243
2030.63	18.3067
2033.56	17.6508
2036.5	17.6835
2039.43	18.2311
2042.36	18.529
2045.29	18.5829
2048.22	20.6771
2051.15	20.3138
2054.07	21.4796
2057	21.3273
2059.92	21.4866
2062.85	24.621
2065.77	24.6316
2068.69	26.3834
2071.61	26.8749
2074.53	28.1249
2077.45	27.4287
2080.37	26.9908
2083.28	24.3651
2086.2	25.1042
2089.11	25.3594
2092.02	23.5287
2094.94	22.3615
2097.85	22.6507
2100.76	21.9508
2103.66	21.809
2106.57	20.2585
2109.48	18.8938
2112.38	18.8178
2115.29	17.943
2118.19	16.604
2121.09	16.3672
2123.99	16.0097
2126.89	15.9085
2129.79	16.614
2132.69	15.9515
2135.59	15.1222
2138.48	15.4391
2141.38	16.5834
2144.27	17.7847
2147.17	17.264
2150.06	18.8182
2152.95	19.7161
2155.84	20.1445
2158.73	20.7578
2161.61	21.2497
2164.5	20.9175
2167.38	21.0178
2170.27	20.8513
2173.15	21.2165
2176.03	19.986
2178.91	19.1771
2181.8	18.2792
2184.67	18.1406
2187.55	17.2617
2190.43	17.7247
2193.3	18.0871
2196.18	18.8584
2199.05	19.3523
2201.93	18.8337
2204.8	19.6476
2207.67	19.9162
2210.54	21.5606
2213.41	21.6851
2216.27	23.4041
2219.14	23.9917
2222.01	24.8865
2224.87	24.3524
2227.73	23.6499
2230.6	24.581
2233.46	23.6018
2236.32	23.4248
2239.18	24.6503
2242.03	24.7947
2244.89	23.9249
2247.75	23.2601
2250.6	23.9219
2253.46	24.9863
2256.31	24.7137
2259.16	24.4339
2262.01	25.2868
2264.86	26.2069
2267.71	23.0931
2270.56	21.8443
2273.4	21.4355
2276.25	20.0534
2279.09	20.4334
2281.94	21.3622
2284.78	20.2093
2287.62	19.7776
2290.46	19.1999
2293.3	17.5037
2296.14	16.6589
2298.98	17.2898
2301.82	17.9242
2304.65	20.5856
2307.49	21.3153
2310.32	22.8256
2313.15	23.9785
2315.98	23.2165
2318.81	24.1849
2321.64	24.8346
2324.47	24.6921
2327.3	22.4371
2330.12	22.7036
2332.95	22.1129
2335.77	19.6742
2338.6	17.0552
2341.42	15.2871
2344.24	14.0983
2347.06	12.3916
2349.88	10.9664
2352.7	8.02205
2355.51	6.23028
2358.33	4.69781
2361.14	4.88128
2363.96	3.74759
2366.77	4.756
2369.58	5.35798
2372.39	7.00476
2375.2	7.07469
2378.01	7.42606
2380.82	7.45567
2383.63	9.26399
2386.43	8.83009
2389.24	9.88079
2392.04	11.7777
2394.84	11.3116
2397.65	10.2092
2400.45	11.2142
2403.25	10.8106
2406.05	8.48336
2408.84	7.00453
2411.64	7.23411
2414.44	8.48157
2417.23	8.27806
2420.02	10.0236
2422.82	9.53158
2425.61	10.6149
2428.4	10.9055
2431.19	10.6217
2433.98	11.1281
2436.77	9.25952
2439.55	10.2971
2442.34	10.5151
2445.12	8.23241
2447.91	8.76258
2450.69	7.23219
2453.47	6.08007
2456.25	3.86411
2459.03	4.183
2461.81	3.24047
2464.59	0.66265
2467.36	-0.458817
2470.14	-0.476867
2472.92	-2.13532
2475.69	-2.59969
2478.46	-1.56426
2481.23	-1.01312
2484	0.244446
2486.77	1.66103
2489.54	2.52777
2492.31	2.54767
2495.08	2.43923
2497.84	2.76422
2500.61	2.57683
2503.37	1.64242
2506.13	2.24195
2508.9	2.52258
2511.66	0.653395
2514.42	0.995133
2517.18	2.23586
2519.93	1.71195
2522.69	1.95633
2525.45	2.49721
2528.2	3.76785
2530.95	3.28112
2533.71	4.20401
2536.46	3.90788
2539.21	3.61836
2541.96	5.20077
2544.71	6.6596
2547.46	7.39915
2550.2	8.60557
2552.95	9.38582
2555.7	9.61456
2558.44	9.11548
2561.18	7.91284
2563.93	8.36942
2566.67	9.09544
2569.41	7.8126
2572.15	8.34244
2574.88	8.06687
2577.62	7.78829
2580.36	8.56391
2583.09	8.94641
2585.83	9.38081
2588.56	8.83469
2591.29	8.34097
2594.02	9.2152
2596.75	9.96112
2599.48	10.3876
2602.21	9.66188
2604.94	10.5131
2607.67	10.6336
2610.39	9.5386
2613.12	8.87008
2615.84	8.62412
2618.56	8.55895
2621.28	7.62892
2624.01	8.46424
2626.72	8.00351
2629.44	7.61467
2632.16	8.81329
2634.88	8.48984
2637.59	9.26573
2640.31	10.4672
2643.02	9.7606
2645.74	9.66292
2648.45	9.57618
2651.16	8.98309
2653.87	8.94315
2656.58	8.94427
2659.29	9.87407
2661.99	8.795
2664.7	8.91835
2667.41	8.1676
2670.11	7.32419
2672.81	5.67451
2675.51	4.56066
2678.22	4.53446
2680.92	5.0589
2683.62	5.3786
2686.31	6.75262
2689.01	6.43162
2691.71	7.47215
2694.4	7.82773
2697.1	7.91941
2699.79	8.5207
2702.49	10.7424
2705.18	11.7931
2707.87	11.906
2710.56	13.6744
2713.25	14.8288
2715.94	16.0066
2718.62	17.0719
2721.31	18.3035
2723.99	18.2498
2726.68	16.9602
2729.36	16.3988
2732.04	16.8091
2734.73	17.0643
2737.41	16.9571
2740.08	17.8198
2742.76	16.9904
2745.44	15.9417
2748.12	14.3455
2750.79	13.6641
2753.47	11.5675
2756.14	11.3233
2758.81	9.85116
2761.49	9.11067
2764.16	8.08408
2766.83	7.57838
2769.5	6.38654
2772.16	5.78997
2774.83	5.02133
2777.5	4.83884
2780.16	2.76878
2782.83	2.60568
2785.49	2.57426
2788.15	2.05565
2790.82	-0.102754
2793.48	-0.0220295
2796.14	-1.7909
2798.79	-1.46855
2801.45	-2.09712
2804.11	-2.51688
2806.76	-1.84193
2809.42	-1.99069
2812.07	-1.378
2814.73	-0.818892
2817.38	5.73948
2820.03	11.8214
2822.68	18.3422
2825.33	25.5203
2827.98	34.5738
2830.63	43.125
2833.27	53.6747
2835.92	65.304
2838.56	78.2583
2841.21	94.1068
2843.85	111.254
2846.49	128.75
2849.13	147.173
2851.77	167.583
2854.41	187.079
2857.05	204.772
2859.69	223.711
2862.32	238.915
2864.96	254.867
2867.59	268.43
2870.23	282.564
2872.86	292.837
2875.49	302.328
2878.12	310.834
2880.75	319.606
2883.38	328.272
2886.01	333.481
2888.63	338.144
2891.26	344.187
2893.89	349.533
2896.51	358.552
2899.13	368.58
2901.76	378.738
2904.38	392.088
2907	408.982
2909.62	425.61
2912.24	442.939
2914.85	462.113
2917.47	477.727
2920.09	491.389
2922.7	502.087
2925.32	510.571
2927.93	513.976
2930.54	515.029
2933.15	513.138
2935.76	507.796
2938.37	497.912
2940.98	486.666
2943.59	473.016
2946.2	456.918
2948.8	438.364
2951.41	418.469
2954.01	400.145
2956.62	380.608
2959.22	362.563
2961.82	343.914
2964.42	325.954
2967.02	308.694
2969.62	293.85
2972.22	280.166
2974.81	265.528
2977.41	250.48
2980	233.698
2982.6	216.675
2985.19	201.267
2987.78	184.14
2990.38	167.268
2992.97	151.317
2995.56	135.476
2998.14	120.945
3000.73	105.552
3003.32	92.1915
3005.91	79.599
3008.49	66.7387
3011.07	55.4629
3013.66	43.8489
3016.24	34.8689
3018.82	27.7764
3021.4	20.4255
3023.98	14.1001
3026.56	8.76096
3029.14	5.18641
3031.71	1.89278
3034.29	0.25467
3036.87	-0.604246
3039.44	-1.94134
3042.01	-0.578877
3044.59	-0.0776711
3047.16	1.61464
3049.73	4.26572
3052.3	5.36116
3054.87	8.12285
3057.43	8.96166
3060	9.49746
3062.57	10.8491
3065.13	11.1641
3067.7	11.8975
3070.26	10.5029
3072.82	10.952
3075.39	10.3965
3077.95	9.2149
3080.51	7.95142
3083.07	6.7132
3085.63	4.9125
3088.18	4.6608
3090.74	5.29461
3093.29	5.07233
3095.85	4.9591
3098.4	6.27289
3100.95	7.49304
3103.51	9.00776
3106.06	10.6664
3108.61	12.7573
3111.16	14.9511
3113.71	16.9511
3116.25	21.0593
3118.8	22.7891
3121.35	25.4973
3123.89	28.4119
3126.44	30.5588
3128.98	32.3798
3131.52	33.3996
3134.06	35.51
3136.6	38.5835
3139.14	39.8472
3141.68	40.9183
3144.22	42.3216
3146.76	43.8369
3149.29	40.8298