File: data/Raman/poly_smoothed/Mb_00_13_14_1x_45s_532 nm_x100_100%_600 gr_mm_01.txt
#Acq. time (s)=	45
#Accumulations=	2
#Range (cm-¹)=	200...3150
#Windows=	2
#Auto scanning=	Off
#Autofocus=	Off
#Macrospot=	Off
#AutoExposure=	Off
#Spike filter=	Multiple accum.
#Delay time (s)=	0
#Binning=	1
#Readout mode=	Signal
#DeNoise=	Off
#ICS correction=	On
#Dark correction=	Off
#Inst. Process=	Off
#Detector Gain=	Best Dynamic Range
#Detector ADC=	20 kHz
#Detector temperature (°C)=	-69.85
#Instrument=	LabRAM HR Evol
#Detector=	Synapse
#Objective=	x100
#Grating=	600 gr/mm
#ND Filter=	100%
#Laser (nm)=	532
#Hole=	100.021
#Range=	Auto
#Laser Pol.=	No
#Raman. Pol.=	No
#Laser Pol. (°)=	-0.0007625
#Raman Pol. (°)=	89.9995
#Collection=	Microscope
#StageXY=	Marzhauser
#StageZ=	Marzhauser
#X (µm)=	-1020
#Y (µm)=	-2927.7
#Z (µm)=	527.8
#Full time(mm:ss)=	3:18
#Project=
#Sample=
#Site=
#Title=	Mb_00_13_14_2x_45s_532 nm_x100_100%_600 gr_mm
#Remark=
#Date=	06.07.2022 10:37
#Acquired=	06.07.2022 10:37:07
#Base:Fit=	10.08.2022 10:16:56
#Base:Sub=	10.08.2022 10:17:24
#Filter:Polynom=	16.08.2022 10:36:38
#AxisType[0]=Intens
#AxisUnit[0]=Cnt
#AxisType[1]=Spectr
#AxisUnit[1]=1/cm
200.398	28.3205
204.027	15.3592
207.657	4.14176
211.283	-2.32239
214.909	-0.491704
218.533	8.79614
222.157	24.0623
225.777	38.6824
229.396	57.586
233.016	72.2245
236.632	84.3944
240.247	95.1884
243.86	105.539
247.474	115.221
251.085	126.29
254.694	134.598
258.301	138.536
261.908	138.334
265.513	137.202
269.116	131.561
272.718	124.553
276.319	112.747
279.918	101.468
283.516	85.7796
287.113	73.2871
290.708	61.6214
294.302	49.9863
297.894	42.8525
301.485	37.2169
305.073	35.6254
308.661	31.6412
312.247	28.8505
315.833	25.4222
319.415	23.4104
322.997	21.1988
326.579	17.8353
330.156	16.204
333.735	15.9871
337.31	14.572
340.885	13
344.458	10.2833
348.03	6.35137
351.6	3.47252
355.17	2.58318
358.737	2.11159
362.304	3.17062
365.868	10.9574
369.431	17.1817
372.994	25.0961
376.554	33.6774
380.112	45.668
383.669	61.6608
387.225	80.9483
390.781	99.3273
394.334	114.417
397.885	126.302
401.436	135.777
404.984	141.495
408.532	145.598
412.078	145.7
415.623	143.383
419.166	139.146
422.708	132.549
426.248	123.869
429.788	113.835
433.326	101.33
436.86	87.2835
440.395	74.1873
443.929	59.9113
447.461	48.192
450.99	39.5162
454.52	32.8015
458.048	24.2865
461.573	19.3951
465.099	18.6709
468.623	23.0355
472.144	25.5944
475.666	26.7739
479.184	28.0855
482.703	27.4856
486.218	30.6419
489.734	33.3324
493.247	37.6082
496.759	42.4955
500.271	45.6524
503.779	51.7465
507.287	55.8951
510.795	61.9005
514.299	67.7279
517.803	68.5092
521.305	70.1688
524.805	74.2159
528.307	74.7023
531.805	75.1827
535.301	75.62
538.797	75.3909
542.291	74.3627
545.783	71.0538
549.275	66.7521
552.765	63.6333
556.253	57.0215
559.738	51.1587
563.224	48.7732
566.709	48.4292
570.192	46.0539
573.674	43.0028
577.153	39.6286
580.632	38.4276
584.11	35.7009
587.587	33.057
591.06	30.8757
594.534	28.215
598.005	26.8733
601.476	24.3216
604.944	23.9326
608.413	23.0758
611.878	22.9857
615.344	19.9886
618.807	21.2402
622.27	21.2452
625.73	21.6588
629.189	21.9403
632.648	25.234
636.105	25.9404
639.559	26.7651
643.013	28.5285
646.467	29.009
649.918	32.2478
653.368	29.7503
656.816	27.4326
660.263	22.8482
663.708	21.1786
667.153	20.9426
670.596	17.122
674.037	15.6603
677.478	14.2912
680.917	11.9063
684.355	10.1794
687.791	8.10979
691.224	9.28253
694.658	8.16451
698.091	6.61787
701.522	5.98784
704.95	5.79955
708.379	6.52925
711.806	8.0367
715.23	9.31922
718.655	9.57394
722.078	7.47959
725.498	8.56711
728.919	7.79711
732.337	8.40274
735.755	5.23995
739.17	4.62554
742.584	5.47145
745.998	9.28986
749.409	12.9771
752.819	14.7228
756.23	19.5479
759.637	24.6418
763.043	25.78
766.448	30.9029
769.853	35.9582
773.255	39.9646
776.656	42.5231
780.056	44.148
783.454	46.4046
786.851	47.849
790.247	48.2301
793.641	49.8738
797.034	50.0776
800.426	49.4187
803.817	50.2814
807.206	50.8225
810.592	52.1268
813.979	50.9221
817.364	49.7493
820.748	49.1032
824.129	51.7347
827.511	54.7076
830.891	53.5672
834.269	52.4088
837.646	52.0043
841.023	50.3435
844.396	46.566
847.77	44.5488
851.141	42.6832
854.513	35.9442
857.881	31.3141
861.248	29.5384
864.616	25.7206
867.98	21.4063
871.343	19.7148
874.707	18.4232
878.068	16.5523
881.428	17.4017
884.786	17.8497
888.143	16.2901
891.498	14.5968
894.855	13.7549
898.208	13.8765
901.56	13.3332
904.91	16.4661
908.26	17.976
911.608	17.8059
914.955	18.0112
918.298	19.639
921.643	20.5654
924.986	21.2446
928.328	21.9564
931.668	21.1711
935.006	21.6149
938.344	21.7082
941.681	25.1344
945.014	25.2246
948.349	26.902
951.682	30.0702
955.012	31.2341
958.343	29.2808
961.67	30.5275
964.998	34.8576
968.323	38.7409
971.649	43.284
974.971	47.2714
978.293	51.418
981.615	54.1992
984.933	57.2323
988.251	56.8623
991.567	58.3853
994.884	59.5859
998.198	60.7527
1001.51	62.3781
1004.82	62.7475
1008.13	60.9497
1011.44	61.6953
1014.75	66.5772
1018.06	76.2496
1021.36	91.7768
1024.66	106.423
1027.97	120.165
1031.27	132.141
1034.57	140.617
1037.87	149.308
1041.16	157.858
1044.46	166.605
1047.76	172.505
1051.05	173.387
1054.34	171.022
1057.63	167.108
1060.92	155.905
1064.21	144.217
1067.5	131.12
1070.78	116.696
1074.07	102.219
1077.35	86.7642
1080.63	68.3714
1083.91	51.8041
1087.19	37.5023
1090.47	28.2225
1093.75	25.7231
1097.03	26.355
1100.3	29.641
1103.57	31.3194
1106.84	29.9424
1110.11	27.1886
1113.38	25.5188
1116.65	24.1761
1119.92	21.3991
1123.19	19.1682
1126.45	19.0701
1129.71	18.091
1132.97	17.4727
1136.23	16.7364
1139.49	13.7817
1142.75	12.5014
1146.01	14.1311
1149.26	13.0424
1152.52	13.1451
1155.77	11.4571
1159.02	8.73681
1162.27	7.12826
1165.52	7.76947
1168.77	11.5285
1172.02	15.8329
1175.26	18.7577
1178.51	22.2584
1181.75	25.971
1184.99	25.9888
1188.23	26.5778
1191.47	27.4011
1194.71	31.781
1197.94	36.5331
1201.18	43.813
1204.41	48.8739
1207.65	57.2389
1210.88	68.1121
1214.11	76.7661
1217.34	85.7198
1220.57	92.8877
1223.79	103.357
1227.02	110.906
1230.24	116.646
1233.47	122.213
1236.69	126.248
1239.91	130.334
1243.13	135.426
1246.34	139.088
1249.56	143.14
1252.78	145.952
1255.99	145.895
1259.2	142.268
1262.42	140.397
1265.63	139.365
1268.84	139.768
1272.04	140.071
1275.25	142.042
1278.46	144.212
1281.66	145.815
1284.86	150.648
1288.07	157.901
1291.27	161.472
1294.47	165.456
1297.66	171.192
1300.86	177.748
1304.06	181.269
1307.25	186.487
1310.44	192.673
1313.64	196.765
1316.83	202.054
1320.02	204.291
1323.2	204.977
1326.39	206.655
1329.58	206.668
1332.76	203.283
1335.95	196.859
1339.13	192.909
1342.31	189.128
1345.49	182.648
1348.67	176.589
1351.85	171.013
1355.02	165.354
1358.2	158.888
1361.37	153.971
1364.54	148.638
1367.71	141.721
1370.88	135.396
1374.05	129.938
1377.22	123.965
1380.39	120.091
1383.55	117.812
1386.72	118.634
1389.88	117.545
1393.04	114.925
1396.2	113.433
1399.36	111.231
1402.52	110.912
1405.68	115.771
1408.83	120.38
1411.98	128.474
1415.14	138.663
1418.29	152.664
1421.44	168.618
1424.59	184.707
1427.74	202.964
1430.89	223.832
1434.03	241.328
1437.18	257.009
1440.32	268.193
1443.46	276.962
1446.6	282.684
1449.74	283.239
1452.88	282.187
1456.02	277.516
1459.16	269.013
1462.29	255.485
1465.43	240.74
1468.56	221.476
1471.69	202.862
1474.82	182.407
1477.95	164.563
1481.08	147.871
1484.2	132.215
1487.33	117.602
1490.46	104.847
1493.58	93.0896
1496.7	83.9885
1499.82	77.6868
1502.94	73.894
1506.06	72.0708
1509.18	69.4768
1512.29	66.8086
1515.41	63.6374
1518.52	66.9987
1521.63	68.2723
1524.75	69.2406
1527.85	71.1522
1530.96	74.1148
1534.07	75.2489
1537.18	76.9885
1540.28	82.1914
1543.39	86.3389
1546.49	90.0097
1549.59	97.2897
1552.69	99.9616
1555.79	104.747
1558.89	107.165
1561.99	108.615
1565.08	112.951
1568.18	116.713
1571.27	123.006
1574.37	128.189
1577.46	131.337
1580.55	135.832
1583.64	139.374
1586.73	142.468
1589.81	147.484
1592.9	152.843
1595.98	157.085
1599.06	157.704
1602.15	156.875
1605.23	154.636
1608.31	152.995
1611.39	150.397
1614.46	147.972
1617.54	146.272
1620.61	147.004
1623.69	147.726
1626.76	149.821
1629.83	151.766
1632.9	156.833
1635.97	160.722
1639.04	166.916
1642.11	173.213
1645.17	178.352
1648.24	183.848
1651.3	186.989
1654.36	189.463
1657.42	191.408
1660.48	191.212
1663.54	187.437
1666.6	183.907
1669.66	176.425
1672.71	167.163
1675.77	155.174
1678.82	141.129
1681.87	127.224
1684.92	113.496
1687.97	99.5802
1691.02	87.1798
1694.07	76.0673
1697.11	63.4942
1700.16	55.5446
1703.2	48.141
1706.25	40.4447
1709.29	34.7894
1712.33	27.643
1715.37	23.4372
1718.41	18.8838
1721.44	16.9835
1724.48	14.2212
1727.51	14.1767
1730.55	13.4497
1733.58	12.3207
1736.61	11.0255
1739.64	9.5665
1742.67	9.46657
1745.7	10.9424
1748.72	10.5726
1751.75	11.1428
1754.77	9.93964
1757.8	9.5083
1760.82	9.46015
1763.84	8.95071
1766.86	9.33099
1769.88	7.53792
1772.9	7.6616
1775.91	8.66268
1778.93	8.69447
1781.94	7.38429
1784.96	7.2977
1787.97	6.33485
1790.98	5.37299
1793.99	5.11076
1797	5.64711
1800.01	6.85023
1803.01	6.78534
1806.02	6.71198
1809.02	6.00443
1812.02	5.28815
1815.02	5.06214
1818.03	4.21538
1821.02	4.71828
1824.02	4.14802
1827.02	3.46357
1830.02	2.77205
1833.01	3.49038
1836.01	1.80351
1839	2.38695
1841.99	2.41248
1844.98	4.16351
1847.97	4.80586
1850.96	5.25716
1853.95	4.59415
1856.93	5.14279
1859.92	3.84149
1862.9	3.77096
1865.88	5.50836
1868.87	6.31349
1871.85	6.54566
1874.83	5.96796
1877.81	5.46486
1880.78	6.06332
1882.53	5.05689
1885.52	4.84451
1888.51	4.45053
1891.5	5.37168
1894.48	6.61918
1897.47	7.05103
1900.45	8.215
1903.43	8.2866
1906.41	8.29248
1909.39	9.11947
1912.37	10.3089
1915.35	10.9694
1918.33	11.2371
1921.3	10.9731
1924.28	10.497
1927.25	8.49018
1930.22	4.64469
1933.19	4.11216
1936.16	3.5365
1939.13	3.58624
1942.1	2.64984
1945.07	1.38526
1948.03	0.987209
1951	1.84879
1953.96	1.69456
1956.92	1.7264
1959.88	2.31251
1962.84	3.50816
1965.8	4.62171
1968.76	4.61445
1971.72	5.36715
1974.67	3.93918
1977.63	4.52624
1980.58	5.38494
1983.54	7.09039
1986.49	6.10308
1989.44	8.16936
1992.39	8.86192
1995.33	9.51507
1998.28	9.71639
2001.23	9.62606
2004.17	11.6819
2007.12	13.4888
2010.06	14.145
2013	15.5445
2015.94	17.3159
2018.88	16.9302
2021.82	18.5733
2024.76	17.4973
2027.69	18.5432
2030.63	16.7095
2033.56	15.9215
2036.5	15.3252
2039.43	14.5159
2042.36	13.6719
2045.29	10.6486
2048.22	10.4726
2051.15	11.4228
2054.07	13.4283
2057	13.2043
2059.92	13.6216
2062.85	16.1309
2065.77	15.892
2068.69	19.048
2071.61	18.7428
2074.53	19.1312
2077.45	20.1177
2080.37	19.5463
2083.28	20.6548
2086.2	20.1236
2089.11	19.7999
2092.02	19.5334
2094.94	18.3609
2097.85	16.4952
2100.76	15.0937
2103.66	13.0315
2106.57	13.3882
2109.48	13.7518
2112.38	12.6543
2115.29	9.75357
2118.19	9.32827
2121.09	10.5061
2123.99	10.1221
2126.89	10.7435
2129.79	10.8883
2132.69	11.9775
2135.59	11.86
2138.48	11.7824
2141.38	9.42383
2144.27	9.80381
2147.17	10.4131
2150.06	10.6382
2152.95	11.5266
2155.84	13.4031
2158.73	12.9328
2161.61	14.204
2164.5	14.4003
2167.38	15.3273
2170.27	15.8462
2173.15	17.2736
2176.03	19.5267
2178.91	19.5707
2181.8	18.9322
2184.67	17.5068
2187.55	18.7728
2190.43	18.4396
2193.3	18.2425
2196.18	17.7787
2199.05	15.9754
2201.93	16.9228
2204.8	14.3554
2207.67	13.8472
2210.54	13.1857
2213.41	14.5865
2216.27	15.0705
2219.14	15.1763
2222.01	16.8009
2224.87	18.6403
2227.73	19.9621
2230.6	19.9517
2233.46	20.5136
2236.32	20.892
2239.18	22.9901
2242.03	21.4529
2244.89	21.1406
2247.75	21.9112
2250.6	21.6965
2253.46	20.2186
2256.31	19.6518
2259.16	20.0342
2262.01	17.2936
2264.86	18.0444
2267.71	16.7078
2270.56	16.8788
2273.4	16.0666
2276.25	16.1075
2279.09	14.948
2281.94	14.9481
2284.78	14.2874
2287.62	12.2194
2290.46	12.9035
2293.3	11.9564
2296.14	11.5012
2298.98	10.026
2301.82	8.70647
2304.65	8.59801
2307.49	8.13465
2310.32	7.65477
2313.15	6.99324
2315.98	8.87127
2318.81	7.52152
2321.64	7.96863
2324.47	7.62299
2327.3	9.25914
2330.12	9.22733
2332.95	10.2427
2335.77	10.7483
2338.6	9.84554
2341.42	9.58127
2344.24	8.32423
2347.06	6.84837
2349.88	6.87985
2352.7	7.03009
2355.51	6.10773
2358.33	6.15953
2361.14	5.34047
2363.96	4.54263
2366.77	4.65199
2369.58	3.95598
2372.39	4.65377
2375.2	5.50743
2378.01	5.2384
2380.82	4.16707
2383.63	3.18442
2386.43	2.28365
2389.24	0.0351507
2392.04	0.779374
2394.84	2.3159
2397.65	2.1911
2400.45	2.70386
2403.25	2.08859
2406.05	2.8377
2408.84	4.17522
2411.64	6.04861
2414.44	6.00651
2417.23	7.77981
2420.02	8.5723
2422.82	9.72801
2425.61	9.92168
2428.4	10.2158
2431.19	11.2373
2433.98	10.6671
2436.77	11.6573
2439.55	10.7336
2442.34	11.252
2445.12	11.4068
2447.91	7.47033
2450.69	4.78328
2453.47	2.74736
2456.25	2.29957
2459.03	0.981104
2461.81	1.29524
2464.59	-0.175707
2467.36	0.0316062
2470.14	0.409388
2472.92	0.314982
2475.69	0.639805
2478.46	0.647305
2481.23	0.872198
2484	1.23549
2486.77	3.20213
2489.54	4.79483
2492.31	5.08368
2495.08	5.48109
2497.84	6.22102
2500.61	6.08291
2503.37	4.95064
2506.13	5.96012
2508.9	5.04165
2511.66	4.18706
2514.42	5.89859
2517.18	4.29708
2519.93	5.04099
2522.69	4.17621
2525.45	4.38929
2528.2	4.56748
2530.95	5.19832
2533.71	5.94436
2536.46	5.99435
2539.21	6.56615
2541.96	7.6709
2544.71	8.62378
2547.46	10.437
2550.2	11.2733
2552.95	11.3501
2555.7	12.1407
2558.44	10.7593
2561.18	10.2543
2563.93	10.7075
2566.67	10.1875
2569.41	9.31591
2572.15	9.10936
2574.88	9.80095
2577.62	9.77363
2580.36	10.1802
2583.09	9.64447
2585.83	7.99341
2588.56	7.07345
2591.29	7.3288
2594.02	7.19109
2596.75	8.80602
2599.48	8.13196
2602.21	9.5269
2604.94	9.00624
2607.67	10.3956
2610.39	12.0949
2613.12	12.0531
2615.84	11.3656
2618.56	11.2473
2621.28	12.197
2624.01	13.0177
2626.72	13.267
2629.44	14.2054
2632.16	12.5095
2634.88	14.0894
2637.59	14.9904
2640.31	15.6896
2643.02	16.1227
2645.74	17.7345
2648.45	17.2741
2651.16	17.2723
2653.87	17.3688
2656.58	19.3715
2659.29	20.4169
2661.99	21.7436
2664.7	20.8293
2667.41	19.6318
2670.11	19.5215
2672.81	17.984
2675.51	18.0102
2678.22	16.0874
2680.92	13.1409
2683.62	11.7812
2686.31	11.8149
2689.01	11.8332
2691.71	13.0518
2694.4	12.5307
2697.1	13.9169
2699.79	16.3922
2702.49	18.7998
2705.18	20.4052
2707.87	23.3338
2710.56	23.9533
2713.25	25.7072
2715.94	28.2779
2718.62	30.1748
2721.31	30.6383
2723.99	31.5992
2726.68	31.113
2729.36	30.1698
2732.04	28.1705
2734.73	25.8595
2737.41	22.6553
2740.08	19.5041
2742.76	17.5065
2745.44	13.7278
2748.12	11.8861
2750.79	9.66397
2753.47	8.53236
2756.14	7.59383
2758.81	7.19158
2761.49	5.64276
2764.16	4.93666
2766.83	3.26747
2769.5	2.60309
2772.16	1.25768
2774.83	-0.0771384
2777.5	0.0589156
2780.16	-0.0747901
2782.83	-0.284151
2785.49	-8.36986e-005
2788.15	-0.886315
2790.82	-0.535412
2793.48	-1.69353
2796.14	-2.37394
2798.79	-2.50383
2801.45	-2.06056
2804.11	-3.13188
2806.76	-4.03686
2809.42	-3.17403
2812.07	-3.66251
2814.73	-1.09727
2817.38	4.36737
2820.03	9.98245
2822.68	18.8788
2825.33	29.6801
2827.98	39.829
2830.63	52.2482
2833.27	66.3974
2835.92	80.4938
2838.56	98.5722
2841.21	119.791
2843.85	142.725
2846.49	168.37
2849.13	197.307
2851.77	227.382
2854.41	257.202
2857.05	286.723
2859.69	313.784
2862.32	340.017
2864.96	363.919
2867.59	385.154
2870.23	403.949
2872.86	423.467
2875.49	438.723
2878.12	454.734
2880.75	467.844
2883.38	478.847
2886.01	489.102
2888.63	499.4
2891.26	511.101
2893.89	522.254
2896.51	533.38
2899.13	549.253
2901.76	565.933
2904.38	588.121
2907	614.095
2909.62	642.197
2912.24	673.518
2914.85	702.445
2917.47	728.422
2920.09	748.379
2922.7	764.376
2925.32	776.319
2927.93	781.13
2930.54	780.633
2933.15	774.534
2935.76	765.053
2938.37	749.412
2940.98	729.043
2943.59	703.916
2946.2	676.565
2948.8	647.804
2951.41	616.488
2954.01	586.028
2956.62	555.604
2959.22	524.339
2961.82	493.839
2964.42	467.107
2967.02	440.554
2969.62	417.84
2972.22	395.305
2974.81	374.02
2977.41	352.34
2980	327.414
2982.6	303.889
2985.19	276.729
2987.78	251.162
2990.38	225.4
2992.97	200.75
2995.56	177.516
2998.14	155.697
3000.73	134.199
3003.32	115.334
3005.91	96.0346
3008.49	79.233
3011.07	62.5862
3013.66	49.0733
3016.24	36.8973
3018.82	27.437
3021.4	17.4506
3023.98	10.1584
3026.56	3.62664
3029.14	-0.318384
3031.71	-1.99401
3034.29	-2.14235
3036.87	-1.54416
3039.44	-0.552983
3042.01	2.2426
3044.59	4.38741
3047.16	6.11826
3049.73	7.63813
3052.3	11.2749
3054.87	13.1319
3057.43	14.0216
3060	14.7038
3062.57	14.7812
3065.13	14.9932
3067.7	13.4349
3070.26	11.3166
3072.82	10.7468
3075.39	9.32679
3077.95	7.02572
3080.51	6.87542
3083.07	4.8634
3085.63	2.99088
3088.18	1.971
3090.74	1.4408
3093.29	3.12074
3095.85	4.89425
3098.4	5.65211
3100.95	8.01883
3103.51	10.5799
3106.06	13.2974
3108.61	15.7334
3111.16	18.921
3113.71	22.4712
3116.25	27.0512
3118.8	31.1013
3121.35	35.9639
3123.89	38.6682
3126.44	43.3186
3128.98	46.9839
3131.52	51.2433
3134.06	55.529
3136.6	61.112
3139.14	66.3289
3141.68	70.5738
3144.22	73.6865
3146.76	76.9898
3149.29	77.803