File: data/Raman/poly_smoothed/Mb_00_13_30_1x_45s_532 nm_x100_100%_600 gr_mm_01.txt
#Acq. time (s)=	45
#Accumulations=	2
#Range (cm-¹)=	200...3150
#Windows=	2
#Auto scanning=	Off
#Autofocus=	Off
#Macrospot=	Off
#AutoExposure=	Off
#Spike filter=	Multiple accum.
#Delay time (s)=	0
#Binning=	1
#Readout mode=	Signal
#DeNoise=	Off
#ICS correction=	On
#Dark correction=	Off
#Inst. Process=	Off
#Detector Gain=	Best Dynamic Range
#Detector ADC=	20 kHz
#Detector temperature (°C)=	-69.85
#Instrument=	LabRAM HR Evol
#Detector=	Synapse
#Objective=	x100
#Grating=	600 gr/mm
#ND Filter=	100%
#Laser (nm)=	532
#Hole=	100.021
#Range=	Auto
#Laser Pol.=	No
#Raman. Pol.=	No
#Laser Pol. (°)=	-0.0007625
#Raman Pol. (°)=	89.9995
#Collection=	Microscope
#StageXY=	Marzhauser
#StageZ=	Marzhauser
#X (µm)=	-995.3
#Y (µm)=	-2854.5
#Z (µm)=	528.9
#Full time(mm:ss)=	3:18
#Project=
#Sample=
#Site=
#Title=	Mb_00_13_30_2x_45s_532 nm_x100_100%_600 gr_mm
#Remark=
#Date=	06.07.2022 12:00
#Acquired=	06.07.2022 12:00:03
#Base:Fit=	10.08.2022 10:16:56
#Base:Sub=	10.08.2022 10:17:24
#Filter:Polynom=	16.08.2022 10:36:38
#AxisType[0]=Intens
#AxisUnit[0]=Cnt
#AxisType[1]=Spectr
#AxisUnit[1]=1/cm
200.398	4.8778
204.027	1.33819
207.657	-0.844385
211.283	-2.53556
214.909	-1.49572
218.533	3.63049
222.157	11.5486
225.777	17.8711
229.396	24.2295
233.016	29.4587
236.632	35.2094
240.247	39.7371
243.86	42.3582
247.474	44.4103
251.085	46.4658
254.694	48.8206
258.301	49.9018
261.908	49.4474
265.513	48.463
269.116	47.8029
272.718	44.5234
276.319	40.0259
279.918	33.9637
283.516	28.9448
287.113	23.808
290.708	18.7216
294.302	13.7551
297.894	11.2504
301.485	9.62958
305.073	9.94316
308.661	10.2482
312.247	9.08042
315.833	8.44173
319.415	7.45724
322.997	7.93406
326.579	8.94767
330.156	10.1461
333.735	8.2214
337.31	7.64159
340.885	7.81516
344.458	7.78992
348.03	8.9118
351.6	6.69512
355.17	4.10896
358.737	3.07302
362.304	3.32763
365.868	3.45567
369.431	7.0981
372.994	8.98527
376.554	11.7977
380.112	15.3672
383.669	20.9526
387.225	26.0458
390.781	31.3348
394.334	37.615
397.885	42.1647
401.436	45.8198
404.984	47.1844
408.532	48.6162
412.078	50.2934
415.623	50.8512
419.166	50.6307
422.708	48.2766
426.248	46.1488
429.788	43.2052
433.326	39.3789
436.86	34.0673
440.395	27.7597
443.929	23.0964
447.461	19.3315
450.99	15.9136
454.52	13.0074
458.048	10.5329
461.573	7.38946
465.099	6.70676
468.623	6.27017
472.144	7.91715
475.666	8.01867
479.184	8.18303
482.703	6.7428
486.218	7.38369
489.734	6.96509
493.247	7.57144
496.759	9.48599
500.271	12.8068
503.779	15.589
507.287	18.5913
510.795	21.3077
514.299	24.5101
517.803	25.7848
521.305	27.9083
524.805	27.3694
528.307	27.0055
531.805	25.9347
535.301	26.0126
538.797	25.1832
542.291	25.7763
545.783	24.8633
549.275	24.6866
552.765	23.596
556.253	22.042
559.738	18.8702
563.224	17.5681
566.709	14.9152
570.192	12.3828
573.674	10.9641
577.153	10.3351
580.632	10.7836
584.11	9.24218
587.587	9.8588
591.06	8.62639
594.534	9.72709
598.005	9.51875
601.476	9.58115
604.944	8.60431
608.413	7.65642
611.878	7.50579
615.344	7.5678
618.807	5.96007
622.27	7.59456
625.73	9.3174
629.189	12.392
632.648	12.787
636.105	13.9437
639.559	14.2112
643.013	14.249
646.467	17.8831
649.918	19.0052
653.368	19.509
656.816	20.165
660.263	22.5882
663.708	24.2241
667.153	25.467
670.596	25.6885
674.037	25.3233
677.478	26.2251
680.917	27.4587
684.355	27.1608
687.791	27.146
691.224	25.7931
694.658	26.1759
698.091	26.1526
701.522	24.413
704.95	23.6848
708.379	24.426
711.806	25.8487
715.23	25.4161
718.655	25.5401
722.078	25.5567
725.498	26.9988
728.919	28.5887
732.337	29.2864
735.755	31.3403
739.17	33.2178
742.584	36.7536
745.998	39.6016
749.409	43.1284
752.819	45.7948
756.23	48.9071
759.637	52.9998
763.043	56.8899
766.448	60.4955
769.853	62.8384
773.255	65.6028
776.656	65.6712
780.056	67.3042
783.454	67.8502
786.851	68.4193
790.247	69.2137
793.641	70.134
797.034	70.0943
800.426	67.9418
803.817	68.2878
807.206	69.2926
810.592	69.5933
813.979	69.2135
817.364	69.9383
820.748	69.4527
824.129	68.5218
827.511	68.5722
830.891	67.1853
834.269	68.055
837.646	68.1404
841.023	66.4469
844.396	65.3078
847.77	62.4135
851.141	60.1248
854.513	58.7665
857.881	56.8466
861.248	53.6728
864.616	51.2106
867.98	49.2207
871.343	48.9741
874.707	47.547
878.068	46.1317
881.428	44.7309
884.786	43.888
888.143	44.4825
891.498	45.0579
894.855	45.7182
898.208	45.5336
901.56	46.3936
904.91	47.1254
908.26	47.1496
911.608	45.5765
914.955	46.2998
918.298	45.5436
921.643	45.4253
924.986	45.1735
928.328	45.3132
931.668	45.9823
935.006	44.4692
938.344	44.5137
941.681	41.454
945.014	39.8386
948.349	38.9766
951.682	38.5347
955.012	35.8097
958.343	32.5757
961.67	30.9478
964.998	31.0403
968.323	32.3164
971.649	35.0783
974.971	36.1571
978.293	37.6942
981.615	38.5969
984.933	39.6786
988.251	39.7341
991.567	39.3414
994.884	39.734
998.198	41.0698
1001.51	41.2919
1004.82	41.4411
1008.13	41.3835
1011.44	41.1206
1014.75	40.0695
1018.06	40.3291
1021.36	44.1863
1024.66	48.3618
1027.97	51.8903
1031.27	54.7754
1034.57	56.6313
1037.87	56.8011
1041.16	58.6967
1044.46	61.6308
1047.76	64.3134
1051.05	64.891
1054.34	64.8175
1057.63	62.6479
1060.92	61.1778
1064.21	60.359
1067.5	57.358
1070.78	55.7447
1074.07	51.4665
1077.35	46.4245
1080.63	39.0417
1083.91	33.3947
1087.19	28.745
1090.47	26.6192
1093.75	25.3781
1097.03	25.142
1100.3	25.3271
1103.57	25.0928
1106.84	23.6075
1110.11	22.0663
1113.38	20.4128
1116.65	17.4138
1119.92	16.258
1123.19	14.3814
1126.45	12.7398
1129.71	12.0826
1132.97	10.1848
1136.23	8.79123
1139.49	7.33304
1142.75	8.04824
1146.01	8.04081
1149.26	9.11827
1152.52	10.001
1155.77	10.6963
1159.02	9.68835
1162.27	10.1086
1165.52	12.7266
1168.77	13.5946
1172.02	15.8804
1175.26	17.3855
1178.51	17.7664
1181.75	17.4224
1184.99	18.0672
1188.23	20.1173
1191.47	20.565
1194.71	21.9976
1197.94	22.0612
1201.18	24.4221
1204.41	25.6817
1207.65	28.1456
1210.88	28.9468
1214.11	30.177
1217.34	32.2538
1220.57	36.6942
1223.79	42.2153
1227.02	45.6416
1230.24	48.0516
1233.47	51.4723
1236.69	52.3174
1239.91	53.8809
1243.13	55.9179
1246.34	56.0703
1249.56	56.9171
1252.78	56.5159
1255.99	56.1517
1259.2	54.7563
1262.42	54.7275
1265.63	54.9116
1268.84	55.4949
1272.04	57.4317
1275.25	57.4065
1278.46	59.2712
1281.66	61.0903
1284.86	62.7899
1288.07	63.8912
1291.27	66.4067
1294.47	66.8167
1297.66	69.9994
1300.86	72.3135
1304.06	73.2321
1307.25	75.6559
1310.44	76.9677
1313.64	78.9899
1316.83	78.6013
1320.02	78.4681
1323.2	77.7929
1326.39	76.138
1329.58	73.8347
1332.76	73.093
1335.95	72.8157
1339.13	71.9524
1342.31	71.5495
1345.49	69.8504
1348.67	69.396
1351.85	69.053
1355.02	68.3634
1358.2	67.0815
1361.37	67.3591
1364.54	65.3949
1367.71	64.7125
1370.88	63.6053
1374.05	62.9478
1377.22	62.4127
1380.39	61.7945
1383.55	61.1176
1386.72	60.4966
1389.88	59.1066
1393.04	56.6531
1396.2	54.1649
1399.36	52.2322
1402.52	50.7898
1405.68	49.5582
1408.83	50.2563
1411.98	53.9291
1415.14	54.9406
1418.29	58.6112
1421.44	62.6904
1424.59	66.3699
1427.74	73.6468
1430.89	80.2661
1434.03	87.2578
1437.18	94.3025
1440.32	99.9781
1443.46	104.055
1446.6	107.38
1449.74	109.787
1452.88	109.528
1456.02	108.423
1459.16	106.746
1462.29	102.257
1465.43	96.3068
1468.56	90.6468
1471.69	83.0901
1474.82	74.497
1477.95	67.3274
1481.08	61.3199
1484.2	55.2151
1487.33	49.7937
1490.46	44.9883
1493.58	37.9904
1496.7	34.7639
1499.82	31.5
1502.94	29.228
1506.06	28.8537
1509.18	27.6879
1512.29	28.2742
1515.41	27.5773
1518.52	27.1221
1521.63	27.9822
1524.75	29.9381
1527.85	31.2433
1530.96	30.8994
1534.07	33.0311
1537.18	35.0875
1540.28	35.9753
1543.39	38.9629
1546.49	40.7626
1549.59	41.8978
1552.69	44.2953
1555.79	46.8233
1558.89	47.0783
1561.99	47.9338
1565.08	50.0266
1568.18	50.6814
1571.27	51.1689
1574.37	51.8957
1577.46	52.8662
1580.55	55.0653
1583.64	56.9554
1586.73	57.6723
1589.81	58.3895
1592.9	59.2426
1595.98	60.5601
1599.06	61.7608
1602.15	63.017
1605.23	61.4136
1608.31	60.6438
1611.39	60.9199
1614.46	59.0622
1617.54	59.8285
1620.61	59.2076
1623.69	59.0637
1626.76	60.2254
1629.83	61.5726
1632.9	61.8012
1635.97	62.5969
1639.04	63.7666
1642.11	66.1577
1645.17	67.0985
1648.24	67.8998
1651.3	68.8844
1654.36	70.5202
1657.42	71.31
1660.48	71.0171
1663.54	69.6233
1666.6	67.2006
1669.66	65.6854
1672.71	63.1562
1675.77	59.8942
1678.82	55.2657
1681.87	49.8135
1684.92	43.5201
1687.97	38.403
1691.02	33.6095
1694.07	28.9138
1697.11	24.5657
1700.16	22.0942
1703.2	18.9325
1706.25	16.1526
1709.29	13.8558
1712.33	11.5981
1715.37	9.917
1718.41	8.17715
1721.44	7.3838
1724.48	7.7371
1727.51	6.71193
1730.55	6.72681
1733.58	5.1071
1736.61	4.64077
1739.64	3.01083
1742.67	2.31273
1745.7	2.92426
1748.72	2.26461
1751.75	1.9164
1754.77	1.42201
1757.8	0.719785
1760.82	-0.076877
1763.84	0.0402698
1766.86	0.632766
1769.88	1.84514
1772.9	2.29592
1775.91	2.89656
1778.93	3.38315
1781.94	4.52439
1784.96	3.01178
1787.97	3.01957
1790.98	3.13923
1793.99	3.29322
1797	3.75536
1800.01	4.29063
1803.01	4.24484
1806.02	2.4701
1809.02	2.42211
1812.02	2.16005
1815.02	2.02175
1818.03	2.36674
1821.02	2.9917
1824.02	2.74535
1827.02	3.96883
1830.02	4.11588
1833.01	3.70981
1836.01	3.53789
1839	3.59734
1841.99	3.85781
1844.98	3.24511
1847.97	4.01135
1850.96	3.37824
1853.95	2.57692
1856.93	3.3587
1859.92	2.78261
1862.9	4.10949
1865.88	4.38355
1868.87	5.4601
1871.85	7.05905
1874.83	6.72589
1877.81	5.9101
1880.78	7.499
1882.53	7.31384
1885.52	7.38712
1888.51	7.05967
1891.5	7.12514
1894.48	6.98584
1897.47	6.84028
1900.45	5.41621
1903.43	4.55481
1906.41	2.9713
1909.39	3.7139
1912.37	3.64014
1915.35	2.95031
1918.33	2.64699
1921.3	2.84878
1924.28	2.35776
1927.25	3.24694
1930.22	2.20084
1933.19	3.3864
1936.16	3.50923
1939.13	4.38268
1942.1	5.75956
1945.07	5.42003
1948.03	5.78529
1951	5.48142
1953.96	5.28118
1956.92	5.29165
1959.88	5.70934
1962.84	5.06597
1965.8	5.12098
1968.76	4.35799
1971.72	4.67285
1974.67	4.81298
1977.63	5.27391
1980.58	5.86375
1983.54	5.69252
1986.49	5.56943
1989.44	5.02383
1992.39	4.13237
1995.33	3.26418
1998.28	3.11549
2001.23	3.20983
2004.17	3.31449
2007.12	3.47886
2010.06	3.22843
2013	3.71405
2015.94	3.53841
2018.88	3.38682
2021.82	2.12776
2024.76	1.6587
2027.69	1.82249
2030.63	2.35527
2033.56	2.62981
2036.5	4.36914
2039.43	4.37086
2042.36	5.74744
2045.29	5.97527
2048.22	6.70754
2051.15	7.59373
2054.07	7.24576
2057	7.60221
2059.92	7.77175
2062.85	7.4006
2065.77	7.39134
2068.69	7.4264
2071.61	8.32924
2074.53	8.53875
2077.45	8.80844
2080.37	9.67354
2083.28	9.32678
2086.2	9.32704
2089.11	8.64214
2092.02	7.51651
2094.94	7.92364
2097.85	8.01427
2100.76	9.03025
2103.66	8.86614
2106.57	8.51046
2109.48	8.61378
2112.38	7.78799
2115.29	7.28526
2118.19	6.5063
2121.09	7.49076
2123.99	7.69487
2126.89	7.19382
2129.79	7.54757
2132.69	7.45154
2135.59	7.75108
2138.48	7.84134
2141.38	8.14753
2144.27	8.63558
2147.17	8.48895
2150.06	7.57149
2152.95	7.76477
2155.84	7.49313
2158.73	7.76538
2161.61	7.10629
2164.5	7.86406
2167.38	9.40585
2170.27	10.2528
2173.15	10.243
2176.03	9.61039
2178.91	9.32699
2181.8	10.6832
2184.67	11.261
2187.55	10.4039
2190.43	9.94334
2193.3	9.92756
2196.18	9.67279
2199.05	10.0011
2201.93	10.7076
2204.8	9.82386
2207.67	8.64897
2210.54	7.58323
2213.41	6.69148
2216.27	6.29995
2219.14	5.01659
2222.01	5.98411
2224.87	4.30515
2227.73	4.12571
2230.6	5.01695
2233.46	5.50255
2236.32	6.07193
2239.18	7.04012
2242.03	5.78507
2244.89	5.69173
2247.75	6.04527
2250.6	8.05998
2253.46	8.08288
2256.31	8.73629
2259.16	7.68394
2262.01	8.17793
2264.86	10.2607
2267.71	10.8018
2270.56	13.5105
2273.4	13.9974
2276.25	11.9139
2279.09	11.9438
2281.94	11.6658
2284.78	11.6374
2287.62	11.3246
2290.46	11.0559
2293.3	11.1234
2296.14	12.0906
2298.98	13.0862
2301.82	12.6544
2304.65	12.3122
2307.49	11.0671
2310.32	10.1495
2313.15	9.77231
2315.98	9.00675
2318.81	8.56696
2321.64	8.17009
2324.47	8.31964
2327.3	8.01336
2330.12	8.06728
2332.95	7.92587
2335.77	7.76264
2338.6	6.51751
2341.42	5.93083
2344.24	3.47908
2347.06	2.7267
2349.88	2.81484
2352.7	2.46529
2355.51	2.14444
2358.33	2.98745
2361.14	3.25054
2363.96	5.30595
2366.77	5.47338
2369.58	5.74899
2372.39	5.67029
2375.2	6.40145
2378.01	7.23782
2380.82	7.26636
2383.63	6.33999
2386.43	5.27186
2389.24	5.68226
2392.04	5.76033
2394.84	6.72245
2397.65	5.64286
2400.45	5.62075
2403.25	4.70997
2406.05	3.91697
2408.84	3.43094
2411.64	4.18271
2414.44	4.66805
2417.23	4.54272
2420.02	4.00105
2422.82	3.53371
2425.61	4.21237
2428.4	4.70251
2431.19	4.51092
2433.98	4.18179
2436.77	3.85896
2439.55	3.89687
2442.34	3.70074
2445.12	2.63944
2447.91	1.51925
2450.69	-0.483765
2453.47	-1.04535
2456.25	-0.49793
2459.03	-0.357801
2461.81	0.127228
2464.59	0.323663
2467.36	0.180565
2470.14	0.786769
2472.92	0.609982
2475.69	1.12468
2478.46	1.33408
2481.23	2.0932
2484	1.67166
2486.77	3.13097
2489.54	2.81041
2492.31	3.40083
2495.08	4.116
2497.84	2.5863
2500.61	3.1087
2503.37	2.83397
2506.13	3.76961
2508.9	3.31024
2511.66	3.51218
2514.42	3.60309
2517.18	3.88904
2519.93	4.43344
2522.69	5.45625
2525.45	5.73162
2528.2	6.0492
2530.95	6.37873
2533.71	6.33372
2536.46	7.33697
2539.21	8.03839
2541.96	9.0148
2544.71	9.66278
2547.46	10.2602
2550.2	11.137
2552.95	11.108
2555.7	11.6395
2558.44	11.7764
2561.18	11.418
2563.93	11.6296
2566.67	10.4082
2569.41	10.249
2572.15	10.414
2574.88	10.2851
2577.62	11.5359
2580.36	11.1605
2583.09	11.9665
2585.83	11.5798
2588.56	10.9503
2591.29	10.1797
2594.02	9.64499
2596.75	9.26643
2599.48	8.16733
2602.21	8.94973
2604.94	8.81333
2607.67	9.26916
2610.39	9.32231
2613.12	8.95659
2615.84	8.91547
2618.56	8.7078
2621.28	8.98072
2624.01	8.77961
2626.72	8.78132
2629.44	7.89012
2632.16	7.5196
2634.88	7.41346
2637.59	8.84435
2640.31	9.97569
2643.02	9.97695
2645.74	9.44197
2648.45	10.0395
2651.16	10.4544
2653.87	10.1102
2656.58	9.35377
2659.29	8.58102
2661.99	8.14686
2664.7	8.30737
2667.41	7.39836
2670.11	7.07298
2672.81	6.40832
2675.51	6.51051
2678.22	6.61654
2680.92	6.71646
2683.62	7.10342
2686.31	6.2234
2689.01	5.26661
2691.71	5.63669
2694.4	5.53066
2697.1	6.0214
2699.79	6.24969
2702.49	6.50579
2705.18	6.85056
2707.87	8.3871
2710.56	8.84584
2713.25	9.79887
2715.94	10.6547
2718.62	10.8206
2721.31	11.2593
2723.99	11.5663
2726.68	11.9685
2729.36	11.7907
2732.04	11.4599
2734.73	12.363
2737.41	12.4544
2740.08	12.5675
2742.76	12.353
2745.44	12.4769
2748.12	11.7416
2750.79	10.5495
2753.47	10.0547
2756.14	9.94634
2758.81	9.9382
2761.49	10.28
2764.16	9.34638
2766.83	8.02279
2769.5	7.26211
2772.16	8.44817
2774.83	8.06981
2777.5	6.00535
2780.16	5.61473
2782.83	5.30303
2785.49	4.14787
2788.15	3.39534
2790.82	2.57086
2793.48	1.42493
2796.14	0.606319
2798.79	-0.238946
2801.45	0.0325093
2804.11	-0.202267
2806.76	-1.27208
2809.42	-2.36178
2812.07	-2.41831
2814.73	-1.57214
2817.38	-0.0433029
2820.03	1.73437
2822.68	4.03108
2825.33	8.03742
2827.98	11.2845
2830.63	15.0313
2833.27	19.8125
2835.92	25.1339
2838.56	30.3855
2841.21	37.2256
2843.85	44.2839
2846.49	53.0666
2849.13	61.7299
2851.77	70.7143
2854.41	79.6366
2857.05	89.0286
2859.69	97.5187
2862.32	105.949
2864.96	114.4
2867.59	121.522
2870.23	127.349
2872.86	132.245
2875.49	138.519
2878.12	144.009
2880.75	147.068
2883.38	150.75
2886.01	155.669
2888.63	159.451
2891.26	163.139
2893.89	167.129
2896.51	172.092
2899.13	176.43
2901.76	181.754
2904.38	186.586
2907	193.996
2909.62	203.096
2912.24	211.03
2914.85	218.883
2917.47	226.619
2920.09	233.447
2922.7	239.207
2925.32	241.739
2927.93	244.211
2930.54	243.574
2933.15	242.073
2935.76	239.442
2938.37	234.297
2940.98	228.209
2943.59	220.291
2946.2	212.501
2948.8	204.738
2951.41	195.464
2954.01	185.906
2956.62	176.11
2959.22	167.272
2961.82	158.216
2964.42	148.15
2967.02	139.711
2969.62	132.227
2972.22	125.22
2974.81	117.989
2977.41	110.894
2980	103.515
2982.6	95.3922
2985.19	88.4
2987.78	80.1838
2990.38	73.3022
2992.97	65.5508
2995.56	58.1242
2998.14	51.6044
3000.73	44.9212
3003.32	37.4154
3005.91	32.0666
3008.49	26.1792
3011.07	21.6617
3013.66	17.3168
3016.24	13.1962
3018.82	9.88046
3021.4	7.51042
3023.98	5.38099
3026.56	2.7867
3029.14	0.988691
3031.71	-0.30381
3034.29	-0.237168
3036.87	-0.432822
3039.44	1.05926
3042.01	1.4472
3044.59	2.44055
3047.16	3.94605
3049.73	6.10669
3052.3	6.21649
3054.87	7.55509
3057.43	8.29347
3060	8.72042
3062.57	8.07101
3065.13	7.829
3067.7	8.12581
3070.26	7.95915
3072.82	7.44932
3075.39	6.56975
3077.95	5.31836
3080.51	4.31711
3083.07	3.55063
3085.63	3.08076
3088.18	2.42271
3090.74	2.72578
3093.29	3.0341
3095.85	4.09945
3098.4	5.26808
3100.95	6.03089
3103.51	6.09259
3106.06	7.64901
3108.61	8.87922
3111.16	10.2384
3113.71	12.1619
3116.25	14.2454
3118.8	15.9932
3121.35	17.0188
3123.89	18.4767
3126.44	20.0432
3128.98	21.4568
3131.52	23.1204
3134.06	24.4684
3136.6	25.8642
3139.14	26.5939
3141.68	28.5002
3144.22	30.1153
3146.76	30.4463
3149.29	28.4352