File: data/Raman/poly_smoothed/Mb_00_13_05_1x_45s_532 nm_x100_100%_600 gr_mm_01.txt
#Acq. time (s)=	45
#Accumulations=	2
#Range (cm-¹)=	200...3150
#Windows=	2
#Auto scanning=	Off
#Autofocus=	Off
#Macrospot=	Off
#AutoExposure=	Off
#Spike filter=	Multiple accum.
#Delay time (s)=	0
#Binning=	1
#Readout mode=	Signal
#DeNoise=	Off
#ICS correction=	On
#Dark correction=	Off
#Inst. Process=	Off
#Detector Gain=	Best Dynamic Range
#Detector ADC=	20 kHz
#Detector temperature (°C)=	-69.85
#Instrument=	LabRAM HR Evol
#Detector=	Synapse
#Objective=	x100
#Grating=	600 gr/mm
#ND Filter=	100%
#Laser (nm)=	532
#Hole=	100.021
#Range=	Auto
#Laser Pol.=	No
#Raman. Pol.=	No
#Laser Pol. (°)=	-0.0007625
#Raman Pol. (°)=	89.9995
#Collection=	Microscope
#StageXY=	Marzhauser
#StageZ=	Marzhauser
#X (µm)=	-974.7
#Y (µm)=	-2924.1
#Z (µm)=	527.75
#Full time(mm:ss)=	3:18
#Project=
#Sample=
#Site=
#Title=	Mb_00_13_05_2x_45s_532 nm_x100_100%_600 gr_mm
#Remark=
#Date=	06.07.2022 10:02
#Acquired=	06.07.2022 10:02:08
#Base:Fit=	10.08.2022 10:16:36
#Base:Fit=	10.08.2022 10:16:56
#Base:Sub=	10.08.2022 10:17:24
#Filter:Polynom=	16.08.2022 10:36:38
#AxisType[0]=Intens
#AxisUnit[0]=Cnt
#AxisType[1]=Spectr
#AxisUnit[1]=1/cm
200.398	18.0346
204.027	20.9573
207.657	21.419
211.283	22.4019
214.909	23.5624
218.533	30.757
222.157	40.2415
225.777	51.9401
229.396	63.7681
233.016	74.4442
236.632	83.4933
240.247	91.7407
243.86	97.4985
247.474	102.332
251.085	106.252
254.694	111.517
258.301	114.987
261.908	117.057
265.513	117.363
269.116	114.131
272.718	109.404
276.319	103.941
279.918	96.0232
283.516	84.943
287.113	72.5266
290.708	62.8915
294.302	55.6736
297.894	46.2099
301.485	38.7139
305.073	31.6564
308.661	28.2996
312.247	24.6472
315.833	20.5192
319.415	17.3773
322.997	13.6032
326.579	13.4513
330.156	12.786
333.735	12.7857
337.31	12.6815
340.885	12.1426
344.458	10.0309
348.03	8.76204
351.6	7.41541
355.17	6.90331
358.737	5.79692
362.304	8.14273
365.868	12.5244
369.431	16.0796
372.994	19.9342
376.554	26.4023
380.112	32.4088
383.669	39.9399
387.225	47.9577
390.781	58.4936
394.334	67.0014
397.885	75.8231
401.436	81.451
404.984	89.1243
408.532	92.4142
412.078	94.0931
415.623	94.7503
419.166	92.0181
422.708	87.0228
426.248	79.9025
429.788	72.8033
433.326	64.6386
436.86	54.149
440.395	42.8525
443.929	33.8651
447.461	24.3764
450.99	17.7018
454.52	9.9193
458.048	3.20884
461.573	-0.631703
465.099	-0.422271
468.623	1.15881
472.144	2.08028
475.666	5.30951
479.184	5.69614
482.703	6.54278
486.218	10.0557
489.734	13.3942
493.247	16.7648
496.759	19.5382
500.271	23.4079
503.779	27.5624
507.287	30.3178
510.795	35.9432
514.299	40.0696
517.803	42.4918
521.305	43.8725
524.805	44.1324
528.307	44.3936
531.805	42.7658
535.301	39.8633
538.797	38.8904
542.291	36.123
545.783	36.215
549.275	32.5065
552.765	29.5653
556.253	24.6804
559.738	20.5627
563.224	18.2581
566.709	15.087
570.192	14.1855
573.674	12.8004
577.153	12.3161
580.632	11.1027
584.11	9.00696
587.587	8.28028
591.06	8.37498
594.534	7.37732
598.005	7.64472
601.476	9.01092
604.944	8.26017
608.413	9.50927
611.878	9.17823
615.344	6.04064
618.807	4.43046
622.27	5.14345
625.73	6.50994
629.189	9.34367
632.648	11.9768
636.105	14.9703
639.559	16.8249
643.013	20.8972
646.467	22.7716
649.918	23.2493
653.368	23.2153
656.816	23.2864
660.263	23.0642
663.708	22.9423
667.153	21.4222
670.596	22.4346
674.037	22.6709
677.478	22.058
680.917	22.3013
684.355	21.7507
687.791	21.4096
691.224	20.2031
694.658	18.1197
698.091	16.0987
701.522	16.9332
704.95	18.7776
708.379	22.2852
711.806	26.4616
715.23	28.5748
718.655	29.3522
722.078	30.3297
725.498	31.8245
728.919	32.9999
732.337	33.8382
735.755	32.7345
739.17	33.5442
742.584	36.786
745.998	37.0854
749.409	38.8241
752.819	40.2436
756.23	42.98
759.637	42.4269
763.043	40.6147
766.448	41.4067
769.853	41.741
773.255	42.5314
776.656	43.9205
780.056	45.997
783.454	47.1715
786.851	50.0434
790.247	52.2448
793.641	55.0484
797.034	54.2117
800.426	54.8139
803.817	58.515
807.206	61.1694
810.592	61.1324
813.979	61.876
817.364	64.0741
820.748	65.1524
824.129	67.9937
827.511	69.6579
830.891	70.0265
834.269	70.8862
837.646	71.3189
841.023	69.1057
844.396	65.7301
847.77	64.1615
851.141	64.4973
854.513	59.4073
857.881	55.8132
861.248	53.7033
864.616	50.2557
867.98	49.9672
871.343	46.3391
874.707	44.6095
878.068	40.4478
881.428	39.2486
884.786	40.2622
888.143	39.5394
891.498	37.5166
894.855	37.763
898.208	38.8371
901.56	41.9183
904.91	43.9725
908.26	46.718
911.608	47.0121
914.955	47.682
918.298	48.2816
921.643	49.6535
924.986	49.482
928.328	49.1783
931.668	50.0684
935.006	50.0349
938.344	49.0552
941.681	47.8599
945.014	46.6653
948.349	45.1102
951.682	43.2293
955.012	41.4364
958.343	38.0577
961.67	38.9947
964.998	43.9137
968.323	47.9198
971.649	50.3471
974.971	55.1653
978.293	60.0213
981.615	62.3511
984.933	64.2833
988.251	65.8112
991.567	67.3476
994.884	69.9507
998.198	71.8414
1001.51	72.702
1004.82	72.2449
1008.13	73.0787
1011.44	72.7914
1014.75	74.5421
1018.06	78.9095
1021.36	83.7811
1024.66	88.8146
1027.97	94.9896
1031.27	100.389
1034.57	103.927
1037.87	105.86
1041.16	110.075
1044.46	115.252
1047.76	116.23
1051.05	114.922
1054.34	112.764
1057.63	110.419
1060.92	106.221
1064.21	99.585
1067.5	92.6264
1070.78	85.1081
1074.07	77.3817
1077.35	68.9911
1080.63	58.896
1083.91	50.2993
1087.19	42.0762
1090.47	37.4992
1093.75	35.3019
1097.03	37.429
1100.3	38.4706
1103.57	39.155
1106.84	36.2831
1110.11	35.3965
1113.38	32.1182
1116.65	26.8739
1119.92	24.2838
1123.19	21.6833
1126.45	17.8232
1129.71	15.1474
1132.97	13.3076
1136.23	13.6632
1139.49	11.6705
1142.75	10.2582
1146.01	8.29692
1149.26	7.42279
1152.52	7.5009
1155.77	8.7841
1159.02	8.12598
1162.27	8.36466
1165.52	9.57897
1168.77	12.8604
1172.02	17.8079
1175.26	22.3287
1178.51	24.4988
1181.75	28.3547
1184.99	31.8939
1188.23	34.9781
1191.47	39.2948
1194.71	42.598
1197.94	48.382
1201.18	53.6516
1204.41	57.5691
1207.65	63.1881
1210.88	68.2543
1214.11	73.9815
1217.34	78.4261
1220.57	82.6055
1223.79	87.9342
1227.02	91.9592
1230.24	93.2277
1233.47	97.8512
1236.69	100.667
1239.91	101.82
1243.13	102.555
1246.34	106.18
1249.56	105.57
1252.78	105.57
1255.99	104.616
1259.2	102.857
1262.42	104.493
1265.63	104.366
1268.84	104.755
1272.04	103.918
1275.25	105.388
1278.46	106.296
1281.66	107.267
1284.86	108.316
1288.07	110.038
1291.27	112.415
1294.47	114.46
1297.66	116.659
1300.86	120.481
1304.06	120.925
1307.25	124.704
1310.44	127.256
1313.64	129.545
1316.83	129.183
1320.02	129.414
1323.2	129.257
1326.39	128.305
1329.58	127.144
1332.76	127.774
1335.95	127.845
1339.13	126.524
1342.31	124.662
1345.49	120.577
1348.67	119.406
1351.85	116.996
1355.02	114.81
1358.2	109.253
1361.37	104.007
1364.54	100.552
1367.71	97.4862
1370.88	93.7059
1374.05	89.966
1377.22	88.0429
1380.39	84.1666
1383.55	82.1203
1386.72	81.8087
1389.88	80.2688
1393.04	78.3278
1396.2	75.8657
1399.36	75.3731
1402.52	76.5582
1405.68	80.1676
1408.83	86.8129
1411.98	93.1346
1415.14	102.503
1418.29	110.848
1421.44	119.937
1424.59	132.708
1427.74	144.381
1430.89	153.291
1434.03	162.072
1437.18	168.25
1440.32	175.055
1443.46	181.032
1446.6	183.924
1449.74	183.789
1452.88	180.837
1456.02	175.203
1459.16	167.359
1462.29	160.043
1465.43	150.398
1468.56	137.712
1471.69	124.177
1474.82	113.07
1477.95	100.34
1481.08	90.1577
1484.2	80.6828
1487.33	73.8246
1490.46	66.0471
1493.58	59.0811
1496.7	55.167
1499.82	52.1036
1502.94	51.0333
1506.06	48.0093
1509.18	45.9823
1512.29	45.6776
1515.41	45.2672
1518.52	46.0668
1521.63	48.2524
1524.75	46.9832
1527.85	47.7501
1530.96	48.9339
1534.07	49.9192
1537.18	52.919
1540.28	55.4683
1543.39	56.3877
1546.49	59.0959
1549.59	61.5639
1552.69	63.3643
1555.79	64.1752
1558.89	66.1268
1561.99	67.3389
1565.08	67.4812
1568.18	71.878
1571.27	76.7603
1574.37	80.2155
1577.46	82.8242
1580.55	85.7129
1583.64	89.9604
1586.73	92.0823
1589.81	95.5075
1592.9	98.333
1595.98	101.644
1599.06	103.68
1602.15	104.623
1605.23	103.776
1608.31	103.082
1611.39	101.305
1614.46	103.319
1617.54	103.952
1620.61	104.996
1623.69	106.112
1626.76	109.561
1629.83	111.435
1632.9	114.147
1635.97	117.803
1639.04	121.02
1642.11	126.716
1645.17	131.681
1648.24	134.75
1651.3	137.884
1654.36	138.837
1657.42	139.024
1660.48	138.989
1663.54	136.831
1666.6	134.798
1669.66	128.724
1672.71	121.76
1675.77	112.314
1678.82	102.39
1681.87	91.1186
1684.92	80.4465
1687.97	71.1119
1691.02	62.6019
1694.07	52.1016
1697.11	43.9752
1700.16	37.331
1703.2	31.5703
1706.25	25.9281
1709.29	21.5222
1712.33	16.3796
1715.37	12.8435
1718.41	9.743
1721.44	8.11055
1724.48	6.62228
1727.51	6.75758
1730.55	5.76132
1733.58	6.22537
1736.61	7.20642
1739.64	7.75004
1742.67	7.70894
1745.7	6.86884
1748.72	7.81015
1751.75	7.57321
1754.77	6.5468
1757.8	5.22674
1760.82	6.77332
1763.84	6.32772
1766.86	6.42698
1769.88	4.79089
1772.9	5.36087
1775.91	4.41422
1778.93	2.4218
1781.94	2.35286
1784.96	1.18885
1787.97	0.711112
1790.98	0.791386
1793.99	1.1508
1797	0.97491
1800.01	0.897198
1803.01	0.9207
1806.02	0.788115
1809.02	1.74746
1812.02	2.004
1815.02	2.97065
1818.03	2.66346
1821.02	2.89625
1824.02	3.2957
1827.02	2.98554
1830.02	2.94985
1833.01	4.12159
1836.01	5.3535
1839	4.93439
1841.99	3.68645
1844.98	3.69786
1847.97	4.65817
1850.96	5.21626
1853.95	6.79443
1856.93	8.06567
1859.92	8.97019
1862.9	9.10593
1865.88	9.77842
1868.87	9.8216
1871.85	9.24579
1874.83	9.44577
1877.81	9.40435
1880.78	8.79978
1882.53	8.35919
1885.52	8.33474
1888.51	7.89025
1891.5	5.27623
1894.48	5.19479
1897.47	5.54609
1900.45	6.04926
1903.43	6.3813
1906.41	7.10043
1909.39	7.61857
1912.37	8.30076
1915.35	9.60816
1918.33	11.0723
1921.3	11.7194
1924.28	12.5953
1927.25	12.3093
1930.22	11.5126
1933.19	10.9397
1936.16	9.91791
1939.13	9.96055
1942.1	8.83962
1945.07	8.04766
1948.03	7.67247
1951	6.40344
1953.96	5.89407
1956.92	4.94931
1959.88	3.7462
1962.84	2.52161
1965.8	3.23836
1968.76	3.31659
1971.72	2.7599
1974.67	4.36105
1977.63	5.58846
1980.58	6.31631
1983.54	6.26253
1986.49	6.75411
1989.44	6.69599
1992.39	6.82514
1995.33	6.59361
1998.28	7.35464
2001.23	8.28487
2004.17	9.04581
2007.12	10.3683
2010.06	9.4727
2013	7.84261
2015.94	9.76417
2018.88	9.06896
2021.82	9.22074
2024.76	10.7158
2027.69	10.5064
2030.63	11.2089
2033.56	11.2312
2036.5	11.0558
2039.43	10.0605
2042.36	9.70087
2045.29	11.5937
2048.22	11.65
2051.15	11.9271
2054.07	11.0852
2057	11.3969
2059.92	12.0661
2062.85	12.6034
2065.77	12.8621
2068.69	13.9366
2071.61	16.3646
2074.53	15.9442
2077.45	15.0237
2080.37	14.2821
2083.28	12.1933
2086.2	12.6885
2089.11	12.6872
2092.02	12.0799
2094.94	11.294
2097.85	9.70321
2100.76	10.6853
2103.66	9.74947
2106.57	8.97076
2109.48	8.47744
2112.38	8.83482
2115.29	8.58192
2118.19	8.07819
2121.09	7.00808
2123.99	6.47614
2126.89	5.71266
2129.79	6.4604
2132.69	4.58627
2135.59	3.82916
2138.48	3.92084
2141.38	4.92
2144.27	4.68562
2147.17	4.79209
2150.06	4.08161
2152.95	3.86194
2155.84	3.96459
2158.73	3.44589
2161.61	3.86279
2164.5	3.86657
2167.38	4.68068
2170.27	6.25876
2173.15	7.27748
2176.03	7.59426
2178.91	9.29065
2181.8	9.89575
2184.67	8.97459
2187.55	7.60644
2190.43	7.63675
2193.3	7.68384
2196.18	6.57795
2199.05	5.44644
2201.93	4.9698
2204.8	4.02376
2207.67	4.45306
2210.54	4.50957
2213.41	4.31286
2216.27	4.40466
2219.14	5.45363
2222.01	6.2241
2224.87	6.94002
2227.73	7.17074
2230.6	7.20635
2233.46	7.01227
2236.32	7.33832
2239.18	7.87213
2242.03	7.81934
2244.89	8.8637
2247.75	9.20701
2250.6	9.56738
2253.46	9.16444
2256.31	8.84794
2259.16	8.04023
2262.01	8.20421
2264.86	6.20548
2267.71	7.04025
2270.56	7.07895
2273.4	7.09497
2276.25	7.1383
2279.09	5.24798
2281.94	5.87897
2284.78	6.32506
2287.62	6.63945
2290.46	6.63149
2293.3	6.49046
2296.14	5.46979
2298.98	5.58334
2301.82	6.21218
2304.65	6.94888
2307.49	8.16517
2310.32	9.58597
2313.15	9.57304
2315.98	10.129
2318.81	10.2432
2321.64	11.3698
2324.47	11.6507
2327.3	10.6438
2330.12	11.2747
2332.95	11.7749
2335.77	11.9219
2338.6	12.5003
2341.42	12.6949
2344.24	10.9374
2347.06	9.84826
2349.88	7.57923
2352.7	5.90311
2355.51	4.19768
2358.33	3.81089
2361.14	2.21351
2363.96	3.01965
2366.77	3.59574
2369.58	3.72119
2372.39	3.54792
2375.2	3.9793
2378.01	3.39797
2380.82	3.88247
2383.63	4.31432
2386.43	5.15269
2389.24	5.96675
2392.04	6.31904
2394.84	7.17872
2397.65	6.414
2400.45	6.21539
2403.25	6.19415
2406.05	6.32157
2408.84	5.1242
2411.64	5.2052
2414.44	4.79735
2417.23	4.72319
2420.02	3.88532
2422.82	4.321
2425.61	4.61589
2428.4	4.75871
2431.19	4.71936
2433.98	4.23634
2436.77	4.5265
2439.55	3.78289
2442.34	4.39236
2445.12	3.90174
2447.91	4.19849
2450.69	4.56432
2453.47	4.80639
2456.25	5.32926
2459.03	5.14829
2461.81	5.69556
2464.59	4.70512
2467.36	4.40544
2470.14	4.83101
2472.92	4.37675
2475.69	3.96613
2478.46	5.0227
2481.23	5.70195
2484	6.57384
2486.77	6.45924
2489.54	5.35847
2492.31	5.666
2495.08	5.42207
2497.84	4.44376
2500.61	4.35606
2503.37	4.13476
2506.13	4.58498
2508.9	3.45119
2511.66	3.97394
2514.42	3.43051
2517.18	4.65387
2519.93	5.99369
2522.69	6.83747
2525.45	8.09719
2528.2	8.24471
2530.95	7.99538
2533.71	8.38332
2536.46	8.84297
2539.21	8.20771
2541.96	7.88696
2544.71	7.58562
2547.46	8.50464
2550.2	9.0043
2552.95	8.30419
2555.7	9.1704
2558.44	8.58301
2561.18	8.80147
2563.93	8.5574
2566.67	9.54849
2569.41	9.12542
2572.15	9.28871
2574.88	10.3193
2577.62	9.72733
2580.36	11.4694
2583.09	12.3537
2585.83	11.9254
2588.56	12.1755
2591.29	12.0387
2594.02	11.4807
2596.75	11.1077
2599.48	10.7339
2602.21	10.469
2604.94	10.1199
2607.67	8.95506
2610.39	9.83281
2613.12	8.51727
2615.84	9.12471
2618.56	8.18363
2621.28	8.33273
2624.01	8.59941
2626.72	8.46518
2629.44	7.6002
2632.16	8.16093
2634.88	8.24886
2637.59	7.80352
2640.31	9.36179
2643.02	8.89039
2645.74	9.98072
2648.45	11.5
2651.16	11.7511
2653.87	11.6115
2656.58	12.3663
2659.29	12.369
2661.99	12.9328
2664.7	13.8156
2667.41	12.9172
2670.11	13.2073
2672.81	13.5204
2675.51	13.5942
2678.22	14.1772
2680.92	13.9623
2683.62	13.9381
2686.31	13.8515
2689.01	13.6322
2691.71	12.4398
2694.4	12.126
2697.1	13.4611
2699.79	14.4587
2702.49	13.7711
2705.18	14.4562
2707.87	14.7993
2710.56	16.4679
2713.25	17.8199
2715.94	19.1128
2718.62	18.7565
2721.31	19.9162
2723.99	20.9979
2726.68	21.1405
2729.36	20.8947
2732.04	20.4463
2734.73	21.3124
2737.41	20.6079
2740.08	20.5255
2742.76	19.7925
2745.44	17.9503
2748.12	16.2308
2750.79	13.9426
2753.47	13.3846
2756.14	12.0405
2758.81	10.7659
2761.49	9.05105
2764.16	8.02817
2766.83	5.7436
2769.5	3.88329
2772.16	3.07252
2774.83	1.91619
2777.5	1.02254
2780.16	1.10957
2782.83	0.983843
2785.49	0.795803
2788.15	1.15022
2790.82	0.864471
2793.48	1.60537
2796.14	0.165589
2798.79	-1.32675
2801.45	-1.16802
2804.11	-2.34037
2806.76	-2.49018
2809.42	-4.93487
2812.07	-4.23968
2814.73	-3.67745
2817.38	0.195768
2820.03	3.98086
2822.68	8.80365
2825.33	14.5306
2827.98	21.663
2830.63	29.3126
2833.27	38.0536
2835.92	48.0626
2838.56	59.7005
2841.21	73.6397
2843.85	90.3366
2846.49	108.842
2849.13	128.26
2851.77	148.56
2854.41	168.487
2857.05	187.483
2859.69	204.618
2862.32	221.26
2864.96	236.636
2867.59	251.195
2870.23	263.099
2872.86	273.698
2875.49	282.868
2878.12	293.107
2880.75	300.936
2883.38	307.426
2886.01	312.484
2888.63	317.864
2891.26	323.815
2893.89	329.861
2896.51	337.661
2899.13	347.094
2901.76	357.435
2904.38	371.725
2907	389.205
2909.62	407.154
2912.24	426.542
2914.85	444.877
2917.47	460.246
2920.09	475.282
2922.7	486.605
2925.32	494.795
2927.93	499.356
2930.54	499.13
2933.15	495.509
2935.76	488.299
2938.37	477.829
2940.98	463.97
2943.59	445.159
2946.2	426.771
2948.8	406.772
2951.41	386.126
2954.01	364.968
2956.62	344.024
2959.22	324.434
2961.82	305.16
2964.42	287.674
2967.02	272.593
2969.62	259.146
2972.22	245.32
2974.81	231.695
2977.41	218.717
2980	205.277
2982.6	192.163
2985.19	177.473
2987.78	162.305
2990.38	145.718
2992.97	130.83
2995.56	115.559
2998.14	101.67
3000.73	86.2225
3003.32	72.4052
3005.91	59.8852
3008.49	47.6255
3011.07	38.3611
3013.66	29.1474
3016.24	21.2597
3018.82	14.5195
3021.4	8.83496
3023.98	5.29407
3026.56	3.21259
3029.14	2.01946
3031.71	1.25115
3034.29	1.43009
3036.87	2.28119
3039.44	3.33899
3042.01	5.88833
3044.59	7.99544
3047.16	8.74045
3049.73	10.8172
3052.3	11.4978
3054.87	12.5373
3057.43	12.4067
3060	12.4189
3062.57	12.1263
3065.13	11.6414
3067.7	10.7425
3070.26	9.69799
3072.82	8.19273
3075.39	6.98432
3077.95	5.12195
3080.51	2.2609
3083.07	0.915389
3085.63	0.181181
3088.18	-1.38967
3090.74	-1.28093
3093.29	-2.10689
3095.85	-1.18633
3098.4	-0.786834
3100.95	0.864448
3103.51	3.67035
3106.06	5.77744
3108.61	8.09538
3111.16	10.2088
3113.71	12.8849
3116.25	14.8635
3118.8	17.0598
3121.35	20.4392
3123.89	22.9326
3126.44	25.7399
3128.98	28.6038
3131.52	30.4469
3134.06	33.7134
3136.6	35.7075
3139.14	37.7784
3141.68	40.1525
3144.22	42.4809
3146.76	44.6106
3149.29	49.3342