File: data/Raman/poly_smoothed/Mb_00_13_10_1x_45s_532 nm_x100_100%_600 gr_mm_01.txt
#Acq. time (s)=	45
#Accumulations=	2
#Range (cm-¹)=	200...3150
#Windows=	2
#Auto scanning=	Off
#Autofocus=	Off
#Macrospot=	Off
#AutoExposure=	Off
#Spike filter=	Multiple accum.
#Delay time (s)=	0
#Binning=	1
#Readout mode=	Signal
#DeNoise=	Off
#ICS correction=	On
#Dark correction=	Off
#Inst. Process=	Off
#Detector Gain=	Best Dynamic Range
#Detector ADC=	20 kHz
#Detector temperature (°C)=	-69.85
#Instrument=	LabRAM HR Evol
#Detector=	Synapse
#Objective=	x100
#Grating=	600 gr/mm
#ND Filter=	100%
#Laser (nm)=	532
#Hole=	100.021
#Range=	Auto
#Laser Pol.=	No
#Raman. Pol.=	No
#Laser Pol. (°)=	-0.0007625
#Raman Pol. (°)=	89.9995
#Collection=	Microscope
#StageXY=	Marzhauser
#StageZ=	Marzhauser
#X (µm)=	-1011
#Y (µm)=	-2947.9
#Z (µm)=	527.85
#Full time(mm:ss)=	3:18
#Project=
#Sample=
#Site=
#Title=	Mb_00_13_10_2x_45s_532 nm_x100_100%_600 gr_mm
#Remark=
#Date=	06.07.2022 10:21
#Acquired=	06.07.2022 10:21:41
#Base:Fit=	10.08.2022 10:16:56
#Base:Sub=	10.08.2022 10:17:24
#Filter:Polynom=	16.08.2022 10:36:38
#AxisType[0]=Intens
#AxisUnit[0]=Cnt
#AxisType[1]=Spectr
#AxisUnit[1]=1/cm
200.398	3.79615
204.027	3.09487
207.657	0.369764
211.283	-1.87699
214.909	-1.97289
218.533	-0.945231
222.157	3.29646
225.777	8.48393
229.396	14.4478
233.016	19.5195
236.632	25.0667
240.247	28.4772
243.86	31.2337
247.474	34.6406
251.085	38.5493
254.694	41.1281
258.301	42.3373
261.908	44.3616
265.513	45.1769
269.116	44.5716
272.718	42.201
276.319	41.2634
279.918	37.4012
283.516	34.5138
287.113	28.7568
290.708	23.7756
294.302	19.3972
297.894	15.8602
301.485	13.2128
305.073	11.8729
308.661	11.3841
312.247	10.0282
315.833	9.94889
319.415	10.2413
322.997	9.90706
326.579	10.5798
330.156	9.19095
333.735	9.1192
337.31	9.94982
340.885	7.97802
344.458	7.46198
348.03	5.78309
351.6	5.13459
355.17	5.29913
358.737	4.24005
362.304	5.55298
365.868	6.50051
369.431	6.33441
372.994	5.19253
376.554	6.40474
380.112	9.72693
383.669	12.9101
387.225	18.8651
390.781	23.3335
394.334	28.8972
397.885	32.6538
401.436	36.5971
404.984	39.0474
408.532	41.7137
412.078	43.3034
415.623	42.4548
419.166	41.8452
422.708	41.3687
426.248	37.8653
429.788	34.405
433.326	30.7501
436.86	23.6274
440.395	20.5987
443.929	17.8605
447.461	13.3285
450.99	10.8685
454.52	7.01354
458.048	4.93355
461.573	3.371
465.099	2.49264
468.623	3.49647
472.144	4.41028
475.666	4.15542
479.184	5.0925
482.703	4.89283
486.218	5.94513
489.734	7.77589
493.247	9.51536
496.759	12.8878
500.271	15.5855
503.779	17.4471
507.287	19.2097
510.795	20.5343
514.299	21.5767
517.803	22.5909
521.305	22
524.805	23.7817
528.307	25.9195
531.805	26.6349
535.301	27.2775
538.797	27.0188
542.291	25.53
545.783	23.0188
549.275	20.8935
552.765	17.968
556.253	15.6395
559.738	12.1834
563.224	9.51314
566.709	7.74281
570.192	7.29743
573.674	5.79783
577.153	3.77594
580.632	4.00956
584.11	4.60027
587.587	1.78122
591.06	0.0422052
594.534	-1.11131
598.005	0.0211547
601.476	-0.0637268
604.944	-0.0981348
608.413	-0.10611
611.878	1.08706
615.344	2.97722
618.807	3.0793
622.27	2.83485
625.73	3.35072
629.189	3.3937
632.648	3.83637
636.105	5.0146
639.559	4.82473
643.013	5.36113
646.467	5.7054
649.918	5.64623
653.368	6.25503
656.816	6.34623
660.263	6.51368
663.708	7.56564
667.153	9.89849
670.596	9.17123
674.037	10.4482
677.478	10.2576
680.917	12.1239
684.355	11.7449
687.791	12.9136
691.224	13.4158
694.658	13.9589
698.091	15.8255
701.522	17.504
704.95	18.6949
708.379	20.2792
711.806	23.3489
715.23	23.8032
718.655	23.8591
722.078	23.7449
725.498	23.2603
728.919	21.6348
732.337	22.1831
735.755	22.8633
739.17	22.7609
742.584	24.934
745.998	26.1141
749.409	30.5582
752.819	35.9916
756.23	39.4036
759.637	42.6475
763.043	45.3802
766.448	49.9551
769.853	53.5237
773.255	57.3697
776.656	60.5764
780.056	62.5592
783.454	66.1307
786.851	69.6115
790.247	72.2289
793.641	74.0746
797.034	73.5018
800.426	72.9393
803.817	71.8451
807.206	69.2768
810.592	67.5661
813.979	65.3268
817.364	64.6328
820.748	63.3805
824.129	62.3882
827.511	62.4345
830.891	60.9561
834.269	61.4379
837.646	60.4029
841.023	59.0678
844.396	57.5111
847.77	55.5159
851.141	54.0533
854.513	51.8937
857.881	50.7344
861.248	48.3054
864.616	47.1808
867.98	47.675
871.343	45.7243
874.707	43.2965
878.068	41.9696
881.428	41.6518
884.786	40.4394
888.143	38.0868
891.498	37.9855
894.855	38.6163
898.208	38.826
901.56	38.2651
904.91	38.9441
908.26	37.6143
911.608	36.942
914.955	36.1333
918.298	36.9159
921.643	37.4347
924.986	36.8649
928.328	37.5422
931.668	36.8047
935.006	36.129
938.344	33.3751
941.681	32.8374
945.014	33.3542
948.349	32.6321
951.682	30.7316
955.012	30.5213
958.343	29.212
961.67	30.3715
964.998	32.8849
968.323	34.6969
971.649	36.4171
974.971	38.8709
978.293	40.5862
981.615	41.2636
984.933	42.325
988.251	42.1625
991.567	44.1822
994.884	43.9989
998.198	45.3776
1001.51	45.3996
1004.82	44.7587
1008.13	44.1384
1011.44	42.2317
1014.75	41.5335
1018.06	42.0944
1021.36	46.3628
1024.66	50.404
1027.97	54.7521
1031.27	57.2548
1034.57	58.8542
1037.87	59.1352
1041.16	60.3155
1044.46	63.8534
1047.76	63.9105
1051.05	62.2487
1054.34	62.9377
1057.63	61.148
1060.92	58.4925
1064.21	57.0428
1067.5	55.4959
1070.78	52.8544
1074.07	49.7673
1077.35	44.8608
1080.63	41.2704
1083.91	36.562
1087.19	32.4789
1090.47	30.5673
1093.75	28.9632
1097.03	29.8486
1100.3	30.727
1103.57	31.5795
1106.84	29.9182
1110.11	28.4935
1113.38	26.4309
1116.65	22.7574
1119.92	21.0468
1123.19	20.8314
1126.45	19.9629
1129.71	17.01
1132.97	15.2483
1136.23	14.0276
1139.49	13.5137
1142.75	12.6884
1146.01	11.9038
1149.26	10.6553
1152.52	9.35044
1155.77	8.50996
1159.02	7.76349
1162.27	7.08679
1165.52	7.00376
1168.77	8.29499
1172.02	8.75107
1175.26	8.35268
1178.51	11.1713
1181.75	14.4681
1184.99	17.2704
1188.23	17.8598
1191.47	19.077
1194.71	21.0775
1197.94	23.4164
1201.18	26.9493
1204.41	29.6698
1207.65	33.5822
1210.88	34.835
1214.11	37.7055
1217.34	40.3231
1220.57	45.4701
1223.79	48.1633
1227.02	51.8011
1230.24	54.336
1233.47	55.6965
1236.69	57.7148
1239.91	58.509
1243.13	58.4787
1246.34	58.4056
1249.56	58.1344
1252.78	58.008
1255.99	59.8861
1259.2	60.8942
1262.42	59.4845
1265.63	58.0627
1268.84	59.0168
1272.04	59.3266
1275.25	61.0576
1278.46	62.1376
1281.66	62.9765
1284.86	64.4909
1288.07	65.7047
1291.27	67.058
1294.47	70.8093
1297.66	73.9221
1300.86	76.7687
1304.06	78.7502
1307.25	81.1828
1310.44	82.1238
1313.64	85.6733
1316.83	87.5709
1320.02	87.8884
1323.2	87.8675
1326.39	89.5956
1329.58	89.6726
1332.76	91.8973
1335.95	92.2848
1339.13	92.1412
1342.31	91.368
1345.49	92.8612
1348.67	92.2412
1351.85	91.5732
1355.02	90.2949
1358.2	88.6777
1361.37	87.0895
1364.54	85.587
1367.71	83.6086
1370.88	81.0085
1374.05	77.235
1377.22	74.5014
1380.39	72.0046
1383.55	70.1984
1386.72	68.1867
1389.88	66.0156
1393.04	64.2967
1396.2	60.9995
1399.36	59.2073
1402.52	59.4586
1405.68	59.8304
1408.83	62.4979
1411.98	65.1214
1415.14	70.0045
1418.29	74.4843
1421.44	80.3925
1424.59	85.7448
1427.74	91.6155
1430.89	99.2631
1434.03	104.806
1437.18	107.964
1440.32	111.489
1443.46	114.992
1446.6	116.416
1449.74	116.489
1452.88	114.953
1456.02	112.94
1459.16	109.595
1462.29	105.308
1465.43	99.5302
1468.56	91.4758
1471.69	84.3435
1474.82	76.3377
1477.95	71.3223
1481.08	65.9045
1484.2	59.8553
1487.33	55.3041
1490.46	51.5904
1493.58	48.0032
1496.7	45.5925
1499.82	43.8099
1502.94	41.1261
1506.06	40.5803
1509.18	39.2979
1512.29	37.8369
1515.41	37.511
1518.52	39.6654
1521.63	40.2283
1524.75	41.0448
1527.85	42.5638
1530.96	44.2719
1534.07	45.1221
1537.18	46.5043
1540.28	46.7506
1543.39	48.394
1546.49	50.6369
1549.59	51.3543
1552.69	53.4283
1555.79	55.2991
1558.89	58.1737
1561.99	59.7377
1565.08	61.0026
1568.18	64.7318
1571.27	67.8083
1574.37	69.06
1577.46	69.1301
1580.55	71.9709
1583.64	72.7002
1586.73	72.7606
1589.81	74.5361
1592.9	74.4354
1595.98	74.5517
1599.06	74.2404
1602.15	74.7185
1605.23	73.9636
1608.31	72.7269
1611.39	70.581
1614.46	70.9761
1617.54	71.0295
1620.61	71.5047
1623.69	70.5175
1626.76	69.8994
1629.83	71.5359
1632.9	72.9397
1635.97	73.1564
1639.04	74.0227
1642.11	76.8966
1645.17	78.3034
1648.24	79.4594
1651.3	79.9909
1654.36	81.6481
1657.42	81.401
1660.48	79.9683
1663.54	77.5405
1666.6	75.8945
1669.66	73.872
1672.71	70.373
1675.77	66.1055
1678.82	61.3625
1681.87	57.2609
1684.92	53.8766
1687.97	48.8719
1691.02	45.0948
1694.07	40.4809
1697.11	36.2983
1700.16	32.269
1703.2	31.2059
1706.25	26.8487
1709.29	22.7519
1712.33	19.3601
1715.37	19.125
1718.41	18.2227
1721.44	17.6107
1724.48	16.9765
1727.51	14.9515
1730.55	14.0141
1733.58	12.3623
1736.61	11.2639
1739.64	11.5947
1742.67	10.0272
1745.7	9.28494
1748.72	8.21424
1751.75	8.45454
1754.77	7.18191
1757.8	6.14381
1760.82	4.47855
1763.84	5.19436
1766.86	4.51458
1769.88	4.70204
1772.9	4.91225
1775.91	5.24836
1778.93	5.68285
1781.94	4.12009
1784.96	4.79188
1787.97	5.93472
1790.98	7.05396
1793.99	6.73503
1797	6.8968
1800.01	7.29432
1803.01	8.05693
1806.02	7.56881
1809.02	8.53804
1812.02	8.91055
1815.02	8.12447
1818.03	8.29953
1821.02	7.74992
1824.02	5.44934
1827.02	4.00746
1830.02	3.84062
1833.01	3.21982
1836.01	3.2013
1839	2.86253
1841.99	2.27908
1844.98	1.55382
1847.97	1.11367
1850.96	1.55744
1853.95	1.27433
1856.93	0.558213
1859.92	0.275281
1862.9	0.347608
1865.88	0.952649
1868.87	1.98946
1871.85	3.19315
1874.83	3.47201
1877.81	2.7824
1880.78	3.67746
1882.53	4.97619
1885.52	4.77667
1888.51	4.81243
1891.5	4.92748
1894.48	4.26174
1897.47	4.58874
1900.45	5.20974
1903.43	5.36731
1906.41	5.35737
1909.39	6.25021
1912.37	6.25169
1915.35	5.73928
1918.33	6.32702
1921.3	7.38331
1924.28	7.35777
1927.25	6.52106
1930.22	6.17046
1933.19	7.19961
1936.16	7.82557
1939.13	7.70438
1942.1	7.34899
1945.07	6.3237
1948.03	7.09288
1951	7.22643
1953.96	6.80277
1956.92	6.77183
1959.88	5.77685
1962.84	5.25093
1965.8	4.1511
1968.76	3.04282
1971.72	2.77825
1974.67	2.81495
1977.63	3.74588
1980.58	3.26705
1983.54	3.08009
1986.49	2.89454
1989.44	3.45683
1992.39	3.09982
1995.33	3.4998
1998.28	2.27629
2001.23	3.17921
2004.17	3.35247
2007.12	3.07534
2010.06	3.52935
2013	3.50166
2015.94	4.11549
2018.88	4.25973
2021.82	5.37443
2024.76	4.56563
2027.69	3.26047
2030.63	3.02769
2033.56	2.93295
2036.5	2.457
2039.43	3.09465
2042.36	3.62849
2045.29	4.35799
2048.22	5.45144
2051.15	5.14197
2054.07	5.5633
2057	6.15171
2059.92	6.68095
2062.85	7.38831
2065.77	8.08793
2068.69	8.98637
2071.61	8.88999
2074.53	8.77398
2077.45	9.70863
2080.37	9.99417
2083.28	9.90301
2086.2	10.2377
2089.11	9.84017
2092.02	9.21596
2094.94	8.69044
2097.85	7.81106
2100.76	5.69497
2103.66	5.00071
2106.57	4.79422
2109.48	4.00947
2112.38	2.88744
2115.29	2.44976
2118.19	3.03422
2121.09	2.66909
2123.99	2.30793
2126.89	3.29151
2129.79	4.38076
2132.69	5.15115
2135.59	6.58506
2138.48	8.38888
2141.38	6.92113
2144.27	5.82054
2147.17	6.37929
2150.06	6.2273
2152.95	8.12882
2155.84	8.32523
2158.73	7.68335
2161.61	8.25612
2164.5	8.6186
2167.38	7.62341
2170.27	6.15626
2173.15	5.60491
2176.03	4.40486
2178.91	4.47269
2181.8	3.6494
2184.67	3.8008
2187.55	3.492
2190.43	3.13216
2193.3	3.69778
2196.18	4.41214
2199.05	6.10675
2201.93	4.92343
2204.8	5.12224
2207.67	3.8493
2210.54	3.35247
2213.41	2.06864
2216.27	3.06434
2219.14	3.8105
2222.01	4.50534
2224.87	5.71806
2227.73	5.37637
2230.6	5.75146
2233.46	6.08146
2236.32	6.36655
2239.18	5.18278
2242.03	5.86537
2244.89	5.56174
2247.75	5.72295
2250.6	6.75989
2253.46	7.69453
2256.31	7.46417
2259.16	7.27428
2262.01	7.90208
2264.86	8.40831
2267.71	8.06678
2270.56	6.84447
2273.4	5.73326
2276.25	6.5227
2279.09	5.58315
2281.94	4.30187
2284.78	3.24639
2287.62	3.27579
2290.46	3.54746
2293.3	2.91172
2296.14	4.92913
2298.98	5.87735
2301.82	5.47786
2304.65	5.40087
2307.49	6.30078
2310.32	7.32717
2313.15	7.13969
2315.98	7.47099
2318.81	7.42797
2321.64	7.79006
2324.47	7.75476
2327.3	7.14142
2330.12	7.03519
2332.95	7.54381
2335.77	7.21156
2338.6	5.64194
2341.42	5.09994
2344.24	4.50776
2347.06	4.2534
2349.88	3.15878
2352.7	2.49935
2355.51	2.64223
2358.33	2.6877
2361.14	2.30584
2363.96	3.04945
2366.77	3.78704
2369.58	3.85351
2372.39	4.73278
2375.2	6.06043
2378.01	7.13153
2380.82	7.328
2383.63	6.70609
2386.43	6.70054
2389.24	7.32193
2392.04	7.72257
2394.84	7.94813
2397.65	7.41709
2400.45	8.87886
2403.25	8.01402
2406.05	7.73853
2408.84	6.76307
2411.64	6.99583
2414.44	6.45998
2417.23	5.9349
2420.02	4.59532
2422.82	4.05195
2425.61	3.04045
2428.4	2.43022
2431.19	1.98856
2433.98	2.16713
2436.77	1.87134
2439.55	2.12482
2442.34	2.2407
2445.12	1.57301
2447.91	1.47944
2450.69	0.699776
2453.47	-0.195959
2456.25	-0.13414
2459.03	-0.697467
2461.81	-1.10994
2464.59	0.921767
2467.36	2.84327
2470.14	2.64171
2472.92	3.66513
2475.69	3.20641
2478.46	4.21243
2481.23	4.86443
2484	5.67214
2486.77	4.96119
2489.54	4.86772
2492.31	5.87536
2495.08	5.60572
2497.84	4.95668
2500.61	6.08278
2503.37	5.48661
2506.13	6.86858
2508.9	6.49494
2511.66	5.77066
2514.42	5.01309
2517.18	5.21912
2519.93	5.34249
2522.69	6.15696
2525.45	7.60803
2528.2	7.43413
2530.95	8.00416
2533.71	8.47703
2536.46	8.24504
2539.21	7.5917
2541.96	8.02837
2544.71	8.39471
2547.46	9.12141
2550.2	9.19191
2552.95	9.56183
2555.7	8.83544
2558.44	9.78338
2561.18	9.61395
2563.93	8.70584
2566.67	8.35328
2569.41	7.79779
2572.15	7.73954
2574.88	7.27346
2577.62	6.70415
2580.36	6.92379
2583.09	6.79435
2585.83	7.03549
2588.56	8.14614
2591.29	7.63353
2594.02	7.58135
2596.75	7.09888
2599.48	7.47366
2602.21	8.90474
2604.94	9.51382
2607.67	9.79455
2610.39	10.6882
2613.12	11.276
2615.84	12.657
2618.56	12.7002
2621.28	13.2475
2624.01	13.2977
2626.72	13.5952
2629.44	12.4516
2632.16	12.0597
2634.88	11.2884
2637.59	10.5296
2640.31	9.89812
2643.02	8.24831
2645.74	7.94783
2648.45	8.27664
2651.16	7.23304
2653.87	6.98882
2656.58	6.31888
2659.29	5.78385
2661.99	6.24148
2664.7	5.49874
2667.41	5.49871
2670.11	4.87426
2672.81	5.4298
2675.51	5.22644
2678.22	4.90555
2680.92	5.02438
2683.62	5.06463
2686.31	5.44326
2689.01	6.38991
2691.71	6.68153
2694.4	6.86396
2697.1	7.42189
2699.79	8.50233
2702.49	8.59694
2705.18	9.30949
2707.87	9.95508
2710.56	10.7763
2713.25	11.3699
2715.94	11.5063
2718.62	12.4364
2721.31	13.3673
2723.99	15.3523
2726.68	15.0915
2729.36	14.1431
2732.04	14.7714
2734.73	15.1207
2737.41	14.3722
2740.08	13.5636
2742.76	12.3498
2745.44	11.2243
2748.12	10.525
2750.79	8.84656
2753.47	9.23911
2756.14	8.44178
2758.81	7.70543
2761.49	6.35391
2764.16	5.33129
2766.83	4.05928
2769.5	3.30229
2772.16	2.38526
2774.83	1.18202
2777.5	1.38852
2780.16	0.611916
2782.83	0.675153
2785.49	1.22976
2788.15	1.33912
2790.82	1.19567
2793.48	0.0694019
2796.14	0.412911
2798.79	-0.620125
2801.45	-0.673578
2804.11	0.305483
2806.76	0.909186
2809.42	0.559187
2812.07	0.849943
2814.73	3.26521
2817.38	6.52579
2820.03	10.6673
2822.68	15.543
2825.33	18.8582
2827.98	23.9814
2830.63	30.344
2833.27	37.1958
2835.92	44.7059
2838.56	53.267
2841.21	63.5841
2843.85	73.1622
2846.49	84.3047
2849.13	97.2164
2851.77	108.181
2854.41	120.16
2857.05	131.429
2859.69	142.418
2862.32	151.962
2864.96	161.689
2867.59	171.817
2870.23	177.703
2872.86	183.786
2875.49	189.476
2878.12	195.297
2880.75	201.851
2883.38	205.249
2886.01	208.794
2888.63	211.757
2891.26	214.212
2893.89	218.622
2896.51	222.653
2899.13	227.498
2901.76	234.039
2904.38	240.952
2907	249.561
2909.62	258.257
2912.24	268.34
2914.85	278.346
2917.47	287.36
2920.09	292.902
2922.7	297.116
2925.32	299.246
2927.93	300.556
2930.54	298.82
2933.15	295.088
2935.76	289.582
2938.37	284.545
2940.98	275.472
2943.59	266.953
2946.2	257.13
2948.8	244.722
2951.41	233.385
2954.01	222.468
2956.62	210.18
2959.22	198.252
2961.82	188.4
2964.42	176.936
2967.02	167.529
2969.62	157.373
2972.22	149.511
2974.81	141.802
2977.41	132.584
2980	123.513
2982.6	113.673
2985.19	103.178
2987.78	93.5908
2990.38	84.3132
2992.97	75.5376
2995.56	67.4055
2998.14	58.6321
3000.73	51.2414
3003.32	44.4352
3005.91	38.1035
3008.49	32.1192
3011.07	27.1664
3013.66	22.2122
3016.24	16.8493
3018.82	13.4045
3021.4	9.84556
3023.98	7.26089
3026.56	4.24027
3029.14	2.68162
3031.71	1.55091
3034.29	1.4312
3036.87	1.72289
3039.44	1.79992
3042.01	1.91855
3044.59	3.59388
3047.16	4.00558
3049.73	4.81723
3052.3	7.19684
3054.87	7.47845
3057.43	7.5001
3060	7.74545
3062.57	7.1854
3065.13	8.41647
3067.7	8.18542
3070.26	7.0456
3072.82	6.92413
3075.39	5.79177
3077.95	3.94094
3080.51	3.20491
3083.07	2.41651
3085.63	1.00312
3088.18	0.724953
3090.74	0.376673
3093.29	-0.272709
3095.85	1.06002
3098.4	1.87094
3100.95	3.67778
3103.51	5.22073
3106.06	7.25853
3108.61	8.21629
3111.16	9.4998
3113.71	11.9277
3116.25	13.4994
3118.8	15.312
3121.35	17.5892
3123.89	18.9555
3126.44	21.4236
3128.98	23.5551
3131.52	25.6574
3134.06	27.1012
3136.6	27.0102
3139.14	27.8279
3141.68	29.353
3144.22	30.5212
3146.76	31.46
3149.29	32.7706