File: data/Raman/poly_smoothed/Mb_00_13_24_1x_45s_532 nm_x100_100%_600 gr_mm_01.txt
#Acq. time (s)=	45
#Accumulations=	2
#Range (cm-¹)=	200...3150
#Windows=	2
#Auto scanning=	Off
#Autofocus=	Off
#Macrospot=	Off
#AutoExposure=	Off
#Spike filter=	Multiple accum.
#Delay time (s)=	0
#Binning=	1
#Readout mode=	Signal
#DeNoise=	Off
#ICS correction=	On
#Dark correction=	Off
#Inst. Process=	Off
#Detector Gain=	Best Dynamic Range
#Detector ADC=	20 kHz
#Detector temperature (°C)=	-69.85
#Instrument=	LabRAM HR Evol
#Detector=	Synapse
#Objective=	x100
#Grating=	600 gr/mm
#ND Filter=	100%
#Laser (nm)=	532
#Hole=	100.021
#Range=	Auto
#Laser Pol.=	No
#Raman. Pol.=	No
#Laser Pol. (°)=	-0.0007625
#Raman Pol. (°)=	89.9995
#Collection=	Microscope
#StageXY=	Marzhauser
#StageZ=	Marzhauser
#X (µm)=	-975.8
#Y (µm)=	-2825.8
#Z (µm)=	528.55
#Full time(mm:ss)=	3:18
#Project=
#Sample=
#Site=
#Title=	Mb_00_13_24_2x_45s_532 nm_x100_100%_600 gr_mm
#Remark=
#Date=	06.07.2022 11:34
#Acquired=	06.07.2022 11:34:55
#Base:Fit=	10.08.2022 10:16:56
#Base:Sub=	10.08.2022 10:17:24
#Filter:Polynom=	16.08.2022 10:36:38
#AxisType[0]=Intens
#AxisUnit[0]=Cnt
#AxisType[1]=Spectr
#AxisUnit[1]=1/cm
200.398	9.79297
204.027	7.27786
207.657	5.21491
211.283	1.78302
214.909	1.59185
218.533	6.45915
222.157	12.2151
225.777	18.376
229.396	26.5744
233.016	37.6589
236.632	46.2686
240.247	55.1881
243.86	62.3449
247.474	68.5378
251.085	75.1295
254.694	81.9963
258.301	87.2727
261.908	89.0333
265.513	88.3475
269.116	85.4285
272.718	79.7652
276.319	74.3788
279.918	67.1728
283.516	60.6397
287.113	52.6389
290.708	43.1763
294.302	36.0138
297.894	27.1338
301.485	23.1716
305.073	19.6758
308.661	16.893
312.247	14.2844
315.833	14.5817
319.415	16.7899
322.997	15.6327
326.579	15.2733
330.156	17.0816
333.735	15.3693
337.31	17.3092
340.885	14.9699
344.458	14.3254
348.03	13.5531
351.6	11.9428
355.17	8.26846
358.737	5.40696
362.304	6.6686
365.868	8.26836
369.431	12.0359
372.994	16.4275
376.554	20.1857
380.112	26.2307
383.669	32.1435
387.225	40.9526
390.781	52.5965
394.334	60.2083
397.885	68.9645
401.436	77.0897
404.984	82.9191
408.532	85.8156
412.078	87.6232
415.623	89.4791
419.166	88.2607
422.708	87.525
426.248	84.6433
429.788	78.4031
433.326	72.5417
436.86	62.975
440.395	53.5939
443.929	47.8854
447.461	39.8282
450.99	36.6649
454.52	34.4337
458.048	31.3098
461.573	27.7984
465.099	24.5851
468.623	26.935
472.144	29.3523
475.666	30.9805
479.184	31.9882
482.703	33.0512
486.218	35.5865
489.734	36.7366
493.247	40.179
496.759	42.6349
500.271	44.771
503.779	47.6456
507.287	49.6878
510.795	52.4526
514.299	52.1074
517.803	50.6847
521.305	52.4214
524.805	52.4269
528.307	53.4846
531.805	52.7684
535.301	50.626
538.797	52.2474
542.291	50.3644
545.783	46.9898
549.275	43.903
552.765	40.3897
556.253	36.1188
559.738	30.3855
563.224	25.9365
566.709	24.0422
570.192	20.2512
573.674	17.5207
577.153	15.1041
580.632	13.284
584.11	11.1163
587.587	10.4096
591.06	8.25073
594.534	7.69443
598.005	7.12396
601.476	5.19459
604.944	7.56724
608.413	8.90954
611.878	10.7215
615.344	10.8022
618.807	10.6289
622.27	14.8182
625.73	17.4904
629.189	20.9722
632.648	24.5973
636.105	26.2598
639.559	29.2645
643.013	30.7866
646.467	29.7886
649.918	31.1169
653.368	32.0238
656.816	29.4681
660.263	28.0893
663.708	28.0498
667.153	25.8666
670.596	24.5829
674.037	21.3553
677.478	21.1988
680.917	18.2813
684.355	17.5775
687.791	17.3981
691.224	14.6111
694.658	12.9495
698.091	12.1087
701.522	12.8464
704.95	13.1162
708.379	16.2567
711.806	17.6553
715.23	19.3927
718.655	19.6636
722.078	18.8016
725.498	19.8484
728.919	17.5186
732.337	18.096
735.755	18.7339
739.17	18.3612
742.584	19.1577
745.998	21.6093
749.409	23.6519
752.819	26.1994
756.23	28.6685
759.637	32.1704
763.043	33.5361
766.448	35.0593
769.853	36.8897
773.255	37.6452
776.656	41.1185
780.056	42.7486
783.454	44.3829
786.851	48.0206
790.247	49.1768
793.641	50.7867
797.034	52.8827
800.426	54.2184
803.817	53.9834
807.206	54.1283
810.592	53.4937
813.979	51.0232
817.364	51.6594
820.748	52.1724
824.129	53.4951
827.511	55.5046
830.891	57.1729
834.269	56.824
837.646	55.5872
841.023	53.2218
844.396	50.7548
847.77	48.7373
851.141	45.144
854.513	43.5174
857.881	39.3757
861.248	35.3296
864.616	31.819
867.98	29.9681
871.343	28.9856
874.707	28.1314
878.068	26.7578
881.428	25.1982
884.786	21.8194
888.143	18.9661
891.498	15.7742
894.855	14.6774
898.208	15.1743
901.56	14.9184
904.91	16.9128
908.26	17.8786
911.608	16.9438
914.955	15.9578
918.298	13.9925
921.643	15.2433
924.986	16.916
928.328	17.7407
931.668	16.7635
935.006	16.3391
938.344	16.4969
941.681	17.564
945.014	16.8464
948.349	18.6392
951.682	21.1303
955.012	21.4205
958.343	18.1979
961.67	16.7013
964.998	18.4509
968.323	23.3169
971.649	30.3798
974.971	39.7832
978.293	48.6444
981.615	58.7738
984.933	66.4274
988.251	72.8627
991.567	75.5247
994.884	78.7802
998.198	82.4035
1001.51	85.0179
1004.82	86.3493
1008.13	82.2006
1011.44	79.394
1014.75	78.7875
1018.06	79.1202
1021.36	80.6766
1024.66	82.5478
1027.97	83.0934
1031.27	86.4037
1034.57	82.7964
1037.87	79.7848
1041.16	78.2211
1044.46	80.8664
1047.76	83.4873
1051.05	87.1593
1054.34	87.5696
1057.63	87.7002
1060.92	84.4089
1064.21	79.9275
1067.5	74.6612
1070.78	66.859
1074.07	59.0215
1077.35	49.3171
1080.63	40.1063
1083.91	31.1918
1087.19	23.4399
1090.47	18.1689
1093.75	17.1308
1097.03	17.7537
1100.3	18.3461
1103.57	20.5865
1106.84	20.9505
1110.11	20.1908
1113.38	18.223
1116.65	12.477
1119.92	11.7592
1123.19	11.3608
1126.45	9.98067
1129.71	11.4393
1132.97	10.0401
1136.23	10.0124
1139.49	8.71488
1142.75	7.90206
1146.01	7.18263
1149.26	6.29819
1152.52	5.33119
1155.77	4.65814
1159.02	4.54267
1162.27	4.58769
1165.52	3.80313
1168.77	5.21547
1172.02	6.14688
1175.26	7.43784
1178.51	7.20537
1181.75	10.7352
1184.99	13.9761
1188.23	16.2717
1191.47	19.5239
1194.71	22.4722
1197.94	28.4206
1201.18	34.5811
1204.41	42.5244
1207.65	48.2869
1210.88	54.6962
1214.11	60.8363
1217.34	67.1473
1220.57	70.8086
1223.79	76.3143
1227.02	82.2068
1230.24	87.4877
1233.47	91.3283
1236.69	91.6515
1239.91	92.6397
1243.13	90.7847
1246.34	92.9171
1249.56	95.2561
1252.78	95.3238
1255.99	94.41
1259.2	93.4089
1262.42	94.1111
1265.63	93.9797
1268.84	97.3691
1272.04	99.3687
1275.25	100.315
1278.46	103.702
1281.66	106.9
1284.86	110.34
1288.07	112.234
1291.27	115.565
1294.47	118.998
1297.66	121.276
1300.86	125.25
1304.06	128.789
1307.25	131.356
1310.44	135.542
1313.64	138.337
1316.83	138.869
1320.02	141.23
1323.2	140.945
1326.39	143.287
1329.58	142.456
1332.76	139.744
1335.95	136.463
1339.13	135.222
1342.31	136.192
1345.49	135.853
1348.67	132.488
1351.85	127.616
1355.02	125.161
1358.2	120.982
1361.37	118.586
1364.54	114.193
1367.71	109.056
1370.88	105.012
1374.05	99.854
1377.22	95.6692
1380.39	92.6563
1383.55	90.8009
1386.72	90.2651
1389.88	88.0381
1393.04	85.6556
1396.2	84.2688
1399.36	79.92
1402.52	80.6017
1405.68	80.8605
1408.83	84.0948
1411.98	91.2387
1415.14	100.556
1418.29	110.805
1421.44	122.801
1424.59	134.54
1427.74	146.68
1430.89	161.659
1434.03	173.763
1437.18	184.902
1440.32	194.256
1443.46	198.61
1446.6	201.298
1449.74	203.453
1452.88	202.298
1456.02	199.147
1459.16	193.552
1462.29	185.333
1465.43	173.938
1468.56	161.731
1471.69	147.889
1474.82	134.849
1477.95	119.535
1481.08	109.545
1484.2	99.0531
1487.33	91.286
1490.46	86.4034
1493.58	81.7157
1496.7	76.0311
1499.82	71.6714
1502.94	68.7144
1506.06	66.5739
1509.18	64.6939
1512.29	61.951
1515.41	60.4475
1518.52	61.5563
1521.63	61.1288
1524.75	60.6411
1527.85	59.7494
1530.96	61.2475
1534.07	60.8881
1537.18	61.2909
1540.28	62.5315
1543.39	62.4877
1546.49	66.361
1549.59	68.7431
1552.69	68.4085
1555.79	72.1094
1558.89	75.6445
1561.99	79.1358
1565.08	83.4474
1568.18	87.1131
1571.27	88.0386
1574.37	91.85
1577.46	95.4717
1580.55	100.094
1583.64	103.554
1586.73	105.284
1589.81	109.596
1592.9	113.911
1595.98	115.119
1599.06	116.384
1602.15	116.454
1605.23	115.894
1608.31	115.343
1611.39	112.453
1614.46	113.198
1617.54	112.046
1620.61	112.973
1623.69	112.905
1626.76	112.052
1629.83	114.555
1632.9	118.858
1635.97	119.704
1639.04	122.712
1642.11	124.884
1645.17	129.935
1648.24	135.061
1651.3	137.901
1654.36	140.134
1657.42	140.473
1660.48	140.498
1663.54	139.276
1666.6	136.614
1669.66	132.297
1672.71	128.171
1675.77	119.296
1678.82	111.229
1681.87	101.43
1684.92	92.2722
1687.97	83.401
1691.02	74.769
1694.07	64.5767
1697.11	58.2485
1700.16	48.5549
1703.2	41.1766
1706.25	35.3285
1709.29	27.5635
1712.33	21.3451
1715.37	17.0016
1718.41	15.2108
1721.44	12.3241
1724.48	10.2185
1727.51	7.80974
1730.55	6.37185
1733.58	5.01026
1736.61	4.41928
1739.64	5.50342
1742.67	5.938
1745.7	3.93663
1748.72	3.14978
1751.75	0.826941
1754.77	1.32503
1757.8	3.92874
1760.82	5.71741
1763.84	4.69419
1766.86	5.68335
1769.88	5.71865
1772.9	5.86439
1775.91	4.51401
1778.93	4.17507
1781.94	4.14644
1784.96	2.28085
1787.97	2.22691
1790.98	3.06755
1793.99	2.50855
1797	1.7941
1800.01	2.16587
1803.01	1.33542
1806.02	1.61546
1809.02	2.73739
1812.02	3.8252
1815.02	3.62195
1818.03	2.85139
1821.02	3.41955
1824.02	4.81581
1827.02	6.23434
1830.02	7.78456
1833.01	8.5379
1836.01	8.46349
1839	8.35635
1841.99	9.50651
1844.98	8.70858
1847.97	8.74344
1850.96	10.2164
1853.95	11.3001
1856.93	11.9565
1859.92	11.808
1862.9	12.1961
1865.88	11.1999
1868.87	11.6866
1871.85	11.9251
1874.83	11.0227
1877.81	11.3313
1880.78	10.5307
1882.53	10.1046
1885.52	8.72524
1888.51	8.72008
1891.5	8.69128
1894.48	9.21337
1897.47	8.80572
1900.45	7.03225
1903.43	5.93065
1906.41	5.58121
1909.39	5.50017
1912.37	6.26295
1915.35	6.29005
1918.33	7.92704
1921.3	8.70304
1924.28	9.9098
1927.25	10.2909
1930.22	10.3952
1933.19	10.7255
1936.16	9.41368
1939.13	8.19423
1942.1	7.95762
1945.07	6.8208
1948.03	6.56491
1951	4.90545
1953.96	4.69457
1956.92	3.77558
1959.88	4.94736
1962.84	4.87479
1965.8	4.59221
1968.76	2.97343
1971.72	3.8037
1974.67	1.80535
1977.63	3.77683
1980.58	6.17305
1983.54	6.27485
1986.49	7.80642
1989.44	9.17198
1992.39	9.55468
1995.33	9.84831
1998.28	11.3488
2001.23	12.6644
2004.17	13.7456
2007.12	14.2065
2010.06	14.0525
2013	14.1746
2015.94	13.2873
2018.88	13.6717
2021.82	13.3891
2024.76	12.1465
2027.69	12.2088
2030.63	11.7446
2033.56	13.0104
2036.5	13.3005
2039.43	12.1177
2042.36	12.235
2045.29	11.2311
2048.22	9.94658
2051.15	10.8547
2054.07	10.6811
2057	10.8998
2059.92	10.6034
2062.85	10.8854
2065.77	11.6164
2068.69	12.1792
2071.61	12.9275
2074.53	13.5253
2077.45	12.657
2080.37	13.3121
2083.28	11.1024
2086.2	9.92182
2089.11	8.12185
2092.02	6.88246
2094.94	6.67146
2097.85	5.93549
2100.76	5.6372
2103.66	6.21029
2106.57	5.61756
2109.48	4.47521
2112.38	5.4712
2115.29	5.73392
2118.19	7.13468
2121.09	7.86815
2123.99	8.75812
2126.89	10.5087
2129.79	10.5897
2132.69	10.5434
2135.59	10.9846
2138.48	11.7098
2141.38	12.6003
2144.27	11.74
2147.17	12.4489
2150.06	11.829
2152.95	10.78
2155.84	10.1416
2158.73	8.52513
2161.61	6.17281
2164.5	5.80058
2167.38	4.59201
2170.27	4.71158
2173.15	4.85758
2176.03	4.88258
2178.91	5.66254
2181.8	6.60183
2184.67	7.34472
2187.55	8.49172
2190.43	8.06829
2193.3	7.43824
2196.18	7.03987
2199.05	6.65286
2201.93	5.36495
2204.8	6.04453
2207.67	7.5979
2210.54	6.41454
2213.41	6.74959
2216.27	8.1729
2219.14	8.10678
2222.01	9.53317
2224.87	11.6131
2227.73	11.6526
2230.6	11.3136
2233.46	12.4806
2236.32	13.7878
2239.18	13.0321
2242.03	15.5335
2244.89	15.6456
2247.75	16.461
2250.6	18.2603
2253.46	18.4932
2256.31	19.1946
2259.16	19.3499
2262.01	17.8632
2264.86	16.9945
2267.71	16.4864
2270.56	15.282
2273.4	14.5158
2276.25	13.4515
2279.09	11.83
2281.94	9.45683
2284.78	10.0318
2287.62	10.5232
2290.46	7.9587
2293.3	7.78343
2296.14	6.52888
2298.98	5.91585
2301.82	6.00071
2304.65	5.21068
2307.49	5.1936
2310.32	5.95766
2313.15	6.92029
2315.98	5.59439
2318.81	5.82321
2321.64	5.77391
2324.47	5.3053
2327.3	6.42837
2330.12	5.88927
2332.95	6.59894
2335.77	5.95897
2338.6	4.86573
2341.42	5.97561
2344.24	4.98532
2347.06	4.70708
2349.88	3.75763
2352.7	3.41255
2355.51	3.77929
2358.33	2.08571
2361.14	3.03124
2363.96	3.46403
2366.77	4.25704
2369.58	4.10347
2372.39	5.44371
2375.2	4.91851
2378.01	6.2223
2380.82	6.08859
2383.63	4.9363
2386.43	3.74059
2389.24	3.37515
2392.04	1.45348
2394.84	2.84744
2397.65	2.13508
2400.45	1.46022
2403.25	1.78687
2406.05	2.15614
2408.84	0.841184
2411.64	-0.326985
2414.44	0.67673
2417.23	2.02111
2420.02	2.47629
2422.82	3.29618
2425.61	3.20527
2428.4	4.0003
2431.19	5.25128
2433.98	5.10082
2436.77	6.13302
2439.55	7.36018
2442.34	8.27024
2445.12	7.53665
2447.91	8.04968
2450.69	8.31649
2453.47	7.85064
2456.25	5.48256
2459.03	5.21067
2461.81	5.54831
2464.59	5.56392
2467.36	4.55298
2470.14	3.41779
2472.92	2.67797
2475.69	2.90484
2478.46	2.28724
2481.23	3.28132
2484	3.30007
2486.77	3.32141
2489.54	3.30999
2492.31	3.78153
2495.08	3.7666
2497.84	4.16274
2500.61	4.10982
2503.37	4.11641
2506.13	5.82013
2508.9	6.53343
2511.66	5.62372
2514.42	6.39223
2517.18	6.04207
2519.93	6.86512
2522.69	6.33215
2525.45	6.42562
2528.2	6.98962
2530.95	6.0774
2533.71	5.073
2536.46	4.65251
2539.21	4.25662
2541.96	5.05008
2544.71	3.94228
2547.46	3.9526
2550.2	3.972
2552.95	4.56008
2555.7	5.50097
2558.44	7.03943
2561.18	6.37561
2563.93	6.42153
2566.67	6.81499
2569.41	8.32963
2572.15	9.57655
2574.88	10.6267
2577.62	9.93771
2580.36	10.1422
2583.09	10.7875
2585.83	11.0694
2588.56	10.5992
2591.29	10.2939
2594.02	9.67129
2596.75	7.71437
2599.48	7.16894
2602.21	6.33049
2604.94	6.08723
2607.67	5.62741
2610.39	5.1305
2613.12	4.68339
2615.84	5.67528
2618.56	6.23489
2621.28	6.8887
2624.01	6.59887
2626.72	7.22541
2629.44	7.85958
2632.16	9.53754
2634.88	10.2853
2637.59	11.6144
2640.31	11.9701
2643.02	14.5253
2645.74	15.0795
2648.45	16.897
2651.16	17.7144
2653.87	17.6819
2656.58	17.5595
2659.29	17.2122
2661.99	17.5073
2664.7	17.6141
2667.41	16.6941
2670.11	15.8755
2672.81	13.6972
2675.51	13.544
2678.22	12.8644
2680.92	13.6076
2683.62	13.2164
2686.31	13.1535
2689.01	12.6571
2691.71	14.1884
2694.4	13.3619
2697.1	13.4788
2699.79	14.3988
2702.49	15.6874
2705.18	16.302
2707.87	19.7518
2710.56	21.2034
2713.25	21.2377
2715.94	22.6436
2718.62	21.4993
2721.31	21.264
2723.99	21.9681
2726.68	21.6195
2729.36	19.9844
2732.04	18.4626
2734.73	16.7987
2737.41	15.2639
2740.08	13.735
2742.76	12.3516
2745.44	12.2555
2748.12	11.4012
2750.79	11.1591
2753.47	10.0419
2756.14	9.52161
2758.81	7.67812
2761.49	7.61354
2764.16	7.45198
2766.83	7.00063
2769.5	6.69813
2772.16	5.70136
2774.83	5.77973
2777.5	3.82014
2780.16	3.04176
2782.83	3.00486
2785.49	2.22356
2788.15	1.67485
2790.82	2.81058
2793.48	1.87191
2796.14	1.63804
2798.79	1.18864
2801.45	0.272978
2804.11	-0.357257
2806.76	-1.73015
2809.42	-1.13169
2812.07	0.048134
2814.73	0.538287
2817.38	2.58542
2820.03	6.07406
2822.68	10.5516
2825.33	16.2092
2827.98	22.3389
2830.63	28.0663
2833.27	35.5718
2835.92	44.5688
2838.56	54.5435
2841.21	66.4182
2843.85	81.0587
2846.49	96.1239
2849.13	111.251
2851.77	128.299
2854.41	144.669
2857.05	162.106
2859.69	175.714
2862.32	190.787
2864.96	204.315
2867.59	215.733
2870.23	227.002
2872.86	236.042
2875.49	245.017
2878.12	252.424
2880.75	258.966
2883.38	264.496
2886.01	270.321
2888.63	275.796
2891.26	279.748
2893.89	283.549
2896.51	290.614
2899.13	298.938
2901.76	310.898
2904.38	322.169
2907	334.671
2909.62	350.394
2912.24	365.409
2914.85	380.314
2917.47	394.585
2920.09	406.345
2922.7	416.317
2925.32	423.374
2927.93	427.695
2930.54	426.911
2933.15	423.83
2935.76	417.398
2938.37	409.221
2940.98	397.352
2943.59	384.005
2946.2	370.1
2948.8	353.52
2951.41	337.185
2954.01	319.269
2956.62	301.31
2959.22	284.62
2961.82	269.289
2964.42	253.476
2967.02	237.341
2969.62	224.87
2972.22	212.762
2974.81	200.951
2977.41	187.501
2980	174.6
2982.6	160.086
2985.19	146.68
2987.78	133.293
2990.38	118.206
2992.97	103.902
2995.56	90.7237
2998.14	77.4447
3000.73	66.2227
3003.32	55.4005
3005.91	45.1216
3008.49	36.5765
3011.07	27.7074
3013.66	20.4472
3016.24	14.1167
3018.82	9.27362
3021.4	4.33381
3023.98	1.85246
3026.56	0.512532
3029.14	-0.858472
3031.71	-1.38027
3034.29	-2.43574
3036.87	-1.78436
3039.44	-1.12163
3042.01	1.95418
3044.59	2.52874
3047.16	5.74156
3049.73	8.84855
3052.3	10.1606
3054.87	10.3096
3057.43	11.8799
3060	12.2171
3062.57	12.4756
3065.13	11.4918
3067.7	10.3164
3070.26	10.206
3072.82	9.61711
3075.39	8.91053
3077.95	8.13497
3080.51	6.81736
3083.07	5.56007
3085.63	4.08863
3088.18	3.4871
3090.74	2.62982
3093.29	1.85133
3095.85	2.2536
3098.4	3.21322
3100.95	5.47753
3103.51	7.60036
3106.06	10.3108
3108.61	12.9786
3111.16	16.676
3113.71	19.1911
3116.25	21.4661
3118.8	25.039
3121.35	27.617
3123.89	29.6267
3126.44	32.0837
3128.98	35.7321
3131.52	38.9609
3134.06	41.8298
3136.6	44.4237
3139.14	47.0504
3141.68	47.4425
3144.22	48.2736
3146.76	49.7475
3149.29	51.7058