File: data/Raman/poly_smoothed/Mb_00_13_42_1x_45s_532 nm_x100_100%_600 gr_mm_01.txt
#Acq. time (s)=	45
#Accumulations=	2
#Range (cm-¹)=	200...3150
#Windows=	2
#Auto scanning=	Off
#Autofocus=	Off
#Macrospot=	Off
#AutoExposure=	Off
#Spike filter=	Multiple accum.
#Delay time (s)=	0
#Binning=	1
#Readout mode=	Signal
#DeNoise=	Off
#ICS correction=	On
#Dark correction=	Off
#Inst. Process=	Off
#Detector Gain=	Best Dynamic Range
#Detector ADC=	20 kHz
#Detector temperature (°C)=	-69.85
#Instrument=	LabRAM HR Evol
#Detector=	Synapse
#Objective=	x100
#Grating=	600 gr/mm
#ND Filter=	100%
#Laser (nm)=	532
#Hole=	100.021
#Range=	Auto
#Laser Pol.=	No
#Raman. Pol.=	No
#Laser Pol. (°)=	-0.0007625
#Raman Pol. (°)=	89.9995
#Collection=	Microscope
#StageXY=	Marzhauser
#StageZ=	Marzhauser
#X (µm)=	-1041.8
#Y (µm)=	-2886.7
#Z (µm)=	528.8
#Full time(mm:ss)=	3:18
#Project=
#Sample=
#Site=
#Title=	Mb_00_13_42_2x_45s_532 nm_x100_100%_600 gr_mm
#Remark=
#Date=	06.07.2022 13:05
#Acquired=	06.07.2022 13:05:50
#Base:Fit=	10.08.2022 10:16:56
#Base:Sub=	10.08.2022 10:17:24
#Filter:Polynom=	16.08.2022 10:36:38
#AxisType[0]=Intens
#AxisUnit[0]=Cnt
#AxisType[1]=Spectr
#AxisUnit[1]=1/cm
200.398	20.2072
204.027	16.055
207.657	10.1184
211.283	6.89812
214.909	10.6429
218.533	19.966
222.157	37.4103
225.777	57.0275
229.396	76.7566
233.016	99.3028
236.632	115.542
240.247	129.333
243.86	140.13
247.474	151.087
251.085	161.5
254.694	166.474
258.301	171.33
261.908	172.27
265.513	170.496
269.116	165.14
272.718	154.84
276.319	142.344
279.918	127.011
283.516	108.621
287.113	92.9629
290.708	75.5579
294.302	61.2058
297.894	49.6086
301.485	40.4574
305.073	35.0185
308.661	31.7946
312.247	28.895
315.833	26.906
319.415	25.4121
322.997	23.3311
326.579	21.4406
330.156	18.97
333.735	16.4935
337.31	13.5249
340.885	10.7803
344.458	8.50984
348.03	5.56405
351.6	1.97168
355.17	1.44208
358.737	-1.77667
362.304	-3.54091
365.868	1.85443
369.431	6.81271
372.994	15.5575
376.554	25.2083
380.112	35.4451
383.669	52.0942
387.225	71.0578
390.781	91.5585
394.334	111.331
397.885	125.866
401.436	139.829
404.984	149.487
408.532	155.77
412.078	158.122
415.623	155.693
419.166	150.474
422.708	143.94
426.248	134.407
429.788	122.58
433.326	107.809
436.86	90.3076
440.395	72.6145
443.929	54.2999
447.461	39.0043
450.99	27.9917
454.52	16.9849
458.048	6.30708
461.573	-0.888096
465.099	-2.87093
468.623	-2.73361
472.144	0.884509
475.666	5.25145
479.184	8.44866
482.703	12.6946
486.218	16.0947
489.734	18.1539
493.247	21.3151
496.759	23.1396
500.271	26.6577
503.779	31.9221
507.287	37.7609
510.795	41.5181
514.299	43.8312
517.803	46.9751
521.305	49.2062
524.805	52.4283
528.307	52.5355
531.805	53.5538
535.301	52.1366
538.797	50.3947
542.291	47.1059
545.783	43.2332
549.275	38.7325
552.765	36.0908
556.253	31.4307
559.738	28.8384
563.224	25.0658
566.709	21.2052
570.192	18.6995
573.674	15.1215
577.153	11.4326
580.632	10.1886
584.11	7.76424
587.587	7.69731
591.06	7.33052
594.534	4.85803
598.005	3.93861
601.476	5.23035
604.944	8.64825
608.413	9.11462
611.878	8.71939
615.344	9.01405
618.807	10.2893
622.27	10.3275
625.73	11.9853
629.189	16.2399
632.648	20.0136
636.105	24.1107
639.559	28.3342
643.013	31.954
646.467	31.1813
649.918	32.6901
653.368	34.1815
656.816	35.6237
660.263	34.4881
663.708	31.729
667.153	29.7975
670.596	27.6149
674.037	25.6495
677.478	23.47
680.917	19.4186
684.355	18.1475
687.791	14.3047
691.224	10.227
694.658	7.10665
698.091	5.80975
701.522	4.69555
704.95	2.40524
708.379	2.59332
711.806	4.17316
715.23	5.03635
718.655	6.31863
722.078	8.50962
725.498	9.12086
728.919	8.73271
732.337	8.563
735.755	10.6016
739.17	11.6811
742.584	11.9625
745.998	12.3145
749.409	15.0132
752.819	19.0977
756.23	22.5925
759.637	24.7796
763.043	24.481
766.448	25.0121
769.853	24.7902
773.255	25.6878
776.656	27.1765
780.056	29.0709
783.454	28.253
786.851	30.0197
790.247	31.6839
793.641	32.0747
797.034	32.6563
800.426	31.6989
803.817	31.8375
807.206	30.5952
810.592	31.1346
813.979	30.9714
817.364	31.2156
820.748	33.7804
824.129	34.3661
827.511	36.2518
830.891	38.4487
834.269	38.8249
837.646	37.3136
841.023	35.0918
844.396	32.7327
847.77	29.9815
851.141	27.6791
854.513	24.4281
857.881	22.079
861.248	19.4383
864.616	17.5893
867.98	16.2373
871.343	13.6019
874.707	11.1644
878.068	8.04716
881.428	6.64627
884.786	5.47649
888.143	6.07314
891.498	8.72591
894.855	8.74991
898.208	8.04892
901.56	7.85321
904.91	7.77322
908.26	7.088
911.608	6.30607
914.955	5.4633
918.298	4.91133
921.643	5.37007
924.986	4.63131
928.328	6.30995
931.668	5.76747
935.006	5.40855
938.344	3.85187
941.681	4.91646
945.014	4.67127
948.349	4.15258
951.682	3.93348
955.012	4.29651
958.343	3.30188
961.67	2.70393
964.998	5.93274
968.323	9.23371
971.649	13.0502
974.971	17.7298
978.293	22.8691
981.615	25.5031
984.933	27.2027
988.251	30.667
991.567	35.197
994.884	39.1428
998.198	42.8312
1001.51	42.839
1004.82	44.4195
1008.13	44.1432
1011.44	43.2118
1014.75	42.3585
1018.06	50.9883
1021.36	62.9313
1024.66	77.5556
1027.97	92.8992
1031.27	106.424
1034.57	117.114
1037.87	125.409
1041.16	132.228
1044.46	138.671
1047.76	142.502
1051.05	143.951
1054.34	141.454
1057.63	138.094
1060.92	131.957
1064.21	124.168
1067.5	114.293
1070.78	101.612
1074.07	88.6547
1077.35	72.4927
1080.63	52.7258
1083.91	35.0603
1087.19	18.1366
1090.47	5.5367
1093.75	1.38879
1097.03	1.4343
1100.3	5.92895
1103.57	10.2117
1106.84	11.1207
1110.11	13.5589
1113.38	11.4723
1116.65	10.4967
1119.92	9.05862
1123.19	7.80799
1126.45	7.37437
1129.71	8.27888
1132.97	6.76142
1136.23	6.26494
1139.49	9.89452
1142.75	9.75144
1146.01	10.3317
1149.26	9.52514
1152.52	9.75603
1155.77	9.58858
1159.02	6.85797
1162.27	5.5745
1165.52	5.09454
1168.77	6.42311
1172.02	8.50264
1175.26	10.8508
1178.51	12.8391
1181.75	15.5405
1184.99	16.6778
1188.23	18.5859
1191.47	19.17
1194.71	19.8018
1197.94	22.1013
1201.18	26.6868
1204.41	30.8573
1207.65	35.6972
1210.88	41.0662
1214.11	46.8967
1217.34	55.341
1220.57	62.4023
1223.79	66.1891
1227.02	73.2664
1230.24	77.798
1233.47	82.45
1236.69	86.1909
1239.91	88.1168
1243.13	91.2007
1246.34	93.2612
1249.56	95.2378
1252.78	95.4556
1255.99	93.5566
1259.2	91.086
1262.42	89.2013
1265.63	85.9588
1268.84	82.6184
1272.04	81.0121
1275.25	80.457
1278.46	82.1763
1281.66	84.0625
1284.86	85.9425
1288.07	89.0395
1291.27	92.5597
1294.47	99.469
1297.66	104.266
1300.86	108.901
1304.06	113.476
1307.25	119.801
1310.44	123.776
1313.64	127.07
1316.83	129.348
1320.02	131.571
1323.2	133.738
1326.39	131.993
1329.58	131.599
1332.76	130.077
1335.95	127.734
1339.13	124.559
1342.31	121.378
1345.49	117.058
1348.67	113.068
1351.85	110.886
1355.02	107.464
1358.2	102.16
1361.37	96.9249
1364.54	90.8795
1367.71	87.8684
1370.88	85.1615
1374.05	80.6034
1377.22	78.0737
1380.39	76.0899
1383.55	74.4339
1386.72	73.4403
1389.88	73.1418
1393.04	71.2833
1396.2	69.3073
1399.36	68.1859
1402.52	69.6155
1405.68	74.0276
1408.83	79.9148
1411.98	89.61
1415.14	100.014
1418.29	109.184
1421.44	123.169
1424.59	137.234
1427.74	150.321
1430.89	163.606
1434.03	173.586
1437.18	185.805
1440.32	194.131
1443.46	200.402
1446.6	207.384
1449.74	208.685
1452.88	207.588
1456.02	204.648
1459.16	198.58
1462.29	189.248
1465.43	177.564
1468.56	162.951
1471.69	147.518
1474.82	132.377
1477.95	118.988
1481.08	107.331
1484.2	95.9231
1487.33	85.2805
1490.46	76.6218
1493.58	66.4335
1496.7	61.0417
1499.82	55.6082
1502.94	50.2863
1506.06	48.001
1509.18	48.0737
1512.29	46.8916
1515.41	47.654
1518.52	47.1284
1521.63	47.2197
1524.75	47.8991
1527.85	48.3705
1530.96	48.071
1534.07	48.23
1537.18	50.3857
1540.28	53.8304
1543.39	54.7391
1546.49	57.2051
1549.59	62.1507
1552.69	64.105
1555.79	67.471
1558.89	69.6114
1561.99	71.5254
1565.08	72.8112
1568.18	75.8743
1571.27	80.4647
1574.37	86.3677
1577.46	93.0084
1580.55	98.4885
1583.64	103.37
1586.73	108.277
1589.81	110.903
1592.9	111.661
1595.98	114.306
1599.06	113.142
1602.15	111.248
1605.23	109.824
1608.31	107.558
1611.39	107.306
1614.46	107.374
1617.54	105.644
1620.61	107.416
1623.69	107.729
1626.76	108.243
1629.83	107.233
1632.9	107.835
1635.97	108.97
1639.04	110.868
1642.11	115.275
1645.17	118.771
1648.24	123.172
1651.3	126.345
1654.36	128.884
1657.42	128.667
1660.48	126.085
1663.54	125.298
1666.6	122.073
1669.66	119.235
1672.71	112.275
1675.77	103.477
1678.82	95.5531
1681.87	88.6619
1684.92	80.3099
1687.97	70.0928
1691.02	61.8127
1694.07	53.993
1697.11	47.9705
1700.16	40.3989
1703.2	33.5611
1706.25	28.5662
1709.29	23.7868
1712.33	20.547
1715.37	16.3143
1718.41	13.8533
1721.44	12.2614
1724.48	10.6444
1727.51	11.3585
1730.55	9.56888
1733.58	9.06846
1736.61	8.31096
1739.64	10.0469
1742.67	9.10069
1745.7	8.64184
1748.72	7.66161
1751.75	9.00329
1754.77	10.3823
1757.8	10.8211
1760.82	10.6299
1763.84	9.93126
1766.86	10.5689
1769.88	9.25054
1772.9	8.67284
1775.91	8.51598
1778.93	6.28187
1781.94	5.12599
1784.96	5.18501
1787.97	4.71635
1790.98	5.28239
1793.99	5.67665
1797	4.98178
1800.01	5.68467
1803.01	4.34288
1806.02	4.10925
1809.02	5.71513
1812.02	4.5464
1815.02	4.4747
1818.03	3.94478
1821.02	5.13491
1824.02	5.54435
1827.02	6.25414
1830.02	6.26175
1833.01	7.38999
1836.01	6.96561
1839	6.7752
1841.99	6.78237
1844.98	4.31188
1847.97	3.01091
1850.96	2.25449
1853.95	2.92853
1856.93	3.16331
1859.92	3.40807
1862.9	3.85849
1865.88	4.27931
1868.87	4.95448
1871.85	6.18344
1874.83	6.42702
1877.81	6.37024
1880.78	6.90662
1882.53	7.01153
1885.52	5.80839
1888.51	5.89676
1891.5	5.86034
1894.48	6.24734
1897.47	6.06512
1900.45	5.18042
1903.43	4.66659
1906.41	6.19458
1909.39	5.33293
1912.37	5.50507
1915.35	3.79639
1918.33	3.34281
1921.3	3.11012
1924.28	2.28845
1927.25	3.21409
1930.22	3.63783
1933.19	4.1916
1936.16	4.89787
1939.13	6.42228
1942.1	7.7256
1945.07	7.79028
1948.03	8.42746
1951	8.71175
1953.96	9.25296
1956.92	9.54873
1959.88	8.97275
1962.84	9.66814
1965.8	8.19553
1968.76	8.3615
1971.72	9.00604
1974.67	8.27546
1977.63	8.48492
1980.58	7.37038
1983.54	6.71952
1986.49	5.52526
1989.44	5.6039
1992.39	6.437
1995.33	6.19685
1998.28	6.29654
2001.23	7.18592
2004.17	7.76888
2007.12	8.77157
2010.06	10.6089
2013	10.0744
2015.94	8.94364
2018.88	8.592
2021.82	8.83205
2024.76	9.26735
2027.69	10.2444
2030.63	9.20188
2033.56	8.68987
2036.5	7.94456
2039.43	7.45728
2042.36	7.28099
2045.29	7.02016
2048.22	7.09922
2051.15	5.53746
2054.07	5.46628
2057	4.44153
2059.92	4.49311
2062.85	5.26639
2065.77	5.06321
2068.69	4.85622
2071.61	4.50198
2074.53	4.51182
2077.45	5.47545
2080.37	5.06294
2083.28	4.5665
2086.2	2.05654
2089.11	1.70654
2092.02	1.8327
2094.94	2.51288
2097.85	4.11174
2100.76	4.58382
2103.66	3.09195
2106.57	2.65201
2109.48	3.16463
2112.38	3.33196
2115.29	3.40099
2118.19	2.56776
2121.09	0.202526
2123.99	1.34668
2126.89	1.52619
2129.79	1.65656
2132.69	2.66807
2135.59	2.92505
2138.48	3.27782
2141.38	2.98741
2144.27	3.33232
2147.17	3.54989
2150.06	4.02692
2152.95	2.28106
2155.84	1.81103
2158.73	1.87929
2161.61	4.34931
2164.5	3.23951
2167.38	3.97804
2170.27	4.20982
2173.15	3.42602
2176.03	3.98423
2178.91	3.57873
2181.8	3.47919
2184.67	3.14394
2187.55	3.13533
2190.43	2.67946
2193.3	3.95268
2196.18	5.68494
2199.05	7.16323
2201.93	7.71175
2204.8	6.97802
2207.67	6.79288
2210.54	6.79001
2213.41	6.77143
2216.27	5.415
2219.14	7.64524
2222.01	7.01543
2224.87	8.45411
2227.73	9.15271
2230.6	9.29929
2233.46	9.2417
2236.32	9.62495
2239.18	9.18249
2242.03	8.78592
2244.89	9.14446
2247.75	8.70724
2250.6	7.95371
2253.46	7.58058
2256.31	8.43728
2259.16	6.15962
2262.01	7.16225
2264.86	5.85607
2267.71	5.64649
2270.56	4.5568
2273.4	4.04048
2276.25	1.9476
2279.09	1.09516
2281.94	-0.0184097
2284.78	-1.23949
2287.62	0.301188
2290.46	0.199477
2293.3	-0.725698
2296.14	0.44614
2298.98	0.42095
2301.82	1.83911
2304.65	2.11851
2307.49	3.10541
2310.32	4.62388
2313.15	5.83748
2315.98	4.35244
2318.81	4.27119
2321.64	5.56903
2324.47	5.67432
2327.3	5.88746
2330.12	6.0168
2332.95	4.8094
2335.77	5.87625
2338.6	5.43364
2341.42	6.56605
2344.24	5.3675
2347.06	4.57742
2349.88	4.93214
2352.7	4.34806
2355.51	4.49533
2358.33	4.31818
2361.14	4.52586
2363.96	5.63063
2366.77	6.76443
2369.58	7.88969
2372.39	9.29488
2375.2	9.18475
2378.01	10.7097
2380.82	10.6715
2383.63	9.18535
2386.43	9.81457
2389.24	9.78419
2392.04	9.10061
2394.84	7.52269
2397.65	5.68105
2400.45	5.02407
2403.25	5.28837
2406.05	5.54205
2408.84	5.76566
2411.64	5.98506
2414.44	4.41858
2417.23	4.72491
2420.02	5.31439
2422.82	5.54544
2425.61	6.15015
2428.4	6.41904
2431.19	7.23651
2433.98	6.86529
2436.77	7.77239
2439.55	9.3556
2442.34	11.3582
2445.12	11.4576
2447.91	11.055
2450.69	9.8449
2453.47	9.47215
2456.25	8.29797
2459.03	6.39216
2461.81	6.07826
2464.59	4.36516
2467.36	3.97357
2470.14	4.68487
2472.92	5.14055
2475.69	5.05829
2478.46	4.1168
2481.23	4.54981
2484	3.4179
2486.77	5.08661
2489.54	5.87366
2492.31	5.13695
2495.08	6.17054
2497.84	6.32561
2500.61	6.32523
2503.37	6.54389
2506.13	7.41683
2508.9	8.90942
2511.66	8.79094
2514.42	8.90711
2517.18	9.19293
2519.93	11.11
2522.69	13.0074
2525.45	13.7796
2528.2	15.1388
2530.95	16.2728
2533.71	16.6028
2536.46	17.9846
2539.21	19.1701
2541.96	20.3785
2544.71	21.3777
2547.46	23.0248
2550.2	23.0454
2552.95	23.7583
2555.7	23.447
2558.44	22.7681
2561.18	21.7638
2563.93	21.9756
2566.67	19.9304
2569.41	19.3741
2572.15	18.9254
2574.88	18.6179
2577.62	17.2433
2580.36	16.8664
2583.09	17.3863
2585.83	17.7672
2588.56	17.9608
2591.29	17.9611
2594.02	19.0927
2596.75	18.5346
2599.48	19.2963
2602.21	18.848
2604.94	19.7762
2607.67	20.6938
2610.39	22.3935
2613.12	24.2009
2615.84	24.6493
2618.56	24.7005
2621.28	25.032
2624.01	25.7351
2626.72	25.0691
2629.44	25.2727
2632.16	25.1192
2634.88	25.0875
2637.59	24.7646
2640.31	24.6933
2643.02	23.3899
2645.74	23.8835
2648.45	23.2735
2651.16	23.5459
2653.87	24.9545
2656.58	24.6344
2659.29	23.4971
2661.99	23.7305
2664.7	23.235
2667.41	23.1897
2670.11	23.0762
2672.81	22.8287
2675.51	23.1271
2678.22	22.7891
2680.92	22.9514
2683.62	22.0749
2686.31	22.2191
2689.01	21.9661
2691.71	22.1827
2694.4	21.4138
2697.1	22.666
2699.79	24.4005
2702.49	24.9218
2705.18	26.3537
2707.87	27.3272
2710.56	28.4893
2713.25	30.1608
2715.94	31.3378
2718.62	32.3758
2721.31	32.9641
2723.99	33.6462
2726.68	35.5465
2729.36	36.4685
2732.04	36.5866
2734.73	36.2882
2737.41	34.8902
2740.08	34.5942
2742.76	32.4792
2745.44	30.5208
2748.12	28.9583
2750.79	28.7085
2753.47	28.1786
2756.14	27.4566
2758.81	26.3502
2761.49	25.7143
2764.16	24.6124
2766.83	23.6976
2769.5	21.588
2772.16	19.705
2774.83	17.8174
2777.5	15.766
2780.16	13.9986
2782.83	13.67
2785.49	12.9567
2788.15	13.0066
2790.82	13.6675
2793.48	12.3445
2796.14	11.707
2798.79	11.3576
2801.45	9.61736
2804.11	9.6231
2806.76	8.08318
2809.42	6.96715
2812.07	8.33917
2814.73	9.60332
2817.38	12.9687
2820.03	19.145
2822.68	23.8994
2825.33	29.056
2827.98	35.4623
2830.63	42.0364
2833.27	49.5753
2835.92	57.9323
2838.56	68.2657
2841.21	81.0259
2843.85	95.4518
2846.49	111.467
2849.13	129.168
2851.77	147.333
2854.41	166.036
2857.05	183.67
2859.69	200.92
2862.32	216.89
2864.96	230.017
2867.59	242.965
2870.23	254.407
2872.86	263.692
2875.49	272.693
2878.12	281.057
2880.75	289.641
2883.38	297.162
2886.01	302.178
2888.63	306.451
2891.26	310.648
2893.89	314.312
2896.51	318.088
2899.13	323.696
2901.76	333.61
2904.38	344.399
2907	355.465
2909.62	368.82
2912.24	383.779
2914.85	397.934
2917.47	411.155
2920.09	421.754
2922.7	429.23
2925.32	435.65
2927.93	438.583
2930.54	439.475
2933.15	436.498
2935.76	430.898
2938.37	422.282
2940.98	411.337
2943.59	397.514
2946.2	382.824
2948.8	365.5
2951.41	350.37
2954.01	331.572
2956.62	312.394
2959.22	295.787
2961.82	278.182
2964.42	262.325
2967.02	247.142
2969.62	232.156
2972.22	219.459
2974.81	207.24
2977.41	194.356
2980	180.47
2982.6	165.78
2985.19	152.073
2987.78	137.017
2990.38	124.047
2992.97	110.946
2995.56	97.71
2998.14	85.1149
3000.73	73.0086
3003.32	61.2229
3005.91	50.3571
3008.49	40.7492
3011.07	33.111
3013.66	25.6306
3016.24	19.4998
3018.82	12.8765
3021.4	8.42529
3023.98	5.33763
3026.56	1.00638
3029.14	-0.210491
3031.71	-2.31948
3034.29	-2.59022
3036.87	-0.658767
3039.44	-0.913677
3042.01	0.648375
3044.59	2.15024
3047.16	4.37604
3049.73	5.97833
3052.3	8.34672
3054.87	11.1475
3057.43	12.7266
3060	13.2745
3062.57	13.3541
3065.13	13.4182
3067.7	13.3413
3070.26	13.7958
3072.82	13.655
3075.39	13.2514
3077.95	12.3516
3080.51	11.0677
3083.07	9.9674
3085.63	8.44829
3088.18	8.02896
3090.74	6.88907
3093.29	6.81168
3095.85	8.23189
3098.4	9.11974
3100.95	10.6612
3103.51	13.2799
3106.06	15.6123
3108.61	18.5769
3111.16	22.5966
3113.71	25.0613
3116.25	28.2687
3118.8	31.5971
3121.35	34.6295
3123.89	38.2434
3126.44	41.8147
3128.98	46.0648
3131.52	49.7183
3134.06	54.4046
3136.6	59.252
3139.14	62.4585
3141.68	66.0651
3144.22	69.2452
3146.76	73.2615
3149.29	76.0013