File: data/Raman/poly_smoothed/Mb_00_13_36_1x_45s_532 nm_x100_100%_600 gr_mm_01.txt
#Acq. time (s)=	45
#Accumulations=	2
#Range (cm-¹)=	200...3150
#Windows=	2
#Auto scanning=	Off
#Autofocus=	Off
#Macrospot=	Off
#AutoExposure=	Off
#Spike filter=	Multiple accum.
#Delay time (s)=	0
#Binning=	1
#Readout mode=	Signal
#DeNoise=	Off
#ICS correction=	On
#Dark correction=	Off
#Inst. Process=	Off
#Detector Gain=	Best Dynamic Range
#Detector ADC=	20 kHz
#Detector temperature (°C)=	-69.85
#Instrument=	LabRAM HR Evol
#Detector=	Synapse
#Objective=	x100
#Grating=	600 gr/mm
#ND Filter=	100%
#Laser (nm)=	532
#Hole=	100.021
#Range=	Auto
#Laser Pol.=	No
#Raman. Pol.=	No
#Laser Pol. (°)=	-0.0007625
#Raman Pol. (°)=	89.9995
#Collection=	Microscope
#StageXY=	Marzhauser
#StageZ=	Marzhauser
#X (µm)=	-1022.4
#Y (µm)=	-2894.5
#Z (µm)=	528.75
#Full time(mm:ss)=	3:18
#Project=
#Sample=
#Site=
#Title=	Mb_00_13_36_2x_45s_532 nm_x100_100%_600 gr_mm
#Remark=
#Date=	06.07.2022 12:37
#Acquired=	06.07.2022 12:37:44
#Base:Fit=	10.08.2022 10:16:56
#Base:Sub=	10.08.2022 10:17:24
#Filter:Polynom=	16.08.2022 10:36:38
#AxisType[0]=Intens
#AxisUnit[0]=Cnt
#AxisType[1]=Spectr
#AxisUnit[1]=1/cm
200.398	-175.573
204.027	-179.731
207.657	-186.018
211.283	-189.063
214.909	-184.264
218.533	-168.455
222.157	-138.479
225.777	-99.4457
229.396	-58.8712
233.016	-17.4282
236.632	22.722
240.247	56.304
243.86	86.4706
247.474	115.472
251.085	145.58
254.694	167.682
258.301	182.711
261.908	194.857
265.513	197.938
269.116	197.548
272.718	188.604
276.319	175.056
279.918	157.511
283.516	132.25
287.113	108.147
290.708	80.4413
294.302	55.5012
297.894	34.1315
301.485	18.6344
305.073	8.23599
308.661	3.62914
312.247	1.21769
315.833	2.59156
319.415	-0.503842
322.997	0.729352
326.579	1.55362
330.156	3.52582
333.735	5.38272
337.31	5.47649
340.885	4.59517
344.458	4.77058
348.03	6.07263
351.6	6.66566
355.17	7.69622
358.737	8.67356
362.304	14.1308
365.868	25.8386
369.431	39.197
372.994	56.0833
376.554	69.8833
380.112	89.4157
383.669	116.921
387.225	151.45
390.781	189.484
394.334	221.236
397.885	252.836
401.436	279.044
404.984	298.399
408.532	311.731
412.078	319.096
415.623	322.813
419.166	317.644
422.708	306.39
426.248	290.085
429.788	269.997
433.326	247.234
436.86	220.295
440.395	195.032
443.929	170.364
447.461	149.138
450.99	129.709
454.52	111.574
458.048	95.2972
461.573	83.7486
465.099	77.8276
468.623	82.7492
472.144	91.5368
475.666	99.73
479.184	102.143
482.703	105.161
486.218	109.479
489.734	112.483
493.247	115.733
496.759	117.816
500.271	119.255
503.779	120.725
507.287	118.838
510.795	119.114
514.299	117.637
517.803	117.832
521.305	118.545
524.805	120.151
528.307	121.003
531.805	119.604
535.301	116.952
538.797	113.065
542.291	110.122
545.783	106.083
549.275	100.433
552.765	92.6699
556.253	85.445
559.738	79.0777
563.224	73.6916
566.709	68.8858
570.192	63.0454
573.674	58.633
577.153	54.5099
580.632	54.2543
584.11	56.5936
587.587	58.4561
591.06	59.6435
594.534	62.7347
598.005	68.0278
601.476	73.2624
604.944	79.6696
608.413	85.0389
611.878	88.2246
615.344	89.0555
618.807	89.6197
622.27	90.7152
625.73	92.046
629.189	94.1262
632.648	96.4835
636.105	98.0547
639.559	100.765
643.013	103.014
646.467	103.009
649.918	102.712
653.368	97.4326
656.816	90.9186
660.263	86.3583
663.708	83.9735
667.153	81.6407
670.596	77.6729
674.037	73.5723
677.478	68.7663
680.917	64.7647
684.355	58.9106
687.791	52.5018
691.224	42.699
694.658	34.8908
698.091	26.7263
701.522	18.78
704.95	13.0078
708.379	9.8917
711.806	8.10329
715.23	7.41394
718.655	8.81543
722.078	9.8321
725.498	10.6876
728.919	11.1711
732.337	13.6024
735.755	14.9756
739.17	16.4227
742.584	21.1463
745.998	28.9753
749.409	36.3748
752.819	42.464
756.23	48.2235
759.637	55.3952
763.043	58.8332
766.448	63.1349
769.853	66.2581
773.255	69.5749
776.656	73.2604
780.056	74.9422
783.454	75.7776
786.851	76.2247
790.247	77.9139
793.641	79.1609
797.034	76.0302
800.426	76.0354
803.817	73.6745
807.206	71.7833
810.592	69.4498
813.979	67.0231
817.364	66.3583
820.748	65.8408
824.129	65.9723
827.511	64.7733
830.891	64.293
834.269	61.6686
837.646	58.9584
841.023	58.5771
844.396	55.8495
847.77	51.6035
851.141	48.7339
854.513	43.5808
857.881	38.2529
861.248	32.9979
864.616	32.0788
867.98	30.7859
871.343	26.3859
874.707	24.1085
878.068	19.5825
881.428	16.4056
884.786	13.3181
888.143	12.453
891.498	10.3354
894.855	10.0195
898.208	7.76655
901.56	7.84633
904.91	7.28602
908.26	7.57848
911.608	8.02474
914.955	9.65157
918.298	9.15498
921.643	11.7027
924.986	13.8526
928.328	14.8344
931.668	16.1352
935.006	15.1911
938.344	15.2215
941.681	15.9
945.014	18.6304
948.349	18.3654
951.682	16.075
955.012	13.6798
958.343	8.65209
961.67	8.62174
964.998	11.4779
968.323	22.9763
971.649	43.7
974.971	75.2507
978.293	114.426
981.615	152.966
984.933	190.198
988.251	221.41
991.567	249.248
994.884	271.047
998.198	288.974
1001.51	299.831
1004.82	303.411
1008.13	304.112
1011.44	293.49
1014.75	280.104
1018.06	266.636
1021.36	261.211
1024.66	263.791
1027.97	266.239
1031.27	265.342
1034.57	260.086
1037.87	255.002
1041.16	249.777
1044.46	247.801
1047.76	252.404
1051.05	265.388
1054.34	279.298
1057.63	288.546
1060.92	291.74
1064.21	287.293
1067.5	275.978
1070.78	257.581
1074.07	236.395
1077.35	210.851
1080.63	179.767
1083.91	145.95
1087.19	112.75
1090.47	82.9387
1093.75	59.0563
1097.03	49.6042
1100.3	50.2293
1103.57	57.9805
1106.84	61.0317
1110.11	58.5436
1113.38	56.5881
1116.65	52.0565
1119.92	49.9596
1123.19	47.2946
1126.45	46.268
1129.71	46.8308
1132.97	49.4431
1136.23	48.6242
1139.49	51.7451
1142.75	52.175
1146.01	51.1719
1149.26	48.6507
1152.52	44.8192
1155.77	42.2451
1159.02	38.0207
1162.27	32.816
1165.52	30.2428
1168.77	31.1914
1172.02	32.1969
1175.26	33.2822
1178.51	33.3976
1181.75	35.7379
1184.99	39.3402
1188.23	41.172
1191.47	47.4511
1194.71	52.5922
1197.94	57.9821
1201.18	64.6504
1204.41	70.4235
1207.65	75.8528
1210.88	83.5014
1214.11	89.0341
1217.34	93.1986
1220.57	100.1
1223.79	106.213
1227.02	110.468
1230.24	112.506
1233.47	119.559
1236.69	121.499
1239.91	123.062
1243.13	125.093
1246.34	127.68
1249.56	126.778
1252.78	126.208
1255.99	125.471
1259.2	127.67
1262.42	128.503
1265.63	125.97
1268.84	125.897
1272.04	124.482
1275.25	125.29
1278.46	126.515
1281.66	126.15
1284.86	125.314
1288.07	124.658
1291.27	126.322
1294.47	127.557
1297.66	130.709
1300.86	134.334
1304.06	137.196
1307.25	140.182
1310.44	143.99
1313.64	146.668
1316.83	147.649
1320.02	149.935
1323.2	147.638
1326.39	146.603
1329.58	143.459
1332.76	143.64
1335.95	141.508
1339.13	139.164
1342.31	137.249
1345.49	135.739
1348.67	134.471
1351.85	133.726
1355.02	131.69
1358.2	126.274
1361.37	122.738
1364.54	119.351
1367.71	115.389
1370.88	111.872
1374.05	108.114
1377.22	104.504
1380.39	104.464
1383.55	101.526
1386.72	101.321
1389.88	102.763
1393.04	101.421
1396.2	100.419
1399.36	97.0366
1402.52	100.01
1405.68	107.685
1408.83	116.673
1411.98	125.623
1415.14	137.38
1418.29	149.602
1421.44	163.514
1424.59	177.551
1427.74	192.774
1430.89	206.003
1434.03	216.676
1437.18	227.785
1440.32	235.791
1443.46	239.076
1446.6	240.843
1449.74	240.229
1452.88	237.113
1456.02	230.669
1459.16	220.593
1462.29	211.473
1465.43	197.016
1468.56	181.49
1471.69	163.191
1474.82	149.079
1477.95	133.244
1481.08	122.472
1484.2	108.231
1487.33	95.3094
1490.46	84.3642
1493.58	76.7098
1496.7	70.6429
1499.82	67.1215
1502.94	63.4733
1506.06	60.7638
1509.18	56.8465
1512.29	55.1276
1515.41	53.4687
1518.52	53.381
1521.63	53.5465
1524.75	57.0881
1527.85	57.553
1530.96	59.0242
1534.07	61.6862
1537.18	65.4075
1540.28	68.0201
1543.39	71.6551
1546.49	76.9519
1549.59	80.5079
1552.69	85.4568
1555.79	88.7335
1558.89	91.4465
1561.99	93.6461
1565.08	96.5966
1568.18	101.746
1571.27	106.74
1574.37	110.589
1577.46	114.486
1580.55	118.158
1583.64	118.926
1586.73	122.802
1589.81	125.771
1592.9	129.376
1595.98	132.265
1599.06	134.389
1602.15	133.711
1605.23	134.489
1608.31	132.586
1611.39	131.093
1614.46	129.566
1617.54	128.187
1620.61	129.031
1623.69	128.967
1626.76	127.935
1629.83	125.951
1632.9	124.415
1635.97	123.18
1639.04	123.458
1642.11	124.839
1645.17	125.957
1648.24	127.027
1651.3	129.007
1654.36	128.652
1657.42	127.829
1660.48	125.327
1663.54	124.059
1666.6	122.128
1669.66	119.536
1672.71	113.049
1675.77	107.379
1678.82	99.6374
1681.87	91.9954
1684.92	83.7381
1687.97	75.6391
1691.02	68.5889
1694.07	62.642
1697.11	56.1717
1700.16	48.4065
1703.2	42.8183
1706.25	40.1058
1709.29	35.5589
1712.33	30.539
1715.37	26.6234
1718.41	22.7108
1721.44	19.7154
1724.48	17.6099
1727.51	14.2941
1730.55	11.4057
1733.58	9.13249
1736.61	8.08232
1739.64	7.40743
1742.67	7.18831
1745.7	4.85374
1748.72	3.24551
1751.75	3.05545
1754.77	2.13075
1757.8	0.295555
1760.82	-0.87713
1763.84	0.361889
1766.86	0.790621
1769.88	1.70687
1772.9	3.72019
1775.91	3.72611
1778.93	4.39635
1781.94	4.54551
1784.96	4.18222
1787.97	5.19634
1790.98	5.15682
1793.99	6.34759
1797	5.87598
1800.01	6.42835
1803.01	7.26201
1806.02	7.17811
1809.02	7.65061
1812.02	7.096
1815.02	7.57385
1818.03	8.52125
1821.02	7.91691
1824.02	7.519
1827.02	6.88827
1830.02	7.63967
1833.01	7.85606
1836.01	8.62873
1839	7.79052
1841.99	7.17486
1844.98	5.91401
1847.97	4.96589
1850.96	3.80644
1853.95	3.86012
1856.93	3.4653
1859.92	3.15344
1862.9	2.49093
1865.88	3.84186
1868.87	5.17717
1871.85	5.53218
1874.83	4.6353
1877.81	2.68993
1880.78	2.4776
1882.53	3.97184
1885.52	4.89927
1888.51	5.12114
1891.5	3.69589
1894.48	2.82591
1897.47	5.06776
1900.45	6.36243
1903.43	8.14036
1906.41	8.72708
1909.39	10.2516
1912.37	10.3439
1915.35	10.4411
1918.33	11.6964
1921.3	12.5177
1924.28	11.7622
1927.25	11.9719
1930.22	12.4522
1933.19	12.7254
1936.16	11.5207
1939.13	12.4212
1942.1	12.6158
1945.07	11.7926
1948.03	10.1078
1951	11.2717
1953.96	10.4932
1956.92	10.2373
1959.88	7.21853
1962.84	6.67863
1965.8	3.73923
1968.76	3.68856
1971.72	3.87115
1974.67	2.41564
1977.63	2.95133
1980.58	5.08822
1983.54	5.6807
1986.49	5.04603
1989.44	5.0558
1992.39	5.79437
1995.33	4.11651
1998.28	3.34907
2001.23	4.47822
2004.17	-32.8023
2007.12	-28.1354
2010.06	-6.80848
2013	14.2584
2015.94	33.3123
2018.88	48.0468
2021.82	63.5412
2024.76	75.6351
2027.69	83.6906
2030.63	92.6681
2033.56	98.7173
2036.5	101.865
2039.43	103.318
2042.36	104.182
2045.29	103.325
2048.22	101.17
2051.15	97.1183
2054.07	89.9836
2057	80.8781
2059.92	69.1301
2062.85	56.6323
2065.77	40.9132
2068.69	23.6753
2071.61	7.27919
2074.53	-13.0594
2077.45	-25.857
2080.37	21.1509
2083.28	21.1867
2086.2	20.964
2089.11	21.6861
2092.02	21.9124
2094.94	22.7511
2097.85	22.7744
2100.76	21.2639
2103.66	21.1478
2106.57	21.6555
2109.48	20.0318
2112.38	16.6686
2115.29	14.7554
2118.19	13.9508
2121.09	12.431
2123.99	10.8893
2126.89	9.38571
2129.79	10.3372
2132.69	8.39912
2135.59	6.10876
2138.48	2.68301
2141.38	4.80558
2144.27	6.54785
2147.17	5.42093
2150.06	7.02129
2152.95	8.17626
2155.84	7.49962
2158.73	8.54814
2161.61	12.2229
2164.5	13.7019
2167.38	16.5086
2170.27	17.3025
2173.15	17.7436
2176.03	19.981
2178.91	19.0718
2181.8	18.5392
2184.67	20.9584
2187.55	21.1239
2190.43	21.2449
2193.3	20.7151
2196.18	21.3231
2199.05	21.9003
2201.93	21.7253
2204.8	19.907
2207.67	19.1422
2210.54	18.2841
2213.41	20.9562
2216.27	19.1002
2219.14	20.8568
2222.01	20.8767
2224.87	20.3606
2227.73	21.5488
2230.6	23.0746
2233.46	24.567
2236.32	24.3612
2239.18	23.9192
2242.03	21.8692
2244.89	21.4268
2247.75	20.9444
2250.6	20.0513
2253.46	18.6726
2256.31	16.4152
2259.16	15.3423
2262.01	14.5084
2264.86	14.2586
2267.71	13.8643
2270.56	12.6236
2273.4	12.398
2276.25	10.3864
2279.09	10.9837
2281.94	8.81695
2284.78	7.96103
2287.62	7.9446
2290.46	7.58773
2293.3	6.36297
2296.14	8.18096
2298.98	9.23306
2301.82	10.2333
2304.65	12.5146
2307.49	12.3818
2310.32	12.5267
2313.15	12.8426
2315.98	13.5767
2318.81	13.469
2321.64	14.2309
2324.47	13.9355
2327.3	14.0287
2330.12	13.7688
2332.95	13.6152
2335.77	11.7
2338.6	10.5827
2341.42	10.0585
2344.24	9.02926
2347.06	8.52416
2349.88	7.41199
2352.7	6.92496
2355.51	4.39195
2358.33	4.71957
2361.14	5.00261
2363.96	7.07944
2366.77	8.06715
2369.58	7.73172
2372.39	8.29407
2375.2	8.02703
2378.01	5.85042
2380.82	6.25091
2383.63	7.52931
2386.43	8.7862
2389.24	10.7379
2392.04	10.7485
2394.84	9.90004
2397.65	7.41232
2400.45	7.14308
2403.25	5.97621
2406.05	4.26846
2408.84	5.44255
2411.64	5.70172
2414.44	6.34023
2417.23	6.96907
2420.02	8.24915
2422.82	8.12325
2425.61	8.18688
2428.4	7.82315
2431.19	8.85714
2433.98	8.54821
2436.77	7.38047
2439.55	7.07971
2442.34	6.50446
2445.12	5.25097
2447.91	6.10942
2450.69	5.58645
2453.47	5.84621
2456.25	3.92573
2459.03	2.44323
2461.81	1.72664
2464.59	0.124573
2467.36	-0.346802
2470.14	-1.63257
2472.92	-2.85524
2475.69	-3.74967
2478.46	-0.987172
2481.23	0.438635
2484	2.04165
2486.77	3.18149
2489.54	2.63173
2492.31	2.43215
2495.08	3.98659
2497.84	5.14691
2500.61	5.50669
2503.37	5.63143
2506.13	7.13843
2508.9	7.08241
2511.66	6.46953
2514.42	6.57792
2517.18	6.94635
2519.93	5.30401
2522.69	5.49566
2525.45	5.59388
2528.2	6.44628
2530.95	8.07487
2533.71	6.79722
2536.46	6.53446
2539.21	6.7274
2541.96	7.81613
2544.71	8.13058
2547.46	11.4621
2550.2	10.8101
2552.95	10.3137
2555.7	9.93814
2558.44	8.85125
2561.18	9.50385
2563.93	9.69898
2566.67	9.36508
2569.41	10.4634
2572.15	10.7131
2574.88	10.5507
2577.62	9.86162
2580.36	10.2228
2583.09	10.6689
2585.83	10.2186
2588.56	10.6218
2591.29	11.7955
2594.02	11.1537
2596.75	11.3796
2599.48	10.7035
2602.21	8.99209
2604.94	9.6515
2607.67	10.4781
2610.39	10.9243
2613.12	9.6386
2615.84	9.73079
2618.56	8.86409
2621.28	8.47701
2624.01	6.49469
2626.72	7.08004
2629.44	7.29212
2632.16	7.78606
2634.88	9.80682
2637.59	10.13
2640.31	10.4888
2643.02	10.7201
2645.74	12.4859
2648.45	12.3584
2651.16	13.8381
2653.87	13.2644
2656.58	14.4805
2659.29	12.8428
2661.99	12.1772
2664.7	12.7834
2667.41	11.8427
2670.11	11.8389
2672.81	12.6668
2675.51	11.9729
2678.22	10.6447
2680.92	11.5307
2683.62	10.9887
2686.31	11.373
2689.01	9.41276
2691.71	9.84893
2694.4	12.0624
2697.1	13.1074
2699.79	16.4019
2702.49	17.7259
2705.18	20.6912
2707.87	23.2998
2710.56	26.6802
2713.25	28.1247
2715.94	28.3261
2718.62	29.9932
2721.31	30.404
2723.99	29.8143
2726.68	29.1922
2729.36	30.2025
2732.04	29.9611
2734.73	28.718
2737.41	27.8651
2740.08	25.5481
2742.76	22.9558
2745.44	20.2919
2748.12	16.4641
2750.79	13.2334
2753.47	10.5156
2756.14	8.61963
2758.81	8.43955
2761.49	7.69946
2764.16	6.62185
2766.83	6.02817
2769.5	6.33413
2772.16	5.91898
2774.83	4.29835
2777.5	3.28098
2780.16	2.94549
2782.83	3.64812
2785.49	2.92437
2788.15	1.50324
2790.82	3.03376
2793.48	3.54455
2796.14	3.85417
2798.79	3.40717
2801.45	2.77513
2804.11	-0.0332365
2806.76	-2.32347
2809.42	-5.40172
2812.07	-3.83487
2814.73	-0.256099
2817.38	10.2059
2820.03	22.0571
2822.68	35.3432
2825.33	51.1105
2827.98	69.6362
2830.63	89.1928
2833.27	109.713
2835.92	128.42
2838.56	150.063
2841.21	174.112
2843.85	197.036
2846.49	221.029
2849.13	246.502
2851.77	273.158
2854.41	300.023
2857.05	327.095
2859.69	350.752
2862.32	374.487
2864.96	390.369
2867.59	402.68
2870.23	415.203
2872.86	424.196
2875.49	435.151
2878.12	445.756
2880.75	454.173
2883.38	462.295
2886.01	468.613
2888.63	472.276
2891.26	478.324
2893.89	480.755
2896.51	483.012
2899.13	485.519
2901.76	489.592
2904.38	499.128
2907	511.084
2909.62	523.044
2912.24	540.081
2914.85	558.543
2917.47	577.108
2920.09	590.785
2922.7	600.695
2925.32	607.874
2927.93	611.227
2930.54	609.808
2933.15	606.395
2935.76	597.195
2938.37	585.557
2940.98	570.4
2943.59	551.237
2946.2	530.519
2948.8	509.855
2951.41	484.204
2954.01	459.99
2956.62	434.221
2959.22	408.079
2961.82	383.39
2964.42	360.067
2967.02	339.579
2969.62	319.86
2972.22	298.802
2974.81	281.229
2977.41	263.419
2980	243.202
2982.6	223.946
2985.19	205.913
2987.78	186.878
2990.38	168.662
2992.97	151.811
2995.56	133.53
2998.14	116.869
3000.73	101.133
3003.32	87.4376
3005.91	74.7007
3008.49	63.1357
3011.07	52.2239
3013.66	42.57
3016.24	33.3441
3018.82	26.1098
3021.4	18.5334
3023.98	13.4754
3026.56	7.68276
3029.14	4.05065
3031.71	-0.723093
3034.29	-1.07402
3036.87	-0.407694
3039.44	0.809491
3042.01	2.63823
3044.59	4.15974
3047.16	6.46615
3049.73	7.05671
3052.3	8.03671
3054.87	9.53361
3057.43	10.0365
3060	10.1677
3062.57	10.9755
3065.13	10.6164
3067.7	10.4866
3070.26	10.4062
3072.82	8.28992
3075.39	6.63498
3077.95	5.53802
3080.51	3.58758
3083.07	2.16605
3085.63	0.444902
3088.18	-0.481586
3090.74	-2.21334
3093.29	-1.52814
3095.85	0.764578
3098.4	2.58015
3100.95	4.45755
3103.51	6.08955
3106.06	8.04322
3108.61	9.98392
3111.16	11.4843
3113.71	13.5207
3116.25	16.0082
3118.8	17.5256
3121.35	19.4192
3123.89	21.5646
3126.44	23.1794
3128.98	25.8137
3131.52	27.0827
3134.06	29.3853
3136.6	30.9021
3139.14	33.2376
3141.68	35.063
3144.22	37.0049
3146.76	39.2829
3149.29	42.2824