File: data/Raman/poly_smoothed/Mb_00_13_18_1x_45s_532 nm_x100_100%_600 gr_mm_01.txt
#Acq. time (s)=	45
#Accumulations=	2
#Range (cm-¹)=	200...3150
#Windows=	2
#Auto scanning=	Off
#Autofocus=	Off
#Macrospot=	Off
#AutoExposure=	Off
#Spike filter=	Multiple accum.
#Delay time (s)=	0
#Binning=	1
#Readout mode=	Signal
#DeNoise=	Off
#ICS correction=	On
#Dark correction=	Off
#Inst. Process=	Off
#Detector Gain=	Best Dynamic Range
#Detector ADC=	20 kHz
#Detector temperature (°C)=	-69.85
#Instrument=	LabRAM HR Evol
#Detector=	Synapse
#Objective=	x100
#Grating=	600 gr/mm
#ND Filter=	100%
#Laser (nm)=	532
#Hole=	100.021
#Range=	Auto
#Laser Pol.=	No
#Raman. Pol.=	No
#Laser Pol. (°)=	-0.0007625
#Raman Pol. (°)=	89.9995
#Collection=	Microscope
#StageXY=	Marzhauser
#StageZ=	Marzhauser
#X (µm)=	-957.7
#Y (µm)=	-2829.7
#Z (µm)=	528.2
#Full time(mm:ss)=	3:19
#Project=
#Sample=
#Site=
#Title=	Mb_00_13_18_2x_45s_532 nm_x100_100%_600 gr_mm
#Remark=
#Date=	06.07.2022 11:01
#Acquired=	06.07.2022 11:01:13
#Base:Fit=	10.08.2022 10:16:56
#Base:Sub=	10.08.2022 10:17:24
#Filter:Polynom=	16.08.2022 10:36:38
#AxisType[0]=Intens
#AxisUnit[0]=Cnt
#AxisType[1]=Spectr
#AxisUnit[1]=1/cm
200.398	14.8891
204.027	12.6521
207.657	8.13444
211.283	6.08497
214.909	9.70336
218.533	17.8891
222.157	28.8365
225.777	42.0383
229.396	56.6365
233.016	69.0343
236.632	84.5155
240.247	95.7757
243.86	105.007
247.474	113.619
251.085	121.004
254.694	126.135
258.301	131.217
261.908	130.884
265.513	130.915
269.116	125.942
272.718	121.988
276.319	113.908
279.918	104.373
283.516	94.5332
287.113	80.5919
290.708	66.5326
294.302	56.8439
297.894	47.7149
301.485	42.7414
305.073	37.2149
308.661	35.9278
312.247	30.1456
315.833	27.9193
319.415	27.8528
322.997	25.8435
326.579	24.9494
330.156	22.0871
333.735	20.3047
337.31	18.7053
340.885	14.8457
344.458	13.2954
348.03	6.92614
351.6	3.5789
355.17	3.75762
358.737	3.44243
362.304	6.42402
365.868	9.97308
369.431	15.571
372.994	21.0273
376.554	24.6511
380.112	27.5973
383.669	47.8785
387.225	68.8696
390.781	89.5084
394.334	105.607
397.885	121.635
401.436	132.839
404.984	143.554
408.532	149.008
412.078	152.563
415.623	152.917
419.166	148.466
422.708	142.673
426.248	132.463
429.788	119.339
433.326	104.771
436.86	88.3264
440.395	73.9428
443.929	59.5747
447.461	44.2371
450.99	31.2017
454.52	18.0146
458.048	5.60216
461.573	-5.06708
465.099	-12.2581
468.623	-4.39662
472.144	2.59613
475.666	6.80894
479.184	7.98877
482.703	9.67572
486.218	12.5619
489.734	15.5851
493.247	17.7238
496.759	20.7315
500.271	25.1272
503.779	29.0187
507.287	31.9995
510.795	36.4418
514.299	38.5453
517.803	38.7557
521.305	39.8447
524.805	41.9844
528.307	42.707
531.805	43.6439
535.301	43.4469
538.797	41.8788
542.291	39.5841
545.783	36.9744
549.275	35.2359
552.765	30.1349
556.253	27.8484
559.738	28.1338
563.224	23.5266
566.709	20.2787
570.192	17.8854
573.674	14.359
577.153	11.9321
580.632	9.37016
584.11	10.2608
587.587	9.82865
591.06	6.24729
594.534	6.71097
598.005	4.46921
601.476	2.57462
604.944	1.52931
608.413	0.979538
611.878	0.529095
615.344	-0.181119
618.807	0.403116
622.27	-0.32156
625.73	2.1208
629.189	3.50855
632.648	6.92715
636.105	8.69357
639.559	12.3536
643.013	15.6012
646.467	19.222
649.918	21.8534
653.368	22.8533
656.816	24.0035
660.263	25.5659
663.708	26.5902
667.153	28.1206
670.596	29.3
674.037	27.2252
677.478	24.3809
680.917	23.1065
684.355	20.06
687.791	18.5999
691.224	15.1726
694.658	11.8242
698.091	9.33501
701.522	4.74267
704.95	4.4876
708.379	4.3515
711.806	4.46844
715.23	4.65035
718.655	4.27784
722.078	4.19407
725.498	6.25349
728.919	7.41828
732.337	7.43316
735.755	8.23808
739.17	8.60701
742.584	8.91427
745.998	11.4821
749.409	13.7812
752.819	16.5356
756.23	18.6569
759.637	20.2721
763.043	22.3228
766.448	26.0743
769.853	30.6454
773.255	34.3169
776.656	35.4087
780.056	38.3736
783.454	40.6823
786.851	42.0181
790.247	44.5484
793.641	45.4803
797.034	45.6773
800.426	44.7855
803.817	44.829
807.206	44.9766
810.592	43.9511
813.979	43.8258
817.364	43.4365
820.748	44.4753
824.129	44.3345
827.511	46.6405
830.891	47.8056
834.269	46.6182
837.646	45.5502
841.023	45.3101
844.396	44.6229
847.77	42.4696
851.141	42.0763
854.513	41.1852
857.881	38.3589
861.248	35.6125
864.616	34.5212
867.98	32.3702
871.343	30.8119
874.707	27.1841
878.068	26.0646
881.428	24.2892
884.786	21.3705
888.143	19.857
891.498	10.3524
894.855	5.86718
898.208	16.0299
901.56	25.4394
904.91	33.7311
908.26	39.9184
911.608	46.5437
914.955	49.2702
918.298	53.462
921.643	54.0028
924.986	54.6726
928.328	55.0469
931.668	55.678
935.006	55.3914
938.344	53.03
941.681	51.3962
945.014	48.0602
948.349	46.2181
951.682	42.5318
955.012	37.3866
958.343	31.3569
961.67	26.2341
964.998	20.9598
968.323	18.3021
971.649	14.4245
974.971	18.6117
978.293	34.5197
981.615	43.5293
984.933	47.277
988.251	48.9861
991.567	51.5911
994.884	50.022
998.198	49.1409
1001.51	49.3716
1004.82	50.4168
1008.13	50.8937
1011.44	49.8401
1014.75	48.6054
1018.06	51.4071
1021.36	59.2059
1024.66	72.4924
1027.97	83.1675
1031.27	93.0067
1034.57	101.286
1037.87	107.255
1041.16	113.955
1044.46	120.67
1047.76	126.157
1051.05	128.86
1054.34	127.876
1057.63	124.241
1060.92	120.752
1064.21	113.596
1067.5	106.588
1070.78	95.4409
1074.07	83.4518
1077.35	71.7973
1080.63	57.2388
1083.91	41.5169
1087.19	30.4663
1090.47	20.7527
1093.75	15.9385
1097.03	13.549
1100.3	17.484
1103.57	20.6214
1106.84	21.7326
1110.11	21.9415
1113.38	19.6617
1116.65	17.932
1119.92	15.9675
1123.19	14.6459
1126.45	14.6076
1129.71	12.74
1132.97	11.7665
1136.23	11.0371
1139.49	13.9414
1142.75	15.8166
1146.01	16.6305
1149.26	15.5586
1152.52	13.087
1155.77	10.885
1159.02	7.11282
1162.27	5.93896
1165.52	6.12368
1168.77	7.20262
1172.02	9.11103
1175.26	9.46769
1178.51	13.0686
1181.75	13.5634
1184.99	15.4146
1188.23	17.9059
1191.47	17.7917
1194.71	21.931
1197.94	25.413
1201.18	28.5675
1204.41	29.6833
1207.65	36.3732
1210.88	40.4945
1214.11	45.6696
1217.34	49.9556
1220.57	56.6937
1223.79	59.8919
1227.02	63.3424
1230.24	65.2728
1233.47	68.1725
1236.69	69.3879
1239.91	70.6521
1243.13	72.4115
1246.34	73.6928
1249.56	74.7713
1252.78	73.6526
1255.99	74.3231
1259.2	74.6907
1262.42	70.7251
1265.63	66.8705
1268.84	67.0921
1272.04	64.9631
1275.25	66.6025
1278.46	65.4999
1281.66	65.6261
1284.86	69.5832
1288.07	72.561
1291.27	75.3034
1294.47	80.0475
1297.66	83.9254
1300.86	89.3664
1304.06	93.7664
1307.25	95.8706
1310.44	99.7155
1313.64	103.337
1316.83	104.434
1320.02	104.849
1323.2	106.468
1326.39	107.371
1329.58	103.759
1332.76	102.349
1335.95	100.21
1339.13	96.9105
1342.31	93.8902
1345.49	91.5854
1348.67	89.642
1351.85	89.4373
1355.02	87.6259
1358.2	82.5561
1361.37	81.9392
1364.54	79.9088
1367.71	78.5081
1370.88	76.3089
1374.05	74.5439
1377.22	71.6708
1380.39	70.32
1383.55	70.7436
1386.72	69.0544
1389.88	69.6331
1393.04	66.4227
1396.2	66.1123
1399.36	69.1764
1402.52	71.3345
1405.68	71.9272
1408.83	74.2249
1411.98	80.5334
1415.14	86.135
1418.29	92.6321
1421.44	100.387
1424.59	110.543
1427.74	120.012
1430.89	126.679
1434.03	131.82
1437.18	135.904
1440.32	141.607
1443.46	144.061
1446.6	145.663
1449.74	145.068
1452.88	144.636
1456.02	143.267
1459.16	139.733
1462.29	132.807
1465.43	126.944
1468.56	119.743
1471.69	112.408
1474.82	103.121
1477.95	96.0235
1481.08	85.8835
1484.2	78.635
1487.33	72.9281
1490.46	65.8515
1493.58	59.2334
1496.7	58.0313
1499.82	56.2504
1502.94	53.114
1506.06	50.9825
1509.18	47.1667
1512.29	43.8152
1515.41	44.7075
1518.52	43.6124
1521.63	45.0071
1524.75	45.9032
1527.85	46.9156
1530.96	47.937
1534.07	46.7746
1537.18	47.2767
1540.28	50.6485
1543.39	51.977
1546.49	53.7424
1549.59	54.5897
1552.69	54.7711
1555.79	57.4131
1558.89	56.9015
1561.99	58.8766
1565.08	61.7035
1568.18	64.0733
1571.27	69.2214
1574.37	72.2197
1577.46	76.3556
1580.55	80.4442
1583.64	83.3948
1586.73	86.2082
1589.81	89.566
1592.9	92.1581
1595.98	94.7981
1599.06	95.5562
1602.15	94.3715
1605.23	94.3125
1608.31	90.3786
1611.39	88.2381
1614.46	87.5361
1617.54	85.6758
1620.61	82.1729
1623.69	78.3473
1626.76	76.8791
1629.83	77.2649
1632.9	77.8821
1635.97	79.8701
1639.04	80.5022
1642.11	83.4395
1645.17	87.1555
1648.24	89.6029
1651.3	91.2741
1654.36	91.5238
1657.42	92.0386
1660.48	90.0708
1663.54	91.2462
1666.6	90.1803
1669.66	86.2072
1672.71	81.62
1675.77	76.617
1678.82	71.6162
1681.87	64.4656
1684.92	57.4674
1687.97	50.6465
1691.02	43.9319
1694.07	35.8223
1697.11	32.773
1700.16	30.2756
1703.2	26.6678
1706.25	24.3905
1709.29	23.3079
1712.33	22.4685
1715.37	22.4429
1718.41	21.3913
1721.44	19.1712
1724.48	17.6579
1727.51	16.2362
1730.55	14.4696
1733.58	14.414
1736.61	12.9729
1739.64	11.8173
1742.67	10.8752
1745.7	9.67576
1748.72	8.56279
1751.75	7.02485
1754.77	4.54935
1757.8	3.58704
1760.82	1.97587
1763.84	0.830107
1766.86	0.962171
1769.88	2.42912
1772.9	3.29938
1775.91	2.81412
1778.93	4.18957
1781.94	5.46623
1784.96	7.35389
1787.97	8.45928
1790.98	8.68604
1793.99	8.99109
1797	8.9177
1800.01	11.7573
1803.01	11.7862
1806.02	10.489
1809.02	10.0552
1812.02	11.2315
1815.02	11.5828
1818.03	12.3142
1821.02	10.3399
1824.02	9.55191
1827.02	9.58856
1830.02	8.92522
1833.01	10.155
1836.01	8.95454
1839	7.85022
1841.99	7.64665
1844.98	8.44599
1847.97	8.87963
1850.96	9.49211
1853.95	9.13744
1856.93	10.173
1859.92	10.374
1862.9	12.5717
1865.88	12.7701
1868.87	11.7647
1871.85	13.0497
1874.83	13.6717
1877.81	13.6063
1880.78	12.9391
1882.53	14.3856
1885.52	14.7866
1888.51	12.9402
1891.5	12.3841
1894.48	11.0562
1897.47	9.63559
1900.45	8.6958
1903.43	7.50347
1906.41	7.31005
1909.39	5.59376
1912.37	6.50294
1915.35	6.87458
1918.33	6.82443
1921.3	7.08001
1924.28	8.12549
1927.25	9.61794
1930.22	11.2708
1933.19	11.9565
1936.16	12.2171
1939.13	12.6013
1942.1	12.4031
1945.07	14.0728
1948.03	15.0827
1951	16.178
1953.96	17.0543
1956.92	17.2882
1959.88	13.4618
1962.84	12.5367
1965.8	11.5348
1968.76	10.1645
1971.72	10.733
1974.67	10.8728
1977.63	11.6166
1980.58	10.0936
1983.54	11.7519
1986.49	12.1292
1989.44	10.6046
1992.39	9.54086
1995.33	9.94138
1998.28	9.52249
2001.23	8.16527
2004.17	8.02024
2007.12	7.57217
2010.06	7.93552
2013	9.14193
2015.94	10.4349
2018.88	13.1333
2021.82	13.9641
2024.76	13.5935
2027.69	12.9761
2030.63	12.2579
2033.56	13.2454
2036.5	15.0993
2039.43	16.3333
2042.36	16.7958
2045.29	19.2068
2048.22	20.7978
2051.15	23.2803
2054.07	24.1666
2057	23.031
2059.92	21.0854
2062.85	21.9348
2065.77	21.2908
2068.69	19.902
2071.61	18.1437
2074.53	18.676
2077.45	19.1228
2080.37	21.3743
2083.28	23.4353
2086.2	24.3739
2089.11	25.6805
2092.02	22.7196
2094.94	20.6331
2097.85	19.7898
2100.76	17.0889
2103.66	16.6628
2106.57	16.9932
2109.48	17.8762
2112.38	16.8338
2115.29	17.6459
2118.19	16.9671
2121.09	16.1471
2123.99	16.3884
2126.89	17.0849
2129.79	13.8401
2132.69	14.8868
2135.59	14.1019
2138.48	11.4186
2141.38	12.0647
2144.27	13.7287
2147.17	14.7082
2150.06	16.9434
2152.95	18.7957
2155.84	18.458
2158.73	18.5778
2161.61	16.6896
2164.5	15.6049
2167.38	14.4368
2170.27	12.7939
2173.15	11.6595
2176.03	12.3336
2178.91	11.8886
2181.8	11.5769
2184.67	11.8125
2187.55	12.9388
2190.43	13.839
2193.3	13.7013
2196.18	12.6826
2199.05	11.3234
2201.93	10.1137
2204.8	12.5395
2207.67	13.092
2210.54	13.1545
2213.41	15.2237
2216.27	15.7651
2219.14	16.9381
2222.01	17.4945
2224.87	17.6655
2227.73	17.9913
2230.6	18.2819
2233.46	18.3678
2236.32	17.8773
2239.18	15.7966
2242.03	15.513
2244.89	18.2057
2247.75	19.2417
2250.6	18.7477
2253.46	20.3368
2256.31	20.4585
2259.16	20.129
2262.01	19.19
2264.86	19.3591
2267.71	18.8585
2270.56	19.584
2273.4	19.7954
2276.25	20.2192
2279.09	17.1055
2281.94	15.3191
2284.78	13.3048
2287.62	12.4247
2290.46	10.5315
2293.3	8.32227
2296.14	6.54466
2298.98	8.07587
2301.82	8.73439
2304.65	7.04907
2307.49	8.14443
2310.32	8.57161
2313.15	9.80457
2315.98	9.56889
2318.81	7.34038
2321.64	8.04637
2324.47	7.27639
2327.3	7.90973
2330.12	8.809
2332.95	10.0127
2335.77	9.64045
2338.6	8.2174
2341.42	7.53237
2344.24	7.59964
2347.06	7.73471
2349.88	5.60182
2352.7	4.48268
2355.51	3.88343
2358.33	3.78832
2361.14	3.26803
2363.96	3.86243
2366.77	5.94045
2369.58	8.97262
2372.39	7.90329
2375.2	6.53016
2378.01	6.78585
2380.82	6.32788
2383.63	5.82298
2386.43	4.43863
2389.24	3.86522
2392.04	3.33797
2394.84	3.66203
2397.65	3.64163
2400.45	4.79778
2403.25	5.20371
2406.05	4.87087
2408.84	6.03553
2411.64	6.81032
2414.44	7.58537
2417.23	6.04258
2420.02	5.25825
2422.82	5.11841
2425.61	6.20557
2428.4	7.29711
2431.19	6.06296
2433.98	6.16821
2436.77	7.21342
2439.55	7.18486
2442.34	6.63487
2445.12	5.70845
2447.91	5.20182
2450.69	3.63515
2453.47	5.33251
2456.25	5.06185
2459.03	5.13122
2461.81	6.63994
2464.59	5.55113
2467.36	5.06678
2470.14	5.39596
2472.92	5.54134
2475.69	3.76455
2478.46	4.20442
2481.23	2.68282
2484	1.08043
2486.77	0.737712
2489.54	-0.557504
2492.31	-1.24487
2495.08	0.725302
2497.84	1.99659
2500.61	0.577572
2503.37	1.22341
2506.13	2.0708
2508.9	2.52941
2511.66	2.86605
2514.42	2.05195
2517.18	3.38235
2519.93	5.99935
2522.69	7.32025
2525.45	6.19967
2528.2	5.70111
2530.95	5.11055
2533.71	4.87456
2536.46	6.26895
2539.21	8.70762
2541.96	8.51746
2544.71	8.87091
2547.46	8.92971
2550.2	9.38953
2552.95	8.91125
2555.7	10.0173
2558.44	11.6027
2561.18	12.2448
2563.93	14.8285
2566.67	13.7778
2569.41	13.8795
2572.15	13.8608
2574.88	12.5983
2577.62	12.7508
2580.36	10.7419
2583.09	9.48835
2585.83	10.1799
2588.56	8.91237
2591.29	8.15803
2594.02	7.47116
2596.75	7.37506
2599.48	8.45219
2602.21	9.65187
2604.94	10.686
2607.67	10.1315
2610.39	9.01986
2613.12	9.80996
2615.84	11.354
2618.56	11.6682
2621.28	10.94
2624.01	11.7126
2626.72	11.189
2629.44	11.7109
2632.16	12.3757
2634.88	11.2474
2637.59	10.0751
2640.31	8.50534
2643.02	9.02139
2645.74	10.1439
2648.45	11.1846
2651.16	11.0079
2653.87	11.9414
2656.58	11.8562
2659.29	13.3513
2661.99	14.15
2664.7	13.9952
2667.41	13.7509
2670.11	14.0102
2672.81	13.6666
2675.51	14.047
2678.22	14.6692
2680.92	15.0658
2683.62	14.2441
2686.31	12.5288
2689.01	11.7435
2691.71	10.5348
2694.4	11.4998
2697.1	11.9743
2699.79	11.7118
2702.49	11.2741
2705.18	13.2311
2707.87	15.144
2710.56	17.5877
2713.25	20.8148
2715.94	21.798
2718.62	21.1788
2721.31	22.0511
2723.99	24.8749
2726.68	27.8622
2729.36	29.4659
2732.04	28.4886
2734.73	28.3149
2737.41	28.5881
2740.08	26.5886
2742.76	25.2539
2745.44	23.0633
2748.12	20.9522
2750.79	20.026
2753.47	18.8951
2756.14	17.4838
2758.81	17.2465
2761.49	16.6129
2764.16	14.9019
2766.83	13.4227
2769.5	13.1224
2772.16	11.9147
2774.83	9.74802
2777.5	9.22667
2780.16	8.5514
2782.83	7.68132
2785.49	8.63207
2788.15	9.84228
2790.82	9.46337
2793.48	7.02764
2796.14	3.88364
2798.79	2.39257
2801.45	0.710278
2804.11	0.515625
2806.76	-0.582416
2809.42	-0.0974936
2812.07	0.828718
2814.73	3.84168
2817.38	8.42156
2820.03	14.487
2822.68	20.6238
2825.33	27.7725
2827.98	35.7544
2830.63	43.7204
2833.27	51.5321
2835.92	59.6435
2838.56	70.051
2841.21	82.0247
2843.85	93.7314
2846.49	107.675
2849.13	122.187
2851.77	136.425
2854.41	148.773
2857.05	159.715
2859.69	173.862
2862.32	185.809
2864.96	194.926
2867.59	204.808
2870.23	213.752
2872.86	222.172
2875.49	228.823
2878.12	234.297
2880.75	240.349
2883.38	246.6
2886.01	251.647
2888.63	255.97
2891.26	260.444
2893.89	264.51
2896.51	269.213
2899.13	273.817
2901.76	279.323
2904.38	286.343
2907	295.457
2909.62	303.753
2912.24	314.994
2914.85	327.277
2917.47	336.207
2920.09	343.192
2922.7	350.513
2925.32	355.824
2927.93	356.191
2930.54	356.915
2933.15	353.739
2935.76	349.467
2938.37	341.846
2940.98	332.737
2943.59	320.913
2946.2	310.169
2948.8	297.414
2951.41	284.433
2954.01	270.705
2956.62	258.554
2959.22	245.427
2961.82	230.605
2964.42	216.176
2967.02	203.206
2969.62	192.017
2972.22	181.553
2974.81	172.595
2977.41	161.823
2980	150.909
2982.6	138.532
2985.19	128.491
2987.78	117.302
2990.38	106.93
2992.97	95.2763
2995.56	84.5005
2998.14	74.7742
3000.73	65.9128
3003.32	55.3168
3005.91	46.8257
3008.49	38.2752
3011.07	34.1613
3013.66	28.4584
3016.24	23.0938
3018.82	18.1206
3021.4	13.4979
3023.98	10.7592
3026.56	8.14924
3029.14	6.47373
3031.71	4.66584
3034.29	3.31993
3036.87	3.04882
3039.44	3.03218
3042.01	1.04251
3044.59	2.7315
3047.16	3.78181
3049.73	4.41211
3052.3	3.12561
3054.87	4.38041
3057.43	3.44863
3060	3.48728
3062.57	4.81938
3065.13	2.93421
3067.7	3.28527
3070.26	3.00269
3072.82	2.99203
3075.39	2.53004
3077.95	0.570288
3080.51	0.186325
3083.07	1.56958
3085.63	1.35317
3088.18	-0.150131
3090.74	-0.305086
3093.29	-0.21975
3095.85	-1.19382
3098.4	0.339553
3100.95	2.36997
3103.51	3.84692
3106.06	5.79135
3108.61	8.34431
3111.16	8.57117
3113.71	8.72027
3116.25	10.5306
3118.8	12.9705
3121.35	14.937
3123.89	16.1458
3126.44	18.5019
3128.98	19.6768
3131.52	21.5939
3134.06	22.92
3136.6	24.6627
3139.14	25.6146
3141.68	26.8451
3144.22	26.9422
3146.76	27.1719
3149.29	30.4911