File: data/Raman/poly_smoothed/Mb_00_13_31_1x_45s_532 nm_x100_100%_600 gr_mm_01.txt
#Acq. time (s)=	45
#Accumulations=	2
#Range (cm-¹)=	200...3150
#Windows=	2
#Auto scanning=	Off
#Autofocus=	Off
#Macrospot=	Off
#AutoExposure=	Off
#Spike filter=	Multiple accum.
#Delay time (s)=	0
#Binning=	1
#Readout mode=	Signal
#DeNoise=	Off
#ICS correction=	On
#Dark correction=	Off
#Inst. Process=	Off
#Detector Gain=	Best Dynamic Range
#Detector ADC=	20 kHz
#Detector temperature (°C)=	-69.85
#Instrument=	LabRAM HR Evol
#Detector=	Synapse
#Objective=	x100
#Grating=	600 gr/mm
#ND Filter=	100%
#Laser (nm)=	532
#Hole=	100.021
#Range=	Auto
#Laser Pol.=	No
#Raman. Pol.=	No
#Laser Pol. (°)=	-0.0007625
#Raman Pol. (°)=	89.9995
#Collection=	Microscope
#StageXY=	Marzhauser
#StageZ=	Marzhauser
#X (µm)=	-984.3
#Y (µm)=	-2867.3
#Z (µm)=	528.65
#Full time(mm:ss)=	3:19
#Project=
#Sample=
#Site=
#Title=	Mb_00_13_31_2x_45s_532 nm_x100_100%_600 gr_mm
#Remark=
#Date=	06.07.2022 12:06
#Acquired=	06.07.2022 12:06:51
#Base:Fit=	10.08.2022 10:16:56
#Base:Sub=	10.08.2022 10:17:24
#Filter:Polynom=	16.08.2022 10:36:38
#AxisType[0]=Intens
#AxisUnit[0]=Cnt
#AxisType[1]=Spectr
#AxisUnit[1]=1/cm
200.398	20.55
204.027	8.64037
207.657	-0.703071
211.283	-6.99059
214.909	-6.73696
218.533	3.70779
222.157	22.03
225.777	39.7683
229.396	61.5851
233.016	83.6309
236.632	102.124
240.247	117.185
243.86	128.901
247.474	142.289
251.085	155.244
254.694	164.333
258.301	170.221
261.908	171.41
265.513	168.475
269.116	163.897
272.718	154.944
276.319	143.851
279.918	127.483
283.516	106.3
287.113	88.1201
290.708	70.7591
294.302	53.4948
297.894	40.0739
301.485	31.6841
305.073	27.4074
308.661	21.1291
312.247	18.8468
315.833	15.9786
319.415	16.2184
322.997	14.5325
326.579	12.6436
330.156	11.5583
333.735	10.0686
337.31	8.82915
340.885	8.17197
344.458	6.61234
348.03	5.44778
351.6	3.99703
355.17	3.59563
358.737	2.77919
362.304	5.82229
365.868	11.8911
369.431	17.6018
372.994	25.3027
376.554	36.9232
380.112	49.5231
383.669	68.3953
387.225	92.333
390.781	114.352
394.334	136.367
397.885	154.893
401.436	169.108
404.984	182.349
408.532	189.978
412.078	191.679
415.623	193.478
419.166	190.146
422.708	182.063
426.248	173.725
429.788	161.449
433.326	145.304
436.86	125.721
440.395	104.711
443.929	86.2916
447.461	68.2261
450.99	50.6785
454.52	35.5467
458.048	22.8297
461.573	15.3613
465.099	12.1206
468.623	14.291
472.144	18.6133
475.666	22.0657
479.184	26.5364
482.703	30.4896
486.218	31.7155
489.734	36.3013
493.247	43.0876
496.759	49.3531
500.271	56.2165
503.779	64.1519
507.287	71.1978
510.795	73.9513
514.299	78.986
517.803	80.8373
521.305	82.331
524.805	82.9866
528.307	86.403
531.805	84.6263
535.301	81.5681
538.797	82.2422
542.291	79.6145
545.783	78.3468
549.275	73.8532
552.765	67.1766
556.253	61.8917
559.738	55.4101
563.224	51.6219
566.709	46.2403
570.192	42.2237
573.674	38.3992
577.153	36.5665
580.632	36.2541
584.11	34.4812
587.587	33.2402
591.06	31.3018
594.534	28.499
598.005	24.356
601.476	27.1834
604.944	28.5408
608.413	29.5917
611.878	31.0108
615.344	30.2151
618.807	30.7533
622.27	32.3688
625.73	34.5594
629.189	39.0588
632.648	42.4069
636.105	45.0577
639.559	46.7924
643.013	48.6432
646.467	51.0054
649.918	53.6904
653.368	53.0042
656.816	53.7207
660.263	52.5963
663.708	49.844
667.153	48.0185
670.596	45.6267
674.037	39.8865
677.478	33.5377
680.917	30.8721
684.355	26.3526
687.791	22.7628
691.224	17.6273
694.658	14.3521
698.091	12.6724
701.522	10.1995
704.95	11.413
708.379	13.1018
711.806	16.1652
715.23	16.9799
718.655	18.3228
722.078	19.2364
725.498	22.0148
728.919	24.4495
732.337	26.7336
735.755	27.996
739.17	29.153
742.584	31.1127
745.998	34.0781
749.409	36.6108
752.819	44.8414
756.23	46.2308
759.637	48.7511
763.043	51.7738
766.448	54.6053
769.853	57.4881
773.255	61.6698
776.656	66.0863
780.056	63.2468
783.454	61.8654
786.851	66.2046
790.247	71.119
793.641	75.079
797.034	78.2293
800.426	79.5466
803.817	79.2071
807.206	81.071
810.592	81.0775
813.979	80.2866
817.364	79.3287
820.748	82.5652
824.129	82.4424
827.511	81.2765
830.891	80.8886
834.269	79.6803
837.646	73.3178
841.023	66.788
844.396	60.5585
847.77	53.7478
851.141	46.5976
854.513	39.3253
857.881	32.6378
861.248	23.7583
864.616	16.401
867.98	18.9977
871.343	17.4435
874.707	16.1294
878.068	15.3511
881.428	13.7304
884.786	10.6261
888.143	10.4229
891.498	15.1658
894.855	15.2512
898.208	16.3338
901.56	20.7547
904.91	21.8028
908.26	21.456
911.608	21.2191
914.955	21.5206
918.298	20.8997
921.643	20.1071
924.986	21.8079
928.328	19.11
931.668	18.4895
935.006	20.2424
938.344	17.776
941.681	16.4924
945.014	16.1156
948.349	15.4131
951.682	15.34
955.012	17.1773
958.343	14.4664
961.67	11.3489
964.998	13.9878
968.323	21.4903
971.649	29.2601
974.971	38.657
978.293	47.2768
981.615	57.0429
984.933	63.905
988.251	69.0525
991.567	74.0789
994.884	78.7314
998.198	84.4908
1001.51	86.4448
1004.82	85.7842
1008.13	87.4223
1011.44	84.0907
1014.75	83.7991
1018.06	88.2625
1021.36	96.6705
1024.66	110.596
1027.97	124.085
1031.27	135.826
1034.57	146.275
1037.87	151.497
1041.16	154.937
1044.46	164.042
1047.76	171.441
1051.05	175.379
1054.34	177.325
1057.63	177.059
1060.92	169.573
1064.21	161.606
1067.5	147.364
1070.78	132.051
1074.07	116.144
1077.35	98.4406
1080.63	79.206
1083.91	59.9729
1087.19	42.0868
1090.47	28.8567
1093.75	20.0428
1097.03	18.5066
1100.3	20.5964
1103.57	23.1161
1106.84	24.7147
1110.11	23.0266
1113.38	22.3294
1116.65	21.7051
1119.92	21.3257
1123.19	20.4079
1126.45	20.1144
1129.71	20.6483
1132.97	18.8969
1136.23	20.4351
1139.49	18.1801
1142.75	16.218
1146.01	13.9803
1149.26	9.04696
1152.52	8.86145
1155.77	7.16762
1159.02	4.53689
1162.27	3.72179
1165.52	1.19021
1168.77	3.57992
1172.02	2.73612
1175.26	4.29856
1178.51	4.1841
1181.75	6.20453
1184.99	8.73632
1188.23	11.4551
1191.47	15.1421
1194.71	20.4034
1197.94	25.7364
1201.18	33.7031
1204.41	40.7399
1207.65	48.5152
1210.88	55.3872
1214.11	64.9059
1217.34	74.1783
1220.57	83.4804
1223.79	90.2638
1227.02	96.4367
1230.24	101.876
1233.47	104.802
1236.69	107.748
1239.91	111.64
1243.13	113.972
1246.34	112.916
1249.56	113.477
1252.78	112.75
1255.99	111.753
1259.2	107.59
1262.42	105.604
1265.63	102.912
1268.84	101.435
1272.04	101.421
1275.25	100.148
1278.46	102.27
1281.66	106.922
1284.86	109.392
1288.07	113.18
1291.27	116.647
1294.47	120.379
1297.66	125.382
1300.86	129.859
1304.06	134.819
1307.25	137.037
1310.44	144.948
1313.64	151.156
1316.83	156.986
1320.02	161.881
1323.2	164.793
1326.39	166.465
1329.58	167.985
1332.76	168.025
1335.95	165.006
1339.13	162.3
1342.31	158.683
1345.49	155.764
1348.67	151.549
1351.85	148.034
1355.02	143.789
1358.2	139.315
1361.37	133.417
1364.54	127.092
1367.71	119.492
1370.88	110.874
1374.05	105.091
1377.22	100.533
1380.39	99.3438
1383.55	95.3159
1386.72	93.9576
1389.88	93.9004
1393.04	93.4753
1396.2	93.9086
1399.36	94.4427
1402.52	97.3302
1405.68	102.036
1408.83	109.031
1411.98	116.546
1415.14	127.038
1418.29	138.04
1421.44	151.921
1424.59	166.703
1427.74	182.584
1430.89	199.726
1434.03	215.36
1437.18	230.437
1440.32	240.654
1443.46	249.813
1446.6	253.337
1449.74	256.33
1452.88	255.009
1456.02	251.491
1459.16	241.664
1462.29	230.392
1465.43	216.905
1468.56	203.794
1471.69	187.889
1474.82	171.178
1477.95	156.483
1481.08	141.753
1484.2	128.564
1487.33	115.215
1490.46	100.458
1493.58	89.2819
1496.7	81.5227
1499.82	76.6839
1502.94	72.5161
1506.06	70.656
1509.18	69.7005
1512.29	69.7425
1515.41	68.293
1518.52	65.3525
1521.63	65.2682
1524.75	66.1911
1527.85	65.0766
1530.96	63.2756
1534.07	63.0085
1537.18	62.4864
1540.28	63.4818
1543.39	65.9995
1546.49	70.034
1549.59	71.8825
1552.69	76.0161
1555.79	79.1591
1558.89	82.1224
1561.99	84.5319
1565.08	87.2789
1568.18	88.9046
1571.27	94.8948
1574.37	100.503
1577.46	105.475
1580.55	112.273
1583.64	119.268
1586.73	123.411
1589.81	126.047
1592.9	129.695
1595.98	132.059
1599.06	135.664
1602.15	133.664
1605.23	132.175
1608.31	131.651
1611.39	130.662
1614.46	127.983
1617.54	128.308
1620.61	127.559
1623.69	125.768
1626.76	129.071
1629.83	127.568
1632.9	129.592
1635.97	130.651
1639.04	131.852
1642.11	134.267
1645.17	138.55
1648.24	143.422
1651.3	144.913
1654.36	145.604
1657.42	146.16
1660.48	141.655
1663.54	139.789
1666.6	136.215
1669.66	131.121
1672.71	126.007
1675.77	119.704
1678.82	108.759
1681.87	100.294
1684.92	89.8214
1687.97	78.3985
1691.02	70.7139
1694.07	61.9638
1697.11	52.2037
1700.16	45.3501
1703.2	38.6307
1706.25	31.5543
1709.29	26.7716
1712.33	22.4209
1715.37	18.9007
1718.41	16.2101
1721.44	13.2289
1724.48	10.6353
1727.51	9.14872
1730.55	9.98787
1733.58	8.94903
1736.61	10.5551
1739.64	10.7731
1742.67	11.9936
1745.7	13.4845
1748.72	15.6639
1751.75	13.8049
1754.77	14.2671
1757.8	13.5279
1760.82	14.007
1763.84	13.3674
1766.86	11.8925
1769.88	10.6219
1772.9	8.38207
1775.91	7.17103
1778.93	6.69726
1781.94	6.83153
1784.96	5.9835
1787.97	4.97984
1790.98	3.51621
1793.99	2.26409
1797	3.31188
1800.01	4.44915
1803.01	6.50698
1806.02	4.93094
1809.02	5.94739
1812.02	6.12021
1815.02	7.41578
1818.03	8.08258
1821.02	7.85291
1824.02	7.85263
1827.02	8.00153
1830.02	6.92521
1833.01	7.60234
1836.01	7.5104
1839	5.69922
1841.99	6.33847
1844.98	6.94734
1847.97	7.05676
1850.96	8.25343
1853.95	9.68011
1856.93	9.96765
1859.92	10.9845
1862.9	12.429
1865.88	15.7633
1868.87	17.0071
1871.85	17.4402
1874.83	16.6122
1877.81	14.597
1880.78	14.2631
1882.53	14.3426
1885.52	11.9557
1888.51	11.7655
1891.5	11.543
1894.48	11.6978
1897.47	10.9054
1900.45	9.61531
1903.43	8.12973
1906.41	7.33308
1909.39	6.67438
1912.37	6.28867
1915.35	6.12268
1918.33	6.49741
1921.3	9.7578
1924.28	11.3708
1927.25	12.2822
1930.22	14.051
1933.19	15.2297
1936.16	15.1814
1939.13	15.2155
1942.1	13.146
1945.07	11.3932
1948.03	10.229
1951	11.0634
1953.96	9.81984
1956.92	8.71311
1959.88	8.17045
1962.84	8.94289
1965.8	8.1968
1968.76	7.818
1971.72	5.98055
1974.67	6.43723
1977.63	4.51595
1980.58	5.51182
1983.54	6.00003
1986.49	7.68487
1989.44	9.53288
1992.39	12.54
1995.33	13.7224
1998.28	13.7026
2001.23	14.2516
2004.17	15.4911
2007.12	16.1819
2010.06	15.5803
2013	15.5148
2015.94	15.7422
2018.88	14.8025
2021.82	12.7122
2024.76	12.1227
2027.69	12.3712
2030.63	12.45
2033.56	9.87132
2036.5	8.31604
2039.43	7.44761
2042.36	6.21439
2045.29	6.29831
2048.22	4.03382
2051.15	3.18777
2054.07	3.32324
2057	2.37597
2059.92	2.09246
2062.85	3.15843
2065.77	3.43552
2068.69	5.01365
2071.61	6.1757
2074.53	8.71921
2077.45	10.7436
2080.37	11.5134
2083.28	13.7581
2086.2	14.6527
2089.11	15.6576
2092.02	13.8301
2094.94	16.1213
2097.85	16.6453
2100.76	17.5182
2103.66	15.0971
2106.57	13.3449
2109.48	11.5726
2112.38	11.6415
2115.29	13.2586
2118.19	12.3015
2121.09	10.9904
2123.99	10.6852
2126.89	10.4678
2129.79	10.18
2132.69	10.9438
2135.59	10.1736
2138.48	11.8352
2141.38	12.9164
2144.27	13.6779
2147.17	15.7725
2150.06	16.5813
2152.95	18.2827
2155.84	18.3564
2158.73	18.5342
2161.61	18.5685
2164.5	18.734
2167.38	17.0673
2170.27	17.2354
2173.15	15.9833
2176.03	16.3302
2178.91	16.3793
2181.8	18.3563
2184.67	19.8595
2187.55	19.1799
2190.43	18.5909
2193.3	16.6136
2196.18	17.1825
2199.05	17.571
2201.93	17.1968
2204.8	16.6309
2207.67	17.3566
2210.54	16.098
2213.41	15.828
2216.27	16.6994
2219.14	19.0181
2222.01	19.4062
2224.87	19.0616
2227.73	19.5861
2230.6	21.6682
2233.46	22.7288
2236.32	22.7292
2239.18	24.7613
2242.03	24.9862
2244.89	25.8666
2247.75	24.9894
2250.6	24.8918
2253.46	24.5433
2256.31	22.9509
2259.16	21.8037
2262.01	20.983
2264.86	22.5726
2267.71	22.5257
2270.56	21.093
2273.4	19.1649
2276.25	19.3313
2279.09	19.2647
2281.94	20.0829
2284.78	21.1471
2287.62	20.5246
2290.46	19.9215
2293.3	19.1078
2296.14	18.4708
2298.98	20.6117
2301.82	21.8032
2304.65	21.3149
2307.49	20.9313
2310.32	20.6615
2313.15	18.1338
2315.98	17.0222
2318.81	17.0051
2321.64	17.5295
2324.47	15.9121
2327.3	13.2341
2330.12	12.0107
2332.95	11.8684
2335.77	11.4524
2338.6	7.5811
2341.42	7.63557
2344.24	9.05361
2347.06	8.32837
2349.88	7.6496
2352.7	5.55536
2355.51	4.17446
2358.33	2.15804
2361.14	2.50063
2363.96	4.23666
2366.77	4.85085
2369.58	5.60499
2372.39	6.09251
2375.2	5.14449
2378.01	5.2817
2380.82	5.48244
2383.63	6.21545
2386.43	8.04201
2389.24	7.06122
2392.04	6.84269
2394.84	5.79181
2397.65	7.21799
2400.45	7.4173
2403.25	9.44572
2406.05	8.42409
2408.84	8.68963
2411.64	9.11262
2414.44	7.94365
2417.23	5.8157
2420.02	5.73314
2422.82	6.21617
2425.61	6.65526
2428.4	8.14487
2431.19	8.47595
2433.98	7.86737
2436.77	7.44467
2439.55	7.71309
2442.34	6.516
2445.12	5.54899
2447.91	3.43883
2450.69	2.42487
2453.47	2.60729
2456.25	1.75788
2459.03	1.80904
2461.81	1.49275
2464.59	3.3926
2467.36	3.42229
2470.14	2.6715
2472.92	3.07256
2475.69	1.59897
2478.46	1.76901
2481.23	0.159249
2484	0.803328
2486.77	0.403749
2489.54	0.751831
2492.31	-0.34392
2495.08	0.962413
2497.84	-0.0562226
2500.61	0.538923
2503.37	1.36244
2506.13	1.7251
2508.9	2.94311
2511.66	3.84374
2514.42	4.26568
2517.18	4.60621
2519.93	6.26738
2522.69	8.21616
2525.45	8.62423
2528.2	9.21017
2530.95	9.90914
2533.71	11.3053
2536.46	10.6116
2539.21	11.3151
2541.96	10.0527
2544.71	9.69515
2547.46	8.62002
2550.2	7.24192
2552.95	7.43202
2555.7	5.95988
2558.44	4.44109
2561.18	3.72074
2563.93	3.55191
2566.67	5.01788
2569.41	7.02034
2572.15	8.64317
2574.88	10.0046
2577.62	11.9397
2580.36	12.1771
2583.09	12.3334
2585.83	11.8869
2588.56	12.565
2591.29	11.6496
2594.02	12.3806
2596.75	12.6463
2599.48	12.6328
2602.21	11.4856
2604.94	9.90603
2607.67	9.00164
2610.39	7.56847
2613.12	6.58473
2615.84	4.50559
2618.56	4.21218
2621.28	5.26621
2624.01	4.01438
2626.72	4.31582
2629.44	4.80662
2632.16	6.64464
2634.88	7.5979
2637.59	8.39457
2640.31	9.85641
2643.02	9.25953
2645.74	10.6201
2648.45	11.975
2651.16	12.4759
2653.87	13.8299
2656.58	14.6329
2659.29	16.3772
2661.99	16.5335
2664.7	16.4061
2667.41	17.3787
2670.11	18.8645
2672.81	17.2765
2675.51	17.7422
2678.22	17.1071
2680.92	16.1013
2683.62	15.3731
2686.31	14.7398
2689.01	14.3682
2691.71	13.9856
2694.4	13.0888
2697.1	12.6799
2699.79	14.4686
2702.49	15.7483
2705.18	17.4943
2707.87	18.6546
2710.56	20.0589
2713.25	22.5929
2715.94	25.2302
2718.62	27.4623
2721.31	28.0179
2723.99	29.36
2726.68	30.4349
2729.36	30.1567
2732.04	30.6695
2734.73	31.4349
2737.41	29.8545
2740.08	27.9249
2742.76	26.3426
2745.44	24.697
2748.12	22.4286
2750.79	20.7533
2753.47	20.0412
2756.14	18.6234
2758.81	18.079
2761.49	15.5471
2764.16	14.454
2766.83	15.1039
2769.5	12.1431
2772.16	11.6854
2774.83	10.8058
2777.5	10.7312
2780.16	9.16899
2782.83	7.21992
2785.49	5.71708
2788.15	4.01064
2790.82	3.34656
2793.48	0.566334
2796.14	-0.148683
2798.79	-0.293541
2801.45	-1.42672
2804.11	-2.57941
2806.76	-3.05038
2809.42	-4.08637
2812.07	-3.54946
2814.73	-0.424361
2817.38	3.78823
2820.03	12.6446
2822.68	20.6573
2825.33	30.7412
2827.98	41.403
2830.63	55.0261
2833.27	68.8123
2835.92	81.8896
2838.56	99.6631
2841.21	119.566
2843.85	139.985
2846.49	162.416
2849.13	185.936
2851.77	212.737
2854.41	238.949
2857.05	262.816
2859.69	287.127
2862.32	309.203
2864.96	328.293
2867.59	346.238
2870.23	360.848
2872.86	374.597
2875.49	388.714
2878.12	401.173
2880.75	413.425
2883.38	423.246
2886.01	432.14
2888.63	439.681
2891.26	447.271
2893.89	456.097
2896.51	463.169
2899.13	473.62
2901.76	488.823
2904.38	505.007
2907	526.53
2909.62	549.094
2912.24	571.413
2914.85	595.693
2917.47	617.014
2920.09	634.539
2922.7	647.908
2925.32	658.025
2927.93	662.003
2930.54	661.781
2933.15	657.833
2935.76	649.784
2938.37	637.405
2940.98	621.223
2943.59	602.069
2946.2	578.223
2948.8	553.189
2951.41	527.259
2954.01	500.1
2956.62	471.943
2959.22	447.483
2961.82	420.783
2964.42	398.51
2967.02	377.499
2969.62	356.611
2972.22	337.822
2974.81	316.703
2977.41	297.582
2980	277.283
2982.6	254.139
2985.19	231.787
2987.78	211.04
2990.38	190.301
2992.97	168.647
2995.56	148.783
2998.14	131.203
3000.73	112.383
3003.32	95.5694
3005.91	80.3477
3008.49	66.6241
3011.07	51.9641
3013.66	41.5491
3016.24	30.5032
3018.82	23.7711
3021.4	17.9649
3023.98	12.6556
3026.56	7.58968
3029.14	4.75734
3031.71	2.48666
3034.29	1.40911
3036.87	1.39406
3039.44	1.56113
3042.01	3.58895
3044.59	4.43633
3047.16	5.42976
3049.73	8.13827
3052.3	10.1078
3054.87	10.3572
3057.43	10.3528
3060	10.1901
3062.57	10.6972
3065.13	10.1325
3067.7	8.59533
3070.26	8.39744
3072.82	6.68587
3075.39	5.95132
3077.95	4.82535
3080.51	2.70122
3083.07	1.39225
3085.63	-0.499976
3088.18	-0.944414
3090.74	-3.36979
3093.29	-3.57531
3095.85	-2.85719
3098.4	-1.27776
3100.95	0.8436
3103.51	3.15813
3106.06	3.3
3108.61	5.2378
3111.16	8.00708
3113.71	12.4797
3116.25	15.6192
3118.8	18.7369
3121.35	22.3731
3123.89	26.899
3126.44	30.159
3128.98	34.8211
3131.52	39.1301
3134.06	44.4625
3136.6	48.159
3139.14	53.0586
3141.68	55.411
3144.22	57.4836
3146.76	58.6706
3149.29	56.891