File: data/Raman/poly_smoothed/Mb_00_13_03_1x_45s_532 nm_x100_100%_600 gr_mm_01.txt
#Acq. time (s)=	45
#Accumulations=	2
#Range (cm-¹)=	200...3150
#Windows=	2
#Auto scanning=	Off
#Autofocus=	Off
#Macrospot=	Off
#AutoExposure=	Off
#Spike filter=	Multiple accum.
#Delay time (s)=	0
#Binning=	1
#Readout mode=	Signal
#DeNoise=	Off
#ICS correction=	On
#Dark correction=	Off
#Inst. Process=	Off
#Detector Gain=	Best Dynamic Range
#Detector ADC=	20 kHz
#Detector temperature (°C)=	-69.85
#Instrument=	LabRAM HR Evol
#Detector=	Synapse
#Objective=	x100
#Grating=	600 gr/mm
#ND Filter=	100%
#Laser (nm)=	532
#Hole=	100.021
#Range=	Auto
#Laser Pol.=	No
#Raman. Pol.=	No
#Laser Pol. (°)=	-0.0007625
#Raman Pol. (°)=	89.9995
#Collection=	Microscope
#StageXY=	Marzhauser
#StageZ=	Marzhauser
#X (µm)=	-983.1
#Y (µm)=	-2933.7
#Z (µm)=	527.5
#Full time(mm:ss)=	3:18
#Project=
#Sample=
#Site=
#Title=	Mb_00_13_03_2x_45s_532 nm_x100_100%_600 gr_mm
#Remark=
#Date=	06.07.2022 09:54
#Acquired=	06.07.2022 09:54:28
#Base:Fit=	10.08.2022 10:16:36
#Base:Fit=	10.08.2022 10:16:56
#Base:Sub=	10.08.2022 10:17:24
#Filter:Polynom=	16.08.2022 10:36:38
#AxisType[0]=Intens
#AxisUnit[0]=Cnt
#AxisType[1]=Spectr
#AxisUnit[1]=1/cm
200.398	45.4575
204.027	27.6803
207.657	10.951
211.283	2.86217
214.909	2.86989
218.533	14.982
222.157	32.313
225.777	52.5164
229.396	75.4856
233.016	97.9152
236.632	116.438
240.247	133.083
243.86	146.23
247.474	158.875
251.085	172.69
254.694	182.681
258.301	187.119
261.908	189.315
265.513	185.569
269.116	180.382
272.718	170.098
276.319	156.761
279.918	139.327
283.516	120.016
287.113	98.8559
290.708	81.2228
294.302	65.8114
297.894	55.6779
301.485	46.8037
305.073	39.6516
308.661	35.3009
312.247	29.316
315.833	26.2049
319.415	24.4568
322.997	22.632
326.579	21.5813
330.156	20.3887
333.735	18.0351
337.31	16.0721
340.885	13.9746
344.458	12.0982
348.03	9.53193
351.6	9.34669
355.17	8.2202
358.737	7.94787
362.304	13.844
365.868	22.5096
369.431	31.0891
372.994	41.8042
376.554	54.1485
380.112	70.4885
383.669	89.5802
387.225	110.345
390.781	130.154
394.334	147.6
397.885	164.385
401.436	174.571
404.984	185.937
408.532	191.002
412.078	192.191
415.623	188.407
419.166	182.108
422.708	169.299
426.248	155.524
429.788	139.298
433.326	120.121
436.86	99.4497
440.395	76.6405
443.929	58.8271
447.461	43.104
450.99	28.6977
454.52	15.3111
458.048	3.41949
461.573	-3.8237
465.099	-6.48752
468.623	-7.56969
472.144	-4.52652
475.666	0.200964
479.184	3.32907
482.703	9.71487
486.218	15.5833
489.734	20.8633
493.247	28.4552
496.759	36.1573
500.271	42.645
503.779	49.9049
507.287	57.3623
510.795	63.1686
514.299	68.2646
517.803	70.7566
521.305	72.6037
524.805	72.0598
528.307	72.8037
531.805	73.9415
535.301	73.8747
538.797	70.5353
542.291	66.0685
545.783	58.742
549.275	51.9327
552.765	46.5126
556.253	40.54
559.738	37.8024
563.224	33.104
566.709	29.6994
570.192	27.6462
573.674	24.4328
577.153	21.7984
580.632	19.3034
584.11	17.777
587.587	16.9836
591.06	15.9244
594.534	13.3791
598.005	11.376
601.476	11.5578
604.944	10.1896
608.413	10.9086
611.878	10.9929
615.344	11.898
618.807	12.1667
622.27	12.8811
625.73	13.2839
629.189	17.0096
632.648	22.3682
636.105	26.4594
639.559	31.12
643.013	35.4254
646.467	39.3425
649.918	41.1992
653.368	43.21
656.816	42.9639
660.263	39.3229
663.708	37.104
667.153	34.7878
670.596	33.4414
674.037	30.9259
677.478	27.2057
680.917	27.0003
684.355	25.301
687.791	23.5192
691.224	18.9685
694.658	15.9268
698.091	13.2523
701.522	12.7318
704.95	12.7918
708.379	12.8174
711.806	13.823
715.23	14.5647
718.655	15.0216
722.078	15.2872
725.498	14.9351
728.919	13.72
732.337	14.5612
735.755	13.3303
739.17	16.0253
742.584	17.4517
745.998	20.08
749.409	25.8781
752.819	32.0357
756.23	35.3018
759.637	39.986
763.043	45.9272
766.448	51.5337
769.853	56.0422
773.255	61.4433
776.656	63.5992
780.056	68.063
783.454	69.8826
786.851	70.8689
790.247	71.0089
793.641	69.1814
797.034	68.0537
800.426	66.1426
803.817	62.0278
807.206	56.6392
810.592	53.7087
813.979	50.6516
817.364	48.9724
820.748	48.9524
824.129	48.2457
827.511	46.1189
830.891	43.9275
834.269	41.2887
837.646	39.4722
841.023	38.8297
844.396	37.8329
847.77	37.7462
851.141	37.7007
854.513	35.8251
857.881	35.1572
861.248	30.6351
864.616	28.3061
867.98	25.9655
871.343	21.8295
874.707	18.4069
878.068	18.1647
881.428	15.4976
884.786	12.1122
888.143	8.86643
891.498	8.30471
894.855	7.11523
898.208	7.73978
901.56	7.7651
904.91	7.76695
908.26	7.34692
911.608	8.16391
914.955	10.6341
918.298	12.722
921.643	16.7124
924.986	19.9977
928.328	22.0796
931.668	24.6983
935.006	27.6247
938.344	27.667
941.681	25.9737
945.014	26.9079
948.349	27.9988
951.682	29.8781
955.012	27.6865
958.343	27.9417
961.67	27.3831
964.998	29.8361
968.323	35.225
971.649	38.8643
974.971	42.7432
978.293	48.3798
981.615	49.9494
984.933	51.9988
988.251	52.9659
991.567	54.0002
994.884	57.0408
998.198	59.7891
1001.51	62.1619
1004.82	63.7708
1008.13	64.6624
1011.44	61.3091
1014.75	67.015
1018.06	74.9393
1021.36	91.3753
1024.66	111.683
1027.97	132.823
1031.27	154.583
1034.57	169.243
1037.87	181.822
1041.16	196.347
1044.46	206.65
1047.76	213.416
1051.05	217.077
1054.34	216.301
1057.63	214.67
1060.92	207.857
1064.21	198.438
1067.5	185.3
1070.78	170.408
1074.07	153.581
1077.35	132.812
1080.63	110.732
1083.91	88.9308
1087.19	67.5872
1090.47	49.9706
1093.75	39.9409
1097.03	36.1993
1100.3	36.8247
1103.57	36.0675
1106.84	34.2369
1110.11	30.1419
1113.38	25.7936
1116.65	20.7902
1119.92	16.9081
1123.19	12.991
1126.45	8.55272
1129.71	5.99503
1132.97	4.8786
1136.23	6.3078
1139.49	5.93574
1142.75	5.3637
1146.01	6.49937
1149.26	5.98186
1152.52	5.63854
1155.77	6.41509
1159.02	4.57055
1162.27	6.11683
1165.52	7.54942
1168.77	9.04809
1172.02	11.8943
1175.26	11.5154
1178.51	14.6389
1181.75	16.9826
1184.99	20.1966
1188.23	25.3636
1191.47	29.0084
1194.71	33.6671
1197.94	39.7438
1201.18	45.06
1204.41	49.7877
1207.65	57.4175
1210.88	64.5594
1214.11	71.4861
1217.34	80.3095
1220.57	87.7467
1223.79	94.9202
1227.02	102.036
1230.24	107.533
1233.47	112.959
1236.69	116.93
1239.91	118.499
1243.13	119.478
1246.34	122.347
1249.56	121.371
1252.78	118.358
1255.99	116.121
1259.2	114.948
1262.42	111.593
1265.63	110.564
1268.84	105.901
1272.04	103.091
1275.25	101.963
1278.46	101.394
1281.66	101.51
1284.86	102.925
1288.07	103.984
1291.27	104.215
1294.47	107.149
1297.66	110.074
1300.86	112.088
1304.06	114.658
1307.25	120.053
1310.44	124.915
1313.64	129.115
1316.83	131.857
1320.02	132.684
1323.2	136.398
1326.39	137.738
1329.58	136.868
1332.76	136.024
1335.95	134.96
1339.13	131.945
1342.31	127.024
1345.49	124.529
1348.67	122.075
1351.85	118.333
1355.02	115.266
1358.2	107.729
1361.37	101.806
1364.54	95.6274
1367.71	89.2292
1370.88	84.3297
1374.05	79.5464
1377.22	75.1026
1380.39	74.7191
1383.55	72.9358
1386.72	73.9793
1389.88	73.4111
1393.04	72.9582
1396.2	70.5185
1399.36	72.7301
1402.52	76.7161
1405.68	82.3163
1408.83	87.446
1411.98	95.0394
1415.14	106.117
1418.29	118.177
1421.44	131.758
1424.59	147.679
1427.74	163.711
1430.89	177.439
1434.03	189.465
1437.18	197.988
1440.32	205.666
1443.46	212.779
1446.6	214.729
1449.74	214.588
1452.88	212.181
1456.02	210.309
1459.16	200.457
1462.29	190.402
1465.43	178.463
1468.56	163.694
1471.69	148.963
1474.82	134.167
1477.95	120.845
1481.08	107.557
1484.2	93.2437
1487.33	79.5035
1490.46	70.7986
1493.58	64.0059
1496.7	60.5507
1499.82	55.5278
1502.94	53.0685
1506.06	50.5423
1509.18	48.0249
1512.29	44.9587
1515.41	44.0993
1518.52	44.5132
1521.63	44.6611
1524.75	47.2173
1527.85	48.4378
1530.96	50.105
1534.07	50.9763
1537.18	54.8611
1540.28	58.9339
1543.39	62.5583
1546.49	65.6679
1549.59	68.769
1552.69	69.8671
1555.79	71.4605
1558.89	73.8381
1561.99	75.7273
1565.08	76.3279
1568.18	80.4094
1571.27	85.7703
1574.37	89.5956
1577.46	93.4603
1580.55	98.7299
1583.64	101.812
1586.73	106.654
1589.81	109.829
1592.9	114.945
1595.98	119.01
1599.06	121.226
1602.15	122.213
1605.23	121.142
1608.31	120.265
1611.39	122.388
1614.46	123.501
1617.54	121.32
1620.61	120.314
1623.69	119.524
1626.76	118.05
1629.83	119.463
1632.9	120.898
1635.97	122.257
1639.04	125.808
1642.11	128.167
1645.17	133.339
1648.24	135.665
1651.3	140.178
1654.36	141.33
1657.42	141.668
1660.48	141.586
1663.54	140.156
1666.6	138.753
1669.66	134.384
1672.71	128.52
1675.77	122.286
1678.82	115.591
1681.87	105.38
1684.92	97.8203
1687.97	88.8395
1691.02	79.3393
1694.07	68.8789
1697.11	61.659
1700.16	53.1678
1703.2	46.3219
1706.25	41.7286
1709.29	35.8869
1712.33	31.8373
1715.37	29.3546
1718.41	23.8081
1721.44	21.0535
1724.48	18.5554
1727.51	17.8806
1730.55	15.2528
1733.58	14.9362
1736.61	15.4406
1739.64	16.2365
1742.67	15.7064
1745.7	15.4645
1748.72	17.9064
1751.75	15.8022
1754.77	16.3675
1757.8	16.0898
1760.82	16.7384
1763.84	16.1292
1766.86	15.4303
1769.88	13.3476
1772.9	12.9204
1775.91	11.8128
1778.93	12.1752
1781.94	9.55701
1784.96	9.14932
1787.97	9.34661
1790.98	8.3102
1793.99	8.45703
1797	7.22848
1800.01	8.06777
1803.01	7.90117
1806.02	8.32577
1809.02	9.31453
1812.02	9.27546
1815.02	9.66482
1818.03	9.63237
1821.02	8.79277
1824.02	9.78359
1827.02	9.28721
1830.02	8.57327
1833.01	8.94099
1836.01	7.65614
1839	8.26196
1841.99	8.306
1844.98	7.21597
1847.97	6.01823
1850.96	5.03642
1853.95	4.19
1856.93	5.14705
1859.92	5.14766
1862.9	5.06897
1865.88	4.76722
1868.87	4.75905
1871.85	4.11911
1874.83	6.26207
1877.81	5.32265
1880.78	6.0169
1882.53	6.91555
1885.52	7.80191
1888.51	7.66841
1891.5	7.91437
1894.48	8.92902
1897.47	9.95273
1900.45	10.5594
1903.43	9.94847
1906.41	10.9378
1909.39	11.7972
1912.37	12.2673
1915.35	9.71433
1918.33	8.72087
1921.3	6.20244
1924.28	7.12037
1927.25	6.17568
1930.22	6.07367
1933.19	6.28392
1936.16	3.91553
1939.13	4.6676
1942.1	4.7878
1945.07	3.55424
1948.03	1.63774
1951	0.452739
1953.96	2.54409
1956.92	2.86513
1959.88	2.87144
1962.84	2.32298
1965.8	3.11413
1968.76	3.12129
1971.72	3.70369
1974.67	4.23408
1977.63	4.06772
1980.58	4.33279
1983.54	3.556
1986.49	1.08692
1989.44	2.1451
1992.39	2.49801
1995.33	3.97567
1998.28	5.71449
2001.23	6.53236
2004.17	6.49746
2007.12	5.79441
2010.06	5.08231
2013	6.92113
2015.94	5.55728
2018.88	5.31598
2021.82	7.22922
2024.76	10.0643
2027.69	10.6222
2030.63	10.0001
2033.56	9.57454
2036.5	9.45921
2039.43	9.38831
2042.36	11.1633
2045.29	10.9457
2048.22	10.6258
2051.15	9.251
2054.07	10.9647
2057	10.6656
2059.92	11.5834
2062.85	12.9192
2065.77	13.2852
2068.69	13.272
2071.61	13.9486
2074.53	12.188
2077.45	12.0921
2080.37	11.3142
2083.28	11.2171
2086.2	11.4688
2089.11	10.8282
2092.02	13.6671
2094.94	11.7642
2097.85	10.158
2100.76	8.56509
2103.66	7.07979
2106.57	6.9746
2109.48	4.58201
2112.38	4.44601
2115.29	4.29059
2118.19	4.6201
2121.09	5.03963
2123.99	7.95619
2126.89	8.92834
2129.79	9.02868
2132.69	9.42075
2135.59	10.7794
2138.48	10.5696
2141.38	10.1613
2144.27	12.3608
2147.17	11.1643
2150.06	13.1474
2152.95	13.5823
2155.84	14.9288
2158.73	15.5619
2161.61	15.8537
2164.5	17.7641
2167.38	18.0499
2170.27	18.8527
2173.15	17.7865
2176.03	16.1807
2178.91	18.3539
2181.8	18.3218
2184.67	18.6254
2187.55	17.209
2190.43	20.3674
2193.3	18.9244
2196.18	17.4657
2199.05	16.492
2201.93	13.1952
2204.8	11.0869
2207.67	10.2897
2210.54	9.08494
2213.41	9.822
2216.27	10.1829
2219.14	10.1184
2222.01	9.74481
2224.87	10.0301
2227.73	10.3433
2230.6	9.86772
2233.46	10.1616
2236.32	10.5333
2239.18	10.7706
2242.03	10.8551
2244.89	12.1839
2247.75	14.5348
2250.6	14.859
2253.46	14.1805
2256.31	13.7013
2259.16	15.008
2262.01	14.6159
2264.86	13.8135
2267.71	13.8909
2270.56	12.7997
2273.4	10.6209
2276.25	11.9109
2279.09	11.2881
2281.94	12.425
2284.78	12.142
2287.62	9.8144
2290.46	9.24897
2293.3	8.16782
2296.14	10.0383
2298.98	10.5072
2301.82	11.0961
2304.65	10.9278
2307.49	10.6951
2310.32	11.7543
2313.15	12.5159
2315.98	13.314
2318.81	13.8762
2321.64	13.2297
2324.47	12.763
2327.3	12.6567
2330.12	14.3448
2332.95	14.683
2335.77	13.9765
2338.6	13.1276
2341.42	11.7876
2344.24	10.2955
2347.06	9.7676
2349.88	6.96046
2352.7	4.79082
2355.51	4.61519
2358.33	3.57203
2361.14	5.48883
2363.96	4.90312
2366.77	4.75547
2369.58	3.07738
2372.39	1.69607
2375.2	0.233162
2378.01	0.0788723
2380.82	0.0838083
2383.63	2.21685
2386.43	0.697767
2389.24	0.436787
2392.04	1.93852
2394.84	1.69938
2397.65	4.25717
2400.45	4.78087
2403.25	4.70477
2406.05	5.20399
2408.84	5.2227
2411.64	4.8908
2414.44	5.57571
2417.23	5.96938
2420.02	6.86383
2422.82	6.79755
2425.61	7.975
2428.4	9.54076
2431.19	8.45814
2433.98	7.56967
2436.77	7.66116
2439.55	7.01325
2442.34	6.13944
2445.12	6.3947
2447.91	6.85814
2450.69	6.59785
2453.47	6.94391
2456.25	4.89203
2459.03	5.27326
2461.81	5.61486
2464.59	6.19366
2467.36	5.62155
2470.14	5.05747
2472.92	4.57346
2475.69	3.62642
2478.46	3.29379
2481.23	3.38406
2484	4.28595
2486.77	3.53766
2489.54	1.11036
2492.31	2.28597
2495.08	2.51288
2497.84	0.890412
2500.61	1.07885
2503.37	-0.25
2506.13	0.487612
2508.9	1.28706
2511.66	0.298615
2514.42	0.389718
2517.18	1.13687
2519.93	1.76974
2522.69	1.7761
2525.45	4.26053
2528.2	5.0595
2530.95	6.55717
2533.71	5.98937
2536.46	6.4638
2539.21	6.25983
2541.96	6.4441
2544.71	7.0812
2547.46	6.61232
2550.2	8.30161
2552.95	8.18522
2555.7	7.7105
2558.44	7.14839
2561.18	7.21678
2563.93	6.81729
2566.67	7.88889
2569.41	8.08451
2572.15	6.65455
2574.88	6.22263
2577.62	4.49523
2580.36	4.51168
2583.09	4.90707
2585.83	6.07393
2588.56	5.06373
2591.29	5.01405
2594.02	5.23162
2596.75	4.05327
2599.48	2.6958
2602.21	1.54682
2604.94	1.49728
2607.67	1.71588
2610.39	3.50939
2613.12	4.3024
2615.84	6.55345
2618.56	9.35049
2621.28	8.90927
2624.01	8.42399
2626.72	9.65148
2629.44	10.0758
2632.16	13.0712
2634.88	14.061
2637.59	14.0782
2640.31	14.4482
2643.02	14.9237
2645.74	15.3206
2648.45	14.4345
2651.16	13.062
2653.87	11.8331
2656.58	9.35519
2659.29	9.49351
2661.99	7.86543
2664.7	4.98508
2667.41	4.40216
2670.11	3.88868
2672.81	5.95894
2675.51	7.75541
2678.22	8.45823
2680.92	8.52322
2683.62	8.92977
2686.31	9.35231
2689.01	7.73525
2691.71	8.22117
2694.4	8.54084
2697.1	11.7863
2699.79	13.3595
2702.49	15.0004
2705.18	16.4404
2707.87	17.2896
2710.56	17.642
2713.25	16.697
2715.94	17.2693
2718.62	18.4595
2721.31	18.9019
2723.99	20.508
2726.68	19.2172
2729.36	18.5659
2732.04	18.6185
2734.73	18.4657
2737.41	19.0754
2740.08	20.0868
2742.76	18.9352
2745.44	17.7461
2748.12	17.061
2750.79	16.4597
2753.47	15.1524
2756.14	13.7991
2758.81	14.3275
2761.49	14.4483
2764.16	13.2842
2766.83	11.5956
2769.5	9.59357
2772.16	9.33219
2774.83	7.76604
2777.5	7.41662
2780.16	7.90728
2782.83	7.46367
2785.49	7.28413
2788.15	6.34553
2790.82	3.76348
2793.48	3.65297
2796.14	3.80601
2798.79	4.31662
2801.45	2.93245
2804.11	2.50576
2806.76	2.2519
2809.42	2.05034
2812.07	3.43885
2814.73	6.93776
2817.38	11.1471
2820.03	17.1962
2822.68	25.1571
2825.33	34.4913
2827.98	42.7682
2830.63	52.5678
2833.27	62.8995
2835.92	76.3681
2838.56	91.0717
2841.21	108.886
2843.85	128.936
2846.49	148.532
2849.13	169.797
2851.77	193.794
2854.41	216.845
2857.05	238.803
2859.69	259.268
2862.32	278.306
2864.96	293.945
2867.59	307.651
2870.23	320.447
2872.86	333.277
2875.49	345.819
2878.12	354.428
2880.75	362.599
2883.38	370.392
2886.01	377.512
2888.63	384.66
2891.26	391.583
2893.89	397.855
2896.51	406.415
2899.13	418.758
2901.76	433.817
2904.38	451.261
2907	471.921
2909.62	495.405
2912.24	521.289
2914.85	544.622
2917.47	566.651
2920.09	585.792
2922.7	600.853
2925.32	610.826
2927.93	616.745
2930.54	616.58
2933.15	613.992
2935.76	606.51
2938.37	596.537
2940.98	580.459
2943.59	560.593
2946.2	539.829
2948.8	516.945
2951.41	494.688
2954.01	469.543
2956.62	443.851
2959.22	420.131
2961.82	396.524
2964.42	374.33
2967.02	352.935
2969.62	333.378
2972.22	314.988
2974.81	299.266
2977.41	281.665
2980	263.935
2982.6	245.638
2985.19	225.904
2987.78	206.943
2990.38	187.789
2992.97	167.655
2995.56	150.84
2998.14	133.293
3000.73	117.733
3003.32	102.686
3005.91	87.3156
3008.49	73.395
3011.07	62.2111
3013.66	52.3897
3016.24	43.899
3018.82	35.7807
3021.4	26.5853
3023.98	20.3393
3026.56	15.2702
3029.14	12.5007
3031.71	11.5265
3034.29	9.8396
3036.87	10.7738
3039.44	12.0519
3042.01	12.3082
3044.59	14.3304
3047.16	16.7206
3049.73	18.2795
3052.3	20.9572
3054.87	20.9612
3057.43	21.2439
3060	20.4097
3062.57	19.5296
3065.13	18.7448
3067.7	17.3396
3070.26	16.3322
3072.82	14.9287
3075.39	13.7184
3077.95	11.9559
3080.51	10.2687
3083.07	7.68089
3085.63	5.46772
3088.18	5.57122
3090.74	4.9265
3093.29	6.53337
3095.85	6.9029
3098.4	7.39505
3100.95	8.81437
3103.51	11.3999
3106.06	14.0242
3108.61	17.9929
3111.16	21.9711
3113.71	23.7943
3116.25	27.0412
3118.8	30.2338
3121.35	33.6894
3123.89	37.078
3126.44	40.7885
3128.98	44.8354
3131.52	48.5213
3134.06	51.7628
3136.6	55.0298
3139.14	58.0572
3141.68	60.5091
3144.22	62.1288
3146.76	63.2272
3149.29	62.3622