File: data/Raman/poly_smoothed/Mb_00_13_46_1x_45s_532 nm_x100_100%_600 gr_mm_01.txt
#Acq. time (s)=	45
#Accumulations=	2
#Range (cm-¹)=	200...3150
#Windows=	2
#Auto scanning=	Off
#Autofocus=	Off
#Macrospot=	Off
#AutoExposure=	Off
#Spike filter=	Multiple accum.
#Delay time (s)=	0
#Binning=	1
#Readout mode=	Signal
#DeNoise=	Off
#ICS correction=	On
#Dark correction=	Off
#Inst. Process=	Off
#Detector Gain=	Best Dynamic Range
#Detector ADC=	20 kHz
#Detector temperature (°C)=	-69.85
#Instrument=	LabRAM HR Evol
#Detector=	Synapse
#Objective=	x100
#Grating=	600 gr/mm
#ND Filter=	100%
#Laser (nm)=	532
#Hole=	100.021
#Range=	Auto
#Laser Pol.=	No
#Raman. Pol.=	No
#Laser Pol. (°)=	-0.0007625
#Raman Pol. (°)=	89.9995
#Collection=	Microscope
#StageXY=	Marzhauser
#StageZ=	Marzhauser
#X (µm)=	-1059.9
#Y (µm)=	-2885.2
#Z (µm)=	528
#Full time(mm:ss)=	3:18
#Project=
#Sample=
#Site=
#Title=	Mb_00_13_46_2x_45s_532 nm_x100_100%_600 gr_mm
#Remark=
#Date=	06.07.2022 13:23
#Acquired=	06.07.2022 13:23:01
#Base:Fit=	10.08.2022 10:16:56
#Base:Sub=	10.08.2022 10:17:24
#Filter:Polynom=	16.08.2022 10:36:38
#AxisType[0]=Intens
#AxisUnit[0]=Cnt
#AxisType[1]=Spectr
#AxisUnit[1]=1/cm
200.398	21.8733
204.027	13.9383
207.657	4.99268
211.283	-1.29523
214.909	-1.67923
218.533	4.86024
222.157	20.2334
225.777	39.9142
229.396	61.6962
233.016	85.1849
236.632	109.156
240.247	129.23
243.86	145.158
247.474	160.877
251.085	174.019
254.694	187.392
258.301	198.479
261.908	202.008
265.513	200.567
269.116	195.659
272.718	186.953
276.319	173.155
279.918	157.274
283.516	138.203
287.113	117.61
290.708	96.9086
294.302	78.4094
297.894	60.8133
301.485	47.2328
305.073	37.4799
308.661	33.6254
312.247	28.3616
315.833	26.7821
319.415	27.5479
322.997	27.1859
326.579	26.5024
330.156	24.0459
333.735	22.9518
337.31	23.1189
340.885	22.2245
344.458	19.6928
348.03	15.771
351.6	13.3217
355.17	8.8274
358.737	8.90139
362.304	9.33101
365.868	14.4848
369.431	22.5352
372.994	34.1106
376.554	43.3207
380.112	55.2185
383.669	73.0324
387.225	97.551
390.781	122.404
394.334	147.524
397.885	171.411
401.436	186.651
404.984	200.284
408.532	209.257
412.078	212.274
415.623	210.069
419.166	207.809
422.708	198.827
426.248	188.02
429.788	171.24
433.326	151.504
436.86	131.812
440.395	110.807
443.929	90.4306
447.461	75.2318
450.99	61.0271
454.52	48.8849
458.048	37.4981
461.573	27.9468
465.099	21.6566
468.623	24.901
472.144	29.6912
475.666	35.2446
479.184	39.3701
482.703	43.3273
486.218	46.3917
489.734	49.3943
493.247	51.8479
496.759	53.3327
500.271	57.2644
503.779	60.0545
507.287	61.9459
510.795	61.6729
514.299	62.3953
517.803	65.1916
521.305	67.3267
524.805	70.0749
528.307	71.3827
531.805	73.935
535.301	72.3088
538.797	70.4351
542.291	68.4931
545.783	68.7457
549.275	62.0312
552.765	58.0817
556.253	53.3401
559.738	50.75
563.224	47.7338
566.709	44.9814
570.192	45.0895
573.674	40.4944
577.153	36.5596
580.632	34.3462
584.11	32.424
587.587	28.651
591.06	27.8243
594.534	25.7239
598.005	25.4865
601.476	27.8382
604.944	31.0079
608.413	31.7531
611.878	31.6654
615.344	31.8653
618.807	31.7589
622.27	31.1425
625.73	33.427
629.189	37.0715
632.648	41.2939
636.105	43.5811
639.559	48.4287
643.013	53.1471
646.467	53.1373
649.918	54.4469
653.368	56.5388
656.816	57.7269
660.263	53.7448
663.708	49.8395
667.153	46.0415
670.596	43.1963
674.037	41.1401
677.478	37.7129
680.917	33.7294
684.355	32.1726
687.791	28.209
691.224	23.0217
694.658	18.4342
698.091	14.885
701.522	10.1816
704.95	8.05574
708.379	9.35275
711.806	10.9211
715.23	13.9926
718.655	16.6944
722.078	20.1961
725.498	21.3344
728.919	21.062
732.337	22.212
735.755	27.3779
739.17	28.4297
742.584	28.2526
745.998	30.2746
749.409	33.0861
752.819	36.758
756.23	40.8269
759.637	42.6197
763.043	43.6314
766.448	45.8027
769.853	46.1423
773.255	48.2826
776.656	49.7102
780.056	48.6081
783.454	49.7926
786.851	50.4388
790.247	50.288
793.641	50.4844
797.034	51.4708
800.426	52.7633
803.817	54.4907
807.206	52.1362
810.592	52.7655
813.979	52.9234
817.364	52.7023
820.748	53.4122
824.129	54.9837
827.511	56.0657
830.891	56.4336
834.269	58.7099
837.646	58.0909
841.023	56.3246
844.396	55.806
847.77	53.0589
851.141	52.8128
854.513	51.4757
857.881	46.5898
861.248	41.9859
864.616	37.4855
867.98	33.1304
871.343	28.4212
874.707	27.175
878.068	24.9512
881.428	23.4157
884.786	21.7694
888.143	22.9703
891.498	20.8596
894.855	19.4449
898.208	15.5526
901.56	14.2021
904.91	17.2884
908.26	17.4897
911.608	17.271
914.955	18.6703
918.298	17.9079
921.643	18.556
924.986	21.3067
928.328	20.1811
931.668	20.2273
935.006	20.0494
938.344	17.1536
941.681	16.0457
945.014	15.9643
948.349	15.2704
951.682	14.9708
955.012	15.3215
958.343	12.9002
961.67	8.78823
964.998	12.8573
968.323	16.2279
971.649	25.1722
974.971	37.059
978.293	52.1732
981.615	68.6421
984.933	86.3179
988.251	98.7246
991.567	110.327
994.884	119.545
998.198	127.273
1001.51	131.382
1004.82	134.653
1008.13	131.892
1011.44	124.478
1014.75	119.381
1018.06	116.539
1021.36	116.538
1024.66	121.043
1027.97	128.793
1031.27	134.23
1034.57	140.278
1037.87	142.725
1041.16	144.6
1044.46	153.163
1047.76	158.126
1051.05	163.405
1054.34	169.779
1057.63	172.701
1060.92	174.005
1064.21	168.558
1067.5	159.052
1070.78	147.07
1074.07	132.334
1077.35	112.898
1080.63	90.4515
1083.91	69.9418
1087.19	48.0964
1090.47	27.5466
1093.75	13.8414
1097.03	5.02226
1100.3	1.88735
1103.57	3.71374
1106.84	8.01071
1110.11	10.6969
1113.38	11.4668
1116.65	12.8948
1119.92	14.1544
1123.19	15.5008
1126.45	17.6998
1129.71	16.4418
1132.97	16.755
1136.23	18.5035
1139.49	18.617
1142.75	19.9411
1146.01	18.1165
1149.26	16.0013
1152.52	14.4681
1155.77	14.01
1159.02	11.3191
1162.27	11.3605
1165.52	10.2754
1168.77	7.9422
1172.02	8.46989
1175.26	5.58054
1178.51	6.6605
1181.75	7.43598
1184.99	10.0683
1188.23	11.0748
1191.47	15.0178
1194.71	18.562
1197.94	22.4278
1201.18	27.3155
1204.41	32.4114
1207.65	35.7139
1210.88	41.2218
1214.11	48.6354
1217.34	55.0974
1220.57	59.2298
1223.79	63.2151
1227.02	68.1772
1230.24	72.9418
1233.47	76.568
1236.69	80.3937
1239.91	82.8731
1243.13	85.1903
1246.34	85.51
1249.56	84.6757
1252.78	83.4142
1255.99	80.8191
1259.2	80.8458
1262.42	78.6128
1265.63	77.0268
1268.84	72.3568
1272.04	72.392
1275.25	72.4039
1278.46	72.3983
1281.66	74.2181
1284.86	77.776
1288.07	81.4298
1291.27	82.4021
1294.47	86.223
1297.66	88.0791
1300.86	91.3838
1304.06	93.6268
1307.25	96.6613
1310.44	99.4952
1313.64	103.97
1316.83	106.692
1320.02	110.034
1323.2	110.318
1326.39	109.95
1329.58	109.238
1332.76	108.521
1335.95	108.851
1339.13	106.835
1342.31	106.761
1345.49	104.372
1348.67	102.789
1351.85	103.882
1355.02	103.018
1358.2	101.772
1361.37	99.1251
1364.54	97.4594
1367.71	93.2445
1370.88	89.0813
1374.05	84.1943
1377.22	79.9263
1380.39	77.3598
1383.55	75.173
1386.72	75.2447
1389.88	73.3521
1393.04	69.3656
1396.2	67.5738
1399.36	64.144
1402.52	64.2758
1405.68	66.8581
1408.83	70.6323
1411.98	77.9365
1415.14	87.6461
1418.29	96.608
1421.44	107.207
1424.59	116.031
1427.74	128.479
1430.89	140.044
1434.03	151.461
1437.18	160.096
1440.32	167.486
1443.46	171.755
1446.6	174.685
1449.74	175.095
1452.88	173.622
1456.02	172.587
1459.16	166.22
1462.29	160.182
1465.43	151.767
1468.56	139.542
1471.69	125.943
1474.82	116.974
1477.95	106.702
1481.08	98.1927
1484.2	89.3425
1487.33	84.2033
1490.46	79.6492
1493.58	74.3484
1496.7	69.4333
1499.82	64.6806
1502.94	61.7948
1506.06	61.4524
1509.18	60.0297
1512.29	56.9585
1515.41	53.5562
1518.52	53.6843
1521.63	52.179
1524.75	50.3778
1527.85	49.9077
1530.96	48.2855
1534.07	49.2511
1537.18	49.9399
1540.28	53.4086
1543.39	54.8783
1546.49	55.8652
1549.59	58.2948
1552.69	61.4209
1555.79	64.7436
1558.89	65.4816
1561.99	69.0382
1565.08	70.8856
1568.18	73.8361
1571.27	75.9984
1574.37	79.5498
1577.46	83.7344
1580.55	87.1212
1583.64	90.6015
1586.73	93.9091
1589.81	96.1462
1592.9	100.683
1595.98	101.434
1599.06	103.114
1602.15	102.905
1605.23	103.928
1608.31	104.226
1611.39	103.807
1614.46	103.243
1617.54	103.339
1620.61	101.932
1623.69	99.926
1626.76	100.005
1629.83	97.3652
1632.9	96.2286
1635.97	93.5245
1639.04	91.7794
1642.11	93.4634
1645.17	94.0786
1648.24	93.4063
1651.3	95.399
1654.36	94.423
1657.42	93.5089
1660.48	92.018
1663.54	90.6797
1666.6	85.5022
1669.66	85.1089
1672.71	79.0484
1675.77	75.061
1678.82	68.9092
1681.87	61.994
1684.92	55.8193
1687.97	49.4531
1691.02	42.4086
1694.07	36.6986
1697.11	30.7493
1700.16	25.6805
1703.2	20.5714
1706.25	17.1427
1709.29	14.0543
1712.33	9.14427
1715.37	6.54367
1718.41	4.97576
1721.44	0.886168
1724.48	1.09752
1727.51	-0.105709
1730.55	-1.49053
1733.58	-1.89937
1736.61	-2.79244
1739.64	-2.38337
1742.67	-2.12505
1745.7	-1.90717
1748.72	-1.67718
1751.75	-0.791766
1754.77	-2.33127
1757.8	-1.83526
1760.82	0.0494944
1763.84	0.23361
1766.86	0.655014
1769.88	1.24126
1772.9	3.13739
1775.91	4.13471
1778.93	6.58915
1781.94	7.46779
1784.96	8.03587
1787.97	7.43754
1790.98	7.24281
1793.99	6.64957
1797	6.7891
1800.01	6.50713
1803.01	5.44853
1806.02	4.37437
1809.02	5.07199
1812.02	3.678
1815.02	3.14361
1818.03	3.45152
1821.02	3.43964
1824.02	4.05612
1827.02	4.25045
1830.02	3.93617
1833.01	3.05674
1836.01	3.3603
1839	3.34256
1841.99	4.63456
1844.98	5.97311
1847.97	6.95583
1850.96	8.60837
1853.95	9.93267
1856.93	8.16524
1859.92	7.25802
1862.9	7.10182
1865.88	7.24621
1868.87	6.29184
1871.85	6.66201
1874.83	5.31874
1877.81	6.37516
1880.78	7.50769
1882.53	8.84007
1885.52	10.7525
1888.51	12.8168
1891.5	13.6182
1894.48	13.3275
1897.47	13.9997
1900.45	12.8519
1903.43	14.1349
1906.41	14.6538
1909.39	16.2174
1912.37	16.2186
1915.35	17.3919
1918.33	15.988
1921.3	16.2219
1924.28	14.5402
1927.25	11.6302
1930.22	9.47345
1933.19	8.55049
1936.16	7.10354
1939.13	6.72255
1942.1	6.76713
1945.07	7.2598
1948.03	7.93245
1951	9.35145
1953.96	13.7365
1956.92	16.414
1959.88	18.2569
1962.84	16.4787
1965.8	17.1988
1968.76	17.281
1971.72	17.2729
1974.67	19.0498
1977.63	18.3417
1980.58	18.5801
1983.54	17.8295
1986.49	17.3669
1989.44	17.4962
1992.39	17.4656
1995.33	16.7394
1998.28	15.7288
2001.23	14.382
2004.17	13.238
2007.12	13.7664
2010.06	11.4382
2013	10.2385
2015.94	9.95121
2018.88	8.69131
2021.82	9.72826
2024.76	11.7824
2027.69	12.8352
2030.63	12.7826
2033.56	12.7941
2036.5	13.0713
2039.43	14.1644
2042.36	13.4052
2045.29	14.0026
2048.22	15.9542
2051.15	16.4939
2054.07	18.8927
2057	20.1111
2059.92	22.5708
2062.85	22.8585
2065.77	24.2298
2068.69	25.0671
2071.61	24.268
2074.53	22.4441
2077.45	21.5834
2080.37	20.8585
2083.28	20.4829
2086.2	20.4041
2089.11	20.7263
2092.02	20.8242
2094.94	22.3017
2097.85	21.0572
2100.76	21.7697
2103.66	21.883
2106.57	21.7362
2109.48	20.325
2112.38	21.8526
2115.29	20.0197
2118.19	23.1757
2121.09	21.9203
2123.99	21.9472
2126.89	22.9797
2129.79	21.6315
2132.69	19.9371
2135.59	17.4154
2138.48	15.4739
2141.38	14.6604
2144.27	14.3425
2147.17	13.3605
2150.06	15.5604
2152.95	15.7242
2155.84	16.9927
2158.73	17.9784
2161.61	16.7396
2164.5	17.6893
2167.38	17.5772
2170.27	19.4783
2173.15	22.7691
2176.03	22.3858
2178.91	23.2659
2181.8	25.5069
2184.67	26.443
2187.55	28.5698
2190.43	30.6212
2193.3	31.2697
2196.18	31.7403
2199.05	31.201
2201.93	30.0689
2204.8	28.5963
2207.67	26.8979
2210.54	26.8039
2213.41	27.5704
2216.27	26.8615
2219.14	27.1408
2222.01	27.6557
2224.87	25.2371
2227.73	23.4715
2230.6	23.8934
2233.46	22.0953
2236.32	21.6247
2239.18	20.8779
2242.03	22.2752
2244.89	21.6926
2247.75	21.5904
2250.6	22.7944
2253.46	24.8667
2256.31	25.4452
2259.16	25.8772
2262.01	25.0454
2264.86	24.1457
2267.71	22.418
2270.56	22.4541
2273.4	22.224
2276.25	20.8221
2279.09	20.6184
2281.94	21.3958
2284.78	21.7234
2287.62	21.1264
2290.46	18.6609
2293.3	15.213
2296.14	14.2915
2298.98	16.5766
2301.82	17.172
2304.65	16.0066
2307.49	15.2457
2310.32	15.6098
2313.15	14.8748
2315.98	15.6439
2318.81	14.4978
2321.64	14.9857
2324.47	13.6055
2327.3	12.5843
2330.12	11.345
2332.95	10.5544
2335.77	9.11977
2338.6	8.51408
2341.42	9.03344
2344.24	6.99029
2347.06	6.44545
2349.88	4.71999
2352.7	3.63885
2355.51	2.71074
2358.33	0.66877
2361.14	-1.13176
2363.96	1.42226
2366.77	3.32445
2369.58	4.46781
2372.39	4.55476
2375.2	3.70217
2378.01	4.80813
2380.82	5.3548
2383.63	5.05463
2386.43	7.46
2389.24	8.67182
2392.04	10.847
2394.84	12.8474
2397.65	13.5426
2400.45	12.98
2403.25	13.1682
2406.05	12.5782
2408.84	12.1721
2411.64	11.7974
2414.44	9.21769
2417.23	8.92806
2420.02	8.12567
2422.82	9.2476
2425.61	7.68921
2428.4	6.66796
2431.19	5.14301
2433.98	6.38926
2436.77	6.28271
2439.55	4.76393
2442.34	2.68649
2445.12	1.91757
2447.91	0.727842
2450.69	0.152645
2453.47	0.253674
2456.25	1.94486
2459.03	3.35487
2461.81	4.44826
2464.59	5.6402
2467.36	4.06278
2470.14	2.87041
2472.92	3.71064
2475.69	4.06633
2478.46	4.31698
2481.23	4.47402
2484	4.90297
2486.77	5.64676
2489.54	5.43047
2492.31	5.97374
2495.08	4.38631
2497.84	3.68072
2500.61	3.00691
2503.37	4.0989
2506.13	3.76294
2508.9	2.98936
2511.66	3.94924
2514.42	4.24842
2517.18	4.4343
2519.93	5.96187
2522.69	7.60638
2525.45	8.94563
2528.2	8.92079
2530.95	10.5573
2533.71	9.70882
2536.46	9.09602
2539.21	9.14934
2541.96	8.22146
2544.71	6.66706
2547.46	5.1903
2550.2	4.68877
2552.95	2.71721
2555.7	3.37075
2558.44	3.47446
2561.18	1.43143
2563.93	1.95804
2566.67	2.00992
2569.41	1.67275
2572.15	2.7153
2574.88	3.77882
2577.62	4.05243
2580.36	5.90808
2583.09	7.20087
2585.83	8.63111
2588.56	10.1482
2591.29	11.2086
2594.02	12.797
2596.75	12.6527
2599.48	13.3864
2602.21	12.2634
2604.94	11.2025
2607.67	10.3019
2610.39	9.79674
2613.12	9.56222
2615.84	8.34973
2618.56	6.6347
2621.28	6.99864
2624.01	6.7996
2626.72	5.31113
2629.44	5.48966
2632.16	7.01189
2634.88	4.89534
2637.59	4.91319
2640.31	3.78673
2643.02	3.99479
2645.74	6.85803
2648.45	7.72119
2651.16	7.62232
2653.87	9.11519
2656.58	9.90365
2659.29	10.8244
2661.99	10.7699
2664.7	11.8153
2667.41	12.1657
2670.11	12.2421
2672.81	12.9702
2675.51	12.7687
2678.22	13.283
2680.92	13.2138
2683.62	11.9687
2686.31	11.911
2689.01	12.874
2691.71	13.412
2694.4	14.668
2697.1	13.7738
2699.79	13.4662
2702.49	12.4547
2705.18	14.2971
2707.87	14.344
2710.56	17.2811
2713.25	18.8586
2715.94	18.774
2718.62	20.3077
2721.31	20.6181
2723.99	21.6415
2726.68	20.9677
2729.36	22.7588
2732.04	23.0328
2734.73	22.9173
2737.41	21.0927
2740.08	19.5158
2742.76	17.158
2745.44	14.7548
2748.12	13.5963
2750.79	11.49
2753.47	11.0101
2756.14	9.54478
2758.81	9.13338
2761.49	6.20784
2764.16	4.79898
2766.83	5.95021
2769.5	5.53089
2772.16	5.66776
2774.83	5.5317
2777.5	6.68139
2780.16	5.64671
2782.83	5.25148
2785.49	4.63476
2788.15	4.54928
2790.82	4.45718
2793.48	3.78398
2796.14	4.5012
2798.79	4.61566
2801.45	2.8411
2804.11	1.07711
2806.76	-0.462686
2809.42	-1.32531
2812.07	-0.376161
2814.73	2.22513
2817.38	5.947
2820.03	12.1759
2822.68	19.7239
2825.33	29.1316
2827.98	37.8398
2830.63	49.0941
2833.27	59.714
2835.92	71.0239
2838.56	84.1794
2841.21	98.5524
2843.85	113.836
2846.49	130.28
2849.13	146.953
2851.77	166.723
2854.41	185.682
2857.05	203.385
2859.69	220.79
2862.32	237.845
2864.96	251.306
2867.59	262.869
2870.23	274.163
2872.86	284.084
2875.49	294.302
2878.12	301.873
2880.75	310.307
2883.38	318.317
2886.01	326.027
2888.63	332.431
2891.26	336.446
2893.89	342.513
2896.51	345.892
2899.13	352.088
2901.76	361.909
2904.38	371.962
2907	383.467
2909.62	397.591
2912.24	414.27
2914.85	431.5
2917.47	446.357
2920.09	457.778
2922.7	467.156
2925.32	473.571
2927.93	476.828
2930.54	477.096
2933.15	473.303
2935.76	468.396
2938.37	457.81
2940.98	444.64
2943.59	431.887
2946.2	415.279
2948.8	398.669
2951.41	379.337
2954.01	358.895
2956.62	339.041
2959.22	318.934
2961.82	299.739
2964.42	285.035
2967.02	268.749
2969.62	252.887
2972.22	239.585
2974.81	228.212
2977.41	215.565
2980	200.194
2982.6	185.056
2985.19	170.231
2987.78	155.151
2990.38	139.127
2992.97	125.093
2995.56	111.569
2998.14	99.4236
3000.73	85.3634
3003.32	72.5829
3005.91	61.8942
3008.49	51.7094
3011.07	41.6345
3013.66	33.6756
3016.24	25.5529
3018.82	19.446
3021.4	12.4021
3023.98	7.9148
3026.56	5.53758
3029.14	2.25094
3031.71	-0.201417
3034.29	-0.143321
3036.87	-0.677166
3039.44	0.472935
3042.01	0.600272
3044.59	1.66264
3047.16	2.98376
3049.73	3.95711
3052.3	5.57918
3054.87	5.69635
3057.43	7.84883
3060	8.55085
3062.57	8.39437
3065.13	8.28075
3067.7	7.65903
3070.26	7.10892
3072.82	7.82302
3075.39	6.53113
3077.95	5.35274
3080.51	3.78353
3083.07	1.81727
3085.63	1.76345
3088.18	1.74414
3090.74	1.69016
3093.29	0.133573
3095.85	0.986927
3098.4	0.630724
3100.95	2.48509
3103.51	3.71339
3106.06	4.16633
3108.61	5.3962
3111.16	5.95833
3113.71	7.93047
3116.25	9.17869
3118.8	10.4756
3121.35	12.7917
3123.89	14.3693
3126.44	15.9894
3128.98	18.5737
3131.52	20.5791
3134.06	23.9582
3136.6	26.4943
3139.14	29.04
3141.68	33.1424
3144.22	36.2761
3146.76	39.6246
3149.29	39.2746