File: data/Raman/poly_smoothed/Mb_00_13_26_1x_45s_532 nm_x100_100%_600 gr_mm_01.txt
#Acq. time (s)=	45
#Accumulations=	2
#Range (cm-¹)=	200...3150
#Windows=	2
#Auto scanning=	Off
#Autofocus=	Off
#Macrospot=	Off
#AutoExposure=	Off
#Spike filter=	Multiple accum.
#Delay time (s)=	0
#Binning=	1
#Readout mode=	Signal
#DeNoise=	Off
#ICS correction=	On
#Dark correction=	Off
#Inst. Process=	Off
#Detector Gain=	Best Dynamic Range
#Detector ADC=	20 kHz
#Detector temperature (°C)=	-69.85
#Instrument=	LabRAM HR Evol
#Detector=	Synapse
#Objective=	x100
#Grating=	600 gr/mm
#ND Filter=	100%
#Laser (nm)=	532
#Hole=	100.021
#Range=	Auto
#Laser Pol.=	No
#Raman. Pol.=	No
#Laser Pol. (°)=	-0.0007625
#Raman Pol. (°)=	89.9995
#Collection=	Microscope
#StageXY=	Marzhauser
#StageZ=	Marzhauser
#X (µm)=	-959.3
#Y (µm)=	-2852.3
#Z (µm)=	528.45
#Full time(mm:ss)=	3:19
#Project=
#Sample=
#Site=
#Title=	Mb_00_13_26_2x_45s_532 nm_x100_100%_600 gr_mm
#Remark=
#Date=	06.07.2022 11:44
#Acquired=	06.07.2022 11:44:08
#Base:Fit=	10.08.2022 10:16:56
#Base:Sub=	10.08.2022 10:17:24
#Filter:Polynom=	16.08.2022 10:36:38
#AxisType[0]=Intens
#AxisUnit[0]=Cnt
#AxisType[1]=Spectr
#AxisUnit[1]=1/cm
200.398	43.1491
204.027	32.1686
207.657	18.7017
211.283	10.4818
214.909	8.58896
218.533	14.2508
222.157	23.442
225.777	35.9269
229.396	46.1766
233.016	59.1371
236.632	68.0673
240.247	76.3112
243.86	84.5011
247.474	91.7228
251.085	100.969
254.694	104.648
258.301	109.938
261.908	113.015
265.513	115.244
269.116	110.951
272.718	106.223
276.319	99.1745
279.918	90.9572
283.516	81.8143
287.113	70.5273
290.708	57.3996
294.302	48.966
297.894	43.3874
301.485	40.3496
305.073	39.1887
308.661	36.5727
312.247	33.3025
315.833	30.4775
319.415	28.1195
322.997	26.5788
326.579	23.6167
330.156	23.5445
333.735	22.7723
337.31	20.1191
340.885	18.9716
344.458	18.3532
348.03	17.2821
351.6	15.2929
355.17	16.2058
358.737	17.0797
362.304	17.73
365.868	22.0587
369.431	27.5334
372.994	32.3624
376.554	36.6966
380.112	48.8107
383.669	62.3642
387.225	74.823
390.781	87.7296
394.334	96.9461
397.885	106.639
401.436	111.529
404.984	115.21
408.532	118.64
412.078	119.771
415.623	120.026
419.166	117.949
422.708	113.819
426.248	107.521
429.788	99.5175
433.326	89.204
436.86	78.3722
440.395	70.1786
443.929	63.444
447.461	57.7825
450.99	52.9421
454.52	49.3854
458.048	47.3272
461.573	45.7937
465.099	48.8418
468.623	51.7605
472.144	53.761
475.666	54.9436
479.184	57.2327
482.703	58.0474
486.218	57.9605
489.734	58.8099
493.247	61.0063
496.759	63.34
500.271	65.3627
503.779	68.286
507.287	68.0774
510.795	68.4022
514.299	67.9861
517.803	66.9945
521.305	67.1519
524.805	67.4206
528.307	68.8732
531.805	68.9377
535.301	68.4993
538.797	66.7149
542.291	65.5786
545.783	64.6093
549.275	59.8105
552.765	56.1766
556.253	52.1422
559.738	48.6389
563.224	45.4082
566.709	44.4296
570.192	41.4948
573.674	38.0906
577.153	35.5944
580.632	34.0137
584.11	33.5768
587.587	32.7479
591.06	29.6872
594.534	25.8481
598.005	25.4576
601.476	24.9447
604.944	25.5819
608.413	25.7599
611.878	26.0495
615.344	25.7204
618.807	22.7936
622.27	21.6035
625.73	21.8716
629.189	23.3735
632.648	23.0185
636.105	25.3409
639.559	27.7342
643.013	30.6355
646.467	30.3889
649.918	30.5622
653.368	29.8765
656.816	27.8004
660.263	27.589
663.708	28.3905
667.153	26.4298
670.596	24.7899
674.037	22.8271
677.478	18.8818
680.917	16.7399
684.355	15.1611
687.791	14.2872
691.224	13.0377
694.658	10.7675
698.091	9.52139
701.522	7.05153
704.95	4.89195
708.379	5.68848
711.806	6.27116
715.23	6.89826
718.655	7.43346
722.078	7.38826
725.498	4.89624
728.919	2.82433
732.337	3.26777
735.755	1.8063
739.17	1.30823
742.584	2.65134
745.998	5.4116
749.409	6.52605
752.819	10.9505
756.23	13.9425
759.637	14.4135
763.043	17.0362
766.448	20.0405
769.853	24.5247
773.255	28.3082
776.656	30.7533
780.056	33.6808
783.454	35.8994
786.851	38.0469
790.247	39.0908
793.641	40.1589
797.034	40.3065
800.426	40.5608
803.817	40.0929
807.206	40.1237
810.592	40.5574
813.979	39.9744
817.364	42.3214
820.748	43.2278
824.129	46.8959
827.511	47.2812
830.891	49.1383
834.269	51.0388
837.646	49.6586
841.023	46.132
844.396	44.6016
847.77	42.6365
851.141	40.5386
854.513	37.1075
857.881	34.0859
861.248	29.396
864.616	24.556
867.98	21.4745
871.343	17.9864
874.707	14.1427
878.068	12.6087
881.428	10.0449
884.786	7.78084
888.143	5.05588
891.498	5.81734
894.855	7.24889
898.208	7.46542
901.56	8.21696
904.91	11.015
908.26	9.65662
911.608	12.1405
914.955	13.011
918.298	13.6009
921.643	14.4519
924.986	16.1876
928.328	17.1697
931.668	18.4737
935.006	17.4577
938.344	16.8034
941.681	17.9224
945.014	17.0056
948.349	15.3521
951.682	16.14
955.012	15.6397
958.343	11.9475
961.67	12.1565
964.998	13.0224
968.323	18.0212
971.649	24.9222
974.971	32.7311
978.293	41.5358
981.615	52.4402
984.933	58.4659
988.251	64.6492
991.567	69.0101
994.884	73.2604
998.198	76.5383
1001.51	77.7641
1004.82	77.8061
1008.13	74.1845
1011.44	71.9408
1014.75	72.8827
1018.06	77.9165
1021.36	86.0904
1024.66	91.648
1027.97	96.3007
1031.27	101.183
1034.57	103.758
1037.87	104.238
1041.16	105.454
1044.46	110.51
1047.76	113.034
1051.05	113.358
1054.34	115.099
1057.63	112.241
1060.92	108.855
1064.21	99.8208
1067.5	87.7368
1070.78	76.7868
1074.07	66.0921
1077.35	52.3129
1080.63	37.5354
1083.91	25.2854
1087.19	13.846
1090.47	10.2377
1093.75	9.47133
1097.03	12.5713
1100.3	14.3193
1103.57	16.7312
1106.84	18.0026
1110.11	19.4254
1113.38	17.619
1116.65	17.489
1119.92	17.2689
1123.19	15.4389
1126.45	15.9198
1129.71	14.999
1132.97	15.0141
1136.23	16.4643
1139.49	16.071
1142.75	16.5553
1146.01	16.7177
1149.26	13.8115
1152.52	12.8698
1155.77	11.3408
1159.02	7.55697
1162.27	10.0311
1165.52	10.688
1168.77	10.6774
1172.02	11.1944
1175.26	11.678
1178.51	13.0193
1181.75	12.4067
1184.99	15.0872
1188.23	17.0766
1191.47	19.0738
1194.71	22.9512
1197.94	26.4729
1201.18	31.4202
1204.41	39.3169
1207.65	47.1168
1210.88	57.2164
1214.11	63.5596
1217.34	73.9904
1220.57	80.8104
1223.79	87.5202
1227.02	94.0913
1230.24	99.3446
1233.47	103.896
1236.69	106.308
1239.91	110.909
1243.13	114.65
1246.34	116.159
1249.56	117.379
1252.78	116.224
1255.99	115.878
1259.2	114.762
1262.42	113.794
1265.63	112.8
1268.84	112.306
1272.04	112.163
1275.25	111.17
1278.46	116.224
1281.66	122.996
1284.86	125.943
1288.07	129.712
1291.27	131.8
1294.47	135.796
1297.66	141.616
1300.86	147.411
1304.06	153.507
1307.25	157.663
1310.44	160.33
1313.64	165.111
1316.83	166.129
1320.02	169.471
1323.2	171.25
1326.39	172.511
1329.58	170.976
1332.76	170.268
1335.95	169.364
1339.13	168.34
1342.31	166.206
1345.49	164.009
1348.67	161.338
1351.85	156.754
1355.02	155.442
1358.2	153.368
1361.37	147.628
1364.54	141.948
1367.71	136.542
1370.88	128.643
1374.05	126.845
1377.22	122.958
1380.39	118.599
1383.55	113.902
1386.72	110.231
1389.88	106.409
1393.04	102.649
1396.2	100.539
1399.36	100.385
1402.52	101.24
1405.68	104.986
1408.83	111.658
1411.98	120.184
1415.14	130.892
1418.29	141.219
1421.44	153.331
1424.59	167.084
1427.74	180.813
1430.89	195.13
1434.03	209.09
1437.18	220.927
1440.32	230.556
1443.46	236.883
1446.6	240.421
1449.74	240.173
1452.88	238.068
1456.02	232.042
1459.16	224.869
1462.29	214.85
1465.43	201.548
1468.56	188.06
1471.69	171.569
1474.82	153.704
1477.95	141.136
1481.08	129.364
1484.2	116.684
1487.33	105.497
1490.46	95.7397
1493.58	88.7934
1496.7	83.4204
1499.82	79.5687
1502.94	75.9445
1506.06	74.9124
1509.18	75.8329
1512.29	76.5134
1515.41	77.0881
1518.52	76.3517
1521.63	78.7105
1524.75	80.4153
1527.85	80.895
1530.96	83.0147
1534.07	83.7252
1537.18	84.1501
1540.28	84.5899
1543.39	85.5941
1546.49	85.3179
1549.59	84.3053
1552.69	86.707
1555.79	88.2951
1558.89	87.3447
1561.99	87.6155
1565.08	89.3985
1568.18	93.6351
1571.27	96.1559
1574.37	102.176
1577.46	107.399
1580.55	113.522
1583.64	119.129
1586.73	124.992
1589.81	129.912
1592.9	134.713
1595.98	139.144
1599.06	142.169
1602.15	142.772
1605.23	142.677
1608.31	142.24
1611.39	140.481
1614.46	141.549
1617.54	140.829
1620.61	140.488
1623.69	140.879
1626.76	139.186
1629.83	138.157
1632.9	139.766
1635.97	142.369
1639.04	143.229
1642.11	148.118
1645.17	150.263
1648.24	153.553
1651.3	155.284
1654.36	156.051
1657.42	156.718
1660.48	155.397
1663.54	152.173
1666.6	147.889
1669.66	143.168
1672.71	135.832
1675.77	125.907
1678.82	117.305
1681.87	109.272
1684.92	100.148
1687.97	91.8271
1691.02	81.5799
1694.07	71.3106
1697.11	61.8289
1700.16	55.1698
1703.2	48.194
1706.25	43.223
1709.29	37.4244
1712.33	30.6063
1715.37	25.4814
1718.41	22.0173
1721.44	18.1014
1724.48	16.2467
1727.51	14.5143
1730.55	14.2793
1733.58	12.3991
1736.61	9.74866
1739.64	6.21812
1742.67	5.54712
1745.7	5.46342
1748.72	4.17006
1751.75	4.60458
1754.77	4.98393
1757.8	4.87986
1760.82	3.6771
1763.84	4.12601
1766.86	2.42816
1769.88	3.76477
1772.9	4.9995
1775.91	5.40348
1778.93	5.75536
1781.94	5.13481
1784.96	5.78229
1787.97	5.52075
1790.98	5.45284
1793.99	6.21206
1797	6.1616
1800.01	6.04752
1803.01	5.09628
1806.02	3.14293
1809.02	2.8544
1812.02	1.33824
1815.02	0.589322
1818.03	0.438829
1821.02	-0.638887
1824.02	-1.65962
1827.02	-1.26501
1830.02	-0.541264
1833.01	-0.130456
1836.01	1.86617
1839	2.33725
1841.99	3.48353
1844.98	5.08924
1847.97	5.97717
1850.96	7.31657
1853.95	8.35884
1856.93	8.98814
1859.92	9.91686
1862.9	9.74389
1865.88	9.36114
1868.87	8.22593
1871.85	7.91394
1874.83	7.7758
1877.81	6.9184
1880.78	6.95938
1882.53	5.97733
1885.52	3.99501
1888.51	3.82321
1891.5	3.7158
1894.48	3.29472
1897.47	5.82551
1900.45	7.01615
1903.43	7.30873
1906.41	9.15559
1909.39	9.30029
1912.37	8.55027
1915.35	10.2746
1918.33	11.3286
1921.3	11.5055
1924.28	12.3079
1927.25	13.0436
1930.22	11.8876
1933.19	11.9321
1936.16	10.0468
1939.13	8.80047
1942.1	8.49092
1945.07	8.14638
1948.03	8.47013
1951	6.79343
1953.96	6.3962
1956.92	6.56867
1959.88	6.63494
1962.84	7.09453
1965.8	6.44611
1968.76	6.58015
1971.72	6.12215
1974.67	5.47298
1977.63	6.02469
1980.58	6.19426
1983.54	6.02208
1986.49	7.87894
1989.44	9.82044
1992.39	10.4958
1995.33	10.521
1998.28	10.9724
2001.23	9.12189
2004.17	8.86172
2007.12	7.56341
2010.06	6.19373
2013	7.14042
2015.94	8.20445
2018.88	8.07092
2021.82	7.29661
2024.76	6.02481
2027.69	4.8072
2030.63	3.91445
2033.56	2.55046
2036.5	2.83548
2039.43	2.41714
2042.36	3.33196
2045.29	2.87531
2048.22	4.25774
2051.15	5.28182
2054.07	5.7539
2057	5.61692
2059.92	7.53672
2062.85	7.12783
2065.77	7.33259
2068.69	6.45641
2071.61	6.17718
2074.53	6.84415
2077.45	8.27524
2080.37	9.25725
2083.28	10.5518
2086.2	10.5845
2089.11	9.61692
2092.02	8.81572
2094.94	7.97329
2097.85	7.87145
2100.76	7.90356
2103.66	9.35952
2106.57	10.007
2109.48	9.26417
2112.38	8.36459
2115.29	8.12309
2118.19	8.61971
2121.09	9.37642
2123.99	8.57255
2126.89	7.84272
2129.79	8.65411
2132.69	7.041
2135.59	5.71652
2138.48	5.46457
2141.38	5.56557
2144.27	7.49414
2147.17	8.38657
2150.06	9.0209
2152.95	10.1455
2155.84	9.66254
2158.73	10.5476
2161.61	11.1786
2164.5	12.7475
2167.38	13.9756
2170.27	14.7934
2173.15	13.5176
2176.03	13.3082
2178.91	12.9322
2181.8	13.2409
2184.67	13.0833
2187.55	13.9141
2190.43	13.3499
2193.3	13.5805
2196.18	12.8422
2199.05	11.2598
2201.93	9.54778
2204.8	9.05856
2207.67	9.47027
2210.54	10.9297
2213.41	12.082
2216.27	11.4122
2219.14	12.566
2222.01	13.7082
2224.87	12.6744
2227.73	12.851
2230.6	13.1252
2233.46	13.022
2236.32	12.1972
2239.18	11.5055
2242.03	10.4232
2244.89	11.2373
2247.75	11.4012
2250.6	11.0865
2253.46	9.59104
2256.31	9.41432
2259.16	9.45628
2262.01	10.4473
2264.86	9.5307
2267.71	9.28476
2270.56	9.95996
2273.4	10.0038
2276.25	10.498
2279.09	11.2322
2281.94	10.5223
2284.78	10.6871
2287.62	10.142
2290.46	8.66463
2293.3	7.54207
2296.14	7.24489
2298.98	7.86826
2301.82	8.65807
2304.65	9.4384
2307.49	10.8671
2310.32	11.8863
2313.15	12.6703
2315.98	12.7879
2318.81	12.3945
2321.64	10.7519
2324.47	9.79196
2327.3	9.77928
2330.12	10.6607
2332.95	10.5041
2335.77	9.70156
2338.6	8.44711
2341.42	7.75363
2344.24	7.94136
2347.06	6.55787
2349.88	5.26226
2352.7	4.76145
2355.51	4.43285
2358.33	3.12042
2361.14	2.56098
2363.96	3.14175
2366.77	4.73565
2369.58	4.91069
2372.39	5.87747
2375.2	6.60808
2378.01	7.56005
2380.82	6.47582
2383.63	5.50339
2386.43	4.638
2389.24	3.31882
2392.04	2.33027
2394.84	1.72126
2397.65	3.39529
2400.45	3.6255
2403.25	3.03656
2406.05	2.81718
2408.84	2.43287
2411.64	2.90155
2414.44	4.07462
2417.23	3.63569
2420.02	4.569
2422.82	3.81671
2425.61	4.51887
2428.4	4.85272
2431.19	5.86658
2433.98	7.26044
2436.77	6.75185
2439.55	6.27691
2442.34	6.47293
2445.12	6.20146
2447.91	5.76773
2450.69	5.07067
2453.47	5.26789
2456.25	5.28786
2459.03	4.5352
2461.81	3.43404
2464.59	3.52494
2467.36	3.71586
2470.14	3.70161
2472.92	4.2001
2475.69	4.98921
2478.46	6.67603
2481.23	6.53187
2484	7.32485
2486.77	7.11885
2489.54	7.92889
2492.31	8.30743
2495.08	9.06291
2497.84	8.59017
2500.61	7.55481
2503.37	6.25362
2506.13	5.29131
2508.9	5.5969
2511.66	6.33272
2514.42	6.42052
2517.18	5.50632
2519.93	5.80562
2522.69	6.5872
2525.45	6.56115
2528.2	6.59118
2530.95	6.42702
2533.71	7.56825
2536.46	8.43386
2539.21	8.64934
2541.96	8.78214
2544.71	9.74003
2547.46	9.77773
2550.2	10.9489
2552.95	10.8333
2555.7	11.3993
2558.44	11.0815
2561.18	10.8929
2563.93	9.52757
2566.67	8.41299
2569.41	8.66523
2572.15	8.25645
2574.88	8.42915
2577.62	8.81971
2580.36	9.82637
2583.09	9.67656
2585.83	11.7114
2588.56	13.0432
2591.29	13.4032
2594.02	12.31
2596.75	13.6516
2599.48	13.418
2602.21	14.1159
2604.94	13.7934
2607.67	13.105
2610.39	13.0017
2613.12	12.515
2615.84	13.4449
2618.56	12.8573
2621.28	12.4392
2624.01	11.7907
2626.72	11.8584
2629.44	11.0693
2632.16	10.1674
2634.88	10.0165
2637.59	11.9268
2640.31	11.5398
2643.02	12.3659
2645.74	12.5857
2648.45	13.1748
2651.16	14.2298
2653.87	14.2901
2656.58	13.0174
2659.29	12.4736
2661.99	13.3006
2664.7	13.9157
2667.41	15.4125
2670.11	14.8486
2672.81	14.1933
2675.51	15.2135
2678.22	14.8702
2680.92	15.0693
2683.62	15.5232
2686.31	16.839
2689.01	16.8433
2691.71	17.2234
2694.4	17.7278
2697.1	18.5196
2699.79	20.6993
2702.49	22.5559
2705.18	23.8398
2707.87	25.0953
2710.56	26.9151
2713.25	27.074
2715.94	28.0769
2718.62	28.0719
2721.31	26.7223
2723.99	24.8177
2726.68	24.2058
2729.36	23.7484
2732.04	23.4603
2734.73	22.1226
2737.41	19.9586
2740.08	18.2051
2742.76	15.6544
2745.44	13.3009
2748.12	12.5282
2750.79	10.7603
2753.47	9.74999
2756.14	7.57038
2758.81	6.10823
2761.49	5.6886
2764.16	5.9565
2766.83	5.67954
2769.5	4.91177
2772.16	5.38231
2774.83	6.01722
2777.5	5.80942
2780.16	4.88286
2782.83	3.58835
2785.49	2.72296
2788.15	1.65901
2790.82	0.508837
2793.48	0.970003
2796.14	0.710412
2798.79	-1.1981
2801.45	-2.82191
2804.11	-3.61677
2806.76	-5.8771
2809.42	-6.74548
2812.07	-6.25175
2814.73	-3.9768
2817.38	-0.796471
2820.03	3.41948
2822.68	8.83188
2825.33	17.0155
2827.98	26.1389
2830.63	35.5984
2833.27	45.5982
2835.92	57.5803
2838.56	70.928
2841.21	86.2833
2843.85	104.94
2846.49	124.072
2849.13	146.845
2851.77	168.535
2854.41	190.078
2857.05	211.022
2859.69	230.637
2862.32	248.352
2864.96	264.084
2867.59	278.904
2870.23	293.49
2872.86	306.552
2875.49	318.014
2878.12	329.427
2880.75	337.941
2883.38	346.608
2886.01	354.367
2888.63	362.653
2891.26	371.814
2893.89	380.716
2896.51	389.365
2899.13	401.345
2901.76	416.506
2904.38	433.546
2907	453.707
2909.62	474.995
2912.24	496.698
2914.85	515.5
2917.47	534.12
2920.09	548.144
2922.7	557.01
2925.32	563.413
2927.93	566.52
2930.54	565.314
2933.15	559.743
2935.76	551.178
2938.37	538.319
2940.98	522.292
2943.59	503.184
2946.2	483.436
2948.8	463.036
2951.41	440.613
2954.01	420.704
2956.62	399.875
2959.22	378.19
2961.82	359.007
2964.42	338.864
2967.02	321.431
2969.62	303.448
2972.22	288.183
2974.81	270.369
2977.41	254.032
2980	235.489
2982.6	216.271
2985.19	195.904
2987.78	176.641
2990.38	157.478
2992.97	139.268
2995.56	120.293
2998.14	102.803
3000.73	87.6896
3003.32	72.2915
3005.91	58.4275
3008.49	47.2351
3011.07	37.1846
3013.66	28.0212
3016.24	21.7524
3018.82	16.5198
3021.4	12.0203
3023.98	6.77286
3026.56	3.35034
3029.14	0.21801
3031.71	-1.78158
3034.29	-2.14791
3036.87	-2.30637
3039.44	-1.87448
3042.01	-0.054867
3044.59	1.69639
3047.16	2.83012
3049.73	4.46815
3052.3	6.33032
3054.87	7.60766
3057.43	8.74675
3060	9.63532
3062.57	9.4684
3065.13	9.83927
3067.7	10.455
3070.26	11.4923
3072.82	11.4339
3075.39	11.6576
3077.95	12.2771
3080.51	11.1175
3083.07	11.2598
3085.63	10.0268
3088.18	9.80906
3090.74	9.33724
3093.29	10.5165
3095.85	12.0884
3098.4	12.3879
3100.95	14.7882
3103.51	16.9352
3106.06	18.522
3108.61	21.7641
3111.16	24.2994
3113.71	28.6734
3116.25	33.0964
3118.8	37.0403
3121.35	40.7176
3123.89	44.5366
3126.44	47.8971
3128.98	53.1645
3131.52	58.7951
3134.06	63.4742
3136.6	67.3974
3139.14	72.4995
3141.68	75.8906
3144.22	79.2686
3146.76	81.3214
3149.29	81.9941