File: data/Raman/poly_smoothed/Mb_00_13_23_1x_45s_532 nm_x100_100%_600 gr_mm_01.txt
#Acq. time (s)=	45
#Accumulations=	2
#Range (cm-¹)=	200...3150
#Windows=	2
#Auto scanning=	Off
#Autofocus=	Off
#Macrospot=	Off
#AutoExposure=	Off
#Spike filter=	Multiple accum.
#Delay time (s)=	0
#Binning=	1
#Readout mode=	Signal
#DeNoise=	Off
#ICS correction=	On
#Dark correction=	Off
#Inst. Process=	Off
#Detector Gain=	Best Dynamic Range
#Detector ADC=	20 kHz
#Detector temperature (°C)=	-69.85
#Instrument=	LabRAM HR Evol
#Detector=	Synapse
#Objective=	x100
#Grating=	600 gr/mm
#ND Filter=	100%
#Laser (nm)=	532
#Hole=	100.021
#Range=	Auto
#Laser Pol.=	No
#Raman. Pol.=	No
#Laser Pol. (°)=	-0.0007625
#Raman Pol. (°)=	89.9995
#Collection=	Microscope
#StageXY=	Marzhauser
#StageZ=	Marzhauser
#X (µm)=	-969
#Y (µm)=	-2845.2
#Z (µm)=	529.15
#Full time(mm:ss)=	3:18
#Project=
#Sample=
#Site=
#Title=	Mb_00_13_23_2x_45s_532 nm_x100_100%_600 gr_mm
#Remark=
#Date=	06.07.2022 11:30
#Acquired=	06.07.2022 11:30:03
#Base:Fit=	10.08.2022 10:16:56
#Base:Sub=	10.08.2022 10:17:24
#Filter:Polynom=	16.08.2022 10:36:38
#AxisType[0]=Intens
#AxisUnit[0]=Cnt
#AxisType[1]=Spectr
#AxisUnit[1]=1/cm
200.398	19.286
204.027	8.3938
207.657	2.65657
211.283	-0.164851
214.909	-0.974904
218.533	2.84505
222.157	12.1271
225.777	20.9146
229.396	31.8564
233.016	43.6388
236.632	53.3874
240.247	63.8514
243.86	71.1559
247.474	77.923
251.085	87.2125
254.694	93.0827
258.301	96.0664
261.908	98.64
265.513	99.2492
269.116	96.1632
272.718	92.586
276.319	87.5965
279.918	81.8582
283.516	76.1637
287.113	68.3207
290.708	59.1523
294.302	52.4064
297.894	46.3121
301.485	42.6547
305.073	40.444
308.661	38.5318
312.247	36.1756
315.833	33.6269
319.415	32.3448
322.997	33.2028
326.579	31.3114
330.156	30.7623
333.735	29.9734
337.31	29.831
340.885	27.6881
344.458	24.0936
348.03	19.7792
351.6	17.4459
355.17	13.673
358.737	10.309
362.304	10.7891
365.868	12.8253
369.431	15.3995
372.994	17.7263
376.554	22.1644
380.112	29.0433
383.669	37.9484
387.225	50.1457
390.781	60.9064
394.334	69.1961
397.885	78.3172
401.436	85.5537
404.984	92.7041
408.532	96.2745
412.078	98.3275
415.623	99.0642
419.166	99.5098
422.708	94.9857
426.248	89.5639
429.788	80.5083
433.326	72.1833
436.86	63.2784
440.395	54.6457
443.929	46.6031
447.461	39.2383
450.99	33.929
454.52	29.0869
458.048	25.0336
461.573	24.0484
465.099	24.2841
468.623	25.9783
472.144	27.1965
475.666	29.2237
479.184	30.9331
482.703	32.7009
486.218	34.6558
489.734	34.6477
493.247	36.1132
496.759	35.967
500.271	37.5625
503.779	39.0847
507.287	40.0026
510.795	40.5597
514.299	40.3451
517.803	39.0043
521.305	40.8987
524.805	40.4283
528.307	40.5246
531.805	40.764
535.301	38.8749
538.797	38.4064
542.291	36.4866
545.783	34.2797
549.275	32.6398
552.765	28.9047
556.253	24.1656
559.738	22.104
563.224	21.2013
566.709	20.3731
570.192	17.8369
573.674	15.7744
577.153	13.35
580.632	12.3143
584.11	11.6237
587.587	10.5705
591.06	8.2224
594.534	7.98585
598.005	7.25129
601.476	8.73226
604.944	9.28989
608.413	9.5884
611.878	9.39021
615.344	10.0645
618.807	9.24203
622.27	8.3834
625.73	8.20891
629.189	9.62743
632.648	12.0269
636.105	12.6743
639.559	13.1988
643.013	15.3766
646.467	16.5092
649.918	17.8817
653.368	17.0708
656.816	17.4743
660.263	15.6888
663.708	16.0027
667.153	15.2205
670.596	13.9057
674.037	12.3756
677.478	12.5747
680.917	12.9495
684.355	11.1718
687.791	11.5697
691.224	9.76537
694.658	8.6955
698.091	6.5785
701.522	7.59966
704.95	6.54886
708.379	6.78074
711.806	7.54544
715.23	8.36485
718.655	8.29099
722.078	10.8674
725.498	11.0479
728.919	11.563
732.337	12.9302
735.755	13.6232
739.17	14.8396
742.584	15.1777
745.998	15.7848
749.409	17.7906
752.819	19.9558
756.23	23.5444
759.637	27.3469
763.043	30.4178
766.448	32.5589
769.853	35.1662
773.255	39.6743
776.656	42.8997
780.056	44.1124
783.454	47.2279
786.851	48.5621
790.247	48.5517
793.641	50.0344
797.034	51.3469
800.426	53.1518
803.817	55.0199
807.206	52.8924
810.592	52.0321
813.979	51.1679
817.364	51.8333
820.748	49.5585
824.129	49.4405
827.511	49.6207
830.891	49.1282
834.269	47.43
837.646	43.8669
841.023	40.0509
844.396	38.4927
847.77	35.5998
851.141	34.62
854.513	34.2723
857.881	31.4395
861.248	28.1622
864.616	25.0892
867.98	23.6136
871.343	21.9617
874.707	21.633
878.068	21.5998
881.428	22.5323
884.786	22.7108
888.143	22.9031
891.498	23.2432
894.855	25.4862
898.208	27.1406
901.56	26.7652
904.91	28.2249
908.26	28.696
911.608	28.7321
914.955	26.9202
918.298	24.638
921.643	25.832
924.986	26.0706
928.328	27.7379
931.668	26.9208
935.006	25.2939
938.344	23.8806
941.681	22.4475
945.014	18.9887
948.349	17.449
951.682	16.7524
955.012	13.7087
958.343	11.0566
961.67	11.0933
964.998	13.0204
968.323	14.8224
971.649	19.138
974.971	27.1424
978.293	35.7498
981.615	45.4475
984.933	53.6322
988.251	60.6446
991.567	66.8751
994.884	72.375
998.198	76.9916
1001.51	81.4552
1004.82	82.0383
1008.13	80.2286
1011.44	79.2075
1014.75	77.1004
1018.06	76.1441
1021.36	78.2253
1024.66	79.1275
1027.97	80.0045
1031.27	80.4687
1034.57	79.0428
1037.87	77.2537
1041.16	75.8346
1044.46	76.8942
1047.76	79.1302
1051.05	80.1083
1054.34	81.9768
1057.63	82.6713
1060.92	79.6577
1064.21	75.7502
1067.5	70.0296
1070.78	63.672
1074.07	56.8941
1077.35	48.8829
1080.63	40.746
1083.91	31.1667
1087.19	21.2552
1090.47	16.0479
1093.75	13.9946
1097.03	14.9672
1100.3	16.3446
1103.57	19.8246
1106.84	18.9787
1110.11	19.2072
1113.38	18.8354
1116.65	15.6866
1119.92	15.5765
1123.19	15.5096
1126.45	17.1618
1129.71	16.9467
1132.97	16.73
1136.23	16.0633
1139.49	16.1144
1142.75	15.0176
1146.01	13.0975
1149.26	11.878
1152.52	11.2524
1155.77	10.5344
1159.02	9.37802
1162.27	8.09986
1165.52	7.5029
1168.77	7.62989
1172.02	10.775
1175.26	12.3192
1178.51	12.5394
1181.75	12.1244
1184.99	11.9675
1188.23	13.0964
1191.47	14.1029
1194.71	16.8789
1197.94	19.4287
1201.18	23.3543
1204.41	28.4937
1207.65	32.9138
1210.88	36.8739
1214.11	42.5905
1217.34	48.016
1220.57	52.4369
1223.79	55.9416
1227.02	59.4532
1230.24	64.9826
1233.47	68.5571
1236.69	70.3573
1239.91	72.1727
1243.13	74.7123
1246.34	76.2949
1249.56	77.6581
1252.78	78.5374
1255.99	75.978
1259.2	74.7517
1262.42	74.3522
1265.63	71.832
1268.84	72.5165
1272.04	71.133
1275.25	70.2928
1278.46	69.7452
1281.66	71.1201
1284.86	72.3605
1288.07	76.2536
1291.27	78.8358
1294.47	82.2904
1297.66	87.0801
1300.86	90.7485
1304.06	93.0683
1307.25	95.0463
1310.44	97.9538
1313.64	98.8161
1316.83	101.221
1320.02	103.236
1323.2	103.408
1326.39	102.108
1329.58	101.262
1332.76	98.4917
1335.95	95.9958
1339.13	94.0974
1342.31	89.9198
1345.49	86.1633
1348.67	83.4532
1351.85	80.2892
1355.02	77.6902
1358.2	75.0509
1361.37	72.2161
1364.54	69.5208
1367.71	66.7149
1370.88	66.1012
1374.05	63.7211
1377.22	63.7968
1380.39	61.473
1383.55	60.7689
1386.72	59.7449
1389.88	59.9273
1393.04	59.9028
1396.2	59.713
1399.36	58.9959
1402.52	61.5153
1405.68	63.1294
1408.83	66.4882
1411.98	71.4169
1415.14	77.8389
1418.29	83.9644
1421.44	90.5013
1424.59	101.722
1427.74	110.581
1430.89	118.75
1434.03	125.037
1437.18	130.729
1440.32	134.774
1443.46	139.299
1446.6	141.123
1449.74	141.518
1452.88	140.425
1456.02	138.002
1459.16	133.288
1462.29	127.753
1465.43	121.072
1468.56	112.044
1471.69	102.592
1474.82	92.3906
1477.95	82.295
1481.08	74.0839
1484.2	66.3913
1487.33	60.5577
1490.46	56.5692
1493.58	51.8319
1496.7	46.7944
1499.82	46.0064
1502.94	44.1919
1506.06	40.6833
1509.18	39.0023
1512.29	36.5364
1515.41	36.9299
1518.52	36.3074
1521.63	37.0952
1524.75	38.2994
1527.85	38.7738
1530.96	39.8349
1534.07	42.7632
1537.18	45.0332
1540.28	47.5899
1543.39	49.6437
1546.49	50.5968
1549.59	52.8228
1552.69	55.091
1555.79	56.512
1558.89	58.4587
1561.99	60.101
1565.08	62.9501
1568.18	64.934
1571.27	65.5109
1574.37	68.1542
1577.46	70.4894
1580.55	71.2432
1583.64	72.8578
1586.73	74.2074
1589.81	77.1448
1592.9	78.7198
1595.98	80.4586
1599.06	79.5486
1602.15	79.5459
1605.23	78.9554
1608.31	80.3436
1611.39	81.0966
1614.46	80.4551
1617.54	80.2268
1620.61	79.3675
1623.69	78.6496
1626.76	76.6316
1629.83	76.1548
1632.9	76.3273
1635.97	75.4978
1639.04	77.9089
1642.11	79.307
1645.17	81.1565
1648.24	82.088
1651.3	85.037
1654.36	85.7981
1657.42	86.9431
1660.48	86.4262
1663.54	84.2083
1666.6	82.6456
1669.66	79.749
1672.71	76.317
1675.77	72.6972
1678.82	67.6007
1681.87	63.6116
1684.92	60.1161
1687.97	55.8388
1691.02	49.7576
1694.07	45.0771
1697.11	40.4097
1700.16	34.95
1703.2	31.8896
1706.25	28.3792
1709.29	24.0865
1712.33	18.6931
1715.37	14.4242
1718.41	14.3298
1721.44	13.6744
1724.48	14.5498
1727.51	15.4784
1730.55	16.8846
1733.58	16.2387
1736.61	15.3471
1739.64	15.308
1742.67	16.0869
1745.7	17.2073
1748.72	16.753
1751.75	17.0275
1754.77	17.6175
1757.8	17.6371
1760.82	17.0953
1763.84	16.2054
1766.86	15.9134
1769.88	15.5138
1772.9	14.7417
1775.91	13.9118
1778.93	11.1277
1781.94	7.2001
1784.96	5.0801
1787.97	2.22321
1790.98	4.72301
1793.99	5.23394
1797	4.97074
1800.01	5.53189
1803.01	6.22786
1806.02	5.03396
1809.02	4.28011
1812.02	3.57678
1815.02	3.20683
1818.03	2.0191
1821.02	1.79245
1824.02	2.15287
1827.02	1.82689
1830.02	1.0122
1833.01	1.99854
1836.01	2.9993
1839	4.2335
1841.99	5.30468
1844.98	6.12379
1847.97	7.31458
1850.96	8.39295
1853.95	9.19523
1856.93	8.93849
1859.92	9.63584
1862.9	10.0365
1865.88	11.3241
1868.87	12.6408
1871.85	13.8779
1874.83	15.131
1877.81	14.105
1880.78	14.7963
1882.53	13.5325
1885.52	14.0618
1888.51	13.6612
1891.5	13.2446
1894.48	13.9218
1897.47	13.9498
1900.45	12.9939
1903.43	11.9552
1906.41	11.1542
1909.39	10.0325
1912.37	8.35021
1915.35	7.68217
1918.33	6.78266
1921.3	6.58068
1924.28	6.20748
1927.25	4.72875
1930.22	5.20489
1933.19	4.11436
1936.16	5.54143
1939.13	5.68377
1942.1	6.07517
1945.07	6.80143
1948.03	7.31158
1951	6.93483
1953.96	7.03714
1956.92	7.0015
1959.88	6.04993
1962.84	6.47275
1965.8	7.92305
1968.76	8.58973
1971.72	8.50991
1974.67	8.31208
1977.63	8.1691
1980.58	8.80714
1983.54	7.33315
1986.49	7.90229
1989.44	7.63425
1992.39	7.66972
1995.33	7.31217
1998.28	8.19863
2001.23	7.80578
2004.17	7.92545
2007.12	7.54577
2010.06	7.81825
2013	6.75427
2015.94	7.50924
2018.88	6.99011
2021.82	5.53796
2024.76	4.65208
2027.69	3.51668
2030.63	4.26868
2033.56	5.84383
2036.5	7.00724
2039.43	8.83393
2042.36	9.18801
2045.29	9.64888
2048.22	10.8139
2051.15	10.6599
2054.07	9.92507
2057	10.5428
2059.92	10.9533
2062.85	12.811
2065.77	13.7975
2068.69	14.1104
2071.61	14.5649
2074.53	12.9596
2077.45	12.3354
2080.37	12.5613
2083.28	11.851
2086.2	11.6675
2089.11	12.4679
2092.02	10.2641
2094.94	10.5516
2097.85	10.5511
2100.76	11.0859
2103.66	10.9702
2106.57	10.4255
2109.48	9.8629
2112.38	8.10507
2115.29	7.52571
2118.19	8.32419
2121.09	7.34394
2123.99	5.83648
2126.89	5.0074
2129.79	4.25453
2132.69	4.10398
2135.59	2.85469
2138.48	3.36408
2141.38	3.31178
2144.27	3.82373
2147.17	3.471
2150.06	4.55416
2152.95	5.34039
2155.84	6.02141
2158.73	7.24088
2161.61	7.44262
2164.5	7.53422
2167.38	7.74391
2170.27	8.18659
2173.15	7.97538
2176.03	8.02193
2178.91	6.77461
2181.8	6.80921
2184.67	7.57753
2187.55	7.32434
2190.43	7.35806
2193.3	5.89515
2196.18	5.99677
2199.05	5.56781
2201.93	5.67272
2204.8	6.70205
2207.67	7.97901
2210.54	9.47679
2213.41	9.26783
2216.27	9.98316
2219.14	9.86482
2222.01	10.2508
2224.87	10.1715
2227.73	10.2673
2230.6	9.76107
2233.46	10.828
2236.32	9.74468
2239.18	10.1744
2242.03	9.28909
2244.89	8.96326
2247.75	8.50201
2250.6	7.82161
2253.46	8.51052
2256.31	7.20057
2259.16	7.0834
2262.01	6.45936
2264.86	5.97658
2267.71	5.97254
2270.56	4.32735
2273.4	4.35116
2276.25	3.50324
2279.09	3.40121
2281.94	3.8376
2284.78	3.02626
2287.62	1.9233
2290.46	1.40562
2293.3	0.576653
2296.14	1.70118
2298.98	3.18287
2301.82	4.41784
2304.65	4.48997
2307.49	4.67718
2310.32	5.86585
2313.15	5.36633
2315.98	6.23774
2318.81	6.87301
2321.64	8.00153
2324.47	8.26511
2327.3	7.63155
2330.12	7.86363
2332.95	6.71467
2335.77	5.493
2338.6	4.63147
2341.42	3.72067
2344.24	3.66219
2347.06	3.91491
2349.88	5.06626
2352.7	4.95277
2355.51	3.08678
2358.33	2.70228
2361.14	2.98728
2363.96	4.0239
2366.77	5.6162
2369.58	5.71187
2372.39	6.50112
2375.2	7.3283
2378.01	9.06805
2380.82	9.39518
2383.63	10.0923
2386.43	10.3043
2389.24	11.0749
2392.04	11.4259
2394.84	11.182
2397.65	10.4646
2400.45	8.80593
2403.25	7.10862
2406.05	6.41041
2408.84	6.91188
2411.64	7.53805
2414.44	7.53104
2417.23	6.89696
2420.02	5.22547
2422.82	5.22053
2425.61	5.20189
2428.4	5.31106
2431.19	5.67619
2433.98	5.18787
2436.77	4.92393
2439.55	5.8145
2442.34	6.37017
2445.12	6.2743
2447.91	5.6297
2450.69	4.90997
2453.47	4.2067
2456.25	4.51707
2459.03	5.34033
2461.81	5.85939
2464.59	4.85839
2467.36	2.92453
2470.14	3.91409
2472.92	4.74968
2475.69	4.67336
2478.46	4.61702
2481.23	3.60335
2484	3.50608
2486.77	3.77018
2489.54	4.44781
2492.31	4.80306
2495.08	3.6762
2497.84	3.44886
2500.61	2.65137
2503.37	1.83981
2506.13	2.23032
2508.9	1.25272
2511.66	-0.207592
2514.42	-0.188488
2517.18	-0.514403
2519.93	-0.930907
2522.69	0.568609
2525.45	1.67893
2528.2	2.06471
2530.95	2.59634
2533.71	2.17462
2536.46	3.2502
2539.21	4.91644
2541.96	6.32713
2544.71	7.42066
2547.46	8.74316
2550.2	9.17903
2552.95	10.3442
2555.7	9.97652
2558.44	10.2604
2561.18	9.62966
2563.93	10.1233
2566.67	9.91389
2569.41	8.57248
2572.15	8.4118
2574.88	7.39565
2577.62	6.85768
2580.36	6.51123
2583.09	7.29556
2585.83	6.81739
2588.56	6.06147
2591.29	6.78647
2594.02	5.01142
2596.75	4.34299
2599.48	3.87756
2602.21	4.22307
2604.94	5.00978
2607.67	5.14595
2610.39	5.89059
2613.12	6.36645
2615.84	6.74006
2618.56	6.76962
2621.28	6.3367
2624.01	5.92246
2626.72	6.594
2629.44	7.76646
2632.16	7.95008
2634.88	8.64631
2637.59	8.21065
2640.31	8.62605
2643.02	9.40475
2645.74	10.4952
2648.45	10.4003
2651.16	10.369
2653.87	9.98908
2656.58	9.79303
2659.29	8.97153
2661.99	9.10585
2664.7	9.41191
2667.41	10.3191
2670.11	10.5953
2672.81	12.2425
2675.51	10.8807
2678.22	12.5452
2680.92	11.5871
2683.62	10.6159
2686.31	10.2974
2689.01	10.0846
2691.71	10.6321
2694.4	12.2416
2697.1	12.1294
2699.79	12.2017
2702.49	12.1816
2705.18	11.3404
2707.87	11.3328
2710.56	11.5817
2713.25	11.7685
2715.94	11.3669
2718.62	12.5532
2721.31	13.5502
2723.99	13.0387
2726.68	12.8966
2729.36	13.1332
2732.04	12.1325
2734.73	11.8113
2737.41	11.8579
2740.08	11.2881
2742.76	10.5896
2745.44	10.7561
2748.12	9.42318
2750.79	10.1545
2753.47	8.83213
2756.14	9.04485
2758.81	8.65195
2761.49	8.57642
2764.16	7.11269
2766.83	5.40727
2769.5	4.33647
2772.16	3.88598
2774.83	3.44099
2777.5	3.11056
2780.16	3.09993
2782.83	3.85744
2785.49	3.97835
2788.15	2.31982
2790.82	2.39336
2793.48	1.95058
2796.14	0.815739
2798.79	0.115777
2801.45	0.34253
2804.11	0.407788
2806.76	0.653175
2809.42	0.573465
2812.07	-0.573716
2814.73	-0.461466
2817.38	1.00285
2820.03	2.76279
2822.68	6.62339
2825.33	10.9585
2827.98	16.1495
2830.63	19.1153
2833.27	23.3049
2835.92	29.1198
2838.56	34.5624
2841.21	42.5348
2843.85	49.6901
2846.49	58.8656
2849.13	68.5826
2851.77	77.7916
2854.41	88.2001
2857.05	97.0578
2859.69	105.66
2862.32	113.768
2864.96	121.35
2867.59	128.587
2870.23	134.904
2872.86	139.67
2875.49	144.088
2878.12	147.674
2880.75	152.738
2883.38	156.867
2886.01	161.803
2888.63	165.65
2891.26	169.707
2893.89	171.026
2896.51	173.168
2899.13	179.007
2901.76	184.726
2904.38	190.668
2907	199.1
2909.62	208.593
2912.24	216.66
2914.85	226.503
2917.47	233.68
2920.09	239.809
2922.7	245.038
2925.32	248.442
2927.93	250.703
2930.54	248.772
2933.15	246.676
2935.76	243.601
2938.37	237.242
2940.98	231.507
2943.59	223.065
2946.2	215.635
2948.8	206.948
2951.41	196.739
2954.01	185.838
2956.62	176.526
2959.22	167.298
2961.82	159.713
2964.42	151.251
2967.02	142.746
2969.62	135.622
2972.22	128.58
2974.81	120.843
2977.41	112.889
2980	105.495
2982.6	95.9004
2985.19	86.7903
2987.78	78.3853
2990.38	69.9577
2992.97	61.3777
2995.56	52.8124
2998.14	45.8862
3000.73	38.9532
3003.32	31.5052
3005.91	26.9758
3008.49	20.9142
3011.07	15.3458
3013.66	10.4822
3016.24	6.96848
3018.82	5.03095
3021.4	4.62105
3023.98	3.68035
3026.56	1.53139
3029.14	0.618641
3031.71	1.58733
3034.29	0.500737
3036.87	0.587586
3039.44	0.0899692
3042.01	1.1413
3044.59	1.13748
3047.16	2.91654
3049.73	3.56448
3052.3	4.52225
3054.87	5.87616
3057.43	5.64844
3060	5.0611
3062.57	5.12127
3065.13	4.24681
3067.7	4.40967
3070.26	4.97709
3072.82	3.75072
3075.39	2.77475
3077.95	3.75944
3080.51	3.58681
3083.07	3.54212
3085.63	2.64266
3088.18	2.1069
3090.74	2.00858
3093.29	3.86512
3095.85	4.90296
3098.4	5.43436
3100.95	6.57073
3103.51	9.02325
3106.06	11.0222
3108.61	12.677
3111.16	15.5647
3113.71	18.5227
3116.25	21.2681
3118.8	23.1343
3121.35	25.1967
3123.89	27.7667
3126.44	30.4348
3128.98	33.349
3131.52	36.4973
3134.06	38.2556
3136.6	39.2861
3139.14	41.1575
3141.68	40.862
3144.22	41.4168
3146.76	41.4309
3149.29	42.0314