File: data/Raman/poly_smoothed/Mb_00_13_15_1x_45s_532 nm_x100_100%_600 gr_mm_01.txt
#Acq. time (s)=	45
#Accumulations=	2
#Range (cm-¹)=	200...3150
#Windows=	2
#Auto scanning=	Off
#Autofocus=	Off
#Macrospot=	Off
#AutoExposure=	Off
#Spike filter=	Multiple accum.
#Delay time (s)=	0
#Binning=	1
#Readout mode=	Signal
#DeNoise=	Off
#ICS correction=	On
#Dark correction=	Off
#Inst. Process=	Off
#Detector Gain=	Best Dynamic Range
#Detector ADC=	20 kHz
#Detector temperature (°C)=	-69.85
#Instrument=	LabRAM HR Evol
#Detector=	Synapse
#Objective=	x100
#Grating=	600 gr/mm
#ND Filter=	100%
#Laser (nm)=	532
#Hole=	100.021
#Range=	Auto
#Laser Pol.=	No
#Raman. Pol.=	No
#Laser Pol. (°)=	-0.0007625
#Raman Pol. (°)=	89.9995
#Collection=	Microscope
#StageXY=	Marzhauser
#StageZ=	Marzhauser
#X (µm)=	-1013.1
#Y (µm)=	-2916.6
#Z (µm)=	528.1
#Full time(mm:ss)=	3:18
#Project=
#Sample=
#Site=
#Title=	Mb_00_13_15_2x_45s_532 nm_x100_100%_600 gr_mm
#Remark=
#Date=	06.07.2022 10:41
#Acquired=	06.07.2022 10:41:01
#Base:Fit=	10.08.2022 10:16:56
#Base:Sub=	10.08.2022 10:17:24
#Filter:Polynom=	16.08.2022 10:36:38
#AxisType[0]=Intens
#AxisUnit[0]=Cnt
#AxisType[1]=Spectr
#AxisUnit[1]=1/cm
200.398	6.55158
204.027	4.16024
207.657	0.620645
211.283	-2.81232
214.909	-2.37841
218.533	1.80208
222.157	7.24032
225.777	14.6586
229.396	23.7949
233.016	35.1418
236.632	41.2454
240.247	47.8367
243.86	54.0379
247.474	59.8072
251.085	63.7981
254.694	67.4018
258.301	70.2041
261.908	71.5833
265.513	73.0179
269.116	70.9436
272.718	66.676
276.319	63.1378
279.918	56.4789
283.516	50.9296
287.113	43.2198
290.708	37.382
294.302	29.9203
297.894	23.3386
301.485	20.7347
305.073	18.2397
308.661	16.5588
312.247	16.0888
315.833	14.3393
319.415	14.9316
322.997	12.9046
326.579	11.318
330.156	11.6401
333.735	8.73087
337.31	8.61352
340.885	6.98536
344.458	5.75261
348.03	3.79634
351.6	2.71993
355.17	-1.08376
358.737	-2.58319
362.304	-1.08877
365.868	0.691989
369.431	3.61046
372.994	6.0378
376.554	10.1153
380.112	15.3699
383.669	22.9251
387.225	31.6951
390.781	40.8108
394.334	51.3221
397.885	59.3962
401.436	65.4582
404.984	69.9822
408.532	74.5028
412.078	76.8461
415.623	76.4847
419.166	75.7267
422.708	74.0478
426.248	70.9638
429.788	65.6275
433.326	57.0643
436.86	49.8846
440.395	41.6732
443.929	33.7662
447.461	26.6027
450.99	20.4121
454.52	14.1288
458.048	10.2402
461.573	6.57901
465.099	7.55059
468.623	10.1489
472.144	12.4221
475.666	16.092
479.184	17.4887
482.703	18.4671
486.218	19.4281
489.734	20.208
493.247	21.9261
496.759	25.0783
500.271	26.9332
503.779	28.9779
507.287	32.9692
510.795	35.3794
514.299	34.637
517.803	35.2939
521.305	36.5238
524.805	37.3642
528.307	37.5277
531.805	36.6828
535.301	36.4695
538.797	37.1179
542.291	36.5686
545.783	36.3543
549.275	34.9169
552.765	33.9181
556.253	30.0929
559.738	28.6779
563.224	22.4078
566.709	18.8741
570.192	15.9482
573.674	12.7112
577.153	9.54437
580.632	7.96694
584.11	4.89188
587.587	1.85994
591.06	0.217409
594.534	-0.149724
598.005	-1.58325
601.476	2.14997
604.944	4.5055
608.413	4.06725
611.878	6.68265
615.344	7.9274
618.807	9.55017
622.27	12.1703
625.73	15.5326
629.189	17.7015
632.648	20.8432
636.105	22.7609
639.559	25.1276
643.013	28.368
646.467	26.2842
649.918	25.9398
653.368	30.3937
656.816	32.8058
660.263	32.9088
663.708	33.6888
667.153	35.8046
670.596	36.3111
674.037	36.8542
677.478	38.2231
680.917	40.277
684.355	40.4696
687.791	40.4098
691.224	37.8056
694.658	38.2434
698.091	37.7696
701.522	37.5313
704.95	37.0681
708.379	37.7359
711.806	36.4804
715.23	35.178
718.655	34.426
722.078	32.5796
725.498	32.7673
728.919	30.8334
732.337	31.2997
735.755	35.6861
739.17	36.9113
742.584	37.3563
745.998	38.5133
749.409	42.1582
752.819	45.2988
756.23	47.166
759.637	49.9238
763.043	52.0262
766.448	55.5868
769.853	57.8467
773.255	61.2813
776.656	64.4189
780.056	66.3002
783.454	67.9012
786.851	70.1783
790.247	71.3466
793.641	72.451
797.034	74.4234
800.426	74.7345
803.817	76.039
807.206	76.9207
810.592	76.1929
813.979	76.8231
817.364	76.0522
820.748	74.2952
824.129	72.6076
827.511	69.6415
830.891	68.7209
834.269	66.3076
837.646	63.5198
841.023	60.3626
844.396	57.5731
847.77	55.6394
851.141	53.4197
854.513	49.3552
857.881	46.0138
861.248	44.2203
864.616	44.3069
867.98	42.1328
871.343	39.8748
874.707	37.1482
878.068	38.1347
881.428	38.4167
884.786	38.1964
888.143	37.568
891.498	36.5904
894.855	37.5591
898.208	36.1492
901.56	37.3424
904.91	37.2483
908.26	35.7367
911.608	35.642
914.955	34.0832
918.298	33.0767
921.643	33.9425
924.986	35.6534
928.328	35.3422
931.668	35.1687
935.006	34.2946
938.344	33.6238
941.681	34.6305
945.014	33.2275
948.349	33.5526
951.682	30.5191
955.012	29.3246
958.343	26.6614
961.67	26.6683
964.998	27.8809
968.323	29.8039
971.649	33.5776
974.971	38.6755
978.293	45.5262
981.615	50.7822
984.933	55.5141
988.251	58.2475
991.567	59.9249
994.884	59.9233
998.198	61.6403
1001.51	63.8768
1004.82	64.3049
1008.13	63.9165
1011.44	61.6653
1014.75	63.541
1018.06	67.9243
1021.36	72.7066
1024.66	77.2327
1027.97	80.9699
1031.27	83.8553
1034.57	84.8857
1037.87	86.6705
1041.16	86.7196
1044.46	89.7843
1047.76	93.3645
1051.05	97.2907
1054.34	97.2787
1057.63	96.2835
1060.92	92.85
1064.21	86.041
1067.5	79.505
1070.78	70.2402
1074.07	59.0589
1077.35	47.1101
1080.63	39.1677
1083.91	28.6524
1087.19	20.5782
1090.47	14.5786
1093.75	10.8796
1097.03	12.2594
1100.3	13.4332
1103.57	13.9862
1106.84	11.543
1110.11	9.48547
1113.38	7.86959
1116.65	7.15266
1119.92	6.47093
1123.19	7.25288
1126.45	9.64811
1129.71	10.8405
1132.97	9.96952
1136.23	9.9011
1139.49	10.6049
1142.75	10.9159
1146.01	10.4848
1149.26	11.9134
1152.52	12.8643
1155.77	11.8672
1159.02	13.6035
1162.27	14.2444
1165.52	15.0417
1168.77	15.677
1172.02	18.0309
1175.26	19.15
1178.51	20.1323
1181.75	19.4767
1184.99	19.8757
1188.23	20.9198
1191.47	22.4399
1194.71	24.8492
1197.94	29.2663
1201.18	33.4963
1204.41	36.7649
1207.65	39.8717
1210.88	43.498
1214.11	46.9104
1217.34	49.2087
1220.57	52.8224
1223.79	58.0919
1227.02	63.1042
1230.24	66.391
1233.47	67.9306
1236.69	70.1596
1239.91	71.3643
1243.13	71.1381
1246.34	72.2262
1249.56	72.649
1252.78	70.0467
1255.99	67.8345
1259.2	67.8012
1262.42	66.9356
1265.63	64.9748
1268.84	63.3275
1272.04	63.4496
1275.25	64.8118
1278.46	65.9074
1281.66	67.0998
1284.86	68.6104
1288.07	72.3574
1291.27	74.8502
1294.47	77.3081
1297.66	81.9222
1300.86	86.7789
1304.06	89.0626
1307.25	93.0805
1310.44	95.7016
1313.64	97.1263
1316.83	100.195
1320.02	103.456
1323.2	104.447
1326.39	104.642
1329.58	104.977
1332.76	104.009
1335.95	104.934
1339.13	103.386
1342.31	99.8371
1345.49	97.6052
1348.67	96.4373
1351.85	96.9514
1355.02	94.2895
1358.2	91.2079
1361.37	89.039
1364.54	87.2309
1367.71	84.8536
1370.88	83.1943
1374.05	79.2337
1377.22	76.5504
1380.39	72.6394
1383.55	69.4748
1386.72	67.5075
1389.88	66.7903
1393.04	66.057
1396.2	63.1041
1399.36	62.1787
1402.52	60.1045
1405.68	60.3769
1408.83	63.2034
1411.98	66.6778
1415.14	71.6719
1418.29	77.6909
1421.44	84.2112
1424.59	91.8843
1427.74	99.7556
1430.89	107.098
1434.03	112.955
1437.18	120.268
1440.32	126.848
1443.46	130.661
1446.6	134.481
1449.74	136.47
1452.88	135.9
1456.02	134.875
1459.16	129.649
1462.29	125.08
1465.43	117.756
1468.56	109.94
1471.69	99.0298
1474.82	87.5948
1477.95	78.3881
1481.08	70.4849
1484.2	62.7311
1487.33	55.7666
1490.46	51.4566
1493.58	46.3013
1496.7	43.0766
1499.82	38.9598
1502.94	37.158
1506.06	37.9323
1509.18	38.2477
1512.29	38.1042
1515.41	39.6496
1518.52	42.8207
1521.63	44.9844
1524.75	44.9126
1527.85	45.3085
1530.96	45.281
1534.07	44.4979
1537.18	44.3704
1540.28	46.0994
1543.39	46.8763
1546.49	45.7718
1549.59	45.2289
1552.69	47.0803
1555.79	49.5535
1558.89	50.8573
1561.99	53.0438
1565.08	55.7658
1568.18	57.4057
1571.27	59.0129
1574.37	61.9171
1577.46	64.4795
1580.55	68.6385
1583.64	72.9796
1586.73	76.4382
1589.81	80.6459
1592.9	84.9371
1595.98	86.2066
1599.06	86.4093
1602.15	85.2475
1605.23	85.4709
1608.31	83.4306
1611.39	83.3917
1614.46	84.263
1617.54	83.4969
1620.61	81.8721
1623.69	83.4381
1626.76	85.782
1629.83	86.0096
1632.9	88.6946
1635.97	89.7241
1639.04	91.8179
1642.11	93.9357
1645.17	95.2501
1648.24	97.2446
1651.3	98.4767
1654.36	101.071
1657.42	103.78
1660.48	102.801
1663.54	101.334
1666.6	98.9436
1669.66	93.6043
1672.71	88.032
1675.77	82.9049
1678.82	76.2272
1681.87	68.5432
1684.92	63.6298
1687.97	57.8774
1691.02	50.538
1694.07	42.3341
1697.11	35.8891
1700.16	31.2878
1703.2	23.9728
1706.25	20.477
1709.29	15.9093
1712.33	12.241
1715.37	8.89399
1718.41	6.5235
1721.44	4.74055
1724.48	3.80757
1727.51	3.76909
1730.55	3.20957
1733.58	2.97958
1736.61	2.55565
1739.64	2.12981
1742.67	1.75471
1745.7	1.58206
1748.72	2.70798
1751.75	3.57306
1754.77	3.07007
1757.8	3.25106
1760.82	3.96881
1763.84	3.52332
1766.86	2.19623
1769.88	1.15068
1772.9	1.90285
1775.91	1.84007
1778.93	1.94311
1781.94	2.10105
1784.96	3.25727
1787.97	3.96396
1790.98	4.46661
1793.99	4.71444
1797	6.31353
1800.01	6.52679
1803.01	6.86468
1806.02	7.42091
1809.02	7.7149
1812.02	8.00316
1815.02	7.5175
1818.03	7.29478
1821.02	6.38249
1824.02	5.68126
1827.02	4.87034
1830.02	4.3863
1833.01	3.52659
1836.01	3.69557
1839	2.52703
1841.99	1.86977
1844.98	2.37269
1847.97	1.79048
1850.96	1.26434
1853.95	0.170948
1856.93	-1.33544
1859.92	0.122604
1862.9	0.380754
1865.88	-0.174377
1868.87	-0.072857
1871.85	1.78098
1874.83	2.89409
1877.81	4.79162
1880.78	5.17226
1882.53	7.29321
1885.52	9.13842
1888.51	9.37554
1891.5	9.18916
1894.48	9.36303
1897.47	10.7039
1900.45	10.9969
1903.43	12.2706
1906.41	12.983
1909.39	13.8225
1912.37	14.8368
1915.35	14.813
1918.33	13.6951
1921.3	13.3799
1924.28	13.8433
1927.25	12.2883
1930.22	10.8294
1933.19	11.0455
1936.16	10.2689
1939.13	8.92354
1942.1	10.6676
1945.07	9.4994
1948.03	9.71791
1951	9.11295
1953.96	8.12909
1956.92	7.12804
1959.88	5.26682
1962.84	4.23854
1965.8	3.16728
1968.76	4.33885
1971.72	3.4263
1974.67	3.05934
1977.63	4.29586
1980.58	3.72071
1983.54	3.94477
1986.49	4.93619
1989.44	4.27152
1992.39	4.1404
1995.33	2.72864
1998.28	0.81576
2001.23	-0.612441
2004.17	1.25095
2007.12	1.86917
2010.06	3.04633
2013	3.67851
2015.94	3.68515
2018.88	4.50769
2021.82	4.77691
2024.76	5.95701
2027.69	6.07968
2030.63	8.09844
2033.56	11.2679
2036.5	13.0201
2039.43	13.6658
2042.36	13.4974
2045.29	12.8013
2048.22	12.7132
2051.15	13.2903
2054.07	13.1091
2057	12.9975
2059.92	13.7777
2062.85	13.7531
2065.77	12.3251
2068.69	11.8179
2071.61	13.7169
2074.53	14.0435
2077.45	14.9037
2080.37	15.0795
2083.28	15.0839
2086.2	13.7353
2089.11	13.7825
2092.02	13.5515
2094.94	13.7949
2097.85	15.0778
2100.76	15.5977
2103.66	16.5569
2106.57	15.4968
2109.48	14.677
2112.38	13.734
2115.29	12.7644
2118.19	12.8526
2121.09	12.2238
2123.99	12.9538
2126.89	13.396
2129.79	14.2845
2132.69	15.4912
2135.59	15.2525
2138.48	15.7346
2141.38	16.3049
2144.27	16.531
2147.17	16.8122
2150.06	15.9581
2152.95	15.5693
2155.84	14.5473
2158.73	15.1689
2161.61	15.8033
2164.5	15.7467
2167.38	15.4901
2170.27	14.9532
2173.15	16.4284
2176.03	17.9859
2178.91	19.2721
2181.8	18.6214
2184.67	18.6151
2187.55	18.8911
2190.43	17.2446
2193.3	17.0556
2196.18	17.3578
2199.05	17.2843
2201.93	18.4845
2204.8	18.4675
2207.67	18.7295
2210.54	18.348
2213.41	17.6669
2216.27	16.7154
2219.14	15.9015
2222.01	15.3307
2224.87	17.6672
2227.73	15.9565
2230.6	15.2119
2233.46	14.8406
2236.32	14.0465
2239.18	14.9067
2242.03	16.4288
2244.89	17.1633
2247.75	17.6311
2250.6	16.2583
2253.46	16.1136
2256.31	16.5167
2259.16	14.655
2262.01	15.0404
2264.86	16.3332
2267.71	15.5062
2270.56	14.7457
2273.4	15.9107
2276.25	14.5181
2279.09	13.9169
2281.94	13.7267
2284.78	12.6559
2287.62	13.0515
2290.46	12.5358
2293.3	11.5291
2296.14	11.8108
2298.98	10.3784
2301.82	11.3805
2304.65	13.9942
2307.49	14.446
2310.32	13.6876
2313.15	12.8678
2315.98	14.7663
2318.81	13.9894
2321.64	14.2087
2324.47	14.1159
2327.3	12.2512
2330.12	13.1894
2332.95	13.2862
2335.77	13.015
2338.6	10.7238
2341.42	12.018
2344.24	10.4038
2347.06	9.33757
2349.88	9.18083
2352.7	7.54779
2355.51	8.35644
2358.33	7.07524
2361.14	5.1964
2363.96	5.40174
2366.77	4.28644
2369.58	4.01404
2372.39	6.09428
2375.2	4.64396
2378.01	3.65367
2380.82	3.3543
2383.63	4.10497
2386.43	4.11747
2389.24	3.63651
2392.04	3.79667
2394.84	3.01404
2397.65	3.60564
2400.45	3.87238
2403.25	4.1158
2406.05	4.05388
2408.84	5.19242
2411.64	5.84731
2414.44	7.07432
2417.23	8.18202
2420.02	9.98709
2422.82	10.7898
2425.61	12.054
2428.4	11.56
2431.19	11.4619
2433.98	13.0575
2436.77	13.4093
2439.55	14.5891
2442.34	13.4491
2445.12	11.1237
2447.91	10.5175
2450.69	9.56916
2453.47	9.89574
2456.25	8.84102
2459.03	6.42574
2461.81	5.40591
2464.59	4.83481
2467.36	4.80441
2470.14	4.70854
2472.92	3.02397
2475.69	2.55188
2478.46	2.07963
2481.23	1.58531
2484	0.925752
2486.77	0.821296
2489.54	1.8618
2492.31	2.63532
2495.08	2.90033
2497.84	3.27817
2500.61	4.28947
2503.37	4.23673
2506.13	4.4356
2508.9	2.14444
2511.66	2.1022
2514.42	3.36542
2517.18	4.51176
2519.93	6.22146
2522.69	7.39496
2525.45	7.89987
2528.2	8.88815
2530.95	9.16003
2533.71	9.30821
2536.46	10.5389
2539.21	9.11126
2541.96	7.40012
2544.71	7.13577
2547.46	6.85641
2550.2	5.48029
2552.95	6.60903
2555.7	7.32492
2558.44	6.54029
2561.18	7.4099
2563.93	7.51032
2566.67	6.82955
2569.41	7.91625
2572.15	8.23905
2574.88	9.69497
2577.62	10.4669
2580.36	12.4661
2583.09	12.7134
2585.83	12.9086
2588.56	14.0089
2591.29	15.392
2594.02	15.7537
2596.75	15.6088
2599.48	15.5987
2602.21	15.6356
2604.94	14.7203
2607.67	12.4809
2610.39	12.0061
2613.12	11.9716
2615.84	10.94
2618.56	10.0605
2621.28	9.22791
2624.01	8.77668
2626.72	7.9107
2629.44	6.32581
2632.16	5.50773
2634.88	5.85229
2637.59	5.78389
2640.31	5.58746
2643.02	6.26383
2645.74	6.59118
2648.45	7.26882
2651.16	7.31623
2653.87	7.76033
2656.58	9.10257
2659.29	9.48549
2661.99	8.85168
2664.7	9.73814
2667.41	10.1819
2670.11	10.4947
2672.81	10.7541
2675.51	10.6637
2678.22	11.1528
2680.92	11.7406
2683.62	10.9165
2686.31	10.9971
2689.01	10.269
2691.71	10.8038
2694.4	10.0245
2697.1	10.0727
2699.79	10.2401
2702.49	9.32451
2705.18	8.57607
2707.87	9.49835
2710.56	9.65124
2713.25	10.2887
2715.94	9.42682
2718.62	8.75088
2721.31	9.39992
2723.99	10.6983
2726.68	11.2034
2729.36	12.6948
2732.04	13.012
2734.73	13.3083
2737.41	14.081
2740.08	13.7796
2742.76	13.6941
2745.44	14.4732
2748.12	14.0748
2750.79	13.2752
2753.47	14.3821
2756.14	14.9341
2758.81	15.0219
2761.49	14.1087
2764.16	13.0097
2766.83	12.4004
2769.5	11.0918
2772.16	10.2659
2774.83	9.72642
2777.5	8.16071
2780.16	7.8355
2782.83	6.28156
2785.49	6.62311
2788.15	6.81146
2790.82	5.63213
2793.48	3.69645
2796.14	1.20186
2798.79	-0.388293
2801.45	-0.845555
2804.11	-1.4854
2806.76	-1.66983
2809.42	-2.50515
2812.07	-3.2804
2814.73	-3.01882
2817.38	-0.0293442
2820.03	2.89182
2822.68	6.52742
2825.33	10.7742
2827.98	16.7212
2830.63	21.0747
2833.27	26.3305
2835.92	32.224
2838.56	39.0197
2841.21	47.6397
2843.85	58.3416
2846.49	69.3727
2849.13	81.708
2851.77	95.0953
2854.41	107.315
2857.05	119.773
2859.69	130.086
2862.32	141.393
2864.96	151.586
2867.59	161.065
2870.23	170.002
2872.86	175.186
2875.49	181.653
2878.12	187.235
2880.75	191.718
2883.38	197.091
2886.01	201.917
2888.63	204.894
2891.26	208.241
2893.89	210.56
2896.51	214.531
2899.13	221.372
2901.76	228.375
2904.38	237.096
2907	247.826
2909.62	261.011
2912.24	273.403
2914.85	284.872
2917.47	297.298
2920.09	305.89
2922.7	313.338
2925.32	319.539
2927.93	322.888
2930.54	323.54
2933.15	322.408
2935.76	319.114
2938.37	313.678
2940.98	305.91
2943.59	296.6
2946.2	286.914
2948.8	276.144
2951.41	263.16
2954.01	249.734
2956.62	237.904
2959.22	225.227
2961.82	213.83
2964.42	202.7
2967.02	190.955
2969.62	180.282
2972.22	169.94
2974.81	159.313
2977.41	148.805
2980	139.003
2982.6	127.2
2985.19	116.735
2987.78	106.709
2990.38	95.981
2992.97	83.672
2995.56	73.933
2998.14	65.4988
3000.73	57.1986
3003.32	49.5511
3005.91	42.283
3008.49	36.3359
3011.07	32.2849
3013.66	27.5027
3016.24	23.5055
3018.82	20.6261
3021.4	16.8386
3023.98	14.3986
3026.56	12.8224
3029.14	11.5399
3031.71	9.81931
3034.29	8.62268
3036.87	8.53474
3039.44	9.51269
3042.01	10.1985
3044.59	11.1144
3047.16	10.9947
3049.73	11.1921
3052.3	10.1154
3054.87	10.1229
3057.43	10.5389
3060	10.9747
3062.57	10.3332
3065.13	9.87767
3067.7	9.20059
3070.26	8.68911
3072.82	7.26394
3075.39	6.34067
3077.95	4.95144
3080.51	2.75863
3083.07	0.77457
3085.63	-0.617754
3088.18	-0.496769
3090.74	-0.573335
3093.29	-1.01362
3095.85	-1.69795
3098.4	-0.337552
3100.95	1.51584
3103.51	2.73337
3106.06	3.39946
3108.61	4.0316
3111.16	4.40962
3113.71	6.46549
3116.25	7.3742
3118.8	8.8327
3121.35	10.3473
3123.89	11.3249
3126.44	13.2668
3128.98	14.9385
3131.52	15.8967
3134.06	18.1936
3136.6	18.7171
3139.14	20.5507
3141.68	22.2063
3144.22	24.8035
3146.76	27.998
3149.29	28.9937