File: data/Raman/poly_smoothed/Mb_00_13_38_1x_45s_532 nm_x100_100%_600 gr_mm_01.txt
#Acq. time (s)=	45
#Accumulations=	2
#Range (cm-¹)=	200...3150
#Windows=	2
#Auto scanning=	Off
#Autofocus=	Off
#Macrospot=	Off
#AutoExposure=	Off
#Spike filter=	Multiple accum.
#Delay time (s)=	0
#Binning=	1
#Readout mode=	Signal
#DeNoise=	Off
#ICS correction=	On
#Dark correction=	Off
#Inst. Process=	Off
#Detector Gain=	Best Dynamic Range
#Detector ADC=	20 kHz
#Detector temperature (°C)=	-69.85
#Instrument=	LabRAM HR Evol
#Detector=	Synapse
#Objective=	x100
#Grating=	600 gr/mm
#ND Filter=	100%
#Laser (nm)=	532
#Hole=	100.021
#Range=	Auto
#Laser Pol.=	No
#Raman. Pol.=	No
#Laser Pol. (°)=	-0.0007625
#Raman Pol. (°)=	89.9995
#Collection=	Microscope
#StageXY=	Marzhauser
#StageZ=	Marzhauser
#X (µm)=	-1023.7
#Y (µm)=	-2882.9
#Z (µm)=	528.75
#Full time(mm:ss)=	3:18
#Project=
#Sample=
#Site=
#Title=	Mb_00_13_38_2x_45s_532 nm_x100_100%_600 gr_mm
#Remark=
#Date=	06.07.2022 12:47
#Acquired=	06.07.2022 12:47:15
#Base:Fit=	10.08.2022 10:16:56
#Base:Sub=	10.08.2022 10:17:24
#Filter:Polynom=	16.08.2022 10:36:38
#AxisType[0]=Intens
#AxisUnit[0]=Cnt
#AxisType[1]=Spectr
#AxisUnit[1]=1/cm
200.398	16.3554
204.027	15.9837
207.657	8.90196
211.283	5.11582
214.909	3.95619
218.533	11.2987
222.157	24.6424
225.777	39.3232
229.396	55.0164
233.016	69.7549
236.632	80.3332
240.247	90.6366
243.86	98.9177
247.474	105.905
251.085	114.117
254.694	119.613
258.301	124.393
261.908	126.701
265.513	126.675
269.116	119.57
272.718	111.308
276.319	103.121
279.918	91.6925
283.516	78.7671
287.113	64.4781
290.708	49.363
294.302	39.4832
297.894	31.1029
301.485	24.1003
305.073	19.0046
308.661	17.4642
312.247	15.8636
315.833	13.8999
319.415	11.9448
322.997	9.17088
326.579	8.12522
330.156	8.83996
333.735	9.20247
337.31	8.36892
340.885	8.03848
344.458	7.36998
348.03	6.06207
351.6	2.99842
355.17	-0.967062
358.737	-2.14116
362.304	0.725264
365.868	2.12305
369.431	6.15744
372.994	12.9548
376.554	17.7086
380.112	26.7781
383.669	38.3939
387.225	51.817
390.781	64.2118
394.334	75.7252
397.885	87.6176
401.436	96.3557
404.984	100.279
408.532	102.558
412.078	104.517
415.623	104.321
419.166	102.118
422.708	94.523
426.248	87.7761
429.788	79.6924
433.326	69.2785
436.86	58.3422
440.395	45.0335
443.929	33.7911
447.461	25.1494
450.99	15.2966
454.52	8.7582
458.048	4.44371
461.573	-0.144284
465.099	-1.36895
468.623	1.27002
472.144	5.36331
475.666	7.95526
479.184	10.3334
482.703	11.2334
486.218	13.8289
489.734	14.6068
493.247	14.2331
496.759	15.474
500.271	19.1384
503.779	21.7432
507.287	23.5954
510.795	27.1735
514.299	30.0812
517.803	32.29
521.305	33.4177
524.805	34.5386
528.307	34.114
531.805	33.3273
535.301	33.755
538.797	35.6296
542.291	34.3206
545.783	32.0053
549.275	28.989
552.765	26.5794
556.253	24.4121
559.738	20.8093
563.224	18.4554
566.709	14.0864
570.192	11.5613
573.674	8.20553
577.153	4.20031
580.632	2.68393
584.11	1.63198
587.587	3.00221
591.06	2.94268
594.534	1.62221
598.005	1.54471
601.476	2.08241
604.944	0.983805
608.413	2.04482
611.878	1.93686
615.344	2.77611
618.807	3.38718
622.27	3.21256
625.73	1.45192
629.189	1.52852
632.648	3.66358
636.105	6.86811
639.559	7.69976
643.013	9.45623
646.467	11.5484
649.918	12.3265
653.368	13.0656
656.816	13.2427
660.263	13.0674
663.708	15.4078
667.153	16.3253
670.596	16.3753
674.037	17.514
677.478	16.9094
680.917	15.479
684.355	14.3093
687.791	13.2095
691.224	12.2205
694.658	10.6765
698.091	10.1895
701.522	9.04241
704.95	6.26097
708.379	7.17726
711.806	8.43883
715.23	9.7585
718.655	11.62
722.078	11.0345
725.498	12.8719
728.919	11.876
732.337	12.0976
735.755	11.8522
739.17	14.2709
742.584	12.9651
745.998	14.0429
749.409	15.7542
752.819	18.5922
756.23	21.5375
759.637	24.8837
763.043	27.0691
766.448	29.9531
769.853	32.5063
773.255	35.486
776.656	37.4736
780.056	41.4832
783.454	42.5157
786.851	45.8989
790.247	47.7574
793.641	51.3504
797.034	53.3022
800.426	53.9815
803.817	52.7701
807.206	52.3083
810.592	52.4736
813.979	52.7023
817.364	53.8192
820.748	54.0967
824.129	53.8869
827.511	50.689
830.891	50.1296
834.269	52.1559
837.646	50.7015
841.023	49.5638
844.396	48.553
847.77	44.3869
851.141	43.5491
854.513	40.1492
857.881	36.9426
861.248	33.5461
864.616	31.1829
867.98	30.4701
871.343	28.0263
874.707	25.105
878.068	22.6311
881.428	19.8541
884.786	14.8848
888.143	11.5543
891.498	10.092
894.855	9.16035
898.208	7.80691
901.56	7.765
904.91	7.73128
908.26	9.0682
911.608	7.9746
914.955	10.4899
918.298	11.1491
921.643	12.8338
924.986	16.0766
928.328	17.1115
931.668	16.8666
935.006	19.3552
938.344	19.2685
941.681	18.9184
945.014	19.7314
948.349	20.8436
951.682	20.1097
955.012	18.8001
958.343	14.8106
961.67	13.5508
964.998	14.3249
968.323	15.4158
971.649	19.8983
974.971	24.2958
978.293	31.4443
981.615	38.3721
984.933	44.0532
988.251	48.8001
991.567	50.7298
994.884	55.1778
998.198	58.8203
1001.51	59.7547
1004.82	59.5086
1008.13	56.5469
1011.44	55.8372
1014.75	55.8167
1018.06	58.9931
1021.36	64.7997
1024.66	71.4877
1027.97	82.7061
1031.27	91.7741
1034.57	97.5715
1037.87	100.946
1041.16	107.543
1044.46	114.936
1047.76	118.955
1051.05	120.334
1054.34	118.82
1057.63	119.322
1060.92	114.917
1064.21	109.054
1067.5	99.7191
1070.78	89.6105
1074.07	76.2882
1077.35	65.4504
1080.63	52.1207
1083.91	35.6519
1087.19	24.0271
1090.47	15.7331
1093.75	13.6659
1097.03	15.0906
1100.3	18.3994
1103.57	21.8551
1106.84	25.6328
1110.11	26.9342
1113.38	26.012
1116.65	24.7656
1119.92	24.2909
1123.19	22.1044
1126.45	19.5735
1129.71	17.5154
1132.97	15.2582
1136.23	15.9733
1139.49	14.4956
1142.75	14.8359
1146.01	12.268
1149.26	9.02527
1152.52	7.47155
1155.77	8.08763
1159.02	6.11552
1162.27	2.23168
1165.52	0.287625
1168.77	2.05683
1172.02	4.56396
1175.26	7.66349
1178.51	9.14454
1181.75	11.0409
1184.99	14.0764
1188.23	15.5568
1191.47	18.4188
1194.71	20.9422
1197.94	25.1071
1201.18	30.6453
1204.41	35.6343
1207.65	43.2089
1210.88	50.0597
1214.11	55.9132
1217.34	62.9063
1220.57	69.5428
1223.79	75.0993
1227.02	76.894
1230.24	80.7334
1233.47	83.8111
1236.69	84.9864
1239.91	84.8963
1243.13	87.8611
1246.34	88.3794
1249.56	87.7952
1252.78	87.6704
1255.99	86.3824
1259.2	86.1194
1262.42	87.8373
1265.63	90.5278
1268.84	93.7546
1272.04	95.9898
1275.25	99.9978
1278.46	104.211
1281.66	107.209
1284.86	114.564
1288.07	121.22
1291.27	125.442
1294.47	129.164
1297.66	134.014
1300.86	137.213
1304.06	140.847
1307.25	141.928
1310.44	146.032
1313.64	148.504
1316.83	147.836
1320.02	147.698
1323.2	147.6
1326.39	142.828
1329.58	140.438
1332.76	138.429
1335.95	139.785
1339.13	139.762
1342.31	139.318
1345.49	138.089
1348.67	134.136
1351.85	131.027
1355.02	128.398
1358.2	127.371
1361.37	126.519
1364.54	121.999
1367.71	116.861
1370.88	111.583
1374.05	106.727
1377.22	103.47
1380.39	98.4901
1383.55	96.3931
1386.72	92.8446
1389.88	92.652
1393.04	87.7871
1396.2	82.64
1399.36	83.3958
1402.52	84.368
1405.68	89.2838
1408.83	98.2883
1411.98	107.562
1415.14	116.975
1418.29	128.158
1421.44	142.824
1424.59	157.774
1427.74	173.529
1430.89	188.809
1434.03	206.114
1437.18	220.085
1440.32	228.008
1443.46	234.581
1446.6	240.928
1449.74	244.01
1452.88	241.47
1456.02	238.097
1459.16	229.542
1462.29	218.566
1465.43	204.038
1468.56	186.211
1471.69	167.652
1474.82	151.487
1477.95	135.894
1481.08	121.749
1484.2	107.832
1487.33	94.7372
1490.46	83.2434
1493.58	74.227
1496.7	67.7172
1499.82	65.1683
1502.94	63.2547
1506.06	61.6502
1509.18	62.711
1512.29	62.4848
1515.41	63.5618
1518.52	66.0434
1521.63	70.0225
1524.75	71.6235
1527.85	73.0585
1530.96	73.9762
1534.07	76.6685
1537.18	76.4028
1540.28	77.6821
1543.39	78.9276
1546.49	81.3109
1549.59	83.6512
1552.69	84.1276
1555.79	86.638
1558.89	85.4074
1561.99	84.5551
1565.08	86.8596
1568.18	87.4915
1571.27	90.0643
1574.37	94.9658
1577.46	99.7619
1580.55	104.6
1583.64	106.44
1586.73	108.904
1589.81	112.638
1592.9	117.769
1595.98	117.886
1599.06	117.728
1602.15	116.216
1605.23	114.613
1608.31	112.814
1611.39	111.436
1614.46	110.13
1617.54	109.087
1620.61	106.32
1623.69	105.76
1626.76	105.327
1629.83	104.698
1632.9	105.741
1635.97	107.805
1639.04	111.039
1642.11	116.507
1645.17	120.052
1648.24	124.657
1651.3	128.741
1654.36	132.254
1657.42	133.31
1660.48	132.458
1663.54	131.365
1666.6	128.901
1669.66	122.284
1672.71	115.521
1675.77	107.902
1678.82	100.544
1681.87	92.908
1684.92	84.8463
1687.97	76.4259
1691.02	66.6019
1694.07	59.0478
1697.11	50.2116
1700.16	44.5763
1703.2	37.8607
1706.25	34.245
1709.29	30.1197
1712.33	26.915
1715.37	22.4003
1718.41	20.2784
1721.44	19.5482
1724.48	18.4467
1727.51	17.6868
1730.55	14.734
1733.58	14.4838
1736.61	13.0478
1739.64	12.0933
1742.67	11.4211
1745.7	10.3505
1748.72	10.0784
1751.75	9.41675
1754.77	8.42133
1757.8	7.90229
1760.82	6.78944
1763.84	6.3246
1766.86	4.91179
1769.88	4.13068
1772.9	1.87243
1775.91	1.70116
1778.93	2.63398
1781.94	2.56292
1784.96	3.16908
1787.97	2.7005
1790.98	2.66305
1793.99	3.99108
1797	3.71417
1800.01	4.0769
1803.01	5.73986
1806.02	6.70898
1809.02	7.50796
1812.02	7.5608
1815.02	8.62032
1818.03	9.39235
1821.02	10.8225
1824.02	10.6021
1827.02	10.7434
1830.02	10.2675
1833.01	9.33727
1836.01	9.19959
1839	9.39074
1841.99	11.0377
1844.98	11.2464
1847.97	11.7128
1850.96	14.3055
1853.95	13.9643
1856.93	13.6197
1859.92	13.1126
1862.9	12.0129
1865.88	11.0344
1868.87	9.47125
1871.85	9.02258
1874.83	9.02229
1877.81	8.37183
1880.78	9.13881
1882.53	8.98044
1885.52	11.5377
1888.51	12.166
1891.5	10.811
1894.48	7.73026
1897.47	6.76683
1900.45	6.96462
1903.43	5.34622
1906.41	6.51283
1909.39	8.49709
1912.37	8.94944
1915.35	7.95422
1918.33	7.3856
1921.3	6.99583
1924.28	6.82412
1927.25	5.56217
1930.22	5.69548
1933.19	5.91861
1936.16	4.05023
1939.13	2.08915
1942.1	1.05005
1945.07	3.31498
1948.03	7.64743
1951	13.0882
1953.96	15.7096
1956.92	17.896
1959.88	20.8063
1962.84	21.4461
1965.8	21.1993
1968.76	22.1019
1971.72	24.7519
1974.67	25.746
1977.63	25.5608
1980.58	26.1786
1983.54	25.846
1986.49	23.2224
1989.44	21.9102
1992.39	21.0729
1995.33	20.5691
1998.28	20.1652
2001.23	19.7525
2004.17	16.7096
2007.12	12.7127
2010.06	10.1867
2013	7.99455
2015.94	9.87951
2018.88	11.6214
2021.82	11.8741
2024.76	11.8125
2027.69	11.3506
2030.63	10.9022
2033.56	10.3322
2036.5	9.74277
2039.43	9.31203
2042.36	8.06845
2045.29	9.55803
2048.22	10.2764
2051.15	11.2019
2054.07	12.9774
2057	11.9658
2059.92	10.3734
2062.85	13.2645
2065.77	14.4129
2068.69	15.6321
2071.61	15.8537
2074.53	13.7427
2077.45	14.3265
2080.37	13.9115
2083.28	16.1263
2086.2	15.1719
2089.11	16.0268
2092.02	16.9781
2094.94	18.052
2097.85	17.9758
2100.76	15.7496
2103.66	15.551
2106.57	15.7481
2109.48	15.1149
2112.38	15.1275
2115.29	14.8193
2118.19	14.7844
2121.09	13.1896
2123.99	13.1576
2126.89	10.9347
2129.79	8.5639
2132.69	7.16599
2135.59	7.64332
2138.48	6.67839
2141.38	6.74402
2144.27	6.5115
2147.17	7.2168
2150.06	8.06062
2152.95	10.3662
2155.84	12.1578
2158.73	12.2952
2161.61	13.3506
2164.5	14.9162
2167.38	17.001
2170.27	17.7017
2173.15	18.7721
2176.03	20.1393
2178.91	22.7664
2181.8	23.2964
2184.67	23.602
2187.55	22.6947
2190.43	22.4244
2193.3	22.6577
2196.18	23.1729
2199.05	20.1666
2201.93	19.1467
2204.8	17.8952
2207.67	16.4337
2210.54	15.7197
2213.41	17.0234
2216.27	15.8781
2219.14	15.7158
2222.01	16.6737
2224.87	16.9072
2227.73	16.6056
2230.6	16.578
2233.46	17.9143
2236.32	19.9832
2239.18	19.1496
2242.03	18.0191
2244.89	19.5702
2247.75	21.5207
2250.6	21.6494
2253.46	21.2216
2256.31	21.0632
2259.16	21.2904
2262.01	20.7717
2264.86	19.8376
2267.71	19.3913
2270.56	19.3213
2273.4	18.4173
2276.25	16.3409
2279.09	16.4975
2281.94	16.0102
2284.78	15.8202
2287.62	14.4408
2290.46	12.2441
2293.3	10.1509
2296.14	10.5613
2298.98	11.7224
2301.82	12.2499
2304.65	13.4203
2307.49	13.0028
2310.32	12.1796
2313.15	12.5267
2315.98	15.339
2318.81	15.5231
2321.64	14.6664
2324.47	14.5383
2327.3	14.8049
2330.12	14.5643
2332.95	14.1422
2335.77	14.0499
2338.6	13.2225
2341.42	11.7634
2344.24	10.4353
2347.06	10.3838
2349.88	9.15006
2352.7	9.41529
2355.51	7.37237
2358.33	6.9895
2361.14	5.60163
2363.96	6.22632
2366.77	7.38314
2369.58	7.2913
2372.39	6.53658
2375.2	5.95292
2378.01	6.00789
2380.82	4.83052
2383.63	7.57985
2386.43	7.74998
2389.24	7.82777
2392.04	8.27405
2394.84	8.26338
2397.65	6.66259
2400.45	5.31774
2403.25	5.3575
2406.05	5.77631
2408.84	6.37762
2411.64	5.85766
2414.44	6.09329
2417.23	5.69521
2420.02	6.53137
2422.82	5.38679
2425.61	5.06452
2428.4	3.4774
2431.19	3.86769
2433.98	3.24576
2436.77	3.1077
2439.55	1.54931
2442.34	0.981432
2445.12	1.49111
2447.91	1.8968
2450.69	2.69605
2453.47	3.47292
2456.25	1.6949
2459.03	2.00155
2461.81	0.595735
2464.59	1.92515
2467.36	1.12242
2470.14	2.48648
2472.92	1.70376
2475.69	0.432185
2478.46	-0.374765
2481.23	-0.281516
2484	0.242515
2486.77	0.949655
2489.54	0.95519
2492.31	1.16282
2495.08	2.02568
2497.84	2.92998
2500.61	3.37088
2503.37	3.07274
2506.13	3.10798
2508.9	2.65646
2511.66	4.23689
2514.42	3.07107
2517.18	3.72898
2519.93	2.86371
2522.69	1.83107
2525.45	2.94751
2528.2	3.46657
2530.95	4.83
2533.71	5.1203
2536.46	4.60025
2539.21	4.0872
2541.96	4.12608
2544.71	4.78568
2547.46	5.18694
2550.2	6.00307
2552.95	7.47634
2555.7	7.70848
2558.44	8.90863
2561.18	9.20207
2563.93	8.74642
2566.67	8.52956
2569.41	8.60506
2572.15	10.2436
2574.88	8.67809
2577.62	9.79817
2580.36	9.9039
2583.09	10.0652
2585.83	9.05456
2588.56	8.25039
2591.29	8.68125
2594.02	9.08868
2596.75	8.99399
2599.48	10.4221
2602.21	10.0872
2604.94	8.74244
2607.67	9.25785
2610.39	8.65602
2613.12	8.37718
2615.84	7.63293
2618.56	8.266
2621.28	7.65044
2624.01	8.00586
2626.72	9.38985
2629.44	8.17693
2632.16	7.85727
2634.88	9.19061
2637.59	9.43657
2640.31	9.33405
2643.02	8.09403
2645.74	7.37426
2648.45	6.41457
2651.16	5.47847
2653.87	5.75512
2656.58	4.94934
2659.29	3.50458
2661.99	2.76885
2664.7	3.48049
2667.41	3.21923
2670.11	2.14638
2672.81	2.30826
2675.51	3.82077
2678.22	4.31313
2680.92	4.15996
2683.62	5.7347
2686.31	8.27598
2689.01	10.3335
2691.71	11.2668
2694.4	11.1724
2697.1	12.3318
2699.79	15.8316
2702.49	19.3272
2705.18	20.7177
2707.87	23.1169
2710.56	24.5755
2713.25	25.7464
2715.94	27.4665
2718.62	27.6492
2721.31	28.4193
2723.99	27.585
2726.68	26.6702
2729.36	26.6754
2732.04	27.284
2734.73	25.83
2737.41	24.4662
2740.08	23.0801
2742.76	21.7063
2745.44	19.1146
2748.12	17.8351
2750.79	16.7437
2753.47	13.3741
2756.14	10.8444
2758.81	10.2326
2761.49	8.6574
2764.16	9.14009
2766.83	7.69068
2769.5	5.70288
2772.16	4.78056
2774.83	4.528
2777.5	3.34267
2780.16	4.13635
2782.83	3.90124
2785.49	2.77713
2788.15	3.50614
2790.82	1.9656
2793.48	2.27344
2796.14	2.37289
2798.79	1.76253
2801.45	-0.412029
2804.11	-2.62143
2806.76	-6.42763
2809.42	-10.0866
2812.07	-10.29
2814.73	-4.24986
2817.38	3.39883
2820.03	16.54
2822.68	32.6755
2825.33	49.7358
2827.98	68.4343
2830.63	90.0921
2833.27	110.892
2835.92	132.359
2838.56	154.755
2841.21	177.825
2843.85	199.943
2846.49	221.789
2849.13	245.947
2851.77	276.123
2854.41	303.832
2857.05	330.548
2859.69	354.879
2862.32	374.924
2864.96	390.409
2867.59	402.095
2870.23	412.84
2872.86	419.836
2875.49	426.527
2878.12	435.329
2880.75	440.58
2883.38	445.123
2886.01	448.21
2888.63	447.949
2891.26	446.749
2893.89	442.843
2896.51	436.892
2899.13	430.944
2901.76	427.142
2904.38	425.277
2907	426.239
2909.62	431.05
2912.24	442.345
2914.85	457.085
2917.47	468.378
2920.09	476.77
2922.7	480.912
2925.32	481.989
2927.93	480.893
2930.54	477.592
2933.15	470.721
2935.76	462.268
2938.37	449.703
2940.98	435.311
2943.59	419.252
2946.2	402.43
2948.8	385.133
2951.41	366.948
2954.01	346.339
2956.62	326.105
2959.22	305.581
2961.82	287.182
2964.42	271.485
2967.02	256.649
2969.62	242.509
2972.22	228.081
2974.81	215.182
2977.41	201.207
2980	186.883
2982.6	170.618
2985.19	152.493
2987.78	134.968
2990.38	121.379
2992.97	105.599
2995.56	92.425
2998.14	80.5702
3000.73	67.9239
3003.32	56.2668
3005.91	46.7411
3008.49	39.6371
3011.07	32.1021
3013.66	26.8854
3016.24	22.2597
3018.82	17.4935
3021.4	13.9405
3023.98	11.6971
3026.56	8.63457
3029.14	7.18741
3031.71	5.71429
3034.29	4.35904
3036.87	4.60728
3039.44	4.01464
3042.01	4.3665
3044.59	4.301
3047.16	4.42601
3049.73	5.02376
3052.3	5.81254
3054.87	7.34711
3057.43	7.57831
3060	8.04928
3062.57	7.78521
3065.13	7.54541
3067.7	7.37512
3070.26	8.63642
3072.82	8.31498
3075.39	7.70472
3077.95	6.9557
3080.51	5.71858
3083.07	4.70989
3085.63	4.00798
3088.18	3.12001
3090.74	3.37609
3093.29	3.77092
3095.85	2.98075
3098.4	4.46762
3100.95	6.3578
3103.51	9.04016
3106.06	10.7802
3108.61	12.9201
3111.16	14.4801
3113.71	16.8963
3116.25	19.4266
3118.8	22.1096
3121.35	24.3893
3123.89	27.7983
3126.44	29.921
3128.98	33.2596
3131.52	35.3687
3134.06	36.7918
3136.6	38.9907
3139.14	41.9564
3141.68	44.8083
3144.22	47.9623
3146.76	51.8863
3149.29	53.8542