File: data/Raman/poly_smoothed/Mb_00_13_16_1x_45s_532 nm_x100_100%_600 gr_mm_01.txt
#Acq. time (s)=	45
#Accumulations=	2
#Range (cm-¹)=	200...3150
#Windows=	2
#Auto scanning=	Off
#Autofocus=	Off
#Macrospot=	Off
#AutoExposure=	Off
#Spike filter=	Multiple accum.
#Delay time (s)=	0
#Binning=	1
#Readout mode=	Signal
#DeNoise=	Off
#ICS correction=	On
#Dark correction=	Off
#Inst. Process=	Off
#Detector Gain=	Best Dynamic Range
#Detector ADC=	20 kHz
#Detector temperature (°C)=	-69.85
#Instrument=	LabRAM HR Evol
#Detector=	Synapse
#Objective=	x100
#Grating=	600 gr/mm
#ND Filter=	100%
#Laser (nm)=	532
#Hole=	100.021
#Range=	Auto
#Laser Pol.=	No
#Raman. Pol.=	No
#Laser Pol. (°)=	-0.0007625
#Raman Pol. (°)=	89.9995
#Collection=	Microscope
#StageXY=	Marzhauser
#StageZ=	Marzhauser
#X (µm)=	-1019.8
#Y (µm)=	-2910.4
#Z (µm)=	528.1
#Full time(mm:ss)=	3:18
#Project=
#Sample=
#Site=
#Title=	Mb_00_13_16_2x_45s_532 nm_x100_100%_600 gr_mm
#Remark=
#Date=	06.07.2022 10:45
#Acquired=	06.07.2022 10:45:35
#Base:Fit=	10.08.2022 10:16:56
#Base:Sub=	10.08.2022 10:17:24
#Filter:Polynom=	16.08.2022 10:36:38
#AxisType[0]=Intens
#AxisUnit[0]=Cnt
#AxisType[1]=Spectr
#AxisUnit[1]=1/cm
200.398	3.5494
204.027	10.9633
207.657	10.3168
211.283	11.3934
214.909	14.3185
218.533	20.8294
222.157	31.3723
225.777	43.1926
229.396	55.8294
233.016	68.1684
236.632	80.0526
240.247	92.4856
243.86	99.1602
247.474	106.29
251.085	110.818
254.694	118.134
258.301	120.705
261.908	120.869
265.513	119.969
269.116	117.47
272.718	112.116
276.319	105.901
279.918	98.5081
283.516	89.9556
287.113	79.0457
290.708	68.5945
294.302	59.22
297.894	53.3809
301.485	49.3514
305.073	44.9175
308.661	42.3275
312.247	38.522
315.833	35.8785
319.415	35.1026
322.997	33.1802
326.579	32.0099
330.156	29.1912
333.735	26.3998
337.31	23.8852
340.885	20.647
344.458	20.0975
348.03	16.4297
351.6	14.3765
355.17	13.1876
358.737	13.7722
362.304	15.4139
365.868	18.6283
369.431	23.7809
372.994	29.4149
376.554	36.6822
380.112	45.2537
383.669	58.2585
387.225	72.0523
390.781	86.1522
394.334	98.3189
397.885	109.121
401.436	117.351
404.984	124.517
408.532	129.517
412.078	131.809
415.623	131.399
419.166	128.692
422.708	123.336
426.248	117.47
429.788	109.156
433.326	97.3957
436.86	85.6504
440.395	74.08
443.929	62.5579
447.461	52.4923
450.99	42.9622
454.52	35.9404
458.048	31.7034
461.573	27.3336
465.099	24.3547
468.623	26.4305
472.144	29.1433
475.666	30.9936
479.184	32.318
482.703	34.2633
486.218	34.1345
489.734	34.9862
493.247	36.4936
496.759	39.905
500.271	40.0468
503.779	41.5034
507.287	42.3353
510.795	43.3481
514.299	44.4439
517.803	44.6243
521.305	47.0291
524.805	48.1265
528.307	47.3182
531.805	47.4523
535.301	49.4863
538.797	48.9925
542.291	47.3901
545.783	46.1647
549.275	41.9537
552.765	40.0283
556.253	38.6589
559.738	36.8944
563.224	34.3523
566.709	31.1737
570.192	28.9956
573.674	24.4526
577.153	22.5316
580.632	19.8372
584.11	16.9231
587.587	14.2799
591.06	14.5438
594.534	13.9571
598.005	12.8669
601.476	12.7364
604.944	11.727
608.413	12.8523
611.878	12.2371
615.344	13.2669
618.807	13.9668
622.27	13.7284
625.73	13.1644
629.189	16.6778
632.648	18.8642
636.105	21.8773
639.559	23.9741
643.013	26.7307
646.467	28.5158
649.918	27.2589
653.368	25.5717
656.816	24.2549
660.263	22.4476
663.708	21.7551
667.153	19.1871
670.596	17.9033
674.037	18.6523
677.478	18.1685
680.917	16.9642
684.355	14.9335
687.791	15.8789
691.224	14.31
694.658	13.7769
698.091	12.0335
701.522	10.6403
704.95	11.5754
708.379	10.6659
711.806	13.145
715.23	16.4708
718.655	16.3734
722.078	17.9474
725.498	20.825
728.919	22.1826
732.337	23.2247
735.755	22.5919
739.17	25.499
742.584	27.4244
745.998	29.2891
749.409	31.629
752.819	33.8518
756.23	36.71
759.637	36.9356
763.043	39.3211
766.448	40.4675
769.853	42.672
773.255	44.0586
776.656	43.3505
780.056	42.7127
783.454	41.4143
786.851	44.2552
790.247	42.7709
793.641	44.0654
797.034	45.2159
800.426	44.4719
803.817	46.0144
807.206	46.8913
810.592	47.4006
813.979	47.2742
817.364	49.5394
820.748	50.2841
824.129	52.0456
827.511	51.8519
830.891	52.9711
834.269	52.3481
837.646	50.9914
841.023	49.2181
844.396	47.4901
847.77	46.3519
851.141	45.9473
854.513	44.7397
857.881	41.6642
861.248	39.4235
864.616	35.3818
867.98	32.7153
871.343	29.7027
874.707	22.572
878.068	22.6199
881.428	17.7729
884.786	15.0904
888.143	14.5311
891.498	13.2322
894.855	12.8769
898.208	12.7571
901.56	14.3155
904.91	13.1382
908.26	12.6738
911.608	15.1825
914.955	18.0311
918.298	19.6028
921.643	20.5771
924.986	23.5392
928.328	26.5677
931.668	27.9228
935.006	28.145
938.344	25.314
941.681	24.3657
945.014	22.6038
948.349	18.5163
951.682	16.5612
955.012	13.0887
958.343	9.76001
961.67	6.24588
964.998	6.73556
968.323	9.88999
971.649	15.6081
974.971	26.4085
978.293	39.5973
981.615	52.9395
984.933	66.9439
988.251	79.3466
991.567	91.9363
994.884	100.225
998.198	108.993
1001.51	113.755
1004.82	114.809
1008.13	115.73
1011.44	111.163
1014.75	109.309
1018.06	110.763
1021.36	113.729
1024.66	118.07
1027.97	121.312
1031.27	123.822
1034.57	123.277
1037.87	120.944
1041.16	120.41
1044.46	121.197
1047.76	120.826
1051.05	123.492
1054.34	125.794
1057.63	126.698
1060.92	123.532
1064.21	115.867
1067.5	109.615
1070.78	99.9971
1074.07	89.1305
1077.35	74.6898
1080.63	61.7074
1083.91	45.5452
1087.19	32.7608
1090.47	23.8168
1093.75	16.2014
1097.03	16.2434
1100.3	18.4111
1103.57	19.4409
1106.84	19.2549
1110.11	22.4358
1113.38	21.4745
1116.65	22.772
1119.92	24.6182
1123.19	24.5345
1126.45	24.9694
1129.71	23.6165
1132.97	23.6999
1136.23	23.4902
1139.49	23.8303
1142.75	24.2783
1146.01	24.5399
1149.26	25.3366
1152.52	25.4463
1155.77	24.2553
1159.02	21.6978
1162.27	19.9783
1165.52	18.7009
1168.77	20.8547
1172.02	19.1779
1175.26	19.3676
1178.51	20.3216
1181.75	21.2209
1184.99	20.8933
1188.23	25.2197
1191.47	28.8055
1194.71	32.4828
1197.94	36.6937
1201.18	39.1984
1204.41	43.656
1207.65	46.7722
1210.88	51.8075
1214.11	56.0105
1217.34	60.335
1220.57	64.5998
1223.79	66.2345
1227.02	68.9909
1230.24	71.4004
1233.47	75.4382
1236.69	79.0651
1239.91	78.9345
1243.13	81.4565
1246.34	82.5649
1249.56	82.2272
1252.78	79.6689
1255.99	78.8548
1259.2	76.5694
1262.42	74.7862
1265.63	75.4694
1268.84	76.664
1272.04	76.3002
1275.25	77.6295
1278.46	80.514
1281.66	81.1617
1284.86	85.6884
1288.07	87.4521
1291.27	90.4699
1294.47	93.0796
1297.66	97.5099
1300.86	100.716
1304.06	106.67
1307.25	111.501
1310.44	116.299
1313.64	120.521
1316.83	121.57
1320.02	121.162
1323.2	121.998
1326.39	121.17
1329.58	119.78
1332.76	119.189
1335.95	117.489
1339.13	116.619
1342.31	115.092
1345.49	113.3
1348.67	110.348
1351.85	109.28
1355.02	107.362
1358.2	103.475
1361.37	101.023
1364.54	97.9537
1367.71	95.5335
1370.88	93.4073
1374.05	90.4431
1377.22	87.8839
1380.39	87.3035
1383.55	86.3191
1386.72	85.0695
1389.88	83.7091
1393.04	82.1973
1396.2	80.0043
1399.36	79.2573
1402.52	83.0443
1405.68	86.4155
1408.83	91.0999
1411.98	97.023
1415.14	103.471
1418.29	111.986
1421.44	120.256
1424.59	128.804
1427.74	137.134
1430.89	146.107
1434.03	152.883
1437.18	160.952
1440.32	166.289
1443.46	169.869
1446.6	169.242
1449.74	168.83
1452.88	167.353
1456.02	164.958
1459.16	158.526
1462.29	149.888
1465.43	138.937
1468.56	129.121
1471.69	118.387
1474.82	107.708
1477.95	100.351
1481.08	91.1019
1484.2	82.5833
1487.33	76.9925
1490.46	72.4823
1493.58	67.9057
1496.7	64.0725
1499.82	62.0798
1502.94	58.9984
1506.06	57.6163
1509.18	57.3933
1512.29	57.6949
1515.41	58.5017
1518.52	58.0185
1521.63	55.7881
1524.75	56.7672
1527.85	57.4051
1530.96	58.484
1534.07	58.1712
1537.18	58.7961
1540.28	56.8998
1543.39	59.137
1546.49	62.4663
1549.59	62.8421
1552.69	66.8369
1555.79	69.5407
1558.89	69.5344
1561.99	74.1728
1565.08	78.2528
1568.18	80.3954
1571.27	83.4437
1574.37	87.2083
1577.46	90.8956
1580.55	94.2331
1583.64	97.4406
1586.73	99.8162
1589.81	102.847
1592.9	104.674
1595.98	103.467
1599.06	104.561
1602.15	104.671
1605.23	104.93
1608.31	103.247
1611.39	102.931
1614.46	101.812
1617.54	101.078
1620.61	100.654
1623.69	102.01
1626.76	102.161
1629.83	103.029
1632.9	100.503
1635.97	102.158
1639.04	104.135
1642.11	106.659
1645.17	106.94
1648.24	107.418
1651.3	108.679
1654.36	109.553
1657.42	108.661
1660.48	105.379
1663.54	104.395
1666.6	101.783
1669.66	97.2364
1672.71	92.7699
1675.77	87.398
1678.82	83.0905
1681.87	77.7449
1684.92	70.9789
1687.97	65.2569
1691.02	57.2175
1694.07	49.8238
1697.11	43.2577
1700.16	38.4802
1703.2	32.8858
1706.25	26.4366
1709.29	21.0242
1712.33	17.4352
1715.37	14.7871
1718.41	11.754
1721.44	9.44088
1724.48	8.29703
1727.51	7.3845
1730.55	7.14082
1733.58	6.68708
1736.61	7.95784
1739.64	9.68373
1742.67	9.41602
1745.7	9.67286
1748.72	11.2391
1751.75	11.3376
1754.77	11.5954
1757.8	10.3869
1760.82	8.30241
1763.84	6.48571
1766.86	6.26283
1769.88	5.41843
1772.9	4.28092
1775.91	4.714
1778.93	3.16884
1781.94	3.63731
1784.96	3.9698
1787.97	4.70004
1790.98	4.60646
1793.99	5.9503
1797	5.10339
1800.01	5.74861
1803.01	6.22952
1806.02	6.39457
1809.02	6.54861
1812.02	6.62809
1815.02	6.27645
1818.03	6.65905
1821.02	6.99004
1824.02	6.74938
1827.02	6.1888
1830.02	5.1242
1833.01	3.88386
1836.01	3.33473
1839	2.71753
1841.99	3.50403
1844.98	3.64783
1847.97	4.9074
1850.96	5.7634
1853.95	7.05665
1856.93	7.69882
1859.92	7.70661
1862.9	7.85376
1865.88	7.59031
1868.87	6.89754
1871.85	6.48319
1874.83	6.91598
1877.81	8.17318
1880.78	8.57535
1882.53	8.23821
1885.52	6.71081
1888.51	7.21801
1891.5	7.56569
1894.48	6.00083
1897.47	3.69562
1900.45	2.37084
1903.43	1.83188
1906.41	1.77625
1909.39	1.64401
1912.37	1.44406
1915.35	2.00445
1918.33	2.15545
1921.3	0.729719
1924.28	0.720244
1927.25	0.357972
1930.22	-0.0419096
1933.19	0.096792
1936.16	0.612135
1939.13	1.1985
1942.1	1.50297
1945.07	1.55747
1948.03	3.15361
1951	3.77451
1953.96	3.28621
1956.92	2.95183
1959.88	3.01573
1962.84	4.09861
1965.8	1.99126
1968.76	0.900911
1971.72	2.16985
1974.67	2.78498
1977.63	2.36359
1980.58	1.23001
1983.54	0.922147
1986.49	0.0881659
1989.44	0.949425
1992.39	1.05934
1995.33	1.61146
1998.28	1.45793
2001.23	2.11825
2004.17	3.42858
2007.12	2.72218
2010.06	4.42407
2013	5.20987
2015.94	6.72319
2018.88	8.07439
2021.82	10.0155
2024.76	10.1086
2027.69	9.89207
2030.63	10.6693
2033.56	11.2862
2036.5	11.4693
2039.43	11.3669
2042.36	11.5886
2045.29	10.7222
2048.22	9.59428
2051.15	8.40285
2054.07	8.78848
2057	8.18507
2059.92	7.76287
2062.85	7.94651
2065.77	7.41073
2068.69	8.63582
2071.61	9.02684
2074.53	8.68092
2077.45	8.58291
2080.37	9.33796
2083.28	10.0795
2086.2	10.9008
2089.11	10.2675
2092.02	11.5862
2094.94	11.1504
2097.85	11.6365
2100.76	11.1178
2103.66	11.5342
2106.57	11.7493
2109.48	10.2507
2112.38	8.38708
2115.29	8.39591
2118.19	7.90451
2121.09	6.11433
2123.99	4.95098
2126.89	4.26064
2129.79	3.90278
2132.69	4.87043
2135.59	5.18521
2138.48	6.84584
2141.38	7.18301
2144.27	7.42357
2147.17	6.97864
2150.06	7.93769
2152.95	9.47006
2155.84	8.97791
2158.73	8.16864
2161.61	9.49216
2164.5	11.4048
2167.38	12.5621
2170.27	12.8106
2173.15	11.7762
2176.03	12.8332
2178.91	11.5526
2181.8	11.167
2184.67	12.1663
2187.55	11.7074
2190.43	9.30916
2193.3	8.81366
2196.18	9.97175
2199.05	9.77225
2201.93	9.36347
2204.8	9.93305
2207.67	9.61146
2210.54	10.2988
2213.41	10.6615
2216.27	11.9949
2219.14	13.3299
2222.01	13.9281
2224.87	13.6663
2227.73	12.5725
2230.6	13.6305
2233.46	15.4093
2236.32	14.9533
2239.18	14.3665
2242.03	14.8415
2244.89	15.1577
2247.75	16.515
2250.6	16.3849
2253.46	15.8186
2256.31	14.8912
2259.16	14.9099
2262.01	14.441
2264.86	15.2154
2267.71	15.5193
2270.56	15.7029
2273.4	15.3448
2276.25	14.7677
2279.09	14.9397
2281.94	16.4722
2284.78	15.775
2287.62	15.7147
2290.46	15.0341
2293.3	13.0342
2296.14	12.7852
2298.98	11.4031
2301.82	12.2431
2304.65	12.0461
2307.49	12.4781
2310.32	13.7641
2313.15	12.858
2315.98	12.4684
2318.81	11.6459
2321.64	9.84857
2324.47	9.7467
2327.3	9.24987
2330.12	10.2863
2332.95	8.07067
2335.77	6.96409
2338.6	5.76314
2341.42	5.88471
2344.24	2.36764
2347.06	2.28475
2349.88	1.75442
2352.7	0.0911027
2355.51	-1.42766
2358.33	-2.3656
2361.14	-2.37367
2363.96	-1.35024
2366.77	-1.39191
2369.58	-0.337302
2372.39	1.46614
2375.2	3.69826
2378.01	4.64286
2380.82	4.8748
2383.63	4.47259
2386.43	5.85207
2389.24	7.1164
2392.04	7.95773
2394.84	9.27136
2397.65	9.48888
2400.45	9.51171
2403.25	8.46578
2406.05	7.52232
2408.84	9.10508
2411.64	8.24756
2414.44	6.65698
2417.23	6.88827
2420.02	5.45213
2422.82	6.14728
2425.61	6.01983
2428.4	4.53796
2431.19	5.35064
2433.98	3.89522
2436.77	3.17143
2439.55	2.61987
2442.34	2.10578
2445.12	2.07056
2447.91	1.25547
2450.69	2.54322
2453.47	3.77445
2456.25	4.60394
2459.03	3.75683
2461.81	4.03137
2464.59	4.26477
2467.36	4.45914
2470.14	4.79641
2472.92	5.63735
2475.69	6.15138
2478.46	7.33432
2481.23	6.44638
2484	8.24362
2486.77	8.86585
2489.54	8.8816
2492.31	8.05242
2495.08	7.68788
2497.84	7.02084
2500.61	5.85157
2503.37	4.94065
2506.13	5.26429
2508.9	4.96032
2511.66	5.65936
2514.42	7.53122
2517.18	7.51717
2519.93	7.50006
2522.69	8.57663
2525.45	9.62612
2528.2	9.60448
2530.95	10.6237
2533.71	11.45
2536.46	12.422
2539.21	13.0455
2541.96	14.2694
2544.71	14.3558
2547.46	13.2571
2550.2	11.8975
2552.95	11.5454
2555.7	10.8314
2558.44	10.2288
2561.18	10.1024
2563.93	11.2804
2566.67	11.491
2569.41	9.98234
2572.15	10.035
2574.88	11.1261
2577.62	10.6124
2580.36	10.0251
2583.09	8.91332
2585.83	8.75893
2588.56	9.01062
2591.29	8.04158
2594.02	7.13412
2596.75	4.57528
2599.48	5.25975
2602.21	6.21867
2604.94	5.05367
2607.67	5.10581
2610.39	4.29888
2613.12	3.39245
2615.84	2.91563
2618.56	2.39616
2621.28	2.97343
2624.01	2.78109
2626.72	3.30811
2629.44	3.33987
2632.16	3.04748
2634.88	3.65414
2637.59	4.16615
2640.31	4.69973
2643.02	5.81417
2645.74	6.274
2648.45	6.8622
2651.16	7.32739
2653.87	7.14316
2656.58	7.20362
2659.29	6.49524
2661.99	7.16085
2664.7	7.56662
2667.41	8.04692
2670.11	8.77528
2672.81	8.48119
2675.51	9.54309
2678.22	9.94697
2680.92	8.78073
2683.62	7.87866
2686.31	7.07639
2689.01	7.86025
2691.71	8.99552
2694.4	8.9568
2697.1	10.5081
2699.79	12.756
2702.49	13.8216
2705.18	14.8805
2707.87	16.9793
2710.56	18.3869
2713.25	18.7064
2715.94	17.9359
2718.62	19.5021
2721.31	21.1173
2723.99	21.6185
2726.68	21.0168
2729.36	20.1766
2732.04	18.8689
2734.73	17.1381
2737.41	15.719
2740.08	14.6725
2742.76	13.1811
2745.44	11.1345
2748.12	10.2185
2750.79	8.52111
2753.47	8.2801
2756.14	7.47232
2758.81	6.45434
2761.49	5.16743
2764.16	4.29644
2766.83	3.95958
2769.5	2.88409
2772.16	1.41643
2774.83	0.862018
2777.5	2.00396
2780.16	1.04488
2782.83	1.82144
2785.49	3.3803
2788.15	3.24187
2790.82	2.52246
2793.48	1.41256
2796.14	0.99599
2798.79	0.982451
2801.45	0.155483
2804.11	-0.85815
2806.76	-1.92494
2809.42	-4.45506
2812.07	-3.05169
2814.73	-1.58663
2817.38	1.84729
2820.03	5.58407
2822.68	11.5422
2825.33	19.5488
2827.98	27.1147
2830.63	36.47
2833.27	45.7055
2835.92	54.7253
2838.56	65.6127
2841.21	77.9798
2843.85	91.7626
2846.49	105.6
2849.13	121.632
2851.77	136.412
2854.41	153.908
2857.05	169.746
2859.69	183.95
2862.32	196.342
2864.96	206.617
2867.59	216.805
2870.23	224.767
2872.86	232.778
2875.49	240.137
2878.12	247.267
2880.75	253.186
2883.38	259.122
2886.01	264.166
2888.63	268.469
2891.26	271.703
2893.89	275.129
2896.51	278.147
2899.13	282.415
2901.76	287.997
2904.38	296.277
2907	305.926
2909.62	316.801
2912.24	329.303
2914.85	341.988
2917.47	355.099
2920.09	363.063
2922.7	369.35
2925.32	373.985
2927.93	374.908
2930.54	373.733
2933.15	372.241
2935.76	366.563
2938.37	358.577
2940.98	348.609
2943.59	337.902
2946.2	324.992
2948.8	310.661
2951.41	296.056
2954.01	281.501
2956.62	266.242
2959.22	251.14
2961.82	236.598
2964.42	223.253
2967.02	210.604
2969.62	200.251
2972.22	189.243
2974.81	178.588
2977.41	168.217
2980	155.849
2982.6	143.78
2985.19	130.962
2987.78	117.921
2990.38	104.819
2992.97	92.417
2995.56	81.8655
2998.14	70.5901
3000.73	60.3649
3003.32	50.9059
3005.91	44.4219
3008.49	36.7569
3011.07	29.6779
3013.66	23.7282
3016.24	17.9769
3018.82	12.9546
3021.4	8.52543
3023.98	7.41567
3026.56	5.35826
3029.14	4.78815
3031.71	5.06891
3034.29	5.49357
3036.87	5.78579
3039.44	7.41134
3042.01	7.76839
3044.59	9.59926
3047.16	11.2835
3049.73	13.6265
3052.3	14.7549
3054.87	16.3993
3057.43	17.1564
3060	17.5882
3062.57	17.747
3065.13	18.7324
3067.7	18.3598
3070.26	19.0584
3072.82	16.9127
3075.39	15.8084
3077.95	15.6764
3080.51	15.7189
3083.07	16.4
3085.63	17.2402
3088.18	18.1202
3090.74	19.5215
3093.29	21.6762
3095.85	23.9189
3098.4	24.7578
3100.95	26.7193
3103.51	30.3114
3106.06	32.8204
3108.61	35.1487
3111.16	38.5176
3113.71	41.1773
3116.25	43.4689
3118.8	46.0235
3121.35	48.478
3123.89	51.9914
3126.44	55.5336
3128.98	58.0471
3131.52	61.4753
3134.06	65.0687
3136.6	68.8515
3139.14	74.3595
3141.68	80.1086
3144.22	85.5329
3146.76	91.4781
3149.29	96.4128