File: data/Raman/poly_smoothed/Mb_00_13_22_1x_45s_532 nm_x100_100%_600 gr_mm_01.txt
#Acq. time (s)=	45
#Accumulations=	2
#Range (cm-¹)=	200...3150
#Windows=	2
#Auto scanning=	Off
#Autofocus=	Off
#Macrospot=	Off
#AutoExposure=	Off
#Spike filter=	Multiple accum.
#Delay time (s)=	0
#Binning=	1
#Readout mode=	Signal
#DeNoise=	Off
#ICS correction=	On
#Dark correction=	Off
#Inst. Process=	Off
#Detector Gain=	Best Dynamic Range
#Detector ADC=	20 kHz
#Detector temperature (°C)=	-69.85
#Instrument=	LabRAM HR Evol
#Detector=	Synapse
#Objective=	x100
#Grating=	600 gr/mm
#ND Filter=	100%
#Laser (nm)=	532
#Hole=	100.021
#Range=	Auto
#Laser Pol.=	No
#Raman. Pol.=	No
#Laser Pol. (°)=	-0.0007625
#Raman Pol. (°)=	89.9995
#Collection=	Microscope
#StageXY=	Marzhauser
#StageZ=	Marzhauser
#X (µm)=	-968.1
#Y (µm)=	-2834.5
#Z (µm)=	528.2
#Full time(mm:ss)=	3:18
#Project=
#Sample=
#Site=
#Title=	Mb_00_13_22_2x_45s_532 nm_x100_100%_600 gr_mm
#Remark=
#Date=	06.07.2022 11:25
#Acquired=	06.07.2022 11:25:02
#Base:Fit=	10.08.2022 10:16:56
#Base:Sub=	10.08.2022 10:17:24
#Filter:Polynom=	16.08.2022 10:36:38
#AxisType[0]=Intens
#AxisUnit[0]=Cnt
#AxisType[1]=Spectr
#AxisUnit[1]=1/cm
200.398	21.241
204.027	16.0264
207.657	7.53319
211.283	3.58827
214.909	7.96207
218.533	21.9402
222.157	44.3049
225.777	66.9485
229.396	92.7149
233.016	113.191
236.632	132.737
240.247	150.959
243.86	162.955
247.474	174.653
251.085	185.133
254.694	191.707
258.301	195.801
261.908	196.344
265.513	190.712
269.116	186.309
272.718	172.677
276.319	157.871
279.918	136.867
283.516	116.35
287.113	95.9239
290.708	75.8036
294.302	62.3248
297.894	52.2206
301.485	44.6124
305.073	38.9609
308.661	34.8984
312.247	33.0694
315.833	31.0742
319.415	29.3131
322.997	27.0045
326.579	26.7771
330.156	25.4067
333.735	20.6279
337.31	17.8415
340.885	13.8754
344.458	11.7313
348.03	9.6516
351.6	5.11732
355.17	2.07428
358.737	0.0833239
362.304	0.0397447
365.868	3.57912
369.431	12.9509
372.994	24.8779
376.554	34.4064
380.112	50.5515
383.669	72.0418
387.225	94.6209
390.781	117.319
394.334	137.513
397.885	156.428
401.436	169.866
404.984	182.313
408.532	188.683
412.078	192.873
415.623	192.767
419.166	188.386
422.708	179.02
426.248	167.419
429.788	154.406
433.326	138.191
436.86	120.242
440.395	99.1933
443.929	82.6942
447.461	68.636
450.99	57.7331
454.52	49.26
458.048	42.1342
461.573	34.997
465.099	34.6518
468.623	40.5267
472.144	47.0878
475.666	49.9125
479.184	54.6952
482.703	58.75
486.218	62.809
489.734	66.0747
493.247	72.1484
496.759	77.4891
500.271	82.3042
503.779	84.7715
507.287	87.9584
510.795	90.3157
514.299	93.0429
517.803	96.0887
521.305	99.2369
524.805	99.7805
528.307	101.249
531.805	100.411
535.301	101.137
538.797	99.2139
542.291	95.0909
545.783	90.5333
549.275	84.4105
552.765	79.4321
556.253	72.4614
559.738	67.7034
563.224	61.623
566.709	56.0332
570.192	50.4391
573.674	44.0214
577.153	37.5867
580.632	36.8147
584.11	32.3018
587.587	27.6531
591.06	24.8253
594.534	26.1587
598.005	23.7415
601.476	25.8355
604.944	27.5531
608.413	29.5655
611.878	32.2032
615.344	32.2387
618.807	32.236
622.27	33.6133
625.73	34.1206
629.189	35.4538
632.648	37.5765
636.105	41.2728
639.559	44.312
643.013	46.9446
646.467	45.8137
649.918	45.3915
653.368	41.6007
656.816	40.2668
660.263	34.3517
663.708	32.7927
667.153	30.1797
670.596	25.1652
674.037	21.9496
677.478	20.3307
680.917	18.8197
684.355	16.0629
687.791	17.8544
691.224	15.0788
694.658	12.4153
698.091	9.02474
701.522	7.61075
704.95	5.21327
708.379	5.05828
711.806	4.40705
715.23	6.84824
718.655	8.11245
722.078	8.13951
725.498	7.95879
728.919	8.53856
732.337	6.87384
735.755	5.30954
739.17	6.35042
742.584	6.31816
745.998	7.91506
749.409	11.2571
752.819	15.7231
756.23	19.1635
759.637	23.7303
763.043	25.9843
766.448	30.2401
769.853	35.2837
773.255	40.2326
776.656	40.9034
780.056	43.2269
783.454	45.0998
786.851	47.0283
790.247	48.2434
793.641	51.9089
797.034	53.6186
800.426	54.8073
803.817	54.583
807.206	54.8352
810.592	55.9979
813.979	56.9539
817.364	55.633
820.748	55.2589
824.129	57.0953
827.511	56.9664
830.891	55.4053
834.269	55.0246
837.646	52.2248
841.023	49.2582
844.396	44.7466
847.77	40.3776
851.141	36.8394
854.513	32.6378
857.881	27.8575
861.248	21.8011
864.616	20.0344
867.98	16.8755
871.343	17.3738
874.707	16.0816
878.068	14.2576
881.428	13.2864
884.786	10.7417
888.143	11.468
891.498	9.8247
894.855	10.1276
898.208	9.5559
901.56	8.17089
904.91	8.61667
908.26	8.54484
911.608	7.28847
914.955	8.28319
918.298	7.88406
921.643	8.22736
924.986	8.65106
928.328	8.13312
931.668	7.89005
935.006	6.58681
938.344	7.53673
941.681	6.77365
945.014	6.88337
948.349	9.91157
951.682	9.5738
955.012	6.76884
958.343	1.21619
961.67	-1.3197
964.998	4.78922
968.323	12.975
971.649	26.6015
974.971	43.4867
978.293	61.9678
981.615	78.5949
984.933	94.9434
988.251	105.928
991.567	117.49
994.884	129.867
998.198	136.83
1001.51	142.082
1004.82	145.623
1008.13	143.201
1011.44	141.103
1014.75	141.122
1018.06	149.085
1021.36	159.498
1024.66	169.298
1027.97	179.087
1031.27	183.919
1034.57	182.618
1037.87	178.048
1041.16	178.496
1044.46	182.613
1047.76	184.964
1051.05	186.755
1054.34	184.184
1057.63	176.867
1060.92	167.254
1064.21	152.98
1067.5	138.911
1070.78	123.365
1074.07	107.616
1077.35	87.3308
1080.63	64.146
1083.91	44.3859
1087.19	26.047
1090.47	14.668
1093.75	15.6119
1097.03	20.0933
1100.3	26.7781
1103.57	31.0957
1106.84	32.7733
1110.11	33.042
1113.38	31.4856
1116.65	27.4469
1119.92	25.6855
1123.19	21.3422
1126.45	19.8748
1129.71	17.8964
1132.97	15.0185
1136.23	14.0351
1139.49	13.6757
1142.75	12.7816
1146.01	12.7844
1149.26	11.0824
1152.52	8.08938
1155.77	6.51777
1159.02	4.57111
1162.27	1.46298
1165.52	0.22025
1168.77	2.37473
1172.02	4.86129
1175.26	7.20291
1178.51	8.48476
1181.75	11.1576
1184.99	13.1996
1188.23	15.0604
1191.47	19.3466
1194.71	26.0343
1197.94	33.7084
1201.18	39.9454
1204.41	50.4531
1207.65	61.9512
1210.88	72.2927
1214.11	87.6012
1217.34	100.317
1220.57	113.442
1223.79	127.192
1227.02	136.987
1230.24	148.329
1233.47	159.454
1236.69	167.339
1239.91	168.479
1243.13	169.727
1246.34	174.253
1249.56	176.223
1252.78	176.142
1255.99	173.562
1259.2	170.889
1262.42	169.223
1265.63	165.627
1268.84	163.932
1272.04	163.322
1275.25	162.252
1278.46	159.075
1281.66	162.081
1284.86	168.389
1288.07	173.773
1291.27	180.335
1294.47	188.452
1297.66	196.355
1300.86	204.683
1304.06	213.347
1307.25	221.084
1310.44	229.224
1313.64	234.494
1316.83	236.957
1320.02	240.615
1323.2	244.786
1326.39	245.115
1329.58	243.474
1332.76	239.696
1335.95	236.721
1339.13	231.047
1342.31	224.718
1345.49	215.008
1348.67	208.312
1351.85	200.134
1355.02	191.597
1358.2	183.235
1361.37	177.132
1364.54	168.593
1367.71	160.303
1370.88	151.44
1374.05	144.175
1377.22	138.125
1380.39	133.518
1383.55	132.13
1386.72	128.26
1389.88	125.77
1393.04	123.75
1396.2	122.852
1399.36	124.896
1402.52	126.544
1405.68	131.041
1408.83	139.111
1411.98	151.482
1415.14	166.63
1418.29	182.912
1421.44	203.364
1424.59	227.966
1427.74	252.945
1430.89	277.865
1434.03	300.759
1437.18	320.086
1440.32	336.023
1443.46	348.568
1446.6	355.52
1449.74	358.824
1452.88	355.697
1456.02	348.363
1459.16	336.156
1462.29	320.558
1465.43	298.245
1468.56	273.289
1471.69	249.732
1474.82	223.841
1477.95	197.306
1481.08	171.291
1484.2	148.617
1487.33	129.551
1490.46	111.266
1493.58	93.9379
1496.7	82.1601
1499.82	74.5388
1502.94	69.5225
1506.06	65.5304
1509.18	62.7271
1512.29	60.163
1515.41	59.4883
1518.52	58.7414
1521.63	61.0794
1524.75	61.1509
1527.85	62.2286
1530.96	64.9678
1534.07	67.1184
1537.18	73.0161
1540.28	79.2744
1543.39	86.1984
1546.49	93.4361
1549.59	100.035
1552.69	106.393
1555.79	111.449
1558.89	115.335
1561.99	121.05
1565.08	123.65
1568.18	127.948
1571.27	134.859
1574.37	141.992
1577.46	148.376
1580.55	155.88
1583.64	165.541
1586.73	171.93
1589.81	174.425
1592.9	177.905
1595.98	180.727
1599.06	181.528
1602.15	177.824
1605.23	175.421
1608.31	173.735
1611.39	173.794
1614.46	173.145
1617.54	173.755
1620.61	177.005
1623.69	177.744
1626.76	178.606
1629.83	180.031
1632.9	184.548
1635.97	189.976
1639.04	194.649
1642.11	202.679
1645.17	210.49
1648.24	219.598
1651.3	224.628
1654.36	230.64
1657.42	236.058
1660.48	235.49
1663.54	232.035
1666.6	226.878
1669.66	220.409
1672.71	208.218
1675.77	193.603
1678.82	177.992
1681.87	163.121
1684.92	149.547
1687.97	132.948
1691.02	119.743
1694.07	105.348
1697.11	93.0933
1700.16	76.3495
1703.2	65.4734
1706.25	56.5374
1709.29	46.6597
1712.33	37.346
1715.37	30.0794
1718.41	25.7356
1721.44	19.6887
1724.48	15.8034
1727.51	12.7321
1730.55	11.7012
1733.58	11.6926
1736.61	10.5144
1739.64	10.6873
1742.67	9.46267
1745.7	9.72855
1748.72	6.66576
1751.75	7.03069
1754.77	8.09154
1757.8	6.98903
1760.82	7.7096
1763.84	7.25926
1766.86	6.67159
1769.88	6.4221
1772.9	5.52045
1775.91	4.24148
1778.93	3.71936
1781.94	2.21239
1784.96	0.987194
1787.97	1.02242
1790.98	0.681031
1793.99	-0.937468
1797	-2.56859
1800.01	-1.80492
1803.01	-0.854957
1806.02	-0.931187
1809.02	-1.43491
1812.02	0.134759
1815.02	0.296176
1818.03	1.6367
1821.02	2.64294
1824.02	4.37865
1827.02	5.522
1830.02	5.96072
1833.01	6.48655
1836.01	6.07069
1839	6.7093
1841.99	8.08185
1844.98	6.7196
1847.97	6.2558
1850.96	6.72996
1853.95	5.23297
1856.93	4.42254
1859.92	6.25941
1862.9	4.74344
1865.88	4.93156
1868.87	3.71621
1871.85	3.54359
1874.83	6.00763
1877.81	5.18941
1880.78	4.48575
1882.53	5.39486
1885.52	6.5499
1888.51	8.69357
1891.5	9.16213
1894.48	8.90754
1897.47	10.323
1900.45	10.0854
1903.43	11.2504
1906.41	10.9524
1909.39	11.0449
1912.37	12.5431
1915.35	12.3854
1918.33	13.2168
1921.3	14.9567
1924.28	14.5554
1927.25	13.74
1930.22	15.0402
1933.19	15.9953
1936.16	15.3765
1939.13	14.4607
1942.1	14.3348
1945.07	13.4181
1948.03	12.7529
1951	11.7703
1953.96	9.84193
1956.92	7.9845
1959.88	6.6434
1962.84	5.42265
1965.8	4.79144
1968.76	4.08508
1971.72	3.19088
1974.67	3.72803
1977.63	4.21154
1980.58	5.36485
1983.54	5.21786
1986.49	4.46487
1989.44	5.13278
1992.39	7.32026
1995.33	6.63231
1998.28	7.1247
2001.23	8.16717
2004.17	8.27209
2007.12	9.7547
2010.06	9.50513
2013	9.99017
2015.94	9.63929
2018.88	10.1069
2021.82	11.5255
2024.76	11.762
2027.69	11.6717
2030.63	12.1084
2033.56	11.1979
2036.5	12.7909
2039.43	12.2663
2042.36	12.8343
2045.29	13.9873
2048.22	13.034
2051.15	13.6381
2054.07	12.2903
2057	10.5359
2059.92	12.7517
2062.85	13.7491
2065.77	14.2461
2068.69	14.3618
2071.61	15.4867
2074.53	15.0703
2077.45	15.4054
2080.37	15.1148
2083.28	13.7064
2086.2	15.59
2089.11	15.9417
2092.02	17.1386
2094.94	19.0792
2097.85	18.3654
2100.76	16.9614
2103.66	16.2157
2106.57	15.1144
2109.48	15.7346
2112.38	16.0059
2115.29	14.8878
2118.19	13.0165
2121.09	11.1243
2123.99	10.4025
2126.89	8.6334
2129.79	8.19563
2132.69	9.01434
2135.59	7.88469
2138.48	6.32101
2141.38	6.12041
2144.27	5.46083
2147.17	4.263
2150.06	3.67709
2152.95	4.45419
2155.84	5.704
2158.73	6.60604
2161.61	7.51227
2164.5	8.88176
2167.38	9.29702
2170.27	11.1476
2173.15	12.8632
2176.03	13.0886
2178.91	14.0578
2181.8	15.2644
2184.67	13.8368
2187.55	13.254
2190.43	13.375
2193.3	13.4449
2196.18	15.532
2199.05	15.9744
2201.93	17.0003
2204.8	18.4005
2207.67	17.3772
2210.54	17.2974
2213.41	17.4855
2216.27	16.7068
2219.14	17.1142
2222.01	16.5629
2224.87	16.7409
2227.73	16.7957
2230.6	17.2654
2233.46	19.5983
2236.32	20.299
2239.18	21.0228
2242.03	21.2131
2244.89	19.4367
2247.75	17.3585
2250.6	17.6129
2253.46	16.4336
2256.31	16.6861
2259.16	16.536
2262.01	15.9314
2264.86	15.3811
2267.71	14.2883
2270.56	12.9979
2273.4	12.1392
2276.25	11.0085
2279.09	7.83632
2281.94	6.56134
2284.78	4.68809
2287.62	4.28139
2290.46	3.749
2293.3	2.24717
2296.14	4.71924
2298.98	7.33635
2301.82	8.95577
2304.65	10.5632
2307.49	12.5787
2310.32	12.419
2313.15	13.0917
2315.98	12.8313
2318.81	14.294
2321.64	14.1895
2324.47	15.5398
2327.3	14.4577
2330.12	12.4392
2332.95	12.2587
2335.77	11.1622
2338.6	8.53984
2341.42	7.34858
2344.24	4.47071
2347.06	1.67881
2349.88	-0.797295
2352.7	-3.14587
2355.51	-2.15136
2358.33	-2.06606
2361.14	-1.36919
2363.96	1.18746
2366.77	2.07469
2369.58	2.5989
2372.39	3.17435
2375.2	4.52603
2378.01	6.33311
2380.82	6.38694
2383.63	9.17943
2386.43	10.5534
2389.24	10.3167
2392.04	11.4767
2394.84	12.1067
2397.65	11.7169
2400.45	9.90839
2403.25	10.5046
2406.05	7.94009
2408.84	5.41678
2411.64	3.42132
2414.44	3.11285
2417.23	2.42461
2420.02	2.05243
2422.82	3.04826
2425.61	4.21505
2428.4	2.89879
2431.19	2.80243
2433.98	3.85233
2436.77	4.78186
2439.55	5.04012
2442.34	5.91007
2445.12	6.53892
2447.91	6.38584
2450.69	7.92298
2453.47	8.66312
2456.25	9.49177
2459.03	8.56661
2461.81	8.57693
2464.59	8.06754
2467.36	7.48067
2470.14	6.14739
2472.92	6.54977
2475.69	4.9612
2478.46	4.94659
2481.23	6.43803
2484	5.79088
2486.77	5.78175
2489.54	6.40505
2492.31	6.19818
2495.08	6.46568
2497.84	7.79232
2500.61	8.16278
2503.37	8.94515
2506.13	8.62155
2508.9	8.66043
2511.66	9.33269
2514.42	8.46939
2517.18	8.08047
2519.93	9.21433
2522.69	9.26185
2525.45	8.68076
2528.2	8.28998
2530.95	8.07531
2533.71	8.78799
2536.46	8.56967
2539.21	9.38
2541.96	10.8803
2544.71	11.9391
2547.46	12.7708
2550.2	13.3993
2552.95	13.5963
2555.7	15.9985
2558.44	17.2624
2561.18	18.7971
2563.93	20.305
2566.67	20.4521
2569.41	20.9232
2572.15	21.3606
2574.88	20.3213
2577.62	21.1697
2580.36	19.6379
2583.09	18.8835
2585.83	18.085
2588.56	18.2723
2591.29	18.4157
2594.02	19.9561
2596.75	19.5899
2599.48	20.3452
2602.21	19.739
2604.94	18.7976
2607.67	19.4124
2610.39	17.2434
2613.12	17.3717
2615.84	17.0898
2618.56	17.2012
2621.28	17.8119
2624.01	18.7847
2626.72	17.8856
2629.44	18.4745
2632.16	18.5554
2634.88	20.0473
2637.59	21.4292
2640.31	22.0484
2643.02	21.0995
2645.74	22.5467
2648.45	21.3771
2651.16	22.5399
2653.87	22.5682
2656.58	24.1726
2659.29	25.5252
2661.99	25.6381
2664.7	24.3687
2667.41	24.2942
2670.11	24.3647
2672.81	24.009
2675.51	22.7598
2678.22	22.259
2680.92	24.8136
2683.62	24.794
2686.31	24.9561
2689.01	25.8555
2691.71	25.5681
2694.4	28.4742
2697.1	30.0361
2699.79	31.4947
2702.49	32.4958
2705.18	33.8519
2707.87	35.5797
2710.56	36.4445
2713.25	39.6709
2715.94	42.0726
2718.62	44.1227
2721.31	45.9331
2723.99	47.1816
2726.68	48.443
2729.36	47.922
2732.04	46.8855
2734.73	46.1559
2737.41	44.1715
2740.08	42.6412
2742.76	40.3953
2745.44	40.0752
2748.12	38.6818
2750.79	36.599
2753.47	33.3767
2756.14	29.9148
2758.81	27.1614
2761.49	23.9378
2764.16	20.2194
2766.83	16.083
2769.5	14.5154
2772.16	12.3931
2774.83	10.5595
2777.5	8.90697
2780.16	8.58736
2782.83	6.93319
2785.49	5.34213
2788.15	4.5901
2790.82	3.13833
2793.48	3.51876
2796.14	1.83758
2798.79	0.118665
2801.45	-1.1491
2804.11	-1.34176
2806.76	-1.43566
2809.42	-2.07801
2812.07	-0.456213
2814.73	3.43901
2817.38	9.57232
2820.03	20.5006
2822.68	33.3981
2825.33	48.2132
2827.98	65.1794
2830.63	84.9741
2833.27	106.326
2835.92	130.96
2838.56	157.296
2841.21	188.073
2843.85	222.396
2846.49	261.361
2849.13	301.773
2851.77	343.873
2854.41	385.769
2857.05	427.452
2859.69	466.948
2862.32	500.355
2864.96	531.252
2867.59	560.477
2870.23	585.19
2872.86	608.284
2875.49	625.714
2878.12	644.909
2880.75	660.903
2883.38	677.208
2886.01	689.725
2888.63	700.424
2891.26	712.159
2893.89	724.653
2896.51	738.602
2899.13	754.031
2901.76	776.165
2904.38	803.254
2907	835.666
2909.62	873.611
2912.24	912.258
2914.85	949.082
2917.47	983.82
2920.09	1011.95
2922.7	1035.16
2925.32	1049.61
2927.93	1057.28
2930.54	1058.55
2933.15	1052.47
2935.76	1037.34
2938.37	1016.55
2940.98	988.968
2943.59	959.08
2946.2	922.62
2948.8	881.877
2951.41	838.732
2954.01	796.639
2956.62	753.282
2959.22	710.399
2961.82	669.096
2964.42	632.287
2967.02	599.308
2969.62	566.608
2972.22	537.683
2974.81	505.153
2977.41	474.369
2980	442.801
2982.6	407.395
2985.19	373.797
2987.78	339.247
2990.38	305.769
2992.97	272.41
2995.56	240.686
2998.14	209.529
3000.73	180.707
3003.32	153.378
3005.91	127.108
3008.49	103.097
3011.07	81.3638
3013.66	62.5562
3016.24	48.1238
3018.82	33.7091
3021.4	23.353
3023.98	14.2657
3026.56	7.60572
3029.14	3.19076
3031.71	-1.54339
3034.29	-3.18552
3036.87	-1.73987
3039.44	1.30864
3042.01	5.64521
3044.59	9.02777
3047.16	13.285
3049.73	17.4432
3052.3	21.157
3054.87	25.6346
3057.43	28.253
3060	29.3837
3062.57	30.3869
3065.13	30.6822
3067.7	29.6636
3070.26	27.6718
3072.82	26.1087
3075.39	23.1458
3077.95	19.6038
3080.51	15.8695
3083.07	10.8338
3085.63	5.80047
3088.18	2.82184
3090.74	-0.167011
3093.29	-0.126245
3095.85	1.79104
3098.4	4.34167
3100.95	6.63674
3103.51	10.6666
3106.06	14.5358
3108.61	18.4788
3111.16	23.9721
3113.71	29.4835
3116.25	36.7108
3118.8	42.3493
3121.35	49.0066
3123.89	56.0262
3126.44	62.4948
3128.98	69.5306
3131.52	75.8178
3134.06	81.9016
3136.6	88.5203
3139.14	93.4165
3141.68	99.1189
3144.22	105.194
3146.76	113.029
3149.29	118.964