File: data/Raman/poly_smoothed/Mb_00_13_45_1x_45s_532 nm_x100_100%_600 gr_mm_01.txt
#Acq. time (s)=	45
#Accumulations=	2
#Range (cm-¹)=	200...3150
#Windows=	2
#Auto scanning=	Off
#Autofocus=	Off
#Macrospot=	Off
#AutoExposure=	Off
#Spike filter=	Multiple accum.
#Delay time (s)=	0
#Binning=	1
#Readout mode=	Signal
#DeNoise=	Off
#ICS correction=	On
#Dark correction=	Off
#Inst. Process=	Off
#Detector Gain=	Best Dynamic Range
#Detector ADC=	20 kHz
#Detector temperature (°C)=	-69.85
#Instrument=	LabRAM HR Evol
#Detector=	Synapse
#Objective=	x100
#Grating=	600 gr/mm
#ND Filter=	100%
#Laser (nm)=	532
#Hole=	100.021
#Range=	Auto
#Laser Pol.=	No
#Raman. Pol.=	No
#Laser Pol. (°)=	-0.0007625
#Raman Pol. (°)=	89.9995
#Collection=	Microscope
#StageXY=	Marzhauser
#StageZ=	Marzhauser
#X (µm)=	-1055.8
#Y (µm)=	-2896.6
#Z (µm)=	528.4
#Full time(mm:ss)=	3:18
#Project=
#Sample=
#Site=
#Title=	Mb_00_13_45_2x_45s_532 nm_x100_100%_600 gr_mm
#Remark=
#Date=	06.07.2022 13:18
#Acquired=	06.07.2022 13:18:09
#Base:Fit=	10.08.2022 10:16:56
#Base:Sub=	10.08.2022 10:17:24
#Filter:Polynom=	16.08.2022 10:36:38
#AxisType[0]=Intens
#AxisUnit[0]=Cnt
#AxisType[1]=Spectr
#AxisUnit[1]=1/cm
200.398	33.1303
204.027	18.1549
207.657	0.467069
211.283	-16.4958
214.909	-18.7298
218.533	-6.25194
222.157	15.7943
225.777	41.298
229.396	73.8689
233.016	104.817
236.632	131.567
240.247	158.214
243.86	178.947
247.474	197.425
251.085	218.468
254.694	234.796
258.301	245.175
261.908	250.682
265.513	250.461
269.116	245.212
272.718	233.742
276.319	215.653
279.918	194.234
283.516	169.179
287.113	141.742
290.708	111.55
294.302	84.1661
297.894	65.918
301.485	54.4786
305.073	43.6835
308.661	37.2649
312.247	30.8604
315.833	26.5343
319.415	23.6014
322.997	21.5017
326.579	20.7834
330.156	19.4147
333.735	16.7871
337.31	13.7859
340.885	12.5089
344.458	10.8268
348.03	9.42647
351.6	7.56336
355.17	5.71276
358.737	6.35768
362.304	9.76431
365.868	17.9836
369.431	29.7942
372.994	43.0412
376.554	54.8218
380.112	70.0205
383.669	94.5441
387.225	121.277
390.781	151.275
394.334	179.224
397.885	203.004
401.436	221.354
404.984	234.639
408.532	244.082
412.078	249.32
415.623	248.4
419.166	244.479
422.708	232.884
426.248	218.076
429.788	200.222
433.326	178.039
436.86	155.807
440.395	129.149
443.929	105.448
447.461	84.4044
450.99	64.3431
454.52	47.8695
458.048	32.3974
461.573	18.1198
465.099	12.1161
468.623	13.1972
472.144	18.4414
475.666	22.5098
479.184	28.0322
482.703	32.0422
486.218	35.6099
489.734	39.7459
493.247	46.699
496.759	54.0037
500.271	62.3134
503.779	70.2561
507.287	74.4976
510.795	80.7706
514.299	87.5979
517.803	91.2318
521.305	95.0664
524.805	96.3222
528.307	96.4502
531.805	96.7291
535.301	96.5834
538.797	95.989
542.291	92.5337
545.783	88.1949
549.275	82.1983
552.765	78.4546
556.253	70.9193
559.738	65.3504
563.224	61.5825
566.709	55.0738
570.192	49.2215
573.674	46.0575
577.153	43.2751
580.632	39.6611
584.11	36.6681
587.587	33.866
591.06	31.3893
594.534	29.0599
598.005	28.4771
601.476	28.4314
604.944	27.3042
608.413	29.3441
611.878	31.0884
615.344	31.6251
618.807	33.3436
622.27	35.9242
625.73	38.543
629.189	40.9778
632.648	45.6578
636.105	52.4286
639.559	57.6343
643.013	62.632
646.467	66.7203
649.918	67.0191
653.368	67.3027
656.816	69.0365
660.263	66.5095
663.708	61.7646
667.153	57.7302
670.596	54.4486
674.037	51.7876
677.478	46.6401
680.917	41.0128
684.355	35.6557
687.791	30.5013
691.224	26.3948
694.658	18.1895
698.091	13.3661
701.522	9.60352
704.95	6.6134
708.379	5.97835
711.806	7.74844
715.23	9.22673
718.655	11.812
722.078	14.1255
725.498	16.0968
728.919	16.7956
732.337	18.3709
735.755	19.83
739.17	22.0024
742.584	22.7016
745.998	26.5168
749.409	31.0891
752.819	37.3728
756.23	41.5759
759.637	44.0635
763.043	46.8107
766.448	50.4091
769.853	53.0414
773.255	54.513
776.656	53.5885
780.056	54.9379
783.454	57.0935
786.851	58.9975
790.247	60.3606
793.641	61.5914
797.034	60.9199
800.426	58.4667
803.817	58.5123
807.206	57.014
810.592	53.775
813.979	52.0876
817.364	49.497
820.748	47.7633
824.129	48.7545
827.511	49.048
830.891	51.6908
834.269	50.9811
837.646	48.9117
841.023	48.7469
844.396	47.4882
847.77	46.9311
851.141	44.5116
854.513	42.0043
857.881	39.9051
861.248	36.1808
864.616	33.6854
867.98	32.4821
871.343	29.8098
874.707	26.7425
878.068	24.9217
881.428	22.3003
884.786	19.3185
888.143	17.3221
891.498	14.227
894.855	9.03368
898.208	6.44952
901.56	5.5923
904.91	6.56707
908.26	5.95027
911.608	6.71252
914.955	4.58602
918.298	6.0244
921.643	8.38683
924.986	9.24897
928.328	9.33792
931.668	12.1879
935.006	14.7127
938.344	15.5133
941.681	15.8256
945.014	17.387
948.349	17.8804
951.682	17.7579
955.012	19.0433
958.343	15.1982
961.67	14.4158
964.998	18.2334
968.323	24.0639
971.649	30.5441
974.971	40.0516
978.293	49.8726
981.615	59.6568
984.933	68.0603
988.251	76.7154
991.567	82.5379
994.884	89.3201
998.198	95.2567
1001.51	101.289
1004.82	103.044
1008.13	99.3878
1011.44	97.0497
1014.75	98.4307
1018.06	102.98
1021.36	115.459
1024.66	132.685
1027.97	151.427
1031.27	169.011
1034.57	185.032
1037.87	196.432
1041.16	207.548
1044.46	218.664
1047.76	227.03
1051.05	231.545
1054.34	236.08
1057.63	234.925
1060.92	228.073
1064.21	217.778
1067.5	201.587
1070.78	185.407
1074.07	163.767
1077.35	139.972
1080.63	110.544
1083.91	82.1951
1087.19	52.7954
1090.47	25.6915
1093.75	11.7281
1097.03	6.51238
1100.3	7.42649
1103.57	11.9519
1106.84	16.0758
1110.11	16.415
1113.38	14.9229
1116.65	12.1634
1119.92	11.8027
1123.19	11.4526
1126.45	10.6628
1129.71	11.2457
1132.97	13.7619
1136.23	15.0114
1139.49	17.1567
1142.75	17.4415
1146.01	17.8422
1149.26	16.8192
1152.52	14.6404
1155.77	11.3741
1159.02	8.18505
1162.27	4.25369
1165.52	2.3898
1168.77	0.297564
1172.02	2.69569
1175.26	5.70319
1178.51	9.04286
1181.75	12.6625
1184.99	16.0544
1188.23	18.4335
1191.47	21.5386
1194.71	25.7892
1197.94	31.9826
1201.18	40.2241
1204.41	43.8429
1207.65	51.1259
1210.88	58.7384
1214.11	68.7168
1217.34	77.4737
1220.57	82.9352
1223.79	89.9767
1227.02	97.4492
1230.24	102.112
1233.47	105.288
1236.69	107.154
1239.91	110.071
1243.13	110.223
1246.34	111.681
1249.56	113.601
1252.78	112.986
1255.99	111.272
1259.2	108.482
1262.42	107.11
1265.63	104.389
1268.84	103.018
1272.04	101.837
1275.25	101.089
1278.46	102.569
1281.66	105.002
1284.86	107
1288.07	113.763
1291.27	120.915
1294.47	123.072
1297.66	128.782
1300.86	133.565
1304.06	138.757
1307.25	143.525
1310.44	148.469
1313.64	152.694
1316.83	159.057
1320.02	160.727
1323.2	158.281
1326.39	158.576
1329.58	158.33
1332.76	154.541
1335.95	151.72
1339.13	151.192
1342.31	149.257
1345.49	145.853
1348.67	142.766
1351.85	139.442
1355.02	136.112
1358.2	132.939
1361.37	130.054
1364.54	127.962
1367.71	124.025
1370.88	119.291
1374.05	115.227
1377.22	112.957
1380.39	110.487
1383.55	108.779
1386.72	108.734
1389.88	106.638
1393.04	104.156
1396.2	100.894
1399.36	95.8458
1402.52	96.0788
1405.68	102.385
1408.83	109.884
1411.98	116.62
1415.14	129.965
1418.29	144.322
1421.44	160.764
1424.59	175.088
1427.74	190.925
1430.89	205.99
1434.03	220.903
1437.18	236.226
1440.32	247.019
1443.46	255.145
1446.6	260.05
1449.74	260.985
1452.88	259.323
1456.02	253.469
1459.16	244.102
1462.29	233.869
1465.43	218.107
1468.56	201.002
1471.69	183.242
1474.82	169.471
1477.95	152.834
1481.08	138.777
1484.2	125.481
1487.33	112.521
1490.46	102.95
1493.58	96.5962
1496.7	88.9313
1499.82	82.174
1502.94	80.0038
1506.06	76.9753
1509.18	75.1833
1512.29	74.4918
1515.41	72.192
1518.52	70.5714
1521.63	69.7078
1524.75	69.1736
1527.85	66.8296
1530.96	65.5448
1534.07	67.4952
1537.18	69.8875
1540.28	73.0298
1543.39	73.3681
1546.49	76.8592
1549.59	80.3818
1552.69	84.2958
1555.79	87.1155
1558.89	88.9994
1561.99	89.8839
1565.08	93.67
1568.18	99.6428
1571.27	105.998
1574.37	112.751
1577.46	121.272
1580.55	129.823
1583.64	136.889
1586.73	145.28
1589.81	151.433
1592.9	154.633
1595.98	156.068
1599.06	158.824
1602.15	159.543
1605.23	159.488
1608.31	158.762
1611.39	158.44
1614.46	156.689
1617.54	153.495
1620.61	151.058
1623.69	148.521
1626.76	148.742
1629.83	146.15
1632.9	146.237
1635.97	146.934
1639.04	149.025
1642.11	155.088
1645.17	158.539
1648.24	163.163
1651.3	163.433
1654.36	166.391
1657.42	166.692
1660.48	165.978
1663.54	161.648
1666.6	155.436
1669.66	149.233
1672.71	139.911
1675.77	130.609
1678.82	121.951
1681.87	109.693
1684.92	97.8685
1687.97	87.9446
1691.02	75.4423
1694.07	65.6538
1697.11	55.4609
1700.16	49.4896
1703.2	45.0012
1706.25	40.2796
1709.29	35.1299
1712.33	30.0036
1715.37	26.3634
1718.41	23.7789
1721.44	19.1513
1724.48	14.7105
1727.51	13.4121
1730.55	13.2503
1733.58	9.52313
1736.61	9.17975
1739.64	7.07506
1742.67	7.81784
1745.7	5.7533
1748.72	5.32907
1751.75	5.01241
1754.77	5.0965
1757.8	4.73716
1760.82	3.59457
1763.84	2.42292
1766.86	2.50934
1769.88	4.44783
1772.9	5.0971
1775.91	6.01122
1778.93	4.94213
1781.94	3.31795
1784.96	2.75489
1787.97	2.58642
1790.98	3.65417
1793.99	2.99202
1797	2.90846
1800.01	3.47122
1803.01	3.98647
1806.02	4.81502
1809.02	6.17777
1812.02	7.04687
1815.02	7.20019
1818.03	7.88902
1821.02	8.72156
1824.02	8.53426
1827.02	9.95851
1830.02	9.20144
1833.01	9.28106
1836.01	8.93163
1839	9.40236
1841.99	9.87552
1844.98	8.82639
1847.97	9.24642
1850.96	8.9815
1853.95	9.32951
1856.93	10.0025
1859.92	9.02379
1862.9	9.23217
1865.88	8.22594
1868.87	7.49997
1871.85	7.49925
1874.83	8.12274
1877.81	10.001
1880.78	10.9291
1882.53	9.99765
1885.52	12.4667
1888.51	13.209
1891.5	15.4988
1894.48	16.0144
1897.47	15.4223
1900.45	15.2608
1903.43	16.5146
1906.41	17.8187
1909.39	16.771
1912.37	15.2296
1915.35	14.6113
1918.33	14.6931
1921.3	13.9222
1924.28	13.9433
1927.25	12.9982
1930.22	9.72741
1933.19	7.15245
1936.16	8.07628
1939.13	8.28189
1942.1	8.29497
1945.07	7.07198
1948.03	6.14298
1951	5.22654
1953.96	5.47679
1956.92	7.07866
1959.88	7.04815
1962.84	7.30809
1965.8	6.77767
1968.76	5.53845
1971.72	7.36543
1974.67	8.617
1977.63	10.3082
1980.58	11.4775
1983.54	12.2332
1986.49	12.4377
1989.44	14.7072
1992.39	16.4061
1995.33	17.7539
1998.28	19.7065
2001.23	21.436
2004.17	23.613
2007.12	24.438
2010.06	23.6959
2013	23.1107
2015.94	21.9903
2018.88	22.1229
2021.82	20.6688
2024.76	21.439
2027.69	21.4523
2030.63	20.3641
2033.56	21.4052
2036.5	21.1611
2039.43	21.1862
2042.36	21.4543
2045.29	22.3838
2048.22	23.6726
2051.15	23.5988
2054.07	23.3094
2057	24.0653
2059.92	24.3458
2062.85	24.2057
2065.77	24.5484
2068.69	25.4442
2071.61	23.4071
2074.53	22.3892
2077.45	20.6687
2080.37	21.2529
2083.28	21.6542
2086.2	21.8958
2089.11	22.3137
2092.02	23.7058
2094.94	25.6086
2097.85	26.754
2100.76	26.8377
2103.66	26.8718
2106.57	26.5262
2109.48	24.8519
2112.38	25.2215
2115.29	25.501
2118.19	24.2545
2121.09	22.564
2123.99	21.463
2126.89	19.7838
2129.79	20.1156
2132.69	18.2625
2135.59	15.9303
2138.48	15.6513
2141.38	15.345
2144.27	13.8425
2147.17	17.3208
2150.06	17.0201
2152.95	16.1811
2155.84	16.7585
2158.73	17.0537
2161.61	20.1178
2164.5	22.2958
2167.38	23.2177
2170.27	23.4843
2173.15	21.8752
2176.03	21.4205
2178.91	20.3451
2181.8	22.2083
2184.67	23.3096
2187.55	23.2388
2190.43	21.8857
2193.3	23.031
2196.18	23.6644
2199.05	24.9632
2201.93	27.2865
2204.8	26.2337
2207.67	26.7226
2210.54	27.0055
2213.41	27.1416
2216.27	28.2213
2219.14	28.6148
2222.01	28.0629
2224.87	27.7722
2227.73	29.5293
2230.6	30.632
2233.46	30.9945
2236.32	31.2725
2239.18	29.4247
2242.03	27.642
2244.89	26.21
2247.75	24.9249
2250.6	23.7763
2253.46	22.9023
2256.31	22.4358
2259.16	22.2086
2262.01	22.3494
2264.86	21.8952
2267.71	20.9829
2270.56	19.968
2273.4	17.6501
2276.25	17.0865
2279.09	15.3609
2281.94	13.817
2284.78	13.8682
2287.62	13.8767
2290.46	12.2553
2293.3	12.1381
2296.14	14.347
2298.98	15.8321
2301.82	18.2369
2304.65	19.5545
2307.49	19.3557
2310.32	20.7392
2313.15	20.3334
2315.98	20.7142
2318.81	21.1051
2321.64	20.4447
2324.47	20.783
2327.3	20.4219
2330.12	20.1431
2332.95	17.9988
2335.77	15.9097
2338.6	14.1895
2341.42	12.8529
2344.24	9.9178
2347.06	6.88471
2349.88	4.86273
2352.7	3.55866
2355.51	3.1424
2358.33	3.00196
2361.14	3.49024
2363.96	4.81526
2366.77	5.87532
2369.58	6.96929
2372.39	6.79598
2375.2	5.26219
2378.01	6.82716
2380.82	6.6332
2383.63	5.07316
2386.43	4.7533
2389.24	4.93692
2392.04	4.77335
2394.84	5.5534
2397.65	4.78224
2400.45	4.43691
2403.25	3.83938
2406.05	4.50369
2408.84	4.25155
2411.64	2.9835
2414.44	4.59758
2417.23	4.92533
2420.02	5.4626
2422.82	7.26377
2425.61	8.6903
2428.4	8.47282
2431.19	9.65407
2433.98	9.3652
2436.77	8.62669
2439.55	7.82682
2442.34	7.13428
2445.12	7.58565
2447.91	6.44774
2450.69	3.65896
2453.47	4.34678
2456.25	4.18557
2459.03	2.73174
2461.81	0.747854
2464.59	-0.0629784
2467.36	-0.268683
2470.14	-1.3934
2472.92	-1.56986
2475.69	-0.579652
2478.46	-0.791081
2481.23	-0.526499
2484	-1.87277
2486.77	-1.94646
2489.54	-2.76082
2492.31	-0.436801
2495.08	-1.21831
2497.84	-0.914769
2500.61	-1.19831
2503.37	0.705053
2506.13	-0.560088
2508.9	-0.48722
2511.66	-0.375624
2514.42	-0.266662
2517.18	-0.493466
2519.93	-0.23028
2522.69	0.294591
2525.45	0.140407
2528.2	0.516646
2530.95	1.27346
2533.71	3.6617
2536.46	5.42924
2539.21	6.36146
2541.96	7.19819
2544.71	8.0275
2547.46	8.87817
2550.2	7.76573
2552.95	7.84806
2555.7	8.89653
2558.44	9.7979
2561.18	9.74738
2563.93	9.56524
2566.67	9.48905
2569.41	9.67241
2572.15	7.42194
2574.88	6.90534
2577.62	6.56854
2580.36	7.57342
2583.09	5.5275
2585.83	4.20108
2588.56	2.99088
2591.29	3.68177
2594.02	3.14967
2596.75	4.21733
2599.48	3.43868
2602.21	4.55292
2604.94	3.4935
2607.67	3.23093
2610.39	3.22728
2613.12	4.72632
2615.84	4.61262
2618.56	4.06647
2621.28	6.0953
2624.01	7.48525
2626.72	7.56605
2629.44	10.7212
2632.16	12.207
2634.88	12.1909
2637.59	12.5344
2640.31	13.5564
2643.02	14.8431
2645.74	15.4515
2648.45	16.0398
2651.16	14.3198
2653.87	14.6855
2656.58	14.8997
2659.29	12.6816
2661.99	11.8653
2664.7	11.0552
2667.41	11.8539
2670.11	11.4596
2672.81	10.2304
2675.51	9.77598
2678.22	9.66383
2680.92	9.24469
2683.62	8.89243
2686.31	10.3344
2689.01	10.2982
2691.71	10.186
2694.4	11.0037
2697.1	9.95359
2699.79	10.1664
2702.49	12.4813
2705.18	15.2427
2707.87	17.2137
2710.56	18.709
2713.25	19.017
2715.94	19.2793
2718.62	20.1839
2721.31	21.1181
2723.99	20.2914
2726.68	20.0705
2729.36	20.2552
2732.04	20.8139
2734.73	21.0095
2737.41	19.5929
2740.08	18.3134
2742.76	17.2058
2745.44	15.996
2748.12	14.4317
2750.79	12.0311
2753.47	9.59473
2756.14	8.65117
2758.81	5.66451
2761.49	4.89108
2764.16	4.88519
2766.83	3.78502
2769.5	3.88024
2772.16	2.89506
2774.83	1.92369
2777.5	0.785151
2780.16	-0.472947
2782.83	1.05685
2785.49	-0.203894
2788.15	-0.292867
2790.82	-0.708223
2793.48	-1.11557
2796.14	-1.58226
2798.79	-0.563614
2801.45	-0.404495
2804.11	-0.942906
2806.76	-0.611984
2809.42	-2.29023
2812.07	-1.93626
2814.73	2.05201
2817.38	5.56582
2820.03	13.4464
2822.68	21.8262
2825.33	29.9093
2827.98	39.5902
2830.63	50.5026
2833.27	61.508
2835.92	74.5818
2838.56	89.0301
2841.21	105.711
2843.85	125.271
2846.49	146.5
2849.13	170.025
2851.77	194.007
2854.41	217.802
2857.05	240.403
2859.69	262.644
2862.32	283.878
2864.96	302.799
2867.59	319.255
2870.23	333.224
2872.86	346.263
2875.49	358.843
2878.12	370.917
2880.75	382.15
2883.38	390.35
2886.01	399.139
2888.63	403.075
2891.26	409.641
2893.89	416.942
2896.51	425.241
2899.13	436.352
2901.76	451.441
2904.38	467.891
2907	489.302
2909.62	513.838
2912.24	538.947
2914.85	562.908
2917.47	586.807
2920.09	604.984
2922.7	620.016
2925.32	631.399
2927.93	638.54
2930.54	640.815
2933.15	638.386
2935.76	631.058
2938.37	620.52
2940.98	605.005
2943.59	586.503
2946.2	563.77
2948.8	538.133
2951.41	512.578
2954.01	485.003
2956.62	459.652
2959.22	433.807
2961.82	408.653
2964.42	384.725
2967.02	364.528
2969.62	345.077
2972.22	328.036
2974.81	309.539
2977.41	290.541
2980	271.568
2982.6	252.029
2985.19	232.426
2987.78	210.878
2990.38	190.678
2992.97	170.876
2995.56	152.325
2998.14	134.842
3000.73	117.622
3003.32	100.159
3005.91	85.0218
3008.49	70.1474
3011.07	55.8899
3013.66	43.1821
3016.24	33.5221
3018.82	23.5238
3021.4	15.0699
3023.98	10.4304
3026.56	6.06269
3029.14	3.26269
3031.71	2.12936
3034.29	0.312259
3036.87	-0.80626
3039.44	1.086
3042.01	2.26253
3044.59	3.99436
3047.16	6.39032
3049.73	5.98363
3052.3	6.4048
3054.87	8.13785
3057.43	9.70138
3060	12.0561
3062.57	11.4099
3065.13	9.58306
3067.7	9.04113
3070.26	8.86745
3072.82	8.67981
3075.39	6.68907
3077.95	6.26705
3080.51	4.59893
3083.07	4.16592
3085.63	4.96228
3088.18	4.98082
3090.74	4.32419
3093.29	4.05744
3095.85	4.6901
3098.4	5.19798
3100.95	7.53258
3103.51	9.3576
3106.06	11.6827
3108.61	14.0505
3111.16	16.7624
3113.71	19.7747
3116.25	23.7671
3118.8	27.3916
3121.35	31.0326
3123.89	34.3696
3126.44	37.4426
3128.98	40.4266
3131.52	44.6891
3134.06	49.5537
3136.6	52.2075
3139.14	56.4678
3141.68	58.5167
3144.22	60.5657
3146.76	61.6829
3149.29	59.3056