File: data/Raman/poly_smoothed/Mb_00_13_09_1x_45s_532 nm_x100_100%_600 gr_mm_01.txt
#Acq. time (s)=	45
#Accumulations=	2
#Range (cm-¹)=	200...3150
#Windows=	2
#Auto scanning=	Off
#Autofocus=	Off
#Macrospot=	Off
#AutoExposure=	Off
#Spike filter=	Multiple accum.
#Delay time (s)=	0
#Binning=	1
#Readout mode=	Signal
#DeNoise=	Off
#ICS correction=	On
#Dark correction=	Off
#Inst. Process=	Off
#Detector Gain=	Best Dynamic Range
#Detector ADC=	20 kHz
#Detector temperature (°C)=	-69.85
#Instrument=	LabRAM HR Evol
#Detector=	Synapse
#Objective=	x100
#Grating=	600 gr/mm
#ND Filter=	100%
#Laser (nm)=	532
#Hole=	100.021
#Range=	Auto
#Laser Pol.=	No
#Raman. Pol.=	No
#Laser Pol. (°)=	-0.0007625
#Raman Pol. (°)=	89.9995
#Collection=	Microscope
#StageXY=	Marzhauser
#StageZ=	Marzhauser
#X (µm)=	-987.4
#Y (µm)=	-2947.9
#Z (µm)=	527.85
#Full time(mm:ss)=	3:18
#Project=
#Sample=
#Site=
#Title=	Mb_00_13_09_2x_45s_532 nm_x100_100%_600 gr_mm
#Remark=
#Date=	06.07.2022 10:18
#Acquired=	06.07.2022 10:18:03
#Base:Fit=	10.08.2022 10:16:56
#Base:Sub=	10.08.2022 10:17:24
#Filter:Polynom=	16.08.2022 10:36:38
#AxisType[0]=Intens
#AxisUnit[0]=Cnt
#AxisType[1]=Spectr
#AxisUnit[1]=1/cm
200.398	4.84461
204.027	-0.274795
207.657	-4.91952
211.283	-7.24347
214.909	-2.63937
218.533	5.44722
222.157	21.3642
225.777	39.896
229.396	57.9602
233.016	75.3164
236.632	89.5088
240.247	103.535
243.86	113.763
247.474	121.863
251.085	126.825
254.694	137.602
258.301	145.895
261.908	149.868
265.513	149.664
269.116	146.637
272.718	139.278
276.319	128.231
279.918	116.316
283.516	104.339
287.113	92.65
290.708	79.5364
294.302	66.9402
297.894	56.6308
301.485	52.2652
305.073	45.0241
308.661	39.8075
312.247	37.1628
315.833	35.4383
319.415	32.8024
322.997	30.237
326.579	25.923
330.156	23.185
333.735	19.2737
337.31	14.2855
340.885	13.4239
344.458	13.8583
348.03	10.7084
351.6	7.68548
355.17	4.72487
358.737	-0.0933029
362.304	-0.498766
365.868	2.88333
369.431	9.32829
372.994	16.1595
376.554	23.1012
380.112	35.4689
383.669	48.9049
387.225	66.9478
390.781	82.0473
394.334	94.9062
397.885	110.176
401.436	124.166
404.984	132.914
408.532	138.103
412.078	138.492
415.623	138.018
419.166	137.172
422.708	130.048
426.248	119.471
429.788	108.716
433.326	96.1365
436.86	82.7505
440.395	67.7258
443.929	54.2542
447.461	41.0614
450.99	33.7952
454.52	22.1009
458.048	14.1324
461.573	10.6798
465.099	9.03212
468.623	10.4135
472.144	14.6048
475.666	15.6639
479.184	18.3605
482.703	21.9224
486.218	26.8642
489.734	28.9761
493.247	31.2966
496.759	33.9718
500.271	38.2556
503.779	42.8004
507.287	46.1609
510.795	48.0907
514.299	50.1893
517.803	52.7108
521.305	54.1306
524.805	56.4695
528.307	57.4707
531.805	58.2392
535.301	56.7084
538.797	56.2302
542.291	53.4313
545.783	51.649
549.275	48.1865
552.765	42.4905
556.253	37.0956
559.738	32.8646
563.224	29.6498
566.709	26.2226
570.192	23.9765
573.674	21.0895
577.153	17.6522
580.632	15.4981
584.11	11.7876
587.587	10.87
591.06	7.96565
594.534	5.50224
598.005	4.26267
601.476	1.681
604.944	1.90593
608.413	0.754333
611.878	3.46067
615.344	5.25759
618.807	5.36141
622.27	5.30228
625.73	8.89801
629.189	13.5921
632.648	14.88
636.105	17.9766
639.559	19.6526
643.013	23.5504
646.467	27.1588
649.918	28.6896
653.368	30.2475
656.816	31.7005
660.263	32.3689
663.708	28.8323
667.153	26.8909
670.596	24.2958
674.037	21.2427
677.478	17.1387
680.917	15.0217
684.355	11.9933
687.791	10.6568
691.224	7.50793
694.658	7.81382
698.091	6.2998
701.522	4.82478
704.95	5.30702
708.379	8.0286
711.806	9.20179
715.23	10.976
718.655	12.6948
722.078	14.8097
725.498	14.7294
728.919	16.0815
732.337	17.7275
735.755	19.3354
739.17	20.5368
742.584	20.3107
745.998	20.9197
749.409	21.5157
752.819	24.9581
756.23	26.3404
759.637	26.7832
763.043	28.3643
766.448	31.5775
769.853	33.4171
773.255	36.0494
776.656	37.4756
780.056	37.2302
783.454	38.2913
786.851	40.1178
790.247	40.7232
793.641	40.9269
797.034	42.9762
800.426	45.1272
803.817	45.5364
807.206	45.7871
810.592	45.4578
813.979	48.0333
817.364	51.121
820.748	51.7636
824.129	54.0154
827.511	56.5567
830.891	58.6385
834.269	60.2572
837.646	58.1071
841.023	56.178
844.396	56.0039
847.77	55.2901
851.141	52.8906
854.513	47.4183
857.881	43.5615
861.248	39.0934
864.616	32.7378
867.98	31.3357
871.343	27.0232
874.707	23.8716
878.068	21.991
881.428	16.7325
884.786	14.6375
888.143	9.87655
891.498	5.41398
894.855	6.01376
898.208	6.46322
901.56	5.54859
904.91	8.03117
908.26	10.4264
911.608	11.6038
914.955	10.6968
918.298	10.7687
921.643	10.2851
924.986	8.92429
928.328	11.8991
931.668	10.7018
935.006	9.09254
938.344	8.14477
941.681	7.57885
945.014	4.8162
948.349	4.25896
951.682	4.4347
955.012	1.83046
958.343	-1.00649
961.67	-3.28103
964.998	-0.104516
968.323	6.5594
971.649	15.9361
974.971	25.9105
978.293	37.1923
981.615	50.3879
984.933	61.8942
988.251	70.9922
991.567	77.4541
994.884	85.7807
998.198	89.8548
1001.51	94.231
1004.82	97.3356
1008.13	97.5735
1011.44	97.9437
1014.75	99.1044
1018.06	102.371
1021.36	109.473
1024.66	118.316
1027.97	127.06
1031.27	133.339
1034.57	139.131
1037.87	141.812
1041.16	145.795
1044.46	150.695
1047.76	153.922
1051.05	155.478
1054.34	154.45
1057.63	152.014
1060.92	146.441
1064.21	138.206
1067.5	125.93
1070.78	110.588
1074.07	96.0594
1077.35	80.0002
1080.63	63.8291
1083.91	46.5803
1087.19	33.0979
1090.47	21.39
1093.75	19.7636
1097.03	20.8353
1100.3	23.2821
1103.57	28.5437
1106.84	27.3157
1110.11	27.3797
1113.38	24.9121
1116.65	25.4595
1119.92	23.6436
1123.19	23.3988
1126.45	20.1585
1129.71	18.6915
1132.97	19.8445
1136.23	19.7885
1139.49	20.1619
1142.75	18.0846
1146.01	18.9455
1149.26	12.9813
1152.52	12.1977
1155.77	11.5157
1159.02	7.26664
1162.27	5.68715
1165.52	5.70369
1168.77	6.28124
1172.02	7.1395
1175.26	9.35582
1178.51	7.14318
1181.75	8.6101
1184.99	8.68162
1188.23	9.41675
1191.47	10.8229
1194.71	14.0424
1197.94	18.4894
1201.18	23.3476
1204.41	30.2843
1207.65	38.3097
1210.88	47.0664
1214.11	56.0975
1217.34	65.8468
1220.57	73.3815
1223.79	81.3136
1227.02	87.8869
1230.24	95.0874
1233.47	98.7439
1236.69	101.511
1239.91	105.254
1243.13	107.643
1246.34	109.664
1249.56	107.248
1252.78	106.338
1255.99	100.534
1259.2	96.8217
1262.42	92.621
1265.63	90.3505
1268.84	86.3859
1272.04	82.6775
1275.25	81.1191
1278.46	83.984
1281.66	85.6391
1284.86	90.8681
1288.07	91.5653
1291.27	95.7057
1294.47	102.059
1297.66	111.382
1300.86	119.553
1304.06	125.596
1307.25	134.093
1310.44	139.834
1313.64	142.895
1316.83	147.528
1320.02	152.501
1323.2	156.35
1326.39	156.142
1329.58	155.755
1332.76	154.109
1335.95	150.946
1339.13	150.014
1342.31	145.431
1345.49	140.131
1348.67	135.852
1351.85	128.616
1355.02	124.376
1358.2	119.884
1361.37	111.846
1364.54	104.235
1367.71	97.6617
1370.88	93.7733
1374.05	90.0918
1377.22	85.2543
1380.39	80.3386
1383.55	75.6573
1386.72	72.7073
1389.88	67.4065
1393.04	64.1064
1396.2	64.1677
1399.36	66.0653
1402.52	69.1608
1405.68	72.6505
1408.83	79.8717
1411.98	93.0771
1415.14	107.851
1418.29	120.687
1421.44	132.67
1424.59	148.253
1427.74	163.236
1430.89	176.118
1434.03	192.598
1437.18	203.934
1440.32	211.076
1443.46	215.977
1446.6	217.083
1449.74	216.287
1452.88	213.188
1456.02	205.885
1459.16	196.642
1462.29	183.581
1465.43	168.431
1468.56	149.737
1471.69	133.317
1474.82	118.097
1477.95	104.323
1481.08	92.7985
1484.2	80.3955
1487.33	71.3996
1490.46	62.3145
1493.58	56.0258
1496.7	51.4972
1499.82	45.7801
1502.94	43.301
1506.06	43.7749
1509.18	41.9264
1512.29	40.6185
1515.41	40.8626
1518.52	40.0644
1521.63	41.9883
1524.75	43.916
1527.85	45.0483
1530.96	49.0321
1534.07	50.3993
1537.18	52.7516
1540.28	54.343
1543.39	56.5474
1546.49	59.1842
1549.59	63.4082
1552.69	68.7037
1555.79	71.5242
1558.89	71.6496
1561.99	73.113
1565.08	72.8993
1568.18	75.1258
1571.27	79.2084
1574.37	79.1507
1577.46	81.6945
1580.55	84.3288
1583.64	87.9958
1586.73	89.1729
1589.81	92.4944
1592.9	95.4584
1595.98	96.4821
1599.06	96.1244
1602.15	97.4376
1605.23	99.6546
1608.31	100.642
1611.39	100.883
1614.46	102.262
1617.54	103.091
1620.61	106.951
1623.69	111.104
1626.76	113.658
1629.83	118.539
1632.9	118.248
1635.97	122.1
1639.04	123.559
1642.11	125.445
1645.17	132.559
1648.24	137.054
1651.3	141.146
1654.36	142.695
1657.42	142.602
1660.48	140.784
1663.54	138.329
1666.6	130.211
1669.66	123.208
1672.71	115.744
1675.77	109.15
1678.82	102.4
1681.87	90.8088
1684.92	79.6228
1687.97	68.4277
1691.02	58.2379
1694.07	48.1143
1697.11	39.7
1700.16	31.6612
1703.2	24.7011
1706.25	18.1687
1709.29	14.4919
1712.33	11.4219
1715.37	8.41363
1718.41	6.86449
1721.44	7.81886
1724.48	7.50803
1727.51	7.26534
1730.55	5.35121
1733.58	4.30215
1736.61	5.15066
1739.64	4.66011
1742.67	4.3676
1745.7	7.57596
1748.72	8.98764
1751.75	9.56274
1754.77	9.56385
1757.8	9.94421
1760.82	11.8763
1763.84	10.5548
1766.86	8.91686
1769.88	8.79234
1772.9	9.72051
1775.91	11.5933
1778.93	13.7182
1781.94	17.0886
1784.96	19.4834
1787.97	21.5285
1790.98	21.4244
1793.99	22.7243
1797	26.8889
1800.01	27.3628
1803.01	28.0546
1806.02	28.1213
1809.02	29.7126
1812.02	31.0242
1815.02	30.9844
1818.03	30.2035
1821.02	30.917
1824.02	32.1513
1827.02	33.4094
1830.02	31.401
1833.01	29.1202
1836.01	31.5984
1839	31.3056
1841.99	32.4017
1844.98	32.2302
1847.97	32.8283
1850.96	31.1097
1853.95	32.6078
1856.93	31.3302
1859.92	28.509
1862.9	25.2931
1865.88	23.7842
1868.87	20.8143
1871.85	22.8474
1874.83	21.16
1877.81	20.3533
1880.78	19.0832
1882.53	19.2262
1885.52	19.9064
1888.51	21.9967
1891.5	20.7058
1894.48	19.8194
1897.47	19.1888
1900.45	17.197
1903.43	18.1683
1906.41	20.117
1909.39	21.4535
1912.37	19.7027
1915.35	19.1279
1918.33	16.627
1921.3	17.3772
1924.28	15.3524
1927.25	13.0436
1930.22	7.49693
1933.19	5.34801
1936.16	3.55953
1939.13	3.47705
1942.1	2.67971
1945.07	2.77646
1948.03	2.6322
1951	2.68303
1953.96	5.32767
1956.92	4.39644
1959.88	4.27498
1962.84	2.47251
1965.8	0.897299
1968.76	2.41152
1971.72	2.47591
1974.67	3.43365
1977.63	2.82609
1980.58	4.04049
1983.54	4.24646
1986.49	5.16691
1989.44	6.80624
1992.39	7.56098
1995.33	6.28125
1998.28	8.4364
2001.23	9.08406
2004.17	12.7854
2007.12	16.0867
2010.06	14.1587
2013	14.1693
2015.94	15.3535
2018.88	16.3615
2021.82	19.1803
2024.76	18.9767
2027.69	18.8157
2030.63	17.2673
2033.56	14.2469
2036.5	16.7832
2039.43	18.0277
2042.36	17.561
2045.29	18.667
2048.22	15.0934
2051.15	13.5835
2054.07	14.0065
2057	12.2298
2059.92	12.8629
2062.85	9.05325
2065.77	9.31761
2068.69	8.78404
2071.61	7.38591
2074.53	8.30258
2077.45	5.45046
2080.37	5.45951
2083.28	3.06079
2086.2	4.24057
2089.11	5.59828
2092.02	6.48495
2094.94	7.02477
2097.85	7.88644
2100.76	9.80334
2103.66	14.4519
2106.57	14.453
2109.48	17.6644
2112.38	19.0026
2115.29	19.8379
2118.19	17.8928
2121.09	16.6287
2123.99	17.0035
2126.89	16.4593
2129.79	15.1241
2132.69	13.2398
2135.59	10.4622
2138.48	9.17199
2141.38	8.55033
2144.27	6.35805
2147.17	6.38984
2150.06	3.53881
2152.95	2.96301
2155.84	1.96355
2158.73	3.03479
2161.61	4.82777
2164.5	5.69592
2167.38	5.8832
2170.27	7.87952
2173.15	7.09486
2176.03	7.24996
2178.91	6.72204
2181.8	9.23201
2184.67	9.30958
2187.55	10.2344
2190.43	8.51691
2193.3	12.0401
2196.18	12.5424
2199.05	13.9749
2201.93	16.1686
2204.8	15.3483
2207.67	15.0973
2210.54	15.1144
2213.41	14.8135
2216.27	14.0551
2219.14	17.3108
2222.01	18.6964
2224.87	19.1368
2227.73	20.8184
2230.6	21.2231
2233.46	23.8509
2236.32	25.0962
2239.18	25.4644
2242.03	26.0604
2244.89	27.3788
2247.75	27.2274
2250.6	29.8714
2253.46	29.1065
2256.31	29.5284
2259.16	27.2772
2262.01	25.5945
2264.86	26.7385
2267.71	26.9798
2270.56	23.9825
2273.4	21.0857
2276.25	15.0729
2279.09	11.9518
2281.94	9.17735
2284.78	6.94653
2287.62	8.12779
2290.46	7.74043
2293.3	8.68307
2296.14	10.8304
2298.98	11.1792
2301.82	13.5506
2304.65	16.1989
2307.49	16.8553
2310.32	17.7137
2313.15	16.5394
2315.98	16.0095
2318.81	15.8568
2321.64	16.8557
2324.47	14.2725
2327.3	13.4648
2330.12	13.8091
2332.95	15.0549
2335.77	11.6696
2338.6	9.98743
2341.42	4.47361
2344.24	1.73811
2347.06	1.02265
2349.88	-2.08748
2352.7	-2.45814
2355.51	-1.72745
2358.33	-1.74394
2361.14	-0.880638
2363.96	1.38645
2366.77	2.71842
2369.58	3.03423
2372.39	6.76556
2375.2	6.82649
2378.01	9.37854
2380.82	11.1168
2383.63	11.6385
2386.43	10.1817
2389.24	15.5556
2392.04	15.5795
2394.84	17.9779
2397.65	18.931
2400.45	18.9234
2403.25	17.7524
2406.05	16.1657
2408.84	17.8585
2411.64	17.3645
2414.44	19.1503
2417.23	15.0938
2420.02	15.6124
2422.82	14.0086
2425.61	12.1418
2428.4	9.50095
2431.19	12.0751
2433.98	11.435
2436.77	10.1865
2439.55	4.87817
2442.34	6.28873
2445.12	6.75407
2447.91	6.65861
2450.69	7.25422
2453.47	5.41861
2456.25	6.91784
2459.03	7.78311
2461.81	6.72375
2464.59	7.6011
2467.36	7.51486
2470.14	8.63625
2472.92	11.2749
2475.69	14.3923
2478.46	14.6375
2481.23	14.9842
2484	12.3394
2486.77	13.5982
2489.54	15.9416
2492.31	15.9954
2495.08	15.4634
2497.84	19.1622
2500.61	17.5744
2503.37	13.9697
2506.13	13.4256
2508.9	10.7422
2511.66	11.6763
2514.42	12.6137
2517.18	9.56526
2519.93	8.87514
2522.69	8.03428
2525.45	8.40018
2528.2	9.11344
2530.95	10.6968
2533.71	12.0262
2536.46	12.1867
2539.21	14.9059
2541.96	19.398
2544.71	22.2866
2547.46	23.5173
2550.2	24.114
2552.95	30.3161
2555.7	35.0769
2558.44	36.0229
2561.18	38.0691
2563.93	39.6016
2566.67	39.5334
2569.41	37.4214
2572.15	36.6748
2574.88	32.6015
2577.62	32.2235
2580.36	32.703
2583.09	30.2079
2585.83	27.592
2588.56	26.0698
2591.29	25.9254
2594.02	26.0674
2596.75	23.4309
2599.48	21.9068
2602.21	21.6608
2604.94	22.5704
2607.67	24.4164
2610.39	28.1195
2613.12	27.7092
2615.84	30.5971
2618.56	34.1129
2621.28	36.3615
2624.01	33.5885
2626.72	34.3591
2629.44	36.8424
2632.16	36.5396
2634.88	35.4283
2637.59	34.5062
2640.31	34.3339
2643.02	35.0299
2645.74	36.1052
2648.45	35.5529
2651.16	34.3856
2653.87	33.809
2656.58	34.7259
2659.29	35.0598
2661.99	33.5944
2664.7	34.4171
2667.41	34.5499
2670.11	35.7304
2672.81	36.5227
2675.51	39.3345
2678.22	39.8297
2680.92	39.5148
2683.62	39.279
2686.31	37.6135
2689.01	36.3292
2691.71	37.5117
2694.4	39.8447
2697.1	41.9123
2699.79	42.3129
2702.49	44.0182
2705.18	45.266
2707.87	48.9231
2710.56	49.1978
2713.25	52.042
2715.94	54.1684
2718.62	54.5181
2721.31	54.6322
2723.99	52.989
2726.68	51.4953
2729.36	49.3841
2732.04	47.5653
2734.73	47.8937
2737.41	47.3479
2740.08	44.3993
2742.76	42.159
2745.44	37.1718
2748.12	34.4461
2750.79	31.7393
2753.47	30.0929
2756.14	27.2646
2758.81	26.9555
2761.49	24.8853
2764.16	22.644
2766.83	22.1124
2769.5	21.3166
2772.16	18.8314
2774.83	21.198
2777.5	20.8685
2780.16	19.6583
2782.83	16.6003
2785.49	12.9131
2788.15	10.6822
2790.82	10.3676
2793.48	8.87807
2796.14	8.69074
2798.79	8.37769
2801.45	6.93407
2804.11	5.50293
2806.76	3.44474
2809.42	1.95747
2812.07	-0.384082
2814.73	2.08128
2817.38	6.8669
2820.03	16.4862
2822.68	24.3536
2825.33	33.8141
2827.98	43.2967
2830.63	55.8959
2833.27	68.4562
2835.92	83.3506
2838.56	100.136
2841.21	119.746
2843.85	140.326
2846.49	163.136
2849.13	187.563
2851.77	213.233
2854.41	239.46
2857.05	264.795
2859.69	289.612
2862.32	309.127
2864.96	330.164
2867.59	345.833
2870.23	359.66
2872.86	374.289
2875.49	384.483
2878.12	397.191
2880.75	411.667
2883.38	423.193
2886.01	431.057
2888.63	437.735
2891.26	444.31
2893.89	453.013
2896.51	462.061
2899.13	475.489
2901.76	488.382
2904.38	506.93
2907	529.584
2909.62	551.024
2912.24	575.858
2914.85	599.738
2917.47	620.384
2920.09	637.65
2922.7	654.971
2925.32	663.555
2927.93	667.197
2930.54	665.227
2933.15	656.631
2935.76	648.269
2938.37	631.448
2940.98	614.099
2943.59	594.624
2946.2	572.491
2948.8	546.105
2951.41	520.296
2954.01	493.682
2956.62	467.319
2959.22	441.088
2961.82	416.747
2964.42	391.713
2967.02	370.786
2969.62	348.499
2972.22	329.479
2974.81	311.345
2977.41	293.174
2980	271.732
2982.6	253.526
2985.19	236.841
2987.78	214.333
2990.38	191.529
2992.97	167.483
2995.56	147.51
2998.14	129.609
3000.73	110.25
3003.32	91.3093
3005.91	76.5255
3008.49	61.5257
3011.07	46.4434
3013.66	36.3333
3016.24	28.243
3018.82	17.6091
3021.4	10.3886
3023.98	7.26426
3026.56	1.99281
3029.14	2.86726
3031.71	3.10657
3034.29	5.34493
3036.87	9.6847
3039.44	13.952
3042.01	17.5375
3044.59	21.5074
3047.16	26.1378
3049.73	29.491
3052.3	31.9322
3054.87	36.6615
3057.43	38.9605
3060	39.6822
3062.57	42.529
3065.13	43.3487
3067.7	42.8737
3070.26	42.2214
3072.82	42.5621
3075.39	43.4189
3077.95	41.1628
3080.51	40.0227
3083.07	41.1958
3085.63	43.3976
3088.18	44.2466
3090.74	46.4184
3093.29	47.0702
3095.85	48.8524
3098.4	51.7543
3100.95	56.6878
3103.51	59.783
3106.06	64.0503
3108.61	69.0086
3111.16	74.6059
3113.71	80.907
3116.25	85.6081
3118.8	93.8493
3121.35	99.991
3123.89	107.442
3126.44	116.123
3128.98	122.752
3131.52	132.324
3134.06	141.849
3136.6	149.327
3139.14	157.579
3141.68	167.21
3144.22	176.979
3146.76	186.071
3149.29	194.838