File: data/Raman/poly_smoothed/Mb_00_13_39_1x_45s_532 nm_x100_100%_600 gr_mm_01.txt
#Acq. time (s)=	45
#Accumulations=	2
#Range (cm-¹)=	200...3150
#Windows=	2
#Auto scanning=	Off
#Autofocus=	Off
#Macrospot=	Off
#AutoExposure=	Off
#Spike filter=	Multiple accum.
#Delay time (s)=	0
#Binning=	1
#Readout mode=	Signal
#DeNoise=	Off
#ICS correction=	On
#Dark correction=	Off
#Inst. Process=	Off
#Detector Gain=	Best Dynamic Range
#Detector ADC=	20 kHz
#Detector temperature (°C)=	-69.85
#Instrument=	LabRAM HR Evol
#Detector=	Synapse
#Objective=	x100
#Grating=	600 gr/mm
#ND Filter=	100%
#Laser (nm)=	532
#Hole=	100.021
#Range=	Auto
#Laser Pol.=	No
#Raman. Pol.=	No
#Laser Pol. (°)=	-0.0007625
#Raman Pol. (°)=	89.9995
#Collection=	Microscope
#StageXY=	Marzhauser
#StageZ=	Marzhauser
#X (µm)=	-1030.9
#Y (µm)=	-2876.8
#Z (µm)=	528.75
#Full time(mm:ss)=	3:18
#Project=
#Sample=
#Site=
#Title=	Mb_00_13_39_2x_45s_532 nm_x100_100%_600 gr_mm
#Remark=
#Date=	06.07.2022 12:52
#Acquired=	06.07.2022 12:52:24
#Base:Fit=	10.08.2022 10:16:56
#Base:Sub=	10.08.2022 10:17:24
#Filter:Polynom=	16.08.2022 10:36:38
#AxisType[0]=Intens
#AxisUnit[0]=Cnt
#AxisType[1]=Spectr
#AxisUnit[1]=1/cm
200.398	9.22423
204.027	5.38138
207.657	1.58538
211.283	-0.714583
214.909	1.28325
218.533	9.59555
222.157	20.6724
225.777	35.4213
229.396	49.4563
233.016	64.2341
236.632	75.1658
240.247	84.797
243.86	92.9266
247.474	103.086
251.085	112.624
254.694	120.67
258.301	123.953
261.908	126.575
265.513	127.183
269.116	123.683
272.718	116.901
276.319	109.906
279.918	99.5761
283.516	91.0519
287.113	78.3968
290.708	65.9871
294.302	54.643
297.894	45.5578
301.485	40.2398
305.073	35.889
308.661	33.1977
312.247	30.737
315.833	28.9914
319.415	28.933
322.997	25.359
326.579	22.9878
330.156	20.1357
333.735	21.7725
337.31	20.4935
340.885	20.1331
344.458	17.7378
348.03	13.6318
351.6	10.8018
355.17	7.37063
358.737	5.04961
362.304	4.046
365.868	5.67355
369.431	8.64155
372.994	13.8533
376.554	18.7651
380.112	27.6994
383.669	37.3174
387.225	51.2316
390.781	65.0654
394.334	79.605
397.885	90.5703
401.436	101.971
404.984	111.333
408.532	115.42
412.078	115.616
415.623	114.98
419.166	113.326
422.708	110.489
426.248	104.855
429.788	96.5882
433.326	85.3888
436.86	73.5849
440.395	62.9017
443.929	51.1542
447.461	41.4262
450.99	34.9747
454.52	27.6497
458.048	22.6911
461.573	17.0881
465.099	15.1758
468.623	16.4307
472.144	18.5706
475.666	20.6087
479.184	23.1725
482.703	25.7466
486.218	29.2023
489.734	30.0764
493.247	31.6958
496.759	34.9219
500.271	38.4253
503.779	42.8737
507.287	48.1842
510.795	50.4913
514.299	53.1997
517.803	57.1254
521.305	58.6423
524.805	59.3611
528.307	60.8012
531.805	60.0387
535.301	58.7118
538.797	55.4489
542.291	52.4552
545.783	48.7044
549.275	42.5168
552.765	37.6106
556.253	33.072
559.738	26.3689
563.224	21.8344
566.709	18.583
570.192	14.3444
573.674	10.8069
577.153	8.09209
580.632	7.59553
584.11	4.91267
587.587	4.54727
591.06	3.73486
594.534	2.48934
598.005	2.92692
601.476	4.01746
604.944	4.87455
608.413	5.76326
611.878	8.33041
615.344	9.42201
618.807	9.5023
622.27	12.0534
625.73	14.4567
629.189	18.1493
632.648	19.8252
636.105	22.7251
639.559	28.1346
643.013	31.9439
646.467	32.0589
649.918	32.9285
653.368	33.5739
656.816	33.9893
660.263	31.8377
663.708	28.7621
667.153	25.7704
670.596	23.5701
674.037	21.6919
677.478	18.7661
680.917	16.023
684.355	13.887
687.791	11.327
691.224	9.26783
694.658	5.6336
698.091	3.77263
701.522	1.68493
704.95	2.19566
708.379	2.37729
711.806	4.26083
715.23	5.11695
718.655	8.22868
722.078	10.9699
725.498	14.5127
728.919	15.5219
732.337	17.8826
735.755	18.5636
739.17	19.8323
742.584	21.3715
745.998	24.6056
749.409	26.2677
752.819	29.621
756.23	31.3312
759.637	33.223
763.043	31.2571
766.448	34.2865
769.853	34.0593
773.255	33.7254
776.656	34.917
780.056	36.3101
783.454	38.3045
786.851	40.2488
790.247	41.5717
793.641	41.7401
797.034	42.8881
800.426	44.2128
803.817	45.0253
807.206	47.2701
810.592	48.0853
813.979	48.8563
817.364	48.8212
820.748	49.944
824.129	53.121
827.511	56.2268
830.891	56.2855
834.269	53.7641
837.646	53.2511
841.023	50.233
844.396	48.0043
847.77	45.9934
851.141	43.3634
854.513	39.945
857.881	37.2373
861.248	35.4012
864.616	32.9847
867.98	30.9313
871.343	28.4269
874.707	25.9122
878.068	21.125
881.428	19.7221
884.786	17.5642
888.143	15.1226
891.498	16.2198
894.855	14.1519
898.208	14.1911
901.56	14.956
904.91	17.4094
908.26	17.0785
911.608	17.27
914.955	17.8376
918.298	18.0748
921.643	20.1657
924.986	21.324
928.328	24.0724
931.668	25.3406
935.006	22.4952
938.344	23.9358
941.681	25.6279
945.014	24.9156
948.349	25.2217
951.682	26.1358
955.012	24.0955
958.343	20.825
961.67	18.7737
964.998	20.4334
968.323	23.642
971.649	28.0304
974.971	31.1143
978.293	31.4326
981.615	33.7534
984.933	33.5038
988.251	32.4094
991.567	33.2683
994.884	34.8214
998.198	38.3793
1001.51	40.2609
1004.82	40.5865
1008.13	37.7058
1011.44	36.1213
1014.75	35.545
1018.06	37.7139
1021.36	47.2252
1024.66	55.6671
1027.97	68.0376
1031.27	77.7419
1034.57	85.7417
1037.87	89.4267
1041.16	95.7853
1044.46	102.153
1047.76	105.744
1051.05	106.808
1054.34	106.697
1057.63	103.917
1060.92	98.6575
1064.21	93.4324
1067.5	85.9852
1070.78	80.1023
1074.07	71.0792
1077.35	62.6354
1080.63	48.7868
1083.91	36.3229
1087.19	24.3204
1090.47	14.0515
1093.75	11.7409
1097.03	10.9766
1100.3	15.5017
1103.57	19.2881
1106.84	19.3356
1110.11	18.0103
1113.38	15.9167
1116.65	13.6864
1119.92	11.0378
1123.19	9.87835
1126.45	7.33563
1129.71	7.05702
1132.97	6.33967
1136.23	7.94202
1139.49	6.67927
1142.75	7.83932
1146.01	7.83537
1149.26	6.60549
1152.52	7.1406
1155.77	6.67488
1159.02	5.74626
1162.27	4.20705
1165.52	4.79682
1168.77	4.84864
1172.02	5.45615
1175.26	7.24587
1178.51	8.52606
1181.75	10.4438
1184.99	12.4583
1188.23	11.57
1191.47	13.3633
1194.71	17.2582
1197.94	22.2095
1201.18	26.3826
1204.41	31.134
1207.65	35.7841
1210.88	44.6287
1214.11	50.6232
1217.34	59.5747
1220.57	67.6754
1223.79	73.8837
1227.02	79.9923
1230.24	84.2939
1233.47	89.0315
1236.69	93.6623
1239.91	95.5542
1243.13	98.2859
1246.34	99.4079
1249.56	99.8568
1252.78	99.2021
1255.99	98.0157
1259.2	97.4341
1262.42	96.6314
1265.63	94.229
1268.84	91.9053
1272.04	91.6239
1275.25	91.8007
1278.46	92.6287
1281.66	94.9925
1284.86	96.1963
1288.07	101.821
1291.27	109.285
1294.47	111.589
1297.66	117.534
1300.86	121.447
1304.06	126.263
1307.25	132.042
1310.44	136.564
1313.64	143.32
1316.83	146.45
1320.02	147.088
1323.2	149.819
1326.39	151.689
1329.58	152.965
1332.76	154.399
1335.95	154.681
1339.13	151.194
1342.31	147.405
1345.49	144.339
1348.67	141.092
1351.85	138.379
1355.02	134.213
1358.2	131.086
1361.37	123.039
1364.54	121.139
1367.71	115.034
1370.88	108.833
1374.05	104.709
1377.22	100.43
1380.39	96.4072
1383.55	94.4574
1386.72	91.2548
1389.88	87.4472
1393.04	84.0189
1396.2	80.7756
1399.36	82.0386
1402.52	85.4585
1405.68	88.1309
1408.83	92.9641
1411.98	98.8909
1415.14	107.517
1418.29	116.973
1421.44	130.45
1424.59	143.973
1427.74	156.96
1430.89	170.147
1434.03	180.318
1437.18	190.074
1440.32	198.983
1443.46	203.99
1446.6	205.978
1449.74	205.756
1452.88	204.26
1456.02	199.322
1459.16	193.808
1462.29	183.716
1465.43	169.843
1468.56	156.385
1471.69	142.838
1474.82	131.467
1477.95	118.227
1481.08	105.937
1484.2	93.1895
1487.33	85.449
1490.46	79.0041
1493.58	71.3328
1496.7	65.577
1499.82	62.7866
1502.94	60.7554
1506.06	59.2272
1509.18	57.581
1512.29	58.4012
1515.41	59.6463
1518.52	57.8646
1521.63	59.3887
1524.75	60.7123
1527.85	61.6135
1530.96	62.5732
1534.07	63.4139
1537.18	67.9312
1540.28	67.52
1543.39	70.1722
1546.49	73.1074
1549.59	75.1597
1552.69	77.7484
1555.79	78.7714
1558.89	80.6095
1561.99	82.6301
1565.08	84.1357
1568.18	85.979
1571.27	89.281
1574.37	95.5497
1577.46	101.011
1580.55	106.159
1583.64	112.246
1586.73	117.921
1589.81	118.733
1592.9	123.97
1595.98	127.093
1599.06	128.889
1602.15	126.502
1605.23	125.997
1608.31	126.037
1611.39	127.871
1614.46	128.774
1617.54	127.354
1620.61	126.216
1623.69	123.614
1626.76	125.101
1629.83	125.575
1632.9	125.869
1635.97	129.536
1639.04	131.789
1642.11	135.51
1645.17	139.886
1648.24	143.351
1651.3	147.51
1654.36	148.326
1657.42	146.633
1660.48	144.799
1663.54	142.807
1666.6	138.043
1669.66	131.578
1672.71	122.991
1675.77	113.122
1678.82	104.043
1681.87	93.6637
1684.92	82.851
1687.97	72.5267
1691.02	62.4802
1694.07	51.3452
1697.11	44.4126
1700.16	37.7326
1703.2	31.7124
1706.25	27.4631
1709.29	21.9328
1712.33	19.6548
1715.37	15.9567
1718.41	13.3189
1721.44	11.5261
1724.48	10.6935
1727.51	8.17925
1730.55	5.5049
1733.58	4.72197
1736.61	6.05103
1739.64	6.02002
1742.67	4.47139
1745.7	4.19503
1748.72	4.61616
1751.75	3.79734
1754.77	3.85104
1757.8	3.87235
1760.82	3.31924
1763.84	2.96514
1766.86	3.93706
1769.88	3.93194
1772.9	5.07984
1775.91	3.48849
1778.93	2.53907
1781.94	2.3474
1784.96	2.31669
1787.97	1.1945
1790.98	2.05503
1793.99	0.947631
1797	-0.163791
1800.01	-0.840375
1803.01	-1.12183
1806.02	-0.674148
1809.02	0.210486
1812.02	1.29679
1815.02	1.63402
1818.03	1.31718
1821.02	1.10936
1824.02	1.63112
1827.02	1.76339
1830.02	1.98044
1833.01	0.592506
1836.01	0.202957
1839	1.09874
1841.99	1.48259
1844.98	1.43199
1847.97	2.35053
1850.96	4.0078
1853.95	6.36096
1856.93	9.02288
1859.92	11.2416
1862.9	12.7386
1865.88	14.2036
1868.87	14.8149
1871.85	15.7563
1874.83	15.1884
1877.81	13.1948
1880.78	14.007
1882.53	13.4611
1885.52	13.024
1888.51	12.7285
1891.5	13.0847
1894.48	13.39
1897.47	14.7168
1900.45	14.5109
1903.43	12.7281
1906.41	12.9832
1909.39	13.0255
1912.37	13.6577
1915.35	12.7932
1918.33	13.2979
1921.3	14.8827
1924.28	15.5647
1927.25	15.5415
1930.22	12.2285
1933.19	12.3902
1936.16	9.37228
1939.13	6.87948
1942.1	5.65412
1945.07	2.29549
1948.03	-0.391006
1951	-0.236664
1953.96	1.71329
1956.92	0.729146
1959.88	1.20344
1962.84	2.3026
1965.8	4.33632
1968.76	5.84049
1971.72	6.29316
1974.67	7.10791
1977.63	7.45844
1980.58	9.25377
1983.54	10.6916
1986.49	10.4622
1989.44	12.0091
1992.39	13.8386
1995.33	13.6097
1998.28	11.0718
2001.23	10.1404
2004.17	10.206
2007.12	12.4878
2010.06	11.8278
2013	12.0585
2015.94	12.5183
2018.88	13.2239
2021.82	15.5438
2024.76	14.3459
2027.69	14.611
2030.63	12.8877
2033.56	13.6654
2036.5	14.6454
2039.43	13.9723
2042.36	14.4625
2045.29	14.2214
2048.22	13.9368
2051.15	15.3109
2054.07	15.2308
2057	15.9763
2059.92	15.9534
2062.85	14.9857
2065.77	14.1928
2068.69	13.3405
2071.61	13.7844
2074.53	15.7134
2077.45	16.9857
2080.37	16.8479
2083.28	15.9825
2086.2	15.9642
2089.11	16.1537
2092.02	15.7059
2094.94	15.0925
2097.85	12.8121
2100.76	11.8598
2103.66	10.0984
2106.57	10.9339
2109.48	7.65536
2112.38	7.24632
2115.29	7.28086
2118.19	7.89344
2121.09	7.93639
2123.99	9.71375
2126.89	8.21783
2129.79	9.2264
2132.69	9.06381
2135.59	10.8958
2138.48	11.5548
2141.38	11.8056
2144.27	12.3075
2147.17	12.8258
2150.06	14.5546
2152.95	16.2068
2155.84	16.7863
2158.73	17.7394
2161.61	17.3329
2164.5	16.7718
2167.38	17.8472
2170.27	17.3468
2173.15	18.1693
2176.03	17.8264
2178.91	16.8161
2181.8	16.5648
2184.67	16.2234
2187.55	17.0795
2190.43	16.0306
2193.3	16.3932
2196.18	16.526
2199.05	16.2991
2201.93	15.1421
2204.8	15.277
2207.67	15.9586
2210.54	18.4109
2213.41	18.5254
2216.27	18.7193
2219.14	20.8519
2222.01	21.7287
2224.87	21.7477
2227.73	21.2229
2230.6	21.2678
2233.46	22.7053
2236.32	24.2871
2239.18	23.8908
2242.03	21.7295
2244.89	21.0007
2247.75	19.6997
2250.6	19.3678
2253.46	17.0999
2256.31	16.7705
2259.16	16.6556
2262.01	16.0692
2264.86	14.4415
2267.71	14.0791
2270.56	11.6336
2273.4	14.1339
2276.25	16.3315
2279.09	17.8716
2281.94	17.9081
2284.78	19.2375
2287.62	19.0584
2290.46	20.5965
2293.3	19.9072
2296.14	21.4272
2298.98	22.6928
2301.82	24.672
2304.65	25.8942
2307.49	26.6441
2310.32	26.2664
2313.15	26.6572
2315.98	26.2546
2318.81	24.7148
2321.64	24.6116
2324.47	22.3045
2327.3	21.3934
2330.12	19.8588
2332.95	17.944
2335.77	14.75
2338.6	12.3249
2341.42	10.3645
2344.24	9.81498
2347.06	8.64427
2349.88	6.15428
2352.7	5.21117
2355.51	4.59064
2358.33	3.03437
2361.14	1.94329
2363.96	2.42161
2366.77	0.983661
2369.58	2.43834
2372.39	2.13225
2375.2	2.0357
2378.01	2.58239
2380.82	3.23959
2383.63	1.26967
2386.43	1.13389
2389.24	1.00563
2392.04	1.60084
2394.84	1.40719
2397.65	2.30295
2400.45	1.37617
2403.25	0.439008
2406.05	0.936226
2408.84	3.55326
2411.64	7.12008
2414.44	7.9174
2417.23	8.90932
2420.02	11.5073
2422.82	12.2598
2425.61	13.7612
2428.4	13.9483
2431.19	13.4187
2433.98	12.8892
2436.77	12.8526
2439.55	11.7099
2442.34	8.90538
2445.12	8.59221
2447.91	7.3448
2450.69	5.94862
2453.47	5.89555
2456.25	6.49173
2459.03	6.29538
2461.81	6.75241
2464.59	6.45033
2467.36	6.85589
2470.14	6.08408
2472.92	7.26451
2475.69	9.05284
2478.46	10.3188
2481.23	10.7702
2484	10.6992
2486.77	12.0522
2489.54	10.8748
2492.31	9.97351
2495.08	10.8733
2497.84	10.7516
2500.61	11.4696
2503.37	9.13755
2506.13	6.55779
2508.9	4.56819
2511.66	5.19703
2514.42	4.71639
2517.18	4.31961
2519.93	6.84195
2522.69	7.35099
2525.45	6.88154
2528.2	7.16757
2530.95	7.87041
2533.71	8.72586
2536.46	9.94398
2539.21	9.47827
2541.96	10.5138
2544.71	10.541
2547.46	11.5229
2550.2	11.4728
2552.95	11.6708
2555.7	11.8241
2558.44	11.9993
2561.18	12.6905
2563.93	12.8852
2566.67	12.6926
2569.41	12.1701
2572.15	11.8651
2574.88	12.2253
2577.62	12.7087
2580.36	13.3966
2583.09	14.2949
2585.83	14.5267
2588.56	14.9016
2591.29	12.529
2594.02	13.813
2596.75	13.7958
2599.48	12.9414
2602.21	11.8584
2604.94	10.8274
2607.67	10.6332
2610.39	9.57967
2613.12	8.75898
2615.84	8.62889
2618.56	8.27037
2621.28	7.93014
2624.01	7.19338
2626.72	5.99351
2629.44	5.8278
2632.16	5.31296
2634.88	7.6109
2637.59	7.33428
2640.31	7.11537
2643.02	8.10592
2645.74	7.2936
2648.45	7.24275
2651.16	6.72481
2653.87	5.71467
2656.58	5.01529
2659.29	4.50661
2661.99	4.77486
2664.7	4.19273
2667.41	2.77309
2670.11	5.54589
2672.81	6.54324
2675.51	6.67994
2678.22	7.76978
2680.92	9.74234
2683.62	9.97428
2686.31	11.693
2689.01	11.6754
2691.71	12.8696
2694.4	12.9399
2697.1	14.4783
2699.79	15.523
2702.49	15.2246
2705.18	14.8713
2707.87	17.9657
2710.56	17.9414
2713.25	17.4262
2715.94	18.4139
2718.62	18.5733
2721.31	20.1509
2723.99	20.6417
2726.68	21.0431
2729.36	21.9076
2732.04	19.9663
2734.73	19.6315
2737.41	16.6905
2740.08	16.5505
2742.76	15.4267
2745.44	13.8768
2748.12	12.0267
2750.79	10.0373
2753.47	8.3686
2756.14	9.19417
2758.81	8.13961
2761.49	7.08053
2764.16	6.62794
2766.83	6.79699
2769.5	7.94653
2772.16	9.29505
2774.83	9.8705
2777.5	10.6055
2780.16	12.6111
2782.83	14.6724
2785.49	15.5801
2788.15	15.3535
2790.82	15.1121
2793.48	11.6572
2796.14	10.0478
2798.79	8.49419
2801.45	6.1246
2804.11	4.11665
2806.76	3.7624
2809.42	2.16448
2812.07	1.86558
2814.73	2.10969
2817.38	6.39204
2820.03	11.8162
2822.68	16.8168
2825.33	25.0005
2827.98	33.2714
2830.63	43.956
2833.27	53.0044
2835.92	64.5392
2838.56	77.981
2841.21	93.7971
2843.85	110.244
2846.49	127.848
2849.13	148.523
2851.77	167.912
2854.41	188.883
2857.05	208.027
2859.69	227.266
2862.32	244.965
2864.96	259.706
2867.59	272.868
2870.23	284.697
2872.86	294.355
2875.49	302.602
2878.12	311.119
2880.75	318.694
2883.38	325.003
2886.01	330.339
2888.63	334.439
2891.26	340.842
2893.89	344.396
2896.51	348.534
2899.13	357.062
2901.76	369.919
2904.38	381.595
2907	396.694
2909.62	414.808
2912.24	435.639
2914.85	457.177
2917.47	473.955
2920.09	489.119
2922.7	501.142
2925.32	508.621
2927.93	511.181
2930.54	510.793
2933.15	505.089
2935.76	496.745
2938.37	485.487
2940.98	470.862
2943.59	455.488
2946.2	436.295
2948.8	416.858
2951.41	396.801
2954.01	375.729
2956.62	355.498
2959.22	335.615
2961.82	317.786
2964.42	301.318
2967.02	284.303
2969.62	269.756
2972.22	256.538
2974.81	245.403
2977.41	232.016
2980	216.258
2982.6	202.082
2985.19	185.928
2987.78	170.304
2990.38	152.784
2992.97	136.294
2995.56	121.991
2998.14	106.11
3000.73	91.1906
3003.32	78.5971
3005.91	64.6066
3008.49	54.3497
3011.07	42.7665
3013.66	33.9103
3016.24	26.8011
3018.82	21.2623
3021.4	15.7407
3023.98	10.6681
3026.56	7.43979
3029.14	3.76724
3031.71	3.18187
3034.29	2.28868
3036.87	1.96372
3039.44	3.60856
3042.01	3.47889
3044.59	2.60243
3047.16	3.86009
3049.73	4.08993
3052.3	5.51126
3054.87	7.56203
3057.43	9.60652
3060	9.23351
3062.57	7.85472
3065.13	8.08981
3067.7	7.12399
3070.26	7.03803
3072.82	5.95527
3075.39	5.94295
3077.95	6.61044
3080.51	7.64425
3083.07	8.1854
3085.63	7.02609
3088.18	8.46471
3090.74	9.01062
3093.29	9.96597
3095.85	10.9221
3098.4	10.3412
3100.95	10.4394
3103.51	10.4137
3106.06	10.7706
3108.61	13.8281
3111.16	15.5693
3113.71	18.6442
3116.25	21.7779
3118.8	22.9754
3121.35	24.8574
3123.89	26.4617
3126.44	29.1128
3128.98	31.809
3131.52	35.5738
3134.06	38.5271
3136.6	43.9931
3139.14	47.8216
3141.68	51.5584
3144.22	54.7271
3146.76	57.1769
3149.29	57.8879