File: data/Raman/poly_smoothed/Mb_00_13_35_1x_45s_532 nm_x100_100%_600 gr_mm_01.txt
#Acq. time (s)=	45
#Accumulations=	2
#Range (cm-¹)=	200...3150
#Windows=	2
#Auto scanning=	Off
#Autofocus=	Off
#Macrospot=	Off
#AutoExposure=	Off
#Spike filter=	Multiple accum.
#Delay time (s)=	0
#Binning=	1
#Readout mode=	Signal
#DeNoise=	Off
#ICS correction=	On
#Dark correction=	Off
#Inst. Process=	Off
#Detector Gain=	Best Dynamic Range
#Detector ADC=	20 kHz
#Detector temperature (°C)=	-69.85
#Instrument=	LabRAM HR Evol
#Detector=	Synapse
#Objective=	x100
#Grating=	600 gr/mm
#ND Filter=	100%
#Laser (nm)=	532
#Hole=	100.021
#Range=	Auto
#Laser Pol.=	No
#Raman. Pol.=	No
#Laser Pol. (°)=	-0.0007625
#Raman Pol. (°)=	89.9995
#Collection=	Microscope
#StageXY=	Marzhauser
#StageZ=	Marzhauser
#X (µm)=	-1026.3
#Y (µm)=	-2896
#Z (µm)=	528.75
#Full time(mm:ss)=	3:18
#Project=
#Sample=
#Site=
#Title=	Mb_00_13_35_2x_45s_532 nm_x100_100%_600 gr_mm
#Remark=
#Date=	06.07.2022 12:33
#Acquired=	06.07.2022 12:33:38
#Base:Fit=	10.08.2022 10:16:56
#Base:Sub=	10.08.2022 10:17:24
#Filter:Polynom=	16.08.2022 10:36:38
#AxisType[0]=Intens
#AxisUnit[0]=Cnt
#AxisType[1]=Spectr
#AxisUnit[1]=1/cm
200.398	17.8525
204.027	8.91959
207.657	3.66874
211.283	1.41356
214.909	1.46806
218.533	4.95803
222.157	11.3409
225.777	17.7023
229.396	28.7765
233.016	36.9581
236.632	45.0718
240.247	50.814
243.86	55.5911
247.474	60.3411
251.085	64.4333
254.694	67.2764
258.301	71.1323
261.908	72.0914
265.513	71.1427
269.116	68.1488
272.718	63.9112
276.319	58.1697
279.918	51.8513
283.516	45.5146
287.113	39.9594
290.708	35.3187
294.302	30.7303
297.894	25.5489
301.485	22.2966
305.073	19.3785
308.661	19.2318
312.247	18.6881
315.833	17.7829
319.415	17.5187
322.997	14.7337
326.579	12.4203
330.156	12.0773
333.735	12.2673
337.31	10.7926
340.885	8.12474
344.458	7.34179
348.03	6.66126
351.6	5.85455
355.17	4.15471
358.737	3.80949
362.304	3.79824
365.868	4.94998
369.431	10.0114
372.994	11.3628
376.554	17.2748
380.112	21.2585
383.669	28.9069
387.225	36.463
390.781	45.1451
394.334	52.8025
397.885	59.1971
401.436	62.0019
404.984	66.2541
408.532	68.6581
412.078	69.8631
415.623	71.3299
419.166	71.7106
422.708	67.0044
426.248	62.2573
429.788	56.4766
433.326	50.6011
436.86	44.7194
440.395	37.9367
443.929	30.5928
447.461	22.806
450.99	16.3164
454.52	10.905
458.048	7.99802
461.573	6.12503
465.099	5.20119
468.623	6.17332
472.144	8.49226
475.666	10.0714
479.184	12.1023
482.703	13.0019
486.218	14.4085
489.734	17.8987
493.247	19.1434
496.759	20.5477
500.271	23.1593
503.779	24.2676
507.287	25.0409
510.795	27.3717
514.299	29.2384
517.803	29.3454
521.305	30.6322
524.805	31.2588
528.307	30.3714
531.805	30.0953
535.301	30.3604
538.797	29.3767
542.291	29.3745
545.783	28.682
549.275	26.1403
552.765	25.0173
556.253	23.9774
559.738	21.9014
563.224	19.997
566.709	18.8786
570.192	17.1036
573.674	15.4175
577.153	12.9003
580.632	12.1447
584.11	11.0331
587.587	10.5674
591.06	11.1987
594.534	11.3082
598.005	8.76227
601.476	8.25588
604.944	7.49946
608.413	6.63736
611.878	4.77266
615.344	4.87975
618.807	4.88219
622.27	4.7698
625.73	5.01948
629.189	4.19251
632.648	6.97526
636.105	7.53243
639.559	11.3585
643.013	12.2975
646.467	14.9765
649.918	15.7511
653.368	17.0799
656.816	16.5875
660.263	19.0984
663.708	19.911
667.153	20.8326
670.596	21.1823
674.037	21.7227
677.478	22.4004
680.917	21.0544
684.355	19.5792
687.791	19.3847
691.224	17.0602
694.658	15.356
698.091	15.2544
701.522	16.6331
704.95	16.7645
708.379	18.5843
711.806	18.9314
715.23	21.5595
718.655	23.6013
722.078	25.3189
725.498	26.4578
728.919	26.8711
732.337	27.4018
735.755	25.603
739.17	28.2832
742.584	30.32
745.998	32.3876
749.409	33.5612
752.819	36.1883
756.23	38.6155
759.637	40.8121
763.043	44.3604
766.448	47.2977
769.853	48.4395
773.255	50.7663
776.656	53.8122
780.056	57.0929
783.454	59.369
786.851	61.2235
790.247	63.0186
793.641	65.4481
797.034	67.3316
800.426	69.6736
803.817	69.0559
807.206	68.8121
810.592	66.7248
813.979	65.419
817.364	64.0157
820.748	63.1082
824.129	62.1925
827.511	59.3916
830.891	55.6618
834.269	55.6095
837.646	53.0245
841.023	51.4125
844.396	49.7991
847.77	48.1364
851.141	43.8221
854.513	40.3102
857.881	38.5079
861.248	36.8115
864.616	33.6842
867.98	32.3036
871.343	31.6164
874.707	30.5446
878.068	29.7084
881.428	27.629
884.786	26.0886
888.143	24.2092
891.498	22.6233
894.855	21.3312
898.208	19.8836
901.56	17.0335
904.91	18.9865
908.26	18.8019
911.608	20.1112
914.955	18.9198
918.298	20.7426
921.643	20.8668
924.986	20.9504
928.328	20.7134
931.668	19.4424
935.006	20.469
938.344	22.1784
941.681	21.5359
945.014	22.094
948.349	21.1724
951.682	20.1183
955.012	18.5258
958.343	16.7509
961.67	17.4015
964.998	18.3178
968.323	19.7808
971.649	19.0106
974.971	20.6234
978.293	20.8429
981.615	21.8102
984.933	24.888
988.251	25.579
991.567	25.182
994.884	26.7705
998.198	27.3173
1001.51	28.9183
1004.82	25.9449
1008.13	26.1355
1011.44	25.847
1014.75	25.6068
1018.06	28.8595
1021.36	32.5398
1024.66	38.743
1027.97	43.5697
1031.27	49.3357
1034.57	52.4415
1037.87	54.1101
1041.16	58.2587
1044.46	60.1688
1047.76	62.055
1051.05	61.1764
1054.34	61.6453
1057.63	59.7926
1060.92	56.7944
1064.21	53.8436
1067.5	48.7617
1070.78	44.5071
1074.07	37.468
1077.35	31.2775
1080.63	23.0934
1083.91	15.9368
1087.19	7.65432
1090.47	4.19126
1093.75	1.55487
1097.03	2.57882
1100.3	4.01809
1103.57	4.20418
1106.84	5.25223
1110.11	4.89273
1113.38	3.73608
1116.65	3.17506
1119.92	2.89293
1123.19	4.59117
1126.45	4.89989
1129.71	5.83823
1132.97	6.62871
1136.23	7.82122
1139.49	8.12178
1142.75	8.28258
1146.01	8.83778
1149.26	7.18409
1152.52	7.90457
1155.77	7.09205
1159.02	5.80502
1162.27	6.91337
1165.52	6.19425
1168.77	5.99589
1172.02	6.82348
1175.26	7.22903
1178.51	5.31647
1181.75	3.69712
1184.99	1.35846
1188.23	3.17794
1191.47	2.46985
1194.71	3.8259
1197.94	5.10459
1201.18	6.64661
1204.41	8.61715
1207.65	11.5337
1210.88	16.0092
1214.11	18.7037
1217.34	24.0856
1220.57	27.6656
1223.79	29.8652
1227.02	32.8567
1230.24	35.2464
1233.47	38.2338
1236.69	40.1253
1239.91	42.4568
1243.13	44.176
1246.34	42.9242
1249.56	43.3638
1252.78	42.4596
1255.99	42.2554
1259.2	40.9749
1262.42	39.08
1265.63	38.9356
1268.84	38.0358
1272.04	37.5767
1275.25	39.5583
1278.46	41.4042
1281.66	42.8605
1284.86	46.8916
1288.07	50.2904
1291.27	54.7374
1294.47	58.5549
1297.66	60.6161
1300.86	61.2694
1304.06	64.0279
1307.25	66.1405
1310.44	67.8637
1313.64	70.6999
1316.83	72.4053
1320.02	72.2054
1323.2	71.2442
1326.39	70.7904
1329.58	69.8911
1332.76	69.6231
1335.95	69.3
1339.13	66.8679
1342.31	65.5971
1345.49	65.4889
1348.67	63.9705
1351.85	64.5799
1355.02	63.6664
1358.2	63.2324
1361.37	63.7521
1364.54	63.5173
1367.71	61.3731
1370.88	59.9286
1374.05	57.6094
1377.22	55.9102
1380.39	55.3351
1383.55	55.7525
1386.72	52.6969
1389.88	50.8496
1393.04	49.9841
1396.2	44.2041
1399.36	43.3687
1402.52	45.094
1405.68	46.1309
1408.83	49.106
1411.98	51.6596
1415.14	56.9902
1418.29	59.882
1421.44	65.7217
1424.59	72.6408
1427.74	79.615
1430.89	84.0899
1434.03	91.4454
1437.18	95.6662
1440.32	100.292
1443.46	103.29
1446.6	104.393
1449.74	103.776
1452.88	100.768
1456.02	99.0373
1459.16	95.6411
1462.29	89.9125
1465.43	84.8996
1468.56	78.8832
1471.69	73.3275
1474.82	67.6997
1477.95	63.7839
1481.08	58.5193
1484.2	54.633
1487.33	49.8691
1490.46	45.2351
1493.58	41.678
1496.7	38.7925
1499.82	36.9666
1502.94	35.9564
1506.06	34.4211
1509.18	35.141
1512.29	36.5585
1515.41	36.5362
1518.52	37.6889
1521.63	36.881
1524.75	35.7546
1527.85	35.7799
1530.96	36.7317
1534.07	40.5523
1537.18	41.6388
1540.28	43.7575
1543.39	45.698
1546.49	47.0088
1549.59	46.8812
1552.69	48.1483
1555.79	48.5264
1558.89	49.7781
1561.99	49.1904
1565.08	50.283
1568.18	50.224
1571.27	51.8599
1574.37	53.0427
1577.46	54.0106
1580.55	56.339
1583.64	58.3954
1586.73	61.1547
1589.81	63.7967
1592.9	64.1408
1595.98	65.2288
1599.06	62.7738
1602.15	62.8191
1605.23	62.4247
1608.31	62.9292
1611.39	65.2019
1614.46	63.7866
1617.54	62.2508
1620.61	60.9848
1623.69	58.7341
1626.76	57.5142
1629.83	56.5561
1632.9	56.4624
1635.97	56.8404
1639.04	56.8669
1642.11	55.6376
1645.17	56.4121
1648.24	54.959
1651.3	56.1125
1654.36	57.3045
1657.42	57.9838
1660.48	56.771
1663.54	55.5796
1666.6	54.0457
1669.66	50.4769
1672.71	46.491
1675.77	43.5931
1678.82	40.9616
1681.87	38.8106
1684.92	36.4395
1687.97	32.2288
1691.02	27.9862
1694.07	24.2146
1697.11	20.8725
1700.16	17.3139
1703.2	15.3553
1706.25	12.4497
1709.29	8.73629
1712.33	6.71334
1715.37	4.57282
1718.41	4.27969
1721.44	4.35863
1724.48	4.6222
1727.51	5.45505
1730.55	5.82379
1733.58	5.40292
1736.61	5.00972
1739.64	5.09212
1742.67	5.5587
1745.7	5.45654
1748.72	5.77291
1751.75	6.5457
1754.77	7.83484
1757.8	8.11305
1760.82	8.45002
1763.84	8.84599
1766.86	9.10304
1769.88	8.83331
1772.9	7.86958
1775.91	7.16523
1778.93	6.16954
1781.94	6.69374
1784.96	6.26606
1787.97	6.41377
1790.98	6.85203
1793.99	7.21729
1797	7.42509
1800.01	7.48745
1803.01	6.67195
1806.02	6.27111
1809.02	7.28316
1812.02	7.09979
1815.02	7.42112
1818.03	8.08099
1821.02	8.35551
1824.02	8.49179
1827.02	7.15784
1830.02	6.75314
1833.01	6.718
1836.01	6.59913
1839	6.36005
1841.99	6.48051
1844.98	5.99934
1847.97	6.21832
1850.96	6.15667
1853.95	5.5286
1856.93	5.93417
1859.92	4.88309
1862.9	3.82146
1865.88	3.55748
1868.87	4.4058
1871.85	5.16967
1874.83	4.31131
1877.81	5.29392
1880.78	5.82466
1882.53	6.42482
1885.52	7.27801
1888.51	7.87854
1891.5	8.66078
1894.48	8.64685
1897.47	8.83498
1900.45	9.26864
1903.43	10.6125
1906.41	9.11127
1909.39	8.28046
1912.37	9.04662
1915.35	8.95293
1918.33	7.62594
1921.3	6.86574
1924.28	7.09396
1927.25	7.05514
1930.22	6.86268
1933.19	7.74304
1936.16	8.36837
1939.13	9.81431
1942.1	9.37742
1945.07	8.5265
1948.03	8.85889
1951	9.38349
1953.96	8.35266
1956.92	7.83301
1959.88	7.89305
1962.84	7.70059
1965.8	8.47066
1968.76	9.09135
1971.72	9.15866
1974.67	8.49356
1977.63	6.96602
1980.58	6.7018
1983.54	7.66688
1986.49	6.80051
1989.44	7.03033
1992.39	6.74742
1995.33	8.34808
1998.28	9.20905
2001.23	8.74285
2004.17	9.1893
2007.12	9.41184
2010.06	9.94244
2013	8.49553
2015.94	8.79073
2018.88	8.82285
2021.82	7.88266
2024.76	7.45055
2027.69	7.49118
2030.63	8.29868
2033.56	8.20696
2036.5	9.01835
2039.43	8.97343
2042.36	8.57125
2045.29	8.72643
2048.22	8.89692
2051.15	8.30276
2054.07	7.80868
2057	7.28628
2059.92	8.7013
2062.85	8.73878
2065.77	8.71564
2068.69	8.32104
2071.61	7.67062
2074.53	7.3469
2077.45	8.96816
2080.37	9.01968
2083.28	9.13603
2086.2	8.58779
2089.11	9.4833
2092.02	9.73742
2094.94	8.65784
2097.85	9.49293
2100.76	9.30127
2103.66	7.6252
2106.57	7.40793
2109.48	6.62772
2112.38	5.79129
2115.29	5.38791
2118.19	5.92414
2121.09	5.40415
2123.99	5.17236
2126.89	4.85284
2129.79	5.74371
2132.69	6.56221
2135.59	7.34704
2138.48	6.54417
2141.38	5.91457
2144.27	5.70435
2147.17	6.0563
2150.06	6.22854
2152.95	5.12114
2155.84	6.49438
2158.73	7.12297
2161.61	7.30556
2164.5	7.31787
2167.38	8.04187
2170.27	8.76236
2173.15	7.65141
2176.03	7.35543
2178.91	9.96437
2181.8	9.42054
2184.67	10.1538
2187.55	9.61388
2190.43	10.1646
2193.3	9.72864
2196.18	9.20662
2199.05	9.53717
2201.93	9.05571
2204.8	9.51164
2207.67	8.73877
2210.54	8.71198
2213.41	8.53363
2216.27	9.84642
2219.14	11.5968
2222.01	12.2924
2224.87	13.2023
2227.73	13.0941
2230.6	13.9536
2233.46	14.6816
2236.32	14.744
2239.18	13.1368
2242.03	12.4075
2244.89	12.994
2247.75	12.7982
2250.6	12.7428
2253.46	11.9882
2256.31	11.6924
2259.16	12.4105
2262.01	11.7976
2264.86	10.5494
2267.71	10.4552
2270.56	10.9511
2273.4	12.1092
2276.25	11.5852
2279.09	11.5494
2281.94	11.5039
2284.78	11.5178
2287.62	11.9473
2290.46	10.1088
2293.3	8.52632
2296.14	8.18456
2298.98	8.40049
2301.82	7.69181
2304.65	7.08073
2307.49	5.76499
2310.32	6.73481
2313.15	6.6086
2315.98	6.03573
2318.81	5.73534
2321.64	5.87036
2324.47	4.4947
2327.3	5.49027
2330.12	5.71883
2332.95	5.49234
2335.77	6.68545
2338.6	7.73769
2341.42	7.335
2344.24	7.65341
2347.06	7.39769
2349.88	5.93376
2352.7	5.36948
2355.51	5.62139
2358.33	4.91828
2361.14	4.46935
2363.96	6.13694
2366.77	6.24128
2369.58	5.18111
2372.39	5.02495
2375.2	4.35526
2378.01	4.87503
2380.82	5.99982
2383.63	4.93768
2386.43	3.76882
2389.24	3.97025
2392.04	2.44588
2394.84	2.66411
2397.65	3.11063
2400.45	3.23382
2403.25	4.23061
2406.05	5.52558
2408.84	5.08057
2411.64	6.25484
2414.44	7.15571
2417.23	5.83658
2420.02	5.4908
2422.82	6.93086
2425.61	7.76977
2428.4	7.925
2431.19	8.52137
2433.98	8.40906
2436.77	7.64115
2439.55	5.98493
2442.34	8.26679
2445.12	8.02328
2447.91	8.13112
2450.69	6.54521
2453.47	5.56179
2456.25	4.69778
2459.03	3.91643
2461.81	3.29736
2464.59	2.27974
2467.36	1.64136
2470.14	2.54354
2472.92	2.96623
2475.69	2.4828
2478.46	1.77563
2481.23	0.905856
2484	0.267876
2486.77	-1.0771
2489.54	-1.53796
2492.31	-0.707623
2495.08	0.148081
2497.84	0.362035
2500.61	0.370149
2503.37	0.638845
2506.13	0.419418
2508.9	0.307936
2511.66	1.14423
2514.42	0.492246
2517.18	0.789647
2519.93	2.31226
2522.69	3.44373
2525.45	2.91482
2528.2	2.54855
2530.95	3.9507
2533.71	4.48997
2536.46	4.47692
2539.21	5.07208
2541.96	5.44753
2544.71	4.92482
2547.46	4.29358
2550.2	4.13021
2552.95	3.73336
2555.7	3.94105
2558.44	4.24298
2561.18	4.60799
2563.93	4.50058
2566.67	4.63894
2569.41	4.96598
2572.15	5.03132
2574.88	5.68215
2577.62	5.82595
2580.36	7.45245
2583.09	8.06376
2585.83	8.41244
2588.56	8.97295
2591.29	6.99056
2594.02	7.42391
2596.75	7.92365
2599.48	8.46545
2602.21	9.05804
2604.94	9.17214
2607.67	8.64032
2610.39	10.338
2613.12	8.7845
2615.84	8.38196
2618.56	8.48193
2621.28	8.07689
2624.01	6.66003
2626.72	6.18108
2629.44	4.92033
2632.16	5.95323
2634.88	6.91446
2637.59	6.67837
2640.31	6.50242
2643.02	7.67041
2645.74	7.23031
2648.45	7.34826
2651.16	7.71091
2653.87	6.97771
2656.58	7.23679
2659.29	7.25269
2661.99	7.58404
2664.7	9.60635
2667.41	9.46755
2670.11	10.6136
2672.81	11.0891
2675.51	12.1844
2678.22	12.8812
2680.92	11.9676
2683.62	12.0756
2686.31	12.1169
2689.01	11.8455
2691.71	11.1394
2694.4	12.2744
2697.1	12.111
2699.79	13.7554
2702.49	13.5617
2705.18	14.1006
2707.87	14.4625
2710.56	14.2456
2713.25	14.1584
2715.94	14.2268
2718.62	14.6079
2721.31	15.6272
2723.99	14.6884
2726.68	15.2095
2729.36	14.6138
2732.04	14.6223
2734.73	13.5769
2737.41	12.9047
2740.08	11.9569
2742.76	10.6362
2745.44	9.75123
2748.12	8.63478
2750.79	7.1134
2753.47	6.68081
2756.14	6.00042
2758.81	4.54394
2761.49	4.65707
2764.16	3.3861
2766.83	3.58804
2769.5	3.39756
2772.16	3.8302
2774.83	3.51597
2777.5	3.36137
2780.16	3.15935
2782.83	2.90968
2785.49	2.82275
2788.15	2.86161
2790.82	2.22416
2793.48	1.51386
2796.14	0.477496
2798.79	-0.455306
2801.45	-0.85365
2804.11	0.187054
2806.76	-0.49321
2809.42	-0.747025
2812.07	-1.58831
2814.73	1.05046
2817.38	5.64053
2820.03	9.56066
2822.68	15.7524
2825.33	21.3676
2827.98	28.61
2830.63	36.0273
2833.27	42.7488
2835.92	51.4599
2838.56	61.0666
2841.21	69.8395
2843.85	78.5223
2846.49	87.48
2849.13	97.9618
2851.77	109.271
2854.41	118.533
2857.05	128.354
2859.69	136.872
2862.32	145.659
2864.96	153.083
2867.59	160.549
2870.23	165.602
2872.86	170.554
2875.49	174.978
2878.12	179.311
2880.75	185.104
2883.38	188.079
2886.01	192.08
2888.63	194.833
2891.26	197.209
2893.89	199.322
2896.51	201.964
2899.13	207.054
2901.76	210.563
2904.38	215.252
2907	219.059
2909.62	225.092
2912.24	231.767
2914.85	239.206
2917.47	243.477
2920.09	247.84
2922.7	250.506
2925.32	252.756
2927.93	253.174
2930.54	252.313
2933.15	249.288
2935.76	244.683
2938.37	238.053
2940.98	232.196
2943.59	224.603
2946.2	216.507
2948.8	207.688
2951.41	198.163
2954.01	187.862
2956.62	178.697
2959.22	168.183
2961.82	159.998
2964.42	150.402
2967.02	141.578
2969.62	132.626
2972.22	123.315
2974.81	116.859
2977.41	107.708
2980	99.1055
2982.6	90.3035
2985.19	83.446
2987.78	74.2787
2990.38	66.7669
2992.97	59.6102
2995.56	51.6719
2998.14	44.984
3000.73	38.5714
3003.32	33.1272
3005.91	27.1784
3008.49	22.0052
3011.07	16.5053
3013.66	13.4193
3016.24	9.93674
3018.82	7.46502
3021.4	4.52088
3023.98	3.21148
3026.56	2.76101
3029.14	2.01575
3031.71	1.49793
3034.29	0.4752
3036.87	1.91111
3039.44	3.14574
3042.01	3.4076
3044.59	3.50822
3047.16	5.73667
3049.73	7.08479
3052.3	9.03698
3054.87	11.2614
3057.43	13.6519
3060	14.795
3062.57	16.3545
3065.13	17.9604
3067.7	19.1258
3070.26	19.8971
3072.82	20.7349
3075.39	19.174
3077.95	19.117
3080.51	18.8872
3083.07	18.8543
3085.63	19.3432
3088.18	20.1518
3090.74	20.8333
3093.29	20.8759
3095.85	20.7131
3098.4	21.9497
3100.95	22.7611
3103.51	22.6189
3106.06	23.1149
3108.61	25.1392
3111.16	27.8519
3113.71	31.6305
3116.25	35.0649
3118.8	37.4754
3121.35	40.3845
3123.89	43.85
3126.44	46.5453
3128.98	48.4978
3131.52	51.7812
3134.06	53.8638
3136.6	55.7841
3139.14	58.0761
3141.68	61.224
3144.22	63.8655
3146.76	66.8281
3149.29	67.6087