File: data/Raman/poly_smoothed/Mb_00_13_02_1x_45s_532 nm_x100_100%_600 gr_mm_01.txt
#Acq. time (s)=	45
#Accumulations=	2
#Range (cm-¹)=	200...3150
#Windows=	2
#Auto scanning=	Off
#Autofocus=	Off
#Macrospot=	Off
#AutoExposure=	Off
#Spike filter=	Multiple accum.
#Delay time (s)=	0
#Binning=	1
#Readout mode=	Signal
#DeNoise=	Off
#ICS correction=	On
#Dark correction=	Off
#Inst. Process=	Off
#Detector Gain=	Best Dynamic Range
#Detector ADC=	20 kHz
#Detector temperature (°C)=	-69.85
#Instrument=	LabRAM HR Evol
#Detector=	Synapse
#Objective=	x100
#Grating=	600 gr/mm
#ND Filter=	100%
#Laser (nm)=	532
#Hole=	100.021
#Range=	Auto
#Laser Pol.=	No
#Raman. Pol.=	No
#Laser Pol. (°)=	-0.0007625
#Raman Pol. (°)=	89.9995
#Collection=	Microscope
#StageXY=	Marzhauser
#StageZ=	Marzhauser
#X (µm)=	-977.2
#Y (µm)=	-2935.3
#Z (µm)=	527.55
#Full time(mm:ss)=	3:18
#Project=
#Sample=
#Site=
#Title=	Mb_00_13_02_2x_45s_532 nm_x100_100%_600 gr_mm
#Remark=
#Date=	06.07.2022 09:50
#Acquired=	06.07.2022 09:50:24
#Base:Fit=	10.08.2022 10:16:36
#Base:Fit=	10.08.2022 10:16:56
#Base:Sub=	10.08.2022 10:17:24
#Filter:Polynom=	16.08.2022 10:36:38
#AxisType[0]=Intens
#AxisUnit[0]=Cnt
#AxisType[1]=Spectr
#AxisUnit[1]=1/cm
200.398	19.6618
204.027	12.7826
207.657	5.87679
211.283	1.62491
214.909	0.453936
218.533	6.5158
222.157	11.526
225.777	18.1678
229.396	27.2949
233.016	35.139
236.632	41.9215
240.247	47.7875
243.86	52.275
247.474	57.4773
251.085	63.3885
254.694	70.0425
258.301	73.9832
261.908	74.9435
265.513	75.626
269.116	72.3383
272.718	68.2109
276.319	61.6015
279.918	57.0253
283.516	48.0003
287.113	39.5984
290.708	31.6662
294.302	24.0656
297.894	16.9648
301.485	13.3308
305.073	10.0113
308.661	9.17075
312.247	5.4137
315.833	4.30959
319.415	3.76773
322.997	1.77795
326.579	1.15434
330.156	1.87969
333.735	3.36334
337.31	4.03777
340.885	4.08759
344.458	2.28242
348.03	1.2408
351.6	1.31068
355.17	-0.752702
358.737	-2.28228
362.304	-0.892756
365.868	1.06139
369.431	3.03072
372.994	6.72217
376.554	11.0881
380.112	16.7396
383.669	26.3489
387.225	38.486
390.781	48.7278
394.334	59.6834
397.885	67.8124
401.436	72.9646
404.984	79.6993
408.532	82.1798
412.078	84.4368
415.623	83.2501
419.166	80.9332
422.708	77.8883
426.248	73.1061
429.788	66.9788
433.326	59.6847
436.86	50.6004
440.395	40.8185
443.929	33.216
447.461	24.937
450.99	19.3778
454.52	11.4642
458.048	7.08568
461.573	5.24784
465.099	4.215
468.623	6.42936
472.144	10.9684
475.666	13.3764
479.184	16.0904
482.703	18.2361
486.218	18.6628
489.734	20.1882
493.247	21.926
496.759	25.1933
500.271	28.1496
503.779	30.6447
507.287	35.124
510.795	38.3581
514.299	40.737
517.803	40.9855
521.305	40.5834
524.805	43.7011
528.307	43.3735
531.805	44.0598
535.301	43.7778
538.797	43.2688
542.291	42.0768
545.783	40.3549
549.275	38.1268
552.765	35.6895
556.253	35.5864
559.738	32.9254
563.224	30.3401
566.709	26.7956
570.192	24.1317
573.674	20.2737
577.153	18.2783
580.632	16.0619
584.11	14.0297
587.587	10.7284
591.06	7.04378
594.534	4.22865
598.005	2.36387
601.476	1.97928
604.944	2.124
608.413	3.46387
611.878	4.79948
615.344	3.99799
618.807	5.08336
622.27	6.17691
625.73	8.20601
629.189	9.90005
632.648	12.6235
636.105	15.2296
639.559	17.7434
643.013	20.0091
646.467	15.7957
649.918	17.4558
653.368	21.4953
656.816	24.4936
660.263	27.066
663.708	29.6528
667.153	30.3546
670.596	31.1597
674.037	32.8393
677.478	34.829
680.917	35.3965
684.355	34.8493
687.791	34.8087
691.224	34.3249
694.658	32.0139
698.091	30.2919
701.522	27.4204
704.95	25.9294
708.379	28.222
711.806	29.1043
715.23	26.1614
718.655	24.1911
722.078	20.1789
725.498	16.0144
728.919	11.542
732.337	10.4518
735.755	16.6495
739.17	17.0879
742.584	19.4333
745.998	21.3371
749.409	24.3482
752.819	27.9078
756.23	32.5088
759.637	34.7129
763.043	36.1276
766.448	39.0024
769.853	40.4708
773.255	41.1166
776.656	42.1194
780.056	44.7156
783.454	47.6371
786.851	49.7864
790.247	52.2828
793.641	54.204
797.034	55.5879
800.426	54.3864
803.817	51.4697
807.206	51.1726
810.592	51.7822
813.979	52.4559
817.364	53.6453
820.748	55.4751
824.129	54.4703
827.511	56.6885
830.891	56.698
834.269	56.5035
837.646	56.6353
841.023	55.3093
844.396	53.4283
847.77	52.1009
851.141	47.104
854.513	46.1208
857.881	41.8947
861.248	40.6151
864.616	38.0737
867.98	36.2778
871.343	31.708
874.707	28.2417
878.068	27.7466
881.428	25.3241
884.786	22.4811
888.143	22.2638
891.498	22.1023
894.855	23.8873
898.208	22.8936
901.56	24.3089
904.91	23.6422
908.26	25.8294
911.608	26.3469
914.955	29.1855
918.298	33.2045
921.643	35.8593
924.986	34.2979
928.328	34.3145
931.668	34.5692
935.006	35.7537
938.344	36.8614
941.681	35.0446
945.014	35.383
948.349	32.4287
951.682	31.7931
955.012	31.5658
958.343	31.7111
961.67	31.8937
964.998	34.1554
968.323	37.9347
971.649	40.7023
974.971	42.7578
978.293	45.5585
981.615	49.2551
984.933	50.0958
988.251	52.7007
991.567	54.7694
994.884	56.9325
998.198	58.542
1001.51	58.846
1004.82	57.3708
1008.13	56.1383
1011.44	54.8491
1014.75	55.0342
1018.06	57.634
1021.36	61.7438
1024.66	68.7332
1027.97	76.9601
1031.27	82.9363
1034.57	89.4332
1037.87	94.878
1041.16	100.896
1044.46	106.733
1047.76	109.055
1051.05	111.54
1054.34	109.562
1057.63	107.849
1060.92	105.337
1064.21	100.012
1067.5	93.1694
1070.78	85.0523
1074.07	74.8581
1077.35	65.1034
1080.63	53.5422
1083.91	44.3978
1087.19	35.6895
1090.47	27.3153
1093.75	22.3466
1097.03	23.576
1100.3	22.8301
1103.57	24.7449
1106.84	26.7166
1110.11	27.3223
1113.38	25.839
1116.65	25.5802
1119.92	24.1284
1123.19	24.0974
1126.45	22.2867
1129.71	22.6057
1132.97	22.0152
1136.23	20.2176
1139.49	19.7583
1142.75	20.1063
1146.01	18.099
1149.26	16.2337
1152.52	13.3539
1155.77	10.2617
1159.02	8.56892
1162.27	7.62995
1165.52	7.62769
1168.77	8.24709
1172.02	7.62893
1175.26	8.12659
1178.51	9.01242
1181.75	10.7696
1184.99	10.3
1188.23	13.0162
1191.47	15.6183
1194.71	17.0783
1197.94	21.2364
1201.18	26.3377
1204.41	30.7856
1207.65	34.6229
1210.88	41.4089
1214.11	47.2783
1217.34	54.9061
1220.57	62.0599
1223.79	67.207
1227.02	70.8154
1230.24	73.9928
1233.47	76.5218
1236.69	76.9733
1239.91	78.3433
1243.13	79.73
1246.34	80.1989
1249.56	78.9307
1252.78	77.6984
1255.99	76.0811
1259.2	75.4058
1262.42	74.5923
1265.63	73.5519
1268.84	72.3891
1272.04	71.3508
1275.25	71.1084
1278.46	74.2834
1281.66	75.0053
1284.86	78.731
1288.07	81.8429
1291.27	85.6177
1294.47	90.3798
1297.66	93.0002
1300.86	97.265
1304.06	100.878
1307.25	106.554
1310.44	110.171
1313.64	112.273
1316.83	115.472
1320.02	117.21
1323.2	118.678
1326.39	116.937
1329.58	116.41
1332.76	115.696
1335.95	112.211
1339.13	110.133
1342.31	106.559
1345.49	102.345
1348.67	99.8386
1351.85	97.6202
1355.02	95.2776
1358.2	92.1496
1361.37	90.7138
1364.54	88.8817
1367.71	85.1422
1370.88	81.8125
1374.05	80.369
1377.22	79.6414
1380.39	79.3704
1383.55	78.219
1386.72	78.701
1389.88	79.2037
1393.04	77.6683
1396.2	77.2596
1399.36	74.5472
1402.52	74.3077
1405.68	76.0207
1408.83	77.9058
1411.98	82.7256
1415.14	88.3257
1418.29	96.6248
1421.44	105.432
1424.59	115.575
1427.74	125.385
1430.89	132.872
1434.03	141.92
1437.18	149.728
1440.32	156.776
1443.46	158.206
1446.6	159.656
1449.74	158.856
1452.88	156.882
1456.02	154.285
1459.16	147.116
1462.29	137.439
1465.43	128.494
1468.56	116.078
1471.69	103.491
1474.82	92.4308
1477.95	80.5049
1481.08	71.0958
1484.2	62.7933
1487.33	58.2703
1490.46	54.9092
1493.58	51.5928
1496.7	50.0146
1499.82	46.751
1502.94	48.0886
1506.06	46.8721
1509.18	49.1808
1512.29	50.3312
1515.41	52.5104
1518.52	51.9201
1521.63	50.6048
1524.75	50.6918
1527.85	53.2339
1530.96	53.1218
1534.07	52.2864
1537.18	49.9788
1540.28	48.5104
1543.39	46.6474
1546.49	44.0133
1549.59	44.9921
1552.69	45.1489
1555.79	45.3851
1558.89	46.3894
1561.99	48.4027
1565.08	50.2973
1568.18	52.7439
1571.27	57.1256
1574.37	59.9178
1577.46	63.7701
1580.55	68.3709
1583.64	72.2534
1586.73	77.0684
1589.81	78.352
1592.9	80.2314
1595.98	82.1012
1599.06	83.9978
1602.15	86.1454
1605.23	89.5775
1608.31	90.1687
1611.39	90.3555
1614.46	91.4738
1617.54	91.9657
1620.61	91.3529
1623.69	92.8895
1626.76	96.2596
1629.83	97.596
1632.9	100.83
1635.97	102.724
1639.04	104.352
1642.11	107.741
1645.17	110.203
1648.24	111.773
1651.3	112.057
1654.36	112.101
1657.42	112.335
1660.48	110.342
1663.54	106.754
1666.6	102.44
1669.66	98.8212
1672.71	93.4807
1675.77	87.7349
1678.82	82.0171
1681.87	74.9463
1684.92	66.6442
1687.97	58.8789
1691.02	50.1512
1694.07	42.5908
1697.11	38.0106
1700.16	33.5107
1703.2	28.7485
1706.25	25.5048
1709.29	21.2479
1712.33	17.8173
1715.37	16.7471
1718.41	13.7335
1721.44	11.4929
1724.48	11.4539
1727.51	11.8977
1730.55	12.5123
1733.58	13.0189
1736.61	12.9741
1739.64	12.8205
1742.67	12.4384
1745.7	12.9282
1748.72	12.2364
1751.75	12.4078
1754.77	11.0744
1757.8	9.30762
1760.82	6.61153
1763.84	5.25934
1766.86	4.17299
1769.88	4.09911
1772.9	2.85571
1775.91	1.67991
1778.93	2.71383
1781.94	3.1394
1784.96	2.83448
1787.97	3.0276
1790.98	2.35164
1793.99	1.02716
1797	0.904465
1800.01	1.54492
1803.01	2.38829
1806.02	2.62895
1809.02	3.94902
1812.02	4.55103
1815.02	4.96496
1818.03	5.23958
1821.02	5.0033
1824.02	5.42523
1827.02	4.27125
1830.02	4.66717
1833.01	3.95477
1836.01	5.05148
1839	5.60858
1841.99	5.9585
1844.98	4.76625
1847.97	4.93807
1850.96	5.37857
1853.95	6.68835
1856.93	6.77271
1859.92	6.65336
1862.9	6.66741
1865.88	7.32009
1868.87	7.28128
1871.85	8.50358
1874.83	10.1875
1877.81	9.79317
1880.78	10.5516
1882.53	10.1867
1885.52	9.23327
1888.51	8.29367
1891.5	6.97053
1894.48	6.60086
1897.47	7.76571
1900.45	8.00115
1903.43	8.66851
1906.41	8.30021
1909.39	7.92706
1912.37	7.41429
1915.35	6.93311
1918.33	6.57956
1921.3	8.28576
1924.28	7.99101
1927.25	9.1488
1930.22	7.86182
1933.19	6.87142
1936.16	7.41419
1939.13	6.7466
1942.1	6.27098
1945.07	7.22251
1948.03	7.22133
1951	5.69053
1953.96	5.68619
1956.92	4.61862
1959.88	4.21136
1962.84	3.44889
1965.8	4.01102
1968.76	5.48066
1971.72	5.90323
1974.67	5.49506
1977.63	6.74976
1980.58	7.5961
1983.54	8.34103
1986.49	8.96994
1989.44	9.85674
1992.39	10.3205
1995.33	10.4106
1998.28	11.1615
2001.23	10.6964
2004.17	9.86561
2007.12	9.15621
2010.06	9.94667
2013	11.2224
2015.94	11.0128
2018.88	11.9386
2021.82	11.967
2024.76	11.7546
2027.69	10.536
2030.63	9.98673
2033.56	8.81747
2036.5	9.38618
2039.43	10.0031
2042.36	10.1898
2045.29	10.1862
2048.22	11.9018
2051.15	10.9654
2054.07	9.93992
2057	8.74755
2059.92	10.1058
2062.85	10.6401
2065.77	9.53524
2068.69	9.80658
2071.61	8.89696
2074.53	7.06529
2077.45	5.11384
2080.37	7.44951
2083.28	7.06694
2086.2	6.18686
2089.11	5.26617
2092.02	5.95323
2094.94	4.44018
2097.85	3.57786
2100.76	3.39489
2103.66	4.09508
2106.57	5.04028
2109.48	5.9301
2112.38	6.90789
2115.29	7.94027
2118.19	7.47926
2121.09	6.79486
2123.99	7.94994
2126.89	8.99064
2129.79	9.93534
2132.69	10.0637
2135.59	10.5427
2138.48	10.094
2141.38	10.1958
2144.27	9.32722
2147.17	8.28979
2150.06	10.3299
2152.95	10.3482
2155.84	9.79825
2158.73	9.53634
2161.61	9.44919
2164.5	9.17627
2167.38	9.70172
2170.27	9.51111
2173.15	10.3462
2176.03	9.4466
2178.91	9.25879
2181.8	7.98048
2184.67	7.20862
2187.55	5.45682
2190.43	5.89321
2193.3	6.94042
2196.18	7.3279
2199.05	7.38047
2201.93	6.5442
2204.8	5.8186
2207.67	4.74943
2210.54	3.98963
2213.41	3.85892
2216.27	4.08447
2219.14	4.77521
2222.01	6.10021
2224.87	5.96315
2227.73	7.03387
2230.6	7.71493
2233.46	8.1076
2236.32	7.69319
2239.18	6.73023
2242.03	6.89863
2244.89	6.84216
2247.75	8.25643
2250.6	8.93749
2253.46	10.0354
2256.31	9.99389
2259.16	10.4655
2262.01	11.682
2264.86	9.83231
2267.71	9.69647
2270.56	9.81896
2273.4	8.77966
2276.25	8.12723
2279.09	9.5616
2281.94	9.9591
2284.78	9.42588
2287.62	8.42875
2290.46	6.88471
2293.3	6.62847
2296.14	6.92285
2298.98	7.5334
2301.82	7.20608
2304.65	6.77435
2307.49	7.37279
2310.32	7.5386
2313.15	8.80704
2315.98	11.3019
2318.81	11.731
2321.64	11.9499
2324.47	11.8209
2327.3	11.2879
2330.12	10.52
2332.95	8.65726
2335.77	7.56065
2338.6	8.17807
2341.42	8.22971
2344.24	8.43875
2347.06	9.48389
2349.88	7.03851
2352.7	4.9537
2355.51	3.38766
2358.33	1.57584
2361.14	2.26792
2363.96	1.49235
2366.77	3.05541
2369.58	2.88779
2372.39	2.37626
2375.2	4.195
2378.01	3.66308
2380.82	4.75327
2383.63	7.12232
2386.43	7.38063
2389.24	7.28485
2392.04	7.07628
2394.84	5.72342
2397.65	5.7936
2400.45	5.94219
2403.25	7.65336
2406.05	7.94367
2408.84	9.59146
2411.64	9.00564
2414.44	10.5137
2417.23	11.5758
2420.02	10.8102
2422.82	12.0922
2425.61	12.4638
2428.4	11.837
2431.19	12.036
2433.98	12.4604
2436.77	13.1654
2439.55	13.9449
2442.34	13.5119
2445.12	13.2845
2447.91	13.686
2450.69	13.5918
2453.47	13.8971
2456.25	12.3384
2459.03	11.6688
2461.81	9.4157
2464.59	8.81415
2467.36	9.35481
2470.14	7.47931
2472.92	6.60376
2475.69	5.51005
2478.46	5.30313
2481.23	5.4429
2484	6.13399
2486.77	5.31447
2489.54	4.96039
2492.31	4.07826
2495.08	4.0401
2497.84	4.63596
2500.61	4.62034
2503.37	3.56727
2506.13	4.57925
2508.9	5.71466
2511.66	5.60928
2514.42	7.17805
2517.18	8.97437
2519.93	9.61577
2522.69	9.72395
2525.45	8.36717
2528.2	9.3449
2530.95	9.27143
2533.71	11.0316
2536.46	12.1366
2539.21	12.1197
2541.96	12.9151
2544.71	11.6657
2547.46	11.3139
2550.2	11.2188
2552.95	10.2499
2555.7	10.39
2558.44	8.68878
2561.18	9.33706
2563.93	7.23425
2566.67	7.59902
2569.41	7.97826
2572.15	8.60372
2574.88	9.11485
2577.62	8.33266
2580.36	6.91665
2583.09	7.71138
2585.83	7.30247
2588.56	7.31103
2591.29	7.02667
2594.02	8.53192
2596.75	10.3228
2599.48	11.384
2602.21	13.0061
2604.94	12.4729
2607.67	13.536
2610.39	12.6143
2613.12	13.2594
2615.84	13.6962
2618.56	14.2068
2621.28	13.7722
2624.01	13.2251
2626.72	13.0168
2629.44	12.0265
2632.16	11.7846
2634.88	11.3412
2637.59	9.83949
2640.31	8.98101
2643.02	8.14751
2645.74	7.66727
2648.45	7.41567
2651.16	7.35281
2653.87	6.9761
2656.58	6.5829
2659.29	5.98875
2661.99	7.8075
2664.7	7.84409
2667.41	7.98807
2670.11	8.84721
2672.81	9.5186
2675.51	10.4808
2678.22	11.1855
2680.92	13.3939
2683.62	14.263
2686.31	15.0171
2689.01	13.6483
2691.71	13.8815
2694.4	14.0972
2697.1	14.4651
2699.79	15.766
2702.49	16.989
2705.18	18.4165
2707.87	19.5193
2710.56	21.5213
2713.25	21.9689
2715.94	21.9068
2718.62	21.273
2721.31	22.0302
2723.99	20.2045
2726.68	20.5807
2729.36	20.9774
2732.04	20.5478
2734.73	19.373
2737.41	17.3648
2740.08	15.7357
2742.76	14.9332
2745.44	15.407
2748.12	13.8315
2750.79	12.8692
2753.47	10.5727
2756.14	9.56795
2758.81	9.62542
2761.49	10.1003
2764.16	10.4544
2766.83	9.16588
2769.5	9.21825
2772.16	9.68681
2774.83	8.69745
2777.5	8.23364
2780.16	7.68367
2782.83	6.37449
2785.49	6.66718
2788.15	5.65584
2790.82	4.14303
2793.48	2.89462
2796.14	2.21363
2798.79	0.125517
2801.45	-2.03315
2804.11	-1.30228
2806.76	-1.11508
2809.42	-1.57852
2812.07	-1.87247
2814.73	-1.65856
2817.38	0.0426037
2820.03	3.13686
2822.68	8.5181
2825.33	13.0815
2827.98	19.1445
2830.63	24.2077
2833.27	30.1553
2835.92	37.9705
2838.56	46.0978
2841.21	56.404
2843.85	66.4835
2846.49	78.6438
2849.13	92.0817
2851.77	106.945
2854.41	120.851
2857.05	136.018
2859.69	150.517
2862.32	162.938
2864.96	174.397
2867.59	182.559
2870.23	192.145
2872.86	199.767
2875.49	206.687
2878.12	213.194
2880.75	219.539
2883.38	226.546
2886.01	230.302
2888.63	234.184
2891.26	237.63
2893.89	241.165
2896.51	247.662
2899.13	254.904
2901.76	263.743
2904.38	274.26
2907	286.245
2909.62	300.146
2912.24	314.5
2914.85	330.08
2917.47	345.015
2920.09	356.141
2922.7	363.135
2925.32	368.532
2927.93	369.026
2930.54	367.671
2933.15	364.603
2935.76	360.239
2938.37	352.965
2940.98	341.983
2943.59	332.317
2946.2	319.776
2948.8	305.357
2951.41	288.31
2954.01	273.503
2956.62	258.988
2959.22	245.463
2961.82	231.135
2964.42	217.612
2967.02	205.94
2969.62	195.317
2972.22	186.605
2974.81	176.619
2977.41	166.89
2980	158.167
2982.6	146.285
2985.19	133.981
2987.78	122.405
2990.38	109.625
2992.97	96.6505
2995.56	85.339
2998.14	74.4396
3000.73	64.9732
3003.32	55.3965
3005.91	46.1018
3008.49	37.8166
3011.07	29.6054
3013.66	21.425
3016.24	15.9253
3018.82	11.3272
3021.4	6.84433
3023.98	2.88598
3026.56	0.355765
3029.14	-0.412557
3031.71	-1.12358
3034.29	-0.740502
3036.87	-0.418463
3039.44	-0.272642
3042.01	1.92801
3044.59	5.11955
3047.16	6.78595
3049.73	7.07073
3052.3	7.62978
3054.87	7.07778
3057.43	7.62026
3060	8.08708
3062.57	8.6399
3065.13	8.32109
3067.7	6.70731
3070.26	7.28137
3072.82	6.53371
3075.39	5.36634
3077.95	6.81704
3080.51	6.93261
3083.07	6.32728
3085.63	7.43179
3088.18	7.74457
3090.74	8.51839
3093.29	10.2746
3095.85	11.9063
3098.4	13.4285
3100.95	16.0088
3103.51	17.9784
3106.06	19.1179
3108.61	20.9619
3111.16	22.6024
3113.71	25.6639
3116.25	29.3211
3118.8	32.2616
3121.35	34.8789
3123.89	37.5331
3126.44	40.1142
3128.98	43.1998
3131.52	46.2772
3134.06	49.7684
3136.6	52.7381
3139.14	57.0455
3141.68	60.7213
3144.22	63.118
3146.76	64.5301
3149.29	63.2999