File: data/Raman/poly_smoothed/Mb_00_13_13_1x_45s_532 nm_x100_100%_600 gr_mm_01.txt
#Acq. time (s)=	45
#Accumulations=	2
#Range (cm-¹)=	200...3150
#Windows=	2
#Auto scanning=	Off
#Autofocus=	Off
#Macrospot=	Off
#AutoExposure=	Off
#Spike filter=	Multiple accum.
#Delay time (s)=	0
#Binning=	1
#Readout mode=	Signal
#DeNoise=	Off
#ICS correction=	On
#Dark correction=	Off
#Inst. Process=	Off
#Detector Gain=	Best Dynamic Range
#Detector ADC=	20 kHz
#Detector temperature (°C)=	-69.85
#Instrument=	LabRAM HR Evol
#Detector=	Synapse
#Objective=	x100
#Grating=	600 gr/mm
#ND Filter=	100%
#Laser (nm)=	532
#Hole=	100.021
#Range=	Auto
#Laser Pol.=	No
#Raman. Pol.=	No
#Laser Pol. (°)=	-0.0007625
#Raman Pol. (°)=	89.9995
#Collection=	Microscope
#StageXY=	Marzhauser
#StageZ=	Marzhauser
#X (µm)=	-1008.1
#Y (µm)=	-2965
#Z (µm)=	527.8
#Full time(mm:ss)=	3:18
#Project=
#Sample=
#Site=
#Title=	Mb_00_13_13_2x_45s_532 nm_x100_100%_600 gr_mm
#Remark=
#Date=	06.07.2022 10:33
#Acquired=	06.07.2022 10:33:22
#Base:Fit=	10.08.2022 10:16:56
#Base:Sub=	10.08.2022 10:17:24
#Filter:Polynom=	16.08.2022 10:36:38
#AxisType[0]=Intens
#AxisUnit[0]=Cnt
#AxisType[1]=Spectr
#AxisUnit[1]=1/cm
200.398	41.3019
204.027	28.9596
207.657	16.69
211.283	9.12274
214.909	6.70036
218.533	10.2048
222.157	16.1061
225.777	22.6774
229.396	33.7702
233.016	43.4181
236.632	51.8763
240.247	56.0504
243.86	61.4586
247.474	67.5774
251.085	73.8525
254.694	79.7684
258.301	83.7163
261.908	84.157
265.513	84.7591
269.116	80.9337
272.718	76.7942
276.319	70.476
279.918	63.5038
283.516	56.5225
287.113	47.2248
290.708	39.6517
294.302	32.3992
297.894	28.303
301.485	22.8477
305.073	18.8924
308.661	18.4925
312.247	16.4193
315.833	16.8084
319.415	17.4094
322.997	14.6755
326.579	13.0463
330.156	12.4731
333.735	11.5197
337.31	12.2418
340.885	10.0359
344.458	7.5941
348.03	7.0281
351.6	5.59243
355.17	1.63515
358.737	0.830961
362.304	2.83419
365.868	3.87713
369.431	6.29653
372.994	9.82886
376.554	11.2126
380.112	17.8128
383.669	25.7955
387.225	33.2713
390.781	40.3269
394.334	53.0156
397.885	62.1061
401.436	68.6966
404.984	74.9166
408.532	80.6032
412.078	83.2792
415.623	82.9004
419.166	82.0273
422.708	79.6026
426.248	75.4759
429.788	69.2636
433.326	61.6868
436.86	54.1912
440.395	45.1189
443.929	40.1516
447.461	33.2583
450.99	25.8198
454.52	17.9994
458.048	13.5988
461.573	9.24204
465.099	7.09052
468.623	9.14599
472.144	9.75492
475.666	12.2481
479.184	14.1016
482.703	17.8526
486.218	21.8688
489.734	23.534
493.247	28.4066
496.759	31.0612
500.271	31.9563
503.779	35.3332
507.287	37.1951
510.795	40.0957
514.299	41.7133
517.803	42.4698
521.305	43.817
524.805	46.2043
528.307	47.2838
531.805	47.2652
535.301	45.9188
538.797	44.4402
542.291	43.4691
545.783	43.0091
549.275	41.5614
552.765	40.0861
556.253	37.6004
559.738	36.4899
563.224	34.4197
566.709	31.5217
570.192	29.7048
573.674	26.2247
577.153	23.0136
580.632	20.3887
584.11	17.656
587.587	16.1197
591.06	14.7916
594.534	12.1297
598.005	12.3829
601.476	11.7172
604.944	12.6424
608.413	14.9615
611.878	16.5212
615.344	18.5489
618.807	19.313
622.27	21.0856
625.73	24.8491
629.189	29.9236
632.648	32.4143
636.105	36.7666
639.559	41.3187
643.013	43.8282
646.467	46.9354
649.918	45.9166
653.368	47.2924
656.816	48.8
660.263	48.962
663.708	46.9157
667.153	47.22
670.596	47.6104
674.037	46.1687
677.478	45.7567
680.917	45.0735
684.355	44.835
687.791	43.4055
691.224	44.9368
694.658	44.5163
698.091	44.2146
701.522	43.1875
704.95	43.8274
708.379	45.499
711.806	47.5127
715.23	49.0169
718.655	49.784
722.078	50.7858
725.498	51.3137
728.919	50.6911
732.337	51.579
735.755	52.3371
739.17	51.6645
742.584	53.4933
745.998	56.5884
749.409	60.2629
752.819	64.0427
756.23	66.9932
759.637	70.0995
763.043	72.6436
766.448	75.0105
769.853	78.5979
773.255	82.6219
776.656	87.0086
780.056	88.7236
783.454	91.275
786.851	93.2946
790.247	94.6049
793.641	96.4798
797.034	96.0799
800.426	94.8339
803.817	93.2215
807.206	90.7627
810.592	89.0091
813.979	87.421
817.364	85.5476
820.748	82.9465
824.129	83.4846
827.511	83.3822
830.891	80.127
834.269	77.4696
837.646	74.7811
841.023	72.1338
844.396	69.5631
847.77	65.4259
851.141	64.8094
854.513	63.0274
857.881	59.617
861.248	58.1371
864.616	57.8763
867.98	57.7624
871.343	55.6124
874.707	54.55
878.068	53.3591
881.428	51.6338
884.786	49.9129
888.143	47.9406
891.498	46.6801
894.855	46.766
898.208	45.8899
901.56	44.8822
904.91	43.7961
908.26	41.4099
911.608	38.1504
914.955	36.6561
918.298	35.9181
921.643	34.0257
924.986	32.3527
928.328	31.4602
931.668	29.4818
935.006	28.8535
938.344	27.5581
941.681	25.6546
945.014	25.7544
948.349	25.1413
951.682	25.5408
955.012	23.8586
958.343	24.3133
961.67	26.477
964.998	27.7173
968.323	31.5495
971.649	37.0077
974.971	42.0495
978.293	45.7222
981.615	49.5183
984.933	51.9896
988.251	54.3706
991.567	56.8476
994.884	57.4984
998.198	58.9443
1001.51	59.6986
1004.82	57.1105
1008.13	54.9577
1011.44	52.9875
1014.75	51.0847
1018.06	53.7615
1021.36	57.1973
1024.66	62.0649
1027.97	68.8334
1031.27	73.1465
1034.57	76.2533
1037.87	77.4761
1041.16	80.7626
1044.46	83.427
1047.76	84.08
1051.05	83.895
1054.34	83.5961
1057.63	81.8452
1060.92	78.2673
1064.21	74.2393
1067.5	69.5246
1070.78	63.3257
1074.07	56.0153
1077.35	46.6196
1080.63	36.5398
1083.91	29.5365
1087.19	20.9857
1090.47	17.127
1093.75	12.1815
1097.03	12.1558
1100.3	13.6814
1103.57	14.6724
1106.84	14.7474
1110.11	11.5765
1113.38	9.6808
1116.65	6.35647
1119.92	4.70869
1123.19	3.56062
1126.45	2.75487
1129.71	3.40837
1132.97	1.93982
1136.23	1.43561
1139.49	2.15772
1142.75	2.8176
1146.01	4.64403
1149.26	4.13992
1152.52	5.08224
1155.77	4.45751
1159.02	3.91185
1162.27	4.40718
1165.52	5.53533
1168.77	4.62944
1172.02	6.38741
1175.26	7.71796
1178.51	10.5968
1181.75	12.4143
1184.99	14.7764
1188.23	16.2699
1191.47	17.3872
1194.71	21.5355
1197.94	24.6762
1201.18	28.3073
1204.41	31.5507
1207.65	33.2422
1210.88	36.035
1214.11	40.0819
1217.34	43.121
1220.57	46.7271
1223.79	50.9147
1227.02	54.3596
1230.24	55.0062
1233.47	57.4565
1236.69	58.0633
1239.91	59.9852
1243.13	59.6674
1246.34	61.4007
1249.56	60.6693
1252.78	59.9289
1255.99	58.1347
1259.2	58.7242
1262.42	58.5826
1265.63	57.0407
1268.84	56.1428
1272.04	55.7008
1275.25	55.8528
1278.46	55.6374
1281.66	58.0006
1284.86	56.2978
1288.07	59.6906
1291.27	61.4288
1294.47	62.7295
1297.66	66.1926
1300.86	71.8883
1304.06	76.1686
1307.25	79.5261
1310.44	83.2692
1313.64	87.4744
1316.83	87.8285
1320.02	87.9856
1323.2	88.6002
1326.39	88.2832
1329.58	87.2743
1332.76	87.4756
1335.95	86.5561
1339.13	86.7103
1342.31	84.2889
1345.49	81.9771
1348.67	81.7747
1351.85	79.5299
1355.02	77.3347
1358.2	74.9205
1361.37	73.1863
1364.54	70.1402
1367.71	67.4087
1370.88	67.4773
1374.05	66.9343
1377.22	66.0506
1380.39	64.5748
1383.55	63.9146
1386.72	63.2034
1389.88	62.4468
1393.04	59.1818
1396.2	55.6198
1399.36	54.7451
1402.52	53.8565
1405.68	54.9322
1408.83	57.0024
1411.98	59.1965
1415.14	64.6346
1418.29	69.9976
1421.44	72.5242
1424.59	78.7388
1427.74	85.5317
1430.89	88.9601
1434.03	94.8593
1437.18	99.7945
1440.32	102.289
1443.46	103.09
1446.6	106.019
1449.74	107.723
1452.88	108.198
1456.02	105.168
1459.16	102.651
1462.29	98.1524
1465.43	92.6033
1468.56	84.9291
1471.69	76.451
1474.82	70.6287
1477.95	64.8172
1481.08	59.3589
1484.2	54.5206
1487.33	52.2687
1490.46	49.7161
1493.58	46.5042
1496.7	43.5407
1499.82	41.0225
1502.94	40.2643
1506.06	39.4838
1509.18	38.9969
1512.29	38.8435
1515.41	37.363
1518.52	35.6826
1521.63	35.6244
1524.75	36.0701
1527.85	35.9002
1530.96	35.2461
1534.07	34.392
1537.18	35.0254
1540.28	34.6859
1543.39	36.5512
1546.49	38.7052
1549.59	42.1724
1552.69	45.3006
1555.79	49.4013
1558.89	51.5031
1561.99	55.0555
1565.08	58.8177
1568.18	60.6559
1571.27	62.8924
1574.37	66.096
1577.46	67.9595
1580.55	72.2001
1583.64	74.3029
1586.73	74.9473
1589.81	74.3559
1592.9	74.8543
1595.98	74.5112
1599.06	72.9432
1602.15	69.752
1605.23	69.1038
1608.31	68.3319
1611.39	66.5993
1614.46	64.6191
1617.54	64.566
1620.61	65.0901
1623.69	66.1849
1626.76	66.9253
1629.83	68.2693
1632.9	68.9405
1635.97	70.0176
1639.04	72.392
1642.11	74.3566
1645.17	77.2509
1648.24	81.3497
1651.3	83.1905
1654.36	85.5215
1657.42	87.0359
1660.48	88.0691
1663.54	86.4317
1666.6	85.513
1669.66	82.1596
1672.71	77.1054
1675.77	74.9154
1678.82	70.4251
1681.87	66.9171
1684.92	60.1865
1687.97	53.2467
1691.02	47.4141
1694.07	40.4594
1697.11	34.7747
1700.16	30.9174
1703.2	26.3153
1706.25	22.6572
1709.29	19.435
1712.33	18.111
1715.37	14.7222
1718.41	13.2542
1721.44	12.496
1724.48	11.2142
1727.51	10.7966
1730.55	11.7254
1733.58	11.4936
1736.61	11.881
1739.64	11.2332
1742.67	11.7437
1745.7	12.2047
1748.72	12.7909
1751.75	12.9521
1754.77	12.4868
1757.8	6.97606
1760.82	6.44372
1763.84	6.97097
1766.86	8.01473
1769.88	9.42234
1772.9	11.7853
1775.91	12.4058
1778.93	13.1871
1781.94	14.0239
1784.96	15.24
1787.97	16.1453
1790.98	15.1382
1793.99	16.109
1797	16.4774
1800.01	16.5949
1803.01	16.8692
1806.02	16.882
1809.02	14.85
1812.02	14.0186
1815.02	12.6723
1818.03	12.0431
1821.02	10.6021
1824.02	7.93029
1827.02	6.78036
1830.02	4.97207
1833.01	3.81376
1836.01	7.53377
1839	7.05221
1841.99	7.54426
1844.98	8.77921
1847.97	10.0332
1850.96	9.88755
1853.95	8.59857
1856.93	7.93784
1859.92	8.08821
1862.9	6.02617
1865.88	4.94616
1868.87	3.72252
1871.85	3.51578
1874.83	3.0328
1877.81	3.43213
1880.78	1.62954
1882.53	1.91314
1885.52	0.172161
1888.51	2.38032
1891.5	2.98728
1894.48	2.58849
1897.47	3.19956
1900.45	4.82793
1903.43	5.87992
1906.41	5.73619
1909.39	8.038
1912.37	9.12466
1915.35	9.83239
1918.33	11.3743
1921.3	9.4817
1924.28	7.54455
1927.25	8.76451
1930.22	8.63335
1933.19	9.22615
1936.16	8.27261
1939.13	7.99615
1942.1	9.12957
1945.07	8.91603
1948.03	9.1773
1951	9.85471
1953.96	11.376
1956.92	10.8782
1959.88	10.7032
1962.84	11.3127
1965.8	11.3606
1968.76	9.50286
1971.72	9.08531
1974.67	9.04885
1977.63	9.22799
1980.58	8.89113
1983.54	7.37038
1986.49	5.32348
1989.44	5.42431
1992.39	6.89032
1995.33	6.7939
1998.28	6.70934
2001.23	6.83117
2004.17	7.32072
2007.12	5.93994
2010.06	5.95232
2013	7.36602
2015.94	7.61626
2018.88	8.13592
2021.82	9.70091
2024.76	10.7264
2027.69	10.25
2030.63	9.69509
2033.56	9.7834
2036.5	11.4551
2039.43	11.0468
2042.36	10.3484
2045.29	12.3021
2048.22	11.8688
2051.15	13.7965
2054.07	11.9524
2057	12.2706
2059.92	13.504
2062.85	15.2033
2065.77	14.3623
2068.69	14.2878
2071.61	12.7253
2074.53	12.6534
2077.45	13.6539
2080.37	12.7935
2083.28	13.9487
2086.2	14.3968
2089.11	14.2806
2092.02	14.5769
2094.94	14.4531
2097.85	15.3138
2100.76	16.1871
2103.66	16.8843
2106.57	16.1196
2109.48	15.1928
2112.38	14.2259
2115.29	13.8035
2118.19	11.8453
2121.09	12.0436
2123.99	10.7735
2126.89	10.2818
2129.79	9.72539
2132.69	9.97706
2135.59	9.40071
2138.48	9.41989
2141.38	8.76202
2144.27	9.64166
2147.17	9.55228
2150.06	10.1569
2152.95	10.5283
2155.84	11.3891
2158.73	13.0195
2161.61	13.126
2164.5	14.6351
2167.38	15.3632
2170.27	15.8276
2173.15	16.7675
2176.03	15.0694
2178.91	13.4277
2181.8	13.3062
2184.67	14.0737
2187.55	15.1932
2190.43	15.3124
2193.3	16.4077
2196.18	14.4808
2199.05	13.8761
2201.93	14.7258
2204.8	16.3241
2207.67	15.9595
2210.54	14.4494
2213.41	15.0446
2216.27	14.7221
2219.14	14.973
2222.01	14.2388
2224.87	13.6067
2227.73	15.6004
2230.6	16.1459
2233.46	15.8426
2236.32	14.1804
2239.18	13.4143
2242.03	12.1314
2244.89	11.9565
2247.75	12.1138
2250.6	13.7799
2253.46	14.0236
2256.31	15.7846
2259.16	14.1703
2262.01	14.2476
2264.86	12.5818
2267.71	11.852
2270.56	12.1677
2273.4	12.5146
2276.25	12.0348
2279.09	9.71001
2281.94	9.1796
2284.78	9.96598
2287.62	10.405
2290.46	8.68219
2293.3	9.3637
2296.14	11.2804
2298.98	12.1303
2301.82	10.8554
2304.65	10.5796
2307.49	10.8673
2310.32	12.6583
2313.15	13.4735
2315.98	15.0263
2318.81	14.2869
2321.64	13.1001
2324.47	13.1839
2327.3	13.7235
2330.12	13.4016
2332.95	12.7284
2335.77	11.2622
2338.6	10.1527
2341.42	9.30639
2344.24	9.03562
2347.06	8.63541
2349.88	8.31297
2352.7	9.55571
2355.51	8.9481
2358.33	7.82061
2361.14	8.48299
2363.96	8.93829
2366.77	9.92221
2369.58	7.50674
2372.39	7.4656
2375.2	8.3727
2378.01	7.53428
2380.82	7.69264
2383.63	8.13868
2386.43	6.58651
2389.24	4.76932
2392.04	4.64686
2394.84	5.27249
2397.65	4.71541
2400.45	3.93659
2403.25	4.05858
2406.05	2.82144
2408.84	4.13277
2411.64	7.03929
2414.44	7.25758
2417.23	8.84205
2420.02	10.766
2422.82	11.9395
2425.61	12.4331
2428.4	13.0234
2431.19	13.3377
2433.98	11.8264
2436.77	11.3401
2439.55	11.1202
2442.34	11.438
2445.12	11.0743
2447.91	9.8454
2450.69	9.39149
2453.47	7.75773
2456.25	6.09769
2459.03	4.76394
2461.81	4.60059
2464.59	5.16274
2467.36	3.80964
2470.14	1.98107
2472.92	0.789171
2475.69	1.4758
2478.46	2.57599
2481.23	1.8045
2484	3.4649
2486.77	4.08231
2489.54	4.60899
2492.31	3.78129
2495.08	3.04608
2497.84	1.73863
2500.61	1.37338
2503.37	1.56052
2506.13	0.666641
2508.9	1.05899
2511.66	0.833139
2514.42	-0.00139732
2517.18	-1.46287
2519.93	-2.31871
2522.69	-1.93358
2525.45	-0.231267
2528.2	-0.267733
2530.95	-1.34169
2533.71	-1.2883
2536.46	-2.10674
2539.21	-0.624359
2541.96	1.07581
2544.71	1.60915
2547.46	1.32845
2550.2	2.19954
2552.95	2.64559
2555.7	3.19831
2558.44	4.39858
2561.18	5.16171
2563.93	5.53773
2566.67	6.19428
2569.41	6.68827
2572.15	6.70028
2574.88	7.81149
2577.62	7.43763
2580.36	6.08374
2583.09	4.89361
2585.83	3.89864
2588.56	5.33624
2591.29	5.08081
2594.02	3.89664
2596.75	2.70315
2599.48	3.68068
2602.21	3.80595
2604.94	3.40284
2607.67	5.21443
2610.39	5.34357
2613.12	5.35878
2615.84	6.80091
2618.56	7.17082
2621.28	7.38315
2624.01	8.09783
2626.72	9.31131
2629.44	9.34544
2632.16	10.8981
2634.88	10.3757
2637.59	9.65816
2640.31	8.98323
2643.02	7.77823
2645.74	7.00611
2648.45	6.51672
2651.16	5.65656
2653.87	5.28657
2656.58	4.74621
2659.29	4.24593
2661.99	3.79127
2664.7	4.6729
2667.41	6.67505
2670.11	7.44773
2672.81	6.91354
2675.51	8.86478
2678.22	9.94918
2680.92	10.327
2683.62	9.68783
2686.31	10.1977
2689.01	9.10443
2691.71	10.1263
2694.4	9.34548
2697.1	9.93037
2699.79	9.36888
2702.49	8.64099
2705.18	9.05523
2707.87	9.68071
2710.56	10.1774
2713.25	10.4898
2715.94	10.9488
2718.62	12.2916
2721.31	14.3064
2723.99	15.9504
2726.68	17.3863
2729.36	18.3866
2732.04	19.2315
2734.73	20.2326
2737.41	19.2765
2740.08	18.8366
2742.76	16.9958
2745.44	14.7144
2748.12	13.2326
2750.79	12.899
2753.47	11.6614
2756.14	9.29352
2758.81	7.30184
2761.49	6.68369
2764.16	4.56716
2766.83	3.03615
2769.5	3.51997
2772.16	2.7373
2774.83	2.34791
2777.5	2.22782
2780.16	3.06711
2782.83	5.42628
2785.49	6.75842
2788.15	7.12405
2790.82	6.6599
2793.48	6.24555
2796.14	5.76708
2798.79	5.1823
2801.45	4.94388
2804.11	3.80232
2806.76	3.18751
2809.42	0.736885
2812.07	1.66414
2814.73	1.77849
2817.38	3.40964
2820.03	5.5683
2822.68	8.25069
2825.33	11.4737
2827.98	14.0171
2830.63	18.7669
2833.27	24.7316
2835.92	31.0887
2838.56	38.1055
2841.21	46.4614
2843.85	56.1358
2846.49	65.9771
2849.13	77.3659
2851.77	88.5687
2854.41	99.746
2857.05	109.506
2859.69	120.538
2862.32	130.526
2864.96	140.108
2867.59	147.439
2870.23	154.464
2872.86	160.413
2875.49	165.964
2878.12	172.836
2880.75	178.524
2883.38	183.259
2886.01	186.752
2888.63	189.951
2891.26	193.505
2893.89	196.364
2896.51	201.454
2899.13	206.774
2901.76	212.225
2904.38	220.022
2907	228.137
2909.62	237.672
2912.24	248.732
2914.85	259.505
2917.47	267.471
2920.09	273.72
2922.7	280.014
2925.32	285.484
2927.93	287.813
2930.54	287.872
2933.15	287.077
2935.76	284.605
2938.37	281.28
2940.98	276.882
2943.59	268.815
2946.2	261.129
2948.8	251.668
2951.41	241.503
2954.01	231.058
2956.62	219.053
2959.22	209.077
2961.82	199.407
2964.42	188.129
2967.02	179.444
2969.62	171.028
2972.22	161.282
2974.81	151.374
2977.41	142.075
2980	133.131
2982.6	121.309
2985.19	111.625
2987.78	99.6239
2990.38	89.2175
2992.97	78.7311
2995.56	69.1561
2998.14	59.0173
3000.73	49.4559
3003.32	42.006
3005.91	34.4822
3008.49	27.6492
3011.07	21.9556
3013.66	16.6395
3016.24	11.7762
3018.82	7.8928
3021.4	4.95009
3023.98	3.12426
3026.56	0.362987
3029.14	0.460684
3031.71	-1.50027
3034.29	-2.49108
3036.87	-2.4887
3039.44	-0.371292
3042.01	0.349823
3044.59	0.751713
3047.16	0.0335765
3049.73	-0.178023
3052.3	-0.206282
3054.87	0.136704
3057.43	0.827998
3060	1.93057
3062.57	2.00773
3065.13	2.74634
3067.7	2.73351
3070.26	3.64989
3072.82	4.29074
3075.39	4.49594
3077.95	3.51335
3080.51	3.8946
3083.07	4.75128
3085.63	5.18227
3088.18	4.004
3090.74	4.55054
3093.29	4.5367
3095.85	5.00565
3098.4	6.20401
3100.95	6.54473
3103.51	6.86817
3106.06	7.49343
3108.61	7.34008
3111.16	8.0004
3113.71	9.39031
3116.25	11.0613
3118.8	12.7541
3121.35	14.9612
3123.89	16.7851
3126.44	18.0458
3128.98	19.2797
3131.52	21.7258
3134.06	24.6505
3136.6	28.1869
3139.14	30.2599
3141.68	33.3476
3144.22	36.378
3146.76	38.798
3149.29	43.3894