File: data/Raman/poly_smoothed/Mb_00_13_33_1x_45s_532 nm_x100_100%_600 gr_mm_01.txt
#Acq. time (s)=	45
#Accumulations=	2
#Range (cm-¹)=	200...3150
#Windows=	2
#Auto scanning=	Off
#Autofocus=	Off
#Macrospot=	Off
#AutoExposure=	Off
#Spike filter=	Multiple accum.
#Delay time (s)=	0
#Binning=	1
#Readout mode=	Signal
#DeNoise=	Off
#ICS correction=	On
#Dark correction=	Off
#Inst. Process=	Off
#Detector Gain=	Best Dynamic Range
#Detector ADC=	20 kHz
#Detector temperature (°C)=	-69.85
#Instrument=	LabRAM HR Evol
#Detector=	Synapse
#Objective=	x100
#Grating=	600 gr/mm
#ND Filter=	100%
#Laser (nm)=	532
#Hole=	100.021
#Range=	Auto
#Laser Pol.=	No
#Raman. Pol.=	No
#Laser Pol. (°)=	-0.0007625
#Raman Pol. (°)=	89.9995
#Collection=	Microscope
#StageXY=	Marzhauser
#StageZ=	Marzhauser
#X (µm)=	-1015.4
#Y (µm)=	-2824.2
#Z (µm)=	528.6
#Full time(mm:ss)=	3:18
#Project=
#Sample=
#Site=
#Title=	Mb_00_13_33_2x_45s_532 nm_x100_100%_600 gr_mm
#Remark=
#Date=	06.07.2022 12:23
#Acquired=	06.07.2022 12:23:29
#Base:Fit=	10.08.2022 10:16:56
#Base:Sub=	10.08.2022 10:17:24
#Filter:Polynom=	16.08.2022 10:36:38
#AxisType[0]=Intens
#AxisUnit[0]=Cnt
#AxisType[1]=Spectr
#AxisUnit[1]=1/cm
200.398	10.369
204.027	4.52788
207.657	0.707799
211.283	-2.22524
214.909	-0.898743
218.533	4.56174
222.157	14.5017
225.777	26.3776
229.396	34.9982
233.016	43.3288
236.632	50.9931
240.247	58.3306
243.86	64.813
247.474	72.541
251.085	79.6838
254.694	82.9351
258.301	85.2832
261.908	88.6682
265.513	88.7865
269.116	85.4569
272.718	80.5973
276.319	77.2915
279.918	70.1594
283.516	61.7278
287.113	52.5466
290.708	44.1321
294.302	37.7258
297.894	28.7746
301.485	25.0538
305.073	21.6685
308.661	18.8976
312.247	16.5792
315.833	11.4507
319.415	8.37716
322.997	7.13699
326.579	7.134
330.156	5.47683
333.735	4.66693
337.31	4.69208
340.885	2.74942
344.458	0.941377
348.03	-0.444908
351.6	-0.778353
355.17	-3.71672
358.737	-4.11887
362.304	-2.43241
365.868	1.51063
369.431	7.26942
372.994	11.7742
376.554	15.3123
380.112	22.1206
383.669	29.2896
387.225	39.3554
390.781	50.2518
394.334	59.5647
397.885	66.8857
401.436	73.8315
404.984	79.1601
408.532	83.6139
412.078	86.1875
415.623	84.6861
419.166	82.4822
422.708	79.8241
426.248	76.2384
429.788	68.4125
433.326	59.546
436.86	51.0202
440.395	39.6699
443.929	31.219
447.461	22.3882
450.99	16.7678
454.52	12.6569
458.048	6.899
461.573	0.0102776
465.099	-0.942279
468.623	0.474228
472.144	3.7675
475.666	7.67984
479.184	8.93378
482.703	10.3523
486.218	13.78
489.734	18.0292
493.247	23.5712
496.759	25.5672
500.271	27.8414
503.779	28.9222
507.287	32.3157
510.795	33.8802
514.299	35.3062
517.803	37.9024
521.305	37.7785
524.805	37.2885
528.307	35.9622
531.805	35.1209
535.301	33.9568
538.797	32.2301
542.291	30.0838
545.783	27.4772
549.275	23.7024
552.765	22.308
556.253	20.6152
559.738	21.7007
563.224	21.3268
566.709	18.5774
570.192	17.791
573.674	16.5841
577.153	15.2706
580.632	12.7866
584.11	11.6936
587.587	8.24929
591.06	7.25645
594.534	7.48518
598.005	9.18746
601.476	9.19439
604.944	10.0176
608.413	11.5163
611.878	12.2506
615.344	12.6959
618.807	12.5266
622.27	12.6199
625.73	14.1812
629.189	16.6867
632.648	18.6514
636.105	22.2057
639.559	24.5244
643.013	27.3795
646.467	29.8348
649.918	30.8361
653.368	29.1562
656.816	29.4369
660.263	29.865
663.708	28.6636
667.153	29.0074
670.596	26.8266
674.037	26.2067
677.478	26.9222
680.917	26.606
684.355	26.4307
687.791	26.6007
691.224	26.0293
694.658	24.7603
698.091	23.8687
701.522	21.3368
704.95	20.1234
708.379	22.7887
711.806	22.9316
715.23	23.5388
718.655	22.1418
722.078	23.6306
725.498	23.99
728.919	23.3059
732.337	24.0439
735.755	23.6398
739.17	25.8299
742.584	29.0855
745.998	30.9659
749.409	34.5216
752.819	37.9193
756.23	42.6173
759.637	46.4408
763.043	51.0922
766.448	53.1261
769.853	56.5811
773.255	59.9066
776.656	60.0669
780.056	61.3119
783.454	62.1373
786.851	63.6639
790.247	66.5462
793.641	67.0043
797.034	67.545
800.426	65.4561
803.817	63.338
807.206	61.9181
810.592	59.1161
813.979	57.0057
817.364	58.6532
820.748	57.351
824.129	57.496
827.511	56.26
830.891	55.3786
834.269	54.7423
837.646	53.8986
841.023	50.2436
844.396	47.1606
847.77	44.6638
851.141	41.6025
854.513	39.9537
857.881	37.1912
861.248	34.9804
864.616	35.2097
867.98	35.7969
871.343	33.0242
874.707	31.024
878.068	28.261
881.428	24.8991
884.786	22.2041
888.143	19.8161
891.498	17.8454
894.855	15.6623
898.208	17.8729
901.56	17.3164
904.91	17.3565
908.26	16.4079
911.608	15.6691
914.955	14.3737
918.298	13.2757
921.643	12.0614
924.986	12.7819
928.328	13.5729
931.668	13.4525
935.006	15.0103
938.344	17.5479
941.681	18.0193
945.014	19.0125
948.349	19.7
951.682	17.6664
955.012	16.2978
958.343	14.1966
961.67	12.3285
964.998	12.2049
968.323	12.7805
971.649	11.9321
974.971	13.2416
978.293	14.0786
981.615	15.5415
984.933	13.8533
988.251	15.7243
991.567	15.9669
994.884	16.505
998.198	17.1477
1001.51	16.9004
1004.82	18.197
1008.13	18.269
1011.44	22.018
1014.75	24.7938
1018.06	32.3705
1021.36	40.7875
1024.66	48.9928
1027.97	59.9381
1031.27	68.5427
1034.57	75.5007
1037.87	80.8235
1041.16	84.3519
1044.46	90.7006
1047.76	91.2759
1051.05	90.5253
1054.34	87.3288
1057.63	85.3567
1060.92	80.9301
1064.21	74.2849
1067.5	67.4036
1070.78	59.7437
1074.07	49.5623
1077.35	38.784
1080.63	29.1805
1083.91	18.7113
1087.19	10.6512
1090.47	3.66914
1093.75	1.96218
1097.03	2.91635
1100.3	4.59366
1103.57	7.77168
1106.84	8.28876
1110.11	9.15615
1113.38	9.73298
1116.65	10.8438
1119.92	9.9671
1123.19	9.69053
1126.45	8.73013
1129.71	9.66574
1132.97	10.7451
1136.23	11.6915
1139.49	11.7173
1142.75	11.2805
1146.01	11.4876
1149.26	10.7419
1152.52	9.22621
1155.77	8.03304
1159.02	4.46394
1162.27	4.6275
1165.52	1.74334
1168.77	0.777943
1172.02	1.97234
1175.26	3.82896
1178.51	4.6787
1181.75	5.71486
1184.99	4.65571
1188.23	5.60957
1191.47	6.02607
1194.71	7.37523
1197.94	6.8285
1201.18	8.91885
1204.41	12.2207
1207.65	17.5575
1210.88	20.9086
1214.11	25.1678
1217.34	28.6245
1220.57	33.5836
1223.79	35.8805
1227.02	37.6998
1230.24	40.8354
1233.47	43.4227
1236.69	43.1937
1239.91	45.321
1243.13	45.3806
1246.34	46.7305
1249.56	48.7709
1252.78	48.3989
1255.99	49.3199
1259.2	46.1818
1262.42	43.8754
1265.63	42.5228
1268.84	39.932
1272.04	39.6624
1275.25	37.9393
1278.46	39.1493
1281.66	42.9888
1284.86	41.474
1288.07	45.5198
1291.27	49.2145
1294.47	51.4
1297.66	54.8565
1300.86	57.866
1304.06	59.7297
1307.25	62.8444
1310.44	66.8234
1313.64	67.0836
1316.83	68.0675
1320.02	71.4909
1323.2	72.494
1326.39	71.8509
1329.58	71.3282
1332.76	68.7764
1335.95	68.3773
1339.13	67.215
1342.31	67.3453
1345.49	68.2003
1348.67	66.3199
1351.85	64.4709
1355.02	63.2593
1358.2	61.4987
1361.37	59.2015
1364.54	57.969
1367.71	59.2772
1370.88	57.7407
1374.05	56.8609
1377.22	54.1956
1380.39	54.2047
1383.55	53.6273
1386.72	52.9195
1389.88	52.4373
1393.04	50.2228
1396.2	49.3671
1399.36	48.6586
1402.52	49.7977
1405.68	52.2784
1408.83	54.7835
1411.98	59.2628
1415.14	65.1224
1418.29	72.1044
1421.44	76.9637
1424.59	80.9869
1427.74	85.5845
1430.89	91.942
1434.03	98.5502
1437.18	104.252
1440.32	109.646
1443.46	110.446
1446.6	111.725
1449.74	111.078
1452.88	110.451
1456.02	107.943
1459.16	106.196
1462.29	101.368
1465.43	94.543
1468.56	87.8456
1471.69	81.9821
1474.82	76.9168
1477.95	71.2372
1481.08	64.9009
1484.2	58.033
1487.33	52.3952
1490.46	46.7279
1493.58	42.373
1496.7	37.8785
1499.82	33.2787
1502.94	31.2577
1506.06	31.1415
1509.18	28.7541
1512.29	25.4181
1515.41	24.5748
1518.52	20.5073
1521.63	18.7989
1524.75	19.9915
1527.85	19.3931
1530.96	20.6096
1534.07	20.1648
1537.18	21.3333
1540.28	21.8977
1543.39	22.8692
1546.49	24.4888
1549.59	25.6686
1552.69	26.7936
1555.79	27.389
1558.89	30.7697
1561.99	33.2267
1565.08	36.4179
1568.18	40.7569
1571.27	45.857
1574.37	48.6084
1577.46	54.6553
1580.55	57.8003
1583.64	59.5742
1586.73	60.7853
1589.81	61.6536
1592.9	65.4154
1595.98	67.2397
1599.06	67.5126
1602.15	66.9628
1605.23	66.267
1608.31	65.3109
1611.39	64.2335
1614.46	62.2889
1617.54	61.1209
1620.61	58.7847
1623.69	56.3659
1626.76	55.6477
1629.83	55.5632
1632.9	56.425
1635.97	56.6299
1639.04	56.8638
1642.11	57.9441
1645.17	60.7223
1648.24	62.0723
1651.3	63.8333
1654.36	64.7515
1657.42	67.3073
1660.48	66.1259
1663.54	65.5945
1666.6	66.3598
1669.66	65.6668
1672.71	63.4342
1675.77	61.3109
1678.82	57.0014
1681.87	52.6229
1684.92	49.1646
1687.97	43.626
1691.02	39.8475
1694.07	33.3441
1697.11	26.965
1700.16	21.69
1703.2	17.2436
1706.25	13.3852
1709.29	9.4909
1712.33	7.11029
1715.37	4.35296
1718.41	3.46127
1721.44	3.49592
1724.48	2.39511
1727.51	1.41753
1730.55	2.52988
1733.58	2.46512
1736.61	2.36915
1739.64	2.21409
1742.67	3.63736
1745.7	2.94856
1748.72	4.42526
1751.75	3.42454
1754.77	4.6922
1757.8	4.04054
1760.82	4.44267
1763.84	4.24424
1766.86	2.89001
1769.88	2.52261
1772.9	1.94656
1775.91	3.10577
1778.93	3.59674
1781.94	3.35725
1784.96	3.7683
1787.97	3.14492
1790.98	3.36409
1793.99	2.81424
1797	2.58646
1800.01	2.31895
1803.01	3.11047
1806.02	3.87239
1809.02	2.65676
1812.02	2.27671
1815.02	1.38412
1818.03	2.55596
1821.02	3.3363
1824.02	3.67162
1827.02	5.06852
1830.02	5.52368
1833.01	6.90619
1836.01	6.25652
1839	6.23295
1841.99	6.35473
1844.98	6.78123
1847.97	5.90984
1850.96	7.14368
1853.95	6.05994
1856.93	8.19151
1859.92	7.76391
1862.9	7.81905
1865.88	7.68449
1868.87	8.55087
1871.85	9.7049
1874.83	9.11825
1877.81	8.94146
1880.78	7.09769
1882.53	5.33178
1885.52	4.36267
1888.51	4.92327
1891.5	4.50032
1894.48	4.77577
1897.47	4.45073
1900.45	3.94876
1903.43	4.51257
1906.41	6.44793
1909.39	5.97239
1912.37	6.25846
1915.35	7.86195
1918.33	6.93922
1921.3	7.45289
1924.28	9.46851
1927.25	10.7945
1930.22	10.9078
1933.19	10.6617
1936.16	10.7448
1939.13	10.986
1942.1	10.9023
1945.07	9.6574
1948.03	10.4203
1951	9.88101
1953.96	9.30795
1956.92	8.12231
1959.88	5.60185
1962.84	4.64335
1965.8	4.29006
1968.76	3.36862
1971.72	3.24016
1974.67	3.67244
1977.63	5.82672
1980.58	4.666
1983.54	5.41902
1986.49	5.82092
1989.44	6.77684
1992.39	7.69662
1995.33	8.95232
1998.28	10.0039
2001.23	8.86867
2004.17	10.2838
2007.12	10.3086
2010.06	12.2875
2013	12.0288
2015.94	13.2123
2018.88	14.7209
2021.82	14.2023
2024.76	13.0387
2027.69	11.1661
2030.63	8.86773
2033.56	8.53388
2036.5	6.78411
2039.43	4.87756
2042.36	4.50158
2045.29	4.46098
2048.22	2.77966
2051.15	3.02973
2054.07	3.4606
2057	3.40981
2059.92	3.97293
2062.85	4.39999
2065.77	4.78471
2068.69	4.91577
2071.61	6.18483
2074.53	5.49181
2077.45	7.6705
2080.37	8.45936
2083.28	9.72403
2086.2	9.44891
2089.11	9.83898
2092.02	8.3157
2094.94	8.36875
2097.85	7.14611
2100.76	6.14958
2103.66	6.45356
2106.57	4.55911
2109.48	3.875
2112.38	3.60475
2115.29	3.49705
2118.19	3.06659
2121.09	4.35944
2123.99	2.91598
2126.89	4.5653
2129.79	2.66149
2132.69	2.25946
2135.59	3.27593
2138.48	4.66509
2141.38	4.41083
2144.27	5.12576
2147.17	5.93417
2150.06	6.69657
2152.95	8.98914
2155.84	8.95514
2158.73	8.56771
2161.61	7.86026
2164.5	6.88666
2167.38	7.15692
2170.27	6.22152
2173.15	7.80846
2176.03	8.6104
2178.91	8.4733
2181.8	7.49727
2184.67	6.86974
2187.55	6.73282
2190.43	6.55267
2193.3	5.7928
2196.18	4.85337
2199.05	5.18637
2201.93	5.44914
2204.8	5.636
2207.67	6.39132
2210.54	6.61285
2213.41	8.15747
2216.27	10.0535
2219.14	12.4469
2222.01	14.0874
2224.87	13.4072
2227.73	12.028
2230.6	12.5986
2233.46	12.7857
2236.32	15.6611
2239.18	15.2717
2242.03	15.2188
2244.89	16.2618
2247.75	16.4697
2250.6	14.2065
2253.46	13.4193
2256.31	13.3869
2259.16	12.5234
2262.01	12.7028
2264.86	11.7573
2267.71	10.0872
2270.56	9.8087
2273.4	8.09272
2276.25	8.71075
2279.09	8.20478
2281.94	8.84088
2284.78	8.91054
2287.62	10.2371
2290.46	10.2184
2293.3	8.58194
2296.14	9.35503
2298.98	9.98979
2301.82	11.5144
2304.65	12.1225
2307.49	11.8654
2310.32	11.4077
2313.15	11.7216
2315.98	12.0176
2318.81	12.1709
2321.64	12.3636
2324.47	12.811
2327.3	11.1661
2330.12	9.58695
2332.95	9.1168
2335.77	7.1664
2338.6	8.33761
2341.42	7.08078
2344.24	5.63212
2347.06	4.79362
2349.88	4.84625
2352.7	5.5013
2355.51	4.66607
2358.33	3.2961
2361.14	2.36908
2363.96	3.39501
2366.77	4.28591
2369.58	4.24854
2372.39	5.2708
2375.2	5.65128
2378.01	5.90317
2380.82	6.85846
2383.63	7.04877
2386.43	8.54482
2389.24	9.86557
2392.04	10.0996
2394.84	9.64049
2397.65	10.1844
2400.45	10.7439
2403.25	12.7132
2406.05	12.362
2408.84	11.8737
2411.64	10.916
2414.44	11.464
2417.23	10.1516
2420.02	10.7992
2422.82	9.39577
2425.61	7.47665
2428.4	7.33163
2431.19	7.96762
2433.98	9.52968
2436.77	8.4744
2439.55	8.93527
2442.34	9.00119
2445.12	9.46575
2447.91	10.1591
2450.69	10.6048
2453.47	11.0891
2456.25	11.6913
2459.03	11.168
2461.81	9.816
2464.59	8.42228
2467.36	7.27105
2470.14	6.704
2472.92	6.39446
2475.69	4.95516
2478.46	4.9348
2481.23	5.61029
2484	5.39685
2486.77	5.83467
2489.54	4.92497
2492.31	4.44013
2495.08	4.09006
2497.84	5.68142
2500.61	7.91523
2503.37	7.73842
2506.13	8.70209
2508.9	10.9894
2511.66	12.088
2514.42	12.1751
2517.18	11.7093
2519.93	12.4831
2522.69	12.5838
2525.45	12.7145
2528.2	11.9952
2530.95	12.9963
2533.71	12.963
2536.46	13.7226
2539.21	14.2423
2541.96	15.695
2544.71	16.2213
2547.46	16.5729
2550.2	16.2167
2552.95	16.9562
2555.7	16.0567
2558.44	15.6477
2561.18	16.3315
2563.93	17.8254
2566.67	18.9596
2569.41	19.904
2572.15	19.7334
2574.88	20.4335
2577.62	18.7889
2580.36	18.9138
2583.09	17.2334
2585.83	16.5107
2588.56	16.2988
2591.29	15.4432
2594.02	15.0836
2596.75	14.5916
2599.48	14.5741
2602.21	13.2156
2604.94	13.4279
2607.67	11.9914
2610.39	11.8462
2613.12	12.0124
2615.84	11.0867
2618.56	11.3138
2621.28	11.9896
2624.01	13.1764
2626.72	13.7798
2629.44	14.8898
2632.16	16.1392
2634.88	17.5928
2637.59	18.5014
2640.31	18.3846
2643.02	17.2605
2645.74	16.8463
2648.45	16.2573
2651.16	15.777
2653.87	14.6278
2656.58	13.7674
2659.29	12.8226
2661.99	13.4652
2664.7	14.8034
2667.41	15.4293
2670.11	15.3175
2672.81	14.813
2675.51	16.6849
2678.22	16.8716
2680.92	16.3321
2683.62	15.9806
2686.31	15.7557
2689.01	16.3032
2691.71	18.6236
2694.4	18.3991
2697.1	20.1993
2699.79	22.5319
2702.49	22.0568
2705.18	21.9395
2707.87	22.0027
2710.56	21.0653
2713.25	20.553
2715.94	20.7307
2718.62	21.1845
2721.31	21.3497
2723.99	21.4947
2726.68	22.2913
2729.36	22.7245
2732.04	21.1127
2734.73	19.7258
2737.41	18.4306
2740.08	17.0842
2742.76	16.2375
2745.44	14.5961
2748.12	13.527
2750.79	11.5085
2753.47	11.9372
2756.14	10.6922
2758.81	10.0146
2761.49	9.00232
2764.16	8.17714
2766.83	6.35348
2769.5	5.51019
2772.16	5.90155
2774.83	4.45288
2777.5	3.15374
2780.16	3.84153
2782.83	4.0118
2785.49	3.21036
2788.15	2.675
2790.82	2.23636
2793.48	0.401607
2796.14	0.853434
2798.79	0.180949
2801.45	-0.39412
2804.11	0.278346
2806.76	0.0922558
2809.42	-1.49178
2812.07	-1.45597
2814.73	-0.421202
2817.38	1.77722
2820.03	4.595
2822.68	8.15284
2825.33	12.5583
2827.98	18.8738
2830.63	24.9487
2833.27	32.3965
2835.92	40.025
2838.56	47.5173
2841.21	54.848
2843.85	64.0095
2846.49	74.0831
2849.13	83.1718
2851.77	93.2194
2854.41	103.119
2857.05	112.726
2859.69	121.24
2862.32	130.167
2864.96	137.053
2867.59	143.214
2870.23	146.876
2872.86	149.546
2875.49	153.833
2878.12	157.14
2880.75	161.904
2883.38	163.71
2886.01	165.82
2888.63	168.516
2891.26	170.949
2893.89	173.421
2896.51	176.748
2899.13	180.031
2901.76	184.766
2904.38	189.727
2907	197.601
2909.62	204.314
2912.24	213.571
2914.85	221.627
2917.47	227.838
2920.09	234.28
2922.7	238.619
2925.32	241.779
2927.93	244.457
2930.54	244.961
2933.15	244.152
2935.76	240.808
2938.37	236.24
2940.98	231.492
2943.59	225.095
2946.2	217.529
2948.8	206.858
2951.41	197.95
2954.01	188.756
2956.62	178.34
2959.22	169.092
2961.82	158.584
2964.42	149.863
2967.02	142.568
2969.62	135.227
2972.22	128.056
2974.81	120.738
2977.41	112.043
2980	103.652
2982.6	95.6664
2985.19	86.7551
2987.78	77.8816
2990.38	69.8487
2992.97	61.0336
2995.56	52.6639
2998.14	45.9196
3000.73	38.3135
3003.32	32.6098
3005.91	26.8783
3008.49	21.8128
3011.07	15.9967
3013.66	11.6806
3016.24	8.44989
3018.82	4.72539
3021.4	2.00386
3023.98	0.116824
3026.56	-0.647914
3029.14	-0.526775
3031.71	-0.663133
3034.29	-1.41505
3036.87	-0.162942
3039.44	0.382776
3042.01	2.17496
3044.59	4.20651
3047.16	4.37171
3049.73	4.85985
3052.3	5.74604
3054.87	6.75458
3057.43	8.01225
3060	10.4318
3062.57	11.9583
3065.13	11.8523
3067.7	13.0375
3070.26	14.0605
3072.82	16.3412
3075.39	17.7102
3077.95	18.6857
3080.51	19.8526
3083.07	21.1097
3085.63	24.0393
3088.18	25.2118
3090.74	27.4602
3093.29	29.2068
3095.85	32.2966
3098.4	34.7691
3100.95	37.3792
3103.51	40.3654
3106.06	43.9492
3108.61	46.3024
3111.16	49.7812
3113.71	53.4616
3116.25	56.778
3118.8	60.2886
3121.35	63.2517
3123.89	67.563
3126.44	70.7187
3128.98	74.1246
3131.52	79.3907
3134.06	84.3718
3136.6	89.8808
3139.14	93.8033
3141.68	99.2107
3144.22	104.834
3146.76	110.089
3149.29	115.352