File: data/Raman/poly_smoothed/Mb_00_13_20_1x_45s_532 nm_x100_100%_600 gr_mm_02.txt
#Acq. time (s)=	45
#Accumulations=	2
#Range (cm-¹)=	200...3150
#Windows=	2
#Auto scanning=	Off
#Autofocus=	Off
#Macrospot=	Off
#AutoExposure=	Off
#Spike filter=	Multiple accum.
#Delay time (s)=	0
#Binning=	1
#Readout mode=	Signal
#DeNoise=	Off
#ICS correction=	On
#Dark correction=	Off
#Inst. Process=	Off
#Detector Gain=	Best Dynamic Range
#Detector ADC=	20 kHz
#Detector temperature (°C)=	-69.85
#Instrument=	LabRAM HR Evol
#Detector=	Synapse
#Objective=	x100
#Grating=	600 gr/mm
#ND Filter=	100%
#Laser (nm)=	532
#Hole=	100.021
#Range=	Auto
#Laser Pol.=	No
#Raman. Pol.=	No
#Laser Pol. (°)=	-0.0007625
#Raman Pol. (°)=	89.9995
#Collection=	Microscope
#StageXY=	Marzhauser
#StageZ=	Marzhauser
#X (µm)=	-961.9
#Y (µm)=	-2834.7
#Z (µm)=	528.2
#Full time(mm:ss)=	3:18
#Project=
#Sample=
#Site=
#Title=	Mb_00_13_20_2x_45s_532 nm_x100_100%_600 gr_mm
#Remark=
#Date=	06.07.2022 11:16
#Acquired=	06.07.2022 11:16:38
#Base:Fit=	10.08.2022 10:16:56
#Base:Sub=	10.08.2022 10:17:24
#Filter:Polynom=	16.08.2022 10:36:38
#AxisType[0]=Intens
#AxisUnit[0]=Cnt
#AxisType[1]=Spectr
#AxisUnit[1]=1/cm
200.398	-79.3719
204.027	-81.3362
207.657	-84.7085
211.283	-82.248
214.909	-76.0473
218.533	-63.9227
222.157	-50.9953
225.777	-35.1318
229.396	-23.8543
233.016	-9.4768
236.632	3.28827
240.247	12.5966
243.86	18.5545
247.474	29.7696
251.085	38.0605
254.694	45.2859
258.301	50.1137
261.908	51.6573
265.513	53.4692
269.116	55.4967
272.718	51.211
276.319	47.8376
279.918	37.9093
283.516	30.6513
287.113	22.2001
290.708	16.5665
294.302	12.6498
297.894	13.7241
301.485	13.8146
305.073	17.167
308.661	21.3669
312.247	21.6863
315.833	21.1509
319.415	22.1135
322.997	24.1597
326.579	23.5525
330.156	21.217
333.735	23.279
337.31	24.2981
340.885	21.4534
344.458	18.689
348.03	15.3219
351.6	12.3592
355.17	12.4411
358.737	9.98481
362.304	8.28826
365.868	10.541
369.431	15.0329
372.994	22.0581
376.554	28.3903
380.112	36.5204
383.669	49.5347
387.225	64.7104
390.781	81.002
394.334	97.7677
397.885	110.945
401.436	120.011
404.984	130.046
408.532	134.475
412.078	137.691
415.623	137.326
419.166	138.938
422.708	133.108
426.248	127.642
429.788	117.707
433.326	105.925
436.86	94.9748
440.395	84.5632
443.929	72.631
447.461	59.3356
450.99	51.4162
454.52	43.2565
458.048	36.1907
461.573	30.3944
465.099	27.6601
468.623	29.7232
472.144	33.7623
475.666	36.9165
479.184	38.3353
482.703	43.8016
486.218	43.2072
489.734	45.2563
493.247	49.4938
496.759	52.3866
500.271	54.7431
503.779	55.7453
507.287	55.1825
510.795	56.4542
514.299	50.3141
517.803	49.08
521.305	48.7224
524.805	47.3568
528.307	43.7481
531.805	40.476
535.301	36.498
538.797	35.2962
542.291	34.0158
545.783	32.3335
549.275	27.504
552.765	24.9647
556.253	20.042
559.738	16.7157
563.224	12.0785
566.709	10.7599
570.192	10.4259
573.674	10.1563
577.153	8.52079
580.632	6.39954
584.11	3.83213
587.587	2.25305
591.06	0.493715
594.534	-4.44473
598.005	-2.73081
601.476	-2.57943
604.944	-1.41381
608.413	-1.30066
611.878	-1.39471
615.344	0.484184
618.807	0.249671
622.27	1.69709
625.73	6.67899
629.189	11.9323
632.648	16.8706
636.105	21.2388
639.559	25.6756
643.013	28.6803
646.467	30.7691
649.918	34.1555
653.368	34.2664
656.816	33.7951
660.263	34.0008
663.708	30.922
667.153	31.9256
670.596	28.8285
674.037	24.5954
677.478	23.7838
680.917	22.4502
684.355	22.1067
687.791	16.2822
691.224	11.629
694.658	8.1938
698.091	8.08281
701.522	6.88137
704.95	4.45795
708.379	5.52048
711.806	4.01208
715.23	3.38317
718.655	2.66426
722.078	0.310986
725.498	-1.19017
728.919	-0.164031
732.337	2.18966
735.755	4.73467
739.17	6.81608
742.584	11.2512
745.998	15.7024
749.409	20.5339
752.819	28.1626
756.23	35.8321
759.637	43.3789
763.043	51.1129
766.448	57.7871
769.853	58.7859
773.255	61.5288
776.656	63.4637
780.056	66.3854
783.454	65.8096
786.851	64.4872
790.247	59.3085
793.641	54.8098
797.034	50.6023
800.426	47.5724
803.817	45.193
807.206	43.5586
810.592	41.198
813.979	42.3331
817.364	41.9665
820.748	41.5858
824.129	41.4759
827.511	38.3841
830.891	35.7246
834.269	34.8022
837.646	33.8603
841.023	34.0102
844.396	33.4458
847.77	29.4718
851.141	25.616
854.513	21.7574
857.881	22.6508
861.248	21.8888
864.616	20.1005
867.98	20.9122
871.343	19.1779
874.707	17.4207
878.068	16.9812
881.428	16.2005
884.786	16.4909
888.143	18.0233
891.498	23.114
894.855	23.3536
898.208	26.8464
901.56	25.9514
904.91	25.0632
908.26	25.5843
911.608	23.4909
914.955	25.4996
918.298	29.3641
921.643	30.9688
924.986	31.9182
928.328	30.5727
931.668	31.7246
935.006	33.1226
938.344	34.7693
941.681	37.918
945.014	41.0948
948.349	39.9501
951.682	40.4457
955.012	38.479
958.343	38.2431
961.67	39.0883
964.998	40.9169
968.323	50.4908
971.649	59.4524
974.971	72.1252
978.293	85.9509
981.615	99.4976
984.933	111.044
988.251	128.313
991.567	138.161
994.884	152.496
998.198	160.832
1001.51	173.378
1004.82	176.161
1008.13	177.629
1011.44	178.137
1014.75	183.18
1018.06	185.17
1021.36	190.984
1024.66	194.005
1027.97	195.579
1031.27	194.393
1034.57	194.781
1037.87	189.285
1041.16	189.69
1044.46	191.238
1047.76	192.106
1051.05	194.761
1054.34	199.704
1057.63	204.677
1060.92	203.733
1064.21	206.966
1067.5	207.373
1070.78	204.644
1074.07	201.809
1077.35	199.733
1080.63	193.033
1083.91	187.761
1087.19	179.961
1090.47	175.275
1093.75	180.592
1097.03	183.743
1100.3	188.907
1103.57	190.045
1106.84	192.748
1110.11	194.14
1113.38	197.349
1116.65	198.991
1119.92	204.363
1123.19	209.735
1126.45	213.441
1129.71	218.96
1132.97	227.577
1136.23	236.64
1139.49	244.316
1142.75	255.676
1146.01	264.188
1149.26	273.1
1152.52	278.467
1155.77	287.471
1159.02	294.457
1162.27	298.474
1165.52	305.438
1168.77	311.869
1172.02	318.64
1175.26	327.251
1178.51	331.848
1181.75	344.771
1184.99	354.48
1188.23	363.202
1191.47	374.806
1194.71	384.453
1197.94	395.043
1201.18	408.103
1204.41	420.305
1207.65	432.292
1210.88	449.648
1214.11	465.853
1217.34	482.02
1220.57	499.184
1223.79	513.278
1227.02	527.741
1230.24	537.496
1233.47	548.976
1236.69	564.1
1239.91	571.943
1243.13	585.393
1246.34	593.743
1249.56	602.526
1252.78	611.269
1255.99	622.002
1259.2	631.459
1262.42	643.048
1265.63	652.577
1268.84	661.005
1272.04	673.814
1275.25	684.29
1278.46	700.102
1281.66	711.76
1284.86	728.854
1288.07	744.598
1291.27	761.799
1294.47	778.732
1297.66	795.651
1300.86	811.452
1304.06	832.343
1307.25	848.703
1310.44	864.808
1313.64	883.975
1316.83	900.89
1320.02	910.438
1323.2	922.289
1326.39	930.98
1329.58	940.102
1332.76	948.626
1335.95	957.279
1339.13	965.539
1342.31	968.668
1345.49	970.929
1348.67	971.544
1351.85	972.35
1355.02	967.837
1358.2	964.133
1361.37	957.599
1364.54	950.578
1367.71	945.25
1370.88	935.439
1374.05	925.967
1377.22	914.051
1380.39	905.237
1383.55	893.61
1386.72	881.618
1389.88	868.252
1393.04	858.985
1396.2	845.664
1399.36	837.726
1402.52	834.142
1405.68	828.097
1408.83	821.916
1411.98	820.898
1415.14	821.709
1418.29	824.41
1421.44	827.619
1424.59	833.309
1427.74	840.989
1430.89	844.925
1434.03	850.36
1437.18	856.098
1440.32	858.523
1443.46	861.737
1446.6	859.29
1449.74	852.485
1452.88	847.654
1456.02	837.369
1459.16	830.526
1462.29	819.776
1465.43	806.973
1468.56	794.042
1471.69	781.722
1474.82	771.197
1477.95	758.162
1481.08	745.823
1484.2	733.986
1487.33	724.24
1490.46	721.546
1493.58	718.247
1496.7	717.477
1499.82	716.349
1502.94	719.6
1506.06	722.099
1509.18	725.263
1512.29	731.503
1515.41	736.62
1518.52	743.16
1521.63	749.417
1524.75	755.995
1527.85	759.394
1530.96	767.078
1534.07	776.901
1537.18	788.803
1540.28	797.39
1543.39	810.71
1546.49	823.488
1549.59	835.145
1552.69	848.519
1555.79	860.574
1558.89	873.889
1561.99	884.054
1565.08	896.14
1568.18	904.937
1571.27	912.875
1574.37	918.629
1577.46	924.028
1580.55	930.868
1583.64	933.792
1586.73	931.49
1589.81	928.831
1592.9	921.66
1595.98	905.728
1599.06	887.649
1602.15	861.487
1605.23	833.612
1608.31	805.619
1611.39	773.264
1614.46	737.365
1617.54	702.499
1620.61	666.684
1623.69	633.404
1626.76	600.017
1629.83	568.547
1632.9	535.188
1635.97	504.659
1639.04	470.415
1642.11	442.269
1645.17	417.68
1648.24	394.594
1651.3	374.307
1654.36	355.236
1657.42	338.797
1660.48	319.337
1663.54	298.926
1666.6	279.689
1669.66	261.332
1672.71	240.722
1675.77	222.318
1678.82	201.014
1681.87	180.318
1684.92	161.212
1687.97	141.892
1691.02	125.048
1694.07	111.122
1697.11	96.8765
1700.16	86.3593
1703.2	72.7822
1706.25	62.615
1709.29	52.8015
1712.33	44.9112
1715.37	38.486
1718.41	29.2833
1721.44	23.1763
1724.48	20.7358
1727.51	16.0016
1730.55	12.7018
1733.58	10.5165
1736.61	6.0182
1739.64	4.6169
1742.67	4.6107
1745.7	4.41173
1748.72	6.60114
1751.75	6.72598
1754.77	5.5072
1757.8	5.75132
1760.82	4.64835
1763.84	3.4361
1766.86	3.43119
1769.88	5.58721
1772.9	5.14482
1775.91	3.811
1778.93	4.4613
1781.94	4.72186
1784.96	3.97255
1787.97	3.2282
1790.98	1.0178
1793.99	1.25957
1797	5.0526
1800.01	6.96679
1803.01	7.47246
1806.02	5.32909
1809.02	2.45235
1812.02	2.68008
1815.02	2.55438
1818.03	2.46873
1821.02	2.31922
1824.02	0.173271
1827.02	1.51798
1830.02	3.1339
1833.01	2.72982
1836.01	3.87347
1839	3.86639
1841.99	3.67181
1844.98	4.62565
1847.97	6.68468
1850.96	4.64147
1853.95	6.15019
1856.93	6.32464
1859.92	6.03263
1862.9	9.73703
1865.88	11.3798
1868.87	16.9773
1871.85	15.6401
1874.83	14.606
1877.81	12.0821
1880.78	10.9221
1882.53	10.4803
1885.52	7.80605
1888.51	10.8178
1891.5	11.6382
1894.48	14.8906
1897.47	20.9906
1900.45	28.7447
1903.43	29.4756
1906.41	30.2691
1909.39	32.3975
1912.37	30.9735
1915.35	34.6722
1918.33	34.5985
1921.3	33.3802
1924.28	35.7664
1927.25	35.7313
1930.22	31.2319
1933.19	27.5251
1936.16	27.902
1939.13	23.3958
1942.1	18.9457
1945.07	16.4922
1948.03	16.4242
1951	12.1293
1953.96	10.9202
1956.92	10.7915
1959.88	10.7205
1962.84	16.6968
1965.8	14.8193
1968.76	20.236
1971.72	27.3972
1974.67	25.4498
1977.63	27.0911
1980.58	25.9485
1983.54	28.2746
1986.49	28.3134
1989.44	32.6713
1992.39	30.9737
1995.33	38.4461
1998.28	37.8656
2001.23	32.6407
2004.17	34.4078
2007.12	39.9125
2010.06	42.2581
2013	46.2174
2015.94	47.2746
2018.88	51.4851
2021.82	51.2102
2024.76	51.3107
2027.69	55.7583
2030.63	58.7632
2033.56	61.5573
2036.5	64.8864
2039.43	68.2184
2042.36	72.6085
2045.29	73.481
2048.22	68.1181
2051.15	65.6586
2054.07	63.0999
2057	60.7141
2059.92	63.5888
2062.85	57.2045
2065.77	56.4314
2068.69	57.8808
2071.61	56.558
2074.53	55.4076
2077.45	59.3629
2080.37	57.1709
2083.28	56.7015
2086.2	60.2755
2089.11	64.5356
2092.02	63.367
2094.94	64.7205
2097.85	69.7864
2100.76	72.3502
2103.66	74.6869
2106.57	77.0716
2109.48	77.0153
2112.38	75.3184
2115.29	75.8483
2118.19	74.3902
2121.09	70.8935
2123.99	70.9933
2126.89	69.0387
2129.79	65.9532
2132.69	65.1855
2135.59	61.3672
2138.48	60.7815
2141.38	61.7453
2144.27	60.4927
2147.17	64.7498
2150.06	62.3792
2152.95	62.4866
2155.84	61.8582
2158.73	60.4536
2161.61	60.8142
2164.5	62.2354
2167.38	68.1381
2170.27	70.4915
2173.15	75.1316
2176.03	76.6103
2178.91	78.8299
2181.8	77.4533
2184.67	79.6158
2187.55	81.1049
2190.43	78.843
2193.3	77.8707
2196.18	74.971
2199.05	76.2967
2201.93	78.9508
2204.8	75.3342
2207.67	74.7948
2210.54	76.2608
2213.41	80.8689
2216.27	77.2333
2219.14	76.5461
2222.01	74.817
2224.87	77.8063
2227.73	78.6572
2230.6	82.7788
2233.46	87.4834
2236.32	90.2455
2239.18	90.6839
2242.03	91.7463
2244.89	93.5225
2247.75	91.5978
2250.6	87.1219
2253.46	84.9029
2256.31	81.916
2259.16	81.028
2262.01	78.2179
2264.86	76.4051
2267.71	75.9141
2270.56	70.6347
2273.4	69.1191
2276.25	66.6162
2279.09	67.4304
2281.94	67.7653
2284.78	67.444
2287.62	68.299
2290.46	63.4687
2293.3	63.7129
2296.14	65.116
2298.98	64.0601
2301.82	60.6681
2304.65	58.6423
2307.49	54.6186
2310.32	55.096
2313.15	53.6048
2315.98	51.5032
2318.81	47.1006
2321.64	45.5962
2324.47	42.2768
2327.3	40.8471
2330.12	40.1855
2332.95	40.4522
2335.77	37.3671
2338.6	33.9683
2341.42	33.0442
2344.24	34.1392
2347.06	31.3612
2349.88	31.7579
2352.7	33.6403
2355.51	31.7171
2358.33	29.7043
2361.14	28.8082
2363.96	28.0252
2366.77	28.2358
2369.58	31.6918
2372.39	34.3188
2375.2	34.9085
2378.01	35.1716
2380.82	35.1442
2383.63	36.7047
2386.43	36.4427
2389.24	35.0294
2392.04	32.9025
2394.84	37.4711
2397.65	38.6991
2400.45	36.2818
2403.25	37.1324
2406.05	30.5117
2408.84	27.9148
2411.64	30.6719
2414.44	34.3819
2417.23	33.8353
2420.02	34.2938
2422.82	32.9683
2425.61	30.9962
2428.4	29.8304
2431.19	25.7081
2433.98	28.3289
2436.77	31.4548
2439.55	30.5649
2442.34	25.229
2445.12	22.6376
2447.91	21.0969
2450.69	20.5183
2453.47	19.4858
2456.25	15.5976
2459.03	12.4172
2461.81	10.1935
2464.59	6.55111
2467.36	5.87531
2470.14	7.03118
2472.92	3.17584
2475.69	6.19459
2478.46	8.42251
2481.23	8.45914
2484	7.10825
2486.77	0.753732
2489.54	1.7308
2492.31	0.0284101
2495.08	-0.420763
2497.84	0.148439
2500.61	-0.600396
2503.37	5.78667
2506.13	4.85299
2508.9	2.70403
2511.66	7.04864
2514.42	10.6674
2517.18	13.5137
2519.93	16.2082
2522.69	21.8117
2525.45	25.0512
2528.2	28.9171
2530.95	36.2428
2533.71	39.3043
2536.46	43.6367
2539.21	46.4719
2541.96	48.1998
2544.71	50.5139
2547.46	49.836
2550.2	49.5498
2552.95	47.8013
2555.7	50.7635
2558.44	49.4814
2561.18	49.8228
2563.93	47.4664
2566.67	47.7802
2569.41	48.1784
2572.15	42.8739
2574.88	38.4317
2577.62	38.8983
2580.36	36.3545
2583.09	38.7556
2585.83	38.7928
2588.56	35.0105
2591.29	33.7166
2594.02	35.5718
2596.75	34.9379
2599.48	34.0568
2602.21	31.1935
2604.94	29.339
2607.67	28.8762
2610.39	31.3888
2613.12	28.932
2615.84	28.5148
2618.56	29.3257
2621.28	29.2428
2624.01	32.0702
2626.72	35.1939
2629.44	33.2817
2632.16	37.8741
2634.88	38.9145
2637.59	39.2601
2640.31	36.2627
2643.02	40.375
2645.74	42.3719
2648.45	43.1302
2651.16	43.5266
2653.87	41.1383
2656.58	41.0415
2659.29	40.8008
2661.99	41.0841
2664.7	40.0383
2667.41	43.0471
2670.11	44.0187
2672.81	45.8102
2675.51	47.4845
2678.22	47.2994
2680.92	45.6014
2683.62	43.1072
2686.31	44.8387
2689.01	45.6544
2691.71	48.2706
2694.4	46.5343
2697.1	48.18
2699.79	50.2591
2702.49	53.1014
2705.18	55.1724
2707.87	55.2353
2710.56	58.1817
2713.25	59.9582
2715.94	59.025
2718.62	58.6734
2721.31	60.2384
2723.99	62.4246
2726.68	63.1682
2729.36	61.7509
2732.04	59.3546
2734.73	59.6642
2737.41	59.0097
2740.08	55.4534
2742.76	48.646
2745.44	45.2879
2748.12	41.441
2750.79	38.2047
2753.47	32.4194
2756.14	30.4659
2758.81	28.1386
2761.49	22.8822
2764.16	18.7253
2766.83	18.1635
2769.5	17.3676
2772.16	16.9131
2774.83	17.1078
2777.5	16.9906
2780.16	18.7439
2782.83	20.5407
2785.49	25.1867
2788.15	26.2005
2790.82	24.5291
2793.48	23.8823
2796.14	23.2546
2798.79	25.1277
2801.45	26.4316
2804.11	20.7341
2806.76	16.8912
2809.42	9.99176
2812.07	8.66577
2814.73	8.64567
2817.38	5.5222
2820.03	9.34132
2822.68	11.8578
2825.33	14.4482
2827.98	21.4997
2830.63	32.7791
2833.27	43.7831
2835.92	57.2198
2838.56	74.7944
2841.21	92.1541
2843.85	112.871
2846.49	136.32
2849.13	166.173
2851.77	192.38
2854.41	217.781
2857.05	239.761
2859.69	261.469
2862.32	283.486
2864.96	302.253
2867.59	313.409
2870.23	326.041
2872.86	335.339
2875.49	346.893
2878.12	358.526
2880.75	365.037
2883.38	376.887
2886.01	384.641
2888.63	392.575
2891.26	400.224
2893.89	410.849
2896.51	420.894
2899.13	433.186
2901.76	450.044
2904.38	471.504
2907	493.059
2909.62	520.833
2912.24	548.346
2914.85	571.761
2917.47	593.289
2920.09	611.714
2922.7	622.944
2925.32	634.203
2927.93	638.719
2930.54	635.677
2933.15	629.831
2935.76	618.847
2938.37	603.097
2940.98	585.58
2943.59	561.588
2946.2	539.755
2948.8	513.942
2951.41	488.929
2954.01	461.95
2956.62	435.21
2959.22	408.466
2961.82	384.175
2964.42	363.751
2967.02	345.412
2969.62	328.333
2972.22	310.039
2974.81	294.96
2977.41	275.2
2980	260.056
2982.6	242.426
2985.19	222.237
2987.78	199.642
2990.38	179.368
2992.97	159.474
2995.56	141.092
2998.14	120.48
3000.73	99.7716
3003.32	79.6789
3005.91	64.1566
3008.49	49.2094
3011.07	36.8722
3013.66	27.5034
3016.24	20.2617
3018.82	10.9148
3021.4	6.61959
3023.98	3.01919
3026.56	2.33483
3029.14	1.35168
3031.71	1.64783
3034.29	0.339277
3036.87	1.50371
3039.44	5.60008
3042.01	10.1898
3044.59	14.1744
3047.16	18.7016
3049.73	20.4211
3052.3	28.4503
3054.87	30.0171
3057.43	36.046
3060	37.9673
3062.57	39.1716
3065.13	42.2638
3067.7	45.8875
3070.26	49.5168
3072.82	56.3153
3075.39	58.8098
3077.95	63.3365
3080.51	64.2546
3083.07	66.6297
3085.63	69.0325
3088.18	71.9474
3090.74	73.0669
3093.29	75.6232
3095.85	77.2576
3098.4	86.6777
3100.95	96.3698
3103.51	104.698
3106.06	115.183
3108.61	121.322
3111.16	132.108
3113.71	144.312
3116.25	153.785
3118.8	162.872
3121.35	175.055
3123.89	183.551
3126.44	196.309
3128.98	207.505
3131.52	218.162
3134.06	228.024
3136.6	233.017
3139.14	238.336
3141.68	242.228
3144.22	245.701
3146.76	247.876
3149.29	255.716