File: data/Raman/poly_smoothed/Mb_00_13_50_1x_45s_532 nm_x100_100%_600 gr_mm_01.txt
#Acq. time (s)=	45
#Accumulations=	2
#Range (cm-¹)=	200...3150
#Windows=	2
#Auto scanning=	Off
#Autofocus=	Off
#Macrospot=	Off
#AutoExposure=	Off
#Spike filter=	Multiple accum.
#Delay time (s)=	0
#Binning=	1
#Readout mode=	Signal
#DeNoise=	Off
#ICS correction=	On
#Dark correction=	Off
#Inst. Process=	Off
#Detector Gain=	Best Dynamic Range
#Detector ADC=	20 kHz
#Detector temperature (°C)=	-69.85
#Instrument=	LabRAM HR Evol
#Detector=	Synapse
#Objective=	x100
#Grating=	600 gr/mm
#ND Filter=	100%
#Laser (nm)=	532
#Hole=	100.021
#Range=	Auto
#Laser Pol.=	No
#Raman. Pol.=	No
#Laser Pol. (°)=	-0.0007625
#Raman Pol. (°)=	89.9995
#Collection=	Microscope
#StageXY=	Marzhauser
#StageZ=	Marzhauser
#X (µm)=	-1083.4
#Y (µm)=	-2881.7
#Z (µm)=	528.95
#Full time(mm:ss)=	3:15
#Project=
#Sample=
#Site=
#Title=	Mb_00_13_50_2x_45s_532 nm_x100_100%_600 gr_mm
#Remark=
#Date=	06.07.2022 13:55
#Acquired=	06.07.2022 13:55:59
#Base:Fit=	10.08.2022 10:16:56
#Base:Sub=	10.08.2022 10:17:24
#Filter:Polynom=	16.08.2022 10:36:38
#AxisType[0]=Intens
#AxisUnit[0]=Cnt
#AxisType[1]=Spectr
#AxisUnit[1]=1/cm
200.398	23.1007
204.027	13.9621
207.657	0.098985
211.283	-10.3004
214.909	-12.1259
218.533	-3.7651
222.157	12.0141
225.777	27.8708
229.396	50.2444
233.016	73.8015
236.632	95.3064
240.247	115.699
243.86	131.686
247.474	146.694
251.085	162.628
254.694	174.995
258.301	183.183
261.908	189.196
265.513	189.213
269.116	187.035
272.718	178.632
276.319	167.002
279.918	150.347
283.516	131.192
287.113	112.305
290.708	89.7873
294.302	70.6949
297.894	56.9437
301.485	44.4346
305.073	35.0207
308.661	25.8311
312.247	18.5584
315.833	13.2638
319.415	12.3223
322.997	9.70527
326.579	9.8908
330.156	8.05696
333.735	5.59822
337.31	5.37729
340.885	4.44827
344.458	3.46445
348.03	0.976161
351.6	1.17428
355.17	-1.98196
358.737	-3.2953
362.304	0.0526903
365.868	5.0244
369.431	14.3599
372.994	23.0554
376.554	30.6719
380.112	41.968
383.669	59.2966
387.225	80.0284
390.781	99.7011
394.334	118.815
397.885	136.5
401.436	150.53
404.984	159.861
408.532	170.386
412.078	175.006
415.623	176.51
419.166	170.57
422.708	163.178
426.248	154.38
429.788	140.996
433.326	123.132
436.86	104.018
440.395	83.7138
443.929	64.5248
447.461	49.1149
450.99	37.0244
454.52	22.6776
458.048	9.09687
461.573	-3.06253
465.099	-7.68671
468.623	-6.34347
472.144	-2.86995
475.666	-0.201891
479.184	1.77006
482.703	4.24996
486.218	7.06896
489.734	11.4398
493.247	16.1726
496.759	22.3248
500.271	26.5081
503.779	28.6188
507.287	30.8958
510.795	35.6904
514.299	38.9975
517.803	40.4761
521.305	42.385
524.805	46.5136
528.307	46.6765
531.805	47.5157
535.301	47.6399
538.797	44.4168
542.291	41.6035
545.783	39.6234
549.275	36.3553
552.765	30.6804
556.253	27.0197
559.738	23.1835
563.224	19.6073
566.709	17.6392
570.192	15.513
573.674	13.3685
577.153	11.6954
580.632	9.15402
584.11	8.11375
587.587	7.298
591.06	5.40743
594.534	4.24849
598.005	1.47199
601.476	2.00601
604.944	2.48215
608.413	3.3144
611.878	3.17798
615.344	3.75237
618.807	2.5226
622.27	4.64623
625.73	5.0627
629.189	6.86319
632.648	10.3286
636.105	9.89914
639.559	12.228
643.013	14.6704
646.467	19.6387
649.918	23.1013
653.368	23.7464
656.816	23.2452
660.263	23.1578
663.708	22.0896
667.153	23.7291
670.596	22.5613
674.037	20.6455
677.478	18.1402
680.917	16.1267
684.355	14.6408
687.791	12.9524
691.224	10.1648
694.658	7.07153
698.091	5.77743
701.522	5.63444
704.95	3.83571
708.379	5.58342
711.806	5.00848
715.23	7.25748
718.655	7.82077
722.078	10.1658
725.498	13.6864
728.919	15.5621
732.337	16.0339
735.755	15.0489
739.17	14.1221
742.584	16.352
745.998	19.8769
749.409	21.0866
752.819	27.5466
756.23	28.9416
759.637	30.1542
763.043	30.4224
766.448	30.7067
769.853	31.0295
773.255	31.6362
776.656	30.494
780.056	32.7256
783.454	32.0106
786.851	31.4202
790.247	32.5258
793.641	33.7133
797.034	34.2487
800.426	36.0965
803.817	36.8667
807.206	37.3095
810.592	37.234
813.979	36.7059
817.364	37.2379
820.748	38.7529
824.129	42.8546
827.511	46.9933
830.891	47.6589
834.269	52.6978
837.646	52.6842
841.023	52.7542
844.396	52.6511
847.77	53.6571
851.141	50.1022
854.513	46.8495
857.881	42.5982
861.248	40.2921
864.616	38.4643
867.98	34.1771
871.343	33.2708
874.707	29.9933
878.068	26.4821
881.428	23.5768
884.786	19.6513
888.143	14.8209
891.498	13.5247
894.855	12.5253
898.208	12.054
901.56	12.5531
904.91	13.5119
908.26	15.1832
911.608	15.162
914.955	15.9405
918.298	17.2802
921.643	16.9254
924.986	17.1604
928.328	16.7621
931.668	14.4765
935.006	15.458
938.344	14.3497
941.681	14.8769
945.014	16.1298
948.349	13.2983
951.682	10.7197
955.012	9.72339
958.343	5.40834
961.67	1.93338
964.998	3.8439
968.323	8.0555
971.649	13.47
974.971	21.9347
978.293	26.9513
981.615	34.3426
984.933	40.1368
988.251	44.8413
991.567	49.2994
994.884	53.1832
998.198	57.0933
1001.51	58.088
1004.82	57.9424
1008.13	57.5994
1011.44	56.2076
1014.75	58.1077
1018.06	64.6355
1021.36	74.3046
1024.66	90.8563
1027.97	106.634
1031.27	120.139
1034.57	133.338
1037.87	145.647
1041.16	154.748
1044.46	164.854
1047.76	173.796
1051.05	176.575
1054.34	176.962
1057.63	174.554
1060.92	167.257
1064.21	160.958
1067.5	149.943
1070.78	137.649
1074.07	121.042
1077.35	102.58
1080.63	78.0249
1083.91	53.9125
1087.19	31.8298
1090.47	16.8976
1093.75	8.81226
1097.03	8.98228
1100.3	13.3257
1103.57	17.4822
1106.84	22.9117
1110.11	24.0714
1113.38	26.9192
1116.65	28.9924
1119.92	27.9906
1123.19	25.4701
1126.45	25.4771
1129.71	24.2164
1132.97	21.8072
1136.23	23.29
1139.49	23.4586
1142.75	23.0966
1146.01	24.0201
1149.26	22.0627
1152.52	18.1071
1155.77	14.8224
1159.02	11.2848
1162.27	6.11015
1165.52	4.58728
1168.77	5.60176
1172.02	9.01047
1175.26	9.30427
1178.51	13.197
1181.75	14.4581
1184.99	17.6352
1188.23	21.4255
1191.47	23.6408
1194.71	27.1336
1197.94	31.3131
1201.18	38.0323
1204.41	43.4696
1207.65	48.9768
1210.88	54.9119
1214.11	65.1146
1217.34	73.8889
1220.57	82.2163
1223.79	88.9735
1227.02	96.2185
1230.24	100.722
1233.47	107.78
1236.69	115.11
1239.91	118.507
1243.13	120.468
1246.34	122.223
1249.56	120.449
1252.78	119.384
1255.99	117.502
1259.2	117.647
1262.42	116.318
1265.63	117.46
1268.84	116.258
1272.04	115.565
1275.25	115.066
1278.46	113.526
1281.66	114.204
1284.86	114.32
1288.07	119.341
1291.27	124.229
1294.47	129.49
1297.66	131.702
1300.86	135.395
1304.06	138.451
1307.25	143.093
1310.44	150.512
1313.64	155.087
1316.83	157.772
1320.02	157.464
1323.2	157.089
1326.39	157.017
1329.58	157.338
1332.76	155.915
1335.95	157.097
1339.13	157.852
1342.31	157.535
1345.49	152.988
1348.67	150.411
1351.85	147.59
1355.02	141.941
1358.2	139.198
1361.37	139.723
1364.54	138.242
1367.71	135
1370.88	132.653
1374.05	127.662
1377.22	124.49
1380.39	122.596
1383.55	121.136
1386.72	119.616
1389.88	118.981
1393.04	114.875
1396.2	111.935
1399.36	110.164
1402.52	110.848
1405.68	115.59
1408.83	121.739
1411.98	129.617
1415.14	141.802
1418.29	152.989
1421.44	166.571
1424.59	179.012
1427.74	193.32
1430.89	207.746
1434.03	221.161
1437.18	235.373
1440.32	244.544
1443.46	253.319
1446.6	255.684
1449.74	255.415
1452.88	251.819
1456.02	246.937
1459.16	240.031
1462.29	229.259
1465.43	216.586
1468.56	201.306
1471.69	183.713
1474.82	169.298
1477.95	153.581
1481.08	141.791
1484.2	130.725
1487.33	122.554
1490.46	114.761
1493.58	108.976
1496.7	100.708
1499.82	98.4146
1502.94	96.741
1506.06	96.5846
1509.18	95.3231
1512.29	91.8201
1515.41	91.5646
1518.52	90.584
1521.63	90.3212
1524.75	90.5824
1527.85	89.7538
1530.96	91.4664
1534.07	92.1233
1537.18	95.0157
1540.28	95.14
1543.39	96.4401
1546.49	98.716
1549.59	100.04
1552.69	100.73
1555.79	104.278
1558.89	105.84
1561.99	107.749
1565.08	111.611
1568.18	116.024
1571.27	117.677
1574.37	121.555
1577.46	127.09
1580.55	131.137
1583.64	134.044
1586.73	134.883
1589.81	138.141
1592.9	143.072
1595.98	143.874
1599.06	145.732
1602.15	143.623
1605.23	142.839
1608.31	141.547
1611.39	138.707
1614.46	137.826
1617.54	135.441
1620.61	133.897
1623.69	133.747
1626.76	133.074
1629.83	132.776
1632.9	133.653
1635.97	132.56
1639.04	135.051
1642.11	136.239
1645.17	139.061
1648.24	140.611
1651.3	143.76
1654.36	144.164
1657.42	142.847
1660.48	140.266
1663.54	138.434
1666.6	135.495
1669.66	130.984
1672.71	122.638
1675.77	114.994
1678.82	106.557
1681.87	97.9271
1684.92	90.2309
1687.97	79.2373
1691.02	71.1713
1694.07	64.0023
1697.11	56.9547
1700.16	52.4358
1703.2	44.9844
1706.25	40.3258
1709.29	33.0315
1712.33	28.6521
1715.37	25.9394
1718.41	21.5216
1721.44	20.9929
1724.48	18.1543
1727.51	14.223
1730.55	12.5933
1733.58	12.8059
1736.61	10.5143
1739.64	10.1816
1742.67	9.86787
1745.7	7.65209
1748.72	7.85627
1751.75	8.41273
1754.77	8.55672
1757.8	6.70418
1760.82	8.27422
1763.84	7.02551
1766.86	7.00701
1769.88	7.01442
1772.9	5.62345
1775.91	5.77619
1778.93	4.60753
1781.94	3.7948
1784.96	2.86645
1787.97	2.63701
1790.98	2.27885
1793.99	2.04431
1797	1.91666
1800.01	1.74664
1803.01	2.85029
1806.02	3.56937
1809.02	3.43921
1812.02	1.85546
1815.02	1.29053
1818.03	1.44905
1821.02	3.14588
1824.02	3.87395
1827.02	4.90158
1830.02	5.09133
1833.01	5.12824
1836.01	4.738
1839	6.11561
1841.99	8.30372
1844.98	9.04094
1847.97	10.1309
1850.96	9.61041
1853.95	10.9431
1856.93	10.7652
1859.92	11.5021
1862.9	12.4591
1865.88	12.3815
1868.87	12.1611
1871.85	13.5448
1874.83	14.9066
1877.81	16.7694
1880.78	16.3889
1882.53	14.7488
1885.52	13.1552
1888.51	12.6156
1891.5	13.6349
1894.48	14.5735
1897.47	13.4514
1900.45	13.3275
1903.43	11.3956
1906.41	12.1205
1909.39	12.7174
1912.37	14.4129
1915.35	15.1618
1918.33	16.3055
1921.3	14.5429
1924.28	14.2482
1927.25	16.4355
1930.22	16.9934
1933.19	16.7282
1936.16	14.8532
1939.13	16.0469
1942.1	16.0722
1945.07	18.9591
1948.03	17.9878
1951	16.1417
1953.96	15.2147
1956.92	15.2702
1959.88	14.9715
1962.84	15.7252
1965.8	16.756
1968.76	16.0949
1971.72	14.7864
1974.67	12.4713
1977.63	11.9129
1980.58	13.4664
1983.54	14.1495
1986.49	15.9239
1989.44	16.5573
1992.39	17.7561
1995.33	19.9281
1998.28	21.0696
2001.23	22.483
2004.17	22.6673
2007.12	23.3114
2010.06	23.6774
2013	24.425
2015.94	25.2095
2018.88	23.9789
2021.82	23.105
2024.76	25.3799
2027.69	27.4563
2030.63	27.5091
2033.56	26.2418
2036.5	26.0341
2039.43	24.2735
2042.36	22.6779
2045.29	22.9522
2048.22	23.603
2051.15	22.8436
2054.07	26.3353
2057	24.685
2059.92	25.0661
2062.85	25.475
2065.77	25.7355
2068.69	25.8048
2071.61	25.0396
2074.53	24.6625
2077.45	24.1876
2080.37	23.8208
2083.28	22.5309
2086.2	22.3235
2089.11	21.7063
2092.02	19.7612
2094.94	19.4592
2097.85	17.5749
2100.76	16.4413
2103.66	16.0896
2106.57	14.4515
2109.48	15.0933
2112.38	15.35
2115.29	16.7757
2118.19	17.8013
2121.09	15.8059
2123.99	16.0474
2126.89	14.764
2129.79	14.1272
2132.69	13.3378
2135.59	14.3488
2138.48	13.9617
2141.38	14.1248
2144.27	16.5661
2147.17	17.938
2150.06	17.4007
2152.95	16.442
2155.84	15.0685
2158.73	13.2691
2161.61	14.1529
2164.5	13.9338
2167.38	15.652
2170.27	16.4209
2173.15	18.7506
2176.03	20.0407
2178.91	20.9862
2181.8	23.3908
2184.67	21.6298
2187.55	23.9173
2190.43	23.9407
2193.3	23.7142
2196.18	25.0712
2199.05	24.245
2201.93	25.1834
2204.8	26.1511
2207.67	26.9235
2210.54	26.1453
2213.41	26.5035
2216.27	24.8505
2219.14	24.1412
2222.01	20.7951
2224.87	20.2473
2227.73	19.5412
2230.6	20.0286
2233.46	21.9623
2236.32	23.1294
2239.18	22.7942
2242.03	21.0189
2244.89	19.6796
2247.75	19.6961
2250.6	19.3979
2253.46	18.2175
2256.31	19.7305
2259.16	20.7682
2262.01	21.4735
2264.86	22.382
2267.71	22.8514
2270.56	22.7005
2273.4	23.2428
2276.25	22.1024
2279.09	21.9222
2281.94	22.0266
2284.78	23.5513
2287.62	23.8694
2290.46	21.5272
2293.3	20.0892
2296.14	21.2134
2298.98	23.2878
2301.82	24.9756
2304.65	25.8247
2307.49	25.5838
2310.32	26.3616
2313.15	24.3844
2315.98	24.4223
2318.81	23.2498
2321.64	20.6426
2324.47	18.4137
2327.3	17.8538
2330.12	16.4596
2332.95	13.9162
2335.77	13.1183
2338.6	11.6492
2341.42	11.4508
2344.24	10.3041
2347.06	9.87761
2349.88	9.42771
2352.7	8.24517
2355.51	5.07383
2358.33	5.01943
2361.14	4.54958
2363.96	5.45428
2366.77	7.68281
2369.58	9.83222
2372.39	9.75353
2375.2	8.79266
2378.01	8.72622
2380.82	7.5277
2383.63	5.60704
2386.43	4.73854
2389.24	4.10801
2392.04	3.64798
2394.84	2.60972
2397.65	2.94337
2400.45	3.74549
2403.25	3.90269
2406.05	3.9388
2408.84	3.89709
2411.64	5.17091
2414.44	6.81781
2417.23	9.26812
2420.02	9.70553
2422.82	11.9924
2425.61	14.3186
2428.4	14.2058
2431.19	14.4472
2433.98	14.2105
2436.77	16.284
2439.55	14.6416
2442.34	13.2411
2445.12	12.673
2447.91	12.071
2450.69	11.712
2453.47	9.34359
2456.25	8.65696
2459.03	7.6886
2461.81	6.11758
2464.59	4.2847
2467.36	3.05347
2470.14	2.40529
2472.92	3.0966
2475.69	3.74376
2478.46	5.75507
2481.23	6.81967
2484	7.74351
2486.77	7.30067
2489.54	6.96883
2492.31	6.58282
2495.08	6.23521
2497.84	4.91344
2500.61	4.54392
2503.37	2.96737
2506.13	1.44482
2508.9	1.05351
2511.66	1.27628
2514.42	0.673332
2517.18	0.648094
2519.93	1.28756
2522.69	0.304016
2525.45	-0.0600394
2528.2	-0.454147
2530.95	1.92007
2533.71	1.51717
2536.46	4.14454
2539.21	5.92365
2541.96	5.86551
2544.71	6.27831
2547.46	5.91766
2550.2	7.19364
2552.95	6.34245
2555.7	6.72008
2558.44	6.76322
2561.18	6.38466
2563.93	5.19828
2566.67	5.72748
2569.41	4.85561
2572.15	4.60643
2574.88	4.73971
2577.62	4.5186
2580.36	5.00191
2583.09	5.96349
2585.83	6.2249
2588.56	5.75283
2591.29	4.5008
2594.02	4.25958
2596.75	5.19466
2599.48	5.14311
2602.21	4.58445
2604.94	5.1489
2607.67	5.54933
2610.39	6.53259
2613.12	6.81467
2615.84	7.68273
2618.56	7.61462
2621.28	8.19146
2624.01	7.73963
2626.72	7.08688
2629.44	5.73907
2632.16	4.74016
2634.88	6.25332
2637.59	5.32616
2640.31	4.64211
2643.02	5.44479
2645.74	5.701
2648.45	6.13929
2651.16	5.65276
2653.87	4.73073
2656.58	3.70133
2659.29	3.41791
2661.99	2.67095
2664.7	3.32165
2667.41	5.08462
2670.11	5.9263
2672.81	8.55927
2675.51	9.12095
2678.22	10.0493
2680.92	9.78646
2683.62	9.9211
2686.31	10.2958
2689.01	11.5452
2691.71	12.1603
2694.4	12.1869
2697.1	14.1452
2699.79	16.3919
2702.49	18.3968
2705.18	20.7499
2707.87	21.4074
2710.56	23.1342
2713.25	24.4976
2715.94	25.2377
2718.62	25.2585
2721.31	24.1333
2723.99	24.4005
2726.68	23.2921
2729.36	22.6102
2732.04	23.065
2734.73	22.0619
2737.41	23.1603
2740.08	21.1552
2742.76	19.1519
2745.44	16.8814
2748.12	13.5342
2750.79	11.7679
2753.47	10.0001
2756.14	7.7951
2758.81	6.08745
2761.49	4.56292
2764.16	3.99859
2766.83	4.47357
2769.5	3.95404
2772.16	3.13326
2774.83	2.99659
2777.5	3.44458
2780.16	2.50018
2782.83	2.68633
2785.49	2.18625
2788.15	1.39743
2790.82	0.85288
2793.48	-0.415471
2796.14	0.523918
2798.79	-0.72693
2801.45	-1.09174
2804.11	-2.20863
2806.76	-2.76591
2809.42	-4.73233
2812.07	-4.70658
2814.73	-3.0587
2817.38	4.52148
2820.03	14.1881
2822.68	26.7132
2825.33	41.252
2827.98	57.1968
2830.63	74.8997
2833.27	91.7851
2835.92	109.252
2838.56	128.285
2841.21	145.824
2843.85	164.361
2846.49	182.358
2849.13	204.054
2851.77	226.683
2854.41	250.37
2857.05	272.443
2859.69	292.807
2862.32	310.453
2864.96	324.151
2867.59	335.138
2870.23	345.3
2872.86	352.259
2875.49	361.508
2878.12	367.553
2880.75	375.848
2883.38	382.333
2886.01	385.206
2888.63	386.388
2891.26	385.346
2893.89	388.184
2896.51	387.752
2899.13	387.817
2901.76	388.412
2904.38	392.124
2907	397.417
2909.62	407.356
2912.24	419.249
2914.85	436.59
2917.47	449.787
2920.09	460.734
2922.7	469.403
2925.32	474.797
2927.93	476.536
2930.54	473.591
2933.15	469.153
2935.76	463.715
2938.37	455.606
2940.98	442.705
2943.59	428.578
2946.2	411.992
2948.8	392.758
2951.41	372.246
2954.01	352.854
2956.62	333.156
2959.22	314.089
2961.82	294.523
2964.42	276.071
2967.02	258.73
2969.62	242.959
2972.22	230.793
2974.81	216.686
2977.41	202.769
2980	189.651
2982.6	176.222
2985.19	161.474
2987.78	146.242
2990.38	131.191
2992.97	116.404
2995.56	104.048
2998.14	91.1389
3000.73	80.1316
3003.32	68.6568
3005.91	57.2757
3008.49	47.514
3011.07	38.4104
3013.66	31.2676
3016.24	23.7143
3018.82	17.5541
3021.4	10.9104
3023.98	6.40763
3026.56	1.82767
3029.14	-0.0594148
3031.71	-0.973817
3034.29	-0.438608
3036.87	0.577469
3039.44	1.30972
3042.01	4.78937
3044.59	7.98059
3047.16	10.2693
3049.73	12.3856
3052.3	14.1462
3054.87	16.6605
3057.43	17.7015
3060	19.0266
3062.57	19.5344
3065.13	19.1909
3067.7	19.231
3070.26	18.2557
3072.82	17.5819
3075.39	17.4855
3077.95	16.1232
3080.51	14.0456
3083.07	12.4406
3085.63	12.3055
3088.18	12.705
3090.74	12.6597
3093.29	11.9207
3095.85	13.0786
3098.4	14.8373
3100.95	15.8406
3103.51	19.0213
3106.06	20.6599
3108.61	23.3641
3111.16	25.6156
3113.71	27.6779
3116.25	30.6098
3118.8	33.499
3121.35	36.9675
3123.89	40.1072
3126.44	42.4167
3128.98	45.7322
3131.52	48.7333
3134.06	53.1091
3136.6	56.5284
3139.14	58.7909
3141.68	61.0351
3144.22	64.0689
3146.76	64.7685
3149.29	63.9608