File: data/Raman/poly_smoothed/Mb_00_13_06_1x_45s_532 nm_x100_100%_600 gr_mm_01.txt
#Acq. time (s)=	45
#Accumulations=	2
#Range (cm-¹)=	200...3150
#Windows=	2
#Auto scanning=	Off
#Autofocus=	Off
#Macrospot=	Off
#AutoExposure=	Off
#Spike filter=	Multiple accum.
#Delay time (s)=	0
#Binning=	1
#Readout mode=	Signal
#DeNoise=	Off
#ICS correction=	On
#Dark correction=	Off
#Inst. Process=	Off
#Detector Gain=	Best Dynamic Range
#Detector ADC=	20 kHz
#Detector temperature (°C)=	-69.85
#Instrument=	LabRAM HR Evol
#Detector=	Synapse
#Objective=	x100
#Grating=	600 gr/mm
#ND Filter=	100%
#Laser (nm)=	532
#Hole=	100.021
#Range=	Auto
#Laser Pol.=	No
#Raman. Pol.=	No
#Laser Pol. (°)=	-0.0007625
#Raman Pol. (°)=	89.9995
#Collection=	Microscope
#StageXY=	Marzhauser
#StageZ=	Marzhauser
#X (µm)=	-991.5
#Y (µm)=	-2919.5
#Z (µm)=	527.75
#Full time(mm:ss)=	3:18
#Project=
#Sample=
#Site=
#Title=	Mb_00_13_06_2x_45s_532 nm_x100_100%_600 gr_mm
#Remark=
#Date=	06.07.2022 10:06
#Acquired=	06.07.2022 10:06:00
#Base:Fit=	10.08.2022 10:16:36
#Base:Fit=	10.08.2022 10:16:56
#Base:Sub=	10.08.2022 10:17:24
#Filter:Polynom=	16.08.2022 10:36:38
#AxisType[0]=Intens
#AxisUnit[0]=Cnt
#AxisType[1]=Spectr
#AxisUnit[1]=1/cm
200.398	24.2743
204.027	16.1218
207.657	6.26227
211.283	1.10964
214.909	0.512204
218.533	4.26942
222.157	12.8345
225.777	26.0716
229.396	38.1508
233.016	50.5445
236.632	60.169
240.247	68.636
243.86	76.2731
247.474	83.5307
251.085	92.3116
254.694	98.3363
258.301	102.499
261.908	105.121
265.513	102.411
269.116	97.6543
272.718	93.6445
276.319	85.3354
279.918	76.1909
283.516	64.8548
287.113	50.5566
290.708	39.8138
294.302	30.7175
297.894	23.1878
301.485	14.5161
305.073	11.0218
308.661	7.92368
312.247	5.0829
315.833	3.31351
319.415	1.87069
322.997	-0.841213
326.579	-0.962153
330.156	0.632522
333.735	0.538793
337.31	0.326118
340.885	0.0924402
344.458	-0.573478
348.03	-0.931004
351.6	-1.50451
355.17	-3.27626
358.737	-2.46036
362.304	-0.429904
365.868	2.87045
369.431	6.70606
372.994	9.11924
376.554	14.5966
380.112	23.4648
383.669	32.4761
387.225	42.8325
390.781	52.5435
394.334	63.0482
397.885	71.2293
401.436	78.2345
404.984	84.0556
408.532	86.196
412.078	89.2724
415.623	89.7156
419.166	86.595
422.708	83.1348
426.248	77.0433
429.788	70.9136
433.326	63.3491
436.86	53.1997
440.395	43.4208
443.929	35.1367
447.461	27.3922
450.99	21.3506
454.52	14.4576
458.048	8.47797
461.573	7.19053
465.099	8.35105
468.623	8.00276
472.144	7.52637
475.666	5.72192
479.184	6.50476
482.703	7.42262
486.218	9.69242
489.734	11.284
493.247	14.0003
496.759	17.8214
500.271	22.2749
503.779	24.6231
507.287	29.3913
510.795	34.1573
514.299	37.804
517.803	41.9232
521.305	44.4866
524.805	47.3654
528.307	49.8493
531.805	51.3765
535.301	53.1477
538.797	53.0004
542.291	52.8604
545.783	51.7411
549.275	48.7759
552.765	45.2629
556.253	40.6031
559.738	34.3115
563.224	31.305
566.709	28.1534
570.192	24.7975
573.674	21.3365
577.153	16.7668
580.632	14.5936
584.11	13.3484
587.587	12.0989
591.06	10.303
594.534	10.1961
598.005	10.0892
601.476	10.884
604.944	12.7957
608.413	12.8496
611.878	13.5379
615.344	15.3776
618.807	15.3368
622.27	15.831
625.73	16.2798
629.189	21.1027
632.648	24.0017
636.105	27.4251
639.559	29.561
643.013	28.6386
646.467	26.3347
649.918	26.1992
653.368	26.7355
656.816	25.5596
660.263	25.1344
663.708	25.3616
667.153	24.9245
670.596	25.0468
674.037	24.8716
677.478	23.7133
680.917	23.3454
684.355	24.0645
687.791	23.5574
691.224	23.58
694.658	21.3694
698.091	20.1589
701.522	18.7635
704.95	18.2174
708.379	19.5395
711.806	21.6279
715.23	23.1567
718.655	24.8009
722.078	25.5132
725.498	24.8332
728.919	24.7585
732.337	24.3529
735.755	27.0679
739.17	30.2896
742.584	34.1173
745.998	37.7984
749.409	41.7558
752.819	45.6927
756.23	49.623
759.637	54.1803
763.043	56.3687
766.448	60.3695
769.853	63.9689
773.255	66.8316
776.656	68.2226
780.056	68.3185
783.454	70.2417
786.851	70.5967
790.247	73.3079
793.641	75.6981
797.034	75.2504
800.426	77.2508
803.817	75.6129
807.206	75.2725
810.592	74.4433
813.979	73.1221
817.364	72.3352
820.748	74.6004
824.129	75.1712
827.511	75.6189
830.891	75.8721
834.269	73.7954
837.646	72.8694
841.023	71.6035
844.396	68.8025
847.77	65.2678
851.141	62.7279
854.513	58.3021
857.881	52.8928
861.248	49.209
864.616	46.5243
867.98	44.4341
871.343	42.2246
874.707	39.4777
878.068	36.6328
881.428	34.9301
884.786	33.0255
888.143	31.9775
891.498	35.0804
894.855	34.1048
898.208	34.5341
901.56	35.5766
904.91	35.2205
908.26	35.3912
911.608	36.0566
914.955	34.5021
918.298	34.478
921.643	35.1855
924.986	34.6781
928.328	35.4811
931.668	35.47
935.006	35.218
938.344	36.2181
941.681	38.882
945.014	38.6992
948.349	39.2628
951.682	37.9383
955.012	37.5564
958.343	33.7525
961.67	33.1628
964.998	38.7011
968.323	45.7166
971.649	52.0467
974.971	57.8437
978.293	62.0998
981.615	63.7117
984.933	66.3973
988.251	69.0699
991.567	72.5267
994.884	73.5644
998.198	76.2318
1001.51	78.2475
1004.82	78.6675
1008.13	78.578
1011.44	80.0156
1014.75	83.6151
1018.06	89.199
1021.36	97.079
1024.66	103.732
1027.97	110.636
1031.27	116.67
1034.57	121.108
1037.87	124.182
1041.16	127.71
1044.46	135.321
1047.76	138.185
1051.05	136.404
1054.34	135.473
1057.63	132.196
1060.92	126.475
1064.21	121.128
1067.5	114.503
1070.78	106.194
1074.07	92.0938
1077.35	80.0316
1080.63	68.5575
1083.91	57.1545
1087.19	45.9333
1090.47	39.714
1093.75	35.3459
1097.03	34.0737
1100.3	36.187
1103.57	38.9114
1106.84	36.0588
1110.11	33.7096
1113.38	30.0138
1116.65	28.3746
1119.92	25.7103
1123.19	22.4376
1126.45	20.7244
1129.71	19.3724
1132.97	19.3803
1136.23	18.2962
1139.49	18.5622
1142.75	18.6132
1146.01	16.6536
1149.26	13.3912
1152.52	13.456
1155.77	13.4001
1159.02	12.5595
1162.27	13.6887
1165.52	11.6931
1168.77	12.5794
1172.02	15.685
1175.26	17.0352
1178.51	21.1473
1181.75	24.6359
1184.99	26.4828
1188.23	28.0984
1191.47	31.5184
1194.71	37.2491
1197.94	41.0742
1201.18	45.4756
1204.41	51.085
1207.65	55.7341
1210.88	61.9009
1214.11	65.6294
1217.34	71.6607
1220.57	77.9032
1223.79	80.1238
1227.02	82.4276
1230.24	87.4181
1233.47	91.2453
1236.69	93.3217
1239.91	94.7386
1243.13	97.2465
1246.34	98.9214
1249.56	103.145
1252.78	104.551
1255.99	104.489
1259.2	106.015
1262.42	106.661
1265.63	106.777
1268.84	106.512
1272.04	108.727
1275.25	109.97
1278.46	111.501
1281.66	113.937
1284.86	117.047
1288.07	120.421
1291.27	122.406
1294.47	125.024
1297.66	126.185
1300.86	126.619
1304.06	127.504
1307.25	129.958
1310.44	132.774
1313.64	132.599
1316.83	134.263
1320.02	133.776
1323.2	133.524
1326.39	134.395
1329.58	131.327
1332.76	125.946
1335.95	122.359
1339.13	118.506
1342.31	114.575
1345.49	111.388
1348.67	108.106
1351.85	105.018
1355.02	102.455
1358.2	99.9707
1361.37	97.3258
1364.54	96.6618
1367.71	93.9793
1370.88	89.1617
1374.05	86.5376
1377.22	87.0053
1380.39	84.9485
1383.55	84.206
1386.72	83.3425
1389.88	80.9206
1393.04	79.5045
1396.2	77.2951
1399.36	75.3156
1402.52	76.168
1405.68	79.6349
1408.83	82.9829
1411.98	87.6838
1415.14	97.1333
1418.29	105.207
1421.44	115.146
1424.59	125.707
1427.74	137.967
1430.89	151.331
1434.03	163.496
1437.18	174.088
1440.32	183.117
1443.46	190.683
1446.6	194.533
1449.74	195.247
1452.88	194.069
1456.02	190.447
1459.16	182.217
1462.29	171.875
1465.43	161.813
1468.56	148.166
1471.69	133.72
1474.82	119.588
1477.95	107.372
1481.08	96.7639
1484.2	85.9374
1487.33	75.9706
1490.46	67.3288
1493.58	59.0501
1496.7	52.2061
1499.82	47.5354
1502.94	45.7608
1506.06	45.7833
1509.18	44.9562
1512.29	43.8414
1515.41	44.075
1518.52	43.4372
1521.63	41.5773
1524.75	41.6675
1527.85	38.4734
1530.96	38.7949
1534.07	38.9821
1537.18	40.5318
1540.28	41.497
1543.39	45.6855
1546.49	48.0241
1549.59	51.0713
1552.69	55.6896
1555.79	58.6382
1558.89	61.8785
1561.99	64.2291
1565.08	68.8142
1568.18	73.9125
1571.27	78.33
1574.37	82.9776
1577.46	88.2849
1580.55	94.144
1583.64	97.0857
1586.73	101.57
1589.81	104.302
1592.9	106.304
1595.98	106.175
1599.06	107.528
1602.15	107.785
1605.23	106.725
1608.31	105.957
1611.39	107.013
1614.46	106.35
1617.54	107.73
1620.61	109.314
1623.69	109.384
1626.76	112.279
1629.83	112.626
1632.9	116.809
1635.97	119.323
1639.04	120.486
1642.11	124.472
1645.17	128.181
1648.24	131.073
1651.3	132.69
1654.36	132.107
1657.42	134.006
1660.48	133.3
1663.54	132.464
1666.6	128.705
1669.66	125.501
1672.71	118.154
1675.77	112.836
1678.82	106.305
1681.87	97.1495
1684.92	90.0859
1687.97	82.0141
1691.02	73.3455
1694.07	64.5313
1697.11	57.5559
1700.16	52.3107
1703.2	46.2628
1706.25	39.8139
1709.29	35.1112
1712.33	30.8227
1715.37	25.1333
1718.41	23.9617
1721.44	21.9037
1724.48	19.8477
1727.51	16.6821
1730.55	16.1835
1733.58	16.1946
1736.61	15.5888
1739.64	14.7881
1742.67	13.835
1745.7	12.056
1748.72	11.0832
1751.75	11.0736
1754.77	7.87774
1757.8	7.01294
1760.82	7.19876
1763.84	5.59715
1766.86	4.01459
1769.88	2.91909
1772.9	4.04972
1775.91	4.39901
1778.93	2.76973
1781.94	3.64173
1784.96	3.78705
1787.97	2.04324
1790.98	3.49572
1793.99	3.69932
1797	4.99206
1800.01	5.239
1803.01	5.35102
1806.02	7.15482
1809.02	7.07887
1812.02	8.5181
1815.02	8.85659
1818.03	7.44177
1821.02	7.33614
1824.02	6.96425
1827.02	6.16765
1830.02	6.25496
1833.01	6.4917
1836.01	5.01965
1839	3.36127
1841.99	2.73353
1844.98	1.94302
1847.97	2.14105
1850.96	1.77925
1853.95	3.09739
1856.93	4.46152
1859.92	5.81467
1862.9	4.74318
1865.88	6.01982
1868.87	7.52594
1871.85	9.1026
1874.83	9.49572
1877.81	8.91107
1880.78	9.76251
1882.53	10.7828
1885.52	9.84916
1888.51	8.93132
1891.5	9.2563
1894.48	9.11994
1897.47	9.62763
1900.45	8.80455
1903.43	8.80272
1906.41	7.7067
1909.39	7.41158
1912.37	8.85846
1915.35	10.6993
1918.33	11.8641
1921.3	13.3087
1924.28	13.4525
1927.25	12.2781
1930.22	12.5963
1933.19	10.4422
1936.16	10.1495
1939.13	11.9523
1942.1	11.9729
1945.07	12.0382
1948.03	11.5289
1951	11.078
1953.96	11.309
1956.92	9.12469
1959.88	7.95248
1962.84	8.63084
1965.8	8.29804
1968.76	7.63196
1971.72	6.55573
1974.67	7.45371
1977.63	8.76003
1980.58	10.3863
1983.54	11.3887
1986.49	12.475
1989.44	12.0872
1992.39	12.0022
1995.33	11.5965
1998.28	11.2033
2001.23	10.6538
2004.17	11.344
2007.12	11.4068
2010.06	11.9967
2013	12.8504
2015.94	11.8053
2018.88	9.98934
2021.82	8.76741
2024.76	7.54996
2027.69	7.02819
2030.63	6.60069
2033.56	6.78387
2036.5	5.70448
2039.43	4.10704
2042.36	4.07698
2045.29	5.31217
2048.22	6.82816
2051.15	8.74988
2054.07	9.21566
2057	9.40187
2059.92	11.3793
2062.85	12.2481
2065.77	14.1129
2068.69	15.7053
2071.61	15.2949
2074.53	16.6914
2077.45	17.0494
2080.37	16.9407
2083.28	18.0928
2086.2	18.6617
2089.11	18.0788
2092.02	18.2956
2094.94	18.721
2097.85	18.437
2100.76	17.5082
2103.66	16.0815
2106.57	14.8478
2109.48	13.3969
2112.38	13.7397
2115.29	12.4342
2118.19	12.5486
2121.09	11.6577
2123.99	9.99236
2126.89	9.50231
2129.79	10.5
2132.69	9.9847
2135.59	10.913
2138.48	11.6239
2141.38	12.4125
2144.27	13.6466
2147.17	13.7417
2150.06	15.1296
2152.95	15.9166
2155.84	17.7659
2158.73	18.7191
2161.61	19.1753
2164.5	20.844
2167.38	22.258
2170.27	22.5333
2173.15	22.2423
2176.03	23.3083
2178.91	24.3362
2181.8	23.121
2184.67	22.8871
2187.55	21.7334
2190.43	20.0036
2193.3	19.0851
2196.18	19.3351
2199.05	19.6708
2201.93	18.5983
2204.8	18.9769
2207.67	18.7294
2210.54	18.7834
2213.41	17.941
2216.27	17.4088
2219.14	17.3441
2222.01	18.3983
2224.87	19.2013
2227.73	18.6501
2230.6	18.2148
2233.46	17.8624
2236.32	17.2123
2239.18	17.7217
2242.03	17.4814
2244.89	16.8123
2247.75	15.5945
2250.6	14.8747
2253.46	14.8615
2256.31	13.9037
2259.16	13.8716
2262.01	13.0943
2264.86	14.2909
2267.71	12.7416
2270.56	13.0494
2273.4	12.6164
2276.25	13.6308
2279.09	12.4946
2281.94	12.8293
2284.78	12.0811
2287.62	13.146
2290.46	13.314
2293.3	14.0249
2296.14	13.4277
2298.98	13.7431
2301.82	14.4326
2304.65	14.4231
2307.49	14.1092
2310.32	12.8196
2313.15	11.4637
2315.98	11.3007
2318.81	11.5251
2321.64	12.3607
2324.47	12.2407
2327.3	11.7444
2330.12	11.8828
2332.95	12.2121
2335.77	11.3324
2338.6	10.7843
2341.42	10.0173
2344.24	8.58274
2347.06	7.14687
2349.88	5.51486
2352.7	4.45126
2355.51	4.58811
2358.33	5.57944
2361.14	6.0199
2363.96	4.57059
2366.77	5.18617
2369.58	6.20807
2372.39	4.13847
2375.2	1.60305
2378.01	0.0880885
2380.82	0.450619
2383.63	-0.0255935
2386.43	0.986844
2389.24	1.72432
2392.04	2.48531
2394.84	3.1707
2397.65	4.49961
2400.45	4.75116
2403.25	6.13067
2406.05	5.49354
2408.84	5.24114
2411.64	4.87676
2414.44	5.34537
2417.23	5.14188
2420.02	4.71765
2422.82	6.05378
2425.61	7.99058
2428.4	8.05479
2431.19	7.57198
2433.98	7.79897
2436.77	8.44281
2439.55	7.7379
2442.34	6.37127
2445.12	6.66451
2447.91	7.02507
2450.69	6.55468
2453.47	6.94306
2456.25	6.73845
2459.03	7.32643
2461.81	7.01049
2464.59	5.88343
2467.36	5.45796
2470.14	5.63608
2472.92	4.54356
2475.69	4.27115
2478.46	3.75751
2481.23	3.14049
2484	4.75344
2486.77	3.59812
2489.54	3.92579
2492.31	4.09482
2495.08	5.35821
2497.84	5.47336
2500.61	5.71717
2503.37	5.94605
2506.13	7.28031
2508.9	8.72983
2511.66	9.40286
2514.42	9.19963
2517.18	9.83404
2519.93	10.0722
2522.69	9.67565
2525.45	9.82006
2528.2	11.2059
2530.95	10.6449
2533.71	11.6403
2536.46	11.6923
2539.21	12.1354
2541.96	12.5784
2544.71	12.8059
2547.46	13.2139
2550.2	13.175
2552.95	12.4316
2555.7	13.2152
2558.44	13.5943
2561.18	14.1296
2563.93	14.147
2566.67	14.2963
2569.41	13.2993
2572.15	14.193
2574.88	13.7974
2577.62	11.8028
2580.36	12.0703
2583.09	10.7817
2585.83	8.86403
2588.56	7.73754
2591.29	7.35481
2594.02	8.08323
2596.75	7.18787
2599.48	6.00445
2602.21	7.09801
2604.94	6.90533
2607.67	6.0515
2610.39	5.88539
2613.12	5.70813
2615.84	5.4906
2618.56	6.33564
2621.28	6.03976
2624.01	7.83938
2626.72	8.15341
2629.44	8.55622
2632.16	7.02559
2634.88	7.02934
2637.59	6.87371
2640.31	7.05444
2643.02	6.54436
2645.74	7.2596
2648.45	7.94798
2651.16	6.85901
2653.87	5.37662
2656.58	5.32394
2659.29	4.69693
2661.99	4.25393
2664.7	4.01502
2667.41	4.94644
2670.11	5.7352
2672.81	4.84642
2675.51	5.27627
2678.22	5.06463
2680.92	5.12965
2683.62	5.02738
2686.31	5.05166
2689.01	6.06185
2691.71	6.74496
2694.4	6.46767
2697.1	7.32074
2699.79	10.0934
2702.49	13.0198
2705.18	14.1481
2707.87	14.6768
2710.56	16.4193
2713.25	16.9697
2715.94	17.4755
2718.62	17.641
2721.31	18.601
2723.99	19.761
2726.68	20.4465
2729.36	21.0561
2732.04	20.9925
2734.73	20.4397
2737.41	18.8928
2740.08	17.2229
2742.76	16.2814
2745.44	13.8845
2748.12	12.3109
2750.79	10.4475
2753.47	8.53174
2756.14	6.20542
2758.81	4.91103
2761.49	4.25479
2764.16	3.55326
2766.83	2.58046
2769.5	2.0853
2772.16	1.14838
2774.83	0.0472182
2777.5	-0.674009
2780.16	-0.81448
2782.83	-0.511333
2785.49	0.382054
2788.15	1.02488
2790.82	0.759791
2793.48	-0.944036
2796.14	-1.29638
2798.79	-1.38553
2801.45	-1.15236
2804.11	-1.4848
2806.76	-1.24381
2809.42	-1.58259
2812.07	-1.86498
2814.73	-0.0550224
2817.38	3.85312
2820.03	7.58461
2822.68	13.6728
2825.33	21.8053
2827.98	30.2571
2830.63	39.7501
2833.27	48.956
2835.92	60.6285
2838.56	72.3197
2841.21	86.1951
2843.85	103.519
2846.49	120.431
2849.13	140.876
2851.77	160.749
2854.41	181.507
2857.05	201.587
2859.69	221.129
2862.32	239.552
2864.96	255.742
2867.59	271.467
2870.23	284.526
2872.86	297.13
2875.49	307.358
2878.12	316.999
2880.75	324.495
2883.38	331.247
2886.01	338.087
2888.63	344.933
2891.26	352.853
2893.89	359.767
2896.51	367.581
2899.13	376.565
2901.76	389.83
2904.38	405.671
2907	423.171
2909.62	442.457
2912.24	463.324
2914.85	482.841
2917.47	501.519
2920.09	517.349
2922.7	529.427
2925.32	539.707
2927.93	545.27
2930.54	545.687
2933.15	543.701
2935.76	536.084
2938.37	524.982
2940.98	511.671
2943.59	495.565
2946.2	476.243
2948.8	457.627
2951.41	437.291
2954.01	415.561
2956.62	393.702
2959.22	371.991
2961.82	351.04
2964.42	331.371
2967.02	314.233
2969.62	295.794
2972.22	277.685
2974.81	261.976
2977.41	244.91
2980	228.916
2982.6	212.741
2985.19	195.372
2987.78	177.978
2990.38	160.714
2992.97	143.53
2995.56	126.41
2998.14	110.856
3000.73	95.7551
3003.32	82.6368
3005.91	69.8911
3008.49	57.3518
3011.07	46.936
3013.66	37.4118
3016.24	28.3226
3018.82	21.772
3021.4	14.4624
3023.98	9.3861
3026.56	4.23573
3029.14	1.83378
3031.71	-0.252047
3034.29	-1.48204
3036.87	-1.09448
3039.44	-0.00209585
3042.01	1.13669
3044.59	4.00243
3047.16	5.12665
3049.73	4.84124
3052.3	6.17046
3054.87	7.31328
3057.43	7.74309
3060	8.16063
3062.57	8.70774
3065.13	9.03437
3067.7	9.10442
3070.26	8.21765
3072.82	7.84272
3075.39	6.5302
3077.95	4.87709
3080.51	3.01267
3083.07	1.17557
3085.63	-0.517087
3088.18	-0.251055
3090.74	0.24048
3093.29	0.60823
3095.85	1.7654
3098.4	3.93376
3100.95	6.42795
3103.51	7.86168
3106.06	9.96229
3108.61	11.7325
3111.16	13.7566
3113.71	16.2872
3116.25	19.3856
3118.8	22.0107
3121.35	24.8323
3123.89	28.6646
3126.44	32.3242
3128.98	36.0813
3131.52	38.9516
3134.06	41.2649
3136.6	44.8362
3139.14	47.5133
3141.68	51.9783
3144.22	57.2244
3146.76	64.0433
3149.29	70.4083