File: data/Raman/poly_smoothed/Mb_00_13_47_1x_45s_532 nm_x100_100%_600 gr_mm_03.txt
#Acq. time (s)=	45
#Accumulations=	2
#Range (cm-¹)=	200...3150
#Windows=	2
#Auto scanning=	Off
#Autofocus=	Off
#Macrospot=	Off
#AutoExposure=	Off
#Spike filter=	Multiple accum.
#Delay time (s)=	0
#Binning=	1
#Readout mode=	Signal
#DeNoise=	Off
#ICS correction=	On
#Dark correction=	Off
#Inst. Process=	Off
#Detector Gain=	Best Dynamic Range
#Detector ADC=	20 kHz
#Detector temperature (°C)=	-69.85
#Instrument=	LabRAM HR Evol
#Detector=	Synapse
#Objective=	x100
#Grating=	600 gr/mm
#ND Filter=	100%
#Laser (nm)=	532
#Hole=	100.021
#Range=	Auto
#Laser Pol.=	No
#Raman. Pol.=	No
#Laser Pol. (°)=	-0.0007625
#Raman Pol. (°)=	89.9995
#Collection=	Microscope
#StageXY=	Marzhauser
#StageZ=	Marzhauser
#X (µm)=	-1056.9
#Y (µm)=	-2876.3
#Z (µm)=	527.9
#Full time(mm:ss)=	3:18
#Project=
#Sample=
#Site=
#Title=	Mb_00_13_47_2x_45s_532 nm_x100_100%_600 gr_mm
#Remark=
#Date=	06.07.2022 13:35
#Acquired=	06.07.2022 13:35:50
#Base:Fit=	10.08.2022 10:16:56
#Base:Sub=	10.08.2022 10:17:24
#Filter:Polynom=	16.08.2022 10:36:38
#AxisType[0]=Intens
#AxisUnit[0]=Cnt
#AxisType[1]=Spectr
#AxisUnit[1]=1/cm
200.398	14.347
204.027	7.14363
207.657	-3.04252
211.283	-7.78263
214.909	-5.63191
218.533	5.8737
222.157	26.0397
225.777	48.647
229.396	76.7252
233.016	104.581
236.632	128.211
240.247	149.351
243.86	166.906
247.474	182.339
251.085	198.625
254.694	206.826
258.301	216.193
261.908	217.069
265.513	216.354
269.116	208.907
272.718	199.358
276.319	182.956
279.918	162.74
283.516	138.185
287.113	113.021
290.708	89.0827
294.302	69.0916
297.894	53.4701
301.485	39.3028
305.073	29.502
308.661	22.8008
312.247	19.2238
315.833	14.2709
319.415	14.9536
322.997	13.4098
326.579	13.2824
330.156	11.1916
333.735	10.4977
337.31	9.55685
340.885	6.94982
344.458	8.13258
348.03	8.09254
351.6	6.30014
355.17	4.89874
358.737	0.42899
362.304	0.98705
365.868	7.30786
369.431	16.9247
372.994	27.634
376.554	39.0213
380.112	54.1885
383.669	71.5504
387.225	96.3436
390.781	119.645
394.334	139.725
397.885	159.887
401.436	175.248
404.984	188.967
408.532	198.321
412.078	200.916
415.623	199.464
419.166	195.928
422.708	190.498
426.248	179.54
429.788	162.951
433.326	144.829
436.86	123.111
440.395	99.848
443.929	76.6953
447.461	59.4805
450.99	44.0123
454.52	30.4607
458.048	15.6883
461.573	3.85745
465.099	-2.31185
468.623	-3.16934
472.144	1.33568
475.666	4.9768
479.184	5.60934
482.703	9.00547
486.218	14.7976
489.734	20.0827
493.247	26.1585
496.759	33.3677
500.271	39.8709
503.779	48.2349
507.287	55.5527
510.795	60.8853
514.299	66.9488
517.803	70.4055
521.305	74.0549
524.805	78.1231
528.307	80.2938
531.805	82.4757
535.301	81.0796
538.797	78.0604
542.291	74.5011
545.783	68.8348
549.275	62.8355
552.765	55.1876
556.253	50.8193
559.738	44.2397
563.224	38.4716
566.709	33.3448
570.192	30.545
573.674	24.3547
577.153	18.0658
580.632	17.0708
584.11	14.5909
587.587	13.1358
591.06	11.4099
594.534	10.8566
598.005	10.7551
601.476	11.6758
604.944	11.3432
608.413	13.981
611.878	15.5988
615.344	17.0525
618.807	17.2394
622.27	16.1626
625.73	20.6428
629.189	22.7673
632.648	28.8663
636.105	34.1933
639.559	39.9942
643.013	45.395
646.467	48.3436
649.918	50.2833
653.368	51.6989
656.816	50.8412
660.263	50.1379
663.708	48.8041
667.153	46.502
670.596	44.5295
674.037	39.6675
677.478	35.5884
680.917	29.7809
684.355	24.3664
687.791	20.1442
691.224	13.4236
694.658	10.9697
698.091	7.01367
701.522	0.428799
704.95	-1.27155
708.379	-1.24422
711.806	-0.896081
715.23	0.0588521
718.655	1.92248
722.078	4.50637
725.498	5.03182
728.919	6.61764
732.337	7.45914
735.755	9.3824
739.17	12.2385
742.584	14.2754
745.998	17.7487
749.409	20.8824
752.819	27.8293
756.23	34.4433
759.637	40.0522
763.043	45.0599
766.448	50.443
769.853	56.3627
773.255	59.909
776.656	63.6082
780.056	65.8057
783.454	67.1869
786.851	67.0346
790.247	69.3253
793.641	68.5806
797.034	67.8758
800.426	65.2526
803.817	62.6709
807.206	58.9582
810.592	56.3854
813.979	54.668
817.364	51.0925
820.748	47.8754
824.129	46.909
827.511	46.2135
830.891	47.2458
834.269	48.5487
837.646	47.9505
841.023	47.1625
844.396	43.0022
847.77	39.0086
851.141	37.1274
854.513	30.6
857.881	24.7041
861.248	22.7136
864.616	20.3258
867.98	17.3697
871.343	13.7038
874.707	12.5258
878.068	8.65617
881.428	4.74781
884.786	3.25227
888.143	3.16943
891.498	3.11856
894.855	2.47467
898.208	2.27497
901.56	0.763507
904.91	4.1999
908.26	5.31484
911.608	8.18034
914.955	8.82338
918.298	8.44573
921.643	9.11169
924.986	7.73982
928.328	7.31432
931.668	8.24857
935.006	9.96523
938.344	7.09685
941.681	9.22931
945.014	9.15652
948.349	7.62872
951.682	6.57698
955.012	6.34089
958.343	2.41714
961.67	-0.617015
964.998	4.07582
968.323	10.0047
971.649	15.2756
974.971	20.1184
978.293	25.1256
981.615	32.4775
984.933	36.1467
988.251	40.2424
991.567	46.2301
994.884	48.0803
998.198	52.5835
1001.51	55.812
1004.82	57.4889
1008.13	57.1115
1011.44	57.2891
1014.75	58.9886
1018.06	68.792
1021.36	84.8763
1024.66	106.37
1027.97	129.457
1031.27	150.567
1034.57	167.868
1037.87	181.617
1041.16	194.901
1044.46	208.069
1047.76	218.549
1051.05	223.674
1054.34	223.289
1057.63	219.853
1060.92	211.158
1064.21	199.523
1067.5	184.719
1070.78	165.703
1074.07	147.198
1077.35	123.484
1080.63	100.232
1083.91	74.2723
1087.19	50.2038
1090.47	30.7724
1093.75	16.7922
1097.03	12.7595
1100.3	13.2119
1103.57	15.4956
1106.84	15.6272
1110.11	14.0104
1113.38	10.3646
1116.65	8.88169
1119.92	4.5575
1123.19	3.05287
1126.45	2.84005
1129.71	2.6704
1132.97	2.96064
1136.23	-0.13194
1139.49	2.55672
1142.75	4.99371
1146.01	7.65714
1149.26	7.93025
1152.52	9.74569
1155.77	12.0611
1159.02	12.4954
1162.27	12.4783
1165.52	12.1065
1168.77	14.2478
1172.02	14.113
1175.26	15.5238
1178.51	15.7003
1181.75	19.1955
1184.99	19.4923
1188.23	20.7791
1191.47	25.3328
1194.71	30.4099
1197.94	35.9488
1201.18	42.7346
1204.41	53.249
1207.65	61.9083
1210.88	70.5326
1214.11	78.9379
1217.34	89.8601
1220.57	101.2
1223.79	109.605
1227.02	113.804
1230.24	119.006
1233.47	123.012
1236.69	129.285
1239.91	131.433
1243.13	132.179
1246.34	130.92
1249.56	130.085
1252.78	128.301
1255.99	124.537
1259.2	122.274
1262.42	115.283
1265.63	114.801
1268.84	112.874
1272.04	110.23
1275.25	111.834
1278.46	114.575
1281.66	115.963
1284.86	118.955
1288.07	120.388
1291.27	123.149
1294.47	128.078
1297.66	132.352
1300.86	136.554
1304.06	139.807
1307.25	144.805
1310.44	151.044
1313.64	159.14
1316.83	164.15
1320.02	165.559
1323.2	167.781
1326.39	168.88
1329.58	164.898
1332.76	163.205
1335.95	159.192
1339.13	155.551
1342.31	150.159
1345.49	149.527
1348.67	145.897
1351.85	142.526
1355.02	136.673
1358.2	130.24
1361.37	127.306
1364.54	124.703
1367.71	119.468
1370.88	115.08
1374.05	111.173
1377.22	108.627
1380.39	107.024
1383.55	107.837
1386.72	105.613
1389.88	105.863
1393.04	104.558
1396.2	100.577
1399.36	95.8978
1402.52	97.0565
1405.68	96.9906
1408.83	102.922
1411.98	106.88
1415.14	118.371
1418.29	130.35
1421.44	145.342
1424.59	160.52
1427.74	174.94
1430.89	187.352
1434.03	205.443
1437.18	220.923
1440.32	231.147
1443.46	242.209
1446.6	246.58
1449.74	247.17
1452.88	248.045
1456.02	243.934
1459.16	237.684
1462.29	227.598
1465.43	212.857
1468.56	198.261
1471.69	180.12
1474.82	163.911
1477.95	148.913
1481.08	135.501
1484.2	120.808
1487.33	107.187
1490.46	97.6661
1493.58	89.4312
1496.7	80.9079
1499.82	75.4208
1502.94	68.4093
1506.06	64.3587
1509.18	64.566
1512.29	63.0583
1515.41	61.7695
1518.52	61.6402
1521.63	59.6278
1524.75	58.648
1527.85	59.9419
1530.96	61.9013
1534.07	62.344
1537.18	64.2826
1540.28	64.4707
1543.39	68.4504
1546.49	71.9247
1549.59	75.5239
1552.69	81.7813
1555.79	83.4119
1558.89	85.8161
1561.99	89.4235
1565.08	94.2417
1568.18	100.03
1571.27	106.412
1574.37	113.377
1577.46	119.204
1580.55	126.511
1583.64	133.134
1586.73	139.772
1589.81	145.095
1592.9	147.879
1595.98	150.427
1599.06	149.741
1602.15	148.209
1605.23	146.72
1608.31	144.185
1611.39	142.557
1614.46	140.729
1617.54	139.911
1620.61	139.684
1623.69	139.425
1626.76	137.627
1629.83	138.453
1632.9	137.982
1635.97	140.211
1639.04	141.102
1642.11	144.699
1645.17	149.527
1648.24	154.282
1651.3	156.294
1654.36	159.025
1657.42	158.766
1660.48	160.441
1663.54	156.253
1666.6	151.641
1669.66	145.791
1672.71	136.164
1675.77	124.734
1678.82	115.733
1681.87	107.328
1684.92	95.9136
1687.97	86.4864
1691.02	79.1003
1694.07	69.809
1697.11	59.2877
1700.16	49.3063
1703.2	40.3915
1706.25	34.3641
1709.29	28.4271
1712.33	22.6358
1715.37	19.0492
1718.41	17.5723
1721.44	15.4894
1724.48	13.5167
1727.51	14.6668
1730.55	13.7963
1733.58	14.1082
1736.61	15.898
1739.64	12.9872
1742.67	13.9275
1745.7	12.7903
1748.72	10.8453
1751.75	11.8021
1754.77	11.9575
1757.8	9.75024
1760.82	10.7729
1763.84	12.0113
1766.86	11.363
1769.88	7.49751
1772.9	5.7055
1775.91	3.84746
1778.93	5.58483
1781.94	3.78239
1784.96	1.73768
1787.97	1.32021
1790.98	2.37059
1793.99	2.63319
1797	2.40051
1800.01	3.59254
1803.01	3.04832
1806.02	4.83281
1809.02	5.10702
1812.02	3.47076
1815.02	1.90484
1818.03	2.01737
1821.02	2.40364
1824.02	2.66884
1827.02	3.99656
1830.02	2.65574
1833.01	4.17391
1836.01	5.72478
1839	5.02091
1841.99	5.7152
1844.98	7.294
1847.97	7.79392
1850.96	8.61632
1853.95	9.40385
1856.93	9.4088
1859.92	11.6565
1862.9	12.4692
1865.88	12.3567
1868.87	11.7569
1871.85	9.47636
1874.83	7.61306
1877.81	8.40811
1880.78	7.80788
1882.53	7.54192
1885.52	7.07678
1888.51	7.78203
1891.5	9.02715
1894.48	9.03363
1897.47	9.28366
1900.45	9.43033
1903.43	9.16991
1906.41	9.94667
1909.39	11.9916
1912.37	13.0662
1915.35	16.8459
1918.33	16.6188
1921.3	15.95
1924.28	14.6337
1927.25	15.1523
1930.22	13.915
1933.19	12.7977
1936.16	10.5907
1939.13	5.94909
1942.1	3.43409
1945.07	3.87766
1948.03	3.72231
1951	5.08589
1953.96	5.22126
1956.92	4.33482
1959.88	4.34914
1962.84	5.34268
1965.8	5.53486
1968.76	6.77179
1971.72	6.77813
1974.67	6.32552
1977.63	6.48637
1980.58	8.50082
1983.54	10.8293
1986.49	11.1694
1989.44	11.1856
1992.39	12.1424
1995.33	12.5479
1998.28	12.7452
2001.23	14.1392
2004.17	13.1064
2007.12	14.6704
2010.06	13.0385
2013	13.5074
2015.94	14.1163
2018.88	14.9656
2021.82	16.0618
2024.76	15.8895
2027.69	13.7205
2030.63	14.4664
2033.56	14.3699
2036.5	16.1379
2039.43	15.9222
2042.36	15.2381
2045.29	12.9017
2048.22	12.3273
2051.15	13.5656
2054.07	15.1512
2057	15.7884
2059.92	18.7093
2062.85	18.8555
2065.77	18.0494
2068.69	18.0341
2071.61	17.9603
2074.53	19.7667
2077.45	20.3958
2080.37	19.3578
2083.28	18.2689
2086.2	18.1637
2089.11	18.4119
2092.02	19.4929
2094.94	18.6054
2097.85	16.168
2100.76	15.4116
2103.66	19.3636
2106.57	18.9972
2109.48	19.2932
2112.38	19.5666
2115.29	18.7528
2118.19	18.3261
2121.09	18.5584
2123.99	19.5474
2126.89	20.0094
2129.79	19.6688
2132.69	17.9558
2135.59	17.5627
2138.48	18.2698
2141.38	18.0143
2144.27	17.2854
2147.17	16.587
2150.06	15.4192
2152.95	16.0792
2155.84	15.3621
2158.73	16.0769
2161.61	16.4726
2164.5	16.6408
2167.38	16.3723
2170.27	17.8125
2173.15	19.7128
2176.03	19.3434
2178.91	19.7762
2181.8	20.2878
2184.67	21.893
2187.55	19.9014
2190.43	20.9567
2193.3	20.938
2196.18	21.8756
2199.05	21.6518
2201.93	20.204
2204.8	18.8411
2207.67	17.8208
2210.54	16.5788
2213.41	16.4498
2216.27	17.0884
2219.14	17.1756
2222.01	18.2683
2224.87	17.0545
2227.73	18.0967
2230.6	18.4514
2233.46	19.7093
2236.32	19.9182
2239.18	20.8704
2242.03	21.1225
2244.89	21.0481
2247.75	20.8746
2250.6	21.7006
2253.46	22.1506
2256.31	22.4007
2259.16	22.5298
2262.01	22.2103
2264.86	21.4315
2267.71	20.9716
2270.56	19.1215
2273.4	17.3521
2276.25	18.4988
2279.09	19.4068
2281.94	19.4341
2284.78	19.2587
2287.62	16.3944
2290.46	14.7407
2293.3	13.6778
2296.14	13.2111
2298.98	12.4019
2301.82	12.8128
2304.65	13.9898
2307.49	15.4879
2310.32	15.2012
2313.15	13.8566
2315.98	14.6869
2318.81	15.0349
2321.64	14.2842
2324.47	15.501
2327.3	13.3035
2330.12	13.3543
2332.95	13.4654
2335.77	12.5571
2338.6	12.4216
2341.42	12.6059
2344.24	11.1284
2347.06	11.0976
2349.88	9.98202
2352.7	9.94145
2355.51	8.09942
2358.33	7.28399
2361.14	8.53582
2363.96	9.83585
2366.77	10.3378
2369.58	10.4818
2372.39	11.1382
2375.2	12.2025
2378.01	11.345
2380.82	10.6535
2383.63	9.52259
2386.43	10.3002
2389.24	9.21247
2392.04	7.37949
2394.84	7.18917
2397.65	5.91079
2400.45	4.96792
2403.25	5.89183
2406.05	4.46899
2408.84	4.83247
2411.64	6.02987
2414.44	6.79372
2417.23	9.47695
2420.02	13.0732
2422.82	14.9246
2425.61	15.6884
2428.4	16.6593
2431.19	15.7741
2433.98	17.355
2436.77	15.037
2439.55	13.627
2442.34	12.9661
2445.12	10.4907
2447.91	7.76899
2450.69	4.99031
2453.47	4.86848
2456.25	3.18901
2459.03	-1.14273
2461.81	-1.61775
2464.59	-2.86198
2467.36	-2.70029
2470.14	-3.40128
2472.92	-2.26782
2475.69	-1.03104
2478.46	0.924502
2481.23	3.30261
2484	6.23404
2486.77	7.59953
2489.54	9.44489
2492.31	9.79517
2495.08	10.45
2497.84	11.0047
2500.61	13.2261
2503.37	14.9549
2506.13	16.3925
2508.9	15.8481
2511.66	14.521
2514.42	13.167
2517.18	15.2997
2519.93	13.8814
2522.69	16.255
2525.45	15.2402
2528.2	17.5321
2530.95	17.5625
2533.71	17.3093
2536.46	18.1276
2539.21	18.7932
2541.96	20.2823
2544.71	21.7669
2547.46	23.3285
2550.2	25.5475
2552.95	24.5156
2555.7	25.1804
2558.44	24.8669
2561.18	26.2442
2563.93	27.2256
2566.67	29.2723
2569.41	28.0744
2572.15	28.654
2574.88	27.4232
2577.62	26.3496
2580.36	24.8168
2583.09	24.1417
2585.83	23.146
2588.56	22.489
2591.29	24.5489
2594.02	23.7159
2596.75	21.5356
2599.48	20.5351
2602.21	20.3561
2604.94	20.3067
2607.67	19.9912
2610.39	20.0451
2613.12	20.2368
2615.84	18.4501
2618.56	19.0779
2621.28	20.9122
2624.01	20.9736
2626.72	18.3383
2629.44	20.0199
2632.16	21.4396
2634.88	21.6069
2637.59	20.5778
2640.31	22.3095
2643.02	23.4641
2645.74	23.7656
2648.45	23.3642
2651.16	23.5099
2653.87	24.1275
2656.58	25.8818
2659.29	25.0996
2661.99	24.3851
2664.7	24.9682
2667.41	25.8135
2670.11	25.6934
2672.81	24.8178
2675.51	26.2846
2678.22	26.707
2680.92	27.0264
2683.62	28.9214
2686.31	29.6506
2689.01	29.5198
2691.71	28.4567
2694.4	28.7218
2697.1	30.9233
2699.79	31.1128
2702.49	31.6405
2705.18	32.9022
2707.87	35.8149
2710.56	37.0644
2713.25	38.7543
2715.94	38.3326
2718.62	38.8667
2721.31	40.7843
2723.99	41.3504
2726.68	39.5077
2729.36	39.7925
2732.04	39.2805
2734.73	36.2179
2737.41	35.5555
2740.08	34.6506
2742.76	31.4004
2745.44	28.1542
2748.12	26.0326
2750.79	23.7379
2753.47	21.9926
2756.14	19.4404
2758.81	15.5719
2761.49	13.9469
2764.16	13.2477
2766.83	11.4967
2769.5	10.4274
2772.16	10.1769
2774.83	8.5521
2777.5	8.40886
2780.16	9.35799
2782.83	9.26127
2785.49	9.9486
2788.15	12.9106
2790.82	11.8471
2793.48	11.7832
2796.14	10.0942
2798.79	8.59147
2801.45	8.0638
2804.11	8.01915
2806.76	5.8693
2809.42	4.76517
2812.07	4.62984
2814.73	6.94433
2817.38	9.95516
2820.03	15.0894
2822.68	21.123
2825.33	26.3866
2827.98	35.9007
2830.63	44.2368
2833.27	54.2367
2835.92	67.0133
2838.56	78.9775
2841.21	97.9244
2843.85	116.796
2846.49	138.368
2849.13	162.302
2851.77	187.919
2854.41	212.55
2857.05	235.538
2859.69	258.519
2862.32	280.321
2864.96	300.125
2867.59	317.395
2870.23	331.64
2872.86	346.241
2875.49	357.484
2878.12	369.551
2880.75	379.92
2883.38	391.23
2886.01	399.885
2888.63	408.412
2891.26	416.288
2893.89	425.705
2896.51	436.201
2899.13	448.594
2901.76	463.093
2904.38	480.583
2907	502.959
2909.62	526.771
2912.24	553.129
2914.85	580.628
2917.47	607.051
2920.09	629.662
2922.7	649.185
2925.32	663.546
2927.93	672.305
2930.54	676.179
2933.15	674.353
2935.76	668.341
2938.37	657.318
2940.98	641.417
2943.59	621.217
2946.2	599.234
2948.8	576.336
2951.41	549.721
2954.01	522.889
2956.62	495.214
2959.22	467.753
2961.82	441.453
2964.42	415.008
2967.02	390.603
2969.62	370.541
2972.22	349.002
2974.81	329.429
2977.41	311.023
2980	290.324
2982.6	271.605
2985.19	249.833
2987.78	228.396
2990.38	206.225
2992.97	184.571
2995.56	164.771
2998.14	143.093
3000.73	124.822
3003.32	105.431
3005.91	86.8243
3008.49	71.2
3011.07	57.6754
3013.66	45.5001
3016.24	34.5898
3018.82	25.306
3021.4	17.3264
3023.98	10.9752
3026.56	5.63044
3029.14	-0.0774252
3031.71	-0.999868
3034.29	-2.79263
3036.87	-1.61086
3039.44	-0.63312
3042.01	1.61596
3044.59	3.88338
3047.16	7.92474
3049.73	9.78147
3052.3	12.7751
3054.87	15.2214
3057.43	16.7242
3060	19.0257
3062.57	17.9167
3065.13	19.8065
3067.7	19.2618
3070.26	19.2269
3072.82	19.0588
3075.39	18.446
3077.95	16.3334
3080.51	14.4661
3083.07	13.5448
3085.63	13.2479
3088.18	11.5454
3090.74	11.7056
3093.29	11.6268
3095.85	14.5762
3098.4	17.0636
3100.95	20.6708
3103.51	22.2325
3106.06	25.8282
3108.61	29.3252
3111.16	33.3257
3113.71	36.9473
3116.25	42.0667
3118.8	47.9661
3121.35	52.9358
3123.89	58.8542
3126.44	64.9305
3128.98	71.2862
3131.52	77.5438
3134.06	84.5387
3136.6	91.4229
3139.14	99.0857
3141.68	105.99
3144.22	113.095
3146.76	119.453
3149.29	123.113