File: data/Raman/poly_smoothed/Mb_10_14_47_1x_45s_532 nm_x100_100%_600 gr_mm_01.txt
#Acq. time (s)=	45
#Accumulations=	2
#Range (cm-¹)=	200...3150
#Windows=	2
#Auto scanning=	Off
#Autofocus=	Off
#Macrospot=	Off
#AutoExposure=	Off
#Spike filter=	Multiple accum.
#Delay time (s)=	0
#Binning=	1
#Readout mode=	Signal
#DeNoise=	Off
#ICS correction=	On
#Dark correction=	Off
#Inst. Process=	Off
#Detector Gain=	Best Dynamic Range
#Detector ADC=	20 kHz
#Detector temperature (°C)=	-69.85
#Instrument=	LabRAM HR Evol
#Detector=	Synapse
#Objective=	x100
#Grating=	600 gr/mm
#ND Filter=	100%
#Laser (nm)=	532
#Hole=	100.021
#Range=	Auto
#Laser Pol.=	No
#Raman. Pol.=	No
#Laser Pol. (°)=	-0.0007625
#Raman Pol. (°)=	89.9995
#Collection=	Microscope
#StageXY=	Marzhauser
#StageZ=	Marzhauser
#X (µm)=	-630.6
#Y (µm)=	-1702.2
#Z (µm)=	88.9
#Full time(mm:ss)=	3:18
#Project=
#Sample=
#Site=
#Title=	Mb_10_14_47_2x_45s_532 nm_x100_100%_600 gr_mm
#Remark=
#Date=	11.07.2022 12:13
#Acquired=	11.07.2022 12:13:07
#Base:Fit=	10.08.2022 10:21:11
#Base:Sub=	10.08.2022 10:21:41
#Filter:Polynom=	16.08.2022 10:17:53
#AxisType[0]=Intens
#AxisUnit[0]=Cnt
#AxisType[1]=Spectr
#AxisUnit[1]=1/cm
200.388	16.7429
204.019	14.2762
207.646	9.47106
211.274	5.4893
214.899	3.27586
218.524	4.60833
222.146	5.13227
225.766	7.51023
229.388	10.4849
233.005	11.4387
236.621	14.1872
240.236	15.3252
243.852	15.8779
247.464	16.7087
251.074	18.533
254.683	20.0752
258.291	21.802
261.897	22.6463
265.504	24.6359
269.108	27.0307
272.71	26.8742
276.311	26.1662
279.91	26.4322
283.508	23.4716
287.105	22.0917
290.698	21.3351
294.291	18.502
297.884	18.8564
301.475	17.5694
305.064	18.3778
308.652	19.5596
312.237	19.131
315.822	19.4169
319.406	19.7031
322.987	17.6275
326.568	15.2358
330.148	13.14
333.724	10.0023
337.301	8.1364
340.875	8.53597
344.449	9.05128
348.02	11.6014
351.592	14.3822
355.16	15.4869
358.728	17.2473
362.294	19.2291
365.858	21.5853
369.422	22.2659
372.983	23.4197
376.543	25.6131
380.102	25.8798
383.661	27.668
387.216	30.505
390.771	32.4212
394.324	35.0269
397.875	35.1137
401.425	35.1756
404.974	35.6558
408.524	35.5096
412.07	32.8823
415.614	31.329
419.156	29.3367
422.698	28.1531
426.238	28.1248
429.777	28.0504
433.315	26.8546
436.852	24.2061
440.387	22.9707
443.919	20.9785
447.451	19.4909
450.982	18.4177
454.512	15.5771
458.038	14.4501
461.565	13.9849
465.091	15.4877
468.613	15.8411
472.136	16.8296
475.655	17.3105
479.176	15.7654
482.692	17.5588
486.21	18.433
489.724	20.4136
493.237	22.8419
496.75	22.8188
500.26	23.177
503.769	22.9809
507.279	24.1494
510.785	25.4753
514.289	26.1876
517.793	26.4156
521.297	26.0814
524.797	26.6749
528.297	25.9641
531.795	24.157
535.291	25.124
538.787	23.753
542.281	23.29
545.773	23.7625
549.264	23.4628
552.754	22.1161
556.243	19.4374
559.73	17.7998
563.216	15.7834
566.701	12.799
570.182	11.095
573.664	9.11782
577.145	6.71044
580.624	6.13907
584.1	4.43507
587.577	3.56332
591.052	3.73751
594.524	5.40269
597.997	7.133
601.466	4.64945
604.936	4.37779
608.403	3.40174
611.87	3.30467
615.334	3.02315
618.799	4.08863
622.26	5.24684
625.72	7.26291
629.181	7.24966
632.638	9.89278
636.095	9.97578
639.551	10.6398
643.005	12.3819
646.457	12.4921
649.908	13.3649
653.357	14.2362
656.806	16.1127
660.253	17.2562
663.7	19.5505
667.145	21.2088
670.588	21.4084
674.027	22.9623
677.468	23.7913
680.907	23.383
684.345	22.697
687.781	23.3967
691.216	25.2244
694.65	25.6592
698.081	25.0204
701.512	25.0086
704.942	25.9888
708.371	24.677
711.796	23.9448
715.222	23.1653
718.645	23.8333
722.068	23.1073
725.49	23.6716
728.909	23.7171
732.329	24.3275
735.745	25.9416
739.16	25.8792
742.576	25.5724
745.988	27.7131
749.401	29.6612
752.811	33.4247
756.22	35.2001
759.627	37.6166
763.035	40.7399
766.44	44.7461
769.843	49.5061
773.245	52.6579
776.646	54.3853
780.046	57.1262
783.444	58.4897
786.841	62.0569
790.237	66.2131
793.631	68.6965
797.024	71.8648
800.416	75.1214
803.807	77.4801
807.196	78.8167
810.584	79.5272
813.971	80.906
817.354	81.6238
820.739	81.9876
824.122	79.5644
827.503	79.5331
830.882	80.0747
834.261	78.3303
837.637	76.9468
841.013	72.9335
844.389	71.2932
847.761	68.7738
851.131	65.2963
854.503	60.4417
857.871	58.5534
861.24	56.0662
864.606	53.0965
867.97	51.9081
871.336	51.3875
874.698	50.1333
878.058	48.9646
881.418	46.5564
884.778	45.0567
888.135	44.2749
891.49	43.473
894.845	44.0446
898.198	44.6679
901.55	45.7456
904.901	46.1788
908.25	46.018
911.598	46.6553
914.945	47.7736
918.291	48.6318
921.635	50.034
924.978	50.7303
928.318	50.9388
931.659	52.2463
934.998	53.2876
938.336	52.0519
941.671	52.061
945.007	51.2409
948.339	51.3188
951.672	52.2285
955.004	51.0694
958.333	50.5084
961.662	49.537
964.989	48.9975
968.315	51.3892
971.639	54.4764
974.962	56.4156
978.285	58.1178
981.605	59.5004
984.924	60.3757
988.243	60.4628
991.56	58.4221
994.875	58.9574
998.188	58.4836
1001.5	58.5221
1004.81	57.0842
1008.12	55.9349
1011.43	54.4479
1014.74	53.3255
1018.05	51.7708
1021.35	50.3961
1024.65	49.4396
1027.96	51.1491
1031.26	51.7689
1034.56	49.533
1037.86	47.6641
1041.16	44.7807
1044.45	44.8083
1047.75	44.1894
1051.04	44.0726
1054.33	42.5098
1057.62	41.7167
1060.91	38.1475
1064.2	35.826
1067.49	33.2988
1070.77	28.5743
1074.06	27.0271
1077.34	24.9747
1080.62	22.0888
1083.91	20.1656
1087.18	19.5236
1090.46	18.3886
1093.74	18.6404
1097.02	20.5333
1100.29	19.5754
1103.56	20.1643
1106.84	20.0346
1110.11	21.2553
1113.38	20.7467
1116.64	19.8468
1119.91	19.1884
1123.18	17.2907
1126.44	16.9569
1129.7	16.1807
1132.97	15.8258
1136.23	14.3735
1139.49	14.3829
1142.74	12.2527
1146	10.9914
1149.26	9.1882
1152.51	7.23204
1155.76	5.9185
1159.01	3.95449
1162.27	3.66672
1165.51	3.28004
1168.76	3.74318
1172.01	3.60289
1175.25	4.77205
1178.5	5.00173
1181.74	6.80068
1184.98	7.66816
1188.22	8.73637
1191.46	11.0369
1194.7	12.3807
1197.94	12.7052
1201.17	12.5691
1204.41	14.4418
1207.64	15.2849
1210.87	17.328
1214.1	17.5658
1217.33	21.5676
1220.56	23.3498
1223.79	23.8525
1227.01	26.6213
1230.23	28.3872
1233.46	30.902
1236.68	34.0054
1239.9	35.0196
1243.12	36.6174
1246.34	37.565
1249.55	39.3744
1252.77	39.4972
1255.98	39.6995
1259.2	39.1833
1262.41	39.3928
1265.62	38.3439
1268.83	39.3627
1272.03	39.3682
1275.24	39.1786
1278.45	39.3805
1281.65	40.0381
1284.85	41.2893
1288.06	41.8189
1291.26	43.3778
1294.46	45.8926
1297.66	48.1036
1300.85	49.5666
1304.05	52.7128
1307.24	54.9969
1310.43	56.572
1313.63	58.7924
1316.82	59.821
1320.01	60.371
1323.2	59.2847
1326.38	60.2626
1329.57	58.9699
1332.76	56.7407
1335.94	55.7971
1339.12	53.8192
1342.3	53.1528
1345.48	50.8646
1348.66	50.1714
1351.84	46.9827
1355.01	44.7653
1358.19	42.7013
1361.36	41.2148
1364.53	39.6396
1367.71	37.4232
1370.88	37.0074
1374.04	35.035
1377.21	34.5289
1380.38	32.8995
1383.54	35.0053
1386.71	35.9586
1389.87	36.5205
1393.03	38.6352
1396.19	39.4096
1399.35	39.7207
1402.51	39.0276
1405.67	40.6219
1408.82	40.4981
1411.98	42.7936
1415.13	45.2856
1418.28	48.0773
1421.43	51.8135
1424.58	55.2717
1427.73	59.3607
1430.88	63.158
1434.02	67.851
1437.17	71.3397
1440.31	75.3594
1443.45	77.5159
1446.6	80.7217
1449.74	80.5626
1452.87	81.6452
1456.01	81.1838
1459.15	79.6526
1462.28	78.8642
1465.42	74.9915
1468.55	70.7308
1471.68	65.2645
1474.81	59.555
1477.94	52.5507
1481.07	47.3053
1484.2	41.0259
1487.32	36.3861
1490.45	31.628
1493.57	28.2915
1496.69	24.4241
1499.81	22.2477
1502.93	21.3556
1506.05	19.2983
1509.17	18.6107
1512.28	18.1109
1515.4	17.986
1518.51	18.8772
1521.63	17.9036
1524.74	18.2337
1527.85	18.5845
1530.96	18.575
1534.06	20.1412
1537.17	21.1806
1540.28	21.7921
1543.38	22.8978
1546.48	25.1884
1549.59	26.763
1552.69	29.0223
1555.79	30.5072
1558.88	31.2077
1561.98	31.6563
1565.08	30.7808
1568.17	31.9389
1571.27	34.4641
1574.36	36.9064
1577.45	38.1186
1580.54	39.9721
1583.63	42.6728
1586.72	45.3557
1589.8	46.2132
1592.89	48.1968
1595.97	49.8584
1599.06	50.1893
1602.14	50.7041
1605.22	51.097
1608.3	51.209
1611.38	51.8015
1614.46	53.8185
1617.53	55.9898
1620.61	56.8103
1623.68	57.4194
1626.75	57.9558
1629.82	57.5878
1632.9	57.9479
1635.96	57.1494
1639.03	58.0421
1642.1	59.5189
1645.16	61.5917
1648.23	62.4736
1651.29	62.9522
1654.36	63.8597
1657.42	64.5491
1660.48	64.7556
1663.53	63.6801
1666.59	61.4519
1669.65	58.9103
1672.7	55.7685
1675.76	51.1593
1678.81	46.6219
1681.86	43.3166
1684.91	40.6604
1687.96	37.3092
1691.01	34.8395
1694.06	30.3809
1697.11	27.007
1700.15	24.0167
1703.2	20.8165
1706.24	18.9357
1709.28	19.0076
1712.32	17.1761
1715.36	16.2964
1718.4	14.5642
1721.43	13.8764
1724.47	13.4604
1727.5	12.8219
1730.54	11.9484
1733.57	10.8896
1736.6	9.84753
1739.63	9.65255
1742.66	9.71966
1745.69	8.85164
1748.72	7.8776
1751.74	6.32954
1754.77	7.49095
1757.79	7.73199
1760.81	7.43455
1763.83	7.04265
1766.85	6.52491
1769.87	6.79509
1772.89	6.63898
1775.91	7.80746
1778.92	7.3673
1781.94	6.3367
1784.95	5.8553
1787.96	6.02205
1790.97	5.50013
1793.98	4.96571
1796.99	5.67789
1800	4.26684
1803	2.28861
1806.01	1.77883
1809.01	2.41701
1812.02	3.31751
1815.02	4.23342
1818.02	4.40919
1821.02	4.95599
1824.02	5.25735
1827.01	6.3101
1830.01	5.99572
1833	6.01345
1836	5.63451
1838.99	5.1298
1841.98	6.15737
1844.97	5.74554
1847.96	5.6809
1850.95	4.43582
1853.94	2.78299
1856.92	3.03296
1859.91	3.43043
1862.89	2.50033
1865.88	2.26749
1868.86	1.61228
1871.84	1.01647
1874.82	0.611412
1877.8	1.00886
1880.77	1.23587
1882.52	2.29511
1885.51	2.89143
1888.5	3.62085
1891.49	5.44133
1894.47	6.82604
1897.46	6.65969
1900.44	6.98715
1903.42	7.52674
1906.4	7.93922
1909.38	7.33318
1912.36	9.71623
1915.34	9.48904
1918.32	8.43646
1921.29	8.58951
1924.27	8.10888
1927.24	7.77099
1930.21	8.65271
1933.18	8.39307
1936.15	8.91948
1939.12	8.10177
1942.09	6.64418
1945.06	6.79555
1948.02	6.14581
1950.99	5.09823
1953.95	4.33472
1956.91	3.9771
1959.87	3.18663
1962.84	2.79958
1965.79	3.04021
1968.75	2.02988
1971.71	1.50954
1974.66	1.75563
1977.62	2.62311
1980.57	2.70177
1983.53	3.54657
1986.48	4.07262
1989.43	5.18407
1992.38	5.58399
1995.33	6.9184
1998.27	7.19261
2001.22	8.01779
2004.16	9.32791
2007.11	9.26435
2010.05	8.00713
2012.99	7.22568
2015.93	7.25582
2018.87	7.38931
2021.81	5.58794
2024.75	4.09755
2027.69	3.6788
2030.62	2.95426
2033.56	2.45385
2036.49	1.64122
2039.42	1.96687
2042.35	2.29542
2045.28	2.20202
2048.21	3.64639
2051.14	4.60286
2054.06	4.9997
2056.99	5.99582
2059.92	6.70561
2062.84	8.50757
2065.76	8.75938
2068.68	8.46639
2071.6	10.4068
2074.52	11.9855
2077.44	13.1551
2080.36	13.993
2083.27	14.0397
2086.19	13.4835
2089.1	13.2258
2092.01	12.8388
2094.93	12.7215
2097.84	13.1286
2100.75	12.2123
2103.66	11.4055
2106.56	10.32
2109.47	11.039
2112.37	11.4565
2115.28	10.5906
2118.18	10.9626
2121.09	11.3605
2123.99	11.3841
2126.89	12.1889
2129.79	12.6253
2132.68	14.4594
2135.58	15.7596
2138.48	16.0723
2141.37	18.3591
2144.26	20.4067
2147.16	22.1319
2150.05	23.692
2152.94	23.6497
2155.83	24.2259
2158.72	25.2589
2161.6	27.6179
2164.49	29.2812
2167.38	29.0323
2170.26	29.3948
2173.14	29.3124
2176.03	29.5645
2178.91	30.2614
2181.79	29.5943
2184.67	28.1972
2187.54	26.3319
2190.42	25.4976
2193.3	23.8118
2196.17	23.1492
2199.05	22.9256
2201.92	22.0519
2204.79	21.0403
2207.66	19.0305
2210.53	17.6504
2213.4	17.0158
2216.27	15.6973
2219.13	15.0656
2222	13.8299
2224.86	13.914
2227.72	12.7364
2230.59	12.2344
2233.45	12.6975
2236.31	12.2581
2239.17	10.6805
2242.03	10.4845
2244.88	10.2199
2247.74	10.0656
2250.59	11.2501
2253.45	11.2487
2256.3	11.5226
2259.15	12.2134
2262	12.6859
2264.85	13.8577
2267.7	14.4807
2270.55	14.8752
2273.4	13.9255
2276.24	13.4437
2279.09	13.2175
2281.93	13.0717
2284.77	12.3886
2287.61	11.9807
2290.46	12.1244
2293.29	11.1113
2296.13	10.04
2298.97	9.44341
2301.81	10.9658
2304.64	10.5743
2307.48	10.2867
2310.31	9.79944
2313.14	10.1462
2315.97	11.6557
2318.8	13.6387
2321.63	14.0511
2324.46	14.3151
2327.29	13.7611
2330.12	14.1238
2332.94	13.6568
2335.76	12.5291
2338.59	12.944
2341.41	11.2377
2344.23	9.77991
2347.05	8.89763
2349.87	7.07342
2352.69	6.01134
2355.5	5.24005
2358.32	4.71592
2361.14	3.2203
2363.95	2.61386
2366.76	2.52503
2369.58	2.01335
2372.39	2.63861
2375.2	2.19335
2378	2.50843
2380.81	2.35013
2383.62	3.37961
2386.42	3.43766
2389.23	3.43408
2392.03	2.88751
2394.84	3.68629
2397.64	4.86598
2400.44	4.79901
2403.24	3.15452
2406.04	4.27171
2408.83	3.21128
2411.63	3.12743
2414.43	2.69863
2417.22	3.48124
2420.02	2.88545
2422.81	3.69895
2425.6	3.77523
2428.39	3.37897
2431.18	4.11451
2433.97	4.07819
2436.76	2.75317
2439.54	3.01181
2442.33	3.57032
2445.11	3.59709
2447.9	3.75905
2450.68	3.72739
2453.46	3.60109
2456.24	3.52816
2459.02	3.05418
2461.8	3.1604
2464.58	3.53144
2467.36	3.36087
2470.13	2.2312
2472.91	2.21241
2475.68	2.87838
2478.45	3.52382
2481.22	3.87626
2484	3.38517
2486.77	4.22239
2489.54	4.09594
2492.3	3.83445
2495.07	3.61744
2497.84	3.56513
2500.6	3.07106
2503.36	2.02785
2506.13	2.04052
2508.89	1.51119
2511.65	1.05976
2514.41	0.335517
2517.17	0.486598
2519.93	1.67304
2522.68	2.15526
2525.44	3.36942
2528.19	4.28874
2530.95	4.69633
2533.7	5.19475
2536.45	5.99875
2539.2	5.39035
2541.95	4.39484
2544.7	4.77712
2547.45	4.47457
2550.2	4.17924
2552.94	4.7468
2555.69	4.29631
2558.43	4.49816
2561.17	3.9317
2563.92	3.45516
2566.66	4.09079
2569.4	4.01733
2572.14	3.71859
2574.88	3.54997
2577.61	2.92397
2580.35	3.71299
2583.09	5.1245
2585.82	6.29141
2588.55	7.28826
2591.28	7.60776
2594.02	9.28416
2596.75	7.79689
2599.48	6.44321
2602.2	7.17253
2604.93	6.0716
2607.66	6.28417
2610.38	5.26326
2613.11	5.14076
2615.83	4.00072
2618.56	3.96272
2621.28	4.83676
2624	3.79807
2626.72	4.75421
2629.44	3.54222
2632.15	4.29147
2634.87	5.02806
2637.59	4.69795
2640.3	4.96889
2643.02	4.70185
2645.73	4.92053
2648.44	4.77323
2651.15	4.70115
2653.86	5.06776
2656.57	5.95643
2659.28	5.61293
2661.99	5.50583
2664.69	5.4936
2667.4	7.05111
2670.1	7.67606
2672.81	8.12473
2675.51	8.25612
2678.21	8.2408
2680.91	8.08673
2683.61	8.67997
2686.31	9.92378
2689	10.669
2691.7	11.4163
2694.4	12.4607
2697.09	11.9126
2699.79	11.6643
2702.48	11.9061
2705.17	12.8114
2707.86	13.5757
2710.55	13.721
2713.24	14.1451
2715.93	14.0803
2718.61	14.6896
2721.3	14.5172
2723.99	13.7735
2726.67	14.0188
2729.35	13.308
2732.04	14.1393
2734.72	12.8798
2737.4	12.4773
2740.08	11.1263
2742.76	9.36059
2745.43	8.37545
2748.11	7.65614
2750.79	7.83473
2753.46	6.48876
2756.13	5.5352
2758.81	5.1811
2761.48	3.34857
2764.15	2.14499
2766.82	2.8431
2769.49	3.44937
2772.16	2.85907
2774.82	2.63731
2777.49	1.79561
2780.16	1.70837
2782.82	1.52484
2785.48	1.47681
2788.15	1.52911
2790.81	0.632184
2793.47	0.715811
2796.13	0.985088
2798.79	1.53669
2801.44	1.16057
2804.1	0.338801
2806.76	0.333797
2809.41	0.189801
2812.07	-0.00955211
2814.72	1.35176
2817.37	1.32358
2820.02	3.2889
2822.67	7.03768
2825.32	11.564
2827.97	16.3372
2830.62	22.7405
2833.26	28.9884
2835.91	34.8936
2838.55	41.4857
2841.2	49.7088
2843.84	58.1641
2846.48	67.218
2849.12	77.6631
2851.76	87.2965
2854.4	98.1602
2857.04	109.029
2859.68	119.781
2862.32	130.029
2864.95	138.829
2867.58	146.091
2870.22	153.563
2872.85	159.141
2875.48	164.242
2878.11	170.816
2880.74	175.847
2883.37	181.432
2886	187.415
2888.63	193.309
2891.25	198.296
2893.88	203.328
2896.5	208.155
2899.13	213.485
2901.75	219.978
2904.37	227.505
2906.99	235.434
2909.61	244.421
2912.23	253.372
2914.85	262.061
2917.46	270.617
2920.08	278.819
2922.7	285.336
2925.31	289.638
2927.92	291.036
2930.53	291.076
2933.15	288.865
2935.76	285.615
2938.37	280.108
2940.98	274.66
2943.58	266.355
2946.19	256.775
2948.8	247.428
2951.4	237.161
2954.01	225.877
2956.61	214.202
2959.21	203.208
2961.81	192.761
2964.41	182.24
2967.01	172.127
2969.61	163.578
2972.21	153.957
2974.81	144.859
2977.4	134.781
2980	125.796
2982.59	116.733
2985.18	107.776
2987.78	97.7823
2990.37	87.6637
2992.96	77.7545
2995.55	68.3162
2998.14	59.3029
3000.72	50.3866
3003.31	42.1207
3005.9	35.6618
3008.48	29.4153
3011.07	23.2422
3013.65	17.6683
3016.23	12.8916
3018.81	8.87305
3021.39	5.36794
3023.97	2.8461
3026.55	1.23152
3029.13	0.0637721
3031.71	-0.309598
3034.28	-0.297266
3036.86	0.374127
3039.43	0.212316
3042.01	1.37794
3044.58	2.1453
3047.15	3.44612
3049.72	5.45657
3052.29	6.56834
3054.86	6.92217
3057.43	7.875
3060	8.02169
3062.56	8.19047
3065.13	8.65477
3067.69	8.99011
3070.25	9.05773
3072.82	8.72173
3075.38	8.01891
3077.94	6.89409
3080.5	5.41041
3083.06	3.44291
3085.62	2.95902
3088.17	2.15922
3090.73	1.94778
3093.29	1.78218
3095.84	1.67441
3098.4	2.5525
3100.95	2.94597
3103.5	4.41296
3106.05	4.29398
3108.6	6.25392
3111.15	8.56785
3113.7	9.23068
3116.25	10.9253
3118.79	12.3116
3121.34	13.8805
3123.88	15.1368
3126.43	16.7227
3128.97	18.7679
3131.51	19.791
3134.05	21.7848
3136.59	22.6535
3139.14	22.3577
3141.67	21.9679
3144.21	22.2142
3146.75	21.9667
3149.28	21.7469