File: data/Raman/poly_smoothed/Mb_10_14_40_1x_45s_532 nm_x100_100%_600 gr_mm_01.txt
#Acq. time (s)=	45
#Accumulations=	2
#Range (cm-¹)=	200...3150
#Windows=	2
#Auto scanning=	Off
#Autofocus=	Off
#Macrospot=	Off
#AutoExposure=	Off
#Spike filter=	Multiple accum.
#Delay time (s)=	0
#Binning=	1
#Readout mode=	Signal
#DeNoise=	Off
#ICS correction=	On
#Dark correction=	Off
#Inst. Process=	Off
#Detector Gain=	Best Dynamic Range
#Detector ADC=	20 kHz
#Detector temperature (°C)=	-69.85
#Instrument=	LabRAM HR Evol
#Detector=	Synapse
#Objective=	x100
#Grating=	600 gr/mm
#ND Filter=	100%
#Laser (nm)=	532
#Hole=	100.021
#Range=	Auto
#Laser Pol.=	No
#Raman. Pol.=	No
#Laser Pol. (°)=	-0.0007625
#Raman Pol. (°)=	89.9995
#Collection=	Microscope
#StageXY=	Marzhauser
#StageZ=	Marzhauser
#X (µm)=	-623.4
#Y (µm)=	-1678.9
#Z (µm)=	89
#Full time(mm:ss)=	3:20
#Project=
#Sample=
#Site=
#Title=	Mb_10_14_40_2x_45s_532 nm_x100_100%_600 gr_mm
#Remark=
#Date=	11.07.2022 11:36
#Acquired=	11.07.2022 11:36:20
#Base:Fit=	10.08.2022 10:21:11
#Base:Sub=	10.08.2022 10:21:41
#Filter:Polynom=	16.08.2022 10:17:53
#AxisType[0]=Intens
#AxisUnit[0]=Cnt
#AxisType[1]=Spectr
#AxisUnit[1]=1/cm
200.388	12.1871
204.019	14.1973
207.646	15.2943
211.274	15.7814
214.899	16.6905
218.524	19.0068
222.146	23.8415
225.766	28.1642
229.388	31.376
233.005	35.15
236.621	38.6428
240.236	40.8599
243.852	43.7677
247.464	44.0623
251.074	43.1697
254.683	44.6665
258.291	44.1444
261.897	44.6184
265.504	45.5389
269.108	42.976
272.71	40.1894
276.311	36.959
279.91	33.2421
283.508	30.6751
287.105	26.2027
290.698	22.7362
294.291	20.8472
297.884	17.8658
301.475	16.7595
305.064	16.0677
308.652	14.7337
312.237	13.3202
315.822	11.3594
319.406	11.1676
322.987	11.7013
326.568	10.8042
330.148	10.3306
333.724	9.13186
337.301	6.79697
340.875	8.48177
344.449	7.80613
348.02	10.7121
351.592	13.0359
355.16	14.3168
358.728	18.3966
362.294	21.0666
365.858	24.8595
369.422	29.2554
372.983	34.471
376.543	38.7199
380.102	44.3443
383.661	48.3319
387.216	52.3526
390.771	56.3697
394.324	55.735
397.875	55.3296
401.425	55.5046
404.974	54.089
408.524	52.5996
412.07	50.9183
415.614	45.0165
419.156	41.5264
422.698	36.3263
426.238	33.4332
429.777	31.1149
433.315	27.7338
436.852	24.3495
440.387	19.7024
443.919	16.6222
447.451	14.5946
450.982	13.4773
454.512	13.8365
458.038	14.5154
461.565	16.2312
465.091	16.3813
468.613	19.423
472.136	21.6195
475.655	22.3362
479.176	22.9063
482.692	22.8014
486.21	24.35
489.724	24.2806
493.237	25.7955
496.75	26.8144
500.26	25.9615
503.769	25.8065
507.279	27.3745
510.785	27.6053
514.289	27.0796
517.793	26.0199
521.297	26.0692
524.797	26.1307
528.297	25.8447
531.795	25.7161
535.291	24.8344
538.787	23.2267
542.281	23.7354
545.773	23.7788
549.264	22.2153
552.754	20.9669
556.243	18.2349
559.73	15.9498
563.216	13.3219
566.701	11.8681
570.182	9.45098
573.664	8.63834
577.145	6.8319
580.624	6.78684
584.1	4.50813
587.577	2.85669
591.052	1.85914
594.524	2.85831
597.997	2.61563
601.466	3.76573
604.936	4.54678
608.403	5.81498
611.87	6.89414
615.334	7.2279
618.799	6.37775
622.26	6.41986
625.72	6.08002
629.181	8.27414
632.638	7.4977
636.095	7.93119
639.551	8.28228
643.005	10.186
646.457	10.8036
649.908	10.9872
653.357	11.0123
656.806	10.3261
660.253	9.96113
663.7	8.74924
667.145	7.5186
670.588	6.68278
674.027	6.57954
677.468	8.1986
680.907	8.54978
684.345	9.10642
687.781	9.61612
691.216	9.29962
694.65	9.82973
698.081	11.9156
701.512	12.7137
704.942	14.4668
708.371	15.8908
711.796	17.1556
715.222	20.9779
718.645	21.2437
722.068	23.1821
725.49	24.5286
728.909	25.9406
732.329	24.4739
735.745	23.0765
739.16	23.3704
742.576	24.2922
745.988	23.3034
749.401	25.5434
752.811	27.3536
756.22	30.0966
759.627	30.9127
763.035	31.5717
766.44	32.9414
769.843	32.4532
773.245	36.5576
776.646	38.2106
780.046	42.9004
783.444	47.1736
786.841	49.1423
790.237	51.724
793.631	55.2022
797.024	57.0976
800.416	60.4507
803.807	62.9409
807.196	64.9669
810.584	65.3501
813.971	66.5855
817.354	67.9234
820.739	70.2678
824.122	71.2024
827.503	72.2192
830.882	72.8603
834.261	73.7088
837.637	73.1564
841.013	71.3069
844.389	68.1352
847.761	66.478
851.131	62.0474
854.503	59.4569
857.871	58.8401
861.24	56.6938
864.606	52.9798
867.97	49.2708
871.336	46.4885
874.698	43.8982
878.058	42.0552
881.418	39.8109
884.778	37.7843
888.135	34.2965
891.49	32.5377
894.845	30.7505
898.198	29.4665
901.55	29.454
904.901	28.4218
908.25	26.4318
911.598	29.3263
914.945	30.7598
918.291	30.4671
921.635	33.8619
924.978	34.8955
928.318	34.944
931.659	37.1622
934.998	38.9929
938.336	40.9844
941.671	39.9017
945.007	40.5329
948.339	38.6203
951.672	39.9612
955.004	40.1485
958.333	39.1556
961.662	37.7702
964.989	37.9393
968.315	38.4923
971.639	38.459
974.962	39.8284
978.285	39.8061
981.605	39.8908
984.924	41.0584
988.243	41.2908
991.56	41.2734
994.875	42.558
998.188	45.0328
1001.5	45.4927
1004.81	47.0408
1008.12	48.5841
1011.43	50.0402
1014.74	53.4217
1018.05	54.1824
1021.35	55.6037
1024.65	57.7017
1027.96	60.6057
1031.26	62.3276
1034.56	61.5166
1037.86	59.6556
1041.16	57.9758
1044.45	55.7129
1047.75	53.7813
1051.04	52.5682
1054.33	46.9499
1057.62	43.0659
1060.91	38.6608
1064.2	32.2746
1067.49	26.9894
1070.77	20.8389
1074.06	16.5867
1077.34	12.4906
1080.62	9.32302
1083.91	6.49833
1087.18	5.95902
1090.46	4.9614
1093.74	5.30192
1097.02	7.1569
1100.29	9.16372
1103.56	12.3017
1106.84	13.489
1110.11	14.7394
1113.38	13.1419
1116.64	11.7714
1119.91	11.5476
1123.18	11.3104
1126.44	11.3428
1129.7	11.12
1132.97	8.54912
1136.23	7.94775
1139.49	6.42609
1142.74	6.34948
1146	4.96377
1149.26	4.99115
1152.51	3.91531
1155.76	1.84302
1159.01	1.52592
1162.27	2.684
1165.51	2.63528
1168.76	1.82939
1172.01	1.62988
1175.25	3.59183
1178.5	4.25055
1181.74	4.0795
1184.98	4.94488
1188.22	3.69801
1191.46	3.0205
1194.7	3.6608
1197.94	5.32993
1201.17	6.92871
1204.41	10.3891
1207.64	13.6212
1210.87	14.8741
1214.1	17.3866
1217.33	22.0815
1220.56	27.2136
1223.79	32.9179
1227.01	36.8657
1230.23	39.3452
1233.46	43.274
1236.68	45.3348
1239.9	47.6008
1243.12	51.4613
1246.34	51.9544
1249.55	54.4555
1252.77	56.9927
1255.98	58.9652
1259.2	58.9353
1262.41	58.416
1265.62	57.1396
1268.83	57.5413
1272.03	58.0484
1275.24	58.0641
1278.45	59.8552
1281.65	62.505
1284.85	65.5776
1288.06	66.9785
1291.26	67.7966
1294.46	69.8486
1297.66	73.4355
1300.85	74.6685
1304.05	73.7682
1307.24	74.7665
1310.43	74.5829
1313.63	75.5968
1316.82	75.6566
1320.01	76.8332
1323.2	76.7434
1326.38	77.6852
1329.57	77.922
1332.76	76.4567
1335.94	74.4524
1339.12	70.7246
1342.3	70.3567
1345.48	68.5324
1348.66	65.7515
1351.84	62.6331
1355.01	61.8631
1358.19	60.6307
1361.36	59.0835
1364.53	57.7119
1367.71	55.8001
1370.88	53.2449
1374.04	52.7945
1377.21	51.4995
1380.38	48.9396
1383.54	49.4121
1386.71	50.2278
1389.87	50.8448
1393.03	51.0106
1396.19	50.3392
1399.35	51.2036
1402.51	51.7799
1405.67	52.1319
1408.82	53.4106
1411.98	58.294
1415.13	62.4921
1418.28	68.8716
1421.43	75.4177
1424.58	81.4108
1427.73	88.1543
1430.88	95.3929
1434.02	103.626
1437.17	109.878
1440.31	114.662
1443.45	118.676
1446.6	120.501
1449.74	120.719
1452.87	120.719
1456.01	119.189
1459.15	116.18
1462.28	112.349
1465.42	106.581
1468.55	100.811
1471.68	94.3273
1474.81	88.2477
1477.94	79.7526
1481.07	72.93
1484.2	69.1272
1487.32	65.4938
1490.45	60.9869
1493.57	55.7955
1496.69	53.0312
1499.81	49.0792
1502.93	46.4938
1506.05	44.6099
1509.17	42.7971
1512.28	37.8975
1515.4	36.5865
1518.51	34.033
1521.63	31.7219
1524.74	30.4648
1527.85	29.7389
1530.96	28.5657
1534.06	26.6966
1537.17	25.8287
1540.28	27.5369
1543.38	29.2923
1546.48	31.7618
1549.59	35.0613
1552.69	36.5332
1555.79	39.2401
1558.88	42.7444
1561.98	44.852
1565.08	46.4536
1568.17	48.8932
1571.27	51.9896
1574.36	55.5287
1577.45	58.8444
1580.54	63.3127
1583.63	66.1184
1586.72	69.6978
1589.8	71.5059
1592.89	74.5799
1595.97	76.1082
1599.06	77.5069
1602.14	77.2022
1605.22	78.304
1608.3	77.4253
1611.38	77.5134
1614.46	77.8845
1617.53	76.5913
1620.61	75.1308
1623.68	76.449
1626.75	76.3503
1629.82	76.266
1632.9	77.2242
1635.96	78.9168
1639.03	81.1261
1642.1	80.9358
1645.16	82.6374
1648.23	84.5558
1651.29	86.9527
1654.36	87.5286
1657.42	88.6917
1660.48	88.3403
1663.53	87.4908
1666.59	86.1677
1669.65	83.1368
1672.7	78.1986
1675.76	73.4523
1678.81	69.3567
1681.86	63.989
1684.91	58.3648
1687.96	53.5403
1691.01	47.9699
1694.06	42.5888
1697.11	39.2687
1700.15	36.1746
1703.2	31.3893
1706.24	27.0453
1709.28	23.59
1712.32	21.7708
1715.36	19.9642
1718.4	17.4067
1721.43	14.6734
1724.47	15.2003
1727.5	12.7574
1730.54	10.373
1733.57	10.4433
1736.6	8.15646
1739.63	6.92553
1742.66	5.13729
1745.69	2.29581
1748.72	1.7912
1751.74	1.22027
1754.77	0.568438
1757.79	0.839248
1760.81	1.24451
1763.83	1.5514
1766.85	0.864678
1769.87	0.958386
1772.89	1.15723
1775.91	2.29583
1778.92	2.22661
1781.94	2.37674
1784.95	3.92654
1787.96	5.55603
1790.97	6.20724
1793.98	7.05829
1796.99	7.03017
1800	6.94048
1803	6.23059
1806.01	6.16623
1809.01	6.70952
1812.02	6.16826
1815.02	6.6777
1818.02	6.9688
1821.02	6.76959
1824.02	5.41882
1827.01	5.85179
1830.01	6.68796
1833	7.13922
1836	6.32549
1838.99	6.30321
1841.98	6.52351
1844.97	5.87812
1847.96	4.86945
1850.95	4.14169
1853.94	2.81494
1856.92	2.92174
1859.91	2.39584
1862.89	2.48246
1865.88	2.40266
1868.86	1.52541
1871.84	1.17077
1874.82	1.18427
1877.8	1.38589
1880.77	1.94186
1882.52	2.58303
1885.51	2.76962
1888.5	3.98739
1891.49	4.1209
1894.47	4.66923
1897.46	5.62681
1900.44	6.43945
1903.42	6.93459
1906.4	7.1242
1909.38	8.12984
1912.36	7.46129
1915.34	7.07735
1918.32	7.24029
1921.29	6.58169
1924.27	5.90419
1927.24	4.81633
1930.21	4.78738
1933.18	6.44305
1936.15	6.39391
1939.12	7.20921
1942.09	6.75036
1945.06	6.25132
1948.02	6.69963
1950.99	6.54276
1953.95	7.02137
1956.91	6.44326
1959.87	5.9048
1962.84	5.48365
1965.79	5.70415
1968.75	6.21467
1971.71	5.06671
1974.66	4.95677
1977.62	4.79861
1980.57	4.60561
1983.53	6.35229
1986.48	7.61334
1989.43	8.34459
1992.38	8.66668
1995.33	8.2335
1998.27	8.08293
2001.22	8.25773
2004.16	8.90108
2007.11	9.29196
2010.05	8.41951
2012.99	7.74966
2015.93	6.97508
2018.87	5.77979
2021.81	5.52087
2024.75	5.28287
2027.69	4.08105
2030.62	4.14645
2033.56	4.34024
2036.49	5.79086
2039.42	5.99022
2042.35	5.52878
2045.28	4.40205
2048.21	6.27028
2051.14	8.59523
2054.06	10.7767
2056.99	12.2237
2059.92	13.9451
2062.84	13.7192
2065.76	14.025
2068.68	14.6073
2071.6	14.9811
2074.52	14.9439
2077.44	15.7503
2080.36	15.6932
2083.27	14.4144
2086.19	14.3362
2089.1	13.4191
2092.01	12.2862
2094.93	14.1355
2097.84	13.8682
2100.75	14.7007
2103.66	14.9561
2106.56	14.3493
2109.47	13.7635
2112.37	14.4189
2115.28	14.3971
2118.18	15.4482
2121.09	18.2293
2123.99	20.1634
2126.89	20.321
2129.79	21.4752
2132.68	22.8952
2135.58	24.1422
2138.48	25.6351
2141.37	28.6943
2144.26	30.0892
2147.16	31.7877
2150.05	32.2763
2152.94	33.0389
2155.83	34.9122
2158.72	35.5592
2161.6	36.0982
2164.49	37.1723
2167.38	39.1189
2170.26	40.2457
2173.14	40.4617
2176.03	39.8756
2178.91	39.9458
2181.79	40.7429
2184.67	40.3556
2187.54	39.4933
2190.42	37.5832
2193.3	37.6206
2196.17	35.4716
2199.05	33.6412
2201.92	31.9951
2204.79	29.8581
2207.66	27.8217
2210.53	26.8882
2213.4	25.6972
2216.27	23.0434
2219.13	21.145
2222	18.546
2224.86	16.2674
2227.72	15.9366
2230.59	14.1369
2233.45	12.9874
2236.31	14.0198
2239.17	14.2029
2242.03	13.3766
2244.88	13.8864
2247.74	15.663
2250.59	15.0699
2253.45	14.1999
2256.3	13.0503
2259.15	13.296
2262	13.8991
2264.85	13.7367
2267.7	12.7852
2270.55	11.8257
2273.4	10.4062
2276.24	10.0465
2279.09	9.07288
2281.93	8.95849
2284.77	7.83888
2287.61	7.03111
2290.46	5.10463
2293.29	3.61484
2296.13	3.62203
2298.97	3.10583
2301.81	4.90297
2304.64	6.10826
2307.48	7.87817
2310.31	8.37111
2313.14	9.48402
2315.97	10.7082
2318.8	11.0244
2321.63	10.7661
2324.46	10.5919
2327.29	9.45949
2330.12	8.79568
2332.94	9.43325
2335.76	8.31945
2338.59	7.9491
2341.41	6.23797
2344.23	5.28269
2347.05	4.24329
2349.87	3.77726
2352.69	2.85917
2355.5	0.852617
2358.32	0.988132
2361.14	0.730617
2363.95	1.27791
2366.76	3.95749
2369.58	5.59298
2372.39	7.49851
2375.2	7.77921
2378	8.81047
2380.81	9.51444
2383.62	9.8617
2386.42	8.94073
2389.23	7.56552
2392.03	7.02202
2394.84	6.06682
2397.64	6.54449
2400.44	5.45903
2403.24	5.72992
2406.04	5.89626
2408.83	4.87093
2411.63	3.06568
2414.43	3.60787
2417.22	3.24822
2420.02	3.25788
2422.81	3.30987
2425.6	3.0482
2428.39	3.65215
2431.18	5.13626
2433.97	6.50847
2436.76	7.28798
2439.54	7.45628
2442.33	7.09434
2445.11	7.1977
2447.9	6.85998
2450.68	6.07307
2453.46	5.20132
2456.24	4.06593
2459.02	4.09365
2461.8	3.85942
2464.58	2.95712
2467.36	0.747763
2470.13	0.714752
2472.91	1.69693
2475.68	0.418355
2478.45	-1.18868
2481.22	-0.616826
2484	0.677002
2486.77	1.42661
2489.54	1.27999
2492.3	1.55227
2495.07	1.54469
2497.84	2.6861
2500.6	3.36456
2503.36	3.12875
2506.13	2.97678
2508.89	3.05925
2511.65	2.4953
2514.41	3.28904
2517.17	2.97009
2519.93	2.36741
2522.68	2.5408
2525.44	4.11583
2528.19	4.2334
2530.95	4.00528
2533.7	4.13947
2536.45	5.86079
2539.2	6.4352
2541.95	6.2178
2544.7	7.90007
2547.45	9.06211
2550.2	8.85728
2552.94	10.4923
2555.69	11.4204
2558.43	11.1099
2561.17	12.1269
2563.92	10.8702
2566.66	10.1502
2569.4	9.75651
2572.14	9.9263
2574.88	8.26081
2577.61	7.49937
2580.35	7.26243
2583.09	6.75707
2585.82	5.77872
2588.55	5.55217
2591.28	5.48872
2594.02	5.14198
2596.75	4.61723
2599.48	4.69036
2602.2	4.81953
2604.93	4.69556
2607.66	2.94426
2610.38	3.63231
2613.11	4.33776
2615.83	3.67543
2618.56	4.46886
2621.28	6.43021
2624	5.62025
2626.72	6.13016
2629.44	5.16831
2632.15	5.58224
2634.87	7.00864
2637.59	7.48934
2640.3	6.51431
2643.02	7.8044
2645.73	7.11609
2648.44	8.31524
2651.15	7.7977
2653.86	7.6207
2656.57	7.76975
2659.28	7.69846
2661.99	7.3636
2664.69	8.05526
2667.4	9.00869
2670.1	9.52418
2672.81	9.13507
2675.51	10.0699
2678.21	11.3173
2680.91	11.3475
2683.61	11.5077
2686.31	12.8559
2689	12.1922
2691.7	12.3179
2694.4	12.4199
2697.09	12.6934
2699.79	13.3894
2702.48	13.6089
2705.17	14.6463
2707.86	14.9945
2710.55	14.9887
2713.24	16.4858
2715.93	18.6143
2718.61	19.8985
2721.3	21.8212
2723.99	21.999
2726.67	21.5577
2729.35	22.2949
2732.04	22.7668
2734.72	22.195
2737.4	21.2498
2740.08	19.5617
2742.76	18.9721
2745.43	18.3773
2748.11	16.5521
2750.79	15.9649
2753.46	13.5776
2756.13	11.2321
2758.81	9.37139
2761.48	6.83496
2764.15	5.84694
2766.82	5.64662
2769.49	5.23955
2772.16	4.97174
2774.82	5.40082
2777.49	5.57879
2780.16	7.12618
2782.82	7.24497
2785.48	6.53387
2788.15	5.22028
2790.81	3.64196
2793.47	3.1736
2796.13	2.42798
2798.79	1.38633
2801.44	2.6429
2804.1	2.90896
2806.76	3.40264
2809.41	3.81669
2812.07	4.51778
2814.72	3.98458
2817.37	4.45305
2820.02	5.38326
2822.67	8.35233
2825.32	13.5892
2827.97	19.9699
2830.62	26.7286
2833.26	32.6449
2835.91	40.2219
2838.55	48.4014
2841.2	57.7246
2843.84	68.0823
2846.48	81.5211
2849.12	94.8538
2851.76	107.284
2854.4	121.034
2857.04	134.284
2859.68	147.907
2862.32	161.45
2864.95	175.557
2867.58	187.147
2870.22	196.623
2872.85	204.711
2875.48	214.661
2878.11	220.208
2880.74	227.051
2883.37	233.537
2886	240.377
2888.63	247.016
2891.25	253.427
2893.88	260.044
2896.5	266.027
2899.13	274.502
2901.75	284.189
2904.37	296.233
2906.99	308.696
2909.61	322.199
2912.23	336.874
2914.85	349.732
2917.46	360.603
2920.08	371.598
2922.7	380.581
2925.31	387.428
2927.92	391.114
2930.53	392.144
2933.15	389.921
2935.76	385.643
2938.37	379.377
2940.98	371.002
2943.58	360.919
2946.19	348.683
2948.8	336.6
2951.4	322.318
2954.01	307.173
2956.61	292.386
2959.21	278.362
2961.81	263.613
2964.41	249.989
2967.01	237.802
2969.61	225.079
2972.21	212.718
2974.81	199.723
2977.4	187.026
2980	174.39
2982.59	162.31
2985.18	150.244
2987.78	137.053
2990.37	123.449
2992.96	110.575
2995.55	98.8767
2998.14	88.7197
3000.72	79.3463
3003.31	69.7152
3005.9	59.7764
3008.48	50.6747
3011.07	42.8239
3013.65	35.3768
3016.23	27.882
3018.81	21.7571
3021.39	17.348
3023.97	12.8074
3026.55	10.4026
3029.13	8.10625
3031.71	6.43624
3034.28	5.05324
3036.86	4.42886
3039.43	5.22736
3042.01	7.31545
3044.58	9.4539
3047.15	11.017
3049.72	12.9072
3052.29	15.1806
3054.86	16.5334
3057.43	17.4468
3060	19.7361
3062.56	20.3656
3065.13	20.208
3067.69	20.1384
3070.25	18.1964
3072.82	17.0832
3075.38	14.4779
3077.94	12.4449
3080.5	9.48181
3083.06	8.06129
3085.62	5.69111
3088.17	4.92466
3090.73	3.7618
3093.29	3.64549
3095.84	3.18738
3098.4	4.24391
3100.95	4.93725
3103.5	7.26751
3106.05	9.45008
3108.6	10.8763
3111.15	13.052
3113.7	15.6181
3116.25	18.6357
3118.79	21.5344
3121.34	24.5049
3123.88	28.8873
3126.43	30.769
3128.97	34.183
3131.51	36.43
3134.05	38.9348
3136.59	41.621
3139.14	43.4096
3141.67	45.8674
3144.21	48.3402
3146.75	51.0611
3149.28	52.2746