File: data/Raman/poly_smoothed/Mb_10_14_18_1x_45s_532 nm_x100_100%_600 gr_mm_01.txt
#Acq. time (s)=	45
#Accumulations=	2
#Range (cm-¹)=	200...3150
#Windows=	2
#Auto scanning=	Off
#Autofocus=	Off
#Macrospot=	Off
#AutoExposure=	Off
#Spike filter=	Multiple accum.
#Delay time (s)=	0
#Binning=	1
#Readout mode=	Signal
#DeNoise=	Off
#ICS correction=	On
#Dark correction=	Off
#Inst. Process=	Off
#Detector Gain=	Best Dynamic Range
#Detector ADC=	20 kHz
#Detector temperature (°C)=	-69.85
#Instrument=	LabRAM HR Evol
#Detector=	Synapse
#Objective=	x100
#Grating=	600 gr/mm
#ND Filter=	100%
#Laser (nm)=	532
#Hole=	100.021
#Range=	Auto
#Laser Pol.=	No
#Raman. Pol.=	No
#Laser Pol. (°)=	-0.0007625
#Raman Pol. (°)=	89.9995
#Collection=	Microscope
#StageXY=	Marzhauser
#StageZ=	Marzhauser
#X (µm)=	-628.8
#Y (µm)=	-1601.4
#Z (µm)=	89.25
#Full time(mm:ss)=	3:18
#Project=
#Sample=
#Site=
#Title=	Mb_10_14_18_2x_45s_532 nm_x100_100%_600 gr_mm
#Remark=
#Date=	11.07.2022 09:52
#Acquired=	11.07.2022 09:52:43
#Base:Fit=	10.08.2022 10:21:11
#Base:Sub=	10.08.2022 10:21:41
#Filter:Polynom=	16.08.2022 10:17:53
#AxisType[0]=Intens
#AxisUnit[0]=Cnt
#AxisType[1]=Spectr
#AxisUnit[1]=1/cm
200.388	-1.30393
204.019	0.577893
207.646	-0.0329829
211.274	0.657532
214.899	1.27294
218.524	1.55109
222.146	0.907833
225.766	1.20705
229.388	1.89017
233.005	4.18304
236.621	5.97003
240.236	7.20561
243.852	7.53718
247.464	8.87218
251.074	8.07615
254.683	11.4247
258.291	12.1786
261.897	12.6879
265.504	13.4379
269.108	13.1284
272.71	13.0197
276.311	14.4031
279.91	15.4729
283.508	15.8626
287.105	12.9206
290.698	13.5425
294.291	13.6547
297.884	13.8492
301.475	12.8758
305.064	12.0592
308.652	13.2909
312.237	14.0337
315.822	15.6404
319.406	17.8562
322.987	18.0113
326.568	17.1824
330.148	17.0845
333.724	16.2836
337.301	14.7081
340.875	14.7317
344.449	13.3621
348.02	11.0835
351.592	9.56674
355.16	8.50868
358.728	7.83824
362.294	7.00255
365.858	7.93871
369.422	7.47219
372.983	7.60692
376.543	8.74038
380.102	9.19904
383.661	10.0797
387.216	11.3116
390.771	13.2987
394.324	15.9838
397.875	17.5292
401.425	19.1753
404.974	20.3177
408.524	20.2979
412.07	20.3363
415.614	18.7444
419.156	17.6529
422.698	15.4873
426.238	13.4669
429.777	11.4519
433.315	10.9748
436.852	9.73034
440.387	10.1433
443.919	8.38022
447.451	7.78808
450.982	8.25474
454.512	10.2944
458.038	10.2231
461.565	11.8311
465.091	12.1509
468.613	12.1083
472.136	12.7932
475.655	13.1902
479.176	15.1361
482.692	16.4423
486.21	18.4446
489.724	17.6726
493.237	19.1138
496.75	20.3272
500.26	20.1668
503.769	19.2465
507.279	19.024
510.785	18.9373
514.289	17.8451
517.793	17.4658
521.297	17.3356
524.797	16.8144
528.297	16.5341
531.795	16.023
535.291	16.8232
538.787	17.5275
542.281	15.6091
545.773	14.8157
549.264	14.3148
552.754	13.3247
556.243	12.6483
559.73	12.2863
563.216	11.5178
566.701	11.0387
570.182	10.8164
573.664	9.567
577.145	9.31536
580.624	9.75402
584.1	6.01074
587.577	5.33934
591.052	4.60737
594.524	1.66124
597.997	1.89787
601.466	1.33928
604.936	1.92756
608.403	2.93871
611.87	5.48448
615.334	6.84516
618.799	8.38454
622.26	9.98736
625.72	10.5148
629.181	12.4153
632.638	14.24
636.095	18.6261
639.551	18.9378
643.005	19.8061
646.457	20.5778
649.908	22.3873
653.357	23.449
656.806	23.7496
660.253	23.6395
663.7	21.9586
667.145	20.1179
670.588	20.7805
674.027	20.0835
677.468	20.0332
680.907	20.3803
684.345	20.5158
687.781	21.6813
691.216	24.0435
694.65	27.0313
698.081	30.2444
701.512	31.6822
704.942	33.4201
708.371	34.4599
711.796	37.1066
715.222	38.0816
718.645	40.1425
722.068	40.8793
725.49	39.48
728.909	41.2122
732.329	42.0574
735.745	43.0252
739.16	44.8065
742.576	45.2448
745.988	46.1151
749.401	47.2912
752.811	49.6871
756.22	53.0046
759.627	54.5419
763.035	58.1063
766.44	59.5766
769.843	62.0605
773.245	66.5046
776.646	69.2942
780.046	72.0899
783.444	73.1449
786.841	76.3637
790.237	78.0267
793.631	77.9994
797.024	78.9254
800.416	77.4059
803.807	77.1619
807.196	76.5628
810.584	77.1248
813.971	77.7531
817.354	78.5518
820.739	78.703
824.122	78.7356
827.503	80.2185
830.882	81.7577
834.261	81.8306
837.637	80.4584
841.013	78.8478
844.389	73.9321
847.761	73.1373
851.131	70.7597
854.503	68.9343
857.871	65.4972
861.24	63.8463
864.606	61.9396
867.97	60.4698
871.336	58.3589
874.698	56.189
878.058	54.6482
881.418	53.2279
884.778	51.9799
888.135	51.4251
891.49	53.9706
894.845	54.248
898.198	54.0907
901.55	55.6162
904.901	57.7318
908.25	56.7323
911.598	57.0552
914.945	55.6702
918.291	53.4418
921.635	51.5846
924.978	48.9606
928.318	47.2529
931.659	46.6999
934.998	42.7081
938.336	40.4916
941.671	39.0993
945.007	36.5329
948.339	35.7072
951.672	33.4699
955.004	30.6421
958.333	28.5287
961.662	27.601
964.989	28.5878
968.315	30.1031
971.639	31.9048
974.962	32.5313
978.285	33.5465
981.605	34.9652
984.924	33.8841
988.243	33.6808
991.56	32.0603
994.875	32.456
998.188	31.4012
1001.5	30.7617
1004.81	31.0206
1008.12	32.0033
1011.43	30.2994
1014.74	30.0413
1018.05	28.4739
1021.35	28.0709
1024.65	26.318
1027.96	24.1743
1031.26	21.8987
1034.56	19.3348
1037.86	19.5684
1041.16	19.6469
1044.45	20.0076
1047.75	20.1099
1051.04	20.0579
1054.33	20.0065
1057.62	19.3944
1060.91	20.0086
1064.2	18.7827
1067.49	16.1478
1070.77	16.9891
1074.06	15.3969
1077.34	16.449
1080.62	15.6163
1083.91	17.3341
1087.18	19.2582
1090.46	18.0313
1093.74	17.4337
1097.02	17.9524
1100.29	15.8642
1103.56	15.7117
1106.84	14.9307
1110.11	14.3041
1113.38	13.1542
1116.64	12.1865
1119.91	11.9643
1123.18	12.0033
1126.44	10.3442
1129.7	9.34167
1132.97	7.81403
1136.23	7.89367
1139.49	6.98512
1142.74	5.78502
1146	4.38157
1149.26	4.63418
1152.51	5.13841
1155.76	4.76066
1159.01	5.37716
1162.27	4.566
1165.51	5.92685
1168.76	4.78049
1172.01	3.09541
1175.25	3.84231
1178.5	4.13396
1181.74	5.45342
1184.98	4.36816
1188.22	3.64491
1191.46	3.56314
1194.7	2.68665
1197.94	2.98778
1201.17	3.44096
1204.41	3.93293
1207.64	4.98726
1210.87	6.97193
1214.1	9.39385
1217.33	12.7658
1220.56	15.2214
1223.79	19.2603
1227.01	22.5459
1230.23	24.4456
1233.46	27.2415
1236.68	31.4289
1239.9	33.9575
1243.12	34.2183
1246.34	36.5695
1249.55	36.2285
1252.77	37.5941
1255.98	39.3581
1259.2	39.3228
1262.41	40.3079
1265.62	41.646
1268.83	40.7148
1272.03	42.5681
1275.24	44.1055
1278.45	45.8616
1281.65	48.0289
1284.85	49.9678
1288.06	53.5515
1291.26	55.5688
1294.46	57.9671
1297.66	61.4685
1300.85	63.1956
1304.05	66.1246
1307.24	67.9987
1310.43	70.1291
1313.63	72.8435
1316.82	74.2074
1320.01	73.1876
1323.2	72.6963
1326.38	72.5877
1329.57	71.5351
1332.76	71.6711
1335.94	70.8868
1339.12	68.7264
1342.3	66.7701
1345.48	63.1423
1348.66	61.5283
1351.84	60.8925
1355.01	58.1164
1358.19	55.5709
1361.36	53.2898
1364.53	52.3206
1367.71	49.187
1370.88	45.3804
1374.04	44.4379
1377.21	43.1753
1380.38	40.3978
1383.54	40.8519
1386.71	37.8168
1389.87	37.3444
1393.03	35.6709
1396.19	34.376
1399.35	33.713
1402.51	33.1926
1405.67	34.241
1408.82	36.7592
1411.98	37.6108
1415.13	40.0152
1418.28	41.6164
1421.43	44.6668
1424.58	49.7154
1427.73	55.9554
1430.88	61.793
1434.02	66.3883
1437.17	70.5801
1440.31	74.79
1443.45	77.0589
1446.6	79.3232
1449.74	78.9558
1452.87	78.1531
1456.01	76.8928
1459.15	75.0548
1462.28	72.369
1465.42	67.8228
1468.55	63.1646
1471.68	59.0011
1474.81	54.8993
1477.94	50.7808
1481.07	46.9502
1484.2	43.0162
1487.32	38.7757
1490.45	37.3834
1493.57	33.5284
1496.69	30.3758
1499.81	28.7493
1502.93	27.8023
1506.05	27.4084
1509.17	27.2704
1512.28	26.9573
1515.4	26.0443
1518.51	25.5737
1521.63	23.7192
1524.74	22.4976
1527.85	22.9497
1530.96	22.7039
1534.06	22.1164
1537.17	22.6026
1540.28	22.38
1543.38	23.1689
1546.48	25.1039
1549.59	25.1872
1552.69	25.0215
1555.79	26.6601
1558.88	28.7182
1561.98	30.8217
1565.08	31.812
1568.17	32.5898
1571.27	32.5106
1574.36	34.0266
1577.45	37.5971
1580.54	41.2971
1583.63	44.5239
1586.72	46.6788
1589.8	49.571
1592.89	51.745
1595.97	53.9866
1599.06	54.6943
1602.14	55.2207
1605.22	54.8679
1608.3	54.8516
1611.38	55.3855
1614.46	56.0962
1617.53	54.1323
1620.61	53.5131
1623.68	53.4724
1626.75	54.2349
1629.82	56.3037
1632.9	59.0031
1635.96	60.3787
1639.03	60.9046
1642.1	61.892
1645.16	64.5146
1648.23	66.7875
1651.29	68.7094
1654.36	70.6368
1657.42	72.5163
1660.48	71.7461
1663.53	71.8062
1666.59	70.1344
1669.65	66.7048
1672.7	64.1033
1675.76	61.6877
1678.81	57.5339
1681.86	53.73
1684.91	49.5933
1687.96	44.1017
1691.01	37.3252
1694.06	32.6706
1697.11	26.2032
1700.15	23.8259
1703.2	20.3098
1706.24	17.9785
1709.28	13.6925
1712.32	10.5658
1715.36	8.41539
1718.4	6.86737
1721.43	4.52758
1724.47	4.01948
1727.5	2.21485
1730.54	1.94084
1733.57	1.85315
1736.6	1.68413
1739.63	2.10092
1742.66	1.67176
1745.69	2.88837
1748.72	4.27335
1751.74	3.68767
1754.77	4.24056
1757.79	4.1784
1760.81	4.35831
1763.83	3.69891
1766.85	2.97952
1769.87	2.36441
1772.89	4.43333
1775.91	5.05081
1778.92	3.69968
1781.94	3.47838
1784.95	2.57265
1787.96	3.33396
1790.97	2.65682
1793.98	2.52221
1796.99	2.98459
1800	3.06911
1803	1.92691
1806.01	2.24894
1809.01	2.60211
1812.02	1.79441
1815.02	1.50621
1818.02	1.41325
1821.02	0.744494
1824.02	1.31501
1827.01	1.13279
1830.01	2.0634
1833	3.00476
1836	3.3212
1838.99	3.62994
1841.98	4.20975
1844.97	6.22024
1847.96	6.4491
1850.95	5.51457
1853.94	5.30984
1856.92	6.06242
1859.91	6.22173
1862.89	6.68616
1865.88	5.96325
1868.86	6.53794
1871.84	6.50619
1874.82	7.21168
1877.8	6.97782
1880.77	6.95309
1882.52	5.82624
1885.51	4.52103
1888.5	3.2293
1891.49	3.75561
1894.47	3.22107
1897.46	3.90265
1900.44	3.88059
1903.42	3.75069
1906.4	3.15378
1909.38	3.38847
1912.36	4.08316
1915.34	3.8125
1918.32	3.23066
1921.29	2.28624
1924.27	2.71993
1927.24	3.386
1930.21	2.38555
1933.18	3.04194
1936.15	3.10736
1939.12	2.59788
1942.09	3.04243
1945.06	4.19872
1948.02	3.41554
1950.99	2.62046
1953.95	1.52595
1956.91	0.120051
1959.87	0.88676
1962.84	0.725577
1965.79	1.30358
1968.75	1.80352
1971.71	1.77183
1974.66	1.97826
1977.62	1.86597
1980.57	2.46614
1983.53	1.21121
1986.48	2.60045
1989.43	2.14778
1992.38	2.28474
1995.33	2.02629
1998.27	2.76348
2001.22	1.7376
2004.16	1.79763
2007.11	1.46587
2010.05	1.61596
2012.99	1.01725
2015.93	1.52549
2018.87	2.00366
2021.81	3.34175
2024.75	4.76014
2027.69	4.35401
2030.62	4.92736
2033.56	6.66399
2036.49	7.27621
2039.42	8.29099
2042.35	8.60145
2045.28	10.1081
2048.21	10.7136
2051.14	10.1576
2054.06	9.62618
2056.99	10.2959
2059.92	9.11818
2062.84	8.78094
2065.76	8.59509
2068.68	8.51666
2071.6	7.77887
2074.52	6.74593
2077.44	6.06658
2080.36	6.0766
2083.27	7.60279
2086.19	8.59875
2089.1	10.1913
2092.01	12.0014
2094.93	13.4603
2097.84	14.1466
2100.75	14.0785
2103.66	14.827
2106.56	16.0792
2109.47	17.168
2112.37	18.2088
2115.28	19.2661
2118.18	19.3993
2121.09	19.5922
2123.99	19.5142
2126.89	19.2588
2129.79	19.6502
2132.68	20.8091
2135.58	21.9729
2138.48	21.8387
2141.37	24.1638
2144.26	25.2897
2147.16	26.6781
2150.05	28.6682
2152.94	30.4295
2155.83	32.0082
2158.72	33.1557
2161.6	34.5001
2164.49	35.9571
2167.38	37.9142
2170.26	38.7008
2173.14	38.8949
2176.03	39.3981
2178.91	39.2606
2181.79	39.747
2184.67	38.2964
2187.54	37.4191
2190.42	37.5575
2193.3	36.4758
2196.17	34.539
2199.05	34.807
2201.92	34.888
2204.79	33.5989
2207.66	32.9753
2210.53	31.7655
2213.4	29.6376
2216.27	27.3626
2219.13	26.5678
2222	25.8208
2224.86	23.8191
2227.72	23.0915
2230.59	21.5673
2233.45	22.1572
2236.31	21.5191
2239.17	20.6343
2242.03	19.8576
2244.88	18.3161
2247.74	16.3209
2250.59	13.9711
2253.45	13.8289
2256.3	12.8337
2259.15	12.5802
2262	12.9303
2264.85	12.2752
2267.7	12.3695
2270.55	12.6009
2273.4	12.632
2276.24	11.9863
2279.09	11.0869
2281.93	10.2185
2284.77	9.9924
2287.61	11.0428
2290.46	11.7863
2293.29	10.4162
2296.13	11.8702
2298.97	12.8679
2301.81	13.2059
2304.64	13.827
2307.48	14.2014
2310.31	15.0173
2313.14	14.4458
2315.97	13.6904
2318.8	13.485
2321.63	14.1097
2324.46	14.8102
2327.29	14.315
2330.12	14.183
2332.94	13.7887
2335.76	12.4552
2338.59	11.7887
2341.41	12.0204
2344.23	11.5453
2347.05	10.369
2349.87	9.52376
2352.69	9.87662
2355.5	8.64942
2358.32	8.23701
2361.14	7.20632
2363.95	6.66224
2366.76	7.57494
2369.58	5.3403
2372.39	4.19584
2375.2	3.07755
2378	2.2221
2380.81	1.12579
2383.62	0.607125
2386.42	1.69205
2389.23	2.42729
2392.03	3.29028
2394.84	3.16968
2397.64	3.67184
2400.44	4.3788
2403.24	5.26822
2406.04	6.29038
2408.83	7.43874
2411.63	8.55766
2414.43	10.0097
2417.22	11.1959
2420.02	12.6295
2422.81	13.8327
2425.6	14.2758
2428.39	14.47
2431.18	15.6234
2433.97	14.646
2436.76	14.2599
2439.54	13.1386
2442.33	12.0199
2445.11	11.1899
2447.9	11.1012
2450.68	11.0718
2453.46	11.8365
2456.24	12.4351
2459.02	10.4832
2461.8	10.4538
2464.58	10.619
2467.36	10.5786
2470.13	10.6944
2472.91	9.76795
2475.68	10.1441
2478.45	8.41956
2481.22	8.95992
2484	8.71966
2486.77	8.11927
2489.54	8.1254
2492.3	8.10704
2495.07	7.64779
2497.84	7.69239
2500.6	7.91049
2503.36	8.10174
2506.13	8.07461
2508.89	9.50284
2511.65	8.35784
2514.41	8.30707
2517.17	8.77568
2519.93	9.49641
2522.68	10.502
2525.44	10.6061
2528.19	10.7785
2530.95	12.4639
2533.7	13.4144
2536.45	13.3241
2539.2	13.3541
2541.95	12.5819
2544.7	13.0122
2547.45	12.5884
2550.2	12.3014
2552.94	11.9908
2555.69	12.1576
2558.43	13.3551
2561.17	12.6472
2563.92	11.4624
2566.66	12.882
2569.4	15.2505
2572.14	16.2353
2574.88	16.3541
2577.61	16.1025
2580.35	14.6898
2583.09	15.7275
2585.82	15.9648
2588.55	16.5564
2591.28	16.8355
2594.02	17.4579
2596.75	16.9223
2599.48	15.5818
2602.2	13.6758
2604.93	12.5993
2607.66	11.9702
2610.38	10.9649
2613.11	8.97522
2615.83	9.12325
2618.56	7.77005
2621.28	8.03565
2624	7.29567
2626.72	7.3528
2629.44	7.60612
2632.15	8.67466
2634.87	9.37236
2637.59	9.36076
2640.3	8.60636
2643.02	8.92019
2645.73	8.81177
2648.44	8.75896
2651.15	9.25991
2653.86	9.9952
2656.57	10.6297
2659.28	10.7859
2661.99	10.4374
2664.69	9.44652
2667.4	9.31412
2670.1	8.60818
2672.81	8.71242
2675.51	8.21666
2678.21	9.09657
2680.91	9.70691
2683.61	10.2781
2686.31	10.4709
2689	10.9825
2691.7	11.7992
2694.4	12.6866
2697.09	13.4238
2699.79	14.1934
2702.48	15.2495
2705.17	16.8089
2707.86	17.7758
2710.55	19.0811
2713.24	17.9561
2715.93	18.4998
2718.61	19.2826
2721.3	18.9795
2723.99	18.3041
2726.67	18.2009
2729.35	17.3898
2732.04	16.2641
2734.72	15.6766
2737.4	13.8966
2740.08	14.2833
2742.76	13.6183
2745.43	12.5902
2748.11	10.8459
2750.79	9.95792
2753.46	9.00625
2756.13	7.70425
2758.81	7.91581
2761.48	7.44656
2764.15	7.48866
2766.82	7.8851
2769.49	6.65198
2772.16	6.51913
2774.82	6.09639
2777.49	4.01516
2780.16	3.01276
2782.82	2.44643
2785.48	1.51323
2788.15	1.38521
2790.81	0.59467
2793.47	1.261
2796.13	1.58916
2798.79	1.88414
2801.44	1.48871
2804.1	2.16974
2806.76	0.877904
2809.41	0.367912
2812.07	-0.0583088
2814.72	0.931259
2817.37	2.04427
2820.02	5.22187
2822.67	8.50142
2825.32	12.3216
2827.97	15.4625
2830.62	20.6216
2833.26	24.4619
2835.91	29.2751
2838.55	34.8075
2841.2	41.1801
2843.84	49.3847
2846.48	59.3887
2849.12	69.662
2851.76	81.5504
2854.4	92.9896
2857.04	103.636
2859.68	113.078
2862.32	122.789
2864.95	131.179
2867.58	139.592
2870.22	145.974
2872.85	153.4
2875.48	158.276
2878.11	163.966
2880.74	170.256
2883.37	174.268
2886	178.027
2888.63	181.132
2891.25	184.089
2893.88	187.584
2896.5	192.014
2899.13	196.714
2901.75	203.432
2904.37	211.43
2906.99	220.693
2909.61	232.68
2912.23	243.835
2914.85	255.617
2917.46	266.411
2920.08	274.014
2922.7	280.487
2925.31	285.308
2927.92	289.433
2930.53	291.192
2933.15	290.986
2935.76	287.687
2938.37	283.996
2940.98	276.721
2943.58	269.163
2946.19	259.291
2948.8	249.174
2951.4	238.96
2954.01	227.338
2956.61	215.833
2959.21	205.145
2961.81	193.197
2964.41	182.072
2967.01	170.622
2969.61	160.107
2972.21	151.341
2974.81	142.245
2977.4	133.225
2980	123.822
2982.59	113.371
2985.18	102.499
2987.78	91.8416
2990.37	82.2177
2992.96	71.9257
2995.55	62.6069
2998.14	54.0444
3000.72	46.116
3003.31	37.5801
3005.9	31.0548
3008.48	25.8493
3011.07	21.2426
3013.65	17.7136
3016.23	13.8185
3018.81	9.89046
3021.39	8.08763
3023.97	5.18804
3026.55	2.72819
3029.13	0.905982
3031.71	0.17801
3034.28	-0.0937092
3036.86	1.42782
3039.43	1.99556
3042.01	3.72555
3044.58	4.4163
3047.15	4.96266
3049.72	5.91159
3052.29	6.62908
3054.86	7.72581
3057.43	8.33641
3060	7.54665
3062.56	7.22106
3065.13	7.11874
3067.69	7.12214
3070.25	7.6596
3072.82	6.02089
3075.38	5.99331
3077.94	4.27629
3080.5	2.84737
3083.06	1.94723
3085.62	0.852796
3088.17	-0.344914
3090.73	-1.34713
3093.29	-1.4952
3095.84	-0.693812
3098.4	0.805975
3100.95	2.34245
3103.5	3.44765
3106.05	5.18718
3108.6	6.78578
3111.15	9.80033
3113.7	12.0426
3116.25	14.3431
3118.79	16.1943
3121.34	17.8997
3123.88	19.472
3126.43	21.604
3128.97	23.4103
3131.51	25.1095
3134.05	26.1389
3136.59	26.1081
3139.14	26.6418
3141.67	26.0475
3144.21	24.8682
3146.75	22.5422
3149.28	19.3457