File: data/Raman/poly_smoothed/Mb_10_14_27_1x_45s_532 nm_x100_100%_600 gr_mm_01.txt
#Acq. time (s)=	45
#Accumulations=	2
#Range (cm-¹)=	200...3150
#Windows=	2
#Auto scanning=	Off
#Autofocus=	Off
#Macrospot=	Off
#AutoExposure=	Off
#Spike filter=	Multiple accum.
#Delay time (s)=	0
#Binning=	1
#Readout mode=	Signal
#DeNoise=	Off
#ICS correction=	On
#Dark correction=	Off
#Inst. Process=	Off
#Detector Gain=	Best Dynamic Range
#Detector ADC=	20 kHz
#Detector temperature (°C)=	-69.85
#Instrument=	LabRAM HR Evol
#Detector=	Synapse
#Objective=	x100
#Grating=	600 gr/mm
#ND Filter=	100%
#Laser (nm)=	532
#Hole=	100.021
#Range=	Auto
#Laser Pol.=	No
#Raman. Pol.=	No
#Laser Pol. (°)=	-0.0007625
#Raman Pol. (°)=	89.9995
#Collection=	Microscope
#StageXY=	Marzhauser
#StageZ=	Marzhauser
#X (µm)=	-615.6
#Y (µm)=	-1594.6
#Z (µm)=	89.85
#Full time(mm:ss)=	3:19
#Project=
#Sample=
#Site=
#Title=	Mb_10_14_27_2x_45s_532 nm_x100_100%_600 gr_mm
#Remark=
#Date=	11.07.2022 10:33
#Acquired=	11.07.2022 10:33:14
#Base:Fit=	10.08.2022 10:21:11
#Base:Sub=	10.08.2022 10:21:41
#Filter:Polynom=	16.08.2022 10:17:53
#AxisType[0]=Intens
#AxisUnit[0]=Cnt
#AxisType[1]=Spectr
#AxisUnit[1]=1/cm
200.388	6.7222
204.019	7.2194
207.646	4.86536
211.274	2.57657
214.899	0.786519
218.524	0.757991
222.146	0.945535
225.766	3.57271
229.388	4.6108
233.005	6.18802
236.621	7.53731
240.236	8.75186
243.852	9.4092
247.464	12.1857
251.074	14.91
254.683	15.9922
258.291	16.6639
261.897	17.5495
265.504	18.1259
269.108	16.0265
272.71	15.1518
276.311	15.2722
279.91	14.2175
283.508	13.1823
287.105	12.0696
290.698	10.0089
294.291	10.7145
297.884	11.1587
301.475	12.2745
305.064	14.0151
308.652	15.5
312.237	16.4414
315.822	17.9194
319.406	17.0298
322.987	18.6399
326.568	19.224
330.148	20.0022
333.724	20.5634
337.301	20.8806
340.875	21.4771
344.449	20.3394
348.02	20.5133
351.592	21.6008
355.16	20.227
358.728	19.4018
362.294	19.5285
365.858	19.3126
369.422	19.6974
372.983	21.247
376.543	20.4815
380.102	20.8735
383.661	21.1115
387.216	21.4419
390.771	22.3337
394.324	20.5147
397.875	19.3033
401.425	17.9027
404.974	17.7007
408.524	17.2923
412.07	16.3027
415.614	15.3659
419.156	15.5679
422.698	14.4158
426.238	16.3117
429.777	16.0349
433.315	14.3146
436.852	13.5238
440.387	13.0659
443.919	11.029
447.451	11.7983
450.982	10.9192
454.512	12.2206
458.038	11.7138
461.565	10.1424
465.091	9.32543
468.613	10.2222
472.136	10.9764
475.655	11.7637
479.176	12.3939
482.692	12.9004
486.21	13.6524
489.724	13.0767
493.237	12.6937
496.75	14.0441
500.26	15.7675
503.769	15.7818
507.279	14.8116
510.785	14.6034
514.289	14.1021
517.793	11.5446
521.297	10.6109
524.797	8.82327
528.297	8.30718
531.795	8.4827
535.291	8.93752
538.787	7.09571
542.281	6.85426
545.773	7.10441
549.264	6.68992
552.754	6.99937
556.243	6.998
559.73	7.90664
563.216	7.99086
566.701	5.72209
570.182	4.74381
573.664	3.16435
577.145	3.14611
580.624	4.67944
584.1	5.12657
587.577	3.63427
591.052	2.56399
594.524	2.39111
597.997	2.21824
601.466	2.73365
604.936	1.6098
608.403	1.35687
611.87	2.11746
615.334	5.23406
618.799	6.61903
622.26	6.34164
625.72	7.78238
629.181	9.57327
632.638	11.0985
636.095	12.1471
639.551	12.9705
643.005	14.5607
646.457	15.9863
649.908	15.8705
653.357	16.0418
656.806	16.8655
660.253	17.3137
663.7	18.2969
667.145	19.3999
670.588	19.0302
674.027	18.9809
677.468	19.3193
680.907	19.8356
684.345	19.351
687.781	19.6552
691.216	19.8142
694.65	20.1378
698.081	21.3758
701.512	21.7287
704.942	21.6311
708.371	21.4901
711.796	22.3018
715.222	22.8046
718.645	24.0572
722.068	25.6485
725.49	26.5477
728.909	27.5938
732.329	28.3841
735.745	29.2519
739.16	30.5358
742.576	32.4375
745.988	35.0801
749.401	39.2554
752.811	42.3762
756.22	44.1021
759.627	47.3171
763.035	51.524
766.44	55.1631
769.843	58.5529
773.245	61.9952
776.646	64.8169
780.046	67.3236
783.444	69.163
786.841	69.7057
790.237	71.7853
793.631	72.9836
797.024	74.9538
800.416	76.3342
803.807	75.9779
807.196	77.1795
810.584	76.6701
813.971	77.4274
817.354	76.5799
820.739	76.2745
824.122	75.4144
827.503	75.1817
830.882	73.8573
834.261	72.9928
837.637	72.2917
841.013	70.6985
844.389	69.0537
847.761	66.2695
851.131	63.5171
854.503	61.4283
857.871	59.1754
861.24	57.5082
864.606	55.3894
867.97	53.1301
871.336	51.2589
874.698	50.1769
878.058	49.2427
881.418	48.445
884.778	47.0358
888.135	47.7051
891.49	47.4766
894.845	46.0117
898.198	45.6974
901.55	44.7642
904.901	43.6884
908.25	44.4031
911.598	45.0817
914.945	45.6241
918.291	45.2585
921.635	45.3817
924.978	44.5903
928.318	44.1639
931.659	43.7529
934.998	44.8648
938.336	44.3857
941.671	44.0487
945.007	41.7146
948.339	40.743
951.672	39.0345
955.004	37.0116
958.333	36.8013
961.662	36.1501
964.989	38.8232
968.315	39.354
971.639	40.5587
974.962	40.028
978.285	40.5748
981.605	41.3013
984.924	42.1243
988.243	43.2305
991.56	43.1453
994.875	41.4485
998.188	40.8107
1001.5	40.9795
1004.81	40.8053
1008.12	40.8722
1011.43	39.7667
1014.74	40.3772
1018.05	40.5644
1021.35	38.9117
1024.65	35.6686
1027.96	33.1421
1031.26	31.2533
1034.56	28.5063
1037.86	27.7653
1041.16	28.4525
1044.45	29.1388
1047.75	29.2627
1051.04	27.1296
1054.33	23.2372
1057.62	21.5619
1060.91	19.7557
1064.2	16.7996
1067.49	14.718
1070.77	12.2168
1074.06	10.696
1077.34	9.27131
1080.62	9.7649
1083.91	9.87778
1087.18	10.147
1090.46	10.1409
1093.74	10.3648
1097.02	11.1283
1100.29	10.7828
1103.56	9.62254
1106.84	8.39254
1110.11	9.16881
1113.38	8.70372
1116.64	8.137
1119.91	7.9991
1123.18	7.75171
1126.44	7.47425
1129.7	6.00338
1132.97	5.67306
1136.23	3.18523
1139.49	4.02708
1142.74	4.73012
1146	5.47881
1149.26	4.70259
1152.51	5.12079
1155.76	3.92435
1159.01	2.14187
1162.27	1.75745
1165.51	0.686759
1168.76	1.29267
1172.01	1.5011
1175.25	2.013
1178.5	2.10102
1181.74	2.04938
1184.98	2.378
1188.22	2.29568
1191.46	1.59447
1194.7	2.02858
1197.94	1.42642
1201.17	2.4636
1204.41	4.6149
1207.64	6.77686
1210.87	9.05434
1214.1	10.0741
1217.33	12.3071
1220.56	16.4204
1223.79	18.6202
1227.01	19.3214
1230.23	21.5962
1233.46	22.7423
1236.68	25.1649
1239.9	26.8233
1243.12	29.4447
1246.34	31.7723
1249.55	34.3753
1252.77	37.0236
1255.98	38.799
1259.2	37.4951
1262.41	37.2532
1265.62	37.1331
1268.83	36.9477
1272.03	37.8151
1275.24	38.0408
1278.45	38.4109
1281.65	39.3285
1284.85	40.4624
1288.06	40.6702
1291.26	40.9584
1294.46	42.4787
1297.66	42.187
1300.85	44.0838
1304.05	43.2911
1307.24	44.9891
1310.43	44.8439
1313.63	45.196
1316.82	46.5939
1320.01	46.3122
1323.2	45.969
1326.38	46.4845
1329.57	45.1132
1332.76	44.6882
1335.94	41.8237
1339.12	39.6096
1342.3	37.7978
1345.48	37.334
1348.66	35.6555
1351.84	35.2268
1355.01	35.3204
1358.19	34.7661
1361.36	33.2077
1364.53	31.1433
1367.71	29.7766
1370.88	29.8819
1374.04	28.68
1377.21	29.2342
1380.38	28.173
1383.54	27.467
1386.71	26.1441
1389.87	25.6211
1393.03	25.8783
1396.19	24.0174
1399.35	22.4869
1402.51	22.5597
1405.67	22.5184
1408.82	23.0627
1411.98	23.3775
1415.13	25.4945
1418.28	26.9572
1421.43	29.4226
1424.58	34.2645
1427.73	39.0023
1430.88	44.4704
1434.02	48.0672
1437.17	51.0424
1440.31	52.4021
1443.45	54.8413
1446.6	56.45
1449.74	58.5636
1452.87	58.2578
1456.01	57.688
1459.15	57.1297
1462.28	54.058
1465.42	52.4617
1468.55	49.4205
1471.68	45.8239
1474.81	41.5549
1477.94	37.9256
1481.07	34.3902
1484.2	31.7642
1487.32	27.9735
1490.45	25.1436
1493.57	23.5986
1496.69	21.5473
1499.81	21.6039
1502.93	20.1165
1506.05	19.6111
1509.17	18.7587
1512.28	16.6411
1515.4	14.6609
1518.51	14.9227
1521.63	13.5512
1524.74	14.3616
1527.85	13.904
1530.96	13.9112
1534.06	15.0327
1537.17	15.8454
1540.28	14.7223
1543.38	15.4157
1546.48	16.3435
1549.59	16.5149
1552.69	16.8274
1555.79	17.9596
1558.88	18.7036
1561.98	20.2194
1565.08	22.508
1568.17	24.5551
1571.27	26.5873
1574.36	27.2309
1577.45	29.1899
1580.54	30.419
1583.63	31.5853
1586.72	33.1233
1589.8	33.1244
1592.89	34.1013
1595.97	36.0773
1599.06	36.3282
1602.14	36.574
1605.22	36.4126
1608.3	36.9781
1611.38	36.9884
1614.46	36.9949
1617.53	38.2102
1620.61	39.4661
1623.68	41.4415
1626.75	42.0088
1629.82	44.2298
1632.9	46.6494
1635.96	49.6491
1639.03	53.326
1642.1	54.6077
1645.16	56.1658
1648.23	57.3162
1651.29	58.6219
1654.36	59.5651
1657.42	59.5615
1660.48	57.2975
1663.53	55.6017
1666.59	54.3268
1669.65	52.8259
1672.7	51.4658
1675.76	47.9919
1678.81	44.0936
1681.86	39.6358
1684.91	35.9504
1687.96	32.684
1691.01	29.3652
1694.06	25.5381
1697.11	21.9716
1700.15	18.1608
1703.2	15.6835
1706.24	13.6672
1709.28	11.45
1712.32	8.04405
1715.36	5.07524
1718.4	3.42481
1721.43	2.39337
1724.47	1.04053
1727.5	0.567731
1730.54	0.623152
1733.57	-0.0897335
1736.6	0.776956
1739.63	1.55145
1742.66	2.89211
1745.69	4.16016
1748.72	4.73083
1751.74	4.34469
1754.77	3.71513
1757.79	3.80694
1760.81	4.20776
1763.83	4.49752
1766.85	3.91864
1769.87	3.97313
1772.89	4.19351
1775.91	4.15556
1778.92	4.18935
1781.94	3.07477
1784.95	1.93259
1787.96	2.19627
1790.97	1.53285
1793.98	1.53531
1796.99	1.65437
1800	1.60081
1803	1.24825
1806.01	1.39695
1809.01	1.40108
1812.02	1.55817
1815.02	1.5638
1818.02	2.40158
1821.02	3.79976
1824.02	3.25154
1827.01	3.37307
1830.01	2.71533
1833	4.13915
1836	4.2411
1838.99	4.56882
1841.98	5.75832
1844.97	6.50635
1847.96	6.00083
1850.95	5.99185
1853.94	4.94485
1856.92	4.73144
1859.91	4.57853
1862.89	2.94403
1865.88	1.98854
1868.86	2.08051
1871.84	0.417014
1874.82	-0.659642
1877.8	-0.499913
1880.77	-0.633796
1882.52	0.372495
1885.51	1.0622
1888.5	1.24332
1891.49	1.00353
1894.47	1.51001
1897.46	2.00189
1900.44	2.61716
1903.42	3.591
1906.4	5.16296
1909.38	6.19337
1912.36	7.0613
1915.34	7.87166
1918.32	8.19648
1921.29	7.33549
1924.27	8.2803
1927.24	7.62924
1930.21	8.37604
1933.18	8.53171
1936.15	8.96963
1939.12	8.521
1942.09	8.55517
1945.06	8.48628
1948.02	8.75547
1950.99	8.80044
1953.95	10.3136
1956.91	9.63456
1959.87	9.128
1962.84	7.85071
1965.79	7.42201
1968.75	7.81312
1971.71	7.81326
1974.66	8.00916
1977.62	8.46463
1980.57	9.05806
1983.53	9.91561
1986.48	9.97038
1989.43	10.3711
1992.38	10.1624
1995.33	10.9503
1998.27	11.5192
2001.22	11.7807
2004.16	12.376
2007.11	12.4655
2010.05	11.9087
2012.99	11.8224
2015.93	11.2087
2018.87	11.0503
2021.81	10.9435
2024.75	11.3225
2027.69	11.1535
2030.62	10.5872
2033.56	10.1675
2036.49	10.3696
2039.42	9.56033
2042.35	10.4199
2045.28	11.2332
2048.21	11.6619
2051.14	11.9886
2054.06	12.6936
2056.99	12.2304
2059.92	12.1678
2062.84	12.1025
2065.76	12.3905
2068.68	12.3554
2071.6	12.4303
2074.52	11.491
2077.44	11.3199
2080.36	11.0013
2083.27	10.6217
2086.19	10.4034
2089.1	9.42693
2092.01	9.73215
2094.93	9.65658
2097.84	8.91143
2100.75	9.62846
2103.66	9.54224
2106.56	9.96888
2109.47	11.1602
2112.37	12.1712
2115.28	14.0589
2118.18	15.5998
2121.09	17.0441
2123.99	19.1079
2126.89	20.6322
2129.79	22.3491
2132.68	24.4709
2135.58	26.9214
2138.48	29.8993
2141.37	30.0483
2144.26	30.4056
2147.16	31.115
2150.05	32.9546
2152.94	33.6745
2155.83	34.049
2158.72	34.3041
2161.6	34.0134
2164.49	33.9368
2167.38	33.6959
2170.26	33.7122
2173.14	34.5614
2176.03	33.3916
2178.91	31.9146
2181.79	30.9869
2184.67	30.0759
2187.54	30.1945
2190.42	29.3138
2193.3	28.2014
2196.17	27.2705
2199.05	26.8247
2201.92	26.4651
2204.79	26.9756
2207.66	26.3472
2210.53	25.0832
2213.4	23.7899
2216.27	22.9869
2219.13	22.4811
2222	21.8457
2224.86	21.4328
2227.72	20.3085
2230.59	20.4983
2233.45	19.7405
2236.31	18.053
2239.17	17.2463
2242.03	17.7552
2244.88	17.2855
2247.74	15.98
2250.59	14.6552
2253.45	13.8575
2256.3	14.06
2259.15	12.5899
2262	12.1037
2264.85	11.8133
2267.7	12.0898
2270.55	13.0781
2273.4	13.8064
2276.24	13.3881
2279.09	12.2653
2281.93	12.1976
2284.77	11.9185
2287.61	11.6887
2290.46	10.3974
2293.29	9.66438
2296.13	9.63807
2298.97	10.615
2301.81	12.2718
2304.64	14.0391
2307.48	14.5268
2310.31	15.5621
2313.14	16.3203
2315.97	16.3921
2318.8	16.057
2321.63	15.0866
2324.46	15.2381
2327.29	14.6822
2330.12	13.6616
2332.94	13.2344
2335.76	11.4144
2338.59	9.70709
2341.41	8.87017
2344.23	6.9747
2347.05	6.00881
2349.87	4.97486
2352.69	3.83489
2355.5	2.79545
2358.32	2.26267
2361.14	2.3529
2363.95	2.70769
2366.76	4.04419
2369.58	5.53481
2372.39	5.59443
2375.2	4.93537
2378	4.3661
2380.81	4.79808
2383.62	5.88517
2386.42	5.84718
2389.23	5.77194
2392.03	6.06754
2394.84	6.22363
2397.64	6.03072
2400.44	5.37358
2403.24	5.82617
2406.04	6.00425
2408.83	7.31637
2411.63	9.33569
2414.43	9.94309
2417.22	10.2599
2420.02	10.9743
2422.81	11.829
2425.6	13.952
2428.39	14.1843
2431.18	13.9052
2433.97	13.8979
2436.76	13.1427
2439.54	13.1646
2442.33	13.47
2445.11	13.463
2447.9	12.869
2450.68	12.2861
2453.46	10.1395
2456.24	9.15117
2459.02	8.4773
2461.8	7.86214
2464.58	6.88716
2467.36	6.78322
2470.13	6.67798
2472.91	5.46056
2475.68	5.78475
2478.45	6.20203
2481.22	5.94983
2484	5.13834
2486.77	4.96775
2489.54	5.0671
2492.3	5.65347
2495.07	5.76875
2497.84	5.64318
2500.6	6.01886
2503.36	5.30145
2506.13	6.24733
2508.89	6.22618
2511.65	5.72401
2514.41	4.81502
2517.17	3.62804
2519.93	3.50643
2522.68	3.16716
2525.44	3.45983
2528.19	3.40862
2530.95	3.46995
2533.7	4.14846
2536.45	3.12075
2539.2	2.69594
2541.95	3.44961
2544.7	4.43608
2547.45	4.63533
2550.2	4.97816
2552.94	4.59449
2555.69	4.89847
2558.43	4.63811
2561.17	5.26322
2563.92	6.06832
2566.66	5.20266
2569.4	4.41346
2572.14	4.00049
2574.88	5.09691
2577.61	4.46595
2580.35	3.36634
2583.09	3.50444
2585.82	4.15391
2588.55	4.01812
2591.28	3.82995
2594.02	4.39264
2596.75	4.33549
2599.48	4.23341
2602.2	4.34896
2604.93	4.43757
2607.66	5.36168
2610.38	5.83507
2613.11	5.58222
2615.83	4.72087
2618.56	4.38198
2621.28	3.39756
2624	1.9185
2626.72	1.66874
2629.44	1.04866
2632.15	0.216224
2634.87	-0.146606
2637.59	0.446888
2640.3	0.536738
2643.02	-0.86715
2645.73	-1.89519
2648.44	-2.24236
2651.15	-1.28927
2653.86	-0.57898
2656.57	-0.0932418
2659.28	0.888618
2661.99	1.43882
2664.69	1.61597
2667.4	2.45368
2670.1	3.32888
2672.81	5.05662
2675.51	5.1098
2678.21	5.87482
2680.91	5.73127
2683.61	5.01502
2686.31	4.83856
2689	5.43751
2691.7	5.96406
2694.4	6.44611
2697.09	7.64949
2699.79	8.77805
2702.48	10.188
2705.17	9.39929
2707.86	8.972
2710.55	9.22697
2713.24	10.2846
2715.93	10.8377
2718.61	11.4051
2721.3	11.7304
2723.99	11.3115
2726.67	11.1542
2729.35	10.5357
2732.04	9.92263
2734.72	10.1602
2737.4	8.97491
2740.08	8.07392
2742.76	7.69021
2745.43	6.91274
2748.11	5.79345
2750.79	5.19997
2753.46	5.60132
2756.13	5.98336
2758.81	6.53221
2761.48	6.58434
2764.15	7.59023
2766.82	7.32607
2769.49	6.22984
2772.16	5.46469
2774.82	5.78852
2777.49	5.45521
2780.16	4.80265
2782.82	5.10463
2785.48	4.83432
2788.15	4.52494
2790.81	2.57613
2793.47	1.54633
2796.13	1.801
2798.79	0.716739
2801.44	0.831946
2804.1	1.16
2806.76	1.93435
2809.41	2.43683
2812.07	3.06486
2814.72	4.30172
2817.37	5.08685
2820.02	6.08127
2822.67	8.79399
2825.32	11.3403
2827.97	15.2524
2830.62	17.7382
2833.26	20.6826
2835.91	23.7216
2838.55	28.62
2841.2	34.0008
2843.84	40.2581
2846.48	48.3391
2849.12	56.4565
2851.76	64.4877
2854.4	72.6662
2857.04	80.7327
2859.68	89.3325
2862.32	98.0556
2864.95	105.602
2867.58	113.494
2870.22	120.131
2872.85	126.106
2875.48	131.136
2878.11	135.961
2880.74	140.103
2883.37	145.059
2886	148.816
2888.63	152.988
2891.25	155.837
2893.88	159.523
2896.5	163.027
2899.13	168.393
2901.75	174.96
2904.37	182.524
2906.99	192.58
2909.61	202.787
2912.23	213.013
2914.85	222.928
2917.46	232.488
2920.08	241.094
2922.7	247.968
2925.31	253.797
2927.92	257.173
2930.53	257.529
2933.15	257.13
2935.76	255.321
2938.37	251.771
2940.98	245.807
2943.58	238.459
2946.19	230.519
2948.8	220.14
2951.4	210.089
2954.01	199.346
2956.61	188.508
2959.21	177.652
2961.81	168.348
2964.41	159.423
2967.01	151.123
2969.61	143.62
2972.21	135.824
2974.81	128.122
2977.4	121.307
2980	114.215
2982.59	105.588
2985.18	98.2002
2987.78	90.1568
2990.37	80.8899
2992.96	72.6628
2995.55	64.6602
2998.14	58.3447
3000.72	51.6056
3003.31	44.5157
3005.9	37.6346
3008.48	30.6332
3011.07	24.6877
3013.65	20.4933
3016.23	16.7376
3018.81	12.6066
3021.39	10.3107
3023.97	7.70994
3026.55	6.80054
3029.13	6.83051
3031.71	5.87004
3034.28	4.79246
3036.86	5.64112
3039.43	6.65243
3042.01	8.10693
3044.58	9.13656
3047.15	10.4128
3049.72	10.7527
3052.29	12.2443
3054.86	13.0547
3057.43	13.5256
3060	14.332
3062.56	14.0897
3065.13	12.9527
3067.69	13.0279
3070.25	11.6184
3072.82	10.0749
3075.38	9.4886
3077.94	8.44417
3080.5	6.75604
3083.06	5.91508
3085.62	4.26821
3088.17	3.76883
3090.73	3.84128
3093.29	2.764
3095.84	2.68937
3098.4	2.26065
3100.95	2.10002
3103.5	2.11733
3106.05	2.26166
3108.6	3.29632
3111.15	3.99692
3113.7	4.91944
3116.25	5.18643
3118.79	6.21439
3121.34	7.09209
3123.88	7.3614
3126.43	8.94477
3128.97	10.4426
3131.51	11.6516
3134.05	12.0611
3136.59	12.6751
3139.14	13.9525
3141.67	15.1512
3144.21	15.8349
3146.75	16.7027
3149.28	16.8141