File: data/Raman/poly_smoothed/Mb_10_14_48_1x_45s_532 nm_x100_100%_600 gr_mm_01.txt
#Acq. time (s)=	45
#Accumulations=	2
#Range (cm-¹)=	200...3150
#Windows=	2
#Auto scanning=	Off
#Autofocus=	Off
#Macrospot=	Off
#AutoExposure=	Off
#Spike filter=	Multiple accum.
#Delay time (s)=	0
#Binning=	1
#Readout mode=	Signal
#DeNoise=	Off
#ICS correction=	On
#Dark correction=	Off
#Inst. Process=	Off
#Detector Gain=	Best Dynamic Range
#Detector ADC=	20 kHz
#Detector temperature (°C)=	-69.85
#Instrument=	LabRAM HR Evol
#Detector=	Synapse
#Objective=	x100
#Grating=	600 gr/mm
#ND Filter=	100%
#Laser (nm)=	532
#Hole=	100.021
#Range=	Auto
#Laser Pol.=	No
#Raman. Pol.=	No
#Laser Pol. (°)=	-0.0007625
#Raman Pol. (°)=	89.9995
#Collection=	Microscope
#StageXY=	Marzhauser
#StageZ=	Marzhauser
#X (µm)=	-638.6
#Y (µm)=	-1694.4
#Z (µm)=	88.9
#Full time(mm:ss)=	3:18
#Project=
#Sample=
#Site=
#Title=	Mb_10_14_48_2x_45s_532 nm_x100_100%_600 gr_mm
#Remark=
#Date=	11.07.2022 12:16
#Acquired=	11.07.2022 12:16:55
#Base:Fit=	10.08.2022 10:21:11
#Base:Sub=	10.08.2022 10:21:41
#Filter:Polynom=	16.08.2022 10:17:53
#AxisType[0]=Intens
#AxisUnit[0]=Cnt
#AxisType[1]=Spectr
#AxisUnit[1]=1/cm
200.388	16.4913
204.019	15.259
207.646	10.9654
211.274	7.05152
214.899	5.47558
218.524	6.88314
222.146	7.96017
225.766	10.7043
229.388	12.3783
233.005	16.1227
236.621	16.9615
240.236	20.0459
243.852	21.6347
247.464	24.4059
251.074	27.2218
254.683	29.2346
258.291	31.5151
261.897	34.9236
265.504	36.5511
269.108	37.7285
272.71	37.0815
276.311	38.4562
279.91	38.7598
283.508	37.0645
287.105	35.0821
290.698	34.7355
294.291	32.44
297.884	32.7278
301.475	31.9183
305.064	33.2023
308.652	32.965
312.237	31.7482
315.822	30.0328
319.406	28.3895
322.987	26.8098
326.568	25.6684
330.148	24.7594
333.724	23.6038
337.301	22.1041
340.875	21.9592
344.449	22.1128
348.02	22.7236
351.592	23.1214
355.16	25.1259
358.728	26.7355
362.294	29.2185
365.858	29.8535
369.422	30.6236
372.983	33.9106
376.543	35.4139
380.102	37.5853
383.661	37.7008
387.216	40.59
390.771	40.8223
394.324	41.5394
397.875	40.282
401.425	38.9181
404.974	37.7835
408.524	36.1005
412.07	33.9629
415.614	33.8404
419.156	32.9992
422.698	30.8892
426.238	29.0808
429.777	27.488
433.315	27.3034
436.852	25.4404
440.387	25.8545
443.919	23.8606
447.451	23.2965
450.982	23.2227
454.512	23.4994
458.038	25.9515
461.565	26.1791
465.091	26.1172
468.613	26.9444
472.136	25.3001
475.655	26.4815
479.176	25.5395
482.692	25.4268
486.21	25.3346
489.724	26.2371
493.237	25.9955
496.75	26.0408
500.26	27.6438
503.769	28.2789
507.279	27.1566
510.785	26.1215
514.289	25.7179
517.793	23.8214
521.297	23.2149
524.797	23.3599
528.297	23.5061
531.795	23.0638
535.291	21.577
538.787	20.3085
542.281	19.7464
545.773	18.3102
549.264	14.834
552.754	13.9484
556.243	11.2812
559.73	9.34158
563.216	7.40396
566.701	5.85509
570.182	6.23637
573.664	6.05454
577.145	5.71961
580.624	5.76281
584.1	6.82026
587.577	6.41762
591.052	5.91315
594.524	6.42247
597.997	5.49685
601.466	6.25334
604.936	7.1523
608.403	8.36986
611.87	7.75928
615.334	6.31763
618.799	6.13544
622.26	4.3116
625.72	4.86355
629.181	5.21208
632.638	5.26848
636.095	5.04177
639.551	5.49047
643.005	4.4373
646.457	4.57649
649.908	6.84289
653.357	7.76159
656.806	8.00547
660.253	10.2905
663.7	11.8285
667.145	12.1484
670.588	11.7728
674.027	12.4494
677.468	14.5869
680.907	15.6022
684.345	16.5781
687.781	18.353
691.216	18.974
694.65	19.4864
698.081	20.0575
701.512	21.2332
704.942	21.4045
708.371	22.2825
711.796	23.4235
715.222	25.2367
718.645	26.9953
722.068	27.2384
725.49	27.6013
728.909	27.9533
732.329	29.0934
735.745	29.6135
739.16	30.2064
742.576	31.7512
745.988	32.6909
749.401	33.9411
752.811	35.6977
756.22	37.4441
759.627	40.7664
763.035	42.2563
766.44	44.1362
769.843	47.3105
773.245	49.104
776.646	53.1607
780.046	56.0034
783.444	58.2369
786.841	59.4918
790.237	62.059
793.631	63.6761
797.024	64.453
800.416	65.8816
803.807	65.9102
807.196	65.5275
810.584	64.7542
813.971	64.6626
817.354	64.959
820.739	63.9346
824.122	63.9862
827.503	62.6637
830.882	61.6882
834.261	61.2977
837.637	59.5062
841.013	57.7391
844.389	56.6165
847.761	55.0005
851.131	54.0296
854.503	53.9415
857.871	53.1456
861.24	51.0756
864.606	48.9219
867.97	46.3924
871.336	43.1336
874.698	41.4065
878.058	38.9887
881.418	38.627
884.778	37.4173
888.135	36.7468
891.49	36.1538
894.845	36.8276
898.198	37.414
901.55	35.8558
904.901	35.6671
908.25	35.0381
911.598	36.3897
914.945	35.9803
918.291	37.2194
921.635	36.5646
924.978	37.7869
928.318	38.0188
931.659	39.2825
934.998	40.046
938.336	38.0075
941.671	35.4637
945.007	33.6986
948.339	31.6119
951.672	30.0203
955.004	29
958.333	28.0566
961.662	27.8848
964.989	27.7509
968.315	27.921
971.639	28.1772
974.962	28.0905
978.285	28.9021
981.605	28.2272
984.924	28.0882
988.243	28.6854
991.56	28.7009
994.875	28.8502
998.188	28.2863
1001.5	26.1457
1004.81	25.9911
1008.12	24.3934
1011.43	24.4889
1014.74	23.6904
1018.05	21.7322
1021.35	19.4189
1024.65	19.4148
1027.96	18.9798
1031.26	19.5259
1034.56	19.9455
1037.86	21.1545
1041.16	20.4863
1044.45	21.3387
1047.75	20.3374
1051.04	20.4252
1054.33	19.328
1057.62	19.7273
1060.91	18.9916
1064.2	16.1752
1067.49	16.4676
1070.77	14.5803
1074.06	11.4862
1077.34	10.17
1080.62	8.17832
1083.91	6.77347
1087.18	5.2976
1090.46	4.35712
1093.74	4.93898
1097.02	3.21727
1100.29	4.27132
1103.56	5.14432
1106.84	5.52003
1110.11	5.6161
1113.38	6.30972
1116.64	7.29659
1119.91	6.55753
1123.18	4.93164
1126.44	5.49049
1129.7	5.92236
1132.97	6.03624
1136.23	6.37494
1139.49	5.19791
1142.74	4.6123
1146	3.5093
1149.26	3.00089
1152.51	3.53732
1155.76	4.17308
1159.01	3.67092
1162.27	3.42438
1165.51	3.27074
1168.76	3.09134
1172.01	2.15107
1175.25	3.43281
1178.5	4.08779
1181.74	5.37497
1184.98	4.84232
1188.22	5.82737
1191.46	6.77588
1194.7	7.15732
1197.94	6.88944
1201.17	6.56889
1204.41	9.62035
1207.64	10.1939
1210.87	11.534
1214.1	11.1009
1217.33	10.7357
1220.56	13.0374
1223.79	14.9128
1227.01	16.6717
1230.23	19.2118
1233.46	20.2143
1236.68	20.1569
1239.9	18.5871
1243.12	19.4454
1246.34	19.756
1249.55	19.3596
1252.77	20.3836
1255.98	20.4281
1259.2	19.5689
1262.41	18.6845
1265.62	17.4434
1268.83	16.9023
1272.03	18.0483
1275.24	18.7978
1278.45	20.3593
1281.65	22.3132
1284.85	24.4702
1288.06	24.5989
1291.26	26.4985
1294.46	27.2221
1297.66	30.3567
1300.85	33.4484
1304.05	34.5398
1307.24	35.2722
1310.43	35.8899
1313.63	35.1859
1316.82	34.3514
1320.01	34.5305
1323.2	34.4612
1326.38	33.6702
1329.57	32.533
1332.76	30.2554
1335.94	29.203
1339.12	27.2754
1342.3	27.7262
1345.48	28.5351
1348.66	29.3662
1351.84	29.4616
1355.01	29.4423
1358.19	28.7586
1361.36	28.0093
1364.53	28.0606
1367.71	27.1047
1370.88	26.6796
1374.04	26.0247
1377.21	26.4183
1380.38	25.7194
1383.54	25.2751
1386.71	24.0336
1389.87	24.345
1393.03	24.0164
1396.19	23.3078
1399.35	23.359
1402.51	22.5143
1405.67	21.8507
1408.82	22.9606
1411.98	26.2746
1415.13	28.5578
1418.28	31.2657
1421.43	33.6285
1424.58	36.2324
1427.73	38.4865
1430.88	41.0047
1434.02	42.8361
1437.17	45.6115
1440.31	46.332
1443.45	49.3937
1446.6	49.1896
1449.74	50.3474
1452.87	50.4877
1456.01	49.5497
1459.15	48.2339
1462.28	48.0994
1465.42	47.103
1468.55	45.3141
1471.68	43.175
1474.81	41.2526
1477.94	37.7943
1481.07	34.8902
1484.2	33.4306
1487.32	33.6447
1490.45	31.2035
1493.57	29.6793
1496.69	27.2209
1499.81	25.446
1502.93	23.7553
1506.05	21.9001
1509.17	20.9352
1512.28	20.7594
1515.4	20.9383
1518.51	21.6103
1521.63	20.6062
1524.74	19.4333
1527.85	19.3769
1530.96	19.1727
1534.06	19.5743
1537.17	20.9698
1540.28	20.283
1543.38	20.6718
1546.48	20.4806
1549.59	20.9101
1552.69	20.3764
1555.79	21.2726
1558.88	22.0162
1561.98	22.0084
1565.08	23.0881
1568.17	21.692
1571.27	22.0203
1574.36	22.0607
1577.45	22.5777
1580.54	23.7126
1583.63	24.8627
1586.72	27.0915
1589.8	28.1813
1592.89	30.6269
1595.97	31.3572
1599.06	31.7299
1602.14	31.7002
1605.22	32.2665
1608.3	31.8866
1611.38	31.3735
1614.46	31.1698
1617.53	30.25
1620.61	29.9976
1623.68	28.5314
1626.75	27.3825
1629.82	26.4186
1632.9	25.1662
1635.96	23.4035
1639.03	23.5786
1642.1	24.7495
1645.16	25.5139
1648.23	25.9382
1651.29	27.6869
1654.36	27.482
1657.42	28.4302
1660.48	29.3193
1663.53	28.9081
1666.59	30.5994
1669.65	30.5194
1672.7	29.8441
1675.76	28.6551
1678.81	27.2447
1681.86	25.1914
1684.91	22.667
1687.96	21.0295
1691.01	19.9445
1694.06	18.2287
1697.11	16.7913
1700.15	15.5085
1703.2	14.1194
1706.24	13.031
1709.28	11.4083
1712.32	10.939
1715.36	11.9304
1718.4	12.1197
1721.43	11.6352
1724.47	10.9707
1727.5	11.4727
1730.54	9.81459
1733.57	9.62729
1736.6	7.81795
1739.63	7.15282
1742.66	6.42075
1745.69	5.77974
1748.72	5.57526
1751.74	4.42515
1754.77	2.86873
1757.79	2.50554
1760.81	4.29679
1763.83	4.33922
1766.85	4.00135
1769.87	4.72445
1772.89	5.48359
1775.91	5.11225
1778.92	4.90599
1781.94	5.28338
1784.95	5.58658
1787.96	6.45595
1790.97	6.2222
1793.98	5.77522
1796.99	5.9296
1800	5.21418
1803	4.26976
1806.01	2.41534
1809.01	2.30952
1812.02	2.49234
1815.02	1.86205
1818.02	2.31424
1821.02	2.41755
1824.02	2.64694
1827.01	2.27023
1830.01	3.16624
1833	3.76134
1836	4.20664
1838.99	4.56478
1841.98	4.97055
1844.97	4.37302
1847.96	4.61482
1850.95	4.64032
1853.94	5.21587
1856.92	5.89638
1859.91	6.24566
1862.89	5.0801
1865.88	5.23163
1868.86	5.59103
1871.84	5.70307
1874.82	5.30721
1877.8	5.26693
1880.77	4.59368
1882.52	3.62784
1885.51	3.06707
1888.5	3.97074
1891.49	4.36997
1894.47	4.89139
1897.46	5.27155
1900.44	6.06798
1903.42	5.70099
1906.4	5.1942
1909.38	5.35441
1912.36	4.93272
1915.34	4.2665
1918.32	4.37495
1921.29	5.01165
1924.27	5.3961
1927.24	4.93703
1930.21	5.18424
1933.18	4.21479
1936.15	4.36299
1939.12	4.15365
1942.09	4.29203
1945.06	4.14244
1948.02	4.13674
1950.99	3.66649
1953.95	4.23148
1956.91	4.36775
1959.87	5.14931
1962.84	6.08721
1965.79	5.32282
1968.75	5.38692
1971.71	5.51273
1974.66	5.5881
1977.62	6.33543
1980.57	6.10461
1983.53	6.02105
1986.48	6.24185
1989.43	6.51697
1992.38	7.07849
1995.33	6.93679
1998.27	7.75819
2001.22	6.95103
2004.16	7.37082
2007.11	7.16867
2010.05	8.35456
2012.99	9.50217
2015.93	9.71731
2018.87	9.70013
2021.81	10.2199
2024.75	10.2579
2027.69	10.3856
2030.62	9.58712
2033.56	9.76488
2036.49	9.43126
2039.42	10.5864
2042.35	11.4889
2045.28	12.3148
2048.21	12.1155
2051.14	10.9456
2054.06	10.8368
2056.99	10.3329
2059.92	10.714
2062.84	10.8523
2065.76	10.9497
2068.68	11.7522
2071.6	12.6965
2074.52	12.9279
2077.44	12.4239
2080.36	11.9125
2083.27	11.1678
2086.19	9.80695
2089.1	8.67755
2092.01	8.20161
2094.93	8.75911
2097.84	8.60847
2100.75	7.87408
2103.66	7.43627
2106.56	7.41697
2109.47	8.25038
2112.37	7.35512
2115.28	7.78757
2118.18	5.81557
2121.09	4.30571
2123.99	4.37085
2126.89	4.7393
2129.79	4.63543
2132.68	6.09233
2135.58	6.67648
2138.48	7.95119
2141.37	8.96336
2144.26	9.75994
2147.16	10.0747
2150.05	10.0689
2152.94	10.4651
2155.83	11.8823
2158.72	12.8541
2161.6	15.045
2164.49	17.567
2167.38	18.8575
2170.26	18.9082
2173.14	19.4263
2176.03	20.3552
2178.91	20.5441
2181.79	20.0539
2184.67	19.7174
2187.54	18.8315
2190.42	17.6458
2193.3	16.8658
2196.17	15.4782
2199.05	14.634
2201.92	13.9384
2204.79	13.2126
2207.66	11.8921
2210.53	11.0197
2213.4	10.0759
2216.27	9.54767
2219.13	8.51436
2222	8.00388
2224.86	8.39074
2227.72	9.14587
2230.59	8.8945
2233.45	10.0229
2236.31	10.5863
2239.17	9.05246
2242.03	9.71214
2244.88	9.28241
2247.74	9.10362
2250.59	8.03659
2253.45	8.08608
2256.3	8.32522
2259.15	8.33106
2262	8.87777
2264.85	8.93114
2267.7	9.31054
2270.55	10.05
2273.4	10.2477
2276.24	9.43073
2279.09	8.82112
2281.93	8.70421
2284.77	8.16723
2287.61	8.10528
2290.46	6.95979
2293.29	6.55476
2296.13	7.33294
2298.97	7.8253
2301.81	8.70789
2304.64	7.96106
2307.48	7.92459
2310.31	7.51428
2313.14	7.14486
2315.97	5.98071
2318.8	6.2328
2321.63	6.48484
2324.46	6.4374
2327.29	7.03849
2330.12	7.94255
2332.94	8.16602
2335.76	7.87451
2338.59	7.55128
2341.41	6.83209
2344.23	5.23154
2347.05	4.7354
2349.87	3.68346
2352.69	2.84271
2355.5	1.90505
2358.32	1.41224
2361.14	1.54602
2363.95	2.0203
2366.76	3.5173
2369.58	2.89764
2372.39	1.97964
2375.2	1.75407
2378	2.11999
2380.81	1.88633
2383.62	2.13058
2386.42	2.80351
2389.23	2.68817
2392.03	2.99308
2394.84	3.40446
2397.64	4.07017
2400.44	3.94047
2403.24	4.33241
2406.04	4.04511
2408.83	3.79691
2411.63	4.59203
2414.43	4.47041
2417.22	4.7799
2420.02	4.06369
2422.81	4.30205
2425.6	4.8597
2428.39	3.81115
2431.18	3.88523
2433.97	3.31633
2436.76	3.68622
2439.54	3.8345
2442.33	3.89424
2445.11	3.95955
2447.9	3.83723
2450.68	2.84891
2453.46	2.89573
2456.24	2.53242
2459.02	1.6183
2461.8	1.72534
2464.58	1.21421
2467.36	0.91344
2470.13	0.615182
2472.91	1.0997
2475.68	1.33257
2478.45	1.15709
2481.22	2.13575
2484	1.81555
2486.77	2.09124
2489.54	2.45766
2492.3	2.5389
2495.07	2.33177
2497.84	2.40353
2500.6	3.18319
2503.36	3.01217
2506.13	3.77001
2508.89	3.41973
2511.65	2.93638
2514.41	2.45614
2517.17	2.74276
2519.93	3.05499
2522.68	1.53483
2525.44	2.13955
2528.19	1.32314
2530.95	1.14436
2533.7	0.883663
2536.45	0.243604
2539.2	0.572878
2541.95	0.630656
2544.7	0.175935
2547.45	0.243223
2550.2	-0.101806
2552.94	-0.322894
2555.69	-0.372135
2558.43	-0.204268
2561.17	-0.344716
2563.92	-0.108089
2566.66	0.373994
2569.4	1.05446
2572.14	1.15862
2574.88	1.73949
2577.61	1.48151
2580.35	2.06661
2583.09	3.05192
2585.82	2.8796
2588.55	2.15398
2591.28	1.48879
2594.02	2.23448
2596.75	2.41618
2599.48	2.24684
2602.2	1.91304
2604.93	2.10929
2607.66	2.49716
2610.38	2.38793
2613.11	2.66386
2615.83	2.79787
2618.56	2.28698
2621.28	2.52802
2624	2.28221
2626.72	2.8689
2629.44	2.97057
2632.15	3.153
2634.87	2.83214
2637.59	3.02298
2640.3	2.77817
2643.02	3.10537
2645.73	3.01188
2648.44	2.81368
2651.15	1.62876
2653.86	1.6406
2656.57	1.75325
2659.28	1.30308
2661.99	1.51538
2664.69	1.3489
2667.4	0.991992
2670.1	1.32739
2672.81	0.966738
2675.51	1.59591
2678.21	1.70578
2680.91	2.20905
2683.61	1.99376
2686.31	2.17464
2689	2.63174
2691.7	2.51629
2694.4	3.62608
2697.09	3.57892
2699.79	3.93514
2702.48	4.2446
2705.17	4.84204
2707.86	5.69623
2710.55	6.44154
2713.24	7.22223
2715.93	7.79428
2718.61	8.23478
2721.3	8.36981
2723.99	8.34071
2726.67	8.37471
2729.35	8.21394
2732.04	7.97585
2734.72	7.66233
2737.4	7.56352
2740.08	7.72049
2742.76	7.32264
2745.43	7.05699
2748.11	7.00286
2750.79	6.56852
2753.46	6.90543
2756.13	6.70224
2758.81	6.62875
2761.48	5.87107
2764.15	4.38218
2766.82	4.87218
2769.49	4.73777
2772.16	5.27116
2774.82	5.35575
2777.49	5.52025
2780.16	5.5272
2782.82	5.11454
2785.48	5.09471
2788.15	5.85004
2790.81	5.08076
2793.47	4.56132
2796.13	4.29416
2798.79	3.67333
2801.44	3.95531
2804.1	3.37613
2806.76	3.08233
2809.41	2.90192
2812.07	2.90783
2814.72	2.88687
2817.37	3.31351
2820.02	4.10617
2822.67	4.10001
2825.32	5.8462
2827.97	7.05714
2830.62	8.67206
2833.26	10.5794
2835.91	12.1827
2838.55	15.1754
2841.2	18.1778
2843.84	21.8164
2846.48	25.6679
2849.12	30.6708
2851.76	36.4284
2854.4	41.6435
2857.04	46.0489
2859.68	50.568
2862.32	55.3658
2864.95	58.9578
2867.58	62.4658
2870.22	66.5453
2872.85	69.3683
2875.48	72.2805
2878.11	75.2446
2880.74	77.8927
2883.37	80.3869
2886	82.0796
2888.63	84.1362
2891.25	86.3638
2893.88	87.501
2896.5	89.6503
2899.13	92.114
2901.75	94.9288
2904.37	97.6379
2906.99	102.095
2909.61	106.639
2912.23	112.108
2914.85	116.405
2917.46	121.336
2920.08	124.694
2922.7	126.899
2925.31	128.422
2927.92	129.308
2930.53	130.179
2933.15	130.079
2935.76	130.095
2938.37	128.648
2940.98	126.202
2943.58	122.753
2946.19	118.291
2948.8	114.527
2951.4	110.281
2954.01	106.646
2956.61	102.395
2959.21	98.2581
2961.81	93.6983
2964.41	88.6134
2967.01	84.1038
2969.61	80.9898
2972.21	77.388
2974.81	72.7862
2977.4	68.7693
2980	63.6979
2982.59	58.8393
2985.18	53.0854
2987.78	47.71
2990.37	42.9329
2992.96	38.2124
2995.55	33.5588
2998.14	28.7638
3000.72	24.8372
3003.31	20.7276
3005.9	17.2353
3008.48	14.4314
3011.07	11.8735
3013.65	10.1179
3016.23	8.26227
3018.81	6.84665
3021.39	6.29514
3023.97	4.67737
3026.55	3.43567
3029.13	3.05111
3031.71	2.25945
3034.28	2.6252
3036.86	2.29527
3039.43	2.73618
3042.01	2.74996
3044.58	3.6773
3047.15	3.32878
3049.72	3.91981
3052.29	4.59313
3054.86	4.26385
3057.43	4.75098
3060	4.86838
3062.56	4.96953
3065.13	5.01179
3067.69	5.46766
3070.25	4.84932
3072.82	4.83776
3075.38	4.34626
3077.94	3.61468
3080.5	3.08407
3083.06	2.9516
3085.62	1.869
3088.17	1.22845
3090.73	0.891713
3093.29	0.982657
3095.84	0.685152
3098.4	1.36247
3100.95	0.68451
3103.5	0.329924
3106.05	0.677085
3108.6	1.43688
3111.15	1.32472
3113.7	1.19647
3116.25	0.97524
3118.79	0.758252
3121.34	0.89955
3123.88	0.629107
3126.43	1.02435
3128.97	1.67015
3131.51	2.4297
3134.05	3.40759
3136.59	4.17718
3139.14	5.06751
3141.67	6.14989
3144.21	7.49398
3146.75	9.14707
3149.28	10.7185