File: data/Raman/poly_smoothed/Mb_10_14_05_1x_45s_532 nm_x100_100%_600 gr_mm_01.txt
#Acq. time (s)=	45
#Accumulations=	2
#Range (cm-¹)=	200...3150
#Windows=	2
#Auto scanning=	Off
#Autofocus=	Off
#Macrospot=	Off
#AutoExposure=	Off
#Spike filter=	Multiple accum.
#Delay time (s)=	0
#Binning=	1
#Readout mode=	Signal
#DeNoise=	Off
#ICS correction=	On
#Dark correction=	Off
#Inst. Process=	Off
#Detector Gain=	Best Dynamic Range
#Detector ADC=	20 kHz
#Detector temperature (°C)=	-70.08
#Instrument=	LabRAM HR Evol
#Detector=	Synapse
#Objective=	x100
#Grating=	600 gr/mm
#ND Filter=	100%
#Laser (nm)=	532
#Hole=	100.021
#Range=	Auto
#Laser Pol.=	No
#Raman. Pol.=	No
#Laser Pol. (°)=	-0.0007625
#Raman Pol. (°)=	89.9995
#Collection=	Microscope
#StageXY=	Marzhauser
#StageZ=	Marzhauser
#X (µm)=	-2396.1
#Y (µm)=	2132.9
#Z (µm)=	-40.5
#Full time(mm:ss)=	3:18
#Project=
#Sample=
#Site=
#Title=	Mb_10_14_05_2x_45s_532 nm_x100_100%_600 gr_mm
#Remark=
#Date=	07.07.2022 13:46
#Acquired=	07.07.2022 13:46:09
#Base:Fit=	10.08.2022 10:21:11
#Base:Sub=	10.08.2022 10:21:41
#Filter:Polynom=	16.08.2022 10:17:53
#AxisType[0]=Intens
#AxisUnit[0]=Cnt
#AxisType[1]=Spectr
#AxisUnit[1]=1/cm
200.43	1.86422
204.061	-1.02964
207.688	1.04018
211.316	3.20658
214.941	6.96215
218.566	9.91577
222.188	13.3455
225.809	15.985
229.43	18.2054
233.047	18.7763
236.663	21.2631
240.278	21.4097
243.894	22.6741
247.506	22.7819
251.116	21.8565
254.725	22.6012
258.333	21.5745
261.939	21.5631
265.546	20.6128
269.15	19.6143
272.752	18.6742
276.353	14.9548
279.952	11.0699
283.55	6.62052
287.146	7.89148
290.739	8.56432
294.333	6.65813
297.925	5.48038
301.516	5.33004
305.106	5.96309
308.694	5.78784
312.279	6.61023
315.864	7.70099
319.448	7.15103
323.029	7.59499
326.61	7.89525
330.19	9.79388
333.766	9.53506
337.343	10.2223
340.917	9.83998
344.491	11.1619
348.062	11.3722
351.633	11.5313
355.201	12.1907
358.77	13.0591
362.335	13.1317
365.899	14.1402
369.464	16.4218
373.025	17.7789
376.585	20.7382
380.143	23.3745
383.702	25.1022
387.258	28.3909
390.812	31.9068
394.365	34.4615
397.916	34.4615
401.467	35.3161
405.015	34.6509
408.565	32.7224
412.111	30.0589
415.656	29.4312
419.197	26.6432
422.739	22.4702
426.279	19.9563
429.819	16.7291
433.356	13.7644
436.893	8.02008
440.428	5.83424
443.96	4.31915
447.492	4.3732
451.023	3.92746
454.553	2.36275
458.079	4.39337
461.606	5.47239
465.132	8.56338
468.654	11.7553
472.177	13.2798
475.696	14.9383
479.217	17.9065
482.733	19.6253
486.251	20.5162
489.765	22.9423
493.278	22.8702
496.791	23.0326
500.301	24.1307
503.81	26.4649
507.319	26.6559
510.825	26.7351
514.33	26.3055
517.833	26.5314
521.337	25.866
524.838	24.9894
528.337	23.9535
531.835	22.5786
535.332	21.9401
538.827	19.6898
542.321	19.4422
545.814	18.9946
549.305	17.3355
552.795	16.4491
556.284	14.0647
559.771	12.0629
563.257	12.5053
566.742	12.5697
570.223	10.5474
573.705	9.0315
577.185	7.01721
580.665	5.39088
584.141	4.39813
587.617	6.20219
591.092	6.46447
594.564	4.86357
598.037	4.85018
601.506	5.377
604.976	6.08957
608.443	6.33964
611.91	6.26242
615.374	7.98832
618.839	9.8577
622.3	10.5324
625.761	12.8182
629.221	16.3656
632.679	18.0044
636.135	20.6707
639.592	22.402
643.045	24.0352
646.497	25.7731
649.948	27.8065
653.398	29.0677
656.846	28.7639
660.293	28.3666
663.738	29.668
667.185	31.1198
670.628	32.503
674.067	32.4516
677.508	32.2162
680.947	31.1054
684.385	30.5878
687.821	30.8087
691.256	31.996
694.69	32.7484
698.121	34.0059
701.552	34.738
704.982	34.7219
708.41	35.878
711.836	37.3692
715.262	37.8918
718.685	38.3609
722.108	39.3365
725.53	40.6331
728.949	42.1153
732.369	43.2337
735.785	44.2279
739.2	45.5154
742.616	48.1887
746.028	51.8572
749.441	55.7785
752.851	57.6908
756.26	59.7746
759.667	62.7326
763.075	63.296
766.479	65.4522
769.883	68.7714
773.285	71.9996
776.686	74.3773
780.085	76.9343
783.484	78.0841
786.881	77.2995
790.276	76.6279
793.671	78.0289
797.064	79.2734
800.456	80.0275
803.846	80.5504
807.236	79.8665
810.624	80.9774
814.01	79.5965
817.394	79.2483
820.778	77.9859
824.161	79.381
827.543	79.8857
830.921	80.1636
834.3	78.3397
837.676	77.4965
841.053	76.1012
844.426	75.7736
847.8	73.236
851.171	72.8559
854.542	71.244
857.911	70.8853
861.279	69.2906
864.645	67.2188
868.01	64.8831
871.375	63.0267
874.737	62.0589
878.097	62.0532
881.457	60.5579
884.817	59.811
888.174	59.5162
891.53	59.8635
894.884	58.6911
898.237	58.4927
901.589	57.5039
904.94	56.6871
908.289	56.5361
911.637	56.7993
914.984	54.5376
918.33	52.3797
921.674	51.1542
925.015	50.4254
928.357	50.0802
931.698	48.9007
935.037	48.4787
938.373	47.375
941.71	47.3502
945.046	47.6273
948.378	46.0209
951.711	44.2363
955.043	43.0112
958.372	40.5355
961.701	39.0975
965.027	38.3984
968.354	38.7972
971.678	39.9591
975	39.4588
978.324	38.4492
981.644	38.766
984.962	39.0161
988.282	38.5864
991.598	38.1979
994.913	37.4649
998.227	35.7543
1001.54	36.091
1004.85	36.8645
1008.16	38.0766
1011.47	38.081
1014.78	38.1554
1018.08	40.8446
1021.39	43.8278
1024.69	46.6133
1028	46.9185
1031.3	45.7816
1034.6	45.9831
1037.9	44.9291
1041.19	43.3685
1044.49	43.8483
1047.79	44.2952
1051.08	43.4369
1054.37	40.957
1057.66	38.57
1060.95	36.4914
1064.24	34.8597
1067.53	33.1113
1070.81	29.9008
1074.1	27.644
1077.38	25.4591
1080.66	23.786
1083.94	22.8047
1087.22	21.1892
1090.5	20.9195
1093.78	21.3432
1097.05	20.8624
1100.33	21.0513
1103.6	20.9938
1106.87	20.1337
1110.15	20.2411
1113.41	19.1032
1116.68	18.6197
1119.95	16.836
1123.21	14.9324
1126.48	13.8783
1129.74	11.0213
1133	10.6239
1136.26	8.96945
1139.52	7.92061
1142.78	7.81652
1146.04	8.18878
1149.29	7.92447
1152.55	8.84535
1155.8	9.72511
1159.05	9.67728
1162.3	9.58526
1165.55	11.0573
1168.8	11.942
1172.05	12.5934
1175.29	13.3504
1178.54	14.5761
1181.78	15.5441
1185.02	18.4061
1188.26	19.9567
1191.5	20.5781
1194.74	21.7157
1197.97	21.9209
1201.21	20.9771
1204.44	20.7945
1207.68	20.8888
1210.91	22.0642
1214.14	23.8728
1217.37	25.1283
1220.6	27.4477
1223.82	28.8332
1227.05	30.3757
1230.27	30.901
1233.49	32.6873
1236.72	33.7471
1239.94	34.2633
1243.16	35.0509
1246.37	35.1267
1249.59	35.8501
1252.8	35.7907
1256.02	35.3735
1259.23	35.5835
1262.44	37.4187
1265.66	37.7366
1268.87	38.7489
1272.07	38.5871
1275.28	38.7019
1278.48	38.2116
1281.69	35.79
1284.89	37.8855
1288.09	39.8006
1291.3	40.4949
1294.49	41.0177
1297.69	41.9154
1300.89	44.2162
1304.09	46.464
1307.28	48.8517
1310.47	50.7438
1313.66	52.8863
1316.86	54.9571
1320.05	55.6369
1323.23	56.8116
1326.42	57.5561
1329.61	56.7561
1332.79	56.3511
1335.98	56.6514
1339.16	56.9608
1342.34	56.9203
1345.52	55.7259
1348.7	53.726
1351.87	51.1842
1355.05	50.4364
1358.23	47.6681
1361.4	46.2988
1364.57	44.4344
1367.74	42.0972
1370.91	40.3426
1374.08	39.3796
1377.25	39.2155
1380.42	40.7154
1383.58	40.1303
1386.75	40.287
1389.91	38.2273
1393.07	37.576
1396.23	37.8539
1399.39	37.0973
1402.55	36.0914
1405.7	34.8552
1408.86	34.0615
1412.01	35.2145
1415.17	37.1284
1418.32	38.3393
1421.47	41.787
1424.62	44.7048
1427.77	48.1875
1430.92	53.5809
1434.06	56.7722
1437.2	59.4804
1440.35	61.7888
1443.49	64.4001
1446.63	65.7911
1449.77	67.3212
1452.91	67.9227
1456.05	66.7878
1459.18	66.897
1462.32	66.0003
1465.45	64.5123
1468.59	63.0823
1471.72	62.4215
1474.85	60.1921
1477.98	58.3529
1481.11	55.6844
1484.23	52.9472
1487.36	51.4748
1490.48	51.5018
1493.61	49.9751
1496.73	49.2779
1499.85	46.8894
1502.97	46.0002
1506.09	43.5636
1509.2	40.3813
1512.32	37.1316
1515.44	33.3327
1518.55	30.7039
1521.66	28.4313
1524.77	24.9773
1527.88	23.1907
1530.99	21.9151
1534.1	19.8028
1537.21	19.9815
1540.31	19.8204
1543.42	19.8683
1546.52	20.683
1549.62	21.1124
1552.72	22.1492
1555.82	24.6566
1558.92	27.8663
1562.02	29.7628
1565.11	32.1323
1568.21	33.1795
1571.3	34.5572
1574.39	35.368
1577.49	37.2294
1580.58	39.0639
1583.67	40.338
1586.75	41.0324
1589.84	41.8425
1592.93	42.6708
1596.01	43.0715
1599.09	42.8881
1602.18	42.1365
1605.26	42.2365
1608.34	41.7025
1611.41	41.0569
1614.49	41.1013
1617.57	41.743
1620.64	40.6943
1623.72	40.7657
1626.79	43.0229
1629.86	43.5354
1632.93	46.0035
1636	48.092
1639.07	46.979
1642.14	48.5356
1645.2	50.4862
1648.27	52.2058
1651.33	52.6108
1654.39	54.0634
1657.45	54.8803
1660.51	54.4494
1663.57	53.2277
1666.63	51.4027
1669.69	48.9377
1672.74	47.0484
1675.79	44.758
1678.85	42.9895
1681.9	39.7951
1684.95	36.107
1688	31.3369
1691.05	27.9925
1694.1	24.2154
1697.14	20.2738
1700.19	16.3583
1703.23	14.0188
1706.27	11.5131
1709.32	10.2297
1712.35	8.45837
1715.39	6.90698
1718.43	5.34061
1721.47	3.86893
1724.5	3.34899
1727.54	3.60332
1730.57	2.92252
1733.61	1.87748
1736.64	1.12919
1739.67	0.635448
1742.7	1.48035
1745.72	2.11062
1748.75	1.93646
1751.78	2.69618
1754.8	2.62591
1757.82	2.06086
1760.85	1.84689
1763.87	1.53679
1766.89	1.69664
1769.91	1.6683
1772.92	1.70335
1775.94	1.57281
1778.96	2.93836
1781.97	2.94934
1784.98	3.2448
1788	3.4963
1791.01	3.56615
1794.01	3.27856
1797.02	3.95257
1800.03	4.34054
1803.04	3.30799
1806.04	2.445
1809.05	2.77573
1812.05	3.5514
1815.05	4.05263
1818.05	4.41864
1821.05	4.52766
1824.05	5.6167
1827.05	5.3031
1830.04	5.40729
1833.04	5.13653
1836.03	6.46708
1839.03	7.96433
1842.02	8.36234
1845.01	8.94387
1848	9.61938
1850.99	9.34391
1853.97	9.00995
1856.96	10.1666
1859.94	10.7136
1862.93	9.51393
1865.91	8.95333
1868.89	8.49697
1871.87	8.26413
1874.85	7.07406
1877.83	6.37905
1880.81	5.15595
1882.56	4.29801
1885.55	3.38089
1888.54	3.11188
1891.52	2.82113
1894.51	3.0769
1897.49	3.32667
1900.48	2.93606
1903.46	4.4122
1906.44	5.79814
1909.42	6.04416
1912.4	5.04379
1915.38	5.52069
1918.35	6.02746
1921.33	5.45721
1924.3	5.51674
1927.28	5.86084
1930.25	5.74876
1933.22	4.29009
1936.19	2.97255
1939.16	2.05786
1942.13	1.51365
1945.09	0.678485
1948.06	-0.295618
1951.03	0.758172
1953.99	0.767669
1956.95	1.15915
1959.91	2.09422
1962.87	2.58514
1965.83	4.24273
1968.79	4.54551
1971.75	4.20356
1974.7	5.61677
1977.66	5.82783
1980.61	5.44785
1983.56	4.4083
1986.52	5.30947
1989.47	4.46175
1992.41	3.75899
1995.36	3.66481
1998.31	3.77155
2001.26	3.68742
2004.2	3.76109
2007.15	3.59673
2010.09	3.30894
2013.03	2.94022
2015.97	3.84791
2018.91	4.92237
2021.85	5.06945
2024.79	5.38931
2027.72	5.58897
2030.66	6.65153
2033.59	7.17112
2036.53	7.00491
2039.46	7.67555
2042.39	7.60275
2045.32	8.85604
2048.25	8.00467
2051.18	7.61581
2054.1	9.05629
2057.03	9.17535
2059.95	8.87849
2062.88	8.3528
2065.8	8.37436
2068.72	9.71144
2071.64	10.1478
2074.56	10.5784
2077.48	11.622
2080.39	12.5068
2083.31	11.5292
2086.22	12.8463
2089.14	13.3921
2092.05	12.0866
2094.96	10.9653
2097.87	11.7502
2100.78	11.7185
2103.69	11.8684
2106.6	11.9249
2109.51	11.9283
2112.41	11.4444
2115.32	10.2365
2118.22	10.2065
2121.12	11.1623
2124.02	11.4623
2126.92	11.6576
2129.82	10.3775
2132.72	10.6085
2135.62	11.201
2138.51	12.802
2141.41	13.9407
2144.3	14.6885
2147.19	17.0637
2150.09	18.0833
2152.97	18.903
2155.86	19.5069
2158.75	20.8663
2161.64	22.1438
2164.53	23.6463
2167.41	24.9378
2170.3	25.6775
2173.18	25.7572
2176.06	25.8115
2178.94	25.8989
2181.82	25.0973
2184.7	24.1528
2187.58	24.7537
2190.46	24.2135
2193.33	24.5838
2196.21	23.321
2199.08	21.8955
2201.95	20.7841
2204.83	19.8194
2207.7	18.5338
2210.57	17.1656
2213.43	16.2125
2216.3	15.7794
2219.17	14.8759
2222.03	13.9549
2224.9	12.782
2227.76	12.5442
2230.62	12.9595
2233.49	12.3134
2236.34	12.1215
2239.2	11.2236
2242.06	10.1387
2244.92	9.43048
2247.78	10.0232
2250.63	10.0117
2253.48	11.8345
2256.34	11.4501
2259.19	11.8541
2262.04	12.4558
2264.89	12.1414
2267.74	11.7155
2270.59	11.7349
2273.43	11.5814
2276.28	10.5346
2279.12	10.4047
2281.97	9.84503
2284.81	9.07223
2287.65	8.9636
2290.49	7.22292
2293.33	5.03345
2296.17	4.80921
2299.01	5.80967
2301.84	5.91082
2304.68	5.58189
2307.51	4.71539
2310.35	5.25337
2313.18	4.40837
2316.01	4.92249
2318.84	6.15942
2321.67	6.48993
2324.5	6.698
2327.33	5.1308
2330.15	5.2221
2332.98	5.39433
2335.8	4.66752
2338.62	3.87022
2341.45	3.33793
2344.27	3.72492
2347.09	2.94638
2349.91	1.61652
2352.72	1.65696
2355.54	1.78535
2358.36	2.38463
2361.17	1.49323
2363.98	0.932498
2366.8	2.92859
2369.61	3.47921
2372.42	2.91353
2375.23	2.06887
2378.04	2.7984
2380.85	2.93341
2383.66	2.21011
2386.46	2.89407
2389.26	3.41456
2392.07	2.93475
2394.87	2.35954
2397.67	2.11115
2400.47	1.99
2403.27	2.30513
2406.07	3.05151
2408.87	3.89794
2411.67	3.92627
2414.46	4.63393
2417.26	4.92258
2420.05	5.55869
2422.84	6.20384
2425.64	6.47452
2428.43	7.40657
2431.22	6.64391
2434.01	6.50317
2436.79	6.49289
2439.58	6.1274
2442.37	6.40478
2445.15	5.31973
2447.93	5.33434
2450.72	4.77987
2453.5	5.10674
2456.28	4.90387
2459.06	4.47846
2461.84	4.49979
2464.62	3.88042
2467.39	3.82525
2470.17	3.84615
2472.94	3.87449
2475.72	2.42922
2478.49	1.94904
2481.26	1.52014
2484.03	1.55611
2486.8	0.701226
2489.57	1.09894
2492.34	1.60984
2495.1	1.72033
2497.87	0.654464
2500.63	0.813733
2503.4	2.048
2506.16	2.51578
2508.92	3.58926
2511.68	3.7907
2514.44	4.76931
2517.2	4.88697
2519.96	5.80666
2522.72	6.09169
2525.47	6.43826
2528.23	5.86587
2530.98	6.70816
2533.74	8.10565
2536.49	8.25671
2539.24	8.15701
2541.99	6.13199
2544.74	6.82832
2547.49	6.20214
2550.23	6.61694
2552.98	7.01336
2555.72	6.20697
2558.47	6.16172
2561.21	5.58437
2563.95	6.11946
2566.69	5.75409
2569.43	5.24618
2572.17	4.10507
2574.91	4.50418
2577.65	3.66784
2580.39	3.05913
2583.12	2.69504
2585.85	2.68673
2588.59	2.2834
2591.32	2.23691
2594.05	2.20949
2596.78	3.77876
2599.51	4.06906
2602.24	3.80905
2604.97	4.38166
2607.69	4.26459
2610.42	4.04727
2613.14	5.11513
2615.87	5.45716
2618.59	5.95083
2621.31	5.8969
2624.03	5.56471
2626.75	4.94297
2629.47	5.3485
2632.19	4.49018
2634.91	3.68214
2637.62	4.50522
2640.34	4.97274
2643.05	5.38741
2645.76	4.95757
2648.48	4.84786
2651.19	4.7871
2653.9	4.18381
2656.6	2.51219
2659.31	2.66851
2662.02	3.79724
2664.73	3.28995
2667.43	3.53665
2670.14	4.33941
2672.84	5.02002
2675.54	5.2423
2678.24	4.69495
2680.94	5.38044
2683.64	6.14249
2686.34	5.71695
2689.04	5.75484
2691.74	6.09461
2694.43	6.24551
2697.13	6.90608
2699.82	7.4963
2702.51	8.23092
2705.21	8.02369
2707.9	7.95376
2710.58	8.25359
2713.27	7.25798
2715.96	8.14606
2718.65	8.1287
2721.33	7.67178
2724.02	7.94277
2726.71	8.41719
2729.39	8.40293
2732.07	8.54181
2734.75	9.1033
2737.43	8.73862
2740.11	8.2433
2742.79	7.27638
2745.47	6.97416
2748.14	6.50997
2750.82	5.60443
2753.49	4.87952
2756.17	4.19541
2758.84	2.56001
2761.51	2.41601
2764.18	1.93994
2766.85	1.59498
2769.52	1.39166
2772.19	1.23292
2774.86	2.09233
2777.52	2.78825
2780.19	3.83314
2782.85	4.11003
2785.52	4.09079
2788.18	3.48245
2790.84	4.14594
2793.5	3.11096
2796.16	3.74259
2798.82	4.07053
2801.48	2.87873
2804.13	2.95408
2806.79	1.38745
2809.45	0.897425
2812.1	0.613837
2814.75	0.659255
2817.41	-0.391441
2820.06	0.474764
2822.71	-0.450727
2825.36	0.221096
2828	2.09393
2830.65	4.1636
2833.3	4.96307
2835.94	7.93828
2838.59	11.2371
2841.23	15.0755
2843.87	18.9377
2846.52	23.7358
2849.16	28.8903
2851.8	34.0719
2854.44	39.7781
2857.08	45.4727
2859.71	51.6467
2862.35	57.5521
2864.98	62.1501
2867.62	66.8092
2870.25	71.8758
2872.88	76.172
2875.52	80.4335
2878.15	85.923
2880.78	88.5847
2883.41	91.1996
2886.03	93.8302
2888.66	96.009
2891.29	98.8611
2893.91	101.817
2896.54	105.172
2899.16	109.055
2901.78	113.614
2904.4	119.091
2907.02	124.895
2909.64	131.744
2912.26	138.78
2914.88	146.325
2917.5	153.006
2920.11	159.992
2922.73	165.448
2925.34	168.444
2927.96	170.123
2930.57	171.966
2933.18	173.62
2935.79	172.734
2938.4	170.647
2941.01	169.5
2943.62	165.481
2946.22	160.061
2948.83	154.236
2951.43	147.64
2954.04	141.516
2956.64	135.754
2959.24	130.297
2961.84	123.49
2964.45	116.532
2967.05	110.222
2969.64	104.277
2972.24	99.42
2974.84	94.1627
2977.43	88.5895
2980.03	84.3801
2982.62	78.8582
2985.22	74.0267
2987.81	67.1433
2990.4	60.4119
2992.99	54.5648
2995.58	49.0726
2998.17	43.1621
3000.76	37.7633
3003.34	33.2317
3005.93	29.4452
3008.52	24.8237
3011.1	20.9528
3013.68	18.2355
3016.27	15.2641
3018.85	12.796
3021.43	10.5028
3024.01	7.87293
3026.59	5.83534
3029.16	4.76817
3031.74	3.2741
3034.32	3.51193
3036.89	3.94471
3039.47	4.61916
3042.04	6.45899
3044.61	7.68836
3047.18	8.24849
3049.75	8.90279
3052.32	8.58637
3054.89	8.12686
3057.46	8.22142
3060.03	7.88895
3062.59	7.54156
3065.16	7.59935
3067.72	6.98446
3070.29	6.80169
3072.85	6.3371
3075.41	5.82566
3077.97	4.58497
3080.53	3.82882
3083.09	2.61179
3085.65	2.44117
3088.21	2.8807
3090.76	2.6272
3093.32	3.78851
3095.87	4.71128
3098.43	5.24445
3100.98	5.89094
3103.53	7.16957
3106.08	7.65995
3108.63	8.4264
3111.18	9.48395
3113.73	10.8488
3116.28	10.499
3118.83	10.8155
3121.37	11.7517
3123.92	12.8094
3126.46	13.5906
3129	14.1837
3131.55	15.4616
3134.09	16.8435
3136.63	17.2133
3139.17	18.6204
3141.71	20.6046
3144.24	23.0735
3146.78	25.8049
3149.32	28.2393