File: data/Raman/poly_smoothed/Mb_10_14_06_1x_45s_532 nm_x100_100%_600 gr_mm_01.txt
#Acq. time (s)=	45
#Accumulations=	2
#Range (cm-¹)=	200...3150
#Windows=	2
#Auto scanning=	Off
#Autofocus=	Off
#Macrospot=	Off
#AutoExposure=	Off
#Spike filter=	Multiple accum.
#Delay time (s)=	0
#Binning=	1
#Readout mode=	Signal
#DeNoise=	Off
#ICS correction=	On
#Dark correction=	Off
#Inst. Process=	Off
#Detector Gain=	Best Dynamic Range
#Detector ADC=	20 kHz
#Detector temperature (°C)=	-70.08
#Instrument=	LabRAM HR Evol
#Detector=	Synapse
#Objective=	x100
#Grating=	600 gr/mm
#ND Filter=	100%
#Laser (nm)=	532
#Hole=	100.021
#Range=	Auto
#Laser Pol.=	No
#Raman. Pol.=	No
#Laser Pol. (°)=	-0.0007625
#Raman Pol. (°)=	89.9995
#Collection=	Microscope
#StageXY=	Marzhauser
#StageZ=	Marzhauser
#X (µm)=	-2390.5
#Y (µm)=	2137.1
#Z (µm)=	-40.95
#Full time(mm:ss)=	3:19
#Project=
#Sample=
#Site=
#Title=	Mb_10_14_06_2x_45s_532 nm_x100_100%_600 gr_mm
#Remark=
#Date=	07.07.2022 13:50
#Acquired=	07.07.2022 13:50:32
#Base:Fit=	10.08.2022 10:21:11
#Base:Sub=	10.08.2022 10:21:41
#Filter:Polynom=	16.08.2022 10:17:53
#AxisType[0]=Intens
#AxisUnit[0]=Cnt
#AxisType[1]=Spectr
#AxisUnit[1]=1/cm
200.43	13.2443
204.061	9.97322
207.688	5.66043
211.316	1.30382
214.941	-1.69306
218.566	-1.32881
222.188	-0.544996
225.809	4.20954
229.43	8.09541
233.047	12.8655
236.663	15.5358
240.278	18.7108
243.894	20.1769
247.506	21.8436
251.116	25.9965
254.725	26.6643
258.333	28.7474
261.939	28.343
265.546	28.0093
269.15	28.3306
272.752	27.3717
276.353	25.3358
279.952	25.247
283.55	21.3586
287.146	17.7503
290.739	13.0709
294.333	9.88863
297.925	9.2786
301.516	7.91354
305.106	9.66796
308.694	10.5816
312.279	10.9031
315.864	10.451
319.448	10.5484
323.029	10.6273
326.61	9.84005
330.19	10.3661
333.766	9.94305
337.343	9.86841
340.917	9.53648
344.491	7.7126
348.062	7.75547
351.633	7.09503
355.201	7.62106
358.77	7.19203
362.335	7.95546
365.899	8.81738
369.464	10.6867
373.025	13.7437
376.585	17.0629
380.143	20.6426
383.702	24.4266
387.258	29.6565
390.812	34.2109
394.365	36.5629
397.916	37.792
401.467	38.6115
405.015	40.1131
408.565	40.996
412.111	42.157
415.656	41.185
419.197	40.0267
422.739	37.5667
426.279	35.3279
429.819	32.64
433.356	28.2534
436.893	22.7749
440.428	18.1535
443.96	15.8037
447.492	14.3118
451.023	13.4155
454.553	13.5588
458.079	13.9598
461.606	15.5404
465.132	16.5132
468.654	17.884
472.177	20.6831
475.696	22.2898
479.217	23.0256
482.733	23.6154
486.251	25.6734
489.765	26.7574
493.278	29.0308
496.791	31.0399
500.301	31.2428
503.81	32.4953
507.319	31.7085
510.825	30.8188
514.33	29.3779
517.833	28.5555
521.337	27.4438
524.838	26.1273
528.337	26.8576
531.835	26.5825
535.332	26.5971
538.827	26.4479
542.321	25.8686
545.814	25.3967
549.305	26.0727
552.795	23.8254
556.284	23.0199
559.771	22.578
563.257	21.3994
566.742	19.6756
570.223	17.1907
573.705	14.8392
577.185	15.0142
580.665	13.5469
584.141	11.0574
587.617	8.87892
591.092	6.56527
594.564	4.62995
598.037	5.31078
601.506	4.46405
604.976	4.51429
608.443	2.37158
611.91	3.07208
615.374	5.55496
618.839	5.00332
622.3	4.92562
625.761	6.4002
629.221	9.52761
632.679	11.3697
636.135	13.9888
639.592	14.7743
643.045	17.3679
646.497	20.9864
649.948	23.986
653.398	24.148
656.846	25.0106
660.293	27.505
663.738	28.8524
667.185	30.0628
670.628	28.7481
674.067	28.015
677.508	28.8608
680.947	26.133
684.385	25.106
687.821	24.0776
691.256	23.2213
694.69	23.1475
698.121	22.9441
701.552	21.7842
704.982	22.0187
708.41	22.7059
711.836	24.3601
715.262	25.3343
718.685	26.133
722.108	28.4746
725.53	30.6208
728.949	35.0965
732.369	36.7982
735.785	38.1904
739.2	40.1304
742.616	43.1506
746.028	48.4183
749.441	51.6238
752.851	54.3406
756.26	57.4819
759.667	60.3534
763.075	62.4771
766.479	62.6526
769.883	66.3559
773.285	69.3183
776.686	71.8322
780.085	75.0741
783.484	76.7747
786.881	77.2219
790.276	76.659
793.671	76.3933
797.064	77.6905
800.456	76.9738
803.846	78.4265
807.236	77.3379
810.624	75.8511
814.01	74.1244
817.394	72.4083
820.778	72.7659
824.161	71.6909
827.543	74.6581
830.921	75.5985
834.3	73.0043
837.676	72.5633
841.053	70.8003
844.426	68.6023
847.8	65.816
851.171	65.1119
854.542	63.711
857.911	63.5111
861.279	60.0639
864.645	56.9304
868.01	54.8114
871.375	52.3139
874.737	51.5282
878.097	51.7426
881.457	48.5804
884.817	47.6639
888.174	46.4247
891.53	43.2872
894.884	41.7383
898.237	39.3119
901.589	38.9532
904.94	39.8193
908.289	39.9129
911.637	39.9428
914.984	38.9081
918.33	38.1135
921.674	39.2785
925.015	37.5098
928.357	37.4564
931.698	37.7928
935.037	37.1713
938.373	37.6221
941.71	36.446
945.046	35.8739
948.378	35.8737
951.711	34.9428
955.043	35.5857
958.372	33.8846
961.701	32.5488
965.027	31.8821
968.354	32.1784
971.678	31.3835
975	31.9311
978.324	32.9223
981.644	33.5771
984.962	36.1067
988.282	37.3422
991.598	36.7245
994.913	37.3632
998.227	37.6514
1001.54	39.3597
1004.85	39.9388
1008.16	39.4175
1011.47	40.6927
1014.78	41.9137
1018.08	42.5747
1021.39	42.6062
1024.69	43.18
1028	45.9016
1031.3	46.6417
1034.6	47.4972
1037.9	48.0659
1041.19	47.6037
1044.49	46.0649
1047.79	44.6357
1051.08	42.2577
1054.37	40.8999
1057.66	38.5372
1060.95	36.7408
1064.24	35.3134
1067.53	32.0726
1070.81	28.6276
1074.1	26.8326
1077.38	26.6877
1080.66	24.3091
1083.94	21.6175
1087.22	20.3444
1090.5	19.9104
1093.78	19.6736
1097.05	21.5014
1100.33	23.2588
1103.6	25.5785
1106.87	26.3873
1110.15	28.1924
1113.41	28.2657
1116.68	28.3726
1119.95	26.6742
1123.21	26.1658
1126.48	22.9448
1129.74	19.5027
1133	18.0423
1136.26	17.5019
1139.52	16.2032
1142.78	15.0881
1146.04	13.5443
1149.29	13.0105
1152.55	13.1131
1155.8	11.6683
1159.05	9.19058
1162.3	5.79827
1165.55	5.35825
1168.8	3.67164
1172.05	3.83058
1175.29	6.93953
1178.54	8.28693
1181.78	7.07895
1185.02	7.36641
1188.26	7.98867
1191.5	9.87729
1194.74	10.2257
1197.97	11.3848
1201.21	12.8519
1204.44	13.1766
1207.68	14.4898
1210.91	17.2101
1214.14	20.5131
1217.37	23.5047
1220.6	24.9036
1223.82	28.1012
1227.05	32.5
1230.27	33.9465
1233.49	34.2782
1236.72	36.6341
1239.94	37.5212
1243.16	39.7705
1246.37	40.3458
1249.59	42.3386
1252.8	43.0174
1256.02	43.4572
1259.23	42.999
1262.44	41.8803
1265.66	40.3872
1268.87	41.8903
1272.07	42.494
1275.28	42.386
1278.48	43.6741
1281.69	44.5013
1284.89	45.0377
1288.09	47.3872
1291.3	48.7598
1294.49	50.5669
1297.69	51.3143
1300.89	54.1604
1304.09	56.7329
1307.28	57.2336
1310.47	58.4749
1313.66	61.4198
1316.86	62.9217
1320.05	63.8187
1323.23	63.926
1326.42	64.889
1329.61	64.3665
1332.79	62.9289
1335.98	61.827
1339.16	60.6327
1342.34	59.9102
1345.52	59.7901
1348.7	60.1276
1351.87	59.312
1355.05	59.7233
1358.23	58.7013
1361.4	57.1153
1364.57	56.264
1367.74	55.9006
1370.91	54.3122
1374.08	53.102
1377.25	53.5484
1380.42	52.1996
1383.58	50.9473
1386.75	48.1896
1389.91	48.0494
1393.07	46.4803
1396.23	43.8792
1399.39	42.8318
1402.55	41.3876
1405.7	41.2637
1408.86	40.0941
1412.01	41.099
1415.17	44.3844
1418.32	46.7462
1421.47	51.4071
1424.62	56.3225
1427.77	63.6804
1430.92	69.7531
1434.06	75.2955
1437.2	78.4305
1440.35	83.8015
1443.49	88.1098
1446.63	90.411
1449.77	92.3987
1452.91	92.9886
1456.05	92.9934
1459.18	91.9692
1462.32	90.7614
1465.45	90.7476
1468.59	90.6805
1471.72	88.6073
1474.85	86.146
1477.98	83.5738
1481.11	80.5198
1484.23	77.5972
1487.36	73.0674
1490.48	68.6159
1493.61	64.9613
1496.73	61.141
1499.85	59.3762
1502.97	55.3806
1506.09	48.6029
1509.2	41.3352
1512.32	36.3114
1515.44	31.7608
1518.55	25.685
1521.66	22.0635
1524.77	16.4492
1527.88	13.0706
1530.99	11.4332
1534.1	10.0078
1537.21	10.952
1540.31	12.5154
1543.42	14.568
1546.52	16.424
1549.62	17.4851
1552.72	20.5164
1555.82	21.7579
1558.92	22.8889
1562.02	22.7438
1565.11	24.5908
1568.21	25.532
1571.3	28.5434
1574.39	30.2495
1577.49	32.72
1580.58	34.4633
1583.67	36.7529
1586.75	38.9328
1589.84	41.1854
1592.93	43.5112
1596.01	43.5391
1599.09	43.9283
1602.18	44.0902
1605.26	45.1984
1608.34	46.0769
1611.41	45.4307
1614.49	45.7877
1617.57	44.8784
1620.64	44.9198
1623.72	44.9869
1626.79	44.5636
1629.86	44.8496
1632.93	47.1211
1636	48.2201
1639.07	50.0085
1642.14	53.2342
1645.2	56.9861
1648.27	59.1673
1651.33	61.2457
1654.39	61.9797
1657.45	63.7854
1660.51	62.9205
1663.57	62.3454
1666.63	59.2296
1669.69	58.3983
1672.74	55.2635
1675.79	51.3077
1678.85	47.1972
1681.9	43.103
1684.95	39.1026
1688	32.1244
1691.05	27.5956
1694.1	23.2778
1697.14	18.8703
1700.19	16.7955
1703.23	15.2959
1706.27	14.3812
1709.32	14.3435
1712.35	12.3392
1715.39	12.4342
1718.43	11.8849
1721.47	10.6867
1724.5	11.0692
1727.54	10.8
1730.57	10.5502
1733.61	11.3948
1736.64	11.1634
1739.67	11.2089
1742.7	10.5736
1745.72	10.1979
1748.75	8.74382
1751.78	6.63091
1754.8	6.3744
1757.82	4.79694
1760.85	3.51902
1763.87	2.9964
1766.89	2.72813
1769.91	2.51313
1772.92	2.24115
1775.94	1.8384
1778.96	2.35805
1781.97	1.38593
1784.98	1.69081
1788	2.45429
1791.01	2.47406
1794.01	3.53514
1797.02	4.78059
1800.03	4.41068
1803.04	4.87275
1806.04	5.08681
1809.05	6.00767
1812.05	5.07795
1815.05	4.12527
1818.05	3.27984
1821.05	2.87977
1824.05	2.57154
1827.05	1.59724
1830.04	2.27607
1833.04	2.31048
1836.03	2.64699
1839.03	3.15863
1842.02	3.27976
1845.01	3.06585
1848	3.44995
1850.99	4.86846
1853.97	4.60944
1856.96	4.35888
1859.94	4.70641
1862.93	5.41586
1865.91	4.71686
1868.89	3.25687
1871.87	4.09117
1874.85	4.38811
1877.83	6.22538
1880.81	5.87537
1882.56	6.75708
1885.55	5.14694
1888.54	5.2325
1891.52	5.02799
1894.51	5.75118
1897.49	4.93562
1900.48	5.49417
1903.46	7.32651
1906.44	7.03451
1909.42	7.20501
1912.4	8.52186
1915.38	9.15396
1918.35	9.35369
1921.33	9.7767
1924.3	8.9686
1927.28	8.82703
1930.25	9.08461
1933.22	7.11553
1936.19	7.63471
1939.16	6.70716
1942.13	9.03367
1945.09	11.1289
1948.06	11.3532
1951.03	12.1956
1953.99	12.2015
1956.95	10.9404
1959.91	10.261
1962.87	9.56871
1965.83	9.0774
1968.79	7.99957
1971.75	6.83669
1974.7	6.92369
1977.66	6.40289
1980.61	6.15101
1983.56	6.68602
1986.52	8.94941
1989.47	8.46054
1992.41	7.44016
1995.36	7.44584
1998.31	6.99387
2001.26	7.54144
2004.2	6.60341
2007.15	7.23685
2010.09	7.55278
2013.03	10.0049
2015.97	9.66946
2018.91	8.79577
2021.85	8.49032
2024.79	7.60949
2027.72	8.49452
2030.66	8.07017
2033.59	8.4952
2036.53	8.0541
2039.46	8.39686
2042.39	9.68833
2045.32	11.4885
2048.25	10.9947
2051.18	12.9484
2054.1	13.8116
2057.03	14.8539
2059.95	13.9737
2062.88	12.3661
2065.8	13.2272
2068.72	12.7453
2071.64	14.0067
2074.56	14.3597
2077.48	14.3511
2080.39	13.2809
2083.31	13.6283
2086.22	13.2871
2089.14	11.923
2092.05	11.4975
2094.96	12.4262
2097.87	12.745
2100.78	13.4184
2103.69	13.5221
2106.6	14.2548
2109.51	16.626
2112.41	16.7929
2115.32	18.1345
2118.22	18.6403
2121.12	19.8031
2124.02	20.3446
2126.92	21.4325
2129.82	21.927
2132.72	22.8967
2135.62	24.7208
2138.51	27.7932
2141.41	28.1873
2144.3	30.0521
2147.19	31.1996
2150.09	32.0832
2152.97	31.9305
2155.86	33.8186
2158.75	34.9339
2161.64	35.5129
2164.53	37.4731
2167.41	38.6146
2170.3	38.837
2173.18	39.5424
2176.06	39.9909
2178.94	41.2813
2181.82	40.0651
2184.7	39.9561
2187.58	39.1594
2190.46	37.4936
2193.33	36.6361
2196.21	34.5491
2199.08	33.7744
2201.95	31.3521
2204.83	32.7709
2207.7	31.2222
2210.57	28.3901
2213.43	27.2024
2216.3	25.473
2219.17	24.2555
2222.03	22.6263
2224.9	22.899
2227.76	22.7177
2230.62	22.7884
2233.49	21.8788
2236.34	20.5407
2239.2	19.7713
2242.06	20.3828
2244.92	19.3427
2247.78	19.6812
2250.63	19.1231
2253.48	17.1768
2256.34	15.8608
2259.19	14.8394
2262.04	14.3813
2264.89	12.4179
2267.74	12.015
2270.59	10.8889
2273.43	11.017
2276.28	10.0638
2279.12	7.38032
2281.97	6.21262
2284.81	6.0389
2287.65	5.81133
2290.49	4.83124
2293.33	4.45075
2296.17	3.25982
2299.01	4.11022
2301.84	3.98016
2304.68	5.17578
2307.51	7.69599
2310.35	8.87374
2313.18	10.5356
2316.01	9.67509
2318.84	8.88001
2321.67	9.07451
2324.5	9.47168
2327.33	9.80108
2330.15	10.8169
2332.98	10.1774
2335.8	9.42516
2338.62	8.82559
2341.45	8.29181
2344.27	6.728
2347.09	4.4281
2349.91	3.90617
2352.72	4.74171
2355.54	3.11635
2358.36	2.28087
2361.17	2.01711
2363.98	2.49844
2366.8	3.41834
2369.61	5.06195
2372.42	5.18113
2375.23	6.72613
2378.04	6.84159
2380.85	5.88405
2383.66	5.14492
2386.46	5.89309
2389.26	6.33902
2392.07	6.94441
2394.87	7.24739
2397.67	7.48492
2400.47	7.44534
2403.27	6.84691
2406.07	4.89363
2408.87	3.84599
2411.67	3.34348
2414.46	1.73115
2417.26	1.9892
2420.05	1.63468
2422.84	1.62833
2425.64	1.24735
2428.43	1.42071
2431.22	2.29352
2434.01	3.44701
2436.79	3.45474
2439.58	3.09127
2442.37	3.27699
2445.15	3.34091
2447.93	3.82058
2450.72	3.79707
2453.5	4.28154
2456.28	4.59252
2459.06	4.20552
2461.84	3.84068
2464.62	4.59202
2467.39	5.61797
2470.17	6.00847
2472.94	4.45145
2475.72	4.95382
2478.49	3.49872
2481.26	3.11394
2484.03	3.14714
2486.8	1.81319
2489.57	1.50902
2492.34	1.67826
2495.1	1.17185
2497.87	2.26569
2500.63	2.16653
2503.4	1.80648
2506.16	0.449002
2508.92	0.0317086
2511.68	0.124196
2514.44	0.176131
2517.2	-1.28394
2519.96	-1.18264
2522.72	-0.586159
2525.47	-0.0874903
2528.23	1.12211
2530.98	2.29308
2533.74	3.98555
2536.49	4.86662
2539.24	6.89909
2541.99	6.63128
2544.74	6.7388
2547.49	5.8467
2550.23	6.66504
2552.98	7.64313
2555.72	7.65981
2558.47	7.75279
2561.21	8.08559
2563.95	8.47409
2566.69	8.22534
2569.43	6.48839
2572.17	6.45315
2574.91	5.06107
2577.65	3.73206
2580.39	3.44045
2583.12	2.177
2585.85	1.881
2588.59	1.80715
2591.32	1.93679
2594.05	1.68955
2596.78	1.86762
2599.51	1.50448
2602.24	2.52656
2604.97	2.55665
2607.69	0.534107
2610.42	0.438416
2613.14	1.33721
2615.87	2.51159
2618.59	3.87833
2621.31	3.9186
2624.03	3.51832
2626.75	3.80486
2629.47	4.13113
2632.19	6.79506
2634.91	7.28939
2637.62	8.90671
2640.34	9.31432
2643.05	11.4665
2645.76	12.6745
2648.48	13.5666
2651.19	14.244
2653.9	14.2567
2656.6	14.2302
2659.31	13.9219
2662.02	14.4507
2664.73	14.408
2667.43	12.894
2670.14	12.0389
2672.84	11.3553
2675.54	11.4969
2678.24	11.8153
2680.94	11.2204
2683.64	9.64848
2686.34	8.86605
2689.04	7.88912
2691.74	7.0535
2694.43	6.41753
2697.13	7.07688
2699.82	7.60444
2702.51	9.12416
2705.21	10.1527
2707.9	11.5172
2710.58	12.7095
2713.27	14.5974
2715.96	15.0503
2718.65	15.2611
2721.33	16.5515
2724.02	17.5544
2726.71	17.3173
2729.39	17.928
2732.07	17.361
2734.75	17.6508
2737.43	17.7411
2740.11	16.9306
2742.79	15.2217
2745.47	14.9776
2748.14	14.4694
2750.82	14.1077
2753.49	13.1324
2756.17	12.306
2758.84	10.7821
2761.51	9.40584
2764.18	8.75419
2766.85	7.94371
2769.52	8.19827
2772.19	7.26126
2774.86	7.17146
2777.52	6.24658
2780.19	5.04751
2782.85	4.46942
2785.52	4.10195
2788.18	3.43906
2790.84	2.28184
2793.5	2.2914
2796.16	2.51687
2798.82	2.2607
2801.48	1.86303
2804.13	0.725903
2806.79	1.0919
2809.45	2.25708
2812.1	2.95204
2814.75	3.8834
2817.41	4.58022
2820.06	7.29441
2822.71	10.9785
2825.36	14.8445
2828	19.3676
2830.65	23.7409
2833.3	29.6859
2835.94	36.5964
2838.59	44.5016
2841.23	53.0439
2843.87	61.6461
2846.52	72.4071
2849.16	84.7988
2851.8	95.9153
2854.44	108.729
2857.08	119.683
2859.71	130.181
2862.35	139.777
2864.98	148.94
2867.62	157.091
2870.25	164.321
2872.88	172.022
2875.52	176.606
2878.15	182.325
2880.78	188.582
2883.41	193.112
2886.03	197.921
2888.66	200.329
2891.29	202.825
2893.91	205.244
2896.54	207.376
2899.16	212.535
2901.78	218.319
2904.4	224.356
2907.02	231.046
2909.64	239.459
2912.26	249.779
2914.88	259.676
2917.5	269.42
2920.11	278.975
2922.73	287.116
2925.34	294.434
2927.96	299.983
2930.57	303.447
2933.18	304.555
2935.79	303.192
2938.4	301.038
2941.01	296.209
2943.62	289.87
2946.22	281.859
2948.83	270.013
2951.43	259.783
2954.04	248.048
2956.64	236.064
2959.24	223.91
2961.84	212.354
2964.45	201.276
2967.05	190.103
2969.64	179.873
2972.24	169.144
2974.84	160.296
2977.43	151.451
2980.03	142.742
2982.62	134.096
2985.22	124.025
2987.81	113.831
2990.4	102.943
2992.99	92.7494
2995.58	81.6994
2998.17	73.8857
3000.76	64.1167
3003.34	56.2936
3005.93	46.7502
3008.52	41.1652
3011.1	33.5917
3013.68	28.2561
3016.27	24.3181
3018.85	20.3577
3021.43	16.8317
3024.01	13.3875
3026.59	10.0072
3029.16	8.44118
3031.74	6.36125
3034.32	4.56154
3036.89	3.8585
3039.47	3.44136
3042.04	2.91345
3044.61	2.60297
3047.18	2.47313
3049.75	2.32137
3052.32	2.83038
3054.89	2.47392
3057.46	2.87759
3060.03	3.91172
3062.59	3.72888
3065.16	3.91835
3067.72	4.2415
3070.29	5.3096
3072.85	6.57108
3075.41	6.54334
3077.97	7.70181
3080.53	7.76708
3083.09	7.66197
3085.65	7.16809
3088.21	7.03879
3090.76	7.80095
3093.32	8.39224
3095.87	10.0419
3098.43	10.834
3100.98	12.1562
3103.53	13.1032
3106.08	13.9391
3108.63	14.2354
3111.18	15.4577
3113.73	16.4159
3116.28	16.676
3118.83	18.047
3121.37	18.6268
3123.92	19.4276
3126.46	20.5099
3129	21.2323
3131.55	23.1351
3134.09	25.2592
3136.63	25.5332
3139.17	25.9819
3141.71	27.7214
3144.24	29.3815
3146.78	31.3882
3149.32	33.3462