File: data/Raman/poly_smoothed/Mb_10_14_22_1x_45s_532 nm_x100_100%_600 gr_mm_01.txt
#Acq. time (s)=	45
#Accumulations=	2
#Range (cm-¹)=	200...3150
#Windows=	2
#Auto scanning=	Off
#Autofocus=	Off
#Macrospot=	Off
#AutoExposure=	Off
#Spike filter=	Multiple accum.
#Delay time (s)=	0
#Binning=	1
#Readout mode=	Signal
#DeNoise=	Off
#ICS correction=	On
#Dark correction=	Off
#Inst. Process=	Off
#Detector Gain=	Best Dynamic Range
#Detector ADC=	20 kHz
#Detector temperature (°C)=	-69.85
#Instrument=	LabRAM HR Evol
#Detector=	Synapse
#Objective=	x100
#Grating=	600 gr/mm
#ND Filter=	100%
#Laser (nm)=	532
#Hole=	100.021
#Range=	Auto
#Laser Pol.=	No
#Raman. Pol.=	No
#Laser Pol. (°)=	-0.0007625
#Raman Pol. (°)=	89.9995
#Collection=	Microscope
#StageXY=	Marzhauser
#StageZ=	Marzhauser
#X (µm)=	-620.1
#Y (µm)=	-1585.6
#Z (µm)=	89.85
#Full time(mm:ss)=	3:19
#Project=
#Sample=
#Site=
#Title=	Mb_10_14_22_2x_45s_532 nm_x100_100%_600 gr_mm
#Remark=
#Date=	11.07.2022 10:12
#Acquired=	11.07.2022 10:12:25
#Base:Fit=	10.08.2022 10:21:11
#Base:Sub=	10.08.2022 10:21:41
#Filter:Polynom=	16.08.2022 10:17:53
#AxisType[0]=Intens
#AxisUnit[0]=Cnt
#AxisType[1]=Spectr
#AxisUnit[1]=1/cm
200.388	13.0441
204.019	12.063
207.646	7.95742
211.274	5.48602
214.899	5.11506
218.524	6.7206
222.146	8.72441
225.766	11.4982
229.388	13.6361
233.005	14.8827
236.621	16.063
240.236	18.0988
243.852	20.165
247.464	19.7654
251.074	20.883
254.683	21.8563
258.291	22.2911
261.897	24.22
265.504	26.1475
269.108	27.5644
272.71	29.2889
276.311	29.0606
279.91	27.9823
283.508	26.4041
287.105	24.9266
290.698	22.6397
294.291	20.5721
297.884	19.4713
301.475	18.5778
305.064	17.5776
308.652	17.2245
312.237	15.4448
315.822	16.1745
319.406	15.0709
322.987	14.0446
326.568	13.9328
330.148	12.6085
333.724	10.6445
337.301	8.95284
340.875	10.9981
344.449	10.6289
348.02	12.6646
351.592	14.6108
355.16	16.6094
358.728	18.0652
362.294	20.1293
365.858	21.9369
369.422	22.323
372.983	22.7739
376.543	22.653
380.102	25.2189
383.661	25.4145
387.216	26.5642
390.771	27.4271
394.324	27.5627
397.875	28.1045
401.425	26.6648
404.974	26.7438
408.524	26.1225
412.07	25.4456
415.614	23.5303
419.156	21.0132
422.698	20.4383
426.238	17.8453
429.777	16.189
433.315	13.4567
436.852	11.4912
440.387	11.3542
443.919	11.264
447.451	12.5139
450.982	13.2896
454.512	13.0617
458.038	13.411
461.565	15.4688
465.091	18.3084
468.613	18.4519
472.136	19.0951
475.655	20.3223
479.176	18.6169
482.692	18.7017
486.21	19.8667
489.724	21.3569
493.237	23.6787
496.75	25.0425
500.26	25.1381
503.769	25.8238
507.279	24.9548
510.785	21.7243
514.289	21.7628
517.793	21.0805
521.297	23.2604
524.797	24.8613
528.297	26.228
531.795	24.7624
535.291	24.3457
538.787	22.3175
542.281	22.8675
545.773	22.2591
549.264	21.0949
552.754	18.9981
556.243	17.0594
559.73	16.1062
563.216	14.0369
566.701	12.2692
570.182	11.9193
573.664	12.2921
577.145	11.1031
580.624	10.7362
584.1	8.73736
587.577	6.65084
591.052	5.45606
594.524	3.02882
597.997	4.45285
601.466	5.85424
604.936	5.71202
608.403	5.74
611.87	5.01784
615.334	3.52143
618.799	3.80476
622.26	3.99079
625.72	4.95715
629.181	6.68643
632.638	7.58054
636.095	8.11035
639.551	10.0151
643.005	11.3171
646.457	12.4361
649.908	13.1988
653.357	15.2542
656.806	17.3529
660.253	16.9074
663.7	17.7226
667.145	18.8148
670.588	19.4948
674.027	20.3295
677.468	21.4114
680.907	22.7494
684.345	23.8648
687.781	24.3938
691.216	25.2002
694.65	26.2243
698.081	26.9464
701.512	26.6418
704.942	27.6964
708.371	28.5199
711.796	28.6012
715.222	28.2462
718.645	29.8276
722.068	30.5193
725.49	31.74
728.909	33.1225
732.329	34.1216
735.745	35.1136
739.16	36.5776
742.576	37.6399
745.988	39.1207
749.401	43.349
752.811	45.2465
756.22	47.2813
759.627	48.3386
763.035	51.6244
766.44	55.4533
769.843	58.8066
773.245	61.163
776.646	61.5954
780.046	63.495
783.444	64.7029
786.841	66.9067
790.237	67.8744
793.631	67.733
797.024	70.1476
800.416	72.5815
803.807	72.6122
807.196	72.5983
810.584	72.5845
813.971	72.3266
817.354	71.3887
820.739	71.4804
824.122	70.5237
827.503	69.6528
830.882	70.5931
834.261	69.9479
837.637	67.393
841.013	64.5682
844.389	64.1233
847.761	62.4919
851.131	60.5085
854.503	57.3894
857.871	55.0657
861.24	53.8181
864.606	53.6776
867.97	53.4748
871.336	51.5549
874.698	47.7683
878.058	48.483
881.418	47.7422
884.778	45.7449
888.135	44.8797
891.49	44.0963
894.845	42.584
898.198	41.6294
901.55	41.1442
904.901	40.9372
908.25	40.5847
911.598	39.6338
914.945	38.0524
918.291	37.5676
921.635	37.5464
924.978	37.7631
928.318	37.0503
931.659	37.2052
934.998	36.4875
938.336	36.2779
941.671	37.1247
945.007	36.1435
948.339	35.8081
951.672	34.8718
955.004	33.0403
958.333	32.2228
961.662	32.3793
964.989	32.571
968.315	31.9536
971.639	30.3702
974.962	30.4223
978.285	29.8422
981.605	28.0651
984.924	27.4314
988.243	25.8599
991.56	25.6597
994.875	25.0315
998.188	24.4843
1001.5	25.0107
1004.81	24.8773
1008.12	22.9639
1011.43	21.9564
1014.74	22.4099
1018.05	21.5202
1021.35	21.7454
1024.65	20.6113
1027.96	20.7282
1031.26	21.4212
1034.56	20.828
1037.86	21.0254
1041.16	19.6164
1044.45	19.8894
1047.75	19.7898
1051.04	19.3026
1054.33	18.6538
1057.62	18.0711
1060.91	16.5806
1064.2	14.7093
1067.49	15.4919
1070.77	14.282
1074.06	15.1678
1077.34	12.6263
1080.62	13.0928
1083.91	11.0413
1087.18	10.1987
1090.46	9.30643
1093.74	8.48394
1097.02	7.54172
1100.29	6.60699
1103.56	6.65673
1106.84	6.22916
1110.11	6.76949
1113.38	6.35833
1116.64	5.16393
1119.91	4.80069
1123.18	5.55372
1126.44	6.43945
1129.7	5.93629
1132.97	6.43987
1136.23	6.59232
1139.49	8.29389
1142.74	8.25451
1146	8.47764
1149.26	9.43979
1152.51	8.5711
1155.76	9.63334
1159.01	9.70586
1162.27	9.78128
1165.51	7.99658
1168.76	8.61652
1172.01	8.84959
1175.25	8.99813
1178.5	9.50572
1181.74	11.6912
1184.98	11.6386
1188.22	13.531
1191.46	13.4085
1194.7	13.5519
1197.94	14.5363
1201.17	14.7995
1204.41	16.0205
1207.64	16.839
1210.87	19.8914
1214.1	21.998
1217.33	21.8634
1220.56	22.9131
1223.79	22.5955
1227.01	22.5728
1230.23	22.7881
1233.46	23.3818
1236.68	24.5052
1239.9	24.0509
1243.12	23.9377
1246.34	25.972
1249.55	27.4889
1252.77	28.7865
1255.98	27.9087
1259.2	28.6475
1262.41	28.8272
1265.62	28.4287
1268.83	29.6621
1272.03	28.783
1275.24	30.1056
1278.45	32.8325
1281.65	34.8846
1284.85	35.9041
1288.06	37.2025
1291.26	38.9907
1294.46	40.9737
1297.66	42.6335
1300.85	43.828
1304.05	43.5384
1307.24	43.8627
1310.43	46.2297
1313.63	46.5869
1316.82	47.9501
1320.01	49.1749
1323.2	49.3482
1326.38	49.7193
1329.57	48.2634
1332.76	46.9994
1335.94	45.0028
1339.12	42.3974
1342.3	41.0901
1345.48	40.722
1348.66	39.3686
1351.84	37.9354
1355.01	38.9083
1358.19	37.5522
1361.36	36.6729
1364.53	34.4026
1367.71	35.5288
1370.88	36.2533
1374.04	37.4008
1377.21	37.3936
1380.38	37.7333
1383.54	37.1305
1386.71	37.843
1389.87	37.864
1393.03	37.1863
1396.19	38.0981
1399.35	36.2063
1402.51	34.6833
1405.67	34.0148
1408.82	34.291
1411.98	33.8397
1415.13	34.608
1418.28	37.1633
1421.43	38.5921
1424.58	40.3804
1427.73	42.0337
1430.88	45.1205
1434.02	47.8216
1437.17	51.0265
1440.31	53.8034
1443.45	56.1239
1446.6	59.9844
1449.74	63.4035
1452.87	63.885
1456.01	62.7562
1459.15	61.7285
1462.28	60.8128
1465.42	59.9131
1468.55	58.4444
1471.68	57.7228
1474.81	56.2754
1477.94	53.9433
1481.07	52.4205
1484.2	52.6145
1487.32	51.6046
1490.45	49.8819
1493.57	49.3335
1496.69	47.3833
1499.81	44.7671
1502.93	42.0608
1506.05	39.7602
1509.17	36.6746
1512.28	33.6098
1515.4	30.7467
1518.51	28.2561
1521.63	26.8012
1524.74	25.5522
1527.85	22.5687
1530.96	21.2932
1534.06	21.836
1537.17	21.5917
1540.28	21.7986
1543.38	22.7873
1546.48	25.3921
1549.59	26.6958
1552.69	27.2551
1555.79	28.943
1558.88	30.4847
1561.98	32.4574
1565.08	33.643
1568.17	34.9839
1571.27	35.8611
1574.36	36.2548
1577.45	36.2317
1580.54	35.7554
1583.63	36.4283
1586.72	37.1582
1589.8	37.7436
1592.89	38.1801
1595.97	39.1824
1599.06	38.469
1602.14	38.488
1605.22	40.069
1608.3	40.2232
1611.38	39.0045
1614.46	38.6294
1617.53	38.7762
1620.61	39.4801
1623.68	38.1378
1626.75	38.2567
1629.82	38.0149
1632.9	37.5193
1635.96	36.2909
1639.03	36.4844
1642.1	36.9882
1645.16	37.5408
1648.23	37.931
1651.29	38.6602
1654.36	38.9191
1657.42	39.1874
1660.48	39.3
1663.53	37.3341
1666.59	35.8425
1669.65	34.2506
1672.7	32.5546
1675.76	29.8213
1678.81	27.6885
1681.86	25.1043
1684.91	21.3337
1687.96	18.705
1691.01	17.0688
1694.06	14.251
1697.11	13.1717
1700.15	11.0962
1703.2	8.69233
1706.24	6.17837
1709.28	3.98637
1712.32	2.82298
1715.36	2.28346
1718.4	2.56818
1721.43	2.12638
1724.47	2.55034
1727.5	3.2682
1730.54	3.61512
1733.57	3.95417
1736.6	3.80608
1739.63	4.28718
1742.66	3.5993
1745.69	4.1494
1748.72	4.56995
1751.74	3.77095
1754.77	3.75399
1757.79	4.27193
1760.81	4.7647
1763.83	5.637
1766.85	5.9205
1769.87	5.38835
1772.89	4.71842
1775.91	4.7067
1778.92	3.86403
1781.94	3.83914
1784.95	3.9266
1787.96	4.09921
1790.97	4.55359
1793.98	5.29657
1796.99	5.8651
1800	6.17375
1803	5.46851
1806.01	5.84632
1809.01	5.43709
1812.02	4.8219
1815.02	4.47666
1818.02	4.62312
1821.02	5.15069
1824.02	4.26344
1827.01	3.89112
1830.01	2.90466
1833	3.49569
1836	3.47504
1838.99	2.77242
1841.98	2.75577
1844.97	1.64051
1847.96	1.837
1850.95	2.2533
1853.94	3.29005
1856.92	3.85766
1859.91	4.38033
1862.89	4.53534
1865.88	5.53068
1868.86	5.41445
1871.84	5.78688
1874.82	6.30974
1877.8	6.77126
1880.77	6.48621
1882.52	6.76375
1885.51	6.94389
1888.5	7.6786
1891.49	6.27596
1894.47	5.58385
1897.46	5.22148
1900.44	4.22036
1903.42	3.61418
1906.4	4.03508
1909.38	3.16062
1912.36	2.66169
1915.34	1.39522
1918.32	1.011
1921.29	1.4752
1924.27	2.95725
1927.24	3.39547
1930.21	2.86657
1933.18	2.78034
1936.15	2.81834
1939.12	2.50561
1942.09	2.59698
1945.06	3.41961
1948.02	4.07324
1950.99	3.73081
1953.95	4.17795
1956.91	4.12675
1959.87	3.96192
1962.84	2.64499
1965.79	2.06114
1968.75	2.98819
1971.71	2.9513
1974.66	2.96702
1977.62	3.08299
1980.57	3.11459
1983.53	2.95888
1986.48	2.80685
1989.43	3.21743
1992.38	4.06093
1995.33	4.64062
1998.27	4.70058
2001.22	3.88977
2004.16	3.58869
2007.11	2.76773
2010.05	2.92272
2012.99	4.52569
2015.93	5.63297
2018.87	6.571
2021.81	7.74299
2024.75	7.69611
2027.69	8.43362
2030.62	8.21967
2033.56	10.0981
2036.49	10.9089
2039.42	11.8386
2042.35	12.7098
2045.28	13.4652
2048.21	14.1843
2051.14	14.5748
2054.06	15.7306
2056.99	15.5887
2059.92	15.4001
2062.84	15.5861
2065.76	15.9727
2068.68	15.6176
2071.6	14.2026
2074.52	12.662
2077.44	11.7921
2080.36	10.5774
2083.27	10.2633
2086.19	10.5675
2089.1	10.2651
2092.01	10.1731
2094.93	9.17099
2097.84	8.81913
2100.75	8.81011
2103.66	8.83433
2106.56	9.57428
2109.47	9.12316
2112.37	8.30946
2115.28	8.53803
2118.18	9.53114
2121.09	11.0097
2123.99	12.2296
2126.89	12.5855
2129.79	13.1642
2132.68	13.9945
2135.58	15.2234
2138.48	15.9172
2141.37	15.7035
2144.26	16.3242
2147.16	17.1327
2150.05	17.5095
2152.94	18.5249
2155.83	19.8786
2158.72	21.2322
2161.6	22.3458
2164.49	22.7838
2167.38	23.0764
2170.26	24.2663
2173.14	24.038
2176.03	24.6832
2178.91	24.2903
2181.79	23.8666
2184.67	24.4743
2187.54	24.6633
2190.42	24.7422
2193.3	24.6214
2196.17	23.3111
2199.05	22.294
2201.92	20.837
2204.79	20.1943
2207.66	19.4113
2210.53	18.4515
2213.4	17.1556
2216.27	17.0217
2219.13	15.121
2222	13.6853
2224.86	13.6152
2227.72	13.3108
2230.59	12.7061
2233.45	12.2872
2236.31	12.1853
2239.17	11.7513
2242.03	11.8606
2244.88	10.5914
2247.74	9.61231
2250.59	10.0201
2253.45	10.3286
2256.3	9.75692
2259.15	9.4801
2262	9.00318
2264.85	8.7331
2267.7	7.8989
2270.55	7.04136
2273.4	7.22749
2276.24	8.21088
2279.09	8.1075
2281.93	8.39072
2284.77	7.57862
2287.61	6.57324
2290.46	7.02567
2293.29	7.00397
2296.13	7.53047
2298.97	8.68364
2301.81	9.57799
2304.64	10.5629
2307.48	10.5565
2310.31	10.2908
2313.14	10.3235
2315.97	9.9079
2318.8	10.1575
2321.63	9.90152
2324.46	8.48012
2327.29	8.99211
2330.12	9.32755
2332.94	9.22888
2335.76	8.74048
2338.59	8.30338
2341.41	8.87604
2344.23	9.38788
2347.05	8.24952
2349.87	6.96342
2352.69	6.12294
2355.5	6.09189
2358.32	6.76156
2361.14	6.65642
2363.95	7.16119
2366.76	7.55379
2369.58	7.75285
2372.39	7.17161
2375.2	6.70364
2378	5.6421
2380.81	4.65943
2383.62	4.90208
2386.42	4.71967
2389.23	4.77903
2392.03	5.43196
2394.84	5.92493
2397.64	6.43423
2400.44	6.344
2403.24	5.58415
2406.04	5.08521
2408.83	5.54362
2411.63	5.67129
2414.43	5.35798
2417.22	4.65835
2420.02	4.80856
2422.81	4.44827
2425.6	4.49674
2428.39	4.28026
2431.18	3.30998
2433.97	3.30898
2436.76	2.79558
2439.54	1.49327
2442.33	1.76055
2445.11	0.664878
2447.9	0.744436
2450.68	1.13908
2453.46	1.45847
2456.24	1.27429
2459.02	1.24922
2461.8	1.41972
2464.58	1.07261
2467.36	0.106973
2470.13	0.654744
2472.91	1.0725
2475.68	1.9143
2478.45	2.5725
2481.22	2.4596
2484	1.7854
2486.77	2.22951
2489.54	2.69792
2492.3	3.30507
2495.07	4.56663
2497.84	3.97123
2500.6	3.93609
2503.36	3.61032
2506.13	4.13319
2508.89	4.84878
2511.65	5.23137
2514.41	5.05188
2517.17	5.88448
2519.93	5.03913
2522.68	5.66112
2525.44	5.50557
2528.19	4.82467
2530.95	4.98591
2533.7	4.80652
2536.45	4.32049
2539.2	3.55222
2541.95	3.11166
2544.7	2.335
2547.45	2.23897
2550.2	1.80105
2552.94	1.67678
2555.69	1.69359
2558.43	1.02008
2561.17	0.973385
2563.92	0.0467636
2566.66	0.359362
2569.4	1.25768
2572.14	1.63596
2574.88	2.69097
2577.61	3.61288
2580.35	4.56887
2583.09	5.09425
2585.82	5.41894
2588.55	5.41431
2591.28	6.22196
2594.02	5.62267
2596.75	6.1352
2599.48	5.62073
2602.2	3.95623
2604.93	3.82492
2607.66	3.55791
2610.38	3.64933
2613.11	3.96019
2615.83	4.1565
2618.56	4.29602
2621.28	3.38602
2624	2.67968
2626.72	2.54029
2629.44	3.06069
2632.15	3.72286
2634.87	4.23551
2637.59	4.16315
2640.3	4.52658
2643.02	5.69027
2645.73	5.44602
2648.44	5.06257
2651.15	5.71386
2653.86	5.41768
2656.57	5.34899
2659.28	6.29407
2661.99	6.30413
2664.69	6.60827
2667.4	6.49257
2670.1	6.69381
2672.81	7.02211
2675.51	7.39907
2678.21	8.14877
2680.91	8.10119
2683.61	8.72504
2686.31	8.33361
2689	8.37461
2691.7	8.62206
2694.4	8.70578
2697.09	9.04943
2699.79	7.792
2702.48	8.25695
2705.17	8.48662
2707.86	7.80549
2710.55	7.7691
2713.24	6.83939
2715.93	5.78707
2718.61	5.98236
2721.3	5.47543
2723.99	5.11971
2726.67	5.67873
2729.35	5.45693
2732.04	4.41092
2734.72	3.90519
2737.4	2.94974
2740.08	3.20579
2742.76	4.03349
2745.43	4.18097
2748.11	4.62367
2750.79	6.17082
2753.46	6.39393
2756.13	6.22884
2758.81	5.75898
2761.48	6.79146
2764.15	6.07188
2766.82	6.67844
2769.49	6.93885
2772.16	6.18161
2774.82	4.88293
2777.49	4.74576
2780.16	4.00092
2782.82	4.08168
2785.48	3.19316
2788.15	2.41658
2790.81	1.37852
2793.47	1.11076
2796.13	0.759923
2798.79	-0.100639
2801.44	-0.303692
2804.1	-1.26975
2806.76	-0.815909
2809.41	-1.12895
2812.07	-0.945888
2814.72	0.530876
2817.37	1.13402
2820.02	1.00156
2822.67	2.25309
2825.32	4.26574
2827.97	6.06668
2830.62	8.37027
2833.26	11.454
2835.91	13.1036
2838.55	16.7735
2841.2	20.33
2843.84	24.4547
2846.48	29.6636
2849.12	35.8415
2851.76	41.064
2854.4	46.7225
2857.04	52.7104
2859.68	57.66
2862.32	63.6345
2864.95	68.0307
2867.58	72.0662
2870.22	75.9969
2872.85	80.3111
2875.48	83.463
2878.11	86.7442
2880.74	89.5073
2883.37	91.4992
2886	93.5286
2888.63	96.3143
2891.25	98.8064
2893.88	101.334
2896.5	105.096
2899.13	108.003
2901.75	112.77
2904.37	116.312
2906.99	121.387
2909.61	128.436
2912.23	134.133
2914.85	140.863
2917.46	145.492
2920.08	150.372
2922.7	154.583
2925.31	157.233
2927.92	159.031
2930.53	159.671
2933.15	158.432
2935.76	157.214
2938.37	153.579
2940.98	149.36
2943.58	145.025
2946.19	139.829
2948.8	135.327
2951.4	129.186
2954.01	123.547
2956.61	117.74
2959.21	112.146
2961.81	106.141
2964.41	99.7512
2967.01	93.9953
2969.61	88.8893
2972.21	85.1495
2974.81	80.6266
2977.4	75.576
2980	69.9484
2982.59	64.8605
2985.18	59.263
2987.78	52.7743
2990.37	46.2604
2992.96	39.852
2995.55	34.4366
2998.14	29.5305
3000.72	24.9214
3003.31	20.5974
3005.9	16.5054
3008.48	12.352
3011.07	10.431
3013.65	6.26759
3016.23	3.47672
3018.81	3.07212
3021.39	1.77988
3023.97	1.04291
3026.55	1.24227
3029.13	1.7614
3031.71	2.49298
3034.28	3.30823
3036.86	4.61215
3039.43	5.35164
3042.01	5.84812
3044.58	6.54379
3047.15	7.24251
3049.72	6.8406
3052.29	7.36917
3054.86	7.42282
3057.43	7.7299
3060	7.78748
3062.56	6.89578
3065.13	6.08843
3067.69	6.06623
3070.25	4.16712
3072.82	3.42963
3075.38	2.34977
3077.94	1.92911
3080.5	0.865952
3083.06	0.411031
3085.62	0.235368
3088.17	0.643492
3090.73	0.520313
3093.29	0.336027
3095.84	0.611147
3098.4	1.62126
3100.95	2.7337
3103.5	3.43428
3106.05	3.65877
3108.6	4.30337
3111.15	5.18404
3113.7	7.64371
3116.25	9.04725
3118.79	10.4446
3121.34	11.5702
3123.88	13.6732
3126.43	15.5812
3128.97	17.3365
3131.51	19.298
3134.05	20.7579
3136.59	22.9269
3139.14	25.1314
3141.67	27.0606
3144.21	29.394
3146.75	31.2916
3149.28	31.6437