File: data/Raman/poly_smoothed/Mb_10_14_50_1x_45s_532 nm_x100_100%_600 gr_mm_01.txt
#Acq. time (s)=	45
#Accumulations=	2
#Range (cm-¹)=	200...3150
#Windows=	2
#Auto scanning=	Off
#Autofocus=	Off
#Macrospot=	Off
#AutoExposure=	Off
#Spike filter=	Multiple accum.
#Delay time (s)=	0
#Binning=	1
#Readout mode=	Signal
#DeNoise=	Off
#ICS correction=	On
#Dark correction=	Off
#Inst. Process=	Off
#Detector Gain=	Best Dynamic Range
#Detector ADC=	20 kHz
#Detector temperature (°C)=	-69.85
#Instrument=	LabRAM HR Evol
#Detector=	Synapse
#Objective=	x100
#Grating=	600 gr/mm
#ND Filter=	100%
#Laser (nm)=	532
#Hole=	100.021
#Range=	Auto
#Laser Pol.=	No
#Raman. Pol.=	No
#Laser Pol. (°)=	-0.0007625
#Raman Pol. (°)=	89.9995
#Collection=	Microscope
#StageXY=	Marzhauser
#StageZ=	Marzhauser
#X (µm)=	-645.1
#Y (µm)=	-1709.9
#Z (µm)=	89.45
#Full time(mm:ss)=	3:19
#Project=
#Sample=
#Site=
#Title=	Mb_10_14_50_2x_45s_532 nm_x100_100%_600 gr_mm
#Remark=
#Date=	11.07.2022 12:26
#Acquired=	11.07.2022 12:26:56
#Edit:Spike=	11.07.2022 12:30:37
#Base:Fit=	10.08.2022 10:21:11
#Base:Sub=	10.08.2022 10:21:41
#Filter:Polynom=	16.08.2022 10:17:53
#AxisType[0]=Intens
#AxisUnit[0]=Cnt
#AxisType[1]=Spectr
#AxisUnit[1]=1/cm
200.388	9.17052
204.019	4.52154
207.646	4.7868
211.274	3.09375
214.899	1.51898
218.524	2.07501
222.146	3.1896
225.766	5.93475
229.388	6.57849
233.005	7.59278
236.621	9.31011
240.236	11.541
243.852	12.1749
247.464	13.5847
251.074	15.6988
254.683	15.9893
258.291	15.9625
261.897	14.6648
265.504	14.3251
269.108	15.0999
272.71	13.8981
276.311	12.9134
279.91	11.8399
283.508	11.8992
287.105	11.1693
290.698	9.68473
294.291	6.84061
297.884	4.66669
301.475	4.32675
305.064	4.72436
308.652	5.16921
312.237	5.88673
315.822	4.03181
319.406	4.20231
322.987	4.13427
326.568	5.10605
330.148	5.26509
333.724	5.93435
337.301	6.77656
340.875	5.51399
344.449	5.51494
348.02	4.97785
351.592	6.23199
355.16	9.63671
358.728	11.7327
362.294	13.8715
365.858	14.0793
369.422	15.5555
372.983	16.5906
376.543	15.9453
380.102	16.0795
383.661	17.146
387.216	16.9255
390.771	16.5974
394.324	16.632
397.875	15.0008
401.425	14.3016
404.974	12.1696
408.524	12.4875
412.07	12.1742
415.614	10.0677
419.156	9.56281
422.698	8.18408
426.238	7.6445
429.777	6.72053
433.315	6.45855
436.852	6.67344
440.387	7.43157
443.919	7.41982
447.451	8.72342
450.982	8.94097
454.512	9.96925
458.038	10.3889
461.565	10.567
465.091	11.4399
468.613	11.4182
472.136	12.5744
475.655	12.3816
479.176	12.9496
482.692	13.0595
486.21	12.3305
489.724	13.0058
493.237	14.121
496.75	14.9824
500.26	14.8031
503.769	14.4697
507.279	15.4536
510.785	15.0065
514.289	14.4695
517.793	15.4334
521.297	15.6748
524.797	16.4065
528.297	16.2477
531.795	16.5955
535.291	16.9435
538.787	16.4701
542.281	15.5016
545.773	14.9982
549.264	14.5393
552.754	12.9507
556.243	11.2084
559.73	11.1055
563.216	9.37731
566.701	9.07594
570.182	7.69176
573.664	7.83443
577.145	6.3678
580.624	6.31204
584.1	5.55542
587.577	4.7391
591.052	3.40582
594.524	1.53501
597.997	1.36874
601.466	0.885445
604.936	1.33272
608.403	2.27307
611.87	4.06537
615.334	5.59455
618.799	6.63035
622.26	8.40638
625.72	9.25212
629.181	11.2
632.638	13.4882
636.095	14.6072
639.551	15.3431
643.005	17.2152
646.457	19.3504
649.908	21.1683
653.357	21.2118
656.806	21.7454
660.253	23.4147
663.7	23.7331
667.145	24.7073
670.588	25.7045
674.027	25.6119
677.468	26.3336
680.907	28.3702
684.345	31.2028
687.781	33.1397
691.216	35.02
694.65	36.8764
698.081	37.638
701.512	39.2007
704.942	38.4701
708.371	38.5961
711.796	38.8434
715.222	38.6623
718.645	37.6964
722.068	38.1586
725.49	38.1818
728.909	38.2235
732.329	39.0881
735.745	39.2724
739.16	39.7464
742.576	41.5506
745.988	42.7995
749.401	45.3858
752.811	49.4214
756.22	52.7159
759.627	56.8961
763.035	60.8873
766.44	62.8084
769.843	66.5276
773.245	68.1248
776.646	71.9542
780.046	74.2255
783.444	76.0989
786.841	77.4872
790.237	79.6915
793.631	81.227
797.024	80.3892
800.416	81.1982
803.807	81.3325
807.196	81.1542
810.584	79.3537
813.971	79.1265
817.354	77.535
820.739	76.3586
824.122	75.0017
827.503	73.9304
830.882	73.4786
834.261	73.1202
837.637	72.3102
841.013	71.5323
844.389	71.4264
847.761	69.271
851.131	69.0393
854.503	67.5967
857.871	66.1218
861.24	66.3374
864.606	64.5327
867.97	63.6401
871.336	63.3319
874.698	60.4012
878.058	58.0773
881.418	56.2586
884.778	55.819
888.135	54.5132
891.49	54.2118
894.845	52.1807
898.198	51.0256
901.55	49.7483
904.901	49.005
908.25	50.8222
911.598	49.2416
914.945	49.386
918.291	48.8524
921.635	48.9138
924.978	49.6138
928.318	48.6214
931.659	46.8238
934.998	46.4894
938.336	45.2094
941.671	45.152
945.007	44.2087
948.339	43.4909
951.672	43.5768
955.004	42.7846
958.333	42.4474
961.662	40.829
964.989	42.1551
968.315	41.2957
971.639	41.4255
974.962	39.8526
978.285	39.2741
981.605	37.7461
984.924	36.5265
988.243	35.3631
991.56	33.3894
994.875	31.597
998.188	30.6347
1001.5	31.6274
1004.81	31.4998
1008.12	29.5077
1011.43	29.1059
1014.74	27.8107
1018.05	29.107
1021.35	28.9421
1024.65	30.1066
1027.96	30.1141
1031.26	30.5555
1034.56	30.1811
1037.86	28.1064
1041.16	28.435
1044.45	28.2634
1047.75	28.869
1051.04	28.8451
1054.33	26.9327
1057.62	26.0712
1060.91	22.8635
1064.2	20.4878
1067.49	17.6194
1070.77	16.545
1074.06	16.0292
1077.34	16.718
1080.62	15.7765
1083.91	14.749
1087.18	13.2477
1090.46	13.7218
1093.74	14.2433
1097.02	15.3091
1100.29	15.4578
1103.56	15.3276
1106.84	14.0933
1110.11	12.7402
1113.38	12.0237
1116.64	12.3128
1119.91	12.1299
1123.18	12.8245
1126.44	10.947
1129.7	11.2429
1132.97	9.54582
1136.23	6.91396
1139.49	6.68672
1142.74	6.13333
1146	3.94588
1149.26	5.21266
1152.51	6.25529
1155.76	6.16991
1159.01	6.6788
1162.27	6.20865
1165.51	6.82506
1168.76	8.32883
1172.01	9.13879
1175.25	9.53669
1178.5	9.88469
1181.74	9.50492
1184.98	10.7632
1188.22	11.1508
1191.46	13.2103
1194.7	13.7392
1197.94	13.8746
1201.17	14.7611
1204.41	14.8627
1207.64	15.4682
1210.87	15.6445
1214.1	15.3075
1217.33	16.6604
1220.56	17.2424
1223.79	16.4145
1227.01	17.9868
1230.23	18.9023
1233.46	19.0703
1236.68	19.4643
1239.9	20.0126
1243.12	19.9753
1246.34	20.527
1249.55	20.7418
1252.77	19.2761
1255.98	19.7245
1259.2	20.14
1262.41	20.687
1265.62	20.6524
1268.83	21.0111
1272.03	19.972
1275.24	18.6762
1278.45	19.1104
1281.65	19.7856
1284.85	20.126
1288.06	21.6006
1291.26	21.1521
1294.46	21.7349
1297.66	22.0415
1300.85	23.3163
1304.05	23.8828
1307.24	25.3527
1310.43	26.0899
1313.63	28.1544
1316.82	29.7596
1320.01	28.7804
1323.2	29.375
1326.38	29.9812
1329.57	28.9048
1332.76	27.9915
1335.94	26.8128
1339.12	26.662
1342.3	24.8783
1345.48	22.3919
1348.66	21.729
1351.84	20.0427
1355.01	19.7794
1358.19	19.3708
1361.36	19.3265
1364.53	19.5871
1367.71	18.757
1370.88	18.0728
1374.04	18.547
1377.21	18.9187
1380.38	18.8407
1383.54	17.9194
1386.71	19.0287
1389.87	19.9604
1393.03	20.764
1396.19	20.3992
1399.35	21.277
1402.51	22.2691
1405.67	21.7085
1408.82	21.7326
1411.98	22.0227
1415.13	23.3618
1418.28	24.7694
1421.43	25.0544
1424.58	27.1889
1427.73	29.4918
1430.88	31.9925
1434.02	33.5662
1437.17	35.3
1440.31	37.8799
1443.45	38.4951
1446.6	40.7604
1449.74	41.3999
1452.87	42.1636
1456.01	41.9873
1459.15	42.3178
1462.28	40.9374
1465.42	40.6728
1468.55	40.7522
1471.68	39.8999
1474.81	38.0892
1477.94	36.7709
1481.07	32.8087
1484.2	32.0868
1487.32	30.9323
1490.45	28.5247
1493.57	25.8596
1496.69	22.6418
1499.81	20.8448
1502.93	19.0027
1506.05	17.8731
1509.17	16.1859
1512.28	14.3535
1515.4	13.0359
1518.51	12.6352
1521.63	12.6733
1524.74	11.7516
1527.85	11.189
1530.96	9.67407
1534.06	9.5976
1537.17	10.349
1540.28	10.8966
1543.38	12.2698
1546.48	12.4896
1549.59	12.2553
1552.69	13.4687
1555.79	14.4012
1558.88	15.4295
1561.98	15.9594
1565.08	15.2179
1568.17	14.2822
1571.27	14.4022
1574.36	16.0652
1577.45	17.3389
1580.54	18.9356
1583.63	19.5934
1586.72	20.3337
1589.8	20.8111
1592.89	22.9822
1595.97	24.6657
1599.06	26.2402
1602.14	26.1202
1605.22	27.1819
1608.3	28.0229
1611.38	29.7752
1614.46	29.5634
1617.53	30.6907
1620.61	30.1575
1623.68	31.1601
1626.75	32.0653
1629.82	31.3194
1632.9	29.7346
1635.96	28.8269
1639.03	29.8599
1642.1	29.0834
1645.16	29.7124
1648.23	29.8046
1651.29	29.8128
1654.36	28.5522
1657.42	29.4184
1660.48	27.8377
1663.53	27.6471
1666.59	27.0096
1669.65	26.0384
1672.7	24.5464
1675.76	23.1222
1678.81	21.6682
1681.86	21.2183
1684.91	19.134
1687.96	18.3183
1691.01	15.9554
1694.06	14.3978
1697.11	11.8122
1700.15	9.72919
1703.2	7.0501
1706.24	6.12451
1709.28	5.16158
1712.32	4.28464
1715.36	3.33812
1718.4	0.87294
1721.43	0.414312
1724.47	-0.227019
1727.5	-0.16753
1730.54	0.803715
1733.57	0.579554
1736.6	0.228254
1739.63	-1.48235
1742.66	0.129603
1745.69	0.0023047
1748.72	1.7386
1751.74	1.84124
1754.77	3.20029
1757.79	2.96889
1760.81	3.54544
1763.83	3.90368
1766.85	3.77122
1769.87	3.09132
1772.89	3.90947
1775.91	4.40616
1778.92	3.78286
1781.94	4.23952
1784.95	3.33898
1787.96	2.70054
1790.97	2.28187
1793.98	2.17855
1796.99	2.47068
1800	2.77487
1803	2.99948
1806.01	2.71194
1809.01	3.02954
1812.02	3.41098
1815.02	4.141
1818.02	4.62034
1821.02	5.51708
1824.02	5.44058
1827.01	5.66764
1830.01	6.01218
1833	5.59018
1836	5.90859
1838.99	5.17907
1841.98	4.67387
1844.97	4.86434
1847.96	5.07387
1850.95	4.73389
1853.94	4.26372
1856.92	3.03971
1859.91	2.89027
1862.89	3.14822
1865.88	1.77981
1868.86	2.58125
1871.84	3.21891
1874.82	3.90197
1877.8	5.07355
1880.77	5.73304
1882.52	4.99468
1885.51	4.79084
1888.5	4.40232
1891.49	5.44225
1894.47	4.73601
1897.46	4.95002
1900.44	5.19737
1903.42	4.84217
1906.4	5.67141
1909.38	6.1727
1912.36	6.27183
1915.34	6.69406
1918.32	7.83975
1921.29	7.48178
1924.27	8.00394
1927.24	7.99189
1930.21	7.89233
1933.18	8.58195
1936.15	9.26919
1939.12	8.76421
1942.09	8.97816
1945.06	9.21703
1948.02	9.56477
1950.99	9.81026
1953.95	8.62996
1956.91	8.33143
1959.87	8.42496
1962.84	8.84299
1965.79	9.02877
1968.75	8.26118
1971.71	9.06121
1974.66	7.81191
1977.62	7.73585
1980.57	8.17561
1983.53	8.44725
1986.48	7.56854
1989.43	8.35565
1992.38	8.34168
1995.33	8.36699
1998.27	7.17772
2001.22	6.31993
2004.16	5.81914
2007.11	5.70142
2010.05	4.07
2012.99	3.86359
2015.93	4.83505
2018.87	6.10219
2021.81	6.20768
2024.75	7.9751
2027.69	7.71737
2030.62	8.60184
2033.56	9.74116
2036.49	9.87182
2039.42	9.66359
2042.35	9.49142
2045.28	10.4468
2048.21	10.4556
2051.14	10.9766
2054.06	11.082
2056.99	10.7379
2059.92	11.1913
2062.84	10.6853
2065.76	8.87256
2068.68	8.45603
2071.6	8.31266
2074.52	7.50393
2077.44	7.39768
2080.36	7.74413
2083.27	8.40785
2086.19	9.91864
2089.1	10.5198
2092.01	12.4161
2094.93	12.8291
2097.84	14.2015
2100.75	14.6197
2103.66	14.7187
2106.56	14.8986
2109.47	14.1253
2112.37	14.2747
2115.28	15.0178
2118.18	14.6313
2121.09	14.8083
2123.99	15.1367
2126.89	15.0311
2129.79	15.0539
2132.68	14.1107
2135.58	13.5335
2138.48	12.754
2141.37	14.1053
2144.26	12.9119
2147.16	12.974
2150.05	13.2267
2152.94	13.8657
2155.83	13.9798
2158.72	15.6855
2161.6	15.3886
2164.49	16.176
2167.38	15.3564
2170.26	15.6988
2173.14	16.0007
2176.03	16.1095
2178.91	15.6235
2181.79	15.705
2184.67	16.4283
2187.54	16.6751
2190.42	16.7412
2193.3	16.9135
2196.17	16.6969
2199.05	17.5207
2201.92	17.6076
2204.79	17.3623
2207.66	17.2024
2210.53	17.1275
2213.4	16.5452
2216.27	15.2947
2219.13	14.5549
2222	13.7824
2224.86	13.6127
2227.72	13.5078
2230.59	11.7393
2233.45	11.6668
2236.31	10.6052
2239.17	10.2063
2242.03	10.4907
2244.88	11.3304
2247.74	10.9741
2250.59	10.7343
2253.45	11.2961
2256.3	11.2082
2259.15	10.2703
2262	10.3628
2264.85	9.63446
2267.7	9.63216
2270.55	9.97752
2273.4	8.81924
2276.24	8.50628
2279.09	9.01059
2281.93	8.40113
2284.77	8.57831
2287.61	8.14701
2290.46	7.26851
2293.29	6.18296
2296.13	6.05233
2298.97	7.95943
2301.81	8.85639
2304.64	10.4571
2307.48	10.6302
2310.31	11.1
2313.14	13.1704
2315.97	13.0427
2318.8	13.2102
2321.63	13.5459
2324.46	13.0875
2327.29	13.2288
2330.12	12.1381
2332.94	11.0662
2335.76	9.40634
2338.59	8.7885
2341.41	8.94736
2344.23	8.73855
2347.05	8.89702
2349.87	8.32483
2352.69	8.03485
2355.5	6.44329
2358.32	5.29023
2361.14	4.13909
2363.95	5.8407
2366.76	7.01897
2369.58	6.71951
2372.39	6.33968
2375.2	5.32041
2378	3.99197
2380.81	3.86329
2383.62	2.57149
2386.42	2.94739
2389.23	3.578
2392.03	4.51501
2394.84	4.22499
2397.64	4.16669
2400.44	2.74748
2403.24	3.30053
2406.04	2.83819
2408.83	3.64413
2411.63	4.31944
2414.43	4.92045
2417.22	4.57058
2420.02	5.27919
2422.81	4.82741
2425.6	5.19005
2428.39	5.36305
2431.18	5.99719
2433.97	7.0434
2436.76	6.70992
2439.54	6.21461
2442.33	4.85379
2445.11	5.25327
2447.9	4.24694
2450.68	4.66575
2453.46	4.9163
2456.24	5.06206
2459.02	5.97967
2461.8	5.77004
2464.58	5.75973
2467.36	5.22232
2470.13	4.44115
2472.91	3.21509
2475.68	3.37633
2478.45	3.43693
2481.22	4.32561
2484	4.86157
2486.77	3.64093
2489.54	3.18955
2492.3	2.63945
2495.07	1.992
2497.84	2.91904
2500.6	4.21278
2503.36	4.00504
2506.13	3.31673
2508.89	3.30281
2511.65	3.95294
2514.41	4.2739
2517.17	3.50693
2519.93	3.4737
2522.68	3.55538
2525.44	3.67082
2528.19	3.67576
2530.95	2.84396
2533.7	2.58499
2536.45	2.17039
2539.2	1.54564
2541.95	1.40637
2544.7	2.00671
2547.45	1.69124
2550.2	1.01796
2552.94	0.397905
2555.69	0.828505
2558.43	0.546569
2561.17	1.37953
2563.92	1.73248
2566.66	2.85579
2569.4	2.72327
2572.14	3.33317
2574.88	3.79611
2577.61	4.20371
2580.35	4.41644
2583.09	4.5513
2585.82	5.02404
2588.55	5.21675
2591.28	5.76521
2594.02	6.42088
2596.75	6.38823
2599.48	6.14311
2602.2	6.68983
2604.93	7.1458
2607.66	7.11516
2610.38	7.25858
2613.11	7.40723
2615.83	7.49519
2618.56	6.3501
2621.28	6.83023
2624	6.97084
2626.72	6.52625
2629.44	5.88376
2632.15	6.01357
2634.87	5.74704
2637.59	6.03771
2640.3	5.88728
2643.02	6.34891
2645.73	6.37206
2648.44	7.39227
2651.15	8.30949
2653.86	8.51915
2656.57	8.97544
2659.28	9.53076
2661.99	10.1635
2664.69	10.7969
2667.4	10.714
2670.1	11.0776
2672.81	10.6331
2675.51	10.8504
2678.21	9.63973
2680.91	8.72534
2683.61	7.87795
2686.31	6.61596
2689	5.6874
2691.7	4.56827
2694.4	3.18749
2697.09	2.95059
2699.79	2.81474
2702.48	2.02059
2705.17	2.40702
2707.86	2.97936
2710.55	3.66867
2713.24	4.34278
2715.93	4.39488
2718.61	3.45754
2721.3	4.14982
2723.99	4.92393
2726.67	5.63337
2729.35	5.82465
2732.04	6.28646
2734.72	6.31889
2737.4	6.38252
2740.08	6.97024
2742.76	7.44547
2745.43	7.80514
2748.11	7.60166
2750.79	6.69726
2753.46	6.99631
2756.13	6.29574
2758.81	6.03405
2761.48	5.85521
2764.15	5.51963
2766.82	4.63658
2769.49	4.41214
2772.16	4.00836
2774.82	3.90912
2777.49	3.22157
2780.16	3.13461
2782.82	2.56731
2785.48	2.32814
2788.15	2.58398
2790.81	1.81187
2793.47	1.24134
2796.13	0.895763
2798.79	1.01108
2801.44	0.929922
2804.1	1.42707
2806.76	1.50548
2809.41	2.0284
2812.07	2.49319
2814.72	2.81172
2817.37	3.76835
2820.02	3.93464
2822.67	4.6077
2825.32	6.89166
2827.97	8.6479
2830.62	9.79128
2833.26	11.0476
2835.91	13.3358
2838.55	15.6203
2841.2	18.9558
2843.84	21.6737
2846.48	24.4375
2849.12	26.8163
2851.76	29.2984
2854.4	32.4838
2857.04	35.3061
2859.68	38.2921
2862.32	41.5567
2864.95	43.6393
2867.58	46.026
2870.22	48.5002
2872.85	50.6899
2875.48	52.3041
2878.11	53.304
2880.74	55.5848
2883.37	57.1293
2886	58.7993
2888.63	61.1133
2891.25	62.6744
2893.88	63.4567
2896.5	63.7454
2899.13	65.8878
2901.75	68.675
2904.37	71.3046
2906.99	73.512
2909.61	76.036
2912.23	79.2589
2914.85	82.9926
2917.46	85.7621
2920.08	89.9928
2922.7	92.2036
2925.31	94.1197
2927.92	95.3777
2930.53	95.9778
2933.15	95.6582
2935.76	95.773
2938.37	93.7184
2940.98	92.0304
2943.58	90.2992
2946.19	88.8418
2948.8	85.676
2951.4	82.7527
2954.01	80.8231
2956.61	77.3019
2959.21	73.6047
2961.81	70.0831
2964.41	66.7458
2967.01	64.4531
2969.61	61.4483
2972.21	58.4535
2974.81	55.4259
2977.4	51.8509
2980	47.7734
2982.59	43.4743
2985.18	40.1044
2987.78	36.0391
2990.37	31.9575
2992.96	28.4165
2995.55	24.2258
2998.14	21.4955
3000.72	18.0603
3003.31	14.5402
3005.9	11.3191
3008.48	9.2681
3011.07	7.65633
3013.65	5.65069
3016.23	4.56773
3018.81	3.16659
3021.39	2.70246
3023.97	3.23213
3026.55	3.64634
3029.13	3.8271
3031.71	4.31073
3034.28	3.59603
3036.86	3.6466
3039.43	3.9149
3042.01	4.00923
3044.58	4.47887
3047.15	4.6824
3049.72	4.21771
3052.29	4.46269
3054.86	4.71993
3057.43	3.90652
3060	3.0981
3062.56	2.90531
3065.13	2.40447
3067.69	2.2895
3070.25	1.33154
3072.82	0.956382
3075.38	0.542679
3077.94	0.54583
3080.5	1.44682
3083.06	1.94439
3085.62	2.35751
3088.17	1.90383
3090.73	2.11982
3093.29	2.61672
3095.84	2.79087
3098.4	3.80554
3100.95	4.68305
3103.5	5.95394
3106.05	5.67232
3108.6	5.06725
3111.15	5.23067
3113.7	5.98119
3116.25	6.56703
3118.79	5.83027
3121.34	6.23305
3123.88	5.98374
3126.43	6.23158
3128.97	5.78617
3131.51	4.45914
3134.05	3.66251
3136.59	3.1838
3139.14	3.09467
3141.67	2.30055
3144.21	1.27958
3146.75	1.00922
3149.28	2.4392