File: data/Raman/poly_smoothed/Mb_10_14_43_1x_45s_532 nm_x100_100%_600 gr_mm_01.txt
#Acq. time (s)=	45
#Accumulations=	2
#Range (cm-¹)=	200...3150
#Windows=	2
#Auto scanning=	Off
#Autofocus=	Off
#Macrospot=	Off
#AutoExposure=	Off
#Spike filter=	Multiple accum.
#Delay time (s)=	0
#Binning=	1
#Readout mode=	Signal
#DeNoise=	Off
#ICS correction=	On
#Dark correction=	Off
#Inst. Process=	Off
#Detector Gain=	Best Dynamic Range
#Detector ADC=	20 kHz
#Detector temperature (°C)=	-69.85
#Instrument=	LabRAM HR Evol
#Detector=	Synapse
#Objective=	x100
#Grating=	600 gr/mm
#ND Filter=	100%
#Laser (nm)=	532
#Hole=	100.021
#Range=	Auto
#Laser Pol.=	No
#Raman. Pol.=	No
#Laser Pol. (°)=	-0.0007625
#Raman Pol. (°)=	89.9995
#Collection=	Microscope
#StageXY=	Marzhauser
#StageZ=	Marzhauser
#X (µm)=	-603.2
#Y (µm)=	-1684.8
#Z (µm)=	89.65
#Full time(mm:ss)=	3:18
#Project=
#Sample=
#Site=
#Title=	Mb_10_14_43_2x_45s_532 nm_x100_100%_600 gr_mm
#Remark=
#Date=	11.07.2022 11:54
#Acquired=	11.07.2022 11:54:54
#Edit:Spike=	11.07.2022 11:59:44
#Base:Fit=	10.08.2022 10:21:11
#Base:Sub=	10.08.2022 10:21:41
#Filter:Polynom=	16.08.2022 10:17:53
#AxisType[0]=Intens
#AxisUnit[0]=Cnt
#AxisType[1]=Spectr
#AxisUnit[1]=1/cm
200.388	7.82903
204.019	11.7572
207.646	15.9223
211.274	16.5062
214.899	14.9644
218.524	12.9424
222.146	11.9425
225.766	12.6966
229.388	9.82909
233.005	9.16546
236.621	11.7591
240.236	12.8597
243.852	13.3863
247.464	13.9684
251.074	14.5165
254.683	15.1628
258.291	13.9046
261.897	14.5045
265.504	15.8459
269.108	17.2495
272.71	16.9495
276.311	17.9365
279.91	17.8535
283.508	17.633
287.105	17.9566
290.698	17.3937
294.291	15.3733
297.884	13.336
301.475	12.548
305.064	13.6377
308.652	14.7694
312.237	14.1606
315.822	14.6309
319.406	14.3471
322.987	16.8788
326.568	16.3375
330.148	14.7004
333.724	13.4784
337.301	14.4253
340.875	13.167
344.449	13.1973
348.02	13.2104
351.592	12.8411
355.16	10.9771
358.728	10.2469
362.294	8.67937
365.858	6.16622
369.422	6.35585
372.983	6.32262
376.543	5.27707
380.102	5.23824
383.661	5.33466
387.216	6.10376
390.771	7.9002
394.324	10.5864
397.875	9.93334
401.425	13.0252
404.974	13.5804
408.524	14.0063
412.07	14.796
415.614	16.4806
419.156	17.7077
422.698	19.8792
426.238	20.1771
429.777	21.4181
433.315	20.8765
436.852	19.9896
440.387	18.6301
443.919	17.9624
447.451	17.2342
450.982	16.0326
454.512	16.0795
458.038	16.4266
461.565	15.0138
465.091	14.9987
468.613	16.0968
472.136	16.2979
475.655	18.4115
479.176	19.7628
482.692	20.4631
486.21	21.7785
489.724	24.0657
493.237	24.6425
496.75	25.4211
500.26	27.3026
503.769	27.7137
507.279	27.2916
510.785	27.3578
514.289	25.0689
517.793	24.4029
521.297	22.7348
524.797	21.6731
528.297	20.2012
531.795	17.4207
535.291	18.1709
538.787	17.4936
542.281	16.9775
545.773	14.942
549.264	14.7873
552.754	14.5552
556.243	14.8224
559.73	14.1014
563.216	15.3254
566.701	13.7833
570.182	14.5505
573.664	12.6334
577.145	12.4141
580.624	11.6333
584.1	10.401
587.577	9.33695
591.052	8.56218
594.524	8.23416
597.997	6.60254
601.466	6.10112
604.936	5.47796
608.403	6.35042
611.87	7.24553
615.334	6.50799
618.799	7.90858
622.26	7.35647
625.72	6.35908
629.181	7.47588
632.638	7.94971
636.095	9.29932
639.551	9.41089
643.005	8.91941
646.457	8.45185
649.908	8.16967
653.357	7.81568
656.806	6.75556
660.253	6.13386
663.7	6.10312
667.145	5.10895
670.588	7.49623
674.027	8.56507
677.468	10.6121
680.907	12.2371
684.345	14.0874
687.781	15.252
691.216	16.3042
694.65	17.5222
698.081	19.6276
701.512	20.7781
704.942	21.9582
708.371	23.5923
711.796	24.1637
715.222	25.6097
718.645	24.8145
722.068	24.8514
725.49	24.4313
728.909	24.567
732.329	25.4347
735.745	26.9749
739.16	27.2027
742.576	29.0788
745.988	31.9395
749.401	33.7954
752.811	36.6356
756.22	39.9145
759.627	42.8235
763.035	46.2546
766.44	48.594
769.843	51.4979
773.245	54.4327
776.646	57.7762
780.046	61.7812
783.444	63.9144
786.841	66.4338
790.237	70.3458
793.631	72.3224
797.024	74.9458
800.416	76.8642
803.807	78.7089
807.196	79.9216
810.584	81.8034
813.971	83.4347
817.354	83.8931
820.739	86.0157
824.122	86.1603
827.503	88.0648
830.882	87.6074
834.261	86.6158
837.637	86.4827
841.013	86.9048
844.389	86.8953
847.761	84.4195
851.131	83.101
854.503	80.7952
857.871	80.1517
861.24	78.6418
864.606	76.2329
867.97	74.8885
871.336	74.8148
874.698	73.8727
878.058	72.1012
881.418	71.0453
884.778	69.2887
888.135	67.8795
891.49	68.0482
894.845	67.6255
898.198	66.7693
901.55	66.6388
904.901	66.4786
908.25	67.4494
911.598	67.6427
914.945	66.5176
918.291	64.9408
921.635	65.5208
924.978	67.4739
928.318	69.3749
931.659	71.2951
934.998	73.7144
938.336	74.9602
941.671	76.1743
945.007	76.4271
948.339	76.5761
951.672	77.5676
955.004	77.6959
958.333	75.7462
961.662	72.4996
964.989	71.6053
968.315	71.5007
971.639	70.7719
974.962	70.8925
978.285	69.023
981.605	66.988
984.924	65.704
988.243	62.6595
991.56	60.0819
994.875	57.5535
998.188	55.8585
1001.5	56.2877
1004.81	58.7336
1008.12	61.3456
1011.43	61.8888
1014.74	62.1668
1018.05	60.7489
1021.35	60.5525
1024.65	59.5274
1027.96	59.1512
1031.26	57.7481
1034.56	56.928
1037.86	54.9405
1041.16	52.5775
1044.45	52.3614
1047.75	54.5161
1051.04	53.9968
1054.33	53.8207
1057.62	51.7998
1060.91	51.6188
1064.2	50.3206
1067.49	50.0093
1070.77	47.9929
1074.06	47.28
1077.34	47.5677
1080.62	47.2931
1083.91	49.2256
1087.18	48.2685
1090.46	48.9648
1093.74	49.0681
1097.02	48.6415
1100.29	48.2048
1103.56	48.1043
1106.84	48.0889
1110.11	47.4974
1113.38	47.024
1116.64	46.662
1119.91	46.3865
1123.18	46.4949
1126.44	46.0223
1129.7	44.7432
1132.97	43.5964
1136.23	43.3582
1139.49	42.5325
1142.74	43.0123
1146	41.7895
1149.26	41.7012
1152.51	39.7914
1155.76	39.3808
1159.01	38.8217
1162.27	37.3449
1165.51	35.8911
1168.76	35.4736
1172.01	35.9572
1175.25	35.4142
1178.5	34.244
1181.74	33.9498
1184.98	34.1685
1188.22	34.1392
1191.46	33.3264
1194.7	33.84
1197.94	32.554
1201.17	33.7879
1204.41	34.1698
1207.64	33.8543
1210.87	35.8119
1214.1	37.2242
1217.33	39.2844
1220.56	44.1011
1223.79	47.1837
1227.01	50.1982
1230.23	54.1941
1233.46	57.672
1236.68	61.744
1239.9	63.3907
1243.12	67.2649
1246.34	69.3185
1249.55	71.6788
1252.77	73.0898
1255.98	73.3012
1259.2	74.582
1262.41	73.7025
1265.62	73.3958
1268.83	73.5787
1272.03	73.9559
1275.24	74.2257
1278.45	73.459
1281.65	74.0304
1284.85	73.0752
1288.06	73.5631
1291.26	75.317
1294.46	77.679
1297.66	79.8976
1300.85	81.6576
1304.05	81.9101
1307.24	84.6665
1310.43	86.906
1313.63	87.7278
1316.82	88.7008
1320.01	90.2685
1323.2	89.8147
1326.38	88.2156
1329.57	87.4151
1332.76	86.2697
1335.94	85.6324
1339.12	83.6502
1342.3	82.2657
1345.48	81.5064
1348.66	79.8207
1351.84	79.2943
1355.01	76.721
1358.19	74.6249
1361.36	72.21
1364.53	69.9172
1367.71	71.3831
1370.88	70.3561
1374.04	68.5599
1377.21	66.5814
1380.38	64.7551
1383.54	63.5392
1386.71	63.688
1389.87	63.2598
1393.03	60.5466
1396.19	60.1852
1399.35	59.2728
1402.51	57.3989
1405.67	57.8563
1408.82	58.8483
1411.98	60.4297
1415.13	61.8535
1418.28	63.7795
1421.43	67.5747
1424.58	71.8545
1427.73	76.8754
1430.88	83.5855
1434.02	89.2737
1437.17	93.1735
1440.31	98.4433
1443.45	103.567
1446.6	107.862
1449.74	109.11
1452.87	110.211
1456.01	109.962
1459.15	108.99
1462.28	107.576
1465.42	104.071
1468.55	96.7526
1471.68	91.6242
1474.81	86.5808
1477.94	80.7742
1481.07	77.4582
1484.2	72.2962
1487.32	68.4545
1490.45	64.3951
1493.57	61.159
1496.69	57.4612
1499.81	55.6093
1502.93	53.3022
1506.05	51.3396
1509.17	49.1267
1512.28	46.2736
1515.4	44.3445
1518.51	43.5716
1521.63	42.6645
1524.74	40.8911
1527.85	39.634
1530.96	38.3667
1534.06	36.892
1537.17	35.3152
1540.28	34.972
1543.38	34.3155
1546.48	34.8715
1549.59	36.8761
1552.69	38.1701
1555.79	38.919
1558.88	41.5118
1561.98	43.9149
1565.08	44.8065
1568.17	47.1352
1571.27	49.34
1574.36	51.1593
1577.45	54.9988
1580.54	57.3202
1583.63	59.2912
1586.72	61.2342
1589.8	62.2553
1592.89	64.4951
1595.97	65.5755
1599.06	66.306
1602.14	65.0954
1605.22	63.835
1608.3	63.259
1611.38	61.422
1614.46	61.5894
1617.53	60.9495
1620.61	58.7775
1623.68	57.9187
1626.75	57.3295
1629.82	57.2032
1632.9	57.5185
1635.96	59.6439
1639.03	59.6774
1642.1	60.9244
1645.16	62.7229
1648.23	64.8883
1651.29	67.342
1654.36	67.6005
1657.42	67.9021
1660.48	67.1631
1663.53	66.9809
1666.59	66.0011
1669.65	63.7359
1672.7	60.6613
1675.76	57.0411
1678.81	52.4994
1681.86	49.1472
1684.91	45.3085
1687.96	40.6261
1691.01	35.7898
1694.06	31.5493
1697.11	28.2216
1700.15	24.6179
1703.2	22.9841
1706.24	19.7338
1709.28	18.2365
1712.32	16.2817
1715.36	14.4478
1718.4	15.0937
1721.43	15.2525
1724.47	14.262
1727.5	13.2714
1730.54	12.7954
1733.57	12.4281
1736.6	12.9444
1739.63	12.0032
1742.66	10.5531
1745.69	9.57416
1748.72	9.10033
1751.74	8.26368
1754.77	7.19252
1757.79	6.08544
1760.81	5.5376
1763.83	4.00407
1766.85	2.37665
1769.87	1.23144
1772.89	0.321974
1775.91	0.0882666
1778.92	-0.57407
1781.94	-1.11333
1784.95	-1.38661
1787.96	0.0916555
1790.97	0.168076
1793.98	-0.361908
1796.99	-0.762857
1800	0.0583233
1803	0.657448
1806.01	0.318241
1809.01	1.35411
1812.02	1.67749
1815.02	1.78694
1818.02	2.15542
1821.02	2.72682
1824.02	3.87173
1827.01	3.82639
1830.01	3.91934
1833	3.41778
1836	3.3695
1838.99	2.92845
1841.98	1.7613
1844.97	2.283
1847.96	2.15464
1850.95	1.80946
1853.94	0.0274936
1856.92	-0.23658
1859.91	0.133218
1862.89	-0.887281
1865.88	-1.28003
1868.86	-0.657699
1871.84	0.197066
1874.82	0.435855
1877.8	-0.035695
1880.77	0.990504
1882.52	2.08201
1885.51	1.51196
1888.5	1.86654
1891.49	2.17438
1894.47	2.8799
1897.46	2.97674
1900.44	2.42901
1903.42	2.70581
1906.4	3.10976
1909.38	3.72683
1912.36	3.35008
1915.34	3.57939
1918.32	3.67602
1921.29	2.35148
1924.27	2.17001
1927.24	1.40733
1930.21	1.6615
1933.18	0.768729
1936.15	0.92625
1939.12	2.38459
1942.09	3.02262
1945.06	3.35217
1948.02	3.23212
1950.99	2.87508
1953.95	3.40346
1956.91	2.73886
1959.87	2.58077
1962.84	2.82856
1965.79	2.77973
1968.75	2.39234
1971.71	1.93039
1974.66	2.6901
1977.62	3.07251
1980.57	2.08127
1983.53	2.33773
1986.48	2.07984
1989.43	3.16827
1992.38	2.14417
1995.33	2.86587
1998.27	2.91648
2001.22	1.99621
2004.16	2.40749
2007.11	3.42575
2010.05	4.82826
2012.99	6.51043
2015.93	7.20819
2018.87	6.92822
2021.81	7.41473
2024.75	7.23754
2027.69	7.34903
2030.62	7.49246
2033.56	6.79256
2036.49	7.18887
2039.42	7.95976
2042.35	6.66035
2045.28	7.26216
2048.21	6.81022
2051.14	6.84991
2054.06	7.2299
2056.99	7.85708
2059.92	9.004
2062.84	7.95155
2065.76	8.06916
2068.68	8.02516
2071.6	7.28648
2074.52	7.63879
2077.44	8.31149
2080.36	8.78607
2083.27	9.45311
2086.19	9.40062
2089.1	8.59412
2092.01	9.07951
2094.93	8.56586
2097.84	8.7235
2100.75	9.23327
2103.66	10.0358
2106.56	11.1287
2109.47	11.7942
2112.37	13.6273
2115.28	14.183
2118.18	15.5951
2121.09	16.0452
2123.99	17.251
2126.89	18.9168
2129.79	19.518
2132.68	19.328
2135.58	19.803
2138.48	21.1093
2141.37	20.7722
2144.26	21.4054
2147.16	23.0825
2150.05	23.9806
2152.94	24.1821
2155.83	24.3302
2158.72	25.0429
2161.6	25.3193
2164.49	26.3027
2167.38	27.9056
2170.26	28.0058
2173.14	28.1581
2176.03	29.0274
2178.91	29.1412
2181.79	28.6884
2184.67	27.8945
2187.54	27.0536
2190.42	26.1254
2193.3	25.1538
2196.17	24.9442
2199.05	22.7927
2201.92	20.4462
2204.79	19.603
2207.66	18.7512
2210.53	17.6196
2213.4	17.0169
2216.27	16.8613
2219.13	17.1788
2222	17.0612
2224.86	15.9347
2227.72	14.9656
2230.59	14.7893
2233.45	14.6631
2236.31	14.9344
2239.17	15.4933
2242.03	15.2169
2244.88	16.6515
2247.74	17.0753
2250.59	17.3087
2253.45	16.9006
2256.3	16.7678
2259.15	17.5189
2262	16.4277
2264.85	15.7886
2267.7	14.7121
2270.55	13.2051
2273.4	12.7053
2276.24	13.541
2279.09	12.4483
2281.93	12.2615
2284.77	12.6388
2287.61	12.3266
2290.46	11.2901
2293.29	9.52682
2296.13	7.5963
2298.97	8.74115
2301.81	9.95431
2304.64	10.6164
2307.48	12.0617
2310.31	12.6032
2313.14	12.7448
2315.97	13.632
2318.8	13.3221
2321.63	13.3449
2324.46	13.391
2327.29	13.6022
2330.12	12.7477
2332.94	13.0861
2335.76	12.0248
2338.59	11.5586
2341.41	10.9145
2344.23	10.8046
2347.05	10.4893
2349.87	9.78965
2352.69	8.77792
2355.5	8.86365
2358.32	7.7567
2361.14	7.06913
2363.95	6.2494
2366.76	6.0287
2369.58	5.94005
2372.39	4.87608
2375.2	3.67499
2378	3.4472
2380.81	2.45767
2383.62	2.25825
2386.42	1.68992
2389.23	2.45607
2392.03	2.24516
2394.84	3.10577
2397.64	3.58818
2400.44	4.42245
2403.24	5.10972
2406.04	4.75564
2408.83	6.4377
2411.63	5.91808
2414.43	7.45233
2417.22	8.63263
2420.02	10.2467
2422.81	10.9704
2425.6	11.1064
2428.39	10.497
2431.18	9.61605
2433.97	9.10608
2436.76	7.83561
2439.54	7.5407
2442.33	7.35201
2445.11	6.88255
2447.9	6.21422
2450.68	5.46755
2453.46	4.74946
2456.24	4.12316
2459.02	3.61663
2461.8	3.50907
2464.58	4.30099
2467.36	3.8225
2470.13	4.27183
2472.91	5.22178
2475.68	5.43738
2478.45	5.13939
2481.22	5.79005
2484	6.58724
2486.77	6.65713
2489.54	6.93125
2492.3	6.0257
2495.07	6.48107
2497.84	6.67722
2500.6	6.46386
2503.36	6.84807
2506.13	7.94953
2508.89	9.04862
2511.65	8.07658
2514.41	7.96157
2517.17	8.02353
2519.93	7.7707
2522.68	8.51012
2525.44	9.17237
2528.19	10.766
2530.95	10.5868
2533.7	11.5261
2536.45	11.7895
2539.2	11.2252
2541.95	11.3481
2544.7	10.6406
2547.45	10.4271
2550.2	10.3185
2552.94	10.3755
2555.69	10.7554
2558.43	10.2954
2561.17	10.563
2563.92	10.2555
2566.66	9.10659
2569.4	8.78382
2572.14	10.2621
2574.88	10.7067
2577.61	9.0904
2580.35	8.91138
2583.09	8.41137
2585.82	8.59886
2588.55	7.99484
2591.28	7.60502
2594.02	6.25857
2596.75	6.10089
2599.48	4.8484
2602.2	4.7349
2604.93	4.04014
2607.66	3.58118
2610.38	3.01985
2613.11	2.87898
2615.83	2.41981
2618.56	3.02851
2621.28	3.65462
2624	2.93131
2626.72	2.63181
2629.44	3.09634
2632.15	3.48974
2634.87	4.55069
2637.59	6.43914
2640.3	7.00875
2643.02	6.72515
2645.73	6.63439
2648.44	6.57199
2651.15	6.39856
2653.86	6.73371
2656.57	6.40592
2659.28	6.25151
2661.99	6.73936
2664.69	6.53479
2667.4	6.65666
2670.1	6.26278
2672.81	5.40808
2675.51	5.31433
2678.21	4.40283
2680.91	3.58864
2683.61	3.67424
2686.31	3.46592
2689	2.33403
2691.7	3.13052
2694.4	3.07851
2697.09	3.35815
2699.79	3.84649
2702.48	3.90532
2705.17	4.84851
2707.86	4.58095
2710.55	4.66635
2713.24	4.49903
2715.93	4.36937
2718.61	4.43884
2721.3	4.91077
2723.99	4.89975
2726.67	5.4
2729.35	5.67535
2732.04	5.49013
2734.72	6.09097
2737.4	6.36442
2740.08	6.04572
2742.76	5.99177
2745.43	5.36905
2748.11	5.61748
2750.79	5.6978
2753.46	5.37621
2756.13	5.34625
2758.81	4.71722
2761.48	4.76922
2764.15	4.23123
2766.82	3.11853
2769.49	2.16077
2772.16	1.85465
2774.82	1.18549
2777.49	0.731638
2780.16	-0.222357
2782.82	-0.520931
2785.48	-1.12267
2788.15	-1.16945
2790.81	-1.36018
2793.47	-0.569932
2796.13	-0.897061
2798.79	-1.16084
2801.44	-0.825767
2804.1	-0.608026
2806.76	-0.28499
2809.41	-0.025874
2812.07	0.639445
2814.72	2.07411
2817.37	3.93362
2820.02	5.34524
2822.67	6.84118
2825.32	9.7797
2827.97	12.3524
2830.62	13.978
2833.26	18.0308
2835.91	21.1714
2838.55	25.8623
2841.2	31.4847
2843.84	37.072
2846.48	42.9103
2849.12	49.664
2851.76	56.9394
2854.4	64.2982
2857.04	70.7656
2859.68	76.8223
2862.32	82.5723
2864.95	89.2344
2867.58	95.91
2870.22	101.046
2872.85	106.163
2875.48	110.043
2878.11	114.324
2880.74	118.755
2883.37	122.268
2886	125.859
2888.63	128.613
2891.25	132.848
2893.88	135.197
2896.5	139.296
2899.13	143.191
2901.75	147.024
2904.37	152.755
2906.99	158.395
2909.61	163.974
2912.23	170.434
2914.85	177.429
2917.46	183.785
2920.08	189.067
2922.7	194.476
2925.31	198.27
2927.92	201.816
2930.53	203.187
2933.15	202.091
2935.76	200.808
2938.37	197.279
2940.98	192.354
2943.58	187.64
2946.19	181.706
2948.8	175.818
2951.4	168.263
2954.01	160.594
2956.61	153.257
2959.21	144.982
2961.81	137.026
2964.41	128.064
2967.01	120.008
2969.61	112.533
2972.21	105.652
2974.81	99.6653
2977.4	92.8895
2980	87.4038
2982.59	80.6477
2985.18	74.0039
2987.78	67.8911
2990.37	62.1444
2992.96	55.6079
2995.55	48.6032
2998.14	41.2853
3000.72	35.3178
3003.31	29.4977
3005.9	24.3671
3008.48	20.4249
3011.07	16.4229
3013.65	13.5285
3016.23	10.4771
3018.81	8.47276
3021.39	6.47806
3023.97	4.99403
3026.55	3.69722
3029.13	2.45834
3031.71	2.50913
3034.28	2.57969
3036.86	2.48758
3039.43	2.62408
3042.01	2.64829
3044.58	4.37023
3047.15	5.17961
3049.72	7.30795
3052.29	8.34161
3054.86	9.52537
3057.43	8.77958
3060	7.96057
3062.56	7.84071
3065.13	7.95004
3067.69	7.57443
3070.25	7.11639
3072.82	6.44963
3075.38	5.43698
3077.94	5.73458
3080.5	5.13192
3083.06	4.43432
3085.62	3.48191
3088.17	2.9826
3090.73	2.72741
3093.29	1.85046
3095.84	0.821822
3098.4	0.536936
3100.95	0.720309
3103.5	0.32915
3106.05	2.06406
3108.6	3.24129
3111.15	3.71316
3113.7	4.70076
3116.25	5.64841
3118.79	6.18596
3121.34	6.69606
3123.88	7.27836
3126.43	8.23205
3128.97	9.7077
3131.51	10.2504
3134.05	10.7367
3136.59	11.9179
3139.14	12.8438
3141.67	12.6254
3144.21	11.5197
3146.75	9.84802
3149.28	7.57288