File: data/Raman/poly_smoothed/Mb_10_14_12_1x_45s_532 nm_x100_100%_600 gr_mm_01.txt
#Acq. time (s)=	45
#Accumulations=	2
#Range (cm-¹)=	200...3150
#Windows=	2
#Auto scanning=	Off
#Autofocus=	Off
#Macrospot=	Off
#AutoExposure=	Off
#Spike filter=	Multiple accum.
#Delay time (s)=	0
#Binning=	1
#Readout mode=	Signal
#DeNoise=	Off
#ICS correction=	On
#Dark correction=	Off
#Inst. Process=	Off
#Detector Gain=	Best Dynamic Range
#Detector ADC=	20 kHz
#Detector temperature (°C)=	-69.85
#Instrument=	LabRAM HR Evol
#Detector=	Synapse
#Objective=	x100
#Grating=	600 gr/mm
#ND Filter=	100%
#Laser (nm)=	532
#Hole=	100.021
#Range=	Auto
#Laser Pol.=	No
#Raman. Pol.=	No
#Laser Pol. (°)=	-0.0007625
#Raman Pol. (°)=	89.9995
#Collection=	Microscope
#StageXY=	Marzhauser
#StageZ=	Marzhauser
#X (µm)=	-639
#Y (µm)=	-1589.6
#Z (µm)=	89
#Full time(mm:ss)=	3:18
#Project=
#Sample=
#Site=
#Title=	Mb_10_14_12_2x_45s_532 nm_x100_100%_600 gr_mm
#Remark=
#Date=	11.07.2022 09:25
#Acquired=	11.07.2022 09:25:14
#Base:Fit=	10.08.2022 10:21:11
#Base:Sub=	10.08.2022 10:21:41
#Filter:Polynom=	16.08.2022 10:17:53
#AxisType[0]=Intens
#AxisUnit[0]=Cnt
#AxisType[1]=Spectr
#AxisUnit[1]=1/cm
200.388	15.4926
204.019	14.4191
207.646	9.53668
211.274	6.57178
214.899	4.99049
218.524	5.21165
222.146	7.41036
225.766	8.9789
229.388	12.5655
233.005	14.9522
236.621	16.2236
240.236	18.9823
243.852	21.1368
247.464	22.5564
251.074	24.6277
254.683	26.4972
258.291	26.427
261.897	27.1731
265.504	28.157
269.108	28.2471
272.71	26.6616
276.311	23.5632
279.91	20.1687
283.508	18.5961
287.105	16.4517
290.698	13.9024
294.291	11.9334
297.884	11.4288
301.475	11.1908
305.064	11.6256
308.652	12.4099
312.237	11.7759
315.822	12.2788
319.406	13.8488
322.987	13.8488
326.568	13.2849
330.148	12.816
333.724	13.4791
337.301	13.3055
340.875	13.1296
344.449	13.1278
348.02	13.663
351.592	15.223
355.16	16.5795
358.728	17.5912
362.294	18.6088
365.858	21.295
369.422	22.4108
372.983	25.0333
376.543	26.4954
380.102	27.8936
383.661	29.6526
387.216	31.6128
390.771	34.6289
394.324	35.3076
397.875	34.6963
401.425	35.1819
404.974	33.6378
408.524	32.1602
412.07	29.0475
415.614	25.6503
419.156	24.2579
422.698	22.445
426.238	19.2125
429.777	15.7306
433.315	13.0669
436.852	12.5822
440.387	9.7632
443.919	6.93745
447.451	5.15742
450.982	4.42046
454.512	1.22148
458.038	1.02469
461.565	0.408458
465.091	1.15142
468.613	3.80232
472.136	5.63727
475.655	6.7491
479.176	9.51464
482.692	11.5873
486.21	14.2959
489.724	16.7393
493.237	19.535
496.75	21.7349
500.26	23.7032
503.769	24.9371
507.279	26.6237
510.785	26.8998
514.289	26.791
517.793	26.5693
521.297	26.3922
524.797	25.4251
528.297	24.1439
531.795	21.3644
535.291	20.7105
538.787	17.8355
542.281	17.362
545.773	15.5948
549.264	13.6226
552.754	11.3243
556.243	10.8166
559.73	9.12687
563.216	8.39475
566.701	7.21965
570.182	6.56514
573.664	6.19455
577.145	4.85448
580.624	4.28848
584.1	4.12646
587.577	2.74205
591.052	1.466
594.524	1.62376
597.997	-0.143411
601.466	-0.0799783
604.936	3.60023
608.403	4.72126
611.87	3.41596
615.334	4.05725
618.799	4.32093
622.26	3.86957
625.72	5.82827
629.181	7.13469
632.638	8.20773
636.095	8.86973
639.551	11.6853
643.005	13.484
646.457	15.43
649.908	16.0548
653.357	17.1703
656.806	17.8894
660.253	18.5859
663.7	18.3178
667.145	18.8643
670.588	18.8598
674.027	19.0324
677.468	18.6403
680.907	19.3355
684.345	20.6173
687.781	22.4298
691.216	23.7047
694.65	23.577
698.081	24.6245
701.512	25.7802
704.942	26.8247
708.371	29.0899
711.796	30.6168
715.222	32.7388
718.645	34.4513
722.068	34.4426
725.49	36.9575
728.909	40.16
732.329	40.9205
735.745	42.3255
739.16	43.0317
742.576	44.4034
745.988	46.3504
749.401	48.8988
752.811	50.5591
756.22	52.8355
759.627	53.7287
763.035	56.9231
766.44	59.8981
769.843	63.1023
773.245	66.7831
776.646	69.651
780.046	72.7625
783.444	74.8757
786.841	76.8226
790.237	78.7789
793.631	80.5653
797.024	81.9359
800.416	84.2784
803.807	84.0977
807.196	85.2737
810.584	86.3816
813.971	85.268
817.354	84.5042
820.739	82.684
824.122	80.6183
827.503	79.2694
830.882	77.3866
834.261	75.3403
837.637	72.4614
841.013	71.8845
844.389	70.3048
847.761	67.1099
851.131	66.5168
854.503	63.8903
857.871	61.4255
861.24	58.9007
864.606	56.2369
867.97	54.9144
871.336	53.1516
874.698	53.2601
878.058	52.9511
881.418	52.2658
884.778	51.9787
888.135	51.7893
891.49	51.6011
894.845	50.6945
898.198	51.3524
901.55	52.2279
904.901	53.6659
908.25	54.3204
911.598	55.089
914.945	56.8789
918.291	57.036
921.635	56.7857
924.978	57.0691
928.318	55.5354
931.659	54.4016
934.998	52.2425
938.336	50.2897
941.671	50.3565
945.007	49.5016
948.339	48.0474
951.672	47.3656
955.004	46.9151
958.333	45.0988
961.662	43.7791
964.989	44.5914
968.315	44.3234
971.639	46.5366
974.962	45.9873
978.285	47.0716
981.605	48.2474
984.924	47.8045
988.243	47.6768
991.56	46.5143
994.875	46.2001
998.188	44.7932
1001.5	42.7296
1004.81	40.2558
1008.12	38.5696
1011.43	39.0179
1014.74	39.2014
1018.05	38.8523
1021.35	41.0671
1024.65	42.2474
1027.96	41.6388
1031.26	41.4209
1034.56	41.7943
1037.86	41.4635
1041.16	39.4618
1044.45	40.2382
1047.75	41.0871
1051.04	39.3602
1054.33	37.3415
1057.62	33.8934
1060.91	32.489
1064.2	28.8754
1067.49	27.1618
1070.77	24.2814
1074.06	23.1156
1077.34	19.714
1080.62	14.7897
1083.91	12.111
1087.18	11.1687
1090.46	10.6075
1093.74	10.354
1097.02	9.97525
1100.29	10.9691
1103.56	11.2336
1106.84	11.5665
1110.11	12.1377
1113.38	13.4394
1116.64	12.5244
1119.91	10.9769
1123.18	11.1728
1126.44	11.3599
1129.7	11.2628
1132.97	10.1816
1136.23	11.0788
1139.49	12.301
1142.74	10.9112
1146	10.4451
1149.26	9.7025
1152.51	9.02601
1155.76	6.12751
1159.01	3.5949
1162.27	1.82221
1165.51	1.84662
1168.76	1.63759
1172.01	1.49476
1175.25	2.32507
1178.5	3.43545
1181.74	5.37066
1184.98	6.47651
1188.22	7.26164
1191.46	7.95507
1194.7	8.0288
1197.94	9.48002
1201.17	10.7073
1204.41	14.1159
1207.64	16.8987
1210.87	20.3259
1214.1	22.3874
1217.33	27.1595
1220.56	29.2504
1223.79	31.4695
1227.01	34.7246
1230.23	37.4236
1233.46	40.2648
1236.68	42.6226
1239.9	44.8611
1243.12	48.5357
1246.34	51.1161
1249.55	52.8117
1252.77	54.6293
1255.98	54.1786
1259.2	53.5567
1262.41	52.81
1265.62	50.3218
1268.83	50.3768
1272.03	50.4913
1275.24	49.6811
1278.45	50.2259
1281.65	49.2142
1284.85	49.0222
1288.06	48.954
1291.26	51.2568
1294.46	52.5487
1297.66	54.4934
1300.85	55.1586
1304.05	57.9483
1307.24	58.3274
1310.43	59.5539
1313.63	61.4938
1316.82	63.3203
1320.01	66.1596
1323.2	67.5607
1326.38	67.4817
1329.57	67.5755
1332.76	66.031
1335.94	64.9052
1339.12	63.383
1342.3	61.2456
1345.48	60.3684
1348.66	60.0915
1351.84	57.1775
1355.01	52.5478
1358.19	49.888
1361.36	46.3281
1364.53	44.7143
1367.71	42.6958
1370.88	41.5193
1374.04	38.7279
1377.21	37.1841
1380.38	37.8187
1383.54	35.6574
1386.71	34.0742
1389.87	35.1619
1393.03	35.4418
1396.19	36.3371
1399.35	36.9591
1402.51	38.1879
1405.67	39.56
1408.82	40.2472
1411.98	42.1884
1415.13	45.6212
1418.28	48.9605
1421.43	53.3773
1424.58	57.1091
1427.73	60.0769
1430.88	63.0973
1434.02	67.5534
1437.17	71.3248
1440.31	75.2292
1443.45	75.7874
1446.6	77.3693
1449.74	78.0342
1452.87	78.1459
1456.01	77.6256
1459.15	74.2226
1462.28	69.3581
1465.42	65.8762
1468.55	61.5225
1471.68	55.543
1474.81	51.0188
1477.94	45.5783
1481.07	39.6737
1484.2	35.5264
1487.32	31.6131
1490.45	28.4786
1493.57	27.9603
1496.69	25.3821
1499.81	24.1283
1502.93	25.2403
1506.05	25.302
1509.17	26.7371
1512.28	27.7101
1515.4	27.8088
1518.51	28.3631
1521.63	29.7802
1524.74	31.5482
1527.85	32.3278
1530.96	33.202
1534.06	34.5693
1537.17	34.7129
1540.28	35.5593
1543.38	36.3512
1546.48	36.0826
1549.59	36.3953
1552.69	36.9666
1555.79	37.1062
1558.88	37.0405
1561.98	39.0946
1565.08	41.3212
1568.17	42.3303
1571.27	43.1784
1574.36	44.1273
1577.45	45.1203
1580.54	47.3524
1583.63	48.63
1586.72	50.4846
1589.8	50.7189
1592.89	52.922
1595.97	54.3726
1599.06	55.5649
1602.14	55.5292
1605.22	55.7174
1608.3	57.9336
1611.38	57.3696
1614.46	56.4392
1617.53	57.5633
1620.61	57.4466
1623.68	58.9553
1626.75	60.4908
1629.82	61.6889
1632.9	63.3041
1635.96	66.731
1639.03	69.5041
1642.1	69.9268
1645.16	71.4683
1648.23	73.1562
1651.29	74.2045
1654.36	77.5335
1657.42	76.0908
1660.48	77.0048
1663.53	75.6089
1666.59	73.6565
1669.65	70.8684
1672.7	67.7587
1675.76	62.5239
1678.81	57.3177
1681.86	52.9214
1684.91	47.6068
1687.96	42.2662
1691.01	38.5887
1694.06	33.8534
1697.11	29.6901
1700.15	26.2348
1703.2	21.5177
1706.24	19.7804
1709.28	17.8312
1712.32	16.5157
1715.36	14.5204
1718.4	13.2102
1721.43	11.8115
1724.47	10.1803
1727.5	10.9933
1730.54	10.9996
1733.57	10.538
1736.6	11.2159
1739.63	10.2048
1742.66	10.6751
1745.69	10.847
1748.72	10.3784
1751.74	10.1929
1754.77	10.9582
1757.79	11.4357
1760.81	12.4725
1763.83	11.7752
1766.85	10.9596
1769.87	9.91703
1772.89	9.58746
1775.91	9.97612
1778.92	10.3301
1781.94	9.82448
1784.95	9.32922
1787.96	7.43632
1790.97	5.55904
1793.98	4.52499
1796.99	3.5028
1800	4.00164
1803	3.86262
1806.01	3.668
1809.01	3.56698
1812.02	4.15626
1815.02	4.41709
1818.02	5.21492
1821.02	6.25834
1824.02	6.26564
1827.01	7.43505
1830.01	8.14169
1833	8.98455
1836	9.46202
1838.99	9.04753
1841.98	8.63483
1844.97	9.2585
1847.96	9.45677
1850.95	9.03992
1853.94	8.68023
1856.92	7.47458
1859.91	6.25302
1862.89	6.35211
1865.88	6.5267
1868.86	6.03828
1871.84	6.73731
1874.82	7.28909
1877.8	7.07043
1880.77	7.97075
1882.52	8.78429
1885.51	9.24222
1888.5	8.85631
1891.49	9.39068
1894.47	9.96951
1897.46	9.96953
1900.44	11.4222
1903.42	11.2201
1906.4	12.0037
1909.38	10.6588
1912.36	10.2378
1915.34	10.5206
1918.32	8.73658
1921.29	8.14395
1924.27	6.61553
1927.24	5.53091
1930.21	5.09148
1933.18	4.63991
1936.15	3.29279
1939.12	2.71718
1942.09	2.05073
1945.06	2.22863
1948.02	1.53152
1950.99	1.4223
1953.95	1.48962
1956.91	1.19583
1959.87	2.05487
1962.84	3.17659
1965.79	4.38723
1968.75	4.77616
1971.71	4.73327
1974.66	5.69597
1977.62	5.75564
1980.57	5.91705
1983.53	6.0866
1986.48	6.80065
1989.43	5.6779
1992.38	4.73387
1995.33	5.11364
1998.27	4.84465
2001.22	3.66126
2004.16	3.72126
2007.11	3.86301
2010.05	3.37905
2012.99	3.23898
2015.93	1.83827
2018.87	1.90024
2021.81	2.27803
2024.75	3.50107
2027.69	3.39085
2030.62	4.57323
2033.56	5.26412
2036.49	5.98649
2039.42	6.201
2042.35	5.73288
2045.28	6.56659
2048.21	6.95046
2051.14	7.92993
2054.06	8.63608
2056.99	7.02943
2059.92	7.61281
2062.84	6.73419
2065.76	7.39958
2068.68	6.14858
2071.6	6.12688
2074.52	6.78009
2077.44	7.25759
2080.36	7.32117
2083.27	7.15056
2086.19	6.84642
2089.1	7.98625
2092.01	8.65843
2094.93	9.00295
2097.84	7.31338
2100.75	7.6115
2103.66	9.3739
2106.56	9.57623
2109.47	9.71337
2112.37	9.01805
2115.28	8.96278
2118.18	9.86975
2121.09	9.84704
2123.99	10.5687
2126.89	11.1468
2129.79	11.7341
2132.68	11.3289
2135.58	11.5632
2138.48	11.3207
2141.37	12.0807
2144.26	13.8449
2147.16	15.4326
2150.05	16.3563
2152.94	17.5488
2155.83	19.1856
2158.72	20.9525
2161.6	21.3952
2164.49	21.4831
2167.38	22.3276
2170.26	23.2213
2173.14	23.6068
2176.03	23.3465
2178.91	23.4242
2181.79	24.6642
2184.67	25.2265
2187.54	24.577
2190.42	24.4008
2193.3	23.8425
2196.17	23.4934
2199.05	21.543
2201.92	19.0655
2204.79	18.1074
2207.66	17.7126
2210.53	15.9449
2213.4	15.8929
2216.27	14.9472
2219.13	13.7339
2222	13.3725
2224.86	12.0866
2227.72	12.2444
2230.59	10.5612
2233.45	9.0874
2236.31	8.92307
2239.17	8.46685
2242.03	8.76056
2244.88	8.25783
2247.74	8.99075
2250.59	9.88719
2253.45	10.2351
2256.3	9.43706
2259.15	9.11477
2262	8.29185
2264.85	7.16098
2267.7	6.89973
2270.55	6.04769
2273.4	6.21494
2276.24	6.71625
2279.09	6.90311
2281.93	5.66453
2284.77	5.88222
2287.61	4.75838
2290.46	3.82973
2293.29	1.81709
2296.13	1.02784
2298.97	1.54576
2301.81	1.74081
2304.64	2.2194
2307.48	2.02336
2310.31	2.27185
2313.14	3.32301
2315.97	4.23658
2318.8	5.16882
2321.63	4.96489
2324.46	4.58917
2327.29	5.31316
2330.12	5.10812
2332.94	5.31663
2335.76	4.87774
2338.59	6.33823
2341.41	6.49808
2344.23	6.3416
2347.05	5.87577
2349.87	4.9753
2352.69	5.16784
2355.5	4.22894
2358.32	3.23613
2361.14	2.58411
2363.95	2.7733
2366.76	3.87213
2369.58	2.96076
2372.39	2.96011
2375.2	3.48652
2378	3.99399
2380.81	5.16155
2383.62	5.10259
2386.42	4.92043
2389.23	4.93777
2392.03	5.53319
2394.84	6.64562
2397.64	7.16709
2400.44	7.2951
2403.24	7.22951
2406.04	7.02864
2408.83	6.85448
2411.63	5.79081
2414.43	6.54437
2417.22	5.61359
2420.02	5.14937
2422.81	5.80237
2425.6	5.30485
2428.39	4.92397
2431.18	4.23668
2433.97	3.26376
2436.76	2.82296
2439.54	3.89108
2442.33	4.77035
2445.11	4.48495
2447.9	4.20088
2450.68	3.66306
2453.46	4.09101
2456.24	4.01843
2459.02	4.79685
2461.8	4.74632
2464.58	3.8331
2467.36	4.06688
2470.13	3.24809
2472.91	2.78406
2475.68	2.68222
2478.45	2.68511
2481.22	2.01203
2484	2.08344
2486.77	2.59185
2489.54	3.48194
2492.3	3.73589
2495.07	2.98355
2497.84	3.04543
2500.6	1.67431
2503.36	1.19079
2506.13	3.6087
2508.89	5.19568
2511.65	6.05702
2514.41	6.93483
2517.17	7.62514
2519.93	7.93484
2522.68	8.38616
2525.44	8.39482
2528.19	8.88125
2530.95	8.32897
2533.7	8.07518
2536.45	8.17806
2539.2	8.01891
2541.95	7.99097
2544.7	7.48652
2547.45	7.48446
2550.2	6.82728
2552.94	7.30787
2555.69	7.39276
2558.43	5.64752
2561.17	4.49462
2563.92	3.18839
2566.66	2.74045
2569.4	3.71631
2572.14	5.13885
2574.88	6.52639
2577.61	7.26142
2580.35	7.0075
2583.09	6.6987
2585.82	5.69966
2588.55	4.5795
2591.28	4.66256
2594.02	4.26876
2596.75	4.08371
2599.48	3.86931
2602.2	3.41278
2604.93	3.32623
2607.66	2.9377
2610.38	2.75974
2613.11	2.8663
2615.83	2.43183
2618.56	2.70252
2621.28	3.27388
2624	2.89577
2626.72	1.93932
2629.44	2.55401
2632.15	3.46556
2634.87	4.27175
2637.59	5.56895
2640.3	6.86205
2643.02	6.33119
2645.73	6.06818
2648.44	5.58943
2651.15	4.22248
2653.86	4.59719
2656.57	4.5513
2659.28	3.88728
2661.99	3.58684
2664.69	3.83892
2667.4	3.34111
2670.1	4.14273
2672.81	3.79947
2675.51	4.17874
2678.21	4.34809
2680.91	5.17514
2683.61	5.40084
2686.31	5.39556
2689	4.73603
2691.7	4.2006
2694.4	5.03133
2697.09	6.56926
2699.79	7.89408
2702.48	8.84544
2705.17	9.90644
2707.86	9.73277
2710.55	8.79941
2713.24	9.74801
2715.93	9.23947
2718.61	8.98107
2721.3	9.01619
2723.99	8.43842
2726.67	8.13882
2729.35	8.31544
2732.04	8.23137
2734.72	8.60679
2737.4	9.1443
2740.08	8.31842
2742.76	8.17681
2745.43	7.48975
2748.11	6.20971
2750.79	5.30117
2753.46	4.85736
2756.13	4.89283
2758.81	4.35331
2761.48	4.32572
2764.15	3.92186
2766.82	2.66073
2769.49	2.28411
2772.16	1.68906
2774.82	0.223252
2777.49	0.601178
2780.16	1.41486
2782.82	1.13828
2785.48	0.722913
2788.15	1.12522
2790.81	0.644699
2793.47	1.32994
2796.13	1.9403
2798.79	2.93519
2801.44	3.64329
2804.1	4.02962
2806.76	3.53447
2809.41	2.97233
2812.07	2.64627
2814.72	2.23334
2817.37	2.38162
2820.02	3.12596
2822.67	4.11898
2825.32	4.86965
2827.97	5.50029
2830.62	7.13757
2833.26	10.2952
2835.91	12.688
2838.55	16.2192
2841.2	21.0396
2843.84	26.9268
2846.48	33.3654
2849.12	39.6461
2851.76	47.6185
2854.4	55.0915
2857.04	62.4075
2859.68	69.0448
2862.32	75.7127
2864.95	81.4925
2867.58	87.3688
2870.22	92.8393
2872.85	96.4326
2875.48	100.16
2878.11	103.307
2880.74	106.317
2883.37	109.275
2886	111.164
2888.63	112.003
2891.25	113.922
2893.88	117.03
2896.5	120.641
2899.13	124.95
2901.75	129.14
2904.37	136.534
2906.99	142.508
2909.61	150.749
2912.23	159.824
2914.85	167.639
2917.46	176.482
2920.08	182.488
2922.7	187.831
2925.31	193.008
2927.92	197.057
2930.53	199.977
2933.15	200.199
2935.76	199.252
2938.37	196.522
2940.98	192.06
2943.58	186.794
2946.19	180.118
2948.8	172.288
2951.4	163.034
2954.01	154.312
2956.61	146.345
2959.21	137.121
2961.81	128.687
2964.41	121.172
2967.01	114.08
2969.61	106.685
2972.21	98.6369
2974.81	92.7489
2977.4	86.4125
2980	79.9465
2982.59	73.7188
2985.18	67.0154
2987.78	61.5006
2990.37	55.5898
2992.96	49.2508
2995.55	44.0013
2998.14	38.7055
3000.72	34.3214
3003.31	29.3554
3005.9	24.2543
3008.48	20.1493
3011.07	17.3435
3013.65	13.2373
3016.23	10.2205
3018.81	9.07919
3021.39	6.46473
3023.97	4.91782
3026.55	3.95039
3029.13	3.22565
3031.71	2.07061
3034.28	1.23178
3036.86	1.73522
3039.43	1.99175
3042.01	2.62267
3044.58	2.83165
3047.15	3.216
3049.72	4.81333
3052.29	4.41012
3054.86	4.71631
3057.43	5.17177
3060	5.46526
3062.56	4.92975
3065.13	4.37545
3067.69	3.88214
3070.25	3.40473
3072.82	2.98495
3075.38	2.69777
3077.94	2.5475
3080.5	2.3729
3083.06	1.38279
3085.62	0.576096
3088.17	0.721132
3090.73	0.909763
3093.29	0.544568
3095.84	0.699504
3098.4	1.57185
3100.95	2.39844
3103.5	3.82363
3106.05	5.00087
3108.6	6.44558
3111.15	7.32576
3113.7	8.55056
3116.25	10.0144
3118.79	11.0195
3121.34	12.1019
3123.88	12.8479
3126.43	13.8545
3128.97	14.9698
3131.51	16.4938
3134.05	17.7763
3136.59	19.8803
3139.14	20.1661
3141.67	20.26
3144.21	19.8701
3146.75	19.5382
3149.28	18.3376