File: data/Raman/poly_smoothed/Mb_10_14_37_1x_45s_532 nm_x100_100%_600 gr_mm_01.txt
#Acq. time (s)=	45
#Accumulations=	2
#Range (cm-¹)=	200...3150
#Windows=	2
#Auto scanning=	Off
#Autofocus=	Off
#Macrospot=	Off
#AutoExposure=	Off
#Spike filter=	Multiple accum.
#Delay time (s)=	0
#Binning=	1
#Readout mode=	Signal
#DeNoise=	Off
#ICS correction=	On
#Dark correction=	Off
#Inst. Process=	Off
#Detector Gain=	Best Dynamic Range
#Detector ADC=	20 kHz
#Detector temperature (°C)=	-69.85
#Instrument=	LabRAM HR Evol
#Detector=	Synapse
#Objective=	x100
#Grating=	600 gr/mm
#ND Filter=	100%
#Laser (nm)=	532
#Hole=	100.021
#Range=	Auto
#Laser Pol.=	No
#Raman. Pol.=	No
#Laser Pol. (°)=	-0.0007625
#Raman Pol. (°)=	89.9995
#Collection=	Microscope
#StageXY=	Marzhauser
#StageZ=	Marzhauser
#X (µm)=	-626
#Y (µm)=	-1671.5
#Z (µm)=	89.55
#Full time(mm:ss)=	3:18
#Project=
#Sample=
#Site=
#Title=	Mb_10_14_37_2x_45s_532 nm_x100_100%_600 gr_mm
#Remark=
#Date=	11.07.2022 11:22
#Acquired=	11.07.2022 11:22:03
#Edit:Spike=	11.07.2022 11:29:36
#Base:Fit=	10.08.2022 10:21:11
#Base:Sub=	10.08.2022 10:21:41
#Filter:Polynom=	16.08.2022 10:17:53
#AxisType[0]=Intens
#AxisUnit[0]=Cnt
#AxisType[1]=Spectr
#AxisUnit[1]=1/cm
200.388	8.05158
204.019	5.78401
207.646	5.22141
211.274	3.93721
214.899	4.62386
218.524	6.37578
222.146	8.08489
225.766	10.2996
229.388	10.2518
233.005	12.1196
236.621	14.0555
240.236	15.0581
243.852	16.3365
247.464	18.3436
251.074	19.5489
254.683	20.1968
258.291	19.3641
261.897	20.3351
265.504	23.1433
269.108	23.5126
272.71	24.6522
276.311	24.1664
279.91	23.3425
283.508	21.3057
287.105	20.3056
290.698	20.281
294.291	18.727
297.884	17.2785
301.475	17.7027
305.064	17.2596
308.652	17.8882
312.237	17.712
315.822	16.071
319.406	17.0069
322.987	17.3459
326.568	17.2216
330.148	16.0239
333.724	15.6821
337.301	14.7998
340.875	14.8615
344.449	14.1368
348.02	15.7866
351.592	16.8702
355.16	18.4662
358.728	19.6067
362.294	22.1748
365.858	21.9349
369.422	22.11
372.983	24.4076
376.543	26.2638
380.102	26.459
383.661	26.4489
387.216	26.4967
390.771	26.9196
394.324	28.1846
397.875	27.9374
401.425	25.7937
404.974	24.7877
408.524	24.0118
412.07	21.6728
415.614	18.3277
419.156	14.7527
422.698	13.4742
426.238	11.1427
429.777	8.13955
433.315	7.98742
436.852	7.87886
440.387	4.95911
443.919	4.15722
447.451	5.18413
450.982	4.22984
454.512	3.14009
458.038	4.28177
461.565	3.38779
465.091	3.38615
468.613	3.54559
472.136	5.35822
475.655	6.67865
479.176	7.48545
482.692	5.669
486.21	5.93505
489.724	7.11785
493.237	7.5632
496.75	8.88062
500.26	9.42119
503.769	9.33362
507.279	10.9382
510.785	11.7182
514.289	13.1313
517.793	13.3871
521.297	14.6453
524.797	13.4186
528.297	13.799
531.795	15.2482
535.291	15.7511
538.787	14.9293
542.281	16.7768
545.773	16.1586
549.264	16.553
552.754	16.1863
556.243	16.4594
559.73	14.5492
563.216	12.2923
566.701	9.9565
570.182	9.2133
573.664	8.66815
577.145	7.2347
580.624	7.03146
584.1	6.66899
587.577	4.6456
591.052	4.46512
594.524	2.06289
597.997	1.28554
601.466	0.628538
604.936	1.04278
608.403	0.00608989
611.87	0.0829109
615.334	2.36585
618.799	3.09934
622.26	4.93692
625.72	6.1189
629.181	7.52949
632.638	8.35647
636.095	8.32852
639.551	9.23591
643.005	10.5926
646.457	10.0481
649.908	10.6213
653.357	11.5932
656.806	12.1221
660.253	12.2086
663.7	13.1971
667.145	12.4609
670.588	11.0523
674.027	12.1796
677.468	10.2805
680.907	9.89028
684.345	10.2089
687.781	9.79317
691.216	10.5112
694.65	11.5907
698.081	15.4056
701.512	17.0147
704.942	19.5603
708.371	20.5293
711.796	22.057
715.222	23.5191
718.645	24.3672
722.068	26.7728
725.49	27.9548
728.909	29.5345
732.329	30.452
735.745	32.7196
739.16	35.1408
742.576	35.2823
745.988	36.2529
749.401	36.9225
752.811	40.9791
756.22	42.7468
759.627	44.597
763.035	46.6812
766.44	49.9533
769.843	52.7753
773.245	56.328
776.646	59.4821
780.046	63.2936
783.444	65.5382
786.841	65.8377
790.237	67.6634
793.631	68.5695
797.024	70.0513
800.416	71.2168
803.807	71.5881
807.196	70.0459
810.584	70.5563
813.971	68.415
817.354	68.1685
820.739	65.8728
824.122	64.1206
827.503	64.8203
830.882	63.6971
834.261	63.2431
837.637	61.7082
841.013	60.474
844.389	60.3096
847.761	59.9528
851.131	59.9765
854.503	58.9871
857.871	57.3029
861.24	54.6841
864.606	52.9724
867.97	52.3485
871.336	51.4815
874.698	50.1134
878.058	50.1965
881.418	50.5984
884.778	49.0229
888.135	49.5901
891.49	48.4249
894.845	47.6986
898.198	48.1915
901.55	48.9163
904.901	49.1132
908.25	48.6506
911.598	47.1767
914.945	45.6506
918.291	46.1644
921.635	45.3492
924.978	45.4547
928.318	44.9584
931.659	45.1802
934.998	44.7561
938.336	41.2524
941.671	38.0903
945.007	36.7465
948.339	35.2034
951.672	33.2005
955.004	33.0185
958.333	32.639
961.662	32.2679
964.989	31.2826
968.315	30.0151
971.639	30.771
974.962	30.681
978.285	30.5748
981.605	31.3817
984.924	28.8536
988.243	27.1603
991.56	26.5256
994.875	25.5908
998.188	26.1791
1001.5	26.4143
1004.81	24.282
1008.12	24.147
1011.43	24.076
1014.74	25.306
1018.05	24.9681
1021.35	25.4501
1024.65	27.4916
1027.96	28.7322
1031.26	29.3486
1034.56	30.4493
1037.86	31.9701
1041.16	31.8159
1044.45	31.3552
1047.75	32.9323
1051.04	32.3038
1054.33	30.6382
1057.62	29.6405
1060.91	27.5882
1064.2	26.2327
1067.49	22.9317
1070.77	20.7596
1074.06	19.7672
1077.34	17.399
1080.62	16.4722
1083.91	14.2375
1087.18	12.4228
1090.46	12.7656
1093.74	11.6049
1097.02	10.7953
1100.29	10.5102
1103.56	10.3187
1106.84	9.78277
1110.11	9.24474
1113.38	8.68175
1116.64	8.29078
1119.91	7.8245
1123.18	5.06203
1126.44	6.36277
1129.7	3.7371
1132.97	2.70916
1136.23	3.18939
1139.49	3.28714
1142.74	4.05625
1146	3.48707
1149.26	3.15464
1152.51	2.96625
1155.76	2.98875
1159.01	3.20754
1162.27	4.4454
1165.51	2.13073
1168.76	2.26111
1172.01	2.96308
1175.25	2.85805
1178.5	3.65252
1181.74	4.68504
1184.98	5.4392
1188.22	6.87498
1191.46	7.6472
1194.7	9.4198
1197.94	9.76355
1201.17	8.6555
1204.41	9.89303
1207.64	11.3533
1210.87	12.8622
1214.1	15.1698
1217.33	15.7309
1220.56	16.2631
1223.79	18.7794
1227.01	20.1894
1230.23	20.9434
1233.46	20.6385
1236.68	23.6267
1239.9	23.1696
1243.12	22.7522
1246.34	23.6275
1249.55	24.4582
1252.77	23.9509
1255.98	24.9515
1259.2	25.0454
1262.41	26.313
1265.62	26.6688
1268.83	27.4243
1272.03	27.4723
1275.24	27.1806
1278.45	27.2168
1281.65	29.2355
1284.85	29.9982
1288.06	30.7158
1291.26	32.5363
1294.46	32.5704
1297.66	33.7504
1300.85	36.2671
1304.05	37.4141
1307.24	38.9014
1310.43	38.6403
1313.63	39.5871
1316.82	39.3565
1320.01	39.3784
1323.2	40.2674
1326.38	39.3965
1329.57	38.4579
1332.76	37.4288
1335.94	37.2613
1339.12	36.3637
1342.3	34.0508
1345.48	32.0966
1348.66	32.1428
1351.84	31.9368
1355.01	29.4742
1358.19	27.8932
1361.36	25.2269
1364.53	24.5622
1367.71	23.1525
1370.88	22.9031
1374.04	22.8593
1377.21	21.787
1380.38	22.0923
1383.54	21.7886
1386.71	22.3559
1389.87	21.2763
1393.03	21.5858
1396.19	21.3032
1399.35	21.8977
1402.51	22.282
1405.67	23.429
1408.82	23.488
1411.98	23.6356
1415.13	26.2531
1418.28	28.6086
1421.43	30.9689
1424.58	34.7212
1427.73	37.1454
1430.88	41.6943
1434.02	45.714
1437.17	49.2701
1440.31	52.4276
1443.45	53.3832
1446.6	53.8041
1449.74	55.9284
1452.87	55.2405
1456.01	51.923
1459.15	50.9145
1462.28	47.5812
1465.42	45.211
1468.55	42.3882
1471.68	39.76
1474.81	36.8642
1477.94	33.2898
1481.07	30.8204
1484.2	27.7504
1487.32	24.9105
1490.45	22.0303
1493.57	21.1809
1496.69	20.5261
1499.81	19.774
1502.93	18.668
1506.05	18.0534
1509.17	18.3257
1512.28	17.146
1515.4	15.2417
1518.51	12.6679
1521.63	11.3441
1524.74	10.8714
1527.85	9.52829
1530.96	7.20062
1534.06	5.93438
1537.17	6.35131
1540.28	8.03915
1543.38	8.27055
1546.48	9.94261
1549.59	10.8914
1552.69	11.1276
1555.79	11.4451
1558.88	12.8718
1561.98	13.5061
1565.08	15.5366
1568.17	16.7903
1571.27	18.8635
1574.36	21.1198
1577.45	21.6854
1580.54	23.9265
1583.63	25.2703
1586.72	26.1303
1589.8	26.7332
1592.89	26.2323
1595.97	28.8528
1599.06	30.0744
1602.14	32.5863
1605.22	32.1435
1608.3	31.6963
1611.38	32.0797
1614.46	31.8498
1617.53	32.5393
1620.61	32.2478
1623.68	32.9913
1626.75	31.2887
1629.82	33.1548
1632.9	34.2918
1635.96	35.8086
1639.03	37.7501
1642.1	38.3606
1645.16	39.7335
1648.23	40.3073
1651.29	41.0311
1654.36	40.6587
1657.42	39.5508
1660.48	39.5607
1663.53	38.6679
1666.59	37.7009
1669.65	38.0351
1672.7	37.5779
1675.76	34.3353
1678.81	31.3905
1681.86	28.0064
1684.91	23.2404
1687.96	20.7191
1691.01	17.9787
1694.06	13.6734
1697.11	10.6121
1700.15	7.53062
1703.2	6.44217
1706.24	5.38683
1709.28	5.89242
1712.32	5.96747
1715.36	5.29473
1718.4	3.19605
1721.43	2.87302
1724.47	2.4126
1727.5	1.17028
1730.54	1.34845
1733.57	1.12423
1736.6	1.51859
1739.63	2.32262
1742.66	2.49358
1745.69	2.80604
1748.72	2.90152
1751.74	2.01437
1754.77	2.21382
1757.79	2.05906
1760.81	1.84957
1763.83	1.6573
1766.85	1.0622
1769.87	1.11426
1772.89	2.00768
1775.91	3.59859
1778.92	3.96495
1781.94	5.20269
1784.95	5.99985
1787.96	6.46711
1790.97	5.83845
1793.98	5.9323
1796.99	6.15002
1800	6.43749
1803	5.94436
1806.01	5.4336
1809.01	5.38489
1812.02	6.47119
1815.02	5.73489
1818.02	4.88741
1821.02	4.386
1824.02	4.27827
1827.01	3.29265
1830.01	2.47963
1833	2.80625
1836	2.02287
1838.99	2.47244
1841.98	3.02411
1844.97	3.66724
1847.96	4.50516
1850.95	5.4013
1853.94	5.05306
1856.92	6.15799
1859.91	6.10687
1862.89	5.47452
1865.88	5.21353
1868.86	6.12143
1871.84	6.31693
1874.82	6.75206
1877.8	7.4243
1880.77	7.71718
1882.52	7.54213
1885.51	7.09486
1888.5	5.7819
1891.49	5.62181
1894.47	6.57516
1897.46	6.44757
1900.44	5.88721
1903.42	7.10094
1906.4	8.81756
1909.38	9.16017
1912.36	9.44866
1915.34	10.571
1918.32	10.9323
1921.29	10.6226
1924.27	10.1909
1927.24	9.51036
1930.21	9.50872
1933.18	7.80528
1936.15	8.07266
1939.12	8.04018
1942.09	8.91558
1945.06	7.9143
1948.02	7.79762
1950.99	7.94098
1953.95	7.28812
1956.91	6.15917
1959.87	5.21029
1962.84	5.21532
1965.79	6.07905
1968.75	5.90691
1971.71	6.309
1974.66	7.06776
1977.62	7.38023
1980.57	7.9766
1983.53	8.66108
1986.48	9.91267
1989.43	11.2213
1992.38	11.2176
1995.33	11.4746
1998.27	11.3816
2001.22	11.6716
2004.16	13.0907
2007.11	14.8058
2010.05	14.5581
2012.99	14.7454
2015.93	15.6372
2018.87	15.4395
2021.81	15.3954
2024.75	14.5353
2027.69	13.646
2030.62	12.6866
2033.56	12.6888
2036.49	12.85
2039.42	13.2109
2042.35	12.0787
2045.28	11.1338
2048.21	9.39249
2051.14	8.73395
2054.06	8.06524
2056.99	7.81352
2059.92	6.96867
2062.84	6.44098
2065.76	5.89585
2068.68	7.37568
2071.6	6.16744
2074.52	6.34219
2077.44	6.40508
2080.36	6.50842
2083.27	6.26122
2086.19	7.64955
2089.1	8.63499
2092.01	8.89692
2094.93	8.29883
2097.84	8.59821
2100.75	9.66238
2103.66	11.4848
2106.56	12.5091
2109.47	12.9126
2112.37	12.1586
2115.28	12.9407
2118.18	13.2551
2121.09	12.5147
2123.99	13.4246
2126.89	15.3566
2129.79	16.7609
2132.68	16.6611
2135.58	16.9712
2138.48	18.2698
2141.37	19.5753
2144.26	19.7238
2147.16	21.6361
2150.05	23.4279
2152.94	24.8944
2155.83	26.2963
2158.72	28.3083
2161.6	27.7973
2164.49	27.8492
2167.38	27.9394
2170.26	28.8055
2173.14	28.1721
2176.03	28.386
2178.91	26.3114
2181.79	25.0951
2184.67	23.9003
2187.54	23.1826
2190.42	21.8708
2193.3	19.3873
2196.17	18.9426
2199.05	18.5491
2201.92	17.1754
2204.79	16.0927
2207.66	16.9244
2210.53	17.6188
2213.4	16.8678
2216.27	16.6547
2219.13	16.6054
2222	17.2371
2224.86	18.335
2227.72	19.7399
2230.59	19.4987
2233.45	18.785
2236.31	18.8921
2239.17	17.9137
2242.03	15.7401
2244.88	15.0786
2247.74	13.9467
2250.59	12.9002
2253.45	11.822
2256.3	11.4559
2259.15	10.7322
2262	10.2246
2264.85	10.1817
2267.7	10.8005
2270.55	11.5229
2273.4	11.6622
2276.24	12.1538
2279.09	11.5691
2281.93	11.0916
2284.77	11.5936
2287.61	13.1988
2290.46	13.3505
2293.29	13.2672
2296.13	12.9172
2298.97	14.382
2301.81	13.0859
2304.64	13.2257
2307.48	12.4259
2310.31	10.5879
2313.14	10.0308
2315.97	10.3035
2318.8	10.1406
2321.63	8.88499
2324.46	8.13852
2327.29	9.62699
2330.12	9.54379
2332.94	9.37344
2335.76	10.675
2338.59	10.5696
2341.41	10.0187
2344.23	9.60122
2347.05	8.39526
2349.87	8.42227
2352.69	9.30392
2355.5	8.03188
2358.32	6.24049
2361.14	5.48043
2363.95	5.44556
2366.76	7.07634
2369.58	6.36956
2372.39	5.66007
2375.2	4.53719
2378	3.92494
2380.81	5.22329
2383.62	5.14883
2386.42	4.78881
2389.23	5.04705
2392.03	5.57269
2394.84	7.18596
2397.64	7.4937
2400.44	8.26786
2403.24	9.34558
2406.04	10.51
2408.83	9.60148
2411.63	9.11355
2414.43	9.58091
2417.22	8.45351
2420.02	8.90675
2422.81	8.66849
2425.6	7.6452
2428.39	8.85124
2431.18	8.1466
2433.97	8.62397
2436.76	8.13447
2439.54	6.9303
2442.33	7.17775
2445.11	6.38186
2447.9	4.91457
2450.68	4.6867
2453.46	2.81357
2456.24	2.89667
2459.02	2.75664
2461.8	2.89079
2464.58	2.0313
2467.36	1.06121
2470.13	1.84786
2472.91	2.99075
2475.68	2.5207
2478.45	1.34577
2481.22	1.43315
2484	1.53537
2486.77	1.64705
2489.54	2.38574
2492.3	2.6567
2495.07	2.57477
2497.84	2.10802
2500.6	3.11641
2503.36	3.31918
2506.13	2.38468
2508.89	1.73614
2511.65	2.59288
2514.41	2.40265
2517.17	1.74983
2519.93	2.20644
2522.68	1.91509
2525.44	2.28477
2528.19	2.22497
2530.95	2.02645
2533.7	2.00886
2536.45	2.81034
2539.2	2.76206
2541.95	3.31121
2544.7	3.88951
2547.45	4.4537
2550.2	5.09877
2552.94	5.26298
2555.69	4.44451
2558.43	5.66026
2561.17	4.99089
2563.92	6.7979
2566.66	6.92092
2569.4	6.85149
2572.14	7.38226
2574.88	8.75113
2577.61	8.60126
2580.35	9.6057
2583.09	8.53967
2585.82	7.86226
2588.55	8.21647
2591.28	7.33102
2594.02	6.76774
2596.75	6.33754
2599.48	5.70683
2602.2	5.40585
2604.93	4.3766
2607.66	4.11581
2610.38	4.14165
2613.11	3.84286
2615.83	2.84144
2618.56	3.47182
2621.28	3.78211
2624	2.93054
2626.72	3.85935
2629.44	4.07792
2632.15	2.94248
2634.87	2.94881
2637.59	2.85619
2640.3	3.81031
2643.02	3.86011
2645.73	4.80449
2648.44	4.94272
2651.15	4.89118
2653.86	5.37622
2656.57	5.3559
2659.28	4.13515
2661.99	3.95248
2664.69	4.73566
2667.4	4.86487
2670.1	4.79062
2672.81	3.68631
2675.51	3.96807
2678.21	3.89367
2680.91	4.51064
2683.61	5.14861
2686.31	5.33672
2689	4.41075
2691.7	5.33515
2694.4	5.14752
2697.09	3.81462
2699.79	3.49437
2702.48	3.99749
2705.17	6.03347
2707.86	7.77473
2710.55	8.36692
2713.24	8.8281
2715.93	9.49478
2718.61	9.44986
2721.3	8.54104
2723.99	7.42352
2726.67	6.66294
2729.35	7.23813
2732.04	6.77934
2734.72	5.9838
2737.4	5.9283
2740.08	5.60101
2742.76	5.38463
2745.43	5.49336
2748.11	5.88529
2750.79	5.07149
2753.46	4.87737
2756.13	3.65484
2758.81	2.85213
2761.48	2.3403
2764.15	1.87152
2766.82	3.17205
2769.49	3.9914
2772.16	5.01241
2774.82	4.78039
2777.49	4.20641
2780.16	4.8286
2782.82	4.50726
2785.48	3.28929
2788.15	3.38353
2790.81	3.27139
2793.47	2.46889
2796.13	2.73472
2798.79	3.28175
2801.44	2.93362
2804.1	3.05494
2806.76	2.11595
2809.41	1.58125
2812.07	1.10376
2814.72	0.341662
2817.37	0.975632
2820.02	1.62366
2822.67	3.42271
2825.32	4.93805
2827.97	6.91902
2830.62	9.2944
2833.26	11.9809
2835.91	16.2851
2838.55	20.091
2841.2	25.0694
2843.84	30.5787
2846.48	36.6213
2849.12	42.2009
2851.76	49.0392
2854.4	56.3999
2857.04	62.1595
2859.68	67.8231
2862.32	74.294
2864.95	78.9269
2867.58	82.27
2870.22	86.0305
2872.85	88.9115
2875.48	92.8398
2878.11	96.9646
2880.74	100.287
2883.37	103.849
2886	106.574
2888.63	107.797
2891.25	108.338
2893.88	109.958
2896.5	112.595
2899.13	115.667
2901.75	118.13
2904.37	122.788
2906.99	127.654
2909.61	132.729
2912.23	139.176
2914.85	145.574
2917.46	151.542
2920.08	155.153
2922.7	157.997
2925.31	160.218
2927.92	160.201
2930.53	161.039
2933.15	161.667
2935.76	161.196
2938.37	158.791
2940.98	156.022
2943.58	152.554
2946.19	147.107
2948.8	140.691
2951.4	134.974
2954.01	128.304
2956.61	123.326
2959.21	118.596
2961.81	111.93
2964.41	104.814
2967.01	99.8127
2969.61	94.8008
2972.21	90.1101
2974.81	87.794
2977.4	82.7555
2980	77.294
2982.59	71.5548
2985.18	65.5688
2987.78	59.4851
2990.37	54.4634
2992.96	49.6281
2995.55	44.5296
2998.14	38.9884
3000.72	35.1921
3003.31	31.185
3005.9	26.797
3008.48	23.2
3011.07	19.1946
3013.65	15.9324
3016.23	14.5831
3018.81	13.6224
3021.39	11.4813
3023.97	8.25393
3026.55	5.0655
3029.13	3.49792
3031.71	4.08379
3034.28	4.17807
3036.86	4.40686
3039.43	4.79738
3042.01	5.3041
3044.58	6.09731
3047.15	6.29377
3049.72	6.44965
3052.29	7.78115
3054.86	7.33467
3057.43	8.19214
3060	8.66775
3062.56	9.62649
3065.13	9.56986
3067.69	9.12878
3070.25	9.44675
3072.82	8.19179
3075.38	7.77977
3077.94	8.38799
3080.5	6.76402
3083.06	4.99058
3085.62	2.9511
3088.17	1.39237
3090.73	0.541228
3093.29	1.05271
3095.84	1.23942
3098.4	0.817359
3100.95	1.10428
3103.5	2.08894
3106.05	2.21904
3108.6	2.74091
3111.15	1.89918
3113.7	1.81032
3116.25	2.44709
3118.79	2.99062
3121.34	3.79812
3123.88	3.60538
3126.43	4.2092
3128.97	5.05216
3131.51	5.4678
3134.05	5.3299
3136.59	5.55278
3139.14	5.65918
3141.67	5.56362
3144.21	6.10078
3146.75	7.35489
3149.28	8.69038