File: data/Raman/poly_smoothed/Mb_10_14_29_1x_45s_532 nm_x100_100%_600 gr_mm_01.txt
#Acq. time (s)=	45
#Accumulations=	2
#Range (cm-¹)=	200...3150
#Windows=	2
#Auto scanning=	Off
#Autofocus=	Off
#Macrospot=	Off
#AutoExposure=	Off
#Spike filter=	Multiple accum.
#Delay time (s)=	0
#Binning=	1
#Readout mode=	Signal
#DeNoise=	Off
#ICS correction=	On
#Dark correction=	Off
#Inst. Process=	Off
#Detector Gain=	Best Dynamic Range
#Detector ADC=	20 kHz
#Detector temperature (°C)=	-69.85
#Instrument=	LabRAM HR Evol
#Detector=	Synapse
#Objective=	x100
#Grating=	600 gr/mm
#ND Filter=	100%
#Laser (nm)=	532
#Hole=	100.021
#Range=	Auto
#Laser Pol.=	No
#Raman. Pol.=	No
#Laser Pol. (°)=	-0.0007625
#Raman Pol. (°)=	89.9995
#Collection=	Microscope
#StageXY=	Marzhauser
#StageZ=	Marzhauser
#X (µm)=	-615.9
#Y (µm)=	-1600
#Z (µm)=	89.8
#Full time(mm:ss)=	3:18
#Project=
#Sample=
#Site=
#Title=	Mb_10_14_29_2x_45s_532 nm_x100_100%_600 gr_mm
#Remark=
#Date=	11.07.2022 10:40
#Acquired=	11.07.2022 10:40:54
#Base:Fit=	10.08.2022 10:21:11
#Base:Sub=	10.08.2022 10:21:41
#Filter:Polynom=	16.08.2022 10:17:53
#AxisType[0]=Intens
#AxisUnit[0]=Cnt
#AxisType[1]=Spectr
#AxisUnit[1]=1/cm
200.388	13.3369
204.019	13.7115
207.646	11.7965
211.274	9.86654
214.899	9.23749
218.524	8.9005
222.146	11.6232
225.766	13.3848
229.388	16.0554
233.005	16.3196
236.621	18.4079
240.236	21.3646
243.852	22.1219
247.464	22.8276
251.074	22.5927
254.683	24.7524
258.291	27.7253
261.897	27.7255
265.504	27.1076
269.108	26.553
272.71	25.7171
276.311	23.2654
279.91	20.5656
283.508	16.9478
287.105	13.8341
290.698	10.289
294.291	9.07947
297.884	7.56003
301.475	6.24659
305.064	6.20496
308.652	4.46219
312.237	5.39795
315.822	4.741
319.406	2.71963
322.987	4.17685
326.568	4.93955
330.148	5.44976
333.724	4.37912
337.301	5.83972
340.875	7.25056
344.449	7.16761
348.02	7.40541
351.592	9.40451
355.16	10.5353
358.728	10.9372
362.294	12.7106
365.858	15.1935
369.422	18.8806
372.983	20.8238
376.543	23.2582
380.102	27.0913
383.661	29.9043
387.216	32.3377
390.771	34.7002
394.324	36.0993
397.875	38.5581
401.425	38.4246
404.974	38.4474
408.524	38.3832
412.07	38.3395
415.614	36.2446
419.156	33.6173
422.698	32.4076
426.238	30.7774
429.777	28.3551
433.315	25.9332
436.852	24.0885
440.387	19.8598
443.919	16.0399
447.451	14.0182
450.982	13.3956
454.512	13.675
458.038	14.945
461.565	14.416
465.091	15.7744
468.613	18.8282
472.136	19.947
475.655	20.0537
479.176	21.0908
482.692	22.9188
486.21	24.7021
489.724	26.3571
493.237	27.6275
496.75	29.768
500.26	31.5987
503.769	33.876
507.279	34.6673
510.785	34.8851
514.289	34.3245
517.793	32.3337
521.297	30.2435
524.797	28.9606
528.297	26.5822
531.795	24.6573
535.291	23.36
538.787	22.1929
542.281	20.1593
545.773	17.55
549.264	16.3681
552.754	14.6231
556.243	11.1145
559.73	7.91635
563.216	5.06781
566.701	3.11861
570.182	3.08354
573.664	2.71425
577.145	1.61319
580.624	1.67887
584.1	3.15069
587.577	2.456
591.052	1.75866
594.524	-0.360979
597.997	-0.28925
601.466	0.250634
604.936	-0.268419
608.403	0.139707
611.87	0.433116
615.334	0.35427
618.799	2.53017
622.26	2.81138
625.72	1.53524
629.181	2.07619
632.638	3.21183
636.095	4.6605
639.551	2.7992
643.005	2.13503
646.457	2.31606
649.908	2.60551
653.357	2.16842
656.806	3.16498
660.253	3.69493
663.7	3.82867
667.145	5.64497
670.588	5.53942
674.027	4.64283
677.468	4.62301
680.907	5.8338
684.345	5.41619
687.781	6.30884
691.216	7.39271
694.65	8.2239
698.081	9.66887
701.512	11.6919
704.942	13.4654
708.371	14.8217
711.796	16.5289
715.222	17.4052
718.645	19.0538
722.068	19.807
725.49	20.7316
728.909	21.3695
732.329	21.9616
735.745	23.4178
739.16	18.9721
742.576	23.2278
745.988	26.9717
749.401	32.6445
752.811	36.5952
756.22	40.253
759.627	44.839
763.035	49.2077
766.44	52.919
769.843	56.9393
773.245	62.037
776.646	64.6151
780.046	67.6164
783.444	69.4823
786.841	71.3414
790.237	73.8963
793.631	73.936
797.024	73.9757
800.416	74.8764
803.807	74.3246
807.196	72.6008
810.584	71.9003
813.971	69.1895
817.354	65.5641
820.739	62.0992
824.122	65.0709
827.503	68.7638
830.882	68.1566
834.261	69.3408
837.637	68.4322
841.013	66.08
844.389	66.9225
847.761	65.5363
851.131	63.5762
854.503	61.0073
857.871	59.4924
861.24	56.0578
864.606	55.0538
867.97	52.2871
871.336	51.5037
874.698	50.1698
878.058	48.7998
881.418	48.4034
884.778	47.7428
888.135	45.642
891.49	46.9873
894.845	46.6383
898.198	46.4987
901.55	47.6293
904.901	49.0408
908.25	49.5065
911.598	47.7163
914.945	48.1534
918.291	48.2348
921.635	48.008
924.978	49.1492
928.318	49.5077
931.659	47.6093
934.998	47.4689
938.336	48.032
941.671	46.4288
945.007	46.6162
948.339	46.1341
951.672	46.5341
955.004	46.8525
958.333	46.1777
961.662	45.3556
964.989	47.5828
968.315	50.1689
971.639	54.8085
974.962	55.9573
978.285	57.4682
981.605	57.3088
984.924	56.9177
988.243	55.2276
991.56	53.4889
994.875	51.0589
998.188	48.2837
1001.5	47.6283
1004.81	46.3983
1008.12	44.013
1011.43	41.9351
1014.74	41.9224
1018.05	41.4149
1021.35	41.23
1024.65	40.9431
1027.96	41.0958
1031.26	40.9386
1034.56	41.8345
1037.86	43.7619
1041.16	44.9143
1044.45	46.4237
1047.75	49.6967
1051.04	49.9899
1054.33	50.9959
1057.62	46.971
1060.91	44.766
1064.2	41.578
1067.49	37.3116
1070.77	32.9554
1074.06	28.3311
1077.34	24.7705
1080.62	22.0639
1083.91	20.4059
1087.18	19.9989
1090.46	19.8876
1093.74	21.2864
1097.02	20.857
1100.29	20.9127
1103.56	21.5153
1106.84	21.4894
1110.11	21.4826
1113.38	22.0477
1116.64	23.4254
1119.91	22.7887
1123.18	23.5725
1126.44	23.5668
1129.7	22.4679
1132.97	21.4888
1136.23	19.9483
1139.49	16.1329
1142.74	16.1513
1146	12.8882
1149.26	10.5942
1152.51	8.18486
1155.76	7.48427
1159.01	6.36209
1162.27	5.66772
1165.51	4.72142
1168.76	3.44222
1172.01	1.66963
1175.25	2.04454
1178.5	1.03611
1181.74	1.06794
1184.98	2.24088
1188.22	1.33017
1191.46	1.66423
1194.7	3.46271
1197.94	5.93509
1201.17	6.19517
1204.41	7.44919
1207.64	8.69789
1210.87	11.4686
1214.1	13.2757
1217.33	14.9943
1220.56	17.0127
1223.79	21.3866
1227.01	24.5633
1230.23	26.5613
1233.46	28.7396
1236.68	32.39
1239.9	32.4328
1243.12	34.7754
1246.34	36.7962
1249.55	38.2937
1252.77	39.5123
1255.98	41.2168
1259.2	41.9604
1262.41	42.2845
1265.62	44.0488
1268.83	44.1865
1272.03	45.4878
1275.24	49.513
1278.45	50.1121
1281.65	51.233
1284.85	52.2327
1288.06	54.0218
1291.26	54.9533
1294.46	56.9206
1297.66	57.6776
1300.85	59.9077
1304.05	62.2959
1307.24	63.8157
1310.43	63.7503
1313.63	66.3346
1316.82	66.2048
1320.01	67.0832
1323.2	67.8798
1326.38	67.2594
1329.57	66.3015
1332.76	67.0376
1335.94	66.3379
1339.12	64.9478
1342.3	64.4423
1345.48	63.4013
1348.66	61.0602
1351.84	59.7726
1355.01	57.3288
1358.19	54.0894
1361.36	51.3605
1364.53	48.778
1367.71	46.9501
1370.88	44.1399
1374.04	42.0931
1377.21	41.5415
1380.38	40.9395
1383.54	39.3682
1386.71	37.7822
1389.87	38.5207
1393.03	38.3608
1396.19	37.7727
1399.35	38.5482
1402.51	39.4923
1405.67	39.5605
1408.82	42.4871
1411.98	45.3088
1415.13	48.9474
1418.28	52.2585
1421.43	58.1109
1424.58	61.5626
1427.73	66.9714
1430.88	71.9949
1434.02	78.0523
1437.17	83.7813
1440.31	88.445
1443.45	92.3959
1446.6	96.5644
1449.74	98.4253
1452.87	99.075
1456.01	99.2342
1459.15	96.9244
1462.28	94.0565
1465.42	90.7968
1468.55	86.6994
1471.68	81.1087
1474.81	75.5302
1477.94	71.901
1481.07	66.5037
1484.2	61.0426
1487.32	58.3709
1490.45	54.8916
1493.57	50.2093
1496.69	46.4622
1499.81	42.7494
1502.93	39.58
1506.05	36.4658
1509.17	33.2204
1512.28	31.3539
1515.4	28.2546
1518.51	26.0644
1521.63	25.1368
1524.74	22.4757
1527.85	22.0838
1530.96	20.0526
1534.06	18.9897
1537.17	20.0292
1540.28	20.4267
1543.38	21.4328
1546.48	22.2556
1549.59	24.3299
1552.69	27.7317
1555.79	30.1263
1558.88	33.2401
1561.98	35.534
1565.08	36.0296
1568.17	38.6404
1571.27	41.8282
1574.36	44.4467
1577.45	46.7954
1580.54	49.0306
1583.63	51.7855
1586.72	53.7866
1589.8	55.3698
1592.89	56.1993
1595.97	57.0432
1599.06	55.8718
1602.14	56.1206
1605.22	54.9855
1608.3	53.9971
1611.38	53.0956
1614.46	51.9387
1617.53	50.6861
1620.61	50.4728
1623.68	50.0778
1626.75	52.5467
1629.82	51.8855
1632.9	52.5547
1635.96	54.3052
1639.03	55.3372
1642.1	57.3092
1645.16	60.5163
1648.23	63.257
1651.29	64.424
1654.36	66.2096
1657.42	68.6661
1660.48	70.3043
1663.53	69.6501
1666.59	67.4382
1669.65	65.7517
1672.7	61.2152
1675.76	58.3021
1678.81	54.422
1681.86	49.9174
1684.91	46.0234
1687.96	41.3429
1691.01	37.1286
1694.06	33.7958
1697.11	29.9941
1700.15	25.7352
1703.2	21.3751
1706.24	16.8313
1709.28	16.0322
1712.32	13.1401
1715.36	10.5186
1718.4	8.65574
1721.43	8.68985
1724.47	8.86002
1727.5	8.59664
1730.54	9.09092
1733.57	8.96514
1736.6	9.18347
1739.63	7.73667
1742.66	8.27252
1745.69	7.47151
1748.72	6.52813
1751.74	7.8876
1754.77	8.48352
1757.79	8.6422
1760.81	9.53863
1763.83	8.50711
1766.85	7.15207
1769.87	5.70914
1772.89	4.22635
1775.91	3.87618
1778.92	2.90342
1781.94	2.73624
1784.95	3.16701
1787.96	2.75531
1790.97	2.03131
1793.98	2.36539
1796.99	3.7148
1800	2.66516
1803	2.29844
1806.01	2.04027
1809.01	2.53365
1812.02	3.21527
1815.02	3.30324
1818.02	3.18929
1821.02	3.13694
1824.02	4.23001
1827.01	5.05974
1830.01	4.94424
1833	4.07032
1836	3.17817
1838.99	2.05134
1841.98	1.75169
1844.97	2.17913
1847.96	1.81023
1850.95	2.62238
1853.94	2.61319
1856.92	2.80286
1859.91	3.05489
1862.89	3.03204
1865.88	2.4574
1868.86	1.70137
1871.84	2.03007
1874.82	2.58276
1877.8	4.52255
1880.77	5.1926
1882.52	5.22324
1885.51	4.73631
1888.5	4.56498
1891.49	4.27189
1894.47	5.08183
1897.46	4.79536
1900.44	4.785
1903.42	4.89492
1906.4	5.41393
1909.38	5.44697
1912.36	5.6607
1915.34	6.82233
1918.32	7.11978
1921.29	8.19332
1924.27	8.70957
1927.24	9.00881
1930.21	8.25619
1933.18	8.27151
1936.15	7.50742
1939.12	7.8619
1942.09	7.88424
1945.06	9.36663
1948.02	8.99577
1950.99	7.77954
1953.95	6.29063
1956.91	5.29625
1959.87	3.75216
1962.84	2.49774
1965.79	1.73143
1968.75	1.66798
1971.71	1.2279
1974.66	1.48872
1977.62	2.16414
1980.57	1.74166
1983.53	1.2643
1986.48	2.05894
1989.43	2.20049
1992.38	2.04783
1995.33	3.19784
1998.27	3.96156
2001.22	4.2728
2004.16	3.2965
2007.11	4.87091
2010.05	4.52195
2012.99	3.87592
2015.93	4.58528
2018.87	2.87726
2021.81	3.47818
2024.75	3.89611
2027.69	5.11513
2030.62	5.13495
2033.56	4.72201
2036.49	5.37828
2039.42	4.96665
2042.35	5.22111
2045.28	4.86458
2048.21	4.45629
2051.14	4.16088
2054.06	4.66713
2056.99	4.59573
2059.92	5.4185
2062.84	6.16642
2065.76	6.57579
2068.68	6.88951
2071.6	7.80683
2074.52	7.74369
2077.44	8.16703
2080.36	9.03177
2083.27	9.51685
2086.19	10.5979
2089.1	11.4971
2092.01	11.3495
2094.93	12.3692
2097.84	12.2682
2100.75	12.6243
2103.66	10.4792
2106.56	11.3115
2109.47	10.8282
2112.37	9.87684
2115.28	10.336
2118.18	10.6499
2121.09	10.9217
2123.99	12.5528
2126.89	12.8602
2129.79	14.4003
2132.68	15.072
2135.58	15.5431
2138.48	17.3216
2141.37	18.8039
2144.26	21.1508
2147.16	23.3542
2150.05	24.2907
2152.94	26.3606
2155.83	27.5784
2158.72	28.5644
2161.6	29.4095
2164.49	29.6267
2167.38	31.304
2170.26	31.5545
2173.14	31.6043
2176.03	31.6411
2178.91	32.0127
2181.79	31.2586
2184.67	31.2646
2187.54	30.4625
2190.42	30.5142
2193.3	29.6651
2196.17	27.7763
2199.05	27.0159
2201.92	26.1819
2204.79	24.3047
2207.66	23.0332
2210.53	22.8806
2213.4	22.2945
2216.27	21.4674
2219.13	21.3245
2222	21.2519
2224.86	21.623
2227.72	19.3051
2230.59	18.8878
2233.45	19.3095
2236.31	19.2285
2239.17	17.9555
2242.03	17.5886
2244.88	16.1855
2247.74	16.6016
2250.59	16.2539
2253.45	16.0565
2256.3	15.3113
2259.15	15.1795
2262	14.6833
2264.85	14.2688
2267.7	13.7084
2270.55	14.1284
2273.4	12.5445
2276.24	11.5436
2279.09	10.9421
2281.93	11.0308
2284.77	10.3594
2287.61	10.4386
2290.46	9.13805
2293.29	7.24874
2296.13	7.48856
2298.97	7.13438
2301.81	8.13907
2304.64	7.96123
2307.48	7.01474
2310.31	7.67593
2313.14	8.47136
2315.97	9.5373
2318.8	10.7557
2321.63	11.0049
2324.46	11.4562
2327.29	11.6919
2330.12	13.1882
2332.94	13.8416
2335.76	13.8187
2338.59	12.709
2341.41	11.7154
2344.23	11.2518
2347.05	9.70524
2349.87	8.92743
2352.69	8.44182
2355.5	7.83986
2358.32	6.67379
2361.14	6.04015
2363.95	6.45327
2366.76	5.76414
2369.58	5.46445
2372.39	4.89969
2375.2	4.24453
2378	3.69885
2380.81	3.54792
2383.62	2.58384
2386.42	3.27288
2389.23	2.67326
2392.03	2.33376
2394.84	3.01812
2397.64	4.67502
2400.44	3.51522
2403.24	4.76345
2406.04	5.77801
2408.83	6.40877
2411.63	6.21421
2414.43	6.22731
2417.22	7.71795
2420.02	8.38109
2422.81	9.38901
2425.6	8.66034
2428.39	9.48194
2431.18	9.41673
2433.97	8.39423
2436.76	8.75007
2439.54	7.33846
2442.33	5.6941
2445.11	4.70559
2447.9	4.12103
2450.68	3.16213
2453.46	3.6734
2456.24	2.41331
2459.02	1.64201
2461.8	4.09678
2464.58	4.67849
2467.36	3.87423
2470.13	3.23207
2472.91	3.96288
2475.68	3.39928
2478.45	3.65342
2481.22	3.55828
2484	4.73466
2486.77	5.4195
2489.54	3.84507
2492.3	4.41064
2495.07	2.98453
2497.84	3.11045
2500.6	3.84242
2503.36	3.57823
2506.13	2.90549
2508.89	1.12004
2511.65	2.16192
2514.41	3.06694
2517.17	4.22579
2519.93	5.01251
2522.68	5.63449
2525.44	5.9444
2528.19	7.84148
2530.95	8.74923
2533.7	8.01014
2536.45	7.62311
2539.2	7.43839
2541.95	7.62087
2544.7	8.86445
2547.45	9.19249
2550.2	8.86786
2552.94	8.92912
2555.69	7.75002
2558.43	7.54608
2561.17	7.13696
2563.92	5.80481
2566.66	5.26727
2569.4	5.59686
2572.14	4.66175
2574.88	3.92985
2577.61	4.4053
2580.35	4.48644
2583.09	3.06204
2585.82	3.44058
2588.55	2.564
2591.28	2.3046
2594.02	1.99947
2596.75	1.57057
2599.48	1.15843
2602.2	0.914825
2604.93	1.30927
2607.66	0.701106
2610.38	0.327599
2613.11	1.34592
2615.83	0.981435
2618.56	0.370623
2621.28	0.642043
2624	0.912881
2626.72	0.983916
2629.44	1.23253
2632.15	0.978965
2634.87	2.39673
2637.59	3.77705
2640.3	4.50665
2643.02	5.53656
2645.73	6.17579
2648.44	5.23495
2651.15	5.49789
2653.86	6.40645
2656.57	5.56053
2659.28	6.67246
2661.99	6.62556
2664.69	6.55355
2667.4	6.42506
2670.1	6.95073
2672.81	6.52191
2675.51	5.72357
2678.21	6.21471
2680.91	6.34038
2683.61	5.48713
2686.31	5.91461
2689	5.04625
2691.7	4.92276
2694.4	5.24481
2697.09	4.71899
2699.79	4.5486
2702.48	5.88624
2705.17	5.84477
2707.86	6.36869
2710.55	6.80569
2713.24	6.12703
2715.93	6.0978
2718.61	6.9582
2721.3	7.78938
2723.99	7.92929
2726.67	8.51443
2729.35	9.31257
2732.04	9.3137
2734.72	9.02457
2737.4	9.49844
2740.08	9.41975
2742.76	9.21366
2745.43	9.30031
2748.11	8.52388
2750.79	7.82095
2753.46	6.98227
2756.13	5.88204
2758.81	5.3479
2761.48	5.35843
2764.15	3.97766
2766.82	3.34687
2769.49	3.47334
2772.16	2.08748
2774.82	1.61503
2777.49	1.1407
2780.16	0.75061
2782.82	-0.0699085
2785.48	-1.12583
2788.15	-0.344354
2790.81	0.045057
2793.47	-0.027237
2796.13	-0.684402
2798.79	-0.287016
2801.44	-0.145683
2804.1	-0.437853
2806.76	0.203303
2809.41	0.335952
2812.07	1.21862
2814.72	0.974669
2817.37	2.85389
2820.02	5.7493
2822.67	8.8573
2825.32	12.7641
2827.97	17.1168
2830.62	22.446
2833.26	27.5138
2835.91	33.3392
2838.55	39.9459
2841.2	47.9022
2843.84	56.3398
2846.48	65.2582
2849.12	75.2943
2851.76	86.1439
2854.4	97.4196
2857.04	107.264
2859.68	117.407
2862.32	127.816
2864.95	136.698
2867.58	144.453
2870.22	152.709
2872.85	159.258
2875.48	165.922
2878.11	171.92
2880.74	178.732
2883.37	186.561
2886	192.447
2888.63	199.402
2891.25	206.139
2893.88	212.777
2896.5	218.339
2899.13	225.079
2901.75	234.223
2904.37	243.605
2906.99	253.009
2909.61	263.172
2912.23	272.465
2914.85	281.648
2917.46	289.897
2920.08	296.466
2922.7	299.855
2925.31	302.46
2927.92	302.721
2930.53	299.92
2933.15	296.668
2935.76	291.25
2938.37	283.195
2940.98	275.885
2943.58	266.936
2946.19	258.174
2948.8	248.264
2951.4	238.255
2954.01	227.448
2956.61	215.571
2959.21	204.641
2961.81	193.929
2964.41	184.061
2967.01	175.126
2969.61	166.235
2972.21	157.592
2974.81	148.672
2977.4	139.171
2980	129.362
2982.59	119.27
2985.18	108.946
2987.78	98.3091
2990.37	87.2208
2992.96	77.0378
2995.55	67.4838
2998.14	58.1392
3000.72	49.0328
3003.31	41.2488
3005.9	35.1336
3008.48	28.822
3011.07	23.1929
3013.65	18.1325
3016.23	13.4033
3018.81	9.43153
3021.39	6.673
3023.97	3.93142
3026.55	2.79691
3029.13	1.87617
3031.71	2.69458
3034.28	3.02428
3036.86	3.59877
3039.43	3.61855
3042.01	4.96413
3044.58	6.33183
3047.15	8.99427
3049.72	10.1561
3052.29	10.9784
3054.86	12.0358
3057.43	13.5884
3060	14.2591
3062.56	15.7718
3065.13	16.0779
3067.69	16.7061
3070.25	17.6243
3072.82	17.4154
3075.38	16.7334
3077.94	16.7032
3080.5	16.8034
3083.06	16.8712
3085.62	17.063
3088.17	17.3696
3090.73	18.2837
3093.29	19.0747
3095.84	20.0317
3098.4	21.2906
3100.95	22.31
3103.5	23.3439
3106.05	25.1154
3108.6	26.7857
3111.15	28.2189
3113.7	28.7614
3116.25	30.6735
3118.79	32.7039
3121.34	35.3695
3123.88	37.5236
3126.43	40.8672
3128.97	42.602
3131.51	45.57
3134.05	47.8711
3136.59	50.5093
3139.14	53.9216
3141.67	57.1799
3144.21	60.4083
3146.75	64.3789
3149.28	66.6022