File: data/Raman/poly_smoothed/Mb_10_14_03_1x_45s_532 nm_x100_100%_600 gr_mm_01.txt
#Acq. time (s)=	45
#Accumulations=	2
#Range (cm-¹)=	200...3150
#Windows=	2
#Auto scanning=	Off
#Autofocus=	Off
#Macrospot=	Off
#AutoExposure=	Off
#Spike filter=	Multiple accum.
#Delay time (s)=	0
#Binning=	1
#Readout mode=	Signal
#DeNoise=	Off
#ICS correction=	On
#Dark correction=	Off
#Inst. Process=	Off
#Detector Gain=	Best Dynamic Range
#Detector ADC=	20 kHz
#Detector temperature (°C)=	-70.08
#Instrument=	LabRAM HR Evol
#Detector=	Synapse
#Objective=	x100
#Grating=	600 gr/mm
#ND Filter=	100%
#Laser (nm)=	532
#Hole=	100.021
#Range=	Auto
#Laser Pol.=	No
#Raman. Pol.=	No
#Laser Pol. (°)=	-0.0007625
#Raman Pol. (°)=	89.9995
#Collection=	Microscope
#StageXY=	Marzhauser
#StageZ=	Marzhauser
#X (µm)=	-2399.5
#Y (µm)=	2138.1
#Z (µm)=	-40.55
#Full time(mm:ss)=	3:18
#Project=
#Sample=
#Site=
#Title=	Mb_10_14_03_2x_45s_532 nm_x100_100%_600 gr_mm
#Remark=
#Date=	07.07.2022 13:38
#Acquired=	07.07.2022 13:38:33
#Edit:Spike=	07.07.2022 13:41:27
#Base:Fit=	10.08.2022 10:21:11
#Base:Sub=	10.08.2022 10:21:41
#Filter:Polynom=	16.08.2022 10:17:53
#AxisType[0]=Intens
#AxisUnit[0]=Cnt
#AxisType[1]=Spectr
#AxisUnit[1]=1/cm
200.43	39.81
204.061	31.3893
207.688	23.1663
211.316	16.6234
214.941	13.2071
218.566	11.9354
222.188	10.8335
225.809	12.7665
229.43	16.2373
233.047	18.1917
236.663	20.2865
240.278	21.9889
243.894	23.3269
247.506	23.7972
251.116	25.6962
254.725	27.0281
258.333	29.1751
261.939	28.7068
265.546	29.5487
269.15	27.6603
272.752	24.9366
276.353	22.2694
279.952	20.0542
283.55	19.4868
287.146	18.9438
290.739	15.9365
294.333	14.0874
297.925	11.7424
301.516	11.5433
305.106	11.8972
308.694	10.5513
312.279	11.9305
315.864	13.8437
319.448	13.0742
323.029	12.8606
326.61	13.0034
330.19	12.4013
333.766	11.3676
337.343	12.6925
340.917	13.4617
344.491	11.4023
348.062	9.92325
351.633	10.9411
355.201	12.2886
358.77	12.5961
362.335	14.6003
365.899	17.0576
369.464	19.2781
373.025	20.965
376.585	22.1316
380.143	21.8654
383.702	23.2584
387.258	24.7698
390.812	26.1978
394.365	27.3198
397.916	28.214
401.467	28.161
405.015	26.7553
408.565	25.793
412.111	23.8773
415.656	22.2202
419.197	20.5019
422.739	19.0152
426.279	14.5266
429.819	11.7168
433.356	8.73945
436.893	7.38053
440.428	6.84095
443.96	5.08943
447.492	2.80302
451.023	2.34068
454.553	2.6026
458.079	1.67743
461.606	1.68996
465.132	2.85458
468.654	4.3508
472.177	4.74329
475.696	6.07071
479.217	7.3676
482.733	9.50209
486.251	10.4558
489.765	11.8643
493.278	13.7281
496.791	14.6364
500.301	14.515
503.81	15.0248
507.319	15.097
510.825	14.9581
514.33	14.406
517.833	14.5607
521.337	15.2219
524.838	16.1112
528.337	16.4899
531.835	15.3089
535.332	13.854
538.827	14.1351
542.321	13.5847
545.814	12.1711
549.305	11.8633
552.795	11.3498
556.284	9.42069
559.771	8.22433
563.257	7.79832
566.742	7.40048
570.223	6.44985
573.705	4.98444
577.185	6.21789
580.665	4.76129
584.141	3.20908
587.617	3.24408
591.092	4.01548
594.564	5.22996
598.037	7.32485
601.506	7.24428
604.976	9.44167
608.443	10.6695
611.91	11.6938
615.374	11.261
618.839	11.1543
622.3	11.8269
625.761	13.9566
629.221	15.9206
632.679	17.3605
636.135	19.7775
639.592	19.1014
643.045	18.755
646.497	19.2135
649.948	19.7207
653.398	20.4599
656.846	19.2081
660.293	19.1142
663.738	18.972
667.185	18.7732
670.628	20.4368
674.067	20.8163
677.508	22.7162
680.947	25.4606
684.385	26.4157
687.821	27.8464
691.256	27.6867
694.69	29.3671
698.121	30.0663
701.552	30.4171
704.982	32.6717
708.41	33.7914
711.836	35.2584
715.262	35.3027
718.685	34.316
722.108	33.8597
725.53	33.3629
728.949	34.8385
732.369	35.7068
735.785	35.7546
739.2	36.6901
742.616	37.2506
746.028	39.5916
749.441	42.4586
752.851	44.6016
756.26	47.2881
759.667	51.0932
763.075	55.1513
766.479	57.9899
769.883	59.3268
773.285	61.982
776.686	64.4559
780.085	66.3013
783.484	68.0872
786.881	68.5229
790.276	69.6662
793.671	68.5976
797.064	67.6027
800.456	67.9966
803.846	68.955
807.236	71.5653
810.624	73.5774
814.01	73.5838
817.394	73.7861
820.778	74.8621
824.161	75.5783
827.543	75.5273
830.921	74.9653
834.3	73.0607
837.676	70.7642
841.053	70.0662
844.426	68.055
847.8	65.5516
851.171	64.3498
854.542	61.4083
857.911	60.4376
861.279	58.1545
864.645	57.4256
868.01	55.6358
871.375	55.1891
874.737	52.7282
878.097	52.6441
881.457	52.7464
884.817	52.4055
888.174	52.6205
891.53	52.8383
894.884	51.1148
898.237	50.2072
901.589	50.0151
904.94	49.0439
908.289	47.6951
911.637	46.3788
914.984	44.5261
918.33	42.7805
921.674	41.9023
925.015	41.8033
928.357	41.6419
931.698	42.0425
935.037	42.3362
938.373	41.1942
941.71	41.5801
945.046	40.3092
948.378	38.7318
951.711	38.2887
955.043	37.9417
958.372	37.3971
961.701	36.368
965.027	36.0377
968.354	34.3896
971.678	33.6285
975	34.5862
978.324	33.9036
981.644	32.5018
984.962	31.357
988.282	30.1723
991.598	26.862
994.913	24.9665
998.227	23.8694
1001.54	23.8891
1004.85	22.784
1008.16	21.4025
1011.47	19.3682
1014.78	19.2327
1018.08	20.8247
1021.39	22.2443
1024.69	24.5558
1028	27.4574
1031.3	30.7365
1034.6	34.6788
1037.9	36.5063
1041.19	38.9575
1044.49	40.8704
1047.79	41.3972
1051.08	40.7554
1054.37	40.7658
1057.66	39.6804
1060.95	37.5222
1064.24	33.7777
1067.53	30.713
1070.81	26.2701
1074.1	23.2986
1077.38	19.4585
1080.66	15.8586
1083.94	12.2639
1087.22	6.80531
1090.5	7.13098
1093.78	6.64384
1097.05	8.49388
1100.33	10.5529
1103.6	11.9814
1106.87	10.976
1110.15	12.5184
1113.41	13.2169
1116.68	12.9191
1119.95	13.1044
1123.21	14.0136
1126.48	13.6349
1129.74	12.8114
1133	13.367
1136.26	11.7639
1139.52	11.1289
1142.78	10.5343
1146.04	8.85028
1149.29	7.99436
1152.55	7.44499
1155.8	5.90806
1159.05	4.81461
1162.3	4.05331
1165.55	2.49498
1168.8	2.70877
1172.05	3.68615
1175.29	2.18047
1178.54	1.66148
1181.78	2.66964
1185.02	3.35441
1188.26	4.10312
1191.5	5.88736
1194.74	6.92273
1197.97	8.94435
1201.21	10.7273
1204.44	11.2347
1207.68	13.7188
1210.91	16.1309
1214.14	17.4104
1217.37	17.3065
1220.6	19.5157
1223.82	20.875
1227.05	23.2266
1230.27	24.0865
1233.49	23.7191
1236.72	22.7736
1239.94	24.5086
1243.16	26.0767
1246.37	27.9148
1249.59	28.0612
1252.8	29.2656
1256.02	29.7578
1259.23	31.2527
1262.44	32.5952
1265.66	32.7422
1268.87	33.4146
1272.07	34.3856
1275.28	35.0648
1278.48	35.9538
1281.69	37.5382
1284.89	38.7611
1288.09	40.57
1291.3	41.4803
1294.49	40.9288
1297.69	41.133
1300.89	41.7247
1304.09	41.0543
1307.28	41.4172
1310.47	41.0978
1313.66	42.2276
1316.86	43.9124
1320.05	45.9245
1323.23	47.8946
1326.42	49.1739
1329.61	49.5957
1332.79	49.8195
1335.98	49.2284
1339.16	47.266
1342.34	45.4135
1345.52	44.7305
1348.7	45.0501
1351.87	43.1323
1355.05	41.7425
1358.23	40.7673
1361.4	39.9785
1364.57	37.7948
1367.74	33.5941
1370.91	30.0633
1374.08	26.1981
1377.25	22.7517
1380.42	20.807
1383.58	20.3375
1386.75	19.6039
1389.91	18.9531
1393.07	18.0575
1396.23	18.6586
1399.39	20.5881
1402.55	22.6094
1405.7	24.0169
1408.86	26.8066
1412.01	28.7494
1415.17	32.366
1418.32	35.5472
1421.47	40.4047
1424.62	46.4124
1427.77	50.9343
1430.92	55.2793
1434.06	60.407
1437.2	64.8625
1440.35	66.9065
1443.49	67.0383
1446.63	67.4786
1449.77	66.4884
1452.91	65.1252
1456.05	63.9053
1459.18	61.9882
1462.32	59.8119
1465.45	55.2617
1468.59	49.3879
1471.72	46.309
1474.85	43.5672
1477.98	41.3545
1481.11	38.364
1484.23	35.7055
1487.36	31.7142
1490.48	30.1776
1493.61	27.2209
1496.73	23.9053
1499.85	23.5172
1502.97	20.5685
1506.09	19.4098
1509.2	19.1279
1512.32	17.2071
1515.44	14.169
1518.55	12.6264
1521.66	11.185
1524.77	9.67665
1527.88	10.788
1530.99	11.5275
1534.1	13.0791
1537.21	13.3207
1540.31	13.4312
1543.42	13.7269
1546.52	16.7046
1549.62	18.3187
1552.72	18.7787
1555.82	20.0451
1558.92	20.0415
1562.02	20.2185
1565.11	21.5289
1568.21	21.5383
1571.3	22.187
1574.39	22.9806
1577.49	24.3845
1580.58	23.9859
1583.67	25.5565
1586.75	25.8616
1589.84	26.4865
1592.93	27.1672
1596.01	27.9358
1599.09	29.1353
1602.18	31.6737
1605.26	33.0179
1608.34	33.0402
1611.41	32.9015
1614.49	33.797
1617.57	33.4517
1620.64	32.8134
1623.72	32.3935
1626.79	32.2058
1629.86	33.6805
1632.93	35.5968
1636	35.5259
1639.07	36.74
1642.14	37.6017
1645.2	37.2146
1648.27	40.1482
1651.33	40.4358
1654.39	42.0683
1657.45	44.2189
1660.51	44.8992
1663.57	44.4872
1666.63	43.1069
1669.69	42.4151
1672.74	40.2794
1675.79	38.7468
1678.85	35.7082
1681.9	32.2578
1684.95	29.3846
1688	25.7792
1691.05	22.1451
1694.1	18.0886
1697.14	13.1752
1700.19	10.3414
1703.23	8.40046
1706.27	5.79092
1709.32	3.02629
1712.35	1.21618
1715.39	-0.0186391
1718.43	-1.20344
1721.47	-1.67284
1724.5	0.384936
1727.54	0.110323
1730.57	1.24023
1733.61	1.82574
1736.64	1.72222
1739.67	1.5069
1742.7	1.73128
1745.72	2.03998
1748.75	2.43068
1751.78	3.2125
1754.8	4.3642
1757.82	5.05614
1760.85	4.75552
1763.87	4.78554
1766.89	5.31526
1769.91	4.05396
1772.92	3.67351
1775.94	3.57355
1778.96	3.32128
1781.97	3.84089
1784.98	2.93598
1788	2.65034
1791.01	3.50134
1794.01	3.1361
1797.02	4.20841
1800.03	3.87509
1803.04	3.11778
1806.04	3.18638
1809.05	2.9624
1812.05	2.8697
1815.05	3.18648
1818.05	3.61774
1821.05	3.9361
1824.05	4.46503
1827.05	4.08307
1830.04	4.69623
1833.04	3.78614
1836.03	4.92695
1839.03	6.1657
1842.02	6.34307
1845.01	7.00933
1848	7.61221
1850.99	8.25112
1853.97	9.19876
1856.96	9.36761
1859.94	9.3179
1862.93	10.6935
1865.91	12.1718
1868.89	12.3659
1871.87	11.7708
1874.85	10.8633
1877.83	11.216
1880.81	10.4738
1882.56	10.6181
1885.55	9.54363
1888.54	10.1504
1891.52	10.0014
1894.51	9.01366
1897.49	7.33143
1900.48	6.24283
1903.46	6.12584
1906.44	5.84136
1909.42	6.27462
1912.4	7.3266
1915.38	9.10564
1918.35	8.97051
1921.33	9.5084
1924.3	10.4553
1927.28	10.8473
1930.25	11.0512
1933.22	11.2836
1936.19	12.3054
1939.16	12.1882
1942.13	10.5488
1945.09	10.3282
1948.06	9.10242
1951.03	8.78485
1953.99	8.59069
1956.95	7.41839
1959.91	7.08108
1962.87	6.00714
1965.83	4.05569
1968.79	2.58536
1971.75	2.11153
1974.7	3.07132
1977.66	3.09174
1980.61	3.48521
1983.56	4.21078
1986.52	5.6432
1989.47	5.43914
1992.41	7.49514
1995.36	9.16988
1998.31	10.0999
2001.26	11.3339
2004.2	11.8627
2007.15	11.4562
2010.09	11.5926
2013.03	12.1532
2015.97	13.7435
2018.91	14.3675
2021.85	14.6113
2024.79	15.1162
2027.72	14.8296
2030.66	14.2223
2033.59	14.3016
2036.53	13.8003
2039.46	13.7137
2042.39	14.0034
2045.32	15.479
2048.25	15.6627
2051.18	15.6086
2054.1	15.7341
2057.03	15.4963
2059.95	14.8634
2062.88	16.623
2065.8	17.1355
2068.72	16.9091
2071.64	17.3151
2074.56	18.3015
2077.48	17.0587
2080.39	17.1394
2083.31	18.5575
2086.22	19.8492
2089.14	20.118
2092.05	19.1934
2094.96	19.3671
2097.87	19.3362
2100.78	18.359
2103.69	17.5635
2106.6	17.3954
2109.51	18.2633
2112.41	19.0963
2115.32	19.6467
2118.22	19.3321
2121.12	18.582
2124.02	19.3748
2126.92	18.2549
2129.82	18.1685
2132.72	19.5135
2135.62	19.4905
2138.51	21.173
2141.41	23.4607
2144.3	26.0555
2147.19	26.1394
2150.09	27.8054
2152.97	28.7801
2155.86	29.5184
2158.75	30.3748
2161.64	30.9686
2164.53	32.3599
2167.41	31.9778
2170.3	32.6524
2173.18	32.4394
2176.06	33.0804
2178.94	33.0485
2181.82	32.3347
2184.7	32.148
2187.58	30.5114
2190.46	29.687
2193.33	29.0432
2196.21	27.6334
2199.08	26.1378
2201.95	24.6799
2204.83	24.5423
2207.7	24.5961
2210.57	25.6775
2213.43	23.2576
2216.3	22.3922
2219.17	22.7302
2222.03	21.7282
2224.9	21.7409
2227.76	22.4216
2230.62	23.6384
2233.49	23.366
2236.34	23.9831
2239.2	23.9234
2242.06	22.8638
2244.92	23.4937
2247.78	22.9823
2250.63	22.8486
2253.48	23.557
2256.34	23.264
2259.19	22.4904
2262.04	21.2622
2264.89	20.1422
2267.74	18.1134
2270.59	17.4379
2273.43	16.728
2276.28	13.3825
2279.12	12.5316
2281.97	11.0255
2284.81	11.8387
2287.65	11.6751
2290.49	10.8126
2293.33	9.47804
2296.17	10.9357
2299.01	12.0428
2301.84	13.0578
2304.68	15.0351
2307.51	15.4689
2310.35	16.7064
2313.18	17.7476
2316.01	18.2349
2318.84	18.6269
2321.67	18.8818
2324.5	19.7853
2327.33	19.2252
2330.15	18.8084
2332.98	18.3874
2335.8	15.7421
2338.62	14.9031
2341.45	13.8933
2344.27	12.4355
2347.09	11.1438
2349.91	10.3501
2352.72	8.82571
2355.54	6.58178
2358.36	4.46593
2361.17	3.13437
2363.98	3.13348
2366.8	3.03141
2369.61	3.044
2372.42	2.11806
2375.23	1.07753
2378.04	0.283058
2380.85	-0.264739
2383.66	-1.89254
2386.46	-1.32093
2389.26	-2.4465
2392.07	-2.47576
2394.87	-0.595082
2397.67	0.409489
2400.47	0.758764
2403.27	1.8204
2406.07	2.77763
2408.87	4.91546
2411.67	6.45299
2414.46	6.34232
2417.26	7.10159
2420.05	9.06541
2422.84	10.0584
2425.64	11.7667
2428.43	12.9877
2431.22	14.0489
2434.01	13.5414
2436.79	14.2658
2439.58	14.6613
2442.37	14.4536
2445.15	13.2546
2447.93	12.1996
2450.72	11.2828
2453.5	10.8116
2456.28	8.84489
2459.06	6.70703
2461.84	7.03148
2464.62	6.88781
2467.39	6.06191
2470.17	5.68163
2472.94	4.58673
2475.72	5.10334
2478.49	4.74487
2481.26	3.65757
2484.03	3.70644
2486.8	3.98548
2489.57	3.23355
2492.34	4.47182
2495.1	5.54018
2497.87	5.63561
2500.63	5.4654
2503.4	6.51933
2506.16	6.08308
2508.92	5.88594
2511.68	5.69365
2514.44	5.64693
2517.2	3.52281
2519.96	4.14775
2522.72	3.36466
2525.47	1.74462
2528.23	2.46493
2530.98	3.75993
2533.74	3.10775
2536.49	3.30631
2539.24	3.70351
2541.99	3.63386
2544.74	4.26802
2547.49	4.06844
2550.23	4.0296
2552.98	4.60742
2555.72	4.71908
2558.47	4.44191
2561.21	6.06718
2563.95	4.91537
2566.69	5.35965
2569.43	4.71409
2572.17	4.99314
2574.91	4.2789
2577.65	3.71176
2580.39	3.16263
2583.12	2.71647
2585.85	2.8455
2588.59	2.34963
2591.32	1.60587
2594.05	1.52377
2596.78	2.06786
2599.51	1.13682
2602.24	1.10324
2604.97	1.35619
2607.69	1.77987
2610.42	2.0932
2613.14	2.72828
2615.87	3.79297
2618.59	3.62541
2621.31	3.61659
2624.03	4.07877
2626.75	4.2888
2629.47	3.58316
2632.19	2.97493
2634.91	3.3364
2637.62	4.26319
2640.34	4.91061
2643.05	3.60126
2645.76	4.25207
2648.48	3.89968
2651.19	4.76427
2653.9	4.36618
2656.6	3.55897
2659.31	4.15332
2662.02	3.59329
2664.73	3.02057
2667.43	3.58766
2670.14	4.1691
2672.84	4.12901
2675.54	3.98623
2678.24	4.93096
2680.94	4.83774
2683.64	4.91895
2686.34	4.68501
2689.04	4.44996
2691.74	2.92044
2694.43	3.16874
2697.13	3.2412
2699.82	3.23302
2702.51	4.18548
2705.21	5.17909
2707.9	5.64461
2710.58	6.88571
2713.27	5.6861
2715.96	5.09383
2718.65	6.55804
2721.33	6.04154
2724.02	7.28519
2726.71	7.36699
2729.39	7.20683
2732.07	8.45505
2734.75	7.87653
2737.43	6.88007
2740.11	6.17681
2742.79	6.34242
2745.47	6.02172
2748.14	5.56615
2750.82	6.5306
2753.49	5.22538
2756.17	4.55735
2758.84	4.15942
2761.51	4.00452
2764.18	4.37641
2766.85	4.36233
2769.52	3.71678
2772.19	3.68056
2774.86	2.00691
2777.52	1.49836
2780.19	1.88035
2782.85	2.23415
2785.52	2.28778
2788.18	2.02587
2790.84	1.54001
2793.5	1.09732
2796.16	1.7993
2798.82	0.250015
2801.48	-0.112249
2804.13	0.370019
2806.79	1.56972
2809.45	1.01369
2812.1	0.683503
2814.75	1.58775
2817.41	1.9844
2820.06	1.43863
2822.71	3.45599
2825.36	5.64698
2828	8.33315
2830.65	11.1051
2833.3	14.3317
2835.94	17.9533
2838.59	22.8024
2841.23	28.5296
2843.87	33.5248
2846.52	38.716
2849.16	44.5468
2851.8	50.6225
2854.44	56.8869
2857.08	62.7695
2859.71	69.2405
2862.35	74.9824
2864.98	78.8404
2867.62	84.028
2870.25	88.1153
2872.88	91.0553
2875.52	94.4537
2878.15	97.865
2880.78	100.121
2883.41	103.373
2886.03	107.398
2888.66	111.934
2891.29	115.487
2893.91	119.156
2896.54	122.804
2899.16	126.508
2901.78	130.37
2904.4	133.769
2907.02	137.357
2909.64	142.278
2912.26	149.167
2914.88	154.211
2917.5	159.392
2920.11	161.905
2922.73	163.911
2925.34	165.851
2927.96	166.03
2930.57	166.034
2933.18	166.029
2935.79	164.671
2938.4	162.395
2941.01	158.906
2943.62	155.763
2946.22	151.78
2948.83	148.434
2951.43	143.148
2954.04	137.609
2956.64	131.369
2959.24	125.139
2961.84	119.005
2964.45	113.496
2967.05	108.183
2969.64	102.601
2972.24	99.2996
2974.84	94.8635
2977.43	90.2704
2980.03	84.5892
2982.62	79.6441
2985.22	72.7026
2987.81	67.2892
2990.4	61.5088
2992.99	54.9585
2995.58	49.4757
2998.17	42.6999
3000.76	37.3955
3003.34	31.5409
3005.93	26.031
3008.52	21.4501
3011.1	17.1001
3013.68	13.2924
3016.27	9.19195
3018.85	5.42042
3021.43	3.21314
3024.01	1.47947
3026.59	-0.0407767
3029.16	-1.41966
3031.74	-1.65088
3034.32	-1.60019
3036.89	-0.522303
3039.47	0.584077
3042.04	1.82371
3044.61	3.19645
3047.18	3.94722
3049.75	5.10327
3052.32	6.05808
3054.89	5.92301
3057.46	5.73425
3060.03	5.99943
3062.59	6.72785
3065.16	6.68849
3067.72	5.72375
3070.29	6.2612
3072.85	6.39533
3075.41	6.17978
3077.97	6.05973
3080.53	4.40776
3083.09	3.87891
3085.65	3.44741
3088.21	2.42711
3090.76	2.28533
3093.32	2.02598
3095.87	1.93996
3098.43	1.54435
3100.98	1.9557
3103.53	3.20883
3106.08	3.80705
3108.63	4.32734
3111.18	5.85998
3113.73	6.51841
3116.28	6.85181
3118.83	7.57193
3121.37	8.28189
3123.92	9.15248
3126.46	9.54438
3129	9.95787
3131.55	11.2404
3134.09	13.2706
3136.63	13.4223
3139.17	13.4329
3141.71	12.5209
3144.24	12.331
3146.78	11.2017
3149.32	7.81226