File: data/Raman/poly_smoothed/Mb_10_14_15_1x_45s_532 nm_x100_100%_600 gr_mm_01.txt
#Acq. time (s)=	45
#Accumulations=	2
#Range (cm-¹)=	200...3150
#Windows=	2
#Auto scanning=	Off
#Autofocus=	Off
#Macrospot=	Off
#AutoExposure=	Off
#Spike filter=	Multiple accum.
#Delay time (s)=	0
#Binning=	1
#Readout mode=	Signal
#DeNoise=	Off
#ICS correction=	On
#Dark correction=	Off
#Inst. Process=	Off
#Detector Gain=	Best Dynamic Range
#Detector ADC=	20 kHz
#Detector temperature (°C)=	-69.85
#Instrument=	LabRAM HR Evol
#Detector=	Synapse
#Objective=	x100
#Grating=	600 gr/mm
#ND Filter=	100%
#Laser (nm)=	532
#Hole=	100.021
#Range=	Auto
#Laser Pol.=	No
#Raman. Pol.=	No
#Laser Pol. (°)=	-0.0007625
#Raman Pol. (°)=	89.9995
#Collection=	Microscope
#StageXY=	Marzhauser
#StageZ=	Marzhauser
#X (µm)=	-632.2
#Y (µm)=	-1589.5
#Z (µm)=	89.55
#Full time(mm:ss)=	3:19
#Project=
#Sample=
#Site=
#Title=	Mb_10_14_15_2x_45s_532 nm_x100_100%_600 gr_mm
#Remark=
#Date=	11.07.2022 09:36
#Acquired=	11.07.2022 09:36:58
#Base:Fit=	10.08.2022 10:21:11
#Base:Sub=	10.08.2022 10:21:41
#Filter:Polynom=	16.08.2022 10:17:53
#AxisType[0]=Intens
#AxisUnit[0]=Cnt
#AxisType[1]=Spectr
#AxisUnit[1]=1/cm
200.388	8.19832
204.019	7.19602
207.646	5.97868
211.274	4.87335
214.899	4.47659
218.524	5.69545
222.146	8.64562
225.766	11.7979
229.388	15.7454
233.005	18.3802
236.621	19.5366
240.236	20.7905
243.852	21.6204
247.464	21.6266
251.074	21.0196
254.683	21.7623
258.291	22.2188
261.897	23.9384
265.504	24.4686
269.108	23.6843
272.71	21.8003
276.311	20.912
279.91	17.7981
283.508	16.3454
287.105	12.6981
290.698	10.6285
294.291	8.48719
297.884	6.20345
301.475	4.80577
305.064	4.84618
308.652	5.0053
312.237	5.58836
315.822	5.67094
319.406	5.48488
322.987	4.93201
326.568	5.92965
330.148	5.12741
333.724	5.28178
337.301	5.20228
340.875	4.88843
344.449	6.42614
348.02	7.40303
351.592	7.9481
355.16	9.50308
358.728	10.484
362.294	11.8869
365.858	15.5661
369.422	17.7062
372.983	18.4982
376.543	19.4105
380.102	20.4805
383.661	21.7926
387.216	23.7578
390.771	26.1184
394.324	27.3662
397.875	29.169
401.425	28.4202
404.974	28.6369
408.524	28.4573
412.07	26.3193
415.614	24.2599
419.156	22.2739
422.698	18.9836
426.238	15.1715
429.777	13.6339
433.315	11.6538
436.852	9.47496
440.387	8.70412
443.919	8.23414
447.451	6.95929
450.982	5.75745
454.512	6.28623
458.038	5.28103
461.565	5.89615
465.091	7.24466
468.613	9.31403
472.136	10.776
475.655	12.5803
479.176	14.2701
482.692	14.997
486.21	17.6638
489.724	18.3547
493.237	20.3512
496.75	21.1491
500.26	21.7889
503.769	23.4136
507.279	23.0926
510.785	23.024
514.289	25.4347
517.793	26.0314
521.297	26.6553
524.797	27.8595
528.297	26.6568
531.795	24.5631
535.291	23.3452
538.787	24.2711
542.281	23.556
545.773	22.2511
549.264	21.1979
552.754	18.608
556.243	17.0776
559.73	14.2558
563.216	12.9004
566.701	11.3535
570.182	11.5271
573.664	9.23151
577.145	7.74539
580.624	7.92574
584.1	5.8501
587.577	6.01514
591.052	5.58932
594.524	5.81827
597.997	5.4935
601.466	5.4448
604.936	5.53357
608.403	5.42409
611.87	6.14705
615.334	7.00099
618.799	8.68076
622.26	10.715
625.72	12.0738
629.181	12.3185
632.638	12.6274
636.095	14.6165
639.551	16.0503
643.005	18.9774
646.457	21.6114
649.908	23.8847
653.357	26.1338
656.806	26.6456
660.253	27.4982
663.7	28.1302
667.145	28.4708
670.588	29.5404
674.027	30.0534
677.468	29.2369
680.907	28.864
684.345	29.4975
687.781	30.5712
691.216	30.9327
694.65	32.9078
698.081	34.166
701.512	34.2342
704.942	34.8323
708.371	35.8008
711.796	37.509
715.222	39.3616
718.645	41.3889
722.068	42.5934
725.49	44.7028
728.909	46.5221
732.329	49.2521
735.745	50.9257
739.16	52.0878
742.576	52.2625
745.988	54.7548
749.401	55.2121
752.811	57.5723
756.22	59.6425
759.627	61.4015
763.035	63.6066
766.44	64.5571
769.843	67.5073
773.245	70.6559
776.646	72.3886
780.046	74.2639
783.444	75.665
786.841	77.7142
790.237	80.5595
793.631	82.508
797.024	82.9245
800.416	83.0159
803.807	82.2389
807.196	83.4141
810.584	84.3799
813.971	85.7001
817.354	85.5667
820.739	85.0441
824.122	82.7607
827.503	83.5938
830.882	81.8279
834.261	79.3986
837.637	78.0624
841.013	74.7041
844.389	72.894
847.761	70.0845
851.131	68.5732
854.503	67.5581
857.871	65.1212
861.24	62.4169
864.606	59.1504
867.97	58.2409
871.336	57.2998
874.698	56.3853
878.058	54.6716
881.418	52.5511
884.778	51.0309
888.135	51.2452
891.49	51.7723
894.845	51.1486
898.198	50.2678
901.55	50.5291
904.901	50.0188
908.25	49.8031
911.598	48.7743
914.945	48.0739
918.291	48.4337
921.635	49.5271
924.978	49.9023
928.318	50.053
931.659	50.2293
934.998	50.1554
938.336	48.6602
941.671	46.622
945.007	46.4253
948.339	46.6771
951.672	45.5573
955.004	45.007
958.333	44.3801
961.662	41.2786
964.989	41.6841
968.315	42.8931
971.639	42.3619
974.962	41.2866
978.285	39.6363
981.605	40.3669
984.924	38.1338
988.243	37.3916
991.56	36.9496
994.875	36.6672
998.188	38.8072
1001.5	40.3036
1004.81	39.491
1008.12	39.1655
1011.43	39.496
1014.74	41.5052
1018.05	43.1382
1021.35	43.7784
1024.65	45.6137
1027.96	47.3322
1031.26	47.3154
1034.56	47.8049
1037.86	47.5002
1041.16	48.2437
1044.45	48.7606
1047.75	47.5176
1051.04	45.1583
1054.33	41.5694
1057.62	39.8708
1060.91	38.47
1064.2	35.7199
1067.49	32.6285
1070.77	30.9888
1074.06	27.874
1077.34	25.854
1080.62	22.7689
1083.91	18.669
1087.18	16.5562
1090.46	16.1955
1093.74	17.2601
1097.02	17.1209
1100.29	16.3877
1103.56	16.2576
1106.84	16.2735
1110.11	15.2876
1113.38	14.6671
1116.64	16.2537
1119.91	16.3572
1123.18	16.8528
1126.44	16.2063
1129.7	16.5921
1132.97	17.327
1136.23	18.3965
1139.49	18.6027
1142.74	16.7358
1146	16.1488
1149.26	15.6988
1152.51	15.0154
1155.76	13.3819
1159.01	10.1108
1162.27	8.40045
1165.51	7.29725
1168.76	6.82387
1172.01	6.52837
1175.25	5.20361
1178.5	5.43827
1181.74	5.54042
1184.98	4.5688
1188.22	3.95193
1191.46	3.98293
1194.7	5.59336
1197.94	6.82106
1201.17	8.49487
1204.41	9.50928
1207.64	12.3737
1210.87	13.3478
1214.1	16.0155
1217.33	17.3411
1220.56	19.9473
1223.79	22.319
1227.01	24.9262
1230.23	26.7586
1233.46	28.2779
1236.68	28.6499
1239.9	30.2742
1243.12	32.1138
1246.34	33.0857
1249.55	33.1498
1252.77	34.207
1255.98	35.9724
1259.2	35.0941
1262.41	33.5196
1265.62	32.4446
1268.83	32.0069
1272.03	32.3859
1275.24	31.6967
1278.45	31.9608
1281.65	31.8904
1284.85	33.044
1288.06	34.8863
1291.26	35.8698
1294.46	38.2724
1297.66	40.2044
1300.85	42.5187
1304.05	39.6926
1307.24	43.1981
1310.43	46.4136
1313.63	50.424
1316.82	52.9706
1320.01	55.6218
1323.2	56.3284
1326.38	57.8391
1329.57	59.0566
1332.76	58.3177
1335.94	57.5522
1339.12	54.8753
1342.3	53.3993
1345.48	51.299
1348.66	49.5328
1351.84	46.6989
1355.01	44.3
1358.19	40.7574
1361.36	38.2404
1364.53	35.3934
1367.71	32.0154
1370.88	28.9923
1374.04	26.4581
1377.21	23.8406
1380.38	20.7157
1383.54	22.1757
1386.71	24.1445
1389.87	23.8243
1393.03	23.3234
1396.19	22.342
1399.35	23.5566
1402.51	24.6221
1405.67	25.4069
1408.82	27.4837
1411.98	28.4245
1415.13	32.5128
1418.28	35.5137
1421.43	40.1267
1424.58	44.2048
1427.73	48.7295
1430.88	51.7266
1434.02	55.6459
1437.17	57.8463
1440.31	60.8587
1443.45	62.1377
1446.6	63.1984
1449.74	63.6337
1452.87	63.6091
1456.01	61.9053
1459.15	59.6788
1462.28	58.0104
1465.42	53.5082
1468.55	51.3193
1471.68	48.2486
1474.81	44.3065
1477.94	39.6308
1481.07	34.3291
1484.2	30.898
1487.32	26.8089
1490.45	24.9911
1493.57	21.9979
1496.69	19.5994
1499.81	18.2454
1502.93	13.9822
1506.05	12.2859
1509.17	11.5146
1512.28	9.79078
1515.4	7.88742
1518.51	8.29098
1521.63	8.40834
1524.74	9.85658
1527.85	10.74
1530.96	11.6702
1534.06	15.0908
1537.17	17.8516
1540.28	19.9929
1543.38	20.6726
1546.48	22.1488
1549.59	23.0836
1552.69	23.3756
1555.79	23.7334
1558.88	25.0602
1561.98	25.7737
1565.08	26.4235
1568.17	26.7131
1571.27	27.4452
1574.36	28.7949
1577.45	28.8516
1580.54	30.4501
1583.63	31.1378
1586.72	31.4518
1589.8	32.4672
1592.89	33.4757
1595.97	34.963
1599.06	35.7402
1602.14	36.3483
1605.22	36.806
1608.3	37.7411
1611.38	37.9768
1614.46	37.0808
1617.53	36.7746
1620.61	36.7906
1623.68	38.0044
1626.75	38.9254
1629.82	40.119
1632.9	42.0499
1635.96	44.0377
1639.03	46.6728
1642.1	49.2238
1645.16	51.6177
1648.23	54.0454
1651.29	54.7421
1654.36	55.5802
1657.42	56.5446
1660.48	56.5182
1663.53	54.416
1666.59	52.7856
1669.65	51.9506
1672.7	49.5536
1675.76	47.5915
1678.81	44.1675
1681.86	40.4741
1684.91	37.2245
1687.96	32.6967
1691.01	29.3911
1694.06	25.4581
1697.11	22.4257
1700.15	19.4742
1703.2	17.6672
1706.24	15.1525
1709.28	13.9967
1712.32	12.3792
1715.36	10.2878
1718.4	9.30252
1721.43	8.63129
1724.47	7.53583
1727.5	6.99643
1730.54	7.08177
1733.57	7.16557
1736.6	6.3593
1739.63	6.64532
1742.66	6.21148
1745.69	6.26173
1748.72	5.02545
1751.74	4.10537
1754.77	3.37677
1757.79	2.36139
1760.81	1.2817
1763.83	-0.0668962
1766.85	0.90817
1769.87	0.806005
1772.89	0.102713
1775.91	0.66238
1778.92	0.653136
1781.94	0.0144427
1784.95	0.0110613
1787.96	0.596091
1790.97	0.882253
1793.98	1.09047
1796.99	1.36788
1800	2.42893
1803	2.34055
1806.01	2.87891
1809.01	2.52864
1812.02	3.076
1815.02	2.13901
1818.02	2.00432
1821.02	2.62633
1824.02	2.60362
1827.01	2.89261
1830.01	2.52764
1833	3.08839
1836	3.39433
1838.99	4.10309
1841.98	4.93119
1844.97	5.27292
1847.96	5.36505
1850.95	5.40322
1853.94	4.64551
1856.92	4.23847
1859.91	4.06018
1862.89	4.05189
1865.88	3.804
1868.86	4.19383
1871.84	4.84288
1874.82	3.71037
1877.8	4.28441
1880.77	3.70685
1882.52	3.65345
1885.51	3.62122
1888.5	4.32287
1891.49	4.51878
1894.47	5.06989
1897.46	5.70791
1900.44	6.71449
1903.42	6.72285
1906.4	7.14992
1909.38	7.98524
1912.36	8.92601
1915.34	9.5438
1918.32	9.33997
1921.29	8.78916
1924.27	8.77457
1927.24	8.38859
1930.21	8.33346
1933.18	8.10214
1936.15	8.12569
1939.12	6.88496
1942.09	6.87174
1945.06	7.20196
1948.02	6.48876
1950.99	6.03037
1953.95	6.66728
1956.91	5.97204
1959.87	5.83857
1962.84	5.48996
1965.79	5.87955
1968.75	7.06563
1971.71	7.52765
1974.66	7.62271
1977.62	7.34011
1980.57	7.87078
1983.53	8.17945
1986.48	8.95449
1989.43	8.08262
1992.38	7.37477
1995.33	6.70757
1998.27	6.55552
2001.22	7.14324
2004.16	6.96966
2007.11	6.85805
2010.05	6.38739
2012.99	6.97459
2015.93	7.30773
2018.87	5.80961
2021.81	5.81773
2024.75	6.37929
2027.69	6.94246
2030.62	6.21405
2033.56	6.39323
2036.49	7.55562
2039.42	8.32122
2042.35	8.56073
2045.28	8.59584
2048.21	7.81739
2051.14	7.65389
2054.06	7.87168
2056.99	8.23271
2059.92	7.24123
2062.84	6.42166
2065.76	6.90607
2068.68	7.33859
2071.6	7.84104
2074.52	8.34574
2077.44	9.09454
2080.36	7.82257
2083.27	7.14863
2086.19	7.58701
2089.1	6.51238
2092.01	7.01581
2094.93	6.88035
2097.84	7.47681
2100.75	8.45494
2103.66	9.13561
2106.56	10.2112
2109.47	10.5039
2112.37	10.9326
2115.28	11.0197
2118.18	11.7779
2121.09	11.1421
2123.99	11.4855
2126.89	11.7833
2129.79	12.1516
2132.68	12.7612
2135.58	13.9149
2138.48	15.3192
2141.37	16.9343
2144.26	18.7451
2147.16	19.4597
2150.05	19.2197
2152.94	19.7839
2155.83	19.6642
2158.72	20.8146
2161.6	20.751
2164.49	22.2997
2167.38	23.7439
2170.26	25.3056
2173.14	26.0996
2176.03	26.5821
2178.91	26.0743
2181.79	25.0785
2184.67	24.8489
2187.54	24.356
2190.42	23.0489
2193.3	22.9275
2196.17	22.4114
2199.05	21.2407
2201.92	20.6216
2204.79	19.4465
2207.66	18.0933
2210.53	17.8668
2213.4	15.7563
2216.27	14.3867
2219.13	13.6317
2222	12.9491
2224.86	12.6267
2227.72	10.7627
2230.59	10.816
2233.45	11.8119
2236.31	11.6717
2239.17	11.6298
2242.03	10.9227
2244.88	11.1124
2247.74	10.7851
2250.59	11.1549
2253.45	11.6291
2256.3	12.5247
2259.15	12.9759
2262	13.0295
2264.85	12.9322
2267.7	12.9153
2270.55	12.9198
2273.4	11.9881
2276.24	11.3794
2279.09	11.1185
2281.93	9.83628
2284.77	9.05324
2287.61	8.9294
2290.46	8.0484
2293.29	6.88061
2296.13	5.46573
2298.97	5.88187
2301.81	6.89115
2304.64	7.63921
2307.48	7.71565
2310.31	7.70714
2313.14	7.47115
2315.97	7.75964
2318.8	8.23835
2321.63	9.37599
2324.46	9.63649
2327.29	8.19798
2330.12	7.56588
2332.94	7.06207
2335.76	6.97503
2338.59	6.61459
2341.41	5.28928
2344.23	4.19285
2347.05	2.46568
2349.87	0.829042
2352.69	-0.0532576
2355.5	0.0967631
2358.32	-0.555671
2361.14	-0.10958
2363.95	-0.211586
2366.76	1.4864
2369.58	1.91323
2372.39	2.52927
2375.2	3.8275
2378	3.83283
2380.81	4.50153
2383.62	5.30879
2386.42	5.99727
2389.23	6.11856
2392.03	7.17168
2394.84	6.97483
2397.64	5.29424
2400.44	4.75473
2403.24	3.84691
2406.04	2.94347
2408.83	1.80209
2411.63	1.37317
2414.43	1.13894
2417.22	1.66896
2420.02	1.65241
2422.81	2.58373
2425.6	2.69393
2428.39	2.50042
2431.18	2.38129
2433.97	2.30257
2436.76	4.15239
2439.54	4.33524
2442.33	4.70747
2445.11	4.83175
2447.9	4.68502
2450.68	4.43962
2453.46	4.57364
2456.24	4.73354
2459.02	4.83799
2461.8	4.48818
2464.58	2.97042
2467.36	2.00155
2470.13	2.14487
2472.91	2.65341
2475.68	2.42437
2478.45	3.00903
2481.22	3.80981
2484	4.29773
2486.77	4.89882
2489.54	4.93781
2492.3	5.34602
2495.07	5.75287
2497.84	6.10998
2500.6	6.82601
2503.36	6.97754
2506.13	7.28621
2508.89	6.93631
2511.65	7.47369
2514.41	7.23335
2517.17	6.66372
2519.93	6.44486
2522.68	6.35902
2525.44	6.41467
2528.19	5.96827
2530.95	6.58055
2533.7	6.40655
2536.45	6.7819
2539.2	6.62383
2541.95	6.029
2544.7	5.49183
2547.45	6.06594
2550.2	6.08149
2552.94	6.48676
2555.69	6.98363
2558.43	8.14427
2561.17	9.10173
2563.92	9.48725
2566.66	9.6129
2569.4	9.45128
2572.14	9.25445
2574.88	9.0058
2577.61	8.52983
2580.35	7.61763
2583.09	7.09116
2585.82	5.89666
2588.55	5.36003
2591.28	5.12209
2594.02	4.9219
2596.75	4.27314
2599.48	4.10631
2602.2	3.07981
2604.93	1.81387
2607.66	0.981252
2610.38	1.00185
2613.11	0.647759
2615.83	1.14429
2618.56	1.66576
2621.28	1.59102
2624	2.13084
2626.72	3.15201
2629.44	3.59881
2632.15	3.37448
2634.87	3.20104
2637.59	3.08755
2640.3	3.58905
2643.02	3.25032
2645.73	3.54272
2648.44	3.79049
2651.15	3.26414
2653.86	4.95194
2656.57	4.90135
2659.28	4.7964
2661.99	5.33666
2664.69	4.38082
2667.4	4.0357
2670.1	3.2954
2672.81	3.08466
2675.51	3.77131
2678.21	4.28367
2680.91	4.87256
2683.61	4.83111
2686.31	3.989
2689	4.35181
2691.7	4.74305
2694.4	4.94951
2697.09	4.88295
2699.79	5.53801
2702.48	6.41583
2705.17	6.34269
2707.86	7.58905
2710.55	8.39723
2713.24	10.0636
2715.93	10.741
2718.61	11.7511
2721.3	11.6861
2723.99	11.376
2726.67	11.4582
2729.35	10.9382
2732.04	10.2595
2734.72	9.83776
2737.4	9.90231
2740.08	9.69619
2742.76	9.19299
2745.43	8.39186
2748.11	6.69728
2750.79	5.94626
2753.46	5.14836
2756.13	4.73145
2758.81	3.83179
2761.48	2.91944
2764.15	2.59062
2766.82	1.74129
2769.49	1.75453
2772.16	2.30262
2774.82	2.26602
2777.49	1.71581
2780.16	1.65835
2782.82	0.975435
2785.48	1.06086
2788.15	1.23167
2790.81	1.18253
2793.47	0.288484
2796.13	-0.617462
2798.79	-0.826255
2801.44	-0.922542
2804.1	-1.50555
2806.76	-1.79291
2809.41	-1.72623
2812.07	-0.459419
2814.72	0.0121653
2817.37	2.42328
2820.02	4.30275
2822.67	7.04702
2825.32	8.9505
2827.97	12.3569
2830.62	15.6858
2833.26	19.4665
2835.91	23.8892
2838.55	29.0352
2841.2	33.8513
2843.84	41.4872
2846.48	49.0285
2849.12	56.3072
2851.76	63.825
2854.4	71.2264
2857.04	77.5632
2859.68	83.6412
2862.32	89.8212
2864.95	95.8645
2867.58	102.133
2870.22	107.409
2872.85	113.029
2875.48	117.147
2878.11	121.275
2880.74	124.844
2883.37	128.555
2886	130.798
2888.63	133.378
2891.25	136.63
2893.88	139.053
2896.5	141.936
2899.13	145.814
2901.75	151.639
2904.37	158.028
2906.99	166.145
2909.61	174.548
2912.23	182.631
2914.85	189.121
2917.46	195.928
2920.08	201.12
2922.7	205.874
2925.31	208.663
2927.92	209.903
2930.53	209.87
2933.15	208.634
2935.76	206.232
2938.37	201.546
2940.98	196.488
2943.58	190.173
2946.19	183.969
2948.8	176.083
2951.4	168.574
2954.01	160.547
2956.61	152.872
2959.21	144.624
2961.81	137.793
2964.41	130.629
2967.01	125.442
2969.61	119.475
2972.21	114.058
2974.81	107.861
2977.4	102.471
2980	95.3269
2982.59	88.4475
2985.18	81.1698
2987.78	73.9776
2990.37	66.1973
2992.96	58.5634
2995.55	52.2062
2998.14	44.7024
3000.72	38.8314
3003.31	31.9358
3005.9	26.6276
3008.48	20.6059
3011.07	16.2254
3013.65	13.2076
3016.23	9.89715
3018.81	6.89779
3021.39	4.38901
3023.97	2.77079
3026.55	1.60556
3029.13	1.04002
3031.71	1.29445
3034.28	1.31955
3036.86	1.30928
3039.43	2.13741
3042.01	3.88377
3044.58	4.62087
3047.15	6.02923
3049.72	7.77433
3052.29	8.57638
3054.86	8.89531
3057.43	9.77122
3060	10.8086
3062.56	10.6712
3065.13	10.375
3067.69	9.7589
3070.25	9.39501
3072.82	9.04387
3075.38	8.60421
3077.94	7.56471
3080.5	6.38434
3083.06	4.85463
3085.62	4.02882
3088.17	2.58755
3090.73	1.72164
3093.29	1.01121
3095.84	-0.18331
3098.4	-0.301755
3100.95	-0.36327
3103.5	0.16337
3106.05	1.09374
3108.6	1.19164
3111.15	2.44148
3113.7	3.17277
3116.25	4.40763
3118.79	5.63029
3121.34	7.54802
3123.88	8.76265
3126.43	10.0503
3128.97	11.0072
3131.51	12.7512
3134.05	14.0976
3136.59	15.7703
3139.14	16.4468
3141.67	17.8884
3144.21	18.3275
3146.75	18.9842
3149.28	20.6452