File: data/Raman/poly_smoothed/Mb_10_14_36_1x_45s_532 nm_x100_100%_600 gr_mm_01.txt
#Acq. time (s)=	45
#Accumulations=	2
#Range (cm-¹)=	200...3150
#Windows=	2
#Auto scanning=	Off
#Autofocus=	Off
#Macrospot=	Off
#AutoExposure=	Off
#Spike filter=	Multiple accum.
#Delay time (s)=	0
#Binning=	1
#Readout mode=	Signal
#DeNoise=	Off
#ICS correction=	On
#Dark correction=	Off
#Inst. Process=	Off
#Detector Gain=	Best Dynamic Range
#Detector ADC=	20 kHz
#Detector temperature (°C)=	-69.85
#Instrument=	LabRAM HR Evol
#Detector=	Synapse
#Objective=	x100
#Grating=	600 gr/mm
#ND Filter=	100%
#Laser (nm)=	532
#Hole=	100.021
#Range=	Auto
#Laser Pol.=	No
#Raman. Pol.=	No
#Laser Pol. (°)=	-0.0007625
#Raman Pol. (°)=	89.9995
#Collection=	Microscope
#StageXY=	Marzhauser
#StageZ=	Marzhauser
#X (µm)=	-626
#Y (µm)=	-1664.4
#Z (µm)=	89.2
#Full time(mm:ss)=	3:18
#Project=
#Sample=
#Site=
#Title=	Mb_10_14_36_2x_45s_532 nm_x100_100%_600 gr_mm
#Remark=
#Date=	11.07.2022 11:16
#Acquired=	11.07.2022 11:16:00
#Base:Fit=	10.08.2022 10:21:11
#Base:Sub=	10.08.2022 10:21:41
#Filter:Polynom=	16.08.2022 10:17:53
#AxisType[0]=Intens
#AxisUnit[0]=Cnt
#AxisType[1]=Spectr
#AxisUnit[1]=1/cm
200.388	-0.543577
204.019	3.93873
207.646	7.6492
211.274	9.67301
214.899	11.3225
218.524	14.0234
222.146	18.923
225.766	24.4652
229.388	26.8324
233.005	28.398
236.621	30.0439
240.236	32.9754
243.852	34.8146
247.464	36.8961
251.074	36.5813
254.683	38.0308
258.291	37.8704
261.897	36.441
265.504	36.9309
269.108	38.2406
272.71	38.3518
276.311	39.4966
279.91	39.1227
283.508	40.1452
287.105	36.9321
290.698	36.2024
294.291	35.4412
297.884	34.9437
301.475	33.3919
305.064	34.5475
308.652	34.3706
312.237	32.8074
315.822	28.8048
319.406	24.4094
322.987	22.7618
326.568	21.6259
330.148	19.7439
333.724	15.793
337.301	12.0117
340.875	8.52027
344.449	7.24194
348.02	7.18952
351.592	10.1365
355.16	14.625
358.728	20.2766
362.294	24.1951
365.858	27.3208
369.422	30.6384
372.983	33.5136
376.543	36.5045
380.102	41.3815
383.661	43.6449
387.216	45.8631
390.771	45.6142
394.324	46.0089
397.875	44.7669
401.425	42.1259
404.974	41.1001
408.524	39.7854
412.07	36.9595
415.614	32.091
419.156	27.2355
422.698	21.498
426.238	17.6334
429.777	15.2345
433.315	15.7721
436.852	13.0523
440.387	12.8861
443.919	11.0628
447.451	8.17775
450.982	7.82758
454.512	7.70828
458.038	8.21519
461.565	10.442
465.091	11.986
468.613	14.357
472.136	15.5927
475.655	18.2863
479.176	19.7022
482.692	22.4971
486.21	22.7093
489.724	24.7275
493.237	28.3871
496.75	29.5845
500.26	31.4591
503.769	30.7063
507.279	30.6101
510.785	30.2641
514.289	29.5156
517.793	27.5377
521.297	27.6164
524.797	26.309
528.297	24.6844
531.795	21.2825
535.291	19.6462
538.787	18.9185
542.281	18.3832
545.773	17.9804
549.264	15.6168
552.754	14.1475
556.243	12.1313
559.73	10.7178
563.216	8.58543
566.701	6.28372
570.182	4.70596
573.664	3.46742
577.145	3.79933
580.624	4.13463
584.1	4.0055
587.577	2.85899
591.052	1.74928
594.524	0.458881
597.997	1.20255
601.466	1.11887
604.936	2.3883
608.403	5.07784
611.87	5.11091
615.334	6.03303
618.799	7.2985
622.26	10.9792
625.72	13.583
629.181	14.6296
632.638	16.1132
636.095	16.8755
639.551	19.3931
643.005	19.6638
646.457	20.0899
649.908	19.3727
653.357	19.1003
656.806	19.6296
660.253	18.1001
663.7	17.5286
667.145	17.2274
670.588	15.4593
674.027	13.3182
677.468	13.396
680.907	13.3887
684.345	15.4492
687.781	14.9811
691.216	16.6899
694.65	17.5853
698.081	18.1727
701.512	19.0253
704.942	20.1417
708.371	20.5025
711.796	20.941
715.222	21.0205
718.645	24.2662
722.068	24.4556
725.49	25.5356
728.909	26.8451
732.329	28.4151
735.745	31.1382
739.16	32.5202
742.576	35.5076
745.988	37.8034
749.401	41.8942
752.811	43.9736
756.22	47.7738
759.627	49.4033
763.035	50.2823
766.44	51.8656
769.843	53.0102
773.245	53.9792
776.646	56.02
780.046	57.916
783.444	59.4973
786.841	59.7525
790.237	59.4584
793.631	59.4602
797.024	61.1786
800.416	63.6897
803.807	63.5853
807.196	65.9433
810.584	68.5139
813.971	70.1167
817.354	72.3422
820.739	73.6744
824.122	75.4174
827.503	78.8935
830.882	78.6417
834.261	78.2632
837.637	76.5859
841.013	75.867
844.389	73.0245
847.761	70.2006
851.131	68.4463
854.503	66.7202
857.871	64.0998
861.24	62.2279
864.606	60.0631
867.97	55.2466
871.336	52.8231
874.698	48.8421
878.058	47.2933
881.418	46.0023
884.778	44.1958
888.135	44.45
891.49	44.0522
894.845	42.2156
898.198	42.1588
901.55	41.7053
904.901	43.2724
908.25	43.2195
911.598	43.904
914.945	44.2773
918.291	43.8275
921.635	43.8823
924.978	44.1329
928.318	45.468
931.659	46.161
934.998	47.186
938.336	47.8508
941.671	46.5535
945.007	45.0914
948.339	43.6409
951.672	42.2509
955.004	40.3122
958.333	39.5259
961.662	39.5622
964.989	43.3442
968.315	44.3054
971.639	46.4791
974.962	46.2632
978.285	46.9262
981.605	47.8646
984.924	48.2068
988.243	46.6879
991.56	45.88
994.875	45.3111
998.188	44.4888
1001.5	44.8386
1004.81	45.8953
1008.12	48.3773
1011.43	48.5625
1014.74	49.8482
1018.05	51.2063
1021.35	49.8504
1024.65	49.6582
1027.96	49.1178
1031.26	49.9656
1034.56	49.7469
1037.86	50.733
1041.16	50.7933
1044.45	52.2331
1047.75	51.3584
1051.04	48.6974
1054.33	44.9098
1057.62	42.4745
1060.91	39.034
1064.2	34.2809
1067.49	28.7956
1070.77	23.5429
1074.06	22.1901
1077.34	20.4905
1080.62	18.3478
1083.91	18.8441
1087.18	16.9052
1090.46	15.4092
1093.74	16.298
1097.02	18.0292
1100.29	18.498
1103.56	19.822
1106.84	20.029
1110.11	18.911
1113.38	17.623
1116.64	16.9116
1119.91	15.6838
1123.18	14.382
1126.44	13.3833
1129.7	12.8791
1132.97	12.0029
1136.23	11.6903
1139.49	10.9391
1142.74	9.52532
1146	8.05384
1149.26	7.06047
1152.51	7.26462
1155.76	8.0937
1159.01	8.13541
1162.27	6.83043
1165.51	5.68787
1168.76	4.98462
1172.01	6.69911
1175.25	6.9167
1178.5	6.39847
1181.74	8.73519
1184.98	8.75408
1188.22	8.04539
1191.46	8.93935
1194.7	9.34716
1197.94	11.8079
1201.17	13.9729
1204.41	16.8215
1207.64	21.8247
1210.87	24.7063
1214.1	26.9284
1217.33	30.5495
1220.56	33.3701
1223.79	36.3166
1227.01	39.3548
1230.23	39.8253
1233.46	41.6651
1236.68	42.4729
1239.9	43.6187
1243.12	42.1055
1246.34	42.7023
1249.55	43.4055
1252.77	44.1287
1255.98	42.8904
1259.2	44.378
1262.41	44.989
1265.62	44.128
1268.83	45.3395
1272.03	46.5598
1275.24	48.2913
1278.45	48.7917
1281.65	51.3897
1284.85	52.5633
1288.06	53.9314
1291.26	55.307
1294.46	55.9235
1297.66	56.5014
1300.85	55.6711
1304.05	58.0312
1307.24	58.5766
1310.43	59.0332
1313.63	60.1053
1316.82	59.5107
1320.01	59.9367
1323.2	59.8321
1326.38	59.1716
1329.57	58.5245
1332.76	58.6723
1335.94	56.0835
1339.12	55.3735
1342.3	55.0346
1345.48	52.9632
1348.66	51.5401
1351.84	49.8463
1355.01	48.4835
1358.19	45.4445
1361.36	43.8643
1364.53	41.3488
1367.71	40.834
1370.88	37.0637
1374.04	36.2785
1377.21	34.3951
1380.38	33.9061
1383.54	33.433
1386.71	33.5039
1389.87	33.5086
1393.03	32.997
1396.19	34.9046
1399.35	34.864
1402.51	35.6893
1405.67	36.9028
1408.82	38.9099
1411.98	40.252
1415.13	44.1666
1418.28	47.0532
1421.43	49.9887
1424.58	55.7649
1427.73	60.0572
1430.88	65.4754
1434.02	71.1592
1437.17	74.5647
1440.31	78.9201
1443.45	82.0385
1446.6	83.2031
1449.74	83.378
1452.87	82.3622
1456.01	80.3853
1459.15	78.6052
1462.28	75.2919
1465.42	71.3811
1468.55	67.1694
1471.68	61.8784
1474.81	56.9698
1477.94	51.7091
1481.07	44.441
1484.2	39.7787
1487.32	35.5371
1490.45	31.9311
1493.57	28.3978
1496.69	25.4684
1499.81	23.6711
1502.93	21.2233
1506.05	21.4377
1509.17	22.0696
1512.28	21.2691
1515.4	20.8602
1518.51	22.8992
1521.63	23.4063
1524.74	23.5541
1527.85	23.2216
1530.96	23.39
1534.06	24.0229
1537.17	23.0811
1540.28	23.0268
1543.38	24.9979
1546.48	24.6702
1549.59	24.6684
1552.69	25.1906
1555.79	26.259
1558.88	28.3922
1561.98	30.5179
1565.08	31.8471
1568.17	33.105
1571.27	35.0373
1574.36	37.5328
1577.45	40.4154
1580.54	42.9334
1583.63	44.8168
1586.72	47.4934
1589.8	50.2445
1592.89	51.1494
1595.97	51.7308
1599.06	51.049
1602.14	51.5537
1605.22	51.0259
1608.3	50.386
1611.38	49.2049
1614.46	48.3367
1617.53	48.7157
1620.61	49.0307
1623.68	49.5395
1626.75	50.2082
1629.82	52.747
1632.9	53.7253
1635.96	55.0728
1639.03	55.6909
1642.1	57.8669
1645.16	59.9542
1648.23	61.5518
1651.29	63.4144
1654.36	63.049
1657.42	64.959
1660.48	62.7303
1663.53	62.2974
1666.59	60.8003
1669.65	58.3051
1672.7	55.9737
1675.76	53.0229
1678.81	49.8082
1681.86	46.8347
1684.91	42.3987
1687.96	38.2015
1691.01	35.0867
1694.06	32.0723
1697.11	29.4333
1700.15	26.2565
1703.2	23.7591
1706.24	21.1018
1709.28	19.0473
1712.32	17.4634
1715.36	14.7556
1718.4	13.4201
1721.43	12.8457
1724.47	11.9714
1727.5	12.2002
1730.54	11.1039
1733.57	10.1754
1736.6	7.74034
1739.63	7.56746
1742.66	7.43753
1745.69	6.47516
1748.72	7.02965
1751.74	7.42953
1754.77	6.84078
1757.79	5.3729
1760.81	5.20844
1763.83	4.78776
1766.85	4.17184
1769.87	4.36321
1772.89	3.55386
1775.91	3.71297
1778.92	3.80735
1781.94	4.36084
1784.95	4.0168
1787.96	2.88482
1790.97	2.47095
1793.98	3.83578
1796.99	4.38882
1800	3.52349
1803	4.14922
1806.01	3.30084
1809.01	2.46619
1812.02	2.24117
1815.02	3.04455
1818.02	3.39687
1821.02	3.69236
1824.02	3.95845
1827.01	3.80583
1830.01	2.48264
1833	1.58977
1836	2.21569
1838.99	1.90811
1841.98	2.7214
1844.97	2.74402
1847.96	2.49253
1850.95	3.38161
1853.94	4.04892
1856.92	3.85824
1859.91	4.12594
1862.89	4.89364
1865.88	6.06105
1868.86	6.27135
1871.84	6.8367
1874.82	5.96555
1877.8	5.54242
1880.77	5.17369
1882.52	4.54823
1885.51	5.98531
1888.5	5.94535
1891.49	5.01707
1894.47	5.65443
1897.46	5.47077
1900.44	4.86302
1903.42	4.60956
1906.4	4.66556
1909.38	3.74915
1912.36	2.61175
1915.34	2.4798
1918.32	2.15881
1921.29	2.33992
1924.27	3.17463
1927.24	3.11071
1930.21	3.26015
1933.18	3.23031
1936.15	3.56749
1939.12	3.34845
1942.09	1.91578
1945.06	3.42239
1948.02	2.89089
1950.99	3.32347
1953.95	3.48835
1956.91	4.10364
1959.87	3.56274
1962.84	3.16003
1965.79	5.54673
1968.75	6.92219
1971.71	6.7556
1974.66	9.05871
1977.62	8.62951
1980.57	7.94641
1983.53	7.51848
1986.48	8.23118
1989.43	8.34176
1992.38	6.90769
1995.33	5.54812
1998.27	4.69031
2001.22	5.26386
2004.16	5.5766
2007.11	6.55149
2010.05	7.01738
2012.99	8.03115
2015.93	8.21694
2018.87	7.89868
2021.81	7.8369
2024.75	8.33791
2027.69	7.94949
2030.62	8.19191
2033.56	8.21481
2036.49	8.95124
2039.42	9.90876
2042.35	9.91531
2045.28	11.4546
2048.21	10.3711
2051.14	9.47754
2054.06	8.56361
2056.99	8.0175
2059.92	7.24383
2062.84	5.834
2065.76	6.09643
2068.68	7.0559
2071.6	8.43177
2074.52	9.06301
2077.44	10.0969
2080.36	11.7561
2083.27	12.7011
2086.19	12.6096
2089.1	12.6299
2092.01	12.7905
2094.93	13.8377
2097.84	13.8178
2100.75	12.9892
2103.66	12.6867
2106.56	12.2708
2109.47	13.1239
2112.37	13.1029
2115.28	14.3215
2118.18	15.094
2121.09	15.3474
2123.99	16.1596
2126.89	17.2056
2129.79	16.9116
2132.68	18.4546
2135.58	19.0597
2138.48	19.2948
2141.37	19.883
2144.26	20.7359
2147.16	21.7238
2150.05	23.6216
2152.94	23.3297
2155.83	24.0151
2158.72	24.0196
2161.6	25.0397
2164.49	25.1378
2167.38	26.3114
2170.26	26.5458
2173.14	26.3281
2176.03	26.7971
2178.91	27.0523
2181.79	26.7493
2184.67	26.4699
2187.54	26.9139
2190.42	26.9843
2193.3	28.2049
2196.17	26.2069
2199.05	24.4963
2201.92	23.4727
2204.79	21.8384
2207.66	21.3608
2210.53	20.7208
2213.4	19.7233
2216.27	18.2639
2219.13	17.7121
2222	15.8072
2224.86	15.1863
2227.72	14.3216
2230.59	13.6458
2233.45	13.5628
2236.31	12.9805
2239.17	12.9805
2242.03	12.977
2244.88	11.5677
2247.74	11.5317
2250.59	11.7955
2253.45	11.8599
2256.3	13.03
2259.15	13.8416
2262	13.5277
2264.85	13.3155
2267.7	13.2336
2270.55	13.193
2273.4	14.439
2276.24	15.2371
2279.09	15.5018
2281.93	15.5244
2284.77	16.2959
2287.61	15.7039
2290.46	15.8736
2293.29	16.3222
2296.13	16.3914
2298.97	15.8108
2301.81	16.8616
2304.64	16.2954
2307.48	15.8243
2310.31	16.4512
2313.14	15.3593
2315.97	14.7173
2318.8	14.2336
2321.63	14.8404
2324.46	13.0618
2327.29	11.7076
2330.12	10.8823
2332.94	9.96291
2335.76	8.57675
2338.59	8.78301
2341.41	8.46618
2344.23	7.91358
2347.05	6.06165
2349.87	5.95346
2352.69	6.12689
2355.5	5.733
2358.32	5.29721
2361.14	6.91204
2363.95	6.74352
2366.76	7.87177
2369.58	9.03817
2372.39	10.3868
2375.2	10.0371
2378	10.7887
2380.81	10.8785
2383.62	10.8823
2386.42	11.3553
2389.23	11.3012
2392.03	10.8433
2394.84	10.2604
2397.64	10.3855
2400.44	8.90387
2403.24	8.62864
2406.04	9.26968
2408.83	8.68927
2411.63	6.5868
2414.43	6.24818
2417.22	7.10806
2420.02	7.11935
2422.81	6.89564
2425.6	7.37784
2428.39	8.60121
2431.18	8.88349
2433.97	7.9206
2436.76	9.91522
2439.54	9.25864
2442.33	7.55444
2445.11	8.24337
2447.9	7.13832
2450.68	7.71439
2453.46	7.12399
2456.24	7.77812
2459.02	8.15978
2461.8	7.34478
2464.58	7.572
2467.36	7.46125
2470.13	7.64975
2472.91	7.12074
2475.68	5.85331
2478.45	4.64109
2481.22	4.32047
2484	3.73533
2486.77	3.17576
2489.54	2.10522
2492.3	2.80964
2495.07	2.91147
2497.84	2.19579
2500.6	2.03141
2503.36	2.4805
2506.13	2.06601
2508.89	2.526
2511.65	3.08558
2514.41	3.98694
2517.17	4.07809
2519.93	6.39154
2522.68	6.29249
2525.44	7.08498
2528.19	6.86818
2530.95	7.87189
2533.7	9.01128
2536.45	8.63194
2539.2	8.438
2541.95	7.53952
2544.7	7.43057
2547.45	6.68498
2550.2	6.60775
2552.94	5.77863
2555.69	6.03516
2558.43	5.02651
2561.17	5.49869
2563.92	5.30927
2566.66	4.76507
2569.4	4.32881
2572.14	2.44453
2574.88	2.15725
2577.61	2.6107
2580.35	2.28616
2583.09	1.70744
2585.82	1.55761
2588.55	1.58897
2591.28	1.37989
2594.02	1.18743
2596.75	1.62859
2599.48	1.58615
2602.2	0.700721
2604.93	0.597742
2607.66	1.75944
2610.38	2.04168
2613.11	2.73465
2615.83	2.9157
2618.56	3.23417
2621.28	3.2993
2624	5.01053
2626.72	5.73906
2629.44	5.84285
2632.15	5.40983
2634.87	5.46701
2637.59	4.37773
2640.3	4.41348
2643.02	5.93304
2645.73	5.39711
2648.44	5.92709
2651.15	5.82244
2653.86	7.22796
2656.57	7.70327
2659.28	7.05465
2661.99	5.7621
2664.69	5.40805
2667.4	6.72377
2670.1	6.66184
2672.81	7.69948
2675.51	7.41534
2678.21	7.93449
2680.91	7.43215
2683.61	8.18375
2686.31	8.62443
2689	8.49051
2691.7	9.00158
2694.4	8.78669
2697.09	9.18301
2699.79	8.95343
2702.48	8.79339
2705.17	10.2717
2707.86	10.7036
2710.55	12.0616
2713.24	12.4512
2715.93	12.9026
2718.61	14.1107
2721.3	13.5205
2723.99	13.4446
2726.67	13.1316
2729.35	13.3219
2732.04	14.3433
2734.72	13.632
2737.4	11.7494
2740.08	11.4942
2742.76	10.6861
2745.43	9.49498
2748.11	8.93681
2750.79	8.01996
2753.46	6.67487
2756.13	5.29811
2758.81	5.23194
2761.48	3.903
2764.15	2.41622
2766.82	1.98758
2769.49	2.2443
2772.16	1.62964
2774.82	1.10043
2777.49	0.59925
2780.16	0.376476
2782.82	0.142368
2785.48	-1.1642
2788.15	-0.368937
2790.81	-0.326906
2793.47	-1.03013
2796.13	-1.07804
2798.79	-1.41106
2801.44	-1.61859
2804.1	-1.94266
2806.76	-1.78796
2809.41	-2.58946
2812.07	-2.58216
2814.72	-1.64485
2817.37	-0.953409
2820.02	1.50381
2822.67	4.23315
2825.32	7.54727
2827.97	11.3521
2830.62	15.676
2833.26	20.6833
2835.91	24.8174
2838.55	29.3034
2841.2	35.8713
2843.84	42.9243
2846.48	50.1472
2849.12	59.7751
2851.76	70.4346
2854.4	80.1946
2857.04	88.8604
2859.68	97.7096
2862.32	105.257
2864.95	111.16
2867.58	118.515
2870.22	124.483
2872.85	130.192
2875.48	135.353
2878.11	140.493
2880.74	145.553
2883.37	149.508
2886	155.893
2888.63	159.136
2891.25	163.467
2893.88	168.132
2896.5	173.396
2899.13	177.954
2901.75	183.946
2904.37	192.417
2906.99	200.918
2909.61	212.003
2912.23	223.233
2914.85	234.215
2917.46	243.694
2920.08	251.532
2922.7	257.511
2925.31	262.178
2927.92	264.323
2930.53	268.009
2933.15	267.778
2935.76	266.258
2938.37	262.327
2940.98	258.732
2943.58	251.743
2946.19	244.532
2948.8	236.671
2951.4	226.784
2954.01	216.502
2956.61	207.044
2959.21	195.861
2961.81	185.001
2964.41	175.269
2967.01	165.935
2969.61	156.078
2972.21	147.088
2974.81	138.929
2977.4	130.018
2980	119.805
2982.59	111.367
2985.18	102.198
2987.78	94.0228
2990.37	83.4817
2992.96	75.5217
2995.55	68.2348
2998.14	59.636
3000.72	53.2486
3003.31	45.6962
3005.9	40.2892
3008.48	33.5924
3011.07	27.7829
3013.65	22.2605
3016.23	17.624
3018.81	14.3576
3021.39	10.0347
3023.97	6.71384
3026.55	5.17879
3029.13	3.74669
3031.71	2.95053
3034.28	2.11276
3036.86	2.70133
3039.43	2.79445
3042.01	3.80223
3044.58	5.65733
3047.15	6.24242
3049.72	7.08913
3052.29	8.80979
3054.86	8.90862
3057.43	9.31765
3060	9.42076
3062.56	9.17285
3065.13	9.29232
3067.69	9.18713
3070.25	9.01166
3072.82	8.1461
3075.38	6.39053
3077.94	5.75437
3080.5	4.32803
3083.06	3.30704
3085.62	2.43191
3088.17	1.46419
3090.73	1.16815
3093.29	0.954472
3095.84	0.108222
3098.4	0.511299
3100.95	1.25377
3103.5	3.01036
3106.05	4.43171
3108.6	4.72835
3111.15	5.71658
3113.7	6.75495
3116.25	8.17832
3118.79	8.74354
3121.34	10.1265
3123.88	12.0465
3126.43	13.8277
3128.97	16.5183
3131.51	18.9758
3134.05	19.985
3136.59	21.4981
3139.14	23.3319
3141.67	24.6846
3144.21	26.1011
3146.75	26.8761
3149.28	27.6665