File: data/Raman/poly_smoothed/Mb_10_14_35_1x_45s_532 nm_x100_100%_600 gr_mm_01.txt
#Acq. time (s)=	45
#Accumulations=	2
#Range (cm-¹)=	200...3150
#Windows=	2
#Auto scanning=	Off
#Autofocus=	Off
#Macrospot=	Off
#AutoExposure=	Off
#Spike filter=	Multiple accum.
#Delay time (s)=	0
#Binning=	1
#Readout mode=	Signal
#DeNoise=	Off
#ICS correction=	On
#Dark correction=	Off
#Inst. Process=	Off
#Detector Gain=	Best Dynamic Range
#Detector ADC=	20 kHz
#Detector temperature (°C)=	-69.85
#Instrument=	LabRAM HR Evol
#Detector=	Synapse
#Objective=	x100
#Grating=	600 gr/mm
#ND Filter=	100%
#Laser (nm)=	532
#Hole=	100.021
#Range=	Auto
#Laser Pol.=	No
#Raman. Pol.=	No
#Laser Pol. (°)=	-0.0007625
#Raman Pol. (°)=	89.9995
#Collection=	Microscope
#StageXY=	Marzhauser
#StageZ=	Marzhauser
#X (µm)=	-627.4
#Y (µm)=	-1658.5
#Z (µm)=	88.95
#Full time(mm:ss)=	3:18
#Project=
#Sample=
#Site=
#Title=	Mb_10_14_35_2x_45s_532 nm_x100_100%_600 gr_mm
#Remark=
#Date=	11.07.2022 11:12
#Acquired=	11.07.2022 11:12:06
#Base:Fit=	10.08.2022 10:21:11
#Base:Sub=	10.08.2022 10:21:41
#Filter:Polynom=	16.08.2022 10:17:53
#AxisType[0]=Intens
#AxisUnit[0]=Cnt
#AxisType[1]=Spectr
#AxisUnit[1]=1/cm
200.388	8.53522
204.019	9.29688
207.646	6.41039
211.274	4.2135
214.899	3.78533
218.524	2.8803
222.146	4.64275
225.766	6.39915
229.388	9.20364
233.005	12.0011
236.621	14.7598
240.236	16.2316
243.852	17.4677
247.464	17.9714
251.074	18.1975
254.683	18.3107
258.291	20.5064
261.897	20.6858
265.504	21.9176
269.108	20.8391
272.71	21.0751
276.311	18.5055
279.91	16.5365
283.508	14.8507
287.105	11.1845
290.698	9.72282
294.291	7.83988
297.884	5.27922
301.475	5.42785
305.064	5.94806
308.652	5.87909
312.237	5.43769
315.822	6.10356
319.406	6.41637
322.987	6.89004
326.568	6.35047
330.148	4.46008
333.724	1.82938
337.301	-0.811081
340.875	-0.866581
344.449	-0.924
348.02	-0.293576
351.592	4.28378
355.16	8.41356
358.728	11.4878
362.294	14.83
365.858	17.9398
369.422	22.4571
372.983	27.0403
376.543	31.0839
380.102	34.3086
383.661	39.1845
387.216	43.1462
390.771	46.6279
394.324	47.3152
397.875	46.5737
401.425	45.8085
404.974	44.5055
408.524	42.1175
412.07	38.1353
415.614	31.8448
419.156	25.5197
422.698	21.3006
426.238	17.9811
429.777	14.9732
433.315	13.3842
436.852	12.4373
440.387	10.8308
443.919	9.34529
447.451	7.44702
450.982	6.55771
454.512	4.86423
458.038	6.39498
461.565	7.93514
465.091	7.02256
468.613	7.4501
472.136	9.09131
475.655	9.23093
479.176	9.22616
482.692	10.2758
486.21	10.9287
489.724	14.4909
493.237	14.7272
496.75	16.6935
500.26	17.8426
503.769	21.5158
507.279	24.199
510.785	27.2079
514.289	30.1966
517.793	30.1474
521.297	29.9943
524.797	30.9812
528.297	31.0967
531.795	32.6422
535.291	32.014
538.787	33.4251
542.281	32.7039
545.773	31.1794
549.264	27.5206
552.754	24.7319
556.243	22.7128
559.73	18.7965
563.216	17.1566
566.701	15.5906
570.182	12.0485
573.664	8.83466
577.145	7.0286
580.624	5.48825
584.1	5.76185
587.577	5.45711
591.052	5.84131
594.524	5.25087
597.997	4.47864
601.466	2.13575
604.936	1.91038
608.403	3.55405
611.87	6.82805
615.334	7.80029
618.799	9.59028
622.26	11.2225
625.72	12.7743
629.181	11.97
632.638	12.1541
636.095	14.2551
639.551	15.3715
643.005	16.7702
646.457	18.8577
649.908	19.2719
653.357	18.9106
656.806	18.8087
660.253	17.9112
663.7	18.1849
667.145	17.1483
670.588	15.9794
674.027	16.8146
677.468	15.8359
680.907	15.7727
684.345	16.3669
687.781	18.1092
691.216	19.3929
694.65	19.4742
698.081	19.053
701.512	18.4392
704.942	17.7364
708.371	19.1648
711.796	20.61
715.222	23.1256
718.645	26.0923
722.068	30.0577
725.49	32.6219
728.909	35.9817
732.329	36.4103
735.745	38.6116
739.16	40.9797
742.576	43.4408
745.988	44.7752
749.401	47.0726
752.811	49.4419
756.22	53.107
759.627	57.5693
763.035	61.2479
766.44	63.9565
769.843	65.5782
773.245	66.1369
776.646	67.0733
780.046	66.8576
783.444	66.5161
786.841	66.5048
790.237	67.7339
793.631	70.5728
797.024	71.4469
800.416	72.5678
803.807	75.2861
807.196	74.6342
810.584	74.8117
813.971	75.9046
817.354	76.2183
820.739	78.5367
824.122	77.9441
827.503	77.7101
830.882	76.5239
834.261	74.5613
837.637	72.5775
841.013	71.6416
844.389	70.2172
847.761	66.3522
851.131	63.2839
854.503	60.9394
857.871	58.013
861.24	54.113
864.606	50.42
867.97	48.5322
871.336	48.1225
874.698	47.7301
878.058	48.2507
881.418	49.1093
884.778	48.2026
888.135	48.8043
891.49	48.5187
894.845	49.6127
898.198	49.7456
901.55	50.458
904.901	50.2776
908.25	49.7779
911.598	50.56
914.945	50.402
918.291	48.8537
921.635	49.0871
924.978	48.7907
928.318	48.1186
931.659	47.8488
934.998	48.0767
938.336	47.9087
941.671	45.8359
945.007	43.5472
948.339	42.4133
951.672	43.6564
955.004	43.8441
958.333	43.3765
961.662	41.333
964.989	42.4113
968.315	42.6528
971.639	44.5281
974.962	44.6202
978.285	45.5556
981.605	44.5367
984.924	44.1276
988.243	43.0212
991.56	42.2381
994.875	40.8967
998.188	42.5348
1001.5	43.7798
1004.81	46.4054
1008.12	48.655
1011.43	50.8884
1014.74	54.737
1018.05	56.8716
1021.35	58.143
1024.65	59.5038
1027.96	62.4719
1031.26	64.8839
1034.56	65.9898
1037.86	63.9894
1041.16	62.4629
1044.45	61.2937
1047.75	60.6711
1051.04	57.4538
1054.33	54.7198
1057.62	50.2989
1060.91	45.0573
1064.2	38.9503
1067.49	30.585
1070.77	26.8753
1074.06	22.1423
1077.34	18.7239
1080.62	17.9149
1083.91	16.3512
1087.18	14.0517
1090.46	14.188
1093.74	15.6462
1097.02	16.3935
1100.29	17.0211
1103.56	18.6052
1106.84	20.596
1110.11	22.0248
1113.38	21.8945
1116.64	20.5241
1119.91	19.2601
1123.18	18.6518
1126.44	17.3108
1129.7	17.031
1132.97	18.0508
1136.23	18.2753
1139.49	17.0084
1142.74	17.6219
1146	14.8626
1149.26	13.9083
1152.51	13.0521
1155.76	11.1903
1159.01	9.82825
1162.27	9.62786
1165.51	7.56816
1168.76	6.02544
1172.01	6.91324
1175.25	7.68341
1178.5	7.05869
1181.74	9.08154
1184.98	11.5798
1188.22	12.3802
1191.46	13.0505
1194.7	13.4868
1197.94	15.1059
1201.17	18.021
1204.41	20.3305
1207.64	23.3245
1210.87	29.1497
1214.1	34.1913
1217.33	38.1368
1220.56	40.0715
1223.79	41.2137
1227.01	43.8266
1230.23	45.9671
1233.46	50.1328
1236.68	50.9472
1239.9	52.6642
1243.12	54.2353
1246.34	55.0575
1249.55	57.6184
1252.77	56.276
1255.98	57.575
1259.2	58.4612
1262.41	57.6791
1265.62	55.2435
1268.83	56.3363
1272.03	56.0286
1275.24	56.5669
1278.45	56.8581
1281.65	56.6446
1284.85	57.6655
1288.06	58.751
1291.26	60.7401
1294.46	59.4175
1297.66	60.8286
1300.85	62.5723
1304.05	64.9281
1307.24	68.039
1310.43	71.7031
1313.63	74.4097
1316.82	75.7753
1320.01	78.5525
1323.2	78.8923
1326.38	80.0605
1329.57	78.4495
1332.76	78.8038
1335.94	79.2026
1339.12	77.1977
1342.3	76.5938
1345.48	75.5743
1348.66	73.6163
1351.84	69.4541
1355.01	65.8436
1358.19	60.4939
1361.36	57.3509
1364.53	54.2485
1367.71	50.5202
1370.88	46.811
1374.04	43.3511
1377.21	40.672
1380.38	38.7865
1383.54	38.1815
1386.71	37.152
1389.87	36.7649
1393.03	34.5356
1396.19	34.312
1399.35	34.2605
1402.51	34.0172
1405.67	35.9922
1408.82	38.4468
1411.98	44.3494
1415.13	48.7156
1418.28	54.4049
1421.43	60.5789
1424.58	67.4774
1427.73	73.3615
1430.88	79.3864
1434.02	84.7904
1437.17	90.7574
1440.31	95.6613
1443.45	99.4066
1446.6	101.765
1449.74	101.647
1452.87	101.054
1456.01	101.325
1459.15	101.616
1462.28	99.8163
1465.42	96.2827
1468.55	93.07
1471.68	90.7864
1474.81	88.8397
1477.94	82.2148
1481.07	78.7321
1484.2	75.2646
1487.32	71.3289
1490.45	68.4973
1493.57	64.2696
1496.69	59.9233
1499.81	54.5326
1502.93	49.7536
1506.05	44.5523
1509.17	39.4292
1512.28	35.1997
1515.4	30.6018
1518.51	26.7638
1521.63	23.9712
1524.74	20.7816
1527.85	18.4505
1530.96	18.1299
1534.06	18.6925
1537.17	19.2337
1540.28	21.6501
1543.38	23.6866
1546.48	25.2489
1549.59	27.8396
1552.69	29.1059
1555.79	29.6481
1558.88	31.9256
1561.98	33.5348
1565.08	35.2419
1568.17	38.3538
1571.27	39.9163
1574.36	40.5526
1577.45	43.1469
1580.54	44.5161
1583.63	47.1415
1586.72	50.0226
1589.8	52.1375
1592.89	54.7415
1595.97	55.7958
1599.06	56.2542
1602.14	56.3166
1605.22	57.2747
1608.3	57.2302
1611.38	57.4101
1614.46	57.5938
1617.53	57.9917
1620.61	59.5719
1623.68	60.3955
1626.75	62.6782
1629.82	65.2539
1632.9	67.6043
1635.96	73.8873
1639.03	77.1913
1642.1	82.7978
1645.16	85.1706
1648.23	87.5639
1651.29	89.9197
1654.36	92.3665
1657.42	93.256
1660.48	94.0251
1663.53	91.8064
1666.59	89.986
1669.65	86.6152
1672.7	80.8384
1675.76	76.4078
1678.81	71.7979
1681.86	65.1983
1684.91	57.6209
1687.96	50.2726
1691.01	45.125
1694.06	40.874
1697.11	36.3499
1700.15	31.343
1703.2	27.7055
1706.24	23.9063
1709.28	21.6677
1712.32	18.6653
1715.36	14.3545
1718.4	11.52
1721.43	7.88931
1724.47	6.23816
1727.5	3.87656
1730.54	2.99706
1733.57	4.16859
1736.6	4.23945
1739.63	2.75463
1742.66	2.76325
1745.69	1.57371
1748.72	1.05533
1751.74	1.05042
1754.77	0.340301
1757.79	-0.0075824
1760.81	0.812529
1763.83	1.21843
1766.85	2.22022
1769.87	2.16129
1772.89	2.08638
1775.91	2.537
1778.92	2.06716
1781.94	1.5264
1784.95	1.8245
1787.96	0.808828
1790.97	0.941254
1793.98	1.87446
1796.99	1.75277
1800	2.08672
1803	3.00978
1806.01	4.73421
1809.01	4.67272
1812.02	4.62506
1815.02	4.60847
1818.02	3.64353
1821.02	4.00795
1824.02	3.79523
1827.01	3.84322
1830.01	3.86111
1833	3.67062
1836	3.84928
1838.99	4.25251
1841.98	3.78714
1844.97	3.79286
1847.96	3.98134
1850.95	3.37546
1853.94	3.87717
1856.92	4.62638
1859.91	4.40634
1862.89	5.54963
1865.88	5.92089
1868.86	6.34152
1871.84	7.70415
1874.82	7.04259
1877.8	7.16781
1880.77	7.14409
1882.52	6.64617
1885.51	6.9608
1888.5	6.39693
1891.49	7.0342
1894.47	6.7642
1897.46	6.196
1900.44	5.94911
1903.42	5.49049
1906.4	6.14857
1909.38	7.16058
1912.36	7.68109
1915.34	8.41975
1918.32	9.26125
1921.29	10.2693
1924.27	10.6723
1927.24	9.95343
1930.21	8.7082
1933.18	8.30051
1936.15	7.79124
1939.12	5.91324
1942.09	4.73923
1945.06	4.21087
1948.02	2.99883
1950.99	3.05118
1953.95	2.91964
1956.91	3.86265
1959.87	4.05617
1962.84	3.06332
1965.79	4.16821
1968.75	3.81111
1971.71	3.80165
1974.66	4.32873
1977.62	4.78165
1980.57	5.81189
1983.53	5.98443
1986.48	6.38616
1989.43	6.94119
1992.38	8.2529
1995.33	8.76862
1998.27	9.40559
2001.22	9.65398
2004.16	8.153
2007.11	9.15816
2010.05	9.65825
2012.99	9.52953
2015.93	10.6454
2018.87	11.936
2021.81	12.724
2024.75	14.2947
2027.69	14.0779
2030.62	14.0441
2033.56	12.7645
2036.49	12.5317
2039.42	12.781
2042.35	12.2817
2045.28	12.0516
2048.21	11.6304
2051.14	10.3801
2054.06	9.31772
2056.99	8.61363
2059.92	9.64729
2062.84	10.8204
2065.76	12.0999
2068.68	12.8947
2071.6	13.8266
2074.52	12.2556
2077.44	13.1632
2080.36	14.2988
2083.27	14.5709
2086.19	16.5501
2089.1	17.1121
2092.01	17.7971
2094.93	16.835
2097.84	16.0936
2100.75	16.8883
2103.66	16.6738
2106.56	17.4249
2109.47	18.6766
2112.37	19.7343
2115.28	20.5649
2118.18	21.6051
2121.09	22.3704
2123.99	23.6074
2126.89	24.3349
2129.79	26.3322
2132.68	27.9084
2135.58	29.4436
2138.48	30.3201
2141.37	31.6284
2144.26	33.6585
2147.16	36.0577
2150.05	38.7598
2152.94	42.5051
2155.83	43.6123
2158.72	44.2083
2161.6	44.5789
2164.49	44.9964
2167.38	45.7838
2170.26	46.5036
2173.14	48.201
2176.03	48.2792
2178.91	49.3075
2181.79	48.9472
2184.67	49.3537
2187.54	48.7585
2190.42	48.4285
2193.3	46.4874
2196.17	44.1958
2199.05	41.4689
2201.92	39.3787
2204.79	37.6212
2207.66	35.6771
2210.53	33.8294
2213.4	31.8456
2216.27	30.6764
2219.13	30.0397
2222	28.3791
2224.86	25.9765
2227.72	24.3312
2230.59	21.8777
2233.45	21.6208
2236.31	21.6446
2239.17	20.5316
2242.03	19.7827
2244.88	19.1932
2247.74	19.4031
2250.59	18.7044
2253.45	17.9439
2256.3	17.9155
2259.15	16.2301
2262	16.506
2264.85	16.0471
2267.7	15.0759
2270.55	14.7355
2273.4	15.4824
2276.24	14.3708
2279.09	13.1153
2281.93	11.9278
2284.77	11.833
2287.61	12.9323
2290.46	12.0663
2293.29	10.6055
2296.13	9.48341
2298.97	10.9808
2301.81	10.982
2304.64	11.9838
2307.48	13.1001
2310.31	13.1656
2313.14	13.6576
2315.97	15.0759
2318.8	15.4309
2321.63	15.2534
2324.46	15.7204
2327.29	16.5448
2330.12	17.8616
2332.94	18.9434
2335.76	18.2361
2338.59	17.7776
2341.41	17.4323
2344.23	15.6336
2347.05	12.6331
2349.87	10.7465
2352.69	9.11774
2355.5	7.63232
2358.32	5.69211
2361.14	3.27119
2363.95	2.87642
2366.76	4.16879
2369.58	4.32763
2372.39	3.59936
2375.2	3.54269
2378	3.61939
2380.81	3.09661
2383.62	3.30039
2386.42	3.89671
2389.23	4.59931
2392.03	5.58902
2394.84	8.45176
2397.64	9.29215
2400.44	9.28801
2403.24	9.60056
2406.04	9.68125
2408.83	10.6473
2411.63	9.63007
2414.43	9.9085
2417.22	10.1064
2420.02	10.2147
2422.81	9.12852
2425.6	8.43524
2428.39	8.26343
2431.18	8.31669
2433.97	7.63754
2436.76	8.22463
2439.54	6.78639
2442.33	5.83419
2445.11	6.4813
2447.9	6.51668
2450.68	6.79137
2453.46	7.07688
2456.24	8.46273
2459.02	9.68817
2461.8	10.2119
2464.58	10.7924
2467.36	10.0134
2470.13	9.44207
2472.91	9.2827
2475.68	9.45281
2478.45	9.08804
2481.22	7.42468
2484	6.53317
2486.77	6.64615
2489.54	5.95177
2492.3	4.67023
2495.07	3.84545
2497.84	3.7115
2500.6	3.9083
2503.36	2.35065
2506.13	2.73668
2508.89	2.6765
2511.65	3.32157
2514.41	3.99974
2517.17	5.32193
2519.93	6.31042
2522.68	8.43883
2525.44	9.96771
2528.19	9.90425
2530.95	9.55724
2533.7	9.86545
2536.45	9.82307
2539.2	10.5754
2541.95	10.1797
2544.7	11.158
2547.45	11.918
2550.2	11.5579
2552.94	13.1943
2555.69	13.7886
2558.43	13.4987
2561.17	12.9388
2563.92	12.6789
2566.66	13.0145
2569.4	13.1838
2572.14	12.1461
2574.88	12.9769
2577.61	13.1242
2580.35	13.3084
2583.09	13.1763
2585.82	13.2351
2588.55	12.2133
2591.28	11.6556
2594.02	11.0924
2596.75	10.7607
2599.48	10.8756
2602.2	11.2526
2604.93	10.6398
2607.66	9.88267
2610.38	8.89072
2613.11	8.95444
2615.83	9.13724
2618.56	8.43479
2621.28	8.61876
2624	8.71959
2626.72	8.36496
2629.44	8.07585
2632.15	8.49906
2634.87	8.83698
2637.59	8.43135
2640.3	8.43876
2643.02	8.05612
2645.73	8.46403
2648.44	9.25217
2651.15	9.47419
2653.86	9.19162
2656.57	8.89703
2659.28	10.0132
2661.99	10.6595
2664.69	10.5192
2667.4	10.0403
2670.1	9.08233
2672.81	9.9748
2675.51	9.39198
2678.21	11.3242
2680.91	11.5213
2683.61	9.87027
2686.31	11.0864
2689	10.9667
2691.7	9.72528
2694.4	10.6209
2697.09	10.9206
2699.79	12.2581
2702.48	13.0329
2705.17	13.9606
2707.86	14.838
2710.55	15.8528
2713.24	16.8146
2715.93	16.4719
2718.61	16.6964
2721.3	16.8754
2723.99	16.3302
2726.67	15.8593
2729.35	14.6218
2732.04	12.9616
2734.72	12.5418
2737.4	11.0841
2740.08	9.79105
2742.76	8.96918
2745.43	7.89441
2748.11	5.52374
2750.79	3.84286
2753.46	2.78377
2756.13	1.8432
2758.81	1.77395
2761.48	2.0872
2764.15	1.18898
2766.82	1.86483
2769.49	0.970405
2772.16	0.700457
2774.82	-0.392852
2777.49	0.19297
2780.16	0.691097
2782.82	1.40179
2785.48	1.17863
2788.15	0.65278
2790.81	-0.204076
2793.47	-0.596702
2796.13	-0.663342
2798.79	-0.390771
2801.44	-0.585776
2804.1	0.780419
2806.76	1.4516
2809.41	0.999879
2812.07	0.891476
2814.72	0.631232
2817.37	2.39224
2820.02	4.14538
2822.67	6.45845
2825.32	9.80783
2827.97	14.1819
2830.62	19.3638
2833.26	25.1807
2835.91	30.9947
2838.55	39.1573
2841.2	49.0348
2843.84	61.2603
2846.48	73.6448
2849.12	87.4387
2851.76	102.609
2854.4	117.287
2857.04	132.231
2859.68	147.043
2862.32	161.757
2864.95	175.171
2867.58	188.935
2870.22	199.715
2872.85	209.248
2875.48	217.041
2878.11	224.331
2880.74	229.694
2883.37	235.721
2886	240.724
2888.63	245.895
2891.25	251.126
2893.88	256.021
2896.5	262.51
2899.13	270.872
2901.75	280.339
2904.37	291.044
2906.99	304.265
2909.61	319.999
2912.23	335.957
2914.85	351.765
2917.46	366.112
2920.08	379.58
2922.7	391.61
2925.31	401.188
2927.92	407.972
2930.53	411.214
2933.15	410.667
2935.76	407.359
2938.37	401.625
2940.98	392.809
2943.58	382.164
2946.19	369.331
2948.8	356.55
2951.4	342.077
2954.01	326.408
2956.61	311.278
2959.21	296.296
2961.81	281.96
2964.41	267.267
2967.01	252.349
2969.61	238.795
2972.21	226.907
2974.81	215.649
2977.4	201.519
2980	187.641
2982.59	173.23
2985.18	159.555
2987.78	144.869
2990.37	130.478
2992.96	114.968
2995.55	101.16
2998.14	88.0751
3000.72	74.9292
3003.31	62.6114
3005.9	51.0276
3008.48	41.3352
3011.07	33.2027
3013.65	26.0436
3016.23	19.9329
3018.81	15.7835
3021.39	11.3879
3023.97	7.72944
3026.55	5.51713
3029.13	3.99067
3031.71	3.07025
3034.28	2.91773
3036.86	4.09845
3039.43	3.70227
3042.01	3.78456
3044.58	5.44978
3047.15	7.25963
3049.72	9.07736
3052.29	10.3643
3054.86	12.2782
3057.43	12.3346
3060	12.5722
3062.56	12.1863
3065.13	10.576
3067.69	9.70285
3070.25	9.34199
3072.82	8.76799
3075.38	8.31601
3077.94	8.01036
3080.5	6.98683
3083.06	5.33604
3085.62	3.21942
3088.17	1.62712
3090.73	0.881437
3093.29	0.861093
3095.84	-0.2383
3098.4	-0.060497
3100.95	0.518313
3103.5	1.11189
3106.05	2.34976
3108.6	3.29487
3111.15	4.73561
3113.7	6.01306
3116.25	8.03539
3118.79	9.35414
3121.34	10.7968
3123.88	13.0069
3126.43	13.8266
3128.97	16.2985
3131.51	19.5827
3134.05	22.99
3136.59	26.0818
3139.14	29.5534
3141.67	32.441
3144.21	35.0261
3146.75	38.5984
3149.28	41.3777