File: data/Raman/poly_smoothed/Mb_10_14_31_1x_45s_532 nm_x100_100%_600 gr_mm_01.txt
#Acq. time (s)=	45
#Accumulations=	2
#Range (cm-¹)=	200...3150
#Windows=	2
#Auto scanning=	Off
#Autofocus=	Off
#Macrospot=	Off
#AutoExposure=	Off
#Spike filter=	Multiple accum.
#Delay time (s)=	0
#Binning=	1
#Readout mode=	Signal
#DeNoise=	Off
#ICS correction=	On
#Dark correction=	Off
#Inst. Process=	Off
#Detector Gain=	Best Dynamic Range
#Detector ADC=	20 kHz
#Detector temperature (°C)=	-69.85
#Instrument=	LabRAM HR Evol
#Detector=	Synapse
#Objective=	x100
#Grating=	600 gr/mm
#ND Filter=	100%
#Laser (nm)=	532
#Hole=	100.021
#Range=	Auto
#Laser Pol.=	No
#Raman. Pol.=	No
#Laser Pol. (°)=	-0.0007625
#Raman Pol. (°)=	89.9995
#Collection=	Microscope
#StageXY=	Marzhauser
#StageZ=	Marzhauser
#X (µm)=	-609
#Y (µm)=	-1588.9
#Z (µm)=	90.15
#Full time(mm:ss)=	3:18
#Project=
#Sample=
#Site=
#Title=	Mb_10_14_31_2x_45s_532 nm_x100_100%_600 gr_mm
#Remark=
#Date=	11.07.2022 10:50
#Acquired=	11.07.2022 10:50:20
#Base:Fit=	10.08.2022 10:21:11
#Base:Sub=	10.08.2022 10:21:41
#Filter:Polynom=	16.08.2022 10:17:53
#AxisType[0]=Intens
#AxisUnit[0]=Cnt
#AxisType[1]=Spectr
#AxisUnit[1]=1/cm
200.388	14.6155
204.019	13.1878
207.646	10.9768
211.274	8.85583
214.899	9.04916
218.524	8.29106
222.146	9.57725
225.766	12.4449
229.388	12.3255
233.005	13.316
236.621	12.4244
240.236	13.1499
243.852	13.5663
247.464	13.6552
251.074	13.6757
254.683	13.3899
258.291	13.2864
261.897	12.9985
265.504	13.2074
269.108	12.7752
272.71	10.4941
276.311	9.43979
279.91	7.44923
283.508	5.61281
287.105	3.81472
290.698	2.99888
294.291	1.60394
297.884	2.47327
301.475	2.83398
305.064	2.24147
308.652	3.12869
312.237	4.53458
315.822	4.44178
319.406	3.75472
322.987	3.79317
326.568	4.60914
330.148	5.81189
333.724	4.54577
337.301	5.02585
340.875	3.21062
344.449	2.93298
348.02	2.16032
351.592	3.03959
355.16	3.9402
358.728	5.58151
362.294	8.20359
365.858	11.2485
369.422	12.2868
372.983	13.8329
376.543	16.4789
380.102	19.1665
383.661	22.3238
387.216	24.4983
390.771	27.4939
394.324	28.7017
397.875	30.3191
401.425	29.709
404.974	29.1651
408.524	27.1925
412.07	25.96
415.614	24.477
419.156	21.4964
422.698	17.4208
426.238	14.9498
429.777	12.8967
433.315	10.2785
436.852	7.51073
440.387	5.64844
443.919	4.5553
447.451	4.53134
450.982	2.54848
454.512	2.12204
458.038	2.64667
461.565	4.13554
465.091	5.83357
468.613	9.50221
472.136	11.6934
475.655	14.6668
479.176	18.266
482.692	20.2082
486.21	22.8384
489.724	24.0385
493.237	26.3717
496.75	27.5389
500.26	29.556
503.769	30.1259
507.279	29.1369
510.785	30.5893
514.289	32.6883
517.793	31.1891
521.297	29.0866
524.797	28.2821
528.297	27.3022
531.795	25.3842
535.291	23.3219
538.787	22.0279
542.281	20.2051
545.773	18.634
549.264	18.3699
552.754	16.4944
556.243	15.4901
559.73	14.4229
563.216	13.7378
566.701	12.7322
570.182	11.0508
573.664	10.0783
577.145	6.779
580.624	5.44046
584.1	4.45444
587.577	3.34216
591.052	2.8868
594.524	2.17248
597.997	3.90429
601.466	2.2404
604.936	2.6744
608.403	3.24995
611.87	4.37558
615.334	4.63148
618.799	6.35096
622.26	8.16339
625.72	9.06153
629.181	9.46218
632.638	11.9683
636.095	14.1086
639.551	14.8831
643.005	16.3483
646.457	16.988
649.908	18.1904
653.357	17.6057
656.806	17.3756
660.253	17.0336
663.7	17.6252
667.145	18.9242
670.588	16.3028
674.027	16.6486
677.468	15.4896
680.907	15.9461
684.345	18.743
687.781	20.1103
691.216	22.4938
694.65	26.9199
698.081	28.4074
701.512	32.2824
704.942	34.8725
708.371	38.2413
711.796	40.5911
715.222	41.3311
718.645	43.4234
722.068	45.0643
725.49	46.6296
728.909	47.176
732.329	47.4012
735.745	48.0863
739.16	47.8309
742.576	49.3002
745.988	52.0283
749.401	52.3761
752.811	52.6965
756.22	52.498
759.627	54.0915
763.035	56.8809
766.44	60.2632
769.843	63.9525
773.245	66.4832
776.646	70.2492
780.046	71.931
783.444	71.1958
786.841	72.8789
790.237	76.5463
793.631	80.3582
797.024	82.7846
800.416	84.289
803.807	84.7186
807.196	87.3496
810.584	86.1738
813.971	87.0864
817.354	87.8412
820.739	87.8582
824.122	87.6642
827.503	87.3778
830.882	84.6981
834.261	83.5814
837.637	81.0147
841.013	76.303
844.389	72.775
847.761	70.93
851.131	66.9955
854.503	62.8287
857.871	58.133
861.24	54.0081
864.606	49.6598
867.97	48.7431
871.336	51.9683
874.698	53.0435
878.058	51.2215
881.418	49.6403
884.778	49.2462
888.135	48.4159
891.49	47.847
894.845	48.0614
898.198	48.721
901.55	48.6667
904.901	48.5387
908.25	48.5478
911.598	48.0388
914.945	49.124
918.291	47.6859
921.635	47.1013
924.978	47.9787
928.318	48.5109
931.659	48.4124
934.998	46.6576
938.336	47.3752
941.671	47.2032
945.007	45.3199
948.339	45.6592
951.672	46.5612
955.004	47.2409
958.333	44.0748
961.662	41.0912
964.989	39.7761
968.315	41.8149
971.639	42.3197
974.962	42.0367
978.285	42.6091
981.605	43.1021
984.924	43.9659
988.243	42.1025
991.56	41.0376
994.875	41.8638
998.188	43.3125
1001.5	43.2038
1004.81	43.6229
1008.12	43.449
1011.43	43.7939
1014.74	42.6655
1018.05	44.4156
1021.35	43.9886
1024.65	43.0246
1027.96	43.0898
1031.26	43.881
1034.56	41.5532
1037.86	38.6266
1041.16	35.3312
1044.45	34.9165
1047.75	35.2294
1051.04	34.1959
1054.33	31.6633
1057.62	29.6672
1060.91	27.3155
1064.2	24.2613
1067.49	22.1518
1070.77	21.1017
1074.06	21.517
1077.34	21.2615
1080.62	20.8851
1083.91	19.5222
1087.18	18.5294
1090.46	19.5994
1093.74	20.2649
1097.02	21.0103
1100.29	21.4085
1103.56	19.6289
1106.84	19.5977
1110.11	16.4951
1113.38	14.8399
1116.64	15.1371
1119.91	15.7293
1123.18	17.2902
1126.44	17.3504
1129.7	18.0976
1132.97	17.9862
1136.23	18.6705
1139.49	19.5523
1142.74	19.8533
1146	20.0811
1149.26	22.0582
1152.51	21.1821
1155.76	20.9771
1159.01	20.8242
1162.27	18.7274
1165.51	16.5848
1168.76	13.9093
1172.01	12.2682
1175.25	9.97528
1178.5	6.80356
1181.74	5.18432
1184.98	3.15407
1188.22	2.01632
1191.46	1.63614
1194.7	7.16892
1197.94	7.98332
1201.17	10.0364
1204.41	13.1216
1207.64	17.0753
1210.87	21.4463
1214.1	25.0043
1217.33	28.8235
1220.56	32.488
1223.79	36.9573
1227.01	40.1424
1230.23	45.1536
1233.46	46.3809
1236.68	49.1673
1239.9	49.7339
1243.12	49.2264
1246.34	49.7095
1249.55	49.0873
1252.77	49.0364
1255.98	50.4514
1259.2	49.4949
1262.41	48.5564
1265.62	48.5652
1268.83	47.9459
1272.03	46.4141
1275.24	46.0778
1278.45	46.0528
1281.65	47.984
1284.85	49.1236
1288.06	50.1114
1291.26	51.2025
1294.46	53.0019
1297.66	55.3428
1300.85	58.3794
1304.05	62.5526
1307.24	65.4536
1310.43	68.3467
1313.63	69.3142
1316.82	71.5202
1320.01	72.8986
1323.2	74.9378
1326.38	76.8728
1329.57	76.7577
1332.76	78.1867
1335.94	76.659
1339.12	74.9489
1342.3	74.71
1345.48	71.438
1348.66	68.7344
1351.84	66.1367
1355.01	62.7695
1358.19	59.8302
1361.36	56.1479
1364.53	52.0248
1367.71	49.5553
1370.88	47.8117
1374.04	46.1652
1377.21	45.787
1380.38	46.4496
1383.54	47.0076
1386.71	46.542
1389.87	46.5138
1393.03	46.1401
1396.19	46.843
1399.35	46.2921
1402.51	47.1993
1405.67	47.5746
1408.82	49.2155
1411.98	48.7769
1415.13	50.0335
1418.28	52.1505
1421.43	54.4717
1424.58	56.4305
1427.73	58.9745
1430.88	62.6494
1434.02	65.0144
1437.17	67.0188
1440.31	70.4462
1443.45	73.8429
1446.6	76.8678
1449.74	78.8106
1452.87	80.9095
1456.01	80.7288
1459.15	79.2979
1462.28	78.392
1465.42	75.8268
1468.55	72.6245
1471.68	70.2453
1474.81	66.4181
1477.94	61.1264
1481.07	57.0549
1484.2	53.1173
1487.32	48.7495
1490.45	43.739
1493.57	40.4677
1496.69	38.8624
1499.81	37.3735
1502.93	36.1228
1506.05	33.9909
1509.17	32.4937
1512.28	31.2031
1515.4	31.9758
1518.51	32.3246
1521.63	32.3314
1524.74	30.8987
1527.85	31.216
1530.96	29.6071
1534.06	29.5351
1537.17	28.8943
1540.28	29.3084
1543.38	29.4232
1546.48	29.6333
1549.59	32.8267
1552.69	33.2767
1555.79	33.9548
1558.88	36.735
1561.98	38.518
1565.08	39.0894
1568.17	40.5741
1571.27	43.2107
1574.36	45.2067
1577.45	47.3513
1580.54	48.987
1583.63	51.2068
1586.72	54.2393
1589.8	56.6459
1592.89	58.0885
1595.97	58.4516
1599.06	56.5925
1602.14	56.5318
1605.22	55.8087
1608.3	54.1916
1611.38	54.5142
1614.46	54.1485
1617.53	53.6168
1620.61	52.9547
1623.68	54.7758
1626.75	55.2774
1629.82	55.408
1632.9	57.6463
1635.96	59.5169
1639.03	62.1275
1642.1	64.4206
1645.16	67.3771
1648.23	70.7488
1651.29	72.8793
1654.36	76.6076
1657.42	78.8218
1660.48	79.5171
1663.53	77.4975
1666.59	76.397
1669.65	73.5364
1672.7	70.1034
1675.76	65.5708
1678.81	61.5964
1681.86	56.5363
1684.91	51.7395
1687.96	47.0552
1691.01	41.5317
1694.06	35.9561
1697.11	30.9854
1700.15	26.3571
1703.2	21.7611
1706.24	19.0081
1709.28	16.5878
1712.32	14.3239
1715.36	11.4994
1718.4	10.2127
1721.43	9.43464
1724.47	9.46454
1727.5	8.41594
1730.54	7.28955
1733.57	6.37479
1736.6	4.11365
1739.63	4.41054
1742.66	5.01354
1745.69	4.56375
1748.72	4.46653
1751.74	4.92257
1754.77	5.22857
1757.79	5.28851
1760.81	5.68486
1763.83	6.26687
1766.85	5.49114
1769.87	5.0212
1772.89	4.47742
1775.91	4.7421
1778.92	4.85918
1781.94	5.17405
1784.95	3.76834
1787.96	4.1272
1790.97	4.33815
1793.98	4.15382
1796.99	3.75593
1800	3.50564
1803	2.63429
1806.01	2.98019
1809.01	2.68477
1812.02	3.41463
1815.02	4.821
1818.02	4.37034
1821.02	4.11964
1824.02	4.38816
1827.01	4.61478
1830.01	4.75676
1833	4.30832
1836	4.49921
1838.99	3.60141
1841.98	3.97767
1844.97	4.58277
1847.96	5.06597
1850.95	4.30496
1853.94	3.58146
1856.92	3.2593
1859.91	2.08539
1862.89	1.03134
1865.88	-0.396041
1868.86	-0.826437
1871.84	-0.227579
1874.82	0.530467
1877.8	0.957045
1880.77	1.79028
1882.52	1.88106
1885.51	3.12394
1888.5	2.70956
1891.49	4.10565
1894.47	4.84155
1897.46	6.27901
1900.44	6.21524
1903.42	5.46071
1906.4	6.13488
1909.38	6.48373
1912.36	6.52275
1915.34	5.83208
1918.32	5.02975
1921.29	3.07296
1924.27	2.93386
1927.24	2.3816
1930.21	1.71598
1933.18	1.71107
1936.15	1.28061
1939.12	0.468065
1942.09	1.36345
1945.06	2.18084
1948.02	3.23407
1950.99	3.28381
1953.95	3.50184
1956.91	4.0328
1959.87	4.33843
1962.84	4.68248
1965.79	5.18619
1968.75	5.24176
1971.71	4.40699
1974.66	3.92026
1977.62	3.92262
1980.57	3.66682
1983.53	2.79717
1986.48	1.6419
1989.43	1.95967
1992.38	2.20775
1995.33	3.18236
1998.27	4.17554
2001.22	4.18748
2004.16	4.20261
2007.11	4.93936
2010.05	5.0626
2012.99	5.09851
2015.93	4.131
2018.87	5.13558
2021.81	5.16774
2024.75	5.90055
2027.69	5.532
2030.62	5.99947
2033.56	5.98834
2036.49	6.22719
2039.42	6.11277
2042.35	6.60681
2045.28	6.0808
2048.21	6.49095
2051.14	6.33584
2054.06	5.85797
2056.99	6.3433
2059.92	6.366
2062.84	6.12141
2065.76	5.65473
2068.68	5.27724
2071.6	4.46793
2074.52	4.94106
2077.44	4.94839
2080.36	5.47999
2083.27	4.57001
2086.19	4.79711
2089.1	5.19895
2092.01	6.07782
2094.93	6.59569
2097.84	6.47538
2100.75	6.72901
2103.66	6.53848
2106.56	7.18672
2109.47	6.64599
2112.37	7.28619
2115.28	7.5203
2118.18	7.39494
2121.09	7.68372
2123.99	7.81999
2126.89	7.42345
2129.79	7.57246
2132.68	7.38232
2135.58	7.69497
2138.48	8.77452
2141.37	10.2613
2144.26	11.7985
2147.16	14.0048
2150.05	15.5064
2152.94	17.6695
2155.83	19.932
2158.72	22.6379
2161.6	24.9058
2164.49	26.246
2167.38	27.7115
2170.26	28.7468
2173.14	30.2864
2176.03	31.9825
2178.91	32.3144
2181.79	32.5119
2184.67	33.1516
2187.54	32.6713
2190.42	31.964
2193.3	30.2718
2196.17	28.0035
2199.05	25.2379
2201.92	24.2895
2204.79	21.8955
2207.66	20.1328
2210.53	18.5036
2213.4	16.3847
2216.27	15.1116
2219.13	13.6545
2222	13.2187
2224.86	13.46
2227.72	11.9841
2230.59	11.3415
2233.45	11.0687
2236.31	9.54272
2239.17	9.77279
2242.03	9.66398
2244.88	9.21305
2247.74	9.87454
2250.59	9.74961
2253.45	9.87194
2256.3	9.95775
2259.15	10.1825
2262	8.95806
2264.85	8.80105
2267.7	8.86411
2270.55	8.10836
2273.4	7.21386
2276.24	7.04005
2279.09	7.33481
2281.93	6.98702
2284.77	7.22589
2287.61	6.27546
2290.46	5.07121
2293.29	4.46058
2296.13	4.06118
2298.97	3.72868
2301.81	3.8683
2304.64	4.08511
2307.48	3.71527
2310.31	2.947
2313.14	3.22764
2315.97	4.46304
2318.8	4.58324
2321.63	4.16336
2324.46	4.33791
2327.29	4.7794
2330.12	4.82012
2332.94	4.49035
2335.76	4.97995
2338.59	3.62155
2341.41	3.35206
2344.23	2.33827
2347.05	1.41606
2349.87	1.06804
2352.69	0.298685
2355.5	-0.188115
2358.32	0.0486104
2361.14	0.153547
2363.95	1.29648
2366.76	1.93614
2369.58	2.67161
2372.39	3.10462
2375.2	3.92347
2378	3.76072
2380.81	3.70821
2383.62	3.97659
2386.42	3.88562
2389.23	3.39927
2392.03	4.05357
2394.84	5.18307
2397.64	4.9458
2400.44	5.83077
2403.24	5.1458
2406.04	5.37709
2408.83	5.40397
2411.63	6.23139
2414.43	6.92582
2417.22	7.53519
2420.02	7.05726
2422.81	8.17021
2425.6	8.32048
2428.39	7.90222
2431.18	8.07583
2433.97	7.43577
2436.76	7.76501
2439.54	7.56953
2442.33	7.52196
2445.11	6.5098
2447.9	5.89057
2450.68	5.62724
2453.46	6.7433
2456.24	6.66624
2459.02	6.66995
2461.8	5.91532
2464.58	5.98338
2467.36	5.83919
2470.13	6.15572
2472.91	6.48442
2475.68	6.65614
2478.45	6.96675
2481.22	5.92362
2484	5.41877
2486.77	3.46527
2489.54	3.33966
2492.3	2.92497
2495.07	2.20181
2497.84	1.15864
2500.6	0.987999
2503.36	0.949927
2506.13	0.371015
2508.89	0.0302978
2511.65	0.0774445
2514.41	0.991848
2517.17	1.56518
2519.93	2.55702
2522.68	2.62042
2525.44	2.69019
2528.19	3.23747
2530.95	4.54351
2533.7	5.22277
2536.45	5.45792
2539.2	5.91375
2541.95	6.31052
2544.7	7.13435
2547.45	7.28101
2550.2	7.82123
2552.94	8.36498
2555.69	8.28267
2558.43	8.89004
2561.17	8.2396
2563.92	7.71809
2566.66	7.30882
2569.4	7.29411
2572.14	7.35724
2574.88	6.74921
2577.61	6.84211
2580.35	6.71432
2583.09	6.59599
2585.82	6.45097
2588.55	6.64026
2591.28	6.18606
2594.02	5.95169
2596.75	6.26333
2599.48	5.97803
2602.2	4.74844
2604.93	4.79183
2607.66	4.76084
2610.38	4.08737
2613.11	4.49396
2615.83	4.68491
2618.56	4.69687
2621.28	4.76067
2624	4.57883
2626.72	4.01437
2629.44	3.31965
2632.15	2.63859
2634.87	2.66455
2637.59	2.96773
2640.3	2.73649
2643.02	2.52352
2645.73	2.90711
2648.44	3.02062
2651.15	3.37832
2653.86	3.83661
2656.57	4.00701
2659.28	4.86149
2661.99	4.92943
2664.69	6.36063
2667.4	6.93313
2670.1	7.97929
2672.81	7.90092
2675.51	8.41704
2678.21	8.81536
2680.91	9.44152
2683.61	9.3519
2686.31	8.85502
2689	7.80943
2691.7	7.6904
2694.4	7.34894
2697.09	6.51896
2699.79	5.94659
2702.48	6.43382
2705.17	6.84196
2707.86	6.41962
2710.55	7.12364
2713.24	8.11364
2715.93	9.00363
2718.61	9.48372
2721.3	10.2507
2723.99	11.7468
2726.67	12.7742
2729.35	13.7737
2732.04	15.5529
2734.72	15.5291
2737.4	15.3375
2740.08	15.1232
2742.76	15.1864
2745.43	15.0793
2748.11	14.6507
2750.79	14.122
2753.46	13.0266
2756.13	12.5538
2758.81	12.2844
2761.48	9.97048
2764.15	8.22813
2766.82	7.11292
2769.49	6.39393
2772.16	5.43052
2774.82	4.86679
2777.49	3.61302
2780.16	3.3776
2782.82	3.53041
2785.48	3.4487
2788.15	4.27442
2790.81	3.8934
2793.47	3.5742
2796.13	3.02281
2798.79	2.77837
2801.44	2.63995
2804.1	2.57962
2806.76	3.70456
2809.41	4.00908
2812.07	5.08281
2814.72	6.68122
2817.37	7.30616
2820.02	8.33826
2822.67	10.4443
2825.32	11.7219
2827.97	14.1692
2830.62	17.4386
2833.26	20.0364
2835.91	23.5988
2838.55	28.3558
2841.2	33.9531
2843.84	42.119
2846.48	50.325
2849.12	59.0166
2851.76	68.5044
2854.4	77.8968
2857.04	87.132
2859.68	96.2327
2862.32	104.867
2864.95	113.927
2867.58	121.697
2870.22	128.332
2872.85	134.356
2875.48	139.796
2878.11	145.59
2880.74	149.989
2883.37	153.715
2886	158.219
2888.63	161.715
2891.25	165.689
2893.88	170.706
2896.5	175.801
2899.13	181.335
2901.75	189.348
2904.37	199.031
2906.99	211.532
2909.61	224.409
2912.23	237.492
2914.85	251.258
2917.46	264.446
2920.08	276.488
2922.7	285.867
2925.31	293.238
2927.92	297.67
2930.53	301.378
2933.15	300.821
2935.76	298.552
2938.37	294.493
2940.98	289.107
2943.58	281.264
2946.19	272.172
2948.8	261.604
2951.4	250.454
2954.01	238.668
2956.61	227.168
2959.21	215.793
2961.81	203.885
2964.41	192.59
2967.01	182.779
2969.61	174.091
2972.21	165.478
2974.81	156.109
2977.4	147.632
2980	139.459
2982.59	130.287
2985.18	120.819
2987.78	110.292
2990.37	100.823
2992.96	91.4376
2995.55	81.8906
2998.14	73.5556
3000.72	65.2841
3003.31	57.1389
3005.9	49.8042
3008.48	43.4819
3011.07	37.7486
3013.65	31.2399
3016.23	26.8175
3018.81	22.9425
3021.39	19.1628
3023.97	16.2938
3026.55	13.58
3029.13	11.4374
3031.71	10.663
3034.28	10.0822
3036.86	9.97465
3039.43	9.79541
3042.01	10.3329
3044.58	10.9511
3047.15	11.4941
3049.72	11.7601
3052.29	12.3318
3054.86	12.4802
3057.43	11.6741
3060	11.9906
3062.56	11.5003
3065.13	11.1226
3067.69	9.96756
3070.25	9.32811
3072.82	8.31397
3075.38	6.65798
3077.94	5.10014
3080.5	3.48631
3083.06	2.02747
3085.62	1.19814
3088.17	-0.138154
3090.73	-0.476802
3093.29	-0.610523
3095.84	-0.426015
3098.4	-1.8285
3100.95	-1.56932
3103.5	-0.635125
3106.05	-0.421178
3108.6	0.251727
3111.15	0.689883
3113.7	1.53789
3116.25	1.58046
3118.79	2.52628
3121.34	3.54903
3123.88	4.31289
3126.43	5.57605
3128.97	6.56418
3131.51	7.21311
3134.05	8.15967
3136.59	9.56326
3139.14	10.2826
3141.67	11.0042
3144.21	11.9739
3146.75	12.0993
3149.28	12.1214