File: data/Raman/poly_smoothed/Mb_10_14_13_1x_45s_532 nm_x100_100%_600 gr_mm_01.txt
#Acq. time (s)=	45
#Accumulations=	2
#Range (cm-¹)=	200...3150
#Windows=	2
#Auto scanning=	Off
#Autofocus=	Off
#Macrospot=	Off
#AutoExposure=	Off
#Spike filter=	Multiple accum.
#Delay time (s)=	0
#Binning=	1
#Readout mode=	Signal
#DeNoise=	Off
#ICS correction=	On
#Dark correction=	Off
#Inst. Process=	Off
#Detector Gain=	Best Dynamic Range
#Detector ADC=	20 kHz
#Detector temperature (°C)=	-69.85
#Instrument=	LabRAM HR Evol
#Detector=	Synapse
#Objective=	x100
#Grating=	600 gr/mm
#ND Filter=	100%
#Laser (nm)=	532
#Hole=	100.021
#Range=	Auto
#Laser Pol.=	No
#Raman. Pol.=	No
#Laser Pol. (°)=	-0.0007625
#Raman Pol. (°)=	89.9995
#Collection=	Microscope
#StageXY=	Marzhauser
#StageZ=	Marzhauser
#X (µm)=	-641.9
#Y (µm)=	-1591.2
#Z (µm)=	89
#Full time(mm:ss)=	3:19
#Project=
#Sample=
#Site=
#Title=	Mb_10_14_13_2x_45s_532 nm_x100_100%_600 gr_mm
#Remark=
#Date=	11.07.2022 09:29
#Acquired=	11.07.2022 09:29:10
#Base:Fit=	10.08.2022 10:21:11
#Base:Sub=	10.08.2022 10:21:41
#Filter:Polynom=	16.08.2022 10:17:53
#AxisType[0]=Intens
#AxisUnit[0]=Cnt
#AxisType[1]=Spectr
#AxisUnit[1]=1/cm
200.388	16.6846
204.019	11.5041
207.646	5.36815
211.274	1.195
214.899	-1.77433
218.524	-0.0253104
222.146	4.43434
225.766	8.42014
229.388	12.4164
233.005	13.9606
236.621	19.0824
240.236	22.4074
243.852	23.5168
247.464	25.7886
251.074	28.4028
254.683	30.0282
258.291	33.2833
261.897	32.7689
265.504	30.8367
269.108	30.314
272.71	28.2298
276.311	25.838
279.91	22.4181
283.508	19.0218
287.105	15.1419
290.698	10.8053
294.291	9.42425
297.884	7.88006
301.475	6.49579
305.064	7.16119
308.652	8.07493
312.237	8.23587
315.822	8.48276
319.406	8.72724
322.987	8.81132
326.568	9.03187
330.148	7.35677
333.724	5.90391
337.301	5.71831
340.875	4.38078
344.449	4.61896
348.02	6.97298
351.592	6.58795
355.16	8.29036
358.728	10.7394
362.294	13.154
365.858	16.7924
369.422	19.0085
372.983	22.507
376.543	24.5551
380.102	29.5607
383.661	34.5791
387.216	38.4106
390.771	40.8682
394.324	42.4125
397.875	46.4644
401.425	47.0077
404.974	47.4856
408.524	45.524
412.07	43.8714
415.614	41.2201
419.156	38.6517
422.698	34.276
426.238	30.4716
429.777	28.8887
433.315	25.5921
436.852	23.1054
440.387	20.903
443.919	18.8285
447.451	15.589
450.982	14.372
454.512	13.4648
458.038	12.0248
461.565	11.9894
465.091	12.4973
468.613	14.7146
472.136	15.7709
475.655	15.0592
479.176	16.7317
482.692	19.4363
486.21	22.2456
489.724	23.3071
493.237	26.2636
496.75	29.1245
500.26	29.8753
503.769	31.7218
507.279	31.5402
510.785	31.659
514.289	33.0766
517.793	32.9473
521.297	31.7162
524.797	32.3107
528.297	30.7571
531.795	29.5293
535.291	27.4015
538.787	26.4184
542.281	24.3352
545.773	21.7749
549.264	18.9668
552.754	17.7737
556.243	15.3134
559.73	14.1553
563.216	14.4097
566.701	12.3205
570.182	11.1217
573.664	10.0077
577.145	8.35642
580.624	9.23673
584.1	8.97098
587.577	7.91561
591.052	7.07015
594.524	5.62484
597.997	5.68213
601.466	7.69524
604.936	7.30628
608.403	6.78815
611.87	7.51943
615.334	7.45646
618.799	8.69848
622.26	9.11788
625.72	9.77917
629.181	9.90401
632.638	11.0527
636.095	13.1499
639.551	14.0091
643.005	16.4931
646.457	17.3325
649.908	17.341
653.357	16.571
656.806	17.1511
660.253	17.6843
663.7	17.4732
667.145	17.1061
670.588	16.8554
674.027	17.2267
677.468	19.3329
680.907	19.783
684.345	22.2159
687.781	23.3291
691.216	23.326
694.65	24.8969
698.081	24.9955
701.512	24.5008
704.942	25.0729
708.371	26.4859
711.796	27.2118
715.222	28.358
718.645	31.0507
722.068	33.3073
725.49	33.3732
728.909	34.2948
732.329	35.2741
735.745	34.9158
739.16	36.163
742.576	36.3196
745.988	36.3257
749.401	38.2575
752.811	40.2795
756.22	44.2527
759.627	48.7259
763.035	50.8811
766.44	53.8887
769.843	55.1201
773.245	56.5622
776.646	58.3678
780.046	59.019
783.444	60.4888
786.841	62.4108
790.237	63.6756
793.631	65.791
797.024	67.3374
800.416	67.8848
803.807	69.5497
807.196	70.3016
810.584	69.7159
813.971	69.6315
817.354	68.7133
820.739	68.2221
824.122	67.4748
827.503	66.9062
830.882	66.7856
834.261	68.5694
837.637	69.2331
841.013	69.8909
844.389	67.6752
847.761	65.1083
851.131	63.3538
854.503	60.7783
857.871	58.792
861.24	56.6747
864.606	53.8538
867.97	52.9804
871.336	50.9431
874.698	50.0252
878.058	50.6965
881.418	47.8108
884.778	47.463
888.135	47.017
891.49	45.7928
894.845	44.12
898.198	43.4198
901.55	43.3116
904.901	43.1085
908.25	43.8325
911.598	44.5074
914.945	47.6121
918.291	48.3166
921.635	49.0449
924.978	49.0286
928.318	48.7471
931.659	48.0918
934.998	47.8714
938.336	47.1612
941.671	45.7761
945.007	43.1452
948.339	42.504
951.672	42.804
955.004	43.0577
958.333	43.5274
961.662	40.0292
964.989	42.2696
968.315	43.0086
971.639	45.1636
974.962	47.3793
978.285	48.0768
981.605	50.1417
984.924	51.784
988.243	54.853
991.56	55.625
994.875	56.2329
998.188	58.4523
1001.5	59.715
1004.81	58.971
1008.12	59.9672
1011.43	61.0675
1014.74	62.9605
1018.05	64.7016
1021.35	64.9015
1024.65	65.0952
1027.96	66.4939
1031.26	67.743
1034.56	66.2748
1037.86	63.7339
1041.16	61.2673
1044.45	60.2013
1047.75	59.3291
1051.04	57.4501
1054.33	53.9125
1057.62	48.8107
1060.91	45.1299
1064.2	40.6971
1067.49	35.7801
1070.77	30.2373
1074.06	24.4628
1077.34	21.4151
1080.62	17.8004
1083.91	15.4102
1087.18	12.2693
1090.46	12.3942
1093.74	12.8175
1097.02	12.9774
1100.29	14.456
1103.56	14.3381
1106.84	14.8823
1110.11	14.1214
1113.38	12.6369
1116.64	12.8638
1119.91	12.2031
1123.18	12.3389
1126.44	11.6839
1129.7	10.9176
1132.97	10.1365
1136.23	9.55752
1139.49	8.44697
1142.74	7.55419
1146	8.00364
1149.26	6.54719
1152.51	6.3827
1155.76	5.64588
1159.01	5.72699
1162.27	4.7548
1165.51	5.53648
1168.76	3.33182
1172.01	4.82721
1175.25	6.83904
1178.5	9.16938
1181.74	11.0502
1184.98	11.1002
1188.22	12.0049
1191.46	12.8798
1194.7	16.4416
1197.94	19.2502
1201.17	22.5994
1204.41	24.5616
1207.64	26.3272
1210.87	29.9849
1214.1	32.9317
1217.33	37.2778
1220.56	44.1225
1223.79	46.4834
1227.01	51.9744
1230.23	55.9591
1233.46	60.4467
1236.68	62.7435
1239.9	64.8285
1243.12	66.1557
1246.34	67.0116
1249.55	68.4683
1252.77	70.7047
1255.98	70.0526
1259.2	69.035
1262.41	67.9008
1265.62	66.6677
1268.83	66.6842
1272.03	66.159
1275.24	67.6785
1278.45	67.376
1281.65	66.8882
1284.85	66.963
1288.06	69.4776
1291.26	70.8931
1294.46	74.2452
1297.66	78.3858
1300.85	79.538
1304.05	82.0897
1307.24	83.986
1310.43	85.9088
1313.63	86.5448
1316.82	86.7308
1320.01	87.7575
1323.2	87.5233
1326.38	88.5405
1329.57	88.6021
1332.76	86.5218
1335.94	84.6486
1339.12	82.5073
1342.3	79.4094
1345.48	76.1239
1348.66	73.2532
1351.84	70.3789
1355.01	66.7799
1358.19	63.438
1361.36	59.3661
1364.53	56.2958
1367.71	52.3417
1370.88	49.939
1374.04	46.3622
1377.21	43.4603
1380.38	41.9337
1383.54	40.2189
1386.71	40.6504
1389.87	40.9458
1393.03	43.2392
1396.19	41.4799
1399.35	42.2917
1402.51	43.8916
1405.67	47.067
1408.82	49.18
1411.98	52.6628
1415.13	56.9131
1418.28	62.6575
1421.43	69.3442
1424.58	76.2862
1427.73	81.8077
1430.88	87.7653
1434.02	94.6779
1437.17	99.7234
1440.31	103.527
1443.45	104.771
1446.6	106.917
1449.74	106.46
1452.87	104.958
1456.01	103.832
1459.15	100.326
1462.28	95.4541
1465.42	89.0171
1468.55	81.8895
1471.68	72.7408
1474.81	64.4533
1477.94	57.1007
1481.07	49.8205
1484.2	44.6261
1487.32	40.1467
1490.45	35.9365
1493.57	31.9628
1496.69	30.7236
1499.81	28.6305
1502.93	27.276
1506.05	27.5478
1509.17	27.617
1512.28	26.5231
1515.4	24.4623
1518.51	24.676
1521.63	23.4714
1524.74	24.614
1527.85	25.9206
1530.96	25.3755
1534.06	26.0529
1537.17	27.3073
1540.28	28.9367
1543.38	28.6691
1546.48	29.7295
1549.59	31.8064
1552.69	33.4525
1555.79	34.1712
1558.88	35.1328
1561.98	35.6442
1565.08	37.1164
1568.17	39.1632
1571.27	41.2541
1574.36	43.6919
1577.45	46.9045
1580.54	48.1704
1583.63	50.2732
1586.72	53.0514
1589.8	56.041
1592.89	59.0335
1595.97	59.0278
1599.06	61.7953
1602.14	62.7863
1605.22	62.6145
1608.3	64.4537
1611.38	66.0918
1614.46	67.7351
1617.53	67.2564
1620.61	67.8692
1623.68	70.0634
1626.75	71.8218
1629.82	73.7609
1632.9	75.3489
1635.96	77.8411
1639.03	80.5248
1642.1	84.468
1645.16	88.5382
1648.23	91.1539
1651.29	93.8244
1654.36	96.3111
1657.42	98.7959
1660.48	99.0772
1663.53	99.9451
1666.59	97.7736
1669.65	93.1389
1672.7	89.0415
1675.76	84.445
1678.81	77.8472
1681.86	71.6609
1684.91	65.3665
1687.96	57.5327
1691.01	51.3347
1694.06	45.4117
1697.11	38.9933
1700.15	33.2553
1703.2	27.9525
1706.24	22.8435
1709.28	18.8757
1712.32	15.4004
1715.36	11.0836
1718.4	9.68902
1721.43	8.68577
1724.47	7.23957
1727.5	7.27235
1730.54	8.17601
1733.57	7.66749
1736.6	7.18113
1739.63	7.61638
1742.66	7.62175
1745.69	6.09824
1748.72	6.81366
1751.74	6.08224
1754.77	6.15811
1757.79	5.6447
1760.81	6.04489
1763.83	6.55148
1766.85	6.03075
1769.87	5.70899
1772.89	4.1219
1775.91	3.75765
1778.92	3.64991
1781.94	3.77268
1784.95	4.13558
1787.96	4.47241
1790.97	5.22312
1793.98	5.82569
1796.99	5.4546
1800	6.56152
1803	6.37633
1806.01	5.58359
1809.01	4.62623
1812.02	4.26994
1815.02	5.30639
1818.02	4.98082
1821.02	4.21678
1824.02	3.5428
1827.01	3.01784
1830.01	3.66407
1833	2.94693
1836	1.6238
1838.99	2.09995
1841.98	2.21196
1844.97	1.65396
1847.96	1.69562
1850.95	2.29946
1853.94	3.12913
1856.92	3.13206
1859.91	4.62909
1862.89	3.80986
1865.88	4.09051
1868.86	3.01387
1871.84	3.55063
1874.82	4.06366
1877.8	4.13104
1880.77	5.91444
1882.52	6.28335
1885.51	7.25969
1888.5	7.63274
1891.49	6.65345
1894.47	5.2554
1897.46	5.35878
1900.44	5.25195
1903.42	4.72544
1906.4	4.59417
1909.38	4.4703
1912.36	5.39664
1915.34	4.76989
1918.32	4.06236
1921.29	3.65697
1924.27	3.66031
1927.24	2.1305
1930.21	2.3378
1933.18	1.50525
1936.15	0.765683
1939.12	0.0854583
1942.09	0.0476625
1945.06	0.855002
1948.02	1.43679
1950.99	1.51926
1953.95	1.55674
1956.91	1.80088
1959.87	1.19798
1962.84	-0.00588179
1965.79	0.327724
1968.75	0.666045
1971.71	2.34602
1974.66	2.36902
1977.62	3.59597
1980.57	4.2918
1983.53	5.47356
1986.48	6.10563
1989.43	5.85235
1992.38	5.91318
1995.33	6.12633
1998.27	6.6319
2001.22	6.7429
2004.16	6.28821
2007.11	5.94612
2010.05	5.72735
2012.99	5.17004
2015.93	5.71885
2018.87	6.7524
2021.81	7.05308
2024.75	6.92402
2027.69	6.83835
2030.62	7.33146
2033.56	6.41749
2036.49	7.23261
2039.42	7.67357
2042.35	8.55668
2045.28	8.42919
2048.21	7.6475
2051.14	7.05119
2054.06	7.42665
2056.99	7.66618
2059.92	7.40207
2062.84	5.78036
2065.76	5.34078
2068.68	5.82722
2071.6	5.89659
2074.52	6.29559
2077.44	7.23164
2080.36	8.03911
2083.27	7.33357
2086.19	7.25974
2089.1	9.23092
2092.01	10.2292
2094.93	11.009
2097.84	10.8449
2100.75	11.587
2103.66	12.4792
2106.56	13.2481
2109.47	13.3909
2112.37	11.9058
2115.28	11.1123
2118.18	10.4991
2121.09	10.5793
2123.99	11.2815
2126.89	12.7699
2129.79	12.5534
2132.68	12.989
2135.58	14.0642
2138.48	16.5663
2141.37	17.5309
2144.26	19.2272
2147.16	21.0534
2150.05	22.6777
2152.94	23.1176
2155.83	24.7975
2158.72	28.3904
2161.6	30.8303
2164.49	32.2377
2167.38	34.1514
2170.26	35.0083
2173.14	35.9388
2176.03	35.7649
2178.91	34.1818
2181.79	33.7602
2184.67	33.3284
2187.54	33.1371
2190.42	32.8204
2193.3	31.9213
2196.17	30.3656
2199.05	29.5792
2201.92	27.7859
2204.79	24.8214
2207.66	22.954
2210.53	20.7519
2213.4	20.375
2216.27	19.8757
2219.13	18.2136
2222	17.5407
2224.86	16.5746
2227.72	16.393
2230.59	15.5319
2233.45	15.193
2236.31	15.2856
2239.17	14.7357
2242.03	13.1331
2244.88	12.3951
2247.74	11.8528
2250.59	11.9329
2253.45	11.6423
2256.3	11.1796
2259.15	10.5141
2262	8.89561
2264.85	8.23802
2267.7	7.45061
2270.55	6.29672
2273.4	4.94914
2276.24	4.70333
2279.09	4.04171
2281.93	3.38439
2284.77	3.11035
2287.61	2.4038
2290.46	1.36613
2293.29	1.79215
2296.13	1.26686
2298.97	2.41069
2301.81	3.26473
2304.64	5.15321
2307.48	5.81491
2310.31	6.55217
2313.14	7.22943
2315.97	9.52667
2318.8	10.9905
2321.63	11.6689
2324.46	11.9481
2327.29	11.0744
2330.12	11.1964
2332.94	10.4089
2335.76	11.5838
2338.59	10.2068
2341.41	9.73499
2344.23	10.2555
2347.05	9.84008
2349.87	8.68248
2352.69	8.30014
2355.5	8.69903
2358.32	7.83931
2361.14	7.53523
2363.95	7.62471
2366.76	8.49312
2369.58	8.50928
2372.39	8.67401
2375.2	8.20707
2378	8.30642
2380.81	9.31778
2383.62	9.3141
2386.42	9.5058
2389.23	7.87216
2392.03	7.1078
2394.84	6.40395
2397.64	5.43721
2400.44	6.35682
2403.24	6.14642
2406.04	5.46285
2408.83	4.70725
2411.63	4.61342
2414.43	3.98987
2417.22	4.32732
2420.02	5.15457
2422.81	4.55887
2425.6	5.41402
2428.39	6.64811
2431.18	7.6834
2433.97	7.44487
2436.76	6.92508
2439.54	6.04288
2442.33	5.58141
2445.11	5.73252
2447.9	5.29506
2450.68	4.18443
2453.46	3.83885
2456.24	2.97474
2459.02	2.16766
2461.8	2.05252
2464.58	1.09997
2467.36	1.588
2470.13	0.526203
2472.91	-0.0895597
2475.68	-0.394318
2478.45	-0.982574
2481.22	-1.20417
2484	-1.08658
2486.77	-0.0361486
2489.54	0.118892
2492.3	2.00015
2495.07	3.47988
2497.84	4.14937
2500.6	3.61684
2503.36	4.14689
2506.13	3.64259
2508.89	1.9541
2511.65	1.72863
2514.41	2.37408
2517.17	3.88144
2519.93	4.67003
2522.68	5.07505
2525.44	5.54356
2528.19	5.80068
2530.95	6.82362
2533.7	6.81632
2536.45	8.10364
2539.2	8.38017
2541.95	8.65653
2544.7	8.32875
2547.45	7.80983
2550.2	8.37865
2552.94	8.74269
2555.69	10.143
2558.43	11.5445
2561.17	12.0564
2563.92	12.3566
2566.66	12.2724
2569.4	11.35
2572.14	9.90662
2574.88	8.45089
2577.61	8.63941
2580.35	10.6039
2583.09	10.6393
2585.82	9.91801
2588.55	9.07053
2591.28	8.91816
2594.02	9.14292
2596.75	9.06447
2599.48	9.65552
2602.2	10.5157
2604.93	10.3421
2607.66	10.2072
2610.38	8.88819
2613.11	8.08497
2615.83	8.36012
2618.56	8.29305
2621.28	9.31067
2624	11.2088
2626.72	10.7969
2629.44	10.4697
2632.15	10.1332
2634.87	8.95311
2637.59	7.76841
2640.3	7.70043
2643.02	7.72799
2645.73	7.57672
2648.44	7.92134
2651.15	7.30819
2653.86	6.93618
2656.57	7.60089
2659.28	7.91287
2661.99	8.44446
2664.69	9.27287
2667.4	10.0581
2670.1	9.92602
2672.81	9.03039
2675.51	8.41184
2678.21	8.35598
2680.91	8.91027
2683.61	9.30199
2686.31	10.4579
2689	10.7824
2691.7	11.4289
2694.4	11.2487
2697.09	10.3488
2699.79	9.97031
2702.48	10.1709
2705.17	10.8879
2707.86	11.3884
2710.55	10.9456
2713.24	11.4477
2715.93	11.4087
2718.61	11.1568
2721.3	11.1711
2723.99	11.739
2726.67	12.2769
2729.35	12.7973
2732.04	13.2074
2734.72	13.3031
2737.4	12.5238
2740.08	12.0483
2742.76	11.5209
2745.43	10.5311
2748.11	11.2196
2750.79	10.6776
2753.46	9.29077
2756.13	7.89822
2758.81	7.56329
2761.48	6.27952
2764.15	4.87266
2766.82	4.33216
2769.49	4.44491
2772.16	4.08731
2774.82	3.3563
2777.49	2.59644
2780.16	1.61225
2782.82	1.86823
2785.48	1.37053
2788.15	2.28039
2790.81	2.13912
2793.47	1.79052
2796.13	0.966059
2798.79	1.0931
2801.44	0.845613
2804.1	0.331354
2806.76	0.41539
2809.41	0.118145
2812.07	-0.142606
2814.72	-1.07024
2817.37	-1.05757
2820.02	-0.0109493
2822.67	1.83582
2825.32	4.5069
2827.97	5.90899
2830.62	7.95472
2833.26	11.6952
2835.91	14.802
2838.55	18.276
2841.2	23.8354
2843.84	30.0407
2846.48	37.5605
2849.12	45.8137
2851.76	56.0257
2854.4	65.8746
2857.04	75.4201
2859.68	84.5062
2862.32	93.5704
2864.95	103.213
2867.58	111.582
2870.22	118.25
2872.85	124.703
2875.48	130.963
2878.11	137.605
2880.74	142.965
2883.37	148.158
2886	154.329
2888.63	159.126
2891.25	164.221
2893.88	169.423
2896.5	175.77
2899.13	183.004
2901.75	191.097
2904.37	201.488
2906.99	214.052
2909.61	227.307
2912.23	241.849
2914.85	256.056
2917.46	269.549
2920.08	279.934
2922.7	288.84
2925.31	295.26
2927.92	300.273
2930.53	302.216
2933.15	301.323
2935.76	299.141
2938.37	296.632
2940.98	290.477
2943.58	281.852
2946.19	272.133
2948.8	262.249
2951.4	251.799
2954.01	238.747
2956.61	226.479
2959.21	213.698
2961.81	201.553
2964.41	191.181
2967.01	181.432
2969.61	173.173
2972.21	165.73
2974.81	156.651
2977.4	147.407
2980	137.896
2982.59	128.361
2985.18	117.437
2987.78	106.889
2990.37	96.8414
2992.96	86.4204
2995.55	77.228
2998.14	67.5109
3000.72	58.6672
3003.31	50.6878
3005.9	41.3478
3008.48	34.67
3011.07	27.4323
3013.65	21.8411
3016.23	16.7021
3018.81	12.3211
3021.39	8.46068
3023.97	4.76204
3026.55	2.06266
3029.13	0.650635
3031.71	-0.94423
3034.28	-2.25001
3036.86	-0.957406
3039.43	0.150141
3042.01	1.01059
3044.58	2.19349
3047.15	3.00993
3049.72	5.08313
3052.29	6.1358
3054.86	7.09815
3057.43	7.98185
3060	8.0184
3062.56	8.30004
3065.13	8.32403
3067.69	8.21575
3070.25	7.00163
3072.82	7.41267
3075.38	7.33535
3077.94	6.61191
3080.5	5.96554
3083.06	3.68238
3085.62	2.32166
3088.17	0.799444
3090.73	0.0429934
3093.29	-0.160883
3095.84	-0.431043
3098.4	1.25562
3100.95	2.83782
3103.5	2.78713
3106.05	3.54247
3108.6	5.35495
3111.15	6.34943
3113.7	7.36556
3116.25	7.73457
3118.79	9.05713
3121.34	10.5082
3123.88	11.8498
3126.43	12.8024
3128.97	13.8467
3131.51	15.5444
3134.05	17.9125
3136.59	19.9235
3139.14	20.8277
3141.67	22.321
3144.21	23.2379
3146.75	24.8501
3149.28	26.7543