File: data/Raman/poly_smoothed/Mb_10_14_08_1x_45s_532 nm_x100_100%_600 gr_mm_01.txt
#Acq. time (s)=	45
#Accumulations=	2
#Range (cm-¹)=	200...3150
#Windows=	2
#Auto scanning=	Off
#Autofocus=	Off
#Macrospot=	Off
#AutoExposure=	Off
#Spike filter=	Multiple accum.
#Delay time (s)=	0
#Binning=	1
#Readout mode=	Signal
#DeNoise=	Off
#ICS correction=	On
#Dark correction=	Off
#Inst. Process=	Off
#Detector Gain=	Best Dynamic Range
#Detector ADC=	20 kHz
#Detector temperature (°C)=	-70.08
#Instrument=	LabRAM HR Evol
#Detector=	Synapse
#Objective=	x100
#Grating=	600 gr/mm
#ND Filter=	100%
#Laser (nm)=	532
#Hole=	100.021
#Range=	Auto
#Laser Pol.=	No
#Raman. Pol.=	No
#Laser Pol. (°)=	-0.0007625
#Raman Pol. (°)=	89.9995
#Collection=	Microscope
#StageXY=	Marzhauser
#StageZ=	Marzhauser
#X (µm)=	-2405.6
#Y (µm)=	2130
#Z (µm)=	-40.8
#Full time(mm:ss)=	3:19
#Project=
#Sample=
#Site=
#Title=	Mb_10_14_08_2x_45s_532 nm_x100_100%_600 gr_mm
#Remark=
#Date=	07.07.2022 13:59
#Acquired=	07.07.2022 13:59:03
#Base:Fit=	10.08.2022 10:21:11
#Base:Sub=	10.08.2022 10:21:41
#Filter:Polynom=	16.08.2022 10:17:53
#AxisType[0]=Intens
#AxisUnit[0]=Cnt
#AxisType[1]=Spectr
#AxisUnit[1]=1/cm
200.43	7.41805
204.061	5.28662
207.688	1.49504
211.316	-0.803054
214.941	-0.405169
218.566	1.224
222.188	4.43582
225.809	5.22764
229.43	9.54209
233.047	12.5778
236.663	14.3891
240.278	16.6243
243.894	19.5246
247.506	23.2885
251.116	26.7272
254.725	28.7831
258.333	30.5563
261.939	31.4508
265.546	33.0977
269.15	33.6966
272.752	33.4464
276.353	32.1373
279.952	31.6735
283.55	28.566
287.146	24.6253
290.739	23.7935
294.333	23.3982
297.925	21.8703
301.516	21.29
305.106	21.733
308.694	20.27
312.279	20.6111
315.864	20.5254
319.448	22.0932
323.029	21.4708
326.61	21.8763
330.19	22.5016
333.766	23.1213
337.343	24.2088
340.917	23.0225
344.491	23.1729
348.062	25.7482
351.633	27.968
355.201	30.6286
358.77	31.5169
362.335	33.5674
365.899	34.0677
369.464	38.1281
373.025	42.676
376.585	43.8244
380.143	48.1428
383.702	49.5155
387.258	52.5426
390.812	57.622
394.365	61.6474
397.916	65.0188
401.467	66.6538
405.015	65.4184
408.565	63.7285
412.111	61.897
415.656	58.8969
419.197	55.1315
422.739	51.1725
426.279	47.3377
429.819	42.4123
433.356	39.9709
436.893	36.1036
440.428	33.3346
443.96	28.8541
447.492	26.0343
451.023	22.7183
454.553	21.895
458.079	17.7881
461.606	16.1649
465.132	15.7759
468.654	17.5536
472.177	19.5696
475.696	23.6066
479.217	27.8325
482.733	31.3715
486.251	32.2393
489.765	33.7156
493.278	36.5101
496.791	38.8597
500.301	42.7061
503.81	44.7013
507.319	45.3377
510.825	46.1602
514.33	45.1239
517.833	46.2468
521.337	44.9154
524.838	43.5738
528.337	41.2104
531.835	36.7366
535.332	35.8586
538.827	32.6102
542.321	28.12
545.814	25.4366
549.305	24.1346
552.795	21.8612
556.284	19.8286
559.771	18.4222
563.257	15.1192
566.742	12.5293
570.223	11.3133
573.705	9.71227
577.185	8.46584
580.665	7.89791
584.141	7.52055
587.617	6.14976
591.092	4.38121
594.564	3.9918
598.037	3.14248
601.506	2.91861
604.976	3.62759
608.443	2.25694
611.91	2.12109
615.374	2.22807
618.839	3.16806
622.3	4.17252
625.761	3.61727
629.221	3.0512
632.679	6.26297
636.135	6.21121
639.592	5.8451
643.045	5.49022
646.497	6.35081
649.948	8.12754
653.398	8.20471
656.846	9.00917
660.293	9.76276
663.738	10.6338
667.185	11.0993
670.628	12.3936
674.067	11.9502
677.508	13.7945
680.947	13.0884
684.385	12.8948
687.821	12.2086
691.256	13.6649
694.69	14.7493
698.121	13.9828
701.552	14.8515
704.982	13.9725
708.41	13.861
711.836	13.8206
715.262	15.2948
718.685	16.8593
722.108	16.3345
725.53	18.2724
728.949	18.5007
732.369	18.1732
735.785	19.211
739.2	21.1444
742.616	22.292
746.028	23.4686
749.441	27.5408
752.851	28.4166
756.26	30.1584
759.667	33.4297
763.075	34.0692
766.479	35.9801
769.883	35.569
773.285	37.9794
776.686	40.2579
780.085	41.1241
783.484	41.9982
786.881	42.0954
790.276	43.9127
793.671	45.2112
797.064	47.3205
800.456	48.5409
803.846	49.0178
807.236	49.4124
810.624	48.7469
814.01	49.492
817.394	50.1268
820.778	50.2483
824.161	50.2168
827.543	48.4716
830.921	47.6703
834.3	47.8778
837.676	45.0588
841.053	43.0112
844.426	40.8684
847.8	36.4616
851.171	34.0154
854.542	33.5339
857.911	30.8182
861.279	26.4021
864.645	23.9906
868.01	21.9664
871.375	19.8094
874.737	18.2776
878.097	17.1167
881.457	17.2751
884.817	17.0768
888.174	18.4649
891.53	19.2813
894.884	20.3603
898.237	18.5465
901.589	17.09
904.94	17.8464
908.289	17.5198
911.637	18.3728
914.984	18.3834
918.33	18.207
921.674	19.5772
925.015	19.3108
928.357	18.5008
931.698	17.6358
935.037	17.0664
938.373	15.7693
941.71	13.7566
945.046	12.4164
948.378	7.90898
951.711	9.08419
955.043	6.70888
958.372	3.84138
961.701	3.06039
965.027	5.48658
968.354	7.94344
971.678	9.99308
975	11.6845
978.324	11.6824
981.644	13.6378
984.962	14.6801
988.282	15.2965
991.598	14.6148
994.913	14.2969
998.227	15.8959
1001.54	15.9582
1004.85	16.6005
1008.16	15.0178
1011.47	16.9062
1014.78	19.4397
1018.08	21.7193
1021.39	25.1152
1024.69	27.1798
1028	27.9307
1031.3	28.5767
1034.6	29.7338
1037.9	28.6539
1041.19	30.9486
1044.49	34.4446
1047.79	36.6225
1051.08	36.9177
1054.37	34.3442
1057.66	31.9003
1060.95	31.352
1064.24	29.2855
1067.53	25.2647
1070.81	21.0725
1074.1	19.2744
1077.38	16.4519
1080.66	14.0252
1083.94	13.8482
1087.22	10.721
1090.5	11.4983
1093.78	12.7988
1097.05	13.3194
1100.33	13.8264
1103.6	13.6431
1106.87	12.6644
1110.15	9.98524
1113.41	8.36356
1116.68	7.86133
1119.95	6.97851
1123.21	7.68707
1126.48	7.01478
1129.74	7.23921
1133	5.38363
1136.26	4.73761
1139.52	5.8776
1142.78	7.72831
1146.04	5.74066
1149.29	4.97873
1152.55	6.3445
1155.8	6.22582
1159.05	4.81389
1162.3	5.11842
1165.55	3.95665
1168.8	3.5633
1172.05	4.52421
1175.29	3.78345
1178.54	1.77933
1181.78	1.50346
1185.02	0.859315
1188.26	2.2633
1191.5	1.82728
1194.74	3.10257
1197.97	5.6396
1201.21	10.4776
1204.44	15.5457
1207.68	18.9674
1210.91	22.7709
1214.14	27.5797
1217.37	32.7281
1220.6	37.306
1223.82	42.5631
1227.05	46.984
1230.27	52.8107
1233.49	54.7288
1236.72	56.8493
1239.94	58.9778
1243.16	62.3578
1246.37	64.1695
1249.59	63.9618
1252.8	64.5834
1256.02	63.6379
1259.23	64.3565
1262.44	65.4121
1265.66	65.594
1268.87	65.2123
1272.07	67.101
1275.28	69.4721
1278.48	72.3083
1281.69	75.2036
1284.89	76.7998
1288.09	81.4606
1291.3	85.0205
1294.49	88.6185
1297.69	92.48
1300.89	96.4726
1304.09	100.983
1307.28	104.083
1310.47	107.452
1313.66	110.05
1316.86	112.618
1320.05	115.177
1323.23	114.206
1326.42	113.847
1329.61	111.915
1332.79	111.099
1335.98	106.836
1339.16	105.609
1342.34	102.353
1345.52	98.5097
1348.7	94.9507
1351.87	92.3853
1355.05	88.2228
1358.23	82.6282
1361.4	79.9583
1364.57	77.3551
1367.74	73.6226
1370.91	69.3576
1374.08	65.821
1377.25	64.085
1380.42	61.1887
1383.58	58.808
1386.75	58.1493
1389.91	56.4402
1393.07	55.424
1396.23	55.3495
1399.39	54.0737
1402.55	54.1494
1405.7	54.8162
1408.86	55.5165
1412.01	60.8576
1415.17	64.7888
1418.32	72.0496
1421.47	79.1718
1424.62	87.6614
1427.77	97.4733
1430.92	104.66
1434.06	111.754
1437.2	120.512
1440.35	127.171
1443.49	132.232
1446.63	135.228
1449.77	136.587
1452.91	137.169
1456.05	135.315
1459.18	133.009
1462.32	132.314
1465.45	130.785
1468.59	125.866
1471.72	122.654
1474.85	117.988
1477.98	112.748
1481.11	108.36
1484.23	101.93
1487.36	96.8933
1490.48	90.2517
1493.61	85.4744
1496.73	82.5026
1499.85	79.6278
1502.97	75.4327
1506.09	70.931
1509.2	66.0609
1512.32	61.5075
1515.44	55.658
1518.55	50.8661
1521.66	47.7893
1524.77	43.6214
1527.88	40.5587
1530.99	39.8003
1534.1	39.9111
1537.21	39.7427
1540.31	41.0988
1543.42	42.535
1546.52	44.5482
1549.62	48.1963
1552.72	49.9954
1555.82	53.1221
1558.92	53.9579
1562.02	53.9784
1565.11	55.3456
1568.21	57.4627
1571.3	61.3414
1574.39	64.9343
1577.49	68.1058
1580.58	69.2477
1583.67	72.4217
1586.75	75.6774
1589.84	77.9603
1592.93	80.2794
1596.01	82.9791
1599.09	82.998
1602.18	82.7612
1605.26	83.0467
1608.34	81.6064
1611.41	77.9247
1614.49	76.9005
1617.57	77.6792
1620.64	78.4643
1623.72	78.561
1626.79	80.207
1629.86	80.3081
1632.93	82.6089
1636	83.6619
1639.07	83.6361
1642.14	87.688
1645.2	91.4831
1648.27	94.1082
1651.33	96.6527
1654.39	98.4011
1657.45	99.5469
1660.51	99.6281
1663.57	99.7397
1666.63	96.2837
1669.69	92.7671
1672.74	88.7759
1675.79	84.1303
1678.85	77.4972
1681.9	71.883
1684.95	65.3459
1688	58.8351
1691.05	52.2813
1694.1	47.0145
1697.14	41.0073
1700.19	37.2222
1703.23	33.6058
1706.27	28.7445
1709.32	24.3807
1712.35	20.8637
1715.39	17.9234
1718.43	16.8264
1721.47	14.9922
1724.5	12.8257
1727.54	11.9244
1730.57	10.6251
1733.61	10.0825
1736.64	8.89895
1739.67	8.30225
1742.7	7.16176
1745.72	6.96323
1748.75	6.86121
1751.78	6.02757
1754.8	6.80246
1757.82	4.82608
1760.85	3.58665
1763.87	1.97804
1766.89	2.35158
1769.91	2.66155
1772.92	3.46545
1775.94	3.12435
1778.96	1.97099
1781.97	2.24688
1784.98	2.73379
1788	3.18004
1791.01	4.91183
1794.01	5.52255
1797.02	4.75767
1800.03	4.25267
1803.04	4.01993
1806.04	3.77076
1809.05	2.88652
1812.05	1.66491
1815.05	1.1641
1818.05	0.904923
1821.05	1.49547
1824.05	1.93501
1827.05	1.56073
1830.04	2.23482
1833.04	0.97438
1836.03	1.42585
1839.03	3.43193
1842.02	5.13023
1845.01	5.73837
1848	6.11564
1850.99	6.35272
1853.97	5.61212
1856.96	6.40984
1859.94	6.62116
1862.93	6.28889
1865.91	6.95654
1868.89	6.98023
1871.87	5.48065
1874.85	5.0232
1877.83	4.44338
1880.81	5.7228
1882.56	4.4506
1885.55	5.11091
1888.54	5.12039
1891.52	4.98592
1894.51	5.19614
1897.49	3.99034
1900.48	6.17204
1903.46	6.74174
1906.44	7.03701
1909.42	7.48814
1912.4	9.64046
1915.38	9.88156
1918.35	10.4798
1921.33	10.7371
1924.3	9.9139
1927.28	11.0928
1930.25	10.9247
1933.22	10.6193
1936.19	10.4201
1939.16	10.3603
1942.13	9.36701
1945.09	8.64616
1948.06	7.96124
1951.03	7.64918
1953.99	7.26095
1956.95	6.17882
1959.91	3.91758
1962.87	3.42575
1965.83	2.51398
1968.79	2.89457
1971.75	3.9369
1974.7	4.53536
1977.66	3.74982
1980.61	5.08714
1983.56	5.38886
1986.52	8.19189
1989.47	8.54616
1992.41	10.6497
1995.36	11.411
1998.31	11.295
2001.26	10.6114
2004.2	10.5985
2007.15	9.3984
2010.09	9.64136
2013.03	8.49377
2015.97	8.43059
2018.91	7.43942
2021.85	7.07018
2024.79	7.40909
2027.72	8.31209
2030.66	6.86511
2033.59	6.87143
2036.53	6.74549
2039.46	7.18531
2042.39	7.77423
2045.32	7.92897
2048.25	8.31724
2051.18	8.32056
2054.1	8.8776
2057.03	10.3437
2059.95	9.74254
2062.88	10.5944
2065.8	10.479
2068.72	9.23414
2071.64	7.81922
2074.56	6.7599
2077.48	7.19752
2080.39	6.74981
2083.31	7.2087
2086.22	7.70794
2089.14	8.54104
2092.05	9.60007
2094.96	9.50901
2097.87	10.1853
2100.78	8.59114
2103.69	9.61324
2106.6	10.3258
2109.51	11.5699
2112.41	13.2487
2115.32	13.6641
2118.22	13.9585
2121.12	14.9912
2124.02	16.4515
2126.92	18.9877
2129.82	19.7316
2132.72	20.0381
2135.62	21.1311
2138.51	21.7376
2141.41	22.7374
2144.3	25.3526
2147.19	28.5899
2150.09	30.807
2152.97	33.6497
2155.86	35.7273
2158.75	38.0079
2161.64	40.6135
2164.53	42.0059
2167.41	44.394
2170.3	46.5784
2173.18	48.4436
2176.06	49.47
2178.94	50.6566
2181.82	50.6771
2184.7	49.8927
2187.58	50.3221
2190.46	49.1282
2193.33	49.7853
2196.21	46.9362
2199.08	43.2422
2201.95	40.019
2204.83	35.7937
2207.7	34.0575
2210.57	30.7959
2213.43	28.1884
2216.3	26.0694
2219.17	25.4196
2222.03	23.1977
2224.9	21.9457
2227.76	19.881
2230.62	19.6647
2233.49	18.5231
2236.34	18.5973
2239.2	17.3731
2242.06	16.089
2244.92	15.0746
2247.78	14.5598
2250.63	15.1053
2253.48	14.5562
2256.34	14.2086
2259.19	14.4227
2262.04	12.4906
2264.89	10.2343
2267.74	8.04058
2270.59	7.63984
2273.43	6.82609
2276.28	5.9637
2279.12	5.4963
2281.97	5.04078
2284.81	4.87269
2287.65	5.8427
2290.49	5.4936
2293.33	3.01854
2296.17	2.92446
2299.01	4.90792
2301.84	6.06325
2304.68	6.69803
2307.51	8.72915
2310.35	11.1302
2313.18	11.7665
2316.01	12.5692
2318.84	14.031
2321.67	14.0402
2324.5	12.8071
2327.33	11.9948
2330.15	12.2422
2332.98	10.3719
2335.8	9.43956
2338.62	8.8084
2341.45	8.33931
2344.27	7.28033
2347.09	6.33353
2349.91	5.53271
2352.72	3.83712
2355.54	1.98409
2358.36	0.340229
2361.17	-1.33838
2363.98	-1.64102
2366.8	-0.0500072
2369.61	-0.0336906
2372.42	-0.0297132
2375.23	1.81091
2378.04	1.58823
2380.85	1.56514
2383.66	1.24401
2386.46	1.73527
2389.26	0.26754
2392.07	0.676084
2394.87	1.08894
2397.67	1.49059
2400.47	1.22194
2403.27	1.73284
2406.07	2.26915
2408.87	4.18684
2411.67	5.32342
2414.46	6.40762
2417.26	5.94771
2420.05	6.46366
2422.84	7.62016
2425.64	7.79281
2428.43	8.99365
2431.22	9.57585
2434.01	10.5845
2436.79	10.1975
2439.58	11.2299
2442.37	10.8389
2445.15	9.28393
2447.93	9.49605
2450.72	8.82801
2453.5	8.43389
2456.28	7.54193
2459.06	7.35478
2461.84	7.84589
2464.62	7.39063
2467.39	7.13678
2470.17	7.99227
2472.94	8.11793
2475.72	8.51058
2478.49	9.83672
2481.26	9.76095
2484.03	10.1796
2486.8	11.3274
2489.57	11.0088
2492.34	11.7145
2495.1	11.2861
2497.87	11.4432
2500.63	10.728
2503.4	10.9814
2506.16	11.1268
2508.92	11.0339
2511.68	7.92811
2514.44	6.18877
2517.2	6.22368
2519.96	4.36177
2522.72	3.45759
2525.47	3.10616
2528.23	4.20203
2530.98	4.16706
2533.74	4.16302
2536.49	4.33409
2539.24	4.45159
2541.99	4.55449
2544.74	6.16981
2547.49	6.49271
2550.23	7.37317
2552.98	7.81156
2555.72	7.31742
2558.47	6.89877
2561.21	6.74609
2563.95	7.65904
2566.69	9.28391
2569.43	10.7007
2572.17	11.2797
2574.91	12.0382
2577.65	11.216
2580.39	11.0169
2583.12	10.1264
2585.85	10.7222
2588.59	10.3558
2591.32	11.1949
2594.05	11.6453
2596.78	11.44
2599.51	10.2333
2602.24	8.87782
2604.97	9.47242
2607.69	7.87449
2610.42	8.03827
2613.14	7.15663
2615.87	5.56919
2618.59	4.33403
2621.31	3.68623
2624.03	2.46926
2626.75	2.54084
2629.47	2.76307
2632.19	3.14393
2634.91	3.546
2637.62	3.18575
2640.34	4.00966
2643.05	4.99146
2645.76	5.57852
2648.48	6.48004
2651.19	7.0621
2653.9	8.77695
2656.6	8.85625
2659.31	10.6824
2662.02	12.0289
2664.73	12.1088
2667.43	13.4328
2670.14	14.9888
2672.84	14.1554
2675.54	13.4243
2678.24	12.8699
2680.94	13.0318
2683.64	12.4489
2686.34	14.2162
2689.04	14.1217
2691.74	13.2601
2694.43	13.6209
2697.13	13.733
2699.82	13.6935
2702.51	14.5908
2705.21	14.8031
2707.9	15.617
2710.58	15.6551
2713.27	15.9479
2715.96	16.2201
2718.65	17.506
2721.33	19.0903
2724.02	19.7354
2726.71	20.1353
2729.39	19.4728
2732.07	18.8816
2734.75	17.4747
2737.43	17.275
2740.11	15.4257
2742.79	14.2055
2745.47	14.1511
2748.14	14.4982
2750.82	14.041
2753.49	12.861
2756.17	11.523
2758.84	10.9531
2761.51	10.4522
2764.18	9.10415
2766.85	7.84801
2769.52	8.0375
2772.19	8.14408
2774.86	6.97977
2777.52	6.17636
2780.19	6.41473
2782.85	5.85856
2785.52	5.83985
2788.18	4.90547
2790.84	3.08807
2793.5	2.66447
2796.16	1.86922
2798.82	0.93377
2801.48	0.791628
2804.13	-1.02306
2806.79	-1.74489
2809.45	-3.25393
2812.1	-3.51782
2814.75	-5.32596
2817.41	-4.48812
2820.06	-1.97322
2822.71	2.31889
2825.36	6.63006
2828	10.0302
2830.65	16.1342
2833.3	22.9745
2835.94	30.696
2838.59	38.4251
2841.23	49.1024
2843.87	61.6181
2846.52	74.1144
2849.16	87.981
2851.8	101.938
2854.44	116.731
2857.08	130.837
2859.71	144.714
2862.35	156.363
2864.98	168.301
2867.62	177.372
2870.25	185.287
2872.88	192.378
2875.52	198.64
2878.15	204.311
2880.78	209.796
2883.41	216.081
2886.03	221.429
2888.66	225.602
2891.29	229.688
2893.91	235.602
2896.54	243.141
2899.16	251.602
2901.78	261.651
2904.4	272.675
2907.02	287.312
2909.64	302.148
2912.26	318.806
2914.88	335.718
2917.5	351.333
2920.11	365.238
2922.73	375.83
2925.34	386.367
2927.96	391.237
2930.57	394.329
2933.18	394.498
2935.79	391.13
2938.4	386.919
2941.01	379.156
2943.62	368.596
2946.22	356.516
2948.83	344.063
2951.43	329.446
2954.04	315.984
2956.64	301.992
2959.24	287.888
2961.84	273.85
2964.45	259.373
2967.05	246.617
2969.64	234.608
2972.24	224.686
2974.84	214.2
2977.43	203.212
2980.03	190.093
2982.62	176.752
2985.22	164.019
2987.81	151.327
2990.4	136.686
2992.99	122.357
2995.58	108.972
2998.17	96.1799
3000.76	83.6567
3003.34	71.9679
3005.93	60.3889
3008.52	49.9553
3011.1	41.3647
3013.68	32.1209
3016.27	25.1453
3018.85	19.9725
3021.43	14.9745
3024.01	10.3885
3026.59	7.70454
3029.16	5.05098
3031.74	3.92681
3034.32	2.608
3036.89	2.36649
3039.47	2.01292
3042.04	4.17971
3044.61	4.40615
3047.18	7.37709
3049.75	9.38265
3052.32	10.4855
3054.89	11.2497
3057.46	12.9198
3060.03	14.6133
3062.59	16.586
3065.16	17.1903
3067.72	17.5351
3070.29	16.184
3072.85	14.7895
3075.41	13.4237
3077.97	12.9723
3080.53	11.8986
3083.09	10.7209
3085.65	8.69553
3088.21	7.60713
3090.76	6.75063
3093.32	6.56523
3095.87	7.06929
3098.43	6.51221
3100.98	8.72409
3103.53	11.5497
3106.08	13.4651
3108.63	14.9622
3111.18	17.0524
3113.73	19.7397
3116.28	22.1451
3118.83	24.4411
3121.37	27.3366
3123.92	30.4419
3126.46	33.416
3129	34.4804
3131.55	36.0337
3134.09	37.4667
3136.63	39.7893
3139.17	41.8546
3141.71	43.6646
3144.24	45.0914
3146.78	46.7586
3149.32	51.9292