File: data/Raman/poly_smoothed/Mb_10_14_16_1x_45s_532 nm_x100_100%_600 gr_mm_01.txt
#Acq. time (s)=	45
#Accumulations=	2
#Range (cm-¹)=	200...3150
#Windows=	2
#Auto scanning=	Off
#Autofocus=	Off
#Macrospot=	Off
#AutoExposure=	Off
#Spike filter=	Multiple accum.
#Delay time (s)=	0
#Binning=	1
#Readout mode=	Signal
#DeNoise=	Off
#ICS correction=	On
#Dark correction=	Off
#Inst. Process=	Off
#Detector Gain=	Best Dynamic Range
#Detector ADC=	20 kHz
#Detector temperature (°C)=	-69.85
#Instrument=	LabRAM HR Evol
#Detector=	Synapse
#Objective=	x100
#Grating=	600 gr/mm
#ND Filter=	100%
#Laser (nm)=	532
#Hole=	100.021
#Range=	Auto
#Laser Pol.=	No
#Raman. Pol.=	No
#Laser Pol. (°)=	-0.0007625
#Raman Pol. (°)=	89.9995
#Collection=	Microscope
#StageXY=	Marzhauser
#StageZ=	Marzhauser
#X (µm)=	-636.3
#Y (µm)=	-1595.4
#Z (µm)=	89.55
#Full time(mm:ss)=	3:18
#Project=
#Sample=
#Site=
#Title=	Mb_10_14_16_2x_45s_532 nm_x100_100%_600 gr_mm
#Remark=
#Date=	11.07.2022 09:41
#Acquired=	11.07.2022 09:41:37
#Base:Fit=	10.08.2022 10:21:11
#Base:Sub=	10.08.2022 10:21:41
#Filter:Polynom=	16.08.2022 10:17:53
#AxisType[0]=Intens
#AxisUnit[0]=Cnt
#AxisType[1]=Spectr
#AxisUnit[1]=1/cm
200.388	16.0776
204.019	12.3595
207.646	11.4207
211.274	10.6464
214.899	10.4632
218.524	10.8873
222.146	11.2222
225.766	12.8885
229.388	14.2676
233.005	15.6957
236.621	16.7691
240.236	19.0419
243.852	20.6261
247.464	23.774
251.074	24.6545
254.683	25.4742
258.291	27.3605
261.897	27.6038
265.504	29.5599
269.108	28.6904
272.71	28.4073
276.311	25.2808
279.91	23.676
283.508	23.3895
287.105	22.2133
290.698	19.9631
294.291	17.9544
297.884	13.8582
301.475	12.3488
305.064	10.9246
308.652	10.0607
312.237	8.39796
315.822	7.78143
319.406	6.47718
322.987	5.96108
326.568	5.88312
330.148	4.47156
333.724	5.39082
337.301	4.43602
340.875	3.58912
344.449	4.86113
348.02	4.7623
351.592	6.77063
355.16	7.05993
358.728	6.54992
362.294	7.88602
365.858	9.20563
369.422	11.1923
372.983	12.2269
376.543	12.5206
380.102	11.7175
383.661	13.621
387.216	15.3216
390.771	16.5976
394.324	16.6937
397.875	17.6639
401.425	16.8287
404.974	15.7322
408.524	15.0629
412.07	14.2783
415.614	11.9419
419.156	10.5821
422.698	9.80156
426.238	8.69583
429.777	6.20809
433.315	5.33068
436.852	3.1886
440.387	2.46222
443.919	2.61424
447.451	4.3394
450.982	4.52841
454.512	6.03487
458.038	7.57579
461.565	8.68411
465.091	10.0079
468.613	12.4247
472.136	13.3525
475.655	13.7981
479.176	14.6245
482.692	15.4552
486.21	15.4844
489.724	17.1492
493.237	16.7356
496.75	16.953
500.26	16.4909
503.769	14.7203
507.279	14.1211
510.785	14.7429
514.289	14.51
517.793	14.2049
521.297	13.4993
524.797	12.952
528.297	13.2211
531.795	12.9268
535.291	12.1551
538.787	12.0629
542.281	11.9138
545.773	11.8776
549.264	10.5697
552.754	9.64619
556.243	8.48069
559.73	7.87657
563.216	7.24439
566.701	6.37342
570.182	5.83675
573.664	5.66386
577.145	3.80221
580.624	4.51531
584.1	4.61648
587.577	4.80252
591.052	5.29473
594.524	5.93951
597.997	5.22282
601.466	4.82168
604.936	4.33772
608.403	4.68624
611.87	5.94756
615.334	5.73019
618.799	6.08656
622.26	6.49926
625.72	8.2167
629.181	10.0321
632.638	10.9829
636.095	11.5491
639.551	12.0779
643.005	12.9917
646.457	13.9734
649.908	14.4086
653.357	15.3856
656.806	15.4526
660.253	15.5834
663.7	16.9741
667.145	18.6552
670.588	18.9174
674.027	19.2431
677.468	19.9186
680.907	19.6374
684.345	19.5587
687.781	20.3469
691.216	21.4259
694.65	22.23
698.081	22.111
701.512	22.6032
704.942	23.5277
708.371	25.6771
711.796	27.8092
715.222	27.8717
718.645	28.94
722.068	28.7677
725.49	30.8336
728.909	31.4067
732.329	33.5475
735.745	35.6068
739.16	37.2683
742.576	38.8634
745.988	42.6698
749.401	46.4495
752.811	49.4397
756.22	52.7382
759.627	55.1443
763.035	58.15
766.44	60.0322
769.843	62.8505
773.245	64.8505
776.646	66.9169
780.046	68.3808
783.444	69.3266
786.841	71.7024
790.237	75.6744
793.631	77.43
797.024	78.2357
800.416	77.3941
803.807	77.8337
807.196	78.5826
810.584	78.441
813.971	78.3426
817.354	77.8614
820.739	77.7579
824.122	76.2536
827.503	75.0785
830.882	75.8792
834.261	74.0528
837.637	72.4487
841.013	70.4098
844.389	68.1326
847.761	66.2349
851.131	63.3817
854.503	61.3114
857.871	58.5844
861.24	56.3975
864.606	54.8001
867.97	53.891
871.336	52.5398
874.698	51.452
878.058	49.2119
881.418	48.0686
884.778	48.2923
888.135	47.1449
891.49	44.9789
894.845	44.3909
898.198	44.3023
901.55	43.7915
904.901	45.5321
908.25	46.2132
911.598	47.2521
914.945	48.0011
918.291	47.8393
921.635	47.4741
924.978	47.8683
928.318	48.2658
931.659	47.2847
934.998	48.1855
938.336	48.4422
941.671	48.3994
945.007	47.5791
948.339	46.7129
951.672	43.9873
955.004	42.7771
958.333	41.133
961.662	40.0862
964.989	39.1102
968.315	38.5682
971.639	37.1896
974.962	36.8633
978.285	36.9988
981.605	36.6955
984.924	36.4254
988.243	35.7343
991.56	34.0779
994.875	33.0677
998.188	32.4699
1001.5	32.9474
1004.81	32.7423
1008.12	32.3554
1011.43	32.9664
1014.74	34.439
1018.05	36.7068
1021.35	38.8846
1024.65	39.497
1027.96	40.4046
1031.26	40.0294
1034.56	41.9173
1037.86	41.7683
1041.16	42.3136
1044.45	42.4759
1047.75	42.3312
1051.04	40.0509
1054.33	37.0877
1057.62	33.7236
1060.91	30.8472
1064.2	27.3461
1067.49	23.2892
1070.77	19.6605
1074.06	16.2201
1077.34	13.6901
1080.62	11.7104
1083.91	10.132
1087.18	8.42246
1090.46	8.17869
1093.74	10.1142
1097.02	10.4958
1100.29	12.1069
1103.56	11.8894
1106.84	10.7503
1110.11	11.1284
1113.38	11.4525
1116.64	11.7858
1119.91	10.7666
1123.18	9.7397
1126.44	9.61243
1129.7	8.4982
1132.97	7.20914
1136.23	7.28477
1139.49	7.553
1142.74	6.47394
1146	4.80062
1149.26	3.96636
1152.51	4.17192
1155.76	2.95898
1159.01	3.07062
1162.27	2.70624
1165.51	3.16599
1168.76	4.22785
1172.01	5.24149
1175.25	5.14037
1178.5	5.65457
1181.74	4.8558
1184.98	4.91421
1188.22	5.78375
1191.46	5.18073
1194.7	5.47517
1197.94	6.57314
1201.17	7.28171
1204.41	9.06259
1207.64	10.8325
1210.87	12.792
1214.1	13.9863
1217.33	16.0102
1220.56	17.2606
1223.79	19.6911
1227.01	22.0864
1230.23	25.1851
1233.46	26.7185
1236.68	27.2543
1239.9	28.5189
1243.12	30.1222
1246.34	32.104
1249.55	32.842
1252.77	32.5762
1255.98	32.5545
1259.2	31.0239
1262.41	29.9612
1265.62	29.5051
1268.83	29.494
1272.03	28.5325
1275.24	29.1234
1278.45	29.7338
1281.65	30.591
1284.85	31.7096
1288.06	32.5833
1291.26	33.1573
1294.46	34.7726
1297.66	36.4688
1300.85	37.7284
1304.05	39.8612
1307.24	41.3902
1310.43	42.5915
1313.63	41.8147
1316.82	42.5306
1320.01	44.2236
1323.2	44.1299
1326.38	43.0636
1329.57	43.1958
1332.76	40.4279
1335.94	38.5883
1339.12	36.9776
1342.3	36.4623
1345.48	35.4724
1348.66	34.4103
1351.84	32.2953
1355.01	30.4558
1358.19	29.3463
1361.36	28.1133
1364.53	26.5751
1367.71	25.4962
1370.88	24.4401
1374.04	23.3712
1377.21	22.6061
1380.38	21.3309
1383.54	20.4236
1386.71	19.4414
1389.87	19.1013
1393.03	20.1454
1396.19	20.4581
1399.35	22.0744
1402.51	20.7
1405.67	19.8531
1408.82	20.202
1411.98	20.9195
1415.13	23.0717
1418.28	25.7547
1421.43	28.6459
1424.58	31.9537
1427.73	35.5742
1430.88	39.262
1434.02	42.7186
1437.17	45.3843
1440.31	48.635
1443.45	50.9017
1446.6	51.6912
1449.74	52.7724
1452.87	53.3302
1456.01	52.0729
1459.15	50.06
1462.28	47.6828
1465.42	45.3301
1468.55	43.2807
1471.68	41.0067
1474.81	36.8636
1477.94	33.3043
1481.07	28.1739
1484.2	24.3035
1487.32	21.9152
1490.45	19.6838
1493.57	17.4508
1496.69	15.5953
1499.81	15.2822
1502.93	15.3748
1506.05	14.8442
1509.17	13.8906
1512.28	14.1151
1515.4	14.7835
1518.51	14.0816
1521.63	14.8981
1524.74	14.8292
1527.85	14.9777
1530.96	13.9697
1534.06	13.1529
1537.17	12.4613
1540.28	12.5457
1543.38	14.1581
1546.48	14.6271
1549.59	15.1997
1552.69	15.1777
1555.79	15.2666
1558.88	14.2879
1561.98	15.2121
1565.08	17.2371
1568.17	17.2467
1571.27	18.4681
1574.36	19.7649
1577.45	21.6132
1580.54	23.5663
1583.63	25.6339
1586.72	27.2554
1589.8	28.9324
1592.89	30.0298
1595.97	29.4043
1599.06	29.8793
1602.14	29.651
1605.22	28.7576
1608.3	28.0822
1611.38	27.989
1614.46	28.8718
1617.53	29.9853
1620.61	30.5488
1623.68	29.6467
1626.75	29.8151
1629.82	29.9167
1632.9	29.5358
1635.96	30.8947
1639.03	32.759
1642.1	33.199
1645.16	33.638
1648.23	35.5353
1651.29	36.2064
1654.36	37.7335
1657.42	39.246
1660.48	39.3228
1663.53	39.3365
1666.59	37.6584
1669.65	35.6378
1672.7	32.6173
1675.76	30.2522
1678.81	28.6593
1681.86	25.8508
1684.91	23.8894
1687.96	23.214
1691.01	19.9827
1694.06	17.1698
1697.11	14.2021
1700.15	10.8521
1703.2	9.18048
1706.24	7.19785
1709.28	6.33994
1712.32	6.64288
1715.36	5.72778
1718.4	4.88048
1721.43	4.92977
1724.47	5.29016
1727.5	4.51488
1730.54	5.27981
1733.57	5.3194
1736.6	5.17475
1739.63	4.76909
1742.66	3.76906
1745.69	3.66831
1748.72	3.29834
1751.74	3.63609
1754.77	3.57727
1757.79	3.25915
1760.81	3.40634
1763.83	2.98866
1766.85	2.258
1769.87	1.5029
1772.89	1.33218
1775.91	1.80911
1778.92	2.10733
1781.94	2.5831
1784.95	3.23685
1787.96	3.01968
1790.97	2.57512
1793.98	3.50095
1796.99	4.24651
1800	4.24162
1803	4.10126
1806.01	4.39403
1809.01	4.33167
1812.02	4.49943
1815.02	3.35788
1818.02	3.06581
1821.02	3.07308
1824.02	2.71194
1827.01	2.90231
1830.01	2.91598
1833	3.72346
1836	3.70856
1838.99	3.94504
1841.98	4.33311
1844.97	4.49178
1847.96	5.65718
1850.95	5.49214
1853.94	5.27202
1856.92	4.70872
1859.91	4.85514
1862.89	4.97333
1865.88	4.99238
1868.86	4.82662
1871.84	4.26646
1874.82	4.45109
1877.8	3.55633
1880.77	2.90855
1882.52	2.61366
1885.51	2.31438
1888.5	2.82103
1891.49	3.52531
1894.47	3.82337
1897.46	5.3358
1900.44	6.19386
1903.42	6.82924
1906.4	6.58345
1909.38	6.10158
1912.36	7.03095
1915.34	6.95929
1918.32	7.06868
1921.29	7.79508
1924.27	7.9594
1927.24	8.05597
1930.21	7.43015
1933.18	6.78805
1936.15	6.27302
1939.12	5.0588
1942.09	4.29072
1945.06	3.84016
1948.02	3.49294
1950.99	1.79716
1953.95	1.56942
1956.91	1.95392
1959.87	1.85262
1962.84	2.32932
1965.79	2.92975
1968.75	3.47348
1971.71	2.85559
1974.66	2.28457
1977.62	2.21776
1980.57	2.42762
1983.53	2.42428
1986.48	3.63797
1989.43	4.12565
1992.38	4.21861
1995.33	4.22412
1998.27	3.67467
2001.22	3.55976
2004.16	3.48086
2007.11	3.56414
2010.05	2.78388
2012.99	2.84865
2015.93	3.11305
2018.87	3.03515
2021.81	2.16845
2024.75	1.91193
2027.69	2.31928
2030.62	2.0137
2033.56	2.12313
2036.49	3.25002
2039.42	3.75423
2042.35	3.51304
2045.28	3.4063
2048.21	3.69079
2051.14	4.76924
2054.06	5.03599
2056.99	5.38842
2059.92	5.90648
2062.84	4.39074
2065.76	4.76064
2068.68	4.92694
2071.6	6.05191
2074.52	6.08259
2077.44	5.9863
2080.36	5.88043
2083.27	6.34131
2086.19	6.38494
2089.1	6.17103
2092.01	5.56975
2094.93	5.9777
2097.84	5.60567
2100.75	6.06281
2103.66	5.79406
2106.56	6.12776
2109.47	6.27552
2112.37	6.12324
2115.28	5.99553
2118.18	6.36464
2121.09	6.7151
2123.99	8.1414
2126.89	8.43253
2129.79	8.41322
2132.68	9.13225
2135.58	9.98735
2138.48	10.4525
2141.37	11.4022
2144.26	11.3713
2147.16	11.5711
2150.05	12.005
2152.94	12.9313
2155.83	13.6379
2158.72	14.1412
2161.6	15.5163
2164.49	16.753
2167.38	17.899
2170.26	18.7764
2173.14	19.918
2176.03	20.4037
2178.91	20.9857
2181.79	20.9289
2184.67	21.5042
2187.54	20.9094
2190.42	20.5962
2193.3	20.0777
2196.17	20.2261
2199.05	19.1425
2201.92	17.9908
2204.79	16.8774
2207.66	15.6872
2210.53	14.6066
2213.4	12.7452
2216.27	11.3301
2219.13	9.83292
2222	8.45492
2224.86	7.43423
2227.72	7.29504
2230.59	7.07294
2233.45	7.76391
2236.31	7.15003
2239.17	7.47076
2242.03	7.41126
2244.88	7.91752
2247.74	7.22023
2250.59	6.51137
2253.45	6.495
2256.3	6.38652
2259.15	5.3153
2262	5.11199
2264.85	4.94419
2267.7	4.78422
2270.55	4.80321
2273.4	4.19424
2276.24	5.11447
2279.09	4.7219
2281.93	4.50612
2284.77	4.14251
2287.61	4.89993
2290.46	3.90583
2293.29	3.83638
2296.13	5.56195
2298.97	6.47207
2301.81	7.89092
2304.64	9.61576
2307.48	10.1316
2310.31	10.8485
2313.14	10.767
2315.97	10.9868
2318.8	10.7084
2321.63	10.9282
2324.46	10.4513
2327.29	9.76987
2330.12	8.31411
2332.94	8.09326
2335.76	8.42299
2338.59	8.06277
2341.41	6.44572
2344.23	6.45646
2347.05	4.96609
2349.87	3.27494
2352.69	2.98334
2355.5	2.45779
2358.32	1.55379
2361.14	0.55536
2363.95	1.63393
2366.76	2.33353
2369.58	2.65626
2372.39	3.61465
2375.2	3.9449
2378	3.15415
2380.81	4.25043
2383.62	4.05796
2386.42	4.12912
2389.23	3.66344
2392.03	4.00699
2394.84	3.49789
2397.64	2.53788
2400.44	2.01234
2403.24	2.17491
2406.04	2.91961
2408.83	2.29272
2411.63	2.10575
2414.43	2.3471
2417.22	1.90651
2420.02	1.79162
2422.81	2.19166
2425.6	2.04247
2428.39	2.09314
2431.18	2.06743
2433.97	2.85536
2436.76	2.75355
2439.54	3.39398
2442.33	3.49944
2445.11	3.76297
2447.9	4.66985
2450.68	4.37408
2453.46	4.3528
2456.24	3.9885
2459.02	4.55992
2461.8	4.16032
2464.58	3.40534
2467.36	2.49378
2470.13	2.20693
2472.91	2.60344
2475.68	2.90195
2478.45	2.67153
2481.22	2.05708
2484	2.05641
2486.77	2.12339
2489.54	2.27622
2492.3	2.4491
2495.07	2.4998
2497.84	3.04071
2500.6	2.92858
2503.36	2.76621
2506.13	2.77992
2508.89	2.6249
2511.65	2.31976
2514.41	3.84555
2517.17	4.57278
2519.93	4.04538
2522.68	4.66981
2525.44	4.38669
2528.19	4.29235
2530.95	4.46309
2533.7	3.41468
2536.45	3.64365
2539.2	3.05756
2541.95	3.43713
2544.7	3.40912
2547.45	2.98495
2550.2	2.7367
2552.94	3.87275
2555.69	4.48687
2558.43	4.84134
2561.17	4.8803
2563.92	4.68851
2566.66	4.47308
2569.4	3.66917
2572.14	3.08289
2574.88	2.82919
2577.61	3.13497
2580.35	3.38722
2583.09	3.78959
2585.82	3.04218
2588.55	2.43632
2591.28	2.80004
2594.02	2.84614
2596.75	3.07334
2599.48	2.09321
2602.2	1.82383
2604.93	2.36724
2607.66	1.78875
2610.38	2.56358
2613.11	3.11423
2615.83	3.75906
2618.56	4.14218
2621.28	4.13009
2624	5.24153
2626.72	4.59558
2629.44	5.14467
2632.15	5.29404
2634.87	5.59766
2637.59	5.64042
2640.3	6.06923
2643.02	5.51623
2645.73	5.40431
2648.44	5.70237
2651.15	6.00502
2653.86	5.64838
2656.57	6.23888
2659.28	5.87961
2661.99	5.35515
2664.69	4.84816
2667.4	4.81877
2670.1	5.7899
2672.81	6.03862
2675.51	5.1145
2678.21	4.51183
2680.91	4.16246
2683.61	4.65698
2686.31	4.61354
2689	4.79518
2691.7	4.86966
2694.4	5.15393
2697.09	5.4759
2699.79	4.48177
2702.48	3.77705
2705.17	4.17995
2707.86	4.77999
2710.55	5.44702
2713.24	6.1825
2715.93	6.23221
2718.61	6.9325
2721.3	6.7482
2723.99	7.10543
2726.67	6.83813
2729.35	7.3665
2732.04	7.06037
2734.72	6.08527
2737.4	5.13536
2740.08	3.26104
2742.76	2.61302
2745.43	2.79965
2748.11	3.52876
2750.79	3.59851
2753.46	1.65167
2756.13	1.34702
2758.81	0.8575
2761.48	1.0357
2764.15	0.592328
2766.82	1.0763
2769.49	2.23269
2772.16	2.34484
2774.82	3.33642
2777.49	3.25626
2780.16	3.49164
2782.82	3.87497
2785.48	3.89642
2788.15	4.14259
2790.81	4.23115
2793.47	3.91598
2796.13	3.29484
2798.79	1.83722
2801.44	1.76022
2804.1	1.22116
2806.76	0.234018
2809.41	0.865048
2812.07	0.989131
2814.72	1.66625
2817.37	1.9672
2820.02	2.43955
2822.67	4.25224
2825.32	6.28311
2827.97	7.26394
2830.62	10.0489
2833.26	13.0303
2835.91	15.1406
2838.55	17.4565
2841.2	22.0259
2843.84	26.4044
2846.48	31.2743
2849.12	37.3961
2851.76	42.565
2854.4	47.9362
2857.04	52.2681
2859.68	56.6376
2862.32	60.9351
2864.95	65.7355
2867.58	70.0187
2870.22	73.5769
2872.85	76.4139
2875.48	80.1785
2878.11	82.9173
2880.74	85.7287
2883.37	88.375
2886	90.3131
2888.63	92.2724
2891.25	94.2098
2893.88	95.6101
2896.5	97.9579
2899.13	100.715
2901.75	104.8
2904.37	110.515
2906.99	116.532
2909.61	122.301
2912.23	128.86
2914.85	134.529
2917.46	140.106
2920.08	144.678
2922.7	148.705
2925.31	151.373
2927.92	153.119
2930.53	153.698
2933.15	152.377
2935.76	151.047
2938.37	148.755
2940.98	145.623
2943.58	141.227
2946.19	136.689
2948.8	131.035
2951.4	124.751
2954.01	118.256
2956.61	111.877
2959.21	106.164
2961.81	101.425
2964.41	96.3418
2967.01	92.198
2969.61	88.1392
2972.21	83.2283
2974.81	78.6163
2977.4	74.4006
2980	69.9633
2982.59	65.1133
2985.18	59.7063
2987.78	54.0028
2990.37	47.9482
2992.96	41.9798
2995.55	36.5307
2998.14	31.8195
3000.72	27.3865
3003.31	22.8462
3005.9	19.1557
3008.48	15.4042
3011.07	11.643
3013.65	8.58238
3016.23	6.65742
3018.81	4.43985
3021.39	3.35198
3023.97	2.5584
3026.55	2.09205
3029.13	1.64722
3031.71	1.64262
3034.28	2.28349
3036.86	2.68328
3039.43	2.80521
3042.01	3.01454
3044.58	3.64085
3047.15	4.41048
3049.72	4.96269
3052.29	5.67018
3054.86	6.80186
3057.43	5.97621
3060	6.38529
3062.56	6.55074
3065.13	6.17256
3067.69	5.56983
3070.25	5.29466
3072.82	4.20358
3075.38	2.96956
3077.94	2.81082
3080.5	2.21336
3083.06	2.55674
3085.62	2.37645
3088.17	1.59508
3090.73	0.961254
3093.29	0.502267
3095.84	0.530917
3098.4	-0.415866
3100.95	-0.516281
3103.5	0.222773
3106.05	0.326476
3108.6	2.38171
3111.15	2.45152
3113.7	3.28508
3116.25	3.82852
3118.79	3.61921
3121.34	4.38555
3123.88	5.22684
3126.43	6.02751
3128.97	6.45657
3131.51	7.9197
3134.05	8.98248
3136.59	10.0767
3139.14	11.2751
3141.67	12.1547
3144.21	13.2484
3146.75	14.2147
3149.28	16.8638