File: data/Raman/poly_smoothed/Mb_10_14_23_1x_45s_532 nm_x100_100%_600 gr_mm_01.txt
#Acq. time (s)=	45
#Accumulations=	2
#Range (cm-¹)=	200...3150
#Windows=	2
#Auto scanning=	Off
#Autofocus=	Off
#Macrospot=	Off
#AutoExposure=	Off
#Spike filter=	Multiple accum.
#Delay time (s)=	0
#Binning=	1
#Readout mode=	Signal
#DeNoise=	Off
#ICS correction=	On
#Dark correction=	Off
#Inst. Process=	Off
#Detector Gain=	Best Dynamic Range
#Detector ADC=	20 kHz
#Detector temperature (°C)=	-69.85
#Instrument=	LabRAM HR Evol
#Detector=	Synapse
#Objective=	x100
#Grating=	600 gr/mm
#ND Filter=	100%
#Laser (nm)=	532
#Hole=	100.021
#Range=	Auto
#Laser Pol.=	No
#Raman. Pol.=	No
#Laser Pol. (°)=	-0.0007625
#Raman Pol. (°)=	89.9995
#Collection=	Microscope
#StageXY=	Marzhauser
#StageZ=	Marzhauser
#X (µm)=	-620.1
#Y (µm)=	-1588.4
#Z (µm)=	89.85
#Full time(mm:ss)=	3:19
#Project=
#Sample=
#Site=
#Title=	Mb_10_14_23_2x_45s_532 nm_x100_100%_600 gr_mm
#Remark=
#Date=	11.07.2022 10:16
#Acquired=	11.07.2022 10:16:39
#Base:Fit=	10.08.2022 10:21:11
#Base:Sub=	10.08.2022 10:21:41
#Filter:Polynom=	16.08.2022 10:17:53
#AxisType[0]=Intens
#AxisUnit[0]=Cnt
#AxisType[1]=Spectr
#AxisUnit[1]=1/cm
200.388	4.15749
204.019	6.97345
207.646	8.61867
211.274	9.3881
214.899	10.8128
218.524	13.8114
222.146	15.6152
225.766	16.6197
229.388	18.5372
233.005	20.9636
236.621	22.9842
240.236	24.2711
243.852	24.7854
247.464	25.36
251.074	24.5978
254.683	24.0934
258.291	26.0621
261.897	26.3533
265.504	26.6574
269.108	27.0874
272.71	26.8692
276.311	27.6597
279.91	25.1935
283.508	23.7833
287.105	21.8607
290.698	20.2506
294.291	18.8862
297.884	16.0573
301.475	15.1039
305.064	15.8657
308.652	14.5276
312.237	11.7967
315.822	11.5555
319.406	11.2881
322.987	9.60773
326.568	7.79904
330.148	6.39083
333.724	4.63512
337.301	3.49807
340.875	3.80359
344.449	5.37176
348.02	7.5943
351.592	8.20414
355.16	10.6685
358.728	12.8717
362.294	13.6173
365.858	15.1705
369.422	18.0897
372.983	19.3182
376.543	20.5227
380.102	20.8243
383.661	21.1994
387.216	22.1027
390.771	23.8371
394.324	21.8346
397.875	20.2413
401.425	19.2747
404.974	17.8089
408.524	14.5193
412.07	11.7568
415.614	9.25176
419.156	8.77419
422.698	5.23694
426.238	3.55933
429.777	2.46562
433.315	1.69377
436.852	1.38952
440.387	1.5443
443.919	2.06367
447.451	2.49946
450.982	2.65961
454.512	4.18232
458.038	4.66783
461.565	6.05383
465.091	7.21363
468.613	9.41791
472.136	9.76082
475.655	10.904
479.176	12.0167
482.692	11.784
486.21	13.768
489.724	14.2872
493.237	16.0517
496.75	18.2917
500.26	18.2314
503.769	19.5016
507.279	19.6045
510.785	19.2675
514.289	19.3422
517.793	19.8163
521.297	19.2139
524.797	21.1799
528.297	21.2646
531.795	20.9658
535.291	21.2131
538.787	20.1307
542.281	19.4121
545.773	18.5132
549.264	18.1276
552.754	16.6614
556.243	15.5868
559.73	14.3459
563.216	12.997
566.701	11.6865
570.182	11.0225
573.664	11.6358
577.145	11.2926
580.624	10.9347
584.1	8.7783
587.577	7.19776
591.052	6.23376
594.524	5.5422
597.997	4.949
601.466	5.03507
604.936	5.6973
608.403	6.35688
611.87	6.94458
615.334	6.09792
618.799	7.08577
622.26	7.31096
625.72	8.29854
629.181	8.46313
632.638	10.9969
636.095	12.0545
639.551	13.4537
643.005	12.6889
646.457	13.8742
649.908	13.8158
653.357	16.165
656.806	16.9505
660.253	17.0613
663.7	16.6249
667.145	16.5872
670.588	17.6308
674.027	17.8926
677.468	20.0993
680.907	21.2964
684.345	22.3697
687.781	24.623
691.216	24.9381
694.65	26.0024
698.081	27.8618
701.512	30.1965
704.942	32.4649
708.371	34.9975
711.796	36.4354
715.222	39.5367
718.645	40.8814
722.068	40.7522
725.49	41.9563
728.909	43.1931
732.329	44.8177
735.745	47.0104
739.16	47.3459
742.576	48.9441
745.988	49.716
749.401	50.4568
752.811	51.889
756.22	53.1155
759.627	56.542
763.035	58.6582
766.44	59.2148
769.843	60.8409
773.245	63.4447
776.646	66.0806
780.046	68.5669
783.444	70.1857
786.841	72.4647
790.237	74.6591
793.631	76.2173
797.024	77.9473
800.416	80.1692
803.807	80.5263
807.196	81.4496
810.584	81.9108
813.971	80.7276
817.354	80.7542
820.739	81.5242
824.122	80.8645
827.503	80.4232
830.882	78.8502
834.261	77.6027
837.637	75.6566
841.013	74.5352
844.389	73.0372
847.761	69.6541
851.131	67.8241
854.503	66.5515
857.871	65.4302
861.24	62.8142
864.606	60.9698
867.97	59.4982
871.336	58.3666
874.698	57.0364
878.058	56.7475
881.418	55.5274
884.778	54.6569
888.135	52.2677
891.49	51.4334
894.845	51.3392
898.198	51.7217
901.55	54.0132
904.901	54.5489
908.25	56.5794
911.598	55.8505
914.945	55.1922
918.291	55.0629
921.635	53.5784
924.978	52.9522
928.318	52.4011
931.659	51.4837
934.998	51.559
938.336	50.5658
941.671	47.1831
945.007	43.3781
948.339	42.343
951.672	40.0697
955.004	38.3195
958.333	35.4842
961.662	33.8051
964.989	31.1896
968.315	30.4436
971.639	30.4632
974.962	31.0735
978.285	31.424
981.605	33.8959
984.924	33.8892
988.243	33.0629
991.56	32.8087
994.875	31.9903
998.188	30.9266
1001.5	30.7558
1004.81	29.0432
1008.12	29.2904
1011.43	28.8388
1014.74	30.036
1018.05	30.6358
1021.35	30.024
1024.65	30.2054
1027.96	30.346
1031.26	31.0011
1034.56	30.3428
1037.86	30.0369
1041.16	29.4178
1044.45	30.1561
1047.75	28.4739
1051.04	27.1547
1054.33	25.587
1057.62	24.2175
1060.91	21.9017
1064.2	19.6454
1067.49	15.5081
1070.77	12.9931
1074.06	10.8299
1077.34	9.47119
1080.62	6.59154
1083.91	5.33172
1087.18	3.30219
1090.46	4.77088
1093.74	5.781
1097.02	7.41965
1100.29	8.89997
1103.56	9.11565
1106.84	8.86372
1110.11	10.6257
1113.38	11.5938
1116.64	11.9033
1119.91	10.6143
1123.18	9.20722
1126.44	9.41081
1129.7	9.43501
1132.97	8.6939
1136.23	8.47653
1139.49	7.56846
1142.74	6.18866
1146	4.50677
1149.26	3.88343
1152.51	3.97076
1155.76	4.23839
1159.01	3.11892
1162.27	2.595
1165.51	2.27477
1168.76	2.59837
1172.01	4.22399
1175.25	5.11229
1178.5	5.3104
1181.74	5.97706
1184.98	5.78276
1188.22	6.29916
1191.46	7.1071
1194.7	7.53705
1197.94	7.75837
1201.17	8.96258
1204.41	10.8558
1207.64	12.1998
1210.87	14.4466
1214.1	15.7343
1217.33	16.7346
1220.56	18.5377
1223.79	18.426
1227.01	19.9622
1230.23	21.7343
1233.46	22.6149
1236.68	24.0292
1239.9	23.9282
1243.12	25.8642
1246.34	26.2835
1249.55	27.648
1252.77	28.0815
1255.98	28.7255
1259.2	27.3166
1262.41	27.6283
1265.62	27.3608
1268.83	27.5313
1272.03	28.2544
1275.24	28.5461
1278.45	27.3447
1281.65	26.2232
1284.85	26.3677
1288.06	28.148
1291.26	28.3721
1294.46	29.5779
1297.66	28.06
1300.85	28.9131
1304.05	29.1821
1307.24	30.8566
1310.43	31.0869
1313.63	32.5557
1316.82	34.3526
1320.01	35.2129
1323.2	36.5221
1326.38	36.2186
1329.57	36.0759
1332.76	35.8435
1335.94	35.2235
1339.12	35.5535
1342.3	35.0584
1345.48	34.4603
1348.66	34.1337
1351.84	32.5726
1355.01	30.8444
1358.19	28.6589
1361.36	27.3976
1364.53	27.4977
1367.71	26.158
1370.88	25.3752
1374.04	22.822
1377.21	23.0805
1380.38	23.0085
1383.54	20.9418
1386.71	20.4195
1389.87	19.9715
1393.03	20.6917
1396.19	19.8677
1399.35	18.3535
1402.51	18.0864
1405.67	18.8039
1408.82	20.4658
1411.98	21.1973
1415.13	22.9952
1418.28	25.5981
1421.43	27.709
1424.58	30.6575
1427.73	33.1982
1430.88	35.7152
1434.02	38.5551
1437.17	40.8977
1440.31	44.9494
1443.45	46.8332
1446.6	48.9979
1449.74	49.6044
1452.87	50.6252
1456.01	50.6112
1459.15	49.2196
1462.28	47.9771
1465.42	47.2514
1468.55	46.1419
1471.68	43.7721
1474.81	42.3856
1477.94	40.6079
1481.07	39.304
1484.2	38.1242
1487.32	34.6285
1490.45	32.0247
1493.57	30.7764
1496.69	28.8947
1499.81	27.9379
1502.93	25.1147
1506.05	21.7618
1509.17	18.8078
1512.28	16.6855
1515.4	15.1134
1518.51	13.3171
1521.63	12.2671
1524.74	10.2754
1527.85	10.4883
1530.96	10.2522
1534.06	10.3503
1537.17	10.2044
1540.28	11.4122
1543.38	12.4165
1546.48	11.932
1549.59	13.0316
1552.69	14.85
1555.79	15.7882
1558.88	17.7941
1561.98	18.6639
1565.08	21.0878
1568.17	22.3941
1571.27	23.9614
1574.36	25.1983
1577.45	26.4314
1580.54	26.2316
1583.63	26.053
1586.72	27.0094
1589.8	28.9527
1592.89	30.7518
1595.97	30.7286
1599.06	31.7776
1602.14	32.4595
1605.22	30.917
1608.3	30.4972
1611.38	29.1758
1614.46	28.0603
1617.53	26.6634
1620.61	25.0283
1623.68	24.5666
1626.75	22.7633
1629.82	21.7218
1632.9	21.7669
1635.96	22.6802
1639.03	23.3044
1642.1	25.4493
1645.16	27.2805
1648.23	30.336
1651.29	31.8332
1654.36	33.1407
1657.42	32.907
1660.48	32.3089
1663.53	34.2383
1666.59	34.2382
1669.65	33.9493
1672.7	33.4533
1675.76	31.0156
1678.81	29.0308
1681.86	25.9766
1684.91	24.3
1687.96	20.6731
1691.01	18.3364
1694.06	14.7101
1697.11	11.4988
1700.15	8.34564
1703.2	5.84642
1706.24	4.56803
1709.28	4.82285
1712.32	4.16482
1715.36	3.8779
1718.4	3.60339
1721.43	4.05261
1724.47	3.41217
1727.5	2.51466
1730.54	1.14727
1733.57	0.734538
1736.6	1.76718
1739.63	2.62815
1742.66	2.99035
1745.69	3.37501
1748.72	2.66334
1751.74	2.30755
1754.77	1.60409
1757.79	1.78696
1760.81	1.85798
1763.83	1.12189
1766.85	0.731122
1769.87	-0.0956523
1772.89	0.696932
1775.91	0.203903
1778.92	0.276946
1781.94	1.80084
1784.95	2.37618
1787.96	2.06847
1790.97	1.94128
1793.98	1.67458
1796.99	2.21535
1800	2.11445
1803	1.97488
1806.01	2.68883
1809.01	2.98542
1812.02	3.37635
1815.02	4.01018
1818.02	4.87271
1821.02	4.74556
1824.02	5.39391
1827.01	5.52695
1830.01	5.56894
1833	5.79226
1836	4.98087
1838.99	5.2005
1841.98	4.84567
1844.97	4.81126
1847.96	5.05108
1850.95	5.71081
1853.94	5.46405
1856.92	4.88455
1859.91	4.13945
1862.89	3.71705
1865.88	3.18436
1868.86	3.829
1871.84	3.20909
1874.82	2.87687
1877.8	2.50795
1880.77	2.40079
1882.52	2.81909
1885.51	2.50526
1888.5	2.49845
1891.49	2.47959
1894.47	1.4794
1897.46	0.717767
1900.44	1.49686
1903.42	1.48801
1906.4	1.059
1909.38	0.252073
1912.36	0.678106
1915.34	0.597686
1918.32	1.07429
1921.29	0.787108
1924.27	0.819393
1927.24	0.64183
1930.21	1.16355
1933.18	1.38283
1936.15	1.12285
1939.12	1.62379
1942.09	2.38947
1945.06	1.51648
1948.02	1.98567
1950.99	2.02726
1953.95	1.69147
1956.91	1.75836
1959.87	1.13365
1962.84	1.51071
1965.79	1.70093
1968.75	2.21938
1971.71	2.59131
1974.66	3.75841
1977.62	2.65304
1980.57	2.7189
1983.53	2.54935
1986.48	3.52855
1989.43	3.7976
1992.38	4.19717
1995.33	5.77525
1998.27	5.50088
2001.22	6.00256
2004.16	6.08123
2007.11	5.94035
2010.05	4.7573
2012.99	4.0969
2015.93	4.33716
2018.87	3.42722
2021.81	3.14803
2024.75	3.4419
2027.69	3.80991
2030.62	3.9403
2033.56	4.7792
2036.49	5.14613
2039.42	4.54968
2042.35	4.33976
2045.28	4.36291
2048.21	4.51617
2051.14	4.00002
2054.06	4.7104
2056.99	4.91721
2059.92	5.51366
2062.84	5.53253
2065.76	5.92408
2068.68	7.0596
2071.6	6.29419
2074.52	6.35471
2077.44	6.11961
2080.36	5.21345
2083.27	4.4809
2086.19	5.56233
2089.1	5.41649
2092.01	5.28902
2094.93	6.40178
2097.84	6.62422
2100.75	6.79193
2103.66	6.48807
2106.56	6.98464
2109.47	5.54804
2112.37	6.09922
2115.28	6.61406
2118.18	6.2295
2121.09	6.35836
2123.99	6.36138
2126.89	6.13736
2129.79	6.41858
2132.68	6.5893
2135.58	8.02505
2138.48	7.95053
2141.37	8.45256
2144.26	8.919
2147.16	9.29112
2150.05	10.7035
2152.94	10.5076
2155.83	11.6549
2158.72	12.2702
2161.6	12.2683
2164.49	12.8414
2167.38	13.3104
2170.26	13.3326
2173.14	14.3463
2176.03	14.9919
2178.91	15.3694
2181.79	16.5836
2184.67	17.0649
2187.54	16.3423
2190.42	15.4966
2193.3	16.0674
2196.17	15.9266
2199.05	15.4187
2201.92	15.4237
2204.79	15.0047
2207.66	14.8224
2210.53	14.8063
2213.4	15.5777
2216.27	15.4151
2219.13	15.4729
2222	13.9723
2224.86	12.6292
2227.72	12.4293
2230.59	10.997
2233.45	10.6129
2236.31	10.7842
2239.17	9.35197
2242.03	8.92441
2244.88	8.29746
2247.74	7.88061
2250.59	7.45996
2253.45	6.67319
2256.3	5.04908
2259.15	5.24297
2262	4.88385
2264.85	5.75044
2267.7	5.49828
2270.55	5.49368
2273.4	5.82037
2276.24	6.27536
2279.09	6.54088
2281.93	6.87628
2284.77	7.39361
2287.61	6.52266
2290.46	5.76733
2293.29	4.33985
2296.13	4.70226
2298.97	6.1371
2301.81	6.63022
2304.64	7.25973
2307.48	7.22206
2310.31	8.34402
2313.14	9.03207
2315.97	9.31555
2318.8	10.1074
2321.63	10.1676
2324.46	10.2715
2327.29	11.3096
2330.12	12.3212
2332.94	11.6787
2335.76	11.8378
2338.59	11.1556
2341.41	10.3328
2344.23	9.45244
2347.05	8.62617
2349.87	7.19203
2352.69	5.07685
2355.5	4.4466
2358.32	3.25574
2361.14	2.98642
2363.95	3.55904
2366.76	4.32407
2369.58	4.26836
2372.39	4.41756
2375.2	3.69955
2378	3.35356
2380.81	2.99627
2383.62	2.32211
2386.42	2.0547
2389.23	2.36306
2392.03	2.72266
2394.84	3.06943
2397.64	3.05775
2400.44	2.45004
2403.24	2.30624
2406.04	3.17695
2408.83	3.18856
2411.63	3.1904
2414.43	1.92019
2417.22	1.66859
2420.02	2.79419
2422.81	3.53682
2425.6	3.98386
2428.39	5.03679
2431.18	4.69026
2433.97	4.57077
2436.76	4.05729
2439.54	3.74699
2442.33	2.94662
2445.11	3.10036
2447.9	2.80561
2450.68	2.75755
2453.46	3.23971
2456.24	4.41598
2459.02	4.0574
2461.8	4.1078
2464.58	3.64827
2467.36	3.53514
2470.13	3.84212
2472.91	3.86215
2475.68	4.31471
2478.45	4.56359
2481.22	5.20038
2484	5.75454
2486.77	5.60944
2489.54	5.38328
2492.3	4.44627
2495.07	4.6498
2497.84	3.80879
2500.6	3.95085
2503.36	3.49464
2506.13	3.14329
2508.89	2.94881
2511.65	3.87131
2514.41	4.06358
2517.17	3.97261
2519.93	4.51947
2522.68	5.2198
2525.44	4.49409
2528.19	3.77896
2530.95	4.56475
2533.7	4.2497
2536.45	4.35008
2539.2	4.67582
2541.95	4.50267
2544.7	5.55885
2547.45	6.19536
2550.2	5.78414
2552.94	5.44303
2555.69	4.58257
2558.43	4.33914
2561.17	4.5524
2563.92	4.46902
2566.66	5.15118
2569.4	4.99085
2572.14	4.94821
2574.88	5.73391
2577.61	5.97979
2580.35	7.28374
2583.09	8.51323
2585.82	9.04882
2588.55	8.7182
2591.28	8.47346
2594.02	8.52873
2596.75	8.51599
2599.48	8.64396
2602.2	8.00717
2604.93	7.64063
2607.66	7.40245
2610.38	7.39145
2613.11	8.05849
2615.83	7.31433
2618.56	6.85206
2621.28	5.7342
2624	5.36471
2626.72	5.63415
2629.44	5.00266
2632.15	5.49729
2634.87	6.00729
2637.59	5.9364
2640.3	6.90035
2643.02	7.50487
2645.73	7.98654
2648.44	8.0881
2651.15	8.01945
2653.86	7.95727
2656.57	8.32921
2659.28	8.01128
2661.99	8.56384
2664.69	8.40162
2667.4	8.34964
2670.1	7.58352
2672.81	7.72117
2675.51	8.34696
2678.21	7.68759
2680.91	6.71348
2683.61	6.31888
2686.31	5.50497
2689	5.05433
2691.7	4.20154
2694.4	4.37681
2697.09	5.22107
2699.79	6.94252
2702.48	7.34347
2705.17	8.23882
2707.86	8.11137
2710.55	9.3495
2713.24	9.99715
2715.93	10.3736
2718.61	12.1388
2721.3	12.9833
2723.99	13.496
2726.67	14.1035
2729.35	14.9004
2732.04	14.6013
2734.72	13.5524
2737.4	12.9064
2740.08	12.1229
2742.76	10.3179
2745.43	9.47137
2748.11	8.78447
2750.79	8.37685
2753.46	7.86209
2756.13	7.65932
2758.81	7.48928
2761.48	7.9563
2764.15	7.97855
2766.82	7.03364
2769.49	6.52271
2772.16	5.87785
2774.82	5.22967
2777.49	5.31984
2780.16	4.74447
2782.82	4.60466
2785.48	4.45463
2788.15	2.80459
2790.81	2.51914
2793.47	1.92599
2796.13	1.01154
2798.79	0.194337
2801.44	-0.127259
2804.1	-0.138276
2806.76	0.0253438
2809.41	1.38913
2812.07	2.33662
2814.72	3.33365
2817.37	3.83005
2820.02	6.06273
2822.67	7.9373
2825.32	9.52432
2827.97	10.8272
2830.62	12.6863
2833.26	14.6709
2835.91	16.5303
2838.55	19.8331
2841.2	22.869
2843.84	25.5084
2846.48	28.7026
2849.12	33.0766
2851.76	37.5795
2854.4	42.6193
2857.04	48.0871
2859.68	52.8139
2862.32	57.1573
2864.95	61.713
2867.58	66.7767
2870.22	72.2656
2872.85	75.7784
2875.48	78.5926
2878.11	81.253
2880.74	84.1791
2883.37	87.3647
2886	90.1029
2888.63	91.706
2891.25	93.773
2893.88	95.891
2896.5	98.1943
2899.13	101.569
2901.75	105.184
2904.37	109.548
2906.99	114.341
2909.61	119.737
2912.23	126.633
2914.85	132.688
2917.46	137.29
2920.08	141.653
2922.7	144.524
2925.31	146.046
2927.92	147.908
2930.53	148.587
2933.15	148.254
2935.76	146.843
2938.37	143.779
2940.98	140.555
2943.58	136.875
2946.19	132.667
2948.8	128.366
2951.4	122.639
2954.01	117.752
2956.61	112.25
2959.21	107.332
2961.81	102.311
2964.41	98.1645
2967.01	93.7726
2969.61	89.9928
2972.21	86.7318
2974.81	82.3697
2977.4	77.4153
2980	71.6086
2982.59	66.3932
2985.18	60.2881
2987.78	54.868
2990.37	49.857
2992.96	45.1634
2995.55	40.5888
2998.14	36.1514
3000.72	31.2535
3003.31	26.954
3005.9	23.1788
3008.48	19.5635
3011.07	16.8642
3013.65	14.2071
3016.23	11.165
3018.81	9.39921
3021.39	7.92642
3023.97	6.15869
3026.55	5.62597
3029.13	4.77254
3031.71	4.11009
3034.28	3.9177
3036.86	3.72974
3039.43	4.03473
3042.01	3.935
3044.58	4.47911
3047.15	4.77556
3049.72	4.9274
3052.29	5.23483
3054.86	5.82408
3057.43	6.76464
3060	6.65628
3062.56	5.75149
3065.13	5.33245
3067.69	4.98789
3070.25	4.61405
3072.82	3.89346
3075.38	2.73909
3077.94	2.44053
3080.5	1.69372
3083.06	1.45521
3085.62	0.00538299
3088.17	-0.756203
3090.73	-0.263858
3093.29	-0.19568
3095.84	-1.43439
3098.4	-1.42474
3100.95	-0.872365
3103.5	-0.347682
3106.05	-0.61978
3108.6	0.560713
3111.15	1.39446
3113.7	2.48016
3116.25	3.32412
3118.79	3.97543
3121.34	5.20452
3123.88	5.5476
3126.43	6.82823
3128.97	8.2113
3131.51	9.28058
3134.05	10.3809
3136.59	12.2841
3139.14	13.6271
3141.67	14.6435
3144.21	15.4866
3146.75	15.8841
3149.28	15.0921