File: data/Raman/poly_smoothed/Mb_10_14_28_1x_45s_532 nm_x100_100%_600 gr_mm_01.txt
#Acq. time (s)=	45
#Accumulations=	2
#Range (cm-¹)=	200...3150
#Windows=	2
#Auto scanning=	Off
#Autofocus=	Off
#Macrospot=	Off
#AutoExposure=	Off
#Spike filter=	Multiple accum.
#Delay time (s)=	0
#Binning=	1
#Readout mode=	Signal
#DeNoise=	Off
#ICS correction=	On
#Dark correction=	Off
#Inst. Process=	Off
#Detector Gain=	Best Dynamic Range
#Detector ADC=	20 kHz
#Detector temperature (°C)=	-69.85
#Instrument=	LabRAM HR Evol
#Detector=	Synapse
#Objective=	x100
#Grating=	600 gr/mm
#ND Filter=	100%
#Laser (nm)=	532
#Hole=	100.021
#Range=	Auto
#Laser Pol.=	No
#Raman. Pol.=	No
#Laser Pol. (°)=	-0.0007625
#Raman Pol. (°)=	89.9995
#Collection=	Microscope
#StageXY=	Marzhauser
#StageZ=	Marzhauser
#X (µm)=	-611.8
#Y (µm)=	-1589.8
#Z (µm)=	89.85
#Full time(mm:ss)=	3:18
#Project=
#Sample=
#Site=
#Title=	Mb_10_14_28_2x_45s_532 nm_x100_100%_600 gr_mm
#Remark=
#Date=	11.07.2022 10:37
#Acquired=	11.07.2022 10:37:04
#Base:Fit=	10.08.2022 10:21:11
#Base:Sub=	10.08.2022 10:21:41
#Filter:Polynom=	16.08.2022 10:17:53
#AxisType[0]=Intens
#AxisUnit[0]=Cnt
#AxisType[1]=Spectr
#AxisUnit[1]=1/cm
200.388	29.8126
204.019	21.5728
207.646	14.1233
211.274	9.22285
214.899	6.36525
218.524	5.29634
222.146	5.8795
225.766	8.48133
229.388	9.72753
233.005	11.0807
236.621	13.4465
240.236	15.5471
243.852	17.8219
247.464	18.7647
251.074	20.4336
254.683	22.6503
258.291	23.3152
261.897	24.1647
265.504	23.144
269.108	22.9288
272.71	21.3854
276.311	20.2343
279.91	18.3695
283.508	15.0464
287.105	13.5217
290.698	13.6094
294.291	12.8679
297.884	10.9773
301.475	10.1232
305.064	8.79983
308.652	8.81378
312.237	8.94272
315.822	8.80387
319.406	9.22793
322.987	9.96955
326.568	11.0767
330.148	11.8204
333.724	11.7689
337.301	10.8586
340.875	11.8551
344.449	12.6004
348.02	14.5993
351.592	14.4866
355.16	14.5395
358.728	16.2927
362.294	18.1229
365.858	18.6246
369.422	19.0613
372.983	20.7337
376.543	22.9283
380.102	24.8993
383.661	24.541
387.216	26.0358
390.771	25.8217
394.324	26.6954
397.875	27.6771
401.425	26.1415
404.974	26.1338
408.524	24.9603
412.07	25.4504
415.614	24.809
419.156	23.4141
422.698	21.3768
426.238	20.6012
429.777	19.1644
433.315	17.6566
436.852	16.3419
440.387	14.2244
443.919	13.2973
447.451	13.7899
450.982	13.1834
454.512	13.4705
458.038	14.389
461.565	15.1639
465.091	16.9945
468.613	16.9494
472.136	17.5811
475.655	17.3552
479.176	18.1697
482.692	19.3444
486.21	20.0264
489.724	20.7532
493.237	22.7112
496.75	24.6051
500.26	25.5598
503.769	25.2936
507.279	26.889
510.785	27.8171
514.289	28.7169
517.793	29.2214
521.297	28.4123
524.797	28.5473
528.297	27.4187
531.795	27.3249
535.291	27.5789
538.787	25.3659
542.281	25.1906
545.773	24.6643
549.264	23.521
552.754	21.8964
556.243	19.4304
559.73	17.8141
563.216	17.294
566.701	15.2421
570.182	15.006
573.664	13.6592
577.145	10.7981
580.624	9.4083
584.1	9.2859
587.577	8.13601
591.052	7.15498
594.524	6.2645
597.997	5.03786
601.466	4.90009
604.936	4.23387
608.403	3.67434
611.87	3.91575
615.334	3.79178
618.799	4.41103
622.26	4.04251
625.72	5.08877
629.181	7.56825
632.638	8.4589
636.095	11.3898
639.551	12.6533
643.005	14.0014
646.457	15.6903
649.908	16.0572
653.357	17.505
656.806	19.2805
660.253	19.1163
663.7	20.2597
667.145	21.6299
670.588	21.5625
674.027	21.9264
677.468	23.4149
680.907	23.6801
684.345	23.6008
687.781	24.9489
691.216	24.5598
694.65	25.9173
698.081	26.3256
701.512	27.3121
704.942	28.3819
708.371	29.7014
711.796	30.7057
715.222	32.3838
718.645	33.7452
722.068	35.7759
725.49	36.3887
728.909	37.3302
732.329	38.7564
735.745	40.5199
739.16	45.1596
742.576	46.9056
745.988	50.5312
749.401	53.1279
752.811	55.6168
756.22	60.1418
759.627	62.1641
763.035	64.1914
766.44	65.859
769.843	67.3255
773.245	69.6282
776.646	71.0695
780.046	74.8698
783.444	75.9681
786.841	76.0925
790.237	76.3823
793.631	76.2666
797.024	77.1055
800.416	77.7085
803.807	78.9571
807.196	78.9624
810.584	77.7962
813.971	76.325
817.354	76.8662
820.739	77.3735
824.122	78.062
827.503	76.9737
830.882	76.987
834.261	75.7532
837.637	75.0992
841.013	71.3638
844.389	66.9152
847.761	63.6293
851.131	62.6228
854.503	59.1696
857.871	56.0825
861.24	55.1639
864.606	54.2407
867.97	51.8212
871.336	50.1109
874.698	50.3206
878.058	50.3939
881.418	51.8216
884.778	52.3307
888.135	51.6688
891.49	48.9935
894.845	48.3618
898.198	49.3528
901.55	50.4406
904.901	50.9617
908.25	52.4525
911.598	53.7136
914.945	54.1229
918.291	53.7445
921.635	51.9903
924.978	52.0342
928.318	52.7208
931.659	52.733
934.998	52.3507
938.336	51.1209
941.671	50.0672
945.007	50.3105
948.339	48.4124
951.672	47.1571
955.004	47.1967
958.333	46.6737
961.662	44.7778
964.989	45.1254
968.315	44.4383
971.639	44.0272
974.962	44.7517
978.285	46.8259
981.605	47.4383
984.924	46.8838
988.243	46.4139
991.56	45.3423
994.875	43.8371
998.188	41.5211
1001.5	40.336
1004.81	40.3027
1008.12	39.3378
1011.43	37.5608
1014.74	38.0529
1018.05	36.4795
1021.35	36.5644
1024.65	35.8862
1027.96	35.2412
1031.26	35.6591
1034.56	36.9442
1037.86	36.3502
1041.16	37.0788
1044.45	37.8565
1047.75	38.7017
1051.04	38.3357
1054.33	37.0519
1057.62	38.2005
1060.91	37.262
1064.2	33.4223
1067.49	32.9784
1070.77	29.7243
1074.06	27.7047
1077.34	25.1264
1080.62	23.9709
1083.91	21.5034
1087.18	19.4822
1090.46	19.5987
1093.74	18.5916
1097.02	20.0462
1100.29	18.7303
1103.56	19.343
1106.84	19.1103
1110.11	19.2111
1113.38	19.796
1116.64	19.9388
1119.91	18.63
1123.18	17.7968
1126.44	18.4233
1129.7	17.8942
1132.97	19.1413
1136.23	19.8121
1139.49	20.6842
1142.74	19.3755
1146	17.8502
1149.26	15.7687
1152.51	13.0975
1155.76	13.6399
1159.01	12.2696
1162.27	10.7741
1165.51	11.003
1168.76	10.9458
1172.01	11.1875
1175.25	12.2085
1178.5	11.4677
1181.74	11.9531
1184.98	10.8564
1188.22	10.8292
1191.46	12.4168
1194.7	14.0803
1197.94	15.0192
1201.17	17.6453
1204.41	18.3189
1207.64	19.5931
1210.87	21.905
1214.1	22.7553
1217.33	25.2661
1220.56	25.8952
1223.79	26.8445
1227.01	28.5759
1230.23	31.2903
1233.46	33.8815
1236.68	35.5639
1239.9	37.5451
1243.12	37.4213
1246.34	38.3365
1249.55	37.9004
1252.77	37.8984
1255.98	38.346
1259.2	37.1121
1262.41	37.4395
1265.62	37.5779
1268.83	38.3389
1272.03	38.0935
1275.24	38.18
1278.45	37.1771
1281.65	36.4532
1284.85	37.1625
1288.06	39.8192
1291.26	39.6179
1294.46	40.9687
1297.66	44.5594
1300.85	46.3963
1304.05	48.2462
1307.24	50.2909
1310.43	52.1684
1313.63	52.3722
1316.82	54.4535
1320.01	57.2564
1323.2	57.3901
1326.38	58.4877
1329.57	57.9075
1332.76	57.7118
1335.94	57.8742
1339.12	57.1546
1342.3	55.8325
1345.48	52.7059
1348.66	52.5349
1351.84	51.4279
1355.01	49.0283
1358.19	47.0583
1361.36	45.6096
1364.53	44.1498
1367.71	42.1076
1370.88	38.796
1374.04	37.7284
1377.21	36.5086
1380.38	35.1378
1383.54	34.584
1386.71	33.494
1389.87	33.4778
1393.03	34.5313
1396.19	35.0488
1399.35	34.7673
1402.51	34.077
1405.67	34.6811
1408.82	35.8373
1411.98	38.6552
1415.13	41.9129
1418.28	43.8738
1421.43	47.5843
1424.58	50.9075
1427.73	55.4994
1430.88	60.3151
1434.02	64.1019
1437.17	67.3487
1440.31	70.5794
1443.45	71.8194
1446.6	72.543
1449.74	74.2797
1452.87	74.9889
1456.01	75.1354
1459.15	74.3147
1462.28	74.0174
1465.42	70.9138
1468.55	68.2611
1471.68	65.3331
1474.81	62.5648
1477.94	58.2699
1481.07	55.286
1484.2	50.8568
1487.32	49.0741
1490.45	46.6835
1493.57	42.1803
1496.69	39.7339
1499.81	37.7356
1502.93	34.6009
1506.05	33.0845
1509.17	29.9615
1512.28	26.9205
1515.4	23.3658
1518.51	21.5721
1521.63	19.8297
1524.74	18.3822
1527.85	16.6966
1530.96	15.6088
1534.06	14.6369
1537.17	15.5206
1540.28	15.8387
1543.38	15.3552
1546.48	17.9671
1549.59	18.1617
1552.69	18.9828
1555.79	20.209
1558.88	20.8839
1561.98	22.3309
1565.08	23.8408
1568.17	24.6804
1571.27	27.8662
1574.36	30.2617
1577.45	32.3037
1580.54	34.4403
1583.63	35.351
1586.72	36.8602
1589.8	38.2502
1592.89	39.8281
1595.97	41.9385
1599.06	42.9992
1602.14	42.5116
1605.22	42.3115
1608.3	42.7472
1611.38	43.845
1614.46	44.1333
1617.53	44.8047
1620.61	46.1859
1623.68	46.9226
1626.75	47.2184
1629.82	47.7976
1632.9	48.9077
1635.96	49.5135
1639.03	51.2439
1642.1	52.8785
1645.16	55.4485
1648.23	57.0001
1651.29	59.4148
1654.36	59.3394
1657.42	58.9669
1660.48	58.2761
1663.53	57.1285
1666.59	56.1082
1669.65	54.1755
1672.7	51.7695
1675.76	47.2765
1678.81	44.4571
1681.86	40.7428
1684.91	36.9672
1687.96	32.4011
1691.01	29.2614
1694.06	26.0719
1697.11	22.5897
1700.15	19.13
1703.2	16.7514
1706.24	13.6978
1709.28	11.7985
1712.32	9.81134
1715.36	7.56221
1718.4	7.62245
1721.43	6.08745
1724.47	4.95295
1727.5	4.25285
1730.54	2.32972
1733.57	2.40609
1736.6	2.43202
1739.63	1.50502
1742.66	1.38151
1745.69	2.14592
1748.72	2.15858
1751.74	2.15393
1754.77	2.68072
1757.79	1.52722
1760.81	0.882165
1763.83	1.90348
1766.85	1.87192
1769.87	1.74723
1772.89	0.822015
1775.91	1.00677
1778.92	1.46187
1781.94	0.737383
1784.95	1.52448
1787.96	2.07627
1790.97	1.45435
1793.98	1.40236
1796.99	1.16166
1800	1.34792
1803	0.705366
1806.01	0.822702
1809.01	1.31387
1812.02	1.63673
1815.02	1.51902
1818.02	2.25666
1821.02	2.21479
1824.02	2.28814
1827.01	2.70766
1830.01	2.94959
1833	3.00346
1836	3.72726
1838.99	3.87635
1841.98	3.38326
1844.97	3.13191
1847.96	3.28272
1850.95	3.73606
1853.94	4.53019
1856.92	4.25044
1859.91	5.18918
1862.89	4.62789
1865.88	4.53023
1868.86	4.73519
1871.84	5.14357
1874.82	4.73176
1877.8	4.53695
1880.77	5.69238
1882.52	4.29811
1885.51	3.74274
1888.5	3.29086
1891.49	2.99526
1894.47	3.50546
1897.46	3.54198
1900.44	4.5278
1903.42	5.19169
1906.4	5.54677
1909.38	5.58146
1912.36	4.15756
1915.34	5.24409
1918.32	4.94466
1921.29	6.52515
1924.27	6.58578
1927.24	7.04921
1930.21	6.75072
1933.18	7.0951
1936.15	6.65556
1939.12	6.59956
1942.09	6.92249
1945.06	7.03431
1948.02	5.33599
1950.99	4.27071
1953.95	3.42249
1956.91	2.16623
1959.87	1.7813
1962.84	0.944845
1965.79	0.406561
1968.75	0.126975
1971.71	-0.606825
1974.66	-0.104456
1977.62	-0.0235945
1980.57	-0.634742
1983.53	-0.859131
1986.48	-0.463804
1989.43	-0.205373
1992.38	0.758687
1995.33	1.83393
1998.27	2.33437
2001.22	2.8749
2004.16	2.28503
2007.11	2.43152
2010.05	2.97744
2012.99	3.79783
2015.93	4.66085
2018.87	4.53142
2021.81	4.17909
2024.75	5.02531
2027.69	5.75867
2030.62	6.08311
2033.56	6.35625
2036.49	5.80101
2039.42	6.09231
2042.35	6.46344
2045.28	6.63199
2048.21	6.72045
2051.14	6.95235
2054.06	6.40599
2056.99	7.35736
2059.92	7.66168
2062.84	8.70907
2065.76	8.46088
2068.68	9.14085
2071.6	9.49866
2074.52	9.96589
2077.44	10.5157
2080.36	10.328
2083.27	10.1948
2086.19	9.96849
2089.1	9.65125
2092.01	8.43804
2094.93	8.10878
2097.84	9.53637
2100.75	8.91908
2103.66	8.16128
2106.56	8.026
2109.47	8.41684
2112.37	8.24181
2115.28	8.67096
2118.18	9.49534
2121.09	11.0533
2123.99	12.1249
2126.89	13.7189
2129.79	15.1086
2132.68	17.5209
2135.58	18.4263
2138.48	20.2987
2141.37	21.5801
2144.26	22.4871
2147.16	24.1168
2150.05	25.0709
2152.94	25.3202
2155.83	25.1698
2158.72	24.6689
2161.6	24.5287
2164.49	26.6177
2167.38	26.5005
2170.26	26.063
2173.14	26.7671
2176.03	26.9646
2178.91	27.9489
2181.79	28.5198
2184.67	28.8715
2187.54	29.3733
2190.42	28.6797
2193.3	28.5995
2196.17	27.6866
2199.05	26.9194
2201.92	26.985
2204.79	24.6948
2207.66	23.0222
2210.53	21.2171
2213.4	19.6044
2216.27	18.3021
2219.13	18.0333
2222	15.001
2224.86	12.2621
2227.72	10.881
2230.59	9.98649
2233.45	9.83105
2236.31	8.66664
2239.17	8.06313
2242.03	8.20798
2244.88	8.46375
2247.74	9.05441
2250.59	9.02391
2253.45	8.5036
2256.3	7.8604
2259.15	7.52085
2262	7.22479
2264.85	7.53374
2267.7	7.90835
2270.55	7.44865
2273.4	6.82908
2276.24	6.51504
2279.09	5.12653
2281.93	4.69805
2284.77	4.23417
2287.61	4.07753
2290.46	3.30546
2293.29	1.7703
2296.13	2.52746
2298.97	3.54178
2301.81	4.35006
2304.64	4.09362
2307.48	5.41434
2310.31	6.66116
2313.14	6.70854
2315.97	6.66196
2318.8	6.63577
2321.63	5.96998
2324.46	6.42196
2327.29	6.97339
2330.12	6.71345
2332.94	6.40818
2335.76	5.56951
2338.59	4.88262
2341.41	4.14126
2344.23	3.73943
2347.05	2.23089
2349.87	1.24579
2352.69	1.29305
2355.5	1.4346
2358.32	0.304361
2361.14	0.0358685
2363.95	-0.0994822
2366.76	1.24867
2369.58	1.39714
2372.39	1.226
2375.2	0.8263
2378	1.09336
2380.81	0.811265
2383.62	1.10816
2386.42	2.10013
2389.23	2.59147
2392.03	2.50195
2394.84	2.51269
2397.64	1.94787
2400.44	1.96964
2403.24	2.36529
2406.04	2.80574
2408.83	3.50243
2411.63	4.79281
2414.43	5.39573
2417.22	6.07216
2420.02	6.88126
2422.81	6.91214
2425.6	6.83171
2428.39	7.29366
2431.18	7.51018
2433.97	7.53587
2436.76	7.27947
2439.54	6.95078
2442.33	6.42234
2445.11	5.98234
2447.9	6.35683
2450.68	6.30411
2453.46	6.91799
2456.24	6.217
2459.02	5.1027
2461.8	4.16777
2464.58	4.61428
2467.36	5.50899
2470.13	5.68481
2472.91	7.08999
2475.68	6.02455
2478.45	6.44659
2481.22	7.07752
2484	6.50944
2486.77	5.26369
2489.54	5.00265
2492.3	5.00388
2495.07	4.72974
2497.84	4.29468
2500.6	2.86422
2503.36	2.80463
2506.13	2.17581
2508.89	1.86245
2511.65	1.66084
2514.41	1.37277
2517.17	1.53124
2519.93	2.90601
2522.68	2.48055
2525.44	1.99358
2528.19	1.69162
2530.95	3.26576
2533.7	4.11936
2536.45	4.44615
2539.2	5.20812
2541.95	4.89199
2544.7	5.00434
2547.45	5.12348
2550.2	4.89268
2552.94	4.6255
2555.69	5.73916
2558.43	6.19324
2561.17	6.60045
2563.92	5.89584
2566.66	4.65012
2569.4	4.53403
2572.14	5.33562
2574.88	5.41913
2577.61	5.29382
2580.35	4.42165
2583.09	3.84549
2585.82	4.5359
2588.55	4.00856
2591.28	3.47924
2594.02	2.88495
2596.75	3.02914
2599.48	3.64054
2602.2	4.24929
2604.93	4.39873
2607.66	4.79718
2610.38	5.72355
2613.11	6.70502
2615.83	6.21488
2618.56	5.91992
2621.28	7.15075
2624	7.08276
2626.72	6.1701
2629.44	5.65193
2632.15	5.29245
2634.87	5.34228
2637.59	5.87821
2640.3	5.64169
2643.02	5.06893
2645.73	4.90266
2648.44	4.77849
2651.15	4.53024
2653.86	4.57279
2656.57	4.04856
2659.28	3.44963
2661.99	3.28368
2664.69	4.35855
2667.4	5.11497
2670.1	4.70203
2672.81	5.47902
2675.51	5.90269
2678.21	5.40186
2680.91	4.80654
2683.61	4.54441
2686.31	4.33675
2689	4.21781
2691.7	3.88828
2694.4	5.0238
2697.09	5.79378
2699.79	5.4821
2702.48	5.76534
2705.17	6.58198
2707.86	6.78204
2710.55	7.81841
2713.24	8.668
2715.93	8.53524
2718.61	8.79123
2721.3	9.00746
2723.99	9.67271
2726.67	9.61883
2729.35	10.3186
2732.04	10.5013
2734.72	10.3976
2737.4	11.304
2740.08	10.7314
2742.76	10.9412
2745.43	11.6667
2748.11	10.5799
2750.79	10.947
2753.46	10.7653
2756.13	10.2388
2758.81	9.94255
2761.48	9.47983
2764.15	8.03898
2766.82	7.0624
2769.49	6.41536
2772.16	5.08133
2774.82	4.70219
2777.49	3.22341
2780.16	1.71282
2782.82	1.44348
2785.48	0.907688
2788.15	1.17293
2790.81	0.536148
2793.47	0.351155
2796.13	0.7408
2798.79	0.851834
2801.44	1.80325
2804.1	2.60157
2806.76	3.07701
2809.41	3.37471
2812.07	4.15911
2814.72	5.23476
2817.37	7.27058
2820.02	8.41083
2822.67	10.6987
2825.32	12.8258
2827.97	15.4211
2830.62	18.6087
2833.26	22.6602
2835.91	25.8138
2838.55	31.2926
2841.2	37.6096
2843.84	43.5504
2846.48	51.7858
2849.12	60.9324
2851.76	70.2864
2854.4	78.1427
2857.04	86.8976
2859.68	95.683
2862.32	105.047
2864.95	113.436
2867.58	121.859
2870.22	128.741
2872.85	133.884
2875.48	140.39
2878.11	145.426
2880.74	150.45
2883.37	154.413
2886	158.456
2888.63	163.881
2891.25	168.39
2893.88	172.578
2896.5	177.352
2899.13	183.086
2901.75	189.972
2904.37	197.716
2906.99	208.793
2909.61	218.357
2912.23	229.541
2914.85	239.279
2917.46	248.39
2920.08	256.97
2922.7	265.129
2925.31	271.53
2927.92	275.087
2930.53	276.027
2933.15	275.051
2935.76	272.414
2938.37	268.004
2940.98	261.539
2943.58	254.383
2946.19	245.645
2948.8	235.935
2951.4	226.527
2954.01	215.969
2956.61	204.061
2959.21	193.167
2961.81	181.767
2964.41	172.285
2967.01	162.638
2969.61	153.039
2972.21	144.083
2974.81	135.605
2977.4	126.643
2980	118.581
2982.59	109.136
2985.18	99.8298
2987.78	89.9686
2990.37	80.7195
2992.96	71.1735
2995.55	61.9994
2998.14	54.2739
3000.72	46.1516
3003.31	37.9238
3005.9	31.8558
3008.48	25.8271
3011.07	21.5424
3013.65	18.1983
3016.23	15.1124
3018.81	12.4081
3021.39	10.0626
3023.97	8.95815
3026.55	7.21574
3029.13	6.01353
3031.71	6.19243
3034.28	5.55513
3036.86	6.19835
3039.43	6.93985
3042.01	8.29519
3044.58	8.53127
3047.15	8.23282
3049.72	8.59385
3052.29	9.06995
3054.86	8.88527
3057.43	9.03728
3060	7.36742
3062.56	6.99233
3065.13	6.49887
3067.69	5.75902
3070.25	5.05073
3072.82	4.66141
3075.38	3.80599
3077.94	2.54392
3080.5	1.6057
3083.06	0.580918
3085.62	0.908456
3088.17	0.492079
3090.73	0.531031
3093.29	0.963388
3095.84	0.050921
3098.4	0.0788482
3100.95	1.12567
3103.5	1.31411
3106.05	2.36204
3108.6	2.09073
3111.15	3.17517
3113.7	4.06591
3116.25	5.13233
3118.79	6.17283
3121.34	7.36551
3123.88	8.12842
3126.43	9.83755
3128.97	11.5252
3131.51	12.4424
3134.05	15.0339
3136.59	16.006
3139.14	17.7995
3141.67	20.8238
3144.21	23.6908
3146.75	26.083
3149.28	26.8106