File: data/Raman/poly_smoothed/Mb_10_14_41_1x_45s_532 nm_x100_100%_600 gr_mm_01.txt
#Acq. time (s)=	45
#Accumulations=	2
#Range (cm-¹)=	200...3150
#Windows=	2
#Auto scanning=	Off
#Autofocus=	Off
#Macrospot=	Off
#AutoExposure=	Off
#Spike filter=	Multiple accum.
#Delay time (s)=	0
#Binning=	1
#Readout mode=	Signal
#DeNoise=	Off
#ICS correction=	On
#Dark correction=	Off
#Inst. Process=	Off
#Detector Gain=	Best Dynamic Range
#Detector ADC=	20 kHz
#Detector temperature (°C)=	-69.85
#Instrument=	LabRAM HR Evol
#Detector=	Synapse
#Objective=	x100
#Grating=	600 gr/mm
#ND Filter=	100%
#Laser (nm)=	532
#Hole=	100.021
#Range=	Auto
#Laser Pol.=	No
#Raman. Pol.=	No
#Laser Pol. (°)=	-0.0007625
#Raman Pol. (°)=	89.9995
#Collection=	Microscope
#StageXY=	Marzhauser
#StageZ=	Marzhauser
#X (µm)=	-634.1
#Y (µm)=	-1681.3
#Z (µm)=	88.5
#Full time(mm:ss)=	3:18
#Project=
#Sample=
#Site=
#Title=	Mb_10_14_41_2x_45s_532 nm_x100_100%_600 gr_mm
#Remark=
#Date=	11.07.2022 11:41
#Acquired=	11.07.2022 11:41:01
#Base:Fit=	10.08.2022 10:21:11
#Base:Sub=	10.08.2022 10:21:41
#Filter:Polynom=	16.08.2022 10:17:53
#AxisType[0]=Intens
#AxisUnit[0]=Cnt
#AxisType[1]=Spectr
#AxisUnit[1]=1/cm
200.388	33.4872
204.019	20.1831
207.646	12.201
211.274	6.52023
214.899	4.34295
218.524	7.13324
222.146	11.9585
225.766	17.4965
229.388	22.4104
233.005	25.6191
236.621	28.7714
240.236	31.1315
243.852	36.0058
247.464	38.1794
251.074	42.0148
254.683	43.6346
258.291	44.9057
261.897	46.0748
265.504	45.9513
269.108	43.3012
272.71	40.9051
276.311	37.6696
279.91	32.7179
283.508	28.1742
287.105	23.668
290.698	20.8064
294.291	19.2618
297.884	16.8375
301.475	15.7661
305.064	17.7714
308.652	18.7721
312.237	18.3593
315.822	17.3319
319.406	16.6488
322.987	14.4272
326.568	14.4727
330.148	12.414
333.724	10.6285
337.301	7.69746
340.875	7.4597
344.449	6.14998
348.02	7.58082
351.592	12.3369
355.16	17.1958
358.728	22.1861
362.294	27.464
365.858	34.1446
369.422	39.4219
372.983	45.1138
376.543	50.103
380.102	55.0896
383.661	57.6419
387.216	61.1816
390.771	62.5868
394.324	63.9929
397.875	65.0059
401.425	64.3154
404.974	60.7734
408.524	56.0695
412.07	50.5913
415.614	44.6563
419.156	36.7369
422.698	31.2813
426.238	27.8095
429.777	22.6946
433.315	19.7098
436.852	18.023
440.387	16.2667
443.919	13.2878
447.451	11.1251
450.982	10.9938
454.512	10.9476
458.038	10.7281
461.565	11.38
465.091	12.4522
468.613	14.6076
472.136	16.7286
475.655	18.504
479.176	19.9937
482.692	24.4798
486.21	26.9028
489.724	29.0476
493.237	32.3574
496.75	33.4465
500.26	35.7966
503.769	36.2732
507.279	39.0265
510.785	39.5536
514.289	39.2365
517.793	38.1686
521.297	38.0092
524.797	37.0765
528.297	35.0164
531.795	34.4689
535.291	32.6321
538.787	29.8372
542.281	26.7297
545.773	24.4518
549.264	22.9025
552.754	20.7934
556.243	17.3161
559.73	15.1804
563.216	12.1593
566.701	10.2821
570.182	9.40596
573.664	7.67684
577.145	5.29324
580.624	4.43047
584.1	3.83202
587.577	2.96374
591.052	3.63168
594.524	4.72752
597.997	2.56232
601.466	2.61265
604.936	3.07906
608.403	3.85292
611.87	6.6076
615.334	8.74824
618.799	8.30741
622.26	6.4063
625.72	7.26841
629.181	9.9859
632.638	13.4616
636.095	15.2237
639.551	17.5552
643.005	20.1541
646.457	20.8385
649.908	20.7935
653.357	21.0451
656.806	20.7122
660.253	18.8641
663.7	17.5358
667.145	17.5541
670.588	16.9785
674.027	15.5452
677.468	14.1095
680.907	13.1752
684.345	12.4823
687.781	11.2976
691.216	10.9742
694.65	11.0762
698.081	11.7343
701.512	10.8342
704.942	9.24459
708.371	11.2382
711.796	13.3398
715.222	14.983
718.645	17.9102
722.068	19.8895
725.49	20.6634
728.909	20.7706
732.329	21.834
735.745	23.1793
739.16	23.046
742.576	25.0999
745.988	26.2002
749.401	28.2824
752.811	31.8921
756.22	35.3977
759.627	38.1906
763.035	41.6725
766.44	45.0682
769.843	47.9205
773.245	51.1724
776.646	55.0838
780.046	59.6868
783.444	62.0325
786.841	63.1859
790.237	66.8626
793.631	68.8307
797.024	71.9156
800.416	74.7609
803.807	75.5447
807.196	74.9114
810.584	74.6484
813.971	74.8319
817.354	75.029
820.739	71.8833
824.122	70.8469
827.503	69.6015
830.882	66.9
834.261	67.117
837.637	64.0708
841.013	62.0413
844.389	57.814
847.761	56.7958
851.131	53.7165
854.503	50.8962
857.871	49.7032
861.24	47.6273
864.606	45.4199
867.97	42.0582
871.336	43.9828
874.698	44.9717
878.058	44.0631
881.418	43.3091
884.778	43.0244
888.135	42.8125
891.49	42.4472
894.845	43.9017
898.198	43.1712
901.55	43.3676
904.901	41.9335
908.25	43.1664
911.598	43.4215
914.945	44.5087
918.291	44.6211
921.635	43.2125
924.978	44.9802
928.318	44.9795
931.659	45.4022
934.998	47.1243
938.336	47.5621
941.671	49.1481
945.007	47.3234
948.339	47.1936
951.672	48.3791
955.004	50.822
958.333	47.4815
961.662	42.66
964.989	44.0166
968.315	44.966
971.639	45.6588
974.962	47.9105
978.285	49.4584
981.605	49.8211
984.924	51.0977
988.243	50.3039
991.56	49.9887
994.875	51.2725
998.188	53.1167
1001.5	56.6317
1004.81	60.1776
1008.12	63.1448
1011.43	66.6559
1014.74	70.9767
1018.05	74.6773
1021.35	77.3369
1024.65	79.9389
1027.96	80.2998
1031.26	82.2939
1034.56	81.5146
1037.86	79.3422
1041.16	75.8397
1044.45	74.3153
1047.75	74.0394
1051.04	68.6639
1054.33	62.8068
1057.62	58.1124
1060.91	52.0299
1064.2	44.2997
1067.49	36.4187
1070.77	31.4696
1074.06	28.982
1077.34	28.8396
1080.62	25.91
1083.91	21.7435
1087.18	20.7457
1090.46	21.0264
1093.74	22.3459
1097.02	21.5304
1100.29	23.7184
1103.56	24.8594
1106.84	25.7909
1110.11	26.7271
1113.38	27.5843
1116.64	26.4477
1119.91	26.2654
1123.18	25.2148
1126.44	23.8245
1129.7	19.7928
1132.97	18.7861
1136.23	17.1162
1139.49	14.782
1142.74	13.7436
1146	11.8666
1149.26	10.8048
1152.51	8.37145
1155.76	7.51477
1159.01	3.41549
1162.27	1.80446
1165.51	0.482074
1168.76	0.939642
1172.01	1.32562
1175.25	2.49365
1178.5	2.83572
1181.74	5.64975
1184.98	8.04245
1188.22	9.777
1191.46	12.415
1194.7	15.353
1197.94	18.4331
1201.17	21.6821
1204.41	24.4955
1207.64	27.7405
1210.87	30.1256
1214.1	34.9783
1217.33	40.3131
1220.56	45.6263
1223.79	50.8406
1227.01	54.4173
1230.23	58.9838
1233.46	62.061
1236.68	66.1978
1239.9	69.9265
1243.12	72.0972
1246.34	74.7834
1249.55	80.3148
1252.77	82.2944
1255.98	83.6312
1259.2	85.3254
1262.41	87.1395
1265.62	87.9925
1268.83	88.011
1272.03	87.5783
1275.24	90.359
1278.45	91.4014
1281.65	92.721
1284.85	93.8201
1288.06	96.609
1291.26	96.5583
1294.46	98.5958
1297.66	99.8653
1300.85	102.035
1304.05	102.477
1307.24	104.976
1310.43	106.821
1313.63	108.118
1316.82	109.655
1320.01	109.56
1323.2	110.765
1326.38	109.68
1329.57	109.512
1332.76	106.485
1335.94	104.31
1339.12	101.608
1342.3	97.6145
1345.48	94.8416
1348.66	91.2771
1351.84	90.3713
1355.01	87.3919
1358.19	84.0899
1361.36	81.6843
1364.53	78.2271
1367.71	75.5844
1370.88	71.4004
1374.04	71.7649
1377.21	70.5343
1380.38	70.9113
1383.54	69.7634
1386.71	70.6533
1389.87	72.1561
1393.03	72.6264
1396.19	71.7845
1399.35	70.8884
1402.51	70.4831
1405.67	71.2462
1408.82	74.0132
1411.98	76.0492
1415.13	78.9444
1418.28	83.4731
1421.43	87.7726
1424.58	94.316
1427.73	101.624
1430.88	107.762
1434.02	113.592
1437.17	119.747
1440.31	124.888
1443.45	130.124
1446.6	133.545
1449.74	137.511
1452.87	138.017
1456.01	137.456
1459.15	137.144
1462.28	133.146
1465.42	130.724
1468.55	125.429
1471.68	117.848
1474.81	110.697
1477.94	103.697
1481.07	94.8458
1484.2	87.7439
1487.32	81.5995
1490.45	74.5321
1493.57	69.0834
1496.69	64.4168
1499.81	59.9765
1502.93	57.8109
1506.05	53.6642
1509.17	51.5336
1512.28	48.5426
1515.4	47.3442
1518.51	45.7612
1521.63	43.3256
1524.74	40.7845
1527.85	39.5178
1530.96	38.8863
1534.06	38.7857
1537.17	38.4997
1540.28	40.491
1543.38	43.2871
1546.48	43.7806
1549.59	46.7122
1552.69	47.9789
1555.79	49.2263
1558.88	51.786
1561.98	53.2767
1565.08	55.8141
1568.17	58.1128
1571.27	61.5754
1574.36	65.8667
1577.45	71.7448
1580.54	76.471
1583.63	81.636
1586.72	84.4373
1589.8	86.1406
1592.89	88.2235
1595.97	89.7428
1599.06	89.4983
1602.14	90.4538
1605.22	91.8746
1608.3	91.6546
1611.38	92.2286
1614.46	93.3998
1617.53	95.359
1620.61	95.356
1623.68	97.2049
1626.75	97.0723
1629.82	96.951
1632.9	98.1158
1635.96	100.857
1639.03	102.466
1642.1	106.73
1645.16	110.561
1648.23	114.12
1651.29	116.663
1654.36	119.366
1657.42	120.721
1660.48	118.99
1663.53	117.762
1666.59	116.597
1669.65	113.882
1672.7	108.374
1675.76	101.393
1678.81	96.109
1681.86	87.4119
1684.91	78.6169
1687.96	70.8924
1691.01	64.5472
1694.06	55.9462
1697.11	48.7589
1700.15	43.358
1703.2	36.9509
1706.24	32.9268
1709.28	29.7629
1712.32	24.4579
1715.36	22.1027
1718.4	19.8826
1721.43	16.6431
1724.47	16.4765
1727.5	15.3968
1730.54	15.2775
1733.57	15.0775
1736.6	13.9683
1739.63	13.4358
1742.66	13.4459
1745.69	13.2218
1748.72	12.8308
1751.74	10.9411
1754.77	9.61442
1757.79	8.12161
1760.81	8.10146
1763.83	6.92947
1766.85	6.29115
1769.87	4.628
1772.89	4.70761
1775.91	4.87536
1778.92	3.40014
1781.94	3.95716
1784.95	2.91961
1787.96	3.74353
1790.97	4.22302
1793.98	3.98597
1796.99	3.82652
1800	4.46441
1803	4.25274
1806.01	4.48619
1809.01	4.60014
1812.02	3.13412
1815.02	4.38792
1818.02	5.00971
1821.02	4.84747
1824.02	4.24275
1827.01	3.35346
1830.01	2.89603
1833	3.25787
1836	3.86711
1838.99	4.3944
1841.98	4.51006
1844.97	4.93744
1847.96	4.91149
1850.95	4.58108
1853.94	4.38456
1856.92	4.41999
1859.91	4.20561
1862.89	4.24024
1865.88	4.21043
1868.86	4.18462
1871.84	4.72251
1874.82	4.90776
1877.8	5.05976
1880.77	4.27334
1882.52	4.17704
1885.51	4.7418
1888.5	5.0893
1891.49	5.78304
1894.47	5.35819
1897.46	6.00391
1900.44	7.07195
1903.42	7.00545
1906.4	9.48482
1909.38	10.7586
1912.36	10.9253
1915.34	10.4921
1918.32	9.91924
1921.29	8.88949
1924.27	10.3095
1927.24	8.68918
1930.21	8.17737
1933.18	8.19184
1936.15	7.61156
1939.12	6.5685
1942.09	7.34461
1945.06	7.46937
1948.02	7.34826
1950.99	6.72327
1953.95	5.51551
1956.91	5.83261
1959.87	5.86927
1962.84	6.46302
1965.79	5.90599
1968.75	4.75451
1971.71	4.19822
1974.66	3.90932
1977.62	4.30635
1980.57	4.50481
1983.53	3.95985
1986.48	3.17786
1989.43	2.72308
1992.38	2.56899
1995.33	3.3093
1998.27	2.02892
2001.22	1.74559
2004.16	1.69376
2007.11	1.84873
2010.05	1.9146
2012.99	2.25929
2015.93	2.79962
2018.87	2.68842
2021.81	3.23225
2024.75	2.96666
2027.69	4.49629
2030.62	5.57893
2033.56	5.42369
2036.49	4.22186
2039.42	3.51115
2042.35	3.18673
2045.28	2.89628
2048.21	3.04501
2051.14	4.35845
2054.06	4.86272
2056.99	5.08429
2059.92	5.79898
2062.84	5.0441
2065.76	5.36476
2068.68	5.17007
2071.6	4.82231
2074.52	4.9819
2077.44	4.59794
2080.36	4.32265
2083.27	4.87875
2086.19	4.93982
2089.1	3.77746
2092.01	5.11957
2094.93	4.71754
2097.84	6.38125
2100.75	6.63725
2103.66	6.84579
2106.56	7.02965
2109.47	7.98129
2112.37	9.71119
2115.28	10.0344
2118.18	12.0027
2121.09	14.1542
2123.99	14.5347
2126.89	15.5473
2129.79	17.6316
2132.68	18.5159
2135.58	18.9362
2138.48	20.6179
2141.37	21.6629
2144.26	23.0895
2147.16	24.0221
2150.05	25.8418
2152.94	28.4284
2155.83	31.2189
2158.72	32.5145
2161.6	34.4939
2164.49	36.2981
2167.38	37.9622
2170.26	38.7936
2173.14	40.6744
2176.03	40.538
2178.91	40.9794
2181.79	40.0437
2184.67	39.1274
2187.54	37.7026
2190.42	35.862
2193.3	33.7607
2196.17	32.7344
2199.05	29.7635
2201.92	26.7601
2204.79	24.486
2207.66	22.3633
2210.53	19.6379
2213.4	18.1712
2216.27	16.3969
2219.13	15.2188
2222	13.7418
2224.86	13.8951
2227.72	12.6223
2230.59	12.0893
2233.45	11.7953
2236.31	12.4207
2239.17	11.8061
2242.03	11.7151
2244.88	12.0764
2247.74	11.2162
2250.59	11.3676
2253.45	11.1274
2256.3	11.7519
2259.15	12.4062
2262	12.8802
2264.85	12.5195
2267.7	12.0784
2270.55	10.7966
2273.4	10.3672
2276.24	10.5058
2279.09	10.2716
2281.93	10.21
2284.77	8.81081
2287.61	8.30824
2290.46	7.43422
2293.29	6.58905
2296.13	6.45235
2298.97	6.21406
2301.81	6.30244
2304.64	7.94022
2307.48	8.07273
2310.31	7.66117
2313.14	8.77339
2315.97	8.21164
2318.8	8.45037
2321.63	8.87987
2324.46	8.81165
2327.29	7.53153
2330.12	6.36937
2332.94	6.32632
2335.76	6.84217
2338.59	6.8262
2341.41	6.60493
2344.23	7.07947
2347.05	6.62834
2349.87	5.81004
2352.69	4.35287
2355.5	3.70883
2358.32	4.01269
2361.14	2.95786
2363.95	3.43669
2366.76	6.39052
2369.58	7.00595
2372.39	5.78842
2375.2	7.00161
2378	6.75039
2380.81	6.26117
2383.62	5.11622
2386.42	3.5043
2389.23	3.05493
2392.03	2.85981
2394.84	1.5558
2397.64	0.632388
2400.44	2.19169
2403.24	3.13841
2406.04	3.55742
2408.83	3.84329
2411.63	3.83761
2414.43	4.16386
2417.22	4.09648
2420.02	4.83736
2422.81	5.92018
2425.6	6.95802
2428.39	7.34692
2431.18	6.77284
2433.97	7.77746
2436.76	6.81857
2439.54	5.94161
2442.33	6.00335
2445.11	5.69633
2447.9	3.71732
2450.68	2.41257
2453.46	1.80845
2456.24	1.8966
2459.02	1.28939
2461.8	-0.428529
2464.58	-0.58908
2467.36	-0.207002
2470.13	-0.40264
2472.91	0.0905877
2475.68	1.09785
2478.45	1.35248
2481.22	1.69416
2484	2.45838
2486.77	2.329
2489.54	3.09694
2492.3	3.72907
2495.07	3.89014
2497.84	4.54115
2500.6	5.68984
2503.36	4.2945
2506.13	5.25055
2508.89	6.20609
2511.65	6.67318
2514.41	6.70036
2517.17	8.26642
2519.93	9.56495
2522.68	9.88663
2525.44	10.4898
2528.19	10.9435
2530.95	11.8408
2533.7	12.7686
2536.45	12.7707
2539.2	12.6462
2541.95	13.2032
2544.7	12.7469
2547.45	11.7915
2550.2	10.751
2552.94	10.552
2555.69	9.71883
2558.43	9.73993
2561.17	9.00768
2563.92	8.613
2566.66	7.00097
2569.4	5.85286
2572.14	5.731
2574.88	6.39587
2577.61	4.92044
2580.35	4.29398
2583.09	4.27328
2585.82	3.78257
2588.55	2.8703
2591.28	2.82262
2594.02	2.94552
2596.75	3.81052
2599.48	4.40562
2602.2	4.77596
2604.93	5.02512
2607.66	4.66264
2610.38	6.01835
2613.11	6.7604
2615.83	7.71946
2618.56	7.24101
2621.28	8.33596
2624	8.32247
2626.72	9.5603
2629.44	9.32132
2632.15	8.83551
2634.87	9.71225
2637.59	10.0011
2640.3	9.33256
2643.02	9.19325
2645.73	8.7594
2648.44	8.64447
2651.15	8.12119
2653.86	8.81235
2656.57	9.13873
2659.28	8.77891
2661.99	8.95862
2664.69	9.84254
2667.4	10.769
2670.1	10.6521
2672.81	10.1734
2675.51	10.8088
2678.21	10.398
2680.91	10.6326
2683.61	10.2877
2686.31	11.0128
2689	11.4422
2691.7	9.98637
2694.4	10.291
2697.09	11.3567
2699.79	12.0137
2702.48	13.6798
2705.17	13.9625
2707.86	15.3863
2710.55	17.1898
2713.24	18.4125
2715.93	19.0557
2718.61	20.6478
2721.3	21.2472
2723.99	21.6117
2726.67	20.7859
2729.35	21.7842
2732.04	21.9023
2734.72	21.2247
2737.4	19.5868
2740.08	18.8267
2742.76	17.3145
2745.43	16.446
2748.11	15.5663
2750.79	13.4005
2753.46	11.6765
2756.13	9.22402
2758.81	8.12589
2761.48	6.40659
2764.15	4.50546
2766.82	3.31812
2769.49	2.75201
2772.16	2.31579
2774.82	2.62143
2777.49	1.23426
2780.16	0.178541
2782.82	0.0132013
2785.48	0.381445
2788.15	0.575372
2790.81	0.205575
2793.47	0.30881
2796.13	0.50892
2798.79	2.22954
2801.44	1.23267
2804.1	1.80473
2806.76	1.66018
2809.41	1.30489
2812.07	1.4995
2814.72	1.12883
2817.37	3.21373
2820.02	5.74928
2822.67	9.86045
2825.32	13.6989
2827.97	17.7373
2830.62	25.0377
2833.26	31.2018
2835.91	39.434
2838.55	48.1145
2841.2	58.0964
2843.84	71.2993
2846.48	84.0962
2849.12	99.5994
2851.76	114.145
2854.4	131.134
2857.04	147.18
2859.68	161.452
2862.32	174.987
2864.95	187.956
2867.58	198.088
2870.22	209.167
2872.85	217.761
2875.48	226.896
2878.11	235.001
2880.74	242.693
2883.37	248.895
2886	253.123
2888.63	259.699
2891.25	264.278
2893.88	270.874
2896.5	277.863
2899.13	285.952
2901.75	297.301
2904.37	309.891
2906.99	325.486
2909.61	341.048
2912.23	358.308
2914.85	376.129
2917.46	392.514
2920.08	407.993
2922.7	418.886
2925.31	427.344
2927.92	432.954
2930.53	434.453
2933.15	434.654
2935.76	430.957
2938.37	423.132
2940.98	414.19
2943.58	400.909
2946.19	386.127
2948.8	370.398
2951.4	354.439
2954.01	337.247
2956.61	319.339
2959.21	302.753
2961.81	286.558
2964.41	271.04
2967.01	257.319
2969.61	242.912
2972.21	229.931
2974.81	217.856
2977.4	206.958
2980	193.857
2982.59	179.288
2985.18	164.097
2987.78	149.021
2990.37	134.045
2992.96	119.895
2995.55	105.116
2998.14	91.8817
3000.72	77.7975
3003.31	65.8283
3005.9	54.9316
3008.48	44.7645
3011.07	36.6318
3013.65	28.0913
3016.23	20.4105
3018.81	14.4995
3021.39	10.5757
3023.97	7.13603
3026.55	4.29869
3029.13	1.65781
3031.71	0.189971
3034.28	-0.411063
3036.86	0.796488
3039.43	1.41825
3042.01	2.29085
3044.58	3.71823
3047.15	4.99935
3049.72	6.3455
3052.29	8.41096
3054.86	8.70744
3057.43	9.39581
3060	9.87968
3062.56	9.85275
3065.13	10.5859
3067.69	10.035
3070.25	9.50507
3072.82	8.43011
3075.38	7.09796
3077.94	5.89782
3080.5	5.76148
3083.06	4.31637
3085.62	2.58265
3088.17	0.988845
3090.73	0.144709
3093.29	-0.795073
3095.84	-0.481206
3098.4	-0.179501
3100.95	0.498397
3103.5	2.00481
3106.05	2.58777
3108.6	4.36665
3111.15	5.3059
3113.7	5.83418
3116.25	7.81561
3118.79	9.05817
3121.34	11.6817
3123.88	13.2799
3126.43	17.0406
3128.97	20.3358
3131.51	22.2539
3134.05	25.5601
3136.59	29.0379
3139.14	32.882
3141.67	37.0651
3144.21	41.0756
3146.75	45.9227
3149.28	53.2736