File: data/Raman/poly_smoothed/Mb_10_14_19_1x_45s_532 nm_x100_100%_600 gr_mm_01.txt
#Acq. time (s)=	45
#Accumulations=	2
#Range (cm-¹)=	200...3150
#Windows=	2
#Auto scanning=	Off
#Autofocus=	Off
#Macrospot=	Off
#AutoExposure=	Off
#Spike filter=	Multiple accum.
#Delay time (s)=	0
#Binning=	1
#Readout mode=	Signal
#DeNoise=	Off
#ICS correction=	On
#Dark correction=	Off
#Inst. Process=	Off
#Detector Gain=	Best Dynamic Range
#Detector ADC=	20 kHz
#Detector temperature (°C)=	-69.85
#Instrument=	LabRAM HR Evol
#Detector=	Synapse
#Objective=	x100
#Grating=	600 gr/mm
#ND Filter=	100%
#Laser (nm)=	532
#Hole=	100.021
#Range=	Auto
#Laser Pol.=	No
#Raman. Pol.=	No
#Laser Pol. (°)=	-0.0007625
#Raman Pol. (°)=	89.9995
#Collection=	Microscope
#StageXY=	Marzhauser
#StageZ=	Marzhauser
#X (µm)=	-622.7
#Y (µm)=	-1581.6
#Z (µm)=	89.85
#Full time(mm:ss)=	3:18
#Project=
#Sample=
#Site=
#Title=	Mb_10_14_19_2x_45s_532 nm_x100_100%_600 gr_mm
#Remark=
#Date=	11.07.2022 10:00
#Acquired=	11.07.2022 10:00:11
#Base:Fit=	10.08.2022 10:21:11
#Base:Sub=	10.08.2022 10:21:41
#Filter:Polynom=	16.08.2022 10:17:53
#AxisType[0]=Intens
#AxisUnit[0]=Cnt
#AxisType[1]=Spectr
#AxisUnit[1]=1/cm
200.388	7.56795
204.019	4.06537
207.646	1.17613
211.274	-0.34331
214.899	-1.41211
218.524	0.850759
222.146	5.61158
225.766	8.64263
229.388	9.73552
233.005	13.11
236.621	15.6955
240.236	17.771
243.852	19.9847
247.464	22.6608
251.074	25.8757
254.683	26.5929
258.291	26.7798
261.897	29.1038
265.504	29.378
269.108	29.4825
272.71	29.0132
276.311	28.86
279.91	26.9711
283.508	25.9541
287.105	24.2725
290.698	23.4268
294.291	23.4899
297.884	23.9417
301.475	24.2292
305.064	25.3798
308.652	25.608
312.237	25.6931
315.822	23.9983
319.406	22.8209
322.987	21.7253
326.568	18.8204
330.148	16.6078
333.724	16.1427
337.301	13.6547
340.875	12.7574
344.449	10.998
348.02	10.6703
351.592	9.77694
355.16	7.89621
358.728	8.29082
362.294	8.02831
365.858	10.5588
369.422	12.6373
372.983	14.5341
376.543	17.5991
380.102	21.7454
383.661	24.2064
387.216	28.7797
390.771	31.2309
394.324	32.8352
397.875	34.396
401.425	34.9072
404.974	34.2595
408.524	30.8927
412.07	28.6423
415.614	27.3634
419.156	26.5772
422.698	24.8051
426.238	22.4692
429.777	20.8111
433.315	18.7912
436.852	16.315
440.387	13.4159
443.919	12.2334
447.451	11.8722
450.982	11.6707
454.512	12.0263
458.038	11.6854
461.565	13.9112
465.091	15.6797
468.613	17.1496
472.136	18.1933
475.655	20.9561
479.176	22.183
482.692	22.3152
486.21	23.0808
489.724	23.4355
493.237	24.9645
496.75	24.9632
500.26	26.1485
503.769	26.9259
507.279	27.3382
510.785	28.1634
514.289	28.5454
517.793	28.0541
521.297	28.0347
524.797	26.7151
528.297	25.0653
531.795	26.0397
535.291	24.8335
538.787	23.3188
542.281	22.0066
545.773	20.6319
549.264	19.1573
552.754	17.3469
556.243	16.47
559.73	15.4855
563.216	13.3367
566.701	9.10806
570.182	9.28258
573.664	7.39771
577.145	6.46567
580.624	4.32115
584.1	4.37438
587.577	4.40315
591.052	4.90159
594.524	6.33155
597.997	6.57772
601.466	7.76924
604.936	8.73117
608.403	8.86546
611.87	9.53464
615.334	9.33737
618.799	10.9956
622.26	10.5964
625.72	11.1471
629.181	11.1323
632.638	12.4156
636.095	13.7169
639.551	12.4695
643.005	12.2737
646.457	11.1301
649.908	10.0994
653.357	11.2997
656.806	10.7861
660.253	11.4389
663.7	12.8019
667.145	14.0083
670.588	14.7549
674.027	15.5911
677.468	16.9757
680.907	18.0685
684.345	18.6163
687.781	19.777
691.216	19.4691
694.65	20.2381
698.081	20.8051
701.512	20.1901
704.942	20.3865
708.371	19.9631
711.796	20.5101
715.222	22.2932
718.645	22.0677
722.068	21.915
725.49	22.6118
728.909	23.3962
732.329	23.4894
735.745	26.2164
739.16	26.3578
742.576	28.0354
745.988	29.2094
749.401	31.8292
752.811	33.6057
756.22	36.1086
759.627	40.7339
763.035	42.473
766.44	46.8351
769.843	51.0255
773.245	53.5372
776.646	55.4582
780.046	57.7366
783.444	60.973
786.841	63.7078
790.237	67.2664
793.631	69.4451
797.024	73.1999
800.416	75.9541
803.807	76.7284
807.196	76.4665
810.584	76.1945
813.971	74.9703
817.354	74.6388
820.739	72.7124
824.122	72.2125
827.503	69.4821
830.882	67.6553
834.261	65.1062
837.637	64.665
841.013	62.6341
844.389	60.8304
847.761	57.5209
851.131	55.2623
854.503	51.4887
857.871	49.0287
861.24	47.5259
864.606	46.7831
867.97	45.3783
871.336	44.7929
874.698	45.0194
878.058	45.1406
881.418	44.9523
884.778	43.4495
888.135	42.9284
891.49	41.1537
894.845	40.7594
898.198	41.1585
901.55	41.3104
904.901	39.7021
908.25	38.1
911.598	37.4356
914.945	37.4928
918.291	38.3891
921.635	38.6632
924.978	37.1734
928.318	34.9568
931.659	35.1933
934.998	35.7112
938.336	35.6734
941.671	35.2765
945.007	34.1827
948.339	32.9034
951.672	32.6214
955.004	33.8865
958.333	32.9272
961.662	32.0099
964.989	32.3472
968.315	34.4087
971.639	35.2014
974.962	36.8621
978.285	37.5338
981.605	38.1912
984.924	37.5941
988.243	35.9481
991.56	34.8713
994.875	35.8001
998.188	37.188
1001.5	36.2737
1004.81	34.7789
1008.12	34.4246
1011.43	35.0604
1014.74	36.2597
1018.05	35.3412
1021.35	36.3907
1024.65	37.3078
1027.96	37.1077
1031.26	37.9079
1034.56	38.1868
1037.86	38.316
1041.16	37.5743
1044.45	40.1473
1047.75	41.6423
1051.04	41.3986
1054.33	39.019
1057.62	36.8059
1060.91	34.5102
1064.2	32.189
1067.49	29.0049
1070.77	25.5919
1074.06	23.5373
1077.34	22.8062
1080.62	19.3666
1083.91	15.9379
1087.18	14.8565
1090.46	15.1584
1093.74	15.026
1097.02	14.611
1100.29	15.1247
1103.56	16.2352
1106.84	15.5172
1110.11	14.9281
1113.38	14.7469
1116.64	15.0062
1119.91	15.6542
1123.18	16.657
1126.44	17.1122
1129.7	16.7539
1132.97	15.4658
1136.23	15.3536
1139.49	14.2509
1142.74	12.3465
1146	11.7379
1149.26	10.5454
1152.51	9.66112
1155.76	9.0298
1159.01	7.70515
1162.27	6.39313
1165.51	5.98147
1168.76	7.00633
1172.01	6.1092
1175.25	4.76023
1178.5	5.6368
1181.74	4.8232
1184.98	4.96511
1188.22	6.61722
1191.46	6.88196
1194.7	9.62415
1197.94	11.8756
1201.17	14.1397
1204.41	17.2321
1207.64	19.929
1210.87	23.8747
1214.1	27.0977
1217.33	29.9345
1220.56	30.7495
1223.79	33.074
1227.01	37.1213
1230.23	38.7318
1233.46	41.0865
1236.68	42.6187
1239.9	43.0677
1243.12	44.948
1246.34	46.7326
1249.55	46.7009
1252.77	46.6901
1255.98	47.7361
1259.2	47.896
1262.41	49.1419
1265.62	48.7318
1268.83	50.3432
1272.03	51.6024
1275.24	50.9677
1278.45	51.0237
1281.65	52.8221
1284.85	53.8685
1288.06	54.2469
1291.26	55.5484
1294.46	56.5794
1297.66	57.3139
1300.85	58.3415
1304.05	59.5233
1307.24	61.4261
1310.43	62.4153
1313.63	65.0161
1316.82	65.2218
1320.01	64.7782
1323.2	66.6262
1326.38	65.9413
1329.57	64.9571
1332.76	64.6085
1335.94	64.6056
1339.12	62.6077
1342.3	59.9342
1345.48	58.0806
1348.66	56.2256
1351.84	52.5923
1355.01	48.443
1358.19	45.5831
1361.36	43.4136
1364.53	41.3949
1367.71	39.2553
1370.88	39.7847
1374.04	39.0583
1377.21	38.3059
1380.38	36.7586
1383.54	37.3278
1386.71	38.0209
1389.87	36.9715
1393.03	37.6873
1396.19	37.1051
1399.35	38.8488
1402.51	40.2067
1405.67	41.8585
1408.82	43.9795
1411.98	44.6535
1415.13	46.3116
1418.28	48.3375
1421.43	52.2988
1424.58	56.1817
1427.73	59.0043
1430.88	62.8735
1434.02	67.5673
1437.17	71.2959
1440.31	73.6935
1443.45	76.0692
1446.6	77.188
1449.74	77.6658
1452.87	77.1356
1456.01	74.9455
1459.15	73.4239
1462.28	71.5128
1465.42	67.7395
1468.55	65.1013
1471.68	61.3027
1474.81	56.9634
1477.94	53.2271
1481.07	48.5841
1484.2	43.9011
1487.32	38.2521
1490.45	34.0252
1493.57	30.0864
1496.69	27.2446
1499.81	23.2566
1502.93	21.1094
1506.05	19.3494
1509.17	19.3469
1512.28	17.8582
1515.4	15.1648
1518.51	14.9902
1521.63	15.6255
1524.74	16.0732
1527.85	17.1715
1530.96	19.5368
1534.06	20.4267
1537.17	22.9324
1540.28	24.143
1543.38	25.3964
1546.48	27.3564
1549.59	29.5798
1552.69	31.319
1555.79	33.8143
1558.88	34.9923
1561.98	35.9406
1565.08	36.8357
1568.17	37.9413
1571.27	38.5659
1574.36	38.9054
1577.45	40.5042
1580.54	40.6483
1583.63	41.9354
1586.72	43.0969
1589.8	43.3984
1592.89	44.8054
1595.97	45.0574
1599.06	45.2771
1602.14	46.1082
1605.22	46.6292
1608.3	46.1714
1611.38	46.0708
1614.46	44.9389
1617.53	44.2734
1620.61	44.3521
1623.68	45.7525
1626.75	46.6226
1629.82	48.6374
1632.9	49.2042
1635.96	51.0431
1639.03	53.1989
1642.1	55.1367
1645.16	57.3019
1648.23	58.3688
1651.29	61.4951
1654.36	61.3483
1657.42	61.8852
1660.48	60.6576
1663.53	59.3862
1666.59	58.4727
1669.65	55.5748
1672.7	51.8569
1675.76	48.9215
1678.81	46.4725
1681.86	42.9903
1684.91	36.8663
1687.96	31.8544
1691.01	28.156
1694.06	22.8954
1697.11	18.5708
1700.15	15.1759
1703.2	12.8215
1706.24	10.7199
1709.28	7.94598
1712.32	6.03088
1715.36	4.5337
1718.4	6.27171
1721.43	6.03884
1724.47	5.80909
1727.5	5.83885
1730.54	5.79469
1733.57	4.90944
1736.6	5.37
1739.63	5.14798
1742.66	4.19835
1745.69	3.72454
1748.72	4.50554
1751.74	5.23432
1754.77	5.06098
1757.79	4.2229
1760.81	3.55291
1763.83	2.94399
1766.85	2.79823
1769.87	1.48332
1772.89	1.15085
1775.91	2.01892
1778.92	1.93734
1781.94	0.61839
1784.95	1.54523
1787.96	1.7568
1790.97	3.07532
1793.98	2.90593
1796.99	3.07354
1800	4.01965
1803	3.73702
1806.01	4.17684
1809.01	5.12648
1812.02	4.5828
1815.02	4.15929
1818.02	4.00606
1821.02	3.85625
1824.02	3.86485
1827.01	3.61129
1830.01	3.15143
1833	3.17829
1836	2.65007
1838.99	3.00512
1841.98	3.39291
1844.97	3.34628
1847.96	4.12234
1850.95	3.61338
1853.94	2.94961
1856.92	2.0425
1859.91	1.76309
1862.89	1.78492
1865.88	3.15378
1868.86	3.39531
1871.84	3.11378
1874.82	3.10945
1877.8	3.69713
1880.77	3.1556
1882.52	3.08421
1885.51	2.58006
1888.5	3.2449
1891.49	2.77116
1894.47	3.57859
1897.46	4.0263
1900.44	4.06059
1903.42	3.80747
1906.4	3.85308
1909.38	4.06448
1912.36	3.99746
1915.34	4.57487
1918.32	5.16435
1921.29	4.40725
1924.27	3.8227
1927.24	4.96746
1930.21	4.70814
1933.18	5.07493
1936.15	5.7422
1939.12	4.79379
1942.09	3.5879
1945.06	3.53282
1948.02	3.28645
1950.99	3.53249
1953.95	3.59962
1956.91	4.8809
1959.87	4.83168
1962.84	4.69996
1965.79	5.49254
1968.75	5.89445
1971.71	5.42754
1974.66	6.33523
1977.62	6.65184
1980.57	7.2131
1983.53	7.9743
1986.48	9.91034
1989.43	10.9948
1992.38	11.0898
1995.33	12.5672
1998.27	13.0441
2001.22	12.5881
2004.16	12.0198
2007.11	11.9113
2010.05	11.4777
2012.99	11.5029
2015.93	11.5413
2018.87	11.8402
2021.81	12.6466
2024.75	11.7242
2027.69	11.8135
2030.62	11.5828
2033.56	11.3662
2036.49	11.65
2039.42	11.0448
2042.35	10.5214
2045.28	10.5038
2048.21	8.99463
2051.14	7.92975
2054.06	6.43849
2056.99	6.87838
2059.92	6.98427
2062.84	7.07798
2065.76	7.17239
2068.68	6.6808
2071.6	6.01462
2074.52	6.27144
2077.44	6.91196
2080.36	7.51779
2083.27	7.83824
2086.19	9.08721
2089.1	9.12939
2092.01	10.3815
2094.93	10.1537
2097.84	10.6956
2100.75	11.2659
2103.66	12.3527
2106.56	11.9677
2109.47	12.0803
2112.37	12.6787
2115.28	12.184
2118.18	12.4857
2121.09	12.9135
2123.99	14.2035
2126.89	14.9585
2129.79	16.4009
2132.68	16.8967
2135.58	18.3568
2138.48	19.1362
2141.37	20.1841
2144.26	21.7186
2147.16	22.7787
2150.05	23.5228
2152.94	25.112
2155.83	25.2971
2158.72	26.0773
2161.6	27.5096
2164.49	28.0466
2167.38	28.2095
2170.26	29.5955
2173.14	30.388
2176.03	31.0368
2178.91	31.7718
2181.79	32.2986
2184.67	32.7644
2187.54	32.9196
2190.42	31.9126
2193.3	29.7975
2196.17	27.3793
2199.05	25.9292
2201.92	24.569
2204.79	22.5618
2207.66	21.6727
2210.53	20.3268
2213.4	18.5187
2216.27	16.7026
2219.13	15.8258
2222	14.9144
2224.86	14.4789
2227.72	14.3812
2230.59	14.5038
2233.45	13.9097
2236.31	13.1335
2239.17	12.8298
2242.03	13.6359
2244.88	14.4292
2247.74	15.4359
2250.59	15.2984
2253.45	14.9242
2256.3	14.1958
2259.15	12.2783
2262	10.2907
2264.85	9.45246
2267.7	9.81646
2270.55	8.91163
2273.4	8.29622
2276.24	7.75168
2279.09	8.05522
2281.93	8.31765
2284.77	8.33963
2287.61	8.04129
2290.46	8.5853
2293.29	7.40351
2296.13	8.83124
2298.97	9.6243
2301.81	9.68992
2304.64	10.0587
2307.48	11.7858
2310.31	12.7816
2313.14	13.8107
2315.97	13.6152
2318.8	13.9843
2321.63	13.7447
2324.46	13.5838
2327.29	12.7757
2330.12	11.2936
2332.94	12.1792
2335.76	11.9387
2338.59	10.0877
2341.41	9.49617
2344.23	9.69403
2347.05	9.89006
2349.87	8.6804
2352.69	7.36002
2355.5	7.3849
2358.32	6.65085
2361.14	5.95554
2363.95	5.50814
2366.76	6.64372
2369.58	6.58949
2372.39	5.51081
2375.2	5.34912
2378	5.49445
2380.81	4.59272
2383.62	4.04389
2386.42	5.02833
2389.23	5.06043
2392.03	5.22029
2394.84	4.29066
2397.64	4.07047
2400.44	4.37595
2403.24	4.80392
2406.04	4.16868
2408.83	5.22619
2411.63	6.24929
2414.43	7.1484
2417.22	7.50777
2420.02	7.05742
2422.81	6.73016
2425.6	7.29573
2428.39	6.50365
2431.18	5.76569
2433.97	5.52245
2436.76	4.92862
2439.54	2.95994
2442.33	2.6189
2445.11	1.29374
2447.9	1.07737
2450.68	0.10729
2453.46	0.958248
2456.24	0.28319
2459.02	0.210231
2461.8	-0.681269
2464.58	-0.555585
2467.36	0.651627
2470.13	1.36859
2472.91	2.01513
2475.68	1.90555
2478.45	2.41203
2481.22	2.83836
2484	4.82314
2486.77	3.97645
2489.54	3.64189
2492.3	3.12892
2495.07	3.29998
2497.84	2.16865
2500.6	3.09767
2503.36	2.83167
2506.13	1.84355
2508.89	1.1792
2511.65	0.926234
2514.41	0.741723
2517.17	1.52741
2519.93	1.72072
2522.68	2.38498
2525.44	2.54383
2528.19	2.70743
2530.95	3.38047
2533.7	4.78958
2536.45	6.14633
2539.2	6.21596
2541.95	6.34753
2544.7	6.55637
2547.45	8.12754
2550.2	8.47691
2552.94	8.51861
2555.69	7.59473
2558.43	6.66029
2561.17	7.82093
2563.92	7.68066
2566.66	7.74313
2569.4	7.73032
2572.14	7.26556
2574.88	7.00394
2577.61	6.25092
2580.35	5.8699
2583.09	5.73157
2585.82	6.03535
2588.55	5.85168
2591.28	5.69393
2594.02	5.17861
2596.75	4.8798
2599.48	5.24069
2602.2	5.35794
2604.93	4.66008
2607.66	3.983
2610.38	3.77109
2613.11	3.16801
2615.83	3.12005
2618.56	2.16197
2621.28	1.74596
2624	1.44367
2626.72	2.07417
2629.44	2.74723
2632.15	2.73747
2634.87	3.67605
2637.59	3.92704
2640.3	4.54024
2643.02	4.50674
2645.73	5.2399
2648.44	6.36933
2651.15	6.71142
2653.86	6.49473
2656.57	6.37393
2659.28	5.90284
2661.99	5.66479
2664.69	6.05148
2667.4	6.08267
2670.1	4.50491
2672.81	4.17117
2675.51	4.34922
2678.21	3.91165
2680.91	3.6308
2683.61	3.04129
2686.31	2.44177
2689	3.32164
2691.7	3.87726
2694.4	4.23153
2697.09	4.22522
2699.79	4.90568
2702.48	4.61533
2705.17	5.17358
2707.86	5.69792
2710.55	6.16423
2713.24	6.85055
2715.93	6.1688
2718.61	6.47325
2721.3	6.73202
2723.99	7.73701
2726.67	7.85331
2729.35	8.12076
2732.04	7.97387
2734.72	8.04941
2737.4	8.37165
2740.08	8.49721
2742.76	8.6876
2745.43	8.36636
2748.11	8.54938
2750.79	8.45884
2753.46	9.09514
2756.13	8.69162
2758.81	7.67032
2761.48	7.8761
2764.15	7.1891
2766.82	7.26528
2769.49	7.42549
2772.16	6.0609
2774.82	4.38101
2777.49	4.3115
2780.16	3.08286
2782.82	2.70913
2785.48	2.08312
2788.15	1.9419
2790.81	1.22
2793.47	0.410137
2796.13	-0.0679204
2798.79	-0.0515706
2801.44	-0.395365
2804.1	-0.968715
2806.76	-1.33619
2809.41	-1.51416
2812.07	-1.17663
2814.72	-1.32711
2817.37	-0.302622
2820.02	1.15138
2822.67	2.42871
2825.32	5.07395
2827.97	7.16359
2830.62	8.59247
2833.26	11.1889
2835.91	13.8168
2838.55	17.1726
2841.2	22.327
2843.84	28.6504
2846.48	34.2092
2849.12	40.9345
2851.76	49.3067
2854.4	57.167
2857.04	64.3959
2859.68	71.8284
2862.32	78.5468
2864.95	85.8974
2867.58	91.6919
2870.22	97.2631
2872.85	103.004
2875.48	107.773
2878.11	112.234
2880.74	116.32
2883.37	120.546
2886	123.686
2888.63	126.547
2891.25	129.377
2893.88	132.919
2896.5	138.276
2899.13	143.808
2901.75	150.655
2904.37	158.841
2906.99	168.659
2909.61	177.311
2912.23	186.872
2914.85	197.214
2917.46	206.524
2920.08	213.041
2922.7	219.776
2925.31	224.971
2927.92	227.511
2930.53	228.935
2933.15	229.072
2935.76	227.992
2938.37	224.293
2940.98	218.827
2943.58	213.168
2946.19	205.879
2948.8	198.656
2951.4	189.791
2954.01	181.223
2956.61	172.248
2959.21	165.192
2961.81	157.134
2964.41	149.959
2967.01	142.947
2969.61	136.729
2972.21	129.013
2974.81	121.747
2977.4	115.819
2980	108.27
2982.59	101.523
2985.18	93.9983
2987.78	85.6034
2990.37	77.3699
2992.96	69.8489
2995.55	62.6738
2998.14	54.8546
3000.72	48.855
3003.31	42.0857
3005.9	35.0877
3008.48	29.402
3011.07	24.2077
3013.65	19.3501
3016.23	14.3219
3018.81	11.5048
3021.39	9.07269
3023.97	7.3269
3026.55	5.07504
3029.13	4.25541
3031.71	3.63127
3034.28	3.44596
3036.86	2.51399
3039.43	3.60149
3042.01	3.74929
3044.58	4.77318
3047.15	5.74585
3049.72	6.42466
3052.29	6.70708
3054.86	7.71999
3057.43	7.81559
3060	8.54094
3062.56	9.13993
3065.13	9.07519
3067.69	7.821
3070.25	7.14925
3072.82	7.14358
3075.38	6.92548
3077.94	5.97541
3080.5	4.69785
3083.06	3.60724
3085.62	2.4869
3088.17	2.0594
3090.73	2.05746
3093.29	1.61802
3095.84	0.710773
3098.4	0.208893
3100.95	-0.196925
3103.5	-0.344159
3106.05	0.343712
3108.6	1.14653
3111.15	1.74904
3113.7	1.90408
3116.25	2.34518
3118.79	2.98103
3121.34	4.08223
3123.88	4.99889
3126.43	5.64884
3128.97	6.20177
3131.51	7.64487
3134.05	8.49636
3136.59	8.81948
3139.14	8.71501
3141.67	9.02393
3144.21	9.37765
3146.75	9.39078
3149.28	9.68437