File: data/Raman/poly_smoothed/Mb_10_14_38_1x_45s_532 nm_x100_100%_600 gr_mm_01.txt
#Acq. time (s)=	45
#Accumulations=	2
#Range (cm-¹)=	200...3150
#Windows=	2
#Auto scanning=	Off
#Autofocus=	Off
#Macrospot=	Off
#AutoExposure=	Off
#Spike filter=	Multiple accum.
#Delay time (s)=	0
#Binning=	1
#Readout mode=	Signal
#DeNoise=	Off
#ICS correction=	On
#Dark correction=	Off
#Inst. Process=	Off
#Detector Gain=	Best Dynamic Range
#Detector ADC=	20 kHz
#Detector temperature (°C)=	-69.85
#Instrument=	LabRAM HR Evol
#Detector=	Synapse
#Objective=	x100
#Grating=	600 gr/mm
#ND Filter=	100%
#Laser (nm)=	532
#Hole=	100.021
#Range=	Auto
#Laser Pol.=	No
#Raman. Pol.=	No
#Laser Pol. (°)=	-0.0007625
#Raman Pol. (°)=	89.9995
#Collection=	Microscope
#StageXY=	Marzhauser
#StageZ=	Marzhauser
#X (µm)=	-626.5
#Y (µm)=	-1673.8
#Z (µm)=	89.55
#Full time(mm:ss)=	3:18
#Project=
#Sample=
#Site=
#Title=	Mb_10_14_38_2x_45s_532 nm_x100_100%_600 gr_mm
#Remark=
#Date=	11.07.2022 11:26
#Acquired=	11.07.2022 11:26:15
#Edit:Spike=	11.07.2022 11:29:30
#Base:Fit=	10.08.2022 10:21:11
#Base:Sub=	10.08.2022 10:21:41
#Filter:Polynom=	16.08.2022 10:17:53
#AxisType[0]=Intens
#AxisUnit[0]=Cnt
#AxisType[1]=Spectr
#AxisUnit[1]=1/cm
200.388	21.6473
204.019	15.1964
207.646	9.06949
211.274	4.72296
214.899	3.21883
218.524	4.78933
222.146	7.10226
225.766	9.97349
229.388	13.0686
233.005	18.5677
236.621	23.0105
240.236	26.4624
243.852	30.125
247.464	32.9675
251.074	36.2694
254.683	37.8337
258.291	39.5497
261.897	40.2156
265.504	39.8985
269.108	38.6619
272.71	39.4596
276.311	38.0987
279.91	34.4374
283.508	30.4358
287.105	28.1664
290.698	25.0839
294.291	22.4765
297.884	20.1261
301.475	17.5848
305.064	15.4233
308.652	13.8562
312.237	12.1732
315.822	12.7044
319.406	11.7659
322.987	10.2908
326.568	9.20518
330.148	10.0164
333.724	8.71791
337.301	6.77778
340.875	5.8584
344.449	7.71006
348.02	12.0976
351.592	15.5667
355.16	20.846
358.728	28.2878
362.294	32.7354
365.858	39.5386
369.422	43.9085
372.983	48.964
376.543	53.7956
380.102	57.8109
383.661	61.0233
387.216	62.0355
390.771	65.1695
394.324	66.4583
397.875	66.4668
401.425	65.5865
404.974	61.8055
408.524	56.9283
412.07	52.7373
415.614	49.787
419.156	45.9664
422.698	42.0538
426.238	38.4428
429.777	36.8915
433.315	35.1177
436.852	32.5026
440.387	30.3301
443.919	26.9261
447.451	23.8927
450.982	21.4947
454.512	21.09
458.038	19.5747
461.565	19.0408
465.091	20.8144
468.613	22.8151
472.136	22.6733
475.655	22.3706
479.176	23.412
482.692	24.8908
486.21	26.5317
489.724	27.7599
493.237	30.6103
496.75	33.1466
500.26	36.6033
503.769	40.7557
507.279	45.6613
510.785	50.3425
514.289	51.5407
517.793	52.7
521.297	52.0274
524.797	50.7196
528.297	50.5891
531.795	50.0416
535.291	50.029
538.787	47.5152
542.281	47.1672
545.773	43.9591
549.264	42.9583
552.754	39.8741
556.243	34.7136
559.73	29.8158
563.216	27.3228
566.701	24.3964
570.182	18.6783
573.664	14.8503
577.145	11.2084
580.624	10.8682
584.1	10.329
587.577	9.26819
591.052	11.1268
594.524	11.558
597.997	9.97284
601.466	9.51093
604.936	12.3694
608.403	12.8647
611.87	16.741
615.334	18.6236
618.799	22.1547
622.26	23.7202
625.72	25.7307
629.181	27.3818
632.638	29.9674
636.095	31.0362
639.551	29.1738
643.005	29.7491
646.457	28.7507
649.908	27.8044
653.357	25.266
656.806	23.4645
660.253	23.0978
663.7	23.4107
667.145	22.6399
670.588	21.1831
674.027	21.5437
677.468	21.4988
680.907	20.5343
684.345	20.4435
687.781	21.7077
691.216	23.6195
694.65	24.3467
698.081	25.4429
701.512	26.2111
704.942	27.1465
708.371	27.8663
711.796	28.4518
715.222	30.1837
718.645	30.8712
722.068	32.6759
725.49	33.6139
728.909	35.2028
732.329	36.658
735.745	35.6529
739.16	36.9663
742.576	36.693
745.988	37.7125
749.401	38.6926
752.811	41.3729
756.22	42.6361
759.627	43.8615
763.035	44.8363
766.44	47.3304
769.843	48.6723
773.245	50.4876
776.646	52.0524
780.046	53.6746
783.444	56.4277
786.841	60.3969
790.237	63.3723
793.631	66.8567
797.024	69.6204
800.416	70.3337
803.807	73.7768
807.196	75.0565
810.584	76.3223
813.971	76.41
817.354	75.3461
820.739	74.0126
824.122	72.6002
827.503	71.2441
830.882	70.5806
834.261	70.245
837.637	68.8644
841.013	67.8234
844.389	65.7115
847.761	64.4286
851.131	62.5369
854.503	58.0215
857.871	55.3422
861.24	54.5094
864.606	53.5603
867.97	51.6794
871.336	50.1502
874.698	48.0886
878.058	46.4794
881.418	44.0814
884.778	43.9257
888.135	41.8155
891.49	40.6614
894.845	38.7611
898.198	38.5924
901.55	38.7756
904.901	39.2474
908.25	37.6979
911.598	38.8947
914.945	39.7369
918.291	40.1792
921.635	41.4178
924.978	41.6464
928.318	40.9243
931.659	40.9493
934.998	39.6588
938.336	39.304
941.671	39.0781
945.007	37.9057
948.339	37.6255
951.672	37.8062
955.004	38.6882
958.333	38.2074
961.662	37.2528
964.989	39.3992
968.315	42.2932
971.639	45.6645
974.962	47.8855
978.285	50.6424
981.605	50.5682
984.924	49.8861
988.243	50.2003
991.56	50.6106
994.875	51.7685
998.188	52.9439
1001.5	54.0238
1004.81	56.2754
1008.12	56.2956
1011.43	58.6873
1014.74	62.1773
1018.05	66.134
1021.35	67.2886
1024.65	70.6156
1027.96	74.3932
1031.26	73.6561
1034.56	75.5476
1037.86	73.7711
1041.16	72.2602
1044.45	72.3078
1047.75	70.9999
1051.04	67.1857
1054.33	61.7544
1057.62	55.4307
1060.91	48.7829
1064.2	42.2156
1067.49	37.3678
1070.77	32.5176
1074.06	26.6338
1077.34	23.5739
1080.62	20.1413
1083.91	18.459
1087.18	15.9554
1090.46	15.2439
1093.74	19.2424
1097.02	19.0659
1100.29	20.3035
1103.56	20.1104
1106.84	19.9592
1110.11	19.3201
1113.38	17.7912
1116.64	16.8292
1119.91	15.6133
1123.18	14.3987
1126.44	12.2158
1129.7	11.9309
1132.97	11.2181
1136.23	9.87139
1139.49	10.0191
1142.74	11.2927
1146	13.0575
1149.26	11.6391
1152.51	10.3587
1155.76	10.5064
1159.01	9.64058
1162.27	8.66517
1165.51	8.61047
1168.76	6.77272
1172.01	8.2033
1175.25	9.04734
1178.5	8.70554
1181.74	11.0246
1184.98	10.8737
1188.22	12.4989
1191.46	13.6795
1194.7	15.7568
1197.94	18.5521
1201.17	22.3269
1204.41	26.3802
1207.64	30.8289
1210.87	33.7244
1214.1	39.122
1217.33	44.2163
1220.56	48.3985
1223.79	54.8543
1227.01	56.9251
1230.23	59.7475
1233.46	61.6159
1236.68	64.74
1239.9	67.1646
1243.12	69.5532
1246.34	69.7409
1249.55	72.148
1252.77	74.5609
1255.98	74.954
1259.2	77.7172
1262.41	78.7603
1265.62	79.7204
1268.83	82.0836
1272.03	82.5387
1275.24	83.6352
1278.45	84.984
1281.65	86.7791
1284.85	88.1841
1288.06	88.6468
1291.26	90.7805
1294.46	92.0958
1297.66	90.7971
1300.85	92.2449
1304.05	92.9554
1307.24	95.7254
1310.43	99.9885
1313.63	102.248
1316.82	104.524
1320.01	107.077
1323.2	109.728
1326.38	108.698
1329.57	110.974
1332.76	111.856
1335.94	110.648
1339.12	110.826
1342.3	107.276
1345.48	104.827
1348.66	103.315
1351.84	100.196
1355.01	97.8294
1358.19	93.4804
1361.36	90.5291
1364.53	84.3033
1367.71	79.6218
1370.88	74.2775
1374.04	69.3254
1377.21	66.8585
1380.38	65.773
1383.54	64.0832
1386.71	63.8633
1389.87	63.7379
1393.03	62.8926
1396.19	62.4694
1399.35	62.6249
1402.51	62.468
1405.67	64.3124
1408.82	65.3361
1411.98	66.8437
1415.13	72.1678
1418.28	77.8828
1421.43	84.6138
1424.58	93.7785
1427.73	103.417
1430.88	112.035
1434.02	119.689
1437.17	126.658
1440.31	133.566
1443.45	137.839
1446.6	140.877
1449.74	141.719
1452.87	142.3
1456.01	142.552
1459.15	140.113
1462.28	138.108
1465.42	133.821
1468.55	127.817
1471.68	122.039
1474.81	113.751
1477.94	106.057
1481.07	98.8353
1484.2	92.2069
1487.32	86.1853
1490.45	79.512
1493.57	74.3633
1496.69	68.6231
1499.81	66.7067
1502.93	63.5539
1506.05	60.4288
1509.17	57.6849
1512.28	54.6264
1515.4	51.1786
1518.51	48.0662
1521.63	43.9023
1524.74	40.6392
1527.85	40.0523
1530.96	40.6455
1534.06	42.1633
1537.17	41.6158
1540.28	42.1769
1543.38	43.5672
1546.48	45.9801
1549.59	48.289
1552.69	51.9386
1555.79	55.173
1558.88	57.4495
1561.98	58.482
1565.08	58.4841
1568.17	59.7821
1571.27	65.1898
1574.36	67.2069
1577.45	71.8481
1580.54	74.6682
1583.63	78.2067
1586.72	81.102
1589.8	82.5017
1592.89	85.0799
1595.97	87.5634
1599.06	89.7542
1602.14	91.5979
1605.22	93.0645
1608.3	91.7402
1611.38	91.0253
1614.46	91.7583
1617.53	92.599
1620.61	93.8945
1623.68	94.3068
1626.75	96.909
1629.82	99.1364
1632.9	98.9951
1635.96	100.241
1639.03	101.167
1642.1	103.574
1645.16	106.985
1648.23	108.898
1651.29	110.567
1654.36	112.334
1657.42	113.161
1660.48	112.876
1663.53	111.432
1666.59	109.714
1669.65	105.872
1672.7	101.941
1675.76	96.6082
1678.81	89.6172
1681.86	80.6526
1684.91	73.3263
1687.96	66.481
1691.01	58.8133
1694.06	52.6608
1697.11	46.5963
1700.15	41.159
1703.2	36.4237
1706.24	32.6681
1709.28	28.333
1712.32	24.7609
1715.36	21.7581
1718.4	19.158
1721.43	17.7249
1724.47	17.3818
1727.5	14.8252
1730.54	12.7843
1733.57	11.2258
1736.6	10.1703
1739.63	9.29281
1742.66	9.02603
1745.69	8.60803
1748.72	7.60847
1751.74	6.6224
1754.77	5.92417
1757.79	4.04668
1760.81	4.0487
1763.83	2.86689
1766.85	3.49975
1769.87	3.42332
1772.89	3.66839
1775.91	4.26029
1778.92	4.23988
1781.94	3.74432
1784.95	2.87292
1787.96	2.93993
1790.97	3.03364
1793.98	2.65853
1796.99	2.96012
1800	2.63031
1803	1.72724
1806.01	1.30167
1809.01	1.50804
1812.02	1.99269
1815.02	2.1947
1818.02	2.34065
1821.02	1.77476
1824.02	0.856383
1827.01	1.0428
1830.01	0.890001
1833	0.010819
1836	0.382196
1838.99	-0.43954
1841.98	0.194748
1844.97	0.15964
1847.96	0.483759
1850.95	0.848708
1853.94	1.43799
1856.92	2.65384
1859.91	4.80162
1862.89	4.79455
1865.88	4.81721
1868.86	6.8819
1871.84	7.36125
1874.82	5.55681
1877.8	5.55368
1880.77	6.89838
1882.52	6.38155
1885.51	6.23239
1888.5	6.78778
1891.49	6.71173
1894.47	6.40806
1897.46	5.71911
1900.44	5.7138
1903.42	2.89535
1906.4	2.33784
1909.38	2.50459
1912.36	3.49173
1915.34	3.97125
1918.32	3.95545
1921.29	4.16738
1924.27	4.67164
1927.24	5.24173
1930.21	5.56307
1933.18	4.40205
1936.15	3.5515
1939.12	4.01705
1942.09	4.54264
1945.06	4.89156
1948.02	5.46817
1950.99	6.30497
1953.95	5.96692
1956.91	7.29767
1959.87	7.23461
1962.84	7.3054
1965.79	5.88307
1968.75	5.6101
1971.71	5.82475
1974.66	5.14215
1977.62	6.02733
1980.57	7.71453
1983.53	8.45562
1986.48	7.14499
1989.43	7.13867
1992.38	6.6504
1995.33	7.01478
1998.27	5.38503
2001.22	6.25426
2004.16	6.62506
2007.11	5.04576
2010.05	6.2534
2012.99	6.34967
2015.93	5.63952
2018.87	5.82856
2021.81	4.14322
2024.75	3.33679
2027.69	3.8959
2030.62	3.96205
2033.56	3.66539
2036.49	2.51188
2039.42	2.86346
2042.35	4.69905
2045.28	5.08949
2048.21	7.18789
2051.14	8.36457
2054.06	9.36174
2056.99	8.94971
2059.92	10.4496
2062.84	12.0508
2065.76	11.7195
2068.68	13.112
2071.6	12.8849
2074.52	13.8489
2077.44	11.7828
2080.36	10.8263
2083.27	11.0535
2086.19	9.5697
2089.1	9.75003
2092.01	9.17999
2094.93	8.35889
2097.84	7.58088
2100.75	9.11485
2103.66	8.97916
2106.56	7.46342
2109.47	8.38493
2112.37	8.97031
2115.28	11.1394
2118.18	11.6317
2121.09	12.2708
2123.99	13.5139
2126.89	15.2554
2129.79	17.4164
2132.68	19.2477
2135.58	21.0441
2138.48	21.6112
2141.37	23.0258
2144.26	23.9695
2147.16	24.0319
2150.05	25.4026
2152.94	28.1567
2155.83	29.3007
2158.72	30.8456
2161.6	33.463
2164.49	33.7461
2167.38	36.0634
2170.26	39.0039
2173.14	41.9969
2176.03	42.9155
2178.91	42.9286
2181.79	43.8429
2184.67	43.4249
2187.54	43.4148
2190.42	43.1306
2193.3	40.3831
2196.17	37.8889
2199.05	36.5999
2201.92	34.1128
2204.79	30.7413
2207.66	27.7493
2210.53	23.7492
2213.4	19.871
2216.27	16.0059
2219.13	13.4844
2222	12.1557
2224.86	12.1476
2227.72	9.88562
2230.59	9.4834
2233.45	10.131
2236.31	12.1153
2239.17	13.5178
2242.03	13.7593
2244.88	13.9298
2247.74	14.4648
2250.59	15.7661
2253.45	14.3691
2256.3	13.4341
2259.15	13.8919
2262	12.1733
2264.85	11.168
2267.7	11.3849
2270.55	10.7388
2273.4	10.2818
2276.24	8.12806
2279.09	8.47063
2281.93	7.30173
2284.77	7.71792
2287.61	6.2266
2290.46	7.08699
2293.29	6.31705
2296.13	5.96983
2298.97	6.45188
2301.81	7.35075
2304.64	8.42148
2307.48	8.71036
2310.31	7.9675
2313.14	8.27577
2315.97	8.58083
2318.8	8.21277
2321.63	7.51116
2324.46	6.22876
2327.29	7.80157
2330.12	6.30547
2332.94	6.45004
2335.76	6.12114
2338.59	6.45482
2341.41	6.13512
2344.23	6.91709
2347.05	6.26396
2349.87	7.12745
2352.69	5.00566
2355.5	3.38963
2358.32	2.78221
2361.14	2.71667
2363.95	2.10484
2366.76	2.01337
2369.58	1.37023
2372.39	-0.416634
2375.2	-1.7432
2378	-2.0208
2380.81	-2.18539
2383.62	-0.608131
2386.42	-0.90032
2389.23	-0.350491
2392.03	0.352547
2394.84	1.6679
2397.64	1.72614
2400.44	1.93365
2403.24	4.05887
2406.04	3.9791
2408.83	4.06877
2411.63	5.54691
2414.43	5.23408
2417.22	6.86091
2420.02	7.50598
2422.81	7.27399
2425.6	7.93734
2428.39	7.4377
2431.18	8.17642
2433.97	8.2226
2436.76	6.55783
2439.54	4.76974
2442.33	4.84611
2445.11	5.25322
2447.9	5.40924
2450.68	5.19814
2453.46	5.32146
2456.24	5.49739
2459.02	5.94459
2461.8	5.98672
2464.58	5.76692
2467.36	6.45303
2470.13	6.2698
2472.91	5.3844
2475.68	5.61947
2478.45	5.75763
2481.22	6.15786
2484	5.95769
2486.77	4.77611
2489.54	5.04799
2492.3	4.47299
2495.07	3.42506
2497.84	2.81617
2500.6	1.57693
2503.36	-0.355918
2506.13	-0.351626
2508.89	-0.456556
2511.65	-1.12367
2514.41	-0.0811445
2517.17	-1.26813
2519.93	-0.0346834
2522.68	0.857455
2525.44	1.24896
2528.19	1.8842
2530.95	1.64494
2533.7	2.77611
2536.45	3.16247
2539.2	4.14055
2541.95	5.71963
2544.7	6.42535
2547.45	6.58182
2550.2	6.31522
2552.94	7.12238
2555.69	8.49259
2558.43	9.19217
2561.17	9.51766
2563.92	9.18062
2566.66	9.46624
2569.4	12.2882
2572.14	12.4585
2574.88	13.6653
2577.61	13.191
2580.35	14.0104
2583.09	13.252
2585.82	10.6524
2588.55	10.661
2591.28	10.5907
2594.02	9.68516
2596.75	9.64409
2599.48	8.04117
2602.2	8.61402
2604.93	9.03284
2607.66	9.77787
2610.38	9.72528
2613.11	8.93955
2615.83	8.48064
2618.56	9.35412
2621.28	10.5937
2624	11.8906
2626.72	12.8114
2629.44	13.9375
2632.15	14.2793
2634.87	16.4518
2637.59	16.9781
2640.3	16.7451
2643.02	17.065
2645.73	15.395
2648.44	15.278
2651.15	13.0148
2653.86	11.7081
2656.57	11.9757
2659.28	11.6735
2661.99	12.8022
2664.69	12.9054
2667.4	11.2335
2670.1	13.1293
2672.81	14.1182
2675.51	13.6093
2678.21	13.6797
2680.91	14.2782
2683.61	15.4178
2686.31	14.7128
2689	16.833
2691.7	18.3422
2694.4	18.3056
2697.09	18.3551
2699.79	19.9556
2702.48	21.877
2705.17	22.7076
2707.86	22.1055
2710.55	21.189
2713.24	20.3814
2715.93	18.8915
2718.61	18.8209
2721.3	19.3605
2723.99	19.1294
2726.67	19.4066
2729.35	18.3948
2732.04	16.691
2734.72	16.6689
2737.4	14.4319
2740.08	13.8279
2742.76	14.4537
2745.43	14.3864
2748.11	13.0657
2750.79	12.3218
2753.46	11.6168
2756.13	11.9106
2758.81	11.4566
2761.48	12.4411
2764.15	13.1585
2766.82	13.5876
2769.49	13.7014
2772.16	12.1819
2774.82	11.3502
2777.49	10.7348
2780.16	10.0234
2782.82	9.99464
2785.48	10.4083
2788.15	8.46346
2790.81	7.99967
2793.47	6.97402
2796.13	5.1116
2798.79	4.12221
2801.44	2.90683
2804.1	1.79735
2806.76	1.77785
2809.41	1.27556
2812.07	0.80661
2814.72	1.44144
2817.37	2.85822
2820.02	4.75574
2822.67	8.24924
2825.32	12.8333
2827.97	16.4449
2830.62	19.0962
2833.26	23.8703
2835.91	28.5501
2838.55	34.8862
2841.2	43.2161
2843.84	52.3574
2846.48	62.0128
2849.12	72.52
2851.76	85.5291
2854.4	98.1433
2857.04	110.371
2859.68	120.985
2862.32	132.316
2864.95	142.401
2867.58	151.519
2870.22	160.653
2872.85	169.045
2875.48	176.451
2878.11	184.056
2880.74	190.808
2883.37	197.795
2886	204.225
2888.63	210.107
2891.25	216.073
2893.88	221.656
2896.5	229.509
2899.13	239.159
2901.75	247.288
2904.37	257.949
2906.99	269.959
2909.61	282.794
2912.23	298.434
2914.85	314.849
2917.46	328.83
2920.08	339.765
2922.7	348.917
2925.31	354.033
2927.92	360.526
2930.53	361.508
2933.15	360.288
2935.76	357.77
2938.37	351.441
2940.98	344.364
2943.58	333.894
2946.19	322.738
2948.8	309.84
2951.4	297.658
2954.01	286.218
2956.61	273.619
2959.21	260.868
2961.81	247.365
2964.41	233.854
2967.01	222.151
2969.61	210.847
2972.21	200.229
2974.81	190.449
2977.4	180.423
2980	168.391
2982.59	156.97
2985.18	144.195
2987.78	132.581
2990.37	120.351
2992.96	108.677
2995.55	94.8095
2998.14	83.4687
3000.72	72.4379
3003.31	60.0626
3005.9	49.4238
3008.48	39.5596
3011.07	31.1091
3013.65	23.9133
3016.23	18.7384
3018.81	12.805
3021.39	8.40443
3023.97	5.06057
3026.55	0.30173
3029.13	-1.05685
3031.71	-2.42475
3034.28	-2.90502
3036.86	-2.97791
3039.43	-1.15463
3042.01	-0.0678002
3044.58	2.3497
3047.15	4.18147
3049.72	5.95694
3052.29	7.5087
3054.86	8.02329
3057.43	9.07324
3060	10.2467
3062.56	10.8169
3065.13	11.0012
3067.69	10.3819
3070.25	9.57221
3072.82	9.58512
3075.38	8.97503
3077.94	7.87887
3080.5	5.95937
3083.06	4.38163
3085.62	3.68947
3088.17	2.14144
3090.73	1.1713
3093.29	0.361098
3095.84	1.14479
3098.4	2.31696
3100.95	1.84203
3103.5	3.31796
3106.05	3.77638
3108.6	4.48029
3111.15	6.02157
3113.7	7.62419
3116.25	10.0956
3118.79	12.012
3121.34	14.5648
3123.88	16.5879
3126.43	19.9197
3128.97	22.6487
3131.51	25.5824
3134.05	27.6809
3136.59	31.5936
3139.14	34.0568
3141.67	36.1659
3144.21	38.7501
3146.75	41.6551
3149.28	43.6926