File: data/Raman/poly_smoothed/Mb_10_14_45_1x_45s_532 nm_x100_100%_600 gr_mm_01.txt
#Acq. time (s)=	45
#Accumulations=	2
#Range (cm-¹)=	200...3150
#Windows=	2
#Auto scanning=	Off
#Autofocus=	Off
#Macrospot=	Off
#AutoExposure=	Off
#Spike filter=	Multiple accum.
#Delay time (s)=	0
#Binning=	1
#Readout mode=	Signal
#DeNoise=	Off
#ICS correction=	On
#Dark correction=	Off
#Inst. Process=	Off
#Detector Gain=	Best Dynamic Range
#Detector ADC=	20 kHz
#Detector temperature (°C)=	-69.85
#Instrument=	LabRAM HR Evol
#Detector=	Synapse
#Objective=	x100
#Grating=	600 gr/mm
#ND Filter=	100%
#Laser (nm)=	532
#Hole=	100.021
#Range=	Auto
#Laser Pol.=	No
#Raman. Pol.=	No
#Laser Pol. (°)=	-0.0007625
#Raman Pol. (°)=	89.9995
#Collection=	Microscope
#StageXY=	Marzhauser
#StageZ=	Marzhauser
#X (µm)=	-628.2
#Y (µm)=	-1697.8
#Z (µm)=	89.1
#Full time(mm:ss)=	3:19
#Project=
#Sample=
#Site=
#Title=	Mb_10_14_45_2x_45s_532 nm_x100_100%_600 gr_mm
#Remark=
#Date=	11.07.2022 12:04
#Acquired=	11.07.2022 12:04:52
#Base:Fit=	10.08.2022 10:21:11
#Base:Sub=	10.08.2022 10:21:41
#Filter:Polynom=	16.08.2022 10:17:53
#AxisType[0]=Intens
#AxisUnit[0]=Cnt
#AxisType[1]=Spectr
#AxisUnit[1]=1/cm
200.388	24.1407
204.019	19.2268
207.646	14.2542
211.274	9.16408
214.899	6.16459
218.524	5.31377
222.146	6.69843
225.766	7.68624
229.388	11.0661
233.005	12.2539
236.621	14.694
240.236	16.1423
243.852	17.399
247.464	18.9643
251.074	20.247
254.683	24.0548
258.291	25.1191
261.897	25.8081
265.504	26.3309
269.108	26.7505
272.71	27.0926
276.311	26.284
279.91	23.9823
283.508	21.6515
287.105	19.2416
290.698	16.2167
294.291	14.1248
297.884	11.1675
301.475	9.28894
305.064	8.61145
308.652	7.87722
312.237	5.64526
315.822	5.59396
319.406	4.03778
322.987	1.75723
326.568	0.586014
330.148	-0.66515
333.724	-2.33057
337.301	-1.88452
340.875	-1.85415
344.449	0.291426
348.02	2.1435
351.592	7.474
355.16	9.85642
358.728	12.5501
362.294	16.5559
365.858	22.2729
369.422	26.4255
372.983	29.2191
376.543	30.7988
380.102	33.9399
383.661	35.582
387.216	37.6842
390.771	39.1351
394.324	39.8182
397.875	39.2535
401.425	38.4754
404.974	36.4811
408.524	34.3215
412.07	32.1826
415.614	29.6326
419.156	26.9271
422.698	24.743
426.238	21.4645
429.777	21.4773
433.315	20.5479
436.852	17.7556
440.387	15.5033
443.919	13.2737
447.451	12.0773
450.982	11.1924
454.512	10.741
458.038	9.61174
461.565	9.22876
465.091	11.7775
468.613	12.1154
472.136	14.2083
475.655	15.7457
479.176	15.7219
482.692	16.0877
486.21	18.0612
489.724	21.3115
493.237	24.1012
496.75	26.6309
500.26	28.011
503.769	29.5849
507.279	31.3717
510.785	33.2325
514.289	33.1487
517.793	33.637
521.297	32.1384
524.797	31.7507
528.297	30.6507
531.795	28.728
535.291	26.9496
538.787	24.7984
542.281	24.1595
545.773	21.4568
549.264	19.1215
552.754	16.3935
556.243	14.7123
559.73	11.9708
563.216	9.11357
566.701	8.15126
570.182	6.18596
573.664	4.82721
577.145	3.65358
580.624	1.98268
584.1	3.39801
587.577	2.1813
591.052	3.57632
594.524	4.04304
597.997	2.80079
601.466	1.6109
604.936	1.70944
608.403	1.53091
611.87	3.60734
615.334	4.45909
618.799	5.07771
622.26	4.99882
625.72	6.4861
629.181	7.26826
632.638	8.29347
636.095	7.92332
639.551	10.5812
643.005	10.8678
646.457	13.3432
649.908	15.9929
653.357	15.1853
656.806	14.4711
660.253	14.5166
663.7	15.9845
667.145	18.051
670.588	19.497
674.027	18.9081
677.468	19.5353
680.907	18.5512
684.345	18.6521
687.781	18.8092
691.216	20.3314
694.65	21.8333
698.081	23.8734
701.512	23.2921
704.942	22.8238
708.371	22.6448
711.796	24.732
715.222	26.364
718.645	26.9811
722.068	28.8913
725.49	32.0441
728.909	33.8353
732.329	35.751
735.745	36.2466
739.16	36.286
742.576	37.4881
745.988	38.5304
749.401	41.2519
752.811	44.7585
756.22	46.4992
759.627	47.9509
763.035	49.6308
766.44	52.7424
769.843	52.5046
773.245	53.929
776.646	55.8882
780.046	57.0077
783.444	57.3804
786.841	59.8204
790.237	61.4899
793.631	64.8971
797.024	66.9592
800.416	69.6476
803.807	71.0258
807.196	72.9261
810.584	73.3909
813.971	74.0717
817.354	74.9462
820.739	76.3174
824.122	76.5518
827.503	74.9912
830.882	76.934
834.261	76.7252
837.637	73.7422
841.013	72.0747
844.389	69.4651
847.761	66.5147
851.131	62.6633
854.503	59.964
857.871	57.5961
861.24	54.2433
864.606	51.8728
867.97	50.7889
871.336	50.1435
874.698	48.2009
878.058	46.1605
881.418	44.4736
884.778	43.2065
888.135	40.738
891.49	39.8136
894.845	39.4009
898.198	40.0327
901.55	39.1052
904.901	38.5391
908.25	39.048
911.598	36.9669
914.945	38.5839
918.291	36.2817
921.635	36.0543
924.978	37.0314
928.318	38.09
931.659	40.4709
934.998	42.3981
938.336	43.5861
941.671	43.0266
945.007	43.0166
948.339	44.5173
951.672	45.4116
955.004	47.0474
958.333	46.1548
961.662	45.4224
964.989	48.108
968.315	49.8568
971.639	50.7369
974.962	50.9014
978.285	51.9883
981.605	50.0869
984.924	49.0787
988.243	47.2748
991.56	46.3311
994.875	44.8242
998.188	43.8474
1001.5	43.4941
1004.81	44.4844
1008.12	45.5773
1011.43	45.7686
1014.74	47.184
1018.05	46.309
1021.35	45.3089
1024.65	44.5649
1027.96	45.8531
1031.26	46.1707
1034.56	46.969
1037.86	45.5803
1041.16	44.2326
1044.45	45.7638
1047.75	46.2234
1051.04	43.2924
1054.33	38.7179
1057.62	34.0487
1060.91	29.5995
1064.2	25.4408
1067.49	21.3569
1070.77	17.6833
1074.06	15.3464
1077.34	13.0289
1080.62	12.6773
1083.91	11.3157
1087.18	9.86232
1090.46	9.9287
1093.74	11.3921
1097.02	12.9549
1100.29	13.7893
1103.56	13.929
1106.84	13.7874
1110.11	15.3855
1113.38	14.9119
1116.64	13.3755
1119.91	12.6517
1123.18	12.7854
1126.44	11.8742
1129.7	9.1841
1132.97	8.53533
1136.23	7.91164
1139.49	7.59064
1142.74	6.40681
1146	7.01605
1149.26	6.48108
1152.51	4.41601
1155.76	5.04549
1159.01	3.48784
1162.27	1.39699
1165.51	0.946389
1168.76	-0.00893196
1172.01	1.74079
1175.25	3.34037
1178.5	3.77789
1181.74	5.10654
1184.98	4.95008
1188.22	4.57958
1191.46	4.39911
1194.7	3.85716
1197.94	4.65041
1201.17	5.77353
1204.41	5.97412
1207.64	6.78727
1210.87	9.83643
1214.1	14.2708
1217.33	17.5233
1220.56	20.5223
1223.79	23.2877
1227.01	25.2933
1230.23	27.8693
1233.46	30.8034
1236.68	33.9266
1239.9	35.5598
1243.12	37.3469
1246.34	39.5098
1249.55	40.8741
1252.77	42.6859
1255.98	41.5171
1259.2	41.2474
1262.41	40.8153
1265.62	38.7534
1268.83	38.1795
1272.03	38.5836
1275.24	38.0202
1278.45	38.3414
1281.65	37.8028
1284.85	38.1842
1288.06	39.9604
1291.26	41.919
1294.46	44.1291
1297.66	44.1342
1300.85	45.6356
1304.05	48.2896
1307.24	50.325
1310.43	51.9166
1313.63	54.2656
1316.82	56.1451
1320.01	57.1868
1323.2	57.2301
1326.38	55.5735
1329.57	54.3122
1332.76	52.4876
1335.94	49.1361
1339.12	47.7404
1342.3	47.3213
1345.48	46.0066
1348.66	43.1394
1351.84	41.9874
1355.01	39.6265
1358.19	38.4116
1361.36	36.5092
1364.53	34.6198
1367.71	35.0881
1370.88	33.472
1374.04	32.6169
1377.21	32.1331
1380.38	33.7484
1383.54	33.7815
1386.71	33.9239
1389.87	33.9535
1393.03	37.0835
1396.19	37.3256
1399.35	36.1205
1402.51	35.3323
1405.67	35.0369
1408.82	37.3848
1411.98	39.8531
1415.13	41.7087
1418.28	43.179
1421.43	46.8112
1424.58	51.9286
1427.73	57.3605
1430.88	63.2898
1434.02	68.497
1437.17	72.7909
1440.31	77.9198
1443.45	80.6603
1446.6	83.0784
1449.74	83.542
1452.87	83.317
1456.01	81.4889
1459.15	81.5358
1462.28	78.4157
1465.42	75.2733
1468.55	71.9338
1471.68	66.1237
1474.81	61.7359
1477.94	58.4106
1481.07	53.5727
1484.2	48.1369
1487.32	43.2369
1490.45	38.6272
1493.57	33.8423
1496.69	30.5067
1499.81	30.2968
1502.93	29.6367
1506.05	28.0406
1509.17	24.1651
1512.28	23.1459
1515.4	21.5659
1518.51	19.0189
1521.63	16.6902
1524.74	16.9562
1527.85	15.8411
1530.96	16.8472
1534.06	16.1795
1537.17	17.3528
1540.28	17.415
1543.38	19.1481
1546.48	19.8583
1549.59	22.603
1552.69	26.0591
1555.79	26.9288
1558.88	27.4191
1561.98	29.2041
1565.08	30.0349
1568.17	31.5027
1571.27	32.0941
1574.36	36.2638
1577.45	37.5049
1580.54	38.8473
1583.63	39.4531
1586.72	42.3922
1589.8	41.862
1592.89	42.4112
1595.97	43.8933
1599.06	46.699
1602.14	46.0646
1605.22	46.1572
1608.3	46.2533
1611.38	44.231
1614.46	44.7398
1617.53	44.7957
1620.61	46.5031
1623.68	47.6172
1626.75	49.5624
1629.82	50.2887
1632.9	51.2191
1635.96	52.4783
1639.03	53.0935
1642.1	55.0559
1645.16	57.9115
1648.23	61.2643
1651.29	63.068
1654.36	63.7625
1657.42	63.367
1660.48	63.4057
1663.53	63.113
1666.59	62.4168
1669.65	60.4659
1672.7	57.3399
1675.76	54.8382
1678.81	50.7135
1681.86	46.9488
1684.91	42.1408
1687.96	36.4682
1691.01	32.8153
1694.06	28.4445
1697.11	25.9127
1700.15	21.8962
1703.2	18.5727
1706.24	14.7444
1709.28	12.2877
1712.32	11.204
1715.36	9.95691
1718.4	8.81317
1721.43	7.07809
1724.47	4.44776
1727.5	3.25492
1730.54	2.97549
1733.57	2.62555
1736.6	2.83222
1739.63	3.53944
1742.66	2.76403
1745.69	2.59889
1748.72	2.57734
1751.74	3.2155
1754.77	3.16936
1757.79	3.32974
1760.81	2.3547
1763.83	1.98926
1766.85	3.44036
1769.87	4.22894
1772.89	4.61314
1775.91	4.34599
1778.92	3.7913
1781.94	4.20444
1784.95	6.74252
1787.96	7.41377
1790.97	7.40834
1793.98	7.91272
1796.99	8.05378
1800	7.66658
1803	8.29964
1806.01	7.7785
1809.01	6.28471
1812.02	6.07064
1815.02	6.32896
1818.02	5.76108
1821.02	6.25833
1824.02	7.00931
1827.01	6.15462
1830.01	6.48353
1833	5.39896
1836	4.60194
1838.99	5.45597
1841.98	4.63171
1844.97	4.8809
1847.96	4.1236
1850.95	3.61638
1853.94	3.38964
1856.92	3.50291
1859.91	4.22366
1862.89	5.11517
1865.88	5.28666
1868.86	4.05864
1871.84	3.27286
1874.82	4.14325
1877.8	4.14336
1880.77	4.21122
1882.52	4.25081
1885.51	5.48352
1888.5	6.17882
1891.49	5.90244
1894.47	5.71402
1897.46	5.11662
1900.44	5.22543
1903.42	5.70103
1906.4	6.49513
1909.38	7.43211
1912.36	8.57219
1915.34	9.92778
1918.32	9.89336
1921.29	10.1269
1924.27	9.98993
1927.24	10.2087
1930.21	11.7673
1933.18	12.9658
1936.15	11.7394
1939.12	11.5409
1942.09	11.6248
1945.06	11.3191
1948.02	11.5406
1950.99	10.8646
1953.95	11.2451
1956.91	10.5189
1959.87	10.1568
1962.84	8.50019
1965.79	8.2929
1968.75	7.71863
1971.71	7.05882
1974.66	7.36433
1977.62	6.90397
1980.57	6.30722
1983.53	7.98408
1986.48	7.63546
1989.43	7.26139
1992.38	7.52713
1995.33	7.69584
1998.27	7.06651
2001.22	8.64597
2004.16	8.3976
2007.11	8.03367
2010.05	7.34755
2012.99	7.71856
2015.93	9.97702
2018.87	10.0535
2021.81	9.88764
2024.75	9.773
2027.69	11.8293
2030.62	13.8383
2033.56	13.1809
2036.49	15.1345
2039.42	15.1433
2042.35	15.3371
2045.28	17.8914
2048.21	18.4351
2051.14	19.4649
2054.06	20.6652
2056.99	22.2102
2059.92	21.0589
2062.84	22.4762
2065.76	21.7702
2068.68	22.3945
2071.6	23.5041
2074.52	22.6636
2077.44	22.1847
2080.36	20.9411
2083.27	19.6303
2086.19	19.4902
2089.1	18.831
2092.01	17.2855
2094.93	17.126
2097.84	17.9316
2100.75	18.286
2103.66	18.8331
2106.56	17.9303
2109.47	19.0879
2112.37	20.6195
2115.28	21.3352
2118.18	23.6596
2121.09	23.7777
2123.99	23.7489
2126.89	23.6235
2129.79	24.2941
2132.68	25.1645
2135.58	26.1554
2138.48	27.5574
2141.37	28.8859
2144.26	28.2812
2147.16	28.396
2150.05	30.5681
2152.94	30.679
2155.83	32.7484
2158.72	33.7876
2161.6	34.7434
2164.49	34.5017
2167.38	35.3473
2170.26	36.0154
2173.14	36.4808
2176.03	36.9049
2178.91	37.4908
2181.79	37.6339
2184.67	37.5706
2187.54	38.3315
2190.42	35.215
2193.3	34.8248
2196.17	33.25
2199.05	31.8308
2201.92	32.0305
2204.79	31.7159
2207.66	32.0728
2210.53	31.1281
2213.4	27.9445
2216.27	27.4659
2219.13	27.1798
2222	27.4067
2224.86	27.113
2227.72	26.7374
2230.59	25.7999
2233.45	25.8225
2236.31	25.6855
2239.17	24.1174
2242.03	22.6668
2244.88	21.8236
2247.74	21.1455
2250.59	20.8698
2253.45	19.717
2256.3	18.5291
2259.15	16.8211
2262	15.5511
2264.85	14.7408
2267.7	14.3511
2270.55	13.5134
2273.4	13.2646
2276.24	13.7766
2279.09	13.3959
2281.93	11.4498
2284.77	10.6194
2287.61	11.0029
2290.46	11.8163
2293.29	10.561
2296.13	11.6092
2298.97	11.6918
2301.81	11.9304
2304.64	13.1192
2307.48	12.2543
2310.31	11.8472
2313.14	12.3104
2315.97	11.6986
2318.8	12.3785
2321.63	12.4709
2324.46	12.2211
2327.29	12.0049
2330.12	12.7934
2332.94	12.6486
2335.76	13.6753
2338.59	12.9003
2341.41	11.3968
2344.23	11.3587
2347.05	7.94464
2349.87	4.75658
2352.69	3.65788
2355.5	4.76885
2358.32	6.13861
2361.14	7.55961
2363.95	9.27178
2366.76	11.7057
2369.58	12.0559
2372.39	12.1007
2375.2	12.3491
2378	12.4192
2380.81	12.2518
2383.62	12.9352
2386.42	14.566
2389.23	14.7149
2392.03	14.5112
2394.84	14.2902
2397.64	14.3858
2400.44	13.8193
2403.24	12.2321
2406.04	11.7719
2408.83	9.32886
2411.63	8.52845
2414.43	7.07657
2417.22	5.64367
2420.02	5.96508
2422.81	8.42013
2425.6	9.13122
2428.39	10.2101
2431.18	9.95633
2433.97	9.57448
2436.76	8.03855
2439.54	7.85112
2442.33	7.76254
2445.11	7.17069
2447.9	5.89016
2450.68	6.86076
2453.46	7.46486
2456.24	6.41645
2459.02	5.4969
2461.8	5.39315
2464.58	5.43923
2467.36	5.97096
2470.13	5.00525
2472.91	5.10352
2475.68	5.00989
2478.45	5.62575
2481.22	5.021
2484	3.81161
2486.77	3.08309
2489.54	2.17172
2492.3	1.86935
2495.07	1.89081
2497.84	2.75539
2500.6	3.51404
2503.36	3.13196
2506.13	2.60633
2508.89	4.06692
2511.65	3.55039
2514.41	3.91025
2517.17	5.47269
2519.93	5.132
2522.68	4.90974
2525.44	5.97715
2528.19	6.32111
2530.95	5.82545
2533.7	5.24148
2536.45	5.22183
2539.2	3.83462
2541.95	4.29529
2544.7	3.90865
2547.45	4.27891
2550.2	3.18344
2552.94	4.03749
2555.69	4.86818
2558.43	5.37046
2561.17	7.3914
2563.92	9.11065
2566.66	9.20706
2569.4	7.72293
2572.14	7.89205
2574.88	9.08957
2577.61	10.611
2580.35	8.8389
2583.09	8.83205
2585.82	6.83908
2588.55	5.13961
2591.28	5.75777
2594.02	5.77475
2596.75	4.27495
2599.48	4.39341
2602.2	4.61512
2604.93	3.97919
2607.66	3.72724
2610.38	4.43632
2613.11	3.97751
2615.83	3.93465
2618.56	4.13299
2621.28	4.35089
2624	4.99976
2626.72	5.24886
2629.44	4.92604
2632.15	4.77906
2634.87	3.7508
2637.59	5.31946
2640.3	4.79197
2643.02	3.98138
2645.73	3.97556
2648.44	3.7026
2651.15	3.05283
2653.86	3.4003
2656.57	4.74867
2659.28	5.59503
2661.99	5.46044
2664.69	6.36913
2667.4	6.20179
2670.1	7.00486
2672.81	6.38354
2675.51	6.9488
2678.21	6.70581
2680.91	6.10717
2683.61	6.65664
2686.31	6.98134
2689	7.40893
2691.7	7.08821
2694.4	7.64551
2697.09	7.13626
2699.79	9.14247
2702.48	9.4369
2705.17	7.85
2707.86	8.61982
2710.55	10.722
2713.24	11.6908
2715.93	11.9397
2718.61	12.6969
2721.3	12.5758
2723.99	13.1002
2726.67	12.0957
2729.35	11.5489
2732.04	9.85674
2734.72	8.63487
2737.4	8.1569
2740.08	7.6514
2742.76	6.9642
2745.43	6.14172
2748.11	4.31165
2750.79	3.12677
2753.46	2.93404
2756.13	1.24462
2758.81	0.579255
2761.48	-0.567273
2764.15	-0.556125
2766.82	-0.465238
2769.49	0.0409908
2772.16	-0.0146799
2774.82	0.610028
2777.49	2.25338
2780.16	1.51391
2782.82	1.66578
2785.48	1.99586
2788.15	2.68917
2790.81	3.44698
2793.47	3.17355
2796.13	2.39068
2798.79	2.62549
2801.44	2.58677
2804.1	2.76076
2806.76	1.87905
2809.41	0.916007
2812.07	0.562584
2814.72	0.982504
2817.37	1.43931
2820.02	3.2298
2822.67	5.24998
2825.32	8.25606
2827.97	12.3985
2830.62	16.0197
2833.26	21.505
2835.91	26.4826
2838.55	32.6089
2841.2	41.0772
2843.84	50.2381
2846.48	59.0117
2849.12	69.9399
2851.76	80.4079
2854.4	91.854
2857.04	101.115
2859.68	110.327
2862.32	119.647
2864.95	127.146
2867.58	135.044
2870.22	141.594
2872.85	146.974
2875.48	152.817
2878.11	157.507
2880.74	161.735
2883.37	166.031
2886	171.369
2888.63	175.396
2891.25	179.795
2893.88	183.375
2896.5	188.101
2899.13	193.935
2901.75	201.134
2904.37	209.948
2906.99	219.678
2909.61	229.406
2912.23	240.368
2914.85	252.153
2917.46	260.581
2920.08	269.927
2922.7	275.684
2925.31	280.274
2927.92	282.354
2930.53	282.808
2933.15	281.294
2935.76	278.235
2938.37	274.761
2940.98	268.067
2943.58	260.706
2946.19	251.823
2948.8	242.444
2951.4	232.236
2954.01	220.941
2956.61	210.067
2959.21	199.943
2961.81	188.656
2964.41	178.413
2967.01	168.749
2969.61	159.067
2972.21	150.489
2974.81	142.473
2977.4	134.765
2980	125.251
2982.59	115.232
2985.18	106.416
2987.78	96.5464
2990.37	87.1971
2992.96	77.5898
2995.55	68.8312
2998.14	60.9942
3000.72	54.0378
3003.31	46.5144
3005.9	39.7333
3008.48	34.9178
3011.07	29.3784
3013.65	25.207
3016.23	22.0149
3018.81	18.919
3021.39	15.6517
3023.97	12.206
3026.55	8.42622
3029.13	6.10783
3031.71	5.12749
3034.28	4.42863
3036.86	4.83487
3039.43	5.87007
3042.01	5.19998
3044.58	4.85376
3047.15	5.57406
3049.72	6.58005
3052.29	8.00134
3054.86	7.38652
3057.43	6.4163
3060	6.19231
3062.56	6.37612
3065.13	6.55305
3067.69	7.88972
3070.25	6.71902
3072.82	6.62438
3075.38	7.15118
3077.94	6.6796
3080.5	6.50649
3083.06	4.56276
3085.62	3.86622
3088.17	3.61364
3090.73	2.7712
3093.29	3.17106
3095.84	3.07777
3098.4	2.71171
3100.95	3.04446
3103.5	2.94411
3106.05	4.01294
3108.6	4.39949
3111.15	5.4008
3113.7	5.79649
3116.25	5.60863
3118.79	5.59872
3121.34	5.89371
3123.88	6.11136
3126.43	7.11348
3128.97	8.44191
3131.51	7.5755
3134.05	8.34446
3136.59	9.60573
3139.14	11.3943
3141.67	11.0731
3144.21	11.2524
3146.75	10.7248
3149.28	8.31649