File: data/Raman/poly_smoothed/Mb_10_14_02_1x_45s_532 nm_x100_100%_600 gr_mm_01.txt
#Acq. time (s)=	45
#Accumulations=	2
#Range (cm-¹)=	200...3150
#Windows=	2
#Auto scanning=	Off
#Autofocus=	Off
#Macrospot=	Off
#AutoExposure=	Off
#Spike filter=	Multiple accum.
#Delay time (s)=	0
#Binning=	1
#Readout mode=	Signal
#DeNoise=	Off
#ICS correction=	On
#Dark correction=	Off
#Inst. Process=	Off
#Detector Gain=	Best Dynamic Range
#Detector ADC=	20 kHz
#Detector temperature (°C)=	-70.08
#Instrument=	LabRAM HR Evol
#Detector=	Synapse
#Objective=	x100
#Grating=	600 gr/mm
#ND Filter=	100%
#Laser (nm)=	532
#Hole=	100.021
#Range=	Auto
#Laser Pol.=	No
#Raman. Pol.=	No
#Laser Pol. (°)=	-0.0007625
#Raman Pol. (°)=	89.9995
#Collection=	Microscope
#StageXY=	Marzhauser
#StageZ=	Marzhauser
#X (µm)=	-2408.4
#Y (µm)=	2135.1
#Z (µm)=	-40.85
#Full time(mm:ss)=	3:19
#Project=
#Sample=
#Site=
#Title=	Mb_10_14_02_2x_45s_532 nm_x100_100%_600 gr_mm
#Remark=
#Date=	07.07.2022 13:34
#Acquired=	07.07.2022 13:34:40
#Base:Fit=	10.08.2022 10:21:11
#Base:Sub=	10.08.2022 10:21:41
#Filter:Polynom=	16.08.2022 10:17:53
#AxisType[0]=Intens
#AxisUnit[0]=Cnt
#AxisType[1]=Spectr
#AxisUnit[1]=1/cm
200.43	50.3729
204.061	39.6347
207.688	29.9165
211.316	22.6983
214.941	20.1514
218.566	19.7589
222.188	21.1435
225.809	23.0868
229.43	25.5901
233.047	26.606
236.663	29.3626
240.278	31.4955
243.894	32.8013
247.506	34.4421
251.116	36.6377
254.725	37.6346
258.333	37.6576
261.939	37.7754
265.546	36.9079
269.15	35.0536
272.752	30.5069
276.353	26.3479
279.952	22.0217
283.55	17.6243
287.146	14.0949
290.739	10.3063
294.333	8.5463
297.925	7.82439
301.516	7.78441
305.106	7.32869
308.694	6.48182
312.279	6.97619
315.864	8.56223
319.448	8.20784
323.029	9.37353
326.61	11.9194
330.19	11.532
333.766	11.5116
337.343	10.0218
340.917	8.17877
344.491	7.62417
348.062	7.87392
351.633	6.95478
355.201	8.09528
358.77	7.12512
362.335	7.53097
365.899	8.87135
369.464	10.2715
373.025	11.8
376.585	13.2847
380.143	13.923
383.702	15.7539
387.258	16.89
390.812	17.6943
394.365	19.7973
397.916	20.315
401.467	21.1603
405.015	20.3627
408.565	20.1268
412.111	18.4209
415.656	16.7425
419.197	14.193
422.739	10.7425
426.279	8.63072
429.819	6.77997
433.356	4.62416
436.893	2.62841
440.428	3.85885
443.96	1.80682
447.492	2.23768
451.023	2.30806
454.553	3.13798
458.079	2.50779
461.606	3.18021
465.132	4.39003
468.654	6.677
472.177	8.5619
475.696	11.6988
479.217	13.2637
482.733	14.7097
486.251	16.2451
489.765	18.0915
493.278	19.4181
496.791	20.9964
500.301	22.7505
503.81	24.4259
507.319	25.3025
510.825	25.1108
514.33	25.6284
517.833	25.4724
521.337	26.3539
524.838	27.0842
528.337	25.9624
531.835	23.6736
535.332	23.6563
538.827	20.9803
542.321	18.9451
545.814	17.8185
549.305	16.5606
552.795	14.2457
556.284	13.2192
559.771	10.5756
563.257	8.62351
566.742	5.22465
570.223	4.13338
573.705	3.21988
577.185	1.99697
580.665	1.16181
584.141	1.14844
587.617	0.560635
591.092	1.64353
594.564	1.44712
598.037	3.32682
601.506	3.9241
604.976	5.5503
608.443	7.80844
611.91	9.94053
615.374	10.0397
618.839	11.8033
622.3	11.8607
625.761	13.7443
629.221	14.1759
632.679	16.7642
636.135	18.7807
639.592	19.651
643.045	21.0518
646.497	21.8542
649.948	22.556
653.398	23.9993
656.846	24.1788
660.293	24.2075
663.738	22.8111
667.185	21.9661
670.628	21.6082
674.067	22.1026
677.508	22.311
680.947	22.4847
684.385	22.1128
687.821	21.7247
691.256	23.9515
694.69	23.7544
698.121	23.6274
701.552	25.2071
704.982	26.9891
708.41	28.1935
711.836	30.7077
715.262	32.3641
718.685	35.6418
722.108	36.0629
725.53	35.7183
728.949	37.3469
732.369	38.1893
735.785	40.012
739.2	39.1657
742.616	39.9113
746.028	39.7061
749.441	41.1884
752.851	43.7424
756.26	44.8894
759.667	46.9129
763.075	48.1153
766.479	49.483
769.883	53.0947
773.285	55.1104
776.686	58.4748
780.085	61.6052
783.484	65.9858
786.881	69.3264
790.276	71.1922
793.671	72.6826
797.064	73.982
800.456	74.5639
803.846	74.5242
807.236	73.0735
810.624	73.2823
814.01	72.6927
817.394	73.2758
820.778	73.9567
824.161	72.988
827.543	73.7179
830.921	73.8393
834.3	72.9404
837.676	71.2526
841.053	69.32
844.426	67.2914
847.8	66.0282
851.171	64.4488
854.542	61.533
857.911	60.4604
861.279	57.7359
864.645	55.7717
868.01	55.6516
871.375	54.3856
874.737	52.8819
878.097	50.8319
881.457	49.5221
884.817	47.7952
888.174	47.4302
891.53	44.72
894.884	46.0681
898.237	45.6255
901.589	46.3287
904.94	44.0333
908.289	45.5355
911.637	46.036
914.984	44.4219
918.33	44.1938
921.674	44.8847
925.015	44.1767
928.357	45.625
931.698	43.9992
935.037	43.997
938.373	44.9743
941.71	43.4134
945.046	42.1733
948.378	43.3754
951.711	42.6863
955.043	41.5435
958.372	38.8674
961.701	37.5983
965.027	37.9998
968.354	37.12
971.678	37.4359
975	38.1271
978.324	36.6631
981.644	35.5136
984.962	33.3545
988.282	32.4644
991.598	30.632
994.913	30.1625
998.227	28.4308
1001.54	29.5552
1004.85	30.1671
1008.16	30.2493
1011.47	30.0536
1014.78	30.8689
1018.08	33.3525
1021.39	31.8153
1024.69	32.3852
1028	34.2639
1031.3	34.9206
1034.6	34.6196
1037.9	35.1654
1041.19	36.0829
1044.49	38.9148
1047.79	40.2068
1051.08	40.4155
1054.37	39.2297
1057.66	38.2719
1060.95	36.5467
1064.24	33.3188
1067.53	30.222
1070.81	27.8647
1074.1	24.8447
1077.38	22.5383
1080.66	21.1076
1083.94	19.5104
1087.22	16.0636
1090.5	15.8275
1093.78	15.9619
1097.05	15.8275
1100.33	16.6212
1103.6	17.2217
1106.87	19.4898
1110.15	17.6578
1113.41	16.5242
1116.68	17.5037
1119.95	18.9323
1123.21	18.6407
1126.48	17.8754
1129.74	17.4534
1133	17.1106
1136.26	15.6406
1139.52	13.807
1142.78	13.0148
1146.04	11.077
1149.29	8.58089
1152.55	8.13275
1155.8	5.65844
1159.05	5.02894
1162.3	3.17001
1165.55	0.133771
1168.8	-0.809098
1172.05	0.596475
1175.29	1.39032
1178.54	1.42041
1181.78	2.55846
1185.02	2.96594
1188.26	2.75865
1191.5	3.47252
1194.74	6.37456
1197.97	7.63339
1201.21	6.51411
1204.44	9.30055
1207.68	12.5331
1210.91	14.4815
1214.14	17.199
1217.37	18.6509
1220.6	21.5204
1223.82	24.09
1227.05	27.8606
1230.27	30.4208
1233.49	31.6615
1236.72	33.9345
1239.94	34.4843
1243.16	35.163
1246.37	37.2895
1249.59	39.0125
1252.8	41.0311
1256.02	42.4471
1259.23	41.9863
1262.44	42.1235
1265.66	42.9542
1268.87	42.7534
1272.07	44.6116
1275.28	45.4667
1278.48	45.692
1281.69	47.0837
1284.89	50.6604
1288.09	50.9875
1291.3	51.0021
1294.49	51.5203
1297.69	52.9126
1300.89	55.5952
1304.09	56.173
1307.28	58.2666
1310.47	58.4908
1313.66	60.1705
1316.86	61.2472
1320.05	61.064
1323.23	62.7453
1326.42	63.4746
1329.61	63.6821
1332.79	62.3776
1335.98	61.6436
1339.16	60.3094
1342.34	60.0803
1345.52	59.3483
1348.7	58.7391
1351.87	58.7492
1355.05	54.1013
1358.23	51.1286
1361.4	49.9742
1364.57	46.1287
1367.74	43.8301
1370.91	41.1228
1374.08	37.3791
1377.25	35.513
1380.42	33.0839
1383.58	32.386
1386.75	31.7243
1389.91	29.8792
1393.07	29.8253
1396.23	29.277
1399.39	29.2554
1402.55	30.1604
1405.7	31.2135
1408.86	32.315
1412.01	34.8506
1415.17	38.146
1418.32	42.6724
1421.47	49.3384
1424.62	55.7165
1427.77	62.5618
1430.92	67.9719
1434.06	74.5285
1437.2	80.1759
1440.35	82.595
1443.49	85.1015
1446.63	88.4036
1449.77	88.6549
1452.91	90.9526
1456.05	90.1008
1459.18	89.0064
1462.32	86.4318
1465.45	81.7809
1468.59	75.8001
1471.72	71.3268
1474.85	65.0129
1477.98	58.9868
1481.11	53.1496
1484.23	47.4753
1487.36	40.259
1490.48	35.1637
1493.61	29.4977
1496.73	27.4796
1499.85	24.8442
1502.97	21.2212
1506.09	18.5477
1509.2	16.471
1512.32	12.1933
1515.44	9.37471
1518.55	7.46434
1521.66	8.52628
1524.77	9.75304
1527.88	9.79249
1530.99	10.094
1534.1	10.9155
1537.21	11.5661
1540.31	11.5635
1543.42	14.707
1546.52	17.9294
1549.62	21.2181
1552.72	22.269
1555.82	25.5882
1558.92	27.6889
1562.02	29.3691
1565.11	29.9084
1568.21	30.9151
1571.3	31.8204
1574.39	34.3874
1577.49	36.4412
1580.58	37.5372
1583.67	39.8465
1586.75	38.8271
1589.84	38.7897
1592.93	40.1177
1596.01	41.4011
1599.09	43.0107
1602.18	42.6304
1605.26	41.3891
1608.34	42.1193
1611.41	42.5774
1614.49	41.8721
1617.57	43.0821
1620.64	43.3499
1623.72	43.299
1626.79	43.9553
1629.86	44.5027
1632.93	45.9036
1636	47.4278
1639.07	48.2487
1642.14	49.1667
1645.2	52.8443
1648.27	55.2997
1651.33	57.4322
1654.39	58.8451
1657.45	60.215
1660.51	59.7739
1663.57	59.0384
1666.63	58.1209
1669.69	57.7647
1672.74	57.06
1675.79	54.8977
1678.85	50.0643
1681.9	47.9619
1684.95	44.5744
1688	39.4441
1691.05	34.1323
1694.1	29.5387
1697.14	26.0398
1700.19	22.1725
1703.23	16.7141
1706.27	14.2704
1709.32	12.8519
1712.35	9.5378
1715.39	8.96864
1718.43	7.50973
1721.47	6.37956
1724.5	5.13573
1727.54	3.73301
1730.57	3.45899
1733.61	2.7881
1736.64	2.5545
1739.67	3.51373
1742.7	4.41697
1745.72	5.60736
1748.75	6.73812
1751.78	7.12503
1754.8	6.87449
1757.82	7.88125
1760.85	7.42109
1763.87	7.30103
1766.89	7.18749
1769.91	7.91185
1772.92	7.5729
1775.94	6.6293
1778.96	7.41002
1781.97	7.79593
1784.98	7.58269
1788	7.51946
1791.01	7.77432
1794.01	6.52477
1797.02	6.26115
1800.03	5.94518
1803.04	5.25616
1806.04	5.69227
1809.05	5.66664
1812.05	5.20356
1815.05	5.52004
1818.05	5.11054
1821.05	4.70933
1824.05	4.18263
1827.05	4.26127
1830.04	3.59924
1833.04	3.93605
1836.03	2.92207
1839.03	2.81055
1842.02	3.02931
1845.01	3.03515
1848	3.22638
1850.99	2.91062
1853.97	2.27353
1856.96	2.25427
1859.94	3.05299
1862.93	3.00751
1865.91	2.81696
1868.89	2.09511
1871.87	1.38758
1874.85	1.37169
1877.83	2.79984
1880.81	3.03175
1882.56	2.81697
1885.55	2.53373
1888.54	3.66174
1891.52	4.36946
1894.51	5.16786
1897.49	5.2407
1900.48	5.82996
1903.46	5.74144
1906.44	6.16003
1909.42	7.25956
1912.4	8.15909
1915.38	8.46475
1918.35	8.63343
1921.33	7.18073
1924.3	7.25017
1927.28	7.40218
1930.25	8.39669
1933.22	8.8816
1936.19	8.12737
1939.16	7.40135
1942.13	6.89926
1945.09	7.72026
1948.06	8.08352
1951.03	7.55438
1953.99	6.6889
1956.95	7.02544
1959.91	5.2859
1962.87	4.48808
1965.83	5.48085
1968.79	4.30746
1971.75	3.73773
1974.7	3.15053
1977.66	2.02361
1980.61	3.37041
1983.56	2.97172
1986.52	1.81291
1989.47	1.26769
1992.41	1.76823
1995.36	1.81748
1998.31	1.11243
2001.26	1.78873
2004.2	1.26117
2007.15	1.91958
2010.09	2.2525
2013.03	2.48358
2015.97	2.77272
2018.91	3.11982
2021.85	3.53572
2024.79	3.66797
2027.72	4.68917
2030.66	4.37627
2033.59	5.51865
2036.53	7.05953
2039.46	6.74433
2042.39	6.91262
2045.32	6.78302
2048.25	7.42005
2051.18	7.6676
2054.1	6.94807
2057.03	5.9133
2059.95	6.41114
2062.88	5.83806
2065.8	4.74838
2068.72	4.20151
2071.64	3.20391
2074.56	4.12474
2077.48	3.62316
2080.39	4.27574
2083.31	4.14399
2086.22	4.0966
2089.14	4.95717
2092.05	6.6949
2094.96	7.9106
2097.87	5.94598
2100.78	5.86145
2103.69	6.38833
2106.6	6.67887
2109.51	5.75848
2112.41	6.9331
2115.32	7.73767
2118.22	8.24117
2121.12	7.85898
2124.02	10.1659
2126.92	11.9678
2129.82	13.3363
2132.72	14.2424
2135.62	15.1128
2138.51	16.8487
2141.41	18.6184
2144.3	20.205
2147.19	22.0386
2150.09	23.4089
2152.97	25.284
2155.86	26.9322
2158.75	28.5154
2161.64	29.5736
2164.53	30.4702
2167.41	30.9375
2170.3	31.1066
2173.18	33.0455
2176.06	34.9554
2178.94	34.807
2181.82	35.2663
2184.7	36.0377
2187.58	35.9335
2190.46	34.5766
2193.33	34.5221
2196.21	33.6443
2199.08	32.5777
2201.95	30.8699
2204.83	29.004
2207.7	27.4145
2210.57	25.3515
2213.43	23.7654
2216.3	20.4634
2219.17	17.1884
2222.03	16.1799
2224.9	14.0019
2227.76	12.9888
2230.62	12.3293
2233.49	9.88487
2236.34	9.77532
2239.2	9.42256
2242.06	8.44144
2244.92	8.21794
2247.78	6.91621
2250.63	6.82761
2253.48	6.81801
2256.34	6.30451
2259.19	6.31019
2262.04	6.57309
2264.89	7.19713
2267.74	8.62567
2270.59	8.68493
2273.43	8.88118
2276.28	9.0571
2279.12	8.74058
2281.97	8.40077
2284.81	8.85952
2287.65	8.02599
2290.49	7.7678
2293.33	7.53953
2296.17	7.13855
2299.01	7.48345
2301.84	6.55727
2304.68	5.83264
2307.51	6.59446
2310.35	5.93612
2313.18	5.32363
2316.01	4.26772
2318.84	4.23269
2321.67	4.99452
2324.5	4.03864
2327.33	4.53014
2330.15	5.54133
2332.98	5.61413
2335.8	6.47469
2338.62	6.26866
2341.45	5.41275
2344.27	4.97721
2347.09	5.32881
2349.91	4.5079
2352.72	4.61441
2355.54	3.96134
2358.36	3.21028
2361.17	3.57936
2363.98	3.87121
2366.8	5.51168
2369.61	5.94498
2372.42	5.5656
2375.23	6.05572
2378.04	6.0629
2380.85	6.12946
2383.66	6.22402
2386.46	6.44019
2389.26	5.90666
2392.07	6.04786
2394.87	5.34353
2397.67	5.96138
2400.47	5.45706
2403.27	5.00261
2406.07	4.21018
2408.87	4.10438
2411.67	4.7757
2414.46	4.62687
2417.26	3.71645
2420.05	3.41466
2422.84	3.00904
2425.64	2.7763
2428.43	2.94119
2431.22	2.53106
2434.01	2.65677
2436.79	2.91925
2439.58	2.94168
2442.37	3.13191
2445.15	3.39255
2447.93	3.90481
2450.72	4.2303
2453.5	3.63472
2456.28	3.38409
2459.06	2.97034
2461.84	2.60385
2464.62	3.51972
2467.39	3.71628
2470.17	4.49566
2472.94	4.55489
2475.72	4.85238
2478.49	4.5867
2481.26	4.50315
2484.03	3.90513
2486.8	3.79043
2489.57	4.3863
2492.34	3.50282
2495.1	3.71327
2497.87	3.68679
2500.63	3.42064
2503.4	3.27594
2506.16	3.27662
2508.92	3.53041
2511.68	3.00509
2514.44	2.28612
2517.2	2.61375
2519.96	1.62974
2522.72	1.50248
2525.47	1.74579
2528.23	1.44389
2530.98	2.15155
2533.74	3.11442
2536.49	3.00381
2539.24	3.43606
2541.99	4.07461
2544.74	5.15845
2547.49	6.88905
2550.23	8.22155
2552.98	8.96548
2555.72	8.64717
2558.47	8.64003
2561.21	8.12842
2563.95	8.28628
2566.69	8.71272
2569.43	9.48843
2572.17	9.67906
2574.91	10.6452
2577.65	11.2359
2580.39	11.0343
2583.12	10.9771
2585.85	10.5687
2588.59	10.1923
2591.32	9.93987
2594.05	9.60581
2596.78	8.37585
2599.51	7.21174
2602.24	6.92386
2604.97	6.3696
2607.69	6.50132
2610.42	6.45394
2613.14	6.13885
2615.87	5.59906
2618.59	3.45104
2621.31	2.42261
2624.03	2.17275
2626.75	3.41405
2629.47	3.97792
2632.19	4.0118
2634.91	5.25842
2637.62	5.2912
2640.34	5.80135
2643.05	6.91718
2645.76	7.55025
2648.48	8.30291
2651.19	6.70749
2653.9	5.69993
2656.6	5.96169
2659.31	5.16806
2662.02	4.78664
2664.73	3.34005
2667.43	4.07843
2670.14	4.20114
2672.84	3.34314
2675.54	3.31327
2678.24	2.87659
2680.94	3.06677
2683.64	3.89704
2686.34	4.60435
2689.04	6.37732
2691.74	8.02846
2694.43	8.70643
2697.13	9.50502
2699.82	9.84899
2702.51	11.3124
2705.21	12.8265
2707.9	13.9107
2710.58	15.4279
2713.27	15.2466
2715.96	13.7728
2718.65	13.3887
2721.33	14.0621
2724.02	13.547
2726.71	12.8952
2729.39	12.9678
2732.07	12.5659
2734.75	11.1022
2737.43	11.0761
2740.11	10.8682
2742.79	10.1782
2745.47	9.75967
2748.14	9.55393
2750.82	8.95263
2753.49	8.69526
2756.17	8.34967
2758.84	8.33263
2761.51	8.70774
2764.18	7.57097
2766.85	7.16664
2769.52	7.43651
2772.19	6.80168
2774.86	5.516
2777.52	4.12128
2780.19	2.5595
2782.85	2.01187
2785.52	1.82083
2788.18	1.25757
2790.84	0.38426
2793.5	0.469454
2796.16	0.286689
2798.82	0.250049
2801.48	-0.605676
2804.13	-0.982901
2806.79	-1.87555
2809.45	-2.9293
2812.1	-2.17536
2814.75	-1.64398
2817.41	-0.903759
2820.06	0.794752
2822.71	2.7425
2825.36	5.65727
2828	8.4038
2830.65	12.4026
2833.3	16.5575
2835.94	20.4039
2838.59	24.7772
2841.23	31.7783
2843.87	38.5877
2846.52	46.6417
2849.16	54.738
2851.8	64.7386
2854.44	74.41
2857.08	84.2231
2859.71	93.0672
2862.35	100.79
2864.98	108.278
2867.62	113.937
2870.25	120.287
2872.88	126.515
2875.52	131.407
2878.15	136.488
2880.78	141.5
2883.41	145.675
2886.03	150.111
2888.66	154.129
2891.29	158.189
2893.91	162.431
2896.54	166.855
2899.16	171.34
2901.78	176.556
2904.4	184.003
2907.02	192.471
2909.64	201.092
2912.26	210.355
2914.88	222.198
2917.5	231.373
2920.11	239.105
2922.73	245.105
2925.34	249.623
2927.96	252.798
2930.57	254.531
2933.18	255.253
2935.79	254.838
2938.4	251.946
2941.01	247.406
2943.62	242.388
2946.22	235.903
2948.83	228.534
2951.43	222.055
2954.04	213.76
2956.64	203.97
2959.24	193.239
2961.84	183.667
2964.45	173.99
2967.05	165.042
2969.64	156.973
2972.24	147.961
2974.84	139.835
2977.43	130.75
2980.03	121.443
2982.62	111.577
2985.22	102.171
2987.81	92.8172
2990.4	84.2591
2992.99	75.1243
2995.58	65.786
2998.17	57.7853
3000.76	50.2644
3003.34	42.0163
3005.93	35.8108
3008.52	28.6787
3011.1	23.8028
3013.68	19.384
3016.27	15.8806
3018.85	11.3167
3021.43	8.26329
3024.01	5.07857
3026.59	4.21946
3029.16	3.30608
3031.74	1.98858
3034.32	1.79656
3036.89	1.86299
3039.47	2.76214
3042.04	4.52684
3044.61	6.18962
3047.18	7.99238
3049.75	9.60518
3052.32	10.718
3054.89	11.5817
3057.46	11.035
3060.03	10.8901
3062.59	10.3864
3065.16	9.84409
3067.72	8.27771
3070.29	7.61851
3072.85	6.28875
3075.41	5.10763
3077.97	4.51016
3080.53	2.98572
3083.09	1.31179
3085.65	0.936384
3088.21	0.11555
3090.76	0.250948
3093.32	0.650595
3095.87	0.978175
3098.43	3.21253
3100.98	5.22538
3103.53	7.61015
3106.08	10.004
3108.63	11.1133
3111.18	12.9569
3113.73	15.1679
3116.28	17.7028
3118.83	20.3985
3121.37	22.4057
3123.92	25.5546
3126.46	27.4807
3129	29.6809
3131.55	31.5883
3134.09	33.6115
3136.63	35.1666
3139.17	38.0972
3141.71	40.0012
3144.24	42.0829
3146.78	44.1034
3149.32	45.4956