File: data/Raman/poly_smoothed/Mb_10_14_17_1x_45s_532 nm_x100_100%_600 gr_mm_01.txt
#Acq. time (s)=	45
#Accumulations=	2
#Range (cm-¹)=	200...3150
#Windows=	2
#Auto scanning=	Off
#Autofocus=	Off
#Macrospot=	Off
#AutoExposure=	Off
#Spike filter=	Multiple accum.
#Delay time (s)=	0
#Binning=	1
#Readout mode=	Signal
#DeNoise=	Off
#ICS correction=	On
#Dark correction=	Off
#Inst. Process=	Off
#Detector Gain=	Best Dynamic Range
#Detector ADC=	20 kHz
#Detector temperature (°C)=	-69.85
#Instrument=	LabRAM HR Evol
#Detector=	Synapse
#Objective=	x100
#Grating=	600 gr/mm
#ND Filter=	100%
#Laser (nm)=	532
#Hole=	100.021
#Range=	Auto
#Laser Pol.=	No
#Raman. Pol.=	No
#Laser Pol. (°)=	-0.0007625
#Raman Pol. (°)=	89.9995
#Collection=	Microscope
#StageXY=	Marzhauser
#StageZ=	Marzhauser
#X (µm)=	-640.8
#Y (µm)=	-1604.7
#Z (µm)=	89.25
#Full time(mm:ss)=	3:18
#Project=
#Sample=
#Site=
#Title=	Mb_10_14_17_2x_45s_532 nm_x100_100%_600 gr_mm
#Remark=
#Date=	11.07.2022 09:46
#Acquired=	11.07.2022 09:46:49
#Base:Fit=	10.08.2022 10:21:11
#Base:Sub=	10.08.2022 10:21:41
#Filter:Polynom=	16.08.2022 10:17:53
#AxisType[0]=Intens
#AxisUnit[0]=Cnt
#AxisType[1]=Spectr
#AxisUnit[1]=1/cm
200.388	9.92511
204.019	4.80147
207.646	3.22314
211.274	3.1004
214.899	3.04727
218.524	4.60555
222.146	5.08718
225.766	5.12923
229.388	8.03818
233.005	10.4925
236.621	12.0228
240.236	13.2458
243.852	14.5902
247.464	16.1815
251.074	17.1192
254.683	17.4947
258.291	18.3285
261.897	17.5974
265.504	15.898
269.108	15.9291
272.71	13.2347
276.311	11.1673
279.91	9.3508
283.508	7.69578
287.105	6.57349
290.698	7.13953
294.291	5.96679
297.884	5.52182
301.475	3.35838
305.064	3.91305
308.652	4.14254
312.237	4.11864
315.822	8.47317
319.406	9.37683
322.987	10.2584
326.568	10.4474
330.148	12.2643
333.724	12.8378
337.301	12.0722
340.875	12.331
344.449	12.7028
348.02	12.3707
351.592	13.305
355.16	13.2383
358.728	11.5464
362.294	10.6608
365.858	10.4824
369.422	12.6134
372.983	14.3175
376.543	14.7929
380.102	15.918
383.661	16.8512
387.216	17.1828
390.771	19.3692
394.324	19.6707
397.875	21.3147
401.425	22.1069
404.974	23.0541
408.524	21.1348
412.07	20.2632
415.614	18.8851
419.156	17.6958
422.698	16.3309
426.238	14.294
429.777	13.9747
433.315	10.9201
436.852	8.96991
440.387	7.49156
443.919	6.2789
447.451	5.47512
450.982	5.42028
454.512	7.28204
458.038	7.41865
461.565	7.98867
465.091	9.26968
468.613	10.4293
472.136	11.9483
475.655	14.1195
479.176	16.2327
482.692	16.7303
486.21	18.8284
489.724	18.9982
493.237	20.3032
496.75	20.8648
500.26	21.3159
503.769	21.799
507.279	22.8692
510.785	20.4254
514.289	20.1491
517.793	19.1807
521.297	18.1398
524.797	19.4748
528.297	19.4442
531.795	18.0313
535.291	18.3036
538.787	16.9941
542.281	16.9266
545.773	15.9932
549.264	16.5198
552.754	17.1164
556.243	16.8475
559.73	15.1897
563.216	14.0241
566.701	12.6697
570.182	11.9525
573.664	10.6136
577.145	10.6387
580.624	11.3124
584.1	9.60974
587.577	9.03462
591.052	9.59952
594.524	9.45249
597.997	9.41244
601.466	11.1715
604.936	12.2341
608.403	12.39
611.87	14.299
615.334	14.1299
618.799	15.8975
622.26	16.7686
625.72	17.3218
629.181	18.298
632.638	19.0741
636.095	19.8915
639.551	19.5684
643.005	19.9083
646.457	19.3579
649.908	20.107
653.357	21.2401
656.806	20.5242
660.253	22.2413
663.7	23.2574
667.145	22.4202
670.588	24.1804
674.027	26.2819
677.468	27.8715
680.907	29.2514
684.345	31.339
687.781	32.4359
691.216	34.094
694.65	34.3782
698.081	36.3167
701.512	37.6842
704.942	38.7505
708.371	40.361
711.796	40.9629
715.222	42.4611
718.645	43.1804
722.068	43.9818
725.49	44.5741
728.909	46.2702
732.329	46.836
735.745	48.8144
739.16	50.7761
742.576	53.2614
745.988	55.0928
749.401	55.2253
752.811	57.6012
756.22	60.725
759.627	62.9333
763.035	65.191
766.44	66.866
769.843	68.5214
773.245	70.4325
776.646	72.393
780.046	74.2424
783.444	76.4779
786.841	77.274
790.237	77.6614
793.631	78.1687
797.024	78.953
800.416	79.8668
803.807	81.7905
807.196	83.25
810.584	84.3423
813.971	85.4917
817.354	86.3885
820.739	87.9579
824.122	87.3888
827.503	87.0174
830.882	85.5483
834.261	86.1794
837.637	85.814
841.013	83.1532
844.389	82.8265
847.761	80.854
851.131	78.6416
854.503	77.7672
857.871	74.0467
861.24	71.0699
864.606	70.9656
867.97	68.4463
871.336	66.464
874.698	65.9962
878.058	64.2697
881.418	63.8846
884.778	62.0551
888.135	61.2088
891.49	58.6509
894.845	57.7216
898.198	57.028
901.55	56.0271
904.901	54.4454
908.25	53.5402
911.598	53.1656
914.945	53.451
918.291	53.3778
921.635	53.6279
924.978	52.9034
928.318	52.4367
931.659	50.7284
934.998	51.5807
938.336	51.7953
941.671	52.9522
945.007	53.7556
948.339	53.8891
951.672	53.8493
955.004	53.0419
958.333	51.4468
961.662	51.6248
964.989	50.0596
968.315	50.6846
971.639	50.9903
974.962	50.1378
978.285	50.5523
981.605	49.8555
984.924	47.8427
988.243	48.3198
991.56	46.7431
994.875	45.0318
998.188	45.2453
1001.5	42.987
1004.81	40.1543
1008.12	39.1743
1011.43	37.6874
1014.74	39.1619
1018.05	40.1499
1021.35	40.7997
1024.65	42.094
1027.96	42.9517
1031.26	45.0206
1034.56	45.6817
1037.86	45.8357
1041.16	46.5874
1044.45	47.3398
1047.75	48.352
1051.04	49.2703
1054.33	47.731
1057.62	45.9041
1060.91	45.2711
1064.2	43.0451
1067.49	39.8092
1070.77	38.0971
1074.06	34.5515
1077.34	33.8038
1080.62	31.3456
1083.91	27.9083
1087.18	25.8967
1090.46	23.8122
1093.74	23.6635
1097.02	24.9361
1100.29	24.3761
1103.56	24.6146
1106.84	25.235
1110.11	25.2855
1113.38	24.6966
1116.64	24.1895
1119.91	23.6286
1123.18	22.5951
1126.44	22.2882
1129.7	21.9309
1132.97	21.3102
1136.23	20.0215
1139.49	18.0772
1142.74	16.8239
1146	15.7954
1149.26	15.1644
1152.51	14.5467
1155.76	13.5335
1159.01	12.2208
1162.27	9.61614
1165.51	9.27682
1168.76	8.07359
1172.01	9.5385
1175.25	11.4363
1178.5	12.3842
1181.74	13.8706
1184.98	16.6745
1188.22	17.8943
1191.46	19.7209
1194.7	20.586
1197.94	22.0994
1201.17	23.6792
1204.41	25.3116
1207.64	28.2381
1210.87	30.0452
1214.1	29.5533
1217.33	29.0999
1220.56	28.9275
1223.79	29.3431
1227.01	28.9957
1230.23	28.2843
1233.46	27.4074
1236.68	28.2941
1239.9	28.5638
1243.12	29.1243
1246.34	31.5907
1249.55	33.6892
1252.77	35.7376
1255.98	35.3785
1259.2	35.7632
1262.41	36.5005
1265.62	36.8233
1268.83	35.5768
1272.03	35.8842
1275.24	36.5128
1278.45	37.6643
1281.65	37.7691
1284.85	39.6884
1288.06	39.8478
1291.26	38.1212
1294.46	38.3001
1297.66	37.771
1300.85	38.0823
1304.05	39.3503
1307.24	38.5261
1310.43	40.3225
1313.63	41.896
1316.82	42.8905
1320.01	44.7713
1323.2	47.1943
1326.38	48.2843
1329.57	46.7435
1332.76	47.4902
1335.94	46.7583
1339.12	46.6331
1342.3	44.9327
1345.48	43.7292
1348.66	42.2779
1351.84	42.6098
1355.01	41.4847
1358.19	41.7928
1361.36	40.2649
1364.53	38.9913
1367.71	36.2892
1370.88	33.4596
1374.04	31.3725
1377.21	31.9733
1380.38	32.4487
1383.54	34.1919
1386.71	34.7066
1389.87	34.6055
1393.03	36.1355
1396.19	37.1977
1399.35	38.0227
1402.51	38.9304
1405.67	39.0657
1408.82	39.4166
1411.98	40.3921
1415.13	39.7576
1418.28	40.3556
1421.43	41.8437
1424.58	43.2055
1427.73	44.7066
1430.88	47.0204
1434.02	48.5028
1437.17	48.7442
1440.31	48.6939
1443.45	48.7492
1446.6	48.4784
1449.74	46.794
1452.87	49.7239
1456.01	50.8783
1459.15	49.92
1462.28	48.4714
1465.42	48.14
1468.55	47.0016
1471.68	46.105
1474.81	43.9842
1477.94	40.4825
1481.07	38.2685
1484.2	34.6219
1487.32	32.1822
1490.45	30.1409
1493.57	28.8942
1496.69	27.4288
1499.81	26.1088
1502.93	25.4505
1506.05	24.6121
1509.17	22.7136
1512.28	22.4275
1515.4	20.6667
1518.51	19.7332
1521.63	18.6665
1524.74	18.0093
1527.85	17.3079
1530.96	17.9029
1534.06	17.7968
1537.17	17.4882
1540.28	17.7266
1543.38	18.3182
1546.48	18.4761
1549.59	18.4047
1552.69	19.1406
1555.79	19.8096
1558.88	20.6417
1561.98	21.2727
1565.08	21.7472
1568.17	23.5109
1571.27	25.3441
1574.36	25.989
1577.45	27.6653
1580.54	28.4738
1583.63	29.3237
1586.72	29.577
1589.8	29.4453
1592.89	30.469
1595.97	30.7698
1599.06	30.2775
1602.14	29.2139
1605.22	28.228
1608.3	28.0656
1611.38	28.3025
1614.46	28.0395
1617.53	28.1343
1620.61	28.942
1623.68	30.3772
1626.75	31.36
1629.82	32.7304
1632.9	34.2741
1635.96	34.7438
1639.03	36.153
1642.1	38.8084
1645.16	41.6625
1648.23	43.4931
1651.29	44.5457
1654.36	45.3132
1657.42	44.5214
1660.48	43.6843
1663.53	41.2303
1666.59	38.6511
1669.65	36.7711
1672.7	32.3716
1675.76	29.8855
1678.81	28.1631
1681.86	26.0992
1684.91	24.1024
1687.96	21.7879
1691.01	19.3587
1694.06	16.7402
1697.11	15.4557
1700.15	12.631
1703.2	11.741
1706.24	10.1838
1709.28	9.50625
1712.32	9.17217
1715.36	10.2101
1718.4	9.49474
1721.43	8.4498
1724.47	7.53301
1727.5	5.82551
1730.54	4.82853
1733.57	3.74061
1736.6	1.84803
1739.63	1.45607
1742.66	0.443998
1745.69	0.0235366
1748.72	0.410939
1751.74	0.630941
1754.77	0.699289
1757.79	0.443454
1760.81	1.02419
1763.83	1.62854
1766.85	1.95298
1769.87	2.38643
1772.89	4.21707
1775.91	4.34723
1778.92	5.8891
1781.94	6.85754
1784.95	6.6892
1787.96	7.67016
1790.97	6.75357
1793.98	6.37749
1796.99	5.88848
1800	5.11094
1803	4.65404
1806.01	4.04145
1809.01	3.21396
1812.02	2.92356
1815.02	3.94009
1818.02	3.07728
1821.02	3.63775
1824.02	3.7691
1827.01	3.52552
1830.01	4.66195
1833	4.71466
1836	4.98161
1838.99	4.27436
1841.98	4.97624
1844.97	5.63277
1847.96	6.24241
1850.95	6.1145
1853.94	6.20691
1856.92	5.42573
1859.91	5.67706
1862.89	4.82879
1865.88	4.27761
1868.86	3.39682
1871.84	2.83085
1874.82	2.76194
1877.8	3.36931
1880.77	3.09472
1882.52	3.90064
1885.51	5.54096
1888.5	5.94838
1891.49	7.1212
1894.47	8.00899
1897.46	7.9313
1900.44	8.45224
1903.42	8.17643
1906.4	7.77909
1909.38	7.10906
1912.36	7.54863
1915.34	7.78593
1918.32	7.63674
1921.29	6.95462
1924.27	5.70464
1927.24	6.60973
1930.21	6.03745
1933.18	5.13455
1936.15	4.48221
1939.12	4.60103
1942.09	3.66513
1945.06	4.03937
1948.02	4.85142
1950.99	4.89366
1953.95	5.34754
1956.91	5.87996
1959.87	6.4161
1962.84	6.33856
1965.79	5.57744
1968.75	5.05319
1971.71	4.10299
1974.66	3.9119
1977.62	3.40087
1980.57	3.08921
1983.53	2.64277
1986.48	2.5685
1989.43	2.29971
1992.38	1.94986
1995.33	2.24137
1998.27	1.441
2001.22	2.33368
2004.16	2.16013
2007.11	1.85573
2010.05	2.72458
2012.99	2.96736
2015.93	3.01492
2018.87	3.83588
2021.81	4.1229
2024.75	3.85867
2027.69	3.6059
2030.62	3.7195
2033.56	4.66808
2036.49	4.45543
2039.42	3.68662
2042.35	4.00921
2045.28	4.44448
2048.21	4.56845
2051.14	4.93865
2054.06	5.55856
2056.99	5.8754
2059.92	5.99509
2062.84	7.05281
2065.76	7.63475
2068.68	8.04758
2071.6	8.51789
2074.52	9.22612
2077.44	9.76562
2080.36	11.0633
2083.27	11.1181
2086.19	10.3565
2089.1	10.0495
2092.01	9.60989
2094.93	10.0234
2097.84	10.2823
2100.75	9.79325
2103.66	11.0354
2106.56	9.98754
2109.47	9.68414
2112.37	9.8108
2115.28	10.3443
2118.18	10.286
2121.09	10.3413
2123.99	10.3477
2126.89	10.41
2129.79	9.36636
2132.68	9.12569
2135.58	9.8797
2138.48	10.9132
2141.37	11.8492
2144.26	11.7877
2147.16	12.6811
2150.05	13.0168
2152.94	13.1729
2155.83	12.6338
2158.72	13.5566
2161.6	14.5477
2164.49	14.9585
2167.38	15.5038
2170.26	15.9467
2173.14	16.532
2176.03	17.2726
2178.91	16.2006
2181.79	16.4978
2184.67	17.1232
2187.54	17.0688
2190.42	16.606
2193.3	16.8554
2196.17	16.0677
2199.05	15.7894
2201.92	15.433
2204.79	15.0573
2207.66	15.3011
2210.53	14.4406
2213.4	13.284
2216.27	11.8896
2219.13	10.6863
2222	10.0633
2224.86	9.56796
2227.72	9.5873
2230.59	9.73834
2233.45	8.5384
2236.31	8.48761
2239.17	7.54006
2242.03	7.62245
2244.88	6.99979
2247.74	7.12357
2250.59	6.501
2253.45	6.17016
2256.3	5.94222
2259.15	6.45458
2262	6.22689
2264.85	6.06101
2267.7	5.83893
2270.55	5.18291
2273.4	3.47745
2276.24	3.28807
2279.09	2.41015
2281.93	1.67327
2284.77	1.23049
2287.61	1.29063
2290.46	1.42231
2293.29	2.68098
2296.13	3.14813
2298.97	4.20177
2301.81	4.63689
2304.64	4.84424
2307.48	5.57771
2310.31	5.99063
2313.14	6.52227
2315.97	6.60871
2318.8	6.69126
2321.63	6.53402
2324.46	6.33147
2327.29	6.83604
2330.12	6.64322
2332.94	7.15864
2335.76	6.99331
2338.59	6.77225
2341.41	5.8256
2344.23	5.36813
2347.05	5.16454
2349.87	4.08971
2352.69	2.44889
2355.5	2.93707
2358.32	1.6886
2361.14	1.07201
2363.95	0.873838
2366.76	1.9015
2369.58	1.05582
2372.39	1.01429
2375.2	0.554962
2378	0.370339
2380.81	-0.225661
2383.62	-0.407298
2386.42	-0.511181
2389.23	-0.562921
2392.03	-0.411266
2394.84	0.0423978
2397.64	1.52382
2400.44	2.22657
2403.24	2.27217
2406.04	2.27558
2408.83	2.86244
2411.63	2.74419
2414.43	2.65728
2417.22	2.89139
2420.02	1.73768
2422.81	2.22015
2425.6	1.59719
2428.39	1.69068
2431.18	2.51933
2433.97	2.9214
2436.76	3.22026
2439.54	2.74871
2442.33	3.05
2445.11	3.09023
2447.9	2.82977
2450.68	2.26939
2453.46	1.91082
2456.24	2.0367
2459.02	2.07154
2461.8	2.32135
2464.58	3.15932
2467.36	2.68309
2470.13	2.65299
2472.91	1.131
2475.68	1.1879
2478.45	0.782452
2481.22	0.567041
2484	1.56122
2486.77	1.31682
2489.54	1.15852
2492.3	1.0167
2495.07	0.686447
2497.84	1.19323
2500.6	1.49674
2503.36	1.30356
2506.13	1.24909
2508.89	1.56431
2511.65	1.8386
2514.41	1.76447
2517.17	2.30121
2519.93	2.35796
2522.68	2.20416
2525.44	2.57473
2528.19	3.22626
2530.95	4.16886
2533.7	4.51465
2536.45	4.14505
2539.2	4.67163
2541.95	5.06665
2544.7	5.91108
2547.45	6.56583
2550.2	6.59441
2552.94	6.38336
2555.69	5.51797
2558.43	6.10775
2561.17	5.42671
2563.92	4.72635
2566.66	5.30989
2569.4	4.48308
2572.14	4.03102
2574.88	3.88828
2577.61	3.49152
2580.35	3.23889
2583.09	2.92497
2585.82	1.83671
2588.55	1.56911
2591.28	2.86922
2594.02	3.23057
2596.75	4.40365
2599.48	3.75939
2602.2	3.50845
2604.93	3.93451
2607.66	4.71304
2610.38	4.56451
2613.11	5.1602
2615.83	4.63289
2618.56	4.8475
2621.28	4.81579
2624	5.285
2626.72	5.44404
2629.44	4.94239
2632.15	5.34025
2634.87	5.0844
2637.59	4.28267
2640.3	3.83896
2643.02	3.28294
2645.73	3.33897
2648.44	5.00013
2651.15	4.57302
2653.86	4.29789
2656.57	4.55904
2659.28	4.35758
2661.99	4.80155
2664.69	4.53012
2667.4	4.88391
2670.1	5.96783
2672.81	6.91828
2675.51	7.93862
2678.21	8.4488
2680.91	9.11437
2683.61	9.17732
2686.31	9.53221
2689	9.22624
2691.7	9.27967
2694.4	8.46898
2697.09	8.13083
2699.79	8.54627
2702.48	8.2186
2705.17	7.89484
2707.86	7.66047
2710.55	8.07606
2713.24	9.19925
2715.93	8.64529
2718.61	7.31014
2721.3	7.12196
2723.99	7.69393
2726.67	7.62305
2729.35	8.0329
2732.04	8.82517
2734.72	9.24047
2737.4	8.15126
2740.08	8.73574
2742.76	8.16455
2745.43	8.24717
2748.11	7.8929
2750.79	7.57326
2753.46	6.65673
2756.13	6.45514
2758.81	5.43222
2761.48	5.16587
2764.15	5.27846
2766.82	4.92308
2769.49	4.01916
2772.16	2.54524
2774.82	2.57876
2777.49	1.8128
2780.16	1.32835
2782.82	0.70158
2785.48	1.40479
2788.15	1.62396
2790.81	2.45966
2793.47	3.16866
2796.13	3.22674
2798.79	3.94368
2801.44	3.91945
2804.1	4.45169
2806.76	4.70622
2809.41	4.78476
2812.07	6.03179
2814.72	6.64388
2817.37	8.07462
2820.02	9.18628
2822.67	10.2716
2825.32	11.0209
2827.97	11.5797
2830.62	11.9206
2833.26	12.6205
2835.91	13.348
2838.55	16.1911
2841.2	18.3847
2843.84	21.3657
2846.48	24.5614
2849.12	29.1256
2851.76	33.2393
2854.4	37.6862
2857.04	42.6088
2859.68	46.5847
2862.32	51.1986
2864.95	55.3015
2867.58	59.7611
2870.22	64.3929
2872.85	67.3898
2875.48	71.2812
2878.11	75.3419
2880.74	78.6472
2883.37	81.2523
2886	83.795
2888.63	86.9181
2891.25	88.7607
2893.88	91.6778
2896.5	94.896
2899.13	98.5694
2901.75	102.895
2904.37	106.804
2906.99	110.612
2909.61	115.906
2912.23	120.228
2914.85	125.195
2917.46	129.516
2920.08	133.853
2922.7	135.824
2925.31	137.211
2927.92	139.733
2930.53	139.625
2933.15	137.933
2935.76	136.562
2938.37	134.156
2940.98	130.955
2943.58	127.063
2946.19	123.18
2948.8	120.005
2951.4	115.641
2954.01	111.144
2956.61	106.91
2959.21	102.471
2961.81	97.4545
2964.41	93.2079
2967.01	89.0982
2969.61	84.4626
2972.21	80.5978
2974.81	76.7492
2977.4	72.6788
2980	68.2971
2982.59	63.7828
2985.18	58.7579
2987.78	53.8944
2990.37	49.3306
2992.96	44.0114
2995.55	38.388
2998.14	33.5539
3000.72	29.9574
3003.31	25.2692
3005.9	20.7351
3008.48	16.4212
3011.07	14.0031
3013.65	10.6744
3016.23	8.46622
3018.81	6.17224
3021.39	4.03031
3023.97	2.79291
3026.55	1.07007
3029.13	0.793749
3031.71	0.144241
3034.28	-0.0422416
3036.86	0.354286
3039.43	1.04896
3042.01	1.80541
3044.58	2.48903
3047.15	2.62083
3049.72	2.81125
3052.29	3.87951
3054.86	3.86189
3057.43	3.59283
3060	3.84843
3062.56	3.80637
3065.13	3.49097
3067.69	3.01848
3070.25	2.03147
3072.82	1.7648
3075.38	2.30486
3077.94	1.63061
3080.5	0.902965
3083.06	0.425471
3085.62	0.22996
3088.17	-0.245092
3090.73	-0.328855
3093.29	0.134815
3095.84	0.396673
3098.4	0.684847
3100.95	0.794116
3103.5	0.0608249
3106.05	-0.79082
3108.6	-0.321899
3111.15	0.24655
3113.7	1.00026
3116.25	1.10449
3118.79	1.6847
3121.34	1.53494
3123.88	2.31658
3126.43	2.60274
3128.97	3.53807
3131.51	3.39788
3134.05	4.09509
3136.59	5.35076
3139.14	5.99853
3141.67	6.51151
3144.21	7.43054
3146.75	8.48067
3149.28	8.69226