File: data/Raman/poly_smoothed/Mb_10_14_26_1x_45s_532 nm_x100_100%_600 gr_mm_01.txt
#Acq. time (s)=	45
#Accumulations=	2
#Range (cm-¹)=	200...3150
#Windows=	2
#Auto scanning=	Off
#Autofocus=	Off
#Macrospot=	Off
#AutoExposure=	Off
#Spike filter=	Multiple accum.
#Delay time (s)=	0
#Binning=	1
#Readout mode=	Signal
#DeNoise=	Off
#ICS correction=	On
#Dark correction=	Off
#Inst. Process=	Off
#Detector Gain=	Best Dynamic Range
#Detector ADC=	20 kHz
#Detector temperature (°C)=	-69.85
#Instrument=	LabRAM HR Evol
#Detector=	Synapse
#Objective=	x100
#Grating=	600 gr/mm
#ND Filter=	100%
#Laser (nm)=	532
#Hole=	100.021
#Range=	Auto
#Laser Pol.=	No
#Raman. Pol.=	No
#Laser Pol. (°)=	-0.0007625
#Raman Pol. (°)=	89.9995
#Collection=	Microscope
#StageXY=	Marzhauser
#StageZ=	Marzhauser
#X (µm)=	-616.5
#Y (µm)=	-1589.6
#Z (µm)=	89.85
#Full time(mm:ss)=	3:18
#Project=
#Sample=
#Site=
#Title=	Mb_10_14_26_2x_45s_532 nm_x100_100%_600 gr_mm
#Remark=
#Date=	11.07.2022 10:28
#Acquired=	11.07.2022 10:28:25
#Base:Fit=	10.08.2022 10:21:11
#Base:Sub=	10.08.2022 10:21:41
#Filter:Polynom=	16.08.2022 10:17:53
#AxisType[0]=Intens
#AxisUnit[0]=Cnt
#AxisType[1]=Spectr
#AxisUnit[1]=1/cm
200.388	8.39692
204.019	10.2714
207.646	8.68915
211.274	7.11104
214.899	7.01865
218.524	7.51098
222.146	9.13726
225.766	9.38575
229.388	10.4482
233.005	11.3418
236.621	11.4004
240.236	13.0744
243.852	15.5377
247.464	16.8795
251.074	16.4097
254.683	17.6768
258.291	21.6345
261.897	21.6156
265.504	22.682
269.108	24.0653
272.71	25.5206
276.311	24.9664
279.91	22.9215
283.508	21.307
287.105	19.709
290.698	16.0073
294.291	13.6787
297.884	12.4016
301.475	11.8818
305.064	9.49734
308.652	7.88512
312.237	5.34148
315.822	3.27176
319.406	1.97106
322.987	1.4379
326.568	1.96025
330.148	2.51134
333.724	2.69485
337.301	0.125435
340.875	-0.747514
344.449	-0.579669
348.02	1.00821
351.592	2.51441
355.16	2.11875
358.728	2.36862
362.294	4.09017
365.858	5.22583
369.422	7.29151
372.983	7.77351
376.543	8.05955
380.102	9.29993
383.661	10.8952
387.216	11.7502
390.771	13.2224
394.324	15.0242
397.875	15.4865
401.425	17.7552
404.974	20.0824
408.524	20.1412
412.07	20.9872
415.614	21.2264
419.156	20.3163
422.698	18.5129
426.238	18.1969
429.777	18.1288
433.315	15.2009
436.852	15.3437
440.387	13.2446
443.919	13.7493
447.451	12.9756
450.982	14.8851
454.512	15.551
458.038	14.233
461.565	14.8483
465.091	14.8262
468.613	15.461
472.136	16.0555
475.655	16.1352
479.176	16.322
482.692	16.1995
486.21	17.7227
489.724	17.8362
493.237	18.5607
496.75	18.6085
500.26	16.1956
503.769	16.9403
507.279	15.6596
510.785	16.5318
514.289	14.4137
517.793	13.922
521.297	13.67
524.797	13.3042
528.297	15.0466
531.795	15.2856
535.291	15.766
538.787	17.2085
542.281	17.3213
545.773	16.1448
549.264	17.8075
552.754	16.6269
556.243	15.6565
559.73	13.1058
563.216	10.9257
566.701	11.9254
570.182	12.2842
573.664	10.8529
577.145	8.33947
580.624	8.0062
584.1	6.15045
587.577	5.69994
591.052	6.7877
594.524	6.86431
597.997	7.18235
601.466	7.13861
604.936	6.81536
608.403	7.87886
611.87	11.102
615.334	11.8307
618.799	13.9908
622.26	14.7956
625.72	14.409
629.181	14.1162
632.638	12.5223
636.095	13.0686
639.551	12.9567
643.005	11.1266
646.457	11.8139
649.908	14.0957
653.357	13.9864
656.806	12.4895
660.253	10.7271
663.7	12.4443
667.145	13.3214
670.588	12.4724
674.027	14.0159
677.468	16.293
680.907	17.9147
684.345	17.525
687.781	20.5813
691.216	24.1696
694.65	27.7218
698.081	30.4637
701.512	33.0508
704.942	33.1688
708.371	33.3644
711.796	35.0537
715.222	37.2399
718.645	39.7748
722.068	40.8441
725.49	40.9781
728.909	43.371
732.329	44.4044
735.745	43.3074
739.16	41.7165
742.576	41.5265
745.988	43.2552
749.401	42.3877
752.811	43.8798
756.22	45.047
759.627	46.414
763.035	48.3733
766.44	50.441
769.843	54.0628
773.245	58.2946
776.646	61.628
780.046	63.4583
783.444	66.8131
786.841	69.0252
790.237	71.586
793.631	75.463
797.024	78.1119
800.416	80.2895
803.807	81.127
807.196	81.1335
810.584	82.2934
813.971	82.1776
817.354	79.9131
820.739	77.5799
824.122	76.2524
827.503	75.079
830.882	73.4958
834.261	73.0495
837.637	71.0282
841.013	69.6935
844.389	67.5448
847.761	64.3367
851.131	61.9876
854.503	59.0366
857.871	57.1672
861.24	53.378
864.606	51.4217
867.97	50.8333
871.336	48.3831
874.698	48.5509
878.058	47.8058
881.418	47.5794
884.778	47.4572
888.135	46.1431
891.49	46.1635
894.845	46.2508
898.198	46.2878
901.55	46.3875
904.901	47.7266
908.25	48.9146
911.598	49.9044
914.945	51.931
918.291	52.7354
921.635	52.2202
924.978	51.8938
928.318	52.2283
931.659	50.3125
934.998	50.8561
938.336	51.8741
941.671	48.6424
945.007	47.2357
948.339	46.3711
951.672	45.1384
955.004	44.1447
958.333	42.2187
961.662	41.8883
964.989	40.639
968.315	39.4536
971.639	37.7359
974.962	37.4535
978.285	38.4978
981.605	37.1582
984.924	35.65
988.243	34.4523
991.56	33.2049
994.875	33.4878
998.188	32.8242
1001.5	31.7276
1004.81	30.7644
1008.12	30.6484
1011.43	30.9682
1014.74	33.8657
1018.05	33.7137
1021.35	33.8079
1024.65	32.8739
1027.96	35.5137
1031.26	37.8345
1034.56	39.2863
1037.86	38.4339
1041.16	39.4167
1044.45	38.9088
1047.75	38.8034
1051.04	36.851
1054.33	36.4992
1057.62	36.0698
1060.91	35.0125
1064.2	32.0428
1067.49	29.7672
1070.77	27.2755
1074.06	26.7797
1077.34	25.6957
1080.62	22.2074
1083.91	20.6565
1087.18	22.1638
1090.46	23.5033
1093.74	25.3374
1097.02	24.8062
1100.29	24.8702
1103.56	25.1862
1106.84	26.0396
1110.11	27.2294
1113.38	27.9075
1116.64	26.84
1119.91	25.1178
1123.18	24.5203
1126.44	24.4802
1129.7	22.8068
1132.97	23.2499
1136.23	22.0906
1139.49	20.5096
1142.74	19.7262
1146	17.0027
1149.26	16.82
1152.51	15.2731
1155.76	16.0922
1159.01	16.0468
1162.27	14.9889
1165.51	14.7321
1168.76	12.8706
1172.01	11.7051
1175.25	10.9775
1178.5	10.088
1181.74	10.0132
1184.98	11.385
1188.22	13.9464
1191.46	12.5528
1194.7	12.9259
1197.94	13.1212
1201.17	13.1306
1204.41	12.8753
1207.64	14.0604
1210.87	15.7681
1214.1	17.9827
1217.33	19.3771
1220.56	21.8898
1223.79	26.5698
1227.01	28.4044
1230.23	32.314
1233.46	35.6182
1236.68	37.6938
1239.9	36.8123
1243.12	37.2872
1246.34	38.162
1249.55	38.3639
1252.77	38.7718
1255.98	39.1529
1259.2	40.8257
1262.41	41.3493
1265.62	43.1852
1268.83	42.5218
1272.03	41.0198
1275.24	40.7936
1278.45	39.4832
1281.65	40.2233
1284.85	42.4024
1288.06	45.2724
1291.26	48.6144
1294.46	49.913
1297.66	52.2697
1300.85	54.5094
1304.05	55.9864
1307.24	57.3806
1310.43	59.144
1313.63	59.6281
1316.82	59.4033
1320.01	59.7278
1323.2	59.2429
1326.38	59.5632
1329.57	60.635
1332.76	60.4688
1335.94	59.101
1339.12	57.9163
1342.3	57.4809
1345.48	56.0157
1348.66	52.9488
1351.84	51.3546
1355.01	49.6818
1358.19	49.8805
1361.36	49.9747
1364.53	47.7474
1367.71	47.2982
1370.88	46.759
1374.04	45.3449
1377.21	43.298
1380.38	42.6837
1383.54	42.7361
1386.71	42.5209
1389.87	43.0078
1393.03	41.499
1396.19	41.7251
1399.35	41.7258
1402.51	42.9503
1405.67	44.964
1408.82	45.7573
1411.98	46.599
1415.13	47.2157
1418.28	49.3198
1421.43	52.969
1424.58	55.9092
1427.73	59.5418
1430.88	64.8694
1434.02	68.7083
1437.17	72.3701
1440.31	75.7631
1443.45	78.9108
1446.6	80.5798
1449.74	81.5458
1452.87	81.1442
1456.01	80.1764
1459.15	80.2835
1462.28	78.8809
1465.42	77.3074
1468.55	74.0065
1471.68	72.4628
1474.81	70.4073
1477.94	67.9937
1481.07	66.1757
1484.2	60.9692
1487.32	57.7236
1490.45	54.238
1493.57	52.5637
1496.69	50.623
1499.81	49.7722
1502.93	49.996
1506.05	48.5796
1509.17	46.5506
1512.28	42.7327
1515.4	40.4723
1518.51	38.71
1521.63	36.8199
1524.74	34.525
1527.85	32.8072
1530.96	32.509
1534.06	31.5933
1537.17	31.3901
1540.28	30.7135
1543.38	31.6174
1546.48	32.8951
1549.59	32.7339
1552.69	33.0779
1555.79	34.2658
1558.88	34.1065
1561.98	32.986
1565.08	35.747
1568.17	38.2272
1571.27	40.129
1574.36	42.0937
1577.45	43.9176
1580.54	45.397
1583.63	45.6961
1586.72	46.5865
1589.8	46.7288
1592.89	48.5126
1595.97	49.2039
1599.06	48.7707
1602.14	48.7076
1605.22	47.422
1608.3	46.9738
1611.38	46.0825
1614.46	46.0989
1617.53	46.3016
1620.61	47.3811
1623.68	48.0236
1626.75	47.9037
1629.82	48.5059
1632.9	46.8859
1635.96	48.1068
1639.03	50.3733
1642.1	51.6715
1645.16	52.6143
1648.23	53.7733
1651.29	54.1605
1654.36	55.1425
1657.42	54.2629
1660.48	51.7041
1663.53	50.7996
1666.59	48.9596
1669.65	45.5316
1672.7	41.5962
1675.76	38.761
1678.81	34.6893
1681.86	31.5701
1684.91	28.5203
1687.96	25.7525
1691.01	24.3683
1694.06	22.7035
1697.11	20.0521
1700.15	18.3532
1703.2	15.4916
1706.24	13.5116
1709.28	13.3813
1712.32	13.6372
1715.36	12.0323
1718.4	11.8454
1721.43	12.9472
1724.47	12.3844
1727.5	11.8232
1730.54	10.2814
1733.57	9.28035
1736.6	8.34506
1739.63	7.71873
1742.66	7.30335
1745.69	5.33791
1748.72	5.38425
1751.74	3.7869
1754.77	2.93105
1757.79	1.7762
1760.81	1.4901
1763.83	1.53395
1766.85	1.21727
1769.87	0.171483
1772.89	0.624171
1775.91	0.526854
1778.92	0.939535
1781.94	2.50453
1784.95	3.2548
1787.96	3.57312
1790.97	3.69922
1793.98	5.01772
1796.99	4.35901
1800	4.58962
1803	4.09371
1806.01	5.46936
1809.01	5.01352
1812.02	4.80442
1815.02	5.45553
1818.02	6.44476
1821.02	5.83008
1824.02	4.48943
1827.01	4.04433
1830.01	4.27014
1833	3.47624
1836	3.64506
1838.99	4.52996
1841.98	4.39701
1844.97	5.57423
1847.96	5.77627
1850.95	5.75397
1853.94	6.90482
1856.92	6.76725
1859.91	6.10275
1862.89	4.84053
1865.88	4.88079
1868.86	4.55888
1871.84	4.18936
1874.82	2.61947
1877.8	1.07839
1880.77	0.98048
1882.52	0.228571
1885.51	1.4592
1888.5	2.32916
1891.49	2.47632
1894.47	2.52803
1897.46	3.2449
1900.44	3.59298
1903.42	5.06989
1906.4	6.95209
1909.38	8.78541
1912.36	9.48328
1915.34	9.97003
1918.32	11.6543
1921.29	11.2809
1924.27	12.2873
1927.24	11.2959
1930.21	12.0233
1933.18	11.3836
1936.15	11.7246
1939.12	11.2714
1942.09	9.72578
1945.06	7.90736
1948.02	6.35976
1950.99	7.19298
1953.95	6.26998
1956.91	6.87019
1959.87	7.11366
1962.84	6.66727
1965.79	6.7424
1968.75	6.61513
1971.71	6.18881
1974.66	6.87024
1977.62	7.66837
1980.57	6.80724
1983.53	7.39773
1986.48	7.68661
1989.43	8.81113
1992.38	8.70053
1995.33	8.54924
1998.27	8.3683
2001.22	9.60397
2004.16	9.24328
2007.11	8.52653
2010.05	9.34246
2012.99	10.9512
2015.93	11.4751
2018.87	11.6487
2021.81	11.7101
2024.75	11.5685
2027.69	11.6858
2030.62	11.8017
2033.56	11.1198
2036.49	11.6548
2039.42	12.0799
2042.35	11.4122
2045.28	12.1903
2048.21	12.1929
2051.14	11.3974
2054.06	11.1804
2056.99	11.5941
2059.92	10.9815
2062.84	10.7784
2065.76	9.11947
2068.68	10.4299
2071.6	9.72005
2074.52	9.87427
2077.44	11.7335
2080.36	13.1015
2083.27	14.2736
2086.19	15.1759
2089.1	13.9563
2092.01	13.8539
2094.93	12.7943
2097.84	12.9659
2100.75	11.6609
2103.66	11.2988
2106.56	11.9098
2109.47	13.1397
2112.37	12.3573
2115.28	11.5752
2118.18	11.1496
2121.09	11.2761
2123.99	11.9362
2126.89	12.9864
2129.79	13.2609
2132.68	13.6736
2135.58	14.7878
2138.48	16.1736
2141.37	17.5342
2144.26	18.6517
2147.16	21.3336
2150.05	22.6026
2152.94	24.7819
2155.83	25.9861
2158.72	26.736
2161.6	28.3505
2164.49	28.3472
2167.38	28.6112
2170.26	28.4214
2173.14	28.6243
2176.03	28.7007
2178.91	27.7836
2181.79	27.0133
2184.67	26.4635
2187.54	25.8122
2190.42	24.832
2193.3	24.298
2196.17	23.4436
2199.05	21.5621
2201.92	20.2637
2204.79	19.5834
2207.66	18.6443
2210.53	16.6933
2213.4	14.6644
2216.27	15.3797
2219.13	13.7169
2222	12.6281
2224.86	12.0552
2227.72	11.373
2230.59	9.89665
2233.45	9.09735
2236.31	7.74814
2239.17	6.94484
2242.03	6.56773
2244.88	6.17267
2247.74	5.78919
2250.59	6.23289
2253.45	6.65903
2256.3	6.40456
2259.15	5.67098
2262	5.71548
2264.85	6.61475
2267.7	6.99368
2270.55	6.65366
2273.4	7.357
2276.24	7.13411
2279.09	6.61833
2281.93	6.67552
2284.77	7.15588
2287.61	7.25915
2290.46	7.36177
2293.29	7.49059
2296.13	8.71756
2298.97	9.90852
2301.81	11.45
2304.64	13.1448
2307.48	13.7881
2310.31	15.6262
2313.14	15.8799
2315.97	16.155
2318.8	16.385
2321.63	17.0634
2324.46	16.8388
2327.29	16.6477
2330.12	15.8747
2332.94	15.0283
2335.76	13.8585
2338.59	12.1519
2341.41	9.50564
2344.23	7.86015
2347.05	5.22488
2349.87	3.68388
2352.69	3.28878
2355.5	1.07008
2358.32	0.738564
2361.14	-0.578674
2363.95	-1.13242
2366.76	-0.524617
2369.58	0.358362
2372.39	0.11837
2375.2	0.623758
2378	1.31673
2380.81	2.5229
2383.62	2.00346
2386.42	2.3744
2389.23	2.89409
2392.03	4.25932
2394.84	4.42266
2397.64	3.48713
2400.44	4.07648
2403.24	4.22669
2406.04	5.20675
2408.83	6.20994
2411.63	6.27041
2414.43	7.02584
2417.22	7.531
2420.02	8.18686
2422.81	9.30898
2425.6	9.62008
2428.39	10.3377
2431.18	10.147
2433.97	10.525
2436.76	10.9239
2439.54	10.8396
2442.33	11.309
2445.11	10.256
2447.9	9.81253
2450.68	8.30046
2453.46	7.10815
2456.24	6.4196
2459.02	5.39942
2461.8	5.29123
2464.58	3.10675
2467.36	2.56338
2470.13	3.58291
2472.91	3.69777
2475.68	3.58937
2478.45	2.92281
2481.22	2.4277
2484	1.80323
2486.77	1.48573
2489.54	1.75338
2492.3	1.78663
2495.07	1.99342
2497.84	1.07826
2500.6	2.00938
2503.36	2.28139
2506.13	1.59852
2508.89	0.758151
2511.65	0.386114
2514.41	0.854296
2517.17	0.868694
2519.93	1.24836
2522.68	0.786302
2525.44	1.35265
2528.19	1.62377
2530.95	1.39588
2533.7	2.02316
2536.45	3.1697
2539.2	4.04254
2541.95	3.3518
2544.7	3.80981
2547.45	3.23478
2550.2	3.10068
2552.94	4.14494
2555.69	4.23092
2558.43	4.35752
2561.17	4.80482
2563.92	4.48086
2566.66	5.02132
2569.4	4.76754
2572.14	4.49005
2574.88	5.15493
2577.61	4.58482
2580.35	4.91332
2583.09	5.02726
2585.82	5.40212
2588.55	5.45209
2591.28	5.63678
2594.02	6.13488
2596.75	6.38977
2599.48	6.94605
2602.2	6.94394
2604.93	6.82217
2607.66	7.15616
2610.38	6.28835
2613.11	5.84115
2615.83	5.31488
2618.56	4.22567
2621.28	3.84262
2624	2.494
2626.72	1.74633
2629.44	1.00495
2632.15	0.665263
2634.87	1.3084
2637.59	1.13904
2640.3	1.11944
2643.02	-0.490422
2645.73	-0.887375
2648.44	0.0275333
2651.15	0.268006
2653.86	1.27139
2656.57	1.66861
2659.28	1.8896
2661.99	2.75992
2664.69	3.09207
2667.4	3.1632
2670.1	3.19136
2672.81	3.72808
2675.51	3.01011
2678.21	2.42664
2680.91	2.73764
2683.61	2.90354
2686.31	2.86855
2689	2.81036
2691.7	2.63207
2694.4	3.80367
2697.09	5.20961
2699.79	6.7348
2702.48	6.25157
2705.17	5.85788
2707.86	6.08027
2710.55	8.12612
2713.24	9.60574
2715.93	11.2218
2718.61	11.1506
2721.3	11.2392
2723.99	11.358
2726.67	11.4875
2729.35	11.3735
2732.04	10.8709
2734.72	10.4298
2737.4	10.1843
2740.08	9.66241
2742.76	8.53724
2745.43	7.42729
2748.11	7.32839
2750.79	5.92103
2753.46	4.56503
2756.13	4.01141
2758.81	3.75481
2761.48	4.45643
2764.15	3.70699
2766.82	3.09591
2769.49	2.95612
2772.16	3.54307
2774.82	4.44109
2777.49	4.24739
2780.16	4.26963
2782.82	3.29191
2785.48	2.5328
2788.15	2.48984
2790.81	2.89381
2793.47	2.20989
2796.13	2.94709
2798.79	3.48292
2801.44	4.02518
2804.1	3.085
2806.76	2.11786
2809.41	2.09961
2812.07	1.669
2814.72	1.53551
2817.37	1.44609
2820.02	2.56527
2822.67	4.84832
2825.32	7.56297
2827.97	10.8873
2830.62	13.5363
2833.26	16.6914
2835.91	21.0171
2838.55	26.0319
2841.2	30.2622
2843.84	36.1454
2846.48	42.152
2849.12	49.0554
2851.76	55.9154
2854.4	63.9726
2857.04	71.8946
2859.68	78.7098
2862.32	84.9832
2864.95	91.4731
2867.58	96.1247
2870.22	101.292
2872.85	106.66
2875.48	112.357
2878.11	116.76
2880.74	120.975
2883.37	125.082
2886	128.921
2888.63	133.254
2891.25	137.091
2893.88	141.182
2896.5	144.761
2899.13	149.557
2901.75	155.753
2904.37	160.901
2906.99	166.152
2909.61	173.742
2912.23	180.739
2914.85	187.782
2917.46	193.287
2920.08	198.411
2922.7	200.953
2925.31	203.51
2927.92	205.317
2930.53	205.778
2933.15	204.404
2935.76	202.045
2938.37	198.411
2940.98	194.066
2943.58	188.827
2946.19	182.005
2948.8	176.792
2951.4	169.932
2954.01	163.132
2956.61	156.135
2959.21	149.667
2961.81	142.43
2964.41	135.245
2967.01	128.605
2969.61	122.02
2972.21	116.343
2974.81	110.304
2977.4	103.738
2980	96.8734
2982.59	89.503
2985.18	82.7453
2987.78	75.243
2990.37	67.9315
2992.96	60.2319
2995.55	52.3032
2998.14	45.1023
3000.72	39.4628
3003.31	33.5932
3005.9	29.449
3008.48	24.7822
3011.07	21.2675
3013.65	17.0303
3016.23	13.1222
3018.81	9.49427
3021.39	7.77633
3023.97	6.41529
3026.55	4.32043
3029.13	2.86266
3031.71	2.45276
3034.28	1.9711
3036.86	2.31962
3039.43	3.27895
3042.01	3.33775
3044.58	3.4225
3047.15	5.01876
3049.72	5.10678
3052.29	4.99295
3054.86	4.95424
3057.43	5.38618
3060	5.62833
3062.56	6.37713
3065.13	6.27996
3067.69	5.75089
3070.25	5.20887
3072.82	4.4802
3075.38	3.31786
3077.94	2.57002
3080.5	2.96014
3083.06	2.73779
3085.62	3.83963
3088.17	3.95367
3090.73	4.01786
3093.29	4.74766
3095.84	4.89011
3098.4	6.56592
3100.95	7.69197
3103.5	7.26657
3106.05	7.04981
3108.6	7.67198
3111.15	8.62656
3113.7	8.77775
3116.25	9.29117
3118.79	10.7173
3121.34	12.3671
3123.88	13.4608
3126.43	14.5273
3128.97	15.3806
3131.51	16.6608
3134.05	18.4876
3136.59	21.7291
3139.14	24.7297
3141.67	27.692
3144.21	31.2243
3146.75	34.3051
3149.28	38.0053