File: data/Raman/poly_smoothed/Mb_10_14_34_1x_45s_532 nm_x100_100%_600 gr_mm_01.txt
#Acq. time (s)=	45
#Accumulations=	2
#Range (cm-¹)=	200...3150
#Windows=	2
#Auto scanning=	Off
#Autofocus=	Off
#Macrospot=	Off
#AutoExposure=	Off
#Spike filter=	Multiple accum.
#Delay time (s)=	0
#Binning=	1
#Readout mode=	Signal
#DeNoise=	Off
#ICS correction=	On
#Dark correction=	Off
#Inst. Process=	Off
#Detector Gain=	Best Dynamic Range
#Detector ADC=	20 kHz
#Detector temperature (°C)=	-69.85
#Instrument=	LabRAM HR Evol
#Detector=	Synapse
#Objective=	x100
#Grating=	600 gr/mm
#ND Filter=	100%
#Laser (nm)=	532
#Hole=	100.021
#Range=	Auto
#Laser Pol.=	No
#Raman. Pol.=	No
#Laser Pol. (°)=	-0.0007625
#Raman Pol. (°)=	89.9995
#Collection=	Microscope
#StageXY=	Marzhauser
#StageZ=	Marzhauser
#X (µm)=	-622.3
#Y (µm)=	-1608.6
#Z (µm)=	89.6
#Full time(mm:ss)=	3:18
#Project=
#Sample=
#Site=
#Title=	Mb_10_14_34_2x_45s_532 nm_x100_100%_600 gr_mm
#Remark=
#Date=	11.07.2022 11:02
#Acquired=	11.07.2022 11:02:48
#Base:Fit=	10.08.2022 10:21:11
#Base:Sub=	10.08.2022 10:21:41
#Filter:Polynom=	16.08.2022 10:17:53
#AxisType[0]=Intens
#AxisUnit[0]=Cnt
#AxisType[1]=Spectr
#AxisUnit[1]=1/cm
200.388	15.6338
204.019	12.9492
207.646	10.643
211.274	8.84763
214.899	7.30263
218.524	5.86068
222.146	4.82993
225.766	3.79236
229.388	5.29568
233.005	5.94447
236.621	5.47891
240.236	6.07055
243.852	5.2789
247.464	5.16604
251.074	4.72094
254.683	6.2275
258.291	6.8816
261.897	6.2194
265.504	6.15414
269.108	6.77141
272.71	7.82988
276.311	6.73634
279.91	5.85571
283.508	4.63526
287.105	2.61597
290.698	2.42774
294.291	1.37361
297.884	2.61883
301.475	2.39756
305.064	2.97069
308.652	1.66928
312.237	1.39427
315.822	2.75025
319.406	3.18718
322.987	3.35945
326.568	2.95654
330.148	3.7967
333.724	4.71063
337.301	5.71181
340.875	7.40175
344.449	7.82593
348.02	9.12439
351.592	9.22167
355.16	10.8742
358.728	11.7049
362.294	11.4313
365.858	12.7321
369.422	12.3336
372.983	10.8479
376.543	10.7617
380.102	11.316
383.661	12.236
387.216	12.796
390.771	11.2705
394.324	9.57119
397.875	9.20058
401.425	9.85994
404.974	9.48635
408.524	7.76475
412.07	7.59056
415.614	7.92975
419.156	7.98717
422.698	6.72205
426.238	6.39376
429.777	6.68795
433.315	6.11034
436.852	7.49822
440.387	7.74922
443.919	8.90726
447.451	7.96055
450.982	7.99253
454.512	7.96846
458.038	5.46407
461.565	4.69823
465.091	5.50024
468.613	7.19223
472.136	8.42763
475.655	10.2663
479.176	11.7923
482.692	11.2091
486.21	12.2991
489.724	11.8192
493.237	12.203
496.75	12.5164
500.26	15.2891
503.769	16.4498
507.279	16.3493
510.785	16.2274
514.289	18.269
517.793	18.4134
521.297	18.7889
524.797	19.5977
528.297	17.8645
531.795	16.57
535.291	14.0766
538.787	13.5583
542.281	11.933
545.773	10.9281
549.264	12.8074
552.754	13.1191
556.243	13.0421
559.73	13.0858
563.216	11.9637
566.701	10.2282
570.182	11.0696
573.664	10.5607
577.145	9.85913
580.624	9.36971
584.1	9.48093
587.577	9.25552
591.052	8.07717
594.524	7.48885
597.997	6.81848
601.466	5.96777
604.936	6.13132
608.403	5.64178
611.87	6.05823
615.334	4.78919
618.799	4.95508
622.26	6.05513
625.72	8.78985
629.181	9.22278
632.638	12.3078
636.095	12.8362
639.551	13.6268
643.005	14.6301
646.457	17.0277
649.908	17.1516
653.357	19.0885
656.806	20.2461
660.253	20.1154
663.7	21.2382
667.145	22.1455
670.588	22.3126
674.027	21.0547
677.468	21.1177
680.907	21.6343
684.345	22.1584
687.781	22.9467
691.216	23.3875
694.65	23.2942
698.081	24.3889
701.512	25.6389
704.942	27.4556
708.371	29.5138
711.796	31.6315
715.222	34.2787
718.645	35.431
722.068	36.2608
725.49	36.1712
728.909	38.9991
732.329	39.9507
735.745	41.0276
739.16	43.3679
742.576	44.4761
745.988	46.3836
749.401	48.3152
752.811	51.2901
756.22	53.241
759.627	56.1861
763.035	57.952
766.44	60.7456
769.843	63.1341
773.245	64.3481
776.646	65.8819
780.046	67.3229
783.444	69.9026
786.841	71.6412
790.237	72.8416
793.631	73.368
797.024	75.5204
800.416	76.0574
803.807	74.9916
807.196	74.6227
810.584	74.78
813.971	74.9378
817.354	75.6947
820.739	75.0577
824.122	74.6414
827.503	73.8067
830.882	73.9507
834.261	74.6128
837.637	74.035
841.013	72.8316
844.389	72.4489
847.761	69.2106
851.131	68.5321
854.503	68.4325
857.871	65.7888
861.24	63.2372
864.606	60.9401
867.97	58.2178
871.336	56.4885
874.698	54.0842
878.058	53.5872
881.418	52.4284
884.778	49.9346
888.135	47.8235
891.49	45.5414
894.845	44.7631
898.198	44.6123
901.55	42.8316
904.901	41.0514
908.25	39.8007
911.598	39.1517
914.945	40.5088
918.291	40.2424
921.635	41.1052
924.978	40.7794
928.318	39.8743
931.659	40.7996
934.998	42.913
938.336	42.4919
941.671	41.917
945.007	40.63
948.339	40.9874
951.672	40.0794
955.004	40.852
958.333	39.2862
961.662	37.4738
964.989	35.2897
968.315	34.5539
971.639	34.6293
974.962	34.6133
978.285	35.059
981.605	34.5937
984.924	33.7615
988.243	33.3017
991.56	31.9195
994.875	32.0222
998.188	32.7782
1001.5	31.3396
1004.81	32.1274
1008.12	30.8121
1011.43	30.1931
1014.74	30.7417
1018.05	29.739
1021.35	28.5144
1024.65	26.0352
1027.96	25.1902
1031.26	25.9586
1034.56	24.2772
1037.86	25.4249
1041.16	25.024
1044.45	24.7334
1047.75	24.2957
1051.04	25.5459
1054.33	26.631
1057.62	26.4593
1060.91	26.4069
1064.2	24.8479
1067.49	22.6854
1070.77	21.3412
1074.06	20.6694
1077.34	19.9151
1080.62	18.02
1083.91	17.169
1087.18	15.2347
1090.46	12.0884
1093.74	11.7603
1097.02	12.5396
1100.29	10.2315
1103.56	9.27796
1106.84	8.49033
1110.11	10.0134
1113.38	11.443
1116.64	11.4386
1119.91	11.8036
1123.18	11.9826
1126.44	11.5431
1129.7	13.1018
1132.97	14.3011
1136.23	14.1315
1139.49	12.7406
1142.74	11.2928
1146	9.78953
1149.26	8.55546
1152.51	6.25631
1155.76	5.7973
1159.01	5.93964
1162.27	5.55912
1165.51	4.75306
1168.76	3.7229
1172.01	5.17101
1175.25	6.04703
1178.5	5.738
1181.74	6.8058
1184.98	8.29926
1188.22	8.26298
1191.46	9.58784
1194.7	10.152
1197.94	10.9278
1201.17	14.0595
1204.41	16.9997
1207.64	17.4674
1210.87	19.7474
1214.1	20.9639
1217.33	23.159
1220.56	24.1333
1223.79	25.7963
1227.01	25.1431
1230.23	27.2241
1233.46	28.1114
1236.68	28.7906
1239.9	29.5987
1243.12	30.7049
1246.34	32.8999
1249.55	34.4181
1252.77	34.7487
1255.98	34.54
1259.2	33.9829
1262.41	32.3193
1265.62	32.6888
1268.83	33.7572
1272.03	35.107
1275.24	36.6164
1278.45	39.0231
1281.65	40.3612
1284.85	42.1789
1288.06	42.7764
1291.26	44.5807
1294.46	45.9308
1297.66	47.455
1300.85	47.4497
1304.05	48.0427
1307.24	47.965
1310.43	49.5196
1313.63	51.3212
1316.82	53.2672
1320.01	56.5307
1323.2	58.095
1326.38	58.1357
1329.57	56.6473
1332.76	55.0618
1335.94	52.9939
1339.12	50.8684
1342.3	50.5881
1345.48	50.8897
1348.66	50.2231
1351.84	48.2496
1355.01	46.0762
1358.19	44.2717
1361.36	41.4375
1364.53	39.9911
1367.71	37.8914
1370.88	35.6456
1374.04	31.7243
1377.21	30.5043
1380.38	29.7686
1383.54	30.3328
1386.71	30.7435
1389.87	30.9341
1393.03	31.4962
1396.19	32.1316
1399.35	32.0687
1402.51	31.7558
1405.67	31.9133
1408.82	33.0086
1411.98	34.7791
1415.13	36.4064
1418.28	40.758
1421.43	43.8902
1424.58	47.4161
1427.73	50.294
1430.88	52.4645
1434.02	54.577
1437.17	56.4186
1440.31	58.3179
1443.45	58.6405
1446.6	59.4474
1449.74	60.0378
1452.87	58.5811
1456.01	58.2713
1459.15	56.868
1462.28	55.3865
1465.42	52.0794
1468.55	50.5632
1471.68	47.4044
1474.81	45.7146
1477.94	43.2931
1481.07	42.1584
1484.2	39.4527
1487.32	38.2628
1490.45	36.3697
1493.57	35.9858
1496.69	35.1602
1499.81	34.3466
1502.93	33.8145
1506.05	32.4931
1509.17	31.3733
1512.28	29.4067
1515.4	28.4439
1518.51	28.6356
1521.63	26.9002
1524.74	27.1655
1527.85	25.1953
1530.96	24.6509
1534.06	24.4808
1537.17	23.6145
1540.28	23.9127
1543.38	24.8902
1546.48	25.4376
1549.59	25.3931
1552.69	26.4539
1555.79	26.5864
1558.88	27.755
1561.98	27.8604
1565.08	28.3473
1568.17	30.0623
1571.27	33.0929
1574.36	33.7437
1577.45	34.8604
1580.54	35.8603
1583.63	37.2276
1586.72	38.1248
1589.8	38.6661
1592.89	41.9693
1595.97	42.496
1599.06	43.9292
1602.14	44.1689
1605.22	43.5132
1608.3	42.969
1611.38	43.3316
1614.46	42.4291
1617.53	41.2495
1620.61	40.7168
1623.68	40.208
1626.75	40.2501
1629.82	39.6686
1632.9	39.5902
1635.96	38.2983
1639.03	37.5205
1642.1	37.6288
1645.16	37.8394
1648.23	38.5284
1651.29	39.141
1654.36	40.3719
1657.42	41.2078
1660.48	40.6548
1663.53	39.8422
1666.59	39.2097
1669.65	38.0207
1672.7	36.9209
1675.76	34.9773
1678.81	32.3028
1681.86	30.3639
1684.91	28.6557
1687.96	27.1575
1691.01	23.6516
1694.06	21.1399
1697.11	20.2397
1700.15	17.4922
1703.2	14.1224
1706.24	12.951
1709.28	11.4404
1712.32	9.76241
1715.36	9.66804
1718.4	9.25599
1721.43	10.4417
1724.47	10.8402
1727.5	10.1486
1730.54	8.29364
1733.57	7.47706
1736.6	6.42044
1739.63	7.28334
1742.66	6.54485
1745.69	6.31686
1748.72	6.34324
1751.74	6.10056
1754.77	7.2839
1757.79	6.77031
1760.81	5.8856
1763.83	4.85974
1766.85	3.67293
1769.87	3.35405
1772.89	2.92916
1775.91	2.18706
1778.92	1.597
1781.94	2.10864
1784.95	1.91981
1787.96	1.59188
1790.97	2.39927
1793.98	2.25239
1796.99	2.90703
1800	3.68989
1803	4.06617
1806.01	4.9386
1809.01	6.06408
1812.02	7.29321
1815.02	8.60874
1818.02	8.64929
1821.02	9.70885
1824.02	9.23177
1827.01	9.21295
1830.01	9.38639
1833	10.0891
1836	9.51515
1838.99	9.10433
1841.98	8.29295
1844.97	7.25147
1847.96	6.16523
1850.95	5.83313
1853.94	2.73859
1856.92	2.03176
1859.91	1.38645
1862.89	0.455304
1865.88	0.307623
1868.86	0.685659
1871.84	1.36836
1874.82	0.911479
1877.8	0.878632
1880.77	1.49191
1882.52	1.90887
1885.51	2.29809
1888.5	2.87415
1891.49	3.29194
1894.47	3.79728
1897.46	5.04359
1900.44	6.709
1903.42	6.95793
1906.4	6.98048
1909.38	7.94683
1912.36	7.83796
1915.34	8.1521
1918.32	7.47957
1921.29	6.72187
1924.27	6.20258
1927.24	4.72698
1930.21	3.82415
1933.18	3.44699
1936.15	2.88124
1939.12	3.08856
1942.09	2.93957
1945.06	1.80706
1948.02	0.81923
1950.99	0.39662
1953.95	1.04079
1956.91	2.1563
1959.87	2.89982
1962.84	4.26127
1965.79	4.94391
1968.75	5.56976
1971.71	5.93227
1974.66	5.73646
1977.62	6.15397
1980.57	7.30477
1983.53	7.9484
1986.48	7.31931
1989.43	7.48242
1992.38	7.14391
1995.33	6.5191
1998.27	6.11008
2001.22	5.68434
2004.16	5.62042
2007.11	3.98189
2010.05	3.08339
2012.99	3.47288
2015.93	2.91676
2018.87	2.0991
2021.81	1.47585
2024.75	2.19636
2027.69	2.38013
2030.62	3.0167
2033.56	3.65706
2036.49	3.71853
2039.42	4.13032
2042.35	3.8986
2045.28	3.68259
2048.21	4.45344
2051.14	4.55389
2054.06	4.42062
2056.99	3.61134
2059.92	4.30329
2062.84	4.92889
2065.76	4.16097
2068.68	4.20453
2071.6	4.95489
2074.52	4.66468
2077.44	3.74781
2080.36	3.59324
2083.27	4.96687
2086.19	5.04758
2089.1	5.31224
2092.01	4.72541
2094.93	4.66564
2097.84	5.34113
2100.75	5.73469
2103.66	7.09854
2106.56	7.97528
2109.47	8.37199
2112.37	7.94368
2115.28	8.07253
2118.18	8.25722
2121.09	8.84414
2123.99	8.24932
2126.89	8.68098
2129.79	9.42844
2132.68	10.5211
2135.58	10.6556
2138.48	10.0413
2141.37	11.6798
2144.26	12.3588
2147.16	13.5062
2150.05	13.6745
2152.94	14.8605
2155.83	15.6174
2158.72	16.5664
2161.6	16.8225
2164.49	17.1077
2167.38	18.5825
2170.26	20.3066
2173.14	20.035
2176.03	20.2632
2178.91	19.7531
2181.79	18.5383
2184.67	19.0219
2187.54	18.4751
2190.42	18.6065
2193.3	18.5079
2196.17	17.3455
2199.05	16.7744
2201.92	16.1195
2204.79	15.059
2207.66	13.4981
2210.53	12.7931
2213.4	11.6861
2216.27	10.4172
2219.13	8.31927
2222	9.26489
2224.86	8.62787
2227.72	8.35203
2230.59	9.03526
2233.45	8.81232
2236.31	9.28331
2239.17	9.69369
2242.03	9.36794
2244.88	9.01736
2247.74	9.0698
2250.59	9.78443
2253.45	10.246
2256.3	10.7642
2259.15	10.4156
2262	11.3858
2264.85	10.5141
2267.7	9.98929
2270.55	10.5683
2273.4	8.71224
2276.24	8.02506
2279.09	6.77086
2281.93	5.4038
2284.77	3.83268
2287.61	2.96828
2290.46	3.59632
2293.29	3.08451
2296.13	2.92815
2298.97	3.48293
2301.81	4.73488
2304.64	6.01405
2307.48	7.38732
2310.31	8.26588
2313.14	8.63984
2315.97	9.71225
2318.8	10.0259
2321.63	9.46917
2324.46	10.0835
2327.29	10.2716
2330.12	9.99619
2332.94	9.65354
2335.76	8.63559
2338.59	8.94202
2341.41	7.81114
2344.23	7.29439
2347.05	6.77592
2349.87	5.45435
2352.69	4.16783
2355.5	3.53913
2358.32	2.97462
2361.14	3.38045
2363.95	3.5734
2366.76	4.80712
2369.58	5.18061
2372.39	5.6225
2375.2	6.08544
2378	6.66639
2380.81	6.1944
2383.62	6.16405
2386.42	6.04304
2389.23	5.83789
2392.03	5.37083
2394.84	5.79496
2397.64	5.66036
2400.44	5.02089
2403.24	4.93272
2406.04	4.23053
2408.83	3.78857
2411.63	3.43377
2414.43	3.36141
2417.22	2.92436
2420.02	2.50851
2422.81	2.20034
2425.6	0.922545
2428.39	1.09447
2431.18	0.855514
2433.97	-0.911778
2436.76	-1.16697
2439.54	-1.42716
2442.33	-1.21622
2445.11	0.244371
2447.9	0.869359
2450.68	0.96282
2453.46	1.3645
2456.24	2.90792
2459.02	3.48856
2461.8	4.53652
2464.58	5.65756
2467.36	4.78514
2470.13	4.9951
2472.91	5.38012
2475.68	6.55113
2478.45	7.16753
2481.22	8.25421
2484	8.41963
2486.77	8.6345
2489.54	8.56993
2492.3	8.26756
2495.07	7.59057
2497.84	7.89197
2500.6	7.75294
2503.36	7.31603
2506.13	7.54437
2508.89	7.86847
2511.65	7.75483
2514.41	7.64754
2517.17	7.22542
2519.93	6.17082
2522.68	5.42578
2525.44	5.45004
2528.19	4.10806
2530.95	3.76831
2533.7	4.2544
2536.45	3.67089
2539.2	3.88746
2541.95	3.67998
2544.7	2.55335
2547.45	1.15362
2550.2	1.0861
2552.94	0.563205
2555.69	0.479992
2558.43	1.41939
2561.17	2.29432
2563.92	2.97838
2566.66	2.94449
2569.4	3.31513
2572.14	3.47413
2574.88	3.79337
2577.61	3.67054
2580.35	4.7367
2583.09	4.87588
2585.82	4.64348
2588.55	5.68504
2591.28	6.13625
2594.02	6.69332
2596.75	7.87903
2599.48	9.22774
2602.2	9.39321
2604.93	9.34541
2607.66	9.12638
2610.38	7.6424
2613.11	7.1113
2615.83	7.6266
2618.56	7.5359
2621.28	7.1492
2624	7.06174
2626.72	7.00902
2629.44	5.94726
2632.15	5.04524
2634.87	5.08996
2637.59	5.39297
2640.3	5.24926
2643.02	4.34506
2645.73	3.97436
2648.44	5.21045
2651.15	5.325
2653.86	5.06924
2656.57	5.17777
2659.28	6.24882
2661.99	5.90737
2664.69	7.49397
2667.4	7.39744
2670.1	7.29771
2672.81	8.00128
2675.51	8.12069
2678.21	9.00178
2680.91	9.578
2683.61	10.1717
2686.31	8.99419
2689	8.53024
2691.7	9.16871
2694.4	9.17943
2697.09	8.98042
2699.79	9.85111
2702.48	11.1359
2705.17	11.0191
2707.86	10.8742
2710.55	9.99412
2713.24	11.0863
2715.93	12.0816
2718.61	11.7366
2721.3	11.3912
2723.99	11.4163
2726.67	11.204
2729.35	11.1563
2732.04	10.9881
2734.72	9.31914
2737.4	9.65811
2740.08	9.31037
2742.76	8.40009
2745.43	8.81985
2748.11	9.49379
2750.79	9.23027
2753.46	8.74753
2756.13	8.36692
2758.81	8.25782
2761.48	8.15099
2764.15	7.7293
2766.82	7.45752
2769.49	7.48754
2772.16	6.25067
2774.82	6.41268
2777.49	6.36886
2780.16	5.84173
2782.82	5.51237
2785.48	4.64988
2788.15	3.2463
2790.81	3.30777
2793.47	3.01378
2796.13	2.19872
2798.79	0.932793
2801.44	0.250559
2804.1	0.283663
2806.76	0.134907
2809.41	1.50115
2812.07	2.88037
2814.72	3.82045
2817.37	2.74174
2820.02	3.29134
2822.67	5.11458
2825.32	6.54328
2827.97	6.49944
2830.62	7.81246
2833.26	9.28096
2835.91	11.4909
2838.55	13.8432
2841.2	17.3614
2843.84	21.0371
2846.48	24.2974
2849.12	28.3703
2851.76	32.9357
2854.4	36.7578
2857.04	41.0996
2859.68	44.9848
2862.32	48.3668
2864.95	50.8621
2867.58	54.8222
2870.22	57.9173
2872.85	61.3774
2875.48	64.6098
2878.11	66.5469
2880.74	68.0829
2883.37	70.551
2886	72.3678
2888.63	72.6545
2891.25	74.8113
2893.88	76.7068
2896.5	78.2141
2899.13	81.5749
2901.75	85.4795
2904.37	89.5925
2906.99	94.1689
2909.61	99.5773
2912.23	103.646
2914.85	109.154
2917.46	114.417
2920.08	118.164
2922.7	120.148
2925.31	122.012
2927.92	123.472
2930.53	123.866
2933.15	124.415
2935.76	124.011
2938.37	122.585
2940.98	121.185
2943.58	118.263
2946.19	115.045
2948.8	111.068
2951.4	106.285
2954.01	102.688
2956.61	98.7761
2959.21	93.9032
2961.81	89.8035
2964.41	85.6366
2967.01	81.9212
2969.61	77.4265
2972.21	73.3924
2974.81	69.3564
2977.4	64.812
2980	60.5601
2982.59	55.5938
2985.18	49.5844
2987.78	44.0022
2990.37	40.0673
2992.96	35.7127
2995.55	31.951
2998.14	27.6877
3000.72	23.4837
3003.31	19.3702
3005.9	16.4196
3008.48	13.7602
3011.07	11.491
3013.65	8.85241
3016.23	7.24076
3018.81	4.91661
3021.39	3.57118
3023.97	2.4572
3026.55	1.29103
3029.13	0.948512
3031.71	0.711944
3034.28	0.0274861
3036.86	-0.220304
3039.43	0.128356
3042.01	0.544394
3044.58	1.49743
3047.15	1.96649
3049.72	2.30597
3052.29	3.08669
3054.86	3.9237
3057.43	3.91548
3060	3.93998
3062.56	4.40542
3065.13	4.39823
3067.69	4.4927
3070.25	4.67645
3072.82	3.99573
3075.38	3.51409
3077.94	2.33045
3080.5	2.0532
3083.06	1.87098
3085.62	2.27971
3088.17	1.78889
3090.73	1.53638
3093.29	0.741034
3095.84	1.00956
3098.4	0.762065
3100.95	1.31665
3103.5	2.36515
3106.05	3.31074
3108.6	4.21684
3111.15	4.3486
3113.7	4.97764
3116.25	5.60783
3118.79	5.72596
3121.34	6.41284
3123.88	7.26813
3126.43	8.08955
3128.97	7.93193
3131.51	8.32381
3134.05	7.9804
3136.59	8.91371
3139.14	9.71305
3141.67	9.87983
3144.21	9.89517
3146.75	9.60379
3149.28	11.7974