File: data/Raman/poly_smoothed/Mb_10_14_09_1x_45s_532 nm_x100_100%_600 gr_mm_01.txt
#Acq. time (s)=	45
#Accumulations=	2
#Range (cm-¹)=	200...3150
#Windows=	2
#Auto scanning=	Off
#Autofocus=	Off
#Macrospot=	Off
#AutoExposure=	Off
#Spike filter=	Multiple accum.
#Delay time (s)=	0
#Binning=	1
#Readout mode=	Signal
#DeNoise=	Off
#ICS correction=	On
#Dark correction=	Off
#Inst. Process=	Off
#Detector Gain=	Best Dynamic Range
#Detector ADC=	20 kHz
#Detector temperature (°C)=	-70.08
#Instrument=	LabRAM HR Evol
#Detector=	Synapse
#Objective=	x100
#Grating=	600 gr/mm
#ND Filter=	100%
#Laser (nm)=	532
#Hole=	100.021
#Range=	Auto
#Laser Pol.=	No
#Raman. Pol.=	No
#Laser Pol. (°)=	-0.0007625
#Raman Pol. (°)=	89.9995
#Collection=	Microscope
#StageXY=	Marzhauser
#StageZ=	Marzhauser
#X (µm)=	-2405
#Y (µm)=	2128.3
#Z (µm)=	-40.8
#Full time(mm:ss)=	3:18
#Project=
#Sample=
#Site=
#Title=	Mb_10_14_09_2x_45s_532 nm_x100_100%_600 gr_mm
#Remark=
#Date=	07.07.2022 14:02
#Acquired=	07.07.2022 14:02:44
#Base:Fit=	10.08.2022 10:21:11
#Base:Sub=	10.08.2022 10:21:41
#Filter:Polynom=	16.08.2022 10:17:53
#AxisType[0]=Intens
#AxisUnit[0]=Cnt
#AxisType[1]=Spectr
#AxisUnit[1]=1/cm
200.43	5.09599
204.061	6.47712
207.688	5.57832
211.316	5.15632
214.941	6.43193
218.566	6.73791
222.188	9.21517
225.809	11.5457
229.43	14.0746
233.047	16.609
236.663	20.2002
240.278	20.2667
243.894	20.8928
247.506	20.1136
251.116	20.8282
254.725	20.1795
258.333	18.9694
261.939	17.6732
265.546	18.7658
269.15	17.0659
272.752	14.1443
276.353	11.9411
279.952	9.01894
283.55	8.14604
287.146	6.26317
290.739	3.78613
294.333	2.98619
297.925	4.07717
301.516	5.72473
305.106	7.47429
308.694	7.94488
312.279	8.60885
315.864	9.63919
319.448	11.734
323.029	11.4719
326.61	10.1366
330.19	9.80772
333.766	9.653
337.343	8.71756
340.917	7.37231
344.491	8.2608
348.062	8.90701
351.633	9.48283
355.201	10.0154
358.77	11.6992
362.335	13.8975
365.899	15.2045
369.464	18.3905
373.025	21.0481
376.585	23.7017
380.143	25.4195
383.702	29.1762
387.258	32.4864
390.812	34.8527
394.365	36.693
397.916	36.0501
401.467	35.7202
405.015	36.0449
408.565	35.1906
412.111	32.711
415.656	30.0378
419.197	27.5804
422.739	24.3577
426.279	21.4633
429.819	19.0719
433.356	17.8563
436.893	15.0082
440.428	12.3498
443.96	9.19735
447.492	8.74955
451.023	8.09606
454.553	8.11899
458.079	7.79753
461.606	9.15838
465.132	9.07858
468.654	9.88783
472.177	12.5942
475.696	13.8834
479.217	14.6656
482.733	17.2119
486.251	19.6847
489.765	22.7258
493.278	25.5973
496.791	27.7154
500.301	29.3527
503.81	31.686
507.319	33.2876
510.825	35.0995
514.33	35.4877
517.833	35.077
521.337	35.0863
524.838	33.0851
528.337	30.5393
531.835	28.4347
535.332	26.169
538.827	23.9409
542.321	21.2432
545.814	18.5685
549.305	15.0423
552.795	12.4376
556.284	9.9023
559.771	6.73397
563.257	3.87401
566.742	3.39633
570.223	3.20155
573.705	2.22697
577.185	2.38505
580.665	2.06681
584.141	2.51806
587.617	3.21193
591.092	3.67631
594.564	6.2809
598.037	6.62839
601.506	8.76914
604.976	9.86228
608.443	9.872
611.91	10.6652
615.374	12.2157
618.839	14.0567
622.3	13.6456
625.761	14.1711
629.221	14.8189
632.679	15.8275
636.135	16.6042
639.592	17.4766
643.045	17.6125
646.497	18.7448
649.948	18.2543
653.398	19.2924
656.846	18.3232
660.293	17.0509
663.738	16.0641
667.185	16.4744
670.628	17.8797
674.067	17.908
677.508	18.0981
680.947	18.7692
684.385	19.8438
687.821	22.2849
691.256	23.224
694.69	23.2066
698.121	24.5119
701.552	25.2151
704.982	27.0556
708.41	28.5891
711.836	31.4596
715.262	32.2725
718.685	34.2538
722.108	35.536
725.53	36.1059
728.949	37.8412
732.369	38.9983
735.785	39.1375
739.2	38.5703
742.616	39.549
746.028	41.5223
749.441	45.5288
752.851	48.32
756.26	49.4003
759.667	52.2373
763.075	54.2651
766.479	57.0165
769.883	61.9727
773.285	65.0532
776.686	66.5503
780.085	67.6205
783.484	69.9173
786.881	72.2823
790.276	73.0706
793.671	72.5852
797.064	72.5673
800.456	72.2543
803.846	72.0726
807.236	72.0289
810.624	71.0581
814.01	70.7762
817.394	70.1746
820.778	69.0088
824.161	69.3993
827.543	68.5429
830.921	69.2257
834.3	68.5877
837.676	67.7209
841.053	67.251
844.426	67.1733
847.8	66.5885
851.171	65.3632
854.542	62.8612
857.911	59.8843
861.279	57.5729
864.645	55.4224
868.01	54.2731
871.375	52.4439
874.737	51.3143
878.097	51.3331
881.457	51.8359
884.817	50.797
888.174	50.9972
891.53	50.1552
894.884	51.8085
898.237	52.9368
901.589	51.3759
904.94	51.0345
908.289	52.3891
911.637	53.7244
914.984	54.2691
918.33	55.2714
921.674	54.3841
925.015	55.4789
928.357	54.1651
931.698	52.4897
935.037	50.9719
938.373	48.718
941.71	46.6224
945.046	44.8338
948.378	44.3453
951.711	43.8009
955.043	41.6541
958.372	39.9124
961.701	36.8939
965.027	35.7938
968.354	37.2036
971.678	39.1322
975	41.4529
978.324	43.4179
981.644	42.5387
984.962	45.5366
988.282	46.8751
991.598	47.5931
994.913	46.7607
998.227	48.078
1001.54	47.7968
1004.85	48.0598
1008.16	48.6703
1011.47	48.5462
1014.78	50.5044
1018.08	52.0836
1021.39	52.862
1024.69	53.9115
1028	54.7101
1031.3	55.7595
1034.6	53.8943
1037.9	51.5506
1041.19	50.9021
1044.49	50.9532
1047.79	51.3925
1051.08	50.3467
1054.37	47.2931
1057.66	43.0414
1060.95	38.4311
1064.24	33.6333
1067.53	30.6942
1070.81	26.6165
1074.1	22.5848
1077.38	19.0692
1080.66	16.4383
1083.94	14.7134
1087.22	13.0256
1090.5	14.962
1093.78	19.0159
1097.05	20.7959
1100.33	22.2639
1103.6	23.1182
1106.87	24.6952
1110.15	25.2653
1113.41	26.3845
1116.68	25.2095
1119.95	24.9636
1123.21	24.2081
1126.48	22.5629
1129.74	21.7184
1133	19.1363
1136.26	17.5579
1139.52	15.3626
1142.78	13.494
1146.04	12.5989
1149.29	10.4686
1152.55	7.89634
1155.8	4.75551
1159.05	2.08345
1162.3	2.3437
1165.55	1.78297
1168.8	2.22104
1172.05	2.64063
1175.29	3.02191
1178.54	3.95523
1181.78	4.90371
1185.02	5.9582
1188.26	7.12356
1191.5	8.82725
1194.74	10.4016
1197.97	14.2487
1201.21	18.4565
1204.44	21.4621
1207.68	25.4278
1210.91	30.5923
1214.14	33.7802
1217.37	37.7881
1220.6	41.4051
1223.82	43.6844
1227.05	47.1515
1230.27	47.549
1233.49	49.1391
1236.72	50.8891
1239.94	52.412
1243.16	53.0077
1246.37	52.6723
1249.59	53.4588
1252.8	54.1843
1256.02	53.6948
1259.23	51.3864
1262.44	51.3481
1265.66	49.3478
1268.87	50.5519
1272.07	51.9148
1275.28	52.5718
1278.48	54.825
1281.69	54.4742
1284.89	55.8758
1288.09	57.1622
1291.3	59.6679
1294.49	63.0566
1297.69	64.3103
1300.89	67.137
1304.09	68.6738
1307.28	71.1189
1310.47	72.8484
1313.66	76.0798
1316.86	77.9163
1320.05	78.9182
1323.23	80.4588
1326.42	81.9166
1329.61	82.5656
1332.79	81.4473
1335.98	78.7744
1339.16	75.9656
1342.34	73.4038
1345.52	71.3904
1348.7	68.9884
1351.87	66.0542
1355.05	61.6488
1358.23	58.0373
1361.4	55.5262
1364.57	51.419
1367.74	47.8305
1370.91	44.762
1374.08	40.9895
1377.25	39.2566
1380.42	36.3646
1383.58	35.07
1386.75	34.0628
1389.91	31.9503
1393.07	31.6989
1396.23	30.9964
1399.39	31.0651
1402.55	31.599
1405.7	31.7829
1408.86	34.9562
1412.01	37.3274
1415.17	40.5443
1418.32	44.9951
1421.47	52.4411
1424.62	59.4567
1427.77	67.612
1430.92	74.945
1434.06	81.5797
1437.2	88.9531
1440.35	93.8925
1443.49	96.9866
1446.63	99.5273
1449.77	101.306
1452.91	100.391
1456.05	98.2168
1459.18	95.7014
1462.32	91.6353
1465.45	87.5369
1468.59	82.5085
1471.72	76.2855
1474.85	67.529
1477.98	60.3028
1481.11	53.1499
1484.23	47.8855
1487.36	41.8125
1490.48	36.7971
1493.61	32.3775
1496.73	29.6495
1499.85	27.958
1502.97	25.3394
1506.09	22.5828
1509.2	21.4214
1512.32	19.9035
1515.44	18.7054
1518.55	16.5306
1521.66	15.7811
1524.77	15.5547
1527.88	13.8982
1530.99	12.4243
1534.1	12.6901
1537.21	11.3372
1540.31	10.7396
1543.42	11.5017
1546.52	10.9872
1549.62	11.5735
1552.72	13.2402
1555.82	12.7913
1558.92	13.7462
1562.02	15.3988
1565.11	16.1341
1568.21	20.1424
1571.3	20.8455
1574.39	23.8156
1577.49	27.4005
1580.58	29.9748
1583.67	33.5242
1586.75	37.4196
1589.84	39.2391
1592.93	42.222
1596.01	43.8285
1599.09	44.7093
1602.18	45.3643
1605.26	45.8464
1608.34	46.7257
1611.41	47.0504
1614.49	48.0356
1617.57	48.306
1620.64	50.2637
1623.72	51.92
1626.79	54.194
1629.86	57.2519
1632.93	59.9181
1636	63.5236
1639.07	65.5435
1642.14	69.5508
1645.2	73.6024
1648.27	77.0642
1651.33	81.3487
1654.39	82.8751
1657.45	86.3069
1660.51	86.4729
1663.57	85.0087
1666.63	82.6254
1669.69	79.6336
1672.74	76.145
1675.79	71.7402
1678.85	66.0614
1681.9	59.126
1684.95	53.2099
1688	47.5235
1691.05	40.8592
1694.1	36.4502
1697.14	31.421
1700.19	27.3468
1703.23	23.8087
1706.27	18.4384
1709.32	15.9382
1712.35	12.2539
1715.39	11.0352
1718.43	11.6256
1721.47	10.6106
1724.5	10.4134
1727.54	9.91462
1730.57	10.2388
1733.61	8.92632
1736.64	7.83533
1739.67	7.45054
1742.7	5.79102
1745.72	5.43445
1748.75	3.68301
1751.78	1.8869
1754.8	1.89241
1757.82	2.21457
1760.85	2.22365
1763.87	2.52228
1766.89	2.16888
1769.91	2.8273
1772.92	3.14397
1775.94	3.16584
1778.96	2.36366
1781.97	3.11051
1784.98	4.72319
1788	5.34784
1791.01	6.6353
1794.01	7.05623
1797.02	6.74402
1800.03	7.20434
1803.04	7.08971
1806.04	6.83852
1809.05	6.18581
1812.05	6.2494
1815.05	5.43501
1818.05	4.19136
1821.05	4.21598
1824.05	4.29963
1827.05	4.86504
1830.04	5.48554
1833.04	5.48671
1836.03	5.5864
1839.03	6.05954
1842.02	6.34648
1845.01	7.151
1848	6.57182
1850.99	6.66847
1853.97	6.85308
1856.96	7.02392
1859.94	6.98247
1862.93	6.4127
1865.91	5.17424
1868.89	5.20541
1871.87	4.37634
1874.85	2.85363
1877.83	2.99649
1880.81	3.55521
1882.56	3.57146
1885.55	3.98483
1888.54	4.52285
1891.52	5.34853
1894.51	5.23521
1897.49	5.25957
1900.48	4.20373
1903.46	4.23455
1906.44	4.39665
1909.42	4.60745
1912.4	4.84863
1915.38	5.30543
1918.35	5.71664
1921.33	5.86538
1924.3	6.33185
1927.28	6.29428
1930.25	6.59031
1933.22	6.85196
1936.19	6.32506
1939.16	8.8932
1942.13	9.707
1945.09	9.8054
1948.06	10.7561
1951.03	11.813
1953.99	11.9039
1956.95	12.7301
1959.91	13.1244
1962.87	13.187
1965.83	12.309
1968.79	11.2271
1971.75	10.7418
1974.7	11.3779
1977.66	11.6007
1980.61	11.8754
1983.56	12.9194
1986.52	12.0683
1989.47	12.8241
1992.41	13.238
1995.36	13.9387
1998.31	14.7189
2001.26	15.9794
2004.2	15.7976
2007.15	17.0784
2010.09	18.0268
2013.03	18.2645
2015.97	17.3467
2018.91	16.7341
2021.85	16.2382
2024.79	15.576
2027.72	17.0267
2030.66	17.8017
2033.59	17.5259
2036.53	17.5414
2039.46	17.5545
2042.39	17.8819
2045.32	17.5863
2048.25	16.0605
2051.18	15.6899
2054.1	15.1579
2057.03	14.3043
2059.95	13.6908
2062.88	14.0352
2065.8	13.125
2068.72	12.9531
2071.64	12.7717
2074.56	12.2232
2077.48	12.1225
2080.39	12.644
2083.31	11.644
2086.22	11.1992
2089.14	12.032
2092.05	13.0136
2094.96	14.1815
2097.87	15.6645
2100.78	16.2032
2103.69	17.1688
2106.6	18.0918
2109.51	18.8183
2112.41	19.5003
2115.32	20.4801
2118.22	21.639
2121.12	21.6874
2124.02	22.032
2126.92	22.316
2129.82	23.3941
2132.72	24.3241
2135.62	24.5692
2138.51	25.8601
2141.41	28.3443
2144.3	30.8582
2147.19	32.1235
2150.09	32.8596
2152.97	34.443
2155.86	35.7166
2158.75	38.1507
2161.64	40.0511
2164.53	42.4066
2167.41	43.8505
2170.3	44.0222
2173.18	45.2877
2176.06	46.6173
2178.94	47.9891
2181.82	47.5257
2184.7	46.903
2187.58	45.9588
2190.46	44.5463
2193.33	43.2398
2196.21	42.2613
2199.08	40.5928
2201.95	39.7124
2204.83	37.1672
2207.7	35.9691
2210.57	34.7052
2213.43	32.3427
2216.3	29.9253
2219.17	27.8674
2222.03	26.3176
2224.9	25.2258
2227.76	24.2911
2230.62	22.2684
2233.49	21.683
2236.34	21.2201
2239.2	19.923
2242.06	19.2036
2244.92	18.4038
2247.78	17.3842
2250.63	16.0571
2253.48	13.4699
2256.34	12.6551
2259.19	12.7426
2262.04	12.6568
2264.89	12.3162
2267.74	11.2654
2270.59	10.8675
2273.43	11.1236
2276.28	10.0301
2279.12	9.42723
2281.97	8.7791
2284.81	9.26078
2287.65	8.68192
2290.49	9.08063
2293.33	8.188
2296.17	8.13045
2299.01	10.2119
2301.84	11.4044
2304.68	12.8109
2307.51	13.689
2310.35	14.0589
2313.18	15.2888
2316.01	15.0375
2318.84	15.3731
2321.67	15.0918
2324.5	14.5816
2327.33	13.4052
2330.15	12.4447
2332.98	11.9766
2335.8	11.5113
2338.62	9.7961
2341.45	8.15946
2344.27	6.59356
2347.09	5.74787
2349.91	4.64108
2352.72	3.24661
2355.54	3.20295
2358.36	2.40519
2361.17	1.85601
2363.98	2.44705
2366.8	2.9524
2369.61	3.31265
2372.42	3.12913
2375.23	2.89043
2378.04	2.47925
2380.85	2.63506
2383.66	2.52925
2386.46	2.35116
2389.26	2.47032
2392.07	2.30435
2394.87	1.14543
2397.67	1.58776
2400.47	1.73751
2403.27	1.7696
2406.07	1.82013
2408.87	1.29992
2411.67	2.10369
2414.46	3.61322
2417.26	3.93675
2420.05	3.67117
2422.84	4.81175
2425.64	5.14639
2428.43	4.80708
2431.22	4.61048
2434.01	4.93946
2436.79	3.90591
2439.58	3.5276
2442.37	3.83677
2445.15	2.65703
2447.93	1.44924
2450.72	0.873793
2453.5	0.841014
2456.28	1.09465
2459.06	1.37469
2461.84	0.638618
2464.62	0.228083
2467.39	0.54524
2470.17	1.06272
2472.94	1.2698
2475.72	1.77275
2478.49	1.32591
2481.26	1.21877
2484.03	1.2091
2486.8	1.20462
2489.57	0.890476
2492.34	0.845538
2495.1	1.41192
2497.87	1.65376
2500.63	1.4569
2503.4	1.23841
2506.16	1.11835
2508.92	1.5891
2511.68	1.34234
2514.44	-0.0994301
2517.2	-0.179263
2519.96	0.975812
2522.72	2.54895
2525.47	3.45985
2528.23	3.63062
2530.98	4.89597
2533.74	5.42552
2536.49	6.58966
2539.24	7.39031
2541.99	7.21233
2544.74	7.20464
2547.49	6.07622
2550.23	6.04416
2552.98	6.40198
2555.72	6.0922
2558.47	7.05953
2561.21	7.00891
2563.95	7.20562
2566.69	7.46988
2569.43	7.4197
2572.17	7.84784
2574.91	7.82991
2577.65	6.84748
2580.39	5.57022
2583.12	5.26183
2585.85	5.51274
2588.59	5.2935
2591.32	5.79217
2594.05	5.43614
2596.78	4.5122
2599.51	4.37117
2602.24	4.28073
2604.97	4.32732
2607.69	3.87967
2610.42	2.4767
2613.14	3.15361
2615.87	2.63437
2618.59	2.44007
2621.31	3.11237
2624.03	3.41384
2626.75	3.23816
2629.47	3.50703
2632.19	3.59391
2634.91	4.09453
2637.62	3.75343
2640.34	4.1768
2643.05	3.76533
2645.76	3.02754
2648.48	3.10337
2651.19	3.13818
2653.9	3.79253
2656.6	3.58679
2659.31	3.30939
2662.02	3.17318
2664.73	4.19765
2667.43	5.02036
2670.14	4.85704
2672.84	4.73133
2675.54	4.96131
2678.24	4.9978
2680.94	5.43172
2683.64	4.85854
2686.34	5.39364
2689.04	4.85956
2691.74	4.80554
2694.43	4.50486
2697.13	4.1099
2699.82	4.72763
2702.51	4.81136
2705.21	4.88632
2707.9	4.89768
2710.58	4.9013
2713.27	6.64797
2715.96	7.44366
2718.65	8.27009
2721.33	9.05759
2724.02	8.63709
2726.71	10.1243
2729.39	10.3557
2732.07	9.93713
2734.75	9.49427
2737.43	9.40122
2740.11	8.96816
2742.79	8.44504
2745.47	7.95991
2748.14	6.5168
2750.82	5.8994
2753.49	5.48536
2756.17	4.18275
2758.84	3.10945
2761.51	2.98009
2764.18	1.25145
2766.85	1.69069
2769.52	1.36545
2772.19	0.938662
2774.86	0.281142
2777.52	0.741666
2780.19	1.05132
2782.85	1.04783
2785.52	0.916096
2788.18	0.13022
2790.84	-0.748139
2793.5	-0.549508
2796.16	-0.859607
2798.82	-0.994734
2801.48	-1.38177
2804.13	-1.52156
2806.79	-1.66161
2809.45	-2.0168
2812.1	-1.4629
2814.75	-1.07776
2817.41	1.19869
2820.06	3.19777
2822.71	6.40427
2825.36	10.2438
2828	14.4809
2830.65	18.7385
2833.3	23.7531
2835.94	27.284
2838.59	33.2487
2841.23	39.1298
2843.87	48.0633
2846.52	56.7005
2849.16	65.6309
2851.8	76.4307
2854.44	88.0632
2857.08	100.387
2859.71	111.895
2862.35	122.388
2864.98	131.174
2867.62	140.996
2870.25	151.463
2872.88	159.371
2875.52	168.3
2878.15	174.578
2880.78	182.105
2883.41	188.276
2886.03	194.56
2888.66	200.221
2891.29	206.298
2893.91	211.101
2896.54	216.701
2899.16	223.662
2901.78	232.678
2904.4	243.056
2907.02	256.102
2909.64	268.696
2912.26	283.162
2914.88	298.172
2917.5	313.366
2920.11	326.113
2922.73	337.275
2925.34	345.262
2927.96	350.626
2930.57	355.136
2933.18	357.339
2935.79	355.964
2938.4	350.842
2941.01	343.112
2943.62	334.309
2946.22	325.175
2948.83	315.299
2951.43	303.892
2954.04	290.494
2956.64	277.617
2959.24	265.409
2961.84	253.289
2964.45	241.914
2967.05	229.922
2969.64	219.374
2972.24	210.269
2974.84	199.948
2977.43	190.858
2980.03	180.383
2982.62	168.821
2985.22	157.197
2987.81	144.559
2990.4	131.114
2992.99	118.72
2995.58	106.517
2998.17	94.4328
3000.76	82.3574
3003.34	71.4651
3005.93	62.1916
3008.52	53.768
3011.1	46.2355
3013.68	38.8579
3016.27	32.253
3018.85	27.4626
3021.43	23.4988
3024.01	19.0837
3026.59	16.3804
3029.16	14.7483
3031.74	13.3542
3034.32	13.7119
3036.89	14.0546
3039.47	14.5606
3042.04	15.5059
3044.61	16.491
3047.18	17.9988
3049.75	18.8044
3052.32	19.3747
3054.89	19.4705
3057.46	20.1724
3060.03	19.2416
3062.59	19.9203
3065.16	18.4219
3067.72	17.4151
3070.29	16.1454
3072.85	15.5168
3075.41	13.9758
3077.97	12.5007
3080.53	10.3455
3083.09	8.83736
3085.65	6.43022
3088.21	5.38947
3090.76	3.80912
3093.32	2.72246
3095.87	1.54294
3098.43	1.35115
3100.98	1.125
3103.53	1.45763
3106.08	1.71106
3108.63	2.49038
3111.18	2.59458
3113.73	3.75064
3116.28	3.74223
3118.83	4.01217
3121.37	5.30306
3123.92	6.0403
3126.46	7.93409
3129	8.85215
3131.55	11.4565
3134.09	13.8796
3136.63	15.9085
3139.17	17.5712
3141.71	19.5725
3144.24	21.2792
3146.78	23.0697
3149.32	25.2211