File: data/Raman/poly_smoothed/Mb_10_14_25_1x_45s_532 nm_x100_100%_600 gr_mm_01.txt
#Acq. time (s)=	45
#Accumulations=	2
#Range (cm-¹)=	200...3150
#Windows=	2
#Auto scanning=	Off
#Autofocus=	Off
#Macrospot=	Off
#AutoExposure=	Off
#Spike filter=	Multiple accum.
#Delay time (s)=	0
#Binning=	1
#Readout mode=	Signal
#DeNoise=	Off
#ICS correction=	On
#Dark correction=	Off
#Inst. Process=	Off
#Detector Gain=	Best Dynamic Range
#Detector ADC=	20 kHz
#Detector temperature (°C)=	-69.85
#Instrument=	LabRAM HR Evol
#Detector=	Synapse
#Objective=	x100
#Grating=	600 gr/mm
#ND Filter=	100%
#Laser (nm)=	532
#Hole=	100.021
#Range=	Auto
#Laser Pol.=	No
#Raman. Pol.=	No
#Laser Pol. (°)=	-0.0007625
#Raman Pol. (°)=	89.9995
#Collection=	Microscope
#StageXY=	Marzhauser
#StageZ=	Marzhauser
#X (µm)=	-612.9
#Y (µm)=	-1580.8
#Z (µm)=	89.85
#Full time(mm:ss)=	3:18
#Project=
#Sample=
#Site=
#Title=	Mb_10_14_25_2x_45s_532 nm_x100_100%_600 gr_mm
#Remark=
#Date=	11.07.2022 10:24
#Acquired=	11.07.2022 10:24:35
#Base:Fit=	10.08.2022 10:21:11
#Base:Sub=	10.08.2022 10:21:41
#Filter:Polynom=	16.08.2022 10:17:53
#AxisType[0]=Intens
#AxisUnit[0]=Cnt
#AxisType[1]=Spectr
#AxisUnit[1]=1/cm
200.388	2.71966
204.019	3.33103
207.646	2.39965
211.274	2.12271
214.899	3.4811
218.524	5.82801
222.146	8.1366
225.766	10.6583
229.388	12.7733
233.005	16.0093
236.621	17.388
240.236	18.7109
243.852	20.9753
247.464	21.783
251.074	23.1673
254.683	23.6561
258.291	24.5243
261.897	24.9838
265.504	27.0698
269.108	26.8542
272.71	26.2313
276.311	25.4553
279.91	23.7613
283.508	23.1891
287.105	22.0111
290.698	20.392
294.291	20.492
297.884	20.4099
301.475	21.8701
305.064	22.2708
308.652	22.4821
312.237	21.0436
315.822	19.7327
319.406	19.6506
322.987	18.6668
326.568	16.7731
330.148	17.308
333.724	15.3429
337.301	14.1765
340.875	13.0122
344.449	12.1935
348.02	12.7558
351.592	11.9228
355.16	10.3835
358.728	11.314
362.294	12.0619
365.858	13.0542
369.422	14.9854
372.983	18.029
376.543	18.648
380.102	21.4828
383.661	23.7918
387.216	26.0936
390.771	27.0407
394.324	28.3716
397.875	28.3564
401.425	27.7511
404.974	27.8808
408.524	26.3063
412.07	26.4214
415.614	25.5184
419.156	24.3103
422.698	21.9648
426.238	19.5225
429.777	16.8297
433.315	15.1096
436.852	12.1026
440.387	10.4639
443.919	8.83823
447.451	8.32288
450.982	7.77033
454.512	5.49802
458.038	6.16605
461.565	5.91214
465.091	5.25736
468.613	4.69253
472.136	5.29094
475.655	4.37642
479.176	6.36635
482.692	8.57444
486.21	10.1765
489.724	10.4741
493.237	13.2657
496.75	16.228
500.26	17.3624
503.769	18.7136
507.279	19.5186
510.785	21.0163
514.289	21.1555
517.793	21.9105
521.297	21.9231
524.797	22.7207
528.297	22.9217
531.795	21.2332
535.291	21.7693
538.787	20.5502
542.281	17.514
545.773	16.878
549.264	13.8173
552.754	11.8566
556.243	11.1794
559.73	9.48173
563.216	8.73247
566.701	8.01804
570.182	6.46088
573.664	4.47521
577.145	3.96845
580.624	2.70485
584.1	1.38731
587.577	1.82683
591.052	2.75823
594.524	2.78158
597.997	1.45147
601.466	0.152889
604.936	0.445961
608.403	1.86841
611.87	1.98817
615.334	2.75737
618.799	5.25782
622.26	6.43279
625.72	7.03575
629.181	7.45798
632.638	9.43139
636.095	9.68741
639.551	9.96389
643.005	10.4715
646.457	11.9336
649.908	12.4955
653.357	11.6831
656.806	10.4035
660.253	10.2407
663.7	9.36967
667.145	8.51313
670.588	7.85264
674.027	7.82755
677.468	8.9296
680.907	7.93386
684.345	8.2517
687.781	8.94104
691.216	10.3951
694.65	11.576
698.081	12.3882
701.512	15.9198
704.942	16.6323
708.371	18.0097
711.796	19.3557
715.222	20.4045
718.645	22.6078
722.068	24.1154
725.49	26.4776
728.909	28.7429
732.329	31.6161
735.745	32.3532
739.16	32.4956
742.576	33.1599
745.988	35.7816
749.401	37.9751
752.811	41.2739
756.22	44.9517
759.627	49.0158
763.035	51.4581
766.44	52.3176
769.843	54.1165
773.245	56.9648
776.646	58.3479
780.046	60.6118
783.444	62.9245
786.841	64.3972
790.237	64.2474
793.631	66.0009
797.024	67.0673
800.416	67.9775
803.807	68.8816
807.196	68.8857
810.584	68.5629
813.971	69.307
817.354	69.5619
820.739	67.6891
824.122	66.9839
827.503	69.0413
830.882	69.4051
834.261	71.0465
837.637	69.316
841.013	66.8209
844.389	63.1514
847.761	61.0074
851.131	58.298
854.503	56.493
857.871	53.6496
861.24	51.2277
864.606	48.3033
867.97	45.7413
871.336	43.7746
874.698	42.7078
878.058	41.857
881.418	39.1535
884.778	39.0888
888.135	37.3845
891.49	37.1778
894.845	37.4575
898.198	38.1104
901.55	36.773
904.901	37.5745
908.25	37.6531
911.598	38.8164
914.945	38.344
918.291	37.404
921.635	37.493
924.978	35.0725
928.318	35.0407
931.659	33.5398
934.998	34.19
938.336	33.3525
941.671	32.3897
945.007	30.3948
948.339	29.865
951.672	30.5662
955.004	30.8254
958.333	29.483
961.662	27.9165
964.989	31.1243
968.315	32.9544
971.639	34.1051
974.962	34.8478
978.285	35.3378
981.605	34.5843
984.924	35.8404
988.243	35.0005
991.56	35.3092
994.875	35.3038
998.188	35.6647
1001.5	33.9657
1004.81	32.7799
1008.12	32.0484
1011.43	32.8407
1014.74	32.0862
1018.05	32.8465
1021.35	31.5999
1024.65	31.4569
1027.96	30.5205
1031.26	29.2242
1034.56	28.3112
1037.86	27.3837
1041.16	27.6112
1044.45	29.4474
1047.75	29.9034
1051.04	28.6371
1054.33	26.1865
1057.62	23.4361
1060.91	21.3974
1064.2	19.7965
1067.49	18.2392
1070.77	17.0795
1074.06	14.0313
1077.34	12.2218
1080.62	10.2266
1083.91	8.29982
1087.18	8.35006
1090.46	9.56869
1093.74	8.1058
1097.02	7.65911
1100.29	9.50788
1103.56	8.98359
1106.84	8.87884
1110.11	9.06128
1113.38	9.03235
1116.64	9.39118
1119.91	10.3605
1123.18	10.1792
1126.44	9.53965
1129.7	8.22699
1132.97	6.5814
1136.23	6.25501
1139.49	4.92154
1142.74	4.66593
1146	6.79197
1149.26	6.29097
1152.51	3.51289
1155.76	2.83396
1159.01	3.68418
1162.27	2.72043
1165.51	2.68875
1168.76	3.85036
1172.01	4.9678
1175.25	4.78708
1178.5	5.80379
1181.74	7.26699
1184.98	6.99152
1188.22	9.87008
1191.46	11.0363
1194.7	12.5402
1197.94	13.6839
1201.17	15.9072
1204.41	16.4742
1207.64	17.8917
1210.87	19.8384
1214.1	23.457
1217.33	23.6949
1220.56	24.588
1223.79	26.6595
1227.01	28.7902
1230.23	29.7278
1233.46	30.8296
1236.68	33.4242
1239.9	35.2141
1243.12	38.5585
1246.34	40.656
1249.55	41.2546
1252.77	41.3215
1255.98	40.6891
1259.2	41.7211
1262.41	42.4523
1265.62	44.0782
1268.83	43.6512
1272.03	43.4113
1275.24	44.7988
1278.45	43.2806
1281.65	43.0297
1284.85	42.7818
1288.06	42.3063
1291.26	43.2374
1294.46	43.3726
1297.66	43.1265
1300.85	44.4142
1304.05	45.0677
1307.24	46.3382
1310.43	48.1558
1313.63	51.2069
1316.82	53.4293
1320.01	54.0117
1323.2	56.9109
1326.38	56.7914
1329.57	56.1975
1332.76	56.0311
1335.94	56.3361
1339.12	56.7104
1342.3	55.5124
1345.48	53.6949
1348.66	52.0857
1351.84	51.715
1355.01	49.524
1358.19	46.0099
1361.36	44.4107
1364.53	41.7999
1367.71	40.0438
1370.88	38.137
1374.04	37.4401
1377.21	36.9449
1380.38	35.6968
1383.54	35.8058
1386.71	36.6909
1389.87	36.9729
1393.03	37.7293
1396.19	37.8869
1399.35	38.4664
1402.51	38.294
1405.67	38.2155
1408.82	38.8454
1411.98	41.748
1415.13	44.0527
1418.28	47.9925
1421.43	51.5676
1424.58	55.6019
1427.73	60.644
1430.88	65.037
1434.02	66.4805
1437.17	69.2433
1440.31	70.8695
1443.45	71.6299
1446.6	73.3607
1449.74	75.0533
1452.87	75.8606
1456.01	74.339
1459.15	73.7825
1462.28	72.9209
1465.42	71.1562
1468.55	68.7811
1471.68	64.6218
1474.81	60.6211
1477.94	56.1733
1481.07	52.1042
1484.2	48.6412
1487.32	45.9435
1490.45	42.5651
1493.57	42.4325
1496.69	41.8145
1499.81	41.2244
1502.93	39.3257
1506.05	37.8663
1509.17	35.5953
1512.28	32.6089
1515.4	30.9682
1518.51	29.7933
1521.63	28.5506
1524.74	28.3162
1527.85	26.9345
1530.96	26.9665
1534.06	25.9739
1537.17	26.232
1540.28	26.6131
1543.38	27.4658
1546.48	27.6984
1549.59	28.4096
1552.69	28.9249
1555.79	29.5289
1558.88	29.882
1561.98	30.3788
1565.08	32.2049
1568.17	35.098
1571.27	37.1378
1574.36	36.78
1577.45	37.7563
1580.54	38.2814
1583.63	40.068
1586.72	40.8853
1589.8	42.5471
1592.89	44.152
1595.97	45.8096
1599.06	45.4013
1602.14	45.7349
1605.22	45.613
1608.3	45.06
1611.38	45.5731
1614.46	45.9665
1617.53	46.9408
1620.61	47.6598
1623.68	47.7884
1626.75	50.6563
1629.82	51.7393
1632.9	53.3516
1635.96	55.7032
1639.03	57.6644
1642.1	60.9701
1645.16	62.1416
1648.23	63.5492
1651.29	65.103
1654.36	67.0413
1657.42	67.2125
1660.48	67.6726
1663.53	68.4315
1666.59	68.0235
1669.65	65.1039
1672.7	62.8304
1675.76	59.1412
1678.81	56.2041
1681.86	51.245
1684.91	47.8102
1687.96	42.6041
1691.01	37.9893
1694.06	34.2293
1697.11	31.2118
1700.15	28.8387
1703.2	25.7674
1706.24	21.8415
1709.28	19.1414
1712.32	16.6338
1715.36	15.461
1718.4	13.9402
1721.43	13.3154
1724.47	12.3908
1727.5	11.805
1730.54	10.5393
1733.57	11.0231
1736.6	10.122
1739.63	9.43353
1742.66	9.15249
1745.69	9.97343
1748.72	10.3657
1751.74	9.50857
1754.77	10.8815
1757.79	10.2882
1760.81	10.1717
1763.83	10.0204
1766.85	9.5607
1769.87	9.98229
1772.89	10.8697
1775.91	10.9676
1778.92	10.6747
1781.94	10.7531
1784.95	9.41445
1787.96	9.41808
1790.97	9.28036
1793.98	8.79091
1796.99	7.83386
1800	6.78783
1803	6.62498
1806.01	6.34936
1809.01	5.51639
1812.02	5.57314
1815.02	5.03494
1818.02	5.25648
1821.02	5.51013
1824.02	5.92446
1827.01	6.05207
1830.01	6.51211
1833	6.11703
1836	6.05406
1838.99	6.5554
1841.98	8.12245
1844.97	9.58947
1847.96	10.2347
1850.95	10.3459
1853.94	9.40112
1856.92	8.3017
1859.91	7.83862
1862.89	6.90862
1865.88	7.05736
1868.86	7.16507
1871.84	7.03684
1874.82	7.59373
1877.8	7.80218
1880.77	7.05459
1882.52	8.00466
1885.51	7.6364
1888.5	7.16256
1891.49	6.76386
1894.47	6.4248
1897.46	5.85827
1900.44	4.86993
1903.42	3.81411
1906.4	2.93448
1909.38	2.97442
1912.36	3.71738
1915.34	3.33863
1918.32	3.55097
1921.29	1.72779
1924.27	1.33469
1927.24	1.10845
1930.21	1.49819
1933.18	2.16326
1936.15	3.48168
1939.12	4.68851
1942.09	4.48158
1945.06	5.16382
1948.02	4.45971
1950.99	4.52316
1953.95	4.84253
1956.91	4.94339
1959.87	4.23644
1962.84	3.87948
1965.79	4.20468
1968.75	3.85753
1971.71	3.85469
1974.66	3.64993
1977.62	4.15874
1980.57	5.08211
1983.53	5.89353
1986.48	5.59673
1989.43	4.63483
1992.38	4.74667
1995.33	5.24512
1998.27	5.67866
2001.22	6.24468
2004.16	6.2399
2007.11	5.56087
2010.05	5.02762
2012.99	4.61002
2015.93	3.89416
2018.87	3.44105
2021.81	3.84614
2024.75	4.353
2027.69	4.74714
2030.62	4.75653
2033.56	5.13656
2036.49	5.79381
2039.42	6.59694
2042.35	7.23672
2045.28	8.32342
2048.21	9.10758
2051.14	10.1497
2054.06	10.2109
2056.99	10.487
2059.92	9.64831
2062.84	9.17004
2065.76	8.41166
2068.68	8.49506
2071.6	8.35612
2074.52	8.11172
2077.44	6.13664
2080.36	6.03199
2083.27	6.41019
2086.19	6.2939
2089.1	7.34835
2092.01	8.2706
2094.93	8.43177
2097.84	9.3173
2100.75	9.38545
2103.66	9.62566
2106.56	10.2673
2109.47	11.0365
2112.37	10.8737
2115.28	12.1815
2118.18	13.5584
2121.09	14.4552
2123.99	15.5016
2126.89	16.0082
2129.79	16.6909
2132.68	16.545
2135.58	17.4652
2138.48	17.5126
2141.37	19.0713
2144.26	19.3598
2147.16	20.3641
2150.05	21.9837
2152.94	22.6306
2155.83	23.6071
2158.72	23.7998
2161.6	24.215
2164.49	25.4547
2167.38	25.7792
2170.26	25.5676
2173.14	25.3188
2176.03	25.2836
2178.91	25.5432
2181.79	25.4887
2184.67	25.2224
2187.54	25.2823
2190.42	24.2682
2193.3	22.6219
2196.17	22.4192
2199.05	21.9754
2201.92	21.6224
2204.79	20.8879
2207.66	19.6315
2210.53	19.4209
2213.4	18.1289
2216.27	17.6195
2219.13	16.5951
2222	15.9075
2224.86	14.3734
2227.72	12.7933
2230.59	12.2228
2233.45	11.6866
2236.31	11.6244
2239.17	10.777
2242.03	10.3865
2244.88	9.11053
2247.74	8.46453
2250.59	7.21929
2253.45	6.61862
2256.3	5.24533
2259.15	4.41237
2262	3.76713
2264.85	4.43209
2267.7	4.80289
2270.55	5.83783
2273.4	5.3708
2276.24	5.71323
2279.09	6.37079
2281.93	6.2827
2284.77	5.99485
2287.61	7.4349
2290.46	6.5464
2293.29	5.85482
2296.13	6.8816
2298.97	7.80085
2301.81	8.47961
2304.64	10.0514
2307.48	10.4904
2310.31	10.8884
2313.14	9.73468
2315.97	9.12105
2318.8	9.34058
2321.63	8.65187
2324.46	7.9238
2327.29	6.37326
2330.12	5.47759
2332.94	5.90497
2335.76	5.81223
2338.59	5.49507
2341.41	4.84634
2344.23	3.38729
2347.05	3.37665
2349.87	2.46684
2352.69	1.20782
2355.5	1.71718
2358.32	1.95419
2361.14	0.699635
2363.95	3.3775
2366.76	5.54201
2369.58	5.41616
2372.39	5.5776
2375.2	6.11415
2378	6.97769
2380.81	7.21058
2383.62	7.60575
2386.42	7.12686
2389.23	7.08826
2392.03	6.63976
2394.84	6.22631
2397.64	5.75147
2400.44	6.51273
2403.24	7.01008
2406.04	6.573
2408.83	5.28955
2411.63	4.71368
2414.43	4.08159
2417.22	4.78716
2420.02	5.30262
2422.81	6.00048
2425.6	6.66776
2428.39	6.90431
2431.18	7.31491
2433.97	7.84752
2436.76	6.89406
2439.54	6.19223
2442.33	6.68299
2445.11	6.78429
2447.9	6.71003
2450.68	5.90348
2453.46	5.14096
2456.24	3.82603
2459.02	3.45018
2461.8	3.0592
2464.58	1.72244
2467.36	2.05753
2470.13	1.96485
2472.91	0.591894
2475.68	0.253469
2478.45	0.518808
2481.22	0.781163
2484	0.858142
2486.77	0.319653
2489.54	-0.74524
2492.3	-1.07415
2495.07	-0.949341
2497.84	-1.09689
2500.6	-1.83516
2503.36	-1.79689
2506.13	-1.0124
2508.89	-0.0624007
2511.65	0.759699
2514.41	2.12227
2517.17	2.78476
2519.93	2.9288
2522.68	2.98544
2525.44	3.11054
2528.19	3.70011
2530.95	4.1995
2533.7	4.57856
2536.45	5.98048
2539.2	6.68495
2541.95	7.27392
2544.7	8.04696
2547.45	7.53165
2550.2	7.24396
2552.94	7.25801
2555.69	7.88041
2558.43	9.22056
2561.17	9.41083
2563.92	10.0816
2566.66	10.1287
2569.4	10.3674
2572.14	11.2869
2574.88	11.5394
2577.61	11.548
2580.35	11.5877
2583.09	11.0195
2585.82	9.25882
2588.55	8.95607
2591.28	8.23031
2594.02	7.49205
2596.75	6.51232
2599.48	5.42226
2602.2	4.10558
2604.93	3.01989
2607.66	2.6
2610.38	2.74364
2613.11	2.16438
2615.83	1.87817
2618.56	2.93512
2621.28	3.02102
2624	3.9378
2626.72	4.75336
2629.44	5.18331
2632.15	4.77068
2634.87	5.89065
2637.59	5.98943
2640.3	6.53533
2643.02	7.48147
2645.73	8.47896
2648.44	9.19621
2651.15	9.66839
2653.86	10.0721
2656.57	10.695
2659.28	10.1546
2661.99	10.3881
2664.69	9.95321
2667.4	9.96631
2670.1	9.75666
2672.81	9.66557
2675.51	9.63923
2678.21	9.02025
2680.91	7.95548
2683.61	8.09404
2686.31	7.26871
2689	7.10209
2691.7	7.48602
2694.4	7.06374
2697.09	6.98425
2699.79	6.49134
2702.48	5.75692
2705.17	5.82236
2707.86	5.77253
2710.55	6.4545
2713.24	6.27898
2715.93	6.75966
2718.61	7.38656
2721.3	7.17771
2723.99	8.05191
2726.67	9.10928
2729.35	9.7344
2732.04	9.75839
2734.72	8.92819
2737.4	8.61662
2740.08	8.32673
2742.76	8.35147
2745.43	8.12613
2748.11	8.65132
2750.79	10.2646
2753.46	10.1014
2756.13	10.1757
2758.81	9.47596
2761.48	9.64246
2764.15	8.02324
2766.82	7.39238
2769.49	7.32503
2772.16	6.49872
2774.82	5.94839
2777.49	5.27864
2780.16	4.92212
2782.82	4.01896
2785.48	3.38187
2788.15	3.03274
2790.81	2.04206
2793.47	2.1233
2796.13	1.59497
2798.79	0.92036
2801.44	0.165048
2804.1	0.842988
2806.76	0.872285
2809.41	0.657973
2812.07	1.29326
2814.72	2.87242
2817.37	3.80174
2820.02	5.49472
2822.67	7.62174
2825.32	9.36061
2827.97	11.3309
2830.62	14.1383
2833.26	17.6606
2835.91	20.829
2838.55	25.0909
2841.2	29.6993
2843.84	35.5033
2846.48	42.8243
2849.12	51.4842
2851.76	59.3436
2854.4	67.5921
2857.04	77.4356
2859.68	85.9934
2862.32	93.0909
2864.95	100.652
2867.58	108.205
2870.22	115.415
2872.85	120.87
2875.48	127.099
2878.11	132.653
2880.74	136.722
2883.37	140.259
2886	142.757
2888.63	146.427
2891.25	148.77
2893.88	153.013
2896.5	157.578
2899.13	162.193
2901.75	167.83
2904.37	175.878
2906.99	185.498
2909.61	195.918
2912.23	207.698
2914.85	217.478
2917.46	227.29
2920.08	236.557
2922.7	242.742
2925.31	248.584
2927.92	252.343
2930.53	254.591
2933.15	255.186
2935.76	253.35
2938.37	248.951
2940.98	242.977
2943.58	235.477
2946.19	225.982
2948.8	216.942
2951.4	207.241
2954.01	197.992
2956.61	188.006
2959.21	177.816
2961.81	166.629
2964.41	156.834
2967.01	148.567
2969.61	141.086
2972.21	132.382
2974.81	124.249
2977.4	117.354
2980	108.257
2982.59	99.8148
2985.18	91.673
2987.78	83.2857
2990.37	76.0975
2992.96	68.1881
2995.55	59.939
2998.14	51.8569
3000.72	44.5147
3003.31	38.3995
3005.9	31.6554
3008.48	26.7976
3011.07	22.9775
3013.65	18.593
3016.23	14.839
3018.81	11.2419
3021.39	8.16014
3023.97	5.02235
3026.55	3.11723
3029.13	0.838804
3031.71	0.47341
3034.28	-0.164659
3036.86	0.111474
3039.43	0.974021
3042.01	1.83662
3044.58	2.0286
3047.15	3.94918
3049.72	5.03425
3052.29	5.83806
3054.86	6.44042
3057.43	6.28044
3060	6.75416
3062.56	6.66857
3065.13	7.22999
3067.69	6.39769
3070.25	6.04843
3072.82	5.46822
3075.38	4.42821
3077.94	2.95294
3080.5	2.08869
3083.06	1.21565
3085.62	0.606208
3088.17	-0.0589471
3090.73	-0.723989
3093.29	-0.666947
3095.84	0.320322
3098.4	1.559
3100.95	3.75254
3103.5	5.31142
3106.05	6.23869
3108.6	7.52119
3111.15	9.49895
3113.7	11.6213
3116.25	13.6303
3118.79	14.4805
3121.34	16.1903
3123.88	17.893
3126.43	19.5538
3128.97	20.4992
3131.51	21.7627
3134.05	23.127
3136.59	23.398
3139.14	24.2543
3141.67	24.1134
3144.21	24.1632
3146.75	23.856
3149.28	23.7749