File: data/Raman/poly_smoothed/Mb_10_14_07_1x_45s_532 nm_x100_100%_600 gr_mm_01.txt
#Acq. time (s)=	45
#Accumulations=	2
#Range (cm-¹)=	200...3150
#Windows=	2
#Auto scanning=	Off
#Autofocus=	Off
#Macrospot=	Off
#AutoExposure=	Off
#Spike filter=	Multiple accum.
#Delay time (s)=	0
#Binning=	1
#Readout mode=	Signal
#DeNoise=	Off
#ICS correction=	On
#Dark correction=	Off
#Inst. Process=	Off
#Detector Gain=	Best Dynamic Range
#Detector ADC=	20 kHz
#Detector temperature (°C)=	-69.85
#Instrument=	LabRAM HR Evol
#Detector=	Synapse
#Objective=	x100
#Grating=	600 gr/mm
#ND Filter=	100%
#Laser (nm)=	532
#Hole=	100.021
#Range=	Auto
#Laser Pol.=	No
#Raman. Pol.=	No
#Laser Pol. (°)=	-0.0007625
#Raman Pol. (°)=	89.9995
#Collection=	Microscope
#StageXY=	Marzhauser
#StageZ=	Marzhauser
#X (µm)=	-2390.4
#Y (µm)=	2141.2
#Z (µm)=	-40.8
#Full time(mm:ss)=	3:18
#Project=
#Sample=
#Site=
#Title=	Mb_10_14_07_2x_45s_532 nm_x100_100%_600 gr_mm
#Remark=
#Date=	07.07.2022 13:54
#Acquired=	07.07.2022 13:54:52
#Base:Fit=	10.08.2022 10:21:11
#Base:Sub=	10.08.2022 10:21:41
#Filter:Polynom=	16.08.2022 10:17:53
#AxisType[0]=Intens
#AxisUnit[0]=Cnt
#AxisType[1]=Spectr
#AxisUnit[1]=1/cm
200.43	17.0702
204.061	10.8429
207.688	7.08124
211.316	3.0698
214.941	1.11144
218.566	3.02191
222.188	5.96407
225.809	11.2014
229.43	17.0095
233.047	20.7389
236.663	24.2735
240.278	26.1572
243.894	27.7799
247.506	28.6033
251.116	27.7267
254.725	30.6797
258.333	31.9116
261.939	33.0269
265.546	32.9798
269.15	30.4517
272.752	28.6863
276.353	27.3
279.952	24.2772
283.55	20.4034
287.146	15.2318
290.739	11.6024
294.333	10.9205
297.925	9.44421
301.516	10.2251
305.106	11.4639
308.694	14.2117
312.279	15.4479
315.864	18.2369
319.448	16.8692
323.029	18.0133
326.61	17.122
330.19	14.7603
333.766	14.8161
337.343	13.1625
340.917	13.535
344.491	13.6527
348.062	13.0328
351.633	12.8667
355.201	11.006
358.77	10.8002
362.335	11.5772
365.899	12.6826
369.464	12.2041
373.025	13.3172
376.585	13.3606
380.143	17.048
383.702	18.446
387.258	21.0401
390.812	24.053
394.365	28.3195
397.916	30.2456
401.467	32.3375
405.015	32.83
408.565	32.5657
412.111	33.3194
415.656	32.5514
419.197	32.7972
422.739	32.6108
426.279	30.6803
429.819	28.4435
433.356	25.6088
436.893	23.4915
440.428	22.8093
443.96	19.4525
447.492	18.2209
451.023	17.4866
454.553	18.3087
458.079	16.0846
461.606	13.7203
465.132	13.6986
468.654	14.4348
472.177	15.8753
475.696	17.2419
479.217	18.0258
482.733	19.8301
486.251	21.1911
489.765	23.3696
493.278	23.9574
496.791	25.9676
500.301	26.2047
503.81	27.0321
507.319	27.2209
510.825	27.3018
514.33	25.5673
517.833	25.1977
521.337	25.1152
524.838	21.8143
528.337	20.8644
531.835	19.0816
535.332	18.2346
538.827	16.5047
542.321	14.0114
545.814	11.9337
549.305	10.6354
552.795	8.69548
556.284	7.27515
559.771	6.22565
563.257	3.93537
566.742	2.01776
570.223	1.38614
573.705	2.19837
577.185	0.53136
580.665	1.35468
584.141	0.420941
587.617	2.69753
591.092	2.6184
594.564	3.31846
598.037	3.58585
601.506	3.50051
604.976	5.60763
608.443	5.64338
611.91	5.84104
615.374	7.19298
618.839	7.56687
622.3	8.63587
625.761	9.20239
629.221	9.80138
632.679	11.1534
636.135	11.5856
639.592	11.6424
643.045	13.9807
646.497	15.0307
649.948	15.8954
653.398	17.4757
656.846	18.0644
660.293	18.4242
663.738	20.2366
667.185	19.8688
670.628	20.6731
674.067	20.7278
677.508	20.3923
680.947	20.1331
684.385	20.7384
687.821	19.5282
691.256	18.9834
694.69	16.8806
698.121	14.6339
701.552	13.7647
704.982	12.2213
708.41	11.079
711.836	11.6262
715.262	13.8215
718.685	14.5296
722.108	17.2625
725.53	21.1673
728.949	23.1601
732.369	25.0355
735.785	27.296
739.2	29.8654
742.616	31.5965
746.028	34.8155
749.441	37.5406
752.851	39.8249
756.26	41.8115
759.667	44.8691
763.075	47.2023
766.479	47.4592
769.883	49.3658
773.285	51.2179
776.686	49.8474
780.085	48.3049
783.484	49.1496
786.881	49.4446
790.276	50.1352
793.671	53.2932
797.064	55.2248
800.456	57.1478
803.846	56.6523
807.236	56.6142
810.624	56.2372
814.01	55.4167
817.394	56.5491
820.778	57.1452
824.161	59.1583
827.543	60.3144
830.921	61.3668
834.3	61.7126
837.676	62.2097
841.053	61.6942
844.426	60.1914
847.8	57.2558
851.171	55.2963
854.542	53.632
857.911	49.5031
861.279	46.7164
864.645	44.9748
868.01	44.9809
871.375	44.3686
874.737	40.0301
878.097	38.5434
881.457	36.9532
884.817	33.5385
888.174	30.321
891.53	27.8481
894.884	27.5491
898.237	28.0659
901.589	28.2227
904.94	29.4916
908.289	29.1926
911.637	29.1703
914.984	29.662
918.33	29.011
921.674	25.8167
925.015	24.5913
928.357	23.2523
931.698	22.2009
935.037	20.9768
938.373	20.4478
941.71	18.9408
945.046	18.0985
948.378	18.4941
951.711	19.361
955.043	18.3422
958.372	18.3872
961.701	17.8181
965.027	16.1592
968.354	17.2647
971.678	19.0545
975	20.7559
978.324	22.8766
981.644	21.6541
984.962	22.9294
988.282	22.4665
991.598	21.2605
994.913	21.3233
998.227	21.0523
1001.54	21.0203
1004.85	19.3198
1008.16	15.8734
1011.47	14.7453
1014.78	14.7142
1018.08	16.8905
1021.39	19.0329
1024.69	20.9839
1028	21.729
1031.3	24.2746
1034.6	25.2483
1037.9	24.9515
1041.19	25.1341
1044.49	25.6095
1047.79	28.2801
1051.08	29.6299
1054.37	29.2571
1057.66	27.4095
1060.95	24.4082
1064.24	23.4452
1067.53	22.8491
1070.81	20.2748
1074.1	18.0438
1077.38	17.0449
1080.66	13.8809
1083.94	10.9656
1087.22	6.79649
1090.5	6.70455
1093.78	8.13538
1097.05	8.59809
1100.33	7.88474
1103.6	7.2646
1106.87	6.34592
1110.15	6.68323
1113.41	6.96641
1116.68	6.71396
1119.95	6.88633
1123.21	7.54536
1126.48	8.13477
1129.74	8.36864
1133	8.20537
1136.26	5.61863
1139.52	5.85551
1142.78	6.05653
1146.04	8.51176
1149.29	9.01419
1152.55	8.76722
1155.8	7.24323
1159.05	7.50659
1162.3	7.61868
1165.55	5.88141
1168.8	4.20013
1172.05	5.79864
1175.29	4.35628
1178.54	3.17448
1181.78	3.71387
1185.02	4.02056
1188.26	1.9686
1191.5	0.927046
1194.74	-0.329798
1197.97	0.0548767
1201.21	0.525608
1204.44	1.46728
1207.68	1.88551
1210.91	2.38423
1214.14	2.67912
1217.37	5.5895
1220.6	8.92165
1223.82	12.0853
1227.05	13.4165
1230.27	16.1164
1233.49	17.8065
1236.72	20.8013
1239.94	23.1602
1243.16	24.0179
1246.37	27.8412
1249.59	29.5894
1252.8	30.0836
1256.02	29.7696
1259.23	28.6408
1262.44	28.2514
1265.66	27.4106
1268.87	27.2509
1272.07	30.3684
1275.28	31.6998
1278.48	32.7697
1281.69	33.5017
1284.89	34.2514
1288.09	35.8115
1291.3	37.9451
1294.49	38.7736
1297.69	41.5602
1300.89	42.641
1304.09	43.3253
1307.28	44.409
1310.47	46.6572
1313.66	49.1099
1316.86	50.5338
1320.05	51.4881
1323.23	52.7197
1326.42	52.2551
1329.61	49.8587
1332.79	48.4225
1335.98	46.8205
1339.16	47.3353
1342.34	45.2637
1345.52	44.8723
1348.7	43.9764
1351.87	40.6272
1355.05	38.2456
1358.23	34.8033
1361.4	32.6259
1364.57	30.987
1367.74	28.8986
1370.91	25.5533
1374.08	23.8978
1377.25	20.0581
1380.42	20.2214
1383.58	20.2251
1386.75	21.7867
1389.91	21.3211
1393.07	20.3943
1396.23	20.1112
1399.39	21.8979
1402.55	23.1829
1405.7	24.5465
1408.86	26.7626
1412.01	28.5283
1415.17	34.4411
1418.32	38.0953
1421.47	41.8867
1424.62	48.0287
1427.77	52.4442
1430.92	57.5209
1434.06	63.72
1437.2	67.483
1440.35	71.8734
1443.49	74.8524
1446.63	77.7581
1449.77	79.6651
1452.91	79.8443
1456.05	79.6066
1459.18	80.032
1462.32	77.7812
1465.45	77.5413
1468.59	74.691
1471.72	74.9045
1474.85	73.5529
1477.98	69.4519
1481.11	65.861
1484.23	60.865
1487.36	57.2789
1490.48	54.8469
1493.61	52.3112
1496.73	48.295
1499.85	44.6321
1502.97	41.4236
1506.09	37.3504
1509.2	33.3093
1512.32	28.2315
1515.44	22.9113
1518.55	18.5776
1521.66	16.1849
1524.77	13.827
1527.88	10.374
1530.99	8.49484
1534.1	7.66701
1537.21	7.56496
1540.31	9.43237
1543.42	12.319
1546.52	12.1347
1549.62	12.6458
1552.72	13.0196
1555.82	13.889
1558.92	15.6351
1562.02	16.6994
1565.11	18.0531
1568.21	19.2774
1571.3	21.2896
1574.39	23.5607
1577.49	25.7002
1580.58	27.6477
1583.67	28.0112
1586.75	29.2448
1589.84	30.9678
1592.93	33.7858
1596.01	36.9786
1599.09	38.6724
1602.18	38.407
1605.26	38.0729
1608.34	39.8739
1611.41	39.1651
1614.49	39.5924
1617.57	39.4924
1620.64	39.6238
1623.72	36.8365
1626.79	37.2302
1629.86	37.0509
1632.93	37.1709
1636	38.1263
1639.07	38.6651
1642.14	39.2275
1645.2	42.5107
1648.27	43.7863
1651.33	45.83
1654.39	47.8193
1657.45	49.3989
1660.51	50.5528
1663.57	52.051
1666.63	52.1599
1669.69	51.5362
1672.74	49.886
1675.79	45.6732
1678.85	42.7788
1681.9	39.1026
1684.95	34.2427
1688	28.5892
1691.05	24.127
1694.1	19.6267
1697.14	15.7535
1700.19	12.1911
1703.23	9.08102
1706.27	5.88303
1709.32	4.88336
1712.35	3.93833
1715.39	1.53412
1718.43	0.791468
1721.47	0.686068
1724.5	0.654036
1727.54	1.7046
1730.57	3.62304
1733.61	4.55016
1736.64	4.31069
1739.67	5.29834
1742.7	5.2962
1745.72	5.97938
1748.75	6.09076
1751.78	4.36618
1754.8	4.26053
1757.82	4.38833
1760.85	2.80167
1763.87	2.03577
1766.89	1.87254
1769.91	0.756605
1772.92	0.832448
1775.94	1.56731
1778.96	1.96394
1781.97	2.2352
1784.98	3.42091
1788	4.64301
1791.01	5.18061
1794.01	5.70004
1797.02	6.64743
1800.03	6.75759
1803.04	7.40763
1806.04	6.98848
1809.05	7.5439
1812.05	7.80307
1815.05	7.98668
1818.05	8.40477
1821.05	9.03559
1824.05	8.09353
1827.05	6.21609
1830.04	6.34455
1833.04	4.97304
1836.03	3.09842
1839.03	1.9834
1842.02	1.80862
1845.01	3.15676
1848	4.63502
1850.99	4.22837
1853.97	2.95541
1856.96	3.61981
1859.94	4.23251
1862.93	4.5991
1865.91	4.10325
1868.89	4.77641
1871.87	4.56413
1874.85	5.3223
1877.83	6.65293
1880.81	6.45787
1882.56	6.19124
1885.55	6.13063
1888.54	4.82932
1891.52	5.97695
1894.51	6.30775
1897.49	5.84805
1900.48	6.64217
1903.46	7.6989
1906.44	7.74191
1909.42	7.79113
1912.4	9.15726
1915.38	9.13673
1918.35	9.89851
1921.33	8.91936
1924.3	8.51475
1927.28	9.04712
1930.25	9.63897
1933.22	9.23814
1936.19	8.07541
1939.16	8.65646
1942.13	7.5383
1945.09	9.26943
1948.06	7.37052
1951.03	6.18062
1953.99	5.15149
1956.95	3.55435
1959.91	2.65916
1962.87	3.10195
1965.83	3.24169
1968.79	2.45509
1971.75	3.04369
1974.7	4.15123
1977.66	4.09884
1980.61	3.88785
1983.56	3.93099
1986.52	3.77786
1989.47	2.31245
1992.41	3.09281
1995.36	3.38541
1998.31	3.65548
2001.26	3.7362
2004.2	3.86505
2007.15	4.46869
2010.09	4.27719
2013.03	5.79304
2015.97	5.8747
2018.91	5.7421
2021.85	6.53976
2024.79	6.81503
2027.72	7.20675
2030.66	8.11034
2033.59	9.19604
2036.53	9.60411
2039.46	9.184
2042.39	10.6804
2045.32	11.2176
2048.25	12.1713
2051.18	12.5113
2054.1	14.3693
2057.03	15.5247
2059.95	15.3968
2062.88	15.7195
2065.8	16.3198
2068.72	16.358
2071.64	17.5994
2074.56	17.8685
2077.48	18.3198
2080.39	18.0129
2083.31	17.033
2086.22	18.6089
2089.14	17.4274
2092.05	18.0463
2094.96	18.6278
2097.87	18.2632
2100.78	17.0753
2103.69	16.4524
2106.6	15.2213
2109.51	15.5328
2112.41	15.2674
2115.32	15.3188
2118.22	16.14
2121.12	16.538
2124.02	17.0123
2126.92	17.6034
2129.82	18.9225
2132.72	18.8716
2135.62	19.6288
2138.51	21.0624
2141.41	22.0828
2144.3	24.8279
2147.19	25.4194
2150.09	26.2373
2152.97	27.2367
2155.86	27.6488
2158.75	28.5743
2161.64	29.2732
2164.53	32.0769
2167.41	32.2923
2170.3	32.4439
2173.18	33.9193
2176.06	33.3681
2178.94	34.0735
2181.82	33.7219
2184.7	32.3794
2187.58	32.985
2190.46	31.8688
2193.33	29.3176
2196.21	28.7323
2199.08	27.5663
2201.95	26.9287
2204.83	26.0438
2207.7	22.6587
2210.57	21.7007
2213.43	20.6217
2216.3	19.5453
2219.17	18.0841
2222.03	18.3026
2224.9	15.9756
2227.76	17.0051
2230.62	16.4475
2233.49	18.4418
2236.34	18.9819
2239.2	19.2347
2242.06	18.916
2244.92	17.0028
2247.78	18.4029
2250.63	17.039
2253.48	15.9081
2256.34	15.0717
2259.19	13.8741
2262.04	10.5697
2264.89	10.2024
2267.74	8.72826
2270.59	8.01442
2273.43	7.76423
2276.28	7.10033
2279.12	7.1536
2281.97	7.87903
2284.81	7.8878
2287.65	8.12153
2290.49	8.27159
2293.33	7.88543
2296.17	9.13154
2299.01	11.109
2301.84	12.2813
2304.68	14.5762
2307.51	14.7391
2310.35	14.3208
2313.18	15.031
2316.01	16.3556
2318.84	16.1312
2321.67	16.5518
2324.5	16.326
2327.33	14.7934
2330.15	13.5628
2332.98	12.5287
2335.8	11.981
2338.62	11.3426
2341.45	11.6699
2344.27	11.5153
2347.09	10.9337
2349.91	8.80834
2352.72	6.79164
2355.54	5.13886
2358.36	5.77874
2361.17	5.77631
2363.98	7.53694
2366.8	8.65287
2369.61	8.53772
2372.42	8.81232
2375.23	10.4139
2378.04	11.012
2380.85	10.6376
2383.66	10.9677
2386.46	8.83333
2389.26	8.70162
2392.07	7.87412
2394.87	6.46966
2397.67	3.79373
2400.47	2.52272
2403.27	1.02559
2406.07	0.11912
2408.87	-0.419451
2411.67	-0.190597
2414.46	-0.525203
2417.26	-1.65913
2420.05	-1.07442
2422.84	0.172059
2425.64	2.13863
2428.43	3.1646
2431.22	5.07776
2434.01	5.68648
2436.79	6.64935
2439.58	7.13207
2442.37	7.30231
2445.15	7.70364
2447.93	7.32174
2450.72	6.68222
2453.5	5.39157
2456.28	5.10571
2459.06	5.31911
2461.84	4.96861
2464.62	4.11559
2467.39	2.2877
2470.17	2.11779
2472.94	1.89785
2475.72	1.41199
2478.49	1.3432
2481.26	1.83593
2484.03	2.29306
2486.8	3.18175
2489.57	2.84176
2492.34	2.80661
2495.1	3.01909
2497.87	4.17773
2500.63	4.25194
2503.4	2.89934
2506.16	3.0363
2508.92	3.73598
2511.68	3.92537
2514.44	4.54916
2517.2	4.94424
2519.96	5.82096
2522.72	6.81997
2525.47	7.35062
2528.23	7.99443
2530.98	7.47428
2533.74	7.59124
2536.49	7.07768
2539.24	8.24589
2541.99	8.05703
2544.74	8.35423
2547.49	8.84632
2550.23	8.19754
2552.98	9.45507
2555.72	7.68554
2558.47	7.41428
2561.21	7.48476
2563.95	7.47012
2566.69	7.24289
2569.43	7.82403
2572.17	7.54729
2574.91	9.45966
2577.65	9.25984
2580.39	8.94548
2583.12	9.24651
2585.85	9.68694
2588.59	9.44198
2591.32	9.30618
2594.05	10.2822
2596.78	9.10291
2599.51	9.42018
2602.24	10.1778
2604.97	10.3189
2607.69	10.1328
2610.42	9.71442
2613.14	8.87303
2615.87	7.46038
2618.59	7.40705
2621.31	6.35377
2624.03	5.77964
2626.75	5.8653
2629.47	5.31029
2632.19	5.14484
2634.91	6.27762
2637.62	7.00484
2640.34	7.47522
2643.05	6.92467
2645.76	5.40788
2648.48	7.05152
2651.19	7.70894
2653.9	8.24857
2656.6	9.57426
2659.31	10.5998
2662.02	10.9786
2664.73	10.866
2667.43	11.8345
2670.14	12.3658
2672.84	12.3969
2675.54	12.7608
2678.24	12.2177
2680.94	11.1573
2683.64	10.8624
2686.34	10.4088
2689.04	11.0325
2691.74	9.65584
2694.43	8.48551
2697.13	8.36634
2699.82	8.33949
2702.51	8.63864
2705.21	8.73213
2707.9	8.31408
2710.58	7.55954
2713.27	7.39572
2715.96	7.18386
2718.65	7.52206
2721.33	8.34742
2724.02	8.90368
2726.71	8.69934
2729.39	9.44493
2732.07	8.40664
2734.75	8.21141
2737.43	8.49158
2740.11	8.28713
2742.79	8.38837
2745.47	8.89513
2748.14	8.5661
2750.82	8.34732
2753.49	7.94585
2756.17	7.36133
2758.84	7.56084
2761.51	8.79896
2764.18	8.85291
2766.85	9.55427
2769.52	9.20105
2772.19	9.12953
2774.86	8.97911
2777.52	8.13379
2780.19	7.92583
2782.85	8.35556
2785.52	7.75523
2788.18	6.29561
2790.84	4.32659
2793.5	3.85093
2796.16	2.09497
2798.82	1.84991
2801.48	2.00556
2804.13	0.515625
2806.79	0.2384
2809.45	-1.42525
2812.1	-1.73589
2814.75	-1.33729
2817.41	-1.39947
2820.06	-0.656985
2822.71	3.14904
2825.36	5.48759
2828	9.07236
2830.65	13.6989
2833.3	18.633
2835.94	24.24
2838.59	29.9973
2841.23	37.4212
2843.87	46.5755
2846.52	55.1993
2849.16	66.1312
2851.8	75.7704
2854.44	85.9092
2857.08	96.4963
2859.71	106.189
2862.35	115.44
2864.98	122.906
2867.62	129.903
2870.25	135.407
2872.88	140.724
2875.52	144.81
2878.15	149.259
2880.78	153.58
2883.41	157.159
2886.03	160.115
2888.66	164.423
2891.29	167.711
2893.91	171.489
2896.54	174.547
2899.16	178.69
2901.78	183.786
2904.4	192.115
2907.02	199.369
2909.64	207.463
2912.26	216.104
2914.88	226.206
2917.5	233.087
2920.11	238.945
2922.73	242.506
2925.34	245.61
2927.96	246.747
2930.57	247.995
2933.18	245.587
2935.79	242.17
2938.4	238.901
2941.01	233.753
2943.62	227.998
2946.22	222.155
2948.83	213.13
2951.43	204.134
2954.04	197.126
2956.64	187.274
2959.24	176.779
2961.84	168.981
2964.45	160.589
2967.05	154.049
2969.64	146.418
2972.24	138.123
2974.84	133.139
2977.43	126.551
2980.03	118.482
2982.62	109.818
2985.22	101.653
2987.81	92.5432
2990.4	84.2272
2992.99	75.9542
2995.58	67.4246
2998.17	58.5657
3000.76	51.369
3003.34	44.3686
3005.93	37.361
3008.52	30.1996
3011.1	24.8576
3013.68	19.3086
3016.27	14.4018
3018.85	10.2195
3021.43	6.08289
3024.01	3.22002
3026.59	1.22765
3029.16	-0.397801
3031.74	-0.8937
3034.32	-2.02663
3036.89	-0.696681
3039.47	0.495784
3042.04	0.350949
3044.61	0.633398
3047.18	2.16194
3049.75	3.07986
3052.32	4.17232
3054.89	4.61579
3057.46	5.11593
3060.03	5.40095
3062.59	6.01995
3065.16	7.04837
3067.72	5.88992
3070.29	5.3603
3072.85	6.35647
3075.41	6.31684
3077.97	4.95751
3080.53	4.90988
3083.09	3.78607
3085.65	3.99686
3088.21	2.74931
3090.76	2.80841
3093.32	4.51996
3095.87	4.7008
3098.43	6.02457
3100.98	6.61058
3103.53	6.97535
3106.08	7.39269
3108.63	8.06631
3111.18	10.1188
3113.73	11.9857
3116.28	12.0876
3118.83	12.7628
3121.37	14.8481
3123.92	16.4774
3126.46	18.4245
3129	18.5793
3131.55	21.301
3134.09	23.9786
3136.63	25.6515
3139.17	27.7744
3141.71	30.2933
3144.24	33.8458
3146.78	37.2602
3149.32	41.934