File: data/Raman/poly_smoothed/Mb_10_14_42_1x_45s_532 nm_x100_100%_600 gr_mm_01.txt
#Acq. time (s)=	45
#Accumulations=	2
#Range (cm-¹)=	200...3150
#Windows=	2
#Auto scanning=	Off
#Autofocus=	Off
#Macrospot=	Off
#AutoExposure=	Off
#Spike filter=	Multiple accum.
#Delay time (s)=	0
#Binning=	1
#Readout mode=	Signal
#DeNoise=	Off
#ICS correction=	On
#Dark correction=	Off
#Inst. Process=	Off
#Detector Gain=	Best Dynamic Range
#Detector ADC=	20 kHz
#Detector temperature (°C)=	-69.85
#Instrument=	LabRAM HR Evol
#Detector=	Synapse
#Objective=	x100
#Grating=	600 gr/mm
#ND Filter=	100%
#Laser (nm)=	532
#Hole=	100.021
#Range=	Auto
#Laser Pol.=	No
#Raman. Pol.=	No
#Laser Pol. (°)=	-0.0007625
#Raman Pol. (°)=	89.9995
#Collection=	Microscope
#StageXY=	Marzhauser
#StageZ=	Marzhauser
#X (µm)=	-632
#Y (µm)=	-1688.3
#Z (µm)=	89
#Full time(mm:ss)=	3:18
#Project=
#Sample=
#Site=
#Title=	Mb_10_14_42_2x_45s_532 nm_x100_100%_600 gr_mm
#Remark=
#Date=	11.07.2022 11:45
#Acquired=	11.07.2022 11:45:49
#Base:Fit=	10.08.2022 10:21:11
#Base:Sub=	10.08.2022 10:21:41
#Filter:Polynom=	16.08.2022 10:17:53
#AxisType[0]=Intens
#AxisUnit[0]=Cnt
#AxisType[1]=Spectr
#AxisUnit[1]=1/cm
200.388	22.7914
204.019	6.62123
207.646	2.92795
211.274	5.46013
214.899	10.058
218.524	14.2804
222.146	16.5121
225.766	19.116
229.388	21.6515
233.005	24.1106
236.621	25.4385
240.236	25.8577
243.852	25.2452
247.464	25.9243
251.074	26.3881
254.683	25.3832
258.291	25.0721
261.897	22.1701
265.504	21.5483
269.108	20.2914
272.71	16.6885
276.311	15.4158
279.91	12.5935
283.508	9.11196
287.105	8.39888
290.698	9.48194
294.291	11.5103
297.884	12.0902
301.475	12.4762
305.064	11.1452
308.652	12.3481
312.237	13.3294
315.822	12.8533
319.406	12.3675
322.987	11.526
326.568	10.6541
330.148	8.80602
333.724	8.20931
337.301	7.42395
340.875	7.92055
344.449	7.29585
348.02	6.69797
351.592	7.36869
355.16	9.40845
358.728	11.5666
362.294	13.7212
365.858	16.8363
369.422	18.5312
372.983	19.2181
376.543	20.4607
380.102	20.9861
383.661	23.2458
387.216	24.8737
390.771	25.1126
394.324	24.3291
397.875	23.5118
401.425	21.7826
404.974	18.487
408.524	17.5566
412.07	14.9546
415.614	13.7015
419.156	11.7827
422.698	10.3653
426.238	9.23587
429.777	8.08078
433.315	7.29523
436.852	6.68228
440.387	7.74458
443.919	7.92146
447.451	7.96107
450.982	8.32927
454.512	10.0643
458.038	9.54485
461.565	10.9135
465.091	11.6826
468.613	11.2273
472.136	11.2678
475.655	10.7946
479.176	10.9691
482.692	11.4715
486.21	13.1041
489.724	13.1023
493.237	12.9359
496.75	15.4052
500.26	15.7403
503.769	16.4679
507.279	16.5647
510.785	18.4592
514.289	18.3017
517.793	19.4943
521.297	21.0146
524.797	21.3422
528.297	20.9736
531.795	19.5488
535.291	18.8686
538.787	17.1845
542.281	16.8617
545.773	14.9541
549.264	13.3787
552.754	10.5482
556.243	9.05881
559.73	7.99848
563.216	7.02795
566.701	5.59338
570.182	4.78189
573.664	2.65652
577.145	2.01867
580.624	2.53969
584.1	0.834796
587.577	0.723716
591.052	0.419586
594.524	1.88628
597.997	0.698679
601.466	0.578318
604.936	2.38127
608.403	2.46248
611.87	2.24471
615.334	1.89145
618.799	0.830045
622.26	1.19908
625.72	2.0023
629.181	3.32805
632.638	2.95814
636.095	5.99802
639.551	8.03508
643.005	9.54803
646.457	11.3273
649.908	13.915
653.357	15.0507
656.806	17.8889
660.253	20.0213
663.7	21.8115
667.145	23.3761
670.588	24.3642
674.027	25.7809
677.468	25.4979
680.907	24.8805
684.345	24.6263
687.781	25.2873
691.216	23.9207
694.65	22.1679
698.081	22.5046
701.512	23.4205
704.942	24.5954
708.371	24.429
711.796	25.9962
715.222	26.725
718.645	27.4355
722.068	29.0541
725.49	29.9944
728.909	30.3244
732.329	31.1491
735.745	32.2483
739.16	34.9761
742.576	38.6657
745.988	42.0156
749.401	44.2862
752.811	45.921
756.22	46.19
759.627	47.7978
763.035	48.3884
766.44	51.1472
769.843	51.2681
773.245	54.9563
776.646	56.9694
780.046	60.8438
783.444	65.011
786.841	67.8383
790.237	69.5585
793.631	71.7155
797.024	73.9673
800.416	74.7979
803.807	74.8219
807.196	74.6504
810.584	74.5198
813.971	72.5547
817.354	74.617
820.739	76.3672
824.122	77.5326
827.503	76.7754
830.882	75.6208
834.261	74.0138
837.637	71.6719
841.013	69.1899
844.389	68.1423
847.761	66.1034
851.131	65.1166
854.503	63.5359
857.871	62.7566
861.24	61.1644
864.606	60.0192
867.97	59.8821
871.336	57.6169
874.698	54.6164
878.058	52.6911
881.418	49.8252
884.778	51.0211
888.135	50.0443
891.49	48.3919
894.845	46.443
898.198	48.8171
901.55	48.4087
904.901	47.483
908.25	46.6256
911.598	47.2057
914.945	47.8694
918.291	45.9328
921.635	45.3448
924.978	44.1248
928.318	42.9784
931.659	42.631
934.998	41.3248
938.336	40.3823
941.671	38.4018
945.007	37.4277
948.339	36.021
951.672	34.6158
955.004	32.7343
958.333	31.9792
961.662	30.0428
964.989	30.4669
968.315	31.1975
971.639	31.0586
974.962	30.0528
978.285	29.8897
981.605	29.3616
984.924	28.837
988.243	28.7473
991.56	28.0688
994.875	27.1812
998.188	26.5472
1001.5	27.1355
1004.81	25.3287
1008.12	27.1595
1011.43	28.6506
1014.74	30.3542
1018.05	30.8822
1021.35	31.8614
1024.65	33.587
1027.96	33.5838
1031.26	34.2815
1034.56	34.2413
1037.86	32.5591
1041.16	31.547
1044.45	31.6211
1047.75	32.3623
1051.04	31.7765
1054.33	29.0967
1057.62	27.3284
1060.91	25.8627
1064.2	22.7929
1067.49	19.9818
1070.77	15.5961
1074.06	12.6828
1077.34	12.2897
1080.62	11.3902
1083.91	10.7075
1087.18	10.9653
1090.46	10.1558
1093.74	9.57982
1097.02	8.92393
1100.29	8.32616
1103.56	6.85878
1106.84	6.7879
1110.11	4.48275
1113.38	4.45185
1116.64	2.83321
1119.91	1.71665
1123.18	1.6172
1126.44	1.57038
1129.7	2.29755
1132.97	3.3835
1136.23	5.01321
1139.49	5.98845
1142.74	6.67926
1146	6.41725
1149.26	7.02529
1152.51	7.44873
1155.76	8.7103
1159.01	9.862
1162.27	9.27013
1165.51	10.0249
1168.76	9.96585
1172.01	10.8849
1175.25	11.4539
1178.5	11.8783
1181.74	12.3591
1184.98	12.1197
1188.22	11.8871
1191.46	10.4509
1194.7	10.8234
1197.94	11.9233
1201.17	11.332
1204.41	11.8047
1207.64	14.6101
1210.87	17.0295
1214.1	19.0147
1217.33	19.9958
1220.56	21.1006
1223.79	21.9619
1227.01	22.3155
1230.23	22.1995
1233.46	22.9405
1236.68	22.8734
1239.9	22.2198
1243.12	22.1535
1246.34	22.7653
1249.55	23.3129
1252.77	24.6215
1255.98	26.4524
1259.2	26.738
1262.41	25.2965
1265.62	24.8986
1268.83	24.9438
1272.03	24.9943
1275.24	25.3413
1278.45	24.575
1281.65	26.0483
1284.85	26.0352
1288.06	26.9635
1291.26	28.9575
1294.46	29.8751
1297.66	30.7474
1300.85	31.0296
1304.05	31.3025
1307.24	31.9177
1310.43	30.7881
1313.63	31.4619
1316.82	32.6691
1320.01	33.254
1323.2	34.9282
1326.38	36.5388
1329.57	38.0969
1332.76	39.3846
1335.94	39.2809
1339.12	37.7143
1342.3	38.7245
1345.48	38.6326
1348.66	38.2135
1351.84	36.8537
1355.01	36.09
1358.19	36.207
1361.36	36.5472
1364.53	34.5415
1367.71	34.486
1370.88	32.9455
1374.04	32.302
1377.21	29.0423
1380.38	28.6561
1383.54	28.1914
1386.71	26.3944
1389.87	27.242
1393.03	27.1072
1396.19	25.5607
1399.35	25.6843
1402.51	25.9183
1405.67	27.002
1408.82	27.6179
1411.98	29.5443
1415.13	29.6828
1418.28	32.848
1421.43	35.2571
1424.58	36.5516
1427.73	39.3769
1430.88	44.7104
1434.02	48.1146
1437.17	51.9925
1440.31	53.1852
1443.45	53.5068
1446.6	54.3797
1449.74	54.4642
1452.87	54.2423
1456.01	54.0362
1459.15	54.6584
1462.28	53.1151
1465.42	51.9744
1468.55	50.7379
1471.68	47.6866
1474.81	45.9202
1477.94	43.7866
1481.07	42.1937
1484.2	39.442
1487.32	37.3491
1490.45	33.5765
1493.57	31.1881
1496.69	31.4277
1499.81	30.456
1502.93	29.1228
1506.05	29.135
1509.17	27.7086
1512.28	25.0942
1515.4	21.9298
1518.51	18.9684
1521.63	18.5064
1524.74	16.3298
1527.85	15.427
1530.96	15.2542
1534.06	14.2734
1537.17	15.2227
1540.28	14.3201
1543.38	14.1367
1546.48	15.7999
1549.59	15.7773
1552.69	16.1417
1555.79	16.3786
1558.88	16.378
1561.98	16.5918
1565.08	17.5612
1568.17	19.9877
1571.27	21.8683
1574.36	24.0654
1577.45	25.368
1580.54	27.0279
1583.63	29.4284
1586.72	31.5159
1589.8	32.346
1592.89	34.0971
1595.97	35.6137
1599.06	37.0263
1602.14	37.5256
1605.22	38.0836
1608.3	37.4479
1611.38	36.7241
1614.46	36.3041
1617.53	36.1845
1620.61	37.1176
1623.68	36.027
1626.75	34.9373
1629.82	35.7785
1632.9	36.4076
1635.96	37.0575
1639.03	39.8439
1642.1	41.5916
1645.16	44.6587
1648.23	45.4466
1651.29	48.1914
1654.36	49.8868
1657.42	51.6617
1660.48	51.0103
1663.53	50.7686
1666.59	50.3277
1669.65	49.6389
1672.7	48.2692
1675.76	46.2348
1678.81	42.669
1681.86	40.1913
1684.91	36.6685
1687.96	33.3844
1691.01	30.9337
1694.06	26.1499
1697.11	23.6014
1700.15	19.8485
1703.2	17.568
1706.24	15.8532
1709.28	13.2981
1712.32	12.5606
1715.36	12.0038
1718.4	10.5113
1721.43	9.08124
1724.47	7.36416
1727.5	7.58109
1730.54	7.36916
1733.57	4.94563
1736.6	4.90589
1739.63	4.69878
1742.66	4.57095
1745.69	3.82807
1748.72	3.78609
1751.74	3.43545
1754.77	3.05237
1757.79	3.5888
1760.81	3.63632
1763.83	3.54288
1766.85	4.06116
1769.87	2.57841
1772.89	2.39904
1775.91	2.45941
1778.92	2.87469
1781.94	4.57519
1784.95	5.06597
1787.96	5.82417
1790.97	5.80909
1793.98	5.45513
1796.99	5.24629
1800	6.64216
1803	6.50084
1806.01	5.26205
1809.01	4.40748
1812.02	4.35531
1815.02	4.00764
1818.02	3.42756
1821.02	2.08147
1824.02	2.05653
1827.01	1.76348
1830.01	2.57293
1833	2.50541
1836	2.91343
1838.99	2.78075
1841.98	1.74516
1844.97	1.69637
1847.96	1.30247
1850.95	1.79316
1853.94	3.00716
1856.92	3.72914
1859.91	3.77374
1862.89	4.28335
1865.88	4.23696
1868.86	4.97889
1871.84	5.09031
1874.82	5.04069
1877.8	5.72418
1880.77	6.22826
1882.52	7.25724
1885.51	7.50014
1888.5	7.04165
1891.49	7.31664
1894.47	6.84418
1897.46	6.63239
1900.44	6.92671
1903.42	7.72478
1906.4	8.11419
1909.38	7.65275
1912.36	6.8267
1915.34	6.49075
1918.32	5.45768
1921.29	5.72741
1924.27	5.95141
1927.24	6.10981
1930.21	5.44991
1933.18	4.99502
1936.15	5.41907
1939.12	5.12749
1942.09	3.97624
1945.06	3.77585
1948.02	3.84527
1950.99	3.85325
1953.95	2.94902
1956.91	3.12387
1959.87	2.80081
1962.84	2.47529
1965.79	2.71114
1968.75	3.49324
1971.71	4.7977
1974.66	6.50551
1977.62	7.06158
1980.57	8.20079
1983.53	7.99063
1986.48	8.71429
1989.43	9.65879
1992.38	9.75736
1995.33	9.86143
1998.27	8.80849
2001.22	8.2763
2004.16	8.41653
2007.11	8.58804
2010.05	7.76301
2012.99	6.24773
2015.93	5.14656
2018.87	3.65623
2021.81	3.74451
2024.75	3.1687
2027.69	2.97622
2030.62	3.36219
2033.56	3.43433
2036.49	2.44981
2039.42	2.4706
2042.35	2.44168
2045.28	2.59897
2048.21	2.85116
2051.14	4.75923
2054.06	5.00337
2056.99	4.87361
2059.92	5.49034
2062.84	6.52077
2065.76	6.46503
2068.68	7.3266
2071.6	8.43007
2074.52	9.44305
2077.44	10.7807
2080.36	10.9269
2083.27	10.6897
2086.19	10.8511
2089.1	11.0337
2092.01	11.6613
2094.93	11.2936
2097.84	10.9508
2100.75	12.7747
2103.66	12.861
2106.56	12.2067
2109.47	11.9793
2112.37	11.63
2115.28	11.8744
2118.18	11.7559
2121.09	12.1143
2123.99	11.5678
2126.89	12.1253
2129.79	12.4119
2132.68	13.2687
2135.58	15.3145
2138.48	15.5407
2141.37	15.1638
2144.26	16.1221
2147.16	17.2138
2150.05	17.5525
2152.94	17.4796
2155.83	17.5529
2158.72	18.3986
2161.6	20.0013
2164.49	20.2904
2167.38	21.9981
2170.26	24.3823
2173.14	25.3914
2176.03	26.8907
2178.91	27.6024
2181.79	27.3588
2184.67	27.5103
2187.54	26.7881
2190.42	26.8936
2193.3	26.9943
2196.17	27.8094
2199.05	27.1339
2201.92	27.3574
2204.79	26.0242
2207.66	24.3494
2210.53	23.2324
2213.4	23.2086
2216.27	22.3972
2219.13	21.6944
2222	20.005
2224.86	18.662
2227.72	17.9403
2230.59	17.5371
2233.45	17.1386
2236.31	16.9101
2239.17	16.0146
2242.03	14.7919
2244.88	14.2252
2247.74	14.5169
2250.59	13.4435
2253.45	12.557
2256.3	11.9304
2259.15	11.6751
2262	11.0711
2264.85	11.5462
2267.7	10.3482
2270.55	9.77036
2273.4	9.96107
2276.24	9.96818
2279.09	10.1724
2281.93	10.6969
2284.77	11.5704
2287.61	10.9079
2290.46	10.3577
2293.29	9.84529
2296.13	9.20492
2298.97	10.2107
2301.81	10.3979
2304.64	10.2497
2307.48	9.77557
2310.31	9.91539
2313.14	10.111
2315.97	11.1324
2318.8	11.3279
2321.63	11.2349
2324.46	10.4572
2327.29	9.88455
2330.12	9.28919
2332.94	9.5313
2335.76	9.25302
2338.59	6.98755
2341.41	5.90372
2344.23	5.15661
2347.05	3.55006
2349.87	2.61812
2352.69	1.51395
2355.5	1.6694
2358.32	0.722214
2361.14	0.7277
2363.95	0.9479
2366.76	2.66206
2369.58	4.04019
2372.39	4.40848
2375.2	3.95618
2378	5.11326
2380.81	5.8237
2383.62	6.61465
2386.42	8.21168
2389.23	8.6258
2392.03	9.81479
2394.84	9.46361
2397.64	9.67198
2400.44	9.34298
2403.24	9.08741
2406.04	8.64384
2408.83	8.15729
2411.63	8.1769
2414.43	7.30482
2417.22	5.96738
2420.02	6.06585
2422.81	6.40963
2425.6	6.42286
2428.39	6.20987
2431.18	6.63109
2433.97	6.46823
2436.76	6.00594
2439.54	6.21077
2442.33	5.70451
2445.11	5.69029
2447.9	6.33133
2450.68	6.34992
2453.46	6.60926
2456.24	5.70158
2459.02	6.78262
2461.8	6.03991
2464.58	5.18147
2467.36	5.22409
2470.13	5.73373
2472.91	6.33091
2475.68	5.7501
2478.45	5.25023
2481.22	5.18684
2484	4.78517
2486.77	4.90287
2489.54	5.48329
2492.3	5.32347
2495.07	5.6279
2497.84	5.67005
2500.6	4.68977
2503.36	4.64855
2506.13	4.54438
2508.89	5.28559
2511.65	5.36885
2514.41	5.07588
2517.17	5.03905
2519.93	5.04006
2522.68	6.24542
2525.44	6.94767
2528.19	6.84632
2530.95	6.67711
2533.7	6.30429
2536.45	6.24749
2539.2	6.35877
2541.95	6.50962
2544.7	7.27067
2547.45	7.69811
2550.2	7.87255
2552.94	8.6516
2555.69	9.68323
2558.43	9.65951
2561.17	10.2975
2563.92	9.87481
2566.66	8.56079
2569.4	8.46948
2572.14	8.36692
2574.88	7.86134
2577.61	7.52052
2580.35	7.72717
2583.09	7.1402
2585.82	8.15091
2588.55	7.91126
2591.28	8.52362
2594.02	7.60536
2596.75	7.93607
2599.48	7.80182
2602.2	8.21603
2604.93	8.18371
2607.66	8.38115
2610.38	8.88353
2613.11	9.75153
2615.83	9.97873
2618.56	11.8509
2621.28	12.9782
2624	13.8244
2626.72	13.7494
2629.44	12.7757
2632.15	11.9133
2634.87	10.4155
2637.59	10.0756
2640.3	9.57285
2643.02	9.1194
2645.73	9.99644
2648.44	9.74073
2651.15	9.50992
2653.86	9.18005
2656.57	8.35386
2659.28	9.43401
2661.99	9.08234
2664.69	8.75529
2667.4	8.28026
2670.1	8.15438
2672.81	7.14108
2675.51	7.28201
2678.21	7.22324
2680.91	7.19388
2683.61	6.79272
2686.31	6.52232
2689	5.67518
2691.7	4.47909
2694.4	3.90336
2697.09	3.16872
2699.79	3.45998
2702.48	3.46459
2705.17	3.21193
2707.86	1.86577
2710.55	2.35359
2713.24	2.30046
2715.93	2.74459
2718.61	3.16917
2721.3	2.82307
2723.99	3.66343
2726.67	3.54319
2729.35	2.7492
2732.04	3.21135
2734.72	3.85384
2737.4	4.09606
2740.08	4.38704
2742.76	4.85281
2745.43	6.24145
2748.11	6.85981
2750.79	6.7844
2753.46	6.97324
2756.13	6.84287
2758.81	7.51931
2761.48	8.95803
2764.15	8.6672
2766.82	7.84955
2769.49	6.41171
2772.16	5.236
2774.82	4.97854
2777.49	4.743
2780.16	4.0133
2782.82	2.84704
2785.48	2.64965
2788.15	2.08364
2790.81	1.8363
2793.47	0.818778
2796.13	0.369753
2798.79	-0.420343
2801.44	0.0334356
2804.1	0.574218
2806.76	0.693993
2809.41	1.11742
2812.07	0.922706
2814.72	1.54787
2817.37	1.36126
2820.02	2.39577
2822.67	3.79931
2825.32	4.71657
2827.97	5.96633
2830.62	7.01643
2833.26	9.20544
2835.91	12.0206
2838.55	14.5834
2841.2	18.5614
2843.84	23.2049
2846.48	27.6789
2849.12	33.6576
2851.76	40.329
2854.4	45.6674
2857.04	51.4457
2859.68	57.6366
2862.32	63.9603
2864.95	69.9196
2867.58	74.9687
2870.22	79.8758
2872.85	84.1668
2875.48	87.6341
2878.11	91.3918
2880.74	94.8977
2883.37	97.8039
2886	100.532
2888.63	102.827
2891.25	105.357
2893.88	108.105
2896.5	112.033
2899.13	115.956
2901.75	119.827
2904.37	125.519
2906.99	132.359
2909.61	138.803
2912.23	146.289
2914.85	153.925
2917.46	159.94
2920.08	166.087
2922.7	171.595
2925.31	175.429
2927.92	177.812
2930.53	178.658
2933.15	178.786
2935.76	177.094
2938.37	174.987
2940.98	171.741
2943.58	166.635
2946.19	161.428
2948.8	155.433
2951.4	148.906
2954.01	141.939
2956.61	135.232
2959.21	129.926
2961.81	123.088
2964.41	117.578
2967.01	112.373
2969.61	106.762
2972.21	101.288
2974.81	96.5419
2977.4	91.7506
2980	86.0665
2982.59	80.114
2985.18	74.1682
2987.78	66.8802
2990.37	60.3452
2992.96	54.6072
2995.55	48.4703
2998.14	42.9968
3000.72	37.0576
3003.31	31.6716
3005.9	26.4568
3008.48	21.4167
3011.07	17.225
3013.65	13.4424
3016.23	10.6216
3018.81	8.4571
3021.39	6.80719
3023.97	5.59991
3026.55	4.93404
3029.13	4.37455
3031.71	4.22882
3034.28	4.49995
3036.86	4.81409
3039.43	5.48804
3042.01	6.25317
3044.58	6.9229
3047.15	7.80126
3049.72	7.89519
3052.29	9.24028
3054.86	9.76631
3057.43	9.83554
3060	10.1999
3062.56	10.2063
3065.13	9.30287
3067.69	9.95187
3070.25	9.48608
3072.82	8.55275
3075.38	7.7605
3077.94	6.17524
3080.5	5.50777
3083.06	4.73526
3085.62	3.96324
3088.17	2.80048
3090.73	1.84978
3093.29	1.2964
3095.84	0.883807
3098.4	0.445233
3100.95	0.364651
3103.5	1.28688
3106.05	2.14681
3108.6	3.12219
3111.15	4.13161
3113.7	4.78674
3116.25	5.28833
3118.79	6.12224
3121.34	7.31923
3123.88	8.91393
3126.43	10.1677
3128.97	11.6726
3131.51	13.1457
3134.05	13.9699
3136.59	15.0678
3139.14	14.9761
3141.67	15.8776
3144.21	16.0909
3146.75	16.2176
3149.28	17.9788