File: data/Raman/poly_smoothed/Mb_10_14_49_1x_45s_532 nm_x100_100%_600 gr_mm_01.txt
#Acq. time (s)=	45
#Accumulations=	2
#Range (cm-¹)=	200...3150
#Windows=	2
#Auto scanning=	Off
#Autofocus=	Off
#Macrospot=	Off
#AutoExposure=	Off
#Spike filter=	Multiple accum.
#Delay time (s)=	0
#Binning=	1
#Readout mode=	Signal
#DeNoise=	Off
#ICS correction=	On
#Dark correction=	Off
#Inst. Process=	Off
#Detector Gain=	Best Dynamic Range
#Detector ADC=	20 kHz
#Detector temperature (°C)=	-69.85
#Instrument=	LabRAM HR Evol
#Detector=	Synapse
#Objective=	x100
#Grating=	600 gr/mm
#ND Filter=	100%
#Laser (nm)=	532
#Hole=	100.021
#Range=	Auto
#Laser Pol.=	No
#Raman. Pol.=	No
#Laser Pol. (°)=	-0.0007625
#Raman Pol. (°)=	89.9995
#Collection=	Microscope
#StageXY=	Marzhauser
#StageZ=	Marzhauser
#X (µm)=	-632.5
#Y (µm)=	-1708.7
#Z (µm)=	88.75
#Full time(mm:ss)=	3:18
#Project=
#Sample=
#Site=
#Title=	Mb_10_14_49_2x_45s_532 nm_x100_100%_600 gr_mm
#Remark=
#Date=	11.07.2022 12:23
#Acquired=	11.07.2022 12:23:06
#Base:Fit=	10.08.2022 10:21:11
#Base:Sub=	10.08.2022 10:21:41
#Filter:Polynom=	16.08.2022 10:17:53
#AxisType[0]=Intens
#AxisUnit[0]=Cnt
#AxisType[1]=Spectr
#AxisUnit[1]=1/cm
200.388	32.0997
204.019	28.0633
207.646	20.6324
211.274	15.1133
214.899	11.9155
218.524	9.5136
222.146	8.53019
225.766	8.41488
229.388	7.5994
233.005	10.7395
236.621	11.9057
240.236	13.0053
243.852	13.5091
247.464	14.5608
251.074	15.8111
254.683	17.044
258.291	18.5971
261.897	19.4027
265.504	17.2071
269.108	17.7479
272.71	17.3841
276.311	15.7149
279.91	13.7774
283.508	12.2521
287.105	10.8817
290.698	9.34963
294.291	8.6959
297.884	8.66682
301.475	8.8014
305.064	7.99002
308.652	8.13895
312.237	8.99584
315.822	8.7584
319.406	9.93465
322.987	9.9973
326.568	10.0989
330.148	9.57861
333.724	9.99219
337.301	10.8886
340.875	10.8266
344.449	10.7383
348.02	12.0692
351.592	12.4285
355.16	16.014
358.728	19.4417
362.294	21.8624
365.858	23.9312
369.422	27.1411
372.983	30.874
376.543	33.4809
380.102	34.4682
383.661	35.5741
387.216	36.9578
390.771	36.7018
394.324	36.3778
397.875	35.9123
401.425	34.4199
404.974	31.6497
408.524	27.8538
412.07	23.8323
415.614	21.0147
419.156	18.5061
422.698	15.6826
426.238	13.9591
429.777	10.6
433.315	9.69645
436.852	9.69573
440.387	10.8301
443.919	11.0674
447.451	11.0277
450.982	9.8112
454.512	8.90198
458.038	10.3958
461.565	11.7845
465.091	13.7589
468.613	15.9293
472.136	17.9306
475.655	19.0003
479.176	20.9981
482.692	23.1109
486.21	25.9541
489.724	26.596
493.237	27.6936
496.75	28.4441
500.26	29.1587
503.769	30.6544
507.279	30.4139
510.785	31.3409
514.289	33.1528
517.793	32.8953
521.297	33.4255
524.797	33.3877
528.297	33.3285
531.795	30.5208
535.291	25.9278
538.787	25.6985
542.281	25.5364
545.773	23.9745
549.264	21.9633
552.754	19.2022
556.243	17.0605
559.73	13.3715
563.216	11.0645
566.701	10.3814
570.182	8.54176
573.664	7.4711
577.145	6.05938
580.624	4.69346
584.1	4.09417
587.577	5.08495
591.052	6.88677
594.524	7.88183
597.997	8.60765
601.466	10.3725
604.936	11.8986
608.403	14.4286
611.87	14.3513
615.334	15.4867
618.799	15.7268
622.26	17.4135
625.72	19.1354
629.181	18.9987
632.638	20.359
636.095	22.1724
639.551	21.6445
643.005	21.3152
646.457	22.434
649.908	24.616
653.357	24.6909
656.806	25.0234
660.253	26.6961
663.7	25.9634
667.145	26.3429
670.588	27.1221
674.027	27.9983
677.468	27.5133
680.907	29.0064
684.345	28.6428
687.781	29.4112
691.216	30.4769
694.65	31.0611
698.081	31.235
701.512	32.319
704.942	32.874
708.371	33.415
711.796	36.1451
715.222	39.445
718.645	39.6231
722.068	40.6554
725.49	42.2464
728.909	44.1456
732.329	46.5061
735.745	47.141
739.16	46.5262
742.576	48.8031
745.988	49.9666
749.401	52.3728
752.811	54.7534
756.22	57.233
759.627	57.9847
763.035	60.0834
766.44	63.8776
769.843	65.4576
773.245	68.0471
776.646	70.2727
780.046	72.7686
783.444	72.4936
786.841	74.4159
790.237	76.5097
793.631	77.9846
797.024	78.5703
800.416	79.5025
803.807	80.1908
807.196	81.2268
810.584	81.4362
813.971	82.5975
817.354	82.162
820.739	83.2237
824.122	83.1047
827.503	83.8102
830.882	84.053
834.261	83.9903
837.637	84.0797
841.013	81.4404
844.389	81.098
847.761	80.2665
851.131	78.0666
854.503	75.0303
857.871	73.4691
861.24	71.5701
864.606	66.0474
867.97	62.7424
871.336	60.5609
874.698	57.4328
878.058	54.4616
881.418	52.2829
884.778	51.1622
888.135	49.2816
891.49	48.3111
894.845	47.5078
898.198	48.3467
901.55	48.7518
904.901	50.0279
908.25	49.6913
911.598	50.1397
914.945	50.7944
918.291	51.6574
921.635	52.0339
924.978	52.1381
928.318	52.8853
931.659	52.6458
934.998	51.7336
938.336	51.0101
941.671	48.6988
945.007	45.1443
948.339	42.8837
951.672	41.85
955.004	39.733
958.333	38.0236
961.662	35.5721
964.989	36.6875
968.315	36.8837
971.639	37.3851
974.962	37.956
978.285	40.539
981.605	39.7684
984.924	39.2795
988.243	39.3076
991.56	39.6137
994.875	40.0278
998.188	40.5266
1001.5	41.8499
1004.81	43.515
1008.12	44.3039
1011.43	43.6731
1014.74	46.3039
1018.05	46.4941
1021.35	45.769
1024.65	46.0876
1027.96	47.1863
1031.26	47.9516
1034.56	46.8518
1037.86	47.4948
1041.16	45.5888
1044.45	45.4418
1047.75	45.1186
1051.04	42.1685
1054.33	39.6416
1057.62	37.7196
1060.91	34.8431
1064.2	32.0001
1067.49	30.0853
1070.77	30.0714
1074.06	28.0868
1077.34	25.5675
1080.62	25.2185
1083.91	24.528
1087.18	25.4347
1090.46	25.2214
1093.74	24.4193
1097.02	24.5971
1100.29	24.3136
1103.56	23.6644
1106.84	23.571
1110.11	22.6902
1113.38	21.724
1116.64	19.7837
1119.91	16.4082
1123.18	13.4638
1126.44	12.6937
1129.7	13.3049
1132.97	12.8513
1136.23	11.6551
1139.49	10.1167
1142.74	10.3653
1146	11.3579
1149.26	10.913
1152.51	9.60815
1155.76	7.87279
1159.01	7.69574
1162.27	6.94887
1165.51	6.19356
1168.76	6.6196
1172.01	7.21461
1175.25	7.74677
1178.5	7.61194
1181.74	8.6917
1184.98	7.91205
1188.22	8.70175
1191.46	11.4295
1194.7	13.2875
1197.94	14.4368
1201.17	18.8329
1204.41	22.2012
1207.64	23.9162
1210.87	25.3487
1214.1	27.7276
1217.33	30.5004
1220.56	33.8317
1223.79	35.8407
1227.01	35.9775
1230.23	35.9319
1233.46	37.1011
1236.68	38.2753
1239.9	37.6153
1243.12	39.2001
1246.34	41.0578
1249.55	41.3136
1252.77	39.6826
1255.98	39.376
1259.2	39.0172
1262.41	37.8008
1265.62	38.5747
1268.83	39.5487
1272.03	39.7686
1275.24	40.9258
1278.45	40.258
1281.65	40.3962
1284.85	39.9763
1288.06	40.1363
1291.26	40.9446
1294.46	42.8583
1297.66	43.267
1300.85	45.3075
1304.05	46.1051
1307.24	48.1247
1310.43	49.5239
1313.63	51.5215
1316.82	53.6156
1320.01	54.961
1323.2	55.3855
1326.38	56.4248
1329.57	55.8924
1332.76	55.2741
1335.94	54.1839
1339.12	54.3614
1342.3	53.7695
1345.48	54.1912
1348.66	51.9391
1351.84	51.1964
1355.01	49.4013
1358.19	47.782
1361.36	48.155
1364.53	44.7841
1367.71	43.5028
1370.88	42.8581
1374.04	42.0827
1377.21	38.9178
1380.38	38.6285
1383.54	37.6176
1386.71	38.0123
1389.87	36.9684
1393.03	38.327
1396.19	37.3858
1399.35	35.9757
1402.51	36.2397
1405.67	35.8767
1408.82	35.8984
1411.98	37.8864
1415.13	40.346
1418.28	43.4143
1421.43	46.5274
1424.58	49.6896
1427.73	53.3375
1430.88	57.8223
1434.02	61.4951
1437.17	65.507
1440.31	68.5224
1443.45	69.3952
1446.6	70.0121
1449.74	69.6046
1452.87	69.1817
1456.01	69.3537
1459.15	69.4771
1462.28	67.2127
1465.42	65.1769
1468.55	61.2217
1471.68	57.4841
1474.81	53.8268
1477.94	48.5321
1481.07	46.8107
1484.2	44.0568
1487.32	41.3742
1490.45	39.3231
1493.57	35.522
1496.69	33.9125
1499.81	33.0627
1502.93	32.1655
1506.05	31.9514
1509.17	29.4806
1512.28	28.314
1515.4	27.0614
1518.51	25.3616
1521.63	23.3655
1524.74	23.0939
1527.85	21.1529
1530.96	21.0599
1534.06	19.0158
1537.17	18.5686
1540.28	19.5991
1543.38	19.6673
1546.48	20.7975
1549.59	21.2621
1552.69	23.5522
1555.79	24.5217
1558.88	25.2517
1561.98	26.3593
1565.08	28.5547
1568.17	29.2889
1571.27	32.8951
1574.36	35.1197
1577.45	38.2643
1580.54	39.3613
1583.63	40.7447
1586.72	41.8011
1589.8	43.4786
1592.89	44.684
1595.97	45.1953
1599.06	46.7064
1602.14	46.0867
1605.22	44.5803
1608.3	44.446
1611.38	44.1528
1614.46	45.1139
1617.53	45.4137
1620.61	43.8926
1623.68	43.9341
1626.75	44.6635
1629.82	46.7831
1632.9	47.9319
1635.96	49.2192
1639.03	51.3957
1642.1	54.5861
1645.16	57.151
1648.23	58.3964
1651.29	59.9827
1654.36	62.0315
1657.42	62.9503
1660.48	64.3938
1663.53	64.1453
1666.59	64.1451
1669.65	63.0308
1672.7	60.7882
1675.76	58.5379
1678.81	54.1385
1681.86	50.3555
1684.91	47.1473
1687.96	43.1481
1691.01	37.9333
1694.06	34.0744
1697.11	30.4517
1700.15	28.3105
1703.2	26.5784
1706.24	24.0902
1709.28	20.1682
1712.32	16.4008
1715.36	13.0062
1718.4	12.0692
1721.43	9.49649
1724.47	9.21045
1727.5	9.61164
1730.54	8.62454
1733.57	8.08356
1736.6	8.25965
1739.63	8.14649
1742.66	7.19193
1745.69	6.50083
1748.72	6.62697
1751.74	6.2447
1754.77	6.25708
1757.79	6.71781
1760.81	7.2789
1763.83	7.21675
1766.85	6.60417
1769.87	7.39979
1772.89	6.59113
1775.91	7.89278
1778.92	6.56905
1781.94	6.73206
1784.95	6.33789
1787.96	6.19987
1790.97	6.87471
1793.98	8.02702
1796.99	7.92232
1800	8.09452
1803	8.06296
1806.01	6.89516
1809.01	6.06797
1812.02	5.12764
1815.02	4.87445
1818.02	3.5903
1821.02	3.81199
1824.02	2.42256
1827.01	1.85683
1830.01	0.941247
1833	0.304315
1836	-0.684315
1838.99	-0.902569
1841.98	-0.465382
1844.97	-1.87412
1847.96	-1.70621
1850.95	-0.484933
1853.94	0.603126
1856.92	1.5017
1859.91	2.73645
1862.89	3.33136
1865.88	4.58576
1868.86	4.4586
1871.84	4.98486
1874.82	7.59461
1877.8	8.47769
1880.77	8.56793
1882.52	8.925
1885.51	10.5528
1888.5	11.2833
1891.49	10.4184
1894.47	10.7386
1897.46	10.0037
1900.44	9.01755
1903.42	8.10077
1906.4	7.82977
1909.38	7.60545
1912.36	5.82207
1915.34	4.58331
1918.32	3.57343
1921.29	4.23363
1924.27	2.57623
1927.24	2.10934
1930.21	1.059
1933.18	0.891905
1936.15	0.888965
1939.12	1.87191
1942.09	2.46096
1945.06	3.86383
1948.02	5.47611
1950.99	6.43509
1953.95	7.05702
1956.91	7.73202
1959.87	8.39714
1962.84	7.09068
1965.79	7.59714
1968.75	7.33858
1971.71	7.557
1974.66	7.6281
1977.62	7.79918
1980.57	7.11744
1983.53	6.96965
1986.48	7.27608
1989.43	7.23264
1992.38	5.89815
1995.33	5.66075
1998.27	5.40369
2001.22	5.88521
2004.16	6.13034
2007.11	6.45226
2010.05	7.48146
2012.99	7.13443
2015.93	8.05281
2018.87	9.32953
2021.81	8.9154
2024.75	9.11892
2027.69	8.01795
2030.62	6.82705
2033.56	6.18377
2036.49	4.82737
2039.42	6.39046
2042.35	5.69499
2045.28	6.37338
2048.21	5.62514
2051.14	5.34875
2054.06	5.4184
2056.99	5.95917
2059.92	5.84067
2062.84	5.02047
2065.76	4.57953
2068.68	5.35893
2071.6	6.60589
2074.52	6.94123
2077.44	6.74164
2080.36	7.04868
2083.27	7.54095
2086.19	8.43541
2089.1	8.17018
2092.01	9.17744
2094.93	7.75129
2097.84	7.18141
2100.75	6.51121
2103.66	6.04224
2106.56	6.68804
2109.47	7.65057
2112.37	7.31443
2115.28	7.12259
2118.18	5.9854
2121.09	3.99928
2123.99	3.71879
2126.89	4.27643
2129.79	4.07898
2132.68	4.4094
2135.58	5.42736
2138.48	7.14238
2141.37	10.3476
2144.26	11.088
2147.16	12.6025
2150.05	14.5678
2152.94	16.8888
2155.83	18.1281
2158.72	19.9905
2161.6	21.5457
2164.49	22.378
2167.38	24.4801
2170.26	26.0939
2173.14	27.273
2176.03	27.1917
2178.91	27.4141
2181.79	27.2477
2184.67	26.109
2187.54	25.0421
2190.42	22.6179
2193.3	22.2923
2196.17	21.8401
2199.05	20.3041
2201.92	20.4529
2204.79	20.1909
2207.66	18.7208
2210.53	17.2298
2213.4	16.5117
2216.27	14.2493
2219.13	13.9349
2222	12.6541
2224.86	11.1931
2227.72	10.6638
2230.59	11.3381
2233.45	10.9293
2236.31	11.4236
2239.17	11.2105
2242.03	10.8026
2244.88	11.495
2247.74	10.8415
2250.59	11.0855
2253.45	11.916
2256.3	11.9048
2259.15	10.5094
2262	10.7369
2264.85	10.5265
2267.7	9.35793
2270.55	10.2508
2273.4	9.2214
2276.24	8.56657
2279.09	6.86568
2281.93	5.96665
2284.77	4.17848
2287.61	3.79234
2290.46	2.3756
2293.29	1.04683
2296.13	1.53727
2298.97	0.360991
2301.81	1.06893
2304.64	2.43408
2307.48	3.79201
2310.31	3.52163
2313.14	4.12297
2315.97	3.84852
2318.8	3.37042
2321.63	4.48575
2324.46	5.22702
2327.29	4.66921
2330.12	3.04656
2332.94	3.49924
2335.76	3.78971
2338.59	4.06058
2341.41	4.01606
2344.23	3.26635
2347.05	2.71764
2349.87	2.51379
2352.69	2.62975
2355.5	1.93448
2358.32	1.36873
2361.14	0.432852
2363.95	1.73046
2366.76	1.45322
2369.58	3.67448
2372.39	4.55303
2375.2	5.45706
2378	5.35633
2380.81	5.65931
2383.62	6.54778
2386.42	6.93492
2389.23	7.58694
2392.03	7.59955
2394.84	7.28749
2397.64	7.18323
2400.44	8.028
2403.24	9.37225
2406.04	9.27984
2408.83	10.3971
2411.63	11.6761
2414.43	11.2001
2417.22	11.2205
2420.02	12.3317
2422.81	12.0225
2425.6	11.5009
2428.39	11.6719
2431.18	10.2268
2433.97	9.29837
2436.76	8.34107
2439.54	8.50279
2442.33	7.47244
2445.11	7.46983
2447.9	6.13332
2450.68	5.23853
2453.46	4.53422
2456.24	3.42795
2459.02	2.87081
2461.8	2.48524
2464.58	1.9887
2467.36	2.05641
2470.13	1.32457
2472.91	1.92806
2475.68	1.25006
2478.45	0.905744
2481.22	0.69582
2484	0.923169
2486.77	1.50045
2489.54	2.66468
2492.3	2.92546
2495.07	3.38433
2497.84	2.90184
2500.6	2.90179
2503.36	3.47115
2506.13	3.7471
2508.89	3.97164
2511.65	3.55753
2514.41	4.47745
2517.17	4.01676
2519.93	3.45036
2522.68	4.82457
2525.44	4.77649
2528.19	4.27894
2530.95	4.7032
2533.7	5.36069
2536.45	4.81401
2539.2	4.4525
2541.95	5.03894
2544.7	4.777
2547.45	5.59811
2550.2	7.09416
2552.94	8.22641
2555.69	8.33078
2558.43	7.99729
2561.17	7.94238
2563.92	9.07256
2566.66	8.95136
2569.4	8.61157
2572.14	8.45717
2574.88	8.69013
2577.61	8.50124
2580.35	9.21628
2583.09	8.34246
2585.82	8.23023
2588.55	7.1081
2591.28	6.93275
2594.02	6.01773
2596.75	7.12856
2599.48	6.40625
2602.2	5.86675
2604.93	5.79601
2607.66	6.09322
2610.38	5.03254
2613.11	4.34329
2615.83	3.833
2618.56	3.56672
2621.28	3.40736
2624	2.51316
2626.72	2.44062
2629.44	3.19043
2632.15	4.6578
2634.87	5.65622
2637.59	5.67503
2640.3	5.74304
2643.02	5.55322
2645.73	5.61613
2648.44	5.8443
2651.15	5.6524
2653.86	5.39459
2656.57	5.47133
2659.28	6.48082
2661.99	8.17587
2664.69	8.44911
2667.4	9.69892
2670.1	9.97788
2672.81	9.13331
2675.51	8.36015
2678.21	7.93786
2680.91	8.91628
2683.61	9.35991
2686.31	9.50306
2689	9.77568
2691.7	10.1041
2694.4	10.2792
2697.09	10.9895
2699.79	10.0482
2702.48	8.84025
2705.17	8.38351
2707.86	7.6276
2710.55	8.86452
2713.24	9.45934
2715.93	10.6138
2718.61	10.2263
2721.3	11.484
2723.99	11.8588
2726.67	12.3931
2729.35	13.2028
2732.04	13.381
2734.72	12.8768
2737.4	11.0801
2740.08	10.7525
2742.76	10.2225
2745.43	9.13316
2748.11	8.51075
2750.79	7.78068
2753.46	6.63831
2756.13	6.76258
2758.81	5.52194
2761.48	4.01109
2764.15	2.05723
2766.82	1.66366
2769.49	1.47263
2772.16	2.15926
2774.82	2.56076
2777.49	3.31354
2780.16	2.12283
2782.82	2.32238
2785.48	2.90428
2788.15	3.76935
2790.81	4.0619
2793.47	4.39731
2796.13	3.62834
2798.79	4.21475
2801.44	4.71907
2804.1	5.83997
2806.76	4.34833
2809.41	3.84092
2812.07	3.74377
2814.72	4.44782
2817.37	2.88554
2820.02	3.08902
2822.67	3.76667
2825.32	5.75309
2827.97	8.02132
2830.62	11.2209
2833.26	15.5376
2835.91	18.43
2838.55	23.0331
2841.2	27.4836
2843.84	33.497
2846.48	40.2955
2849.12	48.3208
2851.76	58.7381
2854.4	67.2913
2857.04	76.5176
2859.68	87.2037
2862.32	96.7949
2864.95	106.043
2867.58	113.36
2870.22	120.379
2872.85	126.385
2875.48	132.825
2878.11	138.032
2880.74	142.56
2883.37	146.416
2886	150.973
2888.63	155.656
2891.25	160.407
2893.88	164.574
2896.5	168.782
2899.13	172.711
2901.75	177.825
2904.37	183.735
2906.99	190.384
2909.61	199.948
2912.23	209.438
2914.85	220.296
2917.46	229.491
2920.08	237.219
2922.7	243.012
2925.31	248.632
2927.92	251.729
2930.53	253.86
2933.15	253.301
2935.76	251.975
2938.37	248.128
2940.98	242.652
2943.58	236.275
2946.19	228.423
2948.8	219.573
2951.4	210.278
2954.01	200.148
2956.61	190.53
2959.21	179.972
2961.81	168.778
2964.41	159.557
2967.01	150.215
2969.61	140.508
2972.21	132.456
2974.81	124.824
2977.4	117.451
2980	108.855
2982.59	100.458
2985.18	90.7205
2987.78	82.2229
2990.37	73.8546
2992.96	64.9809
2995.55	56.6173
2998.14	47.9888
3000.72	40.736
3003.31	35.2038
3005.9	29.7189
3008.48	24.6026
3011.07	19.8916
3013.65	14.5288
3016.23	10.5791
3018.81	8.03035
3021.39	5.53088
3023.97	4.38391
3026.55	3.01643
3029.13	1.34523
3031.71	0.650774
3034.28	0.365826
3036.86	1.89983
3039.43	3.43861
3042.01	4.95849
3044.58	6.81102
3047.15	9.06553
3049.72	9.27743
3052.29	10.7489
3054.86	11.5155
3057.43	11.481
3060	11.9001
3062.56	12.2909
3065.13	12.3627
3067.69	12.1762
3070.25	10.9215
3072.82	10.7703
3075.38	9.88534
3077.94	9.09741
3080.5	8.68271
3083.06	8.73207
3085.62	8.22742
3088.17	7.04929
3090.73	7.40715
3093.29	7.71388
3095.84	9.49442
3098.4	11.2838
3100.95	12.4527
3103.5	14.8926
3106.05	16.9632
3108.6	18.9946
3111.15	20.5587
3113.7	21.321
3116.25	23.5219
3118.79	24.8902
3121.34	26.4793
3123.88	28.3615
3126.43	30.5193
3128.97	32.1859
3131.51	35.4733
3134.05	38.1728
3136.59	40.7742
3139.14	42.8187
3141.67	45.8485
3144.21	49.4454
3146.75	53.2655
3149.28	60.0177