File: data/Raman/poly_smoothed/Mb_10_14_30_1x_45s_532 nm_x100_100%_600 gr_mm_01.txt
#Acq. time (s)=	45
#Accumulations=	2
#Range (cm-¹)=	200...3150
#Windows=	2
#Auto scanning=	Off
#Autofocus=	Off
#Macrospot=	Off
#AutoExposure=	Off
#Spike filter=	Multiple accum.
#Delay time (s)=	0
#Binning=	1
#Readout mode=	Signal
#DeNoise=	Off
#ICS correction=	On
#Dark correction=	Off
#Inst. Process=	Off
#Detector Gain=	Best Dynamic Range
#Detector ADC=	20 kHz
#Detector temperature (°C)=	-70.08
#Instrument=	LabRAM HR Evol
#Detector=	Synapse
#Objective=	x100
#Grating=	600 gr/mm
#ND Filter=	100%
#Laser (nm)=	532
#Hole=	100.021
#Range=	Auto
#Laser Pol.=	No
#Raman. Pol.=	No
#Laser Pol. (°)=	-0.0007625
#Raman Pol. (°)=	89.9995
#Collection=	Microscope
#StageXY=	Marzhauser
#StageZ=	Marzhauser
#X (µm)=	-598.7
#Y (µm)=	-1602.5
#Z (µm)=	89.6
#Full time(mm:ss)=	3:18
#Project=
#Sample=
#Site=
#Title=	Mb_10_14_30_2x_45s_532 nm_x100_100%_600 gr_mm
#Remark=
#Date=	11.07.2022 10:45
#Acquired=	11.07.2022 10:45:44
#Base:Fit=	10.08.2022 10:21:11
#Base:Sub=	10.08.2022 10:21:41
#Filter:Polynom=	16.08.2022 10:17:53
#AxisType[0]=Intens
#AxisUnit[0]=Cnt
#AxisType[1]=Spectr
#AxisUnit[1]=1/cm
200.388	8.59861
204.019	6.075
207.646	6.72337
211.274	8.40702
214.899	9.82158
218.524	9.64788
222.146	11.148
225.766	11.7906
229.388	11.0211
233.005	10.3663
236.621	9.34846
240.236	9.20995
243.852	9.4417
247.464	9.83176
251.074	9.08437
254.683	8.56978
258.291	9.03896
261.897	9.98354
265.504	9.70472
269.108	10.5151
272.71	10.0618
276.311	9.07906
279.91	8.12906
283.508	8.17495
287.105	8.57904
290.698	9.10892
294.291	9.91447
297.884	10.8198
301.475	10.7946
305.064	11.0436
308.652	11.7543
312.237	13.4285
315.822	12.7924
319.406	13.1741
322.987	13.6687
326.568	13.485
330.148	14.2929
333.724	13.7632
337.301	13.903
340.875	13.8891
344.449	11.1024
348.02	9.80533
351.592	8.29931
355.16	8.26616
358.728	7.65867
362.294	4.74009
365.858	4.00843
369.422	4.6445
372.983	4.08472
376.543	2.23592
380.102	3.39765
383.661	4.82451
387.216	5.00422
390.771	5.41043
394.324	6.15911
397.875	7.0986
401.425	7.56899
404.974	8.20906
408.524	10.0883
412.07	9.91811
415.614	9.46656
419.156	9.41893
422.698	9.73739
426.238	8.86549
429.777	6.91818
433.315	5.3162
436.852	5.1282
440.387	5.64681
443.919	5.51127
447.451	5.58169
450.982	5.67432
454.512	6.1755
458.038	5.94127
461.565	6.83577
465.091	8.62638
468.613	9.25376
472.136	11.1228
475.655	11.6012
479.176	13.2042
482.692	15.6343
486.21	16.9007
489.724	18.8377
493.237	19.917
496.75	20.4512
500.26	20.8886
503.769	22.8908
507.279	22.3103
510.785	20.6664
514.289	19.8092
517.793	18.9076
521.297	17.938
524.797	16.9822
528.297	16.3879
531.795	15.7278
535.291	14.6911
538.787	14.7674
542.281	14.2795
545.773	13.107
549.264	13.975
552.754	14.4822
556.243	13.9959
559.73	15.0065
563.216	15.8138
566.701	16.9869
570.182	15.3528
573.664	14.3132
577.145	14.2907
580.624	14.6901
584.1	14.7728
587.577	14.3903
591.052	12.2473
594.524	10.1752
597.997	8.57332
601.466	8.06428
604.936	7.04754
608.403	6.53145
611.87	6.24698
615.334	7.02318
618.799	5.60198
622.26	6.90393
625.72	8.0088
629.181	9.21476
632.638	9.91624
636.095	12.0582
639.551	14.0916
643.005	16.8162
646.457	18.9796
649.908	19.472
653.357	20.1934
656.806	20.7369
660.253	22.5641
663.7	24.3293
667.145	25.3469
670.588	25.3765
674.027	26.6307
677.468	27.2664
680.907	27.2979
684.345	29.6418
687.781	31.1446
691.216	32.8105
694.65	34.4775
698.081	36.8724
701.512	38.4733
704.942	39.1105
708.371	39.8245
711.796	41.9867
715.222	41.7058
718.645	42.9217
722.068	41.9602
725.49	42.3634
728.909	42.8123
732.329	44.3337
735.745	44.099
739.16	43.967
742.576	46.0559
745.988	48.4671
749.401	51.6493
752.811	53.993
756.22	54.7417
759.627	55.5831
763.035	59.1599
766.44	62.5011
769.843	66.8622
773.245	70.1975
776.646	73.5184
780.046	76.6652
783.444	77.8697
786.841	79.0899
790.237	80.9841
793.631	83.5365
797.024	84.7559
800.416	85.9139
803.807	86.8385
807.196	88.4886
810.584	89.2735
813.971	89.8359
817.354	88.3688
820.739	89.5569
824.122	90.4907
827.503	90.5223
830.882	88.6684
834.261	86.9361
837.637	84.0424
841.013	80.8323
844.389	80.4601
847.761	77.2076
851.131	75.1605
854.503	72.9061
857.871	69.0877
861.24	67.4398
864.606	65.2725
867.97	64.5025
871.336	63.7731
874.698	63.4707
878.058	62.0781
881.418	61.3309
884.778	61.5707
888.135	60.896
891.49	60.3239
894.845	59.5153
898.198	59.5977
901.55	59.8478
904.901	60.5271
908.25	59.4829
911.598	58.5579
914.945	59.7862
918.291	60.7681
921.635	58.4561
924.978	57.0149
928.318	55.9744
931.659	53.6682
934.998	52.5541
938.336	52.321
941.671	49.9638
945.007	49.1451
948.339	48.7696
951.672	48.3449
955.004	47.8
958.333	46.4734
961.662	44.0326
964.989	45.3667
968.315	45.1188
971.639	44.7624
974.962	44.897
978.285	45.3421
981.605	46.5306
984.924	45.7256
988.243	45.8521
991.56	45.7653
994.875	46.0765
998.188	44.758
1001.5	43.2758
1004.81	40.8701
1008.12	39.4787
1011.43	37.6013
1014.74	36.0274
1018.05	35.3823
1021.35	32.5693
1024.65	29.2829
1027.96	27.8661
1031.26	26.1052
1034.56	25.4632
1037.86	22.8125
1041.16	19.7845
1044.45	21.3047
1047.75	20.4099
1051.04	18.7602
1054.33	18.6927
1057.62	18.4869
1060.91	18.2083
1064.2	17.6529
1067.49	17.6849
1070.77	17.3758
1074.06	17.7934
1077.34	16.8198
1080.62	17.3757
1083.91	16.7471
1087.18	16.9463
1090.46	18.3689
1093.74	18.6196
1097.02	18.5869
1100.29	16.0938
1103.56	15.2919
1106.84	14.3043
1110.11	14.5732
1113.38	14.7872
1116.64	13.6782
1119.91	10.4258
1123.18	9.96919
1126.44	7.35566
1129.7	5.3042
1132.97	5.08871
1136.23	5.54921
1139.49	5.41344
1142.74	5.60738
1146	5.62276
1149.26	5.48435
1152.51	6.47318
1155.76	7.23414
1159.01	8.0536
1162.27	7.6074
1165.51	6.60414
1168.76	7.51206
1172.01	7.38038
1175.25	7.92051
1178.5	7.73644
1181.74	8.29671
1184.98	8.65849
1188.22	10.6972
1191.46	11.8575
1194.7	11.4493
1197.94	11.1502
1201.17	11.6221
1204.41	12.1989
1207.64	13.6874
1210.87	16.1745
1214.1	19.0614
1217.33	21.3764
1220.56	22.2957
1223.79	23.3596
1227.01	24.2187
1230.23	25.8378
1233.46	27.9184
1236.68	27.4913
1239.9	29.3392
1243.12	29.9991
1246.34	32.103
1249.55	33.7606
1252.77	34.8394
1255.98	37.1142
1259.2	37.8642
1262.41	37.7885
1265.62	40.1973
1268.83	41.6276
1272.03	42.2621
1275.24	43.1177
1278.45	44.3518
1281.65	45.0792
1284.85	47.2641
1288.06	49.4609
1291.26	51.5389
1294.46	52.025
1297.66	52.3179
1300.85	51.6883
1304.05	50.9817
1307.24	51.3448
1310.43	51.3562
1313.63	51.2605
1316.82	52.8218
1320.01	52.976
1323.2	52.8573
1326.38	52.0656
1329.57	51.8698
1332.76	51.5915
1335.94	49.5485
1339.12	47.7279
1342.3	45.295
1345.48	44.6637
1348.66	42.8079
1351.84	41.8841
1355.01	40.2426
1358.19	38.1344
1361.36	37.1028
1364.53	35.4718
1367.71	34.8132
1370.88	30.7162
1374.04	29.0345
1377.21	27.2683
1380.38	23.7136
1383.54	22.7139
1386.71	21.9835
1389.87	20.208
1393.03	20.3331
1396.19	20.2645
1399.35	20.8546
1402.51	20.6197
1405.67	21.2712
1408.82	21.9344
1411.98	22.7595
1415.13	24.7138
1418.28	27.7226
1421.43	31.4035
1424.58	35.5042
1427.73	38.9474
1430.88	42.4831
1434.02	45.8179
1437.17	49.6211
1440.31	52.8978
1443.45	53.2606
1446.6	53.6798
1449.74	53.5141
1452.87	53.0589
1456.01	52.2593
1459.15	51.7195
1462.28	49.9513
1465.42	46.6406
1468.55	43.5759
1471.68	40.1706
1474.81	36.7478
1477.94	33.6371
1481.07	30.5977
1484.2	26.2752
1487.32	23.2458
1490.45	20.9435
1493.57	17.8872
1496.69	15.5319
1499.81	14.3477
1502.93	12.917
1506.05	10.4591
1509.17	9.29759
1512.28	7.27789
1515.4	6.81557
1518.51	3.60116
1521.63	3.5065
1524.74	3.47933
1527.85	2.69548
1530.96	4.51838
1534.06	5.40579
1537.17	6.83474
1540.28	7.70069
1543.38	8.25277
1546.48	10.2069
1549.59	11.976
1552.69	13.72
1555.79	14.5496
1558.88	15.3762
1561.98	16.3679
1565.08	15.6499
1568.17	16.9186
1571.27	18.8271
1574.36	20.159
1577.45	21.6908
1580.54	23.2602
1583.63	24.8405
1586.72	25.559
1589.8	26.3639
1592.89	28.1698
1595.97	28.0444
1599.06	29.1555
1602.14	27.9636
1605.22	28.2749
1608.3	28.2827
1611.38	29.5158
1614.46	30.588
1617.53	31.7393
1620.61	31.9537
1623.68	33.9338
1626.75	34.871
1629.82	36.6241
1632.9	38.4434
1635.96	40.5261
1639.03	44.0264
1642.1	47.344
1645.16	51.4968
1648.23	55.2181
1651.29	57.4447
1654.36	60.3222
1657.42	63.2823
1660.48	64.0206
1663.53	63.5552
1666.59	63.0725
1669.65	60.8606
1672.7	57.8589
1675.76	53.404
1678.81	50.2548
1681.86	47.5802
1684.91	43.9491
1687.96	40.0806
1691.01	34.376
1694.06	29.4541
1697.11	25.5628
1700.15	21.9074
1703.2	18.244
1706.24	15.5248
1709.28	11.5459
1712.32	10.0683
1715.36	7.63063
1718.4	5.64653
1721.43	5.32881
1724.47	4.16377
1727.5	3.86406
1730.54	3.19059
1733.57	2.99047
1736.6	2.33117
1739.63	1.06694
1742.66	1.67411
1745.69	1.6683
1748.72	1.96938
1751.74	2.55269
1754.77	2.91277
1757.79	3.46769
1760.81	1.92858
1763.83	1.46927
1766.85	1.85032
1769.87	1.53551
1772.89	2.1798
1775.91	1.94472
1778.92	0.603655
1781.94	0.624467
1784.95	0.550923
1787.96	1.18047
1790.97	1.28495
1793.98	1.20009
1796.99	1.63335
1800	2.49892
1803	2.52485
1806.01	3.24933
1809.01	3.19268
1812.02	2.66406
1815.02	2.38065
1818.02	2.74041
1821.02	3.02636
1824.02	2.47186
1827.01	2.98758
1830.01	2.59959
1833	2.45374
1836	2.72569
1838.99	3.19608
1841.98	4.17653
1844.97	4.4424
1847.96	4.42424
1850.95	4.39685
1853.94	4.61746
1856.92	4.34135
1859.91	4.57907
1862.89	4.83928
1865.88	5.78475
1868.86	5.65069
1871.84	7.04734
1874.82	6.68156
1877.8	6.08044
1880.77	5.36601
1882.52	4.72192
1885.51	4.90431
1888.5	4.49266
1891.49	5.06629
1894.47	5.25538
1897.46	5.77186
1900.44	5.2056
1903.42	4.75937
1906.4	4.25767
1909.38	5.11546
1912.36	4.84954
1915.34	4.81162
1918.32	4.81651
1921.29	5.19459
1924.27	5.44715
1927.24	4.48468
1930.21	5.34531
1933.18	6.07421
1936.15	7.16553
1939.12	7.30888
1942.09	7.52279
1945.06	7.37291
1948.02	7.7273
1950.99	7.83209
1953.95	8.93015
1956.91	9.17887
1959.87	8.93792
1962.84	9.02808
1965.79	9.13198
1968.75	9.12859
1971.71	8.66155
1974.66	6.75065
1977.62	5.62726
1980.57	5.72068
1983.53	5.27482
1986.48	4.41235
1989.43	4.17641
1992.38	5.32531
1995.33	4.65201
1998.27	4.83874
2001.22	4.7815
2004.16	4.73275
2007.11	4.81799
2010.05	4.88446
2012.99	5.1255
2015.93	4.88897
2018.87	6.09086
2021.81	7.42246
2024.75	8.10079
2027.69	8.70037
2030.62	9.98194
2033.56	10.2074
2036.49	11.2218
2039.42	11.3476
2042.35	11.2947
2045.28	10.6348
2048.21	9.76036
2051.14	9.57442
2054.06	9.5303
2056.99	8.68803
2059.92	9.71573
2062.84	10.2129
2065.76	9.98
2068.68	9.90782
2071.6	9.59204
2074.52	8.49809
2077.44	8.34885
2080.36	9.14748
2083.27	9.42976
2086.19	9.40735
2089.1	11.1986
2092.01	12.6073
2094.93	14.3349
2097.84	15.2965
2100.75	17.2622
2103.66	18.2318
2106.56	18.5355
2109.47	18.8428
2112.37	19.8958
2115.28	19.4022
2118.18	18.7649
2121.09	19.4116
2123.99	19.6979
2126.89	19.5476
2129.79	21.0116
2132.68	20.6762
2135.58	21.046
2138.48	20.4029
2141.37	20.7787
2144.26	20.4475
2147.16	21.7842
2150.05	22.4994
2152.94	23.9294
2155.83	24.5809
2158.72	25.992
2161.6	27.4501
2164.49	28.1081
2167.38	29.6491
2170.26	30.5884
2173.14	31.5441
2176.03	32.0783
2178.91	32.8344
2181.79	32.7269
2184.67	32.9799
2187.54	31.4359
2190.42	30.6972
2193.3	30.7895
2196.17	28.8616
2199.05	27.9718
2201.92	26.6769
2204.79	25.2433
2207.66	23.2592
2210.53	22.2385
2213.4	21.3248
2216.27	20.1875
2219.13	19.1234
2222	18.2832
2224.86	17.2142
2227.72	16.1843
2230.59	14.4041
2233.45	13.4684
2236.31	13.3989
2239.17	13.0072
2242.03	12.5835
2244.88	13.1321
2247.74	12.8643
2250.59	13.2467
2253.45	12.968
2256.3	12.6923
2259.15	11.9321
2262	11.7129
2264.85	11.6054
2267.7	11.2029
2270.55	11.159
2273.4	10.9773
2276.24	11.2317
2279.09	10.856
2281.93	10.9241
2284.77	11.488
2287.61	11.2503
2290.46	10.7202
2293.29	9.20189
2296.13	8.7583
2298.97	9.78701
2301.81	9.98318
2304.64	11.6437
2307.48	12.493
2310.31	12.2099
2313.14	13.203
2315.97	12.7096
2318.8	12.7677
2321.63	12.1684
2324.46	11.6727
2327.29	9.97973
2330.12	9.22923
2332.94	8.28382
2335.76	8.06666
2338.59	7.75972
2341.41	6.30095
2344.23	5.64489
2347.05	4.59206
2349.87	3.2662
2352.69	2.40418
2355.5	1.41077
2358.32	-0.195309
2361.14	0.0602844
2363.95	1.05319
2366.76	2.02238
2369.58	2.8161
2372.39	3.51847
2375.2	5.08821
2378	4.32938
2380.81	4.4432
2383.62	3.87709
2386.42	4.13902
2389.23	4.33426
2392.03	5.10163
2394.84	5.93781
2397.64	5.9974
2400.44	6.66591
2403.24	7.56993
2406.04	8.24393
2408.83	8.47391
2411.63	9.79213
2414.43	9.82931
2417.22	9.95012
2420.02	11.0541
2422.81	11.9263
2425.6	13.2594
2428.39	13.334
2431.18	13.8601
2433.97	14.4872
2436.76	14.577
2439.54	14.9081
2442.33	15.5906
2445.11	14.8924
2447.9	13.638
2450.68	12.6945
2453.46	10.931
2456.24	9.98852
2459.02	8.40779
2461.8	6.83969
2464.58	5.15003
2467.36	4.41428
2470.13	4.34577
2472.91	3.51378
2475.68	2.51874
2478.45	2.43536
2481.22	2.08969
2484	1.12538
2486.77	1.31346
2489.54	1.96375
2492.3	2.54918
2495.07	3.00252
2497.84	3.40099
2500.6	4.7509
2503.36	4.6155
2506.13	4.53825
2508.89	4.7769
2511.65	4.46604
2514.41	3.76187
2517.17	2.85302
2519.93	2.52261
2522.68	3.01976
2525.44	3.30265
2528.19	3.33954
2530.95	3.53523
2533.7	4.49822
2536.45	4.31065
2539.2	4.04056
2541.95	3.57788
2544.7	3.4504
2547.45	4.19319
2550.2	3.78026
2552.94	4.43077
2555.69	5.26751
2558.43	5.75441
2561.17	5.69793
2563.92	4.94871
2566.66	5.24123
2569.4	4.82936
2572.14	4.45529
2574.88	4.02434
2577.61	3.91463
2580.35	3.37794
2583.09	4.06268
2585.82	4.44876
2588.55	4.82286
2591.28	4.63703
2594.02	5.09473
2596.75	5.28638
2599.48	4.96317
2602.2	4.57854
2604.93	4.5098
2607.66	4.57954
2610.38	4.43257
2613.11	4.9073
2615.83	4.38809
2618.56	4.32087
2621.28	3.70948
2624	3.41597
2626.72	3.24327
2629.44	2.41434
2632.15	2.04423
2634.87	1.71968
2637.59	1.39674
2640.3	1.29376
2643.02	0.811014
2645.73	0.233403
2648.44	0.0308557
2651.15	-0.610083
2653.86	-0.907385
2656.57	-0.655479
2659.28	-1.0442
2661.99	-0.393407
2664.69	-0.292207
2667.4	-0.0760692
2670.1	0.734476
2672.81	1.19435
2675.51	1.85164
2678.21	1.95339
2680.91	1.66758
2683.61	2.68773
2686.31	2.83519
2689	2.8508
2691.7	3.4255
2694.4	3.12651
2697.09	2.32998
2699.79	2.60258
2702.48	2.27723
2705.17	2.00695
2707.86	1.52118
2710.55	1.54614
2713.24	1.76078
2715.93	2.04164
2718.61	2.29775
2721.3	2.32519
2723.99	2.96349
2726.67	3.32055
2729.35	4.04106
2732.04	4.9137
2734.72	5.4199
2737.4	5.47865
2740.08	5.41928
2742.76	5.56496
2745.43	5.61599
2748.11	5.42975
2750.79	5.98064
2753.46	6.23336
2756.13	6.10932
2758.81	6.33446
2761.48	5.05287
2764.15	4.54466
2766.82	4.06203
2769.49	3.69328
2772.16	3.36889
2774.82	4.04822
2777.49	3.82918
2780.16	3.58499
2782.82	3.12484
2785.48	3.91726
2788.15	4.60115
2790.81	5.23754
2793.47	4.62655
2796.13	4.64202
2798.79	4.18356
2801.44	3.56835
2804.1	3.33736
2806.76	2.43792
2809.41	1.44392
2812.07	1.43406
2814.72	1.57698
2817.37	2.55442
2820.02	3.64931
2822.67	5.51235
2825.32	7.43266
2827.97	9.22358
2830.62	11.4304
2833.26	14.4219
2835.91	17.9491
2838.55	22.3044
2841.2	27.2369
2843.84	32.9289
2846.48	39.6683
2849.12	48.0232
2851.76	57.0834
2854.4	64.59
2857.04	72.3632
2859.68	79.3801
2862.32	86.3084
2864.95	92.8074
2867.58	98.2252
2870.22	103.04
2872.85	106.965
2875.48	111.393
2878.11	115.29
2880.74	119.122
2883.37	121.529
2886	124.466
2888.63	127.91
2891.25	130.313
2893.88	132.438
2896.5	135.968
2899.13	140.704
2901.75	145.555
2904.37	151.985
2906.99	160.561
2909.61	169.702
2912.23	179.568
2914.85	189.562
2917.46	198.378
2920.08	206.329
2922.7	212.37
2925.31	217.071
2927.92	220.262
2930.53	222.048
2933.15	221.2
2935.76	219.543
2938.37	217.139
2940.98	212.404
2943.58	206.666
2946.19	199.367
2948.8	192.397
2951.4	184.129
2954.01	175.623
2956.61	167.402
2959.21	159.382
2961.81	151.42
2964.41	143.328
2967.01	136.854
2969.61	130.779
2972.21	124.519
2974.81	118.706
2977.4	112.374
2980	104.944
2982.59	98.4904
2985.18	90.8643
2987.78	83.1915
2990.37	75.6358
2992.96	69.0433
2995.55	62.1828
2998.14	55.1842
3000.72	48.5236
3003.31	42.0347
3005.9	36.3292
3008.48	31.3869
3011.07	27.4794
3013.65	23.2417
3016.23	19.2934
3018.81	17.9935
3021.39	15.9795
3023.97	13.6148
3026.55	12.5379
3029.13	12.1767
3031.71	12.536
3034.28	12.6128
3036.86	12.2047
3039.43	11.938
3042.01	11.8421
3044.58	11.8614
3047.15	12.4081
3049.72	12.6243
3052.29	12.8743
3054.86	13.2759
3057.43	13.7734
3060	13.2594
3062.56	12.5047
3065.13	11.219
3067.69	9.86906
3070.25	9.74105
3072.82	8.92987
3075.38	7.56355
3077.94	5.6665
3080.5	4.99322
3083.06	4.54987
3085.62	3.65637
3088.17	3.665
3090.73	4.07851
3093.29	3.53226
3095.84	2.10462
3098.4	0.941572
3100.95	0.715797
3103.5	0.366248
3106.05	0.691715
3108.6	0.446368
3111.15	1.85714
3113.7	2.18103
3116.25	3.03008
3118.79	3.46183
3121.34	3.33678
3123.88	2.89222
3126.43	3.27194
3128.97	3.4148
3131.51	4.03602
3134.05	4.23885
3136.59	4.36331
3139.14	4.21129
3141.67	5.0899
3144.21	5.11524
3146.75	4.44897
3149.28	3.58481