File: data/Raman/poly_smoothed/Mb_10_14_14_1x_45s_532 nm_x100_100%_600 gr_mm_01.txt
#Acq. time (s)=	45
#Accumulations=	2
#Range (cm-¹)=	200...3150
#Windows=	2
#Auto scanning=	Off
#Autofocus=	Off
#Macrospot=	Off
#AutoExposure=	Off
#Spike filter=	Multiple accum.
#Delay time (s)=	0
#Binning=	1
#Readout mode=	Signal
#DeNoise=	Off
#ICS correction=	On
#Dark correction=	Off
#Inst. Process=	Off
#Detector Gain=	Best Dynamic Range
#Detector ADC=	20 kHz
#Detector temperature (°C)=	-69.85
#Instrument=	LabRAM HR Evol
#Detector=	Synapse
#Objective=	x100
#Grating=	600 gr/mm
#ND Filter=	100%
#Laser (nm)=	532
#Hole=	100.021
#Range=	Auto
#Laser Pol.=	No
#Raman. Pol.=	No
#Laser Pol. (°)=	-0.0007625
#Raman Pol. (°)=	89.9995
#Collection=	Microscope
#StageXY=	Marzhauser
#StageZ=	Marzhauser
#X (µm)=	-636.2
#Y (µm)=	-1590.1
#Z (µm)=	89
#Full time(mm:ss)=	3:19
#Project=
#Sample=
#Site=
#Title=	Mb_10_14_14_2x_45s_532 nm_x100_100%_600 gr_mm
#Remark=
#Date=	11.07.2022 09:33
#Acquired=	11.07.2022 09:33:02
#Base:Fit=	10.08.2022 10:21:11
#Base:Sub=	10.08.2022 10:21:41
#Filter:Polynom=	16.08.2022 10:17:53
#AxisType[0]=Intens
#AxisUnit[0]=Cnt
#AxisType[1]=Spectr
#AxisUnit[1]=1/cm
200.388	29.6198
204.019	20.889
207.646	13.9627
211.274	9.62872
214.899	8.71053
218.524	8.29803
222.146	9.56258
225.766	10.2228
229.388	13.2927
233.005	15.1572
236.621	14.4491
240.236	15.6229
243.852	17.0602
247.464	17.8765
251.074	19.6749
254.683	20.9894
258.291	22.0691
261.897	21.4715
265.504	20.5784
269.108	17.9283
272.71	16.5725
276.311	14.1307
279.91	11.8048
283.508	10.5598
287.105	9.78762
290.698	7.69507
294.291	7.39275
297.884	6.90274
301.475	7.90624
305.064	9.59655
308.652	10.0541
312.237	7.048
315.822	8.16155
319.406	9.84284
322.987	9.24305
326.568	9.48232
330.148	11.8492
333.724	13.3885
337.301	13.2363
340.875	12.4223
344.449	12.8991
348.02	13.2375
351.592	14.0195
355.16	13.9169
358.728	15.1287
362.294	17.9218
365.858	17.8949
369.422	20.3364
372.983	21.4623
376.543	23.2667
380.102	24.1049
383.661	27.8572
387.216	29.3185
390.771	31.9522
394.324	30.8401
397.875	28.9291
401.425	30.2939
404.974	32.6614
408.524	31.3636
412.07	31.1434
415.614	30.2364
419.156	28.9448
422.698	26.79
426.238	24.0319
429.777	21.1679
433.315	19.0461
436.852	15.5434
440.387	12.6095
443.919	8.23468
447.451	8.1979
450.982	7.25891
454.512	5.17815
458.038	4.38879
461.565	4.84373
465.091	6.77741
468.613	9.24945
472.136	11.1534
475.655	11.45
479.176	11.8413
482.692	14.4859
486.21	18.2345
489.724	21.4094
493.237	21.749
496.75	23.9685
500.26	25.9974
503.769	27.0765
507.279	27.0736
510.785	27.8226
514.289	27.5457
517.793	25.7865
521.297	24.193
524.797	23.1798
528.297	21.7244
531.795	21.0549
535.291	22.3896
538.787	21.4704
542.281	18.3323
545.773	18.8623
549.264	18.4085
552.754	17.8635
556.243	15.6621
559.73	13.6949
563.216	13.3904
566.701	13.5575
570.182	12.1247
573.664	9.80737
577.145	8.64633
580.624	6.79893
584.1	5.61744
587.577	6.61339
591.052	5.22026
594.524	4.76805
597.997	3.29979
601.466	1.97151
604.936	1.30249
608.403	1.00377
611.87	2.83639
615.334	3.50741
618.799	3.9938
622.26	6.34424
625.72	6.51982
629.181	8.16791
632.638	10.2453
636.095	11.4149
639.551	11.6575
643.005	13.5698
646.457	14.4078
649.908	14.4836
653.357	16.2861
656.806	16.2873
660.253	18.3818
663.7	18.4188
667.145	19.0846
670.588	21.5204
674.027	20.7277
677.468	21.4008
680.907	22.5061
684.345	24.3433
687.781	24.8258
691.216	26.4725
694.65	27.6509
698.081	28.6065
701.512	31.2145
704.942	32.2427
708.371	34.544
711.796	36.8334
715.222	38.751
718.645	41.1297
722.068	41.8546
725.49	44.1141
728.909	45.1748
732.329	46.3302
735.745	47.0396
739.16	47.596
742.576	48.0101
745.988	51.3341
749.401	51.8947
752.811	54.2009
756.22	55.6474
759.627	57.2407
763.035	61.1427
766.44	63.9564
769.843	64.679
773.245	65.383
776.646	66.5974
780.046	68.7251
783.444	70.9644
786.841	74.382
790.237	76.1364
793.631	78.61
797.024	80.2385
800.416	81.5377
803.807	82.9918
807.196	83.8037
810.584	83.4587
813.971	82.2007
817.354	82.0253
820.739	80.955
824.122	81.2687
827.503	81.746
830.882	79.7717
834.261	77.452
837.637	75.7864
841.013	74.4119
844.389	73.5674
847.761	71.0182
851.131	67.6254
854.503	64.3154
857.871	60.5112
861.24	59.1176
864.606	58.3081
867.97	56.539
871.336	55.5479
874.698	52.8839
878.058	53.8223
881.418	51.58
884.778	50.7072
888.135	49.0577
891.49	48.5966
894.845	47.2587
898.198	48.7666
901.55	48.67
904.901	48.5153
908.25	50.1574
911.598	48.2185
914.945	47.8658
918.291	49.9563
921.635	50.7716
924.978	50.9598
928.318	50.3041
931.659	49.6602
934.998	48.5009
938.336	46.9594
941.671	46.0003
945.007	45.0094
948.339	42.6375
951.672	41.3311
955.004	40.6065
958.333	41.4735
961.662	40.0078
964.989	40.1682
968.315	39.6783
971.639	40.6844
974.962	41.1304
978.285	42.058
981.605	41.7482
984.924	41.0665
988.243	40.7916
991.56	40.6144
994.875	40.8066
998.188	42.0216
1001.5	40.8622
1004.81	40.7954
1008.12	40.4365
1011.43	40.4409
1014.74	42.0757
1018.05	42.5371
1021.35	43.9905
1024.65	45.1547
1027.96	45.8907
1031.26	48.6081
1034.56	49.6144
1037.86	50.8545
1041.16	51.4439
1044.45	51.1341
1047.75	51.4099
1051.04	48.7113
1054.33	45.0126
1057.62	42.1281
1060.91	38.6686
1064.2	34.3301
1067.49	31.606
1070.77	26.4692
1074.06	24.4976
1077.34	21.8322
1080.62	18.2186
1083.91	15.6256
1087.18	15.862
1090.46	15.3312
1093.74	15.3991
1097.02	16.9484
1100.29	17.2956
1103.56	18.676
1106.84	18.8348
1110.11	20.3366
1113.38	21.6293
1116.64	20.6629
1119.91	21.1705
1123.18	19.2811
1126.44	17.6819
1129.7	16.2523
1132.97	15.0194
1136.23	12.2874
1139.49	11.9929
1142.74	10.5699
1146	8.3333
1149.26	5.99592
1152.51	3.46099
1155.76	3.73529
1159.01	4.36774
1162.27	3.20695
1165.51	4.24885
1168.76	5.20543
1172.01	2.9766
1175.25	3.08522
1178.5	4.15153
1181.74	5.21781
1184.98	4.85324
1188.22	5.53186
1191.46	6.02179
1194.7	7.77931
1197.94	10.0653
1201.17	12.2133
1204.41	15.8514
1207.64	18.5543
1210.87	20.6654
1214.1	22.114
1217.33	24.0607
1220.56	27.6155
1223.79	30.5071
1227.01	31.215
1230.23	33.2015
1233.46	36.7747
1236.68	39.6503
1239.9	42.1638
1243.12	42.8654
1246.34	43.8098
1249.55	43.9162
1252.77	43.0017
1255.98	43.5864
1259.2	42.1429
1262.41	41.1504
1265.62	39.3792
1268.83	39.1576
1272.03	39.9857
1275.24	42.6671
1278.45	44.2484
1281.65	45.8631
1284.85	46.479
1288.06	47.8006
1291.26	49.3067
1294.46	49.1347
1297.66	49.8415
1300.85	51.0766
1304.05	51.4403
1307.24	52.3588
1310.43	54.1813
1313.63	56.9609
1316.82	59.9908
1320.01	61.3822
1323.2	61.3239
1326.38	62.1696
1329.57	60.4276
1332.76	59.86
1335.94	58.233
1339.12	57.1474
1342.3	55.0676
1345.48	54.3897
1348.66	53.8924
1351.84	55.2448
1355.01	53.8035
1358.19	51.8166
1361.36	49.8197
1364.53	48.3418
1367.71	45.8491
1370.88	42.5745
1374.04	41.1572
1377.21	38.7802
1380.38	38.5965
1383.54	37.092
1386.71	38.4401
1389.87	37.9382
1393.03	36.438
1396.19	35.9533
1399.35	35.0649
1402.51	34.1615
1405.67	34.1133
1408.82	34.8701
1411.98	36.2242
1415.13	40.1025
1418.28	43.2973
1421.43	48.2331
1424.58	53.2609
1427.73	58.4658
1430.88	62.9035
1434.02	67.0546
1437.17	72.9563
1440.31	76.1218
1443.45	79.1959
1446.6	80.6313
1449.74	81.3811
1452.87	82.5747
1456.01	81.7126
1459.15	80.3091
1462.28	78.4548
1465.42	75.8927
1468.55	72.0559
1471.68	67.6007
1474.81	62.5818
1477.94	56.6025
1481.07	52.286
1484.2	46.3376
1487.32	42.1125
1490.45	38.9464
1493.57	35.5998
1496.69	33.2161
1499.81	30.408
1502.93	27.5256
1506.05	25.2887
1509.17	23.166
1512.28	22.0166
1515.4	19.6386
1518.51	17.3155
1521.63	14.9071
1524.74	13.5468
1527.85	15.0355
1530.96	14.5115
1534.06	15.7839
1537.17	16.611
1540.28	17.0308
1543.38	17.8935
1546.48	17.5857
1549.59	19.3063
1552.69	21.6574
1555.79	21.845
1558.88	22.6697
1561.98	22.5784
1565.08	25.699
1568.17	27.8218
1571.27	29.6445
1574.36	31.7343
1577.45	33.412
1580.54	34.6152
1583.63	37.283
1586.72	38.6656
1589.8	39.7635
1592.89	40.5077
1595.97	40.9356
1599.06	40.6868
1602.14	42.4214
1605.22	42.9875
1608.3	41.9564
1611.38	40.9145
1614.46	41.8852
1617.53	42.0657
1620.61	42.9066
1623.68	44.8527
1626.75	45.1732
1629.82	47.466
1632.9	48.3238
1635.96	49.518
1639.03	52.7803
1642.1	55.5193
1645.16	58.2777
1648.23	60.0913
1651.29	61.4852
1654.36	63.5727
1657.42	64.3546
1660.48	64.9228
1663.53	63.4957
1666.59	61.6767
1669.65	59.8817
1672.7	56.5103
1675.76	52.7045
1678.81	49.2679
1681.86	45.2266
1684.91	40.7884
1687.96	36.9331
1691.01	31.7649
1694.06	27.776
1697.11	24.0518
1700.15	20.5382
1703.2	16.7692
1706.24	13.9407
1709.28	12.0066
1712.32	10.0444
1715.36	8.37553
1718.4	6.12167
1721.43	4.69011
1724.47	4.2779
1727.5	3.91463
1730.54	3.18029
1733.57	4.106
1736.6	4.33888
1739.63	4.85799
1742.66	4.68569
1745.69	4.77668
1748.72	5.41768
1751.74	5.40384
1754.77	5.71182
1757.79	5.23014
1760.81	4.5922
1763.83	3.33082
1766.85	2.57212
1769.87	2.75648
1772.89	3.59408
1775.91	4.03665
1778.92	4.19812
1781.94	3.97923
1784.95	3.25824
1787.96	3.55247
1790.97	2.95795
1793.98	2.46867
1796.99	3.13821
1800	2.66047
1803	3.34419
1806.01	3.84209
1809.01	3.28961
1812.02	3.11926
1815.02	3.28926
1818.02	3.29322
1821.02	4.19245
1824.02	3.919
1827.01	3.81359
1830.01	4.30894
1833	4.11594
1836	4.21988
1838.99	4.14435
1841.98	4.76103
1844.97	5.88597
1847.96	5.94329
1850.95	5.33367
1853.94	5.21415
1856.92	3.69828
1859.91	3.08484
1862.89	1.53966
1865.88	1.06069
1868.86	1.23972
1871.84	0.989411
1874.82	0.877796
1877.8	0.842735
1880.77	0.221136
1882.52	0.125519
1885.51	-0.639038
1888.5	-0.170166
1891.49	0.379066
1894.47	1.41933
1897.46	0.934768
1900.44	1.9013
1903.42	2.22227
1906.4	3.12573
1909.38	4.36071
1912.36	4.80971
1915.34	5.41711
1918.32	5.52085
1921.29	5.99863
1924.27	7.67586
1927.24	7.70655
1930.21	8.07454
1933.18	9.22063
1936.15	9.7701
1939.12	9.7532
1942.09	9.80809
1945.06	10.3472
1948.02	9.66777
1950.99	9.75457
1953.95	8.27118
1956.91	6.89005
1959.87	6.16677
1962.84	5.59013
1965.79	4.49923
1968.75	4.08215
1971.71	3.23446
1974.66	3.24818
1977.62	3.2246
1980.57	3.53399
1983.53	3.23118
1986.48	3.65142
1989.43	3.76475
1992.38	4.45708
1995.33	5.26829
1998.27	6.31756
2001.22	6.60538
2004.16	6.37003
2007.11	5.98287
2010.05	6.96418
2012.99	7.13175
2015.93	7.95084
2018.87	8.16203
2021.81	8.52679
2024.75	8.85851
2027.69	7.61148
2030.62	6.8082
2033.56	6.31062
2036.49	6.48764
2039.42	6.17031
2042.35	6.32387
2045.28	6.73404
2048.21	7.17337
2051.14	8.5995
2054.06	7.77689
2056.99	8.37028
2059.92	8.25872
2062.84	8.0203
2065.76	9.24646
2068.68	9.055
2071.6	10.2603
2074.52	9.98351
2077.44	11.0497
2080.36	12.6734
2083.27	14.0666
2086.19	14.7161
2089.1	15.0087
2092.01	15.2928
2094.93	15.0764
2097.84	13.4157
2100.75	11.6994
2103.66	10.6246
2106.56	9.82088
2109.47	9.94731
2112.37	9.32295
2115.28	10.4333
2118.18	10.8374
2121.09	10.8825
2123.99	10.8441
2126.89	11.0297
2129.79	11.9291
2132.68	12.8771
2135.58	14.4267
2138.48	15.9608
2141.37	18.3784
2144.26	20.7007
2147.16	22.7652
2150.05	24.6544
2152.94	27.0225
2155.83	28.2327
2158.72	30.3359
2161.6	32.05
2164.49	33.1783
2167.38	34.1142
2170.26	33.5494
2173.14	33.5368
2176.03	33.2218
2178.91	32.7836
2181.79	32.923
2184.67	31.2495
2187.54	31.7413
2190.42	29.9017
2193.3	28.8173
2196.17	27.5876
2199.05	26.921
2201.92	25.2834
2204.79	24.0102
2207.66	22.6383
2210.53	21.5946
2213.4	21.1056
2216.27	20.518
2219.13	19.5179
2222	18.37
2224.86	17.5227
2227.72	17.5811
2230.59	16.9852
2233.45	16.4644
2236.31	15.7733
2239.17	14.7645
2242.03	13.0071
2244.88	11.7178
2247.74	11.5853
2250.59	11.06
2253.45	10.0716
2256.3	9.36435
2259.15	9.32431
2262	9.32567
2264.85	8.61342
2267.7	7.95007
2270.55	7.20826
2273.4	6.90222
2276.24	6.25142
2279.09	6.43215
2281.93	6.42792
2284.77	6.63177
2287.61	6.15784
2290.46	6.16764
2293.29	5.07511
2296.13	5.6252
2298.97	6.29762
2301.81	6.48061
2304.64	6.888
2307.48	6.90389
2310.31	6.76056
2313.14	7.37044
2315.97	8.49887
2318.8	8.53172
2321.63	8.6911
2324.46	7.47829
2327.29	7.28284
2330.12	6.98267
2332.94	6.41111
2335.76	5.9306
2338.59	5.43115
2341.41	4.93935
2344.23	4.63138
2347.05	3.8898
2349.87	4.13497
2352.69	3.11338
2355.5	2.70146
2358.32	2.35342
2361.14	1.26164
2363.95	0.925648
2366.76	2.52012
2369.58	2.81474
2372.39	3.83183
2375.2	4.11034
2378	3.97897
2380.81	5.12006
2383.62	5.52807
2386.42	5.98452
2389.23	5.55034
2392.03	4.81735
2394.84	4.37614
2397.64	5.00022
2400.44	4.70169
2403.24	5.26846
2406.04	4.96905
2408.83	4.57407
2411.63	4.50841
2414.43	4.51423
2417.22	4.14131
2420.02	3.5484
2422.81	2.71748
2425.6	2.76314
2428.39	3.00644
2431.18	2.53419
2433.97	2.89776
2436.76	3.63885
2439.54	3.75594
2442.33	3.96588
2445.11	2.49771
2447.9	1.96167
2450.68	1.40845
2453.46	1.70895
2456.24	1.09442
2459.02	1.12264
2461.8	0.141525
2464.58	0.179882
2467.36	-0.9295
2470.13	-0.207059
2472.91	-0.41507
2475.68	0.26119
2478.45	-0.0474194
2481.22	0.526682
2484	0.450201
2486.77	-0.318875
2489.54	0.572348
2492.3	0.818253
2495.07	1.72579
2497.84	1.69939
2500.6	1.97337
2503.36	1.7858
2506.13	1.82977
2508.89	1.34679
2511.65	1.09593
2514.41	0.92794
2517.17	0.843684
2519.93	1.52394
2522.68	0.860228
2525.44	0.458394
2528.19	-0.124558
2530.95	-0.235275
2533.7	-0.611372
2536.45	0.0442722
2539.2	0.887133
2541.95	1.92824
2544.7	2.37867
2547.45	1.57524
2550.2	2.1146
2552.94	1.72621
2555.69	1.92346
2558.43	1.7847
2561.17	1.5372
2563.92	2.09259
2566.66	2.92568
2569.4	3.69531
2572.14	3.29087
2574.88	3.15602
2577.61	4.40698
2580.35	5.03746
2583.09	4.94265
2585.82	4.32288
2588.55	4.55151
2591.28	3.40883
2594.02	3.69799
2596.75	4.51334
2599.48	5.55823
2602.2	5.3929
2604.93	6.16233
2607.66	6.30106
2610.38	6.3196
2613.11	4.97942
2615.83	4.17525
2618.56	3.7606
2621.28	3.58864
2624	3.87544
2626.72	3.39561
2629.44	4.82757
2632.15	4.39548
2634.87	4.24077
2637.59	3.90574
2640.3	5.26002
2643.02	5.33437
2645.73	5.78217
2648.44	4.98294
2651.15	4.73905
2653.86	4.95198
2656.57	5.64811
2659.28	6.17395
2661.99	7.98153
2664.69	7.144
2667.4	8.21861
2670.1	8.21503
2672.81	8.38317
2675.51	8.37958
2678.21	8.30875
2680.91	8.70585
2683.61	8.67782
2686.31	8.8952
2689	8.60158
2691.7	8.48736
2694.4	7.78317
2697.09	6.87447
2699.79	7.19269
2702.48	7.12817
2705.17	8.28037
2707.86	9.0847
2710.55	8.84037
2713.24	9.37862
2715.93	10.1776
2718.61	10.3604
2721.3	10.8978
2723.99	12.6362
2726.67	13.3906
2729.35	12.4186
2732.04	12.3598
2734.72	13.7189
2737.4	12.8857
2740.08	12.8659
2742.76	12.4117
2745.43	13.1173
2748.11	11.6551
2750.79	10.7393
2753.46	10.2267
2756.13	10.7226
2758.81	9.72959
2761.48	9.30812
2764.15	8.77573
2766.82	7.7736
2769.49	8.23241
2772.16	7.73816
2774.82	6.73394
2777.49	6.06299
2780.16	5.67404
2782.82	5.19906
2785.48	4.70062
2788.15	5.43274
2790.81	4.2866
2793.47	3.29453
2796.13	2.78772
2798.79	3.51535
2801.44	3.16208
2804.1	3.14009
2806.76	3.72452
2809.41	4.6825
2812.07	5.92457
2814.72	6.64797
2817.37	8.21243
2820.02	10.2195
2822.67	11.9235
2825.32	14.0395
2827.97	17.3121
2830.62	21.262
2833.26	24.3917
2835.91	28.2817
2838.55	33.1809
2841.2	38.6232
2843.84	46.5892
2846.48	55.1953
2849.12	64.0357
2851.76	73.1565
2854.4	82.0971
2857.04	90.8796
2859.68	100.277
2862.32	108.464
2864.95	117.362
2867.58	125.137
2870.22	132.211
2872.85	139.558
2875.48	145.487
2878.11	151.058
2880.74	155.986
2883.37	160.542
2886	164.615
2888.63	168.217
2891.25	172.758
2893.88	176.294
2896.5	179.586
2899.13	182.804
2901.75	187.845
2904.37	195.754
2906.99	203.437
2909.61	211.102
2912.23	220.866
2914.85	228.437
2917.46	235.211
2920.08	241.416
2922.7	247.258
2925.31	250.762
2927.92	252.675
2930.53	253.218
2933.15	252.706
2935.76	250.464
2938.37	246.769
2940.98	242.042
2943.58	235.771
2946.19	228.258
2948.8	220.423
2951.4	212.839
2954.01	203.261
2956.61	193.753
2959.21	183.392
2961.81	174.176
2964.41	165.514
2967.01	156.717
2969.61	148.873
2972.21	140.46
2974.81	132.766
2977.4	125.31
2980	116.719
2982.59	108.17
2985.18	98.4622
2987.78	90.9068
2990.37	81.344
2992.96	72.575
2995.55	64.1782
2998.14	56.3332
3000.72	49.0759
3003.31	42.5973
3005.9	35.9988
3008.48	30.0429
3011.07	25.7523
3013.65	20.4917
3016.23	15.9546
3018.81	12.1634
3021.39	8.94089
3023.97	5.60308
3026.55	3.50405
3029.13	1.89851
3031.71	0.994722
3034.28	0.0751671
3036.86	0.53952
3039.43	1.43357
3042.01	1.88977
3044.58	3.47254
3047.15	5.7754
3049.72	6.94801
3052.29	8.33968
3054.86	8.87917
3057.43	9.65482
3060	10.0795
3062.56	10.7067
3065.13	11.0404
3067.69	10.4675
3070.25	10.4997
3072.82	9.63279
3075.38	7.75544
3077.94	6.28768
3080.5	4.69699
3083.06	3.91604
3085.62	2.72098
3088.17	1.56617
3090.73	1.10407
3093.29	0.752429
3095.84	-0.546797
3098.4	-0.926543
3100.95	0.0419054
3103.5	-0.283198
3106.05	0.759201
3108.6	1.58094
3111.15	1.45405
3113.7	2.29335
3116.25	3.58116
3118.79	3.81241
3121.34	4.57263
3123.88	5.62517
3126.43	7.00865
3128.97	7.75518
3131.51	9.5833
3134.05	10.9265
3136.59	11.8051
3139.14	14.3457
3141.67	16.5901
3144.21	18.8755
3146.75	20.9601
3149.28	22.1231