File: data/Raman/poly_smoothed/Mb_10_14_32_1x_45s_532 nm_x100_100%_600 gr_mm_01.txt
#Acq. time (s)=	45
#Accumulations=	2
#Range (cm-¹)=	200...3150
#Windows=	2
#Auto scanning=	Off
#Autofocus=	Off
#Macrospot=	Off
#AutoExposure=	Off
#Spike filter=	Multiple accum.
#Delay time (s)=	0
#Binning=	1
#Readout mode=	Signal
#DeNoise=	Off
#ICS correction=	On
#Dark correction=	Off
#Inst. Process=	Off
#Detector Gain=	Best Dynamic Range
#Detector ADC=	20 kHz
#Detector temperature (°C)=	-69.85
#Instrument=	LabRAM HR Evol
#Detector=	Synapse
#Objective=	x100
#Grating=	600 gr/mm
#ND Filter=	100%
#Laser (nm)=	532
#Hole=	100.021
#Range=	Auto
#Laser Pol.=	No
#Raman. Pol.=	No
#Laser Pol. (°)=	-0.0007625
#Raman Pol. (°)=	89.9995
#Collection=	Microscope
#StageXY=	Marzhauser
#StageZ=	Marzhauser
#X (µm)=	-607.2
#Y (µm)=	-1587.1
#Z (µm)=	90.15
#Full time(mm:ss)=	3:18
#Project=
#Sample=
#Site=
#Title=	Mb_10_14_32_2x_45s_532 nm_x100_100%_600 gr_mm
#Remark=
#Date=	11.07.2022 10:54
#Acquired=	11.07.2022 10:54:20
#Base:Fit=	10.08.2022 10:21:11
#Base:Sub=	10.08.2022 10:21:41
#Filter:Polynom=	16.08.2022 10:17:53
#AxisType[0]=Intens
#AxisUnit[0]=Cnt
#AxisType[1]=Spectr
#AxisUnit[1]=1/cm
200.388	72.9758
204.019	66.6712
207.646	57.0109
211.274	47.984
214.899	41.8485
218.524	36.9589
222.146	36.5936
225.766	36.8997
229.388	35.5142
233.005	36.3708
236.621	36.7882
240.236	38.0849
243.852	38.2304
247.464	38.7228
251.074	39.9364
254.683	39.4722
258.291	41.3942
261.897	41.4905
265.504	40.3991
269.108	38.1767
272.71	35.6253
276.311	32.1886
279.91	29.7042
283.508	23.8329
287.105	19.8724
290.698	16.2788
294.291	13.3526
297.884	10.9841
301.475	10.848
305.064	10.7945
308.652	10.2012
312.237	10.649
315.822	10.2787
319.406	9.4254
322.987	10.3764
326.568	11.595
330.148	12.45
333.724	12.794
337.301	12.3835
340.875	10.5218
344.449	9.16506
348.02	8.5582
351.592	7.39859
355.16	6.86771
358.728	6.77287
362.294	8.33333
365.858	6.97515
369.422	8.21015
372.983	9.29105
376.543	12.0629
380.102	13.899
383.661	15.2008
387.216	17.4403
390.771	20.0284
394.324	21.5809
397.875	21.9245
401.425	23.3411
404.974	22.6936
408.524	21.2573
412.07	20.6846
415.614	19.3375
419.156	18.1029
422.698	14.4971
426.238	10.9955
429.777	8.6263
433.315	8.80923
436.852	7.82102
440.387	7.00546
443.919	5.24611
447.451	2.54454
450.982	1.65016
454.512	2.26925
458.038	3.64064
461.565	2.82556
465.091	4.31608
468.613	5.21173
472.136	8.40494
475.655	9.94746
479.176	12.4052
482.692	13.669
486.21	14.3878
489.724	16.2117
493.237	16.6052
496.75	17.1241
500.26	18.8117
503.769	19.5124
507.279	21.9925
510.785	22.9797
514.289	22.7132
517.793	24.4334
521.297	23.6804
524.797	22.5889
528.297	21.3865
531.795	20.2525
535.291	19.9489
538.787	19.3087
542.281	17.9717
545.773	16.0281
549.264	15.2036
552.754	15.2264
556.243	11.3537
559.73	11.2659
563.216	10.5763
566.701	9.87098
570.182	9.11877
573.664	9.10738
577.145	7.14724
580.624	6.5251
584.1	6.59128
587.577	5.68448
591.052	6.55597
594.524	6.32706
597.997	3.80076
601.466	3.15342
604.936	1.73519
608.403	2.45206
611.87	4.77739
615.334	4.81899
618.799	5.23832
622.26	6.55818
625.72	5.60679
629.181	5.23404
632.638	6.77163
636.095	7.54875
639.551	7.81763
643.005	9.17977
646.457	11.3215
649.908	12.9331
653.357	15.4
656.806	17.666
660.253	18.0262
663.7	18.7404
667.145	19.4042
670.588	18.7268
674.027	20.4366
677.468	22.1175
680.907	24.386
684.345	25.9033
687.781	27.6845
691.216	29.6776
694.65	32.4658
698.081	33.7137
701.512	36.3244
704.942	38.2845
708.371	39.7572
711.796	41.8268
715.222	43.276
718.645	45.2715
722.068	44.1016
725.49	44.8902
728.909	47.0227
732.329	48.4308
735.745	49.405
739.16	51.4597
742.576	51.9173
745.988	53.8343
749.401	56.4513
752.811	58.4854
756.22	61.952
759.627	64.9855
763.035	68.0592
766.44	69.7966
769.843	72.5764
773.245	74.5034
776.646	77.3992
780.046	80.4443
783.444	83.5784
786.841	86.1205
790.237	87.2454
793.631	87.424
797.024	88.6991
800.416	88.2532
803.807	87.1565
807.196	85.5589
810.584	86.105
813.971	86.8571
817.354	86.0784
820.739	85.2464
824.122	85.8763
827.503	86.6399
830.882	87.6832
834.261	87.7697
837.637	87.3895
841.013	88.6293
844.389	89.1107
847.761	89.0301
851.131	88.1958
854.503	88.2654
857.871	86.1931
861.24	85.7549
864.606	85.0976
867.97	84.0176
871.336	82.2843
874.698	80.5898
878.058	78.8959
881.418	78.0478
884.778	76.4897
888.135	76.508
891.49	75.5702
894.845	75.7699
898.198	73.8597
901.55	73.5566
904.901	74.5047
908.25	74.7371
911.598	76.4592
914.945	76.2428
918.291	77.9764
921.635	77.5385
924.978	79.5073
928.318	81.0017
931.659	79.2616
934.998	78.428
938.336	77.6746
941.671	78.3268
945.007	78.8219
948.339	78.1823
951.672	77.0744
955.004	76.0657
958.333	75.3092
961.662	75.3862
964.989	76.4028
968.315	78.3934
971.639	79.3797
974.962	81.8275
978.285	82.9597
981.605	83.4672
984.924	84.5686
988.243	85.9688
991.56	86.9881
994.875	87.271
998.188	88.0513
1001.5	89.096
1004.81	88.3916
1008.12	88.656
1011.43	87.5952
1014.74	86.7974
1018.05	89.0861
1021.35	90.766
1024.65	90.5692
1027.96	91.2418
1031.26	90.626
1034.56	89.6939
1037.86	88.9332
1041.16	88.0139
1044.45	87.1796
1047.75	88.2146
1051.04	86.6244
1054.33	84.6577
1057.62	82.6008
1060.91	78.2261
1064.2	75.4339
1067.49	71.5779
1070.77	68.4052
1074.06	64.5249
1077.34	63.6004
1080.62	59.7866
1083.91	58.237
1087.18	56.6898
1090.46	57.6208
1093.74	58.7204
1097.02	60.6209
1100.29	63.4038
1103.56	64.1939
1106.84	64.5842
1110.11	65.9093
1113.38	66.7109
1116.64	65.7035
1119.91	64.0794
1123.18	62.7418
1126.44	62.6479
1129.7	62.3503
1132.97	61.0347
1136.23	59.7084
1139.49	59.1693
1142.74	56.4029
1146	52.5916
1149.26	49.8297
1152.51	47.8287
1155.76	46.2869
1159.01	41.3011
1162.27	38.5971
1165.51	38.2624
1168.76	36.8976
1172.01	37.2421
1175.25	37.0336
1178.5	36.5318
1181.74	37.5868
1184.98	36.8386
1188.22	37.4192
1191.46	36.8593
1194.7	37.9651
1197.94	38.862
1201.17	40.5956
1204.41	42.2573
1207.64	45.8161
1210.87	49.4425
1214.1	50.2003
1217.33	53.8786
1220.56	55.0105
1223.79	55.6538
1227.01	55.5335
1230.23	60.0431
1233.46	60.6928
1236.68	63.1447
1239.9	63.7768
1243.12	67.3743
1246.34	68.8352
1249.55	71.3654
1252.77	71.6704
1255.98	72.9728
1259.2	73.5465
1262.41	72.785
1265.62	73.4376
1268.83	75.1953
1272.03	75.7377
1275.24	77.5647
1278.45	78.0476
1281.65	79.5649
1284.85	81.251
1288.06	82.0539
1291.26	82.2449
1294.46	84.3661
1297.66	85.2416
1300.85	84.3808
1304.05	86.1526
1307.24	89.1865
1310.43	91.8194
1313.63	92.827
1316.82	96.4812
1320.01	98.0899
1323.2	99.1044
1326.38	99.3092
1329.57	100.738
1332.76	100.237
1335.94	100.171
1339.12	99.673
1342.3	99.2658
1345.48	99.7765
1348.66	98.5212
1351.84	96.2312
1355.01	94.5083
1358.19	91.4531
1361.36	89.8465
1364.53	84.8442
1367.71	80.4963
1370.88	77.7623
1374.04	75.0712
1377.21	71.0101
1380.38	69.1625
1383.54	67.3281
1386.71	64.5573
1389.87	63.2338
1393.03	62.34
1396.19	61.6045
1399.35	60.0419
1402.51	60.7028
1405.67	60.9323
1408.82	63.9384
1411.98	66.1707
1415.13	69.0308
1418.28	72.717
1421.43	78.7822
1424.58	86.3569
1427.73	92.9883
1430.88	101.328
1434.02	106.828
1437.17	112.794
1440.31	116.604
1443.45	119.27
1446.6	121.153
1449.74	121.91
1452.87	120.944
1456.01	118.251
1459.15	115.41
1462.28	111.904
1465.42	105.74
1468.55	98.5209
1471.68	92.0021
1474.81	84.4812
1477.94	78.0815
1481.07	70.7118
1484.2	64.55
1487.32	58.9404
1490.45	52.7566
1493.57	49.4278
1496.69	46.22
1499.81	44.0496
1502.93	42.269
1506.05	39.8248
1509.17	38.3563
1512.28	36.0529
1515.4	33.1836
1518.51	32.9467
1521.63	32.5211
1524.74	33.4337
1527.85	32.876
1530.96	32.5882
1534.06	32.911
1537.17	34.4916
1540.28	34.8929
1543.38	34.7551
1546.48	35.537
1549.59	36.6239
1552.69	37.6073
1555.79	37.1474
1558.88	36.5065
1561.98	36.0647
1565.08	37.3766
1568.17	37.3072
1571.27	38.8947
1574.36	39.9525
1577.45	41.0266
1580.54	41.9781
1583.63	42.8895
1586.72	44.5386
1589.8	45.1264
1592.89	46.578
1595.97	48.9279
1599.06	49.8304
1602.14	49.8786
1605.22	51.1011
1608.3	52.7602
1611.38	53.8106
1614.46	55.8089
1617.53	56.055
1620.61	56.8279
1623.68	57.9783
1626.75	58.66
1629.82	60.6539
1632.9	62.0037
1635.96	64.8108
1639.03	69.7384
1642.1	73.4286
1645.16	75.8352
1648.23	78.6272
1651.29	79.9868
1654.36	80.3144
1657.42	81.4219
1660.48	80.2579
1663.53	80.0728
1666.59	77.2916
1669.65	75.1915
1672.7	71.1673
1675.76	66.1623
1678.81	62.0531
1681.86	57.8654
1684.91	52.9978
1687.96	47.1829
1691.01	42.0509
1694.06	37.5155
1697.11	34.0822
1700.15	29.3615
1703.2	27.1552
1706.24	26.1043
1709.28	24.3314
1712.32	23.4736
1715.36	22.3445
1718.4	20.5209
1721.43	19.3258
1724.47	19.1561
1727.5	18.5698
1730.54	16.6058
1733.57	16.9677
1736.6	15.1273
1739.63	14.0352
1742.66	12.5185
1745.69	11.2629
1748.72	9.72122
1751.74	8.47737
1754.77	6.92556
1757.79	6.15521
1760.81	3.88555
1763.83	3.1628
1766.85	1.27688
1769.87	0.632495
1772.89	0.505174
1775.91	-0.408613
1778.92	0.630954
1781.94	1.0939
1784.95	1.18385
1787.96	1.46144
1790.97	3.6287
1793.98	5.13022
1796.99	5.79996
1800	7.27589
1803	7.94663
1806.01	7.92368
1809.01	8.18436
1812.02	8.93142
1815.02	9.30532
1818.02	8.61092
1821.02	8.38354
1824.02	8.73701
1827.01	8.13206
1830.01	7.38695
1833	7.42463
1836	7.09361
1838.99	6.40988
1841.98	6.75309
1844.97	6.49304
1847.96	6.47683
1850.95	6.50582
1853.94	7.26105
1856.92	6.77234
1859.91	8.37361
1862.89	9.83624
1865.88	10.5099
1868.86	10.4986
1871.84	11.0029
1874.82	11.0607
1877.8	9.15532
1880.77	9.67024
1882.52	9.45271
1885.51	8.81192
1888.5	7.27477
1891.49	7.73804
1894.47	9.08741
1897.46	9.03509
1900.44	9.19022
1903.42	10.4381
1906.4	10.9309
1909.38	9.49092
1912.36	9.85997
1915.34	9.41205
1918.32	8.65477
1921.29	9.07884
1924.27	9.77445
1927.24	9.28639
1930.21	10.6596
1933.18	10.9556
1936.15	10.0322
1939.12	8.64125
1942.09	8.82811
1945.06	9.08321
1948.02	7.89065
1950.99	7.39188
1953.95	8.24856
1956.91	7.1353
1959.87	6.6199
1962.84	7.27575
1965.79	8.15669
1968.75	8.40571
1971.71	8.712
1974.66	8.60235
1977.62	8.25204
1980.57	6.87056
1983.53	5.48407
1986.48	5.20107
1989.43	4.62592
1992.38	4.7102
1995.33	4.9651
1998.27	5.37728
2001.22	4.78144
2004.16	4.67445
2007.11	3.81971
2010.05	3.52941
2012.99	3.75816
2015.93	5.19608
2018.87	4.37265
2021.81	4.99557
2024.75	5.63863
2027.69	6.4653
2030.62	7.31885
2033.56	8.70735
2036.49	9.34639
2039.42	8.53756
2042.35	9.15169
2045.28	9.4296
2048.21	8.71043
2051.14	8.14932
2054.06	7.24681
2056.99	6.6615
2059.92	7.12523
2062.84	7.17816
2065.76	7.50409
2068.68	8.2649
2071.6	7.65642
2074.52	7.7263
2077.44	8.48887
2080.36	8.85039
2083.27	8.38445
2086.19	9.89296
2089.1	10.3996
2092.01	10.0648
2094.93	10.4799
2097.84	12.7104
2100.75	12.1668
2103.66	11.9152
2106.56	12.9044
2109.47	12.0012
2112.37	12.9329
2115.28	13.7143
2118.18	13.2124
2121.09	13.4486
2123.99	13.4625
2126.89	13.4346
2129.79	13.2939
2132.68	13.7731
2135.58	14.7079
2138.48	16.0144
2141.37	16.9219
2144.26	17.4632
2147.16	19.047
2150.05	21.16
2152.94	23.1398
2155.83	24.8082
2158.72	27.3445
2161.6	28.625
2164.49	31.1387
2167.38	32.9642
2170.26	34.3331
2173.14	35.2613
2176.03	36.1778
2178.91	36.4404
2181.79	37.9556
2184.67	39.3605
2187.54	38.7742
2190.42	38.2495
2193.3	37.4807
2196.17	35.4299
2199.05	33.6311
2201.92	31.7171
2204.79	29.6785
2207.66	27.3518
2210.53	25.0625
2213.4	22.9154
2216.27	20.2487
2219.13	19.4394
2222	17.4749
2224.86	15.9846
2227.72	15.8419
2230.59	15.2623
2233.45	14.0515
2236.31	13.4615
2239.17	12.4277
2242.03	11.859
2244.88	11.5496
2247.74	11.6526
2250.59	11.9934
2253.45	13.6693
2256.3	13.6765
2259.15	13.8248
2262	12.6742
2264.85	11.9693
2267.7	11.9768
2270.55	11.8103
2273.4	10.4938
2276.24	10.3952
2279.09	10.2975
2281.93	8.90862
2284.77	6.99205
2287.61	6.34375
2290.46	5.72152
2293.29	4.35132
2296.13	4.03322
2298.97	4.67913
2301.81	5.42709
2304.64	6.10522
2307.48	6.77933
2310.31	7.44879
2313.14	7.99565
2315.97	8.66759
2318.8	8.89708
2321.63	9.97486
2324.46	10.1955
2327.29	9.59789
2330.12	10.338
2332.94	9.02609
2335.76	8.7515
2338.59	8.10981
2341.41	6.37013
2344.23	5.01496
2347.05	5.30015
2349.87	3.48743
2352.69	1.71665
2355.5	0.0962431
2358.32	-0.64857
2361.14	-1.32193
2363.95	-1.21993
2366.76	0.255688
2369.58	0.924313
2372.39	0.962735
2375.2	1.72169
2378	1.66966
2380.81	2.10419
2383.62	1.45384
2386.42	1.41865
2389.23	0.72675
2392.03	1.20957
2394.84	1.77871
2397.64	1.40748
2400.44	1.36793
2403.24	0.144316
2406.04	-0.523805
2408.83	-0.501608
2411.63	-0.989692
2414.43	-0.438538
2417.22	0.398564
2420.02	0.101058
2422.81	0.305056
2425.6	0.583466
2428.39	1.94252
2431.18	2.59163
2433.97	3.35241
2436.76	3.8378
2439.54	4.75895
2442.33	4.96316
2445.11	5.68187
2447.9	5.58571
2450.68	5.2064
2453.46	5.62844
2456.24	6.07005
2459.02	6.03451
2461.8	6.64819
2464.58	6.99167
2467.36	4.92185
2470.13	3.85536
2472.91	2.3718
2475.68	1.53203
2478.45	1.07525
2481.22	0.178064
2484	-0.350586
2486.77	-0.0844746
2489.54	-0.484807
2492.3	0.405188
2495.07	0.757464
2497.84	0.789553
2500.6	0.608983
2503.36	0.767606
2506.13	1.35581
2508.89	2.03329
2511.65	1.82446
2514.41	2.81183
2517.17	2.88863
2519.93	3.10861
2522.68	4.5395
2525.44	4.45931
2528.19	5.7281
2530.95	6.04913
2533.7	6.87782
2536.45	6.37603
2539.2	7.69898
2541.95	8.376
2544.7	8.71583
2547.45	9.38724
2550.2	10.6606
2552.94	10.9904
2555.69	10.8441
2558.43	11.6112
2561.17	11.6045
2563.92	10.596
2566.66	10.7559
2569.4	10.4743
2572.14	11.0912
2574.88	10.1193
2577.61	9.23864
2580.35	8.11616
2583.09	7.97643
2585.82	7.7332
2588.55	8.50861
2591.28	7.77931
2594.02	7.00233
2596.75	5.65036
2599.48	5.65846
2602.2	5.12321
2604.93	4.82239
2607.66	4.77582
2610.38	4.79665
2613.11	4.28387
2615.83	3.4165
2618.56	2.99609
2621.28	2.71527
2624	3.21233
2626.72	3.97767
2629.44	3.23033
2632.15	4.0016
2634.87	4.01661
2637.59	5.41616
2640.3	5.35474
2643.02	4.72273
2645.73	5.53802
2648.44	6.24451
2651.15	6.79524
2653.86	6.94069
2656.57	6.07943
2659.28	4.9473
2661.99	4.37517
2664.69	4.63063
2667.4	4.27061
2670.1	3.11126
2672.81	2.33333
2675.51	2.23028
2678.21	2.84135
2680.91	2.5464
2683.61	3.13541
2686.31	4.05397
2689	5.32837
2691.7	5.83195
2694.4	5.9002
2697.09	6.57002
2699.79	6.96417
2702.48	7.87984
2705.17	7.98197
2707.86	8.14357
2710.55	9.8253
2713.24	11.1693
2715.93	11.7517
2718.61	11.7034
2721.3	12.7972
2723.99	13.2953
2726.67	13.5085
2729.35	13.4194
2732.04	12.7889
2734.72	12.6652
2737.4	11.9119
2740.08	13.274
2742.76	13.2883
2745.43	12.7208
2748.11	12.1029
2750.79	11.9285
2753.46	11.516
2756.13	10.2559
2758.81	7.9947
2761.48	6.50455
2764.15	5.2034
2766.82	4.31327
2769.49	3.92309
2772.16	3.09664
2774.82	2.48999
2777.49	2.41999
2780.16	1.08361
2782.82	-0.17332
2785.48	0.0906544
2788.15	0.304583
2790.81	-0.319767
2793.47	-1.57205
2796.13	-1.98742
2798.79	-1.77379
2801.44	-1.51738
2804.1	-0.848582
2806.76	0.0213952
2809.41	0.466571
2812.07	0.332102
2814.72	1.6225
2817.37	3.38033
2820.02	4.90016
2822.67	7.87009
2825.32	10.1672
2827.97	14.9743
2830.62	20.1645
2833.26	24.1406
2835.91	29.8262
2838.55	36.3471
2841.2	43.3234
2843.84	51.3711
2846.48	61.2062
2849.12	72.61
2851.76	85.349
2854.4	98.1088
2857.04	110
2859.68	122.12
2862.32	134.244
2864.95	144.656
2867.58	154.921
2870.22	163.447
2872.85	172.543
2875.48	179.333
2878.11	186.129
2880.74	192.532
2883.37	199.232
2886	204.036
2888.63	208.797
2891.25	213.084
2893.88	217.656
2896.5	221.993
2899.13	227.584
2901.75	234.74
2904.37	242.531
2906.99	252.219
2909.61	263.717
2912.23	276.498
2914.85	289.019
2917.46	301.212
2920.08	310.618
2922.7	319.623
2925.31	325.837
2927.92	329.419
2930.53	331.008
2933.15	329.843
2935.76	326.371
2938.37	320.608
2940.98	312.727
2943.58	304.983
2946.19	294.657
2948.8	282.377
2951.4	269.2
2954.01	255.588
2956.61	241.255
2959.21	226.812
2961.81	213.234
2964.41	200.148
2967.01	188.788
2969.61	176.88
2972.21	166.874
2974.81	156.538
2977.4	147.348
2980	138.427
2982.59	128.737
2985.18	120.095
2987.78	109.239
2990.37	98.7962
2992.96	89.128
2995.55	78.7217
2998.14	68.8426
3000.72	59.8493
3003.31	50.5101
3005.9	42.9077
3008.48	34.7308
3011.07	27.4397
3013.65	21.0493
3016.23	15.4476
3018.81	10.9744
3021.39	7.96388
3023.97	6.25572
3026.55	3.35501
3029.13	2.50169
3031.71	0.492779
3034.28	-0.0848883
3036.86	0.402544
3039.43	1.26941
3042.01	2.60299
3044.58	3.7784
3047.15	4.99329
3049.72	6.22205
3052.29	8.16323
3054.86	9.94168
3057.43	10.1972
3060	10.1302
3062.56	10.8877
3065.13	9.46718
3067.69	8.96707
3070.25	8.15263
3072.82	7.6611
3075.38	6.88531
3077.94	6.80175
3080.5	6.94305
3083.06	5.87001
3085.62	5.74363
3088.17	4.68043
3090.73	3.31158
3093.29	3.22904
3095.84	2.95903
3098.4	3.14302
3100.95	3.21592
3103.5	2.65052
3106.05	3.93811
3108.6	5.6388
3111.15	7.60851
3113.7	9.40153
3116.25	11.061
3118.79	12.086
3121.34	13.8102
3123.88	15.2696
3126.43	16.9218
3128.97	17.6602
3131.51	19.7376
3134.05	21.7366
3136.59	23.8936
3139.14	26.6927
3141.67	28.2289
3144.21	29.6791
3146.75	31.1278
3149.28	32.0695