File: data/Raman/poly_smoothed/Mb_10_14_10_1x_45s_532 nm_x100_100%_600 gr_mm_01.txt
#Acq. time (s)=	45
#Accumulations=	2
#Range (cm-¹)=	200...3150
#Windows=	2
#Auto scanning=	Off
#Autofocus=	Off
#Macrospot=	Off
#AutoExposure=	Off
#Spike filter=	Multiple accum.
#Delay time (s)=	0
#Binning=	1
#Readout mode=	Signal
#DeNoise=	Off
#ICS correction=	On
#Dark correction=	Off
#Inst. Process=	Off
#Detector Gain=	Best Dynamic Range
#Detector ADC=	20 kHz
#Detector temperature (°C)=	-70.08
#Instrument=	LabRAM HR Evol
#Detector=	Synapse
#Objective=	x100
#Grating=	600 gr/mm
#ND Filter=	100%
#Laser (nm)=	532
#Hole=	100.021
#Range=	Auto
#Laser Pol.=	No
#Raman. Pol.=	No
#Laser Pol. (°)=	-0.0007625
#Raman Pol. (°)=	89.9995
#Collection=	Microscope
#StageXY=	Marzhauser
#StageZ=	Marzhauser
#X (µm)=	-2397
#Y (µm)=	2126.7
#Z (µm)=	-40.5
#Full time(mm:ss)=	3:18
#Project=
#Sample=
#Site=
#Title=	Mb_10_14_10_2x_45s_532 nm_x100_100%_600 gr_mm
#Remark=
#Date=	07.07.2022 14:07
#Acquired=	07.07.2022 14:07:46
#Base:Fit=	10.08.2022 10:21:11
#Base:Sub=	10.08.2022 10:21:41
#Filter:Polynom=	16.08.2022 10:17:53
#AxisType[0]=Intens
#AxisUnit[0]=Cnt
#AxisType[1]=Spectr
#AxisUnit[1]=1/cm
200.43	9.96875
204.061	10.1636
207.688	8.25295
211.316	5.79264
214.941	4.97419
218.566	5.88051
222.188	9.05188
225.809	13.3337
229.43	14.9595
233.047	17.524
236.663	17.8047
240.278	17.1428
243.894	17.3481
247.506	18.9336
251.116	19.3034
254.725	18.4148
258.333	17.6864
261.939	18.2398
265.546	20.3193
269.15	19.3524
272.752	16.1806
276.353	15.3726
279.952	13.315
283.55	10.4821
287.146	8.31389
290.739	4.98596
294.333	2.34358
297.925	2.6355
301.516	4.4254
305.106	4.62975
308.694	7.4509
312.279	8.488
315.864	8.27396
319.448	7.08786
323.029	6.38536
326.61	6.45309
330.19	6.30254
333.766	6.62729
337.343	6.36148
340.917	5.44471
344.491	6.22132
348.062	5.67944
351.633	6.46746
355.201	6.94437
358.77	6.4815
362.335	8.19332
365.899	9.17474
369.464	10.732
373.025	11.9692
376.585	14.5768
380.143	15.6899
383.702	18.972
387.258	24.2275
390.812	25.2134
394.365	25.7511
397.916	27.3715
401.467	27.4398
405.015	26.3608
408.565	25.7043
412.111	26.4599
415.656	24.3949
419.197	21.8818
422.739	20.5382
426.279	18.7828
429.819	16.6463
433.356	14.2031
436.893	12.4606
440.428	10.9462
443.96	9.30584
447.492	7.21022
451.023	6.96131
454.553	7.88254
458.079	7.20679
461.606	8.61198
465.132	9.60767
468.654	10.1889
472.177	12.3101
475.696	12.9081
479.217	13.6514
482.733	14.2732
486.251	17.3156
489.765	17.9022
493.278	19.9573
496.791	20.7476
500.301	22.1637
503.81	23.3814
507.319	26.5334
510.825	26.7677
514.33	26.8644
517.833	27.5602
521.337	28.0848
524.838	28.7452
528.337	26.8842
531.835	24.5881
535.332	23.415
538.827	24.6448
542.321	23.744
545.814	21.9366
549.305	20.4873
552.795	17.4818
556.284	15.668
559.771	13.5992
563.257	12.2721
566.742	11.5069
570.223	8.47808
573.705	6.11147
577.185	5.86818
580.665	3.56369
584.141	2.61239
587.617	2.7205
591.092	3.54194
594.564	4.4853
598.037	5.18659
601.506	5.9295
604.976	6.51013
608.443	7.07594
611.91	7.93538
615.374	8.62405
618.839	10.841
622.3	11.7412
625.761	12.6932
629.221	12.7195
632.679	13.5242
636.135	14.6664
639.592	17.9666
643.045	19.2788
646.497	20.0861
649.948	21.1798
653.398	20.5505
656.846	18.8333
660.293	20.5434
663.738	20.275
667.185	19.6702
670.628	21.2923
674.067	21.8205
677.508	21.8938
680.947	22.3419
684.385	21.9568
687.821	22.8483
691.256	25.2788
694.69	26.4543
698.121	26.0546
701.552	26.2345
704.982	26.6484
708.41	27.3512
711.836	28.9126
715.262	30.1702
718.685	33.3646
722.108	34.8734
725.53	37.7027
728.949	38.245
732.369	40.9563
735.785	42.4215
739.2	42.7345
742.616	46.1707
746.028	49.4743
749.441	52.8718
752.851	58.0527
756.26	60.6932
759.667	64.2306
763.075	66.7694
766.479	70.3178
769.883	73.8706
773.285	77.1409
776.686	78.5739
780.085	78.2225
783.484	79.8526
786.881	81.3047
790.276	82.6665
793.671	83.2999
797.064	83.5142
800.456	83.7245
803.846	83.4856
807.236	82.9782
810.624	81.6262
814.01	81.3843
817.394	81.1974
820.778	80.5832
824.161	80.0775
827.543	80.7933
830.921	80.2688
834.3	78.7814
837.676	76.8347
841.053	74.5426
844.426	71.3641
847.8	67.6831
851.171	65.6979
854.542	64.1032
857.911	61.9281
861.279	60.2693
864.645	57.8195
868.01	56.2627
871.375	53.0607
874.737	50.5063
878.097	49.0694
881.457	46.8906
884.817	46.4102
888.174	44.2966
891.53	44.4732
894.884	44.7821
898.237	45.2823
901.589	45.7253
904.94	46.0896
908.289	45.6802
911.637	45.9064
914.984	46.3172
918.33	45.3519
921.674	46.6017
925.015	46.7015
928.357	46.6762
931.698	46.1367
935.037	45.5365
938.373	44.542
941.71	42.4232
945.046	40.1617
948.378	38.2417
951.711	33.9799
955.043	31.1171
958.372	29.8447
961.701	27.3033
965.027	27.012
968.354	30.2202
971.678	32.7492
975	33.9301
978.324	34.3746
981.644	36.3102
984.962	36.4583
988.282	36.6057
991.598	38.0823
994.913	39.695
998.227	40.9876
1001.54	42.5025
1004.85	44.963
1008.16	44.8643
1011.47	45.2107
1014.78	45.6489
1018.08	46.5066
1021.39	47.4581
1024.69	47.1289
1028	46.9358
1031.3	45.608
1034.6	43.7376
1037.9	43.8137
1041.19	41.4891
1044.49	41.7475
1047.79	40.4343
1051.08	37.8177
1054.37	34.0808
1057.66	30.476
1060.95	26.0672
1064.24	23.2234
1067.53	19.3511
1070.81	17.8868
1074.1	16.6906
1077.38	16.1338
1080.66	14.9532
1083.94	14.0273
1087.22	13.1997
1090.5	15.0055
1093.78	15.3806
1097.05	16.6672
1100.33	16.8975
1103.6	18.8808
1106.87	19.6474
1110.15	19.625
1113.41	19.6208
1116.68	17.7067
1119.95	15.7456
1123.21	13.7437
1126.48	11.6503
1129.74	10.1949
1133	8.90244
1136.26	7.53598
1139.52	6.77568
1142.78	6.88278
1146.04	7.84134
1149.29	8.14286
1152.55	8.02999
1155.8	7.35632
1159.05	7.47449
1162.3	4.87994
1165.55	5.45638
1168.8	6.12731
1172.05	5.94808
1175.29	7.11268
1178.54	6.84527
1181.78	8.09029
1185.02	8.4671
1188.26	6.89917
1191.5	7.97589
1194.74	6.79164
1197.97	6.14424
1201.21	6.92216
1204.44	7.75016
1207.68	9.96783
1210.91	13.5267
1214.14	14.7887
1217.37	19.461
1220.6	22.8878
1223.82	25.3076
1227.05	28.3226
1230.27	30.6984
1233.49	32.4298
1236.72	33.7932
1239.94	36.1132
1243.16	39.2761
1246.37	40.9436
1249.59	42.843
1252.8	45.0359
1256.02	44.3567
1259.23	45.271
1262.44	44.2642
1265.66	44.1152
1268.87	44.3046
1272.07	42.4937
1275.28	41.8415
1278.48	43.135
1281.69	45.1907
1284.89	46.0482
1288.09	48.3969
1291.3	49.137
1294.49	51.0371
1297.69	52.4366
1300.89	53.5877
1304.09	53.6554
1307.28	55.2145
1310.47	57.5427
1313.66	57.9936
1316.86	59.855
1320.05	60.784
1323.23	60.7279
1326.42	61.1828
1329.61	62.1779
1332.79	59.9271
1335.98	58.0032
1339.16	56.0536
1342.34	54.0414
1345.52	51.353
1348.7	49.8818
1351.87	46.7624
1355.05	46.0768
1358.23	43.2823
1361.4	40.7207
1364.57	39.0125
1367.74	36.5734
1370.91	33.7074
1374.08	32.2349
1377.25	30.5177
1380.42	29.4668
1383.58	26.7902
1386.75	26.8759
1389.91	25.4513
1393.07	23.9286
1396.23	24.6479
1399.39	23.008
1402.55	23.5202
1405.7	24.4908
1408.86	25.1962
1412.01	27.4729
1415.17	33.0321
1418.32	37.399
1421.47	42.32
1424.62	48.6195
1427.77	53.8714
1430.92	59.4256
1434.06	63.7662
1437.2	67.6491
1440.35	72.3271
1443.49	75.515
1446.63	77.8429
1449.77	78.1682
1452.91	77.9425
1456.05	76.2083
1459.18	75.2027
1462.32	73.2665
1465.45	69.2882
1468.59	66.0557
1471.72	62.646
1474.85	57.719
1477.98	54.4417
1481.11	51.1771
1484.23	49.4825
1487.36	47.2097
1490.48	45.4068
1493.61	42.8692
1496.73	39.938
1499.85	37.7221
1502.97	34.6534
1506.09	30.9253
1509.2	27.8302
1512.32	25.0209
1515.44	21.9179
1518.55	18.8706
1521.66	16.0003
1524.77	13.0177
1527.88	10.1533
1530.99	9.47728
1534.1	10.0071
1537.21	11.3612
1540.31	10.4926
1543.42	11.2292
1546.52	11.938
1549.62	13.1901
1552.72	15.3046
1555.82	16.2836
1558.92	17.646
1562.02	19.0392
1565.11	20.725
1568.21	24.2843
1571.3	27.4221
1574.39	28.3943
1577.49	31.2355
1580.58	33.0013
1583.67	34.6543
1586.75	36.8925
1589.84	38.9643
1592.93	39.9422
1596.01	42.2269
1599.09	44.9567
1602.18	45.5316
1605.26	47.0011
1608.34	48.2687
1611.41	48.1163
1614.49	47.4884
1617.57	46.8516
1620.64	47.5073
1623.72	48.234
1626.79	47.7951
1629.86	49.7881
1632.93	50.7782
1636	53.5037
1639.07	55.7682
1642.14	59.0083
1645.2	62.551
1648.27	65.0054
1651.33	66.5195
1654.39	67.9063
1657.45	68.0904
1660.51	68.4163
1663.57	67.8315
1666.63	67.209
1669.69	65.1429
1672.74	62.297
1675.79	57.2008
1678.85	53.0044
1681.9	47.1064
1684.95	40.7594
1688	35.0924
1691.05	28.8692
1694.1	23.2703
1697.14	20.1696
1700.19	15.6679
1703.23	12.4419
1706.27	10.3561
1709.32	7.37128
1712.35	4.50348
1715.39	3.26813
1718.43	1.8395
1721.47	1.17583
1724.5	0.314651
1727.54	0.118137
1730.57	-0.827234
1733.61	-0.722164
1736.64	-0.756205
1739.67	-0.230794
1742.7	0.212845
1745.72	-0.088676
1748.75	-1.02132
1751.78	-0.352142
1754.8	0.0245319
1757.82	-0.7189
1760.85	-0.0464496
1763.87	0.0881562
1766.89	-0.388087
1769.91	0.642142
1772.92	1.05284
1775.94	0.693447
1778.96	0.699254
1781.97	0.765884
1784.98	1.50548
1788	1.22527
1791.01	1.17242
1794.01	1.57493
1797.02	1.96954
1800.03	1.59133
1803.04	1.4564
1806.04	1.74051
1809.05	1.95507
1812.05	2.46148
1815.05	3.37649
1818.05	3.72044
1821.05	4.63915
1824.05	4.74827
1827.05	4.70916
1830.04	5.75868
1833.04	5.91499
1836.03	5.56073
1839.03	5.66702
1842.02	5.50374
1845.01	4.86124
1848	4.14832
1850.99	3.77298
1853.97	4.5708
1856.96	4.63255
1859.94	4.46164
1862.93	4.36883
1865.91	4.22404
1868.89	3.97508
1871.87	3.29562
1874.85	3.12345
1877.83	4.33464
1880.81	4.17777
1882.56	3.82414
1885.55	5.14639
1888.54	5.67228
1891.52	6.2621
1894.51	7.63942
1897.49	8.05728
1900.48	7.73688
1903.46	8.48191
1906.44	8.67395
1909.42	8.73469
1912.4	8.50974
1915.38	8.94313
1918.35	8.25955
1921.33	8.6892
1924.3	8.51829
1927.28	8.08999
1930.25	9.34205
1933.22	9.34076
1936.19	10.3077
1939.16	10.2109
1942.13	10.273
1945.09	9.67198
1948.06	9.36628
1951.03	8.85475
1953.99	8.71423
1956.95	8.57968
1959.91	7.71392
1962.87	7.81355
1965.83	7.83792
1968.79	7.59065
1971.75	7.12141
1974.7	6.77752
1977.66	7.12395
1980.61	7.3042
1983.56	8.06357
1986.52	8.48454
1989.47	8.60647
1992.41	9.30413
1995.36	9.71376
1998.31	9.74601
2001.26	10.8807
2004.2	11.3889
2007.15	12.427
2010.09	12.914
2013.03	12.5714
2015.97	11.4436
2018.91	11.5746
2021.85	11.8057
2024.79	12.0203
2027.72	11.7752
2030.66	11.3396
2033.59	11.4679
2036.53	11.3114
2039.46	10.8862
2042.39	11.8372
2045.32	12.0045
2048.25	12.093
2051.18	13.5056
2054.1	14.3542
2057.03	14.6014
2059.95	14.8539
2062.88	14.3704
2065.8	14.3536
2068.72	13.3091
2071.64	12.641
2074.56	12.8186
2077.48	13.444
2080.39	15.1451
2083.31	13.9727
2086.22	13.2121
2089.14	12.9436
2092.05	13.5237
2094.96	13.7062
2097.87	13.3665
2100.78	13.6238
2103.69	13.9387
2106.6	14.384
2109.51	15.4133
2112.41	16.7072
2115.32	18.1004
2118.22	18.1355
2121.12	19.9626
2124.02	21.1578
2126.92	21.9349
2129.82	23.0494
2132.72	24.351
2135.62	25.5571
2138.51	26.9231
2141.41	28.7603
2144.3	30.4507
2147.19	32.5999
2150.09	35.0842
2152.97	36.5251
2155.86	38.1785
2158.75	40.1537
2161.64	40.9734
2164.53	42.3241
2167.41	43.5231
2170.3	43.5213
2173.18	44.8961
2176.06	44.6253
2178.94	43.9579
2181.82	44.0124
2184.7	42.4597
2187.58	40.5574
2190.46	39.6744
2193.33	37.4763
2196.21	35.2328
2199.08	33.0886
2201.95	31.132
2204.83	30.139
2207.7	28.8427
2210.57	26.4676
2213.43	24.6831
2216.3	23.8049
2219.17	23.3893
2222.03	23.8224
2224.9	24.6122
2227.76	24.8296
2230.62	24.7446
2233.49	24.3212
2236.34	25.174
2239.2	24.0263
2242.06	23.8358
2244.92	23.5593
2247.78	22.9489
2250.63	23.4546
2253.48	22.3621
2256.34	20.4947
2259.19	19.4756
2262.04	18.3258
2264.89	17.5984
2267.74	16.7092
2270.59	15.4141
2273.43	14.7167
2276.28	12.6708
2279.12	11.3294
2281.97	10.2768
2284.81	9.57177
2287.65	10.3639
2290.49	9.81165
2293.33	10.1171
2296.17	9.24045
2299.01	9.47658
2301.84	10.2514
2304.68	10.0816
2307.51	11.0454
2310.35	11.1827
2313.18	12.3417
2316.01	13.3693
2318.84	14.2214
2321.67	14.0372
2324.5	13.385
2327.33	14.8588
2330.15	14.3364
2332.98	14.4817
2335.8	14.2507
2338.62	10.8869
2341.45	9.70045
2344.27	7.9439
2347.09	6.49415
2349.91	6.5913
2352.72	5.39129
2355.54	4.27754
2358.36	3.50654
2361.17	2.00431
2363.98	2.47436
2366.8	4.08015
2369.61	3.70354
2372.42	2.79058
2375.23	2.99276
2378.04	3.03779
2380.85	2.63911
2383.66	3.80345
2386.46	4.02941
2389.26	5.15702
2392.07	4.62694
2394.87	5.25395
2397.67	5.46869
2400.47	4.61721
2403.27	3.92071
2406.07	2.66387
2408.87	2.36479
2411.67	3.17248
2414.46	2.52188
2417.26	3.64745
2420.05	4.0716
2422.84	3.75476
2425.64	4.20877
2428.43	5.22815
2431.22	5.51771
2434.01	5.80152
2436.79	5.3113
2439.58	4.28407
2442.37	4.09113
2445.15	3.84845
2447.93	3.82825
2450.72	5.96249
2453.5	5.94511
2456.28	6.16692
2459.06	5.60479
2461.84	5.17145
2464.62	5.48595
2467.39	5.18983
2470.17	4.47917
2472.94	4.03155
2475.72	3.39248
2478.49	3.19592
2481.26	2.60691
2484.03	2.75514
2486.8	2.10319
2489.57	2.43979
2492.34	2.74254
2495.1	3.52261
2497.87	3.70523
2500.63	3.27537
2503.4	3.59285
2506.16	5.01126
2508.92	5.24015
2511.68	5.00109
2514.44	7.00752
2517.2	6.91504
2519.96	7.13303
2522.72	6.60343
2525.47	6.58815
2528.23	7.62493
2530.98	7.60118
2533.74	6.99142
2536.49	6.75937
2539.24	5.89904
2541.99	5.27144
2544.74	4.35879
2547.49	4.07769
2550.23	3.37358
2552.98	2.88865
2555.72	2.66149
2558.47	3.06005
2561.21	2.42273
2563.95	1.98871
2566.69	1.58738
2569.43	1.39233
2572.17	2.10603
2574.91	1.87233
2577.65	0.439043
2580.39	0.813206
2583.12	0.912292
2585.85	0.652022
2588.59	0.824234
2591.32	1.41989
2594.05	2.29248
2596.78	2.25625
2599.51	2.02776
2602.24	1.99901
2604.97	2.33171
2607.69	2.34311
2610.42	2.10472
2613.14	1.94634
2615.87	1.62462
2618.59	1.99623
2621.31	2.57103
2624.03	2.89857
2626.75	3.66378
2629.47	3.76456
2632.19	4.05232
2634.91	4.37439
2637.62	5.16491
2640.34	5.98186
2643.05	5.94705
2645.76	6.4047
2648.48	6.72178
2651.19	6.70439
2653.9	7.08117
2656.6	7.97938
2659.31	8.13484
2662.02	7.59159
2664.73	7.52163
2667.43	7.18457
2670.14	6.82649
2672.84	5.49158
2675.54	4.71833
2678.24	4.0711
2680.94	3.61116
2683.64	3.63163
2686.34	4.01849
2689.04	3.87183
2691.74	3.77565
2694.43	4.32167
2697.13	4.55163
2699.82	4.44601
2702.51	4.86402
2705.21	6.22035
2707.9	6.30013
2710.58	7.27147
2713.27	7.74143
2715.96	9.30556
2718.65	10.1475
2721.33	10.8169
2724.02	11.271
2726.71	10.659
2729.39	10.7747
2732.07	11.4006
2734.75	9.69635
2737.43	9.00579
2740.11	8.88187
2742.79	8.45562
2745.47	7.33034
2748.14	6.29424
2750.82	5.97106
2753.49	5.12776
2756.17	4.81259
2758.84	4.1077
2761.51	3.24387
2764.18	1.714
2766.85	2.19608
2769.52	2.01968
2772.19	0.996521
2774.86	0.673285
2777.52	0.124444
2780.19	0.132352
2782.85	-0.424346
2785.52	-1.2262
2788.18	-1.60895
2790.84	-1.63021
2793.5	-1.8701
2796.16	-1.18701
2798.82	-1.79346
2801.48	-1.94141
2804.13	-1.62919
2806.79	-2.04953
2809.45	-2.97456
2812.1	-2.93464
2814.75	-3.34668
2817.41	-1.97503
2820.06	-0.409215
2822.71	2.30926
2825.36	6.06
2828	10.5699
2830.65	14.8241
2833.3	19.905
2835.94	24.7468
2838.59	31.2507
2841.23	38.1844
2843.87	47.0879
2846.52	56.4536
2849.16	67.0275
2851.8	78.9477
2854.44	90.5174
2857.08	102.62
2859.71	112.074
2862.35	121.609
2864.98	130.731
2867.62	139.419
2870.25	147.038
2872.88	153.418
2875.52	158.103
2878.15	163.407
2880.78	167.747
2883.41	172.595
2886.03	177.297
2888.66	181.097
2891.29	185.423
2893.91	189.085
2896.54	192.959
2899.16	198.466
2901.78	206.233
2904.4	214.77
2907.02	224.568
2909.64	236.375
2912.26	248.274
2914.88	261.2
2917.5	273.138
2920.11	283.679
2922.73	291.725
2925.34	297.603
2927.96	303.015
2930.57	304.765
2933.18	305.25
2935.79	302.277
2938.4	297.864
2941.01	291.36
2943.62	283.317
2946.22	273.546
2948.83	263.159
2951.43	251.465
2954.04	239.505
2956.64	226.788
2959.24	215.164
2961.84	203.752
2964.45	192.424
2967.05	182.936
2969.64	173.115
2972.24	163.845
2974.84	155.147
2977.43	147.494
2980.03	138.009
2982.62	129.094
2985.22	118.452
2987.81	108.105
2990.4	99.4548
2992.99	89.5131
2995.58	79.785
2998.17	71.2542
3000.76	61.9177
3003.34	53.3672
3005.93	44.8065
3008.52	37.2826
3011.1	31.1971
3013.68	26.1601
3016.27	20.7687
3018.85	16.3428
3021.43	13.2338
3024.01	10.134
3026.59	7.32519
3029.16	5.76457
3031.74	4.09388
3034.32	2.92705
3036.89	3.09683
3039.47	3.48279
3042.04	4.87012
3044.61	6.09614
3047.18	7.92087
3049.75	9.53943
3052.32	11.365
3054.89	11.9118
3057.46	12.2134
3060.03	12.0116
3062.59	11.9292
3065.16	11.7837
3067.72	11.7159
3070.29	11.6168
3072.85	11.0216
3075.41	10.4825
3077.97	8.86337
3080.53	7.39118
3083.09	4.99104
3085.65	3.5657
3088.21	1.65834
3090.76	0.291941
3093.32	0.0891467
3095.87	-0.568994
3098.43	0.0431178
3100.98	0.0401817
3103.53	0.759149
3106.08	1.43204
3108.63	1.98076
3111.18	3.22127
3113.73	3.12494
3116.28	3.25784
3118.83	4.30411
3121.37	5.24194
3123.92	6.37381
3126.46	8.36452
3129	9.74212
3131.55	10.6185
3134.09	12.063
3136.63	13.1302
3139.17	14.6949
3141.71	16.3642
3144.24	18.7469
3146.78	22.2125
3149.32	26.2316