File: data/Raman/poly_smoothed/Mb_10_14_01_1x_45s_532 nm_x100_100%_600 gr_mm_01.txt
#Acq. time (s)=	45
#Accumulations=	2
#Range (cm-¹)=	200...3150
#Windows=	2
#Auto scanning=	Off
#Autofocus=	Off
#Macrospot=	Off
#AutoExposure=	Off
#Spike filter=	Multiple accum.
#Delay time (s)=	0
#Binning=	1
#Readout mode=	Signal
#DeNoise=	Off
#ICS correction=	On
#Dark correction=	Off
#Inst. Process=	Off
#Detector Gain=	Best Dynamic Range
#Detector ADC=	20 kHz
#Detector temperature (°C)=	-70.08
#Instrument=	LabRAM HR Evol
#Detector=	Synapse
#Objective=	x100
#Grating=	600 gr/mm
#ND Filter=	100%
#Laser (nm)=	532
#Hole=	100.021
#Range=	Auto
#Laser Pol.=	No
#Raman. Pol.=	No
#Laser Pol. (°)=	-0.0007625
#Raman Pol. (°)=	89.9995
#Collection=	Microscope
#StageXY=	Marzhauser
#StageZ=	Marzhauser
#X (µm)=	-2412.9
#Y (µm)=	2136
#Z (µm)=	-40.85
#Full time(mm:ss)=	3:20
#Project=
#Sample=
#Site=
#Title=	Mb_10_14_01_2x_45s_532 nm_x100_100%_600 gr_mm
#Remark=
#Date=	07.07.2022 13:30
#Acquired=	07.07.2022 13:30:45
#Base:Fit=	10.08.2022 10:21:11
#Base:Sub=	10.08.2022 10:21:41
#Filter:Polynom=	16.08.2022 10:17:53
#AxisType[0]=Intens
#AxisUnit[0]=Cnt
#AxisType[1]=Spectr
#AxisUnit[1]=1/cm
200.43	-2.08995
204.061	1.08941
207.688	3.62606
211.316	6.22782
214.941	8.42568
218.566	11.1904
222.188	14.1095
225.809	15.9395
229.43	19.1767
233.047	21.6285
236.663	23.3234
240.278	26.8917
243.894	27.9273
247.506	28.3738
251.116	28.6677
254.725	27.4111
258.333	27.8276
261.939	26.7628
265.546	24.1789
269.15	21.3687
272.752	21.1928
276.353	19.1567
279.952	15.301
283.55	12.6206
287.146	9.31715
290.739	6.80599
294.333	4.71582
297.925	3.38944
301.516	1.77742
305.106	0.275334
308.694	0.942017
312.279	-0.282948
315.864	-0.24694
319.448	0.967852
323.029	2.21287
326.61	3.195
330.19	4.30321
333.766	2.59982
337.343	3.20946
340.917	5.0286
344.491	4.88011
348.062	6.16775
351.633	7.20982
355.201	9.67296
358.77	14.6913
362.335	16.5708
365.899	19.9892
369.464	23.8723
373.025	25.2718
376.585	28.7247
380.143	31.9032
383.702	35.5948
387.258	38.6124
390.812	40.0704
394.365	41.4025
397.916	41.7753
401.467	41.9601
405.015	41.5442
408.565	41.3645
412.111	38.147
415.656	33.8839
419.197	28.4349
422.739	25.3215
426.279	22.8767
429.819	18.1712
433.356	15.1519
436.893	13.2527
440.428	10.8976
443.96	10.0836
447.492	9.10807
451.023	7.13455
454.553	6.24345
458.079	6.01229
461.606	7.21707
465.132	9.6088
468.654	9.81238
472.177	12.8339
475.696	14.5806
479.217	18.4262
482.733	21.6067
486.251	26.4146
489.765	28.8435
493.278	30.8309
496.791	32.6519
500.301	34.1879
503.81	35.0397
507.319	35.9196
510.825	37.9193
514.33	39.4486
517.833	38.4556
521.337	39.1924
524.838	37.7989
528.337	37.0488
531.835	37.7485
535.332	36.293
538.827	34.0166
542.321	32.2815
545.814	29.2196
549.305	25.8111
552.795	24.9849
556.284	22.3904
559.771	21.3861
563.257	21.0647
566.742	19.4065
570.223	18.1642
573.705	16.1357
577.185	12.7379
580.665	11.5694
584.141	11.3932
587.617	8.24959
591.092	6.41565
594.564	6.82156
598.037	5.20723
601.506	5.26162
604.976	4.7402
608.443	3.52384
611.91	4.76468
615.374	6.87738
618.839	8.02657
622.3	8.30828
625.761	8.7761
629.221	9.81115
632.679	11.7346
636.135	15.7591
639.592	17.7551
643.045	18.9217
646.497	21.1952
649.948	24.3672
653.398	26.2794
656.846	27.2374
660.293	30.337
663.738	32.6167
667.185	35.0013
670.628	38.364
674.067	40.8571
677.508	42.8327
680.947	43.9714
684.385	43.5272
687.821	44.9073
691.256	42.588
694.69	43.1739
698.121	43.9082
701.552	43.3986
704.982	42.6818
708.41	43.7154
711.836	44.2173
715.262	43.422
718.685	42.7013
722.108	39.9317
725.53	39.3185
728.949	40.0141
732.369	40.5326
735.785	43.4993
739.2	44.3572
742.616	45.9007
746.028	47.7036
749.441	50.9401
752.851	53.2144
756.26	54.2611
759.667	55.7174
763.075	56.6477
766.479	54.949
769.883	54.9039
773.285	55.5212
776.686	58.1941
780.085	59.9135
783.484	60.8896
786.881	62.9336
790.276	65.2183
793.671	66.4904
797.064	65.6622
800.456	67.0981
803.846	66.7773
807.236	68.9064
810.624	69.9511
814.01	70.9611
817.394	73.3299
820.778	73.5596
824.161	72.4656
827.543	74.0623
830.921	74.6418
834.3	74.4187
837.676	72.5529
841.053	71.441
844.426	71.6712
847.8	67.5903
851.171	66.5564
854.542	64.8498
857.911	60.985
861.279	59.9626
864.645	58.4089
868.01	57.6734
871.375	55.6611
874.737	53.333
878.097	50.7046
881.457	49.1364
884.817	47.7864
888.174	46.4089
891.53	41.3103
894.884	41.834
898.237	41.6155
901.589	41.7243
904.94	41.2087
908.289	43.2032
911.637	42.5125
914.984	44.3563
918.33	44.4968
921.674	43.9362
925.015	45.1979
928.357	44.8424
931.698	44.3089
935.037	46.3262
938.373	50.0851
941.71	50.8905
945.046	51.6138
948.378	51.0777
951.711	50.3126
955.043	49.955
958.372	47.9337
961.701	46.2677
965.027	46.0921
968.354	47.3375
971.678	46.8838
975	49.0827
978.324	50.9719
981.644	50.8679
984.962	53.5277
988.282	53.3917
991.598	53.089
994.913	51.9577
998.227	51.6729
1001.54	52.0141
1004.85	53.1765
1008.16	56.2139
1011.47	58.7964
1014.78	59.9974
1018.08	63.3733
1021.39	63.9114
1024.69	65.1262
1028	68.1249
1031.3	72.0811
1034.6	73.4212
1037.9	72.4435
1041.19	73.004
1044.49	75.0099
1047.79	75.4284
1051.08	74.4162
1054.37	72.2059
1057.66	68.9146
1060.95	65.7421
1064.24	61.3835
1067.53	54.8422
1070.81	49.9501
1074.1	46.1682
1077.38	42.9034
1080.66	38.5015
1083.94	33.4125
1087.22	30.9143
1090.5	28.5766
1093.78	25.8617
1097.05	23.136
1100.33	24.0423
1103.6	23.9306
1106.87	25.4647
1110.15	25.5202
1113.41	25.9667
1116.68	26.6273
1119.95	27.533
1123.21	26.3158
1126.48	26.313
1129.74	25.9885
1133	24.6311
1136.26	25.4067
1139.52	24.8826
1142.78	26.0137
1146.04	25.6253
1149.29	25.8581
1152.55	26.1065
1155.8	22.6583
1159.05	19.264
1162.3	15.9435
1165.55	14.3347
1168.8	13.1532
1172.05	10.7248
1175.29	9.54672
1178.54	10.1352
1181.78	10.4368
1185.02	11.931
1188.26	12.8598
1191.5	14.1064
1194.74	14.4957
1197.97	15.3138
1201.21	17.8627
1204.44	20.998
1207.68	22.8722
1210.91	27.1411
1214.14	31.171
1217.37	36.2369
1220.6	40.1441
1223.82	43.2589
1227.05	44.2754
1230.27	48.5282
1233.49	49.7074
1236.72	53.3308
1239.94	54.5839
1243.16	58.8608
1246.37	61.7436
1249.59	65.7139
1252.8	68.725
1256.02	70.6995
1259.23	70.0768
1262.44	70.7657
1265.66	72.9483
1268.87	72.0731
1272.07	76.2264
1275.28	77.2277
1278.48	79.2541
1281.69	79.8836
1284.89	78.804
1288.09	79.2761
1291.3	80.3378
1294.49	80.904
1297.69	80.6514
1300.89	79.37
1304.09	80.7322
1307.28	83.5665
1310.47	82.401
1313.66	85.5548
1316.86	89.8515
1320.05	90.7363
1323.23	92.2266
1326.42	92.5132
1329.61	92.3446
1332.79	92.1743
1335.98	90.7836
1339.16	90.8289
1342.34	90.9558
1345.52	89.5296
1348.7	89.7247
1351.87	89.1649
1355.05	85.8106
1358.23	83.3896
1361.4	79.7179
1364.57	76.3971
1367.74	75.5712
1370.91	74.2556
1374.08	72.021
1377.25	70.9518
1380.42	70.4498
1383.58	69.5294
1386.75	67.771
1389.91	67.8134
1393.07	70.8839
1396.23	70.7909
1399.39	71.0819
1402.55	71.615
1405.7	70.8511
1408.86	72.6543
1412.01	75.4921
1415.17	79.2332
1418.32	82.8633
1421.47	86.6966
1424.62	91.0744
1427.77	97.2498
1430.92	100.516
1434.06	106.535
1437.2	113.004
1440.35	117.95
1443.49	121.137
1446.63	122.042
1449.77	122.57
1452.91	120.624
1456.05	118.818
1459.18	115.673
1462.32	111.486
1465.45	108.995
1468.59	104.047
1471.72	96.4466
1474.85	88.9557
1477.98	82.0852
1481.11	75.2795
1484.23	69.3277
1487.36	64.5391
1490.48	59.8945
1493.61	52.7935
1496.73	49.9822
1499.85	47.6738
1502.97	45.4892
1506.09	44.417
1509.2	45.422
1512.32	45.6863
1515.44	45.3792
1518.55	44.1162
1521.66	45.1966
1524.77	43.6452
1527.88	43.61
1530.99	47.0969
1534.1	47.9221
1537.21	50.2129
1540.31	52.6155
1543.42	53.6313
1546.52	56.1676
1549.62	57.8809
1552.72	59.8427
1555.82	62.2706
1558.92	61.6192
1562.02	63.0906
1565.11	64.1606
1568.21	64.588
1571.3	66.3242
1574.39	71.4265
1577.49	72.3983
1580.58	76.333
1583.67	78.9235
1586.75	79.9487
1589.84	82.2417
1592.93	83.136
1596.01	84.7374
1599.09	83.4864
1602.18	81.8351
1605.26	82.3581
1608.34	81.2001
1611.41	80.2586
1614.49	79.8112
1617.57	79.2053
1620.64	80.3161
1623.72	80.3324
1626.79	78.5845
1629.86	77.2347
1632.93	76.9596
1636	76.9729
1639.07	77.5908
1642.14	79.8857
1645.2	80.187
1648.27	82.9072
1651.33	84.1383
1654.39	86.1986
1657.45	87.5545
1660.51	89.6811
1663.57	92.742
1666.63	89.4957
1669.69	86.7621
1672.74	82.2717
1675.79	75.8966
1678.85	68.5468
1681.9	63.7428
1684.95	57.2445
1688	50.6919
1691.05	45.1301
1694.1	39.8594
1697.14	34.382
1700.19	26.4926
1703.23	20.7324
1706.27	17.5127
1709.32	14.9614
1712.35	10.4048
1715.39	7.539
1718.43	6.92345
1721.47	4.02852
1724.5	5.10077
1727.54	5.76596
1730.57	8.29119
1733.61	10.4715
1736.64	12.514
1739.67	9.87261
1742.7	8.71331
1745.72	8.27729
1748.75	7.42042
1751.78	5.27806
1754.8	4.7465
1757.82	5.3385
1760.85	4.79173
1763.87	4.48947
1766.89	4.18883
1769.91	3.36585
1772.92	1.50865
1775.94	1.05041
1778.96	1.85103
1781.97	1.93176
1784.98	0.479375
1788	0.471574
1791.01	1.25969
1794.01	1.36386
1797.02	1.30317
1800.03	3.0059
1803.04	5.4229
1806.04	7.0631
1809.05	6.56121
1812.05	7.56425
1815.05	7.26152
1818.05	9.10026
1821.05	8.91127
1824.05	7.2663
1827.05	8.42358
1830.04	9.40801
1833.04	9.78158
1836.03	8.28756
1839.03	6.98936
1842.02	5.75364
1845.01	4.93653
1848	5.71551
1850.99	5.25169
1853.97	4.76315
1856.96	4.67225
1859.94	5.02333
1862.93	5.61312
1865.91	5.95136
1868.89	5.18383
1871.87	5.50393
1874.85	7.55474
1877.83	8.849
1880.81	9.14221
1882.56	8.95694
1885.55	8.92994
1888.54	7.62918
1891.52	8.27125
1894.51	7.9857
1897.49	8.38546
1900.48	8.85271
1903.46	7.25878
1906.44	6.13561
1909.42	3.67944
1912.4	4.65161
1915.38	3.56883
1918.35	4.84504
1921.33	4.56872
1924.3	4.44829
1927.28	4.6936
1930.25	4.88718
1933.22	6.34024
1936.19	6.39863
1939.16	5.73504
1942.13	6.19974
1945.09	6.53007
1948.06	8.92941
1951.03	7.58954
1953.99	6.58932
1956.95	4.90888
1959.91	5.45117
1962.87	4.86091
1965.83	5.75854
1968.79	7.06309
1971.75	7.65709
1974.7	8.52492
1977.66	6.60827
1980.61	7.1997
1983.56	7.71147
1986.52	8.9037
1989.47	9.58469
1992.41	10.2852
1995.36	9.31339
1998.31	10.963
2001.26	13.5214
2004.2	13.6887
2007.15	13.444
2010.09	13.835
2013.03	15.6282
2015.97	16.1506
2018.91	17.7277
2021.85	16.7446
2024.79	15.6742
2027.72	17.5805
2030.66	16.123
2033.59	17.9381
2036.53	17.2655
2039.46	19.0093
2042.39	20.2237
2045.32	18.6898
2048.25	18.6199
2051.18	17.5785
2054.1	16.9577
2057.03	15.9349
2059.95	15.8838
2062.88	15.7793
2065.8	15.4337
2068.72	16.187
2071.64	15.7178
2074.56	14.8751
2077.48	15.6805
2080.39	15.4357
2083.31	15.3586
2086.22	16.7074
2089.14	16.2693
2092.05	16.3281
2094.96	15.8681
2097.87	16.583
2100.78	16.162
2103.69	16.5847
2106.6	18.1826
2109.51	18.7634
2112.41	18.5025
2115.32	18.1995
2118.22	17.9407
2121.12	20.3111
2124.02	20.7978
2126.92	20.4141
2129.82	24.0817
2132.72	24.6213
2135.62	25.3475
2138.51	26.2427
2141.41	25.948
2144.3	27.8808
2147.19	33.4658
2150.09	35.1731
2152.97	37.362
2155.86	39.7904
2158.75	40.961
2161.64	41.719
2164.53	43.0802
2167.41	45.5373
2170.3	46.1581
2173.18	47.7158
2176.06	49.5791
2178.94	49.8271
2181.82	48.8841
2184.7	48.7808
2187.58	49.388
2190.46	49.1309
2193.33	49.6453
2196.21	47.1944
2199.08	45.0154
2201.95	43.9214
2204.83	42.7259
2207.7	40.3717
2210.57	39.625
2213.43	36.732
2216.3	38.2818
2219.17	36.8182
2222.03	34.3765
2224.9	33.8582
2227.76	29.524
2230.62	29.2697
2233.49	27.3859
2236.34	27.0668
2239.2	25.0343
2242.06	24.3186
2244.92	23.2595
2247.78	21.871
2250.63	20.4446
2253.48	19.8091
2256.34	20.4547
2259.19	20.2983
2262.04	21.9942
2264.89	21.7887
2267.74	21.3329
2270.59	20.8727
2273.43	20.5436
2276.28	21.3305
2279.12	20.7409
2281.97	19.5808
2284.81	17.7229
2287.65	17.752
2290.49	16.5172
2293.33	15.1617
2296.17	14.3812
2299.01	14.651
2301.84	12.9952
2304.68	11.0394
2307.51	9.22209
2310.35	8.57001
2313.18	10.1806
2316.01	10.2489
2318.84	10.9264
2321.67	11.9295
2324.5	11.6803
2327.33	13.3356
2330.15	13.9023
2332.98	13.4756
2335.8	13.6026
2338.62	12.8856
2341.45	11.8854
2344.27	10.9615
2347.09	9.65777
2349.91	7.82479
2352.72	4.88884
2355.54	4.04557
2358.36	3.29023
2361.17	1.13055
2363.98	1.21105
2366.8	2.40771
2369.61	1.46741
2372.42	-0.531956
2375.23	-1.38297
2378.04	0.0739277
2380.85	0.3444
2383.66	2.17428
2386.46	2.26744
2389.26	0.757654
2392.07	1.78771
2394.87	1.10624
2397.67	2.34881
2400.47	2.96777
2403.27	3.92712
2406.07	5.3662
2408.87	4.21002
2411.67	6.2786
2414.46	7.57428
2417.26	10.5841
2420.05	11.2634
2422.84	12.847
2425.64	14.8662
2428.43	17.9545
2431.22	19.4327
2434.01	20.934
2436.79	20.3012
2439.58	19.2154
2442.37	16.8862
2445.15	18.0414
2447.93	17.1699
2450.72	16.4829
2453.5	15.067
2456.28	13.1506
2459.06	11.1956
2461.84	9.1145
2464.62	7.81407
2467.39	6.64129
2470.17	5.62634
2472.94	1.89473
2475.72	0.0203871
2478.49	0.094941
2481.26	2.02556
2484.03	3.59942
2486.8	3.51338
2489.57	4.12881
2492.34	5.18638
2495.1	6.7242
2497.87	7.20608
2500.63	6.74839
2503.4	6.97946
2506.16	8.94175
2508.92	9.926
2511.68	11.7471
2514.44	13.459
2517.2	13.3493
2519.96	13.3081
2522.72	13.6816
2525.47	12.8161
2528.23	11.7668
2530.98	10.7954
2533.74	9.91985
2536.49	8.80475
2539.24	8.71271
2541.99	7.71448
2544.74	7.27961
2547.49	7.56484
2550.23	8.6069
2552.98	7.49287
2555.72	6.35318
2558.47	5.72517
2561.21	6.34125
2563.95	6.62541
2566.69	8.10257
2569.43	7.50578
2572.17	8.399
2574.91	10.8332
2577.65	12.2624
2580.39	12.8103
2583.12	13.5198
2585.85	13.7029
2588.59	14.8264
2591.32	13.5654
2594.05	12.7907
2596.78	12.5275
2599.51	11.3308
2602.24	9.66952
2604.97	10.0217
2607.69	9.07531
2610.42	8.26568
2613.14	7.83281
2615.87	10.5123
2618.59	9.16124
2621.31	6.77842
2624.03	6.97291
2626.75	8.18971
2629.47	9.25367
2632.19	9.65254
2634.91	11.204
2637.62	11.5493
2640.34	12.8565
2643.05	14.1655
2645.76	14.4833
2648.48	14.2249
2651.19	14.2347
2653.9	14.0491
2656.6	12.1961
2659.31	11.158
2662.02	10.3134
2664.73	10.3018
2667.43	9.43268
2670.14	9.74544
2672.84	9.47928
2675.54	9.29294
2678.24	8.37388
2680.94	8.09372
2683.64	7.77992
2686.34	5.76
2689.04	4.28178
2691.74	4.6783
2694.43	4.08198
2697.13	4.48837
2699.82	4.8312
2702.51	6.03131
2705.21	6.4081
2707.9	7.478
2710.58	9.21102
2713.27	9.43808
2715.96	10.5353
2718.65	11.6398
2721.33	13.3011
2724.02	15.3366
2726.71	15.8271
2729.39	16.7523
2732.07	17.6841
2734.75	18.4226
2737.43	17.9389
2740.11	17.9638
2742.79	18.0397
2745.47	17.1083
2748.14	15.0573
2750.82	12.706
2753.49	10.6422
2756.17	8.06744
2758.84	7.73378
2761.51	9.01351
2764.18	9.12163
2766.85	8.73268
2769.52	8.90911
2772.19	9.35446
2774.86	9.22908
2777.52	7.97122
2780.19	7.73066
2782.85	8.456
2785.52	10.2997
2788.18	11.5291
2790.84	10.9371
2793.5	8.74673
2796.16	9.62647
2798.82	7.17481
2801.48	8.99429
2804.13	7.39288
2806.79	7.29251
2809.45	4.98487
2812.1	2.671
2814.75	2.63087
2817.41	1.54909
2820.06	5.86798
2822.71	7.36644
2825.36	12.3393
2828	15.5523
2830.65	21.126
2833.3	26.8495
2835.94	33.9702
2838.59	42.4629
2841.23	51.9687
2843.87	64.5099
2846.52	79.8397
2849.16	93.1839
2851.8	108.597
2854.44	123.908
2857.08	138.09
2859.71	152.574
2862.35	166.027
2864.98	178.691
2867.62	191.032
2870.25	201.27
2872.88	209.969
2875.52	217.317
2878.15	226.114
2880.78	231.904
2883.41	238.333
2886.03	243.839
2888.66	249.129
2891.29	252.545
2893.91	259.006
2896.54	266.511
2899.16	273.795
2901.78	283.348
2904.4	295.512
2907.02	308.411
2909.64	323.637
2912.26	340.008
2914.88	356.671
2917.5	373.45
2920.11	385.96
2922.73	394.792
2925.34	401.591
2927.96	405.262
2930.57	407.996
2933.18	406.565
2935.79	401.491
2938.4	395.156
2941.01	386.817
2943.62	372.694
2946.22	357.84
2948.83	342.987
2951.43	326.94
2954.04	309.06
2956.64	292.193
2959.24	275.92
2961.84	260.69
2964.45	243.571
2967.05	228.691
2969.64	214.743
2972.24	203.089
2974.84	190.385
2977.43	177.352
2980.03	164.182
2982.62	151.126
2985.22	136.653
2987.81	123.372
2990.4	108.496
2992.99	96.1128
2995.58	85.3745
2998.17	73.7105
3000.76	62.1653
3003.34	52.8043
3005.93	43.5555
3008.52	36.653
3011.1	28.8119
3013.68	23.2852
3016.27	18.9093
3018.85	14.7776
3021.43	11.3797
3024.01	7.99265
3026.59	5.2684
3029.16	3.0659
3031.74	2.16569
3034.32	2.41018
3036.89	1.40352
3039.47	1.45441
3042.04	3.17126
3044.61	5.7227
3047.18	6.37689
3049.75	4.87785
3052.32	5.51857
3054.89	6.21862
3057.46	7.83471
3060.03	8.26761
3062.59	8.82403
3065.16	9.21199
3067.72	10.6674
3070.29	8.04545
3072.85	7.1582
3075.41	6.57443
3077.97	6.80728
3080.53	5.92219
3083.09	4.92432
3085.65	2.1682
3088.21	3.48457
3090.76	4.10775
3093.32	4.96638
3095.87	7.1779
3098.43	8.81218
3100.98	10.0692
3103.53	13.1487
3106.08	14.6172
3108.63	15.9021
3111.18	17.7463
3113.73	18.5198
3116.28	19.4339
3118.83	22.7626
3121.37	25.1416
3123.92	29.2373
3126.46	31.4923
3129	34.2066
3131.55	35.9064
3134.09	39.3808
3136.63	43.4385
3139.17	47.9557
3141.71	52.1025
3144.24	57.9239
3146.78	65.5398
3149.32	75.0491