File: data/Raman/poly_smoothed/Mb_10_14_46_1x_45s_532 nm_x100_100%_600 gr_mm_01.txt
#Acq. time (s)=	45
#Accumulations=	2
#Range (cm-¹)=	200...3150
#Windows=	2
#Auto scanning=	Off
#Autofocus=	Off
#Macrospot=	Off
#AutoExposure=	Off
#Spike filter=	Multiple accum.
#Delay time (s)=	0
#Binning=	1
#Readout mode=	Signal
#DeNoise=	Off
#ICS correction=	On
#Dark correction=	Off
#Inst. Process=	Off
#Detector Gain=	Best Dynamic Range
#Detector ADC=	20 kHz
#Detector temperature (°C)=	-69.85
#Instrument=	LabRAM HR Evol
#Detector=	Synapse
#Objective=	x100
#Grating=	600 gr/mm
#ND Filter=	100%
#Laser (nm)=	532
#Hole=	100.021
#Range=	Auto
#Laser Pol.=	No
#Raman. Pol.=	No
#Laser Pol. (°)=	-0.0007625
#Raman Pol. (°)=	89.9995
#Collection=	Microscope
#StageXY=	Marzhauser
#StageZ=	Marzhauser
#X (µm)=	-630.6
#Y (µm)=	-1700.6
#Z (µm)=	89.1
#Full time(mm:ss)=	3:18
#Project=
#Sample=
#Site=
#Title=	Mb_10_14_46_2x_45s_532 nm_x100_100%_600 gr_mm
#Remark=
#Date=	11.07.2022 12:09
#Acquired=	11.07.2022 12:09:07
#Base:Fit=	10.08.2022 10:21:11
#Base:Sub=	10.08.2022 10:21:41
#Filter:Polynom=	16.08.2022 10:17:53
#AxisType[0]=Intens
#AxisUnit[0]=Cnt
#AxisType[1]=Spectr
#AxisUnit[1]=1/cm
200.388	42.0239
204.019	32.0262
207.646	21.7282
211.274	14.3057
214.899	10.367
218.524	9.33008
222.146	12.4966
225.766	16.849
229.388	21.55
233.005	23.1715
236.621	25.3794
240.236	26.2694
243.852	28.9296
247.464	30.6653
251.074	33.7978
254.683	35.3501
258.291	35.1615
261.897	36.1391
265.504	35.5006
269.108	35.5719
272.71	33.2194
276.311	28.7108
279.91	23.9969
283.508	20.5654
287.105	15.9415
290.698	10.9736
294.291	9.13538
297.884	6.54164
301.475	4.94137
305.064	3.65451
308.652	3.97927
312.237	6.15039
315.822	3.21492
319.406	2.05354
322.987	1.00444
326.568	1.25684
330.148	0.732513
333.724	0.213979
337.301	-2.40594
340.875	-2.42916
344.449	-2.1643
348.02	1.32788
351.592	6.0472
355.16	11.6523
358.728	17.5427
362.294	22.0966
365.858	25.9007
369.422	33.1187
372.983	37.8457
376.543	42.3218
380.102	46.3922
383.661	51.5218
387.216	55.9507
390.771	57.5447
394.324	59.7573
397.875	59.5104
401.425	59.3645
404.974	55.5702
408.524	54.1901
412.07	51.2434
415.614	43.727
419.156	37.6626
422.698	31.7534
426.238	26.5582
429.777	22.8164
433.315	19.2884
436.852	18.2025
440.387	15.3015
443.919	15.4155
447.451	12.9993
450.982	8.93483
454.512	6.94218
458.038	6.76653
461.565	7.8281
465.091	9.58615
468.613	10.7175
472.136	13.5653
475.655	15.6668
479.176	15.9739
482.692	18.14
486.21	22.6272
489.724	26.4428
493.237	28.9532
496.75	31.6319
500.26	33.3909
503.769	35.903
507.279	40.3829
510.785	42.0645
514.289	43.7765
517.793	45.3048
521.297	47.2324
524.797	48.5038
528.297	48.2848
531.795	48.3418
535.291	45.8889
538.787	43.4018
542.281	42.195
545.773	41.0117
549.264	37.9467
552.754	34.7756
556.243	31.5872
559.73	26.8329
563.216	23.5931
566.701	19.5741
570.182	16.306
573.664	12.5982
577.145	8.44694
580.624	7.1954
584.1	6.3864
587.577	5.97829
591.052	5.03448
594.524	6.06721
597.997	4.96246
601.466	5.48123
604.936	8.47327
608.403	10.5392
611.87	11.547
615.334	14.8973
618.799	17.0467
622.26	17.5487
625.72	19.7106
629.181	21.0249
632.638	22.671
636.095	23.5029
639.551	23.9977
643.005	25.3166
646.457	26.2082
649.908	25.367
653.357	24.3764
656.806	23.5193
660.253	23.2049
663.7	24.267
667.145	24.9886
670.588	22.6306
674.027	22.0292
677.468	23.1657
680.907	22.1923
684.345	21.3208
687.781	22.5077
691.216	22.4037
694.65	22.6552
698.081	23.3889
701.512	23.4924
704.942	24.4065
708.371	26.7161
711.796	28.3203
715.222	29.1022
718.645	31.1008
722.068	33.9591
725.49	36.3014
728.909	37.5348
732.329	38.1623
735.745	38.2983
739.16	41.7956
742.576	42.4519
745.988	44.0599
749.401	45.9864
752.811	47.9361
756.22	50.7766
759.627	52.3558
763.035	53.6316
766.44	54.4801
769.843	56.8301
773.245	58.3566
776.646	60.7612
780.046	62.0663
783.444	63.1233
786.841	64.2897
790.237	66.3354
793.631	68.8231
797.024	68.1534
800.416	68.8097
803.807	70.961
807.196	70.91
810.584	70.1494
813.971	70.0406
817.354	69.9253
820.739	70.0217
824.122	70.7104
827.503	69.788
830.882	71.7043
834.261	71.2531
837.637	68.8629
841.013	67.9813
844.389	67.1636
847.761	65.1446
851.131	63.235
854.503	59.903
857.871	56.2191
861.24	52.526
864.606	50.3252
867.97	45.8554
871.336	45.545
874.698	46.035
878.058	45.4457
881.418	45.2669
884.778	44.6153
888.135	45.0391
891.49	45.0833
894.845	43.9694
898.198	45.0264
901.55	44.7201
904.901	47.2575
908.25	46.7733
911.598	47.0903
914.945	46.3968
918.291	47.8128
921.635	48.536
924.978	47.1104
928.318	45.1072
931.659	44.3776
934.998	42.3341
938.336	39.9845
941.671	38.7355
945.007	36.3285
948.339	35.5009
951.672	37.0831
955.004	38.304
958.333	36.2367
961.662	35.064
964.989	35.502
968.315	38.7118
971.639	41.0121
974.962	43.4451
978.285	47.3222
981.605	49.466
984.924	49.2591
988.243	49.8023
991.56	49.0034
994.875	49.4636
998.188	52.0515
1001.5	53.7835
1004.81	54.6631
1008.12	55.0464
1011.43	57.8133
1014.74	60.0984
1018.05	63.0536
1021.35	66.941
1024.65	68.104
1027.96	68.4162
1031.26	68.7453
1034.56	67.3625
1037.86	63.8743
1041.16	62.0579
1044.45	61.3226
1047.75	60.5788
1051.04	59.2731
1054.33	53.9113
1057.62	48.6618
1060.91	43.4107
1064.2	36.6301
1067.49	30.8881
1070.77	26.9876
1074.06	22.5365
1077.34	19.5325
1080.62	18.6756
1083.91	16.1279
1087.18	15.7068
1090.46	15.7687
1093.74	17.6347
1097.02	20.4536
1100.29	21.2716
1103.56	22.7494
1106.84	22.2418
1110.11	22.4471
1113.38	21.8845
1116.64	20.687
1119.91	20.6553
1123.18	20.7328
1126.44	19.4297
1129.7	19.434
1132.97	18.6904
1136.23	17.3508
1139.49	16.0655
1142.74	15.6057
1146	13.5945
1149.26	11.8951
1152.51	10.5448
1155.76	9.16699
1159.01	8.13174
1162.27	6.13068
1165.51	4.65186
1168.76	4.54901
1172.01	6.18928
1175.25	7.6052
1178.5	9.17626
1181.74	11.2252
1184.98	14.0741
1188.22	15.2712
1191.46	15.4065
1194.7	16.1744
1197.94	18.0495
1201.17	19.9094
1204.41	24.1331
1207.64	28.6131
1210.87	33.6353
1214.1	36.5594
1217.33	40.7836
1220.56	43.9295
1223.79	48.5449
1227.01	52.1626
1230.23	55.2945
1233.46	58.9058
1236.68	61.5222
1239.9	62.0782
1243.12	64.1469
1246.34	66.8719
1249.55	68.3761
1252.77	69.468
1255.98	69.3598
1259.2	69.7903
1262.41	70.1634
1265.62	67.4536
1268.83	65.4433
1272.03	62.8281
1275.24	63.5071
1278.45	64.8006
1281.65	67.1453
1284.85	68.8007
1288.06	70.6796
1291.26	71.4635
1294.46	73.6798
1297.66	76.29
1300.85	77.3484
1304.05	79.2555
1307.24	81.5624
1310.43	83.0193
1313.63	85.2016
1316.82	86.3901
1320.01	89.6588
1323.2	89.2267
1326.38	89.2764
1329.57	89.9296
1332.76	88.2505
1335.94	88.4922
1339.12	87.4902
1342.3	83.9573
1345.48	82.5045
1348.66	80.8608
1351.84	79.1616
1355.01	77.7592
1358.19	76.3342
1361.36	74.5694
1364.53	72.1973
1367.71	69.9388
1370.88	67.169
1374.04	65.3057
1377.21	62.3596
1380.38	60.3765
1383.54	58.8933
1386.71	57.2789
1389.87	57.0276
1393.03	55.2496
1396.19	54.5911
1399.35	51.7523
1402.51	50.8735
1405.67	52.518
1408.82	53.2521
1411.98	56.4868
1415.13	60.9268
1418.28	64.1893
1421.43	70.0055
1424.58	77.0003
1427.73	85.3575
1430.88	94.6782
1434.02	103.576
1437.17	109.377
1440.31	116.653
1443.45	120.338
1446.6	123.794
1449.74	125.872
1452.87	125.612
1456.01	124.713
1459.15	122.133
1462.28	118.029
1465.42	114.433
1468.55	109.5
1471.68	103.65
1474.81	97.7438
1477.94	93.823
1481.07	88.6992
1484.2	83.8563
1487.32	79.4979
1490.45	75.802
1493.57	69.6008
1496.69	66.7443
1499.81	66.3913
1502.93	64.1593
1506.05	62.5882
1509.17	58.6163
1512.28	53.7737
1515.4	51.0098
1518.51	48.243
1521.63	46.9969
1524.74	43.8459
1527.85	40.5883
1530.96	39.0567
1534.06	38.0319
1537.17	38.1339
1540.28	38.707
1543.38	40.042
1546.48	39.2113
1549.59	39.9378
1552.69	40.4287
1555.79	40.5148
1558.88	40.8838
1561.98	41.0486
1565.08	41.5015
1568.17	43.3997
1571.27	46.6645
1574.36	50.5901
1577.45	51.6233
1580.54	55.0419
1583.63	59.0432
1586.72	62.8897
1589.8	66.4354
1592.89	70.1187
1595.97	72.2988
1599.06	75.1242
1602.14	76.5869
1605.22	76.5396
1608.3	78.7758
1611.38	79.8544
1614.46	80.1043
1617.53	81.3854
1620.61	81.5938
1623.68	80.6548
1626.75	80.7643
1629.82	82.0379
1632.9	83.7013
1635.96	86.7317
1639.03	89.7525
1642.1	93.444
1645.16	98.4267
1648.23	102.064
1651.29	104.83
1654.36	107.313
1657.42	109.82
1660.48	108.462
1663.53	106.219
1666.59	102.509
1669.65	99.3507
1672.7	95.5169
1675.76	90.2118
1678.81	83.7423
1681.86	78.0876
1684.91	72.4712
1687.96	65.1244
1691.01	57.7745
1694.06	49.7416
1697.11	41.7698
1700.15	35.9546
1703.2	31.1253
1706.24	28.0442
1709.28	25.4048
1712.32	22.0963
1715.36	20.3562
1718.4	18.3844
1721.43	16.3773
1724.47	14.0216
1727.5	11.263
1730.54	11.0935
1733.57	9.09802
1736.6	9.28131
1739.63	9.85498
1742.66	10.0405
1745.69	9.81519
1748.72	10.6014
1751.74	9.85736
1754.77	10.2343
1757.79	8.99673
1760.81	7.82055
1763.83	6.91515
1766.85	5.82554
1769.87	5.19005
1772.89	4.16067
1775.91	4.625
1778.92	2.48212
1781.94	2.07842
1784.95	1.23911
1787.96	1.11902
1790.97	0.940518
1793.98	-0.552067
1796.99	-1.11847
1800	-0.350886
1803	1.13137
1806.01	2.3684
1809.01	3.66911
1812.02	4.13905
1815.02	4.33598
1818.02	4.78256
1821.02	5.56672
1824.02	6.33699
1827.01	6.90059
1830.01	6.40981
1833	6.86868
1836	6.60926
1838.99	6.96572
1841.98	6.27207
1844.97	6.1632
1847.96	5.61098
1850.95	5.7457
1853.94	5.55131
1856.92	6.33187
1859.91	6.02814
1862.89	5.2877
1865.88	3.93793
1868.86	3.16795
1871.84	3.90268
1874.82	4.23076
1877.8	4.33686
1880.77	3.68347
1882.52	4.26887
1885.51	3.96274
1888.5	3.43516
1891.49	2.49035
1894.47	1.81035
1897.46	1.4811
1900.44	0.54319
1903.42	0.808465
1906.4	0.993907
1909.38	2.10675
1912.36	3.29314
1915.34	2.87336
1918.32	4.36841
1921.29	5.69013
1924.27	6.6576
1927.24	6.83372
1930.21	7.02949
1933.18	6.67676
1936.15	6.73329
1939.12	6.93246
1942.09	7.56776
1945.06	7.96973
1948.02	8.35414
1950.99	7.80618
1953.95	7.55733
1956.91	6.24186
1959.87	5.55529
1962.84	2.88012
1965.79	3.68337
1968.75	4.45468
1971.71	4.21132
1974.66	5.34732
1977.62	5.53799
1980.57	6.81111
1983.53	6.46169
1986.48	6.70779
1989.43	7.13689
1992.38	8.54795
1995.33	8.5864
1998.27	9.37593
2001.22	10.193
2004.16	10.1344
2007.11	9.26698
2010.05	9.79987
2012.99	9.32857
2015.93	10.0367
2018.87	10.4634
2021.81	9.81895
2024.75	9.63006
2027.69	8.93163
2030.62	7.16326
2033.56	6.63529
2036.49	5.70632
2039.42	7.37672
2042.35	7.74893
2045.28	7.59257
2048.21	6.70214
2051.14	6.31326
2054.06	5.37111
2056.99	5.2642
2059.92	5.64817
2062.84	5.89272
2065.76	6.73887
2068.68	6.51058
2071.6	6.26219
2074.52	5.40596
2077.44	5.82616
2080.36	6.15591
2083.27	7.64675
2086.19	8.88374
2089.1	10.3317
2092.01	9.97712
2094.93	10.0545
2097.84	10.6109
2100.75	10.3477
2103.66	10.5382
2106.56	12.5959
2109.47	14.0933
2112.37	15.2307
2115.28	16.5101
2118.18	16.431
2121.09	16.7757
2123.99	17.5036
2126.89	18.2929
2129.79	19.5331
2132.68	20.2494
2135.58	21.1107
2138.48	21.6613
2141.37	21.732
2144.26	22.9985
2147.16	24.4923
2150.05	25.3845
2152.94	27.2595
2155.83	29.8413
2158.72	31.4681
2161.6	33.6422
2164.49	34.4463
2167.38	35.8994
2170.26	38.2191
2173.14	39.5596
2176.03	41.0995
2178.91	42.2408
2181.79	42.6839
2184.67	43.3574
2187.54	42.8206
2190.42	41.9276
2193.3	40.89
2196.17	39.0574
2199.05	36.7106
2201.92	35.1082
2204.79	33.1643
2207.66	30.6895
2210.53	28.9779
2213.4	26.5819
2216.27	24.5699
2219.13	22.557
2222	20.4257
2224.86	19.4702
2227.72	17.7826
2230.59	16.2913
2233.45	14.1473
2236.31	12.0482
2239.17	10.8226
2242.03	10.1738
2244.88	7.50634
2247.74	7.32145
2250.59	7.35449
2253.45	7.49212
2256.3	6.9506
2259.15	6.24437
2262	5.5846
2264.85	4.39766
2267.7	4.9459
2270.55	6.49216
2273.4	6.77016
2276.24	7.60525
2279.09	7.98737
2281.93	8.51211
2284.77	8.48758
2287.61	9.59935
2290.46	8.80681
2293.29	7.63473
2296.13	6.79296
2298.97	6.92692
2301.81	7.22145
2304.64	7.0198
2307.48	7.27631
2310.31	7.91494
2313.14	8.70386
2315.97	8.67996
2318.8	9.6825
2321.63	10.1841
2324.46	8.84574
2327.29	8.08304
2330.12	7.07361
2332.94	5.9367
2335.76	5.99925
2338.59	6.25459
2341.41	5.62759
2344.23	5.67151
2347.05	5.35448
2349.87	4.17207
2352.69	2.97763
2355.5	2.43756
2358.32	1.01356
2361.14	-1.1982
2363.95	-0.443381
2366.76	0.148533
2369.58	0.396335
2372.39	1.06721
2375.2	3.05652
2378	3.75226
2380.81	3.94596
2383.62	4.88604
2386.42	4.45264
2389.23	5.25761
2392.03	5.45863
2394.84	4.1914
2397.64	4.49511
2400.44	4.56172
2403.24	4.40095
2406.04	4.35141
2408.83	5.22937
2411.63	5.5149
2414.43	6.64451
2417.22	6.30631
2420.02	6.51549
2422.81	5.44002
2425.6	5.78025
2428.39	4.92048
2431.18	6.19168
2433.97	4.9518
2436.76	4.81964
2439.54	5.25818
2442.33	5.49603
2445.11	6.54523
2447.9	5.40997
2450.68	3.38326
2453.46	4.33561
2456.24	3.46568
2459.02	5.64909
2461.8	3.02361
2464.58	3.26688
2467.36	4.02619
2470.13	4.07194
2472.91	2.90652
2475.68	3.70436
2478.45	4.22481
2481.22	5.53806
2484	6.49641
2486.77	6.13163
2489.54	6.7313
2492.3	6.71916
2495.07	8.04389
2497.84	8.37213
2500.6	9.09108
2503.36	8.83086
2506.13	8.10007
2508.89	8.28943
2511.65	7.03888
2514.41	6.30402
2517.17	3.69152
2519.93	4.28825
2522.68	4.40546
2525.44	4.30051
2528.19	3.30534
2530.95	2.62381
2533.7	1.89831
2536.45	1.07448
2539.2	1.15026
2541.95	0.701336
2544.7	0.964133
2547.45	2.06375
2550.2	2.25835
2552.94	3.68969
2555.69	3.34114
2558.43	3.73858
2561.17	5.28849
2563.92	7.07556
2566.66	6.56679
2569.4	6.08633
2572.14	6.97235
2574.88	7.04393
2577.61	6.88483
2580.35	6.29853
2583.09	6.34184
2585.82	6.426
2588.55	7.38695
2591.28	8.49783
2594.02	8.58645
2596.75	8.74215
2599.48	8.72951
2602.2	8.61749
2604.93	9.11661
2607.66	9.3203
2610.38	8.73373
2613.11	10.7971
2615.83	11.7414
2618.56	10.9654
2621.28	11.3087
2624	10.6695
2626.72	11.0758
2629.44	12.2023
2632.15	11.7293
2634.87	10.897
2637.59	11.2279
2640.3	10.6841
2643.02	9.31703
2645.73	9.50543
2648.44	9.17263
2651.15	9.75809
2653.86	9.52805
2656.57	9.45084
2659.28	9.60278
2661.99	9.19142
2664.69	9.79045
2667.4	9.44918
2670.1	9.17924
2672.81	9.74278
2675.51	8.74925
2678.21	9.59599
2680.91	9.50205
2683.61	8.20878
2686.31	7.45952
2689	7.86062
2691.7	8.36746
2694.4	8.3233
2697.09	9.36623
2699.79	9.08489
2702.48	8.47487
2705.17	8.32403
2707.86	8.49831
2710.55	8.34271
2713.24	9.20112
2715.93	9.76458
2718.61	11.879
2721.3	12.9684
2723.99	13.845
2726.67	14.2179
2729.35	13.6765
2732.04	14.1818
2734.72	13.5031
2737.4	13.1815
2740.08	13.0883
2742.76	12.6298
2745.43	12.1689
2748.11	11.2359
2750.79	10.4576
2753.46	10.609
2756.13	9.87477
2758.81	10.062
2761.48	9.36725
2764.15	8.81668
2766.82	6.2493
2769.49	5.32695
2772.16	4.66062
2774.82	3.54643
2777.49	3.26485
2780.16	3.00868
2782.82	2.99199
2785.48	3.92929
2788.15	3.30065
2790.81	1.71505
2793.47	2.19806
2796.13	2.35823
2798.79	2.20769
2801.44	2.10301
2804.1	2.69292
2806.76	3.05191
2809.41	2.58704
2812.07	2.49082
2814.72	3.72187
2817.37	4.37395
2820.02	6.34531
2822.67	9.28337
2825.32	12.2777
2827.97	15.4172
2830.62	20.3877
2833.26	25.3535
2835.91	31.4512
2838.55	37.7738
2841.2	46.3826
2843.84	58.6055
2846.48	71.1032
2849.12	85.0584
2851.76	99.1441
2854.4	113.778
2857.04	128.897
2859.68	144.589
2862.32	158.112
2864.95	170.376
2867.58	180.742
2870.22	190.78
2872.85	199.335
2875.48	206.733
2878.11	215.218
2880.74	221.273
2883.37	227.842
2886	233.261
2888.63	237.544
2891.25	243.997
2893.88	250.601
2896.5	257.602
2899.13	265.396
2901.75	274.63
2904.37	287.564
2906.99	300.389
2909.61	316.936
2912.23	333.307
2914.85	349.612
2917.46	366.458
2920.08	381.232
2922.7	394
2925.31	402.902
2927.92	407.613
2930.53	408.914
2933.15	407.104
2935.76	403.832
2938.37	397.789
2940.98	389.645
2943.58	378.891
2946.19	366.168
2948.8	350.587
2951.4	335.163
2954.01	321.212
2956.61	306.817
2959.21	290.561
2961.81	275.726
2964.41	260.357
2967.01	246.932
2969.61	234.106
2972.21	221.784
2974.81	209.168
2977.4	196.389
2980	184.374
2982.59	171.978
2985.18	158.272
2987.78	142.746
2990.37	129.16
2992.96	113.484
2995.55	98.9941
2998.14	86.2479
3000.72	72.575
3003.31	60.644
3005.9	50.8425
3008.48	41.931
3011.07	33.5871
3013.65	26.6122
3016.23	20.0448
3018.81	15.3129
3021.39	11.4807
3023.97	8.70773
3026.55	6.66036
3029.13	4.55038
3031.71	3.1703
3034.28	1.63436
3036.86	1.94846
3039.43	2.40092
3042.01	4.36646
3044.58	5.57569
3047.15	8.52142
3049.72	10.0904
3052.29	10.6446
3054.86	11.847
3057.43	12.4813
3060	11.9916
3062.56	12.4394
3065.13	12.0756
3067.69	12.8875
3070.25	13.2109
3072.82	12.5585
3075.38	10.1887
3077.94	7.70657
3080.5	6.12709
3083.06	4.72972
3085.62	3.80596
3088.17	2.26512
3090.73	1.27294
3093.29	1.60268
3095.84	2.72512
3098.4	4.29384
3100.95	5.19097
3103.5	7.56227
3106.05	9.17867
3108.6	10.9122
3111.15	12.6858
3113.7	14.126
3116.25	16.8161
3118.79	19.1405
3121.34	21.2007
3123.88	24.3865
3126.43	26.4358
3128.97	28.9433
3131.51	32.5136
3134.05	34.3944
3136.59	35.6433
3139.14	37.1565
3141.67	39.5889
3144.21	42.8598
3146.75	46.2479
3149.28	49.7169