File: data/Raman/poly_smoothed/Mb_10_14_11_1x_45s_532 nm_x100_100%_600 gr_mm_01.txt
#Acq. time (s)=	45
#Accumulations=	2
#Range (cm-¹)=	200...3150
#Windows=	2
#Auto scanning=	Off
#Autofocus=	Off
#Macrospot=	Off
#AutoExposure=	Off
#Spike filter=	Multiple accum.
#Delay time (s)=	0
#Binning=	1
#Readout mode=	Signal
#DeNoise=	Off
#ICS correction=	On
#Dark correction=	Off
#Inst. Process=	Off
#Detector Gain=	Best Dynamic Range
#Detector ADC=	20 kHz
#Detector temperature (°C)=	-69.85
#Instrument=	LabRAM HR Evol
#Detector=	Synapse
#Objective=	x100
#Grating=	600 gr/mm
#ND Filter=	100%
#Laser (nm)=	532
#Hole=	100.021
#Range=	Auto
#Laser Pol.=	No
#Raman. Pol.=	No
#Laser Pol. (°)=	-0.0007625
#Raman Pol. (°)=	89.9995
#Collection=	Microscope
#StageXY=	Marzhauser
#StageZ=	Marzhauser
#X (µm)=	-644.1
#Y (µm)=	-1586.9
#Z (µm)=	89.1
#Full time(mm:ss)=	3:10
#Project=
#Sample=
#Site=
#Title=	Mb_10_14_11_2x_45s_532 nm_x100_100%_600 gr_mm
#Remark=
#Date=	11.07.2022 09:21
#Acquired=	11.07.2022 09:21:14
#Edit:Spike=	11.07.2022 09:59:32
#Edit:Spike=	11.07.2022 09:59:33
#Base:Fit=	10.08.2022 10:21:11
#Base:Sub=	10.08.2022 10:21:41
#Filter:Polynom=	16.08.2022 10:17:53
#AxisType[0]=Intens
#AxisUnit[0]=Cnt
#AxisType[1]=Spectr
#AxisUnit[1]=1/cm
200.388	12.027
204.019	8.84971
207.646	7.15878
211.274	4.20649
214.899	2.8812
218.524	3.51372
222.146	5.88893
225.766	9.45788
229.388	11.2344
233.005	14.1888
236.621	17.4565
240.236	21.4983
243.852	25.1613
247.464	27.5419
251.074	31.1869
254.683	32.8135
258.291	33.9566
261.897	35.8362
265.504	38.3754
269.108	40.1152
272.71	40.3922
276.311	40.8594
279.91	40.0152
283.508	37.6888
287.105	36.5622
290.698	35.0387
294.291	33.3161
297.884	31.8175
301.475	32.2511
305.064	32.9464
308.652	32.5086
312.237	33.6335
315.822	32.4859
319.406	33.2224
322.987	35.8755
326.568	36.979
330.148	36.9929
333.724	37.0392
337.301	37.4146
340.875	38.6074
344.449	37.6894
348.02	38.2404
351.592	39.9176
355.16	42.4233
358.728	44.0026
362.294	44.8597
365.858	46.4188
369.422	46.352
372.983	48.0752
376.543	48.0971
380.102	48.6504
383.661	49.7735
387.216	50.0903
390.771	50.131
394.324	48.7189
397.875	48.2925
401.425	47.6276
404.974	46.1113
408.524	45.4777
412.07	43.7031
415.614	40.428
419.156	37.1798
422.698	34.5524
426.238	31.0996
429.777	28.0263
433.315	23.9268
436.852	20.2643
440.387	18.2783
443.919	16.3658
447.451	13.4436
450.982	12.5796
454.512	11.5217
458.038	13.023
461.565	13.1607
465.091	13.1369
468.613	14.513
472.136	15.3331
475.655	16.8416
479.176	16.3095
482.692	16.9273
486.21	20.1341
489.724	21.0895
493.237	22.896
496.75	24.7079
500.26	23.7923
503.769	24.1555
507.279	25.0188
510.785	24.3
514.289	24.2184
517.793	23.5334
521.297	22.8282
524.797	24.284
528.297	23.8236
531.795	23.0122
535.291	23.0337
538.787	23.5333
542.281	23.3442
545.773	20.2008
549.264	17.9625
552.754	15.6147
556.243	14.7728
559.73	12.5979
563.216	10.4918
566.701	7.87213
570.182	5.81519
573.664	4.67283
577.145	2.63155
580.624	1.90211
584.1	0.645999
587.577	0.162983
591.052	-0.199027
594.524	0.0404801
597.997	-0.985513
601.466	0.100431
604.936	1.1534
608.403	2.05853
611.87	2.74813
615.334	3.45978
618.799	4.17013
622.26	4.96418
625.72	6.18837
629.181	5.56723
632.638	5.02094
636.095	5.93621
639.551	7.03522
643.005	7.54958
646.457	8.09825
649.908	8.092
653.357	7.69053
656.806	7.23655
660.253	6.41001
663.7	5.97803
667.145	5.56573
670.588	4.79136
674.027	4.46662
677.468	4.04545
680.907	5.2384
684.345	5.88178
687.781	7.97532
691.216	8.20456
694.65	9.51111
698.081	12.241
701.512	12.3932
704.942	13.5587
708.371	15.941
711.796	17.3035
715.222	17.9916
718.645	19.8054
722.068	20.2886
725.49	22.2234
728.909	23.8318
732.329	24.5357
735.745	25.3075
739.16	25.8087
742.576	28.3032
745.988	29.9398
749.401	29.5695
752.811	31.3177
756.22	33.7367
759.627	36.0759
763.035	39.4288
766.44	42.159
769.843	45.0578
773.245	47.487
776.646	49.6881
780.046	52.543
783.444	54.5958
786.841	56.4946
790.237	59.1866
793.631	58.8145
797.024	61.0098
800.416	61.0925
803.807	61.707
807.196	61.9646
810.584	62.4905
813.971	61.2944
817.354	62.1545
820.739	63.2493
824.122	64.3404
827.503	65.3632
830.882	64.7953
834.261	64.7155
837.637	64.3479
841.013	64.6925
844.389	64.0634
847.761	62.7671
851.131	62.0565
854.503	59.6568
857.871	56.8577
861.24	54.081
864.606	52.0679
867.97	49.3643
871.336	46.666
874.698	43.7684
878.058	41.3176
881.418	39.6584
884.778	36.8136
888.135	34.9424
891.49	33.4246
894.845	33.65
898.198	33.8447
901.55	34.8785
904.901	36.3321
908.25	37.2798
911.598	37.9828
914.945	37.299
918.291	36.7661
921.635	36.6977
924.978	36.3945
928.318	36.2089
931.659	34.7681
934.998	33.1519
938.336	31.2277
941.671	29.8477
945.007	29.5535
948.339	28.8172
951.672	29.9478
955.004	28.1411
958.333	26.2165
961.662	25.3084
964.989	26.1595
968.315	25.8634
971.639	27.5895
974.962	28.5993
978.285	29.6803
981.605	31.4913
984.924	30.3939
988.243	31.5723
991.56	30.7505
994.875	30.5791
998.188	29.5618
1001.5	29.3517
1004.81	28.8082
1008.12	27.8116
1011.43	26.7533
1014.74	25.5304
1018.05	26.7848
1021.35	27.596
1024.65	28.9171
1027.96	30.3366
1031.26	31.5325
1034.56	31.2374
1037.86	30.7205
1041.16	30.8865
1044.45	30.4688
1047.75	30.9216
1051.04	30.0096
1054.33	31.0745
1057.62	30.5464
1060.91	28.7385
1064.2	27.3707
1067.49	26.4628
1070.77	25.9851
1074.06	24.9257
1077.34	24.1311
1080.62	22.3881
1083.91	21.6205
1087.18	20.4512
1090.46	20.125
1093.74	20.4314
1097.02	20.1649
1100.29	21.23
1103.56	22.003
1106.84	21.8782
1110.11	22.5795
1113.38	22.1608
1116.64	19.9573
1119.91	18.1415
1123.18	14.9577
1126.44	13.1433
1129.7	12.8404
1132.97	12.7375
1136.23	11.7961
1139.49	10.5275
1142.74	10.412
1146	11.1657
1149.26	11.8094
1152.51	11.1437
1155.76	11.6701
1159.01	9.61879
1162.27	9.40232
1165.51	8.64454
1168.76	8.49432
1172.01	9.07326
1175.25	8.85141
1178.5	9.65888
1181.74	11.1941
1184.98	11.4995
1188.22	12.2422
1191.46	12.5131
1194.7	13.1357
1197.94	13.1378
1201.17	13.963
1204.41	16.8569
1207.64	18.8833
1210.87	22.074
1214.1	24.646
1217.33	27.9858
1220.56	31.5316
1223.79	34.7699
1227.01	36.4851
1230.23	39.3361
1233.46	41.1244
1236.68	43.1093
1239.9	42.7765
1243.12	44.0594
1246.34	46.0131
1249.55	46.8096
1252.77	46.5909
1255.98	46.8613
1259.2	46.3448
1262.41	46.0739
1265.62	45.026
1268.83	45.7762
1272.03	45.6944
1275.24	45.603
1278.45	46.548
1281.65	48.7078
1284.85	50.2352
1288.06	50.3485
1291.26	52.9183
1294.46	55.0554
1297.66	56.602
1300.85	57.7415
1304.05	58.5731
1307.24	59.5609
1310.43	59.8108
1313.63	60.3031
1316.82	61.1424
1320.01	61.286
1323.2	61.482
1326.38	62.1113
1329.57	60.3047
1332.76	59.2941
1335.94	57.5579
1339.12	56.2277
1342.3	55.1849
1345.48	54.0385
1348.66	52.8553
1351.84	51.9701
1355.01	50.0111
1358.19	49.6632
1361.36	48.7644
1364.53	47.2847
1367.71	45.3006
1370.88	45.9758
1374.04	45.3247
1377.21	43.6183
1380.38	41.6382
1383.54	39.7649
1386.71	39.4075
1389.87	40.1528
1393.03	38.5044
1396.19	38.7751
1399.35	38.3583
1402.51	37.8582
1405.67	37.3829
1408.82	37.9518
1411.98	39.2394
1415.13	41.4044
1418.28	44.996
1421.43	47.3873
1424.58	50.0182
1427.73	54.4857
1430.88	59.173
1434.02	62.8016
1437.17	66.3163
1440.31	69.8761
1443.45	72.6418
1446.6	75.2148
1449.74	77.0246
1452.87	78.5095
1456.01	77.9505
1459.15	75.6356
1462.28	72.4404
1465.42	69.8046
1468.55	66.6818
1471.68	62.496
1474.81	58.82
1477.94	53.8328
1481.07	49.1116
1484.2	44.5263
1487.32	40.4744
1490.45	36.4867
1493.57	34.452
1496.69	31.7
1499.81	29.5019
1502.93	28.5827
1506.05	26.8599
1509.17	24.9271
1512.28	22.9002
1515.4	21.9795
1518.51	21.668
1521.63	21.6888
1524.74	21.3302
1527.85	21.6295
1530.96	20.5526
1534.06	20.4166
1537.17	20.3314
1540.28	20.6064
1543.38	21.6229
1546.48	21.4399
1549.59	22.065
1552.69	22.2232
1555.79	22.1188
1558.88	23.0036
1561.98	24.5726
1565.08	26.4069
1568.17	27.5186
1571.27	29.169
1574.36	29.9043
1577.45	32.6101
1580.54	34.01
1583.63	36.029
1586.72	38.438
1589.8	40.1981
1592.89	42.3188
1595.97	45.2558
1599.06	46.9448
1602.14	47.6605
1605.22	48.7158
1608.3	49.1021
1611.38	48.4098
1614.46	47.3218
1617.53	46.4206
1620.61	45.0378
1623.68	44.6468
1626.75	43.9044
1629.82	43.6148
1632.9	43.6489
1635.96	45.2544
1639.03	44.7239
1642.1	42.072
1645.16	42.0122
1648.23	42.3354
1651.29	43.4026
1654.36	44.3326
1657.42	43.9036
1660.48	45.373
1663.53	46.1935
1666.59	45.7044
1669.65	45.6831
1672.7	45.6544
1675.76	42.8047
1678.81	41.153
1681.86	38.3352
1684.91	35.071
1687.96	31.3435
1691.01	28.3165
1694.06	25.5396
1697.11	21.7553
1700.15	17.8663
1703.2	16.4284
1706.24	14.2749
1709.28	10.629
1712.32	7.76316
1715.36	4.19786
1718.4	2.7799
1721.43	1.91073
1724.47	2.01555
1727.5	1.73119
1730.54	1.90645
1733.57	1.60567
1736.6	2.08283
1739.63	2.45404
1742.66	2.17014
1745.69	2.5708
1748.72	2.57179
1751.74	1.87576
1754.77	1.82182
1757.79	0.279298
1760.81	0.272829
1763.83	1.2034
1766.85	1.11439
1769.87	1.07668
1772.89	1.07275
1775.91	1.67748
1778.92	2.92701
1781.94	2.47785
1784.95	2.79501
1787.96	2.52965
1790.97	3.35292
1793.98	3.93215
1796.99	4.58453
1800	5.10299
1803	5.03051
1806.01	3.74038
1809.01	3.16271
1812.02	3.66069
1815.02	2.74657
1818.02	1.8166
1821.02	1.67779
1824.02	0.79244
1827.01	0.0535427
1830.01	-0.343236
1833	-0.169168
1836	0.114886
1838.99	0.447977
1841.98	0.34652
1844.97	0.839121
1847.96	1.51045
1850.95	1.56328
1853.94	1.98497
1856.92	1.73385
1859.91	1.87681
1862.89	2.78448
1865.88	3.45073
1868.86	3.32414
1871.84	4.84302
1874.82	5.41015
1877.8	6.28438
1880.77	6.49915
1882.52	7.45881
1885.51	7.26749
1888.5	6.90695
1891.49	7.07983
1894.47	7.34534
1897.46	7.04839
1900.44	6.96638
1903.42	5.87238
1906.4	5.19982
1909.38	5.52679
1912.36	6.50304
1915.34	6.33142
1918.32	6.43921
1921.29	5.05788
1924.27	4.70071
1927.24	4.04558
1930.21	3.90699
1933.18	4.13757
1936.15	4.2792
1939.12	4.76055
1942.09	5.06845
1945.06	5.69929
1948.02	5.63978
1950.99	5.0637
1953.95	4.87257
1956.91	4.76965
1959.87	3.47241
1962.84	3.22915
1965.79	3.09845
1968.75	2.33301
1971.71	2.22626
1974.66	1.8946
1977.62	1.4583
1980.57	1.66897
1983.53	2.35948
1986.48	3.09453
1989.43	2.46845
1992.38	2.42207
1995.33	3.07867
1998.27	3.24549
2001.22	2.98097
2004.16	2.89771
2007.11	3.02836
2010.05	2.63655
2012.99	2.54972
2015.93	2.31908
2018.87	2.4127
2021.81	2.37265
2024.75	2.94007
2027.69	2.57733
2030.62	2.91651
2033.56	2.84424
2036.49	3.05111
2039.42	3.6036
2042.35	3.40645
2045.28	4.15298
2048.21	5.04543
2051.14	5.42587
2054.06	5.53555
2056.99	6.55306
2059.92	7.47011
2062.84	8.59219
2065.76	8.90174
2068.68	8.45488
2071.6	8.8862
2074.52	8.62792
2077.44	7.10389
2080.36	7.65781
2083.27	7.36213
2086.19	7.45277
2089.1	7.86986
2092.01	8.02559
2094.93	7.80335
2097.84	8.98185
2100.75	8.47925
2103.66	9.73102
2106.56	9.34263
2109.47	9.87265
2112.37	10.5973
2115.28	11.6521
2118.18	11.6656
2121.09	11.8797
2123.99	12.159
2126.89	12.9126
2129.79	13.5477
2132.68	14.3949
2135.58	15.3713
2138.48	15.7765
2141.37	16.9196
2144.26	18.4957
2147.16	19.4947
2150.05	21.1806
2152.94	23.0194
2155.83	22.7499
2158.72	25.0197
2161.6	25.6488
2164.49	26.654
2167.38	27.4474
2170.26	27.7266
2173.14	28.8497
2176.03	29.4631
2178.91	30.2467
2181.79	30.3755
2184.67	29.3831
2187.54	28.2711
2190.42	27.029
2193.3	25.4922
2196.17	26.0004
2199.05	24.2527
2201.92	22.7624
2204.79	21.7692
2207.66	20.6057
2210.53	18.8948
2213.4	17.8446
2216.27	16.7136
2219.13	16.1558
2222	15.2766
2224.86	14.436
2227.72	13.6323
2230.59	12.8753
2233.45	12.0047
2236.31	11.2265
2239.17	10.865
2242.03	11.009
2244.88	11.6655
2247.74	11.4791
2250.59	10.165
2253.45	10.005
2256.3	9.54565
2259.15	9.24899
2262	8.16066
2264.85	8.16168
2267.7	8.20263
2270.55	6.41537
2273.4	7.0307
2276.24	7.73613
2279.09	7.09316
2281.93	6.33777
2284.77	7.62865
2287.61	7.76573
2290.46	7.98527
2293.29	7.19997
2296.13	7.9841
2298.97	8.69426
2301.81	9.51825
2304.64	9.46461
2307.48	10.3012
2310.31	10.361
2313.14	11.0599
2315.97	10.8704
2318.8	10.5067
2321.63	9.74895
2324.46	9.27385
2327.29	8.04241
2330.12	7.22305
2332.94	7.11254
2335.76	6.48987
2338.59	6.92834
2341.41	6.49933
2344.23	6.0333
2347.05	5.23171
2349.87	4.03473
2352.69	3.73541
2355.5	3.82152
2358.32	4.41823
2361.14	4.42848
2363.95	5.43869
2366.76	6.11809
2369.58	6.02688
2372.39	5.75471
2375.2	5.5607
2378	6.63502
2380.81	7.1296
2383.62	6.65048
2386.42	6.89702
2389.23	5.91224
2392.03	4.91115
2394.84	4.71033
2397.64	4.97535
2400.44	4.84529
2403.24	3.89715
2406.04	2.71772
2408.83	1.76064
2411.63	0.859141
2414.43	0.940091
2417.22	1.49657
2420.02	2.7214
2422.81	3.11264
2425.6	2.71308
2428.39	2.70223
2431.18	1.9929
2433.97	1.81834
2436.76	2.00766
2439.54	1.4195
2442.33	1.61111
2445.11	2.70443
2447.9	3.00955
2450.68	2.89491
2453.46	2.62525
2456.24	2.67136
2459.02	3.38866
2461.8	3.85194
2464.58	4.29324
2467.36	3.75624
2470.13	3.36352
2472.91	2.98527
2475.68	3.11728
2478.45	3.98056
2481.22	4.22523
2484	5.15077
2486.77	5.18786
2489.54	4.42581
2492.3	4.09302
2495.07	4.23353
2497.84	4.28501
2500.6	4.44003
2503.36	3.3344
2506.13	3.24005
2508.89	2.1985
2511.65	2.83102
2514.41	2.95229
2517.17	2.33765
2519.93	2.26257
2522.68	2.91638
2525.44	2.50651
2528.19	3.14017
2530.95	3.4875
2533.7	3.35566
2536.45	3.33728
2539.2	3.2158
2541.95	4.30487
2544.7	4.82674
2547.45	4.24918
2550.2	4.66146
2552.94	5.33463
2555.69	6.17381
2558.43	6.96014
2561.17	6.4908
2563.92	6.56646
2566.66	6.47696
2569.4	5.57638
2572.14	4.48319
2574.88	5.1705
2577.61	4.98705
2580.35	5.40798
2583.09	4.80982
2585.82	4.17277
2588.55	5.02098
2591.28	5.65168
2594.02	4.63881
2596.75	4.70985
2599.48	3.90371
2602.2	3.25309
2604.93	3.19052
2607.66	4.62938
2610.38	4.57749
2613.11	4.33747
2615.83	4.02206
2618.56	4.67555
2621.28	5.30101
2624	5.00775
2626.72	5.07976
2629.44	4.77526
2632.15	4.86588
2634.87	5.59774
2637.59	5.92402
2640.3	6.36752
2643.02	7.15617
2645.73	7.4377
2648.44	7.04702
2651.15	7.33505
2653.86	7.82108
2656.57	8.41732
2659.28	7.88694
2661.99	6.59018
2664.69	6.68163
2667.4	5.62215
2670.1	5.20051
2672.81	5.23596
2675.51	4.90557
2678.21	5.02717
2680.91	4.41233
2683.61	4.22081
2686.31	4.53911
2689	3.28388
2691.7	4.00449
2694.4	4.63478
2697.09	4.89176
2699.79	5.53621
2702.48	5.81388
2705.17	5.99173
2707.86	5.49374
2710.55	5.44692
2713.24	5.79666
2715.93	6.17895
2718.61	6.26457
2721.3	7.23946
2723.99	7.21632
2726.67	7.2575
2729.35	6.23383
2732.04	5.5332
2734.72	5.3384
2737.4	5.85585
2740.08	5.41461
2742.76	6.19602
2745.43	6.73696
2748.11	5.3285
2750.79	5.44787
2753.46	5.26123
2756.13	5.71403
2758.81	6.09184
2761.48	4.95206
2764.15	3.86125
2766.82	3.16364
2769.49	3.10039
2772.16	1.8583
2774.82	1.26466
2777.49	0.880119
2780.16	0.624928
2782.82	-0.324883
2785.48	-0.104446
2788.15	0.707951
2790.81	0.757209
2793.47	0.182873
2796.13	0.719078
2798.79	1.31153
2801.44	1.65849
2804.1	1.33046
2806.76	2.29244
2809.41	2.85724
2812.07	2.54664
2814.72	3.65214
2817.37	5.28327
2820.02	6.16151
2822.67	8.07484
2825.32	9.24893
2827.97	11.7437
2830.62	14.125
2833.26	16.7111
2835.91	19.0337
2838.55	22.3031
2841.2	26.916
2843.84	32.5716
2846.48	38.8919
2849.12	46.3406
2851.76	53.2262
2854.4	60.1048
2857.04	65.7214
2859.68	72.7969
2862.32	80.1526
2864.95	85.7897
2867.58	90.6423
2870.22	96.2579
2872.85	101.622
2875.48	105.932
2878.11	109.842
2880.74	112.216
2883.37	115.335
2886	117.514
2888.63	119.969
2891.25	122.486
2893.88	124.663
2896.5	127.171
2899.13	131.209
2901.75	135.9
2904.37	141.919
2906.99	149.195
2909.61	157.628
2912.23	166.341
2914.85	172.994
2917.46	178.325
2920.08	185.106
2922.7	190.185
2925.31	195.475
2927.92	198.01
2930.53	198.949
2933.15	198.902
2935.76	197.283
2938.37	194.433
2940.98	189.489
2943.58	182.897
2946.19	177.076
2948.8	169.707
2951.4	163.31
2954.01	155.974
2956.61	148.527
2959.21	140.831
2961.81	134.29
2964.41	127.252
2967.01	121.918
2969.61	116.404
2972.21	112.032
2974.81	106.49
2977.4	100.462
2980	93.3223
2982.59	87.1787
2985.18	80.1551
2987.78	73.1774
2990.37	66.1209
2992.96	59.9245
2995.55	53.1003
2998.14	45.349
3000.72	39.5495
3003.31	33.9713
3005.9	29.7213
3008.48	25.975
3011.07	22.3739
3013.65	18.9786
3016.23	16.7154
3018.81	13.3495
3021.39	11.4215
3023.97	9.88613
3026.55	8.12863
3029.13	7.42811
3031.71	8.04352
3034.28	7.94958
3036.86	8.0492
3039.43	7.69683
3042.01	7.40922
3044.58	6.91054
3047.15	7.07017
3049.72	7.27808
3052.29	8.11637
3054.86	8.19713
3057.43	8.43321
3060	6.78441
3062.56	6.21475
3065.13	7.0572
3067.69	7.3226
3070.25	7.17075
3072.82	6.98803
3075.38	5.83459
3077.94	6.39092
3080.5	6.22421
3083.06	5.95808
3085.62	5.27551
3088.17	4.8986
3090.73	5.93652
3093.29	6.88717
3095.84	6.64494
3098.4	7.64324
3100.95	8.26879
3103.5	8.70562
3106.05	9.18894
3108.6	10.6314
3111.15	11.9225
3113.7	12.5506
3116.25	13.5322
3118.79	13.3714
3121.34	13.0777
3123.88	12.8099
3126.43	14.3841
3128.97	15.946
3131.51	16.1943
3134.05	16.906
3136.59	17.8266
3139.14	18.1866
3141.67	18.715
3144.21	19.1592
3146.75	19.4304
3149.28	20.7643