File: data/Raman/poly_smoothed/Mb_10_14_21_1x_45s_532 nm_x100_100%_600 gr_mm_01.txt
#Acq. time (s)=	45
#Accumulations=	2
#Range (cm-¹)=	200...3150
#Windows=	2
#Auto scanning=	Off
#Autofocus=	Off
#Macrospot=	Off
#AutoExposure=	Off
#Spike filter=	Multiple accum.
#Delay time (s)=	0
#Binning=	1
#Readout mode=	Signal
#DeNoise=	Off
#ICS correction=	On
#Dark correction=	Off
#Inst. Process=	Off
#Detector Gain=	Best Dynamic Range
#Detector ADC=	20 kHz
#Detector temperature (°C)=	-69.85
#Instrument=	LabRAM HR Evol
#Detector=	Synapse
#Objective=	x100
#Grating=	600 gr/mm
#ND Filter=	100%
#Laser (nm)=	532
#Hole=	100.021
#Range=	Auto
#Laser Pol.=	No
#Raman. Pol.=	No
#Laser Pol. (°)=	-0.0007625
#Raman Pol. (°)=	89.9995
#Collection=	Microscope
#StageXY=	Marzhauser
#StageZ=	Marzhauser
#X (µm)=	-621.2
#Y (µm)=	-1586.7
#Z (µm)=	89.85
#Full time(mm:ss)=	3:18
#Project=
#Sample=
#Site=
#Title=	Mb_10_14_21_2x_45s_532 nm_x100_100%_600 gr_mm
#Remark=
#Date=	11.07.2022 10:08
#Acquired=	11.07.2022 10:08:01
#Base:Fit=	10.08.2022 10:21:11
#Base:Sub=	10.08.2022 10:21:41
#Filter:Polynom=	16.08.2022 10:17:53
#AxisType[0]=Intens
#AxisUnit[0]=Cnt
#AxisType[1]=Spectr
#AxisUnit[1]=1/cm
200.388	41.5527
204.019	33.515
207.646	24.5985
211.274	17.7915
214.899	14.6818
218.524	15.2888
222.146	15.7374
225.766	16.4739
229.388	16.9875
233.005	17.8904
236.621	19.2053
240.236	19.5079
243.852	20.0966
247.464	21.3182
251.074	22.9614
254.683	23.3361
258.291	23.8096
261.897	22.8268
265.504	20.8351
269.108	21.3843
272.71	21.1211
276.311	19.1367
279.91	16.6532
283.508	12.7439
287.105	8.61871
290.698	5.45579
294.291	5.63075
297.884	5.02871
301.475	6.33009
305.064	8.12587
308.652	8.24527
312.237	6.5978
315.822	6.22627
319.406	5.36198
322.987	6.36386
326.568	7.29206
330.148	8.13092
333.724	10.0936
337.301	9.66964
340.875	8.5246
344.449	8.49921
348.02	8.2255
351.592	9.34454
355.16	10.3012
358.728	10.4054
362.294	12.0744
365.858	11.7804
369.422	12.3647
372.983	15.5957
376.543	16.5877
380.102	19.3658
383.661	21.1896
387.216	22.3401
390.771	23.8682
394.324	23.5585
397.875	23.2237
401.425	22.6036
404.974	23.161
408.524	22.9351
412.07	23.2008
415.614	22.1207
419.156	20.3636
422.698	17.8984
426.238	15.8789
429.777	14.2945
433.315	12.4103
436.852	9.28783
440.387	8.07342
443.919	7.00088
447.451	7.24568
450.982	7.3539
454.512	9.18434
458.038	10.1034
461.565	10.8817
465.091	12.3086
468.613	14.5205
472.136	15.9662
475.655	16.7636
479.176	16.968
482.692	20.1299
486.21	22.698
489.724	24.6094
493.237	26.2538
496.75	28.597
500.26	30.4029
503.769	32.1083
507.279	33.5292
510.785	33.5905
514.289	33.9821
517.793	34.6252
521.297	33.5206
524.797	33.2476
528.297	35.5671
531.795	34.3299
535.291	32.8535
538.787	30.6823
542.281	28.6362
545.773	26.1248
549.264	23.4056
552.754	21.9886
556.243	20.5797
559.73	16.1191
563.216	12.5595
566.701	11.9039
570.182	11.5643
573.664	7.8387
577.145	6.09079
580.624	5.24096
584.1	5.4922
587.577	4.17644
591.052	2.60973
594.524	2.88179
597.997	3.08495
601.466	4.18099
604.936	4.10313
608.403	4.5431
611.87	5.49122
615.334	5.85404
618.799	4.48941
622.26	4.58905
625.72	6.41357
629.181	8.56113
632.638	10.1078
636.095	10.8815
639.551	12.8012
643.005	14.3631
646.457	15.7967
649.908	16.7573
653.357	16.9531
656.806	17.3505
660.253	17.6239
663.7	18.3911
667.145	18.5122
670.588	18.5126
674.027	17.0815
677.468	17.3896
680.907	17.3692
684.345	17.1626
687.781	17.4585
691.216	17.9574
694.65	19.2825
698.081	20.2014
701.512	19.5074
704.942	20.9639
708.371	21.7211
711.796	23.6944
715.222	24.7551
718.645	25.6697
722.068	26.7537
725.49	27.6187
728.909	29.5155
732.329	31.0391
735.745	33.1613
739.16	34.2101
742.576	34.9279
745.988	36.9681
749.401	40.1054
752.811	41.0502
756.22	42.8858
759.627	43.7253
763.035	47.8436
766.44	50.8213
769.843	55.8294
773.245	58.4706
776.646	60.2601
780.046	62.6454
783.444	65.2604
786.841	66.9775
790.237	71.3418
793.631	73.467
797.024	74.2695
800.416	74.7911
803.807	77.5978
807.196	77.2324
810.584	77.883
813.971	78.787
817.354	77.9137
820.739	77.2887
824.122	77.4513
827.503	77.0251
830.882	76.5997
834.261	75.5129
837.637	71.1712
841.013	69.0728
844.389	67.0062
847.761	66.1173
851.131	63.0078
854.503	60.7495
857.871	57.5096
861.24	56.468
864.606	55.4542
867.97	53.8144
871.336	53.006
874.698	49.6056
878.058	48.9303
881.418	47.4344
884.778	46.7135
888.135	45.7946
891.49	45.21
894.845	44.7797
898.198	44.5971
901.55	44.5019
904.901	46.5276
908.25	45.5707
911.598	44.2549
914.945	44.8631
918.291	44.7971
921.635	44.7929
924.978	46.4037
928.318	47.6425
931.659	47.2488
934.998	49.361
938.336	49.6197
941.671	49.048
945.007	48.2397
948.339	49.0026
951.672	48.6644
955.004	48.6472
958.333	46.8994
961.662	47.3649
964.989	48.84
968.315	50.0613
971.639	51.9045
974.962	54.4604
978.285	55.4279
981.605	57.0175
984.924	56.521
988.243	54.137
991.56	54.2852
994.875	53.5034
998.188	53.7683
1001.5	52.9145
1004.81	52.1007
1008.12	50.6316
1011.43	50.7089
1014.74	50.7015
1018.05	50.9051
1021.35	51.6922
1024.65	51.3891
1027.96	51.4204
1031.26	50.4508
1034.56	48.4332
1037.86	47.3195
1041.16	45.9502
1044.45	46.1357
1047.75	46.3399
1051.04	44.9744
1054.33	43.3574
1057.62	40.8816
1060.91	38.3711
1064.2	35.2709
1067.49	31.432
1070.77	28.7372
1074.06	26.1567
1077.34	22.5367
1080.62	21.1738
1083.91	18.638
1087.18	16.7657
1090.46	17.5734
1093.74	18.3606
1097.02	18.2989
1100.29	18.5315
1103.56	18.6067
1106.84	18.6044
1110.11	18.8357
1113.38	18.399
1116.64	19.5447
1119.91	19.5946
1123.18	20.5658
1126.44	21.9129
1129.7	22.4251
1132.97	23.4271
1136.23	23.5427
1139.49	23.7244
1142.74	23.1739
1146	22.0453
1149.26	20.7123
1152.51	17.8731
1155.76	15.9458
1159.01	13.2468
1162.27	10.4945
1165.51	7.42501
1168.76	8.23951
1172.01	7.20831
1175.25	4.66833
1178.5	4.22293
1181.74	4.19636
1184.98	3.53047
1188.22	4.81474
1191.46	5.85414
1194.7	6.99186
1197.94	8.14097
1201.17	9.50029
1204.41	12.4586
1207.64	15.3912
1210.87	17.7597
1214.1	20.6435
1217.33	24.4094
1220.56	27.6833
1223.79	30.0813
1227.01	32.1337
1230.23	35.8979
1233.46	37.7673
1236.68	38.9495
1239.9	40.7228
1243.12	41.3235
1246.34	44.5329
1249.55	46.4456
1252.77	47.6438
1255.98	48.1954
1259.2	49.2293
1262.41	49.4344
1265.62	50.2236
1268.83	52.1036
1272.03	50.899
1275.24	50.9127
1278.45	51.492
1281.65	53.1204
1284.85	55.9666
1288.06	58.2247
1291.26	60.4707
1294.46	63.0221
1297.66	65.86
1300.85	66.7333
1304.05	67.5392
1307.24	69.7298
1310.43	70.0467
1313.63	69.7801
1316.82	71.0613
1320.01	70.915
1323.2	71.9841
1326.38	70.4825
1329.57	68.754
1332.76	67.5784
1335.94	64.2343
1339.12	62.1947
1342.3	59.8168
1345.48	57.2427
1348.66	56.0985
1351.84	53.1053
1355.01	52.785
1358.19	52.4229
1361.36	52.5187
1364.53	51.4487
1367.71	50.23
1370.88	47.2993
1374.04	46.5698
1377.21	44.2994
1380.38	42.8052
1383.54	42.9215
1386.71	43.9907
1389.87	42.3131
1393.03	43.1008
1396.19	43.773
1399.35	43.1592
1402.51	41.8245
1405.67	41.2212
1408.82	42.1065
1411.98	45.0339
1415.13	48.5935
1418.28	51.9007
1421.43	56.54
1424.58	61.2382
1427.73	67.9177
1430.88	74.3107
1434.02	79.516
1437.17	83.9319
1440.31	88.024
1443.45	89.9281
1446.6	89.8415
1449.74	90.3443
1452.87	90.2934
1456.01	88.026
1459.15	86.5211
1462.28	84.3476
1465.42	79.1429
1468.55	75.539
1471.68	70.3024
1474.81	65.7338
1477.94	59.1001
1481.07	55.6913
1484.2	51.6077
1487.32	46.9219
1490.45	43.9922
1493.57	40.2182
1496.69	36.5425
1499.81	34.0831
1502.93	31.8682
1506.05	29.3455
1509.17	27.0291
1512.28	25.3172
1515.4	23.8331
1518.51	22.8356
1521.63	21.5823
1524.74	20.0136
1527.85	20.4674
1530.96	20.3537
1534.06	20.6134
1537.17	21.1461
1540.28	21.5792
1543.38	23.0273
1546.48	24.8086
1549.59	25.9399
1552.69	26.8032
1555.79	29.178
1558.88	31.4029
1561.98	32.3651
1565.08	33.5552
1568.17	35.5931
1571.27	37.455
1574.36	39.6492
1577.45	40.9674
1580.54	42.1612
1583.63	44.5898
1586.72	47.8722
1589.8	51.5425
1592.89	52.3026
1595.97	52.9061
1599.06	53.3969
1602.14	54.4866
1605.22	55.5275
1608.3	55.3919
1611.38	55.6872
1614.46	54.4878
1617.53	54.8565
1620.61	54.7462
1623.68	55.5135
1626.75	55.6793
1629.82	57.9142
1632.9	60.3808
1635.96	61.7237
1639.03	66.1438
1642.1	68.9073
1645.16	71.3312
1648.23	73.4459
1651.29	75.8311
1654.36	77.1028
1657.42	77.4642
1660.48	78.1928
1663.53	75.9651
1666.59	72.8388
1669.65	68.5162
1672.7	65.9745
1675.76	62.1917
1678.81	57.2647
1681.86	50.8517
1684.91	43.8431
1687.96	38.813
1691.01	33.2976
1694.06	28.8908
1697.11	24.8123
1700.15	20.8968
1703.2	17.2942
1706.24	14.4613
1709.28	12.3059
1712.32	12.029
1715.36	10.0286
1718.4	8.06677
1721.43	7.70837
1724.47	7.97098
1727.5	7.61925
1730.54	6.13564
1733.57	5.48884
1736.6	4.67357
1739.63	4.2688
1742.66	3.56714
1745.69	3.76489
1748.72	4.34027
1751.74	2.96081
1754.77	2.10788
1757.79	1.24733
1760.81	1.76466
1763.83	2.10829
1766.85	2.11236
1769.87	1.61839
1772.89	0.750111
1775.91	0.685575
1778.92	1.15127
1781.94	1.60988
1784.95	1.90123
1787.96	2.43214
1790.97	2.60009
1793.98	2.25904
1796.99	3.32232
1800	2.23821
1803	0.749532
1806.01	-0.383485
1809.01	0.00166108
1812.02	0.743749
1815.02	0.364745
1818.02	1.06403
1821.02	2.86124
1824.02	2.9097
1827.01	3.28653
1830.01	3.89672
1833	3.90677
1836	4.2701
1838.99	3.90141
1841.98	3.75127
1844.97	3.45477
1847.96	3.47625
1850.95	3.70396
1853.94	4.40139
1856.92	4.54808
1859.91	5.34943
1862.89	5.85946
1865.88	3.76868
1868.86	4.03396
1871.84	3.79901
1874.82	3.11003
1877.8	3.91797
1880.77	4.28528
1882.52	4.91287
1885.51	5.71074
1888.5	5.86857
1891.49	6.01773
1894.47	7.02794
1897.46	6.4152
1900.44	6.2411
1903.42	6.14693
1906.4	5.79087
1909.38	5.91222
1912.36	5.21865
1915.34	5.57385
1918.32	3.94602
1921.29	4.96661
1924.27	5.3564
1927.24	5.10482
1930.21	4.83401
1933.18	3.67778
1936.15	3.11138
1939.12	2.77953
1942.09	4.0661
1945.06	4.04488
1948.02	3.53551
1950.99	3.11619
1953.95	2.66032
1956.91	1.7063
1959.87	1.53765
1962.84	0.323223
1965.79	0.81102
1968.75	1.39531
1971.71	1.11776
1974.66	1.78543
1977.62	1.81076
1980.57	1.70962
1983.53	1.90525
1986.48	2.43832
1989.43	3.23996
1992.38	3.41071
1995.33	5.57891
1998.27	6.21347
2001.22	5.78735
2004.16	5.87651
2007.11	5.64359
2010.05	5.7344
2012.99	7.22966
2015.93	6.50126
2018.87	5.44643
2021.81	4.91595
2024.75	5.52607
2027.69	4.86944
2030.62	3.87876
2033.56	3.72504
2036.49	3.2572
2039.42	4.35668
2042.35	3.96918
2045.28	3.65653
2048.21	3.60756
2051.14	4.48971
2054.06	5.223
2056.99	7.47256
2059.92	7.84482
2062.84	8.2703
2065.76	8.09848
2068.68	8.63082
2071.6	9.22303
2074.52	8.6925
2077.44	8.80236
2080.36	8.27257
2083.27	8.19917
2086.19	9.8908
2089.1	8.83221
2092.01	9.12672
2094.93	8.0009
2097.84	7.39736
2100.75	7.83396
2103.66	7.61347
2106.56	6.60489
2109.47	6.66412
2112.37	7.20879
2115.28	7.84839
2118.18	8.71943
2121.09	9.9725
2123.99	11.9644
2126.89	13.3045
2129.79	14.3396
2132.68	15.1082
2135.58	17.8475
2138.48	20.4158
2141.37	22.7749
2144.26	24.6197
2147.16	26.0104
2150.05	27.3746
2152.94	28.896
2155.83	30.7371
2158.72	31.9722
2161.6	31.3833
2164.49	32.7391
2167.38	32.9561
2170.26	33.4338
2173.14	32.6192
2176.03	30.8588
2178.91	30.2904
2181.79	30.4492
2184.67	29.259
2187.54	28.1249
2190.42	27.7091
2193.3	26.6163
2196.17	26.0405
2199.05	24.7926
2201.92	24.0843
2204.79	23.4622
2207.66	22.4071
2210.53	21.3696
2213.4	18.8579
2216.27	18.1408
2219.13	17.4931
2222	16.6099
2224.86	15.4032
2227.72	14.8486
2230.59	14.0896
2233.45	13.6481
2236.31	12.4535
2239.17	10.5637
2242.03	10.2435
2244.88	8.98363
2247.74	9.26541
2250.59	9.09382
2253.45	8.61854
2256.3	7.7856
2259.15	7.10937
2262	6.4085
2264.85	6.45218
2267.7	5.8828
2270.55	5.73639
2273.4	5.08047
2276.24	4.93406
2279.09	5.02938
2281.93	5.3709
2284.77	5.81311
2287.61	6.80058
2290.46	6.18789
2293.29	6.85962
2296.13	7.11616
2298.97	8.29761
2301.81	8.50296
2304.64	9.12463
2307.48	9.15032
2310.31	10.2831
2313.14	9.82016
2315.97	10.8311
2318.8	10.6211
2321.63	9.781
2324.46	10.2628
2327.29	9.19982
2330.12	9.36148
2332.94	9.05799
2335.76	9.05107
2338.59	7.1913
2341.41	6.81752
2344.23	5.54094
2347.05	5.27551
2349.87	4.54253
2352.69	4.1886
2355.5	3.07742
2358.32	2.39254
2361.14	1.89912
2363.95	1.47832
2366.76	1.90047
2369.58	0.603399
2372.39	0.450547
2375.2	0.419532
2378	-0.494307
2380.81	0.740896
2383.62	0.733057
2386.42	1.45372
2389.23	2.10977
2392.03	2.18616
2394.84	4.11765
2397.64	4.69457
2400.44	5.47638
2403.24	5.82714
2406.04	5.8636
2408.83	5.72489
2411.63	6.66344
2414.43	6.85905
2417.22	7.43706
2420.02	7.452
2422.81	6.99644
2425.6	6.95411
2428.39	6.77511
2431.18	5.72863
2433.97	5.00957
2436.76	3.98904
2439.54	3.84318
2442.33	4.04367
2445.11	3.71983
2447.9	3.23447
2450.68	2.68079
2453.46	2.69789
2456.24	3.24271
2459.02	2.53034
2461.8	3.05721
2464.58	3.17964
2467.36	2.64282
2470.13	1.97569
2472.91	2.19337
2475.68	1.76234
2478.45	3.11009
2481.22	3.37943
2484	3.67691
2486.77	3.7354
2489.54	3.39669
2492.3	3.34592
2495.07	2.69496
2497.84	2.54534
2500.6	1.3548
2503.36	1.3557
2506.13	2.71563
2508.89	3.19254
2511.65	3.2783
2514.41	3.41953
2517.17	3.27055
2519.93	4.20905
2522.68	5.09664
2525.44	4.21034
2528.19	3.66007
2530.95	5.05482
2533.7	4.85744
2536.45	5.22762
2539.2	6.93178
2541.95	6.81053
2544.7	8.12352
2547.45	8.64972
2550.2	9.0682
2552.94	8.53653
2555.69	7.35887
2558.43	5.45427
2561.17	4.81225
2563.92	5.10802
2566.66	4.68466
2569.4	3.58973
2572.14	3.87093
2574.88	3.74523
2577.61	3.3977
2580.35	3.81222
2583.09	3.48833
2585.82	3.28393
2588.55	3.37279
2591.28	2.95742
2594.02	3.22319
2596.75	4.31218
2599.48	5.13227
2602.2	5.05645
2604.93	6.52754
2607.66	6.62232
2610.38	8.00245
2613.11	8.32088
2615.83	8.6897
2618.56	8.05459
2621.28	7.83936
2624	8.47594
2626.72	9.30573
2629.44	10.3905
2632.15	10.1925
2634.87	9.1489
2637.59	8.68165
2640.3	9.87089
2643.02	11.2066
2645.73	11.4009
2648.44	10.8531
2651.15	11.3018
2653.86	11.2517
2656.57	10.9696
2659.28	10.7031
2661.99	11.2258
2664.69	10.7222
2667.4	10.9541
2670.1	11.2842
2672.81	11.7268
2675.51	10.8066
2678.21	11.3786
2680.91	10.8486
2683.61	9.88676
2686.31	9.35293
2689	9.67787
2691.7	10.1108
2694.4	10.0202
2697.09	11.186
2699.79	11.0813
2702.48	11.3988
2705.17	12.6388
2707.86	13.4645
2710.55	13.895
2713.24	14.4304
2715.93	15.7404
2718.61	16.7708
2721.3	17.8987
2723.99	18.1392
2726.67	17.9022
2729.35	19.4174
2732.04	19.7265
2734.72	19.3882
2737.4	18.7713
2740.08	17.9721
2742.76	17.3667
2745.43	16.3286
2748.11	14.7754
2750.79	14.2817
2753.46	13.6876
2756.13	11.9663
2758.81	11.3873
2761.48	10.1898
2764.15	8.06935
2766.82	6.59591
2769.49	5.46185
2772.16	4.52412
2774.82	3.78785
2777.49	4.3266
2780.16	3.88336
2782.82	4.10458
2785.48	3.76437
2788.15	2.98761
2790.81	3.08878
2793.47	3.86296
2796.13	4.20812
2798.79	4.20677
2801.44	3.35758
2804.1	3.08402
2806.76	3.84711
2809.41	3.42919
2812.07	3.55134
2814.72	3.6922
2817.37	5.10702
2820.02	6.73584
2822.67	9.61787
2825.32	14.3184
2827.97	18.9257
2830.62	23.9526
2833.26	29.9776
2835.91	36.7316
2838.55	44.5394
2841.2	54.5066
2843.84	65.1852
2846.48	75.9364
2849.12	89.036
2851.76	101.601
2854.4	115.046
2857.04	127.705
2859.68	139.573
2862.32	150.07
2864.95	159.336
2867.58	168.304
2870.22	176.931
2872.85	184.402
2875.48	191.689
2878.11	196.849
2880.74	201.41
2883.37	207.222
2886	212.393
2888.63	217.581
2891.25	221.538
2893.88	225.078
2896.5	229.767
2899.13	235.583
2901.75	242.575
2904.37	251.864
2906.99	263.224
2909.61	275.078
2912.23	286.782
2914.85	297.092
2917.46	307.914
2920.08	317.549
2922.7	325.165
2925.31	330.144
2927.92	333.856
2930.53	334.317
2933.15	332.466
2935.76	328.519
2938.37	321.7
2940.98	313.344
2943.58	304
2946.19	293.329
2948.8	281.547
2951.4	269.434
2954.01	255.813
2956.61	241.773
2959.21	228.128
2961.81	215.169
2964.41	202.674
2967.01	191.81
2969.61	181.184
2972.21	171.141
2974.81	159.962
2977.4	149.674
2980	138.768
2982.59	128.871
2985.18	117.172
2987.78	106.131
2990.37	95.6223
2992.96	83.1021
2995.55	72.2978
2998.14	62.5387
3000.72	52.2984
3003.31	43.6238
3005.9	36.2235
3008.48	29.624
3011.07	22.9408
3013.65	16.9838
3016.23	13.2907
3018.81	9.69986
3021.39	6.53474
3023.97	3.38367
3026.55	1.97139
3029.13	0.528877
3031.71	0.444
3034.28	-0.178799
3036.86	-0.177607
3039.43	1.18211
3042.01	2.50541
3044.58	3.42753
3047.15	5.60566
3049.72	6.66339
3052.29	7.98024
3054.86	8.36649
3057.43	8.23682
3060	8.54904
3062.56	8.55234
3065.13	8.66369
3067.69	7.79407
3070.25	7.12221
3072.82	6.99601
3075.38	5.54674
3077.94	4.68041
3080.5	4.88846
3083.06	3.96342
3085.62	2.59329
3088.17	1.86096
3090.73	1.81818
3093.29	2.17632
3095.84	1.99354
3098.4	2.19638
3100.95	2.37886
3103.5	4.01919
3106.05	5.44384
3108.6	6.19356
3111.15	7.11189
3113.7	8.5816
3116.25	10.7629
3118.79	12.184
3121.34	13.7392
3123.88	16.0559
3126.43	18.7401
3128.97	20.1191
3131.51	21.969
3134.05	24.0785
3136.59	27.0713
3139.14	29.4025
3141.67	32.0686
3144.21	34.2406
3146.75	35.3871
3149.28	35.7183