File: data/Raman/poly_smoothed/Mb_10_14_24_1x_45s_532 nm_x100_100%_600 gr_mm_01.txt
#Acq. time (s)=	45
#Accumulations=	2
#Range (cm-¹)=	200...3150
#Windows=	2
#Auto scanning=	Off
#Autofocus=	Off
#Macrospot=	Off
#AutoExposure=	Off
#Spike filter=	Multiple accum.
#Delay time (s)=	0
#Binning=	1
#Readout mode=	Signal
#DeNoise=	Off
#ICS correction=	On
#Dark correction=	Off
#Inst. Process=	Off
#Detector Gain=	Best Dynamic Range
#Detector ADC=	20 kHz
#Detector temperature (°C)=	-69.85
#Instrument=	LabRAM HR Evol
#Detector=	Synapse
#Objective=	x100
#Grating=	600 gr/mm
#ND Filter=	100%
#Laser (nm)=	532
#Hole=	100.021
#Range=	Auto
#Laser Pol.=	No
#Raman. Pol.=	No
#Laser Pol. (°)=	-0.0007625
#Raman Pol. (°)=	89.9995
#Collection=	Microscope
#StageXY=	Marzhauser
#StageZ=	Marzhauser
#X (µm)=	-616.4
#Y (µm)=	-1582.2
#Z (µm)=	89.85
#Full time(mm:ss)=	3:19
#Project=
#Sample=
#Site=
#Title=	Mb_10_14_24_2x_45s_532 nm_x100_100%_600 gr_mm
#Remark=
#Date=	11.07.2022 10:20
#Acquired=	11.07.2022 10:20:36
#Base:Fit=	10.08.2022 10:21:11
#Base:Sub=	10.08.2022 10:21:41
#Filter:Polynom=	16.08.2022 10:17:53
#AxisType[0]=Intens
#AxisUnit[0]=Cnt
#AxisType[1]=Spectr
#AxisUnit[1]=1/cm
200.388	0.715208
204.019	9.68224
207.646	14.6148
211.274	18.8204
214.899	22.3588
218.524	26.352
222.146	29.9961
225.766	31.8687
229.388	36.2025
233.005	38.0039
236.621	39.7789
240.236	39.8586
243.852	37.8136
247.464	35.8654
251.074	31.076
254.683	30.7204
258.291	29.1757
261.897	27.504
265.504	26.2441
269.108	23.6627
272.71	23.0331
276.311	20.2155
279.91	18.5309
283.508	16.6868
287.105	13.4747
290.698	12.3845
294.291	9.86549
297.884	8.13386
301.475	8.46325
305.064	7.80897
308.652	10.1464
312.237	9.55299
315.822	10.2579
319.406	11.1359
322.987	10.2351
326.568	9.08165
330.148	7.12449
333.724	5.74365
337.301	3.36336
340.875	3.17352
344.449	4.47644
348.02	5.38361
351.592	4.81245
355.16	6.56451
358.728	5.94261
362.294	8.08164
365.858	10.1398
369.422	12.0201
372.983	13.4482
376.543	15.3087
380.102	16.6244
383.661	18.1787
387.216	21.3242
390.771	22.9322
394.324	23.312
397.875	24.1991
401.425	24.4206
404.974	24.4129
408.524	23.7625
412.07	22.1982
415.614	19.1931
419.156	17.5908
422.698	15.3326
426.238	13.7559
429.777	12.1769
433.315	8.76312
436.852	5.89953
440.387	5.37007
443.919	4.04261
447.451	3.31128
450.982	3.50175
454.512	4.41953
458.038	3.51315
461.565	5.61761
465.091	7.4116
468.613	8.07295
472.136	8.72625
475.655	9.6936
479.176	11.7052
482.692	14.3795
486.21	17.4485
489.724	17.8844
493.237	19.7102
496.75	22.1522
500.26	24.8686
503.769	26.3641
507.279	27.715
510.785	27.7664
514.289	27.0065
517.793	27.3566
521.297	27.4344
524.797	27.6186
528.297	26.8033
531.795	24.6305
535.291	24.3375
538.787	23.8745
542.281	22.4431
545.773	21.5968
549.264	21.0833
552.754	20.14
556.243	18.3099
559.73	16.1502
563.216	14.7345
566.701	13.0478
570.182	12.3103
573.664	10.2446
577.145	8.88091
580.624	8.96508
584.1	9.16461
587.577	9.24448
591.052	7.89864
594.524	6.72637
597.997	6.97532
601.466	9.41565
604.936	10.269
608.403	10.2082
611.87	11.5053
615.334	13.3776
618.799	16.0414
622.26	18.5019
625.72	20.354
629.181	20.9799
632.638	23.4416
636.095	26.5402
639.551	27.9565
643.005	27.7862
646.457	27.6178
649.908	27.7226
653.357	28.8505
656.806	30.0052
660.253	29.8106
663.7	30.7966
667.145	31.2438
670.588	30.2617
674.027	30.0085
677.468	30.1566
680.907	31.243
684.345	31.7605
687.781	33.3675
691.216	32.8509
694.65	33.1439
698.081	33.8056
701.512	35.2489
704.942	34.7972
708.371	36.0522
711.796	36.965
715.222	37.3864
718.645	39.4576
722.068	40.2895
725.49	41.2105
728.909	42.2938
732.329	43.9097
735.745	43.9469
739.16	47.3319
742.576	48.0664
745.988	50.3925
749.401	52.5204
752.811	54.5837
756.22	57.2044
759.627	59.4905
763.035	61.8133
766.44	64.679
769.843	68.0698
773.245	70.2714
776.646	71.6218
780.046	73.1772
783.444	74.9664
786.841	77.922
790.237	79.5433
793.631	82.6515
797.024	83.5321
800.416	85.698
803.807	85.9458
807.196	85.1954
810.584	84.7577
813.971	84.6148
817.354	83.4671
820.739	83.4222
824.122	85.4722
827.503	85.0275
830.882	84.9498
834.261	82.4578
837.637	80.7402
841.013	77.9943
844.389	75.5845
847.761	74.642
851.131	72.8849
854.503	69.3935
857.871	67.369
861.24	65.369
864.606	64.8808
867.97	64.5102
871.336	62.5929
874.698	61.8299
878.058	59.9044
881.418	57.3453
884.778	54.3624
888.135	52.7664
891.49	52.5395
894.845	51.9869
898.198	51.8088
901.55	51.5021
904.901	51.5012
908.25	50.3404
911.598	49.6032
914.945	48.2682
918.291	47.1282
921.635	47.5433
924.978	47.7917
928.318	49.0605
931.659	49.3835
934.998	49.2007
938.336	49.7504
941.671	49.0693
945.007	48.4754
948.339	48.5551
951.672	48.851
955.004	46.7981
958.333	45.0824
961.662	44.1436
964.989	45.5107
968.315	48.8973
971.639	48.2761
974.962	49.8242
978.285	51.3358
981.605	51.0202
984.924	51.085
988.243	51.0014
991.56	50.7738
994.875	50.5055
998.188	50.2787
1001.5	49.216
1004.81	49.7296
1008.12	49.0123
1011.43	50.6202
1014.74	51.0385
1018.05	51.9601
1021.35	52
1024.65	53.0464
1027.96	52.7618
1031.26	51.4411
1034.56	50.4144
1037.86	47.8514
1041.16	47.528
1044.45	50.051
1047.75	50.0781
1051.04	48.1116
1054.33	45.5073
1057.62	43.3429
1060.91	39.4318
1064.2	36.2277
1067.49	32.5693
1070.77	26.8001
1074.06	22.2142
1077.34	19.1904
1080.62	15.3065
1083.91	12.6591
1087.18	12.403
1090.46	12.3661
1093.74	11.2828
1097.02	12.1581
1100.29	12.5702
1103.56	11.2664
1106.84	11.0825
1110.11	10.8397
1113.38	10.2624
1116.64	10.8477
1119.91	12.0715
1123.18	12.2149
1126.44	11.615
1129.7	11.524
1132.97	11.2699
1136.23	9.68274
1139.49	9.23236
1142.74	8.17484
1146	7.00189
1149.26	5.93253
1152.51	4.29318
1155.76	3.66864
1159.01	1.50143
1162.27	0.965031
1165.51	0.261835
1168.76	-1.594
1172.01	-1.10272
1175.25	-0.826378
1178.5	0.296333
1181.74	0.727058
1184.98	2.10874
1188.22	4.3619
1191.46	4.40354
1194.7	6.08023
1197.94	7.97084
1201.17	9.58874
1204.41	12.1181
1207.64	15.5273
1210.87	16.8796
1214.1	20.4879
1217.33	23.0017
1220.56	26.4534
1223.79	31.104
1227.01	33.157
1230.23	36.3352
1233.46	39.6115
1236.68	42.2318
1239.9	42.8236
1243.12	43.5803
1246.34	44.6096
1249.55	43.8062
1252.77	45.1565
1255.98	46.5008
1259.2	46.5342
1262.41	46.736
1265.62	47.5655
1268.83	48.4735
1272.03	48.4538
1275.24	48.9276
1278.45	49.6157
1281.65	49.9934
1284.85	51.7445
1288.06	50.0922
1291.26	51.5445
1294.46	52.7137
1297.66	54.2171
1300.85	57.1364
1304.05	58.5069
1307.24	58.6146
1310.43	60.2021
1313.63	61.4388
1316.82	62.8435
1320.01	61.85
1323.2	59.6659
1326.38	57.6537
1329.57	57.5378
1332.76	56.4465
1335.94	56.4436
1339.12	54.683
1342.3	54.1333
1345.48	52.7927
1348.66	50.0494
1351.84	46.5761
1355.01	44.6887
1358.19	43.0389
1361.36	40.7453
1364.53	37.4814
1367.71	36.6368
1370.88	35.2902
1374.04	35.1742
1377.21	34.6221
1380.38	34.6635
1383.54	34.2815
1386.71	34.5786
1389.87	34.1453
1393.03	33.5726
1396.19	32.8866
1399.35	31.286
1402.51	31.809
1405.67	31.618
1408.82	34.2714
1411.98	36.1151
1415.13	40.0503
1418.28	44.3099
1421.43	48.9452
1424.58	54.1403
1427.73	58.5504
1430.88	63.844
1434.02	69.7992
1437.17	74.7945
1440.31	77.8157
1443.45	81.5993
1446.6	84.4702
1449.74	85.586
1452.87	85.1207
1456.01	82.6439
1459.15	80.851
1462.28	77.2674
1465.42	72.454
1468.55	67.296
1471.68	61.5862
1474.81	55.2437
1477.94	49.3649
1481.07	43.8426
1484.2	39.2112
1487.32	34.8389
1490.45	32.3491
1493.57	30.5897
1496.69	27.9996
1499.81	28.0716
1502.93	25.7734
1506.05	25.3425
1509.17	25.5978
1512.28	24.498
1515.4	23.771
1518.51	24.4017
1521.63	24.9666
1524.74	24.2261
1527.85	24.666
1530.96	23.5299
1534.06	23.5693
1537.17	23.0775
1540.28	23.298
1543.38	23.6214
1546.48	23.2534
1549.59	21.621
1552.69	22.7438
1555.79	24.1926
1558.88	25.2777
1561.98	27.4872
1565.08	29.576
1568.17	31.2939
1571.27	33.8662
1574.36	38.4555
1577.45	41.0763
1580.54	43.2607
1583.63	45.0437
1586.72	46.012
1589.8	48.4841
1592.89	50.2531
1595.97	52.0196
1599.06	51.8539
1602.14	52.2339
1605.22	52.6448
1608.3	51.486
1611.38	51.3417
1614.46	49.9189
1617.53	50.5447
1620.61	50.1427
1623.68	50.3628
1626.75	52.4862
1629.82	54.7188
1632.9	57.6281
1635.96	59.3722
1639.03	61.9627
1642.1	65.122
1645.16	67.7003
1648.23	70.6403
1651.29	70.9441
1654.36	71.604
1657.42	71.2333
1660.48	70.934
1663.53	71.3994
1666.59	68.3338
1669.65	66.0383
1672.7	62.1066
1675.76	59.0612
1678.81	53.7957
1681.86	49.5261
1684.91	42.4591
1687.96	37.673
1691.01	32.2123
1694.06	28.0021
1697.11	24.7689
1700.15	21.827
1703.2	19.1365
1706.24	17.5485
1709.28	15.6467
1712.32	13.0047
1715.36	12.8127
1718.4	11.5503
1721.43	10.9216
1724.47	10.4011
1727.5	10.3104
1730.54	9.83454
1733.57	9.72834
1736.6	8.69178
1739.63	8.08712
1742.66	7.29208
1745.69	6.88648
1748.72	6.20918
1751.74	4.67683
1754.77	4.09515
1757.79	3.05469
1760.81	3.01113
1763.83	1.73146
1766.85	2.71088
1769.87	3.34316
1772.89	4.08933
1775.91	5.78457
1778.92	6.14342
1781.94	6.61849
1784.95	6.67585
1787.96	6.86921
1790.97	6.70492
1793.98	6.54669
1796.99	6.26243
1800	6.79125
1803	5.52897
1806.01	5.5925
1809.01	4.41172
1812.02	4.22433
1815.02	4.32292
1818.02	3.32318
1821.02	2.85917
1824.02	2.23756
1827.01	1.09694
1830.01	2.10659
1833	2.52793
1836	2.209
1838.99	2.9705
1841.98	4.06793
1844.97	4.73793
1847.96	5.28268
1850.95	4.81837
1853.94	4.8872
1856.92	4.80103
1859.91	4.77966
1862.89	4.81499
1865.88	4.70899
1868.86	4.34266
1871.84	4.58236
1874.82	3.75107
1877.8	3.70954
1880.77	3.14822
1882.52	3.72386
1885.51	3.83338
1888.5	4.29709
1891.49	3.66499
1894.47	4.04059
1897.46	3.75906
1900.44	3.61153
1903.42	4.64028
1906.4	5.25757
1909.38	5.54944
1912.36	6.1566
1915.34	6.13823
1918.32	6.13042
1921.29	5.57379
1924.27	5.56977
1927.24	5.01043
1930.21	4.39554
1933.18	4.45393
1936.15	3.42543
1939.12	1.38207
1942.09	1.06708
1945.06	1.87295
1948.02	1.52219
1950.99	1.88824
1953.95	1.34221
1956.91	1.72184
1959.87	0.877299
1962.84	1.15202
1965.79	0.367917
1968.75	1.08888
1971.71	1.27119
1974.66	2.00891
1977.62	3.14644
1980.57	3.1216
1983.53	3.21409
1986.48	3.51216
1989.43	3.66773
1992.38	2.83639
1995.33	2.29972
1998.27	2.98017
2001.22	3.61032
2004.16	3.00189
2007.11	3.44305
2010.05	3.18972
2012.99	3.85597
2015.93	4.89037
2018.87	4.49133
2021.81	5.55632
2024.75	5.83118
2027.69	6.40157
2030.62	6.0548
2033.56	6.42173
2036.49	7.06139
2039.42	8.51434
2042.35	8.2398
2045.28	7.83787
2048.21	8.8941
2051.14	8.64774
2054.06	9.14592
2056.99	9.36945
2059.92	9.98179
2062.84	9.71109
2065.76	10.0732
2068.68	11.3386
2071.6	10.6548
2074.52	10.8432
2077.44	11.241
2080.36	11.4228
2083.27	11.8191
2086.19	11.1308
2089.1	12.0582
2092.01	12.703
2094.93	12.7879
2097.84	12.2717
2100.75	11.5742
2103.66	12.0097
2106.56	12.1062
2109.47	12.0631
2112.37	11.641
2115.28	11.8334
2118.18	12.3464
2121.09	12.9242
2123.99	14.4576
2126.89	14.7213
2129.79	15.4958
2132.68	16.0142
2135.58	15.9061
2138.48	16.7051
2141.37	17.38
2144.26	18.4138
2147.16	20.7583
2150.05	22.5186
2152.94	24.755
2155.83	26.5523
2158.72	28.9828
2161.6	31.7741
2164.49	32.6254
2167.38	33.9714
2170.26	35.4934
2173.14	35.8361
2176.03	36.4849
2178.91	37.3685
2181.79	38.5176
2184.67	38.189
2187.54	38.5848
2190.42	38.5708
2193.3	38.0041
2196.17	36.6504
2199.05	34.3266
2201.92	32.1794
2204.79	30.5821
2207.66	27.7796
2210.53	26.9066
2213.4	25.2387
2216.27	24.4492
2219.13	22.8232
2222	21.0483
2224.86	20.4364
2227.72	20.1006
2230.59	18.4481
2233.45	16.358
2236.31	14.9892
2239.17	13.9696
2242.03	12.0096
2244.88	10.8861
2247.74	11.3639
2250.59	11.2421
2253.45	10.8471
2256.3	11.606
2259.15	11.6912
2262	11.3558
2264.85	11.3603
2267.7	10.6288
2270.55	10.3716
2273.4	10.7315
2276.24	9.59783
2279.09	9.41677
2281.93	9.58507
2284.77	9.35071
2287.61	7.93412
2290.46	7.86018
2293.29	7.86854
2296.13	8.09002
2298.97	8.10082
2301.81	7.76949
2304.64	8.05047
2307.48	8.19824
2310.31	8.0022
2313.14	8.24069
2315.97	9.1337
2318.8	9.95661
2321.63	9.86202
2324.46	9.48418
2327.29	9.06659
2330.12	7.55806
2332.94	7.20067
2335.76	6.4054
2338.59	5.24588
2341.41	3.53625
2344.23	2.7007
2347.05	1.92834
2349.87	1.40026
2352.69	1.13005
2355.5	1.30296
2358.32	2.13929
2361.14	3.04051
2363.95	4.08309
2366.76	5.2949
2369.58	5.01595
2372.39	5.66319
2375.2	5.38551
2378	6.37927
2380.81	7.37713
2383.62	7.60585
2386.42	7.29035
2389.23	6.46336
2392.03	6.28496
2394.84	5.71795
2397.64	4.41086
2400.44	4.19582
2403.24	3.87276
2406.04	3.41633
2408.83	4.13751
2411.63	5.05239
2414.43	6.06524
2417.22	7.00547
2420.02	7.08502
2422.81	7.10281
2425.6	7.03618
2428.39	6.93179
2431.18	6.66345
2433.97	6.56474
2436.76	5.96912
2439.54	5.93329
2442.33	6.16171
2445.11	4.79908
2447.9	5.05508
2450.68	4.09567
2453.46	3.82961
2456.24	3.29164
2459.02	2.58368
2461.8	3.25913
2464.58	2.81382
2467.36	3.97913
2470.13	4.72058
2472.91	5.52755
2475.68	6.13659
2478.45	6.60705
2481.22	7.3409
2484	7.77722
2486.77	7.93984
2489.54	7.02956
2492.3	7.21702
2495.07	7.42454
2497.84	7.99243
2500.6	7.84499
2503.36	8.05293
2506.13	7.76494
2508.89	7.0376
2511.65	5.86592
2514.41	4.62299
2517.17	4.69772
2519.93	5.10459
2522.68	6.40613
2525.44	6.39738
2528.19	6.92088
2530.95	6.92353
2533.7	5.65667
2536.45	5.53162
2539.2	5.35573
2541.95	5.57202
2544.7	5.66811
2547.45	5.92262
2550.2	5.46235
2552.94	5.85777
2555.69	6.17215
2558.43	6.38312
2561.17	6.65452
2563.92	5.61318
2566.66	5.26411
2569.4	3.81151
2572.14	3.82851
2574.88	3.94634
2577.61	3.55717
2580.35	3.76661
2583.09	4.68263
2585.82	5.79251
2588.55	6.57551
2591.28	6.37307
2594.02	6.10306
2596.75	6.08857
2599.48	5.04341
2602.2	5.53973
2604.93	6.05608
2607.66	6.81582
2610.38	7.2312
2613.11	6.76803
2615.83	7.22919
2618.56	8.78723
2621.28	8.96348
2624	8.94718
2626.72	9.07738
2629.44	8.29882
2632.15	7.57968
2634.87	8.25209
2637.59	8.76527
2640.3	9.19317
2643.02	8.39914
2645.73	8.82866
2648.44	8.87256
2651.15	8.42467
2653.86	8.63606
2656.57	8.30461
2659.28	8.64922
2661.99	8.5814
2664.69	8.53147
2667.4	7.75666
2670.1	8.11204
2672.81	8.68453
2675.51	9.41132
2678.21	8.9219
2680.91	8.50231
2683.61	9.31462
2686.31	8.23467
2689	8.23266
2691.7	8.38856
2694.4	8.4641
2697.09	9.356
2699.79	9.7326
2702.48	10.0903
2705.17	9.44363
2707.86	10.1782
2710.55	10.2865
2713.24	11.2447
2715.93	11.6525
2718.61	12.9605
2721.3	12.6452
2723.99	12.9562
2726.67	12.2091
2729.35	11.1165
2732.04	11.0001
2734.72	11.6873
2737.4	12.3514
2740.08	11.7506
2742.76	9.48372
2745.43	7.81611
2748.11	7.01129
2750.79	6.51341
2753.46	5.92896
2756.13	5.42615
2758.81	5.06129
2761.48	4.03479
2764.15	3.53201
2766.82	2.51439
2769.49	1.84719
2772.16	1.61202
2774.82	1.53228
2777.49	0.798171
2780.16	1.02996
2782.82	0.566286
2785.48	-0.196643
2788.15	-0.127778
2790.81	-1.05355
2793.47	-0.472822
2796.13	-0.0423865
2798.79	0.27015
2801.44	0.537844
2804.1	-0.913646
2806.76	-1.65237
2809.41	-1.65429
2812.07	-1.5756
2814.72	-1.13901
2817.37	1.21165
2820.02	4.01776
2822.67	7.62067
2825.32	11.2927
2827.97	14.6745
2830.62	19.6788
2833.26	25.6105
2835.91	30.3026
2838.55	36.0284
2841.2	43.5506
2843.84	52.3241
2846.48	62.3208
2849.12	72.3201
2851.76	83.6436
2854.4	94.5226
2857.04	104.235
2859.68	115.078
2862.32	123.911
2864.95	131.71
2867.58	138.961
2870.22	146.149
2872.85	152.688
2875.48	159.745
2878.11	164.851
2880.74	171.62
2883.37	177.085
2886	179.827
2888.63	183.548
2891.25	187.148
2893.88	189.695
2896.5	193.75
2899.13	199.408
2901.75	206.158
2904.37	215.213
2906.99	225.835
2909.61	237.543
2912.23	248.726
2914.85	260.955
2917.46	271.54
2920.08	280.651
2922.7	288.849
2925.31	294.281
2927.92	297.391
2930.53	299.092
2933.15	299.326
2935.76	297.622
2938.37	292.528
2940.98	287.035
2943.58	276.973
2946.19	267.081
2948.8	254.733
2951.4	242.994
2954.01	231.267
2956.61	217.782
2959.21	204.106
2961.81	194.056
2964.41	182.083
2967.01	171.41
2969.61	161.008
2972.21	152.028
2974.81	142.904
2977.4	133.354
2980	124.146
2982.59	113.773
2985.18	103.872
2987.78	93.6645
2990.37	82.6912
2992.96	73.175
2995.55	64.1231
2998.14	54.6751
3000.72	47.4394
3003.31	38.9922
3005.9	30.6514
3008.48	25.0076
3011.07	19.8351
3013.65	15.423
3016.23	10.5754
3018.81	6.61949
3021.39	4.07711
3023.97	2.05401
3026.55	0.724983
3029.13	-0.887662
3031.71	-0.343399
3034.28	-0.666644
3036.86	0.673094
3039.43	1.33709
3042.01	3.78082
3044.58	6.48686
3047.15	7.91539
3049.72	8.94905
3052.29	10.3544
3054.86	10.7343
3057.43	10.6378
3060	10.4694
3062.56	11.1367
3065.13	10.8853
3067.69	9.85051
3070.25	9.36217
3072.82	8.30376
3075.38	7.69543
3077.94	5.55733
3080.5	3.09415
3083.06	1.85791
3085.62	1.04743
3088.17	0.539643
3090.73	-0.581085
3093.29	-0.339443
3095.84	1.34842
3098.4	3.0112
3100.95	5.03756
3103.5	7.56849
3106.05	9.68959
3108.6	10.9636
3111.15	12.5461
3113.7	14.6238
3116.25	16.3487
3118.79	17.91
3121.34	20.1501
3123.88	22.8937
3126.43	25.6915
3128.97	27.1568
3131.51	29.3175
3134.05	32.0813
3136.59	34.0716
3139.14	35.9634
3141.67	38.0957
3144.21	42.0793
3146.75	46.8225
3149.28	52.7103