File: data/Raman/poly_smoothed/Mb_10_14_44_1x_45s_532 nm_x100_100%_600 gr_mm_01.txt
#Acq. time (s)=	45
#Accumulations=	2
#Range (cm-¹)=	200...3150
#Windows=	2
#Auto scanning=	Off
#Autofocus=	Off
#Macrospot=	Off
#AutoExposure=	Off
#Spike filter=	Multiple accum.
#Delay time (s)=	0
#Binning=	1
#Readout mode=	Signal
#DeNoise=	Off
#ICS correction=	On
#Dark correction=	Off
#Inst. Process=	Off
#Detector Gain=	Best Dynamic Range
#Detector ADC=	20 kHz
#Detector temperature (°C)=	-69.85
#Instrument=	LabRAM HR Evol
#Detector=	Synapse
#Objective=	x100
#Grating=	600 gr/mm
#ND Filter=	100%
#Laser (nm)=	532
#Hole=	100.021
#Range=	Auto
#Laser Pol.=	No
#Raman. Pol.=	No
#Laser Pol. (°)=	-0.0007625
#Raman Pol. (°)=	89.9995
#Collection=	Microscope
#StageXY=	Marzhauser
#StageZ=	Marzhauser
#X (µm)=	-605.4
#Y (µm)=	-1688.2
#Z (µm)=	89.1
#Full time(mm:ss)=	3:18
#Project=
#Sample=
#Site=
#Title=	Mb_10_14_44_2x_45s_532 nm_x100_100%_600 gr_mm
#Remark=
#Date=	11.07.2022 12:00
#Acquired=	11.07.2022 12:00:39
#Base:Fit=	10.08.2022 10:21:11
#Base:Sub=	10.08.2022 10:21:41
#Filter:Polynom=	16.08.2022 10:17:53
#AxisType[0]=Intens
#AxisUnit[0]=Cnt
#AxisType[1]=Spectr
#AxisUnit[1]=1/cm
200.388	27.3976
204.019	25.8014
207.646	23.5134
211.274	21.6562
214.899	18.1337
218.524	15.0922
222.146	11.5384
225.766	8.28723
229.388	9.51538
233.005	8.19955
236.621	8.35672
240.236	5.22073
243.852	4.36883
247.464	4.01974
251.074	2.97521
254.683	2.74159
258.291	4.4344
261.897	4.53863
265.504	4.76489
269.108	5.57664
272.71	5.92329
276.311	6.88004
279.91	7.83328
283.508	9.22256
287.105	9.3447
290.698	10.0612
294.291	11.1373
297.884	12.2815
301.475	12.2705
305.064	13.454
308.652	13.1115
312.237	16.0276
315.822	20.5332
319.406	22.6049
322.987	24.7201
326.568	23.5146
330.148	23.4482
333.724	23.892
337.301	24.8615
340.875	24.2538
344.449	23.8054
348.02	21.6347
351.592	17.6161
355.16	15.2646
358.728	12.0329
362.294	12.6587
365.858	11.6981
369.422	10.5796
372.983	10.352
376.543	9.52891
380.102	9.06628
383.661	9.88844
387.216	10.6349
390.771	11.5611
394.324	12.5296
397.875	14.7672
401.425	16.9348
404.974	17.1648
408.524	18.9048
412.07	20.3532
415.614	21.4119
419.156	21.9728
422.698	22.289
426.238	22.9475
429.777	21.1679
433.315	19.3604
436.852	17.9478
440.387	15.6014
443.919	16.9391
447.451	18.6892
450.982	18.097
454.512	19.13
458.038	20.7009
461.565	23.6134
465.091	24.4862
468.613	25.7322
472.136	27.0701
475.655	30.9783
479.176	31.3287
482.692	31.8862
486.21	33.6594
489.724	33.467
493.237	36.9219
496.75	38.7713
500.26	41.7578
503.769	41.0848
507.279	40.3086
510.785	40.0324
514.289	38.8376
517.793	37.814
521.297	37.589
524.797	35.6968
528.297	35.4125
531.795	33.1842
535.291	31.8791
538.787	31.6811
542.281	30.8754
545.773	29.7238
549.264	28.051
552.754	25.6892
556.243	26.1138
559.73	24.9418
563.216	23.0385
566.701	21.1014
570.182	20.2628
573.664	18.1795
577.145	16.1045
580.624	16.0894
584.1	15.6385
587.577	13.2534
591.052	10.3392
594.524	9.01853
597.997	8.13341
601.466	7.09687
604.936	5.77096
608.403	4.51353
611.87	3.84183
615.334	4.21113
618.799	2.52914
622.26	3.44015
625.72	3.5709
629.181	3.17435
632.638	2.31515
636.095	1.74301
639.551	3.67185
643.005	4.02677
646.457	4.00631
649.908	5.51134
653.357	6.27554
656.806	7.74031
660.253	7.29565
663.7	7.17142
667.145	9.48906
670.588	11.1147
674.027	11.7567
677.468	13.9322
680.907	12.691
684.345	12.685
687.781	12.5619
691.216	14.1966
694.65	15.5233
698.081	17.5282
701.512	17.9678
704.942	17.8319
708.371	16.5373
711.796	17.7466
715.222	16.0147
718.645	15.8701
722.068	15.9603
725.49	17.7154
728.909	17.3664
732.329	17.9398
735.745	17.1402
739.16	15.8685
742.576	15.6198
745.988	17.6155
749.401	21.7631
752.811	26.5839
756.22	28.6457
759.627	31.54
763.035	33.0881
766.44	34.7971
769.843	37.3452
773.245	39.8048
776.646	41.5696
780.046	42.714
783.444	43.6781
786.841	43.4758
790.237	45.8984
793.631	47.8955
797.024	49.8268
800.416	53.3913
803.807	56.6006
807.196	61.4745
810.584	62.3525
813.971	62.6064
817.354	65.2458
820.739	66.9586
824.122	69.8532
827.503	72.7021
830.882	75.267
834.261	74.659
837.637	73.962
841.013	70.9129
844.389	67.2269
847.761	66.8297
851.131	63.4009
854.503	59.1098
857.871	51.8455
861.24	49.233
864.606	44.9759
867.97	42.0838
871.336	40.4322
874.698	41.0635
878.058	41.5364
881.418	41.9504
884.778	42.4146
888.135	40.9871
891.49	40.9841
894.845	41.6837
898.198	43.2703
901.55	43.1416
904.901	43.8674
908.25	44.8198
911.598	46.3728
914.945	46.57
918.291	47.0534
921.635	47.4016
924.978	47.7856
928.318	49.365
931.659	49.2969
934.998	48.8331
938.336	47.7994
941.671	46.2736
945.007	46.1442
948.339	43.7023
951.672	44.4473
955.004	45.0255
958.333	42.5837
961.662	37.2001
964.989	33.9994
968.315	36.9229
971.639	39.5753
974.962	44.1352
978.285	47.521
981.605	49.491
984.924	52.1235
988.243	54.8584
991.56	54.5756
994.875	56.4399
998.188	60.2208
1001.5	61.7371
1004.81	63.3036
1008.12	61.3324
1011.43	60.7518
1014.74	59.5153
1018.05	58.3996
1021.35	55.0972
1024.65	52.5818
1027.96	48.0762
1031.26	44.1879
1034.56	39.2978
1037.86	31.9536
1041.16	26.8157
1044.45	26.2224
1047.75	28.2512
1051.04	29.7817
1054.33	28.6823
1057.62	29.4862
1060.91	27.7933
1064.2	27.8252
1067.49	25.7333
1070.77	26.5177
1074.06	26.9683
1077.34	30.921
1080.62	34.2247
1083.91	33.7201
1087.18	35.1548
1090.46	37.4403
1093.74	39.809
1097.02	42.6649
1100.29	44.0339
1103.56	44.9907
1106.84	45.0994
1110.11	43.3397
1113.38	41.9943
1116.64	40.7464
1119.91	39.2182
1123.18	38.7003
1126.44	35.6726
1129.7	34.4381
1132.97	30.5397
1136.23	27.4287
1139.49	24.8203
1142.74	22.4799
1146	18.7303
1149.26	15.826
1152.51	15.0429
1155.76	11.9509
1159.01	10.2112
1162.27	6.82267
1165.51	3.50459
1168.76	2.66297
1172.01	3.60331
1175.25	2.96465
1178.5	3.54066
1181.74	6.17961
1184.98	6.82601
1188.22	9.23022
1191.46	9.95177
1194.7	12.7113
1197.94	18.4292
1201.17	24.9445
1204.41	29.7854
1207.64	37.2238
1210.87	43.7964
1214.1	51.6122
1217.33	61.6339
1220.56	69.7261
1223.79	77.9842
1227.01	85.945
1230.23	92.5623
1233.46	98.1715
1236.68	104.225
1239.9	109.981
1243.12	113.424
1246.34	116.604
1249.55	120.134
1252.77	122.527
1255.98	124.801
1259.2	125.574
1262.41	126.222
1265.62	125.171
1268.83	124.719
1272.03	127.746
1275.24	129.268
1278.45	131.399
1281.65	135.123
1284.85	137.865
1288.06	141.042
1291.26	143.191
1294.46	147.232
1297.66	149.225
1300.85	153.295
1304.05	157.199
1307.24	160.566
1310.43	164.967
1313.63	169.924
1316.82	173.115
1320.01	174.408
1323.2	174.899
1326.38	174.856
1329.57	174.483
1332.76	174.385
1335.94	170.982
1339.12	167.342
1342.3	163.088
1345.48	157.421
1348.66	153.97
1351.84	146.949
1355.01	140.019
1358.19	135.975
1361.36	129.963
1364.53	121.792
1367.71	114.781
1370.88	108.55
1374.04	102.272
1377.21	97.1512
1380.38	93.2409
1383.54	91.5059
1386.71	89.2766
1389.87	87.5683
1393.03	86.1536
1396.19	82.9694
1399.35	80.8225
1402.51	80.1159
1405.67	81.9086
1408.82	84.1919
1411.98	88.6493
1415.13	94.4735
1418.28	101.982
1421.43	111.732
1424.58	122.975
1427.73	136.473
1430.88	150.182
1434.02	163.735
1437.17	176.818
1440.31	187.36
1443.45	195.926
1446.6	202.119
1449.74	205.2
1452.87	204.574
1456.01	201.577
1459.15	197.612
1462.28	191.294
1465.42	180.775
1468.55	168.208
1471.68	153.522
1474.81	138.441
1477.94	122.642
1481.07	109.53
1484.2	97.0943
1487.32	86.4652
1490.45	75.0989
1493.57	66.1422
1496.69	61.0787
1499.81	55.8301
1502.93	52.5342
1506.05	51.0594
1509.17	49.4934
1512.28	48.7756
1515.4	47.8736
1518.51	47.9211
1521.63	48.429
1524.74	47.2594
1527.85	46.3305
1530.96	45.3962
1534.06	46.6368
1537.17	47.5829
1540.28	48.8335
1543.38	51.0869
1546.48	51.7405
1549.59	53.9889
1552.69	56.5845
1555.79	59.409
1558.88	62.1421
1561.98	63.5084
1565.08	64.8192
1568.17	66.4874
1571.27	70.2766
1574.36	73.3995
1577.45	76.9136
1580.54	83.473
1583.63	87.9976
1586.72	92.4085
1589.8	97.4774
1592.89	102.257
1595.97	106.848
1599.06	107.696
1602.14	108.953
1605.22	108.723
1608.3	108.793
1611.38	110.642
1614.46	111.604
1617.53	112.552
1620.61	115.246
1623.68	117.454
1626.75	123.204
1629.82	124.76
1632.9	130.747
1635.96	137.012
1639.03	144.663
1642.1	153.956
1645.16	162.759
1648.23	171.245
1651.29	178.899
1654.36	187.37
1657.42	192.882
1660.48	194.102
1663.53	194.958
1666.59	191.292
1669.65	187.879
1672.7	178.271
1675.76	168.331
1678.81	157.251
1681.86	144.122
1684.91	131.579
1687.96	117.966
1691.01	103.06
1694.06	89.7588
1697.11	76.6306
1700.15	65.0347
1703.2	55.2804
1706.24	48.6027
1709.28	43.0129
1712.32	37.3733
1715.36	32.9065
1718.4	28.5903
1721.43	25.1149
1724.47	23.5088
1727.5	22.1709
1730.54	21.0251
1733.57	18.8927
1736.6	18.0117
1739.63	15.8257
1742.66	15.3153
1745.69	14.3742
1748.72	13.094
1751.74	14.1172
1754.77	14.0049
1757.79	12.3371
1760.81	11.4067
1763.83	10.3694
1766.85	8.60808
1769.87	6.72896
1772.89	6.20335
1775.91	5.9443
1778.92	6.86393
1781.94	6.37072
1784.95	5.86796
1787.96	4.63409
1790.97	3.78882
1793.98	3.13246
1796.99	3.19658
1800	2.82046
1803	2.32826
1806.01	2.34213
1809.01	2.16392
1812.02	3.10768
1815.02	3.77401
1818.02	3.12165
1821.02	2.84262
1824.02	3.20917
1827.01	3.04841
1830.01	2.72333
1833	3.25543
1836	4.24718
1838.99	4.01511
1841.98	4.59803
1844.97	5.42753
1847.96	5.81639
1850.95	5.88718
1853.94	6.38513
1856.92	6.05707
1859.91	5.00561
1862.89	4.59691
1865.88	5.10378
1868.86	6.30814
1871.84	6.02743
1874.82	5.41195
1877.8	5.0012
1880.77	4.10193
1882.52	4.47353
1885.51	3.35333
1888.5	1.84239
1891.49	0.621086
1894.47	0.237225
1897.46	0.357254
1900.44	0.8441
1903.42	0.363282
1906.4	1.23552
1909.38	1.9814
1912.36	2.49137
1915.34	2.27072
1918.32	1.25139
1921.29	1.51929
1924.27	2.21828
1927.24	2.88614
1930.21	3.12506
1933.18	3.60544
1936.15	4.78667
1939.12	5.088
1942.09	5.98231
1945.06	5.64138
1948.02	5.2066
1950.99	4.3199
1953.95	4.74374
1956.91	4.50141
1959.87	4.22179
1962.84	4.68045
1965.79	5.13761
1968.75	5.22824
1971.71	5.76098
1974.66	5.22142
1977.62	5.53238
1980.57	5.0422
1983.53	4.74877
1986.48	4.57506
1989.43	4.37898
1992.38	5.71378
1995.33	6.98947
1998.27	5.99402
2001.22	6.2075
2004.16	5.81661
2007.11	6.02578
2010.05	6.01268
2012.99	6.05142
2015.93	6.50157
2018.87	4.98992
2021.81	3.46981
2024.75	3.52244
2027.69	4.12843
2030.62	4.974
2033.56	6.18972
2036.49	6.45752
2039.42	6.08752
2042.35	6.79959
2045.28	6.37686
2048.21	6.50166
2051.14	6.48203
2054.06	5.66836
2056.99	6.29417
2059.92	6.34406
2062.84	6.36148
2065.76	7.15307
2068.68	7.75447
2071.6	8.03099
2074.52	8.91114
2077.44	9.65704
2080.36	9.41003
2083.27	9.97813
2086.19	10.3811
2089.1	10.0873
2092.01	10.8417
2094.93	11.3723
2097.84	13.2641
2100.75	15.599
2103.66	15.1449
2106.56	15.9889
2109.47	16.2789
2112.37	17.5041
2115.28	19.2251
2118.18	19.9687
2121.09	21.4042
2123.99	22.7113
2126.89	23.7274
2129.79	25.6065
2132.68	28.5395
2135.58	32.4232
2138.48	36.0632
2141.37	40.1239
2144.26	43.4592
2147.16	48.2885
2150.05	51.3518
2152.94	54.7901
2155.83	57.5764
2158.72	60.1479
2161.6	62.3379
2164.49	65.3296
2167.38	68.1686
2170.26	69.174
2173.14	69.4748
2176.03	70.1444
2178.91	70.2385
2181.79	69.5335
2184.67	68.0598
2187.54	65.6512
2190.42	63.7816
2193.3	61.2481
2196.17	56.8489
2199.05	53.7987
2201.92	51.4158
2204.79	48.6616
2207.66	45.9094
2210.53	44.3386
2213.4	41.0354
2216.27	38.3869
2219.13	36.0162
2222	33.8782
2224.86	31.9606
2227.72	30.2478
2230.59	27.9647
2233.45	25.999
2236.31	24.9691
2239.17	22.292
2242.03	20.5716
2244.88	18.9418
2247.74	18.0321
2250.59	17.6544
2253.45	16.3823
2256.3	16.1649
2259.15	15.5238
2262	15.0613
2264.85	14.2007
2267.7	13.6991
2270.55	13.5174
2273.4	13.2594
2276.24	12.2003
2279.09	12.0813
2281.93	12.135
2284.77	12.3677
2287.61	12.2333
2290.46	12.0464
2293.29	11.4254
2296.13	10.5347
2298.97	11.2043
2301.81	10.9063
2304.64	11.4993
2307.48	11.6388
2310.31	10.672
2313.14	10.7338
2315.97	10.4797
2318.8	10.715
2321.63	10.8945
2324.46	10.658
2327.29	8.977
2330.12	9.01793
2332.94	7.44922
2335.76	5.87029
2338.59	5.70577
2341.41	4.40373
2344.23	2.96199
2347.05	1.89594
2349.87	1.26422
2352.69	1.11424
2355.5	-0.0990662
2358.32	-1.0177
2361.14	-1.74791
2363.95	-1.33056
2366.76	0.0591741
2369.58	1.35481
2372.39	1.54997
2375.2	1.0668
2378	0.887334
2380.81	1.54091
2383.62	0.827411
2386.42	-0.071668
2389.23	0.250794
2392.03	0.0479036
2394.84	-0.536946
2397.64	-0.159435
2400.44	0.293187
2403.24	1.13386
2406.04	1.10708
2408.83	0.334171
2411.63	0.421096
2414.43	1.0673
2417.22	2.43261
2420.02	3.57109
2422.81	4.13005
2425.6	4.64095
2428.39	4.31164
2431.18	5.02012
2433.97	5.61137
2436.76	6.33602
2439.54	6.31168
2442.33	6.9252
2445.11	7.32436
2447.9	7.59855
2450.68	6.04663
2453.46	5.47018
2456.24	5.81981
2459.02	5.98068
2461.8	5.91473
2464.58	5.20994
2467.36	4.80036
2470.13	4.6536
2472.91	2.93924
2475.68	2.06699
2478.45	2.25969
2481.22	2.98018
2484	2.81223
2486.77	2.55099
2489.54	2.16425
2492.3	2.13918
2495.07	1.4068
2497.84	1.45017
2500.6	2.01349
2503.36	2.89516
2506.13	3.87374
2508.89	4.52102
2511.65	5.09699
2514.41	5.75084
2517.17	6.30117
2519.93	7.35849
2522.68	7.68902
2525.44	7.51828
2528.19	7.13473
2530.95	6.60225
2533.7	6.06323
2536.45	6.65672
2539.2	6.47426
2541.95	5.75558
2544.7	6.48068
2547.45	6.42507
2550.2	6.01402
2552.94	5.01341
2555.69	5.83712
2558.43	6.85265
2561.17	7.36799
2563.92	7.33199
2566.66	7.53966
2569.4	8.73842
2572.14	9.11254
2574.88	9.53646
2577.61	9.84899
2580.35	10.29
2583.09	10.5799
2585.82	11.4057
2588.55	10.8051
2591.28	9.86796
2594.02	9.15969
2596.75	9.36213
2599.48	8.93199
2602.2	8.57948
2604.93	9.37347
2607.66	10.1528
2610.38	11.2913
2613.11	11.3563
2615.83	11.8553
2618.56	11.3202
2621.28	12.3112
2624	11.8844
2626.72	12.2017
2629.44	11.9338
2632.15	11.9296
2634.87	12.6134
2637.59	11.6577
2640.3	10.8369
2643.02	10.7327
2645.73	10.5841
2648.44	9.78681
2651.15	8.69342
2653.86	8.10553
2656.57	7.06077
2659.28	7.24011
2661.99	7.61584
2664.69	8.20124
2667.4	8.7066
2670.1	9.89115
2672.81	10.391
2675.51	10.7802
2678.21	11.0376
2680.91	10.3619
2683.61	9.75707
2686.31	10.3
2689	10.4495
2691.7	10.2371
2694.4	10.7257
2697.09	11.7776
2699.79	12.2188
2702.48	11.6396
2705.17	12.9597
2707.86	14.1886
2710.55	15.1074
2713.24	15.5336
2715.93	16.8114
2718.61	17.5482
2721.3	18.6193
2723.99	20.2243
2726.67	21.7801
2729.35	23.3631
2732.04	23.405
2734.72	23.2863
2737.4	22.4313
2740.08	21.1522
2742.76	21.2695
2745.43	20.5687
2748.11	18.7948
2750.79	16.5347
2753.46	15.2574
2756.13	13.3598
2758.81	11.7123
2761.48	9.34612
2764.15	6.91908
2766.82	5.29203
2769.49	4.07806
2772.16	2.54759
2774.82	1.45824
2777.49	0.458266
2780.16	-0.610629
2782.82	-1.30442
2785.48	-1.92806
2788.15	-1.06286
2790.81	-1.33479
2793.47	-1.38565
2796.13	-1.7945
2798.79	-1.60503
2801.44	-2.19681
2804.1	-1.01686
2806.76	-0.392688
2809.41	0.410668
2812.07	0.564978
2814.72	1.94614
2817.37	5.22159
2820.02	9.21102
2822.67	13.4333
2825.32	18.6308
2827.97	24.1668
2830.62	31.6926
2833.26	38.1455
2835.91	45.6463
2838.55	55.6169
2841.2	69.1358
2843.84	84.5724
2846.48	101.119
2849.12	121.034
2851.76	141.63
2854.4	163.911
2857.04	185.092
2859.68	206.137
2862.32	226.933
2864.95	247.214
2867.58	266.581
2870.22	284.88
2872.85	300.046
2875.48	314.585
2878.11	327.702
2880.74	338.369
2883.37	348.655
2886	358.334
2888.63	366.776
2891.25	376.95
2893.88	387.158
2896.5	397.305
2899.13	408.293
2901.75	423.281
2904.37	442.701
2906.99	464.978
2909.61	489.254
2912.23	514.829
2914.85	542.167
2917.46	568.209
2920.08	592.957
2922.7	612.377
2925.31	628.115
2927.92	640.757
2930.53	646.957
2933.15	648.459
2935.76	643.183
2938.37	634.547
2940.98	620.503
2943.58	603.575
2946.19	584.294
2948.8	562.744
2951.4	540.249
2954.01	515.506
2956.61	490.941
2959.21	464.87
2961.81	438.375
2964.41	413.528
2967.01	390.786
2969.61	370.393
2972.21	351.651
2974.81	333.18
2977.4	314.387
2980	295.021
2982.59	275.698
2985.18	254.287
2987.78	231.93
2990.37	210.316
2992.96	188.251
2995.55	165.261
2998.14	144.249
3000.72	123.874
3003.31	105.604
3005.9	88.3056
3008.48	73.9999
3011.07	59.3334
3013.65	47.6132
3016.23	37.2323
3018.81	28.0006
3021.39	21.6683
3023.97	16.3683
3026.55	12.5584
3029.13	9.81816
3031.71	7.80305
3034.28	8.09118
3036.86	9.28185
3039.43	11.0185
3042.01	12.96
3044.58	15.2912
3047.15	17.1372
3049.72	19.2239
3052.29	21.2846
3054.86	21.793
3057.43	21.0779
3060	21.2014
3062.56	20.652
3065.13	20.7036
3067.69	20.1973
3070.25	19.1622
3072.82	17.6225
3075.38	15.8818
3077.94	13.9927
3080.5	10.49
3083.06	7.88594
3085.62	5.70225
3088.17	3.49008
3090.73	1.24518
3093.29	0.854893
3095.84	0.456769
3098.4	2.08254
3100.95	3.39258
3103.5	4.05105
3106.05	4.90199
3108.6	6.2211
3111.15	7.77489
3113.7	9.0864
3116.25	11.4018
3118.79	13.4968
3121.34	16.23
3123.88	19.2345
3126.43	22.1118
3128.97	25.5449
3131.51	29.1731
3134.05	32.1409
3136.59	35.5207
3139.14	38.1197
3141.67	41.3458
3144.21	45.1637
3146.75	50.0189
3149.28	56.0947