File: data/Raman/poly_smoothed/Mb_10_14_33_1x_45s_532 nm_x100_100%_600 gr_mm_01.txt
#Acq. time (s)=	45
#Accumulations=	2
#Range (cm-¹)=	200...3150
#Windows=	2
#Auto scanning=	Off
#Autofocus=	Off
#Macrospot=	Off
#AutoExposure=	Off
#Spike filter=	Multiple accum.
#Delay time (s)=	0
#Binning=	1
#Readout mode=	Signal
#DeNoise=	Off
#ICS correction=	On
#Dark correction=	Off
#Inst. Process=	Off
#Detector Gain=	Best Dynamic Range
#Detector ADC=	20 kHz
#Detector temperature (°C)=	-69.85
#Instrument=	LabRAM HR Evol
#Detector=	Synapse
#Objective=	x100
#Grating=	600 gr/mm
#ND Filter=	100%
#Laser (nm)=	532
#Hole=	100.021
#Range=	Auto
#Laser Pol.=	No
#Raman. Pol.=	No
#Laser Pol. (°)=	-0.0007625
#Raman Pol. (°)=	89.9995
#Collection=	Microscope
#StageXY=	Marzhauser
#StageZ=	Marzhauser
#X (µm)=	-612.7
#Y (µm)=	-1585.3
#Z (µm)=	90
#Full time(mm:ss)=	3:18
#Project=
#Sample=
#Site=
#Title=	Mb_10_14_33_2x_45s_532 nm_x100_100%_600 gr_mm
#Remark=
#Date=	11.07.2022 10:58
#Acquired=	11.07.2022 10:58:46
#Base:Fit=	10.08.2022 10:21:11
#Base:Sub=	10.08.2022 10:21:41
#Filter:Polynom=	16.08.2022 10:17:53
#AxisType[0]=Intens
#AxisUnit[0]=Cnt
#AxisType[1]=Spectr
#AxisUnit[1]=1/cm
200.388	9.32146
204.019	8.11203
207.646	8.26646
211.274	8.61026
214.899	8.02518
218.524	6.49248
222.146	8.31815
225.766	10.1605
229.388	10.2799
233.005	11.6004
236.621	12.6279
240.236	14.0277
243.852	14.3835
247.464	15.6084
251.074	14.8888
254.683	15.1743
258.291	16.2844
261.897	17.4242
265.504	18.6867
269.108	21.2922
272.71	22.2704
276.311	23.4132
279.91	23.1976
283.508	22.0848
287.105	22.9954
290.698	23.5562
294.291	24.6276
297.884	24.4116
301.475	23.8765
305.064	24.6227
308.652	27.1601
312.237	28.3928
315.822	29.6164
319.406	30.4114
322.987	31.1243
326.568	31.2056
330.148	30.971
333.724	31.0368
337.301	30.2563
340.875	28.2196
344.449	26.5124
348.02	26.3356
351.592	27.091
355.16	28.1487
358.728	27.3375
362.294	25.5509
365.858	25.3749
369.422	24.7174
372.983	24.7162
376.543	25.1392
380.102	24.3381
383.661	25.5786
387.216	26.3243
390.771	26.1927
394.324	27.558
397.875	27.0026
401.425	25.6716
404.974	25.3655
408.524	24.5537
412.07	24.1493
415.614	23.5518
419.156	22.3433
422.698	22.9356
426.238	22.8232
429.777	20.7832
433.315	19.7084
436.852	18.5923
440.387	17.45
443.919	14.8111
447.451	12.5468
450.982	11.1299
454.512	10.5006
458.038	10.8468
461.565	11.6513
465.091	12.4208
468.613	14.2073
472.136	15.3584
475.655	15.1743
479.176	15.0833
482.692	16.3616
486.21	19.1525
489.724	20.525
493.237	22.4697
496.75	25.3161
500.26	27.5349
503.769	30.0768
507.279	31.7449
510.785	31.6948
514.289	30.797
517.793	30.7092
521.297	30.1742
524.797	28.5087
528.297	26.8416
531.795	25.9794
535.291	23.721
538.787	23.0216
542.281	21.8447
545.773	21.3417
549.264	20.3994
552.754	18.1497
556.243	14.7599
559.73	13.6945
563.216	12.7251
566.701	12.0189
570.182	11.9671
573.664	9.30137
577.145	7.69336
580.624	7.15744
584.1	6.31702
587.577	6.57406
591.052	4.90338
594.524	4.54437
597.997	4.49474
601.466	5.59874
604.936	5.89393
608.403	6.40689
611.87	6.26679
615.334	7.64136
618.799	8.09799
622.26	9.40999
625.72	11.8666
629.181	12.3641
632.638	13.7857
636.095	14.6812
639.551	14.6179
643.005	16.5766
646.457	17.6592
649.908	17.8091
653.357	17.191
656.806	17.434
660.253	18.1131
663.7	18.7717
667.145	19.576
670.588	20.5163
674.027	21.6103
677.468	20.9504
680.907	21.615
684.345	21.9525
687.781	21.8987
691.216	22.7708
694.65	23.4629
698.081	25.5895
701.512	27.4389
704.942	28.7392
708.371	30.9957
711.796	31.4914
715.222	33.604
718.645	35.7229
722.068	36.6503
725.49	36.7151
728.909	37.3627
732.329	38.872
735.745	40.54
739.16	41.6966
742.576	43.2634
745.988	45.4202
749.401	47.4937
752.811	50.5239
756.22	52.1881
759.627	54.293
763.035	57.1098
766.44	59.728
769.843	62.2822
773.245	63.8912
776.646	66.988
780.046	69.1598
783.444	71.6035
786.841	73.3321
790.237	72.5532
793.631	73.4815
797.024	74.2579
800.416	74.4374
803.807	74.5115
807.196	73.6565
810.584	72.827
813.971	72.3309
817.354	71.4194
820.739	70.5676
824.122	70.4541
827.503	69.7155
830.882	68.7835
834.261	67.8156
837.637	67.1921
841.013	66.6912
844.389	67.3419
847.761	65.2622
851.131	62.1543
854.503	60.6479
857.871	60.1275
861.24	58.9817
864.606	57.0053
867.97	54.5228
871.336	50.5954
874.698	49.7165
878.058	49.5765
881.418	47.7648
884.778	46.5233
888.135	43.9336
891.49	42.3494
894.845	42.5251
898.198	40.3328
901.55	40.4244
904.901	39.4093
908.25	38.3833
911.598	38.2319
914.945	37.2321
918.291	37.4374
921.635	36.351
924.978	36.1817
928.318	36.348
931.659	36.0834
934.998	36.7972
938.336	36.9808
941.671	38.7571
945.007	38.8654
948.339	38.4996
951.672	36.6585
955.004	37.4156
958.333	37.976
961.662	37.8595
964.989	36.5595
968.315	36.9181
971.639	37.342
974.962	37.2218
978.285	37.3135
981.605	36.6455
984.924	36.8864
988.243	33.812
991.56	33.1297
994.875	32.0727
998.188	30.2854
1001.5	27.6058
1004.81	26.4685
1008.12	25.152
1011.43	24.9461
1014.74	23.4449
1018.05	23.1411
1021.35	22.6978
1024.65	24.1469
1027.96	22.715
1031.26	21.7733
1034.56	21.2562
1037.86	21.7281
1041.16	22.291
1044.45	22.8655
1047.75	24.2077
1051.04	25.2797
1054.33	25.8766
1057.62	25.4266
1060.91	25.7568
1064.2	23.7579
1067.49	22.7779
1070.77	21.0757
1074.06	19.9673
1077.34	18.0213
1080.62	15.8999
1083.91	13.2554
1087.18	11.2676
1090.46	9.81705
1093.74	8.80168
1097.02	8.69199
1100.29	8.4598
1103.56	9.47471
1106.84	9.08876
1110.11	8.02909
1113.38	7.8511
1116.64	7.46187
1119.91	7.94043
1123.18	8.69897
1126.44	9.27479
1129.7	9.48864
1132.97	10.0851
1136.23	9.23549
1139.49	8.07828
1142.74	8.8506
1146	9.51849
1149.26	8.99298
1152.51	6.73054
1155.76	6.51328
1159.01	5.47547
1162.27	4.15916
1165.51	2.23599
1168.76	1.78237
1172.01	1.94988
1175.25	2.72934
1178.5	5.09619
1181.74	4.81424
1184.98	4.13041
1188.22	4.15484
1191.46	5.75129
1194.7	4.79785
1197.94	4.9497
1201.17	5.31325
1204.41	5.336
1207.64	5.35409
1210.87	5.31411
1214.1	5.07248
1217.33	7.11573
1220.56	9.44707
1223.79	11.2164
1227.01	12.2264
1230.23	13.3478
1233.46	13.9979
1236.68	15.6516
1239.9	16.5531
1243.12	17.6523
1246.34	20.4611
1249.55	22.5742
1252.77	25.0785
1255.98	26.2193
1259.2	26.5912
1262.41	26.8223
1265.62	27.0557
1268.83	27.2607
1272.03	26.05
1275.24	26.9391
1278.45	26.9327
1281.65	26.9606
1284.85	28.3966
1288.06	29.4179
1291.26	30.4268
1294.46	31.3945
1297.66	31.4383
1300.85	32.6308
1304.05	34.0564
1307.24	33.9897
1310.43	34.2785
1313.63	34.7718
1316.82	37.5747
1320.01	38.2477
1323.2	38.5755
1326.38	38.8457
1329.57	38.6203
1332.76	37.7657
1335.94	36.3677
1339.12	36.528
1342.3	35.1045
1345.48	34.0312
1348.66	34.282
1351.84	33.6341
1355.01	33.2296
1358.19	32.0184
1361.36	31.3408
1364.53	30.8915
1367.71	30.0409
1370.88	29.7768
1374.04	29.1117
1377.21	29.2415
1380.38	29.729
1383.54	29.3436
1386.71	27.149
1389.87	27.7419
1393.03	29.6389
1396.19	28.8792
1399.35	26.2491
1402.51	26.2403
1405.67	26.5621
1408.82	26.6799
1411.98	27.0434
1415.13	27.74
1418.28	28.7722
1421.43	29.5498
1424.58	32.0164
1427.73	33.4359
1430.88	34.6252
1434.02	35.8337
1437.17	37.8979
1440.31	39.2715
1443.45	41.1221
1446.6	42.3647
1449.74	43.5363
1452.87	43.7855
1456.01	44.5111
1459.15	42.7639
1462.28	41.8725
1465.42	40.8173
1468.55	38.0316
1471.68	36.499
1474.81	33.4944
1477.94	32.3481
1481.07	30.5465
1484.2	27.7334
1487.32	25.5375
1490.45	22.48
1493.57	19.5578
1496.69	18.862
1499.81	18.6322
1502.93	16.96
1506.05	15.2499
1509.17	13.8042
1512.28	12.0412
1515.4	10.969
1518.51	11.0359
1521.63	11.6509
1524.74	10.4819
1527.85	9.38325
1530.96	8.37309
1534.06	8.09018
1537.17	9.67888
1540.28	10.3402
1543.38	12.0247
1546.48	12.9613
1549.59	15.0172
1552.69	15.3341
1555.79	15.862
1558.88	16.1326
1561.98	17.2952
1565.08	17.9385
1568.17	20.6755
1571.27	22.4295
1574.36	24.1858
1577.45	24.3641
1580.54	25.1791
1583.63	25.4095
1586.72	25.0834
1589.8	26.0072
1592.89	26.5738
1595.97	26.7282
1599.06	25.7554
1602.14	24.3329
1605.22	23.2466
1608.3	23.8101
1611.38	24.571
1614.46	24.5632
1617.53	24.431
1620.61	24.1167
1623.68	23.833
1626.75	23.199
1629.82	23.0609
1632.9	24.337
1635.96	24.991
1639.03	26.6565
1642.1	27.8691
1645.16	28.6943
1648.23	28.7809
1651.29	28.5557
1654.36	27.3806
1657.42	28.9668
1660.48	28.9965
1663.53	30.4624
1666.59	29.9778
1669.65	30.0914
1672.7	27.5264
1675.76	26.4022
1678.81	25.5291
1681.86	24.6988
1684.91	24.1266
1687.96	22.1897
1691.01	19.6551
1694.06	17.1402
1697.11	15.4246
1700.15	13.6595
1703.2	11.8658
1706.24	10.5161
1709.28	9.31072
1712.32	6.72359
1715.36	6.0587
1718.4	5.65461
1721.43	4.78892
1724.47	3.11984
1727.5	3.06949
1730.54	3.15766
1733.57	3.15357
1736.6	2.77998
1739.63	2.78016
1742.66	2.48796
1745.69	1.40383
1748.72	2.04724
1751.74	3.00506
1754.77	3.53271
1757.79	4.44619
1760.81	4.59099
1763.83	4.30626
1766.85	4.35066
1769.87	4.31289
1772.89	5.16137
1775.91	5.11359
1778.92	5.4791
1781.94	5.112
1784.95	5.51009
1787.96	6.18073
1790.97	6.20501
1793.98	5.86608
1796.99	5.69198
1800	4.98084
1803	4.27308
1806.01	3.74969
1809.01	3.67469
1812.02	3.91398
1815.02	3.92622
1818.02	3.05834
1821.02	2.4004
1824.02	2.88339
1827.01	2.67022
1830.01	3.1302
1833	3.17245
1836	2.40414
1838.99	1.1122
1841.98	0.77477
1844.97	0.957813
1847.96	0.824628
1850.95	0.57269
1853.94	0.364458
1856.92	0.694468
1859.91	0.874143
1862.89	0.968515
1865.88	1.89884
1868.86	2.77945
1871.84	3.54932
1874.82	4.00003
1877.8	5.22426
1880.77	5.9016
1882.52	6.36505
1885.51	6.94927
1888.5	6.73613
1891.49	6.57546
1894.47	6.43245
1897.46	6.46751
1900.44	6.28946
1903.42	5.7694
1906.4	4.11387
1909.38	2.3742
1912.36	2.22423
1915.34	1.45782
1918.32	0.752034
1921.29	0.422924
1924.27	1.18788
1927.24	1.39724
1930.21	0.841115
1933.18	0.96447
1936.15	1.87673
1939.12	2.90216
1942.09	3.13379
1945.06	3.51828
1948.02	3.06578
1950.99	2.95912
1953.95	2.7739
1956.91	3.75204
1959.87	4.72574
1962.84	5.7033
1965.79	6.72835
1968.75	6.93799
1971.71	6.81277
1974.66	6.51667
1977.62	6.88447
1980.57	6.04127
1983.53	6.69443
1986.48	7.10162
1989.43	8.07023
1992.38	7.72096
1995.33	7.55454
1998.27	7.40886
2001.22	6.75799
2004.16	6.21967
2007.11	5.59552
2010.05	5.42754
2012.99	4.63444
2015.93	5.81383
2018.87	4.84232
2021.81	4.49449
2024.75	5.09767
2027.69	5.20769
2030.62	5.88077
2033.56	6.06785
2036.49	5.9748
2039.42	4.95763
2042.35	5.35828
2045.28	5.6662
2048.21	5.99182
2051.14	6.30823
2054.06	7.18555
2056.99	6.59054
2059.92	7.30282
2062.84	6.62848
2065.76	5.8823
2068.68	6.28247
2071.6	5.74639
2074.52	5.81413
2077.44	5.80652
2080.36	6.84048
2083.27	7.50836
2086.19	8.46397
2089.1	8.42592
2092.01	8.93682
2094.93	8.09601
2097.84	7.97556
2100.75	7.77867
2103.66	7.90448
2106.56	8.1722
2109.47	8.71337
2112.37	8.86211
2115.28	9.07525
2118.18	8.82074
2121.09	9.03426
2123.99	9.42445
2126.89	8.87621
2129.79	9.13583
2132.68	9.81699
2135.58	10.2171
2138.48	9.99201
2141.37	9.30999
2144.26	10.9679
2147.16	11.9377
2150.05	12.2812
2152.94	12.7303
2155.83	13.5253
2158.72	14.1813
2161.6	14.731
2164.49	15.155
2167.38	14.4645
2170.26	14.6589
2173.14	14.9354
2176.03	14.7315
2178.91	14.5972
2181.79	14.4262
2184.67	14.4206
2187.54	14.5087
2190.42	15.2849
2193.3	15.0191
2196.17	13.9854
2199.05	12.8235
2201.92	12.4584
2204.79	11.8213
2207.66	11.0908
2210.53	10.2808
2213.4	11.0422
2216.27	10.5518
2219.13	9.93615
2222	9.42448
2224.86	9.61442
2227.72	9.39981
2230.59	8.97764
2233.45	9.47059
2236.31	8.72715
2239.17	8.62287
2242.03	8.98299
2244.88	8.95894
2247.74	8.98534
2250.59	9.42751
2253.45	10.1235
2256.3	10.442
2259.15	9.23701
2262	8.48564
2264.85	7.21533
2267.7	6.59183
2270.55	6.28952
2273.4	7.12636
2276.24	6.79197
2279.09	6.5879
2281.93	6.24099
2284.77	6.28658
2287.61	5.75986
2290.46	5.14189
2293.29	3.50353
2296.13	4.15283
2298.97	4.8748
2301.81	4.52015
2304.64	6.06962
2307.48	5.79293
2310.31	6.17354
2313.14	5.76517
2315.97	5.91671
2318.8	6.12636
2321.63	6.45712
2324.46	7.08634
2327.29	6.37012
2330.12	6.02771
2332.94	6.66793
2335.76	6.34621
2338.59	6.85932
2341.41	7.40648
2344.23	7.27225
2347.05	6.78266
2349.87	6.40521
2352.69	5.55956
2355.5	4.758
2358.32	4.11342
2361.14	2.57495
2363.95	2.53571
2366.76	3.41232
2369.58	3.32053
2372.39	3.52777
2375.2	3.11275
2378	1.89347
2380.81	2.11215
2383.62	1.92727
2386.42	1.9231
2389.23	3.24131
2392.03	3.97105
2394.84	3.96557
2397.64	3.82765
2400.44	2.65799
2403.24	2.34282
2406.04	1.63085
2408.83	2.3791
2411.63	2.2916
2414.43	2.21434
2417.22	2.34723
2420.02	1.80841
2422.81	1.76637
2425.6	1.96029
2428.39	0.995722
2431.18	1.34357
2433.97	1.69989
2436.76	1.71012
2439.54	0.793051
2442.33	1.0899
2445.11	0.92335
2447.9	1.96445
2450.68	2.18042
2453.46	2.19847
2456.24	2.80704
2459.02	3.52418
2461.8	3.312
2464.58	2.25063
2467.36	1.88158
2470.13	2.96144
2472.91	2.97845
2475.68	2.81476
2478.45	3.20906
2481.22	3.772
2484	3.16181
2486.77	3.19007
2489.54	3.10435
2492.3	2.71754
2495.07	2.46326
2497.84	2.85576
2500.6	2.59567
2503.36	2.71409
2506.13	1.95765
2508.89	2.19699
2511.65	1.83721
2514.41	1.75625
2517.17	2.05426
2519.93	1.54139
2522.68	1.9053
2525.44	2.39492
2528.19	2.35193
2530.95	1.9604
2533.7	2.52486
2536.45	3.64684
2539.2	3.38324
2541.95	2.76988
2544.7	2.81802
2547.45	3.28565
2550.2	3.62264
2552.94	3.32467
2555.69	4.20109
2558.43	4.92325
2561.17	5.60104
2563.92	5.8854
2566.66	6.05597
2569.4	6.1664
2572.14	6.38956
2574.88	6.77904
2577.61	6.76914
2580.35	6.30072
2583.09	6.59308
2585.82	6.59296
2588.55	5.24736
2591.28	5.54712
2594.02	5.10619
2596.75	4.24616
2599.48	4.72166
2602.2	4.33651
2604.93	3.30487
2607.66	3.07801
2610.38	2.75184
2613.11	3.28954
2615.83	4.27668
2618.56	4.831
2621.28	5.48263
2624	5.26325
2626.72	4.65182
2629.44	4.3917
2632.15	4.22545
2634.87	4.2547
2637.59	4.09517
2640.3	2.89222
2643.02	2.02484
2645.73	1.78811
2648.44	1.74687
2651.15	2.82007
2653.86	2.36016
2656.57	3.07092
2659.28	3.62455
2661.99	3.73654
2664.69	4.12121
2667.4	4.50827
2670.1	4.45767
2672.81	5.18355
2675.51	4.92781
2678.21	5.13353
2680.91	6.40658
2683.61	7.35795
2686.31	7.93971
2689	7.48623
2691.7	7.36924
2694.4	6.33486
2697.09	6.55811
2699.79	5.055
2702.48	4.55141
2705.17	3.87082
2707.86	4.23541
2710.55	5.20385
2713.24	6.63766
2715.93	7.62096
2718.61	8.30943
2721.3	9.37366
2723.99	10.0471
2726.67	10.1522
2729.35	10.5384
2732.04	10.3806
2734.72	10.3667
2737.4	10.0373
2740.08	9.73328
2742.76	8.78612
2745.43	9.31829
2748.11	10.355
2750.79	10.3218
2753.46	8.58484
2756.13	8.01562
2758.81	7.1798
2761.48	5.90064
2764.15	5.41727
2766.82	4.66237
2769.49	4.29401
2772.16	4.15486
2774.82	4.9768
2777.49	4.74503
2780.16	4.74957
2782.82	4.84287
2785.48	4.62296
2788.15	5.08616
2790.81	4.67822
2793.47	4.87823
2796.13	4.42912
2798.79	4.0907
2801.44	4.70629
2804.1	4.74325
2806.76	4.07537
2809.41	4.24182
2812.07	4.13951
2814.72	4.62599
2817.37	4.39728
2820.02	4.20375
2822.67	5.41065
2825.32	5.6606
2827.97	6.02603
2830.62	7.72186
2833.26	9.33688
2835.91	10.8874
2838.55	13.0458
2841.2	15.0711
2843.84	17.7809
2846.48	21.0336
2849.12	23.2777
2851.76	25.9969
2854.4	30.524
2857.04	34.1945
2859.68	38.1492
2862.32	41.1607
2864.95	44.9346
2867.58	48.8394
2870.22	52.1693
2872.85	54.6089
2875.48	57.1093
2878.11	58.9955
2880.74	60.6692
2883.37	61.7321
2886	62.1507
2888.63	63.5521
2891.25	63.5761
2893.88	64.7025
2896.5	66.5995
2899.13	66.9851
2901.75	67.9559
2904.37	69.499
2906.99	72.5147
2909.61	75.6129
2912.23	78.3183
2914.85	81.3436
2917.46	84.5398
2920.08	88.4516
2922.7	90.5922
2925.31	92.9825
2927.92	94.4956
2930.53	97.1659
2933.15	97.5567
2935.76	96.789
2938.37	95.9373
2940.98	94.7698
2943.58	92.0368
2946.19	88.3873
2948.8	84.9895
2951.4	81.5831
2954.01	77.6832
2956.61	73.9035
2959.21	70.494
2961.81	65.4133
2964.41	61.8462
2967.01	58.7452
2969.61	54.2652
2972.21	51.1127
2974.81	48.5213
2977.4	45.1961
2980	42.4659
2982.59	39.6703
2985.18	37.5552
2987.78	34.0001
2990.37	31.5366
2992.96	28.1694
2995.55	25.3562
2998.14	21.9169
3000.72	19.0309
3003.31	16.3456
3005.9	13.438
3008.48	11.3156
3011.07	9.23478
3013.65	8.22466
3016.23	6.27875
3018.81	4.81902
3021.39	3.29639
3023.97	1.81701
3026.55	0.480587
3029.13	-0.0525674
3031.71	-0.849745
3034.28	-0.971772
3036.86	0.188958
3039.43	1.05481
3042.01	1.66003
3044.58	2.35711
3047.15	3.99682
3049.72	4.66696
3052.29	4.867
3054.86	5.74622
3057.43	5.51325
3060	5.83403
3062.56	5.79893
3065.13	5.6224
3067.69	5.98664
3070.25	6.3864
3072.82	6.04224
3075.38	5.10956
3077.94	4.82798
3080.5	3.93187
3083.06	3.13723
3085.62	2.13458
3088.17	1.92998
3090.73	1.15846
3093.29	1.80019
3095.84	1.89069
3098.4	1.77261
3100.95	1.79878
3103.5	1.76015
3106.05	1.6432
3108.6	2.1271
3111.15	2.27584
3113.7	2.59243
3116.25	3.31092
3118.79	3.61682
3121.34	4.21267
3123.88	4.34336
3126.43	4.95271
3128.97	5.28872
3131.51	5.76098
3134.05	5.69241
3136.59	5.34109
3139.14	5.96946
3141.67	6.80551
3144.21	7.49655
3146.75	7.88217
3149.28	7.07412