File: data/Raman/poly_smoothed/Mb_10_14_39_1x_45s_532 nm_x100_100%_600 gr_mm_01.txt
#Acq. time (s)=	45
#Accumulations=	2
#Range (cm-¹)=	200...3150
#Windows=	2
#Auto scanning=	Off
#Autofocus=	Off
#Macrospot=	Off
#AutoExposure=	Off
#Spike filter=	Multiple accum.
#Delay time (s)=	0
#Binning=	1
#Readout mode=	Signal
#DeNoise=	Off
#ICS correction=	On
#Dark correction=	Off
#Inst. Process=	Off
#Detector Gain=	Best Dynamic Range
#Detector ADC=	20 kHz
#Detector temperature (°C)=	-69.85
#Instrument=	LabRAM HR Evol
#Detector=	Synapse
#Objective=	x100
#Grating=	600 gr/mm
#ND Filter=	100%
#Laser (nm)=	532
#Hole=	100.021
#Range=	Auto
#Laser Pol.=	No
#Raman. Pol.=	No
#Laser Pol. (°)=	-0.0007625
#Raman Pol. (°)=	89.9995
#Collection=	Microscope
#StageXY=	Marzhauser
#StageZ=	Marzhauser
#X (µm)=	-625.8
#Y (µm)=	-1676.9
#Z (µm)=	89.25
#Full time(mm:ss)=	3:07
#Project=
#Sample=
#Site=
#Title=	Mb_10_14_39_2x_45s_532 nm_x100_100%_600 gr_mm
#Remark=
#Date=	11.07.2022 11:31
#Acquired=	11.07.2022 11:31:12
#Base:Fit=	10.08.2022 10:21:11
#Base:Sub=	10.08.2022 10:21:41
#Filter:Polynom=	16.08.2022 10:17:53
#AxisType[0]=Intens
#AxisUnit[0]=Cnt
#AxisType[1]=Spectr
#AxisUnit[1]=1/cm
200.388	12.4184
204.019	8.32061
207.646	5.706
211.274	3.07781
214.899	2.89545
218.524	3.52033
222.146	4.78062
225.766	5.97527
229.388	6.68427
233.005	9.11669
236.621	10.0225
240.236	9.65437
243.852	9.18244
247.464	8.58792
251.074	9.33985
254.683	9.04869
258.291	12.3735
261.897	13.4771
265.504	12.4592
269.108	12.0136
272.71	11.6615
276.311	10.9526
279.91	10.2218
283.508	9.06384
287.105	8.04838
290.698	7.24982
294.291	7.88961
297.884	5.80448
301.475	6.18708
305.064	6.46998
308.652	7.12323
312.237	6.87216
315.822	7.01849
319.406	7.35384
322.987	5.66817
326.568	3.78165
330.148	4.34903
333.724	3.69714
337.301	3.52958
340.875	3.49578
344.449	5.07296
348.02	5.57306
351.592	5.83557
355.16	5.99209
358.728	7.70709
362.294	8.95789
365.858	10.0942
369.422	9.49185
372.983	9.81002
376.543	9.70763
380.102	10.9516
383.661	11.456
387.216	11.8352
390.771	13.3101
394.324	13.4438
397.875	13.1001
401.425	12.6028
404.974	12.8145
408.524	11.8279
412.07	10.1148
415.614	10.924
419.156	10.208
422.698	6.58594
426.238	5.25524
429.777	4.55646
433.315	4.53811
436.852	4.15878
440.387	3.5453
443.919	2.06069
447.451	0.81586
450.982	1.37682
454.512	1.70184
458.038	2.51402
461.565	4.57192
465.091	4.55179
468.613	5.94187
472.136	6.47171
475.655	7.56879
479.176	9.49408
482.692	10.3378
486.21	11.6374
489.724	14.0052
493.237	15.1528
496.75	15.124
500.26	16.7573
503.769	17.851
507.279	16.922
510.785	16.5225
514.289	17.3822
517.793	17.4566
521.297	15.4504
524.797	15.5395
528.297	14.1293
531.795	14.1019
535.291	13.7742
538.787	13.0736
542.281	11.9083
545.773	10.4184
549.264	9.38233
552.754	7.21547
556.243	6.87076
559.73	6.56517
563.216	6.60488
566.701	8.04794
570.182	6.52211
573.664	7.0214
577.145	7.08475
580.624	5.8419
584.1	6.39658
587.577	6.52517
591.052	4.68876
594.524	4.19231
597.997	5.50564
601.466	5.07571
604.936	5.73688
608.403	6.79946
611.87	7.37016
615.334	7.77064
618.799	7.08914
622.26	8.31889
625.72	8.18879
629.181	11.4008
632.638	14.431
636.095	15.5615
639.551	16.6724
643.005	19.412
646.457	21.6003
649.908	23.6847
653.357	23.8581
656.806	24.659
660.253	25.6905
663.7	25.6626
667.145	26.6653
670.588	27.1298
674.027	27.2023
677.468	27.2106
680.907	28.9961
684.345	29.7593
687.781	30.849
691.216	31.8832
694.65	30.3418
698.081	31.2601
701.512	31.766
704.942	32.4719
708.371	34.4006
711.796	35.486
715.222	37.0134
718.645	36.7074
722.068	37.4492
725.49	39.7445
728.909	42.3269
732.329	43.1003
735.745	42.9842
739.16	46.596
742.576	47.8541
745.988	49.0655
749.401	50.7318
752.811	51.4792
756.22	53.7017
759.627	55.4697
763.035	58.1457
766.44	59.568
769.843	60.6704
773.245	61.8084
776.646	63.0783
780.046	65.1012
783.444	67.7277
786.841	69.6744
790.237	72.1124
793.631	74.751
797.024	75.5813
800.416	77.2142
803.807	79.3632
807.196	81.6484
810.584	83.7957
813.971	83.7703
817.354	84.4758
820.739	84.77
824.122	84.5488
827.503	83.2426
830.882	82.4071
834.261	80.1509
837.637	79.2117
841.013	77.1852
844.389	76.3848
847.761	74.3573
851.131	69.9471
854.503	68.2197
857.871	66.0391
861.24	65.0666
864.606	62.8456
867.97	60.989
871.336	59.9894
874.698	60.4555
878.058	58.9266
881.418	57.0328
884.778	57.5533
888.135	57.5308
891.49	57.4637
894.845	55.845
898.198	56.7263
901.55	56.0736
904.901	56.7957
908.25	56.7965
911.598	57.138
914.945	56.1437
918.291	55.3841
921.635	55.6411
924.978	55.5038
928.318	57.1172
931.659	55.3879
934.998	53.2922
938.336	53.1431
941.671	52.4942
945.007	50.6507
948.339	49.1679
951.672	48.4222
955.004	46.6108
958.333	46.0228
961.662	41.8915
964.989	40.4762
968.315	40.5539
971.639	39.0462
974.962	37.6118
978.285	37.0582
981.605	36.3602
984.924	35.6866
988.243	35.1655
991.56	34.0487
994.875	34.1915
998.188	32.5346
1001.5	33.025
1004.81	34.547
1008.12	34.9843
1011.43	35.126
1014.74	34.8537
1018.05	36.4661
1021.35	38.2899
1024.65	37.9471
1027.96	39.8075
1031.26	40.6144
1034.56	40.9212
1037.86	39.7042
1041.16	37.8906
1044.45	37.5965
1047.75	38.2555
1051.04	36.7052
1054.33	34.6689
1057.62	33.6594
1060.91	32.1121
1064.2	31.0432
1067.49	28.6971
1070.77	27.1616
1074.06	24.4366
1077.34	21.4715
1080.62	17.6335
1083.91	15.7294
1087.18	15.1456
1090.46	15.3657
1093.74	15.3044
1097.02	15.0781
1100.29	15.0454
1103.56	15.7007
1106.84	15.6952
1110.11	15.2173
1113.38	14.9824
1116.64	14.9402
1119.91	13.2979
1123.18	13.282
1126.44	12.7392
1129.7	12.5845
1132.97	11.6558
1136.23	12.1461
1139.49	10.772
1142.74	10.2076
1146	9.90779
1149.26	8.8219
1152.51	7.69623
1155.76	5.408
1159.01	4.31899
1162.27	2.34061
1165.51	3.78952
1168.76	3.97686
1172.01	3.86852
1175.25	3.96918
1178.5	4.10053
1181.74	4.1434
1184.98	3.85896
1188.22	4.08237
1191.46	4.16198
1194.7	4.16577
1197.94	6.11189
1201.17	5.99381
1204.41	6.86336
1207.64	7.59165
1210.87	9.21757
1214.1	11.8625
1217.33	13.4187
1220.56	14.4177
1223.79	16.2212
1227.01	19.0712
1230.23	19.5924
1233.46	19.9245
1236.68	20.6417
1239.9	20.7909
1243.12	23.0168
1246.34	24.1189
1249.55	22.227
1252.77	21.3163
1255.98	22.1135
1259.2	20.2977
1262.41	18.8983
1265.62	17.8106
1268.83	17.0998
1272.03	15.2027
1275.24	15.4719
1278.45	15.928
1281.65	14.9689
1284.85	15.3879
1288.06	15.5572
1291.26	16.4206
1294.46	17.6003
1297.66	17.057
1300.85	19.0443
1304.05	21.253
1307.24	22.7872
1310.43	24.5594
1313.63	26.0452
1316.82	28.1067
1320.01	28.9851
1323.2	29.986
1326.38	29.3286
1329.57	29.274
1332.76	29.1931
1335.94	29.4938
1339.12	27.833
1342.3	26.0602
1345.48	25.1248
1348.66	24.6333
1351.84	22.3511
1355.01	21.1762
1358.19	19.9439
1361.36	17.4612
1364.53	15.1243
1367.71	14.8751
1370.88	13.5379
1374.04	12.9258
1377.21	13.4261
1380.38	13.9254
1383.54	14.1146
1386.71	15.0284
1389.87	15.3715
1393.03	15.2775
1396.19	14.919
1399.35	16.0877
1402.51	15.3978
1405.67	16.7124
1408.82	16.0527
1411.98	15.1265
1415.13	16.6139
1418.28	17.6474
1421.43	20.5187
1424.58	22.5651
1427.73	23.7131
1430.88	25.376
1434.02	28.2294
1437.17	31.1555
1440.31	33.8683
1443.45	37.3216
1446.6	38.451
1449.74	38.8683
1452.87	39.4606
1456.01	39.9387
1459.15	38.8543
1462.28	40.2215
1465.42	40.7844
1468.55	38.1317
1471.68	37.2032
1474.81	34.3779
1477.94	32.3744
1481.07	28.5381
1484.2	26.714
1487.32	24.2034
1490.45	22.8381
1493.57	21.5234
1496.69	18.9543
1499.81	17.1164
1502.93	14.6731
1506.05	13.7494
1509.17	12.3331
1512.28	11.1549
1515.4	9.2447
1518.51	7.67206
1521.63	6.29475
1524.74	3.79736
1527.85	3.58708
1530.96	2.17731
1534.06	2.18188
1537.17	1.41097
1540.28	2.66218
1543.38	2.49207
1546.48	1.95978
1549.59	1.80083
1552.69	1.35163
1555.79	2.30896
1558.88	3.71532
1561.98	5.37548
1565.08	6.9098
1568.17	7.52819
1571.27	9.2412
1574.36	12.2099
1577.45	13.3378
1580.54	15.8492
1583.63	18.445
1586.72	19.1205
1589.8	20.769
1592.89	22.7042
1595.97	25.0631
1599.06	26.7749
1602.14	25.3659
1605.22	24.7481
1608.3	23.2401
1611.38	23.1264
1614.46	23.8572
1617.53	23.407
1620.61	23.0191
1623.68	22.0836
1626.75	21.4731
1629.82	21.9182
1632.9	21.2008
1635.96	22.1458
1639.03	21.2364
1642.1	21.6433
1645.16	22.0685
1648.23	22.7855
1651.29	24.3665
1654.36	24.9941
1657.42	25.7816
1660.48	26.0504
1663.53	26.2449
1666.59	25.7457
1669.65	26.2911
1672.7	25.2323
1675.76	22.6818
1678.81	19.7898
1681.86	18.945
1684.91	19.5514
1687.96	17.4084
1691.01	14.0776
1694.06	11.9524
1697.11	9.81413
1700.15	9.00315
1703.2	7.65774
1706.24	6.60338
1709.28	4.49184
1712.32	4.03347
1715.36	3.2319
1718.4	2.17557
1721.43	2.07278
1724.47	1.69863
1727.5	1.79212
1730.54	2.69016
1733.57	2.15931
1736.6	1.66227
1739.63	1.52375
1742.66	1.08391
1745.69	1.81176
1748.72	1.85904
1751.74	2.12664
1754.77	2.78968
1757.79	2.92936
1760.81	2.30558
1763.83	1.58127
1766.85	0.84533
1769.87	0.841767
1772.89	1.77013
1775.91	2.08553
1778.92	1.2247
1781.94	1.23076
1784.95	1.06211
1787.96	1.37503
1790.97	1.70947
1793.98	2.75575
1796.99	2.69058
1800	3.02856
1803	3.71685
1806.01	3.63318
1809.01	3.70023
1812.02	4.08935
1815.02	5.48019
1818.02	5.68665
1821.02	6.38547
1824.02	7.50655
1827.01	8.09701
1830.01	7.61607
1833	7.89956
1836	7.54377
1838.99	6.70504
1841.98	5.62372
1844.97	5.95408
1847.96	5.35535
1850.95	4.40447
1853.94	3.30743
1856.92	2.64354
1859.91	1.66158
1862.89	0.584786
1865.88	0.646476
1868.86	1.20619
1871.84	1.59105
1874.82	1.90564
1877.8	2.92295
1880.77	3.64231
1882.52	4.72796
1885.51	5.56628
1888.5	6.24327
1891.49	6.55233
1894.47	8.32419
1897.46	9.59361
1900.44	9.88054
1903.42	11.4597
1906.4	12.5131
1909.38	12.2801
1912.36	13.0495
1915.34	14.2236
1918.32	13.828
1921.29	12.6129
1924.27	11.8337
1927.24	11.8317
1930.21	11.3444
1933.18	12.1328
1936.15	11.892
1939.12	13.3977
1942.09	13.0143
1945.06	14.1489
1948.02	13.6093
1950.99	14.3733
1953.95	15.1592
1956.91	14.9256
1959.87	14.7939
1962.84	15.2365
1965.79	14.9615
1968.75	15.2832
1971.71	14.2341
1974.66	13.4519
1977.62	12.619
1980.57	10.5618
1983.53	9.88157
1986.48	9.01566
1989.43	8.2121
1992.38	7.12807
1995.33	7.21928
1998.27	7.56745
2001.22	7.2393
2004.16	7.63583
2007.11	8.18064
2010.05	9.14629
2012.99	10.347
2015.93	11.2526
2018.87	12.639
2021.81	12.8009
2024.75	12.9042
2027.69	13.1576
2030.62	14.2029
2033.56	14.7805
2036.49	13.8801
2039.42	13.8828
2042.35	14.3667
2045.28	13.8148
2048.21	13.527
2051.14	14.6427
2054.06	15.3192
2056.99	16.8774
2059.92	16.9115
2062.84	18.2301
2065.76	20.1047
2068.68	19.884
2071.6	20.8199
2074.52	21.8205
2077.44	23.2419
2080.36	24.0568
2083.27	23.9247
2086.19	23.5667
2089.1	23.3361
2092.01	22.5025
2094.93	22.1654
2097.84	22.3966
2100.75	21.7929
2103.66	21.9135
2106.56	21.0041
2109.47	21.0353
2112.37	20.0931
2115.28	20.0073
2118.18	20.307
2121.09	20.871
2123.99	21.3934
2126.89	22.0143
2129.79	21.883
2132.68	22.438
2135.58	21.9606
2138.48	23.4287
2141.37	24.3873
2144.26	25.4521
2147.16	25.8779
2150.05	26.6142
2152.94	27.0495
2155.83	27.8395
2158.72	28.0054
2161.6	30.0489
2164.49	30.9404
2167.38	31.7712
2170.26	32.1336
2173.14	32.0258
2176.03	32.5773
2178.91	30.9227
2181.79	30.7133
2184.67	29.3273
2187.54	28.8798
2190.42	28.2718
2193.3	26.7751
2196.17	26.0408
2199.05	24.5936
2201.92	22.8948
2204.79	22.4518
2207.66	20.8754
2210.53	20.6589
2213.4	18.9949
2216.27	18.6186
2219.13	18.158
2222	18.7147
2224.86	18.9897
2227.72	20.3644
2230.59	21.7654
2233.45	21.9705
2236.31	21.8707
2239.17	20.8116
2242.03	19.4339
2244.88	19.9175
2247.74	18.7189
2250.59	18.3964
2253.45	18.2411
2256.3	17.4796
2259.15	16.7374
2262	17.189
2264.85	15.9261
2267.7	15.2452
2270.55	14.6051
2273.4	14.1292
2276.24	12.7151
2279.09	12.3478
2281.93	13.045
2284.77	14.4954
2287.61	16.0596
2290.46	18.3243
2293.29	18.7156
2296.13	19.2033
2298.97	20.0212
2301.81	21.5661
2304.64	21.8048
2307.48	22.3512
2310.31	22.5031
2313.14	22.7329
2315.97	22.4401
2318.8	22.1593
2321.63	22.6407
2324.46	22.1393
2327.29	20.8509
2330.12	20.6552
2332.94	19.432
2335.76	17.4146
2338.59	16.1756
2341.41	14.4009
2344.23	13.3367
2347.05	12.2407
2349.87	11.5267
2352.69	11.0571
2355.5	10.2761
2358.32	10.1906
2361.14	8.94309
2363.95	8.50665
2366.76	9.95102
2369.58	10.2789
2372.39	10.1894
2375.2	8.84704
2378	9.80101
2380.81	8.97948
2383.62	8.6678
2386.42	9.57036
2389.23	9.35486
2392.03	9.38222
2394.84	8.68837
2397.64	8.74386
2400.44	8.74679
2403.24	8.45876
2406.04	8.57408
2408.83	8.29934
2411.63	8.36097
2414.43	8.30385
2417.22	7.91802
2420.02	8.40849
2422.81	8.74862
2425.6	9.00297
2428.39	9.442
2431.18	9.45044
2433.97	9.23743
2436.76	8.4809
2439.54	7.88859
2442.33	7.22589
2445.11	7.18112
2447.9	7.05966
2450.68	5.97664
2453.46	5.7564
2456.24	6.04235
2459.02	4.84471
2461.8	3.98685
2464.58	3.44045
2467.36	3.35006
2470.13	2.3459
2472.91	2.79659
2475.68	2.6312
2478.45	3.00889
2481.22	3.18827
2484	3.24931
2486.77	3.46452
2489.54	2.97992
2492.3	4.1444
2495.07	2.99414
2497.84	1.93152
2500.6	2.25269
2503.36	2.11287
2506.13	2.09829
2508.89	2.36564
2511.65	1.34855
2514.41	1.10344
2517.17	1.74586
2519.93	2.71397
2522.68	3.5935
2525.44	3.81089
2528.19	3.46976
2530.95	3.00998
2533.7	3.30005
2536.45	3.35168
2539.2	4.49791
2541.95	4.13351
2544.7	4.92708
2547.45	5.91942
2550.2	5.08765
2552.94	5.33692
2555.69	5.23851
2558.43	4.64712
2561.17	4.19396
2563.92	3.15751
2566.66	3.20204
2569.4	3.8091
2572.14	2.67093
2574.88	2.03245
2577.61	1.73711
2580.35	0.83702
2583.09	1.89893
2585.82	2.26327
2588.55	2.06069
2591.28	1.73162
2594.02	1.68574
2596.75	1.37894
2599.48	0.31106
2602.2	0.764097
2604.93	0.632873
2607.66	0.76582
2610.38	2.15456
2613.11	3.02623
2615.83	2.41762
2618.56	2.65413
2621.28	3.18983
2624	3.63925
2626.72	3.37818
2629.44	4.00891
2632.15	4.59566
2634.87	5.36175
2637.59	6.43095
2640.3	6.41345
2643.02	6.61789
2645.73	6.87833
2648.44	7.06929
2651.15	6.39935
2653.86	4.83009
2656.57	4.98132
2659.28	6.75571
2661.99	6.35154
2664.69	6.44273
2667.4	6.84426
2670.1	7.31483
2672.81	6.66678
2675.51	6.93101
2678.21	6.29706
2680.91	7.1113
2683.61	7.4762
2686.31	7.09151
2689	7.12398
2691.7	6.14508
2694.4	5.588
2697.09	4.83732
2699.79	4.64421
2702.48	5.23459
2705.17	4.60222
2707.86	4.45866
2710.55	4.85301
2713.24	4.97599
2715.93	4.07809
2718.61	3.03499
2721.3	4.71786
2723.99	4.96644
2726.67	5.86489
2729.35	5.45399
2732.04	5.51358
2734.72	4.62656
2737.4	4.19078
2740.08	4.66313
2742.76	4.82075
2745.43	4.98546
2748.11	5.58941
2750.79	4.54324
2753.46	4.73413
2756.13	4.3463
2758.81	3.40196
2761.48	3.15278
2764.15	2.37973
2766.82	3.61143
2769.49	3.435
2772.16	2.61592
2774.82	3.48833
2777.49	3.7496
2780.16	2.54812
2782.82	1.90412
2785.48	2.47206
2788.15	2.68359
2790.81	2.32546
2793.47	2.40389
2796.13	1.47442
2798.79	1.52927
2801.44	1.56112
2804.1	1.97145
2806.76	1.9965
2809.41	2.34661
2812.07	2.93138
2814.72	2.81298
2817.37	4.63092
2820.02	5.9894
2822.67	6.26494
2825.32	8.06609
2827.97	9.268
2830.62	10.9445
2833.26	13.7009
2835.91	15.606
2838.55	19.2135
2841.2	23.2626
2843.84	26.6347
2846.48	30.7355
2849.12	34.9428
2851.76	40.3078
2854.4	44.2499
2857.04	49.5394
2859.68	53.8008
2862.32	58.8735
2864.95	63.2718
2867.58	67.1822
2870.22	70.7172
2872.85	73.2803
2875.48	76.3127
2878.11	78.5825
2880.74	81.2921
2883.37	83.2962
2886	84.6428
2888.63	87.697
2891.25	87.6717
2893.88	88.5579
2896.5	90.9284
2899.13	92.8814
2901.75	94.4716
2904.37	96.8135
2906.99	100.589
2909.61	105.26
2912.23	111.103
2914.85	116.285
2917.46	122.123
2920.08	126.485
2922.7	130.528
2925.31	133.527
2927.92	136.429
2930.53	137.22
2933.15	138.017
2935.76	138.035
2938.37	136.862
2940.98	135.123
2943.58	132.906
2946.19	129.918
2948.8	126.985
2951.4	123.025
2954.01	117.984
2956.61	111.945
2959.21	105.753
2961.81	99.8419
2964.41	94.2561
2967.01	90.4255
2969.61	86.5125
2972.21	82.8219
2974.81	78.6963
2977.4	74.4595
2980	69.4523
2982.59	64.5949
2985.18	59.1439
2987.78	53.8243
2990.37	49.459
2992.96	44.67
2995.55	40.4656
2998.14	36.5414
3000.72	32.8211
3003.31	28.9161
3005.9	26.2623
3008.48	23.8718
3011.07	21.8536
3013.65	19.8051
3016.23	18.4301
3018.81	16.2428
3021.39	14.323
3023.97	11.6861
3026.55	10.3096
3029.13	9.99829
3031.71	9.28375
3034.28	6.51638
3036.86	5.5112
3039.43	5.46277
3042.01	4.85378
3044.58	3.99886
3047.15	3.2159
3049.72	2.72041
3052.29	3.59429
3054.86	3.79172
3057.43	3.28991
3060	3.75205
3062.56	4.22303
3065.13	4.1995
3067.69	4.73252
3070.25	5.47489
3072.82	6.65355
3075.38	6.64647
3077.94	6.84061
3080.5	7.13263
3083.06	6.68835
3085.62	5.23735
3088.17	4.90014
3090.73	4.70963
3093.29	4.26881
3095.84	3.74832
3098.4	3.29611
3100.95	3.77966
3103.5	3.44443
3106.05	2.73927
3108.6	2.23892
3111.15	1.8225
3113.7	1.91264
3116.25	1.33836
3118.79	-0.0603695
3121.34	0.26911
3123.88	-0.879366
3126.43	-0.915719
3128.97	-1.26814
3131.51	-1.37811
3134.05	-1.686
3136.59	-2.19215
3139.14	-3.18016
3141.67	-3.32699
3144.21	-4.00876
3146.75	-4.42418
3149.28	-3.26981