File: data/Raman/poly_smoothed/Mb_10_14_04_1x_45s_532 nm_x100_100%_600 gr_mm_01.txt
#Acq. time (s)=	45
#Accumulations=	2
#Range (cm-¹)=	200...3150
#Windows=	2
#Auto scanning=	Off
#Autofocus=	Off
#Macrospot=	Off
#AutoExposure=	Off
#Spike filter=	Multiple accum.
#Delay time (s)=	0
#Binning=	1
#Readout mode=	Signal
#DeNoise=	Off
#ICS correction=	On
#Dark correction=	Off
#Inst. Process=	Off
#Detector Gain=	Best Dynamic Range
#Detector ADC=	20 kHz
#Detector temperature (°C)=	-69.85
#Instrument=	LabRAM HR Evol
#Detector=	Synapse
#Objective=	x100
#Grating=	600 gr/mm
#ND Filter=	100%
#Laser (nm)=	532
#Hole=	100.021
#Range=	Auto
#Laser Pol.=	No
#Raman. Pol.=	No
#Laser Pol. (°)=	-0.0007625
#Raman Pol. (°)=	89.9995
#Collection=	Microscope
#StageXY=	Marzhauser
#StageZ=	Marzhauser
#X (µm)=	-2398.9
#Y (µm)=	2141.1
#Z (µm)=	-40.45
#Full time(mm:ss)=	3:18
#Project=
#Sample=
#Site=
#Title=	Mb_10_14_04_2x_45s_532 nm_x100_100%_600 gr_mm
#Remark=
#Date=	07.07.2022 13:42
#Acquired=	07.07.2022 13:42:23
#Base:Fit=	10.08.2022 10:21:11
#Base:Sub=	10.08.2022 10:21:41
#Filter:Polynom=	16.08.2022 10:17:53
#AxisType[0]=Intens
#AxisUnit[0]=Cnt
#AxisType[1]=Spectr
#AxisUnit[1]=1/cm
200.43	9.33496
204.061	6.34645
207.688	2.56184
211.316	-0.682107
214.941	-0.717206
218.566	-0.461854
222.188	2.99848
225.809	8.07397
229.43	13.8631
233.047	19.9395
236.663	24.1411
240.278	26.9572
243.894	29.4704
247.506	31.6422
251.116	33.4225
254.725	36.1224
258.333	36.464
261.939	35.4268
265.546	36.2357
269.15	37.5472
272.752	36.3789
276.353	35.058
279.952	33.9433
283.55	31.4059
287.146	28.8052
290.739	25.828
294.333	22.9885
297.925	21.2615
301.516	22.0239
305.106	22.3923
308.694	22.9614
312.279	26.7367
315.864	27.4217
319.448	29.9995
323.029	27.8432
326.61	26.1678
330.19	24.7481
333.766	23.6486
337.343	21.3803
340.917	17.2422
344.491	16.3416
348.062	16.4198
351.633	17.856
355.201	18.1441
358.77	18.8998
362.335	20.586
365.899	22.6174
369.464	23.4244
373.025	24.4756
376.585	25.9805
380.143	27.235
383.702	30.6422
387.258	33.7136
390.812	39.279
394.365	41.4726
397.916	45.8683
401.467	47.5088
405.015	47.2397
408.565	47.261
412.111	46.3401
415.656	44.0622
419.197	42.1369
422.739	40.1245
426.279	36.3021
429.819	33.3092
433.356	33.2256
436.893	27.8278
440.428	22.8626
443.96	19.5012
447.492	16.6808
451.023	13.2652
454.553	12.2421
458.079	10.4861
461.606	12.2435
465.132	13.2201
468.654	15.4994
472.177	18.0765
475.696	20.3825
479.217	22.2629
482.733	24.5095
486.251	26.9745
489.765	27.8727
493.278	29.5668
496.791	30.1432
500.301	31.1651
503.81	30.7631
507.319	31.7907
510.825	31.5567
514.33	30.9897
517.833	28.3936
521.337	26.4884
524.838	24.7305
528.337	23.8909
531.835	21.7962
535.332	22.9231
538.827	22.603
542.321	23.613
545.814	23.63
549.305	22.0108
552.795	20.0684
556.284	17.8409
559.771	17.0156
563.257	14.7783
566.742	11.5689
570.223	12.3822
573.705	9.21355
577.185	8.49621
580.665	6.52308
584.141	5.30032
587.617	4.90929
591.092	4.39548
594.564	4.50269
598.037	2.23264
601.506	2.4435
604.976	2.5172
608.443	3.79668
611.91	2.29248
615.374	2.33589
618.839	1.21949
622.3	1.99041
625.761	2.24986
629.221	2.87671
632.679	3.0698
636.135	3.73473
639.592	4.48934
643.045	6.0397
646.497	7.49055
649.948	9.74124
653.398	11.5272
656.846	11.5896
660.293	11.5321
663.738	12.6704
667.185	14.0537
670.628	15.1909
674.067	15.7955
677.508	17.3257
680.947	16.7519
684.385	16.916
687.821	18.8639
691.256	17.8684
694.69	16.5778
698.121	17.3097
701.552	17.5093
704.982	17.6899
708.41	18.1926
711.836	17.946
715.262	20.6412
718.685	21.261
722.108	24.2381
725.53	25.4183
728.949	25.8128
732.369	29.6536
735.785	30.6103
739.2	30.6878
742.616	32.6091
746.028	35.7215
749.441	37.6911
752.851	39.7557
756.26	43.2813
759.667	46.0362
763.075	49.025
766.479	49.699
769.883	52.2081
773.285	54.8955
776.686	58.0194
780.085	61.4454
783.484	65.4258
786.881	66.0184
790.276	67.3562
793.671	69.7649
797.064	69.8817
800.456	70.9051
803.846	72.0647
807.236	71.6843
810.624	72.0369
814.01	72.3526
817.394	73.1342
820.778	72.8353
824.161	71.9486
827.543	72.0662
830.921	71.0201
834.3	69.6876
837.676	68.3419
841.053	67.1822
844.426	65.9619
847.8	63.5059
851.171	62.654
854.542	61.5628
857.911	61.1879
861.279	60.5314
864.645	59.0505
868.01	57.4129
871.375	55.1299
874.737	51.7645
878.097	50.2265
881.457	47.6422
884.817	47.4055
888.174	45.8197
891.53	46.5121
894.884	44.3769
898.237	45.1298
901.589	46.4569
904.94	46.3238
908.289	45.4909
911.637	45.8626
914.984	45.7945
918.33	48.2888
921.674	50.2541
925.015	51.0689
928.357	51.6882
931.698	49.377
935.037	48.8612
938.373	48.4999
941.71	48.78
945.046	48.4744
948.378	46.9727
951.711	47.4311
955.043	46.7044
958.372	44.6062
961.701	42.7345
965.027	42.6027
968.354	42.1065
971.678	43.4844
975	45.1135
978.324	46.4796
981.644	49.652
984.962	49.6362
988.282	50.891
991.598	52.5956
994.913	51.3919
998.227	51.9641
1001.54	49.8721
1004.85	47.432
1008.16	45.7236
1011.47	45.1267
1014.78	44.338
1018.08	44.95
1021.39	46.0442
1024.69	46.8421
1028	49.4171
1031.3	50.141
1034.6	50.567
1037.9	50.0239
1041.19	49.9059
1044.49	51.5745
1047.79	51.0577
1051.08	52.6811
1054.37	53.9957
1057.66	53.9838
1060.95	52.7753
1064.24	50.8618
1067.53	48.0075
1070.81	45.4563
1074.1	40.9372
1077.38	37.1102
1080.66	34.0246
1083.94	31.9379
1087.22	29.2689
1090.5	28.4327
1093.78	27.7783
1097.05	27.1619
1100.33	26.349
1103.6	28.529
1106.87	30.0368
1110.15	29.7932
1113.41	29.1488
1116.68	27.3171
1119.95	27.6588
1123.21	27.374
1126.48	27.0909
1129.74	26.2302
1133	27.4919
1136.26	26.3295
1139.52	25.9861
1142.78	24.1602
1146.04	22.0067
1149.29	22.4565
1152.55	19.3427
1155.8	18.3068
1159.05	17.1407
1162.3	15.3795
1165.55	13.4006
1168.8	13.7712
1172.05	13.5691
1175.29	12.8706
1178.54	12.552
1181.78	14.5378
1185.02	15.7214
1188.26	16.5186
1191.5	16.9464
1194.74	17.8121
1197.97	19.6071
1201.21	21.7456
1204.44	23.6867
1207.68	25.674
1210.91	29.2001
1214.14	31.8682
1217.37	34.2069
1220.6	36.7141
1223.82	38.2318
1227.05	40.9698
1230.27	42.0984
1233.49	44.5512
1236.72	47.7017
1239.94	48.2105
1243.16	49.8755
1246.37	51.3073
1249.59	52.035
1252.8	53.4776
1256.02	55.741
1259.23	56.7137
1262.44	57.8376
1265.66	56.7266
1268.87	59.6408
1272.07	61.4146
1275.28	63.0066
1278.48	64.5754
1281.69	66.0924
1284.89	68.7235
1288.09	70.0595
1291.3	71.515
1294.49	72.7741
1297.69	74.0924
1300.89	73.6723
1304.09	74.3995
1307.28	76.4438
1310.47	78.5656
1313.66	80.2076
1316.86	80.1953
1320.05	80.7372
1323.23	81.7493
1326.42	81.4348
1329.61	79.8799
1332.79	79.4424
1335.98	76.9648
1339.16	75.7237
1342.34	71.8938
1345.52	70.2769
1348.7	68.4785
1351.87	66.242
1355.05	62.7177
1358.23	60.6882
1361.4	55.9489
1364.57	52.6353
1367.74	50.0306
1370.91	47.4633
1374.08	45.6929
1377.25	43.5745
1380.42	41.8594
1383.58	43.3959
1386.75	43.4614
1389.91	43.6925
1393.07	43.8833
1396.23	43.5442
1399.39	43.0676
1402.55	44.0491
1405.7	45.0195
1408.86	47.5668
1412.01	50.2534
1415.17	52.4485
1418.32	56.1715
1421.47	60.6021
1424.62	66.1475
1427.77	72.8622
1430.92	79.4141
1434.06	85.1168
1437.2	90.07
1440.35	93.5727
1443.49	97.7792
1446.63	99.1825
1449.77	100.572
1452.91	100.963
1456.05	99.2774
1459.18	97.2465
1462.32	94.5448
1465.45	91.1736
1468.59	86.1803
1471.72	81.7489
1474.85	76.9444
1477.98	71.8986
1481.11	65.4071
1484.23	59.2428
1487.36	54.1222
1490.48	50.2077
1493.61	45.4512
1496.73	42.8768
1499.85	40.1368
1502.97	37.6248
1506.09	35.7239
1509.2	33.0981
1512.32	31.1394
1515.44	27.4561
1518.55	23.0045
1521.66	19.7426
1524.77	19.1243
1527.88	16.5017
1530.99	15.8095
1534.1	15.6272
1537.21	15.9539
1540.31	17.4853
1543.42	19.6503
1546.52	20.5273
1549.62	20.9043
1552.72	23.0097
1555.82	23.8565
1558.92	23.221
1562.02	24.2557
1565.11	25.617
1568.21	27.7123
1571.3	30.5927
1574.39	32.6722
1577.49	35.9044
1580.58	39.1541
1583.67	41.1819
1586.75	43.4981
1589.84	45.0254
1592.93	46.7124
1596.01	48.3851
1599.09	49.9069
1602.18	50.0705
1605.26	50.8055
1608.34	52.1953
1611.41	52.2298
1614.49	53.0975
1617.57	53.5638
1620.64	53.1112
1623.72	54.1115
1626.79	54.7996
1629.86	55.0908
1632.93	54.8597
1636	55.1092
1639.07	56.176
1642.14	59.0918
1645.2	61.2572
1648.27	63.2208
1651.33	65.7006
1654.39	67.7601
1657.45	68.8852
1660.51	68.2615
1663.57	68.5104
1666.63	67.9864
1669.69	65.6414
1672.74	62.8486
1675.79	59.977
1678.85	56.5486
1681.9	52.0599
1684.95	47.697
1688	43.3613
1691.05	38.8433
1694.1	34.4162
1697.14	30.4543
1700.19	26.4507
1703.23	22.1486
1706.27	18.1771
1709.32	14.5364
1712.35	13.2966
1715.39	11.9855
1718.43	11.1622
1721.47	10.1135
1724.5	8.89002
1727.54	7.21959
1730.57	5.32055
1733.61	4.38593
1736.64	4.34122
1739.67	4.1179
1742.7	3.89502
1745.72	2.3369
1748.75	1.3782
1751.78	0.888368
1754.8	1.8605
1757.82	1.91691
1760.85	1.26727
1763.87	1.42533
1766.89	1.64129
1769.91	1.44922
1772.92	1.04599
1775.94	0.245279
1778.96	0.277025
1781.97	0.86007
1784.98	2.28131
1788	3.64928
1791.01	3.92604
1794.01	3.99566
1797.02	4.45947
1800.03	3.21494
1803.04	3.69099
1806.04	4.37474
1809.05	5.44223
1812.05	6.52076
1815.05	6.50189
1818.05	7.43705
1821.05	6.91699
1824.05	7.05787
1827.05	7.16971
1830.04	7.57471
1833.04	7.3248
1836.03	7.11637
1839.03	7.28387
1842.02	6.64857
1845.01	5.25864
1848	5.11037
1850.99	4.07829
1853.97	3.30274
1856.96	2.95793
1859.94	2.51615
1862.93	1.8762
1865.91	1.17213
1868.89	1.13495
1871.87	1.02837
1874.85	1.39194
1877.83	1.35344
1880.81	1.65978
1882.56	2.64178
1885.55	2.46745
1888.54	1.8821
1891.52	2.05544
1894.51	2.24319
1897.49	2.08299
1900.48	1.92322
1903.46	2.64524
1906.44	1.90396
1909.42	2.12187
1912.4	2.17955
1915.38	2.19191
1918.35	1.29941
1921.33	0.853251
1924.3	0.722561
1927.28	0.964845
1930.25	1.25952
1933.22	0.488069
1936.19	0.740352
1939.16	0.534949
1942.13	1.14861
1945.09	2.12007
1948.06	1.30435
1951.03	1.89435
1953.99	1.15731
1956.95	0.579772
1959.91	0.490172
1962.87	1.66605
1965.83	2.6423
1968.79	2.02569
1971.75	2.53506
1974.7	2.70952
1977.66	3.35745
1980.61	2.30246
1983.56	2.14689
1986.52	2.12287
1989.47	2.38729
1992.41	2.75765
1995.36	4.02861
1998.31	4.15049
2001.26	3.88048
2004.2	4.76468
2007.15	4.31406
2010.09	4.44626
2013.03	4.3421
2015.97	4.49882
2018.91	4.53434
2021.85	4.78419
2024.79	3.23871
2027.72	3.416
2030.66	4.19208
2033.59	5.19721
2036.53	5.04148
2039.46	4.86018
2042.39	5.19677
2045.32	4.03121
2048.25	3.541
2051.18	3.34707
2054.1	3.90582
2057.03	4.16745
2059.95	5.62004
2062.88	7.24483
2065.8	7.41048
2068.72	7.10717
2071.64	6.39372
2074.56	6.73798
2077.48	6.53333
2080.39	6.34785
2083.31	6.65561
2086.22	7.16544
2089.14	7.80974
2092.05	8.15183
2094.96	8.08413
2097.87	7.94398
2100.78	9.27224
2103.69	9.813
2106.6	9.46943
2109.51	9.08625
2112.41	8.88608
2115.32	7.88555
2118.22	7.41672
2121.12	8.632
2124.02	9.72948
2126.92	8.92463
2129.82	8.84968
2132.72	10.0939
2135.62	11.2161
2138.51	12.0538
2141.41	12.9967
2144.3	14.5806
2147.19	16.4346
2150.09	18.886
2152.97	21.3537
2155.86	24.491
2158.75	26.9256
2161.64	29.4907
2164.53	30.9123
2167.41	33.5481
2170.3	34.6363
2173.18	34.958
2176.06	34.2266
2178.94	35.6282
2181.82	34.3097
2184.7	33.4656
2187.58	31.2643
2190.46	29.6069
2193.33	27.1309
2196.21	23.5843
2199.08	21.1803
2201.95	19.7539
2204.83	19.3365
2207.7	19.0867
2210.57	17.6604
2213.43	17.3793
2216.3	18.0293
2219.17	17.3216
2222.03	17.1713
2224.9	18.2385
2227.76	18.0613
2230.62	18.2658
2233.49	18.2691
2236.34	18.4808
2239.2	18.2999
2242.06	17.592
2244.92	18.1333
2247.78	19.2644
2250.63	18.6469
2253.48	17.9113
2256.34	16.983
2259.19	15.5104
2262.04	14.3862
2264.89	13.6173
2267.74	13.7766
2270.59	13.1577
2273.43	13.1936
2276.28	12.8429
2279.12	12.5857
2281.97	12.0747
2284.81	13.0469
2287.65	12.2142
2290.49	11.0778
2293.33	10.6796
2296.17	10.8355
2299.01	11.8407
2301.84	11.9607
2304.68	12.2458
2307.51	10.8126
2310.35	9.37212
2313.18	9.43477
2316.01	9.51323
2318.84	9.16559
2321.67	8.88635
2324.5	8.75659
2327.33	8.67683
2330.15	8.22287
2332.98	7.68409
2335.8	7.4664
2338.62	6.61105
2341.45	6.25826
2344.27	4.69623
2347.09	3.57073
2349.91	3.28337
2352.72	4.42975
2355.54	3.79768
2358.36	2.87526
2361.17	3.04186
2363.98	2.96183
2366.8	3.17693
2369.61	2.3815
2372.42	1.36047
2375.23	1.02965
2378.04	-1.48912
2380.85	-1.11029
2383.66	0.097567
2386.46	-0.00695264
2389.26	0.630827
2392.07	0.752788
2394.87	1.35996
2397.67	1.34184
2400.47	1.69735
2403.27	1.42472
2406.07	2.35094
2408.87	2.76445
2411.67	3.8494
2414.46	4.39691
2417.26	5.90768
2420.05	8.31021
2422.84	10.5037
2425.64	12.4032
2428.43	13.0826
2431.22	13.5422
2434.01	13.5468
2436.79	12.9774
2439.58	13.6709
2442.37	13.6238
2445.15	13.2389
2447.93	12.9599
2450.72	12.6252
2453.5	12.4095
2456.28	10.3621
2459.06	7.98637
2461.84	7.34893
2464.62	6.13611
2467.39	4.66824
2470.17	3.3214
2472.94	2.07796
2475.72	1.56426
2478.49	1.04286
2481.26	2.00975
2484.03	2.04049
2486.8	3.63318
2489.57	4.51828
2492.34	4.19475
2495.1	4.89045
2497.87	4.61784
2500.63	4.63089
2503.4	4.75946
2506.16	5.53581
2508.92	5.54436
2511.68	5.18424
2514.44	5.10258
2517.2	4.1663
2519.96	4.0411
2522.72	3.91229
2525.47	4.03071
2528.23	5.31872
2530.98	4.92912
2533.74	4.85786
2536.49	5.44854
2539.24	6.22632
2541.99	7.28557
2544.74	8.2967
2547.49	8.66715
2550.23	9.01333
2552.98	9.5368
2555.72	8.85949
2558.47	8.90197
2561.21	9.83769
2563.95	10.2449
2566.69	9.68673
2569.43	9.34633
2572.17	9.10996
2574.91	9.24549
2577.65	10.0025
2580.39	10.0113
2583.12	10.9438
2585.85	10.6982
2588.59	10.9302
2591.32	10.9307
2594.05	10.9102
2596.78	10.1625
2599.51	9.45585
2602.24	9.59128
2604.97	10.3957
2607.69	9.55169
2610.42	9.14987
2613.14	9.29395
2615.87	8.6271
2618.59	7.31157
2621.31	7.90264
2624.03	7.95133
2626.75	8.94005
2629.47	8.72258
2632.19	7.94581
2634.91	8.87426
2637.62	9.94395
2640.34	10.6661
2643.05	12.6272
2645.76	13.0912
2648.48	13.4907
2651.19	13.4733
2653.9	12.2205
2656.6	11.3696
2659.31	12.1658
2662.02	12.8284
2664.73	12.2342
2667.43	11.8333
2670.14	12.1925
2672.84	12.1905
2675.54	12.9891
2678.24	13.448
2680.94	14.635
2683.64	14.7208
2686.34	15.8407
2689.04	16.5227
2691.74	17.2851
2694.43	16.9068
2697.13	16.998
2699.82	17.0628
2702.51	17.7844
2705.21	17.9584
2707.9	18.6928
2710.58	18.8979
2713.27	19.171
2715.96	18.9038
2718.65	18.9927
2721.33	18.8339
2724.02	18.9184
2726.71	18.8027
2729.39	17.7178
2732.07	17.394
2734.75	16.6452
2737.43	17.4252
2740.11	18.3846
2742.79	19.177
2745.47	18.6069
2748.14	18.8818
2750.82	18.3687
2753.49	18.4306
2756.17	16.0617
2758.84	15.4596
2761.51	14.3044
2764.18	12.9916
2766.85	11.6175
2769.52	10.9099
2772.19	9.80186
2774.86	8.99636
2777.52	7.68752
2780.19	7.2328
2782.85	7.88535
2785.52	6.77776
2788.18	6.10739
2790.84	6.86279
2793.5	7.74082
2796.16	7.14605
2798.82	6.39857
2801.48	7.6855
2804.13	9.13423
2806.79	8.84785
2809.45	7.61443
2812.1	8.28055
2814.75	7.98531
2817.41	8.59658
2820.06	10.4157
2822.71	12.8824
2825.36	17.2039
2828	20.9676
2830.65	25.643
2833.3	31.6202
2835.94	37.9992
2838.59	45.5117
2841.23	52.7957
2843.87	61.2199
2846.52	71.9417
2849.16	83.1458
2851.8	94.8071
2854.44	106.63
2857.08	117.631
2859.71	127.271
2862.35	136.3
2864.98	144.969
2867.62	152.483
2870.25	156.889
2872.88	161.103
2875.52	166.649
2878.15	170.952
2880.78	175.047
2883.41	179.966
2886.03	184.831
2888.66	188.959
2891.29	193.964
2893.91	198.694
2896.54	202.739
2899.16	206.887
2901.78	213.13
2904.4	220.156
2907.02	229.627
2909.64	239.054
2912.26	249.129
2914.88	259.504
2917.5	267.329
2920.11	275.248
2922.73	281.05
2925.34	283.801
2927.96	285.384
2930.57	285.865
2933.18	282.488
2935.79	278.129
2938.4	273.685
2941.01	268.5
2943.62	261.992
2946.22	253.74
2948.83	244.872
2951.43	235.078
2954.04	225.849
2956.64	216.029
2959.24	205.502
2961.84	195.131
2964.45	185.624
2967.05	176.466
2969.64	168.705
2972.24	159.273
2974.84	150.783
2977.43	141.495
2980.03	131.753
2982.62	121.733
2985.22	112.17
2987.81	101.929
2990.4	91.9253
2992.99	83.0401
2995.58	73.4029
2998.17	63.0462
3000.76	55.1797
3003.34	47.5289
3005.93	39.8354
3008.52	32.6508
3011.1	25.7431
3013.68	20.6656
3016.27	16.0662
3018.85	12.3275
3021.43	9.26579
3024.01	6.36325
3026.59	3.62697
3029.16	1.2799
3031.74	0.534031
3034.32	0.0398341
3036.89	-0.568198
3039.47	-0.327822
3042.04	0.396633
3044.61	0.989726
3047.18	3.74439
3049.75	5.89484
3052.32	7.71563
3054.89	8.46286
3057.46	9.01417
3060.03	10.3837
3062.59	10.7718
3065.16	10.6966
3067.72	11.3586
3070.29	10.8775
3072.85	10.0429
3075.41	9.3215
3077.97	9.07524
3080.53	7.06954
3083.09	5.95635
3085.65	4.88835
3088.21	3.81489
3090.76	3.9602
3093.32	4.01083
3095.87	4.12053
3098.43	3.46101
3100.98	2.76009
3103.53	2.66448
3106.08	1.9645
3108.63	1.80726
3111.18	2.40036
3113.73	3.41609
3116.28	3.71975
3118.83	4.13413
3121.37	5.67765
3123.92	7.06703
3126.46	8.3374
3129	9.38936
3131.55	10.9248
3134.09	12.3089
3136.63	13.8214
3139.17	16.3177
3141.71	18.8743
3144.24	22.4428
3146.78	26.3836
3149.32	30.1763