File: data/Raman/poly_smoothed/Mb_10_14_20_1x_45s_532 nm_x100_100%_600 gr_mm_01.txt
#Acq. time (s)=	45
#Accumulations=	2
#Range (cm-¹)=	200...3150
#Windows=	2
#Auto scanning=	Off
#Autofocus=	Off
#Macrospot=	Off
#AutoExposure=	Off
#Spike filter=	Multiple accum.
#Delay time (s)=	0
#Binning=	1
#Readout mode=	Signal
#DeNoise=	Off
#ICS correction=	On
#Dark correction=	Off
#Inst. Process=	Off
#Detector Gain=	Best Dynamic Range
#Detector ADC=	20 kHz
#Detector temperature (°C)=	-69.85
#Instrument=	LabRAM HR Evol
#Detector=	Synapse
#Objective=	x100
#Grating=	600 gr/mm
#ND Filter=	100%
#Laser (nm)=	532
#Hole=	100.021
#Range=	Auto
#Laser Pol.=	No
#Raman. Pol.=	No
#Laser Pol. (°)=	-0.0007625
#Raman Pol. (°)=	89.9995
#Collection=	Microscope
#StageXY=	Marzhauser
#StageZ=	Marzhauser
#X (µm)=	-622.3
#Y (µm)=	-1586.7
#Z (µm)=	89.85
#Full time(mm:ss)=	3:18
#Project=
#Sample=
#Site=
#Title=	Mb_10_14_20_2x_45s_532 nm_x100_100%_600 gr_mm
#Remark=
#Date=	11.07.2022 10:04
#Acquired=	11.07.2022 10:04:25
#Base:Fit=	10.08.2022 10:21:11
#Base:Sub=	10.08.2022 10:21:41
#Filter:Polynom=	16.08.2022 10:17:53
#AxisType[0]=Intens
#AxisUnit[0]=Cnt
#AxisType[1]=Spectr
#AxisUnit[1]=1/cm
200.388	-0.474201
204.019	0.925734
207.646	3.69032
211.274	5.64881
214.899	7.63938
218.524	11.2303
222.146	15.0087
225.766	19.4926
229.388	20.4873
233.005	22.8188
236.621	23.9674
240.236	26.1927
243.852	27.6351
247.464	27.5413
251.074	26.2391
254.683	25.8219
258.291	24.7677
261.897	23.7502
265.504	22.3772
269.108	19.85
272.71	17.5121
276.311	14.8239
279.91	10.8916
283.508	9.75496
287.105	9.39154
290.698	7.54653
294.291	6.86806
297.884	5.66295
301.475	6.33662
305.064	6.10014
308.652	7.25034
312.237	7.45568
315.822	6.88673
319.406	7.27388
322.987	7.31207
326.568	7.2778
330.148	7.28282
333.724	7.08832
337.301	4.78346
340.875	3.92521
344.449	3.71101
348.02	1.66846
351.592	1.74427
355.16	1.46636
358.728	3.43691
362.294	6.35724
365.858	7.28129
369.422	9.85934
372.983	11.7258
376.543	12.9868
380.102	15.3947
383.661	16.8016
387.216	20.2349
390.771	20.2748
394.324	21.0175
397.875	20.698
401.425	19.5408
404.974	19.3415
408.524	19.3136
412.07	18.3641
415.614	18.9292
419.156	18.2634
422.698	16.0911
426.238	15.453
429.777	13.9189
433.315	12.9225
436.852	12.0116
440.387	9.34562
443.919	9.11326
447.451	9.27763
450.982	8.92339
454.512	5.605
458.038	5.17556
461.565	5.57687
465.091	6.50076
468.613	7.05967
472.136	10.1821
475.655	10.2056
479.176	9.76706
482.692	8.69637
486.21	9.71792
489.724	11.5433
493.237	14.8092
496.75	16.5778
500.26	18.4452
503.769	21.5241
507.279	20.8816
510.785	21.3388
514.289	23.597
517.793	22.7288
521.297	22.3742
524.797	19.0053
528.297	17.2224
531.795	17.4845
535.291	17.2816
538.787	16.8757
542.281	17.4538
545.773	17.4571
549.264	17.4024
552.754	17.1983
556.243	16.5164
559.73	15.2041
563.216	12.4927
566.701	10.7294
570.182	11.4182
573.664	10.1153
577.145	9.13032
580.624	8.26473
584.1	7.3601
587.577	5.43414
591.052	4.06961
594.524	3.43835
597.997	2.84368
601.466	2.80269
604.936	2.49444
608.403	1.5629
611.87	-2.40438
615.334	-1.40305
618.799	4.00609
622.26	7.81461
625.72	9.86774
629.181	13.3047
632.638	15.6305
636.095	19.3078
639.551	21.1132
643.005	22.8735
646.457	23.3927
649.908	24.2802
653.357	24.9999
656.806	25.0142
660.253	23.8333
663.7	25.6663
667.145	26.4435
670.588	25.377
674.027	25.9149
677.468	25.0955
680.907	24.2243
684.345	25.6651
687.781	23.9143
691.216	22.3967
694.65	19.9022
698.081	21.709
701.512	26.7308
704.942	28.011
708.371	28.644
711.796	30.3675
715.222	31.7706
718.645	31.5591
722.068	31.3734
725.49	31.7516
728.909	32.9479
732.329	33.2094
735.745	34.1598
739.16	35.0151
742.576	37.9307
745.988	39.2627
749.401	42.9714
752.811	44.733
756.22	47.0502
759.627	50.2603
763.035	53.4758
766.44	56.5147
769.843	58.2742
773.245	61.4754
776.646	62.952
780.046	67.8209
783.444	68.1651
786.841	71.1989
790.237	73.6205
793.631	74.2
797.024	73.627
800.416	75.0357
803.807	75.6199
807.196	77.9669
810.584	76.6617
813.971	76.3536
817.354	75.479
820.739	74.1577
824.122	73.3794
827.503	72.2657
830.882	71.167
834.261	69.8511
837.637	67.7466
841.013	65.8057
844.389	63.0067
847.761	60.4869
851.131	58.2815
854.503	55.5866
857.871	54.353
861.24	52.8953
864.606	51.9012
867.97	49.7503
871.336	48.9406
874.698	47.2534
878.058	45.2105
881.418	44.061
884.778	43.1653
888.135	43.4768
891.49	43.9785
894.845	43.283
898.198	45.2753
901.55	45.2103
904.901	46.493
908.25	46.975
911.598	48.3937
914.945	47.6144
918.291	48.2305
921.635	47.8456
924.978	47.706
928.318	47.0598
931.659	47.8158
934.998	47.079
938.336	45.1486
941.671	44.2921
945.007	41.6186
948.339	40.0981
951.672	38.6923
955.004	38.0559
958.333	34.0618
961.662	32.2431
964.989	30.5376
968.315	30.2897
971.639	31.5761
974.962	30.9257
978.285	31.5469
981.605	30.7868
984.924	29.6035
988.243	28.9427
991.56	27.9792
994.875	26.8449
998.188	26.5076
1001.5	27.3794
1004.81	27.9716
1008.12	29.7103
1011.43	31.7538
1014.74	33.1163
1018.05	33.0025
1021.35	34.4799
1024.65	37.6808
1027.96	37.8147
1031.26	41.1112
1034.56	41.2319
1037.86	38.0622
1041.16	37.0818
1044.45	38.0121
1047.75	36.6844
1051.04	35.608
1054.33	34.3633
1057.62	31.4648
1060.91	28.2321
1064.2	24.9841
1067.49	21.6593
1070.77	18.1754
1074.06	15.371
1077.34	13.1743
1080.62	12.2493
1083.91	12.8085
1087.18	12.1731
1090.46	13.2574
1093.74	13.7729
1097.02	14.0723
1100.29	14.9062
1103.56	15.2237
1106.84	16.3218
1110.11	14.2255
1113.38	13.5117
1116.64	11.605
1119.91	11.0321
1123.18	10.6272
1126.44	11.8908
1129.7	12.0585
1132.97	13.0051
1136.23	12.353
1139.49	13.4412
1142.74	14.9933
1146	15.6706
1149.26	14.9698
1152.51	13.7924
1155.76	12.9565
1159.01	12.4076
1162.27	13.2911
1165.51	11.9371
1168.76	11.2312
1172.01	10.7149
1175.25	10.1554
1178.5	10.1208
1181.74	9.18734
1184.98	7.49869
1188.22	8.02234
1191.46	6.08159
1194.7	5.38947
1197.94	5.74826
1201.17	6.46054
1204.41	9.61822
1207.64	12.7961
1210.87	13.6777
1214.1	17.2859
1217.33	21.1864
1220.56	25.3213
1223.79	29.6544
1227.01	32.1479
1230.23	34.0795
1233.46	34.9631
1236.68	37.0669
1239.9	40.4196
1243.12	40.6446
1246.34	40.4505
1249.55	41.072
1252.77	41.8314
1255.98	40.4627
1259.2	40.038
1262.41	39.2408
1265.62	38.7184
1268.83	37.3677
1272.03	36.3037
1275.24	35.5445
1278.45	37.2282
1281.65	38.3968
1284.85	39.2324
1288.06	39.2617
1291.26	41.004
1294.46	43.9406
1297.66	46.5244
1300.85	48.8551
1304.05	51.3626
1307.24	52.9778
1310.43	54.5778
1313.63	56.4297
1316.82	59.8385
1320.01	60.7616
1323.2	60.3309
1326.38	60.2688
1329.57	60.0362
1332.76	58.8981
1335.94	57.2751
1339.12	55.9962
1342.3	53.1359
1345.48	50.5475
1348.66	48.2601
1351.84	47.1077
1355.01	44.732
1358.19	41.5769
1361.36	40.4006
1364.53	38.9873
1367.71	36.9448
1370.88	35.6928
1374.04	34.9962
1377.21	34.6892
1380.38	34.8009
1383.54	33.5587
1386.71	32.8917
1389.87	32.3907
1393.03	33.394
1396.19	32.3708
1399.35	32.1808
1402.51	31.0142
1405.67	31.424
1408.82	32.8574
1411.98	34.5162
1415.13	35.3761
1418.28	40.0297
1421.43	43.2287
1424.58	47.361
1427.73	52.9957
1430.88	58.1106
1434.02	63.2088
1437.17	68.0167
1440.31	71.9931
1443.45	75.8435
1446.6	77.3358
1449.74	79.3716
1452.87	79.1831
1456.01	79.0011
1459.15	77.9317
1462.28	76.3763
1465.42	75.4209
1468.55	73.5844
1471.68	71.1134
1474.81	68.4211
1477.94	64.8363
1481.07	61.3779
1484.2	59.3021
1487.32	57.7287
1490.45	54.0327
1493.57	51.3539
1496.69	48.8158
1499.81	46.4043
1502.93	44.6161
1506.05	41.9634
1509.17	38.3372
1512.28	34.8893
1515.4	31.0355
1518.51	27.9728
1521.63	25.8536
1524.74	24.5673
1527.85	23.1285
1530.96	23.4045
1534.06	23.7165
1537.17	25.8532
1540.28	25.5492
1543.38	26.7941
1546.48	28.4
1549.59	31.4381
1552.69	32.7267
1555.79	32.8444
1558.88	34.8013
1561.98	35.3404
1565.08	37.4158
1568.17	36.8444
1571.27	39.3443
1574.36	39.4508
1577.45	40.4895
1580.54	40.5736
1583.63	41.4398
1586.72	43.315
1589.8	42.294
1592.89	44.44
1595.97	44.4419
1599.06	45.0939
1602.14	45.9135
1605.22	46.866
1608.3	47.2252
1611.38	46.647
1614.46	47.2336
1617.53	48.7332
1620.61	50.6378
1623.68	52.8487
1626.75	53.0675
1629.82	53.7157
1632.9	54.2382
1635.96	55.3543
1639.03	57.7753
1642.1	58.0868
1645.16	58.3776
1648.23	58.6415
1651.29	57.8325
1654.36	58.5893
1657.42	58.5795
1660.48	56.6749
1663.53	53.7273
1666.59	50.8959
1669.65	47.5349
1672.7	43.444
1675.76	39.5775
1678.81	35.5544
1681.86	31.6292
1684.91	28.0167
1687.96	24.0203
1691.01	21.3243
1694.06	20.2545
1697.11	18.1923
1700.15	16.4071
1703.2	14.8809
1706.24	15.2468
1709.28	14.5386
1712.32	13.8102
1715.36	13.0887
1718.4	12.8531
1721.43	12.7654
1724.47	12.7262
1727.5	11.8047
1730.54	11.4443
1733.57	10.295
1736.6	10.1288
1739.63	9.60926
1742.66	8.77943
1745.69	7.09636
1748.72	5.08683
1751.74	4.65825
1754.77	3.74395
1757.79	3.10557
1760.81	1.45167
1763.83	0.536529
1766.85	0.720154
1769.87	0.340112
1772.89	-0.0864797
1775.91	0.251815
1778.92	1.66668
1781.94	0.622656
1784.95	0.00777723
1787.96	0.425813
1790.97	0.926452
1793.98	0.910655
1796.99	0.481968
1800	0.805755
1803	0.521596
1806.01	1.1313
1809.01	2.12416
1812.02	2.54288
1815.02	2.59934
1818.02	2.72306
1821.02	3.74132
1824.02	4.29108
1827.01	4.98769
1830.01	5.93282
1833	6.57259
1836	6.82601
1838.99	7.22745
1841.98	6.81403
1844.97	6.70129
1847.96	7.05218
1850.95	8.33821
1853.94	8.08878
1856.92	7.82309
1859.91	8.69008
1862.89	8.12653
1865.88	8.55401
1868.86	7.28898
1871.84	7.85007
1874.82	7.36915
1877.8	7.26957
1880.77	8.1276
1882.52	8.39681
1885.51	8.19999
1888.5	8.71264
1891.49	9.21004
1894.47	9.50374
1897.46	9.97738
1900.44	10.383
1903.42	9.80888
1906.4	9.14872
1909.38	10.5253
1912.36	10.7403
1915.34	9.92326
1918.32	9.76844
1921.29	10.3651
1924.27	10.5267
1927.24	11.1186
1930.21	11.667
1933.18	11.2846
1936.15	10.9601
1939.12	10.9686
1942.09	11.4295
1945.06	11.4205
1948.02	10.7349
1950.99	10.8126
1953.95	10.418
1956.91	10.5171
1959.87	10.6289
1962.84	10.45
1965.79	10.6174
1968.75	10.8183
1971.71	9.38277
1974.66	8.902
1977.62	8.4664
1980.57	8.59978
1983.53	8.1211
1986.48	7.11332
1989.43	6.56927
1992.38	7.5957
1995.33	8.70537
1998.27	9.98481
2001.22	10.2291
2004.16	10.6214
2007.11	11.7901
2010.05	11.827
2012.99	12.6799
2015.93	11.8774
2018.87	12.4252
2021.81	11.9803
2024.75	12.37
2027.69	12.6782
2030.62	13.1947
2033.56	13.6325
2036.49	14.5543
2039.42	14.802
2042.35	14.2164
2045.28	13.4964
2048.21	14.0643
2051.14	14.2653
2054.06	14.2527
2056.99	13.5484
2059.92	14.1377
2062.84	14.4401
2065.76	14.9479
2068.68	14.0907
2071.6	14.4701
2074.52	14.7865
2077.44	14.4203
2080.36	14.0779
2083.27	13.8698
2086.19	13.5882
2089.1	13.2193
2092.01	12.6778
2094.93	13.2312
2097.84	13.9095
2100.75	13.7164
2103.66	13.9884
2106.56	14.5141
2109.47	15.4253
2112.37	16.2788
2115.28	15.8677
2118.18	16.761
2121.09	17.4072
2123.99	17.133
2126.89	17.7893
2129.79	19.0902
2132.68	19.5476
2135.58	19.3742
2138.48	20.9862
2141.37	22.5992
2144.26	23.2618
2147.16	24.7525
2150.05	27.0422
2152.94	27.9348
2155.83	29.825
2158.72	31.0312
2161.6	32.454
2164.49	33.9065
2167.38	35.1857
2170.26	34.6852
2173.14	35.5343
2176.03	36.4951
2178.91	37.4798
2181.79	37.2912
2184.67	36.9509
2187.54	35.6019
2190.42	34.9104
2193.3	32.7754
2196.17	31.1574
2199.05	30.4231
2201.92	28.2206
2204.79	25.8252
2207.66	24.2187
2210.53	23.2931
2213.4	22.6276
2216.27	21.2537
2219.13	21.5228
2222	20.4801
2224.86	20.9487
2227.72	20.4175
2230.59	19.0297
2233.45	18.5702
2236.31	17.4777
2239.17	16.6425
2242.03	16.5942
2244.88	16.9746
2247.74	16.714
2250.59	16.0411
2253.45	16.1241
2256.3	15.7783
2259.15	15.4843
2262	14.3637
2264.85	14.7459
2267.7	14.4276
2270.55	13.9692
2273.4	12.603
2276.24	11.8196
2279.09	10.9094
2281.93	9.56109
2284.77	8.85213
2287.61	7.92964
2290.46	6.96275
2293.29	5.54763
2296.13	5.05535
2298.97	4.93271
2301.81	4.06099
2304.64	5.26813
2307.48	6.40697
2310.31	7.62852
2313.14	7.10291
2315.97	7.65421
2318.8	8.19549
2321.63	8.46785
2324.46	9.04753
2327.29	9.95792
2330.12	10.0391
2332.94	9.73772
2335.76	8.62998
2338.59	8.41987
2341.41	6.26583
2344.23	4.03902
2347.05	3.22547
2349.87	2.18813
2352.69	1.25085
2355.5	0.987769
2358.32	0.734515
2361.14	-0.230079
2363.95	0.320898
2366.76	1.53392
2369.58	2.23893
2372.39	3.95811
2375.2	4.61175
2378	4.64589
2380.81	4.28987
2383.62	5.06239
2386.42	5.74683
2389.23	4.86175
2392.03	5.82418
2394.84	6.05217
2397.64	5.17007
2400.44	4.0824
2403.24	4.58278
2406.04	4.05556
2408.83	3.06688
2411.63	2.53424
2414.43	2.556
2417.22	2.84798
2420.02	2.66284
2422.81	2.49444
2425.6	2.49027
2428.39	1.50238
2431.18	1.95592
2433.97	2.87525
2436.76	3.17665
2439.54	3.53469
2442.33	3.97675
2445.11	2.84957
2447.9	2.94454
2450.68	3.41622
2453.46	3.54823
2456.24	2.82573
2459.02	3.33534
2461.8	3.00002
2464.58	3.07196
2467.36	3.77283
2470.13	4.36611
2472.91	4.26494
2475.68	4.38884
2478.45	4.02338
2481.22	4.4347
2484	5.96618
2486.77	6.13894
2489.54	6.33747
2492.3	6.54469
2495.07	6.71071
2497.84	5.94713
2500.6	5.99907
2503.36	5.79778
2506.13	4.56592
2508.89	4.30767
2511.65	3.01334
2514.41	3.10417
2517.17	2.74996
2519.93	2.60917
2522.68	3.1001
2525.44	2.33825
2528.19	2.20206
2530.95	2.48035
2533.7	2.93758
2536.45	3.56075
2539.2	3.60915
2541.95	3.81824
2544.7	4.29068
2547.45	5.17366
2550.2	6.69307
2552.94	6.33536
2555.69	6.81472
2558.43	6.93614
2561.17	5.47113
2563.92	4.16353
2566.66	3.56838
2569.4	3.72798
2572.14	2.86467
2574.88	2.69301
2577.61	1.92277
2580.35	1.93597
2583.09	2.20432
2585.82	1.69415
2588.55	2.13719
2591.28	2.56133
2594.02	2.53032
2596.75	2.54649
2599.48	2.15371
2602.2	2.5972
2604.93	2.4423
2607.66	2.48021
2610.38	2.36247
2613.11	4.07383
2615.83	4.41518
2618.56	3.4799
2621.28	3.44129
2624	3.60829
2626.72	3.19069
2629.44	3.51919
2632.15	4.16146
2634.87	5.23589
2637.59	6.4214
2640.3	5.64512
2643.02	5.10342
2645.73	5.33923
2648.44	5.64397
2651.15	5.37653
2653.86	5.65667
2656.57	5.63444
2659.28	6.00601
2661.99	6.1336
2664.69	5.96021
2667.4	6.08344
2670.1	6.01708
2672.81	6.25761
2675.51	6.03352
2678.21	6.78879
2680.91	6.55615
2683.61	5.89654
2686.31	6.84576
2689	6.47662
2691.7	6.94083
2694.4	7.92768
2697.09	8.97392
2699.79	9.46659
2702.48	10.835
2705.17	9.93602
2707.86	10.2054
2710.55	10.6308
2713.24	10.7442
2715.93	10.5032
2718.61	11.1543
2721.3	11.0201
2723.99	11.4171
2726.67	11.2256
2729.35	11.4215
2732.04	11.2828
2734.72	10.7933
2737.4	10.7015
2740.08	10.5842
2742.76	11.1478
2745.43	10.8281
2748.11	10.7744
2750.79	10.9407
2753.46	9.742
2756.13	8.21173
2758.81	8.5468
2761.48	8.46956
2764.15	8.01788
2766.82	7.06672
2769.49	6.81479
2772.16	6.54142
2774.82	6.34071
2777.49	5.23693
2780.16	4.00259
2782.82	3.6178
2785.48	2.42119
2788.15	1.67848
2790.81	1.15399
2793.47	1.11901
2796.13	0.77084
2798.79	0.329892
2801.44	0.83938
2804.1	2.23438
2806.76	3.00007
2809.41	3.71441
2812.07	3.51512
2814.72	3.82315
2817.37	5.03505
2820.02	6.30682
2822.67	10.0554
2825.32	14.4282
2827.97	18.006
2830.62	22.6045
2833.26	27.507
2835.91	32.0724
2838.55	37.2034
2841.2	43.2428
2843.84	50.1963
2846.48	57.6335
2849.12	65.9236
2851.76	74.9156
2854.4	83.408
2857.04	92.6948
2859.68	101.506
2862.32	109.572
2864.95	117.148
2867.58	124.175
2870.22	130.217
2872.85	135.445
2875.48	139.737
2878.11	143.705
2880.74	147.771
2883.37	151.897
2886	155.857
2888.63	159.46
2891.25	163.182
2893.88	166.04
2896.5	169.994
2899.13	175.221
2901.75	180.134
2904.37	187.318
2906.99	195.89
2909.61	205.265
2912.23	214.198
2914.85	224.255
2917.46	233.409
2920.08	241.698
2922.7	249.347
2925.31	253.895
2927.92	257.259
2930.53	258.57
2933.15	257.045
2935.76	255.297
2938.37	251.117
2940.98	245.171
2943.58	238.109
2946.19	229.966
2948.8	220.689
2951.4	211.114
2954.01	200.516
2956.61	189.681
2959.21	179.578
2961.81	170.198
2964.41	161.362
2967.01	151.69
2969.61	143.358
2972.21	135.799
2974.81	128.401
2977.4	121.364
2980	113.633
2982.59	105.566
2985.18	97.8913
2987.78	89.9039
2990.37	80.9691
2992.96	73.4168
2995.55	66.0453
2998.14	59.0613
3000.72	52.7802
3003.31	45.47
3005.9	38.9052
3008.48	32.6462
3011.07	26.5826
3013.65	21.5825
3016.23	17.8331
3018.81	14.136
3021.39	12.0827
3023.97	10.0653
3026.55	7.65507
3029.13	6.5421
3031.71	6.15892
3034.28	6.03497
3036.86	7.59467
3039.43	7.94627
3042.01	7.61852
3044.58	7.99398
3047.15	8.43578
3049.72	9.25003
3052.29	10.1034
3054.86	11.5781
3057.43	12.7687
3060	12.7649
3062.56	12.9809
3065.13	12.7066
3067.69	11.4559
3070.25	10.2271
3072.82	8.85321
3075.38	7.37157
3077.94	6.20277
3080.5	6.2182
3083.06	5.36591
3085.62	4.15171
3088.17	3.54682
3090.73	3.37253
3093.29	2.24981
3095.84	2.3557
3098.4	2.11907
3100.95	1.23437
3103.5	0.621269
3106.05	1.40353
3108.6	1.27503
3111.15	1.16515
3113.7	1.96247
3116.25	2.27947
3118.79	3.28683
3121.34	4.15448
3123.88	4.47535
3126.43	5.30026
3128.97	4.79858
3131.51	5.427
3134.05	5.74845
3136.59	6.07745
3139.14	6.92942
3141.67	8.0785
3144.21	8.70541
3146.75	9.98314
3149.28	10.5191