File: data/Raman/poly_smoothed/Mb_20_23_41_2x_45s_532 nm_x100_100%_600 gr_mm.txt
#Acq. time (s)=	45
#Accumulations=	2
#Range (cm-¹)=	200...3150
#Windows=	2
#Auto scanning=	Off
#Autofocus=	Off
#Macrospot=	Off
#AutoExposure=	Off
#Spike filter=	Multiple accum.
#Delay time (s)=	0
#Binning=	1
#Readout mode=	Signal
#DeNoise=	Off
#ICS correction=	On
#Dark correction=	Off
#Inst. Process=	Off
#Detector Gain=	Best Dynamic Range
#Detector ADC=	20 kHz
#Detector temperature (°C)=	-69.85
#Instrument=	LabRAM HR Evol
#Detector=	Synapse
#Objective=	x100
#Grating=	600 gr/mm
#ND Filter=	100%
#Laser (nm)=	532
#Hole=	100.021
#Range=	Auto
#Laser Pol.=	No
#Raman. Pol.=	No
#Laser Pol. (°)=	-0.0007625
#Raman Pol. (°)=	89.9995
#Collection=	Microscope
#StageXY=	Marzhauser
#StageZ=	Marzhauser
#X (µm)=	-7071.6
#Y (µm)=	2195.3
#Z (µm)=	-74.4
#Full time(mm:ss)=	2:51
#Project=
#Sample=
#Site=
#Title=	Mb_20_23_41_2x_45s_532 nm_x100_100%_600 gr_mm
#Remark=
#Date=	13.07.2022 16:48
#Acquired=	13.07.2022 16:48:43
#Base:Fit=	10.08.2022 10:29:37
#Base:Sub=	10.08.2022 10:35:48
#Filter:Polynom=	16.08.2022 10:13:29
#AxisType[0]=Intens
#AxisUnit[0]=Cnt
#AxisType[1]=Spectr
#AxisUnit[1]=1/cm
200.563	344.216
204.194	309.096
207.821	282.385
211.449	257.958
215.074	238.257
218.699	217.399
222.321	195.528
225.941	179.191
229.562	159.514
233.18	140.597
236.796	128.077
240.411	114.57
244.026	99.3311
247.638	84.2115
251.248	71.9041
254.857	59.0074
258.465	53.5157
262.071	43.9413
265.678	39.0794
269.282	29.9707
272.884	23.9136
276.484	15.582
280.084	10.5991
283.682	3.56523
287.276	8.36024
290.871	7.66019
294.465	9.58557
298.057	10.6382
301.648	11.7193
305.237	13.1812
308.823	14.9797
312.41	15.992
315.995	17.8807
319.579	21.7595
323.16	20.6995
326.741	22.4458
330.321	18.2905
333.897	14.638
337.474	13.9963
341.048	11.1322
344.622	9.88075
348.192	10.1828
351.764	6.36532
355.332	4.85204
358.901	8.02734
362.466	6.24143
366.03	2.46314
369.594	-1.74401
373.155	3.48856
376.715	7.09976
380.273	7.19498
383.832	10.6011
387.388	12.1963
390.942	14.21
394.495	17.3936
398.047	18.7049
401.597	25.0758
405.145	30.886
408.693	32.3704
412.239	33.5767
415.783	32.2907
419.327	34.2687
422.869	31.5583
426.409	32.0109
429.948	32.7815
433.486	34.7283
437.022	36.315
440.558	37.0589
444.089	39.0509
447.622	42.0874
451.153	38.2787
454.682	39.0365
458.208	39.1907
461.735	40.0206
465.259	42.406
468.783	39.6358
472.306	38.3697
475.825	37.8433
479.346	39.1427
482.862	39.1264
486.38	39.5242
489.894	38.1336
493.407	33.5223
496.92	31.0069
500.43	29.5624
503.939	31.0584
507.448	36.0833
510.954	35.4323
514.459	39.3174
517.962	39.1715
521.466	36.1661
524.966	37.6865
528.466	36.8807
531.964	35.0873
535.46	36.1097
538.955	34.9574
542.449	31.0258
545.942	27.0731
549.433	22.0147
552.923	20.7479
556.412	16.7599
559.899	10.8037
563.385	7.54911
566.867	2.84131
570.35	-2.2285
573.832	-3.72247
577.313	-2.81122
580.79	-1.54526
584.268	5.23201
587.745	12.1385
591.218	10.8538
594.692	10.8905
598.164	14.6797
601.634	21.5882
605.104	25.5226
608.57	37.6025
612.037	47.7065
615.501	51.6353
618.966	61.6305
622.427	67.3551
625.887	69.6451
629.348	73.6237
632.806	76.6984
636.262	78.8741
639.716	80.7901
643.172	82.9183
646.624	83.7657
650.075	83.4377
653.524	83.7924
656.972	83.9165
660.419	85.6346
663.865	81.4106
667.309	76.862
670.752	71.854
674.194	64.5234
677.634	60.4409
681.073	57.018
684.511	54.5657
687.947	51.4859
691.382	48.3749
694.816	46.6744
698.247	45.989
701.678	43.5893
705.108	45.066
708.534	42.3609
711.962	39.1184
715.388	35.0642
718.81	34.8991
722.234	31.7346
725.654	33.1129
729.075	37.9267
732.492	40.9333
735.91	41.6664
739.325	41.2372
742.741	45.7419
746.153	46.5115
749.564	44.1269
752.976	47.5319
756.385	50.1016
759.792	51.3649
763.2	56.7388
766.604	59.1807
770.008	60.8192
773.41	63.9104
776.811	66.368
780.21	73.8287
783.608	76.8254
787.005	75.0706
790.401	76.3372
793.795	74.6139
797.188	69.8873
800.58	71.1632
803.971	66.1874
807.36	64.0216
810.748	60.2876
814.135	53.4913
817.518	48.7512
820.902	41.9899
824.285	35.0161
827.665	31.2997
831.045	24.2864
834.424	18.396
837.8	20.0967
841.177	17.8461
844.55	15.6509
847.924	14.8952
851.295	7.37309
854.666	5.31892
858.034	6.55762
861.403	7.18974
864.769	6.62069
868.133	9.03249
871.498	7.24578
874.86	7.7222
878.221	8.08791
881.58	12.5983
884.938	10.7524
888.297	2.96493
891.653	4.63634
895.007	3.98932
898.36	3.86313
901.712	3.34922
905.063	5.02378
908.412	10.3001
911.76	11.6733
915.107	15.2387
918.452	19.6097
921.797	22.5915
925.138	22.701
928.48	24.0823
931.82	24.3223
935.16	23.3422
938.496	29.773
941.833	30.9262
945.168	34.9353
948.5	37.3712
951.834	44.7457
955.163	54.3119
958.494	58.4339
961.821	67.7714
965.15	76.3661
968.474	86.9122
971.8	100.591
975.123	115.737
978.446	132.817
981.766	146.725
985.084	162.123
988.402	176.38
991.72	188.329
995.035	199.567
998.349	207.48
1001.66	218.432
1004.97	227.981
1008.28	239.298
1011.59	255.421
1014.9	264.746
1018.21	280.535
1021.51	294.208
1024.81	303.602
1028.12	318.418
1031.42	333.571
1034.72	352.77
1038.02	372.802
1041.31	394.016
1044.61	413.741
1047.91	434.562
1051.2	453.581
1054.49	471.126
1057.78	487.031
1061.07	499.619
1064.36	511.773
1067.65	526.537
1070.93	537.203
1074.22	554.043
1077.5	567.625
1080.78	578.134
1084.06	595.262
1087.34	615.736
1090.62	638.22
1093.9	650.881
1097.17	669.356
1100.45	685.625
1103.72	699.294
1106.99	719.709
1110.27	737.749
1113.53	757.954
1116.8	779.092
1120.07	804.432
1123.33	821.415
1126.6	837.688
1129.86	857.004
1133.12	876.861
1136.38	902.355
1139.64	926.981
1142.9	960.303
1146.16	985.708
1149.41	1008.24
1152.67	1037.58
1155.92	1068.35
1159.17	1096.59
1162.42	1127.62
1165.67	1158.03
1168.92	1190.45
1172.16	1217.72
1175.41	1244.88
1178.65	1276.33
1181.9	1306.66
1185.14	1335.57
1188.38	1368.75
1191.62	1398.46
1194.86	1434.86
1198.09	1471.92
1201.33	1505.62
1204.56	1542.81
1207.8	1587.94
1211.03	1637.51
1214.26	1684.88
1217.49	1738
1220.71	1790.33
1223.94	1839.38
1227.16	1885.45
1230.39	1937.32
1233.61	1987.31
1236.83	2041.51
1240.05	2089.27
1243.27	2131.87
1246.49	2182.77
1249.71	2230.08
1252.92	2269.15
1256.14	2320.61
1259.35	2368.98
1262.56	2421.89
1265.77	2473.54
1268.98	2523.94
1272.19	2581.45
1275.4	2636.67
1278.6	2695.91
1281.81	2750.71
1285.01	2811.68
1288.21	2875.22
1291.41	2937.29
1294.61	2996.21
1297.81	3055.08
1301.01	3114.07
1304.2	3170.56
1307.4	3227.44
1310.59	3282.59
1313.78	3340.66
1316.97	3392.2
1320.16	3433.92
1323.35	3482.27
1326.54	3523.16
1329.72	3555.49
1332.91	3591.63
1336.09	3621.87
1339.27	3640.99
1342.45	3659.04
1345.64	3671.32
1348.81	3677.01
1351.99	3681.01
1355.17	3679.2
1358.34	3673.17
1361.51	3664.73
1364.69	3650.69
1367.86	3636.27
1371.03	3609.26
1374.2	3580.89
1377.37	3555.3
1380.53	3530.72
1383.7	3509.09
1386.86	3478.26
1390.02	3447.46
1393.19	3416.32
1396.35	3388.25
1399.51	3360.97
1402.66	3332.43
1405.82	3301.86
1408.97	3280.65
1412.13	3256.67
1415.28	3228.83
1418.43	3213.1
1421.59	3197.15
1424.73	3188.28
1427.88	3179.78
1431.03	3174.97
1434.18	3168.49
1437.32	3162.37
1440.46	3150.23
1443.61	3128.66
1446.75	3105.21
1449.89	3080.29
1453.03	3056.43
1456.16	3034.08
1459.3	3009.07
1462.44	2973.74
1465.57	2945.59
1468.7	2918.73
1471.83	2885.93
1474.96	2852.66
1478.09	2829.96
1481.22	2800.48
1484.35	2778.68
1487.47	2760.64
1490.6	2751.86
1493.72	2754.44
1496.84	2759.49
1499.96	2776.99
1503.08	2796.91
1506.2	2819.26
1509.32	2850.75
1512.44	2879.6
1515.55	2911.57
1518.66	2942.2
1521.78	2976.82
1524.89	3017.27
1528	3061.45
1531.11	3111.87
1534.21	3164.42
1537.32	3221.84
1540.43	3278.32
1543.53	3330.79
1546.63	3386.26
1549.74	3439.27
1552.84	3489.27
1555.94	3541.28
1559.03	3585.87
1562.13	3637.07
1565.23	3686.76
1568.32	3737.14
1571.42	3782.48
1574.51	3819.91
1577.6	3847.11
1580.69	3868.35
1583.78	3880.47
1586.87	3873.24
1589.95	3851.65
1593.04	3817.95
1596.12	3763.72
1599.21	3699.63
1602.29	3619.42
1605.37	3524.52
1608.45	3418.4
1611.53	3301.68
1614.6	3171.33
1617.68	3026.29
1620.75	2881.43
1623.83	2733.65
1626.9	2579.32
1629.97	2429.71
1633.04	2283.52
1636.11	2140.64
1639.18	2011
1642.25	1886.83
1645.31	1774.74
1648.38	1660.69
1651.44	1559.29
1654.5	1463.17
1657.56	1379.87
1660.62	1291.84
1663.68	1215.73
1666.74	1150.39
1669.8	1081.7
1672.85	1014.53
1675.91	955.334
1678.96	894.282
1682.01	838.963
1685.06	785.647
1688.11	735.746
1691.16	686.005
1694.21	639.13
1697.25	599.666
1700.3	557.737
1703.34	517.384
1706.39	483.079
1709.43	450.072
1712.47	415.668
1715.51	388.033
1718.54	361.949
1721.58	333.605
1724.62	308.927
1727.65	285.483
1730.68	267.638
1733.72	244.862
1736.75	229.195
1739.78	216.492
1742.81	202.229
1745.84	187.822
1748.86	175.525
1751.89	164.553
1754.91	153.079
1757.93	143.515
1760.96	134.796
1763.98	127.622
1767	115.41
1770.02	110.069
1773.03	101.068
1776.05	93.5543
1779.07	87.5277
1782.08	80.853
1785.09	74.5715
1788.11	69.3136
1791.12	69.6538
1794.13	65.7508
1797.13	58.609
1800.14	52.1675
1803.15	52.075
1806.15	47.5538
1809.16	43.5443
1812.16	42.7268
1815.16	41.8183
1818.16	40.9924
1821.16	41.8546
1824.16	41.4144
1827.16	37.2944
1830.16	36.3815
1833.15	33.3065
1836.14	33.2067
1839.14	27.8901
1842.13	28.6537
1845.12	26.5266
1848.11	20.8628
1851.1	14.0449
1854.08	7.73468
1857.07	9.90778
1860.05	8.96622
1863.04	9.83443
1866.02	9.07747
1869	5.81259
1871.98	5.92159
1874.96	6.46842
1877.94	10.0524
1880.92	9.02397
1882.51	11.9624
1885.5	12.5194
1888.48	17.1751
1891.47	19.665
1894.46	22.3861
1897.44	24.3562
1900.42	28.5354
1903.41	29.6551
1906.39	32.5227
1909.37	34.45
1912.35	36.691
1915.32	37.6211
1918.3	35.663
1921.27	32.0727
1924.25	32.5467
1927.22	33.1429
1930.19	36.9183
1933.17	37.4045
1936.14	37.5209
1939.11	39.8445
1942.07	41.6914
1945.04	43.7965
1948.01	43.9061
1950.97	44.3839
1953.93	44.3199
1956.9	44.9954
1959.86	45.8165
1962.82	45.8447
1965.78	45.2625
1968.74	46.4595
1971.69	46.2031
1974.65	44.5808
1977.6	45.2161
1980.56	45.4063
1983.51	43.7035
1986.46	45.6168
1989.41	44.408
1992.36	41.6376
1995.31	45.5355
1998.26	44.4955
2001.2	45.3117
2004.15	48.7486
2007.09	49.1304
2010.04	52.6769
2012.98	54.0854
2015.92	58.9329
2018.86	57.6957
2021.8	58.9307
2024.73	58.3393
2027.67	61.4305
2030.61	60.4732
2033.54	59.5032
2036.47	55.3833
2039.4	55.3763
2042.33	55.2699
2045.27	54.1788
2048.19	56.1004
2051.12	57.447
2054.05	58.3074
2056.97	62.0384
2059.9	63.3197
2062.82	67.4354
2065.74	71.8873
2068.67	73.5281
2071.59	74.0364
2074.51	75.398
2077.42	78.3858
2080.34	79.0509
2083.26	83.1221
2086.17	84.5299
2089.09	82.9182
2092	80.2838
2094.91	82.9929
2097.82	82.7781
2100.73	83.5509
2103.64	80.3145
2106.55	81.3627
2109.45	79.6089
2112.36	78.4469
2115.26	80.4351
2118.17	83.6469
2121.07	83.7411
2123.97	87.6959
2126.87	91.2047
2129.77	94.5524
2132.67	98.5118
2135.56	103.252
2138.46	107.064
2141.35	109.954
2144.25	113.611
2147.14	119.761
2150.03	125.763
2152.92	129.158
2155.81	131.366
2158.7	136.833
2161.59	141.746
2164.47	147.332
2167.36	152.907
2170.24	157.054
2173.13	158.928
2176.01	158.013
2178.89	158.72
2181.77	158.943
2184.65	160.492
2187.53	161.544
2190.4	159.621
2193.28	159.181
2196.16	161.358
2199.03	156.761
2201.9	152.734
2204.77	152.501
2207.64	149.222
2210.51	146.364
2213.38	140.872
2216.25	136.734
2219.12	133.356
2221.98	129.281
2224.85	126.084
2227.71	121.526
2230.57	119.481
2233.43	113.703
2236.29	107.36
2239.15	100.384
2242.01	95.2468
2244.87	89.5123
2247.72	82.9337
2250.58	80.4048
2253.43	75.4848
2256.29	67.5391
2259.14	63.1096
2261.99	61.5603
2264.84	59.3854
2267.69	55.0736
2270.53	53.0937
2273.38	50.6656
2276.23	50.8713
2279.07	47.6145
2281.91	44.1543
2284.76	42.4013
2287.6	44.2529
2290.44	45.0836
2293.28	43.8469
2296.12	43.1892
2298.96	39.698
2301.79	40.725
2304.63	39.1246
2307.46	39.8081
2310.3	44.652
2313.13	46.1882
2315.96	41.6471
2318.79	42.565
2321.62	37.0978
2324.45	34.0362
2327.27	31.7693
2330.1	31.949
2332.92	32.9075
2335.75	31.8895
2338.57	31.9138
2341.39	30.062
2344.21	26.9374
2347.04	22.8016
2349.85	18.0309
2352.67	16.9157
2355.49	17.3468
2358.3	16.7566
2361.12	16.1854
2363.93	14.5038
2366.75	10.6791
2369.56	12.6233
2372.37	12.7481
2375.18	13.502
2377.99	16.8287
2380.8	18.3966
2383.6	14.3974
2386.41	13.8101
2389.21	13.353
2392.02	10.8774
2394.82	12.3228
2397.62	11.9619
2400.42	11.1096
2403.22	13.0221
2406.02	12.3326
2408.82	12.1683
2411.62	10.5344
2414.41	11.4574
2417.21	14.0777
2420	14.6574
2422.79	15.6617
2425.59	14.6339
2428.38	14.9633
2431.17	10.8274
2433.95	9.45988
2436.74	9.64965
2439.53	9.0935
2442.31	8.25414
2445.1	7.94201
2447.88	9.91635
2450.67	7.27036
2453.45	7.16726
2456.23	4.98676
2459.01	2.28521
2461.79	1.83393
2464.57	-0.393959
2467.34	-2.57644
2470.12	-3.07789
2472.89	-2.13368
2475.67	-2.03862
2478.44	-1.41758
2481.21	-3.52201
2483.98	-0.078074
2486.75	0.457128
2489.52	-0.116316
2492.29	-0.630621
2495.05	-1.64501
2497.82	-3.95294
2500.58	-1.79272
2503.35	-3.33127
2506.11	-3.4531
2508.87	-3.80478
2511.63	0.210636
2514.39	2.14743
2517.15	3.05747
2519.91	4.22703
2522.67	3.62773
2525.42	3.30886
2528.18	3.57997
2530.93	4.92383
2533.69	3.62104
2536.44	4.89845
2539.19	5.47641
2541.94	9.93849
2544.69	10.712
2547.44	9.51763
2550.18	12.5374
2552.93	15.9741
2555.67	16.9375
2558.42	19.2386
2561.16	19.2744
2563.9	21.3974
2566.64	21.0073
2569.38	22.9006
2572.12	22.0101
2574.86	25.5692
2577.6	24.7137
2580.33	26.8442
2583.07	23.4438
2585.8	25.189
2588.54	21.5393
2591.27	19.5527
2594	19.9334
2596.73	17.1487
2599.46	15.0712
2602.19	13.9783
2604.92	9.62058
2607.64	10.3154
2610.37	6.10631
2613.09	7.05903
2615.82	7.64711
2618.54	6.57258
2621.26	8.02196
2623.98	10.3972
2626.7	10.4073
2629.42	15.2285
2632.14	16.1624
2634.86	19.0949
2637.57	24.7233
2640.29	27.7149
2643	30.0204
2645.71	33.3226
2648.43	38.1991
2651.14	39.2412
2653.85	40.7254
2656.56	41.0444
2659.26	43.0896
2661.97	44.7452
2664.68	46.3008
2667.38	43.9076
2670.09	43.5672
2672.79	45.259
2675.49	47.0133
2678.19	47.7041
2680.89	47.7852
2683.59	46.8837
2686.29	46.9911
2688.99	45.0713
2691.69	44.5647
2694.38	46.4172
2697.08	47.3372
2699.77	47.2648
2702.46	48.6727
2705.15	49.565
2707.85	49.4626
2710.54	48.3822
2713.22	50.9852
2715.91	48.8437
2718.6	47.3741
2721.29	47.5783
2723.97	51.4509
2726.66	50.7924
2729.34	51.5021
2732.02	51.1486
2734.7	47.1042
2737.38	45.2483
2740.06	43.888
2742.74	39.3059
2745.42	33.8625
2748.09	31.0531
2750.77	26.7987
2753.45	20.9786
2756.12	19.3923
2758.79	19.4729
2761.46	19.6533
2764.14	16.3688
2766.8	13.2162
2769.47	9.64248
2772.14	9.52574
2774.81	8.62396
2777.48	9.18132
2780.14	9.77988
2782.8	9.58765
2785.47	9.66351
2788.13	11.1443
2790.79	12.3882
2793.45	9.86444
2796.11	8.80133
2798.77	3.67747
2801.43	1.34493
2804.09	0.0822576
2806.74	-2.83569
2809.4	-11.0725
2812.05	-10.2091
2814.71	-9.94254
2817.36	-5.7739
2820.01	2.52783
2822.66	21.9119
2825.31	38.6939
2827.96	58.6581
2830.6	84.0706
2833.25	110.67
2835.9	140.355
2838.54	169.884
2841.18	200.764
2843.83	227.417
2846.47	256.815
2849.11	287.081
2851.75	319.472
2854.39	354.143
2857.03	384.157
2859.66	409.345
2862.3	431.154
2864.94	449.515
2867.57	465.976
2870.2	478.796
2872.84	489.225
2875.47	498.226
2878.1	509.394
2880.73	517.099
2883.36	529.881
2885.99	542.055
2888.61	551.933
2891.24	563.834
2893.86	575.455
2896.49	584.818
2899.11	592.243
2901.73	599.969
2904.36	607.587
2906.98	617.434
2909.6	630.838
2912.21	651.588
2914.83	670.301
2917.45	689.702
2920.07	700.713
2922.68	707.615
2925.29	710.865
2927.91	709.871
2930.52	706.35
2933.13	698.394
2935.74	685.105
2938.35	669.339
2940.96	651.316
2943.57	628.688
2946.18	602.756
2948.78	573.54
2951.39	544.171
2953.99	512.72
2956.59	480.486
2959.2	449.815
2961.8	417.47
2964.4	385.299
2967	354.875
2969.6	327.612
2972.19	304.114
2974.79	281.107
2977.39	257.259
2979.98	235.169
2982.58	209.755
2985.17	187.408
2987.76	162.807
2990.35	142.251
2992.94	120.561
2995.53	101.614
2998.12	81.8845
3000.71	66.0556
3003.3	55.1326
3005.88	42.6872
3008.47	30.7349
3011.05	20.5662
3013.64	15.0856
3016.22	10.034
3018.8	3.77449
3021.38	1.28568
3023.96	-3.59224
3026.54	-6.85481
3029.12	-8.29053
3031.69	-5.89947
3034.27	-5.23938
3036.84	-2.53994
3039.42	1.10554
3041.99	5.36159
3044.57	8.65914
3047.14	14.0874
3049.71	15.8479
3052.28	17.947
3054.85	22.5905
3057.41	22.9619
3059.98	26.3602
3062.55	31.3204
3065.11	37.1432
3067.68	41.3973
3070.24	45.0338
3072.8	49.3819
3075.36	52.0611
3077.93	57.9512
3080.49	60.9499
3083.04	63.8959
3085.6	70.583
3088.16	74.6955
3090.72	80.5279
3093.27	88.2762
3095.83	92.9591
3098.38	99.2533
3100.93	107.848
3103.49	116.659
3106.04	124.485
3108.59	134.746
3111.14	145.92
3113.69	155.776
3116.23	167.069
3118.78	179.89
3121.33	191.416
3123.87	206.084
3126.41	221.149
3128.96	235.039
3131.5	248.624
3134.04	261.51
3136.58	276.022
3139.12	291.775
3141.66	305.49
3144.2	316.981
3146.74	326.771
3149.27	334.245