File: data/Raman/poly_smoothed/Mb_20_23_12_1x_45s_532 nm_x100_100%_600 gr_mm_01.txt
#Acq. time (s)=	45
#Accumulations=	2
#Range (cm-¹)=	200...3150
#Windows=	2
#Auto scanning=	Off
#Autofocus=	Off
#Macrospot=	Off
#AutoExposure=	Off
#Spike filter=	Multiple accum.
#Delay time (s)=	0
#Binning=	1
#Readout mode=	Signal
#DeNoise=	Off
#ICS correction=	On
#Dark correction=	Off
#Inst. Process=	Off
#Detector Gain=	Best Dynamic Range
#Detector ADC=	20 kHz
#Detector temperature (°C)=	-69.85
#Instrument=	LabRAM HR Evol
#Detector=	Synapse
#Objective=	x100
#Grating=	600 gr/mm
#ND Filter=	100%
#Laser (nm)=	532
#Hole=	100.021
#Range=	Auto
#Laser Pol.=	No
#Raman. Pol.=	No
#Laser Pol. (°)=	-0.0007625
#Raman Pol. (°)=	89.9995
#Collection=	Microscope
#StageXY=	Marzhauser
#StageZ=	Marzhauser
#X (µm)=	-6987.9
#Y (µm)=	2133.5
#Z (µm)=	-74.85
#Full time(mm:ss)=	3:19
#Project=
#Sample=
#Site=
#Title=	Mb_20_23_12_2x_45s_532 nm_x100_100%_600 gr_mm
#Remark=
#Date=	13.07.2022 13:48
#Acquired=	13.07.2022 13:48:34
#Base:Fit=	10.08.2022 10:29:19
#Base:Fit=	10.08.2022 10:29:37
#Base:Sub=	10.08.2022 10:32:28
#Filter:Polynom=	16.08.2022 10:13:29
#AxisType[0]=Intens
#AxisUnit[0]=Cnt
#AxisType[1]=Spectr
#AxisUnit[1]=1/cm
200.563	17.0549
204.194	11.916
207.821	8.23625
211.449	5.99998
215.074	3.4038
218.699	1.95651
222.321	1.91227
225.941	1.91495
229.562	2.20849
233.18	2.07681
236.796	2.90704
240.411	2.81148
244.026	2.91029
247.638	3.20053
251.248	4.34129
254.857	3.01238
258.465	3.14515
262.071	3.79127
265.678	3.0673
269.282	3.02446
272.884	3.01074
276.484	2.70475
280.084	2.89451
283.682	1.42455
287.276	0.54162
290.871	0.328419
294.465	0.29396
298.057	1.42588
301.648	1.76199
305.237	3.80587
308.823	6.39758
312.41	9.52149
315.995	12.4614
319.579	14.5043
323.16	15.2179
326.741	17.5667
330.321	17.2153
333.897	18.5671
337.474	17.8984
341.048	19.175
344.622	18.8946
348.192	18.0959
351.764	17.5814
355.332	16.1002
358.901	15.12
362.466	13.6859
366.03	13.3199
369.594	11.9564
373.155	10.8158
376.715	10.2342
380.273	9.09747
383.832	9.94343
387.388	10.6516
390.942	12.4935
394.495	14.1917
398.047	15.0131
401.597	15.1609
405.145	13.4998
408.693	12.5825
412.239	13.4628
415.783	13.194
419.327	13.2873
422.869	12.4376
426.409	13.1844
429.948	13.7308
433.486	13.1045
437.022	13.2699
440.558	11.7914
444.089	10.2347
447.622	11.6193
451.153	11.4474
454.682	12.6817
458.208	12.4062
461.735	12.2557
465.259	12.4499
468.783	12.7706
472.306	13.7487
475.825	14.1979
479.346	14.6833
482.862	14.3725
486.38	13.3026
489.894	11.5309
493.407	12.2354
496.92	15.8833
500.43	16.934
503.939	18.7239
507.448	20.6482
510.954	22.1629
514.459	24.2149
517.962	25.2069
521.466	25.7718
524.966	25.4265
528.466	24.7426
531.964	25.3099
535.46	24.7252
538.955	23.3907
542.449	21.9454
545.942	21.0425
549.433	19.6118
552.923	17.3405
556.412	14.4632
559.899	11.8771
563.385	8.553
566.867	5.92352
570.35	5.16713
573.832	1.99716
577.313	3.52927
580.79	2.75586
584.268	3.13766
587.745	3.64275
591.218	2.15326
594.692	1.51624
598.164	2.68454
601.634	4.66261
605.104	5.00612
608.57	4.05725
612.037	5.06776
615.501	5.32197
618.966	6.68686
622.427	9.26571
625.887	9.86096
629.348	8.87162
632.806	9.16493
636.262	9.32134
639.716	9.13137
643.172	9.87889
646.624	9.78569
650.075	8.99016
653.524	8.75252
656.972	9.15344
660.419	8.13046
663.865	6.4542
667.309	7.49162
670.752	8.19604
674.194	6.69607
677.634	7.79325
681.073	8.31606
684.511	9.3963
687.947	11.5908
691.382	12.8509
694.816	15.0187
698.247	11.6426
701.678	13.6455
705.108	20.7637
708.534	24.8854
711.962	28.7753
715.388	32.5119
718.81	38.0222
722.234	41.7108
725.654	43.8076
729.075	46.2108
732.492	46.6994
735.91	47.6703
739.325	47.6271
742.741	48.2432
746.153	49.0702
749.564	51.4836
752.976	53.3356
756.385	53.0005
759.792	53.347
763.2	54.703
766.604	54.6434
770.008	55.905
773.41	56.5909
776.811	56.2267
780.21	56.7044
783.608	59.3725
787.005	68.7097
790.401	70.215
793.795	66.9613
797.188	70.3902
800.58	75.8602
803.971	80.6432
807.36	83.7402
810.748	86.4159
814.135	89.3362
817.518	91.3712
820.902	91.7939
824.285	92.7381
827.665	92.9024
831.045	91.6238
834.424	92.0434
837.8	90.7299
841.177	87.9076
844.55	84.475
847.924	79.4424
851.295	75.836
854.666	72.9337
858.034	69.9476
861.403	65.9498
864.769	61.4385
868.133	57.1812
871.498	51.3219
874.86	47.7076
878.221	46.3658
881.58	50.8983
884.938	49.8062
888.297	48.0497
891.653	47.4294
895.007	48.7567
898.36	48.7707
901.712	48.1466
905.063	48.394
908.412	48.1532
911.76	47.8863
915.107	47.8111
918.452	47.8173
921.797	44.8967
925.138	43.3078
928.48	41.2808
931.82	41.0036
935.16	40.978
938.496	40.8908
941.833	38.3198
945.168	35.9126
948.5	33.8058
951.834	33.8199
955.163	33.9933
958.494	31.1393
961.821	29.0629
965.15	29.7742
968.474	30.1547
971.8	31.1241
975.123	31.6535
978.446	31.9316
981.766	31.7504
985.084	32.0052
988.402	30.7575
991.72	30.4231
995.035	29.7532
998.349	29.5053
1001.66	28.4063
1004.97	28.3272
1008.28	27.5869
1011.59	29.3859
1014.9	30.1167
1018.21	28.8511
1021.51	27.9217
1024.81	28.5084
1028.12	30.3561
1031.42	31.6913
1034.72	33.3904
1038.02	33.0316
1041.31	34.5788
1044.61	37.1993
1047.91	38.5374
1051.2	39.9717
1054.49	40.9967
1057.78	42.002
1061.07	43.7354
1064.36	43.9738
1067.65	43.5558
1070.93	42.8894
1074.22	42.4282
1077.5	42.6182
1080.78	40.9603
1084.06	39.1323
1087.34	39.1359
1090.62	38.9466
1093.9	36.4361
1097.17	34.3481
1100.45	34.4209
1103.72	36.3307
1106.99	37.3165
1110.27	36.0233
1113.53	36.2668
1116.8	35.199
1120.07	34.2052
1123.33	33.5208
1126.6	33.3848
1129.86	31.9648
1133.12	30.6241
1136.38	30.451
1139.64	28.6931
1142.9	25.6031
1146.16	21.9115
1149.41	19.2211
1152.67	16.0513
1155.92	11.9654
1159.17	7.95645
1162.42	5.12659
1165.67	2.31226
1168.92	2.48259
1172.16	0.441905
1175.41	2.13127
1178.65	2.39118
1181.9	3.61613
1185.14	4.70256
1188.38	3.78615
1191.62	4.44793
1194.86	7.10247
1198.09	9.15945
1201.33	11.2252
1204.56	13.0786
1207.8	15.8171
1211.03	18.0074
1214.26	20.8506
1217.49	24.6439
1220.71	27.0167
1223.94	30.6612
1227.16	33.2638
1230.39	34.6386
1233.61	36.7982
1236.83	39.7218
1240.05	43.0472
1243.27	45.8768
1246.49	48.5852
1249.71	52.6078
1252.92	56.0085
1256.14	59.3042
1259.35	60.316
1262.56	62.0378
1265.77	63.3905
1268.98	65.5115
1272.19	69.2002
1275.4	70.982
1278.6	73.4777
1281.81	75.563
1285.01	78.136
1288.21	82.1234
1291.41	83.5939
1294.61	86.5809
1297.81	88.861
1301.01	90.4248
1304.2	90.4025
1307.4	90.6762
1310.59	90.9481
1313.78	91.7626
1316.97	92.2632
1320.16	91.829
1323.35	90.4704
1326.54	89.8989
1329.72	88.6975
1332.91	85.3851
1336.09	81.4748
1339.27	78.3994
1342.45	75.1157
1345.64	73.2878
1348.81	71.2276
1351.99	68.0989
1355.17	66.847
1358.34	64.1442
1361.51	62.7665
1364.69	61.2849
1367.86	59.4492
1371.03	58.7927
1374.2	57.6211
1377.37	57.5723
1380.53	55.5683
1383.7	56.6101
1386.86	57.3144
1390.02	56.9862
1393.19	59.0816
1396.35	60.0651
1399.51	60.0475
1402.66	60.5969
1405.82	64.1308
1408.97	68.015
1412.13	72.4173
1415.28	77.286
1418.43	84.8269
1421.59	92.7371
1424.73	100.917
1427.88	108.523
1431.03	116.247
1434.18	124.657
1437.32	129.266
1440.46	134.123
1443.61	136.406
1446.75	137.528
1449.89	135.945
1453.03	133.613
1456.16	130.395
1459.3	126.264
1462.44	120.999
1465.57	112.448
1468.7	103.638
1471.83	94.7317
1474.96	85.9407
1478.09	77.178
1481.22	70.82
1484.35	63.7833
1487.47	57.8677
1490.6	51.1822
1493.72	46.6631
1496.84	43.5129
1499.96	41.4981
1503.08	38.0883
1506.2	36.3823
1509.32	34.2214
1512.44	32.0169
1515.55	29.6875
1518.66	27.9047
1521.78	26.5922
1524.89	26.4845
1528	25.7023
1531.11	25.9986
1534.21	27.856
1537.32	29.4787
1540.43	30.8973
1543.53	30.8801
1546.63	33.9966
1549.74	35.9466
1552.84	39.1957
1555.94	41.2336
1559.03	44.5008
1562.13	45.8126
1565.23	47.5784
1568.32	49.3894
1571.42	51.5374
1574.51	54.121
1577.6	55.9588
1580.69	56.6739
1583.78	59.9175
1586.87	60.756
1589.95	61.7196
1593.04	62.1611
1596.12	61.8336
1599.21	61.3857
1602.29	58.7921
1605.37	59.3018
1608.45	59.6393
1611.53	59.5139
1614.6	59.203
1617.68	59.293
1620.75	59.0535
1623.83	60.6813
1626.9	63.0122
1629.97	66.2898
1633.04	69.5671
1636.11	71.376
1639.18	74.325
1642.25	78.3951
1645.31	81.0831
1648.38	83.4697
1651.44	84.6586
1654.5	85.9515
1657.56	86.6902
1660.62	86.9496
1663.68	85.1269
1666.74	82.0194
1669.8	77.1808
1672.85	71.2723
1675.91	64.95
1678.96	58.847
1682.01	55.5696
1685.06	50.3751
1688.11	45.8343
1691.16	41.1767
1694.21	37.388
1697.25	34.6326
1700.3	32.0096
1703.34	30.8354
1706.39	29.3347
1709.43	27.0803
1712.47	25.5433
1715.51	24.8817
1718.54	23.8234
1721.58	23.3055
1724.62	21.7025
1727.65	22.0749
1730.68	21.4795
1733.72	21.4237
1736.75	21.0133
1739.78	19.377
1742.81	17.7287
1745.84	15.2289
1748.86	13.6159
1751.89	13.7084
1754.91	13.4618
1757.93	13.1077
1760.96	11.6189
1763.98	11.6305
1767	11.3584
1770.02	9.94863
1773.03	9.96603
1776.05	9.05147
1779.07	8.66933
1782.08	8.08173
1785.09	7.1554
1788.11	6.8368
1791.12	6.4452
1794.13	5.05093
1797.13	4.537
1800.14	4.1129
1803.15	4.15683
1806.15	4.48383
1809.16	4.28891
1812.16	4.20647
1815.16	3.84789
1818.16	3.6197
1821.16	3.47235
1824.16	2.9447
1827.16	3.30433
1830.16	3.0652
1833.15	3.92767
1836.14	3.46684
1839.14	5.00517
1842.13	5.71883
1845.12	5.17789
1848.11	4.84995
1851.1	4.26821
1854.08	3.81452
1857.07	3.95832
1860.05	3.54786
1863.04	3.06927
1866.02	3.61833
1869	3.824
1871.98	4.62589
1874.96	4.70283
1877.94	4.17532
1880.92	3.70252
1882.51	3.7362
1885.5	3.73546
1888.48	4.63754
1891.47	5.32522
1894.46	5.37628
1897.44	5.72397
1900.42	6.72048
1903.41	6.99485
1906.39	7.24227
1909.37	7.11025
1912.35	7.03954
1915.32	5.72403
1918.3	4.6367
1921.27	3.95791
1924.25	3.93341
1927.22	3.20588
1930.19	3.02448
1933.17	2.90635
1936.14	3.64356
1939.11	3.60431
1942.07	2.65293
1945.04	3.18711
1948.01	3.14276
1950.97	3.66301
1953.93	3.46849
1956.9	4.40112
1959.86	4.6591
1962.82	4.60319
1965.78	5.78831
1968.74	5.85145
1971.69	4.49325
1974.65	4.12176
1977.6	3.13416
1980.56	2.05246
1983.51	2.02973
1986.46	1.60492
1989.41	0.28743
1992.36	-0.0928495
1995.31	0.307588
1998.26	-1.05221
2001.2	-1.50579
2004.15	-1.39261
2007.09	-0.37683
2010.04	0.0544374
2012.98	0.350986
2015.92	1.79176
2018.86	1.42459
2021.8	1.35544
2024.73	2.09222
2027.67	3.23249
2030.61	4.26439
2033.54	3.8295
2036.47	5.32822
2039.4	5.84402
2042.33	4.62168
2045.27	5.17235
2048.19	4.79635
2051.12	5.86082
2054.05	5.52633
2056.97	5.67194
2059.9	5.37096
2062.82	4.58222
2065.74	4.42193
2068.67	3.2922
2071.59	2.57856
2074.51	3.86133
2077.42	4.28687
2080.34	4.88082
2083.26	4.4747
2086.17	5.58936
2089.09	6.42969
2092	6.45842
2094.91	7.32379
2097.82	8.00923
2100.73	9.90227
2103.64	10.5773
2106.55	12.0601
2109.45	13.8418
2112.36	14.0674
2115.26	16.1782
2118.17	18.1916
2121.07	19.6988
2123.97	21.0477
2126.87	22.7043
2129.77	25.0392
2132.67	26.1
2135.56	28.5294
2138.46	29.7335
2141.35	31.2907
2144.25	33.9872
2147.14	36.8125
2150.03	38.9074
2152.92	41.9938
2155.81	46.0074
2158.7	46.9255
2161.59	48.1833
2164.47	49.7939
2167.36	51.7583
2170.24	53.3471
2173.13	54.2657
2176.01	53.6646
2178.89	53.9225
2181.77	53.8053
2184.65	53.4494
2187.53	52.0459
2190.4	50.1082
2193.28	48.4697
2196.16	46.1169
2199.03	42.1509
2201.9	39.5094
2204.77	36.8789
2207.64	33.5469
2210.51	30.7703
2213.38	28.4573
2216.25	27.2345
2219.12	24.7201
2221.98	23.487
2224.85	21.3863
2227.71	19.7066
2230.57	18.7533
2233.43	18.0082
2236.29	17.5343
2239.15	16.2105
2242.01	16.0833
2244.87	14.111
2247.72	13.8081
2250.58	14.023
2253.43	14.2541
2256.29	13.9941
2259.14	12.8453
2261.99	13.1569
2264.84	11.4732
2267.69	10.5145
2270.53	10.0323
2273.38	10.4714
2276.23	10.8609
2279.07	10.8107
2281.91	10.7391
2284.76	10.2098
2287.6	9.94902
2290.44	9.0158
2293.28	8.57091
2296.12	7.93099
2298.96	8.42588
2301.79	8.18956
2304.63	8.20959
2307.46	7.44596
2310.3	7.82397
2313.13	7.58155
2315.96	7.2977
2318.79	7.14734
2321.62	7.79601
2324.45	7.73406
2327.27	6.5718
2330.1	5.97084
2332.92	4.98748
2335.75	4.93748
2338.57	5.57038
2341.39	4.20021
2344.21	4.29903
2347.04	3.9559
2349.85	2.75571
2352.67	1.90268
2355.49	0.697164
2358.3	1.77339
2361.12	1.72089
2363.93	1.42777
2366.75	2.89034
2369.56	4.12593
2372.37	4.63087
2375.18	4.98348
2377.99	5.38526
2380.8	5.90989
2383.6	6.09384
2386.41	5.12941
2389.21	6.27288
2392.02	5.56688
2394.82	5.07635
2397.62	5.00169
2400.42	4.49755
2403.22	4.17202
2406.02	3.88157
2408.82	3.93668
2411.62	3.66566
2414.41	3.37225
2417.21	3.18942
2420	3.25992
2422.79	3.25397
2425.59	3.61724
2428.38	4.0297
2431.17	3.45471
2433.95	4.74586
2436.74	5.40741
2439.53	5.21906
2442.31	5.42035
2445.1	5.57902
2447.88	5.46665
2450.67	5.97127
2453.45	6.18883
2456.23	5.96341
2459.01	6.50252
2461.79	7.03097
2464.57	7.51687
2467.34	7.23533
2470.12	7.63884
2472.89	6.74787
2475.67	7.91929
2478.44	7.53354
2481.21	6.64781
2483.98	5.51597
2486.75	3.89806
2489.52	2.73803
2492.29	3.16575
2495.05	2.57095
2497.82	1.92793
2500.58	1.16765
2503.35	0.777158
2506.11	0.228384
2508.87	-0.235875
2511.63	0.0459383
2514.39	-0.0515992
2517.15	0.261583
2519.91	0.337553
2522.67	1.49619
2525.42	2.88418
2528.18	4.51277
2530.93	5.0609
2533.69	5.99752
2536.44	6.08197
2539.19	6.51505
2541.94	7.74451
2544.69	8.38968
2547.44	8.16138
2550.18	9.34932
2552.93	9.43259
2555.67	9.39897
2558.42	10.1834
2561.16	10.9827
2563.9	10.0573
2566.64	9.50002
2569.38	9.5192
2572.12	9.18078
2574.86	8.92795
2577.6	8.05146
2580.33	8.03906
2583.07	8.29414
2585.8	7.07213
2588.54	7.38002
2591.27	7.09185
2594	6.53925
2596.73	5.75642
2599.46	5.59266
2602.19	6.76981
2604.92	6.64774
2607.64	7.51366
2610.37	7.66064
2613.09	8.08687
2615.82	8.57328
2618.54	8.49855
2621.26	8.31024
2623.98	8.44834
2626.7	8.44767
2629.42	8.4953
2632.14	7.99435
2634.86	9.07938
2637.57	8.59189
2640.29	9.17519
2643	8.5762
2645.71	9.6321
2648.43	9.46337
2651.14	8.62712
2653.85	8.01645
2656.56	7.62293
2659.26	7.78202
2661.97	9.71218
2664.68	9.9908
2667.38	11.1342
2670.09	10.959
2672.79	9.91645
2675.49	9.99627
2678.19	10.1555
2680.89	9.70246
2683.59	9.49281
2686.29	8.81233
2688.99	9.2139
2691.69	9.63439
2694.38	9.8328
2697.08	10.6325
2699.77	11.116
2702.46	12.2665
2705.15	12.3748
2707.85	12.7298
2710.54	12.7608
2713.22	14.0147
2715.91	14.2009
2718.6	14.5868
2721.29	15.1551
2723.97	16.306
2726.66	16.3971
2729.34	15.7337
2732.02	14.4242
2734.7	12.537
2737.38	11.2546
2740.06	10.3739
2742.74	9.51828
2745.42	8.98997
2748.09	7.39496
2750.77	6.70109
2753.45	5.07353
2756.12	4.10955
2758.79	3.4842
2761.46	2.47236
2764.14	1.86057
2766.8	1.74293
2769.47	0.57007
2772.14	0.206696
2774.81	-0.413819
2777.48	-0.166822
2780.14	0.392421
2782.8	0.554173
2785.47	1.46788
2788.13	1.20588
2790.79	0.690484
2793.45	0.97281
2796.11	1.44727
2798.77	1.12473
2801.43	2.07276
2804.09	3.01796
2806.74	3.20204
2809.4	2.80012
2812.05	2.39242
2814.71	1.87155
2817.36	2.66155
2820.01	4.79937
2822.66	9.48499
2825.31	15.3372
2827.96	22.535
2830.6	30.4143
2833.25	39.4157
2835.9	48.302
2838.54	59.3684
2841.18	70.4686
2843.83	82.0158
2846.47	94.4121
2849.11	108.161
2851.75	121.689
2854.39	133.871
2857.03	145.849
2859.66	158.487
2862.3	169.84
2864.94	179.785
2867.57	188.149
2870.2	196.21
2872.84	201.876
2875.47	208.217
2878.1	213.82
2880.73	219.531
2883.36	226.269
2885.99	232.94
2888.61	239.177
2891.24	245.65
2893.86	252.56
2896.49	258.74
2899.11	266.463
2901.73	273.656
2904.36	280.976
2906.98	290.209
2909.6	299.974
2912.21	311.022
2914.83	321.026
2917.45	329.986
2920.07	336.896
2922.68	343.416
2925.29	347.136
2927.91	349.698
2930.52	350.277
2933.13	348.589
2935.74	344.899
2938.35	337.959
2940.96	329.742
2943.57	319.218
2946.18	307.972
2948.78	296.292
2951.39	284.163
2953.99	270.102
2956.59	257.428
2959.2	244.019
2961.8	230.507
2964.4	217.036
2967	204.347
2969.6	192.903
2972.19	181.594
2974.79	170.779
2977.39	158.804
2979.98	146.739
2982.58	134.954
2985.17	122.938
2987.76	112.494
2990.35	100.924
2992.94	89.1373
2995.53	77.1439
2998.12	66.395
3000.71	54.7714
3003.3	45.0496
3005.88	36.5607
3008.47	29.3892
3011.05	23.4941
3013.64	18.7048
3016.22	13.8451
3018.8	9.69565
3021.38	7.01315
3023.96	4.51909
3026.54	2.35095
3029.12	1.55044
3031.69	1.19789
3034.27	1.47604
3036.84	0.334643
3039.42	0.597151
3041.99	1.50771
3044.57	2.38351
3047.14	4.03506
3049.71	6.84412
3052.28	7.36172
3054.85	6.52243
3057.41	6.52606
3059.98	7.09929
3062.55	6.94564
3065.11	6.95073
3067.68	6.77897
3070.24	6.48725
3072.8	7.14697
3075.36	7.22372
3077.93	6.76711
3080.49	6.59402
3083.04	6.19553
3085.6	5.81806
3088.16	5.99602
3090.72	6.81318
3093.27	7.22334
3095.83	7.62276
3098.38	9.49379
3100.93	11.3589
3103.49	13.2253
3106.04	15.0725
3108.59	17.892
3111.14	20.5448
3113.69	22.3378
3116.23	23.7385
3118.78	25.7103
3121.33	28.5102
3123.87	30.5149
3126.41	32.8253
3128.96	35.7618
3131.5	39.0342
3134.04	42.102
3136.58	45.2859
3139.12	47.7909
3141.66	50.3941
3144.2	53.4141
3146.74	56.9704
3149.27	60.5475