File: data/Raman/poly_smoothed/Mb_20_23_37_1x_45s_532 nm_x100_100%_600 gr_mm_01.txt
#Acq. time (s)=	45
#Accumulations=	2
#Range (cm-¹)=	200...3150
#Windows=	2
#Auto scanning=	Off
#Autofocus=	Off
#Macrospot=	Off
#AutoExposure=	Off
#Spike filter=	Multiple accum.
#Delay time (s)=	0
#Binning=	1
#Readout mode=	Signal
#DeNoise=	Off
#ICS correction=	On
#Dark correction=	Off
#Inst. Process=	Off
#Detector Gain=	Best Dynamic Range
#Detector ADC=	20 kHz
#Detector temperature (°C)=	-69.85
#Instrument=	LabRAM HR Evol
#Detector=	Synapse
#Objective=	x100
#Grating=	600 gr/mm
#ND Filter=	100%
#Laser (nm)=	532
#Hole=	100.021
#Range=	Auto
#Laser Pol.=	No
#Raman. Pol.=	No
#Laser Pol. (°)=	-0.0007625
#Raman Pol. (°)=	89.9995
#Collection=	Microscope
#StageXY=	Marzhauser
#StageZ=	Marzhauser
#X (µm)=	-6978.8
#Y (µm)=	1939.5
#Z (µm)=	-75.2
#Full time(mm:ss)=	3:18
#Project=
#Sample=
#Site=
#Title=	Mb_20_23_37_2x_45s_532 nm_x100_100%_600 gr_mm
#Remark=
#Date=	13.07.2022 16:03
#Acquired=	13.07.2022 16:03:10
#Base:Fit=	10.08.2022 10:29:37
#Base:Sub=	10.08.2022 10:34:43
#Filter:Polynom=	16.08.2022 10:13:29
#AxisType[0]=Intens
#AxisUnit[0]=Cnt
#AxisType[1]=Spectr
#AxisUnit[1]=1/cm
200.563	16.9538
204.194	12.8521
207.821	11.7649
211.449	11.7116
215.074	10.9105
218.699	10.6747
222.321	9.1995
225.941	9.86754
229.562	9.93157
233.18	9.86344
236.796	11.2866
240.411	12.1964
244.026	12.4165
247.638	13.029
251.248	12.3898
254.857	11.6924
258.465	11.4663
262.071	10.556
265.678	9.39277
269.282	9.07175
272.884	7.65781
276.484	7.22126
280.084	6.54606
283.682	8.92354
287.276	9.79795
290.871	9.96921
294.465	11.5116
298.057	12.842
301.648	13.9861
305.237	14.8759
308.823	15.9839
312.41	19.1344
315.995	20.8981
319.579	23.4865
323.16	26.6501
326.741	28.3134
330.321	29.1711
333.897	28.898
337.474	28.8185
341.048	27.8009
344.622	27.493
348.192	25.792
351.764	25.2643
355.332	24.7095
358.901	23.0207
362.466	21.8825
366.03	21.1946
369.594	21.247
373.155	21.0631
376.715	18.3696
380.273	19.0088
383.832	18.5083
387.388	17.5135
390.942	17.403
394.495	16.9575
398.047	17.088
401.597	19.0595
405.145	19.4062
408.693	18.8207
412.239	19.4262
415.783	16.5805
419.327	13.8719
422.869	14.4836
426.409	14.1065
429.948	15.1093
433.486	13.1141
437.022	13.3969
440.558	13.7742
444.089	13.3516
447.622	13.7747
451.153	14.3327
454.682	14.8992
458.208	15.1399
461.735	14.1924
465.259	14.9053
468.783	14.4245
472.306	15.4775
475.825	16.2631
479.346	16.9026
482.862	17.1002
486.38	18.0213
489.894	17.5158
493.407	16.3852
496.92	17.3631
500.43	17.7179
503.939	17.6203
507.448	19.3703
510.954	18.5652
514.459	19.6173
517.962	19.9346
521.466	19.0973
524.966	19.1387
528.466	19.4271
531.964	17.8812
535.46	17.7982
538.955	17.9478
542.449	17.4051
545.942	17.8501
549.433	18.9773
552.923	19.0023
556.412	18.9943
559.899	18.3612
563.385	17.4902
566.867	15.2951
570.35	15.2781
573.832	14.6715
577.313	14.2732
580.79	14.6766
584.268	14.5394
587.745	12.0554
591.218	9.50536
594.692	7.07224
598.164	5.98451
601.634	6.14821
605.104	4.55913
608.57	4.73804
612.037	3.31777
615.501	2.29972
618.966	1.28303
622.427	2.50716
625.887	1.70801
629.348	1.31956
632.806	2.45657
636.262	2.67316
639.716	2.36824
643.172	1.83942
646.624	2.04803
650.075	3.55555
653.524	4.06773
656.972	5.18294
660.419	5.4643
663.865	7.26695
667.309	6.19881
670.752	4.39229
674.194	4.36052
677.634	5.44587
681.073	6.30394
684.511	6.48862
687.947	7.1194
691.382	8.38457
694.816	8.80523
698.247	8.56689
701.678	10.4581
705.108	12.0358
708.534	12.799
711.962	13.4226
715.388	14.8446
718.81	17.0484
722.234	18.7377
725.654	18.8265
729.075	20.1911
732.492	22.6096
735.91	25.3356
739.325	26.2132
742.741	28.5485
746.153	30.5357
749.564	31.7658
752.976	34.1579
756.385	35.9932
759.792	38.4533
763.2	43.1043
766.604	44.7235
770.008	47.4679
773.41	48.5419
776.811	51.5718
780.21	53.671
783.608	57.8159
787.005	60.0648
790.401	62.099
793.795	64.2607
797.188	66.4257
800.58	69.0526
803.971	72.357
807.36	72.7911
810.748	75.7487
814.135	77.2507
817.518	78.6554
820.902	79.0607
824.285	80.1317
827.665	80.2573
831.045	81.5077
834.424	80.7134
837.8	81.4221
841.177	79.2455
844.55	80.1185
847.924	80.0423
851.295	75.8975
854.666	74.5338
858.034	73.6121
861.403	74.1401
864.769	73.7588
868.133	71.0148
871.498	70.6009
874.86	70.4836
878.221	68.9204
881.58	68.7986
884.938	66.7581
888.297	64.8591
891.653	62.8589
895.007	59.5837
898.36	57.4059
901.712	54.1603
905.063	51.7687
908.412	49.1359
911.76	46.6042
915.107	44.4212
918.452	42.8474
921.797	43.6581
925.138	41.7606
928.48	40.4108
931.82	38.7659
935.16	38.0047
938.496	37.7729
941.833	36.4091
945.168	35.8778
948.5	33.0836
951.834	32.2559
955.163	31.5346
958.494	27.4503
961.821	24.9825
965.15	23.2146
968.474	20.4626
971.8	19.0191
975.123	19.4684
978.446	17.3538
981.766	15.9957
985.084	14.9988
988.402	14.939
991.72	16.1001
995.035	16.4268
998.349	17.0345
1001.66	21.4967
1004.97	25.3429
1008.28	27.6838
1011.59	31.9907
1014.9	32.6753
1018.21	33.8537
1021.51	37.5797
1024.81	40.7404
1028.12	42.6146
1031.42	46.0049
1034.72	47.64
1038.02	49.3988
1041.31	52.7506
1044.61	56.3849
1047.91	58.7756
1051.2	60.1925
1054.49	61.8405
1057.78	61.4892
1061.07	61.6871
1064.36	61.6287
1067.65	61.3935
1070.93	59.7793
1074.22	57.8345
1077.5	55.2585
1080.78	55.3638
1084.06	53.2032
1087.34	49.7865
1090.62	47.1165
1093.9	43.5922
1097.17	41.1679
1100.45	40.7417
1103.72	39.8564
1106.99	37.1453
1110.27	34.446
1113.53	32.8961
1116.8	32.1097
1120.07	31.217
1123.33	30.0181
1126.6	28.424
1129.86	28.3182
1133.12	27.5503
1136.38	26.1024
1139.64	25.0894
1142.9	23.5233
1146.16	21.6834
1149.41	18.4167
1152.67	16.0027
1155.92	13.1292
1159.17	10.0923
1162.42	8.67048
1165.67	7.92745
1168.92	8.43628
1172.16	10.126
1175.41	9.35591
1178.65	9.18092
1181.9	10.343
1185.14	8.47513
1188.38	9.30692
1191.62	10.4288
1194.86	10.8798
1198.09	13.3145
1201.33	14.5915
1204.56	16.5127
1207.8	19.6282
1211.03	21.1848
1214.26	21.6133
1217.49	25.9112
1220.71	29.1957
1223.94	32.915
1227.16	36.0331
1230.39	38.8506
1233.61	41.8723
1236.83	45.3516
1240.05	49.1029
1243.27	53.2078
1246.49	58.5777
1249.71	61.0783
1252.92	62.6852
1256.14	64.2352
1259.35	66.852
1262.56	73.0092
1265.77	76.7589
1268.98	83.5142
1272.19	90.6175
1275.4	96.9497
1278.6	104.792
1281.81	111.066
1285.01	118.044
1288.21	123.904
1291.41	128.171
1294.61	132.497
1297.81	136.02
1301.01	138.416
1304.2	138.071
1307.4	138.678
1310.59	136.957
1313.78	133.301
1316.97	130.932
1320.16	125.987
1323.35	121.574
1326.54	115.992
1329.72	107.677
1332.91	101.478
1336.09	95.2556
1339.27	91.2891
1342.45	88.5186
1345.64	86.7146
1348.81	84.3141
1351.99	83.8863
1355.17	82.0416
1358.34	80.7852
1361.51	78.8278
1364.69	78.5136
1367.86	77.3477
1371.03	75.663
1374.2	74.7622
1377.37	75.6167
1380.53	72.0943
1383.7	72.5514
1386.86	71.4653
1390.02	70.2748
1393.19	70.432
1396.35	68.8497
1399.51	68.7363
1402.66	73.5462
1405.82	80.8912
1408.97	88.2318
1412.13	99.5279
1415.28	111.515
1418.43	128.536
1421.59	144.784
1424.73	160.663
1427.88	176.241
1431.03	191.498
1434.18	205.534
1437.32	216.814
1440.46	228.721
1443.61	235.813
1446.75	237.386
1449.89	234.035
1453.03	229.713
1456.16	219.706
1459.3	208.109
1462.44	194.837
1465.57	178.214
1468.7	159.916
1471.83	140.453
1474.96	124.307
1478.09	110.56
1481.22	99.0798
1484.35	85.4754
1487.47	73.7889
1490.6	65.2329
1493.72	57.8923
1496.84	51.5569
1499.96	46.403
1503.08	43.8517
1506.2	41.6871
1509.32	41.0397
1512.44	39.6309
1515.55	37.7324
1518.66	37.2466
1521.78	34.5401
1524.89	33.6078
1528	33.782
1531.11	33.9093
1534.21	34.3192
1537.32	35.1876
1540.43	37.4347
1543.53	39.479
1546.63	40.7951
1549.74	43.0994
1552.84	44.0968
1555.94	44.1116
1559.03	45.2435
1562.13	46.8053
1565.23	50.0041
1568.32	53.0871
1571.42	57.561
1574.51	61.2939
1577.6	66.182
1580.69	69.5196
1583.78	72.2265
1586.87	76.4103
1589.95	78.7461
1593.04	81.6304
1596.12	84.547
1599.21	86.3025
1602.29	86.567
1605.37	88.1812
1608.45	88.0451
1611.53	87.5545
1614.6	88.2299
1617.68	85.2967
1620.75	84.9273
1623.83	83.9547
1626.9	82.9604
1629.97	81.231
1633.04	81.0567
1636.11	80.0467
1639.18	81.3642
1642.25	81.8982
1645.31	82.6044
1648.38	82.7627
1651.44	83.2419
1654.5	82.6119
1657.56	81.7082
1660.62	80.3947
1663.68	77.8876
1666.74	75.7084
1669.8	72.3886
1672.85	69.4715
1675.91	64.7096
1678.96	61.9334
1682.01	57.851
1685.06	55.1921
1688.11	51.327
1691.16	48.0082
1694.21	46.5153
1697.25	45.2647
1700.3	44.2882
1703.34	42.4766
1706.39	41.097
1709.43	40.7621
1712.47	39.8652
1715.51	40.6117
1718.54	39.9976
1721.58	40.1266
1724.62	39.9764
1727.65	40.8903
1730.68	39.3961
1733.72	38.912
1736.75	37.3406
1739.78	35.4757
1742.81	34.414
1745.84	31.5193
1748.86	29.3272
1751.89	27.795
1754.91	26.5188
1757.93	24.4032
1760.96	22.2087
1763.98	20.9469
1767	19.2812
1770.02	18.5067
1773.03	17.6644
1776.05	17.1961
1779.07	16.3951
1782.08	15.7232
1785.09	15.5714
1788.11	14.8617
1791.12	15.4008
1794.13	15.8393
1797.13	16.3164
1800.14	15.887
1803.15	15.6833
1806.15	15.6836
1809.16	14.8592
1812.16	14.4282
1815.16	13.3594
1818.16	12.1575
1821.16	11.7576
1824.16	12.757
1827.16	12.4467
1830.16	11.7501
1833.15	11.7951
1836.14	11.749
1839.14	11.4868
1842.13	11.9685
1845.12	11.3775
1848.11	10.0963
1851.1	9.71196
1854.08	7.87464
1857.07	6.47808
1860.05	5.23826
1863.04	4.25965
1866.02	3.62779
1869	2.28519
1871.98	2.05314
1874.96	2.8366
1877.94	2.53652
1880.92	1.99768
1882.51	2.01319
1885.5	3.74923
1888.48	4.10288
1891.47	5.06628
1894.46	6.25195
1897.44	6.55758
1900.42	7.1439
1903.41	7.79466
1906.39	8.72204
1909.37	9.72508
1912.35	9.47757
1915.32	10.1939
1918.3	9.73619
1921.27	9.79051
1924.25	10.3934
1927.22	11.0026
1930.19	11.1196
1933.17	10.1681
1936.14	9.8622
1939.11	9.53529
1942.07	10.3133
1945.04	10.5304
1948.01	9.93577
1950.97	9.38341
1953.93	8.23738
1956.9	8.38147
1959.86	7.7801
1962.82	6.27591
1965.78	5.57202
1968.74	5.43211
1971.69	5.27007
1974.65	4.01832
1977.6	4.30888
1980.56	3.79044
1983.51	4.6727
1986.46	4.18095
1989.41	4.05307
1992.36	4.30191
1995.31	4.5574
1998.26	5.42995
2001.2	3.17548
2004.15	4.28111
2007.09	5.0056
2010.04	5.0919
2012.98	5.17219
2015.92	5.48572
2018.86	5.74445
2021.8	5.72435
2024.73	5.60281
2027.67	6.06134
2030.61	7.11086
2033.54	7.18092
2036.47	8.61121
2039.4	7.71556
2042.33	8.37537
2045.27	8.85947
2048.19	8.13399
2051.12	8.67712
2054.05	8.39102
2056.97	9.32452
2059.9	8.89727
2062.82	9.64562
2065.74	10.0936
2068.67	9.65814
2071.59	9.27767
2074.51	9.83693
2077.42	10.2471
2080.34	9.39554
2083.26	9.39334
2086.17	9.68062
2089.09	9.17358
2092	9.06163
2094.91	10.1652
2097.82	10.3683
2100.73	10.6756
2103.64	10.3114
2106.55	10.2829
2109.45	10.206
2112.36	11.0066
2115.26	11.8391
2118.17	12.164
2121.07	13.3148
2123.97	15.3869
2126.87	17.2207
2129.77	17.8134
2132.67	20.2271
2135.56	22.0667
2138.46	23.7875
2141.35	25.6964
2144.25	27.7265
2147.14	29.0764
2150.03	29.9526
2152.92	31.4521
2155.81	33.4458
2158.7	34.7732
2161.59	36.6581
2164.47	37.9256
2167.36	38.9994
2170.24	39.1335
2173.13	38.6829
2176.01	39.306
2178.89	39.1439
2181.77	38.5888
2184.65	38.8993
2187.53	38.1128
2190.4	37.3574
2193.28	36.6916
2196.16	32.7672
2199.03	30.8085
2201.9	30.0612
2204.77	29.0364
2207.64	27.3248
2210.51	24.6877
2213.38	23.2381
2216.25	21.0422
2219.12	19.7856
2221.98	18.828
2224.85	18.2272
2227.71	18.0977
2230.57	17.8503
2233.43	17.4316
2236.29	16.3025
2239.15	16.14
2242.01	16.1231
2244.87	17.0839
2247.72	16.4171
2250.58	17.3164
2253.43	17.2916
2256.29	16.3219
2259.14	16.2178
2261.99	15.4403
2264.84	13.6122
2267.69	11.9739
2270.53	11.3417
2273.38	10.4818
2276.23	9.53174
2279.07	8.29768
2281.91	7.77717
2284.76	6.8571
2287.6	6.88659
2290.44	5.88375
2293.28	3.83682
2296.12	3.87915
2298.96	3.28377
2301.79	2.95266
2304.63	3.6166
2307.46	4.25511
2310.3	6.26047
2313.13	6.41132
2315.96	6.00223
2318.79	6.32749
2321.62	7.05657
2324.45	5.78885
2327.27	6.44151
2330.1	5.39704
2332.92	4.52127
2335.75	3.49523
2338.57	4.05374
2341.39	4.76177
2344.21	3.33738
2347.04	3.60703
2349.85	3.42316
2352.67	4.15609
2355.49	3.11246
2358.3	3.04443
2361.12	1.76052
2363.93	2.64217
2366.75	3.79726
2369.56	3.85452
2372.37	4.47964
2375.18	5.92105
2377.99	5.59703
2380.8	6.38388
2383.6	5.56273
2386.41	6.15964
2389.21	6.1595
2392.02	5.18864
2394.82	4.31783
2397.62	3.71595
2400.42	2.21424
2403.22	1.4305
2406.02	1.65614
2408.82	1.45979
2411.62	-0.0553411
2414.41	-0.378181
2417.21	-0.270811
2420	0.435745
2422.79	0.233351
2425.59	-0.196024
2428.38	-0.441097
2431.17	-0.198543
2433.95	0.022423
2436.74	0.534405
2439.53	0.25
2442.31	0.538938
2445.1	0.233016
2447.88	1.3082
2450.67	1.43204
2453.45	1.95816
2456.23	2.30679
2459.01	1.3728
2461.79	1.17662
2464.57	1.07782
2467.34	1.36234
2470.12	1.05512
2472.89	1.69228
2475.67	2.61332
2478.44	2.29206
2481.21	2.98049
2483.98	3.27667
2486.75	3.28223
2489.52	3.93471
2492.29	3.56202
2495.05	3.15844
2497.82	3.78004
2500.58	3.05067
2503.35	2.1411
2506.11	2.63069
2508.87	2.18983
2511.63	2.47947
2514.39	3.33669
2517.15	3.17505
2519.91	3.07471
2522.67	2.53547
2525.42	1.33862
2528.18	1.1659
2530.93	1.66905
2533.69	1.51177
2536.44	1.56
2539.19	2.13032
2541.94	2.90029
2544.69	3.74235
2547.44	3.71669
2550.18	3.76808
2552.93	4.17882
2555.67	4.95167
2558.42	4.6767
2561.16	4.45875
2563.9	4.30937
2566.64	3.86837
2569.38	3.98195
2572.12	4.38725
2574.86	5.89286
2577.6	6.07215
2580.33	6.62228
2583.07	5.93932
2585.8	5.77683
2588.54	5.15074
2591.27	4.50904
2594	3.8712
2596.73	3.9044
2599.46	3.11726
2602.19	4.10615
2604.92	5.22801
2607.64	5.92851
2610.37	6.24291
2613.09	6.10156
2615.82	6.14577
2618.54	5.90261
2621.26	6.73825
2623.98	7.0168
2626.7	7.44415
2629.42	9.80535
2632.14	9.63683
2634.86	11.4534
2637.57	12.6748
2640.29	13.3813
2643	14.4058
2645.71	15.2533
2648.43	15.7242
2651.14	16.0558
2653.85	16.7062
2656.56	15.8344
2659.26	16.3696
2661.97	16.0988
2664.68	16.3792
2667.38	16.5005
2670.09	15.36
2672.79	14.5027
2675.49	13.4363
2678.19	12.9023
2680.89	12.7218
2683.59	13.1338
2686.29	13.2476
2688.99	13.2393
2691.69	13.9451
2694.38	15.6009
2697.08	16.3868
2699.77	16.2627
2702.46	16.7441
2705.15	17.6283
2707.85	20.0183
2710.54	21.7071
2713.22	23.2853
2715.91	24.7367
2718.6	24.3416
2721.29	25.3108
2723.97	24.9757
2726.66	24.7975
2729.34	24.28
2732.02	23.1059
2734.7	21.1284
2737.38	19.5696
2740.06	19.4609
2742.74	17.625
2745.42	16.5932
2748.09	14.8443
2750.77	14.0547
2753.45	10.8985
2756.12	9.40388
2758.79	8.80999
2761.46	7.35111
2764.14	5.52306
2766.8	3.20425
2769.47	3.24122
2772.14	3.31233
2774.81	2.6131
2777.48	3.64435
2780.14	3.17313
2782.8	2.69369
2785.47	2.41872
2788.13	4.06581
2790.79	3.51639
2793.45	4.25994
2796.11	4.71642
2798.77	4.66387
2801.43	4.68225
2804.09	4.42594
2806.74	2.98523
2809.4	2.09273
2812.05	-0.0710111
2814.71	0.102372
2817.36	2.49021
2820.01	8.51979
2822.66	21.3917
2825.31	36.4266
2827.96	55.68
2830.6	77.0054
2833.25	100.516
2835.9	124.957
2838.54	149.866
2841.18	176.599
2843.83	203.069
2846.47	228.955
2849.11	255.086
2851.75	280.152
2854.39	304.127
2857.03	325.017
2859.66	343.725
2862.3	359.207
2864.94	371.436
2867.57	381.427
2870.2	388.025
2872.84	394.286
2875.47	397.494
2878.1	402.024
2880.73	407.687
2883.36	417.022
2885.99	426.758
2888.61	436.682
2891.24	444.847
2893.86	452.748
2896.49	460.655
2899.11	468.339
2901.73	474.607
2904.36	481.179
2906.98	490.674
2909.6	499.232
2912.21	507.751
2914.83	515.424
2917.45	521.976
2920.07	525.433
2922.68	525.001
2925.29	520.404
2927.91	515.383
2930.52	507.044
2933.13	495.696
2935.74	483.456
2938.35	468.914
2940.96	452.932
2943.57	436.326
2946.18	415.85
2948.78	395.732
2951.39	372.617
2953.99	351.012
2956.59	327.669
2959.2	306.214
2961.8	286.755
2964.4	266.431
2967	248.133
2969.6	232.343
2972.19	218.432
2974.79	202.418
2977.39	187.611
2979.98	171.897
2982.58	155.769
2985.17	138.652
2987.76	123.065
2990.35	107.767
2992.94	93.4847
2995.53	80.4775
2998.12	68.9355
3000.71	58.1502
3003.3	48.4955
3005.88	39.7249
3008.47	30.6613
3011.05	23.3899
3013.64	17.4942
3016.22	12.0927
3018.8	7.22591
3021.38	4.49779
3023.96	1.55468
3026.54	0.435639
3029.12	-0.783721
3031.69	-1.21395
3034.27	-0.897054
3036.84	-0.427518
3039.42	-0.67581
3041.99	-0.383372
3044.57	0.310701
3047.14	1.48049
3049.71	2.41209
3052.28	2.59255
3054.85	2.64202
3057.41	3.39007
3059.98	3.57877
3062.55	3.71058
3065.11	3.65939
3067.68	3.3174
3070.24	2.60134
3072.8	1.92958
3075.36	2.25259
3077.93	2.44484
3080.49	2.14485
3083.04	0.404398
3085.6	0.516908
3088.16	1.36166
3090.72	1.80683
3093.27	2.76632
3095.83	3.48038
3098.38	4.61305
3100.93	4.9711
3103.49	6.45687
3106.04	8.87543
3108.59	10.299
3111.14	11.6855
3113.69	13.2459
3116.23	14.9508
3118.78	17.2656
3121.33	19.2748
3123.87	21.1627
3126.41	23.1388
3128.96	24.8266
3131.5	27.3207
3134.04	29.6698
3136.58	32.6928
3139.12	36.0531
3141.66	38.0809
3144.2	41.2581
3146.74	45.2497
3149.27	48.281