File: data/Raman/poly_smoothed/Mb_20_23_48_1x_45s_532 nm_x100_100%_600 gr_mm_01.txt
#Acq. time (s)=	45
#Accumulations=	2
#Range (cm-¹)=	200...3150
#Windows=	2
#Auto scanning=	Off
#Autofocus=	Off
#Macrospot=	Off
#AutoExposure=	Off
#Spike filter=	Multiple accum.
#Delay time (s)=	0
#Binning=	1
#Readout mode=	Signal
#DeNoise=	Off
#ICS correction=	On
#Dark correction=	Off
#Inst. Process=	Off
#Detector Gain=	Best Dynamic Range
#Detector ADC=	20 kHz
#Detector temperature (°C)=	-70.08
#Instrument=	LabRAM HR Evol
#Detector=	Synapse
#Objective=	x100
#Grating=	600 gr/mm
#ND Filter=	100%
#Laser (nm)=	532
#Hole=	100.021
#Range=	Auto
#Laser Pol.=	No
#Raman. Pol.=	No
#Laser Pol. (°)=	-0.0007625
#Raman Pol. (°)=	89.9995
#Collection=	Microscope
#StageXY=	Marzhauser
#StageZ=	Marzhauser
#X (µm)=	494.2
#Y (µm)=	2964.3
#Z (µm)=	-9.25
#Full time(mm:ss)=	3:18
#Project=
#Sample=
#Site=
#Title=	Mb_20_23_48_2x_45s_532 nm_x100_100%_600 gr_mm
#Remark=
#Date=	14.07.2022 10:00
#Acquired=	14.07.2022 10:00:26
#Base:Fit=	10.08.2022 10:29:37
#Base:Sub=	10.08.2022 10:35:48
#Filter:Polynom=	16.08.2022 10:13:29
#AxisType[0]=Intens
#AxisUnit[0]=Cnt
#AxisType[1]=Spectr
#AxisUnit[1]=1/cm
200.554	31.0781
204.183	28.5704
207.813	25.4318
211.439	20.223
215.065	16.5367
218.688	14.5654
222.312	14.5294
225.933	11.2381
229.552	8.16386
233.171	6.83756
236.787	6.28617
240.402	6.23617
244.015	5.81386
247.627	5.96791
251.24	5.96991
254.849	7.12375
258.457	7.6103
262.063	6.25629
265.668	7.05283
269.271	7.72215
272.873	8.5558
276.474	8.7302
280.073	7.39394
283.671	6.70134
287.268	6.40822
290.863	5.40208
294.456	3.86467
298.049	4.40716
301.637	6.02711
305.227	7.45891
308.815	10.9082
312.402	9.0012
315.987	8.52043
319.569	9.84254
323.151	10.4822
326.733	12.8282
330.31	15.0812
333.889	15.3944
337.464	16.5645
341.039	16.2855
344.611	16.747
348.184	18.0712
351.754	15.1351
355.324	13.5388
358.89	10.6697
362.455	10.5876
366.021	8.53672
369.584	6.95878
373.145	6.09942
376.707	4.96644
380.265	3.57495
383.822	3.63399
387.378	3.68957
390.934	3.31998
394.487	2.38472
398.038	1.96989
401.588	1.15705
405.137	1.76811
408.685	1.96432
412.23	2.78706
415.775	3.17223
419.318	4.23934
422.86	3.94227
426.401	3.68236
429.94	3.85768
433.478	5.66162
437.012	5.25563
440.547	5.06371
444.081	6.22027
447.613	7.96119
451.142	10.6368
454.672	11.3409
458.2	12.4358
461.725	14.3761
465.251	14.8678
468.775	15.7163
472.296	17.7991
475.817	18.4628
479.335	18.7958
482.854	19.4728
486.37	19.4519
489.886	19.5739
493.398	19.1657
496.91	19.2949
500.422	19.2943
503.93	18.6992
507.438	18.96
510.946	17.7156
514.45	16.4951
517.954	18.456
521.456	17.7555
524.956	16.8742
528.456	16.3215
531.956	14.0386
535.452	13.3491
538.947	13.1482
542.441	11.1347
545.934	10.2259
549.425	9.18239
552.915	7.49041
556.403	6.8494
559.889	5.49851
563.375	3.84783
566.859	4.56644
570.342	4.15189
573.824	3.58747
577.303	3.70849
580.782	4.22325
584.26	6.02194
587.734	4.44747
591.21	5.32225
594.684	5.06672
598.154	6.3358
601.626	8.16413
605.094	7.55346
608.562	7.194
612.027	6.80401
615.493	5.42136
618.956	5.71709
622.419	5.00079
625.879	4.03738
629.338	3.83175
632.797	3.08355
636.254	1.53095
639.708	1.12804
643.162	1.49177
646.614	0.80128
650.067	1.86422
653.516	2.17471
656.964	3.49346
660.411	4.00083
663.857	4.4741
667.301	4.57362
670.744	4.40189
674.186	3.91123
677.626	5.66059
681.065	7.40354
684.503	6.13536
687.939	6.92543
691.372	8.05588
694.806	8.45932
698.239	8.8779
701.67	10.4042
705.098	9.74683
708.526	10.2244
711.954	11.2895
715.378	12.9526
718.802	11.911
722.226	13.6166
725.646	15.7172
729.067	16.7582
732.484	18.6451
735.902	20.6093
739.317	23.7196
742.731	26.9988
746.145	29.1491
749.556	31.5095
752.966	35.1138
756.377	38.5515
759.784	40.9106
763.19	44.0641
766.594	44.4044
770	48.3191
773.402	51.7814
776.803	55.1061
780.202	57.7137
783.6	59.4785
786.997	61.0903
790.393	62.8789
793.787	64.0215
797.18	65.3621
800.572	66.9627
803.963	68.7547
807.35	70.5246
810.738	70.9823
814.125	71.5532
817.51	73.7005
820.894	73.4098
824.275	73.0484
827.657	73.0572
831.037	72.2336
834.414	72.3896
837.792	71.2947
841.167	67.9404
844.542	67.9592
847.914	66.9053
851.287	65.582
854.656	63.9637
858.026	64.4022
861.393	62.4646
864.761	60.6436
868.125	58.9237
871.489	57.404
874.85	55.4039
878.213	53.5555
881.572	51.3916
884.931	51.6119
888.287	50.8287
891.643	49.8959
894.997	49.551
898.352	49.5407
901.704	48.2334
905.055	46.6541
908.404	47.6748
911.75	48.4899
915.097	47.5994
918.443	49.8075
921.787	49.9006
925.13	51.7027
928.472	51.3901
931.813	48.9685
935.15	48.0855
938.488	45.8599
941.825	44.6507
945.158	41.581
948.493	41.0571
951.824	39.2922
955.156	37.8116
958.486	34.1389
961.814	31.8953
965.142	31.9444
968.467	32.8955
971.79	33.6305
975.115	34.833
978.436	34.9225
981.756	35.4773
985.077	38.1987
988.394	39.6804
991.71	39.9706
995.025	40.2951
998.341	39.5993
1001.65	40.7657
1004.97	40.8067
1008.28	41.2034
1011.58	41.9265
1014.89	41.7334
1018.2	41.827
1021.5	41.3766
1024.81	46.3546
1028.11	52.4656
1031.41	57.9995
1034.71	61.9292
1038.01	65.9897
1041.31	69.1047
1044.6	74.6987
1047.9	78.9706
1051.19	82.3457
1054.48	84.276
1057.77	83.2535
1061.06	82.3862
1064.35	83.103
1067.64	81.2571
1070.93	79.8251
1074.21	76.5308
1077.49	72.4161
1080.78	69.0423
1084.06	67.068
1087.34	61.6444
1090.61	57.9544
1093.89	56.7311
1097.17	55.3518
1100.44	57.2205
1103.71	60.2899
1106.99	63.6187
1110.26	63.3011
1113.52	62.7422
1116.79	62.1564
1120.06	59.6108
1123.32	57.6152
1126.59	54.3988
1129.85	51.5774
1133.11	47.3667
1136.37	43.6395
1139.63	40.2903
1142.89	37.1778
1146.15	32.3982
1149.4	28.6708
1152.66	23.6516
1155.91	17.6396
1159.16	14.0318
1162.41	8.96735
1165.66	4.03868
1168.91	0.608032
1172.16	2.12801
1175.4	2.07741
1178.65	3.99692
1181.89	3.83094
1185.13	3.84164
1188.37	3.62103
1191.61	3.83977
1194.85	4.06996
1198.08	3.8673
1201.32	4.47116
1204.55	5.27065
1207.79	6.34981
1211.02	9.67273
1214.25	11.3278
1217.48	13.5466
1220.71	16.1247
1223.93	19.3894
1227.16	21.2344
1230.38	22.6951
1233.6	25.1104
1236.83	27.0085
1240.05	28.7441
1243.26	31.7785
1246.48	34.4418
1249.7	36.3818
1252.92	37.8342
1256.13	41.0525
1259.34	46.5667
1262.55	52.7537
1265.76	61.7846
1268.97	69.9939
1272.18	78.8728
1275.39	89.5032
1278.59	97.9
1281.8	105.891
1285	114.625
1288.2	121.01
1291.4	125.69
1294.6	128.636
1297.8	129.845
1301	130.499
1304.19	129.975
1307.39	128.51
1310.58	124.666
1313.77	121.382
1316.96	115.866
1320.15	108.177
1323.34	101.236
1326.53	90.972
1329.72	82.2923
1332.9	75.998
1336.08	73.9167
1339.27	72.6707
1342.45	71.9664
1345.63	71.8391
1348.8	70.9292
1351.98	70.5533
1355.16	68.9643
1358.33	66.9095
1361.51	65.7155
1364.68	65.4269
1367.85	64.2216
1371.02	60.8147
1374.19	60.341
1377.36	61.4004
1380.52	62.7366
1383.69	63.5372
1386.85	63.5302
1390.02	63.8373
1393.18	63.7183
1396.34	62.701
1399.5	63.8587
1402.65	70.1585
1405.81	81.3511
1408.97	94.8433
1412.12	112.181
1415.27	129.125
1418.43	147.944
1421.58	166.795
1424.73	184.537
1427.87	203.317
1431.02	219.868
1434.17	235.44
1437.31	249.302
1440.46	259.535
1443.6	264.993
1446.74	264.922
1449.88	261.741
1453.02	256.19
1456.16	244.894
1459.29	229.289
1462.43	210.959
1465.56	188.591
1468.69	165.861
1471.83	141.969
1474.95	121.759
1478.08	105.45
1481.21	90.6586
1484.34	76.281
1487.47	64.1029
1490.59	50.9658
1493.71	42.6603
1496.84	36.5128
1499.96	30.6259
1503.07	26.8288
1506.19	25.7699
1509.31	23.7572
1512.43	21.9197
1515.54	12.6783
1518.65	6.9591
1521.77	9.83958
1524.88	14.449
1527.99	19.0857
1531.1	24.5644
1534.21	28.0826
1537.31	32.1247
1540.42	37.0248
1543.52	40.204
1546.63	42.4678
1549.73	45.0375
1552.83	47.762
1555.93	48.8387
1559.03	48.5375
1562.12	50.2182
1565.22	50.8976
1568.31	52.0401
1571.41	53.791
1574.5	52.7329
1577.59	53.0149
1580.68	51.6251
1583.77	50.3232
1586.86	46.319
1589.95	42.2884
1593.03	43.144
1596.11	50.6575
1599.2	56.1498
1602.28	57.0064
1605.36	58.8634
1608.44	60.2438
1611.52	60.7811
1614.6	61.2581
1617.67	61.391
1620.75	60.2407
1623.82	61.136
1626.89	61.784
1629.96	60.926
1633.04	59.6598
1636.11	59.8999
1639.17	60.0611
1642.24	60.8123
1645.31	61.4826
1648.37	62.0971
1651.43	61.8654
1654.5	63.1775
1657.56	61.5346
1660.62	60.5405
1663.67	59.9635
1666.73	58.5967
1669.79	55.7517
1672.84	51.8126
1675.9	47.942
1678.95	45.8051
1682	43.3863
1685.05	42.1352
1688.1	38.8163
1691.15	36.1864
1694.2	34.1599
1697.25	31.9691
1700.29	29.2558
1703.33	27.8479
1706.38	26.6781
1709.42	26.1325
1712.46	26.098
1715.5	26.3815
1718.54	27.864
1721.57	28.3378
1724.61	29.4083
1727.64	28.6221
1730.68	28.1495
1733.71	27.9343
1736.74	27.4128
1739.77	25.5766
1742.8	23.3418
1745.83	20.1154
1748.85	18.6658
1751.88	17.5198
1754.91	14.8204
1757.93	11.9704
1760.95	10.6344
1763.97	7.13663
1766.99	4.71681
1770.01	2.90479
1773.03	0.844952
1776.04	-0.304791
1779.06	0.190282
1782.07	0.582931
1785.09	0.643051
1788.1	0.75112
1791.11	1.70891
1794.12	2.25168
1797.13	2.39002
1800.13	1.314
1803.14	1.30535
1806.15	3.25608
1809.15	2.75756
1812.15	1.8934
1815.16	0.941526
1818.15	0.278803
1821.16	0.812101
1824.15	0.907699
1827.15	0.750429
1830.15	1.39368
1833.14	1.77203
1836.14	1.97346
1839.13	2.92393
1842.12	3.14014
1845.11	3.16502
1848.1	3.8445
1851.09	4.63176
1854.08	5.90061
1857.06	6.56135
1860.05	6.61956
1863.03	7.60097
1866.01	7.43746
1869	7.40226
1871.98	7.16131
1874.96	7.08142
1877.93	8.02128
1880.91	8.21266
1882.47	7.44907
1885.46	6.98893
1888.44	7.0766
1891.43	6.74324
1894.42	5.91191
1897.4	5.05858
1900.39	5.22515
1903.37	4.06991
1906.35	3.47179
1909.33	2.29904
1912.31	1.68644
1915.29	1.56896
1918.26	1.37058
1921.24	2.12927
1924.21	1.97235
1927.19	2.05416
1930.16	2.21982
1933.13	2.89227
1936.1	2.76225
1939.07	1.03847
1942.04	1.06868
1945	1.68067
1947.97	2.31029
1950.93	3.59738
1953.9	4.47174
1956.86	4.14243
1959.82	5.13125
1962.78	5.13004
1965.74	5.41908
1968.7	4.95511
1971.65	4.49828
1974.61	4.3761
1977.57	3.90788
1980.52	3.57921
1983.47	5.01276
1986.42	5.67487
1989.37	7.10989
1992.32	6.59213
1995.27	7.38976
1998.22	7.713
2001.17	9.11053
2004.11	9.6457
2007.05	10.57
2010	10.0669
2012.94	11.409
2015.88	12.9168
2018.82	12.8066
2021.76	13.8054
2024.7	14.7023
2027.63	15.6785
2030.57	15.7846
2033.5	14.4421
2036.44	14.501
2039.37	13.7121
2042.3	13.5931
2045.23	13.6777
2048.16	14.4005
2051.08	14.5607
2054.01	14.7997
2056.94	14.4976
2059.86	13.5616
2062.79	12.5795
2065.71	13.1128
2068.63	13.3447
2071.55	14.0841
2074.47	15.0657
2077.39	15.8337
2080.31	15.7666
2083.22	16.8606
2086.13	17.2082
2089.05	16.4751
2091.96	17.7271
2094.87	17.5444
2097.78	17.9625
2100.69	17.5384
2103.6	17.8005
2106.51	19.2917
2109.42	20.2302
2112.32	21.0714
2115.23	21.4036
2118.13	21.8589
2121.03	22.3328
2123.93	22.1564
2126.83	23.2906
2129.73	24.0357
2132.63	25.3687
2135.53	27.4382
2138.42	28.9329
2141.32	30.3437
2144.21	31.8849
2147.1	33.6686
2150	35.2341
2152.89	36.2864
2155.78	37.9756
2158.66	40.2443
2161.55	41.9373
2164.44	42.8337
2167.32	42.7216
2170.21	43.6282
2173.09	44.6682
2175.97	44.9772
2178.85	44.3562
2181.73	43.7174
2184.61	41.231
2187.49	39.9933
2190.37	38.1684
2193.24	37.8699
2196.12	37.3331
2198.99	37.2904
2201.87	36.5716
2204.74	34.9239
2207.61	33.6033
2210.48	32.5305
2213.35	29.9031
2216.21	29.1385
2219.08	29.143
2221.95	28.8896
2224.81	28.9148
2227.67	28.6974
2230.54	27.8181
2233.4	26.0461
2236.26	25.4724
2239.11	25.0956
2241.97	23.9559
2244.83	24.3414
2247.69	24.1357
2250.54	23.2929
2253.4	22.6931
2256.25	21.3838
2259.1	20.6261
2261.95	19.4922
2264.8	19.7549
2267.65	19.434
2270.5	18.527
2273.34	17.4435
2276.19	16.5564
2279.03	16.0156
2281.88	14.0573
2284.72	14.7342
2287.56	15.0271
2290.4	14.3468
2293.24	12.7441
2296.08	12.9765
2298.92	12.6789
2301.76	13.0658
2304.59	14.0158
2307.43	14.4375
2310.26	14.6691
2313.09	14.5641
2315.92	15.1521
2318.75	15.049
2321.58	14.4059
2324.41	13.0775
2327.24	12.2828
2330.06	9.04474
2332.89	8.55387
2335.71	7.86785
2338.54	6.80421
2341.36	5.72512
2344.18	5.44879
2347	5.35029
2349.82	5.04842
2352.64	4.24977
2355.45	3.92278
2358.27	3.62533
2361.08	3.84056
2363.9	4.7513
2366.71	5.05625
2369.52	5.60675
2372.33	6.58347
2375.14	6.72127
2377.95	7.10579
2380.76	5.50515
2383.57	5.90741
2386.37	5.66624
2389.18	7.54726
2391.98	7.03821
2394.79	6.71229
2397.59	6.24104
2400.39	6.29988
2403.19	6.96809
2405.99	7.62239
2408.78	8.09756
2411.58	10.2632
2414.38	10.5167
2417.17	11.7761
2419.97	10.7237
2422.76	11.5992
2425.55	12.433
2428.34	12.0926
2431.13	12.748
2433.92	12.0379
2436.71	11.6149
2439.49	11.852
2442.28	10.9043
2445.06	10.994
2447.85	10.6494
2450.63	10.2275
2453.41	9.97882
2456.19	9.88745
2458.97	9.53321
2461.75	8.7837
2464.53	8.71028
2467.31	7.43398
2470.08	7.14177
2472.86	5.53619
2475.63	5.75689
2478.4	5.40626
2481.17	4.02575
2483.94	3.76647
2486.72	2.89756
2489.48	2.40221
2492.25	1.95712
2495.02	1.63015
2497.79	1.36243
2500.55	1.26171
2503.31	1.05296
2506.08	1.20488
2508.84	0.731679
2511.6	0.844766
2514.36	0.219085
2517.12	-0.557935
2519.88	-0.739408
2522.63	-0.319326
2525.39	0.483672
2528.14	0.927393
2530.9	1.52309
2533.65	0.989079
2536.4	0.102333
2539.15	0.512928
2541.9	1.18169
2544.65	1.65554
2547.4	1.48317
2550.15	2.7481
2552.89	3.03171
2555.64	4.17123
2558.38	5.32607
2561.12	5.37733
2563.87	5.95178
2566.61	5.44172
2569.35	6.27948
2572.09	6.68235
2574.83	6.76908
2577.56	7.90971
2580.3	8.12813
2583.04	8.41399
2585.77	10.1508
2588.5	9.491
2591.23	10.3121
2593.97	11.5241
2596.7	11.3102
2599.43	11.1973
2602.15	11.1726
2604.88	11.3123
2607.61	11.9934
2610.33	11.9668
2613.06	11.4687
2615.78	11.6097
2618.51	11.6805
2621.23	12.354
2623.95	11.9923
2626.67	11.3067
2629.39	11.1115
2632.1	10.2377
2634.82	10.1705
2637.54	10.8337
2640.25	11.8266
2642.97	12.4904
2645.68	12.6637
2648.39	12.9852
2651.1	13.4925
2653.81	14.06
2656.52	14.3107
2659.23	15.0229
2661.94	15.8921
2664.64	15.667
2667.35	14.721
2670.05	14.1441
2672.76	13.9058
2675.46	13.0601
2678.16	12.5595
2680.86	12.3421
2683.56	12.8641
2686.26	14.1997
2688.96	13.8974
2691.65	14.7463
2694.35	16.401
2697.04	18.8502
2699.74	21.1983
2702.43	24.2387
2705.12	28.6956
2707.81	32.6097
2710.5	35.2417
2713.19	37.779
2715.88	39.7841
2718.57	41.2558
2721.25	42.7942
2723.94	43.3877
2726.62	43.1981
2729.3	41.4498
2731.99	38.6259
2734.67	35.0356
2737.35	31.3365
2740.03	28.6263
2742.71	24.7857
2745.38	21.1484
2748.06	17.9458
2750.74	14.8566
2753.41	11.7566
2756.09	8.7342
2758.76	6.75315
2761.43	4.8538
2764.1	2.92272
2766.77	2.5712
2769.44	2.44611
2772.11	2.71147
2774.77	2.15398
2777.44	2.2919
2780.11	2.50995
2782.77	3.51262
2785.43	3.18462
2788.1	3.45646
2790.76	2.95429
2793.42	2.45531
2796.08	2.00721
2798.74	1.48287
2801.4	0.748592
2804.05	-0.753106
2806.71	-3.55427
2809.36	-7.46077
2812.02	-9.19911
2814.67	-6.4602
2817.32	3.48957
2819.97	20.486
2822.62	45.8644
2825.27	77.3095
2827.92	114.313
2830.57	152.935
2833.22	193.328
2835.86	234.379
2838.51	273.638
2841.15	312.022
2843.79	346.934
2846.43	379.043
2849.08	414.25
2851.72	452.324
2854.36	491.936
2856.99	530.194
2859.63	563.993
2862.27	590.678
2864.9	612.097
2867.54	626.134
2870.17	633.951
2872.8	639.346
2875.43	642.954
2878.07	648.499
2880.7	655.488
2883.32	662.473
2885.95	667.484
2888.58	669.538
2891.21	667.058
2893.83	662.692
2896.46	653.543
2899.08	641.94
2901.7	630.47
2904.32	616.619
2906.94	604.005
2909.56	595.935
2912.18	595.227
2914.8	601.127
2917.42	606.059
2920.03	607.549
2922.65	605.943
2925.26	599.905
2927.88	592.344
2930.49	582.438
2933.1	570.44
2935.71	557.093
2938.32	541.349
2940.93	522.463
2943.54	500.711
2946.14	476.661
2948.75	451.135
2951.35	424.217
2953.96	396.626
2956.56	371.143
2959.16	343.305
2961.77	318.644
2964.37	294.707
2966.96	272.774
2969.56	251.371
2972.16	233.133
2974.76	215
2977.35	197.318
2979.95	179.305
2982.54	161.877
2985.14	143.115
2987.73	126.446
2990.32	111.031
2992.91	97.0696
2995.5	83.7147
2998.09	71.3147
3000.68	60.5668
3003.26	51.2081
3005.85	42.2731
3008.43	33.3838
3011.02	26.5058
3013.6	20.9517
3016.19	16.2324
3018.77	11.9674
3021.35	8.21491
3023.93	5.10509
3026.5	2.97402
3029.08	1.17064
3031.66	0.0598369
3034.24	-0.72809
3036.81	-0.422894
3039.39	-0.0615762
3041.96	0.464506
3044.53	0.835139
3047.1	1.44355
3049.67	0.742629
3052.24	1.76359
3054.81	2.66282
3057.38	2.80454
3059.95	2.87288
3062.52	3.34996
3065.08	3.721
3067.65	4.61553
3070.21	3.86702
3072.77	3.41939
3075.33	3.46531
3077.89	3.63926
3080.45	2.22985
3083.01	1.18703
3085.57	0.0413247
3088.13	-0.862893
3090.68	-0.911957
3093.24	-0.98489
3095.79	-0.378951
3098.35	1.23335
3100.9	2.54672
3103.45	3.57002
3106	5.39746
3108.55	6.70123
3111.1	8.36433
3113.65	11.2496
3116.2	13.8491
3118.75	15.8245
3121.29	18.5053
3123.84	21.162
3126.38	24.3906
3128.92	26.7583
3131.47	29.8006
3134.01	32.1614
3136.55	34.4599
3139.09	36.8658
3141.63	38.0032
3144.17	39.5298
3146.7	41.9921
3149.24	45.112