File: data/Raman/poly_smoothed/Mb_20_23_27_1x_45s_532 nm_x100_100%_600 gr_mm_01.txt
#Acq. time (s)=	45
#Accumulations=	2
#Range (cm-¹)=	200...3150
#Windows=	2
#Auto scanning=	Off
#Autofocus=	Off
#Macrospot=	Off
#AutoExposure=	Off
#Spike filter=	Multiple accum.
#Delay time (s)=	0
#Binning=	1
#Readout mode=	Signal
#DeNoise=	Off
#ICS correction=	On
#Dark correction=	Off
#Inst. Process=	Off
#Detector Gain=	Best Dynamic Range
#Detector ADC=	20 kHz
#Detector temperature (°C)=	-69.85
#Instrument=	LabRAM HR Evol
#Detector=	Synapse
#Objective=	x100
#Grating=	600 gr/mm
#ND Filter=	100%
#Laser (nm)=	532
#Hole=	100.021
#Range=	Auto
#Laser Pol.=	No
#Raman. Pol.=	No
#Laser Pol. (°)=	-0.0007625
#Raman Pol. (°)=	89.9995
#Collection=	Microscope
#StageXY=	Marzhauser
#StageZ=	Marzhauser
#X (µm)=	-6950.3
#Y (µm)=	2018.9
#Z (µm)=	-74.8
#Full time(mm:ss)=	3:18
#Project=
#Sample=
#Site=
#Title=	Mb_20_23_27_2x_45s_532 nm_x100_100%_600 gr_mm
#Remark=
#Date=	13.07.2022 15:15
#Acquired=	13.07.2022 15:15:37
#Base:Fit=	10.08.2022 10:29:37
#Edit:Spike=	10.08.2022 10:33:35
#Edit:Spike=	10.08.2022 10:33:35
#Edit:Spike=	10.08.2022 10:33:36
#Base:Sub=	10.08.2022 10:33:46
#Filter:Polynom=	16.08.2022 10:13:29
#AxisType[0]=Intens
#AxisUnit[0]=Cnt
#AxisType[1]=Spectr
#AxisUnit[1]=1/cm
200.563	88.3624
204.194	82.6581
207.821	73.1399
211.449	62.6513
215.074	55.3451
218.699	49.8808
222.321	42.8707
225.941	39.1729
229.562	37.7971
233.18	33.9582
236.796	28.7404
240.411	27.3066
244.026	25.592
247.638	23.1243
251.248	20.3564
254.857	19.1872
258.465	18.5145
262.071	14.7244
265.678	15.1243
269.282	14.0944
272.884	11.7685
276.484	11.6327
280.084	10.5055
283.682	9.15471
287.276	6.69841
290.871	5.38008
294.465	5.08145
298.057	6.09817
301.648	7.37417
305.237	9.78133
308.823	10.8107
312.41	13.1485
315.995	16.2445
319.579	18.4349
323.16	20.1716
326.741	23.7896
330.321	27.5765
333.897	27.0574
337.474	27.0462
341.048	27.5726
344.622	26.4956
348.192	23.5729
351.764	20.0203
355.332	18.7972
358.901	15.3256
362.466	12.8079
366.03	13.3442
369.594	12.413
373.155	12.3002
376.715	10.5768
380.273	9.88153
383.832	8.2105
387.388	7.81946
390.942	10.0878
394.495	13.254
398.047	16.2028
401.597	20.3097
405.145	23.162
408.693	25.8845
412.239	25.7684
415.783	26.9371
419.327	26.3934
422.869	25.325
426.409	26.2228
429.948	24.6101
433.486	22.7771
437.022	20.8188
440.558	20.8323
444.089	20.0033
447.622	22.0078
451.153	22.1846
454.682	23.4846
458.208	24.5566
461.735	23.815
465.259	23.1822
468.783	25.1751
472.306	29.0918
475.825	32.4792
479.346	36.3535
482.862	40.2023
486.38	42.3646
489.894	42.1856
493.407	40.8702
496.92	42.0993
500.43	41.4627
503.939	45.012
507.448	46.6551
510.954	47.1203
514.459	46.3438
517.962	44.4987
521.466	43.465
524.966	43.6104
528.466	44.7113
531.964	43.3156
535.46	39.3254
538.955	36.4036
542.449	33.1959
545.942	31.3711
549.433	28.2886
552.923	27.5813
556.412	26.5841
559.899	24.4616
563.385	22.2827
566.867	19.8426
570.35	18.7708
573.832	15.6987
577.313	12.4605
580.79	12.6511
584.268	12.4158
587.745	12.1659
591.218	10.5075
594.692	9.26368
598.164	8.17594
601.634	6.51949
605.104	6.52252
608.57	4.1771
612.037	-1.06751
615.501	-0.0577527
618.966	-1.37857
622.427	0.858427
625.887	2.76792
629.348	5.74775
632.806	9.87122
636.262	12.6573
639.716	14.8522
643.172	15.1869
646.624	17.3414
650.075	17.8529
653.524	18.2963
656.972	17.6708
660.419	17.1269
663.865	16.4757
667.309	14.5646
670.752	14.522
674.194	11.1621
677.634	10.3487
681.073	8.10009
684.511	7.58747
687.947	3.54635
691.382	-0.0197104
694.816	-4.51597
698.247	1.34548
701.678	1.94854
705.108	4.46029
708.534	7.03284
711.962	6.59664
715.388	8.34299
718.81	9.58306
722.234	10.0394
725.654	9.9346
729.075	12.1648
732.492	13.7823
735.91	14.7571
739.325	19.1625
742.741	22.3516
746.153	25.6271
749.564	28.8737
752.976	34.2309
756.385	38.3595
759.792	40.9785
763.2	43.5868
766.604	48.3359
770.008	50.4662
773.41	51.5846
776.811	54.2391
780.21	56.3928
783.608	56.3295
787.005	56.9473
790.401	57.5576
793.795	56.1135
797.188	56.6289
800.58	59.3934
803.971	58.4727
807.36	58.7327
810.748	60.0165
814.135	60.7029
817.518	61.3134
820.902	63.9646
824.285	64.3291
827.665	64.4305
831.045	64.4988
834.424	64.571
837.8	64.148
841.177	61.9683
844.55	60.5616
847.924	60.5858
851.295	57.877
854.666	55.6031
858.034	54.3529
861.403	51.0169
864.769	49.397
868.133	48.6939
871.498	49.2001
874.86	47.3367
878.221	44.3498
881.58	44.8792
884.938	45.8115
888.297	45.2623
891.653	45.3432
895.007	44.0038
898.36	43.5687
901.712	40.8849
905.063	39.5673
908.412	37.1111
911.76	34.7139
915.107	33.8139
918.452	30.7376
921.797	29.5612
925.138	28.3783
928.48	27.4891
931.82	25.1622
935.16	23.495
938.496	23.2779
941.833	21.3468
945.168	18.0296
948.5	19.0358
951.834	17.3784
955.163	16.8017
958.494	16.6187
961.821	14.93
965.15	17.4463
968.474	20.2266
971.8	22.7023
975.123	24.8952
978.446	28.462
981.766	30.9113
985.084	34.0784
988.402	37.4534
991.72	37.5892
995.035	37.203
998.349	36.9173
1001.66	37.4931
1004.97	39.0632
1008.28	39.5738
1011.59	42.3422
1014.9	44.6705
1018.21	47.9262
1021.51	50.6819
1024.81	52.0674
1028.12	57.3566
1031.42	63.3119
1034.72	66.7912
1038.02	67.6894
1041.31	68.1163
1044.61	71.9688
1047.91	76.7511
1051.2	81.7108
1054.49	84.5896
1057.78	87.0273
1061.07	87.9134
1064.36	87.9712
1067.65	86.8302
1070.93	83.8713
1074.22	78.063
1077.5	75.2406
1080.78	72.2295
1084.06	67.7083
1087.34	64.8617
1090.62	66.0723
1093.9	65.9366
1097.17	64.3834
1100.45	64.7915
1103.72	64.4247
1106.99	65.0877
1110.27	66.1001
1113.53	64.4978
1116.8	61.7114
1120.07	56.5338
1123.33	54.5249
1126.6	52.8008
1129.86	50.7531
1133.12	46.7153
1136.38	43.7598
1139.64	39.6032
1142.9	36.4279
1146.16	30.8367
1149.41	26.1113
1152.67	21.432
1155.92	16.0981
1159.17	11.1182
1162.42	4.69926
1165.67	0.66189
1168.92	-1.27162
1172.16	-0.97457
1175.41	0.0129996
1178.65	0.840165
1181.9	2.62124
1185.14	3.45395
1188.38	8.46673
1191.62	8.73255
1194.86	10.6191
1198.09	15.4535
1201.33	19.0823
1204.56	25.6174
1207.8	32.8953
1211.03	39.6856
1214.26	47.8159
1217.49	56.271
1220.71	63.4379
1223.94	71.5799
1227.16	77.4412
1230.39	83.8192
1233.61	90.0901
1236.83	93.33
1240.05	96.6787
1243.27	101.046
1246.49	105.108
1249.71	108.899
1252.92	114.358
1256.14	115.299
1259.35	117.379
1262.56	121.39
1265.77	125.41
1268.98	130.251
1272.19	137.571
1275.4	145.958
1278.6	151.834
1281.81	160.143
1285.01	168.09
1288.21	174.438
1291.41	183.456
1294.61	189.783
1297.81	195.566
1301.01	198.472
1304.2	202.777
1307.4	206.25
1310.59	210.04
1313.78	210.143
1316.97	209.399
1320.16	207.571
1323.35	202.463
1326.54	198.242
1329.72	193.224
1332.91	187.507
1336.09	181.866
1339.27	177.739
1342.45	174.66
1345.64	170.314
1348.81	165.823
1351.99	162.395
1355.17	159.349
1358.34	157.226
1361.51	154.078
1364.69	150.564
1367.86	149.765
1371.03	147.988
1374.2	145.849
1377.37	145.819
1380.53	148.456
1383.7	149.879
1386.86	151.618
1390.02	151.834
1393.19	150.534
1396.35	147.417
1399.51	145.902
1402.66	148.464
1405.82	153.055
1408.97	160.491
1412.13	171.486
1415.28	183.994
1418.43	198.815
1421.59	216.884
1424.73	234.715
1427.88	252.454
1431.03	272.296
1434.18	288.54
1437.32	303.001
1440.46	315.241
1443.61	326.431
1446.75	332.809
1449.89	335.79
1453.03	333.503
1456.16	327.831
1459.3	316.597
1462.44	302.01
1465.57	282.165
1468.7	259.529
1471.83	235.029
1474.96	211.454
1478.09	189.588
1481.22	169.273
1484.35	149.61
1487.47	132.611
1490.6	116.538
1493.72	102.399
1496.84	90.1443
1499.96	79.208
1503.08	72.7192
1506.2	66.1503
1509.32	60.4493
1512.44	56.1483
1515.55	53.8891
1518.66	52.7154
1521.78	50.959
1524.89	49.3534
1528	49.2559
1531.11	48.7053
1534.21	50.3058
1537.32	52.9855
1540.43	55.7631
1543.53	58.2358
1546.63	61.6694
1549.74	62.7626
1552.84	67.6188
1555.94	70.9054
1559.03	73.8714
1562.13	76.5354
1565.23	82.0716
1568.32	85.7219
1571.42	90.0192
1574.51	95.4729
1577.6	102.772
1580.69	109.767
1583.78	116.141
1586.87	121.592
1589.95	125.394
1593.04	128.099
1596.12	131.175
1599.21	133.335
1602.29	135.594
1605.37	135.991
1608.45	137.511
1611.53	139.004
1614.6	138.052
1617.68	137.839
1620.75	137.22
1623.83	137.214
1626.9	139.73
1629.97	142.895
1633.04	145.056
1636.11	147.544
1639.18	151.672
1642.25	157.67
1645.31	164.098
1648.38	167.899
1651.44	172.272
1654.5	174.337
1657.56	175.298
1660.62	174.546
1663.68	170.989
1666.74	165.67
1669.8	159.203
1672.85	151.71
1675.91	142.893
1678.96	132.432
1682.01	123.191
1685.06	112.344
1688.11	102.122
1691.16	93.312
1694.21	84.6021
1697.25	75.1087
1700.3	69.3935
1703.34	62.1699
1706.39	57.6151
1709.43	50.9659
1712.47	47.4001
1715.51	44.8402
1718.54	42.5045
1721.58	39.3007
1724.62	37.529
1727.65	36.3486
1730.68	33.6549
1733.72	30.1635
1736.75	29.3103
1739.78	26.2664
1742.81	25.1812
1745.84	24.2555
1748.86	22.1595
1751.89	19.9516
1754.91	17.8817
1757.93	17.9054
1760.96	15.3988
1763.98	15.2832
1767	13.7474
1770.02	11.9435
1773.03	11.0851
1776.05	8.43395
1779.07	6.84557
1782.08	5.48523
1785.09	3.96771
1788.11	4.17019
1791.12	4.30342
1794.13	2.79718
1797.13	3.66303
1800.14	3.48487
1803.15	2.88045
1806.15	2.81276
1809.16	2.77512
1812.16	3.71073
1815.16	3.64349
1818.16	3.99132
1821.16	3.78862
1824.16	1.73724
1827.16	1.4373
1830.16	1.39297
1833.15	1.39767
1836.14	2.18175
1839.14	1.13603
1842.13	1.34322
1845.12	0.896073
1848.11	-0.547865
1851.1	-1.45164
1854.08	-0.719622
1857.07	0.130469
1860.05	1.61484
1863.04	3.27077
1866.02	2.03067
1869	3.11616
1871.98	3.69524
1874.96	3.812
1877.94	4.59462
1880.92	5.20025
1882.51	6.02543
1885.5	7.66335
1888.48	9.48292
1891.47	10.4376
1894.46	10.8254
1897.44	12.1245
1900.42	13.4284
1903.41	15.5433
1906.39	15.0189
1909.37	14.6769
1912.35	13.748
1915.32	14.2541
1918.3	12.7146
1921.27	12.9384
1924.25	12.4298
1927.22	12.1143
1930.19	10.984
1933.17	8.93012
1936.14	6.75166
1939.11	5.14108
1942.07	4.29791
1945.04	2.38456
1948.01	1.74683
1950.97	2.67856
1953.93	3.62605
1956.9	3.50724
1959.86	2.90267
1962.82	4.98511
1965.78	5.21652
1968.74	6.30584
1971.69	7.09928
1974.65	7.27747
1977.6	6.963
1980.56	6.59029
1983.51	5.38737
1986.46	6.91249
1989.41	7.7098
1992.36	7.73605
1995.31	8.11397
1998.26	7.53672
2001.2	6.11397
2004.15	7.24338
2007.09	6.95931
2010.04	7.38701
2012.98	7.38503
2015.92	7.1403
2018.86	6.77098
2021.8	6.14296
2024.73	5.65308
2027.67	5.57235
2030.61	6.179
2033.54	7.15283
2036.47	8.48261
2039.4	8.46327
2042.33	8.56019
2045.27	8.14151
2048.19	8.28705
2051.12	8.63239
2054.05	8.73663
2056.97	10.3013
2059.9	12.3718
2062.82	12.1275
2065.74	12.0261
2068.67	12.2671
2071.59	13.6834
2074.51	14.5152
2077.42	15.1933
2080.34	15.793
2083.26	16.2573
2086.17	16.3198
2089.09	16.3636
2092	15.5568
2094.91	16.426
2097.82	16.5886
2100.73	16.5774
2103.64	17.1185
2106.55	18.4303
2109.45	20.9129
2112.36	21.7529
2115.26	23.8211
2118.17	27.268
2121.07	29.4808
2123.97	31.4218
2126.87	34.6365
2129.77	36.8911
2132.67	40.3591
2135.56	42.6267
2138.46	47.3845
2141.35	52.4798
2144.25	57.9676
2147.14	63.1701
2150.03	67.405
2152.92	72.7316
2155.81	77.0121
2158.7	80.74
2161.59	83.218
2164.47	85.6954
2167.36	88.139
2170.24	89.7392
2173.13	90.2945
2176.01	91.3574
2178.89	91.797
2181.77	90.1489
2184.65	88.98
2187.53	86.8526
2190.4	82.2212
2193.28	78.5527
2196.16	75.1397
2199.03	71.1814
2201.9	66.2019
2204.77	62.3329
2207.64	59.1115
2210.51	56.1059
2213.38	53.2126
2216.25	49.7748
2219.12	46.1707
2221.98	43.572
2224.85	40.8246
2227.71	38.001
2230.57	35.4361
2233.43	32.1909
2236.29	30.0534
2239.15	28.2316
2242.01	25.7587
2244.87	24.3176
2247.72	23.1313
2250.58	22.9875
2253.43	21.8568
2256.29	20.6591
2259.14	19.2042
2261.99	19.6132
2264.84	18.5863
2267.69	18.2129
2270.53	18.0982
2273.38	17.2877
2276.23	16.1374
2279.07	17.4415
2281.91	15.9171
2284.76	16.4139
2287.6	15.1261
2290.44	13.2348
2293.28	10.6921
2296.12	9.07815
2298.96	8.56346
2301.79	8.86254
2304.63	9.96749
2307.46	9.28736
2310.3	9.41396
2313.13	8.25674
2315.96	7.57534
2318.79	8.74722
2321.62	6.28638
2324.45	5.40146
2327.27	3.37199
2330.1	3.98809
2332.92	4.21806
2335.75	2.52792
2338.57	2.89495
2341.39	3.32808
2344.21	2.6164
2347.04	3.79828
2349.85	3.27284
2352.67	2.36121
2355.49	2.29429
2358.3	1.01497
2361.12	0.726992
2363.93	2.05423
2366.75	3.34744
2369.56	4.8678
2372.37	5.59675
2375.18	6.33757
2377.99	5.30755
2380.8	4.93086
2383.6	4.8358
2386.41	4.33424
2389.21	3.72115
2392.02	1.78594
2394.82	1.08584
2397.62	0.0480846
2400.42	1.51802
2403.22	0.615138
2406.02	1.55142
2408.82	3.25884
2411.62	4.73297
2414.41	5.47821
2417.21	6.35813
2420	5.94204
2422.79	7.20563
2425.59	7.28121
2428.38	8.03017
2431.17	8.43509
2433.95	8.94248
2436.74	9.58875
2439.53	9.24844
2442.31	8.64111
2445.1	8.72008
2447.88	6.84883
2450.67	6.33589
2453.45	6.06405
2456.23	5.29377
2459.01	5.14064
2461.79	4.61196
2464.57	5.10115
2467.34	5.4448
2470.12	5.93039
2472.89	7.5045
2475.67	7.08082
2478.44	8.20333
2481.21	8.52625
2483.98	7.20885
2486.75	7.286
2489.52	7.3827
2492.29	6.80668
2495.05	6.05316
2497.82	5.17818
2500.58	4.51224
2503.35	4.18047
2506.11	2.53228
2508.87	2.13815
2511.63	2.15685
2514.39	1.28241
2517.15	1.81001
2519.91	2.24844
2522.67	4.39786
2525.42	5.08962
2528.18	4.26048
2530.93	4.87419
2533.69	4.9788
2536.44	6.40026
2539.19	8.09396
2541.94	9.32431
2544.69	10.221
2547.44	11.6322
2550.18	11.7952
2552.93	11.7105
2555.67	12.6188
2558.42	13.2892
2561.16	12.2092
2563.9	11.9998
2566.64	12.8179
2569.38	13.4574
2572.12	13.5877
2574.86	14.0123
2577.6	14.7568
2580.33	14.7946
2583.07	15.6764
2585.8	16.3418
2588.54	15.1675
2591.27	14.7493
2594	15.0425
2596.73	15.1266
2599.46	15.2498
2602.19	15.4924
2604.92	16.0588
2607.64	15.4462
2610.37	15.7857
2613.09	15.7967
2615.82	15.9056
2618.54	15.6771
2621.26	14.9534
2623.98	14.9132
2626.7	13.7838
2629.42	13.4138
2632.14	13.3692
2634.86	13.9699
2637.57	13.7769
2640.29	13.6621
2643	12.7475
2645.71	13.3221
2648.43	14.0675
2651.14	13.5359
2653.85	12.235
2656.56	12.9545
2659.26	14.1375
2661.97	14.6978
2664.68	14.517
2667.38	14.9702
2670.09	14.9823
2672.79	15.1995
2675.49	15.1717
2678.19	16.1381
2680.89	16.4877
2683.59	16.3283
2686.29	17.0937
2688.99	17.5619
2691.69	18.3529
2694.38	19.1743
2697.08	19.9992
2699.77	22.0757
2702.46	23.961
2705.15	25.6064
2707.85	27.6375
2710.54	30.5986
2713.22	32.533
2715.91	34.5949
2718.6	36.6011
2721.29	37.3394
2723.97	39.1466
2726.66	38.7343
2729.34	39.0817
2732.02	38.3762
2734.7	36.5324
2737.38	34.2822
2740.06	32.4227
2742.74	30.2012
2745.42	27.2413
2748.09	24.6241
2750.77	21.8271
2753.45	19.7248
2756.12	16.5652
2758.79	14.1702
2761.46	11.7118
2764.14	10.0213
2766.8	8.67167
2769.47	6.82893
2772.14	6.4289
2774.81	5.25019
2777.48	4.2341
2780.14	2.57407
2782.8	2.46107
2785.47	0.0204048
2788.13	-0.238821
2790.79	-1.65838
2793.45	-2.10303
2796.11	-0.270059
2798.77	-1.36928
2801.43	-0.940877
2804.09	-1.18322
2806.74	-1.97229
2809.4	-2.58336
2812.05	-3.26174
2814.71	-2.28233
2817.36	1.12598
2820.01	8.75334
2822.66	21.269
2825.31	36.3769
2827.96	55.1169
2830.6	76.8913
2833.25	99.0794
2835.9	123.854
2838.54	150.155
2841.18	176.674
2843.83	205.837
2846.47	235.06
2849.11	264.581
2851.75	295.868
2854.39	327.334
2857.03	356.995
2859.66	386.534
2862.3	412.402
2864.94	436.95
2867.57	455.713
2870.2	472.497
2872.84	487.489
2875.47	500.4
2878.1	513.089
2880.73	526.386
2883.36	541.028
2885.99	553.68
2888.61	566.877
2891.24	580.533
2893.86	591.557
2896.49	604.375
2899.11	618.386
2901.73	630.956
2904.36	647.297
2906.98	665.207
2909.6	685.181
2912.21	706.103
2914.83	727.107
2917.45	747.445
2920.07	766.175
2922.68	779.943
2925.29	789.447
2927.91	794.524
2930.52	795.494
2933.13	791.316
2935.74	783.113
2938.35	767.84
2940.96	750.042
2943.57	727.265
2946.18	701.519
2948.78	671.318
2951.39	640.084
2953.99	609.323
2956.59	576.122
2959.2	543.82
2961.8	512.047
2964.4	480.46
2967	450.291
2969.6	423.447
2972.19	399.09
2974.79	373.447
2977.39	348.157
2979.98	323.361
2982.58	298.026
2985.17	273.934
2987.76	247.811
2990.35	223.254
2992.94	197.891
2995.53	174.519
2998.12	152.178
3000.71	130.43
3003.3	110.064
3005.88	91.4603
3008.47	74.5944
3011.05	60.0041
3013.64	46.7413
3016.22	36.6606
3018.8	26.3514
3021.38	19.2973
3023.96	13.1643
3026.54	8.0497
3029.12	4.91383
3031.69	3.0825
3034.27	1.94004
3036.84	1.48995
3039.42	1.39644
3041.99	1.38469
3044.57	3.28533
3047.14	3.66583
3049.71	6.04128
3052.28	6.43769
3054.85	6.07808
3057.41	6.78546
3059.98	7.50464
3062.55	6.83646
3065.11	6.18534
3067.68	5.2149
3070.24	4.33207
3072.8	4.08691
3075.36	3.19426
3077.93	3.31902
3080.49	2.49469
3083.04	2.68508
3085.6	3.29288
3088.16	3.63901
3090.72	5.15737
3093.27	7.45145
3095.83	8.36339
3098.38	10.7727
3100.93	14.6417
3103.49	18.3981
3106.04	20.9633
3108.59	24.6288
3111.14	28.3173
3113.69	31.9134
3116.23	35.565
3118.78	38.8096
3121.33	42.7883
3123.87	47.2281
3126.41	51.3387
3128.96	56.6839
3131.5	60.2927
3134.04	64.9325
3136.58	70.2163
3139.12	75.5705
3141.66	81.565
3144.2	87.6777
3146.74	94.1093
3149.27	101.204