File: data/Raman/poly_smoothed/Mb_20_23_03_1x_45s_532 nm_x50_100%_600 gr_mm_01.txt
#Acq. time (s)=	45
#Accumulations=	2
#Range (cm-¹)=	200...3150
#Windows=	2
#Auto scanning=	Off
#Autofocus=	Off
#Macrospot=	Off
#AutoExposure=	Off
#Spike filter=	Multiple accum.
#Delay time (s)=	0
#Binning=	1
#Readout mode=	Signal
#DeNoise=	Off
#ICS correction=	On
#Dark correction=	Off
#Inst. Process=	Off
#Detector Gain=	Best Dynamic Range
#Detector ADC=	20 kHz
#Detector temperature (°C)=	-69.85
#Instrument=	LabRAM HR Evol
#Detector=	Synapse
#Objective=	x50
#Grating=	600 gr/mm
#ND Filter=	100%
#Laser (nm)=	532
#Hole=	100.021
#Range=	Auto
#Laser Pol.=	No
#Raman. Pol.=	No
#Laser Pol. (°)=	-0.0007625
#Raman Pol. (°)=	89.9995
#Collection=	Microscope
#StageXY=	Marzhauser
#StageZ=	Marzhauser
#X (µm)=	-6993.5
#Y (µm)=	2158.4
#Z (µm)=	-74.35
#Full time(mm:ss)=	3:18
#Project=
#Sample=
#Site=
#Title=	Mb_20_23_03_2x_45s_532 nm_x50_100%_600 gr_mm
#Remark=
#Date=	13.07.2022 13:07
#Acquired=	13.07.2022 13:07:31
#Base:Fit=	10.08.2022 10:29:19
#Base:Fit=	10.08.2022 10:29:37
#Base:Sub=	10.08.2022 10:31:46
#Filter:Polynom=	16.08.2022 10:13:29
#AxisType[0]=Intens
#AxisUnit[0]=Cnt
#AxisType[1]=Spectr
#AxisUnit[1]=1/cm
200.563	8.41095
204.194	10.8036
207.821	11.5805
211.449	12.4533
215.074	13.1411
218.699	14.62
222.321	15.3804
225.941	16.0379
229.562	15.3305
233.18	15.9675
236.796	16.09
240.411	16.318
244.026	16.2582
247.638	15.9105
251.248	16.3053
254.857	16.38
258.465	15.712
262.071	16.3987
265.678	15.7779
269.282	14.6346
272.884	12.9633
276.484	10.4356
280.084	9.43677
283.682	7.86493
287.276	5.55957
290.871	6.25772
294.465	5.77089
298.057	7.49791
301.648	9.54733
305.237	10.193
308.823	12.3226
312.41	13.6509
315.995	15.3174
319.579	17.7325
323.16	19.8803
326.741	21.9975
330.321	22.9362
333.897	23.1748
337.474	25.6986
341.048	27.6151
344.622	27.0868
348.192	27.461
351.764	27.0638
355.332	26.0306
358.901	25.2014
362.466	22.27
366.03	20.6387
369.594	18.8873
373.155	17.4725
376.715	18.5709
380.273	18.6761
383.832	19.5911
387.388	21.1621
390.942	19.298
394.495	19.8643
398.047	19.0832
401.597	17.7518
405.145	16.1326
408.693	16.4033
412.239	13.1685
415.783	12.2302
419.327	11.6299
422.869	11.5802
426.409	12.9381
429.948	11.8351
433.486	10.9185
437.022	12.5813
440.558	11.6991
444.089	11.7273
447.622	11.1127
451.153	10.654
454.682	11.8133
458.208	14.3706
461.735	17.9609
465.259	18.9817
468.783	21.4208
472.306	22.2493
475.825	23.4611
479.346	24.814
482.862	27.9721
486.38	28.5952
489.894	28.7238
493.407	29.3446
496.92	30.4545
500.43	33.9241
503.939	35.6733
507.448	36.9084
510.954	37.1645
514.459	37.8075
517.962	38.3261
521.466	38.5436
524.966	38.5303
528.466	36.2832
531.964	35.585
535.46	33.9638
538.955	31.8368
542.449	30.6101
545.942	30.2673
549.433	27.5558
552.923	24.9134
556.412	22.4528
559.899	15.5079
563.385	8.63965
566.867	11.0097
570.35	12.1962
573.832	12.685
577.313	13.6246
580.79	15.993
584.268	19.4247
587.745	19.6676
591.218	22.5753
594.692	21.9207
598.164	21.8527
601.634	23.8161
605.104	24.4818
608.57	23.4726
612.037	23.8747
615.501	21.1904
618.966	19.705
622.427	17.3641
625.887	16.2683
629.348	14.0317
632.806	11.0158
636.262	9.30931
639.716	5.85671
643.172	1.5259
646.624	-4.0842
650.075	3.13974
653.524	3.77389
656.972	3.48451
660.419	3.19292
663.865	2.69087
667.309	4.69017
670.752	6.08016
674.194	7.15326
677.634	7.90027
681.073	7.35784
684.511	10.1285
687.947	12.2154
691.382	11.4806
694.816	13.5993
698.247	13.1198
701.678	14.4449
705.108	16.1339
708.534	17.834
711.962	20.1854
715.388	22.8156
718.81	25.0633
722.234	25.3347
725.654	25.4643
729.075	26.2002
732.492	27.4853
735.91	27.5311
739.325	27.6727
742.741	28.2888
746.153	29.7727
749.564	31.3054
752.976	32.9626
756.385	33.0383
759.792	35.7084
763.2	37.303
766.604	40.3195
770.008	44.0165
773.41	44.4828
776.811	47.8357
780.21	48.1293
783.608	50.1002
787.005	53.3127
790.401	54.9912
793.795	57.7034
797.188	61.6059
800.58	61.7481
803.971	64.2308
807.36	66.8727
810.748	69.2581
814.135	69.9739
817.518	70.0211
820.902	70.1368
824.285	71.2786
827.665	72.2592
831.045	71.7979
834.424	71.5717
837.8	70.8604
841.177	70.3467
844.55	70.3622
847.924	68.5428
851.295	65.8145
854.666	65.0878
858.034	62.3847
861.403	61.0492
864.769	59.2913
868.133	57.8694
871.498	55.6557
874.86	54.0648
878.221	55.3353
881.58	54.4145
884.938	52.541
888.297	52.3227
891.653	52.1769
895.007	51.2269
898.36	52.4621
901.712	51.7235
905.063	51.2367
908.412	52.2526
911.76	49.8825
915.107	49.1827
918.452	47.5049
921.797	43.7924
925.138	45.0682
928.48	42.749
931.82	40.4629
935.16	39.7797
938.496	36.9851
941.833	34.09
945.168	29.8017
948.5	28.8682
951.834	27.8664
955.163	26.9852
958.494	27.8835
961.821	25.6564
965.15	23.5572
968.474	24.7219
971.8	30.5934
975.123	33.2923
978.446	35.9707
981.766	37.8338
985.084	37.4646
988.402	38.39
991.72	38.5993
995.035	38.9943
998.349	38.5899
1001.66	39.3792
1004.97	39.6422
1008.28	40.909
1011.59	37.3639
1014.9	37.0324
1018.21	35.5775
1021.51	34.5942
1024.81	35.7634
1028.12	38.3806
1031.42	41.2064
1034.72	42.0622
1038.02	42.4211
1041.31	41.413
1044.61	42.7396
1047.91	47.0263
1051.2	50.9029
1054.49	52.8308
1057.78	53.0792
1061.07	53.7652
1064.36	54.3441
1067.65	54.3386
1070.93	54.6793
1074.22	55.3824
1077.5	53.4379
1080.78	52.4094
1084.06	50.1094
1087.34	48.1139
1090.62	46.3497
1093.9	45.0791
1097.17	44.2155
1100.45	44.1891
1103.72	42.1198
1106.99	42.2816
1110.27	40.6347
1113.53	39.4807
1116.8	37.8027
1120.07	36.7874
1123.33	33.6478
1126.6	32.2861
1129.86	29.2245
1133.12	28.6765
1136.38	27.9734
1139.64	26.9842
1142.9	26.4676
1146.16	25.9967
1149.41	21.2203
1152.67	18.3631
1155.92	15.7857
1159.17	13.3652
1162.42	12.806
1165.67	10.6571
1168.92	8.16478
1172.16	6.44513
1175.41	6.59485
1178.65	6.39014
1181.9	5.26852
1185.14	4.28894
1188.38	6.03895
1191.62	7.06806
1194.86	8.80575
1198.09	9.27635
1201.33	12.4862
1204.56	14.623
1207.8	19.8043
1211.03	23.8605
1214.26	29.9314
1217.49	34.6332
1220.71	40.0484
1223.94	45.6543
1227.16	51.3352
1230.39	58.003
1233.61	64.2188
1236.83	69.7613
1240.05	73.7527
1243.27	77.416
1246.49	81.0896
1249.71	84.7888
1252.92	90.4144
1256.14	91.8173
1259.35	93.2508
1262.56	95.7471
1265.77	99.0967
1268.98	103.768
1272.19	110.451
1275.4	114.856
1278.6	121.114
1281.81	126.616
1285.01	132.657
1288.21	138.745
1291.41	143.358
1294.61	148.107
1297.81	151.765
1301.01	157.404
1304.2	158.598
1307.4	160.743
1310.59	159.149
1313.78	157.916
1316.97	157.704
1320.16	153.234
1323.35	150.571
1326.54	146.248
1329.72	141.459
1332.91	134.931
1336.09	128.472
1339.27	125.152
1342.45	120.216
1345.64	116.286
1348.81	113.635
1351.99	111.221
1355.17	107.369
1358.34	103.407
1361.51	101.999
1364.69	99.0246
1367.86	96.5182
1371.03	95.7611
1374.2	97.0465
1377.37	98.5675
1380.53	97.7089
1383.7	96.3479
1386.86	96.9234
1390.02	95.5633
1393.19	97.7051
1396.35	98.261
1399.51	98.6262
1402.66	104.676
1405.82	110.101
1408.97	118.01
1412.13	126.313
1415.28	137.622
1418.43	148.954
1421.59	162.979
1424.73	178.049
1427.88	191.728
1431.03	205.965
1434.18	220.305
1437.32	229.872
1440.46	239.875
1443.61	247.473
1446.75	251.681
1449.89	251.322
1453.03	248.837
1456.16	239.321
1459.3	228.181
1462.44	215.229
1465.57	198.364
1468.7	180.69
1471.83	163.547
1474.96	143.44
1478.09	127.183
1481.22	112.084
1484.35	95.6828
1487.47	82.0488
1490.6	70.7933
1493.72	60.9626
1496.84	53.3603
1499.96	47.0982
1503.08	41.6255
1506.2	39.4852
1509.32	37.7982
1512.44	35.8329
1515.55	35.9526
1518.66	37.7073
1521.78	37.2421
1524.89	37.292
1528	39.2368
1531.11	41.3427
1534.21	42.2345
1537.32	44.8671
1540.43	45.0116
1543.53	48.326
1546.63	49.9321
1549.74	51.4305
1552.84	52.6904
1555.94	54.1345
1559.03	54.7393
1562.13	56.2519
1565.23	58.981
1568.32	60.9939
1571.42	64.5699
1574.51	68.0971
1577.6	71.5199
1580.69	75.2159
1583.78	79.1017
1586.87	84.6682
1589.95	87.9763
1593.04	91.8666
1596.12	93.7074
1599.21	95.9576
1602.29	97.4106
1605.37	98.6292
1608.45	98.6603
1611.53	99.2086
1614.6	97.6216
1617.68	97.8187
1620.75	98.7969
1623.83	98.6598
1626.9	100.295
1629.97	102.332
1633.04	105.109
1636.11	106.81
1639.18	110.777
1642.25	114.084
1645.31	118.39
1648.38	122.271
1651.44	124.491
1654.5	126.291
1657.56	125.915
1660.62	125.348
1663.68	124.028
1666.74	121.659
1669.8	117.55
1672.85	110.868
1675.91	103.849
1678.96	98.1443
1682.01	89.063
1685.06	82.1514
1688.11	73.7502
1691.16	66.9111
1694.21	60.0515
1697.25	54.4926
1700.3	48.9535
1703.34	45.6926
1706.39	41.1695
1709.43	37.9779
1712.47	36.309
1715.51	36.1908
1718.54	35.8261
1721.58	35.8645
1724.62	34.4448
1727.65	34.9024
1730.68	33.4058
1733.72	31.7787
1736.75	31.5754
1739.78	29.8052
1742.81	28.6783
1745.84	25.5322
1748.86	23.0403
1751.89	20.9959
1754.91	17.7711
1757.93	17.124
1760.96	14.921
1763.98	10.6007
1767	8.28181
1770.02	6.14175
1773.03	3.5407
1776.05	1.94204
1779.07	2.30857
1782.08	1.6587
1785.09	1.94521
1788.11	1.68892
1791.12	2.49495
1794.13	2.04965
1797.13	2.41686
1800.14	3.13742
1803.15	3.51192
1806.15	3.00619
1809.16	3.75048
1812.16	5.09173
1815.16	5.81328
1818.16	6.03333
1821.16	5.27056
1824.16	5.07417
1827.16	6.15423
1830.16	5.68949
1833.15	5.13386
1836.14	4.79936
1839.14	3.98207
1842.13	3.16522
1845.12	2.13393
1848.11	1.00801
1851.1	0.349592
1854.08	-0.511232
1857.07	-1.0121
1860.05	-1.44479
1863.04	-0.526114
1866.02	-0.60928
1869	-0.503903
1871.98	0.787578
1874.96	1.74762
1877.94	1.58393
1880.92	2.3728
1882.51	3.08963
1885.5	3.53633
1888.48	3.32792
1891.47	4.03261
1894.46	2.8369
1897.44	3.37737
1900.42	2.71174
1903.41	2.78572
1906.39	3.37608
1909.37	2.95669
1912.35	1.82655
1915.32	1.31593
1918.3	0.78433
1921.27	1.29636
1924.25	0.944003
1927.22	1.00048
1930.19	1.36787
1933.17	2.2258
1936.14	2.69574
1939.11	2.35784
1942.07	2.89718
1945.04	2.74598
1948.01	3.6196
1950.97	4.86625
1953.93	3.67343
1956.9	3.77079
1959.86	3.93337
1962.82	3.1974
1965.78	2.76124
1968.74	2.05005
1971.69	1.99257
1974.65	2.51079
1977.6	2.37968
1980.56	2.11209
1983.51	2.18408
1986.46	2.41899
1989.41	2.68175
1992.36	2.11708
1995.31	1.63686
1998.26	2.33386
2001.2	2.98317
2004.15	2.77869
2007.09	3.98409
2010.04	4.80786
2012.98	5.20828
2015.92	5.26773
2018.86	6.42894
2021.8	7.19274
2024.73	7.21348
2027.67	6.57297
2030.61	7.92606
2033.54	8.12375
2036.47	8.132
2039.4	9.00275
2042.33	8.96378
2045.27	10.4746
2048.19	9.40759
2051.12	9.0548
2054.05	8.34606
2056.97	7.91202
2059.9	7.94223
2062.82	7.7291
2065.74	6.13954
2068.67	5.86364
2071.59	5.63615
2074.51	5.53454
2077.42	5.60107
2080.34	5.96476
2083.26	6.22501
2086.17	6.09137
2089.09	6.2605
2092	7.72204
2094.91	9.94539
2097.82	11.2686
2100.73	13.3891
2103.64	15.1239
2106.55	17.146
2109.45	18.9621
2112.36	21.8625
2115.26	22.6375
2118.17	23.8074
2121.07	25.8482
2123.97	27.8606
2126.87	30.059
2129.77	31.7696
2132.67	32.9037
2135.56	33.9951
2138.46	35.2865
2141.35	38.3347
2144.25	42.5582
2147.14	46.1724
2150.03	50.4216
2152.92	54.0861
2155.81	57.7465
2158.7	61.4427
2161.59	65.6984
2164.47	68.2911
2167.36	70.2503
2170.24	72.6712
2173.13	74.2486
2176.01	75.1827
2178.89	75.4341
2181.77	75.6458
2184.65	74.4362
2187.53	72.3135
2190.4	70.0775
2193.28	67.6636
2196.16	64.0503
2199.03	60.402
2201.9	56.5848
2204.77	52.8149
2207.64	48.9243
2210.51	46.1595
2213.38	44.1319
2216.25	39.805
2219.12	36.8583
2221.98	34.437
2224.85	31.8221
2227.71	28.5832
2230.57	26.4556
2233.43	23.7733
2236.29	20.8476
2239.15	19.1822
2242.01	18.2358
2244.87	16.5392
2247.72	15.5489
2250.58	14.1502
2253.43	13.8715
2256.29	13.3333
2259.14	12.2481
2261.99	12.8337
2264.84	12.9946
2267.69	12.303
2270.53	12.6668
2273.38	10.6607
2276.23	10.4473
2279.07	9.75546
2281.91	9.47965
2284.76	8.83131
2287.6	7.9583
2290.44	7.71296
2293.28	6.88284
2296.12	6.64486
2298.96	7.154
2301.79	7.55177
2304.63	7.8049
2307.46	8.08922
2310.3	9.18545
2313.13	9.03004
2315.96	9.45687
2318.79	9.30797
2321.62	10.3262
2324.45	11.1571
2327.27	11.1749
2330.1	12.5792
2332.92	12.1216
2335.75	12.9371
2338.57	12.0698
2341.39	10.0777
2344.21	9.0037
2347.04	9.24844
2349.85	8.6965
2352.67	8.10853
2355.49	7.8145
2358.3	6.47057
2361.12	6.53589
2363.93	6.14432
2366.75	5.67457
2369.56	5.28228
2372.37	3.92604
2375.18	3.98487
2377.99	3.3357
2380.8	3.30011
2383.6	1.85937
2386.41	1.097
2389.21	2.10064
2392.02	1.03573
2394.82	-0.0566572
2397.62	0.505366
2400.42	-0.0730622
2403.22	0.702397
2406.02	1.26917
2408.82	0.897104
2411.62	1.64592
2414.41	1.99254
2417.21	2.6791
2420	3.08869
2422.79	3.42301
2425.59	5.00369
2428.38	4.97114
2431.17	5.62872
2433.95	4.31128
2436.74	4.06067
2439.53	5.20596
2442.31	3.8394
2445.1	5.17315
2447.88	4.50176
2450.67	3.52996
2453.45	2.01897
2456.23	1.76301
2459.01	0.859387
2461.79	-0.15758
2464.57	0.399249
2467.34	0.170872
2470.12	0.730537
2472.89	1.69385
2475.67	0.957384
2478.44	1.20594
2481.21	1.35839
2483.98	2.02729
2486.75	2.02038
2489.52	2.92324
2492.29	3.74104
2495.05	4.30617
2497.82	4.53932
2500.58	4.60414
2503.35	4.5202
2506.11	5.67884
2508.87	5.54122
2511.63	5.14655
2514.39	5.46878
2517.15	5.85758
2519.91	6.30045
2522.67	6.16812
2525.42	6.28825
2528.18	6.0464
2530.93	5.42436
2533.69	5.53852
2536.44	5.99284
2539.19	6.04904
2541.94	6.61095
2544.69	6.83678
2547.44	6.22859
2550.18	6.76003
2552.93	6.79327
2555.67	7.357
2558.42	8.20876
2561.16	8.28257
2563.9	9.68748
2566.64	9.41851
2569.38	10.8984
2572.12	11.3541
2574.86	12.0351
2577.6	12.7767
2580.33	12.7707
2583.07	14.5752
2585.8	15.5238
2588.54	15.2028
2591.27	14.6451
2594	14.2602
2596.73	15.17
2599.46	14.5242
2602.19	14.757
2604.92	14.95
2607.64	14.516
2610.37	14.8472
2613.09	13.6158
2615.82	13.2469
2618.54	12.964
2621.26	12.1853
2623.98	12.9483
2626.7	13.0912
2629.42	12.6524
2632.14	13.24
2634.86	13.5024
2637.57	13.9332
2640.29	13.6754
2643	13.8012
2645.71	13.6902
2648.43	14.1611
2651.14	14.8177
2653.85	14.3193
2656.56	12.6289
2659.26	13.27
2661.97	13.1201
2664.68	13.3375
2667.38	14.4164
2670.09	15.0909
2672.79	15.8464
2675.49	16.1166
2678.19	16.3879
2680.89	16.6708
2683.59	16.1134
2686.29	16.6175
2688.99	17.9793
2691.69	18.7858
2694.38	19.712
2697.08	20.3046
2699.77	22.9119
2702.46	23.8712
2705.15	24.9779
2707.85	26.3146
2710.54	27.6886
2713.22	28.1573
2715.91	28.8958
2718.6	29.0493
2721.29	28.1563
2723.97	28.6159
2726.66	28.4356
2729.34	27.28
2732.02	27.4718
2734.7	26.1238
2737.38	23.6153
2740.06	22.5588
2742.74	20.1245
2745.42	17.2092
2748.09	14.4862
2750.77	12.999
2753.45	11.881
2756.12	10.0433
2758.79	8.29587
2761.46	6.96272
2764.14	5.96
2766.8	4.78887
2769.47	3.95723
2772.14	4.3911
2774.81	2.68955
2777.48	2.36926
2780.14	1.80599
2782.8	1.07598
2785.47	0.0189622
2788.13	-0.109078
2790.79	-0.963554
2793.45	-0.746001
2796.11	-0.0471525
2798.77	0.0412683
2801.43	1.06339
2804.09	1.08299
2806.74	0.500947
2809.4	-0.893656
2812.05	-2.35365
2814.71	-3.51355
2817.36	-1.22977
2820.01	6.68135
2822.66	20.0796
2825.31	38.0098
2827.96	59.5864
2830.6	84.1872
2833.25	111.936
2835.9	139.064
2838.54	167.107
2841.18	196.764
2843.83	227.595
2846.47	259.476
2849.11	291.171
2851.75	321.145
2854.39	350.702
2857.03	379.697
2859.66	405.19
2862.3	428.283
2864.94	447.441
2867.57	463.001
2870.2	473.98
2872.84	483.125
2875.47	487.662
2878.1	492.182
2880.73	498.86
2883.36	509.687
2885.99	519.825
2888.61	529.09
2891.24	538.762
2893.86	548.747
2896.49	557.97
2899.11	567.528
2901.73	577.866
2904.36	587.773
2906.98	602.71
2909.6	618.012
2912.21	635.038
2914.83	649.603
2917.45	664.342
2920.07	676.453
2922.68	683.453
2925.29	688.1
2927.91	687.273
2930.52	682.206
2933.13	674.403
2935.74	662.519
2938.35	646.224
2940.96	626.767
2943.57	605.016
2946.18	579.705
2948.78	551.584
2951.39	522.361
2953.99	492.905
2956.59	463.246
2959.2	433.986
2961.8	405.474
2964.4	377.407
2967	351.19
2969.6	328.212
2972.19	307.046
2974.79	285.979
2977.39	264.401
2979.98	242.874
2982.58	221.201
2985.17	198.87
2987.76	176.37
2990.35	157.02
2992.94	137.211
2995.53	119.299
2998.12	103.135
3000.71	88.8426
3003.3	74.1112
3005.88	61.9426
3008.47	50.7717
3011.05	40.9808
3013.64	32.805
3016.22	25.9568
3018.8	19.1874
3021.38	14.328
3023.96	10.5608
3026.54	7.51803
3029.12	5.69483
3031.69	4.01853
3034.27	3.40229
3036.84	3.38042
3039.42	2.93438
3041.99	3.70635
3044.57	4.7761
3047.14	5.30704
3049.71	5.59973
3052.28	6.67947
3054.85	7.15054
3057.41	6.69032
3059.98	7.14067
3062.55	7.14898
3065.11	7.00608
3067.68	6.27973
3070.24	5.96014
3072.8	4.99338
3075.36	3.55317
3077.93	2.07394
3080.49	1.7363
3083.04	-0.592521
3085.6	-0.212614
3088.16	-0.476844
3090.72	-0.190869
3093.27	-0.149717
3095.83	0.532293
3098.38	2.13931
3100.93	4.05485
3103.49	6.31767
3106.04	8.81076
3108.59	10.7703
3111.14	13.3207
3113.69	15.5892
3116.23	17.7793
3118.78	20.2163
3121.33	23.1398
3123.87	26.6545
3126.41	30.875
3128.96	34.0363
3131.5	37.4832
3134.04	41.7616
3136.58	45.9479
3139.12	49.6153
3141.66	54.3393
3144.2	59.2589
3146.74	65.1927
3149.27	69.8365