File: data/Raman/poly_smoothed/Mb_20_23_10_1x_45s_532 nm_x100_100%_600 gr_mm_01.txt
#Acq. time (s)=	45
#Accumulations=	2
#Range (cm-¹)=	200...3150
#Windows=	2
#Auto scanning=	Off
#Autofocus=	Off
#Macrospot=	Off
#AutoExposure=	Off
#Spike filter=	Multiple accum.
#Delay time (s)=	0
#Binning=	1
#Readout mode=	Signal
#DeNoise=	Off
#ICS correction=	On
#Dark correction=	Off
#Inst. Process=	Off
#Detector Gain=	Best Dynamic Range
#Detector ADC=	20 kHz
#Detector temperature (°C)=	-69.85
#Instrument=	LabRAM HR Evol
#Detector=	Synapse
#Objective=	x100
#Grating=	600 gr/mm
#ND Filter=	100%
#Laser (nm)=	532
#Hole=	100.021
#Range=	Auto
#Laser Pol.=	No
#Raman. Pol.=	No
#Laser Pol. (°)=	-0.0007625
#Raman Pol. (°)=	89.9995
#Collection=	Microscope
#StageXY=	Marzhauser
#StageZ=	Marzhauser
#X (µm)=	-6916.1
#Y (µm)=	2136.4
#Z (µm)=	-74.85
#Full time(mm:ss)=	3:18
#Project=
#Sample=
#Site=
#Title=	Mb_20_23_10_2x_45s_532 nm_x100_100%_600 gr_mm
#Remark=
#Date=	13.07.2022 13:40
#Acquired=	13.07.2022 13:40:15
#Base:Fit=	10.08.2022 10:29:19
#Base:Fit=	10.08.2022 10:29:37
#Base:Sub=	10.08.2022 10:31:46
#Filter:Polynom=	16.08.2022 10:13:29
#AxisType[0]=Intens
#AxisUnit[0]=Cnt
#AxisType[1]=Spectr
#AxisUnit[1]=1/cm
200.563	50.3422
204.194	42.1523
207.821	38.9206
211.449	35.9348
215.074	33.9603
218.699	32.6733
222.321	30.4235
225.941	27.532
229.562	24.4004
233.18	20.5009
236.796	20.1033
240.411	18.3784
244.026	15.7708
247.638	14.8487
251.248	15.7242
254.857	14.0476
258.465	13.1461
262.071	14.5263
265.678	13.9168
269.282	12.7474
272.884	14.2325
276.484	13.4943
280.084	11.6501
283.682	10.345
287.276	11.5019
290.871	11.2019
294.465	9.90499
298.057	11.2334
301.648	14.2522
305.237	14.5938
308.823	14.0658
312.41	12.5218
315.995	12.1126
319.579	10.6988
323.16	10.1741
326.741	11.3117
330.321	11.1154
333.897	11.3644
337.474	12.6617
341.048	14.1593
344.622	13.1078
348.192	13.6538
351.764	11.6849
355.332	10.6055
358.901	11.5809
362.466	9.62033
366.03	8.4154
369.594	6.59151
373.155	7.00791
376.715	7.56418
380.273	6.51801
383.832	5.8462
387.388	7.41697
390.942	7.00713
394.495	6.92357
398.047	6.56928
401.597	7.40506
405.145	8.65119
408.693	9.50477
412.239	10.3547
415.783	10.7976
419.327	11.6625
422.869	12.0256
426.409	11.3189
429.948	11.4007
433.486	10.8179
437.022	9.95668
440.558	8.69125
444.089	8.67923
447.622	8.2228
451.153	7.05322
454.682	8.42057
458.208	8.9613
461.735	9.81653
465.259	10.711
468.783	8.99392
472.306	8.29101
475.825	9.55063
479.346	10.79
482.862	10.0787
486.38	9.96478
489.894	12.3772
493.407	14.5277
496.92	14.931
500.43	16.0506
503.939	17.6021
507.448	18.4403
510.954	19.0177
514.459	20.4281
517.962	19.8169
521.466	17.6309
524.966	18.0143
528.466	17.1641
531.964	16.9047
535.46	16.1866
538.955	14.9659
542.449	14.4683
545.942	13.4835
549.433	13.1589
552.923	12.4444
556.412	9.49989
559.899	7.9061
563.385	5.32663
566.867	5.2099
570.35	4.80143
573.832	6.07047
577.313	7.73012
580.79	8.35555
584.268	9.48689
587.745	8.79671
591.218	7.48796
594.692	8.28475
598.164	6.34353
601.634	7.88338
605.104	6.17865
608.57	6.23497
612.037	6.33891
615.501	6.55506
618.966	4.44668
622.427	3.53312
625.887	2.68398
629.348	4.65319
632.806	5.98102
636.262	5.306
639.716	4.41916
643.172	2.78309
646.624	4.65408
650.075	6.10227
653.524	7.77596
656.972	7.92482
660.419	8.06212
663.865	9.01317
667.309	10.5111
670.752	11.4825
674.194	11.5056
677.634	12.4628
681.073	14.4542
684.511	16.0657
687.947	16.551
691.382	16.6722
694.816	17.8612
698.247	19.0564
701.678	20.6605
705.108	23.5654
708.534	23.9752
711.962	26.2248
715.388	27.6255
718.81	29.0944
722.234	29.7086
725.654	29.9757
729.075	30.9736
732.492	30.6394
735.91	31.094
739.325	31.3816
742.741	33.7023
746.153	35.4822
749.564	38.7523
752.976	41.2051
756.385	41.206
759.792	43.0568
763.2	46.6946
766.604	47.4058
770.008	47.5598
773.41	50.3759
776.811	52.7463
780.21	54.1244
783.608	57.266
787.005	59.6633
790.401	61.0209
793.795	64.136
797.188	65.5768
800.58	68.3141
803.971	68.8744
807.36	67.9036
810.748	68.2955
814.135	66.43
817.518	67.3489
820.902	66.7976
824.285	69.5314
827.665	68.9456
831.045	68.2002
834.424	66.1182
837.8	65.2075
841.177	65.0633
844.55	63.8428
847.924	61.8227
851.295	60.4159
854.666	58.2519
858.034	58.109
861.403	55.9113
864.769	55.1276
868.133	54.3332
871.498	53.0314
874.86	52.975
878.221	54.0213
881.58	53.2484
884.938	52.7356
888.297	51.3021
891.653	48.5033
895.007	47.8031
898.36	47.8468
901.712	48.7151
905.063	47.9203
908.412	48.8514
911.76	48.3992
915.107	48.6037
918.452	49.8071
921.797	50.6572
925.138	49.1111
928.48	48.7427
931.82	47.9129
935.16	44.141
938.496	41.9918
941.833	38.9754
945.168	35.112
948.5	32.7101
951.834	32.1081
955.163	32.1805
958.494	29.5266
961.821	28.9372
965.15	28.5739
968.474	29.0952
971.8	30.7456
975.123	33.4606
978.446	34.8008
981.766	37.4021
985.084	36.7146
988.402	37.1344
991.72	36.5595
995.035	35.1108
998.349	32.6158
1001.66	30.6558
1004.97	26.7071
1008.28	26.8244
1011.59	28.9172
1014.9	29.7015
1018.21	33.0049
1021.51	36.7187
1024.81	41.7339
1028.12	46.0117
1031.42	51.6025
1034.72	56.4608
1038.02	59.6633
1041.31	63.1464
1044.61	67.4944
1047.91	71.3864
1051.2	75.4091
1054.49	76.056
1057.78	73.2005
1061.07	69.4464
1064.36	67.3124
1067.65	62.5056
1070.93	56.9217
1074.22	52.3426
1077.5	46.0052
1080.78	39.2988
1084.06	34.4593
1087.34	31.413
1090.62	31.199
1093.9	30.5447
1097.17	32.0722
1100.45	31.6804
1103.72	31.1285
1106.99	31.1433
1110.27	30.6558
1113.53	29.3983
1116.8	27.0728
1120.07	26.1485
1123.33	23.2375
1126.6	22.1657
1129.86	22.0295
1133.12	19.5061
1136.38	17.0094
1139.64	13.906
1142.9	14.2261
1146.16	14.2732
1149.41	11.4538
1152.67	9.84385
1155.92	6.77338
1159.17	3.45799
1162.42	1.46028
1165.67	0.700711
1168.92	2.02006
1172.16	3.55416
1175.41	5.32127
1178.65	5.58025
1181.9	5.93947
1185.14	7.73349
1188.38	6.07026
1191.62	7.79448
1194.86	7.91785
1198.09	9.34807
1201.33	10.4847
1204.56	11.5679
1207.8	14.3263
1211.03	15.7001
1214.26	17.5558
1217.49	18.6548
1220.71	22.0027
1223.94	24.7855
1227.16	25.965
1230.39	27.887
1233.61	32.167
1236.83	35.0313
1240.05	38.3541
1243.27	42.0531
1246.49	46.3647
1249.71	48.7986
1252.92	50.7899
1256.14	52.5478
1259.35	55.3171
1262.56	60.205
1265.77	64.8615
1268.98	71.4844
1272.19	76.4515
1275.4	83.4729
1278.6	88.9168
1281.81	91.3034
1285.01	95.114
1288.21	98.0123
1291.41	98.4924
1294.61	100.917
1297.81	102.675
1301.01	102.037
1304.2	101.106
1307.4	101.041
1310.59	99.039
1313.78	98.2191
1316.97	96.4724
1320.16	93.3729
1323.35	90.6638
1326.54	86.2486
1329.72	81.1517
1332.91	78.1865
1336.09	75.1072
1339.27	74.7948
1342.45	75.1772
1345.64	75.4512
1348.81	74.0119
1351.99	74.109
1355.17	73.8421
1358.34	71.2139
1361.51	69.9881
1364.69	69.5968
1367.86	70.471
1371.03	68.2965
1374.2	69.9142
1377.37	68.9495
1380.53	70.65
1383.7	71.3801
1386.86	72.889
1390.02	73.9998
1393.19	75.4563
1396.35	74.2738
1399.51	75.7997
1402.66	76.5131
1405.82	80.1269
1408.97	87.2199
1412.13	94.8951
1415.28	101.137
1418.43	111.309
1421.59	122.528
1424.73	134.192
1427.88	144.547
1431.03	155.675
1434.18	165.921
1437.32	174.603
1440.46	179.79
1443.61	185.784
1446.75	187.396
1449.89	187.468
1453.03	185.06
1456.16	180.626
1459.3	173.788
1462.44	166.627
1465.57	157.971
1468.7	145.007
1471.83	133.602
1474.96	120.979
1478.09	110.093
1481.22	99.9697
1484.35	90.7103
1487.47	81.8729
1490.6	72.5641
1493.72	64.3286
1496.84	60.0559
1499.96	56.01
1503.08	52.8201
1506.2	48.5516
1509.32	45.2545
1512.44	40.8444
1515.55	37.3231
1518.66	33.7546
1521.78	32.2592
1524.89	31.4904
1528	30.5201
1531.11	31.6127
1534.21	32.338
1537.32	33.8274
1540.43	37.9667
1543.53	39.8387
1546.63	41.7398
1549.74	43.7041
1552.84	44.4992
1555.94	46.7216
1559.03	48.5251
1562.13	49.2401
1565.23	51.051
1568.32	51.9385
1571.42	53.3595
1574.51	56.8344
1577.6	58.7356
1580.69	60.8488
1583.78	60.1315
1586.87	61.8031
1589.95	63.2286
1593.04	64.8355
1596.12	64.8914
1599.21	65.765
1602.29	65.6745
1605.37	65.4459
1608.45	65.7204
1611.53	65.1248
1614.6	64.6096
1617.68	65.6932
1620.75	65.1815
1623.83	66.914
1626.9	67.6698
1629.97	67.2289
1633.04	70.0935
1636.11	71.0769
1639.18	73.6484
1642.25	76.2841
1645.31	78.2465
1648.38	80.6924
1651.44	80.6522
1654.5	81.5796
1657.56	80.9607
1660.62	80.7315
1663.68	79.4431
1666.74	76.084
1669.8	70.7539
1672.85	66.455
1675.91	62.0224
1678.96	57.782
1682.01	52.2849
1685.06	46.4613
1688.11	40.9277
1691.16	37.8441
1694.21	35.7321
1697.25	32.4552
1700.3	31.0718
1703.34	26.9883
1706.39	26.8994
1709.43	26.3264
1712.47	24.756
1715.51	24.0096
1718.54	22.4666
1721.58	20.287
1724.62	19.7955
1727.65	18.9135
1730.68	19.2938
1733.72	18.5223
1736.75	18.2249
1739.78	16.2769
1742.81	14.4238
1745.84	13.7779
1748.86	13.192
1751.89	12.9392
1754.91	12.0685
1757.93	10.7039
1760.96	10.6924
1763.98	10.9733
1767	9.21829
1770.02	7.75938
1773.03	6.94245
1776.05	5.8481
1779.07	3.79965
1782.08	4.11737
1785.09	3.14103
1788.11	1.99617
1791.12	1.65416
1794.13	1.3174
1797.13	1.79423
1800.14	2.12098
1803.15	2.36754
1806.15	2.19103
1809.16	1.62248
1812.16	1.52562
1815.16	3.07935
1818.16	3.88116
1821.16	4.53933
1824.16	5.70016
1827.16	5.77257
1830.16	5.64682
1833.15	6.04533
1836.14	6.60526
1839.14	6.35001
1842.13	5.71447
1845.12	5.49602
1848.11	5.6639
1851.1	5.07426
1854.08	4.66728
1857.07	3.95363
1860.05	3.85492
1863.04	4.01377
1866.02	3.29609
1869	2.72477
1871.98	1.76859
1874.96	1.78029
1877.94	2.13938
1880.92	1.84388
1882.51	2.16809
1885.5	2.8424
1888.48	4.42313
1891.47	4.4696
1894.46	3.82555
1897.44	3.56386
1900.42	3.57384
1903.41	3.98748
1906.39	4.40003
1909.37	4.95785
1912.35	5.60924
1915.32	5.75798
1918.3	5.19158
1921.27	6.95232
1924.25	6.60854
1927.22	6.06978
1930.19	6.04062
1933.17	4.4871
1936.14	4.7447
1939.11	4.22411
1942.07	4.50121
1945.04	5.02474
1948.01	5.7848
1950.97	6.41432
1953.93	6.65343
1956.9	6.44221
1959.86	6.51637
1962.82	5.53067
1965.78	5.31751
1968.74	5.26776
1971.69	5.35097
1974.65	5.37925
1977.6	5.29354
1980.56	5.97777
1983.51	6.06515
1986.46	5.96834
1989.41	5.53331
1992.36	7.28567
1995.31	6.48915
1998.26	6.65692
2001.2	6.05631
2004.15	6.51351
2007.09	7.43991
2010.04	7.82801
2012.98	7.49227
2015.92	8.53076
2018.86	9.40961
2021.8	9.50189
2024.73	9.84212
2027.67	9.28244
2030.61	9.31956
2033.54	10.0275
2036.47	11.223
2039.4	11.1497
2042.33	10.0497
2045.27	10.4005
2048.19	8.51221
2051.12	8.72582
2054.05	8.89432
2056.97	7.81996
2059.9	8.90915
2062.82	8.30422
2065.74	8.81897
2068.67	8.26038
2071.59	8.60476
2074.51	8.41284
2077.42	9.40227
2080.34	9.03133
2083.26	8.99016
2086.17	9.48558
2089.09	11.6909
2092	11.6769
2094.91	11.7294
2097.82	11.968
2100.73	13.1883
2103.64	14.0972
2106.55	15.0143
2109.45	15.5617
2112.36	15.8022
2115.26	17.0716
2118.17	18.8448
2121.07	19.8581
2123.97	21.3032
2126.87	23.4155
2129.77	24.4451
2132.67	25.3104
2135.56	28.3888
2138.46	29.9286
2141.35	31.8053
2144.25	33.9481
2147.14	36.6597
2150.03	39.0618
2152.92	40.3783
2155.81	42.3083
2158.7	45.1349
2161.59	46.5537
2164.47	47.0638
2167.36	48.0702
2170.24	48.709
2173.13	48.8787
2176.01	48.7206
2178.89	48.0138
2181.77	46.2208
2184.65	45.5784
2187.53	44.674
2190.4	44.3829
2193.28	42.0754
2196.16	41.1555
2199.03	39.1234
2201.9	37.475
2204.77	35.8391
2207.64	34.1351
2210.51	31.6422
2213.38	29.5548
2216.25	27.7636
2219.12	25.9778
2221.98	24.4456
2224.85	24.3509
2227.71	22.4345
2230.57	21.7893
2233.43	19.9132
2236.29	19.1912
2239.15	16.736
2242.01	15.2076
2244.87	13.3224
2247.72	12.1859
2250.58	11.5044
2253.43	11.2314
2256.29	11.6938
2259.14	11.7225
2261.99	11.9493
2264.84	12.268
2267.69	12.3681
2270.53	13.0491
2273.38	12.8369
2276.23	12.9302
2279.07	12.4481
2281.91	11.862
2284.76	10.6004
2287.6	10.8072
2290.44	10.5725
2293.28	8.6188
2296.12	8.45225
2298.96	7.36595
2301.79	6.78637
2304.63	6.4615
2307.46	6.77463
2310.3	6.19837
2313.13	5.64427
2315.96	5.50299
2318.79	5.59123
2321.62	5.82418
2324.45	5.06214
2327.27	5.08279
2330.1	6.32595
2332.92	6.77392
2335.75	6.4048
2338.57	6.62056
2341.39	6.65246
2344.21	5.5916
2347.04	4.73673
2349.85	3.23396
2352.67	2.10444
2355.49	1.75533
2358.3	1.55092
2361.12	0.151759
2363.93	0.388341
2366.75	0.362089
2369.56	-0.617449
2372.37	-0.42637
2375.18	-0.0517362
2377.99	0.997068
2380.8	0.382309
2383.6	0.902994
2386.41	0.94795
2389.21	1.453
2392.02	1.91136
2394.82	3.64489
2397.62	4.75871
2400.42	5.47367
2403.22	5.94921
2406.02	5.95563
2408.82	7.3562
2411.62	7.32492
2414.41	6.99981
2417.21	8.1548
2420	7.90872
2422.79	7.31954
2425.59	8.05115
2428.38	7.40211
2431.17	6.7841
2433.95	6.14594
2436.74	5.63399
2439.53	5.30859
2442.31	4.42974
2445.1	3.93648
2447.88	3.31531
2450.67	2.57166
2453.45	2.01018
2456.23	2
2459.01	2.38378
2461.79	3.45541
2464.57	1.62443
2467.34	1.59117
2470.12	1.75859
2472.89	1.36505
2475.67	1.46199
2478.44	1.49845
2481.21	1.39612
2483.98	2.19498
2486.75	2.62317
2489.52	1.96144
2492.29	2.72745
2495.05	2.95372
2497.82	3.25428
2500.58	3.48092
2503.35	3.11327
2506.11	3.2398
2508.87	1.90072
2511.63	2.78026
2514.39	2.61512
2517.15	2.47113
2519.91	2.56049
2522.67	2.22894
2525.42	3.57406
2528.18	3.63163
2530.93	4.0735
2533.69	3.17424
2536.44	4.46011
2539.19	3.2447
2541.94	2.36645
2544.69	3.82485
2547.44	2.74506
2550.18	3.14727
2552.93	3.07688
2555.67	3.18809
2558.42	3.16493
2561.16	2.93258
2563.9	1.70145
2566.64	2.38311
2569.38	2.23502
2572.12	1.84101
2574.86	2.33898
2577.6	2.1544
2580.33	2.72353
2583.07	2.61685
2585.8	1.90226
2588.54	2.68563
2591.27	3.0413
2594	3.82896
2596.73	4.18548
2599.46	5.29778
2602.19	4.15157
2604.92	4.50486
2607.64	4.22266
2610.37	5.01947
2613.09	5.60169
2615.82	5.65287
2618.54	6.85887
2621.26	7.61406
2623.98	8.6942
2626.7	8.91339
2629.42	9.19914
2632.14	9.40477
2634.86	10.3189
2637.57	10.6583
2640.29	12.299
2643	12.077
2645.71	12.8583
2648.43	12.2834
2651.14	12.2688
2653.85	12.4268
2656.56	13.5826
2659.26	13.1027
2661.97	13.4026
2664.68	12.5701
2667.38	11.9697
2670.09	11.5095
2672.79	10.8512
2675.49	11.0311
2678.19	10.7736
2680.89	11.0094
2683.59	10.831
2686.29	12.6666
2688.99	13.5876
2691.69	14.9282
2694.38	14.6291
2697.08	16.1298
2699.77	16.5058
2702.46	17.4939
2705.15	19.0899
2707.85	20.0136
2710.54	20.7114
2713.22	21.0022
2715.91	20.7871
2718.6	20.9474
2721.29	20.9384
2723.97	21.1247
2726.66	21.1546
2729.34	20.4152
2732.02	19.446
2734.7	18.5254
2737.38	16.3514
2740.06	14.8648
2742.74	13.8521
2745.42	11.8378
2748.09	10.7309
2750.77	10.1443
2753.45	8.97806
2756.12	7.94739
2758.79	6.02742
2761.46	4.62343
2764.14	3.14338
2766.8	2.69451
2769.47	2.31587
2772.14	1.6825
2774.81	0.763937
2777.48	-0.133131
2780.14	-1.16242
2782.8	-1.18529
2785.47	-0.234257
2788.13	0.172196
2790.79	0.374917
2793.45	0.590329
2796.11	0.85554
2798.77	1.26489
2801.43	-0.261259
2804.09	-0.912043
2806.74	-1.74519
2809.4	-2.15962
2812.05	-2.84625
2814.71	-1.81597
2817.36	1.35756
2820.01	8.59565
2822.66	18.7598
2825.31	31.701
2827.96	47.2632
2830.6	63.7055
2833.25	81.0643
2835.9	99.1634
2838.54	116.044
2841.18	133.226
2843.83	149.492
2846.47	165.788
2849.11	182.266
2851.75	199.745
2854.39	219.348
2857.03	238.529
2859.66	255.989
2862.3	271.474
2864.94	283.969
2867.57	294.228
2870.2	303.627
2872.84	310.375
2875.47	316.775
2878.1	321.996
2880.73	329.427
2883.36	337.66
2885.99	346.197
2888.61	352.258
2891.24	357.491
2893.86	361.126
2896.49	365.258
2899.11	367.869
2901.73	369.393
2904.36	370.662
2906.98	374.397
2909.6	380.145
2912.21	386.444
2914.83	395.386
2917.45	405.829
2920.07	414.954
2922.68	419.309
2925.29	421.399
2927.91	421.992
2930.52	419.582
2933.13	415.509
2935.74	407.96
2938.35	399.255
2940.96	388.721
2943.57	376.055
2946.18	362.348
2948.78	345.791
2951.39	328.915
2953.99	312.314
2956.59	294.714
2959.2	277.399
2961.8	261.492
2964.4	244.896
2967	229.999
2969.6	217.006
2972.19	203.656
2974.79	191.266
2977.39	178.415
2979.98	165.787
2982.58	153.658
2985.17	139.545
2987.76	125.827
2990.35	113.321
2992.94	100.885
2995.53	87.3534
2998.12	75.6646
3000.71	64.6685
3003.3	55.5177
3005.88	46.2019
3008.47	36.5466
3011.05	28.5667
3013.64	22.1447
3016.22	16.8426
3018.8	12.2612
3021.38	7.77087
3023.96	5.77703
3026.54	3.20834
3029.12	1.50594
3031.69	0.196823
3034.27	0.106771
3036.84	-0.0549839
3039.42	-0.10647
3041.99	-0.0945743
3044.57	0.775993
3047.14	1.02641
3049.71	0.355004
3052.28	0.85346
3054.85	1.28477
3057.41	1.67991
3059.98	1.47219
3062.55	1.5418
3065.11	1.73068
3067.68	0.460001
3070.24	-0.0876984
3072.8	-0.220318
3075.36	0.393497
3077.93	0.742998
3080.49	0.974729
3083.04	1.03939
3085.6	1.88097
3088.16	2.02237
3090.72	2.69746
3093.27	3.02988
3095.83	4.60602
3098.38	6.67653
3100.93	7.54388
3103.49	8.28176
3106.04	9.79597
3108.59	11.2171
3111.14	13.4485
3113.69	15.5285
3116.23	17.9732
3118.78	20.209
3121.33	22.7247
3123.87	24.5418
3126.41	26.5603
3128.96	28.8206
3131.5	30.4063
3134.04	33.302
3136.58	36.5678
3139.12	38.6269
3141.66	40.4872
3144.2	42.5376
3146.74	44.0622
3149.27	48.6091