File: data/Raman/poly_smoothed/Mb_20_23_02_1x_45s_532 nm_x50_100%_600 gr_mm_01.txt
#Acq. time (s)=	45
#Accumulations=	2
#Range (cm-¹)=	200...3150
#Windows=	2
#Auto scanning=	Off
#Autofocus=	Off
#Macrospot=	Off
#AutoExposure=	Off
#Spike filter=	Multiple accum.
#Delay time (s)=	0
#Binning=	1
#Readout mode=	Signal
#DeNoise=	Off
#ICS correction=	On
#Dark correction=	Off
#Inst. Process=	Off
#Detector Gain=	Best Dynamic Range
#Detector ADC=	20 kHz
#Detector temperature (°C)=	-69.85
#Instrument=	LabRAM HR Evol
#Detector=	Synapse
#Objective=	x50
#Grating=	600 gr/mm
#ND Filter=	100%
#Laser (nm)=	532
#Hole=	100.021
#Range=	Auto
#Laser Pol.=	No
#Raman. Pol.=	No
#Laser Pol. (°)=	-0.0007625
#Raman Pol. (°)=	89.9995
#Collection=	Microscope
#StageXY=	Marzhauser
#StageZ=	Marzhauser
#X (µm)=	-6996.1
#Y (µm)=	2170.4
#Z (µm)=	-74.5
#Full time(mm:ss)=	3:18
#Project=
#Sample=
#Site=
#Title=	Mb_20_23_02_2x_45s_532 nm_x50_100%_600 gr_mm
#Remark=
#Date=	13.07.2022 13:02
#Acquired=	13.07.2022 13:02:01
#Base:Fit=	10.08.2022 10:29:19
#Base:Fit=	10.08.2022 10:29:37
#Base:Sub=	10.08.2022 10:31:46
#Filter:Polynom=	16.08.2022 10:13:29
#AxisType[0]=Intens
#AxisUnit[0]=Cnt
#AxisType[1]=Spectr
#AxisUnit[1]=1/cm
200.563	15.5985
204.194	16.1421
207.821	16.9791
211.449	17.4181
215.074	17.6789
218.699	19.3085
222.321	21.6455
225.941	23.351
229.562	20.8578
233.18	20.9645
236.796	22.7767
240.411	22.8281
244.026	22.5594
247.638	22.6837
251.248	21.0266
254.857	20.5345
258.465	20.5179
262.071	21.9066
265.678	20.7578
269.282	18.4223
272.884	17.9632
276.484	16.6445
280.084	15.403
283.682	14.8875
287.276	13.372
290.871	13.4476
294.465	14.5827
298.057	15.3156
301.648	16.6229
305.237	18.6065
308.823	19.9273
312.41	19.9303
315.995	19.4036
319.579	21.7809
323.16	23.7322
326.741	24.8036
330.321	25.2825
333.897	25.6948
337.474	26.4604
341.048	25.0953
344.622	24.7414
348.192	24.8965
351.764	23.3654
355.332	20.101
358.901	18.5536
362.466	17.1147
366.03	14.4709
369.594	12.3786
373.155	10.8738
376.715	9.69067
380.273	10.5718
383.832	9.45796
387.388	10.0684
390.942	8.57188
394.495	8.17013
398.047	9.78791
401.597	10.268
405.145	11.2914
408.693	11.7317
412.239	13.4661
415.783	15.6277
419.327	15.653
422.869	15.1151
426.409	14.5208
429.948	16.3419
433.486	15.9267
437.022	15.6435
440.558	14.7944
444.089	15.0249
447.622	17.1991
451.153	16.135
454.682	15.5485
458.208	14.5759
461.735	14.6245
465.259	14.3031
468.783	14.9288
472.306	14.0458
475.825	15.2627
479.346	16.9902
482.862	18.1233
486.38	19.4954
489.894	20.3005
493.407	22.7925
496.92	25.0731
500.43	25.9178
503.939	26.1692
507.448	25.6424
510.954	26.4202
514.459	26.7299
517.962	27.0432
521.466	27.8185
524.966	27.8071
528.466	28.4741
531.964	28.0171
535.46	25.3584
538.955	23.6183
542.449	22.1085
545.942	19.6547
549.433	18.8569
552.923	17.2364
556.412	16.3721
559.899	15.385
563.385	13.8312
566.867	12.8655
570.35	13.2992
573.832	14.96
577.313	15.6641
580.79	15.6052
584.268	14.9183
587.745	13.5196
591.218	12.4908
594.692	13.0689
598.164	12.1571
601.634	11.0315
605.104	9.19347
608.57	7.89067
612.037	6.79594
615.501	6.44266
618.966	5.47349
622.427	6.36784
625.887	7.77029
629.348	7.36523
632.806	7.49316
636.262	9.71614
639.716	10.7791
643.172	11.5817
646.624	13.8715
650.075	15.1247
653.524	18.0928
656.972	19.5498
660.419	20.4201
663.865	20.161
667.309	20.4698
670.752	20.5961
674.194	20.1545
677.634	19.9279
681.073	21.5063
684.511	21.2538
687.947	20.8637
691.382	20.8933
694.816	22.4382
698.247	22.105
701.678	24.0781
705.108	24.424
708.534	25.3367
711.962	26.3273
715.388	27.3726
718.81	29.1444
722.234	29.6132
725.654	30.9209
729.075	32.9892
732.492	34.0895
735.91	35.2091
739.325	36.9935
742.741	38.1362
746.153	40.1377
749.564	41.7378
752.976	44.1255
756.385	47.7179
759.792	50.9189
763.2	55.3711
766.604	57.1629
770.008	59.6037
773.41	61.9955
776.811	65.9273
780.21	67.4076
783.608	68.5152
787.005	68.6969
790.401	70.3964
793.795	73.0412
797.188	72.713
800.58	73.5275
803.971	73.788
807.36	76.6012
810.748	77.3421
814.135	77.6975
817.518	78.7749
820.902	79.8789
824.285	79.417
827.665	78.7301
831.045	77.5641
834.424	75.8616
837.8	76.5471
841.177	74.0508
844.55	71.1423
847.924	68.6289
851.295	66.1627
854.666	64.1347
858.034	62.9354
861.403	59.8751
864.769	58.0366
868.133	57.221
871.498	57.6805
874.86	56.1517
878.221	53.9288
881.58	53.8335
884.938	54.45
888.297	57.4913
891.653	58.1159
895.007	58.9242
898.36	60.1845
901.712	60.6639
905.063	61.5234
908.412	61.2026
911.76	61.1385
915.107	58.6829
918.452	57.1737
921.797	55.4444
925.138	52.5596
928.48	50.1005
931.82	48.1153
935.16	44.2931
938.496	42.3978
941.833	38.6038
945.168	34.1309
948.5	32.4815
951.834	30.9131
955.163	27.5927
958.494	25.8026
961.821	22.762
965.15	24.8955
968.474	26.6399
971.8	26.4999
975.123	26.9049
978.446	27.7634
981.766	29.6823
985.084	29.1812
988.402	31.1519
991.72	31.3217
995.035	30.1511
998.349	29.1088
1001.66	27.0782
1004.97	26.8929
1008.28	28.6817
1011.59	31.2751
1014.9	33.2482
1018.21	37.3252
1021.51	38.7018
1024.81	40.5287
1028.12	43.4564
1031.42	47.002
1034.72	49.527
1038.02	50.6171
1041.31	52.1001
1044.61	53.7254
1047.91	55.7692
1051.2	54.2453
1054.49	53.0014
1057.78	50.748
1061.07	48.7577
1064.36	44.693
1067.65	41.2646
1070.93	37.2988
1074.22	33.5959
1077.5	27.9618
1080.78	24.8693
1084.06	23.2091
1087.34	23.7727
1090.62	22.7799
1093.9	23.3562
1097.17	23.3602
1100.45	23.9124
1103.72	23.6719
1106.99	24.0865
1110.27	23.6016
1113.53	22.6717
1116.8	21.8807
1120.07	21.667
1123.33	20.9724
1126.6	19.1887
1129.86	18.3226
1133.12	16.2181
1136.38	14.6324
1139.64	12.6377
1142.9	10.4616
1146.16	8.57471
1149.41	8.3668
1152.67	6.82265
1155.92	4.71228
1159.17	4.02136
1162.42	3.78483
1165.67	3.69413
1168.92	2.97868
1172.16	3.28421
1175.41	3.50639
1178.65	4.77882
1181.9	4.71966
1185.14	5.14514
1188.38	5.38757
1191.62	6.24069
1194.86	7.79088
1198.09	9.82804
1201.33	10.5189
1204.56	11.5802
1207.8	12.8856
1211.03	15.1855
1214.26	15.6932
1217.49	16.7514
1220.71	18.4194
1223.94	21.6435
1227.16	22.2472
1230.39	24.8663
1233.61	25.8157
1236.83	28.9488
1240.05	31.4422
1243.27	33.8467
1246.49	35.0952
1249.71	36.0921
1252.92	37.2837
1256.14	39.7305
1259.35	41.8867
1262.56	44.2934
1265.77	47.1286
1268.98	48.9697
1272.19	51.8099
1275.4	55.3246
1278.6	57.9993
1281.81	62.1232
1285.01	64.377
1288.21	66.3143
1291.41	68.368
1294.61	68.2191
1297.81	70.1769
1301.01	72.1454
1304.2	72.9481
1307.4	73.1218
1310.59	72.5053
1313.78	70.7076
1316.97	69.34
1320.16	68.8683
1323.35	67.7738
1326.54	64.8483
1329.72	63.6309
1332.91	62.358
1336.09	59.4463
1339.27	58.8542
1342.45	58.5183
1345.64	55.8846
1348.81	55.7947
1351.99	56.2276
1355.17	55.5926
1358.34	55.6623
1361.51	55.0009
1364.69	55.865
1367.86	55.5329
1371.03	55.2398
1374.2	55.6558
1377.37	57.5356
1380.53	56.5117
1383.7	55.5518
1386.86	54.115
1390.02	54.4726
1393.19	55.5707
1396.35	55.2991
1399.51	55.7224
1402.66	56.4557
1405.82	58.261
1408.97	61.9161
1412.13	64.4164
1415.28	69.2737
1418.43	74.9384
1421.59	79.8801
1424.73	85.8009
1427.88	92.4236
1431.03	98.7561
1434.18	103.971
1437.32	110.036
1440.46	114.217
1443.61	116.522
1446.75	118.418
1449.89	116.825
1453.03	114.756
1456.16	112.173
1459.3	106.922
1462.44	100.383
1465.57	94.2044
1468.7	87.1179
1471.83	78.2553
1474.96	68.7028
1478.09	61.1684
1481.22	53.8172
1484.35	48.0109
1487.47	43.6825
1490.6	38.7125
1493.72	33.2405
1496.84	29.1956
1499.96	27.5022
1503.08	25.5211
1506.2	25.2879
1509.32	23.7755
1512.44	22.1128
1515.55	21.6633
1518.66	19.8022
1521.78	17.9198
1524.89	18.9011
1528	19.0764
1531.11	19.3759
1534.21	19.0786
1537.32	17.2732
1540.43	18.5602
1543.53	18.7016
1546.63	18.96
1549.74	19.3313
1552.84	20.9919
1555.94	23.5119
1559.03	27.2822
1562.13	30.4261
1565.23	31.7465
1568.32	32.7774
1571.42	35.6377
1574.51	38.8887
1577.6	41.7793
1580.69	44.8731
1583.78	47.0818
1586.87	48.0944
1589.95	49.2883
1593.04	50.4648
1596.12	50.2986
1599.21	51.5313
1602.29	52.6923
1605.37	50.5649
1608.45	49.8175
1611.53	46.6749
1614.6	45.5548
1617.68	46.3153
1620.75	47.6022
1623.83	48.682
1626.9	51.5339
1629.97	53.9721
1633.04	56.8609
1636.11	59.0644
1639.18	61.0537
1642.25	63.8789
1645.31	65.9405
1648.38	68.5583
1651.44	70.5502
1654.5	72.4982
1657.56	72.4695
1660.62	72.1458
1663.68	69.8824
1666.74	67.6285
1669.8	63.7051
1672.85	60.7993
1675.91	56.4102
1678.96	51.2594
1682.01	47.7598
1685.06	41.5853
1688.11	36.2612
1691.16	34.6658
1694.21	32.4712
1697.25	29.7231
1700.3	28.3613
1703.34	27.012
1706.39	25.7102
1709.43	24.4756
1712.47	23.7393
1715.51	22.7476
1718.54	22.2533
1721.58	21.1078
1724.62	20.895
1727.65	19.2099
1730.68	17.7511
1733.72	16.1081
1736.75	15.5018
1739.78	13.5015
1742.81	12.0659
1745.84	11.0191
1748.86	9.58839
1751.89	8.97302
1754.91	8.25017
1757.93	7.25702
1760.96	5.68702
1763.98	6.61493
1767	7.07473
1770.02	6.98469
1773.03	8.1043
1776.05	7.74226
1779.07	8.54939
1782.08	9.5847
1785.09	8.82423
1788.11	9.80104
1791.12	9.80939
1794.13	9.83799
1797.13	9.78622
1800.14	10.414
1803.15	10.4963
1806.15	10.6511
1809.16	10.9732
1812.16	9.83007
1815.16	8.76477
1818.16	8.43489
1821.16	7.60873
1824.16	6.41828
1827.16	5.39934
1830.16	4.82584
1833.15	5.54189
1836.14	5.49173
1839.14	6.17568
1842.13	6.80589
1845.12	7.05233
1848.11	5.86349
1851.1	5.81625
1854.08	5.95887
1857.07	4.97778
1860.05	5.38044
1863.04	5.9153
1866.02	5.13823
1869	6.10116
1871.98	5.8456
1874.96	6.6566
1877.94	5.49646
1880.92	4.37963
1882.51	3.42858
1885.5	3.24568
1888.48	2.91586
1891.47	3.20093
1894.46	3.22616
1897.44	4.06287
1900.42	4.11408
1903.41	5.11399
1906.39	5.2478
1909.37	7.31424
1912.35	8.44875
1915.32	7.19656
1918.3	6.6166
1921.27	5.59017
1924.25	5.6736
1927.22	6.36888
1930.19	6.03577
1933.17	6.78199
1936.14	5.62021
1939.11	6.17759
1942.07	7.92258
1945.04	6.96178
1948.01	7.23989
1950.97	6.53412
1953.93	7.32099
1956.9	6.74575
1959.86	7.33467
1962.82	7.71514
1965.78	6.74558
1968.74	7.42289
1971.69	7.79521
1974.65	7.41976
1977.6	7.69724
1980.56	9.35021
1983.51	9.20012
1986.46	7.0314
1989.41	6.44658
1992.36	6.87945
1995.31	6.61004
1998.26	6.7154
2001.2	6.1666
2004.15	6.54917
2007.09	6.62092
2010.04	7.10352
2012.98	8.24047
2015.92	8.14413
2018.86	8.66452
2021.8	8.78955
2024.73	10.368
2027.67	10.0399
2030.61	9.41867
2033.54	9.02204
2036.47	9.98462
2039.4	10.4403
2042.33	11.0557
2045.27	12.2574
2048.19	13.1088
2051.12	13.2624
2054.05	13.2296
2056.97	12.9688
2059.9	13.2239
2062.82	12.8862
2065.74	12.7156
2068.67	12.9569
2071.59	12.5758
2074.51	12.8514
2077.42	13.1365
2080.34	13.6838
2083.26	14.3752
2086.17	15.3557
2089.09	15.568
2092	16.5946
2094.91	18.1107
2097.82	17.6262
2100.73	18.5046
2103.64	19.3127
2106.55	21.7538
2109.45	23.0355
2112.36	24.0798
2115.26	25.6561
2118.17	26.631
2121.07	26.7775
2123.97	26.9588
2126.87	27.1365
2129.77	28.2195
2132.67	30.2263
2135.56	30.5432
2138.46	32.7205
2141.35	33.5704
2144.25	34.5802
2147.14	35.863
2150.03	38.6898
2152.92	40.5762
2155.81	42.4964
2158.7	45.1042
2161.59	46.8883
2164.47	48.1641
2167.36	49.9229
2170.24	51.4669
2173.13	51.6136
2176.01	51.8523
2178.89	52.435
2181.77	51.7053
2184.65	51.6695
2187.53	50.3013
2190.4	49.0857
2193.28	47.3699
2196.16	45.2148
2199.03	43.3142
2201.9	41.2032
2204.77	39.7095
2207.64	36.3723
2210.51	33.5703
2213.38	30.9605
2216.25	29.3839
2219.12	28.3133
2221.98	26.7627
2224.85	24.7174
2227.71	21.5569
2230.57	20.0791
2233.43	18.3507
2236.29	16.5541
2239.15	15.1683
2242.01	13.6538
2244.87	12.4454
2247.72	12.8301
2250.58	12.1797
2253.43	12.2981
2256.29	11.5435
2259.14	12.2996
2261.99	12.0145
2264.84	12.5562
2267.69	13.2073
2270.53	12.5762
2273.38	12.9422
2276.23	12.0302
2279.07	11.1384
2281.91	10.1769
2284.76	9.54205
2287.6	9.72995
2290.44	8.84964
2293.28	7.00653
2296.12	6.48971
2298.96	6.52033
2301.79	7.44505
2304.63	6.96127
2307.46	7.01412
2310.3	7.5306
2313.13	7.36956
2315.96	7.37499
2318.79	8.18906
2321.62	8.13503
2324.45	9.06341
2327.27	10.807
2330.1	10.7826
2332.92	11.2576
2335.75	11.1952
2338.57	9.71396
2341.39	9.26574
2344.21	7.88918
2347.04	6.34922
2349.85	5.17833
2352.67	5.18636
2355.49	4.44123
2358.3	3.56681
2361.12	2.25851
2363.93	2.16296
2366.75	3.25857
2369.56	2.5117
2372.37	3.0436
2375.18	3.38587
2377.99	2.85512
2380.8	2.43994
2383.6	3.29936
2386.41	3.83737
2389.21	5.00571
2392.02	5.00588
2394.82	6.03172
2397.62	6.1874
2400.42	5.77267
2403.22	6.08092
2406.02	6.57045
2408.82	6.35391
2411.62	6.6079
2414.41	5.94404
2417.21	6.79951
2420	6.91332
2422.79	6.83048
2425.59	5.53617
2428.38	3.53459
2431.17	3.32733
2433.95	3.57765
2436.74	3.67657
2439.53	4.03317
2442.31	2.69208
2445.1	2.88984
2447.88	2.77317
2450.67	3.24576
2453.45	3.08397
2456.23	2.00062
2459.01	1.59264
2461.79	1.86224
2464.57	0.875077
2467.34	1.15037
2470.12	1.56718
2472.89	2.00396
2475.67	0.927828
2478.44	2.17635
2481.21	1.44239
2483.98	1.36792
2486.75	1.10394
2489.52	1.07391
2492.29	0.511358
2495.05	-0.300123
2497.82	0.209032
2500.58	1.64958
2503.35	2.35462
2506.11	2.74835
2508.87	2.07208
2511.63	1.58681
2514.39	2.22902
2517.15	2.20895
2519.91	2.51976
2522.67	1.80025
2525.42	1.41381
2528.18	1.07302
2530.93	1.17217
2533.69	0.59146
2536.44	0.0765956
2539.19	-0.132437
2541.94	0.185144
2544.69	0.50261
2547.44	1.33465
2550.18	0.251599
2552.93	0.436824
2555.67	1.22243
2558.42	0.737918
2561.16	1.29924
2563.9	1.82255
2566.64	2.37395
2569.38	2.71954
2572.12	2.39183
2574.86	1.90241
2577.6	1.40073
2580.33	2.72975
2583.07	2.65732
2585.8	2.7895
2588.54	3.26689
2591.27	2.23299
2594	1.94776
2596.73	2.21863
2599.46	1.215
2602.19	1.05172
2604.92	1.67988
2607.64	1.89094
2610.37	2.40929
2613.09	3.03115
2615.82	2.54193
2618.54	3.44877
2621.26	3.60453
2623.98	4.31613
2626.7	4.01421
2629.42	4.08486
2632.14	5.37391
2634.86	5.41635
2637.57	5.80602
2640.29	5.70953
2643	5.35534
2645.71	5.59335
2648.43	5.36556
2651.14	5.44962
2653.85	5.69023
2656.56	5.1951
2659.26	5.65366
2661.97	5.63603
2664.68	5.46357
2667.38	5.84097
2670.09	6.73586
2672.79	6.49622
2675.49	6.58348
2678.19	6.40769
2680.89	6.57775
2683.59	6.67938
2686.29	7.10077
2688.99	7.21114
2691.69	7.98594
2694.38	9.29523
2697.08	12.0113
2699.77	13.6007
2702.46	13.2483
2705.15	13.8132
2707.85	14.0473
2710.54	13.0526
2713.22	14.2904
2715.91	14.222
2718.6	14.7579
2721.29	14.5987
2723.97	14.2314
2726.66	13.9905
2729.34	12.6224
2732.02	10.8496
2734.7	8.39545
2737.38	7.17854
2740.06	5.342
2742.74	5.11052
2745.42	4.81893
2748.09	5.13015
2750.77	4.70381
2753.45	4.75843
2756.12	5.30797
2758.79	5.30276
2761.46	5.63564
2764.14	5.09638
2766.8	4.93307
2769.47	4.74835
2772.14	4.51631
2774.81	4.53337
2777.48	4.38839
2780.14	4.04205
2782.8	3.58969
2785.47	3.2763
2788.13	2.38539
2790.79	1.30929
2793.45	0.684381
2796.11	-0.780731
2798.77	-1.99649
2801.43	-2.70213
2804.09	-2.50571
2806.74	-1.91147
2809.4	-1.65586
2812.05	-2.43961
2814.71	-2.56657
2817.36	0.241512
2820.01	4.43412
2822.66	9.22823
2825.31	17.1378
2827.96	25.8637
2830.6	35.814
2833.25	46.3522
2835.9	57.6267
2838.54	69.8623
2841.18	81.0444
2843.83	94.054
2846.47	105.663
2849.11	118.237
2851.75	131.122
2854.39	143.075
2857.03	155.111
2859.66	167.607
2862.3	176.336
2864.94	185.538
2867.57	192.641
2870.2	198.036
2872.84	202.105
2875.47	206.094
2878.1	209.367
2880.73	213.789
2883.36	219.013
2885.99	222.366
2888.61	225.354
2891.24	229.032
2893.86	232.879
2896.49	237.631
2899.11	241.415
2901.73	246.558
2904.36	250.231
2906.98	255.604
2909.6	261.995
2912.21	268.915
2914.83	276.75
2917.45	282.464
2920.07	287.969
2922.68	292.91
2925.29	295.124
2927.91	295.302
2930.52	294.127
2933.13	290.49
2935.74	285.399
2938.35	278.825
2940.96	270.118
2943.57	259.698
2946.18	248.137
2948.78	236.457
2951.39	224.043
2953.99	211.287
2956.59	199.308
2959.2	187.16
2961.8	174.422
2964.4	163.22
2967	151.803
2969.6	141.749
2972.19	133.15
2974.79	124.269
2977.39	114.462
2979.98	105.484
2982.58	97.0624
2985.17	88.9011
2987.76	80.2265
2990.35	71.209
2992.94	63.9905
2995.53	55.0772
2998.12	47.3669
3000.71	40.1744
3003.3	33.4406
3005.88	27.1649
3008.47	21.2961
3011.05	16.6023
3013.64	12.1043
3016.22	8.74402
3018.8	5.44405
3021.38	2.95731
3023.96	1.21009
3026.54	0.127141
3029.12	-0.940764
3031.69	-0.988653
3034.27	-1.18019
3036.84	-0.900098
3039.42	-0.40838
3041.99	0.684773
3044.57	0.953191
3047.14	2.00848
3049.71	2.91591
3052.28	4.35606
3054.85	5.33899
3057.41	5.18746
3059.98	4.77887
3062.55	5.61526
3065.11	6.10165
3067.68	5.70346
3070.24	5.42569
3072.8	4.15599
3075.36	3.87416
3077.93	3.5695
3080.49	2.94098
3083.04	2.74282
3085.6	2.04137
3088.16	1.66737
3090.72	1.68471
3093.27	1.94595
3095.83	1.47341
3098.38	1.62332
3100.93	2.48491
3103.49	2.88151
3106.04	3.47753
3108.59	4.74848
3111.14	6.51425
3113.69	8.84481
3116.23	10.6031
3118.78	11.8101
3121.33	13.372
3123.87	16.0496
3126.41	18.0331
3128.96	19.7602
3131.5	21.9188
3134.04	23.5947
3136.58	26.5295
3139.12	28.7572
3141.66	31.721
3144.2	34.2572
3146.74	36.1347
3149.27	38.4832