File: data/Raman/poly_smoothed/Mb_20_23_24_1x_45s_532 nm_x100_100%_600 gr_mm_01.txt
#Acq. time (s)=	45
#Accumulations=	2
#Range (cm-¹)=	200...3150
#Windows=	2
#Auto scanning=	Off
#Autofocus=	Off
#Macrospot=	Off
#AutoExposure=	Off
#Spike filter=	Multiple accum.
#Delay time (s)=	0
#Binning=	1
#Readout mode=	Signal
#DeNoise=	Off
#ICS correction=	On
#Dark correction=	Off
#Inst. Process=	Off
#Detector Gain=	Best Dynamic Range
#Detector ADC=	20 kHz
#Detector temperature (°C)=	-69.85
#Instrument=	LabRAM HR Evol
#Detector=	Synapse
#Objective=	x100
#Grating=	600 gr/mm
#ND Filter=	100%
#Laser (nm)=	532
#Hole=	100.021
#Range=	Auto
#Laser Pol.=	No
#Raman. Pol.=	No
#Laser Pol. (°)=	-0.0007625
#Raman Pol. (°)=	89.9995
#Collection=	Microscope
#StageXY=	Marzhauser
#StageZ=	Marzhauser
#X (µm)=	-6929.7
#Y (µm)=	2032.7
#Z (µm)=	-74.5
#Full time(mm:ss)=	3:20
#Project=
#Sample=
#Site=
#Title=	Mb_20_23_24_2x_45s_532 nm_x100_100%_600 gr_mm
#Remark=
#Date=	13.07.2022 15:02
#Acquired=	13.07.2022 15:02:40
#Base:Fit=	10.08.2022 10:29:37
#Edit:Spike=	10.08.2022 10:33:12
#Base:Sub=	10.08.2022 10:33:46
#Filter:Polynom=	16.08.2022 10:13:29
#AxisType[0]=Intens
#AxisUnit[0]=Cnt
#AxisType[1]=Spectr
#AxisUnit[1]=1/cm
200.563	130.849
204.194	129.535
207.821	125.777
211.449	120.083
215.074	114.884
218.699	111.249
222.321	105.119
225.941	96.6997
229.562	92.9176
233.18	89.2362
236.796	82.6318
240.411	76.4058
244.026	71.766
247.638	66.6223
251.248	62.3948
254.857	57.3019
258.465	53.1743
262.071	46.9481
265.678	45.073
269.282	41.2634
272.884	36.0785
276.484	31.9755
280.084	27.4136
283.682	20.2655
287.276	16.6521
290.871	14.5764
294.465	11.7375
298.057	10.9269
301.648	13.041
305.237	14.8252
308.823	16.367
312.41	18.7129
315.995	22.6427
319.579	27.6462
323.16	29.2988
326.741	31.918
330.321	36.8139
333.897	42.3179
337.474	45.1072
341.048	44.4121
344.622	43.9127
348.192	41.9723
351.764	39.8443
355.332	38.3033
358.901	32.6827
362.466	26.7236
366.03	20.6906
369.594	14.8641
373.155	13.3845
376.715	8.39002
380.273	3.67903
383.832	4.51664
387.388	5.04864
390.942	4.45273
394.495	6.24438
398.047	8.74062
401.597	11.3832
405.145	14.1534
408.693	15.7812
412.239	19.0023
415.783	22.6933
419.327	24.5979
422.869	23.766
426.409	24.3525
429.948	22.4045
433.486	19.4761
437.022	17.9428
440.558	18.1173
444.089	16.7707
447.622	16.3374
451.153	16.2523
454.682	17.1135
458.208	18.8183
461.735	19.7305
465.259	19.0591
468.783	20.9581
472.306	22.7939
475.825	25.4965
479.346	32.8594
482.862	36.4579
486.38	40.1349
489.894	44.4957
493.407	47.039
496.92	51.5264
500.43	51.7699
503.939	55.4452
507.448	56.1658
510.954	56.3541
514.459	56.7829
517.962	54.0136
521.466	56.3737
524.966	56.5339
528.466	59.1005
531.964	57.1536
535.46	56.1689
538.955	53.5639
542.449	53.2713
545.942	50.7841
549.433	45.8558
552.923	41.1119
556.412	38.8234
559.899	37.0842
563.385	37.9457
566.867	36.0985
570.35	31.7099
573.832	28.2855
577.313	25.5633
580.79	22.7545
584.268	20.7354
587.745	19.8875
591.218	16.6856
594.692	14.6654
598.164	12.8055
601.634	13.6362
605.104	14.0812
608.57	17.2936
612.037	17.954
615.501	21.0893
618.966	21.3469
622.427	21.9301
625.887	24.9896
629.348	26.0938
632.806	27.4822
636.262	30.5541
639.716	32.8374
643.172	33.2159
646.624	33.0584
650.075	29.8844
653.524	27.8198
656.972	23.5639
660.419	21.2258
663.865	18.3403
667.309	15.8662
670.752	13.1178
674.194	11.8872
677.634	10.6897
681.073	12.1698
684.511	13.3373
687.947	15.9788
691.382	18.944
694.816	18.747
698.247	19.7237
701.678	22.4629
705.108	22.1657
708.534	23.9451
711.962	28.4161
715.388	30.1187
718.81	30.4584
722.234	32.4041
725.654	31.9429
729.075	31.5965
732.492	30.5996
735.91	29.257
739.325	32.3889
742.741	33.106
746.153	35.1053
749.564	38.956
752.976	41.6957
756.385	46.4728
759.792	47.0657
763.2	51.7436
766.604	54.4356
770.008	57.5727
773.41	60.1958
776.811	60.8329
780.21	60.4484
783.608	60.8731
787.005	60.9701
790.401	61.1176
793.795	63.6671
797.188	61.9105
800.58	61.8138
803.971	63.223
807.36	64.3118
810.748	64.8838
814.135	65.982
817.518	67.3504
820.902	72.7934
824.285	74.3022
827.665	75.6225
831.045	79.2988
834.424	82.4562
837.8	80.4811
841.177	80.0706
844.55	78.9168
847.924	80.536
851.295	75.8745
854.666	76.2395
858.034	74.098
861.403	72.1706
864.769	72.3401
868.133	71.3199
871.498	69.5368
874.86	66.9252
878.221	65.5773
881.58	64.0581
884.938	64.7064
888.297	62.9603
891.653	59.2053
895.007	57.8376
898.36	58.5452
901.712	58.5058
905.063	58.5063
908.412	56.9872
911.76	57.0974
915.107	57.5465
918.452	56.4308
921.797	54.4587
925.138	55.5812
928.48	53.5499
931.82	52.863
935.16	52.5895
938.496	51.9409
941.833	48.925
945.168	43.6653
948.5	42.1474
951.834	41.4065
955.163	39.234
958.494	36.8803
961.821	34.4677
965.15	35.5483
968.474	37.6718
971.8	40.4413
975.123	42.8972
978.446	52.4157
981.766	56.3544
985.084	58.0845
988.402	59.8117
991.72	61.3553
995.035	62.5872
998.349	60.8848
1001.66	62.3548
1004.97	62.838
1008.28	65.4393
1011.59	69.8387
1014.9	71.7592
1018.21	71.8344
1021.51	74.7048
1024.81	78.01
1028.12	84.6666
1031.42	93.3789
1034.72	97.2792
1038.02	100.817
1041.31	105.055
1044.61	112.804
1047.91	116.633
1051.2	119.222
1054.49	119.594
1057.78	116.961
1061.07	112.423
1064.36	106.781
1067.65	99.9228
1070.93	95.6165
1074.22	90.4337
1077.5	84.3505
1080.78	80.6733
1084.06	76.7689
1087.34	72.5065
1090.62	71.9845
1093.9	74.2564
1097.17	78.3481
1100.45	82.5565
1103.72	86.7057
1106.99	91.9661
1110.27	93.3811
1113.53	93.9616
1116.8	92.9021
1120.07	91.9039
1123.33	90.0776
1126.6	87.1379
1129.86	84.56
1133.12	79.0339
1136.38	74.0918
1139.64	67.1737
1142.9	61.9287
1146.16	55.6545
1149.41	49.2437
1152.67	42.0698
1155.92	33.441
1159.17	26.7979
1162.42	18.2855
1165.67	12.0855
1168.92	9.675
1172.16	8.61133
1175.41	7.3182
1178.65	6.36682
1181.9	5.07655
1185.14	3.6363
1188.38	3.95425
1191.62	5.5685
1194.86	9.5023
1198.09	15.3739
1201.33	23.1056
1204.56	31.838
1207.8	38.8175
1211.03	46.807
1214.26	57.0026
1217.49	66.5954
1220.71	75.2437
1223.94	86.2356
1227.16	93.2835
1230.39	102.892
1233.61	112.736
1236.83	121.581
1240.05	128.416
1243.27	134.88
1246.49	140.725
1249.71	144.168
1252.92	143.574
1256.14	146.995
1259.35	153.47
1262.56	161.447
1265.77	169.528
1268.98	178.216
1272.19	186.437
1275.4	195.903
1278.6	205.064
1281.81	215.262
1285.01	225.561
1288.21	232.707
1291.41	237.568
1294.61	243.619
1297.81	247.201
1301.01	250.736
1304.2	254.41
1307.4	256.092
1310.59	258.763
1313.78	256.103
1316.97	251.843
1320.16	246.837
1323.35	240.799
1326.54	232.907
1329.72	223.066
1332.91	217.635
1336.09	218.007
1339.27	217.393
1342.45	212.461
1345.64	207.217
1348.81	202.844
1351.99	198.731
1355.17	196.419
1358.34	193.127
1361.51	189.577
1364.69	186.593
1367.86	181.947
1371.03	177.498
1374.2	174.912
1377.37	173.038
1380.53	170.836
1383.7	170.937
1386.86	167.178
1390.02	165.874
1393.19	165.421
1396.35	164.819
1399.51	163.278
1402.66	165.387
1405.82	172.052
1408.97	185.194
1412.13	201.766
1415.28	219.616
1418.43	237.928
1421.59	261.213
1424.73	286.474
1427.88	314.265
1431.03	339.965
1434.18	366.258
1437.32	389.458
1440.46	409.212
1443.61	424.645
1446.75	433.578
1449.89	436.789
1453.03	435.272
1456.16	428.262
1459.3	418.927
1462.44	405.013
1465.57	384.767
1468.7	361.793
1471.83	338.852
1474.96	313.074
1478.09	288.173
1481.22	265.516
1484.35	243.108
1487.47	221.619
1490.6	199.029
1493.72	180.69
1496.84	166.067
1499.96	151.404
1503.08	138.235
1506.2	127.107
1509.32	113.573
1512.44	103.389
1515.55	95.5467
1518.66	85.9605
1521.78	80.1785
1524.89	72.3466
1528	68.604
1531.11	67.0835
1534.21	68.5205
1537.32	71.5709
1540.43	76.696
1543.53	80.9651
1546.63	87.1125
1549.74	93.9047
1552.84	98.6863
1555.94	104.115
1559.03	110.591
1562.13	114.19
1565.23	118.127
1568.32	124.654
1571.42	133.735
1574.51	139.059
1577.6	147.087
1580.69	152.27
1583.78	155.749
1586.87	160.738
1589.95	169.408
1593.04	171.23
1596.12	175.164
1599.21	178.319
1602.29	181.195
1605.37	181.424
1608.45	181.619
1611.53	182.509
1614.6	184.785
1617.68	183.516
1620.75	184.995
1623.83	187.686
1626.9	191.597
1629.97	195.943
1633.04	199.786
1636.11	205.625
1639.18	209.687
1642.25	217.063
1645.31	222.86
1648.38	227.257
1651.44	230.12
1654.5	230.348
1657.56	228.572
1660.62	224.709
1663.68	220.632
1666.74	211.745
1669.8	200.482
1672.85	190.202
1675.91	175.442
1678.96	159.922
1682.01	144.795
1685.06	128.544
1688.11	115.86
1691.16	101.364
1694.21	89.1808
1697.25	78.8724
1700.3	68.0229
1703.34	58.8726
1706.39	53.7599
1709.43	48.3096
1712.47	43.4399
1715.51	39.5796
1718.54	38.9332
1721.58	36.7943
1724.62	34.2447
1727.65	34.4544
1730.68	32.5329
1733.72	29.798
1736.75	26.8049
1739.78	25.7646
1742.81	23.7129
1745.84	22.8877
1748.86	21.7383
1751.89	19.5661
1754.91	17.5977
1757.93	14.5876
1760.96	11.9221
1763.98	9.65629
1767	6.14697
1770.02	4.35549
1773.03	2.54202
1776.05	0.683697
1779.07	1.64435
1782.08	-0.736863
1785.09	-0.827937
1788.11	-0.0307709
1791.12	1.18001
1794.13	0.548515
1797.13	0.861994
1800.14	1.18336
1803.15	0.741453
1806.15	-0.848559
1809.16	-0.425237
1812.16	-0.0818265
1815.16	1.08042
1818.16	1.98726
1821.16	1.91002
1824.16	2.25169
1827.16	1.5815
1830.16	1.3297
1833.15	1.77062
1836.14	2.98052
1839.14	4.35378
1842.13	4.5067
1845.12	3.65745
1848.11	3.33174
1851.1	2.8939
1854.08	2.71802
1857.07	3.70598
1860.05	4.37859
1863.04	4.04104
1866.02	3.99381
1869	2.59429
1871.98	0.95991
1874.96	0.682753
1877.94	2.61282
1880.92	4.77395
1882.51	5.49283
1885.5	5.63118
1888.48	6.12945
1891.47	5.69223
1894.46	6.6114
1897.44	7.85222
1900.42	8.53075
1903.41	9.44562
1906.39	11.1193
1909.37	10.6946
1912.35	10.1542
1915.32	10.3818
1918.3	10.8893
1921.27	12.2338
1924.25	13.0049
1927.22	12.8324
1930.19	13.3357
1933.17	12.294
1936.14	11.4629
1939.11	10.6362
1942.07	9.70075
1945.04	11.0555
1948.01	12.129
1950.97	12.1902
1953.93	13.0941
1956.9	12.5327
1959.86	12.0281
1962.82	12.2966
1965.78	11.5497
1968.74	12.0124
1971.69	12.1516
1974.65	12.3477
1977.6	11.3527
1980.56	11.3969
1983.51	9.91714
1986.46	9.78391
1989.41	8.58679
1992.36	7.85513
1995.31	7.2253
1998.26	6.70765
2001.2	6.53827
2004.15	4.83925
2007.09	5.77359
2010.04	4.94098
2012.98	5.34544
2015.92	3.95402
2018.86	4.22523
2021.8	3.33698
2024.73	4.55989
2027.67	4.9985
2030.61	4.54151
2033.54	6.0866
2036.47	6.94988
2039.4	7.65107
2042.33	9.21431
2045.27	10.5414
2048.19	12.6792
2051.12	14.1942
2054.05	17.1126
2056.97	17.7997
2059.9	19.0635
2062.82	21.2438
2065.74	23.9307
2068.67	25.6149
2071.59	25.8502
2074.51	26.3172
2077.42	28.9577
2080.34	30.7541
2083.26	32.1619
2086.17	33.2046
2089.09	33.3446
2092	35.0878
2094.91	34.5746
2097.82	36.1039
2100.73	38.8937
2103.64	39.8331
2106.55	41.0148
2109.45	43.403
2112.36	45.9854
2115.26	48.6586
2118.17	53.1524
2121.07	58.1652
2123.97	63.2013
2126.87	67.0371
2129.77	72.0568
2132.67	76.8252
2135.56	82.72
2138.46	89.6522
2141.35	96.3719
2144.25	103.232
2147.14	112.451
2150.03	119.88
2152.92	127.491
2155.81	134.161
2158.7	141.452
2161.59	148.313
2164.47	155.384
2167.36	159.251
2170.24	163.917
2173.13	165.835
2176.01	167.046
2178.89	165.871
2181.77	163.39
2184.65	159.715
2187.53	155.937
2190.4	152.081
2193.28	145.478
2196.16	138.627
2199.03	129.99
2201.9	122.86
2204.77	115.013
2207.64	106.451
2210.51	98.5121
2213.38	90.415
2216.25	81.7111
2219.12	75.0528
2221.98	68.22
2224.85	63.878
2227.71	59.9566
2230.57	56.1318
2233.43	51.8189
2236.29	47.2372
2239.15	45.5077
2242.01	43.8927
2244.87	40.9222
2247.72	38.2542
2250.58	36.7584
2253.43	35.7658
2256.29	36.1522
2259.14	34.32
2261.99	34.0604
2264.84	32.5735
2267.69	31.3166
2270.53	29.7206
2273.38	28.7775
2276.23	26.2456
2279.07	23.562
2281.91	21.3322
2284.76	18.7488
2287.6	18.9286
2290.44	17.0567
2293.28	14.6709
2296.12	13.2049
2298.96	12.1795
2301.79	12.3144
2304.63	11.2066
2307.46	10.5671
2310.3	10.0205
2313.13	8.99558
2315.96	10.3
2318.79	10.8649
2321.62	11.1439
2324.45	9.66666
2327.27	10.8689
2330.1	9.49996
2332.92	9.46869
2335.75	8.05889
2338.57	7.75889
2341.39	6.9114
2344.21	6.01087
2347.04	4.65496
2349.85	3.88736
2352.67	3.5746
2355.49	3.09936
2358.3	2.89355
2361.12	1.77005
2363.93	0.810986
2366.75	-0.466391
2369.56	-0.704729
2372.37	-1.86669
2375.18	-2.84417
2377.99	-2.65767
2380.8	-1.658
2383.6	-0.77602
2386.41	-1.58516
2389.21	-1.77195
2392.02	-1.35825
2394.82	-1.21841
2397.62	-1.17352
2400.42	-2.09038
2403.22	-1.84093
2406.02	-1.30017
2408.82	0.0363342
2411.62	2.52945
2414.41	1.87933
2417.21	2.96735
2420	2.86731
2422.79	3.19121
2425.59	5.04439
2428.38	5.71038
2431.17	4.99869
2433.95	4.57024
2436.74	4.03547
2439.53	3.30492
2442.31	5.22877
2445.1	5.34118
2447.88	5.93682
2450.67	4.98689
2453.45	4.47272
2456.23	4.48682
2459.01	6.06696
2461.79	5.98367
2464.57	4.63295
2467.34	3.98022
2470.12	5.3003
2472.89	5.58129
2475.67	5.23526
2478.44	3.64891
2481.21	3.90686
2483.98	1.83959
2486.75	1.12826
2489.52	0.640918
2492.29	0.942452
2495.05	2.43958
2497.82	2.77426
2500.58	2.06372
2503.35	1.68506
2506.11	1.83828
2508.87	2.52566
2511.63	3.65885
2514.39	4.11738
2517.15	4.09471
2519.91	5.58549
2522.67	8.37251
2525.42	8.56688
2528.18	10.0409
2530.93	9.78004
2533.69	10.6755
2536.44	10.4599
2539.19	11.2857
2541.94	11.843
2544.69	11.7763
2547.44	12.1841
2550.18	11.8024
2552.93	11.7132
2555.67	12.2707
2558.42	14.0528
2561.16	15.4485
2563.9	16.4076
2566.64	15.5613
2569.38	14.2302
2572.12	13.6778
2574.86	14.5849
2577.6	14.0325
2580.33	14.591
2583.07	15.2793
2585.8	15.2283
2588.54	15.1044
2591.27	15.2752
2594	14.2468
2596.73	14.7905
2599.46	13.349
2602.19	13.1208
2604.92	13.0312
2607.64	13.4288
2610.37	13.875
2613.09	12.7426
2615.82	12.7146
2618.54	11.4708
2621.26	11.1082
2623.98	12.5323
2626.7	12.8509
2629.42	12.871
2632.14	12.0215
2634.86	12.6079
2637.57	12.9114
2640.29	14.0926
2643	14.8807
2645.71	16.7576
2648.43	17.4877
2651.14	18.6517
2653.85	18.5255
2656.56	19.0809
2659.26	19.7276
2661.97	18.1022
2664.68	18.4264
2667.38	19.3745
2670.09	19.4298
2672.79	19.0886
2675.49	19.4796
2678.19	19.7921
2680.89	19.6377
2683.59	19.5005
2686.29	20.4138
2688.99	20.9937
2691.69	22.537
2694.38	24.7585
2697.08	27.1315
2699.77	30.5727
2702.46	32.7949
2705.15	37.1811
2707.85	41.9176
2710.54	46.3887
2713.22	49.1248
2715.91	51.6437
2718.6	52.9301
2721.29	54.6041
2723.97	55.2942
2726.66	55.1965
2729.34	55.7194
2732.02	55.0857
2734.7	52.9623
2737.38	49.5733
2740.06	46.6893
2742.74	43.0021
2745.42	38.2181
2748.09	33.0067
2750.77	29.2602
2753.45	26.222
2756.12	22.8638
2758.79	19.3225
2761.46	16.7224
2764.14	12.7614
2766.8	9.68087
2769.47	9.9871
2772.14	8.65156
2774.81	6.21238
2777.48	3.74775
2780.14	2.91139
2782.8	2.10214
2785.47	-0.80766
2788.13	-1.21368
2790.79	-1.0497
2793.45	-0.215517
2796.11	0.0928545
2798.77	0.340461
2801.43	1.8345
2804.09	1.14893
2806.74	-1.07969
2809.4	-5.00971
2812.05	-5.7057
2814.71	-0.780026
2817.36	12.3741
2820.01	33.9071
2822.66	60.5987
2825.31	91.3126
2827.96	127.565
2830.6	168.395
2833.25	212.161
2835.9	255.683
2838.54	300.605
2841.18	344.92
2843.83	389.877
2846.47	435.072
2849.11	481.343
2851.75	536.891
2854.39	594.704
2857.03	652.047
2859.66	706.117
2862.3	752.146
2864.94	795.182
2867.57	828.312
2870.2	854.862
2872.84	878.904
2875.47	900.921
2878.1	924.309
2880.73	948.387
2883.36	970.343
2885.99	989.991
2888.61	1005.36
2891.24	1016.89
2893.86	1027.09
2896.49	1036.45
2899.11	1044.35
2901.73	1054.47
2904.36	1067.45
2906.98	1083.86
2909.6	1104.84
2912.21	1134.96
2914.83	1170.99
2917.45	1204.68
2920.07	1233.66
2922.68	1255.17
2925.29	1267.3
2927.91	1271.9
2930.52	1270.14
2933.13	1261.76
2935.74	1243.97
2938.35	1218.86
2940.96	1190.49
2943.57	1153
2946.18	1112.94
2948.78	1065.15
2951.39	1012.79
2953.99	961.051
2956.59	908.209
2959.2	855.832
2961.8	805.959
2964.4	759.273
2967	714.412
2969.6	670.661
2972.19	632.901
2974.79	593.258
2977.39	555.822
2979.98	514.683
2982.58	474.026
2985.17	433.956
2987.76	391.529
2990.35	352.676
2992.94	311.629
2995.53	273.664
2998.12	237.987
3000.71	205.401
3003.3	175.51
3005.88	148.237
3008.47	120.787
3011.05	96.9053
3013.64	76.9105
3016.22	59.4729
3018.8	46.2007
3021.38	31.723
3023.96	22.3321
3026.54	12.9093
3029.12	7.38883
3031.69	3.83096
3034.27	1.57191
3036.84	1.42764
3039.42	2.31158
3041.99	3.19339
3044.57	4.35385
3047.14	6.29532
3049.71	9.46144
3052.28	10.0082
3054.85	10.6177
3057.41	13.0105
3059.98	12.6032
3062.55	14.4618
3065.11	15.2588
3067.68	14.2423
3070.24	12.6794
3072.8	12.5278
3075.36	10.6609
3077.93	8.56189
3080.49	5.43191
3083.04	3.63928
3085.6	1.55448
3088.16	0.849198
3090.72	3.05965
3093.27	4.48125
3095.83	6.8373
3098.38	9.66688
3100.93	12.6811
3103.49	16.8097
3106.04	20.7728
3108.59	25.336
3111.14	30.3638
3113.69	37.137
3116.23	42.6447
3118.78	48.2539
3121.33	54.5973
3123.87	61.3552
3126.41	69.2251
3128.96	75.7299
3131.5	83.841
3134.04	91.651
3136.58	99.4728
3139.12	106.657
3141.66	116.216
3144.2	126.387
3146.74	137.772
3149.27	148.888