File: data/Raman/poly_smoothed/Mb_20_23_34_1x_45s_532 nm_x100_100%_600 gr_mm_01.txt
#Acq. time (s)=	45
#Accumulations=	2
#Range (cm-¹)=	200...3150
#Windows=	2
#Auto scanning=	Off
#Autofocus=	Off
#Macrospot=	Off
#AutoExposure=	Off
#Spike filter=	Multiple accum.
#Delay time (s)=	0
#Binning=	1
#Readout mode=	Signal
#DeNoise=	Off
#ICS correction=	On
#Dark correction=	Off
#Inst. Process=	Off
#Detector Gain=	Best Dynamic Range
#Detector ADC=	20 kHz
#Detector temperature (°C)=	-69.85
#Instrument=	LabRAM HR Evol
#Detector=	Synapse
#Objective=	x100
#Grating=	600 gr/mm
#ND Filter=	100%
#Laser (nm)=	532
#Hole=	100.021
#Range=	Auto
#Laser Pol.=	No
#Raman. Pol.=	No
#Laser Pol. (°)=	-0.0007625
#Raman Pol. (°)=	89.9995
#Collection=	Microscope
#StageXY=	Marzhauser
#StageZ=	Marzhauser
#X (µm)=	-6950.3
#Y (µm)=	1949.1
#Z (µm)=	-75
#Full time(mm:ss)=	3:18
#Project=
#Sample=
#Site=
#Title=	Mb_20_23_34_2x_45s_532 nm_x100_100%_600 gr_mm
#Remark=
#Date=	13.07.2022 15:46
#Acquired=	13.07.2022 15:46:33
#Base:Fit=	10.08.2022 10:29:37
#Base:Sub=	10.08.2022 10:34:43
#Filter:Polynom=	16.08.2022 10:13:29
#AxisType[0]=Intens
#AxisUnit[0]=Cnt
#AxisType[1]=Spectr
#AxisUnit[1]=1/cm
200.563	32.479
204.194	33.5372
207.821	33.4006
211.449	32.6915
215.074	30.7267
218.699	28.7443
222.321	24.2914
225.941	21.3019
229.562	19.0479
233.18	15.9222
236.796	15.337
240.411	15.1621
244.026	12.1824
247.638	11.0012
251.248	8.14296
254.857	8.81203
258.465	8.97299
262.071	8.02088
265.678	7.34927
269.282	6.65704
272.884	8.43385
276.484	7.48849
280.084	5.88052
283.682	5.27825
287.276	7.32327
290.871	6.25267
294.465	6.23765
298.057	7.43425
301.648	7.0239
305.237	7.75043
308.823	9.98085
312.41	11.3753
315.995	12.3091
319.579	12.7522
323.16	13.6743
326.741	14.9239
330.321	14.1765
333.897	13.8122
337.474	16.7032
341.048	16.3847
344.622	19.5861
348.192	16.0006
351.764	14.1993
355.332	13.9874
358.901	10.6176
362.466	9.67256
366.03	8.99156
369.594	7.51353
373.155	6.73774
376.715	6.0654
380.273	7.54651
383.832	11.2303
387.388	13.801
390.942	15.223
394.495	16.5027
398.047	17.1954
401.597	17.1774
405.145	17.8082
408.693	18.0748
412.239	19.6049
415.783	19.9485
419.327	18.8567
422.869	20.8637
426.409	19.8009
429.948	18.3062
433.486	17.2692
437.022	13.4893
440.558	14.2692
444.089	13.3436
447.622	11.5194
451.153	11.3485
454.682	11.2962
458.208	10.3808
461.735	11.5859
465.259	12.8768
468.783	14.2583
472.306	15.8929
475.825	17.0041
479.346	19.3673
482.862	20.378
486.38	22.0828
489.894	26.4444
493.407	28.0195
496.92	30.1005
500.43	33.2173
503.939	34.187
507.448	35.0073
510.954	36.2199
514.459	35.7515
517.962	35.1495
521.466	34.1903
524.966	35.0931
528.466	34.9617
531.964	31.968
535.46	31.78
538.955	29.5839
542.449	28.2401
545.942	25.7183
549.433	23.987
552.923	19.7659
556.412	18.1943
559.899	16.1537
563.385	14.4396
566.867	12.8251
570.35	11.6543
573.832	8.18792
577.313	9.74577
580.79	9.30471
584.268	7.8682
587.745	5.34019
591.218	3.97578
594.692	3.48787
598.164	3.41423
601.634	3.22524
605.104	1.64546
608.57	3.19679
612.037	4.91487
615.501	4.82894
618.966	5.22316
622.427	5.27736
625.887	5.63238
629.348	4.44667
632.806	4.9007
636.262	3.67064
639.716	3.32889
643.172	3.04034
646.624	2.00832
650.075	2.22785
653.524	2.60855
656.972	3.54004
660.419	2.62469
663.865	3.12394
667.309	2.41215
670.752	0.338631
674.194	1.61803
677.634	2.94495
681.073	3.66648
684.511	1.77022
687.947	1.74731
691.382	3.23427
694.816	6.76628
698.247	7.67603
701.678	8.50222
705.108	10.1774
708.534	11.5843
711.962	13.5432
715.388	14.984
718.81	15.8635
722.234	16.2878
725.654	17.9145
729.075	19.5485
732.492	20.721
735.91	22.8296
739.325	26.3507
742.741	28.1256
746.153	27.565
749.564	31.2295
752.976	33.0546
756.385	36.7713
759.792	40.118
763.2	40.1195
766.604	42.9839
770.008	45.8703
773.41	50.2686
776.811	53.2473
780.21	56.0778
783.608	57.4918
787.005	58.9139
790.401	60.3953
793.795	62.537
797.188	64.3178
800.58	64.2779
803.971	63.9481
807.36	65.1423
810.748	65.7874
814.135	66.6797
817.518	65.9115
820.902	66.4782
824.285	66.7594
827.665	67.1198
831.045	66.4731
834.424	66.6087
837.8	66.1319
841.177	64.521
844.55	62.1095
847.924	62.1049
851.295	61.3434
854.666	60.4517
858.034	61.1884
861.403	59.6972
864.769	59.8091
868.133	59.0638
871.498	58.6004
874.86	56.6326
878.221	55.5289
881.58	52.9392
884.938	52.2597
888.297	51.6594
891.653	52.5123
895.007	52.605
898.36	51.9249
901.712	51.2358
905.063	52.8061
908.412	53.333
911.76	53.8083
915.107	52.8486
918.452	50.3328
921.797	51.4236
925.138	52.6247
928.48	51.9139
931.82	51.3587
935.16	48.4765
938.496	45.7289
941.833	43.4756
945.168	39.6303
948.5	37.4265
951.834	33.4039
955.163	30.1558
958.494	26.1099
961.821	22.435
965.15	20.4905
968.474	22.5516
971.8	23.2358
975.123	22.9931
978.446	22.9524
981.766	24.5662
985.084	27.0077
988.402	26.9219
991.72	26.2751
995.035	26.7197
998.349	28.0644
1001.66	30.4224
1004.97	32.4991
1008.28	35.3196
1011.59	37.1503
1014.9	40.1484
1018.21	43.6572
1021.51	49.2268
1024.81	54.6278
1028.12	65.2155
1031.42	71.963
1034.72	77.3382
1038.02	83.5834
1041.31	87.9063
1044.61	94.2689
1047.91	98.6292
1051.2	102.892
1054.49	103.277
1057.78	102.255
1061.07	102.465
1064.36	99.2991
1067.65	96.9074
1070.93	89.9111
1074.22	84.7545
1077.5	79.5901
1080.78	75.4211
1084.06	67.7512
1087.34	61.7273
1090.62	62.5156
1093.9	63.6284
1097.17	67.1398
1100.45	71.256
1103.72	75.7255
1106.99	81.0368
1110.27	83.3311
1113.53	83.1194
1116.8	81.7043
1120.07	81.7866
1123.33	80.149
1126.6	76.1159
1129.86	70.494
1133.12	68.239
1136.38	62.666
1139.64	57.8748
1142.9	53.9513
1146.16	47.0357
1149.41	38.8923
1152.67	32.6838
1155.92	24.1286
1159.17	16.693
1162.42	10.7826
1165.67	4.74546
1168.92	4.96901
1172.16	6.1857
1175.41	8.40905
1178.65	9.24991
1181.9	8.64565
1185.14	9.28179
1188.38	9.98956
1191.62	9.06013
1194.86	9.66378
1198.09	11.5285
1201.33	15.0028
1204.56	17.57
1207.8	22.0657
1211.03	26.1235
1214.26	32.5485
1217.49	38.8904
1220.71	44.7454
1223.94	50.8703
1227.16	54.7652
1230.39	60.9981
1233.61	65.4498
1236.83	69.4025
1240.05	74.6388
1243.27	77.9629
1246.49	81.1868
1249.71	80.9472
1252.92	83.247
1256.14	85.7858
1259.35	90.3304
1262.56	97.1774
1265.77	104.886
1268.98	111.551
1272.19	119.701
1275.4	129.039
1278.6	136.913
1281.81	142.254
1285.01	148.057
1288.21	154.147
1291.41	158.354
1294.61	161.766
1297.81	161.497
1301.01	161.423
1304.2	161.516
1307.4	159.738
1310.59	157.026
1313.78	151.203
1316.97	147.04
1320.16	138.789
1323.35	132.01
1326.54	124.543
1329.72	116.089
1332.91	113.585
1336.09	111.521
1339.27	112.071
1342.45	109.89
1345.64	108.777
1348.81	107.286
1351.99	107.726
1355.17	107.46
1358.34	106.459
1361.51	104.822
1364.69	104.658
1367.86	103.401
1371.03	101.389
1374.2	98.4252
1377.37	97.5279
1380.53	99.8768
1383.7	100.572
1386.86	101.655
1390.02	101.112
1393.19	100.813
1396.35	98.3358
1399.51	99.423
1402.66	105.076
1405.82	117.368
1408.97	132.897
1412.13	150.546
1415.28	167.675
1418.43	187.511
1421.59	207.959
1424.73	229.196
1427.88	250.916
1431.03	274.353
1434.18	295.752
1437.32	311.466
1440.46	326.215
1443.61	335.472
1446.75	341.299
1449.89	340.23
1453.03	337.215
1456.16	328.318
1459.3	314.688
1462.44	295.994
1465.57	273.348
1468.7	247.339
1471.83	221.437
1474.96	196.64
1478.09	175.598
1481.22	159.777
1484.35	141.661
1487.47	124.622
1490.6	108.624
1493.72	93.7481
1496.84	81.9617
1499.96	71.6903
1503.08	65.68
1506.2	60.8403
1509.32	57.5971
1512.44	54.1404
1515.55	51.7761
1518.66	49.4476
1521.78	46.9395
1524.89	45.728
1528	45.4505
1531.11	44.2799
1534.21	44.0866
1537.32	44.1629
1540.43	45.4413
1543.53	46.4276
1546.63	46.6369
1549.74	49.1219
1552.84	51.7169
1555.94	54.3286
1559.03	56.6725
1562.13	58.7276
1565.23	60.233
1568.32	62.273
1571.42	65.9759
1574.51	69.4257
1577.6	74.5211
1580.69	78.6554
1583.78	80.4282
1586.87	85.3028
1589.95	89.0654
1593.04	90.6225
1596.12	92.0526
1599.21	93.2176
1602.29	93.054
1605.37	91.4382
1608.45	90.1106
1611.53	90.8185
1614.6	92.3755
1617.68	91.9186
1620.75	93.9499
1623.83	93.7067
1626.9	96.4135
1629.97	95.2815
1633.04	97.8913
1636.11	99.6959
1639.18	102.67
1642.25	107.078
1645.31	110.544
1648.38	113.934
1651.44	116.533
1654.5	119.211
1657.56	118.505
1660.62	117.736
1663.68	116.334
1666.74	113.766
1669.8	109.008
1672.85	104.431
1675.91	97.8211
1678.96	91.7005
1682.01	84.3154
1685.06	78.9319
1688.11	73.8734
1691.16	67.6541
1694.21	61.2865
1697.25	54.905
1700.3	47.5074
1703.34	42.0131
1706.39	36.8888
1709.43	33.4471
1712.47	30.0945
1715.51	27.7956
1718.54	27.17
1721.58	25.8292
1724.62	26.4518
1727.65	25.6626
1730.68	24.9672
1733.72	24.7699
1736.75	23.72
1739.78	23.2158
1742.81	23.06
1745.84	21.3264
1748.86	19.7338
1751.89	19.6864
1754.91	19.0459
1757.93	18.6925
1760.96	17.678
1763.98	16.8139
1767	14.2953
1770.02	12.1155
1773.03	9.07623
1776.05	7.36875
1779.07	5.21133
1782.08	3.71805
1785.09	3.82854
1788.11	4.16924
1791.12	4.79802
1794.13	4.92476
1797.13	4.389
1800.14	4.36454
1803.15	4.19284
1806.15	2.96322
1809.16	1.90236
1812.16	1.04386
1815.16	0.385806
1818.16	-0.469169
1821.16	0.461741
1824.16	0.79025
1827.16	0.668209
1830.16	-0.436407
1833.15	-0.919503
1836.14	0.254024
1839.14	1.2922
1842.13	1.78587
1845.12	1.28855
1848.11	1.23122
1851.1	2.21316
1854.08	2.70544
1857.07	4.23671
1860.05	5.28324
1863.04	6.20561
1866.02	6.47959
1869	5.87501
1871.98	5.50525
1874.96	6.15217
1877.94	4.97714
1880.92	4.84237
1882.51	4.97051
1885.5	4.13944
1888.48	3.01698
1891.47	3.06236
1894.46	3.87551
1897.44	1.88023
1900.42	2.85141
1903.41	3.5333
1906.39	3.99999
1909.37	4.99843
1912.35	5.79059
1915.32	6.31651
1918.3	5.89291
1921.27	6.45836
1924.25	6.5606
1927.22	6.33979
1930.19	6.53573
1933.17	6.7139
1936.14	6.05818
1939.11	6.07826
1942.07	5.8778
1945.04	5.86966
1948.01	5.27152
1950.97	4.9978
1953.93	5.69041
1956.9	6.2116
1959.86	6.06328
1962.82	8.19696
1965.78	8.77929
1968.74	8.30609
1971.69	9.03175
1974.65	9.46834
1977.6	8.76347
1980.56	8.49756
1983.51	8.96759
1986.46	8.43122
1989.41	7.05067
1992.36	6.81412
1995.31	6.03376
1998.26	5.28279
2001.2	5.15798
2004.15	6.22052
2007.09	6.70454
2010.04	7.90342
2012.98	8.86993
2015.92	7.70253
2018.86	8.3232
2021.8	8.4084
2024.73	9.56969
2027.67	9.48906
2030.61	10.2676
2033.54	9.42329
2036.47	9.54602
2039.4	9.89577
2042.33	8.18465
2045.27	8.27326
2048.19	8.03095
2051.12	7.43827
2054.05	8.41437
2056.97	9.47873
2059.9	10.6451
2062.82	9.64377
2065.74	11.518
2068.67	12.7884
2071.59	16.0748
2074.51	18.0175
2077.42	19.8743
2080.34	20.851
2083.26	21.5063
2086.17	21.8436
2089.09	22.1078
2092	22.4071
2094.91	23.4604
2097.82	22.5644
2100.73	23.6349
2103.64	24.5866
2106.55	24.0438
2109.45	23.9386
2112.36	24.6373
2115.26	24.8779
2118.17	26.0164
2121.07	28.5134
2123.97	31.3218
2126.87	34.9642
2129.77	37.4773
2132.67	42.3557
2135.56	46.4836
2138.46	49.6024
2141.35	51.8881
2144.25	54.181
2147.14	57.6917
2150.03	60.7845
2152.92	64.8673
2155.81	68.0163
2158.7	70.4446
2161.59	73.4579
2164.47	76.1874
2167.36	76.632
2170.24	77.0189
2173.13	78.2193
2176.01	77.1693
2178.89	75.8688
2181.77	75.1496
2184.65	74.2695
2187.53	72.1075
2190.4	69.9247
2193.28	67.5907
2196.16	65.7966
2199.03	61.5466
2201.9	58.2424
2204.77	54.1825
2207.64	50.2369
2210.51	46.9025
2213.38	43.4712
2216.25	40.0917
2219.12	38.2755
2221.98	35.7441
2224.85	34.6808
2227.71	31.7466
2230.57	31.6934
2233.43	30.4755
2236.29	29.4775
2239.15	28.2138
2242.01	28.257
2244.87	27.7884
2247.72	28.3807
2250.58	29.1251
2253.43	29.2553
2256.29	28.9264
2259.14	26.77
2261.99	25.8477
2264.84	25.6192
2267.69	23.6777
2270.53	22.0765
2273.38	21.2815
2276.23	19.5471
2279.07	19.2265
2281.91	18.2452
2284.76	16.0308
2287.6	15.3212
2290.44	14.1477
2293.28	10.9254
2296.12	11.8341
2298.96	12.1441
2301.79	13.0293
2304.63	13.0825
2307.46	12.7429
2310.3	13.8595
2313.13	14.3245
2315.96	13.3359
2318.79	13.3169
2321.62	11.3057
2324.45	9.50962
2327.27	9.3829
2330.1	8.46943
2332.92	6.99259
2335.75	5.77314
2338.57	4.4227
2341.39	5.20274
2344.21	3.45043
2347.04	3.01581
2349.85	1.44428
2352.67	-0.846548
2355.49	-1.51692
2358.3	-1.56981
2361.12	-1.59952
2363.93	-0.748682
2366.75	0.834276
2369.56	1.92669
2372.37	2.76882
2375.18	3.84424
2377.99	4.67237
2380.8	4.70053
2383.6	5.47963
2386.41	6.12349
2389.21	6.22264
2392.02	7.06982
2394.82	7.67519
2397.62	7.68406
2400.42	7.89735
2403.22	6.86131
2406.02	7.38914
2408.82	8.52411
2411.62	8.03508
2414.41	6.42219
2417.21	5.5349
2420	4.60281
2422.79	5.23293
2425.59	5.72167
2428.38	4.72898
2431.17	3.50726
2433.95	3.94474
2436.74	3.26611
2439.53	3.55244
2442.31	4.1165
2445.1	3.80993
2447.88	4.36063
2450.67	4.85864
2453.45	5.57175
2456.23	4.20496
2459.01	4.41092
2461.79	3.69091
2464.57	3.5394
2467.34	3.39039
2470.12	3.55629
2472.89	3.33216
2475.67	2.68935
2478.44	1.36402
2481.21	0.931706
2483.98	0.706893
2486.75	-0.606772
2489.52	-0.182176
2492.29	0.189685
2495.05	-1.00548
2497.82	-0.782669
2500.58	-1.80865
2503.35	-1.06799
2506.11	-0.0047442
2508.87	0.869244
2511.63	0.231023
2514.39	0.692771
2517.15	1.10205
2519.91	2.76742
2522.67	3.68609
2525.42	5.24475
2528.18	5.80549
2530.93	7.43598
2533.69	7.3579
2536.44	7.46557
2539.19	6.75633
2541.94	6.23697
2544.69	5.78934
2547.44	6.64805
2550.18	6.02861
2552.93	5.92607
2555.67	5.70715
2558.42	5.54755
2561.16	4.51627
2563.9	5.40803
2566.64	5.92448
2569.38	5.93969
2572.12	7.27687
2574.86	7.6501
2577.6	8.04798
2580.33	8.94425
2583.07	9.97977
2585.8	12.7367
2588.54	14.1426
2591.27	14.1057
2594	15.2996
2596.73	16.6784
2599.46	18.5136
2602.19	17.6024
2604.92	16.8731
2607.64	16.0181
2610.37	16.1242
2613.09	16.0158
2615.82	15.2513
2618.54	14.4956
2621.26	14.2196
2623.98	12.85
2626.7	12.242
2629.42	12.2595
2632.14	13.7184
2634.86	13.804
2637.57	14.1216
2640.29	15.1124
2643	14.6607
2645.71	14.3091
2648.43	14.5727
2651.14	14.7148
2653.85	16.0548
2656.56	14.9357
2659.26	15.4467
2661.97	16.7802
2664.68	15.838
2667.38	15.1666
2670.09	13.5919
2672.79	13.5773
2675.49	13.973
2678.19	13.9463
2680.89	15.0447
2683.59	15.9554
2686.29	16.8722
2688.99	18.9713
2691.69	21.7574
2694.38	24.7945
2697.08	28.5134
2699.77	33.1789
2702.46	36.6757
2705.15	40.5235
2707.85	44.0351
2710.54	48.9763
2713.22	52.2197
2715.91	54.8403
2718.6	57.3575
2721.29	57.6231
2723.97	57.4146
2726.66	55.345
2729.34	53.3374
2732.02	51.7268
2734.7	47.6841
2737.38	43.9657
2740.06	40.9798
2742.74	35.8182
2745.42	32.9209
2748.09	28.9765
2750.77	23.7857
2753.45	19.2232
2756.12	15.6402
2758.79	13.1097
2761.46	11.2961
2764.14	9.05695
2766.8	7.23433
2769.47	5.62991
2772.14	6.33653
2774.81	6.61353
2777.48	5.72396
2780.14	5.41847
2782.8	6.3835
2785.47	7.04794
2788.13	6.10428
2790.79	6.64066
2793.45	8.38682
2796.11	8.45496
2798.77	8.46009
2801.43	6.37751
2804.09	4.90884
2806.74	2.01676
2809.4	-1.73043
2812.05	-3.44169
2814.71	0.856146
2817.36	16.2786
2820.01	40.8462
2822.66	73.4587
2825.31	113.096
2827.96	156.896
2830.6	205.553
2833.25	256.871
2835.9	307.828
2838.54	358.433
2841.18	407.414
2843.83	452.858
2846.47	491.529
2849.11	526.62
2851.75	570.959
2854.39	623.52
2857.03	675.554
2859.66	721.06
2862.3	758.831
2864.94	786.744
2867.57	805.964
2870.2	818.431
2872.84	826.277
2875.47	834.794
2878.1	841.939
2880.73	851.684
2883.36	858.385
2885.99	863.507
2888.61	862.469
2891.24	857.32
2893.86	847.66
2896.49	833.862
2899.11	817.253
2901.73	798.392
2904.36	778.147
2906.98	760.34
2909.6	744.73
2912.21	740.57
2914.83	749.339
2917.45	765.283
2920.07	775.122
2922.68	776.661
2925.29	774.497
2927.91	767.147
2930.52	756.479
2933.13	742.626
2935.74	726.59
2938.35	706.271
2940.96	683.357
2943.57	656.239
2946.18	625.843
2948.78	593.175
2951.39	557.967
2953.99	522.791
2956.59	486.097
2959.2	450.716
2961.8	417.4
2964.4	386.924
2967	358.492
2969.6	331.644
2972.19	310.438
2974.79	288.78
2977.39	267.397
2979.98	245.903
2982.58	223.368
2985.17	199.581
2987.76	178.723
2990.35	158.102
2992.94	139.834
2995.53	121.851
2998.12	105.851
3000.71	90.1209
3003.3	77.8366
3005.88	66.0863
3008.47	56.3262
3011.05	46.3292
3013.64	37.4528
3016.22	30.1846
3018.8	23.8797
3021.38	19.5534
3023.96	14.919
3026.54	11.8792
3029.12	9.28623
3031.69	6.83677
3034.27	6.73928
3036.84	6.69565
3039.42	6.90942
3041.99	5.67276
3044.57	6.83399
3047.14	6.84497
3049.71	8.38686
3052.28	9.62352
3054.85	10.2775
3057.41	11.9531
3059.98	12.0366
3062.55	11.6474
3065.11	12.5701
3067.68	11.5095
3070.24	11.163
3072.8	9.49146
3075.36	7.94924
3077.93	7.41629
3080.49	6.77018
3083.04	6.28229
3085.6	5.70165
3088.16	5.36238
3090.72	5.10054
3093.27	4.98023
3095.83	6.47557
3098.38	9.1367
3100.93	9.93286
3103.49	11.1916
3106.04	12.6579
3108.59	15.1802
3111.14	17.771
3113.69	20.2838
3116.23	22.2672
3118.78	24.0183
3121.33	26.6798
3123.87	28.3817
3126.41	31.7055
3128.96	33.9026
3131.5	36.2617
3134.04	38.7292
3136.58	43.1574
3139.12	46.3136
3141.66	50.0153
3144.2	54.123
3146.74	58.7864
3149.27	63.8843