File: data/Raman/poly_smoothed/Mb_20_23_30_1x_45s_532 nm_x100_100%_600 gr_mm_01.txt
#Acq. time (s)=	45
#Accumulations=	2
#Range (cm-¹)=	200...3150
#Windows=	2
#Auto scanning=	Off
#Autofocus=	Off
#Macrospot=	Off
#AutoExposure=	Off
#Spike filter=	Multiple accum.
#Delay time (s)=	0
#Binning=	1
#Readout mode=	Signal
#DeNoise=	Off
#ICS correction=	On
#Dark correction=	Off
#Inst. Process=	Off
#Detector Gain=	Best Dynamic Range
#Detector ADC=	20 kHz
#Detector temperature (°C)=	-69.85
#Instrument=	LabRAM HR Evol
#Detector=	Synapse
#Objective=	x100
#Grating=	600 gr/mm
#ND Filter=	100%
#Laser (nm)=	532
#Hole=	100.021
#Range=	Auto
#Laser Pol.=	No
#Raman. Pol.=	No
#Laser Pol. (°)=	-0.0007625
#Raman Pol. (°)=	89.9995
#Collection=	Microscope
#StageXY=	Marzhauser
#StageZ=	Marzhauser
#X (µm)=	-6915.9
#Y (µm)=	2007
#Z (µm)=	-75.4
#Full time(mm:ss)=	3:19
#Project=
#Sample=
#Site=
#Title=	Mb_20_23_30_2x_45s_532 nm_x100_100%_600 gr_mm
#Remark=
#Date=	13.07.2022 15:30
#Acquired=	13.07.2022 15:30:31
#Edit:Spike=	13.07.2022 15:32:26
#Base:Fit=	10.08.2022 10:29:37
#Base:Sub=	10.08.2022 10:33:46
#Filter:Polynom=	16.08.2022 10:13:29
#AxisType[0]=Intens
#AxisUnit[0]=Cnt
#AxisType[1]=Spectr
#AxisUnit[1]=1/cm
200.563	36.2734
204.194	34.5636
207.821	27.039
211.449	21.8129
215.074	19.863
218.699	16.6944
222.321	15.3334
225.941	14.8712
229.562	13.9009
233.18	11.9181
236.796	10.9697
240.411	8.70776
244.026	8.91921
247.638	8.58568
251.248	8.93192
254.857	9.86923
258.465	7.47905
262.071	8.13879
265.678	9.75433
269.282	9.30321
272.884	8.81843
276.484	8.20375
280.084	8.83888
283.682	5.83578
287.276	4.32938
290.871	5.52316
294.465	6.05192
298.057	7.97137
301.648	9.9504
305.237	11.6757
308.823	12.4114
312.41	12.4699
315.995	14.0011
319.579	16.2997
323.16	15.8381
326.741	17.1606
330.321	17.4145
333.897	19.5899
337.474	19.7681
341.048	18.431
344.622	17.287
348.192	17.2596
351.764	16.0288
355.332	13.7205
358.901	11.2832
362.466	10.2008
366.03	8.4968
369.594	7.24024
373.155	6.04986
376.715	5.57314
380.273	6.82178
383.832	6.78295
387.388	9.41215
390.942	11.0053
394.495	9.8783
398.047	12.5901
401.597	11.9414
405.145	13.8934
408.693	16.962
412.239	17.1695
415.783	18.1262
419.327	19.3294
422.869	20.3614
426.409	19.7203
429.948	17.0195
433.486	16.2777
437.022	13.1533
440.558	10.181
444.089	7.92728
447.622	7.8744
451.153	8.51261
454.682	8.10996
458.208	8.64516
461.735	9.08432
465.259	9.9726
468.783	12.7786
472.306	13.758
475.825	16.5223
479.346	18.6782
482.862	18.5165
486.38	21.1779
489.894	22.7421
493.407	25.7256
496.92	28.887
500.43	31.2705
503.939	34.0466
507.448	35.3221
510.954	36.9376
514.459	36.938
517.962	38.7502
521.466	36.4126
524.966	36.6304
528.466	35.7137
531.964	36.6641
535.46	36.0505
538.955	33.899
542.449	32.3518
545.942	31.1613
549.433	27.8681
552.923	27.5282
556.412	25.0518
559.899	23.4969
563.385	21.899
566.867	17.0933
570.35	14.8388
573.832	12.9456
577.313	9.34636
580.79	8.93009
584.268	8.76495
587.745	7.90117
591.218	6.64779
594.692	8.59683
598.164	8.54306
601.634	8.47227
605.104	7.83789
608.57	8.86236
612.037	8.51011
615.501	8.92748
618.966	9.58514
622.427	8.48585
625.887	10.6472
629.348	11.9256
632.806	11.8052
636.262	14.1005
639.716	14.3118
643.172	14.1867
646.624	13.2507
650.075	13.9288
653.524	13.5401
656.972	14.1874
660.419	12.7024
663.865	12.0539
667.309	13.2562
670.752	12.712
674.194	12.3447
677.634	13.8895
681.073	15.5186
684.511	16.4324
687.947	18.6291
691.382	19.9183
694.816	21.3216
698.247	23.085
701.678	25.0521
705.108	27.8302
708.534	30.024
711.962	33.624
715.388	34.672
718.81	35.4286
722.234	35.0452
725.654	34.8275
729.075	37.036
732.492	39.2904
735.91	38.9166
739.325	39.439
742.741	39.2808
746.153	39.3173
749.564	41.2961
752.976	44.098
756.385	47.2136
759.792	50.6682
763.2	53.9074
766.604	55.481
770.008	58.9289
773.41	62.0158
776.811	66.2
780.21	69.9979
783.608	72.1297
787.005	75.1909
790.401	78.1096
793.795	80.4256
797.188	81.9442
800.58	81.9162
803.971	82.5275
807.36	83.2408
810.748	84.6891
814.135	85.5157
817.518	84.6805
820.902	83.8853
824.285	86.9327
827.665	86.9053
831.045	87.1839
834.424	88.5231
837.8	88.8525
841.177	88.5449
844.55	84.5774
847.924	82.3094
851.295	80.8944
854.666	79.7264
858.034	79.0954
861.403	76.3596
864.769	73.1162
868.133	70.1045
871.498	67.6776
874.86	64.9596
878.221	60.9256
881.58	60.2205
884.938	58.9661
888.297	57.3923
891.653	55.936
895.007	55.4199
898.36	56.3119
901.712	56.3368
905.063	57.3329
908.412	56.8049
911.76	55.3704
915.107	56.6725
918.452	55.6938
921.797	55.2769
925.138	53.0086
928.48	49.6566
931.82	48.7348
935.16	46.1502
938.496	44.1604
941.833	39.2273
945.168	33.8378
948.5	30.7686
951.834	29.3596
955.163	28.3297
958.494	25.9819
961.821	26.4999
965.15	27.5161
968.474	28.4152
971.8	28.4874
975.123	29.8162
978.446	32.7336
981.766	35.2492
985.084	35.208
988.402	36.6505
991.72	36.3897
995.035	38.4969
998.349	37.9089
1001.66	38.5438
1004.97	37.1481
1008.28	36.2385
1011.59	33.9967
1014.9	34.7871
1018.21	36.1758
1021.51	35.4399
1024.81	37.4761
1028.12	39.8906
1031.42	42.9285
1034.72	42.8654
1038.02	43.197
1041.31	43.3181
1044.61	46.5579
1047.91	48.9562
1051.2	50.1527
1054.49	51.2535
1057.78	52.1224
1061.07	52.4044
1064.36	52.1085
1067.65	50.2091
1070.93	49.2362
1074.22	48.5533
1077.5	47.313
1080.78	42.8722
1084.06	39.9902
1087.34	36.5793
1090.62	35.3919
1093.9	34.2495
1097.17	34.4483
1100.45	35.7046
1103.72	35.6399
1106.99	34.7675
1110.27	32.6773
1113.53	29.9291
1116.8	27.4159
1120.07	26.6544
1123.33	26.7339
1126.6	24.2055
1129.86	23.3561
1133.12	22.1113
1136.38	19.443
1139.64	17.3028
1142.9	14.9983
1146.16	14.0216
1149.41	13.0434
1152.67	12.0934
1155.92	10.873
1159.17	7.7583
1162.42	5.02242
1165.67	3.81898
1168.92	2.95681
1172.16	4.05226
1175.41	4.33357
1178.65	4.98568
1181.9	4.59334
1185.14	4.01529
1188.38	3.54243
1191.62	4.65079
1194.86	4.70354
1198.09	5.42388
1201.33	6.20891
1204.56	8.05362
1207.8	9.51168
1211.03	11.6646
1214.26	15.4424
1217.49	21.0802
1220.71	26.8685
1223.94	31.3975
1227.16	38.386
1230.39	43.7584
1233.61	47.4601
1236.83	51.3704
1240.05	57.9319
1243.27	61.314
1246.49	63.9252
1249.71	67.833
1252.92	69.9617
1256.14	71.8134
1259.35	73.876
1262.56	75.4711
1265.77	79.4631
1268.98	84.0536
1272.19	87.1751
1275.4	91.532
1278.6	94.5392
1281.81	99.5157
1285.01	103.903
1288.21	108.86
1291.41	113.234
1294.61	117.481
1297.81	118.684
1301.01	118.995
1304.2	123.149
1307.4	124.238
1310.59	123.881
1313.78	124.807
1316.97	125.122
1320.16	124.348
1323.35	122.632
1326.54	119.244
1329.72	115.272
1332.91	112.017
1336.09	109.311
1339.27	106.416
1342.45	106.416
1345.64	104.182
1348.81	101.329
1351.99	99.0669
1355.17	94.73
1358.34	92.2391
1361.51	89.0552
1364.69	86.5211
1367.86	83.2008
1371.03	79.0965
1374.2	75.9427
1377.37	74.7554
1380.53	74.4038
1383.7	74.7181
1386.86	72.6238
1390.02	72.7754
1393.19	72.0805
1396.35	71.0062
1399.51	71.979
1402.66	72.8701
1405.82	74.7384
1408.97	80.7189
1412.13	88.0294
1415.28	96.2037
1418.43	106.798
1421.59	116.398
1424.73	128.49
1427.88	140.703
1431.03	152.143
1434.18	163.131
1437.32	174.528
1440.46	182.999
1443.61	188.515
1446.75	190.219
1449.89	191.405
1453.03	192.991
1456.16	189.146
1459.3	183.33
1462.44	175.54
1465.57	166.045
1468.7	155.137
1471.83	142.306
1474.96	129.624
1478.09	116.9
1481.22	106.205
1484.35	94.1003
1487.47	84.0858
1490.6	73.7561
1493.72	64.8599
1496.84	57.1531
1499.96	52.077
1503.08	47.5185
1506.2	41.4988
1509.32	36.9059
1512.44	31.5396
1515.55	27.8009
1518.66	23.2865
1521.78	21.2502
1524.89	19.511
1528	20.3686
1531.11	19.9355
1534.21	20.4563
1537.32	22.7351
1540.43	25.452
1543.53	27.9547
1546.63	29.6776
1549.74	32.2073
1552.84	34.375
1555.94	37.4939
1559.03	39.5817
1562.13	42.0842
1565.23	44.7218
1568.32	49.7801
1571.42	52.4221
1574.51	55.1513
1577.6	58.4094
1580.69	60.1448
1583.78	63.1843
1586.87	66.5059
1589.95	69.2023
1593.04	71.9424
1596.12	73.7607
1599.21	73.4694
1602.29	74.1874
1605.37	73.7607
1608.45	73.8138
1611.53	74.449
1614.6	76.0562
1617.68	76.3319
1620.75	77.5347
1623.83	77.6477
1626.9	78.8442
1629.97	81.8703
1633.04	85.5206
1636.11	89.8169
1639.18	93.0184
1642.25	98.7605
1645.31	101.595
1648.38	104.557
1651.44	106.101
1654.5	106.999
1657.56	107.863
1660.62	108.262
1663.68	106.832
1666.74	104.299
1669.8	100.102
1672.85	94.2643
1675.91	88.8835
1678.96	82.2232
1682.01	75.5237
1685.06	68.4948
1688.11	62.3329
1691.16	54.9457
1694.21	48.8603
1697.25	43.4498
1700.3	39.0264
1703.34	36.2938
1706.39	34.408
1709.43	31.6538
1712.47	30.6039
1715.51	29.6412
1718.54	27.6705
1721.58	24.4755
1724.62	23.4862
1727.65	23.0327
1730.68	21.7658
1733.72	21.3128
1736.75	20.1131
1739.78	19.0579
1742.81	17.4465
1745.84	15.6475
1748.86	13.913
1751.89	12.0458
1754.91	10.9263
1757.93	9.03801
1760.96	7.58906
1763.98	5.45145
1767	3.56493
1770.02	1.26376
1773.03	1.20195
1776.05	1.57281
1779.07	1.72818
1782.08	0.168563
1785.09	-0.643376
1788.11	0.2157
1791.12	-0.483529
1794.13	-0.751748
1797.13	0.119364
1800.14	-0.240086
1803.15	0.210459
1806.15	0.190826
1809.16	0.272614
1812.16	0.54679
1815.16	0.667454
1818.16	0.922165
1821.16	1.3675
1824.16	1.37451
1827.16	1.67814
1830.16	1.89554
1833.15	1.52636
1836.14	0.702791
1839.14	0.569624
1842.13	-0.0296279
1845.12	-0.34011
1848.11	-0.0118263
1851.1	-0.584342
1854.08	-0.59758
1857.07	1.09422
1860.05	1.35585
1863.04	1.88248
1866.02	1.86127
1869	1.77995
1871.98	2.7051
1874.96	3.64785
1877.94	4.31343
1880.92	4.46749
1882.51	4.34507
1885.5	5.28893
1888.48	5.79603
1891.47	5.44948
1894.46	5.52128
1897.44	5.74442
1900.42	5.71061
1903.41	4.8773
1906.39	4.20012
1909.37	4.83452
1912.35	3.64288
1915.32	4.80416
1918.3	4.38439
1921.27	4.62939
1924.25	5.68895
1927.22	5.93609
1930.19	6.34865
1933.17	5.65923
1936.14	5.03126
1939.11	5.01848
1942.07	5.41109
1945.04	6.64459
1948.01	6.14677
1950.97	6.16052
1953.93	5.73467
1956.9	5.83928
1959.86	5.67728
1962.82	4.16584
1965.78	4.17935
1968.74	4.74
1971.69	5.10721
1974.65	3.68497
1977.6	2.54574
1980.56	2.85528
1983.51	2.5032
1986.46	3.13858
1989.41	2.2096
1992.36	1.72032
1995.31	1.52314
1998.26	2.30609
2001.2	1.86477
2004.15	2.69013
2007.09	2.5106
2010.04	2.59654
2012.98	3.98993
2015.92	5.06481
2018.86	5.33741
2021.8	5.85103
2024.73	7.17791
2027.67	8.67597
2030.61	8.8936
2033.54	9.33624
2036.47	10.7187
2039.4	12.208
2042.33	11.5359
2045.27	10.7873
2048.19	9.22914
2051.12	10.2176
2054.05	10.0705
2056.97	10.6278
2059.9	9.13935
2062.82	8.14661
2065.74	8.30381
2068.67	8.217
2071.59	8.37583
2074.51	8.80997
2077.42	9.44871
2080.34	9.80084
2083.26	10.3128
2086.17	11.4255
2089.09	12.6787
2092	14.0629
2094.91	15.7495
2097.82	17.2439
2100.73	18.4302
2103.64	19.7742
2106.55	21.4797
2109.45	23.3734
2112.36	22.965
2115.26	23.3513
2118.17	25.0379
2121.07	26.1417
2123.97	27.0355
2126.87	28.8612
2129.77	30.9312
2132.67	32.3503
2135.56	34.246
2138.46	38.0082
2141.35	40.5872
2144.25	45.1647
2147.14	49.2044
2150.03	53.4698
2152.92	57.2806
2155.81	61.4758
2158.7	64.9191
2161.59	67.9287
2164.47	71.3642
2167.36	73.3698
2170.24	75.053
2173.13	76.7761
2176.01	76.6248
2178.89	76.4857
2181.77	74.2268
2184.65	71.6011
2187.53	69.9445
2190.4	67.2064
2193.28	64.192
2196.16	61.4206
2199.03	58.251
2201.9	55.2841
2204.77	52.7078
2207.64	49.3786
2210.51	47.0956
2213.38	43.8774
2216.25	42.2018
2219.12	38.8133
2221.98	34.4746
2224.85	31.9901
2227.71	30.0561
2230.57	26.4821
2233.43	24.1894
2236.29	22.6876
2239.15	21.1437
2242.01	19.6194
2244.87	18.8758
2247.72	16.6847
2250.58	14.4246
2253.43	12.5267
2256.29	11.2858
2259.14	11.4167
2261.99	11.1411
2264.84	12.4518
2267.69	13.5463
2270.53	13.065
2273.38	13.2396
2276.23	12.4829
2279.07	11.8673
2281.91	10.9424
2284.76	9.79436
2287.6	8.2355
2290.44	6.10285
2293.28	4.93106
2296.12	4.39993
2298.96	5.54495
2301.79	6.14199
2304.63	7.85786
2307.46	7.87249
2310.3	7.45007
2313.13	8.1146
2315.96	6.9782
2318.79	7.3069
2321.62	8.51794
2324.45	9.96012
2327.27	10.256
2330.1	12.0155
2332.92	13.2812
2335.75	13.1125
2338.57	11.8189
2341.39	10.7573
2344.21	9.17742
2347.04	8.39917
2349.85	8.18184
2352.67	7.05355
2355.49	4.83482
2358.3	3.37495
2361.12	1.46722
2363.93	2.35398
2366.75	3.07924
2369.56	3.82201
2372.37	3.59423
2375.18	4.06383
2377.99	3.59574
2380.8	4.31869
2383.6	4.30332
2386.41	5.1219
2389.21	6.53087
2392.02	7.72391
2394.82	7.94801
2397.62	8.55189
2400.42	9.30804
2403.22	9.4288
2406.02	9.71951
2408.82	10.0113
2411.62	9.55723
2414.41	9.53397
2417.21	9.34453
2420	8.07921
2422.79	6.12813
2425.59	5.86502
2428.38	4.97992
2431.17	5.00769
2433.95	5.1912
2436.74	5.04565
2439.53	4.07766
2442.31	4.15644
2445.1	3.27608
2447.88	2.96604
2450.67	3.62223
2453.45	3.31106
2456.23	3.17266
2459.01	3.16682
2461.79	3.44135
2464.57	3.78919
2467.34	3.52778
2470.12	3.96636
2472.89	3.69995
2475.67	3.75827
2478.44	2.99684
2481.21	1.70125
2483.98	1.59801
2486.75	1.97331
2489.52	1.69072
2492.29	1.87647
2495.05	1.80433
2497.82	2.06435
2500.58	3.34506
2503.35	3.15067
2506.11	2.94102
2508.87	3.54568
2511.63	3.74159
2514.39	4.43137
2517.15	4.75393
2519.91	5.32501
2522.67	4.34163
2525.42	5.04195
2528.18	5.80291
2530.93	4.94698
2533.69	4.90767
2536.44	5.08201
2539.19	4.86786
2541.94	5.44136
2544.69	4.59844
2547.44	3.96831
2550.18	2.7677
2552.93	3.03777
2555.67	1.9332
2558.42	1.44531
2561.16	1.50887
2563.9	1.14602
2566.64	1.301
2569.38	0.429505
2572.12	1.0142
2574.86	2.21706
2577.6	2.71748
2580.33	3.6606
2583.07	3.63556
2585.8	4.22812
2588.54	5.0463
2591.27	4.97436
2594	6.269
2596.73	6.06684
2599.46	6.95569
2602.19	8.09182
2604.92	7.96744
2607.64	8.06931
2610.37	7.977
2613.09	7.29585
2615.82	7.40448
2618.54	7.46352
2621.26	6.45924
2623.98	5.79321
2626.7	5.47683
2629.42	5.4702
2632.14	5.34754
2634.86	5.37012
2637.57	7.49949
2640.29	7.60177
2643	7.5866
2645.71	8.69145
2648.43	8.50777
2651.14	9.41795
2653.85	9.75029
2656.56	9.60015
2659.26	9.38739
2661.97	9.56638
2664.68	10.4237
2667.38	10.3404
2670.09	9.75058
2672.79	9.23064
2675.49	9.53296
2678.19	10.4538
2680.89	10.7855
2683.59	10.4941
2686.29	9.392
2688.99	9.1102
2691.69	9.85909
2694.38	10.8953
2697.08	11.6402
2699.77	12.6429
2702.46	12.9754
2705.15	14.1668
2707.85	14.2599
2710.54	16.7472
2713.22	18.0918
2715.91	18.4969
2718.6	19.5028
2721.29	19.8904
2723.97	20.6953
2726.66	20.4901
2729.34	20.3939
2732.02	20.13
2734.7	19.9939
2737.38	18.0544
2740.06	17.6036
2742.74	16.8552
2745.42	15.4345
2748.09	13.9635
2750.77	12.7464
2753.45	10.9384
2756.12	9.90536
2758.79	8.5584
2761.46	6.84532
2764.14	5.30233
2766.8	4.935
2769.47	4.0104
2772.14	3.89578
2774.81	3.19999
2777.48	2.23594
2780.14	0.613099
2782.8	0.920072
2785.47	0.923279
2788.13	0.638614
2790.79	0.655283
2793.45	0.51394
2796.11	1.38359
2798.77	1.04176
2801.43	0.545968
2804.09	0.755535
2806.74	1.33553
2809.4	0.637346
2812.05	0.984318
2814.71	-0.06593
2817.36	2.93012
2820.01	8.26727
2822.66	15.6786
2825.31	25.8129
2827.96	37.5107
2830.6	51.3786
2833.25	66.0033
2835.9	81.0871
2838.54	97.759
2841.18	117.416
2843.83	136.496
2846.47	157.436
2849.11	178.954
2851.75	198.796
2854.39	219.167
2857.03	238.62
2859.66	257.554
2862.3	274.41
2864.94	288.435
2867.57	301.383
2870.2	310.886
2872.84	320.588
2875.47	328.821
2878.1	335.419
2880.73	344.362
2883.36	352.869
2885.99	362.154
2888.61	371.127
2891.24	380.016
2893.86	389.741
2896.49	400.163
2899.11	410.596
2901.73	423.387
2904.36	436.723
2906.98	452.56
2909.6	468.813
2912.21	484.958
2914.83	501.184
2917.45	516.684
2920.07	529.279
2922.68	538.217
2925.29	543.797
2927.91	546.775
2930.52	545.925
2933.13	542.709
2935.74	535.541
2938.35	525.652
2940.96	512.468
2943.57	494.497
2946.18	475.609
2948.78	455.283
2951.39	434.871
2953.99	412.587
2956.59	389.671
2959.2	367.319
2961.8	344.131
2964.4	322.495
2967	302.135
2969.6	282.246
2972.19	265.931
2974.79	248.308
2977.39	232.093
2979.98	215.128
2982.58	197.155
2985.17	178.553
2987.76	160.387
2990.35	144.649
2992.94	128.705
2995.53	114.036
2998.12	101.132
3000.71	87.1427
3003.3	74.3166
3005.88	62.2195
3008.47	51.1509
3011.05	43.0735
3013.64	35.4329
3016.22	27.3462
3018.8	20.0246
3021.38	14.0817
3023.96	9.70924
3026.54	7.12169
3029.12	4.93561
3031.69	3.41252
3034.27	2.63331
3036.84	3.28097
3039.42	2.65607
3041.99	4.8376
3044.57	4.85677
3047.14	6.59531
3049.71	7.96537
3052.28	9.43848
3054.85	10.8208
3057.41	11.6965
3059.98	12.3221
3062.55	11.9739
3065.11	12.0383
3067.68	11.3333
3070.24	10.9565
3072.8	9.904
3075.36	8.67331
3077.93	7.20438
3080.49	6.16745
3083.04	5.57507
3085.6	5.69849
3088.16	5.1288
3090.72	4.10163
3093.27	5.35199
3095.83	6.0688
3098.38	7.78872
3100.93	10.078
3103.49	12.0753
3106.04	14.004
3108.59	15.4966
3111.14	17.6142
3113.69	19.6318
3116.23	20.9427
3118.78	22.388
3121.33	24.9817
3123.87	26.709
3126.41	29.4732
3128.96	32.5243
3131.5	35.697
3134.04	38.5094
3136.58	41.679
3139.12	45.6331
3141.66	49.8853
3144.2	54.5989
3146.74	60.3823
3149.27	69.3948