File: data/Raman/poly_smoothed/Mb_20_23_46_1x_45s_532 nm_x100_100%_600 gr_mm_01.txt
#Acq. time (s)=	45
#Accumulations=	2
#Range (cm-¹)=	200...3150
#Windows=	2
#Auto scanning=	Off
#Autofocus=	Off
#Macrospot=	Off
#AutoExposure=	Off
#Spike filter=	Multiple accum.
#Delay time (s)=	0
#Binning=	1
#Readout mode=	Signal
#DeNoise=	Off
#ICS correction=	On
#Dark correction=	Off
#Inst. Process=	Off
#Detector Gain=	Best Dynamic Range
#Detector ADC=	20 kHz
#Detector temperature (°C)=	-70.08
#Instrument=	LabRAM HR Evol
#Detector=	Synapse
#Objective=	x100
#Grating=	600 gr/mm
#ND Filter=	100%
#Laser (nm)=	532
#Hole=	100.021
#Range=	Auto
#Laser Pol.=	No
#Raman. Pol.=	No
#Laser Pol. (°)=	-0.0007625
#Raman Pol. (°)=	89.9995
#Collection=	Microscope
#StageXY=	Marzhauser
#StageZ=	Marzhauser
#X (µm)=	491.8
#Y (µm)=	2978.9
#Z (µm)=	-8.9
#Full time(mm:ss)=	3:14
#Project=
#Sample=
#Site=
#Title=	Mb_20_23_46_2x_45s_532 nm_x100_100%_600 gr_mm
#Remark=
#Date=	14.07.2022 09:50
#Acquired=	14.07.2022 09:50:19
#Base:Fit=	10.08.2022 10:29:37
#Base:Sub=	10.08.2022 10:35:48
#Filter:Polynom=	16.08.2022 10:13:29
#AxisType[0]=Intens
#AxisUnit[0]=Cnt
#AxisType[1]=Spectr
#AxisUnit[1]=1/cm
200.554	-0.570233
204.183	6.60779
207.813	9.24302
211.439	11.0864
215.065	12.8405
218.688	16.6521
222.312	17.1243
225.933	16.1391
229.552	14.1482
233.171	15.1301
236.787	15.427
240.402	15.7913
244.015	16.4312
247.627	15.9838
251.24	14.8206
254.849	14.4789
258.457	14.3158
262.063	12.9521
265.668	12.0365
269.271	13.5691
272.873	13.8789
276.474	11.5887
280.073	10.7082
283.671	8.63527
287.268	8.8537
290.863	8.68539
294.456	6.9848
298.049	5.69909
301.637	5.3276
305.227	6.7417
308.815	6.96485
312.402	7.85646
315.987	6.48792
319.569	8.34017
323.151	9.96207
326.733	10.5007
330.31	12.8295
333.889	16.0657
337.464	16.2962
341.039	19.642
344.611	22.252
348.184	24.9967
351.754	25.815
355.324	25.6485
358.89	25.4531
362.455	24.6394
366.021	27.2518
369.584	27.8609
373.145	26.9063
376.707	25.1744
380.265	24.2946
383.822	23.8219
387.378	25.6533
390.934	25.161
394.487	26.3901
398.038	25.0553
401.588	23.5759
405.137	20.178
408.685	19.2733
412.23	18.9821
415.775	21.0057
419.318	22.3143
422.86	21.2344
426.401	20.8351
429.94	22.3163
433.478	21.8403
437.012	20.1423
440.547	19.0343
444.081	20.3777
447.613	20.0668
451.142	22.0093
454.672	23.664
458.2	22.4428
461.725	22.9017
465.251	22.9173
468.775	25.8501
472.296	26.1992
475.817	27.806
479.335	29.8808
482.854	31.2208
486.37	32.6881
489.886	34.8347
493.398	37.3901
496.91	39.8053
500.422	42.4607
503.93	43.9024
507.438	44.592
510.946	44.8334
514.45	45.0596
517.954	45.5523
521.456	43.8994
524.956	42.1627
528.456	41.451
531.956	41.1939
535.452	38.4728
538.947	39.4321
542.441	35.4442
545.934	32.4783
549.425	29.5319
552.915	28.5253
556.403	26.4773
559.889	24.921
563.375	22.0073
566.859	19.7611
570.342	17.2362
573.824	14.649
577.303	13.0643
580.782	11.2043
584.26	12.0319
587.734	9.60982
591.21	7.89416
594.684	6.91311
598.154	7.39953
601.626	6.15428
605.094	6.48726
608.562	8.28158
612.027	6.89364
615.493	9.70055
618.956	9.08048
622.419	9.07416
625.879	10.473
629.338	9.47575
632.797	9.28387
636.254	9.66317
639.708	7.08383
643.162	7.07582
646.614	6.514
650.067	6.68786
653.516	5.45326
656.964	4.60047
660.411	4.75187
663.857	4.14551
667.301	4.88642
670.744	4.48032
674.186	2.99752
677.626	2.91166
681.065	2.90111
684.503	5.61303
687.939	6.72042
691.372	7.33186
694.806	7.71326
698.239	8.70416
701.67	9.1386
705.098	11.1093
708.526	12.2617
711.954	12.8593
715.378	13.5377
718.802	13.8868
722.226	14.4388
725.646	15.6144
729.067	18.5067
732.484	20.5598
735.902	21.3005
739.317	21.9922
742.731	24.7431
746.145	25.5521
749.556	29.8863
752.966	32.0576
756.377	34.0861
759.784	34.6631
763.19	37.3009
766.594	40.6628
770	42.9361
773.402	45.1435
776.803	45.5331
780.202	46.5904
783.6	48.3247
786.997	49.673
790.393	51.7548
793.787	52.0132
797.18	51.9149
800.572	52.2176
803.963	54.1151
807.35	55.9103
810.738	58.7506
814.125	59.925
817.51	60.0442
820.894	60.41
824.275	61.2156
827.657	62.3924
831.037	62.4889
834.414	63.7101
837.792	64.3764
841.167	66.1262
844.542	65.7411
847.914	65.1973
851.287	65.1869
854.656	63.0948
858.026	61.4299
861.393	58.6001
864.761	57.2218
868.125	54.4814
871.489	53.8689
874.85	53.6503
878.213	50.5166
881.572	48.7717
884.931	47.993
888.287	46.9218
891.643	46.4559
894.997	45.5039
898.352	44.3615
901.704	44.1719
905.055	42.696
908.404	39.9764
911.75	38.4107
915.097	37.895
918.443	37.6213
921.787	35.9239
925.13	35.1
928.472	33.2169
931.813	30.9475
935.15	29.1667
938.488	25.5159
941.825	23.5099
945.158	18.7544
948.493	14.4742
951.824	12.5896
955.156	10.5997
958.486	6.97202
961.814	5.22248
965.142	6.96312
968.467	8.50238
971.79	9.27343
975.115	12.6867
978.436	13.3992
981.756	15.3998
985.077	17.8114
988.394	17.7419
991.71	17.8387
995.025	19.397
998.341	21.113
1001.65	23.0249
1004.97	23.8606
1008.28	26.3332
1011.58	28.1208
1014.89	30.8596
1018.2	32.2913
1021.5	36.0679
1024.81	39.4268
1028.11	43.6681
1031.41	52.1345
1034.71	57.382
1038.01	61.3025
1041.31	68.6627
1044.6	75.1386
1047.9	80.0513
1051.19	84.6159
1054.48	90.0535
1057.77	92.7954
1061.06	93.557
1064.35	93.4438
1067.64	93.1977
1070.93	88.4266
1074.21	83.521
1077.49	78.7167
1080.78	71.2265
1084.06	61.0594
1087.34	55.1788
1090.61	52.6161
1093.89	50.5935
1097.17	49.3935
1100.44	48.9667
1103.71	50.0465
1106.99	50.0404
1110.26	50.5853
1113.52	49.3111
1116.79	47.6066
1120.06	49.2692
1123.32	47.3047
1126.59	45.6089
1129.85	44.5947
1133.11	42.7778
1136.37	40.7002
1139.63	36.3529
1142.89	33.5166
1146.15	28.4867
1149.4	22.2951
1152.66	18.0147
1155.91	11.4912
1159.16	5.32164
1162.41	0.23377
1165.66	-2.1188
1168.91	0.524323
1172.16	1.66672
1175.4	3.89923
1178.65	5.77557
1181.89	7.34517
1185.13	8.09696
1188.37	9.06254
1191.61	9.62967
1194.85	11.3813
1198.08	14.2945
1201.32	14.1639
1204.55	16.3002
1207.79	19.0487
1211.02	21.8789
1214.25	24.6633
1217.48	28.0328
1220.71	30.6932
1223.93	33.6987
1227.16	38.0659
1230.38	42.8728
1233.6	45.7703
1236.83	49.4166
1240.05	53.4727
1243.26	57.6004
1246.48	60.7065
1249.7	66.5257
1252.92	67.9928
1256.13	70.5565
1259.34	76.2506
1262.55	82.6048
1265.76	87.2073
1268.97	95.8417
1272.18	105.47
1275.39	115.046
1278.59	122.56
1281.8	131.101
1285	139.543
1288.2	146.802
1291.4	152.604
1294.6	159.518
1297.8	163.987
1301	167.401
1304.19	168.86
1307.39	167.581
1310.58	165.118
1313.77	162.297
1316.96	157.696
1320.15	150.299
1323.34	143.844
1326.53	134.81
1329.72	126.58
1332.9	117.953
1336.08	114.162
1339.27	108.51
1342.45	105.504
1345.63	101.078
1348.8	98.9702
1351.98	96.9123
1355.16	94.1719
1358.33	92.7003
1361.51	91.1131
1364.68	89.9523
1367.85	88.4566
1371.02	89.2167
1374.19	89.3251
1377.36	89.3135
1380.52	89.9466
1383.69	89.16
1386.85	91.3195
1390.02	93.2462
1393.18	93.5827
1396.34	93.5426
1399.5	94.8243
1402.65	101.414
1405.81	112.703
1408.97	127.533
1412.12	141.237
1415.27	156.999
1418.43	174.15
1421.58	193.094
1424.73	213.919
1427.87	234.701
1431.02	252.536
1434.17	270.209
1437.31	285.839
1440.46	296.964
1443.6	302.988
1446.74	306.169
1449.88	306.307
1453.02	299.929
1456.16	288.97
1459.29	272.625
1462.43	254.023
1465.56	232.228
1468.69	206.059
1471.83	178.82
1474.95	153.813
1478.08	133.701
1481.21	115.793
1484.34	98.3257
1487.47	83.4528
1490.59	70.2065
1493.71	58.8497
1496.84	51.5298
1499.96	47.1394
1503.07	43.025
1506.19	41.191
1509.31	39.1266
1512.43	37.8109
1515.54	37.0564
1518.65	35.1429
1521.77	34.5476
1524.88	34.6137
1527.99	35.0129
1531.1	35.36
1534.21	35.5403
1537.31	37.7722
1540.42	37.8823
1543.52	39.0245
1546.63	39.4317
1549.73	41.6003
1552.83	42.2762
1555.93	44.9203
1559.03	48.0378
1562.12	52.0531
1565.22	56.8633
1568.31	61.2327
1571.41	66.7173
1574.5	71.7306
1577.59	77.5541
1580.68	81.6831
1583.77	85.3579
1586.86	89.9761
1589.95	92.5846
1593.03	94.5453
1596.11	96.283
1599.2	97.5702
1602.28	98.4905
1605.36	98.988
1608.44	98.0527
1611.52	96.2176
1614.6	95.1114
1617.67	92.3895
1620.75	89.5164
1623.82	87.3681
1626.89	84.9463
1629.96	83.0976
1633.04	83.8026
1636.11	86.0451
1639.17	88.9915
1642.24	90.7354
1645.31	93.1856
1648.37	95.8845
1651.43	97.2686
1654.5	97.3293
1657.56	97.2852
1660.62	96.3921
1663.67	94.7192
1666.73	91.5862
1669.79	87.619
1672.84	83.3381
1675.9	78.606
1678.95	73.5014
1682	66.5747
1685.05	60.7701
1688.1	56.8581
1691.15	51.9126
1694.2	47.9017
1697.25	44.7584
1700.29	42.3475
1703.33	40.6048
1706.38	39.2446
1709.42	40.1268
1712.46	40.0665
1715.5	38.2469
1718.54	36.0146
1721.57	36.145
1724.61	35.6132
1727.64	34.2311
1730.68	32.9564
1733.71	32.1563
1736.74	30.4443
1739.77	27.861
1742.8	26.479
1745.83	24.8955
1748.85	24.0023
1751.88	21.5317
1754.91	19.2639
1757.93	17.8569
1760.95	16.1292
1763.97	13.7634
1766.99	13.5307
1770.01	11.6355
1773.03	9.60385
1776.04	8.31248
1779.06	6.82676
1782.07	6.78324
1785.09	5.28076
1788.1	2.73914
1791.11	1.80323
1794.12	0.731012
1797.13	1.34159
1800.13	1.06071
1803.14	0.699068
1806.15	1.53376
1809.15	2.67689
1812.15	2.61463
1815.16	2.86856
1818.15	3.09633
1821.16	3.03742
1824.15	3.27841
1827.15	3.65135
1830.15	3.52584
1833.14	3.7092
1836.14	3.41418
1839.13	3.29529
1842.12	2.71708
1845.11	2.97816
1848.1	3.12099
1851.09	2.46982
1854.08	3.22713
1857.06	3.48555
1860.05	3.86011
1863.03	3.59563
1866.01	3.75009
1869	3.99717
1871.98	4.70486
1874.96	6.31993
1877.93	5.1345
1880.91	5.24245
1882.47	4.2378
1885.46	4.28328
1888.44	3.19059
1891.43	2.33241
1894.42	4.1728
1897.4	4.26173
1900.39	5.1788
1903.37	4.23193
1906.35	4.71566
1909.33	4.94385
1912.31	5.01764
1915.29	4.57053
1918.26	5.78992
1921.24	5.25965
1924.21	5.09886
1927.19	5.30764
1930.16	5.3485
1933.13	5.98952
1936.1	4.85978
1939.07	5.22971
1942.04	4.74956
1945	4.63673
1947.97	3.73349
1950.93	2.83265
1953.9	3.71971
1956.86	3.51583
1959.82	3.70631
1962.78	3.99806
1965.74	5.54029
1968.7	5.91271
1971.65	5.4668
1974.61	4.77992
1977.57	5.17298
1980.52	5.00464
1983.47	4.19366
1986.42	3.88991
1989.37	3.39244
1992.32	3.4592
1995.27	2.85145
1998.22	2.49899
2001.17	3.20394
2004.11	3.0198
2007.05	2.58101
2010	1.02971
2012.94	1.55707
2015.88	2.2148
2018.82	1.32199
2021.76	3.16269
2024.7	5.67051
2027.63	5.92797
2030.57	7.8712
2033.5	8.9318
2036.44	10.5762
2039.37	10.0319
2042.3	10.3137
2045.23	10.8881
2048.16	11.5072
2051.08	12.2137
2054.01	12.0562
2056.94	12.283
2059.86	12.3874
2062.79	12.9656
2065.71	12.5072
2068.63	13.385
2071.55	12.7376
2074.47	10.788
2077.39	8.19509
2080.31	8.97813
2083.22	8.67591
2086.13	8.60273
2089.05	9.64591
2091.96	10.5544
2094.87	12.91
2097.78	13.6074
2100.69	14.5564
2103.6	16.2274
2106.51	17.6102
2109.42	17.0251
2112.32	18.2063
2115.23	18.9319
2118.13	20.5611
2121.03	21.6476
2123.93	22.8222
2126.83	25.7693
2129.73	27.3772
2132.63	30.7948
2135.53	32.3259
2138.42	34.4947
2141.32	36.9619
2144.21	36.4574
2147.1	37.6219
2150	40.7916
2152.89	43.573
2155.78	44.5315
2158.66	46.7261
2161.55	49.6404
2164.44	51.5149
2167.32	52.6894
2170.21	52.7429
2173.09	53.9637
2175.97	54.0948
2178.85	53.6813
2181.73	52.1815
2184.61	51.992
2187.49	50.0449
2190.37	49.6493
2193.24	48.4935
2196.12	47.0286
2198.99	45.7368
2201.87	43.4794
2204.74	43.0448
2207.61	41.232
2210.48	39.0278
2213.35	37.358
2216.21	34.2664
2219.08	31.4013
2221.95	30.5235
2224.81	28.6495
2227.67	26.5469
2230.54	25.6116
2233.4	24.1933
2236.26	22.2272
2239.11	20.4027
2241.97	20.3871
2244.83	19.021
2247.69	16.1346
2250.54	14.8729
2253.4	14.0753
2256.25	14.4228
2259.1	13.6862
2261.95	13.5491
2264.8	12.2455
2267.65	12.4788
2270.5	11.2614
2273.34	10.7155
2276.19	9.61601
2279.03	9.8992
2281.88	9.44221
2284.72	9.15666
2287.56	7.71963
2290.4	8.17614
2293.24	7.30906
2296.08	6.83767
2298.92	6.12062
2301.76	7.22765
2304.59	8.08239
2307.43	8.48009
2310.26	8.08421
2313.09	9.36327
2315.92	9.10122
2318.75	9.50289
2321.58	10.0541
2324.41	10.4858
2327.24	9.66354
2330.06	8.94911
2332.89	8.10607
2335.71	7.46857
2338.54	7.13114
2341.36	6.15924
2344.18	5.54146
2347	6.39577
2349.82	5.60524
2352.64	4.4688
2355.45	3.33621
2358.27	2.97343
2361.08	1.44731
2363.9	1.23856
2366.71	2.16611
2369.52	2.64074
2372.33	2.11298
2375.14	2.56278
2377.95	2.66165
2380.76	3.81862
2383.57	4.60559
2386.37	4.19001
2389.18	4.32381
2391.98	3.18887
2394.79	2.34211
2397.59	2.46235
2400.39	3.42543
2403.19	4.1374
2405.99	5.27646
2408.78	5.68044
2411.58	6.34338
2414.38	7.45408
2417.17	7.46043
2419.97	7.14764
2422.76	8.04711
2425.55	7.5204
2428.34	8.11234
2431.13	7.71604
2433.92	7.07537
2436.71	6.25588
2439.49	5.77417
2442.28	5.97683
2445.06	7.34353
2447.85	7.62284
2450.63	6.9785
2453.41	6.28728
2456.19	5.53417
2458.97	4.61674
2461.75	3.03243
2464.53	3.64827
2467.31	4.23588
2470.08	4.58795
2472.86	4.27805
2475.63	4.63124
2478.4	4.54109
2481.17	4.08475
2483.94	3.59591
2486.72	3.82104
2489.48	4.95887
2492.25	4.56311
2495.02	3.97139
2497.79	2.83352
2500.55	2.06675
2503.31	0.869694
2506.08	1.52612
2508.84	1.94384
2511.6	1.30902
2514.36	1.12812
2517.12	1.05013
2519.88	0.202785
2522.63	-0.3529
2525.39	-0.974803
2528.14	-0.917202
2530.9	-0.012298
2533.65	0.335781
2536.4	1.61974
2539.15	0.922207
2541.9	1.30293
2544.65	1.58667
2547.4	1.76143
2550.15	2.54942
2552.89	3.59831
2555.64	3.84459
2558.38	3.92997
2561.12	3.41431
2563.87	4.36225
2566.61	4.95837
2569.35	4.33775
2572.09	5.76995
2574.83	6.81084
2577.56	6.9964
2580.3	7.46978
2583.04	7.6597
2585.77	7.52583
2588.5	7.68469
2591.23	8.36351
2593.97	11.134
2596.7	11.6227
2599.43	11.006
2602.15	11.2384
2604.88	9.7497
2607.61	9.15901
2610.33	8.67761
2613.06	8.1706
2615.78	8.07726
2618.51	7.15686
2621.23	6.84561
2623.95	8.02827
2626.67	7.71572
2629.39	8.36029
2632.1	8.3275
2634.82	8.47377
2637.54	8.78983
2640.25	10.3056
2642.97	11.3497
2645.68	12.1914
2648.39	12.8829
2651.1	13.0922
2653.81	13.2423
2656.52	14.0876
2659.23	14.8849
2661.94	14.8047
2664.64	13.7147
2667.35	13.8142
2670.05	14.3541
2672.76	13.1762
2675.46	13.0704
2678.16	13.817
2680.86	14.106
2683.56	16.0126
2686.26	17.855
2688.96	18.6709
2691.65	19.7604
2694.35	22.1088
2697.04	24.9494
2699.74	28.2462
2702.43	31.5212
2705.12	35.4067
2707.81	38.4485
2710.5	41.467
2713.19	43.2383
2715.88	45.1992
2718.57	45.6143
2721.25	46.803
2723.94	47.4955
2726.62	45.5691
2729.3	44.9989
2731.99	43.4263
2734.67	39.5522
2737.35	35.1578
2740.03	30.554
2742.71	27.5011
2745.38	25.8055
2748.06	21.3124
2750.74	17.1763
2753.41	12.8629
2756.09	10.0193
2758.76	8.32105
2761.43	6.63713
2764.1	5.27546
2766.77	3.12198
2769.44	1.54848
2772.11	1.74324
2774.77	0.916287
2777.44	0.366947
2780.11	1.09587
2782.77	1.84423
2785.43	2.65854
2788.1	3.37442
2790.76	3.33971
2793.42	4.10604
2796.08	3.90012
2798.74	3.9659
2801.4	3.68214
2804.05	3.29494
2806.71	1.70566
2809.36	-0.251088
2812.02	-2.10344
2814.67	0.276496
2817.32	9.26591
2819.97	26.9867
2822.62	52.714
2825.27	81.3539
2827.92	114.663
2830.57	152.325
2833.22	191.369
2835.86	231.784
2838.51	272.227
2841.15	310.39
2843.79	346.987
2846.43	383.379
2849.08	421.463
2851.72	460.476
2854.36	498.586
2856.99	533.167
2859.63	561.844
2862.27	587.442
2864.9	606.134
2867.54	617.679
2870.17	627.726
2872.8	631.398
2875.43	635.072
2878.07	640.961
2880.7	648.085
2883.32	657.975
2885.95	667.249
2888.58	672.741
2891.21	676.041
2893.83	679.038
2896.46	679.897
2899.08	679.413
2901.7	677.258
2904.32	677.165
2906.94	677.223
2909.56	682.127
2912.18	690.345
2914.8	701.733
2917.42	709.749
2920.03	714.901
2922.65	714.515
2925.26	710.378
2927.88	703.031
2930.49	692.693
2933.1	678.596
2935.71	662.448
2938.32	642.425
2940.93	619.444
2943.54	593.599
2946.14	565.027
2948.75	537.019
2951.35	506.979
2953.96	474.079
2956.56	443.987
2959.16	415.409
2961.77	386.972
2964.37	359.975
2966.96	334.978
2969.56	313.803
2972.16	291.99
2974.76	271.508
2977.35	252.35
2979.95	231.869
2982.54	211.27
2985.14	190.523
2987.73	170.066
2990.32	150.146
2992.91	131.679
2995.5	114.567
2998.09	98.5413
3000.68	84.0016
3003.26	70.4389
3005.85	58.095
3008.43	47.514
3011.02	37.6911
3013.6	29.4097
3016.19	23.1947
3018.77	17.1795
3021.35	11.8524
3023.93	7.5749
3026.5	5.26495
3029.08	1.23718
3031.66	-0.161785
3034.24	-1.55202
3036.81	-1.83755
3039.39	-1.3989
3041.96	-0.955296
3044.53	-0.401647
3047.1	1.17645
3049.67	1.87001
3052.24	3.55307
3054.81	4.55123
3057.38	4.49096
3059.95	5.01374
3062.52	5.64898
3065.08	5.49025
3067.65	4.69063
3070.21	4.69788
3072.77	4.41425
3075.33	4.72446
3077.89	4.47977
3080.45	4.03497
3083.01	3.20978
3085.57	2.06024
3088.13	3.22914
3090.68	3.36199
3093.24	3.44958
3095.79	4.41622
3098.35	4.8021
3100.9	6.97346
3103.45	9.62914
3106	12.7117
3108.55	14.0469
3111.1	16.4572
3113.65	18.9677
3116.2	21.1814
3118.75	22.3689
3121.29	25.2734
3123.84	28.68
3126.38	30.2673
3128.92	33.339
3131.47	36.4305
3134.01	39.7201
3136.55	43.1979
3139.09	45.7713
3141.63	48.2273
3144.17	52.0083
3146.7	56.8642
3149.24	62.0304