File: data/Raman/poly_smoothed/Mb_20_23_04_1x_45s_532 nm_x50_100%_600 gr_mm_01.txt
#Acq. time (s)=	45
#Accumulations=	2
#Range (cm-¹)=	200...3150
#Windows=	2
#Auto scanning=	Off
#Autofocus=	Off
#Macrospot=	Off
#AutoExposure=	Off
#Spike filter=	Multiple accum.
#Delay time (s)=	0
#Binning=	1
#Readout mode=	Signal
#DeNoise=	Off
#ICS correction=	On
#Dark correction=	Off
#Inst. Process=	Off
#Detector Gain=	Best Dynamic Range
#Detector ADC=	20 kHz
#Detector temperature (°C)=	-69.85
#Instrument=	LabRAM HR Evol
#Detector=	Synapse
#Objective=	x50
#Grating=	600 gr/mm
#ND Filter=	100%
#Laser (nm)=	532
#Hole=	100.021
#Range=	Auto
#Laser Pol.=	No
#Raman. Pol.=	No
#Laser Pol. (°)=	-0.0007625
#Raman Pol. (°)=	89.9995
#Collection=	Microscope
#StageXY=	Marzhauser
#StageZ=	Marzhauser
#X (µm)=	-6988
#Y (µm)=	2171.5
#Z (µm)=	-74.35
#Full time(mm:ss)=	3:18
#Project=
#Sample=
#Site=
#Title=	Mb_20_23_04_2x_45s_532 nm_x50_100%_600 gr_mm
#Remark=
#Date=	13.07.2022 13:12
#Acquired=	13.07.2022 13:12:07
#Edit:Spike=	10.08.2022 10:28:39
#Base:Fit=	10.08.2022 10:29:19
#Base:Fit=	10.08.2022 10:29:37
#Base:Sub=	10.08.2022 10:31:46
#Filter:Polynom=	16.08.2022 10:13:29
#AxisType[0]=Intens
#AxisUnit[0]=Cnt
#AxisType[1]=Spectr
#AxisUnit[1]=1/cm
200.563	44.7737
204.194	42.5599
207.821	39.7945
211.449	36.342
215.074	33.205
218.699	30.0743
222.321	27.8028
225.941	24.5698
229.562	20.6183
233.18	18.8732
236.796	16.885
240.411	16.2311
244.026	14.435
247.638	11.7545
251.248	11.3341
254.857	9.66383
258.465	8.90397
262.071	7.17231
265.678	4.20312
269.282	3.25592
272.884	2.99627
276.484	3.04932
280.084	2.85974
283.682	3.17576
287.276	2.75202
290.871	2.72305
294.465	4.83153
298.057	7.43903
301.648	10.6665
305.237	12.0327
308.823	14.6018
312.41	15.7834
315.995	18.0207
319.579	19.5991
323.16	22.0845
326.741	23.658
330.321	23.0914
333.897	22.7466
337.474	23.7689
341.048	23.5454
344.622	21.0784
348.192	19.1345
351.764	17.6157
355.332	14.3031
358.901	12.531
362.466	10.7021
366.03	7.9629
369.594	5.4155
373.155	5.33952
376.715	3.65568
380.273	4.10184
383.832	3.4
387.388	2.173
390.942	3.48352
394.495	4.24985
398.047	3.60284
401.597	5.41208
405.145	7.48932
408.693	7.02222
412.239	9.48482
415.783	9.56549
419.327	11.4945
422.869	12.6786
426.409	13.1035
429.948	11.8863
433.486	11.394
437.022	10.7488
440.558	9.38817
444.089	8.65462
447.622	8.82583
451.153	8.8351
454.682	10.1908
458.208	10.5239
461.735	9.96386
465.259	12.0863
468.783	13.5331
472.306	16.3349
475.825	20.405
479.346	24.515
482.862	27.0056
486.38	30.9351
489.894	34.5605
493.407	36.8813
496.92	39.3179
500.43	43.4583
503.939	46.5992
507.448	46.8235
510.954	46.7637
514.459	44.6501
517.962	43.0143
521.466	41.9839
524.966	40.9055
528.466	40.6309
531.964	39.6304
535.46	37.7073
538.955	36.2149
542.449	34.0506
545.942	31.2356
549.433	23.2393
552.923	22.0454
556.412	22.7841
559.899	27.3869
563.385	28.6396
566.867	29.4793
570.35	30.3369
573.832	29.2855
577.313	29.7704
580.79	30.6069
584.268	30.1904
587.745	30.0954
591.218	28.0449
594.692	25.1744
598.164	22.6218
601.634	22.1865
605.104	22.93
608.57	22.945
612.037	21.2838
615.501	19.4055
618.966	17.1894
622.427	14.5794
625.887	12.4484
629.348	10.5669
632.806	8.60817
636.262	9.61714
639.716	16.5641
643.172	18.1843
646.624	20.1097
650.075	20.2081
653.524	21.537
656.972	22.1715
660.419	22.9884
663.865	25.2766
667.309	24.0507
670.752	25.658
674.194	25.9578
677.634	27.2763
681.073	28.3439
684.511	27.9108
687.947	28.0058
691.382	27.8212
694.816	27.4859
698.247	27.7466
701.678	28.8018
705.108	30.5038
708.534	31.3969
711.962	32.301
715.388	33.685
718.81	34.4145
722.234	35.0842
725.654	34.7578
729.075	36.822
732.492	36.9426
735.91	37.8206
739.325	40.2101
742.741	41.2974
746.153	41.8451
749.564	43.5724
752.976	46.5373
756.385	50.7905
759.792	54.1436
763.2	55.8489
766.604	57.116
770.008	56.8156
773.41	59.3567
776.811	60.6657
780.21	61.472
783.608	65.5462
787.005	66.9977
790.401	69.3481
793.795	70.707
797.188	72.525
800.58	73.9276
803.971	76.2422
807.36	76.7648
810.748	78.4635
814.135	79.9631
817.518	81.8326
820.902	82.9735
824.285	84.4961
827.665	84.9457
831.045	86.1516
834.424	86.5152
837.8	87.095
841.177	86.7869
844.55	83.9288
847.924	82.5983
851.295	79.7637
854.666	76.1016
858.034	75.4136
861.403	74.5914
864.769	72.6134
868.133	70.5044
871.498	69.4959
874.86	68.9421
878.221	66.8553
881.58	66.0302
884.938	66.2678
888.297	66.0117
891.653	65.0679
895.007	66.4166
898.36	65.9744
901.712	65.4272
905.063	62.8173
908.412	60.573
911.76	58.8313
915.107	57.1771
918.452	56.8465
921.797	56.0222
925.138	54.7524
928.48	55.3821
931.82	53.7638
935.16	50.7025
938.496	48.7956
941.833	47.2401
945.168	42.9035
948.5	40.3505
951.834	39.6333
955.163	39.5685
958.494	37.7929
961.821	34.1926
965.15	34.4523
968.474	32.6149
971.8	31.1143
975.123	33.2483
978.446	33.0286
981.766	32.4791
985.084	31.3102
988.402	30.4343
991.72	31.163
995.035	30.2602
998.349	31.5824
1001.66	32.6474
1004.97	34.0488
1008.28	36.2415
1011.59	35.9079
1014.9	34.5165
1018.21	35.9936
1021.51	37.5894
1024.81	39.283
1028.12	41.5449
1031.42	46.5403
1034.72	48.2724
1038.02	49.6511
1041.31	50.6826
1044.61	51.7944
1047.91	54.4038
1051.2	55.3136
1054.49	55.0473
1057.78	53.7904
1061.07	52.2732
1064.36	51.246
1067.65	49.3268
1070.93	47.0868
1074.22	45.3988
1077.5	43.4555
1080.78	41.0486
1084.06	40.8425
1087.34	37.9794
1090.62	34.7284
1093.9	34.8956
1097.17	34.4582
1100.45	36.8851
1103.72	37.6538
1106.99	39.2061
1110.27	38.5273
1113.53	38.4092
1116.8	37.241
1120.07	34.6833
1123.33	32.0189
1126.6	29.122
1129.86	27.3905
1133.12	24.4348
1136.38	21.0141
1139.64	20.0668
1142.9	17.3735
1146.16	14.8735
1149.41	12.7972
1152.67	11.1751
1155.92	8.02647
1159.17	4.60423
1162.42	1.70598
1165.67	0.346573
1168.92	-0.63203
1172.16	0.133246
1175.41	0.841943
1178.65	1.96716
1181.9	3.23239
1185.14	3.96645
1188.38	4.87934
1191.62	6.57812
1194.86	7.49273
1198.09	7.21111
1201.33	8.58931
1204.56	10.2519
1207.8	13.8969
1211.03	16.6567
1214.26	20.9139
1217.49	24.2726
1220.71	28.278
1223.94	33.013
1227.16	37.3406
1230.39	40.3738
1233.61	43.0747
1236.83	46.7114
1240.05	50.7386
1243.27	56.2432
1246.49	60.9714
1249.71	65.0895
1252.92	67.1308
1256.14	70.358
1259.35	73.4233
1262.56	78.1528
1265.77	82.5216
1268.98	86.4469
1272.19	89.3031
1275.4	92.4391
1278.6	94.3955
1281.81	98.5049
1285.01	101.593
1288.21	104.031
1291.41	106.952
1294.61	109.896
1297.81	110.696
1301.01	112.021
1304.2	112.827
1307.4	112.583
1310.59	112.242
1313.78	113.029
1316.97	111.356
1320.16	111.194
1323.35	109.967
1326.54	107.402
1329.72	104.148
1332.91	100.922
1336.09	98.5955
1339.27	97.3792
1342.45	94.9968
1345.64	91.3869
1348.81	88.4617
1351.99	87.1755
1355.17	85.4117
1358.34	81.9935
1361.51	81.0925
1364.69	77.8382
1367.86	75.8901
1371.03	75.7062
1374.2	73.9017
1377.37	73.9432
1380.53	71.8098
1383.7	70.573
1386.86	68.5193
1390.02	67.6616
1393.19	65.6593
1396.35	63.9541
1399.51	64.5382
1402.66	67.6419
1405.82	69.7244
1408.97	73.5855
1412.13	78.2589
1415.28	84.613
1418.43	90.9405
1421.59	100.565
1424.73	111.406
1427.88	123.235
1431.03	133.798
1434.18	141.795
1437.32	148.903
1440.46	156.086
1443.61	162.296
1446.75	166.914
1449.89	167.321
1453.03	165.095
1456.16	160.383
1459.3	155.611
1462.44	148.097
1465.57	137.834
1468.7	127.448
1471.83	116.146
1474.96	106.411
1478.09	97.0178
1481.22	86.3165
1484.35	77.3033
1487.47	66.401
1490.6	59.5352
1493.72	53.056
1496.84	47.2001
1499.96	44.7573
1503.08	41.675
1506.2	38.8725
1509.32	30.546
1512.44	23.5413
1515.55	26.0683
1518.66	28.7193
1521.78	32.2351
1524.89	34.6034
1528	36.3628
1531.11	38.8908
1534.21	42.4258
1537.32	45.2832
1540.43	47.7536
1543.53	51.2402
1546.63	54.3206
1549.74	57.9844
1552.84	59.5699
1555.94	60.4521
1559.03	61.7197
1562.13	63.8076
1565.23	63.6418
1568.32	64.6049
1571.42	63.5897
1574.51	64.3686
1577.6	65.4828
1580.69	63.8645
1583.78	60.6436
1586.87	57.2441
1589.95	64.8484
1593.04	68.8222
1596.12	69.578
1599.21	69.5318
1602.29	67.0661
1605.37	68.1843
1608.45	68.5993
1611.53	68.0016
1614.6	67.8418
1617.68	70.0939
1620.75	71.316
1623.83	74.6674
1626.9	78.1953
1629.97	80.4748
1633.04	83.6955
1636.11	87.5788
1639.18	91.6462
1642.25	96.1186
1645.31	100.105
1648.38	102.891
1651.44	106.375
1654.5	105.666
1657.56	104.233
1660.62	102.342
1663.68	100.574
1666.74	97.2503
1669.8	92.9442
1672.85	86.0356
1675.91	80.0139
1678.96	73.5606
1682.01	66.3316
1685.06	59.3569
1688.11	51.9119
1691.16	46.8611
1694.21	41.9087
1697.25	37.1649
1700.3	33.6087
1703.34	29.4532
1706.39	26.1111
1709.43	22.8909
1712.47	21.9407
1715.51	20.0971
1718.54	17.4822
1721.58	15.3482
1724.62	14.3888
1727.65	12.6623
1730.68	11.4487
1733.72	9.36802
1736.75	8.66988
1739.78	8.5785
1742.81	6.60423
1745.84	4.53748
1748.86	3.55873
1751.89	2.40781
1754.91	2.02279
1757.93	0.799755
1760.96	1.36874
1763.98	-0.197797
1767	-0.57322
1770.02	-0.200079
1773.03	-1.34094
1776.05	-0.58069
1779.07	0.209517
1782.08	0.0416072
1785.09	0.369835
1788.11	0.737795
1791.12	0.480859
1794.13	-0.0725115
1797.13	1.06051
1800.14	0.889108
1803.15	1.30951
1806.15	1.6485
1809.16	1.95646
1812.16	2.46931
1815.16	3.15333
1818.16	3.4016
1821.16	4.3578
1824.16	5.1838
1827.16	6.02281
1830.16	7.65849
1833.15	6.95513
1836.14	7.54841
1839.14	7.37073
1842.13	6.83695
1845.12	6.95822
1848.11	6.76177
1851.1	7.42921
1854.08	6.91818
1857.07	6.52058
1860.05	5.98696
1863.04	5.84428
1866.02	5.7267
1869	5.90899
1871.98	5.39342
1874.96	4.47388
1877.94	4.97511
1880.92	4.64168
1882.51	3.76584
1885.5	3.59534
1888.48	3.59394
1891.47	4.27066
1894.46	4.47561
1897.44	5.54207
1900.42	6.36989
1903.41	7.32975
1906.39	7.58886
1909.37	8.02369
1912.35	8.30049
1915.32	7.53405
1918.3	7.63971
1921.27	7.9048
1924.25	7.28566
1927.22	7.27646
1930.19	6.89982
1933.17	7.12495
1936.14	7.7035
1939.11	6.64831
1942.07	6.84856
1945.04	5.27894
1948.01	4.50302
1950.97	3.41789
1953.93	2.63218
1956.9	1.9868
1959.86	1.78867
1962.82	1.69178
1965.78	2.31052
1968.74	2.02407
1971.69	1.81429
1974.65	1.75653
1977.6	1.25136
1980.56	0.878979
1983.51	0.613899
1986.46	-0.0174842
1989.41	-0.332108
1992.36	0.230424
1995.31	0.629894
1998.26	0.862311
2001.2	1.34335
2004.15	0.882062
2007.09	2.11192
2010.04	3.58695
2012.98	3.9517
2015.92	4.2096
2018.86	5.27579
2021.8	6.06109
2024.73	7.74048
2027.67	8.51126
2030.61	8.74238
2033.54	8.70425
2036.47	7.65292
2039.4	8.84149
2042.33	8.82183
2045.27	8.69401
2048.19	9.22768
2051.12	10.0465
2054.05	10.1957
2056.97	10.704
2059.9	10.731
2062.82	11.8648
2065.74	12.2319
2068.67	12.4336
2071.59	12.805
2074.51	13.4514
2077.42	14.155
2080.34	14.1637
2083.26	15.2985
2086.17	14.6198
2089.09	14.6717
2092	14.2285
2094.91	14.0084
2097.82	14.3019
2100.73	14.7703
2103.64	14.8104
2106.55	15.8773
2109.45	16.8102
2112.36	18.4663
2115.26	18.8387
2118.17	18.8926
2121.07	21.992
2123.97	24.0753
2126.87	26.7647
2129.77	30.561
2132.67	34.0907
2135.56	37.2733
2138.46	39.6551
2141.35	41.3553
2144.25	45.4907
2147.14	47.6052
2150.03	48.7178
2152.92	50.5422
2155.81	52.0699
2158.7	54.0464
2161.59	56.0029
2164.47	58.7854
2167.36	60.5284
2170.24	62.9162
2173.13	63.6792
2176.01	63.8545
2178.89	62.3184
2181.77	61.8061
2184.65	61.4038
2187.53	60.0974
2190.4	59.2923
2193.28	59.0457
2196.16	57.3284
2199.03	54.8461
2201.9	53.8697
2204.77	51.2714
2207.64	48.6821
2210.51	47.1004
2213.38	43.3575
2216.25	40.5546
2219.12	36.5592
2221.98	34.8584
2224.85	32.8629
2227.71	31.8049
2230.57	30.2705
2233.43	28.9996
2236.29	27.163
2239.15	26.0194
2242.01	24.7693
2244.87	22.3521
2247.72	21.112
2250.58	19.6872
2253.43	19.1502
2256.29	17.7859
2259.14	16.5693
2261.99	16.3309
2264.84	15.9978
2267.69	15.5904
2270.53	14.7409
2273.38	14.5437
2276.23	13.8363
2279.07	11.6208
2281.91	10.4156
2284.76	9.06755
2287.6	9.12596
2290.44	8.17348
2293.28	7.32389
2296.12	7.82044
2298.96	7.88271
2301.79	8.82355
2304.63	9.21746
2307.46	9.12925
2310.3	10.3102
2313.13	11.1657
2315.96	11.5649
2318.79	11.7778
2321.62	11.8165
2324.45	12.0119
2327.27	11.8357
2330.1	11.9926
2332.92	11.832
2335.75	11.9323
2338.57	11.1395
2341.39	9.65944
2344.21	8.35489
2347.04	7.32932
2349.85	6.95003
2352.67	5.86336
2355.49	5.72896
2358.3	5.47057
2361.12	4.43356
2363.93	5.21068
2366.75	6.49308
2369.56	6.8593
2372.37	6.92145
2375.18	6.19618
2377.99	7.32656
2380.8	8.74594
2383.6	8.65947
2386.41	9.01172
2389.21	9.36411
2392.02	8.73445
2394.82	9.22956
2397.62	9.51746
2400.42	9.87275
2403.22	10.7787
2406.02	11.5263
2408.82	11.7357
2411.62	11.71
2414.41	11.9462
2417.21	12.351
2420	12.0337
2422.79	12.4174
2425.59	13.0076
2428.38	11.5855
2431.17	11.658
2433.95	11.8147
2436.74	11.26
2439.53	11.4842
2442.31	11.4762
2445.1	11.9695
2447.88	11.9914
2450.67	10.9248
2453.45	9.98579
2456.23	9.15695
2459.01	8.52608
2461.79	7.91282
2464.57	8.23942
2467.34	7.81502
2470.12	6.93641
2472.89	6.97756
2475.67	6.96462
2478.44	6.79988
2481.21	6.44512
2483.98	6.17014
2486.75	6.15692
2489.52	5.97935
2492.29	5.37504
2495.05	4.69335
2497.82	5.55127
2500.58	6.57477
2503.35	5.67932
2506.11	5.53135
2508.87	5.19842
2511.63	5.35888
2514.39	4.27943
2517.15	3.05238
2519.91	2.30114
2522.67	1.57748
2525.42	1.67894
2528.18	0.356737
2530.93	0.769939
2533.69	0.568822
2536.44	0.738664
2539.19	1.65346
2541.94	1.54004
2544.69	2.38782
2547.44	3.34136
2550.18	3.74002
2552.93	4.39902
2555.67	5.00837
2558.42	6.44435
2561.16	7.97708
2563.9	9.38431
2566.64	9.79225
2569.38	9.9661
2572.12	10.2627
2574.86	10.7522
2577.6	11.6593
2580.33	11.6821
2583.07	11.7631
2585.8	11.6889
2588.54	11.4429
2591.27	11.1307
2594	10.7593
2596.73	10.2386
2599.46	10.3606
2602.19	9.48691
2604.92	8.96324
2607.64	7.56662
2610.37	7.10901
2613.09	6.01503
2615.82	5.75251
2618.54	5.15076
2621.26	5.62125
2623.98	5.98646
2626.7	5.10405
2629.42	5.36259
2632.14	5.64369
2634.86	5.7949
2637.57	6.01684
2640.29	6.15089
2643	6.7604
2645.71	8.0771
2648.43	8.56297
2651.14	9.36545
2653.85	10.2505
2656.56	10.0315
2659.26	10.8894
2661.97	11.2805
2664.68	11.096
2667.38	10.6373
2670.09	10.7482
2672.79	11.7283
2675.49	12.2411
2678.19	11.9294
2680.89	12.3172
2683.59	12.9777
2686.29	12.8405
2688.99	13.767
2691.69	13.6285
2694.38	13.0861
2697.08	13.6298
2699.77	13.7703
2702.46	14.9298
2705.15	15.6469
2707.85	15.5817
2710.54	15.6465
2713.22	15.9752
2715.91	16.7489
2718.6	16.247
2721.29	15.698
2723.97	15.0745
2726.66	14.4579
2729.34	14.0197
2732.02	13.719
2734.7	13.5755
2737.38	13.7017
2740.06	13.9372
2742.74	12.9786
2745.42	13.0313
2748.09	13.432
2750.77	12.3569
2753.45	11.9724
2756.12	12.0159
2758.79	10.7989
2761.46	9.97425
2764.14	9.65314
2766.8	8.99785
2769.47	7.69813
2772.14	6.73712
2774.81	5.06101
2777.48	4.42531
2780.14	2.99878
2782.8	2.98409
2785.47	2.11813
2788.13	1.72626
2790.79	0.35842
2793.45	-0.501279
2796.11	-0.234481
2798.77	-0.641207
2801.43	-0.639958
2804.09	-0.950458
2806.74	-2.38443
2809.4	-2.15429
2812.05	-2.39803
2814.71	-2.93285
2817.36	-1.71087
2820.01	2.57725
2822.66	7.06252
2825.31	13.5559
2827.96	21.9757
2830.6	31.6718
2833.25	41.5721
2835.9	51.9833
2838.54	63.2213
2841.18	75.1999
2843.83	88.6243
2846.47	103.976
2849.11	118.336
2851.75	133.124
2854.39	147.751
2857.03	161.636
2859.66	175.711
2862.3	189.359
2864.94	200.706
2867.57	211.206
2870.2	219.312
2872.84	227.799
2875.47	233.434
2878.1	239.971
2880.73	247.741
2883.36	254.566
2885.99	261.521
2888.61	268.541
2891.24	275.878
2893.86	284.044
2896.49	290.218
2899.11	296.762
2901.73	302.517
2904.36	310.436
2906.98	321.637
2909.6	333.58
2912.21	344.907
2914.83	355.632
2917.45	366.502
2920.07	375.951
2922.68	383.519
2925.29	388.36
2927.91	390.528
2930.52	390.549
2933.13	386.153
2935.74	381.558
2938.35	374.463
2940.96	365.776
2943.57	357.389
2946.18	344.317
2948.78	329.428
2951.39	314.336
2953.99	299.425
2956.59	285.346
2959.2	270.075
2961.8	253.705
2964.4	237.238
2967	223.181
2969.6	211.203
2972.19	198.109
2974.79	184.685
2977.39	172.497
2979.98	159.814
2982.58	146.8
2985.17	134.102
2987.76	120.192
2990.35	107.135
2992.94	95.0764
2995.53	81.5779
2998.12	70.7119
3000.71	60.483
3003.3	51.7547
3005.88	43.3206
3008.47	35.6651
3011.05	26.9907
3013.64	21.3792
3016.22	16.8573
3018.8	13.4127
3021.38	9.12122
3023.96	6.16979
3026.54	2.70584
3029.12	1.68096
3031.69	-0.479599
3034.27	-0.717081
3036.84	-1.30349
3039.42	-0.391223
3041.99	1.57497
3044.57	2.83113
3047.14	3.92085
3049.71	4.72499
3052.28	4.80947
3054.85	5.1979
3057.41	4.62197
3059.98	4.51325
3062.55	4.94957
3065.11	5.11462
3067.68	5.35801
3070.24	4.74557
3072.8	5.57865
3075.36	4.37855
3077.93	3.8899
3080.49	2.62922
3083.04	1.19609
3085.6	0.291193
3088.16	0.203065
3090.72	-0.683524
3093.27	-0.18983
3095.83	0.0110121
3098.38	0.47126
3100.93	1.4141
3103.49	2.43493
3106.04	3.05493
3108.59	3.46741
3111.14	4.57316
3113.69	5.13231
3116.23	7.29058
3118.78	9.51182
3121.33	12.0569
3123.87	14.8216
3126.41	17.1015
3128.96	19.5458
3131.5	22.5961
3134.04	26.2103
3136.58	29.7746
3139.12	31.8196
3141.66	35.2826
3144.2	39.0964
3146.74	42.8008
3149.27	44.9362