File: data/Raman/poly_smoothed/Mb_20_23_05_1x_45s_532 nm_x50_100%_600 gr_mm_01.txt
#Acq. time (s)=	45
#Accumulations=	2
#Range (cm-¹)=	200...3150
#Windows=	2
#Auto scanning=	Off
#Autofocus=	Off
#Macrospot=	Off
#AutoExposure=	Off
#Spike filter=	Multiple accum.
#Delay time (s)=	0
#Binning=	1
#Readout mode=	Signal
#DeNoise=	Off
#ICS correction=	On
#Dark correction=	Off
#Inst. Process=	Off
#Detector Gain=	Best Dynamic Range
#Detector ADC=	20 kHz
#Detector temperature (°C)=	-69.85
#Instrument=	LabRAM HR Evol
#Detector=	Synapse
#Objective=	x50
#Grating=	600 gr/mm
#ND Filter=	100%
#Laser (nm)=	532
#Hole=	100.021
#Range=	Auto
#Laser Pol.=	No
#Raman. Pol.=	No
#Laser Pol. (°)=	-0.0007625
#Raman Pol. (°)=	89.9995
#Collection=	Microscope
#StageXY=	Marzhauser
#StageZ=	Marzhauser
#X (µm)=	-6973.2
#Y (µm)=	2174.5
#Z (µm)=	-74.35
#Full time(mm:ss)=	3:19
#Project=
#Sample=
#Site=
#Title=	Mb_20_23_05_2x_45s_532 nm_x50_100%_600 gr_mm
#Remark=
#Date=	13.07.2022 13:17
#Acquired=	13.07.2022 13:17:21
#Base:Fit=	10.08.2022 10:29:19
#Base:Fit=	10.08.2022 10:29:37
#Base:Sub=	10.08.2022 10:31:46
#Filter:Polynom=	16.08.2022 10:13:29
#AxisType[0]=Intens
#AxisUnit[0]=Cnt
#AxisType[1]=Spectr
#AxisUnit[1]=1/cm
200.563	16.9629
204.194	16.5255
207.821	16.0676
211.449	15.6649
215.074	15.8809
218.699	17.3386
222.321	15.7798
225.941	15.9385
229.562	15.4253
233.18	14.1548
236.796	11.643
240.411	10.7342
244.026	9.52759
247.638	8.98712
251.248	7.63317
254.857	7.36958
258.465	6.86559
262.071	6.16402
265.678	5.26234
269.282	6.60197
272.884	6.59924
276.484	6.5221
280.084	6.24835
283.682	6.32093
287.276	7.07512
290.871	7.93592
294.465	7.86329
298.057	8.58768
301.648	11.7676
305.237	13.3968
308.823	14.1414
312.41	16.2381
315.995	17.5168
319.579	19.5035
323.16	19.2788
326.741	20.1273
330.321	21.7733
333.897	22.9303
337.474	22.2266
341.048	21.5041
344.622	20.1298
348.192	18.2584
351.764	16.3686
355.332	14.6183
358.901	14.2597
362.466	13.6025
366.03	12.1476
369.594	11.505
373.155	9.92239
376.715	8.68544
380.273	7.81382
383.832	7.02772
387.388	6.61738
390.942	6.68341
394.495	7.03288
398.047	8.29728
401.597	7.79188
405.145	8.21268
408.693	9.4315
412.239	9.11891
415.783	7.96359
419.327	8.77161
422.869	7.64751
426.409	7.49906
429.948	7.03104
433.486	6.37132
437.022	4.61552
440.558	4.29186
444.089	4.70517
447.622	6.20245
451.153	7.25162
454.682	7.81222
458.208	8.21769
461.735	7.93557
465.259	8.8981
468.783	9.45036
472.306	9.19353
475.825	12.37
479.346	13.434
482.862	15.4037
486.38	16.7393
489.894	18.5344
493.407	22.6243
496.92	24.2421
500.43	25.0181
503.939	26.0124
507.448	28.3881
510.954	28.8472
514.459	28.8172
517.962	27.7561
521.466	27.5094
524.966	27.2543
528.466	27.6378
531.964	26.8432
535.46	25.1605
538.955	23.005
542.449	21.7209
545.942	18.6479
549.433	17.341
552.923	15.6569
556.412	14.5551
559.899	12.4657
563.385	12.3517
566.867	13.0109
570.35	11.594
573.832	11.6608
577.313	12.0443
580.79	11.7408
584.268	9.9643
587.745	7.38865
591.218	6.72197
594.692	5.9881
598.164	5.05748
601.634	5.90089
605.104	6.9046
608.57	7.90903
612.037	10.876
615.501	11.9518
618.966	11.9925
622.427	12.8083
625.887	14.384
629.348	16.2161
632.806	17.8208
636.262	18.6131
639.716	20.607
643.172	22.074
646.624	23.0455
650.075	24.9642
653.524	26.092
656.972	27.0174
660.419	27.7288
663.865	28.1841
667.309	27.6753
670.752	26.7908
674.194	25.6125
677.634	25.1518
681.073	24.4437
684.511	25.5442
687.947	26.8635
691.382	26.9452
694.816	27.6113
698.247	29.1068
701.678	30.7454
705.108	32.1015
708.534	32.1803
711.962	33.8354
715.388	31.6667
718.81	33.5266
722.234	35.2936
725.654	36.4427
729.075	36.5343
732.492	38.4561
735.91	38.6796
739.325	39.2988
742.741	43.2059
746.153	44.8341
749.564	48.5493
752.976	50.5079
756.385	52.5302
759.792	54.5614
763.2	58.1715
766.604	61.69
770.008	65.5034
773.41	68.0696
776.811	70.027
780.21	72.8544
783.608	77.724
787.005	80.4301
790.401	81.8194
793.795	83.8469
797.188	84.7127
800.58	85.5328
803.971	88.6895
807.36	88.7801
810.748	87.5891
814.135	85.646
817.518	83.8745
820.902	83.2895
824.285	84.281
827.665	82.8693
831.045	82.9512
834.424	81.2859
837.8	78.2223
841.177	77.0785
844.55	76.6153
847.924	73.3943
851.295	72.5191
854.666	69.6663
858.034	67.6785
861.403	66.8484
864.769	66.686
868.133	65.4756
871.498	63.5285
874.86	61.7809
878.221	60.9886
881.58	59.4132
884.938	58.6623
888.297	57.7347
891.653	56.495
895.007	54.2103
898.36	53.8256
901.712	54.145
905.063	53.9762
908.412	53.0965
911.76	51.5559
915.107	51.1238
918.452	50.4048
921.797	48.9901
925.138	48.891
928.48	46.8382
931.82	45.4847
935.16	45.7726
938.496	44.5408
941.833	44.3912
945.168	41.5714
948.5	39.0775
951.834	38.7462
955.163	38.4915
958.494	37.9288
961.821	36.9419
965.15	38.1523
968.474	38.3591
971.8	39.5335
975.123	38.6941
978.446	37.9887
981.766	38.0941
985.084	37.6529
988.402	36.9777
991.72	34.4125
995.035	33.3173
998.349	32.6528
1001.66	31.9422
1004.97	31.1149
1008.28	29.9126
1011.59	29.6871
1014.9	30.7442
1018.21	30.8466
1021.51	29.9569
1024.81	31.0883
1028.12	32.2605
1031.42	34.8908
1034.72	37.1494
1038.02	40.0593
1041.31	40.8614
1044.61	41.3544
1047.91	43.4301
1051.2	42.0493
1054.49	41.9472
1057.78	40.3459
1061.07	39.2891
1064.36	38.7511
1067.65	38.123
1070.93	37.062
1074.22	36.2918
1077.5	34.5881
1080.78	32.8848
1084.06	31.5751
1087.34	30.896
1090.62	30.2154
1093.9	29.8019
1097.17	29.5284
1100.45	29.2192
1103.72	29.2942
1106.99	29.0028
1110.27	29.0178
1113.53	28.58
1116.8	26.1402
1120.07	24.8658
1123.33	23.0679
1126.6	22.5493
1129.86	19.6691
1133.12	18.3679
1136.38	17.3775
1139.64	15.0414
1142.9	14.1141
1146.16	14.1753
1149.41	11.4889
1152.67	9.27455
1155.92	8.42762
1159.17	6.13425
1162.42	6.3787
1165.67	5.79203
1168.92	6.99131
1172.16	8.24582
1175.41	8.14285
1178.65	6.56451
1181.9	5.69141
1185.14	5.16823
1188.38	4.84062
1191.62	4.52554
1194.86	3.99333
1198.09	5.04532
1201.33	6.74583
1204.56	7.89448
1207.8	8.89956
1211.03	9.34647
1214.26	10.8928
1217.49	11.2043
1220.71	14.4691
1223.94	15.0839
1227.16	16.3296
1230.39	18.2897
1233.61	20.2104
1236.83	23.603
1240.05	25.7302
1243.27	27.4786
1246.49	27.9079
1249.71	27.4654
1252.92	27.256
1256.14	27.3914
1259.35	27.0485
1262.56	28.2917
1265.77	30.2668
1268.98	32.7638
1272.19	35.779
1275.4	38.4853
1278.6	40.3145
1281.81	44.2695
1285.01	46.6887
1288.21	48.9516
1291.41	52.2782
1294.61	54.6113
1297.81	56.3613
1301.01	58.9515
1304.2	61.5042
1307.4	61.8238
1310.59	62.3013
1313.78	61.9767
1316.97	62.5128
1320.16	59.9858
1323.35	57.6962
1326.54	55.2909
1329.72	53.5655
1332.91	53.5448
1336.09	50.9199
1339.27	49.5455
1342.45	48.0714
1345.64	47.4275
1348.81	45.4925
1351.99	43.6607
1355.17	41.7351
1358.34	41.458
1361.51	40.4099
1364.69	38.8735
1367.86	38.5841
1371.03	38.9509
1374.2	38.3242
1377.37	36.6054
1380.53	35.9584
1383.7	34.972
1386.86	35.3088
1390.02	35.2315
1393.19	35.121
1396.35	34.8444
1399.51	35.3634
1402.66	35.1806
1405.82	38.1481
1408.97	40.808
1412.13	43.3186
1415.28	47.599
1418.43	53.5461
1421.59	60.0774
1424.73	66.2435
1427.88	71.826
1431.03	79.5664
1434.18	85.5677
1437.32	90.0878
1440.46	93.6787
1443.61	95.938
1446.75	97.0963
1449.89	96.5785
1453.03	94.7195
1456.16	93.7679
1459.3	90.3548
1462.44	86.1588
1465.57	80.2929
1468.7	72.443
1471.83	64.2875
1474.96	57.9606
1478.09	50.5606
1481.22	44.7495
1484.35	39.6576
1487.47	34.6433
1490.6	29.8296
1493.72	26.0706
1496.84	23.0259
1499.96	20.2518
1503.08	17.8129
1506.2	17.0813
1509.32	14.2744
1512.44	12.1385
1515.55	10.5062
1518.66	8.6424
1521.78	6.87317
1524.89	8.9076
1528	9.33664
1531.11	11.0632
1534.21	12.558
1537.32	13.147
1540.43	14.2237
1543.53	16.126
1546.63	17.3559
1549.74	20.1637
1552.84	21.8434
1555.94	23.1552
1559.03	25.7826
1562.13	27.7266
1565.23	29.2524
1568.32	30.6841
1571.42	31.4796
1574.51	32.987
1577.6	33.0155
1580.69	34.4377
1583.78	35.8214
1586.87	36.2594
1589.95	37.1987
1593.04	37.8785
1596.12	39.3633
1599.21	40.2201
1602.29	42.3014
1605.37	42.216
1608.45	42.7584
1611.53	41.9788
1614.6	40.7623
1617.68	42.2626
1620.75	44.3467
1623.83	45.9926
1626.9	48.2986
1629.97	47.8596
1633.04	50.0219
1636.11	52.2212
1639.18	53.475
1642.25	55.0896
1645.31	57.246
1648.38	58.0315
1651.44	58.8227
1654.5	59.6749
1657.56	59.9803
1660.62	59.5001
1663.68	58.7028
1666.74	56.7713
1669.8	55.0275
1672.85	52.2108
1675.91	50.3058
1678.96	46.0069
1682.01	41.3261
1685.06	36.5539
1688.11	32.7303
1691.16	30.5143
1694.21	28.5457
1697.25	23.6103
1700.3	20.6338
1703.34	16.6682
1706.39	14.5504
1709.43	12.9691
1712.47	11.1925
1715.51	8.8412
1718.54	7.78629
1721.58	7.05975
1724.62	5.38805
1727.65	4.56405
1730.68	3.33971
1733.72	4.29997
1736.75	4.17976
1739.78	3.25904
1742.81	3.01822
1745.84	3.05217
1748.86	3.3073
1751.89	2.46833
1754.91	1.94283
1757.93	1.21614
1760.96	2.22875
1763.98	2.82862
1767	2.37457
1770.02	2.13366
1773.03	2.10708
1776.05	2.5932
1779.07	2.66648
1782.08	2.76522
1785.09	2.82543
1788.11	2.32625
1791.12	2.08065
1794.13	3.27913
1797.13	3.68645
1800.14	3.17789
1803.15	2.72957
1806.15	3.16362
1809.16	2.46262
1812.16	1.39635
1815.16	0.40768
1818.16	0.412877
1821.16	0.294
1824.16	0.224793
1827.16	0.372327
1830.16	0.970674
1833.15	1.78533
1836.14	1.88228
1839.14	2.12483
1842.13	2.18111
1845.12	2.23115
1848.11	2.45009
1851.1	3.0894
1854.08	3.56224
1857.07	4.13479
1860.05	3.91873
1863.04	4.97416
1866.02	5.9004
1869	5.6551
1871.98	5.26974
1874.96	4.80656
1877.94	3.81203
1880.92	3.05245
1882.51	3.02918
1885.5	3.07939
1888.48	3.14469
1891.47	3.5045
1894.46	3.18245
1897.44	2.79905
1900.42	3.81473
1903.41	3.44403
1906.39	2.82407
1909.37	2.051
1912.35	1.56291
1915.32	1.33199
1918.3	1.66121
1921.27	1.27963
1924.25	1.95988
1927.22	1.62436
1930.19	1.61418
1933.17	1.12173
1936.14	2.50799
1939.11	2.94766
1942.07	2.54297
1945.04	2.23993
1948.01	3.28094
1950.97	3.32902
1953.93	4.37763
1956.9	5.31055
1959.86	4.7477
1962.82	4.51444
1965.78	4.16864
1968.74	4.73727
1971.69	4.66484
1974.65	4.3569
1977.6	3.94032
1980.56	4.27294
1983.51	4.64229
1986.46	5.96089
1989.41	5.99901
1992.36	5.04346
1995.31	4.82903
1998.26	4.50426
2001.2	3.87151
2004.15	3.77565
2007.09	3.87294
2010.04	4.85548
2012.98	4.7732
2015.92	5.47823
2018.86	6.04511
2021.8	5.27064
2024.73	5.71606
2027.67	5.86179
2030.61	5.15888
2033.54	5.13311
2036.47	5.1493
2039.4	4.78958
2042.33	4.06106
2045.27	4.32974
2048.19	4.69753
2051.12	5.37023
2054.05	6.19624
2056.97	5.59519
2059.9	5.40697
2062.82	4.19416
2065.74	4.09421
2068.67	3.10046
2071.59	4.26175
2074.51	4.87351
2077.42	5.46257
2080.34	6.62004
2083.26	7.64985
2086.17	8.09629
2089.09	9.30263
2092	9.44363
2094.91	10.2979
2097.82	12.3637
2100.73	12.8285
2103.64	14.0772
2106.55	14.4231
2109.45	15.0129
2112.36	15.4346
2115.26	17.7048
2118.17	18.2287
2121.07	18.3426
2123.97	18.4166
2126.87	18.4877
2129.77	19.2473
2132.67	19.8703
2135.56	20.1599
2138.46	21.159
2141.35	22.4964
2144.25	23.8947
2147.14	24.4313
2150.03	25.6188
2152.92	26.9994
2155.81	27.6705
2158.7	28.7308
2161.59	30.0783
2164.47	32.1912
2167.36	33.2886
2170.24	34.4887
2173.13	35.7472
2176.01	36.2619
2178.89	36.9363
2181.77	37.3371
2184.65	37.095
2187.53	37.1589
2190.4	35.0489
2193.28	34.7135
2196.16	32.5792
2199.03	31.2964
2201.9	29.4987
2204.77	26.8716
2207.64	24.6776
2210.51	23.5092
2213.38	21.351
2216.25	18.7082
2219.12	16.8317
2221.98	15.4651
2224.85	13.7364
2227.71	12.5236
2230.57	11.247
2233.43	10.1945
2236.29	9.16453
2239.15	8.28726
2242.01	7.54483
2244.87	7.12245
2247.72	6.1394
2250.58	5.86963
2253.43	5.23763
2256.29	5.34083
2259.14	4.82829
2261.99	4.63334
2264.84	4.60675
2267.69	5.16604
2270.53	5.10527
2273.38	5.15834
2276.23	4.34189
2279.07	5.04945
2281.91	5.57093
2284.76	5.25273
2287.6	5.50382
2290.44	5.58782
2293.28	5.02738
2296.12	4.91169
2298.96	4.79834
2301.79	4.63903
2304.63	5.06325
2307.46	4.92878
2310.3	4.31143
2313.13	3.50293
2315.96	4.10819
2318.79	4.36891
2321.62	4.28235
2324.45	4.74368
2327.27	4.69097
2330.1	5.11809
2332.92	4.7668
2335.75	4.71976
2338.57	3.78929
2341.39	3.77661
2344.21	1.80758
2347.04	1.92112
2349.85	2.6184
2352.67	1.80482
2355.49	0.978834
2358.3	0.359085
2361.12	0.083752
2363.93	-0.358853
2366.75	-0.0153221
2369.56	0.132935
2372.37	0.887292
2375.18	0.369054
2377.99	0.160871
2380.8	0.0771187
2383.6	0.918872
2386.41	1.97664
2389.21	2.02598
2392.02	2.61085
2394.82	2.87365
2397.62	2.52588
2400.42	2.62146
2403.22	3.08592
2406.02	3.68378
2408.82	3.63447
2411.62	3.70916
2414.41	3.81134
2417.21	4.92292
2420	4.75143
2422.79	5.09107
2425.59	4.58796
2428.38	5.14479
2431.17	4.78608
2433.95	4.64804
2436.74	4.72545
2439.53	4.70987
2442.31	3.20873
2445.1	2.36729
2447.88	2.3011
2450.67	2.65677
2453.45	2.98083
2456.23	2.44523
2459.01	2.0453
2461.79	2.32583
2464.57	2.40631
2467.34	2.44283
2470.12	2.62563
2472.89	1.82453
2475.67	1.59558
2478.44	1.82857
2481.21	1.14688
2483.98	1.57101
2486.75	1.2603
2489.52	0.560446
2492.29	1.18818
2495.05	2.19172
2497.82	2.56561
2500.58	1.95146
2503.35	1.55554
2506.11	1.86248
2508.87	2.30048
2511.63	3.07284
2514.39	3.61777
2517.15	4.03489
2519.91	4.01152
2522.67	4.02568
2525.42	3.33053
2528.18	4.30779
2530.93	4.68115
2533.69	3.63092
2536.44	3.36016
2539.19	3.86625
2541.94	3.54367
2544.69	3.47155
2547.44	2.93387
2550.18	3.15765
2552.93	3.09649
2555.67	4.0397
2558.42	5.54403
2561.16	6.18588
2563.9	6.09796
2566.64	5.04931
2569.38	6.30757
2572.12	6.49805
2574.86	6.67289
2577.6	7.11672
2580.33	6.57666
2583.07	6.75866
2585.8	5.78457
2588.54	6.13113
2591.27	5.48657
2594	5.81119
2596.73	6.00096
2599.46	5.71774
2602.19	6.20872
2604.92	7.18019
2607.64	7.24459
2610.37	7.47389
2613.09	7.74195
2615.82	7.78651
2618.54	9.14153
2621.26	9.32347
2623.98	9.04508
2626.7	9.25633
2629.42	8.75394
2632.14	8.91701
2634.86	8.5868
2637.57	8.60694
2640.29	8.62109
2643	8.82241
2645.71	9.81826
2648.43	9.57153
2651.14	9.34563
2653.85	9.05229
2656.56	9.74411
2659.26	10.1045
2661.97	10.1066
2664.68	10.4537
2667.38	10.3014
2670.09	10.7852
2672.79	11.6309
2675.49	12.3656
2678.19	12.0446
2680.89	11.4892
2683.59	11.0095
2686.29	11.7342
2688.99	11.2471
2691.69	11.42
2694.38	11.0265
2697.08	10.7643
2699.77	10.938
2702.46	12.0382
2705.15	13.2016
2707.85	14.9739
2710.54	15.6522
2713.22	16.5795
2715.91	16.3186
2718.6	16.7333
2721.29	17.358
2723.97	18.1248
2726.66	17.7985
2729.34	18.4942
2732.02	18.0525
2734.7	18.3098
2737.38	17.9805
2740.06	16.6577
2742.74	15.4354
2745.42	14.2299
2748.09	13.7576
2750.77	13.4195
2753.45	13.3564
2756.12	12.3173
2758.79	12.1186
2761.46	11.8159
2764.14	11.7357
2766.8	10.8871
2769.47	10.2105
2772.14	9.84675
2774.81	9.23969
2777.48	8.70337
2780.14	8.95586
2782.8	8.74281
2785.47	9.02854
2788.13	8.92253
2790.79	8.74426
2793.45	8.1119
2796.11	7.30381
2798.77	7.6311
2801.43	7.81194
2804.09	7.01752
2806.74	5.69879
2809.4	5.67369
2812.05	5.79029
2814.71	5.39024
2817.36	7.27465
2820.01	10.1948
2822.66	14.0039
2825.31	18.2823
2827.96	22.703
2830.6	27.4213
2833.25	34.9396
2835.9	42.1992
2838.54	51.0289
2841.18	60.166
2843.83	69.0621
2846.47	77.8164
2849.11	88.0915
2851.75	97.8971
2854.39	106.463
2857.03	115.792
2859.66	124.032
2862.3	131.981
2864.94	138.659
2867.57	145.23
2870.2	148.529
2872.84	153.168
2875.47	156.381
2878.1	159.64
2880.73	164.468
2883.36	168.078
2885.99	171.837
2888.61	174.954
2891.24	178.173
2893.86	181.053
2896.49	185.534
2899.11	189.363
2901.73	194.182
2904.36	199.938
2906.98	206.671
2909.6	211.949
2912.21	218.928
2914.83	226.931
2917.45	232.939
2920.07	237.854
2922.68	242.324
2925.29	245.105
2927.91	247.35
2930.52	247.711
2933.13	247.469
2935.74	245.375
2938.35	241.895
2940.96	236.144
2943.57	230.581
2946.18	222.807
2948.78	214.232
2951.39	203.692
2953.99	194.819
2956.59	186.024
2959.2	175.194
2961.8	165.963
2964.4	157.199
2967	150.238
2969.6	142.532
2972.19	134.869
2974.79	126.487
2977.39	119.509
2979.98	111.246
2982.58	102.721
2985.17	94.9427
2987.76	86.5438
2990.35	77.9244
2992.94	70.2738
2995.53	62.0265
2998.12	55.4677
3000.71	47.8727
3003.3	40.8201
3005.88	34.7062
3008.47	28.4877
3011.05	22.8519
3013.64	18.4458
3016.22	14.4149
3018.8	11.6056
3021.38	9.42061
3023.96	7.89987
3026.54	7.0051
3029.12	5.61303
3031.69	5.03484
3034.27	4.28077
3036.84	3.288
3039.42	3.45202
3041.99	3.37076
3044.57	2.95984
3047.14	3.38208
3049.71	3.59871
3052.28	2.62218
3054.85	2.78405
3057.41	3.06286
3059.98	2.23824
3062.55	2.62267
3065.11	2.06552
3067.68	1.44431
3070.24	1.19855
3072.8	0.666058
3075.36	0.304923
3077.93	0.472573
3080.49	1.2333
3083.04	1.52635
3085.6	2.2528
3088.16	2.24093
3090.72	1.4781
3093.27	1.51768
3095.83	1.47486
3098.38	1.94404
3100.93	2.43308
3103.49	2.84793
3106.04	3.89152
3108.59	4.4016
3111.14	5.1068
3113.69	6.67364
3116.23	7.37276
3118.78	8.38236
3121.33	9.4215
3123.87	10.3695
3126.41	11.3067
3128.96	11.8344
3131.5	12.8255
3134.04	13.3019
3136.58	14.636
3139.12	15.964
3141.66	17.2609
3144.2	17.6954
3146.74	17.3247
3149.27	16.2332