File: data/Raman/poly_smoothed/Mb_20_23_42_45s_532 nm_x100_100%_600 gr_mm_01.txt
#Acq. time (s)=	45
#Accumulations=	2
#Range (cm-¹)=	200...3150
#Windows=	2
#Auto scanning=	Off
#Autofocus=	Off
#Macrospot=	Off
#AutoExposure=	Off
#Spike filter=	Multiple accum.
#Delay time (s)=	0
#Binning=	1
#Readout mode=	Signal
#DeNoise=	Off
#ICS correction=	On
#Dark correction=	Off
#Inst. Process=	Off
#Detector Gain=	Best Dynamic Range
#Detector ADC=	20 kHz
#Detector temperature (°C)=	-70.08
#Instrument=	LabRAM HR Evol
#Detector=	Synapse
#Objective=	x100
#Grating=	600 gr/mm
#ND Filter=	100%
#Laser (nm)=	532
#Hole=	100.021
#Range=	Auto
#Laser Pol.=	No
#Raman. Pol.=	No
#Laser Pol. (°)=	-0.0007625
#Raman Pol. (°)=	89.9995
#Collection=	Microscope
#StageXY=	Marzhauser
#StageZ=	Marzhauser
#X (µm)=	437
#Y (µm)=	3011.7
#Z (µm)=	-8.9
#Full time(mm:ss)=	3:11
#Project=
#Sample=
#Site=
#Title=	Mb_20_23_42_45s_532 nm_x100_100%_600 gr_mm
#Remark=
#Date=	14.07.2022 09:32
#Acquired=	14.07.2022 09:32:24
#Base:Fit=	10.08.2022 10:29:37
#Base:Sub=	10.08.2022 10:35:48
#Filter:Polynom=	16.08.2022 10:13:29
#AxisType[0]=Intens
#AxisUnit[0]=Cnt
#AxisType[1]=Spectr
#AxisUnit[1]=1/cm
200.554	23.8151
204.183	21.302
207.813	19.5081
211.439	17.9827
215.065	17.0655
218.688	16.3277
222.312	13.6731
225.933	11.4397
229.552	9.67438
233.171	9.05024
236.787	8.46772
240.402	7.47364
244.015	8.11421
247.627	8.05014
251.24	7.39231
254.849	7.49561
258.457	6.9271
262.063	8.06808
265.668	6.00196
269.271	6.71157
272.873	7.28912
276.474	5.88957
280.073	5.75166
283.671	4.30101
287.268	3.61189
290.863	3.09667
294.456	4.63179
298.049	4.43361
301.637	5.56763
305.227	5.99393
308.815	5.54032
312.402	5.36856
315.987	5.92895
319.569	7.5275
323.151	7.73206
326.733	7.89079
330.31	9.13837
333.889	9.85888
337.464	10.5474
341.039	11.124
344.611	11.9472
348.184	10.4704
351.754	9.93051
355.324	8.6651
358.89	8.51426
362.455	7.75596
366.021	8.05107
369.584	7.82615
373.145	7.08674
376.707	8.82097
380.265	10.5644
383.822	12.2356
387.378	11.7204
390.934	11.8509
394.487	11.2665
398.038	10.9976
401.588	10.914
405.137	12.0038
408.685	11.7142
412.23	10.7176
415.775	10.4416
419.318	10.4505
422.86	12.3136
426.401	12.8161
429.94	12.5109
433.478	10.7748
437.012	9.74956
440.547	8.38525
444.081	8.73122
447.613	11.4769
451.142	13.169
454.672	13.5539
458.2	14.8396
461.725	16.0587
465.251	17.1647
468.775	16.833
472.296	15.9958
475.817	16.7757
479.335	17.0627
482.854	17.7388
486.37	18.5063
489.886	18.3813
493.398	18.7623
496.91	17.4592
500.422	17.0175
503.93	17.3999
507.438	16.9767
510.946	18.01
514.45	16.68
517.954	16.1873
521.456	16.639
524.956	16.9033
528.456	17.788
531.956	18.5398
535.452	20.3977
538.947	19.2856
542.441	17.5912
545.934	17.0733
549.425	15.8322
552.915	16.3101
556.403	15.4646
559.889	15.774
563.375	13.2975
566.859	12.4891
570.342	10.6326
573.824	8.65436
577.303	7.35553
580.782	5.13476
584.26	3.1435
587.734	1.80415
591.21	0.408762
594.684	1.25994
598.154	1.58006
601.626	1.43594
605.094	3.46488
608.562	3.71614
612.027	3.14538
615.493	4.10166
618.956	4.83719
622.419	5.48763
625.879	4.83686
629.338	6.35975
632.797	6.84306
636.254	6.7705
639.708	6.13095
643.162	4.22415
646.614	4.78535
650.067	5.76816
653.516	6.75821
656.964	6.71168
660.411	6.70067
663.857	6.41533
667.301	4.46581
670.744	6.09796
674.186	7.02383
677.626	8.64129
681.065	8.87315
684.503	10.6173
687.939	9.81618
691.372	10.0177
694.806	9.72697
698.239	9.8447
701.67	11.1636
705.098	12.6428
708.526	14.467
711.954	14.6204
715.378	14.1954
718.802	14.8
722.226	14.8721
725.646	17.2006
729.067	20.1427
732.484	22.0656
735.902	24.3313
739.317	24.7527
742.731	26.5227
746.145	28.0875
749.556	30.4016
752.966	33.1601
756.377	36.9488
759.784	39.9515
763.19	41.983
766.594	42.6701
770	44.2282
773.402	45.7715
776.803	47.5956
780.202	49.4741
783.6	52.6382
786.997	55.5326
790.393	56.0998
793.787	57.5251
797.18	58.392
800.572	60.3859
803.963	61.7711
807.35	64.2593
810.738	64.6196
814.125	63.838
817.51	63.396
820.894	65.2864
824.275	65.2471
827.657	66.5747
831.037	66.6435
834.414	66.9686
837.792	66.6242
841.167	66.9199
844.542	64.6848
847.914	62.1495
851.287	61.2533
854.656	61.0043
858.026	60.8494
861.393	59.7548
864.761	59.0626
868.125	57.0422
871.489	55.411
874.85	55.522
878.213	55.2057
881.572	53.8944
884.931	52.6058
888.287	51.622
891.643	48.9091
894.997	47.1905
898.352	45.688
901.704	45.6281
905.055	43.339
908.404	40.6133
911.75	38.6742
915.097	35.9714
918.443	35.1688
921.787	34.7225
925.13	34.2038
928.472	34.4002
931.813	36.1119
935.15	36.633
938.488	35.8996
941.825	34.5906
945.158	32.4488
948.493	31.2219
951.824	30.2051
955.156	30.2308
958.486	28.653
961.814	27.0219
965.142	24.8895
968.467	23.1051
971.79	21.2294
975.115	19.9314
978.436	19.7051
981.756	18.4235
985.077	16.7588
988.394	14.8566
991.71	13.9886
995.025	13.753
998.341	14.2813
1001.65	14.8959
1004.97	15.9527
1008.28	17.7728
1011.58	19.7451
1014.89	19.5683
1018.2	19.2718
1021.5	18.6894
1024.81	22.4999
1028.11	25.7213
1031.41	30.6605
1034.71	33.2599
1038.01	37.3305
1041.31	40.4844
1044.6	44.0098
1047.9	47.2659
1051.19	50.4908
1054.48	54.659
1057.77	56.5346
1061.06	56.7523
1064.35	57.3516
1067.64	56.4934
1070.93	55.3383
1074.21	54.7766
1077.49	51.085
1080.78	47.5789
1084.06	42.5602
1087.34	37.1411
1090.61	34.7235
1093.89	32.4253
1097.17	32.8208
1100.44	34.3504
1103.71	35.7538
1106.99	37.4029
1110.26	38.6946
1113.52	37.6586
1116.79	37.365
1120.06	38.1914
1123.32	36.758
1126.59	34.8451
1129.85	34.7821
1133.11	32.7837
1136.37	32.1613
1139.63	29.4378
1142.89	28.4716
1146.15	26.9529
1149.4	24.1067
1152.66	20.9793
1155.91	16.6345
1159.16	12.1582
1162.41	7.79849
1165.66	4.48619
1168.91	4.49932
1172.16	5.72595
1175.4	6.04842
1178.65	5.84336
1181.89	5.68522
1185.13	4.39627
1188.37	3.6524
1191.61	3.74782
1194.85	3.78223
1198.08	3.62907
1201.32	4.45136
1204.55	5.44179
1207.79	7.81866
1211.02	10.2427
1214.25	12.6425
1217.48	16.1326
1220.71	19.2042
1223.93	22.7275
1227.16	25.4856
1230.38	28.512
1233.6	30.864
1236.83	31.6154
1240.05	32.8469
1243.26	36.3672
1246.48	37.8409
1249.7	38.3006
1252.92	38.8512
1256.13	38.5695
1259.34	42.5631
1262.55	46.101
1265.76	52.3862
1268.97	59.3762
1272.18	66.2713
1275.39	73.5317
1278.59	79.2756
1281.8	85.6993
1285	91.4664
1288.2	95.1299
1291.4	98.8829
1294.6	101.198
1297.8	103.019
1301	103.331
1304.19	103.01
1307.39	99.4865
1310.58	96.1666
1313.77	90.7858
1316.96	84.7605
1320.15	81.8894
1323.34	75.0548
1326.53	67.369
1329.72	62.0216
1332.9	56.299
1336.08	53.3059
1339.27	52.2595
1342.45	51.4631
1345.63	52.4407
1348.8	51.9504
1351.98	52.2741
1355.16	53.0816
1358.33	51.9083
1361.51	51.2221
1364.68	50.975
1367.85	51.4304
1371.02	51.6991
1374.19	52.22
1377.36	52.7594
1380.52	52.8231
1383.69	52.7766
1386.85	53.1726
1390.02	54.217
1393.18	55.2476
1396.34	55.3083
1399.5	55.7964
1402.65	58.4564
1405.81	66.0071
1408.97	76.5742
1412.12	87.6052
1415.27	99.6365
1418.43	113.917
1421.58	128.753
1424.73	143.386
1427.87	158.591
1431.02	173.294
1434.17	186.303
1437.31	197.748
1440.46	207.203
1443.6	213.775
1446.74	217.435
1449.88	218.446
1453.02	216.341
1456.16	209.609
1459.29	199.88
1462.43	187.417
1465.56	172.884
1468.69	155.294
1471.83	137.46
1474.95	119.878
1478.08	105.418
1481.21	93.3019
1484.34	82.5701
1487.47	70.5396
1490.59	59.3751
1493.71	49.5658
1496.84	43.7497
1499.96	37.9717
1503.07	32.8415
1506.19	30.236
1509.31	27.5164
1512.43	26.3003
1515.54	25.8745
1518.65	25.7993
1521.77	25.7618
1524.88	25.9322
1527.99	25.6143
1531.1	26.1383
1534.21	27.0221
1537.31	27.3355
1540.42	28.7986
1543.52	30.2991
1546.63	32.0502
1549.73	33.5208
1552.83	35.3475
1555.93	35.7835
1559.03	37.9235
1562.12	38.7168
1565.22	39.2093
1568.31	41.4604
1571.41	43.3358
1574.5	46.4381
1577.59	47.5107
1580.68	49.273
1583.77	51.1283
1586.86	52.4253
1589.95	53.5919
1593.03	54.2068
1596.11	55.2336
1599.2	54.4557
1602.28	54.8806
1605.36	55.2411
1608.44	54.5912
1611.52	53.2169
1614.6	54.365
1617.67	54.5052
1620.75	53.2193
1623.82	53.0478
1626.89	52.3854
1629.96	53.5373
1633.04	52.5198
1636.11	52.2747
1639.17	52.8131
1642.24	52.3615
1645.31	53.4863
1648.37	53.6164
1651.43	53.8032
1654.5	54.1899
1657.56	54.7884
1660.62	54.2291
1663.67	53.3481
1666.73	51.6454
1669.79	51.0936
1672.84	49.0582
1675.9	46.4165
1678.95	44.1348
1682	42.1951
1685.05	39.1933
1688.1	38.0246
1691.15	35.4186
1694.2	31.9133
1697.25	29.7904
1700.29	28.1191
1703.33	27.557
1706.38	27.2173
1709.42	25.7445
1712.46	25.4107
1715.5	24.8973
1718.54	24.8833
1721.57	25.5278
1724.61	25.3088
1727.64	26.0148
1730.68	27.1604
1733.71	26.4635
1736.74	26.9602
1739.77	27.0486
1742.8	26.8264
1745.83	26.05
1748.85	24.6162
1751.88	23.0958
1754.91	22.1275
1757.93	20.8749
1760.95	18.9688
1763.97	18.4392
1766.99	16.2968
1770.01	15.157
1773.03	14.7269
1776.04	14.2209
1779.06	13.7656
1782.07	13.5332
1785.09	12.8386
1788.1	13.4587
1791.11	12.5439
1794.12	11.9714
1797.13	11.2341
1800.13	11.15
1803.14	10.3148
1806.15	9.75091
1809.15	8.63105
1812.15	7.68287
1815.16	6.00312
1818.15	4.78541
1821.16	4.20653
1824.15	3.89927
1827.15	3.35012
1830.15	3.52116
1833.14	2.67327
1836.14	3.34653
1839.13	3.38741
1842.12	4.00601
1845.11	5.03549
1848.1	5.89444
1851.09	5.6395
1854.08	5.76164
1857.06	5.73184
1860.05	5.71855
1863.03	6.57596
1866.01	6.04539
1869	6.20086
1871.98	5.66398
1874.96	5.16066
1877.93	4.16798
1880.91	4.50723
1882.47	3.44133
1885.46	3.03937
1888.44	2.68853
1891.43	4.22208
1894.42	4.82499
1897.4	3.83013
1900.39	3.90056
1903.37	4.41658
1906.35	5.23578
1909.33	6.67356
1912.31	6.69233
1915.29	6.62755
1918.26	7.0881
1921.24	6.80318
1924.21	6.26872
1927.19	7.1922
1930.16	6.94785
1933.13	6.60201
1936.1	5.57314
1939.07	5.95145
1942.04	5.64923
1945	4.83736
1947.97	4.50694
1950.93	4.27387
1953.9	3.77836
1956.86	3.61642
1959.82	3.98946
1962.78	5.13753
1965.74	4.57178
1968.7	4.05986
1971.65	3.1071
1974.61	2.76758
1977.57	3.07856
1980.52	3.29688
1983.47	3.20831
1986.42	3.28162
1989.37	3.9396
1992.32	5.65498
1995.27	5.79527
1998.22	6.20781
2001.17	5.13063
2004.11	5.40051
2007.05	5.40519
2010	5.50897
2012.94	5.6247
2015.88	4.20212
2018.82	3.27532
2021.76	2.32503
2024.7	2.16304
2027.63	2.7081
2030.57	2.73113
2033.5	3.16157
2036.44	3.09291
2039.37	2.41407
2042.3	2.99827
2045.23	2.77532
2048.16	3.17179
2051.08	4.19971
2054.01	4.97484
2056.94	5.28675
2059.86	6.2266
2062.79	5.60983
2065.71	6.33976
2068.63	5.41786
2071.55	4.09564
2074.47	5.03353
2077.39	4.53361
2080.31	3.98332
2083.22	3.66265
2086.13	2.94769
2089.05	2.43968
2091.96	2.46928
2094.87	2.74646
2097.78	3.59547
2100.69	4.04972
2103.6	5.35571
2106.51	5.6239
2109.42	6.09911
2112.32	5.54527
2115.23	7.04439
2118.13	6.94438
2121.03	7.22979
2123.93	7.36314
2126.83	7.55918
2129.73	7.53908
2132.63	8.30874
2135.53	9.63556
2138.42	10.5472
2141.32	10.9558
2144.21	13.2357
2147.1	14.0696
2150	15.6
2152.89	17.9162
2155.78	18.456
2158.66	19.8427
2161.55	20.6825
2164.44	22.2753
2167.32	23.0631
2170.21	24.2213
2173.09	24.962
2175.97	25.9413
2178.85	25.3308
2181.73	23.7346
2184.61	23.3225
2187.49	22.5741
2190.37	20.9716
2193.24	19.9521
2196.12	18.8314
2198.99	18.7063
2201.87	17.1061
2204.74	16.0439
2207.61	13.829
2210.48	13.4381
2213.35	12.6243
2216.21	11.7887
2219.08	11.5894
2221.95	11.7629
2224.81	10.7519
2227.67	9.62673
2230.54	8.58228
2233.4	8.08551
2236.26	8.52076
2239.11	8.55837
2241.97	9.00803
2244.83	9.17242
2247.69	8.45484
2250.54	8.43708
2253.4	7.82343
2256.25	8.40403
2259.1	8.31387
2261.95	8.44711
2264.8	8.19521
2267.65	6.66004
2270.5	5.80797
2273.34	5.30702
2276.19	4.81764
2279.03	5.32105
2281.88	6.01369
2284.72	5.19868
2287.56	5.1025
2290.4	4.29002
2293.24	3.26799
2296.08	2.32101
2298.92	3.4625
2301.76	3.37007
2304.59	4.53932
2307.43	4.29377
2310.26	4.78199
2313.09	4.62876
2315.92	4.46652
2318.75	4.97491
2321.58	4.6786
2324.41	4.63389
2327.24	4.67278
2330.06	5.3249
2332.89	5.4163
2335.71	5.13906
2338.54	4.45327
2341.36	5.04044
2344.18	3.99338
2347	4.02299
2349.82	3.75934
2352.64	2.11434
2355.45	1.49076
2358.27	1.83751
2361.08	1.10945
2363.9	1.57459
2366.71	3.2627
2369.52	4.02744
2372.33	4.42894
2375.14	5.19183
2377.95	5.56795
2380.76	5.87706
2383.57	6.5197
2386.37	6.44689
2389.18	6.88582
2391.98	7.19757
2394.79	7.87925
2397.59	8.88262
2400.39	8.74652
2403.19	8.92896
2405.99	8.53709
2408.78	8.07377
2411.58	8.88111
2414.38	8.75053
2417.17	8.02626
2419.97	7.92522
2422.76	6.96953
2425.55	6.86709
2428.34	5.45126
2431.13	4.47331
2433.92	3.64655
2436.71	3.92033
2439.49	3.70028
2442.28	3.65856
2445.06	4.85319
2447.85	4.92432
2450.63	4.6585
2453.41	4.44799
2456.19	5.23498
2458.97	5.16827
2461.75	4.29797
2464.53	3.73213
2467.31	3.70522
2470.08	3.64027
2472.86	3.38423
2475.63	4.20643
2478.4	4.97305
2481.17	4.7728
2483.94	4.68779
2486.72	4.41585
2489.48	3.75931
2492.25	3.06891
2495.02	3.33067
2497.79	3.27364
2500.55	3.01097
2503.31	4.27014
2506.08	5.59741
2508.84	6.09756
2511.6	7.46155
2514.36	9.1034
2517.12	9.03616
2519.88	9.21459
2522.63	9.43215
2525.39	9.68737
2528.14	8.79294
2530.9	8.07687
2533.65	8.37561
2536.4	8.51311
2539.15	8.12503
2541.9	8.41097
2544.65	9.47878
2547.4	9.7658
2550.15	10.6223
2552.89	11.3366
2555.64	12.3061
2558.38	12.8172
2561.12	13.4303
2563.87	13.739
2566.61	14.7386
2569.35	15.9657
2572.09	17.2041
2574.83	17.6361
2577.56	17.1645
2580.3	17.9843
2583.04	17.6049
2585.77	16.9241
2588.5	15.1618
2591.23	13.8528
2593.97	13.0889
2596.7	11.7335
2599.43	10.6098
2602.15	9.61549
2604.88	8.2724
2607.61	8.05742
2610.33	8.41367
2613.06	8.44038
2615.78	8.35477
2618.51	8.84048
2621.23	8.92362
2623.95	9.13471
2626.67	10.0167
2629.39	10.7586
2632.1	11.3262
2634.82	12.5048
2637.54	12.7006
2640.25	13.7433
2642.97	13.2922
2645.68	14.5333
2648.39	16.0132
2651.1	15.8538
2653.81	16.6311
2656.52	16.9675
2659.23	17.219
2661.94	16.927
2664.64	16.932
2667.35	16.8409
2670.05	16.4887
2672.76	17.8057
2675.46	17.4469
2678.16	17.661
2680.86	17.7174
2683.56	17.9538
2686.26	18.2621
2688.96	19.4131
2691.65	21.0575
2694.35	21.3242
2697.04	22.6532
2699.74	24.4613
2702.43	27.4277
2705.12	30.2844
2707.81	33.5861
2710.5	36.7592
2713.19	40.0882
2715.88	42.7713
2718.57	43.3814
2721.25	44.6778
2723.94	43.9692
2726.62	43.8955
2729.3	41.8821
2731.99	39.7766
2734.67	37.4722
2737.35	34.3452
2740.03	30.3074
2742.71	26.3436
2745.38	21.4479
2748.06	17.8088
2750.74	14.229
2753.41	10.2222
2756.09	6.89104
2758.76	3.73677
2761.43	1.8128
2764.1	0.709294
2766.77	0.134018
2769.44	-0.328528
2772.11	-0.777368
2774.77	-0.599073
2777.44	-0.080688
2780.11	-1.09503
2782.77	-1.3353
2785.43	-0.987669
2788.1	-0.906144
2790.76	-0.866167
2793.42	-0.867014
2796.08	-0.720759
2798.74	-1.2369
2801.4	-3.28312
2804.05	-5.89115
2806.71	-10.4312
2809.36	-14.6009
2812.02	-15.5652
2814.67	-9.02895
2817.32	4.04545
2819.97	24.5947
2822.62	52.7593
2825.27	85.2899
2827.92	120.182
2830.57	156.731
2833.22	194.149
2835.86	230.652
2838.51	266.917
2841.15	299.445
2843.79	327.172
2846.43	351.115
2849.08	381.195
2851.72	414.72
2854.36	450.083
2856.99	482.567
2859.63	511.544
2862.27	531.939
2864.9	546.28
2867.54	555.359
2870.17	559.223
2872.8	561.535
2875.43	563.906
2878.07	568.729
2880.7	574.902
2883.32	579.473
2885.95	581.21
2888.58	579.653
2891.21	574.761
2893.83	564.977
2896.46	551.095
2899.08	534.985
2901.7	516.896
2904.32	497.399
2906.94	478.535
2909.56	465.651
2912.18	462.179
2914.8	467.374
2917.42	470.737
2920.03	468.433
2922.65	463.541
2925.26	455.686
2927.88	445.107
2930.49	433.332
2933.1	420.757
2935.71	405.372
2938.32	390.046
2940.93	372.593
2943.54	353.303
2946.14	332.166
2948.75	311.099
2951.35	289.072
2953.96	267.579
2956.56	246.004
2959.16	224.174
2961.77	202.487
2964.37	184.82
2966.96	168.827
2969.56	154.43
2972.16	141.436
2974.76	129.283
2977.35	116.85
2979.95	104.924
2982.54	91.7277
2985.14	79.9077
2987.73	69.1294
2990.32	58.1989
2992.91	47.7821
2995.5	40.0897
2998.09	33.0248
3000.68	26.8476
3003.26	20.7143
3005.85	15.7095
3008.43	12.1038
3011.02	9.77942
3013.6	7.15561
3016.19	6.04088
3018.77	4.41091
3021.35	3.55383
3023.93	1.95169
3026.5	1.32249
3029.08	0.934927
3031.66	0.278819
3034.24	-0.524649
3036.81	0.295767
3039.39	0.404662
3041.96	1.46937
3044.53	2.3588
3047.1	4.52586
3049.67	5.9464
3052.24	7.76578
3054.81	9.68989
3057.38	11.337
3059.95	13.2149
3062.52	14.4066
3065.08	15.88
3067.65	17.4404
3070.21	19.9584
3072.77	21.7531
3075.33	23.0293
3077.89	24.9558
3080.45	25.2281
3083.01	26.5982
3085.57	28.0018
3088.13	29.5616
3090.68	30.9713
3093.24	32.6103
3095.79	35.2919
3098.35	37.4256
3100.9	39.8203
3103.45	42.1707
3106	44.9779
3108.55	48.0011
3111.1	51.7227
3113.65	54.899
3116.2	58.0571
3118.75	61.6469
3121.29	65.6307
3123.84	69.7525
3126.38	73.8379
3128.92	78.16
3131.47	82.863
3134.01	87.5785
3136.55	92.9622
3139.09	98.9159
3141.63	105.182
3144.17	112.138
3146.7	119.458
3149.24	127.016