File: data/Raman/poly_smoothed/Mb_20_23_28_1x_45s_532 nm_x100_100%_600 gr_mm_01.txt
#Acq. time (s)=	45
#Accumulations=	2
#Range (cm-¹)=	200...3150
#Windows=	2
#Auto scanning=	Off
#Autofocus=	Off
#Macrospot=	Off
#AutoExposure=	Off
#Spike filter=	Multiple accum.
#Delay time (s)=	0
#Binning=	1
#Readout mode=	Signal
#DeNoise=	Off
#ICS correction=	On
#Dark correction=	Off
#Inst. Process=	Off
#Detector Gain=	Best Dynamic Range
#Detector ADC=	20 kHz
#Detector temperature (°C)=	-69.85
#Instrument=	LabRAM HR Evol
#Detector=	Synapse
#Objective=	x100
#Grating=	600 gr/mm
#ND Filter=	100%
#Laser (nm)=	532
#Hole=	100.021
#Range=	Auto
#Laser Pol.=	No
#Raman. Pol.=	No
#Laser Pol. (°)=	-0.0007625
#Raman Pol. (°)=	89.9995
#Collection=	Microscope
#StageXY=	Marzhauser
#StageZ=	Marzhauser
#X (µm)=	-6945.4
#Y (µm)=	2013.7
#Z (µm)=	-74.8
#Full time(mm:ss)=	3:18
#Project=
#Sample=
#Site=
#Title=	Mb_20_23_28_2x_45s_532 nm_x100_100%_600 gr_mm
#Remark=
#Date=	13.07.2022 15:20
#Acquired=	13.07.2022 15:20:31
#Base:Fit=	10.08.2022 10:29:37
#Edit:Spike=	10.08.2022 10:33:06
#Edit:Spike=	10.08.2022 10:33:07
#Edit:Spike=	10.08.2022 10:33:26
#Edit:Spike=	10.08.2022 10:33:27
#Edit:Spike=	10.08.2022 10:33:28
#Edit:Spike=	10.08.2022 10:33:31
#Edit:Spike=	10.08.2022 10:33:31
#Edit:Spike=	10.08.2022 10:33:32
#Base:Sub=	10.08.2022 10:33:46
#Filter:Polynom=	16.08.2022 10:13:29
#AxisType[0]=Intens
#AxisUnit[0]=Cnt
#AxisType[1]=Spectr
#AxisUnit[1]=1/cm
200.563	38.4253
204.194	30.7202
207.821	23.8501
211.449	19.1722
215.074	15.669
218.699	12.2183
222.321	10.9075
225.941	12.4675
229.562	12.4477
233.18	12.4316
236.796	13.8436
240.411	15.6915
244.026	16.2652
247.638	17.2428
251.248	17.1935
254.857	19.1821
258.465	19.3654
262.071	16.9935
265.678	17.4947
269.282	17.9865
272.884	15.5145
276.484	10.9109
280.084	8.38366
283.682	6.38527
287.276	4.64416
290.871	1.66453
294.465	2.67156
298.057	4.20626
301.648	5.09181
305.237	7.09293
308.823	11.6295
312.41	15.3291
315.995	18.7289
319.579	19.6886
323.16	23.6884
326.741	27.3048
330.321	29.4536
333.897	32.0547
337.474	33.1956
341.048	37.213
344.622	38.2551
348.192	38.6685
351.764	39.4311
355.332	39.3803
358.901	37.0628
362.466	34.0909
366.03	31.7485
369.594	29.6905
373.155	25.4768
376.715	25.6247
380.273	26.4791
383.832	27.4431
387.388	29.9161
390.942	31.2736
394.495	31.6088
398.047	30.9769
401.597	30.4879
405.145	32.249
408.693	33.0099
412.239	33.8359
415.783	34.8522
419.327	32.8611
422.869	34.2077
426.409	34.2434
429.948	34.47
433.486	32.4038
437.022	32.2361
440.558	29.5762
444.089	29.7896
447.622	29.4581
451.153	29.1492
454.682	29.4768
458.208	30.32
461.735	34.2581
465.259	37.8139
468.783	39.4835
472.306	43.828
475.825	48.2891
479.346	50.2191
482.862	52.3041
486.38	55.5286
489.894	60.5181
493.407	62.358
496.92	63.6137
500.43	65.3175
503.939	64.841
507.448	66.1165
510.954	67.1277
514.459	65.9207
517.962	64.5775
521.466	64.6732
524.966	63.861
528.466	64.1454
531.964	64.1019
535.46	63.6396
538.955	61.7505
542.449	59.5541
545.942	59.1667
549.433	57.4754
552.923	53.2878
556.412	51.982
559.899	48.8792
563.385	44.0825
566.867	40.8713
570.35	36.1548
573.832	32.8139
577.313	29.7403
580.79	26.688
584.268	23.1847
587.745	19.8697
591.218	16.2331
594.692	14.8685
598.164	9.29565
601.634	9.2057
605.104	9.25702
608.57	9.43573
612.037	9.77736
615.501	9.18935
618.966	10.3521
622.427	11.9678
625.887	12.1774
629.348	16.7221
632.806	19.6838
636.262	20.1601
639.716	19.8197
643.172	19.7402
646.624	18.6191
650.075	18.2807
653.524	17.314
656.972	15.9844
660.419	16.1326
663.865	14.5519
667.309	11.6688
670.752	7.19788
674.194	6.64187
677.634	4.81236
681.073	4.53175
684.511	3.04642
687.947	6.90999
691.382	5.52589
694.816	8.93873
698.247	9.12502
701.678	13.2394
705.108	15.4325
708.534	16.6416
711.962	18.1986
715.388	21.254
718.81	22.8801
722.234	23.1341
725.654	23.673
729.075	24.6101
732.492	24.3062
735.91	25.2461
739.325	23.9343
742.741	25.6071
746.153	27.896
749.564	27.0249
752.976	29.4242
756.385	31.6731
759.792	34.7367
763.2	35.3224
766.604	38.1679
770.008	39.6614
773.41	41.0559
776.811	42.3064
780.21	44.9186
783.608	45.1602
787.005	46.8614
790.401	48.0617
793.795	49.9472
797.188	50.9886
800.58	53.5455
803.971	56.2251
807.36	58.0076
810.748	57.0443
814.135	58.0548
817.518	59.1229
820.902	60.7133
824.285	62.3724
827.665	62.746
831.045	63.5568
834.424	62.8494
837.8	64.6704
841.177	62.2711
844.55	59.8883
847.924	57.7549
851.295	55.0297
854.666	51.4775
858.034	52.3438
861.403	51.4931
864.769	49.9519
868.133	48.0729
871.498	49.4352
874.86	45.8039
878.221	45.9945
881.58	44.0452
884.938	45.4102
888.297	46.8169
891.653	47.8715
895.007	48.2837
898.36	49.567
901.712	52.8501
905.063	52.3037
908.412	51.7077
911.76	52.4425
915.107	52.3501
918.452	50.8834
921.797	49.7414
925.138	47.5911
928.48	44.972
931.82	42.882
935.16	40.2324
938.496	38.4126
941.833	33.1267
945.168	27.3499
948.5	23.0915
951.834	19.8863
955.163	16.0232
958.494	10.4243
961.821	6.4469
965.15	7.50545
968.474	12.5312
971.8	15.2961
975.123	18.5922
978.446	21.3385
981.766	24.0498
985.084	26.9062
988.402	27.2885
991.72	26.5244
995.035	27.1977
998.349	28.9647
1001.66	26.735
1004.97	27.8638
1008.28	31.0065
1011.59	34.5513
1014.9	42.4132
1018.21	49.1392
1021.51	54.6429
1024.81	63.0614
1028.12	71.8159
1031.42	80.807
1034.72	87.0835
1038.02	91.7756
1041.31	96.7082
1044.61	105.251
1047.91	114.021
1051.2	116.776
1054.49	118.319
1057.78	116.291
1061.07	113.066
1064.36	111.159
1067.65	105.647
1070.93	97.7027
1074.22	91.1805
1077.5	85.6777
1080.78	76.8324
1084.06	71.2137
1087.34	68.6915
1090.62	68.082
1093.9	71.0874
1097.17	71.6925
1100.45	73.9109
1103.72	74.1909
1106.99	75.6662
1110.27	74.0322
1113.53	72.9426
1116.8	71.0388
1120.07	69.3409
1123.33	66.9198
1126.6	62.3656
1129.86	59.8755
1133.12	56.387
1136.38	51.3047
1139.64	46.7198
1142.9	43.8937
1146.16	39.2375
1149.41	33.5056
1152.67	28.3251
1155.92	20.5251
1159.17	15.0206
1162.42	10.3726
1165.67	7.24589
1168.92	6.02667
1172.16	8.58296
1175.41	11.8251
1178.65	11.0234
1181.9	10.237
1185.14	9.09727
1188.38	10.043
1191.62	11.6238
1194.86	13.6676
1198.09	17.7083
1201.33	18.9428
1204.56	22.5481
1207.8	27.7574
1211.03	34.4484
1214.26	41.7143
1217.49	50.5941
1220.71	59.8117
1223.94	66.8908
1227.16	74.0598
1230.39	83.2867
1233.61	89.0619
1236.83	98.3295
1240.05	106.601
1243.27	113.49
1246.49	122.087
1249.71	128.662
1252.92	135.961
1256.14	139.046
1259.35	143.992
1262.56	148.091
1265.77	154.892
1268.98	163.353
1272.19	171.387
1275.4	178.431
1278.6	185.807
1281.81	191.484
1285.01	198.594
1288.21	205.905
1291.41	211.859
1294.61	219.904
1297.81	223.98
1301.01	227.491
1304.2	230.384
1307.4	233.724
1310.59	235.673
1313.78	231.605
1316.97	229.34
1320.16	225.949
1323.35	220.627
1326.54	213.171
1329.72	206.511
1332.91	199.104
1336.09	195.274
1339.27	189.68
1342.45	185.697
1345.64	182.559
1348.81	178.685
1351.99	175.733
1355.17	172.305
1358.34	167.94
1361.51	163.941
1364.69	161.874
1367.86	158.793
1371.03	156.72
1374.2	156.821
1377.37	157.272
1380.53	158.024
1383.7	157.928
1386.86	158.536
1390.02	157.446
1393.19	155.71
1396.35	154.339
1399.51	154.421
1402.66	156.804
1405.82	164.527
1408.97	174.172
1412.13	189.475
1415.28	206.584
1418.43	224.594
1421.59	246.994
1424.73	270.021
1427.88	293.494
1431.03	316.374
1434.18	337.417
1437.32	354.518
1440.46	370.206
1443.61	380.862
1446.75	385.765
1449.89	389.313
1453.03	386.297
1456.16	377.724
1459.3	365.498
1462.44	348.063
1465.57	324.742
1468.7	299.307
1471.83	275.471
1474.96	248.63
1478.09	225.029
1481.22	202.261
1484.35	182.06
1487.47	161.099
1490.6	144.297
1493.72	130.037
1496.84	118.594
1499.96	110.723
1503.08	98.4464
1506.2	89.5602
1509.32	82.1471
1512.44	74.474
1515.55	68.4795
1518.66	62.5139
1521.78	59.591
1524.89	57.8912
1528	57.4163
1531.11	58.3303
1534.21	60.4996
1537.32	63.4414
1540.43	65.5625
1543.53	68.822
1546.63	74.1145
1549.74	78.5702
1552.84	83.1962
1555.94	90.0016
1559.03	94.2155
1562.13	96.7125
1565.23	101.52
1568.32	108.889
1571.42	115.743
1574.51	121.459
1577.6	125.996
1580.69	131.095
1583.78	135.79
1586.87	140.721
1589.95	144.639
1593.04	149.088
1596.12	150.948
1599.21	152.38
1602.29	152.787
1605.37	154.55
1608.45	154.771
1611.53	155.509
1614.6	157.113
1617.68	154.768
1620.75	157.512
1623.83	161.088
1626.9	163.484
1629.97	169.114
1633.04	173.561
1636.11	178.964
1639.18	185.678
1642.25	193.91
1645.31	200.06
1648.38	206.511
1651.44	211.057
1654.5	211.365
1657.56	212.698
1660.62	211.437
1663.68	206.634
1666.74	198.637
1669.8	190.791
1672.85	179.288
1675.91	167.166
1678.96	154.214
1682.01	142.835
1685.06	128.727
1688.11	116.099
1691.16	102.806
1694.21	93.3519
1697.25	84.7701
1700.3	77.179
1703.34	70.2873
1706.39	64.966
1709.43	58.6467
1712.47	53.1174
1715.51	50.5067
1718.54	46.4195
1721.58	43.4295
1724.62	40.8782
1727.65	38.0805
1730.68	35.0615
1733.72	33.8639
1736.75	32.1458
1739.78	28.3295
1742.81	26.0727
1745.84	24.3598
1748.86	22.1062
1751.89	20.8027
1754.91	19.3795
1757.93	17.4876
1760.96	15.0727
1763.98	14.1407
1767	13.7059
1770.02	12.9512
1773.03	11.1909
1776.05	9.07768
1779.07	8.07247
1782.08	7.43082
1785.09	6.17639
1788.11	5.67359
1791.12	4.66022
1794.13	4.67417
1797.13	4.87255
1800.14	3.47441
1803.15	3.53507
1806.15	3.69044
1809.16	3.68611
1812.16	3.29147
1815.16	2.60612
1818.16	3.48609
1821.16	3.72777
1824.16	3.10164
1827.16	3.39906
1830.16	1.92377
1833.15	1.76266
1836.14	1.69875
1839.14	1.91948
1842.13	1.47991
1845.12	1.31207
1848.11	0.857926
1851.1	0.266166
1854.08	-0.68543
1857.07	-1.2705
1860.05	-1.69002
1863.04	-1.36177
1866.02	-0.28225
1869	1.29473
1871.98	1.66892
1874.96	3.70324
1877.94	5.41449
1880.92	6.93068
1882.51	7.42438
1885.5	7.83669
1888.48	8.47948
1891.47	8.29696
1894.46	8.87335
1897.44	7.82894
1900.42	9.1074
1903.41	10.0908
1906.39	9.76039
1909.37	10.2456
1912.35	10.449
1915.32	10.2425
1918.3	10.167
1921.27	8.83612
1924.25	7.89866
1927.22	9.33323
1930.19	8.74667
1933.17	8.36992
1936.14	7.50746
1939.11	7.8348
1942.07	7.37295
1945.04	8.39567
1948.01	7.47454
1950.97	8.49303
1953.93	7.05796
1956.9	5.39499
1959.86	4.60494
1962.82	3.70056
1965.78	2.94479
1968.74	2.70777
1971.69	2.97253
1974.65	3.22537
1977.6	1.96533
1980.56	2.92589
1983.51	3.79631
1986.46	3.20648
1989.41	4.25684
1992.36	4.22531
1995.31	4.02991
1998.26	5.29083
2001.2	6.18456
2004.15	5.09312
2007.09	4.87908
2010.04	5.22038
2012.98	6.30192
2015.92	8.28273
2018.86	9.25226
2021.8	10.4718
2024.73	10.9897
2027.67	11.0784
2030.61	11.8492
2033.54	12.7941
2036.47	13.0661
2039.4	14.4732
2042.33	14.7302
2045.27	15.1696
2048.19	14.9848
2051.12	16.8558
2054.05	16.9346
2056.97	15.6231
2059.9	15.2717
2062.82	15.8492
2065.74	15.3205
2068.67	15.6572
2071.59	16.6376
2074.51	15.4543
2077.42	15.5921
2080.34	17.061
2083.26	20.3019
2086.17	21.9714
2089.09	24.9774
2092	25.473
2094.91	27.897
2097.82	29.7086
2100.73	29.9721
2103.64	32.1183
2106.55	32.0026
2109.45	33.7254
2112.36	35.2413
2115.26	37.1634
2118.17	40.838
2121.07	43.9478
2123.97	47.7171
2126.87	50.562
2129.77	52.4817
2132.67	56.5816
2135.56	60.8113
2138.46	66.5149
2141.35	70.6601
2144.25	74.8226
2147.14	80.9419
2150.03	87.0955
2152.92	92.9911
2155.81	99.6938
2158.7	105.046
2161.59	109.837
2164.47	112.586
2167.36	117.023
2170.24	119.315
2173.13	121.111
2176.01	121.965
2178.89	120.22
2181.77	119.769
2184.65	119.299
2187.53	117.807
2190.4	113.151
2193.28	108.016
2196.16	102.836
2199.03	96.2035
2201.9	91.406
2204.77	86.6334
2207.64	80.5547
2210.51	73.5727
2213.38	66.0962
2216.25	60.8381
2219.12	56.3922
2221.98	51.1045
2224.85	47.3276
2227.71	43.1658
2230.57	41.0691
2233.43	37.4559
2236.29	35.9427
2239.15	35.1337
2242.01	32.2484
2244.87	29.6926
2247.72	27.8399
2250.58	26.7821
2253.43	25.6753
2256.29	23.5544
2259.14	21.6581
2261.99	19.1621
2264.84	17.0071
2267.69	17.1475
2270.53	16.0751
2273.38	14.5869
2276.23	13.2903
2279.07	11.6194
2281.91	10.4501
2284.76	8.87711
2287.6	8.07592
2290.44	5.96602
2293.28	5.30215
2296.12	5.1992
2298.96	6.82506
2301.79	7.29622
2304.63	8.23039
2307.46	8.05146
2310.3	8.11542
2313.13	7.8234
2315.96	8.5245
2318.79	8.87399
2321.62	7.96081
2324.45	6.82973
2327.27	5.99502
2330.1	6.93713
2332.92	5.35547
2335.75	4.43254
2338.57	4.11231
2341.39	3.17701
2344.21	2.10969
2347.04	1.34076
2349.85	1.10139
2352.67	-1.20371
2355.49	-2.60911
2358.3	-2.31262
2361.12	-2.28358
2363.93	-0.128647
2366.75	0.903676
2369.56	1.6898
2372.37	2.33168
2375.18	2.96573
2377.99	3.02471
2380.8	2.39086
2383.6	3.27064
2386.41	2.52222
2389.21	3.78727
2392.02	3.54669
2394.82	2.33549
2397.62	2.63402
2400.42	2.72909
2403.22	2.14889
2406.02	1.09637
2408.82	2.34366
2411.62	3.5671
2414.41	4.5367
2417.21	4.34753
2420	4.36419
2422.79	4.42437
2425.59	5.68757
2428.38	5.10609
2431.17	5.8296
2433.95	6.20791
2436.74	6.72884
2439.53	7.44469
2442.31	7.02313
2445.1	6.65307
2447.88	5.81155
2450.67	5.70678
2453.45	6.36453
2456.23	6.06123
2459.01	3.93826
2461.79	3.16821
2464.57	2.15488
2467.34	2.67584
2470.12	2.02785
2472.89	1.17131
2475.67	1.35872
2478.44	1.88169
2481.21	2.31612
2483.98	0.992067
2486.75	-0.0986214
2489.52	-0.144809
2492.29	-0.440447
2495.05	1.05123
2497.82	2.11256
2500.58	2.76582
2503.35	4.15336
2506.11	4.33163
2508.87	4.27252
2511.63	3.9965
2514.39	4.62096
2517.15	4.49124
2519.91	5.27972
2522.67	5.41774
2525.42	5.68759
2528.18	6.2468
2530.93	6.94899
2533.69	6.62659
2536.44	6.45406
2539.19	6.56117
2541.94	7.50501
2544.69	7.82967
2547.44	8.94324
2550.18	8.66856
2552.93	9.91366
2555.67	10.5151
2558.42	11.5511
2561.16	12.8207
2563.9	12.8514
2566.64	13.204
2569.38	12.7544
2572.12	12.1517
2574.86	11.3327
2577.6	10.6394
2580.33	10.8262
2583.07	9.5154
2585.8	9.69899
2588.54	8.99273
2591.27	10.0138
2594	9.91141
2596.73	9.46293
2599.46	9.45184
2602.19	9.82675
2604.92	11.093
2607.64	11.6593
2610.37	12.1681
2613.09	11.3762
2615.82	11.3989
2618.54	11.5051
2621.26	11.982
2623.98	11.927
2626.7	11.8821
2629.42	11.3119
2632.14	10.7443
2634.86	10.9383
2637.57	11.2093
2640.29	11.1578
2643	11.0021
2645.71	10.3064
2648.43	10.3724
2651.14	10.1995
2653.85	11.8151
2656.56	12.6729
2659.26	13.782
2661.97	14.0438
2664.68	14.4309
2667.38	15.8998
2670.09	16.9711
2672.79	16.2244
2675.49	15.0668
2678.19	16.0036
2680.89	16.2726
2683.59	16.4292
2686.29	17.379
2688.99	17.2049
2691.69	16.2115
2694.38	16.2126
2697.08	18.4153
2699.77	20.5736
2702.46	22.589
2705.15	25.4001
2707.85	27.3419
2710.54	30.5067
2713.22	33.5907
2715.91	36.3191
2718.6	36.5941
2721.29	38.5831
2723.97	40.8868
2726.66	40.9752
2729.34	41.2845
2732.02	41.0344
2734.7	39.3019
2737.38	36.837
2740.06	35.5196
2742.74	33.4659
2745.42	31.4528
2748.09	26.5512
2750.77	21.939
2753.45	18.6853
2756.12	15.1536
2758.79	11.8469
2761.46	9.89495
2764.14	7.75145
2766.8	5.41815
2769.47	3.97822
2772.14	2.74388
2774.81	1.71132
2777.48	1.11349
2780.14	-0.594963
2782.8	-1.99976
2785.47	-1.70138
2788.13	0.29355
2790.79	0.957203
2793.45	1.76157
2796.11	2.25774
2798.77	2.81815
2801.43	2.42372
2804.09	2.56154
2806.74	2.28758
2809.4	0.233089
2812.05	-1.16164
2814.71	0.686993
2817.36	8.7324
2820.01	20.3475
2822.66	38.5473
2825.31	61.0803
2827.96	86.3276
2830.6	112.927
2833.25	141.989
2835.9	175.426
2838.54	208.41
2841.18	241.754
2843.83	275.737
2846.47	310.34
2849.11	348.966
2851.75	388.478
2854.39	431.199
2857.03	472.187
2859.66	510.415
2862.3	545.077
2864.94	576.086
2867.57	603.765
2870.2	624.795
2872.84	643.203
2875.47	660.036
2878.1	678.824
2880.73	695.728
2883.36	712.378
2885.99	728.381
2888.61	744.573
2891.24	754.332
2893.86	766.047
2896.49	776.909
2899.11	790.144
2901.73	803.167
2904.36	816.135
2906.98	834.367
2909.6	856.415
2912.21	881.518
2914.83	910.651
2917.45	939.508
2920.07	963.443
2922.68	983.264
2925.29	996.966
2927.91	1005.37
2930.52	1005.89
2933.13	1000.4
2935.74	988.819
2938.35	971.072
2940.96	946.659
2943.57	917.674
2946.18	884.319
2948.78	847.789
2951.39	808.491
2953.99	766.977
2956.59	725.26
2959.2	684.451
2961.8	644.094
2964.4	605.379
2967	566.893
2969.6	531.645
2972.19	499.942
2974.79	467.846
2977.39	436.517
2979.98	405.498
2982.58	373.664
2985.17	341.773
2987.76	310.373
2990.35	279.223
2992.94	248.21
2995.53	216.92
2998.12	189.253
3000.71	163.484
3003.3	137.446
3005.88	116.331
3008.47	97.1226
3011.05	79.1169
3013.64	64.1065
3016.22	49.3828
3018.8	38.6401
3021.38	29.5764
3023.96	21.406
3026.54	15.0008
3029.12	9.84598
3031.69	6.40133
3034.27	4.00212
3036.84	3.18333
3039.42	3.38905
3041.99	4.03321
3044.57	5.9459
3047.14	6.61464
3049.71	8.08178
3052.28	9.80216
3054.85	10.7181
3057.41	10.3743
3059.98	10.9951
3062.55	10.5157
3065.11	9.93255
3067.68	9.89054
3070.24	8.89849
3072.8	6.82399
3075.36	5.9504
3077.93	3.70309
3080.49	3.07416
3083.04	2.64044
3085.6	1.81286
3088.16	1.44061
3090.72	2.53589
3093.27	4.031
3095.83	5.66125
3098.38	8.20855
3100.93	11.125
3103.49	15.6389
3106.04	19.5694
3108.59	23.79
3111.14	28.0622
3113.69	33.1263
3116.23	37.5124
3118.78	41.8998
3121.33	46.7173
3123.87	51.8417
3126.41	56.7011
3128.96	61.3703
3131.5	65.6339
3134.04	69.2315
3136.58	74.6404
3139.12	79.7666
3141.66	84.3497
3144.2	88.884
3146.74	92.7773
3149.27	95.9314