File: data/Raman/poly_smoothed/Mb_20_23_23_1x_45s_532 nm_x100_100%_600 gr_mm_01.txt
#Acq. time (s)=	45
#Accumulations=	2
#Range (cm-¹)=	200...3150
#Windows=	2
#Auto scanning=	Off
#Autofocus=	Off
#Macrospot=	Off
#AutoExposure=	Off
#Spike filter=	Multiple accum.
#Delay time (s)=	0
#Binning=	1
#Readout mode=	Signal
#DeNoise=	Off
#ICS correction=	On
#Dark correction=	Off
#Inst. Process=	Off
#Detector Gain=	Best Dynamic Range
#Detector ADC=	20 kHz
#Detector temperature (°C)=	-69.85
#Instrument=	LabRAM HR Evol
#Detector=	Synapse
#Objective=	x100
#Grating=	600 gr/mm
#ND Filter=	100%
#Laser (nm)=	532
#Hole=	100.021
#Range=	Auto
#Laser Pol.=	No
#Raman. Pol.=	No
#Laser Pol. (°)=	-0.0007625
#Raman Pol. (°)=	89.9995
#Collection=	Microscope
#StageXY=	Marzhauser
#StageZ=	Marzhauser
#X (µm)=	-6965.7
#Y (µm)=	2053.4
#Z (µm)=	-74.3
#Full time(mm:ss)=	3:05
#Project=
#Sample=
#Site=
#Title=	Mb_20_23_23_2x_45s_532 nm_x100_100%_600 gr_mm
#Remark=
#Date=	13.07.2022 14:58
#Acquired=	13.07.2022 14:58:38
#Base:Fit=	10.08.2022 10:29:37
#Edit:Spike=	10.08.2022 10:33:16
#Base:Sub=	10.08.2022 10:33:46
#Filter:Polynom=	16.08.2022 10:13:29
#AxisType[0]=Intens
#AxisUnit[0]=Cnt
#AxisType[1]=Spectr
#AxisUnit[1]=1/cm
200.563	37.9929
204.194	33.2222
207.821	27.5721
211.449	21.4138
215.074	17.886
218.699	15.0039
222.321	11.4909
225.941	9.9945
229.562	8.43991
233.18	8.11697
236.796	7.6624
240.411	7.90135
244.026	5.87827
247.638	5.04584
251.248	5.94855
254.857	5.28812
258.465	7.63205
262.071	9.38931
265.678	9.78861
269.282	9.57503
272.884	9.98079
276.484	7.87923
280.084	6.92683
283.682	7.33638
287.276	5.43585
290.871	4.53304
294.465	4.16701
298.057	3.521
301.648	5.35501
305.237	7.16444
308.823	8.05971
312.41	8.62663
315.995	9.5697
319.579	10.5876
323.16	10.5194
326.741	10.7053
330.321	10.7773
333.897	10.8408
337.474	12.5723
341.048	12.392
344.622	13.1576
348.192	12.0677
351.764	11.0027
355.332	8.83369
358.901	9.73735
362.466	7.39128
366.03	6.18905
369.594	4.04004
373.155	3.0796
376.715	3.91492
380.273	3.83841
383.832	3.18619
387.388	4.24482
390.942	5.55684
394.495	5.4682
398.047	5.52405
401.597	4.42325
405.145	5.34051
408.693	5.41913
412.239	5.26135
415.783	6.39931
419.327	6.95698
422.869	6.35321
426.409	7.00125
429.948	9.07869
433.486	9.01927
437.022	9.07539
440.558	10.23
444.089	10.1325
447.622	10.0766
451.153	11.6167
454.682	12.4925
458.208	13.2667
461.735	13.9795
465.259	15.2431
468.783	16.3361
472.306	17.8211
475.825	19.9928
479.346	18.946
482.862	19.0719
486.38	21.3498
489.894	21.7225
493.407	22.8326
496.92	24.618
500.43	26.2285
503.939	27.0934
507.448	27.4432
510.954	27.1927
514.459	27.4313
517.962	27.4864
521.466	25.4508
524.966	24.5292
528.466	24.6656
531.964	22.8867
535.46	21.5584
538.955	21.9346
542.449	18.7586
545.942	17.8886
549.433	16.0954
552.923	13.9334
556.412	12.6962
559.899	11.2993
563.385	9.77765
566.867	8.48851
570.35	8.70192
573.832	9.10009
577.313	11.0684
580.79	11.0696
584.268	10.5976
587.745	8.95405
591.218	7.44613
594.692	7.95293
598.164	7.59333
601.634	8.2058
605.104	7.33086
608.57	7.9042
612.037	7.95902
615.501	7.24861
618.966	7.78238
622.427	8.34556
625.887	9.83776
629.348	11.0648
632.806	9.3664
636.262	7.43338
639.716	6.69169
643.172	8.33023
646.624	8.08808
650.075	7.68947
653.524	7.48538
656.972	7.80703
660.419	7.41034
663.865	6.77673
667.309	6.42918
670.752	5.54465
674.194	4.50865
677.634	6.8927
681.073	9.51519
684.511	9.96669
687.947	11.4627
691.382	13.6641
694.816	15.9315
698.247	16.6081
701.678	18.5079
705.108	20.3163
708.534	20.1911
711.962	20.7127
715.388	20.5896
718.81	19.7348
722.234	19.3865
725.654	22.6441
729.075	22.2748
732.492	23.371
735.91	23.8146
739.325	25.3328
742.741	27.9005
746.153	32.1605
749.564	34.3284
752.976	38.546
756.385	39.3094
759.792	43.1746
763.2	47.2316
766.604	50.8759
770.008	53.501
773.41	57.5329
776.811	59.6233
780.21	62.3591
783.608	63.6576
787.005	64.7504
790.401	66.5016
793.795	69.4339
797.188	69.7737
800.58	71.0812
803.971	71.8587
807.36	73.6943
810.748	75.2822
814.135	75.5798
817.518	75.9467
820.902	77.6442
824.285	80.0598
827.665	82.5697
831.045	81.6447
834.424	79.74
837.8	78.2205
841.177	76.2646
844.55	75.6722
847.924	74.3784
851.295	72.3516
854.666	72.1104
858.034	73.8806
861.403	70.7948
864.769	70.0145
868.133	68.2212
871.498	66.2165
874.86	67.0236
878.221	64.204
881.58	61.1835
884.938	59.5157
888.297	58.906
891.653	58.6038
895.007	56.212
898.36	55.5038
901.712	55.2094
905.063	55.2958
908.412	54.3675
911.76	51.6499
915.107	48.8489
918.452	47.4011
921.797	47.2078
925.138	46.3205
928.48	42.5402
931.82	42.5357
935.16	41.0338
938.496	40.6925
941.833	37.2959
945.168	33.6917
948.5	30.9534
951.834	30.6656
955.163	28.772
958.494	28.7732
961.821	27.6089
965.15	28.1909
968.474	29.2607
971.8	30.1495
975.123	31.5528
978.446	32.5896
981.766	33.9964
985.084	34.4423
988.402	35.8948
991.72	35.5734
995.035	37.1463
998.349	38.0819
1001.66	37.235
1004.97	36.6873
1008.28	35.3517
1011.59	36.5716
1014.9	39.3644
1018.21	41.0631
1021.51	40.6419
1024.81	43.1468
1028.12	47.1827
1031.42	51.6231
1034.72	54.8359
1038.02	57.3607
1041.31	57.589
1044.61	59.7055
1047.91	63.7075
1051.2	65.5412
1054.49	65.9963
1057.78	66.831
1061.07	66.1713
1064.36	63.6469
1067.65	62.8135
1070.93	60.7574
1074.22	58.6181
1077.5	54.7807
1080.78	49.6665
1084.06	45.4095
1087.34	42.5272
1090.62	39.5549
1093.9	41.5184
1097.17	41.876
1100.45	40.2882
1103.72	40.1171
1106.99	41.7744
1110.27	40.7854
1113.53	39.8574
1116.8	37.9028
1120.07	35.4457
1123.33	33.0606
1126.6	32.9585
1129.86	32.0346
1133.12	28.9478
1136.38	25.292
1139.64	22.496
1142.9	21.521
1146.16	17.9404
1149.41	11.4635
1152.67	8.18473
1155.92	6.18602
1159.17	4.64426
1162.42	2.15029
1165.67	1.77731
1168.92	2.85622
1172.16	4.79472
1175.41	6.92662
1178.65	7.43752
1181.9	8.84397
1185.14	10.4432
1188.38	10.1834
1191.62	9.385
1194.86	10.0828
1198.09	12.0012
1201.33	11.6828
1204.56	11.3948
1207.8	12.6138
1211.03	13.4362
1214.26	15.2728
1217.49	16.4742
1220.71	17.7944
1223.94	19.7464
1227.16	19.1534
1230.39	23.7412
1233.61	26.2528
1236.83	30.4165
1240.05	32.5622
1243.27	36.2098
1246.49	38.8418
1249.71	41.6677
1252.92	43.2822
1256.14	43.9067
1259.35	49.1123
1262.56	54.1974
1265.77	57.6232
1268.98	62.7215
1272.19	72.1347
1275.4	79.8848
1278.6	86.282
1281.81	93.5778
1285.01	99.3413
1288.21	106.07
1291.41	112.261
1294.61	115.63
1297.81	117.242
1301.01	120.085
1304.2	120.048
1307.4	119.597
1310.59	115.279
1313.78	114.41
1316.97	111.357
1320.16	108.867
1323.35	102.372
1326.54	96.2684
1329.72	89.1276
1332.91	85.2764
1336.09	83.808
1339.27	81.9209
1342.45	80.4668
1345.64	78.0689
1348.81	77.3205
1351.99	78.0552
1355.17	76.7411
1358.34	75.8692
1361.51	74.0662
1364.69	74.4302
1367.86	73.8764
1371.03	74.5864
1374.2	74.3344
1377.37	74.9184
1380.53	76.5812
1383.7	76.3915
1386.86	74.8333
1390.02	76.1136
1393.19	77.2707
1396.35	77.1644
1399.51	79.092
1402.66	83.7517
1405.82	92.2164
1408.97	102.579
1412.13	113.948
1415.28	124.915
1418.43	138.634
1421.59	152.449
1424.73	166.328
1427.88	183.183
1431.03	197.392
1434.18	211.81
1437.32	224.874
1440.46	233.328
1443.61	240.385
1446.75	243.424
1449.89	243.259
1453.03	240.435
1456.16	232.258
1459.3	221.556
1462.44	207.73
1465.57	192.038
1468.7	175.261
1471.83	157.39
1474.96	141.118
1478.09	124.787
1481.22	110.264
1484.35	97.7649
1487.47	84.7354
1490.6	71.2253
1493.72	59.0659
1496.84	50.6154
1499.96	43.1241
1503.08	37.0099
1506.2	34.8102
1509.32	31.5904
1512.44	29.7689
1515.55	27.0688
1518.66	23.8653
1521.78	24.4797
1524.89	25.2853
1528	27.1566
1531.11	28.4675
1534.21	30.4858
1537.32	34.8368
1540.43	37.5898
1543.53	41.1979
1546.63	44.1844
1549.74	47.9258
1552.84	48.7945
1555.94	49.2421
1559.03	51.1185
1562.13	52.7597
1565.23	51.8187
1568.32	53.2466
1571.42	55.0378
1574.51	55.0962
1577.6	58.0062
1580.69	59.814
1583.78	62.4221
1586.87	63.8924
1589.95	65.5372
1593.04	65.1307
1596.12	68.5047
1599.21	70.3025
1602.29	71.2794
1605.37	72.8113
1608.45	73.0966
1611.53	73.8596
1614.6	72.8427
1617.68	71.9215
1620.75	70.456
1623.83	69.5506
1626.9	69.0993
1629.97	69.44
1633.04	70.9579
1636.11	72.1336
1639.18	72.2663
1642.25	73.4132
1645.31	74.7186
1648.38	74.4292
1651.44	76.1578
1654.5	75.8873
1657.56	76.3664
1660.62	75.0023
1663.68	72.6371
1666.74	70.2807
1669.8	67.3207
1672.85	63.6102
1675.91	58.2007
1678.96	54.59
1682.01	48.9705
1685.06	44.2732
1688.11	39.833
1691.16	36.1965
1694.21	32.2425
1697.25	31.3216
1700.3	29.2149
1703.34	27.467
1706.39	26.2441
1709.43	26.2076
1712.47	25.304
1715.51	25.8587
1718.54	24.9085
1721.58	24.2054
1724.62	22.7847
1727.65	21.2752
1730.68	20.8609
1733.72	20.8928
1736.75	19.5432
1739.78	18.4481
1742.81	16.3174
1745.84	15.5696
1748.86	13.9827
1751.89	12.4535
1754.91	11.5677
1757.93	11.84
1760.96	10.6192
1763.98	9.86362
1767	9.08022
1770.02	9.12714
1773.03	8.39224
1776.05	6.32551
1779.07	7.06437
1782.08	5.91545
1785.09	5.70284
1788.11	4.21553
1791.12	1.94398
1794.13	1.19945
1797.13	0.624971
1800.14	-1.58609
1803.15	-0.607555
1806.15	-0.13951
1809.16	0.238478
1812.16	-0.033663
1815.16	0.0346786
1818.16	2.16919
1821.16	1.5713
1824.16	3.46127
1827.16	4.1686
1830.16	4.61386
1833.15	5.15118
1836.14	4.50615
1839.14	5.13109
1842.13	6.40617
1845.12	6.81552
1848.11	6.54628
1851.1	6.5923
1854.08	5.86805
1857.07	5.27794
1860.05	5.38244
1863.04	6.02178
1866.02	6.74616
1869	6.90551
1871.98	8.02679
1874.96	8.43787
1877.94	8.2694
1880.92	8.42859
1882.51	7.89203
1885.5	7.58605
1888.48	7.98836
1891.47	6.72094
1894.46	5.53912
1897.44	5.32171
1900.42	4.54766
1903.41	5.20614
1906.39	3.2021
1909.37	4.6326
1912.35	4.88737
1915.32	5.99465
1918.3	6.24678
1921.27	5.53966
1924.25	6.13998
1927.22	7.33204
1930.19	8.49294
1933.17	9.00093
1936.14	11.0431
1939.11	10.7056
1942.07	12.665
1945.04	12.4584
1948.01	10.7794
1950.97	10.6044
1953.93	10.8374
1956.9	10.0182
1959.86	10.0154
1962.82	8.77635
1965.78	7.98589
1968.74	7.59973
1971.69	7.84028
1974.65	8.37382
1977.6	8.5644
1980.56	8.16619
1983.51	8.77451
1986.46	7.7247
1989.41	8.03106
1992.36	8.43743
1995.31	8.771
1998.26	10.4304
2001.2	10.0848
2004.15	9.20799
2007.09	9.46618
2010.04	9.87635
2012.98	9.54574
2015.92	9.28948
2018.86	8.22161
2021.8	7.89067
2024.73	8.68297
2027.67	8.06345
2030.61	9.121
2033.54	8.73251
2036.47	11.0009
2039.4	11.0366
2042.33	11.5112
2045.27	12.6529
2048.19	13.3902
2051.12	14.4539
2054.05	14.5057
2056.97	14.8768
2059.9	15.4745
2062.82	18.4609
2065.74	20.1051
2068.67	19.0647
2071.59	18.0435
2074.51	18.22
2077.42	18.0592
2080.34	17.705
2083.26	17.1243
2086.17	16.9224
2089.09	17.404
2092	17.1523
2094.91	18.0424
2097.82	18.1016
2100.73	18.9352
2103.64	19.8147
2106.55	21.0131
2109.45	20.2709
2112.36	20.2164
2115.26	21.3362
2118.17	22.2747
2121.07	22.9409
2123.97	23.7324
2126.87	24.6828
2129.77	25.7078
2132.67	27.8591
2135.56	28.881
2138.46	27.9968
2141.35	30.0034
2144.25	31.4768
2147.14	34.2753
2150.03	35.9481
2152.92	37.8224
2155.81	39.5475
2158.7	41.897
2161.59	41.9851
2164.47	42.8127
2167.36	44.2759
2170.24	44.9002
2173.13	44.5725
2176.01	45.6851
2178.89	44.5417
2181.77	43.7864
2184.65	43.2383
2187.53	43.0588
2190.4	41.6433
2193.28	39.9868
2196.16	39.4904
2199.03	37.759
2201.9	36.7883
2204.77	34.8332
2207.64	32.6516
2210.51	31.6537
2213.38	30.2496
2216.25	28.5909
2219.12	27.1778
2221.98	25.189
2224.85	23.2112
2227.71	20.9338
2230.57	20.2644
2233.43	19.7269
2236.29	18.441
2239.15	15.9876
2242.01	14.9171
2244.87	14.0476
2247.72	12.586
2250.58	11.7354
2253.43	11.4165
2256.29	11.5755
2259.14	12.3795
2261.99	12.2746
2264.84	13.2903
2267.69	12.9514
2270.53	11.9753
2273.38	12.423
2276.23	11.3414
2279.07	11.1708
2281.91	10.0406
2284.76	9.89929
2287.6	10.7788
2290.44	8.48395
2293.28	8.10137
2296.12	6.89789
2298.96	6.79691
2301.79	7.78963
2304.63	6.42114
2307.46	5.65302
2310.3	5.80907
2313.13	6.13568
2315.96	6.53536
2318.79	6.88581
2321.62	8.41313
2324.45	9.01088
2327.27	10.6741
2330.1	10.5247
2332.92	10.8783
2335.75	10.0666
2338.57	8.67301
2341.39	8.544
2344.21	6.80216
2347.04	5.55819
2349.85	4.05941
2352.67	3.31091
2355.49	2.06439
2358.3	-0.211182
2361.12	-0.822523
2363.93	-1.81285
2366.75	-1.92671
2369.56	-2.36739
2372.37	-2.56494
2375.18	-3.28436
2377.99	-2.20907
2380.8	-1.66695
2383.6	-0.0804604
2386.41	0.436575
2389.21	1.37132
2392.02	2.3298
2394.82	4.92305
2397.62	4.15139
2400.42	3.48155
2403.22	4.12079
2406.02	4.44389
2408.82	6.16179
2411.62	5.50305
2414.41	5.72659
2417.21	6.11062
2420	6.70372
2422.79	6.85271
2425.59	6.92186
2428.38	7.1787
2431.17	6.53589
2433.95	6.0343
2436.74	6.21966
2439.53	5.02719
2442.31	4.56445
2445.1	4.22621
2447.88	3.81915
2450.67	3.89205
2453.45	3.75719
2456.23	3.05086
2459.01	3.93843
2461.79	4.3194
2464.57	3.66982
2467.34	3.28368
2470.12	3.25646
2472.89	4.8783
2475.67	5.01797
2478.44	4.43485
2481.21	3.80058
2483.98	3.38647
2486.75	3.5064
2489.52	3.11951
2492.29	2.47232
2495.05	2.17336
2497.82	1.84497
2500.58	1.1124
2503.35	0.567974
2506.11	0.189868
2508.87	-0.370394
2511.63	-0.960702
2514.39	0.102276
2517.15	-0.284667
2519.91	0.769444
2522.67	1.17708
2525.42	1.76205
2528.18	2.80477
2530.93	2.28618
2533.69	3.61403
2536.44	2.83014
2539.19	4.11532
2541.94	3.65268
2544.69	4.2015
2547.44	4.91441
2550.18	5.91738
2552.93	6.52586
2555.67	6.92789
2558.42	6.74391
2561.16	6.13251
2563.9	7.14543
2566.64	8.84003
2569.38	8.45399
2572.12	6.78004
2574.86	7.15639
2577.6	6.90522
2580.33	7.94942
2583.07	7.46782
2585.8	6.95161
2588.54	6.96591
2591.27	5.81959
2594	4.94741
2596.73	3.29218
2599.46	2.74542
2602.19	2.10346
2604.92	1.93397
2607.64	1.0729
2610.37	2.59561
2613.09	2.66903
2615.82	3.67098
2618.54	3.76655
2621.26	4.69276
2623.98	4.7585
2626.7	4.85414
2629.42	6.18427
2632.14	8.15261
2634.86	7.32733
2637.57	6.39938
2640.29	7.85768
2643	8.70996
2645.71	9.67729
2648.43	9.23317
2651.14	9.18323
2653.85	8.79907
2656.56	8.79179
2659.26	7.82864
2661.97	6.5611
2664.68	5.63411
2667.38	6.91855
2670.09	6.01889
2672.79	6.54589
2675.49	7.52317
2678.19	9.00848
2680.89	9.16077
2683.59	9.12542
2686.29	9.63673
2688.99	10.1099
2691.69	11.6789
2694.38	13.2619
2697.08	15.5729
2699.77	17.1434
2702.46	19.6396
2705.15	21.6044
2707.85	23.0797
2710.54	23.9716
2713.22	25.2676
2715.91	25.5545
2718.6	26.3898
2721.29	27.5087
2723.97	28.6693
2726.66	28.6866
2729.34	27.315
2732.02	25.5365
2734.7	24.1255
2737.38	22.174
2740.06	20.448
2742.74	19.8589
2745.42	16.959
2748.09	14.9796
2750.77	12.3389
2753.45	11.5323
2756.12	10.5626
2758.79	8.80177
2761.46	6.61034
2764.14	6.40599
2766.8	5.28995
2769.47	5.36152
2772.14	3.72638
2774.81	3.17342
2777.48	4.07859
2780.14	3.64642
2782.8	4.12402
2785.47	4.9527
2788.13	5.63075
2790.79	5.90999
2793.45	5.12259
2796.11	5.36336
2798.77	5.60643
2801.43	5.70281
2804.09	5.74741
2806.74	3.99834
2809.4	3.36431
2812.05	2.16488
2814.71	2.58971
2817.36	7.87146
2820.01	17.7999
2822.66	32.691
2825.31	52.2128
2827.96	75.4387
2830.6	102.084
2833.25	128.96
2835.9	156.724
2838.54	183.626
2841.18	210.998
2843.83	236.96
2846.47	263.532
2849.11	289.841
2851.75	318.302
2854.39	347.396
2857.03	376.327
2859.66	400.35
2862.3	420.816
2864.94	437.068
2867.57	450.978
2870.2	459.279
2872.84	465.853
2875.47	471.224
2878.1	477.783
2880.73	485.561
2883.36	493.568
2885.99	501.59
2888.61	508.936
2891.24	515.743
2893.86	517.997
2896.49	522.03
2899.11	521.814
2901.73	521.565
2904.36	521.964
2906.98	525.069
2909.6	528.762
2912.21	536.364
2914.83	545.277
2917.45	553.224
2920.07	560.193
2922.68	560.933
2925.29	558.971
2927.91	556.318
2930.52	550.043
2933.13	540.942
2935.74	527.744
2938.35	514.053
2940.96	497.828
2943.57	477.957
2946.18	457.31
2948.78	433.635
2951.39	410.933
2953.99	387.841
2956.59	363.867
2959.2	340.618
2961.8	318.482
2964.4	295.817
2967	275.974
2969.6	257.78
2972.19	240.523
2974.79	223.779
2977.39	206.814
2979.98	190.16
2982.58	173.12
2985.17	156.203
2987.76	140.762
2990.35	126.173
2992.94	112.105
2995.53	97.806
2998.12	84.0693
3000.71	72.8494
3003.3	61.6586
3005.88	51.5486
3008.47	43.0625
3011.05	35.7938
3013.64	29.0874
3016.22	23.9429
3018.8	20.3099
3021.38	16.2233
3023.96	12.5079
3026.54	10.4544
3029.12	7.43939
3031.69	4.75841
3034.27	3.29732
3036.84	2.14051
3039.42	0.361283
3041.99	1.01519
3044.57	1.19754
3047.14	2.66659
3049.71	4.07651
3052.28	4.59753
3054.85	5.29471
3057.41	4.21331
3059.98	4.50312
3062.55	4.70989
3065.11	4.92206
3067.68	6.32499
3070.24	5.88287
3072.8	5.78173
3075.36	5.06504
3077.93	5.37751
3080.49	4.40796
3083.04	3.64693
3085.6	2.89992
3088.16	2.992
3090.72	2.93605
3093.27	2.57778
3095.83	3.23143
3098.38	4.07391
3100.93	6.34622
3103.49	7.66275
3106.04	10.0618
3108.59	11.9575
3111.14	13.4323
3113.69	15.8034
3116.23	17.6533
3118.78	19.2645
3121.33	21.5029
3123.87	25.0519
3126.41	26.823
3128.96	30.5049
3131.5	33.5317
3134.04	35.1538
3136.58	37.8081
3139.12	41.0115
3141.66	44.3919
3144.2	48.3047
3146.74	52.4355
3149.27	57.6076