File: data/Raman/poly_smoothed/Mb_20_23_11_1x_45s_532 nm_x100_100%_600 gr_mm_01.txt
#Acq. time (s)=	45
#Accumulations=	2
#Range (cm-¹)=	200...3150
#Windows=	2
#Auto scanning=	Off
#Autofocus=	Off
#Macrospot=	Off
#AutoExposure=	Off
#Spike filter=	Multiple accum.
#Delay time (s)=	0
#Binning=	1
#Readout mode=	Signal
#DeNoise=	Off
#ICS correction=	On
#Dark correction=	Off
#Inst. Process=	Off
#Detector Gain=	Best Dynamic Range
#Detector ADC=	20 kHz
#Detector temperature (°C)=	-69.85
#Instrument=	LabRAM HR Evol
#Detector=	Synapse
#Objective=	x100
#Grating=	600 gr/mm
#ND Filter=	100%
#Laser (nm)=	532
#Hole=	100.021
#Range=	Auto
#Laser Pol.=	No
#Raman. Pol.=	No
#Laser Pol. (°)=	-0.0007625
#Raman Pol. (°)=	89.9995
#Collection=	Microscope
#StageXY=	Marzhauser
#StageZ=	Marzhauser
#X (µm)=	-6964.7
#Y (µm)=	2134.3
#Z (µm)=	-74.85
#Full time(mm:ss)=	3:18
#Project=
#Sample=
#Site=
#Title=	Mb_20_23_11_2x_45s_532 nm_x100_100%_600 gr_mm
#Remark=
#Date=	13.07.2022 13:44
#Acquired=	13.07.2022 13:44:44
#Base:Fit=	10.08.2022 10:29:19
#Base:Fit=	10.08.2022 10:29:37
#Base:Sub=	10.08.2022 10:32:28
#Filter:Polynom=	16.08.2022 10:13:29
#AxisType[0]=Intens
#AxisUnit[0]=Cnt
#AxisType[1]=Spectr
#AxisUnit[1]=1/cm
200.563	12.6038
204.194	12.0591
207.821	12.3146
211.449	12.4479
215.074	11.994
218.699	9.77874
222.321	8.73051
225.941	6.81427
229.562	7.67887
233.18	7.83202
236.796	7.55072
240.411	6.65538
244.026	5.39765
247.638	4.79633
251.248	6.24718
254.857	6.39258
258.465	6.82432
262.071	7.6647
265.678	8.95887
269.282	9.16334
272.884	9.0357
276.484	9.49457
280.084	7.94737
283.682	8.58871
287.276	9.57635
290.871	11.7091
294.465	11.7295
298.057	5.29737
301.648	8.00452
305.237	12.0337
308.823	17.2614
312.41	22.5024
315.995	25.2769
319.579	26.9432
323.16	27.5439
326.741	30.0863
330.321	29.0701
333.897	29.4283
337.474	32.2512
341.048	33.0509
344.622	31.1971
348.192	29.8544
351.764	28.9781
355.332	25.8315
358.901	23.9961
362.466	22.0666
366.03	18.5046
369.594	15.9052
373.155	16.2715
376.715	12.3219
380.273	7.65469
383.832	5.45064
387.388	7.10965
390.942	13.7799
394.495	15.0364
398.047	14.5306
401.597	12.4918
405.145	11.2384
408.693	11.6232
412.239	11.571
415.783	10.4234
419.327	9.66586
422.869	9.95542
426.409	9.39982
429.948	7.80173
433.486	7.17025
437.022	8.06226
440.558	8.83525
444.089	8.93458
447.622	9.23903
451.153	8.12962
454.682	8.90186
458.208	10.2988
461.735	10.2527
465.259	10.1945
468.783	11.0748
472.306	12.8644
475.825	12.1003
479.346	11.8957
482.862	12.5876
486.38	13.4219
489.894	14.2533
493.407	16.2631
496.92	17.7549
500.43	18.9777
503.939	18.9844
507.448	19.5914
510.954	20.8024
514.459	21.8729
517.962	23.6986
521.466	25.7723
524.966	26.0264
528.466	26.6591
531.964	25.244
535.46	24.1509
538.955	24.135
542.449	24.1478
545.942	24.0171
549.433	22.7629
552.923	21.5211
556.412	18.9663
559.899	16.8068
563.385	17.1052
566.867	16.2242
570.35	16.1167
573.832	13.7348
577.313	12.4904
580.79	11.7994
584.268	11.8533
587.745	9.00744
591.218	7.13779
594.692	7.6638
598.164	7.00717
601.634	6.85864
605.104	5.68167
608.57	3.83491
612.037	2.4369
615.501	2.15771
618.966	2.2722
622.427	2.62265
625.887	4.08445
629.348	4.05242
632.806	4.37259
636.262	5.11829
639.716	6.99729
643.172	8.41289
646.624	10.0233
650.075	11.2805
653.524	10.4078
656.972	9.25278
660.419	9.59983
663.865	11.8248
667.309	11.481
670.752	10.5165
674.194	11.451
677.634	12.2162
681.073	13.9691
684.511	13.8106
687.947	14.6715
691.382	16.7204
694.816	18.9422
698.247	21.8437
701.678	24.1674
705.108	26.0126
708.534	28.3212
711.962	30.2481
715.388	32.0064
718.81	35.3059
722.234	36.3517
725.654	38.3623
729.075	38.1945
732.492	36.9334
735.91	38.232
739.325	39.7845
742.741	39.8156
746.153	42.9215
749.564	45.794
752.976	47.8934
756.385	50.471
759.792	52.631
763.2	54.1192
766.604	57.6329
770.008	59.3059
773.41	63.5099
776.811	67.6968
780.21	69.4595
783.608	71.9356
787.005	73.868
790.401	75.995
793.795	78.5697
797.188	79.2597
800.58	81.0346
803.971	81.6476
807.36	80.3258
810.748	81.3758
814.135	79.2625
817.518	79.0689
820.902	79.14
824.285	78.1716
827.665	76.7728
831.045	75.4034
834.424	74.5003
837.8	70.8792
841.177	69.3269
844.55	64.911
847.924	64.3417
851.295	63.6795
854.666	60.208
858.034	58.7158
861.403	56.3815
864.769	54.2643
868.133	52.0083
871.498	49.3963
874.86	47.7554
878.221	48.5971
881.58	47.8151
884.938	46.9738
888.297	45.3181
891.653	45.3572
895.007	45.1442
898.36	42.5329
901.712	41.7549
905.063	41.1334
908.412	40.3291
911.76	40.3226
915.107	38.336
918.452	37.8073
921.797	36.8564
925.138	36.5233
928.48	34.7195
931.82	34.5992
935.16	31.7067
938.496	30.0718
941.833	28.2304
945.168	26.2882
948.5	23.4027
951.834	23.404
955.163	24.994
958.494	26.0432
961.821	25.6639
965.15	27.3247
968.474	28.2037
971.8	31.9526
975.123	32.7569
978.446	35.0852
981.766	37.6832
985.084	38.9123
988.402	40.537
991.72	41.3034
995.035	41.4585
998.349	41.4954
1001.66	42.4469
1004.97	41.0961
1008.28	39.9616
1011.59	38.647
1014.9	37.9061
1018.21	35.644
1021.51	35.5617
1024.81	34.7822
1028.12	33.9485
1031.42	33.9244
1034.72	34.5883
1038.02	32.7505
1041.31	31.3612
1044.61	31.1312
1047.91	29.883
1051.2	29.2085
1054.49	28.669
1057.78	28.7902
1061.07	28.5398
1064.36	28.0726
1067.65	27.7134
1070.93	25.5751
1074.22	24.9115
1077.5	23.178
1080.78	21.2014
1084.06	19.6933
1087.34	20.0804
1090.62	19.2471
1093.9	20.63
1097.17	21.786
1100.45	23.6643
1103.72	24.8371
1106.99	25.8473
1110.27	26.1279
1113.53	26.601
1116.8	25.5195
1120.07	23.9253
1123.33	22.8447
1126.6	21.9653
1129.86	22.7177
1133.12	21.7101
1136.38	21.0935
1139.64	19.5729
1142.9	18.7576
1146.16	17.4127
1149.41	14.0909
1152.67	11.5176
1155.92	9.96115
1159.17	8.03468
1162.42	6.6996
1165.67	5.44876
1168.92	3.56453
1172.16	1.33402
1175.41	1.37894
1178.65	1.96495
1181.9	1.40793
1185.14	2.5484
1188.38	3.23074
1191.62	2.75412
1194.86	3.74417
1198.09	6.04225
1201.33	9.81316
1204.56	13.2725
1207.8	16.6192
1211.03	20.0035
1214.26	23.3198
1217.49	26.8985
1220.71	28.8738
1223.94	32.3299
1227.16	32.8823
1230.39	35.3931
1233.61	38.725
1236.83	40.9584
1240.05	42.6982
1243.27	42.6128
1246.49	44.1539
1249.71	44.9161
1252.92	44.7207
1256.14	46.3497
1259.35	47.3911
1262.56	50.1823
1265.77	52.2377
1268.98	54.6081
1272.19	58.2098
1275.4	61.3365
1278.6	64.7009
1281.81	67.0909
1285.01	69.981
1288.21	72.9348
1291.41	76.1934
1294.61	76.5951
1297.81	76.1974
1301.01	76.7328
1304.2	77.2523
1307.4	77.8101
1310.59	80.0842
1313.78	81.3244
1316.97	81.1922
1320.16	80.5208
1323.35	81.3396
1326.54	79.9889
1329.72	78.1194
1332.91	77.0978
1336.09	75.8461
1339.27	76.4343
1342.45	76.1169
1345.64	75.3236
1348.81	74.6277
1351.99	73.0997
1355.17	71.5838
1358.34	69.8748
1361.51	68.7362
1364.69	66.8251
1367.86	65.4318
1371.03	63.0054
1374.2	59.6092
1377.37	57.2323
1380.53	56.9787
1383.7	55.9885
1386.86	56.1531
1390.02	55.0091
1393.19	54.9766
1396.35	52.4165
1399.51	50.867
1402.66	51.2038
1405.82	52.2555
1408.97	54.5277
1412.13	59.1978
1415.28	61.8408
1418.43	67.7178
1421.59	74.4739
1424.73	81.1842
1427.88	88.0344
1431.03	95.825
1434.18	101.68
1437.32	106.972
1440.46	112.403
1443.61	115.755
1446.75	117.322
1449.89	118.953
1453.03	119.678
1456.16	119.044
1459.3	116.289
1462.44	112.367
1465.57	107.182
1468.7	101.526
1471.83	94.8188
1474.96	88.656
1478.09	83.1381
1481.22	77.9864
1484.35	72.5091
1487.47	67.3138
1490.6	61.3617
1493.72	57.8466
1496.84	54.2402
1499.96	50.6727
1503.08	47.1869
1506.2	45.3608
1509.32	40.6401
1512.44	37.17
1515.55	35.3002
1518.66	32.7821
1521.78	31.8071
1524.89	30.9945
1528	29.5016
1531.11	29.0155
1534.21	29.3937
1537.32	28.6142
1540.43	28.5648
1543.53	30.9106
1546.63	32.5055
1549.74	35.1927
1552.84	36.9736
1555.94	37.9755
1559.03	38.6621
1562.13	39.6689
1565.23	41.0641
1568.32	41.4352
1571.42	42.8025
1574.51	44.3072
1577.6	46.5052
1580.69	48.5768
1583.78	50.7753
1586.87	53.1103
1589.95	54.5157
1593.04	56.2617
1596.12	56.8266
1599.21	58.8706
1602.29	58.7858
1605.37	58.8004
1608.45	58.3918
1611.53	57.578
1614.6	58.2093
1617.68	59.3887
1620.75	61.5811
1623.83	63.5254
1626.9	65.6544
1629.97	67.6108
1633.04	68.5301
1636.11	72.0477
1639.18	73.9442
1642.25	75.3886
1645.31	77.8846
1648.38	81.8316
1651.44	82.8914
1654.5	84.4869
1657.56	82.5699
1660.62	81.0106
1663.68	78.6609
1666.74	75.0182
1669.8	71.4992
1672.85	67.6279
1675.91	61.6327
1678.96	55.5466
1682.01	49.3332
1685.06	44.0913
1688.11	40.2545
1691.16	35.702
1694.21	31.1154
1697.25	28.3727
1700.3	24.3687
1703.34	22.4286
1706.39	20.0348
1709.43	17.7939
1712.47	16.1346
1715.51	13.1349
1718.54	12.7579
1721.58	11.9701
1724.62	11.5397
1727.65	9.72878
1730.68	7.96289
1733.72	6.02999
1736.75	5.61137
1739.78	5.00022
1742.81	6.06578
1745.84	5.89515
1748.86	5.4075
1751.89	5.77785
1754.91	5.8115
1757.93	5.0433
1760.96	4.58931
1763.98	4.36099
1767	4.08082
1770.02	4.15742
1773.03	4.46828
1776.05	4.05752
1779.07	4.05988
1782.08	3.0947
1785.09	1.98509
1788.11	1.18593
1791.12	2.46967
1794.13	2.72258
1797.13	3.39175
1800.14	3.36811
1803.15	2.86406
1806.15	3.45501
1809.16	3.21749
1812.16	3.61068
1815.16	4.20029
1818.16	4.06829
1821.16	4.56931
1824.16	4.8352
1827.16	5.44245
1830.16	5.30207
1833.15	4.32754
1836.14	5.00536
1839.14	6.03659
1842.13	6.24303
1845.12	6.35692
1848.11	5.84162
1851.1	5.24567
1854.08	5.19028
1857.07	5.58114
1860.05	6.18234
1863.04	6.37347
1866.02	8.42728
1869	8.52988
1871.98	8.30007
1874.96	7.62924
1877.94	6.78348
1880.92	6.83175
1882.51	6.15077
1885.5	6.44425
1888.48	6.44212
1891.47	6.52359
1894.46	7.34825
1897.44	6.85935
1900.42	7.14092
1903.41	6.35348
1906.39	6.62655
1909.37	7.07616
1912.35	6.60882
1915.32	7.02074
1918.3	7.67748
1921.27	9.13789
1924.25	8.74236
1927.22	8.30434
1930.19	8.52153
1933.17	7.9322
1936.14	7.88146
1939.11	7.27944
1942.07	6.46544
1945.04	6.26299
1948.01	6.62089
1950.97	6.52491
1953.93	6.12422
1956.9	5.28939
1959.86	4.97647
1962.82	4.90213
1965.78	4.78684
1968.74	4.53354
1971.69	3.79605
1974.65	4.06655
1977.6	4.48852
1980.56	5.47894
1983.51	6.04545
1986.46	6.87206
1989.41	7.71501
1992.36	7.08536
1995.31	6.13945
1998.26	5.87288
2001.2	5.90117
2004.15	5.97168
2007.09	6.04687
2010.04	7.0537
2012.98	7.09427
2015.92	6.73785
2018.86	7.39368
2021.8	7.0057
2024.73	7.02936
2027.67	6.36906
2030.61	6.63313
2033.54	6.41248
2036.47	6.07817
2039.4	6.25097
2042.33	6.24977
2045.27	6.19843
2048.19	6.59635
2051.12	6.52136
2054.05	6.29637
2056.97	7.06282
2059.9	7.64559
2062.82	6.74187
2065.74	7.0951
2068.67	7.16804
2071.59	7.22251
2074.51	7.3973
2077.42	7.42314
2080.34	9.14988
2083.26	9.91431
2086.17	11.7906
2089.09	13.0214
2092	14.8488
2094.91	16.2573
2097.82	16.0739
2100.73	17.7927
2103.64	18.1272
2106.55	19.6993
2109.45	20.0859
2112.36	20.5179
2115.26	21.4914
2118.17	22.8866
2121.07	24.5815
2123.97	25.3671
2126.87	26.7918
2129.77	28.8562
2132.67	29.6052
2135.56	30.4398
2138.46	32.3339
2141.35	33.2131
2144.25	34.5689
2147.14	36.5743
2150.03	39.6397
2152.92	42.1668
2155.81	44.7886
2158.7	47.5056
2161.59	49.094
2164.47	49.37
2167.36	50.4452
2170.24	51.2921
2173.13	53.5833
2176.01	54.3032
2178.89	54.3127
2181.77	53.6302
2184.65	52.3096
2187.53	51.6717
2190.4	50.7409
2193.28	48.7314
2196.16	46.8184
2199.03	43.856
2201.9	42.7373
2204.77	39.567
2207.64	37.1817
2210.51	34.5457
2213.38	31.9488
2216.25	30.018
2219.12	27.755
2221.98	25.9819
2224.85	25.1282
2227.71	23.0984
2230.57	20.4803
2233.43	18.5474
2236.29	17.4607
2239.15	17.2375
2242.01	16.0288
2244.87	15.6218
2247.72	14.156
2250.58	13.3574
2253.43	12.6366
2256.29	12.8908
2259.14	12.5187
2261.99	12.2011
2264.84	12.415
2267.69	12.4117
2270.53	12.3383
2273.38	12.8073
2276.23	11.4868
2279.07	11.0227
2281.91	9.91679
2284.76	9.71893
2287.6	9.36847
2290.44	8.9964
2293.28	7.01669
2296.12	6.68357
2298.96	6.40035
2301.79	7.35984
2304.63	7.36623
2307.46	9.00383
2310.3	8.53606
2313.13	9.18066
2315.96	11.2459
2318.79	11.3462
2321.62	11.9031
2324.45	11.6947
2327.27	10.9004
2330.1	10.8179
2332.92	10.3931
2335.75	10.5805
2338.57	8.9757
2341.39	8.34655
2344.21	7.34654
2347.04	5.10505
2349.85	4.22083
2352.67	3.62314
2355.49	2.45382
2358.3	1.98312
2361.12	1.02436
2363.93	1.30024
2366.75	2.08651
2369.56	3.69511
2372.37	3.55767
2375.18	3.99979
2377.99	4.01258
2380.8	3.67442
2383.6	4.27396
2386.41	3.31733
2389.21	3.27509
2392.02	4.00145
2394.82	4.2415
2397.62	5.45305
2400.42	5.34519
2403.22	5.01716
2406.02	4.6597
2408.82	3.62012
2411.62	4.26666
2414.41	4.61863
2417.21	5.04647
2420	5.34516
2422.79	5.38594
2425.59	5.51203
2428.38	6.35836
2431.17	5.98742
2433.95	4.69073
2436.74	3.69185
2439.53	3.11244
2442.31	2.29116
2445.1	1.80675
2447.88	1.94091
2450.67	1.70744
2453.45	1.78008
2456.23	1.88903
2459.01	2.57425
2461.79	1.73148
2464.57	1.24999
2467.34	0.98727
2470.12	1.1519
2472.89	1.46807
2475.67	1.17142
2478.44	1.39293
2481.21	1.46341
2483.98	1.46009
2486.75	1.69765
2489.52	1.2008
2492.29	0.747509
2495.05	0.546749
2497.82	0.0692026
2500.58	-0.0844262
2503.35	-0.599745
2506.11	-0.134098
2508.87	0.247005
2511.63	0.810412
2514.39	1.95559
2517.15	2.40667
2519.91	2.21334
2522.67	1.51461
2525.42	1.69586
2528.18	1.41719
2530.93	1.98347
2533.69	3.05552
2536.44	3.29353
2539.19	3.74514
2541.94	4.07385
2544.69	3.75109
2547.44	4.64344
2550.18	4.32001
2552.93	4.11926
2555.67	4.83157
2558.42	3.92191
2561.16	4.50228
2563.9	5.16055
2566.64	6.17209
2569.38	6.30072
2572.12	6.84852
2574.86	7.60619
2577.6	7.33393
2580.33	7.67034
2583.07	7.31137
2585.8	6.97094
2588.54	6.32845
2591.27	6.18904
2594	6.05475
2596.73	5.19312
2599.46	4.66106
2602.19	4.70319
2604.92	4.77792
2607.64	4.20927
2610.37	4.13354
2613.09	3.6309
2615.82	3.17641
2618.54	2.62628
2621.26	2.5753
2623.98	3.22974
2626.7	3.04991
2629.42	3.87295
2632.14	4.16316
2634.86	5.32701
2637.57	5.83748
2640.29	5.45106
2643	6.13742
2645.71	6.09042
2648.43	6.17626
2651.14	6.00582
2653.85	6.23419
2656.56	5.90546
2659.26	5.47341
2661.97	5.6321
2664.68	5.44576
2667.38	5.89843
2670.09	5.91684
2672.79	6.81581
2675.49	6.44456
2678.19	6.32814
2680.89	6.14445
2683.59	7.51168
2686.29	8.23191
2688.99	8.94299
2691.69	9.5211
2694.38	9.31149
2697.08	10.0349
2699.77	10.5354
2702.46	10.8992
2705.15	11.4313
2707.85	11.9267
2710.54	12.7377
2713.22	13.0323
2715.91	13.0064
2718.6	13.9789
2721.29	13.8864
2723.97	13.664
2726.66	13.9947
2729.34	14.2781
2732.02	13.9037
2734.7	13.2685
2737.38	13.042
2740.06	13.0151
2742.74	12.2706
2745.42	11.1364
2748.09	10.518
2750.77	9.3981
2753.45	8.09653
2756.12	6.28758
2758.79	5.90628
2761.46	4.48494
2764.14	3.6908
2766.8	2.57034
2769.47	2.39818
2772.14	2.43914
2774.81	2.09008
2777.48	1.4244
2780.14	1.64252
2782.8	1.90119
2785.47	1.37945
2788.13	1.41661
2790.79	1.38261
2793.45	2.24248
2796.11	2.96518
2798.77	3.02797
2801.43	2.78179
2804.09	2.91189
2806.74	2.14494
2809.4	1.15327
2812.05	0.977561
2814.71	0.822262
2817.36	2.90486
2820.01	6.14382
2822.66	11.0889
2825.31	17.3893
2827.96	24.7686
2830.6	32.7538
2833.25	41.8253
2835.9	51.5354
2838.54	60.8182
2841.18	71.4761
2843.83	83.567
2846.47	95.3998
2849.11	107.719
2851.75	120.807
2854.39	134.236
2857.03	147.767
2859.66	159.595
2862.3	169.573
2864.94	178.649
2867.57	186.379
2870.2	193.068
2872.84	199.323
2875.47	206.174
2878.1	210.706
2880.73	215.658
2883.36	222.547
2885.99	228.183
2888.61	234.936
2891.24	242.259
2893.86	247.404
2896.49	253.122
2899.11	259.85
2901.73	267.432
2904.36	276.631
2906.98	286.682
2909.6	296.623
2912.21	307.808
2914.83	319.836
2917.45	330.627
2920.07	339.087
2922.68	346.996
2925.29	350.742
2927.91	353.62
2930.52	353.84
2933.13	351.84
2935.74	348.095
2938.35	341.227
2940.96	332.227
2943.57	321.917
2946.18	310.192
2948.78	298.42
2951.39	285.772
2953.99	271.934
2956.59	257.436
2959.2	243.412
2961.8	230.247
2964.4	215.731
2967	203.8
2969.6	191.893
2972.19	179.832
2974.79	168.993
2977.39	157.97
2979.98	146.694
2982.58	135.837
2985.17	124.905
2987.76	113.221
2990.35	101.835
2992.94	91.1164
2995.53	80.5259
2998.12	69.9558
3000.71	60.0019
3003.3	49.8225
3005.88	41.6717
3008.47	33.6535
3011.05	26.4479
3013.64	21.0125
3016.22	16.7836
3018.8	12.4193
3021.38	9.66662
3023.96	6.56609
3026.54	3.94708
3029.12	2.8891
3031.69	2.18461
3034.27	1.96155
3036.84	2.1231
3039.42	2.73166
3041.99	4.156
3044.57	5.3757
3047.14	5.98759
3049.71	7.03596
3052.28	7.28355
3054.85	6.98906
3057.41	7.94572
3059.98	7.33032
3062.55	7.17991
3065.11	6.01998
3067.68	4.30922
3070.24	3.84701
3072.8	3.59314
3075.36	2.58733
3077.93	2.41594
3080.49	2.55695
3083.04	1.86299
3085.6	1.71971
3088.16	0.589248
3090.72	1.04717
3093.27	1.08554
3095.83	0.974223
3098.38	1.01541
3100.93	1.57035
3103.49	2.42933
3106.04	3.95467
3108.59	3.6502
3111.14	4.64891
3113.69	5.35566
3116.23	6.33714
3118.78	7.17312
3121.33	9.29117
3123.87	10.3696
3126.41	11.8672
3128.96	13.3875
3131.5	16.1326
3134.04	19.2688
3136.58	21.5387
3139.12	24.5273
3141.66	28.3509
3144.2	31.124
3146.74	34.1211
3149.27	37.4652