File: data/Raman/poly_smoothed/Mb_20_23_06_1x_45s_532 nm_x100_100%_600 gr_mm_01.txt
#Acq. time (s)=	45
#Accumulations=	2
#Range (cm-¹)=	200...3150
#Windows=	2
#Auto scanning=	Off
#Autofocus=	Off
#Macrospot=	Off
#AutoExposure=	Off
#Spike filter=	Multiple accum.
#Delay time (s)=	0
#Binning=	1
#Readout mode=	Signal
#DeNoise=	Off
#ICS correction=	On
#Dark correction=	Off
#Inst. Process=	Off
#Detector Gain=	Best Dynamic Range
#Detector ADC=	20 kHz
#Detector temperature (°C)=	-69.85
#Instrument=	LabRAM HR Evol
#Detector=	Synapse
#Objective=	x100
#Grating=	600 gr/mm
#ND Filter=	100%
#Laser (nm)=	532
#Hole=	100.021
#Range=	Auto
#Laser Pol.=	No
#Raman. Pol.=	No
#Laser Pol. (°)=	-0.0007625
#Raman Pol. (°)=	89.9995
#Collection=	Microscope
#StageXY=	Marzhauser
#StageZ=	Marzhauser
#X (µm)=	-6958.5
#Y (µm)=	2179.2
#Z (µm)=	-74.45
#Full time(mm:ss)=	3:18
#Project=
#Sample=
#Site=
#Title=	Mb_20_23_06_2x_45s_532 nm_x100_100%_600 gr_mm
#Remark=
#Date=	13.07.2022 13:23
#Acquired=	13.07.2022 13:23:54
#Base:Fit=	10.08.2022 10:29:19
#Base:Fit=	10.08.2022 10:29:37
#Base:Sub=	10.08.2022 10:31:46
#Filter:Polynom=	16.08.2022 10:13:29
#AxisType[0]=Intens
#AxisUnit[0]=Cnt
#AxisType[1]=Spectr
#AxisUnit[1]=1/cm
200.563	27.7015
204.194	28.458
207.821	27.8894
211.449	27.3808
215.074	26.9964
218.699	26.0331
222.321	25.6756
225.941	24.8108
229.562	24.7104
233.18	22.234
236.796	19.5148
240.411	18.7636
244.026	16.6512
247.638	16.0236
251.248	13.3386
254.857	11.3361
258.465	9.34631
262.071	9.2893
265.678	7.88233
269.282	7.76817
272.884	5.51333
276.484	4.7496
280.084	4.31408
283.682	1.63329
287.276	0.454638
290.871	0.272406
294.465	1.00644
298.057	2.61445
301.648	4.45698
305.237	4.96096
308.823	5.6514
312.41	6.95957
315.995	7.75982
319.579	8.32312
323.16	8.5866
326.741	8.60276
330.321	9.47713
333.897	9.73579
337.474	9.41541
341.048	8.90496
344.622	8.90877
348.192	9.31241
351.764	7.86293
355.332	6.90287
358.901	5.89908
362.466	3.73483
366.03	3.05373
369.594	3.9184
373.155	4.61669
376.715	6.12587
380.273	8.14315
383.832	8.15356
387.388	9.10753
390.942	9.18949
394.495	10.1164
398.047	8.99072
401.597	9.46085
405.145	9.54816
408.693	9.4551
412.239	8.51818
415.783	6.77067
419.327	6.21047
422.869	4.44635
426.409	5.16337
429.948	3.80439
433.486	2.27587
437.022	0.794635
440.558	1.03926
444.089	-0.034323
447.622	1.00749
451.153	1.00981
454.682	3.59076
458.208	3.81527
461.735	4.2749
465.259	5.35933
468.783	7.47545
472.306	9.17611
475.825	12.4611
479.346	14.6411
482.862	15.1545
486.38	16.6373
489.894	19.496
493.407	22.4672
496.92	22.6741
500.43	23.0648
503.939	25.0972
507.448	27.3532
510.954	27.7701
514.459	28.6932
517.962	27.9373
521.466	28.2005
524.966	29.6543
528.466	29.4432
531.964	30.2093
535.46	29.218
538.955	27.2642
542.449	25.5591
545.942	24.7953
549.433	25.1354
552.923	22.7095
556.412	21.6471
559.899	20.1738
563.385	17.6091
566.867	14.9948
570.35	13.5486
573.832	12.4729
577.313	12.0606
580.79	8.65577
584.268	7.35181
587.745	8.50913
591.218	6.36699
594.692	5.75845
598.164	5.54096
601.634	8.39182
605.104	9.27319
608.57	11.4126
612.037	14.0164
615.501	13.891
618.966	13.8044
622.427	11.8835
625.887	12.1969
629.348	14.0648
632.806	14.0267
636.262	13.3432
639.716	11.4547
643.172	11.8993
646.624	10.387
650.075	11.1484
653.524	10.8618
656.972	11.069
660.419	10.1921
663.865	10.3582
667.309	10.0343
670.752	10.4423
674.194	10.1976
677.634	9.86483
681.073	11.6232
684.511	14.6553
687.947	15.984
691.382	16.1601
694.816	18.746
698.247	21.2092
701.678	22.052
705.108	23.2185
708.534	23.7913
711.962	29.9276
715.388	32.0315
718.81	35.6194
722.234	36.5876
725.654	38.2462
729.075	40.5676
732.492	42.9508
735.91	45.4805
739.325	47.5545
742.741	47.6721
746.153	49.8199
749.564	51.3429
752.976	54.2254
756.385	54.9611
759.792	55.7839
763.2	56.6
766.604	57.9976
770.008	58.9814
773.41	61.1755
776.811	63.9392
780.21	66.4275
783.608	68.3028
787.005	70.1961
790.401	72.9978
793.795	75.9124
797.188	79.0695
800.58	80.7921
803.971	81.8928
807.36	83.7491
810.748	87.4369
814.135	89.4799
817.518	89.4222
820.902	92.557
824.285	93.1081
827.665	94.1633
831.045	95.4836
834.424	96.3065
837.8	95.7351
841.177	94.315
844.55	92.7077
847.924	91.3785
851.295	89.6942
854.666	88.5282
858.034	85.5436
861.403	81.9064
864.769	81.7104
868.133	79.4432
871.498	77.7959
874.86	74.8623
878.221	72.6045
881.58	72.1254
884.938	72.4834
888.297	71.3397
891.653	70.2868
895.007	67.5537
898.36	65.972
901.712	67.818
905.063	67.7831
908.412	67.0268
911.76	67.0368
915.107	66.102
918.452	64.1968
921.797	61.1579
925.138	59.4248
928.48	57.5462
931.82	54.644
935.16	53.2013
938.496	53.0428
941.833	51.8076
945.168	49.6876
948.5	47.3719
951.834	46.0583
955.163	44.6442
958.494	42.8517
961.821	42.9508
965.15	42.3195
968.474	42.3088
971.8	43.4309
975.123	44.8838
978.446	48.0345
981.766	49.4415
985.084	52.1054
988.402	52.2382
991.72	53.4245
995.035	54.0056
998.349	54.2174
1001.66	54.7997
1004.97	55.9977
1008.28	57.2764
1011.59	59.0221
1014.9	61.4162
1018.21	62.3664
1021.51	62.4601
1024.81	60.235
1028.12	61.8404
1031.42	61.2035
1034.72	62.7018
1038.02	61.7653
1041.31	62.0487
1044.61	64.3183
1047.91	66.1724
1051.2	67.1759
1054.49	67.0073
1057.78	66.9667
1061.07	66.0399
1064.36	64.789
1067.65	62.9815
1070.93	63.6098
1074.22	61.2302
1077.5	58.7015
1080.78	56.3207
1084.06	54.7422
1087.34	52.3888
1090.62	51.3353
1093.9	50.3786
1097.17	48.0766
1100.45	47.0984
1103.72	47.0215
1106.99	46.4444
1110.27	46.9447
1113.53	44.3612
1116.8	42.69
1120.07	41.4307
1123.33	40.7615
1126.6	38.3333
1129.86	36.0088
1133.12	33.8793
1136.38	32.0725
1139.64	31.4161
1142.9	30.8523
1146.16	29.0475
1149.41	27.3587
1152.67	25.6534
1155.92	22.3643
1159.17	20.283
1162.42	16.9141
1165.67	14.8058
1168.92	13.9707
1172.16	14.0596
1175.41	13.2692
1178.65	13.2606
1181.9	12.844
1185.14	12.3587
1188.38	12.4697
1191.62	10.412
1194.86	10.1314
1198.09	11.2789
1201.33	12.1308
1204.56	14.3878
1207.8	16.1891
1211.03	19.9742
1214.26	25.9726
1217.49	31.3121
1220.71	36.5183
1223.94	40.2898
1227.16	45.1272
1230.39	50.9114
1233.61	54.7456
1236.83	58.5215
1240.05	62.1835
1243.27	66.2764
1246.49	70.7824
1249.71	75.4813
1252.92	76.5579
1256.14	76.4707
1259.35	79.1251
1262.56	81.7267
1265.77	84.983
1268.98	90.1788
1272.19	95.5239
1275.4	100.537
1278.6	106.718
1281.81	113.103
1285.01	118.769
1288.21	125.356
1291.41	130.16
1294.61	132.564
1297.81	134.86
1301.01	136.362
1304.2	138.343
1307.4	141.238
1310.59	141.453
1313.78	140.284
1316.97	138.27
1320.16	135.302
1323.35	130.42
1326.54	125.651
1329.72	118.091
1332.91	110.639
1336.09	106.25
1339.27	102.154
1342.45	96.9199
1345.64	94.3553
1348.81	90.8699
1351.99	87.2299
1355.17	84.2859
1358.34	80.239
1361.51	78.6195
1364.69	77.3113
1367.86	75.8577
1371.03	72.9068
1374.2	71.8676
1377.37	73.4883
1380.53	74.7756
1383.7	76.4624
1386.86	77.6703
1390.02	77.4909
1393.19	77.1573
1396.35	76.4916
1399.51	77.3078
1402.66	81.0715
1405.82	86.5992
1408.97	93.6201
1412.13	101.891
1415.28	111.852
1418.43	123.003
1421.59	135.921
1424.73	149.354
1427.88	162.681
1431.03	176.936
1434.18	188.268
1437.32	200.136
1440.46	209.196
1443.61	215.687
1446.75	219.1
1449.89	220.241
1453.03	217.34
1456.16	211.95
1459.3	202.94
1462.44	189.614
1465.57	173.32
1468.7	156.053
1471.83	138.174
1474.96	119.945
1478.09	104.625
1481.22	90.7606
1484.35	77.3048
1487.47	63.3701
1490.6	51.2909
1493.72	42.3842
1496.84	35.7903
1499.96	30.7038
1503.08	26.3319
1506.2	22.8736
1509.32	20.1394
1512.44	18.6347
1515.55	17.6912
1518.66	17.7315
1521.78	20.3216
1524.89	20.723
1528	21.738
1531.11	22.0867
1534.21	23.309
1537.32	23.7955
1540.43	27.0252
1543.53	29.4614
1546.63	31.9514
1549.74	34.157
1552.84	36.8609
1555.94	39.8791
1559.03	42.6057
1562.13	43.9943
1565.23	46.6288
1568.32	50.5082
1571.42	53.6735
1574.51	56.6506
1577.6	60.4913
1580.69	62.4283
1583.78	64.7946
1586.87	66.7136
1589.95	67.2622
1593.04	70.4162
1596.12	71.6631
1599.21	71.7098
1602.29	71.4572
1605.37	71.0965
1608.45	71.2342
1611.53	70.2274
1614.6	70.8651
1617.68	71.4656
1620.75	70.4563
1623.83	71.1628
1626.9	71.4793
1629.97	72.9405
1633.04	76.1859
1636.11	78.2202
1639.18	82.5091
1642.25	85.4799
1645.31	88.3565
1648.38	91.2305
1651.44	93.6306
1654.5	96.0644
1657.56	97.3505
1660.62	97.2397
1663.68	96.6838
1666.74	97.5869
1669.8	96.1371
1672.85	92.8791
1675.91	88.3393
1678.96	82.6007
1682.01	77.646
1685.06	69.1911
1688.11	62.56
1691.16	57.6722
1694.21	52.0655
1697.25	47.9289
1700.3	42.6135
1703.34	39.5067
1706.39	37.4381
1709.43	33.6998
1712.47	30.7434
1715.51	29.7352
1718.54	28.6243
1721.58	29.2338
1724.62	29.0567
1727.65	28.5948
1730.68	28.8679
1733.72	27.199
1736.75	26.9757
1739.78	26.7639
1742.81	26.999
1745.84	25.1288
1748.86	22.2681
1751.89	20.4467
1754.91	18.0743
1757.93	15.7355
1760.96	14.0034
1763.98	13.3116
1767	11.5663
1770.02	9.73729
1773.03	7.89741
1776.05	6.05401
1779.07	5.5506
1782.08	4.91559
1785.09	4.20026
1788.11	3.4531
1791.12	3.27599
1794.13	3.96672
1797.13	4.29922
1800.14	3.39058
1803.15	3.6897
1806.15	3.53481
1809.16	3.49613
1812.16	4.42432
1815.16	4.81419
1818.16	4.49716
1821.16	4.17713
1824.16	4.13431
1827.16	3.29556
1830.16	3.30387
1833.15	2.5625
1836.14	2.84577
1839.14	3.32566
1842.13	3.11729
1845.12	3.39671
1848.11	3.41653
1851.1	2.55598
1854.08	3.79789
1857.07	3.85004
1860.05	4.04974
1863.04	4.99939
1866.02	7.69252
1869	7.19206
1871.98	8.45868
1874.96	9.47943
1877.94	10.116
1880.92	10.7369
1882.51	11.1243
1885.5	11.3217
1888.48	11.1204
1891.47	11.2015
1894.46	11.0637
1897.44	11.0699
1900.42	11.5305
1903.41	10.7942
1906.39	9.59866
1909.37	8.60557
1912.35	9.03489
1915.32	8.68789
1918.3	6.62999
1921.27	5.46971
1924.25	3.7524
1927.22	2.75411
1930.19	1.65156
1933.17	2.48544
1936.14	4.28361
1939.11	3.06921
1942.07	2.24314
1945.04	2.83129
1948.01	3.83068
1950.97	4.37108
1953.93	4.84573
1956.9	5.56067
1959.86	4.85593
1962.82	4.39631
1965.78	4.03207
1968.74	4.34907
1971.69	4.89699
1974.65	4.83449
1977.6	5.0663
1980.56	6.30156
1983.51	7.97466
1986.46	7.53045
1989.41	7.29603
1992.36	7.41552
1995.31	7.07061
1998.26	8.79846
2001.2	10.5032
2004.15	11.0929
2007.09	11.3406
2010.04	9.5413
2012.98	8.79709
2015.92	9.13596
2018.86	8.64952
2021.8	9.48769
2024.73	8.95997
2027.67	8.11224
2030.61	5.34569
2033.54	3.9799
2036.47	3.49961
2039.4	3.49798
2042.33	3.50083
2045.27	4.74486
2048.19	4.31206
2051.12	4.51426
2054.05	5.4726
2056.97	6.17191
2059.9	6.56291
2062.82	7.74998
2065.74	9.41238
2068.67	10.3277
2071.59	11.3215
2074.51	11.7947
2077.42	13.2517
2080.34	12.7858
2083.26	12.8863
2086.17	14.2588
2089.09	15.4725
2092	16.8694
2094.91	18.3061
2097.82	18.5828
2100.73	19.2803
2103.64	20.1168
2106.55	20.6802
2109.45	20.8794
2112.36	21.9219
2115.26	23.3219
2118.17	25.6805
2121.07	27.1369
2123.97	30.2847
2126.87	33.0155
2129.77	35.2839
2132.67	37.6542
2135.56	40.7334
2138.46	44.6622
2141.35	48.4373
2144.25	50.7752
2147.14	54.7759
2150.03	56.1548
2152.92	57.6692
2155.81	60.2553
2158.7	63.3422
2161.59	65.3145
2164.47	67.3138
2167.36	69.7298
2170.24	70.3498
2173.13	71.3871
2176.01	70.5923
2178.89	69.3364
2181.77	69.0343
2184.65	67.2824
2187.53	67.0024
2190.4	64.7798
2193.28	62.7119
2196.16	60.8344
2199.03	57.5308
2201.9	54.799
2204.77	52.3016
2207.64	50.392
2210.51	47.7344
2213.38	44.1858
2216.25	40.9246
2219.12	38.4207
2221.98	36.389
2224.85	33.8896
2227.71	33.0051
2230.57	30.2779
2233.43	29.2467
2236.29	27.7259
2239.15	26.0101
2242.01	23.8451
2244.87	22.3031
2247.72	20.4089
2250.58	19.2971
2253.43	18.543
2256.29	17.68
2259.14	17.3913
2261.99	16.0594
2264.84	16.3429
2267.69	15.6924
2270.53	15.2435
2273.38	15.6051
2276.23	15.2946
2279.07	15.5767
2281.91	15.5716
2284.76	15.4864
2287.6	14.6525
2290.44	13.8184
2293.28	12.3717
2296.12	12.2972
2298.96	12.7803
2301.79	12.6487
2304.63	12.459
2307.46	12.4514
2310.3	12.4239
2313.13	12.705
2315.96	13.734
2318.79	13.0028
2321.62	12.755
2324.45	13.3744
2327.27	12.7406
2330.1	12.2349
2332.92	11.4824
2335.75	11.221
2338.57	10.0864
2341.39	9.75303
2344.21	8.84528
2347.04	7.68275
2349.85	6.20038
2352.67	4.66161
2355.49	2.81854
2358.3	2.69607
2361.12	1.26065
2363.93	0.603204
2366.75	1.58141
2369.56	1.67328
2372.37	1.34541
2375.18	1.58528
2377.99	2.41469
2380.8	2.7901
2383.6	2.97472
2386.41	2.74355
2389.21	3.9711
2392.02	4.75843
2394.82	5.85055
2397.62	5.06947
2400.42	4.74405
2403.22	6.0124
2406.02	6.91899
2408.82	7.28554
2411.62	7.77954
2414.41	8.07988
2417.21	8.10547
2420	8.34906
2422.79	8.08328
2425.59	7.76254
2428.38	7.62028
2431.17	6.92127
2433.95	6.78617
2436.74	6.75458
2439.53	5.56287
2442.31	5.74488
2445.1	6.27733
2447.88	4.79428
2450.67	3.82691
2453.45	3.02041
2456.23	2.74393
2459.01	3.38403
2461.79	3.60043
2464.57	3.19593
2467.34	3.25175
2470.12	5.3031
2472.89	5.48973
2475.67	5.66036
2478.44	5.88643
2481.21	5.60965
2483.98	4.7533
2486.75	2.90033
2489.52	2.67968
2492.29	1.72139
2495.05	1.96217
2497.82	2.59702
2500.58	2.4166
2503.35	1.85637
2506.11	1.42208
2508.87	1.25215
2511.63	1.66132
2514.39	1.71763
2517.15	0.798035
2519.91	0.35253
2522.67	1.26906
2525.42	3.75888
2528.18	5.9225
2530.93	6.3278
2533.69	7.40912
2536.44	7.19988
2539.19	7.78422
2541.94	8.56189
2544.69	8.64196
2547.44	7.36978
2550.18	7.49635
2552.93	5.88182
2555.67	7.16262
2558.42	7.92577
2561.16	8.17146
2563.9	8.63739
2566.64	7.72545
2569.38	7.5782
2572.12	7.69215
2574.86	7.42138
2577.6	7.64577
2580.33	8.36924
2583.07	7.22248
2585.8	8.42072
2588.54	8.41512
2591.27	9.29485
2594	10.3566
2596.73	9.9729
2599.46	10.0424
2602.19	11.2532
2604.92	13.5083
2607.64	13.9277
2610.37	13.9164
2613.09	12.7246
2615.82	13.4564
2618.54	13.9068
2621.26	14.5629
2623.98	13.1083
2626.7	11.2953
2629.42	10.3131
2632.14	8.68927
2634.86	8.10693
2637.57	8.54103
2640.29	7.80631
2643	8.50875
2645.71	8.00876
2648.43	8.02169
2651.14	6.95455
2653.85	7.31742
2656.56	6.73417
2659.26	8.40307
2661.97	9.31585
2664.68	10.0244
2667.38	11.3119
2670.09	12.9006
2672.79	12.7496
2675.49	12.8276
2678.19	13.2136
2680.89	13.2356
2683.59	13.5077
2686.29	14.3811
2688.99	13.4302
2691.69	13.5485
2694.38	14.8052
2697.08	15.9039
2699.77	17.3637
2702.46	18.419
2705.15	20.1162
2707.85	21.0461
2710.54	21.1962
2713.22	21.2407
2715.91	22.7629
2718.6	21.8991
2721.29	23.8777
2723.97	23.6859
2726.66	24.1184
2729.34	23.3029
2732.02	22.6261
2734.7	22.2057
2737.38	20.7827
2740.06	18.8365
2742.74	15.9153
2745.42	14.0646
2748.09	13.3389
2750.77	11.906
2753.45	10.1539
2756.12	7.8993
2758.79	8.42512
2761.46	7.18787
2764.14	5.74099
2766.8	4.89426
2769.47	3.90493
2772.14	2.00764
2774.81	0.678662
2777.48	0.832187
2780.14	1.08764
2782.8	0.347035
2785.47	0.744923
2788.13	1.03641
2790.79	1.11385
2793.45	0.445422
2796.11	0.0961446
2798.77	-0.943658
2801.43	-1.14644
2804.09	-2.65151
2806.74	-3.00086
2809.4	-4.80565
2812.05	-6.12458
2814.71	-5.08507
2817.36	-3.55223
2820.01	2.31899
2822.66	13.3684
2825.31	28.9682
2827.96	47.5223
2830.6	67.0485
2833.25	89.0415
2835.9	110.536
2838.54	133.563
2841.18	159.593
2843.83	185.56
2846.47	211.065
2849.11	236.798
2851.75	263.646
2854.39	288.644
2857.03	311.709
2859.66	331.155
2862.3	349.255
2864.94	364.781
2867.57	378.711
2870.2	388.7
2872.84	394.454
2875.47	399.236
2878.1	405.138
2880.73	412.169
2883.36	419.795
2885.99	430.523
2888.61	440.666
2891.24	448.789
2893.86	456.069
2896.49	464.437
2899.11	473.77
2901.73	483.378
2904.36	493.546
2906.98	506.024
2909.6	520.872
2912.21	537.145
2914.83	550.102
2917.45	562.772
2920.07	572.615
2922.68	577.868
2925.29	581.007
2927.91	581.317
2930.52	577.547
2933.13	570.37
2935.74	558.685
2938.35	544.405
2940.96	528.193
2943.57	510.251
2946.18	488.004
2948.78	465.683
2951.39	440.7
2953.99	416.455
2956.59	391.968
2959.2	367.542
2961.8	345.183
2964.4	322.294
2967	301.623
2969.6	282.571
2972.19	266.082
2974.79	248.843
2977.39	229.57
2979.98	211.915
2982.58	193.09
2985.17	175.113
2987.76	156.917
2990.35	139.023
2992.94	121.932
2995.53	104.347
2998.12	89.6656
3000.71	74.5508
3003.3	61.9409
3005.88	50.1367
3008.47	39.4479
3011.05	30.2784
3013.64	23.7858
3016.22	16.6295
3018.8	11.3774
3021.38	6.88848
3023.96	3.36977
3026.54	1.23704
3029.12	0.681915
3031.69	-0.357192
3034.27	-1.15591
3036.84	-0.114369
3039.42	1.63187
3041.99	2.64301
3044.57	5.00096
3047.14	6.31509
3049.71	7.84756
3052.28	8.38353
3054.85	8.91514
3057.41	9.18188
3059.98	9.05873
3062.55	9.56504
3065.11	9.63326
3067.68	7.82587
3070.24	7.86363
3072.8	7.37533
3075.36	7.22982
3077.93	5.88834
3080.49	4.25498
3083.04	3.5237
3085.6	4.61025
3088.16	4.54531
3090.72	5.37289
3093.27	6.24865
3095.83	7.6617
3098.38	10.2179
3100.93	12.8339
3103.49	14.7774
3106.04	17.3745
3108.59	20.415
3111.14	22.5555
3113.69	25.6314
3116.23	27.8505
3118.78	30.1369
3121.33	33.1588
3123.87	36.1248
3126.41	39.1696
3128.96	41.6025
3131.5	46.0506
3134.04	49.5629
3136.58	52.8137
3139.12	55.9162
3141.66	59.7865
3144.2	63.5914
3146.74	67.9784
3149.27	71.847