File: data/Raman/poly_smoothed/Mb_20_23_45_1c_45s_532 nm_x100_100%_600 gr_mm_01.txt
#Acq. time (s)=	45
#Accumulations=	2
#Range (cm-¹)=	200...3150
#Windows=	2
#Auto scanning=	Off
#Autofocus=	Off
#Macrospot=	Off
#AutoExposure=	Off
#Spike filter=	Multiple accum.
#Delay time (s)=	0
#Binning=	1
#Readout mode=	Signal
#DeNoise=	Off
#ICS correction=	On
#Dark correction=	Off
#Inst. Process=	Off
#Detector Gain=	Best Dynamic Range
#Detector ADC=	20 kHz
#Detector temperature (°C)=	-70.08
#Instrument=	LabRAM HR Evol
#Detector=	Synapse
#Objective=	x100
#Grating=	600 gr/mm
#ND Filter=	100%
#Laser (nm)=	532
#Hole=	100.021
#Range=	Auto
#Laser Pol.=	No
#Raman. Pol.=	No
#Laser Pol. (°)=	-0.0007625
#Raman Pol. (°)=	89.9995
#Collection=	Microscope
#StageXY=	Marzhauser
#StageZ=	Marzhauser
#X (µm)=	479.6
#Y (µm)=	2970.9
#Z (µm)=	-8.95
#Full time(mm:ss)=	3:09
#Project=
#Sample=
#Site=
#Title=	Mb_20_23_45_2c_45s_532 nm_x100_100%_600 gr_mm
#Remark=
#Date=	14.07.2022 09:46
#Acquired=	14.07.2022 09:46:10
#Base:Fit=	10.08.2022 10:29:37
#Base:Sub=	10.08.2022 10:35:48
#Filter:Polynom=	16.08.2022 10:13:29
#AxisType[0]=Intens
#AxisUnit[0]=Cnt
#AxisType[1]=Spectr
#AxisUnit[1]=1/cm
200.554	84.1478
204.183	70.5472
207.813	55.4492
211.439	43.9396
215.065	37.228
218.688	31.8797
222.312	26.2666
225.933	22.87
229.552	17.8143
233.171	16.9372
236.787	13.1294
240.402	10.9631
244.015	10.5151
247.627	11.414
251.24	14.0087
254.849	13.2014
258.457	13.6581
262.063	13.4378
265.668	13.2561
269.271	13.4677
272.873	10.9212
276.474	11.0446
280.073	8.70462
283.671	8.12569
287.268	6.07381
290.863	4.04662
294.456	4.02841
298.049	6.08233
301.637	6.91178
305.227	6.94196
308.815	7.08052
312.402	9.38206
315.987	9.40576
319.569	11.415
323.151	12.1348
326.733	11.8015
330.31	13.3546
333.889	14.9797
337.464	15.5203
341.039	16.1426
344.611	17.9176
348.184	18.6508
351.754	17.6321
355.324	19.4106
358.89	19.1215
362.455	18.3937
366.021	19.1835
369.584	19.7794
373.145	18.8334
376.707	20.0435
380.265	19.7897
383.822	21.7229
387.378	24.112
390.934	24.0772
394.487	26.0728
398.038	27.7667
401.588	30.4433
405.137	30.3743
408.685	30.6881
412.23	30.0087
415.775	30.0256
419.318	29.9235
422.86	30.0834
426.401	29.9562
429.94	30.0251
433.478	27.7847
437.012	26.6819
440.547	27.8001
444.081	27.8238
447.613	25.7426
451.142	27.6682
454.672	27.3886
458.2	26.9907
461.725	27.6344
465.251	29.7672
468.775	31.6513
472.296	33.2054
475.817	31.4795
479.335	33.1806
482.854	36.142
486.37	37.2183
489.886	39.0651
493.398	41.8606
496.91	44.3034
500.422	44.7436
503.93	44.8811
507.438	43.9168
510.946	44.2574
514.45	44.24
517.954	43.5931
521.456	43.2778
524.956	43.0787
528.456	43.4284
531.956	41.8701
535.452	39.7376
538.947	39.475
542.441	38.8462
545.934	38.229
549.425	39.0265
552.915	36.1158
556.403	33.4021
559.889	31.3847
563.375	29.848
566.859	29.801
570.342	28.5926
573.824	28.1182
577.303	27.6919
580.782	26.4225
584.26	23.2828
587.734	19.3106
591.21	15.7222
594.684	14.8898
598.154	13.9022
601.626	14.0204
605.094	14.0352
608.562	12.65
612.027	11.9502
615.493	8.7675
618.956	8.77434
622.419	8.14688
625.879	6.46649
629.338	8.64765
632.797	8.89249
636.254	9.55382
639.708	8.97026
643.162	8.32884
646.614	9.37391
650.067	8.70988
653.516	10.781
656.964	10.5268
660.411	9.48882
663.857	8.10922
667.301	5.97484
670.744	4.60723
674.186	5.71963
677.626	4.37465
681.065	4.24538
684.503	3.81326
687.939	5.12338
691.372	3.71262
694.806	5.08998
698.239	5.05258
701.67	4.56595
705.098	5.25531
708.526	4.45471
711.954	6.97405
715.378	8.71675
718.802	11.091
722.226	9.71802
725.646	9.10039
729.067	9.8856
732.484	12.4428
735.902	15.5757
739.317	17.5885
742.731	16.9331
746.145	18.6811
749.556	20.7946
752.966	23.0992
756.377	25.7396
759.784	27.9133
763.19	28.124
766.594	31.3152
770	34.9964
773.402	39.009
776.803	43.0058
780.202	45.9729
783.6	47.7137
786.997	50.6362
790.393	51.1834
793.787	53.8482
797.18	54.8911
800.572	56.4442
803.963	55.5889
807.35	56.769
810.738	46.1016
814.125	52.6095
817.51	59.6697
820.894	62.6611
824.275	68.1572
827.657	71.5467
831.037	77.0196
834.414	82.3071
837.792	84.0412
841.167	84.1122
844.542	84.3074
847.914	83.6415
851.287	84.8927
854.656	84.9036
858.026	82.393
861.393	81.4726
864.761	77.6533
868.125	74.2048
871.489	70.0273
874.85	66.636
878.213	60.7854
881.572	55.9321
884.931	50.6349
888.287	44.713
891.643	37.9966
894.997	46.189
898.352	50.7248
901.704	49.3299
905.055	50.27
908.404	50.8578
911.75	51.7609
915.097	50.8435
918.443	50.2678
921.787	48.2715
925.13	47.2719
928.472	47.3625
931.813	45.0912
935.15	42.367
938.488	39.1089
941.825	34.0152
945.158	33.1726
948.493	29.9353
951.824	27.0831
955.156	24.9411
958.486	21.631
961.814	20.3439
965.142	22.1461
968.467	26.3983
971.79	28.189
975.115	33.6941
978.436	37.1576
981.756	37.731
985.077	39.0413
988.394	39.717
991.71	40.2519
995.025	41.3491
998.341	43.3372
1001.65	43.9464
1004.97	45.9376
1008.28	46.4796
1011.58	50.6669
1014.89	52.6417
1018.2	54.6156
1021.5	57.9546
1024.81	64.7188
1028.11	73.2097
1031.41	77.5407
1034.71	83.5251
1038.01	88.6772
1041.31	93.8465
1044.6	103.116
1047.9	110.377
1051.19	115.275
1054.48	116.804
1057.77	117.325
1061.06	111.28
1064.35	107.885
1067.64	104.601
1070.93	100.438
1074.21	93.2158
1077.49	88.3952
1080.78	80.6632
1084.06	74.3527
1087.34	69.6985
1090.61	69.5627
1093.89	70.4605
1097.17	70.5634
1100.44	70.8598
1103.71	71.922
1106.99	73.37
1110.26	73.6142
1113.52	72.0601
1116.79	70.473
1120.06	67.9547
1123.32	66.3007
1126.59	63.7668
1129.85	60.4286
1133.11	57.4187
1136.37	51.9062
1139.63	47.4999
1142.89	43.1606
1146.15	39.3252
1149.4	34.4517
1152.66	29.1499
1155.91	23.4723
1159.16	16.3243
1162.41	11.6575
1165.66	8.95267
1168.91	8.14272
1172.16	10.3001
1175.4	9.684
1178.65	7.98884
1181.89	6.66036
1185.13	6.5657
1188.37	6.20447
1191.61	6.84342
1194.85	5.46502
1198.08	7.43177
1201.32	10.7215
1204.55	16.1463
1207.79	20.5004
1211.02	27.2078
1214.25	31.6847
1217.48	37.6536
1220.71	43.1081
1223.93	49.7648
1227.16	56.0681
1230.38	61.5572
1233.6	66.8124
1236.83	70.7397
1240.05	76.5469
1243.26	80.6227
1246.48	84.8741
1249.7	87.4804
1252.92	88.2464
1256.13	89.1378
1259.34	94.5391
1262.55	100.379
1265.76	108.929
1268.97	118.569
1272.18	127.366
1275.39	136.713
1278.59	148.101
1281.8	157.934
1285	166.972
1288.2	176.962
1291.4	183.252
1294.6	186.768
1297.8	190.737
1301	194.009
1304.19	195.413
1307.39	195.161
1310.58	193.438
1313.77	190.864
1316.96	186.873
1320.15	181.589
1323.34	173.209
1326.53	164.761
1329.72	156.474
1332.9	149.198
1336.08	146.919
1339.27	147.843
1342.45	145.148
1345.63	142.774
1348.8	140.424
1351.98	139.84
1355.16	139.038
1358.33	139.926
1361.51	138.353
1364.68	136.328
1367.85	134.634
1371.02	132.71
1374.19	129.621
1377.36	125.744
1380.52	126.501
1383.69	125.386
1386.85	125.706
1390.02	126.667
1393.18	126.299
1396.34	124.196
1399.5	126.355
1402.65	132.989
1405.81	145.165
1408.97	160.13
1412.12	176.788
1415.27	195.657
1418.43	215.798
1421.58	237.412
1424.73	260.898
1427.87	284.944
1431.02	308.953
1434.17	329.112
1437.31	346.969
1440.46	360.542
1443.6	370.726
1446.74	372.948
1449.88	371.639
1453.02	362.825
1456.16	351.017
1459.29	334.262
1462.43	313.701
1465.56	288.76
1468.69	262.102
1471.83	235.33
1474.95	208.11
1478.08	185.519
1481.21	164.214
1484.34	143.734
1487.47	123.21
1490.59	105.968
1493.71	91.8636
1496.84	82.2188
1499.96	72.6774
1503.07	64.894
1506.19	59.8115
1509.31	54.2562
1512.43	53.1683
1515.54	52.053
1518.65	51.2079
1521.77	50.5015
1524.88	48.7269
1527.99	50.6928
1531.1	50.7044
1534.21	54.0234
1537.31	55.6118
1540.42	59.1559
1543.52	61.9674
1546.63	67.4717
1549.73	70.3563
1552.83	74.0749
1555.93	77.1812
1559.03	80.2799
1562.12	83.2256
1565.22	87.0936
1568.31	91.7926
1571.41	95.5195
1574.5	99.8682
1577.59	103.52
1580.68	108.035
1583.77	113.53
1586.86	117.6
1589.95	121.825
1593.03	126.173
1596.11	128.499
1599.2	128.971
1602.28	129.136
1605.36	129.542
1608.44	128.054
1611.52	128.171
1614.6	127.956
1617.67	128.821
1620.75	127.641
1623.82	125.459
1626.89	125.461
1629.96	126.089
1633.04	124.871
1636.11	125.492
1639.17	124.67
1642.24	127.516
1645.31	129.106
1648.37	131.112
1651.43	131.91
1654.5	132.379
1657.56	131.259
1660.62	129.749
1663.67	126.683
1666.73	122.744
1669.79	117.162
1672.84	110.705
1675.9	105.285
1678.95	97.2841
1682	90.6953
1685.05	84.9269
1688.1	79.0793
1691.15	72.7539
1694.2	66.0667
1697.25	59.9117
1700.29	56.6566
1703.33	53.1099
1706.38	49.339
1709.42	46.4374
1712.46	44.047
1715.5	42.6057
1718.54	43.9231
1721.57	43.2636
1724.61	42.6044
1727.64	43.0069
1730.68	40.9824
1733.71	40.6128
1736.74	40.0859
1739.77	38.9527
1742.8	36.9136
1745.83	33.9516
1748.85	31.6768
1751.88	29.1884
1754.91	26.42
1757.93	23.8797
1760.95	21.4969
1763.97	18.8934
1766.99	15.8784
1770.01	12.9096
1773.03	9.90856
1776.04	8.09955
1779.06	7.53793
1782.07	6.03983
1785.09	6.1433
1788.1	5.48715
1791.11	6.79121
1794.12	6.59022
1797.13	5.02844
1800.13	5.44897
1803.14	6.68211
1806.15	5.63369
1809.15	5.85692
1812.15	5.08111
1815.16	4.22556
1818.15	2.93029
1821.16	2.82411
1824.15	3.26363
1827.15	4.81974
1830.15	4.74978
1833.14	3.48508
1836.14	2.36623
1839.13	0.362846
1842.12	0.394042
1845.11	-0.167599
1848.1	-0.301799
1851.09	-0.787185
1854.08	1.28783
1857.06	1.75272
1860.05	1.95931
1863.03	1.78723
1866.01	1.91856
1869	1.65931
1871.98	2.00986
1874.96	3.87605
1877.93	3.40353
1880.91	2.55624
1882.47	2.28749
1885.46	1.72037
1888.44	2.89445
1891.43	3.55117
1894.42	4.43676
1897.4	4.6935
1900.39	5.25402
1903.37	4.21948
1906.35	2.08866
1909.33	2.60283
1912.31	2.52155
1915.29	3.02275
1918.26	3.11488
1921.24	3.00492
1924.21	3.71043
1927.19	3.14865
1930.16	1.41809
1933.13	1.7315
1936.1	0.826964
1939.07	1.12103
1942.04	1.16015
1945	1.41136
1947.97	1.00707
1950.93	1.12336
1953.9	1.00763
1956.86	2.34153
1959.82	3.2547
1962.78	2.41132
1965.74	3.50579
1968.7	3.33321
1971.65	4.9178
1974.61	5.20784
1977.57	4.39279
1980.52	4.96558
1983.47	5.23638
1986.42	4.89925
1989.37	5.50112
1992.32	5.41406
1995.27	6.09934
1998.22	4.72236
2001.17	4.24768
2004.11	5.55079
2007.05	5.28984
2010	4.8241
2012.94	3.90015
2015.88	2.99212
2018.82	1.94873
2021.76	2.80485
2024.7	3.58138
2027.63	5.14171
2030.57	4.71027
2033.5	4.09776
2036.44	5.08728
2039.37	5.96181
2042.3	7.64327
2045.23	7.82466
2048.16	8.38302
2051.08	8.39324
2054.01	9.32447
2056.94	7.86422
2059.86	8.91327
2062.79	10.5417
2065.71	10.3138
2068.63	10.1941
2071.55	9.90963
2074.47	11.8995
2077.39	10.7924
2080.31	10.639
2083.22	10.2513
2086.13	11.4184
2089.05	12.2656
2091.96	15.7231
2094.87	16.5271
2097.78	17.188
2100.69	18.1133
2103.6	19.3932
2106.51	21.0864
2109.42	24.6632
2112.32	26.7055
2115.23	29.2729
2118.13	30.3232
2121.03	31.792
2123.93	33.3678
2126.83	34.6446
2129.73	37.0256
2132.63	40.0208
2135.53	41.9778
2138.42	45.7665
2141.32	48.5335
2144.21	52.3495
2147.1	54.7258
2150	57.4808
2152.89	59.8173
2155.78	62.9744
2158.66	64.0886
2161.55	67.6237
2164.44	69.023
2167.32	70.2705
2170.21	71.8093
2173.09	73.6607
2175.97	74.2459
2178.85	73.9524
2181.73	72.9813
2184.61	72.0303
2187.49	70.2356
2190.37	68.1746
2193.24	66.038
2196.12	64.1988
2198.99	61.64
2201.87	58.9956
2204.74	56.9734
2207.61	53.8169
2210.48	51.8472
2213.35	48.4504
2216.21	44.6314
2219.08	41.146
2221.95	38.3365
2224.81	34.5446
2227.67	32.7255
2230.54	30.6375
2233.4	28.8002
2236.26	27.5906
2239.11	24.6057
2241.97	23.8418
2244.83	22.6644
2247.69	21.6046
2250.54	21.8141
2253.4	20.5896
2256.25	19.0877
2259.1	18.3732
2261.95	18.3459
2264.8	17.6221
2267.65	18.1141
2270.5	17.649
2273.34	17.9073
2276.19	18.4209
2279.03	17.6346
2281.88	17.801
2284.72	16.7548
2287.56	14.7914
2290.4	13.7994
2293.24	11.3464
2296.08	9.76997
2298.92	9.36311
2301.76	9.63703
2304.59	10.5722
2307.43	10.5763
2310.26	10.4294
2313.09	10.7811
2315.92	11.6456
2318.75	10.8082
2321.58	10.7339
2324.41	9.36433
2327.24	7.79084
2330.06	7.54074
2332.89	6.37228
2335.71	6.7131
2338.54	7.53249
2341.36	7.07797
2344.18	7.13108
2347	6.49757
2349.82	5.76578
2352.64	4.30456
2355.45	3.08995
2358.27	2.03375
2361.08	1.79287
2363.9	0.549315
2366.71	0.948863
2369.52	2.30047
2372.33	3.38593
2375.14	4.21782
2377.95	3.1947
2380.76	4.34436
2383.57	4.96451
2386.37	4.68103
2389.18	3.40759
2391.98	3.0271
2394.79	3.95742
2397.59	4.77973
2400.39	3.62194
2403.19	3.74366
2405.99	4.48723
2408.78	4.09237
2411.58	5.98069
2414.38	6.73136
2417.17	6.09645
2419.97	5.80261
2422.76	5.34736
2425.55	5.37106
2428.34	5.57517
2431.13	4.84943
2433.92	4.04557
2436.71	4.1512
2439.49	5.00972
2442.28	4.46378
2445.06	5.4248
2447.85	5.63187
2450.63	4.71085
2453.41	4.9514
2456.19	5.03185
2458.97	5.61835
2461.75	4.80293
2464.53	5.00702
2467.31	3.97432
2470.08	2.77889
2472.86	3.15082
2475.63	2.90034
2478.4	2.16816
2481.17	1.93094
2483.94	1.31033
2486.72	1.12965
2489.48	-0.0891442
2492.25	-2.11282
2495.02	-2.76607
2497.79	-1.96556
2500.55	-1.51123
2503.31	-0.481746
2506.08	1.05283
2508.84	2.19637
2511.6	2.8398
2514.36	4.73361
2517.12	3.51828
2519.88	5.05436
2522.63	6.84561
2525.39	7.43422
2528.14	7.48712
2530.9	8.40411
2533.65	9.29526
2536.4	10.8697
2539.15	11.0135
2541.9	12.0739
2544.65	12.4315
2547.4	13.1806
2550.15	13.6369
2552.89	12.6798
2555.64	11.4808
2558.38	9.90265
2561.12	10.3672
2563.87	10.9868
2566.61	12.642
2569.35	11.8095
2572.09	10.5918
2574.83	10.8112
2577.56	11.2386
2580.3	11.0242
2583.04	11.186
2585.77	11.4891
2588.5	12.4987
2591.23	11.5462
2593.97	12.2984
2596.7	12.7471
2599.43	14.0083
2602.15	13.4937
2604.88	14.135
2607.61	13.6913
2610.33	15.0636
2613.06	14.0862
2615.78	13.026
2618.51	12.2592
2621.23	10.5976
2623.95	9.83688
2626.67	9.73166
2629.39	8.21592
2632.1	7.8626
2634.82	7.23248
2637.54	5.7157
2640.25	6.22086
2642.97	7.34642
2645.68	7.66437
2648.39	8.85415
2651.1	10.477
2653.81	11.6862
2656.52	11.8495
2659.23	11.5985
2661.94	12.9788
2664.64	13.9851
2667.35	14.9667
2670.05	15.5576
2672.76	16.6752
2675.46	17.6424
2678.16	19.1083
2680.86	19.0455
2683.56	19.8829
2686.26	21.5276
2688.96	22.766
2691.65	25.1113
2694.35	27.7767
2697.04	30.0461
2699.74	32.9128
2702.43	36.8029
2705.12	40.384
2707.81	43.843
2710.5	48.3777
2713.19	52.6907
2715.88	54.1189
2718.57	54.6146
2721.25	55.1671
2723.94	54.6466
2726.62	53.5383
2729.3	52.0808
2731.99	49.7922
2734.67	46.4472
2737.35	42.5451
2740.03	38.2042
2742.71	34.2459
2745.38	29.0177
2748.06	24.7758
2750.74	20.7386
2753.41	16.3404
2756.09	12.5904
2758.76	9.70334
2761.43	6.83595
2764.1	6.00156
2766.77	5.20993
2769.44	4.25569
2772.11	4.02064
2774.77	2.5576
2777.44	1.4579
2780.11	0.190335
2782.77	-0.179338
2785.43	-0.640856
2788.1	-1.55331
2790.76	-2.35242
2793.42	-1.63717
2796.08	-0.293256
2798.74	-0.862133
2801.4	-1.58717
2804.05	-4.11879
2806.71	-6.90075
2809.36	-10.4148
2812.02	-9.72106
2814.67	-5.17106
2817.32	7.39531
2819.97	27.9383
2822.62	58.6985
2825.27	96.503
2827.92	138.07
2830.57	182.477
2833.22	227.937
2835.86	273.819
2838.51	318.986
2841.15	365.618
2843.79	410.663
2846.43	451.727
2849.08	494.377
2851.72	541.969
2854.36	590.965
2856.99	638.677
2859.63	682.085
2862.27	716.463
2864.9	744.198
2867.54	765.402
2870.17	780.913
2872.8	793.797
2875.43	804.807
2878.07	818.562
2880.7	831.556
2883.32	843.962
2885.95	856.162
2888.58	867.236
2891.21	873.3
2893.83	875.147
2896.46	874.694
2899.08	873.479
2901.7	871.488
2904.32	871.908
2906.94	874.429
2909.56	880.261
2912.18	891.185
2914.8	908.913
2917.42	925.959
2920.03	938.895
2922.65	946.456
2925.26	944.598
2927.88	941.357
2930.49	933.165
2933.1	920.984
2935.71	905.044
2938.32	882.686
2940.93	856.999
2943.54	826.397
2946.14	790.833
2948.75	754.132
2951.35	716.499
2953.96	675.643
2956.56	635.215
2959.16	596.291
2961.77	558.186
2964.37	521.96
2966.96	487.473
2969.56	455.432
2972.16	424.328
2974.76	395.797
2977.35	365.913
2979.95	338.192
2982.54	308.321
2985.14	278.151
2987.73	248.468
2990.32	221.619
2992.91	194.885
2995.5	171.406
2998.09	147.668
3000.68	125.596
3003.26	106.486
3005.85	87.6767
3008.43	71.8662
3011.02	57.626
3013.6	46.3915
3016.19	35.8096
3018.77	26.8466
3021.35	19.1036
3023.93	13.3674
3026.5	7.20529
3029.08	2.1321
3031.66	-0.373085
3034.24	-2.12904
3036.81	-2.55781
3039.39	-1.50315
3041.96	0.0807996
3044.53	2.98302
3047.1	5.03651
3049.67	7.45372
3052.24	9.51494
3054.81	10.8554
3057.38	14.1463
3059.95	16.9924
3062.52	17.2225
3065.08	18.5616
3067.65	19.7939
3070.21	19.2707
3072.77	19.5499
3075.33	18.0826
3077.89	18.5079
3080.45	17.037
3083.01	16.8313
3085.57	16.4092
3088.13	16.2507
3090.68	16.9248
3093.24	17.9316
3095.79	20.0655
3098.35	22.85
3100.9	25.6087
3103.45	28.471
3106	33.6026
3108.55	39.2869
3111.1	44.0721
3113.65	48.9542
3116.2	54.1227
3118.75	60.3397
3121.29	66.4404
3123.84	71.7705
3126.38	76.765
3128.92	82.6331
3131.47	88.5241
3134.01	94.5523
3136.55	100.456
3139.09	108.034
3141.63	115.31
3144.17	122.409
3146.7	129.784
3149.24	137.918