File: data/Raman/poly_smoothed/Mb_20_23_22_2x_45s_532 nm_x100_100%_600 gr_mm.txt
#Acq. time (s)=	45
#Accumulations=	2
#Range (cm-¹)=	200...3150
#Windows=	2
#Auto scanning=	Off
#Autofocus=	Off
#Macrospot=	Off
#AutoExposure=	Off
#Spike filter=	Multiple accum.
#Delay time (s)=	0
#Binning=	1
#Readout mode=	Signal
#DeNoise=	Off
#ICS correction=	On
#Dark correction=	Off
#Inst. Process=	Off
#Detector Gain=	Best Dynamic Range
#Detector ADC=	20 kHz
#Detector temperature (°C)=	-69.85
#Instrument=	LabRAM HR Evol
#Detector=	Synapse
#Objective=	x100
#Grating=	600 gr/mm
#ND Filter=	100%
#Laser (nm)=	532
#Hole=	100.021
#Range=	Auto
#Laser Pol.=	No
#Raman. Pol.=	No
#Laser Pol. (°)=	-0.0007625
#Raman Pol. (°)=	89.9995
#Collection=	Microscope
#StageXY=	Marzhauser
#StageZ=	Marzhauser
#X (µm)=	-6973.2
#Y (µm)=	2046.4
#Z (µm)=	-75.4
#Full time(mm:ss)=	2:47
#Project=
#Sample=
#Site=
#Title=	Mb_20_23_22_2x_45s_532 nm_x100_100%_600 gr_mm
#Remark=
#Date=	13.07.2022 14:51
#Acquired=	13.07.2022 14:51:14
#Base:Fit=	10.08.2022 10:29:37
#Base:Sub=	10.08.2022 10:33:46
#Filter:Polynom=	16.08.2022 10:13:29
#AxisType[0]=Intens
#AxisUnit[0]=Cnt
#AxisType[1]=Spectr
#AxisUnit[1]=1/cm
200.563	0.341302
204.194	5.74052
207.821	7.1935
211.449	7.92886
215.074	7.48151
218.699	7.96976
222.321	8.8541
225.941	8.56281
229.562	7.25512
233.18	7.75792
236.796	8.31316
240.411	8.91299
244.026	8.51383
247.638	8.52137
251.248	5.69118
254.857	6.31227
258.465	6.93658
262.071	7.33836
265.678	7.00634
269.282	9.63198
272.884	9.70209
276.484	6.78481
280.084	7.5496
283.682	6.88574
287.276	7.34941
290.871	5.79143
294.465	4.18909
298.057	4.83399
301.648	5.64935
305.237	4.87005
308.823	6.06243
312.41	4.99739
315.995	6.15549
319.579	6.44512
323.16	8.77485
326.741	11.4816
330.321	14.1701
333.897	15.2012
337.474	16.7082
341.048	16.5202
344.622	19.2446
348.192	21.8993
351.764	23.1887
355.332	24.8386
358.901	22.825
362.466	19.6259
366.03	18.9741
369.594	18.5436
373.155	18.9725
376.715	18.5514
380.273	18.5608
383.832	18.8491
387.388	19.95
390.942	19.6629
394.495	20.1149
398.047	20.4326
401.597	21.691
405.145	22.0836
408.693	23.2573
412.239	27.1386
415.783	28.0079
419.327	28.5999
422.869	28.8743
426.409	29.407
429.948	29.5014
433.486	29.6973
437.022	28.5747
440.558	27.3016
444.089	25.9644
447.622	22.6679
451.153	22.4379
454.682	22.6233
458.208	23.2287
461.735	24.5981
465.259	26.2515
468.783	25.8929
472.306	28.3852
475.825	29.1596
479.346	28.276
482.862	29.7193
486.38	29.8157
489.894	32.0739
493.407	34.3199
496.92	37.0449
500.43	41.2152
503.939	41.5492
507.448	42.7941
510.954	43.4275
514.459	45.6454
517.962	46.241
521.466	46.7492
524.966	46.0456
528.466	43.0555
531.964	40.5861
535.46	40.0279
538.955	39.8145
542.449	37.986
545.942	35.1313
549.433	35.9012
552.923	33.3431
556.412	31.6395
559.899	30.986
563.385	27.8242
566.867	27.6025
570.35	27.3442
573.832	26.6598
577.313	28.0313
580.79	28.542
584.268	28.2752
587.745	27.9675
591.218	27.082
594.692	28.0532
598.164	27.9941
601.634	27.5135
605.104	27.7251
608.57	26.956
612.037	24.1273
615.501	21.0809
618.966	20.5092
622.427	19.7532
625.887	17.8447
629.348	16.709
632.806	15.6056
636.262	15.7073
639.716	13.7154
643.172	13.1063
646.624	10.7372
650.075	11.6677
653.524	10.3971
656.972	10.4017
660.419	10.1691
663.865	8.71219
667.309	7.76349
670.752	5.84103
674.194	4.12435
677.634	4.8478
681.073	4.11364
684.511	5.3834
687.947	6.38097
691.382	4.04291
694.816	5.16359
698.247	6.53933
701.678	9.69564
705.108	12.4642
708.534	13.0933
711.962	15.1242
715.388	17.1939
718.81	20.0632
722.234	23.4421
725.654	24.3861
729.075	28.0593
732.492	30.3254
735.91	32.7168
739.325	33.8195
742.741	34.2261
746.153	35.7719
749.564	36.0533
752.976	35.1828
756.385	34.8541
759.792	36.9144
763.2	38.9434
766.604	40.2902
770.008	42.0139
773.41	43.4581
776.811	46.4888
780.21	48.3541
783.608	49.4838
787.005	51.2999
790.401	54.4939
793.795	56.0367
797.188	59.4683
800.58	62.8717
803.971	65.9576
807.36	67.9798
810.748	70.7756
814.135	71.7761
817.518	74.028
820.902	76.3886
824.285	79.2696
827.665	83.1542
831.045	82.1632
834.424	83.4037
837.8	84.9205
841.177	86.5152
844.55	88.4453
847.924	87.0838
851.295	86.6022
854.666	84.8435
858.034	81.1812
861.403	78.9411
864.769	76.6187
868.133	76.3848
871.498	76.7172
874.86	73.9555
878.221	69.0193
881.58	66.7362
884.938	63.4931
888.297	60.923
891.653	58.564
895.007	57.3852
898.36	55.4471
901.712	55.325
905.063	51.7726
908.412	51.3172
911.76	50.4203
915.107	46.9405
918.452	46.3978
921.797	44.3823
925.138	42.9033
928.48	38.7627
931.82	34.644
935.16	32.845
938.496	30.3623
941.833	29.1566
945.168	26.2433
948.5	24.6731
951.834	22.4528
955.163	20.0226
958.494	16.2723
961.821	12.0704
965.15	10.5088
968.474	11.6259
971.8	13.0105
975.123	14.6007
978.446	15.4026
981.766	15.9648
985.084	16.9926
988.402	17.8801
991.72	17.1885
995.035	18.4937
998.349	15.716
1001.66	13.6185
1004.97	13.7634
1008.28	14.2149
1011.59	16.3135
1014.9	20.567
1018.21	22.8251
1021.51	26.3238
1024.81	32.7256
1028.12	38.343
1031.42	44.1966
1034.72	49.6679
1038.02	53.1157
1041.31	58.7326
1044.61	64.7686
1047.91	72.1482
1051.2	78.6398
1054.49	82.5006
1057.78	87.3546
1061.07	87.5742
1064.36	87.3337
1067.65	84.8789
1070.93	79.9156
1074.22	74.285
1077.5	68.0104
1080.78	59.1308
1084.06	54.0169
1087.34	49.6431
1090.62	46.0894
1093.9	43.6341
1097.17	41.5197
1100.45	40.8677
1103.72	42.7887
1106.99	42.2051
1110.27	40.9393
1113.53	39.5958
1116.8	36.3644
1120.07	36.348
1123.33	33.8259
1126.6	31.3641
1129.86	32.0296
1133.12	29.1415
1136.38	27.7019
1139.64	24.1255
1142.9	22.332
1146.16	19.9052
1149.41	14.8772
1152.67	10.5962
1155.92	5.9178
1159.17	3.3398
1162.42	0.583547
1165.67	-0.161126
1168.92	-0.821766
1172.16	0.548102
1175.41	1.59624
1178.65	1.46178
1181.9	3.56356
1185.14	3.37151
1188.38	2.42898
1191.62	2.46294
1194.86	4.38603
1198.09	4.35626
1201.33	3.9578
1204.56	4.65017
1207.8	6.60172
1211.03	7.21185
1214.26	10.9295
1217.49	12.6601
1220.71	17.5324
1223.94	21.4725
1227.16	23.4497
1230.39	26.446
1233.61	27.9256
1236.83	30.6282
1240.05	32.888
1243.27	36.2649
1246.49	37.7534
1249.71	40.3953
1252.92	41.7433
1256.14	45.6381
1259.35	48.4774
1262.56	54.2838
1265.77	61.7277
1268.98	71.6809
1272.19	82.9591
1275.4	93.1859
1278.6	104.619
1281.81	114.12
1285.01	125.196
1288.21	135.224
1291.41	144.224
1294.61	150.899
1297.81	157.016
1301.01	160.18
1304.2	161.684
1307.4	160.901
1310.59	161.281
1313.78	157.723
1316.97	153.383
1320.16	146.354
1323.35	139.538
1326.54	131.417
1329.72	121.822
1332.91	112.205
1336.09	106.29
1339.27	101.825
1342.45	99.4265
1345.64	97.2592
1348.81	94.7944
1351.99	93.5452
1355.17	91.946
1358.34	92.2249
1361.51	90.9853
1364.69	90.588
1367.86	89.0388
1371.03	87.3858
1374.2	87.5685
1377.37	87.329
1380.53	88.1093
1383.7	90.3669
1386.86	90.2799
1390.02	89.4357
1393.19	86.8371
1396.35	84.679
1399.51	86.6443
1402.66	91.541
1405.82	100.944
1408.97	114.211
1412.13	129.51
1415.28	148.086
1418.43	167.181
1421.59	190.439
1424.73	212.645
1427.88	235.227
1431.03	257.001
1434.18	278.938
1437.32	297.221
1440.46	309.161
1443.61	318.558
1446.75	321.819
1449.89	320.479
1453.03	313.298
1456.16	303.263
1459.3	286.589
1462.44	266.01
1465.57	242.514
1468.7	214.338
1471.83	186.571
1474.96	162.746
1478.09	143.507
1481.22	123.967
1484.35	105.764
1487.47	89.2856
1490.6	74.0059
1493.72	62.7518
1496.84	53.7736
1499.96	48.2178
1503.08	42.6349
1506.2	38.1005
1509.32	36.5957
1512.44	35.4605
1515.55	32.4686
1518.66	30.9872
1521.78	28.3857
1524.89	27.3155
1528	27.4127
1531.11	28.6151
1534.21	30.0232
1537.32	31.4419
1540.43	34.1282
1543.53	36.8279
1546.63	39.3243
1549.74	42.8904
1552.84	45.7575
1555.94	48.3637
1559.03	49.9096
1562.13	51.8518
1565.23	53.9935
1568.32	58.0135
1571.42	61.5011
1574.51	68.107
1577.6	73.0697
1580.69	77.3622
1583.78	82.7306
1586.87	88.205
1589.95	88.6647
1593.04	91.4097
1596.12	92.8035
1599.21	94.7108
1602.29	96.3031
1605.37	97.5379
1608.45	97.1871
1611.53	96.5701
1614.6	96.4999
1617.68	96.4045
1620.75	93.8754
1623.83	93.5951
1626.9	92.2659
1629.97	90.9182
1633.04	89.6106
1636.11	89.0562
1639.18	88.9258
1642.25	90.9466
1645.31	92.7904
1648.38	94.6765
1651.44	96.6043
1654.5	95.913
1657.56	95.6362
1660.62	94.5343
1663.68	91.4747
1666.74	86.7997
1669.8	83.5884
1672.85	78.6776
1675.91	75.1234
1678.96	70.1024
1682.01	64.6918
1685.06	60.1064
1688.11	56.5671
1691.16	53.9555
1694.21	49.2491
1697.25	45.9149
1700.3	44.6346
1703.34	43.6299
1706.39	42.2787
1709.43	43.4125
1712.47	42.9952
1715.51	43.6066
1718.54	44.1453
1721.58	43.2939
1724.62	43.9725
1727.65	45.0152
1730.68	42.3852
1733.72	42.0595
1736.75	39.7539
1739.78	36.9204
1742.81	35.8833
1745.84	33.3603
1748.86	31.0916
1751.89	30.1386
1754.91	26.3003
1757.93	26.0786
1760.96	23.2468
1763.98	20.6303
1767	18.5586
1770.02	17.1339
1773.03	16.6217
1776.05	14.2267
1779.07	12.9145
1782.08	11.6906
1785.09	10.104
1788.11	8.73
1791.12	7.36697
1794.13	7.27486
1797.13	7.31046
1800.14	6.89716
1803.15	6.72789
1806.15	5.77216
1809.16	7.60905
1812.16	7.93782
1815.16	7.94777
1818.16	7.71549
1821.16	6.27554
1824.16	8.22124
1827.16	8.14266
1830.16	6.76233
1833.15	8.03903
1836.14	7.26753
1839.14	7.27534
1842.13	5.55595
1845.12	4.54524
1848.11	1.9352
1851.1	1.84412
1854.08	1.98572
1857.07	1.83203
1860.05	1.73687
1863.04	2.0469
1866.02	2.74412
1869	3.06042
1871.98	3.86403
1874.96	6.23014
1877.94	6.39368
1880.92	8.51002
1882.51	10.1249
1885.5	10.1825
1888.48	9.1832
1891.47	9.95538
1894.46	8.76139
1897.44	9.77399
1900.42	8.51143
1903.41	8.31252
1906.39	7.60762
1909.37	7.62898
1912.35	6.27668
1915.32	6.81307
1918.3	7.77867
1921.27	7.60608
1924.25	9.1919
1927.22	9.03797
1930.19	9.62881
1933.17	9.91155
1936.14	11.0873
1939.11	11.425
1942.07	10.9856
1945.04	10.6339
1948.01	11.1605
1950.97	11.9845
1953.93	11.7273
1956.9	9.44977
1959.86	8.2523
1962.82	7.66609
1965.78	8.0245
1968.74	6.66097
1971.69	6.71518
1974.65	4.96721
1977.6	4.55799
1980.56	5.72923
1983.51	6.0817
1986.46	7.14704
1989.41	7.90327
1992.36	8.70881
1995.31	8.43198
1998.26	9.06595
2001.2	9.56565
2004.15	9.78389
2007.09	10.0723
2010.04	9.78219
2012.98	9.92695
2015.92	9.87287
2018.86	9.37675
2021.8	9.56042
2024.73	10.7501
2027.67	10.1371
2030.61	10.1322
2033.54	11.73
2036.47	13.3366
2039.4	12.9304
2042.33	13.0152
2045.27	12.8088
2048.19	12.8097
2051.12	14.0599
2054.05	15.3962
2056.97	16.894
2059.9	16.1418
2062.82	17.0285
2065.74	15.4103
2068.67	16.0573
2071.59	16.6286
2074.51	18.0512
2077.42	17.7538
2080.34	17.5786
2083.26	17.87
2086.17	18.9374
2089.09	18.0853
2092	19.4569
2094.91	19.991
2097.82	20.6558
2100.73	20.7475
2103.64	22.0889
2106.55	23.5789
2109.45	24.3739
2112.36	25.5651
2115.26	25.2754
2118.17	26.1606
2121.07	27.6364
2123.97	28.9179
2126.87	30.7528
2129.77	32.9546
2132.67	34.5697
2135.56	36.8447
2138.46	37.8647
2141.35	40.8187
2144.25	43.5968
2147.14	46.5148
2150.03	48.3477
2152.92	50.4074
2155.81	52.9224
2158.7	53.4369
2161.59	55.1308
2164.47	56.7353
2167.36	57.892
2170.24	59.1385
2173.13	59.1399
2176.01	59.9886
2178.89	59.8316
2181.77	59.2315
2184.65	58.6436
2187.53	57.7164
2190.4	56.48
2193.28	54.6857
2196.16	53.5489
2199.03	51.5103
2201.9	48.7134
2204.77	46.4492
2207.64	44.3375
2210.51	42.6288
2213.38	40.2019
2216.25	36.8347
2219.12	33.0514
2221.98	31.716
2224.85	28.9787
2227.71	26.9264
2230.57	24.7653
2233.43	23.0726
2236.29	21.941
2239.15	21.2557
2242.01	21.7768
2244.87	22.1162
2247.72	21.5618
2250.58	21.4902
2253.43	21.4266
2256.29	21.7318
2259.14	20.1334
2261.99	19.0388
2264.84	17.785
2267.69	17.8324
2270.53	17.6002
2273.38	16.5943
2276.23	15.9663
2279.07	13.4028
2281.91	10.6972
2284.76	8.83745
2287.6	7.9655
2290.44	6.10362
2293.28	4.61401
2296.12	1.97745
2298.96	3.58744
2301.79	2.57272
2304.63	4.90512
2307.46	5.81551
2310.3	9.07753
2313.13	10.0104
2315.96	10.0427
2318.79	10.043
2321.62	10.8209
2324.45	13.1046
2327.27	14.2872
2330.1	13.2282
2332.92	13.6179
2335.75	14.1162
2338.57	15.0033
2341.39	15.4685
2344.21	13.5318
2347.04	12.3486
2349.85	10.8811
2352.67	10.3112
2355.49	9.28257
2358.3	6.35332
2361.12	5.7366
2363.93	5.00281
2366.75	4.65484
2369.56	4.95553
2372.37	3.93499
2375.18	3.8976
2377.99	3.69951
2380.8	3.70996
2383.6	2.67533
2386.41	1.64953
2389.21	3.02714
2392.02	3.74276
2394.82	2.63418
2397.62	2.66132
2400.42	3.0283
2403.22	3.8267
2406.02	4.61646
2408.82	5.4691
2411.62	7.13171
2414.41	8.72716
2417.21	9.958
2420	12.2177
2422.79	13.0946
2425.59	12.9538
2428.38	13.5115
2431.17	13.6532
2433.95	13.5008
2436.74	12.5306
2439.53	12.8405
2442.31	11.3105
2445.1	10.9554
2447.88	10.0704
2450.67	9.3881
2453.45	6.1876
2456.23	4.10001
2459.01	2.96504
2461.79	1.75358
2464.57	0.200848
2467.34	0.839459
2470.12	-0.409751
2472.89	-0.251585
2475.67	-0.797038
2478.44	0.321876
2481.21	-0.0358939
2483.98	-0.53614
2486.75	-1.49134
2489.52	-2.19055
2492.29	-3.0965
2495.05	-2.75591
2497.82	-2.83449
2500.58	-2.48828
2503.35	-2.45791
2506.11	-2.56687
2508.87	-1.53346
2511.63	-1.27928
2514.39	-1.43023
2517.15	-0.716382
2519.91	-0.0925047
2522.67	0.518721
2525.42	1.08685
2528.18	3.40874
2530.93	3.33417
2533.69	3.95037
2536.44	4.88156
2539.19	4.90267
2541.94	4.65131
2544.69	4.28191
2547.44	3.76272
2550.18	3.31978
2552.93	4.06791
2555.67	3.66612
2558.42	3.52027
2561.16	3.96082
2563.9	4.35672
2566.64	4.5442
2569.38	4.75381
2572.12	4.93435
2574.86	5.22827
2577.6	4.6923
2580.33	6.20793
2583.07	6.98102
2585.8	6.95299
2588.54	7.21904
2591.27	7.9833
2594	9.89245
2596.73	10.2214
2599.46	10.4607
2602.19	10.7223
2604.92	9.52368
2607.64	8.23493
2610.37	8.50185
2613.09	9.59443
2615.82	10.6621
2618.54	11.9569
2621.26	11.5797
2623.98	11.7753
2626.7	11.1537
2629.42	10.0879
2632.14	9.63754
2634.86	9.50241
2637.57	9.51374
2640.29	9.96235
2643	10.574
2645.71	11.2625
2648.43	11.7447
2651.14	12.3401
2653.85	12.0809
2656.56	12.3531
2659.26	11.4736
2661.97	11.326
2664.68	11.9687
2667.38	9.57787
2670.09	8.68581
2672.79	8.44803
2675.49	9.39365
2678.19	10.7057
2680.89	10.8355
2683.59	12.4849
2686.29	12.3948
2688.99	13.2953
2691.69	14.2965
2694.38	16.961
2697.08	20.5305
2699.77	23.9936
2702.46	27.23
2705.15	31.6422
2707.85	33.7983
2710.54	36.8734
2713.22	39.5804
2715.91	41.3164
2718.6	41.7005
2721.29	41.6744
2723.97	42.7851
2726.66	43.0824
2729.34	41.2006
2732.02	38.0024
2734.7	34.3211
2737.38	31.8124
2740.06	29.0732
2742.74	26.6127
2745.42	23.5927
2748.09	20.4019
2750.77	18.3951
2753.45	15.6387
2756.12	14.259
2758.79	12.4102
2761.46	11.2548
2764.14	8.64824
2766.8	7.54051
2769.47	4.88408
2772.14	5.08756
2774.81	3.91069
2777.48	4.27821
2780.14	3.42458
2782.8	2.76339
2785.47	1.7875
2788.13	3.26016
2790.79	2.94839
2793.45	1.56196
2796.11	1.08243
2798.77	1.52615
2801.43	2.2927
2804.09	3.19865
2806.74	2.955
2809.4	0.179339
2812.05	-2.58615
2814.71	-4.69312
2817.36	-0.621177
2820.01	12.5732
2822.66	34.6756
2825.31	63.9406
2827.96	100.7
2830.6	142.099
2833.25	188.87
2835.9	235.197
2838.54	281.905
2841.18	329.734
2843.83	377.225
2846.47	424.194
2849.11	470.16
2851.75	515.269
2854.39	559.776
2857.03	597.097
2859.66	631.884
2862.3	662.8
2864.94	687.98
2867.57	705.732
2870.2	716.657
2872.84	722.856
2875.47	726.204
2878.1	731.739
2880.73	740.193
2883.36	752.009
2885.99	767.398
2888.61	780.622
2891.24	793.599
2893.86	805.677
2896.49	815.09
2899.11	823.239
2901.73	831.221
2904.36	840.858
2906.98	852.393
2909.6	864.214
2912.21	876.849
2914.83	889.017
2917.45	899.335
2920.07	905.127
2922.68	905.988
2925.29	903.072
2927.91	894.77
2930.52	880.408
2933.13	861.658
2935.74	841.02
2938.35	816.292
2940.96	787.31
2943.57	755.961
2946.18	720.222
2948.78	682.044
2951.39	642.711
2953.99	603.112
2956.59	564.423
2959.2	525.912
2961.8	488.425
2964.4	452.198
2967	419.437
2969.6	391.931
2972.19	363.522
2974.79	335.33
2977.39	310.735
2979.98	284.202
2982.58	257.371
2985.17	231.44
2987.76	205.903
2990.35	182.729
2992.94	160.248
2995.53	139.297
2998.12	121.121
3000.71	104.017
3003.3	88.3749
3005.88	76.3036
3008.47	65.2697
3011.05	54.8814
3013.64	45.7251
3016.22	38.8557
3018.8	32.0496
3021.38	25.5877
3023.96	19.4342
3026.54	14.4947
3029.12	10.2167
3031.69	6.74208
3034.27	3.95146
3036.84	3.02675
3039.42	1.99355
3041.99	1.66561
3044.57	1.07675
3047.14	1.41463
3049.71	2.69693
3052.28	3.92179
3054.85	4.37985
3057.41	5.70246
3059.98	6.96362
3062.55	7.15703
3065.11	8.01242
3067.68	9.175
3070.24	10.3439
3072.8	11.0687
3075.36	11.3705
3077.93	11.8913
3080.49	12.5716
3083.04	12.029
3085.6	11.7917
3088.16	12.3119
3090.72	12.3779
3093.27	12.4547
3095.83	7.40875
3098.38	6.64789
3100.93	13.2367
3103.49	19.1751
3106.04	24.7668
3108.59	31.8155
3111.14	37.0863
3113.69	42.0446
3116.23	48.404
3118.78	53.7064
3121.33	58.3376
3123.87	62.8383
3126.41	68.7932
3128.96	72.7632
3131.5	77.9435
3134.04	81.7528
3136.58	85.6408
3139.12	86.0416
3141.66	85.2541
3144.2	81.167
3146.74	74.1181
3149.27	64.9328