File: data/Raman/poly_smoothed/Mb_20_23_29_1x_45s_532 nm_x100_100%_600 gr_mm_01.txt
#Acq. time (s)=	45
#Accumulations=	2
#Range (cm-¹)=	200...3150
#Windows=	2
#Auto scanning=	Off
#Autofocus=	Off
#Macrospot=	Off
#AutoExposure=	Off
#Spike filter=	Multiple accum.
#Delay time (s)=	0
#Binning=	1
#Readout mode=	Signal
#DeNoise=	Off
#ICS correction=	On
#Dark correction=	Off
#Inst. Process=	Off
#Detector Gain=	Best Dynamic Range
#Detector ADC=	20 kHz
#Detector temperature (°C)=	-69.85
#Instrument=	LabRAM HR Evol
#Detector=	Synapse
#Objective=	x100
#Grating=	600 gr/mm
#ND Filter=	100%
#Laser (nm)=	532
#Hole=	100.021
#Range=	Auto
#Laser Pol.=	No
#Raman. Pol.=	No
#Laser Pol. (°)=	-0.0007625
#Raman Pol. (°)=	89.9995
#Collection=	Microscope
#StageXY=	Marzhauser
#StageZ=	Marzhauser
#X (µm)=	-6933
#Y (µm)=	2022.7
#Z (µm)=	-74.95
#Full time(mm:ss)=	3:19
#Project=
#Sample=
#Site=
#Title=	Mb_20_23_29_2x_45s_532 nm_x100_100%_600 gr_mm
#Remark=
#Date=	13.07.2022 15:26
#Acquired=	13.07.2022 15:26:08
#Base:Fit=	10.08.2022 10:29:37
#Base:Sub=	10.08.2022 10:33:46
#Filter:Polynom=	16.08.2022 10:13:29
#AxisType[0]=Intens
#AxisUnit[0]=Cnt
#AxisType[1]=Spectr
#AxisUnit[1]=1/cm
200.563	33.1852
204.194	27.7706
207.821	24.8678
211.449	20.5994
215.074	19.8208
218.699	19.8858
222.321	21.3531
225.941	20.3865
229.562	19.4422
233.18	20.1786
236.796	18.5804
240.411	17.108
244.026	16.2675
247.638	14.8526
251.248	13.6625
254.857	13.8963
258.465	14.4636
262.071	13.2372
265.678	13.2292
269.282	13.4047
272.884	13.2312
276.484	9.71527
280.084	4.32285
283.682	4.18986
287.276	4.25135
290.871	3.03803
294.465	1.44429
298.057	2.80253
301.648	3.06815
305.237	5.38069
308.823	5.33526
312.41	5.57773
315.995	4.62022
319.579	7.6049
323.16	6.7124
326.741	8.07559
330.321	9.15791
333.897	8.95202
337.474	9.39587
341.048	8.06173
344.622	8.8219
348.192	11.1028
351.764	10.2098
355.332	9.8071
358.901	9.85995
362.466	8.01906
366.03	6.56568
369.594	7.98726
373.155	10.854
376.715	11.6406
380.273	11.6722
383.832	11.552
387.388	9.8396
390.942	9.54799
394.495	11.4955
398.047	12.5131
401.597	11.4792
405.145	12.1013
408.693	11.9692
412.239	11.409
415.783	11.5253
419.327	8.44233
422.869	7.55208
426.409	8.39389
429.948	8.37812
433.486	10.9913
437.022	10.359
440.558	11.1828
444.089	12.5779
447.622	13.2627
451.153	15.3592
454.682	18.008
458.208	19.6437
461.735	19.7175
465.259	19.2391
468.783	18.6962
472.306	20.5207
475.825	22.9262
479.346	27.0699
482.862	30.0494
486.38	29.505
489.894	31.4083
493.407	32.3466
496.92	33.5499
500.43	33.7184
503.939	34.8293
507.448	36.2272
510.954	37.9148
514.459	39.993
517.962	39.9196
521.466	41.5182
524.966	40.7231
528.466	40.2268
531.964	40.6992
535.46	37.8949
538.955	34.2786
542.449	31.3769
545.942	28.9891
549.433	27.2102
552.923	25.489
556.412	26.0064
559.899	25.2888
563.385	24.6178
566.867	21.9567
570.35	18.1798
573.832	15.7319
577.313	14.7887
580.79	13.5258
584.268	11.6255
587.745	11.3483
591.218	9.5182
594.692	9.28148
598.164	7.40706
601.634	7.50849
605.104	6.61832
608.57	4.96536
612.037	4.15242
615.501	6.14103
618.966	4.54321
622.427	2.00653
625.887	2.46997
629.348	3.41115
632.806	3.17705
636.262	2.33905
639.716	4.04332
643.172	4.20259
646.624	2.42651
650.075	1.44116
653.524	0.397655
656.972	0.339814
660.419	2.42874
663.865	4.02083
667.309	3.30256
670.752	5.11503
674.194	7.59146
677.634	7.94327
681.073	9.10354
684.511	10.2595
687.947	10.1256
691.382	10.6584
694.816	10.2702
698.247	10.2413
701.678	11.0069
705.108	9.22232
708.534	9.58718
711.962	9.56426
715.388	8.87781
718.81	7.6075
722.234	8.34387
725.654	6.91851
729.075	6.52047
732.492	5.67886
735.91	8.05285
739.325	10.3216
742.741	14.2563
746.153	18.7644
749.564	21.1616
752.976	25.7384
756.385	28.638
759.792	31.2268
763.2	34.2941
766.604	36.4774
770.008	38.3569
773.41	42.192
776.811	44.9227
780.21	47.7527
783.608	49.161
787.005	50.8217
790.401	53.3324
793.795	54.5066
797.188	56.0648
800.58	59.8045
803.971	60.9069
807.36	63.0089
810.748	65.3958
814.135	67.9913
817.518	71.0191
820.902	72.2103
824.285	75.0294
827.665	77.4548
831.045	78.8782
834.424	80.9421
837.8	82.4599
841.177	83.6619
844.55	84.3667
847.924	85.6606
851.295	86.4291
854.666	88.5731
858.034	89.2433
861.403	89.7058
864.769	89.2779
868.133	87.695
871.498	88.1656
874.86	85.7556
878.221	82.4339
881.58	80.7742
884.938	76.4018
888.297	71.6981
891.653	68.3813
895.007	66.148
898.36	60.8822
901.712	60.1074
905.063	57.5812
908.412	55.098
911.76	54.076
915.107	53.282
918.452	52.3994
921.797	50.4472
925.138	48.8149
928.48	46.5914
931.82	47.7434
935.16	47.2522
938.496	46.1041
941.833	42.9697
945.168	39.3971
948.5	35.069
951.834	32.6906
955.163	29.1099
958.494	25.1829
961.821	19.7825
965.15	19.3751
968.474	17.9216
971.8	17.1531
975.123	17.4341
978.446	19.4691
981.766	19.3759
985.084	20.7479
988.402	20.0868
991.72	21.6763
995.035	23.3362
998.349	24.8545
1001.66	28.5323
1004.97	30.5088
1008.28	34.0407
1011.59	38.7955
1014.9	41.585
1018.21	43.6082
1021.51	45.1656
1024.81	48.5464
1028.12	55.5315
1031.42	63.2791
1034.72	67.4065
1038.02	73.3534
1041.31	79.3641
1044.61	86.8859
1047.91	92.4218
1051.2	95.7146
1054.49	100.566
1057.78	104.109
1061.07	107.17
1064.36	106.682
1067.65	105.229
1070.93	104.428
1074.22	100.855
1077.5	96.2086
1080.78	91.3206
1084.06	87.284
1087.34	80.5028
1090.62	76.3351
1093.9	73.8308
1097.17	72.5357
1100.45	71.4717
1103.72	71.6936
1106.99	72.3529
1110.27	70.9483
1113.53	67.9566
1116.8	66.6574
1120.07	64.447
1123.33	61.8795
1126.6	59.994
1129.86	55.4326
1133.12	52.9382
1136.38	49.6222
1139.64	45.9004
1142.9	40.1553
1146.16	32.1091
1149.41	25.7598
1152.67	18.9036
1155.92	13.2967
1159.17	7.58814
1162.42	3.74938
1165.67	0.297299
1168.92	-1.14506
1172.16	-0.359277
1175.41	1.73797
1178.65	1.85641
1181.9	1.1118
1185.14	-0.718646
1188.38	-0.541521
1191.62	0.322441
1194.86	2.11505
1198.09	3.79256
1201.33	4.25165
1204.56	5.66108
1207.8	7.007
1211.03	9.65173
1214.26	13.491
1217.49	17.55
1220.71	19.3205
1223.94	22.9289
1227.16	28.5234
1230.39	35.3488
1233.61	41.2405
1236.83	46.3003
1240.05	52.68
1243.27	58.0317
1246.49	62.2013
1249.71	65.9022
1252.92	68.7064
1256.14	69.0083
1259.35	74.9329
1262.56	84.6922
1265.77	95.9601
1268.98	109.146
1272.19	124.405
1275.4	138.769
1278.6	152.934
1281.81	166.409
1285.01	176.457
1288.21	185.57
1291.41	193.594
1294.61	199.378
1297.81	203.269
1301.01	205.752
1304.2	206.629
1307.4	205.929
1310.59	202.537
1313.78	198.268
1316.97	189.545
1320.16	178.552
1323.35	165.536
1326.54	152.783
1329.72	138.261
1332.91	127.533
1336.09	121.734
1339.27	117.8
1342.45	114.469
1345.64	112.156
1348.81	111.252
1351.99	110.441
1355.17	108.332
1358.34	106.404
1361.51	102.69
1364.69	100.299
1367.86	98.676
1371.03	97.5331
1374.2	95.6783
1377.37	96.0771
1380.53	96.1296
1383.7	95.0776
1386.86	97.0156
1390.02	99.4995
1393.19	98.97
1396.35	96.3875
1399.51	98.5314
1402.66	105.419
1405.82	121.221
1408.97	140.227
1412.13	164.329
1415.28	188.748
1418.43	215.369
1421.59	246.917
1424.73	277.73
1427.88	307.26
1431.03	335.666
1434.18	362.495
1437.32	383.148
1440.46	399.731
1443.61	411.396
1446.75	415.419
1449.89	414.552
1453.03	407.156
1456.16	391.749
1459.3	371.296
1462.44	346.573
1465.57	316.542
1468.7	281.086
1471.83	245.15
1474.96	211.995
1478.09	183.022
1481.22	157.216
1484.35	133.392
1487.47	113.513
1490.6	93.1511
1493.72	74.9021
1496.84	62.2174
1499.96	53.6187
1503.08	43.8911
1506.2	36.4463
1509.32	32.6117
1512.44	29.7701
1515.55	27.1528
1518.66	24.9534
1521.78	21.5118
1524.89	21.2479
1528	20.5282
1531.11	23.3239
1534.21	24.7566
1537.32	28.3095
1540.43	30.878
1543.53	34.7273
1546.63	38.4444
1549.74	43.5043
1552.84	48.6574
1555.94	51.4126
1559.03	54.8824
1562.13	57.3717
1565.23	60.5652
1568.32	65.1517
1571.42	71.7563
1574.51	77.2581
1577.6	83.5468
1580.69	89.6413
1583.78	93.9465
1586.87	99.3504
1589.95	103.759
1593.04	106.662
1596.12	110.005
1599.21	110.441
1602.29	112.013
1605.37	114.247
1608.45	115.442
1611.53	112.614
1614.6	110.811
1617.68	109.721
1620.75	108.982
1623.83	107.459
1626.9	104.644
1629.97	101.724
1633.04	98.0655
1636.11	97.1361
1639.18	97.2868
1642.25	99.4006
1645.31	101.353
1648.38	104.064
1651.44	104.535
1654.5	106.421
1657.56	104.671
1660.62	104.626
1663.68	102.493
1666.74	101.247
1669.8	98.3731
1672.85	93.7319
1675.91	90.1036
1678.96	86.337
1682.01	81.387
1685.06	74.5641
1688.11	70.7683
1691.16	66.9286
1694.21	62.7328
1697.25	58.921
1700.3	57.2393
1703.34	53.1814
1706.39	51.7242
1709.43	49.7093
1712.47	51.7185
1715.51	52.5575
1718.54	54.1032
1721.58	54.95
1724.62	55.9103
1727.65	54.5506
1730.68	54.4794
1733.72	53.9503
1736.75	52.5751
1739.78	50.766
1742.81	48.7676
1745.84	47.3259
1748.86	44.143
1751.89	41.8436
1754.91	39.1623
1757.93	34.6722
1760.96	30.6646
1763.98	27.1829
1767	23.369
1770.02	19.089
1773.03	15.7082
1776.05	11.4282
1779.07	8.79299
1782.08	7.33506
1785.09	7.35373
1788.11	6.44956
1791.12	4.1527
1794.13	4.03549
1797.13	3.01342
1800.14	2.34644
1803.15	1.89075
1806.15	2.58904
1809.16	2.80435
1812.16	2.71132
1815.16	3.70326
1818.16	4.71541
1821.16	4.22428
1824.16	3.87581
1827.16	3.74358
1830.16	4.1165
1833.15	3.54006
1836.14	3.25065
1839.14	3.76509
1842.13	2.91103
1845.12	3.84354
1848.11	4.19776
1851.1	3.34691
1854.08	2.71164
1857.07	1.97683
1860.05	-0.28065
1863.04	-1.01179
1866.02	-2.01949
1869	-0.265631
1871.98	0.433347
1874.96	0.450608
1877.94	1.1576
1880.92	2.20496
1882.51	1.66641
1885.5	1.67984
1888.48	1.16167
1891.47	2.2387
1894.46	3.12644
1897.44	2.7446
1900.42	5.58206
1903.41	7.62494
1906.39	7.59342
1909.37	7.76546
1912.35	9.23312
1915.32	9.49848
1918.3	9.94427
1921.27	9.90844
1924.25	9.06783
1927.22	9.88076
1930.19	9.10594
1933.17	9.62941
1936.14	10.4344
1939.11	10.5224
1942.07	11.4623
1945.04	9.69735
1948.01	9.51532
1950.97	9.46944
1953.93	9.27098
1956.9	9.11336
1959.86	8.70435
1962.82	7.98887
1965.78	9.31652
1968.74	9.17745
1971.69	10.2217
1974.65	8.87307
1977.6	8.03775
1980.56	7.17967
1983.51	8.62734
1986.46	9.61545
1989.41	8.93843
1992.36	10.4746
1995.31	11.5466
1998.26	10.7645
2001.2	12.051
2004.15	12.3988
2007.09	13.6489
2010.04	12.6331
2012.98	12.2481
2015.92	12.5326
2018.86	11.2306
2021.8	11.1923
2024.73	10.2489
2027.67	10.7141
2030.61	10.8268
2033.54	10.7325
2036.47	11.7566
2039.4	11.0635
2042.33	10.2577
2045.27	9.10145
2048.19	8.54156
2051.12	9.45254
2054.05	11.5044
2056.97	11.7305
2059.9	11.9712
2062.82	14.2014
2065.74	14.4921
2068.67	14.2352
2071.59	15.0199
2074.51	16.7862
2077.42	17.2854
2080.34	17.6599
2083.26	18.8147
2086.17	19.6282
2089.09	20.2773
2092	21.0787
2094.91	21.984
2097.82	22.5767
2100.73	23.4693
2103.64	24.7017
2106.55	24.0143
2109.45	22.4172
2112.36	21.5322
2115.26	21.71
2118.17	21.364
2121.07	22.6737
2123.97	24.131
2126.87	25.9504
2129.77	27.4074
2132.67	28.7988
2135.56	30.4011
2138.46	32.4191
2141.35	36.9323
2144.25	39.9932
2147.14	44.9867
2150.03	47.7734
2152.92	51.8073
2155.81	55.9397
2158.7	58.8851
2161.59	62.0946
2164.47	63.7389
2167.36	66.2123
2170.24	67.5523
2173.13	69.8322
2176.01	70.0446
2178.89	69.3155
2181.77	68.5933
2184.65	67.8098
2187.53	66.8944
2190.4	65.0841
2193.28	62.7773
2196.16	60.5584
2199.03	58.375
2201.9	55.2412
2204.77	52.008
2207.64	49.8513
2210.51	46.4921
2213.38	43.3206
2216.25	39.8928
2219.12	36.4385
2221.98	34.1058
2224.85	32.9688
2227.71	31.3281
2230.57	28.3756
2233.43	27.5051
2236.29	26.1574
2239.15	24.5012
2242.01	25.2248
2244.87	23.5831
2247.72	22.6157
2250.58	21.137
2253.43	21.162
2256.29	21.3605
2259.14	19.4295
2261.99	18.3234
2264.84	17.443
2267.69	16.0216
2270.53	14.3638
2273.38	12.4824
2276.23	9.83415
2279.07	8.62931
2281.91	7.32863
2284.76	6.3501
2287.6	6.12602
2290.44	6.6521
2293.28	5.63027
2296.12	5.26578
2298.96	7.10249
2301.79	8.79953
2304.63	9.88421
2307.46	10.7992
2310.3	11.9374
2313.13	13.4177
2315.96	14.3916
2318.79	15.2605
2321.62	16.3223
2324.45	17.0653
2327.27	16.069
2330.1	15.0019
2332.92	15.3028
2335.75	14.2069
2338.57	11.4446
2341.39	10.3144
2344.21	9.18387
2347.04	7.90191
2349.85	4.86599
2352.67	3.20033
2355.49	3.14234
2358.3	0.932009
2361.12	-0.450212
2363.93	-0.352797
2366.75	1.46424
2369.56	2.06357
2372.37	1.29225
2375.18	-0.268369
2377.99	0.614241
2380.8	0.710308
2383.6	0.553942
2386.41	-0.330006
2389.21	-1.08167
2392.02	-2.18898
2394.82	-2.11036
2397.62	-2.00617
2400.42	-1.4126
2403.22	-1.50895
2406.02	-2.03209
2408.82	-2.47891
2411.62	0.407465
2414.41	1.30958
2417.21	2.3024
2420	4.98015
2422.79	7.06545
2425.59	9.53294
2428.38	10.4432
2431.17	12.8286
2433.95	14.0091
2436.74	15.94
2439.53	16.2184
2442.31	16.6933
2445.1	17.6159
2447.88	17.0837
2450.67	16.4915
2453.45	13.9497
2456.23	12.5767
2459.01	11.279
2461.79	10.6105
2464.57	9.73589
2467.34	8.46368
2470.12	6.306
2472.89	5.51068
2475.67	4.54876
2478.44	3.90426
2481.21	3.27765
2483.98	2.77946
2486.75	3.50181
2489.52	4.01042
2492.29	4.21862
2495.05	4.15444
2497.82	3.52901
2500.58	3.2166
2503.35	3.42413
2506.11	3.10538
2508.87	2.60427
2511.63	2.68122
2514.39	2.14966
2517.15	1.40119
2519.91	2.00023
2522.67	2.34099
2525.42	3.80526
2528.18	3.17472
2530.93	3.59408
2533.69	3.83997
2536.44	4.46319
2539.19	5.04953
2541.94	4.75589
2544.69	4.13838
2547.44	4.28797
2550.18	6.26606
2552.93	7.3844
2555.67	6.86266
2558.42	7.42421
2561.16	7.6772
2563.9	7.11372
2566.64	6.41247
2569.38	7.08499
2572.12	7.61512
2574.86	8.3964
2577.6	8.96792
2580.33	8.94957
2583.07	9.4713
2585.8	10.1604
2588.54	11.3993
2591.27	11.0745
2594	11.3803
2596.73	11.5284
2599.46	12.5031
2602.19	12.8001
2604.92	13.1803
2607.64	12.8227
2610.37	12.9987
2613.09	13.4445
2615.82	11.8723
2618.54	12.9354
2621.26	12.1439
2623.98	13.0024
2626.7	13.1874
2629.42	12.6032
2632.14	13.4787
2634.86	15.1771
2637.57	16.2789
2640.29	17.7777
2643	17.6008
2645.71	18.6934
2648.43	18.3358
2651.14	17.9585
2653.85	17.6866
2656.56	17.9538
2659.26	17.6782
2661.97	17.4082
2664.68	16.9593
2667.38	15.8961
2670.09	15.98
2672.79	15.8559
2675.49	15.0708
2678.19	15.6881
2680.89	14.9609
2683.59	15.7034
2686.29	17.5188
2688.99	19.6355
2691.69	20.996
2694.38	23.0435
2697.08	27.7234
2699.77	32.0099
2702.46	36.3816
2705.15	41.0303
2707.85	45.3492
2710.54	50.7805
2713.22	55.4843
2715.91	57.5957
2718.6	60.4487
2721.29	61.5157
2723.97	62.0261
2726.66	62.0708
2729.34	59.5387
2732.02	58.3954
2734.7	55.2056
2737.38	52.4624
2740.06	47.8218
2742.74	42.9908
2745.42	37.6181
2748.09	32.0546
2750.77	24.7584
2753.45	19.1312
2756.12	14.5593
2758.79	10.6694
2761.46	7.10153
2764.14	5.40476
2766.8	2.79045
2769.47	2.2349
2772.14	2.1612
2774.81	1.95555
2777.48	2.23791
2780.14	0.747527
2782.8	0.272637
2785.47	0.821827
2788.13	1.16314
2790.79	2.45224
2793.45	2.93506
2796.11	4.04279
2798.77	5.17441
2801.43	5.43126
2804.09	2.71393
2806.74	1.01539
2809.4	-5.24472
2812.05	-7.64508
2814.71	-9.69865
2817.36	-1.23425
2820.01	18.8531
2822.66	51.1186
2825.31	92.3416
2827.96	143.881
2830.6	197.887
2833.25	255.065
2835.9	316.567
2838.54	376.166
2841.18	438.402
2843.83	496.055
2846.47	553.169
2849.11	609.906
2851.75	666.349
2854.39	723.594
2857.03	777.185
2859.66	824.323
2862.3	864
2864.94	893.965
2867.57	914.333
2870.2	928.889
2872.84	937.612
2875.47	942.299
2878.1	949.295
2880.73	959.781
2883.36	973.926
2885.99	987.276
2888.61	1000.91
2891.24	1011.01
2893.86	1017.89
2896.49	1019.66
2899.11	1022.69
2901.73	1023.86
2904.36	1024.35
2906.98	1026.38
2909.6	1032.79
2912.21	1042.52
2914.83	1052.84
2917.45	1063.83
2920.07	1070.58
2922.68	1069.12
2925.29	1062.01
2927.91	1049.37
2930.52	1032.27
2933.13	1011.69
2935.74	985.446
2938.35	956.683
2940.96	922.948
2943.57	884.949
2946.18	844.172
2948.78	800.411
2951.39	754.863
2953.99	709.201
2956.59	663.576
2959.2	618.297
2961.8	575.365
2964.4	535.555
2967	499.161
2969.6	464.133
2972.19	433.98
2974.79	403.523
2977.39	372.853
2979.98	342.85
2982.58	311.325
2985.17	279.312
2987.76	249.29
2990.35	220.173
2992.94	194.551
2995.53	169.385
2998.12	146.276
3000.71	123.891
3003.3	104.37
3005.88	85.7576
3008.47	69.9385
3011.05	56.7152
3013.64	44.3729
3016.22	33.5971
3018.8	24.4747
3021.38	17.9448
3023.96	11.3326
3026.54	6.57721
3029.12	3.81335
3031.69	2.52692
3034.27	1.24809
3036.84	1.90944
3039.42	2.54625
3041.99	4.17307
3044.57	5.77631
3047.14	7.04472
3049.71	8.78639
3052.28	9.84028
3054.85	10.8772
3057.41	10.6548
3059.98	10.8573
3062.55	10.3252
3065.11	9.49521
3067.68	8.68729
3070.24	8.24252
3072.8	6.61077
3075.36	6.58447
3077.93	6.30481
3080.49	4.87978
3083.04	5.73548
3085.6	4.54017
3088.16	4.52546
3090.72	5.35805
3093.27	7.7577
3095.83	10.3006
3098.38	12.3616
3100.93	15.8992
3103.49	19.3279
3106.04	21.7789
3108.59	24.0274
3111.14	26.632
3113.69	28.5158
3116.23	31.3175
3118.78	33.7269
3121.33	37.6277
3123.87	41.6522
3126.41	45.4714
3128.96	49.3899
3131.5	53.0211
3134.04	57.5579
3136.58	61.6346
3139.12	67.714
3141.66	73.023
3144.2	79.6045
3146.74	87.4001
3149.27	97.1585