File: data/Raman/poly_smoothed/Mb_20_x_04_1x_45s_532 nm_x100_100%_600 gr_mm_01.txt
#Acq. time (s)=	45
#Accumulations=	2
#Range (cm-¹)=	200...3150
#Windows=	2
#Auto scanning=	Off
#Autofocus=	Off
#Macrospot=	Off
#AutoExposure=	Off
#Spike filter=	Multiple accum.
#Delay time (s)=	0
#Binning=	1
#Readout mode=	Signal
#DeNoise=	Off
#ICS correction=	On
#Dark correction=	Off
#Inst. Process=	Off
#Detector Gain=	Best Dynamic Range
#Detector ADC=	20 kHz
#Detector temperature (°C)=	-69.85
#Instrument=	LabRAM HR Evol
#Detector=	Synapse
#Objective=	x100
#Grating=	600 gr/mm
#ND Filter=	100%
#Laser (nm)=	532
#Hole=	100.021
#Range=	Auto
#Laser Pol.=	No
#Raman. Pol.=	No
#Laser Pol. (°)=	-0.0007625
#Raman Pol. (°)=	89.9995
#Collection=	Microscope
#StageXY=	Marzhauser
#StageZ=	Marzhauser
#X (µm)=	-807.5
#Y (µm)=	2699.5
#Z (µm)=	584.6
#Full time(mm:ss)=	3:19
#Project=
#Sample=
#Site=
#Title=	Mb_20_x_04_2x_45s_532 nm_x100_100%_600 gr_mm
#Remark=
#Date=	18.07.2022 14:43
#Acquired=	18.07.2022 14:43:11
#Edit:Spike=	18.07.2022 14:47:47
#Base:Fit=	16.08.2022 10:28:40
#Base:Fit=	16.08.2022 10:28:53
#Base:Fit=	16.08.2022 10:29:09
#Base:Fit=	16.08.2022 10:29:17
#Base:Fit=	16.08.2022 10:29:25
#Base:Fit=	16.08.2022 10:29:33
#Base:Sub=	16.08.2022 10:29:38
#Filter:Polynom=	16.08.2022 10:30:49
#AxisType[0]=Intens
#AxisUnit[0]=Cnt
#AxisType[1]=Spectr
#AxisUnit[1]=1/cm
200.419	-2.52239
204.048	0.0544184
207.678	0.448236
211.304	-0.529129
214.928	-0.434506
218.554	0.323216
222.176	-0.0608203
225.798	1.48625
229.417	3.30346
233.035	7.16047
236.653	8.95235
240.268	10.9816
243.881	13.1795
247.493	16.1323
251.103	18.2301
254.715	20.1838
258.322	23.9848
261.929	25.8154
265.534	26.9396
269.137	29.423
272.739	30.9539
276.34	33.9601
279.939	36.888
283.537	38.1444
287.134	40.1091
290.729	41.7381
294.323	41.3452
297.913	41.6973
301.504	43.9759
305.093	46.3529
308.682	46.3561
312.268	46.6979
315.852	47.0578
319.436	48.6721
323.018	49.5569
326.597	49.8085
330.177	50.5656
333.753	50.362
337.331	49.258
340.906	46.417
344.478	45.4265
348.051	43.8097
351.621	42.1202
355.189	40.2646
358.757	41.1269
362.323	40.6354
365.889	38.9915
369.451	37.1527
373.012	36.1167
376.574	36.6669
380.133	35.289
383.69	34.4934
387.245	35.6248
390.8	36.1383
394.353	35.5918
397.906	35.1819
401.456	35.4425
405.005	35.7243
408.552	37.1381
412.099	38.6938
415.643	39.0133
419.187	37.4723
422.728	36.8781
426.269	35.1379
429.806	35.9596
433.344	35.3832
436.881	35.1648
440.416	35.1566
443.949	35.1991
447.48	35.0573
451.011	32.8312
454.541	32.1221
458.069	31.7937
461.594	32.0203
465.119	32.3848
468.642	32.2224
472.165	32.32
475.684	31.7066
479.204	32.3172
482.721	31.7399
486.239	31.975
489.753	32.5285
493.268	32.9932
496.779	34.1048
500.289	35.0019
503.8	34.1669
507.307	34.9341
510.813	36.0023
514.32	36.287
517.823	36.9801
521.325	38.0197
524.826	39.2653
528.325	37.2069
531.823	36.9054
535.32	35.7047
538.815	35.3652
542.309	35.3719
545.802	33.9552
549.293	33.5937
552.783	30.7228
556.271	30.1657
559.759	28.1006
563.245	26.4045
566.729	24.0582
570.213	20.2628
573.693	18.3404
577.173	16.9366
580.652	13.407
584.13	10.8662
587.605	8.26334
591.08	5.74865
594.552	5.68949
598.025	6.2632
601.496	8.04475
604.964	9.54044
608.433	9.74422
611.898	10.4503
615.364	11.1166
618.827	12.2552
622.288	12.7949
625.75	14.5865
629.209	15.7016
632.667	17.9104
636.125	17.9088
639.58	17.8803
643.033	16.2176
646.485	15.5406
649.936	14.0467
653.388	12.3665
656.836	11.8038
660.283	11.4438
663.728	10.307
667.173	10.4682
670.616	9.29875
674.057	9.29316
677.498	10.864
680.937	14.998
684.375	17.7581
687.809	19.1192
691.244	19.981
694.678	22.4112
698.111	24.2087
701.54	26.6004
704.97	29.8143
708.398	31.5029
711.826	33.0794
715.25	35.2574
718.675	33.6235
722.096	32.4958
725.518	32.9386
728.937	35.5868
732.357	36.0796
735.773	34.9819
739.19	34.1697
742.604	33.2634
746.018	33.4901
749.429	34.3392
752.839	34.2132
756.248	34.8588
759.657	36.9569
763.063	38.0083
766.468	40.2529
769.871	42.106
773.273	44.3904
776.676	47.9144
780.075	51.8275
783.474	55.5702
786.871	57.7054
790.266	59.3752
793.661	61.4967
797.054	63.0455
800.446	63.5841
803.834	62.6098
807.224	65.7724
810.612	66.2579
813.998	65.1151
817.384	62.4216
820.766	62.1841
824.149	61.3311
827.531	61.6201
830.909	59.617
834.288	57.955
837.666	55.7091
841.041	55.0155
844.416	52.8012
847.788	51.6115
851.161	50.6654
854.53	50.5734
857.901	48.2265
861.268	46.8883
864.633	45.1566
868	44.012
871.363	42.056
874.725	40.8038
878.088	39.631
881.447	37.66
884.805	35.7835
888.162	33.8967
891.518	32.7767
894.872	29.9879
898.225	30.0011
901.577	29.5182
904.928	27.5517
908.277	27.478
911.625	24.4606
914.972	22.6724
918.318	21.2098
921.662	22.019
925.005	19.8431
928.347	20.9573
931.686	20.4567
935.025	20.5689
938.363	19.9242
941.698	19.1162
945.034	19.1327
948.368	19.7046
951.699	19.3356
955.031	18.8425
958.36	17.737
961.689	17.0873
965.016	16.786
968.343	16.6911
971.666	16.2243
974.991	15.7762
978.312	17.8132
981.632	17.585
984.953	17.2636
988.27	16.0007
991.587	12.6964
994.902	9.82255
998.216	6.93911
1001.53	3.86218
1004.84	1.5131
1008.15	3.5529
1011.46	11.0513
1014.77	20.9376
1018.07	30.5414
1021.38	41.3055
1024.68	51.1548
1027.99	60.0551
1031.29	67.581
1034.59	74.7897
1037.89	79.5481
1041.18	83.0035
1044.48	85.1625
1047.77	85.5416
1051.07	83.5777
1054.36	80.6928
1057.65	77.7321
1060.94	69.8426
1064.23	58.7385
1067.52	48.626
1070.8	35.9636
1074.09	23.9955
1077.37	12.6266
1080.65	3.02753
1083.93	-3.04913
1087.21	-4.97821
1090.49	-0.753809
1093.77	1.66026
1097.04	4.82069
1100.32	9.19681
1103.59	12.8005
1106.86	15.8135
1110.13	16.9669
1113.4	19.8167
1116.67	19.959
1119.94	19.9314
1123.2	20.6298
1126.47	20.6348
1129.73	18.7489
1132.99	18.0104
1136.25	15.8426
1139.51	14.6923
1142.77	10.6169
1146.03	8.9657
1149.28	6.56681
1152.54	4.44577
1155.79	2.60875
1159.04	0.907113
1162.29	0.56217
1165.54	0.0769974
1168.79	0.00284974
1172.04	-0.61314
1175.28	0.302022
1178.53	1.50905
1181.77	3.41174
1185.01	3.27384
1188.25	5.31036
1191.49	6.02532
1194.73	7.25875
1197.96	7.78108
1201.2	8.53487
1204.43	11.2127
1207.66	13.0333
1210.9	13.7577
1214.13	16.7021
1217.36	17.7176
1220.58	20.8068
1223.81	22.9757
1227.04	23.2961
1230.26	24.5186
1233.48	25.1077
1236.71	26.5873
1239.93	28.7901
1243.14	30.8841
1246.36	32.4864
1249.58	32.752
1252.8	33.2486
1256.01	34.4107
1259.22	35.8988
1262.43	39.6863
1265.64	41.854
1268.85	42.7584
1272.06	45.4486
1275.27	47.8969
1278.48	48.5893
1281.68	52.0461
1284.88	53.8828
1288.08	56.7311
1291.28	58.7513
1294.48	60.5754
1297.68	62.9056
1300.88	62.7218
1304.07	62.1057
1307.27	62.0269
1310.46	62.4629
1313.65	60.9956
1316.85	60.7249
1320.03	60.6759
1323.22	60.0562
1326.41	57.741
1329.6	57.5338
1332.78	55.746
1335.96	55.1245
1339.15	55.9817
1342.33	55.2457
1345.51	53.6969
1348.69	51.7347
1351.86	51.4711
1355.04	50.7699
1358.21	49.4001
1361.39	49.6395
1364.56	49.0256
1367.73	47.7764
1370.9	47.3541
1374.07	44.399
1377.24	42.5641
1380.41	42.6653
1383.57	43.0415
1386.73	43.4829
1389.9	42.3599
1393.06	43.1842
1396.22	43.7988
1399.38	43.4242
1402.54	44.1321
1405.69	44.7412
1408.85	48.3039
1412	49.3374
1415.16	50.9181
1418.31	54.3241
1421.46	57.7005
1424.61	61.156
1427.76	65.6872
1430.9	71.8058
1434.05	75.9009
1437.2	80.1887
1440.34	83.0871
1443.48	85.1756
1446.62	87.0053
1449.76	86.3282
1452.9	86.4846
1456.04	85.84
1459.17	85.7762
1462.31	83.0933
1465.44	80.2014
1468.58	77.3221
1471.71	73.307
1474.84	69.7787
1477.97	64.8001
1481.1	60.3197
1484.22	56.4998
1487.35	51.9725
1490.47	47.1092
1493.59	44.3609
1496.72	41.8808
1499.84	40.0144
1502.96	39.5695
1506.08	37.9144
1509.19	36.497
1512.31	34.6348
1515.42	31.8377
1518.54	30.3868
1521.65	30.0579
1524.76	29.7374
1527.87	29.0688
1530.98	29.0073
1534.09	26.5944
1537.2	27.9878
1540.3	28.208
1543.41	29.9375
1546.51	31.5002
1549.61	32.9289
1552.71	34.074
1555.81	34.4524
1558.91	35.0296
1562.01	35.7504
1565.1	36.2888
1568.2	36.7338
1571.29	39.8492
1574.38	41.3925
1577.48	43.1557
1580.57	44.1584
1583.65	46.0154
1586.74	47.8283
1589.83	49.6802
1592.92	52.13
1596	55.2365
1599.08	57.6761
1602.16	57.7185
1605.24	57.3417
1608.32	57.1475
1611.4	57.4318
1614.48	58.4015
1617.56	57.898
1620.63	59.2914
1623.71	60.1821
1626.78	59.2159
1629.85	59.1236
1632.92	58.8273
1635.99	59.9222
1639.06	59.5745
1642.12	60.2654
1645.19	61.2364
1648.25	62.7135
1651.32	64.4617
1654.38	65.7069
1657.44	65.5912
1660.5	64.9019
1663.56	65.0061
1666.62	63.367
1669.67	61.9285
1672.73	60.0016
1675.79	55.6422
1678.84	52.0732
1681.89	49.9686
1684.94	46.8231
1687.99	42.2206
1691.04	37.3733
1694.08	33.9347
1697.13	31.7699
1700.18	28.7
1703.22	26.1655
1706.26	24.8352
1709.3	21.049
1712.35	18.4513
1715.39	15.1388
1718.42	14.0684
1721.46	13.1692
1724.5	14.2356
1727.53	12.1762
1730.56	10.5553
1733.6	8.4452
1736.63	8.13711
1739.66	6.44167
1742.69	5.87594
1745.71	5.70497
1748.74	5.66036
1751.77	4.6483
1754.79	5.39343
1757.81	6.55657
1760.84	6.42787
1763.86	6.19822
1766.88	5.77836
1769.9	5.85692
1772.91	7.2463
1775.93	6.85815
1778.95	6.66558
1781.96	6.8788
1784.97	6.6083
1787.99	6.90194
1791	7.39968
1794.01	7.20542
1797.01	8.35001
1800.02	8.40875
1803.03	7.18157
1806.03	6.3111
1809.04	5.87879
1812.04	5.93996
1815.04	5.69336
1818.04	4.74838
1821.04	3.50242
1824.04	3.11659
1827.04	2.1914
1830.03	2.47642
1833.03	2.40467
1836.02	1.3665
1839.02	0.942476
1842.01	0.762267
1845	1.1776
1847.99	1.2166
1850.98	1.90844
1853.96	3.09385
1856.95	3.64952
1859.94	4.39094
1862.92	5.6892
1865.9	6.42727
1868.88	8.61474
1871.86	9.34001
1874.84	9.15664
1877.82	9.23087
1880.8	9.15301
1882.58	9.95987
1885.57	9.84222
1888.56	9.20633
1891.54	9.20464
1894.53	8.27532
1897.51	8.41144
1900.5	7.33183
1903.48	7.54435
1906.46	6.46149
1909.44	5.9054
1912.42	6.41825
1915.4	5.25903
1918.37	5.82795
1921.35	5.73352
1924.32	4.77495
1927.3	4.65374
1930.27	3.00093
1933.24	3.04192
1936.21	3.60786
1939.18	3.26559
1942.15	3.19148
1945.11	3.3451
1948.08	3.35682
1951.04	3.42592
1954.01	2.97399
1956.97	4.06923
1959.93	4.72526
1962.89	4.86967
1965.85	4.94096
1968.81	4.76913
1971.77	5.02792
1974.72	5.34591
1977.68	6.20365
1980.63	7.17765
1983.58	7.74817
1986.53	9.13052
1989.48	8.7913
1992.43	8.62274
1995.38	7.5215
1998.33	9.17921
2001.27	8.87569
2004.22	9.59866
2007.16	9.4863
2010.11	9.216
2013.05	9.33892
2015.99	9.45794
2018.93	8.85166
2021.87	8.45998
2024.8	8.64635
2027.74	8.63207
2030.68	9.57502
2033.61	8.63907
2036.54	6.99494
2039.48	7.48692
2042.41	7.22952
2045.34	6.98318
2048.27	8.05597
2051.19	8.77946
2054.12	9.21136
2057.05	8.49234
2059.97	9.5966
2062.9	9.35185
2065.82	10.0693
2068.74	11.845
2071.66	12.7352
2074.58	12.7979
2077.5	12.6751
2080.41	12.1557
2083.33	13.4069
2086.24	14.1001
2089.16	14.8889
2092.07	15.5104
2094.98	17.1043
2097.89	18.7705
2100.8	18.509
2103.71	18.9621
2106.62	20.2789
2109.53	20.7954
2112.43	22.0104
2115.33	23.0069
2118.24	23.0705
2121.14	22.7695
2124.04	23.5754
2126.94	24.0429
2129.84	24.7554
2132.74	26.3157
2135.63	25.7936
2138.53	27.9488
2141.43	29.1713
2144.32	29.8641
2147.21	31.1774
2150.1	32.3054
2152.99	33.1978
2155.88	35.0479
2158.77	35.8274
2161.66	36.7443
2164.55	38.7446
2167.43	39.9399
2170.31	41.7225
2173.2	43.2483
2176.08	45.5416
2178.96	46.994
2181.84	46.592
2184.72	45.1766
2187.6	43.3382
2190.47	42.1454
2193.35	41.4821
2196.23	40.2317
2199.1	38.0297
2201.97	36.7565
2204.84	36.0575
2207.71	34.0792
2210.58	32.6499
2213.45	30.3213
2216.32	28.3602
2219.19	26.0798
2222.05	23.5308
2224.92	21.8269
2227.78	20.6733
2230.64	18.4593
2233.5	17.6928
2236.36	17.0486
2239.22	16.1079
2242.08	15.7532
2244.94	15.2885
2247.79	14.5727
2250.65	13.4244
2253.5	12.5216
2256.36	11.8262
2259.21	12.4742
2262.06	12.2997
2264.91	13.0231
2267.76	12.134
2270.6	11.7354
2273.45	11.6408
2276.3	12.0746
2279.14	12.1296
2281.98	11.0913
2284.83	10.0723
2287.67	9.53
2290.51	9.02569
2293.35	7.74983
2296.19	6.42267
2299.02	5.82211
2301.86	5.63132
2304.7	4.97326
2307.53	5.16614
2310.36	6.08477
2313.2	8.05112
2316.03	8.88562
2318.86	8.85113
2321.69	9.43708
2324.51	10.2309
2327.34	11.6208
2330.17	12.5805
2332.99	13.3459
2335.82	12.9563
2338.64	12.4763
2341.46	12.3433
2344.28	12.6644
2347.1	11.3995
2349.92	9.42659
2352.74	7.33329
2355.56	6.55189
2358.37	5.7968
2361.19	4.3536
2364	2.79476
2366.82	3.13767
2369.63	3.2456
2372.44	2.85435
2375.25	3.46345
2378.06	5.10907
2380.86	5.00363
2383.67	4.87495
2386.48	4.26577
2389.28	4.6877
2392.09	6.01557
2394.89	6.74256
2397.69	7.94911
2400.49	7.90556
2403.29	7.74311
2406.09	7.54811
2408.89	7.01667
2411.69	6.70074
2414.48	5.37326
2417.28	4.10128
2420.07	3.91204
2422.86	3.90087
2425.65	3.66539
2428.45	2.65158
2431.23	1.99499
2434.02	2.22356
2436.81	1.44099
2439.6	0.815059
2442.38	0.851328
2445.17	1.33119
2447.95	0.837513
2450.73	0.0788139
2453.52	0.366189
2456.3	0.795664
2459.08	1.46839
2461.85	1.32724
2464.63	2.15285
2467.41	2.8318
2470.19	3.12645
2472.96	3.55689
2475.73	3.28529
2478.51	3.35083
2481.28	3.24779
2484.05	3.0946
2486.82	2.99089
2489.59	2.89526
2492.35	3.69278
2495.12	3.99241
2497.89	3.61182
2500.65	3.4425
2503.42	4.0357
2506.18	4.15264
2508.94	3.15149
2511.7	3.27915
2514.46	2.96436
2517.22	3.00374
2519.98	3.04929
2522.73	3.47755
2525.49	4.22909
2528.25	4.34811
2531	3.77262
2533.75	3.37465
2536.5	2.69094
2539.25	2.10768
2542.01	2.60665
2544.75	2.28
2547.5	2.58684
2550.25	3.01804
2553	2.41486
2555.74	2.65776
2558.49	2.63761
2561.23	2.97987
2563.97	4.13822
2566.71	3.7362
2569.45	4.11693
2572.19	4.4323
2574.93	5.39034
2577.67	5.84654
2580.4	7.1766
2583.14	8.6607
2585.87	8.82209
2588.6	8.42877
2591.34	8.3993
2594.07	8.29557
2596.8	7.17396
2599.53	5.8264
2602.26	6.03845
2604.98	5.13725
2607.71	5.41545
2610.44	5.35423
2613.16	3.86114
2615.88	2.16014
2618.61	0.529578
2621.33	0.253655
2624.05	0.153022
2626.77	0.166537
2629.49	0.809177
2632.21	1.29143
2634.92	0.440515
2637.64	0.218166
2640.35	1.25314
2643.07	1.96875
2645.78	2.35568
2648.49	2.61109
2651.2	2.99791
2653.91	2.72995
2656.62	3.0052
2659.33	3.69277
2662.04	3.33775
2664.74	4.24536
2667.45	4.98709
2670.15	4.47847
2672.86	4.73032
2675.56	4.18171
2678.26	2.56825
2680.96	1.97227
2683.66	2.27468
2686.36	2.91936
2689.06	4.01861
2691.75	4.41699
2694.45	3.85497
2697.14	3.0682
2699.84	3.40774
2702.53	3.4853
2705.22	4.6337
2707.91	5.55963
2710.6	6.4478
2713.29	7.31411
2715.98	7.89549
2718.67	8.72716
2721.35	9.13809
2724.04	9.65524
2726.72	11.005
2729.4	12.3673
2732.09	12.1897
2734.77	11.2648
2737.45	11.4562
2740.13	11.1853
2742.81	9.93666
2745.48	9.30641
2748.16	8.82321
2750.84	7.96124
2753.51	6.64586
2756.19	5.9384
2758.86	4.58288
2761.53	3.05322
2764.2	3.0751
2766.87	3.5591
2769.54	3.30524
2772.21	3.42192
2774.88	2.46722
2777.54	1.32523
2780.21	1.8509
2782.87	2.61971
2785.53	3.39667
2788.2	3.90277
2790.86	4.24881
2793.52	3.8235
2796.18	4.03658
2798.84	3.96525
2801.49	5.04202
2804.15	5.29668
2806.81	4.54935
2809.46	3.00578
2812.12	3.69495
2814.77	3.61157
2817.42	6.55139
2820.07	8.97223
2822.72	13.1152
2825.37	18.3309
2828.02	24.4952
2830.67	30.2729
2833.31	36.5799
2835.96	42.2867
2838.61	49.3832
2841.25	55.42
2843.89	64.2986
2846.53	72.0018
2849.17	81.1422
2851.81	89.9253
2854.45	98.3626
2857.09	107.694
2859.73	116.29
2862.36	124.501
2865	131.85
2867.64	136.767
2870.27	141.134
2872.9	144.26
2875.53	148.386
2878.16	151.923
2880.79	155.977
2883.42	159.412
2886.05	160.481
2888.68	162.282
2891.3	165.266
2893.93	167.736
2896.55	170.761
2899.18	173.654
2901.8	177.642
2904.42	180.702
2907.04	186.386
2909.66	192.702
2912.28	201.375
2914.9	209.994
2917.51	217.501
2920.13	225.238
2922.74	231.126
2925.36	236.052
2927.97	238.358
2930.59	239.532
2933.2	239.066
2935.81	237.467
2938.42	234.371
2941.02	229.773
2943.63	224.116
2946.24	217.222
2948.85	208.709
2951.45	199.628
2954.05	190.912
2956.66	181.983
2959.26	173.654
2961.86	162.744
2964.46	151.918
2967.06	141.726
2969.66	132.691
2972.26	124.78
2974.85	116.703
2977.45	109.807
2980.05	102.805
2982.64	94.7537
2985.23	86.636
2987.83	78.5284
2990.42	70.9818
2993.01	63.1974
2995.6	57.4106
2998.19	50.9353
3000.77	44.8867
3003.36	39.9656
3005.95	36.0524
3008.53	31.5593
3011.12	27.0133
3013.7	23.3305
3016.28	19.5299
3018.86	16.8315
3021.44	13.7812
3024.02	11.3873
3026.6	7.86904
3029.18	5.68732
3031.76	4.09831
3034.33	3.25886
3036.91	2.59278
3039.48	3.09376
3042.05	3.19677
3044.63	2.6696
3047.2	1.71762
3049.77	1.93907
3052.34	3.00209
3054.91	3.53619
3057.48	3.34934
3060.04	4.49669
3062.61	4.5284
3065.17	4.04404
3067.74	4.32379
3070.3	4.69773
3072.87	4.2609
3075.43	4.11586
3077.99	3.8487
3080.55	3.36071
3083.11	3.65848
3085.67	2.8144
3088.22	1.84212
3090.78	1.47344
3093.34	0.688801
3095.89	0.981519
3098.44	0.456552
3101	0.135513
3103.55	0.510579
3106.1	0.323711
3108.65	0.768795
3111.2	0.189447
3113.75	1.68221
3116.3	2.35825
3118.84	2.03937
3121.39	2.00388
3123.93	2.76862
3126.48	2.98965
3129.02	3.72004
3131.56	4.53777
3134.1	3.81338
3136.64	4.35751
3139.18	5.39892
3141.72	6.0839
3144.26	6.60588
3146.8	6.48308
3149.33	8.93385