File: data/Raman/poly_smoothed/Mb_20_23_19_1x_45s_532 nm_x100_100%_600 gr_mm_01.txt
#Acq. time (s)=	45
#Accumulations=	2
#Range (cm-¹)=	200...3150
#Windows=	2
#Auto scanning=	Off
#Autofocus=	Off
#Macrospot=	Off
#AutoExposure=	Off
#Spike filter=	Multiple accum.
#Delay time (s)=	0
#Binning=	1
#Readout mode=	Signal
#DeNoise=	Off
#ICS correction=	On
#Dark correction=	Off
#Inst. Process=	Off
#Detector Gain=	Best Dynamic Range
#Detector ADC=	20 kHz
#Detector temperature (°C)=	-69.85
#Instrument=	LabRAM HR Evol
#Detector=	Synapse
#Objective=	x100
#Grating=	600 gr/mm
#ND Filter=	100%
#Laser (nm)=	532
#Hole=	100.021
#Range=	Auto
#Laser Pol.=	No
#Raman. Pol.=	No
#Laser Pol. (°)=	-0.0007625
#Raman Pol. (°)=	89.9995
#Collection=	Microscope
#StageXY=	Marzhauser
#StageZ=	Marzhauser
#X (µm)=	-6900.9
#Y (µm)=	2112
#Z (µm)=	-74.6
#Full time(mm:ss)=	3:18
#Project=
#Sample=
#Site=
#Title=	Mb_20_23_19_2x_45s_532 nm_x100_100%_600 gr_mm
#Remark=
#Date=	13.07.2022 14:29
#Acquired=	13.07.2022 14:29:01
#Base:Fit=	10.08.2022 10:29:37
#Base:Sub=	10.08.2022 10:32:28
#Filter:Polynom=	16.08.2022 10:13:29
#AxisType[0]=Intens
#AxisUnit[0]=Cnt
#AxisType[1]=Spectr
#AxisUnit[1]=1/cm
200.563	-2.44772
204.194	6.08067
207.821	11.1343
211.449	14.6742
215.074	16.6115
218.699	17.6705
222.321	19.004
225.941	18.501
229.562	19.1264
233.18	22.8661
236.796	22.4526
240.411	22.1066
244.026	22.5346
247.638	22.8511
251.248	20.8495
254.857	19.0554
258.465	18.0463
262.071	16.1585
265.678	15.3304
269.282	12.9402
272.884	11.2177
276.484	10.9446
280.084	11.4103
283.682	8.58622
287.276	6.94387
290.871	5.65047
294.465	5.78679
298.057	4.17426
301.648	4.29533
305.237	4.31603
308.823	5.58669
312.41	6.41825
315.995	7.5706
319.579	11.2155
323.16	12.2213
326.741	11.9628
330.321	13.0364
333.897	14.4883
337.474	14.5069
341.048	14.0956
344.622	13.6518
348.192	15.0335
351.764	15.6885
355.332	14.5512
358.901	13.7298
362.466	11.5679
366.03	11.7042
369.594	11.3528
373.155	8.11799
376.715	8.51143
380.273	9.105
383.832	8.51097
387.388	8.98812
390.942	10.7396
394.495	11.318
398.047	11.2763
401.597	11.6302
405.145	11.762
408.693	11.8293
412.239	10.6731
415.783	10.34
419.327	10.5858
422.869	11.6137
426.409	10.7397
429.948	11.5384
433.486	9.59456
437.022	7.63078
440.558	7.4884
444.089	6.53025
447.622	6.2311
451.153	7.84388
454.682	7.88201
458.208	7.11011
461.735	8.765
465.259	11.1644
468.783	10.9571
472.306	12.831
475.825	14.1646
479.346	15.1573
482.862	18.2626
486.38	19.8653
489.894	20.651
493.407	21.9303
496.92	24.1016
500.43	23.4109
503.939	23.7425
507.448	23.9017
510.954	21.9701
514.459	20.7103
517.962	19.4368
521.466	17.5385
524.966	15.8628
528.466	14.419
531.964	13.823
535.46	12.5072
538.955	9.4959
542.449	6.69812
545.942	6.71037
549.433	4.13007
552.923	1.96446
556.412	0.880896
559.899	0.218278
563.385	-0.252423
566.867	1.74477
570.35	2.10796
573.832	2.54745
577.313	2.93253
580.79	4.04626
584.268	2.07677
587.745	3.24091
591.218	2.89967
594.692	2.92834
598.164	3.18563
601.634	3.49299
605.104	4.86118
608.57	4.43673
612.037	2.90191
615.501	5.46855
618.966	6.76192
622.427	4.50915
625.887	4.05701
629.348	4.61066
632.806	4.28782
636.262	4.48751
639.716	5.1755
643.172	7.34386
646.624	8.22726
650.075	9.60883
653.524	10.9583
656.972	13.8152
660.419	13.615
663.865	15.0918
667.309	15.3207
670.752	15.3592
674.194	15.8005
677.634	17.0557
681.073	18.9096
684.511	20.6522
687.947	22.3433
691.382	24.3788
694.816	26.0242
698.247	28.5738
701.678	29.2676
705.108	27.4452
708.534	26.7247
711.962	28.8547
715.388	29.1362
718.81	29.3648
722.234	28.999
725.654	29.1173
729.075	28.8414
732.492	30.2354
735.91	31.4634
739.325	33.0643
742.741	34.134
746.153	35.7497
749.564	36.0663
752.976	38.3458
756.385	39.2018
759.792	42.8612
763.2	45.7906
766.604	49.4833
770.008	52.4665
773.41	55.0778
776.811	57.1377
780.21	59.4956
783.608	60.0696
787.005	61.7127
790.401	63.1735
793.795	64.047
797.188	64.435
800.58	63.9991
803.971	64.9398
807.36	64.7857
810.748	65.1296
814.135	66.5238
817.518	66.675
820.902	69.503
824.285	71.2732
827.665	71.9391
831.045	73.9802
834.424	73.8802
837.8	75.3865
841.177	74.5873
844.55	74.907
847.924	73.9914
851.295	74.2264
854.666	74.4363
858.034	71.8256
861.403	72.045
864.769	69.1857
868.133	66.8456
871.498	64.9213
874.86	61.3939
878.221	60.721
881.58	58.5194
884.938	57.248
888.297	54.6732
891.653	53.8013
895.007	53.3814
898.36	53.218
901.712	51.9122
905.063	52.5307
908.412	50.8225
911.76	51.3703
915.107	51.3807
918.452	51.2887
921.797	50.966
925.138	50.519
928.48	49.1228
931.82	48.9954
935.16	48.4877
938.496	45.9755
941.833	42.8577
945.168	40.0102
948.5	37.6126
951.834	35.2908
955.163	31.5104
958.494	30.1066
961.821	28.3788
965.15	26.6277
968.474	25.6977
971.8	25.739
975.123	24.563
978.446	25.1942
981.766	26.1775
985.084	25.6661
988.402	26.9283
991.72	26.9499
995.035	27.5978
998.349	27.4208
1001.66	26.3804
1004.97	25.7785
1008.28	27.1809
1011.59	27.2843
1014.9	28.5629
1018.21	28.8619
1021.51	28.7833
1024.81	30.2599
1028.12	30.8321
1031.42	32.0285
1034.72	33.1521
1038.02	34.0704
1041.31	37.6258
1044.61	41.0743
1047.91	42.8741
1051.2	44.4167
1054.49	45.1546
1057.78	47.1465
1061.07	46.9982
1064.36	47.4754
1067.65	45.8134
1070.93	45.5175
1074.22	44.3498
1077.5	42.5184
1080.78	39.0556
1084.06	35.5604
1087.34	34.0874
1090.62	31.3868
1093.9	30.1168
1097.17	28.5444
1100.45	26.7251
1103.72	25.1317
1106.99	26.8052
1110.27	25.9249
1113.53	25.0259
1116.8	24.4845
1120.07	24.5899
1123.33	23.111
1126.6	24.1388
1129.86	22.6765
1133.12	20.577
1136.38	20.6402
1139.64	20.183
1142.9	18.2259
1146.16	19.406
1149.41	19.7823
1152.67	20.1899
1155.92	18.7192
1159.17	16.8613
1162.42	14.9209
1165.67	12.8969
1168.92	12.5485
1172.16	11.7693
1175.41	12.3905
1178.65	12.7998
1181.9	11.9273
1185.14	12.2764
1188.38	11.8861
1191.62	9.66379
1194.86	9.78356
1198.09	11.8452
1201.33	12.2729
1204.56	13.5628
1207.8	13.8065
1211.03	13.302
1214.26	14.189
1217.49	15.2769
1220.71	17.4218
1223.94	19.5333
1227.16	21.3225
1230.39	23.7861
1233.61	25.4879
1236.83	26.4825
1240.05	28.6474
1243.27	29.8627
1246.49	32.7881
1249.71	34.9378
1252.92	38.076
1256.14	39.3057
1259.35	41.6096
1262.56	44.5046
1265.77	48.062
1268.98	52.0843
1272.19	58.3437
1275.4	65.1534
1278.6	69.9955
1281.81	74.9582
1285.01	78.3482
1288.21	81.5063
1291.41	85.813
1294.61	88.8342
1297.81	91.1187
1301.01	93.3414
1304.2	93.7074
1307.4	94.2091
1310.59	92.7971
1313.78	91.9307
1316.97	89.4941
1320.16	87.6858
1323.35	84.2905
1326.54	80.8048
1329.72	76.5412
1332.91	72.8412
1336.09	68.3633
1339.27	66.3246
1342.45	63.7428
1345.64	61.0694
1348.81	59.763
1351.99	58.0829
1355.17	55.6022
1358.34	54.0381
1361.51	53.5675
1364.69	52.4459
1367.86	51.5246
1371.03	50.8565
1374.2	49.8369
1377.37	51.003
1380.53	50.3773
1383.7	49.4715
1386.86	49.0617
1390.02	50.0277
1393.19	49.5966
1396.35	50.0421
1399.51	51.4097
1402.66	55.1871
1405.82	61.4386
1408.97	68.2815
1412.13	76.1041
1415.28	86.472
1418.43	95.8972
1421.59	106.5
1424.73	119.773
1427.88	131.526
1431.03	143.46
1434.18	155.402
1437.32	166.011
1440.46	172.887
1443.61	178.049
1446.75	182.209
1449.89	184.273
1453.03	181.768
1456.16	175.8
1459.3	166.212
1462.44	155.782
1465.57	143.048
1468.7	129.97
1471.83	115.172
1474.96	100.721
1478.09	88.4794
1481.22	77.4778
1484.35	66.3431
1487.47	55.7201
1490.6	46.8869
1493.72	39.7726
1496.84	33.1263
1499.96	29.0073
1503.08	25.2147
1506.2	22.2071
1509.32	20.702
1512.44	20.2689
1515.55	18.1211
1518.66	18.3228
1521.78	19.6209
1524.89	20.0928
1528	19.1271
1531.11	18.2994
1534.21	17.1695
1537.32	17.9663
1540.43	18.3907
1543.53	20.0604
1546.63	21.4264
1549.74	21.8487
1552.84	24.7505
1555.94	27.4023
1559.03	28.3114
1562.13	29.634
1565.23	31.8766
1568.32	35.4722
1571.42	38.0538
1574.51	40.6183
1577.6	44.4688
1580.69	47.5174
1583.78	51.0476
1586.87	55.1549
1589.95	56.8243
1593.04	61.0691
1596.12	63.5585
1599.21	64.4587
1602.29	64.5838
1605.37	63.7234
1608.45	62.2334
1611.53	61.6773
1614.6	60.9102
1617.68	59.9856
1620.75	58.6282
1623.83	56.3581
1626.9	55.7551
1629.97	57.2075
1633.04	55.9842
1636.11	55.4106
1639.18	55.7999
1642.25	56.8856
1645.31	59.6368
1648.38	60.5504
1651.44	62.0401
1654.5	63.7996
1657.56	63.6911
1660.62	63.5122
1663.68	63.1176
1666.74	60.2075
1669.8	58.1465
1672.85	56.7682
1675.91	53.131
1678.96	48.5877
1682.01	44.1188
1685.06	40.914
1688.11	38.4061
1691.16	34.3849
1694.21	32.2629
1697.25	30.0251
1700.3	29.921
1703.34	28.7159
1706.39	27.7598
1709.43	26.3427
1712.47	26.6921
1715.51	26.709
1718.54	27.8438
1721.58	29.3748
1724.62	30.2269
1727.65	31.2344
1730.68	31.8838
1733.72	31.3823
1736.75	29.5967
1739.78	28.8563
1742.81	27.3737
1745.84	26.3638
1748.86	23.6476
1751.89	20.7373
1754.91	19.9455
1757.93	19.0002
1760.96	17.8053
1763.98	15.7645
1767	13.7913
1770.02	12.7405
1773.03	10.2029
1776.05	9.46552
1779.07	8.10436
1782.08	6.88734
1785.09	5.9299
1788.11	5.33936
1791.12	4.93285
1794.13	5.15423
1797.13	4.14148
1800.14	3.13826
1803.15	2.37945
1806.15	1.20274
1809.16	0.610231
1812.16	-0.365624
1815.16	-1.04287
1818.16	-1.55821
1821.16	-0.980552
1824.16	1.10234
1827.16	1.13628
1830.16	2.10596
1833.15	2.02926
1836.14	3.27263
1839.14	3.67633
1842.13	4.51394
1845.12	4.58669
1848.11	5.21503
1851.1	6.55511
1854.08	6.45635
1857.07	6.94383
1860.05	6.68446
1863.04	6.24034
1866.02	5.50529
1869	5.42506
1871.98	6.34153
1874.96	7.33297
1877.94	7.51698
1880.92	8.15069
1882.51	8.6093
1885.5	7.85971
1888.48	7.36503
1891.47	7.83354
1894.46	7.13888
1897.44	6.82022
1900.42	5.88011
1903.41	7.48609
1906.39	6.5505
1909.37	5.31968
1912.35	5.21933
1915.32	5.69513
1918.3	5.01417
1921.27	5.15375
1924.25	3.5809
1927.22	3.07403
1930.19	2.57786
1933.17	2.56718
1936.14	3.70846
1939.11	3.80171
1942.07	4.45125
1945.04	4.44736
1948.01	4.00637
1950.97	3.69922
1953.93	3.34997
1956.9	3.64048
1959.86	2.7059
1962.82	2.37068
1965.78	1.91422
1968.74	2.9287
1971.69	1.74012
1974.65	3.5324
1977.6	3.17257
1980.56	2.83983
1983.51	3.95879
1986.46	4.80403
1989.41	5.05023
1992.36	5.64117
1995.31	6.58454
1998.26	7.65836
2001.2	8.76061
2004.15	9.46861
2007.09	10.6515
2010.04	11.0877
2012.98	10.5187
2015.92	10.7535
2018.86	11.4532
2021.8	10.3153
2024.73	11.1349
2027.67	10.6739
2030.61	10.3475
2033.54	7.78802
2036.47	6.3546
2039.4	5.87418
2042.33	5.21084
2045.27	4.39018
2048.19	4.22766
2051.12	3.96722
2054.05	4.53921
2056.97	4.54141
2059.9	4.69893
2062.82	4.41549
2065.74	4.98708
2068.67	5.92974
2071.59	6.2241
2074.51	7.51373
2077.42	7.93259
2080.34	8.77236
2083.26	8.72089
2086.17	9.82871
2089.09	10.284
2092	10.032
2094.91	9.69991
2097.82	9.28153
2100.73	9.1144
2103.64	7.97129
2106.55	8.19552
2109.45	8.68686
2112.36	6.96337
2115.26	6.80561
2118.17	8.86472
2121.07	9.75466
2123.97	10.0311
2126.87	11.3395
2129.77	11.7314
2132.67	13.4431
2135.56	15.4315
2138.46	18.0597
2141.35	20.0224
2144.25	22.1887
2147.14	24.3269
2150.03	26.0257
2152.92	28.5815
2155.81	31.1687
2158.7	32.836
2161.59	33.2399
2164.47	34.2948
2167.36	34.6287
2170.24	35.4388
2173.13	34.9876
2176.01	35.1803
2178.89	35.2003
2181.77	34.9329
2184.65	34.5566
2187.53	34.9443
2190.4	34.432
2193.28	32.8623
2196.16	31.7965
2199.03	31.2952
2201.9	29.3226
2204.77	28.6275
2207.64	27.2077
2210.51	26.0157
2213.38	23.8878
2216.25	21.2993
2219.12	19.3386
2221.98	17.9594
2224.85	16.3731
2227.71	15.9852
2230.57	14.9966
2233.43	13.6578
2236.29	12.5936
2239.15	11.8429
2242.01	12.0351
2244.87	11.3018
2247.72	11.8752
2250.58	11.2176
2253.43	10.9893
2256.29	9.72124
2259.14	9.52963
2261.99	9.51878
2264.84	9.04767
2267.69	8.29761
2270.53	8.05801
2273.38	7.12662
2276.23	5.65051
2279.07	5.20931
2281.91	4.83033
2284.76	4.57409
2287.6	3.46913
2290.44	3.63313
2293.28	3.17043
2296.12	3.63598
2298.96	5.00988
2301.79	4.71244
2304.63	5.09666
2307.46	6.06822
2310.3	7.38813
2313.13	7.9022
2315.96	8.77041
2318.79	8.07949
2321.62	7.7086
2324.45	8.04056
2327.27	8.2248
2330.1	8.61318
2332.92	8.46804
2335.75	8.22517
2338.57	8.34193
2341.39	7.69203
2344.21	7.09353
2347.04	6.23507
2349.85	6.40798
2352.67	4.7945
2355.49	3.47729
2358.3	1.24476
2361.12	-0.0498004
2363.93	-0.111061
2366.75	-0.220981
2369.56	-0.135991
2372.37	-0.552758
2375.18	1.22405
2377.99	1.17782
2380.8	1.20142
2383.6	0.761597
2386.41	1.52432
2389.21	1.75925
2392.02	3.04761
2394.82	3.84769
2397.62	5.48339
2400.42	6.58078
2403.22	8.70747
2406.02	10.4205
2408.82	10.9162
2411.62	11.2373
2414.41	10.9247
2417.21	11.1242
2420	10.73
2422.79	10.653
2425.59	10.6969
2428.38	10.4018
2431.17	10.3485
2433.95	10.6154
2436.74	10.4845
2439.53	9.77197
2442.31	8.53094
2445.1	8.18067
2447.88	7.65131
2450.67	6.79562
2453.45	7.10425
2456.23	6.73464
2459.01	6.06883
2461.79	6.27472
2464.57	5.88745
2467.34	5.35638
2470.12	5.0622
2472.89	4.22513
2475.67	2.94778
2478.44	2.52037
2481.21	2.20435
2483.98	2.8901
2486.75	2.27889
2489.52	2.61699
2492.29	1.93624
2495.05	2.41156
2497.82	2.6855
2500.58	3.18248
2503.35	2.89579
2506.11	2.91628
2508.87	3.87058
2511.63	4.78013
2514.39	5.14462
2517.15	5.78096
2519.91	6.45325
2522.67	7.52782
2525.42	7.38135
2528.18	8.33981
2530.93	8.48206
2533.69	8.45044
2536.44	8.58696
2539.19	9.73465
2541.94	10.7191
2544.69	10.0462
2547.44	10.418
2550.18	10.2879
2552.93	8.69976
2555.67	8.04816
2558.42	7.03432
2561.16	6.09628
2563.9	5.5982
2566.64	5.10101
2569.38	5.27047
2572.12	5.74559
2574.86	5.28579
2577.6	5.10699
2580.33	5.66316
2583.07	5.13586
2585.8	5.70499
2588.54	6.10464
2591.27	5.79234
2594	5.74217
2596.73	6.16998
2599.46	5.66723
2602.19	5.92273
2604.92	6.53407
2607.64	6.43494
2610.37	5.65423
2613.09	5.21137
2615.82	5.23851
2618.54	4.8188
2621.26	6.01148
2623.98	6.7175
2626.7	6.47633
2629.42	6.80039
2632.14	7.17583
2634.86	8.91216
2637.57	10.4358
2640.29	10.8544
2643	12.0495
2645.71	12.6096
2648.43	13.2588
2651.14	13.2774
2653.85	12.8598
2656.56	13.4085
2659.26	13.2969
2661.97	13.7737
2664.68	14.1323
2667.38	13.9384
2670.09	13.7313
2672.79	13.0187
2675.49	13.9197
2678.19	14.8467
2680.89	14.9975
2683.59	15.6701
2686.29	16.2913
2688.99	17.7618
2691.69	17.6935
2694.38	18.4868
2697.08	20.1519
2699.77	21.8595
2702.46	23.2302
2705.15	23.8705
2707.85	25.8836
2710.54	27.0581
2713.22	27.3289
2715.91	27.7467
2718.6	28.5102
2721.29	28.781
2723.97	29.5063
2726.66	28.3522
2729.34	27.6459
2732.02	26.5061
2734.7	24.7153
2737.38	22.7393
2740.06	21.6962
2742.74	20.6129
2745.42	17.9141
2748.09	16.7732
2750.77	15.4183
2753.45	14.6109
2756.12	13.1671
2758.79	11.8574
2761.46	10.3216
2764.14	9.2859
2766.8	7.62782
2769.47	7.13018
2772.14	5.31957
2774.81	4.90909
2777.48	4.24328
2780.14	4.25442
2782.8	3.6696
2785.47	4.10414
2788.13	3.71289
2790.79	2.12882
2793.45	1.34676
2796.11	0.745095
2798.77	1.0658
2801.43	1.16227
2804.09	0.73957
2806.74	0.101445
2809.4	0.30664
2812.05	0.187311
2814.71	-0.375866
2817.36	1.94016
2820.01	7.63672
2822.66	17.7283
2825.31	31.265
2827.96	47.689
2830.6	66.5846
2833.25	87.078
2835.9	106.697
2838.54	128.151
2841.18	151.217
2843.83	173.226
2846.47	195.391
2849.11	216.583
2851.75	237.101
2854.39	256.36
2857.03	273.203
2859.66	289.417
2862.3	304.071
2864.94	315.304
2867.57	323.072
2870.2	329.864
2872.84	334.061
2875.47	336.766
2878.1	338.795
2880.73	343.492
2883.36	348.272
2885.99	353.366
2888.61	359.126
2891.24	366.833
2893.86	373.507
2896.49	378.346
2899.11	384.212
2901.73	390.532
2904.36	396.882
2906.98	405.297
2909.6	412.716
2912.21	420.817
2914.83	427.279
2917.45	433.652
2920.07	437.543
2922.68	438.47
2925.29	438.354
2927.91	434.63
2930.52	428.312
2933.13	420.578
2935.74	410.562
2938.35	398.507
2940.96	384.569
2943.57	368.213
2946.18	349.766
2948.78	330.747
2951.39	312.321
2953.99	295.267
2956.59	276.831
2959.2	257.96
2961.8	240.311
2964.4	224.621
2967	209.137
2969.6	195.259
2972.19	180.368
2974.79	166.002
2977.39	153.402
2979.98	141.222
2982.58	128.137
2985.17	114.485
2987.76	100.843
2990.35	88.1375
2992.94	76.2547
2995.53	65.7227
2998.12	56.1304
3000.71	46.0283
3003.3	37.7778
3005.88	30.2285
3008.47	22.8795
3011.05	18.351
3013.64	13.1463
3016.22	9.14503
3018.8	6.4741
3021.38	4.00887
3023.96	1.50579
3026.54	1.00991
3029.12	-0.376404
3031.69	-1.15775
3034.27	-2.59474
3036.84	-3.61922
3039.42	-1.71361
3041.99	-0.250185
3044.57	0.318831
3047.14	1.15164
3049.71	1.5021
3052.28	2.24563
3054.85	2.81929
3057.41	2.79493
3059.98	2.92743
3062.55	2.43017
3065.11	2.45143
3067.68	3.14204
3070.24	2.86647
3072.8	2.35825
3075.36	2.55536
3077.93	1.44827
3080.49	1.59498
3083.04	1.36232
3085.6	0.988147
3088.16	1.96496
3090.72	2.46779
3093.27	2.70646
3095.83	3.02575
3098.38	3.91414
3100.93	5.0726
3103.49	7.05688
3106.04	8.9642
3108.59	9.57208
3111.14	11.3083
3113.69	13.5798
3116.23	15.2811
3118.78	16.4287
3121.33	18.8917
3123.87	21.0232
3126.41	23.2032
3128.96	24.7239
3131.5	26.3466
3134.04	27.6092
3136.58	28.8135
3139.12	31.207
3141.66	32.8708
3144.2	34.9183
3146.74	36.9736
3149.27	37.0923