File: data/Raman/poly_smoothed/Mb_20_23_15_1x_45s_532 nm_x100_100%_600 gr_mm_01.txt
#Acq. time (s)=	45
#Accumulations=	2
#Range (cm-¹)=	200...3150
#Windows=	2
#Auto scanning=	Off
#Autofocus=	Off
#Macrospot=	Off
#AutoExposure=	Off
#Spike filter=	Multiple accum.
#Delay time (s)=	0
#Binning=	1
#Readout mode=	Signal
#DeNoise=	Off
#ICS correction=	On
#Dark correction=	Off
#Inst. Process=	Off
#Detector Gain=	Best Dynamic Range
#Detector ADC=	20 kHz
#Detector temperature (°C)=	-69.85
#Instrument=	LabRAM HR Evol
#Detector=	Synapse
#Objective=	x100
#Grating=	600 gr/mm
#ND Filter=	100%
#Laser (nm)=	532
#Hole=	100.021
#Range=	Auto
#Laser Pol.=	No
#Raman. Pol.=	No
#Laser Pol. (°)=	-0.0007625
#Raman Pol. (°)=	89.9995
#Collection=	Microscope
#StageXY=	Marzhauser
#StageZ=	Marzhauser
#X (µm)=	-6987.9
#Y (µm)=	2089.2
#Z (µm)=	-75.05
#Full time(mm:ss)=	3:18
#Project=
#Sample=
#Site=
#Title=	Mb_20_23_15_2x_45s_532 nm_x100_100%_600 gr_mm
#Remark=
#Date=	13.07.2022 14:01
#Acquired=	13.07.2022 14:01:04
#Edit:Spike=	13.07.2022 14:03:54
#Base:Fit=	10.08.2022 10:29:37
#Base:Sub=	10.08.2022 10:32:28
#Filter:Polynom=	16.08.2022 10:13:29
#AxisType[0]=Intens
#AxisUnit[0]=Cnt
#AxisType[1]=Spectr
#AxisUnit[1]=1/cm
200.563	146.591
204.194	135.908
207.821	126.485
211.449	117.262
215.074	109.121
218.699	99.1547
222.321	90.362
225.941	81.2828
229.562	72.1723
233.18	65.0273
236.796	61.0678
240.411	55.5857
244.026	51.1222
247.638	47.5842
251.248	42.5371
254.857	37.515
258.465	35.4462
262.071	32.0499
265.678	30.5107
269.282	27.1643
272.884	23.5475
276.484	18.7047
280.084	12.6898
283.682	11.2521
287.276	8.69275
290.871	6.72181
294.465	9.22034
298.057	10.2266
301.648	10.8669
305.237	11.8221
308.823	12.5562
312.41	15.0749
315.995	17.3307
319.579	20.9234
323.16	24.3737
326.741	26.3757
330.321	28.2514
333.897	30.4822
337.474	29.6649
341.048	28.4408
344.622	27.6887
348.192	24.5601
351.764	22.4341
355.332	17.5471
358.901	13.5984
362.466	8.69736
366.03	4.77178
369.594	6.17992
373.155	6.43194
376.715	6.91072
380.273	10.0631
383.832	11.6139
387.388	13.5717
390.942	15.9816
394.495	19.4479
398.047	23.3551
401.597	24.8553
405.145	26.1207
408.693	29.3602
412.239	30.9381
415.783	32.8378
419.327	35.7473
422.869	34.3589
426.409	33.6087
429.948	34.615
433.486	34.5074
437.022	34.5551
440.558	34.5309
444.089	33.5482
447.622	32.8608
451.153	35.0115
454.682	37.7518
458.208	39.146
461.735	38.4337
465.259	39.1689
468.783	41.235
472.306	41.8596
475.825	41.8508
479.346	43.5446
482.862	43.965
486.38	43.0675
489.894	41.765
493.407	43.1804
496.92	45.4532
500.43	45.5524
503.939	47.1913
507.448	47.2893
510.954	48.259
514.459	49.2029
517.962	50.6352
521.466	52.7881
524.966	52.6638
528.466	50.1412
531.964	51.4238
535.46	51.3816
538.955	53.0426
542.449	50.7628
545.942	49.9798
549.433	47.4822
552.923	44.6621
556.412	42.0963
559.899	39.3599
563.385	36.101
566.867	33.264
570.35	28.3279
573.832	24.372
577.313	22.75
580.79	21.33
584.268	19.0935
587.745	17.9432
591.218	16.5032
594.692	15.9899
598.164	18.1075
601.634	19.768
605.104	20.1759
608.57	20.6204
612.037	21.4427
615.501	20.348
618.966	21.3259
622.427	22.9721
625.887	24.379
629.348	25.234
632.806	24.8719
636.262	23.3227
639.716	22.7058
643.172	20.586
646.624	18.9433
650.075	18.7018
653.524	17.7368
656.972	16.9673
660.419	14.7346
663.865	15.2767
667.309	11.2936
670.752	9.53418
674.194	8.47217
677.634	6.60302
681.073	8.16142
684.511	6.47043
687.947	6.11206
691.382	8.46478
694.816	10.1287
698.247	10.8994
701.678	15.5187
705.108	19.5367
708.534	24.4382
711.962	26.0856
715.388	28.8764
718.81	29.12
722.234	29.9799
725.654	29.7442
729.075	31.8525
732.492	34.7337
735.91	36.043
739.325	37.7516
742.741	38.445
746.153	39.9514
749.564	40.5704
752.976	39.285
756.385	40.5469
759.792	40.2092
763.2	43.238
766.604	47.9645
770.008	49.2758
773.41	53.2599
776.811	56.0534
780.21	57.8081
783.608	63.7723
787.005	65.8413
790.401	67.513
793.795	70.6984
797.188	71.4137
800.58	72.4961
803.971	71.6813
807.36	73.2605
810.748	74.4887
814.135	75.1874
817.518	75.998
820.902	77.4557
824.285	79.0839
827.665	75.7536
831.045	74.7285
834.424	74.0733
837.8	72.0243
841.177	72.3293
844.55	72.2007
847.924	72.1479
851.295	68.1407
854.666	65.4215
858.034	62.7153
861.403	61.2802
864.769	60.1467
868.133	59.1303
871.498	58.2049
874.86	57.0787
878.221	55.6648
881.58	56.2687
884.938	53.8678
888.297	54.6
891.653	58.5748
895.007	59.2001
898.36	61.7915
901.712	64.5542
905.063	62.9262
908.412	62.6627
911.76	64.0148
915.107	64.8634
918.452	66.9338
921.797	66.9759
925.138	66.899
928.48	67.3188
931.82	62.965
935.16	59.8977
938.496	54.4532
941.833	50.0371
945.168	42.042
948.5	39.4676
951.834	44.6801
955.163	48.3841
958.494	52.9949
961.821	59.8283
965.15	72.5454
968.474	86.7327
971.8	105.59
975.123	122.589
978.446	135.057
981.766	149.187
985.084	159.266
988.402	166.419
991.72	171.518
995.035	173.436
998.349	171.314
1001.66	164.231
1004.97	154.177
1008.28	145.122
1011.59	137.498
1014.9	127.857
1018.21	122.62
1021.51	113.69
1024.81	110.819
1028.12	110.789
1031.42	114.484
1034.72	115.813
1038.02	116.351
1041.31	118.633
1044.61	123.848
1047.91	128.049
1051.2	133.851
1054.49	135.159
1057.78	135.06
1061.07	133.826
1064.36	131.357
1067.65	125.18
1070.93	117.363
1074.22	110.359
1077.5	100.11
1080.78	92.0874
1084.06	83.1904
1087.34	82.4748
1090.62	83.5664
1093.9	84.968
1097.17	86.4699
1100.45	89.6419
1103.72	92.2765
1106.99	95.6756
1110.27	95.8449
1113.53	94.9928
1116.8	94.4515
1120.07	92.4398
1123.33	88.7378
1126.6	85.4941
1129.86	83.5685
1133.12	79.6567
1136.38	75.5182
1139.64	72.8005
1142.9	70.2485
1146.16	64.5375
1149.41	56.3353
1152.67	49.4773
1155.92	43.1398
1159.17	34.5677
1162.42	29.7985
1165.67	24.2364
1168.92	24.0001
1172.16	19.3177
1175.41	18.7414
1178.65	19.2491
1181.9	21.3975
1185.14	22.2384
1188.38	23.1894
1191.62	25.2239
1194.86	28.5463
1198.09	34.8682
1201.33	40.3988
1204.56	47.5944
1207.8	57.0175
1211.03	64.728
1214.26	73.6864
1217.49	82.8886
1220.71	92.0257
1223.94	99.7227
1227.16	105.905
1230.39	112.369
1233.61	120.32
1236.83	125.555
1240.05	133.343
1243.27	140.759
1246.49	145.993
1249.71	150.988
1252.92	152.952
1256.14	156.417
1259.35	163.009
1262.56	168.583
1265.77	175.818
1268.98	180.643
1272.19	187.941
1275.4	196.151
1278.6	203.21
1281.81	210.429
1285.01	219.116
1288.21	224.224
1291.41	228.76
1294.61	233.168
1297.81	238.365
1301.01	243.368
1304.2	244.436
1307.4	245.783
1310.59	246.849
1313.78	249.873
1316.97	251.094
1320.16	248.322
1323.35	245.955
1326.54	240.119
1329.72	234.96
1332.91	228.247
1336.09	224.679
1339.27	221.721
1342.45	216.993
1345.64	212.43
1348.81	206.893
1351.99	204.02
1355.17	201.522
1358.34	197.937
1361.51	194.472
1364.69	191.485
1367.86	185.915
1371.03	183.948
1374.2	181.635
1377.37	178.445
1380.53	176.607
1383.7	175.755
1386.86	175.153
1390.02	175.71
1393.19	172.55
1396.35	170.283
1399.51	170.265
1402.66	173.664
1405.82	178.835
1408.97	186.529
1412.13	199.599
1415.28	213.277
1418.43	231.206
1421.59	250.432
1424.73	272.895
1427.88	294.032
1431.03	316.831
1434.18	335.096
1437.32	352.01
1440.46	366.924
1443.61	374.871
1446.75	380.808
1449.89	378.719
1453.03	374.284
1456.16	364.574
1459.3	351.231
1462.44	332.759
1465.57	312.84
1468.7	289.004
1471.83	264.72
1474.96	242.158
1478.09	220.527
1481.22	197.099
1484.35	177.487
1487.47	158.647
1490.6	141.598
1493.72	127.296
1496.84	115.322
1499.96	103.93
1503.08	95.5431
1506.2	87.7642
1509.32	81.9349
1512.44	73.7923
1515.55	69.8085
1518.66	64.574
1521.78	61.9529
1524.89	58.5077
1528	58.3558
1531.11	59.5739
1534.21	60.4291
1537.32	64.6736
1540.43	70.1641
1543.53	75.2926
1546.63	79.8479
1549.74	87.2422
1552.84	93.3011
1555.94	98.2372
1559.03	103.401
1562.13	108.777
1565.23	114.672
1568.32	120.481
1571.42	126.877
1574.51	131.982
1577.6	138.367
1580.69	144.791
1583.78	150.443
1586.87	156.38
1589.95	159.703
1593.04	162.94
1596.12	164.686
1599.21	168.666
1602.29	169.05
1605.37	167.616
1608.45	168.316
1611.53	168.031
1614.6	170.686
1617.68	173.205
1620.75	176.236
1623.83	179.926
1626.9	183.515
1629.97	186.821
1633.04	192.629
1636.11	199.217
1639.18	204.737
1642.25	211.823
1645.31	218.089
1648.38	222.484
1651.44	227.222
1654.5	230.439
1657.56	229.046
1660.62	226.798
1663.68	221.014
1666.74	214.304
1669.8	204.79
1672.85	193.52
1675.91	179.161
1678.96	164.993
1682.01	149.318
1685.06	135.38
1688.11	123.145
1691.16	108.709
1694.21	97.7109
1697.25	86.4441
1700.3	75.4942
1703.34	67.6019
1706.39	59.8561
1709.43	53.0682
1712.47	48.6899
1715.51	43.691
1718.54	40.0423
1721.58	38.1335
1724.62	34.5074
1727.65	31.3123
1730.68	29.3131
1733.72	26.0077
1736.75	24.3413
1739.78	22.3938
1742.81	18.9685
1745.84	15.4285
1748.86	14.0038
1751.89	12.7963
1754.91	11.0303
1757.93	7.97235
1760.96	7.10489
1763.98	5.55613
1767	5.34438
1770.02	5.30422
1773.03	3.41262
1776.05	2.208
1779.07	2.3646
1782.08	1.51139
1785.09	2.03873
1788.11	2.46799
1791.12	2.23589
1794.13	3.87363
1797.13	4.49625
1800.14	4.16694
1803.15	3.54369
1806.15	2.33707
1809.16	2.11445
1812.16	2.65862
1815.16	2.7131
1818.16	1.36516
1821.16	0.941924
1824.16	0.0334112
1827.16	-0.0210842
1830.16	-0.199043
1833.15	-0.582229
1836.14	0.578022
1839.14	1.03559
1842.13	0.250748
1845.12	0.615074
1848.11	0.598139
1851.1	1.36316
1854.08	0.967862
1857.07	2.12167
1860.05	2.63898
1863.04	3.51363
1866.02	4.55911
1869	4.71919
1871.98	3.22085
1874.96	2.59398
1877.94	2.80955
1880.92	4.36484
1882.51	4.85403
1885.5	4.75221
1888.48	3.44814
1891.47	2.07526
1894.46	2.45276
1897.44	3.20288
1900.42	2.40575
1903.41	3.24305
1906.39	3.74251
1909.37	5.2658
1912.35	6.789
1915.32	8.67052
1918.3	12.4939
1921.27	12.7508
1924.25	14.2508
1927.22	15.0148
1930.19	14.9456
1933.17	13.5536
1936.14	12.9257
1939.11	12.2727
1942.07	11.3184
1945.04	11.496
1948.01	10.7927
1950.97	10.5456
1953.93	11.1983
1956.9	9.44485
1959.86	6.58636
1962.82	5.80293
1965.78	5.12943
1968.74	5.0052
1971.69	4.98043
1974.65	5.76186
1977.6	9.12323
1980.56	10.5668
1983.51	13.3624
1986.46	15.7382
1989.41	16.2031
1992.36	17.9097
1995.31	17.6732
1998.26	17.0158
2001.2	17.4609
2004.15	17.9092
2007.09	17.8203
2010.04	19.0601
2012.98	18.9644
2015.92	17.4608
2018.86	18.8671
2021.8	18.3496
2024.73	18.4275
2027.67	18.6376
2030.61	18.5248
2033.54	20.9056
2036.47	23.1541
2039.4	24.0011
2042.33	26.2626
2045.27	27.0208
2048.19	28.7332
2051.12	30.1536
2054.05	28.0051
2056.97	27.9812
2059.9	25.9382
2062.82	26.5179
2065.74	27.6407
2068.67	27.7382
2071.59	27.3602
2074.51	27.8609
2077.42	27.279
2080.34	27.79
2083.26	29.0512
2086.17	26.3451
2089.09	27.1548
2092	29.9062
2094.91	30.4107
2097.82	31.732
2100.73	35.6004
2103.64	38.1205
2106.55	41.0954
2109.45	43.8527
2112.36	47.603
2115.26	51.4369
2118.17	53.8569
2121.07	56.4872
2123.97	59.4061
2126.87	63.4176
2129.77	70.4118
2132.67	73.6473
2135.56	80.0253
2138.46	85.9455
2141.35	91.3179
2144.25	96.0787
2147.14	103.991
2150.03	109.756
2152.92	116.286
2155.81	120.297
2158.7	125.66
2161.59	131.839
2164.47	136.948
2167.36	139.857
2170.24	147.371
2173.13	149.129
2176.01	148.601
2178.89	147.666
2181.77	147.071
2184.65	143.698
2187.53	139.348
2190.4	134.12
2193.28	129.866
2196.16	124.605
2199.03	118.464
2201.9	110.504
2204.77	102.628
2207.64	95.475
2210.51	89.0705
2213.38	82.2558
2216.25	75.7201
2219.12	71.7032
2221.98	65.6694
2224.85	60.7583
2227.71	57.8438
2230.57	55.9243
2233.43	52.1468
2236.29	50.6184
2239.15	49.3651
2242.01	46.0605
2244.87	42.2256
2247.72	39.5157
2250.58	38.5397
2253.43	36.5379
2256.29	35.4457
2259.14	33.2081
2261.99	32.0131
2264.84	31.0167
2267.69	30.1474
2270.53	29.5324
2273.38	26.4488
2276.23	26.2217
2279.07	25.4433
2281.91	23.7798
2284.76	22.0355
2287.6	20.7857
2290.44	21.0961
2293.28	19.9267
2296.12	19.5888
2298.96	22.0557
2301.79	21.9834
2304.63	22.51
2307.46	22.7175
2310.3	22.8936
2313.13	22.8287
2315.96	22.1684
2318.79	22.1459
2321.62	21.6029
2324.45	22.2645
2327.27	20.6527
2330.1	17.1336
2332.92	15.9846
2335.75	14.038
2338.57	14.0932
2341.39	11.3507
2344.21	8.36166
2347.04	6.40865
2349.85	3.42276
2352.67	3.56826
2355.49	2.28972
2358.3	1.40451
2361.12	1.14178
2363.93	1.76691
2366.75	2.73401
2369.56	4.36931
2372.37	3.39389
2375.18	2.22135
2377.99	2.2848
2380.8	2.30726
2383.6	2.65655
2386.41	4.09306
2389.21	4.94812
2392.02	6.08908
2394.82	6.13094
2397.62	5.8693
2400.42	7.468
2403.22	8.27694
2406.02	10.0083
2408.82	11.8311
2411.62	12.644
2414.41	13.0112
2417.21	13.6666
2420	13.7759
2422.79	13.0016
2425.59	14.4601
2428.38	13.6882
2431.17	14.6857
2433.95	14.9282
2436.74	12.8483
2439.53	12.0557
2442.31	12.4683
2445.1	11.4832
2447.88	11.1194
2450.67	11.5306
2453.45	13.3664
2456.23	14.2643
2459.01	12.7932
2461.79	12.6002
2464.57	13.6129
2467.34	13.0571
2470.12	13.7562
2472.89	13.4189
2475.67	13.2792
2478.44	11.2766
2481.21	10.1487
2483.98	8.87134
2486.75	7.28836
2489.52	6.69524
2492.29	6.41985
2495.05	4.42483
2497.82	2.57263
2500.58	-0.0168602
2503.35	-2.48042
2506.11	-2.63594
2508.87	-2.46573
2511.63	-1.8927
2514.39	-3.12222
2517.15	-2.98034
2519.91	-1.54903
2522.67	-1.72363
2525.42	0.573264
2528.18	1.83975
2530.93	3.17922
2533.69	4.93346
2536.44	5.65797
2539.19	6.27256
2541.94	6.71741
2544.69	9.29132
2547.44	9.62521
2550.18	10.1674
2552.93	11.424
2555.67	11.0348
2558.42	10.6619
2561.16	9.52112
2563.9	9.57623
2566.64	8.99977
2569.38	7.22943
2572.12	5.4835
2574.86	5.13061
2577.6	4.92042
2580.33	3.83539
2583.07	3.24695
2585.8	3.76285
2588.54	4.02219
2591.27	4.75612
2594	4.98064
2596.73	4.95845
2599.46	5.60439
2602.19	5.52872
2604.92	5.81161
2607.64	5.05868
2610.37	6.18471
2613.09	5.7555
2615.82	5.57104
2618.54	6.28099
2621.26	6.96171
2623.98	7.8262
2626.7	8.8611
2629.42	9.27481
2632.14	8.73341
2634.86	8.3076
2637.57	8.14658
2640.29	8.79026
2643	9.77911
2645.71	9.59545
2648.43	10.5385
2651.14	9.94947
2653.85	9.9799
2656.56	10.5975
2659.26	9.5119
2661.97	10.4294
2664.68	10.9464
2667.38	12.2117
2670.09	11.4685
2672.79	12.9507
2675.49	12.6497
2678.19	12.1208
2680.89	12.6892
2683.59	12.6637
2686.29	12.5605
2688.99	12.8895
2691.69	13.4472
2694.38	15.2772
2697.08	16.9672
2699.77	18.2865
2702.46	20.0132
2705.15	23.3624
2707.85	26.3133
2710.54	27.8839
2713.22	30.7025
2715.91	31.2488
2718.6	31.8014
2721.29	32.4234
2723.97	33.1251
2726.66	32.9808
2729.34	33.2568
2732.02	33.4547
2734.7	31.6755
2737.38	30.0977
2740.06	28.0917
2742.74	24.9988
2745.42	19.3418
2748.09	16.6687
2750.77	12.4285
2753.45	9.85355
2756.12	7.79635
2758.79	6.5514
2761.46	4.53284
2764.14	3.51091
2766.8	1.66459
2769.47	1.67958
2772.14	2.73406
2774.81	2.92771
2777.48	2.2232
2780.14	1.97144
2782.8	0.60795
2785.47	0.193467
2788.13	0.13448
2790.79	-0.325018
2793.45	-1.35647
2796.11	-1.21602
2798.77	-1.53286
2801.43	-2.68865
2804.09	-2.35765
2806.74	-4.91414
2809.4	-5.68563
2812.05	-5.83398
2814.71	-1.71018
2817.36	7.78522
2820.01	22.8655
2822.66	42.7021
2825.31	64.2354
2827.96	92.0156
2830.6	120.778
2833.25	152.287
2835.9	186.415
2838.54	220.238
2841.18	255.874
2843.83	290.84
2846.47	324.649
2849.11	358.969
2851.75	398.133
2854.39	439.774
2857.03	482.765
2859.66	524.225
2862.3	562.541
2864.94	595.019
2867.57	623.034
2870.2	645.488
2872.84	666.412
2875.47	686.525
2878.1	706.109
2880.73	728.291
2883.36	749.404
2885.99	767.734
2888.61	783.074
2891.24	799.126
2893.86	814.019
2896.49	830.124
2899.11	846.682
2901.73	864.499
2904.36	881.456
2906.98	904.346
2909.6	929.935
2912.21	958.154
2914.83	995.44
2917.45	1030.62
2920.07	1059.42
2922.68	1082.97
2925.29	1098.8
2927.91	1107.71
2930.52	1109.15
2933.13	1102.85
2935.74	1092.55
2938.35	1076.14
2940.96	1053.04
2943.57	1024.25
2946.18	991.128
2948.78	952.508
2951.39	910.84
2953.99	867.215
2956.59	825.187
2959.2	779.614
2961.8	737.308
2964.4	695.64
2967	655.589
2969.6	620.509
2972.19	586.565
2974.79	549.855
2977.39	515.969
2979.98	478.045
2982.58	440.247
2985.17	402.303
2987.76	366.237
2990.35	330.395
2992.94	295.916
2995.53	260.821
2998.12	227.224
3000.71	198.777
3003.3	169.536
3005.88	142.88
3008.47	121.676
3011.05	102.29
3013.64	82.5851
3016.22	67.1933
3018.8	54.6214
3021.38	42.5176
3023.96	34.8389
3026.54	28.8653
3029.12	24.3092
3031.69	21.8723
3034.27	19.932
3036.84	19.6437
3039.42	19.8266
3041.99	21.6681
3044.57	22.018
3047.14	23.3209
3049.71	25.0812
3052.28	25.9532
3054.85	26.2437
3057.41	24.1092
3059.98	23.6829
3062.55	21.7504
3065.11	20.1161
3067.68	18.6598
3070.24	17.2395
3072.8	14.8381
3075.36	12.5654
3077.93	8.12042
3080.49	6.01392
3083.04	4.25317
3085.6	3.31557
3088.16	3.18852
3090.72	2.47357
3093.27	3.70954
3095.83	4.57181
3098.38	8.57372
3100.93	11.2753
3103.49	13.502
3106.04	17.4799
3108.59	19.7748
3111.14	23.9052
3113.69	28.5387
3116.23	31.418
3118.78	35.2038
3121.33	38.8774
3123.87	43.2943
3126.41	48.9874
3128.96	53.8758
3131.5	56.9615
3134.04	61.8467
3136.58	66.5019
3139.12	71.4653
3141.66	76.7974
3144.2	82.7846
3146.74	86.2655
3149.27	88.5941