File: data/Raman/poly_smoothed/Mb_20_23_21_1x_45s_532 nm_x100_100%_600 gr_mm_01.txt
#Acq. time (s)=	45
#Accumulations=	2
#Range (cm-¹)=	200...3150
#Windows=	2
#Auto scanning=	Off
#Autofocus=	Off
#Macrospot=	Off
#AutoExposure=	Off
#Spike filter=	Multiple accum.
#Delay time (s)=	0
#Binning=	1
#Readout mode=	Signal
#DeNoise=	Off
#ICS correction=	On
#Dark correction=	Off
#Inst. Process=	Off
#Detector Gain=	Best Dynamic Range
#Detector ADC=	20 kHz
#Detector temperature (°C)=	-69.85
#Instrument=	LabRAM HR Evol
#Detector=	Synapse
#Objective=	x100
#Grating=	600 gr/mm
#ND Filter=	100%
#Laser (nm)=	532
#Hole=	100.021
#Range=	Auto
#Laser Pol.=	No
#Raman. Pol.=	No
#Laser Pol. (°)=	-0.0007625
#Raman Pol. (°)=	89.9995
#Collection=	Microscope
#StageXY=	Marzhauser
#StageZ=	Marzhauser
#X (µm)=	-6913.2
#Y (µm)=	2067.5
#Z (µm)=	-75.1
#Full time(mm:ss)=	3:18
#Project=
#Sample=
#Site=
#Title=	Mb_20_23_21_2x_45s_532 nm_x100_100%_600 gr_mm
#Remark=
#Date=	13.07.2022 14:47
#Acquired=	13.07.2022 14:47:00
#Base:Fit=	10.08.2022 10:29:37
#Base:Sub=	10.08.2022 10:33:46
#Filter:Polynom=	16.08.2022 10:13:29
#AxisType[0]=Intens
#AxisUnit[0]=Cnt
#AxisType[1]=Spectr
#AxisUnit[1]=1/cm
200.563	9.26244
204.194	8.6256
207.821	7.71923
211.449	5.88087
215.074	5.23102
218.699	6.13438
222.321	8.36445
225.941	8.84568
229.562	8.91165
233.18	7.87895
236.796	7.25373
240.411	7.81953
244.026	8.01981
247.638	7.86025
251.248	9.44555
254.857	8.13006
258.465	9.15673
262.071	8.76181
265.678	7.09712
269.282	5.06463
272.884	5.19534
276.484	3.99035
280.084	3.28359
283.682	3.9895
287.276	2.9688
290.871	3.22656
294.465	3.8984
298.057	6.73579
301.648	8.97683
305.237	12.4712
308.823	16.1764
312.41	18.425
315.995	19.9476
319.579	21.422
323.16	22.318
326.741	25.2013
330.321	27.5683
333.897	28.1086
337.474	28.2239
341.048	27.2839
344.622	25.6137
348.192	22.3385
351.764	19.0245
355.332	15.7656
358.901	14.3528
362.466	14.0842
366.03	12.3546
369.594	10.9858
373.155	10.2054
376.715	11.5906
380.273	14.6716
383.832	15.7839
387.388	16.2857
390.942	18.4995
394.495	19.3584
398.047	19.0338
401.597	19.4748
405.145	20.0792
408.693	18.675
412.239	16.2876
415.783	15.8865
419.327	15.9539
422.869	13.4994
426.409	10.8743
429.948	9.52208
433.486	6.14996
437.022	3.27559
440.558	3.20962
444.089	4.83823
447.622	3.85453
451.153	5.01371
454.682	6.82557
458.208	9.05327
461.735	12.2283
465.259	14.5291
468.783	16.4417
472.306	17.343
475.825	20.5718
479.346	23.8882
482.862	25.3375
486.38	28.8637
489.894	30.921
493.407	32.7824
496.92	34.327
500.43	36.2038
503.939	39.7383
507.448	42.754
510.954	45.625
514.459	45.0236
517.962	46.6308
521.466	45.2001
524.966	45.7861
528.466	44.5343
531.964	43.349
535.46	42.6956
538.955	41.61
542.449	39.7244
545.942	38.0159
549.433	36.2322
552.923	33.746
556.412	31.9575
559.899	28.9171
563.385	27.0617
566.867	25.7372
570.35	22.3904
573.832	20.4384
577.313	17.4566
580.79	15.6718
584.268	13.8053
587.745	11.7075
591.218	11.4064
594.692	9.15729
598.164	7.15687
601.634	7.09821
605.104	4.26221
608.57	3.09119
612.037	4.09987
615.501	3.41747
618.966	2.68568
622.427	2.83146
625.887	2.34324
629.348	2.45696
632.806	4.4283
636.262	4.36477
639.716	3.90895
643.172	2.58576
646.624	3.87986
650.075	6.17394
653.524	6.36888
656.972	6.83275
660.419	5.88477
663.865	4.68211
667.309	6.43164
670.752	6.70942
674.194	7.29222
677.634	6.99845
681.073	7.65222
684.511	10.3325
687.947	11.8015
691.382	9.17011
694.816	9.80288
698.247	12.0845
701.678	11.6258
705.108	13.4386
708.534	13.6306
711.962	14.8888
715.388	17.6403
718.81	18.789
722.234	18.9288
725.654	21.7511
729.075	24.1348
732.492	27.266
735.91	26.793
739.325	27.3301
742.741	27.8828
746.153	29.7194
749.564	31.9167
752.976	35.7436
756.385	37.7651
759.792	40.8804
763.2	42.4456
766.604	44.1399
770.008	44.6772
773.41	45.0261
776.811	46.3978
780.21	50.0715
783.608	51.5604
787.005	53.0408
790.401	55.6077
793.795	57.9004
797.188	60.8316
800.58	64.3812
803.971	71.2
807.36	73.7775
810.748	78.7406
814.135	81.7492
817.518	83.0816
820.902	86.2758
824.285	88.2204
827.665	91.9504
831.045	94.8051
834.424	97.6605
837.8	98.3832
841.177	96.3745
844.55	95.2572
847.924	91.2883
851.295	86.5686
854.666	83.7521
858.034	80.7556
861.403	78.3951
864.769	76.7459
868.133	73.9961
871.498	73.1647
874.86	74.56
878.221	74.7661
881.58	76.2127
884.938	76.9175
888.297	74.177
891.653	72.8746
895.007	73.8018
898.36	72.839
901.712	71.6109
905.063	72.9745
908.412	72.9081
911.76	72.1958
915.107	71.4123
918.452	71.9063
921.797	67.7605
925.138	68.5914
928.48	66.2399
931.82	64.0738
935.16	63.4338
938.496	62.6208
941.833	61.3871
945.168	58.5976
948.5	55.8849
951.834	57.0861
955.163	57.3062
958.494	55.3502
961.821	51.1469
965.15	50.8012
968.474	51.4122
971.8	54.1426
975.123	57.0999
978.446	60.5609
981.766	61.8839
985.084	64.9686
988.402	69.1424
991.72	66.9921
995.035	70.3524
998.349	72.3643
1001.66	73.9898
1004.97	75.2985
1008.28	78.7322
1011.59	80.2822
1014.9	80.4272
1018.21	80.9752
1021.51	78.5547
1024.81	73.7819
1028.12	73.8487
1031.42	73.9657
1034.72	72.3468
1038.02	69.3848
1041.31	67.8192
1044.61	71.5452
1047.91	74.7637
1051.2	78.4446
1054.49	78.7437
1057.78	79.4063
1061.07	79.5753
1064.36	79.8688
1067.65	80.3658
1070.93	78.3443
1074.22	76.1554
1077.5	75.5534
1080.78	72.854
1084.06	71.9877
1087.34	70.9262
1090.62	70.5758
1093.9	69.6757
1097.17	67.2277
1100.45	65.5832
1103.72	63.5342
1106.99	61.3577
1110.27	60.5431
1113.53	55.7551
1116.8	54.0365
1120.07	50.4729
1123.33	48.651
1126.6	44.7733
1129.86	43.9329
1133.12	41.5584
1136.38	38.6419
1139.64	36.8735
1142.9	32.8803
1146.16	28.6985
1149.41	24.4763
1152.67	19.6241
1155.92	14.0087
1159.17	8.14758
1162.42	5.8823
1165.67	5.19088
1168.92	5.42633
1172.16	4.64943
1175.41	5.94671
1178.65	7.42384
1181.9	10.5004
1185.14	11.6733
1188.38	13.5781
1191.62	16.1361
1194.86	17.579
1198.09	21.3387
1201.33	26.274
1204.56	33.5878
1207.8	41.2522
1211.03	49.2931
1214.26	54.0844
1217.49	60.4964
1220.71	66.6958
1223.94	70.944
1227.16	77.8083
1230.39	83.3424
1233.61	89.7748
1236.83	94.1004
1240.05	99.8984
1243.27	107.15
1246.49	110.153
1249.71	113.922
1252.92	115.212
1256.14	118.126
1259.35	122.646
1262.56	127.761
1265.77	130.395
1268.98	138.912
1272.19	147.083
1275.4	155.907
1278.6	165.825
1281.81	177.14
1285.01	186.357
1288.21	193.135
1291.41	201.228
1294.61	206.758
1297.81	213.12
1301.01	218.034
1304.2	221.008
1307.4	222.253
1310.59	222.981
1313.78	222.744
1316.97	220.152
1320.16	214.324
1323.35	206.68
1326.54	196.889
1329.72	186.314
1332.91	175.185
1336.09	166.109
1339.27	156.113
1342.45	147.96
1345.64	142.007
1348.81	134.957
1351.99	128.665
1355.17	121.27
1358.34	115.441
1361.51	111.532
1364.69	106.143
1367.86	102.123
1371.03	97.7099
1374.2	94.2464
1377.37	93.1748
1380.53	91.4253
1383.7	91.4306
1386.86	93.1003
1390.02	93.7739
1393.19	93.9225
1396.35	91.8824
1399.51	94.2813
1402.66	96.6482
1405.82	104.386
1408.97	113.092
1412.13	124.534
1415.28	142.837
1418.43	162.164
1421.59	184.356
1424.73	208.526
1427.88	232.587
1431.03	254.837
1434.18	275.341
1437.32	294.484
1440.46	308.286
1443.61	318.684
1446.75	324.416
1449.89	324.967
1453.03	320.297
1456.16	312.63
1459.3	298.905
1462.44	279.212
1465.57	255.233
1468.7	226.714
1471.83	197.338
1474.96	169.29
1478.09	142.961
1481.22	118.454
1484.35	96.676
1487.47	77.0184
1490.6	61.6898
1493.72	47.2561
1496.84	35.5557
1499.96	30.297
1503.08	26.1356
1506.2	21.179
1509.32	18.6846
1512.44	18.1195
1515.55	17.1533
1518.66	17.3139
1521.78	17.6597
1524.89	18.2476
1528	20.5262
1531.11	23.6503
1534.21	25.8607
1537.32	28.6645
1540.43	30.8831
1543.53	33.919
1546.63	36.7642
1549.74	40.1682
1552.84	43.6757
1555.94	48.001
1559.03	49.0445
1562.13	51.8228
1565.23	54.6582
1568.32	57.2054
1571.42	62.205
1574.51	69.4754
1577.6	75.675
1580.69	81.1861
1583.78	87.5305
1586.87	94.0417
1589.95	96.6407
1593.04	101.541
1596.12	105.088
1599.21	109.208
1602.29	110.251
1605.37	113.325
1608.45	113.413
1611.53	114.479
1614.6	116.907
1617.68	118.105
1620.75	122.479
1623.83	124.846
1626.9	129.642
1629.97	134.216
1633.04	138.942
1636.11	144.093
1639.18	151.962
1642.25	160.474
1645.31	167.105
1648.38	173.125
1651.44	180.099
1654.5	184.369
1657.56	185.983
1660.62	185.293
1663.68	182.103
1666.74	176.372
1669.8	168.344
1672.85	157.708
1675.91	145.823
1678.96	132.794
1682.01	121.03
1685.06	107.22
1688.11	95.2363
1691.16	84.5576
1694.21	72.9909
1697.25	63.9635
1700.3	56.1781
1703.34	48.3897
1706.39	43.368
1709.43	38.9768
1712.47	37.6665
1715.51	37.057
1718.54	35.3386
1721.58	34.7805
1724.62	36.6321
1727.65	36.5057
1730.68	34.8903
1733.72	33.2523
1736.75	31.0293
1739.78	28.7507
1742.81	26.1373
1745.84	25.158
1748.86	23.7658
1751.89	22.1108
1754.91	21.3123
1757.93	19.2079
1760.96	15.6559
1763.98	13.5325
1767	10.9794
1770.02	8.71198
1773.03	6.61639
1776.05	6.07672
1779.07	5.11316
1782.08	4.86354
1785.09	5.3037
1788.11	4.30736
1791.12	4.45349
1794.13	3.64892
1797.13	3.17592
1800.14	1.66006
1803.15	0.623284
1806.15	0.578654
1809.16	-0.051108
1812.16	-0.291833
1815.16	-0.133875
1818.16	0.975754
1821.16	1.71532
1824.16	2.47357
1827.16	2.43834
1830.16	3.06435
1833.15	2.89493
1836.14	3.30184
1839.14	3.93499
1842.13	4.59942
1845.12	4.70328
1848.11	5.1522
1851.1	5.77163
1854.08	5.68264
1857.07	5.10488
1860.05	4.34276
1863.04	3.68962
1866.02	3.45702
1869	2.292
1871.98	2.41537
1874.96	2.61268
1877.94	3.25123
1880.92	3.52112
1882.51	2.46267
1885.5	2.73219
1888.48	1.84944
1891.47	1.15874
1894.46	-0.0042918
1897.44	-1.2693
1900.42	-1.55438
1903.41	-2.06181
1906.39	-0.768127
1909.37	-0.0363273
1912.35	0.997064
1915.32	3.12169
1918.3	3.40296
1921.27	5.14053
1924.25	4.85859
1927.22	4.66635
1930.19	5.30871
1933.17	5.30719
1936.14	6.91995
1939.11	6.96454
1942.07	7.29067
1945.04	8.72384
1948.01	9.41199
1950.97	9.59326
1953.93	9.97098
1956.9	10.6589
1959.86	10.5807
1962.82	9.50691
1965.78	9.72208
1968.74	8.68703
1971.69	8.68833
1974.65	7.84864
1977.6	8.05035
1980.56	7.88985
1983.51	8.19108
1986.46	9.80871
1989.41	9.4391
1992.36	8.30823
1995.31	7.91432
1998.26	7.141
2001.2	7.48711
2004.15	7.3188
2007.09	7.69062
2010.04	7.59428
2012.98	8.01657
2015.92	9.07628
2018.86	9.23042
2021.8	10.5695
2024.73	12.5601
2027.67	13.2002
2030.61	13.0032
2033.54	13.6693
2036.47	12.9619
2039.4	14.2166
2042.33	15.3401
2045.27	16.4053
2048.19	16.8351
2051.12	16.0967
2054.05	17.9007
2056.97	18.9384
2059.9	17.4988
2062.82	16.7375
2065.74	16.8987
2068.67	17.1977
2071.59	16.5478
2074.51	17.3675
2077.42	18.5117
2080.34	18.9175
2083.26	19.0163
2086.17	21.2147
2089.09	22.0935
2092	22.799
2094.91	23.7308
2097.82	25.168
2100.73	27.3246
2103.64	28.8419
2106.55	30.7647
2109.45	34.1056
2112.36	36.7358
2115.26	38.9086
2118.17	39.9488
2121.07	42.4793
2123.97	46.0185
2126.87	47.9159
2129.77	50.0184
2132.67	53.0505
2135.56	56.5001
2138.46	61.3105
2141.35	66.2948
2144.25	72.1267
2147.14	78.1935
2150.03	83.7991
2152.92	89.451
2155.81	96.2745
2158.7	101.346
2161.59	106.313
2164.47	111.184
2167.36	114.332
2170.24	119.651
2173.13	121.699
2176.01	122.841
2178.89	122.806
2181.77	121.168
2184.65	118.604
2187.53	115.738
2190.4	110.015
2193.28	105.054
2196.16	99.3356
2199.03	93.7236
2201.9	88.7882
2204.77	82.4648
2207.64	77.747
2210.51	73.2074
2213.38	67.1653
2216.25	63.3369
2219.12	59.1108
2221.98	55.8445
2224.85	52.6708
2227.71	50.326
2230.57	46.4672
2233.43	45.2125
2236.29	43.1478
2239.15	42.1756
2242.01	40.5618
2244.87	38.1096
2247.72	35.4803
2250.58	32.9494
2253.43	30.9017
2256.29	29.6138
2259.14	28.1608
2261.99	27.8194
2264.84	27.2871
2267.69	27.5622
2270.53	26.0251
2273.38	24.3393
2276.23	23.0173
2279.07	20.6829
2281.91	19.3346
2284.76	18.2615
2287.6	16.0855
2290.44	14.8255
2293.28	12.6568
2296.12	12.0584
2298.96	12.0924
2301.79	11.1951
2304.63	10.2602
2307.46	9.55788
2310.3	9.98586
2313.13	9.88577
2315.96	9.79936
2318.79	9.94221
2321.62	10.8339
2324.45	10.7852
2327.27	11.1103
2330.1	10.5285
2332.92	10.3211
2335.75	10.5212
2338.57	8.73899
2341.39	8.02893
2344.21	6.57638
2347.04	5.4762
2349.85	5.41325
2352.67	3.86855
2355.49	4.53558
2358.3	4.23153
2361.12	4.45408
2363.93	4.93882
2366.75	7.31443
2369.56	7.41233
2372.37	6.70293
2375.18	7.53062
2377.99	8.93186
2380.8	9.50706
2383.6	10.4126
2386.41	9.57987
2389.21	9.34266
2392.02	9.47235
2394.82	8.55152
2397.62	7.59059
2400.42	8.22687
2403.22	8.7687
2406.02	8.67681
2408.82	7.4075
2411.62	8.01388
2414.41	8.33569
2417.21	9.7193
2420	9.81095
2422.79	10.9297
2425.59	11.7263
2428.38	12.6872
2431.17	13.3851
2433.95	13.4824
2436.74	12.4899
2439.53	10.917
2442.31	9.85307
2445.1	9.68601
2447.88	9.55374
2450.67	9.00414
2453.45	7.00632
2456.23	6.94128
2459.01	5.99679
2461.79	6.65629
2464.57	7.06409
2467.34	8.12524
2470.12	8.76305
2472.89	8.55755
2475.67	8.34072
2478.44	7.94262
2481.21	7.9395
2483.98	9.14002
2486.75	7.75179
2489.52	7.41102
2492.29	6.40982
2495.05	7.00235
2497.82	6.09594
2500.58	4.2073
2503.35	2.69932
2506.11	0.627982
2508.87	0.542242
2511.63	-0.415231
2514.39	-0.509823
2517.15	-1.27759
2519.91	-1.48546
2522.67	-0.730993
2525.42	-0.269012
2528.18	1.18407
2530.93	1.46207
2533.69	1.56647
2536.44	1.94205
2539.19	2.07403
2541.94	1.93478
2544.69	2.83237
2547.44	2.90341
2550.18	3.13164
2552.93	3.10588
2555.67	3.67645
2558.42	5.03967
2561.16	4.79884
2563.9	3.99587
2566.64	4.22615
2569.38	4.56494
2572.12	5.24004
2574.86	5.689
2577.6	5.46553
2580.33	6.29212
2583.07	7.17624
2585.8	7.14492
2588.54	7.39666
2591.27	6.18247
2594	4.95412
2596.73	4.85827
2599.46	4.09577
2602.19	4.00599
2604.92	2.96719
2607.64	3.16417
2610.37	3.20169
2613.09	2.24044
2615.82	2.86533
2618.54	2.63518
2621.26	2.61677
2623.98	3.82439
2626.7	3.58374
2629.42	2.74996
2632.14	3.0394
2634.86	3.88856
2637.57	3.72328
2640.29	3.91274
2643	3.58193
2645.71	3.81201
2648.43	4.04013
2651.14	4.0235
2653.85	3.78172
2656.56	4.13258
2659.26	4.30055
2661.97	5.26188
2664.68	5.50969
2667.38	6.09756
2670.09	7.30345
2672.79	8.74974
2675.49	9.0056
2678.19	9.72017
2680.89	10.8468
2683.59	11.7868
2686.29	13.5678
2688.99	14.1465
2691.69	15.7663
2694.38	16.9991
2697.08	18.843
2699.77	21.4533
2702.46	23.9919
2705.15	26.0983
2707.85	28.2575
2710.54	30.5658
2713.22	32.7621
2715.91	34.7247
2718.6	36.1682
2721.29	37.2709
2723.97	37.0418
2726.66	37.0476
2729.34	37.1427
2732.02	35.7063
2734.7	34.2308
2737.38	31.4193
2740.06	28.1775
2742.74	23.9727
2745.42	21.7137
2748.09	19.6411
2750.77	16.0875
2753.45	13.5204
2756.12	12.4838
2758.79	9.79976
2761.46	8.7773
2764.14	7.47903
2766.8	6.99168
2769.47	6.07508
2772.14	4.94201
2774.81	4.19283
2777.48	2.85422
2780.14	1.95011
2782.8	0.556429
2785.47	0.22879
2788.13	1.12154
2790.79	1.52684
2793.45	1.55545
2796.11	1.695
2798.77	2.39289
2801.43	3.09267
2804.09	3.69677
2806.74	4.21513
2809.4	3.92131
2812.05	3.58589
2814.71	4.65116
2817.36	7.76062
2820.01	16.9318
2822.66	32.1951
2825.31	52.6061
2827.96	78.234
2830.6	106.457
2833.25	137.612
2835.9	168.534
2838.54	202.379
2841.18	237.723
2843.83	275.987
2846.47	316.282
2849.11	356.872
2851.75	396.284
2854.39	435.934
2857.03	471.865
2859.66	504.423
2862.3	535.812
2864.94	562.162
2867.57	585.586
2870.2	602.313
2872.84	614.086
2875.47	625.969
2878.1	636.412
2880.73	647.479
2883.36	660.32
2885.99	675.105
2888.61	690.489
2891.24	706.738
2893.86	720.589
2896.49	734.323
2899.11	747.785
2901.73	764.224
2904.36	783.87
2906.98	808.88
2909.6	834.804
2912.21	860.934
2914.83	885.199
2917.45	908.805
2920.07	926.835
2922.68	939.426
2925.29	948.113
2927.91	950.779
2930.52	946.82
2933.13	936.185
2935.74	920.351
2938.35	900.391
2940.96	874.437
2943.57	843.559
2946.18	808.423
2948.78	772.307
2951.39	734.241
2953.99	696.367
2956.59	653.624
2959.2	613.423
2961.8	573.368
2964.4	535.566
2967	501.772
2969.6	471.635
2972.19	443.702
2974.79	416.05
2977.39	388.013
2979.98	358.333
2982.58	330.85
2985.17	303.209
2987.76	274.693
2990.35	247.295
2992.94	221.233
2995.53	196.031
2998.12	171.164
3000.71	150.501
3003.3	129.244
3005.88	109.838
3008.47	91.8053
3011.05	76.6691
3013.64	63.0913
3016.22	51.78
3018.8	41.0925
3021.38	32.9057
3023.96	27.0092
3026.54	22.1638
3029.12	18.8468
3031.69	18.2872
3034.27	17.0005
3036.84	17.8643
3039.42	19.4955
3041.99	20.8618
3044.57	23.2378
3047.14	27.2489
3049.71	28.9029
3052.28	30.495
3054.85	32.2995
3057.41	33.5651
3059.98	33.5299
3062.55	32.9264
3065.11	30.936
3067.68	28.0755
3070.24	23.5847
3072.8	21.4592
3075.36	18.8419
3077.93	16.0919
3080.49	13.3732
3083.04	10.3062
3085.6	8.52843
3088.16	6.34487
3090.72	4.16321
3093.27	2.69303
3095.83	2.30654
3098.38	1.55917
3100.93	2.76791
3103.49	3.58438
3106.04	5.91454
3108.59	7.27423
3111.14	8.50528
3113.69	10.4851
3116.23	12.6075
3118.78	14.7495
3121.33	16.9438
3123.87	18.9856
3126.41	20.2252
3128.96	23.295
3131.5	24.9098
3134.04	28.6735
3136.58	32.6233
3139.12	35.1008
3141.66	38.249
3144.2	41.3616
3146.74	44.3548
3149.27	46.7223