File: data/Raman/poly_smoothed/Mb_20_x_03_1x_45s_532 nm_x100_100%_600 gr_mm_01.txt
#Acq. time (s)=	45
#Accumulations=	2
#Range (cm-¹)=	200...3150
#Windows=	2
#Auto scanning=	Off
#Autofocus=	Off
#Macrospot=	Off
#AutoExposure=	Off
#Spike filter=	Multiple accum.
#Delay time (s)=	0
#Binning=	1
#Readout mode=	Signal
#DeNoise=	Off
#ICS correction=	On
#Dark correction=	Off
#Inst. Process=	Off
#Detector Gain=	Best Dynamic Range
#Detector ADC=	20 kHz
#Detector temperature (°C)=	-69.85
#Instrument=	LabRAM HR Evol
#Detector=	Synapse
#Objective=	x100
#Grating=	600 gr/mm
#ND Filter=	100%
#Laser (nm)=	532
#Hole=	100.021
#Range=	Auto
#Laser Pol.=	No
#Raman. Pol.=	No
#Laser Pol. (°)=	-0.0007625
#Raman Pol. (°)=	89.9995
#Collection=	Microscope
#StageXY=	Marzhauser
#StageZ=	Marzhauser
#X (µm)=	-804.2
#Y (µm)=	2685.6
#Z (µm)=	584.75
#Full time(mm:ss)=	3:18
#Project=
#Sample=
#Site=
#Title=	Mb_20_x_03_2x_45s_532 nm_x100_100%_600 gr_mm
#Remark=
#Date=	18.07.2022 14:38
#Acquired=	18.07.2022 14:38:39
#Edit:Spike=	18.07.2022 14:47:51
#Base:Fit=	16.08.2022 10:28:40
#Base:Fit=	16.08.2022 10:28:53
#Base:Fit=	16.08.2022 10:29:09
#Base:Fit=	16.08.2022 10:29:17
#Base:Fit=	16.08.2022 10:29:25
#Base:Fit=	16.08.2022 10:29:33
#Base:Sub=	16.08.2022 10:29:38
#Filter:Polynom=	16.08.2022 10:30:49
#AxisType[0]=Intens
#AxisUnit[0]=Cnt
#AxisType[1]=Spectr
#AxisUnit[1]=1/cm
200.419	-0.404637
204.048	4.76647
207.678	9.33063
211.304	12.3
214.928	15.2268
218.554	17.4017
222.176	19.562
225.798	20.2482
229.417	22.0428
233.035	22.7259
236.653	22.6685
240.268	24.178
243.881	24.7493
247.493	23.2174
251.103	23.2812
254.715	22.5478
258.322	22.3472
261.929	22.6487
265.534	21.8279
269.137	22.4129
272.739	21.5118
276.34	19.3053
279.939	19.7919
283.537	19.1031
287.134	18.5486
290.729	18.6366
294.323	19.4941
297.913	19.9222
301.504	20.3468
305.093	20.3668
308.682	20.5921
312.268	21.0152
315.852	22.0176
319.436	22.6222
323.018	24.6817
326.597	25.3417
330.177	25.0962
333.753	24.8899
337.331	24.6878
340.906	25.1838
344.478	23.9163
348.051	24.9698
351.621	24.43
355.189	22.2183
358.757	20.922
362.323	19.56
365.889	19.0418
369.451	18.8526
373.012	18.5543
376.574	18.3144
380.133	17.053
383.69	18.0366
387.245	17.3057
390.8	17.6895
394.353	17.1572
397.906	17.765
401.456	17.4577
405.005	16.9265
408.552	16.9869
412.099	18.0596
415.643	17.4567
419.187	17.7196
422.728	18.153
426.269	17.0076
429.806	17.1917
433.344	15.0596
436.881	14.2603
440.416	12.0447
443.949	12.1274
447.48	12.4237
451.011	12.2905
454.541	12.0862
458.069	11.1247
461.594	9.62064
465.119	9.98729
468.642	11.1373
472.165	11.4307
475.684	10.1161
479.204	10.6058
482.721	10.0119
486.239	10.5961
489.753	11.0154
493.268	12.0721
496.779	13.8879
500.289	15.5438
503.8	15.9147
507.307	16.2499
510.813	15.1622
514.32	14.9829
517.823	14.4022
521.325	13.3161
524.826	14.4147
528.325	15.3474
531.823	16.0362
535.32	15.4196
538.815	13.8885
542.309	12.6027
545.802	10.7069
549.293	10.235
552.783	9.62601
556.271	9.00517
559.759	7.22985
563.245	6.4531
566.729	5.93267
570.213	4.44167
573.693	4.85736
577.173	3.26797
580.652	4.82933
584.13	4.40366
587.605	3.65614
591.08	2.43038
594.552	2.87029
598.025	2.11406
601.496	0.850578
604.964	0.700311
608.433	1.91483
611.898	1.94066
615.364	3.06667
618.827	3.23963
622.288	1.99372
625.75	2.29203
629.209	1.65655
632.667	2.2074
636.125	2.75951
639.58	2.31525
643.033	2.68411
646.485	3.80496
649.936	4.62866
653.388	6.3741
656.836	8.53295
660.283	9.67031
663.728	10.9892
667.173	10.9944
670.616	11.9189
674.057	13.6695
677.498	15.4602
680.937	16.588
684.375	17.0336
687.809	18.7145
691.244	20.7837
694.678	21.1332
698.111	22.0219
701.54	23.7132
704.97	23.9154
708.398	26.1054
711.826	28.2788
715.25	28.1194
718.675	29.8399
722.096	30.4304
725.518	32.9431
728.937	34.6851
732.357	36.5633
735.773	37.1829
739.19	39.0529
742.604	41.2979
746.018	43.6001
749.429	45.3023
752.839	47.192
756.248	49.7858
759.657	52.1799
763.063	53.8489
766.468	57.0133
769.871	59.1194
773.273	61.1056
776.676	62.9238
780.075	65.7667
783.474	67.9456
786.871	70.6261
790.266	72.6508
793.661	73.8012
797.054	75.515
800.446	77.0522
803.834	78.0768
807.224	78.1609
810.612	78.8477
813.998	77.9408
817.384	77.5064
820.766	79.0998
824.149	80.3593
827.531	79.7683
830.909	77.6591
834.288	74.9397
837.666	71.8966
841.041	69.4561
844.416	68.8048
847.788	66.228
851.161	63.7747
854.53	60.4686
857.901	57.5259
861.268	54.5362
864.633	53.7892
868	51.2005
871.363	49.7994
874.725	48.1225
878.088	47.714
881.447	47.346
884.805	46.1113
888.162	46.9089
891.518	45.4905
894.872	44.4972
898.225	44.7321
901.577	45.3826
904.928	44.8308
908.277	43.8372
911.625	42.6994
914.972	41.167
918.318	40.5252
921.662	40.5185
925.005	40.5136
928.347	38.7168
931.686	36.412
935.025	33.5946
938.363	32.8605
941.698	30.4975
945.034	30.8077
948.368	29.8416
951.699	28.1633
955.031	29.6753
958.36	28.9647
961.689	28.667
965.016	27.6347
968.343	28.0989
971.666	28.0485
974.991	27.1126
978.312	26.6335
981.632	25.9534
984.953	25.2492
988.27	24.6028
991.587	23.7095
994.902	23.865
998.216	21.4079
1001.53	20.6313
1004.84	19.7599
1008.15	20.0586
1011.46	20.8854
1014.77	25.1
1018.07	27.3252
1021.38	32.2688
1024.68	34.7582
1027.99	37.6889
1031.29	41.4386
1034.59	43.9062
1037.89	45.4446
1041.18	44.953
1044.48	46.7971
1047.77	46.5553
1051.07	45.5799
1054.36	43.5558
1057.65	41.4463
1060.94	37.9444
1064.23	35.1888
1067.52	31.7252
1070.8	26.7792
1074.09	21.3209
1077.37	16.7145
1080.65	13.5639
1083.93	10.9076
1087.21	9.74718
1090.49	11.4534
1093.77	11.6971
1097.04	12.8359
1100.32	13.2714
1103.59	11.8071
1106.86	12.2267
1110.13	11.485
1113.4	12.7384
1116.67	10.8093
1119.94	11.447
1123.2	11.8143
1126.47	11.8195
1129.73	9.47837
1132.99	9.02901
1136.25	10.4959
1139.51	11.3834
1142.77	11.3224
1146.03	11.035
1149.28	10.7473
1152.54	9.66463
1155.79	9.45793
1159.04	8.6572
1162.29	7.31122
1165.54	6.06565
1168.79	6.56707
1172.04	5.49288
1175.28	6.42645
1178.53	6.20343
1181.77	5.03092
1185.01	4.8908
1188.25	6.55889
1191.49	6.54874
1194.73	5.22585
1197.96	4.6364
1201.2	6.3944
1204.43	6.25383
1207.66	6.56985
1210.9	8.64156
1214.13	11.1563
1217.36	14.3469
1220.58	16.5949
1223.81	17.1816
1227.04	18.8017
1230.26	21.1136
1233.48	22.6806
1236.71	23.0615
1239.93	25.2641
1243.14	26.1868
1246.36	27.7561
1249.58	28.0531
1252.8	29.1252
1256.01	29.5113
1259.22	29.4566
1262.43	29.9758
1265.64	30.8036
1268.85	30.4536
1272.06	29.1696
1275.27	30.065
1278.48	30.3056
1281.68	30.685
1284.88	30.3519
1288.08	31.25
1291.28	32.2784
1294.48	33.587
1297.68	32.8337
1300.88	33.602
1304.07	34.9639
1307.27	35.6356
1310.46	35.7492
1313.65	35.8563
1316.85	37.4808
1320.03	37.6355
1323.22	36.941
1326.41	36.5841
1329.6	37.0861
1332.78	36.8107
1335.96	36.8264
1339.15	36.3158
1342.33	37.0363
1345.51	36.7537
1348.69	35.562
1351.86	34.4477
1355.04	33.3874
1358.21	31.786
1361.39	31.0957
1364.56	30.0224
1367.73	28.3298
1370.9	27.8257
1374.07	25.7067
1377.24	24.6873
1380.41	23.6863
1383.57	22.8484
1386.73	21.8213
1389.9	21.5039
1393.06	21.6527
1396.22	21.7764
1399.38	22.823
1402.54	21.9177
1405.69	23.1117
1408.85	23.7083
1412	24.4006
1415.16	25.2155
1418.31	26.3695
1421.46	28.2007
1424.61	31.0559
1427.76	33.6917
1430.9	36.4838
1434.05	39.7175
1437.2	42.0285
1440.34	44.0395
1443.48	45.014
1446.62	46.8605
1449.76	48.9082
1452.9	50.0723
1456.04	50.7013
1459.17	51.11
1462.31	52.3707
1465.44	51.7809
1468.58	49.655
1471.71	47.671
1474.84	46.0296
1477.97	43.1759
1481.1	39.3221
1484.22	36.8849
1487.35	33.2305
1490.47	30.3924
1493.59	27.5124
1496.72	26.1482
1499.84	23.019
1502.96	21.2962
1506.08	19.671
1509.19	18.0621
1512.31	16.17
1515.42	14.4312
1518.54	13.5107
1521.65	13.9024
1524.76	13.664
1527.87	14.0481
1530.98	14.0049
1534.09	14.4906
1537.2	14.9756
1540.3	14.9557
1543.41	14.7317
1546.51	15.0802
1549.61	16.084
1552.71	16.4415
1555.81	16.2263
1558.91	16.392
1562.01	16.6748
1565.1	16.2216
1568.2	17.1339
1571.29	17.4807
1574.38	17.5874
1577.48	19.1764
1580.57	22.0572
1583.65	21.8952
1586.74	22.8561
1589.83	24.8296
1592.92	25.9278
1596	27.6231
1599.08	29.7876
1602.16	29.3832
1605.24	29.6553
1608.32	29.1222
1611.4	29.4296
1614.48	30.0542
1617.56	30.3283
1620.63	31.3575
1623.71	32.5273
1626.78	32.3264
1629.85	32.7971
1632.92	33.3271
1635.99	33.9002
1639.06	34.5738
1642.12	35.4763
1645.19	37.0728
1648.25	37.5314
1651.32	38.4896
1654.38	40.0316
1657.44	38.9763
1660.5	39.2337
1663.56	39.7687
1666.62	39.0075
1669.67	37.7474
1672.73	36.9472
1675.79	34.9298
1678.84	32.1591
1681.89	30.5819
1684.94	30.2543
1687.99	27.7682
1691.04	25.758
1694.08	22.4296
1697.13	20.5146
1700.18	18.0284
1703.22	16.4749
1706.26	15.0461
1709.3	13.2042
1712.35	10.9411
1715.39	10.0568
1718.42	8.72806
1721.46	7.32122
1724.5	5.10174
1727.53	4.2572
1730.56	2.9132
1733.6	2.66449
1736.63	2.225
1739.66	1.6712
1742.69	0.948199
1745.71	0.782061
1748.74	0.731076
1751.77	0.790024
1754.79	0.827289
1757.81	0.919188
1760.84	0.897775
1763.86	0.20867
1766.88	0.0648085
1769.9	-0.658148
1772.91	0.263372
1775.93	0.0113827
1778.95	-0.206089
1781.96	0.299684
1784.97	0.428635
1787.99	0.847731
1791	1.26803
1794.01	1.3559
1797.01	1.50228
1800.02	1.76043
1803.03	1.10684
1806.03	2.43983
1809.04	2.49963
1812.04	2.87073
1815.04	2.50087
1818.04	3.77452
1821.04	3.84366
1824.04	3.66819
1827.04	3.65369
1830.03	5.08982
1833.03	4.82688
1836.02	5.5151
1839.02	5.35153
1842.01	5.93782
1845	6.15611
1847.99	5.84508
1850.98	6.06628
1853.96	5.3516
1856.95	5.30398
1859.94	5.20105
1862.92	5.67136
1865.9	5.62771
1868.88	6.15388
1871.86	6.47328
1874.84	6.39102
1877.82	6.16304
1880.8	6.24547
1882.58	5.82579
1885.57	5.66758
1888.56	5.88623
1891.54	6.34544
1894.53	5.70415
1897.51	5.78906
1900.5	7.22137
1903.48	6.27302
1906.46	6.47072
1909.44	7.03646
1912.42	6.73501
1915.4	6.94753
1918.37	5.9176
1921.35	5.37381
1924.32	4.4949
1927.3	3.61795
1930.27	3.78035
1933.24	3.33406
1936.21	2.81167
1939.18	2.63844
1942.15	2.2534
1945.11	1.63104
1948.08	0.735607
1951.04	-0.0272711
1954.01	0.980309
1956.97	1.71443
1959.93	2.89787
1962.89	4.2719
1965.85	4.92953
1968.81	5.442
1971.77	6.94944
1974.72	7.8325
1977.68	7.67128
1980.63	7.77268
1983.58	8.31648
1986.53	7.46808
1989.48	7.01431
1992.43	7.13146
1995.38	7.04909
1998.33	6.50778
2001.27	6.58419
2004.22	5.2329
2007.16	5.28351
2010.11	3.99041
2013.05	4.19691
2015.99	4.10076
2018.93	4.25496
2021.87	4.62259
2024.8	5.23263
2027.74	6.33718
2030.68	6.99282
2033.61	6.98542
2036.54	7.96712
2039.48	9.30631
2042.41	10.0596
2045.34	10.7782
2048.27	10.7918
2051.19	10.776
2054.12	11.7464
2057.05	13.3176
2059.97	14.9092
2062.9	15.4239
2065.82	16.0891
2068.74	16.4977
2071.66	16.8283
2074.58	16.1658
2077.5	15.8043
2080.41	15.3384
2083.33	15.3855
2086.24	15.6088
2089.16	14.885
2092.07	14.0704
2094.98	13.3759
2097.89	13.0111
2100.8	14.5925
2103.71	14.8448
2106.62	15.4743
2109.53	16.0261
2112.43	16.1248
2115.33	16.1278
2118.24	16.55
2121.14	18.3577
2124.04	20.4185
2126.94	23.2411
2129.84	24.1248
2132.74	25.8833
2135.63	27.0585
2138.53	28.2472
2141.43	29.4656
2144.32	31.046
2147.21	32.1545
2150.1	33.8927
2152.99	35.3301
2155.88	36.281
2158.77	36.6496
2161.66	37.4972
2164.55	38.8541
2167.43	38.9007
2170.31	39.5521
2173.2	39.3837
2176.08	38.0909
2178.96	38.3913
2181.84	37.4318
2184.72	36.5798
2187.6	35.644
2190.47	35.1517
2193.35	34.9135
2196.23	34.749
2199.1	33.8668
2201.97	32.2805
2204.84	31.425
2207.71	29.8176
2210.58	28.0934
2213.45	26.342
2216.32	24.9795
2219.19	23.0957
2222.05	22.3674
2224.92	21.0311
2227.78	19.5679
2230.64	19.0329
2233.5	17.5532
2236.36	15.8702
2239.22	14.6472
2242.08	13.9262
2244.94	13.2175
2247.79	14.1189
2250.65	14.4395
2253.5	13.9108
2256.36	15.0068
2259.21	15.6168
2262.06	15.9442
2264.91	16.9458
2267.76	17.2344
2270.6	17.4586
2273.45	17.2722
2276.3	17.2022
2279.14	15.8888
2281.98	16.0614
2284.83	15.8739
2287.67	15.061
2290.51	13.4723
2293.35	11.4964
2296.19	9.86102
2299.02	9.63041
2301.86	9.92118
2304.7	9.14423
2307.53	9.07097
2310.36	8.11516
2313.2	7.97984
2316.03	8.40039
2318.86	9.01228
2321.69	9.90937
2324.51	9.86748
2327.34	9.56547
2330.17	9.67286
2332.99	10.365
2335.82	9.95357
2338.64	9.21084
2341.46	8.49259
2344.28	7.64656
2347.1	7.61127
2349.92	7.47023
2352.74	6.54926
2355.56	5.48917
2358.37	4.43198
2361.19	3.2803
2364	3.2514
2366.82	4.23343
2369.63	4.15649
2372.44	4.35338
2375.25	3.2188
2378.06	2.75223
2380.86	2.50628
2383.67	3.79238
2386.48	4.40638
2389.28	5.43303
2392.09	5.52741
2394.89	5.08414
2397.69	4.97978
2400.49	5.46026
2403.29	5.35314
2406.09	4.46995
2408.89	4.75006
2411.69	4.78591
2414.48	4.64346
2417.28	3.77386
2420.07	3.36849
2422.86	2.94902
2425.65	2.72322
2428.45	3.05539
2431.23	2.09671
2434.02	1.90589
2436.81	1.59509
2439.6	2.28829
2442.38	2.45151
2445.17	2.66312
2447.95	2.67798
2450.73	3.71452
2453.52	4.48085
2456.3	4.72518
2459.08	4.77391
2461.85	4.85455
2464.63	4.72163
2467.41	5.90227
2470.19	6.33424
2472.96	5.51848
2475.73	3.95539
2478.51	4.39615
2481.28	3.40493
2484.05	2.46467
2486.82	2.15077
2489.59	3.5365
2492.35	3.80992
2495.12	4.19333
2497.89	4.23157
2500.65	4.57998
2503.42	5.02434
2506.18	5.26114
2508.94	6.39839
2511.7	5.62382
2514.46	5.57094
2517.22	5.1259
2519.98	5.31484
2522.73	5.24547
2525.49	4.66683
2528.25	4.04238
2531	2.70951
2533.75	2.35173
2536.5	2.06902
2539.25	0.747883
2542.01	0.30418
2544.75	1.39639
2547.5	1.39063
2550.25	2.35568
2553	3.08442
2555.74	3.70578
2558.49	4.89026
2561.23	5.09035
2563.97	5.59977
2566.71	6.06337
2569.45	6.22903
2572.19	5.95864
2574.93	5.98074
2577.67	5.59958
2580.4	5.57334
2583.14	5.44603
2585.87	5.18235
2588.6	5.17728
2591.34	3.98055
2594.07	3.30653
2596.8	2.85523
2599.53	3.23032
2602.26	3.44958
2604.98	3.65941
2607.71	4.09285
2610.44	4.82796
2613.16	5.00476
2615.88	5.06715
2618.61	5.72193
2621.33	5.1668
2624.05	5.10118
2626.77	4.73258
2629.49	4.13842
2632.21	4.1437
2634.92	3.93397
2637.64	3.16262
2640.35	2.52918
2643.07	2.72727
2645.78	2.15324
2648.49	1.84954
2651.2	1.77304
2653.91	2.04359
2656.62	1.43316
2659.33	1.12107
2662.04	1.28036
2664.74	0.615583
2667.45	0.846413
2670.15	0.115867
2672.86	-0.15892
2675.56	-0.524624
2678.26	-0.926266
2680.96	-0.858091
2683.66	-0.231923
2686.36	0.0971122
2689.06	0.238687
2691.75	0.388734
2694.45	0.603282
2697.14	0.660961
2699.84	0.963251
2702.53	1.91072
2705.22	3.2085
2707.91	3.72875
2710.6	4.72142
2713.29	5.11642
2715.98	5.48474
2718.67	5.6914
2721.35	5.7175
2724.04	5.41217
2726.72	4.42423
2729.4	4.32595
2732.09	3.48422
2734.77	3.12149
2737.45	2.46494
2740.13	2.31877
2742.81	2.53515
2745.48	2.78045
2748.16	3.30254
2750.84	2.34636
2753.51	1.88665
2756.19	2.08727
2758.86	1.75457
2761.53	1.84515
2764.2	2.38012
2766.87	3.51744
2769.54	4.35471
2772.21	4.69446
2774.88	5.33445
2777.54	5.60638
2780.21	4.9526
2782.87	5.01371
2785.53	4.60235
2788.2	4.38397
2790.86	4.69123
2793.52	4.09662
2796.18	4.47487
2798.84	3.69791
2801.49	4.30625
2804.15	2.78303
2806.81	2.74092
2809.46	1.80023
2812.12	0.9465
2814.77	0.925029
2817.42	1.48682
2820.07	3.26083
2822.72	4.2842
2825.37	5.25316
2828.02	6.79283
2830.67	9.72799
2833.31	12.8108
2835.96	15.6313
2838.61	18.1899
2841.25	21.2045
2843.89	24.5804
2846.53	28.7983
2849.17	33.1743
2851.81	38.2514
2854.45	43.5129
2857.09	49.0251
2859.73	53.746
2862.36	58.6233
2865	63.4853
2867.64	67.037
2870.27	71.3122
2872.9	74.8325
2875.53	77.4704
2878.16	80.3966
2880.79	83.3982
2883.42	86.025
2886.05	87.8523
2888.68	89.5811
2891.3	92.6834
2893.93	95.4985
2896.55	98.8616
2899.18	102.248
2901.8	105.184
2904.42	109.042
2907.04	113.507
2909.66	119.216
2912.28	125.193
2914.9	130.658
2917.51	135.737
2920.13	140.472
2922.74	145.165
2925.36	148.494
2927.97	151.476
2930.59	152.237
2933.2	153.142
2935.81	151.952
2938.42	149.026
2941.02	146.264
2943.63	142.337
2946.24	137.312
2948.85	132.856
2951.45	128.166
2954.05	123.365
2956.66	118.088
2959.26	112.732
2961.86	106.797
2964.46	101.169
2967.06	96.5662
2969.66	92.308
2972.26	87.942
2974.85	82.6421
2977.45	77.9499
2980.05	73.1949
2982.64	68.4938
2985.23	63.6923
2987.83	59.1877
2990.42	54.3524
2993.01	49.5784
2995.6	44.4702
2998.19	40.5743
3000.77	36.028
3003.36	32.5542
3005.95	30.0289
3008.53	26.3665
3011.12	24.0762
3013.7	22.2361
3016.28	19.6344
3018.86	17.5072
3021.44	16.1295
3024.02	14.8774
3026.6	13.7042
3029.18	13.0038
3031.76	11.9814
3034.33	11.1872
3036.91	10.5455
3039.48	9.80353
3042.05	9.7476
3044.63	10.2343
3047.2	9.71332
3049.77	9.91771
3052.34	9.56312
3054.91	9.35212
3057.48	8.66201
3060.04	8.50086
3062.61	8.17061
3065.17	7.6696
3067.74	7.68938
3070.3	6.82992
3072.87	6.39635
3075.43	6.23001
3077.99	5.49573
3080.55	4.75407
3083.11	4.91412
3085.67	4.05198
3088.22	3.45435
3090.78	2.78536
3093.34	1.92376
3095.89	1.39006
3098.44	2.15274
3101	1.98651
3103.55	1.33438
3106.1	2.19293
3108.65	2.90158
3111.2	2.27065
3113.75	1.8724
3116.3	1.08726
3118.84	1.20929
3121.39	0.866581
3123.93	0.653629
3126.48	0.609794
3129.02	0.903789
3131.56	1.14398
3134.1	0.98465
3136.64	0.920887
3139.18	0.929972
3141.72	0.790087
3144.26	0.312519
3146.8	0.115066
3149.33	0.349788