File: data/Raman/poly_smoothed/Mb_20_23_47_1x_45s_532 nm_x100_100%_600 gr_mm_01.txt
#Acq. time (s)=	45
#Accumulations=	2
#Range (cm-¹)=	200...3150
#Windows=	2
#Auto scanning=	Off
#Autofocus=	Off
#Macrospot=	Off
#AutoExposure=	Off
#Spike filter=	Multiple accum.
#Delay time (s)=	0
#Binning=	1
#Readout mode=	Signal
#DeNoise=	Off
#ICS correction=	On
#Dark correction=	Off
#Inst. Process=	Off
#Detector Gain=	Best Dynamic Range
#Detector ADC=	20 kHz
#Detector temperature (°C)=	-70.08
#Instrument=	LabRAM HR Evol
#Detector=	Synapse
#Objective=	x100
#Grating=	600 gr/mm
#ND Filter=	100%
#Laser (nm)=	532
#Hole=	100.021
#Range=	Auto
#Laser Pol.=	No
#Raman. Pol.=	No
#Laser Pol. (°)=	-0.0007625
#Raman Pol. (°)=	89.9995
#Collection=	Microscope
#StageXY=	Marzhauser
#StageZ=	Marzhauser
#X (µm)=	504.6
#Y (µm)=	2978.9
#Z (µm)=	-8.9
#Full time(mm:ss)=	3:19
#Project=
#Sample=
#Site=
#Title=	Mb_20_23_47_2x_45s_532 nm_x100_100%_600 gr_mm
#Remark=
#Date=	14.07.2022 09:56
#Acquired=	14.07.2022 09:56:10
#Base:Fit=	10.08.2022 10:29:37
#Base:Sub=	10.08.2022 10:35:48
#Filter:Polynom=	16.08.2022 10:13:29
#AxisType[0]=Intens
#AxisUnit[0]=Cnt
#AxisType[1]=Spectr
#AxisUnit[1]=1/cm
200.554	1.2282
204.183	2.51729
207.813	5.7322
211.439	7.52345
215.065	8.79251
218.688	9.49952
222.312	9.28546
225.933	9.07321
229.552	9.38998
233.171	8.78656
236.787	10.3173
240.402	10.3283
244.015	10.1736
247.627	8.82234
251.24	7.39666
254.849	7.26071
258.457	6.97363
262.063	4.70166
265.668	6.04459
269.271	6.59682
272.873	7.02629
276.474	6.65738
280.073	7.4434
283.671	7.50121
287.268	9.43211
290.863	11.1358
294.456	12.1348
298.049	13.2553
301.637	15.0584
305.227	16.5635
308.815	17.1034
312.402	17.9839
315.987	17.6148
319.569	19.2216
323.151	19.2147
326.733	19.3446
330.31	19.0304
333.889	18.723
337.464	17.3391
341.039	16.8609
344.611	17.4622
348.184	17.4896
351.754	18.3855
355.324	17.8828
358.89	16.7725
362.455	15.4143
366.021	13.8034
369.584	13.3945
373.145	14.3762
376.707	14.0544
380.265	14.0971
383.822	14.3195
387.378	14.1485
390.934	13.7162
394.487	13.3858
398.038	11.8922
401.588	11.1685
405.137	11.9137
408.685	13.3071
412.23	11.8298
415.775	12.8143
419.318	13.6698
422.86	11.5641
426.401	10.9129
429.94	12.9037
433.478	12.7986
437.012	13.3996
440.547	13.5011
444.081	14.0065
447.613	15.3435
451.142	16.2093
454.672	17.4314
458.2	18.4919
461.725	19.146
465.251	19.8758
468.775	19.54
472.296	21.9558
475.817	22.6121
479.335	22.8162
482.854	22.8833
486.37	23.8763
489.886	23.7868
493.398	23.7419
496.91	22.7055
500.422	21.2968
503.93	21.0309
507.438	20.8593
510.946	20.2357
514.45	22.5445
517.954	24.3556
521.456	24.7366
524.956	27.0154
528.456	28.1624
531.956	28.5035
535.452	28.8134
538.947	27.7614
542.441	27.2064
545.934	27.2952
549.425	26.3052
552.915	26.8794
556.403	26.6933
559.889	24.6711
563.375	23.5572
566.859	20.9045
570.342	18.256
573.824	15.455
577.303	13.142
580.782	11.1904
584.26	10.5117
587.734	9.6362
591.21	9.11745
594.684	8.04767
598.154	9.70101
601.626	9.42353
605.094	11.1543
608.562	10.5761
612.027	12.2251
615.493	12.3943
618.956	14.5733
622.419	16.6221
625.879	18.8336
629.338	21.7804
632.797	23.8872
636.254	26.6141
639.708	29.1097
643.162	29.7104
646.614	31.8724
650.067	32.6055
653.516	33.8086
656.964	35.547
660.411	35.5184
663.857	37.6647
667.301	38.1365
670.744	39.5781
674.186	39.9479
677.626	40.8062
681.065	39.3044
684.503	39.0007
687.939	40.6928
691.372	41.4906
694.806	42.8442
698.239	44.6799
701.67	46.3029
705.098	47.1175
708.526	46.6869
711.954	47.1494
715.378	47.0626
718.802	46.833
722.226	48.4086
725.646	47.9587
729.067	48.9241
732.484	51.0953
735.902	52.2294
739.317	54.8234
742.731	56.6568
746.145	57.0535
749.556	59.4394
752.966	61.1643
756.377	62.3495
759.784	64.8985
763.19	67.5747
766.594	69.71
770	72.587
773.402	76.4052
776.803	79.044
780.202	82.5883
783.6	83.5809
786.997	84.0779
790.393	84.138
793.787	85.7199
797.18	85.6089
800.572	84.5173
803.963	84.0083
807.35	83.6531
810.738	82.5574
814.125	83.4415
817.51	84.5264
820.894	84.6891
824.275	84.1553
827.657	84.011
831.037	83.1074
834.414	83.8508
837.792	82.094
841.167	80.9204
844.542	80.8684
847.914	76.7158
851.287	74.5841
854.656	74.8614
858.026	74.5165
861.393	72.3775
864.761	69.3622
868.125	66.379
871.489	64.4289
874.85	63.9331
878.213	62.7559
881.572	60.2883
884.931	58.9612
888.287	58.1665
891.643	57.0793
894.997	58.0389
898.352	59.369
901.704	59.6755
905.055	59.4243
908.404	59.9132
911.75	60.0107
915.097	59.4972
918.443	58.3632
921.787	57.0646
925.13	57.3531
928.472	56.4656
931.813	55.8727
935.15	56.8077
938.488	54.7929
941.825	53.5193
945.158	52.9574
948.493	50.4402
951.824	50.8622
955.156	51.1279
958.486	49.2285
961.814	46.7133
965.142	44.5461
968.467	43.3175
971.79	42.4763
975.115	41.2571
978.436	41.5237
981.756	39.648
985.077	36.8056
988.394	35.3066
991.71	33.1918
995.025	31.8755
998.341	31.5011
1001.65	30.6459
1004.97	30.4857
1008.28	30.651
1011.58	31.6336
1014.89	32.9168
1018.2	33.3064
1021.5	34.9163
1024.81	35.7894
1028.11	37.8941
1031.41	38.0344
1034.71	39.9946
1038.01	41.5738
1041.31	42.5792
1044.6	42.8117
1047.9	44.4764
1051.19	44.9205
1054.48	45.3683
1057.77	44.8406
1061.06	42.9995
1064.35	41.0025
1067.64	38.3168
1070.93	36.0717
1074.21	34.9185
1077.49	33.1712
1080.78	30.7062
1084.06	28.6276
1087.34	27.8256
1090.61	28.0122
1093.89	27.3368
1097.17	26.1386
1100.44	26.6839
1103.71	24.3104
1106.99	22.5597
1110.26	21.6773
1113.52	21.8313
1116.79	22.443
1120.06	22.7122
1123.32	23.0429
1126.59	23.1431
1129.85	23.822
1133.11	22.7701
1136.37	22.4282
1139.63	20.3624
1142.89	19.9706
1146.15	19.3735
1149.4	18.3651
1152.66	19.0613
1155.91	18.1259
1159.16	16.5081
1162.41	15.4083
1165.66	15.6525
1168.91	14.3368
1172.16	14.176
1175.4	11.377
1178.65	8.85556
1181.89	7.49493
1185.13	6.21626
1188.37	7.30752
1191.61	7.36699
1194.85	9.19767
1198.08	10.1032
1201.32	11.6008
1204.55	12.1302
1207.79	11.7023
1211.02	12.1727
1214.25	11.3939
1217.48	13.1107
1220.71	15.1147
1223.93	16.7247
1227.16	17.5836
1230.38	17.5918
1233.6	17.6381
1236.83	18.0959
1240.05	18.6749
1243.26	20.1381
1246.48	19.6646
1249.7	19.5577
1252.92	19.405
1256.13	18.7374
1259.34	19.8197
1262.55	22.6381
1265.76	23.1057
1268.97	23.4957
1272.18	23.9244
1275.39	26.1446
1278.59	28.0779
1281.8	29.3739
1285	31.0299
1288.2	32.9933
1291.4	34.8411
1294.6	36.3084
1297.8	37.9799
1301	37.9355
1304.19	38.7263
1307.39	39.0183
1310.58	40.1148
1313.77	40.5525
1316.96	40.6926
1320.15	40.3454
1323.34	39.516
1326.53	37.1635
1329.72	36.2962
1332.9	35.416
1336.08	33.7994
1339.27	33.2497
1342.45	30.6435
1345.63	29.8148
1348.8	29.7127
1351.98	29.129
1355.16	29.4861
1358.33	29.4457
1361.51	28.8056
1364.68	28.7822
1367.85	29.0723
1371.02	28.0693
1374.19	26.5491
1377.36	26.8632
1380.52	26.6414
1383.69	28.3494
1386.85	28.4196
1390.02	28.5335
1393.18	29.3232
1396.34	30.0649
1399.5	29.6024
1402.65	30.0013
1405.81	31.0842
1408.97	33.3257
1412.12	34.4037
1415.27	36.2886
1418.43	37.2569
1421.58	39.2509
1424.73	43.0125
1427.87	45.283
1431.02	46.4572
1434.17	47.1925
1437.31	47.656
1440.46	49.5004
1443.6	48.8304
1446.74	49.0802
1449.88	47.2028
1453.02	46.3153
1456.16	45.7314
1459.29	43.2484
1462.43	40.0851
1465.56	38.1989
1468.69	34.0483
1471.83	31.2383
1474.95	28.8239
1478.08	23.2313
1481.21	21.2767
1484.34	18.6211
1487.47	16.9943
1490.59	14.589
1493.71	13.6307
1496.84	12.6597
1499.96	12.1589
1503.07	12.0193
1506.19	9.23795
1509.31	8.79098
1512.43	8.45811
1515.54	8.69075
1518.65	8.84393
1521.77	9.06682
1524.88	11.3489
1527.99	11.6981
1531.1	12.1734
1534.21	11.6703
1537.31	11.5188
1540.42	11.9178
1543.52	12.4425
1546.63	12.9369
1549.73	14.7128
1552.83	13.7802
1555.93	14.3253
1559.03	15.4583
1562.12	15.5247
1565.22	16.431
1568.31	17.09
1571.41	16.8911
1574.5	18.2533
1577.59	18.2829
1580.68	18.5598
1583.77	20.1635
1586.86	20.6487
1589.95	21.4659
1593.03	20.8035
1596.11	22.1379
1599.2	23.0165
1602.28	22.0285
1605.36	21.1958
1608.44	20.368
1611.52	20.1141
1614.6	20.1939
1617.67	20.596
1620.75	21.3189
1623.82	21.3612
1626.89	21.8881
1629.96	22.5343
1633.04	24.7725
1636.11	24.6713
1639.17	25.3882
1642.24	26.2684
1645.31	26.3813
1648.37	27.1505
1651.43	26.4208
1654.5	25.5452
1657.56	24.6765
1660.62	24.4484
1663.67	23.6832
1666.73	20.4828
1669.79	18.8912
1672.84	18.7676
1675.9	17.0432
1678.95	14.8755
1682	13.4603
1685.05	12.2246
1688.1	12.6716
1691.15	11.0406
1694.2	9.8215
1697.25	9.99781
1700.29	9.88407
1703.33	9.85859
1706.38	9.7173
1709.42	8.35513
1712.46	7.72928
1715.5	7.81855
1718.54	8.14756
1721.57	6.99997
1724.61	6.58272
1727.64	6.25899
1730.68	6.54455
1733.71	7.51304
1736.74	6.69228
1739.77	5.32119
1742.8	5.2199
1745.83	5.95453
1748.85	5.32528
1751.88	4.0869
1754.91	2.62416
1757.93	4.03818
1760.95	3.52367
1763.97	3.01568
1766.99	2.77075
1770.01	3.20319
1773.03	3.05177
1776.04	3.8083
1779.06	4.0469
1782.07	3.94139
1785.09	4.19198
1788.1	4.61966
1791.11	5.27989
1794.12	4.37728
1797.13	5.01557
1800.13	5.08684
1803.14	5.11073
1806.15	5.49766
1809.15	4.71829
1812.15	3.68883
1815.16	2.64384
1818.15	2.09674
1821.16	1.13511
1824.15	-0.167936
1827.15	-0.794192
1830.15	-1.04589
1833.14	-0.559325
1836.14	0.378823
1839.13	0.321749
1842.12	0.646619
1845.11	1.57014
1848.1	1.85017
1851.09	2.55358
1854.08	1.73615
1857.06	1.9936
1860.05	2.90583
1863.03	2.70362
1866.01	2.97558
1869	2.64837
1871.98	3.01786
1874.96	3.44296
1877.93	4.27438
1880.91	3.98722
1882.47	3.60659
1885.46	3.75688
1888.44	3.62681
1891.43	3.45906
1894.42	3.05779
1897.4	4.08547
1900.39	4.71442
1903.37	6.02284
1906.35	6.14034
1909.33	6.29262
1912.31	6.51972
1915.29	6.20208
1918.26	6.88919
1921.24	7.03053
1924.21	7.24924
1927.19	7.10748
1930.16	7.11428
1933.13	6.15205
1936.1	4.90963
1939.07	3.95387
1942.04	3.3773
1945	3.31535
1947.97	2.52493
1950.93	2.55456
1953.9	1.44717
1956.86	1.39494
1959.82	0.629147
1962.78	0.62908
1965.74	0.974207
1968.7	1.81089
1971.65	2.30955
1974.61	2.59651
1977.57	3.26243
1980.52	3.42435
1983.47	3.35011
1986.42	2.6594
1989.37	3.65201
1992.32	4.20281
1995.27	4.93188
1998.22	4.60446
2001.17	4.54883
2004.11	3.96771
2007.05	2.99942
2010	2.94698
2012.94	3.54246
2015.88	3.76361
2018.82	2.14621
2021.76	4.0284
2024.7	4.62996
2027.63	4.12372
2030.57	4.6447
2033.5	5.17174
2036.44	5.58943
2039.37	5.31545
2042.3	5.27562
2045.23	5.43109
2048.16	5.92407
2051.08	6.3611
2054.01	5.67947
2056.94	4.73864
2059.86	5.54475
2062.79	5.95649
2065.71	6.73504
2068.63	7.60879
2071.55	7.2149
2074.47	6.80092
2077.39	5.75294
2080.31	6.47714
2083.22	8.07181
2086.13	8.49434
2089.05	7.58681
2091.96	7.84361
2094.87	8.40008
2097.78	8.81845
2100.69	9.67759
2103.6	10.3835
2106.51	10.4678
2109.42	10.3739
2112.32	11.2736
2115.23	11.9102
2118.13	11.9394
2121.03	12.0345
2123.93	12.305
2126.83	11.4829
2129.73	12.5963
2132.63	12.5202
2135.53	13.9892
2138.42	14.0352
2141.32	14.0776
2144.21	14.3451
2147.1	14.3927
2150	14.2411
2152.89	15.1608
2155.78	15.3528
2158.66	14.6078
2161.55	14.8198
2164.44	15.5174
2167.32	17.8184
2170.21	17.9496
2173.09	18.5213
2175.97	18.239
2178.85	18.9023
2181.73	18.2013
2184.61	18.0901
2187.49	17.9684
2190.37	16.7961
2193.24	16.7129
2196.12	15.8234
2198.99	16.3372
2201.87	15.8314
2204.74	16.0884
2207.61	14.7112
2210.48	13.9624
2213.35	13.4273
2216.21	12.1964
2219.08	11.5498
2221.95	10.0945
2224.81	9.91272
2227.67	9.09114
2230.54	8.87108
2233.4	8.62551
2236.26	9.49939
2239.11	9.0505
2241.97	7.29258
2244.83	8.17662
2247.69	7.14336
2250.54	6.26214
2253.4	5.56693
2256.25	5.57027
2259.1	5.52899
2261.95	5.43407
2264.8	6.4668
2267.65	7.2235
2270.5	5.95099
2273.34	6.08264
2276.19	6.58179
2279.03	6.461
2281.88	6.05291
2284.72	6.36545
2287.56	5.82162
2290.4	4.85753
2293.24	3.96621
2296.08	3.43553
2298.92	4.51734
2301.76	4.85186
2304.59	5.68295
2307.43	6.62991
2310.26	6.08046
2313.09	5.92071
2315.92	6.38916
2318.75	6.60182
2321.58	6.86584
2324.41	6.8342
2327.24	7.08245
2330.06	7.70546
2332.89	7.6231
2335.71	7.10199
2338.54	6.89978
2341.36	6.87013
2344.18	8.08406
2347	6.67953
2349.82	5.81071
2352.64	4.45205
2355.45	3.6506
2358.27	3.05734
2361.08	2.06903
2363.9	2.29898
2366.71	2.66224
2369.52	3.06389
2372.33	2.24001
2375.14	1.95722
2377.95	0.814459
2380.76	1.02285
2383.57	1.39536
2386.37	0.802224
2389.18	-0.17366
2391.98	0.323075
2394.79	0.0129567
2397.59	-0.0597961
2400.39	-0.12925
2403.19	0.566829
2405.99	0.458854
2408.78	0.910637
2411.58	2.43697
2414.38	3.95274
2417.17	4.4474
2419.97	4.371
2422.76	5.12974
2425.55	6.59253
2428.34	7.26508
2431.13	7.46956
2433.92	8.10193
2436.71	8.01097
2439.49	8.01117
2442.28	6.79284
2445.06	5.89887
2447.85	5.8927
2450.63	5.67959
2453.41	5.58988
2456.19	4.05814
2458.97	3.26652
2461.75	2.86943
2464.53	1.60169
2467.31	1.09417
2470.08	0.847617
2472.86	0.480914
2475.63	-0.315206
2478.4	-0.136949
2481.17	0.0385331
2483.94	-0.998647
2486.72	-0.835007
2489.48	-1.20226
2492.25	-0.255387
2495.02	-0.453758
2497.79	0.707992
2500.55	0.574318
2503.31	0.783302
2506.08	1.17483
2508.84	0.594928
2511.6	1.55426
2514.36	2.41131
2517.12	2.94146
2519.88	3.21751
2522.63	3.33148
2525.39	2.87009
2528.14	3.36736
2530.9	2.95802
2533.65	3.96611
2536.4	4.64083
2539.15	4.52896
2541.9	4.79089
2544.65	4.93333
2547.4	4.87708
2550.15	3.88071
2552.89	4.26941
2555.64	4.76878
2558.38	4.54263
2561.12	4.93451
2563.87	4.66924
2566.61	5.09934
2569.35	5.12469
2572.09	4.42994
2574.83	3.86905
2577.56	4.24428
2580.3	3.58483
2583.04	3.28376
2585.77	3.5443
2588.5	3.83133
2591.23	3.53338
2593.97	3.86557
2596.7	4.03087
2599.43	3.07728
2602.15	3.20145
2604.88	3.88727
2607.61	4.01899
2610.33	4.37574
2613.06	3.03851
2615.78	3.30359
2618.51	3.80101
2621.23	4.342
2623.95	3.8396
2626.67	3.66219
2629.39	3.98082
2632.1	4.73246
2634.82	5.74723
2637.54	5.01245
2640.25	4.4115
2642.97	4.30043
2645.68	4.49476
2648.39	5.79415
2651.1	6.02592
2653.81	6.27789
2656.52	6.74022
2659.23	7.01409
2661.94	6.78065
2664.64	6.10415
2667.35	5.94256
2670.05	6.48375
2672.76	6.67507
2675.46	6.31786
2678.16	5.78528
2680.86	6.19221
2683.56	6.17936
2686.26	5.5115
2688.96	6.04176
2691.65	6.72567
2694.35	7.1727
2697.04	7.66476
2699.74	7.93126
2702.43	8.0583
2705.12	7.71252
2707.81	8.18826
2710.5	9.31195
2713.19	10.3725
2715.88	10.5239
2718.57	10.7637
2721.25	10.6619
2723.94	10.7534
2726.62	10.6288
2729.3	9.77289
2731.99	9.87407
2734.67	8.17048
2737.35	8.26147
2740.03	7.32494
2742.71	6.9415
2745.38	5.9434
2748.06	5.34142
2750.74	4.46532
2753.41	3.58853
2756.09	3.82093
2758.76	3.26786
2761.43	2.46526
2764.1	2.02256
2766.77	1.13143
2769.44	1.07706
2772.11	0.211091
2774.77	0.232746
2777.44	-0.121114
2780.11	-0.0560395
2782.77	0.627188
2785.43	-0.0104437
2788.1	1.15814
2790.76	1.02529
2793.42	1.54945
2796.08	2.01559
2798.74	2.01799
2801.4	2.44325
2804.05	2.37139
2806.71	2.24332
2809.36	1.7225
2812.02	1.91583
2814.67	2.02908
2817.32	1.92118
2819.97	4.96902
2822.62	7.86856
2825.27	11.4285
2827.92	13.9321
2830.57	17.4594
2833.22	21.5661
2835.86	26.1268
2838.51	31.6001
2841.15	37.3576
2843.79	41.9523
2846.43	47.6412
2849.08	53.5782
2851.72	59.2813
2854.36	66.6751
2856.99	71.5232
2859.63	75.9251
2862.27	80.5907
2864.9	84.5586
2867.54	86.9295
2870.17	88.8224
2872.8	90.6765
2875.43	92.5422
2878.07	94.1217
2880.7	96.0748
2883.32	98.4458
2885.95	100.969
2888.58	102.284
2891.21	103.437
2893.83	104.129
2896.46	106.264
2899.08	108.009
2901.7	109.722
2904.32	111.856
2906.94	113.784
2909.56	116.111
2912.18	119.96
2914.8	123.829
2917.42	126.749
2920.03	129.406
2922.65	130.767
2925.26	132.054
2927.88	132.969
2930.49	132.601
2933.1	129.759
2935.71	127.78
2938.32	125.199
2940.93	121.712
2943.54	117.802
2946.14	113.384
2948.75	108.068
2951.35	101.636
2953.96	96.2814
2956.56	89.6129
2959.16	83.3462
2961.77	77.5712
2964.37	72.0877
2966.96	67.0049
2969.56	61.3797
2972.16	56.3595
2974.76	52.9149
2977.35	49.0723
2979.95	45.0962
2982.54	41.8392
2985.14	37.9688
2987.73	34.707
2990.32	30.7559
2992.91	28.419
2995.5	24.3819
2998.09	21.4855
3000.68	19.1561
3003.26	17.5467
3005.85	16.1244
3008.43	14.2419
3011.02	11.9056
3013.6	10.5561
3016.19	9.24112
3018.77	8.70271
3021.35	7.13642
3023.93	6.51917
3026.5	5.64284
3029.08	4.40641
3031.66	3.22771
3034.24	2.85444
3036.81	2.59419
3039.39	2.65216
3041.96	2.55547
3044.53	2.707
3047.1	1.96162
3049.67	1.18942
3052.24	1.33092
3054.81	1.45378
3057.38	1.68932
3059.95	2.18794
3062.52	2.81444
3065.08	2.63591
3067.65	2.86029
3070.21	2.91768
3072.77	2.8186
3075.33	3.82604
3077.89	3.89655
3080.45	4.57846
3083.01	4.93205
3085.57	4.94786
3088.13	4.83882
3090.68	4.31642
3093.24	5.21457
3095.79	6.90618
3098.35	7.72585
3100.9	8.70158
3103.45	9.59411
3106	10.528
3108.55	10.7598
3111.1	11.4067
3113.65	12.3789
3116.2	13.3226
3118.75	14.3722
3121.29	15.5531
3123.84	15.7733
3126.38	16.5654
3128.92	17.4053
3131.47	18.0795
3134.01	19.0805
3136.55	20.5205
3139.09	21.344
3141.63	22.2842
3144.17	24.4884
3146.7	27.3899
3149.24	32.0569