File: data/Raman/poly_smoothed/Mb_20_23_38_1x_45s_532 nm_x100_100%_600 gr_mm_01.txt
#Acq. time (s)=	45
#Accumulations=	2
#Range (cm-¹)=	200...3150
#Windows=	2
#Auto scanning=	Off
#Autofocus=	Off
#Macrospot=	Off
#AutoExposure=	Off
#Spike filter=	Multiple accum.
#Delay time (s)=	0
#Binning=	1
#Readout mode=	Signal
#DeNoise=	Off
#ICS correction=	On
#Dark correction=	Off
#Inst. Process=	Off
#Detector Gain=	Best Dynamic Range
#Detector ADC=	20 kHz
#Detector temperature (°C)=	-69.85
#Instrument=	LabRAM HR Evol
#Detector=	Synapse
#Objective=	x100
#Grating=	600 gr/mm
#ND Filter=	100%
#Laser (nm)=	532
#Hole=	100.021
#Range=	Auto
#Laser Pol.=	No
#Raman. Pol.=	No
#Laser Pol. (°)=	-0.0007625
#Raman Pol. (°)=	89.9995
#Collection=	Microscope
#StageXY=	Marzhauser
#StageZ=	Marzhauser
#X (µm)=	-7085.9
#Y (µm)=	2206
#Z (µm)=	-74.3
#Full time(mm:ss)=	3:20
#Project=
#Sample=
#Site=
#Title=	Mb_20_23_38_2x_45s_532 nm_x100_100%_600 gr_mm
#Remark=
#Date=	13.07.2022 16:27
#Acquired=	13.07.2022 16:27:51
#Base:Fit=	10.08.2022 10:29:37
#Base:Sub=	10.08.2022 10:34:43
#Filter:Polynom=	16.08.2022 10:13:29
#AxisType[0]=Intens
#AxisUnit[0]=Cnt
#AxisType[1]=Spectr
#AxisUnit[1]=1/cm
200.563	34.3194
204.194	30.2017
207.821	25.1564
211.449	21.4468
215.074	18.7944
218.699	17.4687
222.321	15.5467
225.941	13.0278
229.562	12.3233
233.18	13.627
236.796	14.9351
240.411	14.5389
244.026	14.0469
247.638	12.6963
251.248	12.8858
254.857	12.9042
258.465	11.6909
262.071	11.4834
265.678	10.1013
269.282	9.39893
272.884	10.4166
276.484	9.46148
280.084	9.04219
283.682	6.86143
287.276	3.4412
290.871	1.3855
294.465	4.61813
298.057	5.80846
301.648	6.71735
305.237	8.75494
308.823	10.6995
312.41	11.7504
315.995	14.2012
319.579	16.6585
323.16	17.6337
326.741	19.5611
330.321	19.7436
333.897	20.3341
337.474	22.0443
341.048	22.1704
344.622	22.5773
348.192	23.0516
351.764	22.5069
355.332	22.033
358.901	23.8649
362.466	21.6908
366.03	19.2251
369.594	16.2802
373.155	14.4336
376.715	11.9836
380.273	13.8103
383.832	14.0379
387.388	12.479
390.942	15.2964
394.495	14.958
398.047	12.8402
401.597	11.6135
405.145	10.9124
408.693	9.88105
412.239	8.92594
415.783	7.45741
419.327	6.92413
422.869	6.75928
426.409	6.79748
429.948	7.26835
433.486	9.71271
437.022	9.32026
440.558	7.63021
444.089	8.7057
447.622	9.25046
451.153	7.86632
454.682	8.86441
458.208	8.09628
461.735	10.4482
465.259	13.4836
468.783	16.1819
472.306	16.9772
475.825	19.1332
479.346	19.4024
482.862	17.9578
486.38	19.8262
489.894	21.21
493.407	22.4756
496.92	22.2826
500.43	22.1347
503.939	24.0397
507.448	25.3369
510.954	26.0012
514.459	25.6465
517.962	26.8634
521.466	27.2931
524.966	27.1796
528.466	26.4864
531.964	23.9491
535.46	23.2381
538.955	22.2603
542.449	21.1536
545.942	20.4252
549.433	20.6663
552.923	18.9607
556.412	19.4906
559.899	17.3201
563.385	15.4087
566.867	15.4842
570.35	15.6227
573.832	16.6741
577.313	16.6828
580.79	13.994
584.268	15.0667
587.745	15.0521
591.218	13.4475
594.692	10.9216
598.164	11.2573
601.634	11.4228
605.104	11.4968
608.57	8.33603
612.037	6.01947
615.501	3.73686
618.966	2.01772
622.427	2.06663
625.887	0.708191
629.348	1.56877
632.806	0.638321
636.262	0.132318
639.716	0.449455
643.172	1.16456
646.624	1.37031
650.075	4.22918
653.524	6.61519
656.972	7.83771
660.419	11.3214
663.865	12.3689
667.309	13.134
670.752	14.9706
674.194	16.4811
677.634	15.6862
681.073	16.473
684.511	17.3569
687.947	16.8737
691.382	17.4452
694.816	17.837
698.247	18.9544
701.678	18.6334
705.108	18.3272
708.534	20.6359
711.962	19.5687
715.388	20.6701
718.81	20.8968
722.234	22.378
725.654	24.256
729.075	26.1969
732.492	27.2431
735.91	27.7251
739.325	31.9726
742.741	35.9306
746.153	37.4167
749.564	37.899
752.976	39.8547
756.385	43.0393
759.792	44.9044
763.2	47.5999
766.604	48.9051
770.008	49.8473
773.41	52.6614
776.811	54.2805
780.21	56.7965
783.608	57.5095
787.005	58.854
790.401	61.3175
793.795	63.4915
797.188	66.0898
800.58	68.5014
803.971	69.5095
807.36	71.4035
810.748	72.7989
814.135	74.357
817.518	74.6146
820.902	77.2851
824.285	80.0706
827.665	80.6723
831.045	81.139
834.424	81.2642
837.8	81.0142
841.177	80.0461
844.55	78.3361
847.924	75.8291
851.295	72.0973
854.666	71.5786
858.034	68.6391
861.403	66.624
864.769	64.1851
868.133	62.7656
871.498	59.7721
874.86	59.7238
878.221	59.668
881.58	58.0013
884.938	55.4724
888.297	54.8936
891.653	54.7261
895.007	54.8815
898.36	56.0388
901.712	56.0023
905.063	56.3709
908.412	56.9176
911.76	56.3568
915.107	56.4369
918.452	57.3217
921.797	57.2081
925.138	54.4397
928.48	52.2529
931.82	49.3512
935.16	47.9419
938.496	43.9832
941.833	43.0295
945.168	38.2409
948.5	35.7935
951.834	31.2399
955.163	29.9787
958.494	27.5577
961.821	25.4221
965.15	23.1288
968.474	22.2578
971.8	22.4026
975.123	24.384
978.446	25.3585
981.766	24.8701
985.084	25.0648
988.402	25.2427
991.72	23.7284
995.035	25.3432
998.349	27.3477
1001.66	29.5249
1004.97	30.2847
1008.28	31.1529
1011.59	33.4937
1014.9	36.187
1018.21	40.0314
1021.51	43.8088
1024.81	44.2334
1028.12	46.6068
1031.42	49.5699
1034.72	53.5328
1038.02	57.0504
1041.31	59.4238
1044.61	63.6592
1047.91	66.1351
1051.2	68.0207
1054.49	71.009
1057.78	73.2614
1061.07	71.2667
1064.36	71.5532
1067.65	70.5326
1070.93	66.4017
1074.22	65.0342
1077.5	62.6863
1080.78	59.8603
1084.06	55.5392
1087.34	52.1882
1090.62	50.6103
1093.9	47.2058
1097.17	45.1227
1100.45	40.4611
1103.72	40.4571
1106.99	39.9269
1110.27	40.3779
1113.53	39.9694
1116.8	40.0918
1120.07	41.4493
1123.33	40.7523
1126.6	39.3151
1129.86	38.6487
1133.12	38.0658
1136.38	37.5107
1139.64	36.3467
1142.9	33.9392
1146.16	32.5716
1149.41	29.8665
1152.67	26.681
1155.92	21.7842
1159.17	17.1795
1162.42	13.4388
1165.67	9.58231
1168.92	4.76343
1172.16	2.72494
1175.41	1.62245
1178.65	0.944418
1181.9	2.53747
1185.14	3.5274
1188.38	5.14457
1191.62	3.94766
1194.86	4.97441
1198.09	5.82946
1201.33	8.5207
1204.56	12.3871
1207.8	15.6803
1211.03	19.7417
1214.26	23.3271
1217.49	28.0199
1220.71	32.9811
1223.94	38.2062
1227.16	44.039
1230.39	45.6018
1233.61	49.3228
1236.83	53.8994
1240.05	55.2542
1243.27	57.8036
1246.49	63.5514
1249.71	65.916
1252.92	69.6174
1256.14	72.2568
1259.35	76.4674
1262.56	77.8749
1265.77	79.9029
1268.98	82.5211
1272.19	87.4567
1275.4	90.6832
1278.6	97.5863
1281.81	102.64
1285.01	106.089
1288.21	109.722
1291.41	112.422
1294.61	115.311
1297.81	116.399
1301.01	117.66
1304.2	119.278
1307.4	120.952
1310.59	124.366
1313.78	128.293
1316.97	130.577
1320.16	131.033
1323.35	132.572
1326.54	130.287
1329.72	127.156
1332.91	125.857
1336.09	123.976
1339.27	119.727
1342.45	118.486
1345.64	116.843
1348.81	114.893
1351.99	110.244
1355.17	108.373
1358.34	106.297
1361.51	100.523
1364.69	95.8868
1367.86	91.8321
1371.03	86.7098
1374.2	83.3137
1377.37	82.55
1380.53	84.4925
1383.7	86.828
1386.86	87.4528
1390.02	88.7102
1393.19	90.1448
1396.35	88.4951
1399.51	90.3012
1402.66	91.4494
1405.82	95.5424
1408.97	101.753
1412.13	109.201
1415.28	118.908
1418.43	129.311
1421.59	142.006
1424.73	154.666
1427.88	167.173
1431.03	179.153
1434.18	190.597
1437.32	199.23
1440.46	205.694
1443.61	210.084
1446.75	211.673
1449.89	211.503
1453.03	209.09
1456.16	202.309
1459.3	193.896
1462.44	182.862
1465.57	171.932
1468.7	158.473
1471.83	143.624
1474.96	127.764
1478.09	112.727
1481.22	98.2888
1484.35	86.6031
1487.47	73.0699
1490.6	60.4622
1493.72	54.54
1496.84	52.1719
1499.96	53.8484
1503.08	52.8631
1506.2	55.8828
1509.32	59.0302
1512.44	58.7443
1515.55	60.0103
1518.66	62.2832
1521.78	61.9549
1524.89	61.9365
1528	61.8391
1531.11	62.8667
1534.21	63.7061
1537.32	64.3309
1540.43	65.1102
1543.53	65.6119
1546.63	62.5704
1549.74	60.8439
1552.84	59.1553
1555.94	56.4705
1559.03	53.6417
1562.13	51.7465
1565.23	49.3456
1568.32	52.8259
1571.42	60.0793
1574.51	65.4805
1577.6	69.4655
1580.69	74.6521
1583.78	78.4388
1586.87	79.3011
1589.95	81.1848
1593.04	81.8746
1596.12	82.7122
1599.21	82.0111
1602.29	81.7219
1605.37	81.9267
1608.45	80.5226
1611.53	80.4072
1614.6	81.1288
1617.68	81.9134
1620.75	80.6393
1623.83	81.6272
1626.9	83.3184
1629.97	85.1257
1633.04	87.2224
1636.11	88.6801
1639.18	92.516
1642.25	94.5944
1645.31	97.8279
1648.38	100.931
1651.44	101.541
1654.5	102.428
1657.56	101.504
1660.62	99.0622
1663.68	95.6467
1666.74	92.5647
1669.8	86.814
1672.85	81.5353
1675.91	77.128
1678.96	72.494
1682.01	64.3983
1685.06	59.788
1688.11	55.8066
1691.16	49.7952
1694.21	44.2991
1697.25	39.797
1700.3	37.0704
1703.34	34.166
1706.39	31.6125
1709.43	28.212
1712.47	26.3038
1715.51	24.0113
1718.54	22.6596
1721.58	23.0839
1724.62	20.7318
1727.65	20.3441
1730.68	19.4732
1733.72	18.0778
1736.75	16.6867
1739.78	16.4102
1742.81	16.519
1745.84	15.5289
1748.86	16.0627
1751.89	15.0762
1754.91	12.8403
1757.93	11.682
1760.96	11.0551
1763.98	9.04791
1767	7.76827
1770.02	6.48545
1773.03	6.81748
1776.05	4.42809
1779.07	4.82137
1782.08	3.2173
1785.09	4.4679
1788.11	5.14525
1791.12	4.49598
1794.13	5.87196
1797.13	6.58056
1800.14	7.54498
1803.15	7.92186
1806.15	7.72451
1809.16	8.07043
1812.16	7.47775
1815.16	7.01137
1818.16	7.25354
1821.16	6.36133
1824.16	5.28714
1827.16	4.35835
1830.16	2.87985
1833.15	1.86668
1836.14	0.620849
1839.14	0.593011
1842.13	1.37339
1845.12	-0.545915
1848.11	-0.145281
1851.1	0.0608578
1854.08	0.207343
1857.07	-0.016017
1860.05	0.887507
1863.04	1.15639
1866.02	3.38302
1869	5.79675
1871.98	5.97399
1874.96	5.47076
1877.94	6.25427
1880.92	6.87666
1882.51	8.0173
1885.5	8.54353
1888.48	9.04698
1891.47	10.0989
1894.46	10.6091
1897.44	11.4443
1900.42	12.5563
1903.41	13.5208
1906.39	14.5706
1909.37	14.1002
1912.35	14.184
1915.32	12.4259
1918.3	11.3765
1921.27	11.7157
1924.25	11.3299
1927.22	10.1424
1930.19	8.68845
1933.17	9.12781
1936.14	9.50963
1939.11	8.9139
1942.07	8.86644
1945.04	8.95512
1948.01	7.68015
1950.97	8.54538
1953.93	8.77193
1956.9	7.68032
1959.86	7.96152
1962.82	7.66785
1965.78	9.10482
1968.74	10.1035
1971.69	11.2486
1974.65	13.0057
1977.6	13.2935
1980.56	12.2145
1983.51	14.0289
1986.46	15.4364
1989.41	16.2608
1992.36	19.2608
1995.31	20.441
1998.26	19.2715
2001.2	20.4239
2004.15	22.0103
2007.09	22.4148
2010.04	22.598
2012.98	23.0321
2015.92	22.9751
2018.86	23.0501
2021.8	21.0666
2024.73	20.989
2027.67	19.0913
2030.61	18.4587
2033.54	17.6655
2036.47	16.251
2039.4	16.4893
2042.33	16.0036
2045.27	15.4501
2048.19	16.362
2051.12	16.7158
2054.05	18.3428
2056.97	18.2945
2059.9	18.7508
2062.82	19.6426
2065.74	20.3687
2068.67	22.746
2071.59	23.9764
2074.51	26.4876
2077.42	27.1784
2080.34	29.0404
2083.26	29.4813
2086.17	30.0401
2089.09	31.7646
2092	31.0755
2094.91	31.0324
2097.82	31.8657
2100.73	32.256
2103.64	31.9812
2106.55	32.3932
2109.45	32.8364
2112.36	33.4069
2115.26	32.3307
2118.17	33.0884
2121.07	34.016
2123.97	34.1545
2126.87	35.6659
2129.77	36.5507
2132.67	38.8107
2135.56	40.7954
2138.46	43.6436
2141.35	46.4957
2144.25	48.6627
2147.14	50.5173
2150.03	53.1107
2152.92	56.5826
2155.81	58.8707
2158.7	61.9817
2161.59	63.2099
2164.47	63.9683
2167.36	65.5923
2170.24	67.9223
2173.13	68.2517
2176.01	68.0083
2178.89	67.9333
2181.77	66.5309
2184.65	65.2069
2187.53	65.2428
2190.4	65.1254
2193.28	63.6173
2196.16	61.1458
2199.03	60.8795
2201.9	58.1893
2204.77	55.0586
2207.64	51.7792
2210.51	50.2374
2213.38	47.8238
2216.25	45.3482
2219.12	43.2927
2221.98	41.0029
2224.85	39.0821
2227.71	35.4559
2230.57	32.3353
2233.43	30.2614
2236.29	28.4265
2239.15	28.5505
2242.01	25.4085
2244.87	22.1968
2247.72	21.0842
2250.58	19.9724
2253.43	19.902
2256.29	20.4517
2259.14	20.7028
2261.99	21.3335
2264.84	21.6702
2267.69	22.3283
2270.53	22.7843
2273.38	22.6815
2276.23	23.5475
2279.07	23.2917
2281.91	23.0065
2284.76	22.2619
2287.6	18.8934
2290.44	17.4067
2293.28	15.1389
2296.12	13.4899
2298.96	12.3063
2301.79	13.1752
2304.63	13.0845
2307.46	11.1554
2310.3	9.32289
2313.13	9.14189
2315.96	9.6268
2318.79	9.3412
2321.62	11.552
2324.45	12.9068
2327.27	13.347
2330.1	14.5882
2332.92	17.243
2335.75	18.181
2338.57	19.4453
2341.39	20.0228
2344.21	18.9851
2347.04	19.1665
2349.85	17.8234
2352.67	16.9244
2355.49	14.8667
2358.3	13.5927
2361.12	12.3306
2363.93	11.9599
2366.75	12.213
2369.56	12.4906
2372.37	11.3028
2375.18	9.46646
2377.99	8.64294
2380.8	10.0058
2383.6	10.8663
2386.41	11.209
2389.21	12.9407
2392.02	14.0172
2394.82	13.3319
2397.62	14.5584
2400.42	15.3308
2403.22	15.9336
2406.02	16.041
2408.82	15.9539
2411.62	15.4301
2414.41	16.6007
2417.21	16.3156
2420	17.5569
2422.79	17.2752
2425.59	15.4152
2428.38	15.7289
2431.17	14.82
2433.95	13.6033
2436.74	12.738
2439.53	11.7277
2442.31	9.37156
2445.1	8.65443
2447.88	9.38114
2450.67	9.13514
2453.45	9.93015
2456.23	9.81464
2459.01	9.04369
2461.79	8.01677
2464.57	6.00333
2467.34	6.70106
2470.12	5.36484
2472.89	5.07349
2475.67	4.70329
2478.44	5.58681
2481.21	5.42178
2483.98	5.23817
2486.75	6.03453
2489.52	4.86106
2492.29	3.06077
2495.05	3.47664
2497.82	2.58214
2500.58	1.97604
2503.35	2.02712
2506.11	1.6769
2508.87	0.44969
2511.63	0.201398
2514.39	0.394414
2517.15	0.704438
2519.91	0.949265
2522.67	1.30116
2525.42	2.01521
2528.18	1.896
2530.93	1.94394
2533.69	3.07708
2536.44	3.69184
2539.19	3.85368
2541.94	5.67365
2544.69	6.20849
2547.44	6.48988
2550.18	7.6454
2552.93	8.22804
2555.67	7.00079
2558.42	7.24593
2561.16	7.16535
2563.9	6.11749
2566.64	5.93075
2569.38	4.3134
2572.12	4.21458
2574.86	3.51523
2577.6	1.99259
2580.33	1.04266
2583.07	0.618533
2585.8	0.560061
2588.54	0.985389
2591.27	0.336248
2594	1.06214
2596.73	-0.183843
2599.46	0.832762
2602.19	0.983392
2604.92	2.38192
2607.64	2.3143
2610.37	3.48011
2613.09	4.8787
2615.82	6.30569
2618.54	5.49446
2621.26	5.86913
2623.98	6.05615
2626.7	6.89423
2629.42	6.58124
2632.14	6.95707
2634.86	8.58016
2637.57	7.97804
2640.29	7.84003
2643	7.49974
2645.71	5.83774
2648.43	5.65112
2651.14	6.03918
2653.85	5.24965
2656.56	5.10128
2659.26	4.61315
2661.97	4.02909
2664.68	3.26076
2667.38	2.70009
2670.09	2.8275
2672.79	2.21198
2675.49	2.79729
2678.19	3.33209
2680.89	3.75233
2683.59	4.69857
2686.29	5.2786
2688.99	7.08781
2691.69	7.63726
2694.38	9.3583
2697.08	10.9001
2699.77	13.484
2702.46	16.1988
2705.15	17.6568
2707.85	19.0974
2710.54	20.9247
2713.22	22.8979
2715.91	24.5417
2718.6	25.3487
2721.29	25.4877
2723.97	25.9618
2726.66	24.2406
2729.34	22.7819
2732.02	21.737
2734.7	20.2558
2737.38	18.9669
2740.06	15.9704
2742.74	15.2265
2745.42	12.6211
2748.09	10.4325
2750.77	8.61298
2753.45	6.83772
2756.12	5.55097
2758.79	5.04018
2761.46	3.09348
2764.14	2.90086
2766.8	3.42015
2769.47	2.06588
2772.14	1.66474
2774.81	2.08923
2777.48	1.02068
2780.14	0.519111
2782.8	0.807965
2785.47	0.490703
2788.13	0.253303
2790.79	0.121935
2793.45	1.06201
2796.11	1.87762
2798.77	0.924421
2801.43	-0.0431342
2804.09	-0.354838
2806.74	-1.5388
2809.4	-2.347
2812.05	-2.62849
2814.71	-2.41809
2817.36	1.53066
2820.01	7.41531
2822.66	16.7148
2825.31	27.8442
2827.96	40.7943
2830.6	57.5022
2833.25	74.947
2835.9	93.54
2838.54	114.072
2841.18	132.382
2843.83	153.6
2846.47	175.229
2849.11	196.361
2851.75	217.788
2854.39	239.096
2857.03	260.707
2859.66	280.024
2862.3	296.801
2864.94	312.61
2867.57	326.334
2870.2	337.505
2872.84	347.038
2875.47	355.544
2878.1	364.246
2880.73	373.628
2883.36	383.539
2885.99	392.738
2888.61	402.145
2891.24	410.253
2893.86	417.34
2896.49	425.609
2899.11	432.973
2901.73	441.54
2904.36	449.852
2906.98	461.052
2909.6	473.966
2912.21	487.121
2914.83	499.424
2917.45	511.287
2920.07	522.45
2922.68	531.024
2925.29	536.672
2927.91	539.988
2930.52	539.823
2933.13	536.041
2935.74	528.487
2938.35	518.46
2940.96	505.556
2943.57	489.253
2946.18	472.303
2948.78	453.646
2951.39	432.945
2953.99	411.483
2956.59	387.61
2959.2	364.654
2961.8	342.092
2964.4	322.181
2967	302.832
2969.6	284.947
2972.19	267.742
2974.79	251.917
2977.39	234.92
2979.98	217.666
2982.58	201.108
2985.17	184.558
2987.76	166.841
2990.35	150.266
2992.94	133.031
2995.53	116.348
2998.12	101.345
3000.71	86.9738
3003.3	72.9046
3005.88	59.937
3008.47	50.2582
3011.05	41.344
3013.64	32.5601
3016.22	24.0336
3018.8	17.4652
3021.38	11.4572
3023.96	7.83484
3026.54	5.02788
3029.12	3.76689
3031.69	2.00463
3034.27	1.26857
3036.84	1.19613
3039.42	0.125467
3041.99	1.87873
3044.57	1.81138
3047.14	2.81489
3049.71	2.85422
3052.28	2.69475
3054.85	2.29556
3057.41	2.2231
3059.98	2.86012
3062.55	2.84902
3065.11	1.98951
3067.68	2.04537
3070.24	2.3679
3072.8	2.05693
3075.36	1.16128
3077.93	-0.497138
3080.49	-0.707023
3083.04	-0.386044
3085.6	-1.07827
3088.16	0.434621
3090.72	1.86848
3093.27	1.85627
3095.83	1.98643
3098.38	3.46361
3100.93	4.27034
3103.49	4.94665
3106.04	5.61738
3108.59	6.53868
3111.14	8.11278
3113.69	9.68374
3116.23	11.734
3118.78	13.431
3121.33	15.0366
3123.87	17.2342
3126.41	19.0593
3128.96	20.4757
3131.5	22.4675
3134.04	23.2028
3136.58	24.7698
3139.12	25.8553
3141.66	27.7789
3144.2	29.4415
3146.74	30.9702
3149.27	32.1279