File: data/Raman/poly_smoothed/Mb_20_23_08_1x_45s_532 nm_x100_100%_600 gr_mm_01.txt
#Acq. time (s)=	45
#Accumulations=	2
#Range (cm-¹)=	200...3150
#Windows=	2
#Auto scanning=	Off
#Autofocus=	Off
#Macrospot=	Off
#AutoExposure=	Off
#Spike filter=	Multiple accum.
#Delay time (s)=	0
#Binning=	1
#Readout mode=	Signal
#DeNoise=	Off
#ICS correction=	On
#Dark correction=	Off
#Inst. Process=	Off
#Detector Gain=	Best Dynamic Range
#Detector ADC=	20 kHz
#Detector temperature (°C)=	-69.85
#Instrument=	LabRAM HR Evol
#Detector=	Synapse
#Objective=	x100
#Grating=	600 gr/mm
#ND Filter=	100%
#Laser (nm)=	532
#Hole=	100.021
#Range=	Auto
#Laser Pol.=	No
#Raman. Pol.=	No
#Laser Pol. (°)=	-0.0007625
#Raman Pol. (°)=	89.9995
#Collection=	Microscope
#StageXY=	Marzhauser
#StageZ=	Marzhauser
#X (µm)=	-6893.9
#Y (µm)=	2173.9
#Z (µm)=	-74.85
#Full time(mm:ss)=	3:19
#Project=
#Sample=
#Site=
#Title=	Mb_20_23_08_2x_45s_532 nm_x100_100%_600 gr_mm
#Remark=
#Date=	13.07.2022 13:31
#Acquired=	13.07.2022 13:31:58
#Edit:Spike=	13.07.2022 13:34:48
#Edit:Spike=	13.07.2022 13:34:49
#Base:Fit=	10.08.2022 10:29:19
#Base:Fit=	10.08.2022 10:29:37
#Base:Sub=	10.08.2022 10:31:46
#Filter:Polynom=	16.08.2022 10:13:29
#AxisType[0]=Intens
#AxisUnit[0]=Cnt
#AxisType[1]=Spectr
#AxisUnit[1]=1/cm
200.563	106.404
204.194	101.352
207.821	93.4876
211.449	85.526
215.074	79.5805
218.699	73.2218
222.321	71.5345
225.941	65.9189
229.562	60.6522
233.18	55.9161
236.796	49.8383
240.411	43.565
244.026	37.3668
247.638	33.6103
251.248	32.4149
254.857	28.6548
258.465	22.8591
262.071	20.0406
265.678	15.9797
269.282	14.9597
272.884	12.5746
276.484	9.90758
280.084	7.29855
283.682	6.54717
287.276	5.4914
290.871	4.71444
294.465	4.13622
298.057	6.11687
301.648	9.40351
305.237	11.583
308.823	17.7935
312.41	20.5343
315.995	20.8126
319.579	22.1053
323.16	23.421
326.741	23.2532
330.321	23.6163
333.897	25.4269
337.474	25.9629
341.048	24.0811
344.622	24.7309
348.192	23.2391
351.764	19.4064
355.332	18.9706
358.901	16.3552
362.466	11.7289
366.03	6.94504
369.594	5.96171
373.155	5.24237
376.715	4.16456
380.273	4.79142
383.832	3.52486
387.388	5.49675
390.942	5.40779
394.495	5.11728
398.047	6.2286
401.597	5.9393
405.145	6.99152
408.693	6.64943
412.239	7.20729
415.783	7.54115
419.327	7.41641
422.869	7.6661
426.409	7.6221
429.948	7.54669
433.486	4.5106
437.022	3.02497
440.558	1.95048
444.089	3.01865
447.622	1.11635
451.153	2.89696
454.682	4.91512
458.208	4.91146
461.735	7.03561
465.259	8.34177
468.783	6.82729
472.306	6.78876
475.825	8.82775
479.346	10.3861
482.862	12.19
486.38	15.4663
489.894	19.9474
493.407	22.0691
496.92	26.0044
500.43	29.9733
503.939	31.6777
507.448	32.9263
510.954	34.6602
514.459	35.3269
517.962	34.6262
521.466	34.7342
524.966	34.0695
528.466	33.758
531.964	34.7064
535.46	33.8061
538.955	31.8258
542.449	28.128
545.942	24.8759
549.433	23.0137
552.923	20.4878
556.412	20.4189
559.899	20.1077
563.385	19.6403
566.867	18.0009
570.35	16.5805
573.832	17.0978
577.313	15.647
580.79	16.6237
584.268	14.9443
587.745	13.4904
591.218	13.1103
594.692	11.805
598.164	10.2998
601.634	11.0645
605.104	10.944
608.57	9.23756
612.037	10.7585
615.501	13.2113
618.966	10.2333
622.427	10.4709
625.887	10.1112
629.348	8.4803
632.806	7.17106
636.262	4.60653
639.716	7.0686
643.172	10.0421
646.624	10.4643
650.075	12.3526
653.524	15.3509
656.972	17.5819
660.419	18.7947
663.865	21.2169
667.309	23.1297
670.752	21.7599
674.194	22.7514
677.634	24.5891
681.073	27.3646
684.511	28.5349
687.947	30.463
691.382	33.3306
694.816	32.5727
698.247	31.4614
701.678	28.4035
705.108	24.7871
708.534	25.2715
711.962	20.7679
715.388	17.5034
718.81	14.7659
722.234	17.3583
725.654	20.6528
729.075	23.0442
732.492	21.6977
735.91	24.1268
739.325	23.6704
742.741	26.2074
746.153	30.8298
749.564	33.662
752.976	37.4184
756.385	42.6276
759.792	48.7265
763.2	53.8459
766.604	57.0161
770.008	60.3875
773.41	62.8042
776.811	62.7822
780.21	61.1006
783.608	59.9225
787.005	58.0878
790.401	61.8161
793.795	61.4377
797.188	61.3944
800.58	62.2435
803.971	62.6138
807.36	62.4613
810.748	62.5197
814.135	64.2417
817.518	63.9427
820.902	65.8083
824.285	68.2022
827.665	71.5102
831.045	75.8078
834.424	76.3952
837.8	77.0651
841.177	75.9988
844.55	73.9118
847.924	70.5348
851.295	67.3365
854.666	63.6164
858.034	59.5733
861.403	56.3632
864.769	53.5375
868.133	51.1745
871.498	52.0386
874.86	50.7564
878.221	50.7824
881.58	50.2882
884.938	50.8169
888.297	52.5791
891.653	52.1687
895.007	53.2814
898.36	53.8023
901.712	51.5069
905.063	52.991
908.412	51.5226
911.76	52.9589
915.107	51.7543
918.452	50.3115
921.797	49.3647
925.138	49.5618
928.48	49.0981
931.82	47.4921
935.16	46.4432
938.496	45.3501
941.833	42.7837
945.168	37.8732
948.5	36.2589
951.834	34.6936
955.163	33.1777
958.494	30.7579
961.821	32.9965
965.15	35.326
968.474	38.4615
971.8	42.1467
975.123	45.8148
978.446	48.4812
981.766	50.1186
985.084	51.7967
988.402	53.5324
991.72	53.8182
995.035	53.6668
998.349	53.0639
1001.66	50.5368
1004.97	52.0217
1008.28	58.4945
1011.59	65.0409
1014.9	73.9471
1018.21	83.9866
1021.51	91.4333
1024.81	97.6171
1028.12	105.444
1031.42	116.195
1034.72	123.225
1038.02	129.498
1041.31	134.672
1044.61	140.172
1047.91	143.557
1051.2	143.02
1054.49	139.218
1057.78	135.191
1061.07	127.095
1064.36	119.461
1067.65	106.475
1070.93	94.3333
1074.22	84.353
1077.5	69.9327
1080.78	61.1696
1084.06	54.2503
1087.34	50.5369
1090.62	53.6259
1093.9	57.3539
1097.17	58.8808
1100.45	58.4647
1103.72	62.8757
1106.99	69.7449
1110.27	77.1186
1113.53	81.6808
1116.8	84.3849
1120.07	85.9388
1123.33	88.3865
1126.6	87.193
1129.86	87.5759
1133.12	84.7442
1136.38	80.0188
1139.64	74.5129
1142.9	68.7748
1146.16	63.342
1149.41	55.5484
1152.67	49.6059
1155.92	40.2357
1159.17	30.6917
1162.42	23.5606
1165.67	15.3802
1168.92	14.9729
1172.16	13.0854
1175.41	10.5825
1178.65	8.39615
1181.9	12.8732
1185.14	16.3777
1188.38	21.4842
1191.62	23.9469
1194.86	27.8526
1198.09	30.1654
1201.33	34.7689
1204.56	37.4048
1207.8	41.0345
1211.03	44.7675
1214.26	48.012
1217.49	53.5174
1220.71	58.9279
1223.94	65.1937
1227.16	71.6733
1230.39	75.7959
1233.61	82.8316
1236.83	88.6725
1240.05	92.7029
1243.27	98.9914
1246.49	106.906
1249.71	113.304
1252.92	115.363
1256.14	120.038
1259.35	125.932
1262.56	131.56
1265.77	139.977
1268.98	150.245
1272.19	158.367
1275.4	165.684
1278.6	172.714
1281.81	179.934
1285.01	188.557
1288.21	195.222
1291.41	200.961
1294.61	205.499
1297.81	205.122
1301.01	203.298
1304.2	204.327
1307.4	212.008
1310.59	223.812
1313.78	233.327
1316.97	242.2
1320.16	248.377
1323.35	255.172
1326.54	256.406
1329.72	254.968
1332.91	254.356
1336.09	255.929
1339.27	254.21
1342.45	251.878
1345.64	248.164
1348.81	241.715
1351.99	231.66
1355.17	221.607
1358.34	212.464
1361.51	201.412
1364.69	189.598
1367.86	173.313
1371.03	156.762
1374.2	142.561
1377.37	132.132
1380.53	130.482
1383.7	134.429
1386.86	139.773
1390.02	139.228
1393.19	140.687
1396.35	142.804
1399.51	141.477
1402.66	146.967
1405.82	151.191
1408.97	158.287
1412.13	166.213
1415.28	182.054
1418.43	202.112
1421.59	227
1424.73	254.723
1427.88	281.434
1431.03	307.205
1434.18	333.32
1437.32	357.519
1440.46	375.169
1443.61	386.198
1446.75	393.138
1449.89	397.563
1453.03	396.581
1456.16	391.287
1459.3	380.149
1462.44	365.256
1465.57	342.035
1468.7	316.514
1471.83	290.096
1474.96	260.776
1478.09	229.781
1481.22	198.958
1484.35	162.879
1487.47	123.211
1490.6	96.6552
1493.72	100.39
1496.84	115.489
1499.96	135.57
1503.08	155.136
1506.2	174.534
1509.32	192.543
1512.44	207.984
1515.55	218.768
1518.66	227.278
1521.78	235.819
1524.89	242.165
1528	242.926
1531.11	241.579
1534.21	238.546
1537.32	233.063
1540.43	223.009
1543.53	210.396
1546.63	195.342
1549.74	176.683
1552.84	153.121
1555.94	127.498
1559.03	101.444
1562.13	79.8866
1565.23	72.0885
1568.32	86.112
1571.42	106.547
1574.51	117.958
1577.6	126.409
1580.69	133.383
1583.78	138.377
1586.87	141.816
1589.95	145.743
1593.04	150.04
1596.12	153.369
1599.21	155.044
1602.29	153.531
1605.37	153.808
1608.45	154.275
1611.53	155.733
1614.6	157.136
1617.68	159.019
1620.75	160.652
1623.83	161.315
1626.9	163.397
1629.97	165.948
1633.04	173.092
1636.11	177.964
1639.18	183.689
1642.25	190.897
1645.31	196.459
1648.38	202.294
1651.44	206.058
1654.5	206.081
1657.56	205.124
1660.62	202.479
1663.68	197.115
1666.74	192.132
1669.8	182.782
1672.85	173.237
1675.91	159.69
1678.96	146.179
1682.01	134.745
1685.06	121.498
1688.11	109.594
1691.16	96.8424
1694.21	86.0611
1697.25	75.2687
1700.3	65.5592
1703.34	59.1147
1706.39	54.8385
1709.43	49.5659
1712.47	45.1833
1715.51	41.7022
1718.54	37.7787
1721.58	34.596
1724.62	32.4418
1727.65	27.7195
1730.68	25.4355
1733.72	23.9475
1736.75	21.687
1739.78	20.8097
1742.81	19.6021
1745.84	17.5685
1748.86	16.5075
1751.89	14.5421
1754.91	13.2867
1757.93	11.9133
1760.96	12.1506
1763.98	10.6867
1767	8.26994
1770.02	6.63
1773.03	6.03278
1776.05	5.14093
1779.07	3.84588
1782.08	2.94902
1785.09	2.19307
1788.11	2.58668
1791.12	1.86416
1794.13	1.91249
1797.13	1.20871
1800.14	-0.100918
1803.15	-0.121687
1806.15	0.218269
1809.16	0.338525
1812.16	0.934255
1815.16	0.807968
1818.16	-0.545783
1821.16	0.950439
1824.16	0.598853
1827.16	1.82085
1830.16	1.44312
1833.15	0.625763
1836.14	-0.691718
1839.14	-0.335031
1842.13	-0.0755358
1845.12	-0.0899467
1848.11	-1.37308
1851.1	-1.50798
1854.08	-1.60977
1857.07	-0.416661
1860.05	1.55941
1863.04	2.91582
1866.02	2.92175
1869	3.50787
1871.98	4.51343
1874.96	5.933
1877.94	6.66231
1880.92	5.78831
1882.51	6.52166
1885.5	6.49776
1888.48	6.94955
1891.47	7.76956
1894.46	8.23863
1897.44	6.80759
1900.42	7.73621
1903.41	7.21501
1906.39	6.70853
1909.37	6.8428
1912.35	6.71972
1915.32	7.09486
1918.3	6.06532
1921.27	6.02393
1924.25	6.19771
1927.22	6.02618
1930.19	5.934
1933.17	4.60516
1936.14	4.21817
1939.11	3.87364
1942.07	4.09512
1945.04	4.86931
1948.01	4.9372
1950.97	4.83969
1953.93	4.20742
1956.9	3.99352
1959.86	4.41509
1962.82	2.92196
1965.78	3.42143
1968.74	2.90596
1971.69	3.90426
1974.65	5.00129
1977.6	4.26944
1980.56	3.86858
1983.51	4.23946
1986.46	4.64582
1989.41	3.53238
1992.36	3.48144
1995.31	4.70148
1998.26	4.34006
2001.2	4.2108
2004.15	4.38687
2007.09	5.47507
2010.04	5.87812
2012.98	6.64366
2015.92	6.00342
2018.86	7.54249
2021.8	7.87132
2024.73	8.50234
2027.67	8.12466
2030.61	8.43068
2033.54	8.96972
2036.47	9.74491
2039.4	9.80513
2042.33	11.4601
2045.27	10.3523
2048.19	9.81047
2051.12	9.41055
2054.05	10.8377
2056.97	10.4291
2059.9	9.24219
2062.82	8.41981
2065.74	8.8248
2068.67	8.82752
2071.59	8.99023
2074.51	8.15268
2077.42	7.87849
2080.34	8.99867
2083.26	9.0033
2086.17	11.4137
2089.09	12.2939
2092	14.175
2094.91	15.5442
2097.82	17.5704
2100.73	20.1261
2103.64	23.1109
2106.55	25.0305
2109.45	27.3785
2112.36	29.8383
2115.26	33.8236
2118.17	36.9011
2121.07	39.9834
2123.97	42.9561
2126.87	45.8488
2129.77	50.0809
2132.67	53.617
2135.56	58.2125
2138.46	61.6452
2141.35	67.5943
2144.25	74.2198
2147.14	80.2456
2150.03	87.4524
2152.92	94.4773
2155.81	101.992
2158.7	106.866
2161.59	112.595
2164.47	118.77
2167.36	122.703
2170.24	125.033
2173.13	125.882
2176.01	127.254
2178.89	126.578
2181.77	126.297
2184.65	124.197
2187.53	122.103
2190.4	119.133
2193.28	114.414
2196.16	110.485
2199.03	105.004
2201.9	100.116
2204.77	92.7381
2207.64	87.2936
2210.51	80.9949
2213.38	74.993
2216.25	69.1317
2219.12	62.5528
2221.98	58.0922
2224.85	53.9705
2227.71	49.4823
2230.57	44.8663
2233.43	41.9834
2236.29	38.0481
2239.15	34.6069
2242.01	31.4095
2244.87	27.6346
2247.72	25.648
2250.58	25.489
2253.43	23.6127
2256.29	22.3883
2259.14	22.6052
2261.99	22.759
2264.84	21.1682
2267.69	20.6142
2270.53	20.9421
2273.38	19.4664
2276.23	17.8221
2279.07	16.5652
2281.91	16.2657
2284.76	15.7175
2287.6	16.822
2290.44	15.249
2293.28	13.357
2296.12	11.7944
2298.96	10.7726
2301.79	10.5048
2304.63	10.5443
2307.46	8.89002
2310.3	7.64091
2313.13	5.23697
2315.96	3.84736
2318.79	4.28603
2321.62	4.41684
2324.45	2.9829
2327.27	2.86241
2330.1	2.56268
2332.92	2.08333
2335.75	1.19249
2338.57	0.796545
2341.39	0.663819
2344.21	-0.642191
2347.04	-1.06043
2349.85	-1.29832
2352.67	-0.663915
2355.49	0.162412
2358.3	-1.03778
2361.12	-1.2297
2363.93	-0.29991
2366.75	0.982253
2369.56	1.59636
2372.37	0.257278
2375.18	1.38235
2377.99	1.29131
2380.8	1.23774
2383.6	2.7699
2386.41	3.83427
2389.21	4.10253
2392.02	5.27822
2394.82	4.88412
2397.62	5.81913
2400.42	5.23189
2403.22	6.00223
2406.02	6.27486
2408.82	6.21386
2411.62	5.99292
2414.41	5.69598
2417.21	6.29625
2420	7.57658
2422.79	7.73377
2425.59	7.07317
2428.38	7.04272
2431.17	7.13782
2433.95	6.47931
2436.74	6.63572
2439.53	5.21597
2442.31	5.11644
2445.1	5.6998
2447.88	5.7658
2450.67	6.40766
2453.45	4.80524
2456.23	4.27967
2459.01	4.82853
2461.79	3.50883
2464.57	4.35562
2467.34	4.59842
2470.12	4.60795
2472.89	5.70878
2475.67	5.91911
2478.44	5.17226
2481.21	4.37098
2483.98	4.63524
2486.75	4.59258
2489.52	3.75727
2492.29	2.89144
2495.05	3.26536
2497.82	3.61825
2500.58	4.28012
2503.35	4.04652
2506.11	3.39852
2508.87	3.50456
2511.63	3.91736
2514.39	3.45578
2517.15	4.24027
2519.91	4.58748
2522.67	5.14331
2525.42	5.70243
2528.18	5.77103
2530.93	7.33692
2533.69	6.74092
2536.44	7.40292
2539.19	8.77588
2541.94	9.27249
2544.69	10.7506
2547.44	11.1811
2550.18	13.8331
2552.93	14.9045
2555.67	16.6822
2558.42	17.8964
2561.16	18.1451
2563.9	19.0762
2566.64	19.1488
2569.38	19.9429
2572.12	20.4018
2574.86	19.8202
2577.6	18.7034
2580.33	19.6401
2583.07	19.2614
2585.8	19.1589
2588.54	17.7739
2591.27	17.0357
2594	14.708
2596.73	14.3673
2599.46	13.0573
2602.19	11.5559
2604.92	12.1766
2607.64	12.3867
2610.37	13.1861
2613.09	14.3422
2615.82	15.3505
2618.54	15.8639
2621.26	17.7612
2623.98	18.4439
2626.7	17.3716
2629.42	17.4812
2632.14	18.1708
2634.86	19.1265
2637.57	20.2093
2640.29	19.5439
2643	19.6864
2645.71	20.3786
2648.43	20.538
2651.14	20.6309
2653.85	21.5455
2656.56	21.7389
2659.26	21.2909
2661.97	20.7666
2664.68	22.0199
2667.38	21.1115
2670.09	22.9377
2672.79	23.4453
2675.49	24.6281
2678.19	24.0758
2680.89	24.1879
2683.59	23.0016
2686.29	24.8659
2688.99	24.7045
2691.69	23.4655
2694.38	24.9809
2697.08	27.258
2699.77	29.6757
2702.46	30.9761
2705.15	31.5216
2707.85	34.2898
2710.54	36.9961
2713.22	39.5832
2715.91	41.878
2718.6	41.9996
2721.29	42.9675
2723.97	42.7802
2726.66	42.6182
2729.34	40.7701
2732.02	40.245
2734.7	38.1185
2737.38	34.5067
2740.06	31.7519
2742.74	27.5257
2745.42	25.2918
2748.09	22.8617
2750.77	18.9014
2753.45	16.4884
2756.12	14.7396
2758.79	12.725
2761.46	11.9506
2764.14	9.81007
2766.8	7.09075
2769.47	5.03261
2772.14	3.6003
2774.81	4.33801
2777.48	2.88677
2780.14	2.40465
2782.8	2.06901
2785.47	2.18873
2788.13	1.51335
2790.79	0.842889
2793.45	0.724865
2796.11	1.54417
2798.77	1.71394
2801.43	0.746632
2804.09	0.503581
2806.74	-0.145481
2809.4	-1.8371
2812.05	-1.39389
2814.71	1.0692
2817.36	9.10257
2820.01	23.3828
2822.66	40.8662
2825.31	61.9252
2827.96	85.844
2830.6	110.441
2833.25	136.911
2835.9	166.322
2838.54	196.398
2841.18	227.484
2843.83	260.489
2846.47	291.225
2849.11	323.016
2851.75	362.187
2854.39	402.161
2857.03	441.198
2859.66	476.956
2862.3	509.81
2864.94	536.895
2867.57	560.723
2870.2	580.672
2872.84	596.062
2875.47	612.446
2878.1	626.504
2880.73	640.703
2883.36	654.516
2885.99	667.86
2888.61	680.093
2891.24	689.967
2893.86	698.171
2896.49	707.327
2899.11	714.644
2901.73	724.831
2904.36	736.114
2906.98	751.316
2909.6	769.891
2912.21	792.46
2914.83	820.557
2917.45	846.269
2920.07	867.838
2922.68	883.646
2925.29	895.992
2927.91	901.968
2930.52	902.483
2933.13	895.676
2935.74	882.632
2938.35	867.786
2940.96	843.597
2943.57	817.006
2946.18	787.088
2948.78	755.6
2951.39	723.117
2953.99	685.257
2956.59	648.339
2959.2	611.472
2961.8	575.887
2964.4	540.838
2967	510.165
2969.6	478.676
2972.19	450.768
2974.79	422.83
2977.39	394.223
2979.98	366.037
2982.58	336.633
2985.17	308.234
2987.76	279.328
2990.35	250.486
2992.94	223.081
2995.53	195.497
2998.12	171.029
3000.71	146.688
3003.3	123.831
3005.88	103.013
3008.47	85.0432
3011.05	69.6781
3013.64	54.726
3016.22	43.7353
3018.8	31.7318
3021.38	22.1533
3023.96	15.6884
3026.54	10.5889
3029.12	6.68747
3031.69	4.91287
3034.27	4.03751
3036.84	4.55235
3039.42	5.98802
3041.99	8.60256
3044.57	10.6782
3047.14	13.4047
3049.71	15.6022
3052.28	17.3949
3054.85	18.5533
3057.41	19.6547
3059.98	19.2344
3062.55	18.4748
3065.11	18.3137
3067.68	17.6553
3070.24	17.0373
3072.8	14.9573
3075.36	11.9332
3077.93	10.9372
3080.49	8.43771
3083.04	5.82335
3085.6	4.90309
3088.16	4.28577
3090.72	4.42128
3093.27	6.17396
3095.83	7.48434
3098.38	10.1557
3100.93	13.2101
3103.49	17.5181
3106.04	21.3481
3108.59	26.1288
3111.14	30.6383
3113.69	34.3407
3116.23	38.9113
3118.78	44.2469
3121.33	48.8973
3123.87	53.8498
3126.41	59.7827
3128.96	65.8038
3131.5	70.4459
3134.04	75.9246
3136.58	81.5333
3139.12	87.4222
3141.66	92.9771
3144.2	97.0174
3146.74	101.652
3149.27	105.631