File: data/Raman/poly_smoothed/Mb_20_23_40_1x_45s_532 nm_x100_100%_600 gr_mm_01.txt
#Acq. time (s)=	45
#Accumulations=	2
#Range (cm-¹)=	200...3150
#Windows=	2
#Auto scanning=	Off
#Autofocus=	Off
#Macrospot=	Off
#AutoExposure=	Off
#Spike filter=	Multiple accum.
#Delay time (s)=	0
#Binning=	1
#Readout mode=	Signal
#DeNoise=	Off
#ICS correction=	On
#Dark correction=	Off
#Inst. Process=	Off
#Detector Gain=	Best Dynamic Range
#Detector ADC=	20 kHz
#Detector temperature (°C)=	-69.85
#Instrument=	LabRAM HR Evol
#Detector=	Synapse
#Objective=	x100
#Grating=	600 gr/mm
#ND Filter=	100%
#Laser (nm)=	532
#Hole=	100.021
#Range=	Auto
#Laser Pol.=	No
#Raman. Pol.=	No
#Laser Pol. (°)=	-0.0007625
#Raman Pol. (°)=	89.9995
#Collection=	Microscope
#StageXY=	Marzhauser
#StageZ=	Marzhauser
#X (µm)=	-7094.3
#Y (µm)=	2190
#Z (µm)=	-74.8
#Full time(mm:ss)=	3:18
#Project=
#Sample=
#Site=
#Title=	Mb_20_23_40_2x_45s_532 nm_x100_100%_600 gr_mm
#Remark=
#Date=	13.07.2022 16:36
#Acquired=	13.07.2022 16:36:29
#Base:Fit=	10.08.2022 10:29:37
#Base:Sub=	10.08.2022 10:34:43
#Filter:Polynom=	16.08.2022 10:13:29
#AxisType[0]=Intens
#AxisUnit[0]=Cnt
#AxisType[1]=Spectr
#AxisUnit[1]=1/cm
200.563	55.1388
204.194	47.6784
207.821	39.7413
211.449	32.4684
215.074	25.2048
218.699	18.7565
222.321	13.9949
225.941	12.0536
229.562	8.52012
233.18	8.44342
236.796	5.40482
240.411	5.44861
244.026	4.76177
247.638	5.61802
251.248	4.97201
254.857	4.13296
258.465	9.59464
262.071	8.94248
265.678	8.16418
269.282	7.44301
272.884	7.70942
276.484	9.44267
280.084	10.2148
283.682	9.67028
287.276	10.0412
290.871	9.67528
294.465	9.76709
298.057	10.275
301.648	12.3606
305.237	12.1494
308.823	17.8886
312.41	20.2101
315.995	23.0193
319.579	26.5453
323.16	28.1287
326.741	29.1458
330.321	31.957
333.897	34.4492
337.474	35.5404
341.048	34.3653
344.622	32.4727
348.192	30.4235
351.764	30.1282
355.332	29.6752
358.901	27.4659
362.466	25.9045
366.03	24.132
369.594	22.8442
373.155	20.29
376.715	18.4663
380.273	17.1686
383.832	17.132
387.388	16.5928
390.942	15.5989
394.495	15.1567
398.047	17.6921
401.597	17.7247
405.145	20.9155
408.693	19.5482
412.239	20.2419
415.783	19.8818
419.327	20.4112
422.869	17.6974
426.409	16.4495
429.948	15.4296
433.486	16.0738
437.022	19.069
440.558	19.7915
444.089	20.7732
447.622	20.0965
451.153	21.3124
454.682	21.5713
458.208	19.8803
461.735	20.7064
465.259	21.7318
468.783	22.7173
472.306	24.0227
475.825	22.8794
479.346	26.6531
482.862	29.2871
486.38	33.632
489.894	37.0106
493.407	38.6216
496.92	37.6504
500.43	37.3513
503.939	36.4822
507.448	37.6883
510.954	35.7328
514.459	37.0068
517.962	38.7416
521.466	37.5204
524.966	37.4643
528.466	35.6106
531.964	34.7783
535.46	35.8295
538.955	34.9081
542.449	33.0126
545.942	31.1797
549.433	30.7656
552.923	30.5535
556.412	29.7572
559.899	29.0124
563.385	30.1091
566.867	30.5369
570.35	29.2704
573.832	27.4064
577.313	25.9175
580.79	24.5592
584.268	22.9668
587.745	18.707
591.218	16.2429
594.692	13.0509
598.164	11.0341
601.634	10.201
605.104	9.79764
608.57	7.88749
612.037	7.20022
615.501	7.55159
618.966	7.70114
622.427	5.8915
625.887	2.59818
629.348	2.19318
632.806	3.636
636.262	5.35417
639.716	5.71963
643.172	5.87628
646.624	5.47402
650.075	5.7767
653.524	5.92517
656.972	6.31008
660.419	6.57322
663.865	8.3203
667.309	8.42123
670.752	6.18839
674.194	7.32911
677.634	8.76227
681.073	8.91745
684.511	10.4266
687.947	11.6249
691.382	12.1062
694.816	12.2035
698.247	11.7871
701.678	10.3679
705.108	10.8937
708.534	12.1011
711.962	11.8238
715.388	14.023
718.81	13.3775
722.234	12.5058
725.654	11.2994
729.075	11.7927
732.492	14.2727
735.91	14.3487
739.325	18.0583
742.741	20.0043
746.153	21.9937
749.564	24.6268
752.976	26.1769
756.385	28.7751
759.792	32.7612
763.2	34.2173
766.604	36.2102
770.008	38.1411
773.41	38.8058
776.811	41.4973
780.21	40.9261
783.608	40.6529
787.005	43.1012
790.401	43.7859
793.795	45.2812
797.188	45.3329
800.58	46.3695
803.971	49.8559
807.36	51.9126
810.748	54.8483
814.135	59.4846
817.518	62.6549
820.902	64.1746
824.285	65.9063
827.665	66.2943
831.045	67.639
834.424	68.5731
837.8	67.3992
841.177	68.1012
844.55	66.1206
847.924	63.8172
851.295	58.7601
854.666	54.7914
858.034	50.4058
861.403	46.6533
864.769	41.5838
868.133	41.4125
871.498	40.4913
874.86	41.3068
878.221	39.5737
881.58	41.2751
884.938	43.16
888.297	44.8603
891.653	44.1709
895.007	46.3007
898.36	45.7541
901.712	45.5038
905.063	43.6436
908.412	43.4235
911.76	42.2465
915.107	40.5973
918.452	40.2233
921.797	39.4536
925.138	37.7394
928.48	34.6821
931.82	30.3377
935.16	29.0989
938.496	26.1259
941.833	24.5124
945.168	24.8419
948.5	22.761
951.834	24.2539
955.163	23.2452
958.494	22.423
961.821	23.041
965.15	25.5437
968.474	27.3662
971.8	27.5371
975.123	28.8221
978.446	31.6975
981.766	31.9117
985.084	32.4825
988.402	32.5674
991.72	31.0534
995.035	31.612
998.349	32.1828
1001.66	32.9113
1004.97	31.8031
1008.28	33.1313
1011.59	35.7575
1014.9	38.1598
1018.21	38.7548
1021.51	38.1926
1024.81	40.6381
1028.12	43.565
1031.42	46.3832
1034.72	49.8345
1038.02	51.2532
1041.31	52.9488
1044.61	56.7876
1047.91	60.7995
1051.2	64.1581
1054.49	66.2861
1057.78	66.9127
1061.07	66.0915
1064.36	63.8077
1067.65	60.5316
1070.93	57.2918
1074.22	53.0203
1077.5	52.1033
1080.78	49.7858
1084.06	46.8921
1087.34	46.0312
1090.62	45.2225
1093.9	45.2394
1097.17	45.3222
1100.45	44.4215
1103.72	45.4105
1106.99	46.3978
1110.27	47.7309
1113.53	46.6431
1116.8	46.0787
1120.07	46.4552
1123.33	46.8752
1126.6	48.4569
1129.86	46.7309
1133.12	43.8912
1136.38	41.6182
1139.64	38.3211
1142.9	34.5549
1146.16	29.1499
1149.41	24.9156
1152.67	20.9994
1155.92	16.8096
1159.17	12.1643
1162.42	8.26633
1165.67	6.14046
1168.92	5.61735
1172.16	8.12531
1175.41	8.79067
1178.65	7.02873
1181.9	8.26226
1185.14	8.93302
1188.38	7.91011
1191.62	11.1102
1194.86	11.048
1198.09	12.4785
1201.33	13.7965
1204.56	16.94
1207.8	18.8909
1211.03	21.8062
1214.26	26.1663
1217.49	31.7526
1220.71	35.1272
1223.94	39.2633
1227.16	46.1919
1230.39	50.2621
1233.61	54.7135
1236.83	60.2343
1240.05	67.6827
1243.27	75.7031
1246.49	82.2702
1249.71	85.3403
1252.92	87.9771
1256.14	87.6888
1259.35	90.4013
1262.56	93.4693
1265.77	96.3734
1268.98	99.9428
1272.19	104.397
1275.4	107.46
1278.6	112.445
1281.81	117.522
1285.01	123.855
1288.21	128.19
1291.41	132.978
1294.61	138.783
1297.81	144.459
1301.01	150.538
1304.2	156.104
1307.4	156.052
1310.59	158.777
1313.78	162.859
1316.97	163.748
1320.16	164.545
1323.35	161.423
1326.54	155.906
1329.72	150.646
1332.91	144.86
1336.09	140.513
1339.27	138.294
1342.45	134.352
1345.64	129.837
1348.81	126.806
1351.99	122.494
1355.17	117.41
1358.34	113.253
1361.51	110.489
1364.69	106.719
1367.86	104.239
1371.03	104.804
1374.2	104.467
1377.37	104.267
1380.53	103.32
1383.7	102.541
1386.86	103.147
1390.02	104.041
1393.19	104.118
1396.35	107.04
1399.51	109.764
1402.66	113.181
1405.82	120.313
1408.97	126.021
1412.13	135.022
1415.28	147.34
1418.43	160.078
1421.59	174.756
1424.73	188.969
1427.88	205.057
1431.03	220.863
1434.18	230.662
1437.32	242.891
1440.46	251.606
1443.61	259.257
1446.75	262.12
1449.89	262.501
1453.03	258.583
1456.16	251.535
1459.3	239.333
1462.44	228.344
1465.57	213.246
1468.7	196.054
1471.83	179.332
1474.96	161.697
1478.09	142.818
1481.22	125.553
1484.35	109.269
1487.47	92.3227
1490.6	80.9333
1493.72	70.7776
1496.84	64.8527
1499.96	59.6703
1503.08	55.5875
1506.2	53.8256
1509.32	50.3351
1512.44	46.1338
1515.55	44.0676
1518.66	42.7423
1521.78	41.5892
1524.89	41.9227
1528	43.1667
1531.11	43.6849
1534.21	46.3914
1537.32	49.2286
1540.43	52.4218
1543.53	53.8496
1546.63	56.0156
1549.74	57.6306
1552.84	59.0351
1555.94	60.6867
1559.03	61.6339
1562.13	62.4151
1565.23	66.0076
1568.32	72.0842
1571.42	77.8209
1574.51	82.071
1577.6	86.0049
1580.69	90.4172
1583.78	93.7304
1586.87	96.9072
1589.95	100.545
1593.04	104.707
1596.12	106.437
1599.21	109.84
1602.29	112.173
1605.37	113.744
1608.45	112.836
1611.53	114.158
1614.6	114.216
1617.68	115.862
1620.75	116.797
1623.83	115.598
1626.9	116.458
1629.97	116.757
1633.04	118.563
1636.11	120.664
1639.18	121.119
1642.25	122.597
1645.31	124.424
1648.38	125.214
1651.44	123.979
1654.5	124.996
1657.56	123.509
1660.62	120.973
1663.68	117.979
1666.74	114.486
1669.8	108.171
1672.85	100.867
1675.91	92.606
1678.96	85.4396
1682.01	77.5628
1685.06	70.8235
1688.11	64.6989
1691.16	57.9119
1694.21	51.1936
1697.25	45.4975
1700.3	40.8006
1703.34	37.6237
1706.39	35.9266
1709.43	34.8986
1712.47	32.4791
1715.51	30.963
1718.54	30.9866
1721.58	30.5357
1724.62	29.4343
1727.65	28.4961
1730.68	28.9112
1733.72	26.1327
1736.75	25.4194
1739.78	23.8405
1742.81	20.8594
1745.84	18.4451
1748.86	16.3911
1751.89	15.0353
1754.91	13.0923
1757.93	10.2592
1760.96	6.79318
1763.98	5.52229
1767	3.54335
1770.02	4.00691
1773.03	2.39176
1776.05	2.67991
1779.07	3.22852
1782.08	3.4634
1785.09	3.30896
1788.11	3.62465
1791.12	3.89549
1794.13	4.36089
1797.13	4.21226
1800.14	3.59913
1803.15	3.6112
1806.15	3.16793
1809.16	3.06733
1812.16	3.64731
1815.16	4.02661
1818.16	4.31263
1821.16	4.10714
1824.16	3.64491
1827.16	3.69137
1830.16	3.37434
1833.15	3.64027
1836.14	2.65541
1839.14	2.93791
1842.13	3.09283
1845.12	1.72556
1848.11	2.04139
1851.1	1.79959
1854.08	1.63519
1857.07	1.18604
1860.05	1.11727
1863.04	0.718174
1866.02	0.188804
1869	0.246048
1871.98	0.911919
1874.96	1.57919
1877.94	2.80646
1880.92	4.01705
1882.51	4.47304
1885.5	6.39723
1888.48	7.08254
1891.47	8.09235
1894.46	7.44394
1897.44	7.77997
1900.42	6.8347
1903.41	6.44307
1906.39	6.61487
1909.37	5.60328
1912.35	6.18683
1915.32	5.10856
1918.3	4.45685
1921.27	4.44882
1924.25	4.25056
1927.22	4.07559
1930.19	3.39951
1933.17	3.25773
1936.14	2.36435
1939.11	1.8245
1942.07	2.3865
1945.04	4.13234
1948.01	5.33332
1950.97	4.80197
1953.93	4.72139
1956.9	2.951
1959.86	3.82354
1962.82	2.665
1965.78	1.3194
1968.74	1.20389
1971.69	0.891669
1974.65	1.53404
1977.6	2.65777
1980.56	3.39874
1983.51	3.77935
1986.46	3.46776
1989.41	3.53218
1992.36	4.62343
1995.31	5.15525
1998.26	5.71278
2001.2	5.16571
2004.15	6.1801
2007.09	6.80344
2010.04	7.39235
2012.98	8.45085
2015.92	9.64663
2018.86	8.78245
2021.8	9.34453
2024.73	10.4237
2027.67	11.0403
2030.61	11.9852
2033.54	13.1188
2036.47	13.7985
2039.4	15.7431
2042.33	15.7946
2045.27	17.2184
2048.19	17.7736
2051.12	18.6983
2054.05	17.5252
2056.97	16.6655
2059.9	18.0874
2062.82	17.4437
2065.74	17.6576
2068.67	16.7162
2071.59	17.858
2074.51	18.2507
2077.42	18.2616
2080.34	18.417
2083.26	19.4573
2086.17	18.9009
2089.09	16.8354
2092	18.2736
2094.91	19.4057
2097.82	19.4904
2100.73	20.0959
2103.64	22.2986
2106.55	23.5887
2109.45	25.1376
2112.36	26.0114
2115.26	27.3004
2118.17	29.7358
2121.07	31.9768
2123.97	34.1252
2126.87	37.1948
2129.77	39.541
2132.67	42.1994
2135.56	45.4544
2138.46	47.7595
2141.35	50.2702
2144.25	52.2167
2147.14	55.6513
2150.03	59.0847
2152.92	63.0522
2155.81	64.2973
2158.7	67.0715
2161.59	70.7062
2164.47	73.0296
2167.36	73.5378
2170.24	74.7783
2173.13	76.0054
2176.01	76.0504
2178.89	75.769
2181.77	74.1596
2184.65	73.2433
2187.53	70.6915
2190.4	68.6111
2193.28	66.6393
2196.16	63.9331
2199.03	59.2365
2201.9	53.9091
2204.77	51.581
2207.64	46.973
2210.51	42.7931
2213.38	40.3535
2216.25	37.9554
2219.12	35.0515
2221.98	33.5048
2224.85	32.1598
2227.71	31.5176
2230.57	30.5611
2233.43	28.2869
2236.29	26.3307
2239.15	24.7833
2242.01	22.8028
2244.87	22.1162
2247.72	20.8707
2250.58	19.2802
2253.43	18.6221
2256.29	18.8633
2259.14	17.4396
2261.99	17.2202
2264.84	16.701
2267.69	16.5813
2270.53	16.6077
2273.38	16.0945
2276.23	17.0761
2279.07	16.8686
2281.91	17.181
2284.76	17.0297
2287.6	17.4823
2290.44	15.8987
2293.28	15.4813
2296.12	14.9634
2298.96	16.6288
2301.79	16.6433
2304.63	17.3983
2307.46	16.0838
2310.3	14.8929
2313.13	13.7181
2315.96	12.8334
2318.79	11.2182
2321.62	11.2263
2324.45	11.6126
2327.27	11.1765
2330.1	10.813
2332.92	10.2776
2335.75	10.8176
2338.57	10.5572
2341.39	10.079
2344.21	9.73091
2347.04	9.10767
2349.85	8.07369
2352.67	6.53335
2355.49	6.15828
2358.3	4.93706
2361.12	4.08903
2363.93	5.49262
2366.75	6.45748
2369.56	5.76681
2372.37	3.9254
2375.18	4.01472
2377.99	2.53463
2380.8	1.98003
2383.6	1.83679
2386.41	1.90243
2389.21	3.53144
2392.02	4.96519
2394.82	6.69753
2397.62	6.761
2400.42	6.6977
2403.22	6.90639
2406.02	7.23072
2408.82	8.19653
2411.62	9.59588
2414.41	11.1288
2417.21	10.8186
2420	12.7485
2422.79	12.9171
2425.59	13.7055
2428.38	12.8653
2431.17	13.0289
2433.95	13.0317
2436.74	12.319
2439.53	11.0592
2442.31	9.37009
2445.1	8.48403
2447.88	6.2288
2450.67	5.77768
2453.45	6.69096
2456.23	6.74045
2459.01	5.73555
2461.79	5.51488
2464.57	4.49326
2467.34	4.73046
2470.12	4.32116
2472.89	3.83014
2475.67	4.80793
2478.44	6.60163
2481.21	7.58041
2483.98	7.50195
2486.75	6.04687
2489.52	5.38276
2492.29	4.9977
2495.05	4.33906
2497.82	2.7952
2500.58	2.71637
2503.35	3.08093
2506.11	2.78817
2508.87	1.8719
2511.63	1.04608
2514.39	1.7784
2517.15	2.6007
2519.91	2.94108
2522.67	3.48071
2525.42	4.05686
2528.18	2.05833
2530.93	2.2363
2533.69	4.56863
2536.44	4.961
2539.19	4.91641
2541.94	7.28935
2544.69	8.60058
2547.44	8.45399
2550.18	8.10588
2552.93	8.01632
2555.67	8.27473
2558.42	8.57474
2561.16	9.16821
2563.9	9.81638
2566.64	12.0053
2569.38	12.2209
2572.12	13.838
2574.86	11.9901
2577.6	12.7128
2580.33	12.4261
2583.07	12.5491
2585.8	11.3817
2588.54	10.6583
2591.27	9.50207
2594	9.13543
2596.73	9.83304
2599.46	10.9289
2602.19	11.4265
2604.92	11.466
2607.64	11.8639
2610.37	11.468
2613.09	10.4657
2615.82	10.036
2618.54	11.8389
2621.26	12.5476
2623.98	11.1217
2626.7	11.0014
2629.42	10.3956
2632.14	9.9378
2634.86	8.46138
2637.57	7.875
2640.29	7.63741
2643	6.67804
2645.71	6.11185
2648.43	5.07807
2651.14	4.78107
2653.85	4.01598
2656.56	4.58656
2659.26	6.11722
2661.97	6.7965
2664.68	6.48745
2667.38	6.19151
2670.09	7.2127
2672.79	7.28764
2675.49	7.93787
2678.19	8.90063
2680.89	10.2571
2683.59	11.0323
2686.29	10.1599
2688.99	10.6682
2691.69	11.8473
2694.38	13.792
2697.08	13.8842
2699.77	15.5834
2702.46	18.902
2705.15	20.1462
2707.85	22.5753
2710.54	23.4325
2713.22	24.8519
2715.91	25.9022
2718.6	27.2521
2721.29	27.4658
2723.97	28.0174
2726.66	27.1532
2729.34	24.984
2732.02	23.6425
2734.7	23.6569
2737.38	21.1298
2740.06	19.9519
2742.74	17.9499
2745.42	15.4147
2748.09	12.675
2750.77	10.1829
2753.45	8.4871
2756.12	7.1759
2758.79	4.96686
2761.46	3.78877
2764.14	3.34527
2766.8	3.31385
2769.47	2.51059
2772.14	1.75505
2774.81	2.23846
2777.48	1.20948
2780.14	1.75509
2782.8	1.14866
2785.47	-0.951265
2788.13	-1.86861
2790.79	-2.7363
2793.45	-2.81924
2796.11	-2.40941
2798.77	-1.65267
2801.43	-1.16068
2804.09	0.0547145
2806.74	1.41793
2809.4	0.631121
2812.05	0.398063
2814.71	-0.449564
2817.36	3.25869
2820.01	9.87926
2822.66	20.4184
2825.31	33.422
2827.96	49.8909
2830.6	67.1607
2833.25	86.2038
2835.9	104.954
2838.54	127.402
2841.18	149.793
2843.83	174.479
2846.47	198.769
2849.11	223.55
2851.75	247.834
2854.39	274.568
2857.03	301.526
2859.66	326.385
2862.3	346.421
2864.94	366.447
2867.57	383.939
2870.2	398.584
2872.84	409.426
2875.47	418.797
2878.1	429.822
2880.73	442.576
2883.36	454.782
2885.99	467.812
2888.61	479.744
2891.24	491.871
2893.86	504.662
2896.49	516.234
2899.11	527.404
2901.73	540.004
2904.36	554.639
2906.98	570.802
2909.6	587.507
2912.21	604.879
2914.83	622.324
2917.45	638.331
2920.07	653.373
2922.68	663.951
2925.29	668.93
2927.91	672.109
2930.52	670.71
2933.13	664.621
2935.74	654.916
2938.35	641.186
2940.96	624.49
2943.57	606.644
2946.18	586.041
2948.78	561.843
2951.39	537.682
2953.99	513.424
2956.59	489.49
2959.2	461.92
2961.8	434.662
2964.4	409.333
2967	385.02
2969.6	361.001
2972.19	339.075
2974.79	317.461
2977.39	296.523
2979.98	275.523
2982.58	253.253
2985.17	231.272
2987.76	208.627
2990.35	187.155
2992.94	168.038
2995.53	146.79
2998.12	128.046
3000.71	110.269
3003.3	93.7941
3005.88	81.7699
3008.47	68.663
3011.05	57.7571
3013.64	48.3896
3016.22	41.1169
3018.8	33.3541
3021.38	25.5405
3023.96	19.5534
3026.54	15.0787
3029.12	11.8325
3031.69	8.47138
3034.27	5.61001
3036.84	5.22911
3039.42	4.79939
3041.99	3.69102
3044.57	3.82637
3047.14	3.38777
3049.71	4.61197
3052.28	5.69561
3054.85	6.30609
3057.41	7.12793
3059.98	6.36172
3062.55	6.32286
3065.11	5.36272
3067.68	5.99891
3070.24	5.58784
3072.8	5.43088
3075.36	5.36462
3077.93	4.30348
3080.49	4.30331
3083.04	4.28524
3085.6	3.05399
3088.16	2.71423
3090.72	3.60941
3093.27	4.51651
3095.83	5.53618
3098.38	7.4589
3100.93	8.3833
3103.49	10.0531
3106.04	12.1567
3108.59	14.3444
3111.14	16.5183
3113.69	19.6017
3116.23	21.5181
3118.78	23.9876
3121.33	27.1856
3123.87	29.2777
3126.41	31.5329
3128.96	34.2283
3131.5	38.858
3134.04	43.1161
3136.58	46.5139
3139.12	50.3882
3141.66	54.4291
3144.2	58.5084
3146.74	63.489
3149.27	69.0888