File: data/Raman/poly_smoothed/Mb_20_23_33_1x_45s_532 nm_x100_100%_600 gr_mm_01.txt
#Acq. time (s)=	45
#Accumulations=	2
#Range (cm-¹)=	200...3150
#Windows=	2
#Auto scanning=	Off
#Autofocus=	Off
#Macrospot=	Off
#AutoExposure=	Off
#Spike filter=	Multiple accum.
#Delay time (s)=	0
#Binning=	1
#Readout mode=	Signal
#DeNoise=	Off
#ICS correction=	On
#Dark correction=	Off
#Inst. Process=	Off
#Detector Gain=	Best Dynamic Range
#Detector ADC=	20 kHz
#Detector temperature (°C)=	-69.85
#Instrument=	LabRAM HR Evol
#Detector=	Synapse
#Objective=	x100
#Grating=	600 gr/mm
#ND Filter=	100%
#Laser (nm)=	532
#Hole=	100.021
#Range=	Auto
#Laser Pol.=	No
#Raman. Pol.=	No
#Laser Pol. (°)=	-0.0007625
#Raman Pol. (°)=	89.9995
#Collection=	Microscope
#StageXY=	Marzhauser
#StageZ=	Marzhauser
#X (µm)=	-6957.3
#Y (µm)=	1960.4
#Z (µm)=	-75.15
#Full time(mm:ss)=	3:18
#Project=
#Sample=
#Site=
#Title=	Mb_20_23_33_2x_45s_532 nm_x100_100%_600 gr_mm
#Remark=
#Date=	13.07.2022 15:42
#Acquired=	13.07.2022 15:42:40
#Base:Fit=	10.08.2022 10:29:37
#Base:Sub=	10.08.2022 10:34:43
#Filter:Polynom=	16.08.2022 10:13:29
#AxisType[0]=Intens
#AxisUnit[0]=Cnt
#AxisType[1]=Spectr
#AxisUnit[1]=1/cm
200.563	64.4539
204.194	56.0616
207.821	50.1446
211.449	47.4918
215.074	44.8997
218.699	42.6725
222.321	40.3152
225.941	37.7058
229.562	34.2358
233.18	34.6053
236.796	30.3926
240.411	27.1552
244.026	23.7292
247.638	22.0774
251.248	19.4473
254.857	17.3678
258.465	14.2914
262.071	12.2082
265.678	11.623
269.282	11.9347
272.884	10.6848
276.484	6.38549
280.084	5.55318
283.682	3.60578
287.276	1.55597
290.871	3.15055
294.465	4.84709
298.057	6.1265
301.648	5.80932
305.237	6.66436
308.823	6.96555
312.41	9.07701
315.995	8.51782
319.579	10.9344
323.16	12.2767
326.741	11.5362
330.321	13.4617
333.897	16.2832
337.474	16.1172
341.048	19.2761
344.622	20.7207
348.192	21.293
351.764	20.7951
355.332	21.9465
358.901	21.7217
362.466	19.1556
366.03	19.7471
369.594	18.6757
373.155	18.1371
376.715	18.3134
380.273	19.0319
383.832	17.5002
387.388	16.5885
390.942	16.0738
394.495	15.962
398.047	16.549
401.597	16.7913
405.145	19.3415
408.693	19.8108
412.239	21.0503
415.783	23.6105
419.327	25.5105
422.869	27.3057
426.409	28.2152
429.948	25.7792
433.486	25.5177
437.022	26.6864
440.558	26.5408
444.089	24.4419
447.622	23.0432
451.153	23.1508
454.682	24.1222
458.208	23.7505
461.735	22.4363
465.259	21.0512
468.783	22.6701
472.306	23.6844
475.825	24.5923
479.346	28.8972
482.862	29.981
486.38	30.591
489.894	33.4404
493.407	35.0482
496.92	36.123
500.43	38.8945
503.939	42.0632
507.448	41.0877
510.954	42.4875
514.459	41.2886
517.962	40.4584
521.466	42.5071
524.966	39.7424
528.466	39.591
531.964	40.8295
535.46	40.0704
538.955	36.7894
542.449	36.5985
545.942	33.31
549.433	30.0948
552.923	26.618
556.412	24.7741
559.899	21.6499
563.385	19.4206
566.867	18.4764
570.35	15.3166
573.832	14.0105
577.313	11.0421
580.79	9.0662
584.268	7.73348
587.745	5.69265
591.218	4.34801
594.692	1.86964
598.164	2.82411
601.634	3.90208
605.104	3.31968
608.57	3.64593
612.037	3.69301
615.501	5.96674
618.966	7.89195
622.427	5.39034
625.887	6.40508
629.348	7.91749
632.806	6.29393
636.262	7.20469
639.716	5.33706
643.172	4.15038
646.624	5.45265
650.075	8.91706
653.524	7.03829
656.972	6.52598
660.419	6.53778
663.865	7.60923
667.309	8.19074
670.752	7.53166
674.194	6.68929
677.634	6.35681
681.073	8.06431
684.511	7.50077
687.947	6.73184
691.382	7.66111
694.816	6.95015
698.247	9.82393
701.678	11.6479
705.108	13.855
708.534	12.6021
711.962	12.9499
715.388	11.1018
718.81	10.1059
722.234	8.03899
725.654	8.35038
729.075	10.7807
732.492	13.0415
735.91	14.3723
739.325	16.3803
742.741	20.7952
746.153	25.5769
749.564	29.2608
752.976	33.2335
756.385	38.1389
759.792	43.9395
763.2	48.0296
766.604	51.0181
770.008	54.2803
773.41	58.455
776.811	63.3083
780.21	66.062
783.608	69.2328
787.005	70.8977
790.401	71.5853
793.795	71.1341
797.188	70.8962
800.58	70.9895
803.971	71.8564
807.36	72.5329
810.748	76.6113
814.135	78.9456
817.518	79.734
820.902	79.8712
824.285	81.4404
827.665	81.9587
831.045	83.1108
834.424	84.4279
837.8	85.9344
841.177	85.9979
844.55	84.6021
847.924	83.5241
851.295	83.4196
854.666	85.2017
858.034	87.2962
861.403	89.9333
864.769	90.3679
868.133	90.9303
871.498	92.7121
874.86	93.8153
878.221	91.4271
881.58	88.8992
884.938	85.91
888.297	84.8587
891.653	82.7751
895.007	80.3609
898.36	76.9783
901.712	74.4168
905.063	71.3338
908.412	67.9059
911.76	64.9524
915.107	61.5104
918.452	59.2718
921.797	55.7975
925.138	54.033
928.48	52.4582
931.82	51.9948
935.16	50.9122
938.496	48.7132
941.833	46.9067
945.168	43.4032
948.5	40.2678
951.834	38.9211
955.163	35.0491
958.494	28.4459
961.821	23.9876
965.15	20.6088
968.474	22.0341
971.8	20.4273
975.123	21.2525
978.446	22.8568
981.766	23.3039
985.084	21.6233
988.402	20.1077
991.72	19.9962
995.035	20.4621
998.349	19.7013
1001.66	23.1704
1004.97	26.939
1008.28	28.4117
1011.59	31.098
1014.9	30.9992
1018.21	28.083
1021.51	27.9264
1024.81	38.3596
1028.12	54.5645
1031.42	70.0705
1034.72	85.0167
1038.02	99.0506
1041.31	114.857
1044.61	128.633
1047.91	140.263
1051.2	148.394
1054.49	153.669
1057.78	157.402
1061.07	158.468
1064.36	157.278
1067.65	157.601
1070.93	153.844
1074.22	146.867
1077.5	139.24
1080.78	128.944
1084.06	116.571
1087.34	98.765
1090.62	90.7352
1093.9	86.0112
1097.17	83.7835
1100.45	87.0821
1103.72	97.7607
1106.99	105.097
1110.27	111.983
1113.53	113.91
1116.8	114.441
1120.07	113.712
1123.33	110.468
1126.6	103.897
1129.86	97.6789
1133.12	90.3348
1136.38	82.1612
1139.64	74.3957
1142.9	66.1216
1146.16	56.7921
1149.41	46.4454
1152.67	32.9727
1155.92	21.3585
1159.17	8.09491
1162.42	-2.64397
1165.67	-9.55131
1168.92	-8.18139
1172.16	-2.84362
1175.41	0.27419
1178.65	0.152297
1181.9	0.0897642
1185.14	-2.58506
1188.38	-2.08324
1191.62	-2.21787
1194.86	-2.85967
1198.09	-2.76411
1201.33	-0.39796
1204.56	0.523116
1207.8	4.06482
1211.03	6.61575
1214.26	7.6686
1217.49	11.7257
1220.71	17.7229
1223.94	25.1063
1227.16	30.2602
1230.39	34.7046
1233.61	40.5763
1236.83	46.7944
1240.05	51.8357
1243.27	59.0661
1246.49	66.006
1249.71	66.2211
1252.92	62.7635
1256.14	65.4561
1259.35	74.6079
1262.56	92.6917
1265.77	112.089
1268.98	136.124
1272.19	158.013
1275.4	180.855
1278.6	202.595
1281.81	219.398
1285.01	235.157
1288.21	248.48
1291.41	258.273
1294.61	267.031
1297.81	271.487
1301.01	272.663
1304.2	267.974
1307.4	261.182
1310.59	252.954
1313.78	239.196
1316.97	224.502
1320.16	205.301
1323.35	184.461
1326.54	160.737
1329.72	137.646
1332.91	124.033
1336.09	122.528
1339.27	123.354
1342.45	122.039
1345.64	120.197
1348.81	120.007
1351.99	117.942
1355.17	113.781
1358.34	111.796
1361.51	110.029
1364.69	107.943
1367.86	105.565
1371.03	103.226
1374.2	99.9036
1377.37	94.7193
1380.53	94.2049
1383.7	95.9582
1386.86	97.9661
1390.02	100.252
1393.19	99.6113
1396.35	99.1746
1399.51	105.432
1402.66	120.353
1405.82	143.603
1408.97	174.565
1412.13	209.207
1415.28	245.91
1418.43	284.691
1421.59	324.367
1424.73	365.363
1427.88	405.244
1431.03	442.134
1434.18	478.066
1437.32	507.228
1440.46	525.652
1443.61	537.426
1446.75	542.534
1449.89	538.832
1453.03	526.366
1456.16	506.999
1459.3	479.776
1462.44	444.702
1465.57	401.608
1468.7	356.033
1471.83	307.98
1474.96	266.348
1478.09	230.297
1481.22	198.539
1484.35	169.318
1487.47	141.14
1490.6	116.219
1493.72	93.2962
1496.84	76.499
1499.96	62.9857
1503.08	55.478
1506.2	49.8801
1509.32	47.1832
1512.44	43.7134
1515.55	42.6692
1518.66	41.476
1521.78	43.0463
1524.89	44.9627
1528	45.1651
1531.11	46.7438
1534.21	48.5598
1537.32	50.8005
1540.43	53.3255
1543.53	56.159
1546.63	58.2726
1549.74	61.6622
1552.84	63.3852
1555.94	65.1058
1559.03	67.2415
1562.13	68.2689
1565.23	69.7438
1568.32	73.7031
1571.42	76.5664
1574.51	81.9165
1577.6	87.6283
1580.69	94.8719
1583.78	99.4399
1586.87	104.528
1589.95	108.962
1593.04	111.877
1596.12	112.843
1599.21	112.916
1602.29	112.967
1605.37	112.471
1608.45	112.82
1611.53	110.704
1614.6	107.708
1617.68	107.061
1620.75	105.784
1623.83	104.696
1626.9	103.054
1629.97	99.3012
1633.04	98.1528
1636.11	99.0775
1639.18	100.199
1642.25	102.257
1645.31	104.897
1648.38	107.01
1651.44	110.814
1654.5	111.907
1657.56	111.56
1660.62	110.911
1663.68	109.937
1666.74	106.817
1669.8	100.544
1672.85	97.1069
1675.91	92.0539
1678.96	86.0365
1682.01	79.2012
1685.06	72.2763
1688.11	67.8459
1691.16	63.3124
1694.21	59.306
1697.25	56.9488
1700.3	53.6777
1703.34	51.0752
1706.39	50.3175
1709.43	49.608
1712.47	48.0936
1715.51	46.3395
1718.54	45.5608
1721.58	47.0303
1724.62	47.8029
1727.65	47.4249
1730.68	45.8262
1733.72	45.4922
1736.75	44.1347
1739.78	41.4563
1742.81	37.1654
1745.84	33.458
1748.86	31.4486
1751.89	27.7884
1754.91	23.7253
1757.93	20.3414
1760.96	18.2594
1763.98	14.9338
1767	12.2897
1770.02	9.81508
1773.03	8.62701
1776.05	6.09985
1779.07	5.29186
1782.08	4.25885
1785.09	3.14218
1788.11	2.80321
1791.12	2.36242
1794.13	3.18274
1797.13	3.91331
1800.14	4.49752
1803.15	3.76944
1806.15	2.89327
1809.16	2.66809
1812.16	2.36142
1815.16	0.184653
1818.16	-0.391349
1821.16	0.431692
1824.16	-0.597991
1827.16	-0.983755
1830.16	-1.78547
1833.15	-1.93332
1836.14	-1.4976
1839.14	-0.903407
1842.13	-0.718207
1845.12	-0.913387
1848.11	-0.755639
1851.1	-0.103237
1854.08	0.788745
1857.07	1.23345
1860.05	2.90866
1863.04	2.20519
1866.02	3.68631
1869	4.63011
1871.98	6.39362
1874.96	7.43289
1877.94	8.34128
1880.92	8.19376
1882.51	8.27347
1885.5	7.77785
1888.48	6.71252
1891.47	8.53219
1894.46	7.9374
1897.44	7.5247
1900.42	6.50408
1903.41	5.12217
1906.39	5.36668
1909.37	3.99039
1912.35	3.36094
1915.32	3.4263
1918.3	3.1713
1921.27	3.86322
1924.25	5.4032
1927.22	6.82233
1930.19	8.34944
1933.17	9.40812
1936.14	10.4729
1939.11	12.0017
1942.07	12.9127
1945.04	15.3177
1948.01	15.4286
1950.97	16.2603
1953.93	17.0723
1956.9	17.8974
1959.86	19.6055
1962.82	20.8378
1965.78	20.9947
1968.74	20.832
1971.69	20.3115
1974.65	20.0621
1977.6	19.1505
1980.56	17.8207
1983.51	17.5979
1986.46	16.9608
1989.41	16.8494
1992.36	17.202
1995.31	17.9849
1998.26	18.1681
2001.2	17.2655
2004.15	15.075
2007.09	15.1911
2010.04	16.2842
2012.98	16.2609
2015.92	16.3692
2018.86	17.1896
2021.8	18.3257
2024.73	18.9758
2027.67	18.8493
2030.61	19.0293
2033.54	19.0647
2036.47	18.6715
2039.4	20.2232
2042.33	21.1793
2045.27	20.417
2048.19	19.4034
2051.12	18.6326
2054.05	19.4906
2056.97	19.611
2059.9	21.3027
2062.82	21.537
2065.74	20.756
2068.67	20.8061
2071.59	21.0529
2074.51	22.3003
2077.42	22.8064
2080.34	23.9419
2083.26	23.7923
2086.17	24.1361
2089.09	23.8257
2092	25.8367
2094.91	24.3433
2097.82	24.4296
2100.73	24.8655
2103.64	24.4577
2106.55	26.0787
2109.45	27.1839
2112.36	28.2587
2115.26	27.8391
2118.17	29.4774
2121.07	30.0679
2123.97	32.3717
2126.87	32.9464
2129.77	35.3881
2132.67	37.2678
2135.56	39.5833
2138.46	42.9976
2141.35	46.1681
2144.25	48.7489
2147.14	50.9277
2150.03	53.273
2152.92	55.2626
2155.81	56.6313
2158.7	60.9373
2161.59	63.8059
2164.47	65.209
2167.36	66.831
2170.24	70.6096
2173.13	71.7103
2176.01	72.1187
2178.89	72.558
2181.77	71.2824
2184.65	69.902
2187.53	69.1362
2190.4	66.5167
2193.28	64.7221
2196.16	62.9177
2199.03	59.8931
2201.9	57.1047
2204.77	54.629
2207.64	52.3595
2210.51	49.6594
2213.38	47.7945
2216.25	44.9623
2219.12	41.1968
2221.98	37.7256
2224.85	34.891
2227.71	33.5137
2230.57	31.2455
2233.43	28.9603
2236.29	29.2972
2239.15	27.9918
2242.01	26.8612
2244.87	24.8186
2247.72	24.9867
2250.58	24.8672
2253.43	24.4407
2256.29	24.8686
2259.14	25.2902
2261.99	24.6791
2264.84	25.851
2267.69	25.3056
2270.53	26.5452
2273.38	26.0562
2276.23	25.0698
2279.07	25.1579
2281.91	25.3506
2284.76	24.9612
2287.6	23.6967
2290.44	21.5074
2293.28	18.6155
2296.12	18.5914
2298.96	17.3279
2301.79	16.9028
2304.63	16.2212
2307.46	15.7495
2310.3	16.2074
2313.13	16.3246
2315.96	16.4643
2318.79	15.2606
2321.62	14.3749
2324.45	13.5589
2327.27	13.795
2330.1	12.8262
2332.92	13.167
2335.75	12.4678
2338.57	10.364
2341.39	11.3223
2344.21	10.4919
2347.04	8.89446
2349.85	8.66739
2352.67	9.6882
2355.49	9.12162
2358.3	6.85726
2361.12	4.31632
2363.93	4.35243
2366.75	4.67495
2369.56	3.74376
2372.37	2.7632
2375.18	1.51531
2377.99	1.33214
2380.8	2.1801
2383.6	0.687235
2386.41	0.808973
2389.21	1.13374
2392.02	2.56021
2394.82	3.15342
2397.62	3.40399
2400.42	4.40417
2403.22	5.41757
2406.02	6.31943
2408.82	8.44119
2411.62	9.63418
2414.41	9.9527
2417.21	10.8402
2420	12.3519
2422.79	12.6574
2425.59	11.8755
2428.38	10.6893
2431.17	10.7233
2433.95	10.8379
2436.74	9.60036
2439.53	9.03626
2442.31	8.01101
2445.1	6.75302
2447.88	6.51954
2450.67	7.84205
2453.45	7.73137
2456.23	8.59164
2459.01	7.99134
2461.79	5.80353
2464.57	5.27868
2467.34	4.68546
2470.12	4.03556
2472.89	3.09567
2475.67	2.15885
2478.44	2.6482
2481.21	0.291034
2483.98	0.996413
2486.75	0.180256
2489.52	-0.664848
2492.29	-0.891999
2495.05	-1.02703
2497.82	-1.4172
2500.58	-1.22783
2503.35	-2.68989
2506.11	-1.87513
2508.87	-1.02226
2511.63	-0.00981173
2514.39	1.75029
2517.15	2.83352
2519.91	3.83634
2522.67	5.01225
2525.42	5.90303
2528.18	5.88009
2530.93	5.53119
2533.69	5.9822
2536.44	6.01696
2539.19	5.50726
2541.94	5.26473
2544.69	6.05164
2547.44	5.20385
2550.18	4.99562
2552.93	6.30696
2555.67	7.11737
2558.42	7.26539
2561.16	7.40128
2563.9	6.9054
2566.64	7.80585
2569.38	8.48434
2572.12	7.83651
2574.86	9.52194
2577.6	10.2788
2580.33	10.6765
2583.07	11.0066
2585.8	12.4031
2588.54	14.7164
2591.27	15.4773
2594	16.0431
2596.73	16.8402
2599.46	16.4599
2602.19	16.0339
2604.92	15.0967
2607.64	14.8715
2610.37	13.7455
2613.09	13.9305
2615.82	13.4635
2618.54	14.2815
2621.26	16.1418
2623.98	16.5548
2626.7	16.3165
2629.42	16.7554
2632.14	17.2651
2634.86	18.3605
2637.57	17.8502
2640.29	18.8023
2643	20.7004
2645.71	21.8408
2648.43	24.2376
2651.14	26.1867
2653.85	28.5695
2656.56	31.0787
2659.26	31.6306
2661.97	31.7024
2664.68	30.9366
2667.38	30.2929
2670.09	29.8652
2672.79	29.1309
2675.49	28.2965
2678.19	27.8906
2680.89	27.9591
2683.59	28.8127
2686.29	30.3732
2688.99	32.662
2691.69	34.4134
2694.38	39.1193
2697.08	43.7957
2699.77	50.1221
2702.46	57.3774
2705.15	63.5018
2707.85	70.7021
2710.54	76.6137
2713.22	82.0978
2715.91	87.4583
2718.6	90.4565
2721.29	93.2013
2723.97	93.5743
2726.66	90.8757
2729.34	86.9097
2732.02	82.5967
2734.7	77.646
2737.38	71.5211
2740.06	64.145
2742.74	54.7402
2745.42	46.4856
2748.09	37.4422
2750.77	30.4159
2753.45	23.0175
2756.12	16.4048
2758.79	12.9778
2761.46	10.5718
2764.14	7.50162
2766.8	6.06422
2769.47	4.20749
2772.14	1.97094
2774.81	1.0232
2777.48	1.48556
2780.14	1.87626
2782.8	1.31303
2785.47	1.37362
2788.13	2.22443
2790.79	2.304
2793.45	3.10775
2796.11	4.03692
2798.77	5.82076
2801.43	4.85539
2804.09	0.600544
2806.74	-6.06383
2809.4	-16.1131
2812.05	-19.0968
2814.71	-7.87163
2817.36	19.2459
2820.01	64.4674
2822.66	126.225
2825.31	199.251
2827.96	281.074
2830.6	368.893
2833.25	459.927
2835.9	551.836
2838.54	641.273
2841.18	728.544
2843.83	805.102
2846.47	875.615
2849.11	952.047
2851.75	1039.6
2854.39	1127.29
2857.03	1208.64
2859.66	1278.37
2862.3	1335.52
2864.94	1375.25
2867.57	1397.08
2870.2	1408.46
2872.84	1413.2
2875.47	1418.61
2878.1	1427.81
2880.73	1438.68
2883.36	1448.56
2885.99	1453.3
2888.61	1450.38
2891.24	1440.47
2893.86	1423.08
2896.49	1399.62
2899.11	1370.43
2901.73	1336.97
2904.36	1302.9
2906.98	1271.63
2909.6	1251.35
2912.21	1247.71
2914.83	1257.65
2917.45	1265.09
2920.07	1264.02
2922.68	1254.27
2925.29	1237.06
2927.91	1214.65
2930.52	1187.81
2933.13	1156.83
2935.74	1124.65
2938.35	1087.35
2940.96	1043.39
2943.57	996.018
2946.18	943.128
2948.78	889.322
2951.39	834.299
2953.99	776.259
2956.59	720.106
2959.2	665.167
2961.8	613.409
2964.4	564.511
2967	521.163
2969.6	483.466
2972.19	447.936
2974.79	414.268
2977.39	379.733
2979.98	344.796
2982.58	309.153
2985.17	275.083
2987.76	242.032
2990.35	211.844
2992.94	184.831
2995.53	158.75
2998.12	135.996
3000.71	114.946
3003.3	94.4148
3005.88	78.7089
3008.47	62.7356
3011.05	49.6904
3013.64	38.9145
3016.22	28.1003
3018.8	19.9829
3021.38	12.2897
3023.96	6.02361
3026.54	1.36448
3029.12	-1.15851
3031.69	-1.5512
3034.27	-1.53334
3036.84	-1.9001
3039.42	-0.844587
3041.99	-0.0482346
3044.57	2.38057
3047.14	3.94919
3049.71	6.95922
3052.28	8.31649
3054.85	10.2389
3057.41	11.8988
3059.98	13.5587
3062.55	13.6587
3065.11	13.91
3067.68	14.889
3070.24	14.4497
3072.8	14.4245
3075.36	13.6053
3077.93	13.2865
3080.49	12.1139
3083.04	12.0376
3085.6	11.3808
3088.16	11.5836
3090.72	12.3421
3093.27	16.1454
3095.83	17.5646
3098.38	19.8006
3100.93	22.5982
3103.49	26.2776
3106.04	30.7402
3108.59	36.1315
3111.14	40.4957
3113.69	45.4285
3116.23	51.4653
3118.78	57.0294
3121.33	62.4124
3123.87	68.5296
3126.41	75.5584
3128.96	81.1468
3131.5	87.8424
3134.04	94.619
3136.58	101.676
3139.12	108.498
3141.66	116.85
3144.2	124.779
3146.74	132.469
3149.27	143.57