File: data/Raman/poly_smoothed/Mb_20_23_32_1x_45s_532 nm_x100_100%_600 gr_mm_01.txt
#Acq. time (s)=	45
#Accumulations=	2
#Range (cm-¹)=	200...3150
#Windows=	2
#Auto scanning=	Off
#Autofocus=	Off
#Macrospot=	Off
#AutoExposure=	Off
#Spike filter=	Multiple accum.
#Delay time (s)=	0
#Binning=	1
#Readout mode=	Signal
#DeNoise=	Off
#ICS correction=	On
#Dark correction=	Off
#Inst. Process=	Off
#Detector Gain=	Best Dynamic Range
#Detector ADC=	20 kHz
#Detector temperature (°C)=	-69.85
#Instrument=	LabRAM HR Evol
#Detector=	Synapse
#Objective=	x100
#Grating=	600 gr/mm
#ND Filter=	100%
#Laser (nm)=	532
#Hole=	100.021
#Range=	Auto
#Laser Pol.=	No
#Raman. Pol.=	No
#Laser Pol. (°)=	-0.0007625
#Raman Pol. (°)=	89.9995
#Collection=	Microscope
#StageXY=	Marzhauser
#StageZ=	Marzhauser
#X (µm)=	-6960.7
#Y (µm)=	1963.6
#Z (µm)=	-75.15
#Full time(mm:ss)=	3:19
#Project=
#Sample=
#Site=
#Title=	Mb_20_23_32_2x_45s_532 nm_x100_100%_600 gr_mm
#Remark=
#Date=	13.07.2022 15:38
#Acquired=	13.07.2022 15:38:35
#Base:Fit=	10.08.2022 10:29:37
#Base:Sub=	10.08.2022 10:34:43
#Filter:Polynom=	16.08.2022 10:13:29
#AxisType[0]=Intens
#AxisUnit[0]=Cnt
#AxisType[1]=Spectr
#AxisUnit[1]=1/cm
200.563	17.7885
204.194	18.8456
207.821	17.3206
211.449	14.8815
215.074	12.486
218.699	9.5312
222.321	8.20422
225.941	8.67235
229.562	6.38818
233.18	5.02058
236.796	4.27062
240.411	4.12377
244.026	3.83571
247.638	2.66095
251.248	2.35286
254.857	2.32159
258.465	2.61649
262.071	1.40455
265.678	3.15175
269.282	3.73412
272.884	4.95885
276.484	2.68899
280.084	3.19303
283.682	2.35956
287.276	2.34657
290.871	2.93746
294.465	3.39908
298.057	5.34352
301.648	6.40879
305.237	10.2961
308.823	13.3258
312.41	15.0583
315.995	14.7593
319.579	17.1803
323.16	18.3917
326.741	19.7305
330.321	19.5741
333.897	20.3193
337.474	21.191
341.048	22.2948
344.622	21.1177
348.192	19.462
351.764	18.2078
355.332	15.3509
358.901	13.3499
362.466	11.0872
366.03	9.99477
369.594	9.05629
373.155	8.07828
376.715	7.01158
380.273	7.50016
383.832	9.39683
387.388	10.4115
390.942	11.6377
394.495	12.678
398.047	11.5376
401.597	11.6256
405.145	12.7139
408.693	13.5794
412.239	13.4995
415.783	13.1589
419.327	14.6384
422.869	14.9156
426.409	14.7447
429.948	14.8073
433.486	12.9324
437.022	12.3995
440.558	10.1644
444.089	9.75858
447.622	10.534
451.153	11.7338
454.682	13.3224
458.208	15.0171
461.735	14.7187
465.259	16.6625
468.783	18.4
472.306	19.1396
475.825	20.0777
479.346	18.829
482.862	19.1851
486.38	20.7645
489.894	23.0184
493.407	24.2703
496.92	25.1978
500.43	27.0254
503.939	28.9437
507.448	30.9889
510.954	33.2647
514.459	33.3013
517.962	33.7462
521.466	34.4714
524.966	36.9983
528.466	36.179
531.964	36.1525
535.46	37.5429
538.955	37.1943
542.449	36.6502
545.942	32.7955
549.433	32.2198
552.923	30.5043
556.412	26.2837
559.899	21.7993
563.385	17.6042
566.867	13.5935
570.35	13.7264
573.832	11.937
577.313	9.95516
580.79	10.3294
584.268	9.44761
587.745	9.72897
591.218	10.0147
594.692	9.70272
598.164	10.4104
601.634	10.1113
605.104	13.539
608.57	15.8391
612.037	17.0494
615.501	17.3785
618.966	16.325
622.427	16.34
625.887	16.2415
629.348	15.7367
632.806	16.7953
636.262	16.8766
639.716	16.7977
643.172	15.757
646.624	13.8209
650.075	14.5401
653.524	15.3313
656.972	14.6675
660.419	14.4852
663.865	12.8161
667.309	12.9498
670.752	12.5971
674.194	12.3591
677.634	12.6358
681.073	15.2638
684.511	16.6072
687.947	16.515
691.382	17.2001
694.816	16.0396
698.247	15.2043
701.678	13.6924
705.108	14.375
708.534	15.3298
711.962	17.6799
715.388	20.4963
718.81	22.9719
722.234	24.5203
725.654	25.6012
729.075	27.7908
732.492	28.8139
735.91	30.5949
739.325	34.1403
742.741	36.0964
746.153	40.9296
749.564	44.5079
752.976	47.8431
756.385	50.9108
759.792	54.8209
763.2	60.4224
766.604	63.1453
770.008	64.6501
773.41	65.135
776.811	68.2604
780.21	69.3647
783.608	71.8661
787.005	75.4605
790.401	78.4
793.795	80.7293
797.188	81.2194
800.58	84.2264
803.971	84.2378
807.36	84.5424
810.748	85.7598
814.135	85.399
817.518	85.7095
820.902	86.8137
824.285	86.6452
827.665	86.5398
831.045	85.2368
834.424	84.5284
837.8	82.5931
841.177	81.1028
844.55	81.5285
847.924	79.7635
851.295	76.4709
854.666	74.8194
858.034	73.5412
861.403	72.7863
864.769	72.5481
868.133	72.6678
871.498	72.0085
874.86	70.9229
878.221	70.2293
881.58	67.6426
884.938	67.3954
888.297	66.8409
891.653	64.8507
895.007	65.0446
898.36	63.6009
901.712	59.6306
905.063	58.6013
908.412	57.0986
911.76	55.4474
915.107	56.5812
918.452	54.1917
921.797	51.9965
925.138	51.9304
928.48	49.8703
931.82	48.6229
935.16	49.2908
938.496	49.1611
941.833	48.9232
945.168	45.7502
948.5	43.3486
951.834	43.8919
955.163	42.3175
958.494	40.6665
961.821	35.6483
965.15	36.6041
968.474	39.1912
971.8	41.4217
975.123	44.049
978.446	43.9776
981.766	46.1169
985.084	47.1117
988.402	48.6249
991.72	49.0981
995.035	49.3833
998.349	48.1585
1001.66	47.5057
1004.97	48.2322
1008.28	51.2877
1011.59	54.8973
1014.9	58.3779
1018.21	61.1372
1021.51	63.6844
1024.81	65.0828
1028.12	69.6286
1031.42	74.0135
1034.72	77.1803
1038.02	79.1956
1041.31	81.4282
1044.61	85.1203
1047.91	88.2383
1051.2	90.223
1054.49	91.3567
1057.78	89.1458
1061.07	87.7235
1064.36	84.3396
1067.65	80.0484
1070.93	75.0837
1074.22	70.3992
1077.5	65.3881
1080.78	60.8346
1084.06	56.4966
1087.34	54.8966
1090.62	55.5913
1093.9	56.482
1097.17	56.7548
1100.45	57.6926
1103.72	59.5011
1106.99	60.2404
1110.27	60.945
1113.53	60.876
1116.8	59.7846
1120.07	56.8625
1123.33	54.3488
1126.6	50.7413
1129.86	48.903
1133.12	46.9653
1136.38	43.3615
1139.64	37.9486
1142.9	32.7255
1146.16	28.1041
1149.41	23.5501
1152.67	18.5143
1155.92	13.0629
1159.17	9.5562
1162.42	6.05296
1165.67	2.3907
1168.92	1.95403
1172.16	4.12989
1175.41	4.62612
1178.65	6.73576
1181.9	8.57374
1185.14	9.63899
1188.38	10.8364
1191.62	12.391
1194.86	14.9608
1198.09	17.0361
1201.33	20.1797
1204.56	24.035
1207.8	28.2548
1211.03	34.8245
1214.26	40.481
1217.49	44.1876
1220.71	49.1001
1223.94	54.0305
1227.16	59.0505
1230.39	63.167
1233.61	66.1326
1236.83	70.7287
1240.05	73.0849
1243.27	77.0906
1246.49	79.8243
1249.71	85.1998
1252.92	87.5868
1256.14	89.9069
1259.35	91.7219
1262.56	95.9688
1265.77	98.7753
1268.98	104.005
1272.19	108.62
1275.4	114.046
1278.6	118.494
1281.81	122.953
1285.01	128.543
1288.21	133.604
1291.41	137.481
1294.61	139.864
1297.81	139.496
1301.01	142.038
1304.2	141.867
1307.4	142.885
1310.59	141.646
1313.78	139.841
1316.97	137.406
1320.16	135.528
1323.35	133.201
1326.54	129.995
1329.72	124.893
1332.91	120.763
1336.09	119.223
1339.27	116.843
1342.45	114.214
1345.64	109.738
1348.81	107.52
1351.99	105.808
1355.17	101.54
1358.34	98.3745
1361.51	96.8688
1364.69	95.4017
1367.86	93.3504
1371.03	91.265
1374.2	88.6941
1377.37	86.8553
1380.53	86.9719
1383.7	86.8459
1386.86	87.0607
1390.02	86.575
1393.19	84.9768
1396.35	83.1122
1399.51	83.263
1402.66	86.0064
1405.82	93.0695
1408.97	102.601
1412.13	112.418
1415.28	123.454
1418.43	134.006
1421.59	146.83
1424.73	163.672
1427.88	179.371
1431.03	194.634
1434.18	209.425
1437.32	222.076
1440.46	232.085
1443.61	239.354
1446.75	241.059
1449.89	239.658
1453.03	236.608
1456.16	227.826
1459.3	217.019
1462.44	203.929
1465.57	186.5
1468.7	166.696
1471.83	146.922
1474.96	128.277
1478.09	110.703
1481.22	95.4264
1484.35	82.5126
1487.47	68.185
1490.6	56.3695
1493.72	46.1616
1496.84	38.3271
1499.96	34.6764
1503.08	29.6017
1506.2	25.8267
1509.32	23.8639
1512.44	22.3603
1515.55	20.8953
1518.66	20.7157
1521.78	20.9081
1524.89	21.7957
1528	23.1151
1531.11	24.9232
1534.21	27.0169
1537.32	30.8595
1540.43	34.5176
1543.53	38.1683
1546.63	40.2735
1549.74	43.3339
1552.84	45.6826
1555.94	46.1877
1559.03	49.3063
1562.13	51.4619
1565.23	53.4071
1568.32	55.3061
1571.42	58.9783
1574.51	63.5402
1577.6	67.3279
1580.69	70.9986
1583.78	75.4754
1586.87	78.8947
1589.95	82.6178
1593.04	85.5424
1596.12	87.8353
1599.21	89.078
1602.29	89.8155
1605.37	91.3966
1608.45	92.2457
1611.53	91.9466
1614.6	92.9118
1617.68	92.7698
1620.75	92.7385
1623.83	93.1889
1626.9	94.1755
1629.97	95.9571
1633.04	98.2132
1636.11	101.455
1639.18	105.293
1642.25	109.497
1645.31	113.437
1648.38	116.639
1651.44	119.256
1654.5	119.512
1657.56	119.335
1660.62	118.995
1663.68	117.674
1666.74	115.534
1669.8	109.136
1672.85	102.818
1675.91	97.8939
1678.96	91.813
1682.01	84.554
1685.06	77.2818
1688.11	71.0193
1691.16	64.0429
1694.21	56.9652
1697.25	51.5332
1700.3	46.4295
1703.34	42.5622
1706.39	39.6297
1709.43	36.9035
1712.47	34.8065
1715.51	32.0951
1718.54	28.8744
1721.58	26.3818
1724.62	24.6973
1727.65	23.952
1730.68	22.7668
1733.72	23.1
1736.75	22.3542
1739.78	21.7974
1742.81	20.5152
1745.84	19.468
1748.86	20.8013
1751.89	20.2434
1754.91	18.2679
1757.93	17.0553
1760.96	13.9422
1763.98	12.2962
1767	9.36149
1770.02	8.169
1773.03	7.05359
1776.05	5.51012
1779.07	5.04797
1782.08	4.90354
1785.09	4.67463
1788.11	3.64531
1791.12	2.08105
1794.13	1.99224
1797.13	2.37792
1800.14	3.15865
1803.15	2.93096
1806.15	3.31974
1809.16	3.19499
1812.16	2.88471
1815.16	2.03366
1818.16	1.7557
1821.16	1.74005
1824.16	1.94251
1827.16	1.91126
1830.16	3.01041
1833.15	4.29378
1836.14	4.44065
1839.14	5.51731
1842.13	5.84512
1845.12	6.88029
1848.11	6.45559
1851.1	6.45049
1854.08	7.30281
1857.07	7.49441
1860.05	8.47096
1863.04	9.23624
1866.02	8.88625
1869	9.20276
1871.98	8.24055
1874.96	7.72843
1877.94	7.35605
1880.92	6.90332
1882.51	5.24302
1885.5	4.16738
1888.48	3.19962
1891.47	3.49081
1894.46	3.386
1897.44	2.92461
1900.42	3.19278
1903.41	2.89314
1906.39	3.3783
1909.37	3.29508
1912.35	4.42751
1915.32	4.17273
1918.3	3.3159
1921.27	2.79854
1924.25	3.82787
1927.22	3.75762
1930.19	4.9169
1933.17	4.41312
1936.14	3.77562
1939.11	3.24524
1942.07	3.19419
1945.04	4.12062
1948.01	4.83488
1950.97	4.1771
1953.93	3.92923
1956.9	2.41575
1959.86	1.46349
1962.82	1.17255
1965.78	0.828568
1968.74	0.688033
1971.69	0.879676
1974.65	2.27603
1977.6	3.99402
1980.56	5.0274
1983.51	5.58623
1986.46	6.24744
1989.41	6.78725
1992.36	7.56741
1995.31	8.13293
1998.26	9.6517
2001.2	10.52
2004.15	9.71646
2007.09	11.0925
2010.04	11.0089
2012.98	12.1417
2015.92	13.5999
2018.86	12.9668
2021.8	11.6303
2024.73	10.9251
2027.67	9.62402
2030.61	8.38616
2033.54	8.46061
2036.47	8.14244
2039.4	7.95408
2042.33	8.80648
2045.27	9.38951
2048.19	8.98917
2051.12	9.81419
2054.05	10.2182
2056.97	10.443
2059.9	11.0079
2062.82	11.1328
2065.74	11.3758
2068.67	12.8378
2071.59	14.0572
2074.51	15.2104
2077.42	16.5306
2080.34	17.6867
2083.26	18.4959
2086.17	18.8173
2089.09	18.1204
2092	18.6502
2094.91	19.0916
2097.82	19.4139
2100.73	21.0309
2103.64	22.4519
2106.55	23.2038
2109.45	24.3094
2112.36	26.9236
2115.26	28.2389
2118.17	28.8046
2121.07	30.4127
2123.97	32.8426
2126.87	34.1849
2129.77	37.8167
2132.67	39.6664
2135.56	42.209
2138.46	46.2078
2141.35	49.1519
2144.25	52.118
2147.14	55.615
2150.03	57.2229
2152.92	59.956
2155.81	63.1958
2158.7	65.6013
2161.59	68.4388
2164.47	70.4531
2167.36	72.1686
2170.24	73.7805
2173.13	75.0864
2176.01	75.039
2178.89	76.0597
2181.77	76.2974
2184.65	75.6232
2187.53	73.909
2190.4	73.2337
2193.28	70.6419
2196.16	67.7997
2199.03	65.5609
2201.9	63.2584
2204.77	61.2256
2207.64	56.5997
2210.51	52.8883
2213.38	48.6504
2216.25	44.7058
2219.12	41.4974
2221.98	39.5298
2224.85	36.8697
2227.71	33.0955
2230.57	30.5263
2233.43	28.4181
2236.29	27.463
2239.15	26.3476
2242.01	24.8503
2244.87	23.6603
2247.72	23.4101
2250.58	23.6181
2253.43	21.6587
2256.29	19.4888
2259.14	19.078
2261.99	17.8468
2264.84	15.5494
2267.69	15.2129
2270.53	14.5887
2273.38	13.4607
2276.23	12.9725
2279.07	11.3855
2281.91	10.4344
2284.76	10.287
2287.6	11.1062
2290.44	10.9063
2293.28	11.0484
2296.12	11.0401
2298.96	12.3612
2301.79	14.7314
2304.63	16.173
2307.46	17.0763
2310.3	17.7511
2313.13	18.5431
2315.96	19.1229
2318.79	19.0365
2321.62	17.6786
2324.45	16.3277
2327.27	14.9668
2330.1	14.5479
2332.92	13.2203
2335.75	12.3557
2338.57	10.2277
2341.39	8.79811
2344.21	8.36111
2347.04	6.8386
2349.85	6.77975
2352.67	7.33129
2355.49	7.36219
2358.3	6.23592
2361.12	6.05895
2363.93	7.21937
2366.75	7.11914
2369.56	6.29223
2372.37	5.54215
2375.18	5.36903
2377.99	5.09697
2380.8	4.42072
2383.6	3.54954
2386.41	3.54168
2389.21	1.74004
2392.02	1.93467
2394.82	1.51362
2397.62	3.09223
2400.42	3.57853
2403.22	3.57015
2406.02	4.36962
2408.82	5.85148
2411.62	7.01474
2414.41	7.77063
2417.21	8.5814
2420	9.27849
2422.79	10.6404
2425.59	10.8823
2428.38	12.2026
2431.17	12.6047
2433.95	11.3333
2436.74	10.0278
2439.53	8.6248
2442.31	7.54047
2445.1	6.48119
2447.88	4.69062
2450.67	4.44476
2453.45	4.32204
2456.23	3.69817
2459.01	3.42053
2461.79	3.18414
2464.57	3.02108
2467.34	3.45548
2470.12	3.24459
2472.89	4.00128
2475.67	3.84247
2478.44	2.98569
2481.21	2.4979
2483.98	2.68111
2486.75	3.27681
2489.52	3.89618
2492.29	4.08952
2495.05	3.841
2497.82	3.02758
2500.58	2.67693
2503.35	2.20831
2506.11	2.07444
2508.87	2.18469
2511.63	2.99534
2514.39	2.99589
2517.15	3.2671
2519.91	3.50143
2522.67	3.2645
2525.42	3.68409
2528.18	3.47564
2530.93	3.30372
2533.69	3.67188
2536.44	3.61351
2539.19	4.16617
2541.94	4.67042
2544.69	3.98409
2547.44	4.20263
2550.18	4.50329
2552.93	3.1623
2555.67	3.76881
2558.42	3.65661
2561.16	3.82541
2563.9	4.49633
2566.64	4.69292
2569.38	4.5365
2572.12	5.10743
2574.86	4.06616
2577.6	5.12983
2580.33	5.57925
2583.07	5.49036
2585.8	6.08091
2588.54	6.11892
2591.27	8.37449
2594	8.34497
2596.73	8.14172
2599.46	7.91
2602.19	8.08278
2604.92	7.20633
2607.64	7.18245
2610.37	5.31432
2613.09	4.95284
2615.82	4.87371
2618.54	5.01955
2621.26	5.01682
2623.98	4.73874
2626.7	4.76982
2629.42	3.69326
2632.14	3.25323
2634.86	2.01094
2637.57	1.53193
2640.29	0.899818
2643	1.29631
2645.71	2.2807
2648.43	2.94036
2651.14	3.51997
2653.85	4.63495
2656.56	5.82466
2659.26	5.82643
2661.97	6.12612
2664.68	5.14394
2667.38	6.24478
2670.09	6.70042
2672.79	7.16714
2675.49	7.06623
2678.19	6.94013
2680.89	8.54319
2683.59	9.96229
2686.29	10.8414
2688.99	12.6724
2691.69	14.2619
2694.38	15.2588
2697.08	16.7815
2699.77	18.613
2702.46	19.9015
2705.15	22.032
2707.85	23.0027
2710.54	23.8151
2713.22	26.5039
2715.91	27.1945
2718.6	28.0493
2721.29	28.3041
2723.97	27.3769
2726.66	26.7647
2729.34	25.6752
2732.02	23.7874
2734.7	21.8635
2737.38	18.3453
2740.06	16.3288
2742.74	13.3273
2745.42	11.4763
2748.09	9.91709
2750.77	7.84733
2753.45	6.19449
2756.12	5.68557
2758.79	3.82954
2761.46	3.33632
2764.14	2.87254
2766.8	1.49012
2769.47	0.62602
2772.14	0.802663
2774.81	0.557819
2777.48	0.561543
2780.14	0.0156138
2782.8	-0.0887801
2785.47	-1.42953
2788.13	-1.32755
2790.79	-0.736758
2793.45	-1.32485
2796.11	-2.19359
2798.77	-2.74897
2801.43	-3.63446
2804.09	-4.71747
2806.74	-6.62252
2809.4	-8.401
2812.05	-8.94442
2814.71	-5.30682
2817.36	2.16181
2820.01	13.7955
2822.66	29.2185
2825.31	46.767
2827.96	67.1584
2830.6	89.8936
2833.25	114.028
2835.9	139.163
2838.54	164.607
2841.18	188.606
2843.83	212.041
2846.47	236.018
2849.11	263.262
2851.75	291.567
2854.39	321.174
2857.03	350.305
2859.66	375.96
2862.3	399.032
2864.94	417.976
2867.57	433.905
2870.2	446.365
2872.84	457.195
2875.47	466.928
2878.1	476.581
2880.73	487.722
2883.36	496.303
2885.99	505.181
2888.61	510.856
2891.24	515.855
2893.86	520.019
2896.49	524.979
2899.11	527.881
2901.73	532.001
2904.36	537.495
2906.98	544.191
2909.6	555.733
2912.21	572.911
2914.83	590.872
2917.45	608.576
2920.07	622.966
2922.68	633.53
2925.29	640.315
2927.91	641.616
2930.52	640.123
2933.13	632.993
2935.74	622.403
2938.35	607.608
2940.96	591.018
2943.57	570.477
2946.18	548.099
2948.78	522.251
2951.39	496.103
2953.99	468.558
2956.59	441.331
2959.2	414.357
2961.8	387.499
2964.4	362.765
2967	340.321
2969.6	319.501
2972.19	300.207
2974.79	282.758
2977.39	263.684
2979.98	244.16
2982.58	225.448
2985.17	205.734
2987.76	186.169
2990.35	167.375
2992.94	149.416
2995.53	129.714
2998.12	112.876
3000.71	97.988
3003.3	83.3503
3005.88	70.6042
3008.47	58.537
3011.05	48.3298
3013.64	38.7985
3016.22	30.0822
3018.8	24.0843
3021.38	17.931
3023.96	12.9768
3026.54	8.715
3029.12	5.54647
3031.69	3.29266
3034.27	1.94011
3036.84	1.22259
3039.42	0.526071
3041.99	2.71257
3044.57	5.03444
3047.14	5.49038
3049.71	6.56885
3052.28	8.12008
3054.85	8.74842
3057.41	9.20935
3059.98	9.45105
3062.55	10.4683
3065.11	9.58564
3067.68	8.5237
3070.24	7.64771
3072.8	6.15719
3075.36	5.10603
3077.93	4.28568
3080.49	3.17646
3083.04	1.91675
3085.6	0.0261196
3088.16	-0.459427
3090.72	-0.0806317
3093.27	-0.300409
3095.83	1.16357
3098.38	2.15748
3100.93	3.79551
3103.49	6.37939
3106.04	9.36419
3108.59	10.9852
3111.14	13.5041
3113.69	16.8228
3116.23	20.149
3118.78	22.9926
3121.33	26.571
3123.87	30.1383
3126.41	32.9613
3128.96	36.2941
3131.5	39.4885
3134.04	42.7762
3136.58	46.1087
3139.12	49.8793
3141.66	53.2286
3144.2	56.9022
3146.74	60.5294
3149.27	63.6079