File: data/Raman/poly_smoothed/Mb_20_23_26_1x_45s_532 nm_x100_100%_600 gr_mm_01.txt
#Acq. time (s)=	45
#Accumulations=	2
#Range (cm-¹)=	200...3150
#Windows=	2
#Auto scanning=	Off
#Autofocus=	Off
#Macrospot=	Off
#AutoExposure=	Off
#Spike filter=	Multiple accum.
#Delay time (s)=	0
#Binning=	1
#Readout mode=	Signal
#DeNoise=	Off
#ICS correction=	On
#Dark correction=	Off
#Inst. Process=	Off
#Detector Gain=	Best Dynamic Range
#Detector ADC=	20 kHz
#Detector temperature (°C)=	-69.85
#Instrument=	LabRAM HR Evol
#Detector=	Synapse
#Objective=	x100
#Grating=	600 gr/mm
#ND Filter=	100%
#Laser (nm)=	532
#Hole=	100.021
#Range=	Auto
#Laser Pol.=	No
#Raman. Pol.=	No
#Laser Pol. (°)=	-0.0007625
#Raman Pol. (°)=	89.9995
#Collection=	Microscope
#StageXY=	Marzhauser
#StageZ=	Marzhauser
#X (µm)=	-6912.4
#Y (µm)=	2035.9
#Z (µm)=	-74.85
#Full time(mm:ss)=	3:19
#Project=
#Sample=
#Site=
#Title=	Mb_20_23_26_2x_45s_532 nm_x100_100%_600 gr_mm
#Remark=
#Date=	13.07.2022 15:11
#Acquired=	13.07.2022 15:11:28
#Base:Fit=	10.08.2022 10:29:37
#Edit:Spike=	10.08.2022 10:33:20
#Base:Sub=	10.08.2022 10:33:46
#Filter:Polynom=	16.08.2022 10:13:29
#AxisType[0]=Intens
#AxisUnit[0]=Cnt
#AxisType[1]=Spectr
#AxisUnit[1]=1/cm
200.563	63.9751
204.194	53.5688
207.821	48.1392
211.449	42.1129
215.074	36.4987
218.699	32.235
222.321	29.1013
225.941	25.8101
229.562	22.1477
233.18	20.3708
236.796	18.9094
240.411	16.5311
244.026	13.6926
247.638	12.8447
251.248	12.0884
254.857	9.77238
258.465	10.6284
262.071	7.42623
265.678	5.30084
269.282	3.85826
272.884	2.61086
276.484	2.79342
280.084	3.16904
283.682	4.05431
287.276	4.63441
290.871	2.96164
294.465	3.44592
298.057	2.97566
301.648	3.4503
305.237	4.65458
308.823	5.01727
312.41	7.79626
315.995	9.74516
319.579	9.14386
323.16	10.4048
326.741	9.37346
330.321	9.41527
333.897	10.0737
337.474	11.0705
341.048	9.73241
344.622	9.85702
348.192	8.59838
351.764	8.51496
355.332	6.60698
358.901	6.9258
362.466	7.11371
366.03	6.2506
369.594	5.29134
373.155	4.03757
376.715	3.64219
380.273	2.59141
383.832	3.99484
387.388	3.11053
390.942	0.903008
394.495	0.939824
398.047	0.981261
401.597	1.70693
405.145	-0.0224719
408.693	1.75012
412.239	2.34296
415.783	5.20657
419.327	5.72805
422.869	6.75067
426.409	6.72094
429.948	8.06485
433.486	8.40736
437.022	9.58887
440.558	9.16703
444.089	10.3885
447.622	10.4871
451.153	10.869
454.682	10.6519
458.208	11.6957
461.735	13.2795
465.259	14.1261
468.783	14.4405
472.306	13.8497
475.825	12.9846
479.346	12.0951
482.862	13.8469
486.38	14.9832
489.894	16.163
493.407	17.943
496.92	17.6465
500.43	17.4019
503.939	17.897
507.448	18.7827
510.954	19.1278
514.459	20.0032
517.962	20.526
521.466	21.2889
524.966	21.0898
528.466	19.8464
531.964	18.4135
535.46	17.4267
538.955	18.5348
542.449	18.7179
545.942	16.7368
549.433	16.2753
552.923	14.6271
556.412	13.4205
559.899	11.4488
563.385	10.2795
566.867	9.36022
570.35	7.77363
573.832	5.46543
577.313	3.74572
580.79	2.74533
584.268	1.78334
587.745	1.06266
591.218	1.05485
594.692	1.5717
598.164	0.0996195
601.634	0.516221
605.104	0.0527418
608.57	1.12687
612.037	1.47215
615.501	3.35073
618.966	4.0517
622.427	6.26155
625.887	6.45943
629.348	8.31414
632.806	10.1371
636.262	12.3906
639.716	15.1846
643.172	16.4219
646.624	16.9783
650.075	18.2067
653.524	18.4366
656.972	19.43
660.419	18.842
663.865	18.9873
667.309	18.0309
670.752	17.9961
674.194	18.4671
677.634	18.3737
681.073	19.992
684.511	19.7356
687.947	21.2082
691.382	22.6408
694.816	23.7603
698.247	26.7433
701.678	26.9596
705.108	28.0276
708.534	29.5033
711.962	31.8817
715.388	33.1906
718.81	34.538
722.234	37.2977
725.654	37.6239
729.075	38.6559
732.492	40.7815
735.91	40.1845
739.325	42.399
742.741	43.1936
746.153	46.2977
749.564	47.766
752.976	51.0179
756.385	55.8975
759.792	58.9215
763.2	61.8062
766.604	63.485
770.008	66.8599
773.41	68.9471
776.811	70.9873
780.21	75.9917
783.608	78.3128
787.005	80.763
790.401	81.872
793.795	84.1477
797.188	85.1226
800.58	86.6593
803.971	87.4076
807.36	88.8769
810.748	89.9974
814.135	90.902
817.518	91.1373
820.902	93.0298
824.285	94.5641
827.665	95.5617
831.045	96.6276
834.424	95.127
837.8	93.5546
841.177	92.0497
844.55	90.767
847.924	87.2048
851.295	83.4629
854.666	81.1693
858.034	78.2457
861.403	77.7993
864.769	77.432
868.133	74.7295
871.498	74.5969
874.86	72.4242
878.221	71.745
881.58	70.6911
884.938	69.6629
888.297	71.4353
891.653	68.6196
895.007	67.5348
898.36	68.5742
901.712	69.0317
905.063	70.135
908.412	68.7241
911.76	68.0842
915.107	67.2125
918.452	66.8739
921.797	64.5905
925.138	63.8042
928.48	60.7408
931.82	58.4313
935.16	55.9152
938.496	52.233
941.833	50.4353
945.168	48.9598
948.5	46.2041
951.834	44.9826
955.163	43.6197
958.494	40.3251
961.821	39.0827
965.15	38.2189
968.474	38.5829
971.8	38.1869
975.123	38.0056
978.446	40.687
981.766	42.2716
985.084	42.0328
988.402	41.9581
991.72	42.5153
995.035	44.2239
998.349	46.0032
1001.66	46.4722
1004.97	45.5655
1008.28	44.0052
1011.59	44.138
1014.9	44.0567
1018.21	43.0114
1021.51	42.8939
1024.81	43.6426
1028.12	45.1381
1031.42	45.3275
1034.72	46.741
1038.02	47.693
1041.31	47.3431
1044.61	49.9705
1047.91	52.2442
1051.2	53.9104
1054.49	55.5663
1057.78	57.0448
1061.07	55.9869
1064.36	54.789
1067.65	53.0259
1070.93	52.444
1074.22	52.9391
1077.5	50.5295
1080.78	49.6416
1084.06	46.3172
1087.34	43.8129
1090.62	42.4779
1093.9	42.6928
1097.17	42.6387
1100.45	41.8879
1103.72	41.4273
1106.99	42.641
1110.27	42.8576
1113.53	43.2396
1116.8	43.5579
1120.07	41.3848
1123.33	38.3361
1126.6	36.9601
1129.86	35.6866
1133.12	35.031
1136.38	33.7777
1139.64	30.3158
1142.9	28.0742
1146.16	24.4691
1149.41	21.1659
1152.67	18.8263
1155.92	13.3134
1159.17	9.37662
1162.42	7.50567
1165.67	5.4384
1168.92	7.33654
1172.16	6.68998
1175.41	6.42379
1178.65	7.16784
1181.9	6.22344
1185.14	6.9269
1188.38	8.59808
1191.62	9.23226
1194.86	10.762
1198.09	13.4847
1201.33	15.6806
1204.56	17.4161
1207.8	22.5535
1211.03	26.9802
1214.26	30.4625
1217.49	33.259
1220.71	36.9234
1223.94	39.5068
1227.16	44.6123
1230.39	46.8036
1233.61	51.581
1236.83	55.4371
1240.05	57.9485
1243.27	61.0431
1246.49	63.24
1249.71	64.7048
1252.92	64.419
1256.14	64.5654
1259.35	64.5587
1262.56	63.9657
1265.77	65.8421
1268.98	68.0565
1272.19	71.4726
1275.4	75.2048
1278.6	79.9533
1281.81	80.5006
1285.01	84.6093
1288.21	88.65
1291.41	92.5729
1294.61	95.229
1297.81	96.8853
1301.01	98.6164
1304.2	101.042
1307.4	103.457
1310.59	103.975
1313.78	105.415
1316.97	103.34
1320.16	102.01
1323.35	99.3253
1326.54	98.2932
1329.72	94.7221
1332.91	90.5093
1336.09	86.181
1339.27	82.8675
1342.45	79.5897
1345.64	76.6343
1348.81	73.6697
1351.99	73.1598
1355.17	70.1059
1358.34	67.8947
1361.51	66.4658
1364.69	67.1957
1367.86	66.0935
1371.03	64.0014
1374.2	61.251
1377.37	60.1508
1380.53	59.3902
1383.7	60.7337
1386.86	60.8757
1390.02	61.2624
1393.19	58.5597
1396.35	58.3203
1399.51	60.1388
1402.66	63.0658
1405.82	66.4383
1408.97	71.7379
1412.13	75.8189
1415.28	81.0433
1418.43	88.764
1421.59	96.4778
1424.73	107.337
1427.88	118.776
1431.03	128.676
1434.18	139.801
1437.32	149.153
1440.46	156.471
1443.61	161.109
1446.75	162.454
1449.89	162.123
1453.03	158.974
1456.16	153.948
1459.3	147.578
1462.44	136.665
1465.57	126.954
1468.7	116.518
1471.83	103.404
1474.96	92.7955
1478.09	81.8418
1481.22	71.8296
1484.35	61.7264
1487.47	51.1941
1490.6	41.7004
1493.72	35.635
1496.84	30.202
1499.96	26.11
1503.08	25.2194
1506.2	22.8106
1509.32	22.6872
1512.44	21.692
1515.55	19.576
1518.66	19.3943
1521.78	18.0056
1524.89	18.3353
1528	19.2775
1531.11	19.8852
1534.21	21.2893
1537.32	22.5185
1540.43	25.1918
1543.53	27.5339
1546.63	29.5085
1549.74	31.9589
1552.84	33.2959
1555.94	34.8892
1559.03	35.9748
1562.13	36.421
1565.23	37.4146
1568.32	40.0063
1571.42	43.2462
1574.51	46.134
1577.6	48.2539
1580.69	50.6387
1583.78	51.7073
1586.87	53.5548
1589.95	53.8157
1593.04	55.744
1596.12	57.0618
1599.21	57.1671
1602.29	58.3208
1605.37	56.7472
1608.45	56.0861
1611.53	54.9213
1614.6	54.4603
1617.68	54.7332
1620.75	54.8993
1623.83	56.5924
1626.9	56.4578
1629.97	57.9618
1633.04	59.8696
1636.11	61.6661
1639.18	64.1362
1642.25	68.3323
1645.31	72.3747
1648.38	75.6862
1651.44	79.2863
1654.5	81.1701
1657.56	82.6456
1660.62	82.6423
1663.68	82.1544
1666.74	80.726
1669.8	77.9653
1672.85	74.2832
1675.91	69.0619
1678.96	62.9401
1682.01	56.8217
1685.06	51.47
1688.11	47.2638
1691.16	42.3734
1694.21	37.9347
1697.25	33.3515
1700.3	29.5217
1703.34	25.7771
1706.39	23.3264
1709.43	19.8196
1712.47	18.5247
1715.51	17.4197
1718.54	16.8178
1721.58	15.2992
1724.62	14.4399
1727.65	13.8948
1730.68	12.0954
1733.72	11.3486
1736.75	9.32758
1739.78	9.24955
1742.81	9.0616
1745.84	6.7812
1748.86	5.99017
1751.89	5.51222
1754.91	5.0837
1757.93	5.35196
1760.96	6.59011
1763.98	6.04369
1767	6.09258
1770.02	5.11391
1773.03	4.95499
1776.05	4.70139
1779.07	5.34142
1782.08	5.22214
1785.09	5.87113
1788.11	5.37141
1791.12	4.80931
1794.13	4.04884
1797.13	3.56725
1800.14	3.68771
1803.15	2.80682
1806.15	2.40359
1809.16	1.68975
1812.16	1.24781
1815.16	1.4729
1818.16	2.21933
1821.16	2.34585
1824.16	2.94164
1827.16	2.78947
1830.16	2.5299
1833.15	2.41614
1836.14	2.96252
1839.14	2.49139
1842.13	3.40153
1845.12	3.77215
1848.11	4.31503
1851.1	5.59951
1854.08	6.03669
1857.07	5.9953
1860.05	5.72081
1863.04	5.4989
1866.02	6.73168
1869	6.65495
1871.98	5.83799
1874.96	4.46108
1877.94	4.40679
1880.92	4.24461
1882.51	3.64517
1885.5	3.04867
1888.48	3.38337
1891.47	4.02631
1894.46	2.67203
1897.44	4.48295
1900.42	3.09031
1903.41	3.55128
1906.39	4.25817
1909.37	4.63491
1912.35	5.6089
1915.32	6.10259
1918.3	6.00747
1921.27	6.49038
1924.25	6.35805
1927.22	6.67733
1930.19	7.11309
1933.17	6.12882
1936.14	5.37397
1939.11	5.12504
1942.07	3.86474
1945.04	3.68118
1948.01	3.61982
1950.97	3.86911
1953.93	2.53989
1956.9	3.90151
1959.86	3.98149
1962.82	5.17963
1965.78	5.94094
1968.74	7.60663
1971.69	8.97132
1974.65	8.328
1977.6	8.76039
1980.56	8.30333
1983.51	7.983
1986.46	6.63705
1989.41	6.04002
1992.36	5.48309
1995.31	6.02716
1998.26	7.6014
2001.2	7.88869
2004.15	6.67832
2007.09	6.41911
2010.04	7.11443
2012.98	7.32386
2015.92	8.22533
2018.86	8.2922
2021.8	8.4878
2024.73	10.3475
2027.67	11.5645
2030.61	11.9533
2033.54	12.7008
2036.47	14.3213
2039.4	14.6412
2042.33	14.8623
2045.27	14.8153
2048.19	13.5824
2051.12	12.7722
2054.05	12.6277
2056.97	12.2083
2059.9	11.4778
2062.82	12.3262
2065.74	12.8974
2068.67	14.4308
2071.59	14.4708
2074.51	13.362
2077.42	13.1207
2080.34	13.5308
2083.26	14.4855
2086.17	15.0981
2089.09	15.3471
2092	17.183
2094.91	18.7598
2097.82	20.2177
2100.73	21.2871
2103.64	21.5869
2106.55	21.9096
2109.45	22.6474
2112.36	22.7825
2115.26	23.1658
2118.17	23.3321
2121.07	25.1187
2123.97	26.1674
2126.87	27.3329
2129.77	28.0537
2132.67	28.25
2135.56	30.0876
2138.46	31.0948
2141.35	32.6316
2144.25	35.2483
2147.14	38.2885
2150.03	42.0052
2152.92	46.8834
2155.81	50.4507
2158.7	53.2619
2161.59	56.7416
2164.47	58.9909
2167.36	61.0152
2170.24	62.5044
2173.13	63.2504
2176.01	64.1091
2178.89	65.3518
2181.77	64.1248
2184.65	63.8562
2187.53	62.8057
2190.4	61.7004
2193.28	58.6051
2196.16	56.0182
2199.03	51.8495
2201.9	48.9176
2204.77	45.2669
2207.64	43.5192
2210.51	40.4445
2213.38	38.053
2216.25	36.9079
2219.12	34.6255
2221.98	33.3249
2224.85	33.0878
2227.71	30.5778
2230.57	29.3174
2233.43	26.9829
2236.29	24.6201
2239.15	23.668
2242.01	22.4657
2244.87	22.1228
2247.72	21.9966
2250.58	20.1193
2253.43	20.4413
2256.29	19.0737
2259.14	18.6967
2261.99	18.1673
2264.84	17.7871
2267.69	17.3852
2270.53	17.1079
2273.38	16.1382
2276.23	16.267
2279.07	16.329
2281.91	14.8595
2284.76	14.8297
2287.6	14.6136
2290.44	14.3944
2293.28	13.081
2296.12	13.0445
2298.96	10.9445
2301.79	9.99455
2304.63	9.18446
2307.46	9.83208
2310.3	9.61444
2313.13	9.49318
2315.96	9.1546
2318.79	8.24794
2321.62	7.49379
2324.45	7.94632
2327.27	8.30811
2330.1	9.13338
2332.92	9.53323
2335.75	9.32084
2338.57	7.81326
2341.39	7.63954
2344.21	7.90476
2347.04	7.73154
2349.85	6.88897
2352.67	6.31724
2355.49	5.37269
2358.3	5.10179
2361.12	4.26879
2363.93	3.69383
2366.75	4.17649
2369.56	4.68238
2372.37	4.66358
2375.18	5.16553
2377.99	4.5582
2380.8	3.67067
2383.6	4.67128
2386.41	5.29561
2389.21	5.24228
2392.02	4.52971
2394.82	4.48252
2397.62	5.19109
2400.42	6.23869
2403.22	6.48961
2406.02	6.76468
2408.82	7.56929
2411.62	8.91715
2414.41	9.02038
2417.21	8.64803
2420	8.90326
2422.79	8.63675
2425.59	9.12375
2428.38	8.50918
2431.17	7.54052
2433.95	7.54361
2436.74	6.44726
2439.53	6.43318
2442.31	5.03534
2445.1	4.44863
2447.88	3.14344
2450.67	3.26199
2453.45	3.17553
2456.23	2.02718
2459.01	1.0492
2461.79	2.08212
2464.57	2.9447
2467.34	3.55242
2470.12	4.55705
2472.89	4.79837
2475.67	5.80388
2478.44	5.30391
2481.21	5.60451
2483.98	5.8428
2486.75	5.09255
2489.52	5.75978
2492.29	4.95951
2495.05	4.48671
2497.82	3.18871
2500.58	2.54662
2503.35	2.82705
2506.11	2.58631
2508.87	2.48227
2511.63	1.76858
2514.39	1.01773
2517.15	-0.124426
2519.91	0.0870436
2522.67	-0.372513
2525.42	-0.897082
2528.18	-1.04705
2530.93	-0.760976
2533.69	-0.311181
2536.44	0.49714
2539.19	1.00487
2541.94	1.33405
2544.69	2.75786
2547.44	3.84595
2550.18	5.45627
2552.93	5.8964
2555.67	5.94049
2558.42	6.20553
2561.16	6.96974
2563.9	7.21299
2566.64	8.31811
2569.38	9.6674
2572.12	10.2095
2574.86	9.79067
2577.6	9.78918
2580.33	9.64453
2583.07	9.23063
2585.8	8.14971
2588.54	7.22148
2591.27	6.11766
2594	4.564
2596.73	4.92086
2599.46	3.78111
2602.19	2.92223
2604.92	2.19787
2607.64	2.84538
2610.37	3.26194
2613.09	3.21417
2615.82	2.45032
2618.54	2.73774
2621.26	2.06397
2623.98	2.09152
2626.7	2.03785
2629.42	2.76907
2632.14	2.49068
2634.86	2.64012
2637.57	3.04772
2640.29	3.92217
2643	4.69675
2645.71	5.46881
2648.43	5.44611
2651.14	5.66215
2653.85	5.37908
2656.56	6.20426
2659.26	5.74616
2661.97	5.41972
2664.68	5.32636
2667.38	4.82608
2670.09	5.25944
2672.79	6.70693
2675.49	7.91408
2678.19	7.91009
2680.89	7.54051
2683.59	8.51912
2686.29	7.62907
2688.99	8.24632
2691.69	8.69295
2694.38	9.39717
2697.08	10.1943
2699.77	11.842
2702.46	13.4988
2705.15	14.3493
2707.85	16.2382
2710.54	17.8338
2713.22	19.42
2715.91	20.5442
2718.6	21.1016
2721.29	21.9043
2723.97	21.4163
2726.66	20.6962
2729.34	20.524
2732.02	20.013
2734.7	18.4204
2737.38	17.8516
2740.06	16.768
2742.74	15.7405
2745.42	13.0236
2748.09	12.2716
2750.77	9.86727
2753.45	8.70367
2756.12	7.27809
2758.79	7.10821
2761.46	6.04197
2764.14	4.15706
2766.8	3.65413
2769.47	2.87182
2772.14	3.57621
2774.81	2.82361
2777.48	3.48409
2780.14	3.37229
2782.8	2.43901
2785.47	2.00994
2788.13	2.57917
2790.79	2.45805
2793.45	2.76038
2796.11	1.91217
2798.77	2.04611
2801.43	2.13762
2804.09	2.7223
2806.74	2.51155
2809.4	0.928101
2812.05	-0.996222
2814.71	-0.329013
2817.36	1.10482
2820.01	5.4286
2822.66	12.5827
2825.31	23.0634
2827.96	34.9179
2830.6	49.5328
2833.25	65.2501
2835.9	82.8875
2838.54	100.993
2841.18	119.534
2843.83	139.77
2846.47	157.12
2849.11	176.816
2851.75	197.099
2854.39	216.118
2857.03	234.2
2859.66	250.599
2862.3	266.686
2864.94	279.566
2867.57	289.934
2870.2	298.527
2872.84	304.434
2875.47	309.42
2878.1	315.837
2880.73	321.686
2883.36	327.88
2885.99	333.772
2888.61	339.761
2891.24	345.832
2893.86	351.469
2896.49	358.273
2899.11	363.725
2901.73	370.188
2904.36	377.858
2906.98	385.339
2909.6	393.7
2912.21	403.634
2914.83	413.863
2917.45	422.661
2920.07	430.547
2922.68	435.312
2925.29	437.661
2927.91	437.104
2930.52	434.746
2933.13	429.652
2935.74	421.93
2938.35	413.918
2940.96	402.756
2943.57	389.159
2946.18	371.985
2948.78	355.488
2951.39	337.171
2953.99	318.307
2956.59	299.941
2959.2	282.176
2961.8	263.745
2964.4	246.21
2967	229.086
2969.6	214.69
2972.19	199.848
2974.79	186.198
2977.39	172.646
2979.98	159.442
2982.58	145.583
2985.17	131.9
2987.76	116.876
2990.35	104.659
2992.94	92.8033
2995.53	82.2911
2998.12	70.4994
3000.71	61.1788
3003.3	52.1701
3005.88	43.7495
3008.47	37.0274
3011.05	30.3185
3013.64	25.3887
3016.22	19.7882
3018.8	16.44
3021.38	12.6735
3023.96	11.0107
3026.54	8.06814
3029.12	5.29221
3031.69	3.47114
3034.27	1.81531
3036.84	1.53016
3039.42	0.568432
3041.99	0.590053
3044.57	0.963701
3047.14	-0.077043
3049.71	0.654027
3052.28	0.235078
3054.85	0.72345
3057.41	0.999547
3059.98	0.137769
3062.55	-1.10586
3065.11	-0.33599
3067.68	0.740705
3070.24	0.0738177
3072.8	-0.407843
3075.36	0.207361
3077.93	0.361949
3080.49	0.291186
3083.04	0.252507
3085.6	1.29237
3088.16	1.48081
3090.72	0.301134
3093.27	-0.171417
3095.83	-0.137632
3098.38	0.29641
3100.93	-0.24601
3103.49	0.284613
3106.04	1.02861
3108.59	2.34868
3111.14	4.52594
3113.69	5.33066
3116.23	6.31624
3118.78	7.59569
3121.33	8.34633
3123.87	10.2335
3126.41	11.8343
3128.96	14.4515
3131.5	16.8274
3134.04	19.123
3136.58	21.8315
3139.12	24.2197
3141.66	26.4176
3144.2	28.5054
3146.74	29.5292
3149.27	29.14