File: data/Raman/poly_smoothed/Mb_20_23_35_1x_45s_532 nm_x100_100%_600 gr_mm_02.txt
#Acq. time (s)=	45
#Accumulations=	2
#Range (cm-¹)=	200...3150
#Windows=	2
#Auto scanning=	Off
#Autofocus=	Off
#Macrospot=	Off
#AutoExposure=	Off
#Spike filter=	Multiple accum.
#Delay time (s)=	0
#Binning=	1
#Readout mode=	Signal
#DeNoise=	Off
#ICS correction=	On
#Dark correction=	Off
#Inst. Process=	Off
#Detector Gain=	Best Dynamic Range
#Detector ADC=	20 kHz
#Detector temperature (°C)=	-69.85
#Instrument=	LabRAM HR Evol
#Detector=	Synapse
#Objective=	x100
#Grating=	600 gr/mm
#ND Filter=	100%
#Laser (nm)=	532
#Hole=	100.021
#Range=	Auto
#Laser Pol.=	No
#Raman. Pol.=	No
#Laser Pol. (°)=	-0.0007625
#Raman Pol. (°)=	89.9995
#Collection=	Microscope
#StageXY=	Marzhauser
#StageZ=	Marzhauser
#X (µm)=	-6947
#Y (µm)=	1949.8
#Z (µm)=	-75.35
#Full time(mm:ss)=	3:13
#Project=
#Sample=
#Site=
#Title=	Mb_20_23_35_2x_45s_532 nm_x100_100%_600 gr_mm
#Remark=
#Date=	13.07.2022 16:13
#Acquired=	13.07.2022 16:13:28
#Base:Fit=	10.08.2022 10:29:37
#Base:Sub=	10.08.2022 10:34:43
#Filter:Polynom=	16.08.2022 10:13:29
#AxisType[0]=Intens
#AxisUnit[0]=Cnt
#AxisType[1]=Spectr
#AxisUnit[1]=1/cm
200.563	88.347
204.194	90.4034
207.821	89.4725
211.449	86.9321
215.074	82.7099
218.699	79.4056
222.321	70.903
225.941	65.0476
229.562	58.8969
233.18	56.3271
236.796	49.0447
240.411	44.9702
244.026	39.7083
247.638	34.5185
251.248	28.5667
254.857	24.723
258.465	21.4905
262.071	17.454
265.678	14.8638
269.282	11.4578
272.884	9.47645
276.484	8.17992
280.084	9.5948
283.682	7.78325
287.276	4.12435
290.871	3.27523
294.465	5.11829
298.057	6.45305
301.648	8.74605
305.237	11.035
308.823	12.8025
312.41	14.6139
315.995	17.888
319.579	17.327
323.16	19.6052
326.741	20.6682
330.321	23.1471
333.897	21.0499
337.474	21.9739
341.048	21.7051
344.622	18.2796
348.192	16.3051
351.764	13.8725
355.332	12.7031
358.901	8.84976
362.466	8.40584
366.03	7.22478
369.594	4.84803
373.155	2.94414
376.715	5.10938
380.273	5.79697
383.832	5.77328
387.388	8.85154
390.942	11.9491
394.495	13.5213
398.047	12.6299
401.597	12.2109
405.145	13.6465
408.693	15.6427
412.239	16.25
415.783	16.3266
419.327	16.2384
422.869	16.3706
426.409	15.2749
429.948	15.2395
433.486	15.2351
437.022	15.5012
440.558	13.2252
444.089	16.1408
447.622	17.5738
451.153	18.6774
454.682	20.2865
458.208	21.9717
461.735	23.34
465.259	25.5118
468.783	23.9694
472.306	26.437
475.825	28.5142
479.346	29.7285
482.862	32.1686
486.38	34.1971
489.894	38.9189
493.407	39.4029
496.92	41.6643
500.43	44.1806
503.939	48.0248
507.448	52.4351
510.954	54.1237
514.459	56.5272
517.962	57.8844
521.466	57.7203
524.966	60.2284
528.466	61.0002
531.964	59.692
535.46	60.4683
538.955	60.4442
542.449	59.2294
545.942	53.533
549.433	47.3279
552.923	43.4924
556.412	40.2351
559.899	37.915
563.385	31.6959
566.867	29.3045
570.35	26.6926
573.832	21.7168
577.313	19.43
580.79	18.3094
584.268	17.4667
587.745	16.7337
591.218	16.6042
594.692	15.8681
598.164	14.639
601.634	13.9008
605.104	13.4246
608.57	13.2446
612.037	14.9413
615.501	13.022
618.966	13.8966
622.427	14.9284
625.887	16.0268
629.348	15.3238
632.806	13.7757
636.262	15.0365
639.716	17.02
643.172	13.9442
646.624	12.5628
650.075	10.0684
653.524	11.4883
656.972	10.3522
660.419	7.08365
663.865	7.66286
667.309	5.87605
670.752	2.84176
674.194	2.58652
677.634	3.3407
681.073	2.6649
684.511	1.42518
687.947	3.77841
691.382	2.88642
694.816	3.75839
698.247	4.60761
701.678	7.83561
705.108	10.4607
708.534	13.0898
711.962	14.2384
715.388	17.695
718.81	19.0642
722.234	20.1663
725.654	21.0167
729.075	21.3185
732.492	21.2225
735.91	21.3144
739.325	23.4129
742.741	25.0054
746.153	28.3105
749.564	32.9113
752.976	38.0672
756.385	42.2214
759.792	45.7033
763.2	50.5296
766.604	51.6701
770.008	55.2287
773.41	56.9291
776.811	57.382
780.21	60.1506
783.608	61.4029
787.005	60.6923
790.401	60.3788
793.795	62.6523
797.188	63.7043
800.58	65.0295
803.971	64.5562
807.36	64.7306
810.748	62.5419
814.135	62.0404
817.518	60.8959
820.902	62.0213
824.285	64.9831
827.665	67.0024
831.045	65.7673
834.424	65.3421
837.8	64.5605
841.177	62.724
844.55	61.9883
847.924	57.0893
851.295	56.2949
854.666	52.7576
858.034	51.1309
861.403	50.6153
864.769	50.1157
868.133	49.8167
871.498	52.2658
874.86	53.3926
878.221	53.8898
881.58	54.1761
884.938	51.6218
888.297	51.1152
891.653	50.4006
895.007	50.2528
898.36	50.5277
901.712	46.9015
905.063	47.4659
908.412	46.5713
911.76	45.1707
915.107	42.8524
918.452	42.1218
921.797	40.4482
925.138	38.4416
928.48	33.8556
931.82	32.2294
935.16	29.9129
938.496	28.2852
941.833	26.4711
945.168	21.8153
948.5	17.4789
951.834	16.6364
955.163	13.5146
958.494	10.4039
961.821	6.40743
965.15	6.30289
968.474	10.6711
971.8	16.5695
975.123	20.7208
978.446	25.553
981.766	26.6635
985.084	29.9076
988.402	34.6522
991.72	37.3407
995.035	36.1896
998.349	37.1975
1001.66	38.0957
1004.97	38.9408
1008.28	42.5642
1011.59	45.4627
1014.9	52.7172
1018.21	58.4669
1021.51	64.0101
1024.81	68.4668
1028.12	74.9112
1031.42	83.1149
1034.72	88.8331
1038.02	95.3477
1041.31	100.032
1044.61	106.917
1047.91	112.05
1051.2	114.898
1054.49	112.515
1057.78	112.948
1061.07	108.083
1064.36	103.323
1067.65	96.4608
1070.93	89.8155
1074.22	81.0247
1077.5	71.9646
1080.78	66.8797
1084.06	61.2296
1087.34	54.7449
1090.62	54.2475
1093.9	57.2357
1097.17	59.276
1100.45	61.7329
1103.72	62.361
1106.99	63.9384
1110.27	66.2796
1113.53	65.8714
1116.8	64.1001
1120.07	60.9531
1123.33	58.6576
1126.6	52.6821
1129.86	46.1595
1133.12	40.9555
1136.38	38.7325
1139.64	36.0642
1142.9	30.2321
1146.16	24.999
1149.41	19.4889
1152.67	13.25
1155.92	10.2743
1159.17	4.83411
1162.42	0.0613723
1165.67	-4.73936
1168.92	-1.16898
1172.16	2.45731
1175.41	5.38397
1178.65	6.26716
1181.9	10.7712
1185.14	14.6568
1188.38	20.1817
1191.62	24.6453
1194.86	31.0398
1198.09	35.9109
1201.33	40.5867
1204.56	47.2307
1207.8	54.6227
1211.03	64.019
1214.26	74.3583
1217.49	85.4162
1220.71	94.9959
1223.94	103.172
1227.16	112.677
1230.39	122.651
1233.61	132.126
1236.83	139.877
1240.05	146.75
1243.27	154.158
1246.49	161.938
1249.71	170.639
1252.92	174.065
1256.14	180.056
1259.35	187.689
1262.56	195.48
1265.77	205.691
1268.98	214.175
1272.19	224.258
1275.4	233.482
1278.6	241.557
1281.81	252.85
1285.01	261.509
1288.21	271.69
1291.41	282.164
1294.61	287.786
1297.81	293.922
1301.01	298.545
1304.2	301.834
1307.4	304.147
1310.59	304.98
1313.78	305.084
1316.97	303.502
1320.16	302.758
1323.35	296.878
1326.54	293.542
1329.72	289.184
1332.91	284.048
1336.09	281.394
1339.27	280.628
1342.45	279.545
1345.64	277.744
1348.81	277.26
1351.99	276.097
1355.17	274.028
1358.34	271.845
1361.51	268.386
1364.69	265.045
1367.86	261.792
1371.03	257.007
1374.2	252.517
1377.37	246.537
1380.53	244.275
1383.7	240.181
1386.86	238.752
1390.02	235.205
1393.19	234.312
1396.35	233.051
1399.51	227.948
1402.66	232.33
1405.82	243.729
1408.97	256.068
1412.13	270.936
1415.28	290.665
1418.43	311.42
1421.59	331.533
1424.73	354.882
1427.88	383.207
1431.03	408.629
1434.18	430.48
1437.32	452.065
1440.46	464.701
1443.61	475.735
1446.75	478.985
1449.89	475.784
1453.03	470.069
1456.16	457.497
1459.3	441.1
1462.44	420.065
1465.57	390.521
1468.7	362.137
1471.83	331.319
1474.96	300.004
1478.09	271.323
1481.22	249.035
1484.35	222.431
1487.47	202.495
1490.6	184.213
1493.72	168.489
1496.84	155.937
1499.96	148.371
1503.08	143.193
1506.2	140.019
1509.32	138.394
1512.44	135.176
1515.55	133.989
1518.66	134.89
1521.78	136.649
1524.89	136.396
1528	138.638
1531.11	144.04
1534.21	145.584
1537.32	152.008
1540.43	156.796
1543.53	165.641
1546.63	173.039
1549.74	179.079
1552.84	187.121
1555.94	194.429
1559.03	199.382
1562.13	205.167
1565.23	212.357
1568.32	219.154
1571.42	223.714
1574.51	231.951
1577.6	237.817
1580.69	246.286
1583.78	252.692
1586.87	260.633
1589.95	266.124
1593.04	271.593
1596.12	274.301
1599.21	273.627
1602.29	272.693
1605.37	272.763
1608.45	270.729
1611.53	269.823
1614.6	268.328
1617.68	269.294
1620.75	268.975
1623.83	268.889
1626.9	266.621
1629.97	268.028
1633.04	269.554
1636.11	270.717
1639.18	272.023
1642.25	275.062
1645.31	275.914
1648.38	276.537
1651.44	277.522
1654.5	275.449
1657.56	275.232
1660.62	269.497
1663.68	262.199
1666.74	251.785
1669.8	239.019
1672.85	225.781
1675.91	208.694
1678.96	192.72
1682.01	174.296
1685.06	158.643
1688.11	143.932
1691.16	130.336
1694.21	115.153
1697.25	104.527
1700.3	94.5448
1703.34	84.9304
1706.39	76.9664
1709.43	72.1161
1712.47	66.4903
1715.51	62.2632
1718.54	59.374
1721.58	54.8009
1724.62	51.9135
1727.65	49.323
1730.68	46.5108
1733.72	43.4405
1736.75	40.6281
1739.78	38.6359
1742.81	34.7894
1745.84	33.2228
1748.86	29.1272
1751.89	25.9183
1754.91	22.5208
1757.93	19.565
1760.96	17.3853
1763.98	13.6673
1767	12.2694
1770.02	10.4241
1773.03	9.2203
1776.05	7.09871
1779.07	7.61732
1782.08	7.61925
1785.09	8.38609
1788.11	7.00625
1791.12	6.7498
1794.13	3.22228
1797.13	3.0462
1800.14	2.96139
1803.15	0.871979
1806.15	1.25004
1809.16	1.19856
1812.16	1.94316
1815.16	1.15394
1818.16	0.854148
1821.16	1.24496
1824.16	1.18924
1827.16	1.52092
1830.16	1.05029
1833.15	0.56891
1836.14	0.756832
1839.14	1.25048
1842.13	2.11977
1845.12	2.05564
1848.11	1.79363
1851.1	2.24098
1854.08	2.68585
1857.07	2.24182
1860.05	2.15604
1863.04	0.650374
1866.02	1.05339
1869	2.14838
1871.98	3.19425
1874.96	3.40984
1877.94	3.72977
1880.92	4.74739
1882.51	6.19983
1885.5	6.21569
1888.48	7.0039
1891.47	6.20025
1894.46	7.09069
1897.44	6.32123
1900.42	4.73668
1903.41	6.6609
1906.39	6.9129
1909.37	6.07388
1912.35	5.79893
1915.32	5.63191
1918.3	3.67141
1921.27	4.90717
1924.25	6.09962
1927.22	6.53279
1930.19	5.78394
1933.17	5.44138
1936.14	6.86873
1939.11	8.76591
1942.07	10.0971
1945.04	11.2207
1948.01	11.4768
1950.97	12.2574
1953.93	13.0761
1956.9	11.6792
1959.86	10.3649
1962.82	8.16398
1965.78	7.48057
1968.74	7.12166
1971.69	7.09657
1974.65	8.06636
1977.6	8.4124
1980.56	6.59602
1983.51	4.48932
1986.46	4.97751
1989.41	5.71083
1992.36	6.92758
1995.31	9.26414
1998.26	10.9167
2001.2	9.83622
2004.15	11.1411
2007.09	12.5315
2010.04	12.9964
2012.98	13.3067
2015.92	14.5134
2018.86	11.8254
2021.8	12.3458
2024.73	11.4685
2027.67	11.3549
2030.61	11.4213
2033.54	11.9978
2036.47	12.0406
2039.4	11.5441
2042.33	12.5827
2045.27	12.528
2048.19	12.4987
2051.12	13.3539
2054.05	14.2562
2056.97	16.2373
2059.9	17.9846
2062.82	19.4961
2065.74	20.1945
2068.67	21.2492
2071.59	21.8678
2074.51	21.7964
2077.42	23.1011
2080.34	22.7866
2083.26	23.2653
2086.17	23.9248
2089.09	24.9395
2092	25.5644
2094.91	27.6182
2097.82	31.2873
2100.73	32.5446
2103.64	34.0012
2106.55	34.4245
2109.45	34.5577
2112.36	36.428
2115.26	39.5497
2118.17	43.0836
2121.07	46.3632
2123.97	49.3733
2126.87	51.9906
2129.77	55.6507
2132.67	60.8372
2135.56	64.888
2138.46	72.0478
2141.35	76.4025
2144.25	83.1026
2147.14	90.1284
2150.03	96.0655
2152.92	103.695
2155.81	111.222
2158.7	119.063
2161.59	125.487
2164.47	130.716
2167.36	136.465
2170.24	140.281
2173.13	143.082
2176.01	144.714
2178.89	145.252
2181.77	143.882
2184.65	142.633
2187.53	139.351
2190.4	136.081
2193.28	132.676
2196.16	125.759
2199.03	120.424
2201.9	115.644
2204.77	107.3
2207.64	101.449
2210.51	93.8258
2213.38	87.6331
2216.25	81.4178
2219.12	77.854
2221.98	72.6589
2224.85	68.0741
2227.71	64.088
2230.57	58.2088
2233.43	53.1493
2236.29	49.7041
2239.15	45.8884
2242.01	42.5611
2244.87	40.854
2247.72	39.4134
2250.58	36.8622
2253.43	33.3501
2256.29	32.5985
2259.14	31.0704
2261.99	30.3303
2264.84	28.2111
2267.69	27.529
2270.53	26.0369
2273.38	23.528
2276.23	23.0779
2279.07	21.958
2281.91	19.8696
2284.76	21.7041
2287.6	22.3718
2290.44	19.9075
2293.28	18.3755
2296.12	18.551
2298.96	16.8943
2301.79	15.3744
2304.63	16.2368
2307.46	15.2198
2310.3	15.4533
2313.13	14.741
2315.96	15.5887
2318.79	15.0583
2321.62	13.642
2324.45	12.6195
2327.27	14.3683
2330.1	12.6365
2332.92	13.0695
2335.75	13.5823
2338.57	12.4546
2341.39	10.3407
2344.21	10.2818
2347.04	9.47512
2349.85	8.2604
2352.67	8.07048
2355.49	7.71847
2358.3	6.36177
2361.12	6.46907
2363.93	7.66928
2366.75	8.37574
2369.56	7.81622
2372.37	7.53216
2375.18	9.14134
2377.99	9.40073
2380.8	11.1403
2383.6	12.7278
2386.41	13.8721
2389.21	14.0395
2392.02	14.5298
2394.82	14.1285
2397.62	14.356
2400.42	14.4342
2403.22	14.3357
2406.02	12.7897
2408.82	12.4309
2411.62	11.9608
2414.41	11.828
2417.21	11.7598
2420	11.3745
2422.79	10.6218
2425.59	10.1013
2428.38	10.5655
2431.17	9.56355
2433.95	9.27012
2436.74	8.60617
2439.53	6.83028
2442.31	7.15801
2445.1	6.13112
2447.88	5.92999
2450.67	5.47449
2453.45	4.50608
2456.23	3.97017
2459.01	2.72165
2461.79	0.967209
2464.57	0.830016
2467.34	0.462602
2470.12	2.4075
2472.89	2.88783
2475.67	3.38332
2478.44	5.76779
2481.21	6.03942
2483.98	6.89565
2486.75	5.61244
2489.52	5.14325
2492.29	6.9708
2495.05	7.60571
2497.82	7.04112
2500.58	7.20097
2503.35	6.79557
2506.11	6.97822
2508.87	6.65348
2511.63	5.86958
2514.39	5.93018
2517.15	5.62108
2519.91	6.37364
2522.67	6.8212
2525.42	7.22871
2528.18	7.93008
2530.93	8.98617
2533.69	9.78946
2536.44	10.5666
2539.19	12.1398
2541.94	11.0492
2544.69	11.0287
2547.44	11.8281
2550.18	10.9472
2552.93	12.1798
2555.67	13.2496
2558.42	15.0137
2561.16	15.7353
2563.9	17.2694
2566.64	17.1076
2569.38	17.8188
2572.12	16.1967
2574.86	16.7526
2577.6	15.7888
2580.33	16.3426
2583.07	16.4278
2585.8	16.7137
2588.54	18.9582
2591.27	19.2989
2594	19.4981
2596.73	19.4255
2599.46	18.4635
2602.19	17.5616
2604.92	16.9558
2607.64	16.8294
2610.37	14.6437
2613.09	14.636
2615.82	15.0416
2618.54	15.5788
2621.26	15.3513
2623.98	15.1092
2626.7	16.5181
2629.42	18.4919
2632.14	18.5906
2634.86	18.3704
2637.57	18.7266
2640.29	20.0219
2643	22.3526
2645.71	23.2461
2648.43	25.5372
2651.14	26.2107
2653.85	26.8294
2656.56	26.5886
2659.26	24.6054
2661.97	24.4893
2664.68	22.8249
2667.38	21.1556
2670.09	21.4058
2672.79	18.8794
2675.49	17.8868
2678.19	17.8923
2680.89	19.4985
2683.59	19.8213
2686.29	22.9665
2688.99	25.5048
2691.69	27.8911
2694.38	31.183
2697.08	32.6872
2699.77	36.7099
2702.46	43.7952
2705.15	47.9721
2707.85	51.9588
2710.54	57.0801
2713.22	58.8755
2715.91	60.3422
2718.6	60.5807
2721.29	60.9696
2723.97	60.407
2726.66	59.3988
2729.34	57.9989
2732.02	54.9946
2734.7	52.0974
2737.38	49.0016
2740.06	45.0825
2742.74	41.3872
2745.42	37.9257
2748.09	35.4325
2750.77	31.985
2753.45	29.6172
2756.12	25.1915
2758.79	23.1119
2761.46	20.9424
2764.14	19.9343
2766.8	18.9039
2769.47	16.5745
2772.14	12.9233
2774.81	11.7786
2777.48	9.74015
2780.14	7.84451
2782.8	5.97671
2785.47	4.58834
2788.13	5.24024
2790.79	5.0266
2793.45	4.34328
2796.11	4.8421
2798.77	4.46219
2801.43	4.60955
2804.09	4.10601
2806.74	3.27512
2809.4	2.39699
2812.05	3.34704
2814.71	8.37878
2817.36	20.5019
2820.01	40.578
2822.66	65.1639
2825.31	96.2258
2827.96	130.563
2830.6	166.466
2833.25	206.39
2835.9	248.346
2838.54	290.109
2841.18	333.458
2843.83	375.262
2846.47	414.699
2849.11	454.493
2851.75	501.851
2854.39	554.447
2857.03	606.379
2859.66	654.401
2862.3	696.564
2864.94	731.192
2867.57	758.512
2870.2	778.794
2872.84	794.643
2875.47	807.78
2878.1	820.171
2880.73	834.38
2883.36	845.349
2885.99	857.263
2888.61	863.84
2891.24	869.961
2893.86	873.343
2896.49	877.84
2899.11	880.316
2901.73	882.856
2904.36	888.005
2906.98	896.617
2909.6	908.21
2912.21	930.008
2914.83	961.118
2917.45	994.513
2920.07	1023.23
2922.68	1041.28
2925.29	1051.82
2927.91	1055.35
2930.52	1053.23
2933.13	1046
2935.74	1030.47
2938.35	1009.19
2940.96	981.693
2943.57	949.327
2946.18	911.783
2948.78	869.413
2951.39	826.809
2953.99	780.997
2956.59	737.126
2959.2	693.047
2961.8	648.448
2964.4	606.411
2967	565.679
2969.6	530.005
2972.19	495.91
2974.79	463.45
2977.39	432.941
2979.98	402.489
2982.58	369.593
2985.17	335.748
2987.76	301.782
2990.35	271.781
2992.94	241.133
2995.53	213.618
2998.12	186.121
3000.71	159.486
3003.3	136.524
3005.88	113.782
3008.47	93.9499
3011.05	75.9127
3013.64	59.5425
3016.22	45.5378
3018.8	34.9587
3021.38	25.5102
3023.96	16.0408
3026.54	10.1152
3029.12	6.01499
3031.69	2.37152
3034.27	1.02942
3036.84	2.02514
3039.42	3.24661
3041.99	5.07416
3044.57	6.45946
3047.14	8.21363
3049.71	9.59291
3052.28	10.8528
3054.85	12.9842
3057.41	14.2716
3059.98	14.7856
3062.55	14.66
3065.11	15.0274
3067.68	13.4815
3070.24	12.9509
3072.8	10.3574
3075.36	7.44329
3077.93	5.2217
3080.49	2.39012
3083.04	0.542028
3085.6	-0.117284
3088.16	-0.868673
3090.72	-0.545171
3093.27	0.249224
3095.83	2.38553
3098.38	6.30751
3100.93	9.89662
3103.49	13.4044
3106.04	16.6266
3108.59	20.7698
3111.14	24.2267
3113.69	28.4381
3116.23	33.1785
3118.78	37.5059
3121.33	42.5632
3123.87	48.6241
3126.41	54.7317
3128.96	60.7853
3131.5	66.3449
3134.04	73.2241
3136.58	79.1386
3139.12	87.3485
3141.66	96.5457
3144.2	106.799
3146.74	118.657
3149.27	133.747