File: data/Raman/poly_smoothed/Mb_20_23_14_1x_45s_532 nm_x100_100%_600 gr_mm_01.txt
#Acq. time (s)=	45
#Accumulations=	2
#Range (cm-¹)=	200...3150
#Windows=	2
#Auto scanning=	Off
#Autofocus=	Off
#Macrospot=	Off
#AutoExposure=	Off
#Spike filter=	Multiple accum.
#Delay time (s)=	0
#Binning=	1
#Readout mode=	Signal
#DeNoise=	Off
#ICS correction=	On
#Dark correction=	Off
#Inst. Process=	Off
#Detector Gain=	Best Dynamic Range
#Detector ADC=	20 kHz
#Detector temperature (°C)=	-69.85
#Instrument=	LabRAM HR Evol
#Detector=	Synapse
#Objective=	x100
#Grating=	600 gr/mm
#ND Filter=	100%
#Laser (nm)=	532
#Hole=	100.021
#Range=	Auto
#Laser Pol.=	No
#Raman. Pol.=	No
#Laser Pol. (°)=	-0.0007625
#Raman Pol. (°)=	89.9995
#Collection=	Microscope
#StageXY=	Marzhauser
#StageZ=	Marzhauser
#X (µm)=	-6995.3
#Y (µm)=	2104.4
#Z (µm)=	-74.65
#Full time(mm:ss)=	3:18
#Project=
#Sample=
#Site=
#Title=	Mb_20_23_14_2x_45s_532 nm_x100_100%_600 gr_mm
#Remark=
#Date=	13.07.2022 13:56
#Acquired=	13.07.2022 13:56:58
#Edit:Spike=	10.08.2022 10:28:56
#Base:Fit=	10.08.2022 10:29:19
#Base:Fit=	10.08.2022 10:29:37
#Base:Sub=	10.08.2022 10:32:28
#Filter:Polynom=	16.08.2022 10:13:29
#AxisType[0]=Intens
#AxisUnit[0]=Cnt
#AxisType[1]=Spectr
#AxisUnit[1]=1/cm
200.563	19.4066
204.194	12.9107
207.821	10.1158
211.449	8.05395
215.074	5.47169
218.699	4.10214
222.321	2.22063
225.941	1.91097
229.562	1.80946
233.18	1.33395
236.796	2.02775
240.411	4.28448
244.026	3.92634
247.638	4.46116
251.248	5.25963
254.857	4.164
258.465	6.97197
262.071	8.36044
265.678	7.81045
269.282	5.85535
272.884	7.09292
276.484	6.28821
280.084	7.65987
283.682	7.40259
287.276	6.00443
290.871	4.40959
294.465	5.49411
298.057	7.29659
301.648	9.47527
305.237	10.1451
308.823	13.7973
312.41	17.1594
315.995	21.0237
319.579	24.4523
323.16	26.2634
326.741	29.5113
330.321	27.9957
333.897	29.8599
337.474	30.8511
341.048	30.4781
344.622	30.0597
348.192	26.7948
351.764	22.7079
355.332	19.4094
358.901	19.9457
362.466	18.3391
366.03	16.0319
369.594	12.7628
373.155	9.05295
376.715	6.12454
380.273	6.98585
383.832	8.90052
387.388	12.4143
390.942	14.3815
394.495	16.4894
398.047	20.5848
401.597	22.6891
405.145	22.8035
408.693	23.7816
412.239	24.3886
415.783	25.4339
419.327	28.5231
422.869	30.9747
426.409	30.4702
429.948	30.8007
433.486	30.4692
437.022	28.6916
440.558	29.1269
444.089	31.618
447.622	34.0233
451.153	36.165
454.682	36.1737
458.208	38.0718
461.735	38.3288
465.259	39.3146
468.783	41.3618
472.306	45.0659
475.825	47.2756
479.346	49.5251
482.862	51.2215
486.38	53.7455
489.894	54.2798
493.407	55.0531
496.92	59.0813
500.43	60.2097
503.939	61.2375
507.448	60.9244
510.954	63.2731
514.459	61.5645
517.962	60.7374
521.466	59.2524
524.966	59.1153
528.466	59.4331
531.964	60.255
535.46	56.741
538.955	53.419
542.449	51.9511
545.942	48.1474
549.433	45.8707
552.923	41.5244
556.412	38.9202
559.899	37.842
563.385	36.9231
566.867	35.7203
570.35	33.0298
573.832	31.5959
577.313	27.5576
580.79	25.621
584.268	23.4264
587.745	18.9855
591.218	14.271
594.692	12.2662
598.164	12.5534
601.634	9.47066
605.104	10.3232
608.57	12.6998
612.037	10.0985
615.501	9.38615
618.966	10.4888
622.427	11.2555
625.887	13.5243
629.348	13.2521
632.806	15.9164
636.262	16.6332
639.716	17.7992
643.172	20.2528
646.624	23.244
650.075	21.522
653.524	21.7896
656.972	21.124
660.419	18.8637
663.865	17.7905
667.309	15.5253
670.752	13.6426
674.194	10.3705
677.634	10.9625
681.073	12.3361
684.511	13.071
687.947	14.4958
691.382	15.9762
694.816	14.5295
698.247	15.1672
701.678	19.2697
705.108	21.3198
708.534	22.1607
711.962	23.3751
715.388	24.4128
718.81	24.485
722.234	25.0938
725.654	23.6078
729.075	24.98
732.492	25.3104
735.91	25.4984
739.325	25.5965
742.741	24.8309
746.153	28.3694
749.564	29.2796
752.976	31.2195
756.385	33.3477
759.792	36.5595
763.2	39.6912
766.604	42.2378
770.008	45.2949
773.41	47.2659
776.811	48.3336
780.21	52.4747
783.608	54.9457
787.005	58.972
790.401	59.1957
793.795	64.0511
797.188	66.3432
800.58	66.9338
803.971	66.0209
807.36	67.1533
810.748	68.7458
814.135	72.2078
817.518	72.328
820.902	73.6352
824.285	75.2927
827.665	76.5503
831.045	78.1122
834.424	77.4845
837.8	76.3495
841.177	75.0311
844.55	72.7963
847.924	69.3581
851.295	65.5242
854.666	64.2314
858.034	63.2179
861.403	61.7462
864.769	61.4898
868.133	59.4072
871.498	58.921
874.86	58.9192
878.221	56.773
881.58	54.4051
884.938	52.3604
888.297	50.8602
891.653	53.1574
895.007	56.8199
898.36	55.6893
901.712	55.4654
905.063	55.5702
908.412	53.9361
911.76	51.5549
915.107	51.7772
918.452	50.054
921.797	47.1319
925.138	46.79
928.48	45.29
931.82	42.9816
935.16	40.6438
938.496	41.6997
941.833	38.2911
945.168	36.0721
948.5	33.726
951.834	31.827
955.163	29.9253
958.494	24.9958
961.821	23.9553
965.15	28.6339
968.474	28.7204
971.8	30.7769
975.123	34.2239
978.446	36.8509
981.766	37.2542
985.084	39.2257
988.402	40.7302
991.72	44.3178
995.035	46.6587
998.349	45.58
1001.66	47.4189
1004.97	50.3697
1008.28	55.7637
1011.59	59.7565
1014.9	61.7109
1018.21	67.925
1021.51	71.0755
1024.81	78.1042
1028.12	82.4688
1031.42	87.0057
1034.72	88.4216
1038.02	90.3202
1041.31	91.5388
1044.61	95.896
1047.91	98.173
1051.2	98.5589
1054.49	97.6589
1057.78	96.795
1061.07	95.8833
1064.36	92.7796
1067.65	90.1906
1070.93	84.6224
1074.22	78.7793
1077.5	70.8987
1080.78	65.7141
1084.06	62.2324
1087.34	61.875
1090.62	60.8804
1093.9	61.7315
1097.17	62.8812
1100.45	63.4665
1103.72	64.4386
1106.99	64.7459
1110.27	63.267
1113.53	62.7162
1116.8	57.7034
1120.07	53.3706
1123.33	49.5512
1126.6	47.9797
1129.86	45.5767
1133.12	42.9969
1136.38	39.164
1139.64	36.0512
1142.9	33.2515
1146.16	27.895
1149.41	22.3843
1152.67	16.9126
1155.92	12.7732
1159.17	9.65059
1162.42	7.22818
1165.67	5.44826
1168.92	4.69729
1172.16	3.81204
1175.41	3.94498
1178.65	4.59448
1181.9	4.90438
1185.14	8.17749
1188.38	9.53482
1191.62	11.8628
1194.86	14.2173
1198.09	15.3946
1201.33	19.6475
1204.56	27.8066
1207.8	32.4514
1211.03	40.1679
1214.26	47.4009
1217.49	56.468
1220.71	64.8129
1223.94	73.6785
1227.16	82.6775
1230.39	90.2796
1233.61	99.9192
1236.83	105.671
1240.05	109.397
1243.27	114.395
1246.49	116.998
1249.71	120.292
1252.92	123.223
1256.14	127.612
1259.35	132.287
1262.56	138.519
1265.77	141.257
1268.98	146.921
1272.19	152.168
1275.4	160.16
1278.6	165.835
1281.81	174.337
1285.01	182.842
1288.21	190.992
1291.41	200.054
1294.61	207.751
1297.81	212.895
1301.01	216.807
1304.2	220.837
1307.4	222.854
1310.59	223.159
1313.78	221.749
1316.97	217.975
1320.16	213.613
1323.35	209.858
1326.54	204.766
1329.72	197.823
1332.91	190.283
1336.09	184.21
1339.27	178.424
1342.45	171.758
1345.64	164.708
1348.81	161.649
1351.99	158.531
1355.17	156.399
1358.34	153.863
1361.51	154.117
1364.69	151.298
1367.86	149.048
1371.03	147.957
1374.2	144.568
1377.37	142.4
1380.53	142.077
1383.7	141.103
1386.86	141.495
1390.02	140.307
1393.19	139.614
1396.35	139.369
1399.51	139.52
1402.66	144.337
1405.82	150.836
1408.97	156.849
1412.13	170.192
1415.28	182.075
1418.43	199.533
1421.59	217.635
1424.73	238.497
1427.88	259.456
1431.03	281.486
1434.18	300.289
1437.32	317.182
1440.46	327.716
1443.61	334.677
1446.75	336.663
1449.89	334.821
1453.03	328.66
1456.16	319.365
1459.3	304.01
1462.44	286.511
1465.57	264.659
1468.7	241.431
1471.83	217.682
1474.96	194.531
1478.09	172.746
1481.22	152.85
1484.35	134.054
1487.47	115.458
1490.6	100.637
1493.72	88.34
1496.84	80.6522
1499.96	74.5051
1503.08	69.8958
1506.2	65.9565
1509.32	61.3527
1512.44	57.4437
1515.55	54.4543
1518.66	51.7264
1521.78	50.4309
1524.89	49.9402
1528	51.2136
1531.11	52.4621
1534.21	53.2419
1537.32	55.6391
1540.43	58.7087
1543.53	61.1885
1546.63	66.2962
1549.74	70.285
1552.84	75.2334
1555.94	79.4142
1559.03	83.0592
1562.13	85.4492
1565.23	89.0622
1568.32	96.7638
1571.42	105.05
1574.51	113.097
1577.6	119.799
1580.69	124.753
1583.78	128.079
1586.87	131.968
1589.95	135.594
1593.04	137.619
1596.12	139.18
1599.21	140.1
1602.29	138.169
1605.37	137.531
1608.45	136.381
1611.53	135.343
1614.6	137.667
1617.68	134.969
1620.75	135.758
1623.83	136.736
1626.9	139.083
1629.97	142.652
1633.04	146.875
1636.11	152.989
1639.18	158.386
1642.25	168.271
1645.31	177.412
1648.38	183.763
1651.44	187.365
1654.5	190.526
1657.56	190.74
1660.62	188.311
1663.68	185.121
1666.74	180.538
1669.8	172.195
1672.85	163.702
1675.91	153.686
1678.96	142.523
1682.01	132.075
1685.06	119.544
1688.11	105.912
1691.16	94.6521
1694.21	81.4519
1697.25	71.8712
1700.3	64.8743
1703.34	59.0436
1706.39	52.135
1709.43	47.4281
1712.47	43.3843
1715.51	40.2571
1718.54	38.421
1721.58	35.672
1724.62	34.0665
1727.65	32.3158
1730.68	33.4189
1733.72	30.3436
1736.75	28.9941
1739.78	30.0252
1742.81	29.4903
1745.84	29.0331
1748.86	27.3376
1751.89	25.7965
1754.91	21.5433
1757.93	19.2341
1760.96	15.0998
1763.98	11.5306
1767	11.2147
1770.02	10.5669
1773.03	12.8333
1776.05	13.1491
1779.07	12.9882
1782.08	12.4333
1785.09	12.2117
1788.11	13.4444
1791.12	14.1522
1794.13	14.4411
1797.13	13.9366
1800.14	13.8853
1803.15	14.7633
1806.15	13.7485
1809.16	11.6499
1812.16	10.6564
1815.16	10.5109
1818.16	9.48029
1821.16	9.27532
1824.16	6.34638
1827.16	4.91613
1830.16	3.06575
1833.15	1.99172
1836.14	0.190488
1839.14	4.19928
1842.13	3.62722
1845.12	4.38599
1848.11	5.06105
1851.1	3.62132
1854.08	4.78891
1857.07	4.96212
1860.05	5.62372
1863.04	5.95024
1866.02	4.97533
1869	4.33884
1871.98	4.92832
1874.96	4.31456
1877.94	2.71254
1880.92	2.02599
1882.51	1.08343
1885.5	2.38702
1888.48	1.81943
1891.47	2.98068
1894.46	3.7917
1897.44	3.59013
1900.42	3.94819
1903.41	4.86567
1906.39	5.43693
1909.37	6.95506
1912.35	6.44108
1915.32	5.20987
1918.3	5.0321
1921.27	5.21323
1924.25	5.20008
1927.22	5.47375
1930.19	4.3269
1933.17	3.26343
1936.14	2.49552
1939.11	4.01388
1942.07	3.47329
1945.04	3.86381
1948.01	4.51927
1950.97	5.66084
1953.93	6.3741
1956.9	5.85331
1959.86	7.13177
1962.82	6.91635
1965.78	7.13058
1968.74	7.71978
1971.69	8.52811
1974.65	9.02787
1977.6	8.65101
1980.56	7.88586
1983.51	5.94548
1986.46	5.29994
1989.41	6.16622
1992.36	6.00681
1995.31	5.05638
1998.26	4.87855
2001.2	3.97182
2004.15	3.97306
2007.09	4.75382
2010.04	6.19649
2012.98	6.82489
2015.92	8.26368
2018.86	8.8533
2021.8	11.1198
2024.73	11.1924
2027.67	11.9508
2030.61	12.695
2033.54	13.5252
2036.47	13.5575
2039.4	14.2597
2042.33	14.5177
2045.27	14.7004
2048.19	16.4344
2051.12	15.3327
2054.05	14.6254
2056.97	15.8446
2059.9	16.3124
2062.82	16.6375
2065.74	15.4773
2068.67	16.1079
2071.59	16.6823
2074.51	19.0891
2077.42	20.3667
2080.34	20.5528
2083.26	20.3549
2086.17	21.1371
2089.09	22.8023
2092	24.1789
2094.91	24.8319
2097.82	24.6853
2100.73	25.0932
2103.64	25.5832
2106.55	26.5571
2109.45	27.8139
2112.36	31.6598
2115.26	32.7093
2118.17	35.7455
2121.07	37.026
2123.97	38.9149
2126.87	42.312
2129.77	46.9466
2132.67	51.4041
2135.56	54.868
2138.46	58.2674
2141.35	63.9198
2144.25	69.2269
2147.14	72.8942
2150.03	76.9222
2152.92	82.6255
2155.81	89.106
2158.7	93.8144
2161.59	98.2423
2164.47	100.79
2167.36	103.02
2170.24	105.344
2173.13	107.08
2176.01	107.885
2178.89	108.125
2181.77	108.267
2184.65	106.729
2187.53	103.204
2190.4	99.7186
2193.28	95.5898
2196.16	90.7515
2199.03	87.5199
2201.9	83.0622
2204.77	77.8708
2207.64	71.3012
2210.51	66.3942
2213.38	59.5029
2216.25	54.6559
2219.12	49.8062
2221.98	47.0723
2224.85	42.4278
2227.71	37.9974
2230.57	34.2542
2233.43	31.4919
2236.29	28.9232
2239.15	26.9681
2242.01	24.0737
2244.87	22.1724
2247.72	21.0023
2250.58	20.2025
2253.43	20.2
2256.29	19.3862
2259.14	17.7528
2261.99	17.9281
2264.84	18.114
2267.69	18.3946
2270.53	19.3129
2273.38	18.6598
2276.23	17.1415
2279.07	17.0022
2281.91	15.3328
2284.76	13.8324
2287.6	13.9263
2290.44	12.1486
2293.28	11.2729
2296.12	9.69678
2298.96	8.59285
2301.79	7.15498
2304.63	7.78738
2307.46	7.73297
2310.3	6.38373
2313.13	5.99886
2315.96	6.57759
2318.79	6.45388
2321.62	6.10649
2324.45	5.33787
2327.27	4.74886
2330.1	2.88849
2332.92	2.20457
2335.75	0.347403
2338.57	0.32534
2341.39	-0.927311
2344.21	-0.994065
2347.04	-0.524326
2349.85	-0.671517
2352.67	-2.15684
2355.49	-0.700749
2358.3	-0.181706
2361.12	-1.00183
2363.93	-0.37668
2366.75	-0.162527
2369.56	0.938265
2372.37	2.56818
2375.18	3.23119
2377.99	3.79614
2380.8	5.5333
2383.6	5.2448
2386.41	5.05292
2389.21	4.52522
2392.02	4.62581
2394.82	4.30726
2397.62	4.57767
2400.42	4.34938
2403.22	5.45238
2406.02	5.62521
2408.82	5.04334
2411.62	5.79501
2414.41	5.29182
2417.21	4.16431
2420	4.23315
2422.79	3.72562
2425.59	6.13091
2428.38	5.41829
2431.17	6.49633
2433.95	6.49202
2436.74	6.84998
2439.53	6.33753
2442.31	5.24132
2445.1	6.12571
2447.88	6.91485
2450.67	5.71658
2453.45	5.90113
2456.23	5.4455
2459.01	7.00358
2461.79	7.11878
2464.57	6.6818
2467.34	7.96878
2470.12	8.5021
2472.89	7.02187
2475.67	6.72899
2478.44	6.06194
2481.21	4.16561
2483.98	3.00003
2486.75	3.61992
2489.52	2.68465
2492.29	5.10507
2495.05	5.32346
2497.82	5.10337
2500.58	4.70766
2503.35	3.81137
2506.11	3.08914
2508.87	2.79615
2511.63	3.95617
2514.39	4.55384
2517.15	3.81922
2519.91	4.34994
2522.67	3.54685
2525.42	4.07857
2528.18	3.75917
2530.93	2.3709
2533.69	3.60263
2536.44	4.90322
2539.19	4.44086
2541.94	5.06526
2544.69	6.28771
2547.44	6.20517
2550.18	7.22874
2552.93	9.4184
2555.67	11.4915
2558.42	13.4644
2561.16	13.6767
2563.9	15.115
2566.64	14.003
2569.38	13.7084
2572.12	14.0307
2574.86	13.7758
2577.6	13.6765
2580.33	12.9978
2583.07	12.1015
2585.8	10.3168
2588.54	8.86303
2591.27	5.68943
2594	4.57413
2596.73	3.68387
2599.46	3.55314
2602.19	3.36116
2604.92	3.45831
2607.64	3.55531
2610.37	5.66135
2613.09	5.82979
2615.82	7.51254
2618.54	9.44732
2621.26	10.8474
2623.98	12.1563
2626.7	12.3376
2629.42	13.444
2632.14	14.8686
2634.86	16.1199
2637.57	17.5865
2640.29	18.0213
2643	19.8673
2645.71	20.8604
2648.43	21.0124
2651.14	19.6515
2653.85	18.8374
2656.56	16.8814
2659.26	18.4151
2661.97	19.0285
2664.68	19.6066
2667.38	20.2484
2670.09	19.281
2672.79	20.1311
2675.49	20.483
2678.19	20.2394
2680.89	21.2013
2683.59	22.395
2686.29	22.8715
2688.99	22.9142
2691.69	23.1583
2694.38	24.0648
2697.08	26.988
2699.77	29.6671
2702.46	31.4424
2705.15	33.2658
2707.85	35.1225
2710.54	35.1281
2713.22	34.6913
2715.91	34.7499
2718.6	33.8573
2721.29	35.5545
2723.97	36.342
2726.66	35.5948
2729.34	34.6873
2732.02	33.0877
2734.7	31.3392
2737.38	30.9463
2740.06	28.2985
2742.74	26.1057
2745.42	24.3028
2748.09	22.4319
2750.77	21.6897
2753.45	20.383
2756.12	18.4825
2758.79	16.5316
2761.46	15.1661
2764.14	13.0326
2766.8	11.5469
2769.47	10.3533
2772.14	10.8034
2774.81	8.35569
2777.48	7.45498
2780.14	8.29689
2782.8	7.29534
2785.47	8.61052
2788.13	9.5872
2790.79	7.27296
2793.45	7.36048
2796.11	7.6514
2798.77	8.52571
2801.43	9.66225
2804.09	10.8334
2806.74	9.31458
2809.4	10.2365
2812.05	10.1372
2814.71	12.7846
2817.36	17.9527
2820.01	28.2903
2822.66	41.7918
2825.31	58.9447
2827.96	80.8051
2830.6	106.424
2833.25	132.609
2835.9	161.096
2838.54	188.465
2841.18	218.896
2843.83	252.389
2846.47	285.852
2849.11	321.203
2851.75	354.517
2854.39	388.312
2857.03	422.214
2859.66	454.646
2862.3	483.867
2864.94	509.079
2867.57	529.322
2870.2	547.377
2872.84	560.349
2875.47	573.951
2878.1	587.21
2880.73	601.569
2883.36	616.739
2885.99	631.522
2888.61	645.273
2891.24	660.556
2893.86	675.515
2896.49	688.499
2899.11	703.282
2901.73	720.267
2904.36	740.367
2906.98	763.864
2909.6	790.002
2912.21	816.56
2914.83	842.375
2917.45	865.877
2920.07	886.199
2922.68	901.337
2925.29	910.617
2927.91	913.199
2930.52	906.397
2933.13	898.664
2935.74	885.143
2938.35	866.994
2940.96	845.654
2943.57	818.41
2946.18	789.24
2948.78	755.122
2951.39	720.949
2953.99	685.081
2956.59	649.705
2959.2	612.545
2961.8	576.893
2964.4	543.956
2967	512.669
2969.6	484.431
2972.19	455.512
2974.79	426.95
2977.39	399.116
2979.98	368.697
2982.58	338.12
2985.17	307.624
2987.76	276.1
2990.35	245.37
2992.94	215.937
2995.53	187.803
2998.12	162.831
3000.71	139.59
3003.3	118.039
3005.88	97.7614
3008.47	80.6287
3011.05	63.76
3013.64	48.1572
3016.22	38.2763
3018.8	29.6007
3021.38	20.9331
3023.96	15.5711
3026.54	10.0274
3029.12	6.65599
3031.69	4.93538
3034.27	4.35859
3036.84	3.58014
3039.42	6.98829
3041.99	7.9514
3044.57	9.32263
3047.14	11.3781
3049.71	12.2431
3052.28	14.3575
3054.85	16.2305
3057.41	16.0064
3059.98	15.5363
3062.55	15.8491
3065.11	15.0107
3067.68	13.7919
3070.24	11.9625
3072.8	10.2708
3075.36	9.036
3077.93	6.82176
3080.49	5.11529
3083.04	3.15959
3085.6	1.68831
3088.16	0.352419
3090.72	-0.86826
3093.27	-2.50752
3095.83	-1.19686
3098.38	0.272186
3100.93	2.50056
3103.49	3.91802
3106.04	4.688
3108.59	6.09431
3111.14	9.17969
3113.69	11.6221
3116.23	14.7951
3118.78	16.9734
3121.33	19.7366
3123.87	23.8135
3126.41	28.2772
3128.96	32.4659
3131.5	37.1331
3134.04	43.1521
3136.58	48.8676
3139.12	54.4908
3141.66	60.6995
3144.2	68.3775
3146.74	76.8311
3149.27	84.5875