File: data/Raman/poly_smoothed/Mb_20_23_25_1x_45s_532 nm_x100_100%_600 gr_mm_01.txt
#Acq. time (s)=	45
#Accumulations=	2
#Range (cm-¹)=	200...3150
#Windows=	2
#Auto scanning=	Off
#Autofocus=	Off
#Macrospot=	Off
#AutoExposure=	Off
#Spike filter=	Multiple accum.
#Delay time (s)=	0
#Binning=	1
#Readout mode=	Signal
#DeNoise=	Off
#ICS correction=	On
#Dark correction=	Off
#Inst. Process=	Off
#Detector Gain=	Best Dynamic Range
#Detector ADC=	20 kHz
#Detector temperature (°C)=	-69.85
#Instrument=	LabRAM HR Evol
#Detector=	Synapse
#Objective=	x100
#Grating=	600 gr/mm
#ND Filter=	100%
#Laser (nm)=	532
#Hole=	100.021
#Range=	Auto
#Laser Pol.=	No
#Raman. Pol.=	No
#Laser Pol. (°)=	-0.0007625
#Raman Pol. (°)=	89.9995
#Collection=	Microscope
#StageXY=	Marzhauser
#StageZ=	Marzhauser
#X (µm)=	-6926.9
#Y (µm)=	2037.5
#Z (µm)=	-74.5
#Full time(mm:ss)=	3:18
#Project=
#Sample=
#Site=
#Title=	Mb_20_23_25_2x_45s_532 nm_x100_100%_600 gr_mm
#Remark=
#Date=	13.07.2022 15:07
#Acquired=	13.07.2022 15:07:40
#Base:Fit=	10.08.2022 10:29:37
#Base:Sub=	10.08.2022 10:33:46
#Filter:Polynom=	16.08.2022 10:13:29
#AxisType[0]=Intens
#AxisUnit[0]=Cnt
#AxisType[1]=Spectr
#AxisUnit[1]=1/cm
200.563	120.995
204.194	108.936
207.821	97.9716
211.449	87.1171
215.074	78.031
218.699	70.1751
222.321	65.1015
225.941	61.5022
229.562	58.706
233.18	53.8917
236.796	49.5685
240.411	45.2697
244.026	43.5749
247.638	40.5319
251.248	39.006
254.857	35.409
258.465	33.149
262.071	30.4234
265.678	25.3601
269.282	23.2791
272.884	22.367
276.484	21.0928
280.084	15.8951
283.682	11.5665
287.276	8.79734
290.871	6.64336
294.465	4.26047
298.057	2.55856
301.648	2.34267
305.237	3.84139
308.823	5.71491
312.41	7.44737
315.995	8.33196
319.579	8.20411
323.16	9.34426
326.741	13.0087
330.321	14.4271
333.897	16.6474
337.474	16.6191
341.048	15.5145
344.622	14.6048
348.192	15.5094
351.764	15.0055
355.332	15.1995
358.901	13.8589
362.466	11.6845
366.03	11.1032
369.594	9.40516
373.155	5.88191
376.715	3.86554
380.273	4.18137
383.832	4.31886
387.388	2.71588
390.942	2.98643
394.495	3.46053
398.047	2.17208
401.597	1.63949
405.145	2.51472
408.693	3.01551
412.239	4.74785
415.783	5.32369
419.327	5.27586
422.869	4.82984
426.409	4.55966
429.948	3.63547
433.486	4.6794
437.022	4.32494
440.558	3.80075
444.089	3.34969
447.622	5.24523
451.153	6.04369
454.682	7.57563
458.208	7.71699
461.735	6.90259
465.259	8.06882
468.783	10.0493
472.306	10.011
475.825	10.4527
479.346	10.8056
482.862	11.6799
486.38	13.8852
489.894	16.3269
493.407	18.3829
496.92	21.9791
500.43	25.3702
503.939	26.4691
507.448	26.9605
510.954	28.4126
514.459	29.917
517.962	30.2991
521.466	33.6898
524.966	34.9331
528.466	36.1485
531.964	35.1594
535.46	35.2842
538.955	34.4986
542.449	33.5555
545.942	29.6877
549.433	27.4202
552.923	25.6274
556.412	22.2948
559.899	21.0426
563.385	18.4542
566.867	16.1429
570.35	14.9726
573.832	14.0158
577.313	12.6045
580.79	10.7334
584.268	9.89909
587.745	6.18238
591.218	6.11954
594.692	5.66817
598.164	6.67142
601.634	6.31796
605.104	7.34533
608.57	10.3254
612.037	9.56136
615.501	10.022
618.966	8.83778
622.427	9.21505
625.887	9.7469
629.348	9.93958
632.806	10.3934
636.262	11.1767
639.716	12.9885
643.172	14.6164
646.624	16.3225
650.075	15.8787
653.524	13.3078
656.972	14.2726
660.419	14.3382
663.865	14.6051
667.309	14.5308
670.752	15.634
674.194	16.8495
677.634	17.7242
681.073	18.2452
684.511	19.9888
687.947	20.6805
691.382	24.2314
694.816	25.056
698.247	26.0027
701.678	25.259
705.108	26.778
708.534	29.3702
711.962	28.9497
715.388	29.8697
718.81	31.4996
722.234	33.7869
725.654	35.1277
729.075	35.3106
732.492	35.479
735.91	34.2925
739.325	39.3717
742.741	42.2373
746.153	46.4958
749.564	49.4101
752.976	53.0734
756.385	56.9528
759.792	59.213
763.2	61.632
766.604	65.0498
770.008	67.5283
773.41	70.0635
776.811	71.7796
780.21	73.7637
783.608	77.1761
787.005	79.924
790.401	82.4179
793.795	81.3899
797.188	82.6913
800.58	85.305
803.971	85.6496
807.36	84.5186
810.748	86.3796
814.135	87.6591
817.518	88.673
820.902	90.5135
824.285	94.2653
827.665	94.0493
831.045	95.3253
834.424	94.8956
837.8	95.6759
841.177	93.0757
844.55	89.051
847.924	86.8013
851.295	85.3054
854.666	83.0725
858.034	82.6352
861.403	81.2511
864.769	82.1781
868.133	81.4761
871.498	78.9225
874.86	76.6783
878.221	75.5192
881.58	72.9381
884.938	71.2461
888.297	71.0369
891.653	70.428
895.007	70.8371
898.36	69.7419
901.712	66.6046
905.063	65.896
908.412	66.0562
911.76	66.73
915.107	65.7258
918.452	64.3091
921.797	64.2319
925.138	60.9378
928.48	60.0201
931.82	58.6
935.16	55.9192
938.496	55.5744
941.833	53.2505
945.168	50.1655
948.5	49.94
951.834	48.9946
955.163	46.378
958.494	43.5737
961.821	40.2198
965.15	38.6962
968.474	42.0811
971.8	46.0411
975.123	47.2531
978.446	49.2026
981.766	49.7772
985.084	51.5131
988.402	53.6116
991.72	55.024
995.035	54.6361
998.349	55.0666
1001.66	56.1107
1004.97	55.6645
1008.28	55.7485
1011.59	56.2569
1014.9	57.1252
1018.21	59.2942
1021.51	59.8553
1024.81	60.7053
1028.12	63.0101
1031.42	64.9056
1034.72	67.217
1038.02	69.0758
1041.31	68.2608
1044.61	72.483
1047.91	78.7865
1051.2	83.7585
1054.49	84.2034
1057.78	83.4033
1061.07	83.3559
1064.36	80.9257
1067.65	79.9265
1070.93	76.0564
1074.22	73.6056
1077.5	72.3751
1080.78	69.8727
1084.06	66.9869
1087.34	64.9186
1090.62	62.7805
1093.9	62.0563
1097.17	61.9918
1100.45	60.0892
1103.72	59.4142
1106.99	60.4228
1110.27	60.6997
1113.53	59.9136
1116.8	58.4597
1120.07	57.9829
1123.33	55.9198
1126.6	53.7918
1129.86	52.4433
1133.12	47.6291
1136.38	44.6595
1139.64	39.9132
1142.9	35.8188
1146.16	30.877
1149.41	28.1693
1152.67	23.4069
1155.92	17.7881
1159.17	12.8135
1162.42	7.79097
1165.67	4.47201
1168.92	3.89105
1172.16	3.15814
1175.41	4.53625
1178.65	4.15025
1181.9	5.86877
1185.14	4.84437
1188.38	6.55308
1191.62	9.28975
1194.86	12.4834
1198.09	14.631
1201.33	17.9861
1204.56	22.9957
1207.8	25.0209
1211.03	31.6812
1214.26	37.7056
1217.49	43.4786
1220.71	47.168
1223.94	52.4192
1227.16	56.7928
1230.39	62.107
1233.61	65.9259
1236.83	70.78
1240.05	76.7228
1243.27	81.7876
1246.49	84.8914
1249.71	88.909
1252.92	89.9384
1256.14	89.5553
1259.35	92.8611
1262.56	97.5614
1265.77	102.074
1268.98	109.505
1272.19	116.608
1275.4	123.773
1278.6	129.158
1281.81	135.832
1285.01	142.554
1288.21	148.984
1291.41	154.381
1294.61	157.751
1297.81	161.606
1301.01	162.895
1304.2	164.877
1307.4	168.656
1310.59	170.19
1313.78	169.114
1316.97	169.014
1320.16	166.368
1323.35	160.235
1326.54	155.912
1329.72	148.656
1332.91	142.318
1336.09	138.625
1339.27	133.921
1342.45	129.909
1345.64	128.092
1348.81	124.819
1351.99	121.297
1355.17	118.346
1358.34	113.789
1361.51	110.937
1364.69	108.879
1367.86	106.631
1371.03	105.031
1374.2	103.032
1377.37	100.264
1380.53	100.269
1383.7	100.944
1386.86	101.21
1390.02	101.141
1393.19	100.668
1396.35	100.124
1399.51	99.5304
1402.66	101.831
1405.82	106.669
1408.97	113.553
1412.13	125.074
1415.28	137.589
1418.43	151.933
1421.59	168.889
1424.73	188.578
1427.88	206.171
1431.03	223.768
1434.18	241.299
1437.32	255.944
1440.46	268.809
1443.61	278.49
1446.75	283.287
1449.89	284.033
1453.03	280.193
1456.16	274.672
1459.3	267.27
1462.44	256.442
1465.57	241.554
1468.7	225.037
1471.83	205.782
1474.96	187.902
1478.09	169.468
1481.22	151.712
1484.35	134.957
1487.47	120.117
1490.6	108.197
1493.72	96.7429
1496.84	85.039
1499.96	76.6613
1503.08	68.6976
1506.2	61.1719
1509.32	54.6598
1512.44	49.0409
1515.55	44.3451
1518.66	39.5183
1521.78	36.4495
1524.89	31.881
1528	30.4138
1531.11	31.4277
1534.21	33.6251
1537.32	37.2986
1540.43	40.1201
1543.53	44.2677
1546.63	46.8522
1549.74	48.7195
1552.84	51.5307
1555.94	54.9861
1559.03	56.9465
1562.13	59.5846
1565.23	63.348
1568.32	67.1732
1571.42	70.7256
1574.51	74.2256
1577.6	78.2023
1580.69	82.2346
1583.78	87.6384
1586.87	91.3084
1589.95	93.8084
1593.04	97.6777
1596.12	100.165
1599.21	101.25
1602.29	102.388
1605.37	103.08
1608.45	105.601
1611.53	108.452
1614.6	109.393
1617.68	111.376
1620.75	112.549
1623.83	114.095
1626.9	116.648
1629.97	119.862
1633.04	122.848
1636.11	126.407
1639.18	130.019
1642.25	135.229
1645.31	139.313
1648.38	141.656
1651.44	144.772
1654.5	147.683
1657.56	147.39
1660.62	146.588
1663.68	143.559
1666.74	139.294
1669.8	134.336
1672.85	125.277
1675.91	117.57
1678.96	107.591
1682.01	99.4952
1685.06	88.7952
1688.11	78.2722
1691.16	68.0324
1694.21	60.0565
1697.25	51.87
1700.3	44.1965
1703.34	39.8915
1706.39	34.7382
1709.43	30.4712
1712.47	26.772
1715.51	24.5791
1718.54	23.4641
1721.58	21.9001
1724.62	21.4994
1727.65	22.0764
1730.68	21.4826
1733.72	20.469
1736.75	19.3591
1739.78	18.5771
1742.81	18.1373
1745.84	16.2464
1748.86	13.7537
1751.89	13.2588
1754.91	11.5017
1757.93	9.07002
1760.96	7.10024
1763.98	5.28938
1767	3.64462
1770.02	1.89573
1773.03	0.299929
1776.05	-0.701294
1779.07	-0.571319
1782.08	-2.15467
1785.09	-2.36704
1788.11	-2.48798
1791.12	-1.70973
1794.13	-1.21327
1797.13	-1.19847
1800.14	-0.931148
1803.15	-1.18951
1806.15	-0.673077
1809.16	0.388299
1812.16	1.48666
1815.16	3.03725
1818.16	2.60844
1821.16	2.69591
1824.16	3.23078
1827.16	4.1738
1830.16	4.24783
1833.15	4.48154
1836.14	4.94045
1839.14	5.23797
1842.13	4.12291
1845.12	3.61367
1848.11	2.38932
1851.1	3.03734
1854.08	1.7938
1857.07	1.87809
1860.05	2.13419
1863.04	1.20566
1866.02	1.36212
1869	2.42401
1871.98	1.94146
1874.96	2.56688
1877.94	2.5809
1880.92	3.02533
1882.51	3.4417
1885.5	4.26866
1888.48	3.61089
1891.47	3.12984
1894.46	4.2266
1897.44	4.51494
1900.42	4.07341
1903.41	3.57433
1906.39	3.18759
1909.37	2.96943
1912.35	3.2434
1915.32	2.85959
1918.3	3.81318
1921.27	3.94512
1924.25	4.68988
1927.22	3.5136
1930.19	4.38333
1933.17	4.87594
1936.14	4.80426
1939.11	5.87088
1942.07	6.95172
1945.04	6.80833
1948.01	6.68188
1950.97	6.7628
1953.93	8.40633
1956.9	9.11216
1959.86	7.24766
1962.82	6.31511
1965.78	6.46806
1968.74	5.56039
1971.69	5.26047
1974.65	4.63083
1977.6	5.83271
1980.56	6.50046
1983.51	7.46398
1986.46	8.19705
1989.41	8.36174
1992.36	8.27529
1995.31	8.30336
1998.26	7.82597
2001.2	6.54689
2004.15	8.77911
2007.09	8.74491
2010.04	8.80751
2012.98	9.27145
2015.92	9.72449
2018.86	9.12867
2021.8	9.51408
2024.73	9.80995
2027.67	9.48758
2030.61	9.52922
2033.54	8.97397
2036.47	9.84264
2039.4	10.4496
2042.33	10.4344
2045.27	9.51373
2048.19	9.6526
2051.12	9.31603
2054.05	8.3296
2056.97	7.64132
2059.9	9.23211
2062.82	9.15321
2065.74	8.76376
2068.67	8.14482
2071.59	8.53496
2074.51	8.58979
2077.42	9.80987
2080.34	10.6518
2083.26	10.8185
2086.17	11.4315
2089.09	11.4423
2092	12.3107
2094.91	14.6556
2097.82	16.04
2100.73	18.3164
2103.64	19.0466
2106.55	20.8167
2109.45	22.1681
2112.36	23.1573
2115.26	25.6353
2118.17	27.5574
2121.07	30.8884
2123.97	34.6478
2126.87	38.1299
2129.77	42.3582
2132.67	45.8715
2135.56	49.3438
2138.46	53.282
2141.35	57.0386
2144.25	61.567
2147.14	66.4764
2150.03	72.6511
2152.92	75.9789
2155.81	79.7732
2158.7	81.9722
2161.59	85.1025
2164.47	87.3187
2167.36	89.7893
2170.24	92.7894
2173.13	94.494
2176.01	94.2592
2178.89	92.6945
2181.77	91.6661
2184.65	90.6268
2187.53	88.5468
2190.4	85.1107
2193.28	82.7255
2196.16	79.0151
2199.03	75.3286
2201.9	70.8461
2204.77	67.2225
2207.64	62.1454
2210.51	58.6105
2213.38	54.5363
2216.25	51.8558
2219.12	47.544
2221.98	44.4839
2224.85	41.2513
2227.71	38.1945
2230.57	35.0132
2233.43	33.2178
2236.29	31.7402
2239.15	30.3445
2242.01	28.7766
2244.87	26.0616
2247.72	25.3857
2250.58	24.4337
2253.43	24.3261
2256.29	22.4485
2259.14	21.0449
2261.99	20.3185
2264.84	19.7145
2267.69	19.5541
2270.53	18.2258
2273.38	16.9723
2276.23	15.3309
2279.07	14.0502
2281.91	12.0977
2284.76	11.9383
2287.6	11.1739
2290.44	9.31355
2293.28	9.09663
2296.12	7.4938
2298.96	7.40354
2301.79	7.78838
2304.63	7.65806
2307.46	8.86222
2310.3	9.04606
2313.13	10.4362
2315.96	10.8355
2318.79	11.0783
2321.62	10.3077
2324.45	11.0785
2327.27	10.6523
2330.1	10.7744
2332.92	10.8022
2335.75	9.09082
2338.57	8.38513
2341.39	5.6209
2344.21	3.28392
2347.04	2.16433
2349.85	0.480974
2352.67	-0.840609
2355.49	-1.11445
2358.3	-2.7595
2361.12	-3.5088
2363.93	-2.7781
2366.75	-2.78785
2369.56	-2.96047
2372.37	-3.58272
2375.18	-2.3019
2377.99	-1.1351
2380.8	0.979007
2383.6	2.32748
2386.41	3.75745
2389.21	4.12617
2392.02	5.85631
2394.82	6.40621
2397.62	5.32951
2400.42	6.76119
2403.22	7.38199
2406.02	8.11898
2408.82	7.01951
2411.62	8.31126
2414.41	9.29017
2417.21	9.06681
2420	9.07525
2422.79	9.09025
2425.59	10.9126
2428.38	10.752
2431.17	10.1353
2433.95	11.1473
2436.74	10.141
2439.53	10.6883
2442.31	10.6828
2445.1	10.72
2447.88	11.5444
2450.67	11.4826
2453.45	11.5371
2456.23	11.1619
2459.01	10.5648
2461.79	11.1784
2464.57	9.95971
2467.34	9.93075
2470.12	10.9359
2472.89	9.53069
2475.67	8.89949
2478.44	8.36894
2481.21	8.75576
2483.98	8.75333
2486.75	7.5666
2489.52	7.43282
2492.29	7.95804
2495.05	7.34676
2497.82	7.47066
2500.58	6.89862
2503.35	6.59191
2506.11	4.5169
2508.87	4.38803
2511.63	3.47629
2514.39	4.23763
2517.15	4.61103
2519.91	4.81599
2522.67	5.70602
2525.42	5.85429
2528.18	6.74805
2530.93	6.91808
2533.69	5.84888
2536.44	5.69769
2539.19	5.26124
2541.94	6.16254
2544.69	5.81736
2547.44	5.52951
2550.18	6.24728
2552.93	5.71158
2555.67	4.68431
2558.42	6.36315
2561.16	6.55262
2563.9	5.78737
2566.64	5.78164
2569.38	5.7632
2572.12	4.86099
2574.86	6.42172
2577.6	7.14992
2580.33	7.75097
2583.07	8.40029
2585.8	9.42948
2588.54	10.3309
2591.27	10.9698
2594	9.87894
2596.73	8.75054
2599.46	7.021
2602.19	6.30904
2604.92	5.32896
2607.64	4.3893
2610.37	4.05455
2613.09	3.46493
2615.82	4.07559
2618.54	4.01135
2621.26	5.06714
2623.98	6.18504
2626.7	6.65692
2629.42	7.34003
2632.14	7.92983
2634.86	9.37609
2637.57	10.8963
2640.29	13.852
2643	14.4142
2645.71	15.1098
2648.43	16.9771
2651.14	17.6562
2653.85	17.3161
2656.56	16.3496
2659.26	15.3419
2661.97	15.1328
2664.68	14.8653
2667.38	14.5339
2670.09	13.5856
2672.79	13.5344
2675.49	12.8881
2678.19	13.2382
2680.89	13.6305
2683.59	14.5637
2686.29	15.2415
2688.99	15.4796
2691.69	15.672
2694.38	16.8129
2697.08	18.1533
2699.77	19.5287
2702.46	22.3153
2705.15	24.0058
2707.85	25.4632
2710.54	27.3798
2713.22	29.6925
2715.91	30.8878
2718.6	30.9666
2721.29	31.6518
2723.97	31.7262
2726.66	32.1516
2729.34	31.9995
2732.02	31.6487
2734.7	30.5085
2737.38	29.804
2740.06	28.2671
2742.74	26.2843
2745.42	24.087
2748.09	21.8377
2750.77	19.7261
2753.45	17.1429
2756.12	16.4645
2758.79	15.4268
2761.46	13.5102
2764.14	12.9571
2766.8	11.8618
2769.47	10.6373
2772.14	8.86736
2774.81	8.37763
2777.48	6.85931
2780.14	5.78643
2782.8	5.59474
2785.47	6.33311
2788.13	5.70561
2790.79	5.06351
2793.45	4.7018
2796.11	4.15099
2798.77	3.36039
2801.43	2.08535
2804.09	0.599089
2806.74	-1.0824
2809.4	-3.87346
2812.05	-5.10695
2814.71	-3.42798
2817.36	2.79972
2820.01	13.1978
2822.66	28.3032
2825.31	47.0253
2827.96	70.0085
2830.6	93.9984
2833.25	121.077
2835.9	149.134
2838.54	176.692
2841.18	207.598
2843.83	236.843
2846.47	268.594
2849.11	299.959
2851.75	332.133
2854.39	363.742
2857.03	394.593
2859.66	422.522
2862.3	447.458
2864.94	468.847
2867.57	485.282
2870.2	498.628
2872.84	508.982
2875.47	520.225
2878.1	528.937
2880.73	539.028
2883.36	548.469
2885.99	559.718
2888.61	569.56
2891.24	579.732
2893.86	587.876
2896.49	595.502
2899.11	603.268
2901.73	610.852
2904.36	620.804
2906.98	632.152
2909.6	648.757
2912.21	667.33
2914.83	687.887
2917.45	706.819
2920.07	722.684
2922.68	734.074
2925.29	740.172
2927.91	742.101
2930.52	738.246
2933.13	731.044
2935.74	719.5
2938.35	706.655
2940.96	685.328
2943.57	660.282
2946.18	634.908
2948.78	607.037
2951.39	575.765
2953.99	543.444
2956.59	511.699
2959.2	479.526
2961.8	446.735
2964.4	417.195
2967	390.121
2969.6	363.314
2972.19	339.258
2974.79	317.536
2977.39	295.409
2979.98	272.466
2982.58	249.058
2985.17	225.177
2987.76	201.647
2990.35	178.64
2992.94	156.656
2995.53	136.963
2998.12	119.373
3000.71	102.126
3003.3	86.4132
3005.88	71.5114
3008.47	59.5849
3011.05	48.6806
3013.64	38.5767
3016.22	29.9417
3018.8	22.5332
3021.38	16.9099
3023.96	11.8016
3026.54	7.38877
3029.12	5.20135
3031.69	2.07683
3034.27	0.504978
3036.84	-0.132814
3039.42	1.08235
3041.99	0.96121
3044.57	0.960604
3047.14	1.54479
3049.71	2.03906
3052.28	2.54668
3054.85	3.42359
3057.41	3.98373
3059.98	4.02435
3062.55	4.17908
3065.11	5.29986
3067.68	6.25031
3070.24	7.10704
3072.8	6.12267
3075.36	5.18171
3077.93	4.07222
3080.49	3.34566
3083.04	2.69224
3085.6	1.76874
3088.16	2.12548
3090.72	2.43925
3093.27	2.14362
3095.83	3.87843
3098.38	6.68774
3100.93	8.78245
3103.49	11.0919
3106.04	13.8814
3108.59	17.0855
3111.14	19.2588
3113.69	22.7519
3116.23	26.1247
3118.78	28.9909
3121.33	33.3259
3123.87	37.2942
3126.41	42.6072
3128.96	47.2346
3131.5	51.3029
3134.04	54.7741
3136.58	58.1123
3139.12	62.1815
3141.66	66.0532
3144.2	70.3826
3146.74	75.5282
3149.27	79.8418