File: data/Raman/poly_smoothed/Mb_20_23_44_1q_45s_532 nm_x100_100%_600 gr_mm_01.txt
#Acq. time (s)=	45
#Accumulations=	2
#Range (cm-¹)=	200...3150
#Windows=	2
#Auto scanning=	Off
#Autofocus=	Off
#Macrospot=	Off
#AutoExposure=	Off
#Spike filter=	Multiple accum.
#Delay time (s)=	0
#Binning=	1
#Readout mode=	Signal
#DeNoise=	Off
#ICS correction=	On
#Dark correction=	Off
#Inst. Process=	Off
#Detector Gain=	Best Dynamic Range
#Detector ADC=	20 kHz
#Detector temperature (°C)=	-70.31
#Instrument=	LabRAM HR Evol
#Detector=	Synapse
#Objective=	x100
#Grating=	600 gr/mm
#ND Filter=	100%
#Laser (nm)=	532
#Hole=	100.021
#Range=	Auto
#Laser Pol.=	No
#Raman. Pol.=	No
#Laser Pol. (°)=	-0.0007625
#Raman Pol. (°)=	89.9995
#Collection=	Microscope
#StageXY=	Marzhauser
#StageZ=	Marzhauser
#X (µm)=	453.1
#Y (µm)=	2994.2
#Z (µm)=	-9.35
#Full time(mm:ss)=	3:18
#Project=
#Sample=
#Site=
#Title=	Mb_20_23_44_2q_45s_532 nm_x100_100%_600 gr_mm
#Remark=
#Date=	14.07.2022 09:41
#Acquired=	14.07.2022 09:41:29
#Base:Fit=	10.08.2022 10:29:37
#Base:Sub=	10.08.2022 10:35:48
#Filter:Polynom=	16.08.2022 10:13:29
#AxisType[0]=Intens
#AxisUnit[0]=Cnt
#AxisType[1]=Spectr
#AxisUnit[1]=1/cm
200.554	23.8058
204.183	23.3198
207.813	20.5759
211.439	17.6557
215.065	14.6055
218.688	13.5073
222.312	13.2554
225.933	12.7859
229.552	12.43
233.171	11.992
236.787	11.0539
240.402	11.1071
244.015	10.4582
247.627	11.2604
251.24	13.2139
254.849	11.9351
258.457	11.2797
262.063	10.4649
265.668	10.9429
269.271	10.8632
272.873	10.1678
276.474	9.67913
280.073	9.70323
283.671	6.55685
287.268	7.75617
290.863	6.15455
294.456	6.42521
298.049	6.14575
301.637	7.26668
305.227	8.71214
308.815	10.2164
312.402	12.9832
315.987	14.5551
319.569	15.6194
323.151	17.8761
326.733	22.3254
330.31	24.5774
333.889	23.8736
337.464	25.0816
341.039	25.9348
344.611	25.9318
348.184	26.7689
351.754	24.7153
355.324	23.4811
358.89	23.9483
362.455	23.2305
366.021	20.7618
369.584	20.2749
373.145	18.7729
376.707	17.3495
380.265	17.4941
383.822	15.3623
387.378	15.2947
390.934	14.5319
394.487	16.216
398.038	17.1946
401.588	15.9726
405.137	15.6434
408.685	15.5157
412.23	16.2849
415.775	16.5428
419.318	15.0781
422.86	14.573
426.401	16.0172
429.94	17.5261
433.478	18.9569
437.012	20.2483
440.547	22.0109
444.081	22.5801
447.613	24.4297
451.142	24.1876
454.672	25.376
458.2	26.0517
461.725	27.7695
465.251	28.1749
468.775	27.7578
472.296	28.6195
475.817	29.1992
479.335	30.8172
482.854	31.3914
486.37	28.8643
489.886	28.4909
493.398	29.6206
496.91	27.4457
500.422	28.6129
503.93	27.0068
507.438	26.1055
510.946	26.6022
514.45	26.8358
517.954	25.6097
521.456	24.5191
524.956	24.7221
528.456	23.4041
531.956	22.2978
535.452	24.0109
538.947	22.1486
542.441	24.0439
545.934	25.568
549.425	24.7724
552.915	23.7445
556.403	24.8049
559.889	25.8741
563.375	25.5935
566.859	25.3866
570.342	26.216
573.824	25.2002
577.303	25.3481
580.782	24.4592
584.26	24.1327
587.734	22.9993
591.21	20.6866
594.684	17.5102
598.154	14.7585
601.626	13.5588
605.094	12.5113
608.562	10.9942
612.027	10.9088
615.493	9.24257
618.956	8.68411
622.419	8.83957
625.879	9.24954
629.338	9.57875
632.797	8.86747
636.254	9.52683
639.708	9.63284
643.162	10.2331
646.614	11.1575
650.067	10.5274
653.516	12.0207
656.964	12.4658
660.411	12.8196
663.857	14.2673
667.301	13.6071
670.744	14.7888
674.186	14.4107
677.626	15.801
681.065	17.1016
684.503	18.6624
687.939	19.8805
691.372	20.4948
694.806	22.1673
698.239	22.5156
701.67	20.916
705.098	20.0161
708.526	20.8195
711.954	20.9218
715.378	20.9974
718.802	21.844
722.226	20.6833
725.646	20.5267
729.067	20.6315
732.484	21.0644
735.902	22.9416
739.317	23.7075
742.731	26.2117
746.145	27.275
749.556	29.4946
752.966	31.5327
756.377	34.5838
759.784	36.1233
763.19	38.9703
766.594	40.9022
770	44.852
773.402	47.5707
776.803	48.3896
780.202	49.0635
783.6	50.0991
786.997	51.0545
790.393	53.2301
793.787	54.0069
797.18	54.9745
800.572	54.7199
803.963	49.527
807.35	54.6715
810.738	60.1196
814.125	66.244
817.51	71.9748
820.894	74.9296
824.275	78.4521
827.657	79.8572
831.037	80.0983
834.414	80.8158
837.792	80.8072
841.167	80.3949
844.542	79.2349
847.914	77.9362
851.287	75.1037
854.656	70.8918
858.026	67.1058
861.393	64.562
864.761	62.9855
868.125	59.4285
871.489	55.4358
874.85	49.9706
878.213	45.14
881.572	41.1468
884.931	37.729
888.287	42.8087
891.643	46.7669
894.997	47.4707
898.352	47.0861
901.704	47.5007
905.055	46.6482
908.404	44.8778
911.75	45.472
915.097	44.433
918.443	43.5695
921.787	44.0391
925.13	43.0864
928.472	41.1647
931.813	40.3561
935.15	37.4216
938.488	36.5306
941.825	36.9146
945.158	34.6516
948.493	32.6615
951.824	31.2623
955.156	29.165
958.486	26.202
961.814	22.6934
965.142	21.2352
968.467	20.4461
971.79	19.5131
975.115	16.7183
978.436	15.6989
981.756	17.2017
985.077	16.713
988.394	17.0033
991.71	18.1982
995.025	17.1624
998.341	16.7673
1001.65	17.8682
1004.97	17.5866
1008.28	20.1781
1011.58	22.0704
1014.89	24.5305
1018.2	26.8803
1021.5	26.7495
1024.81	30.1306
1028.11	33.8177
1031.41	37.412
1034.71	38.2236
1038.01	38.709
1041.31	39.6023
1044.6	41.9108
1047.9	43.6796
1051.19	45.0695
1054.48	46.224
1057.77	47.8634
1061.06	48.9456
1064.35	47.2098
1067.64	45.8468
1070.93	42.9482
1074.21	39.957
1077.49	37.3003
1080.78	34.8873
1084.06	32.6806
1087.34	32.1251
1090.61	32.1181
1093.89	32.3878
1097.17	32.084
1100.44	31.1593
1103.71	32.8522
1106.99	31.9498
1110.26	29.7523
1113.52	28.6795
1116.79	27.1206
1120.06	24.3904
1123.32	24.5249
1126.59	23.0458
1129.85	21.6982
1133.11	21.5099
1136.37	19.9769
1139.63	16.1559
1142.89	13.9568
1146.15	11.1394
1149.4	9.22446
1152.66	7.35666
1155.91	6.7291
1159.16	5.84279
1162.41	4.40049
1165.66	3.78207
1168.91	4.26282
1172.16	5.51
1175.4	5.37666
1178.65	5.40816
1181.89	3.87412
1185.13	4.03295
1188.37	2.72035
1191.61	2.3984
1194.85	1.86709
1198.08	2.58633
1201.32	2.48222
1204.55	4.51906
1207.79	5.22497
1211.02	6.7912
1214.25	7.42364
1217.48	8.39336
1220.71	10.6675
1223.93	13.8962
1227.16	16.259
1230.38	19.5506
1233.6	24.2355
1236.83	27.4668
1240.05	30.307
1243.26	30.7694
1246.48	30.8754
1249.7	32.8917
1252.92	33.7155
1256.13	35.1436
1259.34	38.5208
1262.55	41.565
1265.76	47.0595
1268.97	51.0096
1272.18	55.4342
1275.39	59.9263
1278.59	64.596
1281.8	68.8604
1285	72.257
1288.2	75.6347
1291.4	77.5419
1294.6	79.3471
1297.8	82.3671
1301	84.9941
1304.19	86.6687
1307.39	88.3067
1310.58	88.8734
1313.77	87.3387
1316.96	84.342
1320.15	80.487
1323.34	74.9398
1326.53	70.1409
1329.72	66.2814
1332.9	62.8246
1336.08	61.984
1339.27	59.4769
1342.45	56.9079
1345.63	55.6567
1348.8	53.4209
1351.98	51.976
1355.16	49.463
1358.33	47.9757
1361.51	45.2873
1364.68	43.3489
1367.85	41.3495
1371.02	40.8903
1374.19	39.3383
1377.36	38.9482
1380.52	37.9399
1383.69	38.8149
1386.85	41.1435
1390.02	40.3115
1393.18	39.1126
1396.34	38.6337
1399.5	38.049
1402.65	41.123
1405.81	49.5022
1408.97	57.7226
1412.12	67.5158
1415.27	76.8752
1418.43	88.6562
1421.58	100.47
1424.73	113.502
1427.87	127.184
1431.02	139.625
1434.17	149.675
1437.31	157.244
1440.46	164.007
1443.6	167.481
1446.74	169.005
1449.88	165.77
1453.02	160.227
1456.16	155.101
1459.29	147.866
1462.43	137.627
1465.56	124.311
1468.69	109.226
1471.83	95.5826
1474.95	82.3188
1478.08	72.2629
1481.21	62.7326
1484.34	52.7834
1487.47	42.4824
1490.59	35.0848
1493.71	27.6854
1496.84	24.5655
1499.96	21.1724
1503.07	18.6286
1506.19	17.2644
1509.31	15.5093
1512.43	14.3701
1515.54	13.3706
1518.65	11.9632
1521.77	11.0332
1524.88	10.0419
1527.99	10.3715
1531.1	11.0022
1534.21	12.532
1537.31	14.0535
1540.42	14.412
1543.52	16.3153
1546.63	19.88
1549.73	19.8252
1552.83	20.57
1555.93	21.9244
1559.03	22.4534
1562.12	22.88
1565.22	25.0791
1568.31	27.8188
1571.41	30.6538
1574.5	32.5587
1577.59	35.0113
1580.68	37.7006
1583.77	41.0424
1586.86	41.5385
1589.95	43.5398
1593.03	44.3362
1596.11	45.0323
1599.2	46.2285
1602.28	48.2373
1605.36	47.5495
1608.44	48.5011
1611.52	49.9897
1614.6	51.8337
1617.67	52.4872
1620.75	54.0179
1623.82	53.6993
1626.89	52.5717
1629.96	54.264
1633.04	53.639
1636.11	54.6884
1639.17	56.031
1642.24	58.8845
1645.31	61.5049
1648.37	63.6293
1651.43	65.4433
1654.5	65.619
1657.56	65.3242
1660.62	64.5784
1663.67	63.1235
1666.73	60.1981
1669.79	57.7322
1672.84	53.6871
1675.9	50.2556
1678.95	45.0809
1682	41.3733
1685.05	37.9277
1688.1	33.5722
1691.15	29.5294
1694.2	26.1284
1697.25	22.8205
1700.29	19.2962
1703.33	18.4253
1706.38	16.7897
1709.42	15.9196
1712.46	15.463
1715.5	15.8482
1718.54	17.5179
1721.57	17.8924
1724.61	17.7932
1727.64	16.7496
1730.68	17.4498
1733.71	17.4264
1736.74	17.831
1739.77	17.4288
1742.8	16.6733
1745.83	15.7902
1748.85	14.6655
1751.88	13.758
1754.91	12.6763
1757.93	11.409
1760.95	9.66017
1763.97	9.29004
1766.99	7.08123
1770.01	6.43227
1773.03	4.9007
1776.04	5.1504
1779.06	4.22621
1782.07	2.80096
1785.09	1.5095
1788.1	0.804436
1791.11	1.57903
1794.12	1.46975
1797.13	0.681006
1800.13	0.0402388
1803.14	0.189812
1806.15	0.427962
1809.15	1.03681
1812.15	1.62062
1815.16	1.92708
1818.15	2.30659
1821.16	2.55888
1824.15	2.24114
1827.15	1.94216
1830.15	2.20123
1833.14	2.60168
1836.14	1.98362
1839.13	2.65276
1842.12	2.55631
1845.11	2.6021
1848.1	2.49945
1851.09	2.51496
1854.08	3.09836
1857.06	3.94264
1860.05	4.7355
1863.03	5.22008
1866.01	5.09564
1869	4.9174
1871.98	4.9169
1874.96	4.24063
1877.93	3.84081
1880.91	3.54242
1882.47	3.62655
1885.46	3.4045
1888.44	3.90923
1891.43	3.72557
1894.42	3.36525
1897.4	4.1752
1900.39	2.9918
1903.37	2.32593
1906.35	2.23335
1909.33	2.39609
1912.31	1.6912
1915.29	1.59193
1918.26	1.69785
1921.24	1.8155
1924.21	2.77304
1927.19	3.16503
1930.16	3.23516
1933.13	2.72289
1936.1	2.0148
1939.07	1.82573
1942.04	2.5584
1945	3.02889
1947.97	3.13553
1950.93	3.43339
1953.9	2.86266
1956.86	3.36801
1959.82	4.60561
1962.78	5.94681
1965.74	6.02514
1968.7	5.63637
1971.65	4.94176
1974.61	4.49901
1977.57	3.94065
1980.52	4.48566
1983.47	3.87232
1986.42	3.00999
1989.37	3.53154
1992.32	4.43028
1995.27	5.38948
1998.22	5.17046
2001.17	5.33517
2004.11	5.40701
2007.05	6.15614
2010	6.03696
2012.94	6.66969
2015.88	6.33376
2018.82	6.52556
2021.76	6.58893
2024.7	7.16555
2027.63	7.22899
2030.57	8.81903
2033.5	8.76694
2036.44	8.75418
2039.37	8.59782
2042.3	7.26635
2045.23	7.7627
2048.16	7.96561
2051.08	8.62696
2054.01	9.92315
2056.94	9.21092
2059.86	9.86415
2062.79	10.3016
2065.71	11.414
2068.63	11.6769
2071.55	12.5242
2074.47	13.3441
2077.39	13.1682
2080.31	13.4496
2083.22	12.9426
2086.13	13.413
2089.05	13.8389
2091.96	15.612
2094.87	16.3691
2097.78	16.1616
2100.69	16.034
2103.6	16.7368
2106.51	16.8311
2109.42	17.628
2112.32	19.4056
2115.23	21.3311
2118.13	22.4393
2121.03	23.4155
2123.93	24.0893
2126.83	24.8519
2129.73	26.2717
2132.63	27.6623
2135.53	29.9798
2138.42	33.4916
2141.32	36.5578
2144.21	39.2158
2147.1	40.9651
2150	43.1453
2152.89	45.0905
2155.78	47.0048
2158.66	50.1131
2161.55	51.4606
2164.44	53.1576
2167.32	54.3737
2170.21	55.1882
2173.09	55.6911
2175.97	55.7389
2178.85	55.5241
2181.73	55.4307
2184.61	54.5576
2187.49	52.1075
2190.37	50.1977
2193.24	47.8566
2196.12	45.8395
2198.99	43.804
2201.87	41.3272
2204.74	38.0659
2207.61	36.8786
2210.48	34.5038
2213.35	32.0711
2216.21	29.5266
2219.08	27.7838
2221.95	25.6172
2224.81	24.0185
2227.67	22.8423
2230.54	21.8277
2233.4	20.3918
2236.26	18.8633
2239.11	16.9482
2241.97	15.616
2244.83	15.2732
2247.69	14.8448
2250.54	13.8533
2253.4	13.4203
2256.25	12.9594
2259.1	13.4743
2261.95	14.1437
2264.8	13.143
2267.65	12.9109
2270.5	12.4942
2273.34	12.4243
2276.19	11.8018
2279.03	11.3178
2281.88	10.9176
2284.72	10.1627
2287.56	9.70946
2290.4	8.85587
2293.24	6.64953
2296.08	6.11529
2298.92	5.6981
2301.76	5.52417
2304.59	4.97603
2307.43	5.27523
2310.26	6.36569
2313.09	6.84886
2315.92	6.67105
2318.75	7.64746
2321.58	8.43772
2324.41	9.52397
2327.24	10.7162
2330.06	10.5282
2332.89	10.7718
2335.71	10.7434
2338.54	10.8322
2341.36	10.2011
2344.18	9.66249
2347	9.58069
2349.82	9.61627
2352.64	9.05382
2355.45	8.44001
2358.27	7.29411
2361.08	5.71822
2363.9	5.5161
2366.71	5.63579
2369.52	5.88138
2372.33	6.82818
2375.14	7.26684
2377.95	7.4095
2380.76	7.58534
2383.57	7.85214
2386.37	8.30473
2389.18	8.49798
2391.98	7.54609
2394.79	6.57943
2397.59	6.05718
2400.39	5.44889
2403.19	5.03724
2405.99	4.16191
2408.78	3.46765
2411.58	2.81119
2414.38	2.7794
2417.17	3.14303
2419.97	2.31995
2422.76	1.25718
2425.55	0.314872
2428.34	-1.18771
2431.13	-1.63385
2433.92	-1.60631
2436.71	-1.60799
2439.49	-1.16484
2442.28	-0.719358
2445.06	-0.726594
2447.85	0.29167
2450.63	0.346782
2453.41	1.69012
2456.19	1.31765
2458.97	1.48132
2461.75	1.75456
2464.53	3.36054
2467.31	2.85835
2470.08	3.00586
2472.86	3.20398
2475.63	3.53756
2478.4	2.84362
2481.17	3.51333
2483.94	4.28412
2486.72	4.74491
2489.48	4.89726
2492.25	4.873
2495.02	4.85731
2497.79	4.80157
2500.55	4.46956
2503.31	3.37885
2506.08	2.74112
2508.84	2.73877
2511.6	2.93048
2514.36	3.10963
2517.12	2.99451
2519.88	2.94473
2522.63	2.61274
2525.39	3.04671
2528.14	2.16566
2530.9	2.31074
2533.65	1.9081
2536.4	0.475723
2539.15	0.406828
2541.9	0.765449
2544.65	1.73417
2547.4	2.85213
2550.15	3.20211
2552.89	3.89097
2555.64	4.32181
2558.38	4.97884
2561.12	3.9187
2563.87	3.85658
2566.61	4.00344
2569.35	3.80465
2572.09	4.3914
2574.83	4.44091
2577.56	5.27066
2580.3	6.49352
2583.04	6.41578
2585.77	6.08196
2588.5	5.80613
2591.23	6.12452
2593.97	6.3801
2596.7	6.757
2599.43	6.86753
2602.15	7.0077
2604.88	6.79354
2607.61	8.13261
2610.33	7.82207
2613.06	7.24281
2615.78	6.73926
2618.51	6.13858
2621.23	5.94153
2623.95	5.71636
2626.67	5.88522
2629.39	5.48685
2632.1	5.04383
2634.82	4.76709
2637.54	4.27636
2640.25	4.51224
2642.97	4.69863
2645.68	5.00524
2648.39	4.62712
2651.1	3.90941
2653.81	4.61058
2656.52	5.4983
2659.23	5.5542
2661.94	5.68918
2664.64	5.21862
2667.35	5.38653
2670.05	4.73377
2672.76	4.38911
2675.46	3.61401
2678.16	2.83797
2680.86	3.02755
2683.56	3.88625
2686.26	3.97506
2688.96	4.74859
2691.65	6.4623
2694.35	6.96034
2697.04	9.26766
2699.74	10.5447
2702.43	13.6725
2705.12	15.6689
2707.81	18.1857
2710.5	19.4652
2713.19	21.2293
2715.88	22.9116
2718.57	23.6581
2721.25	23.943
2723.94	23.3644
2726.62	22.8812
2729.3	22.5756
2731.99	20.0376
2734.67	18.1148
2737.35	17.0019
2740.03	15.4303
2742.71	12.4556
2745.38	10.5035
2748.06	9.08197
2750.74	6.60171
2753.41	5.8919
2756.09	4.72516
2758.76	3.8569
2761.43	3.23062
2764.1	2.96545
2766.77	1.94321
2769.44	1.079
2772.11	0.831048
2774.77	0.922691
2777.44	0.554537
2780.11	0.938692
2782.77	0.47114
2785.43	-0.187021
2788.1	0.230862
2790.76	-0.363141
2793.42	-0.546968
2796.08	-0.695699
2798.74	-1.0771
2801.4	-0.830699
2804.05	-0.731826
2806.71	-1.45048
2809.36	-4.20063
2812.02	-4.27917
2814.67	-3.55452
2817.32	-0.142609
2819.97	7.66795
2822.62	17.683
2825.27	31.154
2827.92	45.5099
2830.57	61.611
2833.22	79.857
2835.86	98.6926
2838.51	118.529
2841.15	138.896
2843.79	158.751
2846.43	177.664
2849.08	198.18
2851.72	219.284
2854.36	241.372
2856.99	261.809
2859.63	281.453
2862.27	297.491
2864.9	311.376
2867.54	323.586
2870.17	332.173
2872.8	338.186
2875.43	343.584
2878.07	350.349
2880.7	356.863
2883.32	364.373
2885.95	370.857
2888.58	375.344
2891.21	379.467
2893.83	382.612
2896.46	385.814
2899.08	388.37
2901.7	391.434
2904.32	395.869
2906.94	401.1
2909.56	407.279
2912.18	415.52
2914.8	426.555
2917.42	435.594
2920.03	442.094
2922.65	446.831
2925.26	449.053
2927.88	447.886
2930.49	445.365
2933.1	439.56
2935.71	430.706
2938.32	420.479
2940.93	409.633
2943.54	394.582
2946.14	379.244
2948.75	361.941
2951.35	342.354
2953.96	325.179
2956.56	306.771
2959.16	288.325
2961.77	270.077
2964.37	253.449
2966.96	237.588
2969.56	223.786
2972.16	209.941
2974.76	196.525
2977.35	182.941
2979.95	169.502
2982.54	155.761
2985.14	142.288
2987.73	128.953
2990.32	115.707
2992.91	103.195
2995.5	90.8462
2998.09	79.5519
3000.68	68.4648
3003.26	58.4907
3005.85	48.8372
3008.43	39.87
3011.02	32.6419
3013.6	26.3938
3016.19	21.336
3018.77	17.3657
3021.35	13.1506
3023.93	8.11081
3026.5	5.56523
3029.08	3.10092
3031.66	1.65112
3034.24	0.051825
3036.81	0.171457
3039.39	0.676973
3041.96	1.32795
3044.53	2.17858
3047.1	3.70201
3049.67	4.72626
3052.24	5.01752
3054.81	5.44471
3057.38	4.69041
3059.95	4.80875
3062.52	5.53941
3065.08	4.06476
3067.65	4.34228
3070.21	3.96098
3072.77	4.12059
3075.33	4.53904
3077.89	3.80915
3080.45	3.47165
3083.01	3.43495
3085.57	2.82418
3088.13	2.35971
3090.68	2.56715
3093.24	2.81495
3095.79	3.50263
3098.35	4.56091
3100.9	6.69212
3103.45	7.57543
3106	8.47466
3108.55	9.74377
3111.1	10.3359
3113.65	10.3507
3116.2	11.2136
3118.75	13.0409
3121.29	14.3529
3123.84	16.4512
3126.38	17.5445
3128.92	19.6452
3131.47	21.979
3134.01	24.4857
3136.55	26.7491
3139.09	29.4825
3141.63	32.5269
3144.17	36.4875
3146.7	40.7019
3149.24	46.3094