File: data/Raman/poly_smoothed/Mb_20_23_41_1x_45s_532 nm_x100_100%_600 gr_mm_02.txt
#Acq. time (s)=	45
#Accumulations=	2
#Range (cm-¹)=	200...3150
#Windows=	2
#Auto scanning=	Off
#Autofocus=	Off
#Macrospot=	Off
#AutoExposure=	Off
#Spike filter=	Multiple accum.
#Delay time (s)=	0
#Binning=	1
#Readout mode=	Signal
#DeNoise=	Off
#ICS correction=	On
#Dark correction=	Off
#Inst. Process=	Off
#Detector Gain=	Best Dynamic Range
#Detector ADC=	20 kHz
#Detector temperature (°C)=	-69.85
#Instrument=	LabRAM HR Evol
#Detector=	Synapse
#Objective=	x100
#Grating=	600 gr/mm
#ND Filter=	100%
#Laser (nm)=	532
#Hole=	100.021
#Range=	Auto
#Laser Pol.=	No
#Raman. Pol.=	No
#Laser Pol. (°)=	-0.0007625
#Raman Pol. (°)=	89.9995
#Collection=	Microscope
#StageXY=	Marzhauser
#StageZ=	Marzhauser
#X (µm)=	-7079.8
#Y (µm)=	2175.6
#Z (µm)=	-74.85
#Full time(mm:ss)=	3:18
#Project=
#Sample=
#Site=
#Title=	Mb_20_23_41_2x_45s_532 nm_x100_100%_600 gr_mm
#Remark=
#Date=	13.07.2022 16:51
#Acquired=	13.07.2022 16:51:59
#Base:Fit=	10.08.2022 10:29:37
#Base:Sub=	10.08.2022 10:35:48
#Filter:Polynom=	16.08.2022 10:13:29
#AxisType[0]=Intens
#AxisUnit[0]=Cnt
#AxisType[1]=Spectr
#AxisUnit[1]=1/cm
200.563	56.7447
204.194	47.8787
207.821	42.4708
211.449	40.05
215.074	37.577
218.699	34.7986
222.321	32.0652
225.941	30.9791
229.562	26.7078
233.18	24.242
236.796	22.5264
240.411	21.2788
244.026	18.8309
247.638	16.6091
251.248	14.9791
254.857	12.1576
258.465	10.4275
262.071	8.48217
265.678	5.91518
269.282	4.29852
272.884	4.24657
276.484	2.97043
280.084	1.67703
283.682	-0.286175
287.276	-0.715076
290.871	1.52765
294.465	3.26817
298.057	5.28322
301.648	7.08579
305.237	8.96396
308.823	12.7614
312.41	16.0078
315.995	16.6519
319.579	18.3819
323.16	20.8189
326.741	21.2965
330.321	21.9343
333.897	21.3951
337.474	22.3907
341.048	21.1397
344.622	19.6654
348.192	17.8016
351.764	14.9126
355.332	14.1772
358.901	11.5854
362.466	10.3126
366.03	9.15004
369.594	8.30622
373.155	6.68161
376.715	6.51345
380.273	6.68557
383.832	6.19654
387.388	6.03175
390.942	7.40579
394.495	9.59269
398.047	10.7915
401.597	10.2819
405.145	10.8075
408.693	12.2515
412.239	11.2978
415.783	10.9294
419.327	10.9834
422.869	11.346
426.409	10.9331
429.948	8.42196
433.486	7.36098
437.022	7.17156
440.558	8.59354
444.089	8.62303
447.622	8.71576
451.153	10.3728
454.682	10.8314
458.208	12.2421
461.735	12.2081
465.259	13.1404
468.783	13.9991
472.306	13.9036
475.825	17.6524
479.346	20.6578
482.862	23.1614
486.38	25.9624
489.894	28.924
493.407	31.2895
496.92	33.5793
500.43	33.0684
503.939	34.8234
507.448	35.4282
510.954	37.6931
514.459	36.9901
517.962	36.724
521.466	38.1017
524.966	38.6536
528.466	39.8752
531.964	39.8168
535.46	37.2996
538.955	35.4625
542.449	33.3447
545.942	33.0065
549.433	31.0678
552.923	29.5491
556.412	28.4539
559.899	28.4961
563.385	26.2483
566.867	24.8325
570.35	21.315
573.832	19.6362
577.313	18.6072
580.79	16.6054
584.268	15.8403
587.745	13.7244
591.218	12.1199
594.692	10.9953
598.164	10.7583
601.634	9.40912
605.104	9.03925
608.57	11.5958
612.037	12.5937
615.501	13.2654
618.966	11.333
622.427	11.489
625.887	13.7523
629.348	15.2223
632.806	16.4866
636.262	17.4281
639.716	16.2348
643.172	16.1583
646.624	15.4371
650.075	15.2541
653.524	14.189
656.972	13.0109
660.419	13.4131
663.865	15.2854
667.309	14.9619
670.752	12.7487
674.194	11.3314
677.634	11.2098
681.073	11.6194
684.511	14.0996
687.947	17.0245
691.382	21.4311
694.816	22.8084
698.247	24.1875
701.678	25.894
705.108	29.1368
708.534	32.733
711.962	36.3209
715.388	36.5693
718.81	36.9926
722.234	39.8563
725.654	40.591
729.075	42.3937
732.492	43.3977
735.91	43.3227
739.325	45.7988
742.741	47.3021
746.153	47.4506
749.564	47.1723
752.976	50.153
756.385	52.9376
759.792	57.92
763.2	60.1087
766.604	63.2876
770.008	68.1843
773.41	70.3843
776.811	74.1625
780.21	77.1961
783.608	79.8655
787.005	82.4707
790.401	83.3475
793.795	85.9909
797.188	86.7992
800.58	86.9865
803.971	86.4538
807.36	87.4561
810.748	87.0221
814.135	85.7374
817.518	89.21
820.902	90.2764
824.285	88.7956
827.665	89.2471
831.045	92.3384
834.424	94.1528
837.8	95.892
841.177	96.6696
844.55	96.5726
847.924	95.0871
851.295	95.1287
854.666	94.3276
858.034	92.6186
861.403	91.6949
864.769	89.1938
868.133	87.9607
871.498	84.2845
874.86	81.8612
878.221	80.9956
881.58	77.8708
884.938	76.1926
888.297	75.7884
891.653	75.0245
895.007	74.1937
898.36	74.515
901.712	74.0754
905.063	71.6116
908.412	73.1654
911.76	74.8804
915.107	76.0986
918.452	74.8055
921.797	74.2791
925.138	74.8794
928.48	73.3581
931.82	72.0608
935.16	71.6643
938.496	70.653
941.833	66.4052
945.168	62.8103
948.5	59.4756
951.834	56.6375
955.163	51.8437
958.494	47.1647
961.821	43.3998
965.15	41.7383
968.474	42.225
971.8	43.0967
975.123	42.5334
978.446	43.688
981.766	44.189
985.084	44.8951
988.402	47.4178
991.72	49.2508
995.035	51.5549
998.349	52.0832
1001.66	53.503
1004.97	55.9338
1008.28	58.4577
1011.59	61.1533
1014.9	64.5437
1018.21	64.9777
1021.51	65.2146
1024.81	67.0379
1028.12	70.5095
1031.42	74.3851
1034.72	74.3473
1038.02	76.6176
1041.31	79.6415
1044.61	85.925
1047.91	90.611
1051.2	93.2074
1054.49	96.7808
1057.78	94.8339
1061.07	93.7952
1064.36	92.9995
1067.65	93.4188
1070.93	90.5862
1074.22	89.2305
1077.5	86.8053
1080.78	83.4908
1084.06	79.6768
1087.34	76.0171
1090.62	72.9377
1093.9	72.8264
1097.17	73.6259
1100.45	73.235
1103.72	76.0075
1106.99	78.3828
1110.27	76.7133
1113.53	76.6951
1116.8	75.2605
1120.07	75.3736
1123.33	73.2971
1126.6	68.9788
1129.86	64.8418
1133.12	61.1691
1136.38	55.9703
1139.64	50.8818
1142.9	46.4238
1146.16	44.137
1149.41	39.2837
1152.67	33.5622
1155.92	27.5616
1159.17	20.9701
1162.42	15.0951
1165.67	11.1996
1168.92	9.71207
1172.16	10.0824
1175.41	11.2391
1178.65	11.951
1181.9	11.5676
1185.14	11.8147
1188.38	13.0643
1191.62	13.534
1194.86	14.3926
1198.09	15.5419
1201.33	17.9009
1204.56	21.47
1207.8	25.1965
1211.03	30.5072
1214.26	34.2587
1217.49	40.2961
1220.71	45.3767
1223.94	51.3499
1227.16	56.1929
1230.39	59.2604
1233.61	63.6251
1236.83	66.3569
1240.05	71.8364
1243.27	77.5157
1246.49	83.2154
1249.71	86.635
1252.92	88.8005
1256.14	92.6921
1259.35	98.0299
1262.56	104.661
1265.77	112.147
1268.98	120.243
1272.19	129.25
1275.4	138.367
1278.6	146.944
1281.81	154.913
1285.01	161.169
1288.21	167.287
1291.41	171.43
1294.61	173.886
1297.81	175.709
1301.01	176.541
1304.2	176.227
1307.4	173.69
1310.59	171.487
1313.78	167.664
1316.97	161.983
1320.16	156.928
1323.35	150.756
1326.54	141.748
1329.72	132.632
1332.91	126.179
1336.09	122.704
1339.27	119.601
1342.45	115.508
1345.64	111.388
1348.81	107.87
1351.99	104.658
1355.17	100.04
1358.34	95.765
1361.51	93.5076
1364.69	90.808
1367.86	89.2084
1371.03	86.6658
1374.2	84.5986
1377.37	85.9418
1380.53	83.7167
1383.7	83.7208
1386.86	84.5821
1390.02	85.3542
1393.19	84.1138
1396.35	84.6004
1399.51	85.994
1402.66	90.545
1405.82	100.831
1408.97	113.657
1412.13	129.935
1415.28	147.659
1418.43	166.639
1421.59	185.771
1424.73	206.226
1427.88	226.179
1431.03	245.256
1434.18	264.31
1437.32	280.845
1440.46	292.8
1443.61	300.335
1446.75	305.153
1449.89	304.48
1453.03	298.767
1456.16	288.604
1459.3	272.715
1462.44	254.15
1465.57	231.18
1468.7	204.538
1471.83	180.301
1474.96	158.423
1478.09	137.542
1481.22	119.658
1484.35	102.517
1487.47	88.199
1490.6	73.2245
1493.72	61.0971
1496.84	51.7337
1499.96	45.2416
1503.08	39.9093
1506.2	36.2319
1509.32	34.1865
1512.44	32.8057
1515.55	30.6029
1518.66	29.337
1521.78	28.6431
1524.89	27.5832
1528	27.3971
1531.11	28.7656
1534.21	29.3502
1537.32	30.9562
1540.43	32.3777
1543.53	35.7149
1546.63	39.5472
1549.74	42.492
1552.84	45.2431
1555.94	48.3659
1559.03	50.7712
1562.13	53.9182
1565.23	57.9244
1568.32	62.339
1571.42	67.5312
1574.51	71.8259
1577.6	74.7828
1580.69	79.6624
1583.78	83.8597
1586.87	85.6672
1589.95	88.3966
1593.04	88.9014
1596.12	90.6975
1599.21	90.1359
1602.29	91.2218
1605.37	93.2811
1608.45	94.1213
1611.53	92.784
1614.6	94.9143
1617.68	96.3886
1620.75	99.1959
1623.83	101.088
1626.9	103.24
1629.97	105.457
1633.04	109.896
1636.11	113.107
1639.18	117.922
1642.25	123.612
1645.31	128.104
1648.38	131.115
1651.44	135.149
1654.5	138.314
1657.56	137.874
1660.62	137.727
1663.68	136.058
1666.74	131.956
1669.8	126.082
1672.85	119.415
1675.91	112.229
1678.96	105.759
1682.01	96.3115
1685.06	86.8872
1688.11	78.1304
1691.16	71.0117
1694.21	62.8794
1697.25	54.5987
1700.3	48.4905
1703.34	42.7121
1706.39	38.8485
1709.43	34.4133
1712.47	33.0216
1715.51	31.5618
1718.54	30.0328
1721.58	29.4815
1724.62	29.4289
1727.65	30.0365
1730.68	29.3288
1733.72	29.6045
1736.75	29.668
1739.78	29.4868
1742.81	28.1678
1745.84	26.6423
1748.86	24.8198
1751.89	22.3756
1754.91	19.4856
1757.93	16.7701
1760.96	14.9407
1763.98	13.193
1767	10.1599
1770.02	8.35321
1773.03	7.76084
1776.05	7.36227
1779.07	6.06909
1782.08	5.07031
1785.09	5.50899
1788.11	5.74706
1791.12	4.97749
1794.13	3.99339
1797.13	4.02631
1800.14	5.07725
1803.15	5.68044
1806.15	5.47273
1809.16	5.25521
1812.16	5.55715
1815.16	4.32283
1818.16	3.00935
1821.16	2.25592
1824.16	1.63738
1827.16	1.21829
1830.16	0.793333
1833.15	1.08019
1836.14	1.16456
1839.14	1.13514
1842.13	1.67271
1845.12	1.98496
1848.11	2.34126
1851.1	2.24267
1854.08	0.829729
1857.07	1.71955
1860.05	2.24852
1863.04	2.12728
1866.02	2.11827
1869	2.94361
1871.98	3.87425
1874.96	3.43396
1877.94	1.99944
1880.92	1.56822
1882.51	2.32597
1885.5	3.57957
1888.48	3.54716
1891.47	4.08922
1894.46	5.02028
1897.44	4.97022
1900.42	4.77701
1903.41	6.3504
1906.39	7.75324
1909.37	7.31337
1912.35	7.49095
1915.32	7.06841
1918.3	8.30806
1921.27	8.53922
1924.25	9.51049
1927.22	9.04359
1930.19	9.33032
1933.17	8.04892
1936.14	7.78946
1939.11	6.12806
1942.07	6.47621
1945.04	4.12587
1948.01	3.5185
1950.97	2.45301
1953.93	2.45737
1956.9	1.86326
1959.86	1.16866
1962.82	0.321599
1965.78	-0.267396
1968.74	-0.73993
1971.69	-0.65614
1974.65	-0.437757
1977.6	0.850826
1980.56	0.703164
1983.51	0.0233379
1986.46	0.928264
1989.41	2.50464
1992.36	3.21136
1995.31	3.5446
1998.26	2.79979
2001.2	2.92448
2004.15	2.78918
2007.09	3.38746
2010.04	3.13228
2012.98	4.36725
2015.92	4.55539
2018.86	3.11819
2021.8	2.49731
2024.73	3.54804
2027.67	3.70993
2030.61	3.68361
2033.54	5.31785
2036.47	5.1517
2039.4	5.62232
2042.33	6.314
2045.27	6.81267
2048.19	6.95141
2051.12	5.65441
2054.05	5.32266
2056.97	4.79243
2059.9	5.98337
2062.82	6.92528
2065.74	6.51296
2068.67	6.13973
2071.59	6.38164
2074.51	5.79493
2077.42	6.63974
2080.34	6.9421
2083.26	7.47371
2086.17	7.95777
2089.09	8.00538
2092	9.59881
2094.91	11.5995
2097.82	13.2745
2100.73	14.296
2103.64	14.7335
2106.55	15.3414
2109.45	16.9028
2112.36	18.1754
2115.26	19.2099
2118.17	20.8948
2121.07	21.8887
2123.97	24.6689
2126.87	27.102
2129.77	31.1065
2132.67	33.8505
2135.56	38.2735
2138.46	41.6708
2141.35	44.8787
2144.25	49.7296
2147.14	53.4858
2150.03	58.081
2152.92	60.9004
2155.81	65.9573
2158.7	69.613
2161.59	73.7665
2164.47	76.8218
2167.36	78.2575
2170.24	80.1541
2173.13	80.3235
2176.01	81.4378
2178.89	81.9016
2181.77	81.232
2184.65	78.676
2187.53	75.8717
2190.4	72.9292
2193.28	70.1903
2196.16	67.9576
2199.03	64.4163
2201.9	61.3414
2204.77	58.0565
2207.64	53.7539
2210.51	50.1371
2213.38	46.4919
2216.25	42.2962
2219.12	38.6301
2221.98	35.2038
2224.85	33.6051
2227.71	31.4917
2230.57	29.8586
2233.43	25.61
2236.29	23.2714
2239.15	22.6348
2242.01	19.9455
2244.87	19.3455
2247.72	17.4473
2250.58	15.2155
2253.43	12.7294
2256.29	11.4999
2259.14	10.13
2261.99	10.2183
2264.84	8.74378
2267.69	7.76878
2270.53	7.3153
2273.38	7.04894
2276.23	6.14923
2279.07	4.53828
2281.91	4.33282
2284.76	3.84265
2287.6	5.67428
2290.44	6.07782
2293.28	5.2692
2296.12	5.94356
2298.96	6.58537
2301.79	5.75228
2304.63	6.36472
2307.46	7.65454
2310.3	7.48089
2313.13	7.56791
2315.96	7.24806
2318.79	7.41778
2321.62	6.59449
2324.45	6.51711
2327.27	5.69939
2330.1	4.66067
2332.92	4.78388
2335.75	5.14104
2338.57	4.20907
2341.39	3.40226
2344.21	2.50678
2347.04	1.81944
2349.85	1.14201
2352.67	2.78961
2355.49	2.45336
2358.3	1.26872
2361.12	1.16452
2363.93	1.28382
2366.75	2.11018
2369.56	1.65887
2372.37	1.4208
2375.18	2.18351
2377.99	1.39867
2380.8	1.58115
2383.6	1.20731
2386.41	1.92622
2389.21	1.35739
2392.02	0.853522
2394.82	0.224899
2397.62	2.06634
2400.42	2.08084
2403.22	2.99849
2406.02	4.2885
2408.82	5.1397
2411.62	6.37716
2414.41	6.92678
2417.21	8.96327
2420	10.3768
2422.79	10.492
2425.59	11.2624
2428.38	13.0447
2431.17	13.835
2433.95	14.4492
2436.74	14.4722
2439.53	14.3117
2442.31	13.3293
2445.1	12.4832
2447.88	12.2332
2450.67	11.6442
2453.45	10.1063
2456.23	8.07281
2459.01	6.40372
2461.79	4.99783
2464.57	5.3809
2467.34	5.02667
2470.12	4.24002
2472.89	4.26758
2475.67	5.14347
2478.44	3.44081
2481.21	3.39927
2483.98	3.86117
2486.75	3.32906
2489.52	2.44932
2492.29	2.37952
2495.05	2.65749
2497.82	2.15084
2500.58	2.17759
2503.35	0.860593
2506.11	0.279382
2508.87	-0.545869
2511.63	-0.962875
2514.39	-0.892032
2517.15	-0.758546
2519.91	-1.0164
2522.67	-0.757138
2525.42	-0.114779
2528.18	0.567861
2530.93	1.82123
2533.69	2.76523
2536.44	3.68402
2539.19	5.13029
2541.94	5.6321
2544.69	5.51941
2547.44	5.54654
2550.18	6.25918
2552.93	6.60814
2555.67	6.19384
2558.42	6.29133
2561.16	6.97735
2563.9	6.91435
2566.64	7.31911
2569.38	7.44489
2572.12	7.32247
2574.86	7.07688
2577.6	7.03435
2580.33	7.57009
2583.07	8.22544
2585.8	9.4841
2588.54	9.56671
2591.27	9.81259
2594	10.4133
2596.73	10.7782
2599.46	10.8425
2602.19	11.2557
2604.92	11.6999
2607.64	12.7819
2610.37	12.2628
2613.09	12.5487
2615.82	13.1734
2618.54	13.0297
2621.26	13.3848
2623.98	13.1228
2626.7	13.3678
2629.42	13.961
2632.14	13.2519
2634.86	12.9581
2637.57	12.6024
2640.29	13.6704
2643	13.6989
2645.71	13.6633
2648.43	13.9229
2651.14	13.8578
2653.85	13.7154
2656.56	14.2074
2659.26	14.3327
2661.97	14.563
2664.68	14.2245
2667.38	13.3515
2670.09	14.0746
2672.79	15.3088
2675.49	15.5249
2678.19	16.2269
2680.89	16.9129
2683.59	17.3274
2686.29	18.6057
2688.99	19.0641
2691.69	20.5119
2694.38	21.5924
2697.08	23.2249
2699.77	25.3122
2702.46	28.5727
2705.15	32.474
2707.85	34.7229
2710.54	36.9713
2713.22	38.3427
2715.91	40.5222
2718.6	41.7758
2721.29	43.4224
2723.97	42.788
2726.66	42.1496
2729.34	42.0065
2732.02	40.5097
2734.7	38.2664
2737.38	35.8422
2740.06	32.4611
2742.74	29.3809
2745.42	25.1253
2748.09	21.5614
2750.77	18.2122
2753.45	14.3547
2756.12	11.2194
2758.79	8.69699
2761.46	7.27436
2764.14	4.94592
2766.8	3.8698
2769.47	3.70045
2772.14	3.82556
2774.81	2.6709
2777.48	2.31848
2780.14	2.22403
2782.8	3.08194
2785.47	4.22439
2788.13	5.69618
2790.79	6.32317
2793.45	7.939
2796.11	7.3943
2798.77	7.43923
2801.43	6.06186
2804.09	4.26294
2806.74	1.08935
2809.4	-2.17166
2812.05	-4.90723
2814.71	-2.82976
2817.36	6.19387
2820.01	24.542
2822.66	50.2134
2825.31	83.0959
2827.96	118.907
2830.6	160.238
2833.25	204.152
2835.9	247.884
2838.54	291.367
2841.18	333.866
2843.83	376.793
2846.47	417.81
2849.11	460.688
2851.75	505.705
2854.39	551.199
2857.03	592.375
2859.66	627.8
2862.3	657.8
2864.94	679.63
2867.57	694.53
2870.2	703.128
2872.84	708.806
2875.47	712.441
2878.1	718.393
2880.73	725.109
2883.36	733.75
2885.99	742.768
2888.61	747.71
2891.24	751.712
2893.86	754.493
2896.49	755.099
2899.11	753.432
2901.73	751.029
2904.36	751.536
2906.98	754.351
2909.6	761.181
2912.21	773.782
2914.83	790.749
2917.45	806.299
2920.07	816.476
2922.68	820.76
2925.29	821.311
2927.91	814.802
2930.52	804.171
2933.13	791.246
2935.74	773.892
2938.35	752.792
2940.96	725.751
2943.57	696.918
2946.18	664.47
2948.78	631.289
2951.39	594.738
2953.99	557.616
2956.59	520.516
2959.2	484.667
2961.8	449.139
2964.4	414.925
2967	384.978
2969.6	356.898
2972.19	331.233
2974.79	306.622
2977.39	282.418
2979.98	258.428
2982.58	235.487
2985.17	210.551
2987.76	187.451
2990.35	164.741
2992.94	143.557
2995.53	125.916
2998.12	107.423
3000.71	90.9855
3003.3	74.6485
3005.88	61.8208
3008.47	50.6641
3011.05	40.2494
3013.64	30.8391
3016.22	22.9444
3018.8	17.1624
3021.38	11.7243
3023.96	7.35578
3026.54	3.94735
3029.12	0.562455
3031.69	-0.95333
3034.27	-1.82992
3036.84	-2.08328
3039.42	-0.764265
3041.99	1.46017
3044.57	3.42241
3047.14	4.65628
3049.71	4.97451
3052.28	5.71847
3054.85	6.84253
3057.41	6.76586
3059.98	7.47836
3062.55	6.85247
3065.11	7.43469
3067.68	7.29913
3070.24	7.65747
3072.8	6.40928
3075.36	5.85464
3077.93	4.93505
3080.49	3.99484
3083.04	2.58705
3085.6	1.55002
3088.16	1.32606
3090.72	1.79719
3093.27	2.41377
3095.83	4.77507
3098.38	5.98513
3100.93	8.38336
3103.49	11.4529
3106.04	13.2583
3108.59	15.512
3111.14	17.7983
3113.69	20.0179
3116.23	21.7298
3118.78	24.9204
3121.33	28.0059
3123.87	32.0621
3126.41	35.5952
3128.96	40.3477
3131.5	44.243
3134.04	47.9203
3136.58	52.4016
3139.12	55.8553
3141.66	60.6029
3144.2	66.0094
3146.74	73.7161
3149.27	81.4703