File: data/Raman/poly_smoothed/Mb_20_23_01_1x_45s_532 nm_x50_100%_600 gr_mm_01.txt
#Acq. time (s)=	45
#Accumulations=	2
#Range (cm-¹)=	200...3150
#Windows=	2
#Auto scanning=	Off
#Autofocus=	Off
#Macrospot=	Off
#AutoExposure=	Off
#Spike filter=	Multiple accum.
#Delay time (s)=	0
#Binning=	1
#Readout mode=	Signal
#DeNoise=	Off
#ICS correction=	On
#Dark correction=	Off
#Inst. Process=	Off
#Detector Gain=	Best Dynamic Range
#Detector ADC=	20 kHz
#Detector temperature (°C)=	-69.85
#Instrument=	LabRAM HR Evol
#Detector=	Synapse
#Objective=	x50
#Grating=	600 gr/mm
#ND Filter=	100%
#Laser (nm)=	532
#Hole=	100.021
#Range=	Auto
#Laser Pol.=	No
#Raman. Pol.=	No
#Laser Pol. (°)=	-0.0007625
#Raman Pol. (°)=	89.9995
#Collection=	Microscope
#StageXY=	Marzhauser
#StageZ=	Marzhauser
#X (µm)=	-7000.6
#Y (µm)=	2174.2
#Z (µm)=	-74.5
#Full time(mm:ss)=	3:20
#Project=
#Sample=
#Site=
#Title=	Mb_20_23_01_2x_45s_532 nm_x50_100%_600 gr_mm
#Remark=
#Date=	13.07.2022 12:58
#Acquired=	13.07.2022 12:58:03
#Edit:Spike=	13.07.2022 12:59:55
#Base:Fit=	10.08.2022 10:29:19
#Base:Fit=	10.08.2022 10:29:37
#Base:Sub=	10.08.2022 10:31:46
#Filter:Polynom=	16.08.2022 10:13:29
#AxisType[0]=Intens
#AxisUnit[0]=Cnt
#AxisType[1]=Spectr
#AxisUnit[1]=1/cm
200.563	10.1635
204.194	8.99651
207.821	8.95333
211.449	9.23018
215.074	10.779
218.699	11.3024
222.321	12.6416
225.941	14.1144
229.562	14.0789
233.18	14.8314
236.796	16.7006
240.411	17.0635
244.026	18.8033
247.638	19.7937
251.248	19.601
254.857	19.3549
258.465	19.273
262.071	19.2449
265.678	19.7733
269.282	17.5022
272.884	15.7866
276.484	15.0047
280.084	12.6977
283.682	10.3735
287.276	10.1854
290.871	9.21154
294.465	10.0272
298.057	10.5326
301.648	11.7921
305.237	12.9808
308.823	14.3887
312.41	18.9762
315.995	22.0417
319.579	25.0275
323.16	27.1202
326.741	31.9221
330.321	35.3482
333.897	37.6574
337.474	39.1566
341.048	39.2343
344.622	39.4509
348.192	38.7228
351.764	38.1785
355.332	35.9369
358.901	35.0274
362.466	35.9072
366.03	35.7831
369.594	34.1294
373.155	33.3853
376.715	33.2319
380.273	33.4573
383.832	34.5762
387.388	35.5929
390.942	35.1612
394.495	36.5374
398.047	37.3086
401.597	38.3154
405.145	36.9569
408.693	38.263
412.239	39.0796
415.783	39.065
419.327	37.5141
422.869	36.3916
426.409	33.4617
429.948	32.1464
433.486	31.4555
437.022	30.2201
440.558	28.8764
444.089	29.3457
447.622	30.197
451.153	30.9619
454.682	29.5215
458.208	29.6253
461.735	31.2051
465.259	32.8212
468.783	34.876
472.306	37.2955
475.825	39.5126
479.346	42.8882
482.862	45.1529
486.38	48.9819
489.894	52.8152
493.407	55.1392
496.92	56.195
500.43	55.3134
503.939	56.9498
507.448	58.8761
510.954	59.1382
514.459	60.1276
517.962	62.5822
521.466	62.3164
524.966	63.4349
528.466	64.2772
531.964	63.2922
535.46	61.7193
538.955	60.1871
542.449	59.4593
545.942	59.8127
549.433	59.5605
552.923	55.8451
556.412	54.4663
559.899	53.8128
563.385	52.7227
566.867	49.5225
570.35	46.226
573.832	41.2099
577.313	34.4272
580.79	30.2307
584.268	26.575
587.745	23.2783
591.218	21.5662
594.692	21.5873
598.164	18.426
601.634	19.1018
605.104	18.8461
608.57	18.4832
612.037	18.1387
615.501	18.5598
618.966	18.8664
622.427	20.2847
625.887	22.6354
629.348	24.2389
632.806	25.3479
636.262	23.6667
639.716	22.0764
643.172	21.9854
646.624	21.0339
650.075	18.5213
653.524	15.6957
656.972	13.1154
660.419	11.0633
663.865	9.99
667.309	10.945
670.752	13.0189
674.194	12.242
677.634	13.2859
681.073	13.7212
684.511	15.3618
687.947	17.6079
691.382	18.7644
694.816	19.9546
698.247	25.32
701.678	28.0621
705.108	31.3426
708.534	34.3968
711.962	35.6707
715.388	36.3163
718.81	35.8448
722.234	35.4037
725.654	34.6406
729.075	34.3345
732.492	34.7304
735.91	34.8143
739.325	35.9111
742.741	36.6678
746.153	38.1986
749.564	40.3085
752.976	42.3529
756.385	45.4376
759.792	47.7763
763.2	51.7752
766.604	54.6829
770.008	57.5083
773.41	61.637
776.811	63.4549
780.21	66.9604
783.608	68.179
787.005	69.1524
790.401	71.4558
793.795	71.7149
797.188	73.7626
800.58	73.7793
803.971	74.714
807.36	74.9749
810.748	75.8655
814.135	77.1977
817.518	78.5339
820.902	79.6473
824.285	81.5173
827.665	81.0903
831.045	81.8195
834.424	82.2282
837.8	82.3561
841.177	81.2499
844.55	81.2499
847.924	79.7999
851.295	78.8759
854.666	77.1025
858.034	74.1335
861.403	72.7145
864.769	71.0328
868.133	70.8123
871.498	70.4176
874.86	70.0617
878.221	68.6002
881.58	66.3494
884.938	65.7045
888.297	65.7356
891.653	65.0997
895.007	64.4155
898.36	64.6841
901.712	64.4158
905.063	66.1479
908.412	66.3074
911.76	64.2359
915.107	65.3848
918.452	65.1343
921.797	64.6096
925.138	64.6716
928.48	62.5052
931.82	60.5573
935.16	57.9875
938.496	54.9717
941.833	53.4508
945.168	49.6895
948.5	48.5963
951.834	48.2079
955.163	46.8861
958.494	41.5532
961.821	36.9791
965.15	38.5693
968.474	40.7724
971.8	45.0382
975.123	48.7387
978.446	51.045
981.766	52.8117
985.084	54.2568
988.402	56.7773
991.72	55.2335
995.035	54.6821
998.349	55.4496
1001.66	51.6625
1004.97	50.7721
1008.28	53.1159
1011.59	58.4385
1014.9	64.9219
1018.21	70.8301
1021.51	78.2857
1024.81	84.9169
1028.12	91.6864
1031.42	96.6576
1034.72	101.539
1038.02	103.42
1041.31	106.758
1044.61	114.185
1047.91	119.386
1051.2	121.083
1054.49	120.334
1057.78	113.922
1061.07	108.744
1064.36	102.349
1067.65	94.3331
1070.93	87.8877
1074.22	78.4565
1077.5	70.9652
1080.78	61.91
1084.06	56.5267
1087.34	56.6962
1090.62	57.8225
1093.9	59.5058
1097.17	58.1106
1100.45	59.1537
1103.72	58.5678
1106.99	58.4945
1110.27	58.825
1113.53	56.2437
1116.8	57.2848
1120.07	56.4747
1123.33	56.0509
1126.6	52.1608
1129.86	50.1078
1133.12	47.5883
1136.38	42.8701
1139.64	39.1031
1142.9	37.1057
1146.16	35.3611
1149.41	31.5628
1152.67	26.2093
1155.92	19.1394
1159.17	14.878
1162.42	12.4948
1165.67	9.38972
1168.92	9.26072
1172.16	9.84079
1175.41	9.1968
1178.65	9.9947
1181.9	10.3949
1185.14	11.3321
1188.38	12.1325
1191.62	12.8363
1194.86	16.3007
1198.09	19.2784
1201.33	24.3809
1204.56	28.505
1207.8	34.0404
1211.03	42.0451
1214.26	49.7388
1217.49	57.4044
1220.71	64.7591
1223.94	72.9458
1227.16	79.1721
1230.39	84.9225
1233.61	89.5966
1236.83	98.8093
1240.05	106.005
1243.27	110.727
1246.49	117.48
1249.71	123.204
1252.92	125.542
1256.14	129.46
1259.35	131.93
1262.56	135.961
1265.77	140.542
1268.98	145.254
1272.19	152.077
1275.4	160.131
1278.6	164.999
1281.81	170.873
1285.01	177.649
1288.21	184.706
1291.41	190.585
1294.61	193.209
1297.81	195.156
1301.01	195.892
1304.2	198.805
1307.4	200.122
1310.59	200.838
1313.78	202.225
1316.97	201.881
1320.16	201.608
1323.35	199.274
1326.54	196.004
1329.72	190.98
1332.91	186.831
1336.09	182.357
1339.27	178.661
1342.45	176.661
1345.64	171.624
1348.81	167.587
1351.99	164.138
1355.17	159.547
1358.34	154.015
1361.51	152.279
1364.69	149.224
1367.86	144.599
1371.03	141.188
1374.2	138.425
1377.37	136.252
1380.53	134.16
1383.7	133.96
1386.86	135.449
1390.02	136.826
1393.19	137.141
1396.35	137.62
1399.51	138.376
1402.66	137.531
1405.82	142.483
1408.97	147.649
1412.13	156.991
1415.28	168.311
1418.43	181.238
1421.59	194.364
1424.73	210.575
1427.88	228.246
1431.03	244.927
1434.18	262.043
1437.32	275.278
1440.46	287.475
1443.61	295.372
1446.75	299.631
1449.89	299.927
1453.03	296.039
1456.16	288.671
1459.3	278.886
1462.44	268.128
1465.57	253.256
1468.7	233.552
1471.83	214.637
1474.96	194.102
1478.09	173.806
1481.22	156.274
1484.35	140.146
1487.47	124.741
1490.6	109.298
1493.72	99.565
1496.84	91.1458
1499.96	82.7155
1503.08	76.1076
1506.2	70.6643
1509.32	64.5642
1512.44	59.5737
1515.55	54.3861
1518.66	51.5922
1521.78	49.4654
1524.89	49.1657
1528	47.5432
1531.11	46.693
1534.21	48.8302
1537.32	51.6057
1540.43	55.4761
1543.53	60.337
1546.63	65.1832
1549.74	69.7114
1552.84	73.0607
1555.94	77.1867
1559.03	79.4333
1562.13	82.6231
1565.23	86.6919
1568.32	92.2319
1571.42	97.0364
1574.51	102.812
1577.6	107.623
1580.69	112.673
1583.78	118.39
1586.87	122.506
1589.95	128.351
1593.04	132.063
1596.12	134.308
1599.21	134.963
1602.29	135.107
1605.37	134.97
1608.45	134.935
1611.53	137.472
1614.6	138.604
1617.68	142.373
1620.75	145.376
1623.83	148.709
1626.9	152.322
1629.97	157.565
1633.04	164.57
1636.11	173.016
1639.18	181.097
1642.25	188.476
1645.31	196.261
1648.38	202.472
1651.44	206.848
1654.5	210.258
1657.56	210.099
1660.62	208.625
1663.68	203.567
1666.74	194.598
1669.8	184.032
1672.85	171.189
1675.91	159.417
1678.96	146.606
1682.01	132.938
1685.06	117.946
1688.11	105.004
1691.16	93.2984
1694.21	80.8057
1697.25	71.2447
1700.3	63.5423
1703.34	55.0037
1706.39	50.6821
1709.43	45.4111
1712.47	40.8734
1715.51	35.905
1718.54	33.2749
1721.58	29.5961
1724.62	28.0325
1727.65	25.9044
1730.68	24.854
1733.72	23.2533
1736.75	19.9867
1739.78	16.9918
1742.81	15.7275
1745.84	13.3496
1748.86	12.3656
1751.89	11.9276
1754.91	10.2938
1757.93	9.37454
1760.96	6.36678
1763.98	4.26545
1767	3.45854
1770.02	1.16423
1773.03	0.223746
1776.05	-0.986012
1779.07	-0.705549
1782.08	-0.43675
1785.09	-2.12631
1788.11	-1.92857
1791.12	-1.3859
1794.13	-0.214923
1797.13	-0.485713
1800.14	-0.305576
1803.15	0.0846506
1806.15	0.911955
1809.16	0.986794
1812.16	1.15137
1815.16	1.54724
1818.16	2.0713
1821.16	2.88316
1824.16	3.94104
1827.16	5.33134
1830.16	5.34133
1833.15	5.38526
1836.14	5.14828
1839.14	4.96981
1842.13	4.83173
1845.12	3.87334
1848.11	3.07264
1851.1	1.06509
1854.08	2.29684
1857.07	2.75989
1860.05	2.8741
1863.04	3.19418
1866.02	4.04182
1869	3.31417
1871.98	3.30757
1874.96	3.74533
1877.94	4.82129
1880.92	5.60569
1882.51	5.90919
1885.5	6.90194
1888.48	7.06879
1891.47	8.47114
1894.46	8.84361
1897.44	8.90765
1900.42	8.5476
1903.41	7.42307
1906.39	7.18625
1909.37	5.86036
1912.35	5.76657
1915.32	5.1563
1918.3	3.08368
1921.27	3.97486
1924.25	4.15341
1927.22	4.89233
1930.19	3.81791
1933.17	3.92397
1936.14	2.88571
1939.11	2.30514
1942.07	2.02204
1945.04	2.3303
1948.01	1.869
1950.97	1.6378
1953.93	3.94202
1956.9	4.51681
1959.86	4.18589
1962.82	4.6775
1965.78	5.41732
1968.74	4.02993
1971.69	4.55379
1974.65	3.39674
1977.6	2.81789
1980.56	3.70351
1983.51	3.32989
1986.46	3.81572
1989.41	3.23126
1992.36	4.00973
1995.31	4.57257
1998.26	3.86614
2001.2	2.80397
2004.15	3.8361
2007.09	1.13616
2010.04	2.59276
2012.98	3.62913
2015.92	5.60553
2018.86	7.12589
2021.8	7.99664
2024.73	9.77635
2027.67	10.1257
2030.61	9.78841
2033.54	9.79603
2036.47	9.7991
2039.4	11.2135
2042.33	10.9091
2045.27	11.14
2048.19	10.9893
2051.12	11.0463
2054.05	11.8356
2056.97	11.7911
2059.9	12.5922
2062.82	13.7831
2065.74	15.3854
2068.67	16.1162
2071.59	16.0323
2074.51	18.0151
2077.42	20.1545
2080.34	22.4065
2083.26	24.3497
2086.17	26.9491
2089.09	27.8815
2092	29.2749
2094.91	31.7416
2097.82	34.2855
2100.73	36.3226
2103.64	39.8349
2106.55	41.6284
2109.45	43.79
2112.36	45.7355
2115.26	47.3582
2118.17	49.7526
2121.07	53.3988
2123.97	56.8982
2126.87	60.5371
2129.77	65.7512
2132.67	70.8831
2135.56	75.8541
2138.46	81.5363
2141.35	86.3874
2144.25	92.5131
2147.14	100.276
2150.03	106.169
2152.92	110.723
2155.81	115.677
2158.7	121.816
2161.59	127.401
2164.47	132.326
2167.36	138.002
2170.24	141.379
2173.13	142.497
2176.01	144.125
2178.89	143.686
2181.77	142.113
2184.65	139.458
2187.53	137.058
2190.4	132.684
2193.28	127.548
2196.16	120.954
2199.03	114.247
2201.9	108.506
2204.77	101.448
2207.64	93.4363
2210.51	86.1882
2213.38	80.0021
2216.25	74.064
2219.12	66.5697
2221.98	61.2802
2224.85	57.4087
2227.71	52.4526
2230.57	49.6157
2233.43	45.8298
2236.29	43.9777
2239.15	41.6787
2242.01	40.0741
2244.87	39.4331
2247.72	37.7786
2250.58	35.82
2253.43	35.2704
2256.29	34.2402
2259.14	33.6867
2261.99	32.2097
2264.84	32.3652
2267.69	29.6996
2270.53	29.3057
2273.38	27.7247
2276.23	25.0704
2279.07	23.2557
2281.91	20.9756
2284.76	17.9651
2287.6	15.8926
2290.44	14.0534
2293.28	12.1913
2296.12	9.80844
2298.96	8.54575
2301.79	7.3491
2304.63	7.12706
2307.46	6.58709
2310.3	6.37039
2313.13	6.57553
2315.96	6.66552
2318.79	7.09671
2321.62	8.42745
2324.45	8.44709
2327.27	9.48446
2330.1	8.92563
2332.92	8.60084
2335.75	8.67429
2338.57	7.78828
2341.39	7.63247
2344.21	5.68693
2347.04	4.06666
2349.85	2.80216
2352.67	1.72851
2355.49	1.41967
2358.3	-0.245468
2361.12	-2.34468
2363.93	-2.13698
2366.75	-1.46408
2369.56	-1.93855
2372.37	-3.21426
2375.18	-3.02482
2377.99	-2.66971
2380.8	-2.57413
2383.6	-1.2154
2386.41	-0.579407
2389.21	-0.145523
2392.02	1.30988
2394.82	1.46824
2397.62	2.46602
2400.42	2.94954
2403.22	4.80255
2406.02	5.26414
2408.82	6.97584
2411.62	6.91897
2414.41	7.0678
2417.21	8.20211
2420	8.00356
2422.79	9.04758
2425.59	8.47895
2428.38	9.37352
2431.17	8.01913
2433.95	7.67499
2436.74	7.21515
2439.53	6.9951
2442.31	6.78582
2445.1	6.87879
2447.88	6.26722
2450.67	5.92879
2453.45	5.77476
2456.23	5.13094
2459.01	4.68797
2461.79	4.83015
2464.57	4.69805
2467.34	3.97335
2470.12	3.81032
2472.89	3.04159
2475.67	3.19575
2478.44	3.00069
2481.21	1.55341
2483.98	2.0929
2486.75	1.34974
2489.52	1.4936
2492.29	1.26768
2495.05	0.226377
2497.82	0.316956
2500.58	0.462821
2503.35	1.85548
2506.11	2.22266
2508.87	3.90754
2511.63	4.28231
2514.39	5.27774
2517.15	6.01705
2519.91	7.52361
2522.67	7.69473
2525.42	6.33969
2528.18	7.94794
2530.93	7.96378
2533.69	8.52094
2536.44	8.85678
2539.19	8.77288
2541.94	10.3145
2544.69	10.2092
2547.44	9.38589
2550.18	10.7203
2552.93	11.6005
2555.67	10.7603
2558.42	10.9059
2561.16	10.2659
2563.9	10.5804
2566.64	11.1336
2569.38	10.8013
2572.12	9.46789
2574.86	8.6326
2577.6	8.02935
2580.33	6.96244
2583.07	6.77211
2585.8	5.69853
2588.54	3.8821
2591.27	3.03533
2594	2.86071
2596.73	3.11455
2599.46	3.94565
2602.19	4.47133
2604.92	5.03944
2607.64	5.07751
2610.37	6.83453
2613.09	7.35996
2615.82	9.04422
2618.54	11.1768
2621.26	12.1556
2623.98	12.9717
2626.7	13.7292
2629.42	15.2655
2632.14	15.7669
2634.86	14.8396
2637.57	14.7962
2640.29	14.0352
2643	14.158
2645.71	13.3243
2648.43	13.7284
2651.14	12.5028
2653.85	11.2266
2656.56	11.48
2659.26	12.36
2661.97	12.1534
2664.68	12.4028
2667.38	12.4727
2670.09	11.3306
2672.79	12.811
2675.49	13.5813
2678.19	13.7258
2680.89	14.2506
2683.59	13.7499
2686.29	14.5798
2688.99	15.2668
2691.69	16.9454
2694.38	17.42
2697.08	18.744
2699.77	19.9049
2702.46	21.1192
2705.15	23.1766
2707.85	24.859
2710.54	25.7902
2713.22	27.4768
2715.91	27.9915
2718.6	27.8593
2721.29	27.7571
2723.97	28.499
2726.66	28.8102
2729.34	27.5925
2732.02	27.7623
2734.7	25.4036
2737.38	23.9872
2740.06	23.1656
2742.74	20.8974
2745.42	17.8972
2748.09	14.9832
2750.77	12.1059
2753.45	10.1536
2756.12	8.88098
2758.79	6.88665
2761.46	5.32196
2764.14	5.12463
2766.8	4.63727
2769.47	3.49648
2772.14	3.24141
2774.81	1.62654
2777.48	0.884632
2780.14	-0.656913
2782.8	-1.53597
2785.47	-2.55919
2788.13	-2.70921
2790.79	-2.60566
2793.45	-0.721323
2796.11	0.228301
2798.77	0.50716
2801.43	1.59482
2804.09	3.11223
2806.74	2.45969
2809.4	2.09528
2812.05	2.01248
2814.71	5.32575
2817.36	11.2799
2820.01	20.7593
2822.66	32.1681
2825.31	47.5487
2827.96	64.2352
2830.6	83.7149
2833.25	104.932
2835.9	127.266
2838.54	150.318
2841.18	176.129
2843.83	204.339
2846.47	235.007
2849.11	267.482
2851.75	300.069
2854.39	334.086
2857.03	366.252
2859.66	394.784
2862.3	422.296
2864.94	447.302
2867.57	469.804
2870.2	487.051
2872.84	503.091
2875.47	518.281
2878.1	534.305
2880.73	549.601
2883.36	564.211
2885.99	580.578
2888.61	594.384
2891.24	608.962
2893.86	623.614
2896.49	638.479
2899.11	654.716
2901.73	674.085
2904.36	697.678
2906.98	724.691
2909.6	755.44
2912.21	785.276
2914.83	817.08
2917.45	845.503
2920.07	868.728
2922.68	887.733
2925.29	901.306
2927.91	910.444
2930.52	911.226
2933.13	906.785
2935.74	894.583
2938.35	878.872
2940.96	858.104
2943.57	831.058
2946.18	800.439
2948.78	766.734
2951.39	730.458
2953.99	691.958
2956.59	653.03
2959.2	614.285
2961.8	578.666
2964.4	543.811
2967	511.32
2969.6	480.788
2972.19	451.968
2974.79	423.65
2977.39	397.012
2979.98	368.61
2982.58	339.815
2985.17	310.758
2987.76	282.978
2990.35	254.35
2992.94	227.052
2995.53	200.902
2998.12	175.613
3000.71	152.602
3003.3	131.766
3005.88	110.472
3008.47	92.6476
3011.05	75.8723
3013.64	61.4877
3016.22	50.8589
3018.8	40.8374
3021.38	32.6194
3023.96	28.2524
3026.54	22.9703
3029.12	19.9429
3031.69	17.1599
3034.27	15.466
3036.84	14.4272
3039.42	15.4203
3041.99	16.4019
3044.57	16.9082
3047.14	17.7344
3049.71	19.0027
3052.28	19.9824
3054.85	20.0164
3057.41	20.022
3059.98	19.5681
3062.55	18.6056
3065.11	16.6279
3067.68	14.4341
3070.24	11.5743
3072.8	9.48472
3075.36	8.08403
3077.93	7.51284
3080.49	5.04819
3083.04	3.32049
3085.6	3.29365
3088.16	3.35489
3090.72	3.50971
3093.27	4.09637
3095.83	5.13531
3098.38	6.76621
3100.93	9.13324
3103.49	11.1683
3106.04	13.5741
3108.59	15.5979
3111.14	18.4675
3113.69	21.5024
3116.23	24.7725
3118.78	27.8729
3121.33	30.9212
3123.87	34.3725
3126.41	36.4042
3128.96	39.7035
3131.5	42.6009
3134.04	46.0319
3136.58	50.3819
3139.12	54.0517
3141.66	57.5829
3144.2	61.2159
3146.74	63.9984
3149.27	64.1743