File: data/Raman/poly_smoothed/Mb_20_23_39_1x_45s_532 nm_x100_100%_600 gr_mm_01.txt
#Acq. time (s)=	45
#Accumulations=	2
#Range (cm-¹)=	200...3150
#Windows=	2
#Auto scanning=	Off
#Autofocus=	Off
#Macrospot=	Off
#AutoExposure=	Off
#Spike filter=	Multiple accum.
#Delay time (s)=	0
#Binning=	1
#Readout mode=	Signal
#DeNoise=	Off
#ICS correction=	On
#Dark correction=	Off
#Inst. Process=	Off
#Detector Gain=	Best Dynamic Range
#Detector ADC=	20 kHz
#Detector temperature (°C)=	-69.85
#Instrument=	LabRAM HR Evol
#Detector=	Synapse
#Objective=	x100
#Grating=	600 gr/mm
#ND Filter=	100%
#Laser (nm)=	532
#Hole=	100.021
#Range=	Auto
#Laser Pol.=	No
#Raman. Pol.=	No
#Laser Pol. (°)=	-0.0007625
#Raman Pol. (°)=	89.9995
#Collection=	Microscope
#StageXY=	Marzhauser
#StageZ=	Marzhauser
#X (µm)=	-7081.2
#Y (µm)=	2197.1
#Z (µm)=	-74.5
#Full time(mm:ss)=	3:18
#Project=
#Sample=
#Site=
#Title=	Mb_20_23_39_2x_45s_532 nm_x100_100%_600 gr_mm
#Remark=
#Date=	13.07.2022 16:31
#Acquired=	13.07.2022 16:31:58
#Base:Fit=	10.08.2022 10:29:37
#Base:Sub=	10.08.2022 10:34:43
#Filter:Polynom=	16.08.2022 10:13:29
#AxisType[0]=Intens
#AxisUnit[0]=Cnt
#AxisType[1]=Spectr
#AxisUnit[1]=1/cm
200.563	41.6264
204.194	38.9882
207.821	34.8112
211.449	31.7282
215.074	30.1968
218.699	30.0047
222.321	27.8961
225.941	27.9965
229.562	28.6596
233.18	25.4907
236.796	22.2036
240.411	21.2542
244.026	18.7722
247.638	17.7562
251.248	16.0852
254.857	14.548
258.465	13.2544
262.071	12.0251
265.678	10.5189
269.282	7.69584
272.884	4.63528
276.484	5.93863
280.084	2.67657
283.682	1.39113
287.276	1.25513
290.871	0.0578577
294.465	-0.848419
298.057	0.640294
301.648	3.82137
305.237	7.64408
308.823	10.3877
312.41	13.0573
315.995	15.2957
319.579	14.3283
323.16	14.7816
326.741	16.7952
330.321	18.8146
333.897	17.7146
337.474	21.0141
341.048	20.6528
344.622	21.8353
348.192	20.3983
351.764	19.8043
355.332	18.0851
358.901	15.7598
362.466	16.0915
366.03	14.683
369.594	12.3045
373.155	13.4908
376.715	12.8957
380.273	12.8866
383.832	14.7795
387.388	15.0864
390.942	16.8626
394.495	17.6353
398.047	18.8416
401.597	17.144
405.145	16.1744
408.693	14.0881
412.239	16.0251
415.783	16.0347
419.327	15.589
422.869	15.8296
426.409	14.8559
429.948	13.5383
433.486	12.1072
437.022	11.8272
440.558	10.3588
444.089	11.253
447.622	10.0924
451.153	11.311
454.682	11.8571
458.208	11.7881
461.735	12.8507
465.259	14.6404
468.783	14.618
472.306	15.5863
475.825	18.9623
479.346	22.1318
482.862	27.7262
486.38	29.9559
489.894	31.2082
493.407	35.1186
496.92	37.3496
500.43	38.9218
503.939	40.8825
507.448	41.9314
510.954	41.8477
514.459	44.3657
517.962	44.4072
521.466	45.4756
524.966	46.7267
528.466	44.4877
531.964	42.1673
535.46	42.0189
538.955	40.3739
542.449	35.9905
545.942	33.9502
549.433	31.353
552.923	28.7238
556.412	28.5938
559.899	28.4945
563.385	27.2809
566.867	26.8985
570.35	24.7285
573.832	20.0127
577.313	18.1215
580.79	15.9497
584.268	13.1463
587.745	11.0534
591.218	11.7887
594.692	9.92335
598.164	9.64525
601.634	8.02466
605.104	6.98604
608.57	6.94335
612.037	5.69963
615.501	3.61895
618.966	5.16859
622.427	4.7677
625.887	4.3659
629.348	4.33199
632.806	5.11821
636.262	4.36252
639.716	7.77216
643.172	7.5584
646.624	8.77126
650.075	10.62
653.524	10.6668
656.972	12.9987
660.419	14.7058
663.865	17.1087
667.309	17.3518
670.752	16.6678
674.194	18.4267
677.634	18.4402
681.073	17.9855
684.511	18.0171
687.947	18.0089
691.382	15.2263
694.816	14.7489
698.247	15.3993
701.678	15.1794
705.108	14.4365
708.534	15.1044
711.962	16.2926
715.388	17.6659
718.81	16.1553
722.234	17.3858
725.654	19.6061
729.075	21.3161
732.492	22.1459
735.91	22.9941
739.325	24.9511
742.741	25.7966
746.153	26.5304
749.564	30.8108
752.976	33.668
756.385	36.1569
759.792	39.7757
763.2	43.7987
766.604	45.5947
770.008	49.5314
773.41	51.3185
776.811	55.9595
780.21	61.1737
783.608	62.7328
787.005	65.2718
790.401	68.3111
793.795	71.1302
797.188	70.5933
800.58	72.4862
803.971	71.9492
807.36	71.6993
810.748	72.604
814.135	75.5454
817.518	75.4597
820.902	76.8123
824.285	77.3371
827.665	78.2568
831.045	81.454
834.424	81.9852
837.8	79.7032
841.177	77.6618
844.55	74.4359
847.924	71.3447
851.295	71.0395
854.666	68.3873
858.034	68.9761
861.403	67.6313
864.769	62.9983
868.133	63.138
871.498	61.7453
874.86	57.2301
878.221	55.2298
881.58	54.1839
884.938	53.088
888.297	53.0854
891.653	53.9369
895.007	53.7833
898.36	54.334
901.712	52.0595
905.063	51.0535
908.412	49.7166
911.76	50.3947
915.107	46.8445
918.452	44.87
921.797	40.8022
925.138	38.2035
928.48	38.3303
931.82	36.9837
935.16	36.9155
938.496	33.7766
941.833	32.4094
945.168	29.6285
948.5	27.8909
951.834	28.4157
955.163	24.9013
958.494	22.3686
961.821	18.9093
965.15	18.1052
968.474	18.1196
971.8	18.404
975.123	18.1138
978.446	17.2093
981.766	15.6638
985.084	14.0367
988.402	13.3075
991.72	13.6867
995.035	12.7961
998.349	11.3329
1001.66	11.4988
1004.97	13.3458
1008.28	15.8835
1011.59	17.3844
1014.9	19.4585
1018.21	22.3132
1021.51	25.8472
1024.81	33.7514
1028.12	39.2886
1031.42	47.9077
1034.72	54.7972
1038.02	61.494
1041.31	66.5306
1044.61	74.2179
1047.91	82.4696
1051.2	86.13
1054.49	87.1564
1057.78	90.7134
1061.07	89.5648
1064.36	89.0343
1067.65	86.5024
1070.93	84.4677
1074.22	82.765
1077.5	77.4912
1080.78	74.3741
1084.06	68.9714
1087.34	62.0097
1090.62	59.2141
1093.9	58.7532
1097.17	56.382
1100.45	55.2701
1103.72	57.5698
1106.99	61.1485
1110.27	64.1896
1113.53	67.1593
1116.8	67.2822
1120.07	67.0206
1123.33	65.4862
1126.6	63.9732
1129.86	60.2887
1133.12	57.3203
1136.38	55.9012
1139.64	52.6302
1142.9	46.4309
1146.16	41.1423
1149.41	37.0207
1152.67	32.3775
1155.92	25.4692
1159.17	19.2946
1162.42	12.34
1165.67	5.51681
1168.92	3.8531
1172.16	3.52321
1175.41	-1.65581
1178.65	-3.07583
1181.9	-1.87515
1185.14	0.213375
1188.38	3.16366
1191.62	2.42736
1194.86	3.70409
1198.09	5.53558
1201.33	6.70311
1204.56	9.97163
1207.8	13.2357
1211.03	17.8298
1214.26	22.8493
1217.49	27.7603
1220.71	32.1952
1223.94	37.2707
1227.16	41.4391
1230.39	46.3026
1233.61	51.6584
1236.83	57.0255
1240.05	59.867
1243.27	63.9173
1246.49	68.3852
1249.71	72.0997
1252.92	71.5479
1256.14	74.4537
1259.35	80.6904
1262.56	89.0087
1265.77	98.598
1268.98	107.65
1272.19	117.205
1275.4	127.3
1278.6	136.623
1281.81	146.947
1285.01	154.074
1288.21	161.169
1291.41	167.956
1294.61	174.635
1297.81	177.557
1301.01	179.994
1304.2	178.559
1307.4	181.412
1310.59	185.333
1313.78	185.081
1316.97	185.108
1320.16	184.955
1323.35	181.434
1326.54	176.277
1329.72	170.33
1332.91	165.819
1336.09	161.385
1339.27	159.315
1342.45	157.719
1345.64	154.781
1348.81	154.838
1351.99	151.881
1355.17	148.118
1358.34	143.916
1361.51	137.554
1364.69	131.697
1367.86	127.353
1371.03	122.411
1374.2	118.88
1377.37	113.652
1380.53	113.901
1383.7	113.775
1386.86	115.968
1390.02	116.374
1393.19	115.884
1396.35	115.205
1399.51	112.879
1402.66	116.605
1405.82	124.538
1408.97	136.107
1412.13	150.718
1415.28	168.411
1418.43	192.314
1421.59	216.388
1424.73	241.821
1427.88	269.902
1431.03	293.252
1434.18	312.688
1437.32	332.496
1440.46	347.277
1443.61	357.485
1446.75	364.372
1449.89	366.423
1453.03	362.084
1456.16	352.218
1459.3	340.588
1462.44	320.84
1465.57	297.818
1468.7	271.452
1471.83	243.741
1474.96	218.604
1478.09	193.33
1481.22	170.423
1484.35	145.799
1487.47	120.676
1490.6	100.351
1493.72	92.9622
1496.84	92.6881
1499.96	92.574
1503.08	95.7279
1506.2	98.9081
1509.32	99.9513
1512.44	102.901
1515.55	105.28
1518.66	104.175
1521.78	105.014
1524.89	108.106
1528	109.958
1531.11	108.672
1534.21	110.054
1537.32	111.148
1540.43	109.648
1543.53	108.015
1546.63	107.219
1549.74	103.461
1552.84	97.2309
1555.94	89.6466
1559.03	82.6087
1562.13	76.9608
1565.23	78.6601
1568.32	87.4847
1571.42	96.9072
1574.51	103.383
1577.6	109.778
1580.69	115.232
1583.78	120.644
1586.87	122.932
1589.95	125.304
1593.04	125.263
1596.12	125.129
1599.21	127.051
1602.29	127.508
1605.37	128.382
1608.45	128.519
1611.53	128.495
1614.6	125.986
1617.68	126.222
1620.75	127.33
1623.83	127.915
1626.9	127.372
1629.97	127.026
1633.04	127.746
1636.11	127.228
1639.18	128.108
1642.25	131.114
1645.31	133.27
1648.38	134.604
1651.44	136.661
1654.5	137.734
1657.56	133.967
1660.62	131.866
1663.68	127.031
1666.74	123.223
1669.8	116.924
1672.85	110.799
1675.91	104.536
1678.96	98.6549
1682.01	91.0411
1685.06	82.5639
1688.11	75.7494
1691.16	70.1194
1694.21	63.7563
1697.25	59.8104
1700.3	54.1694
1703.34	48.9568
1706.39	44.7179
1709.43	40.901
1712.47	38.2007
1715.51	37.2633
1718.54	37.065
1721.58	34.7273
1724.62	33.5398
1727.65	31.5322
1730.68	28.9767
1733.72	27.5729
1736.75	26.175
1739.78	24.9622
1742.81	23.8796
1745.84	21.3537
1748.86	20.2718
1751.89	17.9111
1754.91	16.4055
1757.93	14.9289
1760.96	12.8018
1763.98	11.0354
1767	9.51183
1770.02	8.78488
1773.03	7.55162
1776.05	5.68919
1779.07	4.19132
1782.08	3.26153
1785.09	2.5872
1788.11	4.19662
1791.12	4.80849
1794.13	5.46534
1797.13	4.41233
1800.14	4.01403
1803.15	2.94296
1806.15	3.90471
1809.16	4.25939
1812.16	3.99342
1815.16	4.19983
1818.16	3.24184
1821.16	3.07976
1824.16	3.10096
1827.16	1.24346
1830.16	1.07181
1833.15	1.62398
1836.14	1.11038
1839.14	1.91215
1842.13	1.34993
1845.12	0.651693
1848.11	1.03708
1851.1	1.63039
1854.08	3.15706
1857.07	5.56399
1860.05	8.35682
1863.04	11.284
1866.02	12.3016
1869	11.6777
1871.98	12.7419
1874.96	13.8978
1877.94	15.4006
1880.92	16.2913
1882.51	16.5555
1885.5	16.7926
1888.48	16.2202
1891.47	15.7705
1894.46	15.5042
1897.44	14.3867
1900.42	14.1414
1903.41	15.3441
1906.39	14.2697
1909.37	13.8612
1912.35	14.7578
1915.32	14.6907
1918.3	17.108
1921.27	19.1687
1924.25	20.1474
1927.22	20.0957
1930.19	19.9918
1933.17	18.1572
1936.14	17.594
1939.11	15.4253
1942.07	14.2892
1945.04	13.7658
1948.01	14.4583
1950.97	13.1127
1953.93	12.5851
1956.9	10.7987
1959.86	8.67003
1962.82	6.76065
1965.78	6.38959
1968.74	6.6169
1971.69	6.09148
1974.65	6.53364
1977.6	7.93008
1980.56	7.88151
1983.51	8.73032
1986.46	11.3645
1989.41	13.2684
1992.36	13.5135
1995.31	13.029
1998.26	11.291
2001.2	11.6615
2004.15	12.7065
2007.09	11.7531
2010.04	11.8512
2012.98	11.6756
2015.92	11.8588
2018.86	13.807
2021.8	13.2462
2024.73	12.6679
2027.67	12.6246
2030.61	10.9167
2033.54	11.3407
2036.47	11.3826
2039.4	13.1203
2042.33	12.8912
2045.27	12.9896
2048.19	14.3468
2051.12	14.2525
2054.05	15.11
2056.97	16.5627
2059.9	15.8211
2062.82	15.7939
2065.74	15.4717
2068.67	16.4654
2071.59	17.7632
2074.51	17.9096
2077.42	17.1679
2080.34	15.6193
2083.26	18.1614
2086.17	20.7963
2089.09	22.9366
2092	24.0834
2094.91	24.4151
2097.82	25.9604
2100.73	27.4484
2103.64	29.6138
2106.55	32.488
2109.45	34.4609
2112.36	35.4235
2115.26	37.4458
2118.17	39.6482
2121.07	40.731
2123.97	44.4394
2126.87	46.1052
2129.77	48.2738
2132.67	49.6968
2135.56	53.952
2138.46	57.3306
2141.35	57.7723
2144.25	59.44
2147.14	60.8341
2150.03	62.0761
2152.92	67.8861
2155.81	72.4074
2158.7	74.9957
2161.59	77.5377
2164.47	79.8131
2167.36	81.64
2170.24	84.99
2173.13	86.9767
2176.01	86.7772
2178.89	85.9785
2181.77	84.1174
2184.65	83.0996
2187.53	81.6509
2190.4	80.0195
2193.28	78.2438
2196.16	75.6752
2199.03	71.4327
2201.9	67.8877
2204.77	64.1747
2207.64	61.3694
2210.51	56.4421
2213.38	52.5565
2216.25	48.9962
2219.12	46.1807
2221.98	44.2558
2224.85	42.3836
2227.71	41.1595
2230.57	37.3443
2233.43	38.1922
2236.29	38.8185
2239.15	38.6315
2242.01	37.837
2244.87	37.516
2247.72	36.809
2250.58	35.2804
2253.43	34.5701
2256.29	34.0457
2259.14	34.9788
2261.99	33.6847
2264.84	34.7916
2267.69	32.1109
2270.53	29.956
2273.38	27.8928
2276.23	26.6497
2279.07	23.9104
2281.91	21.5523
2284.76	18.7134
2287.6	16.7111
2290.44	15.0388
2293.28	10.8407
2296.12	10.3089
2298.96	9.0908
2301.79	9.36309
2304.63	10.943
2307.46	10.0069
2310.3	9.34136
2313.13	10.1462
2315.96	8.70741
2318.79	6.84202
2321.62	7.51373
2324.45	7.25843
2327.27	7.18451
2330.1	8.19753
2332.92	8.56962
2335.75	7.27656
2338.57	5.89807
2341.39	6.83328
2344.21	7.80814
2347.04	7.69202
2349.85	7.34856
2352.67	6.44328
2355.49	6.27696
2358.3	5.45504
2361.12	4.91191
2363.93	4.36584
2366.75	5.82386
2369.56	3.59949
2372.37	3.1249
2375.18	2.62376
2377.99	3.33728
2380.8	2.18038
2383.6	2.47532
2386.41	1.16716
2389.21	0.133658
2392.02	0.0269348
2394.82	-0.400561
2397.62	-1.00372
2400.42	-0.958477
2403.22	-0.763515
2406.02	0.39389
2408.82	2.53443
2411.62	4.74195
2414.41	7.13721
2417.21	7.29429
2420	7.96909
2422.79	7.85909
2425.59	9.48521
2428.38	9.35262
2431.17	9.92439
2433.95	10.0029
2436.74	9.72409
2439.53	9.68312
2442.31	9.60918
2445.1	10.5014
2447.88	9.98671
2450.67	10.1557
2453.45	8.88523
2456.23	6.1761
2459.01	5.5582
2461.79	4.35627
2464.57	1.84865
2467.34	1.60517
2470.12	2.14327
2472.89	0.960342
2475.67	2.45312
2478.44	1.70016
2481.21	2.78068
2483.98	0.87082
2486.75	-0.0647571
2489.52	0.0744311
2492.29	-0.401278
2495.05	-0.941468
2497.82	-1.57744
2500.58	-1.80479
2503.35	-0.527412
2506.11	0.100081
2508.87	-0.449028
2511.63	0.957241
2514.39	2.04711
2517.15	1.16718
2519.91	1.34887
2522.67	0.454313
2525.42	1.61869
2528.18	1.29555
2530.93	0.865021
2533.69	2.40291
2536.44	2.63846
2539.19	2.25665
2541.94	3.37053
2544.69	3.84608
2547.44	3.32922
2550.18	4.21492
2552.93	3.81016
2555.67	4.85276
2558.42	5.73527
2561.16	4.67673
2563.9	4.50685
2566.64	6.02061
2569.38	6.45983
2572.12	7.25969
2574.86	6.83205
2577.6	8.53958
2580.33	6.94666
2583.07	6.27885
2585.8	5.21918
2588.54	5.2893
2591.27	4.47638
2594	4.95035
2596.73	3.77139
2599.46	4.80547
2602.19	3.30906
2604.92	3.37268
2607.64	2.51983
2610.37	3.20304
2613.09	3.61223
2615.82	5.06956
2618.54	5.23981
2621.26	5.58933
2623.98	5.60798
2626.7	6.69877
2629.42	6.76286
2632.14	7.70704
2634.86	8.38829
2637.57	10.1972
2640.29	11.1472
2643	12.2054
2645.71	13.7644
2648.43	14.7929
2651.14	15.6174
2653.85	18.1171
2656.56	19.2661
2659.26	20.7175
2661.97	20.8404
2664.68	20.2981
2667.38	20.3577
2670.09	20.0622
2672.79	20.776
2675.49	20.5782
2678.19	20.7074
2680.89	19.9284
2683.59	19.9038
2686.29	18.6907
2688.99	18.6821
2691.69	20.0606
2694.38	21.8495
2697.08	23.9897
2699.77	26.1675
2702.46	29.1485
2705.15	31.5817
2707.85	33.3843
2710.54	37.3648
2713.22	40.0781
2715.91	41.8888
2718.6	42.6127
2721.29	45.1698
2723.97	43.7672
2726.66	43.5344
2729.34	43.0293
2732.02	42.0049
2734.7	39.4664
2737.38	36.3583
2740.06	33.4128
2742.74	29.9258
2745.42	26.373
2748.09	22.6603
2750.77	20.5298
2753.45	18.1207
2756.12	17.3695
2758.79	15.1851
2761.46	13.7226
2764.14	12.9794
2766.8	10.9703
2769.47	9.29679
2772.14	7.83272
2774.81	6.53744
2777.48	5.88037
2780.14	5.33586
2782.8	3.62705
2785.47	4.03617
2788.13	4.42417
2790.79	4.75536
2793.45	5.43452
2796.11	4.83323
2798.77	5.24807
2801.43	3.58722
2804.09	2.4141
2806.74	-0.133772
2809.4	-3.74136
2812.05	-3.92832
2814.71	-0.46665
2817.36	10.7009
2820.01	27.9572
2822.66	53.6976
2825.31	85.2494
2827.96	120
2830.6	157.877
2833.25	196.774
2835.9	237.542
2838.54	278.685
2841.18	319.279
2843.83	357.056
2846.47	396.155
2849.11	437.173
2851.75	481.69
2854.39	525.292
2857.03	567.779
2859.66	605.84
2862.3	638.051
2864.94	661.22
2867.57	680.384
2870.2	694.117
2872.84	704.954
2875.47	713.081
2878.1	724.243
2880.73	736.261
2883.36	746.682
2885.99	757.218
2888.61	764.018
2891.24	768.056
2893.86	768.962
2896.49	769.638
2899.11	768.026
2901.73	765.935
2904.36	766.511
2906.98	768.853
2909.6	775.047
2912.21	786.973
2914.83	803.776
2917.45	818.284
2920.07	830.162
2922.68	836.32
2925.29	835.336
2927.91	833.524
2930.52	825.167
2933.13	815.5
2935.74	800.875
2938.35	780.187
2940.96	757.982
2943.57	730.833
2946.18	700.034
2948.78	666.084
2951.39	630.957
2953.99	593.793
2956.59	558.751
2959.2	523.736
2961.8	488.8
2964.4	456.769
2967	427.77
2969.6	400.136
2972.19	373.329
2974.79	346.524
2977.39	321.681
2979.98	296.49
2982.58	268.728
2985.17	242.161
2987.76	216.192
2990.35	191.674
2992.94	168.2
2995.53	145.889
2998.12	126.295
3000.71	107.666
3003.3	89.6542
3005.88	73.4751
3008.47	59.9129
3011.05	47.1179
3013.64	37.6065
3016.22	28.1638
3018.8	22.4112
3021.38	16.1401
3023.96	11.3726
3026.54	7.77575
3029.12	3.92389
3031.69	2.47692
3034.27	2.02151
3036.84	-0.571387
3039.42	-1.34577
3041.99	-0.922003
3044.57	0.210399
3047.14	1.30611
3049.71	2.43312
3052.28	3.77008
3054.85	4.31584
3057.41	5.21491
3059.98	5.88797
3062.55	6.02209
3065.11	7.0727
3067.68	6.91919
3070.24	7.41429
3072.8	7.4
3075.36	7.43032
3077.93	6.64829
3080.49	5.34278
3083.04	2.85708
3085.6	1.74419
3088.16	0.43549
3090.72	0.0797051
3093.27	-0.585979
3095.83	1.03314
3098.38	1.81941
3100.93	4.83457
3103.49	6.99474
3106.04	10.6471
3108.59	13.5038
3111.14	16.2544
3113.69	20.8737
3116.23	24.5797
3118.78	28.3891
3121.33	32.03
3123.87	37.2325
3126.41	42.5573
3128.96	47.8959
3131.5	52.1924
3134.04	57.3571
3136.58	61.9737
3139.12	66.1963
3141.66	69.8412
3144.2	74.3762
3146.74	80.1799
3149.27	88.3206