File: data/Raman/poly_smoothed/Mb_20_23_36_1x_45s_532 nm_x100_100%_600 gr_mm_01.txt
#Acq. time (s)=	45
#Accumulations=	2
#Range (cm-¹)=	200...3150
#Windows=	2
#Auto scanning=	Off
#Autofocus=	Off
#Macrospot=	Off
#AutoExposure=	Off
#Spike filter=	Multiple accum.
#Delay time (s)=	0
#Binning=	1
#Readout mode=	Signal
#DeNoise=	Off
#ICS correction=	On
#Dark correction=	Off
#Inst. Process=	Off
#Detector Gain=	Best Dynamic Range
#Detector ADC=	20 kHz
#Detector temperature (°C)=	-69.85
#Instrument=	LabRAM HR Evol
#Detector=	Synapse
#Objective=	x100
#Grating=	600 gr/mm
#ND Filter=	100%
#Laser (nm)=	532
#Hole=	100.021
#Range=	Auto
#Laser Pol.=	No
#Raman. Pol.=	No
#Laser Pol. (°)=	-0.0007625
#Raman Pol. (°)=	89.9995
#Collection=	Microscope
#StageXY=	Marzhauser
#StageZ=	Marzhauser
#X (µm)=	-6945.2
#Y (µm)=	1946.6
#Z (µm)=	-75
#Full time(mm:ss)=	3:18
#Project=
#Sample=
#Site=
#Title=	Mb_20_23_36_2x_45s_532 nm_x100_100%_600 gr_mm
#Remark=
#Date=	13.07.2022 15:55
#Acquired=	13.07.2022 15:55:32
#Base:Fit=	10.08.2022 10:29:37
#Base:Sub=	10.08.2022 10:34:43
#Filter:Polynom=	16.08.2022 10:13:29
#AxisType[0]=Intens
#AxisUnit[0]=Cnt
#AxisType[1]=Spectr
#AxisUnit[1]=1/cm
200.563	107.513
204.194	100.274
207.821	93.8684
211.449	87.8461
215.074	82.8138
218.699	78.8619
222.321	74.6747
225.941	69.85
229.562	65.2224
233.18	60.433
236.796	57.5884
240.411	55.114
244.026	49.4437
247.638	46.4464
251.248	41.8908
254.857	36.521
258.465	34.104
262.071	29.7271
265.678	24.8699
269.282	21.5091
272.884	18.9566
276.484	16.745
280.084	11.0236
283.682	8.30118
287.276	6.75714
290.871	6.40173
294.465	7.4346
298.057	7.79549
301.648	10.4947
305.237	15.2161
308.823	19.0324
312.41	24.1008
315.995	26.4528
319.579	28.603
323.16	32.8706
326.741	38.4781
330.321	38.3742
333.897	39.2185
337.474	40.8095
341.048	39.3514
344.622	38.7
348.192	37.4118
351.764	36.8684
355.332	34.3927
358.901	31.5913
362.466	28.551
366.03	24.4351
369.594	22.932
373.155	21.6662
376.715	20.2036
380.273	19.7711
383.832	20.743
387.388	22.2815
390.942	25.2959
394.495	27.4961
398.047	27.7499
401.597	26.1366
405.145	23.4156
408.693	23.0185
412.239	24.6381
415.783	23.3748
419.327	20.8408
422.869	18.2328
426.409	17.7671
429.948	14.1903
433.486	13.9869
437.022	13.4023
440.558	12.1177
444.089	10.9862
447.622	12.4337
451.153	12.8982
454.682	14.6461
458.208	18.0694
461.735	22.4853
465.259	26.3533
468.783	30.4112
472.306	34.3395
475.825	39.9703
479.346	42.545
482.862	44.0986
486.38	45.881
489.894	49.1881
493.407	52.5724
496.92	55.6497
500.43	56.524
503.939	57.6886
507.448	58.1263
510.954	61.6881
514.459	59.5933
517.962	58.8441
521.466	57.3858
524.966	57.5762
528.466	57.7008
531.964	55.8084
535.46	54.4299
538.955	52.728
542.449	49.7126
545.942	47.7299
549.433	46.1431
552.923	44.0575
556.412	43.4647
559.899	41.01
563.385	38.3357
566.867	35.2111
570.35	30.9097
573.832	29.1582
577.313	28.0614
580.79	24.9817
584.268	24.209
587.745	22.8609
591.218	21.6416
594.692	20.2215
598.164	19.7591
601.634	20.6211
605.104	20.6608
608.57	20.3467
612.037	19.7846
615.501	18.4017
618.966	18.2235
622.427	17.6159
625.887	17.4921
629.348	18.6506
632.806	20.7774
636.262	21.5726
639.716	20.2609
643.172	19.0269
646.624	16.9518
650.075	13.7898
653.524	10.9081
656.972	10.4744
660.419	9.9364
663.865	9.05839
667.309	9.12199
670.752	9.21988
674.194	7.19252
677.634	7.62296
681.073	9.47441
684.511	12.6864
687.947	14.2757
691.382	13.8682
694.816	14.6802
698.247	17.5909
701.678	20.2875
705.108	22.5118
708.534	26.3733
711.962	29.2092
715.388	31.8239
718.81	33.2523
722.234	32.5871
725.654	33.3305
729.075	35.5383
732.492	36.0485
735.91	37.9793
739.325	38.2539
742.741	40.5135
746.153	43.1741
749.564	44.1201
752.976	47.7286
756.385	49.6065
759.792	51.8904
763.2	55.3656
766.604	58.245
770.008	59.5256
773.41	61.4358
776.811	61.3406
780.21	64.7444
783.608	65.9518
787.005	70.6997
790.401	72.5399
793.795	76.3178
797.188	79.2533
800.58	81.1644
803.971	82.3613
807.36	83.2337
810.748	86.0537
814.135	89.6084
817.518	90.9805
820.902	91.8093
824.285	92.9086
827.665	92.6446
831.045	92.7097
834.424	91.6719
837.8	91.8781
841.177	89.5171
844.55	87.8662
847.924	86.7017
851.295	83.2877
854.666	84.3412
858.034	86.4216
861.403	85.2999
864.769	84.6582
868.133	87.8504
871.498	88.0594
874.86	87.8023
878.221	88.8993
881.58	88.6744
884.938	89.2042
888.297	90.2959
891.653	89.7573
895.007	89.9108
898.36	88.6023
901.712	87.1251
905.063	86.661
908.412	85.3095
911.76	84.6477
915.107	81.7484
918.452	81.0647
921.797	78.7971
925.138	75.7683
928.48	74.2582
931.82	75.6183
935.16	74.3565
938.496	71.0654
941.833	65.9134
945.168	60.7221
948.5	52.6997
951.834	50.5436
955.163	45.1199
958.494	41.5215
961.821	38.972
965.15	38.0015
968.474	37.4555
971.8	36.8377
975.123	37.6305
978.446	38.8968
981.766	40.8111
985.084	42.7719
988.402	45.5354
991.72	48.4441
995.035	48.4946
998.349	50.4253
1001.66	52.4417
1004.97	53.5173
1008.28	57.8085
1011.59	62.3097
1014.9	66.0342
1018.21	67.925
1021.51	74.5399
1024.81	83.598
1028.12	96.1708
1031.42	109.131
1034.72	119.78
1038.02	130.619
1041.31	137.853
1044.61	144.92
1047.91	150.332
1051.2	153.764
1054.49	155.795
1057.78	155.66
1061.07	151.403
1064.36	147.037
1067.65	144.105
1070.93	139.519
1074.22	131.343
1077.5	121.255
1080.78	112.946
1084.06	99.3633
1087.34	89.3506
1090.62	86.2322
1093.9	87.6901
1097.17	92.6531
1100.45	99.0982
1103.72	110.225
1106.99	116.961
1110.27	120.648
1113.53	120.872
1116.8	120.073
1120.07	116.736
1123.33	110.933
1126.6	105.639
1129.86	101.134
1133.12	94.5139
1136.38	85.7733
1139.64	80.6211
1142.9	73.6448
1146.16	67.2278
1149.41	58.4007
1152.67	45.5121
1155.92	34.1302
1159.17	22.3399
1162.42	10.6502
1165.67	5.21636
1168.92	8.41629
1172.16	11.9627
1175.41	17.5695
1178.65	19.9209
1181.9	19.7293
1185.14	20.0696
1188.38	22.8566
1191.62	23.9322
1194.86	25.4175
1198.09	27.0308
1201.33	30.5379
1204.56	34.7006
1207.8	38.863
1211.03	44.9883
1214.26	51.9915
1217.49	61.8057
1220.71	71.2207
1223.94	77.1584
1227.16	82.596
1230.39	88.0393
1233.61	92.7542
1236.83	97.6875
1240.05	101.406
1243.27	106.623
1246.49	112.739
1249.71	114.984
1252.92	113.025
1256.14	114.611
1259.35	122.97
1262.56	134.265
1265.77	148.311
1268.98	162.823
1272.19	176.812
1275.4	188.052
1278.6	200.585
1281.81	211.504
1285.01	221.942
1288.21	229.862
1291.41	238.067
1294.61	245.11
1297.81	248.422
1301.01	248.635
1304.2	245.674
1307.4	244.138
1310.59	238.856
1313.78	230.122
1316.97	220.754
1320.16	209.449
1323.35	196.211
1326.54	183.308
1329.72	168.573
1332.91	161.717
1336.09	159.292
1339.27	158.886
1342.45	159.847
1345.64	157.688
1348.81	154.573
1351.99	152.59
1355.17	148.98
1358.34	147.465
1361.51	145
1364.69	143.294
1367.86	141.337
1371.03	138.621
1374.2	136.599
1377.37	136.165
1380.53	135.175
1383.7	135.714
1386.86	135.687
1390.02	132.151
1393.19	131.896
1396.35	128.345
1399.51	127.072
1402.66	134.49
1405.82	146.945
1408.97	165.355
1412.13	187.097
1415.28	211.392
1418.43	238.583
1421.59	266.164
1424.73	294.141
1427.88	325.028
1431.03	354.902
1434.18	382.712
1437.32	403.925
1440.46	422.127
1443.61	432.91
1446.75	439.283
1449.89	437.712
1453.03	430.757
1456.16	416.271
1459.3	395.587
1462.44	368.959
1465.57	334.874
1468.7	297.873
1471.83	261.624
1474.96	225.504
1478.09	197.903
1481.22	173.394
1484.35	148.452
1487.47	125.999
1490.6	105.138
1493.72	89.463
1496.84	78.1739
1499.96	69.241
1503.08	65.2302
1506.2	59.1378
1509.32	55.5324
1512.44	53.3265
1515.55	49.9046
1518.66	49.2556
1521.78	47.5797
1524.89	48.4003
1528	47.3332
1531.11	48.3325
1534.21	50.778
1537.32	53.7413
1540.43	57.3478
1543.53	61.398
1546.63	64.9976
1549.74	68.5835
1552.84	72.7458
1555.94	78.2435
1559.03	81.8937
1562.13	86.1569
1565.23	91.2446
1568.32	98.3033
1571.42	105.388
1574.51	111.413
1577.6	117.281
1580.69	120.883
1583.78	124.309
1586.87	129.856
1589.95	132.892
1593.04	134.996
1596.12	135.615
1599.21	138.032
1602.29	136.844
1605.37	136.611
1608.45	138.586
1611.53	139.508
1614.6	139.334
1617.68	139.014
1620.75	138.36
1623.83	137.051
1626.9	140.25
1629.97	143.736
1633.04	147.415
1636.11	150.165
1639.18	156.205
1642.25	160.235
1645.31	166.113
1648.38	171.493
1651.44	175.108
1654.5	177.708
1657.56	178.453
1660.62	178.556
1663.68	175.995
1666.74	170.932
1669.8	164.609
1672.85	157.576
1675.91	147.827
1678.96	138.58
1682.01	128.7
1685.06	117.006
1688.11	106.748
1691.16	94.9951
1694.21	84.1362
1697.25	77.0908
1700.3	69.7324
1703.34	63.9087
1706.39	56.7564
1709.43	51.3519
1712.47	45.8607
1715.51	41.939
1718.54	37.3688
1721.58	35.8102
1724.62	34.2354
1727.65	34.0478
1730.68	32.0713
1733.72	30.0263
1736.75	27.9615
1739.78	26.4733
1742.81	26.402
1745.84	25.0518
1748.86	25.4372
1751.89	23.9215
1754.91	21.8218
1757.93	19.4817
1760.96	18.3523
1763.98	17.8114
1767	16.8186
1770.02	16.5367
1773.03	15.6756
1776.05	13.1101
1779.07	10.6233
1782.08	9.8863
1785.09	8.32929
1788.11	6.97636
1791.12	5.97314
1794.13	6.06157
1797.13	5.33146
1800.14	4.20055
1803.15	2.586
1806.15	2.22044
1809.16	1.64051
1812.16	1.09669
1815.16	0.276633
1818.16	0.622513
1821.16	0.878374
1824.16	1.24044
1827.16	0.86614
1830.16	1.19524
1833.15	1.9886
1836.14	3.3104
1839.14	2.79365
1842.13	2.59833
1845.12	2.28514
1848.11	1.77695
1851.1	3.11852
1854.08	3.3236
1857.07	3.91148
1860.05	4.82593
1863.04	3.6364
1866.02	3.64146
1869	4.19557
1871.98	4.41086
1874.96	4.35422
1877.94	3.73466
1880.92	3.23001
1882.51	2.22124
1885.5	1.96585
1888.48	0.982769
1891.47	0.408992
1894.46	0.367866
1897.44	0.377
1900.42	1.61027
1903.41	3.47725
1906.39	3.24747
1909.37	2.89284
1912.35	2.85044
1915.32	4.29075
1918.3	4.64381
1921.27	6.33831
1924.25	6.17853
1927.22	6.67854
1930.19	6.31179
1933.17	6.99615
1936.14	6.96902
1939.11	6.5702
1942.07	6.96496
1945.04	5.76916
1948.01	3.96965
1950.97	3.86187
1953.93	1.9348
1956.9	0.310329
1959.86	-0.104343
1962.82	-1.05269
1965.78	-1.04315
1968.74	0.166721
1971.69	1.62442
1974.65	3.16115
1977.6	1.79874
1980.56	0.498595
1983.51	0.916002
1986.46	2.10601
1989.41	3.31289
1992.36	2.43351
1995.31	3.33432
1998.26	4.22211
2001.2	4.75883
2004.15	5.78477
2007.09	7.22101
2010.04	6.11605
2012.98	7.44489
2015.92	7.71416
2018.86	7.53838
2021.8	7.92823
2024.73	8.45951
2027.67	7.90628
2030.61	9.09227
2033.54	8.8459
2036.47	9.33725
2039.4	10.5912
2042.33	10.2868
2045.27	9.29307
2048.19	8.38854
2051.12	6.12655
2054.05	7.01674
2056.97	9.85454
2059.9	10.3042
2062.82	12.0758
2065.74	13.3906
2068.67	14.6104
2071.59	16.0267
2074.51	16.4266
2077.42	16.9884
2080.34	16.5771
2083.26	16.9513
2086.17	19.2476
2089.09	19.088
2092	19.4697
2094.91	20.1657
2097.82	20.9238
2100.73	21.1882
2103.64	22.1063
2106.55	23.283
2109.45	23.7727
2112.36	25.4412
2115.26	25.885
2118.17	26.9204
2121.07	30.7737
2123.97	35.69
2126.87	41.6566
2129.77	45.6067
2132.67	49.3998
2135.56	54.1917
2138.46	56.6265
2141.35	60.8131
2144.25	65.6526
2147.14	69.8121
2150.03	75.4036
2152.92	80.9152
2155.81	87.1575
2158.7	92.0625
2161.59	96.0843
2164.47	100.629
2167.36	104.006
2170.24	106.614
2173.13	107.398
2176.01	108.875
2178.89	108.557
2181.77	106.768
2184.65	103.172
2187.53	99.709
2190.4	95.9984
2193.28	92.8819
2196.16	86.804
2199.03	80.8862
2201.9	74.3522
2204.77	67.8045
2207.64	61.409
2210.51	55.5881
2213.38	51.9753
2216.25	47.7223
2219.12	43.3194
2221.98	40.5208
2224.85	37.9218
2227.71	35.1219
2230.57	34.1789
2233.43	33.27
2236.29	31.702
2239.15	30.0396
2242.01	28.206
2244.87	26.6274
2247.72	25.5117
2250.58	23.5466
2253.43	21.2847
2256.29	19.9364
2259.14	19.1081
2261.99	17.5172
2264.84	15.8379
2267.69	14.6648
2270.53	12.738
2273.38	10.2264
2276.23	9.23352
2279.07	8.06908
2281.91	7.9888
2284.76	7.95476
2287.6	6.57757
2290.44	5.22372
2293.28	4.55998
2296.12	4.69724
2298.96	5.84988
2301.79	7.28767
2304.63	8.43963
2307.46	9.27708
2310.3	8.54389
2313.13	9.98977
2315.96	10.5267
2318.79	10.3874
2321.62	9.6089
2324.45	8.26514
2327.27	7.19159
2330.1	6.88318
2332.92	6.48815
2335.75	5.3354
2338.57	5.91382
2341.39	4.80276
2344.21	3.99256
2347.04	4.44825
2349.85	3.95033
2352.67	3.29475
2355.49	3.43202
2358.3	2.53015
2361.12	1.71818
2363.93	2.53631
2366.75	3.88984
2369.56	5.09361
2372.37	5.41879
2375.18	5.29212
2377.99	4.68708
2380.8	4.55377
2383.6	4.36181
2386.41	2.62067
2389.21	1.76599
2392.02	2.08381
2394.82	0.98605
2397.62	1.67826
2400.42	2.10948
2403.22	3.44187
2406.02	4.2506
2408.82	4.94957
2411.62	5.20726
2414.41	5.69412
2417.21	6.69657
2420	8.12811
2422.79	8.8884
2425.59	9.16869
2428.38	9.55729
2431.17	11.902
2433.95	13.0917
2436.74	13.0416
2439.53	13.7441
2442.31	12.7648
2445.1	11.6851
2447.88	11.1251
2450.67	11.6757
2453.45	10.6258
2456.23	10.3932
2459.01	10.5211
2461.79	10.5094
2464.57	8.89971
2467.34	9.16067
2470.12	8.29326
2472.89	7.51037
2475.67	5.18761
2478.44	3.47494
2481.21	2.43225
2483.98	2.20375
2486.75	0.996721
2489.52	0.164914
2492.29	9.0492e-005
2495.05	0.611083
2497.82	1.58634
2500.58	2.12161
2503.35	1.64656
2506.11	1.01729
2508.87	1.87506
2511.63	1.31291
2514.39	3.66327
2517.15	5.59911
2519.91	5.7734
2522.67	7.14003
2525.42	8.2609
2528.18	8.84343
2530.93	9.68868
2533.69	8.40352
2536.44	10.0528
2539.19	10.4163
2541.94	9.16318
2544.69	8.99569
2547.44	7.83935
2550.18	8.04324
2552.93	7.27053
2555.67	7.70992
2558.42	9.42172
2561.16	9.61872
2563.9	10.8236
2566.64	10.2104
2569.38	9.6206
2572.12	9.77303
2574.86	10.4197
2577.6	10.0383
2580.33	10.2852
2583.07	10.4745
2585.8	9.5181
2588.54	10.6898
2591.27	11.5515
2594	10.7791
2596.73	11.1882
2599.46	11.4011
2602.19	11.4525
2604.92	11.6171
2607.64	10.6929
2610.37	10.5128
2613.09	10.3167
2615.82	11.2947
2618.54	12.1627
2621.26	13.2082
2623.98	14.3152
2626.7	15.3791
2629.42	15.7691
2632.14	16.582
2634.86	16.7343
2637.57	17.2332
2640.29	17.7491
2643	18.5299
2645.71	19.4448
2648.43	20.0875
2651.14	20.0891
2653.85	19.2346
2656.56	18.7861
2659.26	18.6479
2661.97	17.056
2664.68	16.378
2667.38	15.9022
2670.09	15.7418
2672.79	13.9146
2675.49	13.4675
2678.19	13.1577
2680.89	13.4531
2683.59	14.7759
2686.29	15.9907
2688.99	17.9112
2691.69	19.8497
2694.38	23.2716
2697.08	26.9255
2699.77	31.53
2702.46	35.7396
2705.15	40.3531
2707.85	46.122
2710.54	50.6613
2713.22	53.9295
2715.91	55.3994
2718.6	57.4454
2721.29	58.9657
2723.97	59.2457
2726.66	59.0633
2729.34	56.1193
2732.02	52.8295
2734.7	48.42
2737.38	42.6014
2740.06	37.1525
2742.74	32.2937
2745.42	27.2391
2748.09	23.5374
2750.77	17.901
2753.45	13.5637
2756.12	9.36495
2758.79	6.36503
2761.46	4.49675
2764.14	2.5782
2766.8	1.71259
2769.47	0.821275
2772.14	-0.186651
2774.81	0.343868
2777.48	0.318378
2780.14	1.24879
2782.8	2.32218
2785.47	3.15888
2788.13	4.49135
2790.79	4.79263
2793.45	4.29636
2796.11	4.61652
2798.77	4.84506
2801.43	3.1339
2804.09	0.6876
2806.74	-2.58386
2809.4	-7.25655
2812.05	-6.83019
2814.71	0.466218
2817.36	16.8144
2820.01	42.4021
2822.66	76.5708
2825.31	117.963
2827.96	165.465
2830.6	217.424
2833.25	271.07
2835.9	325.404
2838.54	380.175
2841.18	434.604
2843.83	486.957
2846.47	531.35
2849.11	578.868
2851.75	634.548
2854.39	697.398
2857.03	758.545
2859.66	813.107
2862.3	858.672
2864.94	891.859
2867.57	915.886
2870.2	932.288
2872.84	943.588
2875.47	954.982
2878.1	966.769
2880.73	976.862
2883.36	986.738
2885.99	993.563
2888.61	993.86
2891.24	992.385
2893.86	984.224
2896.49	975.435
2899.11	963.457
2901.73	950.503
2904.36	941.417
2906.98	935.687
2909.6	934.748
2912.21	943.597
2914.83	966.203
2917.45	993.365
2920.07	1011.32
2922.68	1019.66
2925.29	1020.81
2927.91	1014.8
2930.52	1005.04
2933.13	989.844
2935.74	972.26
2938.35	948.834
2940.96	920.485
2943.57	886.018
2946.18	847.222
2948.78	806.508
2951.39	761.513
2953.99	715.86
2956.59	669.527
2959.2	625.998
2961.8	583.663
2964.4	542.958
2967	507.627
2969.6	474.631
2972.19	443.025
2974.79	411.206
2977.39	381.725
2979.98	351.398
2982.58	319.647
2985.17	286.679
2987.76	256.852
2990.35	228.113
2992.94	199.456
2995.53	173.637
2998.12	149.715
3000.71	128.23
3003.3	107.868
3005.88	88.8138
3008.47	72.887
3011.05	58.8786
3013.64	47.283
3016.22	36.5054
3018.8	27.3435
3021.38	20.4248
3023.96	14.0602
3026.54	8.47161
3029.12	5.01457
3031.69	2.60452
3034.27	0.714012
3036.84	0.772358
3039.42	3.45933
3041.99	4.29951
3044.57	6.4036
3047.14	8.22824
3049.71	9.44051
3052.28	10.5043
3054.85	9.55287
3057.41	10.119
3059.98	9.43662
3062.55	9.90643
3065.11	9.29232
3067.68	8.76433
3070.24	8.49918
3072.8	7.88364
3075.36	6.92364
3077.93	6.15544
3080.49	4.14528
3083.04	3.09993
3085.6	2.26262
3088.16	0.836219
3090.72	1.31918
3093.27	1.90598
3095.83	3.33128
3098.38	6.96984
3100.93	9.79644
3103.49	12.06
3106.04	15.0331
3108.59	19.7521
3111.14	23.4226
3113.69	26.9887
3116.23	30.9281
3118.78	35.732
3121.33	39.7143
3123.87	44.6471
3126.41	50.1927
3128.96	55.6649
3131.5	61.287
3134.04	67.6993
3136.58	74.174
3139.12	78.9993
3141.66	84.3393
3144.2	89.8999
3146.74	95.8249
3149.27	102.474