File: data/Raman/poly_smoothed/Mb_20_23_16_1x_45s_532 nm_x100_100%_600 gr_mm_01.txt
#Acq. time (s)=	45
#Accumulations=	2
#Range (cm-¹)=	200...3150
#Windows=	2
#Auto scanning=	Off
#Autofocus=	Off
#Macrospot=	Off
#AutoExposure=	Off
#Spike filter=	Multiple accum.
#Delay time (s)=	0
#Binning=	1
#Readout mode=	Signal
#DeNoise=	Off
#ICS correction=	On
#Dark correction=	Off
#Inst. Process=	Off
#Detector Gain=	Best Dynamic Range
#Detector ADC=	20 kHz
#Detector temperature (°C)=	-69.85
#Instrument=	LabRAM HR Evol
#Detector=	Synapse
#Objective=	x100
#Grating=	600 gr/mm
#ND Filter=	100%
#Laser (nm)=	532
#Hole=	100.021
#Range=	Auto
#Laser Pol.=	No
#Raman. Pol.=	No
#Laser Pol. (°)=	-0.0007625
#Raman Pol. (°)=	89.9995
#Collection=	Microscope
#StageXY=	Marzhauser
#StageZ=	Marzhauser
#X (µm)=	-6940
#Y (µm)=	2083.4
#Z (µm)=	-75.05
#Full time(mm:ss)=	3:18
#Project=
#Sample=
#Site=
#Title=	Mb_20_23_16_2x_45s_532 nm_x100_100%_600 gr_mm
#Remark=
#Date=	13.07.2022 14:05
#Acquired=	13.07.2022 14:05:31
#Base:Fit=	10.08.2022 10:29:37
#Base:Sub=	10.08.2022 10:32:28
#Filter:Polynom=	16.08.2022 10:13:29
#AxisType[0]=Intens
#AxisUnit[0]=Cnt
#AxisType[1]=Spectr
#AxisUnit[1]=1/cm
200.563	50.3992
204.194	46.9918
207.821	42.0668
211.449	36.7558
215.074	31.8672
218.699	27.1946
222.321	26.2687
225.941	24.8367
229.562	24.6928
233.18	24.675
236.796	22.6459
240.411	21.8051
244.026	20.5224
247.638	18.3223
251.248	16.7973
254.857	15.8639
258.465	15.4328
262.071	14.7603
265.678	13.2607
269.282	13.3809
272.884	10.5229
276.484	9.24415
280.084	8.04125
283.682	7.49736
287.276	5.06814
290.871	4.54719
294.465	2.53881
298.057	3.21704
301.648	4.66884
305.237	7.70042
308.823	10.4667
312.41	12.9085
315.995	15.9021
319.579	18.0057
323.16	18.5578
326.741	16.8235
330.321	18.2307
333.897	18.3877
337.474	18.1414
341.048	18.2728
344.622	16.5853
348.192	14.8475
351.764	12.1737
355.332	8.8084
358.901	8.12115
362.466	5.82049
366.03	4.05661
369.594	3.59209
373.155	2.88951
376.715	2.51907
380.273	1.513
383.832	2.53578
387.388	4.49374
390.942	5.95944
394.495	8.33826
398.047	11.0169
401.597	11.9979
405.145	13.6995
408.693	14.8758
412.239	15.7576
415.783	16.5194
419.327	16.9535
422.869	17.1066
426.409	16.5124
429.948	15.1839
433.486	12.9399
437.022	12.8565
440.558	12.1009
444.089	11.7576
447.622	13.028
451.153	13.1702
454.682	14.062
458.208	14.3475
461.735	13.4798
465.259	14.7389
468.783	16.3693
472.306	19.1753
475.825	19.7326
479.346	22.7102
482.862	25.1449
486.38	26.3566
489.894	27.6034
493.407	30.7153
496.92	30.8752
500.43	32.027
503.939	30.0806
507.448	31.54
510.954	33.1925
514.459	33.7486
517.962	33.8134
521.466	32.3003
524.966	34.4303
528.466	33.3632
531.964	32.7369
535.46	32.7054
538.955	30.2759
542.449	29.6873
545.942	29.1123
549.433	27.906
552.923	26.3121
556.412	24.1158
559.899	23.5908
563.385	22.0841
566.867	20.2582
570.35	18.642
573.832	16.0802
577.313	13.8064
580.79	13.212
584.268	12.142
587.745	11.1989
591.218	11.0066
594.692	9.10763
598.164	7.75613
601.634	6.00716
605.104	5.34196
608.57	5.43259
612.037	6.06127
615.501	5.23211
618.966	7.6096
622.427	8.20854
625.887	10.1915
629.348	13.5937
632.806	16.918
636.262	17.3027
639.716	18.6329
643.172	21.1664
646.624	21.4423
650.075	21.1449
653.524	22.6253
656.972	22.2603
660.419	21.6773
663.865	22.4991
667.309	22.8751
670.752	23.704
674.194	22.8133
677.634	22.3883
681.073	22.348
684.511	24.1165
687.947	24.6229
691.382	25.2751
694.816	25.8437
698.247	26.369
701.678	28.9504
705.108	30.0519
708.534	32.4086
711.962	34.9671
715.388	36.0361
718.81	36.7637
722.234	37.8028
725.654	37.4558
729.075	37.2383
732.492	38.9121
735.91	40.371
739.325	43.1963
742.741	44.3354
746.153	47.0796
749.564	49.7422
752.976	53.7659
756.385	56.7526
759.792	60.3675
763.2	63.5765
766.604	65.58
770.008	66.8067
773.41	66.5958
776.811	69.0447
780.21	70.4357
783.608	73.8667
787.005	75.4732
790.401	77.3267
793.795	79.4477
797.188	80.936
800.58	84.2561
803.971	85.883
807.36	88.0128
810.748	87.4451
814.135	91.1299
817.518	93.6556
820.902	93.9879
824.285	95.3822
827.665	96.238
831.045	93.8919
834.424	93.5431
837.8	92.1856
841.177	90.7714
844.55	87.9936
847.924	85.1444
851.295	82.3425
854.666	78.4868
858.034	76.5217
861.403	75.7601
864.769	72.6504
868.133	69.2477
871.498	69.9183
874.86	70.5845
878.221	69.9693
881.58	70.3438
884.938	70.1481
888.297	69.9563
891.653	69.9216
895.007	71.7106
898.36	71.4102
901.712	73.4417
905.063	74.4858
908.412	75.1484
911.76	75.1018
915.107	74.099
918.452	75.251
921.797	74.7447
925.138	72.9616
928.48	69.99
931.82	71.145
935.16	66.4602
938.496	62.8026
941.833	57.8099
945.168	53.7409
948.5	51.5553
951.834	50.4044
955.163	48.9508
958.494	46.7776
961.821	43.8163
965.15	44.7051
968.474	45.0022
971.8	46.4376
975.123	48.6788
978.446	50.3347
981.766	51.5491
985.084	54.1548
988.402	53.6494
991.72	54.2082
995.035	57.5105
998.349	57.9161
1001.66	58.4723
1004.97	58.7471
1008.28	60.7694
1011.59	62.0133
1014.9	62.1373
1018.21	61.0233
1021.51	60.191
1024.81	60.7637
1028.12	61.237
1031.42	62.6957
1034.72	62.3384
1038.02	61.0189
1041.31	62.8439
1044.61	64.2541
1047.91	66.5605
1051.2	65.7493
1054.49	66.2882
1057.78	64.2533
1061.07	64.0938
1064.36	62.2941
1067.65	61.4447
1070.93	60.735
1074.22	60.3884
1077.5	59.7849
1080.78	58.7176
1084.06	58.1809
1087.34	58.2819
1090.62	58.8529
1093.9	56.9554
1097.17	56.0205
1100.45	56.0588
1103.72	54.4735
1106.99	53.5732
1110.27	51.7769
1113.53	50.0843
1116.8	48.675
1120.07	47.4001
1123.33	46.7966
1126.6	46.3928
1129.86	45.4612
1133.12	42.8913
1136.38	40.0215
1139.64	39.2186
1142.9	36.1523
1146.16	33.7574
1149.41	30.3756
1152.67	25.6347
1155.92	20.9297
1159.17	15.8146
1162.42	12.8526
1165.67	9.06698
1168.92	8.191
1172.16	7.79476
1175.41	6.93374
1178.65	7.94817
1181.9	6.94268
1185.14	8.69075
1188.38	9.7593
1191.62	11.3676
1194.86	14.1599
1198.09	17.5957
1201.33	21.2367
1204.56	26.078
1207.8	29.317
1211.03	35.1934
1214.26	40.6625
1217.49	47.7094
1220.71	54.917
1223.94	59.5347
1227.16	65.6727
1230.39	68.4145
1233.61	72.8458
1236.83	77.4483
1240.05	82.1457
1243.27	85.9451
1246.49	88.3483
1249.71	91.2886
1252.92	95.5023
1256.14	96.2409
1259.35	97.67
1262.56	100.152
1265.77	102.326
1268.98	105.599
1272.19	110.161
1275.4	112.933
1278.6	115.533
1281.81	119.206
1285.01	121.88
1288.21	126.701
1291.41	132.328
1294.61	136.257
1297.81	140.222
1301.01	141.536
1304.2	143.811
1307.4	145.385
1310.59	146.353
1313.78	148.632
1316.97	148.3
1320.16	145.416
1323.35	142.595
1326.54	140.63
1329.72	137.225
1332.91	132.95
1336.09	129.267
1339.27	125.283
1342.45	120.599
1345.64	117.412
1348.81	115.405
1351.99	112.164
1355.17	107.573
1358.34	103.601
1361.51	98.9078
1364.69	95.7014
1367.86	93.0503
1371.03	90.1019
1374.2	86.83
1377.37	85.5765
1380.53	85.1311
1383.7	85.593
1386.86	85.3128
1390.02	86.6642
1393.19	84.8107
1396.35	84.4215
1399.51	84.1744
1402.66	86.0782
1405.82	88.149
1408.97	94.3633
1412.13	99.3377
1415.28	105.973
1418.43	116.141
1421.59	128.196
1424.73	138.937
1427.88	151.795
1431.03	162.681
1434.18	171.808
1437.32	179.758
1440.46	185.538
1443.61	189.957
1446.75	191.492
1449.89	192.709
1453.03	191.569
1456.16	186.913
1459.3	179.874
1462.44	170.22
1465.57	159.476
1468.7	146.498
1471.83	132.906
1474.96	121.194
1478.09	106.433
1481.22	94.1613
1484.35	82.2837
1487.47	72.7389
1490.6	63.185
1493.72	56.3729
1496.84	50.408
1499.96	44.6091
1503.08	39.856
1506.2	35.8239
1509.32	30.9116
1512.44	28.4415
1515.55	24.1873
1518.66	21.7024
1521.78	18.684
1524.89	19.7257
1528	20.4508
1531.11	19.9374
1534.21	22.2737
1537.32	25.3217
1540.43	28.2133
1543.53	31.6495
1546.63	33.418
1549.74	36.48
1552.84	39.6229
1555.94	41.1809
1559.03	44.0675
1562.13	47.4239
1565.23	50.8423
1568.32	55.4812
1571.42	59.425
1574.51	62.8078
1577.6	65.7187
1580.69	70.9233
1583.78	72.9122
1586.87	75.8617
1589.95	78.8221
1593.04	78.9388
1596.12	80.4879
1599.21	82.3287
1602.29	83.6653
1605.37	83.0226
1608.45	84.7237
1611.53	86.8938
1614.6	87.4695
1617.68	88.2373
1620.75	88.0369
1623.83	91.0997
1626.9	95.4542
1629.97	98.2409
1633.04	103.255
1636.11	107.897
1639.18	113.94
1642.25	121.898
1645.31	127.059
1648.38	130.972
1651.44	134.453
1654.5	138.287
1657.56	139.209
1660.62	137.813
1663.68	136.084
1666.74	132.45
1669.8	125.475
1672.85	119.314
1675.91	110.634
1678.96	101.585
1682.01	92.6344
1685.06	83.4385
1688.11	73.6881
1691.16	63.4821
1694.21	55.6317
1697.25	47.5165
1700.3	41.9648
1703.34	36.2985
1706.39	30.647
1709.43	27.8098
1712.47	25.0872
1715.51	22.5217
1718.54	21.0595
1721.58	18.3497
1724.62	16.7172
1727.65	16.7631
1730.68	16.0418
1733.72	14.2571
1736.75	13.4421
1739.78	12.4362
1742.81	11.682
1745.84	11.3551
1748.86	10.1681
1751.89	9.4824
1754.91	8.4488
1757.93	6.62771
1760.96	6.62451
1763.98	4.86873
1767	4.90026
1770.02	2.87196
1773.03	2.83075
1776.05	3.17122
1779.07	2.99743
1782.08	3.07575
1785.09	3.07607
1788.11	3.27076
1791.12	2.41524
1794.13	2.9626
1797.13	2.94907
1800.14	3.16862
1803.15	2.79121
1806.15	2.88999
1809.16	2.51423
1812.16	1.83759
1815.16	1.95203
1818.16	0.684768
1821.16	0.037485
1824.16	-0.427423
1827.16	-0.146304
1830.16	-0.489441
1833.15	-0.490517
1836.14	-0.0535261
1839.14	0.061666
1842.13	0.928071
1845.12	1.63948
1848.11	2.61868
1851.1	3.55368
1854.08	3.51431
1857.07	5.02691
1860.05	5.6938
1863.04	7.36101
1866.02	7.74731
1869	9.29516
1871.98	8.11698
1874.96	8.08306
1877.94	7.41918
1880.92	7.36528
1882.51	7.03071
1885.5	7.0307
1888.48	5.15463
1891.47	4.52789
1894.46	3.51691
1897.44	3.85481
1900.42	1.94561
1903.41	1.52373
1906.39	1.97533
1909.37	2.79398
1912.35	2.04149
1915.32	3.42609
1918.3	3.16683
1921.27	4.51395
1924.25	6.11535
1927.22	6.49259
1930.19	7.03948
1933.17	7.05706
1936.14	6.90559
1939.11	6.43051
1942.07	5.88957
1945.04	5.46362
1948.01	5.03081
1950.97	4.41954
1953.93	3.90987
1956.9	3.21811
1959.86	3.49301
1962.82	2.49081
1965.78	1.97811
1968.74	1.58206
1971.69	1.59027
1974.65	1.55527
1977.6	2.96306
1980.56	3.56657
1983.51	4.68033
1986.46	5.51047
1989.41	7.21349
1992.36	7.4647
1995.31	8.37973
1998.26	8.92118
2001.2	9.67329
2004.15	9.61159
2007.09	9.3763
2010.04	9.16031
2012.98	9.93918
2015.92	9.18488
2018.86	9.631
2021.8	10.1775
2024.73	10.6502
2027.67	11.4626
2030.61	12.3738
2033.54	11.5898
2036.47	11.4686
2039.4	12.7033
2042.33	14.0682
2045.27	15.5094
2048.19	16.0583
2051.12	15.6709
2054.05	16.8191
2056.97	18.2911
2059.9	18.7695
2062.82	18.9865
2065.74	19.2368
2068.67	18.9578
2071.59	19.5459
2074.51	19.5165
2077.42	18.8199
2080.34	18.7112
2083.26	20.3444
2086.17	21.6324
2089.09	22.9266
2092	23.8224
2094.91	24.5523
2097.82	25.8865
2100.73	27.0246
2103.64	27.6825
2106.55	30.1005
2109.45	32.7179
2112.36	34.1353
2115.26	35.742
2118.17	36.0507
2121.07	38.1091
2123.97	40.7949
2126.87	42.8289
2129.77	45.245
2132.67	47.5677
2135.56	49.201
2138.46	53.0128
2141.35	56.3369
2144.25	59.6142
2147.14	63.4221
2150.03	69.1678
2152.92	74.9072
2155.81	79.3303
2158.7	83.1091
2161.59	86.2606
2164.47	89.3197
2167.36	92.54
2170.24	95.5616
2173.13	97.8861
2176.01	99.5979
2178.89	100.259
2181.77	98.1586
2184.65	95.4137
2187.53	92.7044
2190.4	89.0045
2193.28	84.9965
2196.16	80.5531
2199.03	75.9025
2201.9	71.2046
2204.77	67.0752
2207.64	62.4712
2210.51	57.9208
2213.38	55.6172
2216.25	51.3967
2219.12	49.3141
2221.98	45.5286
2224.85	40.9935
2227.71	37.8027
2230.57	34.7127
2233.43	33.1949
2236.29	31.7224
2239.15	31.6171
2242.01	30.9839
2244.87	29.1405
2247.72	28.6317
2250.58	26.8689
2253.43	25.0677
2256.29	23.1058
2259.14	21.7832
2261.99	20.7801
2264.84	20.3243
2267.69	18.4538
2270.53	18.0749
2273.38	17.1813
2276.23	15.5208
2279.07	13.905
2281.91	12.4646
2284.76	11.5091
2287.6	9.17447
2290.44	8.54082
2293.28	6.53039
2296.12	6.58522
2298.96	7.17772
2301.79	7.51006
2304.63	8.80501
2307.46	9.38782
2310.3	9.91947
2313.13	10.3296
2315.96	11.3558
2318.79	11.2212
2321.62	10.327
2324.45	10.248
2327.27	10.6119
2330.1	11.461
2332.92	11.775
2335.75	10.9418
2338.57	11.1273
2341.39	10.7607
2344.21	10.1459
2347.04	10.4111
2349.85	9.95862
2352.67	10.0013
2355.49	9.10012
2358.3	7.24448
2361.12	6.43091
2363.93	7.27445
2366.75	6.70284
2369.56	5.13141
2372.37	4.64921
2375.18	3.65356
2377.99	2.70218
2380.8	1.81986
2383.6	0.963031
2386.41	1.36591
2389.21	0.902147
2392.02	1.22386
2394.82	0.804709
2397.62	1.91826
2400.42	2.7593
2403.22	2.9517
2406.02	2.77667
2408.82	3.62125
2411.62	4.13612
2414.41	5.11188
2417.21	6.34063
2420	5.84626
2422.79	5.51413
2425.59	5.00335
2428.38	5.83995
2431.17	5.94188
2433.95	4.60728
2436.74	4.12863
2439.53	3.57324
2442.31	5.21448
2445.1	4.34956
2447.88	3.80589
2450.67	4.05456
2453.45	4.27677
2456.23	5.12208
2459.01	3.79159
2461.79	3.11582
2464.57	2.52368
2467.34	2.8535
2470.12	1.87545
2472.89	0.578282
2475.67	0.622878
2478.44	0.339217
2481.21	0.162658
2483.98	1.0404
2486.75	1.49543
2489.52	0.916693
2492.29	1.53763
2495.05	2.399
2497.82	1.47156
2500.58	1.01558
2503.35	-0.154254
2506.11	-0.7735
2508.87	-0.265394
2511.63	-0.183629
2514.39	-0.0318143
2517.15	0.145419
2519.91	0.406938
2522.67	1.03742
2525.42	0.249992
2528.18	-0.0696652
2530.93	1.25999
2533.69	1.40887
2536.44	0.578155
2539.19	1.27285
2541.94	2.12673
2544.69	2.73484
2547.44	4.26233
2550.18	4.65197
2552.93	5.11188
2555.67	5.64067
2558.42	6.3933
2561.16	7.58212
2563.9	7.17103
2566.64	7.03555
2569.38	6.22739
2572.12	6.46947
2574.86	6.16238
2577.6	7.79359
2580.33	8.53767
2583.07	8.65658
2585.8	6.79385
2588.54	6.8346
2591.27	6.70012
2594	5.92428
2596.73	5.49718
2599.46	4.99213
2602.19	4.17084
2604.92	4.64546
2607.64	4.02136
2610.37	3.70157
2613.09	2.96306
2615.82	3.39788
2618.54	3.02357
2621.26	4.62025
2623.98	4.95373
2626.7	5.73155
2629.42	5.7455
2632.14	4.92545
2634.86	6.00343
2637.57	6.33039
2640.29	7.76063
2643	7.91669
2645.71	8.38922
2648.43	8.31603
2651.14	8.10676
2653.85	6.9985
2656.56	7.42129
2659.26	7.8912
2661.97	8.31641
2664.68	8.60537
2667.38	8.42785
2670.09	7.99451
2672.79	8.04958
2675.49	8.76587
2678.19	9.37589
2680.89	11.8952
2683.59	12.7634
2686.29	12.2578
2688.99	12.224
2691.69	12.0297
2694.38	12.0077
2697.08	13.4279
2699.77	15.2486
2702.46	16.2984
2705.15	16.4181
2707.85	17.3626
2710.54	17.6581
2713.22	17.6835
2715.91	18.911
2718.6	19.1671
2721.29	20.1591
2723.97	20.7309
2726.66	20.4684
2729.34	19.6378
2732.02	18.8514
2734.7	17.9692
2737.38	16.8874
2740.06	17.6805
2742.74	15.8614
2745.42	14.9739
2748.09	13.8196
2750.77	11.947
2753.45	9.67588
2756.12	8.9167
2758.79	9.0145
2761.46	8.21213
2764.14	7.47673
2766.8	6.39565
2769.47	6.15681
2772.14	5.43797
2774.81	4.77482
2777.48	2.97337
2780.14	2.96619
2782.8	2.47942
2785.47	2.13166
2788.13	1.53565
2790.79	0.981006
2793.45	0.0276306
2796.11	0.790362
2798.77	0.93238
2801.43	1.25591
2804.09	1.47354
2806.74	0.921274
2809.4	1.36362
2812.05	1.47111
2814.71	2.41159
2817.36	5.04621
2820.01	11.2105
2822.66	19.571
2825.31	28.0548
2827.96	37.6747
2830.6	49.1016
2833.25	63.1254
2835.9	77.0852
2838.54	89.742
2841.18	105.317
2843.83	123.195
2846.47	142.35
2849.11	161.948
2851.75	183.213
2854.39	203.383
2857.03	223.74
2859.66	244.252
2862.3	261.984
2864.94	277.99
2867.57	292.111
2870.2	304.086
2872.84	315.322
2875.47	325.306
2878.1	334.749
2880.73	343.753
2883.36	353.036
2885.99	363.081
2888.61	371.206
2891.24	379.53
2893.86	388.787
2896.49	399.589
2899.11	410.319
2901.73	421.54
2904.36	436.139
2906.98	453.536
2909.6	472.762
2912.21	493.374
2914.83	513.838
2917.45	533.262
2920.07	549.951
2922.68	565.943
2925.29	575.598
2927.91	583.1
2930.52	585.747
2933.13	582.782
2935.74	577.723
2938.35	567.645
2940.96	554.368
2943.57	537.947
2946.18	519.286
2948.78	499.394
2951.39	477.263
2953.99	452.33
2956.59	429.538
2959.2	406.567
2961.8	384.301
2964.4	361.629
2967	340.594
2969.6	320.993
2972.19	303.377
2974.79	286.284
2977.39	268.637
2979.98	251.72
2982.58	233.74
2985.17	214.97
2987.76	194.856
2990.35	176.1
2992.94	157.469
2995.53	138.9
2998.12	121.347
3000.71	106.114
3003.3	90.7059
3005.88	77.0031
3008.47	63.8226
3011.05	52.8443
3013.64	43.0333
3016.22	34.737
3018.8	27.9555
3021.38	23.5478
3023.96	19.8692
3026.54	16.5472
3029.12	14.4501
3031.69	13.9366
3034.27	14.0868
3036.84	15.6286
3039.42	16.1669
3041.99	18.0155
3044.57	18.8583
3047.14	19.6598
3049.71	20.1209
3052.28	21.0026
3054.85	21.1676
3057.41	21.4772
3059.98	21.1652
3062.55	20.1889
3065.11	19.8796
3067.68	16.8738
3070.24	13.7994
3072.8	11.8078
3075.36	9.44168
3077.93	7.5324
3080.49	5.29121
3083.04	3.67952
3085.6	2.79864
3088.16	2.27019
3090.72	1.26035
3093.27	1.922
3095.83	3.24339
3098.38	3.851
3100.93	4.66337
3103.49	6.80979
3106.04	9.29418
3108.59	10.8856
3111.14	12.9301
3113.69	14.6648
3116.23	16.4129
3118.78	18.8454
3121.33	20.8756
3123.87	23.1819
3126.41	25.3669
3128.96	26.5988
3131.5	27.5549
3134.04	29.8824
3136.58	32.291
3139.12	33.2988
3141.66	35.2848
3144.2	37.4899
3146.74	40.534
3149.27	43.7543