File: data/Raman/poly_smoothed/Mb_20_23_43_45s_532 nm_x100_100%_600 gr_mm_01.txt
#Acq. time (s)=	45
#Accumulations=	2
#Range (cm-¹)=	200...3150
#Windows=	2
#Auto scanning=	Off
#Autofocus=	Off
#Macrospot=	Off
#AutoExposure=	Off
#Spike filter=	Multiple accum.
#Delay time (s)=	0
#Binning=	1
#Readout mode=	Signal
#DeNoise=	Off
#ICS correction=	On
#Dark correction=	Off
#Inst. Process=	Off
#Detector Gain=	Best Dynamic Range
#Detector ADC=	20 kHz
#Detector temperature (°C)=	-69.85
#Instrument=	LabRAM HR Evol
#Detector=	Synapse
#Objective=	x100
#Grating=	600 gr/mm
#ND Filter=	100%
#Laser (nm)=	532
#Hole=	100.021
#Range=	Auto
#Laser Pol.=	No
#Raman. Pol.=	No
#Laser Pol. (°)=	-0.0007625
#Raman Pol. (°)=	89.9995
#Collection=	Microscope
#StageXY=	Marzhauser
#StageZ=	Marzhauser
#X (µm)=	467.6
#Y (µm)=	3006.5
#Z (µm)=	-9.35
#Full time(mm:ss)=	3:18
#Project=
#Sample=
#Site=
#Title=	Mb_20_23_43_45s_532 nm_x100_100%_600 gr_mm
#Remark=
#Date=	14.07.2022 09:37
#Acquired=	14.07.2022 09:37:09
#Base:Fit=	10.08.2022 10:29:37
#Base:Sub=	10.08.2022 10:35:48
#Filter:Polynom=	16.08.2022 10:13:29
#AxisType[0]=Intens
#AxisUnit[0]=Cnt
#AxisType[1]=Spectr
#AxisUnit[1]=1/cm
200.554	68.9573
204.183	67.1485
207.813	63.5657
211.439	59.6227
215.065	55.0954
218.688	50.8034
222.312	44.3595
225.933	40.7949
229.552	36.3322
233.171	35.3084
236.787	34.0197
240.402	29.7422
244.015	29.1239
247.627	28.3392
251.24	26.8757
254.849	25.5332
258.457	24.9933
262.063	22.5352
265.668	21.3248
269.271	19.2154
272.873	17.7737
276.474	15.8278
280.073	13.8108
283.671	11.7314
287.268	9.65552
290.863	9.87537
294.456	9.18858
298.049	7.70879
301.637	7.57734
305.227	7.66261
308.815	6.87423
312.402	7.73851
315.987	8.11448
319.569	8.88985
323.151	9.33299
326.733	9.73385
330.31	9.13185
333.889	12.7265
337.464	12.3928
341.039	12.8475
344.611	12.4541
348.184	9.35606
351.754	9.21737
355.324	6.90748
358.89	6.60627
362.455	6.54248
366.021	3.17807
369.584	3.06878
373.145	1.50006
376.707	1.87778
380.265	2.47861
383.822	2.94796
387.378	4.45331
390.934	5.22601
394.487	5.42681
398.038	5.70686
401.588	7.28355
405.137	7.7758
408.685	9.75378
412.23	9.14537
415.775	11.559
419.318	11.6992
422.86	10.8219
426.401	10.8028
429.94	11.1361
433.478	7.2668
437.012	7.7749
440.547	6.95489
444.081	8.07574
447.613	6.08466
451.142	4.67729
454.672	1.89586
458.2	1.07281
461.725	0.265961
465.251	2.71786
468.775	3.52498
472.296	5.2648
475.817	5.70481
479.335	6.09655
482.854	8.80333
486.37	10.3101
489.886	10.3126
493.398	12.4951
496.91	12.8208
500.422	13.7819
503.93	12.5641
507.438	14.0826
510.946	14.6728
514.45	16.7672
517.954	15.7956
521.456	15.7046
524.956	14.97
528.456	15.8038
531.956	14.0958
535.452	13.2332
538.947	11.5559
542.441	9.95987
545.934	11.8543
549.425	12.4642
552.915	13.3318
556.403	10.8597
559.889	10.6753
563.375	9.93683
566.859	10.2926
570.342	9.55146
573.824	8.17339
577.303	6.51307
580.782	5.38518
584.26	3.69136
587.734	4.55197
591.21	3.46315
594.684	3.49135
598.154	3.75422
601.626	3.0126
605.094	3.21241
608.562	4.63192
612.027	4.87569
615.493	3.23811
618.956	2.56087
622.419	2.05544
625.879	1.631
629.338	6.26595
632.797	7.36938
636.254	7.21048
639.708	8.70851
643.162	8.61987
646.614	11.1942
650.067	11.8269
653.516	12.3049
656.964	14.2196
660.411	14.23
663.857	16.0743
667.301	16.5826
670.744	19.4878
674.186	19.3499
677.626	21.5123
681.065	23.0361
684.503	24.006
687.939	23.7699
691.372	23.0062
694.806	23.4649
698.239	23.3189
701.67	22.3059
705.098	23.155
708.526	23.7562
711.954	24.9017
715.378	24.5888
718.802	24.0193
722.226	24.762
725.646	25.2672
729.067	26.3588
732.484	29.673
735.902	30.7042
739.317	33.1718
742.731	36.1962
746.145	39.4931
749.556	43.848
752.966	47.945
756.377	51.3856
759.784	53.6909
763.19	56.5748
766.594	58.707
770	59.9251
773.402	63.0403
776.803	66.1505
780.202	69.0897
783.6	70.5903
786.997	70.0272
790.393	70.4336
793.787	71.0494
797.18	72.0608
800.572	71.6557
803.963	72.6536
807.35	74.22
810.738	75.2338
814.125	74.9187
817.51	72.1595
820.894	74.4436
824.275	75.2099
827.657	75.8541
831.037	75.4722
834.414	76.2111
837.792	74.8504
841.167	72.8154
844.542	72.9665
847.914	70.498
851.287	70.0828
854.656	71.1248
858.026	71.3288
861.393	69.691
864.761	70.1502
868.125	68.1298
871.489	69.2223
874.85	69.9896
878.213	68.837
881.572	69.2565
884.931	70.3508
888.287	69.6477
891.643	69.5962
894.997	67.5771
898.352	67.2016
901.704	66.552
905.055	65.8153
908.404	64.2864
911.75	63.2678
915.097	63.9022
918.443	64.1674
921.787	60.654
925.13	59.0751
928.472	56.485
931.813	53.8157
935.15	52.2679
938.488	50.0312
941.825	48.5063
945.158	48.1123
948.493	47.9159
951.824	47.1231
955.156	45.6059
958.486	43.9198
961.814	41.6954
965.142	39.1995
968.467	39.4983
971.79	38.246
975.115	39.011
978.436	38.8564
981.756	37.5911
985.077	38.333
988.394	37.0811
991.71	36.637
995.025	36.0221
998.341	35.409
1001.65	32.1455
1004.97	30.4531
1008.28	29.4326
1011.58	29.7183
1014.89	29.1532
1018.2	29.1894
1021.5	31.6595
1024.81	33.4416
1028.11	34.1883
1031.41	36.8574
1034.71	37.3485
1038.01	35.5254
1041.31	36.7889
1044.6	37.7306
1047.9	42.1114
1051.19	45.0884
1054.48	46.9566
1057.77	46.4653
1061.06	44.3234
1064.35	42.7803
1067.64	40.7324
1070.93	38.9848
1074.21	37.3122
1077.49	35.7624
1080.78	33.4607
1084.06	32.0047
1087.34	31.0807
1090.61	30.0438
1093.89	29.6041
1097.17	28.9052
1100.44	29.3393
1103.71	30.525
1106.99	29.3797
1110.26	29.9877
1113.52	27.5671
1116.79	26.6565
1120.06	25.4592
1123.32	24.5706
1126.59	24.0664
1129.85	21.5226
1133.11	19.6025
1136.37	17.9649
1139.63	17.1563
1142.89	15.8546
1146.15	16.0587
1149.4	14.5781
1152.66	12.6771
1155.91	10.1534
1159.16	8.02453
1162.41	7.82855
1165.66	6.78537
1168.91	5.8098
1172.16	6.32302
1175.4	7.06417
1178.65	7.86351
1181.89	10.1352
1185.13	8.82183
1188.37	7.74945
1191.61	6.84741
1194.85	8.03725
1198.08	9.42842
1201.32	7.68525
1204.55	9.26724
1207.79	11.1986
1211.02	13.0753
1214.25	15.4092
1217.48	16.3304
1220.71	17.7081
1223.93	18.8994
1227.16	21.2681
1230.38	24.0519
1233.6	25.6188
1236.83	28.0868
1240.05	29.7031
1243.26	31.1472
1246.48	32.1941
1249.7	35.6269
1252.92	36.8774
1256.13	36.5814
1259.34	38.622
1262.55	41.3386
1265.76	43.2674
1268.97	47.5931
1272.18	50.2871
1275.39	56.0416
1278.59	58.9904
1281.8	62.096
1285	65.2239
1288.2	68.0346
1291.4	70.195
1294.6	71.5476
1297.8	73.4804
1301	76.4488
1304.19	78.1875
1307.39	79.4299
1310.58	80.3737
1313.77	81.097
1316.96	79.0901
1320.15	76.3575
1323.34	73.8755
1326.53	72.117
1329.72	68.4894
1332.9	64.5711
1336.08	62.8764
1339.27	61.8712
1342.45	60.3744
1345.63	60.7783
1348.8	59.4526
1351.98	59.4473
1355.16	59.2988
1358.33	58.2471
1361.51	58.1743
1364.68	58.0839
1367.85	58.87
1371.02	58.3614
1374.19	59.5887
1377.36	59.5609
1380.52	59.0452
1383.69	59.6524
1386.85	60.9467
1390.02	61.588
1393.18	59.883
1396.34	58.0796
1399.5	57.3354
1402.65	56.9076
1405.81	58.4388
1408.97	59.757
1412.12	62.6907
1415.27	68.1993
1418.43	72.73
1421.58	79.1101
1424.73	84.0045
1427.87	91.045
1431.02	97.9261
1434.17	105.422
1437.31	113.043
1440.46	117.708
1443.6	120.004
1446.74	121.094
1449.88	122.016
1453.02	120.184
1456.16	114.965
1459.29	110.795
1462.43	104.538
1465.56	97.8106
1468.69	89.9115
1471.83	79.3244
1474.95	70.5169
1478.08	61.1863
1481.21	54.2596
1484.34	46.3395
1487.47	38.1856
1490.59	32.2776
1493.71	27.1532
1496.84	22.3269
1499.96	19.2186
1503.07	16.5437
1506.19	17.158
1509.31	16.9701
1512.43	17.1467
1515.54	15.9499
1518.65	15.6095
1521.77	16.1364
1524.88	17.6134
1527.99	17.7449
1531.1	18.3921
1534.21	19.759
1537.31	19.9414
1540.42	22.2442
1543.52	23.6809
1546.63	24.1363
1549.73	24.3375
1552.83	24.9751
1555.93	26.2024
1559.03	27.2713
1562.12	27.1128
1565.22	28.1979
1568.31	30.3309
1571.41	33.8278
1574.5	37.5328
1577.59	41.8972
1580.68	46.0406
1583.77	47.9284
1586.86	50.0969
1589.95	52.797
1593.03	55.3602
1596.11	56.664
1599.2	58.2372
1602.28	57.4206
1605.36	56.5819
1608.44	57.5024
1611.52	55.1028
1614.6	55.0319
1617.67	52.7701
1620.75	50.651
1623.82	49.9368
1626.89	49.1421
1629.96	47.3977
1633.04	48.2485
1636.11	48.299
1639.17	47.4069
1642.24	47.8425
1645.31	48.8329
1648.37	48.2621
1651.43	49.0506
1654.5	47.5436
1657.56	46.1504
1660.62	43.0781
1663.67	41.8977
1666.73	39.1527
1669.79	36.2893
1672.84	34.2534
1675.9	32.7953
1678.95	28.1015
1682	24.6185
1685.05	21.2163
1688.1	20.1171
1691.15	16.4475
1694.2	12.0144
1697.25	10.8537
1700.29	9.41218
1703.33	6.3133
1706.38	5.61352
1709.42	5.04388
1712.46	4.62422
1715.5	3.90426
1718.54	3.88979
1721.57	5.13753
1724.61	5.53513
1727.64	7.02215
1730.68	6.75652
1733.71	6.54224
1736.74	5.97422
1739.77	6.53898
1742.8	6.35396
1745.83	6.54967
1748.85	7.02764
1751.88	4.86007
1754.91	4.89906
1757.93	4.72708
1760.95	5.25249
1763.97	5.2414
1766.99	3.36051
1770.01	2.58062
1773.03	4.58735
1776.04	5.62749
1779.06	6.34873
1782.07	7.3876
1785.09	8.98884
1788.1	10.5357
1791.11	12.0053
1794.12	11.6476
1797.13	12.954
1800.13	11.487
1803.14	12.2366
1806.15	11.8447
1809.15	12.0617
1812.15	11.591
1815.16	11.0859
1818.15	11.6387
1821.16	11.6749
1824.15	12.7955
1827.15	12.6261
1830.15	13.9607
1833.14	14.2194
1836.14	13.6939
1839.13	14.5135
1842.12	16.2045
1845.11	16.2362
1848.1	17.9384
1851.09	18.0135
1854.08	20.3201
1857.06	22.0798
1860.05	22.217
1863.03	20.3322
1866.01	17.8182
1869	16.7005
1871.98	16.1844
1874.96	15.9207
1877.93	15.3142
1880.91	14.176
1882.47	13.2929
1885.46	13.2778
1888.44	14.5705
1891.43	14.5653
1894.42	14.8149
1897.4	15.3664
1900.39	15.6359
1903.37	15.9275
1906.35	17.7414
1909.33	18.9146
1912.31	19.4259
1915.29	18.8869
1918.26	18.7682
1921.24	18.7741
1924.21	19.0273
1927.19	19.6073
1930.16	16.6718
1933.13	14.1065
1936.1	12.1609
1939.07	12.4599
1942.04	10.7338
1945	10.2498
1947.97	9.30594
1950.93	9.17899
1953.9	8.58733
1956.86	10.105
1959.82	8.35133
1962.78	10.0965
1965.74	9.45311
1968.7	11.9863
1971.65	12.591
1974.61	13.6946
1977.57	15.905
1980.52	16.7835
1983.47	15.716
1986.42	16.1302
1989.37	17.9575
1992.32	17.3398
1995.27	16.6108
1998.22	18.2157
2001.17	20.0829
2004.11	21.0988
2007.05	21.5499
2010	22.1047
2012.94	23.0082
2015.88	23.1998
2018.82	23.8865
2021.76	24.2917
2024.7	23.711
2027.63	24.668
2030.57	24.509
2033.5	24.4228
2036.44	24.3301
2039.37	25.1605
2042.3	24.5659
2045.23	25.5696
2048.16	28.0053
2051.08	28.5935
2054.01	28.5689
2056.94	28.8204
2059.86	28.6474
2062.79	27.7056
2065.71	27.41
2068.63	29.1202
2071.55	29.1249
2074.47	29.9844
2077.39	29.3321
2080.31	29.5115
2083.22	29.7037
2086.13	28.9751
2089.05	28.7468
2091.96	27.621
2094.87	28.0477
2097.78	29.1583
2100.69	29.2308
2103.6	28.0275
2106.51	27.9074
2109.42	30.1011
2112.32	30.0626
2115.23	30.9659
2118.13	32.894
2121.03	34.3711
2123.93	35.527
2126.83	36.3126
2129.73	37.965
2132.63	39.1548
2135.53	39.6361
2138.42	41.8737
2141.32	43.118
2144.21	45.1003
2147.1	45.7815
2150	47.7011
2152.89	49.6927
2155.78	51.385
2158.66	54.2375
2161.55	57.4139
2164.44	60.0983
2167.32	62.8089
2170.21	64.576
2173.09	65.1449
2175.97	65.4945
2178.85	65.8863
2181.73	65.3619
2184.61	64.269
2187.49	63.3582
2190.37	62.2961
2193.24	60.4086
2196.12	60.4919
2198.99	57.7731
2201.87	54.9857
2204.74	51.0248
2207.61	49.4563
2210.48	48.3309
2213.35	46.2509
2216.21	42.9295
2219.08	41.1612
2221.95	40.7259
2224.81	40.4182
2227.67	40.536
2230.54	41.8265
2233.4	41.8891
2236.26	41.3046
2239.11	40.9626
2241.97	40.5158
2244.83	39.8338
2247.69	38.9097
2250.54	38.5236
2253.4	38.1243
2256.25	37.548
2259.1	37.8093
2261.95	37.1211
2264.8	38.7157
2267.65	35.8859
2270.5	33.9326
2273.34	31.7815
2276.19	30.6856
2279.03	30.0972
2281.88	27.29
2284.72	26.3398
2287.56	25.0362
2290.4	22.0621
2293.24	22.1493
2296.08	22.8088
2298.92	22.754
2301.76	22.5822
2304.59	23.4686
2307.43	23.1691
2310.26	23.2277
2313.09	23.9917
2315.92	24.7528
2318.75	25.6174
2321.58	26.3468
2324.41	26.9384
2327.24	27.506
2330.06	27.8109
2332.89	27.7181
2335.71	25.5654
2338.54	23.5067
2341.36	23.8131
2344.18	21.7171
2347	22.0175
2349.82	19.1476
2352.64	18.66
2355.45	17.4636
2358.27	17.7648
2361.08	17.7329
2363.9	19.1038
2366.71	19.3912
2369.52	17.7512
2372.33	14.7659
2375.14	14.514
2377.95	12.5974
2380.76	10.7651
2383.57	9.03254
2386.37	7.86618
2389.18	8.98658
2391.98	7.31195
2394.79	5.91669
2397.59	5.40192
2400.39	5.21958
2403.19	4.6295
2405.99	5.31715
2408.78	6.77936
2411.58	8.28661
2414.38	9.31042
2417.17	10.6009
2419.97	12.3396
2422.76	12.7622
2425.55	15.7258
2428.34	16.5122
2431.13	18.2395
2433.92	17.9738
2436.71	16.3447
2439.49	14.3082
2442.28	11.8134
2445.06	14.0673
2447.85	14.5249
2450.63	15.4844
2453.41	16.7327
2456.19	15.6458
2458.97	14.596
2461.75	12.6288
2464.53	12.4043
2467.31	13.8083
2470.08	13.8081
2472.86	13.3325
2475.63	13.9272
2478.4	12.9955
2481.17	13.0935
2483.94	11.6977
2486.72	10.7547
2489.48	9.91444
2492.25	9.14581
2495.02	8.59617
2497.79	6.88687
2500.55	6.30475
2503.31	3.0993
2506.08	3.67993
2508.84	2.94535
2511.6	4.21058
2514.36	5.22256
2517.12	5.81005
2519.88	4.85642
2522.63	6.59158
2525.39	4.64497
2528.14	5.07652
2530.9	3.47399
2533.65	3.9807
2536.4	4.89032
2539.15	4.30253
2541.9	4.45619
2544.65	6.4158
2547.4	6.70627
2550.15	6.67862
2552.89	7.52051
2555.64	7.08162
2558.38	6.20822
2561.12	4.94295
2563.87	4.86216
2566.61	3.34628
2569.35	2.47833
2572.09	2.95848
2574.83	3.52263
2577.56	4.48341
2580.3	6.10117
2583.04	6.51925
2585.77	4.1297
2588.5	4.63242
2591.23	4.36412
2593.97	3.99796
2596.7	4.46586
2599.43	5.86765
2602.15	6.25765
2604.88	7.27266
2607.61	7.17182
2610.33	7.9375
2613.06	8.76943
2615.78	8.44422
2618.51	8.84565
2621.23	9.02382
2623.95	8.38153
2626.67	7.0088
2629.39	5.80046
2632.1	6.53322
2634.82	6.41656
2637.54	6.39205
2640.25	8.32507
2642.97	9.04694
2645.68	10.4543
2648.39	10.8321
2651.1	9.56944
2653.81	8.40228
2656.52	10.8507
2659.23	10.7586
2661.94	12.6106
2664.64	13.7284
2667.35	14.8076
2670.05	14.8931
2672.76	15.2161
2675.46	14.1853
2678.16	13.1456
2680.86	15.2999
2683.56	15.9297
2686.26	14.4443
2688.96	13.7202
2691.65	11.9941
2694.35	10.7641
2697.04	11.0871
2699.74	11.681
2702.43	13.0811
2705.12	13.1208
2707.81	15.3053
2710.5	15.3517
2713.19	16.8133
2715.88	16.5701
2718.57	15.4455
2721.25	16.7034
2723.94	19.0508
2726.62	19.6992
2729.3	20.1093
2731.99	19.6596
2734.67	20.5273
2737.35	18.9147
2740.03	17.2407
2742.71	16.0808
2745.38	15.5613
2748.06	16.3954
2750.74	12.9836
2753.41	11.8495
2756.09	11.1213
2758.76	9.65005
2761.43	8.21487
2764.1	8.12639
2766.77	7.57124
2769.44	5.26069
2772.11	4.03036
2774.77	3.15026
2777.44	2.71657
2780.11	1.74917
2782.77	-0.546826
2785.43	-0.284326
2788.1	1.5324
2790.76	0.506921
2793.42	2.10388
2796.08	4.47139
2798.74	3.43385
2801.4	3.95894
2804.05	4.33987
2806.71	5.90486
2809.36	5.04541
2812.02	5.64633
2814.67	6.73866
2817.32	9.98893
2819.97	14.1543
2822.62	19.9948
2825.27	28.4913
2827.92	38.3008
2830.57	48.083
2833.22	57.2858
2835.86	66.8302
2838.51	77.8762
2841.15	91.4194
2843.79	104.906
2846.43	116.193
2849.08	129.16
2851.72	142.474
2854.36	157.963
2856.99	169.692
2859.63	181.903
2862.27	192.241
2864.9	202.151
2867.54	210.354
2870.17	217.79
2872.8	221.637
2875.43	225.371
2878.07	230.732
2880.7	236.544
2883.32	241.736
2885.95	247.376
2888.58	254.332
2891.21	258.594
2893.83	264.207
2896.46	268.628
2899.08	273.421
2901.7	279.255
2904.32	285.605
2906.94	292.207
2909.56	301.307
2912.18	307.837
2914.8	316.844
2917.42	324.697
2920.03	331.48
2922.65	336.35
2925.26	338.983
2927.88	339.605
2930.49	338.285
2933.1	333.995
2935.71	326.462
2938.32	315.965
2940.93	308.738
2943.54	294.897
2946.14	282.289
2948.75	268.526
2951.35	256.605
2953.96	243.308
2956.56	229.282
2959.16	216.11
2961.77	202.479
2964.37	190.054
2966.96	180.224
2969.56	168.104
2972.16	160.382
2974.76	149.878
2977.35	137.797
2979.95	126.668
2982.54	117.924
2985.14	109.034
2987.73	100.241
2990.32	91.386
2992.91	81.5324
2995.5	71.9788
2998.09	61.0826
3000.68	52.2624
3003.26	45.4469
3005.85	37.2534
3008.43	30.8403
3011.02	26.2706
3013.6	21.7859
3016.19	17.4793
3018.77	14.721
3021.35	11.7
3023.93	8.99996
3026.5	5.81924
3029.08	5.64324
3031.66	4.69545
3034.24	3.70083
3036.81	2.33573
3039.39	0.769855
3041.96	1.92959
3044.53	3.18188
3047.1	4.23144
3049.67	4.17325
3052.24	3.91359
3054.81	3.23126
3057.38	3.64608
3059.95	3.84335
3062.52	3.34537
3065.08	3.08903
3067.65	1.94239
3070.21	2.75389
3072.77	3.0005
3075.33	4.0592
3077.89	3.95035
3080.45	3.90835
3083.01	3.61305
3085.57	2.52882
3088.13	3.31269
3090.68	5.50583
3093.24	7.11089
3095.79	7.88593
3098.35	7.5799
3100.9	8.45632
3103.45	8.70852
3106	9.6571
3108.55	11.2033
3111.1	11.7882
3113.65	12.3607
3116.2	13.893
3118.75	15.5966
3121.29	15.9283
3123.84	16.2419
3126.38	16.2499
3128.92	18.6164
3131.47	20.4056
3134.01	22.3027
3136.55	23.3484
3139.09	24.9271
3141.63	27.0213
3144.17	29.0808
3146.7	33.2006
3149.24	36.028