File: data/Raman/poly_smoothed/Mb_20_23_17_1x_45s_532 nm_x100_100%_600 gr_mm_01.txt
#Acq. time (s)=	45
#Accumulations=	2
#Range (cm-¹)=	200...3150
#Windows=	2
#Auto scanning=	Off
#Autofocus=	Off
#Macrospot=	Off
#AutoExposure=	Off
#Spike filter=	Multiple accum.
#Delay time (s)=	0
#Binning=	1
#Readout mode=	Signal
#DeNoise=	Off
#ICS correction=	On
#Dark correction=	Off
#Inst. Process=	Off
#Detector Gain=	Best Dynamic Range
#Detector ADC=	20 kHz
#Detector temperature (°C)=	-69.85
#Instrument=	LabRAM HR Evol
#Detector=	Synapse
#Objective=	x100
#Grating=	600 gr/mm
#ND Filter=	100%
#Laser (nm)=	532
#Hole=	100.021
#Range=	Auto
#Laser Pol.=	No
#Raman. Pol.=	No
#Laser Pol. (°)=	-0.0007625
#Raman Pol. (°)=	89.9995
#Collection=	Microscope
#StageXY=	Marzhauser
#StageZ=	Marzhauser
#X (µm)=	-6910.2
#Y (µm)=	2087.2
#Z (µm)=	-74.6
#Full time(mm:ss)=	3:18
#Project=
#Sample=
#Site=
#Title=	Mb_20_23_17_2x_45s_532 nm_x100_100%_600 gr_mm
#Remark=
#Date=	13.07.2022 14:09
#Acquired=	13.07.2022 14:09:52
#Base:Fit=	10.08.2022 10:29:37
#Base:Sub=	10.08.2022 10:32:28
#Filter:Polynom=	16.08.2022 10:13:29
#AxisType[0]=Intens
#AxisUnit[0]=Cnt
#AxisType[1]=Spectr
#AxisUnit[1]=1/cm
200.563	29.3027
204.194	22.2925
207.821	17.5876
211.449	14.5333
215.074	12.6414
218.699	10.6547
222.321	7.34707
225.941	7.24361
229.562	5.77778
233.18	3.89439
236.796	2.58054
240.411	2.10292
244.026	0.580031
247.638	1.02818
251.248	2.19269
254.857	3.0928
258.465	3.68293
262.071	4.44835
265.678	6.23583
269.282	5.42831
272.884	7.63374
276.484	7.53859
280.084	6.80177
283.682	7.5708
287.276	6.50332
290.871	7.92359
294.465	8.72164
298.057	9.1584
301.648	9.52262
305.237	9.66538
308.823	6.54437
312.41	6.69706
315.995	6.65118
319.579	7.07295
323.16	7.46184
326.741	8.18268
330.321	7.92737
333.897	10.6499
337.474	12.365
341.048	12.6077
344.622	13.153
348.192	12.7901
351.764	13.803
355.332	13.2822
358.901	13.4134
362.466	13.1501
366.03	12.2882
369.594	12.1576
373.155	13.8108
376.715	12.8662
380.273	11.3836
383.832	9.98287
387.388	10.281
390.942	9.5498
394.495	9.08834
398.047	8.05145
401.597	8.93238
405.145	10.7531
408.693	10.7442
412.239	10.9285
415.783	11.3769
419.327	11.0932
422.869	8.45825
426.409	7.18679
429.948	6.5103
433.486	5.81124
437.022	5.24987
440.558	5.14929
444.089	6.33497
447.622	5.62179
451.153	5.81509
454.682	7.11264
458.208	7.19804
461.735	6.5949
465.259	7.02272
468.783	8.16747
472.306	8.68816
475.825	8.78047
479.346	10.2456
482.862	9.85283
486.38	10.1773
489.894	11.4679
493.407	11.9097
496.92	12.7932
500.43	13.1894
503.939	14.2089
507.448	13.2918
510.954	14.2138
514.459	14.5943
517.962	14.7067
521.466	15.4199
524.966	15.2239
528.466	16.205
531.964	14.977
535.46	15.5656
538.955	16.0757
542.449	15.8604
545.942	14.8287
549.433	14.1513
552.923	12.8657
556.412	11.9366
559.899	12.056
563.385	12.1925
566.867	11.4341
570.35	7.88165
573.832	10.0663
577.313	10.5967
580.79	10.9962
584.268	9.68749
587.745	9.11935
591.218	9.24914
594.692	8.93087
598.164	8.10459
601.634	7.17565
605.104	8.80772
608.57	9.14479
612.037	11.3967
615.501	11.5307
618.966	12.2521
622.427	15.0758
625.887	15.8986
629.348	16.7568
632.806	17.7277
636.262	18.0736
639.716	19.1399
643.172	19.9047
646.624	21.5366
650.075	21.739
653.524	21.0833
656.972	20.3309
660.419	21.7601
663.865	20.7445
667.309	20.0166
670.752	19.5212
674.194	17.8499
677.634	19.8046
681.073	18.8682
684.511	19.7062
687.947	22.5537
691.382	22.8749
694.816	24.7433
698.247	26.518
701.678	29.607
705.108	32.2244
708.534	34.8819
711.962	36.7398
715.388	38.8562
718.81	42.5726
722.234	43.4674
725.654	46.2147
729.075	49.9303
732.492	51.9408
735.91	54.4149
739.325	55.313
742.741	56.5504
746.153	57.8589
749.564	59.4554
752.976	61.0308
756.385	64.9629
759.792	67.7229
763.2	70.9343
766.604	72.0956
770.008	75.0303
773.41	76.0438
776.811	77.4239
780.21	80.107
783.608	82.2389
787.005	83.5491
790.401	85.9313
793.795	88.6664
797.188	90.2292
800.58	92.1048
803.971	92.5177
807.36	93.5915
810.748	93.8155
814.135	92.8558
817.518	92.2674
820.902	92.1168
824.285	91.2217
827.665	90.4598
831.045	90.5283
834.424	91.3117
837.8	92.118
841.177	93.2641
844.55	91.8742
847.924	89.2081
851.295	87.2028
854.666	84.6208
858.034	83.134
861.403	82.8441
864.769	81.8773
868.133	80.815
871.498	78.9146
874.86	76.8236
878.221	73.7671
881.58	70.815
884.938	68.7881
888.297	67.2676
891.653	65.5938
895.007	63.4175
898.36	63.7469
901.712	62.4699
905.063	61.1171
908.412	60.1033
911.76	61.4372
915.107	60.5784
918.452	59.4902
921.797	57.7052
925.138	59.6507
928.48	58.7099
931.82	57.6282
935.16	56.4298
938.496	56.5228
941.833	55.8698
945.168	52.8547
948.5	50.5693
951.834	47.9388
955.163	45.2285
958.494	42.4055
961.821	40.6336
965.15	40.5501
968.474	39.5919
971.8	39.8247
975.123	39.9098
978.446	40.2746
981.766	40.9116
985.084	39.9882
988.402	41.056
991.72	40.4637
995.035	39.7981
998.349	38.8311
1001.66	38.0248
1004.97	38.368
1008.28	39.3907
1011.59	39.641
1014.9	38.9824
1018.21	38.8142
1021.51	38.7546
1024.81	38.3167
1028.12	37.8412
1031.42	38.2521
1034.72	37.3363
1038.02	35.6667
1041.31	35.1782
1044.61	37.1353
1047.91	35.1821
1051.2	35.2807
1054.49	36.898
1057.78	37.0858
1061.07	37.3018
1064.36	37.0488
1067.65	36.9129
1070.93	36.7217
1074.22	36.5041
1077.5	35.454
1080.78	34.6163
1084.06	35.5643
1087.34	34.628
1090.62	34.9854
1093.9	34.1125
1097.17	33.2527
1100.45	34.3551
1103.72	32.8977
1106.99	33.7726
1110.27	31.4277
1113.53	29.7167
1116.8	27.2825
1120.07	25.4361
1123.33	24.3583
1126.6	21.2634
1129.86	19.4614
1133.12	18.3453
1136.38	17.4291
1139.64	16.8368
1142.9	15.7629
1146.16	14.6269
1149.41	15.1893
1152.67	15.8077
1155.92	15.2993
1159.17	15.687
1162.42	14.5738
1165.67	14.6477
1168.92	13.8652
1172.16	13.2842
1175.41	13.1655
1178.65	13.8522
1181.9	13.0686
1185.14	11.9114
1188.38	10.7091
1191.62	9.39394
1194.86	9.38947
1198.09	9.06774
1201.33	9.47758
1204.56	10.5477
1207.8	11.4772
1211.03	11.9879
1214.26	13.5782
1217.49	15.0607
1220.71	16.5928
1223.94	19.6216
1227.16	22.0659
1230.39	26.1069
1233.61	28.0703
1236.83	29.1617
1240.05	30.4039
1243.27	30.2031
1246.49	32.3177
1249.71	32.9242
1252.92	33.0105
1256.14	34.0054
1259.35	33.772
1262.56	33.4504
1265.77	34.7732
1268.98	37.9431
1272.19	41.399
1275.4	44.2872
1278.6	48.7252
1281.81	53.1156
1285.01	55.5849
1288.21	58.3234
1291.41	62.2358
1294.61	63.6208
1297.81	65.2514
1301.01	66.2633
1304.2	68.5224
1307.4	69.047
1310.59	69.2657
1313.78	69.3719
1316.97	68.0866
1320.16	67.1842
1323.35	67.1318
1326.54	64.1745
1329.72	61.609
1332.91	58.7643
1336.09	56.466
1339.27	55.0248
1342.45	53.3985
1345.64	52.8739
1348.81	52.4158
1351.99	51.6156
1355.17	52.3022
1358.34	52.25
1361.51	51.6601
1364.69	51.3935
1367.86	51.9459
1371.03	52.0338
1374.2	50.8742
1377.37	51.5206
1380.53	52.511
1383.7	53.1355
1386.86	54.2576
1390.02	54.7321
1393.19	53.4587
1396.35	53.3409
1399.51	54.4233
1402.66	55.9362
1405.82	57.8229
1408.97	60.0224
1412.13	64.1795
1415.28	71.2602
1418.43	77.8289
1421.59	83.6171
1424.73	91.6191
1427.88	100.41
1431.03	107.153
1434.18	113.894
1437.32	120.384
1440.46	125.519
1443.61	127.673
1446.75	130.262
1449.89	129.153
1453.03	126.944
1456.16	122.913
1459.3	116.893
1462.44	109.826
1465.57	100.689
1468.7	90.4959
1471.83	80.644
1474.96	70.6136
1478.09	61.2078
1481.22	52.8398
1484.35	45.4765
1487.47	38.6324
1490.6	34.1277
1493.72	29.1706
1496.84	25.1093
1499.96	21.751
1503.08	19.8482
1506.2	16.3673
1509.32	15.3943
1512.44	14.6413
1515.55	12.8914
1518.66	13.1549
1521.78	12.167
1524.89	11.8483
1528	12.2562
1531.11	11.434
1534.21	12.054
1537.32	14.3961
1540.43	15.1522
1543.53	15.9451
1546.63	18.1939
1549.74	18.0165
1552.84	18.5442
1555.94	18.8262
1559.03	21.2528
1562.13	21.4999
1565.23	22.503
1568.32	25.7807
1571.42	26.794
1574.51	27.386
1577.6	28.925
1580.69	30.7487
1583.78	32.0523
1586.87	33.0886
1589.95	33.6143
1593.04	34.4928
1596.12	35.1936
1599.21	35.0586
1602.29	35.355
1605.37	35.9136
1608.45	35.6915
1611.53	36.8325
1614.6	35.6123
1617.68	35.788
1620.75	34.9525
1623.83	34.5746
1626.9	33.6165
1629.97	33.0404
1633.04	34.165
1636.11	36.2869
1639.18	37.2239
1642.25	39.1177
1645.31	39.3735
1648.38	39.2935
1651.44	39.7674
1654.5	40.5919
1657.56	40.8803
1660.62	40.2077
1663.68	39.6761
1666.74	38.0223
1669.8	36.7962
1672.85	34.959
1675.91	33.2509
1678.96	31.5644
1682.01	29.0612
1685.06	26.7872
1688.11	23.3935
1691.16	21.1216
1694.21	19.4637
1697.25	18.4498
1700.3	16.628
1703.34	15.0837
1706.39	14.2119
1709.43	13.4853
1712.47	12.5115
1715.51	11.4648
1718.54	9.92733
1721.58	9.89981
1724.62	10.2571
1727.65	10.5871
1730.68	10.4151
1733.72	10.5737
1736.75	11.1722
1739.78	11.2159
1742.81	10.7105
1745.84	9.14279
1748.86	9.09611
1751.89	9.72937
1754.91	8.30301
1757.93	7.81791
1760.96	6.26805
1763.98	5.50569
1767	5.50197
1770.02	4.25642
1773.03	4.29342
1776.05	2.49461
1779.07	1.67192
1782.08	0.5402
1785.09	0.924312
1788.11	-0.205552
1791.12	0.00296949
1794.13	-0.34833
1797.13	0.14701
1800.14	-0.226179
1803.15	-0.644843
1806.15	0.544278
1809.16	0.88374
1812.16	0.910896
1815.16	1.38032
1818.16	2.19528
1821.16	3.43931
1824.16	4.0461
1827.16	5.02422
1830.16	5.21772
1833.15	5.30072
1836.14	5.25997
1839.14	6.0475
1842.13	6.43199
1845.12	6.64463
1848.11	6.36219
1851.1	6.09826
1854.08	6.10339
1857.07	6.27064
1860.05	5.701
1863.04	5.14524
1866.02	4.34925
1869	3.08346
1871.98	3.04573
1874.96	2.54836
1877.94	2.20627
1880.92	2.89544
1882.51	2.92323
1885.5	4.32912
1888.48	5.68803
1891.47	6.50956
1894.46	6.6284
1897.44	7.68337
1900.42	7.89177
1903.41	8.0776
1906.39	8.37028
1909.37	8.10705
1912.35	8.21338
1915.32	7.46318
1918.3	5.26633
1921.27	4.90668
1924.25	4.21457
1927.22	4.15099
1930.19	1.86767
1933.17	0.856327
1936.14	-0.311846
1939.11	-0.772986
1942.07	-0.97459
1945.04	-1.88339
1948.01	-2.95581
1950.97	-2.60208
1953.93	-1.66059
1956.9	-0.0315678
1959.86	0.620499
1962.82	0.4686
1965.78	0.401821
1968.74	1.15718
1971.69	2.03285
1974.65	2.14877
1977.6	4.39648
1980.56	5.70809
1983.51	5.79639
1986.46	6.29456
1989.41	5.23779
1992.36	6.10936
1995.31	6.44511
1998.26	6.98115
2001.2	6.50725
2004.15	6.7847
2007.09	7.27929
2010.04	7.30679
2012.98	7.98849
2015.92	8.48353
2018.86	8.76314
2021.8	10.3885
2024.73	11.2081
2027.67	11.8532
2030.61	11.8118
2033.54	12.3182
2036.47	12.2152
2039.4	11.4336
2042.33	11.1338
2045.27	11.1661
2048.19	12.2886
2051.12	11.5981
2054.05	10.9171
2056.97	10.6172
2059.9	10.1411
2062.82	11.4562
2065.74	11.5918
2068.67	11.4419
2071.59	12.2556
2074.51	12.5646
2077.42	13.1879
2080.34	12.8436
2083.26	13.655
2086.17	13.8238
2089.09	14.7154
2092	15.1052
2094.91	15.4415
2097.82	16.768
2100.73	16.2672
2103.64	16.5035
2106.55	16.307
2109.45	16.019
2112.36	16.2386
2115.26	15.6926
2118.17	15.5107
2121.07	15.9485
2123.97	16.3105
2126.87	19.2117
2129.77	20.3559
2132.67	21.4896
2135.56	22.4821
2138.46	25.1662
2141.35	27.2527
2144.25	29.6482
2147.14	30.4764
2150.03	31.225
2152.92	32.5453
2155.81	33.2293
2158.7	34.2756
2161.59	36.3113
2164.47	37.9495
2167.36	40.1956
2170.24	41.2001
2173.13	42.2494
2176.01	42.9507
2178.89	43.7482
2181.77	43.8527
2184.65	42.5796
2187.53	40.8396
2190.4	40.3097
2193.28	40.236
2196.16	39.5104
2199.03	37.8227
2201.9	36.9697
2204.77	35.7412
2207.64	34.6541
2210.51	33.2671
2213.38	30.0157
2216.25	27.2853
2219.12	25.4248
2221.98	23.5353
2224.85	22.5647
2227.71	21.1186
2230.57	20.0701
2233.43	19.6299
2236.29	18.7694
2239.15	17.9102
2242.01	18.4082
2244.87	17.4469
2247.72	17.4905
2250.58	16.9579
2253.43	16.5767
2256.29	15.2548
2259.14	15.4867
2261.99	16.3508
2264.84	15.5715
2267.69	15.9125
2270.53	16.5013
2273.38	16.2947
2276.23	15.9609
2279.07	15.3561
2281.91	15.7021
2284.76	15.6622
2287.6	16.0725
2290.44	15.5709
2293.28	14.7821
2296.12	14.614
2298.96	14.0267
2301.79	14.5443
2304.63	14.9905
2307.46	14.8361
2310.3	15.6333
2313.13	15.4662
2315.96	15.5499
2318.79	15.274
2321.62	15.0775
2324.45	14.8103
2327.27	14.8834
2330.1	14.6379
2332.92	14.2413
2335.75	13.7729
2338.57	14.9011
2341.39	14.3983
2344.21	13.882
2347.04	12.939
2349.85	12.5574
2352.67	11.4321
2355.49	9.77446
2358.3	8.52979
2361.12	7.38845
2363.93	6.88448
2366.75	6.70648
2369.56	6.10588
2372.37	5.49431
2375.18	5.1782
2377.99	4.64404
2380.8	5.30368
2383.6	6.61294
2386.41	7.05392
2389.21	6.71473
2392.02	7.46956
2394.82	8.75977
2397.62	9.65199
2400.42	10.0722
2403.22	10.9425
2406.02	11.2589
2408.82	11.3896
2411.62	11.1131
2414.41	11.2341
2417.21	10.4152
2420	9.01733
2422.79	8.17792
2425.59	7.3734
2428.38	6.78823
2431.17	6.68236
2433.95	5.74799
2436.74	5.31986
2439.53	5.79641
2442.31	6.02844
2445.1	6.67973
2447.88	8.05972
2450.67	9.56127
2453.45	8.29108
2456.23	8.07105
2459.01	6.86747
2461.79	7.99211
2464.57	7.48498
2467.34	7.41952
2470.12	6.79162
2472.89	6.2978
2475.67	6.72712
2478.44	5.90679
2481.21	5.27188
2483.98	4.20397
2486.75	3.16624
2489.52	2.56346
2492.29	1.67012
2495.05	2.11312
2497.82	3.27515
2500.58	2.97231
2503.35	3.39457
2506.11	4.32044
2508.87	4.79439
2511.63	4.78779
2514.39	5.39469
2517.15	5.33582
2519.91	5.61238
2522.67	5.04232
2525.42	5.1755
2528.18	5.27366
2530.93	5.0758
2533.69	5.25995
2536.44	5.11259
2539.19	4.69132
2541.94	4.5659
2544.69	3.06213
2547.44	2.14877
2550.18	1.51973
2552.93	1.12737
2555.67	0.622965
2558.42	-0.64918
2561.16	-1.04006
2563.9	-0.836175
2566.64	-1.49778
2569.38	-1.1526
2572.12	-0.867101
2574.86	-0.705775
2577.6	-0.0560777
2580.33	-0.051971
2583.07	1.24007
2585.8	2.09238
2588.54	2.79059
2591.27	4.00883
2594	4.74674
2596.73	4.5131
2599.46	5.10561
2602.19	5.92304
2604.92	5.40475
2607.64	5.11137
2610.37	5.80453
2613.09	4.63277
2615.82	5.01704
2618.54	5.99963
2621.26	6.39739
2623.98	6.01696
2626.7	5.85684
2629.42	6.62133
2632.14	6.67614
2634.86	6.67765
2637.57	7.43174
2640.29	6.68329
2643	6.73244
2645.71	6.99423
2648.43	6.40192
2651.14	6.40749
2653.85	5.7526
2656.56	5.65813
2659.26	4.69001
2661.97	3.84477
2664.68	3.48789
2667.38	2.8188
2670.09	2.08641
2672.79	1.63455
2675.49	1.9121
2678.19	1.94848
2680.89	1.99979
2683.59	2.10996
2686.29	2.73108
2688.99	3.00054
2691.69	3.08099
2694.38	3.62618
2697.08	4.73127
2699.77	5.58392
2702.46	6.95784
2705.15	8.20603
2707.85	9.21182
2710.54	11.1106
2713.22	11.3823
2715.91	12.3826
2718.6	13.8267
2721.29	14.8251
2723.97	14.7838
2726.66	14.8472
2729.34	14.9778
2732.02	14.3303
2734.7	13.8956
2737.38	13.3349
2740.06	12.5339
2742.74	12.3117
2745.42	11.4045
2748.09	9.29819
2750.77	8.15798
2753.45	7.19014
2756.12	4.9048
2758.79	4.03972
2761.46	5.32603
2764.14	3.65217
2766.8	2.69714
2769.47	2.04286
2772.14	1.34306
2774.81	1.30566
2777.48	1.30423
2780.14	0.548198
2782.8	0.167917
2785.47	0.570583
2788.13	-0.197543
2790.79	-0.454706
2793.45	-0.927701
2796.11	-1.16878
2798.77	-1.43557
2801.43	-1.81109
2804.09	-1.73656
2806.74	-1.98453
2809.4	-3.03675
2812.05	-3.4826
2814.71	-3.59334
2817.36	-1.39749
2820.01	4.02013
2822.66	12.6385
2825.31	22.6045
2827.96	33.242
2830.6	44.9334
2833.25	58.6037
2835.9	72.4265
2838.54	87.2185
2841.18	101.928
2843.83	116.765
2846.47	130.803
2849.11	145.386
2851.75	160.054
2854.39	172.036
2857.03	185.115
2859.66	197.39
2862.3	207.504
2864.94	215.783
2867.57	222.812
2870.2	227.631
2872.84	231.209
2875.47	234.616
2878.1	238.229
2880.73	242.467
2883.36	246.857
2885.99	252.958
2888.61	257.632
2891.24	261.224
2893.86	265.927
2896.49	270.173
2899.11	273.688
2901.73	277.961
2904.36	281.902
2906.98	287.326
2909.6	295.036
2912.21	301.705
2914.83	308.51
2917.45	314.528
2920.07	318.772
2922.68	321.548
2925.29	322.073
2927.91	320.392
2930.52	317.9
2933.13	312.981
2935.74	305.806
2938.35	296.717
2940.96	286.873
2943.57	274.959
2946.18	262.666
2948.78	248.919
2951.39	235.461
2953.99	220.41
2956.59	207.292
2959.2	193.258
2961.8	180.506
2964.4	167.652
2967	156.883
2969.6	147.12
2972.19	138.29
2974.79	129.301
2977.39	120.014
2979.98	110.558
2982.58	100.855
2985.17	90.6233
2987.76	81.232
2990.35	72.4634
2992.94	64.4787
2995.53	55.4838
2998.12	48.3145
3000.71	40.4281
3003.3	33.3661
3005.88	28.0549
3008.47	23.081
3011.05	18.4026
3013.64	13.1982
3016.22	10.2031
3018.8	7.94532
3021.38	6.29712
3023.96	5.41004
3026.54	3.80496
3029.12	2.53491
3031.69	1.54816
3034.27	2.23875
3036.84	1.71521
3039.42	3.02584
3041.99	4.04673
3044.57	4.30218
3047.14	4.97098
3049.71	5.15766
3052.28	6.67277
3054.85	7.40452
3057.41	6.54508
3059.98	5.95434
3062.55	4.96044
3065.11	4.62474
3067.68	4.54119
3070.24	3.94619
3072.8	2.93454
3075.36	2.02595
3077.93	1.62676
3080.49	1.15247
3083.04	1.0213
3085.6	0.290994
3088.16	-0.00562994
3090.72	-0.574016
3093.27	0.304717
3095.83	0.713865
3098.38	1.19256
3100.93	1.80713
3103.49	2.11673
3106.04	2.34644
3108.59	2.41133
3111.14	4.14684
3113.69	5.58743
3116.23	5.49154
3118.78	6.19862
3121.33	6.80708
3123.87	7.84093
3126.41	9.49397
3128.96	10.8693
3131.5	12.3604
3134.04	13.7086
3136.58	14.7627
3139.12	16.7092
3141.66	18.5703
3144.2	19.8184
3146.74	21.9393
3149.27	21.7513