File: data/Raman/poly_smoothed/Mb_20_23_07_1x_45s_532 nm_x100_100%_600 gr_mm_01.txt
#Acq. time (s)=	45
#Accumulations=	2
#Range (cm-¹)=	200...3150
#Windows=	2
#Auto scanning=	Off
#Autofocus=	Off
#Macrospot=	Off
#AutoExposure=	Off
#Spike filter=	Multiple accum.
#Delay time (s)=	0
#Binning=	1
#Readout mode=	Signal
#DeNoise=	Off
#ICS correction=	On
#Dark correction=	Off
#Inst. Process=	Off
#Detector Gain=	Best Dynamic Range
#Detector ADC=	20 kHz
#Detector temperature (°C)=	-69.85
#Instrument=	LabRAM HR Evol
#Detector=	Synapse
#Objective=	x100
#Grating=	600 gr/mm
#ND Filter=	100%
#Laser (nm)=	532
#Hole=	100.021
#Range=	Auto
#Laser Pol.=	No
#Raman. Pol.=	No
#Laser Pol. (°)=	-0.0007625
#Raman Pol. (°)=	89.9995
#Collection=	Microscope
#StageXY=	Marzhauser
#StageZ=	Marzhauser
#X (µm)=	-6942.5
#Y (µm)=	2175.1
#Z (µm)=	-74.45
#Full time(mm:ss)=	3:18
#Project=
#Sample=
#Site=
#Title=	Mb_20_23_07_2x_45s_532 nm_x100_100%_600 gr_mm
#Remark=
#Date=	13.07.2022 13:27
#Acquired=	13.07.2022 13:27:46
#Base:Fit=	10.08.2022 10:29:19
#Base:Fit=	10.08.2022 10:29:37
#Base:Sub=	10.08.2022 10:31:46
#Filter:Polynom=	16.08.2022 10:13:29
#AxisType[0]=Intens
#AxisUnit[0]=Cnt
#AxisType[1]=Spectr
#AxisUnit[1]=1/cm
200.563	18.3971
204.194	19.053
207.821	15.1677
211.449	12.94
215.074	11.6269
218.699	11.0982
222.321	10.0764
225.941	9.40719
229.562	8.42121
233.18	6.97702
236.796	5.15704
240.411	4.24624
244.026	4.06395
247.638	4.56139
251.248	4.41683
254.857	2.99012
258.465	2.62818
262.071	3.77872
265.678	5.68839
269.282	5.53295
272.884	6.80881
276.484	6.74705
280.084	6.53119
283.682	6.59206
287.276	8.08984
290.871	7.7827
294.465	9.82077
298.057	11.8318
301.648	13.2518
305.237	15.4734
308.823	14.6278
312.41	14.2359
315.995	14.6967
319.579	13.327
323.16	10.2951
326.741	9.4468
330.321	9.746
333.897	9.66501
337.474	9.47729
341.048	8.26375
344.622	8.93985
348.192	8.21304
351.764	9.17601
355.332	9.47435
358.901	9.68161
362.466	8.80749
366.03	10.991
369.594	12.5827
373.155	14.2325
376.715	15.099
380.273	16.9868
383.832	17.3059
387.388	18.7018
390.942	18.5944
394.495	16.9986
398.047	16.7758
401.597	14.7663
405.145	15.2687
408.693	14.8693
412.239	14.313
415.783	14.553
419.327	14.273
422.869	15.4397
426.409	13.4116
429.948	12.9785
433.486	11.7798
437.022	10.3397
440.558	11.1039
444.089	12.4255
447.622	13.0553
451.153	11.9049
454.682	13.0972
458.208	12.7107
461.735	13.4385
465.259	15.911
468.783	16.1396
472.306	18.6023
475.825	19.4182
479.346	21.314
482.862	23.2983
486.38	25.0122
489.894	27.3263
493.407	29.7304
496.92	30.979
500.43	31.4913
503.939	32.7477
507.448	33.4072
510.954	32.8877
514.459	32.6378
517.962	33.001
521.466	32.8567
524.966	31.2233
528.466	29.4491
531.964	27.8501
535.46	26.1806
538.955	23.6968
542.449	24.3782
545.942	23.2173
549.433	21.6585
552.923	22.1273
556.412	20.4402
559.899	18.6679
563.385	17.1788
566.867	15.9096
570.35	13.7371
573.832	12.9782
577.313	11.8903
580.79	9.65681
584.268	9.19053
587.745	7.93866
591.218	6.30552
594.692	3.51977
598.164	2.85434
601.634	2.07162
605.104	3.3451
608.57	2.22458
612.037	2.76787
615.501	2.77455
618.966	5.6749
622.427	5.82051
625.887	5.41265
629.348	5.46972
632.806	5.89717
636.262	6.01514
639.716	6.00902
643.172	5.77523
646.624	6.58244
650.075	7.51509
653.524	8.6126
656.972	9.54534
660.419	9.76559
663.865	10.4664
667.309	10.7715
670.752	10.4815
674.194	9.75608
677.634	8.73578
681.073	8.43136
684.511	10.205
687.947	12.4953
691.382	12.8245
694.816	15.5122
698.247	16.3635
701.678	17.0783
705.108	16.7698
708.534	15.5468
711.962	15.1032
715.388	14.1264
718.81	13.7752
722.234	16.183
725.654	17.6712
729.075	19.3077
732.492	23.4459
735.91	25.8703
739.325	29.1614
742.741	32.3574
746.153	35.5132
749.564	39.7729
752.976	42.9659
756.385	46.8427
759.792	50.364
763.2	52.9479
766.604	58.2725
770.008	61.6044
773.41	64.0808
776.811	66.7264
780.21	68.6143
783.608	68.4592
787.005	69.0539
790.401	69.0765
793.795	69.3772
797.188	69.071
800.58	68.8679
803.971	70.4196
807.36	70.9079
810.748	69.5974
814.135	70.7256
817.518	69.6211
820.902	68.9161
824.285	69.4223
827.665	68.7404
831.045	67.9695
834.424	68.6808
837.8	68.8725
841.177	68.4105
844.55	67.306
847.924	65.6311
851.295	63.8791
854.666	62.6252
858.034	61.7462
861.403	60.6105
864.769	60.3969
868.133	60.0101
871.498	59.3752
874.86	56.5719
878.221	55.1694
881.58	53.7413
884.938	53.2392
888.297	51.1982
891.653	48.2886
895.007	46.3836
898.36	46.3911
901.712	45.8296
905.063	44.7092
908.412	43.102
911.76	42.2552
915.107	42.0129
918.452	41.8223
921.797	41.9164
925.138	40.6227
928.48	40.962
931.82	41.9996
935.16	41.5954
938.496	41.4085
941.833	40.2337
945.168	40.1798
948.5	42.0322
951.834	40.7119
955.163	38.5789
958.494	37.4569
961.821	36.9443
965.15	36.5118
968.474	36.5359
971.8	37.5529
975.123	38.3107
978.446	38.6618
981.766	40.0689
985.084	38.8276
988.402	37.0322
991.72	36.4218
995.035	36.0478
998.349	37.3255
1001.66	36.2383
1004.97	37.3658
1008.28	39.3042
1011.59	41.042
1014.9	44.6188
1018.21	46.5537
1021.51	49.2357
1024.81	53.782
1028.12	57.7275
1031.42	59.3012
1034.72	59.1749
1038.02	61.053
1041.31	62.7965
1044.61	65.1734
1047.91	66.7946
1051.2	68.0737
1054.49	67.6222
1057.78	67.2439
1061.07	64.7578
1064.36	62.6388
1067.65	60.4026
1070.93	57.6468
1074.22	55.0085
1077.5	51.7003
1080.78	49.5107
1084.06	46.1658
1087.34	45.0693
1090.62	44.3748
1093.9	45.2602
1097.17	44.2757
1100.45	44.2635
1103.72	43.5233
1106.99	42.3559
1110.27	40.6596
1113.53	39.0462
1116.8	37.9932
1120.07	37.331
1123.33	35.4194
1126.6	34.3136
1129.86	33.0207
1133.12	31.3754
1136.38	30.552
1139.64	30.3047
1142.9	28.9232
1146.16	28.0747
1149.41	26.4965
1152.67	23.2768
1155.92	19.4518
1159.17	15.8178
1162.42	13.7406
1165.67	11.3467
1168.92	10.752
1172.16	11.1427
1175.41	11.3041
1178.65	10.9811
1181.9	10.2551
1185.14	10.0437
1188.38	11.647
1191.62	13.0462
1194.86	13.9395
1198.09	17.544
1201.33	20.4251
1204.56	23.9854
1207.8	28.1841
1211.03	33.8727
1214.26	39.2733
1217.49	45.1714
1220.71	50.3759
1223.94	53.5941
1227.16	56.124
1230.39	59.2251
1233.61	62.1615
1236.83	65.8957
1240.05	70.2898
1243.27	73.5966
1246.49	75.9852
1249.71	78.5382
1252.92	80.8234
1256.14	81.1498
1259.35	81.7275
1262.56	82.4022
1265.77	85.9399
1268.98	88.8423
1272.19	90.761
1275.4	93.7129
1278.6	97.4576
1281.81	99.734
1285.01	102.421
1288.21	106.791
1291.41	109.014
1294.61	111.134
1297.81	113.054
1301.01	115.422
1304.2	118.145
1307.4	121.048
1310.59	124.827
1313.78	127.945
1316.97	128.499
1320.16	129.11
1323.35	128.709
1326.54	126.604
1329.72	124.631
1332.91	120.902
1336.09	118.8
1339.27	116.127
1342.45	113.648
1345.64	111.058
1348.81	106.687
1351.99	102.409
1355.17	100.458
1358.34	95.3553
1361.51	91.1034
1364.69	89.1902
1367.86	85.1694
1371.03	83.329
1374.2	82.2375
1377.37	82.1826
1380.53	81.2087
1383.7	81.5767
1386.86	82.3722
1390.02	82.8907
1393.19	84.2451
1396.35	83.3965
1399.51	82.0398
1402.66	82.6844
1405.82	86.6373
1408.97	91.7362
1412.13	96.8083
1415.28	105.393
1418.43	113.036
1421.59	121.031
1424.73	129.573
1427.88	140.214
1431.03	149.39
1434.18	158.074
1437.32	165.373
1440.46	171.022
1443.61	175.389
1446.75	177.379
1449.89	179.359
1453.03	176.333
1456.16	171.674
1459.3	165.346
1462.44	156.496
1465.57	147.4
1468.7	137.349
1471.83	125.382
1474.96	112.624
1478.09	102.781
1481.22	94.2031
1484.35	85.153
1487.47	76.9986
1490.6	68.5189
1493.72	60.5986
1496.84	54.3215
1499.96	49.3875
1503.08	46.9154
1506.2	44.138
1509.32	42.2402
1512.44	41.8318
1515.55	40.3371
1518.66	39.2947
1521.78	39.6208
1524.89	40.9787
1528	42.0735
1531.11	43.8271
1534.21	46.6211
1537.32	47.8267
1540.43	49.9296
1543.53	52.2894
1546.63	55.2652
1549.74	56.4032
1552.84	57.8296
1555.94	59.5407
1559.03	61.2619
1562.13	61.0297
1565.23	61.4639
1568.32	61.8931
1571.42	64.2772
1574.51	65.3274
1577.6	67.6539
1580.69	68.1275
1583.78	68.9419
1586.87	71.5289
1589.95	73.4092
1593.04	74.8321
1596.12	76.9136
1599.21	77.818
1602.29	78.6925
1605.37	78.2022
1608.45	77.9241
1611.53	77.9543
1614.6	76.7206
1617.68	77.097
1620.75	78.0912
1623.83	79.2431
1626.9	80.6086
1629.97	82.8742
1633.04	86.2362
1636.11	89.4054
1639.18	92.2377
1642.25	95.712
1645.31	98.9845
1648.38	100.943
1651.44	101.867
1654.5	104.206
1657.56	104.382
1660.62	105.059
1663.68	104.428
1666.74	103.693
1669.8	100.954
1672.85	96.5332
1675.91	90.8166
1678.96	84.7457
1682.01	79.3759
1685.06	73.0681
1688.11	65.6276
1691.16	59.5706
1694.21	53.568
1697.25	48.0615
1700.3	43.4471
1703.34	39.3024
1706.39	35.2489
1709.43	32.3951
1712.47	29.2698
1715.51	26.4519
1718.54	23.9443
1721.58	22.4071
1724.62	20.5876
1727.65	19.5682
1730.68	19.1881
1733.72	19.0324
1736.75	19.3001
1739.78	19.5415
1742.81	18.0941
1745.84	19.0443
1748.86	17.8549
1751.89	16.6271
1754.91	15.5737
1757.93	15.2309
1760.96	13.3264
1763.98	11.7035
1767	11.2484
1770.02	9.98867
1773.03	10.3254
1776.05	10.0234
1779.07	9.39304
1782.08	9.31809
1785.09	9.83059
1788.11	10.2032
1791.12	10.6733
1794.13	10.3743
1797.13	10.6875
1800.14	11.1066
1803.15	11.7067
1806.15	10.6603
1809.16	10.1575
1812.16	9.61494
1815.16	9.23616
1818.16	9.906
1821.16	9.82361
1824.16	9.34892
1827.16	7.56413
1830.16	6.14627
1833.15	5.8136
1836.14	6.10901
1839.14	5.89759
1842.13	6.02808
1845.12	6.73695
1848.11	7.16222
1851.1	7.25415
1854.08	7.23243
1857.07	6.8956
1860.05	7.14896
1863.04	5.98114
1866.02	6.0157
1869	5.68314
1871.98	6.54939
1874.96	6.32711
1877.94	5.366
1880.92	5.35418
1882.51	5.51766
1885.5	7.10313
1888.48	7.4664
1891.47	8.86307
1894.46	9.31295
1897.44	8.84047
1900.42	8.82511
1903.41	8.86859
1906.39	9.45522
1909.37	8.69832
1912.35	9.4822
1915.32	9.87754
1918.3	9.6961
1921.27	8.24149
1924.25	8.06645
1927.22	6.91802
1930.19	6.87919
1933.17	6.57996
1936.14	6.68198
1939.11	6.99263
1942.07	6.55335
1945.04	5.56645
1948.01	5.02972
1950.97	4.69364
1953.93	5.82785
1956.9	6.06585
1959.86	6.76358
1962.82	6.70132
1965.78	7.27323
1968.74	5.62068
1971.69	4.1674
1974.65	3.56611
1977.6	3.91179
1980.56	3.19986
1983.51	3.24084
1986.46	2.85737
1989.41	3.04162
1992.36	3.94976
1995.31	4.70339
1998.26	5.7815
2001.2	7.27904
2004.15	8.79287
2007.09	9.57362
2010.04	9.36585
2012.98	9.50378
2015.92	10.2427
2018.86	10.8286
2021.8	12.5767
2024.73	13.5084
2027.67	14.6618
2030.61	14.513
2033.54	14.2871
2036.47	14.5172
2039.4	14.7458
2042.33	15.7702
2045.27	14.8384
2048.19	15.1671
2051.12	15.8714
2054.05	14.7022
2056.97	13.8724
2059.9	14.24
2062.82	15.2571
2065.74	15.9739
2068.67	15.7344
2071.59	16.9165
2074.51	17.1896
2077.42	17.2141
2080.34	17.2325
2083.26	18.2599
2086.17	19.2153
2089.09	20.7589
2092	21.5202
2094.91	22.9768
2097.82	23.4439
2100.73	24.4712
2103.64	24.626
2106.55	25.6096
2109.45	27.3543
2112.36	27.4582
2115.26	28.7227
2118.17	29.0753
2121.07	29.7877
2123.97	30.4481
2126.87	31.601
2129.77	33.151
2132.67	35.1107
2135.56	37.431
2138.46	39.5449
2141.35	41.99
2144.25	43.9821
2147.14	46.8563
2150.03	49.5539
2152.92	52.5514
2155.81	56.0246
2158.7	58.4961
2161.59	62.2717
2164.47	63.9247
2167.36	65.9935
2170.24	67.7038
2173.13	68.784
2176.01	68.3842
2178.89	68.86
2181.77	68.3718
2184.65	66.7348
2187.53	65.753
2190.4	64.9748
2193.28	62.6321
2196.16	60.9824
2199.03	58.8357
2201.9	55.7387
2204.77	53.6091
2207.64	50.6287
2210.51	47.0373
2213.38	45.2227
2216.25	41.6547
2219.12	39.4917
2221.98	36.7605
2224.85	34.7063
2227.71	32.2888
2230.57	30.6318
2233.43	28.814
2236.29	26.6597
2239.15	24.144
2242.01	22.5461
2244.87	20.2723
2247.72	19.8816
2250.58	19.4927
2253.43	17.7607
2256.29	17.23
2259.14	17.3444
2261.99	16.7221
2264.84	16.4359
2267.69	16.4487
2270.53	15.7677
2273.38	14.7886
2276.23	14.5607
2279.07	13.5431
2281.91	12.3403
2284.76	11.8434
2287.6	10.6796
2290.44	9.58928
2293.28	8.67633
2296.12	8.80177
2298.96	10.3625
2301.79	10.9129
2304.63	11.7299
2307.46	10.8311
2310.3	10.9833
2313.13	12.6392
2315.96	12.1156
2318.79	12.1379
2321.62	11.5314
2324.45	11.1769
2327.27	11.1987
2330.1	10.7727
2332.92	10.4579
2335.75	9.35176
2338.57	8.85038
2341.39	7.64778
2344.21	6.94292
2347.04	5.07807
2349.85	4.2802
2352.67	2.66004
2355.49	2.4004
2358.3	2.41744
2361.12	1.59542
2363.93	1.90159
2366.75	3.75721
2369.56	4.21854
2372.37	4.21995
2375.18	5.37085
2377.99	5.79195
2380.8	5.98299
2383.6	6.1881
2386.41	6.13167
2389.21	7.45566
2392.02	6.86009
2394.82	6.66835
2397.62	6.73143
2400.42	6.71622
2403.22	6.36698
2406.02	5.97484
2408.82	6.7903
2411.62	5.81324
2414.41	5.81012
2417.21	5.64328
2420	4.67387
2422.79	4.88433
2425.59	4.15735
2428.38	3.53265
2431.17	3.1754
2433.95	3.71143
2436.74	3.20284
2439.53	2.95764
2442.31	3.12379
2445.1	3.77402
2447.88	3.70577
2450.67	2.9813
2453.45	3.01911
2456.23	2.99422
2459.01	1.64742
2461.79	0.138643
2464.57	0.44658
2467.34	0.743963
2470.12	-0.126529
2472.89	-0.286206
2475.67	-0.162302
2478.44	-0.0656051
2481.21	0.717818
2483.98	1.88851
2486.75	1.56827
2489.52	1.23805
2492.29	1.66525
2495.05	1.86115
2497.82	1.7921
2500.58	2.23208
2503.35	1.73687
2506.11	1.26806
2508.87	1.09586
2511.63	1.59015
2514.39	1.65609
2517.15	1.8236
2519.91	1.18151
2522.67	1.06641
2525.42	0.33157
2528.18	-0.167839
2530.93	0.453196
2533.69	1.93114
2536.44	1.24919
2539.19	2.04733
2541.94	3.08375
2544.69	4.40083
2547.44	5.1935
2550.18	5.57401
2552.93	5.68684
2555.67	5.30706
2558.42	6.27464
2561.16	5.94827
2563.9	5.66352
2566.64	5.91468
2569.38	5.50066
2572.12	4.86879
2574.86	4.62699
2577.6	4.68569
2580.33	5.34883
2583.07	4.6722
2585.8	5.26107
2588.54	5.18466
2591.27	4.53269
2594	4.11007
2596.73	3.40978
2599.46	3.79577
2602.19	3.8874
2604.92	3.99074
2607.64	4.23503
2610.37	3.75397
2613.09	2.94112
2615.82	2.55677
2618.54	3.28214
2621.26	2.20972
2623.98	2.26244
2626.7	2.56694
2629.42	1.82644
2632.14	0.890623
2634.86	1.27948
2637.57	1.20939
2640.29	1.68765
2643	1.58374
2645.71	2.28809
2648.43	3.45555
2651.14	4.40499
2653.85	4.72121
2656.56	4.85755
2659.26	3.98897
2661.97	3.09998
2664.68	3.44951
2667.38	3.13169
2670.09	3.23707
2672.79	1.74544
2675.49	0.581756
2678.19	0.707368
2680.89	0.874919
2683.59	2.01675
2686.29	2.16728
2688.99	2.6525
2691.69	3.79292
2694.38	3.06464
2697.08	3.90705
2699.77	4.64888
2702.46	6.03831
2705.15	6.891
2707.85	8.11873
2710.54	9.33238
2713.22	10.9617
2715.91	11.6133
2718.6	12.0191
2721.29	11.8417
2723.97	11.8955
2726.66	11.8209
2729.34	13.0198
2732.02	12.624
2734.7	10.8765
2737.38	9.76812
2740.06	8.78435
2742.74	8.95797
2745.42	8.98972
2748.09	9.70175
2750.77	9.27937
2753.45	8.90031
2756.12	8.14065
2758.79	7.74299
2761.46	6.9759
2764.14	6.41175
2766.8	5.83723
2769.47	6.00545
2772.14	4.2367
2774.81	3.60732
2777.48	3.59036
2780.14	3.59878
2782.8	2.19667
2785.47	3.47849
2788.13	3.13866
2790.79	1.82434
2793.45	0.906196
2796.11	-0.271047
2798.77	-0.828517
2801.43	-0.0706288
2804.09	0.482437
2806.74	0.284339
2809.4	0.0676635
2812.05	0.331934
2814.71	1.39063
2817.36	4.44501
2820.01	9.09375
2822.66	14.9022
2825.31	22.5595
2827.96	31.516
2830.6	41.1818
2833.25	51.1105
2835.9	62.5284
2838.54	74.5129
2841.18	88.3638
2843.83	103.082
2846.47	116.818
2849.11	132.034
2851.75	147.099
2854.39	161.985
2857.03	176.93
2859.66	191.004
2862.3	205.838
2864.94	218.1
2867.57	228.802
2870.2	237.252
2872.84	245.955
2875.47	253.341
2878.1	260.91
2880.73	269.696
2883.36	276.577
2885.99	283.984
2888.61	291.097
2891.24	297.517
2893.86	304.468
2896.49	311.028
2899.11	319.095
2901.73	329.275
2904.36	339.007
2906.98	351.298
2909.6	363.32
2912.21	375.559
2914.83	389.834
2917.45	402.736
2920.07	413.039
2922.68	420.716
2925.29	426.454
2927.91	429.63
2930.52	431.522
2933.13	429.182
2935.74	426.072
2938.35	419.812
2940.96	411.493
2943.57	401.512
2946.18	388.19
2948.78	373.809
2951.39	358.695
2953.99	343.084
2956.59	326.621
2959.2	311.172
2961.8	296.301
2964.4	281.675
2967	267.312
2969.6	252.863
2972.19	240.329
2974.79	225.496
2977.39	212.758
2979.98	198.484
2982.58	183.496
2985.17	167.411
2987.76	152.42
2990.35	137.659
2992.94	123.686
2995.53	110.7
2998.12	96.9977
3000.71	85.6627
3003.3	74.6534
3005.88	63.9724
3008.47	54.09
3011.05	46.7385
3013.64	39.8582
3016.22	34.2438
3018.8	29.628
3021.38	26.1733
3023.96	23.0818
3026.54	20.039
3029.12	17.79
3031.69	16.5063
3034.27	16.9202
3036.84	15.5564
3039.42	15.8651
3041.99	16.0294
3044.57	15.2977
3047.14	16.2848
3049.71	17.1896
3052.28	17.0331
3054.85	17.1094
3057.41	16.7879
3059.98	15.3778
3062.55	13.8981
3065.11	12.8646
3067.68	11.9011
3070.24	11.4589
3072.8	10.2564
3075.36	9.47209
3077.93	8.44026
3080.49	6.70004
3083.04	4.93471
3085.6	3.88052
3088.16	2.84397
3090.72	2.98931
3093.27	3.06102
3095.83	4.18151
3098.38	4.30517
3100.93	5.09498
3103.49	5.75785
3106.04	7.09265
3108.59	8.925
3111.14	11.5799
3113.69	12.5848
3116.23	13.4072
3118.78	13.9315
3121.33	15.4496
3123.87	16.333
3126.41	17.7526
3128.96	19.6347
3131.5	21.6915
3134.04	23.0318
3136.58	24.6065
3139.12	24.697
3141.66	25.7968
3144.2	27.1419
3146.74	28.6308
3149.27	29.3932