File: data/Raman/poly_smoothed/Mb_20_23_22_1x_45s_532 nm_x100_100%_600 gr_mm_01.txt
#Acq. time (s)=	45
#Accumulations=	2
#Range (cm-¹)=	200...3150
#Windows=	2
#Auto scanning=	Off
#Autofocus=	Off
#Macrospot=	Off
#AutoExposure=	Off
#Spike filter=	Multiple accum.
#Delay time (s)=	0
#Binning=	1
#Readout mode=	Signal
#DeNoise=	Off
#ICS correction=	On
#Dark correction=	Off
#Inst. Process=	Off
#Detector Gain=	Best Dynamic Range
#Detector ADC=	20 kHz
#Detector temperature (°C)=	-69.85
#Instrument=	LabRAM HR Evol
#Detector=	Synapse
#Objective=	x100
#Grating=	600 gr/mm
#ND Filter=	100%
#Laser (nm)=	532
#Hole=	100.021
#Range=	Auto
#Laser Pol.=	No
#Raman. Pol.=	No
#Laser Pol. (°)=	-0.0007625
#Raman Pol. (°)=	89.9995
#Collection=	Microscope
#StageXY=	Marzhauser
#StageZ=	Marzhauser
#X (µm)=	-6969.1
#Y (µm)=	2051
#Z (µm)=	-75.05
#Full time(mm:ss)=	3:19
#Project=
#Sample=
#Site=
#Title=	Mb_20_23_22_2x_45s_532 nm_x100_100%_600 gr_mm
#Remark=
#Date=	13.07.2022 14:54
#Acquired=	13.07.2022 14:54:48
#Base:Fit=	10.08.2022 10:29:37
#Base:Sub=	10.08.2022 10:33:46
#Filter:Polynom=	16.08.2022 10:13:29
#AxisType[0]=Intens
#AxisUnit[0]=Cnt
#AxisType[1]=Spectr
#AxisUnit[1]=1/cm
200.563	39.438
204.194	39.5766
207.821	37.9323
211.449	37.4959
215.074	37.9614
218.699	37.0647
222.321	35.8215
225.941	34.5636
229.562	33.6446
233.18	33.3968
236.796	31.1755
240.411	29.154
244.026	27.6185
247.638	25.9154
251.248	23.923
254.857	23.3757
258.465	22.6348
262.071	19.897
265.678	15.1561
269.282	11.7
272.884	9.09342
276.484	8.63405
280.084	7.54506
283.682	5.75975
287.276	4.36979
290.871	4.20753
294.465	4.48406
298.057	7.1378
301.648	8.20178
305.237	10.1846
308.823	12.0928
312.41	13.5206
315.995	16.6998
319.579	18.4359
323.16	21.3443
326.741	22.8257
330.321	25.275
333.897	26.4341
337.474	27.4908
341.048	29.414
344.622	28.8655
348.192	25.7997
351.764	24.2961
355.332	23.2648
358.901	20.9097
362.466	18.9054
366.03	17.0933
369.594	14.0802
373.155	12.1239
376.715	11.972
380.273	9.9971
383.832	13.0567
387.388	14.1494
390.942	11.2209
394.495	10.9693
398.047	11.6004
401.597	9.98218
405.145	11.6764
408.693	12.4446
412.239	14.6503
415.783	12.8089
419.327	12.1076
422.869	13.624
426.409	14.5945
429.948	13.5521
433.486	12.0374
437.022	13.4136
440.558	12.7771
444.089	14.2403
447.622	12.6488
451.153	13.3069
454.682	13.1338
458.208	13.9906
461.735	17.064
465.259	18.8687
468.783	20.0273
472.306	20.8867
475.825	21.6172
479.346	22.4746
482.862	24.684
486.38	25.8639
489.894	29.253
493.407	30.3248
496.92	33.8623
500.43	34.8376
503.939	36.4772
507.448	38.2179
510.954	40.6469
514.459	42.7024
517.962	41.2043
521.466	41.6908
524.966	42.3521
528.466	41.7679
531.964	40.3326
535.46	37.2821
538.955	35.3157
542.449	34.1018
545.942	34.556
549.433	31.1219
552.923	24.9244
556.412	24.008
559.899	21.6029
563.385	19.3924
566.867	18.502
570.35	16.6057
573.832	16.3254
577.313	13.2436
580.79	12.1343
584.268	12.2687
587.745	11.263
591.218	9.22202
594.692	7.14122
598.164	8.00517
601.634	4.82819
605.104	4.43788
608.57	6.20584
612.037	3.33417
615.501	2.34363
618.966	1.49565
622.427	1.61532
625.887	-0.000421072
629.348	1.8284
632.806	1.48571
636.262	1.84618
639.716	1.16544
643.172	2.30532
646.624	3.14867
650.075	6.75829
653.524	6.22004
656.972	8.45946
660.419	9.43755
663.865	10.9983
667.309	12.572
670.752	13.2989
674.194	12.3107
677.634	11.6654
681.073	12.1227
684.511	11.2049
687.947	12.5607
691.382	13.2859
694.816	12.0366
698.247	10.2886
701.678	8.52731
705.108	7.70241
708.534	8.34364
711.962	10.0377
715.388	11.1812
718.81	10.3807
722.234	8.59315
725.654	6.87861
729.075	7.69604
732.492	9.16076
735.91	12.0463
739.325	14.5768
742.741	19.3321
746.153	21.9523
749.564	24.9221
752.976	30.8051
756.385	35.2051
759.792	38.2218
763.2	39.7407
766.604	43.677
770.008	49.7245
773.41	51.6278
776.811	52.4771
780.21	55.6531
783.608	59.8692
787.005	65.7993
790.401	70.3082
793.795	71.4429
797.188	74.2347
800.58	74.4944
803.971	74.0191
807.36	75.513
810.748	76.0905
814.135	76.0071
817.518	78.0099
820.902	80.6863
824.285	81.0355
827.665	81.1438
831.045	82.9472
834.424	83.4971
837.8	82.8639
841.177	80.1482
844.55	78.6616
847.924	77.5132
851.295	76.2781
854.666	75.1771
858.034	73.0744
861.403	75.6554
864.769	77.7526
868.133	77.7195
871.498	75.9366
874.86	75.2299
878.221	74.5086
881.58	72.6842
884.938	71.0333
888.297	69.4461
891.653	65.5429
895.007	64.3109
898.36	62.3768
901.712	63.0797
905.063	61.3847
908.412	60.2636
911.76	59.9797
915.107	58.3169
918.452	53.8793
921.797	51.1965
925.138	51.6106
928.48	52.5878
931.82	49.9495
935.16	48.7022
938.496	46.8983
941.833	44.0781
945.168	39.755
948.5	37.3387
951.834	34.5152
955.163	31.5732
958.494	27.7884
961.821	23.6796
965.15	18.2263
968.474	17.5929
971.8	16.3275
975.123	16.5413
978.446	16.9195
981.766	18.0707
985.084	18.4148
988.402	18.0182
991.72	18.4545
995.035	16.6526
998.349	17.332
1001.66	20.1336
1004.97	23.8461
1008.28	30.9517
1011.59	37.8929
1014.9	40.8992
1018.21	44.8071
1021.51	52.1982
1024.81	60.717
1028.12	72.9278
1031.42	86.2889
1034.72	92.8597
1038.02	101.777
1041.31	109.537
1044.61	117.735
1047.91	125.948
1051.2	131.726
1054.49	135.653
1057.78	137.794
1061.07	137.676
1064.36	135.755
1067.65	131.845
1070.93	126.439
1074.22	120.225
1077.5	113.249
1080.78	105.674
1084.06	96.1205
1087.34	86.1133
1090.62	83.0224
1093.9	79.0347
1097.17	75.9236
1100.45	76.9394
1103.72	79.265
1106.99	81.0557
1110.27	81.4458
1113.53	79.0044
1116.8	75.9993
1120.07	75.4648
1123.33	71.9526
1126.6	68.0514
1129.86	64.0381
1133.12	58.713
1136.38	56.3415
1139.64	51.5542
1142.9	48.2204
1146.16	44.787
1149.41	38.866
1152.67	34.7415
1155.92	27.9049
1159.17	21.8765
1162.42	16.5536
1165.67	12.5662
1168.92	13.4455
1172.16	15.1716
1175.41	16.3041
1178.65	15.0227
1181.9	13.9948
1185.14	13.2379
1188.38	12.682
1191.62	12.0905
1194.86	11.4106
1198.09	10.7609
1201.33	9.79122
1204.56	9.46323
1207.8	10.0378
1211.03	12.1742
1214.26	14.995
1217.49	19.2354
1220.71	22.7419
1223.94	28.3824
1227.16	32.8785
1230.39	35.3584
1233.61	40.5211
1236.83	45.4646
1240.05	52.4429
1243.27	59.0173
1246.49	63.0185
1249.71	64.1899
1252.92	63.9491
1256.14	65.8999
1259.35	72.1287
1262.56	85.282
1265.77	98.6539
1268.98	113.951
1272.19	129.047
1275.4	143.301
1278.6	155.768
1281.81	166.962
1285.01	179.907
1288.21	187.066
1291.41	192.785
1294.61	198.52
1297.81	200.599
1301.01	201.548
1304.2	200.067
1307.4	195.318
1310.59	189.404
1313.78	183.519
1316.97	173.755
1320.16	163.002
1323.35	150.753
1326.54	138.218
1329.72	124.713
1332.91	115.867
1336.09	112.432
1339.27	110.714
1342.45	110.45
1345.64	109.402
1348.81	108.976
1351.99	106.18
1355.17	103.622
1358.34	101.346
1361.51	99.5995
1364.69	97.5762
1367.86	93.605
1371.03	91.9768
1374.2	91.8068
1377.37	91.2582
1380.53	91.8945
1383.7	90.4003
1386.86	92.9663
1390.02	96.0409
1393.19	95.474
1396.35	94.4207
1399.51	97.7704
1402.66	109.665
1405.82	126.89
1408.97	150.767
1412.13	173.826
1415.28	199.401
1418.43	227.692
1421.59	255.553
1424.73	283.794
1427.88	312.035
1431.03	337.517
1434.18	362.781
1437.32	384.253
1440.46	400.042
1443.61	410.875
1446.75	417.586
1449.89	417.144
1453.03	409.2
1456.16	392.882
1459.3	372.126
1462.44	346.231
1465.57	313.107
1468.7	276.812
1471.83	240.68
1474.96	209.499
1478.09	183.183
1481.22	159.879
1484.35	138.593
1487.47	116.682
1490.6	94.9664
1493.72	78.5409
1496.84	64.8889
1499.96	54.6164
1503.08	47.4015
1506.2	43.5064
1509.32	41.8
1512.44	38.7571
1515.55	36.0587
1518.66	37.464
1521.78	38.069
1524.89	37.4872
1528	36.9507
1531.11	37.2532
1534.21	38.4914
1537.32	40.929
1540.43	40.6554
1543.53	41.0909
1546.63	44.2743
1549.74	46.5916
1552.84	47.4471
1555.94	49.495
1559.03	51.446
1562.13	52.0663
1565.23	54.5016
1568.32	58.3331
1571.42	61.4036
1574.51	67.6693
1577.6	71.0677
1580.69	74.0945
1583.78	79.6328
1586.87	81.6861
1589.95	83.9774
1593.04	88.6602
1596.12	91.3731
1599.21	92.6679
1602.29	94.0427
1605.37	96.9842
1608.45	97.5084
1611.53	99.0868
1614.6	96.8071
1617.68	95.9977
1620.75	94.0831
1623.83	93.2137
1626.9	91.7971
1629.97	90.5302
1633.04	88.996
1636.11	87.7043
1639.18	87.8269
1642.25	88.8963
1645.31	89.1045
1648.38	88.4006
1651.44	89.7366
1654.5	88.9161
1657.56	88.2491
1660.62	87.9559
1663.68	83.1199
1666.74	80.0076
1669.8	77.2547
1672.85	74.8322
1675.91	72.227
1678.96	67.7522
1682.01	63.6937
1685.06	61.3088
1688.11	57.5628
1691.16	52.988
1694.21	49.5768
1697.25	47.1631
1700.3	45.6885
1703.34	44.8158
1706.39	44.1395
1709.43	43.1486
1712.47	41.8691
1715.51	41.2977
1718.54	40.5394
1721.58	39.6056
1724.62	38.6798
1727.65	37.7709
1730.68	36.4831
1733.72	33.8583
1736.75	32.181
1739.78	29.7364
1742.81	28.7698
1745.84	27.6192
1748.86	25.289
1751.89	22.4993
1754.91	21.1839
1757.93	19.7034
1760.96	17.8396
1763.98	14.8635
1767	12.2393
1770.02	12.1075
1773.03	11.6412
1776.05	11.4367
1779.07	10.474
1782.08	9.05915
1785.09	8.30525
1788.11	7.30497
1791.12	5.99956
1794.13	4.20857
1797.13	3.01607
1800.14	2.55758
1803.15	3.17576
1806.15	2.36618
1809.16	2.13577
1812.16	2.01243
1815.16	2.365
1818.16	2.59096
1821.16	1.66204
1824.16	0.949977
1827.16	2.2546
1830.16	1.98536
1833.15	1.58695
1836.14	1.84209
1839.14	1.86493
1842.13	1.50891
1845.12	2.90462
1848.11	3.45268
1851.1	4.18934
1854.08	3.93391
1857.07	3.25334
1860.05	3.8994
1863.04	3.17754
1866.02	2.93283
1869	2.07708
1871.98	1.42077
1874.96	2.83794
1877.94	4.01608
1880.92	5.04888
1882.51	6.1505
1885.5	6.90997
1888.48	6.67536
1891.47	5.77999
1894.46	4.93969
1897.44	5.2466
1900.42	3.79262
1903.41	2.39564
1906.39	3.20598
1909.37	3.93316
1912.35	3.99762
1915.32	6.0976
1918.3	6.36894
1921.27	6.13895
1924.25	6.51409
1927.22	6.81666
1930.19	6.90566
1933.17	8.60586
1936.14	6.70543
1939.11	6.05198
1942.07	6.21674
1945.04	7.9417
1948.01	9.75305
1950.97	11.3912
1953.93	11.4895
1956.9	10.4257
1959.86	9.64234
1962.82	7.84766
1965.78	9.13598
1968.74	8.91776
1971.69	8.43815
1974.65	8.97546
1977.6	8.56451
1980.56	9.1566
1983.51	8.34592
1986.46	8.14386
1989.41	7.45227
1992.36	7.35192
1995.31	7.46941
1998.26	7.4614
2001.2	9.03059
2004.15	8.91955
2007.09	7.64321
2010.04	6.30599
2012.98	6.65853
2015.92	7.37042
2018.86	6.46613
2021.8	6.54332
2024.73	6.59604
2027.67	6.35078
2030.61	7.08308
2033.54	7.10261
2036.47	9.26538
2039.4	9.15408
2042.33	8.603
2045.27	9.66306
2048.19	9.65691
2051.12	9.75331
2054.05	10.8829
2056.97	12.563
2059.9	14.016
2062.82	15.6246
2065.74	16.4622
2068.67	16.7781
2071.59	17.9614
2074.51	20.4824
2077.42	19.529
2080.34	19.9759
2083.26	20.8155
2086.17	21.4846
2089.09	22.1048
2092	20.3672
2094.91	21.1607
2097.82	20.421
2100.73	19.6726
2103.64	18.2121
2106.55	19.1519
2109.45	17.7092
2112.36	18.3468
2115.26	17.5802
2118.17	17.3615
2121.07	16.6839
2123.97	18.5813
2126.87	19.4185
2129.77	20.6261
2132.67	22.144
2135.56	23.6742
2138.46	23.8167
2141.35	27.2001
2144.25	30.5785
2147.14	32.8823
2150.03	35.5454
2152.92	37.9249
2155.81	41.6324
2158.7	44.1304
2161.59	46.9436
2164.47	48.4605
2167.36	49.8598
2170.24	52.4414
2173.13	53.7756
2176.01	55.1509
2178.89	56.7281
2181.77	56.8309
2184.65	55.5842
2187.53	53.9306
2190.4	51.5824
2193.28	50.6746
2196.16	50.0723
2199.03	47.577
2201.9	44.7359
2204.77	41.5068
2207.64	39.0312
2210.51	36.4386
2213.38	34.4017
2216.25	31.7863
2219.12	29.9995
2221.98	27.3226
2224.85	25.9782
2227.71	26.0782
2230.57	26.2906
2233.43	24.9164
2236.29	25.1994
2239.15	25.0894
2242.01	25.075
2244.87	23.8518
2247.72	22.1599
2250.58	22.3011
2253.43	22.4582
2256.29	21.9223
2259.14	21.0018
2261.99	20.6764
2264.84	19.7859
2267.69	18.4582
2270.53	16.5613
2273.38	14.225
2276.23	12.999
2279.07	11.4986
2281.91	10.7274
2284.76	9.83794
2287.6	8.67861
2290.44	7.5872
2293.28	6.04934
2296.12	7.66021
2298.96	9.72117
2301.79	9.75082
2304.63	10.0736
2307.46	9.28348
2310.3	7.45833
2313.13	6.05682
2315.96	4.65374
2318.79	5.19729
2321.62	7.46837
2324.45	7.35895
2327.27	7.20859
2330.1	6.91468
2332.92	6.25615
2335.75	5.79904
2338.57	3.94499
2341.39	4.42904
2344.21	3.31005
2347.04	4.15409
2349.85	3.97816
2352.67	3.66976
2355.49	4.60694
2358.3	4.76902
2361.12	5.28742
2363.93	6.56882
2366.75	8.19526
2369.56	7.79869
2372.37	6.98848
2375.18	5.78358
2377.99	5.39969
2380.8	4.02215
2383.6	4.90239
2386.41	4.68696
2389.21	5.88668
2392.02	4.71885
2394.82	5.8264
2397.62	4.35412
2400.42	4.13895
2403.22	3.80204
2406.02	4.7301
2408.82	4.61634
2411.62	6.54709
2414.41	7.39656
2417.21	8.23809
2420	9.86007
2422.79	11.1734
2425.59	12.395
2428.38	12.1975
2431.17	13.4232
2433.95	13.4409
2436.74	12.6691
2439.53	12.6727
2442.31	13.3997
2445.1	13.7595
2447.88	12.6133
2450.67	11.6765
2453.45	10.4702
2456.23	10.3832
2459.01	10.5427
2461.79	8.98856
2464.57	7.89164
2467.34	6.58062
2470.12	6.53428
2472.89	6.87773
2475.67	6.64418
2478.44	6.27252
2481.21	6.94547
2483.98	6.12953
2486.75	5.51951
2489.52	5.52398
2492.29	3.94944
2495.05	2.90335
2497.82	2.78765
2500.58	1.35765
2503.35	0.275566
2506.11	1.07654
2508.87	1.68222
2511.63	2.21048
2514.39	1.26787
2517.15	1.57892
2519.91	1.33397
2522.67	2.54315
2525.42	3.4924
2528.18	3.29749
2530.93	4.1461
2533.69	5.46338
2536.44	6.2501
2539.19	7.45074
2541.94	7.43832
2544.69	7.76828
2547.44	7.90868
2550.18	8.53898
2552.93	7.51158
2555.67	7.9386
2558.42	7.73389
2561.16	7.73467
2563.9	6.2233
2566.64	7.58866
2569.38	9.457
2572.12	10.7962
2574.86	12.3078
2577.6	13.0861
2580.33	14.3742
2583.07	15.7478
2585.8	15.97
2588.54	17.8016
2591.27	18.4139
2594	19.3489
2596.73	17.4535
2599.46	16.8218
2602.19	15.246
2604.92	12.33
2607.64	11.4937
2610.37	10.1436
2613.09	9.39329
2615.82	9.28714
2618.54	10.0204
2621.26	8.77834
2623.98	9.26234
2626.7	8.1843
2629.42	8.02452
2632.14	8.6244
2634.86	10.7218
2637.57	12.4315
2640.29	13.5192
2643	14.7551
2645.71	15.4181
2648.43	16.2891
2651.14	16.3671
2653.85	16.708
2656.56	17.3623
2659.26	16.4983
2661.97	15.2442
2664.68	14.4208
2667.38	14.5427
2670.09	13.6741
2672.79	14.417
2675.49	13.9546
2678.19	15.2192
2680.89	16.7735
2683.59	17.7821
2686.29	19.8301
2688.99	21.3976
2691.69	23.5511
2694.38	27.0626
2697.08	32.1138
2699.77	38.2648
2702.46	43.3597
2705.15	46.8487
2707.85	50.734
2710.54	52.5627
2713.22	56.1828
2715.91	58.9191
2718.6	59.7201
2721.29	61.1279
2723.97	60.8941
2726.66	58.4949
2729.34	57.0001
2732.02	54.2557
2734.7	50.2255
2737.38	45.3081
2740.06	40.0025
2742.74	33.3283
2745.42	28.717
2748.09	23.1037
2750.77	18.8037
2753.45	14.8616
2756.12	10.8504
2758.79	8.40862
2761.46	6.58758
2764.14	4.61537
2766.8	2.91323
2769.47	0.769376
2772.14	-0.107853
2774.81	-1.14272
2777.48	-2.24149
2780.14	-2.38315
2782.8	-1.8227
2785.47	-1.08225
2788.13	-1.54357
2790.79	-1.62413
2793.45	-1.89583
2796.11	-0.633465
2798.77	-1.38376
2801.43	-2.18737
2804.09	-4.70095
2806.74	-7.98821
2809.4	-13.1366
2812.05	-14.0135
2814.71	-6.79369
2817.36	10.9025
2820.01	39.3551
2822.66	78.8586
2825.31	123.895
2827.96	175.564
2830.6	230.403
2833.25	285.411
2835.9	343.493
2838.54	401.001
2841.18	454.537
2843.83	500.987
2846.47	546.216
2849.11	595.836
2851.75	650.918
2854.39	708.529
2857.03	761.714
2859.66	808.86
2862.3	847.721
2864.94	874.507
2867.57	892.737
2870.2	903.45
2872.84	909.272
2875.47	914.779
2878.1	923.74
2880.73	933.78
2883.36	942.171
2885.99	947.11
2888.61	949.031
2891.24	944.714
2893.86	935.333
2896.49	921.696
2899.11	908.252
2901.73	891.679
2904.36	873.932
2906.98	858.933
2909.6	850.549
2912.21	855.141
2914.83	865.978
2917.45	876.863
2920.07	881.014
2922.68	877.468
2925.29	870.696
2927.91	859.044
2930.52	843.094
2933.13	824.175
2935.74	803.864
2938.35	779.666
2940.96	750.391
2943.57	720.176
2946.18	686.277
2948.78	650.463
2951.39	613.457
2953.99	574.321
2956.59	537.171
2959.2	500.843
2961.8	466.596
2964.4	435.864
2967	405.864
2969.6	377.677
2972.19	352.436
2974.79	328.29
2977.39	303.169
2979.98	277.058
2982.58	250.259
2985.17	222.682
2987.76	197.748
2990.35	173.011
2992.94	150.467
2995.53	128.94
2998.12	109.46
3000.71	91.959
3003.3	76.0857
3005.88	62.0578
3008.47	49.1144
3011.05	38.8927
3013.64	29.5526
3016.22	21.3403
3018.8	15.5062
3021.38	9.3622
3023.96	5.77104
3026.54	3.05115
3029.12	1.45999
3031.69	-1.1377
3034.27	-3.75101
3036.84	-3.54143
3039.42	-3.90799
3041.99	-3.17931
3044.57	-1.77048
3047.14	-0.451692
3049.71	0.992886
3052.28	2.03797
3054.85	3.68942
3057.41	3.79649
3059.98	3.9444
3062.55	4.82716
3065.11	5.92424
3067.68	8.33821
3070.24	9.10782
3072.8	11.0591
3075.36	12.1815
3077.93	13.7454
3080.49	15.6747
3083.04	16.5071
3085.6	17.7552
3088.16	19.3629
3090.72	21.7351
3093.27	23.0045
3095.83	24.5289
3098.38	26.7902
3100.93	29.7729
3103.49	32.2153
3106.04	34.7961
3108.59	39.2103
3111.14	42.3198
3113.69	46.6191
3116.23	50.1722
3118.78	54.5089
3121.33	58.2575
3123.87	62.6991
3126.41	68.4009
3128.96	75.5558
3131.5	80.9061
3134.04	86.6184
3136.58	92.2347
3139.12	98.6717
3141.66	104.966
3144.2	111.119
3146.74	116.948
3149.27	120.855