File: data/Raman/poly_smoothed/Mb_20_x_02_1x_45s_532 nm_x100_100%_600 gr_mm_01.txt
#Acq. time (s)=	45
#Accumulations=	2
#Range (cm-¹)=	200...3150
#Windows=	2
#Auto scanning=	Off
#Autofocus=	Off
#Macrospot=	Off
#AutoExposure=	Off
#Spike filter=	Multiple accum.
#Delay time (s)=	0
#Binning=	1
#Readout mode=	Signal
#DeNoise=	Off
#ICS correction=	On
#Dark correction=	Off
#Inst. Process=	Off
#Detector Gain=	Best Dynamic Range
#Detector ADC=	20 kHz
#Detector temperature (°C)=	-70.08
#Instrument=	LabRAM HR Evol
#Detector=	Synapse
#Objective=	x100
#Grating=	600 gr/mm
#ND Filter=	100%
#Laser (nm)=	532
#Hole=	100.021
#Range=	Auto
#Laser Pol.=	No
#Raman. Pol.=	No
#Laser Pol. (°)=	-0.0007625
#Raman Pol. (°)=	89.9995
#Collection=	Microscope
#StageXY=	Marzhauser
#StageZ=	Marzhauser
#X (µm)=	-798.1
#Y (µm)=	2674.4
#Z (µm)=	584.55
#Full time(mm:ss)=	3:18
#Project=
#Sample=
#Site=
#Title=	Mb_20_x_02_2x_45s_532 nm_x100_100%_600 gr_mm
#Remark=
#Date=	18.07.2022 14:33
#Acquired=	18.07.2022 14:33:00
#Base:Fit=	16.08.2022 10:28:40
#Base:Fit=	16.08.2022 10:28:53
#Base:Fit=	16.08.2022 10:29:09
#Base:Fit=	16.08.2022 10:29:17
#Base:Fit=	16.08.2022 10:29:25
#Base:Fit=	16.08.2022 10:29:33
#Base:Sub=	16.08.2022 10:29:38
#Filter:Polynom=	16.08.2022 10:30:49
#AxisType[0]=Intens
#AxisUnit[0]=Cnt
#AxisType[1]=Spectr
#AxisUnit[1]=1/cm
200.419	8.48128
204.048	8.1279
207.678	8.23898
211.304	7.68416
214.928	5.8573
218.554	6.82769
222.176	7.33395
225.798	7.46991
229.417	8.97559
233.035	10.614
236.653	9.62364
240.268	10.4753
243.881	10.058
247.493	9.38866
251.103	9.89156
254.715	8.23898
258.322	9.09508
261.929	11.2041
265.534	13.2881
269.137	13.9568
272.739	13.329
276.34	14.5913
279.939	14.7886
283.537	15.566
287.134	15.6252
290.729	18.0442
294.323	19.6739
297.913	21.0335
301.504	22.4912
305.093	22.1335
308.682	23.2477
312.268	24.0053
315.852	25.0296
319.436	27.114
323.018	26.304
326.597	26.6931
330.177	27.7034
333.753	27.3496
337.331	29.0067
340.906	28.1264
344.478	28.9428
348.051	28.5139
351.621	28.6496
355.189	26.3978
358.757	25.7993
362.323	25.0176
365.889	25.633
369.451	25.8643
373.012	25.8075
376.574	25.7818
380.133	25.7136
383.69	23.7726
387.245	21.8634
390.8	19.1169
394.353	18.3954
397.906	20.3299
401.456	21.1904
405.005	20.7167
408.552	21.6073
412.099	21.5177
415.643	21.545
419.187	20.5545
422.728	18.5812
426.269	16.8052
429.806	15.0569
433.344	13.5943
436.881	12.874
440.416	13.0805
443.949	11.6051
447.48	11.8233
451.011	11.2971
454.541	11.291
458.069	10.5008
461.594	11.7767
465.119	10.2512
468.642	10.3996
472.165	11.7058
475.684	13.3477
479.204	14.9647
482.721	17.0412
486.239	18.8928
489.753	20.8643
493.268	22.212
496.779	22.5187
500.289	21.6378
503.8	22.1558
507.307	20.7921
510.813	20.266
514.32	18.3575
517.823	19.4064
521.325	19.2598
524.826	20.6954
528.325	19.5452
531.823	18.8923
535.32	17.4908
538.815	16.7512
542.309	16.217
545.802	15.9374
549.293	15.7916
552.783	13.1683
556.271	11.932
559.759	11.174
563.245	10.8483
566.729	8.71342
570.213	8.14564
573.693	8.29788
577.173	7.61387
580.652	6.03667
584.13	5.74245
587.605	5.89509
591.08	6.65012
594.552	6.02047
598.025	5.80135
601.496	6.48431
604.964	6.95307
608.433	6.74354
611.898	8.19156
615.364	7.24507
618.827	7.0425
622.288	7.98745
625.75	8.63511
629.209	7.16551
632.667	6.822
636.125	8.52849
639.58	5.86737
643.033	5.52684
646.485	6.36369
649.936	6.45051
653.388	7.7796
656.836	8.78243
660.283	8.6047
663.728	10.5358
667.173	12.0595
670.616	13.4084
674.057	16.4604
677.498	15.9679
680.937	15.3297
684.375	14.2136
687.809	14.9445
691.244	14.1921
694.678	15.7148
698.111	16.0476
701.54	16.387
704.97	18.7702
708.398	19.7063
711.826	19.289
715.25	21.9833
718.675	23.6634
722.096	26.3916
725.518	26.0247
728.937	29.2014
732.357	31.8139
735.773	33.5337
739.19	35.7532
742.604	37.7697
746.018	39.0782
749.429	40.0194
752.839	41.8547
756.248	44.1442
759.657	44.5805
763.063	44.7564
766.468	45.4518
769.871	47.7307
773.273	48.8881
776.676	50.0467
780.075	50.6991
783.474	53.4773
786.871	54.3441
790.266	54.8022
793.661	56.4656
797.054	57.3298
800.446	59.4502
803.834	60.3378
807.224	61.3321
810.612	62.2089
813.998	62.3345
817.384	62.5181
820.766	62.6879
824.149	62.1782
827.531	61.5537
830.909	59.8675
834.288	58.9652
837.666	58.1733
841.041	57.0441
844.416	56.225
847.788	53.3297
851.161	52.2142
854.53	51.2049
857.901	49.1509
861.268	45.5326
864.633	43.4112
868	40.5854
871.363	39.5952
874.725	38.891
878.088	38.606
881.447	38.0309
884.805	35.8521
888.162	36.7827
891.518	36.9296
894.872	36.7837
898.225	36.0001
901.577	35.4839
904.928	35.9521
908.277	34.9849
911.625	35.6209
914.972	35.1644
918.318	33.8767
921.662	34.347
925.005	33.4628
928.347	33.7779
931.686	33.6679
935.025	33.2876
938.363	32.329
941.698	30.6574
945.034	27.8688
948.368	26.2892
951.699	26.3222
955.031	25.4658
958.36	24.7299
961.689	23.3934
965.016	20.8851
968.343	21.2795
971.666	22.2762
974.991	20.3793
978.312	19.119
981.632	17.974
984.953	18.0632
988.27	16.8644
991.587	16.2827
994.902	16.614
998.216	15.6629
1001.53	13.2167
1004.84	12.2804
1008.15	12.9503
1011.46	17.1981
1014.77	25.5014
1018.07	31.5025
1021.38	39.0606
1024.68	44.8632
1027.99	49.4537
1031.29	55.3079
1034.59	59.7072
1037.89	62.7591
1041.18	63.6962
1044.48	64.862
1047.77	64.6809
1051.07	64.2527
1054.36	61.4565
1057.65	56.7533
1060.94	53.4604
1064.23	47.2872
1067.52	41.1172
1070.8	33.8633
1074.09	26.0718
1077.37	18.5013
1080.65	11.9421
1083.93	7.24706
1087.21	6.66411
1090.49	8.75641
1093.77	10.1794
1097.04	12.4553
1100.32	11.9861
1103.59	14.6613
1106.86	14.8395
1110.13	14.7367
1113.4	15.8536
1116.67	15.6335
1119.94	15.8176
1123.2	16.248
1126.47	16.6197
1129.73	17.8809
1132.99	18.0012
1136.25	18.5269
1139.51	18.0625
1142.77	18.2348
1146.03	16.9133
1149.28	15.5511
1152.54	15.2365
1155.79	14.4622
1159.04	13.6001
1162.29	11.7924
1165.54	11.2357
1168.79	11.1549
1172.04	10.7758
1175.28	9.44464
1178.53	8.34704
1181.77	8.1203
1185.01	6.99984
1188.25	5.6512
1191.49	6.89546
1194.73	7.65274
1197.96	8.28474
1201.2	9.52113
1204.43	10.2999
1207.66	12.5041
1210.9	13.9075
1214.13	16.2126
1217.36	19.6274
1220.58	20.4768
1223.81	22.5446
1227.04	24.3071
1230.26	24.4002
1233.48	27.434
1236.71	28.715
1239.93	30.9741
1243.14	32.989
1246.36	35.2403
1249.58	36.9276
1252.8	36.3293
1256.01	35.5332
1259.22	37.9938
1262.43	38.6022
1265.64	37.4458
1268.85	38.0477
1272.06	39.1966
1275.27	38.8375
1278.48	38.5447
1281.68	37.8267
1284.88	39.7129
1288.08	40.2499
1291.28	41.1978
1294.48	41.9132
1297.68	43.4672
1300.88	43.6062
1304.07	44.3454
1307.27	44.6315
1310.46	45.9814
1313.65	48.4343
1316.85	50.1012
1320.03	52.157
1323.22	54.3045
1326.41	56.6874
1329.6	56.318
1332.78	57.5812
1335.96	58.8252
1339.15	58.9686
1342.33	57.6794
1345.51	56.561
1348.69	55.5401
1351.86	54.0963
1355.04	52.8564
1358.21	50.4327
1361.39	50.4614
1364.56	49.6518
1367.73	47.065
1370.9	43.8659
1374.07	42.9403
1377.24	41.2866
1380.41	39.3426
1383.57	39.1624
1386.73	39.436
1389.9	39.8241
1393.06	39.8169
1396.22	40.1035
1399.38	41.1076
1402.54	39.9543
1405.69	39.9632
1408.85	40.367
1412	41.4054
1415.16	43.3314
1418.31	44.2313
1421.46	47.0017
1424.61	48.9182
1427.76	51.9071
1430.9	55.6725
1434.05	58.0517
1437.2	61.0541
1440.34	63.0593
1443.48	64.7974
1446.62	65.8746
1449.76	66.0109
1452.9	66.041
1456.04	65.3993
1459.17	65.6703
1462.31	66.3704
1465.44	66.2882
1468.58	65.5148
1471.71	64.5182
1474.84	62.7556
1477.97	59.4073
1481.1	56.752
1484.22	56.2681
1487.35	52.7937
1490.47	51.0565
1493.59	49.3055
1496.72	47.556
1499.84	45.385
1502.96	43.7673
1506.08	42.3002
1509.19	39.6326
1512.31	37.4253
1515.42	35.4282
1518.54	32.9493
1521.65	29.5316
1524.76	26.9629
1527.87	24.4919
1530.98	21.947
1534.09	21.3953
1537.2	22.4471
1540.3	21.9749
1543.41	22.4262
1546.51	22.6989
1549.61	22.34
1552.71	22.5236
1555.81	22.7788
1558.91	23.0159
1562.01	23.0675
1565.1	22.7734
1568.2	25.1131
1571.29	25.1674
1574.38	28.5725
1577.48	31.229
1580.57	34.0747
1583.65	36.0385
1586.74	36.9366
1589.83	39.7159
1592.92	40.925
1596	41.76
1599.08	42.5122
1602.16	43.0784
1605.24	42.6126
1608.32	43.0634
1611.4	42.7218
1614.48	42.4006
1617.56	42.9665
1620.63	42.7799
1623.71	43.6388
1626.78	42.5962
1629.85	43.7735
1632.92	43.4961
1635.99	43.3768
1639.06	45.4917
1642.12	44.5773
1645.19	45.1379
1648.25	46.1093
1651.32	48.3038
1654.38	47.5806
1657.44	47.3985
1660.5	46.7313
1663.56	45.4054
1666.62	44.1455
1669.67	41.9642
1672.73	40.1402
1675.79	37.7215
1678.84	33.9846
1681.89	30.897
1684.94	27.5639
1687.99	24.7011
1691.04	22.4523
1694.08	20.5823
1697.13	17.9774
1700.18	15.4357
1703.22	13.7462
1706.26	12.2689
1709.3	10.0936
1712.35	9.15793
1715.39	8.20186
1718.42	6.95884
1721.46	6.08946
1724.5	6.69067
1727.53	6.61907
1730.56	6.74563
1733.6	6.90801
1736.63	6.06849
1739.66	5.92434
1742.69	5.80928
1745.71	4.89915
1748.74	4.69522
1751.77	3.06146
1754.79	3.20569
1757.81	2.47901
1760.84	2.41732
1763.86	2.32206
1766.88	1.30244
1769.9	0.975103
1772.91	0.480222
1775.93	0.423785
1778.95	0.88546
1781.96	1.05918
1784.97	1.0392
1787.99	1.04923
1791	1.21711
1794.01	1.36927
1797.01	1.82335
1800.02	3.14984
1803.03	3.3559
1806.03	3.31295
1809.04	3.1879
1812.04	3.72551
1815.04	3.60866
1818.04	3.14448
1821.04	3.15676
1824.04	2.87477
1827.04	3.06813
1830.03	2.93145
1833.03	3.5872
1836.02	3.69496
1839.02	3.26837
1842.01	3.29163
1845	2.84838
1847.99	2.6086
1850.98	3.53172
1853.96	4.00721
1856.95	4.60548
1859.94	4.64594
1862.92	5.3023
1865.9	5.47619
1868.88	5.81468
1871.86	6.67119
1874.84	6.56471
1877.82	5.38983
1880.8	5.97834
1882.58	7.3997
1885.57	8.17553
1888.56	8.15813
1891.54	8.96529
1894.53	9.12686
1897.51	9.4063
1900.5	7.96081
1903.48	8.3863
1906.46	7.99525
1909.44	6.87616
1912.42	6.64647
1915.4	5.47096
1918.37	4.41893
1921.35	5.02519
1924.32	4.47862
1927.3	4.63436
1930.27	3.94575
1933.24	3.55705
1936.21	2.69769
1939.18	2.22394
1942.15	1.82129
1945.11	1.7164
1948.08	0.23773
1951.04	0.410921
1954.01	1.59878
1956.97	1.80555
1959.93	2.64178
1962.89	1.65785
1965.85	1.77586
1968.81	1.87174
1971.77	1.35885
1974.72	1.08667
1977.68	0.516505
1980.63	0.319624
1983.58	1.27275
1986.53	1.30079
1989.48	1.78052
1992.43	2.27878
1995.38	2.61062
1998.33	3.17758
2001.27	3.01486
2004.22	3.42616
2007.16	3.35768
2010.11	3.82656
2013.05	5.15612
2015.99	5.63115
2018.93	4.79163
2021.87	5.02671
2024.8	6.2514
2027.74	7.09179
2030.68	5.52805
2033.61	5.52255
2036.54	5.10757
2039.48	5.95118
2042.41	5.79946
2045.34	5.58927
2048.27	5.36311
2051.19	6.00974
2054.12	6.16791
2057.05	6.36153
2059.97	5.90439
2062.9	5.81472
2065.82	4.44651
2068.74	4.21077
2071.66	4.15088
2074.58	4.30699
2077.5	5.01733
2080.41	5.92367
2083.33	6.55918
2086.24	6.33938
2089.16	7.88997
2092.07	9.19089
2094.98	10.0754
2097.89	10.1667
2100.8	9.78098
2103.71	10.0463
2106.62	10.9823
2109.53	11.8554
2112.43	12.2648
2115.33	12.1215
2118.24	13.4824
2121.14	14.6866
2124.04	14.6527
2126.94	16.1802
2129.84	16.8049
2132.74	17.8737
2135.63	19.262
2138.53	20.2797
2141.43	21.5647
2144.32	22.9346
2147.21	22.6948
2150.1	24.2911
2152.99	25.4005
2155.88	26.4252
2158.77	28.1126
2161.66	29.3814
2164.55	28.4596
2167.43	28.9088
2170.31	30.3416
2173.2	29.928
2176.08	30.3167
2178.96	29.6405
2181.84	30.1351
2184.72	30.4011
2187.6	30.5833
2190.47	31.1848
2193.35	29.0739
2196.23	28.6164
2199.1	27.5744
2201.97	28.6718
2204.84	28.352
2207.71	28.0292
2210.58	28.3125
2213.45	27.6569
2216.32	26.5132
2219.19	26.0582
2222.05	25.7734
2224.92	26.1321
2227.78	25.2285
2230.64	24.3197
2233.5	22.7046
2236.36	21.827
2239.22	21.1404
2242.08	21.4199
2244.94	19.5042
2247.79	19.0668
2250.65	18.3439
2253.5	17.0459
2256.36	15.5569
2259.21	13.8587
2262.06	11.8926
2264.91	9.58696
2267.76	9.47249
2270.6	10.5239
2273.45	10.0206
2276.3	9.61302
2279.14	8.5147
2281.98	7.96226
2284.83	7.43308
2287.67	8.31641
2290.51	9.03888
2293.35	8.24905
2296.19	8.55314
2299.02	8.46118
2301.86	8.18408
2304.7	8.40055
2307.53	9.29886
2310.36	9.21224
2313.2	9.80461
2316.03	9.46419
2318.86	9.9161
2321.69	9.77376
2324.51	9.5508
2327.34	9.47437
2330.17	8.9963
2332.99	8.94348
2335.82	7.84801
2338.64	8.34221
2341.46	6.87128
2344.28	5.82688
2347.1	5.27892
2349.92	3.59683
2352.74	3.59682
2355.56	3.88478
2358.37	3.60556
2361.19	1.88672
2364	1.05491
2366.82	1.76501
2369.63	1.50598
2372.44	0.954758
2375.25	0.614861
2378.06	-0.0329667
2380.86	-0.0663235
2383.67	0.566763
2386.48	0.961443
2389.28	1.61699
2392.09	2.185
2394.89	2.84378
2397.69	3.32975
2400.49	3.44724
2403.29	3.28661
2406.09	3.36759
2408.89	4.49364
2411.69	3.95361
2414.48	3.93188
2417.28	4.29197
2420.07	4.49337
2422.86	4.1608
2425.65	4.71164
2428.45	4.36953
2431.23	4.82259
2434.02	4.63323
2436.81	4.80385
2439.6	4.61565
2442.38	2.66423
2445.17	2.10256
2447.95	1.6611
2450.73	1.84683
2453.52	1.93317
2456.3	1.76523
2459.08	1.3518
2461.85	0.709241
2464.63	0.353047
2467.41	0.0103848
2470.19	-0.274981
2472.96	-0.693183
2475.73	-0.419975
2478.51	-1.11969
2481.28	-0.863537
2484.05	-0.610615
2486.82	-0.228392
2489.59	-1.06589
2492.35	-0.279884
2495.12	0.329949
2497.89	-0.174969
2500.65	0.425098
2503.42	0.396456
2506.18	0.0303361
2508.94	-0.837595
2511.7	-0.601864
2514.46	0.693095
2517.22	0.724903
2519.98	1.39711
2522.73	0.708447
2525.49	0.963412
2528.25	1.21647
2531	1.51002
2533.75	2.67732
2536.5	2.75376
2539.25	3.69919
2542.01	4.49162
2544.75	5.0524
2547.5	6.18837
2550.25	6.35993
2553	6.50679
2555.74	6.78615
2558.49	7.00198
2561.23	7.9569
2563.97	6.84726
2566.71	5.95343
2569.45	6.25572
2572.19	5.0949
2574.93	3.78061
2577.67	3.72288
2580.4	3.65339
2583.14	2.74447
2585.87	2.16587
2588.6	1.68036
2591.34	1.45917
2594.07	2.57499
2596.8	3.09129
2599.53	2.24102
2602.26	2.88578
2604.98	3.47682
2607.71	4.09418
2610.44	5.02994
2613.16	4.95623
2615.88	5.39389
2618.61	5.50859
2621.33	5.70945
2624.05	4.9655
2626.77	4.8219
2629.49	3.92831
2632.21	2.53301
2634.92	1.55048
2637.64	2.23378
2640.35	1.46997
2643.07	1.32019
2645.78	1.69105
2648.49	1.48621
2651.2	1.43663
2653.91	1.90999
2656.62	2.42349
2659.33	2.27093
2662.04	3.77842
2664.74	3.9669
2667.45	5.26334
2670.15	5.57732
2672.86	6.33553
2675.56	7.03831
2678.26	8.07368
2680.96	8.39663
2683.66	9.24652
2686.36	8.63392
2689.06	9.06363
2691.75	9.0311
2694.45	9.38757
2697.14	9.63067
2699.84	9.25274
2702.53	9.57207
2705.22	8.8075
2707.91	8.01323
2710.6	8.32232
2713.29	8.02625
2715.98	8.23281
2718.67	7.75295
2721.35	7.8927
2724.04	6.71521
2726.72	7.00059
2729.4	7.70331
2732.09	6.58421
2734.77	7.05541
2737.45	7.99846
2740.13	8.25372
2742.81	8.53389
2745.48	9.11459
2748.16	9.79251
2750.84	9.58631
2753.51	9.93039
2756.19	10.834
2758.86	11.1933
2761.53	11.1851
2764.2	10.826
2766.87	9.79741
2769.54	8.90249
2772.21	7.94544
2774.88	7.25436
2777.54	7.33157
2780.21	7.33971
2782.87	5.40021
2785.53	4.92434
2788.2	3.96716
2790.86	3.59675
2793.52	2.57126
2796.18	2.41172
2798.84	2.68176
2801.49	2.7198
2804.15	2.64379
2806.81	2.57828
2809.46	3.35555
2812.12	3.3609
2814.77	4.48884
2817.42	6.02046
2820.07	8.00739
2822.72	11.2678
2825.37	12.9188
2828.02	15.7721
2830.67	18.5538
2833.31	20.9404
2835.96	24.6207
2838.61	27.7501
2841.25	32.9588
2843.89	37.1379
2846.53	40.5845
2849.17	44.7844
2851.81	51.0322
2854.45	56.5915
2857.09	61.2751
2859.73	65.9096
2862.36	70.8164
2865	76.5006
2867.64	81.354
2870.27	84.3343
2872.9	87.8025
2875.53	91.2868
2878.16	94.9107
2880.79	98.0698
2883.42	99.9512
2886.05	103.017
2888.68	104.93
2891.3	107.888
2893.93	110.69
2896.55	113.162
2899.18	115.495
2901.8	118.198
2904.42	122.927
2907.04	127.128
2909.66	132.137
2912.28	138.03
2914.9	144.645
2917.51	151.299
2920.13	156.718
2922.74	161.688
2925.36	165.781
2927.97	168.768
2930.59	170.253
2933.2	171.49
2935.81	171.048
2938.42	170.538
2941.02	167.834
2943.63	164.527
2946.24	159.82
2948.85	154.512
2951.45	149.086
2954.05	142.654
2956.66	136.661
2959.26	129.789
2961.86	124.261
2964.46	118.054
2967.06	113.039
2969.66	108.598
2972.26	104.03
2974.85	98.1646
2977.45	93.1327
2980.05	89.0352
2982.64	84.308
2985.23	78.7851
2987.83	73.3052
2990.42	66.655
2993.01	61.836
2995.6	58.0855
2998.19	52.7889
3000.77	47.3813
3003.36	42.6098
3005.95	38.3058
3008.53	33.7626
3011.12	29.398
3013.7	25.7296
3016.28	23.6719
3018.86	20.8212
3021.44	18.8929
3024.02	17.8284
3026.6	16.1764
3029.18	16.5504
3031.76	15.3972
3034.33	15.7461
3036.91	15.577
3039.48	15.1334
3042.05	15.6397
3044.63	16.0476
3047.2	15.8314
3049.77	15.25
3052.34	14.8137
3054.91	14.0617
3057.48	14.4201
3060.04	13.7236
3062.61	11.9578
3065.17	9.80259
3067.74	9.0677
3070.3	8.12859
3072.87	6.23928
3075.43	5.53822
3077.99	5.11361
3080.55	4.78949
3083.11	3.55323
3085.67	2.29587
3088.22	1.64148
3090.78	1.96063
3093.34	2.2649
3095.89	2.83643
3098.44	2.81173
3101	2.73414
3103.55	2.60831
3106.1	3.50689
3108.65	3.66783
3111.2	3.80836
3113.75	4.3468
3116.3	5.45277
3118.84	6.06409
3121.39	6.83553
3123.93	6.3992
3126.48	6.47384
3129.02	6.90547
3131.56	7.70167
3134.1	8.0366
3136.64	9.03959
3139.18	9.54195
3141.72	9.80934
3144.26	8.48406
3146.8	7.97655
3149.33	7.94522