File: data/Raman/poly_smoothed/Mb_20_x_05_1x_45s_532 nm_x100_100%_600 gr_mm_01.txt
#Acq. time (s)=	45
#Accumulations=	2
#Range (cm-¹)=	200...3150
#Windows=	2
#Auto scanning=	Off
#Autofocus=	Off
#Macrospot=	Off
#AutoExposure=	Off
#Spike filter=	Multiple accum.
#Delay time (s)=	0
#Binning=	1
#Readout mode=	Signal
#DeNoise=	Off
#ICS correction=	On
#Dark correction=	Off
#Inst. Process=	Off
#Detector Gain=	Best Dynamic Range
#Detector ADC=	20 kHz
#Detector temperature (°C)=	-69.85
#Instrument=	LabRAM HR Evol
#Detector=	Synapse
#Objective=	x100
#Grating=	600 gr/mm
#ND Filter=	100%
#Laser (nm)=	532
#Hole=	100.021
#Range=	Auto
#Laser Pol.=	No
#Raman. Pol.=	No
#Laser Pol. (°)=	-0.0007625
#Raman Pol. (°)=	89.9995
#Collection=	Microscope
#StageXY=	Marzhauser
#StageZ=	Marzhauser
#X (µm)=	-812.1
#Y (µm)=	2707.4
#Z (µm)=	584.5
#Full time(mm:ss)=	3:18
#Project=
#Sample=
#Site=
#Title=	Mb_20_x_05_2x_45s_532 nm_x100_100%_600 gr_mm
#Remark=
#Date=	18.07.2022 14:46
#Acquired=	18.07.2022 14:46:55
#Base:Fit=	16.08.2022 10:28:40
#Base:Fit=	16.08.2022 10:28:53
#Base:Fit=	16.08.2022 10:29:09
#Base:Fit=	16.08.2022 10:29:17
#Base:Fit=	16.08.2022 10:29:25
#Base:Fit=	16.08.2022 10:29:33
#Base:Sub=	16.08.2022 10:29:38
#Filter:Polynom=	16.08.2022 10:30:49
#AxisType[0]=Intens
#AxisUnit[0]=Cnt
#AxisType[1]=Spectr
#AxisUnit[1]=1/cm
200.419	27.2634
204.048	22.8611
207.678	18.0057
211.304	14.3214
214.928	11.8392
218.554	8.34088
222.176	5.94966
225.798	5.59026
229.417	6.07807
233.035	7.08848
236.653	8.48722
240.268	9.29466
243.881	10.6515
247.493	11.8573
251.103	11.6799
254.715	11.8209
258.322	13.4466
261.929	15.4347
265.534	17.0402
269.137	18.0961
272.739	18.61
276.34	18.3654
279.939	18.0818
283.537	17.8961
287.134	17.1771
290.729	15.7249
294.323	16.1092
297.913	14.6053
301.504	14.4902
305.093	14.0762
308.682	13.4841
312.268	14.4714
315.852	15.0672
319.436	15.0767
323.018	14.4462
326.597	14.9286
330.177	14.8472
333.753	14.473
337.331	13.8039
340.906	12.7276
344.478	13.7351
348.051	14.6696
351.621	15.327
355.189	14.8308
358.757	15.0735
362.323	14.2389
365.889	14.9223
369.451	14.1217
373.012	13.8831
376.574	12.3725
380.133	13.5478
383.69	13.5727
387.245	13.1729
390.8	13.6071
394.353	11.8082
397.906	10.6628
401.456	10.1627
405.005	9.29724
408.552	8.41477
412.099	7.38278
415.643	8.66121
419.187	9.08486
422.728	9.67622
426.269	9.35662
429.806	10.9168
433.344	12.3837
436.881	12.6787
440.416	13.1475
443.949	13.0241
447.48	13.084
451.011	14.0373
454.541	15.1831
458.069	15.5213
461.594	16.9644
465.119	16.7387
468.642	17.293
472.165	17.6701
475.684	17.3327
479.204	16.5777
482.721	14.7048
486.239	14.6611
489.753	14.919
493.268	14.5273
496.779	15.8343
500.289	16.0965
503.8	16.2119
507.307	15.2083
510.813	14.9545
514.32	16.2255
517.823	16.9821
521.325	17.6758
524.826	18.8319
528.325	19.1939
531.823	19.806
535.32	19.7921
538.815	19.222
542.309	18.5751
545.802	17.7152
549.293	15.1058
552.783	13.6103
556.271	10.7443
559.759	9.49614
563.245	7.16421
566.729	6.32485
570.213	5.8818
573.693	4.66507
577.173	4.70008
580.652	4.46192
584.13	4.55104
587.605	3.98509
591.08	3.14819
594.552	3.48053
598.025	3.20381
601.496	5.32204
604.964	7.69569
608.433	9.47612
611.898	11.7709
615.364	11.7496
618.827	12.1364
622.288	12.6285
625.75	12.0627
629.209	12.9935
632.667	12.2525
636.125	11.4528
639.58	11.0082
643.033	11.2918
646.485	11.6223
649.936	12.8565
653.388	12.4295
656.836	10.8003
660.283	10.3716
663.728	11.0433
667.173	11.0053
670.616	12.2534
674.057	11.924
677.498	13.6544
680.937	15.6049
684.375	17.1
687.809	20.1731
691.244	22.3257
694.678	24.998
698.111	26.5766
701.54	28.9982
704.97	31.7773
708.398	35.4246
711.826	36.9992
715.25	39.2305
718.675	38.6575
722.096	40.4236
725.518	40.3781
728.937	41.3923
732.357	42.2043
735.773	41.5897
739.19	41.2666
742.604	42.0385
746.018	44.464
749.429	46.7541
752.839	49.6655
756.248	51.0199
759.657	53.3356
763.063	55.8612
766.468	57.1475
769.871	61.8901
773.273	64.7659
776.676	68.1309
780.075	71.9008
783.474	74.0001
786.871	76.8275
790.266	80.2268
793.661	82.2131
797.054	83.4761
800.446	84.9121
803.834	85.7381
807.224	88.2435
810.612	87.5423
813.998	88.4612
817.384	88.3696
820.766	88.8281
824.149	88.4741
827.531	86.3996
830.909	84.3812
834.288	83.0975
837.666	79.4302
841.041	77.5621
844.416	75.2756
847.788	71.5795
851.161	68.7333
854.53	64.7629
857.901	61.2043
861.268	58.141
864.633	56.3375
868	54.0289
871.363	51.1761
874.725	52.535
878.088	50.0132
881.447	49.425
884.805	52.2238
888.162	51.9231
891.518	53.4467
894.872	53.8715
898.225	54.6967
901.577	54.853
904.928	54.1818
908.277	52.1414
911.625	52.6696
914.972	53.8565
918.318	53.5536
921.662	52.7891
925.005	51.7295
928.347	51.5848
931.686	48.9766
935.025	47.1321
938.363	44.7899
941.698	43.231
945.034	41.578
948.368	40.4746
951.699	37.6423
955.031	36.9934
958.36	35.6905
961.689	33.6552
965.016	35.9804
968.343	35.5318
971.666	36.696
974.991	39.4175
978.312	39.056
981.632	38.4542
984.953	35.2769
988.27	38.6915
991.587	43.3638
994.902	48.6439
998.216	51.7934
1001.53	53.5927
1004.84	55.7365
1008.15	59.5135
1011.46	65.9966
1014.77	71.7349
1018.07	76.8863
1021.38	81.3717
1024.68	84.7652
1027.99	86.481
1031.29	87.1682
1034.59	87.0246
1037.89	85.0263
1041.18	81.7678
1044.48	79.8113
1047.77	75.8213
1051.07	71.0026
1054.36	67.7598
1057.65	61.3317
1060.94	52.775
1064.23	44.9961
1067.52	42.5853
1070.8	41.4133
1074.09	34.9818
1077.37	30.4786
1080.65	26.6278
1083.93	24.5733
1087.21	25.7635
1090.49	29.7467
1093.77	33.1384
1097.04	34.8628
1100.32	35.7775
1103.59	35.7309
1106.86	35.4829
1110.13	35.2216
1113.4	34.1682
1116.67	33.215
1119.94	32.824
1123.2	31.2384
1126.47	30.2702
1129.73	29.7261
1132.99	29.1776
1136.25	27.7699
1139.51	24.4745
1142.77	22.9766
1146.03	20.3274
1149.28	18.4663
1152.54	14.4535
1155.79	13.088
1159.04	12.4134
1162.29	10.7096
1165.54	11.6298
1168.79	12.0337
1172.04	12.5888
1175.28	12.5306
1178.53	12.8826
1181.77	12.7853
1185.01	12.6936
1188.25	13.8575
1191.49	14.0348
1194.73	15.701
1197.96	17.5396
1201.2	20.5172
1204.43	22.7062
1207.66	25.3854
1210.9	27.8232
1214.13	30.4082
1217.36	31.3179
1220.58	34.166
1223.81	36.3811
1227.04	38.0319
1230.26	39.751
1233.48	41.8304
1236.71	46.2056
1239.93	47.7848
1243.14	50.1533
1246.36	50.8409
1249.58	53.3386
1252.8	52.9736
1256.01	52.5527
1259.22	54.3252
1262.43	54.6971
1265.64	56.5354
1268.85	57.1484
1272.06	57.3311
1275.27	60.3123
1278.48	62.42
1281.68	65.1989
1284.88	64.9173
1288.08	65.5728
1291.28	66.875
1294.48	68.7788
1297.68	70.1232
1300.88	73.0579
1304.07	75.3269
1307.27	76.0286
1310.46	77.3277
1313.65	78.2614
1316.85	78.0264
1320.03	77.7049
1323.22	77.1545
1326.41	78.229
1329.6	75.7768
1332.78	72.6224
1335.96	71.8266
1339.15	70.6238
1342.33	68.4089
1345.51	66.2241
1348.69	63.3814
1351.86	61.2049
1355.04	58.9321
1358.21	56.5748
1361.39	52.7475
1364.56	50.6559
1367.73	48.9142
1370.9	47.9627
1374.07	45.992
1377.24	43.6446
1380.41	43.4033
1383.57	41.6096
1386.73	39.6925
1389.9	38.1708
1393.06	36.1291
1396.22	34.9109
1399.38	34.8597
1402.54	34.3531
1405.69	34.6911
1408.85	34.9977
1412	38.77
1415.16	41.4046
1418.31	45.6631
1421.46	50.1863
1424.61	56.0304
1427.76	63.7045
1430.9	69.2334
1434.05	75.6101
1437.2	82.2336
1440.34	88.3143
1443.48	92.1189
1446.62	94.0485
1449.76	94.1118
1452.9	94.5569
1456.04	94.9192
1459.17	92.8288
1462.31	89.9796
1465.44	86.1066
1468.58	80.9613
1471.71	75.7189
1474.84	71.8397
1477.97	65.0002
1481.1	58.6511
1484.22	53.0476
1487.35	47.8999
1490.47	43.412
1493.59	38.2181
1496.72	34.6882
1499.84	33.1699
1502.96	31.7755
1506.08	29.3309
1509.19	26.7071
1512.31	26.1278
1515.42	24.0719
1518.54	21.2593
1521.65	20.6644
1524.76	18.8645
1527.87	19.2981
1530.98	20.2352
1534.09	19.2838
1537.2	19.1896
1540.3	21.3413
1543.41	23.6092
1546.51	25.431
1549.61	26.419
1552.71	28.799
1555.81	27.859
1558.91	28.7195
1562.01	30.1745
1565.1	31.774
1568.2	32.3374
1571.29	33.9328
1574.38	35.983
1577.48	38.6702
1580.57	39.9188
1583.65	42.7309
1586.74	45.069
1589.83	46.3579
1592.92	46.7399
1596	48.3917
1599.08	48.9181
1602.16	49.7668
1605.24	50.4002
1608.32	50.7335
1611.4	53.031
1614.48	54.1696
1617.56	54.5532
1620.63	55.3486
1623.71	54.9311
1626.78	56.5483
1629.85	57.0727
1632.92	58.0254
1635.99	59.0595
1639.06	61.1512
1642.12	63.079
1645.19	65.0602
1648.25	66.767
1651.32	67.4004
1654.38	67.9746
1657.44	68.4282
1660.5	69.182
1663.56	66.5902
1666.62	65.2166
1669.67	63.2338
1672.73	60.6659
1675.79	57.3844
1678.84	54.2018
1681.89	51.49
1684.94	47.655
1687.99	41.9673
1691.04	37.8984
1694.08	32.4963
1697.13	29.4453
1700.18	25.2511
1703.22	22.1826
1706.26	18.6538
1709.3	16.2933
1712.35	14.4465
1715.39	12.3169
1718.42	11.2022
1721.46	7.97374
1724.5	6.05888
1727.53	5.14892
1730.56	4.24041
1733.6	4.65173
1736.63	4.90217
1739.66	4.61521
1742.69	4.04345
1745.71	4.02824
1748.74	4.81099
1751.77	4.76178
1754.79	5.33411
1757.81	4.41334
1760.84	2.77977
1763.86	2.44485
1766.88	2.0299
1769.9	1.44484
1772.91	0.962347
1775.93	-0.473946
1778.95	-0.752524
1781.96	-1.1005
1784.97	-0.476417
1787.99	-0.35066
1791	-1.03591
1794.01	-1.61006
1797.01	-1.41641
1800.02	-0.933548
1803.03	0.323518
1806.03	1.36116
1809.04	1.02602
1812.04	1.26845
1815.04	1.79785
1818.04	2.20183
1821.04	2.92301
1824.04	2.75144
1827.04	3.20726
1830.03	3.05746
1833.03	2.71512
1836.02	3.59089
1839.02	2.89704
1842.01	2.45331
1845	2.41677
1847.99	2.17899
1850.98	2.80887
1853.96	3.5386
1856.95	3.59804
1859.94	4.99143
1862.92	5.14365
1865.9	5.85319
1868.88	5.96627
1871.86	7.07292
1874.84	6.98359
1877.82	7.5427
1880.8	8.19289
1882.58	8.02959
1885.57	9.39514
1888.56	9.79051
1891.54	10.4553
1894.53	10.1678
1897.51	11.817
1900.5	11.9613
1903.48	12.3002
1906.46	12.5667
1909.44	13.4535
1912.42	13.4111
1915.4	13.8325
1918.37	14.8201
1921.35	15.4722
1924.32	15.3906
1927.3	16.4154
1930.27	15.3894
1933.24	16.1468
1936.21	14.7599
1939.18	14.1925
1942.15	14.1585
1945.11	13.9502
1948.08	14.146
1951.04	14.8332
1954.01	14.7916
1956.97	14.4977
1959.93	14.6295
1962.89	14.8751
1965.85	15.8519
1968.81	16.6487
1971.77	17.5237
1974.72	17.7433
1977.68	18.7768
1980.63	19.4768
1983.58	20.6154
1986.53	21.7603
1989.48	22.8198
1992.43	23.1137
1995.38	23.0804
1998.33	24.3193
2001.27	24.0574
2004.22	23.9627
2007.16	24.1483
2010.11	24.5842
2013.05	25.0178
2015.99	25.0672
2018.93	25.4185
2021.87	25.8592
2024.8	25.0258
2027.74	24.6933
2030.68	25.2988
2033.61	26.1364
2036.54	26.2711
2039.48	27.5334
2042.41	27.2652
2045.34	27.5865
2048.27	29.012
2051.19	29.6183
2054.12	30.5766
2057.05	31.7019
2059.97	32.6231
2062.9	34.7934
2065.82	35.5292
2068.74	36.1005
2071.66	37.2017
2074.58	37.3668
2077.5	38.9966
2080.41	39.3083
2083.33	40.3684
2086.24	40.3508
2089.16	41.6699
2092.07	42.6707
2094.98	43.4674
2097.89	45.384
2100.8	47.3494
2103.71	49.8145
2106.62	51.4336
2109.53	52.6366
2112.43	54.3398
2115.33	55.8206
2118.24	57.7599
2121.14	58.9107
2124.04	61.5784
2126.94	64.0576
2129.84	67.129
2132.74	69.9261
2135.63	71.659
2138.53	73.0324
2141.43	75.0256
2144.32	76.1645
2147.21	77.0064
2150.1	78.3519
2152.99	79.3067
2155.88	80.9734
2158.77	82.2909
2161.66	83.7673
2164.55	84.6005
2167.43	86.6262
2170.31	87.56
2173.2	88.2213
2176.08	89.2567
2178.96	89.6028
2181.84	90.0476
2184.72	89.1464
2187.6	87.9786
2190.47	86.6344
2193.35	85.5407
2196.23	84.9174
2199.1	83.195
2201.97	81.7949
2204.84	80.4626
2207.71	78.3838
2210.58	75.0106
2213.45	72.8286
2216.32	69.8677
2219.19	67.7993
2222.05	67.1532
2224.92	65.4791
2227.78	62.8882
2230.64	61.0629
2233.5	59.3388
2236.36	57.316
2239.22	55.9246
2242.08	54.9757
2244.94	54.5499
2247.79	54.1108
2250.65	51.8545
2253.5	49.5933
2256.36	48.0063
2259.21	47.1895
2262.06	46.0336
2264.91	45.6046
2267.76	44.416
2270.6	43.6867
2273.45	43.5871
2276.3	42.1106
2279.14	40.4146
2281.98	39.7573
2284.83	38.5909
2287.67	37.0794
2290.51	35.8115
2293.35	34.9053
2296.19	33.8995
2299.02	33.9719
2301.86	33.5172
2304.7	33.9887
2307.53	34.2995
2310.36	35.6094
2313.2	36.05
2316.03	36.1501
2318.86	37.6292
2321.69	37.4701
2324.51	38.3568
2327.34	38.3818
2330.17	38.1753
2332.99	38.4321
2335.82	37.7116
2338.64	35.8943
2341.46	35.7545
2344.28	34.4342
2347.1	32.8804
2349.92	31.4742
2352.74	30.1165
2355.56	27.6216
2358.37	27.3191
2361.19	25.5052
2364	25.0564
2366.82	25.243
2369.63	24.7533
2372.44	23.0179
2375.25	22.869
2378.06	23.0324
2380.86	22.1047
2383.67	22.1003
2386.48	21.2249
2389.28	21.057
2392.09	20.6954
2394.89	19.975
2397.69	19.7191
2400.49	19.7514
2403.29	19.4747
2406.09	19.2679
2408.89	19.1013
2411.69	18.422
2414.48	18.6343
2417.28	18.7692
2420.07	17.8293
2422.86	17.1627
2425.65	16.2591
2428.45	15.5325
2431.23	14.5022
2434.02	14.3888
2436.81	13.6569
2439.6	12.796
2442.38	11.2972
2445.17	10.9439
2447.95	10.8041
2450.73	10.2815
2453.52	9.846
2456.3	9.56124
2459.08	9.53918
2461.85	9.53018
2464.63	9.12891
2467.41	9.12756
2470.19	9.33475
2472.96	8.92182
2475.73	9.02545
2478.51	10.1737
2481.28	10.2828
2484.05	10.4766
2486.82	10.3557
2489.59	9.37952
2492.35	9.79469
2495.12	8.35085
2497.89	7.95001
2500.65	8.19915
2503.42	8.34327
2506.18	8.33745
2508.94	8.51305
2511.7	8.39508
2514.46	7.09988
2517.22	6.52613
2519.98	5.1808
2522.73	5.14393
2525.49	5.61018
2528.25	5.61956
2531	5.93282
2533.75	5.9646
2536.5	5.61024
2539.25	5.02651
2542.01	6.04188
2544.75	5.94321
2547.5	5.56585
2550.25	4.86071
2553	5.56839
2555.74	4.71614
2558.49	3.14164
2561.23	2.7055
2563.97	3.10928
2566.71	2.1803
2569.45	2.21415
2572.19	2.18783
2574.93	1.69954
2577.67	1.79177
2580.4	0.762862
2583.14	0.679959
2585.87	1.48716
2588.6	1.93881
2591.34	2.44877
2594.07	2.49388
2596.8	2.47117
2599.53	2.7807
2602.26	2.99309
2604.98	3.16277
2607.71	3.86685
2610.44	4.06837
2613.16	2.93717
2615.88	2.9374
2618.61	2.57097
2621.33	0.96769
2624.05	-0.00843501
2626.77	-0.12347
2629.49	-0.73745
2632.21	-1.36239
2634.92	-1.07085
2637.64	-1.54752
2640.35	-1.34485
2643.07	-1.29617
2645.78	-1.39676
2648.49	-0.767677
2651.2	-0.455761
2653.91	-0.335914
2656.62	0.428315
2659.33	0.139188
2662.04	1.20406
2664.74	1.74264
2667.45	2.17105
2670.15	2.64412
2672.86	2.74389
2675.56	2.15941
2678.26	0.69383
2680.96	1.15286
2683.66	0.314863
2686.36	0.323925
2689.06	0.325422
2691.75	1.09329
2694.45	0.892791
2697.14	0.579301
2699.84	1.71092
2702.53	2.06469
2705.22	1.00484
2707.91	2.12413
2710.6	2.85288
2713.29	3.67733
2715.98	3.68413
2718.67	3.94592
2721.35	4.766
2724.04	5.12771
2726.72	5.56856
2729.4	6.00513
2732.09	6.08121
2734.77	6.17199
2737.45	5.03249
2740.13	4.65139
2742.81	3.67394
2745.48	4.02539
2748.16	3.83085
2750.84	2.70515
2753.51	2.51316
2756.19	2.20639
2758.86	1.10026
2761.53	0.968594
2764.2	1.14995
2766.87	0.208216
2769.54	-0.439757
2772.21	-1.02668
2774.88	-0.539453
2777.54	-0.329441
2780.21	-0.590742
2782.87	-0.590018
2785.53	-0.145817
2788.2	0.0471873
2790.86	0.103298
2793.52	0.533929
2796.18	0.988293
2798.84	1.67147
2801.49	1.61029
2804.15	1.93737
2806.81	2.97424
2809.46	3.8794
2812.12	4.44595
2814.77	5.23209
2817.42	7.92775
2820.07	11.9381
2822.72	16.2051
2825.37	20.7824
2828.02	27.134
2830.67	32.93
2833.31	39.0228
2835.96	45.8091
2838.61	52.9716
2841.25	60.5649
2843.89	68.7441
2846.53	78.0172
2849.17	87.5903
2851.81	97.1922
2854.45	107.271
2857.09	117.987
2859.73	127.903
2862.36	137.124
2865	144.86
2867.64	152.009
2870.27	158.885
2872.9	165.157
2875.53	170.149
2878.16	174.59
2880.79	179.645
2883.42	184.369
2886.05	189.61
2888.68	193.224
2891.3	198.441
2893.93	203.45
2896.55	206.987
2899.18	212.392
2901.8	218.694
2904.42	227.054
2907.04	236.803
2909.66	248.382
2912.28	259.919
2914.9	271.065
2917.51	282.571
2920.13	293.127
2922.74	300.086
2925.36	305.31
2927.97	308.159
2930.59	308.876
2933.2	308.905
2935.81	306.757
2938.42	301.016
2941.02	293.828
2943.63	286.151
2946.24	276.834
2948.85	266.828
2951.45	255.252
2954.05	243.754
2956.66	232.262
2959.26	219.466
2961.86	207.754
2964.46	197.753
2967.06	188.489
2969.66	179.632
2972.26	171.67
2974.85	163.046
2977.45	154.19
2980.05	145.751
2982.64	136.035
2985.23	125.69
2987.83	115.93
2990.42	106.876
2993.01	97.0704
2995.6	88.853
2998.19	80.9224
3000.77	72.3963
3003.36	65.069
3005.95	58.6252
3008.53	52.8387
3011.12	47.7544
3013.7	42.8945
3016.28	38.5726
3018.86	34.7653
3021.44	30.8282
3024.02	27.7613
3026.6	25.8936
3029.18	24.1334
3031.76	23.1914
3034.33	21.9361
3036.91	21.5241
3039.48	20.1465
3042.05	19.5474
3044.63	19.6458
3047.2	20.2748
3049.77	20.7743
3052.34	21.3657
3054.91	21.6614
3057.48	21.8236
3060.04	21.6856
3062.61	21.2372
3065.17	20.794
3067.74	19.9096
3070.3	18.5956
3072.87	17.5129
3075.43	16.466
3077.99	14.2617
3080.55	12.18
3083.11	10.2555
3085.67	8.69609
3088.22	6.3858
3090.78	4.90802
3093.34	3.47247
3095.89	2.69886
3098.44	1.80278
3101	0.451869
3103.55	-0.671237
3106.1	-0.34258
3108.65	-0.069987
3111.2	0.477348
3113.75	0.514751
3116.3	0.482417
3118.84	0.402515
3121.39	0.666531
3123.93	0.60573
3126.48	0.0497824
3129.02	0.118627
3131.56	-0.229197
3134.1	0.222113
3136.64	-0.0278664
3139.18	-0.304602
3141.72	-0.601426
3144.26	-0.549242
3146.8	-0.432752
3149.33	0.0963406