File: data/Raman/poly_smoothed/Mb_20_23_49_1x_45s_532 nm_x100_100%_600 gr_mm_01.txt
#Acq. time (s)=	45
#Accumulations=	2
#Range (cm-¹)=	200...3150
#Windows=	2
#Auto scanning=	Off
#Autofocus=	Off
#Macrospot=	Off
#AutoExposure=	Off
#Spike filter=	Multiple accum.
#Delay time (s)=	0
#Binning=	1
#Readout mode=	Signal
#DeNoise=	Off
#ICS correction=	On
#Dark correction=	Off
#Inst. Process=	Off
#Detector Gain=	Best Dynamic Range
#Detector ADC=	20 kHz
#Detector temperature (°C)=	-70.08
#Instrument=	LabRAM HR Evol
#Detector=	Synapse
#Objective=	x100
#Grating=	600 gr/mm
#ND Filter=	100%
#Laser (nm)=	532
#Hole=	100.021
#Range=	Auto
#Laser Pol.=	No
#Raman. Pol.=	No
#Laser Pol. (°)=	-0.0007625
#Raman Pol. (°)=	89.9995
#Collection=	Microscope
#StageXY=	Marzhauser
#StageZ=	Marzhauser
#X (µm)=	496.4
#Y (µm)=	2960.3
#Z (µm)=	-9.25
#Full time(mm:ss)=	3:19
#Project=
#Sample=
#Site=
#Title=	Mb_20_23_49_2x_45s_532 nm_x100_100%_600 gr_mm
#Remark=
#Date=	14.07.2022 10:04
#Acquired=	14.07.2022 10:04:26
#Base:Fit=	10.08.2022 10:29:37
#Base:Sub=	10.08.2022 10:35:48
#Filter:Polynom=	16.08.2022 10:13:29
#AxisType[0]=Intens
#AxisUnit[0]=Cnt
#AxisType[1]=Spectr
#AxisUnit[1]=1/cm
200.554	110.561
204.183	97.6943
207.813	86.9111
211.439	77.0301
215.065	69.0255
218.688	62.0209
222.312	54.2462
225.933	49.1004
229.552	43.0582
233.171	39.2805
236.787	36.1278
240.402	29.6613
244.015	25.1993
247.627	22.5338
251.24	20.4955
254.849	18.2725
258.457	15.0177
262.063	12.2774
265.668	11.0989
269.271	9.71529
272.873	8.13696
276.474	7.65827
280.073	7.61458
283.671	5.97075
287.268	4.6935
290.863	4.0557
294.456	4.14189
298.049	3.76741
301.637	3.82464
305.227	3.12835
308.815	3.83931
312.402	4.71765
315.987	5.50174
319.569	6.04312
323.151	6.82493
326.733	4.65422
330.31	5.2906
333.889	5.25488
337.464	5.78679
341.039	4.44528
344.611	5.42836
348.184	5.89435
351.754	6.97534
355.324	6.78184
358.89	6.91741
362.455	7.09836
366.021	6.3026
369.584	4.10875
373.145	4.1491
376.707	4.04868
380.265	3.4412
383.822	4.84939
387.378	3.30966
390.934	3.70029
394.487	5.58798
398.038	5.59691
401.588	5.60567
405.137	5.0847
408.685	4.17019
412.23	4.9123
415.775	6.28494
419.318	5.63818
422.86	6.02172
426.401	4.7804
429.94	6.39892
433.478	7.80728
437.012	8.48499
440.547	9.77287
444.081	10.3138
447.613	11.2045
451.142	11.8656
454.672	11.1774
458.2	12.7401
461.725	15.3854
465.251	18.7367
468.775	19.4227
472.296	22.0016
475.817	22.8611
479.335	24.8221
482.854	24.4206
486.37	25.5688
489.886	26.4654
493.398	27.0831
496.91	29.2316
500.422	29.9625
503.93	29.0693
507.438	29.2416
510.946	28.3777
514.45	27.7582
517.954	29.691
521.456	29.4198
524.956	29.0101
528.456	28.7395
531.956	29.6896
535.452	28.5004
538.947	27.2656
542.441	26.1193
545.934	26.3014
549.425	26.2044
552.915	25.2904
556.403	24.1196
559.889	21.1377
563.375	19.7867
566.859	18.4077
570.342	15.9187
573.824	14.2248
577.303	13.8405
580.782	12.113
584.26	10.5987
587.734	8.34712
591.21	5.91635
594.684	4.84171
598.154	4.59632
601.626	5.01222
605.094	5.20337
608.562	5.35536
612.027	7.13363
615.493	9.01504
618.956	8.78483
622.419	8.08214
625.879	7.92944
629.338	9.21898
632.797	10.8464
636.254	11.4489
639.708	10.4145
643.162	9.94556
646.614	8.12984
650.067	7.67483
653.516	8.04437
656.964	8.08765
660.411	7.40363
663.857	7.14461
667.301	8.2256
670.744	6.09665
674.186	6.75153
677.626	8.35665
681.065	10.6764
684.503	13.6294
687.939	15.6698
691.372	19.1019
694.806	21.867
698.239	25.0023
701.67	25.6616
705.098	26.122
708.526	27.2699
711.954	29.1145
715.378	30.9351
718.802	31.9234
722.226	31.5216
725.646	31.8082
729.067	32.7259
732.484	32.5467
735.902	33.8292
739.317	35.201
742.731	35.9792
746.145	37.9741
749.556	41.7669
752.966	44.6865
756.377	46.6404
759.784	50.3532
763.19	51.66
766.594	55.3526
770	57.7663
773.402	59.2782
776.803	60.4601
780.202	62.2724
783.6	63.9349
786.997	63.8152
790.393	67.4134
793.787	67.7423
797.18	69.6239
800.572	70.8118
803.963	72.8757
807.35	74.1241
810.738	74.8489
814.125	75.3771
817.51	75.7646
820.894	78.609
824.275	80.0565
827.657	82.972
831.037	84.3874
834.414	84.8258
837.792	86.1917
841.167	84.3778
844.542	83.0513
847.914	81.8708
851.287	81.5329
854.656	79.2024
858.026	78.3697
861.393	78.3951
864.761	78.2261
868.125	78.3139
871.489	76.6587
874.85	78.4651
878.213	77.702
881.572	75.989
884.931	74.4539
888.287	72.3343
891.643	70.5999
894.997	71.0958
898.352	70.8373
901.704	70.5987
905.055	70.0947
908.404	70.4713
911.75	67.9922
915.097	64.7788
918.443	63.4695
921.787	59.6011
925.13	55.8749
928.472	53.7379
931.813	52.6838
935.15	51.17
938.488	48.2963
941.825	46.231
945.158	45.5884
948.493	42.5475
951.824	41.2184
955.156	37.1628
958.486	33.5561
961.814	29.5231
965.142	27.7767
968.467	25.6803
971.79	24.7624
975.115	25.9845
978.436	25.2558
981.756	25.3703
985.077	25.5572
988.394	23.8236
991.71	22.3832
995.025	23.29
998.341	22.8451
1001.65	22.4395
1004.97	21.8477
1008.28	24.6521
1011.58	28.4579
1014.89	32.854
1018.2	32.3509
1021.5	37.1238
1024.81	44.6316
1028.11	52.8038
1031.41	59.4834
1034.71	67.1433
1038.01	72.0283
1041.31	79.7359
1044.6	85.6796
1047.9	90.1928
1051.19	92.3377
1054.48	94.8971
1057.77	94.5696
1061.06	95.1726
1064.35	93.6774
1067.64	91.5704
1070.93	87.498
1074.21	83.013
1077.49	76.1259
1080.78	68.1866
1084.06	58.9159
1087.34	51.3957
1090.61	47.7632
1093.89	45.4689
1097.17	44.8784
1100.44	45.6999
1103.71	51.4829
1106.99	55.0481
1110.26	55.6638
1113.52	56.8245
1116.79	56.6907
1120.06	56.4763
1123.32	55.642
1126.59	52.7023
1129.85	51.3416
1133.11	48.758
1136.37	44.2314
1139.63	39.2438
1142.89	35.6361
1146.15	30.3852
1149.4	25.248
1152.66	19.0122
1155.91	13.7106
1159.16	8.6604
1162.41	2.12456
1165.66	-2.0783
1168.91	-1.02684
1172.16	1.62855
1175.4	2.06316
1178.65	2.23075
1181.89	2.91111
1185.13	1.52921
1188.37	3.21879
1191.61	3.1229
1194.85	3.61151
1198.08	5.79535
1201.32	7.32552
1204.55	8.24764
1207.79	12.0062
1211.02	13.3419
1214.25	16.1446
1217.48	17.7226
1220.71	20.2598
1223.93	25.3611
1227.16	28.1484
1230.38	31.8154
1233.6	33.6529
1236.83	35.4773
1240.05	37.4
1243.26	39.929
1246.48	42.9819
1249.7	43.7501
1252.92	41.4281
1256.13	41.1137
1259.34	46.4598
1262.55	55.2157
1265.76	67.1102
1268.97	77.1208
1272.18	86.4519
1275.39	98.1072
1278.59	110.265
1281.8	118.799
1285	126.86
1288.2	133.635
1291.4	138.799
1294.6	142.481
1297.8	144.493
1301	145.285
1304.19	145.108
1307.39	141.458
1310.58	135.836
1313.77	128.722
1316.96	120.646
1320.15	112.621
1323.34	100.997
1326.53	88.5369
1329.72	79.0295
1332.9	73.9588
1336.08	72.1911
1339.27	70.1307
1342.45	69.2021
1345.63	65.5398
1348.8	63.8044
1351.98	62.877
1355.16	61.653
1358.33	60.782
1361.51	58.731
1364.68	57.9418
1367.85	57.7367
1371.02	58.5073
1374.19	58.1865
1377.36	57.7552
1380.52	59.4162
1383.69	61.5725
1386.85	63.1359
1390.02	62.3788
1393.18	62.2934
1396.34	62.4734
1399.5	66.1895
1402.65	74.8977
1405.81	89.5638
1408.97	105.937
1412.12	122.918
1415.27	139.96
1418.43	159.696
1421.58	179.863
1424.73	200.923
1427.87	223.754
1431.02	243.477
1434.17	261.142
1437.31	274.655
1440.46	286.188
1443.6	291.058
1446.74	293.42
1449.88	289.297
1453.02	281.471
1456.16	269.897
1459.29	254.488
1462.43	235.365
1465.56	211.229
1468.69	184.503
1471.83	161.535
1474.95	139.59
1478.08	122.155
1481.21	106.933
1484.34	91.7463
1487.47	77.3039
1490.59	62.9736
1493.71	53.2395
1496.84	44.1643
1499.96	37.999
1503.07	35.6526
1506.19	31.9751
1509.31	28.7283
1512.43	24.4292
1515.54	23.7174
1518.65	22.4873
1521.77	22.1817
1524.88	22.9418
1527.99	22.23
1531.1	22.6124
1534.21	23.2165
1537.31	24.4233
1540.42	26.1746
1543.52	27.5012
1546.63	30.0576
1549.73	31.7882
1552.83	34.2311
1555.93	37.2294
1559.03	38.3498
1562.12	40.9396
1565.22	42.0844
1568.31	44.4691
1571.41	47.606
1574.5	49.9992
1577.59	54.3297
1580.68	58.3111
1583.77	61.2966
1586.86	63.8984
1589.95	66.424
1593.03	68.2958
1596.11	70.0963
1599.2	71.3766
1602.28	70.3314
1605.36	68.3652
1608.44	67.4593
1611.52	67.8625
1614.6	67.5694
1617.67	67.575
1620.75	67.4238
1623.82	65.8038
1626.89	65.2204
1629.96	65.8526
1633.04	65.2719
1636.11	65.0316
1639.17	65.8445
1642.24	67.9976
1645.31	68.7004
1648.37	70.5815
1651.43	71.5489
1654.5	72.4745
1657.56	73.4311
1660.62	71.285
1663.67	69.3056
1666.73	65.1452
1669.79	63.1648
1672.84	58.9966
1675.9	54.3185
1678.95	50.8384
1682	45.9828
1685.05	43.2988
1688.1	40.1023
1691.15	37.1776
1694.2	35.5853
1697.25	32.4616
1700.29	31.1332
1703.33	30.654
1706.38	29.4496
1709.42	28.1147
1712.46	28.959
1715.5	29.5508
1718.54	29.2489
1721.57	30.958
1724.61	31.9905
1727.64	31.8844
1730.68	31.9853
1733.71	31.4437
1736.74	29.7367
1739.77	29.5566
1742.8	27.6274
1745.83	27.05
1748.85	24.7756
1751.88	23.9256
1754.91	21.0863
1757.93	18.2761
1760.95	16.2137
1763.97	13.6906
1766.99	12.7571
1770.01	11.6331
1773.03	10.7043
1776.04	10.6526
1779.06	9.41497
1782.07	8.62593
1785.09	8.92561
1788.1	8.47213
1791.11	9.10203
1794.12	8.66986
1797.13	8.68783
1800.13	8.24959
1803.14	7.88994
1806.15	7.75059
1809.15	7.30918
1812.15	7.46856
1815.16	7.41526
1818.15	6.97865
1821.16	7.27743
1824.15	6.3926
1827.15	5.03194
1830.15	3.51541
1833.14	3.90205
1836.14	3.69374
1839.13	3.48115
1842.12	4.07244
1845.11	4.72662
1848.1	5.53838
1851.09	5.13549
1854.08	5.04282
1857.06	4.9514
1860.05	3.60715
1863.03	2.98352
1866.01	3.28049
1869	3.03117
1871.98	2.87485
1874.96	2.97324
1877.93	2.92168
1880.91	2.53394
1882.47	2.06321
1885.46	2.08637
1888.44	1.12347
1891.43	1.15506
1894.42	1.52098
1897.4	0.655017
1900.39	2.30695
1903.37	3.52399
1906.35	4.124
1909.33	4.93784
1912.31	6.24228
1915.29	6.66614
1918.26	7.76684
1921.24	8.22273
1924.21	9.04196
1927.19	7.67236
1930.16	8.03865
1933.13	7.83283
1936.1	8.1713
1939.07	7.50593
1942.04	6.77353
1945	6.34192
1947.97	5.0193
1950.93	3.98403
1953.9	2.50967
1956.86	0.468949
1959.82	-0.566342
1962.78	-0.835503
1965.74	0.0573505
1968.7	1.17476
1971.65	2.11896
1974.61	3.18554
1977.57	3.26236
1980.52	4.54539
1983.47	6.18555
1986.42	6.5965
1989.37	7.96442
1992.32	8.68632
1995.27	9.69325
1998.22	8.49483
2001.17	8.55077
2004.11	9.58565
2007.05	9.49254
2010	8.9389
2012.94	9.25236
2015.88	6.99091
2018.82	6.54987
2021.76	5.35789
2024.7	4.91152
2027.63	5.69829
2030.57	5.78485
2033.5	5.35184
2036.44	6.32727
2039.37	5.71558
2042.3	6.35216
2045.23	8.48532
2048.16	9.30989
2051.08	9.60529
2054.01	9.07754
2056.94	9.0743
2059.86	9.26668
2062.79	8.54656
2065.71	8.08973
2068.63	8.49283
2071.55	7.14749
2074.47	7.81408
2077.39	7.64526
2080.31	7.26529
2083.22	6.39776
2086.13	5.84027
2089.05	4.92965
2091.96	5.80822
2094.87	6.80826
2097.78	7.21156
2100.69	8.12369
2103.6	8.12309
2106.51	8.32467
2109.42	10.0846
2112.32	10.714
2115.23	12.8805
2118.13	14.1943
2121.03	16.0497
2123.93	16.9067
2126.83	18.3924
2129.73	20.1047
2132.63	21.1793
2135.53	22.6886
2138.42	24.0533
2141.32	26.1417
2144.21	25.9752
2147.1	28.5356
2150	30.0495
2152.89	30.4576
2155.78	31.9361
2158.66	33.7606
2161.55	33.9931
2164.44	34.9167
2167.32	35.2099
2170.21	36.089
2173.09	37.2683
2175.97	36.9481
2178.85	36.4782
2181.73	36.4802
2184.61	37.0482
2187.49	37.3725
2190.37	36.5734
2193.24	35.4579
2196.12	33.5757
2198.99	32.5104
2201.87	29.9975
2204.74	27.9648
2207.61	25.932
2210.48	24.0959
2213.35	22.5427
2216.21	21.6742
2219.08	20.4792
2221.95	17.518
2224.81	16.2447
2227.67	14.371
2230.54	11.9535
2233.4	10.2333
2236.26	10.0271
2239.11	9.99316
2241.97	8.76282
2244.83	7.79626
2247.69	8.03834
2250.54	8.45129
2253.4	8.26266
2256.25	8.79508
2259.1	7.65714
2261.95	8.2149
2264.8	8.94179
2267.65	8.00686
2270.5	7.97381
2273.34	7.44535
2276.19	8.49634
2279.03	7.55745
2281.88	7.84738
2284.72	7.31304
2287.56	5.62431
2290.4	3.46397
2293.24	2.6703
2296.08	2.53763
2298.92	2.8956
2301.76	4.12818
2304.59	4.2933
2307.43	4.22759
2310.26	4.40635
2313.09	5.22972
2315.92	5.36016
2318.75	4.7484
2321.58	5.66685
2324.41	4.85664
2327.24	6.14142
2330.06	6.44046
2332.89	5.91401
2335.71	5.30049
2338.54	5.18974
2341.36	5.64427
2344.18	6.19046
2347	5.65397
2349.82	4.74881
2352.64	4.84047
2355.45	3.94496
2358.27	2.81763
2361.08	1.90967
2363.9	2.55922
2366.71	3.34908
2369.52	3.30437
2372.33	3.58591
2375.14	2.55556
2377.95	3.38042
2380.76	2.99562
2383.57	3.0401
2386.37	3.27482
2389.18	3.98827
2391.98	3.48622
2394.79	3.43463
2397.59	3.68675
2400.39	3.03978
2403.19	2.88189
2405.99	2.99348
2408.78	4.17963
2411.58	4.80562
2414.38	5.63564
2417.17	4.54986
2419.97	4.72263
2422.76	4.97092
2425.55	4.50966
2428.34	5.04055
2431.13	5.38275
2433.92	4.62558
2436.71	4.01327
2439.49	2.71637
2442.28	3.62776
2445.06	3.92465
2447.85	4.0013
2450.63	3.05681
2453.41	3.47417
2456.19	3.79379
2458.97	1.97826
2461.75	1.8015
2464.53	1.46701
2467.31	2.4766
2470.08	1.8379
2472.86	0.161777
2475.63	0.734739
2478.4	0.829629
2481.17	0.749807
2483.94	0.846238
2486.72	0.815849
2489.48	1.15135
2492.25	1.93169
2495.02	1.63652
2497.79	1.94557
2500.55	0.549685
2503.31	0.0467363
2506.08	0.19555
2508.84	0.63865
2511.6	2.2328
2514.36	3.02732
2517.12	2.1322
2519.88	2.05484
2522.63	3.31069
2525.39	2.73955
2528.14	2.03427
2530.9	3.72555
2533.65	3.82568
2536.4	2.85803
2539.15	2.59762
2541.9	2.93787
2544.65	3.62985
2547.4	4.7294
2550.15	4.79293
2552.89	4.96336
2555.64	5.66025
2558.38	6.84489
2561.12	8.00363
2563.87	9.27517
2566.61	9.52329
2569.35	10.3436
2572.09	11.4244
2574.83	12.5417
2577.56	13.3972
2580.3	15.2825
2583.04	14.5084
2585.77	14.8934
2588.5	14.5669
2591.23	14.1781
2593.97	14.3393
2596.7	15.4113
2599.43	15.5405
2602.15	14.5751
2604.88	13.6006
2607.61	14.0796
2610.33	14.7157
2613.06	14.0612
2615.78	14.1235
2618.51	15.5441
2621.23	16.46
2623.95	17.2952
2626.67	17.4899
2629.39	18.5594
2632.1	19.6639
2634.82	19.4435
2637.54	20.1747
2640.25	20.2502
2642.97	20.9251
2645.68	22.2683
2648.39	22.544
2651.1	21.3859
2653.81	21.1814
2656.52	20.9962
2659.23	22.5386
2661.94	22.9011
2664.64	21.8429
2667.35	21.9675
2670.05	20.9671
2672.76	21.1598
2675.46	21.505
2678.16	21.879
2680.86	22.691
2683.56	23.5583
2686.26	23.6973
2688.96	24.7271
2691.65	27.1493
2694.35	30.5371
2697.04	34.0084
2699.74	38.1566
2702.43	41.2925
2705.12	44.6955
2707.81	48.9651
2710.5	53.5871
2713.19	54.4368
2715.88	56.0764
2718.57	56.9237
2721.25	57.8301
2723.94	58.5712
2726.62	58.8155
2729.3	56.9977
2731.99	53.9715
2734.67	51.7682
2737.35	48.3722
2740.03	43.9785
2742.71	38.8176
2745.38	34.7338
2748.06	30.4876
2750.74	24.8068
2753.41	21.2749
2756.09	18.998
2758.76	17.4148
2761.43	15.4676
2764.1	14.9821
2766.77	13.4813
2769.44	13.8292
2772.11	14.4883
2774.77	14.1238
2777.44	13.1763
2780.11	11.994
2782.77	13.0801
2785.43	12.8134
2788.1	14.0426
2790.76	15.7649
2793.42	16.6147
2796.08	16.2313
2798.74	15.2652
2801.4	14.3848
2804.05	10.8403
2806.71	6.86196
2809.36	2.26186
2812.02	1.11497
2814.67	5.90183
2817.32	20.2068
2819.97	45.3403
2822.62	79.5403
2825.27	119.16
2827.92	164.074
2830.57	213.302
2833.22	265.621
2835.86	316.028
2838.51	365.142
2841.15	412.427
2843.79	455.31
2846.43	495.781
2849.08	539.547
2851.72	586.5
2854.36	634.879
2856.99	678.004
2859.63	715.539
2862.27	743.877
2864.9	764.635
2867.54	775.629
2870.17	782.029
2872.8	784.991
2875.43	786.861
2878.07	791.721
2880.7	796.996
2883.32	806.365
2885.95	811.273
2888.58	813.21
2891.21	809.809
2893.83	804.61
2896.46	795.356
2899.08	783.071
2901.7	770.885
2904.32	757.432
2906.94	746.727
2909.56	740.84
2912.18	743.074
2914.8	752.295
2917.42	758.709
2920.03	759.662
2922.65	757.159
2925.26	747.683
2927.88	734.435
2930.49	718.662
2933.1	702.001
2935.71	682.063
2938.32	660.007
2940.93	633.956
2943.54	606.886
2946.14	577.363
2948.75	545.996
2951.35	511.944
2953.96	478.445
2956.56	443.081
2959.16	410.349
2961.77	379.02
2964.37	350.29
2966.96	323.818
2969.56	300.178
2972.16	278.177
2974.76	257.754
2977.35	237.018
2979.95	216.613
2982.54	194.607
2985.14	172.913
2987.73	152.482
2990.32	132.665
2992.91	115.459
2995.5	99.1292
2998.09	85.6969
3000.68	72.7721
3003.26	62.6403
3005.85	52.2363
3008.43	43.3887
3011.02	35.9938
3013.6	30.3413
3016.19	22.7912
3018.77	17.6857
3021.35	12.4757
3023.93	9.3636
3026.5	5.35181
3029.08	3.67805
3031.66	3.06044
3034.24	1.48307
3036.81	1.25352
3039.39	1.43922
3041.96	1.25765
3044.53	2.65221
3047.1	2.24211
3049.67	3.28608
3052.24	4.03398
3054.81	4.45328
3057.38	5.47774
3059.95	5.22461
3062.52	5.77539
3065.08	6.07835
3067.65	6.20308
3070.21	6.10774
3072.77	6.09561
3075.33	4.71831
3077.89	3.75662
3080.45	2.38812
3083.01	1.52546
3085.57	1.63848
3088.13	1.91556
3090.68	0.979173
3093.24	1.43645
3095.79	2.43931
3098.35	2.33595
3100.9	4.99863
3103.45	5.7681
3106	7.50498
3108.55	9.15711
3111.1	11.6639
3113.65	14.6233
3116.2	17.6702
3118.75	20.462
3121.29	23.5108
3123.84	26.8154
3126.38	30.1695
3128.92	33.4954
3131.47	36.5901
3134.01	40.2056
3136.55	43.2135
3139.09	46.6474
3141.63	51.2142
3144.17	55.6078
3146.7	58.7428
3149.24	60.6209