File: data/Raman/poly_smoothed/Mb_20_23_50_1x_45s_532 nm_x100_100%_600 gr_mm_01.txt
#Acq. time (s)=	45
#Accumulations=	2
#Range (cm-¹)=	200...3150
#Windows=	2
#Auto scanning=	Off
#Autofocus=	Off
#Macrospot=	Off
#AutoExposure=	Off
#Spike filter=	Multiple accum.
#Delay time (s)=	0
#Binning=	1
#Readout mode=	Signal
#DeNoise=	Off
#ICS correction=	On
#Dark correction=	Off
#Inst. Process=	Off
#Detector Gain=	Best Dynamic Range
#Detector ADC=	20 kHz
#Detector temperature (°C)=	-70.08
#Instrument=	LabRAM HR Evol
#Detector=	Synapse
#Objective=	x100
#Grating=	600 gr/mm
#ND Filter=	100%
#Laser (nm)=	532
#Hole=	100.021
#Range=	Auto
#Laser Pol.=	No
#Raman. Pol.=	No
#Laser Pol. (°)=	-0.0007625
#Raman Pol. (°)=	89.9995
#Collection=	Microscope
#StageXY=	Marzhauser
#StageZ=	Marzhauser
#X (µm)=	416.2
#Y (µm)=	2941.8
#Z (µm)=	-9.1
#Full time(mm:ss)=	3:19
#Project=
#Sample=
#Site=
#Title=	Mb_20_23_50_2x_45s_532 nm_x100_100%_600 gr_mm
#Remark=
#Date=	14.07.2022 10:08
#Acquired=	14.07.2022 10:08:23
#Base:Fit=	10.08.2022 10:29:37
#Base:Sub=	10.08.2022 10:35:48
#Filter:Polynom=	16.08.2022 10:13:29
#AxisType[0]=Intens
#AxisUnit[0]=Cnt
#AxisType[1]=Spectr
#AxisUnit[1]=1/cm
200.554	20.6182
204.183	19.7423
207.813	16.9068
211.439	13.8022
215.065	9.98568
218.688	7.92669
222.312	5.80617
225.933	3.95627
229.552	3.51658
233.171	3.74255
236.787	3.84131
240.402	3.85065
244.015	3.11402
247.627	2.3099
251.24	1.2628
254.849	1.94133
258.457	4.08126
262.063	5.66305
265.668	6.20497
269.271	6.878
272.873	8.76446
276.474	10.4948
280.073	10.729
283.671	11.4231
287.268	12.9082
290.863	12.0155
294.456	12.2342
298.049	11.7456
301.637	11.638
305.227	13.6581
308.815	16.0627
312.402	18.9147
315.987	22.0525
319.569	23.4643
323.151	24.6984
326.733	26.0927
330.31	24.8789
333.889	26.3316
337.464	27.5334
341.039	27.5749
344.611	31.0738
348.184	30.8108
351.754	32.3721
355.324	31.5046
358.89	31.8304
362.455	28.4568
366.021	24.71
369.584	22.985
373.145	20.6584
376.707	19.618
380.265	16.9539
383.822	15.7922
387.378	15.0504
390.934	14.7924
394.487	17.4665
398.038	17.7783
401.588	18.1848
405.137	18.802
408.685	17.9176
412.23	19.6478
415.775	20.5647
419.318	22.3579
422.86	25.5487
426.401	26.0733
429.94	27.8963
433.478	29.1969
437.012	30.0983
440.547	29.812
444.081	30.5939
447.613	29.0749
451.142	29.0334
454.672	30.9852
458.2	31.339
461.725	30.9941
465.251	32.1332
468.775	31.5415
472.296	32.6503
475.817	33.3795
479.335	33.7065
482.854	36.0964
486.37	36.5463
489.886	37.8381
493.398	39.9177
496.91	40.0987
500.422	39.7064
503.93	38.9154
507.438	39.4219
510.946	38.5081
514.45	38.9598
517.954	38.1746
521.456	36.576
524.956	36.7326
528.456	35.576
531.956	32.3429
535.452	30.281
538.947	29.7784
542.441	26.078
545.934	23.6625
549.425	20.9081
552.915	21.2966
556.403	19.172
559.889	19.3389
563.375	18.0809
566.859	18.1473
570.342	16.1788
573.824	16.1967
577.303	16.0463
580.782	15.9668
584.26	14.0897
587.734	12.065
591.21	12.1628
594.684	12.2321
598.154	12.0494
601.626	11.8866
605.094	13.029
608.562	12.2571
612.027	10.3594
615.493	9.05532
618.956	7.49297
622.419	6.95782
625.879	6.0863
629.338	5.81742
632.797	4.66429
636.254	3.69553
639.708	5.59679
643.162	5.49473
646.614	4.25678
650.067	3.66712
653.516	4.22916
656.964	4.94547
660.411	6.38079
663.857	5.97434
667.301	6.76471
670.744	6.58256
674.186	7.90066
677.626	7.88544
681.065	8.32034
684.503	9.43932
687.939	11.5726
691.372	13.5844
694.806	12.6496
698.239	14.4929
701.67	14.6943
705.098	16.9361
708.526	17.1695
711.954	18.2739
715.378	19.242
718.802	19.6486
722.226	21.5256
725.646	21.4026
729.067	21.47
732.484	22.4196
735.902	24.7372
739.317	25.4733
742.731	25.8401
746.145	27.8401
749.556	31.3974
752.966	32.2722
756.377	33.4929
759.784	34.7736
763.19	34.4623
766.594	37.4119
770	39.1036
773.402	41.4543
776.803	42.2573
780.202	45.0412
783.6	47.8166
786.997	49.8349
790.393	52.111
793.787	55.1495
797.18	56.6416
800.572	59.61
803.963	60.1507
807.35	61.6153
810.738	62.6489
814.125	62.7879
817.51	63.2709
820.894	63.6285
824.275	63.6293
827.657	64.9439
831.037	65.6238
834.414	63.8533
837.792	62.522
841.167	62.6705
844.542	61.5223
847.914	60.3086
851.287	59.7211
854.656	60.2038
858.026	60.2706
861.393	58.3891
864.761	58.6019
868.125	57.2422
871.489	58.9041
874.85	58.2284
878.213	56.868
881.572	55.0029
884.931	54.0206
888.287	51.903
891.643	50.6766
894.997	46.6847
898.352	43.7545
901.704	42.1988
905.055	40.5437
908.404	39.1755
911.75	38.5392
915.097	37.8921
918.443	38.6104
921.787	38.934
925.13	38.2517
928.472	37.4279
931.813	36.8695
935.15	34.7781
938.488	32.7104
941.825	30.1129
945.158	29.0375
948.493	27.3927
951.824	26.9015
955.156	26.4449
958.486	22.3194
961.814	20.1539
965.142	19.541
968.467	19.4029
971.79	20.4166
975.115	19.0586
978.436	17.9142
981.756	18.2809
985.077	18.2354
988.394	17.4679
991.71	16.1355
995.025	16.5807
998.341	18.7214
1001.65	19.0934
1004.97	20.5376
1008.28	23.1103
1011.58	27.2435
1014.89	28.1149
1018.2	29.5062
1021.5	31.1707
1024.81	35.5001
1028.11	38.9333
1031.41	40.6381
1034.71	46.8872
1038.01	48.6945
1041.31	51.1095
1044.6	55.0189
1047.9	57.3944
1051.19	59.0183
1054.48	58.8928
1057.77	58.9982
1061.06	56.5306
1064.35	53.8386
1067.64	48.914
1070.93	46.2674
1074.21	45.0417
1077.49	43.2274
1080.78	42.313
1084.06	40.4724
1087.34	39.6404
1090.61	40.8764
1093.89	39.9706
1097.17	39.2847
1100.44	40.4851
1103.71	41.0153
1106.99	44.0441
1110.26	43.9101
1113.52	42.8514
1116.79	43.4416
1120.06	44.0735
1123.32	43.8882
1126.59	42.1767
1129.85	41.7217
1133.11	39.1426
1136.37	37.1814
1139.63	33.7379
1142.89	29.4883
1146.15	25.24
1149.4	21.4085
1152.66	17.8823
1155.91	13.8618
1159.16	10.4432
1162.41	7.29226
1165.66	6.25453
1168.91	5.14771
1172.16	3.70852
1175.4	1.58367
1178.65	0.0814627
1181.89	-1.05254
1185.13	-1.7534
1188.37	-1.36586
1191.61	-0.223463
1194.85	1.72309
1198.08	4.18141
1201.32	6.37344
1204.55	10.4316
1207.79	14.6228
1211.02	18.676
1214.25	22.1793
1217.48	26.8343
1220.71	30.1449
1223.93	34.564
1227.16	41.6921
1230.38	45.4156
1233.6	52.1504
1236.83	57.2336
1240.05	61.907
1243.26	66.0321
1246.48	68.8931
1249.7	71.1454
1252.92	73.7255
1256.13	75.8914
1259.34	79.6186
1262.55	84.479
1265.76	87.9321
1268.97	95.992
1272.18	99.3993
1275.39	104.752
1278.59	111.393
1281.8	115.54
1285	119.943
1288.2	123.742
1291.4	127.365
1294.6	131.67
1297.8	132.893
1301	134.743
1304.19	135.707
1307.39	135.94
1310.58	134.833
1313.77	134.9
1316.96	131.001
1320.15	124.802
1323.34	119.937
1326.53	116.101
1329.72	111.667
1332.9	107.902
1336.08	104.176
1339.27	100.124
1342.45	97.0557
1345.63	94.8005
1348.8	92.1399
1351.98	89.4057
1355.16	89.3419
1358.33	84.7928
1361.51	82.2783
1364.68	82.0635
1367.85	82.4196
1371.02	81.6693
1374.19	81.581
1377.36	82.3386
1380.52	82.9985
1383.69	83.5131
1386.85	84.2712
1390.02	83.4468
1393.18	81.5851
1396.34	80.8754
1399.5	80.5957
1402.65	83.1668
1405.81	90.6354
1408.97	98.8913
1412.12	110.934
1415.27	120.985
1418.43	132.678
1421.58	147.011
1424.73	161.116
1427.87	176.514
1431.02	190.887
1434.17	201.853
1437.31	212.186
1440.46	220.926
1443.6	226.355
1446.74	229.798
1449.88	229.362
1453.02	226.579
1456.16	220.641
1459.29	208.761
1462.43	194.35
1465.56	178.168
1468.69	159.602
1471.83	143.405
1474.95	127.173
1478.08	111.35
1481.21	100.079
1484.34	88.716
1487.47	77.6147
1490.59	67.1841
1493.71	57.4972
1496.84	50.99
1499.96	46.2749
1503.07	43.7544
1506.19	40.0488
1509.31	37.4524
1512.43	35.1965
1515.54	34.3519
1518.65	31.5357
1521.77	31.2113
1524.88	31.3509
1527.99	32.1263
1531.1	32.4598
1534.21	33.5931
1537.31	35.3653
1540.42	36.4218
1543.52	38.052
1546.63	39.5473
1549.73	41.5637
1552.83	43.8854
1555.93	47.225
1559.03	48.5311
1562.12	49.8857
1565.22	52.421
1568.31	55.4091
1571.41	59.8241
1574.5	64.7287
1577.59	68.2124
1580.68	71.1005
1583.77	74.734
1586.86	78.4262
1589.95	81.2466
1593.03	84.418
1596.11	86.1955
1599.2	87.7498
1602.28	88.471
1605.36	89.4084
1608.44	88.6088
1611.52	87.4504
1614.6	86.7729
1617.67	86.2217
1620.75	85.6343
1623.82	85.2819
1626.89	87.4913
1629.96	88.4026
1633.04	89.7954
1636.11	92.1682
1639.17	94.5255
1642.24	97.0187
1645.31	99.5461
1648.37	102.625
1651.43	105.298
1654.5	107.325
1657.56	107.605
1660.62	107.806
1663.67	105.342
1666.73	102.954
1669.79	97.5973
1672.84	92.0087
1675.9	85.3701
1678.95	78.3254
1682	72.5073
1685.05	67.023
1688.1	60.6169
1691.15	55.0972
1694.2	48.7375
1697.25	43.9824
1700.29	39.4631
1703.33	37.4167
1706.38	35.3645
1709.42	33.8168
1712.46	32.7581
1715.5	31.27
1718.54	30.1405
1721.57	32.2224
1724.61	32.3612
1727.64	31.0233
1730.68	30.261
1733.71	28.9086
1736.74	27.2357
1739.77	24.9473
1742.8	22.4282
1745.83	20.3032
1748.85	18.7291
1751.88	17.2443
1754.91	17.9772
1757.93	17.5845
1760.95	14.7934
1763.97	12.2295
1766.99	9.55816
1770.01	8.98068
1773.03	8.07721
1776.04	8.02497
1779.06	7.62882
1782.07	7.28318
1785.09	7.2023
1788.1	6.32779
1791.11	5.71007
1794.12	4.76036
1797.13	4.13087
1800.13	2.2849
1803.14	1.1597
1806.15	1.31779
1809.15	0.539389
1812.15	-0.320623
1815.16	0.229268
1818.15	0.997911
1821.16	1.19716
1824.15	2.00523
1827.15	1.6402
1830.15	2.32217
1833.14	1.75912
1836.14	0.8353
1839.13	0.232807
1842.12	0.747998
1845.11	1.55449
1848.1	1.33982
1851.09	1.75555
1854.08	1.84636
1857.06	1.66398
1860.05	1.34696
1863.03	1.59536
1866.01	1.86135
1869	2.22107
1871.98	2.69827
1874.96	2.89875
1877.93	2.72674
1880.91	5.01129
1882.47	4.84412
1885.46	5.14071
1888.44	5.33722
1891.43	4.57871
1894.42	4.74361
1897.4	4.27577
1900.39	5.02311
1903.37	5.50382
1906.35	6.97509
1909.33	6.09316
1912.31	7.76717
1915.29	8.57542
1918.26	9.38143
1921.24	10.1423
1924.21	11.4955
1927.19	10.8864
1930.16	11.0221
1933.13	11.2717
1936.1	12.688
1939.07	11.7708
1942.04	10.798
1945	10.8793
1947.97	9.63795
1950.93	9.09273
1953.9	8.39279
1956.86	6.62905
1959.82	5.78818
1962.78	5.10567
1965.74	3.61116
1968.7	2.60253
1971.65	1.09966
1974.61	0.235509
1977.57	0.301204
1980.52	0.771955
1983.47	1.23742
1986.42	0.498385
1989.37	1.4245
1992.32	1.57229
1995.27	2.16618
1998.22	1.65777
2001.17	1.6057
2004.11	2.94236
2007.05	3.48608
2010	4.2731
2012.94	4.51487
2015.88	5.72546
2018.82	4.28958
2021.76	4.44235
2024.7	4.94498
2027.63	6.29773
2030.57	5.22359
2033.5	4.22299
2036.44	4.06038
2039.37	4.7078
2042.3	4.15177
2045.23	4.3364
2048.16	5.85203
2051.08	6.98075
2054.01	7.78144
2056.94	8.05248
2059.86	8.19651
2062.79	8.61365
2065.71	9.92238
2068.63	10.3886
2071.55	11.6718
2074.47	13.1171
2077.39	14.4113
2080.31	16.0138
2083.22	17.1742
2086.13	16.348
2089.05	15.0763
2091.96	14.8475
2094.87	16.5549
2097.78	18.1245
2100.69	18.1077
2103.6	17.4855
2106.51	18.4916
2109.42	19.9191
2112.32	20.8171
2115.23	21.2474
2118.13	22.9192
2121.03	24.3707
2123.93	25.9541
2126.83	25.812
2129.73	28.1189
2132.63	29.4932
2135.53	31.7371
2138.42	35.0278
2141.32	37.0797
2144.21	38.7412
2147.1	42.4652
2150	45.5991
2152.89	47.4164
2155.78	48.9705
2158.66	51.6816
2161.55	54.8808
2164.44	57.6951
2167.32	61.2665
2170.21	61.9291
2173.09	62.6659
2175.97	62.7404
2178.85	63.8909
2181.73	63.7635
2184.61	62.6754
2187.49	61.1592
2190.37	60.2957
2193.24	58.2577
2196.12	55.8334
2198.99	53.641
2201.87	51.7812
2204.74	48.9183
2207.61	45.9495
2210.48	43.8516
2213.35	41.1524
2216.21	38.7068
2219.08	37.0192
2221.95	34.8395
2224.81	32.3239
2227.67	30.1812
2230.54	27.2454
2233.4	23.8018
2236.26	23.0876
2239.11	20.2052
2241.97	18.8751
2244.83	16.6698
2247.69	15.02
2250.54	14.1018
2253.4	12.4227
2256.25	10.4514
2259.1	9.05473
2261.95	8.65859
2264.8	8.14693
2267.65	8.12175
2270.5	8.77661
2273.34	8.86634
2276.19	9.15734
2279.03	11.0762
2281.88	11.0147
2284.72	11.0262
2287.56	10.714
2290.4	10.3
2293.24	9.78002
2296.08	9.26071
2298.92	10.4868
2301.76	9.00023
2304.59	9.55646
2307.43	9.36057
2310.26	8.04777
2313.09	7.92632
2315.92	7.32197
2318.75	6.99415
2321.58	5.94483
2324.41	6.04535
2327.24	4.98768
2330.06	6.21985
2332.89	7.18726
2335.71	8.37823
2338.54	8.54125
2341.36	8.20488
2344.18	9.40481
2347	7.88911
2349.82	8.45909
2352.64	6.66365
2355.45	5.85061
2358.27	5.47128
2361.08	6.16396
2363.9	7.22569
2366.71	6.87764
2369.52	5.45157
2372.33	5.16667
2375.14	5.20897
2377.95	4.11459
2380.76	4.07147
2383.57	5.56301
2386.37	5.32669
2389.18	4.69087
2391.98	4.71039
2394.79	4.07107
2397.59	5.37933
2400.39	6.45373
2403.19	5.28051
2405.99	5.13835
2408.78	4.0414
2411.58	3.77026
2414.38	3.1303
2417.17	2.67085
2419.97	2.56955
2422.76	3.25756
2425.55	3.20567
2428.34	5.38265
2431.13	5.66869
2433.92	4.71972
2436.71	4.87483
2439.49	5.10176
2442.28	6.5911
2445.06	5.93196
2447.85	5.68748
2450.63	6.7216
2453.41	7.405
2456.19	6.44452
2458.97	7.76954
2461.75	7.79878
2464.53	7.25542
2467.31	7.66275
2470.08	6.30746
2472.86	5.8123
2475.63	5.20784
2478.4	5.65528
2481.17	4.41623
2483.94	4.76457
2486.72	5.81444
2489.48	6.18411
2492.25	6.80025
2495.02	7.99284
2497.79	8.06685
2500.55	8.45414
2503.31	8.77955
2506.08	8.38731
2508.84	8.67798
2511.6	7.63986
2514.36	6.85227
2517.12	6.0775
2519.88	5.63012
2522.63	5.56657
2525.39	5.82603
2528.14	5.82725
2530.9	4.55251
2533.65	3.67961
2536.4	3.30196
2539.15	2.83095
2541.9	2.73066
2544.65	2.47816
2547.4	3.06373
2550.15	3.21681
2552.89	4.87613
2555.64	6.97843
2558.38	7.14084
2561.12	9.07484
2563.87	10.4532
2566.61	12.0178
2569.35	14.3203
2572.09	14.7358
2574.83	14.6543
2577.56	14.2858
2580.3	14.3934
2583.04	13.6833
2585.77	14.5154
2588.5	13.6115
2591.23	12.7549
2593.97	12.6199
2596.7	12.2527
2599.43	11.7357
2602.15	10.8638
2604.88	10.0572
2607.61	8.70706
2610.33	7.78176
2613.06	6.74521
2615.78	6.94586
2618.51	6.4807
2621.23	6.26941
2623.95	6.09184
2626.67	5.22915
2629.39	5.51631
2632.1	6.09135
2634.82	6.42054
2637.54	6.1474
2640.25	5.88376
2642.97	6.711
2645.68	7.71845
2648.39	7.54955
2651.1	8.54397
2653.81	8.44204
2656.52	8.44641
2659.23	9.52939
2661.94	10.7572
2664.64	11.4169
2667.35	11.8926
2670.05	11.5624
2672.76	11.6345
2675.46	13.1044
2678.16	13.7028
2680.86	14.3687
2683.56	15.4796
2686.26	15.7006
2688.96	15.8354
2691.65	16.265
2694.35	17.4696
2697.04	18.1654
2699.74	19.912
2702.43	21.551
2705.12	22.4264
2707.81	24.6851
2710.5	25.9988
2713.19	25.9887
2715.88	26.6629
2718.57	27.003
2721.25	27.0531
2723.94	26.7401
2726.62	26.3469
2729.3	25.8231
2731.99	24.5636
2734.67	23.5456
2737.35	22.3781
2740.03	20.1273
2742.71	17.8747
2745.38	15.1252
2748.06	12.2649
2750.74	10.1972
2753.41	8.19717
2756.09	6.69871
2758.76	5.53956
2761.43	4.45313
2764.1	3.92827
2766.77	2.93999
2769.44	2.28865
2772.11	1.71942
2774.77	1.23962
2777.44	1.05634
2780.11	1.32033
2782.77	0.701384
2785.43	0.858014
2788.1	1.45538
2790.76	1.55218
2793.42	1.56984
2796.08	1.58349
2798.74	2.16832
2801.4	1.90573
2804.05	0.180884
2806.71	-2.007
2809.36	-4.51244
2812.02	-5.34408
2814.67	-4.99038
2817.32	0.145251
2819.97	10.2927
2822.62	24.601
2825.27	42.9511
2827.92	63.1215
2830.57	85.4069
2833.22	109.504
2835.86	134.7
2838.51	161.719
2841.15	188.011
2843.79	214.618
2846.43	241.481
2849.08	269.685
2851.72	298.876
2854.36	327.912
2856.99	355.734
2859.63	379.07
2862.27	400.423
2864.9	417.04
2867.54	431.049
2870.17	441.475
2872.8	448.792
2875.43	455.209
2878.07	463.117
2880.7	470.95
2883.32	480.667
2885.95	489.544
2888.58	497.008
2891.21	503.003
2893.83	507.717
2896.46	512.385
2899.08	518.492
2901.7	522.775
2904.32	529.378
2906.94	537.535
2909.56	548.803
2912.18	561.877
2914.8	575.406
2917.42	588.271
2920.03	596.891
2922.65	602.026
2925.26	603.54
2927.88	602.979
2930.49	598.288
2933.1	590.901
2935.71	578.841
2938.32	563.069
2940.93	545.949
2943.54	526.045
2946.14	503.578
2948.75	480.739
2951.35	455.393
2953.96	430.68
2956.56	403.378
2959.16	378.467
2961.77	354.437
2964.37	329.646
2966.96	307.681
2969.56	285.688
2972.16	267.489
2974.76	248.509
2977.35	229.749
2979.95	211.958
2982.54	193.298
2985.14	174.546
2987.73	155.948
2990.32	138.724
2992.91	120.456
2995.5	104.877
2998.09	90.005
3000.68	75.9638
3003.26	63.5662
3005.85	53.0997
3008.43	43.5811
3011.02	35.8994
3013.6	28.8598
3016.19	22.1962
3018.77	15.5788
3021.35	11.1545
3023.93	8.04861
3026.5	4.57384
3029.08	2.02833
3031.66	0.89418
3034.24	0.221556
3036.81	0.463879
3039.39	0.476211
3041.96	1.57927
3044.53	2.77913
3047.1	3.67799
3049.67	3.49366
3052.24	3.81108
3054.81	4.71639
3057.38	4.64799
3059.95	4.98909
3062.52	5.16463
3065.08	4.12264
3067.65	4.19213
3070.21	3.45854
3072.77	3.93199
3075.33	3.8106
3077.89	4.03987
3080.45	3.91617
3083.01	4.42606
3085.57	6.32431
3088.13	8.17094
3090.68	9.1954
3093.24	10.672
3095.79	13.3991
3098.35	15.4798
3100.9	18.523
3103.45	20.0227
3106	22.3752
3108.55	24.6746
3111.1	26.7579
3113.65	28.0673
3116.2	30.7406
3118.75	33.3297
3121.29	34.9001
3123.84	37.0138
3126.38	39.2688
3128.92	43.2738
3131.47	47.3127
3134.01	51.022
3136.55	55.8396
3139.09	60.5356
3141.63	66.177
3144.17	72.8746
3146.7	79.5876
3149.24	87.4404