File: data/Raman/poly_smoothed/Mb_20_x_01_1x_45s_532 nm_x100_100%_600 gr_mm_01.txt
#Acq. time (s)=	45
#Accumulations=	2
#Range (cm-¹)=	200...3150
#Windows=	2
#Auto scanning=	Off
#Autofocus=	Off
#Macrospot=	Off
#AutoExposure=	Off
#Spike filter=	Multiple accum.
#Delay time (s)=	0
#Binning=	1
#Readout mode=	Signal
#DeNoise=	Off
#ICS correction=	On
#Dark correction=	Off
#Inst. Process=	Off
#Detector Gain=	Best Dynamic Range
#Detector ADC=	20 kHz
#Detector temperature (°C)=	-69.85
#Instrument=	LabRAM HR Evol
#Detector=	Synapse
#Objective=	x100
#Grating=	600 gr/mm
#ND Filter=	100%
#Laser (nm)=	532
#Hole=	100.021
#Range=	Auto
#Laser Pol.=	No
#Raman. Pol.=	No
#Laser Pol. (°)=	-0.0007625
#Raman Pol. (°)=	89.9995
#Collection=	Microscope
#StageXY=	Marzhauser
#StageZ=	Marzhauser
#X (µm)=	-785.4
#Y (µm)=	2664.7
#Z (µm)=	584.2
#Full time(mm:ss)=	3:17
#Project=
#Sample=
#Site=
#Title=	Mb_20_x_01_2x_45s_532 nm_x100_100%_600 gr_mm
#Remark=
#Date=	18.07.2022 14:29
#Acquired=	18.07.2022 14:29:04
#Base:Fit=	16.08.2022 10:28:40
#Base:Fit=	16.08.2022 10:28:53
#Base:Fit=	16.08.2022 10:29:09
#Base:Fit=	16.08.2022 10:29:17
#Base:Fit=	16.08.2022 10:29:25
#Base:Fit=	16.08.2022 10:29:33
#Base:Sub=	16.08.2022 10:29:38
#Filter:Polynom=	16.08.2022 10:30:49
#AxisType[0]=Intens
#AxisUnit[0]=Cnt
#AxisType[1]=Spectr
#AxisUnit[1]=1/cm
200.419	14.8024
204.048	14.8361
207.678	13.2704
211.304	11.5391
214.928	9.66189
218.554	8.00104
222.176	6.46499
225.798	5.6105
229.417	4.61474
233.035	3.32604
236.653	2.93443
240.268	1.57544
243.881	2.17986
247.493	1.92549
251.103	4.23481
254.715	3.14242
258.322	1.98774
261.929	3.65027
265.534	2.97222
269.137	2.89838
272.739	3.15192
276.34	4.34865
279.939	4.1896
283.537	4.00788
287.134	5.03854
290.729	6.03163
294.323	6.59459
297.913	7.49044
301.504	7.2925
305.093	10.5587
308.682	10.8604
312.268	11.1583
315.852	12.6154
319.436	12.6754
323.018	12.8488
326.597	13.0196
330.177	14.218
333.753	16.1837
337.331	17.1322
340.906	15.9278
344.478	13.0639
348.051	12.217
351.621	11.1935
355.189	9.48383
358.757	9.29121
362.323	7.49403
365.889	7.68271
369.451	6.5342
373.012	6.88127
376.574	6.84087
380.133	6.44389
383.69	6.03359
387.245	6.07217
390.8	5.86561
394.353	6.21943
397.906	4.91668
401.456	5.28175
405.005	4.4489
408.552	4.23685
412.099	5.23803
415.643	3.92863
419.187	5.9807
422.728	5.33739
426.269	3.03011
429.806	2.35015
433.344	0.548114
436.881	1.12151
440.416	2.86729
443.949	5.15646
447.48	5.24848
451.011	5.52521
454.541	7.55517
458.069	8.94417
461.594	8.88336
465.119	10.7764
468.642	12.4335
472.165	14.8474
475.684	16.1992
479.204	17.6963
482.721	18.3948
486.239	19.3713
489.753	19.6547
493.268	20.8003
496.779	21.8001
500.289	21.5635
503.8	20.2262
507.307	19.6929
510.813	17.326
514.32	14.0271
517.823	14.536
521.325	14.5465
524.826	14.5719
528.325	13.7412
531.823	11.6139
535.32	11.8021
538.815	10.7018
542.309	10.5093
545.802	8.8109
549.293	8.22857
552.783	10.0081
556.271	10.9245
559.759	9.12642
563.245	9.2072
566.729	8.39456
570.213	8.48447
573.693	7.27863
577.173	7.85947
580.652	6.3937
584.13	4.7676
587.605	2.62119
591.08	2.23136
594.552	1.89794
598.025	0.77261
601.496	0.786067
604.964	1.89348
608.433	2.78326
611.898	3.93175
615.364	4.64945
618.827	5.39139
622.288	5.84409
625.75	6.17638
629.209	6.83678
632.667	6.42726
636.125	8.28201
639.58	8.99401
643.033	9.83508
646.485	10.6719
649.936	10.8547
653.388	11.0697
656.836	11.6237
660.283	11.3296
663.728	12.1841
667.173	11.2423
670.616	11.8899
674.057	13.4559
677.498	14.7902
680.937	15.382
684.375	17.113
687.809	19.7366
691.244	21.6561
694.678	24.4637
698.111	27.0903
701.54	28.4312
704.97	28.7615
708.398	30.187
711.826	30.991
715.25	30.0917
718.675	32.6649
722.096	33.858
725.518	34.8292
728.937	34.5958
732.357	36.4221
735.773	36.336
739.19	35.3003
742.604	34.4034
746.018	33.7958
749.429	36.387
752.839	37.4279
756.248	39.4046
759.657	40.9714
763.063	41.387
766.468	45.0076
769.871	46.7595
773.273	47.4627
776.676	49.5849
780.075	51.9563
783.474	53.9871
786.871	55.2044
790.266	57.7086
793.661	59.5914
797.054	62.7084
800.446	64.8183
803.834	67.6461
807.224	67.4075
810.612	68.7806
813.998	69.5906
817.384	68.9001
820.766	68.5027
824.149	68.5115
827.531	68.7852
830.909	70.2937
834.288	71.5372
837.666	69.4416
841.041	68.0146
844.416	65.9898
847.788	64.0479
851.161	61.2398
854.53	58.156
857.901	54.885
861.268	54.2686
864.633	53.446
868	49.3441
871.363	48.1777
874.725	47.2134
878.088	45.9138
881.447	43.4092
884.805	42.4304
888.162	41.0863
891.518	39.3447
894.872	39.6718
898.225	39.178
901.577	39.7483
904.928	39.4107
908.277	39.8552
911.625	41.4321
914.972	42.8372
918.318	41.6195
921.662	41.8025
925.005	40.4476
928.347	39.563
931.686	38.5156
935.025	38.0623
938.363	37.1907
941.698	37.0029
945.034	36.1049
948.368	33.2684
951.699	31.7701
955.031	31.692
958.36	30.2351
961.689	27.8228
965.016	28.4216
968.343	28.967
971.666	29.0531
974.991	30.3644
978.312	31.998
981.632	32.5228
984.953	32.7067
988.27	31.4245
991.587	32.1798
994.902	31.1389
998.216	28.0603
1001.53	23.9154
1004.84	21.3501
1008.15	23.0223
1011.46	31.2687
1014.77	42.8275
1018.07	56.8269
1021.38	71.2434
1024.68	84.2698
1027.99	97.0248
1031.29	107.551
1034.59	113.968
1037.89	118.71
1041.18	120.488
1044.48	123.318
1047.77	122.737
1051.07	118.082
1054.36	114.439
1057.65	107.347
1060.94	96.8831
1064.23	84.2807
1067.52	70.5404
1070.8	55.9802
1074.09	39.3953
1077.37	23.0991
1080.65	8.28528
1083.93	-0.606386
1087.21	-4.43419
1090.49	-1.66959
1093.77	3.18764
1097.04	7.62271
1100.32	11.3084
1103.59	15.3455
1106.86	17.3621
1110.13	17.2106
1113.4	16.0197
1116.67	14.7696
1119.94	14.6999
1123.2	15.6779
1126.47	14.3233
1129.73	12.1337
1132.99	12.4857
1136.25	11.6392
1139.51	9.52119
1142.77	7.86349
1146.03	6.89515
1149.28	5.93343
1152.54	5.20514
1155.79	2.71083
1159.04	1.49738
1162.29	1.14735
1165.54	0.319412
1168.79	1.69924
1172.04	2.06862
1175.28	3.96694
1178.53	5.10267
1181.77	7.0743
1185.01	7.62588
1188.25	9.98006
1191.49	10.6799
1194.73	10.6354
1197.96	11.9654
1201.2	12.5118
1204.43	14.1128
1207.66	14.4024
1210.9	17.8314
1214.13	21.2339
1217.36	22.8654
1220.58	25.405
1223.81	28.5102
1227.04	31.6103
1230.26	33.4071
1233.48	34.3913
1236.71	37.5599
1239.93	39.7289
1243.14	40.4255
1246.36	41.9735
1249.58	42.7053
1252.8	43.5273
1256.01	45.537
1259.22	45.7615
1262.43	48.7265
1265.64	50.7645
1268.85	50.9502
1272.06	51.4518
1275.27	52.1386
1278.48	55.2922
1281.68	55.6881
1284.88	57.5158
1288.08	61.076
1291.28	62.929
1294.48	64.1506
1297.68	65.9491
1300.88	69.8695
1304.07	69.8839
1307.27	71.7284
1310.46	73.8885
1313.65	75.8806
1316.85	76.9033
1320.03	76.8434
1323.22	75.3273
1326.41	73.2707
1329.6	72.0152
1332.78	71.6139
1335.96	68.5887
1339.15	65.7756
1342.33	64.3766
1345.51	60.7863
1348.69	58.4182
1351.86	54.9768
1355.04	53.2869
1358.21	49.7266
1361.39	47.2701
1364.56	46.2148
1367.73	44.2031
1370.9	42.0513
1374.07	40.352
1377.24	41.5964
1380.41	41.7544
1383.57	42.6891
1386.73	46.6821
1389.9	47.8282
1393.06	48.277
1396.22	49.718
1399.38	50.6325
1402.54	50.8864
1405.69	52.9695
1408.85	55.1855
1412	56.2255
1415.16	59.3134
1418.31	62.2725
1421.46	65.5429
1424.61	70.3057
1427.76	74.7919
1430.9	78.6128
1434.05	83.2352
1437.2	87.6766
1440.34	90.7092
1443.48	92.0085
1446.62	92.0893
1449.76	91.9784
1452.9	92.6784
1456.04	92.6111
1459.17	91.3326
1462.31	89.3336
1465.44	85.8095
1468.58	80.4383
1471.71	74.9679
1474.84	71.1874
1477.97	66.4023
1481.1	62.3881
1484.22	56.8604
1487.35	51.3992
1490.47	47.2416
1493.59	42.8383
1496.72	38.339
1499.84	36.807
1502.96	33.6248
1506.08	31.2241
1509.19	28.1256
1512.31	26.5598
1515.42	23.1414
1518.54	20.7747
1521.65	19.7233
1524.76	18.5478
1527.87	19.6224
1530.98	20.191
1534.09	21.52
1537.2	22.0076
1540.3	23.228
1543.41	25.8392
1546.51	28.5819
1549.61	32.2604
1552.71	35.8339
1555.81	37.3195
1558.91	38.6099
1562.01	38.5526
1565.1	41.1032
1568.2	43.6149
1571.29	45.2852
1574.38	47.3598
1577.48	50.2182
1580.57	52.7883
1583.65	54.363
1586.74	56.5383
1589.83	58.3109
1592.92	59.9508
1596	62.252
1599.08	62.6551
1602.16	63.1006
1605.24	62.1308
1608.32	62.5647
1611.4	64.2128
1614.48	65.6954
1617.56	67.7221
1620.63	68.7457
1623.71	69.2885
1626.78	69.3158
1629.85	69.989
1632.92	69.7589
1635.99	70.7738
1639.06	73.4247
1642.12	76.0525
1645.19	75.9797
1648.25	77.3062
1651.32	79.6276
1654.38	80.3597
1657.44	79.8542
1660.5	80.0456
1663.56	80.3419
1666.62	76.4582
1669.67	73.2541
1672.73	69.3113
1675.79	65.3437
1678.84	61.5313
1681.89	58.058
1684.94	54.6419
1687.99	50.696
1691.04	46.2708
1694.08	41.4929
1697.13	37.6008
1700.18	34.5998
1703.22	30.6004
1706.26	28.0028
1709.3	24.9081
1712.35	22.9525
1715.39	21.2545
1718.42	18.822
1721.46	17.05
1724.5	15.7331
1727.53	14.5762
1730.56	13.6122
1733.6	12.2034
1736.63	9.91798
1739.66	7.97887
1742.69	5.31565
1745.71	4.6462
1748.74	4.46527
1751.77	4.13588
1754.79	4.00183
1757.81	4.199
1760.84	4.22087
1763.86	4.50525
1766.88	3.34092
1769.9	3.92845
1772.91	4.28954
1775.93	4.06688
1778.95	4.27183
1781.96	5.5755
1784.97	5.36423
1787.99	5.4171
1791	5.59748
1794.01	6.15746
1797.01	5.19039
1800.02	5.25155
1803.03	4.78655
1806.03	4.72578
1809.04	4.26752
1812.04	4.02798
1815.04	3.70634
1818.04	3.89544
1821.04	4.98857
1824.04	5.9859
1827.04	6.70217
1830.03	6.16047
1833.03	6.14294
1836.02	6.74661
1839.02	6.44324
1842.01	7.16213
1845	6.39932
1847.99	5.81096
1850.98	6.06333
1853.96	5.37693
1856.95	5.11874
1859.94	4.35962
1862.92	5.41435
1865.9	6.67021
1868.88	6.57835
1871.86	6.50515
1874.84	6.51632
1877.82	6.46738
1880.8	7.19023
1882.58	7.0846
1885.57	7.49017
1888.56	7.56998
1891.54	6.73057
1894.53	6.4429
1897.51	5.69353
1900.5	5.13564
1903.48	3.76712
1906.46	3.93732
1909.44	2.82114
1912.42	2.44749
1915.4	2.40675
1918.37	1.81618
1921.35	2.67686
1924.32	3.26599
1927.3	3.61189
1930.27	4.31244
1933.24	4.88479
1936.21	6.88021
1939.18	7.17344
1942.15	7.71567
1945.11	8.76504
1948.08	9.39114
1951.04	10.2808
1954.01	10.4399
1956.97	10.1334
1959.93	10.0942
1962.89	7.90285
1965.85	5.87142
1968.81	5.89143
1971.77	5.06691
1974.72	4.28185
1977.68	3.98974
1980.63	3.23893
1983.58	3.90698
1986.53	4.36527
1989.48	4.82628
1992.43	3.94679
1995.38	5.59756
1998.33	6.60956
2001.27	7.53642
2004.22	8.63339
2007.16	9.76319
2010.11	12.3003
2013.05	13.5095
2015.99	14.483
2018.93	14.4371
2021.87	14.6012
2024.8	14.7376
2027.74	14.8728
2030.68	15.3398
2033.61	14.0204
2036.54	13.9128
2039.48	16.0274
2042.41	16.7032
2045.34	16.3799
2048.27	15.9569
2051.19	16.2458
2054.12	17.4169
2057.05	16.5288
2059.97	17.0531
2062.9	16.731
2065.82	17.9317
2068.74	19.1442
2071.66	19.7962
2074.58	21.6053
2077.5	20.9791
2080.41	21.3534
2083.33	20.1698
2086.24	20.0575
2089.16	20.4805
2092.07	21.0719
2094.98	22.2753
2097.89	24.1778
2100.8	25.6691
2103.71	26.0285
2106.62	26.658
2109.53	29.1216
2112.43	30.3965
2115.33	30.5315
2118.24	31.7266
2121.14	31.6551
2124.04	33.2806
2126.94	34.4974
2129.84	35.5799
2132.74	38.2977
2135.63	40.0606
2138.53	42.2683
2141.43	43.9573
2144.32	45.2398
2147.21	46.7943
2150.1	48.0371
2152.99	49.966
2155.88	52.9929
2158.77	55.2679
2161.66	58.421
2164.55	61.5493
2167.43	62.4842
2170.31	63.977
2173.2	63.9533
2176.08	64.052
2178.96	65.7162
2181.84	65.7243
2184.72	65.2129
2187.6	62.9232
2190.47	60.3394
2193.35	57.527
2196.23	55.4367
2199.1	53.5851
2201.97	51.985
2204.84	50.3094
2207.71	49.2422
2210.58	47.1248
2213.45	44.4383
2216.32	43.0302
2219.19	42.1328
2222.05	40.9225
2224.92	40.7354
2227.78	39.867
2230.64	38.5208
2233.5	38.0434
2236.36	36.0242
2239.22	34.6335
2242.08	35.4465
2244.94	34.3922
2247.79	34.1135
2250.65	33.3015
2253.5	31.6331
2256.36	28.6456
2259.21	27.3238
2262.06	26.1946
2264.91	24.3844
2267.76	24.4093
2270.6	23.6851
2273.45	22.8466
2276.3	23.0289
2279.14	22.2593
2281.98	20.7487
2284.83	18.9721
2287.67	18.7475
2290.51	16.583
2293.35	14.4329
2296.19	12.5859
2299.02	13.1411
2301.86	14.1275
2304.7	14.6175
2307.53	14.4177
2310.36	14.7702
2313.2	14.2159
2316.03	14.5938
2318.86	14.8949
2321.69	14.5885
2324.51	14.8122
2327.34	15.9856
2330.17	16.9556
2332.99	17.0482
2335.82	17.1073
2338.64	17.7506
2341.46	17.4092
2344.28	17.8336
2347.1	17.4431
2349.92	16.5573
2352.74	15.7282
2355.56	14.9309
2358.37	14.8137
2361.19	14.1018
2364	14.7319
2366.82	17.0544
2369.63	17.9068
2372.44	18.121
2375.25	17.0314
2378.06	15.9
2380.86	15.5615
2383.67	14.8035
2386.48	14.699
2389.28	14.7346
2392.09	14.0853
2394.89	14.3199
2397.69	13.2591
2400.49	12.5723
2403.29	12.4605
2406.09	11.6595
2408.89	9.68937
2411.69	8.35336
2414.48	8.27564
2417.28	8.42875
2420.07	7.28769
2422.86	6.64544
2425.65	7.01291
2428.45	6.56469
2431.23	6.14704
2434.02	6.07477
2436.81	4.96789
2439.6	4.56302
2442.38	4.55194
2445.17	5.01909
2447.95	6.10656
2450.73	7.07714
2453.52	6.38184
2456.3	7.25508
2459.08	6.95011
2461.85	7.53907
2464.63	7.06194
2467.41	6.99212
2470.19	7.14134
2472.96	6.10904
2475.73	4.89486
2478.51	5.47505
2481.28	5.14405
2484.05	5.12524
2486.82	5.05441
2489.59	3.50048
2492.35	3.01
2495.12	2.487
2497.89	0.571725
2500.65	0.425803
2503.42	-0.0958126
2506.18	-0.95677
2508.94	-0.983895
2511.7	0.588766
2514.46	0.983847
2517.22	1.0049
2519.98	0.702499
2522.73	1.1499
2525.49	1.57339
2528.25	1.91931
2531	2.04151
2533.75	0.524434
2536.5	1.91927
2539.25	3.49583
2542.01	4.38822
2544.75	6.01489
2547.5	7.4286
2550.25	9.11453
2553	10.6352
2555.74	11.3739
2558.49	12.1601
2561.23	13.176
2563.97	12.3593
2566.71	11.5491
2569.45	11.2584
2572.19	10.1425
2574.93	9.72964
2577.67	9.93552
2580.4	10.2618
2583.14	9.40146
2585.87	7.57151
2588.6	6.85176
2591.34	5.47335
2594.07	4.71995
2596.8	3.08332
2599.53	0.880005
2602.26	1.74617
2604.98	2.1658
2607.71	2.04571
2610.44	2.75615
2613.16	2.34797
2615.88	3.1728
2618.61	3.39369
2621.33	3.44843
2624.05	3.74655
2626.77	4.6431
2629.49	4.05015
2632.21	4.48733
2634.92	4.54134
2637.64	4.57142
2640.35	3.69612
2643.07	4.24289
2645.78	4.09681
2648.49	3.76487
2651.2	2.43535
2653.91	2.22251
2656.62	2.23649
2659.33	2.45518
2662.04	2.8923
2664.74	2.87328
2667.45	3.30607
2670.15	3.26988
2672.86	3.53576
2675.56	3.62601
2678.26	3.10412
2680.96	2.91382
2683.66	2.08543
2686.36	3.60274
2689.06	3.38663
2691.75	4.38226
2694.45	3.3329
2697.14	3.40201
2699.84	3.84663
2702.53	3.48094
2705.22	3.42975
2707.91	2.83168
2710.6	4.39289
2713.29	4.56943
2715.98	5.17152
2718.67	5.25738
2721.35	6.25155
2724.04	7.21081
2726.72	8.21199
2729.4	8.95918
2732.09	8.1955
2734.77	8.91022
2737.45	9.16046
2740.13	8.68972
2742.81	7.93459
2745.48	7.36861
2748.16	6.89111
2750.84	7.30095
2753.51	6.67998
2756.19	5.74187
2758.86	4.90954
2761.53	4.42747
2764.2	4.60992
2766.87	3.52948
2769.54	2.3925
2772.21	2.80166
2774.88	2.5794
2777.54	2.68139
2780.21	2.7721
2782.87	2.67189
2785.53	4.30599
2788.2	3.79243
2790.86	2.78229
2793.52	2.09984
2796.18	2.66137
2798.84	2.26776
2801.49	1.74736
2804.15	1.14772
2806.81	0.700652
2809.46	0.775489
2812.12	-0.0600852
2814.77	0.562926
2817.42	1.55929
2820.07	3.32674
2822.72	5.54462
2825.37	8.31999
2828.02	11.3857
2830.67	13.1442
2833.31	18.1619
2835.96	22.6742
2838.61	28.2127
2841.25	33.7989
2843.89	41.4034
2846.53	49.1119
2849.17	57.437
2851.81	66.4347
2854.45	73.9024
2857.09	82.2865
2859.73	91.6248
2862.36	100.331
2865	107.291
2867.64	114.309
2870.27	121.444
2872.9	127.134
2875.53	132.69
2878.16	137.046
2880.79	143.723
2883.42	148.916
2886.05	154.164
2888.68	157.7
2891.3	162.453
2893.93	166.659
2896.55	171.749
2899.18	178.181
2901.8	184.578
2904.42	191.444
2907.04	200.339
2909.66	209.425
2912.28	219.68
2914.9	230.184
2917.51	241.183
2920.13	251.319
2922.74	260.228
2925.36	268.036
2927.97	272.71
2930.59	274.83
2933.2	275.143
2935.81	273.931
2938.42	272.661
2941.02	267.139
2943.63	261.397
2946.24	253.63
2948.85	244.076
2951.45	233.732
2954.05	223.703
2956.66	212.228
2959.26	200.906
2961.86	190.664
2964.46	180.07
2967.06	168.659
2969.66	159.004
2972.26	150.162
2974.85	141.721
2977.45	134.472
2980.05	126.561
2982.64	118.848
2985.23	110.263
2987.83	101.495
2990.42	92.5457
2993.01	83.0456
2995.6	74.9925
2998.19	67.2443
3000.77	60.4852
3003.36	53.2553
3005.95	45.6105
3008.53	39.7026
3011.12	34.9645
3013.7	30.2683
3016.28	26.4389
3018.86	21.6652
3021.44	17.5537
3024.02	15.1336
3026.6	12.3097
3029.18	10.6662
3031.76	9.08035
3034.33	8.94625
3036.91	9.39042
3039.48	9.3523
3042.05	9.022
3044.63	8.93591
3047.2	10.2197
3049.77	10.4623
3052.34	10.8008
3054.91	10.7603
3057.48	11.44
3060.04	13.036
3062.61	13.2712
3065.17	13.2945
3067.74	13.0268
3070.3	13.0717
3072.87	12.2415
3075.43	11.596
3077.99	9.42211
3080.55	7.51359
3083.11	5.79357
3085.67	4.08398
3088.22	1.94076
3090.78	2.15468
3093.34	3.13771
3095.89	2.83514
3098.44	2.48095
3101	2.01732
3103.55	1.97702
3106.1	1.82676
3108.65	2.55097
3111.2	2.95488
3113.75	3.00564
3116.3	3.65448
3118.84	4.72214
3121.39	5.9537
3123.93	6.09855
3126.48	6.0183
3129.02	6.71875
3131.56	6.67025
3134.1	7.03656
3136.64	6.8969
3139.18	6.37649
3141.72	6.2914
3144.26	6.55942
3146.8	7.35463
3149.33	8.14965