File: data/Raman/poly_smoothed/Mb_20_23_13_1x_45s_532 nm_x100_100%_600 gr_mm_01.txt
#Acq. time (s)=	45
#Accumulations=	2
#Range (cm-¹)=	200...3150
#Windows=	2
#Auto scanning=	Off
#Autofocus=	Off
#Macrospot=	Off
#AutoExposure=	Off
#Spike filter=	Multiple accum.
#Delay time (s)=	0
#Binning=	1
#Readout mode=	Signal
#DeNoise=	Off
#ICS correction=	On
#Dark correction=	Off
#Inst. Process=	Off
#Detector Gain=	Best Dynamic Range
#Detector ADC=	20 kHz
#Detector temperature (°C)=	-69.85
#Instrument=	LabRAM HR Evol
#Detector=	Synapse
#Objective=	x100
#Grating=	600 gr/mm
#ND Filter=	100%
#Laser (nm)=	532
#Hole=	100.021
#Range=	Auto
#Laser Pol.=	No
#Raman. Pol.=	No
#Laser Pol. (°)=	-0.0007625
#Raman Pol. (°)=	89.9995
#Collection=	Microscope
#StageXY=	Marzhauser
#StageZ=	Marzhauser
#X (µm)=	-6980.1
#Y (µm)=	2118.5
#Z (µm)=	-74.85
#Full time(mm:ss)=	3:18
#Project=
#Sample=
#Site=
#Title=	Mb_20_23_13_2x_45s_532 nm_x100_100%_600 gr_mm
#Remark=
#Date=	13.07.2022 13:52
#Acquired=	13.07.2022 13:52:33
#Base:Fit=	10.08.2022 10:29:19
#Base:Fit=	10.08.2022 10:29:37
#Base:Sub=	10.08.2022 10:32:28
#Filter:Polynom=	16.08.2022 10:13:29
#AxisType[0]=Intens
#AxisUnit[0]=Cnt
#AxisType[1]=Spectr
#AxisUnit[1]=1/cm
200.563	15.8796
204.194	14.3184
207.821	11.1405
211.449	8.30453
215.074	5.29407
218.699	3.62085
222.321	3.91801
225.941	4.03856
229.562	3.82727
233.18	5.63171
236.796	7.26281
240.411	7.13927
244.026	8.7227
247.638	9.48496
251.248	11.583
254.857	13.1596
258.465	15.1116
262.071	17.1813
265.678	18.4783
269.282	19.3719
272.884	19.7609
276.484	19.0639
280.084	17.9116
283.682	15.4931
287.276	12.5709
290.871	11.5658
294.465	12.3001
298.057	11.4167
301.648	11.0914
305.237	10.5669
308.823	11.1125
312.41	11.4614
315.995	12.3269
319.579	13.5555
323.16	15.2343
326.741	14.8477
330.321	18.2489
333.897	19.6895
337.474	20.1852
341.048	19.8191
344.622	20.3712
348.192	18.5966
351.764	16.3822
355.332	14.4209
358.901	13.7074
362.466	13.383
366.03	11.3145
369.594	8.62944
373.155	7.81449
376.715	9.36359
380.273	11.9685
383.832	13.3361
387.388	13.8294
390.942	13.8728
394.495	13.1269
398.047	15.0858
401.597	16.2769
405.145	17.4974
408.693	19.5796
412.239	21.9283
415.783	24.0705
419.327	26.456
422.869	26.0107
426.409	24.5217
429.948	24.6518
433.486	23.7907
437.022	23.0652
440.558	22.3456
444.089	22.6188
447.622	24.5467
451.153	24.7627
454.682	25.4131
458.208	26.3228
461.735	26.9692
465.259	30.1569
468.783	31.4223
472.306	31.9253
475.825	30.7413
479.346	31.0978
482.862	30.1507
486.38	32.071
489.894	32.8735
493.407	35.6023
496.92	35.9721
500.43	37.2373
503.939	37.9769
507.448	38.935
510.954	37.4939
514.459	38.5224
517.962	38.1465
521.466	37.703
524.966	36.5917
528.466	35.0807
531.964	34.7215
535.46	33.7618
538.955	31.3374
542.449	30.6077
545.942	29.2957
549.433	27.366
552.923	25.9092
556.412	24.2129
559.899	20.6355
563.385	20.6593
566.867	18.6835
570.35	18.2547
573.832	17.3838
577.313	16.5213
580.79	15.0258
584.268	13.3531
587.745	12.2135
591.218	11.6874
594.692	10.2812
598.164	9.84125
601.634	9.10082
605.104	9.32299
608.57	9.48656
612.037	8.6686
615.501	10.0261
618.966	9.58852
622.427	9.48003
625.887	10.8345
629.348	11.0586
632.806	11.9473
636.262	8.70866
639.716	9.3396
643.172	10.3436
646.624	9.8102
650.075	11.1081
653.524	8.92048
656.972	8.11488
660.419	5.9261
663.865	4.34699
667.309	3.87768
670.752	3.51333
674.194	2.19958
677.634	1.6688
681.073	2.35802
684.511	4.63063
687.947	4.95403
691.382	6.2753
694.816	7.89226
698.247	9.1174
701.678	10.008
705.108	11.606
708.534	13.3464
711.962	16.3332
715.388	16.8176
718.81	16.1834
722.234	17.7331
725.654	18.9751
729.075	20.8812
732.492	22.2216
735.91	23.4366
739.325	25.7653
742.741	28.3247
746.153	31.5192
749.564	33.5253
752.976	36.5933
756.385	39.5124
759.792	41.5298
763.2	45.1739
766.604	48.5885
770.008	51.2138
773.41	52.4739
776.811	55.8682
780.21	55.8479
783.608	58.9052
787.005	62.0221
790.401	64.6051
793.795	67.7134
797.188	67.6834
800.58	67.2526
803.971	67.9986
807.36	69.8516
810.748	71.4353
814.135	72.442
817.518	72.0464
820.902	74.0729
824.285	72.4435
827.665	72.6165
831.045	71.013
834.424	69.4815
837.8	70.5452
841.177	69.0204
844.55	68.6607
847.924	67.8313
851.295	65.3181
854.666	64.4832
858.034	64.3689
861.403	65.2974
864.769	66.1203
868.133	66.9304
871.498	65.5306
874.86	65.4746
878.221	63.1085
881.58	58.8999
884.938	59.0348
888.297	57.7779
891.653	57.0337
895.007	56.6785
898.36	53.7264
901.712	53.2018
905.063	51.4802
908.412	50.4887
911.76	50.6098
915.107	48.9194
918.452	48.3564
921.797	48.6995
925.138	48.4393
928.48	47.1089
931.82	45.4379
935.16	42.4296
938.496	41.9979
941.833	39.961
945.168	38.1975
948.5	34.4628
951.834	34.6107
955.163	34.8198
958.494	31.3928
961.821	29.4398
965.15	30.766
968.474	32.906
971.8	36.0293
975.123	39.9104
978.446	44.4456
981.766	46.4933
985.084	49.3865
988.402	50.9574
991.72	51.6256
995.035	52.6285
998.349	52.7897
1001.66	54.9382
1004.97	54.686
1008.28	55.1662
1011.59	53.7564
1014.9	53.2963
1018.21	53.1826
1021.51	54.0913
1024.81	54.8157
1028.12	57.0019
1031.42	58.5073
1034.72	58.4631
1038.02	56.9442
1041.31	57.8703
1044.61	60.3075
1047.91	62.8005
1051.2	64.8047
1054.49	64.9617
1057.78	64.8242
1061.07	64.4998
1064.36	63.4818
1067.65	62.6742
1070.93	61.5417
1074.22	61.3944
1077.5	60.2292
1080.78	58.8128
1084.06	57.6917
1087.34	57.9054
1090.62	57.608
1093.9	58.6464
1097.17	58.4142
1100.45	56.5945
1103.72	56.1686
1106.99	55.0219
1110.27	52.5183
1113.53	49.6768
1116.8	45.4499
1120.07	42.4338
1123.33	41.6842
1126.6	39.8809
1129.86	36.4611
1133.12	33.9949
1136.38	33.0376
1139.64	32.2849
1142.9	31.7789
1146.16	29.3262
1149.41	28.0597
1152.67	25.5373
1155.92	22.5486
1159.17	19.9828
1162.42	18.518
1165.67	16.5018
1168.92	12.4899
1172.16	11.6588
1175.41	10.5545
1178.65	10.8027
1181.9	8.38205
1185.14	5.93334
1188.38	4.63558
1191.62	6.0596
1194.86	4.58302
1198.09	5.80351
1201.33	9.11247
1204.56	10.3344
1207.8	13.9218
1211.03	16.0187
1214.26	21.7963
1217.49	26.9702
1220.71	31.3326
1223.94	35.6826
1227.16	39.9027
1230.39	44.8991
1233.61	48.8068
1236.83	55.1368
1240.05	62.1686
1243.27	66.3616
1246.49	70.2168
1249.71	75.3201
1252.92	80.6948
1256.14	84.1991
1259.35	86.6836
1262.56	91.2641
1265.77	97.9609
1268.98	104.587
1272.19	109.849
1275.4	114.808
1278.6	123.378
1281.81	130.718
1285.01	137.467
1288.21	142.367
1291.41	145.563
1294.61	149.212
1297.81	150.897
1301.01	152.557
1304.2	152.887
1307.4	152.764
1310.59	153.661
1313.78	151.456
1316.97	150.25
1320.16	147.434
1323.35	141.178
1326.54	135.576
1329.72	131.009
1332.91	125.481
1336.09	120.524
1339.27	118.528
1342.45	115.576
1345.64	112.334
1348.81	107.914
1351.99	105.699
1355.17	103.801
1358.34	102.857
1361.51	98.9081
1364.69	94.1238
1367.86	91.3904
1371.03	89.7431
1374.2	88.3322
1377.37	88.0335
1380.53	85.217
1383.7	83.6073
1386.86	85.1879
1390.02	85.1024
1393.19	82.4503
1396.35	82.5321
1399.51	84.7015
1402.66	88.8745
1405.82	96.327
1408.97	107.549
1412.13	116.194
1415.28	127.97
1418.43	142.533
1421.59	155.7
1424.73	170.311
1427.88	184.842
1431.03	199.835
1434.18	214.087
1437.32	225.276
1440.46	233.756
1443.61	239.776
1446.75	242.38
1449.89	241.388
1453.03	235.249
1456.16	227.925
1459.3	215.867
1462.44	202.461
1465.57	185.884
1468.7	166.425
1471.83	147.829
1474.96	131.766
1478.09	115.241
1481.22	99.3072
1484.35	87.0306
1487.47	74.5979
1490.6	61.91
1493.72	54.5554
1496.84	47.5067
1499.96	40.8777
1503.08	37.1831
1506.2	32.526
1509.32	31.2562
1512.44	29.1638
1515.55	25.9809
1518.66	25.1796
1521.78	23.2145
1524.89	22.6917
1528	24.4071
1531.11	25.8361
1534.21	27.2657
1537.32	28.6425
1540.43	31.4237
1543.53	33.1839
1546.63	37.1269
1549.74	41.5179
1552.84	43.4675
1555.94	47.2625
1559.03	52.1664
1562.13	55.6766
1565.23	57.4581
1568.32	60.8035
1571.42	65.2918
1574.51	69.221
1577.6	72.7048
1580.69	75.7228
1583.78	77.9996
1586.87	80.3686
1589.95	81.2897
1593.04	84.7016
1596.12	86.0882
1599.21	87.7088
1602.29	88.4356
1605.37	89.1613
1608.45	89.737
1611.53	89.934
1614.6	89.0483
1617.68	89.3067
1620.75	90.6546
1623.83	92.2653
1626.9	94.1572
1629.97	98.9503
1633.04	100.946
1636.11	105.307
1639.18	109.727
1642.25	114.626
1645.31	116.966
1648.38	120.243
1651.44	121.757
1654.5	123.086
1657.56	123.829
1660.62	122.648
1663.68	121.065
1666.74	116.431
1669.8	112.505
1672.85	106.683
1675.91	100.162
1678.96	91.1048
1682.01	85.5258
1685.06	77.2869
1688.11	67.5491
1691.16	60.3958
1694.21	56.2085
1697.25	51.5244
1700.3	47.7142
1703.34	45.4154
1706.39	43.7583
1709.43	41.945
1712.47	41.5467
1715.51	40.6776
1718.54	39.8534
1721.58	38.7609
1724.62	39.2125
1727.65	38.4673
1730.68	38.2621
1733.72	35.4311
1736.75	32.293
1739.78	28.9872
1742.81	27.1384
1745.84	25.6447
1748.86	22.481
1751.89	19.64
1754.91	16.6074
1757.93	14.7417
1760.96	12.1876
1763.98	9.97937
1767	8.87448
1770.02	6.68512
1773.03	5.19899
1776.05	3.81296
1779.07	2.39534
1782.08	1.39757
1785.09	1.55473
1788.11	1.91562
1791.12	2.02104
1794.13	1.89544
1797.13	1.22748
1800.14	1.0608
1803.15	0.826184
1806.15	-0.0737294
1809.16	-0.517876
1812.16	-1.44857
1815.16	0.925262
1818.16	1.10562
1821.16	0.479439
1824.16	1.25701
1827.16	2.74167
1830.16	4.42323
1833.15	5.62093
1836.14	5.43245
1839.14	5.9403
1842.13	6.61415
1845.12	7.54662
1848.11	8.09389
1851.1	8.40569
1854.08	9.0763
1857.07	9.07331
1860.05	9.99072
1863.04	10.5082
1866.02	11.5373
1869	11.7991
1871.98	11.0099
1874.96	9.46862
1877.94	8.97375
1880.92	8.3754
1882.51	7.7326
1885.5	7.75781
1888.48	8.14004
1891.47	7.12635
1894.46	6.94633
1897.44	7.19759
1900.42	6.53887
1903.41	6.0469
1906.39	5.72783
1909.37	5.75558
1912.35	5.20874
1915.32	5.82738
1918.3	6.22233
1921.27	5.55302
1924.25	5.46713
1927.22	5.87921
1930.19	5.48031
1933.17	5.51707
1936.14	4.48565
1939.11	3.79775
1942.07	2.97061
1945.04	2.69153
1948.01	2.7574
1950.97	3.67518
1953.93	2.41397
1956.9	1.81768
1959.86	2.24197
1962.82	2.21535
1965.78	2.087
1968.74	2.25966
1971.69	1.72422
1974.65	2.50275
1977.6	2.90919
1980.56	3.39205
1983.51	4.29333
1986.46	7.1073
1989.41	7.81178
1992.36	8.97532
1995.31	8.7811
1998.26	8.45327
2001.2	7.47588
2004.15	6.80522
2007.09	7.41582
2010.04	7.72234
2012.98	8.1403
2015.92	7.40328
2018.86	6.32437
2021.8	5.49655
2024.73	5.05165
2027.67	4.48578
2030.61	4.23404
2033.54	4.78581
2036.47	5.031
2039.4	5.13793
2042.33	5.71975
2045.27	6.00349
2048.19	7.27396
2051.12	7.62901
2054.05	8.97914
2056.97	11.1149
2059.9	12.2027
2062.82	11.6917
2065.74	11.6193
2068.67	10.3192
2071.59	10.8337
2074.51	11.4724
2077.42	12.8918
2080.34	14.3289
2083.26	14.7265
2086.17	14.2921
2089.09	15.7704
2092	15.9521
2094.91	16.6954
2097.82	16.4301
2100.73	17.0691
2103.64	19.3052
2106.55	19.6034
2109.45	22.2144
2112.36	22.9427
2115.26	26.0519
2118.17	27.5353
2121.07	29.7424
2123.97	32.0426
2126.87	33.9787
2129.77	35.2371
2132.67	37.9237
2135.56	39.3684
2138.46	41.1941
2141.35	44.5954
2144.25	49.0995
2147.14	53.1766
2150.03	56.2097
2152.92	60.6581
2155.81	63.4065
2158.7	65.2272
2161.59	67.1949
2164.47	70.0779
2167.36	70.2125
2170.24	72.5942
2173.13	74.464
2176.01	75.2082
2178.89	74.7795
2181.77	74.7453
2184.65	73.7262
2187.53	71.2179
2190.4	69.158
2193.28	66.7335
2196.16	62.9699
2199.03	59.5621
2201.9	55.8916
2204.77	52.7677
2207.64	49.4089
2210.51	46.5619
2213.38	44.0793
2216.25	40.4698
2219.12	36.5056
2221.98	33.091
2224.85	31.2729
2227.71	28.1464
2230.57	26.2929
2233.43	24.3929
2236.29	21.9965
2239.15	21.3387
2242.01	20.8805
2244.87	20.0877
2247.72	19.3424
2250.58	19.7084
2253.43	19.4159
2256.29	19.3489
2259.14	19.2574
2261.99	19.09
2264.84	18.8586
2267.69	17.3925
2270.53	17.316
2273.38	16.6005
2276.23	16.0329
2279.07	14.8077
2281.91	13.31
2284.76	11.5997
2287.6	10.5659
2290.44	9.6913
2293.28	8.16831
2296.12	7.86322
2298.96	8.01007
2301.79	9.33067
2304.63	9.61793
2307.46	10.3323
2310.3	11.2858
2313.13	11.2587
2315.96	12.0013
2318.79	12.3555
2321.62	12.4486
2324.45	11.3751
2327.27	10.7316
2330.1	9.03538
2332.92	8.34729
2335.75	8.84763
2338.57	8.19158
2341.39	8.04065
2344.21	5.60834
2347.04	4.58173
2349.85	3.29266
2352.67	1.78537
2355.49	0.713089
2358.3	0.989873
2361.12	0.454654
2363.93	1.34422
2366.75	2.38176
2369.56	3.34791
2372.37	3.59494
2375.18	3.21987
2377.99	3.54376
2380.8	3.26525
2383.6	2.51935
2386.41	2.46168
2389.21	1.82885
2392.02	0.491573
2394.82	1.37262
2397.62	1.78219
2400.42	1.74528
2403.22	3.2916
2406.02	2.93651
2408.82	3.01798
2411.62	3.08663
2414.41	3.14134
2417.21	3.23296
2420	2.13784
2422.79	2.33323
2425.59	3.88879
2428.38	5.8486
2431.17	4.95285
2433.95	5.79883
2436.74	5.58048
2439.53	6.19807
2442.31	5.39316
2445.1	6.12752
2447.88	5.29648
2450.67	4.4786
2453.45	2.96105
2456.23	2.37016
2459.01	2.6968
2461.79	2.92059
2464.57	2.16353
2467.34	2.11247
2470.12	1.39327
2472.89	0.970808
2475.67	-0.131401
2478.44	0.300348
2481.21	-0.667703
2483.98	0.282471
2486.75	0.119946
2489.52	-0.427829
2492.29	1.10399
2495.05	1.1419
2497.82	-0.0607489
2500.58	-0.573054
2503.35	0.317009
2506.11	-0.382293
2508.87	0.393373
2511.63	1.39397
2514.39	2.05928
2517.15	2.27476
2519.91	2.98439
2522.67	3.04189
2525.42	3.11242
2528.18	3.80074
2530.93	2.97657
2533.69	3.23189
2536.44	4.50395
2539.19	5.06604
2541.94	5.64479
2544.69	4.69744
2547.44	5.57285
2550.18	6.1588
2552.93	6.32662
2555.67	5.92619
2558.42	5.02611
2561.16	4.05823
2563.9	2.66956
2566.64	3.54163
2569.38	3.60883
2572.12	4.00283
2574.86	3.69538
2577.6	5.53535
2580.33	6.52203
2583.07	7.75964
2585.8	8.74892
2588.54	8.53928
2591.27	7.9421
2594	7.62045
2596.73	8.10281
2599.46	7.6286
2602.19	7.18499
2604.92	8.15047
2607.64	7.1671
2610.37	7.47511
2613.09	7.45336
2615.82	7.27192
2618.54	8.08104
2621.26	8.0777
2623.98	7.36507
2626.7	7.50328
2629.42	8.4505
2632.14	8.82904
2634.86	8.58045
2637.57	9.83014
2640.29	11.4366
2643	12.8917
2645.71	13.7935
2648.43	14.9474
2651.14	13.8082
2653.85	13.5091
2656.56	11.6264
2659.26	9.91524
2661.97	8.63684
2664.68	8.08911
2667.38	7.27433
2670.09	7.28289
2672.79	8.96004
2675.49	8.87946
2678.19	9.48796
2680.89	9.57801
2683.59	10.0235
2686.29	10.2809
2688.99	11.1563
2691.69	11.9076
2694.38	13.4288
2697.08	14.4528
2699.77	16.1638
2702.46	18.0343
2705.15	20.2821
2707.85	21.2873
2710.54	22.6647
2713.22	22.7068
2715.91	23.8113
2718.6	23.6906
2721.29	23.5624
2723.97	22.5258
2726.66	23.1901
2729.34	23.1789
2732.02	24.3267
2734.7	23.4299
2737.38	23.0394
2740.06	22.1215
2742.74	20.1902
2745.42	18.5442
2748.09	17.0244
2750.77	15.1176
2753.45	14.5553
2756.12	12.8096
2758.79	10.9285
2761.46	8.55725
2764.14	7.73785
2766.8	7.58973
2769.47	6.18771
2772.14	5.17023
2774.81	2.79137
2777.48	2.34021
2780.14	1.75245
2782.8	0.951136
2785.47	0.641051
2788.13	-0.098189
2790.79	-0.320331
2793.45	-0.522098
2796.11	0.0236816
2798.77	1.09224
2801.43	2.04888
2804.09	3.01079
2806.74	2.82191
2809.4	2.53069
2812.05	2.97009
2814.71	4.12728
2817.36	7.93266
2820.01	15.7346
2822.66	27.0426
2825.31	41.657
2827.96	58.3026
2830.6	77.3029
2833.25	98.7712
2835.9	120.52
2838.54	144.734
2841.18	169.419
2843.83	196.648
2846.47	222.624
2849.11	247.958
2851.75	274.374
2854.39	301.156
2857.03	324.971
2859.66	349.107
2862.3	370.335
2864.94	388.554
2867.57	403.367
2870.2	414.974
2872.84	425.393
2875.47	434.409
2878.1	442.577
2880.73	451.3
2883.36	462.137
2885.99	472.747
2888.61	484.402
2891.24	493.841
2893.86	503.807
2896.49	513.03
2899.11	524.606
2901.73	535.83
2904.36	549.644
2906.98	563.48
2909.6	580.806
2912.21	596.562
2914.83	612.836
2917.45	628.233
2920.07	639.99
2922.68	648.842
2925.29	653.773
2927.91	655.411
2930.52	651.583
2933.13	644.843
2935.74	636.581
2938.35	624.628
2940.96	606.606
2943.57	586.901
2946.18	565.613
2948.78	541.127
2951.39	517.766
2953.99	489.698
2956.59	463.052
2959.2	435.222
2961.8	409.652
2964.4	384.293
2967	359.551
2969.6	337.498
2972.19	316.535
2974.79	296.831
2977.39	276.78
2979.98	254.904
2982.58	234.017
2985.17	213.212
2987.76	192.639
2990.35	173.554
2992.94	154.533
2995.53	136.595
2998.12	120.907
3000.71	104.451
3003.3	88.1112
3005.88	74.2796
3008.47	63.1491
3011.05	52.2657
3013.64	44.3548
3016.22	37.8046
3018.8	30.7551
3021.38	25.3846
3023.96	19.3759
3026.54	14.6369
3029.12	11.3361
3031.69	10.21
3034.27	7.99446
3036.84	7.32439
3039.42	6.91238
3041.99	6.85722
3044.57	7.9111
3047.14	9.70274
3049.71	11.5532
3052.28	12.034
3054.85	11.7132
3057.41	11.7034
3059.98	11.4957
3062.55	11.3449
3065.11	11.258
3067.68	9.97918
3070.24	9.51731
3072.8	9.02904
3075.36	9.06408
3077.93	8.82238
3080.49	6.67192
3083.04	5.00528
3085.6	3.06691
3088.16	2.17268
3090.72	1.38422
3093.27	1.48254
3095.83	1.01155
3098.38	1.03476
3100.93	2.92145
3103.49	4.2308
3106.04	6.26171
3108.59	9.13701
3111.14	11.383
3113.69	13.7146
3116.23	14.7249
3118.78	16.3835
3121.33	19.4969
3123.87	21.6086
3126.41	24.7321
3128.96	27.0471
3131.5	28.4448
3134.04	31.5793
3136.58	33.945
3139.12	36.5623
3141.66	38.1554
3144.2	40.2184
3146.74	42.2231
3149.27	45.2682