File: data/Raman/poly_smoothed/Mb_20_23_31_1x_45s_532 nm_x100_100%_600 gr_mm_01.txt
#Acq. time (s)=	45
#Accumulations=	2
#Range (cm-¹)=	200...3150
#Windows=	2
#Auto scanning=	Off
#Autofocus=	Off
#Macrospot=	Off
#AutoExposure=	Off
#Spike filter=	Multiple accum.
#Delay time (s)=	0
#Binning=	1
#Readout mode=	Signal
#DeNoise=	Off
#ICS correction=	On
#Dark correction=	Off
#Inst. Process=	Off
#Detector Gain=	Best Dynamic Range
#Detector ADC=	20 kHz
#Detector temperature (°C)=	-69.85
#Instrument=	LabRAM HR Evol
#Detector=	Synapse
#Objective=	x100
#Grating=	600 gr/mm
#ND Filter=	100%
#Laser (nm)=	532
#Hole=	100.021
#Range=	Auto
#Laser Pol.=	No
#Raman. Pol.=	No
#Laser Pol. (°)=	-0.0007625
#Raman Pol. (°)=	89.9995
#Collection=	Microscope
#StageXY=	Marzhauser
#StageZ=	Marzhauser
#X (µm)=	-6909.7
#Y (µm)=	1989.2
#Z (µm)=	-75.25
#Full time(mm:ss)=	3:19
#Project=
#Sample=
#Site=
#Title=	Mb_20_23_31_2x_45s_532 nm_x100_100%_600 gr_mm
#Remark=
#Date=	13.07.2022 15:34
#Acquired=	13.07.2022 15:34:26
#Base:Fit=	10.08.2022 10:29:37
#Base:Sub=	10.08.2022 10:34:43
#Filter:Polynom=	16.08.2022 10:13:29
#AxisType[0]=Intens
#AxisUnit[0]=Cnt
#AxisType[1]=Spectr
#AxisUnit[1]=1/cm
200.563	1.55616
204.194	5.42382
207.821	7.07825
211.449	8.30157
215.074	9.44382
218.699	9.99854
222.321	8.65613
225.941	8.17639
229.562	8.88671
233.18	9.22503
236.796	7.79512
240.411	7.51278
244.026	8.85399
247.638	8.69109
251.248	7.52955
254.857	7.49892
258.465	8.82934
262.071	9.07158
265.678	8.68905
269.282	9.28222
272.884	7.45541
276.484	8.3488
280.084	7.93672
283.682	6.35942
287.276	6.05411
290.871	7.18269
294.465	8.66426
298.057	9.40145
301.648	9.332
305.237	8.10884
308.823	10.0044
312.41	9.66389
315.995	11.6705
319.579	13.9529
323.16	14.5294
326.741	15.4774
330.321	17.0866
333.897	18.1698
337.474	18.1054
341.048	16.8494
344.622	17.0212
348.192	15.2343
351.764	13.3501
355.332	12.102
358.901	9.92431
362.466	8.69785
366.03	6.28396
369.594	4.56604
373.155	3.68918
376.715	2.60384
380.273	0.881018
383.832	-0.154745
387.388	0.531777
390.942	-0.404186
394.495	3.13474
398.047	4.02146
401.597	4.55931
405.145	5.89333
408.693	7.05738
412.239	6.57264
415.783	6.4837
419.327	7.69789
422.869	8.06856
426.409	7.51005
429.948	7.96796
433.486	7.47904
437.022	8.26603
440.558	8.17372
444.089	6.4792
447.622	6.62563
451.153	6.2316
454.682	4.85818
458.208	4.06305
461.735	3.80509
465.259	2.57958
468.783	5.2091
472.306	7.00438
475.825	7.98835
479.346	9.07935
482.862	9.07582
486.38	9.58422
489.894	11.0945
493.407	12.1842
496.92	13.2395
500.43	14.999
503.939	15.6784
507.448	16.5584
510.954	17.8664
514.459	19.0043
517.962	19.8676
521.466	20.6482
524.966	19.7966
528.466	19.8267
531.964	17.8387
535.46	16.1586
538.955	14.4297
542.449	12.6257
545.942	12.7926
549.433	11.2686
552.923	9.6538
556.412	7.7213
559.899	5.56561
563.385	4.06322
566.867	5.64856
570.35	6.72961
573.832	7.50262
577.313	7.10324
580.79	8.70711
584.268	9.86308
587.745	10.5397
591.218	9.15631
594.692	11.1566
598.164	10.7538
601.634	10.8985
605.104	11.2239
608.57	9.19378
612.037	8.71407
615.501	7.5899
618.966	6.27955
622.427	6.59795
625.887	6.60574
629.348	6.98759
632.806	5.85761
636.262	4.37722
639.716	3.69896
643.172	4.14661
646.624	6.13209
650.075	8.57636
653.524	9.98822
656.972	12.1504
660.419	13.9354
663.865	14.6949
667.309	18.4071
670.752	19.8455
674.194	19.1758
677.634	19.8381
681.073	20.1555
684.511	20.6385
687.947	23.4851
691.382	23.7917
694.816	25.6166
698.247	26.1699
701.678	28.4319
705.108	29.3321
708.534	31.9972
711.962	34.2385
715.388	35.1197
718.81	36.5349
722.234	37.3136
725.654	38.8525
729.075	41.4646
732.492	43.7921
735.91	45.6559
739.325	47.2461
742.741	50.1603
746.153	51.0345
749.564	54.2996
752.976	57.0417
756.385	57.0355
759.792	57.8667
763.2	60.6997
766.604	63.2456
770.008	67.1334
773.41	69.8021
776.811	72.6846
780.21	76.5705
783.608	79.3066
787.005	82.1939
790.401	85.0023
793.795	87.7292
797.188	89.3375
800.58	89.8015
803.971	91.0847
807.36	89.7541
810.748	90.3622
814.135	90.237
817.518	89.5151
820.902	88.0951
824.285	86.8829
827.665	86.3226
831.045	85.0907
834.424	79.3981
837.8	80.1699
841.177	78.9431
844.55	78.8747
847.924	79.4485
851.295	79.1098
854.666	79.6194
858.034	80.286
861.403	81.4211
864.769	80.787
868.133	80.0402
871.498	79.7189
874.86	79.1921
878.221	79.1081
881.58	76.8025
884.938	74.737
888.297	73.8852
891.653	72.6138
895.007	70.944
898.36	72.1718
901.712	71.9322
905.063	70.0173
908.412	68.8932
911.76	65.8732
915.107	62.9257
918.452	66.0613
921.797	68.2033
925.138	66.1488
928.48	65.2182
931.82	64.2066
935.16	62.197
938.496	61.1942
941.833	59.0533
945.168	56.0261
948.5	54.0858
951.834	52.2652
955.163	48.7587
958.494	45.6535
961.821	43.667
965.15	41.0208
968.474	40.4558
971.8	40.4426
975.123	40.525
978.446	41.2676
981.766	41.3747
985.084	40.3012
988.402	39.5283
991.72	38.2477
995.035	38.4097
998.349	39.5483
1001.66	39.338
1004.97	39.1907
1008.28	39.7361
1011.59	39.802
1014.9	41.7132
1018.21	41.3442
1021.51	41.0966
1024.81	40.4439
1028.12	41.0961
1031.42	41.0885
1034.72	40.6535
1038.02	42.3739
1041.31	43.3768
1044.61	44.524
1047.91	45.0466
1051.2	47.0902
1054.49	47.1439
1057.78	47.6214
1061.07	46.1832
1064.36	44.0314
1067.65	41.202
1070.93	39.952
1074.22	38.192
1077.5	36.7954
1080.78	36.9639
1084.06	36.7315
1087.34	36.01
1090.62	35.2181
1093.9	35.7942
1097.17	35.6165
1100.45	34.8969
1103.72	34.7943
1106.99	36.736
1110.27	37.7351
1113.53	37.3543
1116.8	37.4388
1120.07	36.5894
1123.33	35.0947
1126.6	35.3895
1129.86	35.3305
1133.12	34.2721
1136.38	34.0288
1139.64	32.9829
1142.9	31.5102
1146.16	29.7466
1149.41	25.8372
1152.67	23.2095
1155.92	21.3475
1159.17	20.6887
1162.42	18.7229
1165.67	18.0051
1168.92	17.865
1172.16	16.4683
1175.41	16.6868
1178.65	14.9638
1181.9	14.7236
1185.14	13.5856
1188.38	12.6467
1191.62	10.2486
1194.86	8.98763
1198.09	7.73735
1201.33	7.81202
1204.56	8.70758
1207.8	12.1898
1211.03	14.6458
1214.26	17.8577
1217.49	20.1094
1220.71	21.9289
1223.94	25.6265
1227.16	27.1417
1230.39	28.0875
1233.61	31.7889
1236.83	34.5952
1240.05	37.9898
1243.27	40.6442
1246.49	43.2616
1249.71	44.3042
1252.92	43.9674
1256.14	44.916
1259.35	45.4108
1262.56	44.0306
1265.77	43.6137
1268.98	44.9041
1272.19	44.9473
1275.4	46.95
1278.6	48.7545
1281.81	50.3389
1285.01	53.1829
1288.21	54.4713
1291.41	56.4364
1294.61	56.9111
1297.81	57.8493
1301.01	59.9741
1304.2	60.5632
1307.4	60.6612
1310.59	60.4006
1313.78	60.7887
1316.97	61.8557
1320.16	61.6978
1323.35	58.9747
1326.54	56.8177
1329.72	53.4961
1332.91	53.1318
1336.09	52.1961
1339.27	50.1585
1342.45	49.21
1345.64	47.4535
1348.81	47.1954
1351.99	47.5894
1355.17	46.532
1358.34	46.0795
1361.51	45.9993
1364.69	43.4396
1367.86	42.5172
1371.03	42.149
1374.2	40.1234
1377.37	38.1729
1380.53	37.496
1383.7	35.5906
1386.86	34.3187
1390.02	33.2106
1393.19	33.6823
1396.35	31.6598
1399.51	30.7528
1402.66	31.7583
1405.82	33.6346
1408.97	36.1483
1412.13	39.1333
1415.28	42.8659
1418.43	46.498
1421.59	51.8331
1424.73	56.9382
1427.88	63.5916
1431.03	70.6152
1434.18	75.7842
1437.32	79.4406
1440.46	82.6906
1443.61	84.611
1446.75	86.1552
1449.89	85.9841
1453.03	82.3706
1456.16	79.2136
1459.3	74.4574
1462.44	69.6568
1465.57	65.2314
1468.7	59.7396
1471.83	52.5805
1474.96	45.2263
1478.09	39.8663
1481.22	34.6699
1484.35	29.7341
1487.47	24.3342
1490.6	20.8636
1493.72	17.8133
1496.84	16.135
1499.96	14.8402
1503.08	14.086
1506.2	14.3014
1509.32	13.8017
1512.44	11.8794
1515.55	11.3644
1518.66	10.6308
1521.78	11.0489
1524.89	10.6139
1528	10.8381
1531.11	11.5791
1534.21	11.6841
1537.32	13.5458
1540.43	16.8676
1543.53	17.0847
1546.63	17.2672
1549.74	18.4559
1552.84	20.7421
1555.94	22.0175
1559.03	22.8579
1562.13	22.7656
1565.23	23.7407
1568.32	24.3861
1571.42	25.6968
1574.51	27.2471
1577.6	29.1669
1580.69	29.6217
1583.78	29.6697
1586.87	28.6629
1589.95	28.938
1593.04	29.338
1596.12	29.8483
1599.21	30.1215
1602.29	30.573
1605.37	32.1045
1608.45	32.4961
1611.53	34.0781
1614.6	34.3655
1617.68	34.8422
1620.75	36.0267
1623.83	38.138
1626.9	39.9418
1629.97	39.7939
1633.04	41.452
1636.11	42.2666
1639.18	43.8786
1642.25	46.1592
1645.31	48.5496
1648.38	52.3596
1651.44	53.0893
1654.5	53.6033
1657.56	52.4193
1660.62	51.0764
1663.68	50.7335
1666.74	48.7058
1669.8	46.1834
1672.85	43.732
1675.91	41.1413
1678.96	39.1419
1682.01	35.8353
1685.06	32.1137
1688.11	28.4021
1691.16	24.2983
1694.21	21.9103
1697.25	19.5557
1700.3	15.9326
1703.34	12.0931
1706.39	10.4825
1709.43	9.15491
1712.47	8.22856
1715.51	8.00051
1718.54	8.6517
1721.58	9.20702
1724.62	9.95899
1727.65	10.2456
1730.68	9.85616
1733.72	9.09479
1736.75	9.97594
1739.78	9.43898
1742.81	9.48446
1745.84	9.18654
1748.86	8.8641
1751.89	9.73156
1754.91	9.21869
1757.93	7.71013
1760.96	7.67909
1763.98	7.06288
1767	5.80377
1770.02	4.77603
1773.03	3.31021
1776.05	2.36217
1779.07	1.83537
1782.08	0.856633
1785.09	0.547397
1788.11	0.209088
1791.12	1.08644
1794.13	0.60968
1797.13	0.59221
1800.14	1.49432
1803.15	1.54523
1806.15	1.55641
1809.16	2.39434
1812.16	2.69788
1815.16	2.97044
1818.16	3.4703
1821.16	3.14011
1824.16	4.03645
1827.16	4.63929
1830.16	4.17991
1833.15	5.23071
1836.14	5.98926
1839.14	5.63458
1842.13	6.00339
1845.12	6.06848
1848.11	6.39182
1851.1	6.42165
1854.08	5.84869
1857.07	5.55176
1860.05	5.15801
1863.04	5.56468
1866.02	4.71804
1869	4.79648
1871.98	4.71478
1874.96	4.52325
1877.94	3.51255
1880.92	3.00109
1882.51	2.38058
1885.5	2.14978
1888.48	1.53755
1891.47	0.780828
1894.46	0.323624
1897.44	1.00096
1900.42	0.703706
1903.41	1.16632
1906.39	1.18814
1909.37	1.79309
1912.35	2.14515
1915.32	2.36139
1918.3	3.15646
1921.27	3.43598
1924.25	3.64022
1927.22	3.73017
1930.19	4.39415
1933.17	3.84591
1936.14	3.84026
1939.11	4.29866
1942.07	4.13404
1945.04	2.72553
1948.01	2.98268
1950.97	2.83136
1953.93	2.20528
1956.9	1.5577
1959.86	1.41602
1962.82	1.20081
1965.78	0.264659
1968.74	0.573746
1971.69	-0.184999
1974.65	-0.00407294
1977.6	-0.259139
1980.56	-0.650675
1983.51	-1.0066
1986.46	-0.199984
1989.41	-0.0802277
1992.36	0.593512
1995.31	0.98847
1998.26	2.03552
2001.2	2.78404
2004.15	2.69506
2007.09	2.32061
2010.04	3.06918
2012.98	4.54664
2015.92	3.65546
2018.86	4.4212
2021.8	5.01034
2024.73	4.04062
2027.67	3.51329
2030.61	4.16761
2033.54	4.23845
2036.47	4.00035
2039.4	4.61335
2042.33	5.08289
2045.27	3.76648
2048.19	3.43459
2051.12	2.81676
2054.05	2.4637
2056.97	3.25793
2059.9	3.80441
2062.82	4.08879
2065.74	5.15953
2068.67	5.76159
2071.59	6.78481
2074.51	6.74022
2077.42	8.22108
2080.34	8.56362
2083.26	10.4655
2086.17	10.8635
2089.09	12.5685
2092	13.3238
2094.91	14.3233
2097.82	14.404
2100.73	15.9692
2103.64	17.2631
2106.55	18.4172
2109.45	19.2222
2112.36	19.1577
2115.26	19.0515
2118.17	19.9741
2121.07	21.0831
2123.97	21.4642
2126.87	20.9421
2129.77	23.0226
2132.67	23.8011
2135.56	25.1155
2138.46	26.7258
2141.35	28.8451
2144.25	31.3038
2147.14	33.2652
2150.03	34.1033
2152.92	35.7151
2155.81	37.0059
2158.7	39.762
2161.59	41.6007
2164.47	42.8429
2167.36	43.57
2170.24	44.7503
2173.13	46.0464
2176.01	46.2312
2178.89	46.6495
2181.77	45.0936
2184.65	43.8429
2187.53	42.2046
2190.4	39.6494
2193.28	38.1178
2196.16	35.7922
2199.03	34.253
2201.9	32.6766
2204.77	30.6456
2207.64	29.0847
2210.51	27.1665
2213.38	24.6732
2216.25	23.3238
2219.12	20.4347
2221.98	18.5933
2224.85	17.4371
2227.71	16.8555
2230.57	15.5898
2233.43	15.0215
2236.29	14.6453
2239.15	14.993
2242.01	14.4328
2244.87	15.4063
2247.72	14.5459
2250.58	13.8642
2253.43	13.5436
2256.29	13.9689
2259.14	14.7601
2261.99	14.7265
2264.84	14.7203
2267.69	15.7938
2270.53	15.478
2273.38	15.6369
2276.23	14.9918
2279.07	14.3716
2281.91	13.0663
2284.76	11.8612
2287.6	11.8446
2290.44	10.1709
2293.28	8.18147
2296.12	7.44408
2298.96	8.96933
2301.79	9.45105
2304.63	8.7169
2307.46	9.6594
2310.3	10.2617
2313.13	11.2011
2315.96	11.2065
2318.79	10.6501
2321.62	11.0177
2324.45	11.4693
2327.27	11.4689
2330.1	10.9102
2332.92	10.2365
2335.75	10.2356
2338.57	9.11867
2341.39	7.84842
2344.21	6.74856
2347.04	5.42254
2349.85	4.60869
2352.67	3.55899
2355.49	2.1193
2358.3	1.19461
2361.12	-0.605488
2363.93	-0.458485
2366.75	1.49362
2369.56	1.1537
2372.37	0.0127725
2375.18	0.138079
2377.99	0.0185004
2380.8	0.682357
2383.6	0.872232
2386.41	1.3845
2389.21	1.76111
2392.02	2.1598
2394.82	3.19448
2397.62	4.01547
2400.42	3.28013
2403.22	4.10468
2406.02	3.81276
2408.82	4.36187
2411.62	5.61652
2414.41	6.39254
2417.21	6.62236
2420	6.7293
2422.79	5.9259
2425.59	6.53829
2428.38	7.04637
2431.17	6.58664
2433.95	7.03299
2436.74	6.41828
2439.53	5.56018
2442.31	4.87594
2445.1	5.26451
2447.88	5.21321
2450.67	4.75272
2453.45	4.85429
2456.23	4.4802
2459.01	3.90243
2461.79	3.66076
2464.57	4.24337
2467.34	3.56421
2470.12	2.86196
2472.89	3.01502
2475.67	2.56689
2478.44	2.89019
2481.21	2.41305
2483.98	2.06206
2486.75	0.386114
2489.52	-0.12069
2492.29	0.0996133
2495.05	1.63581
2497.82	1.8929
2500.58	1.91949
2503.35	1.9277
2506.11	2.41814
2508.87	2.0355
2511.63	2.81886
2514.39	3.04831
2517.15	2.68087
2519.91	2.31968
2522.67	2.22915
2525.42	3.1194
2528.18	2.89758
2530.93	3.87515
2533.69	4.7699
2536.44	4.35512
2539.19	4.87194
2541.94	5.90192
2544.69	5.86191
2547.44	6.25311
2550.18	5.35741
2552.93	4.89338
2555.67	4.88179
2558.42	5.60442
2561.16	5.08731
2563.9	5.53747
2566.64	5.33779
2569.38	5.53426
2572.12	5.93304
2574.86	5.83823
2577.6	5.25533
2580.33	4.52284
2583.07	4.94094
2585.8	5.1411
2588.54	5.80118
2591.27	5.67421
2594	4.27709
2596.73	4.05909
2599.46	2.91965
2602.19	2.55239
2604.92	2.21013
2607.64	2.20962
2610.37	2.95954
2613.09	2.36491
2615.82	2.35572
2618.54	2.14885
2621.26	2.19043
2623.98	2.01146
2626.7	0.88099
2629.42	1.89213
2632.14	3.02824
2634.86	3.57117
2637.57	3.16759
2640.29	3.34064
2643	3.96505
2645.71	4.36102
2648.43	5.26649
2651.14	5.99646
2653.85	6.66222
2656.56	6.68876
2659.26	6.38002
2661.97	5.76465
2664.68	5.72036
2667.38	6.30697
2670.09	6.90621
2672.79	7.74848
2675.49	8.12362
2678.19	9.38545
2680.89	9.50959
2683.59	9.95662
2686.29	10.4583
2688.99	10.555
2691.69	10.6173
2694.38	10.837
2697.08	11.5025
2699.77	11.7305
2702.46	11.6783
2705.15	11.2451
2707.85	11.3664
2710.54	12.2185
2713.22	12.1738
2715.91	13.0045
2718.6	12.9365
2721.29	13.0047
2723.97	12.2881
2726.66	12.0125
2729.34	11.3768
2732.02	10.5058
2734.7	9.67723
2737.38	8.91515
2740.06	8.44321
2742.74	8.08331
2745.42	7.66342
2748.09	7.5882
2750.77	6.86409
2753.45	6.71535
2756.12	6.10342
2758.79	5.71182
2761.46	5.3755
2764.14	6.4158
2766.8	6.66811
2769.47	7.14958
2772.14	7.08735
2774.81	7.86975
2777.48	7.81712
2780.14	7.58049
2782.8	7.06535
2785.47	6.56024
2788.13	5.75266
2790.79	6.1652
2793.45	6.10209
2796.11	5.89788
2798.77	5.47134
2801.43	5.65041
2804.09	5.71258
2806.74	5.6838
2809.4	6.42863
2812.05	6.8146
2814.71	7.93236
2817.36	9.61233
2820.01	12.7809
2822.66	16.2009
2825.31	21.3258
2827.96	27.444
2830.6	34.2577
2833.25	41.4922
2835.9	48.8304
2838.54	56.1101
2841.18	64.9118
2843.83	74.0337
2846.47	83.529
2849.11	93.9012
2851.75	104.594
2854.39	115.092
2857.03	125.385
2859.66	133.572
2862.3	142.002
2864.94	150.414
2867.57	157.894
2870.2	163.626
2872.84	168.986
2875.47	172.863
2878.1	175.761
2880.73	178.683
2883.36	182.355
2885.99	185.613
2888.61	188.61
2891.24	191.302
2893.86	195.963
2896.49	200.346
2899.11	204.043
2901.73	209.201
2904.36	214.47
2906.98	221.026
2909.6	229.387
2912.21	237.216
2914.83	245.548
2917.45	253.171
2920.07	258.317
2922.68	263.809
2925.29	268.778
2927.91	271.623
2930.52	271.338
2933.13	270.378
2935.74	267.308
2938.35	262.423
2940.96	256.626
2943.57	249.264
2946.18	242.205
2948.78	232.667
2951.39	223.581
2953.99	212.315
2956.59	201.781
2959.2	191.194
2961.8	180.193
2964.4	169.443
2967	159.408
2969.6	150.497
2972.19	142.278
2974.79	134.603
2977.39	125.869
2979.98	117.913
2982.58	108.693
2985.17	100.662
2987.76	92.1388
2990.35	84.2984
2992.94	76.5438
2995.53	69.3575
2998.12	62.6459
3000.71	55.7619
3003.3	50.3746
3005.88	44.3237
3008.47	39.1659
3011.05	34.3235
3013.64	29.055
3016.22	25.769
3018.8	22.3709
3021.38	20.0212
3023.96	18.0304
3026.54	16.9414
3029.12	14.8961
3031.69	14.6528
3034.27	14.3454
3036.84	14.8778
3039.42	15.3864
3041.99	15.0124
3044.57	15.3064
3047.14	15.2751
3049.71	15.4076
3052.28	16.4078
3054.85	15.9772
3057.41	15.4118
3059.98	14.3988
3062.55	13.5538
3065.11	11.9068
3067.68	9.45716
3070.24	8.38682
3072.8	7.57062
3075.36	6.24937
3077.93	5.35832
3080.49	5.36237
3083.04	3.97298
3085.6	3.15964
3088.16	3.68974
3090.72	3.71387
3093.27	3.57833
3095.83	5.1148
3098.38	6.15417
3100.93	7.06478
3103.49	6.53167
3106.04	6.47031
3108.59	6.33643
3111.14	7.21426
3113.69	8.72168
3116.23	8.90084
3118.78	8.42525
3121.33	8.62888
3123.87	8.85008
3126.41	9.00322
3128.96	8.88693
3131.5	9.7407
3134.04	11.2253
3136.58	11.9059
3139.12	12.6716
3141.66	13.7084
3144.2	15.576
3146.74	18.2168
3149.27	19.16