File: data/Raman/poly_smoothed/Mb_20_23_09_1x_45s_532 nm_x100_100%_600 gr_mm_01.txt
#Acq. time (s)=	45
#Accumulations=	2
#Range (cm-¹)=	200...3150
#Windows=	2
#Auto scanning=	Off
#Autofocus=	Off
#Macrospot=	Off
#AutoExposure=	Off
#Spike filter=	Multiple accum.
#Delay time (s)=	0
#Binning=	1
#Readout mode=	Signal
#DeNoise=	Off
#ICS correction=	On
#Dark correction=	Off
#Inst. Process=	Off
#Detector Gain=	Best Dynamic Range
#Detector ADC=	20 kHz
#Detector temperature (°C)=	-69.85
#Instrument=	LabRAM HR Evol
#Detector=	Synapse
#Objective=	x100
#Grating=	600 gr/mm
#ND Filter=	100%
#Laser (nm)=	532
#Hole=	100.021
#Range=	Auto
#Laser Pol.=	No
#Raman. Pol.=	No
#Laser Pol. (°)=	-0.0007625
#Raman Pol. (°)=	89.9995
#Collection=	Microscope
#StageXY=	Marzhauser
#StageZ=	Marzhauser
#X (µm)=	-6910.5
#Y (µm)=	2149.4
#Z (µm)=	-74.85
#Full time(mm:ss)=	3:18
#Project=
#Sample=
#Site=
#Title=	Mb_20_23_09_2x_45s_532 nm_x100_100%_600 gr_mm
#Remark=
#Date=	13.07.2022 13:36
#Acquired=	13.07.2022 13:36:18
#Base:Fit=	10.08.2022 10:29:19
#Base:Fit=	10.08.2022 10:29:37
#Base:Sub=	10.08.2022 10:31:46
#Filter:Polynom=	16.08.2022 10:13:29
#AxisType[0]=Intens
#AxisUnit[0]=Cnt
#AxisType[1]=Spectr
#AxisUnit[1]=1/cm
200.563	82.3681
204.194	75.5031
207.821	68.8953
211.449	62.0705
215.074	56.1909
218.699	50.9849
222.321	45.7405
225.941	42.3101
229.562	37.9794
233.18	35.1051
236.796	32.466
240.411	30.234
244.026	26.4447
247.638	23.5151
251.248	19.3982
254.857	17.9368
258.465	16.0492
262.071	14.5188
265.678	14.6231
269.282	12.0947
272.884	10.0075
276.484	8.93469
280.084	8.45201
283.682	6.71378
287.276	5.46737
290.871	3.76835
294.465	2.79248
298.057	2.3134
301.648	2.91124
305.237	3.9562
308.823	5.47223
312.41	8.55724
315.995	10.4324
319.579	12.8126
323.16	15.5586
326.741	16.3818
330.321	17.6422
333.897	18.1956
337.474	17.419
341.048	18.2197
344.622	19.712
348.192	18.9801
351.764	17.4016
355.332	15.4467
358.901	13.9286
362.466	12.0333
366.03	9.85363
369.594	8.17346
373.155	7.67103
376.715	6.91858
380.273	6.1662
383.832	5.37526
387.388	4.85042
390.942	4.39736
394.495	5.78045
398.047	6.16053
401.597	7.15006
405.145	7.85459
408.693	7.91755
412.239	7.15141
415.783	6.58631
419.327	7.02315
422.869	6.53249
426.409	5.40575
429.948	4.50092
433.486	2.75638
437.022	1.72476
440.558	1.60999
444.089	2.64272
447.622	2.91215
451.153	4.38164
454.682	6.40333
458.208	5.95279
461.735	7.9503
465.259	6.92643
468.783	7.16958
472.306	10.0059
475.825	11.5264
479.346	12.8267
482.862	15.8768
486.38	16.7198
489.894	19.7549
493.407	20.4873
496.92	21.0589
500.43	23.2096
503.939	23.3871
507.448	25.8698
510.954	27.7699
514.459	28.3332
517.962	28.0197
521.466	28.4863
524.966	29.9886
528.466	28.6734
531.964	26.7208
535.46	24.9626
538.955	23.0859
542.449	19.8715
545.942	17.5314
549.433	15.8901
552.923	13.9309
556.412	12.8508
559.899	11.4262
563.385	8.49991
566.867	7.16622
570.35	4.29731
573.832	3.50474
577.313	1.74346
580.79	1.63789
584.268	0.697598
587.745	0.217302
591.218	0.871844
594.692	1.35769
598.164	1.93936
601.634	1.04321
605.104	0.927974
608.57	1.27566
612.037	2.04229
615.501	2.92931
618.966	2.35814
622.427	3.27658
625.887	2.97562
629.348	4.50037
632.806	5.41433
636.262	7.98252
639.716	7.62861
643.172	7.66738
646.624	7.55675
650.075	5.33041
653.524	6.43602
656.972	5.99066
660.419	5.38209
663.865	3.8894
667.309	3.81547
670.752	5.00313
674.194	5.0741
677.634	4.67226
681.073	5.46723
684.511	6.01275
687.947	8.31394
691.382	11.2329
694.816	12.2764
698.247	14.7737
701.678	15.1109
705.108	16.5469
708.534	19.0379
711.962	20.6972
715.388	23.317
718.81	24.3585
722.234	23.3367
725.654	23.6191
729.075	23.837
732.492	24.7015
735.91	24.3723
739.325	26.2854
742.741	27.446
746.153	29.6573
749.564	33.163
752.976	36.0609
756.385	41.3498
759.792	43.5554
763.2	46.2635
766.604	51.4745
770.008	55.9004
773.41	58.4373
776.811	62.3921
780.21	64.0725
783.608	66.0589
787.005	69.821
790.401	70.9417
793.795	74.4089
797.188	76.0444
800.58	78.5228
803.971	77.1007
807.36	79.4492
810.748	80.7536
814.135	82.4984
817.518	84.2237
820.902	86.9769
824.285	87.7755
827.665	90.1701
831.045	94.1011
834.424	94.5303
837.8	94.6587
841.177	92.0524
844.55	89.2899
847.924	87.7529
851.295	87.7183
854.666	86.7939
858.034	86.2835
861.403	86.2874
864.769	84.8692
868.133	84.3591
871.498	82.6785
874.86	82.8781
878.221	82.7581
881.58	78.8299
884.938	77.1594
888.297	74.2072
891.653	72.8098
895.007	70.6113
898.36	70.2884
901.712	69.0943
905.063	67.3155
908.412	65.6874
911.76	64.6697
915.107	61.4667
918.452	56.7792
921.797	53.1051
925.138	49.5029
928.48	48.7032
931.82	49.112
935.16	47.0281
938.496	44.8924
941.833	42.7217
945.168	40.8993
948.5	39.1867
951.834	36.8652
955.163	35.8915
958.494	32.6839
961.821	29.7621
965.15	27.9307
968.474	28.5458
971.8	28.5518
975.123	30.2948
978.446	30.4389
981.766	27.8321
985.084	25.8194
988.402	25.6097
991.72	25.117
995.035	23.3994
998.349	21.7309
1001.66	22.2475
1004.97	22.8298
1008.28	28.2344
1011.59	39.1964
1014.9	49.609
1018.21	59.1005
1021.51	71.6436
1024.81	86.375
1028.12	103.502
1031.42	118.902
1034.72	131.394
1038.02	142.051
1041.31	150.905
1044.61	161.43
1047.91	166.796
1051.2	172.677
1054.49	172.848
1057.78	169.477
1061.07	162.702
1064.36	154.351
1067.65	145.022
1070.93	132.775
1074.22	119.115
1077.5	106.547
1080.78	94.6188
1084.06	82.3599
1087.34	73.4832
1090.62	71.9634
1093.9	73.3146
1097.17	73.4015
1100.45	75.4041
1103.72	78.4051
1106.99	83.6264
1110.27	85.4475
1113.53	82.6833
1116.8	81.0715
1120.07	80.0852
1123.33	77.5199
1126.6	73.4359
1129.86	68.1477
1133.12	63.1475
1136.38	57.4855
1139.64	50.6183
1142.9	45.1649
1146.16	37.7349
1149.41	31.1479
1152.67	24.2483
1155.92	18.6723
1159.17	13.2128
1162.42	7.17301
1165.67	3.87873
1168.92	7.75809
1172.16	10.3864
1175.41	12.4986
1178.65	12.4306
1181.9	12.4203
1185.14	13.5935
1188.38	12.9732
1191.62	12.4326
1194.86	14.3032
1198.09	14.1577
1201.33	14.8951
1204.56	16.1193
1207.8	19.6816
1211.03	24.2398
1214.26	29.2864
1217.49	34.6987
1220.71	37.6924
1223.94	43.8988
1227.16	48.7379
1230.39	55.2064
1233.61	60.548
1236.83	68.4751
1240.05	75.6813
1243.27	79.1814
1246.49	84.2965
1249.71	85.835
1252.92	84.926
1256.14	87.2237
1259.35	93.6071
1262.56	102.904
1265.77	115.095
1268.98	129.333
1272.19	141.9
1275.4	157.427
1278.6	169.241
1281.81	183.381
1285.01	194.263
1288.21	201.792
1291.41	209.735
1294.61	214.305
1297.81	218.86
1301.01	219.721
1304.2	219.738
1307.4	217.508
1310.59	212.454
1313.78	206.553
1316.97	199.453
1320.16	187.104
1323.35	175.566
1326.54	161.353
1329.72	147.397
1332.91	138.775
1336.09	137.093
1339.27	134.568
1342.45	132.667
1345.64	129.452
1348.81	127.438
1351.99	126.424
1355.17	123.845
1358.34	123.089
1361.51	120.774
1364.69	118.541
1367.86	117.934
1371.03	117.032
1374.2	117.273
1377.37	115.607
1380.53	115.079
1383.7	116.124
1386.86	117.005
1390.02	118.809
1393.19	119.954
1396.35	119.736
1399.51	121.718
1402.66	128.623
1405.82	140.66
1408.97	158.104
1412.13	178.2
1415.28	201.603
1418.43	225.232
1421.59	252.416
1424.73	276.674
1427.88	303.998
1431.03	330.377
1434.18	351.845
1437.32	372.635
1440.46	388.007
1443.61	398.708
1446.75	402.475
1449.89	401.826
1453.03	394.205
1456.16	380.952
1459.3	361.544
1462.44	339.358
1465.57	311.464
1468.7	278.655
1471.83	245.818
1474.96	213.27
1478.09	185.162
1481.22	161.763
1484.35	138.092
1487.47	117.296
1490.6	97.408
1493.72	82.0254
1496.84	68.1922
1499.96	56.7909
1503.08	49.5727
1506.2	44.9718
1509.32	41.7084
1512.44	40.2562
1515.55	38.6005
1518.66	38.9045
1521.78	39.8637
1524.89	40.7552
1528	42.9396
1531.11	44.6661
1534.21	47.2125
1537.32	50.6129
1540.43	54.7519
1543.53	57.6788
1546.63	60.1644
1549.74	63.5492
1552.84	64.5706
1555.94	65.8151
1559.03	67.7241
1562.13	68.3949
1565.23	70.1182
1568.32	72.8576
1571.42	78.0358
1574.51	82.1414
1577.6	84.8016
1580.69	88.983
1583.78	91.6587
1586.87	95.2302
1589.95	97.262
1593.04	99.4832
1596.12	101.51
1599.21	101.174
1602.29	101.702
1605.37	103.866
1608.45	104.288
1611.53	106.033
1614.6	106.564
1617.68	105.197
1620.75	105.803
1623.83	107.205
1626.9	110.125
1629.97	110.101
1633.04	111.975
1636.11	114.177
1639.18	116.903
1642.25	120.877
1645.31	124.052
1648.38	127.259
1651.44	127.284
1654.5	128.432
1657.56	127.536
1660.62	125.569
1663.68	123.918
1666.74	120.061
1669.8	115.302
1672.85	110.745
1675.91	105.971
1678.96	100.171
1682.01	92.9497
1685.06	87.9143
1688.11	81.7362
1691.16	75.5507
1694.21	73.3686
1697.25	69.7941
1700.3	67.7887
1703.34	65.0166
1706.39	62.1778
1709.43	58.1833
1712.47	55.3006
1715.51	53.9624
1718.54	52.0789
1721.58	50.7559
1724.62	48.4592
1727.65	45.9859
1730.68	45.0622
1733.72	43.2337
1736.75	41.8823
1739.78	40.3576
1742.81	37.5283
1745.84	35.3483
1748.86	33.0562
1751.89	29.5558
1754.91	26.0009
1757.93	23.7635
1760.96	22.2297
1763.98	20.4486
1767	19.5119
1770.02	18.4377
1773.03	16.2579
1776.05	14.3838
1779.07	12.696
1782.08	10.2537
1785.09	8.63901
1788.11	7.9678
1791.12	7.34832
1794.13	7.34662
1797.13	6.63488
1800.14	6.88156
1803.15	6.87474
1806.15	7.52133
1809.16	7.79324
1812.16	8.11899
1815.16	8.88117
1818.16	8.49556
1821.16	8.39494
1824.16	7.99415
1827.16	7.4764
1830.16	7.42233
1833.15	6.82502
1836.14	6.98422
1839.14	7.33906
1842.13	7.22588
1845.12	5.74547
1848.11	4.67829
1851.1	3.29844
1854.08	2.97605
1857.07	3.53386
1860.05	3.54
1863.04	5.28223
1866.02	5.14035
1869	4.41993
1871.98	4.39857
1874.96	4.52183
1877.94	6.08323
1880.92	7.28391
1882.51	7.91727
1885.5	8.10553
1888.48	8.924
1891.47	8.21226
1894.46	6.59982
1897.44	6.02229
1900.42	5.2397
1903.41	5.52906
1906.39	6.52986
1909.37	5.99558
1912.35	4.96655
1915.32	4.59732
1918.3	3.51646
1921.27	3.22756
1924.25	3.69493
1927.22	4.47089
1930.19	4.19299
1933.17	4.37337
1936.14	4.09198
1939.11	1.91961
1942.07	0.942185
1945.04	1.35716
1948.01	2.15649
1950.97	1.94179
1953.93	1.45214
1956.9	1.02024
1959.86	0.766093
1962.82	1.80937
1965.78	0.689936
1968.74	0.117601
1971.69	1.99037
1974.65	1.75438
1977.6	1.68165
1980.56	2.11756
1983.51	2.50744
1986.46	2.59657
1989.41	2.73046
1992.36	3.83047
1995.31	4.0695
1998.26	4.83608
2001.2	4.55249
2004.15	5.40771
2007.09	6.4876
2010.04	5.04674
2012.98	3.50893
2015.92	5.29611
2018.86	4.79527
2021.8	5.23577
2024.73	5.72988
2027.67	7.27193
2030.61	6.51066
2033.54	7.72372
2036.47	8.24556
2039.4	7.40708
2042.33	7.36776
2045.27	7.5818
2048.19	7.13141
2051.12	7.9074
2054.05	7.57317
2056.97	8.07794
2059.9	8.91086
2062.82	9.30514
2065.74	9.65663
2068.67	10.8741
2071.59	10.7373
2074.51	10.9177
2077.42	10.6296
2080.34	10.2027
2083.26	9.8573
2086.17	10.4225
2089.09	11.228
2092	11.7088
2094.91	12.0673
2097.82	12.7382
2100.73	13.1252
2103.64	13.3939
2106.55	14.3111
2109.45	15.4861
2112.36	16.11
2115.26	17.3799
2118.17	19.8978
2121.07	21.9018
2123.97	24.2662
2126.87	26.6943
2129.77	30.2369
2132.67	32.1877
2135.56	35.3342
2138.46	38.2088
2141.35	39.6849
2144.25	42.3162
2147.14	46.5877
2150.03	48.9628
2152.92	52.2851
2155.81	55.2076
2158.7	58.4637
2161.59	61.3029
2164.47	63.4251
2167.36	66.5034
2170.24	68.7065
2173.13	70.4812
2176.01	71.8032
2178.89	72.1879
2181.77	71.1007
2184.65	69.1026
2187.53	67.5717
2190.4	65.5693
2193.28	62.1367
2196.16	59.0707
2199.03	55.1113
2201.9	52.6838
2204.77	49.0403
2207.64	44.8583
2210.51	41.0645
2213.38	36.8417
2216.25	34.0956
2219.12	31.5226
2221.98	29.3081
2224.85	28.2894
2227.71	25.7452
2230.57	24.5758
2233.43	23.0329
2236.29	22.1443
2239.15	20.1261
2242.01	19.7987
2244.87	18.0361
2247.72	15.8828
2250.58	13.744
2253.43	12.0463
2256.29	10.433
2259.14	9.89524
2261.99	8.10624
2264.84	9.22399
2267.69	9.42717
2270.53	9.51689
2273.38	9.45087
2276.23	8.32117
2279.07	7.17703
2281.91	5.87211
2284.76	6.19562
2287.6	7.16561
2290.44	5.44084
2293.28	5.41571
2296.12	4.98142
2298.96	4.84403
2301.79	6.45927
2304.63	6.02886
2307.46	6.77136
2310.3	7.52075
2313.13	7.93627
2315.96	7.32272
2318.79	7.76412
2321.62	8.0494
2324.45	8.67234
2327.27	7.94679
2330.1	9.52286
2332.92	10.6208
2335.75	10.8696
2338.57	9.44854
2341.39	8.31466
2344.21	7.52745
2347.04	6.98808
2349.85	5.42134
2352.67	5.00517
2355.49	5.48418
2358.3	3.2196
2361.12	3.02106
2363.93	3.72062
2366.75	3.90824
2369.56	4.15588
2372.37	3.69062
2375.18	4.18231
2377.99	5.35867
2380.8	5.6293
2383.6	6.32614
2386.41	6.23603
2389.21	6.43789
2392.02	6.87315
2394.82	6.86691
2397.62	6.25686
2400.42	6.33751
2403.22	4.26861
2406.02	2.35376
2408.82	1.66696
2411.62	2.28577
2414.41	3.50491
2417.21	2.338
2420	2.3036
2422.79	4.00371
2425.59	3.51785
2428.38	2.91692
2431.17	3.46123
2433.95	1.99451
2436.74	1.96052
2439.53	2.40856
2442.31	3.21065
2445.1	3.11039
2447.88	3.88873
2450.67	5.45203
2453.45	5.31415
2456.23	4.86881
2459.01	5.35774
2461.79	4.6985
2464.57	4.39841
2467.34	4.59342
2470.12	5.44868
2472.89	6.22
2475.67	7.10019
2478.44	8.59515
2481.21	9.27555
2483.98	10.001
2486.75	10.4775
2489.52	11.7217
2492.29	12.2806
2495.05	11.3522
2497.82	9.53321
2500.58	9.90225
2503.35	9.66247
2506.11	9.86771
2508.87	10.3748
2511.63	9.20842
2514.39	7.96874
2517.15	9.07238
2519.91	8.55968
2522.67	7.64241
2525.42	8.07062
2528.18	8.11082
2530.93	9.29169
2533.69	10.5821
2536.44	10.6143
2539.19	10.0501
2541.94	10.7387
2544.69	9.81054
2547.44	10.6054
2550.18	11.3638
2552.93	12.3768
2555.67	13.4974
2558.42	14.2627
2561.16	14.4709
2563.9	13.5989
2566.64	15.2331
2569.38	16.2273
2572.12	15.8687
2574.86	15.7792
2577.6	16.5049
2580.33	16.3466
2583.07	17.1241
2585.8	16.917
2588.54	18.0234
2591.27	18.5656
2594	18.7465
2596.73	20.1531
2599.46	20.7982
2602.19	18.6812
2604.92	18.0614
2607.64	17.8394
2610.37	17.1178
2613.09	17.4127
2615.82	16.8499
2618.54	17.2114
2621.26	15.9377
2623.98	16.1243
2626.7	16.0173
2629.42	16.4889
2632.14	16.4482
2634.86	17.4906
2637.57	17.0913
2640.29	18.7367
2643	20.6243
2645.71	21.7334
2648.43	21.9872
2651.14	21.9929
2653.85	22.82
2656.56	23.6149
2659.26	24.7842
2661.97	24.6125
2664.68	26.5418
2667.38	25.4553
2670.09	25.1043
2672.79	25.0643
2675.49	25.1204
2678.19	25.2678
2680.89	25.5714
2683.59	25.1182
2686.29	25.9223
2688.99	27.1987
2691.69	28.3736
2694.38	30.7564
2697.08	32.5482
2699.77	35.1149
2702.46	38.7578
2705.15	42.6096
2707.85	47.0117
2710.54	49.9982
2713.22	52.262
2715.91	53.9042
2718.6	55.7756
2721.29	57.9017
2723.97	58.8051
2726.66	58.021
2729.34	57.0485
2732.02	55.5573
2734.7	51.4041
2737.38	47.4513
2740.06	44.2793
2742.74	39.1053
2745.42	33.5788
2748.09	28.3633
2750.77	22.4199
2753.45	17.6852
2756.12	12.9225
2758.79	8.91567
2761.46	6.63192
2764.14	3.67304
2766.8	2.7568
2769.47	2.43058
2772.14	1.60626
2774.81	0.807469
2777.48	0.246834
2780.14	0.433339
2782.8	0.394266
2785.47	-0.226619
2788.13	0.530462
2790.79	0.0864671
2793.45	1.54569
2796.11	2.37147
2798.77	2.25178
2801.43	1.67422
2804.09	-0.486344
2806.74	-3.95375
2809.4	-7.72625
2812.05	-9.83146
2814.71	-3.65603
2817.36	10.9813
2820.01	36.2309
2822.66	68.8249
2825.31	110.306
2827.96	156.404
2830.6	206.098
2833.25	257.946
2835.9	309.89
2838.54	361.676
2841.18	412.354
2843.83	460.04
2846.47	503.601
2849.11	550.704
2851.75	603.711
2854.39	658.563
2857.03	710.768
2859.66	755.699
2862.3	792.898
2864.94	819.328
2867.57	838.693
2870.2	852.072
2872.84	860.671
2875.47	867.993
2878.1	879.361
2880.73	890.464
2883.36	900.726
2885.99	908.932
2888.61	913.861
2891.24	916.703
2893.86	914.836
2896.49	908.575
2899.11	902.543
2901.73	895.529
2904.36	888.876
2906.98	886.479
2909.6	888.655
2912.21	898.619
2914.83	917.888
2917.45	934.819
2920.07	946.362
2922.68	948.972
2925.29	946.498
2927.91	938.511
2930.52	927.116
2933.13	913.4
2935.74	893.747
2938.35	869.603
2940.96	841.138
2943.57	808.723
2946.18	773.653
2948.78	735.877
2951.39	695.037
2953.99	653.469
2956.59	612.35
2959.2	571.323
2961.8	531.731
2964.4	496.329
2967	463.54
2969.6	435.234
2972.19	406.464
2974.79	379.722
2977.39	352.042
2979.98	324.579
2982.58	296.424
2985.17	265.778
2987.76	236.241
2990.35	210.935
2992.94	184.47
2995.53	160.037
2998.12	137.878
3000.71	117.649
3003.3	97.7369
3005.88	80.8091
3008.47	64.926
3011.05	51.4899
3013.64	38.1862
3016.22	27.7526
3018.8	18.8715
3021.38	13.0303
3023.96	7.19431
3026.54	2.70796
3029.12	0.763496
3031.69	-0.576938
3034.27	-2.00367
3036.84	-2.9147
3039.42	-3.34553
3041.99	-3.34836
3044.57	-0.925398
3047.14	1.61164
3049.71	3.11603
3052.28	6.0781
3054.85	6.91321
3057.41	7.53008
3059.98	8.40033
3062.55	9.10938
3065.11	8.92445
3067.68	9.35447
3070.24	9.95294
3072.8	9.9052
3075.36	8.45705
3077.93	8.08215
3080.49	7.45092
3083.04	6.68113
3085.6	5.85441
3088.16	5.90026
3090.72	5.30401
3093.27	5.48496
3095.83	6.27605
3098.38	8.1644
3100.93	10.0928
3103.49	13.6626
3106.04	18.7265
3108.59	23.2609
3111.14	28.0621
3113.69	32.8842
3116.23	37.6908
3118.78	43.3436
3121.33	49.2229
3123.87	55.3651
3126.41	61.8406
3128.96	68.3255
3131.5	74.9614
3134.04	80.8922
3136.58	86.9363
3139.12	91.7694
3141.66	97.1224
3144.2	101.747
3146.74	105.493
3149.27	108.68