File: data/Raman/poly_smoothed/Mb_20_23_18_1x_45s_532 nm_x100_100%_600 gr_mm_01.txt
#Acq. time (s)=	45
#Accumulations=	2
#Range (cm-¹)=	200...3150
#Windows=	2
#Auto scanning=	Off
#Autofocus=	Off
#Macrospot=	Off
#AutoExposure=	Off
#Spike filter=	Multiple accum.
#Delay time (s)=	0
#Binning=	1
#Readout mode=	Signal
#DeNoise=	Off
#ICS correction=	On
#Dark correction=	Off
#Inst. Process=	Off
#Detector Gain=	Best Dynamic Range
#Detector ADC=	20 kHz
#Detector temperature (°C)=	-69.85
#Instrument=	LabRAM HR Evol
#Detector=	Synapse
#Objective=	x100
#Grating=	600 gr/mm
#ND Filter=	100%
#Laser (nm)=	532
#Hole=	100.021
#Range=	Auto
#Laser Pol.=	No
#Raman. Pol.=	No
#Laser Pol. (°)=	-0.0007625
#Raman Pol. (°)=	89.9995
#Collection=	Microscope
#StageXY=	Marzhauser
#StageZ=	Marzhauser
#X (µm)=	-6901.4
#Y (µm)=	2092.8
#Z (µm)=	-74.6
#Full time(mm:ss)=	3:19
#Project=
#Sample=
#Site=
#Title=	Mb_20_23_18_2x_45s_532 nm_x100_100%_600 gr_mm
#Remark=
#Date=	13.07.2022 14:14
#Acquired=	13.07.2022 14:14:53
#Base:Fit=	10.08.2022 10:29:37
#Base:Sub=	10.08.2022 10:32:28
#Filter:Polynom=	16.08.2022 10:13:29
#AxisType[0]=Intens
#AxisUnit[0]=Cnt
#AxisType[1]=Spectr
#AxisUnit[1]=1/cm
200.563	12.4049
204.194	12.8679
207.821	11.0696
211.449	8.89817
215.074	7.24739
218.699	5.65881
222.321	4.86205
225.941	3.7889
229.562	3.53235
233.18	3.12036
236.796	1.9814
240.411	0.883083
244.026	1.32992
247.638	1.05327
251.248	0.725954
254.857	1.84341
258.465	3.1342
262.071	3.35395
265.678	2.34161
269.282	2.16166
272.884	2.87584
276.484	4.3228
280.084	5.45065
283.682	5.99714
287.276	6.19393
290.871	5.80832
294.465	7.18203
298.057	8.46504
301.648	9.99504
305.237	13.4358
308.823	14.5829
312.41	16.5156
315.995	17.2357
319.579	18.1025
323.16	17.5062
326.741	19.3671
330.321	20.3485
333.897	20.4909
337.474	20.5621
341.048	19.4796
344.622	19.2745
348.192	16.8602
351.764	15.0982
355.332	14.9412
358.901	13.6166
362.466	13.2162
366.03	11.8742
369.594	11.5156
373.155	10.2498
376.715	8.0228
380.273	8.67576
383.832	9.03054
387.388	8.03354
390.942	8.72436
394.495	8.76965
398.047	9.36807
401.597	8.75669
405.145	9.79451
408.693	7.9735
412.239	8.97359
415.783	8.21249
419.327	5.5342
422.869	5.45937
426.409	4.34991
429.948	4.63832
433.486	3.82646
437.022	3.57369
440.558	4.74177
444.089	5.78467
447.622	6.05671
451.153	6.18811
454.682	6.52604
458.208	8.84487
461.735	9.70643
465.259	11.0597
468.783	12.8896
472.306	14.9416
475.825	16.6397
479.346	20.0942
482.862	22.6865
486.38	23.152
489.894	24.8385
493.407	26.6806
496.92	27.7438
500.43	30.2355
503.939	30.5076
507.448	30.982
510.954	32.5473
514.459	30.9252
517.962	32.3616
521.466	31.7731
524.966	31.7195
528.466	31.3042
531.964	29.7637
535.46	29.5898
538.955	27.422
542.449	27.099
545.942	25.9493
549.433	23.9567
552.923	21.7485
556.412	21.2894
559.899	20.3572
563.385	20.8863
566.867	18.9818
570.35	18.5705
573.832	15.4397
577.313	16.5069
580.79	14.6963
584.268	13.8102
587.745	12.9577
591.218	11.7335
594.692	11.8897
598.164	11.4324
601.634	12.1163
605.104	13.7798
608.57	14.4758
612.037	15.1894
615.501	16.378
618.966	18.0203
622.427	18.2466
625.887	17.9792
629.348	20.3882
632.806	19.4771
636.262	20.0834
639.716	22.1993
643.172	25.6464
646.624	26.7342
650.075	27.2296
653.524	27.2902
656.972	26.5588
660.419	26.6677
663.865	26.5523
667.309	28.374
670.752	28.3622
674.194	29.4169
677.634	30.3479
681.073	31.3704
684.511	32.5652
687.947	35.2609
691.382	37.0851
694.816	37.2419
698.247	39.3238
701.678	40.3521
705.108	41.3941
708.534	43.6055
711.962	45.0565
715.388	46.913
718.81	48.2679
722.234	51.6026
725.654	53.6801
729.075	54.2053
732.492	55.6322
735.91	58.6975
739.325	58.9996
742.741	60.4461
746.153	61.246
749.564	65.1174
752.976	67.5905
756.385	70.5641
759.792	72.7499
763.2	77.7107
766.604	79.3511
770.008	82.8006
773.41	83.3352
776.811	84.3196
780.21	86.864
783.608	88.8847
787.005	90.6634
790.401	92.2254
793.795	93.5567
797.188	94.1407
800.58	94.7862
803.971	95.5213
807.36	95.014
810.748	94.3276
814.135	94.431
817.518	94.6719
820.902	93.067
824.285	91.0008
827.665	90.3897
831.045	90.2243
834.424	89.7202
837.8	89.0652
841.177	87.336
844.55	85.046
847.924	82.8663
851.295	79.9606
854.666	78.3264
858.034	77.9615
861.403	77.8336
864.769	75.3774
868.133	74.1702
871.498	73.3926
874.86	71.663
878.221	71.0827
881.58	68.6251
884.938	68.0705
888.297	68.4645
891.653	69.2216
895.007	70.3042
898.36	69.4832
901.712	71.3665
905.063	71.366
908.412	70.8344
911.76	68.3061
915.107	68.9897
918.452	67.39
921.797	66.1438
925.138	63.7074
928.48	63.1604
931.82	62.737
935.16	62.491
938.496	60.5797
941.833	57.4274
945.168	55.6311
948.5	55.0482
951.834	53.2819
955.163	51.4511
958.494	50.2294
961.821	47.086
965.15	46.6159
968.474	45.4867
971.8	46.723
975.123	45.1794
978.446	46.7396
981.766	47.6555
985.084	48.0611
988.402	45.4741
991.72	43.8983
995.035	42.1624
998.349	41.6374
1001.66	38.224
1004.97	38.0157
1008.28	36.622
1011.59	35.6389
1014.9	35.5395
1018.21	33.7732
1021.51	33.5411
1024.81	33.1273
1028.12	33.4781
1031.42	32.9929
1034.72	31.006
1038.02	29.7007
1041.31	28.4577
1044.61	26.2848
1047.91	26.3272
1051.2	26.4076
1054.49	27.4694
1057.78	28.1299
1061.07	30.4343
1064.36	31.3111
1067.65	29.8843
1070.93	30.0443
1074.22	29.6434
1077.5	28.191
1080.78	28.6284
1084.06	29.5089
1087.34	30.0329
1090.62	29.7376
1093.9	31.9437
1097.17	32.9735
1100.45	33.5073
1103.72	33.5428
1106.99	34.0789
1110.27	33.7323
1113.53	32.3789
1116.8	29.8205
1120.07	28.5693
1123.33	26.8486
1126.6	25.3384
1129.86	25.3054
1133.12	25.0405
1136.38	25.355
1139.64	25.5591
1142.9	24.1921
1146.16	22.0386
1149.41	20.4089
1152.67	19.1232
1155.92	15.6658
1159.17	13.4848
1162.42	11.1066
1165.67	8.66739
1168.92	7.19561
1172.16	7.65806
1175.41	7.76008
1178.65	7.7938
1181.9	8.27449
1185.14	8.45499
1188.38	8.89889
1191.62	9.88793
1194.86	9.52948
1198.09	11.5356
1201.33	13.1606
1204.56	13.7721
1207.8	15.1836
1211.03	18.4436
1214.26	22.9621
1217.49	24.6107
1220.71	26.9039
1223.94	30.8815
1227.16	32.9855
1230.39	34.8096
1233.61	35.9636
1236.83	36.7973
1240.05	37.0207
1243.27	39.4347
1246.49	40.8258
1249.71	40.7153
1252.92	43.1057
1256.14	44.8317
1259.35	45.8718
1262.56	47.7573
1265.77	50.4003
1268.98	50.9049
1272.19	52.5664
1275.4	53.1609
1278.6	55.6427
1281.81	57.1702
1285.01	60.295
1288.21	62.7413
1291.41	66.3762
1294.61	68.7668
1297.81	71.1603
1301.01	74.8647
1304.2	74.9447
1307.4	75.111
1310.59	75.8418
1313.78	76.086
1316.97	75.9198
1320.16	75.6807
1323.35	75.3372
1326.54	73.6451
1329.72	72.9887
1332.91	71.1084
1336.09	69.3521
1339.27	67.4813
1342.45	65.0712
1345.64	61.2122
1348.81	58.84
1351.99	57.1429
1355.17	57.2232
1358.34	56.6365
1361.51	55.3935
1364.69	54.9021
1367.86	54.6353
1371.03	53.8768
1374.2	53.1069
1377.37	50.1979
1380.53	48.387
1383.7	46.8139
1386.86	46.8375
1390.02	46.4968
1393.19	47.7007
1396.35	47.9201
1399.51	48.2783
1402.66	48.676
1405.82	50.037
1408.97	51.1476
1412.13	53.9432
1415.28	58.2481
1418.43	63.0728
1421.59	67.8724
1424.73	75.451
1427.88	80.8937
1431.03	86.8693
1434.18	92.4865
1437.32	95.9163
1440.46	97.7451
1443.61	99.4731
1446.75	100.493
1449.89	99.0102
1453.03	95.958
1456.16	92.1501
1459.3	91.6782
1462.44	87.3516
1465.57	82.3358
1468.7	77.3892
1471.83	70.4073
1474.96	64.1641
1478.09	57.9231
1481.22	52.5838
1484.35	48.3148
1487.47	45.3949
1490.6	42.4471
1493.72	40.317
1496.84	37.4872
1499.96	36.4065
1503.08	35.2174
1506.2	31.9368
1509.32	29.8278
1512.44	27.4194
1515.55	24.8261
1518.66	23.3734
1521.78	22.1253
1524.89	20.1985
1528	18.698
1531.11	18.0737
1534.21	18.297
1537.32	19.7172
1540.43	19.1077
1543.53	19.5941
1546.63	21.5434
1549.74	21.5428
1552.84	22.2004
1555.94	22.1009
1559.03	23.1051
1562.13	24.7366
1565.23	28.4233
1568.32	30.9866
1571.42	32.8387
1574.51	35.4506
1577.6	38.6057
1580.69	39.8599
1583.78	40.4629
1586.87	41.7422
1589.95	43.5128
1593.04	45.4002
1596.12	47.3416
1599.21	48.059
1602.29	48.987
1605.37	49.296
1608.45	50.1725
1611.53	49.1288
1614.6	49.6868
1617.68	47.8832
1620.75	47.6979
1623.83	47.7226
1626.9	48.4688
1629.97	49.5615
1633.04	51.8203
1636.11	54.5135
1639.18	57.3065
1642.25	59.7637
1645.31	62.1215
1648.38	62.824
1651.44	64.0527
1654.5	64.3663
1657.56	63.9066
1660.62	63.955
1663.68	63.1316
1666.74	62.7454
1669.8	61.443
1672.85	58.0097
1675.91	54.7545
1678.96	49.0472
1682.01	43.6828
1685.06	37.804
1688.11	32.1999
1691.16	27.5937
1694.21	25.324
1697.25	23.2663
1700.3	21.2702
1703.34	19.1108
1706.39	17.1115
1709.43	15.1304
1712.47	13.4936
1715.51	10.6816
1718.54	9.51654
1721.58	8.64424
1724.62	8.85577
1727.65	9.05712
1730.68	8.98918
1733.72	8.13085
1736.75	8.51505
1739.78	8.36077
1742.81	9.12644
1745.84	9.20642
1748.86	8.25146
1751.89	8.61797
1754.91	7.65096
1757.93	7.76681
1760.96	8.03086
1763.98	9.33407
1767	10.9094
1770.02	12.0431
1773.03	11.8018
1776.05	10.5074
1779.07	10.4852
1782.08	9.50856
1785.09	9.24697
1788.11	8.09228
1791.12	7.68347
1794.13	7.87671
1797.13	7.21195
1800.14	7.65878
1803.15	7.1664
1806.15	6.11968
1809.16	5.22269
1812.16	4.7435
1815.16	4.3983
1818.16	5.35041
1821.16	4.80357
1824.16	4.21232
1827.16	4.37153
1830.16	3.3491
1833.15	2.69744
1836.14	2.91403
1839.14	2.41446
1842.13	3.16208
1845.12	3.26977
1848.11	2.44755
1851.1	2.12846
1854.08	2.33255
1857.07	2.21079
1860.05	1.66773
1863.04	1.50009
1866.02	1.72902
1869	1.84186
1871.98	1.78562
1874.96	1.12429
1877.94	1.07655
1880.92	1.30966
1882.51	1.20065
1885.5	2.19386
1888.48	2.69943
1891.47	2.6967
1894.46	2.7102
1897.44	2.60521
1900.42	2.979
1903.41	3.43941
1906.39	2.9829
1909.37	2.86689
1912.35	3.07889
1915.32	3.69218
1918.3	3.10193
1921.27	3.20916
1924.25	3.2585
1927.22	3.71698
1930.19	3.46514
1933.17	3.27496
1936.14	3.25244
1939.11	3.02187
1942.07	2.29587
1945.04	1.92526
1948.01	2.2906
1950.97	1.62552
1953.93	1.05157
1956.9	0.877835
1959.86	0.693367
1962.82	0.465555
1965.78	0.382646
1968.74	0.395371
1971.69	1.20586
1974.65	1.56129
1977.6	1.35825
1980.56	1.56894
1983.51	2.53295
1986.46	3.37267
1989.41	4.4073
1992.36	5.17324
1995.31	4.12762
1998.26	4.67519
2001.2	5.95462
2004.15	5.82806
2007.09	5.84836
2010.04	6.91261
2012.98	6.46481
2015.92	6.73412
2018.86	5.69129
2021.8	4.83622
2024.73	3.79044
2027.67	5.16554
2030.61	4.92727
2033.54	5.61362
2036.47	5.82445
2039.4	6.23555
2042.33	7.35133
2045.27	8.3116
2048.19	9.95456
2051.12	10.7524
2054.05	11.0463
2056.97	11.601
2059.9	12.1968
2062.82	11.9175
2065.74	10.9617
2068.67	11.0539
2071.59	11.9529
2074.51	11.9446
2077.42	12.2818
2080.34	12.5358
2083.26	13.0984
2086.17	13.1892
2089.09	12.7679
2092	13.1562
2094.91	14.4279
2097.82	16.0468
2100.73	15.9532
2103.64	16.661
2106.55	17.8135
2109.45	18.0041
2112.36	18.8067
2115.26	20.2754
2118.17	20.3554
2121.07	22.5593
2123.97	22.2555
2126.87	22.6231
2129.77	24.8562
2132.67	25.1494
2135.56	25.8935
2138.46	26.8233
2141.35	27.8318
2144.25	28.9552
2147.14	31.0738
2150.03	32.0076
2152.92	33.988
2155.81	35.0763
2158.7	36.5195
2161.59	38.8502
2164.47	40.5532
2167.36	42.8874
2170.24	44.0632
2173.13	44.6097
2176.01	45.5347
2178.89	46.3586
2181.77	46.6898
2184.65	47.0513
2187.53	46.509
2190.4	45.2341
2193.28	43.9795
2196.16	42.2882
2199.03	42.2309
2201.9	40.6697
2204.77	37.2501
2207.64	34.762
2210.51	32.1142
2213.38	29.2456
2216.25	26.8776
2219.12	24.5099
2221.98	22.5912
2224.85	19.8995
2227.71	18.9102
2230.57	18.523
2233.43	17.2922
2236.29	16.6628
2239.15	17.152
2242.01	16.3939
2244.87	15.2526
2247.72	15.8318
2250.58	15.2564
2253.43	13.953
2256.29	13.113
2259.14	11.9824
2261.99	10.9984
2264.84	10.895
2267.69	11.8239
2270.53	11.5077
2273.38	10.8293
2276.23	8.82302
2279.07	8.51928
2281.91	8.77445
2284.76	7.99952
2287.6	7.5588
2290.44	7.39185
2293.28	5.46898
2296.12	5.90176
2298.96	6.92028
2301.79	8.29389
2304.63	8.69202
2307.46	9.59403
2310.3	9.80057
2313.13	10.2528
2315.96	9.44769
2318.79	10.0687
2321.62	8.96723
2324.45	8.26682
2327.27	7.49675
2330.1	6.60709
2332.92	6.89868
2335.75	7.01604
2338.57	6.35795
2341.39	4.41207
2344.21	4.09848
2347.04	2.55694
2349.85	3.51557
2352.67	2.26226
2355.49	0.802338
2358.3	0.808095
2361.12	0.261614
2363.93	0.836474
2366.75	3.03332
2369.56	2.70697
2372.37	3.06567
2375.18	3.12812
2377.99	3.2329
2380.8	2.25156
2383.6	1.78572
2386.41	2.73207
2389.21	4.01461
2392.02	3.28944
2394.82	2.50969
2397.62	3.25043
2400.42	3.0899
2403.22	3.90649
2406.02	2.65778
2408.82	2.09327
2411.62	1.8088
2414.41	1.5087
2417.21	1.58585
2420	1.22961
2422.79	0.932757
2425.59	0.95016
2428.38	1.699
2431.17	1.95494
2433.95	2.07007
2436.74	1.31739
2439.53	1.85529
2442.31	2.68394
2445.1	1.96874
2447.88	2.42994
2450.67	2.72616
2453.45	3.77054
2456.23	3.97301
2459.01	4.30301
2461.79	3.8434
2464.57	4.90105
2467.34	5.4822
2470.12	4.32214
2472.89	3.41725
2475.67	3.6964
2478.44	4.26511
2481.21	4.15899
2483.98	3.94552
2486.75	3.51247
2489.52	3.63927
2492.29	3.5685
2495.05	3.09655
2497.82	2.60792
2500.58	2.89634
2503.35	3.22333
2506.11	4.20716
2508.87	4.06018
2511.63	3.97449
2514.39	3.56159
2517.15	3.72479
2519.91	3.79219
2522.67	3.33281
2525.42	3.89934
2528.18	5.29699
2530.93	5.60711
2533.69	4.63055
2536.44	3.82313
2539.19	4.17444
2541.94	5.88634
2544.69	5.93535
2547.44	6.35146
2550.18	4.79962
2552.93	5.57314
2555.67	4.88876
2558.42	5.1016
2561.16	4.23706
2563.9	4.6504
2566.64	4.88988
2569.38	4.57494
2572.12	4.57904
2574.86	3.77377
2577.6	3.74621
2580.33	3.63775
2583.07	3.70808
2585.8	4.05667
2588.54	4.06203
2591.27	4.99513
2594	5.41472
2596.73	4.62662
2599.46	4.17849
2602.19	4.65133
2604.92	4.66942
2607.64	4.70836
2610.37	4.20922
2613.09	4.69991
2615.82	4.30248
2618.54	4.28794
2621.26	3.94353
2623.98	4.15418
2626.7	4.14789
2629.42	3.66186
2632.14	4.0552
2634.86	3.45885
2637.57	3.40408
2640.29	3.0189
2643	4.25434
2645.71	4.31852
2648.43	4.66312
2651.14	5.40469
2653.85	5.42691
2656.56	6.16562
2659.26	5.87192
2661.97	5.91619
2664.68	6.81299
2667.38	8.26924
2670.09	8.24317
2672.79	8.65342
2675.49	8.70606
2678.19	8.92366
2680.89	9.56902
2683.59	10.0506
2686.29	10.5819
2688.99	10.5906
2691.69	10.5837
2694.38	10.4718
2697.08	11.2175
2699.77	11.0495
2702.46	11.4169
2705.15	13.2976
2707.85	13.6594
2710.54	13.3403
2713.22	12.9161
2715.91	13.2944
2718.6	12.9477
2721.29	12.5768
2723.97	12.5412
2726.66	13.7087
2729.34	13.8055
2732.02	14.7289
2734.7	14.2891
2737.38	14.0374
2740.06	12.5529
2742.74	11.6861
2745.42	9.22716
2748.09	9.13642
2750.77	7.89402
2753.45	5.85647
2756.12	5.20379
2758.79	4.34221
2761.46	3.5489
2764.14	2.88474
2766.8	2.60764
2769.47	2.8958
2772.14	2.24697
2774.81	1.83755
2777.48	2.30895
2780.14	1.71963
2782.8	2.31979
2785.47	2.52299
2788.13	3.16517
2790.79	3.03283
2793.45	3.07203
2796.11	3.21786
2798.77	2.89904
2801.43	2.89274
2804.09	2.62854
2806.74	2.05248
2809.4	0.789397
2812.05	-0.370582
2814.71	0.572139
2817.36	1.20253
2820.01	4.98745
2822.66	9.18876
2825.31	14.0636
2827.96	20.7185
2830.6	28.5776
2833.25	36.8607
2835.9	46.2954
2838.54	56.2058
2841.18	66.8197
2843.83	76.7296
2846.47	87.7971
2849.11	99.9008
2851.75	111.412
2854.39	122.361
2857.03	132.809
2859.66	144.302
2862.3	154.262
2864.94	163.137
2867.57	170.669
2870.2	176.955
2872.84	181.166
2875.47	185.659
2878.1	189.032
2880.73	193.662
2883.36	198.389
2885.99	203.59
2888.61	207.296
2891.24	211.599
2893.86	216.378
2896.49	222.513
2899.11	227.634
2901.73	234.279
2904.36	241.092
2906.98	249.994
2909.6	258.73
2912.21	269.757
2914.83	279.464
2917.45	289.015
2920.07	296.883
2922.68	303.177
2925.29	307.192
2927.91	310.377
2930.52	311.095
2933.13	309.772
2935.74	306.579
2938.35	300.59
2940.96	293.047
2943.57	284.041
2946.18	273.104
2948.78	261.953
2951.39	251.004
2953.99	238.713
2956.59	226.401
2959.2	214.234
2961.8	201.666
2964.4	190.796
2967	180.74
2969.6	170.844
2972.19	161.617
2974.79	152.709
2977.39	142.623
2979.98	132.811
2982.58	123.106
2985.17	111.513
2987.76	101.247
2990.35	91.1595
2992.94	80.6889
2995.53	70.8792
2998.12	60.4843
3000.71	52.3239
3003.3	44.5584
3005.88	35.7903
3008.47	28.7539
3011.05	23.4981
3013.64	19.1885
3016.22	15.0266
3018.8	11.0237
3021.38	7.34832
3023.96	5.25309
3026.54	4.01161
3029.12	4.38006
3031.69	3.75185
3034.27	3.28084
3036.84	3.82682
3039.42	3.82621
3041.99	3.58928
3044.57	4.59216
3047.14	4.74276
3049.71	5.35955
3052.28	6.23581
3054.85	7.03075
3057.41	8.07911
3059.98	8.06776
3062.55	7.96337
3065.11	8.49028
3067.68	8.10857
3070.24	7.42044
3072.8	7.49094
3075.36	7.12211
3077.93	5.68697
3080.49	4.50328
3083.04	3.95155
3085.6	1.59114
3088.16	0.867143
3090.72	1.1731
3093.27	1.52157
3095.83	-0.485325
3098.38	0.204475
3100.93	0.679974
3103.49	1.13633
3106.04	1.97162
3108.59	3.51696
3111.14	4.31376
3113.69	6.47934
3116.23	7.88801
3118.78	10.0255
3121.33	11.1566
3123.87	12.8033
3126.41	14.8874
3128.96	16.9735
3131.5	18.604
3134.04	20.6245
3136.58	22.7636
3139.12	22.8334
3141.66	24.3473
3144.2	25.7381
3146.74	27.5327
3149.27	30.1187