File: data/Raman/poly_smoothed/Mb_20_23_20_1x_45s_532 nm_x100_100%_600 gr_mm_01.txt
#Acq. time (s)=	45
#Accumulations=	2
#Range (cm-¹)=	200...3150
#Windows=	2
#Auto scanning=	Off
#Autofocus=	Off
#Macrospot=	Off
#AutoExposure=	Off
#Spike filter=	Multiple accum.
#Delay time (s)=	0
#Binning=	1
#Readout mode=	Signal
#DeNoise=	Off
#ICS correction=	On
#Dark correction=	Off
#Inst. Process=	Off
#Detector Gain=	Best Dynamic Range
#Detector ADC=	20 kHz
#Detector temperature (°C)=	-69.85
#Instrument=	LabRAM HR Evol
#Detector=	Synapse
#Objective=	x100
#Grating=	600 gr/mm
#ND Filter=	100%
#Laser (nm)=	532
#Hole=	100.021
#Range=	Auto
#Laser Pol.=	No
#Raman. Pol.=	No
#Laser Pol. (°)=	-0.0007625
#Raman Pol. (°)=	89.9995
#Collection=	Microscope
#StageXY=	Marzhauser
#StageZ=	Marzhauser
#X (µm)=	-6886.3
#Y (µm)=	2114
#Z (µm)=	-74.95
#Full time(mm:ss)=	3:19
#Project=
#Sample=
#Site=
#Title=	Mb_20_23_20_2x_45s_532 nm_x100_100%_600 gr_mm
#Remark=
#Date=	13.07.2022 14:34
#Acquired=	13.07.2022 14:34:14
#Base:Fit=	10.08.2022 10:29:37
#Base:Sub=	10.08.2022 10:32:28
#Filter:Polynom=	16.08.2022 10:13:29
#AxisType[0]=Intens
#AxisUnit[0]=Cnt
#AxisType[1]=Spectr
#AxisUnit[1]=1/cm
200.563	21.3049
204.194	16.7238
207.821	12.3636
211.449	8.41654
215.074	8.54567
218.699	7.5631
222.321	5.19623
225.941	4.40824
229.562	6.56679
233.18	8.35846
236.796	7.72885
240.411	9.30678
244.026	10.7639
247.638	11.1781
251.248	11.6805
254.857	12.5457
258.465	12.3376
262.071	11.9582
265.678	10.8791
269.282	11.3919
272.884	12.2703
276.484	10.3219
280.084	9.0201
283.682	6.79803
287.276	3.41283
290.871	2.63044
294.465	3.3245
298.057	4.98058
301.648	8.38228
305.237	11.2297
308.823	9.89812
312.41	13.3662
315.995	17.8642
319.579	22.2825
323.16	24.8285
326.741	27.0174
330.321	30.5807
333.897	31.2451
337.474	33.283
341.048	33.7108
344.622	34.9688
348.192	36.3402
351.764	35.5968
355.332	35.3647
358.901	33.2625
362.466	30.0133
366.03	26.7729
369.594	24.2254
373.155	24.798
376.715	24.295
380.273	25.3516
383.832	25.5495
387.388	26.9472
390.942	28.2963
394.495	29.7108
398.047	31.2717
401.597	33.5366
405.145	32.8503
408.693	34.7389
412.239	35.1957
415.783	35.4629
419.327	36.8695
422.869	37.3429
426.409	37.9934
429.948	36.8727
433.486	37.0213
437.022	34.7875
440.558	34.3092
444.089	33.7854
447.622	34.7512
451.153	35.5914
454.682	35.5691
458.208	36.7112
461.735	37.578
465.259	39.1793
468.783	39.8169
472.306	42.2653
475.825	43.1794
479.346	44.6287
482.862	46.8626
486.38	47.2603
489.894	47.6078
493.407	48.242
496.92	50.0689
500.43	52.5629
503.939	54.5159
507.448	55.7492
510.954	55.4086
514.459	55.8856
517.962	56.19
521.466	56.6943
524.966	56.6287
528.466	55.3322
531.964	56.7205
535.46	55.8548
538.955	54.9801
542.449	53.1166
545.942	49.8693
549.433	45.8681
552.923	43.1508
556.412	40.1674
559.899	39.0729
563.385	37.7199
566.867	35.3859
570.35	30.121
573.832	26.5682
577.313	22.6666
580.79	20.652
584.268	18.5501
587.745	16.7553
591.218	15.5879
594.692	13.8256
598.164	12.0379
601.634	13.1119
605.104	13.2736
608.57	16.7281
612.037	18.632
615.501	20.6525
618.966	22.1249
622.427	22.3738
625.887	22.5893
629.348	21.7254
632.806	22.4962
636.262	22.8925
639.716	24.1486
643.172	23.812
646.624	22.3133
650.075	20.3604
653.524	16.7542
656.972	11.9936
660.419	9.74229
663.865	8.62064
667.309	7.01861
670.752	6.09587
674.194	4.5254
677.634	5.24244
681.073	5.10448
684.511	7.83835
687.947	12.967
691.382	16.189
694.816	17.5665
698.247	18.1713
701.678	18.8084
705.108	19.8509
708.534	22.1499
711.962	24.2927
715.388	24.5708
718.81	27.7518
722.234	27.7517
725.654	27.5263
729.075	28.4759
732.492	28.5687
735.91	29.1439
739.325	30.8483
742.741	31.9705
746.153	34.3879
749.564	36.0892
752.976	39.3189
756.385	42.5196
759.792	46.3198
763.2	48.4051
766.604	49.9948
770.008	51.3122
773.41	52.8514
776.811	54.0071
780.21	53.4847
783.608	56.4335
787.005	57.6213
790.401	59.1502
793.795	61.0149
797.188	61.269
800.58	61.7495
803.971	64.411
807.36	63.3028
810.748	64.6618
814.135	66.1454
817.518	66.4943
820.902	69.5707
824.285	72.827
827.665	73.7856
831.045	75.6082
834.424	77.5672
837.8	77.0116
841.177	76.5976
844.55	74.3415
847.924	72.6338
851.295	70.7091
854.666	70.7187
858.034	69.194
861.403	67.4636
864.769	66.8121
868.133	66.2347
871.498	64.4248
874.86	61.0763
878.221	60.1845
881.58	56.8541
884.938	54.0331
888.297	53.3303
891.653	51.7925
895.007	50.2991
898.36	48.7605
901.712	49.4074
905.063	48.8772
908.412	48.2208
911.76	46.0247
915.107	46.1186
918.452	45.0481
921.797	45.7329
925.138	44.8846
928.48	43.9521
931.82	42.8867
935.16	41.9762
938.496	40.5126
941.833	39.9344
945.168	39.6726
948.5	37.1917
951.834	35.4605
955.163	34.3017
958.494	33.2141
961.821	30.756
965.15	28.8827
968.474	33.282
971.8	34.4758
975.123	35.651
978.446	37.5834
981.766	37.8126
985.084	38.7181
988.402	39.6785
991.72	41.0957
995.035	41.2666
998.349	43.371
1001.66	42.4957
1004.97	46.219
1008.28	46.1074
1011.59	46.0507
1014.9	48.5863
1018.21	47.1697
1021.51	47.6518
1024.81	48.1546
1028.12	48.4209
1031.42	51.8221
1034.72	53.8024
1038.02	55.4038
1041.31	56.9311
1044.61	59.3434
1047.91	62.3716
1051.2	64.7888
1054.49	65.996
1057.78	64.9513
1061.07	65.2604
1064.36	63.7802
1067.65	63.3439
1070.93	61.8755
1074.22	58.8236
1077.5	57.8857
1080.78	57.7661
1084.06	56.8938
1087.34	55.4174
1090.62	53.5122
1093.9	53.6119
1097.17	54.9576
1100.45	56.9349
1103.72	58.3413
1106.99	59.3521
1110.27	60.5739
1113.53	60.8714
1116.8	59.7239
1120.07	57.9687
1123.33	55.9697
1126.6	55.2539
1129.86	52.1928
1133.12	49.027
1136.38	45.4482
1139.64	43.5794
1142.9	41.3831
1146.16	37.0303
1149.41	30.9385
1152.67	24.85
1155.92	17.82
1159.17	17.4324
1162.42	12.8177
1165.67	10.1034
1168.92	8.20063
1172.16	9.88967
1175.41	13.2198
1178.65	14.4622
1181.9	14.095
1185.14	13.7703
1188.38	15.0976
1191.62	19.0312
1194.86	21.0554
1198.09	23.811
1201.33	26.6851
1204.56	31.6597
1207.8	33.2043
1211.03	38.9772
1214.26	43.7411
1217.49	50.5689
1220.71	56.2134
1223.94	61.4422
1227.16	65.1267
1230.39	69.2376
1233.61	76.5351
1236.83	83.1152
1240.05	88.9244
1243.27	95.7822
1246.49	103.73
1249.71	108.802
1252.92	115.094
1256.14	118.195
1259.35	123.061
1262.56	127.053
1265.77	132.753
1268.98	137.282
1272.19	144.127
1275.4	146.3
1278.6	150.985
1281.81	157.042
1285.01	161.736
1288.21	164.902
1291.41	169.743
1294.61	172.177
1297.81	174.947
1301.01	177.112
1304.2	180.1
1307.4	181.833
1310.59	185.203
1313.78	187.513
1316.97	188.028
1320.16	190.699
1323.35	190.259
1326.54	186.177
1329.72	182.781
1332.91	178.484
1336.09	170.719
1339.27	165.978
1342.45	159.744
1345.64	152.785
1348.81	146.141
1351.99	141.096
1355.17	134.024
1358.34	127.492
1361.51	121.844
1364.69	117.162
1367.86	112.062
1371.03	108.875
1374.2	105.519
1377.37	103.933
1380.53	103.705
1383.7	104.076
1386.86	105.187
1390.02	103.722
1393.19	103.477
1396.35	103.289
1399.51	103.475
1402.66	105.256
1405.82	110.901
1408.97	119.392
1412.13	126.854
1415.28	135.976
1418.43	148.558
1421.59	161.994
1424.73	177.778
1427.88	193.996
1431.03	209.912
1434.18	225.584
1437.32	240.932
1440.46	252.553
1443.61	262.436
1446.75	267.497
1449.89	269.351
1453.03	267.472
1456.16	263.862
1459.3	253.79
1462.44	240.923
1465.57	222.464
1468.7	203.356
1471.83	185.738
1474.96	166.967
1478.09	150.697
1481.22	135.298
1484.35	119.644
1487.47	103.788
1490.6	90.5419
1493.72	79.8847
1496.84	71.6995
1499.96	63.7149
1503.08	57.2879
1506.2	54.1017
1509.32	49.882
1512.44	48.2879
1515.55	45.0378
1518.66	44.7507
1521.78	43.0803
1524.89	42.1747
1528	43.8931
1531.11	46.4637
1534.21	47.8762
1537.32	48.9765
1540.43	49.5721
1543.53	52.1304
1546.63	56.2634
1549.74	60.1452
1552.84	63.3298
1555.94	66.6658
1559.03	69.2709
1562.13	72.7093
1565.23	75.2235
1568.32	79.9431
1571.42	82.7716
1574.51	88.0412
1577.6	93.4774
1580.69	100.149
1583.78	105.727
1586.87	110.359
1589.95	114.729
1593.04	118.663
1596.12	121.495
1599.21	122.944
1602.29	126.002
1605.37	127.405
1608.45	128.094
1611.53	127.554
1614.6	126.785
1617.68	125.812
1620.75	125.863
1623.83	128.459
1626.9	131.678
1629.97	132.801
1633.04	135.501
1636.11	139.417
1639.18	143.186
1642.25	147.711
1645.31	152.126
1648.38	158.468
1651.44	162.33
1654.5	164.321
1657.56	166.06
1660.62	164.654
1663.68	161.849
1666.74	158.609
1669.8	150.084
1672.85	141.867
1675.91	132.081
1678.96	121.108
1682.01	111.354
1685.06	99.5992
1688.11	87.4462
1691.16	76.4747
1694.21	68.3891
1697.25	60.2369
1700.3	52.9703
1703.34	46.0801
1706.39	40.6401
1709.43	36.8681
1712.47	32.7286
1715.51	31.4973
1718.54	29.3654
1721.58	28.0098
1724.62	25.2532
1727.65	24.6444
1730.68	22.4056
1733.72	21.7981
1736.75	19.2319
1739.78	17.4663
1742.81	15.4056
1745.84	12.5394
1748.86	11.6166
1751.89	9.76134
1754.91	9.48454
1757.93	9.05664
1760.96	7.88355
1763.98	7.97674
1767	8.79535
1770.02	9.57986
1773.03	9.63035
1776.05	8.81677
1779.07	9.01182
1782.08	9.12251
1785.09	9.23062
1788.11	8.23181
1791.12	8.88034
1794.13	6.48009
1797.13	5.93371
1800.14	5.4684
1803.15	4.70404
1806.15	3.92261
1809.16	2.46285
1812.16	1.31388
1815.16	1.45717
1818.16	1.51209
1821.16	1.49471
1824.16	1.1948
1827.16	0.390486
1830.16	1.35391
1833.15	1.29965
1836.14	1.55616
1839.14	0.931269
1842.13	1.34475
1845.12	0.357216
1848.11	-0.256992
1851.1	-0.321612
1854.08	-0.824808
1857.07	-0.0920949
1860.05	-1.163
1863.04	-0.350305
1866.02	-0.0511726
1869	0.568948
1871.98	0.293951
1874.96	1.46145
1877.94	1.04186
1880.92	2.49284
1882.51	3.49461
1885.5	3.89654
1888.48	4.59684
1891.47	4.92904
1894.46	5.43472
1897.44	6.09926
1900.42	5.57113
1903.41	5.56102
1906.39	6.08621
1909.37	6.98027
1912.35	7.32155
1915.32	7.82958
1918.3	6.87286
1921.27	7.85589
1924.25	9.22868
1927.22	9.44288
1930.19	9.11984
1933.17	8.4254
1936.14	7.72042
1939.11	6.54751
1942.07	6.62397
1945.04	6.89938
1948.01	7.20408
1950.97	6.50803
1953.93	5.42183
1956.9	4.01129
1959.86	3.43806
1962.82	3.61088
1965.78	2.96367
1968.74	3.15643
1971.69	4.14331
1974.65	3.30296
1977.6	3.85654
1980.56	3.6639
1983.51	4.01166
1986.46	3.94049
1989.41	3.70256
1992.36	3.41696
1995.31	4.95186
1998.26	3.67281
2001.2	4.27578
2004.15	4.19924
2007.09	4.08921
2010.04	5.06872
2012.98	5.9709
2015.92	5.20141
2018.86	4.16588
2021.8	5.02153
2024.73	4.87871
2027.67	6.64368
2030.61	6.67156
2033.54	6.82534
2036.47	8.00712
2039.4	8.19448
2042.33	8.63945
2045.27	9.55817
2048.19	8.44957
2051.12	8.74412
2054.05	7.96016
2056.97	7.71222
2059.9	8.04921
2062.82	7.43497
2065.74	8.92206
2068.67	8.90481
2071.59	9.45292
2074.51	11.8748
2077.42	12.7133
2080.34	13.9431
2083.26	14.7233
2086.17	16.9097
2089.09	17.5529
2092	19.7781
2094.91	20.9837
2097.82	23.5316
2100.73	25.1238
2103.64	26.3573
2106.55	28.8858
2109.45	31.2088
2112.36	33.3743
2115.26	36.8441
2118.17	39.0945
2121.07	42.1189
2123.97	44.741
2126.87	48.1393
2129.77	51.9906
2132.67	56.5046
2135.56	60.3934
2138.46	65.0238
2141.35	69.2342
2144.25	73.704
2147.14	79.1356
2150.03	83.2344
2152.92	87.194
2155.81	92.0501
2158.7	96.2414
2161.59	99.0074
2164.47	102.05
2167.36	106.113
2170.24	107.426
2173.13	108.376
2176.01	108.893
2178.89	107.657
2181.77	106.986
2184.65	104.325
2187.53	101.728
2190.4	99.1498
2193.28	95.4505
2196.16	92.3025
2199.03	87.3487
2201.9	83.1948
2204.77	78.1272
2207.64	71.9652
2210.51	66.0824
2213.38	60.7721
2216.25	56.5798
2219.12	50.5305
2221.98	44.7293
2224.85	40.9125
2227.71	39.8342
2230.57	37.0979
2233.43	35.1016
2236.29	32.1408
2239.15	30.1805
2242.01	26.9691
2244.87	24.9435
2247.72	23.9315
2250.58	21.9679
2253.43	22.0183
2256.29	21.934
2259.14	22.0493
2261.99	22.5758
2264.84	22.8272
2267.69	22.4856
2270.53	21.5603
2273.38	20.0409
2276.23	18.3981
2279.07	17.2041
2281.91	15.8432
2284.76	14.77
2287.6	12.9626
2290.44	10.7611
2293.28	9.27971
2296.12	9.05679
2298.96	9.51067
2301.79	9.12814
2304.63	7.75678
2307.46	5.82301
2310.3	5.44035
2313.13	6.25669
2315.96	5.73479
2318.79	6.41401
2321.62	8.28388
2324.45	11.0799
2327.27	10.3979
2330.1	9.86664
2332.92	10.3236
2335.75	9.23592
2338.57	9.31423
2341.39	8.18458
2344.21	7.82918
2347.04	6.33411
2349.85	6.29321
2352.67	3.68222
2355.49	2.18358
2358.3	0.674947
2361.12	-0.2508
2363.93	-0.152736
2366.75	0.217252
2369.56	0.514446
2372.37	0.503098
2375.18	-0.483817
2377.99	-0.155876
2380.8	0.505096
2383.6	0.766917
2386.41	1.42377
2389.21	0.690757
2392.02	2.60283
2394.82	0.753603
2397.62	0.51273
2400.42	-0.100895
2403.22	0.460244
2406.02	1.6359
2408.82	2.70712
2411.62	2.78668
2414.41	3.30632
2417.21	4.95043
2420	4.8743
2422.79	4.74508
2425.59	6.66637
2428.38	8.19685
2431.17	9.64706
2433.95	11.3264
2436.74	12.1593
2439.53	14.6251
2442.31	15.3077
2445.1	12.3936
2447.88	13.2992
2450.67	13.1043
2453.45	12.7565
2456.23	12.5835
2459.01	12.2553
2461.79	11.235
2464.57	9.83359
2467.34	9.69206
2470.12	7.58351
2472.89	6.7717
2475.67	7.03833
2478.44	7.63637
2481.21	6.02554
2483.98	5.17293
2486.75	4.10903
2489.52	3.57514
2492.29	2.78152
2495.05	2.03853
2497.82	3.25734
2500.58	3.97323
2503.35	4.3785
2506.11	4.70285
2508.87	5.08686
2511.63	5.00197
2514.39	5.45314
2517.15	7.80016
2519.91	8.54357
2522.67	8.38829
2525.42	9.58836
2528.18	10.3702
2530.93	10.4016
2533.69	10.6528
2536.44	10.8666
2539.19	10.9347
2541.94	10.6935
2544.69	11.7423
2547.44	12.5897
2550.18	11.4421
2552.93	11.7187
2555.67	10.9127
2558.42	11.9653
2561.16	12.5073
2563.9	12.9342
2566.64	13.6225
2569.38	13.8955
2572.12	12.901
2574.86	13.311
2577.6	14.0687
2580.33	15.0798
2583.07	15.7753
2585.8	14.3509
2588.54	14.807
2591.27	14.2916
2594	14.4098
2596.73	14.6376
2599.46	13.6119
2602.19	14.026
2604.92	12.9535
2607.64	12.234
2610.37	12.7113
2613.09	13.7834
2615.82	13.6669
2618.54	12.7696
2621.26	11.9311
2623.98	12.2561
2626.7	12.5902
2629.42	10.8028
2632.14	9.81861
2634.86	9.41637
2637.57	8.94462
2640.29	9.37426
2643	10.281
2645.71	10.6619
2648.43	10.0487
2651.14	9.4369
2653.85	8.83026
2656.56	9.89933
2659.26	9.83383
2661.97	10.3716
2664.68	10.6736
2667.38	10.9717
2670.09	11.4448
2672.79	11.7716
2675.49	12.5866
2678.19	13.7799
2680.89	13.9107
2683.59	13.158
2686.29	13.2251
2688.99	13.1534
2691.69	14.4704
2694.38	15.735
2697.08	16.6842
2699.77	18.2135
2702.46	20.3442
2705.15	22.5685
2707.85	24.0764
2710.54	26.1249
2713.22	26.6121
2715.91	27.6324
2718.6	28.4987
2721.29	31.2499
2723.97	30.789
2726.66	30.4107
2729.34	29.7343
2732.02	28.5608
2734.7	26.3375
2737.38	24.518
2740.06	21.871
2742.74	19.1184
2745.42	16.2076
2748.09	13.4697
2750.77	10.997
2753.45	7.73126
2756.12	5.54714
2758.79	4.06215
2761.46	1.70446
2764.14	0.751488
2766.8	-0.795906
2769.47	-0.615101
2772.14	-2.15178
2774.81	-2.37576
2777.48	-1.04084
2780.14	-1.08309
2782.8	0.229049
2785.47	0.22172
2788.13	1.27342
2790.79	0.654523
2793.45	0.957204
2796.11	1.08729
2798.77	0.662796
2801.43	0.097787
2804.09	0.353002
2806.74	-0.576182
2809.4	-1.66008
2812.05	-2.60035
2814.71	-3.3283
2817.36	-1.10943
2820.01	5.11902
2822.66	16.3332
2825.31	30.651
2827.96	47.7523
2830.6	64.9236
2833.25	84.1495
2835.9	105.739
2838.54	129.169
2841.18	155.732
2843.83	181.597
2846.47	209.117
2849.11	236.246
2851.75	265.93
2854.39	294.784
2857.03	321.38
2859.66	347.32
2862.3	370.781
2864.94	390.535
2867.57	407.456
2870.2	423.053
2872.84	436.662
2875.47	448.553
2878.1	458.656
2880.73	471.052
2883.36	482.497
2885.99	495.21
2888.61	507.532
2891.24	518.208
2893.86	528.474
2896.49	539.364
2899.11	553.127
2901.73	568.273
2904.36	586.375
2906.98	606.119
2909.6	625.973
2912.21	648.114
2914.83	669.261
2917.45	688.435
2920.07	706.089
2922.68	718.978
2925.29	727.213
2927.91	730.087
2930.52	728.609
2933.13	722.992
2935.74	714.903
2938.35	700.415
2940.96	682.626
2943.57	660.465
2946.18	637.771
2948.78	611.255
2951.39	584.09
2953.99	554.497
2956.59	524.452
2959.2	495.057
2961.8	468.442
2964.4	441.406
2967	416.485
2969.6	390.119
2972.19	364.605
2974.79	341.53
2977.39	317.793
2979.98	292.456
2982.58	267.649
2985.17	241.875
2987.76	216.303
2990.35	192.428
2992.94	168.03
2995.53	144.848
2998.12	124.417
3000.71	106.782
3003.3	89.0627
3005.88	74.0941
3008.47	60.0976
3011.05	48.6809
3013.64	37.709
3016.22	28.0216
3018.8	20.9866
3021.38	16.6092
3023.96	11.3651
3026.54	7.36778
3029.12	4.22465
3031.69	2.29071
3034.27	1.46553
3036.84	2.58106
3039.42	3.10837
3041.99	4.37511
3044.57	5.38749
3047.14	7.08876
3049.71	10.194
3052.28	11.2434
3054.85	11.4178
3057.41	11.0379
3059.98	10.7123
3062.55	11.7543
3065.11	11.5728
3067.68	11.001
3070.24	9.79797
3072.8	8.92521
3075.36	8.03123
3077.93	6.38677
3080.49	5.83763
3083.04	4.80194
3085.6	3.90065
3088.16	3.76478
3090.72	5.18784
3093.27	6.33372
3095.83	7.25882
3098.38	9.85263
3100.93	12.5321
3103.49	15.2725
3106.04	18.0629
3108.59	22.5225
3111.14	26.0997
3113.69	29.4093
3116.23	32.6705
3118.78	36.7872
3121.33	41.798
3123.87	45.9959
3126.41	50.6484
3128.96	56.1842
3131.5	61.4356
3134.04	66.2556
3136.58	72.6866
3139.12	77.1576
3141.66	82.407
3144.2	87.6211
3146.74	92.6317
3149.27	95.3622