File: data/Raman/poly_smoothed/Mb_30_27_38_1x_45s_532 nm_x100_100%_600 gr_mm_01.txt
#Acq. time (s)=	45
#Accumulations=	2
#Range (cm-¹)=	200...3150
#Windows=	2
#Auto scanning=	Off
#Autofocus=	Off
#Macrospot=	Off
#AutoExposure=	Off
#Spike filter=	Multiple accum.
#Delay time (s)=	0
#Binning=	1
#Readout mode=	Signal
#DeNoise=	Off
#ICS correction=	On
#Dark correction=	Off
#Inst. Process=	Off
#Detector Gain=	Best Dynamic Range
#Detector ADC=	20 kHz
#Detector temperature (°C)=	-69.85
#Instrument=	LabRAM HR Evol
#Detector=	Synapse
#Objective=	x100
#Grating=	600 gr/mm
#ND Filter=	100%
#Laser (nm)=	532
#Hole=	100.021
#Range=	Auto
#Laser Pol.=	No
#Raman. Pol.=	No
#Laser Pol. (°)=	-0.0007625
#Raman Pol. (°)=	89.9995
#Collection=	Microscope
#StageXY=	Marzhauser
#StageZ=	Marzhauser
#X (µm)=	-6345.5
#Y (µm)=	802.2
#Z (µm)=	-65.15
#Full time(mm:ss)=	3:18
#Project=
#Sample=
#Site=
#Title=	Mb_30_27_38_2x_45s_532 nm_x100_100%_600 gr_mm
#Remark=
#Date=	13.07.2022 11:33
#Acquired=	13.07.2022 11:33:08
#Base:Fit=	10.08.2022 10:40:03
#Base:Sub=	10.08.2022 10:40:17
#Filter:Polynom=	16.08.2022 10:16:15
#AxisType[0]=Intens
#AxisUnit[0]=Cnt
#AxisType[1]=Spectr
#AxisUnit[1]=1/cm
200.563	23.2362
204.194	19.0976
207.821	17.7021
211.449	16.3388
215.074	15.2662
218.699	13.1108
222.321	12.1525
225.941	11.2744
229.562	11.0265
233.18	12.2276
236.796	13.3051
240.411	12.7548
244.026	12.6984
247.638	11.418
251.248	11.5824
254.857	10.6422
258.465	9.13818
262.071	9.95422
265.678	10.7891
269.282	8.91597
272.884	6.58654
276.484	6.01024
280.084	6.34316
283.682	5.69163
287.276	6.79423
290.871	7.10805
294.465	7.23062
298.057	5.97197
301.648	5.14155
305.237	5.16319
308.823	4.08458
312.41	5.53351
315.995	5.63034
319.579	8.92414
323.16	8.79292
326.741	7.63141
330.321	7.56169
333.897	7.12188
337.474	6.19135
341.048	5.55991
344.622	4.07425
348.192	3.48725
351.764	3.32483
355.332	3.4022
358.901	2.19475
362.466	2.83189
366.03	4.30255
369.594	6.36808
373.155	6.64646
376.715	7.73975
380.273	10.0828
383.832	11.5687
387.388	12.1124
390.942	13.3811
394.495	13.4442
398.047	13.9703
401.597	15.5929
405.145	15.604
408.693	14.2194
412.239	14.0046
415.783	12.7578
419.327	12.6167
422.869	10.5221
426.409	9.69645
429.948	8.9775
433.486	7.99637
437.022	5.5373
440.558	4.45657
444.089	2.93189
447.622	1.89571
451.153	2.31606
454.682	3.86991
458.208	1.65967
461.735	1.94178
465.259	4.12558
468.783	7.02317
472.306	10.1646
475.825	12.6864
479.346	16.0185
482.862	19.9094
486.38	22.5383
489.894	26.0211
493.407	28.106
496.92	31.413
500.43	34.3504
503.939	36.6539
507.448	40.2737
510.954	42.5674
514.459	44.3153
517.962	44.7525
521.466	43.5268
524.966	42.9992
528.466	41.0815
531.964	37.6034
535.46	37.3689
538.955	35.041
542.449	32.9368
545.942	28.632
549.433	27.6377
552.923	27.7222
556.412	25.0305
559.899	22.72
563.385	21.2687
566.867	17.4755
570.35	14.0508
573.832	9.10384
577.313	9.51846
580.79	7.61913
584.268	6.3312
587.745	6.5249
591.218	7.57576
594.692	6.86558
598.164	7.03697
601.634	6.2811
605.104	5.27558
608.57	4.6725
612.037	4.52282
615.501	5.55561
618.966	7.15382
622.427	8.88784
625.887	8.77757
629.348	8.33262
632.806	8.86878
636.262	9.78001
639.716	10.3454
643.172	9.31131
646.624	11.025
650.075	10.1614
653.524	8.56985
656.972	8.28609
660.419	8.9496
663.865	10.2821
667.309	10.877
670.752	13.2138
674.194	16.3678
677.634	17.5343
681.073	18.0189
684.511	20.2947
687.947	21.8953
691.382	23.7452
694.816	25.3537
698.247	26.6965
701.678	28.2928
705.108	30.3832
708.534	32.6418
711.962	35.1838
715.388	35.16
718.81	38.0176
722.234	38.5055
725.654	41.2383
729.075	41.7439
732.492	43.4723
735.91	43.7515
739.325	44.7765
742.741	45.9892
746.153	47.7066
749.564	50.0179
752.976	54.0295
756.385	57.492
759.792	58.5377
763.2	60.9826
766.604	61.0423
770.008	63.6541
773.41	64.066
776.811	66.5395
780.21	65.9355
783.608	68.8236
787.005	71.3329
790.401	75.6756
793.795	76.3272
797.188	78.762
800.58	80.0465
803.971	81.6897
807.36	83.5208
810.748	85.6511
814.135	86.5313
817.518	87.7547
820.902	87.8339
824.285	88.6206
827.665	90.5406
831.045	91.1855
834.424	89.5503
837.8	87.9275
841.177	86.8884
844.55	84.4068
847.924	81.0585
851.295	78.6951
854.666	77.4659
858.034	73.7373
861.403	71.5799
864.769	70.8185
868.133	70.1102
871.498	68.7462
874.86	68.1956
878.221	67.9854
881.58	68.1924
884.938	67.5304
888.297	66.2737
891.653	65.2109
895.007	64.8565
898.36	65.8378
901.712	66.8897
905.063	67.974
908.412	67.5126
911.76	67.9094
915.107	68.3195
918.452	69.2363
921.797	70.1779
925.138	69.1424
928.48	69.3723
931.82	66.4314
935.16	65.397
938.496	64.2796
941.833	61.3382
945.168	61.7858
948.5	62.6616
951.834	62.0361
955.163	64.0307
958.494	61.1698
961.821	59.673
965.15	61.5845
968.474	63.3333
971.8	63.6805
975.123	65.1764
978.446	68.2444
981.766	71.05
985.084	72.3636
988.402	72.8953
991.72	75.3631
995.035	76.0857
998.349	75.3527
1001.66	74.7577
1004.97	71.456
1008.28	74.755
1011.59	79.3816
1014.9	83.8243
1018.21	90.54
1021.51	95.0408
1024.81	101.072
1028.12	105.029
1031.42	109.256
1034.72	109.382
1038.02	106.897
1041.31	106.248
1044.61	107.628
1047.91	107.031
1051.2	102.566
1054.49	96.7523
1057.78	92.0461
1061.07	87.9704
1064.36	79.9607
1067.65	72.2792
1070.93	65.8033
1074.22	58.9337
1077.5	50.7266
1080.78	45.9641
1084.06	42.9123
1087.34	43.5758
1090.62	49.0812
1093.9	51.091
1097.17	52.191
1100.45	54.9677
1103.72	55.0201
1106.99	55.342
1110.27	56.9578
1113.53	57.8498
1116.8	55.5017
1120.07	54.063
1123.33	53.2763
1126.6	49.4422
1129.86	46.9414
1133.12	45.4153
1136.38	42.8546
1139.64	39.9379
1142.9	35.5027
1146.16	30.085
1149.41	28.1999
1152.67	21.9109
1155.92	19.2365
1159.17	15.2993
1162.42	11.943
1165.67	10.38
1168.92	9.42385
1172.16	8.52138
1175.41	8.42542
1178.65	9.77023
1181.9	12.3287
1185.14	13.0653
1188.38	15.0298
1191.62	20.0327
1194.86	23.2536
1198.09	27.4649
1201.33	31.9768
1204.56	38.1815
1207.8	44.9205
1211.03	52.2371
1214.26	58.3389
1217.49	65.244
1220.71	71.1859
1223.94	77.8852
1227.16	82.9554
1230.39	89.106
1233.61	95.0381
1236.83	102.028
1240.05	108.864
1243.27	115.052
1246.49	121.407
1249.71	126.459
1252.92	131.842
1256.14	135.649
1259.35	139.444
1262.56	141.605
1265.77	143.905
1268.98	146.707
1272.19	148.514
1275.4	150.598
1278.6	152.42
1281.81	155.593
1285.01	157.428
1288.21	158.7
1291.41	158.915
1294.61	158.285
1297.81	159.337
1301.01	158.882
1304.2	159.662
1307.4	159.826
1310.59	161.077
1313.78	161.299
1316.97	160.87
1320.16	161.158
1323.35	160.157
1326.54	157.833
1329.72	155.464
1332.91	152.753
1336.09	147.403
1339.27	142.292
1342.45	136.795
1345.64	130.169
1348.81	123.612
1351.99	119.235
1355.17	114.245
1358.34	108.217
1361.51	102.748
1364.69	94.7259
1367.86	89.4026
1371.03	82.8253
1374.2	79.5359
1377.37	77.5242
1380.53	76.0466
1383.7	73.8219
1386.86	72.6357
1390.02	70.4464
1393.19	67.6662
1396.35	67.7678
1399.51	67.4377
1402.66	69.4186
1405.82	71.1451
1408.97	73.6842
1412.13	76.9547
1415.28	81.3024
1418.43	88.5313
1421.59	96.0932
1424.73	104.113
1427.88	115.599
1431.03	125.538
1434.18	133.913
1437.32	140.232
1440.46	146.531
1443.61	151.792
1446.75	154.437
1449.89	156.198
1453.03	156.651
1456.16	155.128
1459.3	150.222
1462.44	142.792
1465.57	132.705
1468.7	123.574
1471.83	114.704
1474.96	103.637
1478.09	93.2752
1481.22	80.9842
1484.35	70.936
1487.47	61.7087
1490.6	55.2
1493.72	49.2804
1496.84	43.5078
1499.96	41.1668
1503.08	38.7758
1506.2	36.1256
1509.32	33.6317
1512.44	32.0435
1515.55	31.4914
1518.66	32.8716
1521.78	32.473
1524.89	32.1221
1528	32.2724
1531.11	34.0346
1534.21	35.5081
1537.32	36.6893
1540.43	38.4296
1543.53	40.8968
1546.63	43.9977
1549.74	46.7008
1552.84	47.2144
1555.94	49.6471
1559.03	51.8318
1562.13	55.4961
1565.23	58.8855
1568.32	62.2969
1571.42	66.7095
1574.51	72.0015
1577.6	76.76
1580.69	80.4354
1583.78	85.5975
1586.87	89.9376
1589.95	94.0471
1593.04	95.8858
1596.12	97.2658
1599.21	99.48
1602.29	100.549
1605.37	103.225
1608.45	106.279
1611.53	106.961
1614.6	110.149
1617.68	113.437
1620.75	118.318
1623.83	124.039
1626.9	130.895
1629.97	138.711
1633.04	147.132
1636.11	156.335
1639.18	166.284
1642.25	176.027
1645.31	185.741
1648.38	193.628
1651.44	198.555
1654.5	203.488
1657.56	206.453
1660.62	206.798
1663.68	202.77
1666.74	196.001
1669.8	190.354
1672.85	182.401
1675.91	172.94
1678.96	158.947
1682.01	146.893
1685.06	132.677
1688.11	118.131
1691.16	106.099
1694.21	95.3386
1697.25	83.3628
1700.3	72.3629
1703.34	63.8465
1706.39	55.1381
1709.43	48.0492
1712.47	43.0414
1715.51	38.2329
1718.54	34.3326
1721.58	31.2272
1724.62	29.3267
1727.65	28.4942
1730.68	27.3164
1733.72	25.9794
1736.75	23.742
1739.78	22.6122
1742.81	23.0312
1745.84	22.9626
1748.86	20.2773
1751.89	19.454
1754.91	17.1008
1757.93	15.3195
1760.96	13.7521
1763.98	13.1438
1767	12.3014
1770.02	10.6976
1773.03	8.58997
1776.05	7.25738
1779.07	5.85963
1782.08	4.84075
1785.09	4.92276
1788.11	3.89047
1791.12	3.45161
1794.13	3.39941
1797.13	2.92753
1800.14	2.67779
1803.15	2.37055
1806.15	1.77079
1809.16	1.40987
1812.16	1.57244
1815.16	1.19751
1818.16	1.19158
1821.16	1.27509
1824.16	0.754023
1827.16	1.48792
1830.16	1.75818
1833.15	2.12393
1836.14	2.79476
1839.14	3.30187
1842.13	2.65927
1845.12	2.65601
1848.11	2.6258
1851.1	2.66289
1854.08	3.22209
1857.07	2.95736
1860.05	2.97495
1863.04	2.41828
1866.02	2.96356
1869	2.81874
1871.98	3.68984
1874.96	4.4079
1877.94	4.24018
1880.92	5.52962
1882.51	5.91621
1885.5	5.94734
1888.48	7.71917
1891.47	8.21288
1894.46	8.93629
1897.44	7.94535
1900.42	8.79581
1903.41	7.95198
1906.39	8.97474
1909.37	9.39539
1912.35	9.42451
1915.32	8.17834
1918.3	7.66177
1921.27	7.2246
1924.25	5.70918
1927.22	3.78246
1930.19	3.48557
1933.17	3.12518
1936.14	3.48905
1939.11	3.42694
1942.07	3.64963
1945.04	4.10755
1948.01	2.93825
1950.97	2.75768
1953.93	2.79648
1956.9	2.52233
1959.86	2.67737
1962.82	2.80206
1965.78	2.38436
1968.74	1.78878
1971.69	2.1221
1974.65	4.24763
1977.6	5.62781
1980.56	6.05313
1983.51	6.52105
1986.46	5.99015
1989.41	6.04482
1992.36	5.71184
1995.31	5.59354
1998.26	5.54545
2001.2	6.824
2004.15	8.40833
2007.09	7.66332
2010.04	9.01596
2012.98	8.79203
2015.92	9.65488
2018.86	9.50714
2021.8	10.2857
2024.73	11.1723
2027.67	10.4467
2030.61	10.7059
2033.54	10.8865
2036.47	12.9824
2039.4	14.3538
2042.33	16.5408
2045.27	18.3723
2048.19	19.2796
2051.12	19.2243
2054.05	19.9451
2056.97	20.5152
2059.9	21.27
2062.82	22.9245
2065.74	23.0716
2068.67	24.156
2071.59	24.1268
2074.51	24.3753
2077.42	24.6171
2080.34	26.1547
2083.26	27.7774
2086.17	29.5009
2089.09	30.2411
2092	32.2466
2094.91	34.9224
2097.82	36.6413
2100.73	39.9807
2103.64	44.4886
2106.55	48.5
2109.45	53.5598
2112.36	57.8581
2115.26	61.2774
2118.17	65.0982
2121.07	70.7696
2123.97	76.9591
2126.87	83.2859
2129.77	91.0871
2132.67	99.4463
2135.56	106.184
2138.46	114.038
2141.35	121.994
2144.25	130.385
2147.14	139.192
2150.03	147.886
2152.92	155.582
2155.81	163.591
2158.7	170.673
2161.59	176.682
2164.47	183.262
2167.36	187.88
2170.24	191.432
2173.13	193.974
2176.01	194.144
2178.89	192.934
2181.77	190.578
2184.65	187.884
2187.53	183.189
2190.4	178.901
2193.28	173.737
2196.16	166.799
2199.03	159.266
2201.9	152.3
2204.77	144.112
2207.64	135.385
2210.51	127.521
2213.38	120.11
2216.25	111.437
2219.12	104.611
2221.98	97.5617
2224.85	90.7747
2227.71	83.9358
2230.57	78.3363
2233.43	71.7504
2236.29	67.4054
2239.15	62.3198
2242.01	59.0203
2244.87	54.1872
2247.72	51.0958
2250.58	47.9445
2253.43	46.4784
2256.29	43.4962
2259.14	41.4958
2261.99	39.6004
2264.84	37.6045
2267.69	36.7746
2270.53	34.4546
2273.38	34.4477
2276.23	31.5054
2279.07	29.8416
2281.91	28.5716
2284.76	26.0884
2287.6	24.5686
2290.44	22.4629
2293.28	19.0964
2296.12	18.3048
2298.96	17.4021
2301.79	16.197
2304.63	15.6538
2307.46	15.473
2310.3	15.2601
2313.13	15.3094
2315.96	14.8013
2318.79	13.6691
2321.62	13.0926
2324.45	12.7884
2327.27	12.519
2330.1	12.6329
2332.92	11.575
2335.75	11.8801
2338.57	11.8078
2341.39	11.1465
2344.21	10.7173
2347.04	8.92042
2349.85	8.84676
2352.67	7.6792
2355.49	6.24322
2358.3	5.14814
2361.12	4.83162
2363.93	4.67783
2366.75	4.79794
2369.56	4.52783
2372.37	4.145
2375.18	3.3187
2377.99	2.90817
2380.8	3.43811
2383.6	2.12126
2386.41	1.07492
2389.21	0.76751
2392.02	0.349676
2394.82	-0.491113
2397.62	-0.521383
2400.42	-1.45093
2403.22	-0.588241
2406.02	0.223347
2408.82	1.08083
2411.62	1.96301
2414.41	2.1369
2417.21	4.01625
2420	4.71245
2422.79	5.49668
2425.59	6.39818
2428.38	6.62158
2431.17	6.86838
2433.95	6.72488
2436.74	7.11518
2439.53	7.57699
2442.31	6.68689
2445.1	6.36809
2447.88	6.71002
2450.67	6.35674
2453.45	6.00517
2456.23	6.90538
2459.01	6.31259
2461.79	4.68378
2464.57	4.73548
2467.34	5.73414
2470.12	6.00151
2472.89	6.23073
2475.67	5.66453
2478.44	6.68939
2481.21	6.65562
2483.98	7.27201
2486.75	7.11707
2489.52	6.49555
2492.29	7.00594
2495.05	6.38223
2497.82	5.60902
2500.58	4.18678
2503.35	3.5252
2506.11	3.17454
2508.87	1.98388
2511.63	0.72641
2514.39	0.75659
2517.15	0.49437
2519.91	0.557264
2522.67	0.237597
2525.42	0.367043
2528.18	0.638975
2530.93	1.41427
2533.69	2.8908
2536.44	2.92162
2539.19	2.46665
2541.94	1.90803
2544.69	2.55214
2547.44	2.59192
2550.18	2.48009
2552.93	2.5355
2555.67	3.35523
2558.42	3.81122
2561.16	3.4567
2563.9	2.72032
2566.64	3.19505
2569.38	3.05415
2572.12	3.42228
2574.86	2.87992
2577.6	2.60563
2580.33	2.8405
2583.07	3.18777
2585.8	3.43524
2588.54	3.60466
2591.27	3.76514
2594	3.87895
2596.73	3.3947
2599.46	2.98412
2602.19	2.0497
2604.92	0.687435
2607.64	0.28261
2610.37	-0.0866999
2613.09	-0.494166
2615.82	-0.455574
2618.54	0.169312
2621.26	-0.205506
2623.98	0.910485
2626.7	0.709346
2629.42	1.53623
2632.14	2.61389
2634.86	2.56852
2637.57	2.80939
2640.29	3.26908
2643	3.22494
2645.71	3.73036
2648.43	4.28966
2651.14	5.44215
2653.85	5.25474
2656.56	5.45146
2659.26	4.51189
2661.97	4.61812
2664.68	4.83163
2667.38	5.48022
2670.09	4.32272
2672.79	3.52494
2675.49	3.40167
2678.19	3.14344
2680.89	2.76248
2683.59	2.37141
2686.29	1.67243
2688.99	1.5923
2691.69	2.33307
2694.38	2.13866
2697.08	2.23683
2699.77	3.0114
2702.46	3.44595
2705.15	4.86748
2707.85	5.59139
2710.54	6.86586
2713.22	8.46666
2715.91	9.98202
2718.6	11.1531
2721.29	11.7922
2723.97	12.1715
2726.66	13.7417
2729.34	14.7333
2732.02	14.9207
2734.7	14.7079
2737.38	13.9845
2740.06	13.1679
2742.74	12.4858
2745.42	10.8402
2748.09	9.60836
2750.77	7.21744
2753.45	6.44333
2756.12	5.13286
2758.79	3.51496
2761.46	2.37523
2764.14	2.29755
2766.8	2.03496
2769.47	1.0562
2772.14	0.840929
2774.81	0.507628
2777.48	0.343866
2780.14	0.12902
2782.8	-0.0961278
2785.47	-0.950228
2788.13	-0.631472
2790.79	0.328512
2793.45	0.97519
2796.11	1.34046
2798.77	1.61146
2801.43	2.11102
2804.09	1.58405
2806.74	1.27854
2809.4	1.54491
2812.05	1.70647
2814.71	2.55942
2817.36	5.42698
2820.01	8.95955
2822.66	13.5775
2825.31	17.8815
2827.96	23.528
2830.6	30.4107
2833.25	37.5071
2835.9	45.7123
2838.54	55.3134
2841.18	64.2685
2843.83	75.9383
2846.47	88.8868
2849.11	102.607
2851.75	117.766
2854.39	135.101
2857.03	150.754
2859.66	166.938
2862.3	182.299
2864.94	196.479
2867.57	209.451
2870.2	221.608
2872.84	231.745
2875.47	243.537
2878.1	253.806
2880.73	263.996
2883.36	272.794
2885.99	281.946
2888.61	291.629
2891.24	300.342
2893.86	311.494
2896.49	323.164
2899.11	336.417
2901.73	351.407
2904.36	369.314
2906.98	389.958
2909.6	413.749
2912.21	438.83
2914.83	465.987
2917.45	491.287
2920.07	516.195
2922.68	537.457
2925.29	556.644
2927.91	569.979
2930.52	579.039
2933.13	583.964
2935.74	583.701
2938.35	578.979
2940.96	570.695
2943.57	557.135
2946.18	540.28
2948.78	519.918
2951.39	499.016
2953.99	474.873
2956.59	449.488
2959.2	423.819
2961.8	398.48
2964.4	374.684
2967	352.269
2969.6	331.118
2972.19	311.171
2974.79	292.774
2977.39	275.184
2979.98	257.19
2982.58	238.854
2985.17	220.924
2987.76	203.3
2990.35	184.694
2992.94	166.999
2995.53	150.879
2998.12	135.219
3000.71	119.673
3003.3	105.209
3005.88	91.4692
3008.47	78.8652
3011.05	67.0881
3013.64	56.3176
3016.22	47.1385
3018.8	39.6053
3021.38	33.6294
3023.96	28.9503
3026.54	25.8786
3029.12	23.9407
3031.69	20.8358
3034.27	19.5818
3036.84	19.3055
3039.42	19.6656
3041.99	20.7007
3044.57	20.5615
3047.14	21.6073
3049.71	22.5783
3052.28	24.5165
3054.85	25.938
3057.41	26.6581
3059.98	26.2818
3062.55	26.2905
3065.11	25.7275
3067.68	24.202
3070.24	22.0536
3072.8	19.8452
3075.36	17.1708
3077.93	14.5259
3080.49	12.2837
3083.04	9.84677
3085.6	7.39613
3088.16	5.49528
3090.72	2.81112
3093.27	1.38967
3095.83	0.745006
3098.38	0.56089
3100.93	0.296284
3103.49	0.417411
3106.04	0.0143734
3108.59	0.618438
3111.14	1.40253
3113.69	2.6231
3116.23	3.82258
3118.78	4.38717
3121.33	5.31696
3123.87	6.83873
3126.41	8.22176
3128.96	9.00543
3131.5	9.63113
3134.04	11.1522
3136.58	12.7648
3139.12	14.1419
3141.66	15.2665
3144.2	16.8802
3146.74	18.825
3149.27	21.8175