File: data/Raman/poly_smoothed/Mb_30_27_09_1x_45s_532 nm_x100_100%_600 gr_mm_01.txt
#Acq. time (s)=	45
#Accumulations=	2
#Range (cm-¹)=	200...3150
#Windows=	2
#Auto scanning=	Off
#Autofocus=	Off
#Macrospot=	Off
#AutoExposure=	Off
#Spike filter=	Multiple accum.
#Delay time (s)=	0
#Binning=	1
#Readout mode=	Signal
#DeNoise=	Off
#ICS correction=	On
#Dark correction=	Off
#Inst. Process=	Off
#Detector Gain=	Best Dynamic Range
#Detector ADC=	20 kHz
#Detector temperature (°C)=	-69.85
#Instrument=	LabRAM HR Evol
#Detector=	Synapse
#Objective=	x100
#Grating=	600 gr/mm
#ND Filter=	100%
#Laser (nm)=	532
#Hole=	100.021
#Range=	Auto
#Laser Pol.=	No
#Raman. Pol.=	No
#Laser Pol. (°)=	-0.0007625
#Raman Pol. (°)=	89.9995
#Collection=	Microscope
#StageXY=	Marzhauser
#StageZ=	Marzhauser
#X (µm)=	-1280.8
#Y (µm)=	1616.1
#Z (µm)=	-6.35
#Full time(mm:ss)=	3:18
#Project=
#Sample=
#Site=
#Title=	Mb_30_27_09_2x_45s_532 nm_x100_100%_600 gr_mm
#Remark=
#Date=	12.07.2022 16:38
#Acquired=	12.07.2022 16:38:50
#Base:Fit=	10.08.2022 10:39:47
#Base:Sub=	10.08.2022 10:39:55
#Base:Fit=	10.08.2022 10:40:03
#Base:Sub=	10.08.2022 10:40:17
#Filter:Polynom=	16.08.2022 10:16:15
#AxisType[0]=Intens
#AxisUnit[0]=Cnt
#AxisType[1]=Spectr
#AxisUnit[1]=1/cm
200.413	51.3871
204.042	41.1181
207.671	31.6009
211.297	24.2067
214.924	18.4208
218.547	12.8181
222.169	7.87527
225.792	4.34975
229.411	3.24715
233.028	2.48291
236.647	1.20437
240.261	0.0197802
243.875	-0.738653
247.487	-0.381964
251.099	1.45632
254.708	1.86438
258.316	4.46609
261.922	4.28907
265.527	5.19363
269.131	6.7007
272.733	6.92718
276.334	5.97336
279.933	6.54064
283.531	4.80472
287.128	6.433
290.723	7.49858
294.316	7.25703
297.909	8.78831
301.498	10.0129
305.087	8.84031
308.675	10.2182
312.262	10.8518
315.845	11.2312
319.429	11.8834
323.012	11.2956
326.591	11.5687
330.171	11.7638
333.749	11.1555
337.324	11.1092
340.9	12.1794
344.472	12.0784
348.045	12.7787
351.614	12.7774
355.185	13.7935
358.751	12.9837
362.317	11.6901
365.883	10.6985
369.445	11.1937
373.006	11.6474
376.568	12.5083
380.126	12.7613
383.683	14.0515
387.239	16.1281
390.793	16.552
394.348	18.0445
397.9	18.2598
401.45	19.1855
404.999	18.7291
408.546	17.2203
412.092	16.8815
415.637	15.44
419.18	13.3591
422.722	11.6291
426.263	13.4648
429.802	11.16
433.338	9.37219
436.874	8.49328
440.41	7.54613
443.943	5.26051
447.476	4.44725
451.005	5.29195
454.534	5.25823
458.063	7.12291
461.588	8.26475
465.113	11.5958
468.638	14.2344
472.158	16.3826
475.68	18.4623
479.198	19.897
482.717	21.887
486.233	22.7777
489.747	22.0425
493.261	23.6282
496.773	24.4692
500.285	24.4449
503.794	25.2046
507.301	26.3543
510.807	26.0705
514.314	24.2686
517.817	23.1992
521.319	22.6597
524.82	21.6497
528.319	20.0186
531.817	20.2721
535.316	20.7317
538.811	18.9388
542.305	18.9921
545.798	18.8386
549.289	18.3271
552.777	14.6682
556.265	13.0682
559.753	11.6217
563.239	10.6161
566.723	10.0717
570.207	7.89023
573.688	7.96036
577.167	7.46401
580.646	5.49974
584.124	5.30662
587.599	4.87165
591.074	4.6834
594.548	3.67025
598.019	4.01073
601.49	4.80097
604.958	4.64813
608.427	4.15624
611.892	5.03308
615.358	6.04773
618.821	7.46505
622.282	9.40257
625.744	10.2554
629.203	10.9869
632.661	9.4776
636.119	8.91199
639.574	9.6598
643.027	12.0683
646.479	11.9152
649.932	12.9696
653.382	12.7278
656.83	12.2953
660.277	13.1175
663.722	11.7305
667.167	13.6213
670.61	14.8658
674.051	18.0035
677.492	17.6484
680.931	19.5483
684.369	20.7549
687.803	22.909
691.238	25.0274
694.672	27.0331
698.105	29.01
701.536	31.4788
704.964	32.2035
708.393	33.8396
711.82	34.8306
715.244	34.6753
718.669	34.8639
722.09	36.1142
725.512	36.3138
728.933	37.3225
732.351	37.9442
735.767	38.6196
739.184	39.178
742.598	38.0376
746.012	38.957
749.423	42.1949
752.833	45.3035
756.244	47.9783
759.651	48.5165
763.057	49.9452
766.462	52.7641
769.865	55.2726
773.269	57.4463
776.67	59.2377
780.069	61.469
783.468	64.4487
786.865	67.3859
790.26	69.1781
793.655	69.525
797.048	70.2442
800.44	69.6128
803.83	72.3423
807.218	72.6159
810.606	73.5597
813.993	74.8133
817.378	73.5723
820.762	73.223
824.143	71.347
827.525	68.6866
830.905	69.1176
834.282	67.899
837.66	65.2245
841.035	63.0972
844.41	59.5023
847.782	57.5081
851.155	55.2644
854.525	52.9421
857.895	51.2395
861.262	47.2158
864.628	45.7807
867.994	46.2276
871.357	43.5098
874.719	40.0123
878.082	38.8105
881.441	40.1259
884.799	41.3992
888.156	42.2595
891.512	41.2624
894.866	41.872
898.22	43.1917
901.573	43.7096
904.924	44.5546
908.271	43.1281
911.62	43.4578
914.966	44.7682
918.312	43.7968
921.656	42.579
925	41.5555
928.341	39.5057
931.68	39.5634
935.019	37.0158
938.358	35.452
941.694	31.7407
945.028	29.5145
948.362	27.1321
951.694	24.668
955.026	22.3723
958.356	19.1968
961.684	19.4179
965.012	19.4145
968.337	19.4148
971.661	19.3656
974.985	20.8306
978.306	21.3866
981.626	22.2059
984.947	21.9787
988.264	21.9398
991.581	21.2783
994.896	21.3023
998.212	19.3641
1001.52	16.7219
1004.84	14.8127
1008.15	15.8072
1011.45	23.7547
1014.76	37.8335
1018.07	53.2515
1021.37	67.2882
1024.68	80.3795
1027.98	93.2306
1031.28	105.252
1034.58	115.346
1037.88	122.111
1041.18	126.817
1044.47	128.19
1047.77	129.224
1051.06	126.024
1054.35	121.324
1057.64	115.107
1060.94	103.785
1064.22	91.3924
1067.51	78.6829
1070.8	64.7376
1074.08	48.8711
1077.36	34.8179
1080.65	19.5181
1083.93	9.68773
1087.21	5.53528
1090.49	7.0275
1093.76	12.1729
1097.04	15.4731
1100.31	18.0841
1103.59	19.9491
1106.86	22.9775
1110.13	24.7586
1113.4	25.9188
1116.66	24.7358
1119.93	24.9651
1123.2	23.38
1126.46	22.8383
1129.72	22.383
1132.99	20.4387
1136.25	19.8074
1139.51	17.1355
1142.77	14.4891
1146.02	12.8973
1149.28	12.9019
1152.53	9.82122
1155.78	8.58917
1159.04	5.78379
1162.29	4.91688
1165.54	3.61912
1168.78	3.53804
1172.03	2.87943
1175.27	3.55972
1178.52	3.3713
1181.76	4.84322
1185	6.01327
1188.24	7.44085
1191.48	8.36929
1194.72	10.655
1197.96	12.0661
1201.19	14.3213
1204.43	15.7944
1207.66	18.2517
1210.89	20.4912
1214.12	22.7446
1217.35	26.1856
1220.58	28.9813
1223.81	31.7219
1227.03	35.6895
1230.26	37.9646
1233.48	40.7945
1236.7	45.1686
1239.92	47.4009
1243.14	51.6603
1246.36	53.8947
1249.57	55.8911
1252.79	57.5624
1256	58.6256
1259.22	61.4236
1262.43	63.4149
1265.64	65.1684
1268.85	67.2904
1272.06	69.3442
1275.26	71.8105
1278.47	75.2042
1281.67	77.3084
1284.88	80.1315
1288.08	80.6498
1291.28	82.314
1294.48	82.7168
1297.68	84.4549
1300.87	86.0055
1304.07	85.653
1307.26	85.5968
1310.46	88.3603
1313.65	88.7986
1316.84	88.8532
1320.03	88.9374
1323.22	89.6113
1326.4	89.5521
1329.59	87.7648
1332.78	86.7567
1335.96	85.4995
1339.14	85.7954
1342.32	82.8613
1345.5	83.7868
1348.68	82.0584
1351.86	83.2495
1355.03	83.0527
1358.21	81.2118
1361.38	78.615
1364.56	75.1069
1367.73	73.3605
1370.9	70.7201
1374.07	67.9623
1377.23	67.2635
1380.4	66.5804
1383.57	64.6189
1386.73	63.5391
1389.89	63.2429
1393.05	61.1237
1396.21	59.7566
1399.37	57.9915
1402.53	56.3093
1405.69	56.378
1408.84	55.7425
1412	58.0773
1415.15	60.2447
1418.3	64.2301
1421.45	69.1154
1424.6	76.2037
1427.75	82.1785
1430.9	87.9967
1434.04	94.3716
1437.19	98.3935
1440.33	104.095
1443.47	109.918
1446.62	113.411
1449.76	115.649
1452.9	117.017
1456.03	119.419
1459.17	119.233
1462.3	117.535
1465.44	116.392
1468.57	113.499
1471.7	109.491
1474.83	105.626
1477.96	100.763
1481.09	95.8441
1484.22	88.8574
1487.34	84.7228
1490.47	79.543
1493.59	75.4802
1496.71	71.5856
1499.83	67.4732
1502.95	64.0368
1506.07	61.0904
1509.19	56.9893
1512.3	54.0712
1515.42	52.2118
1518.53	48.7952
1521.65	46.0348
1524.76	45.0601
1527.87	43.34
1530.98	42.8078
1534.08	42.5111
1537.19	41.7934
1540.3	42.9153
1543.4	45.2613
1546.5	48.6293
1549.61	49.6623
1552.71	49.3292
1555.81	50.8683
1558.9	52.2811
1562	52.9609
1565.1	54.9648
1568.19	56.2006
1571.29	60.1811
1574.38	62.529
1577.47	66.1594
1580.56	68.3997
1583.65	69.7755
1586.74	73.6118
1589.82	77.5115
1592.91	78.3509
1595.99	80.4188
1599.08	80.7543
1602.16	82.4392
1605.24	82.258
1608.32	81.576
1611.4	81.2009
1614.48	81.5265
1617.55	81.8892
1620.63	81.4155
1623.7	80.5442
1626.77	80.6482
1629.84	81.3035
1632.92	82.7562
1635.98	83.5172
1639.05	84.9632
1642.12	87.4874
1645.19	88.8085
1648.25	91.2076
1651.31	92.3609
1654.38	93.348
1657.44	93.8615
1660.5	95.1269
1663.56	95.2704
1666.61	91.469
1669.67	86.1935
1672.72	81.3799
1675.78	76.6788
1678.83	73.4776
1681.88	68.0564
1684.93	62.3852
1687.98	57.34
1691.03	50.9125
1694.08	46.7997
1697.13	42.7342
1700.17	39.7631
1703.21	34.6379
1706.26	29.6192
1709.3	25.7427
1712.34	23.4005
1715.38	19.7974
1718.42	16.0549
1721.45	14.1003
1724.49	13.3995
1727.52	12.1563
1730.56	11.5161
1733.59	8.85015
1736.62	7.66362
1739.65	6.67727
1742.68	6.05527
1745.71	4.68682
1748.74	4.74449
1751.76	5.58721
1754.79	6.60677
1757.81	6.35322
1760.83	7.41769
1763.85	7.66465
1766.87	7.68118
1769.89	8.85987
1772.91	7.54638
1775.93	7.18902
1778.94	5.49661
1781.95	4.9163
1784.97	5.59762
1787.98	4.7964
1790.99	3.72423
1794	3.03835
1797.01	2.79466
1800.02	2.19353
1803.02	1.4198
1806.03	1.34296
1809.03	2.00838
1812.03	3.36457
1815.04	2.91726
1818.04	2.97054
1821.04	2.65456
1824.04	2.30757
1827.03	2.71924
1830.03	2.39759
1833.02	3.04153
1836.02	4.22431
1839.01	4.21623
1842	4.70618
1844.99	3.95597
1847.98	3.67645
1850.97	4.1237
1853.96	5.03925
1856.95	4.89603
1859.93	5.73144
1862.91	5.01541
1865.9	4.26479
1868.88	3.66855
1871.86	3.07561
1874.84	4.52792
1877.82	4.4525
1880.79	4.83463
1882.53	4.93564
1885.52	4.9551
1888.51	5.70861
1891.49	5.35494
1894.48	6.4898
1897.46	6.23478
1900.45	6.33548
1903.43	7.16009
1906.41	8.40277
1909.39	8.68993
1912.37	8.44088
1915.35	8.54716
1918.32	7.66458
1921.3	9.12598
1924.27	9.06938
1927.25	9.06288
1930.22	9.10312
1933.19	8.41992
1936.16	6.85631
1939.13	6.17938
1942.1	5.77693
1945.06	6.30851
1948.03	5.83292
1950.99	5.1578
1953.96	5.75624
1956.92	5.55005
1959.88	5.61085
1962.84	6.01894
1965.8	5.87278
1968.76	6.56683
1971.72	7.21829
1974.67	7.72182
1977.63	9.16245
1980.58	9.80913
1983.53	9.23606
1986.48	9.04808
1989.43	8.81575
1992.39	8.58456
1995.33	8.96429
1998.28	8.94941
2001.23	9.01713
2004.17	10.0943
2007.11	10.8878
2010.06	10.3978
2013	9.90741
2015.94	9.91926
2018.88	9.39114
2021.82	8.8926
2024.76	10.8784
2027.69	10.5538
2030.63	10.243
2033.56	10.9032
2036.5	11.2226
2039.43	12.9811
2042.36	13.4696
2045.29	14.0634
2048.22	14.7918
2051.14	14.27
2054.07	14.3028
2057	14.1794
2059.92	14.8357
2062.85	16.3912
2065.77	16.6183
2068.69	17.2342
2071.61	18.6152
2074.53	19.0341
2077.45	19.571
2080.36	19.2194
2083.28	18.1201
2086.19	19.6781
2089.11	21.0315
2092.02	23.0043
2094.93	24.9926
2097.84	27.0777
2100.75	28.5885
2103.66	30.4699
2106.57	33.0217
2109.48	37.1232
2112.38	37.9701
2115.29	40.6029
2118.19	44.3358
2121.09	46.9056
2123.99	49.4816
2126.89	53.1096
2129.79	54.9606
2132.69	58.279
2135.59	60.765
2138.48	63.3076
2141.38	66.0156
2144.27	66.2295
2147.16	68.7424
2150.06	71.113
2152.95	73.7723
2155.83	77.8889
2158.72	80.3154
2161.61	83.3724
2164.5	84.9973
2167.38	85.9825
2170.27	86.2572
2173.15	87.6755
2176.03	88.0128
2178.91	87.0859
2181.79	86.0928
2184.67	84.7997
2187.55	83.1649
2190.43	80.9891
2193.3	78.0587
2196.18	74.9245
2199.05	72.3485
2201.92	69.6549
2204.8	65.8912
2207.67	61.8757
2210.54	58.236
2213.4	54.0297
2216.27	50.5998
2219.14	48.9702
2222	47.3592
2224.87	45.8865
2227.73	44.4508
2230.59	42.5665
2233.46	40.4659
2236.32	37.6563
2239.18	36.6287
2242.03	34.5033
2244.89	33.578
2247.75	31.6343
2250.6	30.809
2253.45	27.8496
2256.31	25.6613
2259.16	23.0793
2262.01	21.9094
2264.86	19.8648
2267.71	19.2379
2270.56	18.5027
2273.4	16.3393
2276.25	14.9995
2279.09	13.5057
2281.94	12.7303
2284.78	11.4919
2287.62	10.9815
2290.46	10.3289
2293.3	9.09502
2296.14	10.004
2298.98	9.60738
2301.81	10.2467
2304.65	11.0838
2307.48	11.6781
2310.32	12.2915
2313.15	12.3049
2315.98	13.0652
2318.81	12.124
2321.64	10.1106
2324.47	8.61614
2327.3	7.97445
2330.12	7.55435
2332.95	8.05621
2335.77	8.19779
2338.59	7.75306
2341.42	6.89563
2344.24	5.85158
2347.06	4.17344
2349.88	3.7643
2352.69	2.80936
2355.51	3.93226
2358.33	3.72956
2361.14	4.14532
2363.96	5.73082
2366.77	7.30072
2369.58	7.00673
2372.39	7.55727
2375.2	6.01464
2378.01	6.66182
2380.82	6.91734
2383.63	6.1151
2386.43	5.00214
2389.24	3.45032
2392.04	3.09755
2394.84	3.35175
2397.64	4.03347
2400.45	3.18458
2403.25	4.19392
2406.04	4.38063
2408.84	4.81672
2411.64	5.43712
2414.43	6.46424
2417.23	6.90257
2420.02	8.16597
2422.82	9.68952
2425.61	11.8109
2428.4	12.408
2431.19	12.8025
2433.98	11.6525
2436.76	12.2659
2439.55	12.3539
2442.34	11.1134
2445.12	11.3323
2447.9	11.4558
2450.69	11.0521
2453.47	10.8463
2456.25	10.2645
2459.03	9.42773
2461.81	9.31399
2464.59	8.58773
2467.36	8.39511
2470.14	8.11422
2472.91	7.77204
2475.69	6.5397
2478.46	5.64456
2481.23	4.84749
2484	3.41196
2486.77	3.03925
2489.54	3.1721
2492.31	3.35726
2495.08	2.76214
2497.84	1.28255
2500.61	1.23975
2503.37	1.59592
2506.13	2.96987
2508.89	2.21117
2511.66	2.30416
2514.42	3.6275
2517.17	5.04491
2519.93	6.12825
2522.69	6.04067
2525.44	5.45022
2528.2	5.4944
2530.95	7.07523
2533.71	7.07724
2536.46	7.54585
2539.21	6.52488
2541.96	5.65542
2544.71	5.64038
2547.46	5.79607
2550.2	5.67556
2552.95	5.17704
2555.69	5.16323
2558.44	5.58775
2561.18	4.78533
2563.92	4.99323
2566.67	5.84705
2569.41	7.50662
2572.14	7.94075
2574.88	7.7503
2577.62	8.60736
2580.36	9.07847
2583.09	10.0858
2585.83	9.58656
2588.56	9.44832
2591.29	9.18395
2594.02	10.0755
2596.75	11.0494
2599.48	11.1003
2602.21	10.0095
2604.94	9.62571
2607.67	8.32746
2610.39	7.82832
2613.12	7.69237
2615.84	8.20527
2618.56	8.26401
2621.28	8.04278
2624	7.97762
2626.72	7.66953
2629.44	7.60554
2632.16	7.18448
2634.88	8.12254
2637.59	8.65738
2640.31	8.65192
2643.02	8.41142
2645.73	8.77708
2648.45	7.95782
2651.16	8.50407
2653.87	8.3174
2656.58	8.19909
2659.28	7.66428
2661.99	7.03036
2664.7	5.18324
2667.4	4.95514
2670.11	3.98642
2672.81	2.7399
2675.51	2.76188
2678.21	2.87212
2680.92	3.76533
2683.62	3.29227
2686.31	3.85029
2689.01	4.09748
2691.71	4.596
2694.4	4.3345
2697.1	6.22919
2699.79	7.23639
2702.48	9.40357
2705.18	10.2393
2707.87	11.125
2710.56	11.9602
2713.25	13.6541
2715.93	13.9144
2718.62	13.3132
2721.31	12.853
2723.99	12.5889
2726.68	11.6962
2729.36	10.528
2732.04	9.56421
2734.72	8.18822
2737.4	7.29008
2740.08	6.14451
2742.76	5.2141
2745.44	5.71202
2748.12	4.53802
2750.79	4.16531
2753.47	4.16602
2756.14	3.25525
2758.81	2.31735
2761.48	3.14827
2764.16	3.13367
2766.83	3.47856
2769.49	2.94888
2772.16	2.75146
2774.83	2.04701
2777.5	1.55875
2780.16	0.735978
2782.83	0.884979
2785.49	0.493957
2788.15	-0.266212
2790.81	-0.446601
2793.47	-1.44229
2796.13	-1.69867
2798.79	-1.79781
2801.45	-1.99187
2804.11	-2.40068
2806.76	-2.9679
2809.42	-2.32855
2812.07	-2.05625
2814.73	-1.36844
2817.38	0.72155
2820.03	1.94594
2822.68	3.88496
2825.33	7.9171
2827.98	11.6392
2830.62	14.8638
2833.27	18.6546
2835.92	22.5818
2838.56	28.2745
2841.2	33.7006
2843.85	40.8257
2846.49	49.2677
2849.13	57.4029
2851.77	65.7964
2854.41	75.4401
2857.05	84.9988
2859.68	93.2817
2862.32	101.563
2864.96	109.376
2867.59	115.279
2870.22	121.564
2872.86	127.702
2875.49	133.891
2878.12	139.577
2880.75	144.218
2883.38	148.417
2886.01	152.932
2888.63	157.922
2891.26	163.086
2893.88	168.613
2896.51	175.085
2899.13	182.775
2901.76	191.316
2904.38	201.5
2907	213.747
2909.62	225.614
2912.24	237.599
2914.85	250.317
2917.47	263.041
2920.09	273.14
2922.7	281.982
2925.31	289.432
2927.93	295.639
2930.54	299.459
2933.15	300.662
2935.76	299.28
2938.37	296.696
2940.98	291.443
2943.59	284.803
2946.2	275.428
2948.8	265.711
2951.41	254.898
2954.01	243.874
2956.62	230.73
2959.22	218.265
2961.82	207.462
2964.42	195.809
2967.02	185.029
2969.62	174.426
2972.21	164.165
2974.81	153.312
2977.41	143.479
2980	132.765
2982.6	122.569
2985.19	112.086
2987.78	103.741
2990.37	93.0977
2992.96	83.6176
2995.55	74.3832
2998.14	65.5259
3000.73	56.5317
3003.32	48.0381
3005.9	39.7201
3008.49	33.4222
3011.07	26.1841
3013.66	20.2525
3016.24	15.5837
3018.82	11.1326
3021.4	7.47959
3023.98	5.9892
3026.56	3.709
3029.14	2.02496
3031.71	1.60499
3034.29	1.42632
3036.86	0.983098
3039.44	0.0937315
3042.01	-0.269282
3044.59	0.363412
3047.16	1.3549
3049.73	1.35667
3052.3	1.83177
3054.87	2.0726
3057.43	1.69364
3060	1.95355
3062.57	1.50697
3065.13	1.59935
3067.7	1.17419
3070.26	1.15951
3072.82	0.573706
3075.39	0.836147
3077.95	0.985094
3080.51	-0.0425031
3083.07	-0.389649
3085.62	-0.604468
3088.18	0.781497
3090.74	1.3065
3093.29	1.41557
3095.85	2.36727
3098.4	2.38891
3100.95	3.0394
3103.51	3.70011
3106.06	4.24258
3108.61	5.6518
3111.16	6.89298
3113.71	7.91685
3116.25	8.87775
3118.8	9.86561
3121.34	11.8179
3123.89	13.0284
3126.43	14.4815
3128.98	15.8687
3131.52	17.4665
3134.06	19.6078
3136.6	21.1676
3139.14	24.5133
3141.68	26.7786
3144.22	30.3162
3146.75	34.4505
3149.29	38.1476