File: data/Raman/poly_smoothed/Mb_30_27_50_1x_45s_532 nm_x100_100%_600 gr_mm_01.txt
#Acq. time (s)=	45
#Accumulations=	2
#Range (cm-¹)=	200...3150
#Windows=	2
#Auto scanning=	Off
#Autofocus=	Off
#Macrospot=	Off
#AutoExposure=	Off
#Spike filter=	Multiple accum.
#Delay time (s)=	0
#Binning=	1
#Readout mode=	Signal
#DeNoise=	Off
#ICS correction=	On
#Dark correction=	Off
#Inst. Process=	Off
#Detector Gain=	Best Dynamic Range
#Detector ADC=	20 kHz
#Detector temperature (°C)=	-69.85
#Instrument=	LabRAM HR Evol
#Detector=	Synapse
#Objective=	x100
#Grating=	600 gr/mm
#ND Filter=	100%
#Laser (nm)=	532
#Hole=	100.021
#Range=	Auto
#Laser Pol.=	No
#Raman. Pol.=	No
#Laser Pol. (°)=	-0.0007625
#Raman Pol. (°)=	89.9995
#Collection=	Microscope
#StageXY=	Marzhauser
#StageZ=	Marzhauser
#X (µm)=	-6368
#Y (µm)=	716
#Z (µm)=	-64.85
#Full time(mm:ss)=	3:18
#Project=
#Sample=
#Site=
#Title=	Mb_30_27_50_2x_45s_532 nm_x100_100%_600 gr_mm
#Remark=
#Date=	13.07.2022 12:31
#Acquired=	13.07.2022 12:31:26
#Base:Fit=	10.08.2022 10:40:03
#Base:Sub=	10.08.2022 10:40:17
#Filter:Polynom=	16.08.2022 10:16:15
#AxisType[0]=Intens
#AxisUnit[0]=Cnt
#AxisType[1]=Spectr
#AxisUnit[1]=1/cm
200.563	27.1013
204.194	24.9018
207.821	20.0918
211.449	17.1149
215.074	14.9265
218.699	11.1304
222.321	9.24619
225.941	8.43533
229.562	6.93659
233.18	3.86833
236.796	3.05194
240.411	3.75285
244.026	3.80103
247.638	5.00108
251.248	4.45787
254.857	6.51973
258.465	7.77267
262.071	10.7362
265.678	12.5251
269.282	12.5849
272.884	12.3575
276.484	14.8248
280.084	18.6737
283.682	20.0239
287.276	19.5474
290.871	18.6451
294.465	20.3979
298.057	22.1558
301.648	23.0314
305.237	23.2493
308.823	25.0464
312.41	25.215
315.995	24.4051
319.579	23.2155
323.16	23.0286
326.741	23.1029
330.321	22.6001
333.897	22.5354
337.474	22.6394
341.048	21.0541
344.622	20.5377
348.192	20.0556
351.764	19.406
355.332	17.2341
358.901	15.9265
362.466	17.0176
366.03	17.8606
369.594	16.6423
373.155	15.2252
376.715	13.659
380.273	14.1411
383.832	15.7321
387.388	17.7778
390.942	18.1154
394.495	20.3578
398.047	19.7272
401.597	20.0575
405.145	20.1386
408.693	19.7485
412.239	18.4131
415.783	17.0543
419.327	16.4118
422.869	15.5803
426.409	14.5206
429.948	13.4695
433.486	12.1641
437.022	11.0092
440.558	9.99352
444.089	8.01236
447.622	8.10719
451.153	7.55085
454.682	9.08003
458.208	8.86957
461.735	9.41046
465.259	11.0934
468.783	13.8432
472.306	16.3418
475.825	16.1872
479.346	16.4948
482.862	18.6479
486.38	18.3858
489.894	19.3504
493.407	19.2448
496.92	19.145
500.43	17.8515
503.939	18.9387
507.448	18.6702
510.954	18.091
514.459	18.8241
517.962	17.643
521.466	16.7551
524.966	16.2948
528.466	15.5437
531.964	16.1274
535.46	17.0329
538.955	16.803
542.449	17.183
545.942	16.8048
549.433	16.51
552.923	17.0665
556.412	14.6269
559.899	13.3221
563.385	11.7246
566.867	11.3402
570.35	9.53593
573.832	8.54
577.313	6.70296
580.79	6.66495
584.268	6.33819
587.745	6.35587
591.218	6.73589
594.692	6.78981
598.164	6.01269
601.634	4.41727
605.104	4.88948
608.57	5.31505
612.037	4.98801
615.501	5.46819
618.966	5.72518
622.427	6.11981
625.887	6.84568
629.348	10.2364
632.806	11.1357
636.262	12.4015
639.716	12.5406
643.172	12.737
646.624	13.3665
650.075	13.429
653.524	15.1292
656.972	15.9472
660.419	16.7165
663.865	19.5172
667.309	20.7411
670.752	22.1781
674.194	23.2503
677.634	24.0188
681.073	25.9823
684.511	27.407
687.947	27.3183
691.382	29.3293
694.816	28.4668
698.247	29.2702
701.678	30.9732
705.108	32.4635
708.534	33.5702
711.962	35.8851
715.388	36.1091
718.81	36.084
722.234	36.4021
725.654	36.0823
729.075	36.1847
732.492	37.3832
735.91	38.6774
739.325	39.5021
742.741	42.0952
746.153	44.0737
749.564	46.1473
752.976	48.4492
756.385	51.0641
759.792	53.899
763.2	56.7766
766.604	61.6202
770.008	62.5266
773.41	64.3954
776.811	65.9313
780.21	68.3545
783.608	71.0819
787.005	72.3879
790.401	73.7994
793.795	73.9346
797.188	74.3251
800.58	75.0083
803.971	73.5788
807.36	73.8199
810.748	73.8284
814.135	71.7428
817.518	72.2018
820.902	70.1145
824.285	70.7904
827.665	70.5941
831.045	68.4388
834.424	67.6244
837.8	66.5285
841.177	63.9492
844.55	62.2204
847.924	59.9265
851.295	57.8415
854.666	54.7992
858.034	54.319
861.403	53.2568
864.769	51.3512
868.133	50.4657
871.498	48.7634
874.86	48.8351
878.221	47.7988
881.58	48.5676
884.938	47.3939
888.297	46.6131
891.653	46.1951
895.007	45.9896
898.36	45.1933
901.712	46.1304
905.063	44.5261
908.412	43.7019
911.76	42.872
915.107	42.0581
918.452	41.0918
921.797	40.7334
925.138	39.0391
928.48	39.3936
931.82	39.4108
935.16	39.9107
938.496	39.1957
941.833	39.0732
945.168	37.1705
948.5	35.3335
951.834	34.9928
955.163	33.1931
958.494	31.8471
961.821	30.1058
965.15	30.0087
968.474	28.5143
971.8	27.9437
975.123	26.8515
978.446	25.4866
981.766	24.3658
985.084	24.3251
988.402	21.7111
991.72	21.8886
995.035	20.6721
998.349	19.4354
1001.66	17.1371
1004.97	15.4423
1008.28	16.2933
1011.59	19.6475
1014.9	22.5193
1018.21	27.1933
1021.51	30.3556
1024.81	32.3793
1028.12	33.5323
1031.42	35.6924
1034.72	38.5528
1038.02	39.5159
1041.31	41.056
1044.61	42.221
1047.91	42.533
1051.2	42.0449
1054.49	41.2553
1057.78	38.2184
1061.07	36.6115
1064.36	33.6647
1067.65	30.8012
1070.93	25.215
1074.22	20.9377
1077.5	16.7779
1080.78	14.0395
1084.06	12.3657
1087.34	12.4814
1090.62	13.554
1093.9	14.5193
1097.17	15.9844
1100.45	17.4959
1103.72	15.4622
1106.99	16.6069
1110.27	17.2518
1113.53	16.8727
1116.8	16.3965
1120.07	15.1213
1123.33	14.0621
1126.6	14.8018
1129.86	13.7296
1133.12	12.5973
1136.38	12.0188
1139.64	10.4165
1142.9	9.31605
1146.16	7.50306
1149.41	6.17474
1152.67	6.33747
1155.92	6.53525
1159.17	5.9644
1162.42	5.25901
1165.67	4.5487
1168.92	4.0396
1172.16	4.40844
1175.41	4.97911
1178.65	6.62922
1181.9	6.97111
1185.14	8.2334
1188.38	8.11409
1191.62	8.44225
1194.86	9.5997
1198.09	9.44226
1201.33	10.2396
1204.56	11.1086
1207.8	10.3613
1211.03	11.8599
1214.26	12.5175
1217.49	12.773
1220.71	12.9402
1223.94	13.9682
1227.16	14.859
1230.39	16.9579
1233.61	18.8305
1236.83	19.4568
1240.05	20.5391
1243.27	22.8962
1246.49	25.0707
1249.71	27.7492
1252.92	29.4719
1256.14	31.493
1259.35	33.3852
1262.56	34.1696
1265.77	36.7316
1268.98	38.3128
1272.19	39.0886
1275.4	40.8925
1278.6	41.3651
1281.81	42.3425
1285.01	41.7813
1288.21	44.0475
1291.41	45.6198
1294.61	45.5464
1297.81	46.6863
1301.01	45.6503
1304.2	46.5604
1307.4	45.8635
1310.59	45.2624
1313.78	44.8689
1316.97	46.387
1320.16	47.645
1323.35	47.8878
1326.54	47.5014
1329.72	47.2795
1332.91	46.5464
1336.09	44.7367
1339.27	43.834
1342.45	43.8615
1345.64	44.8459
1348.81	43.1405
1351.99	42.6799
1355.17	41.2139
1358.34	39.6404
1361.51	39.8044
1364.69	38.6939
1367.86	37.3135
1371.03	36.4148
1374.2	35.3355
1377.37	34.6092
1380.53	34.5396
1383.7	33.7615
1386.86	34.6168
1390.02	35.6717
1393.19	35.8781
1396.35	37.9849
1399.51	37.2762
1402.66	37.2164
1405.82	38.2123
1408.97	38.666
1412.13	39.8407
1415.28	40.7503
1418.43	43.4346
1421.59	45.2915
1424.73	46.8046
1427.88	47.2269
1431.03	50.0286
1434.18	52.1888
1437.32	55.176
1440.46	55.6151
1443.61	55.9967
1446.75	56.606
1449.89	57.5429
1453.03	57.8582
1456.16	57.4239
1459.3	56.9866
1462.44	56.3155
1465.57	56.2253
1468.7	54.7742
1471.83	54.0951
1474.96	51.0897
1478.09	49.0796
1481.22	47.6984
1484.35	46.7285
1487.47	43.3268
1490.6	41.0038
1493.72	39.5022
1496.84	36.5496
1499.96	35.7208
1503.08	35.3406
1506.2	34.8103
1509.32	34.5799
1512.44	32.5692
1515.55	31.5037
1518.66	29.5237
1521.78	29.6032
1524.89	29.692
1528	28.8357
1531.11	28.2532
1534.21	29.7272
1537.32	28.8099
1540.43	30.6636
1543.53	30.5004
1546.63	30.0431
1549.74	30.3052
1552.84	30.355
1555.94	31.708
1559.03	31.845
1562.13	32.0177
1565.23	31.2592
1568.32	30.5719
1571.42	31.2064
1574.51	32.0325
1577.6	33.5276
1580.69	34.1259
1583.78	35.5121
1586.87	34.541
1589.95	35.0172
1593.04	37.068
1596.12	37.8648
1599.21	39.4149
1602.29	39.6204
1605.37	38.8932
1608.45	38.8063
1611.53	39.0584
1614.6	38.4471
1617.68	38.7474
1620.75	38.4374
1623.83	40.1314
1626.9	39.8904
1629.97	42.9531
1633.04	43.6584
1636.11	44.1544
1639.18	44.4103
1642.25	44.2589
1645.31	44.9882
1648.38	45.0282
1651.44	44.3822
1654.5	43.9514
1657.56	43.2927
1660.62	40.9977
1663.68	40.3308
1666.74	40.5302
1669.8	39.0963
1672.85	36.4509
1675.91	33.0767
1678.96	29.889
1682.01	26.1826
1685.06	23.1139
1688.11	21.353
1691.16	19.418
1694.21	17.1359
1697.25	14.4316
1700.3	13.6525
1703.34	12.9992
1706.39	13.3571
1709.43	11.8549
1712.47	11.5434
1715.51	11.045
1718.54	10.3476
1721.58	9.78433
1724.62	9.05223
1727.65	7.58021
1730.68	7.582
1733.72	7.67655
1736.75	6.97389
1739.78	6.93619
1742.81	6.55887
1745.84	5.30704
1748.86	4.37184
1751.89	3.39457
1754.91	2.92834
1757.93	2.4013
1760.96	1.67614
1763.98	0.620486
1767	0.436144
1770.02	0.145042
1773.03	0.000718238
1776.05	1.03534
1779.07	1.12937
1782.08	1.07997
1785.09	1.26814
1788.11	1.75963
1791.12	2.52098
1794.13	2.7278
1797.13	2.09205
1800.14	1.61245
1803.15	1.65929
1806.15	1.63305
1809.16	1.57203
1812.16	1.93302
1815.16	1.26306
1818.16	2.01675
1821.16	2.2587
1824.16	2.03362
1827.16	1.7417
1830.16	1.86806
1833.15	1.80724
1836.14	1.69968
1839.14	2.53715
1842.13	2.25637
1845.12	2.91545
1848.11	3.20664
1851.1	3.26051
1854.08	2.72928
1857.07	3.10627
1860.05	2.07145
1863.04	1.33898
1866.02	1.24347
1869	1.17625
1871.98	1.44941
1874.96	2.31711
1877.94	2.22161
1880.92	2.58111
1882.51	2.37316
1885.5	2.16512
1888.48	1.0596
1891.47	2.05421
1894.46	2.21239
1897.44	1.99239
1900.42	2.04199
1903.41	1.86711
1906.39	3.11726
1909.37	2.9593
1912.35	3.13568
1915.32	3.16759
1918.3	4.00027
1921.27	4.18086
1924.25	4.17278
1927.22	4.56471
1930.19	3.85192
1933.17	3.69972
1936.14	5.18842
1939.11	4.76338
1942.07	4.28075
1945.04	4.82816
1948.01	4.4954
1950.97	3.862
1953.93	3.56294
1956.9	3.34996
1959.86	2.82358
1962.82	2.77422
1965.78	3.07587
1968.74	2.81758
1971.69	2.25758
1974.65	2.43714
1977.6	2.3492
1980.56	1.87849
1983.51	2.0262
1986.46	2.17194
1989.41	2.16507
1992.36	2.46413
1995.31	3.06899
1998.26	1.90998
2001.2	1.9252
2004.15	2.62916
2007.09	1.63699
2010.04	1.54617
2012.98	0.278209
2015.92	1.70492
2018.86	1.38278
2021.8	2.41445
2024.73	3.03748
2027.67	3.48481
2030.61	4.67861
2033.54	6.02416
2036.47	7.04194
2039.4	7.64879
2042.33	7.64217
2045.27	7.55092
2048.19	8.43534
2051.12	8.47757
2054.05	8.15975
2056.97	8.28223
2059.9	8.09036
2062.82	8.58817
2065.74	8.16535
2068.67	7.90165
2071.59	7.53303
2074.51	6.99181
2077.42	5.90319
2080.34	6.15108
2083.26	6.83068
2086.17	6.96153
2089.09	7.49749
2092	7.29777
2094.91	8.76793
2097.82	10.6274
2100.73	12.1049
2103.64	14.1623
2106.55	14.2721
2109.45	13.3055
2112.36	13.0638
2115.26	13.0924
2118.17	14.6471
2121.07	16.9195
2123.97	18.2122
2126.87	19.597
2129.77	20.8714
2132.67	22.1198
2135.56	23.954
2138.46	24.8298
2141.35	26.9509
2144.25	28.8613
2147.14	30.9303
2150.03	33.1257
2152.92	35.1958
2155.81	36.4995
2158.7	37.0086
2161.59	38.8
2164.47	41.4161
2167.36	43.2499
2170.24	44.0781
2173.13	44.1241
2176.01	43.8051
2178.89	43.0489
2181.77	42.6309
2184.65	41.847
2187.53	43.4718
2190.4	43.0535
2193.28	41.9329
2196.16	39.7594
2199.03	38.2276
2201.9	37.3029
2204.77	35.5468
2207.64	34.2095
2210.51	32.4478
2213.38	31.1007
2216.25	29.3597
2219.12	28.2326
2221.98	25.4166
2224.85	23.1631
2227.71	21.6377
2230.57	19.8007
2233.43	18.9715
2236.29	17.8186
2239.15	15.0381
2242.01	14.321
2244.87	13.6662
2247.72	12.2406
2250.58	11.2615
2253.43	10.3032
2256.29	10.3533
2259.14	9.96699
2261.99	8.98627
2264.84	8.29596
2267.69	9.16084
2270.53	8.9875
2273.38	8.38637
2276.23	8.44247
2279.07	7.91389
2281.91	8.21155
2284.76	7.74752
2287.6	7.02992
2290.44	6.48501
2293.28	5.32754
2296.12	5.23555
2298.96	5.41543
2301.79	6.31826
2304.63	6.56249
2307.46	7.18755
2310.3	7.01364
2313.13	7.88905
2315.96	8.70265
2318.79	9.02164
2321.62	10.0876
2324.45	10.3654
2327.27	10.545
2330.1	10.4735
2332.92	9.9567
2335.75	10.1811
2338.57	10.3636
2341.39	9.43762
2344.21	8.3802
2347.04	8.08453
2349.85	7.12575
2352.67	6.25509
2355.49	5.11481
2358.3	3.42154
2361.12	1.95392
2363.93	0.586992
2366.75	0.470325
2369.56	0.74808
2372.37	-0.397295
2375.18	-0.538526
2377.99	-0.73289
2380.8	-0.802003
2383.6	-0.239851
2386.41	0.132876
2389.21	0.831259
2392.02	1.40139
2394.82	2.44271
2397.62	3.93874
2400.42	4.60018
2403.22	5.6704
2406.02	6.51119
2408.82	7.54152
2411.62	8.29157
2414.41	7.88502
2417.21	7.80142
2420	7.43748
2422.79	5.73551
2425.59	4.77665
2428.38	4.27354
2431.17	4.85604
2433.95	4.64897
2436.74	4.4902
2439.53	4.40207
2442.31	3.75557
2445.1	5.03634
2447.88	4.32354
2450.67	4.06521
2453.45	4.74734
2456.23	5.26755
2459.01	5.84496
2461.79	6.7864
2464.57	7.79043
2467.34	7.4302
2470.12	6.87371
2472.89	7.17748
2475.67	6.87701
2478.44	5.99269
2481.21	5.53914
2483.98	4.2858
2486.75	3.55458
2489.52	2.08544
2492.29	1.51807
2495.05	2.12517
2497.82	2.00266
2500.58	1.92652
2503.35	1.57095
2506.11	0.821721
2508.87	1.21698
2511.63	1.48107
2514.39	1.4443
2517.15	1.92581
2519.91	2.57349
2522.67	2.95702
2525.42	3.1621
2528.18	3.25205
2530.93	4.31212
2533.69	4.70874
2536.44	4.36516
2539.19	5.3755
2541.94	5.56561
2544.69	5.90259
2547.44	6.15353
2550.18	6.38776
2552.93	5.82547
2555.67	5.93238
2558.42	6.23103
2561.16	7.18355
2563.9	7.30083
2566.64	7.58404
2569.38	8.43348
2572.12	8.31888
2574.86	8.4637
2577.6	8.54017
2580.33	7.87402
2583.07	7.70562
2585.8	7.0426
2588.54	5.6284
2591.27	5.12017
2594	5.18955
2596.73	4.78657
2599.46	5.25422
2602.19	4.69272
2604.92	5.09155
2607.64	3.93506
2610.37	2.89091
2613.09	3.30199
2615.82	2.67388
2618.54	2.26294
2621.26	2.56189
2623.98	3.58408
2626.7	4.32226
2629.42	4.66797
2632.14	5.49708
2634.86	6.3146
2637.57	6.84318
2640.29	6.97941
2643	6.74138
2645.71	6.48758
2648.43	5.94127
2651.14	5.76676
2653.85	5.19759
2656.56	5.84286
2659.26	5.67443
2661.97	6.14802
2664.68	6.37938
2667.38	5.53097
2670.09	5.59706
2672.79	4.75269
2675.49	3.37074
2678.19	4.24643
2680.89	5.15837
2683.59	4.81287
2686.29	5.656
2688.99	6.41978
2691.69	7.00269
2694.38	8.33035
2697.08	9.43436
2699.77	10.359
2702.46	11.525
2705.15	11.4018
2707.85	12.3209
2710.54	12.607
2713.22	12.7194
2715.91	12.5878
2718.6	13.1285
2721.29	13.0217
2723.97	12.4634
2726.66	12.5208
2729.34	12.1243
2732.02	11.6161
2734.7	11.0903
2737.38	11.3572
2740.06	10.6139
2742.74	10.2158
2745.42	9.98035
2748.09	9.11992
2750.77	8.40331
2753.45	7.55985
2756.12	6.62647
2758.79	6.63136
2761.46	5.92276
2764.14	5.46692
2766.8	4.84418
2769.47	4.30514
2772.14	3.09573
2774.81	2.46964
2777.48	1.82181
2780.14	1.41239
2782.8	0.116516
2785.47	0.172042
2788.13	0.756018
2790.79	0.74699
2793.45	1.22374
2796.11	1.55147
2798.77	2.34884
2801.43	2.20969
2804.09	2.39513
2806.74	2.7054
2809.4	2.9363
2812.05	4.61515
2814.71	5.35074
2817.36	5.15192
2820.01	5.73778
2822.66	7.68324
2825.31	9.31919
2827.96	11.6922
2830.6	13.7106
2833.25	14.3383
2835.9	16.3269
2838.54	17.687
2841.18	19.7286
2843.83	21.617
2846.47	24.0971
2849.11	27.7167
2851.75	32.2481
2854.39	34.9217
2857.03	37.5702
2859.66	41.0313
2862.3	44.5285
2864.94	47.4258
2867.57	50.1294
2870.2	53.4363
2872.84	55.5841
2875.47	58.0755
2878.1	60.8979
2880.73	63.1976
2883.36	65.9911
2885.99	68.8459
2888.61	72.1569
2891.24	74.2741
2893.86	76.8236
2896.49	79.0239
2899.11	81.308
2901.73	84.3006
2904.36	86.9332
2906.98	90.7231
2909.6	95.2871
2912.21	100.262
2914.83	105.617
2917.45	109.279
2920.07	113.796
2922.68	117.556
2925.29	120.764
2927.91	122.609
2930.52	123.641
2933.13	125.324
2935.74	126.103
2938.35	124.522
2940.96	123.77
2943.57	122.632
2946.18	119.849
2948.78	117.396
2951.39	112.772
2953.99	107.538
2956.59	101.516
2959.2	97.4824
2961.8	90.8918
2964.4	85.4605
2967	80.8141
2969.6	76.2298
2972.19	71.9161
2974.79	67.3357
2977.39	62.9515
2979.98	58.1412
2982.58	53.5949
2985.17	48.7109
2987.76	43.9004
2990.35	38.8722
2992.94	35.235
2995.53	31.4092
2998.12	27.6987
3000.71	24.1874
3003.3	20.9813
3005.88	18.2447
3008.47	15.2056
3011.05	12.4502
3013.64	8.69696
3016.22	6.85949
3018.8	5.19047
3021.38	3.60752
3023.96	2.15088
3026.54	1.19324
3029.12	1.22331
3031.69	0.649575
3034.27	0.787662
3036.84	0.715905
3039.42	1.0103
3041.99	1.04714
3044.57	1.56038
3047.14	2.31005
3049.71	2.29446
3052.28	2.02684
3054.85	2.82525
3057.41	2.77939
3059.98	2.84882
3062.55	2.63052
3065.11	1.83375
3067.68	1.37249
3070.24	1.43244
3072.8	1.28063
3075.36	0.431957
3077.93	1.19455
3080.49	1.71409
3083.04	1.05199
3085.6	0.594762
3088.16	0.877235
3090.72	0.995123
3093.27	0.556305
3095.83	0.798055
3098.38	0.97765
3100.93	2.08462
3103.49	2.84389
3106.04	4.01771
3108.59	4.30582
3111.14	5.08952
3113.69	5.2965
3116.23	5.80493
3118.78	6.62736
3121.33	7.36729
3123.87	7.83867
3126.41	7.96055
3128.96	9.31914
3131.5	10.855
3134.04	12.1804
3136.58	13.0774
3139.12	15.12
3141.66	16.5926
3144.2	17.7138
3146.74	19.5777
3149.27	21.7692