File: data/Raman/poly_smoothed/Mb_30_27_22_1x_45s_532 nm_x100_100%_600 gr_mm_01.txt
#Acq. time (s)=	45
#Accumulations=	2
#Range (cm-¹)=	200...3150
#Windows=	2
#Auto scanning=	Off
#Autofocus=	Off
#Macrospot=	Off
#AutoExposure=	Off
#Spike filter=	Multiple accum.
#Delay time (s)=	0
#Binning=	1
#Readout mode=	Signal
#DeNoise=	Off
#ICS correction=	On
#Dark correction=	Off
#Inst. Process=	Off
#Detector Gain=	Best Dynamic Range
#Detector ADC=	20 kHz
#Detector temperature (°C)=	-70.31
#Instrument=	LabRAM HR Evol
#Detector=	Synapse
#Objective=	x100
#Grating=	600 gr/mm
#ND Filter=	100%
#Laser (nm)=	532
#Hole=	100.021
#Range=	Auto
#Laser Pol.=	No
#Raman. Pol.=	No
#Laser Pol. (°)=	-0.0007625
#Raman Pol. (°)=	89.9995
#Collection=	Microscope
#StageXY=	Marzhauser
#StageZ=	Marzhauser
#X (µm)=	-6389.2
#Y (µm)=	877.9
#Z (µm)=	-65
#Full time(mm:ss)=	3:18
#Project=
#Sample=
#Site=
#Title=	Mb_30_27_22_2x_45s_532 nm_x100_100%_600 gr_mm
#Remark=
#Date=	13.07.2022 10:15
#Acquired=	13.07.2022 10:15:00
#Base:Fit=	10.08.2022 10:40:03
#Base:Sub=	10.08.2022 10:40:17
#Filter:Polynom=	16.08.2022 10:16:15
#AxisType[0]=Intens
#AxisUnit[0]=Cnt
#AxisType[1]=Spectr
#AxisUnit[1]=1/cm
200.563	8.47199
204.194	10.1908
207.821	9.626
211.449	9.39939
215.074	10.2533
218.699	11.4895
222.321	12.9019
225.941	12.7044
229.562	12.6792
233.18	12.1168
236.796	12.1746
240.411	12.0076
244.026	12.5545
247.638	13.6422
251.248	13.3474
254.857	12.9003
258.465	14.3384
262.071	13.7947
265.678	13.6858
269.282	12.4555
272.884	12.159
276.484	12.1095
280.084	10.8632
283.682	11.8096
287.276	11.3731
290.871	10.7707
294.465	11.1082
298.057	13.1882
301.648	14.4362
305.237	13.5508
308.823	14.4758
312.41	12.6858
315.995	10.9523
319.579	12.4069
323.16	12.3032
326.741	11.3465
330.321	11.2346
333.897	10.7432
337.474	9.83007
341.048	9.10922
344.622	7.35621
348.192	6.22684
351.764	5.26787
355.332	5.05799
358.901	3.68401
362.466	3.1577
366.03	2.2672
369.594	3.30131
373.155	4.21985
376.715	4.91571
380.273	4.64443
383.832	5.93469
387.388	7.39578
390.942	6.35678
394.495	5.8487
398.047	6.01891
401.597	6.19247
405.145	7.08945
408.693	7.91232
412.239	6.65585
415.783	6.32232
419.327	6.18301
422.869	6.29091
426.409	5.45352
429.948	5.20538
433.486	4.18335
437.022	3.66096
440.558	5.23257
444.089	6.91418
447.622	6.28736
451.153	6.79071
454.682	7.0411
458.208	6.75507
461.735	8.41789
465.259	9.44851
468.783	9.00245
472.306	11.4278
475.825	13.8865
479.346	13.9311
482.862	14.7122
486.38	17.067
489.894	18.463
493.407	19.3553
496.92	19.8383
500.43	22.2107
503.939	23.6118
507.448	23.032
510.954	24.1357
514.459	25.2642
517.962	25.7871
521.466	26.1707
524.966	25.6723
528.466	24.4809
531.964	23.2933
535.46	21.3321
538.955	18.8446
542.449	17.5292
545.942	16.1298
549.433	16.3507
552.923	14.5392
556.412	10.7954
559.899	9.40334
563.385	10.1569
566.867	8.06626
570.35	8.19707
573.832	7.05582
577.313	5.88956
580.79	6.03982
584.268	6.35884
587.745	5.3755
591.218	3.46873
594.692	3.04531
598.164	3.68409
601.634	3.49912
605.104	3.90119
608.57	5.5872
612.037	5.24208
615.501	4.9533
618.966	5.92281
622.427	6.02669
625.887	7.34414
629.348	7.72332
632.806	9.45579
636.262	10.1121
639.716	8.60126
643.172	9.31313
646.624	12.4759
650.075	15.3232
653.524	16.1515
656.972	18.0301
660.419	18.6344
663.865	20.3072
667.309	20.788
670.752	22.8568
674.194	24.472
677.634	25.9836
681.073	27.5367
684.511	29.5577
687.947	30.6955
691.382	32.1146
694.816	31.0032
698.247	30.9291
701.678	30.8228
705.108	31.9223
708.534	33.4662
711.962	34.3709
715.388	36.2219
718.81	37.3669
722.234	37.8635
725.654	38.3902
729.075	42.2031
732.492	44.5166
735.91	46.8329
739.325	48.6175
742.741	50.9287
746.153	54.1619
749.564	57.484
752.976	61.1283
756.385	64.597
759.792	66.6914
763.2	68.7242
766.604	69.7846
770.008	71.988
773.41	72.4131
776.811	73.073
780.21	74.0545
783.608	76.7604
787.005	78.1172
790.401	79.7636
793.795	81.8712
797.188	82.845
800.58	84.5878
803.971	84.274
807.36	85.0671
810.748	83.6516
814.135	82.4041
817.518	80.9727
820.902	79.9027
824.285	79.4746
827.665	77.5695
831.045	76.9671
834.424	74.7869
837.8	71.2123
841.177	67.8134
844.55	65.1015
847.924	63.7452
851.295	60.6761
854.666	58.7478
858.034	54.0306
861.403	53.752
864.769	52.4557
868.133	52.9478
871.498	52.7276
874.86	51.5303
878.221	51.4078
881.58	52.9083
884.938	51.5516
888.297	51.66
891.653	49.5146
895.007	49.3608
898.36	49.5132
901.712	49.4487
905.063	51.1379
908.412	49.5297
911.76	49.1714
915.107	49.2448
918.452	47.4929
921.797	45.9992
925.138	46.3077
928.48	45.0723
931.82	43.6006
935.16	42.7185
938.496	41.4861
941.833	39.6223
945.168	40.5316
948.5	39.2365
951.834	39.666
955.163	39.2522
958.494	39.121
961.821	37.4674
965.15	37.0484
968.474	35.6416
971.8	35.5403
975.123	36.3335
978.446	36.4063
981.766	35.2615
985.084	33.3585
988.402	33.6546
991.72	31.95
995.035	30.8751
998.349	29.0367
1001.66	23.8616
1004.97	20.6413
1008.28	22.1542
1011.59	26.388
1014.9	31.7646
1018.21	38.5252
1021.51	43.3964
1024.81	47.5757
1028.12	54.7047
1031.42	58.6814
1034.72	62.6621
1038.02	63.2236
1041.31	63.618
1044.61	65.1169
1047.91	66.3962
1051.2	64.8066
1054.49	63.9358
1057.78	61.3153
1061.07	55.6149
1064.36	50.4301
1067.65	43.7665
1070.93	36.4535
1074.22	29.2645
1077.5	21.7275
1080.78	15.842
1084.06	12.1898
1087.34	14.5838
1090.62	17.1987
1093.9	18.63
1097.17	20.0879
1100.45	19.2599
1103.72	20.5266
1106.99	20.3973
1110.27	20.2265
1113.53	20.3207
1116.8	19.7322
1120.07	19.0535
1123.33	18.8985
1126.6	16.788
1129.86	16.5243
1133.12	14.6366
1136.38	12.3529
1139.64	10.6981
1142.9	9.11803
1146.16	8.29432
1149.41	8.15727
1152.67	7.92327
1155.92	6.86835
1159.17	5.91731
1162.42	6.83045
1165.67	7.66014
1168.92	9.24966
1172.16	10.5401
1175.41	10.7394
1178.65	10.7314
1181.9	11.3689
1185.14	10.7387
1188.38	10.6549
1191.62	10.593
1194.86	9.80421
1198.09	10.8174
1201.33	10.7213
1204.56	10.6978
1207.8	11.3273
1211.03	12.521
1214.26	14.8954
1217.49	16.8984
1220.71	19.7209
1223.94	20.8496
1227.16	23.2495
1230.39	24.6399
1233.61	26.4578
1236.83	28.9768
1240.05	33.7768
1243.27	36.8927
1246.49	40.6359
1249.71	40.7378
1252.92	41.8834
1256.14	42.0831
1259.35	43.201
1262.56	44.0774
1265.77	45.7028
1268.98	46.9218
1272.19	47.9878
1275.4	51.0237
1278.6	49.8743
1281.81	51.5689
1285.01	51.5102
1288.21	51.0788
1291.41	52.3098
1294.61	52.4272
1297.81	53.5765
1301.01	54.3192
1304.2	53.9428
1307.4	55.0766
1310.59	56.9069
1313.78	58.0463
1316.97	58.3927
1320.16	59.8071
1323.35	58.9766
1326.54	58.7524
1329.72	58.4839
1332.91	59.2596
1336.09	58.8839
1339.27	58.4466
1342.45	56.8406
1345.64	56.9015
1348.81	55.133
1351.99	53.57
1355.17	51.2369
1358.34	49.0238
1361.51	48.3745
1364.69	46.9363
1367.86	46.6351
1371.03	44.9406
1374.2	43.5247
1377.37	44.044
1380.53	42.383
1383.7	41.1238
1386.86	40.5417
1390.02	41.6206
1393.19	42.4553
1396.35	42.8365
1399.51	43.4164
1402.66	44.7763
1405.82	45.391
1408.97	47.2853
1412.13	48.7987
1415.28	50.3877
1418.43	53.4172
1421.59	57.1565
1424.73	59.911
1427.88	62.4449
1431.03	65.2023
1434.18	69.3197
1437.32	73.3871
1440.46	75.4985
1443.61	76.1745
1446.75	76.1482
1449.89	75.4151
1453.03	75.9091
1456.16	75.3273
1459.3	73.2754
1462.44	71.5933
1465.57	70.3541
1468.7	68.4165
1471.83	65.9188
1474.96	62.9734
1478.09	61.7822
1481.22	58.3053
1484.35	54.1229
1487.47	51.5044
1490.6	47.2401
1493.72	44.0642
1496.84	41.9531
1499.96	38.6506
1503.08	35.4764
1506.2	33.7557
1509.32	32.267
1512.44	29.7678
1515.55	27.0341
1518.66	24.5273
1521.78	22.2974
1524.89	20.2997
1528	20.1132
1531.11	19.3116
1534.21	19.0529
1537.32	19.3419
1540.43	19.9869
1543.53	20.1096
1546.63	22.8418
1549.74	23.7535
1552.84	24.2547
1555.94	24.5138
1559.03	25.4373
1562.13	27.7049
1565.23	29.7116
1568.32	31.3811
1571.42	33.3555
1574.51	35.507
1577.6	38.3049
1580.69	40.1017
1583.78	43.6229
1586.87	44.3594
1589.95	44.3158
1593.04	45.7061
1596.12	45.5554
1599.21	45.2635
1602.29	45.8833
1605.37	45.8639
1608.45	45.437
1611.53	45.7227
1614.6	46.4413
1617.68	47.0697
1620.75	47.7855
1623.83	49.0507
1626.9	47.4137
1629.97	49.2721
1633.04	50.2602
1636.11	53.6127
1639.18	55.7118
1642.25	56.7913
1645.31	58.3077
1648.38	59.6165
1651.44	60.5252
1654.5	60.5355
1657.56	61.1068
1660.62	60.7459
1663.68	57.8504
1666.74	55.2238
1669.8	52.3178
1672.85	48.7682
1675.91	45.1611
1678.96	43.1412
1682.01	39.2889
1685.06	37.0562
1688.11	34.6108
1691.16	32.2454
1694.21	28.1256
1697.25	24.3228
1700.3	19.7986
1703.34	18.0046
1706.39	15.9487
1709.43	14.3215
1712.47	12.7028
1715.51	10.6938
1718.54	8.08352
1721.58	7.27748
1724.62	5.94475
1727.65	4.54203
1730.68	3.58026
1733.72	2.58261
1736.75	2.41215
1739.78	1.07821
1742.81	0.366273
1745.84	0.489214
1748.86	0.083626
1751.89	0.59713
1754.91	-0.0634047
1757.93	0.405897
1760.96	1.58954
1763.98	1.7155
1767	1.85449
1770.02	1.53905
1773.03	1.40989
1776.05	2.83743
1779.07	3.45007
1782.08	4.01311
1785.09	4.30843
1788.11	4.55957
1791.12	4.65278
1794.13	4.58349
1797.13	4.08213
1800.14	3.43214
1803.15	3.25148
1806.15	3.39574
1809.16	3.33155
1812.16	2.53674
1815.16	2.05339
1818.16	1.95222
1821.16	1.45527
1824.16	0.765892
1827.16	0.826463
1830.16	1.38367
1833.15	1.55529
1836.14	1.68354
1839.14	1.59541
1842.13	0.7269
1845.12	1.15771
1848.11	1.25398
1851.1	2.02386
1854.08	2.32668
1857.07	1.61897
1860.05	1.70721
1863.04	1.26759
1866.02	1.68335
1869	2.62035
1871.98	3.02027
1874.96	3.96129
1877.94	3.27015
1880.92	4.45163
1882.51	5.27284
1885.5	6.32018
1888.48	6.28974
1891.47	6.46748
1894.46	6.19095
1897.44	6.64691
1900.42	5.86421
1903.41	6.0925
1906.39	6.03943
1909.37	5.66633
1912.35	5.64772
1915.32	7.10989
1918.3	6.61987
1921.27	5.85861
1924.25	6.14537
1927.22	5.04822
1930.19	5.00637
1933.17	5.60056
1936.14	4.69868
1939.11	4.99505
1942.07	4.7152
1945.04	4.43478
1948.01	4.53383
1950.97	4.53945
1953.93	5.85906
1956.9	4.68327
1959.86	4.33521
1962.82	3.11707
1965.78	2.16511
1968.74	2.85857
1971.69	1.8792
1974.65	3.06303
1977.6	3.53341
1980.56	3.76922
1983.51	3.19808
1986.46	4.09319
1989.41	3.69811
1992.36	2.92316
1995.31	3.81063
1998.26	4.30167
2001.2	4.74218
2004.15	5.56907
2007.09	6.16138
2010.04	5.77357
2012.98	5.44191
2015.92	5.90517
2018.86	6.62709
2021.8	6.21887
2024.73	5.68741
2027.67	6.05795
2030.61	6.46162
2033.54	6.6172
2036.47	6.66527
2039.4	7.63989
2042.33	8.14954
2045.27	8.16563
2048.19	8.12135
2051.12	6.64392
2054.05	6.92937
2056.97	6.57627
2059.9	7.70119
2062.82	8.60645
2065.74	9.4886
2068.67	11.0861
2071.59	11.1205
2074.51	12.2049
2077.42	12.2681
2080.34	12.7383
2083.26	13.302
2086.17	14.0701
2089.09	15.9443
2092	16.1695
2094.91	16.7762
2097.82	18.3281
2100.73	19.5924
2103.64	20.7499
2106.55	22.2683
2109.45	22.9935
2112.36	23.5805
2115.26	23.7977
2118.17	24.7735
2121.07	25.6681
2123.97	27.3701
2126.87	29.0712
2129.77	31.7936
2132.67	34.5461
2135.56	37.6103
2138.46	40.602
2141.35	43.3732
2144.25	45.8423
2147.14	47.9828
2150.03	50.6619
2152.92	53.0074
2155.81	55.3582
2158.7	57.8957
2161.59	59.9395
2164.47	60.7057
2167.36	62.178
2170.24	62.5359
2173.13	62.7888
2176.01	63.0899
2178.89	61.3878
2181.77	60.4195
2184.65	59.2228
2187.53	58.7132
2190.4	57.2638
2193.28	55.5324
2196.16	54.0478
2199.03	52.5135
2201.9	50.5583
2204.77	48.9151
2207.64	46.3181
2210.51	43.4552
2213.38	41.6368
2216.25	38.112
2219.12	35.8222
2221.98	35.6063
2224.85	33.5842
2227.71	32.9004
2230.57	31.486
2233.43	28.8535
2236.29	27.0765
2239.15	25.32
2242.01	24.0088
2244.87	23.2978
2247.72	21.9784
2250.58	21.5181
2253.43	21.1433
2256.29	21.1136
2259.14	19.6788
2261.99	19.2817
2264.84	19.1758
2267.69	18.3893
2270.53	17.1889
2273.38	16.5016
2276.23	14.9665
2279.07	14.4106
2281.91	14.1857
2284.76	13.8057
2287.6	14.1801
2290.44	13.6258
2293.28	12.6408
2296.12	11.6049
2298.96	11.9291
2301.79	10.625
2304.63	9.80066
2307.46	9.9377
2310.3	9.96259
2313.13	9.66281
2315.96	9.07276
2318.79	9.27182
2321.62	9.73286
2324.45	9.95535
2327.27	9.316
2330.1	8.12343
2332.92	7.46016
2335.75	6.80595
2338.57	5.84341
2341.39	5.33508
2344.21	4.96338
2347.04	4.97517
2349.85	4.46824
2352.67	3.2178
2355.49	3.3317
2358.3	1.90467
2361.12	0.720579
2363.93	0.839225
2366.75	1.43076
2369.56	1.37311
2372.37	1.15086
2375.18	1.88316
2377.99	2.03592
2380.8	2.50626
2383.6	2.45073
2386.41	3.90461
2389.21	4.38344
2392.02	4.41896
2394.82	4.2786
2397.62	3.74165
2400.42	3.85334
2403.22	3.44376
2406.02	3.40145
2408.82	3.38048
2411.62	3.56836
2414.41	4.50897
2417.21	5.43982
2420	4.43991
2422.79	5.04675
2425.59	5.04643
2428.38	3.85873
2431.17	4.49729
2433.95	4.46342
2436.74	4.99364
2439.53	5.8568
2442.31	5.95575
2445.1	6.50704
2447.88	6.58299
2450.67	6.60059
2453.45	7.32436
2456.23	7.9435
2459.01	7.53766
2461.79	7.53543
2464.57	6.68927
2467.34	6.48667
2470.12	5.86857
2472.89	5.81494
2475.67	5.81675
2478.44	6.37589
2481.21	6.26063
2483.98	6.40728
2486.75	6.08471
2489.52	6.23673
2492.29	5.76422
2495.05	5.86554
2497.82	6.54399
2500.58	7.21536
2503.35	7.1785
2506.11	6.69171
2508.87	6.35047
2511.63	5.45718
2514.39	6.19929
2517.15	7.39694
2519.91	6.68822
2522.67	7.2787
2525.42	6.18892
2528.18	6.08688
2530.93	6.46145
2533.69	5.19799
2536.44	5.38675
2539.19	5.39907
2541.94	5.22949
2544.69	4.45501
2547.44	4.55883
2550.18	3.63522
2552.93	4.52964
2555.67	5.16469
2558.42	5.09251
2561.16	5.75655
2563.9	5.50995
2566.64	5.48391
2569.38	5.43871
2572.12	4.23248
2574.86	3.99824
2577.6	5.02071
2580.33	5.02481
2583.07	6.14513
2585.8	4.7494
2588.54	4.38291
2591.27	3.8122
2594	2.88653
2596.73	3.10034
2599.46	3.11658
2602.19	3.61239
2604.92	4.98452
2607.64	5.41633
2610.37	6.18713
2613.09	6.88723
2615.82	7.33962
2618.54	8.7755
2621.26	9.4751
2623.98	10.5211
2626.7	10.8911
2629.42	11.5602
2632.14	10.9312
2634.86	10.5905
2637.57	10.0187
2640.29	8.9641
2643	8.922
2645.71	7.92281
2648.43	6.76668
2651.14	6.32973
2653.85	5.38365
2656.56	4.38201
2659.26	3.24613
2661.97	2.24427
2664.68	1.84107
2667.38	1.89887
2670.09	1.76074
2672.79	1.37023
2675.49	1.769
2678.19	2.53727
2680.89	2.43127
2683.59	3.04992
2686.29	3.85342
2688.99	4.25479
2691.69	5.05898
2694.38	5.07143
2697.08	4.87343
2699.77	5.22764
2702.46	5.45639
2705.15	6.2712
2707.85	6.74215
2710.54	7.92066
2713.22	8.9695
2715.91	10.334
2718.6	10.6273
2721.29	10.3745
2723.97	9.83941
2726.66	9.15047
2729.34	8.48722
2732.02	8.91272
2734.7	8.83356
2737.38	8.42159
2740.06	8.61736
2742.74	8.36257
2745.42	8.37406
2748.09	6.89848
2750.77	5.77237
2753.45	5.49943
2756.12	4.8148
2758.79	4.65708
2761.46	3.74666
2764.14	3.04059
2766.8	2.90215
2769.47	2.66823
2772.14	2.68147
2774.81	2.76875
2777.48	1.94087
2780.14	1.34328
2782.8	0.899704
2785.47	0.167659
2788.13	-0.331667
2790.79	-0.107226
2793.45	1.0614
2796.11	1.06646
2798.77	0.845365
2801.43	-0.19805
2804.09	0.0714266
2806.74	0.374108
2809.4	0.0980756
2812.05	-0.668146
2814.71	-0.70626
2817.36	0.895331
2820.01	2.5387
2822.66	4.08165
2825.31	5.42754
2827.96	7.31295
2830.6	9.43554
2833.25	11.7403
2835.9	14.7332
2838.54	17.5562
2841.18	21.8791
2843.83	26.1632
2846.47	31.6816
2849.11	36.9337
2851.75	42.4892
2854.39	48.743
2857.03	55.233
2859.66	61.11
2862.3	65.4121
2864.94	70.3713
2867.57	75.8195
2870.2	80.0423
2872.84	85.0852
2875.47	88.2728
2878.1	91.4357
2880.73	95.0125
2883.36	98.8229
2885.99	102.351
2888.61	106.506
2891.24	109.898
2893.86	113.463
2896.49	117.584
2899.11	122.469
2901.73	128.372
2904.36	134.596
2906.98	141.894
2909.6	149.764
2912.21	158.39
2914.83	167.022
2917.45	175.544
2920.07	183.363
2922.68	190.724
2925.29	195.987
2927.91	201.388
2930.52	204.883
2933.13	206.857
2935.74	206.778
2938.35	205.259
2940.96	202.514
2943.57	198.377
2946.18	193.896
2948.78	189.723
2951.39	182.316
2953.99	175.577
2956.59	166.914
2959.2	158.499
2961.8	150.957
2964.4	143.528
2967	135.433
2969.6	128.074
2972.19	121.773
2974.79	114.478
2977.39	107.65
2979.98	100.308
2982.58	92.5723
2985.17	86.157
2987.76	78.951
2990.35	71.9594
2992.94	64.5721
2995.53	57.9357
2998.12	51.3335
3000.71	45.6395
3003.3	39.482
3005.88	33.875
3008.47	28.5672
3011.05	23.3198
3013.64	19.3317
3016.22	16.2907
3018.8	12.7261
3021.38	10.9896
3023.96	8.67949
3026.54	7.00331
3029.12	5.74408
3031.69	4.64504
3034.27	5.28216
3036.84	5.50423
3039.42	5.68658
3041.99	6.4346
3044.57	7.31638
3047.14	7.57957
3049.71	7.954
3052.28	7.64262
3054.85	8.5339
3057.41	9.50606
3059.98	9.22556
3062.55	9.13424
3065.11	8.15614
3067.68	6.65102
3070.24	5.23537
3072.8	4.38911
3075.36	3.29577
3077.93	4.10911
3080.49	3.30443
3083.04	2.05835
3085.6	1.26076
3088.16	0.625654
3090.72	0.0661085
3093.27	0.787668
3095.83	1.16979
3098.38	2.21521
3100.93	2.88843
3103.49	3.42174
3106.04	4.81432
3108.59	5.17316
3111.14	5.50229
3113.69	7.37433
3116.23	9.05632
3118.78	10.8839
3121.33	11.7756
3123.87	12.8224
3126.41	13.9538
3128.96	15.089
3131.5	16.9519
3134.04	19.0334
3136.58	21.9619
3139.12	24.1262
3141.66	25.4218
3144.2	27.0928
3146.74	29.3446
3149.27	31.2867