File: data/Raman/poly_smoothed/Mb_30_27_49_1x_45s_532 nm_x100_100%_600 gr_mm_01.txt
#Acq. time (s)=	45
#Accumulations=	2
#Range (cm-¹)=	200...3150
#Windows=	2
#Auto scanning=	Off
#Autofocus=	Off
#Macrospot=	Off
#AutoExposure=	Off
#Spike filter=	Multiple accum.
#Delay time (s)=	0
#Binning=	1
#Readout mode=	Signal
#DeNoise=	Off
#ICS correction=	On
#Dark correction=	Off
#Inst. Process=	Off
#Detector Gain=	Best Dynamic Range
#Detector ADC=	20 kHz
#Detector temperature (°C)=	-69.85
#Instrument=	LabRAM HR Evol
#Detector=	Synapse
#Objective=	x100
#Grating=	600 gr/mm
#ND Filter=	100%
#Laser (nm)=	532
#Hole=	100.021
#Range=	Auto
#Laser Pol.=	No
#Raman. Pol.=	No
#Laser Pol. (°)=	-0.0007625
#Raman Pol. (°)=	89.9995
#Collection=	Microscope
#StageXY=	Marzhauser
#StageZ=	Marzhauser
#X (µm)=	-6372
#Y (µm)=	716.8
#Z (µm)=	-64.85
#Full time(mm:ss)=	3:18
#Project=
#Sample=
#Site=
#Title=	Mb_30_27_49_2x_45s_532 nm_x100_100%_600 gr_mm
#Remark=
#Date=	13.07.2022 12:27
#Acquired=	13.07.2022 12:27:49
#Base:Fit=	10.08.2022 10:40:03
#Base:Sub=	10.08.2022 10:40:17
#Filter:Polynom=	16.08.2022 10:16:15
#AxisType[0]=Intens
#AxisUnit[0]=Cnt
#AxisType[1]=Spectr
#AxisUnit[1]=1/cm
200.563	34.1363
204.194	36.1428
207.821	36.5751
211.449	36.403
215.074	36.4508
218.699	33.5715
222.321	30.5015
225.941	28.5549
229.562	23.5975
233.18	20.0776
236.796	18.3014
240.411	16.1927
244.026	14.8576
247.638	14.1661
251.248	12.5411
254.857	10.0159
258.465	7.93593
262.071	8.84863
265.678	7.83426
269.282	6.25393
272.884	5.63662
276.484	4.5495
280.084	4.26802
283.682	7.25318
287.276	7.3043
290.871	8.29061
294.465	9.60021
298.057	11.6966
301.648	14.3163
305.237	14.3821
308.823	12.8993
312.41	12.7421
315.995	12.8896
319.579	12.5893
323.16	12.6966
326.741	11.9613
330.321	10.8595
333.897	11.7603
337.474	10.1285
341.048	8.70693
344.622	7.97805
348.192	7.79632
351.764	6.82326
355.332	5.10016
358.901	4.6971
362.466	5.38482
366.03	5.95744
369.594	6.45357
373.155	7.79447
376.715	8.27851
380.273	10.6662
383.832	13.2126
387.388	14.7594
390.942	15.0995
394.495	15.0424
398.047	15.1799
401.597	15.0049
405.145	15.2882
408.693	14.9444
412.239	13.5126
415.783	12.2285
419.327	12.6278
422.869	11.0964
426.409	9.13505
429.948	10.4163
433.486	8.76965
437.022	9.62352
440.558	8.23986
444.089	9.98759
447.622	10.8835
451.153	10.6015
454.682	11.4909
458.208	11.0876
461.735	11.3658
465.259	13.5763
468.783	14.3247
472.306	15.9257
475.825	17.1645
479.346	18.1754
482.862	19.4155
486.38	21.2589
489.894	22.3164
493.407	24.257
496.92	24.7494
500.43	24.867
503.939	24.462
507.448	24.8952
510.954	24.6059
514.459	24.3727
517.962	23.9214
521.466	22.1412
524.966	21.9677
528.466	20.6979
531.964	21.7569
535.46	19.0597
538.955	17.7232
542.449	14.8649
545.942	14.4264
549.433	12.7932
552.923	11.082
556.412	9.88567
559.899	7.56294
563.385	6.32698
566.867	4.77149
570.35	5.68066
573.832	6.48192
577.313	5.86449
580.79	5.66286
584.268	5.86616
587.745	4.27171
591.218	3.07171
594.692	2.37225
598.164	1.30511
601.634	1.81066
605.104	4.99959
608.57	7.37701
612.037	10.0353
615.501	12.8245
618.966	13.1759
622.427	13.6314
625.887	16.5408
629.348	18.675
632.806	20.987
636.262	21.2453
639.716	21.8764
643.172	22.3331
646.624	21.8459
650.075	23.0509
653.524	25.4636
656.972	25.5649
660.419	26.0633
663.865	24.9964
667.309	25.9663
670.752	25.5571
674.194	24.662
677.634	25.6841
681.073	26.2379
684.511	28.3177
687.947	29.8382
691.382	31.1657
694.816	32.3116
698.247	31.9051
701.678	32.7024
705.108	33.3836
708.534	35.4489
711.962	35.6126
715.388	35.7957
718.81	35.0712
722.234	35.2663
725.654	37.6685
729.075	37.9914
732.492	38.1777
735.91	37.6913
739.325	39.2767
742.741	41.0562
746.153	42.9421
749.564	44.9652
752.976	47.5386
756.385	51.2999
759.792	53.6597
763.2	56.2773
766.604	58.3685
770.008	60.8205
773.41	63.8723
776.811	65.683
780.21	67.4662
783.608	70.0998
787.005	73.8096
790.401	75.7381
793.795	77.4524
797.188	77.7758
800.58	79.7754
803.971	82.5848
807.36	83.8066
810.748	84.5216
814.135	83.2166
817.518	81.6395
820.902	83.2754
824.285	82.8484
827.665	82.1478
831.045	81.2558
834.424	80.9734
837.8	79.8271
841.177	77.95
844.55	74.0462
847.924	72.0849
851.295	69.6834
854.666	67.0121
858.034	64.9169
861.403	63.8675
864.769	63.0792
868.133	61.0384
871.498	58.835
874.86	56.3374
878.221	54.3462
881.58	55.4476
884.938	56.9181
888.297	56.1975
891.653	54.306
895.007	54.2727
898.36	54.7075
901.712	55.2807
905.063	54.0732
908.412	54.4957
911.76	53.732
915.107	55.1129
918.452	54.3502
921.797	53.5136
925.138	53.1534
928.48	53.1815
931.82	52.1265
935.16	51.5436
938.496	50.7549
941.833	49.4036
945.168	48.0513
948.5	45.0289
951.834	43.2299
955.163	42.6305
958.494	41.1985
961.821	39.776
965.15	38.1736
968.474	34.9039
971.8	34.9307
975.123	34.427
978.446	35.94
981.766	34.7048
985.084	34.6886
988.402	33.5222
991.72	33.6706
995.035	34.5418
998.349	34.9647
1001.66	34.6969
1004.97	35.5983
1008.28	37.417
1011.59	40.8309
1014.9	48.8915
1018.21	56.2754
1021.51	64.1023
1024.81	68.5478
1028.12	75.4225
1031.42	79.2102
1034.72	82.6064
1038.02	82.3688
1041.31	81.0714
1044.61	79.8233
1047.91	77.8382
1051.2	75.1426
1054.49	71.0737
1057.78	64.3507
1061.07	56.9323
1064.36	50.1509
1067.65	42.1384
1070.93	35.1305
1074.22	28.3993
1077.5	21.1597
1080.78	15.3357
1084.06	10.8535
1087.34	10.8395
1090.62	12.9088
1093.9	16.3057
1097.17	20.7493
1100.45	21.2346
1103.72	22.8732
1106.99	22.5267
1110.27	23.3743
1113.53	22.0523
1116.8	21.2708
1120.07	18.7934
1123.33	17.5384
1126.6	16.496
1129.86	16.3523
1133.12	13.6867
1136.38	12.7935
1139.64	11.2059
1142.9	10.811
1146.16	10.0289
1149.41	8.02038
1152.67	7.60833
1155.92	6.61846
1159.17	5.63717
1162.42	4.21922
1165.67	4.12376
1168.92	2.74394
1172.16	1.8768
1175.41	1.82895
1178.65	2.13236
1181.9	2.61216
1185.14	3.57769
1188.38	2.51382
1191.62	2.83528
1194.86	3.95219
1198.09	4.99641
1201.33	7.26087
1204.56	10.769
1207.8	12.5518
1211.03	14.7781
1214.26	17.7033
1217.49	20.5659
1220.71	23.7258
1223.94	26.7342
1227.16	28.243
1230.39	32.2899
1233.61	34.967
1236.83	37.0656
1240.05	40.765
1243.27	42.7354
1246.49	45.1546
1249.71	45.8689
1252.92	47.8955
1256.14	52.0331
1259.35	55.1174
1262.56	57.2987
1265.77	58.1423
1268.98	59.6841
1272.19	60.6606
1275.4	63.161
1278.6	65.2478
1281.81	68.4893
1285.01	69.9819
1288.21	70.9081
1291.41	71.2582
1294.61	72.0346
1297.81	72.9275
1301.01	73.4372
1304.2	74.9957
1307.4	75.833
1310.59	76.8987
1313.78	77.6969
1316.97	77.3091
1320.16	76.803
1323.35	74.9504
1326.54	73.8087
1329.72	73.1113
1332.91	72.6035
1336.09	72.0005
1339.27	68.2149
1342.45	64.985
1345.64	62.1425
1348.81	61.2644
1351.99	59.0375
1355.17	58.0069
1358.34	55.1051
1361.51	53.2508
1364.69	50.56
1367.86	47.6373
1371.03	44.8877
1374.2	44.1276
1377.37	43.6315
1380.53	40.9249
1383.7	41.4399
1386.86	41.1045
1390.02	40.9113
1393.19	41.1068
1396.35	41.196
1399.51	42.2833
1402.66	42.4565
1405.82	43.4805
1408.97	44.1822
1412.13	45.5455
1415.28	47.8018
1418.43	50.3492
1421.59	55.4534
1424.73	59.4061
1427.88	64.5487
1431.03	69.5448
1434.18	72.1139
1437.32	75.7309
1440.46	78.5109
1443.61	79.7234
1446.75	79.4671
1449.89	79.1686
1453.03	77.5817
1456.16	75.1827
1459.3	74.1588
1462.44	72.7342
1465.57	70.3942
1468.7	68.0446
1471.83	63.3772
1474.96	59.0982
1478.09	54.9553
1481.22	50.0211
1484.35	46.5449
1487.47	44.682
1490.6	44.1627
1493.72	42.1064
1496.84	40.0092
1499.96	38.6382
1503.08	35.7576
1506.2	34.549
1509.32	32.0717
1512.44	29.6909
1515.55	26.4183
1518.66	24.6777
1521.78	21.6988
1524.89	19.1355
1528	18.9888
1531.11	18.4208
1534.21	19.4283
1537.32	22.6215
1540.43	23.7727
1543.53	25.4259
1546.63	27.4755
1549.74	28.6069
1552.84	31.5863
1555.94	32.8191
1559.03	34.9836
1562.13	37.2305
1565.23	39.6548
1568.32	42.1598
1571.42	43.7169
1574.51	46.271
1577.6	48.7762
1580.69	50.1201
1583.78	51.9262
1586.87	53.6398
1589.95	53.5562
1593.04	57.2667
1596.12	59.0817
1599.21	60.4866
1602.29	62.4603
1605.37	64.6533
1608.45	65.0412
1611.53	66.0811
1614.6	66.5237
1617.68	67.7166
1620.75	68.7928
1623.83	70.2977
1626.9	72.5504
1629.97	74.6272
1633.04	77.0994
1636.11	80.2866
1639.18	83.1693
1642.25	87.5975
1645.31	89.0008
1648.38	91.4257
1651.44	93.4742
1654.5	94.9716
1657.56	94.8105
1660.62	94.2956
1663.68	93.44
1666.74	92.0039
1669.8	89.1339
1672.85	84.5809
1675.91	79.4303
1678.96	73.394
1682.01	66.4177
1685.06	60.3099
1688.11	55.1148
1691.16	48.8008
1694.21	44.1157
1697.25	40.0007
1700.3	35.9551
1703.34	31.9493
1706.39	28.5136
1709.43	24.946
1712.47	21.9795
1715.51	19.2817
1718.54	15.9793
1721.58	14.5948
1724.62	12.8997
1727.65	10.745
1730.68	8.80105
1733.72	6.74948
1736.75	6.08515
1739.78	5.66819
1742.81	5.7605
1745.84	4.84222
1748.86	4.48864
1751.89	4.06348
1754.91	3.33373
1757.93	3.99039
1760.96	3.27124
1763.98	3.51486
1767	3.57551
1770.02	4.31332
1773.03	4.49637
1776.05	4.37854
1779.07	4.89477
1782.08	3.85
1785.09	3.15676
1788.11	3.4663
1791.12	2.14845
1794.13	2.0173
1797.13	1.76522
1800.14	1.13917
1803.15	1.26507
1806.15	2.53626
1809.16	4.01272
1812.16	5.05209
1815.16	5.25624
1818.16	6.83883
1821.16	6.82771
1824.16	6.50153
1827.16	7.22392
1830.16	7.75172
1833.15	7.67088
1836.14	7.13954
1839.14	7.32124
1842.13	8.47711
1845.12	8.51425
1848.11	8.14352
1851.1	8.43031
1854.08	7.42353
1857.07	6.7246
1860.05	6.10241
1863.04	4.1706
1866.02	3.59816
1869	4.04849
1871.98	2.94238
1874.96	2.64785
1877.94	3.8836
1880.92	5.29588
1882.51	4.38407
1885.5	4.4492
1888.48	4.53705
1891.47	5.89074
1894.46	7.14542
1897.44	7.41223
1900.42	8.18838
1903.41	7.63458
1906.39	7.76997
1909.37	9.76334
1912.35	9.67272
1915.32	9.42955
1918.3	9.6224
1921.27	9.44419
1924.25	8.51941
1927.22	8.17029
1930.19	7.93938
1933.17	6.60822
1936.14	6.64014
1939.11	6.02895
1942.07	5.3001
1945.04	3.48395
1948.01	3.69269
1950.97	3.67424
1953.93	3.54235
1956.9	1.36502
1959.86	1.09041
1962.82	0.601964
1965.78	0.81302
1968.74	0.110594
1971.69	-0.257915
1974.65	0.650965
1977.6	0.444371
1980.56	1.00853
1983.51	0.934997
1986.46	1.75283
1989.41	2.99731
1992.36	4.79318
1995.31	6.33905
1998.26	7.85415
2001.2	8.60746
2004.15	10.1907
2007.09	12.5877
2010.04	13.5754
2012.98	13.9856
2015.92	14.3355
2018.86	14.244
2021.8	14.8885
2024.73	14.4712
2027.67	14.3096
2030.61	13.0305
2033.54	12.5384
2036.47	12.3852
2039.4	11.5962
2042.33	11.1013
2045.27	11.6908
2048.19	11.5968
2051.12	12.5821
2054.05	12.3045
2056.97	12.5938
2059.9	13.5802
2062.82	15.7946
2065.74	15.433
2068.67	16.4344
2071.59	17.6123
2074.51	19.3851
2077.42	22.4961
2080.34	25.4768
2083.26	26.4751
2086.17	26.2179
2089.09	26.7366
2092	26.8996
2094.91	28.5616
2097.82	27.8595
2100.73	28.7815
2103.64	29.4136
2106.55	29.0479
2109.45	30.24
2112.36	31.1682
2115.26	33.1785
2118.17	36.5369
2121.07	39.5034
2123.97	42.6339
2126.87	45.3518
2129.77	48.9542
2132.67	53.301
2135.56	56.0816
2138.46	60.1894
2141.35	65.9269
2144.25	71.478
2147.14	77.3351
2150.03	81.4447
2152.92	86.5206
2155.81	89.7945
2158.7	93.0575
2161.59	96.2148
2164.47	98.5997
2167.36	99.7727
2170.24	101.267
2173.13	100.242
2176.01	99.7581
2178.89	98.8151
2181.77	99.4569
2184.65	98.9475
2187.53	97.3396
2190.4	96.7906
2193.28	95.0578
2196.16	91.6874
2199.03	87.2052
2201.9	84.3071
2204.77	79.4158
2207.64	77.0854
2210.51	74.0918
2213.38	71.0675
2216.25	66.9093
2219.12	64.5366
2221.98	60.3419
2224.85	56.5072
2227.71	51.3729
2230.57	47.5055
2233.43	43.8839
2236.29	39.8718
2239.15	38.1425
2242.01	33.5004
2244.87	31.4663
2247.72	30.5365
2250.58	28.624
2253.43	28.5813
2256.29	29.331
2259.14	28.3008
2261.99	27.976
2264.84	26.8359
2267.69	25.0974
2270.53	24.8692
2273.38	24.7818
2276.23	23.0785
2279.07	23.3844
2281.91	22.2353
2284.76	21.6867
2287.6	18.217
2290.44	17.4363
2293.28	14.0685
2296.12	12.4471
2298.96	11.2336
2301.79	10.7448
2304.63	10.7086
2307.46	10.0606
2310.3	9.6166
2313.13	9.15099
2315.96	9.84159
2318.79	9.61276
2321.62	9.65253
2324.45	10.6596
2327.27	12.001
2330.1	11.3957
2332.92	11.639
2335.75	11.8764
2338.57	10.5762
2341.39	9.63305
2344.21	10.4363
2347.04	9.88378
2349.85	8.91749
2352.67	9.25871
2355.49	8.21075
2358.3	7.56596
2361.12	7.70615
2363.93	8.93975
2366.75	9.98333
2369.56	9.21849
2372.37	9.82232
2375.18	10.5475
2377.99	10.4484
2380.8	9.89841
2383.6	9.68444
2386.41	10.2675
2389.21	10.1052
2392.02	11.5607
2394.82	11.9338
2397.62	11.332
2400.42	10.7001
2403.22	10.0002
2406.02	8.7219
2408.82	7.8642
2411.62	9.30629
2414.41	8.0479
2417.21	8.10897
2420	8.62931
2422.79	9.54832
2425.59	9.54878
2428.38	9.68988
2431.17	10.002
2433.95	9.0767
2436.74	9.22688
2439.53	10.402
2442.31	11.1638
2445.1	11.613
2447.88	11.3795
2450.67	11.7892
2453.45	12.7395
2456.23	11.7936
2459.01	12.9516
2461.79	12.663
2464.57	12.275
2467.34	11.8878
2470.12	10.9333
2472.89	10.5653
2475.67	10.7682
2478.44	10.7262
2481.21	9.81131
2483.98	8.15981
2486.75	6.23546
2489.52	4.43409
2492.29	4.34342
2495.05	4.23765
2497.82	3.31533
2500.58	1.71765
2503.35	1.59623
2506.11	2.36646
2508.87	3.89666
2511.63	3.33255
2514.39	4.41749
2517.15	4.82521
2519.91	4.61635
2522.67	4.97921
2525.42	5.23203
2528.18	6.40755
2530.93	6.00414
2533.69	6.12437
2536.44	7.2118
2539.19	6.76197
2541.94	7.33136
2544.69	7.46206
2547.44	7.26269
2550.18	7.81306
2552.93	8.20651
2555.67	9.30653
2558.42	10.3558
2561.16	10.8891
2563.9	10.4677
2566.64	9.01073
2569.38	8.9297
2572.12	9.67194
2574.86	9.60263
2577.6	8.38743
2580.33	7.41295
2583.07	6.74347
2585.8	6.07685
2588.54	5.88847
2591.27	4.94036
2594	3.91177
2596.73	3.75369
2599.46	3.53479
2602.19	2.89279
2604.92	3.58044
2607.64	3.00694
2610.37	3.34468
2613.09	3.78655
2615.82	4.75807
2618.54	5.79768
2621.26	5.23605
2623.98	5.3904
2626.7	5.57742
2629.42	5.76433
2632.14	6.25882
2634.86	6.35797
2637.57	5.48809
2640.29	3.66901
2643	2.77899
2645.71	4.215
2648.43	3.17789
2651.14	2.74179
2653.85	2.12861
2656.56	1.63615
2659.26	2.73748
2661.97	1.86019
2664.68	2.15515
2667.38	2.05941
2670.09	2.04754
2672.79	1.58302
2675.49	1.68625
2678.19	2.34768
2680.89	2.76739
2683.59	3.60356
2686.29	3.78681
2688.99	4.26134
2691.69	4.456
2694.38	4.46794
2697.08	5.44106
2699.77	6.14909
2702.46	4.977
2705.15	4.16297
2707.85	6.26424
2710.54	7.29891
2713.22	5.01771
2715.91	4.19479
2718.6	5.34633
2721.29	5.95794
2723.97	6.46004
2726.66	6.09293
2729.34	6.4138
2732.02	6.49627
2734.7	6.17598
2737.38	6.65022
2740.06	7.52081
2742.74	7.07559
2745.42	7.61842
2748.09	6.99821
2750.77	6.8199
2753.45	6.79287
2756.12	6.45156
2758.79	5.95273
2761.46	6.27592
2764.14	6.24715
2766.8	5.50376
2769.47	4.24788
2772.14	4.59859
2774.81	3.64401
2777.48	1.91165
2780.14	1.80333
2782.8	1.80601
2785.47	1.06087
2788.13	1.2751
2790.79	1.00105
2793.45	1.02053
2796.11	0.446397
2798.77	0.0586441
2801.43	0.397821
2804.09	0.617752
2806.74	1.2348
2809.4	2.0959
2812.05	3.80658
2814.71	5.62481
2817.36	7.50128
2820.01	9.71266
2822.66	10.9117
2825.31	13.7975
2827.96	14.8019
2830.6	17.2835
2833.25	19.4067
2835.9	22.5157
2838.54	25.6373
2841.18	30.182
2843.83	34.98
2846.47	40.2259
2849.11	47.0233
2851.75	54.5811
2854.39	62.2391
2857.03	69.6059
2859.66	77.6335
2862.3	84.8363
2864.94	92.5069
2867.57	100.918
2870.2	107.58
2872.84	115.505
2875.47	121.602
2878.1	127.199
2880.73	132.351
2883.36	136.644
2885.99	141.807
2888.61	146.858
2891.24	153.731
2893.86	159.988
2896.49	168.381
2899.11	175.386
2901.73	184.028
2904.36	193.661
2906.98	205.771
2909.6	219.092
2912.21	234.063
2914.83	248.897
2917.45	262.828
2920.07	276.185
2922.68	288.205
2925.29	298.536
2927.91	305.164
2930.52	310.923
2933.13	312.713
2935.74	312.721
2938.35	309.459
2940.96	304.62
2943.57	296.542
2946.18	285.973
2948.78	275.647
2951.39	265.758
2953.99	253.655
2956.59	240.963
2959.2	228.343
2961.8	214.852
2964.4	201.918
2967	191.087
2969.6	179.555
2972.19	170.022
2974.79	160.556
2977.39	150.921
2979.98	142.348
2982.58	131.813
2985.17	122.528
2987.76	113.288
2990.35	102.708
2992.94	91.6752
2995.53	82.2804
2998.12	73.8993
3000.71	64.7243
3003.3	55.4568
3005.88	47.2955
3008.47	39.6079
3011.05	33.5488
3013.64	29.9143
3016.22	24.876
3018.8	21.2307
3021.38	18.293
3023.96	15.4921
3026.54	13.5452
3029.12	13.1238
3031.69	13.0839
3034.27	12.696
3036.84	14.0984
3039.42	14.9669
3041.99	16.383
3044.57	17.4853
3047.14	17.8684
3049.71	18.4439
3052.28	18.642
3054.85	19.0603
3057.41	20.1094
3059.98	20.7194
3062.55	20.3861
3065.11	18.8933
3067.68	18.512
3070.24	17.7096
3072.8	15.7135
3075.36	14.5567
3077.93	12.7843
3080.49	10.9915
3083.04	8.68147
3085.6	6.62793
3088.16	5.17086
3090.72	3.35792
3093.27	3.51967
3095.83	2.53972
3098.38	1.60538
3100.93	1.3325
3103.49	1.16624
3106.04	0.985541
3108.59	1.27416
3111.14	2.69991
3113.69	3.47921
3116.23	5.07592
3118.78	6.38694
3121.33	7.84458
3123.87	9.09413
3126.41	9.81758
3128.96	10.9795
3131.5	11.8524
3134.04	12.8035
3136.58	14.8754
3139.12	15.808
3141.66	15.7768
3144.2	15.4507
3146.74	14.9938
3149.27	12.0889