File: data/Raman/poly_smoothed/Mb_30_27_24_1x_45s_532 nm_x100_100%_600 gr_mm_01.txt
#Acq. time (s)=	45
#Accumulations=	2
#Range (cm-¹)=	200...3150
#Windows=	2
#Auto scanning=	Off
#Autofocus=	Off
#Macrospot=	Off
#AutoExposure=	Off
#Spike filter=	Multiple accum.
#Delay time (s)=	0
#Binning=	1
#Readout mode=	Signal
#DeNoise=	Off
#ICS correction=	On
#Dark correction=	Off
#Inst. Process=	Off
#Detector Gain=	Best Dynamic Range
#Detector ADC=	20 kHz
#Detector temperature (°C)=	-69.85
#Instrument=	LabRAM HR Evol
#Detector=	Synapse
#Objective=	x100
#Grating=	600 gr/mm
#ND Filter=	100%
#Laser (nm)=	532
#Hole=	100.021
#Range=	Auto
#Laser Pol.=	No
#Raman. Pol.=	No
#Laser Pol. (°)=	-0.0007625
#Raman Pol. (°)=	89.9995
#Collection=	Microscope
#StageXY=	Marzhauser
#StageZ=	Marzhauser
#X (µm)=	-6358.4
#Y (µm)=	860.4
#Z (µm)=	-64.55
#Full time(mm:ss)=	3:19
#Project=
#Sample=
#Site=
#Title=	Mb_30_27_24_2x_45s_532 nm_x100_100%_600 gr_mm
#Remark=
#Date=	13.07.2022 10:22
#Acquired=	13.07.2022 10:22:31
#Base:Fit=	10.08.2022 10:40:03
#Base:Sub=	10.08.2022 10:40:17
#Filter:Polynom=	16.08.2022 10:16:15
#AxisType[0]=Intens
#AxisUnit[0]=Cnt
#AxisType[1]=Spectr
#AxisUnit[1]=1/cm
200.563	0.599116
204.194	5.58817
207.821	8.44476
211.449	11.6314
215.074	14.3061
218.699	14.4664
222.321	15.0562
225.941	13.7457
229.562	13.072
233.18	13.9219
236.796	14.4523
240.411	14.9538
244.026	14.5577
247.638	13.6981
251.248	12.0957
254.857	10.4519
258.465	9.61488
262.071	9.78761
265.678	9.73118
269.282	8.95536
272.884	7.77515
276.484	8.26276
280.084	8.57357
283.682	9.43007
287.276	11.49
290.871	12.8597
294.465	13.9782
298.057	15.2438
301.648	16.8319
305.237	16.6054
308.823	16.44
312.41	16.3174
315.995	15.7258
319.579	16.0888
323.16	14.7737
326.741	14.5053
330.321	13.7581
333.897	12.1034
337.474	10.3929
341.048	9.45343
344.622	8.86712
348.192	9.59038
351.764	9.67755
355.332	7.90287
358.901	7.0392
362.466	6.75628
366.03	9.76668
369.594	11.2745
373.155	12.4912
376.715	14.5457
380.273	14.6764
383.832	15.8299
387.388	17.1366
390.942	17.4567
394.495	18.7946
398.047	17.5565
401.597	16.9021
405.145	17.1576
408.693	17.3025
412.239	17.737
415.783	17.9402
419.327	16.9342
422.869	17.1042
426.409	15.9772
429.948	15.4225
433.486	16.3601
437.022	14.4928
440.558	13.1975
444.089	13.9825
447.622	13.0083
451.153	12.2603
454.682	12.246
458.208	12.1986
461.735	12.7815
465.259	13.402
468.783	13.9443
472.306	15.0462
475.825	16.7667
479.346	17.5337
482.862	18.1022
486.38	18.5889
489.894	20.746
493.407	21.6688
496.92	23.1142
500.43	23.7272
503.939	23.7548
507.448	25.0909
510.954	25.696
514.459	27.7332
517.962	27.3394
521.466	27.4409
524.966	25.9768
528.466	25.7644
531.964	23.9909
535.46	20.321
538.955	19.6186
542.449	18.161
545.942	17.1483
549.433	14.5919
552.923	13.4887
556.412	10.9974
559.899	8.14631
563.385	9.24808
566.867	6.32777
570.35	4.67371
573.832	3.39252
577.313	3.46779
580.79	1.67906
584.268	1.70971
587.745	0.55128
591.218	0.598023
594.692	1.92516
598.164	3.23743
601.634	4.46324
605.104	3.91175
608.57	3.68352
612.037	3.99775
615.501	5.27795
618.966	4.5964
622.427	5.04639
625.887	5.60775
629.348	4.83106
632.806	6.22869
636.262	6.20539
639.716	7.59157
643.172	7.40066
646.624	8.7803
650.075	9.99609
653.524	9.21672
656.972	10.0288
660.419	9.54329
663.865	10.7391
667.309	10.786
670.752	12.3495
674.194	12.6808
677.634	14.8862
681.073	15.6495
684.511	17.5461
687.947	18.839
691.382	19.9735
694.816	22.7545
698.247	24.6929
701.678	23.7632
705.108	23.669
708.534	24.7426
711.962	26.4996
715.388	28.8409
718.81	30.9295
722.234	32.0495
725.654	35.4165
729.075	36.3273
732.492	37.3423
735.91	36.9348
739.325	38.6324
742.741	40.4006
746.153	43.941
749.564	47.3906
752.976	51.5904
756.385	53.5663
759.792	59.5647
763.2	62.9815
766.604	66.0338
770.008	69.0444
773.41	71.8277
776.811	74.5625
780.21	76.0556
783.608	76.5351
787.005	78.0408
790.401	80.6502
793.795	82.5903
797.188	84.8302
800.58	85.8264
803.971	86.4702
807.36	85.6728
810.748	85.7399
814.135	84.8869
817.518	84.0719
820.902	83.5798
824.285	83.9242
827.665	83.9757
831.045	83.8865
834.424	83.5262
837.8	81.5739
841.177	79.1107
844.55	76.3641
847.924	73.4805
851.295	69.1076
854.666	66.7337
858.034	66.2901
861.403	63.0696
864.769	60.9891
868.133	57.9506
871.498	56.2655
874.86	54.9836
878.221	54.0222
881.58	54.2584
884.938	54.2203
888.297	55.0565
891.653	54.6139
895.007	54.6132
898.36	55.1172
901.712	57.3391
905.063	58.6785
908.412	58.6352
911.76	59.8693
915.107	59.3378
918.452	57.1551
921.797	54.5234
925.138	53.576
928.48	52.5903
931.82	50.6517
935.16	48.6056
938.496	47.5712
941.833	44.7393
945.168	42.3006
948.5	39.8302
951.834	39.9437
955.163	39.8244
958.494	38.4875
961.821	36.999
965.15	37.2611
968.474	37.8216
971.8	38.3847
975.123	39.4183
978.446	40.347
981.766	42.4244
985.084	42.4328
988.402	42.7458
991.72	41.9938
995.035	41.1897
998.349	39.4236
1001.66	38.6344
1004.97	39.0226
1008.28	40.2674
1011.59	40.5144
1014.9	41.6827
1018.21	42.8465
1021.51	42.4823
1024.81	43.2801
1028.12	45.3385
1031.42	48.1838
1034.72	48.4986
1038.02	47.2613
1041.31	45.92
1044.61	46.2709
1047.91	45.5698
1051.2	44.4343
1054.49	44.733
1057.78	41.2502
1061.07	39.1127
1064.36	35.774
1067.65	33.2893
1070.93	30.8433
1074.22	28.4324
1077.5	27.1676
1080.78	26.9975
1084.06	25.3008
1087.34	25.7886
1090.62	26.8314
1093.9	27.5631
1097.17	27.6025
1100.45	28.0877
1103.72	27.742
1106.99	28.3757
1110.27	28.6801
1113.53	27.0791
1116.8	25.8835
1120.07	25.7318
1123.33	24.5022
1126.6	24.9343
1129.86	24.2729
1133.12	21.5146
1136.38	20.4149
1139.64	18.4251
1142.9	17.1774
1146.16	16.5593
1149.41	14.6324
1152.67	13.7892
1155.92	12.6652
1159.17	12.743
1162.42	10.6422
1165.67	10.6351
1168.92	11.485
1172.16	11.2073
1175.41	10.9694
1178.65	11.6078
1181.9	11.3358
1185.14	12.3627
1188.38	14.3401
1191.62	15.5282
1194.86	18.1653
1198.09	19.1825
1201.33	21.1961
1204.56	23.2695
1207.8	24.9521
1211.03	26.6512
1214.26	29.5337
1217.49	33.6999
1220.71	36.3807
1223.94	39.4728
1227.16	42.4035
1230.39	45.835
1233.61	49.8337
1236.83	53.9149
1240.05	56.9918
1243.27	60.045
1246.49	61.8427
1249.71	64.3227
1252.92	68.2852
1256.14	71.8611
1259.35	75.2036
1262.56	76.2193
1265.77	78.2927
1268.98	79.5302
1272.19	80.0345
1275.4	81.7216
1278.6	82.2258
1281.81	84.27
1285.01	84.6214
1288.21	85.49
1291.41	87.4824
1294.61	88.2589
1297.81	87.3534
1301.01	88.2451
1304.2	87.9991
1307.4	89.0807
1310.59	90.7958
1313.78	91.2045
1316.97	91.0961
1320.16	90.3013
1323.35	89.6712
1326.54	90.523
1329.72	89.811
1332.91	89.2041
1336.09	88.2964
1339.27	86.6629
1342.45	82.738
1345.64	80.9453
1348.81	77.5542
1351.99	74.2015
1355.17	71.9705
1358.34	69.3113
1361.51	67.1318
1364.69	63.5096
1367.86	61.8149
1371.03	58.4911
1374.2	54.7709
1377.37	52.6391
1380.53	50.3496
1383.7	50.276
1386.86	49.9022
1390.02	48.3021
1393.19	47.3843
1396.35	47.8503
1399.51	48.2362
1402.66	49.3479
1405.82	51.1398
1408.97	52.4662
1412.13	55.5038
1415.28	58.2858
1418.43	61.5886
1421.59	67.1225
1424.73	70.8835
1427.88	75.3964
1431.03	80.615
1434.18	85.2423
1437.32	89.1977
1440.46	91.3907
1443.61	92.2047
1446.75	92.6415
1449.89	91.8609
1453.03	89.2953
1456.16	87.0173
1459.3	85.4892
1462.44	82.5146
1465.57	78.7548
1468.7	74.3025
1471.83	70.0602
1474.96	65.5184
1478.09	61.6487
1481.22	58.2499
1484.35	54.8149
1487.47	52.1892
1490.6	49.4351
1493.72	46.798
1496.84	44.3162
1499.96	42.4309
1503.08	40.8548
1506.2	40.3749
1509.32	38.7803
1512.44	36.9715
1515.55	35.8612
1518.66	34.3226
1521.78	33.9978
1524.89	33.1079
1528	31.7399
1531.11	31.1106
1534.21	31.7185
1537.32	32.2155
1540.43	32.3696
1543.53	34.4442
1546.63	35.7922
1549.74	37.4485
1552.84	38.4178
1555.94	39.7943
1559.03	42.9417
1562.13	43.3851
1565.23	44.5325
1568.32	46.1037
1571.42	47.6705
1574.51	50.2154
1577.6	52.9501
1580.69	53.8417
1583.78	55.5245
1586.87	57.7689
1589.95	60.7246
1593.04	62.663
1596.12	63.9957
1599.21	65.0441
1602.29	64.6433
1605.37	65.8921
1608.45	66.07
1611.53	67.5836
1614.6	68.4192
1617.68	70.1153
1620.75	71.5618
1623.83	72.3544
1626.9	73.5008
1629.97	75.9059
1633.04	77.8454
1636.11	80.9532
1639.18	83.6576
1642.25	87.2533
1645.31	89.5281
1648.38	91.2397
1651.44	93.6084
1654.5	93.8285
1657.56	94.9389
1660.62	95.5363
1663.68	94.5649
1666.74	93.5478
1669.8	90.0864
1672.85	86.3677
1675.91	82.2702
1678.96	77.271
1682.01	71.6689
1685.06	66.0678
1688.11	61.1354
1691.16	54.5834
1694.21	49.4019
1697.25	44.7355
1700.3	39.7379
1703.34	35.156
1706.39	31.3359
1709.43	29.3634
1712.47	27.5098
1715.51	24.7818
1718.54	23.6984
1721.58	22.5748
1724.62	21.8585
1727.65	20.3714
1730.68	19.8131
1733.72	18.9695
1736.75	16.766
1739.78	15.6761
1742.81	15.257
1745.84	14.167
1748.86	13.6202
1751.89	12.5825
1754.91	11.5742
1757.93	11.0235
1760.96	10.2883
1763.98	8.6449
1767	7.67151
1770.02	7.37391
1773.03	6.54587
1776.05	6.04261
1779.07	5.45953
1782.08	5.58274
1785.09	5.29169
1788.11	4.63623
1791.12	4.53874
1794.13	4.67817
1797.13	5.28395
1800.14	6.03982
1803.15	5.31615
1806.15	4.09891
1809.16	3.35257
1812.16	3.11299
1815.16	3.99441
1818.16	4.13073
1821.16	3.73025
1824.16	4.39767
1827.16	4.29234
1830.16	4.16568
1833.15	4.20334
1836.14	4.75211
1839.14	5.40347
1842.13	5.77762
1845.12	5.57084
1848.11	5.22844
1851.1	3.89597
1854.08	3.33127
1857.07	2.30789
1860.05	2.48451
1863.04	2.7245
1866.02	3.77763
1869	5.09663
1871.98	4.5752
1874.96	4.32422
1877.94	3.64994
1880.92	3.52107
1882.51	3.13742
1885.5	3.97183
1888.48	4.60345
1891.47	4.24945
1894.46	4.02111
1897.44	4.70591
1900.42	4.4106
1903.41	3.68877
1906.39	3.97501
1909.37	4.25505
1912.35	3.81908
1915.32	3.13032
1918.3	2.98329
1921.27	2.90854
1924.25	2.81437
1927.22	3.43924
1930.19	3.64974
1933.17	3.50514
1936.14	4.416
1939.11	4.84598
1942.07	4.1037
1945.04	4.11211
1948.01	4.31921
1950.97	4.0751
1953.93	5.02489
1956.9	5.85664
1959.86	6.17516
1962.82	5.37425
1965.78	4.30088
1968.74	4.09461
1971.69	3.6599
1974.65	3.07378
1977.6	4.19985
1980.56	2.88363
1983.51	2.84758
1986.46	2.27803
1989.41	2.10647
1992.36	1.89685
1995.31	1.97679
1998.26	1.74252
2001.2	0.508743
2004.15	0.860641
2007.09	1.24744
2010.04	2.0499
2012.98	2.02513
2015.92	1.83474
2018.86	1.90842
2021.8	2.70185
2024.73	3.73481
2027.67	3.90893
2030.61	3.40543
2033.54	3.08145
2036.47	3.55131
2039.4	4.25521
2042.33	4.96434
2045.27	5.79849
2048.19	6.10026
2051.12	6.14269
2054.05	6.22713
2056.97	6.57684
2059.9	6.4302
2062.82	7.01569
2065.74	8.34033
2068.67	9.44186
2071.59	9.65847
2074.51	10.8519
2077.42	11.3632
2080.34	11.8199
2083.26	12.0492
2086.17	12.1264
2089.09	12.9133
2092	13.4375
2094.91	14.0969
2097.82	15.1592
2100.73	16.1242
2103.64	17.7259
2106.55	19.3593
2109.45	21.8468
2112.36	23.4382
2115.26	26.2197
2118.17	28.6348
2121.07	31.7137
2123.97	35.1791
2126.87	37.7968
2129.77	41.5886
2132.67	45.5376
2135.56	50.6013
2138.46	54.3855
2141.35	58.0681
2144.25	60.4832
2147.14	63.7686
2150.03	66.5053
2152.92	70.2671
2155.81	72.2246
2158.7	73.8256
2161.59	74.963
2164.47	76.6079
2167.36	76.9568
2170.24	78.2245
2173.13	78.2308
2176.01	78.1148
2178.89	77.3696
2181.77	76.5702
2184.65	74.8971
2187.53	72.9276
2190.4	70.9088
2193.28	67.7708
2196.16	65.2817
2199.03	62.6832
2201.9	59.0083
2204.77	55.7609
2207.64	53.0923
2210.51	50.3108
2213.38	47.7975
2216.25	44.6872
2219.12	42.0802
2221.98	39.4278
2224.85	36.3517
2227.71	32.8867
2230.57	29.8868
2233.43	28.1235
2236.29	27.3062
2239.15	26.501
2242.01	25.1459
2244.87	23.6778
2247.72	22.7353
2250.58	21.6855
2253.43	20.5458
2256.29	18.3865
2259.14	17.07
2261.99	15.6369
2264.84	13.8825
2267.69	13.1561
2270.53	10.6199
2273.38	9.54059
2276.23	9.23654
2279.07	8.3869
2281.91	7.51871
2284.76	6.24134
2287.6	5.58524
2290.44	3.89313
2293.28	2.21132
2296.12	2.5082
2298.96	4.0992
2301.79	3.74907
2304.63	4.61488
2307.46	5.18593
2310.3	5.36569
2313.13	4.74924
2315.96	4.975
2318.79	5.73568
2321.62	5.45042
2324.45	4.85062
2327.27	5.62686
2330.1	5.8833
2332.92	6.30808
2335.75	5.6884
2338.57	4.91482
2341.39	5.14699
2344.21	5.01757
2347.04	5.36291
2349.85	5.11378
2352.67	4.38454
2355.49	3.39647
2358.3	2.12304
2361.12	2.43017
2363.93	3.0138
2366.75	3.64073
2369.56	3.23252
2372.37	2.58959
2375.18	2.27798
2377.99	1.68075
2380.8	1.17629
2383.6	0.964812
2386.41	0.771263
2389.21	0.782707
2392.02	1.26696
2394.82	0.829008
2397.62	0.925306
2400.42	1.11587
2403.22	1.54215
2406.02	1.21526
2408.82	1.01432
2411.62	1.78542
2414.41	1.5794
2417.21	2.0062
2420	1.82447
2422.79	1.37238
2425.59	2.11513
2428.38	2.47587
2431.17	2.52695
2433.95	2.34258
2436.74	3.08022
2439.53	3.14112
2442.31	3.06858
2445.1	4.00323
2447.88	4.81969
2450.67	4.17876
2453.45	4.53692
2456.23	4.55671
2459.01	5.59358
2461.79	4.89854
2464.57	4.09311
2467.34	4.79327
2470.12	5.61648
2472.89	5.80962
2475.67	5.35718
2478.44	4.94305
2481.21	5.06922
2483.98	5.53458
2486.75	5.06763
2489.52	5.07702
2492.29	4.8863
2495.05	3.53084
2497.82	2.89062
2500.58	3.11174
2503.35	2.82898
2506.11	2.65795
2508.87	2.11848
2511.63	2.09746
2514.39	1.83034
2517.15	0.938399
2519.91	1.14183
2522.67	0.548241
2525.42	0.295273
2528.18	-0.0365112
2530.93	-0.530836
2533.69	-0.257042
2536.44	0.269157
2539.19	0.742099
2541.94	-0.159353
2544.69	-1.02417
2547.44	-0.74587
2550.18	0.0122404
2552.93	-0.503092
2555.67	-0.823396
2558.42	-0.814301
2561.16	-0.626713
2563.9	0.607377
2566.64	1.41578
2569.38	2.87432
2572.12	3.20447
2574.86	3.55348
2577.6	3.57384
2580.33	4.03252
2583.07	4.35819
2585.8	4.80424
2588.54	4.66035
2591.27	5.40909
2594	5.54603
2596.73	5.75904
2599.46	5.58283
2602.19	5.5451
2604.92	5.31274
2607.64	4.88438
2610.37	3.7902
2613.09	3.38152
2615.82	3.66666
2618.54	3.14623
2621.26	2.89964
2623.98	2.88869
2626.7	3.94801
2629.42	4.47434
2632.14	5.0994
2634.86	5.34935
2637.57	5.6532
2640.29	5.63417
2643	5.66456
2645.71	5.08411
2648.43	5.70639
2651.14	5.89805
2653.85	5.83479
2656.56	6.73228
2659.26	6.09603
2661.97	5.8493
2664.68	4.95654
2667.38	4.81671
2670.09	4.32666
2672.79	4.79217
2675.49	3.83295
2678.19	4.21888
2680.89	4.25562
2683.59	4.27253
2686.29	4.26139
2688.99	4.70235
2691.69	4.51008
2694.38	5.0144
2697.08	4.56779
2699.77	4.4986
2702.46	4.80109
2705.15	5.73577
2707.85	5.60022
2710.54	5.69796
2713.22	6.72207
2715.91	6.41097
2718.6	6.56824
2721.29	5.89293
2723.97	4.46455
2726.66	3.88698
2729.34	3.67321
2732.02	3.50718
2734.7	3.10037
2737.38	3.19652
2740.06	3.25652
2742.74	3.36931
2745.42	2.74251
2748.09	1.66882
2750.77	1.60324
2753.45	1.27609
2756.12	1.34314
2758.79	1.79959
2761.46	0.858513
2764.14	0.759713
2766.8	1.53872
2769.47	2.19343
2772.14	2.51953
2774.81	1.7736
2777.48	2.43778
2780.14	2.70228
2782.8	1.75391
2785.47	2.07235
2788.13	1.66909
2790.79	1.19232
2793.45	1.96563
2796.11	2.19734
2798.77	1.76277
2801.43	1.4201
2804.09	2.26623
2806.74	1.88104
2809.4	1.59136
2812.05	0.979538
2814.71	1.75858
2817.36	2.63813
2820.01	3.82481
2822.66	5.35383
2825.31	7.21046
2827.96	9.10074
2830.6	11.7892
2833.25	14.7407
2835.9	18.5127
2838.54	21.942
2841.18	26.6098
2843.83	32.3046
2846.47	39.049
2849.11	45.1947
2851.75	52.2443
2854.39	59.129
2857.03	66.9052
2859.66	74.3174
2862.3	81.0502
2864.94	86.5461
2867.57	92.876
2870.2	98.3361
2872.84	103.337
2875.47	106.423
2878.1	110.361
2880.73	114.631
2883.36	118.156
2885.99	121.69
2888.61	125.275
2891.24	129.085
2893.86	132.835
2896.49	138.315
2899.11	143.464
2901.73	149.854
2904.36	156.91
2906.98	166.204
2909.6	176.514
2912.21	186.289
2914.83	196.961
2917.45	206.305
2920.07	216.464
2922.68	223.66
2925.29	230.043
2927.91	234.139
2930.52	238.227
2933.13	239.009
2935.74	237.765
2938.35	234.807
2940.96	230.028
2943.57	225.074
2946.18	217.708
2948.78	209.239
2951.39	199.898
2953.99	189.493
2956.59	179.945
2959.2	169.154
2961.8	158.411
2964.4	147.058
2967	138.125
2969.6	130.533
2972.19	121.564
2974.79	112.145
2977.39	103.808
2979.98	95.5618
2982.58	86.741
2985.17	78.9074
2987.76	71.4394
2990.35	63.4607
2992.94	56.3228
2995.53	49.0422
2998.12	41.6724
3000.71	35.4591
3003.3	28.79
3005.88	23.5117
3008.47	18.6675
3011.05	14.965
3013.64	10.4376
3016.22	7.27577
3018.8	4.99575
3021.38	3.33453
3023.96	1.46442
3026.54	0.31062
3029.12	-0.181038
3031.69	0.348753
3034.27	0.253505
3036.84	-0.490471
3039.42	0.560192
3041.99	0.843721
3044.57	1.91241
3047.14	2.96584
3049.71	4.2639
3052.28	4.85116
3054.85	4.99761
3057.41	5.25449
3059.98	5.19416
3062.55	5.39501
3065.11	4.77083
3067.68	3.81569
3070.24	3.67876
3072.8	3.51051
3075.36	2.59263
3077.93	1.7139
3080.49	1.82659
3083.04	1.20538
3085.6	0.755084
3088.16	1.25585
3090.72	1.43117
3093.27	1.43497
3095.83	1.24487
3098.38	1.63747
3100.93	2.69876
3103.49	3.51992
3106.04	4.40204
3108.59	5.8642
3111.14	7.09927
3113.69	8.72921
3116.23	10.2666
3118.78	11.7543
3121.33	13.149
3123.87	14.3586
3126.41	15.862
3128.96	17.5231
3131.5	19.2418
3134.04	20.3262
3136.58	22.056
3139.12	22.86
3141.66	24.4741
3144.2	25.1647
3146.74	25.4803
3149.27	23.7697