File: data/Raman/poly_smoothed/Mb_30_27_41_1x_45s_532 nm_x100_100%_600 gr_mm_01.txt
#Acq. time (s)=	45
#Accumulations=	2
#Range (cm-¹)=	200...3150
#Windows=	2
#Auto scanning=	Off
#Autofocus=	Off
#Macrospot=	Off
#AutoExposure=	Off
#Spike filter=	Multiple accum.
#Delay time (s)=	0
#Binning=	1
#Readout mode=	Signal
#DeNoise=	Off
#ICS correction=	On
#Dark correction=	Off
#Inst. Process=	Off
#Detector Gain=	Best Dynamic Range
#Detector ADC=	20 kHz
#Detector temperature (°C)=	-69.85
#Instrument=	LabRAM HR Evol
#Detector=	Synapse
#Objective=	x100
#Grating=	600 gr/mm
#ND Filter=	100%
#Laser (nm)=	532
#Hole=	100.021
#Range=	Auto
#Laser Pol.=	No
#Raman. Pol.=	No
#Laser Pol. (°)=	-0.0007625
#Raman Pol. (°)=	89.9995
#Collection=	Microscope
#StageXY=	Marzhauser
#StageZ=	Marzhauser
#X (µm)=	-6351.7
#Y (µm)=	797.7
#Z (µm)=	-64.65
#Full time(mm:ss)=	3:18
#Project=
#Sample=
#Site=
#Title=	Mb_30_27_41_2x_45s_532 nm_x100_100%_600 gr_mm
#Remark=
#Date=	13.07.2022 11:53
#Acquired=	13.07.2022 11:53:25
#Base:Fit=	10.08.2022 10:40:03
#Base:Sub=	10.08.2022 10:40:17
#Filter:Polynom=	16.08.2022 10:16:15
#AxisType[0]=Intens
#AxisUnit[0]=Cnt
#AxisType[1]=Spectr
#AxisUnit[1]=1/cm
200.563	30.1286
204.194	23.9581
207.821	19.4194
211.449	15.7332
215.074	13.4451
218.699	11.7282
222.321	8.59428
225.941	7.07199
229.562	6.94078
233.18	7.93393
236.796	6.33724
240.411	5.92019
244.026	5.80385
247.638	5.78266
251.248	6.44125
254.857	7.18313
258.465	7.41216
262.071	8.11879
265.678	9.70729
269.282	11.9914
272.884	12.0866
276.484	12.3179
280.084	12.5946
283.682	10.2905
287.276	10.7992
290.871	9.17427
294.465	9.18574
298.057	8.32672
301.648	8.60042
305.237	7.91544
308.823	7.51828
312.41	7.64999
315.995	8.2963
319.579	7.89941
323.16	7.09997
326.741	7.33871
330.321	6.99993
333.897	7.45327
337.474	8.09184
341.048	9.57806
344.622	8.13201
348.192	9.53327
351.764	9.61914
355.332	10.6994
358.901	10.7679
362.466	9.41479
366.03	8.89097
369.594	8.5606
373.155	8.26751
376.715	9.86053
380.273	9.32544
383.832	8.569
387.388	8.86477
390.942	8.73892
394.495	9.48304
398.047	8.68743
401.597	8.55486
405.145	9.60799
408.693	9.53447
412.239	10.0221
415.783	10.0265
419.327	10.129
422.869	10.219
426.409	10.0057
429.948	10.0782
433.486	8.6669
437.022	8.94782
440.558	8.32845
444.089	7.40318
447.622	8.98467
451.153	8.98216
454.682	9.70797
458.208	12.7663
461.735	14.7896
465.259	15.07
468.783	15.9045
472.306	16.961
475.825	17.6411
479.346	18.7242
482.862	18.9795
486.38	18.9727
489.894	20.068
493.407	20.7934
496.92	21.5499
500.43	22.3728
503.939	22.4893
507.448	22.5628
510.954	21.7476
514.459	21.3253
517.962	20.8593
521.466	20.3934
524.966	19.8888
528.466	18.9534
531.964	19.3994
535.46	19.2259
538.955	19.0458
542.449	19.725
545.942	20.077
549.433	18.8127
552.923	18.2422
556.412	17.5513
559.899	15.8186
563.385	13.8635
566.867	12.4464
570.35	11.2727
573.832	10.3557
577.313	8.78571
580.79	7.31877
584.268	6.50295
587.745	4.45057
591.218	2.65071
594.692	1.86523
598.164	1.65129
601.634	0.633511
605.104	1.30097
608.57	1.88804
612.037	2.75512
615.501	3.25386
618.966	5.07372
622.427	5.8948
625.887	7.5945
629.348	9.97732
632.806	10.6451
636.262	11.5597
639.716	12.8084
643.172	13.6555
646.624	12.1432
650.075	13.9739
653.524	13.2245
656.972	14.3536
660.419	13.4197
663.865	15.0771
667.309	15.4756
670.752	16.8748
674.194	17.8637
677.634	19.6574
681.073	21.7881
684.511	24.6032
687.947	27.1363
691.382	30.5031
694.816	34.2968
698.247	36.3891
701.678	37.7151
705.108	41.3048
708.534	42.5596
711.962	44.791
715.388	45.4359
718.81	44.8804
722.234	45.8188
725.654	45.8078
729.075	45.2552
732.492	44.6374
735.91	44.0343
739.325	44.9126
742.741	44.8195
746.153	46.1656
749.564	49.5889
752.976	51.9236
756.385	54.7329
759.792	57.843
763.2	62.2914
766.604	66.4071
770.008	70.5081
773.41	73.9368
776.811	77.4697
780.21	80.3265
783.608	81.1826
787.005	83.6091
790.401	86.1144
793.795	88.4393
797.188	90.1794
800.58	90.4745
803.971	90.9075
807.36	92.3431
810.748	91.3277
814.135	91.2552
817.518	89.8218
820.902	88.5486
824.285	88.1953
827.665	87.8234
831.045	86.8521
834.424	85.1326
837.8	83.6093
841.177	81.7097
844.55	79.8458
847.924	77.1874
851.295	74.1937
854.666	70.7543
858.034	67.6989
861.403	64.3204
864.769	63.3099
868.133	60.3616
871.498	58.4721
874.86	55.6491
878.221	53.8436
881.58	52.5383
884.938	53.4702
888.297	54.6708
891.653	54.8237
895.007	55.6343
898.36	55.9187
901.712	55.6735
905.063	56.6009
908.412	55.3301
911.76	54.9312
915.107	54.1871
918.452	54.1207
921.797	53.8513
925.138	54.9356
928.48	52.7424
931.82	51.4904
935.16	48.5379
938.496	47.0769
941.833	46.8933
945.168	45.0368
948.5	45.3568
951.834	42.8956
955.163	41.1294
958.494	39.8039
961.821	40.2162
965.15	42.0938
968.474	42.8389
971.8	42.5043
975.123	42.1818
978.446	42.1458
981.766	40.6366
985.084	38.7115
988.402	36.3667
991.72	36.5222
995.035	35.2275
998.349	32.7183
1001.66	31.0057
1004.97	29.0677
1008.28	29.3508
1011.59	29.9539
1014.9	33.3027
1018.21	37.6367
1021.51	41.7914
1024.81	46.8966
1028.12	50.4957
1031.42	53.4865
1034.72	54.6589
1038.02	56.3454
1041.31	57.3794
1044.61	57.7991
1047.91	57.3261
1051.2	54.7227
1054.49	52.9012
1057.78	49.5032
1061.07	44.4997
1064.36	39.4164
1067.65	35.2373
1070.93	31.1377
1074.22	26.4771
1077.5	21.3377
1080.78	18.3894
1084.06	16.3701
1087.34	16.1731
1090.62	17.7459
1093.9	20.4314
1097.17	21.7234
1100.45	22.6605
1103.72	24.4403
1106.99	24.8773
1110.27	25.2944
1113.53	25.7489
1116.8	25.1575
1120.07	24.6178
1123.33	23.7214
1126.6	22.7891
1129.86	20.2686
1133.12	18.0708
1136.38	16.8008
1139.64	15.3889
1142.9	12.9863
1146.16	11.6888
1149.41	10.0726
1152.67	6.92322
1155.92	5.61592
1159.17	3.65978
1162.42	3.23708
1165.67	1.82191
1168.92	2.38275
1172.16	1.61887
1175.41	2.66972
1178.65	2.04386
1181.9	4.04682
1185.14	4.95447
1188.38	6.22252
1191.62	8.72421
1194.86	10.7048
1198.09	11.5905
1201.33	13.0623
1204.56	14.9979
1207.8	18.2335
1211.03	20.8477
1214.26	23.8498
1217.49	27.5215
1220.71	30.539
1223.94	33.0002
1227.16	35.8265
1230.39	37.8543
1233.61	39.8065
1236.83	40.7966
1240.05	43.2519
1243.27	45.3962
1246.49	46.5378
1249.71	48.313
1252.92	49.4778
1256.14	52.2566
1259.35	52.8167
1262.56	53.2331
1265.77	54.0455
1268.98	53.8918
1272.19	54.3785
1275.4	53.3544
1278.6	53.3876
1281.81	55.1641
1285.01	58.0087
1288.21	59.1807
1291.41	61.2603
1294.61	62.0642
1297.81	63.7213
1301.01	65.3056
1304.2	67.853
1307.4	68.301
1310.59	70.4183
1313.78	71.5233
1316.97	72.2788
1320.16	72.7649
1323.35	74.2033
1326.54	73.6528
1329.72	73.3422
1332.91	71.6762
1336.09	69.3722
1339.27	65.7154
1342.45	62.2496
1345.64	60.48
1348.81	56.5184
1351.99	53.3039
1355.17	50.614
1358.34	49.7148
1361.51	46.9109
1364.69	45.3411
1367.86	43.8883
1371.03	42.2888
1374.2	40.5549
1377.37	39.8804
1380.53	39.2922
1383.7	39.2846
1386.86	39.0744
1390.02	38.2817
1393.19	37.9947
1396.35	36.9594
1399.51	37.0136
1402.66	36.7154
1405.82	35.4209
1408.97	35.8529
1412.13	35.1276
1415.28	35.9021
1418.43	38.2361
1421.59	41.0213
1424.73	43.3965
1427.88	46.9282
1431.03	51.2912
1434.18	55.234
1437.32	59.0073
1440.46	61.1761
1443.61	62.7564
1446.75	64.7493
1449.89	65.565
1453.03	66.4586
1456.16	68.0357
1459.3	67.1654
1462.44	66.8554
1465.57	65.3422
1468.7	62.7846
1471.83	60.0717
1474.96	58.7218
1478.09	55.1106
1481.22	52.212
1484.35	49.0215
1487.47	46.1575
1490.6	43.8737
1493.72	41.6135
1496.84	39.3587
1499.96	37.2075
1503.08	34.8356
1506.2	33.4195
1509.32	31.6302
1512.44	29.4492
1515.55	27.7684
1518.66	26.1204
1521.78	26.5073
1524.89	25.3554
1528	24.1843
1531.11	25.4814
1534.21	25.613
1537.32	25.837
1540.43	26.9486
1543.53	26.9054
1546.63	27.9684
1549.74	29.7994
1552.84	30.2069
1555.94	30.712
1559.03	31.1043
1562.13	32.8838
1565.23	33.7251
1568.32	35.3381
1571.42	35.985
1574.51	35.7586
1577.6	36.5835
1580.69	36.9932
1583.78	37.9517
1586.87	38.9502
1589.95	40.4627
1593.04	41.8321
1596.12	44.3326
1599.21	44.9746
1602.29	44.9289
1605.37	46.2713
1608.45	47.6586
1611.53	49.4985
1614.6	51.9923
1617.68	53.3041
1620.75	54.8293
1623.83	57.377
1626.9	60.231
1629.97	63.6234
1633.04	65.5983
1636.11	69.5904
1639.18	72.4477
1642.25	74.7782
1645.31	75.3661
1648.38	76.9408
1651.44	76.9404
1654.5	76.1393
1657.56	75.5996
1660.62	74.8006
1663.68	73.5044
1666.74	70.9139
1669.8	68.2417
1672.85	64.7299
1675.91	58.8788
1678.96	52.964
1682.01	49.6126
1685.06	44.4889
1688.11	40.2466
1691.16	35.4307
1694.21	30.8136
1697.25	27.9575
1700.3	24.799
1703.34	22.361
1706.39	20.3212
1709.43	17.5946
1712.47	16.3682
1715.51	14.9337
1718.54	14.1713
1721.58	12.0236
1724.62	11.6591
1727.65	9.99794
1730.68	10.6142
1733.72	9.90068
1736.75	9.56358
1739.78	8.93269
1742.81	8.16994
1745.84	7.81644
1748.86	6.91634
1751.89	6.16478
1754.91	6.24514
1757.93	5.1813
1760.96	5.0628
1763.98	4.40417
1767	4.20229
1770.02	3.54292
1773.03	2.90784
1776.05	3.41075
1779.07	2.90273
1782.08	2.16482
1785.09	1.40319
1788.11	1.73978
1791.12	1.62885
1794.13	0.843747
1797.13	1.08249
1800.14	0.94493
1803.15	0.924056
1806.15	0.657291
1809.16	-0.673578
1812.16	-0.839137
1815.16	-0.594727
1818.16	-0.371567
1821.16	-0.833251
1824.16	-0.424617
1827.16	-0.566302
1830.16	-0.800839
1833.15	0.0535542
1836.14	0.217283
1839.14	0.10282
1842.13	0.260981
1845.12	0.704639
1848.11	1.40671
1851.1	1.93694
1854.08	2.03136
1857.07	2.08196
1860.05	2.25175
1863.04	2.61374
1866.02	2.2737
1869	3.62732
1871.98	3.69907
1874.96	3.5495
1877.94	3.87384
1880.92	3.70364
1882.51	3.59087
1885.5	3.89019
1888.48	3.65256
1891.47	3.544
1894.46	3.67012
1897.44	2.73061
1900.42	2.89622
1903.41	3.53408
1906.39	3.21648
1909.37	2.89287
1912.35	3.52805
1915.32	3.73233
1918.3	3.34763
1921.27	2.92857
1924.25	3.16687
1927.22	1.9884
1930.19	2.27029
1933.17	2.85669
1936.14	3.28112
1939.11	3.56362
1942.07	4.43157
1945.04	4.90341
1948.01	4.64893
1950.97	4.8103
1953.93	4.9988
1956.9	5.26393
1959.86	4.95227
1962.82	5.38136
1965.78	4.54247
1968.74	4.50249
1971.69	4.58088
1974.65	5.63214
1977.6	4.01328
1980.56	3.29998
1983.51	3.27287
1986.46	3.03019
1989.41	1.13079
1992.36	0.531503
1995.31	0.70383
1998.26	1.05205
2001.2	0.906786
2004.15	0.181096
2007.09	0.643516
2010.04	0.91872
2012.98	1.11345
2015.92	1.93936
2018.86	2.03806
2021.8	1.98373
2024.73	1.84803
2027.67	2.54753
2030.61	2.27385
2033.54	3.763
2036.47	3.7283
2039.4	4.23867
2042.33	5.59075
2045.27	6.3745
2048.19	6.62332
2051.12	6.69224
2054.05	6.91093
2056.97	7.31606
2059.9	6.9849
2062.82	7.52146
2065.74	8.75273
2068.67	8.94446
2071.59	8.9757
2074.51	8.86127
2077.42	9.49694
2080.34	10.8499
2083.26	11.0555
2086.17	11.6056
2089.09	13.7783
2092	14.3512
2094.91	15.4842
2097.82	17.0777
2100.73	18.3983
2103.64	20.1616
2106.55	22.7544
2109.45	24.3765
2112.36	26.76
2115.26	28.6656
2118.17	30.0401
2121.07	31.0694
2123.97	33.8295
2126.87	36.2545
2129.77	39.2978
2132.67	41.8855
2135.56	43.9782
2138.46	47.5246
2141.35	49.5247
2144.25	50.6997
2147.14	53.133
2150.03	56.6066
2152.92	58.8281
2155.81	60.8831
2158.7	64.1359
2161.59	66.2985
2164.47	66.9641
2167.36	67.5698
2170.24	68.3405
2173.13	69.0773
2176.01	69.3559
2178.89	69.2284
2181.77	68.4788
2184.65	66.9997
2187.53	64.9501
2190.4	63.0919
2193.28	61.3495
2196.16	59.7819
2199.03	58.2397
2201.9	55.7764
2204.77	52.713
2207.64	50.1001
2210.51	46.9224
2213.38	43.1169
2216.25	41.4504
2219.12	39.3704
2221.98	36.8036
2224.85	35.587
2227.71	33.7342
2230.57	31.9393
2233.43	29.8383
2236.29	27.5155
2239.15	26.2891
2242.01	25.0971
2244.87	23.4422
2247.72	22.6183
2250.58	21.3966
2253.43	19.3544
2256.29	18.5114
2259.14	18.4383
2261.99	17.6559
2264.84	16.0749
2267.69	16.2216
2270.53	15.4098
2273.38	14.8824
2276.23	13.593
2279.07	12.6456
2281.91	12.0038
2284.76	11.7153
2287.6	11.1872
2290.44	10.1223
2293.28	9.39146
2296.12	8.77792
2298.96	9.08349
2301.79	9.2173
2304.63	8.77826
2307.46	8.80092
2310.3	8.67694
2313.13	8.92719
2315.96	8.98878
2318.79	9.04638
2321.62	7.38671
2324.45	8.16124
2327.27	8.00633
2330.1	7.3681
2332.92	5.85274
2335.75	6.19036
2338.57	5.38129
2341.39	4.68183
2344.21	4.09679
2347.04	2.23132
2349.85	1.90866
2352.67	1.43411
2355.49	0.813066
2358.3	0.181084
2361.12	-0.242438
2363.93	0.297385
2366.75	0.202178
2369.56	-0.171265
2372.37	-0.330232
2375.18	-0.143934
2377.99	1.29911
2380.8	2.58645
2383.6	2.73934
2386.41	2.76727
2389.21	2.96523
2392.02	4.11607
2394.82	4.12464
2397.62	4.18445
2400.42	4.78382
2403.22	5.92294
2406.02	6.86822
2408.82	6.94926
2411.62	7.50425
2414.41	7.94607
2417.21	8.30295
2420	8.98311
2422.79	9.39777
2425.59	9.27158
2428.38	8.79118
2431.17	8.24823
2433.95	7.96641
2436.74	7.66904
2439.53	8.05467
2442.31	8.57752
2445.1	9.82922
2447.88	10.2325
2450.67	10.1032
2453.45	9.41815
2456.23	9.61186
2459.01	9.50901
2461.79	7.91741
2464.57	8.39014
2467.34	7.77274
2470.12	7.27891
2472.89	7.41833
2475.67	6.86384
2478.44	6.88579
2481.21	6.13218
2483.98	6.84895
2486.75	7.27099
2489.52	7.18403
2492.29	6.27624
2495.05	5.44392
2497.82	5.00629
2500.58	4.64729
2503.35	5.05981
2506.11	4.82495
2508.87	4.92001
2511.63	5.51172
2514.39	5.96061
2517.15	5.84013
2519.91	5.44306
2522.67	4.85408
2525.42	4.23995
2528.18	2.86139
2530.93	3.16211
2533.69	2.23025
2536.44	2.61815
2539.19	3.62554
2541.94	4.41613
2544.69	4.60261
2547.44	5.03253
2550.18	5.70268
2552.93	6.99424
2555.67	6.41636
2558.42	6.65015
2561.16	7.15193
2563.9	7.79533
2566.64	8.51108
2569.38	8.88032
2572.12	9.38621
2574.86	9.29703
2577.6	9.71053
2580.33	10.1709
2583.07	10.1819
2585.8	10.7124
2588.54	9.59169
2591.27	8.30784
2594	7.76649
2596.73	7.7923
2599.46	7.73264
2602.19	7.11541
2604.92	7.60528
2607.64	7.91686
2610.37	7.10028
2613.09	6.12268
2615.82	6.82386
2618.54	7.43122
2621.26	8.06754
2623.98	8.38911
2626.7	8.67739
2629.42	8.69539
2632.14	8.75273
2634.86	8.92031
2637.57	8.24434
2640.29	8.19707
2643	7.92032
2645.71	7.43486
2648.43	8.47861
2651.14	7.92265
2653.85	6.36945
2656.56	5.60094
2659.26	5.80684
2661.97	5.72366
2664.68	5.81263
2667.38	5.4271
2670.09	6.15231
2672.79	6.13028
2675.49	6.05905
2678.19	6.85547
2680.89	7.73598
2683.59	8.26763
2686.29	9.21058
2688.99	9.73795
2691.69	10.0243
2694.38	10.1489
2697.08	9.89864
2699.77	10.076
2702.46	9.6332
2705.15	9.70495
2707.85	9.67128
2710.54	8.79906
2713.22	9.43051
2715.91	8.79818
2718.6	7.98859
2721.29	7.19101
2723.97	6.66019
2726.66	6.57038
2729.34	5.9178
2732.02	5.44377
2734.7	5.20675
2737.38	5.14437
2740.06	5.15738
2742.74	5.45441
2745.42	4.79431
2748.09	5.05715
2750.77	5.72097
2753.45	5.75104
2756.12	5.25508
2758.79	4.29343
2761.46	3.6023
2764.14	3.13823
2766.8	2.84312
2769.47	2.20849
2772.14	2.76932
2774.81	2.36451
2777.48	2.43657
2780.14	3.44799
2782.8	2.64171
2785.47	2.44004
2788.13	1.91869
2790.79	1.50648
2793.45	1.47986
2796.11	0.950329
2798.77	1.20384
2801.43	1.4252
2804.09	2.06945
2806.74	0.712361
2809.4	0.766961
2812.05	-0.123705
2814.71	-0.492411
2817.36	0.009515
2820.01	0.817624
2822.66	1.2142
2825.31	2.79102
2827.96	4.25659
2830.6	6.29719
2833.25	9.41517
2835.9	12.6033
2838.54	17.4131
2841.18	21.6254
2843.83	27.0206
2846.47	32.105
2849.11	37.5003
2851.75	44.5496
2854.39	49.8146
2857.03	55.5153
2859.66	61.1869
2862.3	66.4615
2864.94	72.0134
2867.57	75.8853
2870.2	78.6503
2872.84	81.7922
2875.47	86.1461
2878.1	88.8824
2880.73	91.9376
2883.36	95.0931
2885.99	96.9291
2888.61	100.264
2891.24	103.788
2893.86	108.179
2896.49	113.062
2899.11	119.603
2901.73	126.279
2904.36	133.831
2906.98	142.464
2909.6	151.603
2912.21	159.949
2914.83	170.386
2917.45	178.493
2920.07	185.961
2922.68	192.783
2925.29	198.952
2927.91	203.673
2930.52	205.885
2933.13	207.033
2935.74	206.641
2938.35	204.377
2940.96	200.677
2943.57	194.991
2946.18	187.429
2948.78	181.509
2951.39	173.556
2953.99	166.502
2956.59	158.371
2959.2	150.734
2961.8	142.538
2964.4	135.334
2967	127.471
2969.6	119.254
2972.19	112.043
2974.79	104.603
2977.39	97.8931
2979.98	91.6964
2982.58	84.1766
2985.17	76.4773
2987.76	69.0877
2990.35	62.4769
2992.94	55.2744
2995.53	48.7816
2998.12	43.0134
3000.71	36.8354
3003.3	30.9427
3005.88	26.338
3008.47	21.0178
3011.05	17.646
3013.64	14.7623
3016.22	10.6637
3018.8	9.02062
3021.38	7.45986
3023.96	6.49216
3026.54	5.59709
3029.12	5.41309
3031.69	4.97823
3034.27	5.26646
3036.84	6.12397
3039.42	6.8191
3041.99	7.79588
3044.57	8.13035
3047.14	8.0692
3049.71	8.50892
3052.28	9.86813
3054.85	10.0398
3057.41	10.336
3059.98	10.6173
3062.55	10.1334
3065.11	8.9357
3067.68	7.70749
3070.24	6.37432
3072.8	5.05093
3075.36	3.89884
3077.93	3.26853
3080.49	2.65643
3083.04	2.08588
3085.6	1.8836
3088.16	2.02253
3090.72	2.48595
3093.27	3.67831
3095.83	4.28771
3098.38	4.87977
3100.93	6.05382
3103.49	6.54843
3106.04	9.00535
3108.59	9.44577
3111.14	10.6327
3113.69	11.4802
3116.23	12.0417
3118.78	12.9768
3121.33	14.172
3123.87	14.9164
3126.41	15.5821
3128.96	16.135
3131.5	17.534
3134.04	18.7894
3136.58	20.7645
3139.12	22.7596
3141.66	24.7639
3144.2	27.689
3146.74	32.0957
3149.27	35.5908