File: data/Raman/poly_smoothed/Mb_30_27_19_1x_45s_532 nm_x100_100%_600 gr_mm_01.txt
#Acq. time (s)=	45
#Accumulations=	2
#Range (cm-¹)=	200...3150
#Windows=	2
#Auto scanning=	Off
#Autofocus=	Off
#Macrospot=	Off
#AutoExposure=	Off
#Spike filter=	Multiple accum.
#Delay time (s)=	0
#Binning=	1
#Readout mode=	Signal
#DeNoise=	Off
#ICS correction=	On
#Dark correction=	Off
#Inst. Process=	Off
#Detector Gain=	Best Dynamic Range
#Detector ADC=	20 kHz
#Detector temperature (°C)=	-69.85
#Instrument=	LabRAM HR Evol
#Detector=	Synapse
#Objective=	x100
#Grating=	600 gr/mm
#ND Filter=	100%
#Laser (nm)=	532
#Hole=	100.021
#Range=	Auto
#Laser Pol.=	No
#Raman. Pol.=	No
#Laser Pol. (°)=	-0.0007625
#Raman Pol. (°)=	89.9995
#Collection=	Microscope
#StageXY=	Marzhauser
#StageZ=	Marzhauser
#X (µm)=	-6398.7
#Y (µm)=	870.2
#Z (µm)=	-64.4
#Full time(mm:ss)=	3:19
#Project=
#Sample=
#Site=
#Title=	Mb_30_27_19_2x_45s_532 nm_x100_100%_600 gr_mm
#Remark=
#Date=	13.07.2022 10:02
#Acquired=	13.07.2022 10:02:58
#Base:Fit=	10.08.2022 10:40:03
#Base:Sub=	10.08.2022 10:40:17
#Filter:Polynom=	16.08.2022 10:16:15
#AxisType[0]=Intens
#AxisUnit[0]=Cnt
#AxisType[1]=Spectr
#AxisUnit[1]=1/cm
200.563	30.0723
204.194	34.7449
207.821	37.0827
211.449	37.5564
215.074	37.4918
218.699	37.6001
222.321	37.4616
225.941	35.0679
229.562	33.7175
233.18	29.8799
236.796	27.9894
240.411	24.9949
244.026	23.7182
247.638	21.7094
251.248	20.2382
254.857	19.5636
258.465	18.3211
262.071	14.3527
265.678	13.527
269.282	12.5518
272.884	9.31367
276.484	9.78259
280.084	9.76884
283.682	8.72601
287.276	7.91151
290.871	7.42324
294.465	6.44712
298.057	6.23961
301.648	6.74887
305.237	6.32145
308.823	6.97163
312.41	4.65147
315.995	3.34599
319.579	2.48461
323.16	2.75059
326.741	2.73514
330.321	4.76428
333.897	6.09463
337.474	5.49567
341.048	7.59376
344.622	7.32485
348.192	6.61835
351.764	5.79892
355.332	4.93895
358.901	4.52002
362.466	4.08566
366.03	4.20702
369.594	5.42825
373.155	5.94571
376.715	5.57213
380.273	5.09351
383.832	5.44507
387.388	6.30389
390.942	6.98546
394.495	6.77807
398.047	6.32078
401.597	6.2376
405.145	7.41113
408.693	7.2221
412.239	6.4224
415.783	7.14773
419.327	7.16737
422.869	6.8133
426.409	6.64478
429.948	7.36736
433.486	7.25087
437.022	5.83909
440.558	4.39277
444.089	4.55076
447.622	5.67573
451.153	5.44721
454.682	6.10974
458.208	7.07255
461.735	6.85498
465.259	8.18369
468.783	9.85207
472.306	12.1365
475.825	14.0953
479.346	15.6011
482.862	18.3721
486.38	19.3129
489.894	20.6561
493.407	21.6468
496.92	22.349
500.43	23.1472
503.939	24.2762
507.448	23.888
510.954	25.6693
514.459	25.2147
517.962	28.0853
521.466	27.9313
524.966	26.912
528.466	28.4464
531.964	26.8943
535.46	26.5922
538.955	25.8074
542.449	23.9558
545.942	22.1594
549.433	20.2423
552.923	19.3844
556.412	17.4766
559.899	15.8652
563.385	13.5611
566.867	12.2417
570.35	9.67575
573.832	8.57789
577.313	6.48249
580.79	6.19819
584.268	4.58241
587.745	3.98705
591.218	2.31636
594.692	1.80165
598.164	2.63707
601.634	3.45676
605.104	5.49562
608.57	5.51103
612.037	5.37381
615.501	6.06809
618.966	6.11604
622.427	8.15666
625.887	9.10724
629.348	8.40638
632.806	9.21061
636.262	9.89192
639.716	11.1685
643.172	11.9052
646.624	13.1475
650.075	15.0183
653.524	17.1352
656.972	17.9757
660.419	19.6565
663.865	21.9805
667.309	23.3233
670.752	24.1824
674.194	25.9225
677.634	27.9276
681.073	30.4928
684.511	33.6984
687.947	36.4413
691.382	38.2636
694.816	40.2674
698.247	42.3656
701.678	44.5212
705.108	45.9799
708.534	46.1921
711.962	47.6542
715.388	48.1358
718.81	48.4579
722.234	49.7571
725.654	50.1573
729.075	51.0522
732.492	51.4604
735.91	52.0926
739.325	50.844
742.741	51.512
746.153	51.6787
749.564	53.6075
752.976	56.6616
756.385	57.4762
759.792	60.8688
763.2	64.7672
766.604	67.776
770.008	69.4482
773.41	71.9152
776.811	73.8342
780.21	77.6061
783.608	78.3284
787.005	79.1372
790.401	81.234
793.795	83.3068
797.188	85.6654
800.58	87.293
803.971	89.4226
807.36	90.4714
810.748	89.8035
814.135	88.216
817.518	88.5099
820.902	88.7757
824.285	88.3652
827.665	86.6944
831.045	84.6133
834.424	82.4755
837.8	79.765
841.177	78.0021
844.55	75.3064
847.924	72.5131
851.295	68.0402
854.666	65.0714
858.034	61.7306
861.403	59.2728
864.769	56.7435
868.133	56.0702
871.498	53.7043
874.86	52.338
878.221	51.2468
881.58	50.8784
884.938	51.0768
888.297	50.7074
891.653	50.2549
895.007	50.5941
898.36	53.0058
901.712	54.0623
905.063	53.6411
908.412	52.8772
911.76	53.0273
915.107	52.5126
918.452	51.5548
921.797	50.1738
925.138	49.5918
928.48	49.5647
931.82	48.7061
935.16	48.1634
938.496	46.6641
941.833	45.0871
945.168	44.2578
948.5	42.9278
951.834	41.2535
955.163	39.9524
958.494	38.6506
961.821	37.7487
965.15	38.6753
968.474	38.825
971.8	37.6554
975.123	38.492
978.446	38.6897
981.766	38.2323
985.084	36.8742
988.402	36.6726
991.72	34.3975
995.035	34.2178
998.349	33.0999
1001.66	30.3831
1004.97	29.932
1008.28	34.2437
1011.59	38.5619
1014.9	44.0731
1018.21	50.206
1021.51	54.7009
1024.81	57.3554
1028.12	60.7293
1031.42	63.8062
1034.72	64.9617
1038.02	66.0824
1041.31	64.3797
1044.61	65.1095
1047.91	64.8262
1051.2	63.0056
1054.49	59.4673
1057.78	54.597
1061.07	49.459
1064.36	44.358
1067.65	39.2149
1070.93	34.6615
1074.22	27.7075
1077.5	23.2027
1080.78	18.9747
1084.06	17.2193
1087.34	19.038
1090.62	21.1156
1093.9	22.5615
1097.17	21.9604
1100.45	24.0002
1103.72	24.0393
1106.99	23.9329
1110.27	23.5559
1113.53	22.818
1116.8	23.4272
1120.07	22.8197
1123.33	23.6208
1126.6	23.4443
1129.86	21.8398
1133.12	19.1793
1136.38	17.2693
1139.64	16.2668
1142.9	15.7516
1146.16	12.8092
1149.41	10.9876
1152.67	9.31674
1155.92	7.11553
1159.17	5.72644
1162.42	4.38817
1165.67	2.91424
1168.92	0.858683
1172.16	1.57509
1175.41	2.37135
1178.65	3.5498
1181.9	3.90017
1185.14	4.68884
1188.38	5.23285
1191.62	6.98637
1194.86	9.48124
1198.09	10.9645
1201.33	12.7581
1204.56	16.8751
1207.8	19.1443
1211.03	20.6741
1214.26	22.687
1217.49	26.9865
1220.71	29.8934
1223.94	31.9419
1227.16	35.6537
1230.39	39.1011
1233.61	42.9077
1236.83	45.8234
1240.05	48.6358
1243.27	51.6118
1246.49	52.6921
1249.71	54.548
1252.92	56.4393
1256.14	57.5278
1259.35	58.3041
1262.56	59.5173
1265.77	61.3344
1268.98	62.0836
1272.19	61.9203
1275.4	62.2911
1278.6	62.4017
1281.81	63.2939
1285.01	63.2065
1288.21	61.578
1291.41	61.9858
1294.61	62.8377
1297.81	64.3918
1301.01	64.4046
1304.2	64.4533
1307.4	64.2362
1310.59	66.307
1313.78	66.7101
1316.97	67.1476
1320.16	68.0034
1323.35	67.2543
1326.54	68.4822
1329.72	68.6189
1332.91	69.0547
1336.09	69.893
1339.27	68.6177
1342.45	68.5069
1345.64	67.7418
1348.81	64.5125
1351.99	62.7104
1355.17	61.828
1358.34	58.0459
1361.51	55.807
1364.69	52.8558
1367.86	50.5608
1371.03	47.3519
1374.2	44.6319
1377.37	43.0553
1380.53	39.764
1383.7	38.2107
1386.86	38.3881
1390.02	39.3633
1393.19	38.4488
1396.35	36.5211
1399.51	37.5374
1402.66	36.7813
1405.82	36.9338
1408.97	38.0019
1412.13	39.2247
1415.28	39.1904
1418.43	40.9901
1421.59	44.8178
1424.73	48.2132
1427.88	54.1521
1431.03	58.8543
1434.18	63.2754
1437.32	65.277
1440.46	68.9325
1443.61	70.5269
1446.75	72.8249
1449.89	75.9856
1453.03	77.6019
1456.16	79.8225
1459.3	79.2464
1462.44	78.9515
1465.57	78.0203
1468.7	75.7664
1471.83	73.1393
1474.96	68.4503
1478.09	65.3925
1481.22	60.0105
1484.35	56.168
1487.47	52.74
1490.6	49.7546
1493.72	47.4341
1496.84	44.5453
1499.96	42.8873
1503.08	41.6196
1506.2	38.3577
1509.32	35.7816
1512.44	31.8794
1515.55	28.4999
1518.66	26.9103
1521.78	25.2062
1524.89	25.0106
1528	23.5813
1531.11	24.1263
1534.21	24.9997
1537.32	25.1888
1540.43	26.2217
1543.53	26.7763
1546.63	28.52
1549.74	29.9091
1552.84	30.0406
1555.94	31.9559
1559.03	33.6277
1562.13	34.9159
1565.23	36.7838
1568.32	37.6235
1571.42	40.1314
1574.51	42.1953
1577.6	45.1653
1580.69	47.3025
1583.78	48.4935
1586.87	49.8642
1589.95	51.1845
1593.04	53.1001
1596.12	54.5948
1599.21	55.4829
1602.29	55.7008
1605.37	57.1785
1608.45	59.412
1611.53	61.3756
1614.6	62.8329
1617.68	64.9941
1620.75	67.0621
1623.83	69.0205
1626.9	70.8545
1629.97	73.539
1633.04	76.6992
1636.11	79.2454
1639.18	81.187
1642.25	83.9053
1645.31	86.9143
1648.38	90.161
1651.44	92.6055
1654.5	93.3189
1657.56	92.9932
1660.62	91.5568
1663.68	91.1667
1666.74	87.2066
1669.8	82.2335
1672.85	77.3607
1675.91	72.2827
1678.96	67.2124
1682.01	61.6323
1685.06	54.3925
1688.11	49.0652
1691.16	43.5598
1694.21	38.3826
1697.25	34.3911
1700.3	30.5753
1703.34	27.346
1706.39	24.4351
1709.43	22.2382
1712.47	18.9022
1715.51	16.1314
1718.54	14.5844
1721.58	13.8836
1724.62	13.5398
1727.65	13.6346
1730.68	11.7476
1733.72	10.9045
1736.75	10.721
1739.78	9.98988
1742.81	8.68224
1745.84	6.37861
1748.86	5.84431
1751.89	5.21651
1754.91	3.90239
1757.93	3.1111
1760.96	2.64611
1763.98	2.7138
1767	3.25956
1770.02	2.66165
1773.03	2.29356
1776.05	1.96418
1779.07	1.36922
1782.08	1.46509
1785.09	0.586205
1788.11	-0.363214
1791.12	-0.226814
1794.13	0.0233283
1797.13	0.722209
1800.14	-0.0248113
1803.15	-0.364978
1806.15	0.560349
1809.16	0.643917
1812.16	0.904745
1815.16	1.10281
1818.16	0.523827
1821.16	0.0905163
1824.16	0.0838082
1827.16	0.644322
1830.16	0.837036
1833.15	1.44689
1836.14	2.3674
1839.14	2.77491
1842.13	2.49246
1845.12	1.96171
1848.11	2.6649
1851.1	3.70049
1854.08	4.6649
1857.07	6.11396
1860.05	6.89036
1863.04	6.75702
1866.02	6.94431
1869	7.39851
1871.98	8.06234
1874.96	8.46407
1877.94	8.68976
1880.92	9.04027
1882.51	8.57365
1885.5	8.39562
1888.48	7.37083
1891.47	6.92943
1894.46	5.37343
1897.44	4.73914
1900.42	4.18072
1903.41	3.8551
1906.39	3.45432
1909.37	2.52772
1912.35	1.84348
1915.32	1.64326
1918.3	2.0885
1921.27	4.41736
1924.25	5.55817
1927.22	5.67398
1930.19	5.76651
1933.17	6.1297
1936.14	6.13908
1939.11	6.16279
1942.07	6.00349
1945.04	6.92399
1948.01	7.66264
1950.97	8.25931
1953.93	8.37511
1956.9	8.61259
1959.86	9.15813
1962.82	8.54742
1965.78	8.34564
1968.74	7.35196
1971.69	7.33537
1974.65	6.30345
1977.6	4.3305
1980.56	4.61527
1983.51	3.86331
1986.46	4.86111
1989.41	5.46237
1992.36	6.34644
1995.31	6.24247
1998.26	5.93059
2001.2	5.71973
2004.15	5.9649
2007.09	5.88694
2010.04	6.39393
2012.98	6.1646
2015.92	6.99513
2018.86	8.23807
2021.8	8.30031
2024.73	8.62069
2027.67	9.30276
2030.61	10.2086
2033.54	10.0723
2036.47	10.6574
2039.4	11.5505
2042.33	11.1812
2045.27	11.8134
2048.19	10.9025
2051.12	12.3234
2054.05	13.0789
2056.97	13.4987
2059.9	13.6504
2062.82	12.1228
2065.74	13.4507
2068.67	13.1624
2071.59	13.3276
2074.51	14.6739
2077.42	14.8508
2080.34	15.4936
2083.26	17.2854
2086.17	17.0728
2089.09	18.4777
2092	20.7519
2094.91	21.9371
2097.82	23.9771
2100.73	25.9734
2103.64	27.7856
2106.55	30.1776
2109.45	33.5405
2112.36	36.4552
2115.26	39.6518
2118.17	42.8599
2121.07	45.798
2123.97	48.7215
2126.87	51.0519
2129.77	54.6526
2132.67	57.5963
2135.56	61.7566
2138.46	65.4775
2141.35	69.2777
2144.25	73.9293
2147.14	78.3311
2150.03	81.5411
2152.92	84.7531
2155.81	88.0063
2158.7	90.6216
2161.59	94.133
2164.47	96.5056
2167.36	97.1742
2170.24	96.658
2173.13	96.0952
2176.01	95.7741
2178.89	94.5244
2181.77	93.9034
2184.65	91.7571
2187.53	90.03
2190.4	87.3605
2193.28	83.6414
2196.16	79.838
2199.03	78.0331
2201.9	74.5687
2204.77	70.1257
2207.64	67.5541
2210.51	64.4155
2213.38	61.5095
2216.25	57.4744
2219.12	53.2886
2221.98	50.6996
2224.85	48.6033
2227.71	45.4778
2230.57	43.4451
2233.43	39.6684
2236.29	36.5285
2239.15	32.8003
2242.01	30.4772
2244.87	29.2389
2247.72	27.9796
2250.58	26.4419
2253.43	25.7303
2256.29	25.0484
2259.14	24.471
2261.99	23.3728
2264.84	22.2717
2267.69	22.3573
2270.53	22.0532
2273.38	20.5331
2276.23	18.8235
2279.07	18.1256
2281.91	16.763
2284.76	15.8759
2287.6	14.7449
2290.44	12.9071
2293.28	11.1591
2296.12	10.2726
2298.96	9.79622
2301.79	8.52356
2304.63	8.99337
2307.46	9.0242
2310.3	8.38149
2313.13	9.66444
2315.96	8.66093
2318.79	8.32757
2321.62	7.8008
2324.45	8.69182
2327.27	9.12349
2330.1	9.25127
2332.92	8.63576
2335.75	8.71391
2338.57	7.36016
2341.39	6.90844
2344.21	4.80488
2347.04	3.67046
2349.85	3.26169
2352.67	3.91665
2355.49	2.77558
2358.3	1.09186
2361.12	0.869065
2363.93	1.79735
2366.75	2.30142
2369.56	1.66713
2372.37	1.80893
2375.18	1.70683
2377.99	1.54892
2380.8	0.977085
2383.6	0.553467
2386.41	1.19925
2389.21	1.50223
2392.02	1.41738
2394.82	2.26499
2397.62	2.82452
2400.42	2.94297
2403.22	2.80408
2406.02	2.53587
2408.82	1.94524
2411.62	2.88347
2414.41	2.59321
2417.21	2.72717
2420	4.46926
2422.79	3.61325
2425.59	3.41533
2428.38	3.3289
2431.17	3.31745
2433.95	3.37076
2436.74	2.08861
2439.53	2.51133
2442.31	2.25962
2445.1	3.19704
2447.88	3.17601
2450.67	3.03287
2453.45	3.30171
2456.23	3.17377
2459.01	2.78331
2461.79	2.80379
2464.57	3.14843
2467.34	3.65525
2470.12	3.52206
2472.89	3.38212
2475.67	2.70604
2478.44	3.30056
2481.21	2.68572
2483.98	1.7507
2486.75	1.67004
2489.52	1.90424
2492.29	0.810068
2495.05	0.706504
2497.82	0.537746
2500.58	0.269478
2503.35	0.526394
2506.11	0.887594
2508.87	1.57434
2511.63	1.57119
2514.39	2.56737
2517.15	1.99904
2519.91	1.28454
2522.67	2.00032
2525.42	1.45092
2528.18	2.93289
2530.93	3.14418
2533.69	2.50559
2536.44	1.7687
2539.19	1.61627
2541.94	1.48904
2544.69	1.00829
2547.44	1.63142
2550.18	0.913472
2552.93	0.904603
2555.67	1.16301
2558.42	1.40565
2561.16	1.67565
2563.9	2.43719
2566.64	2.66547
2569.38	2.63388
2572.12	3.13372
2574.86	3.04296
2577.6	3.04898
2580.33	3.0222
2583.07	3.3361
2585.8	3.58374
2588.54	4.68814
2591.27	5.25238
2594	5.52015
2596.73	6.03176
2599.46	5.06285
2602.19	4.84697
2604.92	5.38862
2607.64	5.75894
2610.37	5.49964
2613.09	5.88764
2615.82	4.85253
2618.54	4.31922
2621.26	4.48304
2623.98	5.33906
2626.7	5.12147
2629.42	4.98226
2632.14	4.94729
2634.86	3.94905
2637.57	3.64992
2640.29	3.48898
2643	2.96584
2645.71	3.82447
2648.43	3.3552
2651.14	3.90527
2653.85	3.83316
2656.56	4.21003
2659.26	4.44913
2661.97	4.65112
2664.68	4.21174
2667.38	4.09047
2670.09	4.24859
2672.79	5.16856
2675.49	4.44737
2678.19	5.08623
2680.89	5.51068
2683.59	6.01907
2686.29	6.675
2688.99	7.3391
2691.69	8.10176
2694.38	9.12788
2697.08	10.1103
2699.77	10.3608
2702.46	10.7229
2705.15	11.1146
2707.85	11.1674
2710.54	11.4696
2713.22	10.9354
2715.91	11.2624
2718.6	11.0642
2721.29	11.607
2723.97	11.1324
2726.66	11.2152
2729.34	10.4943
2732.02	10.0019
2734.7	10.9992
2737.38	10.6331
2740.06	10.5666
2742.74	10.7659
2745.42	10.7085
2748.09	10.4833
2750.77	10.6662
2753.45	10.1497
2756.12	10.4321
2758.79	10.5894
2761.46	9.38605
2764.14	8.74694
2766.8	7.63302
2769.47	5.86706
2772.14	4.39251
2774.81	4.12979
2777.48	2.60271
2780.14	2.0865
2782.8	1.58462
2785.47	0.922618
2788.13	0.844298
2790.79	-0.846245
2793.45	-0.964454
2796.11	-1.14126
2798.77	-1.0809
2801.43	-0.301388
2804.09	-1.15123
2806.74	-1.05602
2809.4	-0.323866
2812.05	0.179461
2814.71	1.24259
2817.36	3.20208
2820.01	5.59897
2822.66	8.9663
2825.31	12.2476
2827.96	16.2507
2830.6	19.4969
2833.25	23.2249
2835.9	28.6855
2838.54	33.3282
2841.18	38.3844
2843.83	45.8007
2846.47	53.5314
2849.11	62.0968
2851.75	71.9837
2854.39	81.2429
2857.03	89.9308
2859.66	99.4483
2862.3	108.472
2864.94	117.328
2867.57	122.956
2870.2	128.46
2872.84	135.342
2875.47	140.626
2878.1	146.255
2880.73	152.055
2883.36	157.679
2885.99	163.312
2888.61	168.643
2891.24	175.022
2893.86	180.944
2896.49	186.86
2899.11	194.78
2901.73	203.317
2904.36	213.363
2906.98	225.944
2909.6	238.366
2912.21	252.357
2914.83	265.599
2917.45	278.588
2920.07	289.277
2922.68	298.621
2925.29	306.716
2927.91	311.186
2930.52	313.148
2933.13	313.03
2935.74	310.451
2938.35	306.403
2940.96	299.325
2943.57	291.587
2946.18	282.28
2948.78	271.304
2951.39	259.209
2953.99	247.016
2956.59	234.58
2959.2	220.73
2961.8	208.039
2964.4	195.372
2967	183.142
2969.6	171.876
2972.19	161.414
2974.79	150.854
2977.39	140.955
2979.98	130.571
2982.58	120.033
2985.17	110.379
2987.76	100.366
2990.35	90.9202
2992.94	82.1114
2995.53	72.779
2998.12	64.1139
3000.71	55.46
3003.3	48.5936
3005.88	40.5375
3008.47	34.6655
3011.05	28.7456
3013.64	23.7785
3016.22	18.9864
3018.8	16.3654
3021.38	13.6186
3023.96	11.8518
3026.54	9.55556
3029.12	8.73849
3031.69	8.34803
3034.27	8.25794
3036.84	8.75678
3039.42	9.68458
3041.99	10.4642
3044.57	10.1884
3047.14	11.9011
3049.71	12.8398
3052.28	13.6601
3054.85	14.5522
3057.41	14.3619
3059.98	14.0044
3062.55	12.921
3065.11	12.4697
3067.68	11.2686
3070.24	10.3205
3072.8	9.06219
3075.36	6.95941
3077.93	5.94375
3080.49	5.60279
3083.04	3.5761
3085.6	2.07473
3088.16	0.468074
3090.72	-0.412473
3093.27	-0.451486
3095.83	-0.790386
3098.38	-0.0373812
3100.93	0.255677
3103.49	0.826596
3106.04	1.84966
3108.59	3.17219
3111.14	4.04132
3113.69	5.56268
3116.23	6.96481
3118.78	7.76145
3121.33	9.20912
3123.87	10.5757
3126.41	12.1808
3128.96	14.0972
3131.5	14.8198
3134.04	15.8799
3136.58	16.637
3139.12	17.8521
3141.66	18.363
3144.2	18.5548
3146.74	19.4351
3149.27	21.9614