File: data/Raman/poly_smoothed/Mb_30_27_42_1x_45s_532 nm_x100_100%_600 gr_mm_01.txt
#Acq. time (s)=	45
#Accumulations=	2
#Range (cm-¹)=	200...3150
#Windows=	2
#Auto scanning=	Off
#Autofocus=	Off
#Macrospot=	Off
#AutoExposure=	Off
#Spike filter=	Multiple accum.
#Delay time (s)=	0
#Binning=	1
#Readout mode=	Signal
#DeNoise=	Off
#ICS correction=	On
#Dark correction=	Off
#Inst. Process=	Off
#Detector Gain=	Best Dynamic Range
#Detector ADC=	20 kHz
#Detector temperature (°C)=	-69.85
#Instrument=	LabRAM HR Evol
#Detector=	Synapse
#Objective=	x100
#Grating=	600 gr/mm
#ND Filter=	100%
#Laser (nm)=	532
#Hole=	100.021
#Range=	Auto
#Laser Pol.=	No
#Raman. Pol.=	No
#Laser Pol. (°)=	-0.0007625
#Raman Pol. (°)=	89.9995
#Collection=	Microscope
#StageXY=	Marzhauser
#StageZ=	Marzhauser
#X (µm)=	-6350.2
#Y (µm)=	792.6
#Z (µm)=	-64.95
#Full time(mm:ss)=	3:18
#Project=
#Sample=
#Site=
#Title=	Mb_30_27_42_2x_45s_532 nm_x100_100%_600 gr_mm
#Remark=
#Date=	13.07.2022 11:57
#Acquired=	13.07.2022 11:57:32
#Base:Fit=	10.08.2022 10:40:03
#Base:Sub=	10.08.2022 10:40:17
#Filter:Polynom=	16.08.2022 10:16:15
#AxisType[0]=Intens
#AxisUnit[0]=Cnt
#AxisType[1]=Spectr
#AxisUnit[1]=1/cm
200.563	65.6737
204.194	53.2941
207.821	42.1727
211.449	33.7227
215.074	25.2056
218.699	19.2727
222.321	14.0779
225.941	11.388
229.562	9.08475
233.18	5.90546
236.796	6.31179
240.411	7.33592
244.026	5.36954
247.638	5.10401
251.248	6.12416
254.857	5.58545
258.465	6.9103
262.071	7.57639
265.678	7.82586
269.282	7.88494
272.884	8.48097
276.484	7.52933
280.084	7.91094
283.682	6.49707
287.276	6.46535
290.871	7.84889
294.465	8.7508
298.057	10.4033
301.648	9.68051
305.237	10.0694
308.823	11.3862
312.41	14.2017
315.995	16.4625
319.579	16.9124
323.16	19.5376
326.741	22.9302
330.321	21.7452
333.897	20.0077
337.474	21.0725
341.048	21.3449
344.622	20.2877
348.192	17.3788
351.764	14.9445
355.332	13.461
358.901	9.66021
362.466	7.98694
366.03	7.10326
369.594	7.30654
373.155	4.9995
376.715	6.41492
380.273	5.8334
383.832	6.14408
387.388	4.80941
390.942	6.85191
394.495	6.59808
398.047	7.05519
401.597	8.44075
405.145	8.60932
408.693	11.6922
412.239	14.1654
415.783	15.6527
419.327	16.0849
422.869	17.2166
426.409	17.162
429.948	16.2512
433.486	15.9405
437.022	15.0816
440.558	16.1149
444.089	15.8216
447.622	15.7328
451.153	17.7019
454.682	17.3424
458.208	16.1021
461.735	16.3519
465.259	19.2468
468.783	19.2103
472.306	20.8349
475.825	20.741
479.346	21.7935
482.862	23.2844
486.38	24.3933
489.894	27.1735
493.407	32.224
496.92	35.4693
500.43	36.9668
503.939	38.2606
507.448	39.095
510.954	37.4373
514.459	37.9671
517.962	38.4894
521.466	38.6945
524.966	38.1762
528.466	37.2691
531.964	35.8852
535.46	35.8994
538.955	33.5322
542.449	32.8169
545.942	31.9261
549.433	31.33
552.923	30.4281
556.412	28.9045
559.899	29.5574
563.385	28.025
566.867	27.9124
570.35	26.2364
573.832	25.7646
577.313	24.0481
580.79	24.6036
584.268	21.4812
587.745	19.5135
591.218	15.1755
594.692	11.5792
598.164	12.3683
601.634	12.3011
605.104	12.741
608.57	13.0918
612.037	13.3911
615.501	15.3472
618.966	17.0504
622.427	18.6045
625.887	22.1263
629.348	22.975
632.806	25.963
636.262	28.3658
639.716	32.0763
643.172	34.8055
646.624	36.7544
650.075	37.5241
653.524	39.1236
656.972	39.1616
660.419	39.4791
663.865	42.918
667.309	44.3337
670.752	43.3093
674.194	43.1549
677.634	43.6591
681.073	46.3347
684.511	50.2981
687.947	50.9412
691.382	54.9255
694.816	56.5462
698.247	59.2023
701.678	61.0824
705.108	62.1112
708.534	64.2709
711.962	65.2057
715.388	66.736
718.81	65.9391
722.234	68.0121
725.654	67.1498
729.075	68.007
732.492	68.5481
735.91	68.7394
739.325	71.3438
742.741	71.8095
746.153	74.4259
749.564	76.8211
752.976	77.0306
756.385	79.2236
759.792	80.0423
763.2	83.6963
766.604	88.5052
770.008	91.1292
773.41	93.8724
776.811	96.4009
780.21	98.299
783.608	101.305
787.005	103.015
790.401	104.434
793.795	106.007
797.188	106.65
800.58	106.427
803.971	106.931
807.36	106.464
810.748	105.51
814.135	105.183
817.518	104.44
820.902	103.29
824.285	101.749
827.665	100.412
831.045	97.6413
834.424	96.1708
837.8	95.7403
841.177	94.8501
844.55	93.8475
847.924	91.6552
851.295	89.4835
854.666	86.3396
858.034	83.9308
861.403	81.6677
864.769	79.249
868.133	78.3795
871.498	74.929
874.86	75.888
878.221	74.7864
881.58	73.669
884.938	72.9945
888.297	70.3947
891.653	69.4765
895.007	68.7241
898.36	69.032
901.712	66.1465
905.063	61.936
908.412	63.5293
911.76	61.366
915.107	61.6312
918.452	62.748
921.797	63.4231
925.138	63.2675
928.48	63.614
931.82	62.9387
935.16	61.798
938.496	62.2844
941.833	61.0196
945.168	60.8724
948.5	60.3571
951.834	60.9632
955.163	62.7759
958.494	61.765
961.821	61.0684
965.15	61.4987
968.474	62.1025
971.8	63.9106
975.123	63.432
978.446	62.3831
981.766	58.4953
985.084	57.2183
988.402	56.245
991.72	53.872
995.035	51.1877
998.349	49.1587
1001.66	45.7811
1004.97	45.6322
1008.28	47.5743
1011.59	51.1884
1014.9	57.54
1018.21	66.055
1021.51	71.6149
1024.81	75.9086
1028.12	81.808
1031.42	86.0887
1034.72	89.6031
1038.02	90.3096
1041.31	90.4204
1044.61	92.6157
1047.91	92.2271
1051.2	89.3089
1054.49	85.2191
1057.78	78.1918
1061.07	72.377
1064.36	65.3444
1067.65	58.2018
1070.93	50.1409
1074.22	43.0418
1077.5	35.9738
1080.78	30.5248
1084.06	27.5927
1087.34	28.1853
1090.62	31.0677
1093.9	35.2927
1097.17	37.1457
1100.45	39.1644
1103.72	41.1629
1106.99	42.0043
1110.27	42.6161
1113.53	40.9972
1116.8	40.2243
1120.07	38.0442
1123.33	35.6909
1126.6	33.4365
1129.86	29.0264
1133.12	25.7304
1136.38	22.5995
1139.64	20.0272
1142.9	15.2405
1146.16	13.1097
1149.41	10.0975
1152.67	8.21738
1155.92	6.26052
1159.17	3.08421
1162.42	0.950839
1165.67	-1.29745
1168.92	-1.71972
1172.16	-0.0934516
1175.41	2.28795
1178.65	3.54606
1181.9	6.03091
1185.14	8.20014
1188.38	10.1686
1191.62	13.4672
1194.86	14.0193
1198.09	16.1439
1201.33	19.7932
1204.56	23.601
1207.8	30.0471
1211.03	34.191
1214.26	40.9417
1217.49	45.0559
1220.71	49.4564
1223.94	54.3246
1227.16	59.6867
1230.39	63.1887
1233.61	67.3246
1236.83	70.3726
1240.05	73.6397
1243.27	75.0786
1246.49	76.2849
1249.71	78.5833
1252.92	81.7992
1256.14	82.5088
1259.35	84.4323
1262.56	83.291
1265.77	83.8198
1268.98	83.3624
1272.19	80.567
1275.4	79.423
1278.6	81.4028
1281.81	84.109
1285.01	85.3549
1288.21	88.041
1291.41	90.35
1294.61	93.1179
1297.81	95.7104
1301.01	98.0328
1304.2	103.55
1307.4	105.941
1310.59	107.772
1313.78	108.681
1316.97	110.189
1320.16	109.48
1323.35	109.918
1326.54	110.255
1329.72	109.246
1332.91	106.867
1336.09	103.213
1339.27	98.2357
1342.45	94.0739
1345.64	91.1004
1348.81	86.5673
1351.99	81.9845
1355.17	78.0108
1358.34	74.4116
1361.51	70.225
1364.69	66.3286
1367.86	62.4347
1371.03	58.8435
1374.2	57.3555
1377.37	54.9883
1380.53	52.7124
1383.7	51.9788
1386.86	50.2784
1390.02	47.8852
1393.19	46.3741
1396.35	45.9619
1399.51	44.3061
1402.66	43.7915
1405.82	43.8491
1408.97	44.9584
1412.13	47.4057
1415.28	50.2842
1418.43	54.4125
1421.59	60.8257
1424.73	67.8612
1427.88	74.2038
1431.03	77.0942
1434.18	82.4847
1437.32	88.607
1440.46	91.8309
1443.61	94.92
1446.75	95.6821
1449.89	94.869
1453.03	95.5535
1456.16	94.7568
1459.3	93.276
1462.44	93.9114
1465.57	90.3074
1468.7	86.9236
1471.83	84.511
1474.96	80.7966
1478.09	77.5024
1481.22	72.5384
1484.35	67.7345
1487.47	63.4476
1490.6	60.4937
1493.72	56.7765
1496.84	52.8039
1499.96	48.4093
1503.08	44.9036
1506.2	40.964
1509.32	37.4366
1512.44	32.9365
1515.55	30.3407
1518.66	26.1606
1521.78	21.2098
1524.89	17.4797
1528	15.4976
1531.11	15.3148
1534.21	14.8122
1537.32	14.9916
1540.43	15.7137
1543.53	18.0061
1546.63	20.2159
1549.74	23.6253
1552.84	24.0804
1555.94	26.6434
1559.03	27.564
1562.13	30.5582
1565.23	31.9736
1568.32	36.5206
1571.42	40.1688
1574.51	43.0629
1577.6	47.1162
1580.69	51.836
1583.78	55.2685
1586.87	58.4425
1589.95	61.5101
1593.04	63.9838
1596.12	66.6033
1599.21	68.4944
1602.29	69.1728
1605.37	69.9285
1608.45	70.3403
1611.53	71.4865
1614.6	72.7584
1617.68	75.243
1620.75	76.7683
1623.83	79.4081
1626.9	80.9257
1629.97	82.6537
1633.04	85.8546
1636.11	90.8664
1639.18	95.9827
1642.25	101.908
1645.31	105.612
1648.38	109.281
1651.44	110.466
1654.5	114.292
1657.56	113.045
1660.62	112.165
1663.68	112.589
1666.74	108.341
1669.8	104.15
1672.85	98.9515
1675.91	91.1609
1678.96	83.5426
1682.01	76.783
1685.06	69.1388
1688.11	62.2625
1691.16	54.5534
1694.21	48.1778
1697.25	40.7951
1700.3	34.8546
1703.34	30.47
1706.39	27.7046
1709.43	25.4816
1712.47	23.2537
1715.51	20.9018
1718.54	18.4417
1721.58	16.7184
1724.62	15.3182
1727.65	14.5558
1730.68	13.9754
1733.72	12.687
1736.75	12.6657
1739.78	13.4056
1742.81	10.8965
1745.84	11.1487
1748.86	10.6386
1751.89	9.78487
1754.91	9.27047
1757.93	8.72105
1760.96	7.22422
1763.98	6.42202
1767	5.80667
1770.02	5.00586
1773.03	3.99107
1776.05	3.07614
1779.07	2.62978
1782.08	1.99899
1785.09	2.79067
1788.11	2.97222
1791.12	2.56046
1794.13	3.08671
1797.13	3.44545
1800.14	2.84778
1803.15	4.70579
1806.15	5.53006
1809.16	6.97779
1812.16	7.85645
1815.16	7.53971
1818.16	7.71637
1821.16	7.94315
1824.16	7.62354
1827.16	7.38182
1830.16	6.60594
1833.15	4.85406
1836.14	4.09244
1839.14	4.13071
1842.13	2.65033
1845.12	2.39406
1848.11	1.81937
1851.1	2.18355
1854.08	1.30627
1857.07	3.22601
1860.05	4.42143
1863.04	4.45379
1866.02	5.30723
1869	6.55814
1871.98	6.74553
1874.96	7.78307
1877.94	8.97002
1880.92	9.75463
1882.51	9.8357
1885.5	10.8316
1888.48	12.2727
1891.47	12.2625
1894.46	10.9745
1897.44	11.1678
1900.42	9.20881
1903.41	8.04466
1906.39	7.2738
1909.37	7.04697
1912.35	6.85678
1915.32	8.37172
1918.3	9.32416
1921.27	9.44371
1924.25	10.2213
1927.22	10.89
1930.19	11.7155
1933.17	11.629
1936.14	9.78413
1939.11	8.56821
1942.07	7.77734
1945.04	7.74915
1948.01	7.74453
1950.97	6.98992
1953.93	9.01188
1956.9	9.51741
1959.86	8.65336
1962.82	9.35045
1965.78	8.28409
1968.74	7.5751
1971.69	7.10821
1974.65	6.74033
1977.6	6.82842
1980.56	8.10253
1983.51	9.87885
1986.46	11.2191
1989.41	13.4993
1992.36	14.284
1995.31	16.0583
1998.26	18.2048
2001.2	17.9496
2004.15	17.9139
2007.09	18.4874
2010.04	17.6823
2012.98	18.2549
2015.92	17.4852
2018.86	18.3493
2021.8	17.2649
2024.73	19.0583
2027.67	19.3953
2030.61	19.0474
2033.54	18.4937
2036.47	18.496
2039.4	18.2898
2042.33	17.8896
2045.27	17.944
2048.19	18.3683
2051.12	19.2488
2054.05	21.3766
2056.97	21.2068
2059.9	21.9787
2062.82	22.9056
2065.74	25.1989
2068.67	27.2409
2071.59	27.0579
2074.51	27.4785
2077.42	29.5106
2080.34	31.7363
2083.26	32.7042
2086.17	34.8555
2089.09	37.2455
2092	37.9181
2094.91	40.7743
2097.82	42.7183
2100.73	44.8723
2103.64	47.137
2106.55	49.5284
2109.45	52.1988
2112.36	54.7665
2115.26	57.2014
2118.17	61.8116
2121.07	65.8681
2123.97	69.137
2126.87	71.9385
2129.77	75.152
2132.67	79.4387
2135.56	83.1982
2138.46	87.7375
2141.35	92.7922
2144.25	98.9195
2147.14	105.539
2150.03	111.921
2152.92	116.969
2155.81	123.007
2158.7	127.427
2161.59	132.116
2164.47	135.283
2167.36	138.458
2170.24	140.669
2173.13	141.605
2176.01	141.628
2178.89	140.589
2181.77	138.621
2184.65	137.411
2187.53	134.374
2190.4	130.384
2193.28	126.059
2196.16	120.591
2199.03	114.373
2201.9	108.227
2204.77	101.71
2207.64	97.1044
2210.51	92.4092
2213.38	86.5226
2216.25	81.8197
2219.12	76.8192
2221.98	72.4915
2224.85	68.9894
2227.71	65.4749
2230.57	60.0565
2233.43	56.9574
2236.29	53.193
2239.15	49.3341
2242.01	46.5496
2244.87	44.1431
2247.72	41.0006
2250.58	39.2846
2253.43	36.7224
2256.29	35.2842
2259.14	33.5914
2261.99	32.5578
2264.84	30.3495
2267.69	28.1005
2270.53	26.3994
2273.38	25.1206
2276.23	23.7486
2279.07	23.1529
2281.91	22.0824
2284.76	22.4943
2287.6	21.1575
2290.44	20.414
2293.28	19.5084
2296.12	20.1256
2298.96	20.417
2301.79	20.3772
2304.63	21.08
2307.46	20.2095
2310.3	21.1661
2313.13	20.9662
2315.96	19.9646
2318.79	18.0005
2321.62	16.5231
2324.45	15.9493
2327.27	15.4827
2330.1	13.7259
2332.92	12.4456
2335.75	11.502
2338.57	10.0895
2341.39	8.94671
2344.21	8.34263
2347.04	7.15441
2349.85	6.15599
2352.67	4.99685
2355.49	3.69599
2358.3	2.25383
2361.12	1.18241
2363.93	2.7398
2366.75	4.13058
2369.56	3.32078
2372.37	2.01323
2375.18	1.3303
2377.99	1.50727
2380.8	1.93189
2383.6	0.383056
2386.41	-0.808121
2389.21	-0.990911
2392.02	-0.128287
2394.82	1.09963
2397.62	1.40563
2400.42	2.90703
2403.22	3.17575
2406.02	3.97341
2408.82	4.51624
2411.62	5.20617
2414.41	6.54961
2417.21	6.63679
2420	7.17843
2422.79	9.01269
2425.59	9.43478
2428.38	9.27761
2431.17	10.5814
2433.95	10.0945
2436.74	9.42613
2439.53	8.43513
2442.31	7.70717
2445.1	7.26026
2447.88	7.89296
2450.67	5.47485
2453.45	3.78577
2456.23	3.78761
2459.01	4.40393
2461.79	4.93284
2464.57	4.51857
2467.34	4.54436
2470.12	5.17015
2472.89	4.21008
2475.67	4.00914
2478.44	4.38781
2481.21	5.16172
2483.98	4.61878
2486.75	5.30863
2489.52	6.29158
2492.29	6.29729
2495.05	6.01002
2497.82	5.5556
2500.58	5.80403
2503.35	5.11038
2506.11	4.60841
2508.87	4.67727
2511.63	3.24933
2514.39	2.76082
2517.15	1.89791
2519.91	1.48599
2522.67	1.86024
2525.42	1.65516
2528.18	2.15115
2530.93	1.80345
2533.69	2.18952
2536.44	2.9808
2539.19	2.95109
2541.94	2.15701
2544.69	3.43387
2547.44	3.61779
2550.18	3.47136
2552.93	5.85642
2555.67	5.71551
2558.42	5.78226
2561.16	5.65778
2563.9	5.65746
2566.64	6.53377
2569.38	6.64339
2572.12	6.0596
2574.86	5.50155
2577.6	5.75199
2580.33	4.81421
2583.07	4.90699
2585.8	5.06979
2588.54	4.22779
2591.27	4.74064
2594	4.56567
2596.73	4.60033
2599.46	5.14384
2602.19	5.63551
2604.92	5.31261
2607.64	4.40068
2610.37	5.32128
2613.09	4.55718
2615.82	3.80155
2618.54	3.67373
2621.26	2.76331
2623.98	1.82153
2626.7	1.90996
2629.42	2.52834
2632.14	2.54158
2634.86	3.50321
2637.57	2.74311
2640.29	3.40736
2643	3.16877
2645.71	3.57214
2648.43	3.12598
2651.14	2.32463
2653.85	1.71796
2656.56	2.58894
2659.26	1.43994
2661.97	1.31505
2664.68	0.591673
2667.38	0.474634
2670.09	0.627858
2672.79	-0.558084
2675.49	0.339065
2678.19	-0.259639
2680.89	0.248091
2683.59	1.24879
2686.29	1.7584
2688.99	2.16215
2691.69	3.00864
2694.38	3.39715
2697.08	5.26971
2699.77	6.69315
2702.46	7.07935
2705.15	8.14177
2707.85	9.03128
2710.54	9.71104
2713.22	10.8649
2715.91	10.6557
2718.6	10.939
2721.29	11.997
2723.97	12.1847
2726.66	10.8452
2729.34	10.5505
2732.02	9.79617
2734.7	9.83627
2737.38	10.1571
2740.06	10.0058
2742.74	9.95895
2745.42	9.49854
2748.09	9.343
2750.77	8.06406
2753.45	6.99885
2756.12	5.73352
2758.79	4.63352
2761.46	4.14771
2764.14	3.86683
2766.8	3.20855
2769.47	2.99459
2772.14	2.78564
2774.81	2.12507
2777.48	1.99723
2780.14	1.11871
2782.8	0.277015
2785.47	-0.0180671
2788.13	-0.426156
2790.79	0.169971
2793.45	0.183239
2796.11	0.123864
2798.77	0.951106
2801.43	1.06045
2804.09	0.88284
2806.74	-0.359419
2809.4	-0.492674
2812.05	0.164507
2814.71	0.697808
2817.36	3.50041
2820.01	6.01998
2822.66	10.7401
2825.31	15.2566
2827.96	20.6188
2830.6	25.3021
2833.25	32.191
2835.9	38.2719
2838.54	45.5779
2841.18	53.6509
2843.83	63.9307
2846.47	74.1038
2849.11	85.1329
2851.75	97.6471
2854.39	110.062
2857.03	121.504
2859.66	132.489
2862.3	143.132
2864.94	154.189
2867.57	163.316
2870.2	171.006
2872.84	178.67
2875.47	187.293
2878.1	195.484
2880.73	202.712
2883.36	208.912
2885.99	216.19
2888.61	223.308
2891.24	229.165
2893.86	235.261
2896.49	244.663
2899.11	255.577
2901.73	265.931
2904.36	280.134
2906.98	294.376
2909.6	310.961
2912.21	328.501
2914.83	345.073
2917.45	362.918
2920.07	377.108
2922.68	391.383
2925.29	402.033
2927.91	410.693
2930.52	415.734
2933.13	417.553
2935.74	416.91
2938.35	412.927
2940.96	405.626
2943.57	395.547
2946.18	382.638
2948.78	369.752
2951.39	354.823
2953.99	337.479
2956.59	319.652
2959.2	303.973
2961.8	285.75
2964.4	269.22
2967	253.494
2969.6	240.41
2972.19	224.672
2974.79	212.333
2977.39	200.381
2979.98	185.042
2982.58	170.118
2985.17	157.041
2987.76	143.342
2990.35	128.961
2992.94	115.369
2995.53	102.261
2998.12	91.2523
3000.71	80.1222
3003.3	68.6313
3005.88	57.4769
3008.47	48.8036
3011.05	41.3213
3013.64	34.6093
3016.22	27.4141
3018.8	22.0093
3021.38	17.3415
3023.96	13.8695
3026.54	11.0217
3029.12	10.9073
3031.69	10.8359
3034.27	10.7769
3036.84	11.7427
3039.42	13.6446
3041.99	14.0265
3044.57	15.1238
3047.14	16.4077
3049.71	17.2681
3052.28	17.3171
3054.85	18.0987
3057.41	17.3978
3059.98	17.4256
3062.55	17.1641
3065.11	16.4802
3067.68	14.1061
3070.24	13.9462
3072.8	12.1871
3075.36	9.30273
3077.93	7.14223
3080.49	4.6456
3083.04	3.5921
3085.6	2.1697
3088.16	0.768286
3090.72	0.030034
3093.27	-1.21376
3095.83	-0.519896
3098.38	0.225993
3100.93	1.14562
3103.49	1.56825
3106.04	1.71567
3108.59	1.76271
3111.14	2.29527
3113.69	2.65007
3116.23	4.34355
3118.78	4.93806
3121.33	6.3023
3123.87	7.5961
3126.41	9.2497
3128.96	10.4479
3131.5	10.6621
3134.04	12.7019
3136.58	13.9558
3139.12	14.9454
3141.66	17.221
3144.2	18.2113
3146.74	18.2543
3149.27	20.0507