File: data/Raman/poly_smoothed/Mb_30_27_04_1x_45s_532 nm_x100_100%_600 gr_mm_01.txt
#Acq. time (s)=	45
#Accumulations=	2
#Range (cm-¹)=	200...3150
#Windows=	2
#Auto scanning=	Off
#Autofocus=	Off
#Macrospot=	Off
#AutoExposure=	Off
#Spike filter=	Multiple accum.
#Delay time (s)=	0
#Binning=	1
#Readout mode=	Signal
#DeNoise=	Off
#ICS correction=	On
#Dark correction=	Off
#Inst. Process=	Off
#Detector Gain=	Best Dynamic Range
#Detector ADC=	20 kHz
#Detector temperature (°C)=	-70.08
#Instrument=	LabRAM HR Evol
#Detector=	Synapse
#Objective=	x100
#Grating=	600 gr/mm
#ND Filter=	100%
#Laser (nm)=	532
#Hole=	100.021
#Range=	Auto
#Laser Pol.=	No
#Raman. Pol.=	No
#Laser Pol. (°)=	-0.0007625
#Raman Pol. (°)=	89.9995
#Collection=	Microscope
#StageXY=	Marzhauser
#StageZ=	Marzhauser
#X (µm)=	28066.2
#Y (µm)=	-554.9
#Z (µm)=	1083.45
#Full time(mm:ss)=	3:18
#Project=
#Sample=
#Site=
#Title=	Mb_30_27_04_2x_45s_532 nm_x100_100%_600 gr_mm
#Remark=
#Date=	12.07.2022 15:44
#Acquired=	12.07.2022 15:44:20
#Base:Fit=	10.08.2022 10:39:47
#Base:Sub=	10.08.2022 10:39:55
#Base:Fit=	10.08.2022 10:40:03
#Base:Sub=	10.08.2022 10:40:17
#Filter:Polynom=	16.08.2022 10:16:15
#AxisType[0]=Intens
#AxisUnit[0]=Cnt
#AxisType[1]=Spectr
#AxisUnit[1]=1/cm
200.388	2.59503
204.019	5.38964
207.646	6.03496
211.274	5.67899
214.899	6.46393
218.524	7.89804
222.146	8.17426
225.766	7.771
229.388	8.53691
233.005	9.15813
236.621	6.88507
240.236	5.91714
243.852	5.06605
247.464	4.18648
251.074	3.18034
254.683	3.58275
258.291	3.94569
261.897	4.62704
265.504	4.95568
269.108	5.69911
272.71	6.99038
276.311	5.33891
279.91	6.94124
283.508	8.36675
287.105	9.11569
290.698	8.90158
294.291	9.9358
297.884	11.8972
301.475	13.1647
305.064	15.0522
308.652	15.9108
312.237	15.5936
315.822	15.6165
319.406	14.8427
322.987	12.503
326.568	10.9902
330.148	11.3921
333.724	11.3913
337.301	11.7622
340.875	11.3615
344.449	9.7102
348.02	9.5741
351.592	8.99852
355.16	8.02248
358.728	7.1419
362.294	7.46637
365.858	8.62059
369.422	9.89842
372.983	8.6785
376.543	8.444
380.102	7.45488
383.661	8.24055
387.216	8.52333
390.771	7.20279
394.324	8.7803
397.875	8.64372
401.425	7.55227
404.974	7.02398
408.524	7.00729
412.07	6.91471
415.614	7.92201
419.156	8.57261
422.698	8.36016
426.238	8.43131
429.777	7.33233
433.315	6.5327
436.852	7.65565
440.387	6.87931
443.919	6.50565
447.451	7.96032
450.982	9.09185
454.512	7.50965
458.038	6.60622
461.565	6.57438
465.091	8.57528
468.613	8.37534
472.136	8.9924
475.655	9.5971
479.176	11.1
482.692	11.4198
486.21	12.4125
489.724	13.8989
493.237	16.1828
496.75	18.2981
500.26	19.9576
503.771	20.8953
507.279	22.1903
510.785	22.6259
514.289	24.1619
517.793	23.4968
521.297	24.6029
524.797	26.6637
528.297	25.8023
531.795	27.056
535.291	26.1692
538.787	25.4303
542.281	24.689
545.773	25.2579
549.264	24.9116
552.754	22.2538
556.243	20.7073
559.73	20.1276
563.216	19.0314
566.701	17.2697
570.182	15.227
573.664	14.9988
577.145	13.8012
580.624	11.1835
584.1	9.18901
587.577	7.95357
591.052	6.63949
594.524	6.14097
597.997	5.19182
601.466	4.74924
604.936	5.38869
608.403	6.11354
611.87	6.0493
615.334	7.24807
618.799	7.94461
622.26	7.86168
625.72	8.84253
629.181	9.66342
632.638	10.1398
636.095	12.1866
639.551	14.6114
643.005	15.6846
646.457	17.2172
649.908	18.7666
653.357	19.0573
656.806	20.6147
660.253	22.0562
663.7	24.164
667.145	26.073
670.588	27.0719
674.027	27.5384
677.468	28.6551
680.907	30.1819
684.345	33.3804
687.781	36.2009
691.216	38.3638
694.65	39.89
698.081	42.7075
701.512	44.4788
704.942	45.8644
708.371	48.1451
711.796	50.4479
715.222	51.3595
718.645	53.3656
722.068	55.3737
725.49	56.6969
728.909	57.0581
732.329	57.6595
735.745	57.488
739.16	59.1514
742.576	59.2845
745.988	60.6097
749.401	62.674
752.811	64.966
756.22	66.0071
759.627	69.285
763.035	70.833
766.44	74.5301
769.843	76.2729
773.245	79.0321
776.646	79.6552
780.046	82.2335
783.444	83.3366
786.841	84.3407
790.237	84.8482
793.631	86.322
797.024	88.6992
800.416	89.4063
803.807	91.1119
807.196	90.6467
810.584	91.4601
813.971	91.5977
817.354	91.6748
820.739	92.0341
824.122	92.2646
827.503	91.4746
830.882	92.6961
834.261	92.4499
837.637	90.8176
841.013	88.3182
844.389	85.7434
847.761	83.2516
851.131	77.8747
854.503	74.0799
857.871	71.1105
861.24	68.1519
864.606	63.5898
867.97	60.715
871.336	58.6199
874.698	57.3343
878.058	57.2339
881.418	56.0152
884.778	54.2304
888.135	53.6966
891.49	53.3128
894.845	53.6719
898.198	52.6907
901.55	53.7388
904.901	52.9227
908.25	52.9859
911.598	53.5358
914.945	54.335
918.291	53.5161
921.635	52.3889
924.978	53.0758
928.318	50.7519
931.659	49.5724
934.998	48.3045
938.336	47.4301
941.671	44.1092
945.007	41.631
948.339	41.7176
951.672	42.3507
955.004	43.0013
958.333	42.055
961.662	41.7879
964.989	42.5874
968.315	42.0663
971.639	43.5615
974.962	45.051
978.285	44.5954
981.605	45.5979
984.924	46.3382
988.243	46.9869
991.56	46.2327
994.875	46.5974
998.188	44.734
1001.5	44.3205
1004.81	42.7461
1008.12	42.3017
1011.43	42.6466
1014.74	43.6294
1018.05	44.0707
1021.35	44.1342
1024.65	44.579
1027.96	47.2418
1031.26	48.0506
1034.56	47.9489
1037.86	46.9691
1041.16	46.5332
1044.45	46.8245
1047.75	46.3794
1051.04	45.07
1054.33	44.5976
1057.62	40.388
1060.91	36.7382
1064.2	34.4947
1067.49	31.9079
1070.77	28.2304
1074.06	24.818
1077.34	23.4754
1080.62	21.4128
1083.91	20.7266
1087.18	20.5294
1090.46	22.1776
1093.74	21.2594
1097.02	19.4014
1100.29	19.6363
1103.56	19.1476
1106.84	18.6525
1110.11	18.1072
1113.38	17.0955
1116.64	17.0448
1119.91	15.3866
1123.18	15.6379
1126.44	13.9901
1129.7	12.03
1132.97	9.90693
1136.23	8.44329
1139.49	7.69762
1142.74	7.71304
1146	7.93857
1149.26	7.817
1152.51	7.28529
1155.76	6.44464
1159.01	5.3618
1162.27	4.37755
1165.51	4.56797
1168.76	3.99352
1172.01	2.7549
1175.25	2.73803
1178.5	4.20208
1181.74	3.63847
1184.98	2.16354
1188.22	3.85217
1191.46	5.85965
1194.7	7.05093
1197.94	7.2608
1201.17	8.04854
1204.41	9.81693
1207.64	11.79
1210.87	15.5765
1214.1	19.0083
1217.33	23.4009
1220.56	27.2685
1223.79	30.569
1227.01	33.6595
1230.23	37.6142
1233.46	41.1788
1236.68	43.7832
1239.9	47.8461
1243.12	51.0553
1246.34	53.9424
1249.55	55.3024
1252.77	55.712
1255.98	56.231
1259.2	55.8802
1262.41	56.2818
1265.62	58.9028
1268.83	60.2392
1272.03	62.0374
1275.24	62.5373
1278.45	62.9839
1281.65	63.7275
1284.85	64.7638
1288.06	65.9823
1291.26	66.7599
1294.46	67.4397
1297.66	67.6494
1300.85	68.3847
1304.05	68.7377
1307.24	69.7845
1310.43	69.565
1313.63	70.2128
1316.82	70.9316
1320.01	69.4492
1323.2	68.3181
1326.38	66.8654
1329.57	64.2239
1332.76	62.9086
1335.94	61.3831
1339.12	60.4858
1342.3	59.5728
1345.48	57.3021
1348.66	55.8782
1351.84	53.232
1355.01	50.4804
1358.19	46.4366
1361.36	43.5106
1364.53	41.1252
1367.71	38.4667
1370.88	34.9147
1374.04	32.7618
1377.21	31.059
1380.38	29.6783
1383.54	30.2143
1386.71	30.4634
1389.87	30.6136
1393.03	30.5171
1396.19	29.7164
1399.35	30.4985
1402.51	31.9451
1405.67	33.3279
1408.82	34.9522
1411.98	36.5972
1415.13	39.1107
1418.28	41.2894
1421.43	44.3135
1424.58	47.4145
1427.73	51.5612
1430.88	55.7977
1434.02	59.0618
1437.17	61.2519
1440.31	63.8117
1443.45	63.8574
1446.6	64.1317
1449.74	64.2728
1452.87	65.0516
1456.01	64.0602
1459.15	63.4934
1462.28	61.7537
1465.42	58.7709
1468.55	54.8016
1471.68	51.1678
1474.81	49.2499
1477.94	45.8818
1481.07	43.4869
1484.2	40.2406
1487.32	36.9298
1490.45	33.3698
1493.57	30.7474
1496.69	28.4724
1499.81	26.79
1502.93	26.3883
1506.05	26.2677
1509.17	24.8092
1512.28	23.3276
1515.4	21.5602
1518.51	18.9685
1521.63	18.9995
1524.74	18.0419
1527.85	16.2488
1530.96	16.0171
1534.06	16.8773
1537.17	16.8474
1540.28	17.6652
1543.38	18.7797
1546.48	20.2265
1549.59	20.7912
1552.69	23.2159
1555.79	24.0563
1558.88	24.9486
1561.98	25.7575
1565.08	27.2457
1568.17	29.3323
1571.27	32.3083
1574.36	34.0813
1577.45	36.4556
1580.54	39.9485
1583.63	42.5524
1586.72	43.2404
1589.8	44.5553
1592.89	45.427
1595.97	46.2079
1599.06	46.1114
1602.14	45.1004
1605.22	46.4805
1608.3	47.6974
1611.38	49.6794
1614.46	50.5769
1617.53	52.5095
1620.61	54.0733
1623.68	56.2718
1626.75	58.2758
1629.82	61.5228
1632.9	64.9529
1635.96	69.5087
1639.03	73.4339
1642.1	77.6168
1645.16	81.3156
1648.23	85.1325
1651.29	86.9467
1654.36	88.9557
1657.42	89.1629
1660.48	88.4763
1663.53	87.7306
1666.59	85.4883
1669.65	81.5149
1672.7	77.6351
1675.76	71.9876
1678.81	66.9604
1681.86	62.4196
1684.91	56.6798
1687.96	50.9719
1691.01	45.336
1694.06	39.5849
1697.11	34.919
1700.15	31.6324
1703.2	28.1082
1706.24	25.4558
1709.28	23.3431
1712.32	20.9519
1715.36	19.3431
1718.4	18.2297
1721.43	18.4757
1724.47	17.5353
1727.5	16.5186
1730.54	15.4401
1733.57	14.9663
1736.6	14.542
1739.63	14.528
1742.66	13.7055
1745.69	13.3451
1748.72	12.668
1751.74	11.5059
1754.77	10.6263
1757.79	10.161
1760.81	9.26731
1763.83	8.66895
1766.85	7.57277
1769.87	7.47845
1772.89	6.66716
1775.91	6.33586
1778.92	6.13061
1781.94	5.30221
1784.95	4.85509
1787.96	4.33944
1790.97	4.22317
1793.98	4.76465
1796.99	3.99268
1800	2.58525
1803	2.18676
1806.01	1.45908
1809.01	1.52505
1812.02	1.74908
1815.02	1.71696
1818.02	1.77647
1821.02	2.11543
1824.02	2.49304
1827.01	2.62852
1830.01	3.3004
1833	4.11179
1836	4.01895
1838.99	2.85266
1841.98	2.62857
1844.97	3.25062
1847.96	3.41679
1850.95	3.10926
1853.94	2.31756
1856.92	2.54344
1859.91	2.05394
1862.89	2.10681
1865.88	0.888931
1868.86	0.485693
1871.84	-0.210356
1874.82	-0.309869
1877.8	0.0986451
1880.77	0.74097
1882.51	1.82944
1885.5	2.15344
1888.48	2.41867
1891.47	2.94323
1894.46	3.75297
1897.44	3.72113
1900.42	4.58865
1903.41	4.65177
1906.39	5.04185
1909.37	5.07954
1912.35	5.77201
1915.32	5.56597
1918.3	5.58086
1921.28	5.1388
1924.25	4.06226
1927.22	3.35366
1930.2	2.78095
1933.17	3.14204
1936.14	2.3035
1939.11	2.44349
1942.08	2.4568
1945.04	1.9003
1948.01	2.53972
1950.97	2.32006
1953.94	2.7808
1956.9	1.37754
1959.86	1.23498
1962.82	1.52386
1965.78	1.56893
1968.74	1.94318
1971.69	1.86428
1974.65	1.61846
1977.61	0.721477
1980.56	0.634865
1983.51	0.747789
1986.46	0.227372
1989.41	0.0635607
1992.36	0.378659
1995.31	0.712697
1998.26	0.64703
2001.2	1.18976
2004.15	2.76319
2007.09	3.6364
2010.04	4.08034
2012.98	4.58037
2015.92	4.69409
2018.86	5.15362
2021.8	6.03146
2024.74	6.00937
2027.67	5.76703
2030.61	6.18027
2033.54	7.06381
2036.47	7.25133
2039.41	8.18318
2042.34	7.78488
2045.27	7.16958
2048.2	6.39624
2051.12	6.59186
2054.05	7.11218
2056.98	7.70559
2059.9	7.73352
2062.82	8.12498
2065.75	8.94487
2068.67	8.97149
2071.59	9.73625
2074.51	10.4598
2077.43	11.3436
2080.34	12.5978
2083.26	12.8398
2086.17	14.9444
2089.09	15.7655
2092	17.6146
2094.91	18.8898
2097.82	19.747
2100.73	21.7267
2103.64	23.7466
2106.55	25.6541
2109.46	27.0706
2112.36	28.3348
2115.27	29.3345
2118.17	31.5457
2121.07	33.6441
2123.97	36.0091
2126.87	40.2915
2129.77	42.8911
2132.67	44.9238
2135.57	47.8669
2138.46	50.4362
2141.36	54.1791
2144.25	57.8681
2147.14	60.9698
2150.03	65.6073
2152.92	69.8602
2155.81	74.354
2158.7	78.8344
2161.59	82.8191
2164.48	85.3845
2167.36	87.305
2170.25	88.5561
2173.13	89.6585
2176.01	90.2202
2178.89	90.4827
2181.77	89.8574
2184.65	88.7906
2187.53	87.5029
2190.41	84.7356
2193.28	81.4499
2196.16	78.8189
2199.03	75.0188
2201.9	70.5093
2204.78	66.4146
2207.65	61.3763
2210.51	57.4692
2213.38	53.49
2216.25	49.2595
2219.12	44.4968
2221.98	41.798
2224.85	38.6513
2227.71	36.6734
2230.57	33.7018
2233.43	30.2353
2236.29	28.1067
2239.15	26.1209
2242.01	25.0341
2244.87	23.7614
2247.73	22.347
2250.58	21.7266
2253.43	21.5507
2256.29	22.0055
2259.14	20.8953
2261.99	20.5622
2264.84	21.035
2267.69	20.523
2270.54	19.545
2273.38	18.9729
2276.23	17.5248
2279.07	16.6974
2281.92	16.3102
2284.76	14.8951
2287.6	13.6362
2290.44	11.686
2293.28	9.44669
2296.12	9.16179
2298.96	8.95915
2301.79	9.18456
2304.63	8.38028
2307.46	8.56955
2310.3	8.50143
2313.13	8.47841
2315.96	8.47807
2318.79	7.80461
2321.62	7.96936
2324.45	8.46258
2327.27	8.21195
2330.1	7.56106
2332.93	7.33403
2335.75	7.14474
2338.57	6.16869
2341.4	4.6942
2344.22	3.62125
2347.04	3.03801
2349.86	3.10551
2352.67	2.85351
2355.49	1.89629
2358.31	0.39417
2361.12	0.553419
2363.94	1.05613
2366.75	2.38169
2369.56	3.28337
2372.37	2.64456
2375.18	2.95701
2377.99	2.74855
2380.8	3.88115
2383.61	3.38191
2386.41	3.16444
2389.22	4.03024
2392.02	5.52869
2394.82	5.69742
2397.63	6.52531
2400.43	6.1554
2403.23	6.77984
2406.02	6.26744
2408.82	6.02854
2411.62	6.20141
2414.41	6.79516
2417.21	7.47825
2420	7.62601
2422.79	7.38758
2425.59	6.93271
2428.38	6.3159
2431.17	6.06217
2433.96	4.8128
2436.74	4.93848
2439.53	4.21001
2442.32	3.55958
2445.1	2.91703
2447.88	3.36593
2450.67	2.88018
2453.45	2.58988
2456.23	3.843
2459.01	3.9979
2461.79	4.66102
2464.57	5.01571
2467.34	5.61808
2470.12	5.49314
2472.89	6.34921
2475.67	6.47318
2478.44	6.92791
2481.21	6.60493
2483.98	6.93509
2486.75	7.24449
2489.52	7.05354
2492.29	6.08065
2495.06	4.77876
2497.82	4.03061
2500.59	3.24946
2503.35	2.67352
2506.11	2.61309
2508.88	2.64852
2511.63	1.67633
2514.39	1.33649
2517.15	0.405769
2519.91	-0.597967
2522.67	-0.370139
2525.42	-0.267103
2528.18	-0.359516
2530.93	0.340959
2533.69	0.954757
2536.44	1.97957
2539.19	2.34307
2541.94	3.6299
2544.69	4.29578
2547.44	4.57884
2550.18	4.71123
2552.93	5.16059
2555.68	5.74942
2558.42	5.56396
2561.16	5.32984
2563.9	5.356
2566.64	5.23503
2569.38	5.40651
2572.12	5.06264
2574.86	4.864
2577.6	3.58823
2580.34	2.94842
2583.07	2.31061
2585.81	1.48594
2588.54	1.63294
2591.27	1.55159
2594	1.14272
2596.73	1.17029
2599.46	1.33485
2602.19	1.03528
2604.92	1.60765
2607.64	1.14181
2610.37	1.65952
2613.09	1.94145
2615.82	2.22069
2618.54	3.15689
2621.26	3.9045
2623.98	4.52028
2626.7	5.17715
2629.42	5.79835
2632.14	5.97436
2634.86	6.34214
2637.57	6.83193
2640.29	7.05573
2643	7.57002
2645.72	7.85871
2648.43	8.00841
2651.14	9.04841
2653.85	9.29707
2656.56	8.91298
2659.27	8.25599
2661.97	8.61525
2664.68	7.31366
2667.38	6.94888
2670.09	6.47424
2672.79	5.56455
2675.49	5.71798
2678.2	6.0983
2680.89	6.66693
2683.59	5.83815
2686.29	5.67415
2688.99	5.06878
2691.69	3.908
2694.38	4.07734
2697.08	3.82126
2699.77	4.28859
2702.46	3.9803
2705.16	3.68315
2707.85	5.10947
2710.54	5.53026
2713.23	6.39405
2715.92	7.11758
2718.6	7.37001
2721.29	6.8172
2723.97	7.79793
2726.66	7.96767
2729.34	8.39003
2732.02	8.00297
2734.7	8.1865
2737.39	7.93656
2740.06	8.34304
2742.74	8.86744
2745.42	9.43897
2748.1	8.81141
2750.77	8.11155
2753.45	7.66675
2756.12	7.62283
2758.79	7.22021
2761.47	6.99864
2764.14	6.24426
2766.81	5.1777
2769.48	4.79578
2772.14	5.07008
2774.81	4.81947
2777.48	3.69206
2780.14	2.32735
2782.81	2.27755
2785.47	1.64177
2788.13	1.47262
2790.79	1.6221
2793.46	0.46016
2796.11	-0.34623
2798.77	0.173739
2801.43	-0.424056
2804.09	-0.103351
2806.74	0.413905
2809.4	0.653863
2812.05	0.959819
2814.71	2.04989
2817.36	3.27541
2820.01	4.07691
2822.66	6.00659
2825.31	8.65197
2827.96	10.9002
2830.61	14.6386
2833.25	18.2566
2835.9	22.749
2838.54	27.7012
2841.18	33.0556
2843.83	39.6757
2846.47	46.9969
2849.11	54.7336
2851.75	63.2433
2854.39	71.968
2857.03	80.2564
2859.67	87.4843
2862.3	95.1962
2864.94	102.445
2867.57	108.265
2870.21	113.584
2872.84	118.268
2875.47	122.138
2878.1	126.131
2880.73	129.416
2883.36	133.065
2885.99	137.137
2888.61	141.562
2891.24	145.92
2893.87	151.636
2896.49	157.242
2899.11	164.496
2901.74	172.945
2904.36	183.801
2906.98	194.739
2909.6	207.118
2912.22	219.626
2914.83	233.749
2917.45	245.176
2920.07	256.281
2922.68	265.862
2925.3	273.972
2927.91	280.945
2930.52	283.862
2933.13	284.986
2935.74	284.002
2938.35	280.48
2940.96	275.113
2943.57	268.215
2946.18	259.467
2948.78	249.304
2951.39	237.702
2953.99	225.672
2956.6	213.322
2959.2	200.437
2961.8	187.665
2964.4	177.763
2967	166.588
2969.6	155.411
2972.2	145.056
2974.79	135.455
2977.39	126.643
2979.98	118.157
2982.58	109.359
2985.17	100.82
2987.76	92.7127
2990.36	84.7141
2992.95	76.7569
2995.54	68.9264
2998.12	63.0785
3000.71	55.989
3003.3	49.5554
3005.88	43.7789
3008.47	37.9733
3011.05	32.6115
3013.64	26.775
3016.22	22.6786
3018.8	20.2716
3021.38	17.5391
3023.96	14.4101
3026.54	12.7448
3029.12	12.3061
3031.69	11.0292
3034.27	10.5826
3036.85	11.1725
3039.42	11.6247
3041.99	12.4516
3044.57	12.9085
3047.14	13.9053
3049.71	14.8655
3052.28	15.9236
3054.85	15.9302
3057.42	16.3059
3059.98	16.5145
3062.55	15.7905
3065.11	14.4558
3067.68	13.3401
3070.24	12.3293
3072.8	11.466
3075.37	9.14022
3077.93	7.49634
3080.49	6.20442
3083.05	3.81098
3085.61	2.32366
3088.16	1.42991
3090.72	1.62392
3093.27	0.65213
3095.83	0.126844
3098.38	-0.0432969
3100.94	-0.136075
3103.49	0.348348
3106.04	0.76105
3108.59	1.02851
3111.14	1.30184
3113.69	1.91433
3116.23	2.79736
3118.78	3.9078
3121.33	4.56777
3123.87	5.66581
3126.42	6.18823
3128.96	7.41187
3131.5	8.22486
3134.04	9.25887
3136.58	9.40011
3139.12	9.87957
3141.66	10.7333
3144.2	11.4304
3146.74	11.8471
3149.27	11.2949