File: data/Raman/poly_smoothed/Mb_30_27_01_1x_45s_532 nm_x100_100%_600 gr_mm_01.txt
#Acq. time (s)=	45
#Accumulations=	2
#Range (cm-¹)=	200...3150
#Windows=	2
#Auto scanning=	Off
#Autofocus=	Off
#Macrospot=	Off
#AutoExposure=	Off
#Spike filter=	Multiple accum.
#Delay time (s)=	0
#Binning=	1
#Readout mode=	Signal
#DeNoise=	Off
#ICS correction=	On
#Dark correction=	Off
#Inst. Process=	Off
#Detector Gain=	Best Dynamic Range
#Detector ADC=	20 kHz
#Detector temperature (°C)=	-70.08
#Instrument=	LabRAM HR Evol
#Detector=	Synapse
#Objective=	x100
#Grating=	600 gr/mm
#ND Filter=	100%
#Laser (nm)=	532
#Hole=	100.021
#Range=	Auto
#Laser Pol.=	No
#Raman. Pol.=	No
#Laser Pol. (°)=	-0.0007625
#Raman Pol. (°)=	89.9995
#Collection=	Microscope
#StageXY=	Marzhauser
#StageZ=	Marzhauser
#X (µm)=	28061.1
#Y (µm)=	-586.9
#Z (µm)=	1083.7
#Full time(mm:ss)=	3:19
#Project=
#Sample=
#Site=
#Title=	Mb_30_27_01_2x_45s_532 nm_x100_100%_600 gr_mm
#Remark=
#Date=	12.07.2022 15:28
#Acquired=	12.07.2022 15:28:27
#Base:Fit=	10.08.2022 10:39:47
#Base:Sub=	10.08.2022 10:39:55
#Base:Fit=	10.08.2022 10:40:03
#Base:Sub=	10.08.2022 10:40:17
#Filter:Polynom=	16.08.2022 10:16:15
#AxisType[0]=Intens
#AxisUnit[0]=Cnt
#AxisType[1]=Spectr
#AxisUnit[1]=1/cm
200.388	65.7613
204.019	59.5109
207.646	55.8911
211.274	50.8091
214.899	45.2891
218.524	41.9895
222.146	38.9234
225.766	34.6003
229.388	29.9907
233.005	24.7341
236.621	21.4542
240.236	17.979
243.852	16.1118
247.464	13.6914
251.074	10.8634
254.683	8.6792
258.291	7.99218
261.897	8.75589
265.504	8.57233
269.108	8.28341
272.71	6.84907
276.311	7.42197
279.91	5.48812
283.508	4.56044
287.105	5.42601
290.698	6.40548
294.291	7.08042
297.884	8.74186
301.475	10.6022
305.064	11.7786
308.652	15.2978
312.237	16.0378
315.822	15.5878
319.406	15.0633
322.987	15.894
326.568	15.9368
330.148	16.3416
333.724	16.4455
337.301	14.9507
340.875	13.4175
344.449	12.8899
348.02	10.9364
351.592	8.076
355.16	5.04267
358.728	4.92922
362.294	2.88484
365.858	1.80747
369.422	0.879355
372.983	2.39394
376.543	3.25358
380.102	5.02691
383.661	6.86922
387.216	8.66514
390.771	9.26595
394.324	11.0586
397.875	12.1444
401.425	11.2692
404.974	12.6029
408.524	15.5146
412.07	17.3889
415.614	19.015
419.156	17.8472
422.698	18.9968
426.238	17.9928
429.777	15.383
433.315	13.5213
436.852	12.475
440.387	12.3294
443.919	11.7518
447.451	13.2092
450.982	13.967
454.512	15.0247
458.038	16.5651
461.565	18.4564
465.091	19.3072
468.613	20.1523
472.136	23.0056
475.655	24.3504
479.176	25.2254
482.692	27.9661
486.21	29.4663
489.724	30.6776
493.237	34.0519
496.75	35.3873
500.26	36.7131
503.771	37.4365
507.279	38.6121
510.785	40.1343
514.289	40.4226
517.793	40.7766
521.297	41.3259
524.797	42.3392
528.297	42.3679
531.795	40.3397
535.291	41.0003
538.787	39.798
542.281	37.0947
545.773	33.9169
549.264	30.6864
552.754	27.2568
556.243	24.4939
559.73	22.2164
563.216	17.0793
566.701	14.0568
570.182	10.3666
573.664	4.04096
577.145	2.98169
580.624	1.95772
584.1	1.20171
587.577	1.26168
591.052	2.72718
594.524	2.44396
597.997	3.9069
601.466	3.04929
604.936	5.34208
608.403	6.43779
611.87	9.03796
615.334	9.85179
618.799	11.9245
622.26	13.014
625.72	13.1373
629.181	14.4267
632.638	16.0736
636.095	17.0358
639.551	18.303
643.005	18.2101
646.457	19.1563
649.908	18.876
653.357	18.5376
656.806	19.0062
660.253	20.2611
663.7	22.8695
667.145	23.7703
670.588	25.0203
674.027	25.6718
677.468	27.5627
680.907	27.7009
684.345	30.1918
687.781	32.9571
691.216	35.7738
694.65	36.2124
698.081	39.2053
701.512	40.6479
704.942	43.3455
708.371	44.3346
711.796	44.715
715.222	44.9428
718.645	45.2107
722.068	46.9641
725.49	47.2442
728.909	45.7009
732.329	45.7604
735.745	45.2179
739.16	48.765
742.576	47.6222
745.988	49.3923
749.401	50.6693
752.811	51.3795
756.22	53.4311
759.627	56.2468
763.035	59.2217
766.44	62.5996
769.843	65.4598
773.245	66.5902
776.646	70.8126
780.046	74.4857
783.444	77.4325
786.841	81.712
790.237	83.9152
793.631	86.1199
797.024	88.8877
800.416	92.0124
803.807	95.5099
807.196	96.416
810.584	94.7652
813.971	94.9538
817.354	94.8118
820.739	94.1159
824.122	91.7664
827.503	89.0585
830.882	87.2326
834.261	84.9059
837.637	83.3396
841.013	81.0851
844.389	77.7334
847.761	74.9258
851.131	69.5814
854.503	68.5433
857.871	66.7501
861.24	64.6772
864.606	62.6023
867.97	62.759
871.336	61.8908
874.698	60.2062
878.058	60.7604
881.418	62.6699
884.778	64.3149
888.135	65.0011
891.49	64.7875
894.845	64.1096
898.198	64.1657
901.55	64.2005
904.901	63.0539
908.25	63.184
911.598	63.6902
914.945	64.6803
918.291	66.1599
921.635	64.1329
924.978	62.9127
928.318	60.9896
931.659	57.9834
934.998	58.5749
938.336	55.6406
941.671	53.2574
945.007	50.0578
948.339	48.7693
951.672	49.391
955.004	48.1289
958.333	46.4314
961.662	46.2374
964.989	46.3184
968.315	47.1781
971.639	46.7653
974.962	47.3429
978.285	46.0661
981.605	45.6991
984.924	45.085
988.243	47.482
991.56	47.4698
994.875	48.5645
998.188	46.1612
1001.5	43.0702
1004.81	42.011
1008.12	45.4618
1011.43	54.4358
1014.74	65.3058
1018.05	76.0563
1021.35	84.5823
1024.65	92.2746
1027.96	98.9501
1031.26	104.502
1034.56	109.312
1037.86	109.947
1041.16	110.571
1044.45	110.446
1047.75	109.265
1051.04	104.735
1054.33	99.3679
1057.62	92.8291
1060.91	85.4992
1064.2	77.2983
1067.49	67.1409
1070.77	58.0804
1074.06	47.2604
1077.34	37.8621
1080.62	30.235
1083.91	28.0442
1087.18	32.4981
1090.46	38.4788
1093.74	41.8626
1097.02	44.2399
1100.29	46.9388
1103.56	48.1037
1106.84	48.4933
1110.11	49.3953
1113.38	49.8274
1116.64	48.7613
1119.91	47.5155
1123.18	46.5468
1126.44	46.88
1129.7	44.5682
1132.97	42.8287
1136.23	42.3685
1139.49	41.3714
1142.74	37.4457
1146	33.1872
1149.26	28.7171
1152.51	25.7598
1155.76	22.6692
1159.01	21.2171
1162.27	20.8702
1165.51	18.7929
1168.76	15.3515
1172.01	12.9499
1175.25	11.9933
1178.5	12.8876
1181.74	12.3448
1184.98	12.43
1188.22	11.0933
1191.46	10.9987
1194.7	13.379
1197.94	17.285
1201.17	18.8384
1204.41	23.7299
1207.64	27.0716
1210.87	31.5306
1214.1	37.3006
1217.33	41.337
1220.56	44.8727
1223.79	49.6409
1227.01	54.0725
1230.23	60.4552
1233.46	64.9356
1236.68	68.4647
1239.9	73.1058
1243.12	76.7154
1246.34	78.3668
1249.55	81.545
1252.77	84.7346
1255.98	88.4887
1259.2	90.5204
1262.41	92.2674
1265.62	95.2273
1268.83	97.2412
1272.03	100.6
1275.24	105.464
1278.45	106.935
1281.65	108.707
1284.85	112.588
1288.06	116.515
1291.26	120.181
1294.46	122.521
1297.66	125.258
1300.85	128.251
1304.05	129.881
1307.24	129.809
1310.43	130.746
1313.63	129.889
1316.82	130.04
1320.01	130.334
1323.2	129.668
1326.38	127.142
1329.57	124.098
1332.76	123.911
1335.94	121.505
1339.12	118.984
1342.3	114.599
1345.48	110.814
1348.66	108.047
1351.84	105.235
1355.01	101.216
1358.19	97.9994
1361.36	93.9419
1364.53	91.795
1367.71	89.1445
1370.88	86.6152
1374.04	81.0372
1377.21	76.6703
1380.38	74.1204
1383.54	70.1472
1386.71	70.5142
1389.87	68.3258
1393.03	65.6834
1396.19	62.6555
1399.35	61.133
1402.51	59.3108
1405.67	58.2417
1408.82	59.2332
1411.98	60.5197
1415.13	63.3767
1418.28	67.5652
1421.43	72.786
1424.58	81.2092
1427.73	89.2097
1430.88	97.2851
1434.02	104.918
1437.17	112.994
1440.31	119.345
1443.45	125.673
1446.6	128.549
1449.74	128.119
1452.87	128.209
1456.01	130.899
1459.15	128.794
1462.28	128.675
1465.42	126.217
1468.55	120.493
1471.68	115.912
1474.81	112.197
1477.94	106.657
1481.07	100.088
1484.2	95.471
1487.32	92.2367
1490.45	85.4968
1493.57	80.7126
1496.69	75.8483
1499.81	71.537
1502.93	65.7177
1506.05	61.2486
1509.17	56.9883
1512.28	52.6141
1515.4	48.6568
1518.51	44.3863
1521.63	41.4548
1524.74	37.5563
1527.85	32.8121
1530.96	31.2063
1534.06	31.1823
1537.17	30.6649
1540.28	32.1586
1543.38	34.4614
1546.48	37.6755
1549.59	40.8377
1552.69	43.9652
1555.79	46.2482
1558.88	49.5245
1561.98	52.9453
1565.08	55.6145
1568.17	56.2856
1571.27	59.6337
1574.36	64.5563
1577.45	68.4071
1580.54	72.6655
1583.63	77.3718
1586.72	80.9229
1589.8	85.925
1592.89	88.9331
1595.97	92.2276
1599.06	92.636
1602.14	91.3179
1605.22	92.0142
1608.3	93.0112
1611.38	94.2152
1614.46	95.9738
1617.53	98.6656
1620.61	102.794
1623.68	107.266
1626.75	111.571
1629.82	114.263
1632.9	117.144
1635.96	122.436
1639.03	128.215
1642.1	134.2
1645.16	139.604
1648.23	145.264
1651.29	149.802
1654.36	149.515
1657.42	149.965
1660.48	148.663
1663.53	146.627
1666.59	142.712
1669.65	134.889
1672.7	128.005
1675.76	118.711
1678.81	109.311
1681.86	99.2028
1684.91	90.4509
1687.96	80.5756
1691.01	69.7652
1694.06	61.8366
1697.11	53.8279
1700.15	46.9423
1703.2	40.9743
1706.24	35.4217
1709.28	30.3612
1712.32	28.3117
1715.36	26.272
1718.4	23.7123
1721.43	21.9082
1724.47	19.7094
1727.5	18.3013
1730.54	16.0647
1733.57	16.2535
1736.6	15.8813
1739.63	14.307
1742.66	13.608
1745.69	12.8839
1748.72	12.2152
1751.74	10.6347
1754.77	9.5421
1757.79	8.87811
1760.81	6.17662
1763.83	4.50386
1766.85	4.78961
1769.87	4.7506
1772.89	5.59886
1775.91	4.16712
1778.92	3.83408
1781.94	3.2349
1784.95	2.69616
1787.96	2.04933
1790.97	1.97493
1793.98	0.889234
1796.99	1.44887
1800	1.68749
1803	2.26158
1806.01	2.30602
1809.01	2.26896
1812.02	2.27232
1815.02	3.90066
1818.02	4.13644
1821.02	4.25392
1824.02	4.90566
1827.01	4.44411
1830.01	4.05532
1833	4.54455
1836	5.31088
1838.99	6.71647
1841.98	7.13278
1844.97	7.2259
1847.96	7.83621
1850.95	5.86123
1853.94	4.22138
1856.92	3.06204
1859.91	3.22761
1862.89	2.67053
1865.88	2.62481
1868.86	3.21783
1871.84	2.88081
1874.82	2.16141
1877.8	1.92247
1880.77	3.32528
1882.51	4.14603
1885.5	3.85036
1888.48	4.20934
1891.47	4.74176
1894.46	3.90126
1897.44	4.66056
1900.42	5.27655
1903.41	5.84766
1906.39	6.48236
1909.37	7.30643
1912.35	7.30146
1915.32	6.91639
1918.3	6.30973
1921.28	6.25785
1924.25	6.04687
1927.22	6.95377
1930.2	7.86342
1933.17	8.53125
1936.14	8.54765
1939.11	7.93896
1942.08	6.66361
1945.04	7.22914
1948.01	7.72296
1950.97	8.34447
1953.94	7.26158
1956.9	5.31262
1959.86	3.86195
1962.82	4.43655
1965.78	4.32826
1968.74	3.85414
1971.69	3.81053
1974.65	4.13177
1977.61	4.14934
1980.56	5.76129
1983.51	6.0892
1986.46	6.07199
1989.41	6.99317
1992.36	8.51623
1995.31	9.31661
1998.26	9.44508
2001.2	10.0569
2004.15	9.48175
2007.09	10.3565
2010.04	11.3004
2012.98	10.3263
2015.92	12.5233
2018.86	12.8827
2021.8	12.2925
2024.74	11.6044
2027.67	10.7827
2030.61	12.2713
2033.54	13.9407
2036.47	15.548
2039.41	16.8213
2042.34	17.8886
2045.27	19.2696
2048.2	21.5027
2051.12	22.504
2054.05	22.421
2056.98	23.3387
2059.9	22.9899
2062.82	23.3619
2065.75	24.513
2068.67	25.0503
2071.59	26.0689
2074.51	26.7448
2077.43	30.7577
2080.34	32.6784
2083.26	33.9287
2086.17	35.851
2089.09	40.13
2092	41.794
2094.91	44.1433
2097.82	45.8587
2100.73	47.7581
2103.64	51.3311
2106.55	54.363
2109.46	58.0055
2112.36	60.2508
2115.27	63.6478
2118.17	68.8708
2121.07	72.5269
2123.97	77.4348
2126.87	82.8197
2129.77	88.1413
2132.67	95.8647
2135.57	101.674
2138.46	107.764
2141.36	114.519
2144.25	122.316
2147.14	129.812
2150.03	137.611
2152.92	143.994
2155.81	149.951
2158.7	155.934
2161.59	161.17
2164.48	163.04
2167.36	165.139
2170.25	165.981
2173.13	166.914
2176.01	166.87
2178.89	164.714
2181.77	160.763
2184.65	156.816
2187.53	153.765
2190.41	149.818
2193.28	144.753
2196.16	138.688
2199.03	132.148
2201.9	126.054
2204.78	117.74
2207.65	109.886
2210.51	104.395
2213.38	97.2602
2216.25	91.1148
2219.12	85.0148
2221.98	79.0581
2224.85	73.0595
2227.71	68.1665
2230.57	63.7018
2233.43	58.9358
2236.29	53.3435
2239.15	48.2172
2242.01	44.326
2244.87	40.7522
2247.73	36.6342
2250.58	33.8824
2253.43	31.9072
2256.29	29.5466
2259.14	28.5815
2261.99	26.1541
2264.84	24.3326
2267.69	24.3991
2270.54	23.9276
2273.38	23.6134
2276.23	22.2025
2279.07	23.1701
2281.92	23.5958
2284.76	24.2789
2287.6	23.2287
2290.44	22.0096
2293.28	20.2273
2296.12	19.9089
2298.96	19.0606
2301.79	17.7923
2304.63	16.892
2307.46	14.8722
2310.3	13.9689
2313.13	14.2218
2315.96	11.9352
2318.79	11.5917
2321.62	10.8914
2324.45	9.79408
2327.27	9.03166
2330.1	8.19058
2332.93	7.52739
2335.75	7.87229
2338.57	8.20109
2341.4	7.10289
2344.22	6.18704
2347.04	5.47049
2349.86	5.50803
2352.67	4.54655
2355.49	3.48301
2358.31	1.03458
2361.12	0.486348
2363.94	-0.246868
2366.75	-0.35272
2369.56	-0.900545
2372.37	0.445942
2375.18	0.70758
2377.99	1.26407
2380.8	1.56139
2383.61	1.67049
2386.41	3.00398
2389.22	3.50413
2392.02	4.08664
2394.82	3.97191
2397.63	5.43213
2400.43	5.88914
2403.23	5.91153
2406.02	5.99624
2408.82	6.58888
2411.62	5.84977
2414.41	6.53347
2417.21	6.03879
2420	5.86239
2422.79	5.04172
2425.59	4.01282
2428.38	3.33077
2431.17	4.17342
2433.96	4.85563
2436.74	5.26968
2439.53	6.34152
2442.32	7.48115
2445.1	7.14698
2447.88	6.5866
2450.67	7.3781
2453.45	8.05026
2456.23	7.32153
2459.01	6.38269
2461.79	7.15212
2464.57	5.78903
2467.34	4.88245
2470.12	4.55652
2472.89	3.86715
2475.67	3.94634
2478.44	4.90941
2481.21	4.00062
2483.98	3.52293
2486.75	2.70435
2489.52	1.64053
2492.29	0.799821
2495.06	1.73858
2497.82	2.41598
2500.59	1.73761
2503.35	2.09051
2506.11	1.39153
2508.88	1.28642
2511.63	0.503962
2514.39	-0.648453
2517.15	-0.448622
2519.91	0.0203481
2522.67	-0.26229
2525.42	-0.0674556
2528.18	-1.48692
2530.93	-1.89315
2533.69	-1.2463
2536.44	-0.864986
2539.19	-0.949154
2541.94	0.624947
2544.69	1.34442
2547.44	2.85211
2550.18	2.74805
2552.93	4.10289
2555.68	4.97639
2558.42	6.44528
2561.16	8.3871
2563.9	8.83413
2566.64	8.6723
2569.38	8.4688
2572.12	8.07942
2574.86	7.20566
2577.6	7.28286
2580.34	7.28732
2583.07	7.25332
2585.81	6.92566
2588.54	5.39363
2591.27	4.34927
2594	3.41724
2596.73	2.15685
2599.46	1.64805
2602.19	1.70883
2604.92	1.08936
2607.64	1.56809
2610.37	1.59593
2613.09	1.33846
2615.82	2.99687
2618.54	2.13782
2621.26	3.27389
2623.98	4.26903
2626.7	4.39752
2629.42	3.93794
2632.14	3.84719
2634.86	3.82289
2637.57	3.42666
2640.29	3.79551
2643	4.45642
2645.72	4.66583
2648.43	5.33022
2651.14	5.71535
2653.85	5.63167
2656.56	6.7862
2659.27	6.86744
2661.97	7.75118
2664.68	8.50978
2667.38	10.4651
2670.09	10.6575
2672.79	11.17
2675.49	11.3797
2678.2	11.4595
2680.89	11.5909
2683.59	11.6693
2686.29	10.6084
2688.99	9.98168
2691.69	9.33496
2694.38	8.16115
2697.08	7.26806
2699.77	6.2237
2702.46	5.56026
2705.16	5.88828
2707.85	4.68352
2710.54	4.21404
2713.23	5.20555
2715.92	5.93781
2718.6	7.55849
2721.29	8.58942
2723.97	9.166
2726.66	9.20911
2729.34	10.7514
2732.02	11.4339
2734.7	10.9646
2737.39	12.0522
2740.06	12.924
2742.74	13.2096
2745.42	13.2595
2748.1	13.5176
2750.77	13.0109
2753.45	11.4717
2756.12	10.9338
2758.79	10.4554
2761.47	9.5895
2764.14	8.74075
2766.81	8.8314
2769.48	7.31293
2772.14	5.46474
2774.81	3.99187
2777.48	3.79105
2780.14	3.68838
2782.81	3.46854
2785.47	2.91541
2788.13	2.11035
2790.79	1.59389
2793.46	0.829131
2796.11	1.16907
2798.77	0.932061
2801.43	1.67126
2804.09	1.1632
2806.74	0.943951
2809.4	0.971166
2812.05	0.25781
2814.71	1.45879
2817.36	3.52454
2820.01	6.29319
2822.66	11.7998
2825.31	16.5969
2827.96	23.5433
2830.61	30.553
2833.25	37.3585
2835.9	43.0049
2838.54	52.4891
2841.18	63.4418
2843.83	76.3684
2846.47	90.462
2849.11	105.295
2851.75	119.972
2854.39	135.101
2857.03	150.654
2859.67	164.344
2862.3	176.041
2864.94	189.679
2867.57	199.803
2870.21	210.251
2872.84	220.099
2875.47	228.858
2878.1	237.954
2880.73	246.785
2883.36	254.569
2885.99	263.259
2888.61	273.173
2891.24	281.495
2893.87	292.846
2896.49	304.38
2899.11	316.353
2901.74	330.744
2904.36	348.805
2906.98	368.503
2909.6	389.808
2912.22	411.606
2914.83	430.892
2917.45	450.627
2920.07	467.899
2922.68	481.226
2925.3	492.133
2927.91	500.691
2930.52	506.591
2933.13	507.744
2935.74	505.631
2938.35	498.373
2940.96	487.589
2943.57	475.275
2946.18	460.419
2948.78	442.639
2951.39	423.719
2953.99	403.932
2956.6	383.438
2959.2	362.799
2961.8	341.276
2964.4	319.261
2967	299.531
2969.6	282.027
2972.2	264.732
2974.79	246.966
2977.39	228.79
2979.98	211.494
2982.58	194.014
2985.17	177.326
2987.76	160.693
2990.36	145.112
2992.95	130.158
2995.54	115.078
2998.12	101.426
3000.71	88.2284
3003.3	76.2829
3005.88	65.4137
3008.47	55.8839
3011.05	47.1893
3013.64	39.704
3016.22	33.5054
3018.8	27.8086
3021.38	23.5869
3023.96	20.1112
3026.54	16.6362
3029.12	15.3891
3031.69	15.1119
3034.27	15.3923
3036.85	15.7482
3039.42	16.2607
3041.99	18.0599
3044.57	19.004
3047.14	20.441
3049.71	20.8822
3052.28	21.3943
3054.85	20.7109
3057.42	19.7917
3059.98	20.3308
3062.55	18.6745
3065.11	17.9624
3067.68	15.6823
3070.24	14.1084
3072.8	13.174
3075.37	11.0038
3077.93	7.81406
3080.49	6.57369
3083.05	4.31829
3085.61	2.12935
3088.16	0.557148
3090.72	0.445484
3093.27	-0.54678
3095.83	-1.16967
3098.38	-1.2022
3100.94	-1.17751
3103.49	0.0846311
3106.04	0.206647
3108.59	1.50287
3111.14	1.63604
3113.69	2.6968
3116.23	3.56362
3118.78	3.85252
3121.33	5.71084
3123.87	7.34086
3126.42	8.40625
3128.96	9.82603
3131.5	11.5517
3134.04	12.8015
3136.58	14.018
3139.12	14.8348
3141.66	15.7157
3144.2	16.0109
3146.74	16.1999
3149.27	16.7052