File: data/Raman/poly_smoothed/Mb_30_27_16_1x_45s_532 nm_x100_100%_600 gr_mm_01.txt
#Acq. time (s)=	45
#Accumulations=	2
#Range (cm-¹)=	200...3150
#Windows=	2
#Auto scanning=	Off
#Autofocus=	Off
#Macrospot=	Off
#AutoExposure=	Off
#Spike filter=	Multiple accum.
#Delay time (s)=	0
#Binning=	1
#Readout mode=	Signal
#DeNoise=	Off
#ICS correction=	On
#Dark correction=	Off
#Inst. Process=	Off
#Detector Gain=	Best Dynamic Range
#Detector ADC=	20 kHz
#Detector temperature (°C)=	-69.85
#Instrument=	LabRAM HR Evol
#Detector=	Synapse
#Objective=	x100
#Grating=	600 gr/mm
#ND Filter=	100%
#Laser (nm)=	532
#Hole=	100.021
#Range=	Auto
#Laser Pol.=	No
#Raman. Pol.=	No
#Laser Pol. (°)=	-0.0007625
#Raman Pol. (°)=	89.9995
#Collection=	Microscope
#StageXY=	Marzhauser
#StageZ=	Marzhauser
#X (µm)=	-6424.4
#Y (µm)=	853.3
#Z (µm)=	-64.4
#Full time(mm:ss)=	3:18
#Project=
#Sample=
#Site=
#Title=	Mb_30_27_16_2x_45s_532 nm_x100_100%_600 gr_mm
#Remark=
#Date=	13.07.2022 09:49
#Acquired=	13.07.2022 09:49:42
#Base:Fit=	10.08.2022 10:40:03
#Base:Sub=	10.08.2022 10:40:17
#Filter:Polynom=	16.08.2022 10:16:15
#AxisType[0]=Intens
#AxisUnit[0]=Cnt
#AxisType[1]=Spectr
#AxisUnit[1]=1/cm
200.563	27.8537
204.194	23.7273
207.821	18.9009
211.449	15.9911
215.074	13.3688
218.699	11.673
222.321	11.3144
225.941	9.56964
229.562	10.3274
233.18	10.2984
236.796	8.99823
240.411	8.35525
244.026	7.77132
247.638	7.8231
251.248	6.98976
254.857	6.75087
258.465	7.45435
262.071	7.97018
265.678	7.88223
269.282	5.8129
272.884	3.81389
276.484	3.31132
280.084	3.56881
283.682	2.71242
287.276	2.28649
290.871	2.13273
294.465	0.333433
298.057	0.100782
301.648	1.96106
305.237	4.30095
308.823	7.24889
312.41	8.39859
315.995	11.4063
319.579	13.3485
323.16	14.8052
326.741	15.4929
330.321	17.396
333.897	19.0555
337.474	19.3262
341.048	20.6319
344.622	21.2534
348.192	21.4499
351.764	21.2759
355.332	20.4828
358.901	19.9814
362.466	20.9633
366.03	19.6879
369.594	18.547
373.155	17.3917
376.715	14.346
380.273	13.1054
383.832	11.5046
387.388	12.7048
390.942	13.3965
394.495	13.9913
398.047	12.9223
401.597	12.2607
405.145	10.6849
408.693	10.0965
412.239	10.1963
415.783	10.608
419.327	10.625
422.869	9.60088
426.409	9.08595
429.948	8.63825
433.486	8.0425
437.022	7.5575
440.558	7.9658
444.089	6.18174
447.622	6.61053
451.153	7.01706
454.682	7.65034
458.208	5.47743
461.735	5.56463
465.259	5.3766
468.783	5.89257
472.306	6.4646
475.825	6.56709
479.346	6.45396
482.862	6.57994
486.38	6.21465
489.894	6.54169
493.407	8.25244
496.92	8.74551
500.43	9.28778
503.939	10.4591
507.448	10.5905
510.954	10.8235
514.459	11.3684
517.962	11.1725
521.466	11.7427
524.966	10.7423
528.466	10.5021
531.964	10.0699
535.46	11.5723
538.955	11.2787
542.449	9.76727
545.942	8.60078
549.433	9.36648
552.923	10.4116
556.412	10.09
559.899	9.05235
563.385	8.73703
566.867	8.5879
570.35	9.03979
573.832	8.27081
577.313	8.25792
580.79	8.87215
584.268	7.95116
587.745	6.92638
591.218	6.83292
594.692	7.236
598.164	6.13629
601.634	5.06993
605.104	3.6507
608.57	2.99293
612.037	1.52816
615.501	1.53339
618.966	0.803519
622.427	-0.241475
625.887	-0.12228
629.348	-1.8955
632.806	-0.307803
636.262	-0.00302121
639.716	-0.24343
643.172	0.129484
646.624	1.17051
650.075	1.91739
653.524	3.21246
656.972	3.93136
660.419	4.05189
663.865	5.65432
667.309	6.47376
670.752	7.30697
674.194	8.57173
677.634	11.3046
681.073	11.5427
684.511	13.7886
687.947	15.076
691.382	14.5003
694.816	15.7956
698.247	17.5311
701.678	17.9651
705.108	19.1968
708.534	20.3111
711.962	21.9553
715.388	23.3398
718.81	24.8572
722.234	24.8888
725.654	25.8229
729.075	27.2917
732.492	28.568
735.91	29.75
739.325	29.6621
742.741	30.6157
746.153	33.5694
749.564	36.9857
752.976	36.9721
756.385	39.1851
759.792	42.2706
763.2	44.8684
766.604	47.4479
770.008	48.3757
773.41	49.4496
776.811	51.4697
780.21	54.3988
783.608	57.3996
787.005	59.9696
790.401	61.8384
793.795	64.6461
797.188	67.5636
800.58	68.0783
803.971	69.0266
807.36	70.4151
810.748	70.7252
814.135	71.6812
817.518	71.9551
820.902	71.5367
824.285	69.4966
827.665	69.0374
831.045	67.8465
834.424	63.6123
837.8	61.4444
841.177	59.9432
844.55	58.5288
847.924	57.4871
851.295	54.1178
854.666	52.054
858.034	50.0184
861.403	48.3616
864.769	46.6222
868.133	46.2974
871.498	44.7068
874.86	43.1829
878.221	42.0628
881.58	41.575
884.938	41.8997
888.297	41.5038
891.653	41.0991
895.007	39.6842
898.36	39.8796
901.712	37.8162
905.063	36.357
908.412	35.6165
911.76	36.3405
915.107	35.4533
918.452	37.2651
921.797	38.2033
925.138	38.7339
928.48	38.5482
931.82	37.8286
935.16	36.6576
938.496	35.34
941.833	34.3802
945.168	31.8149
948.5	32.5014
951.834	30.1689
955.163	28.8259
958.494	28.463
961.821	27.8444
965.15	28.8567
968.474	28.0227
971.8	27.5167
975.123	26.6009
978.446	25.4902
981.766	25.6919
985.084	25.868
988.402	26.3166
991.72	27.0259
995.035	25.6013
998.349	25.1358
1001.66	23.8762
1004.97	22.4372
1008.28	21.8158
1011.59	24.2906
1014.9	25.5774
1018.21	28.1507
1021.51	29.9431
1024.81	29.6595
1028.12	30.3284
1031.42	32.9066
1034.72	33.6476
1038.02	35.5076
1041.31	35.6351
1044.61	35.4221
1047.91	34.5831
1051.2	33.3757
1054.49	31.7562
1057.78	30.2262
1061.07	27.7444
1064.36	26.1979
1067.65	22.7317
1070.93	19.6513
1074.22	14.3939
1077.5	9.93994
1080.78	7.17602
1084.06	5.32879
1087.34	5.19266
1090.62	5.28493
1093.9	6.45793
1097.17	7.3568
1100.45	7.22814
1103.72	7.16174
1106.99	7.27536
1110.27	9.28305
1113.53	10.4249
1116.8	12.2188
1120.07	12.6203
1123.33	13.3035
1126.6	12.7819
1129.86	13.7613
1133.12	12.971
1136.38	12.5902
1139.64	12.1125
1142.9	11.2998
1146.16	9.50385
1149.41	8.13079
1152.67	6.48523
1155.92	3.97937
1159.17	3.4285
1162.42	2.70317
1165.67	1.8327
1168.92	1.14166
1172.16	0.653945
1175.41	3.07296
1178.65	2.48306
1181.9	3.50039
1185.14	5.14415
1188.38	5.31334
1191.62	6.81346
1194.86	7.01741
1198.09	7.95711
1201.33	8.74912
1204.56	11.3593
1207.8	13.158
1211.03	15.278
1214.26	18.3333
1217.49	21.0569
1220.71	23.8428
1223.94	25.8973
1227.16	28.5428
1230.39	31.609
1233.61	34.0638
1236.83	36.6721
1240.05	39.8104
1243.27	41.7824
1246.49	43.3521
1249.71	45.4983
1252.92	48.7818
1256.14	49.2647
1259.35	49.3813
1262.56	49.7537
1265.77	48.6151
1268.98	49.5933
1272.19	51.4574
1275.4	51.2015
1278.6	51.578
1281.81	53.2457
1285.01	54.422
1288.21	54.1407
1291.41	55.8311
1294.61	56.3465
1297.81	55.763
1301.01	56.4865
1304.2	56.8585
1307.4	56.8062
1310.59	56.4197
1313.78	56.6218
1316.97	56.5794
1320.16	56.0537
1323.35	54.6826
1326.54	54.8613
1329.72	54.1563
1332.91	53.1628
1336.09	52.2677
1339.27	51.0461
1342.45	50.6441
1345.64	49.7768
1348.81	49.0405
1351.99	49.2838
1355.17	47.1805
1358.34	47.7404
1361.51	46.4657
1364.69	45.7309
1367.86	44.6947
1371.03	43.4211
1374.2	40.9348
1377.37	40.6501
1380.53	39.9537
1383.7	39.0131
1386.86	38.2161
1390.02	36.5392
1393.19	34.3326
1396.35	32.1002
1399.51	32.0692
1402.66	32.2249
1405.82	32.7503
1408.97	32.4734
1412.13	33.1941
1415.28	33.0339
1418.43	35.9507
1421.59	37.494
1424.73	41.1337
1427.88	45.5835
1431.03	50.1356
1434.18	52.5353
1437.32	54.0247
1440.46	56.6375
1443.61	57.634
1446.75	59.6635
1449.89	59.7787
1453.03	61.0365
1456.16	61.9954
1459.3	61.5019
1462.44	60.1334
1465.57	56.7625
1468.7	53.4058
1471.83	49.9401
1474.96	48.902
1478.09	47.1601
1481.22	43.8107
1484.35	39.5679
1487.47	35.9446
1490.6	33.2279
1493.72	30.8584
1496.84	29.3165
1499.96	28.2324
1503.08	27.4975
1506.2	26.1205
1509.32	25.5516
1512.44	23.8431
1515.55	22.1662
1518.66	22.6495
1521.78	22.7353
1524.89	22.185
1528	23.6809
1531.11	24.2171
1534.21	25.26
1537.32	27.0462
1540.43	28.2525
1543.53	29.2557
1546.63	31.0039
1549.74	32.4484
1552.84	33.5977
1555.94	32.6009
1559.03	32.3331
1562.13	32.7791
1565.23	34.5602
1568.32	35.5281
1571.42	37.3576
1574.51	39.4015
1577.6	41.1502
1580.69	42.3732
1583.78	43.3314
1586.87	44.7438
1589.95	43.3084
1593.04	43.7778
1596.12	44.6595
1599.21	44.9788
1602.29	45.7839
1605.37	45.6567
1608.45	44.8354
1611.53	43.6257
1614.6	42.8152
1617.68	42.8312
1620.75	43.2074
1623.83	43.5208
1626.9	43.8748
1629.97	44.3828
1633.04	45.7064
1636.11	49.5296
1639.18	52.6093
1642.25	53.7979
1645.31	57.3019
1648.38	58.9908
1651.44	60.1969
1654.5	60.2859
1657.56	60.6176
1660.62	60.9116
1663.68	59.3095
1666.74	57.8624
1669.8	56.5521
1672.85	54.0088
1675.91	50.4365
1678.96	47.486
1682.01	43.1368
1685.06	37.7921
1688.11	34.8129
1691.16	31.5112
1694.21	28.5547
1697.25	25.0059
1700.3	21.9654
1703.34	20.0029
1706.39	19.591
1709.43	18.4164
1712.47	17.1332
1715.51	15.9209
1718.54	14.9924
1721.58	13.4323
1724.62	12.385
1727.65	11.8419
1730.68	12.0919
1733.72	12.5271
1736.75	11.4987
1739.78	11.2
1742.81	10.9443
1745.84	10.8007
1748.86	10.7502
1751.89	9.79919
1754.91	10.108
1757.93	9.2408
1760.96	8.87018
1763.98	7.93279
1767	7.76435
1770.02	6.65125
1773.03	6.64984
1776.05	7.77374
1779.07	7.27352
1782.08	7.43931
1785.09	7.24569
1788.11	7.15077
1791.12	6.65139
1794.13	6.27898
1797.13	6.81204
1800.14	6.53017
1803.15	6.56389
1806.15	5.66679
1809.16	5.47326
1812.16	4.92844
1815.16	5.34101
1818.16	5.62284
1821.16	4.90941
1824.16	5.37148
1827.16	5.84822
1830.16	6.92339
1833.15	6.90879
1836.14	6.69052
1839.14	7.07565
1842.13	6.60493
1845.12	7.07633
1848.11	7.64223
1851.1	6.67261
1854.08	6.19587
1857.07	5.68792
1860.05	5.43011
1863.04	4.79729
1866.02	4.82535
1869	3.94532
1871.98	2.27932
1874.96	0.510007
1877.94	-0.145925
1880.92	0.0149391
1882.51	-0.665028
1885.5	-0.452906
1888.48	0.271682
1891.47	0.923344
1894.46	1.64668
1897.44	2.19411
1900.42	2.8527
1903.41	2.68886
1906.39	3.20593
1909.37	3.97356
1912.35	4.14927
1915.32	4.73074
1918.3	5.43014
1921.27	4.43289
1924.25	3.68166
1927.22	3.68552
1930.19	4.17645
1933.17	3.42515
1936.14	3.46929
1939.11	2.01676
1942.07	0.781587
1945.04	0.314638
1948.01	0.516276
1950.97	0.972621
1953.93	2.10487
1956.9	2.67716
1959.86	3.20626
1962.82	2.72196
1965.78	3.50139
1968.74	3.1526
1971.69	3.44592
1974.65	3.9718
1977.6	3.40665
1980.56	3.43717
1983.51	3.59369
1986.46	2.97291
1989.41	3.21345
1992.36	2.66802
1995.31	2.24914
1998.26	1.20945
2001.2	2.14505
2004.15	2.51622
2007.09	2.61091
2010.04	2.49445
2012.98	2.64265
2015.92	2.72846
2018.86	4.22526
2021.8	5.04342
2024.73	5.99563
2027.67	6.51216
2030.61	6.48074
2033.54	7.034
2036.47	7.3749
2039.4	8.35772
2042.33	9.58911
2045.27	9.51249
2048.19	8.62155
2051.12	8.36292
2054.05	8.8388
2056.97	8.56351
2059.9	8.70534
2062.82	7.72501
2065.74	7.80735
2068.67	8.13584
2071.59	8.63416
2074.51	9.48364
2077.42	10.8826
2080.34	11.2231
2083.26	13.0097
2086.17	14.0184
2089.09	15.897
2092	16.8445
2094.91	17.6376
2097.82	18.2864
2100.73	20.6545
2103.64	22.0861
2106.55	23.2064
2109.45	24.1257
2112.36	25.3211
2115.26	26.1401
2118.17	25.4473
2121.07	26.1278
2123.97	27.4415
2126.87	27.0465
2129.77	28.442
2132.67	30.3617
2135.56	32.0727
2138.46	34.0523
2141.35	36.1264
2144.25	37.3894
2147.14	41.0068
2150.03	43.8748
2152.92	46.4123
2155.81	49.5709
2158.7	52.8907
2161.59	54.9579
2164.47	57.5213
2167.36	59.6311
2170.24	60.9808
2173.13	60.9243
2176.01	61.0482
2178.89	59.8981
2181.77	59.8572
2184.65	58.8525
2187.53	57.2829
2190.4	55.3866
2193.28	53.1929
2196.16	51.2517
2199.03	48.5991
2201.9	46.9205
2204.77	44.2277
2207.64	41.1886
2210.51	37.299
2213.38	34.9223
2216.25	32.7783
2219.12	31.9345
2221.98	29.5496
2224.85	28.7543
2227.71	27.4994
2230.57	25.8263
2233.43	23.8041
2236.29	23.0428
2239.15	21.035
2242.01	20.3289
2244.87	19.3539
2247.72	18.4976
2250.58	17.5521
2253.43	17.4336
2256.29	16.2408
2259.14	16.269
2261.99	15.7579
2264.84	15.6162
2267.69	14.8216
2270.53	14.817
2273.38	14.7026
2276.23	13.9056
2279.07	12.7214
2281.91	13.1729
2284.76	12.3947
2287.6	11.7255
2290.44	10.978
2293.28	8.72527
2296.12	9.20074
2298.96	8.73746
2301.79	10.0616
2304.63	10.4419
2307.46	11.0578
2310.3	11.0193
2313.13	11.6446
2315.96	10.9584
2318.79	10.6066
2321.62	10.7622
2324.45	10.1995
2327.27	10.062
2330.1	10.8512
2332.92	10.2997
2335.75	9.79609
2338.57	9.78686
2341.39	9.2243
2344.21	8.25117
2347.04	6.646
2349.85	5.64222
2352.67	3.72769
2355.49	2.45616
2358.3	2.23487
2361.12	2.12029
2363.93	1.73754
2366.75	3.18132
2369.56	3.40912
2372.37	2.76295
2375.18	1.81756
2377.99	1.82532
2380.8	1.2018
2383.6	2.06799
2386.41	2.01561
2389.21	2.26891
2392.02	1.57732
2394.82	1.77285
2397.62	1.36625
2400.42	1.36776
2403.22	1.58544
2406.02	2.15866
2408.82	2.48538
2411.62	1.90224
2414.41	1.92383
2417.21	2.29742
2420	3.02694
2422.79	3.85313
2425.59	4.82643
2428.38	5.69406
2431.17	4.79608
2433.95	5.51773
2436.74	6.19966
2439.53	5.43033
2442.31	5.34783
2445.1	5.3064
2447.88	4.93711
2450.67	4.63779
2453.45	4.62152
2456.23	4.75387
2459.01	4.98532
2461.79	5.55467
2464.57	5.74617
2467.34	6.04831
2470.12	6.49922
2472.89	6.88676
2475.67	7.20895
2478.44	6.08889
2481.21	6.14513
2483.98	6.48687
2486.75	6.54206
2489.52	6.61701
2492.29	5.80338
2495.05	5.61839
2497.82	4.33919
2500.58	3.50601
2503.35	3.10525
2506.11	1.9425
2508.87	0.362786
2511.63	0.457656
2514.39	-0.394522
2517.15	-0.614306
2519.91	0.499326
2522.67	1.36683
2525.42	2.36752
2528.18	3.49772
2530.93	3.63489
2533.69	5.33928
2536.44	5.26401
2539.19	5.89317
2541.94	5.49001
2544.69	5.82694
2547.44	5.51595
2550.18	5.71644
2552.93	5.58964
2555.67	5.54241
2558.42	5.16434
2561.16	4.23403
2563.9	3.1497
2566.64	2.92555
2569.38	2.80189
2572.12	2.04331
2574.86	1.08772
2577.6	1.66046
2580.33	1.70938
2583.07	2.03688
2585.8	2.78067
2588.54	2.5097
2591.27	2.98168
2594	3.02945
2596.73	2.99406
2599.46	3.06271
2602.19	2.8137
2604.92	2.0815
2607.64	2.27644
2610.37	1.71473
2613.09	2.73622
2615.82	3.34586
2618.54	3.57702
2621.26	4.50892
2623.98	4.98248
2626.7	4.65999
2629.42	4.95713
2632.14	5.40931
2634.86	5.54635
2637.57	4.97206
2640.29	5.63002
2643	6.32969
2645.71	6.08433
2648.43	5.84119
2651.14	6.22645
2653.85	6.13758
2656.56	4.92199
2659.26	4.32885
2661.97	3.60907
2664.68	3.71432
2667.38	3.75703
2670.09	3.95064
2672.79	3.97
2675.49	4.35952
2678.19	5.49522
2680.89	6.40736
2683.59	6.2298
2686.29	6.85467
2688.99	6.87022
2691.69	7.57637
2694.38	6.80052
2697.08	6.77711
2699.77	6.67691
2702.46	6.94399
2705.15	7.13167
2707.85	6.92125
2710.54	6.58613
2713.22	6.57809
2715.91	6.41621
2718.6	6.45079
2721.29	5.6596
2723.97	5.49371
2726.66	6.40782
2729.34	6.66504
2732.02	7.13119
2734.7	6.80049
2737.38	6.95943
2740.06	7.28234
2742.74	8.02587
2745.42	8.51508
2748.09	7.72377
2750.77	7.5968
2753.45	6.78883
2756.12	6.35837
2758.79	5.53072
2761.46	4.58446
2764.14	3.89339
2766.8	3.85759
2769.47	2.57968
2772.14	2.20013
2774.81	1.072
2777.48	1.26086
2780.14	0.459849
2782.8	0.34152
2785.47	0.292234
2788.13	0.577887
2790.79	0.541474
2793.45	0.73066
2796.11	-0.178562
2798.77	-0.180513
2801.43	0.430559
2804.09	0.755403
2806.74	0.840002
2809.4	0.926435
2812.05	1.12489
2814.71	1.22411
2817.36	1.40307
2820.01	2.51875
2822.66	4.38161
2825.31	6.19376
2827.96	7.43422
2830.6	10.5581
2833.25	13.3268
2835.9	15.5261
2838.54	18.9525
2841.18	22.4807
2843.83	27.6016
2846.47	32.0247
2849.11	38.1006
2851.75	43.0261
2854.39	49.3539
2857.03	54.5328
2859.66	60.8707
2862.3	66.941
2864.94	72.6017
2867.57	77.3185
2870.2	81.5906
2872.84	86.2477
2875.47	90.4691
2878.1	94.2938
2880.73	98.6604
2883.36	101.963
2885.99	105.963
2888.61	109.295
2891.24	112.793
2893.86	116.229
2896.49	120.596
2899.11	124.104
2901.73	129.185
2904.36	134.37
2906.98	140.959
2909.6	148.78
2912.21	156.52
2914.83	165.016
2917.45	173.282
2920.07	180.768
2922.68	186.611
2925.29	192.596
2927.91	196.391
2930.52	198.353
2933.13	199.333
2935.74	199.117
2938.35	197.816
2940.96	193.856
2943.57	190.367
2946.18	184.351
2948.78	176.948
2951.39	170.979
2953.99	162.431
2956.59	154.233
2959.2	145.563
2961.8	137.423
2964.4	129.168
2967	121.868
2969.6	114.592
2972.19	108.455
2974.79	103.069
2977.39	96.2595
2979.98	89.068
2982.58	83.1142
2985.17	76.0648
2987.76	70.228
2990.35	64.1318
2992.94	57.1584
2995.53	51.0257
2998.12	45.7607
3000.71	40.094
3003.3	33.8535
3005.88	28.7277
3008.47	24.2877
3011.05	19.8362
3013.64	16.53
3016.22	13.0564
3018.8	10.9024
3021.38	8.9172
3023.96	7.64764
3026.54	7.08557
3029.12	5.80394
3031.69	5.32492
3034.27	4.63428
3036.84	4.38432
3039.42	3.8961
3041.99	3.99933
3044.57	5.42451
3047.14	5.61621
3049.71	6.00793
3052.28	5.81634
3054.85	5.00258
3057.41	5.6256
3059.98	5.86931
3062.55	5.22024
3065.11	3.71593
3067.68	3.34524
3070.24	3.66991
3072.8	3.0844
3075.36	3.36648
3077.93	3.83175
3080.49	3.0477
3083.04	2.90685
3085.6	2.26031
3088.16	1.59854
3090.72	1.42951
3093.27	1.87
3095.83	1.40419
3098.38	2.00302
3100.93	2.75171
3103.49	3.51985
3106.04	3.88003
3108.59	4.20227
3111.14	3.92761
3113.69	3.696
3116.23	4.20021
3118.78	5.28566
3121.33	5.96849
3123.87	5.98933
3126.41	6.42099
3128.96	6.89205
3131.5	8.37299
3134.04	9.73992
3136.58	11.0363
3139.12	12.0048
3141.66	12.605
3144.2	13.9706
3146.74	16.1464
3149.27	20.0522