File: data/Raman/poly_smoothed/Mb_30_27_34_1x_45s_532 nm_x100_100%_600 gr_mm_01.txt
#Acq. time (s)=	45
#Accumulations=	2
#Range (cm-¹)=	200...3150
#Windows=	2
#Auto scanning=	Off
#Autofocus=	Off
#Macrospot=	Off
#AutoExposure=	Off
#Spike filter=	Multiple accum.
#Delay time (s)=	0
#Binning=	1
#Readout mode=	Signal
#DeNoise=	Off
#ICS correction=	On
#Dark correction=	Off
#Inst. Process=	Off
#Detector Gain=	Best Dynamic Range
#Detector ADC=	20 kHz
#Detector temperature (°C)=	-69.85
#Instrument=	LabRAM HR Evol
#Detector=	Synapse
#Objective=	x100
#Grating=	600 gr/mm
#ND Filter=	100%
#Laser (nm)=	532
#Hole=	100.021
#Range=	Auto
#Laser Pol.=	No
#Raman. Pol.=	No
#Laser Pol. (°)=	-0.0007625
#Raman Pol. (°)=	89.9995
#Collection=	Microscope
#StageXY=	Marzhauser
#StageZ=	Marzhauser
#X (µm)=	-6356.8
#Y (µm)=	812.8
#Z (µm)=	-64.95
#Full time(mm:ss)=	3:18
#Project=
#Sample=
#Site=
#Title=	Mb_30_27_34_2x_45s_532 nm_x100_100%_600 gr_mm
#Remark=
#Date=	13.07.2022 11:15
#Acquired=	13.07.2022 11:15:41
#Edit:Spike=	13.07.2022 11:20:01
#Base:Fit=	10.08.2022 10:40:03
#Base:Sub=	10.08.2022 10:40:17
#Filter:Polynom=	16.08.2022 10:16:15
#AxisType[0]=Intens
#AxisUnit[0]=Cnt
#AxisType[1]=Spectr
#AxisUnit[1]=1/cm
200.563	66.8556
204.194	62.4287
207.821	57.2479
211.449	51.9511
215.074	45.613
218.699	38.0141
222.321	31.409
225.941	26.0079
229.562	23.6783
233.18	21.4766
236.796	19.217
240.411	17.3303
244.026	15.0954
247.638	14.0917
251.248	13.951
254.857	11.792
258.465	10.1071
262.071	8.81243
265.678	8.38871
269.282	8.20482
272.884	9.06246
276.484	8.19905
280.084	6.82598
283.682	6.97432
287.276	8.37817
290.871	8.39473
294.465	8.21691
298.057	7.78794
301.648	5.60415
305.237	3.55465
308.823	3.29125
312.41	4.04628
315.995	5.71307
319.579	7.1916
323.16	8.09441
326.741	8.77509
330.321	9.06521
333.897	9.28756
337.474	9.56621
341.048	9.90125
344.622	8.78737
348.192	7.19928
351.764	6.52457
355.332	6.56082
358.901	5.47819
362.466	4.85497
366.03	4.19626
369.594	5.58703
373.155	6.48911
376.715	8.27632
380.273	8.1031
383.832	8.12331
387.388	8.29048
390.942	8.41191
394.495	7.30427
398.047	8.1016
401.597	7.90885
405.145	7.9725
408.693	7.87573
412.239	7.94291
415.783	7.20117
419.327	6.85561
422.869	4.90746
426.409	6.4229
429.948	4.67382
433.486	2.57521
437.022	2.29226
440.558	2.36896
444.089	3.09798
447.622	3.78747
451.153	6.71661
454.682	7.94258
458.208	9.62358
461.735	9.37591
465.259	11.5947
468.783	12.8309
472.306	14.4598
475.825	16.2907
479.346	17.4634
482.862	17.6666
486.38	19.0795
489.894	21.9377
493.407	23.6779
496.92	25.4502
500.43	28.5531
503.939	28.8505
507.448	29.4335
510.954	30.4269
514.459	30.8755
517.962	31.7
521.466	32.2329
524.966	32.005
528.466	32.7129
531.964	33.3842
535.46	32.8996
538.955	31.7358
542.449	28.8655
545.942	26.4352
549.433	24.04
552.923	22.8293
556.412	22.291
559.899	20.4649
563.385	15.7181
566.867	14.317
570.35	10.9505
573.832	10.3435
577.313	9.00733
580.79	9.04469
584.268	7.48866
587.745	6.55823
591.218	4.95497
594.692	5.30395
598.164	5.84283
601.634	6.87611
605.104	8.15717
608.57	8.637
612.037	9.93381
615.501	12.0614
618.966	14.1253
622.427	14.8392
625.887	17.2094
629.348	18.3298
632.806	18.9943
636.262	21.2044
639.716	22.1153
643.172	21.6038
646.624	19.7059
650.075	20.5662
653.524	21.2339
656.972	21.3482
660.419	23.4966
663.865	24.923
667.309	24.8943
670.752	26.5259
674.194	29.6772
677.634	31.8296
681.073	33.1547
684.511	36.8311
687.947	38.2744
691.382	39.8778
694.816	42.0896
698.247	43.7299
701.678	46.0614
705.108	46.0897
708.534	47.2901
711.962	47.8599
715.388	49.389
718.81	50.1138
722.234	50.1266
725.654	49.0644
729.075	49.1379
732.492	49.6838
735.91	49.4982
739.325	49.5011
742.741	49.1388
746.153	50.64
749.564	51.6883
752.976	54.5785
756.385	57.9742
759.792	61.1494
763.2	64.7023
766.604	67.0832
770.008	69.3218
773.41	71.1939
776.811	74.1581
780.21	73.7781
783.608	75.0716
787.005	75.9725
790.401	77.4365
793.795	80.9195
797.188	82.9306
800.58	86.0618
803.971	86.0863
807.36	84.5429
810.748	86.0265
814.135	87.4141
817.518	85.7006
820.902	85.4515
824.285	84.8166
827.665	85.0334
831.045	85.4975
834.424	86.263
837.8	85.4057
841.177	82.9688
844.55	81.4631
847.924	79.2663
851.295	76.6963
854.666	73.5752
858.034	71.0937
861.403	67.9751
864.769	64.2237
868.133	60.5407
871.498	58.9173
874.86	56.8447
878.221	55.3277
881.58	54.5536
884.938	52.2427
888.297	51.0009
891.653	50.5081
895.007	50.1764
898.36	49.5748
901.712	48.9916
905.063	48.5358
908.412	48.1757
911.76	49.0585
915.107	48.3655
918.452	47.9116
921.797	45.8407
925.138	45.8007
928.48	44.3142
931.82	43.0158
935.16	43.6718
938.496	43.8305
941.833	41.8454
945.168	39.7961
948.5	38.9803
951.834	39.4558
955.163	39.4189
958.494	37.8301
961.821	38.7571
965.15	39.0063
968.474	39.157
971.8	40.6371
975.123	40.2126
978.446	39.4115
981.766	40.141
985.084	40.1648
988.402	40.5535
991.72	39.6805
995.035	37.094
998.349	33.6265
1001.66	31.0722
1004.97	29.8141
1008.28	31.5761
1011.59	33.843
1014.9	38.3426
1018.21	40.9882
1021.51	41.074
1024.81	43.9929
1028.12	45.4961
1031.42	48.105
1034.72	46.8673
1038.02	46.3866
1041.31	45.2068
1044.61	45.7462
1047.91	46.2806
1051.2	45.9422
1054.49	44.9291
1057.78	43.4454
1061.07	41.2585
1064.36	39.8099
1067.65	36.2905
1070.93	32.7611
1074.22	28.8553
1077.5	24.6032
1080.78	23.8255
1084.06	23.0908
1087.34	25.6221
1090.62	26.3608
1093.9	27.1914
1097.17	27.5523
1100.45	26.6062
1103.72	27.7044
1106.99	28.3845
1110.27	27.0628
1113.53	27.7733
1116.8	26.2366
1120.07	25.7902
1123.33	26.5563
1126.6	26.7175
1129.86	26.6468
1133.12	25.7408
1136.38	25.4723
1139.64	23.9431
1142.9	23.4483
1146.16	20.5963
1149.41	18.9009
1152.67	18.1124
1155.92	15.0827
1159.17	12.8833
1162.42	9.65227
1165.67	6.43022
1168.92	6.06274
1172.16	4.41259
1175.41	4.32819
1178.65	2.74432
1181.9	3.02239
1185.14	2.00374
1188.38	1.62225
1191.62	2.62163
1194.86	2.10067
1198.09	2.81349
1201.33	4.80252
1204.56	7.00109
1207.8	10.8327
1211.03	14.0979
1214.26	18.9113
1217.49	22.7989
1220.71	26.9979
1223.94	30.9369
1227.16	37.5937
1230.39	42.0946
1233.61	45.2858
1236.83	49.6564
1240.05	53.8587
1243.27	56.283
1246.49	60.6075
1249.71	64.6664
1252.92	65.1825
1256.14	65.6317
1259.35	68.8404
1262.56	69.7133
1265.77	71.1057
1268.98	73.2608
1272.19	74.5419
1275.4	76.1722
1278.6	78.3229
1281.81	79.312
1285.01	81.4401
1288.21	83.3672
1291.41	85.5451
1294.61	87.5227
1297.81	89.69
1301.01	88.0643
1304.2	91.1811
1307.4	93.0567
1310.59	93.0244
1313.78	93.5998
1316.97	94.7936
1320.16	93.1936
1323.35	91.9514
1326.54	92.0946
1329.72	88.6114
1332.91	88.0798
1336.09	88.4612
1339.27	85.8607
1342.45	81.6789
1345.64	79.4083
1348.81	76.7873
1351.99	74.4355
1355.17	70.5228
1358.34	68.3469
1361.51	65.0123
1364.69	62.7781
1367.86	60.5892
1371.03	58.1913
1374.2	54.9934
1377.37	53.354
1380.53	51.0479
1383.7	50.8876
1386.86	48.198
1390.02	45.1522
1393.19	45.9211
1396.35	43.5397
1399.51	41.988
1402.66	39.4827
1405.82	39.535
1408.97	39.884
1412.13	42.6825
1415.28	43.7554
1418.43	44.5284
1421.59	47.8178
1424.73	55.018
1427.88	63.2442
1431.03	69.561
1434.18	76.7318
1437.32	83.7388
1440.46	87.9931
1443.61	92.6481
1446.75	95.2761
1449.89	95.4244
1453.03	96.8225
1456.16	96.9618
1459.3	96.8376
1462.44	94.6586
1465.57	92.869
1468.7	93.2677
1471.83	91.9391
1474.96	87.8885
1478.09	85.3102
1481.22	82.8223
1484.35	81.5905
1487.47	80.6243
1490.6	77.7217
1493.72	74.2888
1496.84	72.7409
1499.96	70.2638
1503.08	67.7634
1506.2	64.924
1509.32	59.8221
1512.44	55.0377
1515.55	48.1428
1518.66	42.355
1521.78	36.923
1524.89	32.0024
1528	27.4057
1531.11	25.6182
1534.21	24.7665
1537.32	24.4445
1540.43	23.9285
1543.53	25.6346
1546.63	28.1137
1549.74	30.3898
1552.84	32.5267
1555.94	36.3035
1559.03	39.7508
1562.13	42.8038
1565.23	45.5528
1568.32	49.8977
1571.42	53.4817
1574.51	57.6177
1577.6	61.0795
1580.69	65.2566
1583.78	69.36
1586.87	71.3904
1589.95	73.5929
1593.04	74.8763
1596.12	76.629
1599.21	77.9405
1602.29	78.7065
1605.37	79.0034
1608.45	78.5601
1611.53	79.1383
1614.6	77.7378
1617.68	77.8751
1620.75	78.5521
1623.83	81.6337
1626.9	81.4814
1629.97	82.9036
1633.04	85.999
1636.11	86.9786
1639.18	89.9785
1642.25	93.2953
1645.31	95.4125
1648.38	99.5545
1651.44	101.997
1654.5	101.844
1657.56	101.188
1660.62	99.872
1663.68	97.1823
1666.74	94.3
1669.8	89.1131
1672.85	82.3032
1675.91	77.1441
1678.96	68.8144
1682.01	61.9725
1685.06	55.2898
1688.11	48.7586
1691.16	42.0531
1694.21	37.6715
1697.25	33.4593
1700.3	28.554
1703.34	23.716
1706.39	19.7005
1709.43	17.4222
1712.47	14.0949
1715.51	12.5718
1718.54	12.3962
1721.58	12.6061
1724.62	11.2479
1727.65	11.0193
1730.68	10.3076
1733.72	10.2298
1736.75	11.299
1739.78	10.766
1742.81	10.4585
1745.84	8.50502
1748.86	8.71665
1751.89	6.86995
1754.91	6.97095
1757.93	6.20411
1760.96	4.99461
1763.98	5.12987
1767	3.17269
1770.02	2.43722
1773.03	1.2789
1776.05	-0.186955
1779.07	-0.689691
1782.08	-1.20319
1785.09	-1.44869
1788.11	-2.14671
1791.12	-0.714554
1794.13	-0.204366
1797.13	0.17043
1800.14	0.995895
1803.15	0.868613
1806.15	1.5095
1809.16	2.46562
1812.16	3.3599
1815.16	5.02666
1818.16	5.0777
1821.16	4.93955
1824.16	4.36386
1827.16	3.73262
1830.16	3.97111
1833.15	4.03803
1836.14	3.91556
1839.14	3.3585
1842.13	3.39998
1845.12	4.1534
1848.11	2.94427
1851.1	2.43277
1854.08	2.5494
1857.07	3.30511
1860.05	2.76085
1863.04	4.58715
1866.02	4.36781
1869	3.95626
1871.98	4.29756
1874.96	5.54544
1877.94	5.04964
1880.92	5.76328
1882.51	6.28497
1885.5	7.2296
1888.48	6.67529
1891.47	6.99581
1894.46	7.12289
1897.44	8.32583
1900.42	11.2525
1903.41	11.7958
1906.39	13.0838
1909.37	11.8921
1912.35	14.5392
1915.32	14.5537
1918.3	15.1346
1921.27	15.9806
1924.25	17.1193
1927.22	17.6005
1930.19	16.8534
1933.17	15.5582
1936.14	15.6181
1939.11	13.3728
1942.07	12.8333
1945.04	10.8602
1948.01	12.2849
1950.97	12.2504
1953.93	11.5372
1956.9	10.9363
1959.86	10.0852
1962.82	9.7169
1965.78	10.4217
1968.74	11.6525
1971.69	10.9689
1974.65	10.4967
1977.6	10.0186
1980.56	8.8578
1983.51	10.7831
1986.46	10.1183
1989.41	11.6242
1992.36	12.2271
1995.31	13.2677
1998.26	11.4058
2001.2	12.0552
2004.15	11.5442
2007.09	11.3424
2010.04	14.6873
2012.98	16.1644
2015.92	17.8186
2018.86	19.9348
2021.8	23.041
2024.73	23.4986
2027.67	25.0021
2030.61	26.0884
2033.54	26.5732
2036.47	27.4353
2039.4	28.9935
2042.33	27.3624
2045.27	25.9353
2048.19	24.3205
2051.12	24.6446
2054.05	26.5815
2056.97	27.0821
2059.9	27.7277
2062.82	28.6983
2065.74	27.8927
2068.67	27.7179
2071.59	28.0114
2074.51	28.2115
2077.42	30.4038
2080.34	33.8729
2083.26	35.7367
2086.17	35.9084
2089.09	38.6325
2092	40.3343
2094.91	41.5075
2097.82	42.0326
2100.73	44.2405
2103.64	46.3457
2106.55	48.8414
2109.45	50.2601
2112.36	51.0615
2115.26	54.4023
2118.17	58.3558
2121.07	60.8279
2123.97	65.0688
2126.87	70.7922
2129.77	73.4607
2132.67	79.5751
2135.56	84.4501
2138.46	87.8167
2141.35	93.3681
2144.25	99.1659
2147.14	104.323
2150.03	109.591
2152.92	114.876
2155.81	120.387
2158.7	124.664
2161.59	129.35
2164.47	131.88
2167.36	133.86
2170.24	135.799
2173.13	137.595
2176.01	138.007
2178.89	135.301
2181.77	132.178
2184.65	129.861
2187.53	124.729
2190.4	119.985
2193.28	114.401
2196.16	109.783
2199.03	104.939
2201.9	100.26
2204.77	94.9395
2207.64	89.2087
2210.51	84.8645
2213.38	80.1103
2216.25	74.8667
2219.12	71.4665
2221.98	68.1727
2224.85	64.428
2227.71	59.6276
2230.57	54.5306
2233.43	52.598
2236.29	49.5367
2239.15	45.089
2242.01	42.1583
2244.87	42.3075
2247.72	39.3631
2250.58	36.7729
2253.43	34.2487
2256.29	33.3144
2259.14	33.133
2261.99	31.0002
2264.84	31.918
2267.69	32.8166
2270.53	32.5234
2273.38	32.3971
2276.23	31.8332
2279.07	31.9039
2281.91	31.0402
2284.76	30.5402
2287.6	27.9426
2290.44	26.3057
2293.28	23.6154
2296.12	21.2261
2298.96	19.7856
2301.79	21.5288
2304.63	22.9599
2307.46	20.7484
2310.3	20.8472
2313.13	20.8147
2315.96	19.3327
2318.79	20.1623
2321.62	18.4953
2324.45	17.5305
2327.27	16.9441
2330.1	16.5783
2332.92	15.4058
2335.75	15.3305
2338.57	13.9463
2341.39	13.6688
2344.21	11.4551
2347.04	9.97242
2349.85	8.94812
2352.67	6.53078
2355.49	5.49647
2358.3	2.50886
2361.12	1.24642
2363.93	2.00255
2366.75	2.18579
2369.56	2.62882
2372.37	2.46116
2375.18	1.84301
2377.99	1.42158
2380.8	0.55197
2383.6	0.488075
2386.41	1.24092
2389.21	2.17154
2392.02	2.03832
2394.82	3.15084
2397.62	4.72261
2400.42	5.0792
2403.22	6.11697
2406.02	8.16746
2408.82	8.40365
2411.62	10.1139
2414.41	9.25507
2417.21	10.0003
2420	10.8861
2422.79	11.3677
2425.59	10.6549
2428.38	10.1431
2431.17	9.83546
2433.95	8.33093
2436.74	7.09586
2439.53	7.50795
2442.31	5.55837
2445.1	4.40914
2447.88	3.44481
2450.67	2.75261
2453.45	1.88947
2456.23	2.66421
2459.01	3.43415
2461.79	4.73541
2464.57	5.7457
2467.34	5.89676
2470.12	6.52861
2472.89	7.24634
2475.67	7.85156
2478.44	8.05169
2481.21	9.32224
2483.98	8.94869
2486.75	9.96689
2489.52	9.60471
2492.29	7.97438
2495.05	5.62792
2497.82	4.5863
2500.58	3.75618
2503.35	2.06922
2506.11	1.82758
2508.87	0.330389
2511.63	-0.938172
2514.39	0.231817
2517.15	-1.03969
2519.91	0.928746
2522.67	1.30374
2525.42	2.50826
2528.18	4.98212
2530.93	6.32684
2533.69	6.68607
2536.44	8.35009
2539.19	8.7373
2541.94	10.4498
2544.69	10.873
2547.44	10.9572
2550.18	10.5427
2552.93	9.28852
2555.67	9.67697
2558.42	8.55781
2561.16	6.80184
2563.9	6.53083
2566.64	7.79351
2569.38	4.82158
2572.12	4.74542
2574.86	4.5899
2577.6	4.58303
2580.33	4.09037
2583.07	3.40445
2585.8	2.60191
2588.54	3.9632
2591.27	5.16967
2594	4.80061
2596.73	6.17985
2599.46	5.96845
2602.19	7.77468
2604.92	7.70612
2607.64	6.16173
2610.37	5.94897
2613.09	7.15965
2615.82	7.3198
2618.54	8.13556
2621.26	8.55202
2623.98	9.69676
2626.7	9.35298
2629.42	9.92162
2632.14	10.67
2634.86	9.26584
2637.57	9.30163
2640.29	8.74795
2643	7.10676
2645.71	6.27698
2648.43	6.20853
2651.14	4.9892
2653.85	5.21215
2656.56	5.14362
2659.26	4.68779
2661.97	6.13938
2664.68	6.97502
2667.38	9.23022
2670.09	8.96135
2672.79	9.73612
2675.49	11.8441
2678.19	13.2424
2680.89	12.7251
2683.59	12.9362
2686.29	14.8693
2688.99	13.9031
2691.69	13.8265
2694.38	14.3469
2697.08	13.7342
2699.77	13.4738
2702.46	13.8949
2705.15	13.8766
2707.85	13.7968
2710.54	13.1799
2713.22	13.9998
2715.91	14.2249
2718.6	14.3059
2721.29	15.1407
2723.97	14.7255
2726.66	15.847
2729.34	15.9763
2732.02	16.9453
2734.7	17.1325
2737.38	16.1845
2740.06	14.6695
2742.74	13.7594
2745.42	11.9096
2748.09	9.67815
2750.77	8.68206
2753.45	7.68196
2756.12	7.61066
2758.79	6.51182
2761.46	5.21261
2764.14	4.06214
2766.8	4.20015
2769.47	3.26474
2772.14	3.44972
2774.81	3.06812
2777.48	2.56694
2780.14	2.72584
2782.8	1.98829
2785.47	1.91687
2788.13	2.06024
2790.79	3.04402
2793.45	2.99033
2796.11	3.17599
2798.77	3.93494
2801.43	2.92537
2804.09	1.85665
2806.74	0.293922
2809.4	2.13054
2812.05	2.21144
2814.71	3.67612
2817.36	6.72399
2820.01	9.06779
2822.66	12.8342
2825.31	18.1493
2827.96	22.895
2830.6	29.8509
2833.25	34.6536
2835.9	41.0574
2838.54	48.3173
2841.18	57.6053
2843.83	67.1526
2846.47	77.6247
2849.11	89.25
2851.75	102.004
2854.39	115.2
2857.03	126.966
2859.66	137.556
2862.3	147.553
2864.94	156.873
2867.57	163.894
2870.2	170.883
2872.84	177.93
2875.47	183.674
2878.1	189.287
2880.73	195.273
2883.36	199.906
2885.99	203.757
2888.61	210.259
2891.24	216.323
2893.86	222.151
2896.49	228.446
2899.11	236.581
2901.73	249.023
2904.36	262.801
2906.98	277.913
2909.6	293.688
2912.21	310.777
2914.83	328.605
2917.45	343.607
2920.07	356.636
2922.68	369.356
2925.29	378.271
2927.91	384.339
2930.52	388.599
2933.13	389.823
2935.74	386.693
2938.35	382.562
2940.96	374.966
2943.57	364.975
2946.18	352.249
2948.78	338.553
2951.39	323.617
2953.99	308.215
2956.59	291.673
2959.2	275.111
2961.8	260.887
2964.4	246.971
2967	232.686
2969.6	218.852
2972.19	206.771
2974.79	192.878
2977.39	179.303
2979.98	165.737
2982.58	150.534
2985.17	138.964
2987.76	127.437
2990.35	113.659
2992.94	101.792
2995.53	91.1458
2998.12	79.6612
3000.71	68.4277
3003.3	59.1312
3005.88	48.3399
3008.47	39.0052
3011.05	32.8444
3013.64	24.7479
3016.22	19.9165
3018.8	15.0309
3021.38	11.1797
3023.96	8.28093
3026.54	6.52397
3029.12	5.5144
3031.69	4.4452
3034.27	4.44852
3036.84	4.58251
3039.42	5.20116
3041.99	5.24604
3044.57	6.4479
3047.14	8.84457
3049.71	10.4983
3052.28	11.0857
3054.85	12.098
3057.41	12.5378
3059.98	12.5278
3062.55	10.4748
3065.11	10.0198
3067.68	7.86169
3070.24	7.04363
3072.8	6.05217
3075.36	6.01921
3077.93	2.863
3080.49	1.15522
3083.04	0.763681
3085.6	-0.146236
3088.16	-0.746612
3090.72	0.0842035
3093.27	-0.31786
3095.83	-0.666573
3098.38	-0.680191
3100.93	-0.3886
3103.49	0.664535
3106.04	0.952382
3108.59	1.19131
3111.14	1.43478
3113.69	2.17849
3116.23	4.20343
3118.78	6.04561
3121.33	6.09649
3123.87	6.38321
3126.41	7.84163
3128.96	9.03559
3131.5	9.96365
3134.04	10.5837
3136.58	12.2994
3139.12	13.4587
3141.66	15.0867
3144.2	16.0682
3146.74	16.1544
3149.27	14.5582