File: data/Raman/poly_smoothed/Mb_30_27_03_1x_45s_532 nm_x100_100%_600 gr_mm_01.txt
#Acq. time (s)=	45
#Accumulations=	2
#Range (cm-¹)=	200...3150
#Windows=	2
#Auto scanning=	Off
#Autofocus=	Off
#Macrospot=	Off
#AutoExposure=	Off
#Spike filter=	Multiple accum.
#Delay time (s)=	0
#Binning=	1
#Readout mode=	Signal
#DeNoise=	Off
#ICS correction=	On
#Dark correction=	Off
#Inst. Process=	Off
#Detector Gain=	Best Dynamic Range
#Detector ADC=	20 kHz
#Detector temperature (°C)=	-69.85
#Instrument=	LabRAM HR Evol
#Detector=	Synapse
#Objective=	x100
#Grating=	600 gr/mm
#ND Filter=	100%
#Laser (nm)=	532
#Hole=	100.021
#Range=	Auto
#Laser Pol.=	No
#Raman. Pol.=	No
#Laser Pol. (°)=	-0.0007625
#Raman Pol. (°)=	89.9995
#Collection=	Microscope
#StageXY=	Marzhauser
#StageZ=	Marzhauser
#X (µm)=	28061.2
#Y (µm)=	-557.8
#Z (µm)=	1083.7
#Full time(mm:ss)=	3:18
#Project=
#Sample=
#Site=
#Title=	Mb_30_27_03_2x_45s_532 nm_x100_100%_600 gr_mm
#Remark=
#Date=	12.07.2022 15:39
#Acquired=	12.07.2022 15:39:39
#Base:Fit=	10.08.2022 10:39:47
#Base:Sub=	10.08.2022 10:39:55
#Base:Fit=	10.08.2022 10:40:03
#Base:Sub=	10.08.2022 10:40:17
#Filter:Polynom=	16.08.2022 10:16:15
#AxisType[0]=Intens
#AxisUnit[0]=Cnt
#AxisType[1]=Spectr
#AxisUnit[1]=1/cm
200.388	61.5861
204.019	47.42
207.646	36.5453
211.274	29.3056
214.899	23.7358
218.524	20.1349
222.146	18.3175
225.766	15.5832
229.388	11.4814
233.005	10.3639
236.621	9.61838
240.236	8.37427
243.852	8.648
247.464	8.05452
251.074	9.41295
254.683	9.15941
258.291	10.3739
261.897	9.92897
265.504	10.5057
269.108	9.53717
272.71	6.44687
276.311	5.82393
279.91	2.66118
283.508	1.69899
287.105	2.15197
290.698	1.46573
294.291	2.38656
297.884	4.69496
301.475	5.51598
305.064	5.1336
308.652	6.1105
312.237	6.05836
315.822	6.39693
319.406	7.47551
322.987	7.2595
326.568	7.98118
330.148	8.5023
333.724	9.49701
337.301	10.3005
340.875	12.0692
344.449	11.4888
348.02	11.2751
351.592	11.2487
355.16	10.2843
358.728	8.9765
362.294	8.37078
365.858	8.67656
369.422	8.36474
372.983	7.22131
376.543	8.53896
380.102	10.6542
383.661	13.1204
387.216	12.135
390.771	12.0328
394.324	12.7304
397.875	14.3978
401.425	13.557
404.974	15.0847
408.524	14.2183
412.07	14.5208
415.614	14.2679
419.156	14.6525
422.698	14.7149
426.238	14.8118
429.777	12.5999
433.315	11.4423
436.852	10.0304
440.387	9.91797
443.919	9.80965
447.451	8.84875
450.982	9.3994
454.512	10.7794
458.038	11.1983
461.565	11.4456
465.091	13.309
468.613	16.5482
472.136	16.3955
475.655	19.4014
479.176	22.5159
482.692	24.1505
486.21	24.6256
489.724	24.6433
493.237	24.9572
496.75	25.4575
500.26	27.1209
503.771	27.1659
507.279	27.2582
510.785	27.5715
514.289	27.3541
517.793	26.7375
521.297	26.8573
524.797	26.2219
528.297	25.3078
531.795	23.4232
535.291	22.3677
538.787	22.5252
542.281	21.4783
545.773	20.1023
549.264	18.485
552.754	18.2032
556.243	16.3497
559.73	14.7952
563.216	13.5299
566.701	10.5602
570.182	9.22789
573.664	7.53072
577.145	6.72493
580.624	5.79089
584.1	5.59455
587.577	3.50673
591.052	2.11389
594.524	1.62419
597.997	3.62219
601.466	3.39511
604.936	4.29336
608.403	3.80981
611.87	3.2347
615.334	1.98677
618.799	2.76748
622.26	5.11982
625.72	6.72405
629.181	7.24684
632.638	8.70309
636.095	9.92839
639.551	11.5791
643.005	11.3012
646.457	12.7855
649.908	12.4541
653.357	13.1374
656.806	13.7801
660.253	13.3518
663.7	12.1425
667.145	13.6919
670.588	15.3817
674.027	15.3717
677.468	17.6542
680.907	20.4393
684.345	23.2789
687.781	24.9028
691.216	25.1411
694.65	26.9585
698.081	31.4467
701.512	33.4872
704.942	36.8295
708.371	38.8043
711.796	39.5317
715.222	40.3576
718.645	42.3563
722.068	42.6629
725.49	42.8495
728.909	42.5684
732.329	42.69
735.745	43.6891
739.16	43.9283
742.576	43.9737
745.988	45.6314
749.401	47.8084
752.811	49.7354
756.22	51.5209
759.627	56.3284
763.035	59.4609
766.44	61.4985
769.843	62.8623
773.245	65.898
776.646	70.861
780.046	73.7436
783.444	75.952
786.841	76.5854
790.237	79.1132
793.631	81.1686
797.024	80.833
800.416	82.658
803.807	82.3022
807.196	82.8402
810.584	82.6727
813.971	82.3661
817.354	79.8016
820.739	77.82
824.122	76.4098
827.503	76.2759
830.882	73.4441
834.261	70.8444
837.637	69.8646
841.013	67.713
844.389	65.9121
847.761	63.06
851.131	60.5805
854.503	60.0065
857.871	57.2974
861.24	55.4458
864.606	53.1325
867.97	52.5104
871.336	52.0171
874.698	53.3394
878.058	52.8779
881.418	51.1411
884.778	51.2384
888.135	51.1135
891.49	51.544
894.845	50.0994
898.198	47.5219
901.55	47.3628
904.901	48.4522
908.25	48.3627
911.598	46.8902
914.945	44.7061
918.291	44.6606
921.635	43.9857
924.978	43.4606
928.318	42.194
931.659	38.7644
934.998	36.0695
938.336	33.7804
941.671	31.8618
945.007	28.096
948.339	26.0971
951.672	26.8134
955.004	25.7776
958.333	24.7564
961.662	23.7823
964.989	25.0439
968.315	27.4876
971.639	28.3717
974.962	30.3521
978.285	32.2505
981.605	35.9597
984.924	38.3134
988.243	40.0831
991.56	40.6021
994.875	41.6866
998.188	39.3349
1001.5	38.3455
1004.81	39.2663
1008.12	42.0576
1011.43	44.7991
1014.74	48.9713
1018.05	52.8429
1021.35	55.468
1024.65	57.4133
1027.96	58.9671
1031.26	60.3934
1034.56	60.0654
1037.86	57.7252
1041.16	57.5364
1044.45	57.9058
1047.75	55.5575
1051.04	52.8764
1054.33	50.0052
1057.62	48.1523
1060.91	43.7549
1064.2	38.0621
1067.49	32.955
1070.77	27.9427
1074.06	21.7902
1077.34	18.0778
1080.62	15.5172
1083.91	14.6698
1087.18	16.0419
1090.46	18.873
1093.74	20.2532
1097.02	21.5626
1100.29	21.9952
1103.56	21.4679
1106.84	20.6654
1110.11	19.5958
1113.38	18.3258
1116.64	17.1285
1119.91	18.5279
1123.18	18.0714
1126.44	16.5697
1129.7	16.0386
1132.97	15.4263
1136.23	15.2662
1139.49	14.18
1142.74	14.3612
1146	12.7638
1149.26	11.2764
1152.51	11.0825
1155.76	10.8622
1159.01	10.1874
1162.27	7.53664
1165.51	6.75995
1168.76	5.99695
1172.01	6.18421
1175.25	7.68253
1178.5	7.06742
1181.74	7.39329
1184.98	7.69959
1188.22	8.75197
1191.46	9.9896
1194.7	13.7139
1197.94	16.2587
1201.17	19.0984
1204.41	21.6429
1207.64	23.7492
1210.87	28.3435
1214.1	32.9897
1217.33	37.0198
1220.56	42.0272
1223.79	45.9611
1227.01	50.3232
1230.23	54.8282
1233.46	59.7836
1236.68	64.455
1239.9	67.406
1243.12	70.4489
1246.34	73.9169
1249.55	75.1886
1252.77	77.9387
1255.98	80.3571
1259.2	81.2545
1262.41	83.5005
1265.62	85.2394
1268.83	88.1459
1272.03	91.4818
1275.24	93.7528
1278.45	94.5254
1281.65	96.3574
1284.85	95.4906
1288.06	97.241
1291.26	98.44
1294.46	99.5904
1297.66	100.249
1300.85	101.552
1304.05	101.794
1307.24	103.21
1310.43	103.687
1313.63	104.674
1316.82	104.746
1320.01	105.057
1323.2	104.88
1326.38	103.063
1329.57	100.519
1332.76	97.9846
1335.94	95.6015
1339.12	93.8495
1342.3	93.0767
1345.48	90.1856
1348.66	88.5774
1351.84	86.0111
1355.01	80.7825
1358.19	77.0272
1361.36	72.3891
1364.53	69.1087
1367.71	65.6818
1370.88	62.3075
1374.04	58.7124
1377.21	56.5773
1380.38	53.8793
1383.54	52.9528
1386.71	54.0936
1389.87	53.7497
1393.03	53.4809
1396.19	53.5148
1399.35	51.7453
1402.51	51.7817
1405.67	52.294
1408.82	53.0055
1411.98	56.2472
1415.13	59.234
1418.28	62.7866
1421.43	67.5993
1424.58	73.5581
1427.73	80.3984
1430.88	86.7526
1434.02	92.2008
1437.17	98.8033
1440.31	102.64
1443.45	105.23
1446.6	106.872
1449.74	107.258
1452.87	106.148
1456.01	103.226
1459.15	100.204
1462.28	96.3597
1465.42	92.2552
1468.55	86.4418
1471.68	82.5038
1474.81	76.6893
1477.94	71.814
1481.07	66.6412
1484.2	61.9968
1487.32	56.5106
1490.45	52.2381
1493.57	49.8879
1496.69	48.6072
1499.81	46.3843
1502.93	46.3551
1506.05	44.9128
1509.17	45.7409
1512.28	44.252
1515.4	43.0164
1518.51	42.6873
1521.63	40.2329
1524.74	38.6888
1527.85	36.5182
1530.96	35.0655
1534.06	36.4165
1537.17	39.2283
1540.28	39.8688
1543.38	41.5865
1546.48	43.8293
1549.59	44.2098
1552.69	44.7855
1555.79	45.3747
1558.88	46.0698
1561.98	48.0124
1565.08	49.1773
1568.17	49.9388
1571.27	51.7297
1574.36	54.9817
1577.45	58.208
1580.54	61.7221
1583.63	65.4807
1586.72	67.9568
1589.8	70.3379
1592.89	72.5157
1595.97	73.4678
1599.06	73.5803
1602.14	74.5343
1605.22	75.7115
1608.3	77.5212
1611.38	77.9751
1614.46	78.5944
1617.53	79.5204
1620.61	81.8502
1623.68	84.5104
1626.75	88.48
1629.82	90.6648
1632.9	94.5185
1635.96	99.7761
1639.03	102.906
1642.1	107.875
1645.16	111.816
1648.23	117.349
1651.29	122.491
1654.36	126.089
1657.42	128.413
1660.48	128.069
1663.53	126.638
1666.59	124.331
1669.65	118.856
1672.7	113.787
1675.76	106.809
1678.81	99.246
1681.86	90.805
1684.91	82.975
1687.96	74.6607
1691.01	68.2206
1694.06	60.8546
1697.11	54.4189
1700.15	47.8764
1703.2	41.1239
1706.24	35.0949
1709.28	29.5702
1712.32	24.4645
1715.36	21.3652
1718.4	19.1193
1721.43	17.6797
1724.47	14.905
1727.5	13.1905
1730.54	12.2041
1733.57	10.7669
1736.6	8.98645
1739.63	8.94473
1742.66	8.66634
1745.69	7.07984
1748.72	6.4208
1751.74	5.36051
1754.77	5.26802
1757.79	5.26852
1760.81	4.5767
1763.83	4.64882
1766.85	4.61924
1769.87	3.44804
1772.89	3.19527
1775.91	3.07315
1778.92	2.61641
1781.94	2.14058
1784.95	1.84963
1787.96	2.4382
1790.97	1.5388
1793.98	1.78768
1796.99	1.62378
1800	0.999532
1803	1.90722
1806.01	2.11466
1809.01	1.51566
1812.02	0.877448
1815.02	1.19566
1818.02	1.02569
1821.02	0.921337
1824.02	0.317344
1827.01	0.380214
1830.01	0.0308894
1833	-0.610857
1836	-1.02483
1838.99	-0.529937
1841.98	-0.775221
1844.97	-0.571693
1847.96	-0.339382
1850.95	-0.382932
1853.94	-0.0257683
1856.92	-0.122942
1859.91	-0.0534402
1862.89	0.28581
1865.88	1.501
1868.86	2.08133
1871.84	2.002
1874.82	3.10409
1877.8	3.31409
1880.77	3.48804
1882.51	3.29502
1885.5	4.84377
1888.48	4.83579
1891.47	4.91993
1894.46	4.6204
1897.44	4.58833
1900.42	4.198
1903.41	4.17068
1906.39	4.09475
1909.37	5.17704
1912.35	5.07083
1915.32	4.94485
1918.3	4.97986
1921.28	5.02175
1924.25	4.72974
1927.22	4.14961
1930.2	3.81299
1933.17	3.82822
1936.14	4.61115
1939.11	4.73563
1942.08	4.34337
1945.04	4.31825
1948.01	4.86232
1950.97	5.29873
1953.94	6.16505
1956.9	5.86028
1959.86	5.35376
1962.82	4.38997
1965.78	4.26742
1968.74	3.1106
1971.69	3.7573
1974.65	3.16297
1977.61	3.01559
1980.56	3.39884
1983.51	3.92421
1986.46	4.28498
1989.41	3.97464
1992.36	4.57423
1995.31	3.40319
1998.26	3.27453
2001.2	3.1713
2004.15	4.15615
2007.09	3.67163
2010.04	4.29085
2012.98	4.28865
2015.92	5.22275
2018.86	5.05092
2021.8	5.96587
2024.74	6.49201
2027.67	7.27914
2030.61	7.71793
2033.54	7.61033
2036.47	8.17975
2039.41	8.12008
2042.34	8.44201
2045.27	9.93268
2048.2	10.6203
2051.12	11.6522
2054.05	12.1698
2056.98	13.4559
2059.9	14.3356
2062.82	14.6072
2065.75	14.012
2068.67	14.1
2071.59	15.1177
2074.51	16.621
2077.43	16.2584
2080.34	16.494
2083.26	17.2811
2086.17	18.9754
2089.09	20.9266
2092	23.0594
2094.91	25.7176
2097.82	27.9026
2100.73	29.4096
2103.64	31.0713
2106.55	34.5905
2109.46	37.1143
2112.36	39.5182
2115.27	42.9767
2118.17	46.3068
2121.07	49.594
2123.97	53.0348
2126.87	57.1644
2129.77	62.9087
2132.67	67.1357
2135.57	70.6741
2138.46	75.7155
2141.36	81.7517
2144.25	86.7571
2147.14	92.0151
2150.03	96.6076
2152.92	102.095
2155.81	107.619
2158.7	113.188
2161.59	117.427
2164.48	121.198
2167.36	124.78
2170.25	125.99
2173.13	127.953
2176.01	129.324
2178.89	129.144
2181.77	125.805
2184.65	124.08
2187.53	121.075
2190.41	116.659
2193.28	112.558
2196.16	107.858
2199.03	102.623
2201.9	96.4052
2204.78	90.189
2207.65	84.7312
2210.51	78.9937
2213.38	73.272
2216.25	68.3139
2219.12	63.7455
2221.98	59.8931
2224.85	56.2674
2227.71	52.6227
2230.57	49.3164
2233.43	46.0382
2236.29	42.6794
2239.15	40.004
2242.01	37.313
2244.87	35.1397
2247.73	33.0205
2250.58	30.7986
2253.43	28.8071
2256.29	26.2421
2259.14	24.157
2261.99	21.7833
2264.84	19.5091
2267.69	17.0923
2270.54	14.734
2273.38	13.9125
2276.23	11.9653
2279.07	10.5888
2281.92	10.1084
2284.76	9.82273
2287.6	9.39736
2290.44	9.25164
2293.28	8.33272
2296.12	7.79749
2298.96	7.60391
2301.79	7.57172
2304.63	7.46453
2307.46	9.07526
2310.3	8.65899
2313.13	8.6963
2315.96	9.09091
2318.79	9.77022
2321.62	9.46988
2324.45	8.9803
2327.27	8.20823
2330.1	7.16645
2332.93	5.2081
2335.75	4.94261
2338.57	3.617
2341.4	3.28575
2344.22	2.5265
2347.04	1.39462
2349.86	1.26083
2352.67	0.755165
2355.49	-0.01264
2358.31	-0.10599
2361.12	-1.03877
2363.94	-0.733806
2366.75	-0.117581
2369.56	0.659297
2372.37	0.966735
2375.18	1.6028
2377.99	3.30943
2380.8	3.26098
2383.61	5.23816
2386.41	5.6887
2389.22	6.57528
2392.02	6.12371
2394.82	6.49517
2397.63	6.15905
2400.43	5.49743
2403.23	5.54669
2406.02	5.27966
2408.82	4.91274
2411.62	4.6726
2414.41	4.48985
2417.21	4.68783
2420	4.67968
2422.79	4.24246
2425.59	4.30607
2428.38	4.564
2431.17	4.92721
2433.96	5.81973
2436.74	6.38623
2439.53	6.69658
2442.32	7.272
2445.1	7.27333
2447.88	7.49755
2450.67	7.40884
2453.45	7.55633
2456.23	6.86703
2459.01	6.19063
2461.79	5.49502
2464.57	5.38736
2467.34	4.14161
2470.12	4.5432
2472.89	3.97941
2475.67	2.96148
2478.44	2.89902
2481.21	1.91707
2483.98	2.32408
2486.75	2.65139
2489.52	2.09386
2492.29	3.36852
2495.06	4.69401
2497.82	4.97382
2500.59	5.63158
2503.35	4.71594
2506.11	3.85721
2508.88	3.79612
2511.63	2.87917
2514.39	2.16473
2517.15	2.27297
2519.91	2.86035
2522.67	3.37457
2525.42	3.59445
2528.18	3.91721
2530.93	4.26292
2533.69	4.32757
2536.44	4.83175
2539.19	5.16728
2541.94	4.56914
2544.69	5.2942
2547.44	5.3929
2550.18	6.15724
2552.93	6.64083
2555.68	6.93159
2558.42	6.48807
2561.16	7.11306
2563.9	6.13761
2566.64	5.4829
2569.38	4.80272
2572.12	4.37942
2574.86	3.60034
2577.6	3.22751
2580.34	3.28135
2583.07	3.33909
2585.81	3.62184
2588.54	4.15979
2591.27	3.7134
2594	3.91211
2596.73	4.13467
2599.46	3.47706
2602.19	3.83521
2604.92	4.86707
2607.64	5.13925
2610.37	6.47789
2613.09	6.47843
2615.82	6.46746
2618.54	7.51441
2621.26	7.29599
2623.98	5.98357
2626.7	6.72424
2629.42	6.12682
2632.14	5.57446
2634.86	6.43015
2637.57	6.54936
2640.29	5.23902
2643	4.59302
2645.72	4.81667
2648.43	3.95339
2651.14	3.84275
2653.85	3.8953
2656.56	4.23086
2659.27	3.50651
2661.97	3.59645
2664.68	3.77053
2667.38	4.3616
2670.09	5.20884
2672.79	5.68062
2675.49	5.44303
2678.2	4.90108
2680.89	4.96938
2683.59	6.15302
2686.29	6.40169
2688.99	6.20745
2691.69	6.83975
2694.38	6.64674
2697.08	5.80694
2699.77	6.61568
2702.46	5.87282
2705.16	5.9817
2707.85	6.1886
2710.54	6.82926
2713.23	6.14348
2715.92	7.09473
2718.6	7.35712
2721.29	6.70464
2723.97	6.7618
2726.66	6.77312
2729.34	7.17395
2732.02	8.08323
2734.7	7.61487
2737.39	7.17657
2740.06	6.39156
2742.74	6.62778
2745.42	6.08336
2748.1	5.58466
2750.77	5.28612
2753.45	4.13456
2756.12	2.8307
2758.79	2.24058
2761.47	1.20548
2764.14	1.00063
2766.81	0.566057
2769.48	0.157954
2772.14	0.00120305
2774.81	-0.205659
2777.48	-0.690943
2780.14	-0.950054
2782.81	-0.0769228
2785.47	-0.453012
2788.13	-0.708536
2790.79	0.161213
2793.46	1.41223
2796.11	1.83124
2798.77	2.11153
2801.43	2.37144
2804.09	1.38255
2806.74	1.14888
2809.4	0.335622
2812.05	0.13844
2814.71	0.164511
2817.36	1.29238
2820.01	3.49294
2822.66	6.75625
2825.31	9.83468
2827.96	13.7455
2830.61	18.1356
2833.25	22.7849
2835.9	28.9329
2838.54	36.3709
2841.18	43.4016
2843.83	51.9816
2846.47	62.5067
2849.11	72.79
2851.75	83.8389
2854.39	95.1771
2857.03	107.493
2859.67	117.982
2862.3	127.542
2864.94	135.872
2867.57	143.495
2870.21	149.995
2872.84	156.414
2875.47	161.938
2878.1	168.051
2880.73	174.369
2883.36	180.266
2885.99	186.966
2888.61	192.524
2891.24	198.968
2893.87	207.437
2896.49	216.378
2899.11	227.483
2901.74	239.157
2904.36	253.582
2906.98	269.929
2909.6	288.444
2912.22	306.794
2914.83	325.099
2917.45	343.026
2920.07	359.141
2922.68	372.677
2925.3	383.467
2927.91	390.158
2930.52	394.861
2933.13	395.217
2935.74	393.874
2938.35	390.103
2940.96	383.501
2943.57	373.364
2946.18	360.63
2948.78	345.859
2951.39	329.145
2953.99	312.636
2956.6	296.15
2959.2	278.861
2961.8	262.397
2964.4	246.393
2967	231.7
2969.6	218.651
2972.2	205.372
2974.79	192.714
2977.39	179.697
2979.98	166.484
2982.58	154.377
2985.17	141.086
2987.76	128.216
2990.36	115.659
2992.95	103.796
2995.54	91.9061
2998.12	81.4742
3000.71	70.6297
3003.3	60.6015
3005.88	50.938
3008.47	41.969
3011.05	33.3787
3013.64	26.1715
3016.22	20.5966
3018.8	15.6184
3021.38	12.2709
3023.96	9.76102
3026.54	8.46859
3029.12	6.55247
3031.69	5.16301
3034.27	4.99439
3036.85	5.94644
3039.42	6.85454
3041.99	8.5009
3044.57	9.45083
3047.14	11.2589
3049.71	12.531
3052.28	12.9502
3054.85	13.7575
3057.42	14.071
3059.98	13.8967
3062.55	13.4989
3065.11	12.5857
3067.68	11.7331
3070.24	10.058
3072.8	8.77143
3075.37	7.85432
3077.93	6.17227
3080.49	4.92778
3083.05	2.78997
3085.61	1.14767
3088.16	0.354955
3090.72	-1.03364
3093.27	-1.11832
3095.83	-1.61114
3098.38	-0.707632
3100.94	0.317059
3103.49	1.1095
3106.04	1.96901
3108.59	3.41594
3111.14	4.1827
3113.69	5.59933
3116.23	6.70997
3118.78	7.83744
3121.33	9.73508
3123.87	11.1013
3126.42	12.6671
3128.96	14.7443
3131.5	17.0299
3134.04	19.7867
3136.58	21.915
3139.12	24.6954
3141.66	26.7456
3144.2	29.7867
3146.74	33.994
3149.27	37.168