File: data/Raman/poly_smoothed/Mb_30_27_15_1x_45s_532 nm_x100_100%_600 gr_mm_01.txt
#Acq. time (s)=	45
#Accumulations=	2
#Range (cm-¹)=	200...3150
#Windows=	2
#Auto scanning=	Off
#Autofocus=	Off
#Macrospot=	Off
#AutoExposure=	Off
#Spike filter=	Multiple accum.
#Delay time (s)=	0
#Binning=	1
#Readout mode=	Signal
#DeNoise=	Off
#ICS correction=	On
#Dark correction=	Off
#Inst. Process=	Off
#Detector Gain=	Best Dynamic Range
#Detector ADC=	20 kHz
#Detector temperature (°C)=	-69.62
#Instrument=	LabRAM HR Evol
#Detector=	Synapse
#Objective=	x100
#Grating=	600 gr/mm
#ND Filter=	100%
#Laser (nm)=	532
#Hole=	100.021
#Range=	Auto
#Laser Pol.=	No
#Raman. Pol.=	No
#Laser Pol. (°)=	-0.0007625
#Raman Pol. (°)=	89.9995
#Collection=	Microscope
#StageXY=	Marzhauser
#StageZ=	Marzhauser
#X (µm)=	-6421.9
#Y (µm)=	856.8
#Z (µm)=	-64.95
#Full time(mm:ss)=	3:18
#Project=
#Sample=
#Site=
#Title=	Mb_30_27_15_2x_45s_532 nm_x100_100%_600 gr_mm
#Remark=
#Date=	13.07.2022 09:45
#Acquired=	13.07.2022 09:45:48
#Base:Fit=	10.08.2022 10:40:03
#Base:Sub=	10.08.2022 10:40:17
#Filter:Polynom=	16.08.2022 10:16:15
#AxisType[0]=Intens
#AxisUnit[0]=Cnt
#AxisType[1]=Spectr
#AxisUnit[1]=1/cm
200.563	12.1313
204.194	10.3916
207.821	9.28431
211.449	10.2059
215.074	11.1104
218.699	11.4435
222.321	12.7563
225.941	12.6672
229.562	12.6478
233.18	11.9236
236.796	12.0631
240.411	11.2034
244.026	10.9225
247.638	9.65945
251.248	8.05823
254.857	7.44956
258.465	8.6246
262.071	9.01385
265.678	7.87703
269.282	4.76091
272.884	5.29754
276.484	6.21733
280.084	7.20881
283.682	7.42988
287.276	7.97091
290.871	9.30651
294.465	8.45054
298.057	9.54979
301.648	10.6134
305.237	11.3079
308.823	11.5398
312.41	11.9762
315.995	11.8475
319.579	12.2735
323.16	12.4728
326.741	12.0301
330.321	12.288
333.897	10.9903
337.474	8.82257
341.048	9.707
344.622	8.96329
348.192	7.33021
351.764	6.99366
355.332	5.98309
358.901	6.88615
362.466	9.0253
366.03	7.52367
369.594	8.30162
373.155	6.39068
376.715	6.93326
380.273	6.94465
383.832	7.51564
387.388	8.46308
390.942	9.83229
394.495	10.1256
398.047	9.76283
401.597	10.0868
405.145	10.5516
408.693	12.3487
412.239	13.0215
415.783	11.3875
419.327	10.9603
422.869	9.2732
426.409	9.24046
429.948	9.61702
433.486	6.65547
437.022	6.20772
440.558	5.87867
444.089	4.61059
447.622	5.52788
451.153	5.11681
454.682	4.9345
458.208	4.25566
461.735	4.63634
465.259	6.03782
468.783	6.4394
472.306	8.12093
475.825	10.0331
479.346	12.1536
482.862	14.4691
486.38	17.0504
489.894	19.3609
493.407	21.5158
496.92	23.3728
500.43	24.5552
503.939	25.6917
507.448	26.0893
510.954	26.1947
514.459	25.9221
517.962	27.2795
521.466	26.4066
524.966	26.8646
528.466	26.4997
531.964	26.0629
535.46	25.5758
538.955	22.7331
542.449	20.2438
545.942	19.7695
549.433	17.9845
552.923	17.0463
556.412	16.466
559.899	17.2767
563.385	17.6229
566.867	16.0323
570.35	15.884
573.832	15.4764
577.313	15.4995
580.79	14.7608
584.268	14.7929
587.745	14.1897
591.218	13.7561
594.692	12.6618
598.164	12.2432
601.634	13.1556
605.104	13.9188
608.57	12.6721
612.037	12.7993
615.501	11.7442
618.966	9.9078
622.427	9.03664
625.887	7.37727
629.348	6.22396
632.806	7.33625
636.262	8.05052
639.716	8.71084
643.172	10.1111
646.624	9.38744
650.075	9.60854
653.524	9.83762
656.972	10.1879
660.419	11.2018
663.865	11.3938
667.309	12.7118
670.752	15.0676
674.194	16.551
677.634	18.0398
681.073	19.7048
684.511	22.168
687.947	23.854
691.382	23.4852
694.816	24.2608
698.247	24.8116
701.678	24.8631
705.108	28.3135
708.534	30.3005
711.962	33.6076
715.388	35.6725
718.81	36.7248
722.234	37.8551
725.654	37.5304
729.075	38.695
732.492	38.4559
735.91	38.4626
739.325	40.9742
742.741	43.0981
746.153	46.4086
749.564	48.9947
752.976	52.996
756.385	56.2875
759.792	58.5812
763.2	61.6285
766.604	64.419
770.008	66.0749
773.41	69.7164
776.811	71.8365
780.21	74.6947
783.608	76.1776
787.005	79.3373
790.401	81.7513
793.795	84.9918
797.188	86.0779
800.58	87.1991
803.971	87.3838
807.36	88.527
810.748	88.6254
814.135	88.0823
817.518	85.5622
820.902	84.8103
824.285	85.8044
827.665	84.3727
831.045	82.7638
834.424	80.8892
837.8	80.2237
841.177	77.2751
844.55	75.3007
847.924	73.9525
851.295	71.8612
854.666	69.3205
858.034	66.9667
861.403	65.9011
864.769	64.4888
868.133	63.5342
871.498	63.9782
874.86	63.8781
878.221	63.6992
881.58	63.5711
884.938	62.7728
888.297	60.7492
891.653	60.595
895.007	59.0568
898.36	56.4037
901.712	55.1159
905.063	54.8131
908.412	53.9847
911.76	52.6021
915.107	52.7604
918.452	52.2623
921.797	52.1494
925.138	51.0465
928.48	50.9164
931.82	48.6301
935.16	46.8131
938.496	46.1863
941.833	45.6323
945.168	43.856
948.5	42.9319
951.834	42.4791
955.163	42.7592
958.494	42.483
961.821	40.6379
965.15	40.446
968.474	39.8753
971.8	40.723
975.123	41.659
978.446	41.0023
981.766	41.0122
985.084	40.7169
988.402	41.9731
991.72	41.1452
995.035	40.5484
998.349	40.0699
1001.66	37.326
1004.97	37.443
1008.28	38.1724
1011.59	41.0783
1014.9	46.0285
1018.21	52.5411
1021.51	57.4922
1024.81	61.1788
1028.12	64.2798
1031.42	67.334
1034.72	69.6021
1038.02	70.3614
1041.31	71.8969
1044.61	72.5313
1047.91	73.135
1051.2	72.0974
1054.49	69.4967
1057.78	67.2659
1061.07	62.7019
1064.36	58.4208
1067.65	53.2961
1070.93	47.1727
1074.22	42.0351
1077.5	36.7787
1080.78	32.8883
1084.06	30.8604
1087.34	30.4888
1090.62	30.8744
1093.9	31.4085
1097.17	30.5303
1100.45	30.9861
1103.72	29.5069
1106.99	28.4855
1110.27	27.4861
1113.53	27.5287
1116.8	27.8598
1120.07	27.2589
1123.33	27.0494
1126.6	25.7873
1129.86	24.8724
1133.12	24.9279
1136.38	23.9688
1139.64	21.4089
1142.9	20.957
1146.16	19.3531
1149.41	18.0092
1152.67	16.9491
1155.92	15.5549
1159.17	13.0558
1162.42	10.6409
1165.67	6.46883
1168.92	7.03132
1172.16	3.9171
1175.41	2.46069
1178.65	3.443
1181.9	4.32382
1185.14	4.03478
1188.38	5.30635
1191.62	6.68374
1194.86	7.35928
1198.09	8.07518
1201.33	10.2012
1204.56	12.3578
1207.8	16.0013
1211.03	19.7227
1214.26	22.5694
1217.49	27.5987
1220.71	30.6667
1223.94	35.1271
1227.16	38.2917
1230.39	42.3525
1233.61	43.7989
1236.83	46.7175
1240.05	49.3849
1243.27	53.2647
1246.49	57.2094
1249.71	59.3737
1252.92	63.1887
1256.14	66.5573
1259.35	69.486
1262.56	71.0151
1265.77	73.8619
1268.98	76.3189
1272.19	78.1744
1275.4	80.2322
1278.6	82.6091
1281.81	85.6546
1285.01	88.8868
1288.21	89.625
1291.41	90.9439
1294.61	92.4654
1297.81	92.3413
1301.01	92.1307
1304.2	90.9631
1307.4	91.7024
1310.59	90.5577
1313.78	88.8
1316.97	87.628
1320.16	87.3078
1323.35	85.9118
1326.54	82.5173
1329.72	80.749
1332.91	78.759
1336.09	77.1573
1339.27	74.8223
1342.45	72.728
1345.64	70.6663
1348.81	69.4852
1351.99	67.555
1355.17	65.937
1358.34	63.7164
1361.51	61.4358
1364.69	56.6198
1367.86	54.312
1371.03	51.7399
1374.2	49.2354
1377.37	46.7245
1380.53	46.3927
1383.7	45.351
1386.86	44.3933
1390.02	42.8111
1393.19	42.3058
1396.35	42.222
1399.51	41.4066
1402.66	41.475
1405.82	42.8203
1408.97	45.1507
1412.13	47.8606
1415.28	50.8728
1418.43	54.1203
1421.59	59.9753
1424.73	66.2979
1427.88	72.4934
1431.03	77.9564
1434.18	83.6055
1437.32	88.564
1440.46	92.574
1443.61	96.0878
1446.75	98.6478
1449.89	100.697
1453.03	100.764
1456.16	99.5876
1459.3	97.47
1462.44	93.7762
1465.57	89.56
1468.7	85.8864
1471.83	81.6025
1474.96	76.0831
1478.09	70.687
1481.22	65.1798
1484.35	59.8752
1487.47	54.5951
1490.6	50.5633
1493.72	45.7277
1496.84	42.3699
1499.96	39.4109
1503.08	36.7175
1506.2	33.3473
1509.32	31.9701
1512.44	30.4967
1515.55	29.2463
1518.66	28.1607
1521.78	26.8445
1524.89	26.4486
1528	25.8383
1531.11	25.9113
1534.21	25.9928
1537.32	26.5856
1540.43	27.4971
1543.53	29.8406
1546.63	32.3387
1549.74	34.5226
1552.84	36.492
1555.94	37.5004
1559.03	39.114
1562.13	40.8372
1565.23	42.6206
1568.32	44.0576
1571.42	43.8724
1574.51	45.2193
1577.6	47.4326
1580.69	50.4926
1583.78	53.197
1586.87	56.1707
1589.95	57.5113
1593.04	60.4815
1596.12	61.8352
1599.21	63.4354
1602.29	64.2623
1605.37	65.5804
1608.45	66.0338
1611.53	67.6421
1614.6	70.531
1617.68	71.6591
1620.75	73.9057
1623.83	76.0965
1626.9	78.6333
1629.97	83.4288
1633.04	86.7635
1636.11	90.1733
1639.18	95.0472
1642.25	99.039
1645.31	102.956
1648.38	105.726
1651.44	109.224
1654.5	111.702
1657.56	113.834
1660.62	113.217
1663.68	111.844
1666.74	108.995
1669.8	104.924
1672.85	99.682
1675.91	93.7142
1678.96	86.8799
1682.01	80.1902
1685.06	73.4483
1688.11	66.963
1691.16	60.4956
1694.21	52.8721
1697.25	45.6217
1700.3	40.886
1703.34	37.2081
1706.39	32.5126
1709.43	28.0822
1712.47	25.8036
1715.51	23.6628
1718.54	22.2237
1721.58	20.1807
1724.62	19.0023
1727.65	18.6895
1730.68	17.6996
1733.72	17.2019
1736.75	15.7336
1739.78	15.6031
1742.81	14.6057
1745.84	13.9036
1748.86	14.6778
1751.89	14.1777
1754.91	13.8745
1757.93	13.1154
1760.96	11.5857
1763.98	10.8209
1767	9.49996
1770.02	8.67286
1773.03	8.14784
1776.05	7.04674
1779.07	6.87926
1782.08	6.43303
1785.09	6.33302
1788.11	5.99746
1791.12	6.20112
1794.13	5.86246
1797.13	5.50108
1800.14	5.52589
1803.15	5.78712
1806.15	5.30582
1809.16	4.51451
1812.16	4.68535
1815.16	4.03594
1818.16	3.71692
1821.16	4.25069
1824.16	3.48234
1827.16	2.43597
1830.16	2.67521
1833.15	2.01805
1836.14	2.13147
1839.14	2.24136
1842.13	1.71491
1845.12	1.77671
1848.11	1.23476
1851.1	1.63092
1854.08	2.6731
1857.07	3.66151
1860.05	4.43201
1863.04	4.64831
1866.02	4.12997
1869	3.72984
1871.98	3.35387
1874.96	2.95702
1877.94	2.96326
1880.92	2.23514
1882.51	2.50483
1885.5	2.38295
1888.48	2.2418
1891.47	2.27467
1894.46	2.37238
1897.44	1.87874
1900.42	2.0254
1903.41	2.51665
1906.39	1.93954
1909.37	2.04656
1912.35	2.36169
1915.32	2.32205
1918.3	3.48306
1921.27	4.59113
1924.25	6.63291
1927.22	5.88897
1930.19	6.07466
1933.17	5.28368
1936.14	4.68665
1939.11	3.49676
1942.07	3.64498
1945.04	2.90847
1948.01	3.16478
1950.97	3.23962
1953.93	2.87889
1956.9	2.58944
1959.86	2.46801
1962.82	2.01829
1965.78	1.59407
1968.74	1.76579
1971.69	1.41661
1974.65	1.20384
1977.6	1.7461
1980.56	2.84263
1983.51	3.02512
1986.46	3.22255
1989.41	3.93833
1992.36	6.10429
1995.31	6.22124
1998.26	6.04984
2001.2	5.75052
2004.15	5.6855
2007.09	6.11057
2010.04	5.93472
2012.98	7.27906
2015.92	6.57761
2018.86	6.47635
2021.8	6.71581
2024.73	5.60381
2027.67	6.13354
2030.61	5.78423
2033.54	6.06228
2036.47	5.9099
2039.4	5.46291
2042.33	6.07941
2045.27	5.55508
2048.19	6.85047
2051.12	7.17722
2054.05	6.13029
2056.97	6.27513
2059.9	7.70395
2062.82	8.36391
2065.74	8.90574
2068.67	8.55252
2071.59	9.41431
2074.51	10.4973
2077.42	10.944
2080.34	12.1399
2083.26	13.9672
2086.17	14.5051
2089.09	15.4275
2092	16.9121
2094.91	17.9171
2097.82	18.3859
2100.73	19.6793
2103.64	20.7263
2106.55	22.4952
2109.45	23.8032
2112.36	25.2506
2115.26	26.4819
2118.17	28.6025
2121.07	30.7719
2123.97	32.7202
2126.87	35.249
2129.77	37.7213
2132.67	40.1151
2135.56	41.9436
2138.46	45.4484
2141.35	48.7485
2144.25	52.4097
2147.14	54.745
2150.03	59.0661
2152.92	61.899
2155.81	64.72
2158.7	67.2919
2161.59	70.1649
2164.47	72.672
2167.36	74.0525
2170.24	75.3376
2173.13	76.3862
2176.01	77.3227
2178.89	78.1607
2181.77	78.1356
2184.65	77.3801
2187.53	76.7377
2190.4	75.5091
2193.28	72.5033
2196.16	70.1881
2199.03	66.3209
2201.9	63.7267
2204.77	60.4169
2207.64	57.0222
2210.51	53.9637
2213.38	50.098
2216.25	46.2625
2219.12	42.7463
2221.98	39.2341
2224.85	34.8913
2227.71	31.4853
2230.57	29.2645
2233.43	25.9938
2236.29	23.6163
2239.15	20.9637
2242.01	19.3252
2244.87	17.4535
2247.72	16.7474
2250.58	16.1206
2253.43	15.0533
2256.29	14.2006
2259.14	13.9066
2261.99	13.2847
2264.84	13.2853
2267.69	13.2883
2270.53	13.3166
2273.38	13.1335
2276.23	12.6555
2279.07	12.543
2281.91	11.7134
2284.76	10.593
2287.6	9.8242
2290.44	8.75322
2293.28	5.9749
2296.12	5.06224
2298.96	5.00645
2301.79	5.14522
2304.63	4.08534
2307.46	4.57642
2310.3	4.08587
2313.13	3.337
2315.96	2.70787
2318.79	3.66108
2321.62	5.4109
2324.45	5.52674
2327.27	5.32999
2330.1	5.20593
2332.92	5.42174
2335.75	4.68935
2338.57	4.99526
2341.39	4.56334
2344.21	3.94887
2347.04	3.14746
2349.85	1.53049
2352.67	1.77611
2355.49	1.0071
2358.3	-0.239472
2361.12	-0.750136
2363.93	-0.721561
2366.75	0.949072
2369.56	0.904886
2372.37	0.454201
2375.18	0.0621942
2377.99	0.836168
2380.8	1.19927
2383.6	0.957655
2386.41	2.79461
2389.21	3.14939
2392.02	3.43381
2394.82	2.89955
2397.62	2.9341
2400.42	3.56703
2403.22	4.46543
2406.02	5.01751
2408.82	5.56964
2411.62	5.00793
2414.41	5.27629
2417.21	5.4275
2420	5.75304
2422.79	7.02582
2425.59	7.73935
2428.38	8.60949
2431.17	10.0955
2433.95	10.6651
2436.74	11.1748
2439.53	11.0812
2442.31	11.2628
2445.1	11.3796
2447.88	11.6577
2450.67	11.2709
2453.45	10.3325
2456.23	10.421
2459.01	9.67923
2461.79	9.0956
2464.57	8.29678
2467.34	8.58024
2470.12	8.46224
2472.89	7.04131
2475.67	6.1844
2478.44	5.29196
2481.21	4.17531
2483.98	4.34756
2486.75	4.5203
2489.52	4.02566
2492.29	3.37324
2495.05	4.13583
2497.82	3.99928
2500.58	4.08147
2503.35	3.17614
2506.11	2.66404
2508.87	2.72999
2511.63	1.82352
2514.39	1.73776
2517.15	1.4074
2519.91	1.92002
2522.67	2.61268
2525.42	3.38484
2528.18	2.88383
2530.93	3.95459
2533.69	3.7668
2536.44	4.12177
2539.19	4.45894
2541.94	3.92639
2544.69	3.65653
2547.44	3.3284
2550.18	3.60781
2552.93	2.76058
2555.67	1.70823
2558.42	0.785537
2561.16	0.357304
2563.9	0.902245
2566.64	0.257877
2569.38	0.327758
2572.12	-0.354019
2574.86	-0.0113379
2577.6	0.21346
2580.33	-0.697865
2583.07	0.761214
2585.8	1.61369
2588.54	2.8961
2591.27	3.20737
2594	3.42196
2596.73	3.53843
2599.46	3.84158
2602.19	4.41541
2604.92	4.45782
2607.64	3.35598
2610.37	2.8307
2613.09	2.04426
2615.82	2.52462
2618.54	1.57781
2621.26	1.50197
2623.98	1.72139
2626.7	2.96285
2629.42	3.11407
2632.14	3.31266
2634.86	3.30348
2637.57	2.99395
2640.29	3.41148
2643	3.56536
2645.71	3.42844
2648.43	4.41883
2651.14	4.38768
2653.85	4.47274
2656.56	5.03047
2659.26	5.38079
2661.97	5.4306
2664.68	5.68063
2667.38	5.78847
2670.09	5.64713
2672.79	5.34908
2675.49	5.39035
2678.19	5.28916
2680.89	4.6667
2683.59	4.82022
2686.29	5.04098
2688.99	4.92262
2691.69	5.5486
2694.38	5.60635
2697.08	5.48054
2699.77	5.46203
2702.46	5.74044
2705.15	6.46258
2707.85	7.50683
2710.54	7.9066
2713.22	8.69252
2715.91	8.96742
2718.6	9.56313
2721.29	10.9732
2723.97	12.154
2726.66	12.5958
2729.34	12.8598
2732.02	12.3684
2734.7	11.9914
2737.38	11.102
2740.06	10.9648
2742.74	10.14
2745.42	8.74467
2748.09	7.94538
2750.77	7.52226
2753.45	6.56298
2756.12	5.60164
2758.79	5.14022
2761.46	4.56834
2764.14	4.05568
2766.8	3.2377
2769.47	2.99023
2772.14	2.4227
2774.81	1.67052
2777.48	0.97576
2780.14	0.369812
2782.8	1.48826
2785.47	1.84623
2788.13	1.74023
2790.79	0.905655
2793.45	0.91876
2796.11	0.923507
2798.77	0.928307
2801.43	0.371028
2804.09	0.855529
2806.74	1.04923
2809.4	1.40056
2812.05	1.57323
2814.71	2.44261
2817.36	4.1422
2820.01	5.55106
2822.66	7.19628
2825.31	9.57687
2827.96	11.044
2830.6	12.1692
2833.25	14.6278
2835.9	17.9438
2838.54	21.8811
2841.18	27.5669
2843.83	34.2587
2846.47	41.7735
2849.11	49.6784
2851.75	57.5181
2854.39	66.4053
2857.03	75.6443
2859.66	84.0716
2862.3	92.6995
2864.94	99.9539
2867.57	106.876
2870.2	113.856
2872.84	119.961
2875.47	126.461
2878.1	132.149
2880.73	137.767
2883.36	142.161
2885.99	145.689
2888.61	149.504
2891.24	152.877
2893.86	157.564
2896.49	163.831
2899.11	171.931
2901.73	180.975
2904.36	191.827
2906.98	203.999
2909.6	217.155
2912.21	230.59
2914.83	243.582
2917.45	256.865
2920.07	268.934
2922.68	278.629
2925.29	287.634
2927.91	294.353
2930.52	297.725
2933.13	299.357
2935.74	299.148
2938.35	296.003
2940.96	291.026
2943.57	284.16
2946.18	274.15
2948.78	262.885
2951.39	250.753
2953.99	238.298
2956.59	226.172
2959.2	214.11
2961.8	201.819
2964.4	190.876
2967	180.481
2969.6	169.492
2972.19	159.181
2974.79	148.783
2977.39	138.216
2979.98	128.025
2982.58	119.127
2985.17	109.914
2987.76	99.7175
2990.35	89.9086
2992.94	79.7471
2995.53	69.7409
2998.12	60.1121
3000.71	51.69
3003.3	44.1012
3005.88	36.267
3008.47	29.1983
3011.05	22.4167
3013.64	17.6236
3016.22	12.7474
3018.8	9.58357
3021.38	5.84867
3023.96	3.0793
3026.54	1.56192
3029.12	0.509135
3031.69	0.368994
3034.27	0.564569
3036.84	1.20031
3039.42	1.81045
3041.99	3.01234
3044.57	4.59676
3047.14	5.41334
3049.71	5.72549
3052.28	6.27281
3054.85	6.71736
3057.41	6.40394
3059.98	6.39602
3062.55	6.03745
3065.11	5.9572
3067.68	4.68822
3070.24	4.20633
3072.8	3.94345
3075.36	3.19224
3077.93	1.52696
3080.49	0.888592
3083.04	-0.267889
3085.6	-1.68897
3088.16	-1.8007
3090.72	-1.25715
3093.27	-1.04165
3095.83	-1.3212
3098.38	-0.753265
3100.93	0.0078918
3103.49	0.739994
3106.04	2.1051
3108.59	3.07625
3111.14	4.17349
3113.69	5.42479
3116.23	6.99508
3118.78	8.10862
3121.33	9.5285
3123.87	11.2169
3126.41	13.361
3128.96	15.4322
3131.5	17.9974
3134.04	20.5129
3136.58	23.0632
3139.12	25.4761
3141.66	27.0609
3144.2	29.3582
3146.74	31.8821
3149.27	33.9034