File: data/Raman/poly_smoothed/Mb_30_27_28_1x_45s_532 nm_x100_100%_600 gr_mm_01.txt
#Acq. time (s)=	45
#Accumulations=	2
#Range (cm-¹)=	200...3150
#Windows=	2
#Auto scanning=	Off
#Autofocus=	Off
#Macrospot=	Off
#AutoExposure=	Off
#Spike filter=	Multiple accum.
#Delay time (s)=	0
#Binning=	1
#Readout mode=	Signal
#DeNoise=	Off
#ICS correction=	On
#Dark correction=	Off
#Inst. Process=	Off
#Detector Gain=	Best Dynamic Range
#Detector ADC=	20 kHz
#Detector temperature (°C)=	-69.85
#Instrument=	LabRAM HR Evol
#Detector=	Synapse
#Objective=	x100
#Grating=	600 gr/mm
#ND Filter=	100%
#Laser (nm)=	532
#Hole=	100.021
#Range=	Auto
#Laser Pol.=	No
#Raman. Pol.=	No
#Laser Pol. (°)=	-0.0007625
#Raman Pol. (°)=	89.9995
#Collection=	Microscope
#StageXY=	Marzhauser
#StageZ=	Marzhauser
#X (µm)=	-6363.7
#Y (µm)=	843.8
#Z (µm)=	-64.95
#Full time(mm:ss)=	3:18
#Project=
#Sample=
#Site=
#Title=	Mb_30_27_28_2x_45s_532 nm_x100_100%_600 gr_mm
#Remark=
#Date=	13.07.2022 10:47
#Acquired=	13.07.2022 10:47:36
#Base:Fit=	10.08.2022 10:40:03
#Base:Sub=	10.08.2022 10:40:17
#Filter:Polynom=	16.08.2022 10:16:15
#AxisType[0]=Intens
#AxisUnit[0]=Cnt
#AxisType[1]=Spectr
#AxisUnit[1]=1/cm
200.563	6.47975
204.194	5.9393
207.821	6.5305
211.449	7.05359
215.074	6.68333
218.699	6.79375
222.321	6.12403
225.941	6.94761
229.562	7.99913
233.18	9.04279
236.796	6.42325
240.411	5.61426
244.026	5.4682
247.638	5.74141
251.248	6.3414
254.857	6.20099
258.465	5.77602
262.071	5.77052
265.678	6.04828
269.282	6.91498
272.884	7.68436
276.484	9.04329
280.084	10.8383
283.682	12.4822
287.276	14.605
290.871	15.9857
294.465	18.2005
298.057	19.2874
301.648	18.7553
305.237	19.7024
308.823	19.9254
312.41	20.9115
315.995	22.2315
319.579	21.1196
323.16	19.1279
326.741	18.8708
330.321	18.4318
333.897	17.7506
337.474	18.1796
341.048	16.8313
344.622	15.7355
348.192	15.5019
351.764	15.0773
355.332	15.1245
358.901	14.7949
362.466	14.993
366.03	14.9591
369.594	15.6261
373.155	16.8665
376.715	17.1727
380.273	15.9333
383.832	14.1245
387.388	12.3898
390.942	11.9555
394.495	11.6762
398.047	12.421
401.597	12.7281
405.145	12.8634
408.693	11.3748
412.239	11.653
415.783	12.6063
419.327	11.3653
422.869	10.9043
426.409	10.2479
429.948	10.1606
433.486	9.42866
437.022	10.2018
440.558	10.3326
444.089	10.7953
447.622	12.9072
451.153	12.8034
454.682	12.6775
458.208	12.2042
461.735	12.734
465.259	12.2962
468.783	13.1728
472.306	14.1735
475.825	16.6498
479.346	17.8423
482.862	20.1868
486.38	22.9434
489.894	24.6141
493.407	25.9749
496.92	26.8752
500.43	27.9699
503.939	27.5505
507.448	27.0589
510.954	28.0529
514.459	28.0944
517.962	27.7783
521.466	27.5998
524.966	27.8311
528.466	26.2387
531.964	24.7785
535.46	22.9306
538.955	20.9602
542.449	17.0113
545.942	15.4462
549.433	14.1978
552.923	13.0151
556.412	12.4068
559.899	11.3919
563.385	11.2993
566.867	11.3696
570.35	12.1016
573.832	12.3476
577.313	11.2839
580.79	9.66712
584.268	8.94829
587.745	7.70579
591.218	9.17244
594.692	9.41308
598.164	9.47392
601.634	8.81262
605.104	8.48988
608.57	6.8221
612.037	6.67405
615.501	5.47597
618.966	4.84326
622.427	5.67613
625.887	5.78138
629.348	5.05919
632.806	5.73483
636.262	8.59325
639.716	9.31119
643.172	9.6438
646.624	10.701
650.075	11.2196
653.524	12.208
656.972	11.7489
660.419	11.4831
663.865	10.4288
667.309	10.5032
670.752	10.8908
674.194	11.753
677.634	13.171
681.073	13.9422
684.511	13.6551
687.947	14.5965
691.382	16.7939
694.816	19.8919
698.247	23.0867
701.678	25.9691
705.108	27.8272
708.534	30.3945
711.962	32.3179
715.388	34.0902
718.81	37.1125
722.234	38.6991
725.654	40.1466
729.075	41.8227
732.492	45.0544
735.91	47.1405
739.325	47.1294
742.741	48.7464
746.153	49.5035
749.564	52.1231
752.976	53.5959
756.385	57.0292
759.792	59.7975
763.2	62.5104
766.604	64.3166
770.008	65.606
773.41	69.4409
776.811	71.6941
780.21	74.6224
783.608	75.1221
787.005	76.7269
790.401	77.7888
793.795	78.5117
797.188	77.4077
800.58	78.0888
803.971	78.4612
807.36	79.1154
810.748	80.2342
814.135	80.3042
817.518	81.4088
820.902	79.7382
824.285	79.3302
827.665	79.4361
831.045	80.034
834.424	78.9657
837.8	78.9924
841.177	77.8165
844.55	78.0717
847.924	75.8098
851.295	72.7377
854.666	71.3555
858.034	68.8747
861.403	66.8188
864.769	65.8558
868.133	64.9976
871.498	63.7879
874.86	62.4567
878.221	60.0102
881.58	56.8936
884.938	55.2676
888.297	55.519
891.653	54.3977
895.007	54.167
898.36	53.9788
901.712	53.8847
905.063	54.3096
908.412	54.3973
911.76	54.368
915.107	53.3259
918.452	52.2517
921.797	51.1278
925.138	47.8779
928.48	46.7272
931.82	43.2784
935.16	42.4271
938.496	41.0309
941.833	42.0274
945.168	39.9979
948.5	39.9223
951.834	39.9577
955.163	38.7153
958.494	36.7753
961.821	36.3557
965.15	35.438
968.474	37.253
971.8	36.9596
975.123	37.7767
978.446	38.7395
981.766	39.7714
985.084	41.1918
988.402	41.8437
991.72	41.3181
995.035	39.5753
998.349	38.1829
1001.66	34.4927
1004.97	33.005
1008.28	33.0206
1011.59	36.0543
1014.9	38.4609
1018.21	42.381
1021.51	44.9443
1024.81	45.7613
1028.12	47.8527
1031.42	50.3425
1034.72	51.5653
1038.02	52.4169
1041.31	50.2175
1044.61	49.0773
1047.91	47.7466
1051.2	47.0149
1054.49	46.5198
1057.78	43.4955
1061.07	40.7257
1064.36	38.0309
1067.65	34.3257
1070.93	29.5607
1074.22	25.0518
1077.5	20.4512
1080.78	18.1179
1084.06	14.2183
1087.34	14.2277
1090.62	16.5398
1093.9	18.3033
1097.17	18.0554
1100.45	18.3901
1103.72	18.1663
1106.99	18.6353
1110.27	19.4261
1113.53	19.8216
1116.8	20.146
1120.07	17.9658
1123.33	17.3592
1126.6	15.986
1129.86	16.1474
1133.12	15.7872
1136.38	12.5371
1139.64	11.9219
1142.9	10.9124
1146.16	10.0644
1149.41	8.77435
1152.67	7.48189
1155.92	7.25439
1159.17	7.91019
1162.42	7.34354
1165.67	7.1041
1168.92	8.39038
1172.16	8.28275
1175.41	9.03214
1178.65	9.58232
1181.9	11.5091
1185.14	12.7444
1188.38	14.5261
1191.62	15.9596
1194.86	17.0651
1198.09	18.3253
1201.33	18.2606
1204.56	20.3854
1207.8	22.438
1211.03	24.6436
1214.26	26.0099
1217.49	26.6691
1220.71	28.5847
1223.94	29.6182
1227.16	30.7427
1230.39	30.4723
1233.61	31.9171
1236.83	34.1481
1240.05	36.9202
1243.27	38.1957
1246.49	40.1311
1249.71	42.1296
1252.92	44.7115
1256.14	47.0346
1259.35	47.9013
1262.56	49.7586
1265.77	51.5433
1268.98	52.3841
1272.19	54.5664
1275.4	55.3923
1278.6	56.834
1281.81	59.6501
1285.01	60.4699
1288.21	62.4708
1291.41	64.1027
1294.61	63.6898
1297.81	63.5828
1301.01	64.5932
1304.2	65.0304
1307.4	65.4361
1310.59	66.3048
1313.78	67.0284
1316.97	67.9091
1320.16	66.7125
1323.35	66.3113
1326.54	66.3072
1329.72	66.4288
1332.91	64.9291
1336.09	63.9486
1339.27	60.8727
1342.45	59.127
1345.64	55.2457
1348.81	52.7759
1351.99	51.6379
1355.17	48.828
1358.34	47.8105
1361.51	45.2778
1364.69	41.732
1367.86	39.0729
1371.03	37.4319
1374.2	35.1787
1377.37	33.4532
1380.53	33.4548
1383.7	33.791
1386.86	32.9188
1390.02	32.6352
1393.19	32.824
1396.35	33.7262
1399.51	34.8748
1402.66	34.4202
1405.82	36.5374
1408.97	36.3032
1412.13	37.382
1415.28	38.495
1418.43	41.3454
1421.59	43.7858
1424.73	47.7034
1427.88	51.9413
1431.03	55.6256
1434.18	58.7529
1437.32	61.9066
1440.46	62.5422
1443.61	64.4451
1446.75	66.1454
1449.89	65.3539
1453.03	63.877
1456.16	62.0934
1459.3	61.1645
1462.44	59.7954
1465.57	56.9593
1468.7	52.8467
1471.83	49.3167
1474.96	44.9465
1478.09	39.5241
1481.22	36.0168
1484.35	32.1349
1487.47	28.3807
1490.6	25.3925
1493.72	23.4582
1496.84	21.4045
1499.96	19.8754
1503.08	20.0604
1506.2	19.2897
1509.32	18.508
1512.44	17.5214
1515.55	16.7864
1518.66	16.7547
1521.78	16.7762
1524.89	15.2961
1528	13.8907
1531.11	13.2918
1534.21	14.4377
1537.32	15.1964
1540.43	16.2599
1543.53	16.8906
1546.63	19.3323
1549.74	19.7929
1552.84	20.8027
1555.94	22.7931
1559.03	23.7844
1562.13	24.9137
1565.23	27.0621
1568.32	29.0366
1571.42	31.3242
1574.51	33.223
1577.6	35.9996
1580.69	38.756
1583.78	41.4649
1586.87	42.7646
1589.95	43.3898
1593.04	44.9198
1596.12	44.8489
1599.21	44.8509
1602.29	44.8186
1605.37	44.0029
1608.45	43.238
1611.53	42.798
1614.6	41.7829
1617.68	41.6775
1620.75	42.7493
1623.83	42.5631
1626.9	43.4258
1629.97	44.3765
1633.04	46.3342
1636.11	48.1775
1639.18	50.4688
1642.25	54.1009
1645.31	56.5021
1648.38	59.5063
1651.44	62.8309
1654.5	65.023
1657.56	66.2998
1660.62	67.1158
1663.68	66.5567
1666.74	65.2863
1669.8	62.291
1672.85	60.6491
1675.91	58.4492
1678.96	53.3715
1682.01	48.4823
1685.06	43.2428
1688.11	38.7603
1691.16	34.6489
1694.21	31.4452
1697.25	27.7012
1700.3	25.2448
1703.34	21.7465
1706.39	18.4787
1709.43	16.0504
1712.47	13.2774
1715.51	11.8117
1718.54	10.3223
1721.58	8.60442
1724.62	7.42931
1727.65	6.93443
1730.68	6.49952
1733.72	6.64075
1736.75	6.89278
1739.78	6.33913
1742.81	5.68184
1745.84	6.49024
1748.86	6.23312
1751.89	5.03246
1754.91	3.82009
1757.93	3.63649
1760.96	4.14354
1763.98	3.86653
1767	3.34841
1770.02	5.11586
1773.03	5.46634
1776.05	5.95761
1779.07	5.60306
1782.08	5.91645
1785.09	5.9716
1788.11	6.56291
1791.12	6.01414
1794.13	6.21751
1797.13	5.6784
1800.14	5.8804
1803.15	5.76733
1806.15	5.78476
1809.16	5.83209
1812.16	4.91563
1815.16	4.69346
1818.16	4.40482
1821.16	2.83205
1824.16	2.4112
1827.16	2.37986
1830.16	1.61107
1833.15	2.0159
1836.14	2.04297
1839.14	2.20339
1842.13	4.3113
1845.12	4.08642
1848.11	4.18
1851.1	4.93899
1854.08	5.8199
1857.07	5.65958
1860.05	5.78518
1863.04	5.2984
1866.02	4.14112
1869	3.90072
1871.98	3.11306
1874.96	3.46713
1877.94	3.3167
1880.92	2.85947
1882.51	2.62222
1885.5	3.52812
1888.48	3.43033
1891.47	3.84517
1894.46	4.16233
1897.44	4.33325
1900.42	4.85701
1903.41	4.78121
1906.39	5.79851
1909.37	5.4012
1912.35	5.07577
1915.32	5.59202
1918.3	5.8346
1921.27	6.18536
1924.25	5.83109
1927.22	5.81369
1930.19	5.24659
1933.17	4.4888
1936.14	4.54057
1939.11	3.84655
1942.07	3.95576
1945.04	4.87996
1948.01	4.90569
1950.97	4.72895
1953.93	4.94047
1956.9	4.39992
1959.86	5.48826
1962.82	5.41085
1965.78	4.33452
1968.74	3.85912
1971.69	3.04392
1974.65	2.60339
1977.6	2.53347
1980.56	2.64958
1983.51	1.05539
1986.46	1.5242
1989.41	1.26458
1992.36	1.2082
1995.31	1.38006
1998.26	1.62928
2001.2	1.73177
2004.15	1.37661
2007.09	2.07182
2010.04	3.52378
2012.98	3.33145
2015.92	4.27298
2018.86	3.76468
2021.8	4.21424
2024.73	4.19928
2027.67	5.03803
2030.61	5.59729
2033.54	6.3045
2036.47	5.93529
2039.4	6.77503
2042.33	7.24574
2045.27	8.98753
2048.19	8.9554
2051.12	9.63773
2054.05	10.478
2056.97	11.4026
2059.9	12.0497
2062.82	12.3014
2065.74	13.3853
2068.67	14.442
2071.59	15.8053
2074.51	16.4132
2077.42	17.176
2080.34	17.8208
2083.26	18.1194
2086.17	18.48
2089.09	18.8661
2092	18.9052
2094.91	20.2313
2097.82	21.4604
2100.73	22.6992
2103.64	23.5575
2106.55	23.7015
2109.45	25.1757
2112.36	26.1503
2115.26	28.9684
2118.17	30.376
2121.07	30.8823
2123.97	32.2777
2126.87	34.832
2129.77	36.504
2132.67	38.6453
2135.56	41.8032
2138.46	45.3801
2141.35	48.3735
2144.25	52.2015
2147.14	55.4557
2150.03	59.1688
2152.92	62.8834
2155.81	66.6157
2158.7	70.5105
2161.59	72.704
2164.47	75.4904
2167.36	77.5236
2170.24	78.6281
2173.13	78.603
2176.01	78.347
2178.89	78.3115
2181.77	77.4998
2184.65	76.742
2187.53	73.9233
2190.4	71.278
2193.28	68.0873
2196.16	66.7681
2199.03	64.4205
2201.9	60.9252
2204.77	58.0024
2207.64	54.7176
2210.51	51.1466
2213.38	49.5806
2216.25	47.993
2219.12	44.6347
2221.98	42.2742
2224.85	40.643
2227.71	38.2945
2230.57	35.4805
2233.43	33.3795
2236.29	30.7101
2239.15	28.148
2242.01	26.6362
2244.87	25.1738
2247.72	23.4488
2250.58	21.9549
2253.43	20.2807
2256.29	19.9713
2259.14	18.9086
2261.99	18.0296
2264.84	17.4779
2267.69	17.7473
2270.53	16.5554
2273.38	15.0674
2276.23	14.0888
2279.07	12.6283
2281.91	12.4305
2284.76	11.8787
2287.6	10.9432
2290.44	9.75695
2293.28	8.10939
2296.12	7.55832
2298.96	7.21618
2301.79	8.49344
2304.63	8.83863
2307.46	8.44073
2310.3	9.52547
2313.13	9.28982
2315.96	9.00733
2318.79	8.80408
2321.62	9.64588
2324.45	9.50955
2327.27	8.72032
2330.1	8.11875
2332.92	8.8714
2335.75	8.84326
2338.57	8.1864
2341.39	6.96525
2344.21	5.62683
2347.04	5.07128
2349.85	4.71479
2352.67	3.89459
2355.49	3.33963
2358.3	1.53854
2361.12	0.453779
2363.93	0.547611
2366.75	1.95321
2369.56	2.55511
2372.37	2.7331
2375.18	2.39655
2377.99	2.57251
2380.8	2.22065
2383.6	1.11765
2386.41	1.75347
2389.21	2.47513
2392.02	3.47463
2394.82	4.01123
2397.62	3.82422
2400.42	4.71465
2403.22	5.7467
2406.02	6.19108
2408.82	6.10291
2411.62	6.05305
2414.41	5.9351
2417.21	6.60972
2420	5.97347
2422.79	4.88897
2425.59	3.81949
2428.38	3.15714
2431.17	3.10688
2433.95	2.11604
2436.74	1.70972
2439.53	1.68655
2442.31	1.01522
2445.1	0.749199
2447.88	0.759639
2450.67	0.496347
2453.45	1.83104
2456.23	2.4256
2459.01	3.01567
2461.79	3.7736
2464.57	4.03865
2467.34	3.63389
2470.12	4.08844
2472.89	4.26672
2475.67	4.63227
2478.44	5.24145
2481.21	4.76266
2483.98	4.53249
2486.75	3.89374
2489.52	2.92511
2492.29	3.38963
2495.05	2.8073
2497.82	2.18445
2500.58	2.6668
2503.35	3.00154
2506.11	2.28711
2508.87	2.87905
2511.63	2.46369
2514.39	3.48768
2517.15	3.91642
2519.91	4.02761
2522.67	4.70269
2525.42	4.16011
2528.18	4.65777
2530.93	4.30357
2533.69	4.32697
2536.44	3.29776
2539.19	3.65765
2541.94	3.89958
2544.69	3.79809
2547.44	3.75695
2550.18	3.15149
2552.93	3.03371
2555.67	2.8258
2558.42	3.42223
2561.16	3.64898
2563.9	4.253
2566.64	4.50461
2569.38	5.00342
2572.12	4.38211
2574.86	4.15458
2577.6	5.21478
2580.33	5.34891
2583.07	5.41832
2585.8	5.88968
2588.54	6.17859
2591.27	6.113
2594	5.82107
2596.73	4.62735
2599.46	4.30154
2602.19	4.13901
2604.92	3.74524
2607.64	3.63928
2610.37	3.34351
2613.09	2.26575
2615.82	2.28872
2618.54	1.52564
2621.26	1.52504
2623.98	1.85304
2626.7	2.8277
2629.42	3.10279
2632.14	2.43988
2634.86	2.78467
2637.57	2.83894
2640.29	3.33103
2643	3.94439
2645.71	4.46159
2648.43	5.30356
2651.14	5.63864
2653.85	5.8109
2656.56	5.22372
2659.26	4.66781
2661.97	4.64305
2664.68	3.92063
2667.38	3.85642
2670.09	4.22373
2672.79	3.65707
2675.49	3.71044
2678.19	3.01722
2680.89	2.5837
2683.59	2.07126
2686.29	1.6559
2688.99	1.91501
2691.69	2.31793
2694.38	1.65448
2697.08	2.31174
2699.77	2.94349
2702.46	3.96469
2705.15	3.67354
2707.85	3.66843
2710.54	4.72849
2713.22	5.75999
2715.91	6.32002
2718.6	6.28961
2721.29	6.31792
2723.97	6.4446
2726.66	6.59782
2729.34	5.79837
2732.02	5.65435
2734.7	6.40047
2737.38	6.79174
2740.06	6.83102
2742.74	6.51923
2745.42	5.25082
2748.09	4.26147
2750.77	3.09564
2753.45	2.81947
2756.12	2.26925
2758.79	2.17111
2761.46	1.87009
2764.14	1.93316
2766.8	1.51051
2769.47	0.818478
2772.14	0.20624
2774.81	1.78249
2777.48	1.99193
2780.14	2.08306
2782.8	2.84499
2785.47	2.94421
2788.13	2.86091
2790.79	2.77607
2793.45	3.50685
2796.11	3.85343
2798.77	4.31269
2801.43	4.6535
2804.09	4.19119
2806.74	2.99644
2809.4	1.66655
2812.05	1.43135
2814.71	0.526499
2817.36	1.63771
2820.01	2.31766
2822.66	4.18474
2825.31	7.13374
2827.96	9.21456
2830.6	12.6813
2833.25	15.1416
2835.9	18.5675
2838.54	22.9358
2841.18	27.0736
2843.83	31.9841
2846.47	36.9004
2849.11	43.5298
2851.75	49.95
2854.39	57.5119
2857.03	63.6858
2859.66	70.0607
2862.3	76.1303
2864.94	80.8666
2867.57	85.8879
2870.2	89.4861
2872.84	93.5685
2875.47	97.8859
2878.1	101.966
2880.73	105.554
2883.36	110.122
2885.99	113.026
2888.61	116.965
2891.24	122.034
2893.86	125.754
2896.49	130.243
2899.11	134.681
2901.73	140.526
2904.36	148.085
2906.98	156.912
2909.6	164.743
2912.21	173.269
2914.83	182.581
2917.45	191.042
2920.07	198.122
2922.68	204.774
2925.29	210.956
2927.91	214.426
2930.52	216.846
2933.13	218.13
2935.74	216.994
2938.35	214.44
2940.96	211.612
2943.57	206.091
2946.18	199.935
2948.78	193.192
2951.39	185.296
2953.99	178.261
2956.59	170.695
2959.2	161.863
2961.8	153.583
2964.4	145.705
2967	137.873
2969.6	130.616
2972.19	122.021
2974.79	113.68
2977.39	106.815
2979.98	99.9934
2982.58	92.1375
2985.17	84.8233
2987.76	76.7317
2990.35	69.1328
2992.94	61.5255
2995.53	54.2444
2998.12	47.6931
3000.71	40.8242
3003.3	34.9955
3005.88	29.9557
3008.47	25.7254
3011.05	21.9287
3013.64	18.2162
3016.22	15.4843
3018.8	13.359
3021.38	10.3124
3023.96	9.02953
3026.54	6.6987
3029.12	4.99848
3031.69	4.21979
3034.27	3.65271
3036.84	4.07217
3039.42	4.05876
3041.99	4.83721
3044.57	4.4654
3047.14	4.9729
3049.71	5.07505
3052.28	5.31247
3054.85	5.29974
3057.41	5.51736
3059.98	5.09082
3062.55	5.3137
3065.11	5.94653
3067.68	6.89115
3070.24	7.45016
3072.8	6.90631
3075.36	5.47829
3077.93	5.70021
3080.49	4.73889
3083.04	4.01293
3085.6	3.57178
3088.16	2.7665
3090.72	1.81944
3093.27	1.25754
3095.83	1.65702
3098.38	1.48889
3100.93	0.931051
3103.49	1.45098
3106.04	1.24273
3108.59	0.753108
3111.14	0.355343
3113.69	-0.462091
3116.23	-0.172179
3118.78	0.322937
3121.33	0.682863
3123.87	0.602628
3126.41	1.53057
3128.96	2.11057
3131.5	2.11657
3134.04	2.18739
3136.58	2.29211
3139.12	3.63152
3141.66	5.13872
3144.2	6.05523
3146.74	7.72724
3149.27	9.71427