File: data/Raman/poly_smoothed/Mb_30_27_27_1x_45s_532 nm_x100_100%_600 gr_mm_01.txt
#Acq. time (s)=	45
#Accumulations=	2
#Range (cm-¹)=	200...3150
#Windows=	2
#Auto scanning=	Off
#Autofocus=	Off
#Macrospot=	Off
#AutoExposure=	Off
#Spike filter=	Multiple accum.
#Delay time (s)=	0
#Binning=	1
#Readout mode=	Signal
#DeNoise=	Off
#ICS correction=	On
#Dark correction=	Off
#Inst. Process=	Off
#Detector Gain=	Best Dynamic Range
#Detector ADC=	20 kHz
#Detector temperature (°C)=	-69.85
#Instrument=	LabRAM HR Evol
#Detector=	Synapse
#Objective=	x100
#Grating=	600 gr/mm
#ND Filter=	100%
#Laser (nm)=	532
#Hole=	100.021
#Range=	Auto
#Laser Pol.=	No
#Raman. Pol.=	No
#Laser Pol. (°)=	-0.0007625
#Raman Pol. (°)=	89.9995
#Collection=	Microscope
#StageXY=	Marzhauser
#StageZ=	Marzhauser
#X (µm)=	-6375.9
#Y (µm)=	850
#Z (µm)=	-64.55
#Full time(mm:ss)=	3:19
#Project=
#Sample=
#Site=
#Title=	Mb_30_27_27_2x_45s_532 nm_x100_100%_600 gr_mm
#Remark=
#Date=	13.07.2022 10:43
#Acquired=	13.07.2022 10:43:37
#Base:Fit=	10.08.2022 10:40:03
#Base:Sub=	10.08.2022 10:40:17
#Filter:Polynom=	16.08.2022 10:16:15
#AxisType[0]=Intens
#AxisUnit[0]=Cnt
#AxisType[1]=Spectr
#AxisUnit[1]=1/cm
200.563	0.498934
204.194	9.63769
207.821	12.8801
211.449	14.0544
215.074	13.439
218.699	12.1156
222.321	10.8929
225.941	10.5468
229.562	11.1166
233.18	11.4472
236.796	12.8721
240.411	12.8483
244.026	12.103
247.638	12.3674
251.248	12.6258
254.857	12.5524
258.465	12.8161
262.071	12.598
265.678	13.3454
269.282	14.1379
272.884	13.8458
276.484	13.5317
280.084	14.8783
283.682	15.1102
287.276	14.9632
290.871	16.0455
294.465	13.9093
298.057	13.8799
301.648	12.8804
305.237	12.8233
308.823	11.5164
312.41	12.4351
315.995	13.3479
319.579	12.138
323.16	12.388
326.741	12.026
330.321	11.4839
333.897	10.8034
337.474	11.8575
341.048	11.9026
344.622	10.3475
348.192	8.04106
351.764	5.78093
355.332	4.79386
358.901	3.70702
362.466	2.75565
366.03	3.6922
369.594	3.46055
373.155	2.87704
376.715	3.85101
380.273	4.18113
383.832	5.89203
387.388	6.35049
390.942	6.57116
394.495	6.90382
398.047	8.10513
401.597	8.14778
405.145	9.03501
408.693	8.96353
412.239	8.66854
415.783	9.41564
419.327	9.15222
422.869	9.14959
426.409	8.3643
429.948	6.88824
433.486	5.73114
437.022	4.6424
440.558	3.81174
444.089	2.42499
447.622	2.59564
451.153	3.21096
454.682	3.00873
458.208	2.86136
461.735	5.52352
465.259	6.46001
468.783	8.18938
472.306	8.75012
475.825	10.3593
479.346	12.3166
482.862	14.7412
486.38	15.8597
489.894	16.1519
493.407	18.1591
496.92	18.2672
500.43	19.2915
503.939	20.1166
507.448	21.2357
510.954	20.9869
514.459	21.329
517.962	21.0285
521.466	20.1735
524.966	18.6453
528.466	16.6249
531.964	16.073
535.46	17.1415
538.955	16.4646
542.449	15.9348
545.942	14.5198
549.433	13.7426
552.923	13.4982
556.412	13.9294
559.899	14.639
563.385	15.05
566.867	14.5022
570.35	13.2646
573.832	11.6236
577.313	10.7006
580.79	9.84628
584.268	8.54112
587.745	7.90826
591.218	8.58475
594.692	7.99923
598.164	7.35499
601.634	8.90987
605.104	9.61026
608.57	9.82803
612.037	11.0053
615.501	12.6082
618.966	14.7234
622.427	15.975
625.887	17.9174
629.348	18.6772
632.806	20.7323
636.262	22.8462
639.716	24.3901
643.172	25.5379
646.624	26.1918
650.075	27.0218
653.524	26.6527
656.972	26.3142
660.419	28.1624
663.865	28.9213
667.309	29.725
670.752	30.4058
674.194	32.3436
677.634	33.0949
681.073	35.0194
684.511	37.2459
687.947	38.9921
691.382	39.7748
694.816	41.9014
698.247	43.7749
701.678	45.7768
705.108	47.3955
708.534	49.0566
711.962	51.0747
715.388	52.6389
718.81	54.2542
722.234	55.2922
725.654	55.5054
729.075	57.5994
732.492	58.1525
735.91	60.6424
739.325	61.7254
742.741	63.6307
746.153	65.501
749.564	68.0038
752.976	69.675
756.385	72.0314
759.792	72.9223
763.2	74.5475
766.604	76.1925
770.008	77.2164
773.41	78.7313
776.811	80.7765
780.21	82.575
783.608	82.2379
787.005	84.0892
790.401	86.7129
793.795	89.023
797.188	89.3393
800.58	89.2849
803.971	87.9357
807.36	88.2837
810.748	89.5366
814.135	89.6123
817.518	90.1753
820.902	90.3724
824.285	90.1237
827.665	91.6759
831.045	90.8073
834.424	90.8465
837.8	88.5825
841.177	86.7092
844.55	84.9416
847.924	82.8157
851.295	80.3616
854.666	77.7295
858.034	73.485
861.403	70.7615
864.769	70.2294
868.133	69.8013
871.498	70.2298
874.86	69.2821
878.221	67.984
881.58	66.742
884.938	66.0736
888.297	65.7129
891.653	66.1886
895.007	66.2893
898.36	66.6967
901.712	65.3304
905.063	65.0768
908.412	63.6423
911.76	63.2157
915.107	61.6448
918.452	59.833
921.797	57.9505
925.138	56.2879
928.48	54.8196
931.82	52.5736
935.16	50.2944
938.496	47.3578
941.833	46.1778
945.168	48.4598
948.5	48.4021
951.834	47.056
955.163	47.1394
958.494	47.1232
961.821	46.8955
965.15	46.5097
968.474	45.3576
971.8	45.421
975.123	45.0822
978.446	44.0827
981.766	42.8727
985.084	42.3485
988.402	40.5816
991.72	37.6988
995.035	37.7267
998.349	33.8729
1001.66	31.5755
1004.97	30.7924
1008.28	30.4439
1011.59	30.3729
1014.9	30.0254
1018.21	30.4903
1021.51	30.1056
1024.81	31.7463
1028.12	32.9486
1031.42	33.5244
1034.72	34.0331
1038.02	35.042
1041.31	34.2367
1044.61	35.3607
1047.91	35.3359
1051.2	34.7427
1054.49	34.1542
1057.78	34.2529
1061.07	32.5969
1064.36	31.1511
1067.65	28.4305
1070.93	25.8653
1074.22	23.3265
1077.5	21.103
1080.78	19.5762
1084.06	18.726
1087.34	18.3135
1090.62	17.9053
1093.9	17.5738
1097.17	17.5507
1100.45	17.5318
1103.72	16.5675
1106.99	16.5513
1110.27	17.4692
1113.53	15.9123
1116.8	13.5868
1120.07	12.2022
1123.33	12.0551
1126.6	12.7835
1129.86	11.7675
1133.12	11.4912
1136.38	11.8947
1139.64	11.0607
1142.9	10.3834
1146.16	9.06153
1149.41	7.6481
1152.67	6.61006
1155.92	6.93896
1159.17	6.83137
1162.42	6.68716
1165.67	5.4824
1168.92	5.36865
1172.16	5.86645
1175.41	5.93756
1178.65	5.09226
1181.9	5.04007
1185.14	4.36583
1188.38	4.23728
1191.62	4.68081
1194.86	4.08742
1198.09	4.51465
1201.33	5.67611
1204.56	7.74788
1207.8	8.06093
1211.03	8.43338
1214.26	9.3847
1217.49	11.1841
1220.71	12.3227
1223.94	13.5335
1227.16	15.8562
1230.39	16.8889
1233.61	18.3794
1236.83	22.151
1240.05	23.2065
1243.27	24.3928
1246.49	24.5951
1249.71	24.3666
1252.92	25.8391
1256.14	25.4869
1259.35	26.0563
1262.56	26.9285
1265.77	27.4499
1268.98	28.4276
1272.19	30.0234
1275.4	28.7199
1278.6	29.5715
1281.81	30.2696
1285.01	32.5101
1288.21	31.8357
1291.41	31.9807
1294.61	32.856
1297.81	33.8795
1301.01	34.0623
1304.2	33.6031
1307.4	33.2038
1310.59	33.4275
1313.78	35.7193
1316.97	37.2748
1320.16	36.4889
1323.35	36.1738
1326.54	36.5239
1329.72	36.8134
1332.91	36.7435
1336.09	37.0208
1339.27	37.0476
1342.45	36.3567
1345.64	36.8136
1348.81	35.1707
1351.99	33.9227
1355.17	32.9194
1358.34	31.5053
1361.51	30.6515
1364.69	27.9825
1367.86	24.9597
1371.03	23.1972
1374.2	22.0428
1377.37	20.4494
1380.53	18.7381
1383.7	18.3654
1386.86	17.8442
1390.02	19.1915
1393.19	18.8615
1396.35	17.6774
1399.51	17.8255
1402.66	17.7771
1405.82	19.1597
1408.97	19.734
1412.13	20.7433
1415.28	21.5834
1418.43	22.3874
1421.59	22.9188
1424.73	24.0615
1427.88	24.9673
1431.03	26.3395
1434.18	28.4292
1437.32	30.0523
1440.46	32.2699
1443.61	35.2468
1446.75	35.8367
1449.89	36.4099
1453.03	36.5491
1456.16	38.2247
1459.3	39.9626
1462.44	39.8833
1465.57	40.6945
1468.7	40.9156
1471.83	39.9786
1474.96	39.8327
1478.09	40.1737
1481.22	40.2041
1484.35	38.9796
1487.47	37.2447
1490.6	34.0648
1493.72	32.3407
1496.84	29.9792
1499.96	26.9041
1503.08	25.2431
1506.2	22.1327
1509.32	20.1924
1512.44	18.0417
1515.55	16.3102
1518.66	14.1635
1521.78	11.8639
1524.89	9.54527
1528	6.81328
1531.11	6.14071
1534.21	6.27808
1537.32	6.35489
1540.43	7.59488
1543.53	8.58382
1546.63	10.9783
1549.74	11.6423
1552.84	11.5589
1555.94	12.2686
1559.03	13.4316
1562.13	14.0893
1565.23	13.4497
1568.32	13.8178
1571.42	16.0733
1574.51	17.4906
1577.6	19.1621
1580.69	21.1201
1583.78	21.9655
1586.87	23.0792
1589.95	24.973
1593.04	26.4812
1596.12	26.5004
1599.21	28.1311
1602.29	28.4257
1605.37	28.7227
1608.45	29.8297
1611.53	30.9624
1614.6	32.2076
1617.68	33.6291
1620.75	33.8487
1623.83	35.1516
1626.9	34.4096
1629.97	35.3025
1633.04	36.8464
1636.11	37.7506
1639.18	38.7443
1642.25	39.5368
1645.31	41.0064
1648.38	43.5224
1651.44	44.1883
1654.5	44.2663
1657.56	44.2328
1660.62	44.5238
1663.68	44.6126
1666.74	43.2353
1669.8	41.3412
1672.85	38.6567
1675.91	36.57
1678.96	32.6285
1682.01	29.6829
1685.06	27.9213
1688.11	24.7804
1691.16	22.2029
1694.21	19.7719
1697.25	17.6024
1700.3	14.7056
1703.34	12.2905
1706.39	10.1145
1709.43	9.26618
1712.47	7.25859
1715.51	5.90989
1718.54	5.19503
1721.58	4.60358
1724.62	4.10617
1727.65	3.16382
1730.68	2.89619
1733.72	3.12447
1736.75	2.41489
1739.78	1.57253
1742.81	2.39472
1745.84	1.90913
1748.86	1.82053
1751.89	1.83544
1754.91	1.76518
1757.93	2.21588
1760.96	2.1308
1763.98	2.73437
1767	1.77753
1770.02	1.97839
1773.03	1.88295
1776.05	1.65769
1779.07	1.83667
1782.08	2.51612
1785.09	3.33579
1788.11	3.26377
1791.12	4.31577
1794.13	4.79712
1797.13	4.1893
1800.14	3.92923
1803.15	4.37347
1806.15	4.58561
1809.16	5.19989
1812.16	5.73915
1815.16	5.77845
1818.16	5.13945
1821.16	4.24833
1824.16	3.58525
1827.16	3.74515
1830.16	3.82473
1833.15	3.12141
1836.14	2.8372
1839.14	2.73954
1842.13	2.43785
1845.12	2.55236
1848.11	2.38819
1851.1	2.91045
1854.08	3.30892
1857.07	3.13438
1860.05	3.44349
1863.04	3.5841
1866.02	3.90805
1869	3.51642
1871.98	3.82521
1874.96	3.79228
1877.94	4.29304
1880.92	4.66323
1882.51	4.90276
1885.5	5.18956
1888.48	5.13776
1891.47	5.65413
1894.46	6.44705
1897.44	7.26672
1900.42	7.33168
1903.41	7.30102
1906.39	7.66894
1909.37	7.4094
1912.35	8.1373
1915.32	8.24249
1918.3	8.39608
1921.27	8.44119
1924.25	7.49512
1927.22	6.74917
1930.19	6.76582
1933.17	6.71167
1936.14	6.41166
1939.11	5.77062
1942.07	5.61209
1945.04	5.36421
1948.01	4.47959
1950.97	5.27842
1953.93	5.02079
1956.9	6.14976
1959.86	6.20088
1962.82	5.72756
1965.78	5.96963
1968.74	4.92143
1971.69	4.31897
1974.65	4.34474
1977.6	4.92787
1980.56	5.06929
1983.51	5.00474
1986.46	5.0263
1989.41	5.67469
1992.36	5.64878
1995.31	5.43747
1998.26	5.62962
2001.2	7.2826
2004.15	7.51984
2007.09	6.9077
2010.04	6.74775
2012.98	6.57417
2015.92	6.91592
2018.86	6.21934
2021.8	5.55403
2024.73	5.95496
2027.67	6.36983
2030.61	5.51513
2033.54	5.32132
2036.47	4.65375
2039.4	4.99463
2042.33	5.67023
2045.27	6.20555
2048.19	7.25023
2051.12	7.93819
2054.05	8.91753
2056.97	9.48444
2059.9	10.5305
2062.82	11.9491
2065.74	12.3995
2068.67	13.7788
2071.59	14.7497
2074.51	15.3855
2077.42	14.9529
2080.34	14.3738
2083.26	14.684
2086.17	14.6222
2089.09	14.1065
2092	13.7332
2094.91	14.3176
2097.82	14.1742
2100.73	13.0084
2103.64	13.2496
2106.55	13.1215
2109.45	13.3952
2112.36	14.4875
2115.26	14.5845
2118.17	15.5637
2121.07	16.5267
2123.97	18.3273
2126.87	20.4946
2129.77	22.6073
2132.67	24.8483
2135.56	26.7735
2138.46	30.4504
2141.35	33.5732
2144.25	36.6181
2147.14	38.5224
2150.03	41.6669
2152.92	44.0809
2155.81	46.8557
2158.7	47.3255
2161.59	49.7615
2164.47	50.7269
2167.36	52.3661
2170.24	52.0598
2173.13	52.2257
2176.01	51.3639
2178.89	51.0035
2181.77	51.2039
2184.65	49.8545
2187.53	49.0617
2190.4	48.4991
2193.28	46.786
2196.16	45.9769
2199.03	44.9582
2201.9	43.033
2204.77	40.8767
2207.64	39.1811
2210.51	36.7022
2213.38	34.7481
2216.25	31.5788
2219.12	29.7802
2221.98	27.6779
2224.85	25.3995
2227.71	23.4712
2230.57	23.1855
2233.43	22.366
2236.29	21.4499
2239.15	20.119
2242.01	17.6104
2244.87	16.9191
2247.72	16.5131
2250.58	16.4317
2253.43	16.5291
2256.29	15.8434
2259.14	15.9842
2261.99	16.3908
2264.84	15.4716
2267.69	14.7276
2270.53	13.4586
2273.38	13.1413
2276.23	12.315
2279.07	12.1582
2281.91	12.6426
2284.76	12.3046
2287.6	11.8759
2290.44	11.1893
2293.28	9.30433
2296.12	9.84433
2298.96	10.708
2301.79	11.8449
2304.63	11.7375
2307.46	11.3933
2310.3	10.826
2313.13	11.0515
2315.96	11.2841
2318.79	11.9255
2321.62	11.0552
2324.45	11.2998
2327.27	11.3587
2330.1	11.1505
2332.92	10.3401
2335.75	8.83741
2338.57	8.0418
2341.39	7.88802
2344.21	7.62168
2347.04	7.0174
2349.85	6.26181
2352.67	5.16813
2355.49	4.88592
2358.3	3.71071
2361.12	3.54103
2363.93	4.28377
2366.75	5.1242
2369.56	5.69171
2372.37	6.23082
2375.18	5.65247
2377.99	5.45075
2380.8	4.87644
2383.6	4.76351
2386.41	5.64524
2389.21	5.39072
2392.02	5.17808
2394.82	5.7886
2397.62	5.46633
2400.42	4.7737
2403.22	4.52322
2406.02	4.42325
2408.82	4.9069
2411.62	5.39524
2414.41	5.41054
2417.21	5.06732
2420	4.97772
2422.79	5.29343
2425.59	5.49323
2428.38	5.22125
2431.17	5.13704
2433.95	5.19555
2436.74	5.2668
2439.53	5.94205
2442.31	4.95949
2445.1	4.50159
2447.88	4.02531
2450.67	3.39247
2453.45	3.81933
2456.23	3.57359
2459.01	3.80347
2461.79	3.69663
2464.57	4.108
2467.34	3.67428
2470.12	4.14001
2472.89	3.80461
2475.67	4.18297
2478.44	4.17293
2481.21	4.04234
2483.98	3.54219
2486.75	2.87425
2489.52	2.56531
2492.29	2.7607
2495.05	2.76286
2497.82	3.09109
2500.58	3.14228
2503.35	2.58658
2506.11	2.18664
2508.87	2.23585
2511.63	1.61969
2514.39	1.26115
2517.15	1.05554
2519.91	0.862066
2522.67	0.611743
2525.42	0.685399
2528.18	0.910146
2530.93	0.911902
2533.69	0.790038
2536.44	-0.0118083
2539.19	0.124238
2541.94	-0.354874
2544.69	0.401696
2547.44	0.723289
2550.18	1.7873
2552.93	1.18955
2555.67	1.453
2558.42	1.90551
2561.16	1.93455
2563.9	2.62698
2566.64	3.4622
2569.38	3.99692
2572.12	3.79463
2574.86	3.93822
2577.6	3.98435
2580.33	4.39289
2583.07	4.36444
2585.8	4.39865
2588.54	4.41588
2591.27	4.49245
2594	4.21872
2596.73	4.43486
2599.46	3.3832
2602.19	2.70589
2604.92	3.05524
2607.64	2.31695
2610.37	2.10945
2613.09	1.78479
2615.82	1.91142
2618.54	1.03418
2621.26	0.325734
2623.98	0.113961
2626.7	0.31288
2629.42	0.328797
2632.14	1.06934
2634.86	1.20952
2637.57	1.15828
2640.29	0.937147
2643	0.985929
2645.71	1.34497
2648.43	1.66198
2651.14	2.22908
2653.85	2.5536
2656.56	2.60185
2659.26	2.54257
2661.97	2.15357
2664.68	2.38355
2667.38	2.268
2670.09	2.81149
2672.79	2.84888
2675.49	2.28986
2678.19	2.0299
2680.89	1.81227
2683.59	0.861133
2686.29	1.24618
2688.99	0.732757
2691.69	1.66518
2694.38	1.91559
2697.08	2.74323
2699.77	3.66986
2702.46	4.35243
2705.15	4.895
2707.85	5.1748
2710.54	4.96167
2713.22	5.10995
2715.91	4.73642
2718.6	4.61909
2721.29	4.70821
2723.97	4.254
2726.66	4.2283
2729.34	3.93909
2732.02	4.12005
2734.7	3.77441
2737.38	3.81558
2740.06	3.48779
2742.74	3.02794
2745.42	2.91159
2748.09	2.74135
2750.77	2.8834
2753.45	2.65123
2756.12	3.27747
2758.79	3.36781
2761.46	3.59285
2764.14	3.70426
2766.8	3.57306
2769.47	3.54225
2772.14	3.04709
2774.81	2.00378
2777.48	1.71214
2780.14	1.59052
2782.8	1.87821
2785.47	1.58172
2788.13	1.41816
2790.79	0.848271
2793.45	1.09132
2796.11	0.767054
2798.77	1.24196
2801.43	1.7708
2804.09	1.6673
2806.74	1.141
2809.4	0.352524
2812.05	-0.0185533
2814.71	0.58663
2817.36	1.22449
2820.01	2.8966
2822.66	5.25379
2825.31	6.51126
2827.96	9.36055
2830.6	11.8966
2833.25	14.6124
2835.9	17.2161
2838.54	20.0773
2841.18	23.8095
2843.83	27.5195
2846.47	31.4212
2849.11	34.925
2851.75	39.3644
2854.39	44.2125
2857.03	48.6832
2859.66	52.7591
2862.3	56.55
2864.94	59.9986
2867.57	62.4633
2870.2	64.8128
2872.84	67.5291
2875.47	69.6335
2878.1	71.7107
2880.73	74.4336
2883.36	76.1597
2885.99	79.0354
2888.61	80.8259
2891.24	82.8806
2893.86	85.5433
2896.49	88.7828
2899.11	92.1517
2901.73	96.0667
2904.36	100.076
2906.98	105.517
2909.6	111.216
2912.21	117.804
2914.83	124.126
2917.45	131.268
2920.07	136.662
2922.68	141.099
2925.29	145.13
2927.91	148.244
2930.52	149.508
2933.13	149.75
2935.74	150.318
2938.35	148.461
2940.96	145.827
2943.57	142.452
2946.18	138.39
2948.78	132.809
2951.39	127.107
2953.99	121.016
2956.59	114.72
2959.2	108.979
2961.8	102.966
2964.4	96.0069
2967	90.5779
2969.6	85.0056
2972.19	80.0246
2974.79	75.6225
2977.39	70.3498
2979.98	64.9442
2982.58	59.8331
2985.17	54.5872
2987.76	49.6263
2990.35	44.6148
2992.94	39.3575
2995.53	34.5661
2998.12	30.8206
3000.71	27.4778
3003.3	22.9896
3005.88	20.6708
3008.47	16.9733
3011.05	13.8333
3013.64	10.5173
3016.22	7.9855
3018.8	6.31846
3021.38	5.1353
3023.96	3.79435
3026.54	4.15142
3029.12	3.93208
3031.69	3.62261
3034.27	3.69616
3036.84	4.28087
3039.42	4.8529
3041.99	4.70171
3044.57	5.25565
3047.14	5.68865
3049.71	5.90345
3052.28	6.37482
3054.85	6.47624
3057.41	6.53821
3059.98	6.80944
3062.55	6.86508
3065.11	7.08835
3067.68	6.51069
3070.24	6.01908
3072.8	5.14003
3075.36	4.04565
3077.93	3.21156
3080.49	3.4097
3083.04	2.61996
3085.6	2.12776
3088.16	2.39648
3090.72	1.54013
3093.27	0.885738
3095.83	0.523083
3098.38	0.727093
3100.93	0.569635
3103.49	0.620066
3106.04	0.535194
3108.59	1.07287
3111.14	1.24887
3113.69	1.85547
3116.23	2.21238
3118.78	2.71373
3121.33	2.79209
3123.87	3.76359
3126.41	4.25966
3128.96	5.30485
3131.5	6.04785
3134.04	7.47513
3136.58	8.77756
3139.12	9.14498
3141.66	10.2767
3144.2	11.1455
3146.74	12.5459
3149.27	13.6174