File: data/Raman/poly_smoothed/Mb_30_27_37_1x_45s_532 nm_x100_100%_600 gr_mm_01.txt
#Acq. time (s)=	45
#Accumulations=	2
#Range (cm-¹)=	200...3150
#Windows=	2
#Auto scanning=	Off
#Autofocus=	Off
#Macrospot=	Off
#AutoExposure=	Off
#Spike filter=	Multiple accum.
#Delay time (s)=	0
#Binning=	1
#Readout mode=	Signal
#DeNoise=	Off
#ICS correction=	On
#Dark correction=	Off
#Inst. Process=	Off
#Detector Gain=	Best Dynamic Range
#Detector ADC=	20 kHz
#Detector temperature (°C)=	-70.08
#Instrument=	LabRAM HR Evol
#Detector=	Synapse
#Objective=	x100
#Grating=	600 gr/mm
#ND Filter=	100%
#Laser (nm)=	532
#Hole=	100.021
#Range=	Auto
#Laser Pol.=	No
#Raman. Pol.=	No
#Laser Pol. (°)=	-0.0007625
#Raman Pol. (°)=	89.9995
#Collection=	Microscope
#StageXY=	Marzhauser
#StageZ=	Marzhauser
#X (µm)=	-6347.9
#Y (µm)=	802.2
#Z (µm)=	-64.3
#Full time(mm:ss)=	3:18
#Project=
#Sample=
#Site=
#Title=	Mb_30_27_37_2x_45s_532 nm_x100_100%_600 gr_mm
#Remark=
#Date=	13.07.2022 11:28
#Acquired=	13.07.2022 11:28:43
#Base:Fit=	10.08.2022 10:40:03
#Base:Sub=	10.08.2022 10:40:17
#Filter:Polynom=	16.08.2022 10:16:15
#AxisType[0]=Intens
#AxisUnit[0]=Cnt
#AxisType[1]=Spectr
#AxisUnit[1]=1/cm
200.563	18.3871
204.194	18.9783
207.821	17.934
211.449	16.1939
215.074	15.6118
218.699	14.4118
222.321	14.1808
225.941	12.2712
229.562	11.9599
233.18	11.2431
236.796	11.0611
240.411	9.62378
244.026	9.10506
247.638	8.75408
251.248	7.17687
254.857	6.56805
258.465	7.47889
262.071	7.0516
265.678	7.9699
269.282	9.61897
272.884	10.1955
276.484	13.4046
280.084	12.7093
283.682	13.774
287.276	13.2556
290.871	13.984
294.465	15.5524
298.057	16.528
301.648	19.9097
305.237	20.4313
308.823	20.8984
312.41	21.2653
315.995	21.3803
319.579	22.2006
323.16	21.5717
326.741	21.4312
330.321	20.425
333.897	19.9784
337.474	19.0423
341.048	18.4748
344.622	19.3002
348.192	19.3698
351.764	18.3674
355.332	17.9209
358.901	17.7142
362.466	17.2176
366.03	16.2445
369.594	15.3502
373.155	16.0088
376.715	15.4977
380.273	16.6975
383.832	15.457
387.388	16.0656
390.942	15.7716
394.495	13.8921
398.047	11.6555
401.597	10.4151
405.145	10.5759
408.693	9.05514
412.239	8.68031
415.783	7.63179
419.327	7.14894
422.869	5.90928
426.409	6.51007
429.948	5.37
433.486	4.38205
437.022	2.713
440.558	2.88641
444.089	2.4461
447.622	2.93954
451.153	1.57378
454.682	1.78124
458.208	2.49197
461.735	3.06337
465.259	4.66662
468.783	5.08203
472.306	5.82457
475.825	8.30766
479.346	9.32579
482.862	10.8466
486.38	12.6466
489.894	15.0673
493.407	15.6383
496.92	16.5572
500.43	18.2152
503.939	19.374
507.448	19.3976
510.954	19.3918
514.459	19.5668
517.962	18.9961
521.466	18.1706
524.966	18.0903
528.466	17.0233
531.964	16.3582
535.46	14.1279
538.955	13.6685
542.449	12.5749
545.942	12.2949
549.433	12.3212
552.923	13.1217
556.412	12.1654
559.899	12.1739
563.385	13.2104
566.867	13.2814
570.35	13.8693
573.832	13.9576
577.313	14.4807
580.79	13.2665
584.268	14.1354
587.745	13.2711
591.218	10.8295
594.692	10.7695
598.164	9.06037
601.634	8.88412
605.104	8.34133
608.57	8.69915
612.037	9.44317
615.501	9.86184
618.966	11.0863
622.427	10.9626
625.887	11.0251
629.348	12.4354
632.806	12.6616
636.262	13.4494
639.716	15.4705
643.172	15.956
646.624	18.0026
650.075	20.1899
653.524	21.7129
656.972	24.3866
660.419	24.5346
663.865	24.5094
667.309	25.5008
670.752	24.7384
674.194	25.397
677.634	26.6423
681.073	25.5847
684.511	26.093
687.947	28.109
691.382	29.462
694.816	30.5704
698.247	32.5955
701.678	32.0753
705.108	33.4593
708.534	33.6773
711.962	34.7995
715.388	37.0977
718.81	38.1299
722.234	40.4285
725.654	42.0596
729.075	44.3455
732.492	45.8713
735.91	48.2621
739.325	49.9542
742.741	52.224
746.153	54.0005
749.564	55.792
752.976	57.5401
756.385	59.5731
759.792	63.0388
763.2	62.6896
766.604	64.3144
770.008	68.1335
773.41	70.7685
776.811	73.1793
780.21	75.7586
783.608	77.6941
787.005	79.2538
790.401	81.0653
793.795	82.699
797.188	84.881
800.58	86.0258
803.971	85.47
807.36	86.2871
810.748	85.4216
814.135	83.5403
817.518	82.818
820.902	81.7878
824.285	80.8299
827.665	78.719
831.045	75.7751
834.424	74.1852
837.8	72.3274
841.177	70.5917
844.55	69.1594
847.924	66.1053
851.295	65.0046
854.666	62.9226
858.034	60.6826
861.403	58.5491
864.769	56.315
868.133	54.7589
871.498	52.7029
874.86	50.6623
878.221	49.6717
881.58	47.5991
884.938	47.2913
888.297	46.7674
891.653	46.787
895.007	46.8847
898.36	46.7649
901.712	47.8144
905.063	48.0931
908.412	46.662
911.76	45.9866
915.107	46.3882
918.452	46.1867
921.797	46.7686
925.138	48.1637
928.48	46.695
931.82	44.8673
935.16	42.1751
938.496	41.2028
941.833	41.2764
945.168	40.4924
948.5	38.4384
951.834	38.1577
955.163	36.7862
958.494	36.9185
961.821	35.6933
965.15	36.3321
968.474	35.5706
971.8	35.3362
975.123	36.2222
978.446	34.6872
981.766	33.6682
985.084	30.6354
988.402	29.4276
991.72	27.3079
995.035	26.4519
998.349	23.8027
1001.66	23.538
1004.97	23.2177
1008.28	21.2802
1011.59	19.418
1014.9	19.0048
1018.21	18.869
1021.51	20.5792
1024.81	21.0465
1028.12	20.1971
1031.42	21.1535
1034.72	20.8952
1038.02	22.1936
1041.31	22.4123
1044.61	21.8636
1047.91	21.2456
1051.2	20.9643
1054.49	21.8048
1057.78	19.7044
1061.07	17.6164
1064.36	16.9415
1067.65	15.8421
1070.93	16.6632
1074.22	15.4834
1077.5	14.2687
1080.78	14.1068
1084.06	14.0965
1087.34	14.4168
1090.62	14.9575
1093.9	14.3789
1097.17	14.5919
1100.45	14.3871
1103.72	13.6995
1106.99	13.0536
1110.27	12.729
1113.53	12.3285
1116.8	11.2364
1120.07	10.0279
1123.33	7.01273
1126.6	4.96706
1129.86	3.92312
1133.12	3.15885
1136.38	1.45723
1139.64	1.52094
1142.9	2.68108
1146.16	3.45911
1149.41	2.8264
1152.67	2.95181
1155.92	3.10844
1159.17	3.79955
1162.42	3.52279
1165.67	3.43239
1168.92	4.3262
1172.16	3.91697
1175.41	4.34111
1178.65	5.26971
1181.9	4.82712
1185.14	4.52208
1188.38	5.5783
1191.62	5.10856
1194.86	5.39161
1198.09	5.30117
1201.33	5.33988
1204.56	7.14274
1207.8	8.5297
1211.03	8.8957
1214.26	9.3999
1217.49	11.6865
1220.71	13.5333
1223.94	15.5667
1227.16	16.4552
1230.39	18.5692
1233.61	20.0245
1236.83	19.3904
1240.05	19.1589
1243.27	18.3853
1246.49	18.3245
1249.71	16.7263
1252.92	16.7058
1256.14	17.0928
1259.35	16.4733
1262.56	15.7576
1265.77	15.3441
1268.98	16.1709
1272.19	15.9054
1275.4	15.9572
1278.6	16.0346
1281.81	16.1521
1285.01	14.968
1288.21	14.3834
1291.41	14.7233
1294.61	14.4673
1297.81	15.2722
1301.01	16.3058
1304.2	17.5738
1307.4	19.0096
1310.59	19.7291
1313.78	19.197
1316.97	18.9514
1320.16	19.6997
1323.35	18.8836
1326.54	19.81
1329.72	19.5699
1332.91	21.2402
1336.09	22.3426
1339.27	22.5896
1342.45	22.2973
1345.64	22.9218
1348.81	22.7547
1351.99	22.5008
1355.17	21.8827
1358.34	19.0925
1361.51	17.8807
1364.69	16.2569
1367.86	15.803
1371.03	15.13
1374.2	14.7141
1377.37	15.7917
1380.53	15.681
1383.7	15.3772
1386.86	14.8058
1390.02	13.311
1393.19	13.6642
1396.35	11.8305
1399.51	12.8351
1402.66	13.3226
1405.82	14.2817
1408.97	13.9193
1412.13	14.2796
1415.28	15.5643
1418.43	14.9554
1421.59	15.027
1424.73	17.2811
1427.88	19.4006
1431.03	20.4552
1434.18	20.8036
1437.32	21.8846
1440.46	23.8943
1443.61	26.653
1446.75	28.0218
1449.89	29.2941
1453.03	29.2457
1456.16	29.8199
1459.3	29.8138
1462.44	30.8803
1465.57	31.0373
1468.7	31.4175
1471.83	33.1643
1474.96	33.4903
1478.09	33.9839
1481.22	31.5313
1484.35	29.4389
1487.47	28.0691
1490.6	27.0862
1493.72	24.5112
1496.84	22.299
1499.96	22.4344
1503.08	22.0977
1506.2	20.8361
1509.32	19.6569
1512.44	18.9095
1515.55	17.6009
1518.66	15.3196
1521.78	14.2368
1524.89	12.1096
1528	11.4324
1531.11	11.4045
1534.21	11.2599
1537.32	12.1155
1540.43	12.7932
1543.53	14.0267
1546.63	14.0929
1549.74	14.8826
1552.84	13.9017
1555.94	13.4095
1559.03	13.8222
1562.13	13.9509
1565.23	13.9627
1568.32	13.9004
1571.42	15.1997
1574.51	16.5565
1577.6	17.3199
1580.69	18.681
1583.78	19.8695
1586.87	21.302
1589.95	22.1843
1593.04	23.9639
1596.12	24.4498
1599.21	24.705
1602.29	25.0013
1605.37	25.1199
1608.45	26.2688
1611.53	26.3894
1614.6	27.5643
1617.68	27.7964
1620.75	28.5276
1623.83	28.7342
1626.9	28.1844
1629.97	28.7712
1633.04	30.0742
1636.11	30.6076
1639.18	30.1172
1642.25	31.1972
1645.31	30.801
1648.38	31.4491
1651.44	31.1644
1654.5	32.044
1657.56	31.316
1660.62	30.8052
1663.68	30.1628
1666.74	29.178
1669.8	27.0127
1672.85	23.5439
1675.91	21.7643
1678.96	19.6418
1682.01	18.3553
1685.06	15.7807
1688.11	13.0303
1691.16	11.0665
1694.21	10.2923
1697.25	8.42513
1700.3	6.59179
1703.34	6.84761
1706.39	6.71561
1709.43	7.22398
1712.47	6.89207
1715.51	6.12055
1718.54	5.9547
1721.58	5.17818
1724.62	5.65042
1727.65	4.96528
1730.68	5.78582
1733.72	5.38568
1736.75	5.90458
1739.78	5.36155
1742.81	4.60338
1745.84	3.58934
1748.86	3.85148
1751.89	3.66314
1754.91	1.83098
1757.93	0.9757
1760.96	-0.281635
1763.98	0.0296831
1767	0.356285
1770.02	0.633693
1773.03	-0.0347688
1776.05	1.10607
1779.07	1.18238
1782.08	1.1699
1785.09	1.39981
1788.11	0.447652
1791.12	0.808564
1794.13	1.02881
1797.13	1.69777
1800.14	2.50473
1803.15	2.88058
1806.15	3.01093
1809.16	3.08141
1812.16	3.14159
1815.16	3.18781
1818.16	3.39243
1821.16	3.26084
1824.16	3.90645
1827.16	3.5842
1830.16	3.44991
1833.15	3.53161
1836.14	3.75062
1839.14	3.95683
1842.13	3.91654
1845.12	4.40498
1848.11	4.54176
1851.1	4.46833
1854.08	3.34106
1857.07	3.49602
1860.05	3.01572
1863.04	2.20201
1866.02	2.27669
1869	3.03142
1871.98	3.40611
1874.96	3.53873
1877.94	3.55077
1880.92	3.19717
1882.51	2.52161
1885.5	2.68334
1888.48	3.24636
1891.47	3.58589
1894.46	4.5788
1897.44	4.51041
1900.42	4.23639
1903.41	5.41672
1906.39	6.17494
1909.37	6.41413
1912.35	6.65066
1915.32	6.00817
1918.3	6.40812
1921.27	6.8239
1924.25	6.64243
1927.22	6.30154
1930.19	6.04079
1933.17	4.69738
1936.14	4.88355
1939.11	5.36523
1942.07	5.08829
1945.04	4.02902
1948.01	2.75805
1950.97	2.36527
1953.93	1.7552
1956.9	1.97481
1959.86	1.53427
1962.82	1.51347
1965.78	1.28203
1968.74	0.696538
1971.69	0.4228
1974.65	1.13786
1977.6	0.832968
1980.56	0.37774
1983.51	0.599122
1986.46	1.40928
1989.41	2.5888
1992.36	4.08999
1995.31	4.26779
1998.26	4.2356
2001.2	4.16535
2004.15	4.64507
2007.09	5.05526
2010.04	6.81566
2012.98	7.03282
2015.92	7.51463
2018.86	8.13229
2021.8	9.74994
2024.73	10.0645
2027.67	9.8484
2030.61	9.78601
2033.54	9.7588
2036.47	9.18808
2039.4	8.71271
2042.33	8.53383
2045.27	8.42142
2048.19	8.01409
2051.12	7.9568
2054.05	8.77088
2056.97	9.44374
2059.9	9.85485
2062.82	9.4021
2065.74	9.24736
2068.67	7.82431
2071.59	8.11733
2074.51	9.08094
2077.42	8.93724
2080.34	8.93718
2083.26	8.79995
2086.17	8.90643
2089.09	7.86937
2092	7.33609
2094.91	7.92357
2097.82	7.69079
2100.73	7.55601
2103.64	8.2199
2106.55	9.1144
2109.45	8.61969
2112.36	9.77298
2115.26	10.7203
2118.17	11.6619
2121.07	12.4657
2123.97	13.9055
2126.87	15.6656
2129.77	17.2652
2132.67	18.8834
2135.56	20.0734
2138.46	21.3208
2141.35	22.6395
2144.25	24.2731
2147.14	24.8509
2150.03	25.0158
2152.92	25.5573
2155.81	26.3698
2158.7	26.4742
2161.59	26.863
2164.47	28.7731
2167.36	30.6669
2170.24	30.9367
2173.13	31.3026
2176.01	31.2271
2178.89	30.8376
2181.77	30.4587
2184.65	31.1466
2187.53	30.5324
2190.4	29.2434
2193.28	28.5
2196.16	26.9485
2199.03	26.2957
2201.9	25.3601
2204.77	24.5066
2207.64	23.0064
2210.51	21.6749
2213.38	20.5695
2216.25	18.5762
2219.12	17.0823
2221.98	16.1791
2224.85	15.3264
2227.71	14.2462
2230.57	14.1531
2233.43	15.2572
2236.29	14.9751
2239.15	14.1307
2242.01	14.0245
2244.87	13.7254
2247.72	13.7117
2250.58	13.2936
2253.43	12.9864
2256.29	12.657
2259.14	12.4545
2261.99	11.7366
2264.84	11.0631
2267.69	10.4245
2270.53	10.1517
2273.38	10.1959
2276.23	10.1458
2279.07	9.93419
2281.91	9.83919
2284.76	9.90976
2287.6	9.05303
2290.44	7.69421
2293.28	6.81406
2296.12	6.46759
2298.96	7.47564
2301.79	7.34779
2304.63	7.62026
2307.46	7.8869
2310.3	8.38778
2313.13	7.60348
2315.96	7.57883
2318.79	7.63504
2321.62	7.27793
2324.45	7.04614
2327.27	6.0914
2330.1	4.9193
2332.92	4.45099
2335.75	4.22278
2338.57	5.03812
2341.39	5.28605
2344.21	4.77694
2347.04	4.27126
2349.85	3.48499
2352.67	3.11643
2355.49	2.52388
2358.3	1.28072
2361.12	0.454518
2363.93	1.49994
2366.75	2.6983
2369.56	2.29518
2372.37	2.33134
2375.18	2.77432
2377.99	3.15611
2380.8	2.74316
2383.6	2.82207
2386.41	3.14448
2389.21	2.90155
2392.02	2.43767
2394.82	2.02807
2397.62	2.44669
2400.42	3.08791
2403.22	3.81116
2406.02	4.27558
2408.82	3.75526
2411.62	2.74001
2414.41	2.95737
2417.21	3.0252
2420	3.53758
2422.79	2.72637
2425.59	2.27993
2428.38	2.4325
2431.17	2.43609
2433.95	1.87782
2436.74	0.855539
2439.53	0.272939
2442.31	0.699138
2445.1	1.50497
2447.88	1.55784
2450.67	1.15804
2453.45	1.64221
2456.23	2.03694
2459.01	2.53693
2461.79	3.49402
2464.57	3.97747
2467.34	4.20802
2470.12	4.35426
2472.89	4.89506
2475.67	5.25225
2478.44	5.72442
2481.21	5.73488
2483.98	5.57225
2486.75	5.17157
2489.52	4.27804
2492.29	3.94655
2495.05	3.40266
2497.82	2.46285
2500.58	1.58305
2503.35	0.45409
2506.11	0.355764
2508.87	0.839675
2511.63	0.977584
2514.39	0.719298
2517.15	0.806468
2519.91	0.389345
2522.67	1.04697
2525.42	1.87195
2528.18	2.43795
2530.93	2.8138
2533.69	3.06
2536.44	4.12307
2539.19	5.0634
2541.94	5.5626
2544.69	6.21428
2547.44	6.55842
2550.18	6.6549
2552.93	6.60332
2555.67	6.62091
2558.42	6.7169
2561.16	5.28715
2563.9	5.49211
2566.64	5.43876
2569.38	4.52435
2572.12	4.42177
2574.86	4.23924
2577.6	3.55851
2580.33	2.42468
2583.07	2.33087
2585.8	2.26761
2588.54	3.60656
2591.27	4.24728
2594	3.59971
2596.73	4.17112
2599.46	4.0541
2602.19	4.09638
2604.92	4.28135
2607.64	4.83689
2610.37	5.23042
2613.09	5.67159
2615.82	5.44845
2618.54	5.06544
2621.26	4.42788
2623.98	4.64504
2626.7	4.79203
2629.42	4.98438
2632.14	5.26474
2634.86	4.2871
2637.57	3.19078
2640.29	3.2423
2643	3.65025
2645.71	4.51261
2648.43	5.56493
2651.14	7.17933
2653.85	8.40996
2656.56	8.66281
2659.26	8.43115
2661.97	8.37625
2664.68	7.58837
2667.38	7.93788
2670.09	7.67528
2672.79	7.58606
2675.49	7.93882
2678.19	7.31347
2680.89	6.87364
2683.59	6.13973
2686.29	5.15807
2688.99	4.89121
2691.69	5.22411
2694.38	5.27245
2697.08	4.57974
2699.77	3.83753
2702.46	3.1007
2705.15	4.13228
2707.85	4.9755
2710.54	6.36578
2713.22	6.99078
2715.91	7.26946
2718.6	7.15304
2721.29	7.20792
2723.97	7.45175
2726.66	6.7499
2729.34	5.96792
2732.02	6.09719
2734.7	6.73279
2737.38	6.1368
2740.06	6.55966
2742.74	5.99556
2745.42	4.97586
2748.09	4.4282
2750.77	3.63026
2753.45	4.29883
2756.12	3.2332
2758.79	2.55699
2761.46	2.23046
2764.14	1.3385
2766.8	1.69569
2769.47	1.69798
2772.14	2.25022
2774.81	1.58787
2777.48	1.39246
2780.14	0.930454
2782.8	1.03479
2785.47	0.73101
2788.13	0.661011
2790.79	-0.0274907
2793.45	-0.143601
2796.11	-0.579669
2798.77	0.512467
2801.43	0.568743
2804.09	0.624161
2806.74	0.875696
2809.4	0.936033
2812.05	1.03575
2814.71	1.78004
2817.36	2.55498
2820.01	3.20096
2822.66	3.70261
2825.31	5.60971
2827.96	6.54864
2830.6	8.22521
2833.25	9.67143
2835.9	11.2051
2838.54	13.0482
2841.18	15.0453
2843.83	17.5616
2846.47	19.0979
2849.11	21.6278
2851.75	24.1605
2854.39	26.3198
2857.03	28.8217
2859.66	31.6773
2862.3	34.5934
2864.94	37.0566
2867.57	38.6669
2870.2	40.0976
2872.84	42.2765
2875.47	43.1803
2878.1	44.0089
2880.73	45.8508
2883.36	46.675
2885.99	47.4942
2888.61	48.4038
2891.24	49.6079
2893.86	50.2784
2896.49	52.2049
2899.11	52.7319
2901.73	54.7416
2904.36	57.5436
2906.98	60.2177
2909.6	64.4178
2912.21	68.945
2914.83	72.7233
2917.45	76.1772
2920.07	79.8628
2922.68	82.4903
2925.29	85.322
2927.91	87.3623
2930.52	88.9787
2933.13	89.1577
2935.74	89.0371
2938.35	88.4637
2940.96	86.6629
2943.57	85.8774
2946.18	83.3491
2948.78	80.8677
2951.39	78.6777
2953.99	75.2084
2956.59	71.2192
2959.2	68.4978
2961.8	63.5226
2964.4	60.9853
2967	58.3267
2969.6	54.8534
2972.19	53.1213
2974.79	49.2261
2977.39	46.3921
2979.98	42.7196
2982.58	39.555
2985.17	36.2062
2987.76	32.6682
2990.35	30.2087
2992.94	27.3401
2995.53	23.8376
2998.12	21.3423
3000.71	19.1787
3003.3	17.1367
3005.88	15.6019
3008.47	13.6512
3011.05	11.1093
3013.64	9.82019
3016.22	8.73376
3018.8	6.1407
3021.38	5.68967
3023.96	4.21334
3026.54	3.48525
3029.12	2.87979
3031.69	1.91031
3034.27	1.79888
3036.84	1.18728
3039.42	0.817921
3041.99	1.01007
3044.57	1.88855
3047.14	1.89839
3049.71	1.35394
3052.28	1.70922
3054.85	1.64652
3057.41	1.82249
3059.98	2.1719
3062.55	2.79756
3065.11	2.76784
3067.68	2.49817
3070.24	2.46698
3072.8	2.65013
3075.36	2.99904
3077.93	3.51612
3080.49	4.17866
3083.04	4.181
3085.6	4.73669
3088.16	4.04405
3090.72	3.79193
3093.27	4.13047
3095.83	4.35656
3098.38	4.62292
3100.93	5.20681
3103.49	5.41777
3106.04	5.53756
3108.59	5.68692
3111.14	5.32257
3113.69	5.66267
3116.23	5.25916
3118.78	5.16249
3121.33	5.03584
3123.87	4.84487
3126.41	4.40966
3128.96	4.59958
3131.5	5.01928
3134.04	4.87587
3136.58	5.62785
3139.12	5.61658
3141.66	5.01793
3144.2	4.0098
3146.74	3.20277
3149.27	3.49744