File: data/Raman/poly_smoothed/Mb_30_27_05_1x_45s_532 nm_x100_100%_600 gr_mm_01.txt
#Acq. time (s)=	45
#Accumulations=	2
#Range (cm-¹)=	200...3150
#Windows=	2
#Auto scanning=	Off
#Autofocus=	Off
#Macrospot=	Off
#AutoExposure=	Off
#Spike filter=	Multiple accum.
#Delay time (s)=	0
#Binning=	1
#Readout mode=	Signal
#DeNoise=	Off
#ICS correction=	On
#Dark correction=	Off
#Inst. Process=	Off
#Detector Gain=	Best Dynamic Range
#Detector ADC=	20 kHz
#Detector temperature (°C)=	-69.85
#Instrument=	LabRAM HR Evol
#Detector=	Synapse
#Objective=	x100
#Grating=	600 gr/mm
#ND Filter=	100%
#Laser (nm)=	532
#Hole=	100.021
#Range=	Auto
#Laser Pol.=	No
#Raman. Pol.=	No
#Laser Pol. (°)=	-0.0007625
#Raman Pol. (°)=	89.9995
#Collection=	Microscope
#StageXY=	Marzhauser
#StageZ=	Marzhauser
#X (µm)=	28068.1
#Y (µm)=	-550.7
#Z (µm)=	1083.45
#Full time(mm:ss)=	3:19
#Project=
#Sample=
#Site=
#Title=	Mb_30_27_05_2x_45s_532 nm_x100_100%_600 gr_mm
#Remark=
#Date=	12.07.2022 15:48
#Acquired=	12.07.2022 15:48:26
#Base:Fit=	10.08.2022 10:39:47
#Base:Sub=	10.08.2022 10:39:55
#Base:Fit=	10.08.2022 10:40:03
#Base:Sub=	10.08.2022 10:40:17
#Filter:Polynom=	16.08.2022 10:16:15
#AxisType[0]=Intens
#AxisUnit[0]=Cnt
#AxisType[1]=Spectr
#AxisUnit[1]=1/cm
200.388	3.83705
204.019	12.5519
207.646	17.2676
211.274	21.1799
214.899	22.7705
218.524	23.5279
222.146	22.4928
225.766	21.9986
229.388	21.5528
233.005	21.8138
236.621	21.9523
240.236	21.613
243.852	20.6984
247.464	19.9759
251.074	17.3265
254.683	18.3904
258.291	19.7926
261.897	20.7337
265.504	20.8341
269.108	20.8987
272.71	21.4511
276.311	21.1883
279.91	20.4557
283.508	21.1911
287.105	19.8203
290.698	20.0534
294.291	20.074
297.884	18.5511
301.475	17.8629
305.064	16.3396
308.652	14.7898
312.237	14.5814
315.822	13.6703
319.406	14.5529
322.987	14.1294
326.568	13.765
330.148	12.3539
333.724	12.5331
337.301	13.6815
340.875	13.8312
344.449	14.2467
348.02	13.6561
351.592	13.3442
355.16	12.4933
358.728	11.8179
362.294	10.1334
365.858	8.71251
369.422	9.28472
372.983	8.04651
376.543	8.32203
380.102	8.73043
383.661	8.02337
387.216	7.66609
390.771	8.61002
394.324	7.34255
397.875	6.62625
401.425	6.91519
404.974	7.20757
408.524	5.83102
412.07	5.07633
415.614	6.03226
419.156	5.64483
422.698	7.1222
426.238	7.42747
429.777	5.82404
433.315	5.63409
436.852	4.34755
440.387	3.29026
443.919	1.76188
447.451	1.97438
450.982	2.74721
454.512	3.54459
458.038	5.07299
461.565	5.37807
465.091	6.29921
468.613	6.89388
472.136	7.92258
475.655	9.4276
479.176	11.1149
482.692	11.5282
486.21	12.1421
489.724	12.4362
493.237	15.2673
496.75	17.2164
500.26	18.7672
503.771	18.7581
507.279	19.6717
510.785	19.671
514.289	18.3088
517.793	16.9757
521.297	16.1078
524.797	15.6637
528.297	15.5911
531.795	16.0304
535.291	14.9801
538.787	13.4435
542.281	12.7385
545.773	11.6307
549.264	11.6379
552.754	11.6316
556.243	10.5756
559.73	9.65187
563.216	9.9355
566.701	9.79661
570.182	6.81599
573.664	7.03417
577.145	6.30073
580.624	6.59575
584.1	5.55303
587.577	4.96853
591.052	6.06708
594.524	6.14941
597.997	6.03515
601.466	6.2559
604.936	7.28954
608.403	7.49371
611.87	9.14583
615.334	10.1873
618.799	8.93349
622.26	9.11974
625.72	9.72091
629.181	11.0109
632.638	12.1671
636.095	12.9983
639.551	13.2754
643.005	12.4562
646.457	12.9773
649.908	15.3703
653.357	15.1242
656.806	15.4667
660.253	16.1651
663.7	16.5239
667.145	16.9018
670.588	18.1725
674.027	19.849
677.468	20.8389
680.907	20.3233
684.345	22.8481
687.781	23.8484
691.216	24.1012
694.65	26.2026
698.081	27.9571
701.512	29.8455
704.942	31.0917
708.371	33.1975
711.796	34.1592
715.222	36.0146
718.645	36.2195
722.068	35.9426
725.49	37.9901
728.909	39.9548
732.329	41.0761
735.745	42.4452
739.16	44.1893
742.576	46.4434
745.988	48.4703
749.401	50.6628
752.811	54.9843
756.22	58.677
759.627	61.5254
763.035	63.3773
766.44	67.1147
769.843	69.9406
773.245	71.7635
776.646	73.9342
780.046	75.9039
783.444	77.5929
786.841	78.66
790.237	80.2444
793.631	80.6288
797.024	81.8162
800.416	80.7452
803.807	80.2731
807.196	81.4138
810.584	81.1803
813.971	80.5288
817.354	79.7813
820.739	81.4201
824.122	82.0918
827.503	81.8084
830.882	81.9765
834.261	81.7675
837.637	81.3507
841.013	80.3301
844.389	78.0936
847.761	75.5863
851.131	74.2559
854.503	72.5636
857.871	69.7356
861.24	68.8458
864.606	66.7169
867.97	64.6653
871.336	63.7236
874.698	63.078
878.058	61.9945
881.418	60.2905
884.778	59.6439
888.135	58.7135
891.49	57.0644
894.845	56.548
898.198	56.2996
901.55	55.6178
904.901	56.2869
908.25	55.8387
911.598	55.218
914.945	55.6007
918.291	54.6836
921.635	53.2836
924.978	51.796
928.318	49.9315
931.659	47.6815
934.998	46.2948
938.336	44.3045
941.671	42.7843
945.007	40.6969
948.339	40.2659
951.672	39.1968
955.004	40.0465
958.333	40.1193
961.662	38.8738
964.989	37.5961
968.315	37.5098
971.639	36.2255
974.962	36.253
978.285	35.9886
981.605	34.5584
984.924	35.725
988.243	33.1907
991.56	29.9925
994.875	29.7148
998.188	30.8642
1001.5	31.3975
1004.81	31.7734
1008.12	34.7968
1011.43	39.1283
1014.74	44.2489
1018.05	48.6671
1021.35	53.0105
1024.65	57.2204
1027.96	60.7201
1031.26	63.2955
1034.56	64.3879
1037.86	65.3186
1041.16	64.317
1044.45	63.5667
1047.75	60.0116
1051.04	56.1076
1054.33	50.7765
1057.62	46.9778
1060.91	41.1097
1064.2	35.2908
1067.49	29.8656
1070.77	20.7003
1074.06	18.1315
1077.34	16.3841
1080.62	15.3289
1083.91	14.4389
1087.18	15.1494
1090.46	17.3381
1093.74	19.4479
1097.02	19.8049
1100.29	20.5764
1103.56	21.5641
1106.84	20.9396
1110.11	22.0835
1113.38	22.5199
1116.64	22.4989
1119.91	21.9526
1123.18	21.4259
1126.44	19.9155
1129.7	17.5737
1132.97	16.5043
1136.23	15.7018
1139.49	14.046
1142.74	12.3178
1146	10.7133
1149.26	7.86488
1152.51	6.22206
1155.76	4.41693
1159.01	2.55955
1162.27	1.8734
1165.51	1.73804
1168.76	2.36946
1172.01	1.70601
1175.25	-0.297632
1178.5	0.289811
1181.74	-0.196845
1184.98	0.267747
1188.22	2.14041
1191.46	3.25649
1194.7	3.77077
1197.94	4.96347
1201.17	6.68792
1204.41	8.96882
1207.64	10.5355
1210.87	12.5209
1214.1	16.3893
1217.33	20.4286
1220.56	24.3747
1223.79	26.5143
1227.01	28.8058
1230.23	31.6522
1233.46	34.691
1236.68	36.3561
1239.9	39.4963
1243.12	41.9157
1246.34	44.7981
1249.55	45.1299
1252.77	47.5199
1255.98	46.9885
1259.2	48.3511
1262.41	49.7612
1265.62	50.5648
1268.83	51.1303
1272.03	52.1542
1275.24	53.3881
1278.45	53.8601
1281.65	55.4031
1284.85	57.3653
1288.06	59.399
1291.26	61.1259
1294.46	62.7863
1297.66	63.9901
1300.85	62.5018
1304.05	61.828
1307.24	61.7456
1310.43	62.7001
1313.63	61.9001
1316.82	60.5826
1320.01	59.4224
1323.2	59.548
1326.38	57.9602
1329.57	55.3862
1332.76	51.7402
1335.94	49.0896
1339.12	46.5166
1342.3	43.9354
1345.48	42.155
1348.66	40.1268
1351.84	37.7947
1355.01	37.2395
1358.19	35.9969
1361.36	35.0241
1364.53	33.1668
1367.71	30.6372
1370.88	29.6172
1374.04	27.5977
1377.21	25.1965
1380.38	22.745
1383.54	22.0899
1386.71	23.1491
1389.87	21.8096
1393.03	21.2232
1396.19	19.9989
1399.35	19.3754
1402.51	19.011
1405.67	18.3072
1408.82	19.3765
1411.98	21.0856
1415.13	23.6494
1418.28	26.3113
1421.43	28.9283
1424.58	33.4335
1427.73	37.4873
1430.88	42.6001
1434.02	46.0512
1437.17	49.5049
1440.31	53.9882
1443.45	56.5873
1446.6	57.2403
1449.74	58.1724
1452.87	58.6823
1456.01	58.7943
1459.15	59.4964
1462.28	60.5371
1465.42	60.5607
1468.55	59.0836
1471.68	57.0401
1474.81	54.3344
1477.94	51.4725
1481.07	48.6057
1484.2	47.9185
1487.32	45.3991
1490.45	41.8621
1493.57	37.5792
1496.69	35.6244
1499.81	32.1409
1502.93	30.4232
1506.05	28.2274
1509.17	26.6918
1512.28	24.1524
1515.4	22.1019
1518.51	17.9053
1521.63	14.7963
1524.74	13.0674
1527.85	12.7276
1530.96	12.0613
1534.06	13.9504
1537.17	15.9508
1540.28	17.8061
1543.38	19.038
1546.48	20.7565
1549.59	21.7496
1552.69	23.5003
1555.79	25.1797
1558.88	25.4233
1561.98	26.4995
1565.08	26.8357
1568.17	27.7493
1571.27	29.2701
1574.36	30.8582
1577.45	32.3121
1580.54	33.044
1583.63	33.6779
1586.72	34.9916
1589.8	34.7986
1592.89	36.2404
1595.97	35.9113
1599.06	36.6682
1602.14	36.7486
1605.22	37.0262
1608.3	37.8349
1611.38	39.9026
1614.46	41.9444
1617.53	44.0732
1620.61	46.2449
1623.68	47.3422
1626.75	49.5296
1629.82	51.2438
1632.9	54.5521
1635.96	58.9052
1639.03	63.6529
1642.1	67.5661
1645.16	70.7605
1648.23	72.2414
1651.29	74.6138
1654.36	76.8942
1657.42	77.0322
1660.48	76.174
1663.53	75.703
1666.59	73.5724
1669.65	69.9924
1672.7	66.113
1675.76	61.6356
1678.81	56.1897
1681.86	51.4725
1684.91	46.8793
1687.96	41.6751
1691.01	36.3283
1694.06	30.0805
1697.11	25.3324
1700.15	20.564
1703.2	18.0647
1706.24	16.8082
1709.28	15.2341
1712.32	12.9613
1715.36	10.7002
1718.4	9.87099
1721.43	8.76469
1724.47	7.6375
1727.5	7.72599
1730.54	6.90041
1733.57	5.43871
1736.6	4.92172
1739.63	4.5886
1742.66	5.23637
1745.69	3.8747
1748.72	4.09532
1751.74	3.16052
1754.77	3.53569
1757.79	3.69516
1760.81	2.39338
1763.83	1.59844
1766.85	0.815439
1769.87	0.164007
1772.89	0.248076
1775.91	-0.281095
1778.92	-0.347894
1781.94	-0.68381
1784.95	0.104945
1787.96	-0.0640759
1790.97	0.0563192
1793.98	-0.0566723
1796.99	0.210374
1800	0.410735
1803	0.827767
1806.01	0.701742
1809.01	1.0007
1812.02	1.39723
1815.02	2.00704
1818.02	2.75425
1821.02	3.95193
1824.02	4.84099
1827.01	5.6821
1830.01	5.75135
1833	6.66068
1836	7.2152
1838.99	6.78802
1841.98	6.29971
1844.97	6.3313
1847.96	6.10486
1850.95	5.88591
1853.94	6.11826
1856.92	6.3659
1859.91	7.06407
1862.89	6.89531
1865.88	6.70014
1868.86	6.40919
1871.84	5.95341
1874.82	5.4372
1877.8	5.06851
1880.77	5.112
1882.51	5.66148
1885.5	4.99104
1888.48	5.71571
1891.47	6.25462
1894.46	5.27775
1897.44	5.05722
1900.42	4.84409
1903.41	4.45829
1906.39	4.2502
1909.37	2.89489
1912.35	1.70111
1915.32	1.78519
1918.3	1.43672
1921.28	1.83614
1924.25	1.71508
1927.22	1.84389
1930.2	1.7403
1933.17	1.849
1936.14	1.59731
1939.11	1.81369
1942.08	1.79876
1945.04	1.29893
1948.01	1.1657
1950.97	1.41944
1953.94	1.49284
1956.9	2.44128
1959.86	2.53886
1962.82	2.70892
1965.78	2.73211
1968.74	3.56661
1971.69	4.47122
1974.65	5.30505
1977.61	5.35042
1980.56	5.0594
1983.51	4.76568
1986.46	4.64162
1989.41	5.97104
1992.36	7.36774
1995.31	8.29359
1998.26	8.29877
2001.2	8.93272
2004.15	8.65985
2007.09	8.53414
2010.04	8.73059
2012.98	9.22152
2015.92	8.63573
2018.86	8.24327
2021.8	7.84699
2024.74	8.42492
2027.67	8.41731
2030.61	8.85321
2033.54	8.41736
2036.47	9.08806
2039.41	8.97577
2042.34	9.47174
2045.27	10.1719
2048.2	10.2686
2051.12	9.89238
2054.05	10.4092
2056.98	11.377
2059.9	13.0618
2062.82	13.7939
2065.75	15.7611
2068.67	16.0441
2071.59	16.6072
2074.51	17.9868
2077.43	18.6859
2080.34	19.6342
2083.26	20.1663
2086.17	21.2711
2089.09	21.7272
2092	21.7763
2094.91	23.644
2097.82	25.2378
2100.73	26.9686
2103.64	28.8591
2106.55	29.873
2109.46	31.7528
2112.36	32.6698
2115.27	34.8765
2118.17	36.9209
2121.07	39.0309
2123.97	42.3777
2126.87	45.3928
2129.77	48.2195
2132.67	51.4513
2135.57	55.3007
2138.46	59.1653
2141.36	62.6967
2144.25	67.5036
2147.14	71.9202
2150.03	74.0647
2152.92	77.5275
2155.81	80.2688
2158.7	83.4107
2161.59	85.9706
2164.48	88.2579
2167.36	90.4699
2170.25	91.4518
2173.13	91.9225
2176.01	91.7607
2178.89	91.3819
2181.77	89.5126
2184.65	87.6894
2187.53	85.4484
2190.41	82.9256
2193.28	80.0583
2196.16	77.1018
2199.03	73.1584
2201.9	69.0432
2204.78	66.7733
2207.65	63.3056
2210.51	60.4728
2213.38	56.5198
2216.25	53.4803
2219.12	49.5048
2221.98	45.9176
2224.85	42.7121
2227.71	38.9696
2230.57	36.0084
2233.43	33.1643
2236.29	29.9891
2239.15	27.4483
2242.01	25.9441
2244.87	24.7021
2247.73	24.0339
2250.58	22.7618
2253.43	21.2787
2256.29	20.8856
2259.14	19.5626
2261.99	18.8124
2264.84	18.3244
2267.69	17.8771
2270.54	17.3347
2273.38	16.8969
2276.23	15.5526
2279.07	14.1452
2281.92	13.3007
2284.76	12.3179
2287.6	11.0791
2290.44	10.1369
2293.28	7.97692
2296.12	6.92227
2298.96	7.46804
2301.79	8.05062
2304.63	8.6878
2307.46	9.23466
2310.3	10.38
2313.13	10.8947
2315.96	11.6189
2318.79	11.348
2321.62	11.7173
2324.45	11.3025
2327.27	10.8802
2330.1	10.2078
2332.93	9.47181
2335.75	8.9261
2338.57	7.94563
2341.4	6.35976
2344.22	4.12389
2347.04	3.31731
2349.86	2.926
2352.67	2.02763
2355.49	0.537155
2358.31	-0.878352
2361.12	-2.2691
2363.94	-1.59609
2366.75	-0.554165
2369.56	-0.48615
2372.37	-0.513189
2375.18	-0.945968
2377.99	-0.571375
2380.8	-0.0704674
2383.61	-0.28187
2386.41	0.0206023
2389.22	0.0742638
2392.02	-0.100984
2394.82	0.0361087
2397.63	0.919543
2400.43	1.37595
2403.23	2.88573
2406.02	4.72126
2408.82	5.21548
2411.62	6.1555
2414.41	6.05511
2417.21	7.19157
2420	7.73331
2422.79	7.79351
2425.59	7.99706
2428.38	7.693
2431.17	7.52091
2433.96	7.33581
2436.74	6.76397
2439.53	6.76267
2442.32	5.70957
2445.1	5.53538
2447.88	5.31855
2450.67	4.43097
2453.45	4.00798
2456.23	2.93823
2459.01	2.36587
2461.79	1.32561
2464.57	1.39988
2467.34	2.49202
2470.12	2.0439
2472.89	2.86904
2475.67	2.60874
2478.44	2.33016
2481.21	2.64722
2483.98	2.28611
2486.75	2.29038
2489.52	2.13875
2492.29	1.59133
2495.06	1.97684
2497.82	1.79395
2500.59	1.90037
2503.35	2.01654
2506.11	2.39149
2508.88	1.68906
2511.63	1.98438
2514.39	1.80385
2517.15	1.77583
2519.91	1.87744
2522.67	1.56442
2525.42	1.19875
2528.18	0.345144
2530.93	0.883025
2533.69	0.964489
2536.44	0.883781
2539.19	0.876674
2541.94	1.14461
2544.69	0.916695
2547.44	0.989203
2550.18	1.48103
2552.93	0.835524
2555.68	0.817785
2558.42	0.437624
2561.16	0.758033
2563.9	1.18747
2566.64	1.80704
2569.38	2.45912
2572.12	3.21844
2574.86	3.83732
2577.6	3.99115
2580.34	4.93233
2583.07	4.71006
2585.81	5.7566
2588.54	6.44972
2591.27	6.38688
2594	5.88369
2596.73	6.20038
2599.46	6.2245
2602.19	5.91962
2604.92	5.72399
2607.64	5.38105
2610.37	4.79551
2613.09	3.94742
2615.82	3.72169
2618.54	2.65503
2621.26	2.75436
2623.98	2.83331
2626.7	2.59134
2629.42	3.23733
2632.14	3.66438
2634.86	3.48805
2637.57	3.50688
2640.29	2.94914
2643	3.65313
2645.72	3.62635
2648.43	4.13045
2651.14	4.46607
2653.85	4.71955
2656.56	5.29534
2659.27	5.32674
2661.97	5.3099
2664.68	5.71634
2667.38	5.49035
2670.09	4.3895
2672.79	3.82744
2675.49	3.99255
2678.2	3.44656
2680.89	3.65753
2683.59	3.30088
2686.29	3.97782
2688.99	4.40568
2691.69	4.06931
2694.38	3.18171
2697.08	2.64844
2699.77	2.19211
2702.46	2.39208
2705.16	2.73911
2707.85	3.27193
2710.54	4.59647
2713.23	4.76475
2715.92	5.72426
2718.6	6.80357
2721.29	7.71732
2723.97	8.24472
2726.66	7.49036
2729.34	7.10252
2732.02	7.79977
2734.7	7.13966
2737.39	7.49081
2740.06	7.76103
2742.74	7.70162
2745.42	7.07202
2748.1	6.57874
2750.77	6.01076
2753.45	5.30421
2756.12	3.4963
2758.79	3.00173
2761.47	2.63373
2764.14	1.95417
2766.81	1.73853
2769.48	1.90119
2772.14	2.01961
2774.81	2.63609
2777.48	3.34067
2780.14	3.48741
2782.81	3.67611
2785.47	3.04637
2788.13	1.97183
2790.79	1.27632
2793.46	1.08131
2796.11	2.39994
2798.77	2.64242
2801.43	3.27921
2804.09	2.36546
2806.74	1.83273
2809.4	1.82933
2812.05	1.50132
2814.71	1.55982
2817.36	2.59035
2820.01	4.04297
2822.66	6.10327
2825.31	8.65196
2827.96	11.0215
2830.61	14.6553
2833.25	18.511
2835.9	22.8449
2838.54	27.9285
2841.18	32.4996
2843.83	39.2367
2846.47	45.6071
2849.11	52.5035
2851.75	59.6127
2854.39	68.2504
2857.03	76.4897
2859.67	83.9082
2862.3	91.2985
2864.94	97.4017
2867.57	103.03
2870.21	107.845
2872.84	112.324
2875.47	117.688
2878.1	122.147
2880.73	126.361
2883.36	130.888
2885.99	135.179
2888.61	140.573
2891.24	145.161
2893.87	150.29
2896.49	156.654
2899.11	163.561
2901.74	172.708
2904.36	183.071
2906.98	194.776
2909.6	207.91
2912.22	221.283
2914.83	233.628
2917.45	245.36
2920.07	256.649
2922.68	266.445
2925.3	273.755
2927.91	278.602
2930.52	281.861
2933.13	281.982
2935.74	280.083
2938.35	277.92
2940.96	272.985
2943.57	265.411
2946.18	257.073
2948.78	247.209
2951.39	237.611
2953.99	226.29
2956.6	214.353
2959.2	203.417
2961.8	191.9
2964.4	182.166
2967	171.876
2969.6	162.314
2972.2	152.166
2974.79	143.808
2977.39	134.616
2979.98	125.23
2982.58	116.273
2985.17	107.435
2987.76	97.9897
2990.36	88.1035
2992.95	79.078
2995.54	70.7223
2998.12	62.7985
3000.71	55.6884
3003.3	49.5039
3005.88	43.2415
3008.47	36.9265
3011.05	32.4138
3013.64	28.6835
3016.22	25.5599
3018.8	22.2121
3021.38	19.6869
3023.96	17.9582
3026.54	16.3019
3029.12	15.1156
3031.69	14.6075
3034.27	14.631
3036.85	14.8724
3039.42	15.7174
3041.99	16.4705
3044.57	17.6095
3047.14	18.347
3049.71	17.8446
3052.28	17.281
3054.85	17.0715
3057.42	16.92
3059.98	16.7837
3062.55	15.7381
3065.11	15.1096
3067.68	14.4707
3070.24	13.7998
3072.8	12.605
3075.37	11.7454
3077.93	9.74274
3080.49	7.89587
3083.05	6.46869
3085.61	5.48455
3088.16	4.12998
3090.72	3.56143
3093.27	3.51695
3095.83	3.57539
3098.38	3.67396
3100.94	4.12826
3103.49	4.38322
3106.04	4.78376
3108.59	5.51197
3111.14	5.53353
3113.69	5.94314
3116.23	7.08028
3118.78	7.70492
3121.33	8.33888
3123.87	9.30236
3126.42	10.406
3128.96	11.9512
3131.5	12.2078
3134.04	12.9102
3136.58	12.6957
3139.12	12.5297
3141.66	12.2334
3144.2	12.4395
3146.74	11.9011
3149.27	11.4751