File: data/Raman/poly_smoothed/Mb_30_27_44_1x_45s_532 nm_x100_100%_600 gr_mm_01.txt
#Acq. time (s)=	45
#Accumulations=	2
#Range (cm-¹)=	200...3150
#Windows=	2
#Auto scanning=	Off
#Autofocus=	Off
#Macrospot=	Off
#AutoExposure=	Off
#Spike filter=	Multiple accum.
#Delay time (s)=	0
#Binning=	1
#Readout mode=	Signal
#DeNoise=	Off
#ICS correction=	On
#Dark correction=	Off
#Inst. Process=	Off
#Detector Gain=	Best Dynamic Range
#Detector ADC=	20 kHz
#Detector temperature (°C)=	-69.85
#Instrument=	LabRAM HR Evol
#Detector=	Synapse
#Objective=	x100
#Grating=	600 gr/mm
#ND Filter=	100%
#Laser (nm)=	532
#Hole=	100.021
#Range=	Auto
#Laser Pol.=	No
#Raman. Pol.=	No
#Laser Pol. (°)=	-0.0007625
#Raman Pol. (°)=	89.9995
#Collection=	Microscope
#StageXY=	Marzhauser
#StageZ=	Marzhauser
#X (µm)=	-6379.6
#Y (µm)=	796.7
#Z (µm)=	-64.55
#Full time(mm:ss)=	3:18
#Project=
#Sample=
#Site=
#Title=	Mb_30_27_44_2x_45s_532 nm_x100_100%_600 gr_mm
#Remark=
#Date=	13.07.2022 12:05
#Acquired=	13.07.2022 12:05:29
#Base:Fit=	10.08.2022 10:40:03
#Base:Sub=	10.08.2022 10:40:17
#Filter:Polynom=	16.08.2022 10:16:15
#AxisType[0]=Intens
#AxisUnit[0]=Cnt
#AxisType[1]=Spectr
#AxisUnit[1]=1/cm
200.563	14.8992
204.194	12.8814
207.821	12.3155
211.449	10.9217
215.074	11.0242
218.699	10.3083
222.321	11.2733
225.941	11.5647
229.562	10.7183
233.18	10.782
236.796	11.3776
240.411	10.5923
244.026	12.2975
247.638	12.927
251.248	12.8048
254.857	13.1109
258.465	11.9953
262.071	12.3967
265.678	11.1726
269.282	8.31687
272.884	6.69564
276.484	6.82653
280.084	7.16145
283.682	5.97218
287.276	4.98353
290.871	5.56999
294.465	3.78952
298.057	3.41618
301.648	5.60226
305.237	5.52866
308.823	5.96279
312.41	6.95555
315.995	5.46225
319.579	6.20961
323.16	6.29294
326.741	7.66173
330.321	9.06202
333.897	8.47355
337.474	7.32638
341.048	6.60558
344.622	6.4735
348.192	7.23727
351.764	6.54585
355.332	5.4557
358.901	4.19527
362.466	3.50006
366.03	4.6741
369.594	5.06108
373.155	6.41856
376.715	7.10611
380.273	8.64535
383.832	9.4376
387.388	10.0109
390.942	11.679
394.495	12.6537
398.047	12.8773
401.597	12.1705
405.145	12.6584
408.693	12.2773
412.239	12.2011
415.783	12.8975
419.327	11.7268
422.869	10.6811
426.409	9.13875
429.948	7.73221
433.486	5.54046
437.022	4.93694
440.558	2.86155
444.089	3.00413
447.622	4.69623
451.153	7.14334
454.682	8.2806
458.208	10.6081
461.735	12.6823
465.259	14.6917
468.783	17.6135
472.306	19.0357
475.825	22.8575
479.346	26.1031
482.862	28.3042
486.38	30.0461
489.894	31.2927
493.407	32.2113
496.92	33.0627
500.43	33.2094
503.939	33.5125
507.448	32.5173
510.954	28.236
514.459	26.1838
517.962	25.3141
521.466	23.903
524.966	22.9224
528.466	22.6203
531.964	21.6954
535.46	20.7745
538.955	19.4033
542.449	19.317
545.942	17.3637
549.433	15.4412
552.923	13.009
556.412	12.0893
559.899	10.7736
563.385	10.3435
566.867	9.09839
570.35	8.01976
573.832	6.67403
577.313	5.92091
580.79	5.05886
584.268	5.28835
587.745	4.42748
591.218	5.64543
594.692	5.06512
598.164	4.06552
601.634	4.5881
605.104	5.40406
608.57	6.01728
612.037	6.59922
615.501	7.89648
618.966	8.90137
622.427	8.79102
625.887	9.59747
629.348	9.61373
632.806	10.1737
636.262	10.4525
639.716	11.0023
643.172	13.5195
646.624	13.0828
650.075	14.2964
653.524	15.2995
656.972	16.1559
660.419	16.5451
663.865	18.6054
667.309	19.5637
670.752	20.2812
674.194	21.5487
677.634	21.8316
681.073	21.3807
684.511	20.6049
687.947	21.0148
691.382	23.4446
694.816	24.9894
698.247	24.4091
701.678	26.0121
705.108	26.8657
708.534	28.1453
711.962	30.3556
715.388	31.5165
718.81	34.486
722.234	35.7576
725.654	37.6709
729.075	37.8639
732.492	40.2755
735.91	42.5002
739.325	43.8601
742.741	46.5115
746.153	50.0751
749.564	51.9748
752.976	55.7246
756.385	59.1926
759.792	59.6811
763.2	62.4506
766.604	66.0908
770.008	68.3568
773.41	69.609
776.811	71.1177
780.21	72.755
783.608	73.5995
787.005	74.8444
790.401	75.226
793.795	74.8112
797.188	75.0297
800.58	75.9738
803.971	75.9525
807.36	75.6924
810.748	76.3763
814.135	76.4852
817.518	75.5924
820.902	76.0331
824.285	75.0179
827.665	74.7904
831.045	73.7742
834.424	73.2084
837.8	72.273
841.177	69.1996
844.55	66.4421
847.924	65.2094
851.295	62.2277
854.666	59.8417
858.034	59.1012
861.403	58.8881
864.769	57.9235
868.133	56.9257
871.498	55.2627
874.86	54.3702
878.221	55.7027
881.58	55.9651
884.938	57.5925
888.297	57.5728
891.653	57.643
895.007	57.6457
898.36	58.5283
901.712	58.6509
905.063	60.5292
908.412	59.5048
911.76	60.4948
915.107	59.7341
918.452	59.273
921.797	55.3838
925.138	52.9581
928.48	50.9457
931.82	48.5569
935.16	49.4433
938.496	49.3849
941.833	47.3479
945.168	46.1254
948.5	43.604
951.834	41.6997
955.163	41.3405
958.494	40.4277
961.821	39.4295
965.15	38.4416
968.474	39.4963
971.8	40.3779
975.123	40.7954
978.446	42.2213
981.766	44.7842
985.084	45.1179
988.402	45.3429
991.72	44.0006
995.035	44.5276
998.349	43.1074
1001.66	40.7977
1004.97	38.3286
1008.28	38.6067
1011.59	41.5071
1014.9	44.8885
1018.21	47.7493
1021.51	51.3785
1024.81	54.1068
1028.12	56.4244
1031.42	59.7961
1034.72	62.3092
1038.02	62.0674
1041.31	61.6893
1044.61	63.9018
1047.91	64.5746
1051.2	63.9804
1054.49	63.4873
1057.78	60.9635
1061.07	59.3598
1064.36	55.1052
1067.65	50.2733
1070.93	45.4582
1074.22	40.6503
1077.5	34.7393
1080.78	31.1992
1084.06	27.3468
1087.34	26.8274
1090.62	28.0456
1093.9	29.3305
1097.17	30.0461
1100.45	30.8411
1103.72	32.0776
1106.99	30.6665
1110.27	31.7551
1113.53	31.7235
1116.8	30.5485
1120.07	30.4542
1123.33	30.3682
1126.6	30.0476
1129.86	29.292
1133.12	28.1409
1136.38	25.2816
1139.64	23.014
1142.9	21.0935
1146.16	17.6969
1149.41	14.6988
1152.67	12.3075
1155.92	9.39666
1159.17	8.21392
1162.42	6.33711
1165.67	4.63948
1168.92	3.68696
1172.16	3.44099
1175.41	2.46411
1178.65	4.20142
1181.9	4.15092
1185.14	5.52319
1188.38	6.83225
1191.62	8.48269
1194.86	9.60338
1198.09	12.0702
1201.33	14.8567
1204.56	18.4419
1207.8	20.7942
1211.03	24.2232
1214.26	26.0005
1217.49	29.0872
1220.71	34.2991
1223.94	39.0076
1227.16	43.801
1230.39	48.6477
1233.61	51.7365
1236.83	54.6889
1240.05	57.9513
1243.27	60.9259
1246.49	64.1366
1249.71	67.6608
1252.92	70.4051
1256.14	73.8711
1259.35	76.9588
1262.56	77.5885
1265.77	79.4545
1268.98	81.5382
1272.19	81.8759
1275.4	83.8999
1278.6	85.8387
1281.81	86.1103
1285.01	86.7576
1288.21	88.041
1291.41	88.9068
1294.61	90.9242
1297.81	93.3357
1301.01	96.4616
1304.2	96.7934
1307.4	98.5332
1310.59	99.3867
1313.78	100.779
1316.97	101.655
1320.16	102.676
1323.35	101.043
1326.54	101.869
1329.72	101.379
1332.91	99.2257
1336.09	98.6369
1339.27	94.961
1342.45	91.1356
1345.64	86.9853
1348.81	83.5903
1351.99	80.1883
1355.17	76.6424
1358.34	72.5698
1361.51	69.0737
1364.69	65.8503
1367.86	62.6028
1371.03	58.3856
1374.2	57.1053
1377.37	54.8972
1380.53	53.8577
1383.7	52.1362
1386.86	52.8155
1390.02	51.9628
1393.19	51.7227
1396.35	49.9162
1399.51	48.7873
1402.66	48.2856
1405.82	50.0482
1408.97	49.6005
1412.13	51.5958
1415.28	55.067
1418.43	57.3007
1421.59	59.934
1424.73	65.3836
1427.88	69.4312
1431.03	74.7456
1434.18	80.9954
1437.32	85.902
1440.46	89.5277
1443.61	91.6654
1446.75	92.6777
1449.89	94.5134
1453.03	93.3548
1456.16	92.4329
1459.3	90.7052
1462.44	88.8838
1465.57	85.4791
1468.7	82.0474
1471.83	76.9695
1474.96	72.3145
1478.09	67.2939
1481.22	62.3523
1484.35	57.23
1487.47	54.4748
1490.6	52.0862
1493.72	48.6758
1496.84	45.8737
1499.96	44.6778
1503.08	44.2281
1506.2	43.1306
1509.32	40.8436
1512.44	38.3372
1515.55	36.0903
1518.66	33.2829
1521.78	30.9298
1524.89	30.2607
1528	29.8463
1531.11	28.6425
1534.21	26.6433
1537.32	27.5088
1540.43	29.1464
1543.53	29.6748
1546.63	31.3922
1549.74	31.7783
1552.84	32.3651
1555.94	32.8235
1559.03	33.5107
1562.13	35.0183
1565.23	37.6894
1568.32	40.6786
1571.42	43.2895
1574.51	46.7981
1577.6	49.1995
1580.69	51.7732
1583.78	52.6892
1586.87	53.8682
1589.95	54.7815
1593.04	57.0142
1596.12	58.4151
1599.21	58.955
1602.29	60.1503
1605.37	59.2926
1608.45	58.3363
1611.53	58.7091
1614.6	59.8547
1617.68	61.6306
1620.75	62.6893
1623.83	65.9522
1626.9	68.2101
1629.97	71.0928
1633.04	74.8204
1636.11	77.9032
1639.18	82.8635
1642.25	87.188
1645.31	91.0002
1648.38	93.9936
1651.44	97.7085
1654.5	98.363
1657.56	98.5353
1660.62	98.3932
1663.68	97.0923
1666.74	94.8036
1669.8	91.8109
1672.85	86.189
1675.91	80.5475
1678.96	73.5574
1682.01	66.8838
1685.06	61.0276
1688.11	55.6639
1691.16	48.687
1694.21	44.4597
1697.25	39.5883
1700.3	35.3456
1703.34	31.6619
1706.39	28.2166
1709.43	24.7257
1712.47	22.2709
1715.51	20.6004
1718.54	18.9455
1721.58	18.4963
1724.62	17.2467
1727.65	16.5684
1730.68	14.4983
1733.72	14.199
1736.75	13.4308
1739.78	12.2549
1742.81	10.7304
1745.84	9.09559
1748.86	8.77968
1751.89	7.75926
1754.91	7.74045
1757.93	7.52476
1760.96	5.80089
1763.98	4.27301
1767	3.36723
1770.02	3.46326
1773.03	3.17031
1776.05	2.81969
1779.07	3.00401
1782.08	2.23369
1785.09	2.25483
1788.11	2.93681
1791.12	2.97112
1794.13	2.66726
1797.13	2.69237
1800.14	2.73434
1803.15	2.07757
1806.15	1.64765
1809.16	1.30727
1812.16	0.475169
1815.16	0.228358
1818.16	0.961517
1821.16	0.957903
1824.16	0.631217
1827.16	1.69169
1830.16	1.04314
1833.15	0.93616
1836.14	0.943391
1839.14	1.48089
1842.13	1.507
1845.12	1.70426
1848.11	1.51564
1851.1	1.54269
1854.08	1.61826
1857.07	2.06029
1860.05	2.17715
1863.04	2.28523
1866.02	1.66038
1869	2.65677
1871.98	3.14621
1874.96	3.20022
1877.94	3.25363
1880.92	3.19645
1882.51	3.86605
1885.5	4.2495
1888.48	4.01643
1891.47	4.18281
1894.46	3.97018
1897.44	3.5234
1900.42	4.12108
1903.41	3.79542
1906.39	4.00425
1909.37	3.55404
1912.35	3.06448
1915.32	2.87593
1918.3	2.88246
1921.27	3.06775
1924.25	1.93048
1927.22	1.12543
1930.19	1.21354
1933.17	0.866318
1936.14	0.585819
1939.11	1.51614
1942.07	1.85044
1945.04	0.749043
1948.01	1.21087
1950.97	1.40475
1953.93	0.782492
1956.9	1.50561
1959.86	0.78627
1962.82	1.28653
1965.78	1.5647
1968.74	2.75007
1971.69	2.84444
1974.65	4.50729
1977.6	5.1175
1980.56	5.3871
1983.51	5.62854
1986.46	6.28804
1989.41	6.77742
1992.36	6.83911
1995.31	6.35896
1998.26	5.63987
2001.2	5.7088
2004.15	5.25953
2007.09	5.55787
2010.04	4.77811
2012.98	4.27768
2015.92	2.68864
2018.86	2.59361
2021.8	2.30054
2024.73	1.64084
2027.67	1.80212
2030.61	2.14932
2033.54	3.0923
2036.47	3.40107
2039.4	4.81819
2042.33	5.42731
2045.27	4.81346
2048.19	5.65272
2051.12	5.75943
2054.05	6.63692
2056.97	7.73889
2059.9	8.7868
2062.82	9.46742
2065.74	10.0925
2068.67	10.6155
2071.59	11.2999
2074.51	12.9813
2077.42	14.7726
2080.34	15.8914
2083.26	16.2654
2086.17	17.8419
2089.09	20.1178
2092	21.5654
2094.91	23.1084
2097.82	25.2109
2100.73	27.4033
2103.64	29.5804
2106.55	30.7097
2109.45	32.5907
2112.36	35.5773
2115.26	37.0912
2118.17	39.8754
2121.07	43.4257
2123.97	47.2885
2126.87	51.7447
2129.77	55.2835
2132.67	58.4893
2135.56	61.7989
2138.46	66.1957
2141.35	70.2517
2144.25	74.5745
2147.14	77.8991
2150.03	81.3436
2152.92	85.5177
2155.81	88.2587
2158.7	92.0999
2161.59	94.0855
2164.47	95.5699
2167.36	97.8327
2170.24	98.7869
2173.13	98.4634
2176.01	98.2296
2178.89	97.6153
2181.77	96.6198
2184.65	95.2403
2187.53	93.0743
2190.4	90.791
2193.28	88.2153
2196.16	85.9157
2199.03	81.4739
2201.9	76.8386
2204.77	73.8123
2207.64	69.8639
2210.51	65.44
2213.38	61.0919
2216.25	56.3836
2219.12	52.2987
2221.98	49.307
2224.85	45.1363
2227.71	41.413
2230.57	37.1145
2233.43	33.4117
2236.29	31.5366
2239.15	28.7001
2242.01	26.3297
2244.87	23.1886
2247.72	21.6895
2250.58	20.2714
2253.43	19.646
2256.29	18.8143
2259.14	17.953
2261.99	17.9565
2264.84	17.3418
2267.69	17.3731
2270.53	17.1253
2273.38	16.905
2276.23	15.614
2279.07	14.9364
2281.91	13.5819
2284.76	12.5923
2287.6	10.7887
2290.44	9.49391
2293.28	7.63945
2296.12	6.37263
2298.96	5.77348
2301.79	5.53415
2304.63	5.62016
2307.46	5.24433
2310.3	4.05876
2313.13	4.65289
2315.96	4.92141
2318.79	5.29534
2321.62	5.46461
2324.45	6.07295
2327.27	6.68568
2330.1	6.43713
2332.92	6.54278
2335.75	6.53595
2338.57	6.25661
2341.39	5.29962
2344.21	4.72759
2347.04	4.00732
2349.85	2.36224
2352.67	1.12424
2355.49	0.581601
2358.3	0.331052
2361.12	0.695063
2363.93	2.35991
2366.75	3.03689
2369.56	3.38115
2372.37	3.20792
2375.18	3.49905
2377.99	4.28072
2380.8	4.75434
2383.6	4.46894
2386.41	5.48199
2389.21	6.42772
2392.02	7.34933
2394.82	7.68527
2397.62	8.13006
2400.42	8.17495
2403.22	8.31924
2406.02	8.36675
2408.82	7.68918
2411.62	8.03454
2414.41	6.75234
2417.21	6.08319
2420	5.3324
2422.79	5.78663
2425.59	6.55375
2428.38	7.05096
2431.17	5.81892
2433.95	5.3777
2436.74	4.63021
2439.53	3.44783
2442.31	2.62258
2445.1	1.99362
2447.88	2.02776
2450.67	2.21921
2453.45	2.55714
2456.23	3.15635
2459.01	2.65963
2461.79	2.50171
2464.57	2.68286
2467.34	2.0409
2470.12	1.38905
2472.89	1.38591
2475.67	1.39725
2478.44	1.20075
2481.21	0.638113
2483.98	0.875924
2486.75	0.579155
2489.52	0.298008
2492.29	1.38519
2495.05	1.11356
2497.82	1.40068
2500.58	1.56151
2503.35	1.21987
2506.11	2.20536
2508.87	1.87719
2511.63	2.13355
2514.39	3.17992
2517.15	3.7426
2519.91	4.19559
2522.67	3.09736
2525.42	3.42378
2528.18	4.07347
2530.93	4.81131
2533.69	4.52696
2536.44	4.99724
2539.19	5.88204
2541.94	6.05823
2544.69	5.2282
2547.44	6.17462
2550.18	6.65805
2552.93	6.99835
2555.67	7.26223
2558.42	7.37756
2561.16	8.52213
2563.9	8.6326
2566.64	8.31851
2569.38	7.88075
2572.12	8.72764
2574.86	9.2823
2577.6	8.71343
2580.33	9.01294
2583.07	9.2423
2585.8	9.52393
2588.54	9.75561
2591.27	9.94109
2594	9.90535
2596.73	10.2336
2599.46	9.50296
2602.19	9.58074
2604.92	9.34992
2607.64	9.24479
2610.37	9.42347
2613.09	9.50479
2615.82	10.0301
2618.54	9.04921
2621.26	8.01801
2623.98	8.21925
2626.7	8.3828
2629.42	7.84721
2632.14	8.24007
2634.86	8.28386
2637.57	8.69848
2640.29	9.23357
2643	10.2332
2645.71	9.07427
2648.43	9.37111
2651.14	8.82728
2653.85	7.98104
2656.56	7.71448
2659.26	7.63097
2661.97	7.39206
2664.68	7.49611
2667.38	7.97139
2670.09	7.60807
2672.79	7.07642
2675.49	8.23998
2678.19	8.17852
2680.89	7.98266
2683.59	7.86798
2686.29	7.14263
2688.99	7.5577
2691.69	8.3935
2694.38	8.18191
2697.08	8.15461
2699.77	8.56758
2702.46	9.16053
2705.15	9.60518
2707.85	9.85746
2710.54	9.09269
2713.22	8.92044
2715.91	9.40018
2718.6	10.0891
2721.29	10.6917
2723.97	11.1265
2726.66	12.4528
2729.34	11.9139
2732.02	11.7617
2734.7	11.6058
2737.38	11.637
2740.06	11.9363
2742.74	11.4685
2745.42	10.4761
2748.09	9.59184
2750.77	9.39291
2753.45	8.15794
2756.12	7.54403
2758.79	6.3925
2761.46	4.92023
2764.14	5.0655
2766.8	4.39726
2769.47	3.75946
2772.14	2.44359
2774.81	2.31421
2777.48	1.01867
2780.14	0.462347
2782.8	0.377837
2785.47	0.581173
2788.13	0.22486
2790.79	0.0564529
2793.45	-0.0370996
2796.11	-0.141864
2798.77	-0.498554
2801.43	-0.274699
2804.09	-0.274567
2806.74	-0.177934
2809.4	-1.25946
2812.05	-0.624607
2814.71	-0.222636
2817.36	1.51762
2820.01	3.59446
2822.66	6.2997
2825.31	9.38202
2827.96	14.2754
2830.6	19.6303
2833.25	24.1751
2835.9	29.3933
2838.54	36.0299
2841.18	43.8159
2843.83	51.5016
2846.47	61.7466
2849.11	71.9975
2851.75	81.6843
2854.39	91.397
2857.03	100.036
2859.66	109.344
2862.3	117.692
2864.94	125.815
2867.57	133.643
2870.2	139.727
2872.84	145.596
2875.47	151.284
2878.1	155.754
2880.73	161.432
2883.36	167.125
2885.99	171.734
2888.61	176.137
2891.24	181.66
2893.86	187.829
2896.49	194.067
2899.11	200.273
2901.73	208.988
2904.36	219.278
2906.98	231.349
2909.6	243.236
2912.21	256.142
2914.83	267.121
2917.45	277.477
2920.07	287.018
2922.68	296.302
2925.29	302.139
2927.91	307.411
2930.52	310.353
2933.13	311.029
2935.74	309.29
2938.35	304.538
2940.96	298.575
2943.57	290.498
2946.18	281.782
2948.78	271.096
2951.39	259.124
2953.99	246.256
2956.59	233.612
2959.2	220.122
2961.8	206.92
2964.4	195.215
2967	184.47
2969.6	173.916
2972.19	163.01
2974.79	152.052
2977.39	140.962
2979.98	129.88
2982.58	118.847
2985.17	107.816
2987.76	96.8667
2990.35	86.4621
2992.94	76.9362
2995.53	66.6488
2998.12	57.1615
3000.71	47.0749
3003.3	38.7821
3005.88	31.4184
3008.47	24.8574
3011.05	19.0459
3013.64	13.9711
3016.22	9.76465
3018.8	6.35337
3021.38	3.77752
3023.96	2.04297
3026.54	1.44469
3029.12	1.25803
3031.69	1.64507
3034.27	1.7746
3036.84	2.54755
3039.42	3.6581
3041.99	4.82811
3044.57	5.86172
3047.14	6.32083
3049.71	6.59603
3052.28	6.67728
3054.85	7.16964
3057.41	6.85799
3059.98	6.67261
3062.55	6.25531
3065.11	6.38125
3067.68	6.14946
3070.24	6.0112
3072.8	5.40512
3075.36	4.05738
3077.93	2.83148
3080.49	2.00266
3083.04	1.72847
3085.6	1.16821
3088.16	1.13595
3090.72	1.98888
3093.27	2.46082
3095.83	2.71645
3098.38	3.83924
3100.93	5.60763
3103.49	7.13483
3106.04	7.40628
3108.59	8.55333
3111.14	9.3691
3113.69	11.1583
3116.23	12.3383
3118.78	14.4436
3121.33	16.4511
3123.87	18.5841
3126.41	20.6162
3128.96	23.5592
3131.5	25.1262
3134.04	27.066
3136.58	28.8035
3139.12	31.2615
3141.66	34.5681
3144.2	38.0039
3146.74	41.8183
3149.27	47.3765