File: data/Raman/poly_smoothed/Mb_30_27_35_1x_45s_532 nm_x100_100%_600 gr_mm_01.txt
#Acq. time (s)=	45
#Accumulations=	2
#Range (cm-¹)=	200...3150
#Windows=	2
#Auto scanning=	Off
#Autofocus=	Off
#Macrospot=	Off
#AutoExposure=	Off
#Spike filter=	Multiple accum.
#Delay time (s)=	0
#Binning=	1
#Readout mode=	Signal
#DeNoise=	Off
#ICS correction=	On
#Dark correction=	Off
#Inst. Process=	Off
#Detector Gain=	Best Dynamic Range
#Detector ADC=	20 kHz
#Detector temperature (°C)=	-69.85
#Instrument=	LabRAM HR Evol
#Detector=	Synapse
#Objective=	x100
#Grating=	600 gr/mm
#ND Filter=	100%
#Laser (nm)=	532
#Hole=	100.021
#Range=	Auto
#Laser Pol.=	No
#Raman. Pol.=	No
#Laser Pol. (°)=	-0.0007625
#Raman Pol. (°)=	89.9995
#Collection=	Microscope
#StageXY=	Marzhauser
#StageZ=	Marzhauser
#X (µm)=	-6351.9
#Y (µm)=	809.6
#Z (µm)=	-64.95
#Full time(mm:ss)=	3:18
#Project=
#Sample=
#Site=
#Title=	Mb_30_27_35_2x_45s_532 nm_x100_100%_600 gr_mm
#Remark=
#Date=	13.07.2022 11:20
#Acquired=	13.07.2022 11:20:55
#Base:Fit=	10.08.2022 10:40:03
#Base:Sub=	10.08.2022 10:40:17
#Filter:Polynom=	16.08.2022 10:16:15
#AxisType[0]=Intens
#AxisUnit[0]=Cnt
#AxisType[1]=Spectr
#AxisUnit[1]=1/cm
200.563	37.517
204.194	29.9268
207.821	22.2848
211.449	17.2853
215.074	14.767
218.699	10.9932
222.321	10.5759
225.941	9.76495
229.562	7.17268
233.18	6.43022
236.796	5.43868
240.411	4.56126
244.026	3.41234
247.638	2.96162
251.248	4.05349
254.857	3.29908
258.465	4.41734
262.071	5.32577
265.678	7.40592
269.282	6.94457
272.884	6.34234
276.484	6.95863
280.084	7.84593
283.682	7.84706
287.276	7.27667
290.871	8.61388
294.465	9.82956
298.057	11.8347
301.648	12.6983
305.237	12.4871
308.823	14.0348
312.41	13.2728
315.995	12.9713
319.579	12.4527
323.16	12.3632
326.741	12.1352
330.321	12.6382
333.897	12.2442
337.474	13.0829
341.048	13.8158
344.622	12.8185
348.192	12.4285
351.764	13.4642
355.332	13.319
358.901	13.2561
362.466	12.2283
366.03	12.503
369.594	11.3947
373.155	11.1175
376.715	10.0146
380.273	9.29083
383.832	8.34797
387.388	7.28052
390.942	6.45382
394.495	7.2609
398.047	7.281
401.597	6.34269
405.145	6.58826
408.693	5.50544
412.239	6.33191
415.783	8.2985
419.327	6.87798
422.869	6.28351
426.409	5.94124
429.948	6.03199
433.486	5.94131
437.022	6.25287
440.558	6.78462
444.089	6.79089
447.622	4.72472
451.153	2.62303
454.682	4.09051
458.208	3.32852
461.735	4.36947
465.259	4.99429
468.783	4.82732
472.306	6.6102
475.825	7.8247
479.346	9.31553
482.862	11.1332
486.38	11.5437
489.894	11.7435
493.407	12.9499
496.92	12.5273
500.43	13.5851
503.939	13.2516
507.448	13.1736
510.954	13.4102
514.459	13.0629
517.962	12.4651
521.466	10.8736
524.966	10.5447
528.466	9.97256
531.964	7.69624
535.46	7.57452
538.955	6.50651
542.449	7.91192
545.942	7.53234
549.433	7.50056
552.923	7.19015
556.412	5.82296
559.899	6.16865
563.385	5.49624
566.867	5.43744
570.35	4.26118
573.832	3.85998
577.313	3.78972
580.79	2.93802
584.268	3.57924
587.745	3.81364
591.218	4.13872
594.692	2.8652
598.164	2.23085
601.634	1.7364
605.104	3.20778
608.57	4.34654
612.037	4.13561
615.501	4.92981
618.966	5.84387
622.427	6.92585
625.887	8.29449
629.348	9.61023
632.806	10.1689
636.262	11.2534
639.716	11.2616
643.172	11.8469
646.624	12.9741
650.075	13.653
653.524	12.7861
656.972	13.4017
660.419	13.5569
663.865	15.5494
667.309	15.7906
670.752	18.1248
674.194	19.0697
677.634	18.9246
681.073	20.6216
684.511	23.3027
687.947	26.4255
691.382	27.6037
694.816	28.851
698.247	30.6018
701.678	32.3027
705.108	33.7422
708.534	33.8067
711.962	36.147
715.388	37.599
718.81	38.2655
722.234	39.5527
725.654	40.4368
729.075	41.1299
732.492	41.3498
735.91	42.1005
739.325	43.5905
742.741	46.4693
746.153	48.0394
749.564	50.4549
752.976	53.1065
756.385	56.1031
759.792	58.0765
763.2	60.2429
766.604	64.7526
770.008	67.5109
773.41	69.683
776.811	70.2458
780.21	71.9607
783.608	73.2183
787.005	74.4478
790.401	75.8912
793.795	76.9563
797.188	78.3355
800.58	77.6927
803.971	78.5382
807.36	78.4504
810.748	77.2309
814.135	77.1316
817.518	77.7292
820.902	76.0695
824.285	76.3336
827.665	75.0507
831.045	74.5409
834.424	73.8807
837.8	72.5802
841.177	71.537
844.55	69.9933
847.924	69.7426
851.295	67.5393
854.666	65.2016
858.034	62.7541
861.403	60.4208
864.769	57.3753
868.133	55.8057
871.498	54.2652
874.86	52.5081
878.221	50.5319
881.58	48.7942
884.938	49.1979
888.297	48.0021
891.653	46.6424
895.007	45.7168
898.36	45.3913
901.712	45.0007
905.063	45.0765
908.412	46.6092
911.76	46.9599
915.107	46.239
918.452	46.8862
921.797	47.3384
925.138	48.3225
928.48	47.2401
931.82	46.5924
935.16	44.4236
938.496	42.8811
941.833	40.8362
945.168	38.6241
948.5	37.6222
951.834	36.62
955.163	33.9736
958.494	31.9305
961.821	29.915
965.15	27.8002
968.474	26.859
971.8	25.993
975.123	23.9718
978.446	23.6806
981.766	23.3357
985.084	22.3888
988.402	21.7501
991.72	22.153
995.035	21.868
998.349	22.7187
1001.66	21.3717
1004.97	22.3172
1008.28	21.9297
1011.59	23.8969
1014.9	24.0914
1018.21	26.082
1021.51	27.1274
1024.81	28.2206
1028.12	30.1
1031.42	31.3846
1034.72	30.5334
1038.02	30.3461
1041.31	28.7924
1044.61	28.6104
1047.91	26.532
1051.2	25.3372
1054.49	23.8677
1057.78	22.0133
1061.07	21.6397
1064.36	19.2451
1067.65	17.6586
1070.93	16.8457
1074.22	14.1875
1077.5	11.3035
1080.78	10.5272
1084.06	9.33463
1087.34	11.2032
1090.62	11.4362
1093.9	11.9799
1097.17	11.8465
1100.45	10.6193
1103.72	11.2718
1106.99	12.068
1110.27	13.1837
1113.53	12.4662
1116.8	11.9006
1120.07	9.99102
1123.33	9.63165
1126.6	8.4375
1129.86	7.98634
1133.12	8.34167
1136.38	8.38765
1139.64	7.07341
1142.9	6.52904
1146.16	6.35586
1149.41	6.10674
1152.67	4.69134
1155.92	1.41372
1159.17	2.64792
1162.42	2.36751
1165.67	3.12361
1168.92	2.84051
1172.16	2.69209
1175.41	0.988758
1178.65	0.788391
1181.9	1.24935
1185.14	1.66576
1188.38	2.00992
1191.62	3.32062
1194.86	2.98724
1198.09	3.08974
1201.33	3.69425
1204.56	3.85594
1207.8	4.80069
1211.03	5.63796
1214.26	5.88092
1217.49	6.74392
1220.71	7.79823
1223.94	10.0708
1227.16	10.7981
1230.39	10.4731
1233.61	10.5768
1236.83	12.157
1240.05	13.455
1243.27	15.8255
1246.49	17.9152
1249.71	19.4949
1252.92	20.6509
1256.14	20.7836
1259.35	22.2729
1262.56	23.2331
1265.77	24.2402
1268.98	24.2417
1272.19	25.2261
1275.4	25.1979
1278.6	25.5033
1281.81	26.0268
1285.01	24.6383
1288.21	24.7833
1291.41	26.3711
1294.61	26.063
1297.81	26.8632
1301.01	27.4125
1304.2	26.2628
1307.4	25.8252
1310.59	24.7102
1313.78	26.7781
1316.97	28.5733
1320.16	29.4798
1323.35	30.0747
1326.54	30.7351
1329.72	31.8368
1332.91	31.2138
1336.09	31.2852
1339.27	31.2853
1342.45	30.5531
1345.64	29.9865
1348.81	29.5664
1351.99	28.8151
1355.17	27.1341
1358.34	24.9642
1361.51	23.549
1364.69	21.6795
1367.86	21.7772
1371.03	20.7713
1374.2	18.0864
1377.37	17.3261
1380.53	16.2065
1383.7	14.8472
1386.86	13.6951
1390.02	13.6372
1393.19	13.6386
1396.35	14.5419
1399.51	13.3207
1402.66	15.3916
1405.82	15.694
1408.97	15.4657
1412.13	17.3732
1415.28	19.6677
1418.43	20.2385
1421.59	23.5199
1424.73	25.313
1427.88	27.362
1431.03	28.9422
1434.18	30.1635
1437.32	31.7668
1440.46	34.1136
1443.61	34.9489
1446.75	35.9078
1449.89	37.6126
1453.03	36.6606
1456.16	36.2277
1459.3	36.4807
1462.44	35.0809
1465.57	35.079
1468.7	34.4379
1471.83	34.7163
1474.96	33.4564
1478.09	32.978
1481.22	32.5653
1484.35	30.3962
1487.47	29.7506
1490.6	28.8011
1493.72	27.2488
1496.84	26.8172
1499.96	27.2851
1503.08	24.939
1506.2	24.8492
1509.32	22.9414
1512.44	21.4526
1515.55	20.0843
1518.66	19.9
1521.78	18.3329
1524.89	17.3766
1528	17.9441
1531.11	16.2848
1534.21	15.9902
1537.32	15.0545
1540.43	14.0328
1543.53	14.9971
1546.63	14.7588
1549.74	15.2606
1552.84	15.8584
1555.94	15.0037
1559.03	14.6925
1562.13	14.6873
1565.23	15.8502
1568.32	15.9269
1571.42	17.3149
1574.51	17.9186
1577.6	18.9084
1580.69	20.3589
1583.78	20.9467
1586.87	23.0154
1589.95	24.6728
1593.04	26.3592
1596.12	27.1265
1599.21	28.7833
1602.29	29.0575
1605.37	29.1039
1608.45	27.5736
1611.53	28.8398
1614.6	29.1075
1617.68	29.4034
1620.75	30.372
1623.83	31.3637
1626.9	31.6702
1629.97	32.2877
1633.04	32.2315
1636.11	32.3939
1639.18	31.8988
1642.25	32.1863
1645.31	35.2476
1648.38	35.2166
1651.44	35.6838
1654.5	37.083
1657.56	37.696
1660.62	38.2196
1663.68	37.4748
1666.74	35.6231
1669.8	35.1253
1672.85	34.2766
1675.91	32.2367
1678.96	30.5752
1682.01	28.3638
1685.06	27.2687
1688.11	25.9036
1691.16	23.5207
1694.21	22.2542
1697.25	20.4163
1700.3	18.8908
1703.34	16.6241
1706.39	14.9476
1709.43	13.159
1712.47	11.5162
1715.51	11.1332
1718.54	9.43851
1721.58	10.41
1724.62	8.06695
1727.65	8.05315
1730.68	7.53468
1733.72	5.81063
1736.75	4.36662
1739.78	4.01522
1742.81	3.47928
1745.84	3.13712
1748.86	3.97997
1751.89	4.33313
1754.91	3.17996
1757.93	3.0169
1760.96	3.51019
1763.98	3.58166
1767	4.23936
1770.02	5.14345
1773.03	4.83476
1776.05	4.90195
1779.07	5.15519
1782.08	5.26481
1785.09	4.6833
1788.11	4.98145
1791.12	5.33838
1794.13	5.35039
1797.13	4.67715
1800.14	4.37084
1803.15	3.69952
1806.15	2.86865
1809.16	2.00219
1812.16	2.08621
1815.16	1.64907
1818.16	1.63068
1821.16	1.51636
1824.16	1.96496
1827.16	0.770234
1830.16	1.04874
1833.15	1.7096
1836.14	1.76685
1839.14	1.6325
1842.13	1.83793
1845.12	1.39771
1848.11	1.18484
1851.1	1.4499
1854.08	0.373833
1857.07	1.16171
1860.05	2.17479
1863.04	2.26146
1866.02	2.02257
1869	2.16897
1871.98	2.53649
1874.96	3.10284
1877.94	2.93448
1880.92	4.67407
1882.51	4.18114
1885.5	4.37351
1888.48	4.91598
1891.47	5.34336
1894.46	6.24829
1897.44	6.29079
1900.42	6.16666
1903.41	6.83443
1906.39	6.83549
1909.37	6.65286
1912.35	6.67641
1915.32	7.25114
1918.3	6.99802
1921.27	5.71339
1924.25	4.7971
1927.22	4.74795
1930.19	4.939
1933.17	4.48776
1936.14	4.05662
1939.11	4.1576
1942.07	4.34416
1945.04	4.69712
1948.01	4.91949
1950.97	5.49292
1953.93	5.52984
1956.9	4.69678
1959.86	4.95915
1962.82	4.8528
1965.78	5.23336
1968.74	5.36253
1971.69	4.60852
1974.65	4.5075
1977.6	5.39483
1980.56	5.15124
1983.51	5.58292
1986.46	5.91368
1989.41	6.61508
1992.36	5.94204
1995.31	6.27308
1998.26	6.15136
2001.2	5.88199
2004.15	4.75977
2007.09	4.51753
2010.04	4.29768
2012.98	4.64025
2015.92	4.31306
2018.86	4.43497
2021.8	4.36469
2024.73	4.617
2027.67	5.31986
2030.61	4.85194
2033.54	5.48074
2036.47	5.03898
2039.4	5.34047
2042.33	5.70889
2045.27	5.91052
2048.19	6.631
2051.12	6.34516
2054.05	6.65185
2056.97	8.18854
2059.9	9.40708
2062.82	10.8864
2065.74	10.4098
2068.67	10.6023
2071.59	10.5643
2074.51	10.8599
2077.42	11.3234
2080.34	11.708
2083.26	12.032
2086.17	12.1579
2089.09	13.6258
2092	14.4992
2094.91	15.4851
2097.82	17.2827
2100.73	17.4169
2103.64	17.4082
2106.55	17.8902
2109.45	18.7686
2112.36	19.48
2115.26	19.2996
2118.17	20.0869
2121.07	21.7962
2123.97	23.212
2126.87	24.6829
2129.77	26.8521
2132.67	28.5241
2135.56	29.5516
2138.46	30.7409
2141.35	33.6419
2144.25	35.5392
2147.14	37.0863
2150.03	38.622
2152.92	39.7315
2155.81	41.8361
2158.7	43.4417
2161.59	45.2147
2164.47	47.047
2167.36	47.8833
2170.24	49.0235
2173.13	48.7683
2176.01	50.0553
2178.89	49.4956
2181.77	48.5239
2184.65	47.4461
2187.53	46.4653
2190.4	45.9305
2193.28	44.1859
2196.16	41.9369
2199.03	40.8996
2201.9	38.665
2204.77	36.1095
2207.64	34.4072
2210.51	33.1753
2213.38	31.4422
2216.25	29.3364
2219.12	27.1201
2221.98	24.3445
2224.85	23.0128
2227.71	21.7103
2230.57	20.9732
2233.43	20.4999
2236.29	19.9127
2239.15	19.9514
2242.01	18.9919
2244.87	18.427
2247.72	17.8911
2250.58	16.4863
2253.43	16.0646
2256.29	15.1778
2259.14	14.2915
2261.99	14.489
2264.84	14.4069
2267.69	14.0259
2270.53	13.144
2273.38	13.2078
2276.23	12.8861
2279.07	13.2793
2281.91	12.737
2284.76	13.0204
2287.6	12.5814
2290.44	10.7115
2293.28	10.039
2296.12	10.6857
2298.96	10.9533
2301.79	11.4648
2304.63	12.007
2307.46	12.133
2310.3	12.624
2313.13	12.3485
2315.96	12.7897
2318.79	11.489
2321.62	11.0492
2324.45	10.7613
2327.27	10.5222
2330.1	10.1305
2332.92	9.88632
2335.75	8.83982
2338.57	9.02993
2341.39	8.79399
2344.21	7.33293
2347.04	6.86843
2349.85	6.65629
2352.67	6.19838
2355.49	6.70411
2358.3	6.1893
2361.12	5.39407
2363.93	6.37266
2366.75	7.96085
2369.56	8.08498
2372.37	7.80031
2375.18	7.73355
2377.99	8.50929
2380.8	7.90897
2383.6	7.63429
2386.41	6.85239
2389.21	7.32039
2392.02	7.97918
2394.82	7.25263
2397.62	7.36447
2400.42	6.71165
2403.22	6.11073
2406.02	5.85681
2408.82	5.5836
2411.62	5.57296
2414.41	5.12598
2417.21	6.81071
2420	6.84117
2422.79	7.44141
2425.59	7.22035
2428.38	7.59115
2431.17	7.67925
2433.95	8.08832
2436.74	7.51208
2439.53	7.44446
2442.31	7.30742
2445.1	6.96772
2447.88	6.43822
2450.67	6.04913
2453.45	5.80349
2456.23	5.65543
2459.01	5.62357
2461.79	4.79591
2464.57	3.99057
2467.34	3.36202
2470.12	2.74081
2472.89	2.95524
2475.67	2.77211
2478.44	1.27712
2481.21	0.651805
2483.98	1.09418
2486.75	1.38824
2489.52	0.131732
2492.29	-0.0343577
2495.05	-0.256148
2497.82	-0.776005
2500.58	-0.60837
2503.35	-0.514035
2506.11	-0.125342
2508.87	0.0758734
2511.63	0.240181
2514.39	0.746321
2517.15	1.68
2519.91	2.47567
2522.67	3.49543
2525.42	4.69439
2528.18	5.15682
2530.93	5.33027
2533.69	6.15682
2536.44	6.13514
2539.19	6.48007
2541.94	6.88243
2544.69	6.59448
2547.44	5.97436
2550.18	6.55617
2552.93	6.1114
2555.67	5.58908
2558.42	5.0555
2561.16	4.30479
2563.9	3.68998
2566.64	3.54453
2569.38	3.60807
2572.12	2.9928
2574.86	2.63159
2577.6	2.04709
2580.33	2.26694
2583.07	2.24879
2585.8	1.93518
2588.54	2.25857
2591.27	2.72647
2594	2.05553
2596.73	2.29622
2599.46	2.29868
2602.19	3.11253
2604.92	3.25848
2607.64	3.90273
2610.37	4.05191
2613.09	3.41155
2615.82	3.09626
2618.54	3.67381
2621.26	4.14122
2623.98	4.61467
2626.7	3.7648
2629.42	3.82501
2632.14	4.61091
2634.86	4.07481
2637.57	4.02328
2640.29	3.21316
2643	3.83739
2645.71	2.94186
2648.43	2.62372
2651.14	2.84637
2653.85	2.97746
2656.56	3.42744
2659.26	2.9138
2661.97	2.63394
2664.68	2.09218
2667.38	2.55487
2670.09	2.82134
2672.79	3.12285
2675.49	2.90393
2678.19	2.47086
2680.89	2.83415
2683.59	3.90501
2686.29	4.03051
2688.99	3.21808
2691.69	3.10849
2694.38	2.9337
2697.08	3.64273
2699.77	3.72766
2702.46	3.53132
2705.15	3.95346
2707.85	4.7549
2710.54	4.52735
2713.22	4.01869
2715.91	4.50933
2718.6	5.15617
2721.29	5.17942
2723.97	5.13897
2726.66	4.47713
2729.34	4.49084
2732.02	4.41086
2734.7	4.54708
2737.38	4.57102
2740.06	4.43989
2742.74	5.31705
2745.42	5.18872
2748.09	4.68558
2750.77	4.55721
2753.45	3.55247
2756.12	2.99579
2758.79	2.9493
2761.46	2.57053
2764.14	2.14888
2766.8	1.76546
2769.47	1.88598
2772.14	1.22348
2774.81	0.32188
2777.48	0.247608
2780.14	0.397947
2782.8	0.234671
2785.47	0.180541
2788.13	-0.260479
2790.79	-0.586227
2793.45	-0.787988
2796.11	-0.270216
2798.77	-0.247958
2801.43	-0.210945
2804.09	-0.990696
2806.74	-0.35214
2809.4	-0.425003
2812.05	-0.570087
2814.71	-0.112422
2817.36	0.463594
2820.01	0.903783
2822.66	2.13337
2825.31	3.47724
2827.96	4.85345
2830.6	7.03206
2833.25	9.682
2835.9	12.5773
2838.54	15.1512
2841.18	18.946
2843.83	22.7186
2846.47	25.0234
2849.11	28.174
2851.75	31.8204
2854.39	35.4451
2857.03	39.7738
2859.66	43.7547
2862.3	47.1567
2864.94	49.4301
2867.57	52.6458
2870.2	54.7756
2872.84	57.4451
2875.47	60.1259
2878.1	61.228
2880.73	62.5176
2883.36	64.7477
2885.99	67.244
2888.61	69.8168
2891.24	71.6887
2893.86	73.8998
2896.49	76.5271
2899.11	80.0798
2901.73	83.9502
2904.36	87.4879
2906.98	91.3211
2909.6	95.1894
2912.21	100.419
2914.83	106.711
2917.45	112.112
2920.07	118.173
2922.68	122.372
2925.29	125.828
2927.91	129.12
2930.52	130.927
2933.13	132.522
2935.74	133.216
2938.35	131.865
2940.96	129.938
2943.57	126.75
2946.18	122.828
2948.78	118.848
2951.39	113.811
2953.99	108.417
2956.59	102.703
2959.2	96.6727
2961.8	91.6734
2964.4	85.8038
2967	80.25
2969.6	75.645
2972.19	70.5032
2974.79	65.6786
2977.39	62.1797
2979.98	57.3596
2982.58	52.2304
2985.17	47.8206
2987.76	42.731
2990.35	39.0543
2992.94	34.7863
2995.53	31.2334
2998.12	26.963
3000.71	22.7115
3003.3	19.1348
3005.88	15.9498
3008.47	13.2138
3011.05	10.8817
3013.64	9.05426
3016.22	7.70153
3018.8	6.08892
3021.38	5.05602
3023.96	4.3005
3026.54	3.77144
3029.12	3.36713
3031.69	3.62331
3034.27	3.14842
3036.84	3.42769
3039.42	3.49571
3041.99	4.6464
3044.57	4.69549
3047.14	5.2751
3049.71	6.14998
3052.28	6.19868
3054.85	5.65434
3057.41	5.41418
3059.98	5.37023
3062.55	4.98945
3065.11	5.40388
3067.68	5.64326
3070.24	5.71708
3072.8	5.81626
3075.36	5.57288
3077.93	5.2891
3080.49	4.41582
3083.04	4.08791
3085.6	3.52809
3088.16	2.41371
3090.72	1.96027
3093.27	1.97131
3095.83	0.918816
3098.38	1.62929
3100.93	2.06364
3103.49	2.30641
3106.04	2.92885
3108.59	3.89807
3111.14	3.75858
3113.69	4.22753
3116.23	4.07182
3118.78	4.92634
3121.33	5.88276
3123.87	6.81513
3126.41	8.35662
3128.96	9.34906
3131.5	10.3908
3134.04	11.4976
3136.58	12.2527
3139.12	12.7169
3141.66	12.9126
3144.2	12.7314
3146.74	12.7148
3149.27	11.9833