File: data/Raman/poly_smoothed/Mb_30_27_17_1x_45s_532 nm_x100_100%_600 gr_mm_01.txt
#Acq. time (s)=	45
#Accumulations=	2
#Range (cm-¹)=	200...3150
#Windows=	2
#Auto scanning=	Off
#Autofocus=	Off
#Macrospot=	Off
#AutoExposure=	Off
#Spike filter=	Multiple accum.
#Delay time (s)=	0
#Binning=	1
#Readout mode=	Signal
#DeNoise=	Off
#ICS correction=	On
#Dark correction=	Off
#Inst. Process=	Off
#Detector Gain=	Best Dynamic Range
#Detector ADC=	20 kHz
#Detector temperature (°C)=	-69.85
#Instrument=	LabRAM HR Evol
#Detector=	Synapse
#Objective=	x100
#Grating=	600 gr/mm
#ND Filter=	100%
#Laser (nm)=	532
#Hole=	100.021
#Range=	Auto
#Laser Pol.=	No
#Raman. Pol.=	No
#Laser Pol. (°)=	-0.0007625
#Raman Pol. (°)=	89.9995
#Collection=	Microscope
#StageXY=	Marzhauser
#StageZ=	Marzhauser
#X (µm)=	-6414
#Y (µm)=	863.4
#Z (µm)=	-64.65
#Full time(mm:ss)=	3:18
#Project=
#Sample=
#Site=
#Title=	Mb_30_27_17_2x_45s_532 nm_x100_100%_600 gr_mm
#Remark=
#Date=	13.07.2022 09:54
#Acquired=	13.07.2022 09:54:41
#Base:Fit=	10.08.2022 10:40:03
#Base:Sub=	10.08.2022 10:40:17
#Filter:Polynom=	16.08.2022 10:16:15
#AxisType[0]=Intens
#AxisUnit[0]=Cnt
#AxisType[1]=Spectr
#AxisUnit[1]=1/cm
200.563	31.7875
204.194	23.686
207.821	17.7857
211.449	14.1539
215.074	12.7009
218.699	11.2574
222.321	10.0217
225.941	7.83371
229.562	7.50835
233.18	7.5642
236.796	6.63694
240.411	5.86233
244.026	5.3567
247.638	6.76657
251.248	8.17239
254.857	11.066
258.465	10.9131
262.071	12.4233
265.678	13.2377
269.282	14.4619
272.884	13.4385
276.484	13.1038
280.084	12.4862
283.682	12.1601
287.276	13.8455
290.871	14.0147
294.465	15.4062
298.057	16.0034
301.648	16.4613
305.237	15.4152
308.823	15.4435
312.41	15.2519
315.995	14.6821
319.579	14.2974
323.16	13.4617
326.741	11.8865
330.321	12.7579
333.897	13.4474
337.474	13.8185
341.048	13.0404
344.622	11.6555
348.192	11.3836
351.764	9.89632
355.332	9.86331
358.901	7.55209
362.466	8.61077
366.03	8.84163
369.594	8.20154
373.155	9.78412
376.715	9.04668
380.273	9.88612
383.832	11.851
387.388	10.3096
390.942	10.2409
394.495	10.5614
398.047	9.44989
401.597	10.2702
405.145	8.64403
408.693	7.81114
412.239	9.5032
415.783	9.42274
419.327	9.14474
422.869	9.11197
426.409	7.90122
429.948	6.39684
433.486	5.64359
437.022	4.92545
440.558	4.41904
444.089	4.78313
447.622	4.58003
451.153	5.51416
454.682	5.5479
458.208	7.15298
461.735	7.49574
465.259	8.25514
468.783	11.4243
472.306	10.8474
475.825	10.6632
479.346	12.7956
482.862	14.2537
486.38	16.3406
489.894	17.5785
493.407	18.9097
496.92	19.6677
500.43	19.719
503.939	19.9322
507.448	18.82
510.954	17.5241
514.459	16.72
517.962	16.9994
521.466	16.7189
524.966	16.4904
528.466	16.9929
531.964	16.808
535.46	15.5019
538.955	15.402
542.449	14.2302
545.942	12.0362
549.433	12.1381
552.923	12.7024
556.412	11.257
559.899	9.14322
563.385	9.75192
566.867	9.42269
570.35	8.25028
573.832	7.6594
577.313	6.53759
580.79	6.12768
584.268	4.87178
587.745	3.80154
591.218	2.99604
594.692	2.31367
598.164	3.26623
601.634	4.08587
605.104	4.90485
608.57	6.08936
612.037	5.71867
615.501	5.04657
618.966	4.30863
622.427	4.72853
625.887	4.99412
629.348	3.41014
632.806	4.70005
636.262	4.90347
639.716	3.85199
643.172	5.18137
646.624	5.28911
650.075	6.8383
653.524	6.59114
656.972	6.94724
660.419	6.65693
663.865	7.23299
667.309	8.12924
670.752	7.68235
674.194	7.74369
677.634	9.31855
681.073	11.2265
684.511	13.6981
687.947	15.2588
691.382	16.7771
694.816	18.004
698.247	19.5286
701.678	21.5175
705.108	22.8879
708.534	25.6784
711.962	26.0876
715.388	28.2442
718.81	30.468
722.234	31.3568
725.654	32.8922
729.075	33.8371
732.492	35.2515
735.91	37.3824
739.325	37.8832
742.741	39.0953
746.153	39.5995
749.564	42.0436
752.976	45.1999
756.385	46.4729
759.792	47.8845
763.2	51.4104
766.604	54.2563
770.008	56.8613
773.41	58.9469
776.811	62.0041
780.21	63.4856
783.608	64.5753
787.005	64.4719
790.401	67.3745
793.795	69.1141
797.188	69.2244
800.58	69.509
803.971	69.9678
807.36	69.0186
810.748	68.2001
814.135	67.9272
817.518	68.8638
820.902	68.7981
824.285	68.4686
827.665	68.0297
831.045	66.4139
834.424	66.175
837.8	63.8444
841.177	62.5903
844.55	61.0491
847.924	60.3648
851.295	58.307
854.666	56.7677
858.034	55.5226
861.403	54.716
864.769	52.5247
868.133	51.5726
871.498	52.2116
874.86	52.5287
878.221	49.5475
881.58	49.0538
884.938	48.1996
888.297	46.5754
891.653	45.7864
895.007	44.8487
898.36	44.6556
901.712	43.7225
905.063	42.8034
908.412	40.6608
911.76	39.2013
915.107	37.7771
918.452	35.7798
921.797	35.2313
925.138	34.7232
928.48	32.4589
931.82	31.5574
935.16	32.4648
938.496	31.5652
941.833	30.8571
945.168	30.0493
948.5	30.216
951.834	32.8684
955.163	33.5466
958.494	32.9787
961.821	31.8442
965.15	33.5335
968.474	32.9882
971.8	33.0944
975.123	32.9979
978.446	32.3003
981.766	31.2196
985.084	30.8386
988.402	31.0555
991.72	31.8762
995.035	30.2314
998.349	27.9406
1001.66	27.34
1004.97	24.7643
1008.28	27.2956
1011.59	31.4736
1014.9	36.0139
1018.21	40.0282
1021.51	42.4713
1024.81	46.8522
1028.12	50.6504
1031.42	53.1615
1034.72	52.8394
1038.02	53.0872
1041.31	52.7733
1044.61	54.5348
1047.91	55.2225
1051.2	52.6134
1054.49	49.9724
1057.78	46.549
1061.07	42.5846
1064.36	38.6808
1067.65	35.6434
1070.93	30.61
1074.22	23.4557
1077.5	18.3611
1080.78	15.4297
1084.06	13.372
1087.34	13.5542
1090.62	14.1237
1093.9	16.5474
1097.17	18.8819
1100.45	19.0371
1103.72	20.6348
1106.99	19.6303
1110.27	19.5415
1113.53	18.9461
1116.8	19.9734
1120.07	21.3856
1123.33	22.8782
1126.6	22.9825
1129.86	21.4047
1133.12	19.28
1136.38	17.8931
1139.64	16.8209
1142.9	15.9561
1146.16	14.0232
1149.41	13.2476
1152.67	10.9154
1155.92	8.80296
1159.17	8.93891
1162.42	8.41973
1165.67	7.61114
1168.92	6.87797
1172.16	7.34283
1175.41	9.76446
1178.65	10.4184
1181.9	11.2629
1185.14	10.2851
1188.38	9.79991
1191.62	12.413
1194.86	12.9125
1198.09	16.8091
1201.33	18.645
1204.56	20.1507
1207.8	20.2844
1211.03	22.5728
1214.26	25.7792
1217.49	28.4564
1220.71	30.7151
1223.94	35.0448
1227.16	37.3359
1230.39	39.8504
1233.61	42.4991
1236.83	46.451
1240.05	48.4597
1243.27	50.1755
1246.49	52.8877
1249.71	55.574
1252.92	58.2733
1256.14	60.5051
1259.35	62.9974
1262.56	63.3936
1265.77	63.3501
1268.98	64.5562
1272.19	65.8061
1275.4	66.3467
1278.6	66.8739
1281.81	65.3987
1285.01	66.9002
1288.21	66.5248
1291.41	68.1699
1294.61	69.3756
1297.81	68.5716
1301.01	69.456
1304.2	69.6734
1307.4	70.2255
1310.59	69.9236
1313.78	69.8289
1316.97	71.3269
1320.16	71.3334
1323.35	73.5244
1326.54	74.281
1329.72	75.6869
1332.91	75.8746
1336.09	76.8904
1339.27	75.4507
1342.45	74.495
1345.64	73.7047
1348.81	72.4958
1351.99	72.5496
1355.17	70.2505
1358.34	68.7851
1361.51	67.6694
1364.69	65.6326
1367.86	63.6384
1371.03	62.0555
1374.2	60.2636
1377.37	57.6181
1380.53	55.5122
1383.7	53.2389
1386.86	51.175
1390.02	48.5703
1393.19	47.9509
1396.35	45.541
1399.51	45.7058
1402.66	43.9271
1405.82	43.511
1408.97	43.1856
1412.13	44.0715
1415.28	44.7182
1418.43	46.5463
1421.59	49.6757
1424.73	53.9409
1427.88	57.8417
1431.03	62.5255
1434.18	67.3561
1437.32	70.8092
1440.46	74.0598
1443.61	77.29
1446.75	80.3459
1449.89	83.4715
1453.03	83.3269
1456.16	83.8655
1459.3	83.0422
1462.44	84.3522
1465.57	85.0948
1468.7	86.1038
1471.83	85.9807
1474.96	86.3024
1478.09	86.7073
1481.22	85.1454
1484.35	84.3483
1487.47	81.4383
1490.6	79.343
1493.72	77.7165
1496.84	76.5557
1499.96	74.0685
1503.08	71.4097
1506.2	66.9165
1509.32	63.4391
1512.44	57.9033
1515.55	53.4309
1518.66	48.0901
1521.78	44.0024
1524.89	41.3285
1528	37.1222
1531.11	35.2672
1534.21	33.8067
1537.32	32.3888
1540.43	33.8016
1543.53	34.119
1546.63	35.9761
1549.74	37.4707
1552.84	39.901
1555.94	41.255
1559.03	44.0139
1562.13	44.7688
1565.23	47.4787
1568.32	49.4366
1571.42	51.6413
1574.51	53.1522
1577.6	55.7044
1580.69	58.1329
1583.78	58.8144
1586.87	59.9698
1589.95	62.4612
1593.04	63.6957
1596.12	64.307
1599.21	65.4708
1602.29	65.9202
1605.37	63.7325
1608.45	63.996
1611.53	62.9921
1614.6	63.4585
1617.68	64.1298
1620.75	65.2935
1623.83	65.9123
1626.9	68.1077
1629.97	70.5046
1633.04	73.0618
1636.11	76.8558
1639.18	79.1874
1642.25	82.326
1645.31	85.2889
1648.38	88.5495
1651.44	90.9229
1654.5	91.6418
1657.56	91.3658
1660.62	90.2607
1663.68	89.8124
1666.74	86.4979
1669.8	82.6052
1672.85	78.2351
1675.91	72.8153
1678.96	67.6232
1682.01	62.6906
1685.06	56.9528
1688.11	51.3053
1691.16	45.2865
1694.21	39.9937
1697.25	36.4257
1700.3	33.233
1703.34	30.7435
1706.39	28.2906
1709.43	26.1176
1712.47	23.745
1715.51	21.6314
1718.54	19.9508
1721.58	19.049
1724.62	16.9067
1727.65	16.7709
1730.68	14.9936
1733.72	14.3275
1736.75	14.5716
1739.78	13.5825
1742.81	13.8688
1745.84	12.8582
1748.86	11.217
1751.89	9.68801
1754.91	8.83471
1757.93	7.11956
1760.96	6.10818
1763.98	5.45884
1767	4.93642
1770.02	4.32203
1773.03	3.89309
1776.05	3.01884
1779.07	2.56258
1782.08	2.20533
1785.09	1.59209
1788.11	0.817782
1791.12	0.684704
1794.13	1.07936
1797.13	1.64817
1800.14	2.57844
1803.15	2.99772
1806.15	2.81062
1809.16	3.78548
1812.16	4.07954
1815.16	4.84466
1818.16	4.03853
1821.16	3.36448
1824.16	3.53007
1827.16	3.99732
1830.16	4.32021
1833.15	5.44424
1836.14	5.44205
1839.14	4.74463
1842.13	4.42246
1845.12	4.39122
1848.11	4.11439
1851.1	4.45185
1854.08	4.68575
1857.07	5.09724
1860.05	4.48482
1863.04	4.04562
1866.02	3.94039
1869	5.06894
1871.98	5.47263
1874.96	4.59272
1877.94	3.97118
1880.92	4.34189
1882.51	4.07204
1885.5	4.25158
1888.48	4.34787
1891.47	3.38239
1894.46	3.30127
1897.44	2.96542
1900.42	2.94935
1903.41	2.54566
1906.39	1.91002
1909.37	2.05139
1912.35	2.42797
1915.32	2.37367
1918.3	2.08936
1921.27	2.38395
1924.25	2.48663
1927.22	2.15416
1930.19	1.98507
1933.17	1.91323
1936.14	2.58891
1939.11	3.48721
1942.07	4.16924
1945.04	4.18339
1948.01	3.55477
1950.97	4.33112
1953.93	4.92768
1956.9	4.67841
1959.86	4.51441
1962.82	5.1567
1965.78	3.85254
1968.74	3.01522
1971.69	3.76198
1974.65	4.09289
1977.6	4.43598
1980.56	5.29932
1983.51	4.94417
1986.46	3.57827
1989.41	3.49484
1992.36	2.94074
1995.31	2.65927
1998.26	2.06013
2001.2	1.58968
2004.15	1.70961
2007.09	1.63398
2010.04	1.59163
2012.98	1.53442
2015.92	2.92162
2018.86	2.84108
2021.8	3.01515
2024.73	3.61262
2027.67	3.75408
2030.61	3.99298
2033.54	3.93683
2036.47	4.7522
2039.4	4.48627
2042.33	4.69982
2045.27	5.14587
2048.19	6.24159
2051.12	6.02961
2054.05	6.31901
2056.97	6.34704
2059.9	5.69255
2062.82	6.50552
2065.74	5.20868
2068.67	5.36682
2071.59	4.62862
2074.51	5.61675
2077.42	6.20174
2080.34	7.14718
2083.26	7.95024
2086.17	9.02965
2089.09	8.82078
2092	9.37117
2094.91	11.1242
2097.82	12.4381
2100.73	14.1254
2103.64	14.8179
2106.55	16.2721
2109.45	17.7872
2112.36	19.0524
2115.26	21.2839
2118.17	24.1073
2121.07	26.0995
2123.97	28.7057
2126.87	31.7704
2129.77	35.6502
2132.67	38.5834
2135.56	41.2442
2138.46	44.7759
2141.35	49.0659
2144.25	52.672
2147.14	57.7994
2150.03	60.4918
2152.92	63.7052
2155.81	65.8823
2158.7	68.7657
2161.59	72.8296
2164.47	75.0125
2167.36	78.3473
2170.24	81.0928
2173.13	80.9367
2176.01	80.1294
2178.89	80.938
2181.77	78.8773
2184.65	76.9891
2187.53	75.4523
2190.4	72.5863
2193.28	70.4556
2196.16	67.5158
2199.03	64.5708
2201.9	59.8491
2204.77	56.3225
2207.64	52.3777
2210.51	49.8038
2213.38	45.0997
2216.25	42.0253
2219.12	37.3551
2221.98	34.5314
2224.85	31.9878
2227.71	29.4957
2230.57	26.886
2233.43	24.7109
2236.29	23.8311
2239.15	22.4168
2242.01	20.1942
2244.87	17.9981
2247.72	16.873
2250.58	15.4802
2253.43	13.9013
2256.29	13.826
2259.14	11.8972
2261.99	11.4691
2264.84	11.2586
2267.69	11.7995
2270.53	10.6531
2273.38	11.5504
2276.23	12.0236
2279.07	11.4111
2281.91	10.2972
2284.76	9.93645
2287.6	9.74644
2290.44	9.2203
2293.28	8.32061
2296.12	6.68737
2298.96	7.20623
2301.79	8.20548
2304.63	8.27512
2307.46	9.21281
2310.3	8.6934
2313.13	8.64199
2315.96	8.6928
2318.79	8.02428
2321.62	7.55041
2324.45	7.07531
2327.27	6.40052
2330.1	6.71244
2332.92	6.61098
2335.75	5.64709
2338.57	5.76223
2341.39	5.52314
2344.21	4.85123
2347.04	3.05048
2349.85	2.11817
2352.67	0.730672
2355.49	0.557814
2358.3	-0.323083
2361.12	-0.371282
2363.93	-0.758323
2366.75	0.551651
2369.56	1.19118
2372.37	1.37312
2375.18	2.13963
2377.99	2.01612
2380.8	1.54472
2383.6	1.6151
2386.41	0.402556
2389.21	1.32234
2392.02	0.530332
2394.82	-0.662854
2397.62	-0.498847
2400.42	-0.932299
2403.22	-0.568151
2406.02	-0.580393
2408.82	0.819089
2411.62	-0.0812029
2414.41	1.08985
2417.21	1.45192
2420	1.89136
2422.79	3.32282
2425.59	3.75918
2428.38	4.04462
2431.17	5.58387
2433.95	6.55259
2436.74	7.64976
2439.53	8.16061
2442.31	7.75185
2445.1	7.40139
2447.88	6.83622
2450.67	6.24672
2453.45	5.97391
2456.23	5.32136
2459.01	4.9577
2461.79	4.72177
2464.57	4.36892
2467.34	4.11663
2470.12	4.25721
2472.89	4.95302
2475.67	4.5242
2478.44	5.05462
2481.21	4.15002
2483.98	3.94762
2486.75	2.66887
2489.52	3.29123
2492.29	3.28377
2495.05	2.70744
2497.82	4.30615
2500.58	3.85856
2503.35	3.77825
2506.11	3.30068
2508.87	2.98357
2511.63	2.88427
2514.39	3.60205
2517.15	4.22866
2519.91	4.08259
2522.67	4.55812
2525.42	4.31664
2528.18	5.00373
2530.93	5.24513
2533.69	5.18646
2536.44	5.87821
2539.19	6.25835
2541.94	5.95939
2544.69	5.43571
2547.44	4.94147
2550.18	4.02576
2552.93	4.1165
2555.67	4.47577
2558.42	5.41561
2561.16	5.53657
2563.9	5.84044
2566.64	5.69855
2569.38	4.97358
2572.12	5.95256
2574.86	6.64176
2577.6	7.11571
2580.33	7.59887
2583.07	7.06788
2585.8	6.97938
2588.54	7.8539
2591.27	6.93736
2594	6.65327
2596.73	7.32532
2599.46	6.6767
2602.19	7.26256
2604.92	7.25809
2607.64	6.91548
2610.37	6.11075
2613.09	5.81523
2615.82	5.83158
2618.54	6.55758
2621.26	6.19362
2623.98	7.68305
2626.7	7.31265
2629.42	7.16112
2632.14	6.66723
2634.86	6.35751
2637.57	6.50771
2640.29	6.27562
2643	5.54319
2645.71	5.20615
2648.43	4.74647
2651.14	5.55009
2653.85	5.8593
2656.56	5.93155
2659.26	6.08299
2661.97	6.00484
2664.68	6.93704
2667.38	7.62535
2670.09	7.53336
2672.79	8.10586
2675.49	8.18575
2678.19	9.19315
2680.89	10.011
2683.59	10.2912
2686.29	10.5501
2688.99	11.2363
2691.69	11.3708
2694.38	10.1707
2697.08	10.7245
2699.77	10.3333
2702.46	9.48331
2705.15	9.37931
2707.85	8.92348
2710.54	8.88921
2713.22	8.77775
2715.91	9.31533
2718.6	9.06072
2721.29	8.90696
2723.97	8.78273
2726.66	8.79524
2729.34	8.99495
2732.02	8.67378
2734.7	8.46758
2737.38	8.94547
2740.06	9.55844
2742.74	9.68141
2745.42	9.73094
2748.09	8.45943
2750.77	7.47366
2753.45	6.54391
2756.12	6.0354
2758.79	5.24115
2761.46	6.28118
2764.14	5.6444
2766.8	5.15202
2769.47	5.29519
2772.14	5.24067
2774.81	4.83153
2777.48	4.07955
2780.14	4.14424
2782.8	3.914
2785.47	3.62767
2788.13	2.66455
2790.79	2.5256
2793.45	2.62213
2796.11	1.6013
2798.77	1.25804
2801.43	1.41771
2804.09	1.05023
2806.74	0.763317
2809.4	0.0493372
2812.05	-1.12938
2814.71	-1.18747
2817.36	0.0640383
2820.01	1.12107
2822.66	2.32277
2825.31	4.64163
2827.96	7.28696
2830.6	9.60347
2833.25	13.3754
2835.9	17.0344
2838.54	21.0648
2841.18	26.6924
2843.83	32.5747
2846.47	39.6131
2849.11	46.5191
2851.75	52.8999
2854.39	60.5222
2857.03	68.2016
2859.66	76.2161
2862.3	83.1251
2864.94	88.734
2867.57	93.6717
2870.2	99.4604
2872.84	104.795
2875.47	108.694
2878.1	112.805
2880.73	116.416
2883.36	118.758
2885.99	120.521
2888.61	123.9
2891.24	127.848
2893.86	130.641
2896.49	136.325
2899.11	142.072
2901.73	150.706
2904.36	159.924
2906.98	170.61
2909.6	181.154
2912.21	192.23
2914.83	203.062
2917.45	212.814
2920.07	223.533
2922.68	232.536
2925.29	239.278
2927.91	243.737
2930.52	247.525
2933.13	248.86
2935.74	250.742
2938.35	248.461
2940.96	244.329
2943.57	237.704
2946.18	228.935
2948.78	220.59
2951.39	211.528
2953.99	201.152
2956.59	190.291
2959.2	179.923
2961.8	170.606
2964.4	159.874
2967	150.337
2969.6	141.814
2972.19	131.715
2974.79	121.999
2977.39	112.605
2979.98	103.353
2982.58	94.9856
2985.17	86.1014
2987.76	77.4319
2990.35	68.8578
2992.94	61.3712
2995.53	54.5668
2998.12	47.9485
3000.71	42.6478
3003.3	36.5791
3005.88	30.0974
3008.47	24.7093
3011.05	21.1283
3013.64	18.0819
3016.22	14.0041
3018.8	11.0141
3021.38	8.90029
3023.96	6.72333
3026.54	4.84211
3029.12	3.70474
3031.69	3.33093
3034.27	2.59493
3036.84	3.21963
3039.42	3.22577
3041.99	3.60185
3044.57	5.05898
3047.14	5.42047
3049.71	6.48892
3052.28	7.15348
3054.85	6.99435
3057.41	6.91833
3059.98	8.21657
3062.55	7.68456
3065.11	7.44754
3067.68	7.16104
3070.24	6.23831
3072.8	5.86912
3075.36	5.55646
3077.93	4.49691
3080.49	3.60482
3083.04	1.75453
3085.6	0.777587
3088.16	0.0860801
3090.72	-1.18516
3093.27	-1.00694
3095.83	-0.118516
3098.38	-0.0344489
3100.93	0.662519
3103.49	1.94037
3106.04	2.63717
3108.59	4.4369
3111.14	5.89523
3113.69	6.44536
3116.23	6.9909
3118.78	8.08644
3121.33	10.1059
3123.87	11.5698
3126.41	13.1053
3128.96	14.4922
3131.5	16.7953
3134.04	18.095
3136.58	19.9352
3139.12	21.2782
3141.66	21.7628
3144.2	22.4833
3146.74	24.0281
3149.27	24.3725