File: data/Raman/poly_smoothed/Mb_30_27_14_1x_45s_532 nm_x100_100%_600 gr_mm_01.txt
#Acq. time (s)=	45
#Accumulations=	2
#Range (cm-¹)=	200...3150
#Windows=	2
#Auto scanning=	Off
#Autofocus=	Off
#Macrospot=	Off
#AutoExposure=	Off
#Spike filter=	Multiple accum.
#Delay time (s)=	0
#Binning=	1
#Readout mode=	Signal
#DeNoise=	Off
#ICS correction=	On
#Dark correction=	Off
#Inst. Process=	Off
#Detector Gain=	Best Dynamic Range
#Detector ADC=	20 kHz
#Detector temperature (°C)=	-69.85
#Instrument=	LabRAM HR Evol
#Detector=	Synapse
#Objective=	x100
#Grating=	600 gr/mm
#ND Filter=	100%
#Laser (nm)=	532
#Hole=	100.021
#Range=	Auto
#Laser Pol.=	No
#Raman. Pol.=	No
#Laser Pol. (°)=	-0.0007625
#Raman Pol. (°)=	89.9995
#Collection=	Microscope
#StageXY=	Marzhauser
#StageZ=	Marzhauser
#X (µm)=	-6420.6
#Y (µm)=	871.3
#Z (µm)=	-64.95
#Full time(mm:ss)=	3:19
#Project=
#Sample=
#Site=
#Title=	Mb_30_27_14_2x_45s_532 nm_x100_100%_600 gr_mm
#Remark=
#Date=	13.07.2022 09:38
#Acquired=	13.07.2022 09:38:43
#Edit:Spike=	13.07.2022 09:42:33
#Edit:Spike=	13.07.2022 09:42:34
#Base:Fit=	10.08.2022 10:40:03
#Base:Sub=	10.08.2022 10:40:17
#Filter:Polynom=	16.08.2022 10:16:15
#AxisType[0]=Intens
#AxisUnit[0]=Cnt
#AxisType[1]=Spectr
#AxisUnit[1]=1/cm
200.563	3.25278
204.194	4.97783
207.821	5.30735
211.449	4.93416
215.074	5.50063
218.699	3.72495
222.321	3.14684
225.941	3.29598
229.562	2.72662
233.18	3.24097
236.796	3.72943
240.411	3.53622
244.026	2.30473
247.638	3.33369
251.248	2.89767
254.857	1.5395
258.465	2.0722
262.071	2.26834
265.678	3.66933
269.282	4.92326
272.884	4.83884
276.484	5.11077
280.084	4.77979
283.682	4.54629
287.276	4.64583
290.871	4.60018
294.465	2.99776
298.057	3.15674
301.648	3.38583
305.237	2.0437
308.823	2.60654
312.41	2.05457
315.995	3.46845
319.579	3.77441
323.16	5.07404
326.741	5.38069
330.321	6.17094
333.897	6.11488
337.474	7.22826
341.048	6.49942
344.622	7.72855
348.192	8.52468
351.764	9.3578
355.332	9.95642
358.901	9.24832
362.466	9.9905
366.03	10.0288
369.594	8.26772
373.155	7.67851
376.715	6.89
380.273	4.79103
383.832	4.39268
387.388	3.63422
390.942	3.97244
394.495	2.92581
398.047	3.62186
401.597	4.43643
405.145	5.99946
408.693	8.46636
412.239	10.3086
415.783	10.0867
419.327	11.2041
422.869	12.3402
426.409	11.5044
429.948	10.5991
433.486	10.9892
437.022	9.66845
440.558	10.3625
444.089	9.40946
447.622	10.6273
451.153	9.97352
454.682	9.31113
458.208	8.91952
461.735	8.16749
465.259	6.98348
468.783	6.9021
472.306	7.44838
475.825	7.82121
479.346	7.22943
482.862	8.74821
486.38	11.1245
489.894	13.0132
493.407	14.5769
496.92	15.5919
500.43	16.443
503.939	17.0023
507.448	18.0202
510.954	15.9658
514.459	15.6522
517.962	16.4794
521.466	15.6175
524.966	15.4596
528.466	15.575
531.964	14.8447
535.46	13.714
538.955	13.6682
542.449	12.2324
545.942	10.2814
549.433	10.1203
552.923	9.557
556.412	7.9643
559.899	7.37481
563.385	6.17668
566.867	6.46423
570.35	5.23908
573.832	3.35318
577.313	3.00643
580.79	3.19083
584.268	2.13979
587.745	3.76768
591.218	3.33556
594.692	3.16263
598.164	2.84862
601.634	3.8698
605.104	3.8026
608.57	3.86801
612.037	3.76268
615.501	3.2829
618.966	3.73649
622.427	3.50291
625.887	3.21611
629.348	3.50642
632.806	3.87325
636.262	4.72887
639.716	4.42453
643.172	5.6114
646.624	5.93486
650.075	5.92113
653.524	6.48495
656.972	7.74549
660.419	7.90769
663.865	10.2515
667.309	12.7565
670.752	14.6496
674.194	16.9973
677.634	18.7693
681.073	21.1266
684.511	23.0936
687.947	23.7733
691.382	25.8545
694.816	27.939
698.247	29.7974
701.678	30.9388
705.108	31.787
708.534	32.3756
711.962	31.6398
715.388	32.1548
718.81	31.5863
722.234	33.4693
725.654	32.2864
729.075	32.012
732.492	31.0136
735.91	31.7936
739.325	31.9618
742.741	32.5304
746.153	34.0786
749.564	36.6627
752.976	39.3201
756.385	41.8012
759.792	44.236
763.2	46.8289
766.604	49.6379
770.008	52.5648
773.41	54.5732
776.811	57.6523
780.21	61.3043
783.608	62.2229
787.005	64.7274
790.401	66.1613
793.795	67.7465
797.188	69.6337
800.58	72.6997
803.971	73.872
807.36	74.3183
810.748	73.754
814.135	72.7804
817.518	71.7201
820.902	71.3056
824.285	69.7545
827.665	70.0869
831.045	69.4244
834.424	69.1896
837.8	67.7136
841.177	65.3795
844.55	62.7286
847.924	61.5954
851.295	57.6471
854.666	54.0265
858.034	51.0998
861.403	48.0738
864.769	45.8566
868.133	44.4304
871.498	41.45
874.86	40.1731
878.221	39.9679
881.58	38.6886
884.938	37.2085
888.297	35.4252
891.653	34.5229
895.007	33.2526
898.36	32.4735
901.712	31.5736
905.063	31.031
908.412	31.2227
911.76	30.7285
915.107	31.6697
918.452	31.6116
921.797	31.2385
925.138	32.0004
928.48	33.6328
931.82	33.9401
935.16	31.4849
938.496	31.4747
941.833	30.9348
945.168	29.8713
948.5	28.4841
951.834	27.0692
955.163	26.4816
958.494	25.3061
961.821	23.7408
965.15	22.8279
968.474	22.835
971.8	22.0252
975.123	21.3543
978.446	20.5181
981.766	19.4927
985.084	18.0333
988.402	17.922
991.72	18.244
995.035	16.7578
998.349	16.4656
1001.66	15.5405
1004.97	14.586
1008.28	15.9729
1011.59	17.9363
1014.9	21.2846
1018.21	24.42
1021.51	27.9562
1024.81	29.6434
1028.12	33.0421
1031.42	34.459
1034.72	35.4551
1038.02	36.1475
1041.31	36.5802
1044.61	37.908
1047.91	37.4952
1051.2	36.783
1054.49	36.7959
1057.78	36.1776
1061.07	34.7635
1064.36	30.9577
1067.65	27.1425
1070.93	23.7263
1074.22	19.82
1077.5	15.895
1080.78	13.6865
1084.06	11.4766
1087.34	11.5584
1090.62	13.253
1093.9	13.5125
1097.17	13.403
1100.45	14.194
1103.72	14.6553
1106.99	14.6625
1110.27	14.0975
1113.53	12.2853
1116.8	11.73
1120.07	11.5718
1123.33	11.515
1126.6	10.3162
1129.86	9.35514
1133.12	8.0438
1136.38	7.82632
1139.64	6.45923
1142.9	5.47632
1146.16	4.40639
1149.41	3.27636
1152.67	3.0414
1155.92	2.79681
1159.17	1.86101
1162.42	2.27531
1165.67	0.785392
1168.92	1.79793
1172.16	1.6929
1175.41	1.75031
1178.65	2.94367
1181.9	3.58761
1185.14	3.00951
1188.38	4.1671
1191.62	5.46903
1194.86	6.31361
1198.09	6.71975
1201.33	7.08734
1204.56	7.75862
1207.8	9.08455
1211.03	11.5383
1214.26	14.6114
1217.49	16.0499
1220.71	18.0439
1223.94	20.1371
1227.16	22.4352
1230.39	25.036
1233.61	28.7195
1236.83	29.6694
1240.05	31.8248
1243.27	33.0765
1246.49	35.7319
1249.71	37.0287
1252.92	36.4517
1256.14	37.6412
1259.35	38.1373
1262.56	37.4783
1265.77	39.7473
1268.98	40.8735
1272.19	41.527
1275.4	40.4991
1278.6	40.7839
1281.81	40.335
1285.01	41.9571
1288.21	43.9602
1291.41	46.1617
1294.61	46.816
1297.81	47.5546
1301.01	48.0153
1304.2	49.7105
1307.4	50.7573
1310.59	52.6746
1313.78	54.0816
1316.97	54.0655
1320.16	55.4307
1323.35	56.1705
1326.54	56.3894
1329.72	55.8519
1332.91	55.595
1336.09	56.1881
1339.27	56.6141
1342.45	56.9507
1345.64	56.1957
1348.81	54.3417
1351.99	51.4355
1355.17	49.6123
1358.34	47.4376
1361.51	45.2447
1364.69	44.2053
1367.86	41.9159
1371.03	39.744
1374.2	36.6783
1377.37	35.7731
1380.53	35.4714
1383.7	33.9523
1386.86	32.1663
1390.02	30.2619
1393.19	28.798
1396.35	29.0921
1399.51	29.9488
1402.66	30.6921
1405.82	31.467
1408.97	33.2517
1412.13	34.4538
1415.28	36.6106
1418.43	37.9654
1421.59	41.1205
1424.73	44.1423
1427.88	46.9093
1431.03	51.2412
1434.18	55.038
1437.32	57.5863
1440.46	60.021
1443.61	61.181
1446.75	62.588
1449.89	62.8963
1453.03	63.3612
1456.16	63.308
1459.3	61.3834
1462.44	58.9841
1465.57	56.5207
1468.7	55.0604
1471.83	53.9335
1474.96	51.2894
1478.09	47.9601
1481.22	44.5606
1484.35	41.1073
1487.47	37.8078
1490.6	34.4575
1493.72	32.9328
1496.84	29.9566
1499.96	28.1526
1503.08	26.7946
1506.2	26.3343
1509.32	24.4158
1512.44	23.2999
1515.55	20.9553
1518.66	20.2529
1521.78	20.2522
1524.89	19.723
1528	19.364
1531.11	18.8387
1534.21	19.7101
1537.32	20.4934
1540.43	21.5402
1543.53	21.3226
1546.63	21.9222
1549.74	23.728
1552.84	23.3592
1555.94	24.2042
1559.03	25.5662
1562.13	24.6402
1565.23	24.6018
1568.32	25.6691
1571.42	26.7569
1574.51	28.6432
1577.6	30.8659
1580.69	33.3069
1583.78	35.9483
1586.87	37.6341
1589.95	39.8431
1593.04	42.2132
1596.12	45.2274
1599.21	46.8663
1602.29	48.3575
1605.37	49.4329
1608.45	50.6612
1611.53	49.09
1614.6	49.2307
1617.68	48.9409
1620.75	49.113
1623.83	50.739
1626.9	52.0541
1629.97	50.7435
1633.04	51.4065
1636.11	51.3969
1639.18	51.6101
1642.25	52.8236
1645.31	54.2117
1648.38	54.4044
1651.44	54.8926
1654.5	56.1356
1657.56	55.6274
1660.62	55.2061
1663.68	54.0161
1666.74	52.8429
1669.8	52.0579
1672.85	51.0127
1675.91	48.2635
1678.96	43.9615
1682.01	40.0452
1685.06	35.1363
1688.11	31.9815
1691.16	29.1093
1694.21	25.5447
1697.25	22.1964
1700.3	19.2225
1703.34	17.5002
1706.39	14.9551
1709.43	12.6754
1712.47	9.82827
1715.51	9.24137
1718.54	8.23492
1721.58	7.65854
1724.62	6.61674
1727.65	7.04694
1730.68	7.88221
1733.72	8.1012
1736.75	9.47003
1739.78	10.3243
1742.81	11.4375
1745.84	11.6106
1748.86	10.6802
1751.89	11.1418
1754.91	10.5785
1757.93	10.7761
1760.96	10.7347
1763.98	10.6163
1767	8.39344
1770.02	7.53456
1773.03	6.85468
1776.05	6.07186
1779.07	5.79384
1782.08	4.53285
1785.09	3.88739
1788.11	2.58061
1791.12	2.4791
1794.13	1.13238
1797.13	1.25704
1800.14	0.995371
1803.15	1.37233
1806.15	1.96237
1809.16	1.86344
1812.16	1.82015
1815.16	2.19753
1818.16	2.01973
1821.16	2.54817
1824.16	2.92068
1827.16	2.94138
1830.16	3.21667
1833.15	2.91821
1836.14	2.91201
1839.14	2.1835
1842.13	2.87238
1845.12	3.41494
1848.11	4.33837
1851.1	4.70207
1854.08	4.85314
1857.07	4.97163
1860.05	5.62609
1863.04	5.39443
1866.02	5.43003
1869	4.85738
1871.98	4.77177
1874.96	3.86861
1877.94	3.88795
1880.92	3.77456
1882.51	3.24106
1885.5	2.56234
1888.48	2.73509
1891.47	2.58499
1894.46	1.79274
1897.44	1.51174
1900.42	1.57883
1903.41	3.04375
1906.39	4.10623
1909.37	5.25827
1912.35	7.85275
1915.32	8.59811
1918.3	9.49669
1921.27	10.8828
1924.25	12.1089
1927.22	13.0804
1930.19	13.8526
1933.17	13.1799
1936.14	12.3449
1939.11	11.7124
1942.07	9.80033
1945.04	8.39872
1948.01	7.39619
1950.97	6.62296
1953.93	4.37546
1956.9	2.02901
1959.86	1.3885
1962.82	0.244165
1965.78	-0.24729
1968.74	-1.28433
1971.69	-0.325313
1974.65	0.403062
1977.6	0.805239
1980.56	1.28378
1983.51	1.16461
1986.46	1.50916
1989.41	2.33485
1992.36	3.53789
1995.31	5.02399
1998.26	5.06683
2001.2	6.25322
2004.15	6.04222
2007.09	6.21107
2010.04	7.73809
2012.98	7.99475
2015.92	8.57619
2018.86	9.63704
2021.8	9.67446
2024.73	9.79451
2027.67	10.2647
2030.61	10.1835
2033.54	10.4454
2036.47	10.8362
2039.4	11.7196
2042.33	12.8117
2045.27	13.8315
2048.19	14.4696
2051.12	15.1917
2054.05	15.6575
2056.97	15.746
2059.9	15.8443
2062.82	17.0131
2065.74	16.7532
2068.67	17.005
2071.59	16.215
2074.51	16.9363
2077.42	18.2437
2080.34	18.6025
2083.26	19.5984
2086.17	20.4645
2089.09	20.7933
2092	20.5892
2094.91	20.7942
2097.82	21.8909
2100.73	21.2805
2103.64	22.1176
2106.55	22.876
2109.45	25.8814
2112.36	26.991
2115.26	27.4756
2118.17	28.4584
2121.07	29.6161
2123.97	30.5232
2126.87	31.0639
2129.77	31.9344
2132.67	34.0044
2135.56	34.596
2138.46	36.405
2141.35	38.3905
2144.25	41.0751
2147.14	44.7865
2150.03	47.3371
2152.92	50.1795
2155.81	53.5483
2158.7	55.6311
2161.59	57.2532
2164.47	58.8809
2167.36	61.2163
2170.24	63.1375
2173.13	64.9982
2176.01	67.0459
2178.89	67
2181.77	66.1592
2184.65	64.6601
2187.53	63.5476
2190.4	62.5904
2193.28	59.9347
2196.16	57.3431
2199.03	54.0691
2201.9	52.1371
2204.77	49.8953
2207.64	48.1516
2210.51	45.4567
2213.38	42.6882
2216.25	40.3548
2219.12	36.9158
2221.98	33.346
2224.85	30.9324
2227.71	29.5407
2230.57	26.5294
2233.43	25.434
2236.29	23.9502
2239.15	23.3125
2242.01	22.7317
2244.87	21.1823
2247.72	20.2442
2250.58	19.0073
2253.43	17.8325
2256.29	16.9125
2259.14	15.1901
2261.99	13.7969
2264.84	13.9819
2267.69	13.8839
2270.53	14.5234
2273.38	14.2579
2276.23	13.3995
2279.07	13.1032
2281.91	12.5121
2284.76	12.3924
2287.6	11.8971
2290.44	10.6567
2293.28	9.41547
2296.12	9.7858
2298.96	10.7941
2301.79	10.8673
2304.63	11.8372
2307.46	12.6802
2310.3	13.3364
2313.13	13.811
2315.96	12.8457
2318.79	11.6948
2321.62	11.7337
2324.45	11.4526
2327.27	10.945
2330.1	10.7498
2332.92	11.0459
2335.75	10.7989
2338.57	8.95028
2341.39	7.83553
2344.21	6.31993
2347.04	5.65114
2349.85	4.75536
2352.67	3.34878
2355.49	3.03078
2358.3	2.38633
2361.12	1.91173
2363.93	2.22867
2366.75	2.97264
2369.56	3.26228
2372.37	3.0285
2375.18	3.56499
2377.99	4.44305
2380.8	4.21206
2383.6	3.11221
2386.41	3.38121
2389.21	4.42966
2392.02	5.07296
2394.82	4.88465
2397.62	4.65616
2400.42	4.05304
2403.22	3.48641
2406.02	2.96085
2408.82	3.30789
2411.62	3.4792
2414.41	3.90916
2417.21	3.72693
2420	4.10827
2422.79	5.03132
2425.59	5.76574
2428.38	6.1818
2431.17	6.17548
2433.95	5.47147
2436.74	6.12303
2439.53	7.31844
2442.31	8.16469
2445.1	7.85386
2447.88	8.19777
2450.67	8.01621
2453.45	8.09441
2456.23	8.89754
2459.01	8.2268
2461.79	8.02638
2464.57	7.3601
2467.34	6.72298
2470.12	6.4788
2472.89	5.98282
2475.67	5.97963
2478.44	4.92821
2481.21	4.27616
2483.98	4.29569
2486.75	4.4379
2489.52	4.29427
2492.29	4.61199
2495.05	4.5949
2497.82	4.66708
2500.58	4.34085
2503.35	4.54588
2506.11	4.84209
2508.87	5.68165
2511.63	5.85584
2514.39	5.42034
2517.15	5.5797
2519.91	6.22753
2522.67	6.28255
2525.42	5.92515
2528.18	6.86255
2530.93	5.98881
2533.69	5.10446
2536.44	5.16052
2539.19	4.00149
2541.94	4.33382
2544.69	4.45656
2547.44	3.80017
2550.18	4.02394
2552.93	3.87856
2555.67	3.32956
2558.42	2.6262
2561.16	3.20914
2563.9	3.10001
2566.64	3.12617
2569.38	3.35896
2572.12	3.86983
2574.86	4.22079
2577.6	4.34983
2580.33	4.51176
2583.07	4.85249
2585.8	5.0056
2588.54	5.59871
2591.27	5.33148
2594	6.07611
2596.73	6.69387
2599.46	4.82009
2602.19	4.52548
2604.92	4.76396
2607.64	4.93469
2610.37	4.50637
2613.09	3.94565
2615.82	3.08416
2618.54	2.54845
2621.26	2.30349
2623.98	1.55057
2626.7	0.936927
2629.42	0.380071
2632.14	-0.0625762
2634.86	-0.583115
2637.57	0.492031
2640.29	0.12717
2643	-0.548097
2645.71	-0.164637
2648.43	-0.452507
2651.14	-0.399653
2653.85	0.313665
2656.56	0.290639
2659.26	1.03957
2661.97	1.00007
2664.68	0.841959
2667.38	1.22415
2670.09	0.948235
2672.79	1.4168
2675.49	2.36962
2678.19	2.30987
2680.89	1.72452
2683.59	3.05705
2686.29	3.12495
2688.99	2.96231
2691.69	3.75407
2694.38	3.31929
2697.08	3.51057
2699.77	3.6764
2702.46	5.11437
2705.15	6.40896
2707.85	5.52375
2710.54	6.70071
2713.22	7.2129
2715.91	7.25653
2718.6	8.0139
2721.29	9.26672
2723.97	9.64203
2726.66	10.1054
2729.34	9.72998
2732.02	9.96462
2734.7	8.96502
2737.38	9.30596
2740.06	10.0943
2742.74	9.87516
2745.42	9.56571
2748.09	9.99332
2750.77	9.17433
2753.45	7.80724
2756.12	6.6829
2758.79	5.47073
2761.46	4.52639
2764.14	3.69007
2766.8	4.26668
2769.47	3.74787
2772.14	4.04382
2774.81	3.93527
2777.48	4.12143
2780.14	3.80326
2782.8	4.53293
2785.47	4.74503
2788.13	4.97845
2790.79	5.04068
2793.45	4.83508
2796.11	5.22481
2798.77	5.66877
2801.43	5.57903
2804.09	6.43274
2806.74	5.87522
2809.4	5.91091
2812.05	5.59854
2814.71	6.48147
2817.36	6.09109
2820.01	7.14429
2822.66	6.84714
2825.31	8.10834
2827.96	10.3758
2830.6	13.176
2833.25	14.9894
2835.9	17.0018
2838.54	19.6495
2841.18	22.7173
2843.83	27.1494
2846.47	32.5664
2849.11	38.1905
2851.75	43.6931
2854.39	49.7539
2857.03	55.3226
2859.66	61.4924
2862.3	66.967
2864.94	72.5942
2867.57	76.4002
2870.2	81.3721
2872.84	85.5195
2875.47	90.016
2878.1	93.2972
2880.73	95.9024
2883.36	98.6989
2885.99	101.717
2888.61	105.189
2891.24	108.782
2893.86	112.757
2896.49	115.296
2899.11	120.519
2901.73	126.528
2904.36	133.261
2906.98	142.535
2909.6	151.778
2912.21	160.618
2914.83	169.135
2917.45	176.968
2920.07	185.03
2922.68	191.495
2925.29	197.25
2927.91	201.043
2930.52	203.911
2933.13	205.991
2935.74	206.417
2938.35	205.253
2940.96	201.557
2943.57	196.914
2946.18	191.511
2948.78	185.094
2951.39	178.774
2953.99	171.788
2956.59	163.989
2959.2	156.512
2961.8	149.873
2964.4	144.297
2967	137.503
2969.6	131.184
2972.19	125.046
2974.79	117.641
2977.39	111.105
2979.98	103.413
2982.58	95.7832
2985.17	88.9105
2987.76	81.9735
2990.35	75.2068
2992.94	68.2386
2995.53	61.4761
2998.12	55.6684
3000.71	49.8416
3003.3	42.9316
3005.88	36.5403
3008.47	31.3276
3011.05	26.3715
3013.64	22.3307
3016.22	18.8455
3018.8	16.3845
3021.38	14.9077
3023.96	13.562
3026.54	12.534
3029.12	11.8167
3031.69	11.2376
3034.27	10.9368
3036.84	10.9989
3039.42	10.944
3041.99	11.012
3044.57	11.9914
3047.14	12.2335
3049.71	12.7808
3052.28	12.9086
3054.85	13.6849
3057.41	13.2908
3059.98	13.0332
3062.55	12.6544
3065.11	11.0005
3067.68	10.0691
3070.24	9.078
3072.8	7.84695
3075.36	5.9494
3077.93	5.22697
3080.49	4.99076
3083.04	3.70301
3085.6	1.9628
3088.16	0.686136
3090.72	0.571967
3093.27	0.788783
3095.83	1.48429
3098.38	1.8947
3100.93	1.83843
3103.49	1.85155
3106.04	2.45722
3108.59	3.10478
3111.14	3.43589
3113.69	3.65603
3116.23	3.89559
3118.78	4.33198
3121.33	4.49258
3123.87	5.223
3126.41	6.43406
3128.96	6.77642
3131.5	7.90906
3134.04	8.63907
3136.58	9.72384
3139.12	11.3052
3141.66	13.5762
3144.2	15.89
3146.74	20.3107
3149.27	27.1563