File: data/Raman/poly_smoothed/Mb_30_27_39_1x_45s_532 nm_x100_100%_600 gr_mm_01.txt
#Acq. time (s)=	45
#Accumulations=	2
#Range (cm-¹)=	200...3150
#Windows=	2
#Auto scanning=	Off
#Autofocus=	Off
#Macrospot=	Off
#AutoExposure=	Off
#Spike filter=	Multiple accum.
#Delay time (s)=	0
#Binning=	1
#Readout mode=	Signal
#DeNoise=	Off
#ICS correction=	On
#Dark correction=	Off
#Inst. Process=	Off
#Detector Gain=	Best Dynamic Range
#Detector ADC=	20 kHz
#Detector temperature (°C)=	-69.85
#Instrument=	LabRAM HR Evol
#Detector=	Synapse
#Objective=	x100
#Grating=	600 gr/mm
#ND Filter=	100%
#Laser (nm)=	532
#Hole=	100.021
#Range=	Auto
#Laser Pol.=	No
#Raman. Pol.=	No
#Laser Pol. (°)=	-0.0007625
#Raman Pol. (°)=	89.9995
#Collection=	Microscope
#StageXY=	Marzhauser
#StageZ=	Marzhauser
#X (µm)=	-6353.6
#Y (µm)=	800.9
#Z (µm)=	-65
#Full time(mm:ss)=	3:08
#Project=
#Sample=
#Site=
#Title=	Mb_30_27_39_2x_45s_532 nm_x100_100%_600 gr_mm
#Remark=
#Date=	13.07.2022 11:39
#Acquired=	13.07.2022 11:39:23
#Base:Fit=	10.08.2022 10:40:03
#Base:Sub=	10.08.2022 10:40:17
#Filter:Polynom=	16.08.2022 10:16:15
#AxisType[0]=Intens
#AxisUnit[0]=Cnt
#AxisType[1]=Spectr
#AxisUnit[1]=1/cm
200.563	16.7715
204.194	12.1251
207.821	10.367
211.449	8.60023
215.074	7.10098
218.699	6.28605
222.321	6.90652
225.941	6.93472
229.562	8.05734
233.18	9.2844
236.796	9.71976
240.411	10.0122
244.026	10.8914
247.638	11.4633
251.248	11.5018
254.857	13.4954
258.465	14.7883
262.071	16.2608
265.678	17.9904
269.282	17.9878
272.884	18.3125
276.484	16.4197
280.084	15.3511
283.682	15.7214
287.276	15.1446
290.871	15.8943
294.465	16.7522
298.057	16.0289
301.648	16.0231
305.237	16.3077
308.823	16.4906
312.41	16.1402
315.995	16.0506
319.579	15.3407
323.16	14.3192
326.741	13.8608
330.321	14.7165
333.897	16.1161
337.474	15.3125
341.048	15.8941
344.622	16.1169
348.192	16.3886
351.764	16.1074
355.332	15.1596
358.901	15.0331
362.466	13.9922
366.03	12.7402
369.594	12.8062
373.155	12.9411
376.715	13.5791
380.273	15.7264
383.832	15.7408
387.388	17.3163
390.942	17.2524
394.495	16.6918
398.047	16.9164
401.597	15.9183
405.145	14.0475
408.693	13.9628
412.239	14.4985
415.783	12.4569
419.327	12.9385
422.869	11.8184
426.409	8.10119
429.948	7.74926
433.486	6.87974
437.022	5.4852
440.558	4.79762
444.089	4.26479
447.622	3.41587
451.153	2.35299
454.682	2.71506
458.208	4.29813
461.735	7.25027
465.259	9.89397
468.783	12.5492
472.306	15.6923
475.825	17.5922
479.346	18.2192
482.862	19.7661
486.38	19.6787
489.894	20.3936
493.407	21.8371
496.92	23.5184
500.43	22.7997
503.939	21.6311
507.448	21.6874
510.954	20.0622
514.459	19.9621
517.962	20.7925
521.466	18.0377
524.966	18.05
528.466	17.6791
531.964	14.7715
535.46	13.1732
538.955	12.4762
542.449	12.7061
545.942	13.5261
549.433	13.4463
552.923	13.2886
556.412	12.5865
559.899	11.3478
563.385	10.7455
566.867	9.83444
570.35	9.32666
573.832	8.14626
577.313	8.06615
580.79	6.30704
584.268	5.66575
587.745	4.17541
591.218	4.12588
594.692	4.08275
598.164	4.28853
601.634	3.89105
605.104	3.69875
608.57	4.9091
612.037	5.53319
615.501	3.5294
618.966	3.07021
622.427	2.59604
625.887	4.26181
629.348	4.564
632.806	6.38397
636.262	7.44478
639.716	8.85399
643.172	10.5323
646.624	12.1417
650.075	12.2223
653.524	12.5058
656.972	13.5288
660.419	13.3655
663.865	14.7552
667.309	15.1169
670.752	15.4778
674.194	17.8005
677.634	19.4876
681.073	20.9445
684.511	23.4874
687.947	24.7586
691.382	26.512
694.816	27.7553
698.247	29.2809
701.678	31.3937
705.108	32.8236
708.534	34.1085
711.962	36.1456
715.388	37.2504
718.81	39.5175
722.234	40.4607
725.654	41.3399
729.075	42.2292
732.492	43.3629
735.91	43.2912
739.325	43.6561
742.741	44.8884
746.153	46.2185
749.564	48.6794
752.976	49.9439
756.385	53.2026
759.792	55.6581
763.2	57.8555
766.604	59.5901
770.008	62.0338
773.41	65.0842
776.811	68.5327
780.21	71.1178
783.608	74.1903
787.005	74.6471
790.401	76.1442
793.795	77.4068
797.188	77.577
800.58	78.1579
803.971	77.679
807.36	77.6439
810.748	77.3542
814.135	77.0588
817.518	75.2656
820.902	73.9063
824.285	73.299
827.665	72.3276
831.045	73.3574
834.424	71.8744
837.8	70.7988
841.177	70.5535
844.55	67.9691
847.924	65.1901
851.295	64.46
854.666	61.9162
858.034	60.4253
861.403	56.6724
864.769	56.2386
868.133	55.3173
871.498	53.1468
874.86	52.2828
878.221	51.3654
881.58	49.0559
884.938	47.8394
888.297	45.4189
891.653	43.0363
895.007	41.6041
898.36	40.3321
901.712	40.3182
905.063	41.0318
908.412	41.6306
911.76	43.8621
915.107	43.3361
918.452	43.4309
921.797	43.4274
925.138	43.0806
928.48	40.6287
931.82	39.0092
935.16	38.2758
938.496	36.6971
941.833	35.7276
945.168	34.5533
948.5	35.4155
951.834	34.4479
955.163	32.9183
958.494	31.8971
961.821	29.9171
965.15	27.813
968.474	25.9998
971.8	24.9321
975.123	24.917
978.446	25.6724
981.766	25.9646
985.084	25.5681
988.402	25.5901
991.72	24.6662
995.035	23.419
998.349	21.2214
1001.66	19.0272
1004.97	18.5023
1008.28	18.1512
1011.59	17.4214
1014.9	18.7956
1018.21	19.9424
1021.51	21.86
1024.81	23.8944
1028.12	26.4164
1031.42	29.3422
1034.72	29.713
1038.02	30.1953
1041.31	31.3794
1044.61	32.2846
1047.91	31.9345
1051.2	30.4677
1054.49	30.303
1057.78	28.192
1061.07	26.3949
1064.36	24.7087
1067.65	20.9792
1070.93	16.9809
1074.22	13.5167
1077.5	10.4618
1080.78	8.41726
1084.06	7.56924
1087.34	8.15081
1090.62	9.13918
1093.9	9.69612
1097.17	13.2777
1100.45	14.0275
1103.72	14.8633
1106.99	16.3084
1110.27	18.8703
1113.53	19.1614
1116.8	19.2479
1120.07	19.7229
1123.33	18.9426
1126.6	19.0833
1129.86	18.5601
1133.12	17.1251
1136.38	17.2813
1139.64	15.6877
1142.9	14.6286
1146.16	12.0223
1149.41	9.91768
1152.67	9.13488
1155.92	8.05165
1159.17	5.90518
1162.42	5.44433
1165.67	4.46648
1168.92	3.34133
1172.16	2.66056
1175.41	2.20704
1178.65	1.90701
1181.9	0.379144
1185.14	0.690278
1188.38	0.67354
1191.62	-0.0790283
1194.86	-0.34919
1198.09	-0.10532
1201.33	2.3231
1204.56	4.78704
1207.8	6.85172
1211.03	9.06601
1214.26	11.9313
1217.49	14.4083
1220.71	17.1063
1223.94	19.2988
1227.16	23.2225
1230.39	25.0333
1233.61	28.1734
1236.83	30.5246
1240.05	33.9485
1243.27	35.8593
1246.49	38.1082
1249.71	39.8785
1252.92	41.4012
1256.14	41.5165
1259.35	41.7131
1262.56	40.6725
1265.77	40.3406
1268.98	40.9746
1272.19	40.6576
1275.4	41.7367
1278.6	42.2949
1281.81	44.0379
1285.01	44.7463
1288.21	45.8509
1291.41	46.4858
1294.61	48.2447
1297.81	49.7433
1301.01	50.2516
1304.2	52.7898
1307.4	54.0929
1310.59	54.9811
1313.78	56.4216
1316.97	57.7099
1320.16	58.5399
1323.35	57.7938
1326.54	57.8663
1329.72	56.0896
1332.91	54.4888
1336.09	52.9426
1339.27	51.6639
1342.45	51.1997
1345.64	50.0274
1348.81	47.215
1351.99	46.2595
1355.17	43.6129
1358.34	41.2616
1361.51	40.0513
1364.69	37.5287
1367.86	34.7323
1371.03	33.4798
1374.2	31.8513
1377.37	30.6876
1380.53	30.5383
1383.7	28.3452
1386.86	27.7584
1390.02	26.6857
1393.19	25.7044
1396.35	25.9142
1399.51	26.2817
1402.66	25.3602
1405.82	26.4679
1408.97	29.0575
1412.13	31.1228
1415.28	34.9275
1418.43	37.6947
1421.59	41.8634
1424.73	44.903
1427.88	48.6374
1431.03	51.6654
1434.18	53.8784
1437.32	55.8718
1440.46	58.1586
1443.61	59.7474
1446.75	60.1852
1449.89	60.5206
1453.03	61.4929
1456.16	60.7432
1459.3	59.4386
1462.44	58.8293
1465.57	58.4068
1468.7	56.1901
1471.83	53.7396
1474.96	50.7669
1478.09	46.2794
1481.22	43.9686
1484.35	42.0131
1487.47	38.2804
1490.6	36.5583
1493.72	34.2717
1496.84	31.1291
1499.96	29.6601
1503.08	27.2162
1506.2	25.5556
1509.32	22.4026
1512.44	20.6154
1515.55	17.9372
1518.66	16.3991
1521.78	14.7644
1524.89	13.0644
1528	13.4806
1531.11	13.881
1534.21	13.1522
1537.32	15.0117
1540.43	15.7422
1543.53	16.8411
1546.63	19.2505
1549.74	19.3579
1552.84	19.3952
1555.94	20.832
1559.03	21.3193
1562.13	23.4793
1565.23	26.4001
1568.32	28.9691
1571.42	29.4779
1574.51	31.6655
1577.6	33.4525
1580.69	35.6496
1583.78	36.1235
1586.87	36.7514
1589.95	38.2922
1593.04	38.8115
1596.12	39.2907
1599.21	39.425
1602.29	39.1276
1605.37	38.3742
1608.45	36.6379
1611.53	37.384
1614.6	37.8497
1617.68	39.0971
1620.75	39.4116
1623.83	38.8778
1626.9	38.9853
1629.97	39.6824
1633.04	42.8146
1636.11	45.4995
1639.18	48.2756
1642.25	48.9855
1645.31	50.4186
1648.38	51.8366
1651.44	53.0802
1654.5	53.4779
1657.56	54.2354
1660.62	53.7049
1663.68	55.0971
1666.74	53.2683
1669.8	49.8717
1672.85	47.8481
1675.91	45.3058
1678.96	40.9346
1682.01	37.9388
1685.06	35.3126
1688.11	32.5526
1691.16	29.2801
1694.21	25.6089
1697.25	23.2248
1700.3	21.3723
1703.34	20.1669
1706.39	19.5581
1709.43	17.121
1712.47	15.3112
1715.51	14.7983
1718.54	13.639
1721.58	13.026
1724.62	10.4897
1727.65	9.09466
1730.68	8.99895
1733.72	8.70779
1736.75	7.32293
1739.78	6.35952
1742.81	4.52219
1745.84	3.91684
1748.86	4.21734
1751.89	3.95312
1754.91	4.08293
1757.93	4.42343
1760.96	4.29502
1763.98	4.09472
1767	4.10524
1770.02	4.28819
1773.03	5.14022
1776.05	5.92174
1779.07	5.97306
1782.08	6.3534
1785.09	6.22163
1788.11	6.98863
1791.12	6.53596
1794.13	6.599
1797.13	6.45015
1800.14	6.24581
1803.15	5.71936
1806.15	6.10598
1809.16	5.65157
1812.16	5.59816
1815.16	5.3558
1818.16	5.26659
1821.16	5.4301
1824.16	5.67758
1827.16	4.6906
1830.16	4.94733
1833.15	3.5433
1836.14	2.36542
1839.14	2.10908
1842.13	2.8208
1845.12	1.76227
1848.11	1.61343
1851.1	2.24329
1854.08	1.51023
1857.07	1.08913
1860.05	1.53961
1863.04	1.20294
1866.02	0.406045
1869	0.326665
1871.98	0.258682
1874.96	1.17905
1877.94	1.71754
1880.92	2.86415
1882.51	3.02275
1885.5	4.01079
1888.48	4.64129
1891.47	5.12321
1894.46	4.66044
1897.44	5.55663
1900.42	6.04083
1903.41	5.41358
1906.39	5.29568
1909.37	6.60864
1912.35	7.98224
1915.32	8.21263
1918.3	8.01715
1921.27	8.66695
1924.25	9.38327
1927.22	9.89229
1930.19	8.67449
1933.17	7.73888
1936.14	6.26536
1939.11	6.48736
1942.07	7.57707
1945.04	8.46062
1948.01	8.47745
1950.97	9.02859
1953.93	9.58741
1956.9	9.25092
1959.86	10.0461
1962.82	9.38587
1965.78	9.34248
1968.74	10.3955
1971.69	9.64319
1974.65	9.63267
1977.6	8.91584
1980.56	7.93502
1983.51	8.29904
1986.46	7.65132
1989.41	7.48321
1992.36	8.32249
1995.31	7.37717
1998.26	7.36925
2001.2	5.35874
2004.15	4.73551
2007.09	3.65792
2010.04	4.62513
2012.98	5.01759
2015.92	5.05055
2018.86	4.35848
2021.8	3.83577
2024.73	4.10006
2027.67	5.3545
2030.61	6.13837
2033.54	6.72445
2036.47	7.35504
2039.4	8.74441
2042.33	8.97941
2045.27	8.77987
2048.19	9.49082
2051.12	9.9464
2054.05	10.4325
2056.97	11.7143
2059.9	11.6873
2062.82	12.8681
2065.74	13.9289
2068.67	13.6292
2071.59	14.4003
2074.51	15.5462
2077.42	16.5015
2080.34	17.1935
2083.26	17.145
2086.17	17.94
2089.09	19.6499
2092	21.4877
2094.91	22.4667
2097.82	24.4724
2100.73	25.3391
2103.64	26.5416
2106.55	26.0533
2109.45	27.0268
2112.36	28.7975
2115.26	29.0416
2118.17	31.0833
2121.07	31.7172
2123.97	33.6105
2126.87	36.0053
2129.77	38.3224
2132.67	41.2383
2135.56	43.8721
2138.46	46.5452
2141.35	48.476
2144.25	51.658
2147.14	55.8543
2150.03	58.4733
2152.92	61.7773
2155.81	65.0894
2158.7	69.1925
2161.59	69.8874
2164.47	71.9473
2167.36	72.7871
2170.24	74.2847
2173.13	74.7977
2176.01	74.4064
2178.89	73.2403
2181.77	73.6267
2184.65	73.0928
2187.53	71.4411
2190.4	69.2778
2193.28	67.1529
2196.16	65.7403
2199.03	63.0324
2201.9	59.4503
2204.77	55.8065
2207.64	52.9024
2210.51	48.9651
2213.38	47.3104
2216.25	44.2212
2219.12	42.1529
2221.98	39.2844
2224.85	35.8773
2227.71	33.5604
2230.57	30.8663
2233.43	28.6316
2236.29	27.6023
2239.15	27.299
2242.01	26.3132
2244.87	25.8615
2247.72	25.0981
2250.58	24.9295
2253.43	24.1808
2256.29	23.6652
2259.14	22.2304
2261.99	21.3544
2264.84	18.899
2267.69	18.2893
2270.53	17.6131
2273.38	16.7604
2276.23	16.0947
2279.07	15.5949
2281.91	15.3841
2284.76	14.5247
2287.6	13.2285
2290.44	13.0318
2293.28	10.6839
2296.12	10.421
2298.96	11.3185
2301.79	12.3783
2304.63	13.7881
2307.46	15.6456
2310.3	14.9827
2313.13	15.2938
2315.96	14.8043
2318.79	13.8287
2321.62	13.5234
2324.45	12.957
2327.27	10.7246
2330.1	9.72392
2332.92	8.48417
2335.75	7.27831
2338.57	7.19875
2341.39	5.69329
2344.21	5.20588
2347.04	4.7804
2349.85	3.90485
2352.67	2.96467
2355.49	2.79923
2358.3	2.75559
2361.12	1.65293
2363.93	1.47501
2366.75	2.99029
2369.56	3.81013
2372.37	4.24056
2375.18	4.90826
2377.99	3.67629
2380.8	2.97565
2383.6	3.89702
2386.41	3.25327
2389.21	2.91584
2392.02	2.42862
2394.82	2.07919
2397.62	2.67698
2400.42	3.37066
2403.22	3.4423
2406.02	3.34774
2408.82	3.5561
2411.62	3.25854
2414.41	2.63672
2417.21	2.11542
2420	2.40175
2422.79	3.43905
2425.59	3.46699
2428.38	2.72519
2431.17	3.01854
2433.95	4.16484
2436.74	4.36794
2439.53	4.52271
2442.31	4.81044
2445.1	4.36486
2447.88	4.37018
2450.67	3.82538
2453.45	2.96987
2456.23	2.95833
2459.01	3.85458
2461.79	4.99133
2464.57	6.02022
2467.34	6.34933
2470.12	5.61424
2472.89	6.04223
2475.67	4.65618
2478.44	4.71854
2481.21	4.59455
2483.98	3.91541
2486.75	4.34421
2489.52	4.55158
2492.29	4.78926
2495.05	4.03972
2497.82	4.18122
2500.58	4.1615
2503.35	2.86415
2506.11	1.25726
2508.87	1.22865
2511.63	0.983308
2514.39	0.607659
2517.15	0.325097
2519.91	-0.31805
2522.67	0.301091
2525.42	1.50466
2528.18	1.96815
2530.93	3.28714
2533.69	4.1549
2536.44	3.1623
2539.19	4.00898
2541.94	3.58745
2544.69	4.32262
2547.44	4.16292
2550.18	4.73171
2552.93	4.62679
2555.67	4.75266
2558.42	4.63414
2561.16	4.63942
2563.9	3.62692
2566.64	3.54712
2569.38	2.08167
2572.12	1.85677
2574.86	1.47143
2577.6	2.69542
2580.33	3.23915
2583.07	3.64273
2585.8	2.96253
2588.54	3.90491
2591.27	5.13462
2594	5.58341
2596.73	6.30101
2599.46	6.15525
2602.19	6.63031
2604.92	6.39303
2607.64	5.96057
2610.37	5.32331
2613.09	4.67695
2615.82	4.16579
2618.54	4.89783
2621.26	4.82555
2623.98	4.61831
2626.7	5.05474
2629.42	4.03438
2632.14	4.05577
2634.86	4.24815
2637.57	4.61682
2640.29	5.24637
2643	6.12658
2645.71	7.64669
2648.43	7.6711
2651.14	8.67436
2653.85	9.39929
2656.56	9.42191
2659.26	10.0281
2661.97	9.36567
2664.68	9.69006
2667.38	10.3256
2670.09	8.89065
2672.79	8.59562
2675.49	8.24738
2678.19	8.10891
2680.89	7.83059
2683.59	7.73537
2686.29	7.591
2688.99	7.24833
2691.69	7.61778
2694.38	7.16926
2697.08	6.51862
2699.77	7.16647
2702.46	7.27937
2705.15	8.28635
2707.85	8.80187
2710.54	9.42363
2713.22	9.38596
2715.91	9.82723
2718.6	10.5279
2721.29	10.2101
2723.97	9.98377
2726.66	10.81
2729.34	11.4008
2732.02	11.2382
2734.7	10.6174
2737.38	10.5779
2740.06	10.8389
2742.74	10.5796
2745.42	9.84156
2748.09	9.67682
2750.77	8.02245
2753.45	6.98322
2756.12	6.15661
2758.79	6.06627
2761.46	5.49344
2764.14	5.0658
2766.8	5.93194
2769.47	6.76425
2772.14	7.47284
2774.81	8.24581
2777.48	8.23335
2780.14	7.78086
2782.8	7.56455
2785.47	7.56493
2788.13	6.56064
2790.79	6.63918
2793.45	5.93759
2796.11	5.22622
2798.77	5.01683
2801.43	4.55817
2804.09	4.64898
2806.74	4.59743
2809.4	3.60547
2812.05	3.02046
2814.71	3.96516
2817.36	4.32625
2820.01	6.77213
2822.66	9.68938
2825.31	13.5493
2827.96	18.421
2830.6	23.6275
2833.25	28.9435
2835.9	34.5459
2838.54	40.1684
2841.18	45.292
2843.83	50.4551
2846.47	56.1619
2849.11	62.8919
2851.75	69.4186
2854.39	76.0778
2857.03	83.1716
2859.66	90.4666
2862.3	97.3416
2864.94	104.084
2867.57	108.14
2870.2	112.408
2872.84	115.668
2875.47	119.103
2878.1	122.582
2880.73	125.997
2883.36	128.217
2885.99	132.428
2888.61	135.725
2891.24	138.685
2893.86	141.981
2896.49	146.232
2899.11	150.865
2901.73	156.056
2904.36	161.517
2906.98	168.27
2909.6	175.477
2912.21	183.563
2914.83	191.652
2917.45	199.102
2920.07	206.683
2922.68	214.335
2925.29	219.082
2927.91	222.395
2930.52	224.424
2933.13	225.01
2935.74	223.613
2938.35	220.484
2940.96	216.942
2943.57	210.923
2946.18	204.226
2948.78	197.567
2951.39	189.671
2953.99	180.745
2956.59	172.629
2959.2	164.404
2961.8	156.82
2964.4	148.603
2967	140.932
2969.6	133.417
2972.19	125.877
2974.79	118.767
2977.39	111.077
2979.98	103.514
2982.58	96.854
2985.17	90.3183
2987.76	83.1443
2990.35	76.6534
2992.94	70.1107
2995.53	63.2192
2998.12	55.741
3000.71	49.7679
3003.3	44.3722
3005.88	38.4487
3008.47	32.9006
3011.05	27.7648
3013.64	24.7314
3016.22	21.9318
3018.8	19.5949
3021.38	17.5498
3023.96	15.7125
3026.54	14.0535
3029.12	12.8719
3031.69	11.8806
3034.27	10.456
3036.84	10.1403
3039.42	10.3598
3041.99	10.9211
3044.57	11.3704
3047.14	12.1758
3049.71	11.4816
3052.28	11.5813
3054.85	10.4097
3057.41	10.0845
3059.98	9.43979
3062.55	8.98402
3065.11	7.74287
3067.68	7.12805
3070.24	5.8574
3072.8	5.0369
3075.36	4.37359
3077.93	4.12569
3080.49	3.61285
3083.04	2.40464
3085.6	1.52194
3088.16	0.627331
3090.72	0.856479
3093.27	-0.562217
3095.83	-0.571356
3098.38	0.0187343
3100.93	0.423827
3103.49	1.09343
3106.04	0.41686
3108.59	0.0842599
3111.14	0.244883
3113.69	0.195964
3116.23	-0.416482
3118.78	-0.272316
3121.33	-0.0967278
3123.87	-0.457352
3126.41	-0.0890046
3128.96	0.243238
3131.5	0.298045
3134.04	0.122382
3136.58	0.58784
3139.12	0.320357
3141.66	0.779781
3144.2	1.20499
3146.74	1.98801
3149.27	4.12749