File: data/Raman/poly_smoothed/Mb_30_27_10_1x_45s_532 nm_x100_100%_600 gr_mm_01.txt
#Acq. time (s)=	45
#Accumulations=	2
#Range (cm-¹)=	200...3150
#Windows=	2
#Auto scanning=	Off
#Autofocus=	Off
#Macrospot=	Off
#AutoExposure=	Off
#Spike filter=	Multiple accum.
#Delay time (s)=	0
#Binning=	1
#Readout mode=	Signal
#DeNoise=	Off
#ICS correction=	On
#Dark correction=	Off
#Inst. Process=	Off
#Detector Gain=	Best Dynamic Range
#Detector ADC=	20 kHz
#Detector temperature (°C)=	-69.85
#Instrument=	LabRAM HR Evol
#Detector=	Synapse
#Objective=	x100
#Grating=	600 gr/mm
#ND Filter=	100%
#Laser (nm)=	532
#Hole=	100.021
#Range=	Auto
#Laser Pol.=	No
#Raman. Pol.=	No
#Laser Pol. (°)=	-0.0007625
#Raman Pol. (°)=	89.9995
#Collection=	Microscope
#StageXY=	Marzhauser
#StageZ=	Marzhauser
#X (µm)=	-1255.6
#Y (µm)=	1610.7
#Z (µm)=	-6.3
#Full time(mm:ss)=	3:18
#Project=
#Sample=
#Site=
#Title=	Mb_30_27_10_2x_45s_532 nm_x100_100%_600 gr_mm
#Remark=
#Date=	12.07.2022 16:42
#Acquired=	12.07.2022 16:42:41
#Base:Fit=	10.08.2022 10:39:47
#Base:Sub=	10.08.2022 10:39:55
#Base:Fit=	10.08.2022 10:40:03
#Base:Sub=	10.08.2022 10:40:17
#Filter:Polynom=	16.08.2022 10:16:15
#AxisType[0]=Intens
#AxisUnit[0]=Cnt
#AxisType[1]=Spectr
#AxisUnit[1]=1/cm
200.413	13.0751
204.042	12.6765
207.671	9.72377
211.297	8.09052
214.924	6.95959
218.547	5.8426
222.169	5.38217
225.792	2.92242
229.411	1.22664
233.028	1.38759
236.647	2.42409
240.261	1.57588
243.875	1.3772
247.487	1.67155
251.099	1.96048
254.708	2.57673
258.316	2.99577
261.922	3.45776
265.527	4.06855
269.131	5.38774
272.733	4.87368
276.334	4.95074
279.933	6.00951
283.531	7.87742
287.128	10.0093
290.723	10.2825
294.316	11.4491
297.909	13.2367
301.498	14.488
305.087	14.8649
308.675	14.1469
312.262	14.3886
315.845	14.9829
319.429	17.0164
323.012	17.6007
326.591	16.9324
330.171	16.1072
333.749	15.3835
337.324	14.8765
340.9	13.4058
344.472	12.6483
348.045	10.9883
351.614	11.2113
355.185	9.82101
358.751	8.2235
362.317	8.74994
365.883	9.36529
369.445	9.18708
373.006	10.6815
376.568	9.22618
380.126	10.147
383.683	11.1002
387.239	10.9184
390.793	9.68448
394.348	10.0093
397.9	9.70832
401.45	9.14929
404.999	8.72165
408.546	8.02932
412.092	7.60111
415.637	7.04998
419.18	6.32763
422.722	5.50867
426.263	4.11551
429.802	3.19732
433.338	2.60528
436.874	2.56376
440.41	4.10494
443.943	3.91488
447.476	3.77219
451.005	4.3418
454.534	4.68415
458.063	7.21914
461.588	9.33702
465.113	11.3745
468.638	12.0094
472.158	11.6306
475.68	11.0508
479.198	11.4493
482.717	11.622
486.233	10.7088
489.747	10.7575
493.261	12.2257
496.773	11.6694
500.285	11.4151
503.794	12.2843
507.301	12.109
510.807	10.6538
514.314	10.2451
517.817	9.86721
521.319	9.61243
524.82	10.4629
528.319	9.88397
531.817	8.7443
535.316	8.87641
538.811	10.3168
542.305	11.2745
545.798	10.8526
549.289	10.5714
552.777	9.64292
556.265	7.98762
559.753	8.86607
563.239	7.74091
566.723	7.77457
570.207	6.17979
573.688	5.67144
577.167	5.64217
580.646	3.58474
584.124	2.84876
587.599	4.03189
591.074	3.7719
594.548	3.55536
598.019	1.17666
601.49	1.82537
604.958	1.97781
608.427	0.632936
611.892	1.38288
615.358	3.31775
618.821	4.28292
622.282	5.87376
625.744	6.08885
629.203	7.33807
632.661	9.257
636.119	9.26936
639.574	9.90208
643.027	12.1039
646.479	14.2876
649.932	15.8304
653.382	18.4725
656.83	18.1052
660.277	19.274
663.722	19.5741
667.167	19.5712
670.61	21.2902
674.051	21.9258
677.492	22.4097
680.931	22.3149
684.369	22.9599
687.803	23.6007
691.238	25.1926
694.672	26.7084
698.105	28.5852
701.536	30.0717
704.964	32.064
708.393	33.4528
711.82	35.0722
715.244	35.9592
718.669	36.0926
722.09	37.2434
725.512	40.5349
728.933	41.9714
732.351	42.4275
735.767	44.0067
739.184	44.934
742.598	44.6489
746.012	47.2859
749.423	50.0265
752.833	53.4734
756.244	56.7205
759.651	58.5752
763.057	61.4947
766.462	63.2412
769.865	65.1947
773.269	66.6941
776.67	68.4084
780.069	70.9041
783.468	73.9056
786.865	75.5518
790.26	77.3191
793.655	78.5746
797.048	79.9077
800.44	79.317
803.83	79.5325
807.218	79.0035
810.606	78.1252
813.993	75.9459
817.378	74.9596
820.762	75.5506
824.143	74.7907
827.525	74.0146
830.905	73.9073
834.282	72.1265
837.66	68.5392
841.035	65.3433
844.41	62.4395
847.782	60.6115
851.155	58.3598
854.525	56.9635
857.895	54.7142
861.262	53.2604
864.628	52.0645
867.994	51.0589
871.357	50.0427
874.719	49.2114
878.082	49.0435
881.441	48.3263
884.799	46.9725
888.156	47.7594
891.512	47.9447
894.866	48.1714
898.22	47.9034
901.573	48.9422
904.924	48.4209
908.271	49.0846
911.62	48.4101
914.966	46.9274
918.312	45.2075
921.656	44.7139
925	44.3014
928.341	44.5357
931.68	44.0801
935.019	43.0312
938.358	41.5221
941.694	39.7821
945.028	38.9982
948.362	38.6996
951.694	37.8677
955.026	36.6042
958.356	34.8022
961.684	33.0316
965.012	32.3314
968.337	31.1389
971.661	30.3899
974.985	28.4194
978.306	27.9989
981.626	27.7535
984.947	26.4014
988.264	25.9057
991.581	24.558
994.896	22.5912
998.212	21.9231
1001.52	20.2832
1004.84	20.1173
1008.15	20.9763
1011.45	22.6912
1014.76	26.4701
1018.07	28.3229
1021.37	30.8681
1024.68	34.3702
1027.98	35.1159
1031.28	36.9324
1034.58	38.6757
1037.88	39.1385
1041.18	38.601
1044.47	38.8504
1047.77	38.579
1051.06	37.1623
1054.35	35.6368
1057.64	33.9254
1060.94	32.9845
1064.22	30.3312
1067.51	27.0228
1070.8	22.7099
1074.08	17.7335
1077.36	16.2232
1080.65	13.0481
1083.93	10.4526
1087.21	12.0158
1090.49	11.7779
1093.76	11.8705
1097.04	12.1296
1100.31	10.9606
1103.59	9.37139
1106.86	9.44205
1110.13	8.63171
1113.4	9.09506
1116.66	9.16821
1119.93	9.21105
1123.2	9.46988
1126.46	9.16082
1129.72	8.40481
1132.99	8.72787
1136.25	8.3548
1139.51	8.26513
1142.77	7.92386
1146.02	6.46175
1149.28	5.20706
1152.53	4.75712
1155.78	4.26795
1159.04	3.36329
1162.29	3.80342
1165.54	3.63059
1168.78	3.66862
1172.03	3.44002
1175.27	3.82756
1178.52	3.3775
1181.76	2.85534
1185	4.13142
1188.24	4.84444
1191.48	5.41672
1194.72	5.70593
1197.96	6.33288
1201.19	5.43503
1204.43	4.58674
1207.66	3.83403
1210.89	4.84761
1214.12	6.13951
1217.35	5.55221
1220.58	5.12239
1223.81	5.41183
1227.03	4.87068
1230.26	5.23306
1233.48	6.92382
1236.7	7.88732
1239.92	9.5262
1243.14	10.7075
1246.36	13.6654
1249.57	15.8746
1252.79	18.0732
1256	20.0355
1259.22	21.6804
1262.43	24.3084
1265.64	26.0153
1268.85	26.587
1272.06	27.0097
1275.26	25.6736
1278.47	26.1368
1281.67	27.3664
1284.88	27.5665
1288.08	28.3185
1291.28	26.0891
1294.48	25.7558
1297.68	24.3174
1300.87	24.2193
1304.07	22.8595
1307.26	23.8299
1310.46	24.199
1313.65	25.4824
1316.84	25.6686
1320.03	26.2358
1323.22	26.1348
1326.4	25.4039
1329.59	24.7484
1332.78	26.4497
1335.96	26.392
1339.14	28.964
1342.32	27.1676
1345.5	26.2887
1348.68	24.4454
1351.86	23.2776
1355.03	22.7623
1358.21	22.4729
1361.38	21.7965
1364.56	17.9361
1367.73	16.5001
1370.9	14.9087
1374.07	15.7778
1377.23	15.4119
1380.4	15.8071
1383.57	16.2935
1386.73	16.7894
1389.89	17.9258
1393.05	16.8763
1396.21	17.1099
1399.37	17.7805
1402.53	17.1076
1405.69	19.0554
1408.84	20.7471
1412	21.7985
1415.15	22.5758
1418.3	22.7614
1421.45	23.8385
1424.6	24.5335
1427.75	25.8042
1430.9	28.9486
1434.04	29.5422
1437.19	31.3491
1440.33	33.2009
1443.47	35.5944
1446.62	36.7926
1449.76	37.8641
1452.9	39.708
1456.03	40.323
1459.17	41.9654
1462.3	43.6187
1465.44	43.9424
1468.57	43.2985
1471.7	42.6191
1474.83	41.7503
1477.96	39.608
1481.09	38.3732
1484.22	35.7311
1487.34	32.7278
1490.47	31.6047
1493.59	30.0757
1496.71	29.1221
1499.83	27.567
1502.95	25.7356
1506.07	22.8649
1509.19	21.8879
1512.3	19.5538
1515.42	18.1614
1518.53	16.5886
1521.65	16.0357
1524.76	16.5043
1527.87	15.376
1530.98	16.8582
1534.08	16.7794
1537.19	16.9339
1540.3	16.8861
1543.4	17.0233
1546.5	17.9294
1549.61	18.3294
1552.71	18.167
1555.81	18.061
1558.9	18.4448
1562	18.943
1565.1	20.6414
1568.19	22.1784
1571.29	22.4203
1574.38	22.7892
1577.47	23.6734
1580.56	24.7317
1583.65	26.7283
1586.74	27.3738
1589.82	28.2431
1592.91	30.0624
1595.99	30.6102
1599.08	31.2229
1602.16	31.9128
1605.24	31.3186
1608.32	31.7285
1611.4	32.6861
1614.48	32.5112
1617.55	32.8205
1620.63	33.2629
1623.7	32.5583
1626.77	33.7226
1629.84	34.7113
1632.92	33.861
1635.98	34.2729
1639.05	34.0774
1642.12	33.8383
1645.19	34.6998
1648.25	35.3013
1651.31	35.7036
1654.38	37.0094
1657.44	36.5178
1660.5	35.875
1663.56	35.0208
1666.61	33.3629
1669.67	31.6456
1672.72	30.0095
1675.78	27.367
1678.83	26.0893
1681.88	23.7243
1684.93	23.6235
1687.98	22.0172
1691.03	18.7913
1694.08	18.3209
1697.13	16.5789
1700.17	15.0861
1703.21	15.1886
1706.26	12.4567
1709.3	10.5722
1712.34	9.3846
1715.38	8.07659
1718.42	7.3136
1721.45	6.43519
1724.49	5.8408
1727.52	5.56669
1730.56	4.42894
1733.59	3.43908
1736.62	4.15944
1739.65	3.6505
1742.68	4.03765
1745.71	3.81496
1748.74	3.60832
1751.76	3.81494
1754.79	4.40473
1757.81	4.68864
1760.83	4.72367
1763.85	4.63729
1766.87	4.78798
1769.89	5.18687
1772.91	5.4809
1775.93	5.38574
1778.94	5.42472
1781.95	4.55261
1784.97	3.69641
1787.98	3.41072
1790.99	1.87487
1794	1.57399
1797.01	1.91235
1800.02	2.45318
1803.02	2.2871
1806.03	3.87608
1809.03	3.94419
1812.03	5.08896
1815.04	5.39467
1818.04	5.64847
1821.04	5.66895
1824.04	5.31738
1827.03	6.12671
1830.03	6.19014
1833.02	5.4217
1836.02	5.16709
1839.01	6.01652
1842	6.00818
1844.99	5.97126
1847.98	5.49815
1850.97	5.44654
1853.96	6.10953
1856.95	6.48953
1859.93	5.89899
1862.91	5.79167
1865.9	4.87977
1868.88	5.59121
1871.86	6.32851
1874.84	6.09881
1877.82	6.0936
1880.79	6.36343
1882.53	5.93949
1885.52	6.45173
1888.51	6.68724
1891.49	6.7045
1894.48	6.05644
1897.46	5.96169
1900.45	5.87639
1903.43	5.45408
1906.41	6.43828
1909.39	6.81192
1912.37	7.67892
1915.35	7.95257
1918.32	8.62021
1921.3	9.64935
1924.27	11.2751
1927.25	12.3506
1930.22	11.8045
1933.19	11.4361
1936.16	10.4034
1939.13	8.99961
1942.1	8.53792
1945.06	7.51505
1948.03	7.25315
1950.99	6.50834
1953.96	5.41365
1956.92	5.25706
1959.88	5.78348
1962.84	5.07404
1965.8	5.80845
1968.76	4.7798
1971.72	4.6591
1974.67	6.2678
1977.63	7.52288
1980.58	8.19678
1983.53	9.64562
1986.48	10.4098
1989.43	11.8539
1992.39	13.0554
1995.33	13.2187
1998.28	13.5241
2001.23	12.8188
2004.17	12.0014
2007.11	11.2726
2010.06	9.91849
2013	9.85708
2015.94	9.81058
2018.88	9.31767
2021.82	9.36054
2024.76	9.85789
2027.69	10.5027
2030.63	10.5771
2033.56	10.5339
2036.5	10.1282
2039.43	10.6792
2042.36	11.0724
2045.29	13.0255
2048.22	13.713
2051.14	13.2814
2054.07	13.9681
2057	14.3308
2059.92	14.3945
2062.85	15.2957
2065.77	14.5482
2068.69	13.505
2071.61	13.3707
2074.53	14.0963
2077.45	13.6763
2080.36	13.7781
2083.28	12.8068
2086.19	13.071
2089.11	12.1756
2092.02	13.0985
2094.93	14.6175
2097.84	14.6137
2100.75	13.2124
2103.66	12.9287
2106.57	12.8401
2109.48	13.5605
2112.38	14.2995
2115.29	15.8728
2118.19	16.3466
2121.09	17.1459
2123.99	18.8806
2126.89	20.1593
2129.79	20.3486
2132.69	21.7714
2135.59	25.1627
2138.48	26.0988
2141.38	28.6663
2144.27	31.4699
2147.16	33.6376
2150.06	35.0028
2152.95	36.4124
2155.83	37.7476
2158.72	39.3219
2161.61	40.325
2164.5	42.1732
2167.38	41.5389
2170.27	41.5688
2173.15	40.5007
2176.03	40.057
2178.91	39.683
2181.79	39.31
2184.67	37.8544
2187.55	37.5615
2190.43	35.9492
2193.3	34.5513
2196.18	33.1783
2199.05	31.5806
2201.92	31.0183
2204.8	31.5177
2207.67	30.4911
2210.54	30.4591
2213.4	29.3989
2216.27	28.7666
2219.14	27.4126
2222	26.9915
2224.87	26.2566
2227.73	25.1281
2230.59	23.8932
2233.46	22.968
2236.32	21.2231
2239.18	19.2331
2242.03	19.1105
2244.89	18.129
2247.75	17.3861
2250.6	16.2468
2253.45	16.2406
2256.31	15.8015
2259.16	15.7722
2262.01	14.6037
2264.86	13.7764
2267.71	14.2092
2270.56	14.9503
2273.4	15.1729
2276.25	14.817
2279.09	15.5484
2281.94	16.1956
2284.78	16.0929
2287.62	16.0031
2290.46	15.194
2293.3	13.1245
2296.14	11.9659
2298.98	10.951
2301.81	10.1825
2304.65	10.0008
2307.48	9.73379
2310.32	9.04371
2313.15	8.87559
2315.98	8.50511
2318.81	8.62999
2321.64	8.99143
2324.47	9.39962
2327.3	9.95921
2330.12	9.53313
2332.95	10.261
2335.77	11.214
2338.59	11.3445
2341.42	11.9147
2344.24	11.7921
2347.06	11.2905
2349.88	11.1894
2352.69	11.2391
2355.51	9.28344
2358.33	8.06244
2361.14	6.87324
2363.96	5.60207
2366.77	5.52376
2369.58	4.78612
2372.39	5.20444
2375.2	4.17701
2378.01	2.89847
2380.82	2.55898
2383.63	2.40912
2386.43	2.23276
2389.24	3.51203
2392.04	4.61401
2394.84	5.2022
2397.64	5.71979
2400.45	6.17733
2403.25	7.30482
2406.04	7.91087
2408.84	8.05114
2411.64	7.68329
2414.43	7.63102
2417.23	7.54376
2420.02	8.42099
2422.82	8.43321
2425.61	7.50192
2428.4	7.8242
2431.19	7.61473
2433.98	8.07677
2436.76	8.37931
2439.55	7.58948
2442.34	7.57589
2445.12	6.1364
2447.9	6.05675
2450.69	5.52654
2453.47	4.95375
2456.25	5.63637
2459.03	5.09203
2461.81	4.15262
2464.59	4.02155
2467.36	4.938
2470.14	5.26773
2472.91	5.20321
2475.69	3.87902
2478.46	3.59595
2481.23	3.1126
2484	3.40725
2486.77	3.36354
2489.54	2.76245
2492.31	2.50169
2495.08	3.11569
2497.84	3.55801
2500.61	3.22061
2503.37	2.82433
2506.13	1.63909
2508.89	1.81652
2511.66	0.844526
2514.42	0.641176
2517.17	0.587726
2519.93	0.715418
2522.69	0.610289
2525.44	0.521434
2528.2	0.794888
2530.95	1.69967
2533.71	3.42791
2536.46	3.76321
2539.21	3.31908
2541.96	3.00756
2544.71	3.18582
2547.46	3.89029
2550.2	4.65446
2552.95	4.0962
2555.69	4.24097
2558.44	4.40417
2561.18	4.72172
2563.92	4.9141
2566.67	4.2291
2569.41	4.36109
2572.14	3.88741
2574.88	3.59813
2577.62	3.32045
2580.36	2.78248
2583.09	2.61925
2585.83	2.23727
2588.56	2.52739
2591.29	1.17038
2594.02	1.24737
2596.75	1.85188
2599.48	1.71918
2602.21	1.77564
2604.94	0.81841
2607.67	1.27476
2610.39	1.70059
2613.12	2.04697
2615.84	1.64392
2618.56	1.29156
2621.28	1.35229
2624	1.30377
2626.72	1.45489
2629.44	1.10514
2632.16	1.48902
2634.88	1.02265
2637.59	0.9612
2640.31	0.342343
2643.02	1.05463
2645.73	1.16832
2648.45	1.2754
2651.16	1.04051
2653.87	1.55241
2656.58	0.864867
2659.28	1.55394
2661.99	2.55514
2664.7	3.04478
2667.4	2.96179
2670.11	3.53506
2672.81	4.2337
2675.51	3.8232
2678.21	3.78312
2680.92	4.20087
2683.62	2.97867
2686.31	2.75604
2689.01	2.73742
2691.71	2.95044
2694.4	4.1115
2697.1	3.49213
2699.79	2.53271
2702.48	3.11458
2705.18	3.08319
2707.87	3.65616
2710.56	3.29596
2713.25	2.12279
2715.93	2.71624
2718.62	2.62476
2721.31	3.33182
2723.99	3.95272
2726.68	3.53054
2729.36	3.12071
2732.04	2.66488
2734.72	2.75938
2737.4	2.93091
2740.08	3.46074
2742.76	3.39637
2745.44	3.82701
2748.12	3.46308
2750.79	2.84717
2753.47	4.31027
2756.14	5.89058
2758.81	6.99981
2761.48	7.02857
2764.16	6.25464
2766.83	6.56138
2769.49	5.85975
2772.16	5.50517
2774.83	5.51422
2777.5	4.91207
2780.16	5.51966
2782.83	5.81785
2785.49	5.32581
2788.15	5.63427
2790.81	4.39698
2793.47	4.06684
2796.13	3.29543
2798.79	3.65749
2801.45	2.37924
2804.11	2.94202
2806.76	2.35365
2809.42	2.21697
2812.07	2.47325
2814.73	2.2812
2817.38	3.41149
2820.03	4.21609
2822.68	5.06118
2825.33	5.99989
2827.98	5.51029
2830.62	7.00991
2833.27	8.04691
2835.92	8.93089
2838.56	11.0787
2841.2	13.5929
2843.85	16.3707
2846.49	19.145
2849.13	22.11
2851.77	26.0966
2854.41	28.6735
2857.05	32.0531
2859.68	34.8549
2862.32	37.4966
2864.96	40.3276
2867.59	42.6076
2870.22	45.2303
2872.86	46.6657
2875.49	48.9993
2878.12	50.9856
2880.75	51.285
2883.38	52.645
2886.01	55.072
2888.63	57.895
2891.26	59.0429
2893.88	60.8756
2896.51	64.0791
2899.13	66.6639
2901.76	69.8152
2904.38	73.5965
2907	77.8243
2909.62	82.1581
2912.24	87.3151
2914.85	91.7809
2917.47	96.1344
2920.09	99.239
2922.7	102.987
2925.31	105.583
2927.93	107.055
2930.54	109.238
2933.15	108.885
2935.76	109.6
2938.37	108.444
2940.98	106.169
2943.59	104.506
2946.2	101.559
2948.8	99.3505
2951.41	96.6017
2954.01	92.4736
2956.62	88.4037
2959.22	84.3233
2961.82	80.5749
2964.42	75.0403
2967.02	70.5421
2969.62	66.2677
2972.21	62.2355
2974.81	58.3499
2977.41	55.2357
2980	51.4224
2982.6	48.9907
2985.19	46.2217
2987.78	43.0323
2990.37	39.5257
2992.96	36.4384
2995.55	33.0843
2998.14	30.2063
3000.73	26.8626
3003.32	24.5414
3005.9	22.6049
3008.49	20.8708
3011.07	19.3454
3013.66	18.1066
3016.24	15.9354
3018.82	13.9997
3021.4	11.7387
3023.98	9.23673
3026.56	7.19935
3029.14	5.26291
3031.71	4.60477
3034.29	4.90692
3036.86	4.67622
3039.44	5.21395
3042.01	5.6396
3044.59	6.01276
3047.16	5.87623
3049.73	5.90607
3052.3	6.46141
3054.87	5.93343
3057.43	6.71404
3060	7.13409
3062.57	7.65239
3065.13	7.15338
3067.7	6.78734
3070.26	7.3709
3072.82	7.02933
3075.39	7.00208
3077.95	6.1497
3080.51	5.09583
3083.07	3.87247
3085.62	2.32239
3088.18	0.893491
3090.74	0.655194
3093.29	0.912689
3095.85	1.28451
3098.4	1.08137
3100.95	1.07723
3103.51	1.36255
3106.06	0.644892
3108.61	0.522354
3111.16	1.53692
3113.71	2.44383
3116.25	3.07297
3118.8	3.61039
3121.34	4.43576
3123.89	4.99718
3126.43	5.2155
3128.98	4.99071
3131.52	6.34034
3134.06	6.78209
3136.6	7.03183
3139.14	6.30896
3141.68	6.80059
3144.22	6.27755
3146.75	6.02398
3149.29	6.1179