File: data/Raman/poly_smoothed/Mb_30_27_40_1x_45s_532 nm_x100_100%_600 gr_mm_01.txt
#Acq. time (s)=	45
#Accumulations=	2
#Range (cm-¹)=	200...3150
#Windows=	2
#Auto scanning=	Off
#Autofocus=	Off
#Macrospot=	Off
#AutoExposure=	Off
#Spike filter=	Multiple accum.
#Delay time (s)=	0
#Binning=	1
#Readout mode=	Signal
#DeNoise=	Off
#ICS correction=	On
#Dark correction=	Off
#Inst. Process=	Off
#Detector Gain=	Best Dynamic Range
#Detector ADC=	20 kHz
#Detector temperature (°C)=	-69.85
#Instrument=	LabRAM HR Evol
#Detector=	Synapse
#Objective=	x100
#Grating=	600 gr/mm
#ND Filter=	100%
#Laser (nm)=	532
#Hole=	100.021
#Range=	Auto
#Laser Pol.=	No
#Raman. Pol.=	No
#Laser Pol. (°)=	-0.0007625
#Raman Pol. (°)=	89.9995
#Collection=	Microscope
#StageXY=	Marzhauser
#StageZ=	Marzhauser
#X (µm)=	-6352.7
#Y (µm)=	798.7
#Z (µm)=	-64.8
#Full time(mm:ss)=	3:19
#Project=
#Sample=
#Site=
#Title=	Mb_30_27_40_2x_45s_532 nm_x100_100%_600 gr_mm
#Remark=
#Date=	13.07.2022 11:43
#Acquired=	13.07.2022 11:43:48
#Base:Fit=	10.08.2022 10:40:03
#Base:Sub=	10.08.2022 10:40:17
#Filter:Polynom=	16.08.2022 10:16:15
#AxisType[0]=Intens
#AxisUnit[0]=Cnt
#AxisType[1]=Spectr
#AxisUnit[1]=1/cm
200.563	1.75557
204.194	5.85589
207.821	7.55973
211.449	8.4022
215.074	8.75011
218.699	7.92478
222.321	7.3853
225.941	7.07761
229.562	6.11186
233.18	5.48557
236.796	4.27618
240.411	5.02173
244.026	3.44626
247.638	2.22657
251.248	1.36965
254.857	0.308699
258.465	0.274408
262.071	0.0536194
265.678	1.24002
269.282	0.723194
272.884	2.16861
276.484	1.89233
280.084	1.88767
283.682	2.15162
287.276	1.45871
290.871	2.38158
294.465	2.31988
298.057	3.12584
301.648	3.91197
305.237	3.18967
308.823	2.6485
312.41	4.27934
315.995	3.10706
319.579	3.9705
323.16	4.39141
326.741	4.41374
330.321	2.4075
333.897	3.69776
337.474	4.67256
341.048	4.66474
344.622	4.65584
348.192	4.23878
351.764	3.69623
355.332	2.99602
358.901	3.33419
362.466	2.29779
366.03	2.6477
369.594	2.56806
373.155	4.49727
376.715	5.3424
380.273	5.51888
383.832	5.84221
387.388	6.02774
390.942	5.6469
394.495	5.67851
398.047	6.52457
401.597	6.39198
405.145	5.95312
408.693	5.71637
412.239	5.66789
415.783	5.00349
419.327	6.38046
422.869	5.73174
426.409	4.62837
429.948	4.31511
433.486	4.01882
437.022	2.27682
440.558	1.39128
444.089	1.27018
447.622	2.07115
451.153	4.77894
454.682	5.91738
458.208	7.19807
461.735	9.36353
465.259	10.3613
468.783	10.183
472.306	10.6313
475.825	10.8304
479.346	13.1058
482.862	13.7479
486.38	15.3684
489.894	15.5227
493.407	16.641
496.92	18.0464
500.43	18.6583
503.939	18.6241
507.448	18.5099
510.954	18.4293
514.459	19.2216
517.962	18.7249
521.466	18.8181
524.966	18.3647
528.466	17.9831
531.964	18.3531
535.46	17.4613
538.955	16.9647
542.449	15.4658
545.942	14.8657
549.433	13.3756
552.923	12.5446
556.412	11.4733
559.899	11.2243
563.385	9.97198
566.867	9.79256
570.35	8.01301
573.832	7.23953
577.313	6.31231
580.79	5.42417
584.268	5.61378
587.745	4.76886
591.218	5.4675
594.692	5.89359
598.164	5.72596
601.634	6.22897
605.104	7.01608
608.57	6.77035
612.037	7.54695
615.501	8.85007
618.966	9.33048
622.427	9.71239
625.887	10.6289
629.348	12.4348
632.806	12.8238
636.262	14.1945
639.716	15.9007
643.172	16.4212
646.624	16.0505
650.075	17.7895
653.524	18.1602
656.972	18.1574
660.419	19.811
663.865	20.636
667.309	20.6672
670.752	21.5716
674.194	21.6806
677.634	23.8436
681.073	24.9606
684.511	27.4016
687.947	28.9034
691.382	31.8466
694.816	34.4199
698.247	36.5229
701.678	37.797
705.108	39.779
708.534	41.7055
711.962	43.408
715.388	45.1735
718.81	45.1733
722.234	47.3552
725.654	49.029
729.075	49.8584
732.492	50.5905
735.91	53.9036
739.325	53.518
742.741	54.5074
746.153	56.152
749.564	56.547
752.976	57.5189
756.385	59.332
759.792	63.5774
763.2	67.2103
766.604	70.1702
770.008	74.3041
773.41	76.9522
776.811	79.8778
780.21	82.4571
783.608	83.8129
787.005	87.1877
790.401	89.3691
793.795	89.6772
797.188	91.1084
800.58	91.7849
803.971	93.6907
807.36	93.7512
810.748	93.651
814.135	94.5504
817.518	94.5621
820.902	93.0055
824.285	91.0683
827.665	88.3635
831.045	84.9656
834.424	82.6378
837.8	81.0545
841.177	79.7202
844.55	78.2995
847.924	75.4603
851.295	73.3391
854.666	70.3647
858.034	67.9454
861.403	63.9892
864.769	62.6895
868.133	60.7335
871.498	59.2702
874.86	57.9581
878.221	57.1693
881.58	56.284
884.938	55.937
888.297	54.9794
891.653	55.8388
895.007	57.393
898.36	57.055
901.712	57.7806
905.063	56.6049
908.412	54.6746
911.76	53.2312
915.107	52.7553
918.452	54.3847
921.797	54.9752
925.138	54.8195
928.48	54.6587
931.82	54.3032
935.16	52.5856
938.496	51.4921
941.833	49.9354
945.168	48.5334
948.5	46.9378
951.834	44.9833
955.163	43.2215
958.494	40.8431
961.821	39.0014
965.15	38.4416
968.474	37.696
971.8	37.2717
975.123	37.4158
978.446	37.3476
981.766	35.6113
985.084	36.0286
988.402	34.6929
991.72	33.2101
995.035	33.1706
998.349	32.0582
1001.66	31.9208
1004.97	31.4936
1008.28	33.95
1011.59	37.5586
1014.9	42.0085
1018.21	46.7664
1021.51	51.1533
1024.81	54.9298
1028.12	58.0276
1031.42	59.0755
1034.72	60.7014
1038.02	61.9065
1041.31	61.6196
1044.61	62.3364
1047.91	61.9204
1051.2	60.0125
1054.49	57.9553
1057.78	54.8356
1061.07	51.6135
1064.36	47.6971
1067.65	41.565
1070.93	36.606
1074.22	31.007
1077.5	25.8752
1080.78	21.9697
1084.06	19.2089
1087.34	20.102
1090.62	21.3205
1093.9	23.2861
1097.17	22.5531
1100.45	22.0468
1103.72	22.2528
1106.99	22.1314
1110.27	21.6838
1113.53	21.1465
1116.8	22.0402
1120.07	21.4913
1123.33	20.154
1126.6	20.4171
1129.86	19.2529
1133.12	17.6524
1136.38	16.4037
1139.64	15.4057
1142.9	14.1955
1146.16	12.5024
1149.41	11.4317
1152.67	9.57826
1155.92	7.43192
1159.17	6.23346
1162.42	3.84546
1165.67	3.58933
1168.92	3.45484
1172.16	1.91015
1175.41	0.863002
1178.65	0.154334
1181.9	1.59828
1185.14	1.829
1188.38	3.12923
1191.62	5.49928
1194.86	7.51054
1198.09	9.66594
1201.33	12.8784
1204.56	14.9612
1207.8	17.7441
1211.03	20.6597
1214.26	24.7776
1217.49	27.0012
1220.71	30.3365
1223.94	33.6178
1227.16	37.7771
1230.39	40.4364
1233.61	43.2829
1236.83	45.1783
1240.05	46.8482
1243.27	49.6688
1246.49	51.883
1249.71	53.1011
1252.92	53.5258
1256.14	56.1583
1259.35	57.7119
1262.56	57.9446
1265.77	59.2
1268.98	61.3613
1272.19	62.5134
1275.4	62.3848
1278.6	62.9349
1281.81	63.2872
1285.01	63.9518
1288.21	64.518
1291.41	65.4142
1294.61	65.1223
1297.81	65.6368
1301.01	66.7103
1304.2	66.2664
1307.4	66.9967
1310.59	68.9904
1313.78	69.137
1316.97	69.3332
1320.16	70.6877
1323.35	71.5809
1326.54	71.9708
1329.72	70.6093
1332.91	69.6092
1336.09	67.2651
1339.27	65.9234
1342.45	63.5228
1345.64	60.547
1348.81	58.494
1351.99	54.8505
1355.17	51.8779
1358.34	49.474
1361.51	47.2029
1364.69	45.2231
1367.86	42.1583
1371.03	39.9976
1374.2	38.7527
1377.37	37.9805
1380.53	37.179
1383.7	36.0825
1386.86	36.4618
1390.02	36.6328
1393.19	36.6924
1396.35	37.3429
1399.51	38.1805
1402.66	39.3237
1405.82	39.2822
1408.97	39.0397
1412.13	40.3178
1415.28	41.924
1418.43	44.4985
1421.59	47.2214
1424.73	50.0711
1427.88	52.1601
1431.03	56.991
1434.18	60.6571
1437.32	62.3831
1440.46	65.1617
1443.61	66.5935
1446.75	67.5152
1449.89	67.6022
1453.03	68.4098
1456.16	67.9144
1459.3	66.2529
1462.44	66.1514
1465.57	64.6972
1468.7	63.5271
1471.83	61.5339
1474.96	59.2287
1478.09	56.7643
1481.22	53.8266
1484.35	50.1873
1487.47	46.7809
1490.6	44.5297
1493.72	42.281
1496.84	40.5039
1499.96	38.728
1503.08	36.2254
1506.2	35.2986
1509.32	33.5127
1512.44	31.5017
1515.55	28.3794
1518.66	26.7131
1521.78	25.3622
1524.89	22.5738
1528	22.2299
1531.11	23.4114
1534.21	22.9443
1537.32	22.129
1540.43	22.7854
1543.53	22.0678
1546.63	23.2798
1549.74	23.5942
1552.84	24.7246
1555.94	26.5214
1559.03	28.7413
1562.13	28.7933
1565.23	31.1957
1568.32	32.9547
1571.42	36.3658
1574.51	38.9428
1577.6	40.9287
1580.69	42.5859
1583.78	44.2122
1586.87	44.7859
1589.95	45.8825
1593.04	47.3542
1596.12	48.3267
1599.21	48.1678
1602.29	47.1514
1605.37	47.9336
1608.45	46.5271
1611.53	45.2445
1614.6	44.864
1617.68	45.0797
1620.75	46.4973
1623.83	49.4865
1626.9	51.6925
1629.97	54.8097
1633.04	58.011
1636.11	61.7621
1639.18	65.3198
1642.25	70.3433
1645.31	72.2176
1648.38	76.1557
1651.44	78.4545
1654.5	78.5457
1657.56	79.8611
1660.62	80.8883
1663.68	80.3568
1666.74	79.6521
1669.8	77.3966
1672.85	74.0012
1675.91	68.5311
1678.96	64.306
1682.01	59.4626
1685.06	53.942
1688.11	48.7951
1691.16	44.073
1694.21	40.039
1697.25	35.5975
1700.3	31.4634
1703.34	27.7746
1706.39	25.054
1709.43	23.2572
1712.47	20.9889
1715.51	18.2819
1718.54	15.301
1721.58	14.4591
1724.62	13.2327
1727.65	11.8124
1730.68	11.1287
1733.72	10.8516
1736.75	9.85949
1739.78	9.63609
1742.81	10.8103
1745.84	10.2573
1748.86	9.58938
1751.89	9.37253
1754.91	9.75547
1757.93	8.22384
1760.96	7.12123
1763.98	6.54464
1767	5.7406
1770.02	4.44855
1773.03	4.41214
1776.05	3.85567
1779.07	3.90538
1782.08	4.03681
1785.09	3.02106
1788.11	2.71065
1791.12	3.37608
1794.13	3.4104
1797.13	3.24497
1800.14	2.38531
1803.15	2.39243
1806.15	2.60745
1809.16	2.10719
1812.16	2.47443
1815.16	3.33046
1818.16	3.41846
1821.16	2.78073
1824.16	1.64818
1827.16	1.80955
1830.16	1.7476
1833.15	1.72574
1836.14	2.09573
1839.14	2.73146
1842.13	2.38071
1845.12	2.20932
1848.11	3.11485
1851.1	4.01507
1854.08	4.16531
1857.07	5.70157
1860.05	6.71471
1863.04	8.11969
1866.02	7.78016
1869	7.74477
1871.98	8.00809
1874.96	7.80325
1877.94	8.07316
1880.92	7.79645
1882.51	8.26583
1885.5	8.86251
1888.48	8.7908
1891.47	7.9257
1894.46	7.95219
1897.44	7.70044
1900.42	7.97624
1903.41	7.54558
1906.39	6.86854
1909.37	7.15373
1912.35	6.69036
1915.32	6.71526
1918.3	7.53872
1921.27	7.58751
1924.25	6.7655
1927.22	7.32128
1930.19	6.34485
1933.17	5.83708
1936.14	5.00906
1939.11	4.48578
1942.07	4.01566
1945.04	3.50721
1948.01	3.03003
1950.97	3.45851
1953.93	4.06001
1956.9	4.85729
1959.86	4.69182
1962.82	5.05946
1965.78	4.53045
1968.74	5.89699
1971.69	5.61547
1974.65	5.99253
1977.6	6.13013
1980.56	7.2785
1983.51	8.3112
1986.46	8.85202
1989.41	10.4094
1992.36	10.6417
1995.31	11.1838
1998.26	11.7514
2001.2	11.3522
2004.15	11.3439
2007.09	11.3831
2010.04	11.7418
2012.98	11.7664
2015.92	11.6009
2018.86	11.7365
2021.8	12.4813
2024.73	13.5053
2027.67	14.0209
2030.61	14.2963
2033.54	13.9437
2036.47	14.654
2039.4	14.9775
2042.33	14.1091
2045.27	13.0682
2048.19	13.3671
2051.12	13.9645
2054.05	14.3181
2056.97	14.1464
2059.9	15.7915
2062.82	16.4678
2065.74	17.5272
2068.67	17.3008
2071.59	18.1506
2074.51	18.3793
2077.42	19.4766
2080.34	20.473
2083.26	21.2632
2086.17	22.3277
2089.09	23.3771
2092	24.8906
2094.91	27.8174
2097.82	29.0944
2100.73	30.9081
2103.64	31.9562
2106.55	33.9433
2109.45	35.3319
2112.36	36.3421
2115.26	38.075
2118.17	40.1894
2121.07	42.0492
2123.97	44.1715
2126.87	46.8826
2129.77	50.2845
2132.67	52.4208
2135.56	55.0296
2138.46	57.6654
2141.35	60.4798
2144.25	63.8195
2147.14	66.2812
2150.03	68.7412
2152.92	71.4273
2155.81	73.6039
2158.7	76.6513
2161.59	78.8069
2164.47	82.005
2167.36	82.965
2170.24	83.8849
2173.13	84.8552
2176.01	85.1655
2178.89	85.2339
2181.77	85.0093
2184.65	83.8175
2187.53	82.2147
2190.4	79.4175
2193.28	75.7741
2196.16	72.9655
2199.03	69.5309
2201.9	66.3198
2204.77	62.5947
2207.64	60.225
2210.51	56.152
2213.38	52.9008
2216.25	50.3554
2219.12	46.3884
2221.98	43.521
2224.85	40.8743
2227.71	38.8266
2230.57	35.3415
2233.43	33.6625
2236.29	30.3883
2239.15	27.6515
2242.01	25.6722
2244.87	24.8212
2247.72	23.5406
2250.58	21.9923
2253.43	19.9855
2256.29	17.763
2259.14	15.5927
2261.99	14.2924
2264.84	14.3131
2267.69	14.4205
2270.53	14.0826
2273.38	13.7545
2276.23	13.4816
2279.07	13.6923
2281.91	13.7028
2284.76	13.9612
2287.6	14.6487
2290.44	13.2872
2293.28	12.2256
2296.12	12.916
2298.96	12.8241
2301.79	13.0266
2304.63	14.2682
2307.46	14.3835
2310.3	15.0017
2313.13	15.072
2315.96	16.0034
2318.79	14.8931
2321.62	14.2938
2324.45	13.7664
2327.27	13.7102
2330.1	13.0052
2332.92	12.7454
2335.75	12.0397
2338.57	10.2485
2341.39	9.25298
2344.21	7.29856
2347.04	6.45793
2349.85	5.20495
2352.67	4.14473
2355.49	3.08629
2358.3	1.59686
2361.12	0.741174
2363.93	1.45479
2366.75	1.76057
2369.56	1.49421
2372.37	2.43778
2375.18	2.7085
2377.99	3.5741
2380.8	4.4533
2383.6	4.52507
2386.41	5.58865
2389.21	5.57116
2392.02	6.50301
2394.82	7.28759
2397.62	7.39767
2400.42	7.31447
2403.22	7.29775
2406.02	6.66664
2408.82	6.60335
2411.62	5.57083
2414.41	5.59582
2417.21	5.80466
2420	5.06564
2422.79	4.68583
2425.59	4.65215
2428.38	4.40175
2431.17	3.97443
2433.95	2.49649
2436.74	2.41662
2439.53	2.71625
2442.31	2.90153
2445.1	2.99829
2447.88	3.4668
2450.67	4.00223
2453.45	5.40743
2456.23	5.9423
2459.01	6.30026
2461.79	6.30574
2464.57	6.50661
2467.34	5.09137
2470.12	5.69099
2472.89	5.29217
2475.67	4.84139
2478.44	3.54608
2481.21	2.58742
2483.98	2.34984
2486.75	1.97693
2489.52	1.49878
2492.29	2.02867
2495.05	2.46722
2497.82	2.03368
2500.58	1.71607
2503.35	2.09747
2506.11	2.20526
2508.87	2.493
2511.63	3.44759
2514.39	4.1487
2517.15	5.08907
2519.91	5.46624
2522.67	5.64401
2525.42	5.4714
2528.18	5.96511
2530.93	6.71995
2533.69	6.61029
2536.44	5.95218
2539.19	5.14555
2541.94	4.79362
2544.69	5.02504
2547.44	3.59583
2550.18	3.42501
2552.93	4.13401
2555.67	3.04611
2558.42	3.1884
2561.16	3.02142
2563.9	2.54174
2566.64	3.05041
2569.38	3.13456
2572.12	3.26408
2574.86	3.14305
2577.6	3.83413
2580.33	3.33807
2583.07	3.60872
2585.8	3.48582
2588.54	3.61306
2591.27	3.8755
2594	5.16096
2596.73	5.8203
2599.46	7.3373
2602.19	6.56456
2604.92	6.53762
2607.64	5.95583
2610.37	7.25269
2613.09	6.15168
2615.82	5.45518
2618.54	6.03037
2621.26	5.43033
2623.98	4.8432
2626.7	4.93028
2629.42	4.26252
2632.14	3.51264
2634.86	3.18391
2637.57	2.82501
2640.29	3.38469
2643	3.45424
2645.71	3.26245
2648.43	2.76901
2651.14	3.09409
2653.85	2.7914
2656.56	3.47029
2659.26	3.92012
2661.97	4.69809
2664.68	4.47568
2667.38	4.33745
2670.09	4.44043
2672.79	4.40161
2675.49	4.82694
2678.19	4.12396
2680.89	3.39871
2683.59	3.65915
2686.29	4.38154
2688.99	3.60464
2691.69	3.17733
2694.38	2.111
2697.08	2.23486
2699.77	2.25582
2702.46	3.36956
2705.15	4.94753
2707.85	5.15541
2710.54	5.51771
2713.22	6.05091
2715.91	5.66976
2718.6	5.5575
2721.29	6.65384
2723.97	6.93542
2726.66	7.28197
2729.34	7.60742
2732.02	7.23347
2734.7	7.56048
2737.38	6.0486
2740.06	5.8471
2742.74	5.55107
2745.42	5.10929
2748.09	5.00869
2750.77	5.00317
2753.45	3.48675
2756.12	1.94853
2758.79	1.43805
2761.46	1.08044
2764.14	0.0842865
2766.8	0.42582
2769.47	0.851246
2772.14	1.48938
2774.81	0.446149
2777.48	-0.0860517
2780.14	0.0452409
2782.8	0.0123021
2785.47	0.884663
2788.13	1.60791
2790.79	1.321
2793.45	1.68467
2796.11	2.09072
2798.77	2.39778
2801.43	2.31003
2804.09	2.17874
2806.74	2.55272
2809.4	2.00339
2812.05	1.29863
2814.71	0.932845
2817.36	1.02544
2820.01	1.77033
2822.66	2.57122
2825.31	4.10998
2827.96	5.71015
2830.6	8.06707
2833.25	10.3197
2835.9	13.5201
2838.54	17.6998
2841.18	21.9833
2843.83	27.5542
2846.47	33.8352
2849.11	40.8832
2851.75	47.5785
2854.39	53.9551
2857.03	60.8057
2859.66	68.3078
2862.3	75.2362
2864.94	81.3452
2867.57	86.9474
2870.2	91.0232
2872.84	96.7675
2875.47	101.279
2878.1	105.872
2880.73	110.611
2883.36	115.575
2885.99	120.052
2888.61	124.561
2891.24	128.816
2893.86	135.867
2896.49	141.216
2899.11	148.623
2901.73	156.782
2904.36	166.643
2906.98	177.16
2909.6	187.665
2912.21	198.149
2914.83	208.77
2917.45	219.372
2920.07	228.087
2922.68	236.139
2925.29	242.804
2927.91	247.081
2930.52	250.59
2933.13	252.083
2935.74	251.817
2938.35	249.734
2940.96	245.705
2943.57	240.851
2946.18	233.64
2948.78	224.39
2951.39	215.122
2953.99	205.001
2956.59	195.471
2959.2	184.975
2961.8	173.836
2964.4	163.213
2967	153.291
2969.6	143.316
2972.19	132.318
2974.79	123.055
2977.39	113.224
2979.98	103.141
2982.58	94.7218
2985.17	85.0201
2987.76	76.1608
2990.35	67.6953
2992.94	59.7892
2995.53	52.1904
2998.12	45.1939
3000.71	38.4797
3003.3	31.9382
3005.88	26.3368
3008.47	20.6856
3011.05	15.8251
3013.64	12.4716
3016.22	10.3013
3018.8	8.04327
3021.38	6.96288
3023.96	5.57297
3026.54	3.02001
3029.12	2.41139
3031.69	1.87991
3034.27	1.34329
3036.84	1.56395
3039.42	1.52509
3041.99	2.10099
3044.57	2.47284
3047.14	3.61708
3049.71	3.59204
3052.28	4.00828
3054.85	4.15078
3057.41	4.26946
3059.98	4.30381
3062.55	4.14238
3065.11	3.54483
3067.68	2.94649
3070.24	2.59155
3072.8	1.56649
3075.36	2.23651
3077.93	2.10599
3080.49	1.84717
3083.04	1.59802
3085.6	1.92749
3088.16	1.27521
3090.72	0.119042
3093.27	0.344677
3095.83	0.216873
3098.38	-0.423853
3100.93	-0.520543
3103.49	0.310097
3106.04	0.234801
3108.59	0.715418
3111.14	1.56709
3113.69	2.55671
3116.23	3.50925
3118.78	4.03411
3121.33	5.4607
3123.87	5.75833
3126.41	6.70316
3128.96	7.82259
3131.5	9.62658
3134.04	10.5067
3136.58	11.8944
3139.12	13.9848
3141.66	15.3305
3144.2	16.6912
3146.74	16.8711
3149.27	16.0442