File: data/Raman/poly_smoothed/Mb_30_27_32_1x_45s_532 nm_x100_100%_600 gr_mm_01.txt
#Acq. time (s)=	45
#Accumulations=	2
#Range (cm-¹)=	200...3150
#Windows=	2
#Auto scanning=	Off
#Autofocus=	Off
#Macrospot=	Off
#AutoExposure=	Off
#Spike filter=	Multiple accum.
#Delay time (s)=	0
#Binning=	1
#Readout mode=	Signal
#DeNoise=	Off
#ICS correction=	On
#Dark correction=	Off
#Inst. Process=	Off
#Detector Gain=	Best Dynamic Range
#Detector ADC=	20 kHz
#Detector temperature (°C)=	-69.85
#Instrument=	LabRAM HR Evol
#Detector=	Synapse
#Objective=	x100
#Grating=	600 gr/mm
#ND Filter=	100%
#Laser (nm)=	532
#Hole=	100.021
#Range=	Auto
#Laser Pol.=	No
#Raman. Pol.=	No
#Laser Pol. (°)=	-0.0007625
#Raman Pol. (°)=	89.9995
#Collection=	Microscope
#StageXY=	Marzhauser
#StageZ=	Marzhauser
#X (µm)=	-6367.9
#Y (µm)=	825.8
#Z (µm)=	-64.65
#Full time(mm:ss)=	3:18
#Project=
#Sample=
#Site=
#Title=	Mb_30_27_32_2x_45s_532 nm_x100_100%_600 gr_mm
#Remark=
#Date=	13.07.2022 11:06
#Acquired=	13.07.2022 11:06:04
#Base:Fit=	10.08.2022 10:40:03
#Base:Sub=	10.08.2022 10:40:17
#Filter:Polynom=	16.08.2022 10:16:15
#AxisType[0]=Intens
#AxisUnit[0]=Cnt
#AxisType[1]=Spectr
#AxisUnit[1]=1/cm
200.563	14.3039
204.194	14.2509
207.821	14.0423
211.449	13.0202
215.074	12.0073
218.699	11.5276
222.321	9.82818
225.941	8.51065
229.562	8.10037
233.18	7.17083
236.796	6.33214
240.411	6.23762
244.026	4.72111
247.638	4.67642
251.248	2.78052
254.857	2.59403
258.465	0.773633
262.071	1.2574
265.678	1.59536
269.282	2.09791
272.884	3.66841
276.484	2.20525
280.084	2.02599
283.682	3.16292
287.276	3.65681
290.871	4.53793
294.465	4.93121
298.057	3.98703
301.648	4.91411
305.237	5.25268
308.823	4.34941
312.41	4.01865
315.995	4.24062
319.579	5.07542
323.16	5.63495
326.741	6.32523
330.321	5.07708
333.897	4.71852
337.474	5.85839
341.048	4.48399
344.622	4.93603
348.192	4.1893
351.764	3.92077
355.332	3.99746
358.901	3.45575
362.466	3.65688
366.03	2.47036
369.594	4.18534
373.155	3.59349
376.715	3.52055
380.273	4.941
383.832	4.54249
387.388	3.04566
390.942	3.87658
394.495	3.52464
398.047	3.10632
401.597	3.81108
405.145	4.63363
408.693	6.28387
412.239	5.2465
415.783	5.71984
419.327	6.63784
422.869	7.00012
426.409	5.6937
429.948	3.61816
433.486	3.41013
437.022	2.69229
440.558	2.14201
444.089	2.23872
447.622	2.23447
451.153	3.40811
454.682	5.05978
458.208	5.48721
461.735	6.98266
465.259	8.5024
468.783	9.53623
472.306	10.67
475.825	12.2674
479.346	14.413
482.862	16.1161
486.38	18.2843
489.894	18.6929
493.407	19.3645
496.92	19.6429
500.43	20.0875
503.939	21.0897
507.448	20.0529
510.954	19.0028
514.459	18.6424
517.962	17.2984
521.466	17.1529
524.966	16.7664
528.466	15.4296
531.964	14.5919
535.46	12.5313
538.955	10.9264
542.449	9.36691
545.942	8.97406
549.433	7.84516
552.923	7.83165
556.412	8.54479
559.899	8.83272
563.385	10.3035
566.867	10.2626
570.35	11.7435
573.832	13.1091
577.313	13.8765
580.79	14.3537
584.268	15.3799
587.745	15.7393
591.218	16.4319
594.692	16.8569
598.164	18.1066
601.634	19.7349
605.104	20.0024
608.57	20.8682
612.037	19.7759
615.501	19.0115
618.966	18.182
622.427	19.0695
625.887	19.4686
629.348	20.9025
632.806	21.7111
636.262	23.4222
639.716	24.5785
643.172	25.5399
646.624	26.727
650.075	27.2508
653.524	28.6373
656.972	30.345
660.419	30.7942
663.865	30.2774
667.309	30.7332
670.752	30.8963
674.194	32.5717
677.634	33.1968
681.073	34.6011
684.511	35.7383
687.947	38.3472
691.382	40.5756
694.816	42.1389
698.247	44.2122
701.678	45.1133
705.108	47.2992
708.534	48.9582
711.962	49.8256
715.388	52.4675
718.81	52.6589
722.234	53.7424
725.654	54.6656
729.075	55.1748
732.492	56.6504
735.91	58.7753
739.325	58.9373
742.741	59.0858
746.153	60.4056
749.564	62.5292
752.976	63.7617
756.385	65.7618
759.792	66.271
763.2	69.4993
766.604	71.9752
770.008	74.3358
773.41	76.0911
776.811	78.6916
780.21	81.5938
783.608	83.9286
787.005	86.2805
790.401	88.8357
793.795	88.8711
797.188	90.0006
800.58	90.6764
803.971	91.4095
807.36	92.6651
810.748	92.9577
814.135	93.5637
817.518	93.5353
820.902	91.3755
824.285	90.4375
827.665	90.7379
831.045	89.6405
834.424	90.4346
837.8	87.697
841.177	85.0024
844.55	82.5833
847.924	81.3961
851.295	78.7578
854.666	76.7332
858.034	75.8116
861.403	76.0858
864.769	74.4898
868.133	73.9622
871.498	72.7636
874.86	71.2937
878.221	68.8386
881.58	68.1492
884.938	65.4946
888.297	66.1916
891.653	65.9332
895.007	64.8575
898.36	64.4555
901.712	62.5442
905.063	62.2134
908.412	61.9254
911.76	60.9467
915.107	60.2319
918.452	59.235
921.797	57.6165
925.138	55.6478
928.48	53.4875
931.82	52.0272
935.16	50.3293
938.496	50.3983
941.833	49.582
945.168	48.4755
948.5	46.1015
951.834	44.4983
955.163	41.4783
958.494	39.8699
961.821	38.7114
965.15	37.541
968.474	35.7884
971.8	35.0952
975.123	33.4037
978.446	32.5731
981.766	31.885
985.084	32.6969
988.402	32.7067
991.72	32.2986
995.035	32.4924
998.349	33.1134
1001.66	32.9465
1004.97	31.7644
1008.28	31.5827
1011.59	31.109
1014.9	31.9532
1018.21	34.4998
1021.51	34.6644
1024.81	33.2557
1028.12	32.9459
1031.42	32.2991
1034.72	32.9625
1038.02	33.1839
1041.31	31.6019
1044.61	30.5593
1047.91	29.6614
1051.2	27.9579
1054.49	26.3542
1057.78	25.7954
1061.07	25.8179
1064.36	23.8183
1067.65	21.3038
1070.93	18.535
1074.22	17.1072
1077.5	16.9775
1080.78	15.1054
1084.06	14.5882
1087.34	13.3579
1090.62	12.7196
1093.9	11.5276
1097.17	11.9474
1100.45	12.1252
1103.72	11.3628
1106.99	10.8712
1110.27	10.9725
1113.53	10.5011
1116.8	11.3245
1120.07	10.161
1123.33	11.4783
1126.6	11.7756
1129.86	10.8257
1133.12	11.4287
1136.38	11.6514
1139.64	11.9841
1142.9	10.6597
1146.16	9.66776
1149.41	8.92568
1152.67	8.45243
1155.92	7.97973
1159.17	6.85241
1162.42	5.85401
1165.67	4.58179
1168.92	3.30987
1172.16	3.77435
1175.41	3.05889
1178.65	2.07121
1181.9	1.23089
1185.14	1.34413
1188.38	0.798307
1191.62	1.07478
1194.86	1.46177
1198.09	3.59537
1201.33	3.67705
1204.56	6.11109
1207.8	6.77414
1211.03	8.53594
1214.26	8.99774
1217.49	11.7279
1220.71	13.2585
1223.94	14.2963
1227.16	15.5571
1230.39	16.5959
1233.61	17.6158
1236.83	19.3104
1240.05	20.3625
1243.27	21.0812
1246.49	20.9526
1249.71	21.6663
1252.92	21.1484
1256.14	20.5965
1259.35	19.508
1262.56	19.6523
1265.77	19.1366
1268.98	19.9596
1272.19	21.2178
1275.4	22.8474
1278.6	23.1066
1281.81	23.8696
1285.01	25.4682
1288.21	26.9265
1291.41	28.1288
1294.61	30.0467
1297.81	32.0666
1301.01	33.8883
1304.2	36.396
1307.4	38.2941
1310.59	39.8123
1313.78	41.8316
1316.97	42.5143
1320.16	42.3769
1323.35	40.2752
1326.54	39.4978
1329.72	38.9782
1332.91	38.0024
1336.09	36.1703
1339.27	33.4129
1342.45	31.937
1345.64	30.452
1348.81	28.4293
1351.99	27.5108
1355.17	25.4354
1358.34	23.521
1361.51	22.6818
1364.69	22.1807
1367.86	21.0429
1371.03	21.178
1374.2	19.5614
1377.37	20.5272
1380.53	20.4826
1383.7	21.4739
1386.86	21.538
1390.02	22.0724
1393.19	20.9127
1396.35	19.8798
1399.51	19.5741
1402.66	20.2892
1405.82	20.1974
1408.97	20.8187
1412.13	20.5551
1415.28	21.3553
1418.43	23.747
1421.59	25.4117
1424.73	26.3167
1427.88	29.4575
1431.03	32.1577
1434.18	33.4791
1437.32	35.2122
1440.46	37.7503
1443.61	38.7766
1446.75	40.7465
1449.89	41.0502
1453.03	42.5032
1456.16	43.3556
1459.3	42.4065
1462.44	42.1675
1465.57	40.841
1468.7	38.6965
1471.83	37.3378
1474.96	35.9215
1478.09	35.0079
1481.22	33.4118
1484.35	32.612
1487.47	30.1962
1490.6	28.7013
1493.72	26.227
1496.84	24.5864
1499.96	21.0023
1503.08	18.7626
1506.2	17.8409
1509.32	15.0506
1512.44	13.2378
1515.55	11.2296
1518.66	10.1864
1521.78	8.37901
1524.89	7.69682
1528	7.10435
1531.11	5.71167
1534.21	4.70891
1537.32	5.06674
1540.43	4.64892
1543.53	5.44807
1546.63	7.89789
1549.74	9.60202
1552.84	11.844
1555.94	13.0144
1559.03	12.8348
1562.13	14.4669
1565.23	15.0763
1568.32	16.1799
1571.42	17.5255
1574.51	18.4063
1577.6	19.1389
1580.69	20.6855
1583.78	23.2483
1586.87	24.5216
1589.95	26.7528
1593.04	26.9609
1596.12	28.6549
1599.21	28.8898
1602.29	28.7411
1605.37	29.1114
1608.45	29.7106
1611.53	30.3023
1614.6	30.5148
1617.68	30.0248
1620.75	30.4332
1623.83	29.8049
1626.9	30.0441
1629.97	30.8363
1633.04	31.379
1636.11	32.831
1639.18	32.8877
1642.25	33.5959
1645.31	34.15
1648.38	34.2941
1651.44	35.1529
1654.5	34.3004
1657.56	34.6051
1660.62	34.3993
1663.68	34.403
1666.74	32.5297
1669.8	30.4753
1672.85	28.9446
1675.91	26.2205
1678.96	24.6115
1682.01	23.3779
1685.06	22.4669
1688.11	19.3195
1691.16	15.5177
1694.21	13.2375
1697.25	12.012
1700.3	10.2382
1703.34	9.72252
1706.39	9.32047
1709.43	9.92173
1712.47	8.47179
1715.51	7.66169
1718.54	6.71225
1721.58	7.29015
1724.62	7.42346
1727.65	6.24021
1730.68	6.37113
1733.72	5.82653
1736.75	6.59272
1739.78	6.02153
1742.81	5.00815
1745.84	5.48088
1748.86	5.60695
1751.89	5.6058
1754.91	6.0089
1757.93	5.28734
1760.96	4.46751
1763.98	2.18168
1767	2.03385
1770.02	1.42774
1773.03	1.06706
1776.05	0.818294
1779.07	1.46582
1782.08	1.73684
1785.09	1.81147
1788.11	1.52884
1791.12	1.00182
1794.13	1.29223
1797.13	2.42577
1800.14	2.78521
1803.15	3.54077
1806.15	3.55388
1809.16	3.6379
1812.16	4.58898
1815.16	4.83195
1818.16	5.3666
1821.16	5.80682
1824.16	5.6988
1827.16	5.82368
1830.16	6.57451
1833.15	6.73691
1836.14	6.49011
1839.14	6.70488
1842.13	8.00489
1845.12	7.5729
1848.11	7.61152
1851.1	8.4851
1854.08	8.19843
1857.07	7.52002
1860.05	6.8924
1863.04	5.9261
1866.02	5.57754
1869	5.78424
1871.98	5.57202
1874.96	5.50028
1877.94	5.38976
1880.92	4.33556
1882.51	5.01646
1885.5	5.6616
1888.48	6.19372
1891.47	6.98454
1894.46	7.26086
1897.44	6.51196
1900.42	7.06265
1903.41	6.50349
1906.39	6.5375
1909.37	6.38405
1912.35	7.09454
1915.32	7.04162
1918.3	6.77752
1921.27	8.10354
1924.25	6.67346
1927.22	5.27397
1930.19	4.72216
1933.17	3.65466
1936.14	3.34605
1939.11	3.79664
1942.07	3.29418
1945.04	3.30553
1948.01	3.59915
1950.97	3.84879
1953.93	4.50135
1956.9	5.95312
1959.86	6.7142
1962.82	6.81091
1965.78	6.43343
1968.74	5.08477
1971.69	5.52425
1974.65	6.37627
1977.6	6.58214
1980.56	6.95572
1983.51	6.98583
1986.46	7.09206
1989.41	5.8731
1992.36	5.86801
1995.31	5.6629
1998.26	4.66382
2001.2	3.60944
2004.15	2.81113
2007.09	2.30084
2010.04	1.74871
2012.98	1.09342
2015.92	0.900762
2018.86	1.14197
2021.8	1.22281
2024.73	0.764976
2027.67	0.169228
2030.61	-0.549541
2033.54	-0.117409
2036.47	0.163392
2039.4	1.03764
2042.33	2.31088
2045.27	4.74068
2048.19	5.3951
2051.12	6.09034
2054.05	7.01603
2056.97	8.03698
2059.9	8.49476
2062.82	8.81742
2065.74	9.51022
2068.67	10.2242
2071.59	9.41937
2074.51	9.62786
2077.42	9.44866
2080.34	9.94964
2083.26	10.739
2086.17	11.723
2089.09	11.9927
2092	11.2041
2094.91	11.2318
2097.82	10.5811
2100.73	9.6874
2103.64	11.1771
2106.55	13.1544
2109.45	14.0927
2112.36	14.612
2115.26	15.7659
2118.17	16.6955
2121.07	17.3402
2123.97	17.6911
2126.87	18.9476
2129.77	20.0614
2132.67	21.1944
2135.56	22.0692
2138.46	22.5366
2141.35	23.8827
2144.25	23.3748
2147.14	24.3872
2150.03	24.924
2152.92	27.3825
2155.81	28.2696
2158.7	29.093
2161.59	29.6433
2164.47	30.5855
2167.36	30.9074
2170.24	31.6579
2173.13	31.9386
2176.01	32.6006
2178.89	32.4926
2181.77	32.6912
2184.65	32.3724
2187.53	32.6699
2190.4	32.1043
2193.28	31.6207
2196.16	30.9837
2199.03	30.1687
2201.9	28.3979
2204.77	27.1815
2207.64	24.1222
2210.51	23.0919
2213.38	21.6909
2216.25	20.1072
2219.12	18.9356
2221.98	17.5113
2224.85	17.5307
2227.71	16.7079
2230.57	17.4858
2233.43	16.94
2236.29	16.0863
2239.15	15.706
2242.01	14.9925
2244.87	14.1616
2247.72	14.7534
2250.58	14.5154
2253.43	13.7275
2256.29	13.0659
2259.14	11.5915
2261.99	11.0204
2264.84	9.48225
2267.69	8.22102
2270.53	7.45363
2273.38	6.77541
2276.23	6.64685
2279.07	5.07147
2281.91	4.87088
2284.76	3.96136
2287.6	3.09275
2290.44	3.20298
2293.28	2.84479
2296.12	3.16763
2298.96	4.58131
2301.79	5.0134
2304.63	5.00957
2307.46	5.55121
2310.3	6.25964
2313.13	6.22415
2315.96	7.27701
2318.79	7.74431
2321.62	7.05781
2324.45	6.83074
2327.27	6.6816
2330.1	6.65768
2332.92	6.27228
2335.75	6.04486
2338.57	5.50995
2341.39	5.99954
2344.21	5.24579
2347.04	4.69537
2349.85	3.00145
2352.67	2.20058
2355.49	1.04914
2358.3	1.17792
2361.12	0.561936
2363.93	0.157806
2366.75	0.961577
2369.56	0.844553
2372.37	1.08445
2375.18	1.06496
2377.99	1.5609
2380.8	1.32861
2383.6	1.29846
2386.41	2.5726
2389.21	1.94659
2392.02	2.22165
2394.82	2.46037
2397.62	2.0368
2400.42	2.22406
2403.22	3.02268
2406.02	3.05482
2408.82	3.4344
2411.62	3.72252
2414.41	4.20335
2417.21	4.16414
2420	3.42721
2422.79	4.70864
2425.59	5.50916
2428.38	5.69871
2431.17	6.37304
2433.95	6.56589
2436.74	6.37546
2439.53	5.85938
2442.31	5.96851
2445.1	5.29847
2447.88	5.0711
2450.67	4.54776
2453.45	3.37288
2456.23	3.49797
2459.01	2.03123
2461.79	2.05744
2464.57	1.64348
2467.34	1.75789
2470.12	2.98754
2472.89	3.22365
2475.67	2.22242
2478.44	2.68224
2481.21	2.13444
2483.98	2.40972
2486.75	2.25544
2489.52	2.88348
2492.29	3.37091
2495.05	3.82596
2497.82	4.12639
2500.58	3.48367
2503.35	3.19809
2506.11	2.37463
2508.87	2.10237
2511.63	1.51485
2514.39	1.47478
2517.15	1.80979
2519.91	1.81048
2522.67	2.0071
2525.42	2.08617
2528.18	2.15388
2530.93	3.34221
2533.69	3.98181
2536.44	5.35876
2539.19	5.15831
2541.94	5.09041
2544.69	5.35327
2547.44	4.71383
2550.18	5.19441
2552.93	4.92478
2555.67	4.27338
2558.42	4.53207
2561.16	4.83912
2563.9	4.3218
2566.64	3.7902
2569.38	4.11451
2572.12	3.576
2574.86	3.44417
2577.6	3.24127
2580.33	3.58603
2583.07	3.61162
2585.8	3.90541
2588.54	4.26509
2591.27	4.12262
2594	4.40911
2596.73	4.57087
2599.46	5.30259
2602.19	6.31161
2604.92	6.51017
2607.64	6.66221
2610.37	6.29452
2613.09	5.44744
2615.82	4.59654
2618.54	4.61554
2621.26	3.9736
2623.98	3.81511
2626.7	3.79782
2629.42	3.8644
2632.14	3.88312
2634.86	4.33689
2637.57	4.67225
2640.29	4.42207
2643	4.91414
2645.71	5.97165
2648.43	5.61797
2651.14	6.77868
2653.85	6.94692
2656.56	5.73007
2659.26	6.39868
2661.97	5.85802
2664.68	6.35937
2667.38	6.39754
2670.09	6.83065
2672.79	6.01727
2675.49	5.59393
2678.19	5.02429
2680.89	4.72013
2683.59	4.24821
2686.29	4.67418
2688.99	4.29665
2691.69	4.62057
2694.38	4.53374
2697.08	4.25825
2699.77	4.91846
2702.46	5.69675
2705.15	5.42181
2707.85	6.14165
2710.54	6.25868
2713.22	6.04444
2715.91	6.16281
2718.6	6.93281
2721.29	6.47683
2723.97	7.03343
2726.66	7.64879
2729.34	7.93798
2732.02	8.62008
2734.7	8.74624
2737.38	9.10392
2740.06	9.72595
2742.74	9.75446
2745.42	9.68854
2748.09	9.38096
2750.77	8.3854
2753.45	8.02295
2756.12	8.24744
2758.79	6.81094
2761.46	7.13577
2764.14	6.65666
2766.8	4.93521
2769.47	4.39279
2772.14	3.59482
2774.81	3.09646
2777.48	2.01428
2780.14	1.42274
2782.8	1.87361
2785.47	2.22393
2788.13	2.26526
2790.79	2.39201
2793.45	2.90666
2796.11	2.58863
2798.77	2.7824
2801.43	2.46123
2804.09	3.10196
2806.74	3.28737
2809.4	2.57971
2812.05	2.89803
2814.71	2.63406
2817.36	3.35269
2820.01	5.24279
2822.66	6.37306
2825.31	8.5248
2827.96	10.0528
2830.6	11.9744
2833.25	14.946
2835.9	17.8062
2838.54	20.9918
2841.18	22.5016
2843.83	24.7293
2846.47	28.6219
2849.11	31.4447
2851.75	34.8695
2854.39	37.7882
2857.03	41.2555
2859.66	44.688
2862.3	47.2014
2864.94	49.7966
2867.57	52.2264
2870.2	52.8954
2872.84	53.7168
2875.47	54.5886
2878.1	55.1681
2880.73	57.554
2883.36	59.3459
2885.99	61.3942
2888.61	62.1468
2891.24	63.0963
2893.86	64.7697
2896.49	66.3437
2899.11	67.4234
2901.73	68.5102
2904.36	70.266
2906.98	72.4948
2909.6	75.754
2912.21	78.9462
2914.83	82.7298
2917.45	86.6058
2920.07	90.2935
2922.68	93.6506
2925.29	96.4374
2927.91	98.6877
2930.52	99.2255
2933.13	99.0153
2935.74	98.9407
2938.35	98.0283
2940.96	96.4513
2943.57	94.853
2946.18	92.1544
2948.78	89.1072
2951.39	85.6638
2953.99	81.1153
2956.59	76.8741
2959.2	72.173
2961.8	67.6287
2964.4	63.8521
2967	60.0595
2969.6	57.0896
2972.19	54.0148
2974.79	50.3128
2977.39	48.1668
2979.98	45.1858
2982.58	42.1228
2985.17	38.8
2987.76	35.7529
2990.35	32.7586
2992.94	28.4192
2995.53	26.7518
2998.12	24.0331
3000.71	21.0679
3003.3	18.4426
3005.88	16.415
3008.47	14.9081
3011.05	13.0436
3013.64	11.7051
3016.22	9.53925
3018.8	9.25514
3021.38	7.97946
3023.96	6.76017
3026.54	6.34923
3029.12	6.50624
3031.69	6.30298
3034.27	5.99419
3036.84	6.12481
3039.42	6.12879
3041.99	5.51792
3044.57	4.96082
3047.14	4.18733
3049.71	3.96414
3052.28	3.72863
3054.85	3.33743
3057.41	3.20455
3059.98	2.13859
3062.55	1.06802
3065.11	1.04765
3067.68	1.21105
3070.24	1.40169
3072.8	1.92843
3075.36	2.57384
3077.93	2.68208
3080.49	2.83505
3083.04	2.79436
3085.6	1.77716
3088.16	2.10649
3090.72	3.10454
3093.27	3.19005
3095.83	3.63884
3098.38	5.20268
3100.93	5.69854
3103.49	6.47268
3106.04	7.2344
3108.59	7.58758
3111.14	7.98675
3113.69	7.78617
3116.23	7.61967
3118.78	8.37802
3121.33	8.54292
3123.87	8.70621
3126.41	9.66661
3128.96	10.8382
3131.5	12.0331
3134.04	12.7483
3136.58	14.5103
3139.12	14.7536
3141.66	15.6364
3144.2	17.1516
3146.74	19.1808
3149.27	22.3941