File: data/Raman/poly_smoothed/Mb_30_27_29_1x_45s_532 nm_x100_100%_600 gr_mm_01.txt
#Acq. time (s)=	45
#Accumulations=	2
#Range (cm-¹)=	200...3150
#Windows=	2
#Auto scanning=	Off
#Autofocus=	Off
#Macrospot=	Off
#AutoExposure=	Off
#Spike filter=	Multiple accum.
#Delay time (s)=	0
#Binning=	1
#Readout mode=	Signal
#DeNoise=	Off
#ICS correction=	On
#Dark correction=	Off
#Inst. Process=	Off
#Detector Gain=	Best Dynamic Range
#Detector ADC=	20 kHz
#Detector temperature (°C)=	-69.85
#Instrument=	LabRAM HR Evol
#Detector=	Synapse
#Objective=	x100
#Grating=	600 gr/mm
#ND Filter=	100%
#Laser (nm)=	532
#Hole=	100.021
#Range=	Auto
#Laser Pol.=	No
#Raman. Pol.=	No
#Laser Pol. (°)=	-0.0007625
#Raman Pol. (°)=	89.9995
#Collection=	Microscope
#StageXY=	Marzhauser
#StageZ=	Marzhauser
#X (µm)=	-6384
#Y (µm)=	833
#Z (µm)=	-64.35
#Full time(mm:ss)=	3:18
#Project=
#Sample=
#Site=
#Title=	Mb_30_27_29_2x_45s_532 nm_x100_100%_600 gr_mm
#Remark=
#Date=	13.07.2022 10:53
#Acquired=	13.07.2022 10:53:32
#Base:Fit=	10.08.2022 10:40:03
#Base:Sub=	10.08.2022 10:40:17
#Filter:Polynom=	16.08.2022 10:16:15
#AxisType[0]=Intens
#AxisUnit[0]=Cnt
#AxisType[1]=Spectr
#AxisUnit[1]=1/cm
200.563	7.12093
204.194	7.13998
207.821	5.15814
211.449	4.0166
215.074	3.06116
218.699	4.16602
222.321	5.61552
225.941	5.49198
229.562	7.3008
233.18	7.477
236.796	6.36192
240.411	5.13241
244.026	5.31816
247.638	5.28106
251.248	5.94847
254.857	5.95381
258.465	7.30967
262.071	8.16922
265.678	8.04224
269.282	9.05865
272.884	11.2786
276.484	12.1823
280.084	13.1016
283.682	14.6047
287.276	17.2281
290.871	18.5894
294.465	18.5839
298.057	20.4848
301.648	22.7614
305.237	24.2735
308.823	26.0734
312.41	27.2569
315.995	26.3995
319.579	26.2625
323.16	24.5288
326.741	24.4514
330.321	25.2382
333.897	25.9602
337.474	25.1346
341.048	25.7678
344.622	24.2907
348.192	23.9002
351.764	23.3939
355.332	23.219
358.901	25.5399
362.466	25.5555
366.03	25.9029
369.594	24.6544
373.155	24.6487
376.715	23.9218
380.273	23.5699
383.832	23.6603
387.388	24.1705
390.942	21.7258
394.495	20.4642
398.047	18.6272
401.597	18.2166
405.145	16.9385
408.693	16.5924
412.239	16.1165
415.783	17.1152
419.327	14.7358
422.869	12.7325
426.409	12.3967
429.948	10.9987
433.486	10.0716
437.022	9.18081
440.558	9.80988
444.089	10.5763
447.622	10.8129
451.153	11.6804
454.682	12.838
458.208	13.3208
461.735	16.7858
465.259	18.5272
468.783	20.2517
472.306	20.5624
475.825	20.6021
479.346	22.5675
482.862	23.2561
486.38	24.3427
489.894	25.9189
493.407	26.6103
496.92	27.5189
500.43	27.2907
503.939	27.2624
507.448	27.0242
510.954	28.407
514.459	27.333
517.962	27.0531
521.466	27.5867
524.966	26.0915
528.466	24.7923
531.964	23.5346
535.46	21.9094
538.955	22.166
542.449	21.1903
545.942	20.6686
549.433	20.5609
552.923	19.7817
556.412	18.1737
559.899	17.7289
563.385	16.1093
566.867	14.4453
570.35	12.5681
573.832	10.4929
577.313	9.75112
580.79	9.00256
584.268	8.23405
587.745	8.1484
591.218	7.57869
594.692	6.84163
598.164	4.74933
601.634	4.29113
605.104	3.66951
608.57	2.46706
612.037	1.90312
615.501	2.24
618.966	3.62264
622.427	4.11521
625.887	5.54874
629.348	7.11265
632.806	9.6204
636.262	11.0593
639.716	12.251
643.172	14.1895
646.624	13.2076
650.075	13.7285
653.524	15.1475
656.972	15.7221
660.419	17.2941
663.865	18.0296
667.309	18.8877
670.752	19.2159
674.194	18.4631
677.634	18.6072
681.073	19.4429
684.511	20.97
687.947	22.8422
691.382	23.6211
694.816	26.1235
698.247	28.1502
701.678	29.8262
705.108	30.2245
708.534	31.8545
711.962	34.3428
715.388	34.7768
718.81	36.3704
722.234	37.4093
725.654	37.8694
729.075	37.4476
732.492	36.9984
735.91	38.3297
739.325	38.1331
742.741	38.609
746.153	40.4391
749.564	42.3458
752.976	43.1503
756.385	45.6383
759.792	48.4071
763.2	51.6092
766.604	54.0222
770.008	58.0957
773.41	61.202
776.811	65.3912
780.21	67.176
783.608	69.1437
787.005	72.7647
790.401	75.0539
793.795	77.9543
797.188	80.1778
800.58	82.9083
803.971	82.8731
807.36	83.4142
810.748	82.1203
814.135	82.1817
817.518	82.3486
820.902	81.3677
824.285	81.3532
827.665	80.8355
831.045	80.7782
834.424	77.4316
837.8	75.0531
841.177	73.4977
844.55	70.6926
847.924	67.754
851.295	64.1928
854.666	62.5977
858.034	59.6871
861.403	57.1886
864.769	53.8012
868.133	52.0168
871.498	51.5415
874.86	49.5832
878.221	49.3754
881.58	48.143
884.938	46.3608
888.297	44.9976
891.653	43.5125
895.007	43.3428
898.36	44.7546
901.712	44.057
905.063	43.8787
908.412	45.2956
911.76	44.1476
915.107	44.3825
918.452	43.4513
921.797	43.6324
925.138	43.5071
928.48	42.0883
931.82	40.5663
935.16	40.5544
938.496	39.2547
941.833	38.2042
945.168	35.9276
948.5	34.4136
951.834	33.8792
955.163	32.1952
958.494	31.0113
961.821	29.3191
965.15	28.2279
968.474	28.3761
971.8	27.3089
975.123	27.9507
978.446	26.5442
981.766	26.5764
985.084	27.5036
988.402	27.7363
991.72	28.1863
995.035	26.8607
998.349	26.8601
1001.66	25.6461
1004.97	25.9398
1008.28	27.0417
1011.59	30.1024
1014.9	34.8579
1018.21	39.4099
1021.51	41.6957
1024.81	44.5752
1028.12	46.0275
1031.42	48.4466
1034.72	49.702
1038.02	50.6967
1041.31	51.3004
1044.61	50.3147
1047.91	49.2423
1051.2	47.9168
1054.49	44.1658
1057.78	40.3492
1061.07	37.1248
1064.36	33.9597
1067.65	28.5094
1070.93	23.4952
1074.22	18.2173
1077.5	14.087
1080.78	10.0676
1084.06	8.50745
1087.34	8.50706
1090.62	10.2209
1093.9	11.7863
1097.17	12.7064
1100.45	13.3826
1103.72	14.7764
1106.99	17.554
1110.27	17.935
1113.53	20.0309
1116.8	18.7978
1120.07	18.3093
1123.33	16.814
1126.6	16.9297
1129.86	16.3931
1133.12	16.1501
1136.38	15.5058
1139.64	13.6292
1142.9	12.5815
1146.16	11.69
1149.41	9.16489
1152.67	7.14568
1155.92	5.31507
1159.17	3.88129
1162.42	2.75595
1165.67	1.86992
1168.92	2.09341
1172.16	2.60253
1175.41	4.14451
1178.65	6.07091
1181.9	6.19248
1185.14	6.57272
1188.38	6.87963
1191.62	7.13192
1194.86	7.05478
1198.09	7.64437
1201.33	9.96734
1204.56	14.1866
1207.8	16.5174
1211.03	19.3934
1214.26	21.7419
1217.49	23.2187
1220.71	24.7422
1223.94	27.1369
1227.16	28.3946
1230.39	28.4329
1233.61	29.9025
1236.83	32.1091
1240.05	33.4612
1243.27	34.9277
1246.49	36.4441
1249.71	37.3744
1252.92	39.0161
1256.14	40.4567
1259.35	40.4688
1262.56	41.9005
1265.77	43.4793
1268.98	44.3624
1272.19	45.8115
1275.4	47.2162
1278.6	49.28
1281.81	51.6536
1285.01	51.9502
1288.21	52.2718
1291.41	52.6596
1294.61	54.4734
1297.81	54.6595
1301.01	57.14
1304.2	59.1705
1307.4	61.7726
1310.59	63.2786
1313.78	64.1812
1316.97	64.8583
1320.16	66.4932
1323.35	66.7324
1326.54	66.2349
1329.72	66.362
1332.91	67.8143
1336.09	66.3539
1339.27	64.446
1342.45	62.7002
1345.64	59.9863
1348.81	57.7143
1351.99	54.7388
1355.17	51.1356
1358.34	48.4178
1361.51	44.5139
1364.69	40.0829
1367.86	37.968
1371.03	37.9739
1374.2	35.9877
1377.37	34.8615
1380.53	34.6415
1383.7	34.2795
1386.86	33.0264
1390.02	32.5457
1393.19	33.0357
1396.35	33.2036
1399.51	31.9428
1402.66	33.416
1405.82	35.0825
1408.97	36.5161
1412.13	38.1038
1415.28	38.9861
1418.43	41.0813
1421.59	43.1961
1424.73	47.3131
1427.88	49.7947
1431.03	51.3894
1434.18	55.3982
1437.32	58.4102
1440.46	60.193
1443.61	62.31
1446.75	63.1618
1449.89	63.2444
1453.03	63.4658
1456.16	62.6798
1459.3	62.0966
1462.44	62.9048
1465.57	61.7654
1468.7	60.2511
1471.83	58.1087
1474.96	54.4596
1478.09	52.3383
1481.22	50.8889
1484.35	47.4374
1487.47	44.5378
1490.6	41.9922
1493.72	37.4604
1496.84	34.6475
1499.96	31.8924
1503.08	29.1086
1506.2	26.1705
1509.32	24.3967
1512.44	23.228
1515.55	20.924
1518.66	18.44
1521.78	16.1248
1524.89	16.7697
1528	16.5415
1531.11	16.6107
1534.21	18.1188
1537.32	19.3268
1540.43	20.9828
1543.53	21.9904
1546.63	22.9333
1549.74	24.3089
1552.84	25.5162
1555.94	26.8246
1559.03	28.0491
1562.13	27.8081
1565.23	30.4255
1568.32	31.661
1571.42	32.0167
1574.51	34.1232
1577.6	35.923
1580.69	37.0219
1583.78	38.239
1586.87	41.1138
1589.95	42.4479
1593.04	44.2083
1596.12	45.7956
1599.21	47.9742
1602.29	49.4017
1605.37	51.1013
1608.45	51.4465
1611.53	51.6458
1614.6	52.9661
1617.68	52.9262
1620.75	53.9678
1623.83	55.0444
1626.9	57.4277
1629.97	59.0342
1633.04	60.8189
1636.11	62.7635
1639.18	65.7196
1642.25	68.4593
1645.31	70.0232
1648.38	72.7471
1651.44	74.0031
1654.5	75.3725
1657.56	75.9296
1660.62	75.6346
1663.68	74.2294
1666.74	72.3484
1669.8	68.7468
1672.85	65.6415
1675.91	62.483
1678.96	58.351
1682.01	53.0522
1685.06	47.6714
1688.11	42.9373
1691.16	38.3942
1694.21	33.4859
1697.25	29.9538
1700.3	25.4637
1703.34	22.575
1706.39	18.5421
1709.43	15.6376
1712.47	13.5423
1715.51	12.3094
1718.54	11.4328
1721.58	10.1182
1724.62	9.65438
1727.65	8.46999
1730.68	8.2193
1733.72	7.55802
1736.75	6.62638
1739.78	6.82869
1742.81	6.04289
1745.84	5.07924
1748.86	5.72426
1751.89	5.97712
1754.91	6.07645
1757.93	6.1819
1760.96	5.19361
1763.98	5.32174
1767	3.69425
1770.02	2.96692
1773.03	2.86903
1776.05	2.60799
1779.07	2.29832
1782.08	1.61951
1785.09	1.81446
1788.11	1.63427
1791.12	1.10432
1794.13	1.01341
1797.13	0.655269
1800.14	1.16238
1803.15	1.08366
1806.15	1.33065
1809.16	1.37365
1812.16	1.35951
1815.16	0.849628
1818.16	0.287241
1821.16	0.507105
1824.16	1.69522
1827.16	1.24544
1830.16	1.07843
1833.15	0.729727
1836.14	-0.289815
1839.14	-0.361713
1842.13	-0.51851
1845.12	0.11932
1848.11	-0.328023
1851.1	-0.433142
1854.08	0.148838
1857.07	0.967739
1860.05	0.624077
1863.04	0.649332
1866.02	0.496186
1869	1.39686
1871.98	1.39917
1874.96	1.75424
1877.94	2.0369
1880.92	2.54076
1882.51	2.5636
1885.5	2.49673
1888.48	2.66048
1891.47	2.69829
1894.46	3.54788
1897.44	3.31142
1900.42	3.65693
1903.41	4.00669
1906.39	4.35815
1909.37	4.51949
1912.35	5.30319
1915.32	6.07384
1918.3	5.70366
1921.27	6.50576
1924.25	7.02334
1927.22	7.68138
1930.19	6.11829
1933.17	6.51345
1936.14	6.27391
1939.11	6.61573
1942.07	7.1297
1945.04	6.13526
1948.01	6.221
1950.97	6.72321
1953.93	7.50731
1956.9	7.48481
1959.86	7.34559
1962.82	6.58817
1965.78	6.68192
1968.74	6.49573
1971.69	6.11922
1974.65	6.25715
1977.6	6.24126
1980.56	5.54903
1983.51	5.20411
1986.46	4.85569
1989.41	5.18464
1992.36	4.48702
1995.31	4.75104
1998.26	4.60393
2001.2	4.80951
2004.15	5.85028
2007.09	6.44701
2010.04	7.35335
2012.98	8.04289
2015.92	7.85357
2018.86	9.88963
2021.8	10.2446
2024.73	10.6721
2027.67	10.4951
2030.61	10.0185
2033.54	10.5196
2036.47	11.1617
2039.4	11.647
2042.33	10.6222
2045.27	11.7454
2048.19	12.4003
2051.12	11.541
2054.05	11.2976
2056.97	11.758
2059.9	12.68
2062.82	12.9354
2065.74	14.076
2068.67	15.1722
2071.59	15.3064
2074.51	15.9283
2077.42	17.4704
2080.34	18.0938
2083.26	19.0795
2086.17	19.8846
2089.09	20.4323
2092	21.462
2094.91	21.6848
2097.82	23.5488
2100.73	24.5999
2103.64	26.3456
2106.55	28.4498
2109.45	29.9784
2112.36	30.4053
2115.26	32.0198
2118.17	34.4701
2121.07	36.1856
2123.97	38.3915
2126.87	40.6598
2129.77	43.5741
2132.67	47.3675
2135.56	50.2284
2138.46	53.7108
2141.35	56.7025
2144.25	59.6042
2147.14	63.5903
2150.03	67.4609
2152.92	71.4157
2155.81	74.5371
2158.7	78.0694
2161.59	82.1186
2164.47	84.682
2167.36	87.0335
2170.24	88.6323
2173.13	89.068
2176.01	89.9531
2178.89	89.7559
2181.77	87.6197
2184.65	85.6761
2187.53	84.6119
2190.4	82.5068
2193.28	79.4364
2196.16	76.0259
2199.03	72.2482
2201.9	69.2049
2204.77	65.3995
2207.64	61.1837
2210.51	57
2213.38	52.4603
2216.25	48.5825
2219.12	45.3558
2221.98	42.292
2224.85	40.0947
2227.71	37.5148
2230.57	35.1029
2233.43	32.5998
2236.29	30.9587
2239.15	29.0386
2242.01	26.5176
2244.87	24.5537
2247.72	23.4718
2250.58	21.9948
2253.43	21.7174
2256.29	21.0867
2259.14	21.1414
2261.99	20.0546
2264.84	19.2605
2267.69	18.0131
2270.53	17.8385
2273.38	17.0678
2276.23	16.1816
2279.07	15.3989
2281.91	14.5617
2284.76	13.6607
2287.6	13.2944
2290.44	12.5677
2293.28	11.7112
2296.12	10.8991
2298.96	10.0211
2301.79	9.52243
2304.63	9.64764
2307.46	9.10388
2310.3	8.29183
2313.13	8.39712
2315.96	8.50135
2318.79	8.69285
2321.62	7.89644
2324.45	8.24221
2327.27	8.24146
2330.1	7.67992
2332.92	6.88269
2335.75	6.43652
2338.57	5.52337
2341.39	4.74929
2344.21	4.93292
2347.04	5.32834
2349.85	3.82139
2352.67	2.84027
2355.49	2.14384
2358.3	1.48996
2361.12	0.116805
2363.93	-0.613931
2366.75	-0.812511
2369.56	-0.989271
2372.37	-0.250595
2375.18	-0.103019
2377.99	-0.336641
2380.8	-0.496445
2383.6	-0.678796
2386.41	-0.925962
2389.21	-0.662758
2392.02	-0.178188
2394.82	0.255013
2397.62	0.944162
2400.42	2.01844
2403.22	2.41235
2406.02	2.61658
2408.82	3.0307
2411.62	3.94937
2414.41	5.22952
2417.21	5.14412
2420	5.4436
2422.79	5.88566
2425.59	6.10063
2428.38	5.7092
2431.17	5.53324
2433.95	4.91805
2436.74	5.64198
2439.53	5.1446
2442.31	5.05037
2445.1	3.99335
2447.88	4.10668
2450.67	3.91379
2453.45	4.55702
2456.23	4.94154
2459.01	5.01298
2461.79	5.41876
2464.57	5.55472
2467.34	5.68074
2470.12	6.02122
2472.89	6.18807
2475.67	7.50822
2478.44	8.06243
2481.21	7.71725
2483.98	7.71868
2486.75	6.42305
2489.52	6.20296
2492.29	6.12486
2495.05	5.35997
2497.82	5.16228
2500.58	4.72249
2503.35	4.23607
2506.11	4.06841
2508.87	3.35968
2511.63	3.63651
2514.39	3.52242
2517.15	3.78082
2519.91	3.11866
2522.67	3.68913
2525.42	3.84096
2528.18	3.99169
2530.93	3.13369
2533.69	3.43818
2536.44	4.15217
2539.19	4.92725
2541.94	4.94739
2544.69	4.99083
2547.44	4.40067
2550.18	3.29138
2552.93	2.86343
2555.67	3.29833
2558.42	3.10901
2561.16	2.53993
2563.9	2.34394
2566.64	2.01216
2569.38	2.38983
2572.12	1.91717
2574.86	2.5254
2577.6	2.44331
2580.33	2.33209
2583.07	2.37494
2585.8	1.68174
2588.54	1.89463
2591.27	3.69603
2594	2.74314
2596.73	3.03513
2599.46	3.99997
2602.19	5.46223
2604.92	6.18751
2607.64	6.53198
2610.37	6.16503
2613.09	6.18578
2615.82	5.69441
2618.54	4.92108
2621.26	4.87782
2623.98	4.82119
2626.7	3.83796
2629.42	4.58162
2632.14	4.52786
2634.86	3.65961
2637.57	3.43361
2640.29	3.23428
2643	2.82404
2645.71	2.12852
2648.43	1.80592
2651.14	2.53131
2653.85	3.09503
2656.56	3.29195
2659.26	3.4857
2661.97	4.02404
2664.68	5.31731
2667.38	6.70156
2670.09	6.52447
2672.79	6.80748
2675.49	6.25214
2678.19	6.00956
2680.89	5.21812
2683.59	4.67118
2686.29	4.52555
2688.99	4.81057
2691.69	3.46854
2694.38	2.75139
2697.08	2.76677
2699.77	2.92524
2702.46	3.3287
2705.15	2.97298
2707.85	2.85421
2710.54	3.51586
2713.22	4.43847
2715.91	5.4535
2718.6	6.03804
2721.29	6.09749
2723.97	6.86192
2726.66	7.46511
2729.34	7.32978
2732.02	7.81799
2734.7	7.60683
2737.38	7.87017
2740.06	7.58557
2742.74	7.83836
2745.42	7.36731
2748.09	7.23061
2750.77	7.35471
2753.45	6.79476
2756.12	6.07774
2758.79	5.28853
2761.46	5.5623
2764.14	5.67997
2766.8	5.39231
2769.47	5.4235
2772.14	5.29555
2774.81	5.91415
2777.48	6.23452
2780.14	6.37127
2782.8	6.35396
2785.47	5.15828
2788.13	4.00453
2790.79	2.97099
2793.45	2.27349
2796.11	1.92245
2798.77	1.11103
2801.43	1.28898
2804.09	0.650362
2806.74	0.768962
2809.4	1.44482
2812.05	1.95059
2814.71	3.12536
2817.36	4.19116
2820.01	5.31715
2822.66	7.64215
2825.31	10.2404
2827.96	13.1096
2830.6	16.3894
2833.25	19.5982
2835.9	23.9331
2838.54	28.9651
2841.18	33.6113
2843.83	39.4022
2846.47	45.3071
2849.11	51.4375
2851.75	57.684
2854.39	64.6744
2857.03	73.1243
2859.66	79.3643
2862.3	85.0181
2864.94	91.3767
2867.57	96.7523
2870.2	101.006
2872.84	106.552
2875.47	111.383
2878.1	116.775
2880.73	119.962
2883.36	123.02
2885.99	127.534
2888.61	130.804
2891.24	134.877
2893.86	139.62
2896.49	145.022
2899.11	152.252
2901.73	159.918
2904.36	169.344
2906.98	179.871
2909.6	191.833
2912.21	204.211
2914.83	216.555
2917.45	228.508
2920.07	240.094
2922.68	249.394
2925.29	256.919
2927.91	263.087
2930.52	265.967
2933.13	267.185
2935.74	267.591
2938.35	266.614
2940.96	262.933
2943.57	256.213
2946.18	249.065
2948.78	240.749
2951.39	231.142
2953.99	220.589
2956.59	210.678
2959.2	199.959
2961.8	187.691
2964.4	177.399
2967	167.116
2969.6	158.123
2972.19	148.712
2974.79	139.757
2977.39	130.813
2979.98	120.631
2982.58	112.366
2985.17	104.044
2987.76	95.0337
2990.35	86.7173
2992.94	77.2718
2995.53	68.9012
2998.12	61.0678
3000.71	54.7805
3003.3	47.9125
3005.88	41.9704
3008.47	37.3823
3011.05	32.7183
3013.64	28.4998
3016.22	24.687
3018.8	21.7237
3021.38	19.234
3023.96	16.6379
3026.54	14.5925
3029.12	14.1073
3031.69	13.6992
3034.27	12.6651
3036.84	12.7184
3039.42	12.5317
3041.99	12.7468
3044.57	13.7208
3047.14	15.725
3049.71	15.3764
3052.28	16.1985
3054.85	15.8117
3057.41	15.1621
3059.98	15.0177
3062.55	14.6694
3065.11	13.6699
3067.68	13.4815
3070.24	13.4036
3072.8	12.1967
3075.36	10.2897
3077.93	9.08578
3080.49	7.21912
3083.04	5.89839
3085.6	5.24886
3088.16	3.66205
3090.72	1.9676
3093.27	0.576453
3095.83	0.399534
3098.38	0.0258694
3100.93	0.328036
3103.49	0.380826
3106.04	0.474084
3108.59	1.12535
3111.14	1.46408
3113.69	1.52546
3116.23	2.04091
3118.78	1.55143
3121.33	1.96908
3123.87	2.93225
3126.41	3.34916
3128.96	4.3619
3131.5	4.98536
3134.04	4.85445
3136.58	4.77568
3139.12	5.41057
3141.66	6.15077
3144.2	6.7525
3146.74	7.72184
3149.27	8.53408