File: data/Raman/poly_smoothed/Mb_30_27_47_1x_45s_532 nm_x100_100%_600 gr_mm_01.txt
#Acq. time (s)=	45
#Accumulations=	2
#Range (cm-¹)=	200...3150
#Windows=	2
#Auto scanning=	Off
#Autofocus=	Off
#Macrospot=	Off
#AutoExposure=	Off
#Spike filter=	Multiple accum.
#Delay time (s)=	0
#Binning=	1
#Readout mode=	Signal
#DeNoise=	Off
#ICS correction=	On
#Dark correction=	Off
#Inst. Process=	Off
#Detector Gain=	Best Dynamic Range
#Detector ADC=	20 kHz
#Detector temperature (°C)=	-69.85
#Instrument=	LabRAM HR Evol
#Detector=	Synapse
#Objective=	x100
#Grating=	600 gr/mm
#ND Filter=	100%
#Laser (nm)=	532
#Hole=	100.021
#Range=	Auto
#Laser Pol.=	No
#Raman. Pol.=	No
#Laser Pol. (°)=	-0.0007625
#Raman Pol. (°)=	89.9995
#Collection=	Microscope
#StageXY=	Marzhauser
#StageZ=	Marzhauser
#X (µm)=	-6370
#Y (µm)=	777
#Z (µm)=	-65.1
#Full time(mm:ss)=	3:18
#Project=
#Sample=
#Site=
#Title=	Mb_30_27_47_2x_45s_532 nm_x100_100%_600 gr_mm
#Remark=
#Date=	13.07.2022 12:17
#Acquired=	13.07.2022 12:17:53
#Base:Fit=	10.08.2022 10:40:03
#Base:Sub=	10.08.2022 10:40:17
#Filter:Polynom=	16.08.2022 10:16:15
#AxisType[0]=Intens
#AxisUnit[0]=Cnt
#AxisType[1]=Spectr
#AxisUnit[1]=1/cm
200.563	17.4947
204.194	16.0349
207.821	12.7993
211.449	9.63246
215.074	8.1937
218.699	6.07194
222.321	5.25142
225.941	5.84426
229.562	4.2759
233.18	3.71115
236.796	3.45491
240.411	3.64418
244.026	3.72604
247.638	4.47431
251.248	5.60503
254.857	6.75291
258.465	6.49707
262.071	7.56136
265.678	7.87238
269.282	8.03616
272.884	10.8151
276.484	10.9966
280.084	12.4536
283.682	13.0204
287.276	12.7624
290.871	12.6221
294.465	12.0396
298.057	12.619
301.648	13.2106
305.237	11.878
308.823	11.0538
312.41	11.8562
315.995	10.7254
319.579	10.6542
323.16	10.6849
326.741	10.5693
330.321	11.4118
333.897	9.74288
337.474	9.89687
341.048	9.75724
344.622	8.62098
348.192	7.18217
351.764	7.21989
355.332	6.63639
358.901	6.73381
362.466	6.86937
366.03	7.02922
369.594	6.53401
373.155	6.69167
376.715	7.83656
380.273	8.42205
383.832	7.76993
387.388	8.14716
390.942	6.43309
394.495	7.08239
398.047	7.10921
401.597	6.13225
405.145	7.20617
408.693	9.38176
412.239	10.1889
415.783	11.3159
419.327	11.1652
422.869	9.77996
426.409	9.46917
429.948	9.79515
433.486	9.00425
437.022	7.80286
440.558	8.9928
444.089	8.97085
447.622	9.15903
451.153	11.6139
454.682	11.5094
458.208	12.7862
461.735	14.1824
465.259	14.3732
468.783	14.3869
472.306	13.6431
475.825	15.7169
479.346	16.2665
482.862	16.1589
486.38	17.4589
489.894	17.6779
493.407	20.7035
496.92	22.0361
500.43	22.0978
503.939	20.9242
507.448	19.7782
510.954	19.6999
514.459	20.3947
517.962	20.8786
521.466	21.7473
524.966	21.0372
528.466	21.8747
531.964	20.463
535.46	19.508
538.955	18.0182
542.449	15.9761
545.942	14.6874
549.433	12.8133
552.923	11.977
556.412	11.6035
559.899	9.67398
563.385	8.38383
566.867	5.53636
570.35	4.72526
573.832	3.7455
577.313	4.34026
580.79	4.71686
584.268	3.55551
587.745	2.81783
591.218	2.45692
594.692	3.32248
598.164	3.62229
601.634	4.08
605.104	5.45834
608.57	7.05047
612.037	7.00815
615.501	7.80112
618.966	6.93867
622.427	6.65949
625.887	6.33367
629.348	5.87733
632.806	7.15337
636.262	6.51986
639.716	5.4311
643.172	6.20776
646.624	4.82686
650.075	5.00343
653.524	6.40835
656.972	8.76549
660.419	10.5696
663.865	13.1064
667.309	13.6679
670.752	15.0031
674.194	17.4709
677.634	19.1439
681.073	21.3489
684.511	23.2287
687.947	26.126
691.382	29.3826
694.816	30.7676
698.247	32.7445
701.678	34.8527
705.108	34.8547
708.534	37.4022
711.962	39.0315
715.388	39.5865
718.81	40.5121
722.234	40.4638
725.654	41.4424
729.075	42.6585
732.492	44.0742
735.91	46.9952
739.325	48.0912
742.741	49.4325
746.153	52.5967
749.564	54.0305
752.976	56.4322
756.385	59.2711
759.792	61.371
763.2	62.694
766.604	65.7076
770.008	68.2665
773.41	71.8839
776.811	74.0331
780.21	76.1466
783.608	77.9159
787.005	79.7028
790.401	79.4055
793.795	81.0631
797.188	80.2575
800.58	80.5049
803.971	79.5767
807.36	79.9199
810.748	79.1725
814.135	78.3203
817.518	76.8274
820.902	75.3747
824.285	74.7361
827.665	74.7279
831.045	74.7459
834.424	73.3091
837.8	72.4925
841.177	72.3343
844.55	71.4509
847.924	70.4282
851.295	69.2223
854.666	67.3531
858.034	65.6125
861.403	65.4173
864.769	65.2511
868.133	63.3607
871.498	60.9251
874.86	61.4093
878.221	61.3711
881.58	60.9632
884.938	59.3695
888.297	59.4929
891.653	59.9899
895.007	61.1161
898.36	58.0537
901.712	57.3418
905.063	57.2042
908.412	55.8626
911.76	56.4695
915.107	55.4363
918.452	54.1776
921.797	54.0621
925.138	52.2687
928.48	51.1334
931.82	48.7115
935.16	46.9254
938.496	46.345
941.833	44.6733
945.168	42.239
948.5	40.3519
951.834	39.1734
955.163	38.6438
958.494	38.6304
961.821	36.0063
965.15	34.083
968.474	33.7706
971.8	34.6305
975.123	33.3484
978.446	31.6734
981.766	28.608
985.084	28.7436
988.402	29.2969
991.72	28.8377
995.035	28.3986
998.349	28.0431
1001.66	27.3233
1004.97	26.6302
1008.28	27.0882
1011.59	27.9024
1014.9	30.1044
1018.21	31.7254
1021.51	32.7415
1024.81	33.6028
1028.12	35.3626
1031.42	37.0526
1034.72	38.0791
1038.02	37.7838
1041.31	38.0275
1044.61	35.6429
1047.91	34.8032
1051.2	33.346
1054.49	31.6696
1057.78	29.7521
1061.07	26.949
1064.36	24.5234
1067.65	21.2624
1070.93	17.3819
1074.22	16.1874
1077.5	14.827
1080.78	11.9556
1084.06	10.8544
1087.34	12.1199
1090.62	13.0998
1093.9	13.9034
1097.17	15.2674
1100.45	15.5575
1103.72	16.3906
1106.99	17.1721
1110.27	17.8722
1113.53	17.5107
1116.8	17.3712
1120.07	16.899
1123.33	15.6263
1126.6	13.6295
1129.86	13.1109
1133.12	10.5604
1136.38	10.6253
1139.64	9.2174
1142.9	8.2982
1146.16	6.99716
1149.41	5.45925
1152.67	4.90984
1155.92	5.61828
1159.17	4.78637
1162.42	3.46589
1165.67	3.59775
1168.92	2.69719
1172.16	2.30262
1175.41	3.03897
1178.65	2.97638
1181.9	3.36648
1185.14	2.17164
1188.38	2.24784
1191.62	2.94541
1194.86	4.03423
1198.09	5.65109
1201.33	6.64922
1204.56	7.302
1207.8	8.61389
1211.03	12.1736
1214.26	14.4317
1217.49	18.187
1220.71	20.8549
1223.94	23.3808
1227.16	25.5077
1230.39	27.5675
1233.61	29.8453
1236.83	32.5648
1240.05	35.0841
1243.27	37.8743
1246.49	40.2388
1249.71	42.4213
1252.92	43.0962
1256.14	44.5481
1259.35	44.4802
1262.56	44.6208
1265.77	45.0575
1268.98	47.2166
1272.19	48.9886
1275.4	51.0312
1278.6	52.3096
1281.81	51.3513
1285.01	52.6107
1288.21	53.4667
1291.41	52.5215
1294.61	53.0704
1297.81	54.0862
1301.01	53.2939
1304.2	54.0396
1307.4	53.3445
1310.59	54.5042
1313.78	54.506
1316.97	56.0586
1320.16	55.45
1323.35	53.6477
1326.54	52.5937
1329.72	52.204
1332.91	50.9912
1336.09	49.5412
1339.27	47.0428
1342.45	46.6509
1345.64	46.704
1348.81	46.0305
1351.99	45.304
1355.17	43.3184
1358.34	41.8311
1361.51	39.614
1364.69	37.2818
1367.86	35.447
1371.03	34.8955
1374.2	35.0638
1377.37	33.717
1380.53	32.3745
1383.7	32.7684
1386.86	31.4456
1390.02	29.7408
1393.19	27.8109
1396.35	25.9023
1399.51	25.0023
1402.66	25.3374
1405.82	25.2248
1408.97	25.1169
1412.13	25.5724
1415.28	26.028
1418.43	28.4155
1421.59	30.4482
1424.73	33.0111
1427.88	37.8984
1431.03	42.028
1434.18	46.4358
1437.32	49.4805
1440.46	53.5885
1443.61	55.7659
1446.75	57.4623
1449.89	59.839
1453.03	60.0152
1456.16	58.5435
1459.3	57.2871
1462.44	56.2517
1465.57	52.5379
1468.7	50.3251
1471.83	47.7895
1474.96	44.7946
1478.09	43.2056
1481.22	39.2921
1484.35	36.6719
1487.47	33.9606
1490.6	31.4947
1493.72	29.2763
1496.84	26.5539
1499.96	25.0232
1503.08	25.9325
1506.2	24.9529
1509.32	23.9769
1512.44	23.0121
1515.55	22.26
1518.66	22.4693
1521.78	21.3807
1524.89	19.239
1528	19.59
1531.11	18.6084
1534.21	18.7394
1537.32	20.1442
1540.43	20.3143
1543.53	21.1181
1546.63	23.6865
1549.74	25.3883
1552.84	27.0064
1555.94	27.2854
1559.03	28.3497
1562.13	28.2462
1565.23	29.7951
1568.32	30.3907
1571.42	31.3974
1574.51	33.3932
1577.6	34.4304
1580.69	35.1445
1583.78	36.0434
1586.87	36.4426
1589.95	38.4444
1593.04	39.5749
1596.12	40.6716
1599.21	41.4156
1602.29	40.2266
1605.37	40.8663
1608.45	40.8267
1611.53	41.309
1614.6	42.3763
1617.68	41.6781
1620.75	42.7783
1623.83	44.4024
1626.9	45.1713
1629.97	46.3238
1633.04	47.847
1636.11	49.6724
1639.18	51.86
1642.25	54.1706
1645.31	55.2608
1648.38	57.3084
1651.44	58.5061
1654.5	58.3655
1657.56	58.0366
1660.62	57.8336
1663.68	57.9892
1666.74	57.1353
1669.8	55.6275
1672.85	53.6524
1675.91	50.2527
1678.96	47.7506
1682.01	43.4023
1685.06	41.6469
1688.11	38.351
1691.16	35.3567
1694.21	32.6754
1697.25	31.7266
1700.3	30.7955
1703.34	28.1457
1706.39	25.5392
1709.43	24.2673
1712.47	21.0503
1715.51	19.1479
1718.54	16.5843
1721.58	15.2337
1724.62	13.5229
1727.65	12.4942
1730.68	12.0327
1733.72	12.1217
1736.75	10.7876
1739.78	10.3501
1742.81	9.63117
1745.84	9.94345
1748.86	9.21425
1751.89	8.48097
1754.91	9.13281
1757.93	9.37722
1760.96	9.48975
1763.98	8.88041
1767	9.07054
1770.02	9.16765
1773.03	8.28327
1776.05	6.87485
1779.07	6.43207
1782.08	5.45883
1785.09	5.00681
1788.11	4.5528
1791.12	4.08349
1794.13	4.13868
1797.13	4.27631
1800.14	4.77358
1803.15	5.94463
1806.15	5.6938
1809.16	5.66777
1812.16	5.24536
1815.16	5.54095
1818.16	6.44732
1821.16	6.73863
1824.16	7.34036
1827.16	6.79963
1830.16	6.60827
1833.15	6.58483
1836.14	6.93369
1839.14	7.39844
1842.13	7.61153
1845.12	7.83709
1848.11	7.20283
1851.1	7.03937
1854.08	6.89459
1857.07	5.84317
1860.05	4.98915
1863.04	4.90146
1866.02	3.75379
1869	3.39582
1871.98	2.82832
1874.96	2.13089
1877.94	1.2686
1880.92	1.1147
1882.51	1.10049
1885.5	0.919576
1888.48	2.01153
1891.47	2.94764
1894.46	3.85716
1897.44	4.81137
1900.42	6.56209
1903.41	8.0786
1906.39	10.372
1909.37	12.1661
1912.35	13.1509
1915.32	13.621
1918.3	13.4609
1921.27	13.8983
1924.25	13.6959
1927.22	13.0031
1930.19	11.4235
1933.17	10.7712
1936.14	10.01
1939.11	7.98833
1942.07	7.17093
1945.04	5.85557
1948.01	5.23528
1950.97	4.34678
1953.93	3.91636
1956.9	2.92127
1959.86	2.99621
1962.82	3.65793
1965.78	2.96885
1968.74	2.12641
1971.69	2.02636
1974.65	2.11451
1977.6	1.93058
1980.56	1.81662
1983.51	1.55018
1986.46	1.16598
1989.41	1.20387
1992.36	1.85883
1995.31	2.65913
1998.26	2.72109
2001.2	2.43485
2004.15	3.60544
2007.09	4.24585
2010.04	4.46277
2012.98	5.5932
2015.92	6.2173
2018.86	6.37086
2021.8	6.31992
2024.73	6.79809
2027.67	7.50774
2030.61	8.53894
2033.54	9.19908
2036.47	9.53785
2039.4	9.80535
2042.33	10.3405
2045.27	10.6046
2048.19	11.0766
2051.12	11.0297
2054.05	11.057
2056.97	11.2204
2059.9	12.6335
2062.82	13.9147
2065.74	13.7169
2068.67	13.5726
2071.59	14.0137
2074.51	13.4592
2077.42	13.3744
2080.34	13.7291
2083.26	13.474
2086.17	13.3842
2089.09	13.1482
2092	13.5584
2094.91	13.3395
2097.82	14.2101
2100.73	14.0438
2103.64	13.4772
2106.55	15.6702
2109.45	16.2008
2112.36	17.0805
2115.26	18.7457
2118.17	20.0605
2121.07	21.4252
2123.97	23.1348
2126.87	25.6155
2129.77	27.28
2132.67	29.5338
2135.56	31.2388
2138.46	33.3081
2141.35	36.7665
2144.25	37.9542
2147.14	40.212
2150.03	42.8855
2152.92	45.4944
2155.81	47.4524
2158.7	49.4466
2161.59	51.152
2164.47	51.7889
2167.36	53.1737
2170.24	54.5002
2173.13	54.9217
2176.01	56.3104
2178.89	56.3846
2181.77	56.2238
2184.65	55.0896
2187.53	54.3311
2190.4	53.5131
2193.28	52.4888
2196.16	51.6701
2199.03	49.4527
2201.9	47.1938
2204.77	45.1929
2207.64	44.105
2210.51	41.2277
2213.38	39.3293
2216.25	36.436
2219.12	34.3255
2221.98	32.0818
2224.85	29.489
2227.71	27.6691
2230.57	26.8955
2233.43	24.9891
2236.29	24.7994
2239.15	23.918
2242.01	22.855
2244.87	20.5549
2247.72	19.3394
2250.58	17.5067
2253.43	16.4401
2256.29	15.9468
2259.14	15.2644
2261.99	14.9639
2264.84	13.714
2267.69	12.9427
2270.53	11.9356
2273.38	11.0429
2276.23	10.9416
2279.07	10.3738
2281.91	10.4721
2284.76	9.86742
2287.6	9.14644
2290.44	8.20278
2293.28	7.27646
2296.12	6.80665
2298.96	8.1747
2301.79	9.59646
2304.63	10.2774
2307.46	10.8724
2310.3	10.8512
2313.13	9.90592
2315.96	10.4963
2318.79	10.9018
2321.62	10.6646
2324.45	10.8243
2327.27	9.97619
2330.1	9.75931
2332.92	8.88523
2335.75	7.84017
2338.57	7.1473
2341.39	5.31037
2344.21	5.35032
2347.04	4.8575
2349.85	4.19373
2352.67	4.10158
2355.49	2.18672
2358.3	1.84529
2361.12	0.545565
2363.93	1.64154
2366.75	2.46377
2369.56	2.51261
2372.37	3.0938
2375.18	3.41687
2377.99	3.04129
2380.8	3.99537
2383.6	4.51675
2386.41	5.52697
2389.21	5.95819
2392.02	6.56743
2394.82	6.7354
2397.62	7.18356
2400.42	6.98599
2403.22	5.81832
2406.02	5.72537
2408.82	5.209
2411.62	4.67323
2414.41	4.42378
2417.21	3.79833
2420	3.48877
2422.79	3.76433
2425.59	4.22329
2428.38	4.25901
2431.17	3.57502
2433.95	2.90305
2436.74	2.7975
2439.53	2.92318
2442.31	2.99517
2445.1	2.90878
2447.88	3.48916
2450.67	3.88675
2453.45	4.51993
2456.23	4.7968
2459.01	5.02492
2461.79	5.01885
2464.57	4.45423
2467.34	4.27744
2470.12	3.26551
2472.89	2.35563
2475.67	2.14765
2478.44	1.77291
2481.21	1.18923
2483.98	1.23138
2486.75	0.3725
2489.52	0.325971
2492.29	0.745322
2495.05	1.09797
2497.82	0.73459
2500.58	0.886518
2503.35	0.716473
2506.11	1.29865
2508.87	1.88219
2511.63	2.18504
2514.39	2.82094
2517.15	2.88323
2519.91	3.2584
2522.67	2.83959
2525.42	2.86196
2528.18	2.85662
2530.93	2.28974
2533.69	1.33593
2536.44	1.06666
2539.19	1.04247
2541.94	1.38952
2544.69	1.21837
2547.44	1.96768
2550.18	1.66681
2552.93	1.34783
2555.67	2.36444
2558.42	2.6226
2561.16	2.85852
2563.9	3.30391
2566.64	3.46637
2569.38	3.15454
2572.12	2.85928
2574.86	3.01329
2577.6	3.15194
2580.33	3.38731
2583.07	3.73791
2585.8	4.78967
2588.54	4.30074
2591.27	3.81497
2594	3.98788
2596.73	3.0549
2599.46	2.88254
2602.19	3.76292
2604.92	3.0398
2607.64	3.76308
2610.37	3.77163
2613.09	4.09498
2615.82	3.65233
2618.54	3.64664
2621.26	3.62314
2623.98	2.73117
2626.7	1.79948
2629.42	1.1332
2632.14	0.965283
2634.86	1.01041
2637.57	0.98511
2640.29	1.86759
2643	3.03515
2645.71	3.67787
2648.43	4.14612
2651.14	4.23383
2653.85	4.52945
2656.56	4.44607
2659.26	4.47097
2661.97	4.95004
2664.68	6.17925
2667.38	5.94052
2670.09	5.96895
2672.79	5.47349
2675.49	5.78105
2678.19	5.76384
2680.89	4.95503
2683.59	4.6273
2686.29	4.05981
2688.99	3.69333
2691.69	3.62666
2694.38	3.59825
2697.08	3.9891
2699.77	4.33036
2702.46	4.37631
2705.15	3.97724
2707.85	4.1397
2710.54	4.06574
2713.22	3.88917
2715.91	4.16322
2718.6	4.13272
2721.29	4.81702
2723.97	4.36124
2726.66	4.0853
2729.34	4.43024
2732.02	4.68786
2734.7	4.53172
2737.38	4.67002
2740.06	4.19578
2742.74	5.03318
2745.42	5.08178
2748.09	5.00279
2750.77	4.55255
2753.45	4.69511
2756.12	4.71565
2758.79	4.77793
2761.46	4.40531
2764.14	4.60859
2766.8	4.08345
2769.47	3.34698
2772.14	3.96642
2774.81	4.06158
2777.48	3.70231
2780.14	2.52106
2782.8	2.14077
2785.47	1.08834
2788.13	1.10505
2790.79	0.154282
2793.45	-0.440536
2796.11	-0.697631
2798.77	0.316229
2801.43	0.34082
2804.09	-0.0640444
2806.74	0.352599
2809.4	0.609912
2812.05	0.318185
2814.71	1.17603
2817.36	1.42063
2820.01	1.66165
2822.66	2.68329
2825.31	3.58403
2827.96	5.20204
2830.6	6.2619
2833.25	8.15694
2835.9	10.1601
2838.54	12.8106
2841.18	15.877
2843.83	18.4971
2846.47	22.1366
2849.11	26.0181
2851.75	30.3193
2854.39	35.4323
2857.03	39.5762
2859.66	44.5006
2862.3	48.7505
2864.94	52.7667
2867.57	56.0445
2870.2	60.2855
2872.84	64.1141
2875.47	67.5151
2878.1	70.3982
2880.73	73.527
2883.36	75.8351
2885.99	78.507
2888.61	81.4706
2891.24	84.8859
2893.86	88.7077
2896.49	93.1186
2899.11	98.7455
2901.73	103.253
2904.36	109.597
2906.98	116.558
2909.6	123.004
2912.21	129.979
2914.83	136.768
2917.45	143.124
2920.07	149.032
2922.68	154.543
2925.29	158.634
2927.91	161.409
2930.52	163.543
2933.13	164.544
2935.74	164.919
2938.35	163.844
2940.96	161.622
2943.57	157.531
2946.18	153.603
2948.78	149.401
2951.39	144.038
2953.99	139.399
2956.59	134.492
2959.2	128.292
2961.8	121.49
2964.4	115.389
2967	108.143
2969.6	102.086
2972.19	94.886
2974.79	87.5813
2977.39	81.016
2979.98	75.019
2982.58	69.0996
2985.17	63.6647
2987.76	58.2349
2990.35	52.8375
2992.94	46.9793
2995.53	41.9867
2998.12	37.3817
3000.71	32.7238
3003.3	28.3562
3005.88	24.4439
3008.47	22.1895
3011.05	20.1768
3013.64	18.336
3016.22	15.9477
3018.8	13.9191
3021.38	11.4086
3023.96	10.5749
3026.54	8.29032
3029.12	7.08691
3031.69	5.99538
3034.27	5.11767
3036.84	3.92825
3039.42	5.07972
3041.99	5.36378
3044.57	5.35728
3047.14	5.94354
3049.71	6.20657
3052.28	6.52228
3054.85	6.13732
3057.41	5.42952
3059.98	5.21524
3062.55	4.85473
3065.11	3.99954
3067.68	4.05329
3070.24	3.34126
3072.8	3.32352
3075.36	2.85401
3077.93	2.49113
3080.49	1.70425
3083.04	1.36551
3085.6	1.05278
3088.16	1.07796
3090.72	0.248679
3093.27	0.605975
3095.83	0.241264
3098.38	1.03074
3100.93	1.53046
3103.49	2.33998
3106.04	2.01712
3108.59	2.29014
3111.14	2.62649
3113.69	3.30156
3116.23	2.54902
3118.78	2.85442
3121.33	3.15356
3123.87	3.84372
3126.41	4.02898
3128.96	4.54159
3131.5	5.06713
3134.04	6.3916
3136.58	8.02708
3139.12	8.7976
3141.66	9.87604
3144.2	10.8625
3146.74	12.0763
3149.27	14.0389