File: data/Raman/poly_smoothed/Mb_30_27_13_1x_45s_532 nm_x100_100%_600 gr_mm_01.txt
#Acq. time (s)=	45
#Accumulations=	2
#Range (cm-¹)=	200...3150
#Windows=	2
#Auto scanning=	Off
#Autofocus=	Off
#Macrospot=	Off
#AutoExposure=	Off
#Spike filter=	Multiple accum.
#Delay time (s)=	0
#Binning=	1
#Readout mode=	Signal
#DeNoise=	Off
#ICS correction=	On
#Dark correction=	Off
#Inst. Process=	Off
#Detector Gain=	Best Dynamic Range
#Detector ADC=	20 kHz
#Detector temperature (°C)=	-69.85
#Instrument=	LabRAM HR Evol
#Detector=	Synapse
#Objective=	x100
#Grating=	600 gr/mm
#ND Filter=	100%
#Laser (nm)=	532
#Hole=	100.021
#Range=	Auto
#Laser Pol.=	No
#Raman. Pol.=	No
#Laser Pol. (°)=	-0.0007625
#Raman Pol. (°)=	89.9995
#Collection=	Microscope
#StageXY=	Marzhauser
#StageZ=	Marzhauser
#X (µm)=	-6413.6
#Y (µm)=	879.5
#Z (µm)=	-64.95
#Full time(mm:ss)=	3:18
#Project=
#Sample=
#Site=
#Title=	Mb_30_27_13_2x_45s_532 nm_x100_100%_600 gr_mm
#Remark=
#Date=	13.07.2022 09:33
#Acquired=	13.07.2022 09:33:49
#Base:Fit=	10.08.2022 10:40:03
#Base:Sub=	10.08.2022 10:40:17
#Filter:Polynom=	16.08.2022 10:16:15
#AxisType[0]=Intens
#AxisUnit[0]=Cnt
#AxisType[1]=Spectr
#AxisUnit[1]=1/cm
200.563	44.6306
204.194	37.1391
207.821	30.8545
211.449	25.1299
215.074	20.8232
218.699	16.4657
222.321	11.5917
225.941	10.0754
229.562	7.47696
233.18	4.90998
236.796	4.65666
240.411	4.51208
244.026	4.33434
247.638	5.23322
251.248	6.51037
254.857	5.96083
258.465	6.544
262.071	6.42677
265.678	5.84748
269.282	7.37576
272.884	8.23955
276.484	8.06088
280.084	6.46937
283.682	7.33587
287.276	7.43577
290.871	8.6134
294.465	9.89173
298.057	11.8475
301.648	13.0437
305.237	15.114
308.823	14.5768
312.41	15.5419
315.995	16.4999
319.579	15.5082
323.16	18.016
326.741	19.1297
330.321	19.7303
333.897	20.0267
337.474	20.1104
341.048	18.9137
344.622	17.6581
348.192	16.0611
351.764	15.7847
355.332	16.9365
358.901	17.4667
362.466	16.9873
366.03	17.8556
369.594	19.7401
373.155	19.4205
376.715	20.2036
380.273	21.063
383.832	23.0568
387.388	23.9972
390.942	24.7684
394.495	25.8535
398.047	24.0657
401.597	22.7914
405.145	22.8527
408.693	22.3731
412.239	21.9731
415.783	21.3747
419.327	19.5124
422.869	18.9824
426.409	17.8124
429.948	16.5698
433.486	16.9727
437.022	16.2607
440.558	17.4684
444.089	18.6329
447.622	18.5411
451.153	19.5613
454.682	21.1341
458.208	21.0921
461.735	20.7655
465.259	20.8788
468.783	22.7467
472.306	24.7848
475.825	24.0335
479.346	25.3733
482.862	25.7048
486.38	25.9423
489.894	26.9759
493.407	29.0625
496.92	32.0355
500.43	33.4624
503.939	33.8902
507.448	34.3807
510.954	35.1046
514.459	36.2968
517.962	37.2151
521.466	37.6761
524.966	38.6381
528.466	38.979
531.964	38.8734
535.46	40.6202
538.955	40.6287
542.449	36.9787
545.942	34.2792
549.433	30.6898
552.923	29.833
556.412	28.0486
559.899	26.4073
563.385	24.198
566.867	21.2744
570.35	20.4765
573.832	18.9238
577.313	18.2445
580.79	18.1771
584.268	16.8951
587.745	12.0488
591.218	11.2536
594.692	9.49322
598.164	10.3541
601.634	10.0837
605.104	9.40731
608.57	10.1377
612.037	10.3397
615.501	11.3506
618.966	12.2904
622.427	12.3273
625.887	11.2336
629.348	11.391
632.806	12.6563
636.262	13.586
639.716	14.2308
643.172	14.5335
646.624	16.621
650.075	17.308
653.524	17.2304
656.972	18.1782
660.419	19.3221
663.865	19.4571
667.309	19.9038
670.752	19.4433
674.194	20.5611
677.634	21.9037
681.073	23.8712
684.511	26.1249
687.947	28.0874
691.382	31.3919
694.816	33.7917
698.247	37.3067
701.678	40.2582
705.108	44.1274
708.534	46.1006
711.962	48.1008
715.388	50.9304
718.81	53.3474
722.234	53.9083
725.654	53.9415
729.075	53.637
732.492	54.9881
735.91	54.2207
739.325	55.2798
742.741	56.4584
746.153	59.1106
749.564	61.5245
752.976	61.961
756.385	63.2134
759.792	65.1203
763.2	66.9989
766.604	70.9318
770.008	72.4275
773.41	75.6216
776.811	77.0862
780.21	80.8142
783.608	82.7297
787.005	84.6675
790.401	85.9618
793.795	86.5292
797.188	88.0338
800.58	86.991
803.971	86.7361
807.36	84.2457
810.748	81.7811
814.135	80.0091
817.518	81.2536
820.902	79.9342
824.285	80.3491
827.665	78.4088
831.045	78.3593
834.424	76.3431
837.8	74.283
841.177	73.1694
844.55	70.6348
847.924	69.9944
851.295	66.5022
854.666	63.256
858.034	61.472
861.403	59.9806
864.769	59.0298
868.133	57.9423
871.498	57.4176
874.86	56.8565
878.221	56.5608
881.58	54.3639
884.938	52.9739
888.297	51.6409
891.653	50.1311
895.007	49.5544
898.36	49.9285
901.712	50.3788
905.063	49.9364
908.412	49.6393
911.76	50.8408
915.107	49.6819
918.452	49.5473
921.797	50.4485
925.138	50.2039
928.48	50.0364
931.82	48.9233
935.16	48.5341
938.496	49.2341
941.833	48.5018
945.168	47.1693
948.5	47.1515
951.834	45.876
955.163	44.9954
958.494	43.9443
961.821	40.3504
965.15	38.4356
968.474	38.6785
971.8	39.0927
975.123	37.7842
978.446	36.7307
981.766	36.2538
985.084	35.8286
988.402	33.9073
991.72	33.9942
995.035	31.4602
998.349	30.8438
1001.66	28.8355
1004.97	27.5132
1008.28	28.8164
1011.59	30.7896
1014.9	38.0572
1018.21	42.8294
1021.51	48.8123
1024.81	53.3579
1028.12	57.9197
1031.42	61.5786
1034.72	63.2453
1038.02	64.2936
1041.31	64.1119
1044.61	64.6388
1047.91	64.6288
1051.2	63.6461
1054.49	61.3242
1057.78	56.7258
1061.07	53.7669
1064.36	49.6795
1067.65	43.969
1070.93	38.0306
1074.22	32.4291
1077.5	26.6967
1080.78	22.4666
1084.06	19.6403
1087.34	19.6913
1090.62	20.9549
1093.9	23.295
1097.17	26.6872
1100.45	27.448
1103.72	28.1312
1106.99	28.4569
1110.27	27.9276
1113.53	28.9618
1116.8	28.6849
1120.07	25.5599
1123.33	24.7226
1126.6	23.9103
1129.86	23.25
1133.12	22.3223
1136.38	20.0054
1139.64	19.1379
1142.9	17.9909
1146.16	14.771
1149.41	12.6054
1152.67	9.80458
1155.92	8.52014
1159.17	6.0335
1162.42	4.35543
1165.67	2.38964
1168.92	0.674207
1172.16	0.440462
1175.41	0.803852
1178.65	2.41899
1181.9	2.38077
1185.14	4.58203
1188.38	5.35998
1191.62	5.9149
1194.86	7.06759
1198.09	8.61715
1201.33	10.2471
1204.56	13.8635
1207.8	15.6066
1211.03	17.6799
1214.26	19.4524
1217.49	22.9241
1220.71	26.1838
1223.94	28.3584
1227.16	30.9295
1230.39	32.5361
1233.61	35.2398
1236.83	39.0437
1240.05	40.9286
1243.27	43.9953
1246.49	45.1521
1249.71	48.4892
1252.92	51.2586
1256.14	53.1139
1259.35	54.7792
1262.56	55.3986
1265.77	57.7351
1268.98	57.4715
1272.19	58.0728
1275.4	60.6488
1278.6	60.5121
1281.81	60.9581
1285.01	61.4839
1288.21	62.0021
1291.41	63.1578
1294.61	64.5219
1297.81	63.9835
1301.01	65.9564
1304.2	67.0162
1307.4	67.0337
1310.59	68.4162
1313.78	69.5945
1316.97	69.6071
1320.16	68.725
1323.35	68.746
1326.54	68.8288
1329.72	67.9685
1332.91	66.146
1336.09	63.4163
1339.27	61.363
1342.45	59.3049
1345.64	57.2088
1348.81	53.8777
1351.99	52.2179
1355.17	50.5451
1358.34	47.3755
1361.51	45.2958
1364.69	44.8651
1367.86	43.2944
1371.03	42.3357
1374.2	41.4259
1377.37	41.6102
1380.53	40.443
1383.7	39.3525
1386.86	38.3437
1390.02	37.5631
1393.19	38.0183
1396.35	36.8413
1399.51	35.5784
1402.66	35.5264
1405.82	35.7943
1408.97	36.1689
1412.13	37.9897
1415.28	39.739
1418.43	44.7118
1421.59	48.1122
1424.73	54.5996
1427.88	59.9915
1431.03	66.9296
1434.18	71.2892
1437.32	74.291
1440.46	78.7704
1443.61	81.0443
1446.75	82.5661
1449.89	82.9592
1453.03	83.3357
1456.16	83.044
1459.3	81.3697
1462.44	79.883
1465.57	77.1177
1468.7	75.1432
1471.83	70.6056
1474.96	65.7878
1478.09	62.1078
1481.22	57.5723
1484.35	54.7514
1487.47	51.9617
1490.6	48.4534
1493.72	46.3024
1496.84	45.3548
1499.96	45.1623
1503.08	44.4889
1506.2	42.1909
1509.32	38.9343
1512.44	34.4419
1515.55	31.2101
1518.66	28.2241
1521.78	25.4652
1524.89	24.6436
1528	22.5276
1531.11	20.1537
1534.21	18.48
1537.32	18.8593
1540.43	19.1524
1543.53	20.4327
1546.63	22.5185
1549.74	23.7773
1552.84	25.5633
1555.94	27.9578
1559.03	30.7565
1562.13	32.2294
1565.23	35.2782
1568.32	38.2219
1571.42	41.0047
1574.51	45.9599
1577.6	48.7626
1580.69	50.6225
1583.78	53.1234
1586.87	54.0491
1589.95	56.05
1593.04	57.5665
1596.12	58.0029
1599.21	58.2367
1602.29	57.564
1605.37	56.9147
1608.45	56.7576
1611.53	57.3956
1614.6	58.1779
1617.68	59.7083
1620.75	60.4044
1623.83	61.3465
1626.9	62.603
1629.97	64.6613
1633.04	66.7996
1636.11	70.1953
1639.18	71.4198
1642.25	73.9065
1645.31	77.9508
1648.38	81.7322
1651.44	84.1634
1654.5	85.8645
1657.56	86.8191
1660.62	86.5829
1663.68	85.3709
1666.74	82.3541
1669.8	81.4095
1672.85	76.7607
1675.91	72.8631
1678.96	66.4232
1682.01	60.7884
1685.06	54.7999
1688.11	48.7137
1691.16	41.895
1694.21	35.6975
1697.25	30.118
1700.3	26.2891
1703.34	22.3812
1706.39	19.5943
1709.43	15.7211
1712.47	12.4407
1715.51	10.0912
1718.54	8.8583
1721.58	7.67314
1724.62	5.91005
1727.65	6.00054
1730.68	5.40001
1733.72	4.91654
1736.75	4.17176
1739.78	4.89654
1742.81	5.97709
1745.84	5.99461
1748.86	4.55289
1751.89	5.1347
1754.91	4.93056
1757.93	4.8357
1760.96	4.3191
1763.98	3.89588
1767	3.13778
1770.02	3.53771
1773.03	3.94057
1776.05	3.56047
1779.07	2.45711
1782.08	2.03566
1785.09	2.21285
1788.11	1.87568
1791.12	1.8885
1794.13	1.08421
1797.13	1.30974
1800.14	1.16585
1803.15	1.40068
1806.15	0.812614
1809.16	0.398009
1812.16	0.502183
1815.16	0.295202
1818.16	-0.151726
1821.16	0.495081
1824.16	0.564151
1827.16	0.583661
1830.16	-0.022256
1833.15	0.154507
1836.14	0.184026
1839.14	0.829147
1842.13	1.75545
1845.12	2.2734
1848.11	2.7991
1851.1	2.48101
1854.08	3.35205
1857.07	3.42818
1860.05	2.80582
1863.04	2.92821
1866.02	3.47347
1869	4.13089
1871.98	3.35359
1874.96	2.75125
1877.94	2.61262
1880.92	2.09437
1882.51	1.76331
1885.5	1.28094
1888.48	1.35511
1891.47	1.38404
1894.46	2.13267
1897.44	2.62931
1900.42	2.3302
1903.41	2.50291
1906.39	3.18696
1909.37	2.75202
1912.35	4.07593
1915.32	4.24404
1918.3	4.60011
1921.27	4.84902
1924.25	5.73977
1927.22	5.44408
1930.19	5.45562
1933.17	4.41846
1936.14	4.99117
1939.11	4.4525
1942.07	4.03266
1945.04	3.24776
1948.01	2.38021
1950.97	2.31259
1953.93	1.56749
1956.9	1.00596
1959.86	0.631672
1962.82	0.920705
1965.78	1.22945
1968.74	0.947208
1971.69	0.576629
1974.65	0.357049
1977.6	-0.172741
1980.56	-0.734933
1983.51	0.645351
1986.46	2.25773
1989.41	2.20831
1992.36	2.84377
1995.31	3.16884
1998.26	3.703
2001.2	2.84033
2004.15	2.07232
2007.09	2.66093
2010.04	3.23902
2012.98	3.09817
2015.92	2.79781
2018.86	3.00475
2021.8	3.89847
2024.73	3.77195
2027.67	3.98105
2030.61	4.07065
2033.54	3.78819
2036.47	4.68127
2039.4	3.1029
2042.33	3.47068
2045.27	3.53818
2048.19	4.21082
2051.12	3.33001
2054.05	3.90982
2056.97	4.60608
2059.9	5.14835
2062.82	5.91985
2065.74	6.74107
2068.67	8.30978
2071.59	9.0934
2074.51	9.67898
2077.42	12.188
2080.34	14.2267
2083.26	15.0237
2086.17	15.6998
2089.09	17.9191
2092	19.425
2094.91	21.3089
2097.82	23.8667
2100.73	25.0233
2103.64	26.2772
2106.55	28.1506
2109.45	28.887
2112.36	31.8724
2115.26	35.3277
2118.17	36.7584
2121.07	37.8187
2123.97	39.6768
2126.87	42.2294
2129.77	46.2872
2132.67	49.9314
2135.56	53.8006
2138.46	56.5797
2141.35	61.064
2144.25	63.7036
2147.14	65.9703
2150.03	68.2658
2152.92	69.5738
2155.81	71.8099
2158.7	74.1302
2161.59	76.8241
2164.47	78.6672
2167.36	80.907
2170.24	81.5888
2173.13	81.1003
2176.01	81.792
2178.89	81.6155
2181.77	81.6496
2184.65	80.0959
2187.53	77.6765
2190.4	74.9496
2193.28	72.1728
2196.16	69.8492
2199.03	68.2189
2201.9	65.5564
2204.77	62.1533
2207.64	58.3903
2210.51	54.6778
2213.38	51.0252
2216.25	46.1713
2219.12	42.1946
2221.98	40.173
2224.85	37.3023
2227.71	34.7472
2230.57	32.9131
2233.43	31.4936
2236.29	29.4383
2239.15	27.1494
2242.01	25.1272
2244.87	23.8729
2247.72	23.1957
2250.58	21.514
2253.43	19.8209
2256.29	18.8449
2259.14	19.0114
2261.99	18.4413
2264.84	17.9083
2267.69	17.3774
2270.53	15.6905
2273.38	14.6307
2276.23	13.9605
2279.07	13.3019
2281.91	12.5589
2284.76	11.1564
2287.6	10.3099
2290.44	9.60722
2293.28	7.67522
2296.12	8.1234
2298.96	8.65551
2301.79	9.81712
2304.63	10.1827
2307.46	10.3336
2310.3	9.80977
2313.13	10.7018
2315.96	10.7795
2318.79	10.3497
2321.62	9.15409
2324.45	10.2418
2327.27	11.4804
2330.1	11.0131
2332.92	9.90109
2335.75	8.81429
2338.57	7.20848
2341.39	6.01022
2344.21	5.83398
2347.04	5.37975
2349.85	3.89821
2352.67	2.63795
2355.49	1.94274
2358.3	1.23916
2361.12	0.627243
2363.93	1.06574
2366.75	2.83036
2369.56	3.208
2372.37	3.48883
2375.18	3.16837
2377.99	2.68158
2380.8	3.5573
2383.6	3.03621
2386.41	3.33556
2389.21	4.05746
2392.02	4.44921
2394.82	4.57073
2397.62	3.86779
2400.42	3.43316
2403.22	3.23359
2406.02	2.4985
2408.82	2.51255
2411.62	2.82632
2414.41	3.6629
2417.21	4.57217
2420	4.98558
2422.79	5.50083
2425.59	4.86161
2428.38	5.1228
2431.17	5.07054
2433.95	6.48669
2436.74	6.27572
2439.53	5.08224
2442.31	5.7838
2445.1	5.11532
2447.88	5.49478
2450.67	5.05879
2453.45	5.24657
2456.23	5.40996
2459.01	5.3623
2461.79	5.172
2464.57	4.03872
2467.34	3.9105
2470.12	4.51526
2472.89	3.54724
2475.67	3.18847
2478.44	3.32045
2481.21	3.20695
2483.98	2.71465
2486.75	2.36293
2489.52	1.63737
2492.29	1.91782
2495.05	2.0962
2497.82	1.85424
2500.58	2.03049
2503.35	1.53663
2506.11	1.16352
2508.87	1.29433
2511.63	1.11925
2514.39	0.871794
2517.15	1.8813
2519.91	2.66771
2522.67	3.1932
2525.42	2.93824
2528.18	2.87215
2530.93	2.87562
2533.69	2.79784
2536.44	2.94076
2539.19	2.0491
2541.94	1.39336
2544.69	1.08041
2547.44	0.0671448
2550.18	-0.0384525
2552.93	1.55037
2555.67	1.73867
2558.42	2.16894
2561.16	2.572
2563.9	2.47402
2566.64	2.88761
2569.38	2.68962
2572.12	3.08598
2574.86	3.64155
2577.6	3.72323
2580.33	4.53623
2583.07	5.32539
2585.8	4.78431
2588.54	3.71365
2591.27	2.94537
2594	2.43867
2596.73	2.7666
2599.46	1.98435
2602.19	1.03605
2604.92	0.450972
2607.64	-0.46353
2610.37	-0.23856
2613.09	0.675319
2615.82	0.695108
2618.54	1.42022
2621.26	1.59973
2623.98	0.791205
2626.7	0.893444
2629.42	0.986693
2632.14	1.93686
2634.86	2.1896
2637.57	2.54784
2640.29	3.5087
2643	4.04897
2645.71	4.4007
2648.43	4.55101
2651.14	4.69935
2653.85	4.70111
2656.56	4.89379
2659.26	4.87413
2661.97	5.089
2664.68	4.41973
2667.38	4.83272
2670.09	4.83367
2672.79	4.81718
2675.49	5.16661
2678.19	5.61141
2680.89	5.7201
2683.59	5.20545
2686.29	5.11652
2688.99	5.0692
2691.69	4.8219
2694.38	5.20549
2697.08	5.31211
2699.77	5.79836
2702.46	5.44412
2705.15	5.55525
2707.85	4.92751
2710.54	4.38659
2713.22	4.15603
2715.91	4.37493
2718.6	3.82268
2721.29	2.89933
2723.97	3.11176
2726.66	3.28513
2729.34	2.99315
2732.02	3.49257
2734.7	3.56124
2737.38	3.01743
2740.06	3.9562
2742.74	3.87456
2745.42	4.70008
2748.09	6.08793
2750.77	6.52833
2753.45	6.23148
2756.12	6.03295
2758.79	5.91628
2761.46	6.14758
2764.14	6.01027
2766.8	5.34167
2769.47	5.14381
2772.14	4.12431
2774.81	3.97582
2777.48	3.31913
2780.14	3.78435
2782.8	3.79387
2785.47	3.67052
2788.13	3.94735
2790.79	3.35036
2793.45	3.02342
2796.11	2.24872
2798.77	1.80295
2801.43	1.04259
2804.09	0.816048
2806.74	-0.0438796
2809.4	0.0715457
2812.05	0.46484
2814.71	0.777002
2817.36	0.932771
2820.01	2.02792
2822.66	4.15842
2825.31	6.71992
2827.96	10.1161
2830.6	13.4262
2833.25	17.0737
2835.9	22.3622
2838.54	28.5123
2841.18	34.8598
2843.83	41.3902
2846.47	48.6431
2849.11	57.5253
2851.75	65.0762
2854.39	74.4152
2857.03	82.264
2859.66	89.9744
2862.3	97.1889
2864.94	104.353
2867.57	110.938
2870.2	116.434
2872.84	121.924
2875.47	126.825
2878.1	130.524
2880.73	135.327
2883.36	139.355
2885.99	143.348
2888.61	148.653
2891.24	153.729
2893.86	158.704
2896.49	165.398
2899.11	173.691
2901.73	181.912
2904.36	191.21
2906.98	201.903
2909.6	212.688
2912.21	224.723
2914.83	237.1
2917.45	248.153
2920.07	258.731
2922.68	266.922
2925.29	274.027
2927.91	279.035
2930.52	283.08
2933.13	282.457
2935.74	280.707
2938.35	277.132
2940.96	272.33
2943.57	266.133
2946.18	258.441
2948.78	249.436
2951.39	239.686
2953.99	228.917
2956.59	218.191
2959.2	207.639
2961.8	197.839
2964.4	187.916
2967	176.546
2969.6	167.026
2972.19	157.531
2974.79	148.129
2977.39	139.494
2979.98	130.671
2982.58	121.823
2985.17	113.795
2987.76	104.142
2990.35	94.8354
2992.94	85.8927
2995.53	76.9412
2998.12	69.0658
3000.71	60.1812
3003.3	52.9146
3005.88	46.7906
3008.47	40.7782
3011.05	34.8936
3013.64	30.1575
3016.22	26.0861
3018.8	21.7635
3021.38	19.0112
3023.96	17.0765
3026.54	15.6465
3029.12	14.1969
3031.69	13.7463
3034.27	14.1783
3036.84	14.6754
3039.42	14.6041
3041.99	15.2538
3044.57	16.7752
3047.14	17.9685
3049.71	18.9445
3052.28	18.5854
3054.85	18.6105
3057.41	18.0662
3059.98	16.7898
3062.55	15.7905
3065.11	14.5433
3067.68	14.6137
3070.24	13.079
3072.8	12.1735
3075.36	9.96129
3077.93	7.95204
3080.49	5.71574
3083.04	4.93332
3085.6	4.12756
3088.16	4.38273
3090.72	2.99406
3093.27	3.28019
3095.83	3.2291
3098.38	3.04277
3100.93	3.30681
3103.49	3.59303
3106.04	4.67092
3108.59	6.36856
3111.14	6.75107
3113.69	6.53674
3116.23	6.66311
3118.78	6.85409
3121.33	7.80915
3123.87	9.04668
3126.41	9.99212
3128.96	11.2453
3131.5	11.8485
3134.04	11.7772
3136.58	12.9913
3139.12	14.7025
3141.66	16.2945
3144.2	18.3864
3146.74	20.5354
3149.27	23.302