File: data/Raman/poly_smoothed/Mb_30_27_21_1x_45s_532 nm_x100_100%_600 gr_mm_01.txt
#Acq. time (s)=	45
#Accumulations=	2
#Range (cm-¹)=	200...3150
#Windows=	2
#Auto scanning=	Off
#Autofocus=	Off
#Macrospot=	Off
#AutoExposure=	Off
#Spike filter=	Multiple accum.
#Delay time (s)=	0
#Binning=	1
#Readout mode=	Signal
#DeNoise=	Off
#ICS correction=	On
#Dark correction=	Off
#Inst. Process=	Off
#Detector Gain=	Best Dynamic Range
#Detector ADC=	20 kHz
#Detector temperature (°C)=	-69.85
#Instrument=	LabRAM HR Evol
#Detector=	Synapse
#Objective=	x100
#Grating=	600 gr/mm
#ND Filter=	100%
#Laser (nm)=	532
#Hole=	100.021
#Range=	Auto
#Laser Pol.=	No
#Raman. Pol.=	No
#Laser Pol. (°)=	-0.0007625
#Raman Pol. (°)=	89.9995
#Collection=	Microscope
#StageXY=	Marzhauser
#StageZ=	Marzhauser
#X (µm)=	-6392.1
#Y (µm)=	879.4
#Z (µm)=	-64.7
#Full time(mm:ss)=	3:18
#Project=
#Sample=
#Site=
#Title=	Mb_30_27_21_2x_45s_532 nm_x100_100%_600 gr_mm
#Remark=
#Date=	13.07.2022 10:11
#Acquired=	13.07.2022 10:11:04
#Base:Fit=	10.08.2022 10:40:03
#Base:Sub=	10.08.2022 10:40:17
#Filter:Polynom=	16.08.2022 10:16:15
#AxisType[0]=Intens
#AxisUnit[0]=Cnt
#AxisType[1]=Spectr
#AxisUnit[1]=1/cm
200.563	14.2494
204.194	14.1317
207.821	13.3565
211.449	11.567
215.074	9.09745
218.699	6.12027
222.321	7.54871
225.941	6.66194
229.562	5.35412
233.18	5.2628
236.796	4.2804
240.411	3.83357
244.026	3.89984
247.638	2.85122
251.248	3.27396
254.857	2.68994
258.465	5.07483
262.071	5.63294
265.678	5.73973
269.282	6.19531
272.884	6.589
276.484	8.27101
280.084	8.9803
283.682	8.84637
287.276	9.5872
290.871	8.57232
294.465	8.31061
298.057	7.18945
301.648	7.95271
305.237	9.58876
308.823	12.5852
312.41	14.2474
315.995	14.5598
319.579	13.8262
323.16	13.9857
326.741	14.7128
330.321	13.7696
333.897	14.9693
337.474	15.6964
341.048	16.8395
344.622	14.2378
348.192	14.968
351.764	11.8377
355.332	11.6428
358.901	10.5899
362.466	10.4147
366.03	8.8463
369.594	7.8902
373.155	6.63007
376.715	4.55209
380.273	4.33588
383.832	5.51564
387.388	6.70977
390.942	7.45841
394.495	9.96332
398.047	10.1852
401.597	9.67522
405.145	9.48186
408.693	9.93983
412.239	11.3948
415.783	14.6899
419.327	15.0667
422.869	15.3902
426.409	14.5395
429.948	13.1049
433.486	10.8137
437.022	11.1895
440.558	11.0092
444.089	11.2719
447.622	10.712
451.153	8.40446
454.682	6.50906
458.208	5.74791
461.735	5.03368
465.259	5.12665
468.783	6.41882
472.306	6.79306
475.825	7.29401
479.346	7.2736
482.862	7.16481
486.38	9.84052
489.894	11.2433
493.407	14.1292
496.92	18.3121
500.43	22.1143
503.939	24.9476
507.448	27.3818
510.954	29.5912
514.459	29.9662
517.962	30.7226
521.466	32.7594
524.966	33.1792
528.466	33.1268
531.964	30.7642
535.46	29.2036
538.955	28.0489
542.449	26.6618
545.942	25.7414
549.433	23.3264
552.923	20.6137
556.412	18.4794
559.899	16.3663
563.385	14.0624
566.867	11.4663
570.35	10.2162
573.832	9.27687
577.313	8.42191
580.79	6.98675
584.268	6.87825
587.745	5.59119
591.218	4.25211
594.692	3.60894
598.164	3.15741
601.634	2.67165
605.104	2.75925
608.57	4.25323
612.037	4.1873
615.501	4.9341
618.966	5.1571
622.427	5.28059
625.887	5.29701
629.348	4.9459
632.806	6.01069
636.262	7.41743
639.716	7.20236
643.172	8.7026
646.624	11.2464
650.075	11.5811
653.524	13.0956
656.972	12.7815
660.419	12.353
663.865	12.2416
667.309	12.9801
670.752	14.8523
674.194	15.2266
677.634	17.6597
681.073	18.2671
684.511	20.9401
687.947	22.4333
691.382	25.2879
694.816	26.4923
698.247	28.5683
701.678	29.2079
705.108	30.8256
708.534	32.1513
711.962	34.8984
715.388	36.3911
718.81	38.4832
722.234	40.6552
725.654	40.8119
729.075	42.4804
732.492	41.1267
735.91	42.4749
739.325	43.6478
742.741	44.1392
746.153	45.1695
749.564	45.5482
752.976	47.6914
756.385	48.3046
759.792	50.5534
763.2	52.0839
766.604	54.1907
770.008	55.915
773.41	59.5868
776.811	61.2593
780.21	63.9804
783.608	65.4823
787.005	67.1013
790.401	72.7208
793.795	76.1956
797.188	78.0157
800.58	79.6369
803.971	81.6635
807.36	80.1023
810.748	80.1966
814.135	82.9204
817.518	84.5677
820.902	87.1927
824.285	87.2166
827.665	87.3481
831.045	85.1356
834.424	83.4539
837.8	83.5368
841.177	81.5663
844.55	79.6923
847.924	75.6656
851.295	71.2182
854.666	68.7514
858.034	64.7175
861.403	61.3055
864.769	57.1899
868.133	54.1645
871.498	52.0583
874.86	50.8301
878.221	46.929
881.58	45.0427
884.938	43.7662
888.297	43.3216
891.653	41.4424
895.007	43.1836
898.36	44.5164
901.712	46.6614
905.063	46.7374
908.412	47.454
911.76	48.0562
915.107	48.2126
918.452	48.2494
921.797	47.9927
925.138	47.0339
928.48	45.7357
931.82	43.4491
935.16	43.7467
938.496	40.4105
941.833	36.5822
945.168	34.3973
948.5	33.0449
951.834	31.9877
955.163	31.7953
958.494	31.1303
961.821	30.0971
965.15	29.9793
968.474	30.5985
971.8	33.319
975.123	34.6148
978.446	37.4072
981.766	39.1491
985.084	40.1973
988.402	39.5622
991.72	40.0743
995.035	38.8976
998.349	36.218
1001.66	32.8316
1004.97	32.4008
1008.28	35.8796
1011.59	44.0941
1014.9	53.8679
1018.21	66.3202
1021.51	75.0147
1024.81	84.1387
1028.12	94.2652
1031.42	101.873
1034.72	106.392
1038.02	109.54
1041.31	110.729
1044.61	110.053
1047.91	110.304
1051.2	109.77
1054.49	106.403
1057.78	99.1603
1061.07	90.7768
1064.36	81.0957
1067.65	69.4213
1070.93	58.2332
1074.22	47.7088
1077.5	35.371
1080.78	26.6538
1084.06	23.4362
1087.34	24.8768
1090.62	29.5875
1093.9	31.7079
1097.17	35.4986
1100.45	38.6253
1103.72	39.3263
1106.99	39.9455
1110.27	39.8521
1113.53	38.9874
1116.8	37.5597
1120.07	36.9087
1123.33	36.1923
1126.6	34.8419
1129.86	32.5212
1133.12	29.0562
1136.38	26.6098
1139.64	24.1365
1142.9	20.8516
1146.16	18.3701
1149.41	13.8604
1152.67	12.1061
1155.92	8.124
1159.17	5.40258
1162.42	4.19801
1165.67	3.28454
1168.92	3.3901
1172.16	3.06139
1175.41	3.25426
1178.65	6.1828
1181.9	6.91686
1185.14	4.26712
1188.38	5.62344
1191.62	8.64731
1194.86	9.83997
1198.09	14.3301
1201.33	16.353
1204.56	18.3912
1207.8	21.5472
1211.03	24.7393
1214.26	28.1246
1217.49	32.3825
1220.71	35.5205
1223.94	36.9911
1227.16	39.4859
1230.39	42.8135
1233.61	47.4165
1236.83	50.3783
1240.05	56.0878
1243.27	57.2282
1246.49	61.0813
1249.71	63.7383
1252.92	64.7591
1256.14	65.7669
1259.35	69.3423
1262.56	70.4011
1265.77	74.2654
1268.98	78.3506
1272.19	80.6253
1275.4	83.1496
1278.6	84.9006
1281.81	86.6016
1285.01	87.677
1288.21	89.2869
1291.41	91.046
1294.61	93.5054
1297.81	94.0494
1301.01	94.2399
1304.2	95.022
1307.4	98.1164
1310.59	98.4554
1313.78	98.2528
1316.97	97.1542
1320.16	96.7656
1323.35	96.3997
1326.54	95.7456
1329.72	93.3317
1332.91	92.2674
1336.09	92.2218
1339.27	91.116
1342.45	89.18
1345.64	85.9854
1348.81	82.9988
1351.99	81.3379
1355.17	78.1714
1358.34	73.9777
1361.51	71.8189
1364.69	69.3838
1367.86	67.9849
1371.03	68.2632
1374.2	66.6142
1377.37	64.9943
1380.53	63.8311
1383.7	62.1542
1386.86	62.0456
1390.02	60.6417
1393.19	60.3909
1396.35	61.2384
1399.51	61.7499
1402.66	61.4574
1405.82	62.2902
1408.97	64.119
1412.13	66.8303
1415.28	70.1796
1418.43	75.0467
1421.59	78.6062
1424.73	83.9495
1427.88	89.463
1431.03	95.7436
1434.18	100.449
1437.32	105.853
1440.46	110.384
1443.61	112.52
1446.75	115.848
1449.89	116.919
1453.03	117.647
1456.16	117.058
1459.3	116.433
1462.44	114.561
1465.57	111.731
1468.7	109.674
1471.83	105.182
1474.96	99.0148
1478.09	92.9068
1481.22	89.2567
1484.35	83.2313
1487.47	78.1711
1490.6	73.3534
1493.72	67.25
1496.84	62.7125
1499.96	58.6203
1503.08	55.992
1506.2	51.8387
1509.32	49.11
1512.44	46.4213
1515.55	42.6316
1518.66	40.8781
1521.78	38.152
1524.89	38.0485
1528	37.9263
1531.11	39.5607
1534.21	40.5233
1537.32	42.4151
1540.43	43.618
1543.53	45.0936
1546.63	46.7159
1549.74	47.0237
1552.84	47.3053
1555.94	49.9114
1559.03	50.783
1562.13	52.0568
1565.23	52.5001
1568.32	54.354
1571.42	55.9995
1574.51	58.7208
1577.6	60.4167
1580.69	62.3337
1583.78	64.7866
1586.87	67.6716
1589.95	71.5586
1593.04	72.7486
1596.12	74.2633
1599.21	75.293
1602.29	77.7354
1605.37	78.5483
1608.45	79.1889
1611.53	79.4806
1614.6	80.8026
1617.68	82.0175
1620.75	82.168
1623.83	82.9381
1626.9	82.7778
1629.97	85.1571
1633.04	87.3312
1636.11	88.789
1639.18	91.2929
1642.25	91.9151
1645.31	93.457
1648.38	93.7248
1651.44	93.4413
1654.5	92.5586
1657.56	92.0116
1660.62	89.6137
1663.68	87.7995
1666.74	84.6746
1669.8	79.8987
1672.85	75.2395
1675.91	70.9808
1678.96	63.4069
1682.01	57.7135
1685.06	50.9775
1688.11	44.7885
1691.16	39.5728
1694.21	34.2011
1697.25	29.1785
1700.3	24.5434
1703.34	22.4768
1706.39	20.2367
1709.43	16.7881
1712.47	16.0396
1715.51	14.6217
1718.54	13.9802
1721.58	13.2871
1724.62	12.3766
1727.65	12.0192
1730.68	12.3609
1733.72	11.9508
1736.75	10.6952
1739.78	11.3527
1742.81	11.4198
1745.84	10.6847
1748.86	9.17631
1751.89	7.90792
1754.91	5.70984
1757.93	4.53419
1760.96	3.97578
1763.98	4.49532
1767	4.69147
1770.02	4.02088
1773.03	2.17266
1776.05	2.2702
1779.07	2.31266
1782.08	2.47366
1785.09	4.07584
1788.11	4.31283
1791.12	3.69157
1794.13	3.95109
1797.13	4.20259
1800.14	4.55823
1803.15	3.93985
1806.15	3.27074
1809.16	2.24387
1812.16	2.74902
1815.16	2.90038
1818.16	1.85128
1821.16	1.98785
1824.16	1.12482
1827.16	1.26467
1830.16	1.59923
1833.15	1.29538
1836.14	1.81724
1839.14	2.72101
1842.13	2.68255
1845.12	2.6444
1848.11	2.96833
1851.1	4.15289
1854.08	5.26511
1857.07	5.74632
1860.05	6.16521
1863.04	6.04954
1866.02	6.62741
1869	7.83093
1871.98	8.96522
1874.96	8.60189
1877.94	9.4744
1880.92	10.6684
1882.51	11.6748
1885.5	11.7423
1888.48	10.656
1891.47	11.6336
1894.46	12.1821
1897.44	11.9845
1900.42	10.7178
1903.41	11.7087
1906.39	10.7739
1909.37	10.0979
1912.35	9.16581
1915.32	7.48988
1918.3	6.24088
1921.27	5.22625
1924.25	3.40736
1927.22	2.34319
1930.19	2.98703
1933.17	1.75742
1936.14	1.76435
1939.11	2.15604
1942.07	2.47651
1945.04	2.38872
1948.01	3.07749
1950.97	4.80741
1953.93	6.65277
1956.9	7.38769
1959.86	7.52647
1962.82	9.82638
1965.78	10.1814
1968.74	10.9619
1971.69	11.0802
1974.65	10.8067
1977.6	10.4953
1980.56	8.80601
1983.51	8.75513
1986.46	8.77556
1989.41	7.84196
1992.36	7.91837
1995.31	8.46156
1998.26	8.30413
2001.2	8.99149
2004.15	8.66765
2007.09	8.69615
2010.04	8.2322
2012.98	9.09202
2015.92	9.87432
2018.86	10.0085
2021.8	11.1963
2024.73	12.5242
2027.67	12.7664
2030.61	12.0126
2033.54	11.0498
2036.47	11.9378
2039.4	11.9405
2042.33	11.8725
2045.27	12.6175
2048.19	12.7464
2051.12	14.3542
2054.05	15.3303
2056.97	17.3602
2059.9	16.7969
2062.82	18.5291
2065.74	18.5534
2068.67	19.1356
2071.59	20.3476
2074.51	21.0022
2077.42	21.0573
2080.34	22.2006
2083.26	23.8756
2086.17	24.6157
2089.09	24.5896
2092	25.747
2094.91	27.3841
2097.82	28.8275
2100.73	29.1915
2103.64	30.1421
2106.55	31.8395
2109.45	32.5689
2112.36	33.8318
2115.26	35.1363
2118.17	36.8071
2121.07	38.4395
2123.97	39.6391
2126.87	40.7816
2129.77	42.3111
2132.67	44.4423
2135.56	47.8598
2138.46	52.3517
2141.35	56.1651
2144.25	58.6444
2147.14	62.1211
2150.03	65.8636
2152.92	69.1461
2155.81	73.3591
2158.7	75.8983
2161.59	77.882
2164.47	81.7259
2167.36	84.4718
2170.24	85.2668
2173.13	86.8608
2176.01	86.7109
2178.89	86.8388
2181.77	85.4252
2184.65	85.224
2187.53	83.3136
2190.4	79.7904
2193.28	76.3488
2196.16	74.3705
2199.03	73.2588
2201.9	70.2699
2204.77	66.8209
2207.64	64.0705
2210.51	59.7734
2213.38	54.8266
2216.25	49.534
2219.12	46.8509
2221.98	42.7467
2224.85	40.5744
2227.71	37.6969
2230.57	36.0014
2233.43	34.4484
2236.29	33.8003
2239.15	31.6222
2242.01	29.8954
2244.87	28.8403
2247.72	27.838
2250.58	27.3082
2253.43	26.6773
2256.29	25.5275
2259.14	25.1769
2261.99	25.3635
2264.84	26.1414
2267.69	25.9516
2270.53	24.563
2273.38	22.8638
2276.23	22.2447
2279.07	21.1145
2281.91	18.6671
2284.76	18.0494
2287.6	18.0125
2290.44	17.3328
2293.28	15.4162
2296.12	15.38
2298.96	15.7306
2301.79	14.4515
2304.63	14.2335
2307.46	12.8169
2310.3	12.9023
2313.13	11.8047
2315.96	12.3812
2318.79	12.1188
2321.62	10.5323
2324.45	10.2867
2327.27	10.3774
2330.1	8.96306
2332.92	7.45982
2335.75	6.16302
2338.57	4.55443
2341.39	5.15089
2344.21	4.36414
2347.04	4.03133
2349.85	3.8502
2352.67	3.09144
2355.49	3.50774
2358.3	2.49539
2361.12	1.25677
2363.93	2.7053
2366.75	4.0781
2369.56	4.54483
2372.37	5.54618
2375.18	7.00861
2377.99	8.69748
2380.8	8.80777
2383.6	9.04875
2386.41	9.12068
2389.21	10.4138
2392.02	10.4861
2394.82	10.8424
2397.62	10.3834
2400.42	10.0236
2403.22	10.8811
2406.02	9.88017
2408.82	9.16746
2411.62	9.38494
2414.41	8.60225
2417.21	7.49752
2420	6.84576
2422.79	6.41523
2425.59	5.3425
2428.38	5.62324
2431.17	4.65121
2433.95	5.15109
2436.74	5.22094
2439.53	4.69823
2442.31	4.42985
2445.1	4.08666
2447.88	4.07676
2450.67	3.77931
2453.45	3.86099
2456.23	4.87927
2459.01	4.63888
2461.79	4.54318
2464.57	4.74473
2467.34	4.32851
2470.12	5.26462
2472.89	5.08716
2475.67	4.20988
2478.44	3.58375
2481.21	3.87706
2483.98	4.27243
2486.75	4.49652
2489.52	4.40546
2492.29	4.72593
2495.05	4.56124
2497.82	4.72141
2500.58	4.41965
2503.35	3.634
2506.11	2.21588
2508.87	1.49572
2511.63	0.902456
2514.39	0.377666
2517.15	0.835777
2519.91	-0.750572
2522.67	-0.734245
2525.42	-0.845731
2528.18	-1.33182
2530.93	-0.940352
2533.69	-0.367364
2536.44	0.070393
2539.19	0.435865
2541.94	1.40873
2544.69	0.733774
2547.44	1.18716
2550.18	1.88336
2552.93	2.60751
2555.67	2.63533
2558.42	4.15075
2561.16	4.84081
2563.9	5.86889
2566.64	6.87849
2569.38	7.12465
2572.12	7.54298
2574.86	8.76282
2577.6	8.58145
2580.33	9.19076
2583.07	9.42169
2585.8	10.4667
2588.54	10.2747
2591.27	10.3351
2594	10.4021
2596.73	9.90522
2599.46	9.9873
2602.19	9.22161
2604.92	8.84022
2607.64	8.5368
2610.37	8.01769
2613.09	7.87085
2615.82	7.72845
2618.54	7.3828
2621.26	7.58701
2623.98	7.90409
2626.7	8.85663
2629.42	8.93881
2632.14	9.52177
2634.86	9.43324
2637.57	10.0227
2640.29	9.99542
2643	9.60434
2645.71	10.2269
2648.43	10.8779
2651.14	10.1135
2653.85	8.95074
2656.56	8.8994
2659.26	7.9615
2661.97	8.17333
2664.68	9.07045
2667.38	8.33495
2670.09	8.54892
2672.79	7.70676
2675.49	7.38529
2678.19	7.55726
2680.89	8.26318
2683.59	6.94197
2686.29	7.28394
2688.99	7.37427
2691.69	7.30795
2694.38	6.39787
2697.08	5.76045
2699.77	6.56639
2702.46	7.00953
2705.15	6.78551
2707.85	7.37978
2710.54	7.52838
2713.22	7.64864
2715.91	7.11346
2718.6	7.94718
2721.29	9.07364
2723.97	9.68166
2726.66	11.1021
2729.34	10.9968
2732.02	11.4102
2734.7	11.9535
2737.38	12.0155
2740.06	11.6323
2742.74	12.1687
2745.42	11.7228
2748.09	10.4716
2750.77	8.7045
2753.45	7.94026
2756.12	6.84949
2758.79	5.58457
2761.46	4.90799
2764.14	5.01309
2766.8	4.25909
2769.47	4.41048
2772.14	4.9418
2774.81	5.00131
2777.48	5.76942
2780.14	6.43701
2782.8	7.76232
2785.47	8.44121
2788.13	9.08382
2790.79	9.416
2793.45	8.70226
2796.11	7.55346
2798.77	7.69625
2801.43	6.98872
2804.09	5.59407
2806.74	4.64974
2809.4	4.5696
2812.05	3.91156
2814.71	2.17959
2817.36	2.24459
2820.01	3.52231
2822.66	4.89992
2825.31	5.64623
2827.96	9.51628
2830.6	13.4686
2833.25	17.5655
2835.9	22.6137
2838.54	28.7364
2841.18	35.3111
2843.83	42.6197
2846.47	50.2421
2849.11	58.4705
2851.75	67.1136
2854.39	74.8899
2857.03	82.9076
2859.66	90.0447
2862.3	98.325
2864.94	104.657
2867.57	110.629
2870.2	117.032
2872.84	122.737
2875.47	127.315
2878.1	131.053
2880.73	135.125
2883.36	139.814
2885.99	143.978
2888.61	149.601
2891.24	154.804
2893.86	161.225
2896.49	168.148
2899.11	175.035
2901.73	184.008
2904.36	193.034
2906.98	204.096
2909.6	215.966
2912.21	228.439
2914.83	239.76
2917.45	250.458
2920.07	260.734
2922.68	268.184
2925.29	274.466
2927.91	279.044
2930.52	282.055
2933.13	283.454
2935.74	283.185
2938.35	278.117
2940.96	273.606
2943.57	268.033
2946.18	260.704
2948.78	251.635
2951.39	242.431
2953.99	231.704
2956.59	219.586
2959.2	208.131
2961.8	193.518
2964.4	183.195
2967	171.353
2969.6	160.769
2972.19	151.516
2974.79	140.58
2977.39	131.046
2979.98	121.312
2982.58	111.202
2985.17	101.477
2987.76	93.4802
2990.35	84.5225
2992.94	76.3162
2995.53	67.1264
2998.12	59.7241
3000.71	52.652
3003.3	46.0761
3005.88	40.8747
3008.47	35.4611
3011.05	30.5397
3013.64	25.2018
3016.22	21.0512
3018.8	16.1922
3021.38	12.8817
3023.96	9.96857
3026.54	8.46221
3029.12	7.98272
3031.69	6.58196
3034.27	6.36417
3036.84	5.3532
3039.42	4.60101
3041.99	3.61548
3044.57	4.25288
3047.14	4.98481
3049.71	5.53582
3052.28	5.31149
3054.85	4.35098
3057.41	4.66208
3059.98	3.68958
3062.55	3.79677
3065.11	3.88638
3067.68	3.20468
3070.24	3.33277
3072.8	3.05026
3075.36	1.72893
3077.93	0.993685
3080.49	0.575646
3083.04	0.527673
3085.6	-0.362389
3088.16	0.224313
3090.72	0.64706
3093.27	0.756496
3095.83	0.0130985
3098.38	-0.647755
3100.93	-0.456364
3103.49	-0.687569
3106.04	0.210273
3108.59	0.63472
3111.14	1.23173
3113.69	2.50479
3116.23	4.22564
3118.78	5.03601
3121.33	5.64769
3123.87	7.0013
3126.41	7.97733
3128.96	8.22594
3131.5	10.1403
3134.04	12.0084
3136.58	11.852
3139.12	12.9289
3141.66	14.0982
3144.2	14.243
3146.74	13.7476
3149.27	11.6596