File: data/Raman/poly_smoothed/Mb_30_27_36_1x_45s_532 nm_x100_100%_600 gr_mm_01.txt
#Acq. time (s)=	45
#Accumulations=	2
#Range (cm-¹)=	200...3150
#Windows=	2
#Auto scanning=	Off
#Autofocus=	Off
#Macrospot=	Off
#AutoExposure=	Off
#Spike filter=	Multiple accum.
#Delay time (s)=	0
#Binning=	1
#Readout mode=	Signal
#DeNoise=	Off
#ICS correction=	On
#Dark correction=	Off
#Inst. Process=	Off
#Detector Gain=	Best Dynamic Range
#Detector ADC=	20 kHz
#Detector temperature (°C)=	-69.85
#Instrument=	LabRAM HR Evol
#Detector=	Synapse
#Objective=	x100
#Grating=	600 gr/mm
#ND Filter=	100%
#Laser (nm)=	532
#Hole=	100.021
#Range=	Auto
#Laser Pol.=	No
#Raman. Pol.=	No
#Laser Pol. (°)=	-0.0007625
#Raman Pol. (°)=	89.9995
#Collection=	Microscope
#StageXY=	Marzhauser
#StageZ=	Marzhauser
#X (µm)=	-6344.2
#Y (µm)=	808.6
#Z (µm)=	-64.95
#Full time(mm:ss)=	3:18
#Project=
#Sample=
#Site=
#Title=	Mb_30_27_36_2x_45s_532 nm_x100_100%_600 gr_mm
#Remark=
#Date=	13.07.2022 11:24
#Acquired=	13.07.2022 11:24:40
#Base:Fit=	10.08.2022 10:40:03
#Base:Sub=	10.08.2022 10:40:17
#Filter:Polynom=	16.08.2022 10:16:15
#AxisType[0]=Intens
#AxisUnit[0]=Cnt
#AxisType[1]=Spectr
#AxisUnit[1]=1/cm
200.563	28.3173
204.194	20.239
207.821	13.7688
211.449	9.51185
215.074	7.24441
218.699	5.25066
222.321	5.00629
225.941	4.3249
229.562	5.5695
233.18	4.79435
236.796	4.9405
240.411	6.5616
244.026	5.51953
247.638	6.93212
251.248	7.93423
254.857	8.77195
258.465	9.13261
262.071	10.2192
265.678	8.90006
269.282	9.05691
272.884	8.95354
276.484	7.88408
280.084	7.00097
283.682	6.71908
287.276	5.93891
290.871	5.59748
294.465	7.33255
298.057	8.12906
301.648	9.13096
305.237	8.0384
308.823	8.17864
312.41	8.31897
315.995	8.27649
319.579	10.7667
323.16	11.2022
326.741	12.6384
330.321	12.5592
333.897	12.6223
337.474	13.1577
341.048	13.2881
344.622	12.3539
348.192	13.0858
351.764	10.5407
355.332	9.08544
358.901	7.88312
362.466	7.18175
366.03	6.47137
369.594	7.18204
373.155	6.48087
376.715	6.38542
380.273	5.98237
383.832	5.22616
387.388	3.98772
390.942	1.81012
394.495	0.748957
398.047	0.264277
401.597	0.733914
405.145	2.46299
408.693	3.25583
412.239	4.46471
415.783	3.81257
419.327	5.41522
422.869	6.04378
426.409	5.53673
429.948	5.76979
433.486	5.65312
437.022	5.1006
440.558	5.1314
444.089	6.16342
447.622	7.28667
451.153	8.20336
454.682	8.93596
458.208	7.83758
461.735	7.87513
465.259	7.95475
468.783	9.13946
472.306	8.32
475.825	8.52953
479.346	9.14228
482.862	8.73037
486.38	9.55486
489.894	11.4763
493.407	12.6433
496.92	13.5063
500.43	14.8194
503.939	15.2
507.448	15.0468
510.954	15.7554
514.459	14.8836
517.962	14.7546
521.466	15.6116
524.966	14.6505
528.466	14.8645
531.964	14.2845
535.46	12.4291
538.955	11.1545
542.449	10.1195
545.942	7.92522
549.433	7.06238
552.923	7.64692
556.412	5.86854
559.899	5.28246
563.385	4.49818
566.867	2.77459
570.35	3.09613
573.832	2.74523
577.313	2.19101
580.79	2.16084
584.268	3.17811
587.745	3.38989
591.218	3.23454
594.692	2.63193
598.164	2.06194
601.634	1.8811
605.104	2.65627
608.57	3.30356
612.037	1.82687
615.501	2.27067
618.966	2.65252
622.427	3.23485
625.887	4.02013
629.348	4.92242
632.806	4.54869
636.262	5.10277
639.716	6.29078
643.172	6.59255
646.624	9.05313
650.075	9.32027
653.524	11.3458
656.972	12.9441
660.419	14.1381
663.865	15.3245
667.309	16.0868
670.752	18.7513
674.194	18.4631
677.634	18.5506
681.073	18.5094
684.511	20.2577
687.947	23.1415
691.382	23.8001
694.816	23.9064
698.247	24.6454
701.678	27.1214
705.108	28.5369
708.534	31.1609
711.962	32.3688
715.388	33.1317
718.81	33.7207
722.234	33.8064
725.654	36.2067
729.075	38.016
732.492	39.0887
735.91	40.0894
739.325	40.6124
742.741	41.5147
746.153	44.4037
749.564	47.3788
752.976	50.4439
756.385	53.2156
759.792	55.7876
763.2	57.8203
766.604	61.551
770.008	66.0965
773.41	68.5855
776.811	70.6239
780.21	72.5416
783.608	75.5154
787.005	79.0044
790.401	81.8916
793.795	83.1412
797.188	82.8872
800.58	84.7467
803.971	85.0577
807.36	85.0455
810.748	84.0887
814.135	83.8551
817.518	82.7632
820.902	81.2121
824.285	79.9604
827.665	78.3162
831.045	78.2277
834.424	77.8906
837.8	75.7496
841.177	72.3388
844.55	71.0201
847.924	67.4615
851.295	65.168
854.666	62.8309
858.034	59.902
861.403	58.1617
864.769	57.475
868.133	55.9496
871.498	55.0596
874.86	53.9236
878.221	53.5601
881.58	54.8425
884.938	55.0498
888.297	53.4787
891.653	53.2982
895.007	53.5743
898.36	54.0653
901.712	53.4136
905.063	52.7988
908.412	54.534
911.76	55.2857
915.107	54.8173
918.452	52.1387
921.797	49.5127
925.138	48.8856
928.48	48.8231
931.82	45.0728
935.16	43.4109
938.496	40.9425
941.833	40.2629
945.168	37.4698
948.5	36.0294
951.834	35.5088
955.163	33.2434
958.494	30.8445
961.821	33.0883
965.15	35.726
968.474	39.3382
971.8	42.2103
975.123	46.1058
978.446	48.1133
981.766	49.3027
985.084	51.876
988.402	52.3365
991.72	53.6587
995.035	52.2821
998.349	49.6905
1001.66	48.0215
1004.97	47.5386
1008.28	46.85
1011.59	45.5309
1014.9	45.5345
1018.21	45.4678
1021.51	44.5306
1024.81	45.723
1028.12	45.1514
1031.42	44.733
1034.72	43.6675
1038.02	43.972
1041.31	47.276
1044.61	47.6035
1047.91	47.0893
1051.2	45.4211
1054.49	43.3235
1057.78	42.2573
1061.07	39.6979
1064.36	36.8557
1067.65	34.0706
1070.93	31.5218
1074.22	29.6911
1077.5	24.9326
1080.78	24.0039
1084.06	22.2741
1087.34	23.054
1090.62	24.3405
1093.9	25.4473
1097.17	26.7059
1100.45	28.0027
1103.72	29.1662
1106.99	28.649
1110.27	27.4867
1113.53	27.3563
1116.8	27.2297
1120.07	26.1078
1123.33	23.0738
1126.6	20.745
1129.86	20.0001
1133.12	19.302
1136.38	17.3253
1139.64	15.0169
1142.9	13.1083
1146.16	12.1149
1149.41	9.75476
1152.67	7.92308
1155.92	6.21083
1159.17	4.0941
1162.42	3.1292
1165.67	2.38739
1168.92	2.63887
1172.16	1.4207
1175.41	1.5994
1178.65	2.76754
1181.9	1.05011
1185.14	1.98502
1188.38	2.97736
1191.62	5.09812
1194.86	8.03024
1198.09	10.0803
1201.33	14.0595
1204.56	16.1982
1207.8	19.8385
1211.03	23.5032
1214.26	26.5737
1217.49	29.4303
1220.71	31.9543
1223.94	36.212
1227.16	38.7866
1230.39	40.6784
1233.61	44.0433
1236.83	46.6959
1240.05	49.7062
1243.27	51.8074
1246.49	55.1653
1249.71	55.5336
1252.92	56.9173
1256.14	58.3091
1259.35	60.1915
1262.56	60.7534
1265.77	61.714
1268.98	63.0455
1272.19	64.3442
1275.4	64.9147
1278.6	66.6527
1281.81	67.785
1285.01	69.5821
1288.21	71.3101
1291.41	72.188
1294.61	72.7714
1297.81	73.7753
1301.01	76.0953
1304.2	77.5492
1307.4	78.8442
1310.59	79.7465
1313.78	80.529
1316.97	80.2538
1320.16	80.0434
1323.35	80.9905
1326.54	79.6841
1329.72	77.9162
1332.91	77.3036
1336.09	75.5446
1339.27	72.2896
1342.45	70.1474
1345.64	66.3977
1348.81	62.2759
1351.99	59.6773
1355.17	57.1069
1358.34	55.0389
1361.51	52.8352
1364.69	48.7792
1367.86	45.3839
1371.03	43.9889
1374.2	42.3194
1377.37	40.1584
1380.53	38.7096
1383.7	36.5014
1386.86	37.1988
1390.02	36.2074
1393.19	35.7613
1396.35	34.3871
1399.51	33.8025
1402.66	33.8465
1405.82	33.6879
1408.97	36.0155
1412.13	37.83
1415.28	38.9969
1418.43	41.0968
1421.59	43.4921
1424.73	47.0686
1427.88	51.4155
1431.03	55.9484
1434.18	60.1924
1437.32	64.0522
1440.46	66.4587
1443.61	69.3961
1446.75	72.5363
1449.89	74.5593
1453.03	74.8988
1456.16	73.8753
1459.3	74.6503
1462.44	74.1072
1465.57	72.8083
1468.7	69.3179
1471.83	65.8602
1474.96	63.4798
1478.09	61.3094
1481.22	58.0532
1484.35	55.8772
1487.47	52.34
1490.6	49.3022
1493.72	46.3383
1496.84	44.4253
1499.96	42.661
1503.08	40.7731
1506.2	39.7716
1509.32	37.0462
1512.44	34.3379
1515.55	32.5899
1518.66	30.6997
1521.78	28.1841
1524.89	26.1054
1528	24.8672
1531.11	23.6581
1534.21	23.1675
1537.32	22.9841
1540.43	23.9506
1543.53	24.7923
1546.63	25.5035
1549.74	27.8302
1552.84	28.7353
1555.94	30.8166
1559.03	31.4165
1562.13	31.7723
1565.23	32.7267
1568.32	34.6975
1571.42	38.0883
1574.51	40.6816
1577.6	42.6833
1580.69	44.7218
1583.78	46.3838
1586.87	46.7945
1589.95	48.4686
1593.04	51.118
1596.12	52.3023
1599.21	53.4262
1602.29	53.2802
1605.37	55.5101
1608.45	56.5752
1611.53	58.4387
1614.6	58.7368
1617.68	60.0183
1620.75	63.331
1623.83	65.1861
1626.9	68.8835
1629.97	72.7704
1633.04	76.3215
1636.11	80.2175
1639.18	83.9736
1642.25	88.0758
1645.31	93.4332
1648.38	96.6464
1651.44	98.524
1654.5	99.521
1657.56	99.5186
1660.62	98.3574
1663.68	96.7216
1666.74	95.0893
1669.8	91.2358
1672.85	85.5559
1675.91	80.0074
1678.96	72.8678
1682.01	65.336
1685.06	58.0938
1688.11	51.5731
1691.16	45.4595
1694.21	40.0991
1697.25	35.0679
1700.3	31.421
1703.34	28.8252
1706.39	25.6914
1709.43	22.9543
1712.47	20.5774
1715.51	18.9531
1718.54	16.5061
1721.58	16.4223
1724.62	14.5757
1727.65	14.3655
1730.68	12.5358
1733.72	12.5821
1736.75	11.6343
1739.78	11.4355
1742.81	10.2596
1745.84	8.85443
1748.86	8.76596
1751.89	6.53227
1754.91	5.31178
1757.93	5.43234
1760.96	5.93938
1763.98	5.24408
1767	4.1785
1770.02	3.91437
1773.03	3.29796
1776.05	3.05583
1779.07	2.71487
1782.08	1.89474
1785.09	1.89971
1788.11	1.84439
1791.12	1.05599
1794.13	1.0037
1797.13	0.718476
1800.14	0.939555
1803.15	0.10667
1806.15	0.0425466
1809.16	0.315288
1812.16	0.0537544
1815.16	0.165531
1818.16	-0.205461
1821.16	0.0915205
1824.16	0.0831309
1827.16	1.18534
1830.16	1.08649
1833.15	0.786548
1836.14	1.29701
1839.14	1.64711
1842.13	2.0157
1845.12	1.86564
1848.11	2.07875
1851.1	2.06334
1854.08	1.78756
1857.07	2.68609
1860.05	2.74041
1863.04	2.61706
1866.02	2.74694
1869	3.14235
1871.98	2.73724
1874.96	2.13657
1877.94	1.63875
1880.92	1.92017
1882.51	2.42184
1885.5	2.57644
1888.48	2.07926
1891.47	2.78446
1894.46	3.11402
1897.44	2.87354
1900.42	2.24022
1903.41	1.90989
1906.39	1.93874
1909.37	2.99175
1912.35	3.41675
1915.32	3.91594
1918.3	3.19552
1921.27	3.38498
1924.25	3.67122
1927.22	4.359
1930.19	3.79691
1933.17	3.89297
1936.14	3.98874
1939.11	3.14043
1942.07	2.30339
1945.04	1.50672
1948.01	1.51578
1950.97	1.51633
1953.93	1.91637
1956.9	2.3469
1959.86	2.06093
1962.82	1.65381
1965.78	1.77084
1968.74	1.54361
1971.69	1.57886
1974.65	1.78182
1977.6	2.64323
1980.56	2.99871
1983.51	3.55537
1986.46	2.9449
1989.41	3.11085
1992.36	4.14382
1995.31	3.87173
1998.26	3.57399
2001.2	3.66646
2004.15	3.84582
2007.09	4.27636
2010.04	3.4838
2012.98	3.51353
2015.92	3.82418
2018.86	4.03983
2021.8	4.34169
2024.73	3.69744
2027.67	2.57399
2030.61	3.24559
2033.54	3.37906
2036.47	3.73278
2039.4	4.11048
2042.33	4.76938
2045.27	4.89513
2048.19	4.9149
2051.12	5.34975
2054.05	5.67707
2056.97	5.60123
2059.9	6.73613
2062.82	8.12813
2065.74	8.87519
2068.67	9.0933
2071.59	11.1839
2074.51	11.7531
2077.42	12.6076
2080.34	14.1993
2083.26	15.5507
2086.17	17.1903
2089.09	18.002
2092	19.3296
2094.91	19.3438
2097.82	20.002
2100.73	21.8952
2103.64	24.2678
2106.55	25.4809
2109.45	26.8899
2112.36	28.5449
2115.26	30.5097
2118.17	33.4114
2121.07	36.5325
2123.97	39.3699
2126.87	42.4171
2129.77	46.8909
2132.67	50.5495
2135.56	53.8645
2138.46	57.6245
2141.35	62.0166
2144.25	65.7733
2147.14	69.0477
2150.03	73.5569
2152.92	77.5793
2155.81	80.6042
2158.7	83.9795
2161.59	86.1539
2164.47	88.3989
2167.36	90.2449
2170.24	92.4909
2173.13	93.8705
2176.01	94.6221
2178.89	93.538
2181.77	92.9354
2184.65	92.289
2187.53	91.3542
2190.4	89.2387
2193.28	86.878
2196.16	83.8193
2199.03	80.3855
2201.9	77.2595
2204.77	72.9484
2207.64	68.7938
2210.51	64.4868
2213.38	59.9323
2216.25	54.9838
2219.12	50.3314
2221.98	46.3754
2224.85	42.2994
2227.71	39.0236
2230.57	35.1064
2233.43	32.3791
2236.29	29.6199
2239.15	26.7845
2242.01	25.2401
2244.87	23.4429
2247.72	21.8337
2250.58	20.8002
2253.43	19.9496
2256.29	18.811
2259.14	19.0893
2261.99	18.2102
2264.84	17.3282
2267.69	16.8046
2270.53	17.0284
2273.38	16.9552
2276.23	16.411
2279.07	15.676
2281.91	15.3331
2284.76	14.1722
2287.6	11.876
2290.44	10.7963
2293.28	8.71732
2296.12	7.66227
2298.96	8.10885
2301.79	8.34421
2304.63	8.60378
2307.46	8.37409
2310.3	9.46444
2313.13	9.48532
2315.96	9.86758
2318.79	10.1264
2321.62	10.2099
2324.45	10.6237
2327.27	10.7099
2330.1	11.1074
2332.92	10.1964
2335.75	10.7285
2338.57	10.432
2341.39	9.65121
2344.21	8.80444
2347.04	8.58673
2349.85	7.93348
2352.67	6.17666
2355.49	3.90034
2358.3	1.90166
2361.12	0.875563
2363.93	1.09156
2366.75	1.72182
2369.56	2.30166
2372.37	1.85574
2375.18	1.29988
2377.99	0.900514
2380.8	1.0762
2383.6	1.32511
2386.41	1.76027
2389.21	1.50204
2392.02	1.44452
2394.82	0.962904
2397.62	0.481203
2400.42	0.820862
2403.22	0.523623
2406.02	0.249393
2408.82	0.556742
2411.62	1.56872
2414.41	2.762
2417.21	3.47313
2420	4.14047
2422.79	3.48923
2425.59	3.45166
2428.38	3.54516
2431.17	3.91327
2433.95	4.47903
2436.74	4.3899
2439.53	4.31888
2442.31	3.94732
2445.1	3.84089
2447.88	4.44519
2450.67	3.89864
2453.45	3.86011
2456.23	3.47667
2459.01	2.44138
2461.79	2.23685
2464.57	2.30613
2467.34	2.04482
2470.12	2.25324
2472.89	2.30122
2475.67	3.12638
2478.44	3.17112
2481.21	3.04346
2483.98	3.12374
2486.75	3.17002
2489.52	2.57801
2492.29	2.02254
2495.05	1.81687
2497.82	2.30019
2500.58	2.27499
2503.35	1.91682
2506.11	2.53745
2508.87	3.01235
2511.63	2.89088
2514.39	3.45702
2517.15	3.85215
2519.91	3.53674
2522.67	3.73939
2525.42	4.11215
2528.18	4.74697
2530.93	5.22446
2533.69	5.58863
2536.44	5.52267
2539.19	6.03659
2541.94	5.03315
2544.69	4.66251
2547.44	4.27194
2550.18	4.51589
2552.93	4.09942
2555.67	4.00018
2558.42	3.0754
2561.16	2.61185
2563.9	2.36639
2566.64	2.93942
2569.38	2.84085
2572.12	3.81829
2574.86	3.53571
2577.6	2.80841
2580.33	2.7751
2583.07	2.24962
2585.8	1.83643
2588.54	2.17291
2591.27	3.30248
2594	3.54103
2596.73	3.12944
2599.46	3.94172
2602.19	4.04136
2604.92	4.41864
2607.64	4.93355
2610.37	5.7821
2613.09	6.11368
2615.82	5.97908
2618.54	6.13813
2621.26	5.81137
2623.98	5.36868
2626.7	5.22905
2629.42	5.63936
2632.14	6.2624
2634.86	6.70432
2637.57	6.53701
2640.29	5.73539
2643	5.69751
2645.71	5.85239
2648.43	5.96825
2651.14	5.26071
2653.85	5.87016
2656.56	5.24518
2659.26	4.71045
2661.97	4.33243
2664.68	4.65497
2667.38	4.79129
2670.09	4.00444
2672.79	3.93983
2675.49	4.56171
2678.19	3.35515
2680.89	2.80086
2683.59	1.34523
2686.29	1.77518
2688.99	2.23644
2691.69	2.47015
2694.38	3.54539
2697.08	4.9744
2699.77	6.22572
2702.46	6.8146
2705.15	7.10299
2707.85	8.92378
2710.54	8.92671
2713.22	9.92916
2715.91	10.4227
2718.6	11.1072
2721.29	11.8896
2723.97	12.1264
2726.66	12.4711
2729.34	12.5086
2732.02	12.6535
2734.7	11.9625
2737.38	12.027
2740.06	12.6146
2742.74	11.7318
2745.42	10.6381
2748.09	10.1408
2750.77	9.26262
2753.45	8.62517
2756.12	7.82822
2758.79	7.32741
2761.46	7.30009
2764.14	6.61138
2766.8	4.68463
2769.47	4.04159
2772.14	4.21543
2774.81	3.01002
2777.48	2.80434
2780.14	2.58067
2782.8	1.69122
2785.47	1.53198
2788.13	0.717122
2790.79	0.83765
2793.45	1.08921
2796.11	1.68276
2798.77	2.51779
2801.43	2.79451
2804.09	2.89436
2806.74	2.52979
2809.4	2.26664
2812.05	2.29019
2814.71	2.78986
2817.36	3.11188
2820.01	4.439
2822.66	6.92187
2825.31	9.59775
2827.96	13.3005
2830.6	16.891
2833.25	20.8142
2835.9	26.2161
2838.54	30.1022
2841.18	35.4398
2843.83	41.9611
2846.47	48.5747
2849.11	56.3024
2851.75	66.1044
2854.39	74.3967
2857.03	84.0341
2859.66	91.8595
2862.3	99.6805
2864.94	106.765
2867.57	113.887
2870.2	119.969
2872.84	125.378
2875.47	130.777
2878.1	135.975
2880.73	139.302
2883.36	144.519
2885.99	149.673
2888.61	154.637
2891.24	158.974
2893.86	163.495
2896.49	169.339
2899.11	176.413
2901.73	184.149
2904.36	193.155
2906.98	204.5
2909.6	216.088
2912.21	228.235
2914.83	240.933
2917.45	252.652
2920.07	262.156
2922.68	272.145
2925.29	279.936
2927.91	286.12
2930.52	290.38
2933.13	291.999
2935.74	291.267
2938.35	288.362
2940.96	282.489
2943.57	274.883
2946.18	265.953
2948.78	257.393
2951.39	245.841
2953.99	233.139
2956.59	220.868
2959.2	208.566
2961.8	196.669
2964.4	185.783
2967	173.878
2969.6	163.621
2972.19	152.537
2974.79	143.033
2977.39	133.98
2979.98	123.966
2982.58	114.022
2985.17	105.497
2987.76	96.5869
2990.35	87.2604
2992.94	78.0591
2995.53	69.9661
2998.12	61.5494
3000.71	53.7735
3003.3	46.7564
3005.88	39.6643
3008.47	34.1246
3011.05	28.9075
3013.64	24.6016
3016.22	20.4338
3018.8	16.9701
3021.38	15.4239
3023.96	12.8083
3026.54	11.0716
3029.12	10.2634
3031.69	9.61974
3034.27	9.43528
3036.84	9.88522
3039.42	10.3965
3041.99	10.4585
3044.57	10.3256
3047.14	11.0686
3049.71	11.2061
3052.28	10.9744
3054.85	11.1628
3057.41	12.1795
3059.98	12.2155
3062.55	12.3864
3065.11	11.1204
3067.68	10.7208
3070.24	10.3053
3072.8	9.18331
3075.36	7.73274
3077.93	6.55192
3080.49	5.66444
3083.04	4.72267
3085.6	3.35617
3088.16	3.28608
3090.72	2.90049
3093.27	2.8407
3095.83	2.8494
3098.38	3.01018
3100.93	2.88412
3103.49	3.61573
3106.04	4.06454
3108.59	5.04538
3111.14	6.22482
3113.69	6.69701
3116.23	8.08105
3118.78	8.51349
3121.33	9.38749
3123.87	10.5197
3126.41	11.2645
3128.96	11.5815
3131.5	12.8731
3134.04	13.0807
3136.58	13.2854
3139.12	14.1378
3141.66	15.1656
3144.2	16.7406
3146.74	18.6553
3149.27	20.323