File: data/Raman/poly_smoothed/Mb_30_27_31_1x_45s_532 nm_x100_100%_600 gr_mm_01.txt
#Acq. time (s)=	45
#Accumulations=	2
#Range (cm-¹)=	200...3150
#Windows=	2
#Auto scanning=	Off
#Autofocus=	Off
#Macrospot=	Off
#AutoExposure=	Off
#Spike filter=	Multiple accum.
#Delay time (s)=	0
#Binning=	1
#Readout mode=	Signal
#DeNoise=	Off
#ICS correction=	On
#Dark correction=	Off
#Inst. Process=	Off
#Detector Gain=	Best Dynamic Range
#Detector ADC=	20 kHz
#Detector temperature (°C)=	-69.85
#Instrument=	LabRAM HR Evol
#Detector=	Synapse
#Objective=	x100
#Grating=	600 gr/mm
#ND Filter=	100%
#Laser (nm)=	532
#Hole=	100.021
#Range=	Auto
#Laser Pol.=	No
#Raman. Pol.=	No
#Laser Pol. (°)=	-0.0007625
#Raman Pol. (°)=	89.9995
#Collection=	Microscope
#StageXY=	Marzhauser
#StageZ=	Marzhauser
#X (µm)=	-6374.4
#Y (µm)=	826.6
#Z (µm)=	-64.65
#Full time(mm:ss)=	3:18
#Project=
#Sample=
#Site=
#Title=	Mb_30_27_31_2x_45s_532 nm_x100_100%_600 gr_mm
#Remark=
#Date=	13.07.2022 11:01
#Acquired=	13.07.2022 11:01:32
#Base:Fit=	10.08.2022 10:40:03
#Base:Sub=	10.08.2022 10:40:17
#Filter:Polynom=	16.08.2022 10:16:15
#AxisType[0]=Intens
#AxisUnit[0]=Cnt
#AxisType[1]=Spectr
#AxisUnit[1]=1/cm
200.563	31.2056
204.194	29.7342
207.821	27.6278
211.449	24.4875
215.074	19.9056
218.699	16.0406
222.321	15.0108
225.941	14.5416
229.562	13.4687
233.18	13.8329
236.796	11.295
240.411	11.9107
244.026	11.7791
247.638	9.71633
251.248	8.70211
254.857	9.751
258.465	11.6105
262.071	14.5288
265.678	15.8702
269.282	17.0783
272.884	16.5174
276.484	16.5656
280.084	17.2563
283.682	20.5381
287.276	21.5434
290.871	21.0035
294.465	20.5678
298.057	18.3902
301.648	17.0988
305.237	17.1125
308.823	17.4486
312.41	17.4494
315.995	16.2682
319.579	15.9011
323.16	15.6703
326.741	15.1493
330.321	15.5812
333.897	14.5537
337.474	12.886
341.048	13.8841
344.622	16.1914
348.192	16.8343
351.764	18.0504
355.332	16.3557
358.901	15.4595
362.466	14.7911
366.03	15.5761
369.594	16.0669
373.155	15.8389
376.715	13.3126
380.273	11.7499
383.832	10.4222
387.388	10.8406
390.942	11.4492
394.495	11.5075
398.047	12.0428
401.597	11.7363
405.145	11.8128
408.693	13.2944
412.239	13.1581
415.783	15.0621
419.327	14.1034
422.869	13.8115
426.409	16.0516
429.948	17.0219
433.486	17.3673
437.022	18.1038
440.558	16.464
444.089	15.6332
447.622	16.1858
451.153	16.7488
454.682	16.2455
458.208	15.7482
461.735	15.0067
465.259	13.1883
468.783	15.2468
472.306	15.6943
475.825	17.5189
479.346	17.9761
482.862	18.2973
486.38	20.1412
489.894	23.2533
493.407	26.7694
496.92	29.2272
500.43	30.1399
503.939	30.343
507.448	31.1109
510.954	31.4927
514.459	32.9644
517.962	31.836
521.466	31.8765
524.966	31.5108
528.466	30.9461
531.964	29.3297
535.46	28.0674
538.955	26.0422
542.449	25.3141
545.942	23.4461
549.433	21.4273
552.923	19.6104
556.412	17.2318
559.899	16.3887
563.385	15.0194
566.867	13.1987
570.35	12.436
573.832	12.2857
577.313	12.6139
580.79	10.7101
584.268	8.78074
587.745	7.06342
591.218	4.81504
594.692	3.42329
598.164	3.20003
601.634	1.88151
605.104	2.54137
608.57	5.51909
612.037	7.60239
615.501	7.56163
618.966	8.16726
622.427	10.2012
625.887	11.2747
629.348	13.4347
632.806	14.0877
636.262	13.7611
639.716	14.5521
643.172	15.0568
646.624	15.6586
650.075	15.7862
653.524	14.2358
656.972	14.5665
660.419	14.545
663.865	13.6465
667.309	13.8635
670.752	12.954
674.194	12.9128
677.634	13.9602
681.073	16.4214
684.511	18.4976
687.947	21.0082
691.382	25.1706
694.816	28.7303
698.247	30.306
701.678	33.1369
705.108	35.3559
708.534	37.0093
711.962	38.9564
715.388	39.0016
718.81	40.1354
722.234	41.0363
725.654	42.4282
729.075	42.4898
732.492	43.4435
735.91	44.1622
739.325	44.2504
742.741	44.4594
746.153	46.7938
749.564	49.5606
752.976	51.2207
756.385	53.8974
759.792	57.5019
763.2	60.8002
766.604	62.476
770.008	66.246
773.41	69.4721
776.811	71.7963
780.21	74.8039
783.608	76.7209
787.005	76.979
790.401	78.1848
793.795	79.4592
797.188	80.7944
800.58	82.3255
803.971	83.9382
807.36	84.6452
810.748	85.6231
814.135	85.7784
817.518	86.194
820.902	86.4026
824.285	85.545
827.665	87.2341
831.045	85.5794
834.424	82.2132
837.8	79.683
841.177	78.5788
844.55	75.7866
847.924	72.705
851.295	68.966
854.666	66.5166
858.034	64.1976
861.403	61.3384
864.769	57.9665
868.133	55.3735
871.498	53.5059
874.86	52.3301
878.221	51.568
881.58	49.195
884.938	49.7065
888.297	50.0138
891.653	49.544
895.007	48.4852
898.36	48.9119
901.712	48.4502
905.063	48.1513
908.412	48.0264
911.76	48.7307
915.107	47.6326
918.452	48.9841
921.797	50.5855
925.138	49.8154
928.48	49.384
931.82	49.2402
935.16	47.2706
938.496	47.4436
941.833	46.2587
945.168	44.724
948.5	43.8639
951.834	42.1557
955.163	40.8256
958.494	40.483
961.821	37.5541
965.15	39.0482
968.474	38.7513
971.8	38.0322
975.123	36.7617
978.446	36.3041
981.766	35.6064
985.084	35.7517
988.402	35.3777
991.72	34.6795
995.035	31.0319
998.349	27.8822
1001.66	30.3035
1004.97	31.6427
1008.28	34.9659
1011.59	39.7123
1014.9	43.1935
1018.21	47.4185
1021.51	52.0914
1024.81	55.0763
1028.12	58.5239
1031.42	61.0118
1034.72	62.8771
1038.02	65.9372
1041.31	66.1655
1044.61	67.243
1047.91	68.1077
1051.2	66.2707
1054.49	62.9813
1057.78	57.8477
1061.07	52.9404
1064.36	47.2454
1067.65	40.0785
1070.93	32.7592
1074.22	25.241
1077.5	19.8042
1080.78	19.2787
1084.06	19.3688
1087.34	16.7185
1090.62	16.9471
1093.9	16.6189
1097.17	17.6735
1100.45	18.6824
1103.72	17.3746
1106.99	18.6956
1110.27	20.0797
1113.53	18.8539
1116.8	20.3074
1120.07	21.5985
1123.33	20.0664
1126.6	19.4842
1129.86	19.338
1133.12	17.0584
1136.38	14.6621
1139.64	13.3096
1142.9	11.6713
1146.16	9.89032
1149.41	9.0005
1152.67	7.79558
1155.92	6.93361
1159.17	5.12321
1162.42	3.26723
1165.67	2.44281
1168.92	2.70815
1172.16	2.55375
1175.41	3.83526
1178.65	2.33023
1181.9	3.09591
1185.14	2.32366
1188.38	3.80553
1191.62	4.27358
1194.86	6.26721
1198.09	7.91466
1201.33	7.59548
1204.56	8.38516
1207.8	11.1316
1211.03	14.1885
1214.26	16.79
1217.49	19.453
1220.71	21.6861
1223.94	25.7219
1227.16	29.8512
1230.39	36.0257
1233.61	40.1251
1236.83	44.5676
1240.05	49.4667
1243.27	53.5165
1246.49	57.1164
1249.71	60.7326
1252.92	62.5768
1256.14	65.1758
1259.35	66.4175
1262.56	68.8431
1265.77	70.8836
1268.98	72.5238
1272.19	74.5165
1275.4	74.0636
1278.6	73.0504
1281.81	72.2869
1285.01	73.2088
1288.21	73.9317
1291.41	72.6666
1294.61	73.2683
1297.81	72.4495
1301.01	73.99
1304.2	76.1134
1307.4	78.2237
1310.59	80.865
1313.78	82.5313
1316.97	83.4429
1320.16	83.3413
1323.35	83.0066
1326.54	82.6944
1329.72	80.7133
1332.91	80.1021
1336.09	78.512
1339.27	76.7904
1342.45	74.9403
1345.64	72.8374
1348.81	69.0568
1351.99	64.732
1355.17	60.6349
1358.34	57.3287
1361.51	54.1965
1364.69	51.8004
1367.86	50.1277
1371.03	48.1303
1374.2	46.5149
1377.37	45.8029
1380.53	46.2532
1383.7	45.657
1386.86	46.356
1390.02	45.3995
1393.19	43.8349
1396.35	41.4051
1399.51	39.5063
1402.66	38.3187
1405.82	38.333
1408.97	40.1125
1412.13	40.5628
1415.28	43.1558
1418.43	46.6316
1421.59	50.0943
1424.73	53.5814
1427.88	58.9475
1431.03	63.6025
1434.18	69.6102
1437.32	74.4535
1440.46	78.8278
1443.61	82.4833
1446.75	86.5452
1449.89	87.0016
1453.03	89.8852
1456.16	89.3031
1459.3	88.3434
1462.44	85.2914
1465.57	80.2313
1468.7	75.1792
1471.83	69.4503
1474.96	64.6615
1478.09	59.5797
1481.22	56.4973
1484.35	53.084
1487.47	48.5917
1490.6	44.5927
1493.72	42.3702
1496.84	39.7825
1499.96	37.2697
1503.08	35.1572
1506.2	32.8973
1509.32	31.61
1512.44	30.207
1515.55	28.2164
1518.66	26.9725
1521.78	25.6737
1524.89	25.9154
1528	25.4582
1531.11	24.8967
1534.21	23.9456
1537.32	25.5698
1540.43	24.4865
1543.53	26.0422
1546.63	28.8672
1549.74	28.9813
1552.84	31.1387
1555.94	33.7964
1559.03	35.3751
1562.13	38.2243
1565.23	40.7708
1568.32	43.9448
1571.42	47.0954
1574.51	49.3077
1577.6	51.7988
1580.69	53.5043
1583.78	57.7861
1586.87	60.5135
1589.95	62.5987
1593.04	65.7295
1596.12	66.5444
1599.21	68.3079
1602.29	70.9606
1605.37	70.981
1608.45	72.0994
1611.53	73.6884
1614.6	73.5973
1617.68	75.1713
1620.75	75.7745
1623.83	76.2337
1626.9	76.9731
1629.97	79.9069
1633.04	82.4719
1636.11	87.1401
1639.18	90.5839
1642.25	92.8046
1645.31	97.0036
1648.38	100.764
1651.44	103.518
1654.5	106.409
1657.56	107.47
1660.62	107.83
1663.68	106.761
1666.74	105.861
1669.8	102.485
1672.85	97.5819
1675.91	93.6975
1678.96	88.7104
1682.01	83.0793
1685.06	76.21
1688.11	69.416
1691.16	63.0561
1694.21	56.2071
1697.25	50.1413
1700.3	44.2365
1703.34	39.9507
1706.39	36.8596
1709.43	32.612
1712.47	28.1992
1715.51	25.0191
1718.54	24.486
1721.58	23.6834
1724.62	21.3799
1727.65	19.216
1730.68	17.9784
1733.72	17.4459
1736.75	15.9547
1739.78	15.253
1742.81	13.7504
1745.84	11.654
1748.86	11.6572
1751.89	10.6544
1754.91	9.56402
1757.93	8.24431
1760.96	6.99473
1763.98	6.43001
1767	5.02941
1770.02	4.40093
1773.03	2.83333
1776.05	1.94827
1779.07	2.30805
1782.08	1.01055
1785.09	0.315609
1788.11	0.706447
1791.12	1.1287
1794.13	1.38551
1797.13	1.61358
1800.14	1.29999
1803.15	1.27333
1806.15	1.52462
1809.16	2.10723
1812.16	1.68124
1815.16	2.31633
1818.16	3.218
1821.16	3.41858
1824.16	3.55646
1827.16	3.55797
1830.16	3.77584
1833.15	3.96509
1836.14	4.27632
1839.14	5.06754
1842.13	4.80591
1845.12	4.07416
1848.11	3.48807
1851.1	3.91513
1854.08	3.89484
1857.07	3.52869
1860.05	3.63244
1863.04	2.95448
1866.02	2.95892
1869	1.78377
1871.98	1.64729
1874.96	0.76713
1877.94	0.628424
1880.92	0.83845
1882.51	-0.137515
1885.5	0.204346
1888.48	0.747225
1891.47	0.491869
1894.46	0.631691
1897.44	0.833506
1900.42	2.55437
1903.41	3.37566
1906.39	3.38091
1909.37	3.56129
1912.35	3.71148
1915.32	3.34526
1918.3	3.69163
1921.27	3.95905
1924.25	4.95856
1927.22	3.909
1930.19	3.86214
1933.17	3.80969
1936.14	3.04095
1939.11	2.50832
1942.07	2.52435
1945.04	3.22888
1948.01	2.90199
1950.97	1.7234
1953.93	1.11403
1956.9	0.810748
1959.86	1.82055
1962.82	2.14646
1965.78	2.9072
1968.74	3.53371
1971.69	4.97793
1974.65	5.46512
1977.6	5.80239
1980.56	5.34503
1983.51	6.1471
1986.46	7.04068
1989.41	7.77789
1992.36	8.64425
1995.31	8.18744
1998.26	8.69639
2001.2	8.55508
2004.15	8.4831
2007.09	8.3896
2010.04	8.58799
2012.98	9.57933
2015.92	9.36088
2018.86	7.75243
2021.8	7.34072
2024.73	8.28416
2027.67	7.93241
2030.61	8.28031
2033.54	8.99274
2036.47	9.11349
2039.4	9.33295
2042.33	9.24716
2045.27	9.46984
2048.19	9.13623
2051.12	9.35382
2054.05	9.03444
2056.97	9.391
2059.9	10.4246
2062.82	10.7099
2065.74	11.4926
2068.67	11.9156
2071.59	12.6868
2074.51	14.1413
2077.42	15.3616
2080.34	16.9554
2083.26	18.1832
2086.17	20.0056
2089.09	19.8786
2092	21.8931
2094.91	23.568
2097.82	25.7319
2100.73	27.7051
2103.64	30.3101
2106.55	31.9896
2109.45	32.7204
2112.36	33.443
2115.26	36.4733
2118.17	38.328
2121.07	40.2404
2123.97	43.645
2126.87	46.2308
2129.77	51.3095
2132.67	54.9334
2135.56	59.0632
2138.46	64.8847
2141.35	69.4137
2144.25	73.9497
2147.14	78.2683
2150.03	82.9731
2152.92	87.2926
2155.81	91.8871
2158.7	95.5615
2161.59	98.3848
2164.47	101.837
2167.36	105.039
2170.24	107.16
2173.13	108.279
2176.01	108.226
2178.89	107.954
2181.77	106.836
2184.65	104.95
2187.53	103.014
2190.4	98.9695
2193.28	95.0666
2196.16	92.2425
2199.03	88.8894
2201.9	84.425
2204.77	80.1991
2207.64	77.0504
2210.51	72.8261
2213.38	67.9441
2216.25	63.0104
2219.12	58.692
2221.98	54.7687
2224.85	51.297
2227.71	47.2621
2230.57	43.9812
2233.43	40.7834
2236.29	38.4803
2239.15	36.2111
2242.01	33.9795
2244.87	31.9539
2247.72	30.692
2250.58	28.8654
2253.43	27.1383
2256.29	24.8687
2259.14	23.2526
2261.99	22.207
2264.84	22.6433
2267.69	22.3645
2270.53	20.8985
2273.38	19.7166
2276.23	19.6118
2279.07	19.3069
2281.91	17.7132
2284.76	16.1585
2287.6	15.0464
2290.44	13.4083
2293.28	11.7813
2296.12	10.7003
2298.96	10.4119
2301.79	11.0328
2304.63	11.3393
2307.46	11.4911
2310.3	10.3594
2313.13	10.5347
2315.96	10.4038
2318.79	9.50545
2321.62	8.67651
2324.45	8.07748
2327.27	7.39373
2330.1	7.2288
2332.92	7.72347
2335.75	7.64446
2338.57	6.03243
2341.39	4.65731
2344.21	4.61869
2347.04	4.0158
2349.85	2.85107
2352.67	1.42442
2355.49	1.23548
2358.3	0.780434
2361.12	-0.0143782
2363.93	-0.072897
2366.75	0.549384
2369.56	1.32111
2372.37	1.44927
2375.18	1.47924
2377.99	1.29663
2380.8	0.573906
2383.6	1.43915
2386.41	1.68323
2389.21	1.71837
2392.02	1.60121
2394.82	1.99353
2397.62	1.39412
2400.42	2.74752
2403.22	1.65084
2406.02	2.46552
2408.82	2.70278
2411.62	2.72403
2414.41	2.81192
2417.21	2.06249
2420	1.95227
2422.79	2.45321
2425.59	3.50117
2428.38	3.67147
2431.17	4.1775
2433.95	4.57237
2436.74	5.15295
2439.53	4.9794
2442.31	4.9761
2445.1	5.15847
2447.88	5.53881
2450.67	5.32485
2453.45	5.73308
2456.23	5.07962
2459.01	4.4143
2461.79	4.21346
2464.57	3.8143
2467.34	3.82386
2470.12	3.51566
2472.89	2.97097
2475.67	2.7207
2478.44	2.43953
2481.21	1.38938
2483.98	1.77066
2486.75	1.61209
2489.52	1.99752
2492.29	2.17643
2495.05	1.24051
2497.82	0.709116
2500.58	0.686007
2503.35	0.64742
2506.11	0.140212
2508.87	0.376588
2511.63	0.0542281
2514.39	0.246097
2517.15	-0.0789439
2519.91	0.193111
2522.67	-0.0177139
2525.42	0.440694
2528.18	0.326157
2530.93	0.558742
2533.69	0.879023
2536.44	1.43912
2539.19	1.58352
2541.94	2.01986
2544.69	2.68158
2547.44	2.99317
2550.18	3.55145
2552.93	4.30579
2555.67	4.48818
2558.42	4.99047
2561.16	3.99803
2563.9	3.93222
2566.64	4.27923
2569.38	4.80803
2572.12	4.7434
2574.86	4.03107
2577.6	3.8083
2580.33	3.15699
2583.07	3.07568
2585.8	3.29956
2588.54	2.83109
2591.27	2.8153
2594	1.61874
2596.73	2.23501
2599.46	2.01179
2602.19	0.975381
2604.92	0.893118
2607.64	0.716964
2610.37	0.667798
2613.09	0.36767
2615.82	1.04198
2618.54	1.88783
2621.26	2.1801
2623.98	3.16708
2626.7	2.97492
2629.42	3.92386
2632.14	3.7167
2634.86	4.19218
2637.57	4.41382
2640.29	4.17587
2643	4.61581
2645.71	5.2012
2648.43	4.90442
2651.14	5.98532
2653.85	5.56492
2656.56	6.2984
2659.26	7.15998
2661.97	7.06361
2664.68	6.55011
2667.38	5.57197
2670.09	5.43263
2672.79	4.72027
2675.49	3.97154
2678.19	3.98107
2680.89	3.75939
2683.59	4.19374
2686.29	4.38991
2688.99	4.41235
2691.69	4.35054
2694.38	3.62282
2697.08	3.52239
2699.77	4.1182
2702.46	4.69566
2705.15	4.96133
2707.85	5.06432
2710.54	6.26083
2713.22	6.01676
2715.91	6.12382
2718.6	7.05219
2721.29	8.06394
2723.97	9.82332
2726.66	11.059
2729.34	10.7358
2732.02	11.0463
2734.7	11.3517
2737.38	11.3553
2740.06	12.0296
2742.74	12.4666
2745.42	11.7049
2748.09	11.3248
2750.77	11.1817
2753.45	10.1802
2756.12	9.56841
2758.79	9.34224
2761.46	8.7303
2764.14	8.52287
2766.8	7.08518
2769.47	5.54733
2772.14	3.80641
2774.81	3.01247
2777.48	1.70547
2780.14	1.3943
2782.8	1.21997
2785.47	1.9969
2788.13	2.44298
2790.79	3.36253
2793.45	3.45562
2796.11	2.84429
2798.77	2.84399
2801.43	2.3875
2804.09	2.66715
2806.74	2.06788
2809.4	0.967723
2812.05	1.20222
2814.71	1.68216
2817.36	2.74205
2820.01	5.50017
2822.66	8.38128
2825.31	11.1523
2827.96	14.3328
2830.6	18.3491
2833.25	22.3779
2835.9	28.1425
2838.54	34.4672
2841.18	40.8396
2843.83	49.0784
2846.47	57.9001
2849.11	66.5493
2851.75	76.6795
2854.39	86.5456
2857.03	94.603
2859.66	103.556
2862.3	112.238
2864.94	119.676
2867.57	126.833
2870.2	133.264
2872.84	137.986
2875.47	143.14
2878.1	148.56
2880.73	153.205
2883.36	157.918
2885.99	162.981
2888.61	167.014
2891.24	171.798
2893.86	176.83
2896.49	183.071
2899.11	191.064
2901.73	199.77
2904.36	210.388
2906.98	223.159
2909.6	236.307
2912.21	250.717
2914.83	265.364
2917.45	279.382
2920.07	292.926
2922.68	304.949
2925.29	315.624
2927.91	321.848
2930.52	326.661
2933.13	329.535
2935.74	328.789
2938.35	324.963
2940.96	320.316
2943.57	313.501
2946.18	304.3
2948.78	293.138
2951.39	280.552
2953.99	266.283
2956.59	251.532
2959.2	238.138
2961.8	223.855
2964.4	210.86
2967	197.421
2969.6	185.027
2972.19	173.328
2974.79	162.539
2977.39	152.6
2979.98	141.998
2982.58	131.491
2985.17	121.8
2987.76	112.094
2990.35	101.41
2992.94	92.2622
2995.53	84.5221
2998.12	75.8757
3000.71	67.6817
3003.3	59.692
3005.88	53.8359
3008.47	47.1361
3011.05	40.4852
3013.64	34.8188
3016.22	29.3891
3018.8	24.8246
3021.38	21.7951
3023.96	18.914
3026.54	14.9544
3029.12	12.9991
3031.69	10.8759
3034.27	10.3417
3036.84	10.2186
3039.42	9.83862
3041.99	10.7168
3044.57	11.0954
3047.14	12.3905
3049.71	13.8409
3052.28	14.0873
3054.85	14.0872
3057.41	14.4912
3059.98	14.2886
3062.55	13.4967
3065.11	12.8496
3067.68	11.9688
3070.24	11.1129
3072.8	10.2044
3075.36	8.79425
3077.93	7.46414
3080.49	6.59055
3083.04	5.18921
3085.6	4.0366
3088.16	2.48185
3090.72	1.45671
3093.27	-0.219997
3095.83	0.537782
3098.38	-0.0415784
3100.93	0.0123931
3103.49	0.565549
3106.04	0.883931
3108.59	1.54475
3111.14	1.00764
3113.69	1.46994
3116.23	0.57948
3118.78	0.99348
3121.33	1.25043
3123.87	1.44977
3126.41	2.02603
3128.96	2.87958
3131.5	2.38159
3134.04	4.11823
3136.58	4.57969
3139.12	5.11684
3141.66	5.74662
3144.2	6.19829
3146.74	6.86927
3149.27	8.21158