File: data/Raman/poly_smoothed/Mb_30_27_18_1x_45s_532 nm_x100_100%_600 gr_mm_01.txt
#Acq. time (s)=	45
#Accumulations=	2
#Range (cm-¹)=	200...3150
#Windows=	2
#Auto scanning=	Off
#Autofocus=	Off
#Macrospot=	Off
#AutoExposure=	Off
#Spike filter=	Multiple accum.
#Delay time (s)=	0
#Binning=	1
#Readout mode=	Signal
#DeNoise=	Off
#ICS correction=	On
#Dark correction=	Off
#Inst. Process=	Off
#Detector Gain=	Best Dynamic Range
#Detector ADC=	20 kHz
#Detector temperature (°C)=	-69.85
#Instrument=	LabRAM HR Evol
#Detector=	Synapse
#Objective=	x100
#Grating=	600 gr/mm
#ND Filter=	100%
#Laser (nm)=	532
#Hole=	100.021
#Range=	Auto
#Laser Pol.=	No
#Raman. Pol.=	No
#Laser Pol. (°)=	-0.0007625
#Raman Pol. (°)=	89.9995
#Collection=	Microscope
#StageXY=	Marzhauser
#StageZ=	Marzhauser
#X (µm)=	-6400
#Y (µm)=	874.6
#Z (µm)=	-64.4
#Full time(mm:ss)=	3:18
#Project=
#Sample=
#Site=
#Title=	Mb_30_27_18_2x_45s_532 nm_x100_100%_600 gr_mm
#Remark=
#Date=	13.07.2022 09:58
#Acquired=	13.07.2022 09:58:38
#Base:Fit=	10.08.2022 10:40:03
#Base:Sub=	10.08.2022 10:40:17
#Filter:Polynom=	16.08.2022 10:16:15
#AxisType[0]=Intens
#AxisUnit[0]=Cnt
#AxisType[1]=Spectr
#AxisUnit[1]=1/cm
200.563	21.4035
204.194	22.7455
207.821	23.0451
211.449	22.8281
215.074	21.2814
218.699	19.3588
222.321	16.2051
225.941	13.8009
229.562	11.83
233.18	10.6669
236.796	10.9669
240.411	9.58279
244.026	8.83538
247.638	6.4617
251.248	5.35526
254.857	5.87677
258.465	4.4264
262.071	5.15549
265.678	4.78689
269.282	5.92151
272.884	5.79471
276.484	5.60572
280.084	6.13888
283.682	7.31435
287.276	8.03719
290.871	9.85116
294.465	9.47374
298.057	9.95928
301.648	10.0035
305.237	9.69952
308.823	10.0124
312.41	9.65094
315.995	10.5124
319.579	10.8295
323.16	10.9325
326.741	10.3774
330.321	9.24704
333.897	8.35563
337.474	9.27085
341.048	9.12468
344.622	8.16581
348.192	7.31843
351.764	5.46611
355.332	4.5905
358.901	4.34843
362.466	3.44273
366.03	3.9457
369.594	3.44734
373.155	3.02634
376.715	3.48337
380.273	3.18756
383.832	3.4604
387.388	3.08746
390.942	5.12717
394.495	4.44358
398.047	5.41847
401.597	5.97329
405.145	6.03416
408.693	7.2658
412.239	6.66352
415.783	6.24355
419.327	7.07704
422.869	7.44172
426.409	6.31861
429.948	6.1877
433.486	4.76544
437.022	3.61301
440.558	3.35362
444.089	3.04422
447.622	3.02935
451.153	3.64151
454.682	3.74538
458.208	3.63265
461.735	3.73314
465.259	4.89945
468.783	6.28725
472.306	8.18842
475.825	9.04229
479.346	10.6573
482.862	11.1811
486.38	13.3266
489.894	15.4133
493.407	16.1497
496.92	16.9401
500.43	19.776
503.939	21.3358
507.448	23.5796
510.954	22.7802
514.459	22.7598
517.962	22.3547
521.466	21.4941
524.966	21.4923
528.466	21.906
531.964	21.31
535.46	21.0538
538.955	19.8191
542.449	19.824
545.942	19.4074
549.433	17.4745
552.923	16.1752
556.412	15.8614
559.899	12.5596
563.385	10.9247
566.867	9.25859
570.35	8.46946
573.832	9.89052
577.313	9.37471
580.79	9.21684
584.268	9.32757
587.745	9.83305
591.218	8.66382
594.692	8.06358
598.164	7.34549
601.634	6.1237
605.104	4.96401
608.57	6.53217
612.037	6.95086
615.501	7.16624
618.966	7.69527
622.427	8.20938
625.887	10.2211
629.348	10.67
632.806	9.95432
636.262	11.5351
639.716	11.3612
643.172	12.6202
646.624	13.35
650.075	15.5408
653.524	18.4554
656.972	18.9668
660.419	21.3179
663.865	22.0581
667.309	24.1287
670.752	24.0833
674.194	25.6322
677.634	26.2704
681.073	27.4742
684.511	28.8147
687.947	30.2233
691.382	33.8394
694.816	35.3744
698.247	37.3195
701.678	39.2939
705.108	40.7012
708.534	42.7607
711.962	44.4492
715.388	45.3339
718.81	47.0795
722.234	47.8651
725.654	48.3791
729.075	50.3016
732.492	50.7311
735.91	51.7469
739.325	52.654
742.741	54.0676
746.153	55.8125
749.564	57.0262
752.976	58.542
756.385	60.7808
759.792	62.4684
763.2	65.194
766.604	67.9907
770.008	70.1726
773.41	73.3914
776.811	74.5649
780.21	76.4424
783.608	78.2966
787.005	79.7194
790.401	79.4988
793.795	80.4554
797.188	81.5487
800.58	81.9865
803.971	81.5614
807.36	81.5443
810.748	81.6236
814.135	81.0878
817.518	80.127
820.902	81.1416
824.285	81.3682
827.665	80.141
831.045	79.1814
834.424	77.6148
837.8	75.5729
841.177	74.2049
844.55	71.6436
847.924	70.7306
851.295	70.2496
854.666	68.4494
858.034	65.9743
861.403	63.3934
864.769	62.1313
868.133	61.1735
871.498	61.0516
874.86	60.593
878.221	59.4112
881.58	58.9501
884.938	58.1932
888.297	57.6845
891.653	56.9796
895.007	55.7405
898.36	54.9154
901.712	55.2163
905.063	54.0284
908.412	53.2101
911.76	51.761
915.107	51.4277
918.452	49.0151
921.797	47.7366
925.138	45.7257
928.48	44.4703
931.82	43.4911
935.16	42.6239
938.496	41.3243
941.833	40.413
945.168	39.9461
948.5	40.6119
951.834	40.5141
955.163	39.7405
958.494	38.7892
961.821	38.253
965.15	38.2204
968.474	39.656
971.8	39.3694
975.123	39.1452
978.446	37.8917
981.766	38.411
985.084	38.2725
988.402	38.2517
991.72	38.4724
995.035	37.4606
998.349	35.848
1001.66	32.6177
1004.97	31.2401
1008.28	31.7184
1011.59	32.9805
1014.9	35.3844
1018.21	37.8858
1021.51	39.7969
1024.81	41.3635
1028.12	42.3052
1031.42	44.7024
1034.72	45.6067
1038.02	46.967
1041.31	46.994
1044.61	46.0279
1047.91	45.2553
1051.2	43.3293
1054.49	39.0103
1057.78	37.4426
1061.07	34.959
1064.36	31.8111
1067.65	28.9814
1070.93	26.1065
1074.22	22.6449
1077.5	18.4042
1080.78	15.2793
1084.06	13.6023
1087.34	12.775
1090.62	13.5982
1093.9	13.793
1097.17	14.2765
1100.45	14.8459
1103.72	16.6037
1106.99	16.975
1110.27	17.0228
1113.53	16.985
1116.8	16.2344
1120.07	15.9701
1123.33	15.9319
1126.6	15.356
1129.86	15.1981
1133.12	14.1177
1136.38	15.1701
1139.64	14.0835
1142.9	12.4002
1146.16	12.4607
1149.41	10.9374
1152.67	9.01716
1155.92	7.57533
1159.17	6.77899
1162.42	6.17596
1165.67	5.98068
1168.92	5.00595
1172.16	4.1938
1175.41	2.57507
1178.65	3.56332
1181.9	3.72728
1185.14	3.81519
1188.38	4.49055
1191.62	4.64165
1194.86	6.01469
1198.09	6.18532
1201.33	7.73342
1204.56	9.9382
1207.8	10.1539
1211.03	12.7533
1214.26	14.1963
1217.49	15.1135
1220.71	15.946
1223.94	17.0943
1227.16	19.4722
1230.39	19.8593
1233.61	21.8698
1236.83	23.4519
1240.05	24.4624
1243.27	25.7732
1246.49	27.8635
1249.71	28.8303
1252.92	30.3561
1256.14	31.1631
1259.35	33.2366
1262.56	32.5223
1265.77	33.6867
1268.98	34.3515
1272.19	36.365
1275.4	36.8612
1278.6	37.3963
1281.81	39.8316
1285.01	41.154
1288.21	42.4254
1291.41	44.4983
1294.61	43.9486
1297.81	45.2743
1301.01	46.84
1304.2	49.0873
1307.4	50.0408
1310.59	51.1133
1313.78	51.8077
1316.97	52.9304
1320.16	53.742
1323.35	54.0525
1326.54	53.1163
1329.72	50.6984
1332.91	47.8442
1336.09	45.016
1339.27	44.0558
1342.45	42.3079
1345.64	40.0467
1348.81	38.2988
1351.99	35.4661
1355.17	32.3124
1358.34	31.0363
1361.51	29.7587
1364.69	28.0392
1367.86	26.932
1371.03	25.0694
1374.2	23.7067
1377.37	24.0768
1380.53	25.0409
1383.7	25.2963
1386.86	25.8998
1390.02	25.3164
1393.19	26.1325
1396.35	26.2982
1399.51	26.0861
1402.66	25.1854
1405.82	24.5698
1408.97	24.2032
1412.13	24.6701
1415.28	25.2663
1418.43	26.8206
1421.59	28.2945
1424.73	29.8032
1427.88	31.3393
1431.03	35.1504
1434.18	36.6979
1437.32	40.334
1440.46	41.8333
1443.61	43.0292
1446.75	43.2446
1449.89	44.202
1453.03	44.8347
1456.16	45.1736
1459.3	45.0029
1462.44	45.2491
1465.57	42.6314
1468.7	41.4281
1471.83	39.9401
1474.96	38.1008
1478.09	36.0417
1481.22	33.7134
1484.35	31.1767
1487.47	28.6312
1490.6	26.0808
1493.72	24.6507
1496.84	25.2564
1499.96	22.6151
1503.08	21.4593
1506.2	19.5397
1509.32	18.8269
1512.44	17.6488
1515.55	16.4421
1518.66	15.4618
1521.78	14.6801
1524.89	14.7575
1528	15.361
1531.11	15.0413
1534.21	15.0245
1537.32	15.1601
1540.43	14.682
1543.53	15.7273
1546.63	17.6503
1549.74	18.6927
1552.84	21.0389
1555.94	20.9816
1559.03	21.5293
1562.13	22.6023
1565.23	23.2311
1568.32	23.7124
1571.42	25.0809
1574.51	25.9271
1577.6	27.5996
1580.69	29.8034
1583.78	31.7988
1586.87	33.1828
1589.95	35.3296
1593.04	37.1483
1596.12	38.3372
1599.21	39.8086
1602.29	40.8781
1605.37	42.6366
1608.45	42.512
1611.53	42.3241
1614.6	42.6013
1617.68	44.9859
1620.75	46.6067
1623.83	47.8494
1626.9	48.4586
1629.97	49.0985
1633.04	50.0831
1636.11	52.0711
1639.18	53.3354
1642.25	54.3538
1645.31	57.202
1648.38	59.9192
1651.44	60.7325
1654.5	59.6906
1657.56	59.6532
1660.62	57.8921
1663.68	55.9015
1666.74	54.2417
1669.8	51.2434
1672.85	48.2373
1675.91	45.3798
1678.96	41.9951
1682.01	38.1519
1685.06	34.5708
1688.11	31.63
1691.16	29.0694
1694.21	26.2332
1697.25	23.2094
1700.3	20.7274
1703.34	18.8124
1706.39	17.3279
1709.43	16.3256
1712.47	16.1509
1715.51	15.0285
1718.54	14.1575
1721.58	13.3634
1724.62	11.1265
1727.65	8.16629
1730.68	7.25396
1733.72	6.91555
1736.75	5.84831
1739.78	4.8064
1742.81	4.33814
1745.84	2.94084
1748.86	3.1718
1751.89	3.26144
1754.91	3.10057
1757.93	3.10968
1760.96	4.32347
1763.98	4.27684
1767	3.54277
1770.02	3.71873
1773.03	3.56162
1776.05	3.74353
1779.07	3.02082
1782.08	3.44604
1785.09	3.52697
1788.11	3.57348
1791.12	3.02526
1794.13	2.69087
1797.13	2.33444
1800.14	2.35563
1803.15	2.01686
1806.15	1.63099
1809.16	1.4261
1812.16	1.15241
1815.16	1.64374
1818.16	2.05662
1821.16	2.34999
1824.16	2.8641
1827.16	2.65539
1830.16	3.40494
1833.15	3.83955
1836.14	4.5182
1839.14	3.55428
1842.13	3.24114
1845.12	3.42263
1848.11	3.48039
1851.1	3.46653
1854.08	4.29853
1857.07	4.47797
1860.05	4.93517
1863.04	4.19219
1866.02	3.8838
1869	3.49856
1871.98	3.25399
1874.96	2.93504
1877.94	2.91301
1880.92	3.81908
1882.51	3.9126
1885.5	4.66723
1888.48	5.61463
1891.47	6.06588
1894.46	5.88234
1897.44	5.44466
1900.42	6.62851
1903.41	6.13752
1906.39	5.89346
1909.37	5.48679
1912.35	5.0185
1915.32	4.48208
1918.3	4.25299
1921.27	3.93699
1924.25	3.73487
1927.22	3.94744
1930.19	4.03822
1933.17	3.44094
1936.14	2.85217
1939.11	2.42962
1942.07	2.38515
1945.04	2.06417
1948.01	1.4952
1950.97	1.4685
1953.93	2.14052
1956.9	3.31299
1959.86	2.86996
1962.82	3.2917
1965.78	1.77717
1968.74	2.09248
1971.69	2.57997
1974.65	2.67393
1977.6	2.29092
1980.56	2.08587
1983.51	1.29824
1986.46	1.05632
1989.41	0.561316
1992.36	1.08521
1995.31	0.620179
1998.26	1.15417
2001.2	2.19391
2004.15	2.10035
2007.09	2.80215
2010.04	2.4735
2012.98	3.05567
2015.92	3.95711
2018.86	4.65435
2021.8	5.45646
2024.73	6.59107
2027.67	7.59381
2030.61	7.52008
2033.54	7.5597
2036.47	7.87917
2039.4	7.76183
2042.33	8.41176
2045.27	8.16916
2048.19	7.12258
2051.12	5.97772
2054.05	6.15597
2056.97	5.34256
2059.9	5.31217
2062.82	5.49945
2065.74	5.83095
2068.67	6.174
2071.59	6.77556
2074.51	7.22279
2077.42	7.73351
2080.34	8.76151
2083.26	10.0355
2086.17	11.8472
2089.09	13.1607
2092	13.6113
2094.91	14.1794
2097.82	15.734
2100.73	16.8241
2103.64	18.0618
2106.55	19.4253
2109.45	20.9909
2112.36	23.0245
2115.26	24.5844
2118.17	26.5114
2121.07	27.9591
2123.97	29.2641
2126.87	30.7642
2129.77	33.0749
2132.67	35.2957
2135.56	37.0104
2138.46	39.4274
2141.35	40.8214
2144.25	42.4276
2147.14	44.1152
2150.03	47.2354
2152.92	48.6003
2155.81	51.0087
2158.7	51.7592
2161.59	52.7211
2164.47	54.0812
2167.36	54.3549
2170.24	55.6211
2173.13	56.1011
2176.01	57.3221
2178.89	57.8024
2181.77	58.0285
2184.65	56.6186
2187.53	55.4439
2190.4	54.2316
2193.28	51.5466
2196.16	49.1091
2199.03	47.2915
2201.9	45.4457
2204.77	43.5981
2207.64	41.401
2210.51	39.1737
2213.38	36.6103
2216.25	34.8649
2219.12	32.5851
2221.98	29.517
2224.85	26.9431
2227.71	25.4379
2230.57	22.3338
2233.43	20.038
2236.29	17.6235
2239.15	17.4481
2242.01	16.6036
2244.87	15.3717
2247.72	15.0064
2250.58	14.1271
2253.43	12.7984
2256.29	12.5687
2259.14	11.9302
2261.99	11.6905
2264.84	11.608
2267.69	11.712
2270.53	12.1667
2273.38	12.455
2276.23	11.6937
2279.07	11.6301
2281.91	10.5901
2284.76	10.4346
2287.6	9.49172
2290.44	8.78929
2293.28	7.57648
2296.12	7.59786
2298.96	7.85503
2301.79	8.095
2304.63	8.85892
2307.46	10.0212
2310.3	10.4741
2313.13	11.1734
2315.96	11.5052
2318.79	11.5945
2321.62	10.9355
2324.45	10.9665
2327.27	11.6718
2330.1	10.9034
2332.92	10.5119
2335.75	9.54167
2338.57	8.59002
2341.39	7.30867
2344.21	6.26162
2347.04	5.40123
2349.85	4.83733
2352.67	3.80332
2355.49	2.7518
2358.3	1.43321
2361.12	1.62848
2363.93	1.63876
2366.75	1.97305
2369.56	1.23638
2372.37	1.81086
2375.18	1.57492
2377.99	1.72431
2380.8	2.52823
2383.6	2.31352
2386.41	1.90385
2389.21	2.0321
2392.02	2.62967
2394.82	2.66563
2397.62	2.80048
2400.42	3.53493
2403.22	3.40613
2406.02	3.89794
2408.82	4.40903
2411.62	5.74487
2414.41	5.96613
2417.21	6.63529
2420	7.35632
2422.79	6.72921
2425.59	6.43463
2428.38	6.42718
2431.17	6.69632
2433.95	5.92644
2436.74	5.07785
2439.53	5.16141
2442.31	5.18143
2445.1	3.82783
2447.88	3.91619
2450.67	3.58588
2453.45	3.61252
2456.23	2.57926
2459.01	2.17001
2461.79	1.60804
2464.57	1.93522
2467.34	2.83887
2470.12	2.29189
2472.89	3.27001
2475.67	3.65653
2478.44	3.96766
2481.21	4.42369
2483.98	3.47165
2486.75	3.24048
2489.52	3.35755
2492.29	3.02064
2495.05	2.50847
2497.82	2.82327
2500.58	2.18207
2503.35	1.77673
2506.11	1.17711
2508.87	0.824599
2511.63	1.05658
2514.39	1.1854
2517.15	2.02094
2519.91	1.97251
2522.67	2.06225
2525.42	1.75521
2528.18	1.87032
2530.93	2.71061
2533.69	3.60521
2536.44	3.74207
2539.19	4.1078
2541.94	4.5698
2544.69	4.89474
2547.44	4.25898
2550.18	3.68933
2552.93	4.33246
2555.67	4.72095
2558.42	4.47825
2561.16	3.78188
2563.9	3.0566
2566.64	2.57691
2569.38	2.7233
2572.12	3.27539
2574.86	3.34745
2577.6	4.50305
2580.33	4.27247
2583.07	4.55749
2585.8	4.92815
2588.54	4.82829
2591.27	3.71895
2594	2.66541
2596.73	2.14462
2599.46	2.21976
2602.19	2.33386
2604.92	2.4497
2607.64	2.67223
2610.37	1.54395
2613.09	1.93766
2615.82	1.97546
2618.54	2.88965
2621.26	3.10033
2623.98	3.62068
2626.7	3.53769
2629.42	4.38974
2632.14	4.91185
2634.86	6.52799
2637.57	7.50904
2640.29	7.9337
2643	8.06875
2645.71	7.71111
2648.43	8.12367
2651.14	8.46503
2653.85	7.20294
2656.56	6.29723
2659.26	5.31956
2661.97	5.66218
2664.68	5.17125
2667.38	5.22205
2670.09	5.2305
2672.79	4.94587
2675.49	4.94855
2678.19	4.82355
2680.89	5.46407
2683.59	5.35324
2686.29	6.26857
2688.99	6.35368
2691.69	7.04715
2694.38	7.34248
2697.08	6.82702
2699.77	7.61868
2702.46	8.04452
2705.15	7.73844
2707.85	7.88623
2710.54	7.89455
2713.22	7.98864
2715.91	8.07876
2718.6	7.89771
2721.29	8.42014
2723.97	9.17536
2726.66	8.92841
2729.34	9.20008
2732.02	8.90731
2734.7	8.92784
2737.38	8.93613
2740.06	7.5266
2742.74	6.82246
2745.42	7.08893
2748.09	6.12348
2750.77	6.21799
2753.45	4.88064
2756.12	3.78947
2758.79	2.37462
2761.46	1.20065
2764.14	0.652078
2766.8	0.482915
2769.47	-0.210574
2772.14	-0.379351
2774.81	-0.0498849
2777.48	-0.183111
2780.14	0.411919
2782.8	0.83824
2785.47	1.73691
2788.13	2.38434
2790.79	1.62252
2793.45	1.22851
2796.11	2.23327
2798.77	2.27774
2801.43	2.87588
2804.09	3.22336
2806.74	3.06276
2809.4	2.89307
2812.05	3.11058
2814.71	3.16879
2817.36	3.36969
2820.01	4.14424
2822.66	5.7024
2825.31	7.1739
2827.96	9.1774
2830.6	11.2245
2833.25	13.2468
2835.9	15.6158
2838.54	18.6151
2841.18	22.1274
2843.83	26.5037
2846.47	31.0182
2849.11	36.3367
2851.75	41.1312
2854.39	45.6526
2857.03	51.2798
2859.66	56.4523
2862.3	61.9933
2864.94	66.7678
2867.57	70.5089
2870.2	73.7513
2872.84	76.7344
2875.47	79.4081
2878.1	82.0821
2880.73	85.1461
2883.36	87.5881
2885.99	89.4421
2888.61	92.1636
2891.24	94.4171
2893.86	96.9077
2896.49	100.932
2899.11	104.504
2901.73	109.73
2904.36	115.029
2906.98	121.385
2909.6	127.66
2912.21	133.898
2914.83	140.563
2917.45	146.678
2920.07	152.925
2922.68	157.738
2925.29	161.592
2927.91	164.478
2930.52	166.69
2933.13	166.194
2935.74	165.658
2938.35	163.886
2940.96	161.412
2943.57	158.055
2946.18	153.439
2948.78	147.833
2951.39	142.945
2953.99	137.957
2956.59	132.336
2959.2	126.579
2961.8	119.983
2964.4	114.21
2967	108.075
2969.6	102.486
2972.19	96.585
2974.79	90.2155
2977.39	84.3518
2979.98	78.2026
2982.58	73.1326
2985.17	67.8393
2987.76	61.5155
2990.35	55.6171
2992.94	50.6029
2995.53	44.7114
2998.12	39.4198
3000.71	34.1121
3003.3	29.8571
3005.88	25.8281
3008.47	22.1467
3011.05	18.1972
3013.64	14.9489
3016.22	12.719
3018.8	10.6482
3021.38	9.13215
3023.96	8.40843
3026.54	7.85314
3029.12	7.06802
3031.69	6.96089
3034.27	6.81745
3036.84	6.95872
3039.42	7.22885
3041.99	8.39962
3044.57	9.54403
3047.14	10.6564
3049.71	10.513
3052.28	11.1308
3054.85	11.0884
3057.41	10.4619
3059.98	10.806
3062.55	11.113
3065.11	10.3648
3067.68	10.1548
3070.24	8.88092
3072.8	6.78496
3075.36	6.27389
3077.93	5.39654
3080.49	5.76584
3083.04	5.26705
3085.6	4.54468
3088.16	3.07828
3090.72	1.90437
3093.27	2.55122
3095.83	2.6378
3098.38	2.15368
3100.93	2.45273
3103.49	3.27427
3106.04	4.24506
3108.59	5.56114
3111.14	6.35974
3113.69	6.85349
3116.23	7.70236
3118.78	8.47641
3121.33	9.93368
3123.87	11.0491
3126.41	11.9435
3128.96	11.8199
3131.5	11.6861
3134.04	12.2698
3136.58	13.9817
3139.12	14.4816
3141.66	14.5925
3144.2	14.0088
3146.74	13.8334
3149.27	15.1352