File: data/Raman/poly_smoothed/Mb_30_27_30_1x_45s_532 nm_x100_100%_600 gr_mm_01.txt
#Acq. time (s)=	45
#Accumulations=	2
#Range (cm-¹)=	200...3150
#Windows=	2
#Auto scanning=	Off
#Autofocus=	Off
#Macrospot=	Off
#AutoExposure=	Off
#Spike filter=	Multiple accum.
#Delay time (s)=	0
#Binning=	1
#Readout mode=	Signal
#DeNoise=	Off
#ICS correction=	On
#Dark correction=	Off
#Inst. Process=	Off
#Detector Gain=	Best Dynamic Range
#Detector ADC=	20 kHz
#Detector temperature (°C)=	-69.85
#Instrument=	LabRAM HR Evol
#Detector=	Synapse
#Objective=	x100
#Grating=	600 gr/mm
#ND Filter=	100%
#Laser (nm)=	532
#Hole=	100.021
#Range=	Auto
#Laser Pol.=	No
#Raman. Pol.=	No
#Laser Pol. (°)=	-0.0007625
#Raman Pol. (°)=	89.9995
#Collection=	Microscope
#StageXY=	Marzhauser
#StageZ=	Marzhauser
#X (µm)=	-6378.2
#Y (µm)=	830.1
#Z (µm)=	-64.65
#Full time(mm:ss)=	3:18
#Project=
#Sample=
#Site=
#Title=	Mb_30_27_30_2x_45s_532 nm_x100_100%_600 gr_mm
#Remark=
#Date=	13.07.2022 10:57
#Acquired=	13.07.2022 10:57:36
#Base:Fit=	10.08.2022 10:40:03
#Base:Sub=	10.08.2022 10:40:17
#Filter:Polynom=	16.08.2022 10:16:15
#AxisType[0]=Intens
#AxisUnit[0]=Cnt
#AxisType[1]=Spectr
#AxisUnit[1]=1/cm
200.563	28.9671
204.194	23.512
207.821	18.7922
211.449	16.6369
215.074	14.1746
218.699	11.2102
222.321	10.1798
225.941	9.21181
229.562	8.66395
233.18	9.10153
236.796	8.67562
240.411	9.23728
244.026	8.77864
247.638	9.13464
251.248	10.3189
254.857	12.0578
258.465	13.0917
262.071	13.7638
265.678	13.4665
269.282	14.3879
272.884	12.6768
276.484	10.8613
280.084	12.3397
283.682	12.4732
287.276	14.5857
290.871	14.4105
294.465	15.2261
298.057	15.6132
301.648	13.6316
305.237	12.3571
308.823	13.4868
312.41	15.6395
315.995	15.8123
319.579	15.7904
323.16	16.2436
326.741	16.4018
330.321	17.1122
333.897	17.0388
337.474	16.7407
341.048	16.1139
344.622	15.39
348.192	12.1632
351.764	10.4483
355.332	9.25321
358.901	8.45317
362.466	7.19973
366.03	9.26682
369.594	10.0902
373.155	9.92147
376.715	9.44429
380.273	10.2242
383.832	11.1274
387.388	10.3061
390.942	12.0275
394.495	14.925
398.047	17.5902
401.597	19.3349
405.145	20.0194
408.693	21.5777
412.239	21.4755
415.783	21.8837
419.327	24.4743
422.869	22.9086
426.409	20.141
429.948	18.9501
433.486	17.4965
437.022	16.3561
440.558	15.334
444.089	14.5426
447.622	13.7416
451.153	14.625
454.682	13.309
458.208	11.2985
461.735	10.1627
465.259	12.0104
468.783	13.2481
472.306	12.0483
475.825	12.4828
479.346	14.8318
482.862	14.9433
486.38	15.8404
489.894	17.2842
493.407	16.5738
496.92	16.385
500.43	17.6757
503.939	18.6873
507.448	18.5422
510.954	16.5808
514.459	15.4827
517.962	15.9345
521.466	15.3999
524.966	14.9567
528.466	13.9766
531.964	15.1621
535.46	14.5046
538.955	12.6028
542.449	11.6272
545.942	11.4158
549.433	10.8473
552.923	11.1299
556.412	9.40625
559.899	9.23901
563.385	8.76619
566.867	7.35753
570.35	7.09749
573.832	5.57218
577.313	4.30521
580.79	3.30927
584.268	2.68713
587.745	3.17217
591.218	2.61071
594.692	3.17515
598.164	3.33314
601.634	3.50113
605.104	4.20628
608.57	4.40645
612.037	5.05108
615.501	7.30425
618.966	6.20842
622.427	5.88842
625.887	6.54448
629.348	7.90141
632.806	8.81759
636.262	11.3884
639.716	11.7703
643.172	12.4491
646.624	12.6047
650.075	13.2862
653.524	14.2509
656.972	14.5839
660.419	16.3622
663.865	17.9622
667.309	19.0886
670.752	19.9012
674.194	19.9748
677.634	20.7417
681.073	21.7608
684.511	21.4715
687.947	20.7737
691.382	23.2294
694.816	25.6639
698.247	27.7775
701.678	27.4934
705.108	27.4081
708.534	27.4644
711.962	29.5837
715.388	30.6238
718.81	30.417
722.234	32.4055
725.654	33.5264
729.075	35.0336
732.492	36.1897
735.91	38.063
739.325	40.0489
742.741	41.7241
746.153	44.905
749.564	47.4703
752.976	48.1272
756.385	50.4596
759.792	52.4709
763.2	56.0959
766.604	58.1694
770.008	61.6164
773.41	64.5461
776.811	67.8911
780.21	69.7667
783.608	70.771
787.005	73.1147
790.401	76.3208
793.795	79.6525
797.188	80.3582
800.58	79.6663
803.971	80.3014
807.36	82.0186
810.748	79.8076
814.135	79.4331
817.518	80.4283
820.902	78.3886
824.285	78.5139
827.665	77.8769
831.045	76.9487
834.424	72.7352
837.8	70.5572
841.177	69.4766
844.55	67.2959
847.924	64.201
851.295	60.0178
854.666	58.1079
858.034	54.8114
861.403	54.8927
864.769	53.7647
868.133	53.8215
871.498	51.5137
874.86	49.8265
878.221	48.054
881.58	46.122
884.938	45.9148
888.297	46.2841
891.653	46.3046
895.007	45.4167
898.36	47.2945
901.712	47.2754
905.063	46.7659
908.412	47.4024
911.76	48.4429
915.107	47.485
918.452	48.888
921.797	48.7615
925.138	47.1427
928.48	45.8021
931.82	43.4402
935.16	41.5709
938.496	41.5912
941.833	42.1326
945.168	40.8596
948.5	39.3837
951.834	38.1332
955.163	36.8091
958.494	35.0117
961.821	32.8686
965.15	32.3661
968.474	32.7203
971.8	32.446
975.123	31.3031
978.446	32.5349
981.766	32.5751
985.084	31.191
988.402	31.3033
991.72	30.2595
995.035	28.635
998.349	26.6088
1001.66	25.1359
1004.97	24.3947
1008.28	26.2168
1011.59	27.8952
1014.9	30.5929
1018.21	34.4091
1021.51	38.8151
1024.81	39.3191
1028.12	39.8548
1031.42	42.1217
1034.72	42.8319
1038.02	42.4131
1041.31	41.9496
1044.61	41.2431
1047.91	41.7818
1051.2	42.279
1054.49	40.7183
1057.78	39.0088
1061.07	35.4366
1064.36	31.8144
1067.65	28.5645
1070.93	22.9408
1074.22	20.2975
1077.5	18.1527
1080.78	15.4287
1084.06	13.7019
1087.34	16.1793
1090.62	17.4826
1093.9	18.2929
1097.17	18.6306
1100.45	18.706
1103.72	19.5789
1106.99	19.1166
1110.27	19.2006
1113.53	19.319
1116.8	18.9984
1120.07	19.2605
1123.33	18.8385
1126.6	19.0663
1129.86	19.027
1133.12	18.3524
1136.38	16.5091
1139.64	14.1685
1142.9	13.7975
1146.16	12.0335
1149.41	10.6221
1152.67	8.77585
1155.92	6.69488
1159.17	5.255
1162.42	3.38784
1165.67	2.74884
1168.92	3.758
1172.16	2.17866
1175.41	2.02007
1178.65	2.41522
1181.9	3.03532
1185.14	4.90403
1188.38	5.06291
1191.62	6.83725
1194.86	8.52874
1198.09	9.74286
1201.33	11.8908
1204.56	14.1374
1207.8	16.7364
1211.03	17.8841
1214.26	21.0729
1217.49	23.2948
1220.71	25.674
1223.94	29.0297
1227.16	32.2099
1230.39	36.2832
1233.61	39.0682
1236.83	42.3859
1240.05	45.9756
1243.27	48.9114
1246.49	51.1153
1249.71	53.4401
1252.92	56.3706
1256.14	56.5594
1259.35	58.3566
1262.56	60.9949
1265.77	63.3282
1268.98	64.4978
1272.19	66.1828
1275.4	68.0077
1278.6	67.7941
1281.81	70.5977
1285.01	72.0333
1288.21	73.5691
1291.41	75.1816
1294.61	75.4153
1297.81	75.4547
1301.01	74.979
1304.2	76.9184
1307.4	77.4692
1310.59	78.3841
1313.78	79.3875
1316.97	79.3008
1320.16	78.5521
1323.35	76.8406
1326.54	75.7907
1329.72	74.6441
1332.91	73.6931
1336.09	72.7392
1339.27	71.8601
1342.45	70.1488
1345.64	67.9566
1348.81	66.4631
1351.99	64.7438
1355.17	62.9092
1358.34	61.0024
1361.51	58.9935
1364.69	57.767
1367.86	54.5702
1371.03	51.1363
1374.2	48.58
1377.37	47.1568
1380.53	47.1255
1383.7	46.1237
1386.86	46.117
1390.02	45.6717
1393.19	43.7816
1396.35	43.6756
1399.51	45.3502
1402.66	46.6521
1405.82	47.8141
1408.97	50.1135
1412.13	52.976
1415.28	56.6317
1418.43	59.8471
1421.59	65.0769
1424.73	69.252
1427.88	75.0933
1431.03	79.7904
1434.18	83.5639
1437.32	87.8944
1440.46	89.855
1443.61	93.4558
1446.75	96.5717
1449.89	96.8131
1453.03	95.9943
1456.16	96.7522
1459.3	94.7846
1462.44	92.7355
1465.57	88.7339
1468.7	83.5315
1471.83	80.2259
1474.96	76.3307
1478.09	70.5776
1481.22	65.5742
1484.35	60.7398
1487.47	55.8372
1490.6	52.1399
1493.72	48.6938
1496.84	44.6488
1499.96	41.6792
1503.08	38.3887
1506.2	35.4829
1509.32	32.3319
1512.44	28.9018
1515.55	26.1836
1518.66	25.2481
1521.78	22.8053
1524.89	21.311
1528	18.7394
1531.11	18.8391
1534.21	19.7812
1537.32	18.6119
1540.43	19.9191
1543.53	20.909
1546.63	22.4647
1549.74	24.2894
1552.84	26.0147
1555.94	28.2994
1559.03	29.3426
1562.13	32.1664
1565.23	34.1416
1568.32	37.5494
1571.42	41.4009
1574.51	44.0634
1577.6	47.1762
1580.69	49.4486
1583.78	53.0003
1586.87	55.3792
1589.95	57.3292
1593.04	59.4369
1596.12	60.6558
1599.21	60.7084
1602.29	61.6537
1605.37	60.7723
1608.45	60.9696
1611.53	60.7267
1614.6	60.1587
1617.68	61.2859
1620.75	59.9807
1623.83	60.4583
1626.9	60.8503
1629.97	61.7863
1633.04	62.6191
1636.11	64.5811
1639.18	67.5016
1642.25	68.8893
1645.31	70.8791
1648.38	74.0944
1651.44	75.9031
1654.5	77.6145
1657.56	79.3087
1660.62	80.3861
1663.68	81.489
1666.74	79.0813
1669.8	76.7227
1672.85	73.0071
1675.91	68.1686
1678.96	65.901
1682.01	60.0465
1685.06	54.8408
1688.11	50.3244
1691.16	46.0026
1694.21	41.4803
1697.25	37.6554
1700.3	34.1818
1703.34	31.7935
1706.39	28.1199
1709.43	25.631
1712.47	22.8201
1715.51	20.8599
1718.54	19.434
1721.58	18.7227
1724.62	17.0295
1727.65	16.6594
1730.68	16.8876
1733.72	15.8488
1736.75	14.0605
1739.78	12.6844
1742.81	11.07
1745.84	8.83513
1748.86	7.27228
1751.89	7.04881
1754.91	6.51787
1757.93	5.67323
1760.96	5.13101
1763.98	3.89903
1767	4.29564
1770.02	2.20866
1773.03	2.59451
1776.05	1.71307
1779.07	0.998273
1782.08	0.485096
1785.09	0.293195
1788.11	1.20465
1791.12	0.592812
1794.13	0.746143
1797.13	0.879247
1800.14	1.86364
1803.15	1.89987
1806.15	1.60808
1809.16	0.853156
1812.16	1.23808
1815.16	1.86668
1818.16	1.6241
1821.16	1.73572
1824.16	2.23629
1827.16	2.86848
1830.16	2.91179
1833.15	2.87704
1836.14	3.12513
1839.14	3.21797
1842.13	2.92742
1845.12	1.90532
1848.11	2.07368
1851.1	2.26744
1854.08	2.64178
1857.07	2.34065
1860.05	2.4945
1863.04	2.93778
1866.02	2.72714
1869	2.42913
1871.98	1.52395
1874.96	0.659462
1877.94	-0.27721
1880.92	0.213095
1882.51	0.493091
1885.5	0.33407
1888.48	0.0131719
1891.47	0.42365
1894.46	-0.0944751
1897.44	0.462634
1900.42	0.81048
1903.41	0.453297
1906.39	0.407775
1909.37	0.137616
1912.35	0.989631
1915.32	2.04585
1918.3	2.33668
1921.27	4.23915
1924.25	4.71761
1927.22	4.89267
1930.19	6.09635
1933.17	7.79495
1936.14	9.2073
1939.11	9.88416
1942.07	10.1166
1945.04	10.2808
1948.01	12.1544
1950.97	12.5863
1953.93	13.4054
1956.9	12.4492
1959.86	12.4804
1962.82	12.552
1965.78	11.9462
1968.74	11.5313
1971.69	11.6979
1974.65	11.9417
1977.6	12.1723
1980.56	11.7717
1983.51	11.9699
1986.46	11.9112
1989.41	11.7414
1992.36	12.1306
1995.31	11.6019
1998.26	11.3687
2001.2	11.9772
2004.15	13.2376
2007.09	12.8905
2010.04	13.4681
2012.98	13.5322
2015.92	12.7059
2018.86	12.7393
2021.8	13.015
2024.73	13.4236
2027.67	13.6558
2030.61	15.2038
2033.54	15.4788
2036.47	15.8785
2039.4	14.9641
2042.33	16.3225
2045.27	17.1586
2048.19	16.7733
2051.12	16.635
2054.05	16.3881
2056.97	16.9597
2059.9	17.8668
2062.82	18.8521
2065.74	19.4213
2068.67	20.0268
2071.59	19.9478
2074.51	20.4451
2077.42	22.2714
2080.34	22.6189
2083.26	23.314
2086.17	22.9129
2089.09	25.4938
2092	27.7705
2094.91	30.666
2097.82	32.1098
2100.73	32.8582
2103.64	33.6487
2106.55	34.7921
2109.45	36.7116
2112.36	37.8094
2115.26	39.779
2118.17	40.6186
2121.07	41.9891
2123.97	43.4258
2126.87	46.7054
2129.77	48.9341
2132.67	51.8524
2135.56	55.1698
2138.46	58.7388
2141.35	61.9508
2144.25	65.0367
2147.14	68.3845
2150.03	71.0681
2152.92	73.91
2155.81	79
2158.7	82.2083
2161.59	86.1255
2164.47	88.4203
2167.36	89.4586
2170.24	90.9166
2173.13	91.9324
2176.01	92.4214
2178.89	92.716
2181.77	92.2409
2184.65	89.6933
2187.53	87.6375
2190.4	85.4452
2193.28	83.0241
2196.16	79.1949
2199.03	76.4358
2201.9	72.326
2204.77	69.1381
2207.64	65.9716
2210.51	62.6453
2213.38	59.7129
2216.25	56.1028
2219.12	52.8852
2221.98	50.0033
2224.85	48.152
2227.71	45.8901
2230.57	43.7907
2233.43	42.592
2236.29	39.7802
2239.15	38.152
2242.01	35.9329
2244.87	34.752
2247.72	33.6614
2250.58	32.1171
2253.43	30.2693
2256.29	28.4802
2259.14	27.2436
2261.99	25.6018
2264.84	25.1546
2267.69	24.1655
2270.53	23.3138
2273.38	21.7062
2276.23	21.3449
2279.07	20.7041
2281.91	19.9906
2284.76	18.5347
2287.6	17.7641
2290.44	16.6887
2293.28	16.383
2296.12	16.5577
2298.96	17.2558
2301.79	17.8555
2304.63	17.3896
2307.46	17.5422
2310.3	17.3189
2313.13	17.0715
2315.96	16.7438
2318.79	15.8986
2321.62	15.4427
2324.45	14.9066
2327.27	15.1484
2330.1	15.4562
2332.92	14.4615
2335.75	13.287
2338.57	10.8554
2341.39	9.95724
2344.21	8.60807
2347.04	8.13299
2349.85	7.11833
2352.67	6.3945
2355.49	6.10119
2358.3	4.53735
2361.12	3.96489
2363.93	3.73346
2366.75	4.74362
2369.56	5.36916
2372.37	5.16467
2375.18	5.71691
2377.99	4.28318
2380.8	3.71388
2383.6	4.56375
2386.41	4.4351
2389.21	4.44292
2392.02	4.40208
2394.82	4.85743
2397.62	5.23047
2400.42	4.01335
2403.22	2.87243
2406.02	3.09624
2408.82	2.97645
2411.62	3.45862
2414.41	3.39353
2417.21	3.49947
2420	3.14655
2422.79	2.83284
2425.59	3.12938
2428.38	3.09027
2431.17	4.14746
2433.95	5.91096
2436.74	5.88098
2439.53	5.39032
2442.31	5.8513
2445.1	5.14171
2447.88	5.7367
2450.67	6.96722
2453.45	7.1079
2456.23	7.22141
2459.01	7.7091
2461.79	8.0377
2464.57	8.83095
2467.34	8.44456
2470.12	7.74466
2472.89	8.55972
2475.67	7.5066
2478.44	7.39362
2481.21	6.95837
2483.98	6.97008
2486.75	7.07378
2489.52	6.6914
2492.29	6.22776
2495.05	5.2215
2497.82	4.27623
2500.58	3.57434
2503.35	2.18325
2506.11	1.52654
2508.87	1.96567
2511.63	0.761351
2514.39	-0.414404
2517.15	-0.543337
2519.91	-0.192874
2522.67	0.271136
2525.42	1.11853
2528.18	1.94924
2530.93	2.41078
2533.69	2.34295
2536.44	2.72207
2539.19	3.50203
2541.94	4.24034
2544.69	4.75564
2547.44	5.7692
2550.18	5.79682
2552.93	6.05514
2555.67	5.86906
2558.42	4.94563
2561.16	4.88266
2563.9	4.97055
2566.64	4.72415
2569.38	4.35087
2572.12	5.33273
2574.86	5.02939
2577.6	3.93659
2580.33	3.09991
2583.07	2.90808
2585.8	4.12206
2588.54	3.66986
2591.27	4.18132
2594	3.81195
2596.73	3.40899
2599.46	2.43232
2602.19	2.30259
2604.92	2.52839
2607.64	1.7334
2610.37	0.708432
2613.09	-0.190852
2615.82	0.150409
2618.54	0.0784712
2621.26	0.0669342
2623.98	-0.428188
2626.7	-0.319995
2629.42	0.290251
2632.14	0.430504
2634.86	0.997669
2637.57	2.08441
2640.29	3.62809
2643	3.74843
2645.71	4.42818
2648.43	4.41009
2651.14	5.87405
2653.85	5.89979
2656.56	5.87193
2659.26	5.64686
2661.97	5.12673
2664.68	4.71924
2667.38	4.29413
2670.09	4.13025
2672.79	4.20748
2675.49	3.96098
2678.19	3.89629
2680.89	4.71546
2683.59	4.92907
2686.29	4.89014
2688.99	4.64344
2691.69	4.73683
2694.38	5.40016
2697.08	6.09044
2699.77	6.46292
2702.46	7.61125
2705.15	8.36711
2707.85	8.32729
2710.54	7.98524
2713.22	8.82623
2715.91	9.42064
2718.6	8.58636
2721.29	9.14891
2723.97	8.12534
2726.66	8.31304
2729.34	8.5263
2732.02	8.9917
2734.7	8.78475
2737.38	8.80779
2740.06	9.56317
2742.74	9.49115
2745.42	9.48559
2748.09	9.19024
2750.77	9.30779
2753.45	9.21975
2756.12	8.26211
2758.79	7.52266
2761.46	6.4715
2764.14	4.87475
2766.8	4.43224
2769.47	3.90746
2772.14	3.26837
2774.81	2.49343
2777.48	2.65647
2780.14	2.00951
2782.8	2.31818
2785.47	2.30037
2788.13	1.81436
2790.79	1.42722
2793.45	1.41137
2796.11	1.86594
2798.77	2.61279
2801.43	3.0976
2804.09	4.09094
2806.74	5.11306
2809.4	4.92686
2812.05	5.5051
2814.71	6.1015
2817.36	6.37245
2820.01	7.94364
2822.66	9.12845
2825.31	10.119
2827.96	12.3276
2830.6	14.9756
2833.25	18.2855
2835.9	22.0585
2838.54	26.5154
2841.18	31.0509
2843.83	36.1769
2846.47	42.2145
2849.11	49.4364
2851.75	55.7491
2854.39	63.1051
2857.03	70.7132
2859.66	78.755
2862.3	87.2444
2864.94	93.8183
2867.57	100.71
2870.2	106.459
2872.84	111.565
2875.47	116.49
2878.1	122.208
2880.73	127.093
2883.36	132.618
2885.99	137.51
2888.61	142.387
2891.24	146.743
2893.86	152.379
2896.49	157.755
2899.11	165.059
2901.73	173.059
2904.36	180.002
2906.98	189.547
2909.6	200.885
2912.21	212.555
2914.83	223.493
2917.45	234.262
2920.07	243.042
2922.68	252.031
2925.29	258.174
2927.91	264.362
2930.52	265.813
2933.13	267.066
2935.74	265.766
2938.35	263.917
2940.96	261.349
2943.57	255.74
2946.18	248.668
2948.78	240.544
2951.39	231.755
2953.99	221.152
2956.59	210.825
2959.2	200.056
2961.8	190.331
2964.4	180.123
2967	168.994
2969.6	159.869
2972.19	152.396
2974.79	144.189
2977.39	135.631
2979.98	127.119
2982.58	118.513
2985.17	110.345
2987.76	102.493
2990.35	93.166
2992.94	85.16
2995.53	76.8788
2998.12	70.1143
3000.71	64.6861
3003.3	57.9071
3005.88	52.0778
3008.47	46.2167
3011.05	40.5201
3013.64	35.7783
3016.22	31.5997
3018.8	27.4877
3021.38	24.3587
3023.96	20.8595
3026.54	17.3835
3029.12	15.7972
3031.69	14.6284
3034.27	13.4991
3036.84	12.5135
3039.42	11.8803
3041.99	11.6526
3044.57	11.8038
3047.14	12.8702
3049.71	13.3078
3052.28	13.5561
3054.85	13.296
3057.41	14.1091
3059.98	14.574
3062.55	14.5611
3065.11	13.9364
3067.68	12.6179
3070.24	11.7738
3072.8	10.8272
3075.36	10.5882
3077.93	9.22397
3080.49	8.01029
3083.04	6.3484
3085.6	4.76764
3088.16	3.72651
3090.72	2.71122
3093.27	1.75338
3095.83	0.631966
3098.38	-0.642963
3100.93	-0.815369
3103.49	-1.10626
3106.04	-0.494091
3108.59	0.125303
3111.14	0.420891
3113.69	0.825676
3116.23	0.658072
3118.78	0.231503
3121.33	0.980634
3123.87	0.435958
3126.41	0.475413
3128.96	0.566958
3131.5	-0.12815
3134.04	0.950884
3136.58	1.73471
3139.12	1.82164
3141.66	1.95122
3144.2	2.01138
3146.74	2.1703
3149.27	1.96047