File: data/Raman/poly_smoothed/Mb_30_27_45_1x_45s_532 nm_x100_100%_600 gr_mm_01.txt
#Acq. time (s)=	45
#Accumulations=	2
#Range (cm-¹)=	200...3150
#Windows=	2
#Auto scanning=	Off
#Autofocus=	Off
#Macrospot=	Off
#AutoExposure=	Off
#Spike filter=	Multiple accum.
#Delay time (s)=	0
#Binning=	1
#Readout mode=	Signal
#DeNoise=	Off
#ICS correction=	On
#Dark correction=	Off
#Inst. Process=	Off
#Detector Gain=	Best Dynamic Range
#Detector ADC=	20 kHz
#Detector temperature (°C)=	-69.85
#Instrument=	LabRAM HR Evol
#Detector=	Synapse
#Objective=	x100
#Grating=	600 gr/mm
#ND Filter=	100%
#Laser (nm)=	532
#Hole=	100.021
#Range=	Auto
#Laser Pol.=	No
#Raman. Pol.=	No
#Laser Pol. (°)=	-0.0007625
#Raman Pol. (°)=	89.9995
#Collection=	Microscope
#StageXY=	Marzhauser
#StageZ=	Marzhauser
#X (µm)=	-6402.9
#Y (µm)=	781.5
#Z (µm)=	-64.6
#Full time(mm:ss)=	3:18
#Project=
#Sample=
#Site=
#Title=	Mb_30_27_45_2x_45s_532 nm_x100_100%_600 gr_mm
#Remark=
#Date=	13.07.2022 12:09
#Acquired=	13.07.2022 12:09:19
#Base:Fit=	10.08.2022 10:40:03
#Base:Sub=	10.08.2022 10:40:17
#Filter:Polynom=	16.08.2022 10:16:15
#AxisType[0]=Intens
#AxisUnit[0]=Cnt
#AxisType[1]=Spectr
#AxisUnit[1]=1/cm
200.563	-7.98069
204.194	-0.275832
207.821	3.62049
211.449	6.39901
215.074	7.57429
218.699	2.85102
222.321	2.54582
225.941	6.83434
229.562	10.0201
233.18	12.9746
236.796	14.431
240.411	17.5173
244.026	18.9342
247.638	20.3453
251.248	20.5683
254.857	21.0848
258.465	21.6078
262.071	21.1006
265.678	20.0143
269.282	18.5613
272.884	15.6346
276.484	15.3124
280.084	15.9221
283.682	14.6238
287.276	12.7183
290.871	11.226
294.465	10.4368
298.057	8.11872
301.648	7.24753
305.237	4.69216
308.823	7.97568
312.41	12.228
315.995	13.2348
319.579	13.5525
323.16	15.4149
326.741	17.6809
330.321	18.5509
333.897	18.8485
337.474	19.5386
341.048	18.8248
344.622	18.6991
348.192	19.0042
351.764	17.1627
355.332	15.2698
358.901	13.9517
362.466	14.386
366.03	14.7853
369.594	15.0974
373.155	15.1504
376.715	16.4917
380.273	17.9976
383.832	19.2202
387.388	19.7602
390.942	21.22
394.495	21.5982
398.047	21.1787
401.597	19.7139
405.145	19.0798
408.693	19.2783
412.239	19.6529
415.783	19.1662
419.327	18.0099
422.869	17.3389
426.409	16.1916
429.948	15.8399
433.486	16.3577
437.022	14.1333
440.558	12.5354
444.089	10.6875
447.622	11.164
451.153	11.3701
454.682	11.1506
458.208	12.5735
461.735	14.8064
465.259	17.5272
468.783	21.0616
472.306	22.5275
475.825	23.107
479.346	23.9823
482.862	24.0479
486.38	26.4095
489.894	27.287
493.407	28.4889
496.92	30.3624
500.43	32.2135
503.939	33.2155
507.448	33.7969
510.954	35.0127
514.459	35.2901
517.962	35.6012
521.466	34.2263
524.966	32.5279
528.466	31.5302
531.964	30.4454
535.46	29.7584
538.955	29.2781
542.449	29.2192
545.942	29.7679
549.433	28.8025
552.923	26.5012
556.412	23.8845
559.899	21.0495
563.385	17.5076
566.867	16.3808
570.35	15.7595
573.832	14.197
577.313	12.9155
580.79	10.4783
584.268	9.71235
587.745	9.12386
591.218	6.79648
594.692	4.39138
598.164	4.65927
601.634	4.91681
605.104	5.51961
608.57	5.82019
612.037	7.89369
615.501	7.15531
618.966	7.45024
622.427	10.0236
625.887	10.301
629.348	11.2079
632.806	11.4674
636.262	13.1351
639.716	14.415
643.172	15.5774
646.624	16.1209
650.075	17.382
653.524	18.8109
656.972	19.8601
660.419	21.559
663.865	22.8294
667.309	22.4336
670.752	23.2747
674.194	23.2994
677.634	23.7564
681.073	25.8785
684.511	28.2615
687.947	30.0282
691.382	31.3908
694.816	32.8317
698.247	34.9049
701.678	36.8634
705.108	37.5392
708.534	38.9671
711.962	41.6123
715.388	43.5399
718.81	46.0846
722.234	46.7754
725.654	46.187
729.075	45.8087
732.492	46.0968
735.91	47.6067
739.325	47.8734
742.741	49.3973
746.153	50.6145
749.564	51.7252
752.976	52.7091
756.385	55.179
759.792	56.1241
763.2	57.9909
766.604	60.8413
770.008	63.5458
773.41	67.2298
776.811	69.1716
780.21	71.8615
783.608	74.5635
787.005	76.4958
790.401	79.4772
793.795	81.2714
797.188	81.9686
800.58	82.6086
803.971	82.8922
807.36	81.5721
810.748	81.7465
814.135	82.3692
817.518	82.7641
820.902	82.6572
824.285	82.5338
827.665	80.8864
831.045	79.2949
834.424	76.6718
837.8	75.3451
841.177	72.3242
844.55	70.9337
847.924	68.4814
851.295	67.2824
854.666	65.8724
858.034	62.6379
861.403	59.568
864.769	57.8675
868.133	56.4813
871.498	54.5147
874.86	52.168
878.221	50.6372
881.58	49.1792
884.938	49.6554
888.297	47.9896
891.653	46.9989
895.007	47.2184
898.36	47.2686
901.712	47.8378
905.063	48.1193
908.412	47.7292
911.76	47.3937
915.107	47.9495
918.452	47.6814
921.797	49.9765
925.138	50.0329
928.48	49.0219
931.82	49.7514
935.16	49.0467
938.496	48.5408
941.833	48.2269
945.168	48.4898
948.5	47.5734
951.834	47.9487
955.163	47.6591
958.494	46.6298
961.821	46.0336
965.15	46.5645
968.474	47.8989
971.8	48.4835
975.123	49.5527
978.446	50.6093
981.766	50.3615
985.084	52.0829
988.402	52.7922
991.72	51.3333
995.035	49.8097
998.349	49.0203
1001.66	48.0551
1004.97	46.4902
1008.28	45.8281
1011.59	47.7047
1014.9	49.5937
1018.21	49.8652
1021.51	50.5848
1024.81	50.8732
1028.12	51.0703
1031.42	51.0728
1034.72	50.4645
1038.02	49.8845
1041.31	47.644
1044.61	48.0587
1047.91	47.4049
1051.2	45.7981
1054.49	42.8184
1057.78	40.1345
1061.07	37.4719
1064.36	34.1515
1067.65	30.9721
1070.93	28.0681
1074.22	23.4608
1077.5	21.0467
1080.78	19.5423
1084.06	17.878
1087.34	18.8867
1090.62	19.7318
1093.9	20.0331
1097.17	19.3886
1100.45	20.737
1103.72	20.7582
1106.99	19.0107
1110.27	20.0293
1113.53	19.8067
1116.8	19.8385
1120.07	18.6672
1123.33	17.2562
1126.6	17.1281
1129.86	15.8746
1133.12	14.5317
1136.38	12.8835
1139.64	11.7267
1142.9	10.7825
1146.16	9.2662
1149.41	7.39499
1152.67	7.18561
1155.92	5.72506
1159.17	3.55142
1162.42	2.53068
1165.67	0.716852
1168.92	1.07407
1172.16	0.614402
1175.41	1.30378
1178.65	1.90054
1181.9	2.57779
1185.14	2.89018
1188.38	3.34288
1191.62	5.27415
1194.86	8.5655
1198.09	9.6941
1201.33	12.5742
1204.56	16.3623
1207.8	19.8376
1211.03	23.1149
1214.26	25.9242
1217.49	29.6657
1220.71	34.4732
1223.94	38.5984
1227.16	41.3903
1230.39	45.5195
1233.61	48.5542
1236.83	49.7314
1240.05	53.4777
1243.27	56.6385
1246.49	59.5657
1249.71	62.2311
1252.92	63.499
1256.14	63.3696
1259.35	63.8318
1262.56	62.8701
1265.77	64.1607
1268.98	64.3817
1272.19	66.3387
1275.4	67.2518
1278.6	68.6629
1281.81	69.4898
1285.01	71.342
1288.21	72.8365
1291.41	71.9107
1294.61	74.4152
1297.81	75.9206
1301.01	76.4087
1304.2	76.945
1307.4	76.2133
1310.59	76.8252
1313.78	78.6912
1316.97	79.7668
1320.16	80.4875
1323.35	79.5928
1326.54	78.6063
1329.72	78.7565
1332.91	76.2799
1336.09	74.2394
1339.27	72.695
1342.45	70.4343
1345.64	68.005
1348.81	65.1013
1351.99	62.3317
1355.17	59.9008
1358.34	57.0048
1361.51	54.941
1364.69	51.2437
1367.86	46.8853
1371.03	43.852
1374.2	41.4758
1377.37	37.836
1380.53	35.0558
1383.7	32.8936
1386.86	31.3912
1390.02	31.8778
1393.19	32.6062
1396.35	31.7086
1399.51	29.8188
1402.66	29.1117
1405.82	29.891
1408.97	30.7646
1412.13	33.0145
1415.28	36.1389
1418.43	38.8855
1421.59	42.6318
1424.73	46.8938
1427.88	51.1982
1431.03	56.7973
1434.18	61.5061
1437.32	65.5967
1440.46	68.4808
1443.61	70.0746
1446.75	70.909
1449.89	71.2033
1453.03	70.0778
1456.16	67.9153
1459.3	67.2043
1462.44	65.4862
1465.57	63.8631
1468.7	62.1844
1471.83	57.6977
1474.96	54.037
1478.09	49.9903
1481.22	45.3741
1484.35	43.2135
1487.47	40.2645
1490.6	36.2735
1493.72	33.7268
1496.84	32.5065
1499.96	32.0158
1503.08	31.3395
1506.2	30.6964
1509.32	30.2134
1512.44	28.4653
1515.55	26.7374
1518.66	25.5738
1521.78	23.847
1524.89	23.3224
1528	21.879
1531.11	21.9545
1534.21	22.3191
1537.32	22.2723
1540.43	23.4382
1543.53	24.8013
1546.63	25.5103
1549.74	27.0711
1552.84	28.7123
1555.94	29.5504
1559.03	30.7439
1562.13	32.1577
1565.23	33.6296
1568.32	35.0975
1571.42	39.0797
1574.51	42.1333
1577.6	45.1525
1580.69	47.7245
1583.78	50.1003
1586.87	53.2277
1589.95	55.5128
1593.04	58.114
1596.12	60.0349
1599.21	61.5961
1602.29	61.5507
1605.37	61.5963
1608.45	60.924
1611.53	59.684
1614.6	60.9682
1617.68	61.7131
1620.75	63.3551
1623.83	66.2155
1626.9	70.1844
1629.97	73.1485
1633.04	76.7853
1636.11	80.9181
1639.18	85.1622
1642.25	89.7024
1645.31	95.0256
1648.38	100.169
1651.44	103.589
1654.5	105.639
1657.56	106.622
1660.62	107.333
1663.68	105.313
1666.74	103.586
1669.8	99.6038
1672.85	94.5239
1675.91	87.8688
1678.96	80.3642
1682.01	71.9501
1685.06	64.2163
1688.11	56.4672
1691.16	49.4218
1694.21	43.8633
1697.25	38.1981
1700.3	33.6085
1703.34	29.9998
1706.39	25.4323
1709.43	19.5069
1712.47	18.2958
1715.51	18.2635
1718.54	19.286
1721.58	19.311
1724.62	19.1043
1727.65	17.6155
1730.68	16.6753
1733.72	16.6782
1736.75	16.671
1739.78	16.2945
1742.81	15.6216
1745.84	14.6792
1748.86	14.3122
1751.89	12.8981
1754.91	11.282
1757.93	10.5343
1760.96	9.22327
1763.98	7.9754
1767	6.60938
1770.02	5.21422
1773.03	3.99141
1776.05	3.12314
1779.07	2.11422
1782.08	0.246073
1785.09	2.11423
1788.11	4.17412
1791.12	4.2067
1794.13	4.3806
1797.13	2.52829
1800.14	1.97317
1803.15	2.0989
1806.15	2.56141
1809.16	1.56594
1812.16	1.0984
1815.16	1.30009
1818.16	1.11397
1821.16	1.15111
1824.16	0.70808
1827.16	0.726951
1830.16	1.05996
1833.15	0.458638
1836.14	1.04653
1839.14	1.22616
1842.13	1.82614
1845.12	1.88622
1848.11	2.3326
1851.1	2.53821
1854.08	2.41229
1857.07	1.52676
1860.05	1.45033
1863.04	1.73498
1866.02	1.13484
1869	1.29316
1871.98	1.57111
1874.96	2.20368
1877.94	2.66813
1880.92	2.21045
1882.51	3.22783
1885.5	3.64513
1888.48	3.26829
1891.47	3.5782
1894.46	4.58345
1897.44	5.57641
1900.42	5.7624
1903.41	5.68073
1906.39	5.91042
1909.37	5.83288
1912.35	6.48818
1915.32	6.28109
1918.3	5.79725
1921.27	5.56256
1924.25	4.90457
1927.22	5.34572
1930.19	5.61905
1933.17	4.94375
1936.14	3.71528
1939.11	3.56029
1942.07	4.69865
1945.04	4.89826
1948.01	5.24353
1950.97	5.25091
1953.93	4.54405
1956.9	3.94575
1959.86	3.10112
1962.82	3.02315
1965.78	3.40438
1968.74	3.19863
1971.69	2.7762
1974.65	2.80607
1977.6	2.65092
1980.56	2.28617
1983.51	2.54404
1986.46	3.19016
1989.41	2.43526
1992.36	3.23475
1995.31	3.94776
1998.26	5.4345
2001.2	5.95003
2004.15	5.72366
2007.09	4.73302
2010.04	6.37969
2012.98	7.87967
2015.92	7.70142
2018.86	8.13725
2021.8	8.06155
2024.73	7.72436
2027.67	6.80155
2030.61	6.84373
2033.54	7.53976
2036.47	7.27307
2039.4	7.55839
2042.33	7.66059
2045.27	8.10214
2048.19	7.94135
2051.12	7.68419
2054.05	7.95819
2056.97	9.69683
2059.9	9.69105
2062.82	11.7882
2065.74	12.35
2068.67	12.8725
2071.59	13.5962
2074.51	14.9412
2077.42	15.6783
2080.34	16.8075
2083.26	17.8886
2086.17	19.2249
2089.09	20.2154
2092	21.6463
2094.91	22.7406
2097.82	23.8235
2100.73	24.7083
2103.64	25.971
2106.55	27.4356
2109.45	28.8345
2112.36	30.8973
2115.26	33.7734
2118.17	35.2644
2121.07	37.3921
2123.97	40.858
2126.87	44.6843
2129.77	48.6834
2132.67	51.8485
2135.56	55.5199
2138.46	59.6327
2141.35	63.6374
2144.25	69.1391
2147.14	73.824
2150.03	78.8102
2152.92	83.0232
2155.81	87.3646
2158.7	91.5894
2161.59	95.3674
2164.47	97.8635
2167.36	100.422
2170.24	102.737
2173.13	104.255
2176.01	104.858
2178.89	104.581
2181.77	103.206
2184.65	101.176
2187.53	97.9054
2190.4	94.5056
2193.28	89.9007
2196.16	86.4208
2199.03	81.5348
2201.9	76.2551
2204.77	72.237
2207.64	67.9366
2210.51	64.2095
2213.38	60.1796
2216.25	56.8699
2219.12	53.2192
2221.98	48.4616
2224.85	45.9622
2227.71	43.6243
2230.57	41.2122
2233.43	39.4567
2236.29	37.9817
2239.15	35.8974
2242.01	34.424
2244.87	32.3641
2247.72	30.9395
2250.58	29.0693
2253.43	27.8117
2256.29	26.3389
2259.14	24.7126
2261.99	22.7892
2264.84	21.1821
2267.69	20.2046
2270.53	18.7041
2273.38	18.6468
2276.23	17.8642
2279.07	16.4956
2281.91	15.7611
2284.76	15.1217
2287.6	14.204
2290.44	13.3031
2293.28	11.1168
2296.12	11.8782
2298.96	11.8205
2301.79	11.4002
2304.63	11.0339
2307.46	10.6885
2310.3	10.3295
2313.13	10.3414
2315.96	11.2503
2318.79	12.3117
2321.62	11.3819
2324.45	10.8658
2327.27	10.517
2330.1	10.9818
2332.92	10.2965
2335.75	10.2113
2338.57	9.27554
2341.39	8.58533
2344.21	8.21596
2347.04	7.54348
2349.85	6.81965
2352.67	5.9317
2355.49	4.46745
2358.3	4.07895
2361.12	3.06901
2363.93	3.66061
2366.75	3.52308
2369.56	2.83405
2372.37	1.60807
2375.18	1.3388
2377.99	0.886074
2380.8	0.0810108
2383.6	0.686921
2386.41	0.884079
2389.21	-0.285673
2392.02	-0.158795
2394.82	0.501335
2397.62	0.634067
2400.42	2.1313
2403.22	2.27174
2406.02	3.16009
2408.82	3.52075
2411.62	4.56185
2414.41	4.87506
2417.21	6.30601
2420	6.56298
2422.79	6.38519
2425.59	8.27443
2428.38	7.97069
2431.17	9.03665
2433.95	9.37733
2436.74	9.55143
2439.53	8.2566
2442.31	8.34172
2445.1	8.21512
2447.88	7.41955
2450.67	6.73646
2453.45	6.48101
2456.23	5.53957
2459.01	5.27112
2461.79	4.77067
2464.57	5.13254
2467.34	4.71076
2470.12	4.86836
2472.89	4.5722
2475.67	4.46014
2478.44	5.47903
2481.21	5.1345
2483.98	4.49321
2486.75	4.47903
2489.52	3.25001
2492.29	2.77403
2495.05	3.32363
2497.82	2.63212
2500.58	2.64863
2503.35	1.85118
2506.11	1.97002
2508.87	1.27424
2511.63	0.3538
2514.39	1.01693
2517.15	0.984125
2519.91	1.89223
2522.67	1.76549
2525.42	1.75285
2528.18	2.72277
2530.93	2.79595
2533.69	3.30045
2536.44	3.55416
2539.19	3.48742
2541.94	4.58979
2544.69	5.33897
2547.44	5.44101
2550.18	4.48128
2552.93	3.56826
2555.67	3.63129
2558.42	3.10308
2561.16	3.97275
2563.9	4.02663
2566.64	3.03606
2569.38	3.55371
2572.12	3.43506
2574.86	2.84531
2577.6	1.82026
2580.33	2.23355
2583.07	2.41439
2585.8	2.88408
2588.54	2.56086
2591.27	3.14578
2594	2.96573
2596.73	2.63966
2599.46	2.3721
2602.19	1.92346
2604.92	1.84019
2607.64	1.88343
2610.37	2.69201
2613.09	1.59872
2615.82	1.20097
2618.54	0.865782
2621.26	1.51653
2623.98	0.971712
2626.7	0.746363
2629.42	1.03021
2632.14	0.449918
2634.86	1.09645
2637.57	0.880405
2640.29	0.771384
2643	0.656372
2645.71	0.397323
2648.43	1.85467
2651.14	2.59124
2653.85	4.25895
2656.56	4.47211
2659.26	4.99947
2661.97	5.09343
2664.68	5.39056
2667.38	5.35451
2670.09	6.15068
2672.79	6.09852
2675.49	5.55227
2678.19	5.52637
2680.89	4.91491
2683.59	5.19257
2686.29	5.59429
2688.99	4.21327
2691.69	3.96034
2694.38	4.30045
2697.08	4.64451
2699.77	4.27256
2702.46	5.20351
2705.15	5.22698
2707.85	5.60576
2710.54	5.77659
2713.22	6.58144
2715.91	7.28576
2718.6	7.11831
2721.29	7.02423
2723.97	5.90845
2726.66	6.00221
2729.34	5.58542
2732.02	5.0479
2734.7	5.31123
2737.38	5.97453
2740.06	5.68172
2742.74	5.88599
2745.42	5.94115
2748.09	6.28187
2750.77	5.57343
2753.45	4.93988
2756.12	4.75296
2758.79	4.47521
2761.46	3.97367
2764.14	3.47687
2766.8	3.86248
2769.47	3.16134
2772.14	3.26361
2774.81	2.55195
2777.48	2.46561
2780.14	2.04763
2782.8	1.60787
2785.47	0.447965
2788.13	-0.25394
2790.79	-0.266598
2793.45	-0.0729426
2796.11	-0.131396
2798.77	0.484215
2801.43	0.482587
2804.09	0.240236
2806.74	0.892074
2809.4	1.14474
2812.05	1.41366
2814.71	0.865652
2817.36	1.55246
2820.01	2.78627
2822.66	4.07349
2825.31	5.58984
2827.96	7.8931
2830.6	11.1231
2833.25	13.3579
2835.9	16.502
2838.54	20.4248
2841.18	25.4191
2843.83	31.5736
2846.47	37.4696
2849.11	44.238
2851.75	52.4977
2854.39	60.7068
2857.03	69.3325
2859.66	76.9383
2862.3	84.1873
2864.94	90.7873
2867.57	97.213
2870.2	103.494
2872.84	110.064
2875.47	114.995
2878.1	120.278
2880.73	125.25
2883.36	130.034
2885.99	135.63
2888.61	140.937
2891.24	146.764
2893.86	153.801
2896.49	160.746
2899.11	169.826
2901.73	179.576
2904.36	191.25
2906.98	204.932
2909.6	219.093
2912.21	233.574
2914.83	248.695
2917.45	263.313
2920.07	276.998
2922.68	288.276
2925.29	296.963
2927.91	303.086
2930.52	307.621
2933.13	309.918
2935.74	309.887
2938.35	307.716
2940.96	302.043
2943.57	293.151
2946.18	283.79
2948.78	273.391
2951.39	262.077
2953.99	249.532
2956.59	237.08
2959.2	224.992
2961.8	212.652
2964.4	200.804
2967	189.203
2969.6	178.074
2972.19	167.76
2974.79	157.629
2977.39	147.655
2979.98	137.676
2982.58	128.257
2985.17	117.556
2987.76	107.118
2990.35	97.2526
2992.94	88.1545
2995.53	79.1455
2998.12	71.2767
3000.71	62.6921
3003.3	54.0529
3005.88	45.6322
3008.47	39.4255
3011.05	34.1975
3013.64	29.2323
3016.22	24.8926
3018.8	22.0773
3021.38	20.6135
3023.96	18.6704
3026.54	16.5841
3029.12	15.7266
3031.69	15.4392
3034.27	15.6965
3036.84	15.9229
3039.42	16.259
3041.99	17.3584
3044.57	18.3964
3047.14	18.9607
3049.71	19.4225
3052.28	20.4027
3054.85	21.1112
3057.41	21.8847
3059.98	21.3683
3062.55	19.5488
3065.11	18.0198
3067.68	16.3491
3070.24	15.2036
3072.8	13.6216
3075.36	12.168
3077.93	10.6573
3080.49	9.44769
3083.04	8.44049
3085.6	6.90474
3088.16	5.11907
3090.72	4.39955
3093.27	3.74326
3095.83	3.32979
3098.38	2.84532
3100.93	3.46622
3103.49	4.04659
3106.04	4.72634
3108.59	4.64086
3111.14	5.31303
3113.69	5.69104
3116.23	6.22191
3118.78	5.72211
3121.33	5.24325
3123.87	4.23661
3126.41	4.11687
3128.96	4.62353
3131.5	5.1928
3134.04	5.59382
3136.58	5.49804
3139.12	5.25686
3141.66	4.95422
3144.2	3.72649
3146.74	2.61589
3149.27	2.75138