File: data/Raman/poly_smoothed/Mb_30_27_06_1x_45s_532 nm_x100_100%_600 gr_mm_01.txt
#Acq. time (s)=	45
#Accumulations=	2
#Range (cm-¹)=	200...3150
#Windows=	2
#Auto scanning=	Off
#Autofocus=	Off
#Macrospot=	Off
#AutoExposure=	Off
#Spike filter=	Multiple accum.
#Delay time (s)=	0
#Binning=	1
#Readout mode=	Signal
#DeNoise=	Off
#ICS correction=	On
#Dark correction=	Off
#Inst. Process=	Off
#Detector Gain=	Best Dynamic Range
#Detector ADC=	20 kHz
#Detector temperature (°C)=	-69.85
#Instrument=	LabRAM HR Evol
#Detector=	Synapse
#Objective=	x100
#Grating=	600 gr/mm
#ND Filter=	100%
#Laser (nm)=	532
#Hole=	100.021
#Range=	Auto
#Laser Pol.=	No
#Raman. Pol.=	No
#Laser Pol. (°)=	-0.0007625
#Raman Pol. (°)=	89.9995
#Collection=	Microscope
#StageXY=	Marzhauser
#StageZ=	Marzhauser
#X (µm)=	28066.3
#Y (µm)=	-545.2
#Z (µm)=	1083.85
#Full time(mm:ss)=	3:08
#Project=
#Sample=
#Site=
#Title=	Mb_30_27_06_2x_45s_532 nm_x100_100%_600 gr_mm
#Remark=
#Date=	12.07.2022 15:52
#Acquired=	12.07.2022 15:52:47
#Base:Fit=	10.08.2022 10:39:47
#Base:Sub=	10.08.2022 10:39:55
#Base:Fit=	10.08.2022 10:40:03
#Base:Sub=	10.08.2022 10:40:17
#Filter:Polynom=	16.08.2022 10:16:15
#AxisType[0]=Intens
#AxisUnit[0]=Cnt
#AxisType[1]=Spectr
#AxisUnit[1]=1/cm
200.388	28.7365
204.019	29.1512
207.646	25.397
211.274	22.6616
214.899	20.3473
218.524	16.7314
222.146	16.5667
225.766	14.7773
229.388	13.1723
233.005	12.7823
236.621	10.8979
240.236	9.18444
243.852	7.50005
247.464	6.17846
251.074	6.00938
254.683	4.68423
258.291	4.25923
261.897	4.482
265.504	4.61282
269.108	4.97242
272.71	4.69031
276.311	6.90454
279.91	6.8443
283.508	8.01262
287.105	7.16588
290.698	7.05017
294.291	7.94117
297.884	10.1922
301.475	10.2216
305.064	9.40745
308.652	10.7483
312.237	12.4172
315.822	12.1669
319.406	13.3869
322.987	12.6179
326.568	10.8173
330.148	12.1942
333.724	13.4756
337.301	14.3471
340.875	12.9933
344.449	12.605
348.02	12.0179
351.592	11.8327
355.16	10.6441
358.728	10.755
362.294	9.76692
365.858	10.5107
369.422	10.2608
372.983	10.4344
376.543	11.3163
380.102	12.4296
383.661	11.7048
387.216	12.6451
390.771	12.9037
394.324	12.4868
397.875	14.4904
401.425	14.3996
404.974	13.8817
408.524	14.2959
412.07	15.2599
415.614	17.6818
419.156	18.936
422.698	20.5271
426.238	19.8602
429.777	18.1602
433.315	16.6766
436.852	16.3205
440.387	17.3082
443.919	16.0398
447.451	16.4858
450.982	17.9346
454.512	20.827
458.038	20.463
461.565	22.1459
465.091	23.425
468.613	23.2907
472.136	24.0185
475.655	25.0529
479.176	24.5205
482.692	27.1199
486.21	28.9296
489.724	32.0864
493.237	33.446
496.75	37.8266
500.26	39.0074
503.771	41.0383
507.279	42.0541
510.785	42.6922
514.289	41.6022
517.793	39.4663
521.297	40.8723
524.797	41.8943
528.297	40.0478
531.795	38.5288
535.291	38.725
538.787	38.7341
542.281	34.8725
545.773	29.1067
549.264	28.0029
552.754	25.7213
556.243	22.3687
559.73	19.2789
563.216	17.3398
566.701	16.0243
570.182	15.4877
573.664	15.5265
577.145	12.6655
580.624	10.5089
584.1	10.1143
587.577	9.09152
591.052	7.51389
594.524	6.63885
597.997	4.70499
601.466	3.77473
604.936	4.40059
608.403	6.2597
611.87	8.40896
615.334	6.94505
618.799	9.17984
622.26	10.7241
625.72	10.8489
629.181	13.4633
632.638	15.7476
636.095	18.8047
639.551	18.3836
643.005	17.6897
646.457	17.8263
649.908	18.6423
653.357	18.0807
656.806	16.4455
660.253	16.0393
663.7	14.5481
667.145	13.9563
670.588	13.8675
674.027	13.2661
677.468	13.1247
680.907	13.0288
684.345	14.7285
687.781	16.8451
691.216	21.6834
694.65	24.0298
698.081	25.3914
701.512	28.0398
704.942	32.5383
708.371	35.8338
711.796	40.6691
715.222	44.9549
718.645	47.0714
722.068	49.0058
725.49	50.1753
728.909	49.9858
732.329	51.4161
735.745	49.9987
739.16	50.3502
742.576	51.3532
745.988	52.9413
749.401	54.0696
752.811	57.0219
756.22	59.2823
759.627	59.9158
763.035	62.7898
766.44	64.3549
769.843	65.2363
773.245	65.1907
776.646	65.8696
780.046	66.63
783.444	69.1162
786.841	72.178
790.237	74.9579
793.631	75.9623
797.024	76.6336
800.416	77.6162
803.807	77.9577
807.196	78.3414
810.584	78.3717
813.971	79.3689
817.354	81.3501
820.739	80.7929
824.122	83.1064
827.503	83.7333
830.882	82.0064
834.261	81.4538
837.637	80.7828
841.013	80.9083
844.389	77.2768
847.761	74.1786
851.131	71.5972
854.503	67.4848
857.871	66.2359
861.24	63.0557
864.606	60.5165
867.97	57.3972
871.336	56.7087
874.698	53.8531
878.058	51.0818
881.418	50.2867
884.778	49.0277
888.135	46.9569
891.49	46.5344
894.845	47.2866
898.198	46.7544
901.55	45.54
904.901	44.5518
908.25	44.1977
911.598	43.9372
914.945	43.1442
918.291	44.0304
921.635	44.9574
924.978	43.7399
928.318	42.4093
931.659	41.5756
934.998	41.9664
938.336	40.2702
941.671	37.9329
945.007	36.5018
948.339	37.218
951.672	37.5044
955.004	36.9816
958.333	35.6178
961.662	34.0336
964.989	32.886
968.315	33.3593
971.639	34.2244
974.962	35.0132
978.285	34.5569
981.605	35.714
984.924	39.3421
988.243	40.1486
991.56	39.6947
994.875	38.2339
998.188	37.6019
1001.5	35.4529
1004.81	35.9725
1008.12	40.849
1011.43	50.5607
1014.74	63.0283
1018.05	74.1394
1021.35	83.2832
1024.65	92.2546
1027.96	99.4673
1031.26	104.214
1034.56	106.535
1037.86	107.289
1041.16	108.457
1044.45	108.802
1047.75	107.525
1051.04	105.03
1054.33	99.1885
1057.62	90.9801
1060.91	84.4416
1064.2	75.2393
1067.49	62.748
1070.77	51.585
1074.06	41.5467
1077.34	31.9475
1080.62	26.0672
1083.91	23.6899
1087.18	26.2638
1090.46	30.2723
1093.74	33.8476
1097.02	36.669
1100.29	37.8498
1103.56	39.3263
1106.84	40.7008
1110.11	39.6281
1113.38	39.974
1116.64	39.9751
1119.91	39.6724
1123.18	39.0648
1126.44	37.3953
1129.7	35.5538
1132.97	33.6823
1136.23	29.8442
1139.49	26.4536
1142.74	22.5683
1146	19.7187
1149.26	17.9811
1152.51	15.0544
1155.76	11.419
1159.01	7.6238
1162.27	6.19921
1165.51	3.17622
1168.76	1.62268
1172.01	1.87971
1175.25	4.76992
1178.5	5.38393
1181.74	5.82308
1184.98	7.56587
1188.22	8.57232
1191.46	10.7944
1194.7	14.4102
1197.94	17.0777
1201.17	18.8922
1204.41	22.1876
1207.64	27.5147
1210.87	32.7943
1214.1	38.8313
1217.33	43.8517
1220.56	49.3247
1223.79	53.6957
1227.01	57.6971
1230.23	62.3193
1233.46	67.5677
1236.68	74.7022
1239.9	79.0004
1243.12	82.9018
1246.34	86.5299
1249.55	89.531
1252.77	91.406
1255.98	94.0629
1259.2	96.8482
1262.41	98.7515
1265.62	101.86
1268.83	102.182
1272.03	104.233
1275.24	107.147
1278.45	108.576
1281.65	109.943
1284.85	112.54
1288.06	115.144
1291.26	117.406
1294.46	120.296
1297.66	120.628
1300.85	122.042
1304.05	123.698
1307.24	127.328
1310.43	130.764
1313.63	133.62
1316.82	134.271
1320.01	132.65
1323.2	132.801
1326.38	132.203
1329.57	130.116
1332.76	129.668
1335.94	128.157
1339.12	125.194
1342.3	122.22
1345.48	118.571
1348.66	115.185
1351.84	111.21
1355.01	106.771
1358.19	100.349
1361.36	94.1203
1364.53	88.2206
1367.71	82.2896
1370.88	77.064
1374.04	71.7214
1377.21	68.1769
1380.38	66.9435
1383.54	64.0325
1386.71	62.8552
1389.87	61.3352
1393.03	59.3875
1396.19	57.7428
1399.35	57.9331
1402.51	57.1748
1405.67	57.3712
1408.82	58.2657
1411.98	60.5417
1415.13	63.7652
1418.28	69.6047
1421.43	75.1119
1424.58	82.1393
1427.73	90.9285
1430.88	99.8801
1434.02	106.986
1437.17	114.625
1440.31	119.467
1443.45	122.398
1446.6	125.791
1449.74	129.18
1452.87	131.374
1456.01	132.604
1459.15	130.292
1462.28	128.386
1465.42	125.133
1468.55	121.068
1471.68	116.148
1474.81	111.522
1477.94	107.631
1481.07	100.981
1484.2	94.6523
1487.32	89.7378
1490.45	84.8201
1493.57	80.5601
1496.69	74.6166
1499.81	69.9126
1502.93	66.3949
1506.05	61.3545
1509.17	57.9054
1512.28	51.1926
1515.4	45.4732
1518.51	40.8137
1521.63	36.4386
1524.74	34.2194
1527.85	31.7188
1530.96	30.3665
1534.06	28.6002
1537.17	29.6012
1540.28	30.6116
1543.38	31.7369
1546.48	33.7403
1549.59	37.1648
1552.69	40.5267
1555.79	44.5161
1558.88	47.603
1561.98	51.4483
1565.08	54.6764
1568.17	58.8092
1571.27	62.8763
1574.36	65.9204
1577.45	69.0338
1580.54	72.7062
1583.63	77.4913
1586.72	80.096
1589.8	82.3875
1592.89	84.6363
1595.97	88.2165
1599.06	89.2568
1602.14	91.4941
1605.22	90.943
1608.3	90.7337
1611.38	91.3355
1614.46	90.9724
1617.53	92.3011
1620.61	92.6084
1623.68	96.7366
1626.75	100.004
1629.82	105.225
1632.9	109.69
1635.96	115.564
1639.03	121.299
1642.1	127.259
1645.16	132.629
1648.23	134.896
1651.29	137.85
1654.36	139.949
1657.42	141.316
1660.48	140.103
1663.53	136.44
1666.59	133.247
1669.65	127.316
1672.7	120.014
1675.76	112.106
1678.81	102.601
1681.86	93.3329
1684.91	83.84
1687.96	74.877
1691.01	67.2607
1694.06	57.3916
1697.11	50.3944
1700.15	44.9282
1703.2	39.5969
1706.24	35.9094
1709.28	31.5251
1712.32	28.4067
1715.36	24.9162
1718.4	21.9002
1721.43	18.4815
1724.47	16.7044
1727.5	15.4087
1730.54	14.0682
1733.57	11.8083
1736.6	10.9361
1739.63	8.97623
1742.66	8.64038
1745.69	7.18853
1748.72	6.05153
1751.74	5.27024
1754.77	4.43094
1757.79	4.18926
1760.81	2.58418
1763.83	2.20993
1766.85	0.44764
1769.87	0.916132
1772.89	0.477377
1775.91	0.400347
1778.92	1.30754
1781.94	1.70811
1784.95	1.96525
1787.96	1.98467
1790.97	2.90287
1793.98	2.83338
1796.99	2.07608
1800	1.53928
1803	1.58807
1806.01	0.973365
1809.01	0.921236
1812.02	1.24283
1815.02	0.31609
1818.02	-0.0203086
1821.02	-0.424816
1824.02	-1.18008
1827.01	-0.519994
1830.01	0.246953
1833	0.0210325
1836	-0.502729
1838.99	0.0568415
1841.98	0.611574
1844.97	1.40658
1847.96	1.48848
1850.95	2.10527
1853.94	2.52968
1856.92	2.49712
1859.91	2.48826
1862.89	2.95925
1865.88	3.23064
1868.86	1.93812
1871.84	2.41086
1874.82	3.30318
1877.8	4.06818
1880.77	4.68573
1882.51	4.90837
1885.5	5.16756
1888.48	5.16777
1891.47	5.43982
1894.46	6.23294
1897.44	6.85305
1900.42	7.41584
1903.41	7.16862
1906.39	7.08415
1909.37	6.38312
1912.35	6.18701
1915.32	5.82798
1918.3	4.89736
1921.28	3.47521
1924.25	4.24031
1927.22	3.28487
1930.2	3.37473
1933.17	3.2572
1936.14	2.94948
1939.11	3.35557
1942.08	3.87454
1945.04	4.80584
1948.01	5.56614
1950.97	4.96986
1953.94	5.2206
1956.9	5.06304
1959.86	5.00739
1962.82	5.40967
1965.78	5.80294
1968.74	5.92674
1971.69	5.67848
1974.65	5.55101
1977.61	6.0795
1980.56	6.48325
1983.51	6.34797
1986.46	7.02742
1989.41	7.96108
1992.36	7.90249
1995.31	8.72209
1998.26	8.35591
2001.2	7.62907
2004.15	8.49858
2007.09	8.6046
2010.04	10.0385
2012.98	11.336
2015.92	11.3768
2018.86	12.1253
2021.8	11.9475
2024.74	13.1142
2027.67	13.2925
2030.61	12.3272
2033.54	13.1599
2036.47	13.3887
2039.41	13.3602
2042.34	12.4489
2045.27	13.4006
2048.2	14.2119
2051.12	15.3888
2054.05	15.7861
2056.98	16.1911
2059.9	16.699
2062.82	17.1446
2065.75	18.063
2068.67	19.928
2071.59	20.5496
2074.51	22.8714
2077.43	25.1896
2080.34	27.9142
2083.26	30.8941
2086.17	33.7529
2089.09	36.63
2092	38.3162
2094.91	41.8672
2097.82	43.7286
2100.73	46.8426
2103.64	49.8949
2106.55	52.848
2109.46	54.6226
2112.36	57.7702
2115.27	60.8089
2118.17	65.7879
2121.07	69.5948
2123.97	74.3346
2126.87	79.1936
2129.77	84.1596
2132.67	90.699
2135.57	95.9505
2138.46	101.804
2141.36	108.357
2144.25	114.078
2147.14	120.351
2150.03	125.891
2152.92	131.438
2155.81	137.515
2158.7	142.235
2161.59	145.376
2164.48	149.6
2167.36	152.819
2170.25	155.251
2173.13	156.752
2176.01	155.744
2178.89	154.484
2181.77	151.738
2184.65	149.27
2187.53	145.295
2190.41	142.562
2193.28	137.289
2196.16	132.586
2199.03	126
2201.9	121.006
2204.78	114.272
2207.65	108.122
2210.51	102.156
2213.38	95.5267
2216.25	87.8721
2219.12	81.7491
2221.98	76.9962
2224.85	71.7067
2227.71	67.0712
2230.57	62.6186
2233.43	57.5549
2236.29	53.5853
2239.15	49.4069
2242.01	46.8833
2244.87	42.5109
2247.73	39.041
2250.58	35.9485
2253.43	33.3442
2256.29	31.8381
2259.14	30.9365
2261.99	30.5915
2264.84	29.4062
2267.69	27.8879
2270.54	26.8179
2273.38	26.8575
2276.23	25.1995
2279.07	23.2603
2281.92	21.3753
2284.76	20.0743
2287.6	19.4032
2290.44	16.9302
2293.28	15.5359
2296.12	14.0553
2298.96	14.061
2301.79	12.0947
2304.63	11.1254
2307.46	10.2565
2310.3	10.1399
2313.13	9.01026
2315.96	9.46945
2318.79	8.94434
2321.62	8.55728
2324.45	9.07747
2327.27	10.6003
2330.1	10.311
2332.93	10.0363
2335.75	9.58167
2338.57	8.94984
2341.4	8.00357
2344.22	7.2357
2347.04	5.78721
2349.86	5.40953
2352.67	4.2615
2355.49	3.03593
2358.31	1.76036
2361.12	1.2437
2363.94	0.916399
2366.75	1.68274
2369.56	1.07224
2372.37	2.39121
2375.18	2.91344
2377.99	3.32296
2380.8	3.13733
2383.61	3.71567
2386.41	3.31402
2389.22	3.32855
2392.02	4.03889
2394.82	3.31659
2397.63	3.12388
2400.43	2.99746
2403.23	3.32659
2406.02	3.71792
2408.82	3.91656
2411.62	4.28875
2414.41	4.85146
2417.21	4.70376
2420	4.5026
2422.79	3.76048
2425.59	4.50615
2428.38	4.75146
2431.17	5.51442
2433.96	4.6385
2436.74	4.30427
2439.53	4.18424
2442.32	5.23542
2445.1	4.11824
2447.88	2.7303
2450.67	3.2786
2453.45	3.98656
2456.23	3.61715
2459.01	3.68875
2461.79	3.10402
2464.57	3.60513
2467.34	4.37653
2470.12	5.05796
2472.89	5.51081
2475.67	6.60836
2478.44	6.41086
2481.21	6.33209
2483.98	6.12207
2486.75	5.44842
2489.52	5.07234
2492.29	5.12104
2495.06	5.60125
2497.82	5.95877
2500.59	5.6784
2503.35	4.2055
2506.11	3.58018
2508.88	4.09436
2511.63	3.61801
2514.39	4.18468
2517.15	5.49126
2519.91	6.22218
2522.67	5.61469
2525.42	5.3503
2528.18	5.57109
2530.93	6.31656
2533.69	6.66853
2536.44	6.54936
2539.19	6.0763
2541.94	5.78045
2544.69	4.99131
2547.44	5.0602
2550.18	5.72388
2552.93	6.31297
2555.68	7.32507
2558.42	7.28826
2561.16	7.47231
2563.9	8.27874
2566.64	7.36212
2569.38	6.32026
2572.12	6.02379
2574.86	4.47453
2577.6	4.48248
2580.34	4.7699
2583.07	4.03297
2585.81	4.37251
2588.54	4.79537
2591.27	4.7628
2594	4.26344
2596.73	5.12225
2599.46	4.04978
2602.19	3.44901
2604.92	2.85504
2607.64	2.725
2610.37	3.06131
2613.09	3.31613
2615.82	3.37029
2618.54	3.69302
2621.26	3.62093
2623.98	4.5819
2626.7	4.41163
2629.42	4.29404
2632.14	3.59708
2634.86	3.50346
2637.57	3.38461
2640.29	3.14381
2643	3.41928
2645.72	4.41056
2648.43	5.44825
2651.14	5.76495
2653.85	7.12091
2656.56	7.75915
2659.27	8.18292
2661.97	8.17723
2664.68	9.02248
2667.38	9.00572
2670.09	10.183
2672.79	10.0849
2675.49	9.25645
2678.2	9.5534
2680.89	8.95095
2683.59	9.38051
2686.29	9.38155
2688.99	9.79566
2691.69	10.3292
2694.38	9.08944
2697.08	9.12157
2699.77	8.3294
2702.46	9.32619
2705.16	9.64102
2707.85	9.74985
2710.54	10.0631
2713.23	10.7516
2715.92	11.1233
2718.6	11.5131
2721.29	12.3582
2723.97	12.2303
2726.66	11.638
2729.34	12.262
2732.02	12.0281
2734.7	11.6911
2737.39	10.1333
2740.06	8.84116
2742.74	7.79643
2745.42	7.2436
2748.1	6.55745
2750.77	5.60069
2753.45	4.70824
2756.12	4.46348
2758.79	3.57375
2761.47	2.91059
2764.14	2.47784
2766.81	2.88495
2769.48	2.97836
2772.14	2.7438
2774.81	2.7144
2777.48	1.17153
2780.14	1.51391
2782.81	1.30458
2785.47	1.46528
2788.13	1.04152
2790.79	1.29965
2793.46	1.39279
2796.11	0.63763
2798.77	-0.24257
2801.43	-1.93178
2804.09	-2.21048
2806.74	-1.85346
2809.4	-2.89096
2812.05	-2.11663
2814.71	-1.23407
2817.36	0.459346
2820.01	4.30483
2822.66	8.02643
2825.31	12.4293
2827.96	17.898
2830.61	23.2237
2833.25	31.2333
2835.9	38.7893
2838.54	47.4739
2841.18	57.4304
2843.83	68.9794
2846.47	81.5214
2849.11	95.1123
2851.75	108.708
2854.39	121.956
2857.03	134.751
2859.67	147.161
2862.3	157.738
2864.94	167.894
2867.57	178.304
2870.21	189.142
2872.84	196.611
2875.47	203.93
2878.1	211.361
2880.73	219.154
2883.36	226.617
2885.99	233.275
2888.61	239.487
2891.24	247.471
2893.87	257.558
2896.49	269.883
2899.11	283.245
2901.74	297.345
2904.36	314.848
2906.98	334.19
2909.6	355.564
2912.22	376.396
2914.83	396.627
2917.45	415.487
2920.07	433.434
2922.68	446.964
2925.3	459.039
2927.91	467.505
2930.52	471.294
2933.13	472.35
2935.74	470.561
2938.35	463.852
2940.96	454.623
2943.57	442.515
2946.18	427.93
2948.78	410.531
2951.39	391.126
2953.99	372.223
2956.6	355.118
2959.2	336.288
2961.8	317.009
2964.4	298.319
2967	280.618
2969.6	264.775
2972.2	249.522
2974.79	232.83
2977.39	217.388
2979.98	200.662
2982.58	185.579
2985.17	170.974
2987.76	155.593
2990.36	140.62
2992.95	126.043
2995.54	111.598
2998.12	99.5451
3000.71	87.7633
3003.3	76.6955
3005.88	66.247
3008.47	57.0678
3011.05	47.3909
3013.64	39.7508
3016.22	32.4954
3018.8	27.7559
3021.38	23.2543
3023.96	18.7194
3026.54	16.7942
3029.12	14.1107
3031.69	12.9371
3034.27	12.1652
3036.85	12.8688
3039.42	12.9916
3041.99	13.5462
3044.57	14.8242
3047.14	16.5026
3049.71	16.6251
3052.28	16.967
3054.85	16.7042
3057.42	16.7025
3059.98	17.2028
3062.55	17.1728
3065.11	16.1075
3067.68	14.6935
3070.24	12.3595
3072.8	10.35
3075.37	8.96934
3077.93	7.03814
3080.49	5.40736
3083.05	4.05736
3085.61	2.79212
3088.16	2.7811
3090.72	1.58083
3093.27	0.549995
3095.83	0.19773
3098.38	0.442162
3100.94	0.971932
3103.49	0.907585
3106.04	1.54174
3108.59	1.57818
3111.14	2.09131
3113.69	2.43612
3116.23	3.16724
3118.78	4.02618
3121.33	5.47193
3123.87	6.59755
3126.42	7.24882
3128.96	7.54783
3131.5	8.32743
3134.04	9.54636
3136.58	12.0945
3139.12	13.8491
3141.66	15.5402
3144.2	17.0896
3146.74	17.8924
3149.27	17.8936