File: data/Raman/poly_smoothed/Mb_30_27_07_1x_45s_532 nm_x100_100%_600 gr_mm_01.txt
#Acq. time (s)=	45
#Accumulations=	2
#Range (cm-¹)=	200...3150
#Windows=	2
#Auto scanning=	Off
#Autofocus=	Off
#Macrospot=	Off
#AutoExposure=	Off
#Spike filter=	Multiple accum.
#Delay time (s)=	0
#Binning=	1
#Readout mode=	Signal
#DeNoise=	Off
#ICS correction=	On
#Dark correction=	Off
#Inst. Process=	Off
#Detector Gain=	Best Dynamic Range
#Detector ADC=	20 kHz
#Detector temperature (°C)=	-69.85
#Instrument=	LabRAM HR Evol
#Detector=	Synapse
#Objective=	x100
#Grating=	600 gr/mm
#ND Filter=	100%
#Laser (nm)=	532
#Hole=	100.021
#Range=	Auto
#Laser Pol.=	No
#Raman. Pol.=	No
#Laser Pol. (°)=	-0.0007625
#Raman Pol. (°)=	89.9995
#Collection=	Microscope
#StageXY=	Marzhauser
#StageZ=	Marzhauser
#X (µm)=	28066.1
#Y (µm)=	-536.8
#Z (µm)=	1083.55
#Full time(mm:ss)=	3:20
#Project=
#Sample=
#Site=
#Title=	Mb_30_27_07_2x_45s_532 nm_x100_100%_600 gr_mm
#Remark=
#Date=	12.07.2022 15:56
#Acquired=	12.07.2022 15:56:33
#Base:Fit=	10.08.2022 10:39:47
#Base:Sub=	10.08.2022 10:39:55
#Base:Fit=	10.08.2022 10:40:03
#Base:Sub=	10.08.2022 10:40:17
#Filter:Polynom=	16.08.2022 10:16:15
#AxisType[0]=Intens
#AxisUnit[0]=Cnt
#AxisType[1]=Spectr
#AxisUnit[1]=1/cm
200.388	18.695
204.019	17.8217
207.646	17.0093
211.274	15.4111
214.899	12.6801
218.524	11.9161
222.146	11.2562
225.766	9.55806
229.388	8.39554
233.005	8.27801
236.621	5.54182
240.236	5.55614
243.852	4.92949
247.464	3.94772
251.074	2.88749
254.683	2.20385
258.291	2.48385
261.897	2.49098
265.504	5.40887
269.108	5.12589
272.71	5.17824
276.311	5.51566
279.91	4.93112
283.508	6.00705
287.105	6.05522
290.698	7.59837
294.291	10.0265
297.884	10.4522
301.475	10.6503
305.064	13.0041
308.652	15.0842
312.237	13.5621
315.822	16.0789
319.406	14.8537
322.987	15.6565
326.568	15.8572
330.148	15.7248
333.724	16.6642
337.301	16.5115
340.875	18.6419
344.449	19.1755
348.02	18.0975
351.592	17.3457
355.16	15.8565
358.728	14.058
362.294	14.5399
365.858	15.9616
369.422	17.3545
372.983	18.2269
376.543	20.3761
380.102	21.4229
383.661	22.202
387.216	25.0499
390.771	25.455
394.324	25.673
397.875	23.9004
401.425	23.0414
404.974	24.128
408.524	23.4544
412.07	21.6273
415.614	19.6321
419.156	17.4293
422.698	16.3758
426.238	15.1734
429.777	12.9322
433.315	9.19909
436.852	6.50863
440.387	5.12528
443.919	5.50363
447.451	6.29536
450.982	7.02359
454.512	7.75907
458.038	9.27363
461.565	12.3718
465.091	14.2303
468.613	17.1138
472.136	21.4907
475.655	25.3024
479.176	27.5069
482.692	29.7518
486.21	33.0336
489.724	37.5947
493.237	38.2084
496.75	38.9416
500.26	40.0525
503.771	41.1271
507.279	41.9804
510.785	41.9003
514.289	40.7175
517.793	39.6893
521.297	37.6829
524.797	37.9451
528.297	35.551
531.795	31.6877
535.291	29.7036
538.787	28.4127
542.281	27.0503
545.773	23.1329
549.264	20.5114
552.754	20.7489
556.243	18.3088
559.73	15.7131
563.216	13.5665
566.701	11.1225
570.182	11.0601
573.664	8.97442
577.145	6.97441
580.624	5.40469
584.1	5.89637
587.577	5.79073
591.052	4.65928
594.524	4.0851
597.997	4.47416
601.466	3.92027
604.936	3.67343
608.403	5.2905
611.87	5.34099
615.334	5.10485
618.799	7.22791
622.26	9.00817
625.72	11.0666
629.181	11.8221
632.638	12.2783
636.095	12.7144
639.551	13.0116
643.005	11.4586
646.457	11.7149
649.908	11.9238
653.357	11.5394
656.806	12.1115
660.253	10.3704
663.7	10.2013
667.145	10.1259
670.588	9.78283
674.027	9.37254
677.468	9.96583
680.907	10.1366
684.345	10.4618
687.781	11.006
691.216	13.4502
694.65	15.4215
698.081	16.7436
701.512	18.4597
704.942	20.9262
708.371	23.0752
711.796	27.2869
715.222	28.5064
718.645	30.18
722.068	31.8797
725.49	34.0557
728.909	36.6166
732.329	37.8049
735.745	36.5901
739.16	36.7913
742.576	36.1744
745.988	37.7112
749.401	40.0121
752.811	42.6865
756.22	43.6817
759.627	47.0155
763.035	51.8596
766.44	53.8168
769.843	56.8118
773.245	59.475
776.646	62.0423
780.046	64.6837
783.444	67.052
786.841	69.915
790.237	73.3628
793.631	77.351
797.024	78.9489
800.416	80.8513
803.807	80.9135
807.196	80.8994
810.584	80.4775
813.971	79.4072
817.354	78.2689
820.739	75.4876
824.122	74.2998
827.503	73.6966
830.882	72.3789
834.261	71.004
837.637	69.3341
841.013	69.6534
844.389	69.4219
847.761	67.1345
851.131	63.4822
854.503	63.0233
857.871	61.5515
861.24	61.1428
864.606	60.6048
867.97	59.3483
871.336	59.3365
874.698	59.6681
878.058	58.7989
881.418	59.2913
884.778	57.5529
888.135	57.5685
891.49	56.8261
894.845	56.2266
898.198	55.5247
901.55	54.0797
904.901	53.5049
908.25	53.866
911.598	53.5379
914.945	52.4205
918.291	51.9073
921.635	51.4239
924.978	49.693
928.318	47.2897
931.659	43.2156
934.998	44.6521
938.336	44.2684
941.671	41.8743
945.007	39.0291
948.339	37.5288
951.672	37.7141
955.004	39.2146
958.333	37.4447
961.662	37.8989
964.989	39.6391
968.315	41.5089
971.639	45.2487
974.962	46.3595
978.285	47.9411
981.605	49.8442
984.924	51.6869
988.243	54.8729
991.56	55.7785
994.875	55.3286
998.188	53.0531
1001.5	51.674
1004.81	51.9718
1008.12	54.5799
1011.43	60.8302
1014.74	68.5339
1018.05	74.8788
1021.35	79.1866
1024.65	83.006
1027.96	86.5936
1031.26	92.3822
1034.56	91.8297
1037.86	92.0013
1041.16	92.8576
1044.45	93.1912
1047.75	92.0364
1051.04	89.3948
1054.33	84.6904
1057.62	78.6222
1060.91	72.2127
1064.2	65.6641
1067.49	58.3622
1070.77	51.2795
1074.06	41.3383
1077.34	33.7559
1080.62	29.2556
1083.91	27.2411
1087.18	27.0734
1090.46	30.0136
1093.74	31.0434
1097.02	31.7236
1100.29	32.1101
1103.56	32.2566
1106.84	32.7599
1110.11	33.6221
1113.38	33.6351
1116.64	32.2843
1119.91	31.7147
1123.18	28.4727
1126.44	25.3981
1129.7	24.2997
1132.97	22.2747
1136.23	20.3163
1139.49	19.667
1142.74	18.2877
1146	17.2211
1149.26	14.9636
1152.51	14.0561
1155.76	11.9664
1159.01	11.5347
1162.27	8.8642
1165.51	6.40651
1168.76	6.92566
1172.01	7.81982
1175.25	7.78905
1178.5	9.00934
1181.74	10.4378
1184.98	11.8947
1188.22	14.4838
1191.46	16.6455
1194.7	17.5208
1197.94	20.6793
1201.17	24.5882
1204.41	28.8563
1207.64	33.1169
1210.87	39.5134
1214.1	45.118
1217.33	51.9724
1220.56	57.6597
1223.79	62.3888
1227.01	68.2358
1230.23	73.809
1233.46	78.7925
1236.68	83.1032
1239.9	86.597
1243.12	89.7788
1246.34	93.6026
1249.55	96.8556
1252.77	99.9285
1255.98	100.633
1259.2	102.809
1262.41	103.797
1265.62	105.057
1268.83	106.665
1272.03	108.903
1275.24	111.731
1278.45	112.603
1281.65	114.421
1284.85	115.776
1288.06	118.601
1291.26	120.515
1294.46	121.664
1297.66	121.932
1300.85	122.62
1304.05	122.651
1307.24	124.346
1310.43	124.53
1313.63	125.928
1316.82	126.264
1320.01	124.375
1323.2	124.385
1326.38	121.593
1329.57	118.645
1332.76	113.96
1335.94	109.934
1339.12	105.995
1342.3	100.099
1345.48	95.4935
1348.66	90.0168
1351.84	85.3354
1355.01	81.1533
1358.19	76.3836
1361.36	71.2881
1364.53	67.2858
1367.71	62.3983
1370.88	57.6182
1374.04	54.6225
1377.21	50.9673
1380.38	49.0302
1383.54	47.9501
1386.71	47.0712
1389.87	46.5157
1393.03	46.0868
1396.19	45.5464
1399.35	44.1804
1402.51	44.1448
1405.67	44.9468
1408.82	47.8915
1411.98	51.6433
1415.13	57.3071
1418.28	62.65
1421.43	69.9471
1424.58	76.9992
1427.73	84.9018
1430.88	95.7885
1434.02	104.096
1437.17	111.705
1440.31	117.23
1443.45	123.21
1446.6	127.125
1449.74	129.384
1452.87	129.706
1456.01	127.731
1459.15	125.102
1462.28	118.59
1465.42	112.949
1468.55	105.333
1471.68	98.3511
1474.81	90.5216
1477.94	81.3411
1481.07	73.4552
1484.2	65.2929
1487.32	57.6223
1490.45	51.4514
1493.57	44.7969
1496.69	39.9217
1499.81	37.1326
1502.93	34.6212
1506.05	33.6552
1509.17	32.6278
1512.28	31.0612
1515.4	28.935
1518.51	28.9387
1521.63	28.335
1524.74	26.6151
1527.85	27.719
1530.96	28.2776
1534.06	27.6176
1537.17	29.1413
1540.28	30.5239
1543.38	32.9103
1546.48	34.6354
1549.59	36.7092
1552.69	36.6476
1555.79	37.5201
1558.88	38.8319
1561.98	39.5336
1565.08	41.7889
1568.17	44.1475
1571.27	48.3875
1574.36	53.1473
1577.45	56.2884
1580.54	60.7656
1583.63	66.2625
1586.72	69.7898
1589.8	73.5458
1592.89	75.8236
1595.97	77.9395
1599.06	79.2865
1602.14	82.8634
1605.22	85.4146
1608.3	86.4566
1611.38	86.648
1614.46	88.7704
1617.53	89.4799
1620.61	92.0692
1623.68	95.0614
1626.75	98.7194
1629.82	102.188
1632.9	107.037
1635.96	112.694
1639.03	119.847
1642.1	126.814
1645.16	132.693
1648.23	140.052
1651.29	145.703
1654.36	149.996
1657.42	152.671
1660.48	152.595
1663.53	151.838
1666.59	148.484
1669.65	142.753
1672.7	136.573
1675.76	129.47
1678.81	119.885
1681.86	109.068
1684.91	99.0017
1687.96	89.7349
1691.01	80.0271
1694.06	71.1041
1697.11	62.7629
1700.15	55.0875
1703.2	48.2474
1706.24	41.739
1709.28	36.827
1712.32	33.0907
1715.36	29.3548
1718.4	25.3939
1721.43	23.8669
1724.47	22.2788
1727.5	19.3296
1730.54	17.2005
1733.57	16.4607
1736.6	14.9045
1739.63	13.5934
1742.66	11.865
1745.69	10.1875
1748.72	8.53215
1751.74	7.51661
1754.77	6.5762
1757.79	6.98243
1760.81	6.97885
1763.83	5.71955
1766.85	5.06662
1769.87	4.17765
1772.89	3.84225
1775.91	2.83627
1778.92	1.98834
1781.94	1.75293
1784.95	1.9726
1787.96	2.01647
1790.97	1.74249
1793.98	1.6349
1796.99	1.7487
1800	1.2857
1803	1.02335
1806.01	1.33927
1809.01	1.15704
1812.02	1.02546
1815.02	0.752454
1818.02	0.401918
1821.02	-0.0855908
1824.02	-0.00835653
1827.01	1.33956
1830.01	0.934891
1833	0.911578
1836	0.64915
1838.99	0.337569
1841.98	0.60507
1844.97	0.634773
1847.96	0.406882
1850.95	0.168247
1853.94	0.761223
1856.92	1.85909
1859.91	2.28562
1862.89	2.53351
1865.88	4.1295
1868.86	5.55923
1871.84	6.52769
1874.82	7.02433
1877.8	7.82433
1880.77	7.89095
1882.51	6.82492
1885.5	7.05627
1888.48	6.94962
1891.47	5.62979
1894.46	5.16894
1897.44	6.01521
1900.42	5.22902
1903.41	3.31225
1906.39	3.44125
1909.37	2.41751
1912.35	1.76442
1915.32	1.59889
1918.3	1.7368
1921.28	1.86488
1924.25	3.01204
1927.22	3.71709
1930.2	5.41383
1933.17	5.99657
1936.14	7.69706
1939.11	8.66241
1942.08	8.91026
1945.04	8.5572
1948.01	7.54874
1950.97	6.95601
1953.94	6.47512
1956.9	5.65086
1959.86	6.0736
1962.82	5.5306
1965.78	5.81279
1968.74	6.39252
1971.69	6.69787
1974.65	5.45706
1977.61	6.93411
1980.56	6.79843
1983.51	7.09012
1986.46	6.92169
1989.41	6.94622
1992.36	6.2852
1995.31	6.47433
1998.26	7.01923
2001.2	7.60281
2004.15	8.34933
2007.09	8.70425
2010.04	8.23357
2012.98	8.77452
2015.92	9.04475
2018.86	9.16789
2021.8	8.8833
2024.74	9.80897
2027.67	10.2982
2030.61	10.2404
2033.54	11.6654
2036.47	12.3758
2039.41	13.5574
2042.34	14.6518
2045.27	15.7533
2048.2	16.9128
2051.12	16.7153
2054.05	16.9203
2056.98	17.3532
2059.9	17.216
2062.82	17.1941
2065.75	18.5631
2068.67	20.26
2071.59	21.6528
2074.51	23.7688
2077.43	25.1073
2080.34	27.0194
2083.26	28.5958
2086.17	30.2275
2089.09	30.8846
2092	32.0116
2094.91	34.1821
2097.82	36.5064
2100.73	38.8921
2103.64	42.6326
2106.55	45.7029
2109.46	49.4407
2112.36	53.7362
2115.27	58.1466
2118.17	62.4134
2121.07	67.4446
2123.97	73.6495
2126.87	78.4973
2129.77	84.1491
2132.67	90.7237
2135.57	97.0149
2138.46	104.355
2141.36	111.664
2144.25	118.557
2147.14	125.118
2150.03	131.25
2152.92	137.133
2155.81	142.123
2158.7	147.257
2161.59	150.749
2164.48	155.341
2167.36	158.063
2170.25	160.534
2173.13	162.191
2176.01	162.134
2178.89	160.629
2181.77	159.208
2184.65	156.714
2187.53	152.243
2190.41	147.883
2193.28	142.164
2196.16	135.096
2199.03	128.076
2201.9	122.968
2204.78	116.143
2207.65	109.818
2210.51	103.744
2213.38	97.0197
2216.25	90.2247
2219.12	84.9433
2221.98	78.9731
2224.85	73.7567
2227.71	68.4165
2230.57	63.0491
2233.43	58.1271
2236.29	54.1152
2239.15	49.5201
2242.01	46.6489
2244.87	43.2943
2247.73	39.9556
2250.58	37.6549
2253.43	36.3429
2256.29	33.9451
2259.14	31.764
2261.99	30.3111
2264.84	28.8683
2267.69	27.5478
2270.54	27.0781
2273.38	26.0826
2276.23	25.6997
2279.07	25.0849
2281.92	23.6027
2284.76	23.0792
2287.6	22.7577
2290.44	21.172
2293.28	19.2271
2296.12	18.1477
2298.96	17.4595
2301.79	17.3582
2304.63	16.9525
2307.46	15.4962
2310.3	15.2661
2313.13	14.169
2315.96	13.7522
2318.79	13.5083
2321.62	13.5273
2324.45	13.0756
2327.27	12.4608
2330.1	11.7668
2332.93	12.055
2335.75	10.8052
2338.57	10.2106
2341.4	9.46217
2344.22	9.50296
2347.04	8.00143
2349.86	6.00937
2352.67	5.28359
2355.49	4.60339
2358.31	3.72046
2361.12	3.18472
2363.94	3.98745
2366.75	3.26846
2369.56	3.50672
2372.37	3.47169
2375.18	3.03198
2377.99	2.96374
2380.8	2.37106
2383.61	2.53802
2386.41	3.0085
2389.22	3.46189
2392.02	3.74756
2394.82	5.09878
2397.63	5.94931
2400.43	6.78493
2403.23	7.71431
2406.02	7.73836
2408.82	8.38017
2411.62	9.21399
2414.41	8.58574
2417.21	8.60316
2420	9.74867
2422.79	9.98954
2425.59	9.21576
2428.38	9.17603
2431.17	8.96686
2433.96	8.22173
2436.74	7.70283
2439.53	9.00912
2442.32	8.45033
2445.1	8.75927
2447.88	8.67978
2450.67	8.88383
2453.45	8.92112
2456.23	8.15629
2459.01	7.93536
2461.79	7.4754
2464.57	7.04487
2467.34	7.15972
2470.12	6.76728
2472.89	6.46051
2475.67	5.55847
2478.44	4.46494
2481.21	3.75039
2483.98	2.39732
2486.75	2.65193
2489.52	1.37516
2492.29	0.565662
2495.06	-0.255949
2497.82	-0.67429
2500.59	-1.55724
2503.35	-2.22863
2506.11	-0.87814
2508.88	-0.615525
2511.63	-0.82522
2514.39	-0.803422
2517.15	-0.395205
2519.91	-0.772706
2522.67	-0.81627
2525.42	-0.881189
2528.18	-0.526498
2530.93	1.0606
2533.69	2.65042
2536.44	3.87776
2539.19	3.8376
2541.94	3.74034
2544.69	4.45969
2547.44	5.32957
2550.18	5.96517
2552.93	5.93714
2555.68	6.03516
2558.42	6.00771
2561.16	5.45699
2563.9	4.99623
2566.64	4.86363
2569.38	4.09326
2572.12	3.64108
2574.86	3.97454
2577.6	3.84339
2580.34	3.10057
2583.07	2.13896
2585.81	2.15685
2588.54	1.60542
2591.27	1.26021
2594	1.68587
2596.73	2.81229
2599.46	2.46315
2602.19	2.74826
2604.92	2.34131
2607.64	1.60203
2610.37	2.53421
2613.09	3.45834
2615.82	2.78374
2618.54	1.70486
2621.26	1.86973
2623.98	2.26293
2626.7	2.36801
2629.42	3.19405
2632.14	4.19284
2634.86	5.05574
2637.57	4.94216
2640.29	5.92489
2643	6.16688
2645.72	6.86085
2648.43	7.62193
2651.14	7.41677
2653.85	8.00116
2656.56	7.78784
2659.27	7.76496
2661.97	7.85715
2664.68	7.82921
2667.38	8.4849
2670.09	8.02253
2672.79	7.29002
2675.49	6.5079
2678.2	5.98426
2680.89	5.43311
2683.59	3.67928
2686.29	3.18831
2688.99	2.93181
2691.69	3.37605
2694.38	4.12905
2697.08	3.70476
2699.77	3.90902
2702.46	5.14631
2705.16	6.08421
2707.85	6.68299
2710.54	7.9047
2713.23	9.11562
2715.92	10.2881
2718.6	10.714
2721.29	10.5926
2723.97	10.1923
2726.66	11.1009
2729.34	10.8364
2732.02	10.9172
2734.7	10.5815
2737.39	9.61091
2740.06	8.98159
2742.74	6.91403
2745.42	6.95059
2748.1	6.71821
2750.77	5.52502
2753.45	5.28677
2756.12	4.0105
2758.79	4.54127
2761.47	3.53211
2764.14	2.43467
2766.81	2.42349
2769.48	2.54799
2772.14	2.35646
2774.81	1.8881
2777.48	2.64614
2780.14	3.12937
2782.81	3.56762
2785.47	3.64929
2788.13	3.2558
2790.79	3.64326
2793.46	4.33344
2796.11	3.28417
2798.77	4.01239
2801.43	4.25421
2804.09	4.12884
2806.74	4.07373
2809.4	4.95473
2812.05	5.74808
2814.71	6.22361
2817.36	7.16055
2820.01	9.41423
2822.66	12.8503
2825.31	16.9428
2827.96	21.0467
2830.61	26.241
2833.25	33.1714
2835.9	40.4046
2838.54	49.3551
2841.18	59.2051
2843.83	70.9218
2846.47	82.8482
2849.11	96.3608
2851.75	110.796
2854.39	124.787
2857.03	139.308
2859.67	152.192
2862.3	165.854
2864.94	177.12
2867.57	188.004
2870.21	197.96
2872.84	205.985
2875.47	213.524
2878.1	221.937
2880.73	227.783
2883.36	235.79
2885.99	243.671
2888.61	250.932
2891.24	259.566
2893.87	268.931
2896.49	280.832
2899.11	294.728
2901.74	310.006
2904.36	327.791
2906.98	347.796
2909.6	370.746
2912.22	394.831
2914.83	417.597
2917.45	438.597
2920.07	456.75
2922.68	472.632
2925.3	485.895
2927.91	495.643
2930.52	500.745
2933.13	502.533
2935.74	499.697
2938.35	492.582
2940.96	482.691
2943.57	469.655
2946.18	453.588
2948.78	436.282
2951.39	416.953
2953.99	397.074
2956.6	376.212
2959.2	356.761
2961.8	336.953
2964.4	316.88
2967	297.857
2969.6	280.988
2972.2	264.547
2974.79	248.671
2977.39	233.088
2979.98	217.31
2982.58	201.751
2985.17	186.055
2987.76	170.947
2990.36	155.232
2992.95	139.672
2995.54	125.248
2998.12	112.159
3000.71	99.2846
3003.3	86.4231
3005.88	75.7217
3008.47	65.7287
3011.05	56.5771
3013.64	48.1545
3016.22	40.1985
3018.8	33.159
3021.38	28.0035
3023.96	24.7098
3026.54	21.2874
3029.12	18.372
3031.69	17.1219
3034.27	16.6983
3036.85	16.6843
3039.42	17.7263
3041.99	18.4933
3044.57	20.1306
3047.14	20.9264
3049.71	20.7579
3052.28	21.2153
3054.85	21.2788
3057.42	21.3407
3059.98	21.2131
3062.55	21.0083
3065.11	19.8863
3067.68	18.4568
3070.24	16.7336
3072.8	15.2558
3075.37	12.5211
3077.93	10.343
3080.49	8.76307
3083.05	6.92571
3085.61	5.81337
3088.16	3.79927
3090.72	2.79458
3093.27	1.51081
3095.83	1.00085
3098.38	0.619035
3100.94	0.061223
3103.49	0.0805455
3106.04	0.24018
3108.59	0.271448
3111.14	0.271566
3113.69	0.986434
3116.23	0.836902
3118.78	1.60771
3121.33	2.94287
3123.87	3.90037
3126.42	5.01692
3128.96	5.33056
3131.5	6.8081
3134.04	8.95207
3136.58	10.2794
3139.12	11.7749
3141.66	13.3664
3144.2	14.732
3146.74	17.0308
3149.27	19.6808