File: data/Raman/poly_smoothed/Mb_30_27_12_1x_45s_532 nm_x100_100%_600 gr_mm_01.txt
#Acq. time (s)=	45
#Accumulations=	2
#Range (cm-¹)=	200...3150
#Windows=	2
#Auto scanning=	Off
#Autofocus=	Off
#Macrospot=	Off
#AutoExposure=	Off
#Spike filter=	Multiple accum.
#Delay time (s)=	0
#Binning=	1
#Readout mode=	Signal
#DeNoise=	Off
#ICS correction=	On
#Dark correction=	Off
#Inst. Process=	Off
#Detector Gain=	Best Dynamic Range
#Detector ADC=	20 kHz
#Detector temperature (°C)=	-69.85
#Instrument=	LabRAM HR Evol
#Detector=	Synapse
#Objective=	x100
#Grating=	600 gr/mm
#ND Filter=	100%
#Laser (nm)=	532
#Hole=	100.021
#Range=	Auto
#Laser Pol.=	No
#Raman. Pol.=	No
#Laser Pol. (°)=	-0.0007625
#Raman Pol. (°)=	89.9995
#Collection=	Microscope
#StageXY=	Marzhauser
#StageZ=	Marzhauser
#X (µm)=	-1244
#Y (µm)=	1606.2
#Z (µm)=	-6.95
#Full time(mm:ss)=	3:18
#Project=
#Sample=
#Site=
#Title=	Mb_30_27_12_2x_45s_532 nm_x100_100%_600 gr_mm
#Remark=
#Date=	12.07.2022 16:51
#Acquired=	12.07.2022 16:51:56
#Base:Fit=	10.08.2022 10:40:03
#Base:Sub=	10.08.2022 10:40:17
#Filter:Polynom=	16.08.2022 10:16:15
#AxisType[0]=Intens
#AxisUnit[0]=Cnt
#AxisType[1]=Spectr
#AxisUnit[1]=1/cm
200.413	8.85082
204.042	11.8219
207.671	11.3862
211.297	10.6632
214.924	10.8173
218.547	11.0453
222.169	11.4545
225.792	10.9683
229.411	11.2196
233.028	9.97669
236.647	9.88274
240.261	10.8541
243.875	11.8952
247.487	12.1478
251.099	12.6572
254.708	13.1042
258.316	14.5361
261.922	16.6524
265.527	18.3025
269.131	18.7001
272.733	20.8839
276.334	22.168
279.933	22.6439
283.531	23.2427
287.128	22.6276
290.723	22.419
294.316	23.6222
297.909	23.6871
301.498	23.4359
305.087	23.1489
308.675	23.0124
312.262	22.1272
315.845	21.1556
319.429	21.6788
323.012	21.7426
326.591	21.2274
330.171	19.9815
333.749	18.1835
337.324	17.8004
340.9	15.0471
344.472	14.1399
348.045	14.8943
351.614	13.0767
355.185	11.8516
358.751	10.5755
362.317	9.49771
365.883	8.95392
369.445	7.878
373.006	5.44087
376.568	5.34811
380.126	5.37477
383.683	2.78441
387.239	1.84987
390.793	1.20023
394.348	2.99271
397.9	2.32967
401.45	3.09902
404.999	3.63592
408.546	1.96173
412.092	2.11139
415.637	0.846238
419.18	1.09271
422.722	0.854972
426.263	2.21702
429.802	2.09829
433.338	2.8834
436.874	2.38215
440.41	2.13218
443.943	1.9699
447.476	1.33014
451.005	2.74453
454.534	2.7026
458.063	5.01677
461.588	5.33746
465.113	7.37045
468.638	7.43729
472.158	7.48883
475.68	9.66358
479.198	11.2255
482.717	12.773
486.233	12.0186
489.747	14.4144
493.261	14.3814
496.773	15.9207
500.285	17.2781
503.794	16.4161
507.301	16.6149
510.807	15.5111
514.314	14.1117
517.817	13.0552
521.319	12.4729
524.82	11.2587
528.319	10.1991
531.817	7.8437
535.316	5.43717
538.811	5.57554
542.305	6.03706
545.798	4.69704
549.289	4.54228
552.777	4.65491
556.265	2.9119
559.753	4.31415
563.239	3.88414
566.723	4.66209
570.207	3.63446
573.688	3.97608
577.167	4.14212
580.646	4.38849
584.124	3.89788
587.599	2.33584
591.074	2.22691
594.548	2.24805
598.019	0.982091
601.49	2.26534
604.958	1.41867
608.427	3.81553
611.892	3.82214
615.358	3.12397
618.821	3.27816
622.282	2.95632
625.744	4.59794
629.203	5.01066
632.661	6.4432
636.119	6.62523
639.574	7.57555
643.027	9.03369
646.479	10.2687
649.932	12.4505
653.382	12.7497
656.83	13.4823
660.277	12.7914
663.722	12.2683
667.167	13.2089
670.61	13.6662
674.051	14.3255
677.492	15.773
680.931	17.0839
684.369	18.4708
687.803	19.2415
691.238	21.754
694.672	21.9467
698.105	21.6254
701.536	22.9747
704.964	23.8452
708.393	24.9457
711.82	24.8969
715.244	25.5336
718.669	25.2712
722.09	25.3987
725.512	26.6443
728.933	28.8652
732.351	29.795
735.767	29.4278
739.184	30.4967
742.598	32.6957
746.012	35.0446
749.423	38.4018
752.833	42.7846
756.244	46.8647
759.651	50.1458
763.057	53.3535
766.462	57.6282
769.865	61.3803
773.269	64.6954
776.67	69.0259
780.069	73.0374
783.468	76.6808
786.865	81.0096
790.26	82.4468
793.655	84.4967
797.048	86.8255
800.44	89.1219
803.83	89.4468
807.218	90.9969
810.606	92.7547
813.993	92.8417
817.378	92.1279
820.762	91.9108
824.143	93.5461
827.525	92.707
830.905	90.8544
834.282	88.8592
837.66	86.2491
841.035	84.6292
844.41	81.9583
847.782	79.3198
851.155	76.7846
854.525	74.9624
857.895	71.9954
861.262	70.4493
864.628	67.0749
867.994	66.1954
871.357	63.8164
874.719	63.419
878.082	64.4504
881.441	63.0563
884.799	62.4875
888.156	60.6519
891.512	60.8657
894.866	59.6308
898.22	58.4735
901.573	57.7172
904.924	58.6059
908.271	57.8478
911.62	58.3167
914.966	56.0013
918.312	56.9966
921.656	55.6242
925	54.5862
928.341	52.146
931.68	49.2013
935.019	47.4224
938.358	44.2115
941.694	43.063
945.028	40.8472
948.362	39.3705
951.694	39.0593
955.026	38.0123
958.356	36.5845
961.684	35.4815
965.012	34.2897
968.337	33.2286
971.661	32.2888
974.985	31.1152
978.306	29.7257
981.626	30.8172
984.947	29.3549
988.264	30.5755
991.581	27.7786
994.896	26.9376
998.212	26.2669
1001.52	24.0869
1004.84	22.6862
1008.15	22.0546
1011.45	21.368
1014.76	23.7231
1018.07	27.3541
1021.37	30.5499
1024.68	32.9744
1027.98	36.1671
1031.28	37.905
1034.58	39.3921
1037.88	40.3535
1041.18	41.9517
1044.47	43.4191
1047.77	43.8728
1051.06	42.0722
1054.35	40.9023
1057.64	40.6695
1060.94	39.8463
1064.22	37.8938
1067.51	35.0528
1070.8	31.9409
1074.08	28.8361
1077.36	24.8571
1080.65	21.6667
1083.93	20.2582
1087.21	18.2078
1090.49	17.5677
1093.76	15.4693
1097.04	18.0792
1100.31	16.49
1103.59	14.5058
1106.86	14.0837
1110.13	12.5098
1113.4	12.3608
1116.66	14.828
1119.93	14.7972
1123.2	14.4095
1126.46	14.7086
1129.72	15.6084
1132.99	16.6462
1136.25	18.1726
1139.51	18.3567
1142.77	19.3712
1146.02	18.3144
1149.28	16.1756
1152.53	15.3585
1155.78	13.6883
1159.04	12.0441
1162.29	11.3658
1165.54	9.58859
1168.78	7.23503
1172.03	5.30226
1175.27	4.8753
1178.52	3.91939
1181.76	1.23028
1185	0.632799
1188.24	1.6079
1191.48	2.30388
1194.72	3.68147
1197.96	5.12738
1201.19	7.26653
1204.43	9.78984
1207.66	11.6719
1210.89	13.5705
1214.12	15.6543
1217.35	19.4868
1220.58	22.0583
1223.81	23.8344
1227.03	26.5113
1230.26	31.0496
1233.48	33.7327
1236.7	36.4025
1239.92	39.2793
1243.14	42.0507
1246.36	43.2554
1249.57	42.0793
1252.79	42.5322
1256	45.3619
1259.22	45.2208
1262.43	44.7355
1265.64	47.1486
1268.85	48.1102
1272.06	48.7449
1275.26	51.7965
1278.47	55.4687
1281.67	54.9744
1284.88	57.239
1288.08	58.8526
1291.28	59.724
1294.48	61.8228
1297.68	60.6329
1300.87	63.5578
1304.07	65.0473
1307.26	66.4684
1310.46	67.3252
1313.65	68.4587
1316.84	69.062
1320.03	69.8759
1323.22	69.4282
1326.4	69.9501
1329.59	68.7141
1332.78	68.8997
1335.96	68.5734
1339.14	65.4135
1342.32	62.8036
1345.5	62.7572
1348.68	61.5849
1351.86	60.5581
1355.03	59.4128
1358.21	55.8399
1361.38	54.9912
1364.56	53.5434
1367.73	50.7505
1370.9	49.6545
1374.07	45.7381
1377.23	43.7438
1380.4	43.4251
1383.57	41.0707
1386.73	40.9974
1389.89	40.8111
1393.05	41.5138
1396.21	41.2355
1399.37	42.4515
1402.53	45.116
1405.69	46.5543
1408.84	48.3251
1412	51.5451
1415.15	54.2327
1418.3	56.3499
1421.45	60.0397
1424.6	66.0125
1427.75	69.0126
1430.9	72.2187
1434.04	78.7421
1437.19	81.5382
1440.33	83.3037
1443.47	84.0762
1446.62	84.7581
1449.76	83.7153
1452.9	83.3917
1456.03	84.2711
1459.17	82.9674
1462.3	81.8973
1465.44	79.7634
1468.57	77.2131
1471.7	74.5612
1474.83	70.8029
1477.96	68.5952
1481.09	65.1355
1484.22	60.7585
1487.34	58.2583
1490.47	54.4867
1493.59	52.2963
1496.71	49.4263
1499.83	48.1199
1502.95	47.0487
1506.07	43.7743
1509.19	42.6781
1512.3	40.4067
1515.42	36.387
1518.53	34.4977
1521.65	33.502
1524.76	32.5997
1527.87	32.2118
1530.98	33.4122
1534.08	34.0527
1537.19	33.5864
1540.3	35.6964
1543.4	35.3458
1546.5	36.3268
1549.61	37.8079
1552.71	39.7468
1555.81	42.4707
1558.9	43.7385
1562	45.7466
1565.1	49.2713
1568.19	51.3662
1571.29	53.4036
1574.38	55.6644
1577.47	56.5357
1580.56	57.5193
1583.65	61.3812
1586.74	62.1467
1589.82	63.0301
1592.91	64.4011
1595.99	66.2647
1599.08	66.8998
1602.16	66.4931
1605.24	67.5463
1608.32	68.357
1611.4	66.6425
1614.48	69.6227
1617.55	69.4151
1620.63	69.7589
1623.7	72.1392
1626.77	73.4796
1629.84	74.8586
1632.92	76.482
1635.98	75.8653
1639.05	78.2467
1642.12	80.626
1645.19	81.2184
1648.25	82.6215
1651.31	83.5561
1654.38	84.5066
1657.44	87.4297
1660.5	88.4865
1663.56	86.1601
1666.61	85.8876
1669.67	86.2668
1672.72	83.2273
1675.78	80.4281
1678.83	75.7548
1681.88	72.2383
1684.93	68.8182
1687.98	65.4443
1691.03	62.2317
1694.08	57.6365
1697.13	55.3817
1700.17	51.7817
1703.21	47.0861
1706.26	44.0399
1709.3	41.568
1712.34	37.7303
1715.38	37.1299
1718.42	35.3864
1721.45	34.4275
1724.49	33.9404
1727.52	34.1631
1730.56	35.2492
1733.59	35.6707
1736.62	34.6865
1739.65	34.5515
1742.68	35.4405
1745.71	36.2585
1748.74	35.4766
1751.76	35.3062
1754.79	33.9848
1757.81	34.4873
1760.83	33.5901
1763.85	33.3223
1766.87	32.2402
1769.89	31.8125
1772.91	31.0245
1775.93	29.2755
1778.94	29.1846
1781.95	29.5057
1784.97	29.4398
1787.98	30.1014
1790.99	31.5791
1794	33.5468
1797.01	33.487
1800.02	35.0431
1803.02	35.7722
1806.03	36.2052
1809.03	37.1605
1812.03	38.1243
1815.04	39.4127
1818.04	38.7748
1821.04	39.2812
1824.04	39.2478
1827.03	38.158
1830.03	37.9098
1833.02	38.0334
1836.02	37.4011
1839.01	36.7258
1842	36.061
1844.99	35.9836
1847.98	35.1913
1850.97	35.8933
1853.96	37.2872
1856.95	37.7175
1859.93	37.4381
1862.91	37.7839
1865.9	37.773
1868.88	38.1116
1871.86	37.0383
1874.84	36.4674
1877.82	35.9343
1880.79	34.7819
1882.53	34.2413
1885.52	33.2246
1888.51	31.5633
1891.49	31.186
1894.48	31.0873
1897.46	30.7873
1900.45	29.9824
1903.43	28.906
1906.41	26.6308
1909.39	25.5735
1912.37	24.7823
1915.35	23.8484
1918.32	22.4571
1921.3	22.5964
1924.27	22.6306
1927.25	22.2462
1930.22	21.2178
1933.19	19.9746
1936.16	19.4378
1939.13	17.2968
1942.1	16.6128
1945.06	13.7826
1948.03	10.9847
1950.99	8.86747
1953.96	8.48491
1956.92	8.15672
1959.88	6.95435
1962.84	5.99014
1965.8	4.78098
1968.76	4.64003
1971.72	3.53483
1974.67	2.52178
1977.63	0.885255
1980.58	1.15781
1983.53	2.7257
1986.48	1.88452
1989.43	2.32256
1992.39	3.03349
1995.33	3.48587
1998.28	4.32595
2001.23	6.4419
2004.17	6.82705
2007.11	6.77343
2010.06	6.67743
2013	6.59218
2015.94	6.93355
2018.88	6.29474
2021.82	7.59969
2024.76	9.18066
2027.69	9.88554
2030.63	10.0055
2033.56	9.21353
2036.5	10.4529
2039.43	10.917
2042.36	12.2117
2045.29	12.226
2048.22	11.6658
2051.14	13.5511
2054.07	16.3252
2057	16.2521
2059.92	17.599
2062.85	18.7969
2065.77	20.7817
2068.69	21.4449
2071.61	21.5092
2074.53	21.072
2077.45	19.8205
2080.36	19.6156
2083.28	18.9882
2086.19	19.9486
2089.11	20.8998
2092.02	20.7117
2094.93	21.6707
2097.84	23.2078
2100.75	23.7313
2103.66	25.0232
2106.57	26.5734
2109.48	27.1695
2112.38	28.3223
2115.29	29.4055
2118.19	31.4076
2121.09	33.3959
2123.99	36.8434
2126.89	40.5891
2129.79	43.8129
2132.69	48.0628
2135.59	50.7201
2138.48	53.0587
2141.38	55.081
2144.27	57.822
2147.16	60.1399
2150.06	62.8492
2152.95	65.3857
2155.83	67.1985
2158.72	69.4012
2161.61	71.4488
2164.5	73.4764
2167.38	73.5041
2170.27	74.9668
2173.15	74.6928
2176.03	74.172
2178.91	74.4537
2181.79	73.0677
2184.67	72.4626
2187.55	70.8386
2190.43	69.6003
2193.3	68.0768
2196.18	67.3189
2199.05	65.0967
2201.92	64.3423
2204.8	61.1886
2207.67	59.8269
2210.54	58.212
2213.4	56.4272
2216.27	52.4998
2219.14	50.169
2222	47.3764
2224.87	44.6835
2227.73	41.9324
2230.59	39.9039
2233.46	37.6465
2236.32	35.8597
2239.18	34.0439
2242.03	33.3582
2244.89	31.1339
2247.75	29.9876
2250.6	28.287
2253.45	25.3466
2256.31	23.8703
2259.16	23.1212
2262.01	22.4578
2264.86	20.4914
2267.71	20.2384
2270.56	20.2855
2273.4	19.9075
2276.25	19.583
2279.09	19.4542
2281.94	17.3275
2284.78	16.6365
2287.62	15.3845
2290.46	15.2346
2293.3	13.1283
2296.14	12.5496
2298.98	13.3512
2301.81	13.4424
2304.65	12.7389
2307.48	12.1958
2310.32	11.4472
2313.15	11.1771
2315.98	11.0126
2318.81	11.6571
2321.64	10.9596
2324.47	10.907
2327.3	11.4982
2330.12	12.0638
2332.95	11.5094
2335.77	10.0207
2338.59	9.12306
2341.42	9.55838
2344.24	8.77239
2347.06	8.5926
2349.88	7.10759
2352.69	6.72177
2355.51	4.96592
2358.33	4.55938
2361.14	3.30529
2363.96	3.30779
2366.77	3.63991
2369.58	4.10858
2372.39	3.42056
2375.2	3.82511
2378.01	3.0086
2380.82	3.48288
2383.63	3.68466
2386.43	4.56074
2389.24	3.54402
2392.04	2.16424
2394.84	3.23793
2397.64	3.36206
2400.45	2.55405
2403.25	2.93514
2406.04	3.37003
2408.84	4.6572
2411.64	6.60501
2414.43	7.19022
2417.23	8.59454
2420.02	9.78896
2422.82	9.01463
2425.61	9.822
2428.4	9.71131
2431.19	10.3685
2433.98	10.014
2436.76	10.5615
2439.55	10.9981
2442.34	10.9129
2445.12	10.0496
2447.9	7.50521
2450.69	6.52044
2453.47	6.32457
2456.25	5.44711
2459.03	4.27747
2461.81	5.16579
2464.59	4.866
2467.36	5.68776
2470.14	5.02388
2472.91	4.80444
2475.69	5.29453
2478.46	5.4925
2481.23	5.48185
2484	6.57394
2486.77	6.12712
2489.54	5.41397
2492.31	4.56444
2495.08	4.8671
2497.84	4.98613
2500.61	4.92886
2503.37	4.89688
2506.13	4.91551
2508.89	5.50442
2511.66	5.19258
2514.42	4.46671
2517.17	4.10479
2519.93	4.24648
2522.69	5.42202
2525.44	5.11386
2528.2	6.74797
2530.95	7.13048
2533.71	6.30719
2536.46	6.86137
2539.21	6.33643
2541.96	5.44402
2544.71	5.5458
2547.46	5.17713
2550.2	5.91722
2552.95	5.2837
2555.69	3.90035
2558.44	3.96442
2561.18	4.39781
2563.92	3.82165
2566.67	3.31651
2569.41	3.00203
2572.14	2.69559
2574.88	2.75714
2577.62	3.73267
2580.36	3.47173
2583.09	2.05141
2585.83	1.51285
2588.56	2.07137
2591.29	1.40066
2594.02	1.32225
2596.75	1.27713
2599.48	-0.196883
2602.21	0.131952
2604.94	-0.0026108
2607.67	0.232072
2610.39	1.45478
2613.12	1.5177
2615.84	1.08285
2618.56	2.26393
2621.28	2.63182
2624	3.9185
2626.72	5.2726
2629.44	4.88589
2632.16	5.01107
2634.88	5.8149
2637.59	5.33849
2640.31	6.7856
2643.02	6.30427
2645.73	7.37268
2648.45	6.40668
2651.16	5.1502
2653.87	5.62527
2656.58	4.66933
2659.28	4.91374
2661.99	4.12447
2664.7	3.50376
2667.4	2.48304
2670.11	2.95101
2672.81	3.83196
2675.51	4.13833
2678.21	5.44368
2680.92	6.07924
2683.62	7.55052
2686.31	8.94699
2689.01	8.02639
2691.71	8.07509
2694.4	8.32751
2697.1	7.36722
2699.79	8.25325
2702.48	7.36587
2705.18	7.48155
2707.87	8.40211
2710.56	7.89745
2713.25	9.18899
2715.93	8.04928
2718.62	7.92652
2721.31	8.38919
2723.99	7.08623
2726.68	7.26771
2729.36	6.11245
2732.04	6.90036
2734.72	8.01344
2737.4	9.29882
2740.08	9.46289
2742.76	10.5061
2745.44	10.6501
2748.12	10.3896
2750.79	9.57631
2753.47	7.4246
2756.14	5.97379
2758.81	6.26222
2761.48	5.79003
2764.16	4.8691
2766.83	3.23398
2769.49	2.39814
2772.16	1.46671
2774.83	1.3472
2777.5	1.6549
2780.16	1.70728
2782.83	1.10887
2785.49	1.24087
2788.15	0.755209
2790.81	1.13745
2793.47	1.60192
2796.13	1.80632
2798.79	2.35993
2801.45	1.57448
2804.11	2.66185
2806.76	1.06326
2809.42	1.72047
2812.07	0.308628
2814.73	-0.79713
2817.38	0.926763
2820.03	2.90923
2822.68	5.9605
2825.33	7.82005
2827.98	11.0352
2830.62	15.0354
2833.27	20.5276
2835.92	25.643
2838.56	32.7108
2841.2	40.7757
2843.85	48.6031
2846.49	55.4782
2849.13	64.172
2851.77	73.1195
2854.41	81.8364
2857.05	89.4054
2859.68	95.6921
2862.32	101.914
2864.96	108.603
2867.59	114.723
2870.22	119.853
2872.86	123.305
2875.49	127.421
2878.12	131.577
2880.75	137.2
2883.38	142.254
2886.01	145.223
2888.63	149.118
2891.26	153.987
2893.88	159.082
2896.51	164.708
2899.13	170.909
2901.76	177.445
2904.38	186.299
2907	193.89
2909.62	203.502
2912.24	213.284
2914.85	223.479
2917.47	230.339
2920.09	235.963
2922.7	239.177
2925.31	243.912
2927.93	247.171
2930.54	248.971
2933.15	247.28
2935.76	245.046
2938.37	241.094
2940.98	236.722
2943.59	231.141
2946.2	223.792
2948.8	214.388
2951.41	206.18
2954.01	196.461
2956.62	186.546
2959.22	176.392
2961.82	166.713
2964.42	158.488
2967.02	149.742
2969.62	140.667
2972.21	132.522
2974.81	124.228
2977.41	114.395
2980	104.981
2982.6	95.7378
2985.19	87.0617
2987.78	78.2268
2990.37	71.1842
2992.96	63.2558
2995.55	54.5092
2998.14	48.9049
3000.73	42.8095
3003.32	38.1536
3005.9	33.4336
3008.49	29.1487
3011.07	24.9775
3013.66	21.4684
3016.24	18.7275
3018.82	15.2399
3021.4	14.9749
3023.98	14.5321
3026.56	12.5357
3029.14	12.0526
3031.71	10.9596
3034.29	9.45302
3036.86	9.34781
3039.44	8.71779
3042.01	8.48946
3044.59	8.03256
3047.16	8.37378
3049.73	8.07628
3052.3	6.40456
3054.87	5.8125
3057.43	6.35684
3060	7.0536
3062.57	8.1743
3065.13	7.87052
3067.7	7.0103
3070.26	8.18118
3072.82	6.95875
3075.39	6.88735
3077.95	6.96526
3080.51	7.56289
3083.07	8.64249
3085.62	9.40605
3088.18	7.07704
3090.74	5.69247
3093.29	5.04429
3095.85	5.33486
3098.4	5.07742
3100.95	5.78154
3103.51	5.9426
3106.06	6.13432
3108.61	7.58248
3111.16	8.22853
3113.71	8.25896
3116.25	9.90408
3118.8	11.8669
3121.34	13.0523
3123.89	15.0402
3126.43	15.9003
3128.98	17.9052
3131.52	20.6601
3134.06	22.0463
3136.6	24.6563
3139.14	27.0589
3141.68	28.2186
3144.22	28.2058
3146.75	27.7643
3149.29	28.6336