File: data/Raman/poly_smoothed/Mb_30_27_02_1x_45s_532 nm_x100_100%_600 gr_mm_01.txt
#Acq. time (s)=	45
#Accumulations=	2
#Range (cm-¹)=	200...3150
#Windows=	2
#Auto scanning=	Off
#Autofocus=	Off
#Macrospot=	Off
#AutoExposure=	Off
#Spike filter=	Multiple accum.
#Delay time (s)=	0
#Binning=	1
#Readout mode=	Signal
#DeNoise=	Off
#ICS correction=	On
#Dark correction=	Off
#Inst. Process=	Off
#Detector Gain=	Best Dynamic Range
#Detector ADC=	20 kHz
#Detector temperature (°C)=	-69.85
#Instrument=	LabRAM HR Evol
#Detector=	Synapse
#Objective=	x100
#Grating=	600 gr/mm
#ND Filter=	100%
#Laser (nm)=	532
#Hole=	100.021
#Range=	Auto
#Laser Pol.=	No
#Raman. Pol.=	No
#Laser Pol. (°)=	-0.0007625
#Raman Pol. (°)=	89.9995
#Collection=	Microscope
#StageXY=	Marzhauser
#StageZ=	Marzhauser
#X (µm)=	28058.5
#Y (µm)=	-563.4
#Z (µm)=	1083.7
#Full time(mm:ss)=	3:19
#Project=
#Sample=
#Site=
#Title=	Mb_30_27_02_2x_45s_532 nm_x100_100%_600 gr_mm
#Remark=
#Date=	12.07.2022 15:34
#Acquired=	12.07.2022 15:34:39
#Base:Fit=	10.08.2022 10:39:47
#Base:Sub=	10.08.2022 10:39:55
#Base:Fit=	10.08.2022 10:40:03
#Base:Sub=	10.08.2022 10:40:17
#Filter:Polynom=	16.08.2022 10:16:15
#AxisType[0]=Intens
#AxisUnit[0]=Cnt
#AxisType[1]=Spectr
#AxisUnit[1]=1/cm
200.388	10.2627
204.019	12.4239
207.646	11.8685
211.274	11.805
214.899	11.7002
218.524	10.261
222.146	12.0129
225.766	13.4714
229.388	14.4188
233.005	13.2176
236.621	10.9237
240.236	10.8963
243.852	11.1491
247.464	10.7691
251.074	11.0267
254.683	12.7681
258.291	13.5777
261.897	14.401
265.504	15.4267
269.108	16.5691
272.71	18.348
276.311	18.0208
279.91	18.1034
283.508	19.9751
287.105	19.6862
290.698	19.8434
294.291	22.5589
297.884	25.4205
301.475	25.9223
305.064	25.9588
308.652	27.644
312.237	29.8227
315.822	27.1186
319.406	26.6585
322.987	24.0704
326.568	23.8993
330.148	23.7668
333.724	22.6433
337.301	23.3019
340.875	22.6987
344.449	22.7947
348.02	21.647
351.592	21.8455
355.16	23.7816
358.728	24.9163
362.294	24.1615
365.858	25.6007
369.422	25.2245
372.983	25.4306
376.543	25.715
380.102	27.1541
383.661	26.5938
387.216	26.4898
390.771	26.1466
394.324	25.1863
397.875	24.4544
401.425	22.6389
404.974	20.404
408.524	18.6198
412.07	17.885
415.614	17.862
419.156	17.6763
422.698	16.6177
426.238	15.8468
429.777	14.7541
433.315	15.3413
436.852	17.2314
440.387	19.9555
443.919	20.3126
447.451	21.6162
450.982	21.8606
454.512	22.8118
458.038	22.1421
461.565	23.708
465.091	23.969
468.613	24.546
472.136	26.0071
475.655	29.7382
479.176	31.5149
482.692	31.6188
486.21	33.9405
489.724	34.7176
493.237	35.3011
496.75	37.3273
500.26	37.9522
503.771	38.4077
507.279	39.0659
510.785	38.5445
514.289	37.5806
517.793	37.4016
521.297	37.6349
524.797	36.4875
528.297	34.1642
531.795	31.6887
535.291	29.1979
538.787	27.1874
542.281	25.7868
545.773	22.8218
549.264	21.1213
552.754	21.4364
556.243	20.3508
559.73	20.8543
563.216	20.9593
566.701	20.7398
570.182	20.4371
573.664	18.8442
577.145	16.7979
580.624	16.4
584.1	17.0696
587.577	16.4404
591.052	15.4012
594.524	14.7355
597.997	14.982
601.466	14.7197
604.936	13.7915
608.403	12.4431
611.87	11.8132
615.334	12.2167
618.799	11.7246
622.26	13.6924
625.72	14.3118
629.181	14.6642
632.638	15.9747
636.095	17.8136
639.551	18.6942
643.005	21.1245
646.457	23.8447
649.908	24.0118
653.357	24.0693
656.806	23.3614
660.253	22.6005
663.7	24.6542
667.145	25.1638
670.588	25.1743
674.027	25.4291
677.468	26.1017
680.907	28.0479
684.345	28.1723
687.781	28.429
691.216	29.3086
694.65	31.6823
698.081	34.5859
701.512	36.2717
704.942	38.1508
708.371	38.5228
711.796	40.2612
715.222	41.4083
718.645	44.0902
722.068	45.801
725.49	48.8716
728.909	51.3562
732.329	51.4205
735.745	52.0072
739.16	53.6836
742.576	54.7955
745.988	57.6471
749.401	59.9741
752.811	62.2014
756.22	63.6642
759.627	64.0574
763.035	67.0615
766.44	68.4464
769.843	71.092
773.245	73.1329
776.646	75.0025
780.046	76.3807
783.444	76.8128
786.841	78.2856
790.237	78.5607
793.631	81.1081
797.024	81.6479
800.416	82.6312
803.807	84.3188
807.196	85.241
810.584	86.2677
813.971	86.781
817.354	86.7521
820.739	86.1124
824.122	87.4564
827.503	86.0061
830.882	84.9376
834.261	84.0747
837.637	81.2539
841.013	77.1573
844.389	77.0555
847.761	74.9788
851.131	71.9862
854.503	68.0503
857.871	65.507
861.24	63.066
864.606	60.8025
867.97	59.3568
871.336	57.8743
874.698	55.5428
878.058	52.3087
881.418	50.2584
884.778	48.4238
888.135	48.9656
891.49	48.639
894.845	48.121
898.198	46.7292
901.55	45.3644
904.901	45.3781
908.25	45.9719
911.598	43.6574
914.945	43.2359
918.291	40.9509
921.635	39.9475
924.978	40.3939
928.318	41.1562
931.659	41.0537
934.998	40.2692
938.336	39.774
941.671	40.1781
945.007	39.7498
948.339	39.9084
951.672	40.7366
955.004	39.1368
958.333	38.9533
961.662	39.0721
964.989	38.5636
968.315	39.9275
971.639	38.9392
974.962	39.3638
978.285	38.9736
981.605	38.4127
984.924	39.7186
988.243	39.3978
991.56	38.3569
994.875	36.4489
998.188	34.6538
1001.5	32.4251
1004.81	32.8959
1008.12	34.0185
1011.43	35.6123
1014.74	37.5367
1018.05	39.5949
1021.35	41.8327
1024.65	41.7014
1027.96	43.2889
1031.26	44.5641
1034.56	45.7432
1037.86	45.3832
1041.16	45.1769
1044.45	43.1351
1047.75	41.3999
1051.04	40.5463
1054.33	36.9041
1057.62	35.0982
1060.91	30.9024
1064.2	28.177
1067.49	23.5212
1070.77	20.1047
1074.06	15.281
1077.34	10.9632
1080.62	7.43807
1083.91	7.22777
1087.18	7.62198
1090.46	8.39825
1093.74	9.3432
1097.02	9.05784
1100.29	8.76718
1103.56	9.28718
1106.84	10.0618
1110.11	10.5514
1113.38	11.8381
1116.64	12.1375
1119.91	12.1134
1123.18	11.0328
1126.44	10.111
1129.7	9.52993
1132.97	8.17839
1136.23	7.77136
1139.49	7.18275
1142.74	5.60543
1146	5.16122
1149.26	3.46597
1152.51	3.98639
1155.76	4.66798
1159.01	4.24122
1162.27	4.06851
1165.51	3.43838
1168.76	3.86219
1172.01	4.84335
1175.25	5.4232
1178.5	6.18695
1181.74	6.40347
1184.98	6.89748
1188.22	5.89767
1191.46	6.34633
1194.7	7.48217
1197.94	7.11586
1201.17	6.06763
1204.41	8.29158
1207.64	9.63892
1210.87	10.1881
1214.1	12.4275
1217.33	13.9738
1220.56	16.2676
1223.79	19.8696
1227.01	22.7913
1230.23	27.1024
1233.46	30.7737
1236.68	34.1699
1239.9	34.8011
1243.12	36.6722
1246.34	38.7101
1249.55	40.3367
1252.77	41.8929
1255.98	42.379
1259.2	41.683
1262.41	40.9394
1265.62	40.4944
1268.83	40.4138
1272.03	41.0675
1275.24	41.0988
1278.45	40.9112
1281.65	42.8036
1284.85	42.3129
1288.06	41.103
1291.26	41.7481
1294.46	42.7849
1297.66	44.8532
1300.85	47.297
1304.05	49.3369
1307.24	50.9051
1310.43	51.6396
1313.63	52.332
1316.82	52.699
1320.01	51.5907
1323.2	51.8099
1326.38	51.6282
1329.57	50.7637
1332.76	51.0949
1335.94	49.3991
1339.12	49.6168
1342.3	49.1975
1345.48	49.7132
1348.66	49.7778
1351.84	50.2553
1355.01	48.4153
1358.19	47.2195
1361.36	46.6905
1364.53	45.3911
1367.71	43.9718
1370.88	43.1836
1374.04	42.4377
1377.21	40.9555
1380.38	40.0892
1383.54	37.966
1386.71	36.4045
1389.87	35.1267
1393.03	33.5724
1396.19	30.4484
1399.35	29.8613
1402.51	28.6457
1405.67	27.6417
1408.82	26.9301
1411.98	26.8732
1415.13	28.4636
1418.28	29.1857
1421.43	31.5701
1424.58	34.0503
1427.73	37.1898
1430.88	40.2858
1434.02	42.4721
1437.17	44.7426
1440.31	47.227
1443.45	49.003
1446.6	50.0001
1449.74	50.8321
1452.87	51.9768
1456.01	52.9751
1459.15	53.6076
1462.28	55.1374
1465.42	54.9854
1468.55	52.4904
1471.68	51.9874
1474.81	50.4737
1477.94	48.5088
1481.07	46.5504
1484.2	44.2718
1487.32	40.7555
1490.45	38.4386
1493.57	36.2358
1496.69	34.9131
1499.81	33.5245
1502.93	30.9912
1506.05	29.946
1509.17	27.0732
1512.28	24.1643
1515.4	21.8664
1518.51	19.7991
1521.63	18.278
1524.74	16.1117
1527.85	15.3677
1530.96	14.0628
1534.06	15.3207
1537.17	15.8892
1540.28	15.9112
1543.38	16.425
1546.48	18.8042
1549.59	21.1508
1552.69	22.2652
1555.79	23.5242
1558.88	24.3944
1561.98	24.8097
1565.08	26.3326
1568.17	29.0003
1571.27	30.9034
1574.36	31.9277
1577.45	34.963
1580.54	35.6103
1583.63	36.9749
1586.72	37.1402
1589.8	38.3449
1592.89	38.0304
1595.97	37.7174
1599.06	38.5235
1602.14	37.0528
1605.22	36.9928
1608.3	37.5567
1611.38	37.5346
1614.46	37.9619
1617.53	39.84
1620.61	40.7986
1623.68	41.9612
1626.75	43.9424
1629.82	44.9507
1632.9	45.8606
1635.96	47.0665
1639.03	47.9852
1642.1	50.7818
1645.16	52.884
1648.23	53.9345
1651.29	55.2553
1654.36	56.3123
1657.42	57.3911
1660.48	57.2653
1663.53	57.502
1666.59	55.3715
1669.65	53.8142
1672.7	51.6308
1675.76	48.0928
1678.81	43.5599
1681.86	39.2285
1684.91	34.1992
1687.96	30.7085
1691.01	27.5906
1694.06	25.1853
1697.11	20.9142
1700.15	18.1032
1703.2	14.9921
1706.24	13.0038
1709.28	10.9553
1712.32	9.25509
1715.36	8.52759
1718.4	6.73631
1721.43	5.85626
1724.47	5.49431
1727.5	7.02998
1730.54	6.75106
1733.57	6.74361
1736.6	6.75627
1739.63	6.7407
1742.66	7.19169
1745.69	5.70935
1748.72	5.28117
1751.74	3.92896
1754.77	4.37304
1757.79	3.79149
1760.81	4.03419
1763.83	4.4433
1766.85	4.28785
1769.87	3.6787
1772.89	3.02793
1775.91	2.89738
1778.92	3.06688
1781.94	2.58744
1784.95	2.71967
1787.96	3.00035
1790.97	2.06478
1793.98	2.09888
1796.99	2.44116
1800	3.14378
1803	2.15148
1806.01	2.04914
1809.01	1.47742
1812.02	1.65368
1815.02	2.05917
1818.02	1.17635
1821.02	1.44035
1824.02	2.31925
1827.01	2.047
1830.01	2.60454
1833	2.56849
1836	2.02127
1838.99	1.70911
1841.98	1.44846
1844.97	0.926026
1847.96	0.600208
1850.95	1.18479
1853.94	0.75312
1856.92	0.58291
1859.91	0.863389
1862.89	0.320007
1865.88	-0.00965232
1868.86	0.424299
1871.84	0.724528
1874.82	0.362272
1877.8	0.38437
1880.77	0.0832799
1882.51	-0.086467
1885.5	-0.0488331
1888.48	0.909603
1891.47	0.280167
1894.46	1.34911
1897.44	0.488381
1900.42	0.729057
1903.41	0.502708
1906.39	0.212834
1909.37	0.779124
1912.35	1.0954
1915.32	1.3352
1918.3	1.85679
1921.28	2.37191
1924.25	2.52519
1927.22	3.28199
1930.2	3.85009
1933.17	3.78238
1936.14	3.7785
1939.11	5.07833
1942.08	4.8204
1945.04	4.72368
1948.01	4.50721
1950.97	3.91944
1953.94	4.30605
1956.9	3.71965
1959.86	3.87557
1962.82	3.77845
1965.78	3.73963
1968.74	3.11092
1971.69	2.55642
1974.65	2.04638
1977.61	1.10677
1980.56	1.21328
1983.51	1.53597
1986.46	1.12914
1989.41	1.16912
1992.36	2.17034
1995.31	2.08428
1998.26	2.51969
2001.2	2.06731
2004.15	1.51059
2007.09	2.3912
2010.04	1.51712
2012.98	2.94051
2015.92	2.54288
2018.86	3.00965
2021.8	3.33707
2024.74	4.23228
2027.67	3.90304
2030.61	4.1081
2033.54	5.35891
2036.47	5.52571
2039.41	5.16884
2042.34	6.29691
2045.27	6.43142
2048.2	6.65588
2051.12	6.77326
2054.05	7.16471
2056.98	7.83313
2059.9	9.2161
2062.82	9.94297
2065.75	10.377
2068.67	11.8536
2071.59	12.3012
2074.51	12.4022
2077.43	13.3944
2080.34	14.4531
2083.26	14.2452
2086.17	14.9993
2089.09	14.2617
2092	14.2207
2094.91	14.2735
2097.82	14.2465
2100.73	14.8791
2103.64	16.3694
2106.55	18.5568
2109.46	19.2489
2112.36	21.2159
2115.27	22.4797
2118.17	23.5536
2121.07	26.0438
2123.97	28.1407
2126.87	30.1435
2129.77	32.7881
2132.67	36.4079
2135.57	39.5597
2138.46	43.039
2141.36	46.2699
2144.25	49.766
2147.14	53.0559
2150.03	55.6651
2152.92	57.9822
2155.81	60.2532
2158.7	63.1682
2161.59	64.5819
2164.48	67.8346
2167.36	68.833
2170.25	70.5496
2173.13	71.974
2176.01	72.6473
2178.89	72.6549
2181.77	73.0886
2184.65	72.2042
2187.53	69.9712
2190.41	68.5929
2193.28	65.6907
2196.16	62.6277
2199.03	60.1228
2201.9	57.0665
2204.78	53.5667
2207.65	51.1838
2210.51	48.4358
2213.38	46.4605
2216.25	43.7397
2219.12	39.7986
2221.98	37.016
2224.85	34.7474
2227.71	31.9761
2230.57	29.4238
2233.43	27.2496
2236.29	24.5552
2239.15	22.2953
2242.01	21.4081
2244.87	19.6651
2247.73	18.7904
2250.58	18.3052
2253.43	17.0337
2256.29	14.9452
2259.14	13.9112
2261.99	12.7871
2264.84	12.9504
2267.69	13.2138
2270.54	12.1919
2273.38	11.8693
2276.23	11.8175
2279.07	12.5781
2281.92	11.9321
2284.76	11.5382
2287.6	9.55564
2290.44	8.82359
2293.28	7.84627
2296.12	8.52157
2298.96	8.23719
2301.79	9.0828
2304.63	10.2008
2307.46	10.5711
2310.3	11.7987
2313.13	11.776
2315.96	12.8472
2318.79	12.4069
2321.62	12.0429
2324.45	11.6838
2327.27	11.4513
2330.1	10.7259
2332.93	10.4024
2335.75	10.0657
2338.57	9.08572
2341.4	7.52038
2344.22	6.43144
2347.04	5.47241
2349.86	3.59008
2352.67	1.94547
2355.49	0.350717
2358.31	-0.525248
2361.12	-0.600764
2363.94	-0.294245
2366.75	0.432641
2369.56	1.06403
2372.37	2.36445
2375.18	1.77566
2377.99	2.86157
2380.8	2.67551
2383.61	3.0047
2386.41	2.88492
2389.22	1.54901
2392.02	1.982
2394.82	1.42762
2397.63	2.14466
2400.43	2.28892
2403.23	2.95124
2406.02	2.6032
2408.82	2.87139
2411.62	2.67744
2414.41	2.71823
2417.21	3.29537
2420	3.9906
2422.79	4.44137
2425.59	4.87952
2428.38	4.79701
2431.17	4.52613
2433.96	4.58199
2436.74	4.50626
2439.53	4.94484
2442.32	4.16927
2445.1	3.54222
2447.88	2.47266
2450.67	2.99162
2453.45	1.66263
2456.23	0.679758
2459.01	-0.18113
2461.79	0.426084
2464.57	1.33954
2467.34	2.02038
2470.12	0.778622
2472.89	1.10693
2475.67	1.60129
2478.44	1.83816
2481.21	2.34654
2483.98	3.16999
2486.75	3.38903
2489.52	3.42028
2492.29	3.40025
2495.06	3.39869
2497.82	3.05553
2500.59	3.28071
2503.35	3.0599
2506.11	3.17727
2508.88	2.98067
2511.63	3.49335
2514.39	2.67112
2517.15	3.59225
2519.91	3.0142
2522.67	2.08609
2525.42	2.59931
2528.18	2.78309
2530.93	3.8857
2533.69	3.84534
2536.44	3.67598
2539.19	3.69522
2541.94	4.03827
2544.69	3.9743
2547.44	5.03056
2550.18	5.53028
2552.93	5.41146
2555.68	4.75148
2558.42	4.7635
2561.16	3.54813
2563.9	3.53748
2566.64	3.89124
2569.38	4.04906
2572.12	4.44668
2574.86	4.70458
2577.6	5.10476
2580.34	4.48046
2583.07	4.1219
2585.81	4.02448
2588.54	4.06197
2591.27	4.47535
2594	4.524
2596.73	4.26895
2599.46	3.81044
2602.19	3.77782
2604.92	4.37639
2607.64	4.28563
2610.37	5.1158
2613.09	4.77026
2615.82	4.06485
2618.54	2.86298
2621.26	2.56553
2623.98	2.0301
2626.7	1.65653
2629.42	0.77803
2632.14	1.02323
2634.86	0.577023
2637.57	0.105832
2640.29	-0.0121351
2643	0.057173
2645.72	0.341965
2648.43	1.21699
2651.14	1.69111
2653.85	2.28131
2656.56	2.68096
2659.27	3.15303
2661.97	3.69846
2664.68	5.09311
2667.38	5.76495
2670.09	6.27784
2672.79	6.50984
2675.49	6.45498
2678.2	6.90189
2680.89	6.18075
2683.59	6.01851
2686.29	5.59123
2688.99	4.90289
2691.69	5.47036
2694.38	4.4047
2697.08	4.45885
2699.77	4.53114
2702.46	3.85274
2705.16	4.15343
2707.85	4.77106
2710.54	4.28373
2713.23	4.33996
2715.92	5.41809
2718.6	5.65969
2721.29	5.81107
2723.97	5.59142
2726.66	6.30372
2729.34	7.32011
2732.02	7.20652
2734.7	7.37081
2737.39	7.4327
2740.06	7.84329
2742.74	7.31011
2745.42	7.05114
2748.1	6.1205
2750.77	5.50533
2753.45	5.27564
2756.12	5.48919
2758.79	4.64328
2761.47	4.59436
2764.14	4.66317
2766.81	3.65398
2769.48	3.86767
2772.14	3.15295
2774.81	3.24667
2777.48	2.47579
2780.14	3.06394
2782.81	2.99408
2785.47	2.34445
2788.13	1.87967
2790.79	1.9023
2793.46	2.34478
2796.11	2.19564
2798.77	1.28619
2801.43	1.08117
2804.09	0.577739
2806.74	0.312294
2809.4	-0.115932
2812.05	-0.0555113
2814.71	-0.633595
2817.36	0.471199
2820.01	1.49516
2822.66	3.51376
2825.31	5.05361
2827.96	7.68614
2830.61	10.1103
2833.25	12.4004
2835.9	14.9563
2838.54	18.3754
2841.18	22.6534
2843.83	26.8464
2846.47	31.6115
2849.11	37.404
2851.75	42.0712
2854.39	47.1764
2857.03	53.3695
2859.67	58.4325
2862.3	63.9031
2864.94	68.9255
2867.57	73.4628
2870.21	77.416
2872.84	80.8771
2875.47	84.5149
2878.1	88.598
2880.73	92.2883
2883.36	94.9312
2885.99	97.8756
2888.61	101.438
2891.24	105.231
2893.87	109.604
2896.49	114.294
2899.11	120.183
2901.74	127.725
2904.36	135.893
2906.98	144.697
2909.6	154.268
2912.22	165.05
2914.83	174.637
2917.45	183.448
2920.07	192.801
2922.68	200.811
2925.3	207.178
2927.91	210.787
2930.52	213.697
2933.13	214.895
2935.74	214.091
2938.35	211.555
2940.96	208.531
2943.57	202.718
2946.18	196.278
2948.78	188.763
2951.39	182.235
2953.99	174.775
2956.6	166.136
2959.2	158.115
2961.8	149.758
2964.4	141.813
2967	133.54
2969.6	125.413
2972.2	118.066
2974.79	111.232
2977.39	103.025
2979.98	95.5079
2982.58	87.3619
2985.17	80.2383
2987.76	72.7959
2990.36	65.375
2992.95	57.9944
2995.54	51.4359
2998.12	44.3097
3000.71	39.2783
3003.3	33.9618
3005.88	29.6147
3008.47	25.1275
3011.05	21.3841
3013.64	18.7735
3016.22	17.5342
3018.8	14.6529
3021.38	11.9249
3023.96	10.0194
3026.54	8.60727
3029.12	8.81474
3031.69	7.69345
3034.27	7.48351
3036.85	6.95449
3039.42	5.60491
3041.99	5.2677
3044.57	6.05131
3047.14	6.63212
3049.71	7.52111
3052.28	7.58277
3054.85	7.76026
3057.42	8.12443
3059.98	8.38913
3062.55	8.8604
3065.11	8.62064
3067.68	7.97674
3070.24	7.29126
3072.8	6.71303
3075.37	5.90548
3077.93	6.27057
3080.49	4.67867
3083.05	3.21313
3085.61	2.47839
3088.16	1.7204
3090.72	1.81319
3093.27	1.28966
3095.83	0.968507
3098.38	-0.455625
3100.94	-0.882412
3103.49	-1.20482
3106.04	-0.0902765
3108.59	-0.071871
3111.14	0.138076
3113.69	0.109693
3116.23	1.11555
3118.78	1.91163
3121.33	2.17604
3123.87	2.99038
3126.42	3.72045
3128.96	4.39799
3131.5	5.23669
3134.04	6.17939
3136.58	7.43544
3139.12	8.74052
3141.66	10.4926
3144.2	12.3265
3146.74	14.3026
3149.27	16.8822