File: data/Raman/poly_smoothed/Mb_30_27_48_1x_45s_532 nm_x100_100%_600 gr_mm_01.txt
#Acq. time (s)=	45
#Accumulations=	2
#Range (cm-¹)=	200...3150
#Windows=	2
#Auto scanning=	Off
#Autofocus=	Off
#Macrospot=	Off
#AutoExposure=	Off
#Spike filter=	Multiple accum.
#Delay time (s)=	0
#Binning=	1
#Readout mode=	Signal
#DeNoise=	Off
#ICS correction=	On
#Dark correction=	Off
#Inst. Process=	Off
#Detector Gain=	Best Dynamic Range
#Detector ADC=	20 kHz
#Detector temperature (°C)=	-69.85
#Instrument=	LabRAM HR Evol
#Detector=	Synapse
#Objective=	x100
#Grating=	600 gr/mm
#ND Filter=	100%
#Laser (nm)=	532
#Hole=	100.021
#Range=	Auto
#Laser Pol.=	No
#Raman. Pol.=	No
#Laser Pol. (°)=	-0.0007625
#Raman Pol. (°)=	89.9995
#Collection=	Microscope
#StageXY=	Marzhauser
#StageZ=	Marzhauser
#X (µm)=	-6375.1
#Y (µm)=	725.6
#Z (µm)=	-64.85
#Full time(mm:ss)=	3:19
#Project=
#Sample=
#Site=
#Title=	Mb_30_27_48_2x_45s_532 nm_x100_100%_600 gr_mm
#Remark=
#Date=	13.07.2022 12:24
#Acquired=	13.07.2022 12:24:10
#Base:Fit=	10.08.2022 10:40:03
#Base:Sub=	10.08.2022 10:40:17
#Filter:Polynom=	16.08.2022 10:16:15
#AxisType[0]=Intens
#AxisUnit[0]=Cnt
#AxisType[1]=Spectr
#AxisUnit[1]=1/cm
200.563	3.36453
204.194	8.73216
207.821	9.87246
211.449	10.1319
215.074	9.61162
218.699	9.51907
222.321	8.29013
225.941	7.7961
229.562	8.43007
233.18	7.76156
236.796	7.70158
240.411	5.86918
244.026	7.23582
247.638	6.15306
251.248	5.34163
254.857	4.87096
258.465	5.54258
262.071	7.0984
265.678	8.48094
269.282	10.4189
272.884	11.176
276.484	12.2219
280.084	12.7435
283.682	12.9436
287.276	12.1664
290.871	11.539
294.465	10.3703
298.057	10.5852
301.648	10.3914
305.237	10.9323
308.823	10.1469
312.41	11.1218
315.995	10.9765
319.579	10.5789
323.16	9.16608
326.741	9.21527
330.321	8.82584
333.897	8.04716
337.474	8.09891
341.048	7.6196
344.622	8.25265
348.192	8.62064
351.764	8.38062
355.332	7.23772
358.901	5.67229
362.466	4.07862
366.03	5.41473
369.594	4.98966
373.155	5.25843
376.715	3.90745
380.273	3.74322
383.832	4.66478
387.388	5.35151
390.942	6.37904
394.495	6.83277
398.047	7.95705
401.597	6.64109
405.145	6.50812
408.693	7.75938
412.239	7.89706
415.783	7.66876
419.327	6.92431
422.869	6.89428
426.409	6.87192
429.948	5.25102
433.486	5.5529
437.022	4.1425
440.558	2.37783
444.089	1.7183
447.622	2.05316
451.153	1.74911
454.682	2.47251
458.208	3.25518
461.735	2.50367
465.259	3.16883
468.783	4.17598
472.306	4.98729
475.825	5.52841
479.346	6.2049
482.862	6.85028
486.38	7.02167
489.894	8.2486
493.407	9.09042
496.92	10.4039
500.43	10.2783
503.939	10.3757
507.448	9.76922
510.954	9.88113
514.459	10.4611
517.962	9.89255
521.466	9.26947
524.966	8.7278
528.466	8.99432
531.964	9.42373
535.46	9.17379
538.955	8.25934
542.449	8.37847
545.942	7.59445
549.433	8.74804
552.923	8.71148
556.412	7.72668
559.899	9.12169
563.385	10.4394
566.867	11.2057
570.35	10.3551
573.832	10.9764
577.313	11.0383
580.79	9.9756
584.268	9.83561
587.745	9.10096
591.218	9.19633
594.692	9.51292
598.164	9.16599
601.634	8.98892
605.104	7.77981
608.57	7.64721
612.037	9.54095
615.501	9.42123
618.966	9.46241
622.427	9.87031
625.887	10.2919
629.348	10.91
632.806	12.6625
636.262	13.0281
639.716	13.6288
643.172	15.2227
646.624	18.2766
650.075	18.8924
653.524	20.3236
656.972	20.9276
660.419	21.4138
663.865	22.1251
667.309	23.3505
670.752	25.0881
674.194	26.1369
677.634	28.6359
681.073	29.7773
684.511	30.6925
687.947	32.8232
691.382	35.4741
694.816	36.6886
698.247	38.1129
701.678	38.8975
705.108	40.0215
708.534	41.9279
711.962	42.2167
715.388	42.5932
718.81	44.1849
722.234	45.7711
725.654	46.3523
729.075	47.5709
732.492	49.2596
735.91	49.1444
739.325	50.0673
742.741	51.5493
746.153	52.6235
749.564	54.352
752.976	56.1391
756.385	58.3771
759.792	62.7901
763.2	65.9678
766.604	69.5986
770.008	74.046
773.41	77.3073
776.811	80.3512
780.21	81.7734
783.608	83.8729
787.005	86.7268
790.401	88.0697
793.795	89.3991
797.188	90.4443
800.58	91.0305
803.971	91.5638
807.36	91.7988
810.748	90.8936
814.135	91.1565
817.518	89.961
820.902	90.245
824.285	89.7908
827.665	88.3933
831.045	86.8053
834.424	84.6636
837.8	84.176
841.177	83.2429
844.55	81.7111
847.924	79.5583
851.295	78.4467
854.666	77.0448
858.034	74.3152
861.403	72.5207
864.769	69.4086
868.133	68.8959
871.498	66.0296
874.86	64.1274
878.221	64.6397
881.58	63.2203
884.938	62.391
888.297	61.696
891.653	62.7487
895.007	61.9603
898.36	62.7399
901.712	63.3529
905.063	63.3278
908.412	62.5335
911.76	61.8125
915.107	61.5116
918.452	60.3131
921.797	59.6165
925.138	57.4616
928.48	57.2902
931.82	55.6778
935.16	54.0965
938.496	53.0383
941.833	51.6294
945.168	51.1383
948.5	51.0732
951.834	50.4441
955.163	48.4166
958.494	47.3287
961.821	46.2458
965.15	45.6571
968.474	44.2383
971.8	44.6678
975.123	42.5224
978.446	42.5105
981.766	41.4333
985.084	40.8077
988.402	39.2168
991.72	38.0394
995.035	36.1626
998.349	34.6326
1001.66	32.6081
1004.97	31.4319
1008.28	31.8853
1011.59	33.2058
1014.9	33.0467
1018.21	34.399
1021.51	35.673
1024.81	35.7162
1028.12	37.5764
1031.42	38.521
1034.72	37.0576
1038.02	36.9064
1041.31	37.4496
1044.61	37.9639
1047.91	36.2292
1051.2	35.3232
1054.49	35.1539
1057.78	35.5681
1061.07	34.8518
1064.36	33.1987
1067.65	31.034
1070.93	28.6164
1074.22	26.9399
1077.5	24.3017
1080.78	22.3013
1084.06	22.0179
1087.34	21.6756
1090.62	23.0002
1093.9	22.6083
1097.17	21.7014
1100.45	21.3687
1103.72	20.8698
1106.99	21.3214
1110.27	21.6385
1113.53	18.9595
1116.8	18.7331
1120.07	18.0121
1123.33	18.4467
1126.6	18.0261
1129.86	18.4595
1133.12	19.2372
1136.38	19.3855
1139.64	19.122
1142.9	17.7123
1146.16	17.1959
1149.41	16.2827
1152.67	15.9651
1155.92	15.5072
1159.17	15.0223
1162.42	14.6849
1165.67	13.2898
1168.92	13.2942
1172.16	11.8797
1175.41	11.2796
1178.65	9.70158
1181.9	9.05881
1185.14	9.59299
1188.38	10.7719
1191.62	9.36268
1194.86	9.33565
1198.09	9.93095
1201.33	10.4959
1204.56	12.0114
1207.8	13.6934
1211.03	15.5853
1214.26	15.7354
1217.49	17.4405
1220.71	18.2636
1223.94	19.9229
1227.16	22.2012
1230.39	23.8313
1233.61	27.7412
1236.83	29.5414
1240.05	30.6467
1243.27	30.009
1246.49	30.1939
1249.71	30.493
1252.92	30.6552
1256.14	30.0355
1259.35	31.0086
1262.56	31.1785
1265.77	30.6358
1268.98	29.1397
1272.19	28.4358
1275.4	29.6204
1278.6	28.778
1281.81	29.8821
1285.01	31.5781
1288.21	32.8307
1291.41	32.3441
1294.61	32.9065
1297.81	33.6429
1301.01	34.1868
1304.2	35.8622
1307.4	37.6051
1310.59	39.9071
1313.78	40.7761
1316.97	40.0298
1320.16	40.5414
1323.35	39.905
1326.54	40.0719
1329.72	39.5277
1332.91	37.5804
1336.09	36.7308
1339.27	36.87
1342.45	36.0633
1345.64	35.6531
1348.81	34.5749
1351.99	33.6069
1355.17	32.6194
1358.34	31.624
1361.51	30.5814
1364.69	29.6633
1367.86	27.9736
1371.03	26.219
1374.2	24.4639
1377.37	23.0075
1380.53	21.8145
1383.7	21.5366
1386.86	22.2841
1390.02	22.1864
1393.19	21.2402
1396.35	21.2132
1399.51	20.9024
1402.66	19.7373
1405.82	21.5762
1408.97	20.4075
1412.13	20.1331
1415.28	22.0254
1418.43	23.7267
1421.59	24.6314
1424.73	26.2705
1427.88	26.4238
1431.03	28.1414
1434.18	29.4448
1437.32	31.3964
1440.46	33.4366
1443.61	33.528
1446.75	33.2374
1449.89	32.8772
1453.03	32.2916
1456.16	33.3854
1459.3	32.43
1462.44	32.8991
1465.57	31.9478
1468.7	30.8682
1471.83	28.5821
1474.96	28.2997
1478.09	27.0952
1481.22	25.9259
1484.35	24.5355
1487.47	22.2615
1490.6	22.6596
1493.72	21.6243
1496.84	21.6457
1499.96	19.9139
1503.08	19.0104
1506.2	18.53
1509.32	18.4216
1512.44	17.8037
1515.55	17.4058
1518.66	15.8573
1521.78	12.9785
1524.89	11.4956
1528	10.2309
1531.11	9.54373
1534.21	8.41836
1537.32	7.58618
1540.43	6.85155
1543.53	7.44596
1546.63	8.65208
1549.74	9.14214
1552.84	10.4834
1555.94	12.1939
1559.03	12.6949
1562.13	13.8445
1565.23	15.889
1568.32	17.0149
1571.42	19.3911
1574.51	21.7369
1577.6	23.9093
1580.69	25.5409
1583.78	26.4074
1586.87	28.7451
1589.95	28.8393
1593.04	29.2307
1596.12	29.992
1599.21	29.6962
1602.29	28.3844
1605.37	27.0444
1608.45	26.9693
1611.53	26.3601
1614.6	27.0281
1617.68	27.8867
1620.75	27.3551
1623.83	27.2306
1626.9	28.318
1629.97	28.031
1633.04	28.5489
1636.11	27.9679
1639.18	30.0063
1642.25	29.992
1645.31	30.1875
1648.38	31.9249
1651.44	32.3012
1654.5	32.5103
1657.56	32.8736
1660.62	32.4663
1663.68	32.0329
1666.74	29.2527
1669.8	28.0636
1672.85	26.6291
1675.91	23.4475
1678.96	21.6774
1682.01	20.1069
1685.06	18.2135
1688.11	16.3795
1691.16	15.3143
1694.21	13.7656
1697.25	12.4171
1700.3	11.2037
1703.34	10.4019
1706.39	9.69337
1709.43	9.07006
1712.47	8.27705
1715.51	7.11037
1718.54	6.9705
1721.58	8.20553
1724.62	8.42457
1727.65	8.95152
1730.68	8.71468
1733.72	8.01204
1736.75	7.92274
1739.78	6.71155
1742.81	6.02339
1745.84	5.75665
1748.86	4.77096
1751.89	3.99361
1754.91	3.04965
1757.93	2.06459
1760.96	2.48912
1763.98	2.16546
1767	2.47816
1770.02	2.53348
1773.03	2.49861
1776.05	2.97747
1779.07	3.36775
1782.08	3.08427
1785.09	3.39582
1788.11	4.20946
1791.12	4.92261
1794.13	5.83521
1797.13	5.52962
1800.14	6.40616
1803.15	6.34876
1806.15	5.66264
1809.16	5.89243
1812.16	5.20001
1815.16	5.21115
1818.16	4.90217
1821.16	4.5655
1824.16	5.39913
1827.16	5.21148
1830.16	4.71887
1833.15	5.49723
1836.14	5.61625
1839.14	5.18055
1842.13	4.69195
1845.12	5.03874
1848.11	4.8783
1851.1	4.86572
1854.08	4.13004
1857.07	4.26688
1860.05	4.85899
1863.04	4.2868
1866.02	3.28526
1869	2.67145
1871.98	2.67597
1874.96	2.27668
1877.94	1.10473
1880.92	0.0230018
1882.51	0.225661
1885.5	0.00316009
1888.48	0.274825
1891.47	-0.256922
1894.46	0.337869
1897.44	0.457475
1900.42	0.852178
1903.41	0.846116
1906.39	1.32011
1909.37	1.63618
1912.35	2.22327
1915.32	2.5537
1918.3	2.8366
1921.27	3.47947
1924.25	4.44582
1927.22	4.92175
1930.19	4.93219
1933.17	4.47035
1936.14	4.02362
1939.11	2.94866
1942.07	3.01716
1945.04	3.51903
1948.01	2.56256
1950.97	2.26662
1953.93	1.53767
1956.9	1.49365
1959.86	1.05368
1962.82	0.604287
1965.78	0.694578
1968.74	1.25227
1971.69	0.99645
1974.65	0.789126
1977.6	0.587598
1980.56	0.321773
1983.51	0.792984
1986.46	0.467718
1989.41	0.320125
1992.36	1.65545
1995.31	1.67016
1998.26	1.33907
2001.2	1.07629
2004.15	1.44484
2007.09	1.28521
2010.04	1.70281
2012.98	2.25871
2015.92	2.09204
2018.86	2.40656
2021.8	2.51953
2024.73	2.48171
2027.67	2.64107
2030.61	2.83986
2033.54	3.37713
2036.47	4.43345
2039.4	4.81414
2042.33	4.94134
2045.27	4.91383
2048.19	5.11152
2051.12	5.69302
2054.05	5.93835
2056.97	7.14742
2059.9	7.78915
2062.82	8.62751
2065.74	9.70497
2068.67	10.2895
2071.59	11.2139
2074.51	11.3983
2077.42	11.5815
2080.34	11.9165
2083.26	12.2693
2086.17	12.0048
2089.09	12.172
2092	12.5628
2094.91	12.125
2097.82	12.2773
2100.73	12.8954
2103.64	13.5562
2106.55	14.1764
2109.45	14.4201
2112.36	14.6662
2115.26	14.7354
2118.17	15.7247
2121.07	16.8351
2123.97	17.5636
2126.87	19.1718
2129.77	19.9346
2132.67	21.5481
2135.56	23.3201
2138.46	26.1447
2141.35	27.6675
2144.25	27.7816
2147.14	28.6806
2150.03	29.7025
2152.92	30.3
2155.81	31.3951
2158.7	32.6361
2161.59	32.9131
2164.47	33.4409
2167.36	33.9316
2170.24	34.7485
2173.13	34.9864
2176.01	35.4977
2178.89	34.7303
2181.77	34.0293
2184.65	32.6359
2187.53	32.0572
2190.4	31.6576
2193.28	30.8258
2196.16	29.9877
2199.03	28.8137
2201.9	28.7904
2204.77	27.3813
2207.64	25.7255
2210.51	24.3899
2213.38	21.4113
2216.25	19.6987
2219.12	18.6264
2221.98	16.6071
2224.85	15.6532
2227.71	15.7003
2230.57	14.27
2233.43	13.2177
2236.29	12.3464
2239.15	11.8496
2242.01	10.6995
2244.87	10.4063
2247.72	9.46642
2250.58	8.6291
2253.43	8.90504
2256.29	9.38691
2259.14	8.58805
2261.99	9.27232
2264.84	10.0699
2267.69	9.47626
2270.53	9.47404
2273.38	9.44904
2276.23	9.45741
2279.07	9.39664
2281.91	8.58855
2284.76	8.60011
2287.6	8.93068
2290.44	7.61577
2293.28	6.57083
2296.12	7.29309
2298.96	7.93467
2301.79	8.03305
2304.63	8.30052
2307.46	8.25637
2310.3	8.1764
2313.13	8.59553
2315.96	8.5119
2318.79	8.70647
2321.62	9.01558
2324.45	8.49334
2327.27	8.92328
2330.1	8.85124
2332.92	8.78731
2335.75	7.17789
2338.57	6.71484
2341.39	6.00551
2344.21	5.37869
2347.04	4.34628
2349.85	3.42919
2352.67	2.29707
2355.49	2.14152
2358.3	0.929438
2361.12	0.319605
2363.93	1.17211
2366.75	3.16188
2369.56	3.15579
2372.37	4.36211
2375.18	4.6134
2377.99	5.57585
2380.8	5.90282
2383.6	6.17794
2386.41	6.26767
2389.21	6.24115
2392.02	5.95465
2394.82	6.07952
2397.62	6.34512
2400.42	5.74714
2403.22	5.41466
2406.02	4.92621
2408.82	4.71656
2411.62	5.31655
2414.41	4.65214
2417.21	4.85977
2420	5.17816
2422.79	5.16216
2425.59	5.71264
2428.38	5.85607
2431.17	6.12027
2433.95	6.133
2436.74	6.48412
2439.53	6.15178
2442.31	5.70513
2445.1	5.46443
2447.88	4.39976
2450.67	3.22791
2453.45	2.69574
2456.23	1.72943
2459.01	1.42753
2461.79	1.14154
2464.57	1.44563
2467.34	1.31118
2470.12	0.69209
2472.89	0.88134
2475.67	1.24673
2478.44	1.8485
2481.21	1.92943
2483.98	2.48086
2486.75	3.18802
2489.52	3.87167
2492.29	3.77574
2495.05	4.21846
2497.82	4.16049
2500.58	3.48306
2503.35	3.28197
2506.11	2.6327
2508.87	2.92652
2511.63	2.56839
2514.39	1.88463
2517.15	1.16947
2519.91	0.996401
2522.67	0.861032
2525.42	0.276338
2528.18	0.745902
2530.93	1.0483
2533.69	1.51019
2536.44	1.42298
2539.19	2.58924
2541.94	3.65957
2544.69	4.02245
2547.44	4.70356
2550.18	4.82695
2552.93	5.22325
2555.67	4.97697
2558.42	4.94411
2561.16	4.95179
2563.9	4.99031
2566.64	4.68475
2569.38	4.01916
2572.12	4.88384
2574.86	5.09637
2577.6	4.39421
2580.33	4.2104
2583.07	3.69112
2585.8	3.00837
2588.54	2.1288
2591.27	1.7981
2594	1.7989
2596.73	1.4845
2599.46	1.3807
2602.19	0.906848
2604.92	1.10169
2607.64	1.07982
2610.37	0.268102
2613.09	0.792064
2615.82	0.914808
2618.54	0.75733
2621.26	0.758283
2623.98	1.50372
2626.7	2.59901
2629.42	2.8664
2632.14	2.84874
2634.86	2.88021
2637.57	3.89793
2640.29	5.13224
2643	5.78148
2645.71	6.20859
2648.43	4.94947
2651.14	4.94194
2653.85	4.49496
2656.56	4.66499
2659.26	4.48598
2661.97	4.23622
2664.68	4.1885
2667.38	4.16927
2670.09	3.93956
2672.79	3.81951
2675.49	3.13342
2678.19	3.21378
2680.89	3.85334
2683.59	4.00306
2686.29	3.80437
2688.99	4.26639
2691.69	4.10105
2694.38	3.92773
2697.08	3.96761
2699.77	4.48307
2702.46	5.38871
2705.15	5.96651
2707.85	6.02313
2710.54	6.21224
2713.22	5.13809
2715.91	5.97637
2718.6	7.46681
2721.29	8.1751
2723.97	8.61359
2726.66	8.3791
2729.34	8.33985
2732.02	8.05243
2734.7	7.94956
2737.38	6.90585
2740.06	6.25944
2742.74	5.85962
2745.42	5.87641
2748.09	5.75333
2750.77	5.59311
2753.45	4.83638
2756.12	5.06483
2758.79	4.94824
2761.46	5.02642
2764.14	5.35608
2766.8	5.18691
2769.47	4.68556
2772.14	3.72875
2774.81	3.81299
2777.48	3.51327
2780.14	3.86323
2782.8	4.82708
2785.47	5.16513
2788.13	4.81442
2790.79	3.73109
2793.45	3.88225
2796.11	3.57704
2798.77	4.06855
2801.43	3.04125
2804.09	2.37046
2806.74	2.48743
2809.4	2.16692
2812.05	1.60875
2814.71	1.90559
2817.36	2.47692
2820.01	4.01526
2822.66	5.64079
2825.31	6.27203
2827.96	7.02576
2830.6	7.95595
2833.25	8.74067
2835.9	9.69288
2838.54	11.958
2841.18	14.4359
2843.83	17.1913
2846.47	20.3116
2849.11	23.5406
2851.75	25.9285
2854.39	28.2069
2857.03	30.8405
2859.66	33.7468
2862.3	37.0333
2864.94	38.8865
2867.57	40.2233
2870.2	42.3209
2872.84	44.1272
2875.47	45.3734
2878.1	47.5602
2880.73	49.7249
2883.36	51.825
2885.99	53.0693
2888.61	54.3408
2891.24	55.7235
2893.86	57.5536
2896.49	60.2015
2899.11	63.0086
2901.73	66.088
2904.36	69.9747
2906.98	73.4986
2909.6	77.3918
2912.21	81.8983
2914.83	86.2581
2917.45	90.3962
2920.07	94.8315
2922.68	98.6603
2925.29	102.135
2927.91	104.604
2930.52	105.834
2933.13	106.937
2935.74	107.208
2938.35	106.673
2940.96	104.543
2943.57	102.297
2946.18	98.8674
2948.78	94.7042
2951.39	90.5477
2953.99	86.5435
2956.59	83.3425
2959.2	79.6379
2961.8	74.8227
2964.4	70.086
2967	65.84
2969.6	62.2
2972.19	58.9755
2974.79	56.0949
2977.39	52.5573
2979.98	49.083
2982.58	45.062
2985.17	42.5398
2987.76	39.5555
2990.35	36.9571
2992.94	33.7392
2995.53	30.9165
2998.12	28.6776
3000.71	25.75
3003.3	22.6885
3005.88	19.9506
3008.47	18.0754
3011.05	16.3444
3013.64	15.0118
3016.22	13.8362
3018.8	13.0008
3021.38	11.8355
3023.96	10.9957
3026.54	9.464
3029.12	8.83916
3031.69	8.82021
3034.27	8.79036
3036.84	8.71033
3039.42	8.47413
3041.99	7.66362
3044.57	7.15888
3047.14	6.92983
3049.71	6.91578
3052.28	5.784
3054.85	5.35248
3057.41	5.28606
3059.98	4.83134
3062.55	4.80951
3065.11	4.3732
3067.68	4.0798
3070.24	4.0227
3072.8	3.62318
3075.36	3.18295
3077.93	2.54446
3080.49	2.12846
3083.04	2.37654
3085.6	2.44331
3088.16	2.15278
3090.72	1.73471
3093.27	1.76181
3095.83	1.78182
3098.38	1.8229
3100.93	1.5041
3103.49	1.64097
3106.04	1.31065
3108.59	0.827566
3111.14	1.04479
3113.69	0.799194
3116.23	0.676083
3118.78	1.19816
3121.33	1.60307
3123.87	1.62903
3126.41	2.49044
3128.96	2.93425
3131.5	2.97092
3134.04	3.51312
3136.58	4.57443
3139.12	5.1197
3141.66	6.03608
3144.2	6.81073
3146.74	7.20827
3149.27	9.37181