File: data/Raman/poly_smoothed/Mb_30_27_46_1x_45s_532 nm_x100_100%_600 gr_mm_01.txt
#Acq. time (s)=	45
#Accumulations=	2
#Range (cm-¹)=	200...3150
#Windows=	2
#Auto scanning=	Off
#Autofocus=	Off
#Macrospot=	Off
#AutoExposure=	Off
#Spike filter=	Multiple accum.
#Delay time (s)=	0
#Binning=	1
#Readout mode=	Signal
#DeNoise=	Off
#ICS correction=	On
#Dark correction=	Off
#Inst. Process=	Off
#Detector Gain=	Best Dynamic Range
#Detector ADC=	20 kHz
#Detector temperature (°C)=	-69.85
#Instrument=	LabRAM HR Evol
#Detector=	Synapse
#Objective=	x100
#Grating=	600 gr/mm
#ND Filter=	100%
#Laser (nm)=	532
#Hole=	100.021
#Range=	Auto
#Laser Pol.=	No
#Raman. Pol.=	No
#Laser Pol. (°)=	-0.0007625
#Raman Pol. (°)=	89.9995
#Collection=	Microscope
#StageXY=	Marzhauser
#StageZ=	Marzhauser
#X (µm)=	-6379
#Y (µm)=	778.3
#Z (µm)=	-65.15
#Full time(mm:ss)=	3:18
#Project=
#Sample=
#Site=
#Title=	Mb_30_27_46_2x_45s_532 nm_x100_100%_600 gr_mm
#Remark=
#Date=	13.07.2022 12:13
#Acquired=	13.07.2022 12:13:57
#Base:Fit=	10.08.2022 10:40:03
#Base:Sub=	10.08.2022 10:40:17
#Filter:Polynom=	16.08.2022 10:16:15
#AxisType[0]=Intens
#AxisUnit[0]=Cnt
#AxisType[1]=Spectr
#AxisUnit[1]=1/cm
200.563	44.0522
204.194	33.4757
207.821	26.085
211.449	21.1508
215.074	17.5984
218.699	15.7683
222.321	13.0636
225.941	11.4745
229.562	10.2946
233.18	11.1879
236.796	10.9894
240.411	10.4075
244.026	8.82451
247.638	8.74059
251.248	10.1581
254.857	10.6062
258.465	10.0283
262.071	10.3341
265.678	9.24437
269.282	9.32716
272.884	8.01668
276.484	7.69557
280.084	7.53884
283.682	4.85646
287.276	3.64494
290.871	4.00924
294.465	4.6197
298.057	5.1985
301.648	4.92032
305.237	5.15069
308.823	6.37776
312.41	6.11475
315.995	6.40432
319.579	7.84566
323.16	9.04399
326.741	8.95978
330.321	8.04918
333.897	7.62804
337.474	9.79092
341.048	9.87454
344.622	8.24937
348.192	8.4649
351.764	8.41233
355.332	7.58666
358.901	7.01537
362.466	6.51547
366.03	4.09931
369.594	4.20948
373.155	3.8732
376.715	5.32548
380.273	4.57028
383.832	5.27869
387.388	5.00536
390.942	5.81023
394.495	7.38321
398.047	8.00453
401.597	6.84042
405.145	6.63134
408.693	7.90223
412.239	8.7886
415.783	9.07699
419.327	8.12646
422.869	8.16065
426.409	9.5162
429.948	9.4412
433.486	8.91959
437.022	8.67833
440.558	7.63371
444.089	5.97301
447.622	5.49114
451.153	5.83988
454.682	7.71753
458.208	8.87928
461.735	8.90216
465.259	8.50767
468.783	7.98023
472.306	8.5846
475.825	9.18615
479.346	9.9114
482.862	10.4591
486.38	9.27796
489.894	10.0339
493.407	9.7668
496.92	10.6519
500.43	12.6819
503.939	11.8161
507.448	11.3452
510.954	12.5431
514.459	13.9574
517.962	13.4625
521.466	13.4886
524.966	13.2752
528.466	14.5565
531.964	13.3898
535.46	14.8624
538.955	15.4826
542.449	15.21
545.942	14.2464
549.433	12.1476
552.923	11.5151
556.412	11.8194
559.899	11.0523
563.385	9.62844
566.867	8.66149
570.35	7.43544
573.832	6.0547
577.313	5.43002
580.79	5.12557
584.268	4.71302
587.745	2.93147
591.218	1.88673
594.692	0.654866
598.164	1.51687
601.634	0.543324
605.104	1.2499
608.57	2.0335
612.037	3.10496
615.501	4.55516
618.966	5.18593
622.427	7.00376
625.887	7.69726
629.348	7.87922
632.806	9.23728
636.262	12.0786
639.716	15.8902
643.172	17.3392
646.624	19.6589
650.075	19.4692
653.524	20.3937
656.972	22.8463
660.419	24.3077
663.865	26.3383
667.309	26.589
670.752	26.5636
674.194	27.0845
677.634	28.9263
681.073	30.3683
684.511	32.1342
687.947	33.3451
691.382	36.5913
694.816	36.9451
698.247	37.8448
701.678	38.8356
705.108	39.707
708.534	41.8555
711.962	42.9337
715.388	43.9064
718.81	44.9894
722.234	45.7546
725.654	46.4491
729.075	45.2817
732.492	47.0462
735.91	46.0323
739.325	48.704
742.741	48.5132
746.153	49.888
749.564	52.8856
752.976	54.7302
756.385	57.2765
759.792	59.5637
763.2	61.8114
766.604	64.1571
770.008	66.013
773.41	67.776
776.811	69.5546
780.21	72.8454
783.608	75.6563
787.005	77.587
790.401	80.3817
793.795	82.6211
797.188	82.3924
800.58	84.1584
803.971	85.9266
807.36	87.6146
810.748	86.977
814.135	87.8353
817.518	86.3162
820.902	86.1137
824.285	85.4678
827.665	84.1468
831.045	85.5805
834.424	85.1607
837.8	82.8534
841.177	81.8934
844.55	80.4865
847.924	78.2196
851.295	76.4918
854.666	73.1236
858.034	73.0194
861.403	70.4977
864.769	69.6023
868.133	68.5233
871.498	67.6147
874.86	67.1831
878.221	64.7039
881.58	63.2477
884.938	62.4182
888.297	60.0362
891.653	57.3527
895.007	55.7057
898.36	53.6802
901.712	53.1265
905.063	51.5414
908.412	50.263
911.76	50.1505
915.107	50.9871
918.452	49.151
921.797	51.0673
925.138	50.835
928.48	49.5245
931.82	48.2594
935.16	45.9967
938.496	45.3907
941.833	46.352
945.168	45.4695
948.5	44.5415
951.834	44.5061
955.163	43.2454
958.494	39.8678
961.821	38.6025
965.15	37.8636
968.474	37.3501
971.8	36.3215
975.123	37.6025
978.446	36.5764
981.766	35.9855
985.084	35.9432
988.402	33.9422
991.72	34.5848
995.035	34.1447
998.349	32.8681
1001.66	33.0894
1004.97	30.9602
1008.28	31.8074
1011.59	32.4676
1014.9	33.4799
1018.21	35.9929
1021.51	37.4304
1024.81	38.6802
1028.12	38.7784
1031.42	39.7135
1034.72	40.6826
1038.02	40.539
1041.31	41.6621
1044.61	42.4954
1047.91	42.795
1051.2	43.5822
1054.49	41.8855
1057.78	41.8187
1061.07	40.6391
1064.36	39.4962
1067.65	38.2582
1070.93	36.2115
1074.22	34.6107
1077.5	32.4992
1080.78	30.4883
1084.06	30.3037
1087.34	30.9027
1090.62	31.4857
1093.9	32.6251
1097.17	32.5886
1100.45	32.5313
1103.72	32.1823
1106.99	32.5716
1110.27	30.3166
1113.53	29.587
1116.8	30.1094
1120.07	29.1144
1123.33	28.7315
1126.6	27.2312
1129.86	25.2722
1133.12	23.1094
1136.38	21.4454
1139.64	19.5777
1142.9	16.7528
1146.16	13.8419
1149.41	12.0464
1152.67	10.4543
1155.92	9.29916
1159.17	8.07504
1162.42	6.72326
1165.67	8.15125
1168.92	7.68146
1172.16	8.56549
1175.41	9.85012
1178.65	9.77987
1181.9	10.4029
1185.14	12.1839
1188.38	13.4616
1191.62	15.5285
1194.86	19.9001
1198.09	21.7137
1201.33	23.9524
1204.56	25.0031
1207.8	25.9393
1211.03	26.399
1214.26	28.1468
1217.49	29.8364
1220.71	30.9838
1223.94	32.3083
1227.16	34.973
1230.39	36.8426
1233.61	39.2967
1236.83	39.7646
1240.05	40.5533
1243.27	43.4725
1246.49	44.7146
1249.71	45.5391
1252.92	47.5503
1256.14	49.2913
1259.35	49.7682
1262.56	50.6897
1265.77	51.3781
1268.98	52.4788
1272.19	54.2176
1275.4	55.2111
1278.6	56.2999
1281.81	54.9049
1285.01	54.576
1288.21	56.1665
1291.41	57.612
1294.61	59.6784
1297.81	60.502
1301.01	61.388
1304.2	61.9297
1307.4	63.2598
1310.59	62.478
1313.78	62.6112
1316.97	61.8554
1320.16	63.3763
1323.35	63.365
1326.54	63.5528
1329.72	61.987
1332.91	60.8746
1336.09	60.358
1339.27	56.5043
1342.45	56.6575
1345.64	54.7805
1348.81	54.1685
1351.99	52.396
1355.17	50.0518
1358.34	48.3087
1361.51	47.2191
1364.69	47.6565
1367.86	47.2012
1371.03	45.7424
1374.2	43.1813
1377.37	44.1136
1380.53	42.8737
1383.7	41.1781
1386.86	40.5868
1390.02	39.8257
1393.19	40.3404
1396.35	40.0998
1399.51	39.2153
1402.66	38.8879
1405.82	38.2896
1408.97	38.2287
1412.13	39.0747
1415.28	39.5171
1418.43	41.791
1421.59	45.4974
1424.73	47.4131
1427.88	50.8973
1431.03	54.6332
1434.18	57.099
1437.32	60.473
1440.46	62.2737
1443.61	62.0721
1446.75	63.1719
1449.89	63.9829
1453.03	64.9602
1456.16	65.2972
1459.3	63.2233
1462.44	60.6098
1465.57	57.6063
1468.7	55.7093
1471.83	52.2889
1474.96	49.2719
1478.09	46.0852
1481.22	42.5318
1484.35	38.778
1487.47	34.8218
1490.6	33.5025
1493.72	32.6756
1496.84	29.459
1499.96	29.012
1503.08	28.5153
1506.2	26.3796
1509.32	22.8977
1512.44	20.3079
1515.55	17.8136
1518.66	16.0486
1521.78	16.7251
1524.89	16.0695
1528	16.1572
1531.11	16.379
1534.21	15.4702
1537.32	14.8099
1540.43	16.3064
1543.53	18.8754
1546.63	22.1341
1549.74	25.867
1552.84	28.3737
1555.94	30.8298
1559.03	32.8251
1562.13	35.3316
1565.23	38.5045
1568.32	41.8415
1571.42	43.7954
1574.51	45.8311
1577.6	47.164
1580.69	46.8973
1583.78	46.6466
1586.87	47.3788
1589.95	46.6759
1593.04	47.9255
1596.12	48.5802
1599.21	48.4213
1602.29	47.1012
1605.37	47.3174
1608.45	47.5329
1611.53	47.0799
1614.6	47.1213
1617.68	49.1495
1620.75	50.8526
1623.83	52.9236
1626.9	54.5219
1629.97	56.4858
1633.04	58.5606
1636.11	61.5584
1639.18	64.6892
1642.25	67.5958
1645.31	69.5956
1648.38	69.9642
1651.44	69.9594
1654.5	70.7873
1657.56	69.3111
1660.62	68.0031
1663.68	66.033
1666.74	63.4731
1669.8	60.2514
1672.85	56.3639
1675.91	52.1041
1678.96	48.4
1682.01	44.6159
1685.06	40.999
1688.11	35.381
1691.16	32.5358
1694.21	29.1897
1697.25	25.9202
1700.3	22.4692
1703.34	19.434
1706.39	17.7769
1709.43	16.4995
1712.47	15.3062
1715.51	13.2719
1718.54	11.24
1721.58	9.8101
1724.62	8.56971
1727.65	8.11775
1730.68	7.38048
1733.72	6.43465
1736.75	7.06229
1739.78	5.7137
1742.81	5.67972
1745.84	4.93762
1748.86	4.60633
1751.89	4.92516
1754.91	4.35929
1757.93	4.61512
1760.96	3.86238
1763.98	3.74046
1767	2.70716
1770.02	2.45731
1773.03	1.82623
1776.05	1.10602
1779.07	1.5836
1782.08	1.95714
1785.09	0.388546
1788.11	0.690391
1791.12	0.256331
1794.13	1.29837
1797.13	0.731766
1800.14	1.38657
1803.15	1.62808
1806.15	2.03005
1809.16	2.9477
1812.16	3.45088
1815.16	3.31339
1818.16	3.6398
1821.16	3.4716
1824.16	3.56339
1827.16	2.6564
1830.16	2.90996
1833.15	2.88733
1836.14	2.74306
1839.14	1.95347
1842.13	1.6692
1845.12	2.30539
1848.11	2.43242
1851.1	2.0797
1854.08	1.84564
1857.07	1.80491
1860.05	2.62845
1863.04	2.34014
1866.02	2.25818
1869	2.24894
1871.98	1.69919
1874.96	2.02987
1877.94	2.22307
1880.92	2.8649
1882.51	3.18089
1885.5	3.22757
1888.48	3.6809
1891.47	3.22528
1894.46	2.94792
1897.44	2.63718
1900.42	3.08922
1903.41	4.15542
1906.39	3.31256
1909.37	3.73342
1912.35	2.4341
1915.32	2.59843
1918.3	3.14793
1921.27	2.88918
1924.25	2.57373
1927.22	3.08197
1930.19	3.68236
1933.17	3.54226
1936.14	4.13288
1939.11	3.58085
1942.07	3.40749
1945.04	2.8731
1948.01	2.50967
1950.97	2.27108
1953.93	2.92945
1956.9	3.15023
1959.86	2.74635
1962.82	2.56041
1965.78	2.17461
1968.74	3.09671
1971.69	3.82071
1974.65	3.44919
1977.6	3.64079
1980.56	4.02136
1983.51	4.45695
1986.46	4.08351
1989.41	4.49004
1992.36	4.96346
1995.31	5.51072
1998.26	5.20905
2001.2	5.23043
2004.15	6.22398
2007.09	6.46406
2010.04	6.42998
2012.98	5.299
2015.92	3.76892
2018.86	3.92397
2021.8	3.64937
2024.73	3.66518
2027.67	3.82593
2030.61	3.98012
2033.54	4.45989
2036.47	5.24933
2039.4	6.13699
2042.33	6.26055
2045.27	6.81718
2048.19	8.29407
2051.12	9.50255
2054.05	9.38436
2056.97	10.0845
2059.9	10.6038
2062.82	11.7105
2065.74	12.027
2068.67	12.3687
2071.59	13.1135
2074.51	13.5869
2077.42	14.0187
2080.34	14.5492
2083.26	15.4049
2086.17	15.5244
2089.09	16.5354
2092	17.65
2094.91	18.2296
2097.82	19.2357
2100.73	20.7324
2103.64	22.4886
2106.55	24.7654
2109.45	25.3537
2112.36	26.016
2115.26	27.3113
2118.17	28.4026
2121.07	29.8354
2123.97	32.2744
2126.87	35.3086
2129.77	37.2826
2132.67	38.9725
2135.56	41.7148
2138.46	44.1455
2141.35	46.3415
2144.25	49.4924
2147.14	52.0259
2150.03	55.0688
2152.92	57.9052
2155.81	60.5459
2158.7	62.5151
2161.59	64.666
2164.47	66.6751
2167.36	68.5221
2170.24	70.4559
2173.13	71.0711
2176.01	71.4585
2178.89	71.0002
2181.77	69.9427
2184.65	69.2583
2187.53	68.9762
2190.4	67.646
2193.28	66.4223
2196.16	64.7216
2199.03	61.679
2201.9	58.3476
2204.77	55.2185
2207.64	52.9466
2210.51	48.1273
2213.38	44.8355
2216.25	42.6475
2219.12	40.423
2221.98	38.0831
2224.85	35.6861
2227.71	32.7995
2230.57	30.1856
2233.43	28.7002
2236.29	27.5909
2239.15	25.7264
2242.01	25.1293
2244.87	24.788
2247.72	24.4769
2250.58	23.482
2253.43	24.0251
2256.29	24.1141
2259.14	23.3466
2261.99	22.9627
2264.84	22.6133
2267.69	21.5382
2270.53	21.0116
2273.38	20.7073
2276.23	20.032
2279.07	19.3837
2281.91	18.5382
2284.76	17.9174
2287.6	16.8389
2290.44	15.6066
2293.28	14.0379
2296.12	13.2002
2298.96	12.5277
2301.79	12.8042
2304.63	13.4468
2307.46	13.6087
2310.3	13.4729
2313.13	12.3923
2315.96	12.1948
2318.79	10.8162
2321.62	10.8997
2324.45	11.0121
2327.27	10.4409
2330.1	10.2312
2332.92	10.4591
2335.75	9.40878
2338.57	9.26939
2341.39	8.61842
2344.21	7.71153
2347.04	6.77325
2349.85	5.50663
2352.67	3.94498
2355.49	2.8262
2358.3	2.20077
2361.12	1.6333
2363.93	2.00958
2366.75	2.50337
2369.56	3.60136
2372.37	4.81553
2375.18	5.74538
2377.99	5.16923
2380.8	4.78763
2383.6	5.47577
2386.41	5.78337
2389.21	6.52004
2392.02	7.38795
2394.82	7.15549
2397.62	7.0746
2400.42	7.68587
2403.22	7.72934
2406.02	7.72651
2408.82	7.50117
2411.62	7.67845
2414.41	7.38499
2417.21	6.54183
2420	6.40653
2422.79	6.86269
2425.59	6.72816
2428.38	6.51266
2431.17	6.437
2433.95	6.22455
2436.74	6.26477
2439.53	6.52014
2442.31	7.21419
2445.1	6.46167
2447.88	6.92197
2450.67	6.87931
2453.45	6.63066
2456.23	6.05006
2459.01	5.34527
2461.79	4.27768
2464.57	3.4757
2467.34	3.62037
2470.12	2.64856
2472.89	2.33733
2475.67	2.30871
2478.44	2.0861
2481.21	2.2957
2483.98	1.54354
2486.75	2.80049
2489.52	3.51723
2492.29	3.72367
2495.05	3.61861
2497.82	4.03191
2500.58	4.29017
2503.35	4.41382
2506.11	4.59049
2508.87	5.3602
2511.63	6.59431
2514.39	6.93189
2517.15	6.98506
2519.91	7.00417
2522.67	7.24524
2525.42	6.449
2528.18	6.15778
2530.93	5.33923
2533.69	4.86329
2536.44	4.75911
2539.19	4.66587
2541.94	5.4083
2544.69	5.4922
2547.44	5.12823
2550.18	5.16712
2552.93	4.69634
2555.67	4.35293
2558.42	3.72923
2561.16	3.82098
2563.9	3.28992
2566.64	3.60084
2569.38	3.63278
2572.12	3.98709
2574.86	3.3088
2577.6	3.90884
2580.33	2.96583
2583.07	2.56734
2585.8	3.44806
2588.54	2.95868
2591.27	3.36747
2594	3.37639
2596.73	2.99935
2599.46	3.5242
2602.19	4.64993
2604.92	5.11117
2607.64	5.97073
2610.37	5.76444
2613.09	5.77485
2615.82	5.76333
2618.54	5.98945
2621.26	6.43225
2623.98	6.65064
2626.7	6.26245
2629.42	6.6801
2632.14	6.47912
2634.86	5.87223
2637.57	4.05695
2640.29	3.92988
2643	3.45649
2645.71	2.43865
2648.43	1.91301
2651.14	2.65685
2653.85	2.63348
2656.56	2.43423
2659.26	2.53123
2661.97	3.07937
2664.68	3.56158
2667.38	4.86008
2670.09	5.40937
2672.79	5.80602
2675.49	5.83544
2678.19	6.66027
2680.89	7.58232
2683.59	7.48159
2686.29	8.46156
2688.99	8.30286
2691.69	7.88402
2694.38	7.83383
2697.08	7.69233
2699.77	8.43825
2702.46	8.66943
2705.15	9.15706
2707.85	10.0297
2710.54	10.5346
2713.22	10.819
2715.91	11.4214
2718.6	12.3589
2721.29	11.898
2723.97	11.9499
2726.66	11.2064
2729.34	11.1971
2732.02	10.5684
2734.7	9.89184
2737.38	9.07073
2740.06	8.85756
2742.74	7.22628
2745.42	6.77352
2748.09	5.16238
2750.77	4.77899
2753.45	3.4484
2756.12	2.2533
2758.79	1.44102
2761.46	0.832331
2764.14	0.330559
2766.8	0.207463
2769.47	-0.19876
2772.14	-0.170474
2774.81	0.573808
2777.48	0.831331
2780.14	1.08479
2782.8	1.4971
2785.47	1.42795
2788.13	1.25521
2790.79	1.21606
2793.45	0.995485
2796.11	1.23904
2798.77	0.701966
2801.43	0.801147
2804.09	0.823804
2806.74	0.289472
2809.4	0.223694
2812.05	-0.355918
2814.71	-0.293757
2817.36	0.727202
2820.01	1.38245
2822.66	2.96213
2825.31	5.28076
2827.96	7.33467
2830.6	11.3823
2833.25	15.8387
2835.9	19.33
2838.54	24.4048
2841.18	29.157
2843.83	34.0453
2846.47	39.0017
2849.11	44.6629
2851.75	50.837
2854.39	56.7624
2857.03	62.2513
2859.66	67.7046
2862.3	73.138
2864.94	77.9814
2867.57	82.0403
2870.2	85.8335
2872.84	89.4205
2875.47	92.1007
2878.1	94.9328
2880.73	97.1134
2883.36	100.9
2885.99	103.648
2888.61	106.538
2891.24	109.696
2893.86	112.629
2896.49	117.052
2899.11	120.044
2901.73	125.009
2904.36	129.853
2906.98	135.637
2909.6	143.48
2912.21	151.084
2914.83	159.309
2917.45	166.714
2920.07	173.227
2922.68	179.164
2925.29	184.011
2927.91	187.855
2930.52	189.944
2933.13	191.076
2935.74	191.336
2938.35	188.755
2940.96	186.342
2943.57	182.271
2946.18	177.412
2948.78	170.885
2951.39	163.429
2953.99	155.023
2956.59	147.343
2959.2	139.059
2961.8	131.703
2964.4	122.754
2967	115.772
2969.6	108.758
2972.19	102.695
2974.79	96.6302
2977.39	90.0981
2979.98	83.424
2982.58	76.5621
2985.17	69.5108
2987.76	63.5214
2990.35	57.3594
2992.94	51.4609
2995.53	45.952
2998.12	40.9545
3000.71	35.6714
3003.3	31.0789
3005.88	26.2151
3008.47	21.2897
3011.05	17.2625
3013.64	14.466
3016.22	10.5643
3018.8	8.3849
3021.38	6.73812
3023.96	4.81738
3026.54	3.29125
3029.12	2.89193
3031.69	2.79765
3034.27	1.63574
3036.84	2.4911
3039.42	1.46218
3041.99	1.97301
3044.57	1.65868
3047.14	2.14445
3049.71	3.16431
3052.28	3.26452
3054.85	3.12366
3057.41	4.02063
3059.98	4.03041
3062.55	4.27589
3065.11	4.38186
3067.68	3.46232
3070.24	2.9573
3072.8	2.72097
3075.36	2.68433
3077.93	2.28316
3080.49	2.50196
3083.04	2.49424
3085.6	1.84306
3088.16	2.05219
3090.72	2.42843
3093.27	2.5258
3095.83	2.14674
3098.38	3.16684
3100.93	3.67906
3103.49	3.25665
3106.04	4.07288
3108.59	5.0115
3111.14	5.50619
3113.69	5.38771
3116.23	6.30387
3118.78	7.31589
3121.33	8.28431
3123.87	8.82822
3126.41	9.95227
3128.96	9.67195
3131.5	9.08768
3134.04	10.132
3136.58	11.1307
3139.12	12.2004
3141.66	13.2605
3144.2	14.3757
3146.74	15.8498
3149.27	17.0847