File: data/Raman/poly_smoothed/Mb_30_27_43_1x_45s_532 nm_x100_100%_600 gr_mm_01.txt
#Acq. time (s)=	45
#Accumulations=	2
#Range (cm-¹)=	200...3150
#Windows=	2
#Auto scanning=	Off
#Autofocus=	Off
#Macrospot=	Off
#AutoExposure=	Off
#Spike filter=	Multiple accum.
#Delay time (s)=	0
#Binning=	1
#Readout mode=	Signal
#DeNoise=	Off
#ICS correction=	On
#Dark correction=	Off
#Inst. Process=	Off
#Detector Gain=	Best Dynamic Range
#Detector ADC=	20 kHz
#Detector temperature (°C)=	-69.85
#Instrument=	LabRAM HR Evol
#Detector=	Synapse
#Objective=	x100
#Grating=	600 gr/mm
#ND Filter=	100%
#Laser (nm)=	532
#Hole=	100.021
#Range=	Auto
#Laser Pol.=	No
#Raman. Pol.=	No
#Laser Pol. (°)=	-0.0007625
#Raman Pol. (°)=	89.9995
#Collection=	Microscope
#StageXY=	Marzhauser
#StageZ=	Marzhauser
#X (µm)=	-6369.1
#Y (µm)=	794.8
#Z (µm)=	-65.1
#Full time(mm:ss)=	3:18
#Project=
#Sample=
#Site=
#Title=	Mb_30_27_43_2x_45s_532 nm_x100_100%_600 gr_mm
#Remark=
#Date=	13.07.2022 12:01
#Acquired=	13.07.2022 12:01:39
#Base:Fit=	10.08.2022 10:40:03
#Base:Sub=	10.08.2022 10:40:17
#Filter:Polynom=	16.08.2022 10:16:15
#AxisType[0]=Intens
#AxisUnit[0]=Cnt
#AxisType[1]=Spectr
#AxisUnit[1]=1/cm
200.563	61.606
204.194	54.0546
207.821	44.7005
211.449	37.2253
215.074	31.598
218.699	26.8755
222.321	19.8018
225.941	15.398
229.562	14.0298
233.18	11.4521
236.796	8.95005
240.411	5.75683
244.026	6.34263
247.638	6.15626
251.248	5.92583
254.857	6.27366
258.465	4.12739
262.071	5.65726
265.678	6.18176
269.282	5.24329
272.884	6.94664
276.484	8.92996
280.084	10.0111
283.682	8.9213
287.276	10.2114
290.871	10.3146
294.465	13.2088
298.057	12.3429
301.648	14.1613
305.237	14.6589
308.823	13.9124
312.41	15.4833
315.995	18.414
319.579	19.0604
323.16	18.0758
326.741	17.0716
330.321	18.0102
333.897	17.0521
337.474	16.1377
341.048	15.7869
344.622	13.4585
348.192	12.5862
351.764	12.8597
355.332	10.9729
358.901	10.6115
362.466	11.1741
366.03	11.2422
369.594	11.7955
373.155	10.9657
376.715	11.9288
380.273	14.0082
383.832	15.8389
387.388	17.907
390.942	20.7067
394.495	24.8976
398.047	27.6718
401.597	30.107
405.145	31.6036
408.693	32.5919
412.239	33.2016
415.783	32.993
419.327	35.5644
422.869	33.9623
426.409	34.7333
429.948	32.7741
433.486	30.9931
437.022	29.6284
440.558	28.3873
444.089	26.5129
447.622	26.0271
451.153	24.54
454.682	25.2211
458.208	24.8606
461.735	25.4299
465.259	27.0629
468.783	29.3077
472.306	30.5808
475.825	34.4805
479.346	37.289
482.862	40.3072
486.38	42.0617
489.894	43.1262
493.407	46.399
496.92	47.5518
500.43	50.0704
503.939	51.4459
507.448	51.6527
510.954	53.1126
514.459	54.7968
517.962	53.8078
521.466	51.294
524.966	47.6442
528.466	47.2258
531.964	46.7335
535.46	44.4798
538.955	42.8237
542.449	40.1245
545.942	36.5485
549.433	33.8658
552.923	28.4838
556.412	27.3106
559.899	23.7463
563.385	20.1589
566.867	17.6227
570.35	13.791
573.832	10.6701
577.313	8.35713
580.79	6.47359
584.268	5.88688
587.745	3.70827
591.218	3.10612
594.692	1.21952
598.164	1.64277
601.634	-0.87502
605.104	-1.0236
608.57	0.386859
612.037	3.39593
615.501	6.81417
618.966	8.61328
622.427	10.1007
625.887	11.6675
629.348	14.4756
632.806	16.1302
636.262	18.2441
639.716	20.426
643.172	21.4303
646.624	19.7327
650.075	22.4039
653.524	23.0508
656.972	22.2827
660.419	22.9642
663.865	21.5782
667.309	20.4436
670.752	20.2078
674.194	20.0458
677.634	21.0059
681.073	22.4515
684.511	24.714
687.947	26.8204
691.382	30.675
694.816	31.4758
698.247	33.0946
701.678	34.8826
705.108	37.4875
708.534	37.2596
711.962	39.5824
715.388	39.9501
718.81	40.2002
722.234	40.58
725.654	39.4706
729.075	39.4711
732.492	39.6484
735.91	40.0505
739.325	38.5136
742.741	38.3596
746.153	37.602
749.564	39.7319
752.976	42.4644
756.385	47.7911
759.792	52.4564
763.2	56.0914
766.604	57.933
770.008	60.0878
773.41	62.07
776.811	64.2792
780.21	65.9287
783.608	65.9849
787.005	68.5446
790.401	71.4604
793.795	74.4913
797.188	75.7412
800.58	76.6024
803.971	77.2531
807.36	77.5055
810.748	76.5906
814.135	76.3075
817.518	77.534
820.902	77.2149
824.285	78.6317
827.665	79.2454
831.045	80.9375
834.424	82.1784
837.8	81.163
841.177	80.9995
844.55	77.9011
847.924	75.17
851.295	72.7596
854.666	70.6049
858.034	67.9878
861.403	65.3369
864.769	61.7929
868.133	61.306
871.498	61.9079
874.86	61.7068
878.221	61.3085
881.58	60.401
884.938	58.6121
888.297	57.9822
891.653	57.6879
895.007	55.4672
898.36	57.7198
901.712	60.2375
905.063	60.8141
908.412	60.9314
911.76	59.9317
915.107	58.8506
918.452	56.2661
921.797	56.4804
925.138	56.7344
928.48	54.8839
931.82	52.2003
935.16	50.6357
938.496	49.869
941.833	47.2895
945.168	43.4842
948.5	44.0004
951.834	45.4194
955.163	47.3557
958.494	45.4273
961.821	45.1443
965.15	46.1734
968.474	50.1243
971.8	52.1942
975.123	54.1187
978.446	56.778
981.766	58.3718
985.084	59.2123
988.402	58.3221
991.72	58.925
995.035	58.2357
998.349	55.5407
1001.66	53.0616
1004.97	54.2798
1008.28	57.6127
1011.59	67.0084
1014.9	75.5572
1018.21	84.4796
1021.51	94.2214
1024.81	101.416
1028.12	108.391
1031.42	115.728
1034.72	118.687
1038.02	121.226
1041.31	120.641
1044.61	123.686
1047.91	124.48
1051.2	118.245
1054.49	112.037
1057.78	106.71
1061.07	97.3232
1064.36	88.8396
1067.65	79.7307
1070.93	70.556
1074.22	57.6712
1077.5	48.2155
1080.78	41.9379
1084.06	41.4014
1087.34	44.1547
1090.62	49.2576
1093.9	51.8595
1097.17	55.4605
1100.45	58.8129
1103.72	61.5368
1106.99	62.2145
1110.27	64.6079
1113.53	64.9853
1116.8	64.0688
1120.07	63.8966
1123.33	62.7477
1126.6	60.6353
1129.86	58.8207
1133.12	54.3136
1136.38	50.7551
1139.64	46.7684
1142.9	42.3298
1146.16	38.8233
1149.41	33.0407
1152.67	26.3968
1155.92	22.1932
1159.17	17.3625
1162.42	13.4077
1165.67	8.75555
1168.92	4.8709
1172.16	3.47807
1175.41	4.16899
1178.65	5.45306
1181.9	6.57137
1185.14	8.37099
1188.38	11.7256
1191.62	14.0188
1194.86	16.9917
1198.09	23.4423
1201.33	29.6439
1204.56	36.3946
1207.8	44.4452
1211.03	51.3815
1214.26	59.4406
1217.49	68.2711
1220.71	76.1531
1223.94	83.4552
1227.16	90.3769
1230.39	94.7967
1233.61	99.2708
1236.83	104.434
1240.05	109.002
1243.27	113.536
1246.49	119.317
1249.71	123.819
1252.92	129.157
1256.14	131.61
1259.35	132.834
1262.56	134.302
1265.77	139.093
1268.98	141.67
1272.19	145.816
1275.4	149.563
1278.6	151.858
1281.81	156.151
1285.01	159.659
1288.21	162.706
1291.41	165.178
1294.61	168.056
1297.81	169.203
1301.01	169.964
1304.2	168.319
1307.4	169.601
1310.59	168.028
1313.78	169.281
1316.97	170.228
1320.16	168.599
1323.35	166.368
1326.54	163.009
1329.72	158.709
1332.91	154.004
1336.09	147.98
1339.27	143.709
1342.45	140.582
1345.64	135.564
1348.81	131.044
1351.99	126.64
1355.17	122.197
1358.34	116.83
1361.51	112.538
1364.69	106.216
1367.86	102.121
1371.03	97.9516
1374.2	95.5495
1377.37	93.8152
1380.53	90.1118
1383.7	88.5389
1386.86	87.2371
1390.02	85.4845
1393.19	85.2887
1396.35	81.282
1399.51	80.0924
1402.66	78.0141
1405.82	76.5174
1408.97	78.3208
1412.13	80.8083
1415.28	85.6993
1418.43	92.85
1421.59	101.239
1424.73	112.259
1427.88	124.059
1431.03	136.227
1434.18	146.121
1437.32	153.717
1440.46	161.092
1443.61	167.42
1446.75	172.251
1449.89	175.343
1453.03	175.494
1456.16	174.637
1459.3	169.043
1462.44	161.839
1465.57	154.854
1468.7	144.47
1471.83	136.883
1474.96	125.69
1478.09	116.734
1481.22	106.837
1484.35	98.4828
1487.47	90.3697
1490.6	84.0162
1493.72	79.2034
1496.84	73.4372
1499.96	69.4665
1503.08	65.7159
1506.2	61.6658
1509.32	57.5668
1512.44	53.1184
1515.55	49.2749
1518.66	47.8021
1521.78	44.3134
1524.89	42.7516
1528	41.9449
1531.11	39.3733
1534.21	39.011
1537.32	36.9397
1540.43	39.1847
1543.53	42.3965
1546.63	47.0457
1549.74	51.1884
1552.84	55.8134
1555.94	59.3596
1559.03	64.1956
1562.13	67.8467
1565.23	70.7394
1568.32	74.3265
1571.42	78.1277
1574.51	82.7455
1577.6	87.5191
1580.69	92.3933
1583.78	98.594
1586.87	103.056
1589.95	107.548
1593.04	110.413
1596.12	113.951
1599.21	114.779
1602.29	117.926
1605.37	118.243
1608.45	119.041
1611.53	120.443
1614.6	124.108
1617.68	127.639
1620.75	132.922
1623.83	137.445
1626.9	142.749
1629.97	148.319
1633.04	154.668
1636.11	160.059
1639.18	164.16
1642.25	172.404
1645.31	178.955
1648.38	186.474
1651.44	190.83
1654.5	195.634
1657.56	198.351
1660.62	197.446
1663.68	193.301
1666.74	188.253
1669.8	181.553
1672.85	171.953
1675.91	161.253
1678.96	148.707
1682.01	135.567
1685.06	121.623
1688.11	110.242
1691.16	98.7
1694.21	87.4917
1697.25	75.6504
1700.3	66.1952
1703.34	56.5772
1706.39	49.4302
1709.43	43.5652
1712.47	37.4366
1715.51	33.1626
1718.54	31.5541
1721.58	28.4651
1724.62	25.3521
1727.65	23.4938
1730.68	21.2894
1733.72	20.4796
1736.75	17.9318
1739.78	16.7348
1742.81	14.6082
1745.84	13.1404
1748.86	10.3373
1751.89	9.96111
1754.91	7.85131
1757.93	7.10943
1760.96	6.0341
1763.98	4.17885
1767	4.14629
1770.02	2.01763
1773.03	1.67311
1776.05	1.62759
1779.07	1.56419
1782.08	2.23655
1785.09	1.84857
1788.11	3.07317
1791.12	1.97677
1794.13	2.15366
1797.13	2.27586
1800.14	1.868
1803.15	2.60392
1806.15	3.84589
1809.16	3.12096
1812.16	2.94954
1815.16	2.59336
1818.16	2.43946
1821.16	3.12515
1824.16	3.25976
1827.16	3.43647
1830.16	3.31167
1833.15	2.50931
1836.14	2.99652
1839.14	3.01451
1842.13	3.26593
1845.12	3.00941
1848.11	3.0819
1851.1	3.12969
1854.08	1.95694
1857.07	1.38448
1860.05	1.5828
1863.04	0.714084
1866.02	0.0910116
1869	0.469487
1871.98	0.730723
1874.96	0.822239
1877.94	1.80483
1880.92	0.926261
1882.51	0.231701
1885.5	0.0955539
1888.48	0.636453
1891.47	1.90859
1894.46	1.35353
1897.44	2.86758
1900.42	4.07146
1903.41	5.06855
1906.39	6.29166
1909.37	8.20701
1912.35	8.16758
1915.32	7.59582
1918.3	7.93958
1921.27	7.37107
1924.25	7.92141
1927.22	8.4847
1930.19	8.78818
1933.17	8.35024
1936.14	7.33497
1939.11	7.115
1942.07	8.20341
1945.04	8.87127
1948.01	9.19567
1950.97	8.9292
1953.93	7.34613
1956.9	7.43407
1959.86	6.42124
1962.82	5.85833
1965.78	5.30299
1968.74	4.40788
1971.69	3.64845
1974.65	3.66596
1977.6	3.87824
1980.56	3.48421
1983.51	3.69095
1986.46	3.81603
1989.41	3.95528
1992.36	4.98231
1995.31	5.4903
1998.26	6.56724
2001.2	6.13593
2004.15	6.95066
2007.09	7.63829
2010.04	8.55718
2012.98	9.42998
2015.92	10.5198
2018.86	11.041
2021.8	11.6679
2024.73	11.7806
2027.67	11.1247
2030.61	10.5839
2033.54	9.78091
2036.47	9.93001
2039.4	9.39594
2042.33	10.6193
2045.27	12.0561
2048.19	13.5437
2051.12	16.01
2054.05	17.2434
2056.97	18.252
2059.9	19.4552
2062.82	21.437
2065.74	23.7125
2068.67	26.1114
2071.59	27.6071
2074.51	30.0754
2077.42	31.9754
2080.34	34.7085
2083.26	36.4273
2086.17	38.291
2089.09	40.5657
2092	43.5642
2094.91	46.3723
2097.82	47.6075
2100.73	49.9024
2103.64	53.1859
2106.55	56.4542
2109.45	60.7167
2112.36	65.1426
2115.26	70.9794
2118.17	76.4291
2121.07	82.457
2123.97	89.2134
2126.87	94.8365
2129.77	102.56
2132.67	109.531
2135.56	118.587
2138.46	126.711
2141.35	135.43
2144.25	143.769
2147.14	153.225
2150.03	162.689
2152.92	170.466
2155.81	178.658
2158.7	186.194
2161.59	194.022
2164.47	199.258
2167.36	203.243
2170.24	205.886
2173.13	207.189
2176.01	207.238
2178.89	206.096
2181.77	203.535
2184.65	200.415
2187.53	194.728
2190.4	187.686
2193.28	179.86
2196.16	172.794
2199.03	164.47
2201.9	155.691
2204.77	146.194
2207.64	136.774
2210.51	128.712
2213.38	120.5
2216.25	112.366
2219.12	104.907
2221.98	98.3724
2224.85	92.3072
2227.71	86.8521
2230.57	81.4915
2233.43	76.4063
2236.29	70.5898
2239.15	66.0075
2242.01	62.742
2244.87	58.6035
2247.72	55.9546
2250.58	53.379
2253.43	49.6457
2256.29	46.8259
2259.14	43.7736
2261.99	42.0614
2264.84	40.5813
2267.69	38.4858
2270.53	36.7021
2273.38	35.0388
2276.23	32.0748
2279.07	29.9428
2281.91	28.0956
2284.76	26.2633
2287.6	23.4769
2290.44	21.848
2293.28	19.304
2296.12	17.8114
2298.96	17.4205
2301.79	16.9158
2304.63	16.665
2307.46	17.0502
2310.3	16.8917
2313.13	16.296
2315.96	15.2864
2318.79	14.8503
2321.62	14.2942
2324.45	12.5372
2327.27	11.9588
2330.1	10.6028
2332.92	10.4421
2335.75	9.62142
2338.57	9.16885
2341.39	8.0937
2344.21	5.9484
2347.04	4.42654
2349.85	3.30762
2352.67	2.19209
2355.49	0.854463
2358.3	1.20293
2361.12	0.840043
2363.93	2.51431
2366.75	4.81851
2369.56	6.47478
2372.37	7.41032
2375.18	9.19901
2377.99	8.29725
2380.8	8.6434
2383.6	9.76089
2386.41	10.4856
2389.21	10.8498
2392.02	10.2126
2394.82	9.45868
2397.62	9.87307
2400.42	9.54825
2403.22	8.87294
2406.02	8.91657
2408.82	8.13518
2411.62	7.51592
2414.41	8.02029
2417.21	7.90827
2420	6.74822
2422.79	7.39018
2425.59	8.25771
2428.38	8.5555
2431.17	8.64881
2433.95	9.88473
2436.74	9.94403
2439.53	9.22439
2442.31	10.0325
2445.1	11.2599
2447.88	10.3637
2450.67	10.5398
2453.45	11.0702
2456.23	11.5938
2459.01	11.8008
2461.79	10.9479
2464.57	11.4968
2467.34	10.6492
2470.12	9.65616
2472.89	9.24592
2475.67	8.17349
2478.44	6.27385
2481.21	6.51139
2483.98	5.58609
2486.75	4.82558
2489.52	3.95121
2492.29	3.0442
2495.05	2.38747
2497.82	1.24573
2500.58	0.0787455
2503.35	-0.211506
2506.11	-0.863555
2508.87	0.0465098
2511.63	0.487839
2514.39	-1.17502
2517.15	-1.55014
2519.91	-0.33219
2522.67	0.117277
2525.42	-0.268066
2528.18	0.501541
2530.93	1.45851
2533.69	1.95497
2536.44	1.38678
2539.19	0.909307
2541.94	1.62469
2544.69	1.92822
2547.44	3.22192
2550.18	4.96098
2552.93	5.43585
2555.67	6.24776
2558.42	6.04043
2561.16	8.55076
2563.9	7.9639
2566.64	6.77085
2569.38	6.23652
2572.12	6.21406
2574.86	6.56554
2577.6	5.18843
2580.33	4.12537
2583.07	4.01716
2585.8	4.52052
2588.54	4.77981
2591.27	3.08613
2594	2.97313
2596.73	3.47707
2599.46	3.35024
2602.19	2.69159
2604.92	3.0098
2607.64	4.38565
2610.37	5.08302
2613.09	6.15214
2615.82	7.91341
2618.54	8.48509
2621.26	8.60742
2623.98	9.20924
2626.7	9.33911
2629.42	9.6768
2632.14	8.21904
2634.86	9.012
2637.57	9.05931
2640.29	8.81574
2643	8.70315
2645.71	7.62512
2648.43	6.73964
2651.14	7.08669
2653.85	5.65929
2656.56	4.80183
2659.26	4.30162
2661.97	4.50152
2664.68	4.63837
2667.38	4.73171
2670.09	4.2521
2672.79	3.7374
2675.49	4.54853
2678.19	4.97025
2680.89	6.4727
2683.59	7.09546
2686.29	7.03025
2688.99	7.59184
2691.69	7.78463
2694.38	8.29992
2697.08	8.92648
2699.77	10.5187
2702.46	11.165
2705.15	11.1104
2707.85	11.5017
2710.54	12.3563
2713.22	12.8827
2715.91	13.4865
2718.6	14.485
2721.29	15.0841
2723.97	16.1065
2726.66	15.7468
2729.34	16.0757
2732.02	15.4435
2734.7	14.9268
2737.38	13.9369
2740.06	13.6075
2742.74	13.3497
2745.42	12.0585
2748.09	9.71316
2750.77	7.7235
2753.45	6.13998
2756.12	5.90517
2758.79	3.95136
2761.46	2.83019
2764.14	2.39342
2766.8	2.47629
2769.47	0.796088
2772.14	1.34209
2774.81	2.91487
2777.48	3.04887
2780.14	3.95033
2782.8	4.05928
2785.47	3.77741
2788.13	3.92236
2790.79	4.47993
2793.45	4.35883
2796.11	4.46531
2798.77	4.44797
2801.43	4.13484
2804.09	4.70426
2806.74	3.37478
2809.4	2.6623
2812.05	2.33386
2814.71	4.13149
2817.36	6.24494
2820.01	10.2485
2822.66	15.5632
2825.31	21.1745
2827.96	28.1724
2830.6	35.3055
2833.25	43.5564
2835.9	53.3093
2838.54	65.1458
2841.18	78.0559
2843.83	91.1074
2846.47	106.748
2849.11	121.734
2851.75	138.736
2854.39	156.122
2857.03	174.449
2859.66	191.614
2862.3	208.97
2864.94	224.065
2867.57	237.414
2870.2	250.645
2872.84	262.769
2875.47	274.477
2878.1	284.725
2880.73	294.241
2883.36	304.449
2885.99	315.742
2888.61	324.587
2891.24	334.745
2893.86	346.654
2896.49	358.986
2899.11	374.706
2901.73	393.157
2904.36	413.259
2906.98	437.269
2909.6	464.035
2912.21	490.536
2914.83	517.647
2917.45	545.238
2920.07	570.291
2922.68	592.145
2925.29	608.542
2927.91	622.657
2930.52	630.053
2933.13	635.191
2935.74	633.578
2938.35	626.597
2940.96	616.022
2943.57	601.404
2946.18	583.056
2948.78	561.429
2951.39	537.63
2953.99	513.223
2956.59	487.898
2959.2	461.243
2961.8	436.143
2964.4	411.51
2967	387.364
2969.6	365.74
2972.19	344.954
2974.79	323.934
2977.39	304.296
2979.98	283.603
2982.58	263.599
2985.17	242.883
2987.76	223.54
2990.35	203.105
2992.94	183.7
2995.53	164.556
2998.12	146.998
3000.71	128.656
3003.3	112.354
3005.88	97.4954
3008.47	83.4453
3011.05	70.7879
3013.64	60.189
3016.22	51.187
3018.8	43.2226
3021.38	35.0441
3023.96	30.0192
3026.54	25.1377
3029.12	20.5625
3031.69	18.5836
3034.27	17.72
3036.84	17.3502
3039.42	17.7707
3041.99	18.2036
3044.57	19.5599
3047.14	21.4792
3049.71	22.1941
3052.28	22.7456
3054.85	22.9154
3057.41	22.5159
3059.98	22.5073
3062.55	21.2795
3065.11	20.0156
3067.68	18.2265
3070.24	16.9599
3072.8	14.5921
3075.36	12.1885
3077.93	10.647
3080.49	7.51523
3083.04	4.94544
3085.6	3.099
3088.16	-0.0489104
3090.72	-1.07682
3093.27	-2.02671
3095.83	-1.50241
3098.38	-1.48677
3100.93	-1.92968
3103.49	-0.397966
3106.04	0.807056
3108.59	1.86773
3111.14	2.01502
3113.69	3.0286
3116.23	4.14967
3118.78	5.00798
3121.33	5.95974
3123.87	7.00993
3126.41	8.39004
3128.96	9.19246
3131.5	9.85207
3134.04	10.6307
3136.58	11.1819
3139.12	12.6334
3141.66	13.2792
3144.2	13.6426
3146.74	14.3416
3149.27	15.4476