File: data/Raman/poly_smoothed/Mb_30_27_33_1x_45s_532 nm_x100_100%_600 gr_mm_01.txt
#Acq. time (s)=	45
#Accumulations=	2
#Range (cm-¹)=	200...3150
#Windows=	2
#Auto scanning=	Off
#Autofocus=	Off
#Macrospot=	Off
#AutoExposure=	Off
#Spike filter=	Multiple accum.
#Delay time (s)=	0
#Binning=	1
#Readout mode=	Signal
#DeNoise=	Off
#ICS correction=	On
#Dark correction=	Off
#Inst. Process=	Off
#Detector Gain=	Best Dynamic Range
#Detector ADC=	20 kHz
#Detector temperature (°C)=	-69.85
#Instrument=	LabRAM HR Evol
#Detector=	Synapse
#Objective=	x100
#Grating=	600 gr/mm
#ND Filter=	100%
#Laser (nm)=	532
#Hole=	100.021
#Range=	Auto
#Laser Pol.=	No
#Raman. Pol.=	No
#Laser Pol. (°)=	-0.0007625
#Raman Pol. (°)=	89.9995
#Collection=	Microscope
#StageXY=	Marzhauser
#StageZ=	Marzhauser
#X (µm)=	-6359.4
#Y (µm)=	815
#Z (µm)=	-64.7
#Full time(mm:ss)=	3:18
#Project=
#Sample=
#Site=
#Title=	Mb_30_27_33_2x_45s_532 nm_x100_100%_600 gr_mm
#Remark=
#Date=	13.07.2022 11:09
#Acquired=	13.07.2022 11:09:52
#Base:Fit=	10.08.2022 10:40:03
#Base:Sub=	10.08.2022 10:40:17
#Filter:Polynom=	16.08.2022 10:16:15
#AxisType[0]=Intens
#AxisUnit[0]=Cnt
#AxisType[1]=Spectr
#AxisUnit[1]=1/cm
200.563	2.71616
204.194	3.79405
207.821	3.46155
211.449	3.15039
215.074	3.03868
218.699	4.66501
222.321	5.92785
225.941	4.07797
229.562	5.3071
233.18	5.1643
236.796	5.23626
240.411	5.06229
244.026	4.60884
247.638	4.13726
251.248	4.03276
254.857	4.42357
258.465	5.09943
262.071	5.1971
265.678	5.19205
269.282	4.92934
272.884	4.75331
276.484	5.17439
280.084	4.63274
283.682	6.98569
287.276	8.2018
290.871	7.9551
294.465	9.58391
298.057	10.2223
301.648	11.9579
305.237	14.3888
308.823	15.2662
312.41	16.1504
315.995	15.7541
319.579	17.9762
323.16	18.388
326.741	18.3098
330.321	18.9698
333.897	19.2141
337.474	18.662
341.048	18.9322
344.622	18.5903
348.192	19.421
351.764	19.2896
355.332	19.0825
358.901	19.8684
362.466	17.8281
366.03	17.3258
369.594	16.3065
373.155	16.302
376.715	16.2297
380.273	14.9325
383.832	14.4727
387.388	13.2222
390.942	12.6938
394.495	12.4438
398.047	12.4523
401.597	12.6165
405.145	12.0797
408.693	13.1986
412.239	12.9377
415.783	12.1281
419.327	12.6931
422.869	10.9833
426.409	9.70602
429.948	9.53701
433.486	9.32147
437.022	7.76218
440.558	9.26227
444.089	8.69804
447.622	8.51028
451.153	8.47795
454.682	10.2566
458.208	12.0351
461.735	12.9034
465.259	14.0965
468.783	14.1038
472.306	15.2832
475.825	16.3087
479.346	17.1187
482.862	17.7815
486.38	18.9348
489.894	19.1634
493.407	18.9438
496.92	19.2083
500.43	17.3152
503.939	16.8222
507.448	16.3341
510.954	15.1835
514.459	14.816
517.962	13.8647
521.466	14.0802
524.966	15.8852
528.466	15.5136
531.964	15.6072
535.46	17.9581
538.955	18.7644
542.449	18.9741
545.942	18.6676
549.433	18.0658
552.923	17.5135
556.412	17.3283
559.899	16.6146
563.385	15.8587
566.867	13.7465
570.35	13.9018
573.832	12.7019
577.313	11.5654
580.79	9.94547
584.268	7.49974
587.745	6.5709
591.218	6.53838
594.692	5.89697
598.164	5.70518
601.634	5.08398
605.104	4.51029
608.57	5.38284
612.037	6.77761
615.501	7.97913
618.966	8.8599
622.427	8.82879
625.887	8.30426
629.348	8.2625
632.806	7.55757
636.262	8.97891
639.716	10.3968
643.172	10.3979
646.624	10.7013
650.075	9.81058
653.524	10.8614
656.972	12.5205
660.419	11.8878
663.865	12.2646
667.309	12.2184
670.752	12.8818
674.194	14.9945
677.634	16.5196
681.073	17.4176
684.511	18.7549
687.947	19.8982
691.382	22.0121
694.816	25.5336
698.247	27.474
701.678	28.5464
705.108	29.3894
708.534	29.624
711.962	31.6566
715.388	32.7226
718.81	33.8318
722.234	34.7387
725.654	35.6187
729.075	35.9514
732.492	37.5143
735.91	39.3388
739.325	40.7314
742.741	42.1476
746.153	43.8915
749.564	47.2038
752.976	49.2276
756.385	52.3159
759.792	54.7353
763.2	55.9227
766.604	58.1643
770.008	60.1589
773.41	62.9304
776.811	66.0149
780.21	68.2268
783.608	69.7981
787.005	71.2277
790.401	72.1943
793.795	72.9586
797.188	72.8862
800.58	71.1753
803.971	70.921
807.36	71.8426
810.748	71.5115
814.135	70.2542
817.518	70.344
820.902	69.6691
824.285	69.804
827.665	68.7341
831.045	68.8314
834.424	67.6732
837.8	65.6285
841.177	63.3218
844.55	60.2128
847.924	57.6517
851.295	56.4517
854.666	54.9946
858.034	53.8303
861.403	52.4146
864.769	51.2816
868.133	49.716
871.498	48.6215
874.86	47.3394
878.221	47.0309
881.58	46.2096
884.938	46.003
888.297	46.6435
891.653	46.8241
895.007	47.1362
898.36	46.3153
901.712	47.0915
905.063	47.1034
908.412	46.9555
911.76	45.6863
915.107	44.4651
918.452	42.9804
921.797	40.2989
925.138	37.4975
928.48	36.1327
931.82	35.8509
935.16	36.9495
938.496	36.2533
941.833	36.718
945.168	36.5193
948.5	35.7911
951.834	36.0138
955.163	36.0585
958.494	36.1205
961.821	34.207
965.15	33.2503
968.474	32.4552
971.8	30.7012
975.123	29.6021
978.446	28.1797
981.766	28.481
985.084	27.5969
988.402	25.4217
991.72	22.6794
995.035	20.7584
998.349	18.2365
1001.66	15.7345
1004.97	14.5297
1008.28	15.5456
1011.59	17.2756
1014.9	20.125
1018.21	22.3475
1021.51	25.0399
1024.81	26.4799
1028.12	29.0066
1031.42	30.941
1034.72	32.9561
1038.02	32.6238
1041.31	33.0186
1044.61	33.9332
1047.91	33.2547
1051.2	33.0834
1054.49	32.0076
1057.78	31.7676
1061.07	31.9272
1064.36	30.8873
1067.65	27.3846
1070.93	24.6359
1074.22	21.6041
1077.5	19.1403
1080.78	15.999
1084.06	14.2414
1087.34	13.3397
1090.62	13.3822
1093.9	14.4261
1097.17	14.9124
1100.45	14.1807
1103.72	12.5299
1106.99	11.5165
1110.27	10.9854
1113.53	11.2652
1116.8	9.96194
1120.07	8.67309
1123.33	8.27408
1126.6	7.5099
1129.86	5.31737
1133.12	4.82118
1136.38	5.00975
1139.64	6.3254
1142.9	6.2715
1146.16	5.47418
1149.41	5.11318
1152.67	5.19204
1155.92	5.66846
1159.17	6.0619
1162.42	5.61721
1165.67	5.934
1168.92	7.05615
1172.16	8.33352
1175.41	8.816
1178.65	8.59643
1181.9	7.62527
1185.14	7.73038
1188.38	7.81122
1191.62	7.7164
1194.86	7.23727
1198.09	6.35975
1201.33	6.73513
1204.56	7.17485
1207.8	5.95464
1211.03	6.09778
1214.26	9.37871
1217.49	10.6479
1220.71	12.3552
1223.94	15.1461
1227.16	18.2578
1230.39	21.113
1233.61	24.0748
1236.83	27.0868
1240.05	28.9815
1243.27	30.3807
1246.49	32.2083
1249.71	33.1586
1252.92	34.7302
1256.14	34.9241
1259.35	35.9983
1262.56	36.8982
1265.77	37.1245
1268.98	35.8641
1272.19	36.617
1275.4	37.423
1278.6	37.8666
1281.81	37.5524
1285.01	37.3377
1288.21	38.9961
1291.41	40.516
1294.61	39.8416
1297.81	40.6885
1301.01	41.2607
1304.2	42.7859
1307.4	42.1431
1310.59	43.554
1313.78	43.9403
1316.97	43.4542
1320.16	43.9975
1323.35	43.2946
1326.54	42.9566
1329.72	42.1708
1332.91	42.75
1336.09	41.8547
1339.27	41.8073
1342.45	41.0017
1345.64	40.7185
1348.81	40.1397
1351.99	39.8561
1355.17	38.5247
1358.34	38.2203
1361.51	37.5895
1364.69	37.1177
1367.86	36.0614
1371.03	34.2801
1374.2	32.6014
1377.37	32.0947
1380.53	30.8241
1383.7	28.649
1386.86	28.4843
1390.02	27.9115
1393.19	27.3767
1396.35	27.0811
1399.51	25.9394
1402.66	25.4447
1405.82	24.8172
1408.97	25.4626
1412.13	25.7099
1415.28	26.6557
1418.43	28.159
1421.59	31.0479
1424.73	31.6061
1427.88	33.8203
1431.03	36.5423
1434.18	39.7075
1437.32	42.1124
1440.46	42.5623
1443.61	44.3136
1446.75	44.8263
1449.89	45.4907
1453.03	45.1847
1456.16	44.1777
1459.3	42.3115
1462.44	40.8826
1465.57	38.2967
1468.7	35.7578
1471.83	33.682
1474.96	32.9902
1478.09	31.1871
1481.22	28.7163
1484.35	26.739
1487.47	25.5055
1490.6	24.3206
1493.72	22.7904
1496.84	22.9308
1499.96	20.6314
1503.08	20.2118
1506.2	19.804
1509.32	19.8574
1512.44	18.306
1515.55	16.2532
1518.66	16.1236
1521.78	15.8113
1524.89	14.3446
1528	13.7946
1531.11	12.822
1534.21	12.5863
1537.32	12.463
1540.43	14.6024
1543.53	15.1472
1546.63	17.6806
1549.74	18.6826
1552.84	20.4816
1555.94	22.0961
1559.03	22.309
1562.13	22.0465
1565.23	22.9441
1568.32	23.5373
1571.42	24.6947
1574.51	24.8274
1577.6	25.8748
1580.69	26.7165
1583.78	27.7204
1586.87	28.5032
1589.95	29.5913
1593.04	30.0092
1596.12	32.1072
1599.21	32.2372
1602.29	32.824
1605.37	32.2984
1608.45	32.4105
1611.53	32.164
1614.6	33.0832
1617.68	32.6948
1620.75	31.8777
1623.83	32.1119
1626.9	32.5755
1629.97	33.8047
1633.04	34.1593
1636.11	34.325
1639.18	34.7716
1642.25	35.8524
1645.31	37.1415
1648.38	37.4819
1651.44	37.9951
1654.5	39.2007
1657.56	40.0885
1660.62	40.6832
1663.68	41.3303
1666.74	40.2745
1669.8	39.5131
1672.85	37.6433
1675.91	35.2701
1678.96	32.4849
1682.01	29.7262
1685.06	26.9889
1688.11	24.9304
1691.16	23.4706
1694.21	20.886
1697.25	20.184
1700.3	17.7673
1703.34	17.7946
1706.39	16.149
1709.43	14.7024
1712.47	13.4669
1715.51	12.2663
1718.54	11.9889
1721.58	11.3316
1724.62	9.84926
1727.65	10.3699
1730.68	10.8973
1733.72	11.2983
1736.75	10.427
1739.78	9.53201
1742.81	9.18246
1745.84	8.43109
1748.86	6.56608
1751.89	6.07344
1754.91	5.63411
1757.93	4.89083
1760.96	4.39281
1763.98	4.18592
1767	2.85581
1770.02	2.72764
1773.03	1.94295
1776.05	1.10184
1779.07	1.03738
1782.08	0.177263
1785.09	0.0606926
1788.11	-0.205923
1791.12	-0.0299207
1794.13	0.418288
1797.13	0.249331
1800.14	1.76642
1803.15	3.72958
1806.15	4.38101
1809.16	4.79128
1812.16	5.03893
1815.16	5.52226
1818.16	5.68533
1821.16	6.13039
1824.16	6.48279
1827.16	5.89118
1830.16	6.01532
1833.15	5.89563
1836.14	4.85028
1839.14	4.90192
1842.13	4.78246
1845.12	3.72936
1848.11	2.94827
1851.1	3.10644
1854.08	3.02382
1857.07	2.65076
1860.05	2.78102
1863.04	2.55426
1866.02	1.95114
1869	1.66569
1871.98	1.99332
1874.96	2.88239
1877.94	3.09943
1880.92	2.48357
1882.51	2.23118
1885.5	2.79711
1888.48	2.21558
1891.47	2.80412
1894.46	3.90248
1897.44	3.65322
1900.42	4.1094
1903.41	5.64203
1906.39	5.31584
1909.37	5.55882
1912.35	6.46827
1915.32	7.12324
1918.3	7.97765
1921.27	9.03283
1924.25	9.56212
1927.22	8.98644
1930.19	9.00901
1933.17	8.73301
1936.14	7.96458
1939.11	7.29965
1942.07	7.30262
1945.04	7.63782
1948.01	6.53205
1950.97	6.0148
1953.93	5.77929
1956.9	4.8716
1959.86	4.93552
1962.82	5.28477
1965.78	5.67778
1968.74	6.18456
1971.69	6.33052
1974.65	5.82992
1977.6	5.57428
1980.56	4.71284
1983.51	4.76689
1986.46	4.60818
1989.41	5.03174
1992.36	4.92211
1995.31	5.03704
1998.26	4.95067
2001.2	5.97249
2004.15	6.38043
2007.09	6.93592
2010.04	6.85305
2012.98	6.75992
2015.92	6.99351
2018.86	6.63056
2021.8	6.80597
2024.73	7.30724
2027.67	7.89544
2030.61	7.95425
2033.54	8.75989
2036.47	8.85828
2039.4	9.06039
2042.33	9.2873
2045.27	9.04998
2048.19	8.42156
2051.12	7.85919
2054.05	6.93305
2056.97	7.4731
2059.9	7.55967
2062.82	8.31166
2065.74	9.23786
2068.67	9.59117
2071.59	11.1925
2074.51	11.0923
2077.42	11.3367
2080.34	12.1013
2083.26	12.8486
2086.17	13.8514
2089.09	14.4709
2092	15.2008
2094.91	15.9247
2097.82	16.97
2100.73	17.7933
2103.64	18.803
2106.55	19.087
2109.45	19.0688
2112.36	19.8995
2115.26	19.8928
2118.17	20.201
2121.07	19.9482
2123.97	21.0835
2126.87	23.0293
2129.77	25.0748
2132.67	26.086
2135.56	27.179
2138.46	28.649
2141.35	30.8925
2144.25	32.4101
2147.14	34.5544
2150.03	36.2117
2152.92	38.7259
2155.81	41.107
2158.7	42.6739
2161.59	43.4921
2164.47	44.7445
2167.36	45.5457
2170.24	46.1142
2173.13	46.4472
2176.01	46.4296
2178.89	45.7974
2181.77	46.4781
2184.65	45.9012
2187.53	45.3789
2190.4	44.7847
2193.28	44.0944
2196.16	42.6047
2199.03	41.8985
2201.9	40.0808
2204.77	38.455
2207.64	36.1582
2210.51	34.2099
2213.38	31.6121
2216.25	29.8857
2219.12	28.0659
2221.98	26.502
2224.85	24.8508
2227.71	22.4082
2230.57	20.2102
2233.43	18.9229
2236.29	16.9657
2239.15	15.2347
2242.01	14.0839
2244.87	13.255
2247.72	13.6581
2250.58	13.8901
2253.43	14.0305
2256.29	13.4986
2259.14	12.9793
2261.99	12.1377
2264.84	11.9612
2267.69	11.7395
2270.53	11.5348
2273.38	10.9346
2276.23	10.3841
2279.07	9.90465
2281.91	9.05554
2284.76	8.48752
2287.6	7.281
2290.44	6.52308
2293.28	4.65568
2296.12	4.46976
2298.96	4.33631
2301.79	4.2521
2304.63	4.36404
2307.46	3.86451
2310.3	4.55136
2313.13	4.79224
2315.96	5.03098
2318.79	5.56155
2321.62	6.04992
2324.45	4.94179
2327.27	4.05385
2330.1	3.36999
2332.92	3.10927
2335.75	2.99122
2338.57	2.21276
2341.39	1.70593
2344.21	1.6454
2347.04	1.5302
2349.85	0.838271
2352.67	0.641199
2355.49	0.866968
2358.3	0.204007
2361.12	0.845169
2363.93	1.4794
2366.75	2.63097
2369.56	1.65174
2372.37	1.97893
2375.18	2.15268
2377.99	3.57938
2380.8	3.94994
2383.6	3.69784
2386.41	3.72017
2389.21	3.6176
2392.02	3.1126
2394.82	3.29482
2397.62	3.46773
2400.42	3.82865
2403.22	3.66449
2406.02	3.74938
2408.82	3.86268
2411.62	3.32701
2414.41	3.46062
2417.21	3.18308
2420	3.15607
2422.79	2.57432
2425.59	2.82669
2428.38	2.56598
2431.17	2.31721
2433.95	1.32148
2436.74	0.720218
2439.53	0.485753
2442.31	0.627469
2445.1	0.944624
2447.88	0.829694
2450.67	1.07259
2453.45	0.860723
2456.23	1.28655
2459.01	1.83307
2461.79	2.87024
2464.57	4.35423
2467.34	4.50623
2470.12	5.38407
2472.89	5.13476
2475.67	4.45156
2478.44	4.23703
2481.21	3.89165
2483.98	4.59415
2486.75	4.12121
2489.52	4.10242
2492.29	4.26748
2495.05	4.35545
2497.82	3.62102
2500.58	3.26295
2503.35	2.24459
2506.11	2.75561
2508.87	2.89133
2511.63	2.65205
2514.39	2.34846
2517.15	1.89426
2519.91	1.93867
2522.67	1.99473
2525.42	2.33993
2528.18	3.4325
2530.93	3.29175
2533.69	3.42081
2536.44	3.23237
2539.19	3.39426
2541.94	2.8083
2544.69	3.12044
2547.44	3.28823
2550.18	4.16868
2552.93	3.62507
2555.67	3.66207
2558.42	3.66984
2561.16	3.46874
2563.9	4.24603
2566.64	3.42888
2569.38	3.44784
2572.12	3.75508
2574.86	2.97173
2577.6	1.8842
2580.33	1.97488
2583.07	1.71494
2585.8	1.96792
2588.54	2.3212
2591.27	2.98359
2594	2.28189
2596.73	2.02168
2599.46	1.95453
2602.19	1.82314
2604.92	1.9744
2607.64	1.98174
2610.37	2.36205
2613.09	1.93107
2615.82	2.22157
2618.54	2.11434
2621.26	1.18609
2623.98	1.38697
2626.7	1.41096
2629.42	1.60131
2632.14	0.813407
2634.86	0.930844
2637.57	1.10922
2640.29	1.57207
2643	2.12204
2645.71	2.18236
2648.43	3.44092
2651.14	3.01487
2653.85	2.35611
2656.56	2.80686
2659.26	2.97517
2661.97	2.42741
2664.68	2.68903
2667.38	2.55708
2670.09	2.05946
2672.79	2.77421
2675.49	3.30677
2678.19	3.22855
2680.89	3.04729
2683.59	3.05312
2686.29	2.59981
2688.99	3.0708
2691.69	2.93699
2694.38	3.00872
2697.08	2.20248
2699.77	2.42634
2702.46	3.1741
2705.15	3.47165
2707.85	3.57616
2710.54	3.67415
2713.22	4.01074
2715.91	3.87331
2718.6	4.18273
2721.29	4.56345
2723.97	5.2569
2726.66	4.75113
2729.34	4.86807
2732.02	4.93654
2734.7	4.97888
2737.38	4.79622
2740.06	4.9903
2742.74	4.67037
2745.42	4.74678
2748.09	4.86132
2750.77	5.30196
2753.45	5.53376
2756.12	5.07071
2758.79	4.31071
2761.46	3.98948
2764.14	3.04527
2766.8	3.21233
2769.47	2.55338
2772.14	2.67982
2774.81	2.60781
2777.48	2.46023
2780.14	1.7567
2782.8	1.6485
2785.47	1.34568
2788.13	1.2187
2790.79	0.676048
2793.45	0.392084
2796.11	0.757085
2798.77	0.238396
2801.43	-0.37518
2804.09	-0.25759
2806.74	0.325607
2809.4	0.911192
2812.05	1.94063
2814.71	2.37535
2817.36	3.22497
2820.01	3.82295
2822.66	4.92411
2825.31	6.10687
2827.96	7.51006
2830.6	9.4491
2833.25	11.0754
2835.9	13.8331
2838.54	15.8619
2841.18	18.1217
2843.83	20.7931
2846.47	24.1809
2849.11	27.7161
2851.75	30.8806
2854.39	34.3058
2857.03	37.3563
2859.66	41.1653
2862.3	43.7535
2864.94	47.085
2867.57	49.7183
2870.2	52.0337
2872.84	53.9485
2875.47	56.3664
2878.1	57.968
2880.73	59.4849
2883.36	61.1128
2885.99	62.9858
2888.61	65.716
2891.24	67.5576
2893.86	69.3732
2896.49	72.5659
2899.11	75.7535
2901.73	79.8404
2904.36	83.6509
2906.98	88.1519
2909.6	93.3142
2912.21	98.4042
2914.83	103.285
2917.45	108.053
2920.07	112.824
2922.68	116.57
2925.29	120.548
2927.91	123.755
2930.52	125.165
2933.13	126.672
2935.74	127.924
2938.35	127.365
2940.96	126.784
2943.57	124.659
2946.18	121.853
2948.78	119.161
2951.39	115.886
2953.99	112.325
2956.59	107.308
2959.2	103.263
2961.8	98.7703
2964.4	93.0492
2967	88.5752
2969.6	83.3367
2972.19	78.8646
2974.79	73.4991
2977.39	68.8302
2979.98	64.3274
2982.58	59.4001
2985.17	54.828
2987.76	50.7766
2990.35	46.4015
2992.94	42.2273
2995.53	38.3058
2998.12	34.0367
3000.71	30.2455
3003.3	27.0597
3005.88	23.2956
3008.47	20.5568
3011.05	17.3937
3013.64	15.3369
3016.22	13.5651
3018.8	12.018
3021.38	10.8111
3023.96	9.19777
3026.54	7.9665
3029.12	7.66627
3031.69	7.62707
3034.27	7.37425
3036.84	8.30278
3039.42	8.64198
3041.99	9.24495
3044.57	9.16416
3047.14	8.75663
3049.71	8.39646
3052.28	8.42418
3054.85	8.72972
3057.41	8.16212
3059.98	7.13601
3062.55	6.88918
3065.11	5.98685
3067.68	4.97533
3070.24	4.58095
3072.8	3.72269
3075.36	3.04225
3077.93	3.06399
3080.49	2.5189
3083.04	2.08405
3085.6	1.44118
3088.16	1.68747
3090.72	1.58308
3093.27	1.72462
3095.83	1.66664
3098.38	1.27971
3100.93	1.23149
3103.49	0.788913
3106.04	1.26352
3108.59	1.10976
3111.14	1.1356
3113.69	1.55251
3116.23	2.46946
3118.78	2.76693
3121.33	3.09196
3123.87	2.44419
3126.41	2.82411
3128.96	3.09233
3131.5	3.3524
3134.04	3.61805
3136.58	3.87937
3139.12	4.27806
3141.66	3.93191
3144.2	3.32076
3146.74	2.1545
3149.27	-0.320263