File: data/Raman/poly_smoothed/Mb_30_27_11_1x_45s_532 nm_x100_100%_600 gr_mm_01.txt
#Acq. time (s)=	45
#Accumulations=	2
#Range (cm-¹)=	200...3150
#Windows=	2
#Auto scanning=	Off
#Autofocus=	Off
#Macrospot=	Off
#AutoExposure=	Off
#Spike filter=	Multiple accum.
#Delay time (s)=	0
#Binning=	1
#Readout mode=	Signal
#DeNoise=	Off
#ICS correction=	On
#Dark correction=	Off
#Inst. Process=	Off
#Detector Gain=	Best Dynamic Range
#Detector ADC=	20 kHz
#Detector temperature (°C)=	-69.85
#Instrument=	LabRAM HR Evol
#Detector=	Synapse
#Objective=	x100
#Grating=	600 gr/mm
#ND Filter=	100%
#Laser (nm)=	532
#Hole=	100.021
#Range=	Auto
#Laser Pol.=	No
#Raman. Pol.=	No
#Laser Pol. (°)=	-0.0007625
#Raman Pol. (°)=	89.9995
#Collection=	Microscope
#StageXY=	Marzhauser
#StageZ=	Marzhauser
#X (µm)=	-1245.8
#Y (µm)=	1614.4
#Z (µm)=	-6.65
#Full time(mm:ss)=	3:05
#Project=
#Sample=
#Site=
#Title=	Mb_30_27_11_2x_45s_532 nm_x100_100%_600 gr_mm
#Remark=
#Date=	12.07.2022 16:47
#Acquired=	12.07.2022 16:47:36
#Base:Fit=	10.08.2022 10:40:03
#Base:Sub=	10.08.2022 10:40:17
#Filter:Polynom=	16.08.2022 10:16:15
#AxisType[0]=Intens
#AxisUnit[0]=Cnt
#AxisType[1]=Spectr
#AxisUnit[1]=1/cm
200.413	-1.01577
204.042	1.89904
207.671	4.10561
211.297	5.53643
214.924	5.6746
218.547	6.06178
222.169	4.26014
225.792	5.28001
229.411	4.63031
233.028	4.56729
236.647	4.75428
240.261	5.86404
243.875	5.47673
247.487	4.31933
251.099	4.33358
254.708	4.34836
258.316	5.29003
261.922	5.42001
265.527	7.34977
269.131	8.89873
272.733	7.71395
276.334	7.75483
279.933	8.99869
283.531	9.62183
287.128	9.3382
290.723	10.2972
294.316	9.45812
297.909	9.54862
301.498	9.13778
305.087	10.0109
308.675	9.47308
312.262	9.38436
315.845	9.74314
319.429	7.95192
323.012	7.25099
326.591	7.13389
330.171	7.30979
333.749	7.78109
337.324	7.77037
340.9	8.47179
344.472	8.59232
348.045	8.47456
351.614	9.26614
355.185	9.60863
358.751	9.47473
362.317	9.488
365.883	10.8942
369.445	10.7677
373.006	11.181
376.568	10.5185
380.126	10.1922
383.683	10.5467
387.239	10.4048
390.793	10.0084
394.348	9.53461
397.9	7.50264
401.45	5.61175
404.999	4.6455
408.546	2.64464
412.092	3.28194
415.637	2.81169
419.18	2.24921
422.722	0.391634
426.263	0.707283
429.802	0.409878
433.338	-0.198299
436.874	-0.942054
440.41	0.333474
443.943	0.280698
447.476	1.7858
451.005	1.33985
454.534	1.75972
458.063	2.52597
461.588	2.83658
465.113	3.62119
468.638	5.48533
472.158	7.78938
475.68	9.36004
479.198	11.0674
482.717	13.3941
486.233	14.6914
489.747	16.7699
493.261	16.5867
496.773	19.0352
500.285	20.1663
503.794	20.6552
507.301	21.3769
510.807	21.444
514.314	21.9517
517.817	20.5181
521.319	19.346
524.82	18.1647
528.319	16.8479
531.817	15.3297
535.316	13.6839
538.811	11.7072
542.305	11.5175
545.798	10.6272
549.289	9.11652
552.777	8.0873
556.265	7.67498
559.753	7.36847
563.239	6.52961
566.723	5.70442
570.207	5.08576
573.688	4.89518
577.167	4.41757
580.646	3.37635
584.124	3.90543
587.599	4.06082
591.074	2.95624
594.548	2.07418
598.019	2.17802
601.49	1.63387
604.958	0.408855
608.427	0.162428
611.892	1.39114
615.358	1.87955
618.821	2.63594
622.282	2.71592
625.744	4.64638
629.203	4.90286
632.661	5.29771
636.119	6.02385
639.574	7.50982
643.027	8.47224
646.479	10.0864
649.932	11.4731
653.382	11.8107
656.83	14.0638
660.277	15.8753
663.722	15.8965
667.167	16.7322
670.61	18.3089
674.051	21.1924
677.492	22.8297
680.931	24.1218
684.369	26.8008
687.803	28.0968
691.238	28.8769
694.672	30.1031
698.105	32.5941
701.536	33.168
704.964	34.9351
708.393	36.3474
711.82	38.2208
715.244	39.8528
718.669	40.6029
722.09	41.6908
725.512	42.9729
728.933	42.8182
732.351	43.0276
735.767	43.3147
739.184	43.4405
742.598	44.8202
746.012	46.4954
749.423	47.4996
752.833	48.9972
756.244	51.6059
759.651	54.9759
763.057	56.9401
766.462	59.802
769.865	62.2638
773.269	64.9174
776.67	67.604
780.069	71.2931
783.468	72.902
786.865	74.387
790.26	77.5172
793.655	79.8597
797.048	83.2901
800.44	84.9177
803.83	86.0128
807.218	87.2939
810.606	86.3489
813.993	86.413
817.378	86.6199
820.762	86.6234
824.143	85.6466
827.525	84.0646
830.905	83.3255
834.282	80.5923
837.66	78.8942
841.035	76.8147
844.41	74.413
847.782	71.5285
851.155	69.0884
854.525	66.3505
857.895	63.1577
861.262	59.895
864.628	57.2746
867.994	54.8881
871.357	54.8835
874.719	54.3227
878.082	53.8205
881.441	52.749
884.799	52.7596
888.156	52.5522
891.512	52.3395
894.866	51.2062
898.22	51.9496
901.573	52.4199
904.924	53.1288
908.271	53.3022
911.62	53.7396
914.966	55.0884
918.312	54.6933
921.656	53.6545
925	51.6807
928.341	50.2784
931.68	49.7616
935.019	46.6285
938.358	44.7555
941.694	44.6744
945.028	44.564
948.362	43.4433
951.694	44.206
955.026	44.3064
958.356	42.7554
961.684	42.3128
965.012	42.1373
968.337	41.5552
971.661	39.0235
974.985	37.9151
978.306	38.27
981.626	37.4748
984.947	35.9397
988.264	35.0658
991.581	34.4299
994.896	32.3638
998.212	29.5066
1001.52	25.8566
1004.84	21.943
1008.15	21.6294
1011.45	23.1981
1014.76	24.9403
1018.07	28.2634
1021.37	32.1686
1024.68	35.1737
1027.98	36.741
1031.28	39.0588
1034.58	41.1624
1037.88	43.0069
1041.18	43.1053
1044.47	44.6604
1047.77	45.182
1051.06	45.2798
1054.35	44.8332
1057.64	45.245
1060.94	43.4911
1064.22	40.251
1067.51	37.8544
1070.8	33.143
1074.08	29.3643
1077.36	25.1091
1080.65	19.6671
1083.93	18.109
1087.21	19.0431
1090.49	19.7604
1093.76	21.1898
1097.04	20.9054
1100.31	20.2116
1103.59	18.9303
1106.86	16.9615
1110.13	16
1113.4	16.4685
1116.66	17.1219
1119.93	16.6675
1123.2	17.9381
1126.46	18.2956
1129.72	17.2988
1132.99	18.4224
1136.25	19.283
1139.51	20.7063
1142.77	19.7846
1146.02	18.9562
1149.28	17.3104
1152.53	15.2352
1155.78	14.005
1159.04	12.9636
1162.29	13.2091
1165.54	12.5813
1168.78	11.3101
1172.03	11.4232
1175.27	11.4736
1178.52	9.65622
1181.76	8.28629
1185	8.02723
1188.24	9.52415
1191.48	10.2333
1194.72	8.76566
1197.96	9.88081
1201.19	9.83606
1204.43	11.6028
1207.66	12.4598
1210.89	13.5413
1214.12	15.0807
1217.35	14.9616
1220.58	16.4806
1223.81	17.5108
1227.03	18.4844
1230.26	16.9856
1233.48	17.9277
1236.7	19.8165
1239.92	20.6713
1243.14	20.7826
1246.36	21.2562
1249.57	22.318
1252.79	23.3144
1256	25.7052
1259.22	27.5843
1262.43	29.7723
1265.64	32.763
1268.85	34.501
1272.06	33.1004
1275.26	34.4548
1278.47	35.8229
1281.67	37.1181
1284.88	37.5669
1288.08	36.4133
1291.28	36.2568
1294.48	36.0887
1297.68	37.4458
1300.87	38.182
1304.07	39.5703
1307.26	38.7168
1310.46	38.7891
1313.65	40.1694
1316.84	41.2457
1320.03	42.1497
1323.22	42.1537
1326.4	42.5455
1329.59	42.6238
1332.78	43.7243
1335.96	44.7318
1339.14	43.2609
1342.32	41.6185
1345.5	40.3501
1348.68	38.8854
1351.86	38.121
1355.03	38.1184
1358.21	37.345
1361.38	35.8405
1364.56	33.606
1367.73	31.7246
1370.9	29.208
1374.07	27.8929
1377.23	26.578
1380.4	26.511
1383.57	26.743
1386.73	26.5771
1389.89	26.5306
1393.05	27.2648
1396.21	27.1423
1399.37	26.7337
1402.53	27.2539
1405.69	27.9014
1408.84	29.3833
1412	28.8811
1415.15	29.4605
1418.3	29.9435
1421.45	31.8878
1424.6	34.6483
1427.75	38.2464
1430.9	40.6419
1434.04	43.1622
1437.19	44.232
1440.33	45.1631
1443.47	46.2489
1446.62	46.8305
1449.76	47.0743
1452.9	47.8356
1456.03	46.9257
1459.17	46.1744
1462.3	44.7076
1465.44	43.674
1468.57	42.6524
1471.7	41.7549
1474.83	40.943
1477.96	39.4445
1481.09	38.2398
1484.22	36.2126
1487.34	34.2047
1490.47	32.84
1493.59	31.2888
1496.71	28.8272
1499.83	28.331
1502.95	28.4584
1506.07	27.8002
1509.19	26.057
1512.3	25.0605
1515.42	22.7029
1518.53	20.8487
1521.65	19.8828
1524.76	17.7401
1527.87	16.8144
1530.98	15.4045
1534.08	14.3817
1537.19	14.3476
1540.3	14.5093
1543.4	14.778
1546.5	15.9644
1549.61	17.3416
1552.71	18.8751
1555.81	20.7561
1558.9	22.288
1562	23.7767
1565.1	24.9197
1568.19	26.4048
1571.29	27.7995
1574.38	28.9803
1577.47	30.2924
1580.56	31.532
1583.65	31.3799
1586.74	30.9715
1589.82	29.7159
1592.91	30.3633
1595.99	31.2282
1599.08	31.9976
1602.16	32.8376
1605.24	33.2725
1608.32	32.5163
1611.4	32.3113
1614.48	32.9002
1617.55	34.0173
1620.63	35.8772
1623.7	38.3618
1626.77	39.2522
1629.84	39.6289
1632.92	40.4061
1635.98	41.3551
1639.05	42.6939
1642.12	42.3119
1645.19	42.4381
1648.25	42.398
1651.31	41.642
1654.38	40.5068
1657.44	39.9596
1660.5	38.6801
1663.56	37.85
1666.61	37.8393
1669.67	36.0504
1672.72	33.9218
1675.78	32.4874
1678.83	30.2756
1681.88	28.0882
1684.93	25.6192
1687.98	23.7846
1691.03	22.9984
1694.08	22.2165
1697.13	21.5861
1700.17	20.0329
1703.21	17.9417
1706.26	18.3247
1709.3	17.9448
1712.34	16.8655
1715.38	14.5725
1718.42	13.0121
1721.45	12.0351
1724.49	10.988
1727.52	10.0968
1730.56	9.75282
1733.59	9.91816
1736.62	8.97937
1739.65	8.71904
1742.68	7.36151
1745.71	5.18886
1748.74	4.82454
1751.76	5.40092
1754.79	5.01837
1757.81	5.13291
1760.83	4.35728
1763.85	4.05429
1766.87	4.21122
1769.89	4.02616
1772.91	4.89545
1775.93	5.42701
1778.94	5.98976
1781.95	6.37745
1784.97	5.69848
1787.98	5.00865
1790.99	5.12831
1794	5.45851
1797.01	5.24071
1800.02	5.47005
1803.02	6.15077
1806.03	6.39251
1809.03	5.91943
1812.03	5.82585
1815.04	5.1463
1818.04	5.16669
1821.04	5.48504
1824.04	4.99059
1827.03	4.00867
1830.03	3.42866
1833.02	3.67934
1836.02	2.3988
1839.01	2.1961
1842	1.55657
1844.99	0.810724
1847.98	0.907064
1850.97	0.590515
1853.96	0.0879673
1856.95	-0.519824
1859.93	0.0553349
1862.91	0.296907
1865.9	0.968536
1868.88	1.74336
1871.86	2.43568
1874.84	3.55931
1877.82	3.73672
1880.79	4.42246
1882.53	4.40578
1885.52	4.90528
1888.51	5.29414
1891.49	4.90078
1894.48	4.02885
1897.46	3.43142
1900.45	3.64816
1903.43	4.29432
1906.41	4.29691
1909.39	4.06946
1912.37	4.16675
1915.35	2.88458
1918.32	3.29141
1921.3	3.49264
1924.27	2.78144
1927.25	2.45481
1930.22	2.63924
1933.19	2.58674
1936.16	2.47464
1939.13	3.6498
1942.1	3.91461
1945.06	4.65479
1948.03	4.39324
1950.99	5.49911
1953.96	5.77608
1956.92	6.99872
1959.88	7.21067
1962.84	5.79917
1965.8	5.65291
1968.76	5.86932
1971.72	6.17002
1974.67	6.56396
1977.63	6.36228
1980.58	6.6203
1983.53	6.34717
1986.48	6.07931
1989.43	6.58995
1992.39	6.17552
1995.33	5.04975
1998.28	5.53159
2001.23	5.26549
2004.17	5.74062
2007.11	5.33862
2010.06	5.45385
2013	5.37895
2015.94	5.80405
2018.88	6.56063
2021.82	7.72262
2024.76	8.76357
2027.69	9.19715
2030.63	8.7879
2033.56	7.74354
2036.5	8.27402
2039.43	9.10713
2042.36	9.75631
2045.29	10.4143
2048.22	10.0999
2051.14	10.7113
2054.07	12.0736
2057	12.6915
2059.92	13.5315
2062.85	14.874
2065.77	15.1856
2068.69	15.0297
2071.61	15.3258
2074.53	15.2628
2077.45	14.3725
2080.36	13.6598
2083.28	13.8273
2086.19	13.9358
2089.11	14.5959
2092.02	14.6076
2094.93	15.2516
2097.84	15.0362
2100.75	15.5729
2103.66	15.039
2106.57	16.2919
2109.48	16.9081
2112.38	17.7538
2115.29	17.9225
2118.19	18.2426
2121.09	20.0221
2123.99	21.5389
2126.89	23.2873
2129.79	24.394
2132.69	25.2595
2135.59	26.3314
2138.48	27.5607
2141.38	28.6184
2144.27	30.8006
2147.16	31.9608
2150.06	32.9952
2152.95	34.5681
2155.83	35.4685
2158.72	35.8727
2161.61	37.0301
2164.5	37.6311
2167.38	37.8995
2170.27	38.0772
2173.15	39.1868
2176.03	38.8436
2178.91	38.9977
2181.79	39.323
2184.67	37.9661
2187.55	37.106
2190.43	36.5372
2193.3	35.0491
2196.18	33.0769
2199.05	31.2047
2201.92	29.357
2204.8	28.211
2207.67	28.1981
2210.54	28.0427
2213.4	27.0253
2216.27	25.8209
2219.14	24.4305
2222	22.958
2224.87	22.0833
2227.73	20.9625
2230.59	21.0691
2233.46	20.4703
2236.32	19.9655
2239.18	20.4857
2242.03	20.2887
2244.89	19.5184
2247.75	18.9786
2250.6	18.3141
2253.45	17.5194
2256.31	17.1015
2259.16	16.2713
2262.01	15.3073
2264.86	14.0512
2267.71	12.6801
2270.56	12.0196
2273.4	11.2351
2276.25	10.9453
2279.09	9.72791
2281.94	8.84401
2284.78	7.13459
2287.62	6.79797
2290.46	5.95424
2293.3	4.85346
2296.14	5.38997
2298.98	6.7749
2301.81	7.17459
2304.65	8.44645
2307.48	9.26724
2310.32	9.95385
2313.15	10.0829
2315.98	10.854
2318.81	11.0157
2321.64	11.4363
2324.47	12.6037
2327.3	12.7882
2330.12	12.4451
2332.95	12.7043
2335.77	12.3337
2338.59	12.2614
2341.42	11.9557
2344.24	10.6393
2347.06	9.58623
2349.88	9.63884
2352.69	8.05796
2355.51	6.14467
2358.33	4.64809
2361.14	3.89112
2363.96	4.14983
2366.77	4.23677
2369.58	4.60026
2372.39	4.92739
2375.2	5.26648
2378.01	5.1845
2380.82	4.71751
2383.63	5.27107
2386.43	5.25551
2389.24	5.29973
2392.04	5.88906
2394.84	6.60532
2397.64	6.175
2400.45	6.6273
2403.25	7.46957
2406.04	7.43562
2408.84	6.69815
2411.64	7.14717
2414.43	7.06815
2417.23	8.08948
2420.02	8.71303
2422.82	8.26826
2425.61	7.93697
2428.4	8.30832
2431.19	8.32112
2433.98	8.52978
2436.76	8.33428
2439.55	8.26697
2442.34	8.74262
2445.12	8.70852
2447.9	7.68802
2450.69	6.84889
2453.47	6.11
2456.25	6.10887
2459.03	5.28733
2461.81	4.45535
2464.59	2.47271
2467.36	1.93339
2470.14	1.99081
2472.91	0.808254
2475.69	-0.12899
2478.46	-0.469245
2481.23	0.118275
2484	0.0976439
2486.77	0.81221
2489.54	0.131819
2492.31	0.469253
2495.08	0.92583
2497.84	0.528169
2500.61	1.36056
2503.37	1.28458
2506.13	0.838895
2508.89	0.981827
2511.66	1.3329
2514.42	0.574697
2517.17	0.881987
2519.93	1.22872
2522.69	2.42354
2525.44	2.94637
2528.2	2.80733
2530.95	2.92148
2533.71	3.77759
2536.46	4.6197
2539.21	5.23172
2541.96	4.97455
2544.71	4.84933
2547.46	5.39923
2550.2	5.64881
2552.95	6.43526
2555.69	6.43759
2558.44	7.19621
2561.18	7.08407
2563.92	5.43129
2566.67	4.93935
2569.41	5.26861
2572.14	4.86325
2574.88	4.1479
2577.62	4.19455
2580.36	3.69681
2583.09	3.69756
2585.83	3.36047
2588.56	3.34047
2591.29	2.7304
2594.02	2.56445
2596.75	2.37198
2599.48	1.88314
2602.21	1.91308
2604.94	1.30785
2607.67	1.24299
2610.39	1.232
2613.12	1.27759
2615.84	1.32552
2618.56	1.08123
2621.28	1.67349
2624	1.42362
2626.72	1.35613
2629.44	2.01718
2632.16	1.89003
2634.88	2.83356
2637.59	3.96629
2640.31	4.61262
2643.02	4.99168
2645.73	4.79507
2648.45	4.48505
2651.16	3.86063
2653.87	4.57203
2656.58	4.48386
2659.28	3.79039
2661.99	4.13698
2664.7	4.48781
2667.4	4.0171
2670.11	3.34361
2672.81	3.63232
2675.51	3.72457
2678.21	3.62544
2680.92	4.04044
2683.62	3.53749
2686.31	3.82758
2689.01	3.21428
2691.71	2.67048
2694.4	2.72507
2697.1	2.75805
2699.79	2.76261
2702.48	3.42172
2705.18	3.61769
2707.87	3.11938
2710.56	3.28418
2713.25	3.62204
2715.93	4.12361
2718.62	5.12091
2721.31	6.43516
2723.99	6.63162
2726.68	7.10625
2729.36	7.59337
2732.04	7.43869
2734.72	7.49424
2737.4	7.82711
2740.08	8.48734
2742.76	7.54784
2745.44	7.39437
2748.12	7.19655
2750.79	5.94797
2753.47	5.58045
2756.14	4.00778
2758.81	4.45858
2761.48	4.09097
2764.16	4.23124
2766.83	4.31305
2769.49	3.39433
2772.16	3.50043
2774.83	3.3916
2777.5	3.75184
2780.16	4.0973
2782.83	4.52817
2785.49	3.74441
2788.15	3.41687
2790.81	2.68599
2793.47	2.04582
2796.13	1.82312
2798.79	1.41899
2801.45	1.25493
2804.11	0.742258
2806.76	0.868728
2809.42	0.621546
2812.07	-0.299688
2814.73	0.0252731
2817.38	1.02866
2820.03	1.60031
2822.68	3.32625
2825.33	5.4
2827.98	6.81498
2830.62	8.66842
2833.27	9.76248
2835.92	10.5977
2838.56	12.5459
2841.2	15.0369
2843.85	17.7328
2846.49	20.2893
2849.13	23.0706
2851.77	26.326
2854.41	30.2327
2857.05	33.7777
2859.68	36.8172
2862.32	39.6546
2864.96	42.4114
2867.59	46.0502
2870.22	48.8437
2872.86	50.8069
2875.49	52.7691
2878.12	55.7091
2880.75	58.449
2883.38	60.8975
2886.01	63.8374
2888.63	66.1672
2891.26	68.5357
2893.88	71.6116
2896.51	74.274
2899.13	77.0151
2901.76	80.5767
2904.38	84.7824
2907	89.1445
2909.62	93.4751
2912.24	99.035
2914.85	104.627
2917.47	108.954
2920.09	113.309
2922.7	117.555
2925.31	121.865
2927.93	124.008
2930.54	125.358
2933.15	125.84
2935.76	125.306
2938.37	123.728
2940.98	120.555
2943.59	117.475
2946.2	113.542
2948.8	109.988
2951.41	106.126
2954.01	100.504
2956.62	95.8084
2959.22	91.1285
2961.82	85.164
2964.42	80.4359
2967.02	75.9532
2969.62	71.8786
2972.21	68.4202
2974.81	65.3849
2977.41	62.5093
2980	58.3449
2982.6	54.9884
2985.19	51.0696
2987.78	47.4584
2990.37	43.3825
2992.96	38.601
2995.55	34.3645
2998.14	30.8181
3000.73	26.3812
3003.32	22.135
3005.9	18.6736
3008.49	16.0058
3011.07	12.9834
3013.66	10.908
3016.24	8.32967
3018.82	5.40013
3021.4	4.25542
3023.98	2.92981
3026.56	2.27428
3029.14	2.78503
3031.71	3.32169
3034.29	3.50685
3036.86	3.69476
3039.44	3.84855
3042.01	3.48125
3044.59	2.93475
3047.16	2.80417
3049.73	3.16226
3052.3	3.65035
3054.87	3.07504
3057.43	2.5297
3060	2.60451
3062.57	2.34235
3065.13	2.06555
3067.7	1.42914
3070.26	1.17905
3072.82	1.11849
3075.39	0.706931
3077.95	1.35259
3080.51	0.586085
3083.07	0.46469
3085.62	0.570843
3088.18	0.780647
3090.74	1.36467
3093.29	1.62198
3095.85	1.32345
3098.4	1.07229
3100.95	0.737194
3103.51	1.47593
3106.06	2.02523
3108.61	1.88219
3111.16	1.14248
3113.71	0.744363
3116.25	0.364878
3118.8	0.520514
3121.34	0.606728
3123.89	0.453889
3126.43	0.826717
3128.98	1.50282
3131.52	2.01495
3134.06	2.48531
3136.6	3.92336
3139.14	5.06892
3141.68	6.32643
3144.22	7.88283
3146.75	9.47794
3149.29	10.4809