File: data/Raman/poly_smoothed/Mb_30_27_26_1x_45s_532 nm_x100_100%_600 gr_mm_01.txt
#Acq. time (s)=	45
#Accumulations=	2
#Range (cm-¹)=	200...3150
#Windows=	2
#Auto scanning=	Off
#Autofocus=	Off
#Macrospot=	Off
#AutoExposure=	Off
#Spike filter=	Multiple accum.
#Delay time (s)=	0
#Binning=	1
#Readout mode=	Signal
#DeNoise=	Off
#ICS correction=	On
#Dark correction=	Off
#Inst. Process=	Off
#Detector Gain=	Best Dynamic Range
#Detector ADC=	20 kHz
#Detector temperature (°C)=	-69.85
#Instrument=	LabRAM HR Evol
#Detector=	Synapse
#Objective=	x100
#Grating=	600 gr/mm
#ND Filter=	100%
#Laser (nm)=	532
#Hole=	100.021
#Range=	Auto
#Laser Pol.=	No
#Raman. Pol.=	No
#Laser Pol. (°)=	-0.0007625
#Raman Pol. (°)=	89.9995
#Collection=	Microscope
#StageXY=	Marzhauser
#StageZ=	Marzhauser
#X (µm)=	-6377.8
#Y (µm)=	843.8
#Z (µm)=	-64.8
#Full time(mm:ss)=	3:18
#Project=
#Sample=
#Site=
#Title=	Mb_30_27_26_2x_45s_532 nm_x100_100%_600 gr_mm
#Remark=
#Date=	13.07.2022 10:39
#Acquired=	13.07.2022 10:39:07
#Base:Fit=	10.08.2022 10:40:03
#Base:Sub=	10.08.2022 10:40:17
#Filter:Polynom=	16.08.2022 10:16:15
#AxisType[0]=Intens
#AxisUnit[0]=Cnt
#AxisType[1]=Spectr
#AxisUnit[1]=1/cm
200.563	28.4286
204.194	26.9987
207.821	23.2547
211.449	21.0073
215.074	19.0666
218.699	16.8267
222.321	15.053
225.941	12.578
229.562	10.9258
233.18	9.81937
236.796	8.43385
240.411	6.6393
244.026	5.4749
247.638	5.13581
251.248	5.35477
254.857	3.61424
258.465	2.46121
262.071	3.59752
265.678	3.74005
269.282	4.69843
272.884	5.52905
276.484	6.18073
280.084	5.9376
283.682	6.08374
287.276	5.16141
290.871	3.94562
294.465	3.95725
298.057	5.27592
301.648	5.15334
305.237	6.21844
308.823	6.069
312.41	6.00563
315.995	5.70444
319.579	6.83089
323.16	6.29685
326.741	5.59672
330.321	6.7362
333.897	6.83268
337.474	6.94422
341.048	5.83483
344.622	5.18014
348.192	4.65976
351.764	5.3173
355.332	5.38969
358.901	4.94401
362.466	4.70982
366.03	4.81968
369.594	2.93899
373.155	3.52912
376.715	1.76249
380.273	0.614863
383.832	0.937388
387.388	2.43756
390.942	4.49148
394.495	4.91117
398.047	4.35091
401.597	4.05024
405.145	5.76581
408.693	6.16884
412.239	6.09817
415.783	7.009
419.327	5.88436
422.869	6.55667
426.409	8.64046
429.948	9.06608
433.486	8.65497
437.022	8.69505
440.558	8.26562
444.089	7.68623
447.622	7.69441
451.153	7.37289
454.682	7.24481
458.208	7.98721
461.735	8.07203
465.259	9.10601
468.783	9.88411
472.306	12.3169
475.825	12.5428
479.346	12.5562
482.862	13.6992
486.38	13.7975
489.894	16.2602
493.407	18.4422
496.92	19.9108
500.43	20.043
503.939	21.7815
507.448	22.7899
510.954	24.5759
514.459	25.3234
517.962	22.5879
521.466	21.7866
524.966	20.7857
528.466	19.9519
531.964	18.4982
535.46	18.9551
538.955	18.9873
542.449	18.0011
545.942	17.6846
549.433	17.5465
552.923	17.1191
556.412	16.1747
559.899	14.0911
563.385	12.9483
566.867	11.9871
570.35	11.3413
573.832	10.7773
577.313	10.0601
580.79	8.71032
584.268	7.57973
587.745	6.19471
591.218	6.16038
594.692	4.41418
598.164	4.63003
601.634	4.67322
605.104	5.28239
608.57	5.65169
612.037	6.26376
615.501	5.94295
618.966	6.76791
622.427	6.49031
625.887	6.47765
629.348	8.45793
632.806	8.63149
636.262	8.28782
639.716	7.71091
643.172	7.0288
646.624	7.47865
650.075	8.19951
653.524	9.35962
656.972	10.2314
660.419	10.4757
663.865	10.4675
667.309	10.1046
670.752	11.2142
674.194	11.5422
677.634	14.2565
681.073	17.8261
684.511	19.2294
687.947	21.861
691.382	24.2013
694.816	27.9172
698.247	29.0162
701.678	31.3865
705.108	33.5198
708.534	34.7246
711.962	36.4165
715.388	36.0165
718.81	36.7998
722.234	37.0579
725.654	38.0886
729.075	37.6348
732.492	39.9474
735.91	39.9831
739.325	39.6198
742.741	40.6506
746.153	40.7078
749.564	43.3737
752.976	47.9107
756.385	49.9974
759.792	53.4767
763.2	57.0963
766.604	59.9969
770.008	63.2088
773.41	66.5719
776.811	69.0342
780.21	71.7446
783.608	73.9085
787.005	76.9768
790.401	78.1627
793.795	78.4511
797.188	78.8029
800.58	81.1401
803.971	82.0606
807.36	82.9811
810.748	81.4785
814.135	82.2414
817.518	82.1631
820.902	81.5718
824.285	81.2339
827.665	81.5532
831.045	81.0694
834.424	82.0273
837.8	81.1678
841.177	79.0359
844.55	76.1425
847.924	73.5612
851.295	71.787
854.666	68.6398
858.034	67.0777
861.403	65.162
864.769	63.8819
868.133	61.7153
871.498	60.1365
874.86	58.5515
878.221	58.081
881.58	57.5066
884.938	58.086
888.297	55.9489
891.653	55.1014
895.007	54.5142
898.36	54.9733
901.712	53.5104
905.063	54.4631
908.412	54.5973
911.76	55.6901
915.107	56.3161
918.452	56.927
921.797	55.2321
925.138	52.9714
928.48	52.4607
931.82	51.9772
935.16	51.9797
938.496	51.7048
941.833	51.9922
945.168	49.4853
948.5	46.5956
951.834	46.4809
955.163	44.9343
958.494	43.8738
961.821	41.4002
965.15	40.4388
968.474	40.8023
971.8	41.1048
975.123	41.9156
978.446	41.9715
981.766	40.5661
985.084	39.5179
988.402	39.4161
991.72	38.3098
995.035	38.0524
998.349	35.0842
1001.66	31.7235
1004.97	30.2846
1008.28	30.5063
1011.59	31.557
1014.9	34.776
1018.21	37.7619
1021.51	39.5305
1024.81	41.241
1028.12	42.1448
1031.42	43.5058
1034.72	45.2063
1038.02	44.8329
1041.31	45.694
1044.61	46.9205
1047.91	48.9826
1051.2	49.4874
1054.49	47.4368
1057.78	44.1786
1061.07	42.1816
1064.36	39.2473
1067.65	35.4813
1070.93	34.265
1074.22	31.4058
1077.5	26.5538
1080.78	22.9538
1084.06	21.6288
1087.34	21.1377
1090.62	20.7613
1093.9	22.6393
1097.17	24.418
1100.45	25.3423
1103.72	27.8323
1106.99	27.4709
1110.27	25.3752
1113.53	23.2805
1116.8	23.1279
1120.07	22.5586
1123.33	22.0635
1126.6	19.9958
1129.86	18.8701
1133.12	16.2462
1136.38	15.2725
1139.64	14.4536
1142.9	12.9211
1146.16	11.394
1149.41	10.2063
1152.67	9.77155
1155.92	5.6734
1159.17	4.24969
1162.42	2.53444
1165.67	2.14237
1168.92	1.29569
1172.16	1.79128
1175.41	3.21514
1178.65	3.04165
1181.9	1.21783
1185.14	0.719679
1188.38	1.55978
1191.62	1.67891
1194.86	3.13343
1198.09	5.85563
1201.33	6.55357
1204.56	8.10386
1207.8	11.1133
1211.03	14.0517
1214.26	17.9006
1217.49	21.3913
1220.71	24.3439
1223.94	28.5962
1227.16	32.4002
1230.39	35.1108
1233.61	37.9702
1236.83	40.6066
1240.05	44.2708
1243.27	45.4239
1246.49	48.3635
1249.71	50.9582
1252.92	52.4954
1256.14	54.3642
1259.35	56.2006
1262.56	59.3436
1265.77	61.6526
1268.98	66.6716
1272.19	67.8412
1275.4	70.4706
1278.6	70.7342
1281.81	72.2402
1285.01	74.2642
1288.21	75.1454
1291.41	75.7158
1294.61	76.7575
1297.81	78.9907
1301.01	79.5701
1304.2	79.4992
1307.4	78.599
1310.59	79.9713
1313.78	79.3768
1316.97	78.8278
1320.16	79.732
1323.35	77.8677
1326.54	76.9124
1329.72	75.5186
1332.91	74.6924
1336.09	72.1012
1339.27	70.1543
1342.45	67.9284
1345.64	67.5143
1348.81	65.9222
1351.99	61.2465
1355.17	58.1301
1358.34	53.8586
1361.51	51.7906
1364.69	48.7781
1367.86	46.0049
1371.03	41.7567
1374.2	39.3799
1377.37	38.3026
1380.53	35.4356
1383.7	33.0713
1386.86	31.7463
1390.02	30.8543
1393.19	29.9041
1396.35	28.1955
1399.51	27.0444
1402.66	25.2767
1405.82	25.413
1408.97	26.6131
1412.13	28.077
1415.28	31.3737
1418.43	36.0341
1421.59	41.8942
1424.73	47.9318
1427.88	52.4104
1431.03	57.6489
1434.18	62.4188
1437.32	66.7827
1440.46	71.9928
1443.61	72.6307
1446.75	74.7833
1449.89	76.1439
1453.03	76.5914
1456.16	75.1278
1459.3	72.1206
1462.44	69.6864
1465.57	66.9703
1468.7	63.3441
1471.83	58.0568
1474.96	52.9653
1478.09	47.394
1481.22	43.3501
1484.35	39.6688
1487.47	34.4733
1490.6	31.369
1493.72	30.0429
1496.84	27.6098
1499.96	24.9927
1503.08	22.7312
1506.2	20.4433
1509.32	18.2032
1512.44	16.6921
1515.55	14.9421
1518.66	12.8877
1521.78	11.9512
1524.89	12.2657
1528	12.8805
1531.11	12.7558
1534.21	13.1832
1537.32	14.7859
1540.43	15.2042
1543.53	16.2405
1546.63	17.6734
1549.74	18.5631
1552.84	19.4645
1555.94	21.5895
1559.03	22.5044
1562.13	24.0475
1565.23	26.2133
1568.32	27.6562
1571.42	29.7974
1574.51	32.9487
1577.6	36.4933
1580.69	39.0076
1583.78	40.991
1586.87	42.2046
1589.95	43.9375
1593.04	47.0238
1596.12	48.0726
1599.21	49.3762
1602.29	50.1353
1605.37	51.4044
1608.45	51.9212
1611.53	52.5488
1614.6	50.9364
1617.68	53.9602
1620.75	54.6215
1623.83	57.0264
1626.9	59.6493
1629.97	61.9422
1633.04	64.4345
1636.11	68.5103
1639.18	72.7209
1642.25	76.4133
1645.31	80.7813
1648.38	84.3041
1651.44	88.2607
1654.5	89.9649
1657.56	90.4003
1660.62	91.7408
1663.68	91.8343
1666.74	92.0478
1669.8	89.5636
1672.85	85.2063
1675.91	79.8652
1678.96	75.2117
1682.01	68.7907
1685.06	61.7128
1688.11	55.3165
1691.16	49.1634
1694.21	44.4854
1697.25	37.7802
1700.3	33.9779
1703.34	27.5809
1706.39	21.4857
1709.43	17.2942
1712.47	14.4197
1715.51	11.9699
1718.54	11.032
1721.58	8.24498
1724.62	7.89749
1727.65	6.84234
1730.68	7.69879
1733.72	7.92461
1736.75	8.82766
1739.78	8.16382
1742.81	8.36302
1745.84	8.3547
1748.86	8.77485
1751.89	8.86983
1754.91	8.58201
1757.93	8.1846
1760.96	7.67711
1763.98	8.11658
1767	7.6666
1770.02	7.07938
1773.03	6.12293
1776.05	5.34959
1779.07	4.28132
1782.08	4.5889
1785.09	5.5649
1788.11	6.18977
1791.12	6.89552
1794.13	6.007
1797.13	5.10561
1800.14	4.66422
1803.15	5.18566
1806.15	5.16707
1809.16	5.05024
1812.16	4.50639
1815.16	5.02475
1818.16	5.85185
1821.16	5.52086
1824.16	4.91143
1827.16	4.51116
1830.16	4.24278
1833.15	3.62783
1836.14	2.81242
1839.14	2.25758
1842.13	1.37223
1845.12	1.25917
1848.11	0.994344
1851.1	1.1528
1854.08	1.21469
1857.07	1.52211
1860.05	2.17702
1863.04	2.05396
1866.02	1.95954
1869	2.80424
1871.98	2.95019
1874.96	3.55517
1877.94	4.85117
1880.92	4.67374
1882.51	5.46144
1885.5	6.44093
1888.48	7.04658
1891.47	7.6355
1894.46	8.4781
1897.44	7.66632
1900.42	8.66044
1903.41	7.54485
1906.39	7.36372
1909.37	7.82301
1912.35	8.34248
1915.32	8.7425
1918.3	8.34576
1921.27	7.77583
1924.25	7.59291
1927.22	7.01406
1930.19	6.28159
1933.17	5.4576
1936.14	4.5494
1939.11	3.63092
1942.07	3.67765
1945.04	2.6793
1948.01	2.4818
1950.97	1.86656
1953.93	1.90566
1956.9	1.54564
1959.86	2.17058
1962.82	2.05262
1965.78	2.31112
1968.74	2.8746
1971.69	3.67463
1974.65	5.12861
1977.6	6.61937
1980.56	7.94577
1983.51	9.10048
1986.46	10.1757
1989.41	9.99188
1992.36	10.1494
1995.31	9.84195
1998.26	9.12024
2001.2	8.96365
2004.15	9.42773
2007.09	9.06676
2010.04	9.46597
2012.98	9.65052
2015.92	10.3829
2018.86	10.2138
2021.8	10.3616
2024.73	10.492
2027.67	10.8856
2030.61	11.6298
2033.54	12.1925
2036.47	12.1347
2039.4	12.2411
2042.33	14.0577
2045.27	13.9637
2048.19	14.6483
2051.12	15.2487
2054.05	15.2646
2056.97	15.8408
2059.9	16.4628
2062.82	16.0434
2065.74	16.4749
2068.67	16.5379
2071.59	17.0291
2074.51	17.5056
2077.42	17.583
2080.34	17.7955
2083.26	18.811
2086.17	21.3951
2089.09	22.464
2092	23.3219
2094.91	24.9177
2097.82	27.1873
2100.73	29.0555
2103.64	31.3816
2106.55	33.4658
2109.45	35.2272
2112.36	37.8087
2115.26	39.8611
2118.17	42.101
2121.07	45.0598
2123.97	49.7709
2126.87	52.7318
2129.77	56.9402
2132.67	59.9095
2135.56	63.4573
2138.46	66.0708
2141.35	69.4871
2144.25	74.2007
2147.14	76.3569
2150.03	80.1351
2152.92	84.0515
2155.81	87.5929
2158.7	90.6101
2161.59	92.5991
2164.47	94.6463
2167.36	96.7816
2170.24	97.2392
2173.13	98.3212
2176.01	97.7305
2178.89	96.3232
2181.77	95.6328
2184.65	94.7516
2187.53	91.813
2190.4	89.1394
2193.28	86.338
2196.16	83.6192
2199.03	80.4228
2201.9	76.5805
2204.77	71.9367
2207.64	67.9162
2210.51	64.7768
2213.38	61.4661
2216.25	58.2857
2219.12	54.0883
2221.98	51.1901
2224.85	48.0511
2227.71	45.7147
2230.57	42.9632
2233.43	40.3848
2236.29	38.0537
2239.15	34.8935
2242.01	32.4816
2244.87	30.6529
2247.72	28.984
2250.58	28.1821
2253.43	27.4568
2256.29	24.8478
2259.14	23.4849
2261.99	21.7381
2264.84	21.1883
2267.69	20.726
2270.53	18.6925
2273.38	17.5044
2276.23	15.2756
2279.07	14.9729
2281.91	14.9884
2284.76	13.9016
2287.6	13.9468
2290.44	11.8469
2293.28	10.2037
2296.12	10.8729
2298.96	11.1731
2301.79	11.188
2304.63	12.042
2307.46	11.9343
2310.3	12.1415
2313.13	12.6909
2315.96	12.5552
2318.79	12.2308
2321.62	12.2172
2324.45	12.0795
2327.27	12.5595
2330.1	12.0021
2332.92	11.3871
2335.75	10.7957
2338.57	9.73837
2341.39	8.65406
2344.21	6.9187
2347.04	5.82849
2349.85	5.06788
2352.67	3.68395
2355.49	2.68795
2358.3	2.07032
2361.12	1.37972
2363.93	2.66875
2366.75	4.23964
2369.56	3.72867
2372.37	3.17266
2375.18	3.82207
2377.99	3.47268
2380.8	3.3269
2383.6	3.01547
2386.41	2.18295
2389.21	2.89749
2392.02	3.70196
2394.82	3.23307
2397.62	3.29159
2400.42	3.01543
2403.22	3.17389
2406.02	2.95168
2408.82	3.08476
2411.62	2.34724
2414.41	2.64821
2417.21	3.68285
2420	3.8645
2422.79	4.95267
2425.59	5.09703
2428.38	5.18327
2431.17	5.61411
2433.95	5.75484
2436.74	5.84854
2439.53	5.69618
2442.31	5.20233
2445.1	5.54926
2447.88	5.61753
2450.67	5.75593
2453.45	5.67958
2456.23	6.49531
2459.01	6.95054
2461.79	6.60216
2464.57	7.04308
2467.34	7.25024
2470.12	6.49799
2472.89	6.25968
2475.67	5.05619
2478.44	6.09599
2481.21	5.73201
2483.98	5.49022
2486.75	4.79675
2489.52	4.30248
2492.29	2.70049
2495.05	0.921448
2497.82	1.0496
2500.58	0.268568
2503.35	-0.58404
2506.11	-1.56281
2508.87	-2.64531
2511.63	-3.02454
2514.39	-2.09733
2517.15	-2.21343
2519.91	-2.17837
2522.67	-1.16792
2525.42	-0.716732
2528.18	0.218065
2530.93	1.78882
2533.69	2.41702
2536.44	3.0296
2539.19	3.4852
2541.94	3.57715
2544.69	4.47807
2547.44	5.04904
2550.18	4.68264
2552.93	6.13457
2555.67	6.50615
2558.42	7.37718
2561.16	6.5177
2563.9	6.66663
2566.64	6.85279
2569.38	6.40012
2572.12	5.54031
2574.86	4.81889
2577.6	3.66267
2580.33	2.93125
2583.07	2.85325
2585.8	3.46441
2588.54	4.32297
2591.27	5.44024
2594	5.6358
2596.73	5.37847
2599.46	5.42685
2602.19	4.71439
2604.92	4.8477
2607.64	4.28809
2610.37	4.15061
2613.09	4.42978
2615.82	4.8528
2618.54	5.46839
2621.26	5.63962
2623.98	5.39855
2626.7	5.12435
2629.42	4.94282
2632.14	4.41105
2634.86	3.81891
2637.57	3.64987
2640.29	3.52836
2643	3.51156
2645.71	4.12224
2648.43	4.99607
2651.14	5.45397
2653.85	5.91956
2656.56	6.11299
2659.26	6.31359
2661.97	6.03542
2664.68	5.39435
2667.38	5.14022
2670.09	5.00708
2672.79	5.7911
2675.49	5.24415
2678.19	5.92571
2680.89	6.4771
2683.59	6.05239
2686.29	6.42479
2688.99	6.15634
2691.69	5.93715
2694.38	5.93364
2697.08	6.01455
2699.77	5.32968
2702.46	5.62724
2705.15	6.67378
2707.85	6.66486
2710.54	7.57573
2713.22	7.5719
2715.91	7.14032
2718.6	7.10665
2721.29	7.05341
2723.97	7.3942
2726.66	7.01953
2729.34	7.11478
2732.02	7.22708
2734.7	7.28318
2737.38	6.62408
2740.06	6.59562
2742.74	6.54354
2745.42	6.29005
2748.09	6.20455
2750.77	5.87024
2753.45	5.36277
2756.12	5.71589
2758.79	5.3609
2761.46	5.07334
2764.14	4.66738
2766.8	5.08773
2769.47	5.28688
2772.14	4.66156
2774.81	3.8482
2777.48	3.53964
2780.14	2.63709
2782.8	2.21147
2785.47	1.59124
2788.13	1.35172
2790.79	0.42396
2793.45	1.27469
2796.11	0.712122
2798.77	0.20988
2801.43	-0.175519
2804.09	-0.451454
2806.74	-0.584516
2809.4	-0.758856
2812.05	-0.560867
2814.71	0.358267
2817.36	1.98479
2820.01	3.90573
2822.66	6.84541
2825.31	9.60239
2827.96	12.8713
2830.6	16.7069
2833.25	21.087
2835.9	25.2377
2838.54	30.2825
2841.18	36.1215
2843.83	43.0285
2846.47	51.1577
2849.11	59.8204
2851.75	68.6368
2854.39	77.4117
2857.03	86.4634
2859.66	95.5763
2862.3	104.243
2864.94	111.49
2867.57	117.82
2870.2	124.271
2872.84	130.105
2875.47	135.611
2878.1	141.49
2880.73	147.068
2883.36	152.341
2885.99	156.131
2888.61	159.711
2891.24	164.857
2893.86	170.087
2896.49	175.695
2899.11	181.33
2901.73	189.169
2904.36	197.774
2906.98	207.064
2909.6	217.304
2912.21	228.296
2914.83	238.862
2917.45	247.933
2920.07	257.563
2922.68	265.232
2925.29	272.079
2927.91	276.409
2930.52	279.723
2933.13	281.147
2935.74	280.199
2938.35	278.429
2940.96	274.381
2943.57	269.485
2946.18	261.907
2948.78	252.828
2951.39	242.712
2953.99	231.996
2956.59	220.731
2959.2	209.092
2961.8	198.112
2964.4	186.455
2967	175.367
2969.6	164.276
2972.19	154.842
2974.79	144.523
2977.39	133.256
2979.98	122.72
2982.58	112.178
2985.17	102.865
2987.76	92.8832
2990.35	83.2689
2992.94	74.1438
2995.53	65.4948
2998.12	57.3715
3000.71	50.1006
3003.3	43.252
3005.88	37.3318
3008.47	32.5583
3011.05	27.7939
3013.64	24.2573
3016.22	19.8577
3018.8	16.6428
3021.38	13.7782
3023.96	11.6621
3026.54	10.5039
3029.12	9.54761
3031.69	9.09829
3034.27	8.86816
3036.84	7.95749
3039.42	7.76124
3041.99	8.40389
3044.57	9.3153
3047.14	9.88325
3049.71	10.4766
3052.28	10.4757
3054.85	10.272
3057.41	10.3262
3059.98	9.93267
3062.55	10.4574
3065.11	9.88323
3067.68	9.27775
3070.24	9.16369
3072.8	8.42691
3075.36	7.46456
3077.93	6.28219
3080.49	4.14683
3083.04	2.82283
3085.6	1.67111
3088.16	1.34928
3090.72	-0.0272196
3093.27	-0.628272
3095.83	-1.50326
3098.38	-2.29293
3100.93	-1.85666
3103.49	-0.987189
3106.04	-0.100397
3108.59	0.243413
3111.14	1.47332
3113.69	2.11844
3116.23	2.49604
3118.78	3.47729
3121.33	4.36575
3123.87	5.67355
3126.41	6.92761
3128.96	8.07657
3131.5	9.15695
3134.04	10.1118
3136.58	11.8325
3139.12	13.0058
3141.66	14.2584
3144.2	15.2254
3146.74	16.0171
3149.27	17.4499