File: data/Raman/poly_smoothed/Mb_30_27_08_1x_45s_532 nm_x100_100%_600 gr_mm_03.txt
#Acq. time (s)=	45
#Accumulations=	2
#Range (cm-¹)=	200...3150
#Windows=	2
#Auto scanning=	Off
#Autofocus=	Off
#Macrospot=	Off
#AutoExposure=	Off
#Spike filter=	Multiple accum.
#Delay time (s)=	0
#Binning=	1
#Readout mode=	Signal
#DeNoise=	Off
#ICS correction=	On
#Dark correction=	Off
#Inst. Process=	Off
#Detector Gain=	Best Dynamic Range
#Detector ADC=	20 kHz
#Detector temperature (°C)=	-69.85
#Instrument=	LabRAM HR Evol
#Detector=	Synapse
#Objective=	x100
#Grating=	600 gr/mm
#ND Filter=	100%
#Laser (nm)=	532
#Hole=	100.021
#Range=	Auto
#Laser Pol.=	No
#Raman. Pol.=	No
#Laser Pol. (°)=	-0.0007625
#Raman Pol. (°)=	89.9995
#Collection=	Microscope
#StageXY=	Marzhauser
#StageZ=	Marzhauser
#X (µm)=	-1270.9
#Y (µm)=	1616.1
#Z (µm)=	-6.35
#Full time(mm:ss)=	3:18
#Project=
#Sample=
#Site=
#Title=	Mb_30_27_08_2x_45s_532 nm_x100_100%_600 gr_mm
#Remark=
#Date=	12.07.2022 16:34
#Acquired=	12.07.2022 16:34:44
#Base:Fit=	10.08.2022 10:39:47
#Base:Sub=	10.08.2022 10:39:55
#Base:Fit=	10.08.2022 10:40:03
#Base:Sub=	10.08.2022 10:40:17
#Filter:Polynom=	16.08.2022 10:16:15
#AxisType[0]=Intens
#AxisUnit[0]=Cnt
#AxisType[1]=Spectr
#AxisUnit[1]=1/cm
200.413	22.337
204.042	16.2588
207.671	12.272
211.297	9.44983
214.924	7.00026
218.547	5.66228
222.169	6.27195
225.792	6.40554
229.411	5.63117
233.028	6.75894
236.647	8.00432
240.261	8.81589
243.875	9.72605
247.487	10.4078
251.099	12.067
254.708	12.3772
258.316	12.473
261.922	13.1044
265.527	14.1373
269.131	16.6195
272.733	15.6147
276.334	14.646
279.933	13.8344
283.531	14.6676
287.128	13.7622
290.723	11.875
294.316	11.2228
297.909	11.73
301.498	10.1927
305.087	9.88923
308.675	10.4464
312.262	10.8158
315.845	10.6778
319.429	10.6729
323.012	10.5805
326.591	11.4449
330.171	10.85
333.749	10.1371
337.324	9.86529
340.9	9.8152
344.472	10.4907
348.045	10.3974
351.614	11.0164
355.185	11.8841
358.751	11.821
362.317	9.79061
365.883	9.39626
369.445	9.77952
373.006	7.76705
376.568	7.94503
380.126	6.17727
383.683	7.07802
387.239	4.72619
390.793	4.17905
394.348	3.09088
397.9	4.20451
401.45	2.94256
404.999	4.07559
408.546	2.8219
412.092	2.72672
415.637	2.92974
419.18	4.17291
422.722	3.46795
426.263	2.7519
429.802	3.52111
433.338	2.27911
436.874	3.24882
440.41	4.34239
443.943	5.60623
447.476	5.6648
451.005	6.92216
454.534	9.19233
458.063	10.2551
461.588	11.2351
465.113	12.4945
468.638	13.1407
472.158	14.0888
475.68	15.7222
479.198	16.5478
482.717	18.2245
486.233	20.571
489.747	19.7234
493.261	19.7839
496.773	18.7118
500.285	20.2438
503.794	21.4894
507.301	19.1584
510.807	17.9205
514.314	18.0334
517.817	18.2832
521.319	17.8292
524.82	18.1186
528.319	17.5017
531.817	17.4135
535.316	16.3888
538.811	15.7711
542.305	14.8449
545.798	13.1834
549.289	12.956
552.777	11.4234
556.265	11.3003
559.753	11.2287
563.239	11.0612
566.723	10.9026
570.207	11.1473
573.688	9.55404
577.167	8.23873
580.646	7.30916
584.124	7.80912
587.599	7.39067
591.074	6.63096
594.548	6.50326
598.019	6.82284
601.49	8.40074
604.958	7.72168
608.427	7.17263
611.892	7.03651
615.358	7.2028
618.821	6.88168
622.282	5.50548
625.744	8.68315
629.203	9.37956
632.661	10.7409
636.119	12.1236
639.574	13.0063
643.027	13.6392
646.479	14.8915
649.932	15.1444
653.382	15.0136
656.83	15.2817
660.277	16.9047
663.722	16.6736
667.167	17.3967
670.61	19.2857
674.051	21.329
677.492	23.2544
680.931	25.5787
684.369	27.3559
687.803	28.8232
691.238	32.143
694.672	32.6066
698.105	36.2082
701.536	37.4979
704.964	39.3519
708.393	41.2116
711.82	44.4008
715.244	44.2162
718.669	45.4654
722.09	45.5492
725.512	43.4066
728.933	43.3897
732.351	43.3815
735.767	42.8387
739.184	44.3046
742.598	44.9858
746.012	44.7444
749.423	46.1213
752.833	47.5302
756.244	49.3052
759.651	50.6725
763.057	52.5337
766.462	54.7226
769.865	56.3299
773.269	60.1457
776.67	61.9812
780.069	64.7648
783.468	66.6344
786.865	67.3971
790.26	68.9721
793.655	71.0403
797.048	72.5513
800.44	73.9589
803.83	73.8092
807.218	73.2009
810.606	73.2788
813.993	72.5175
817.378	72.7375
820.762	71.2659
824.143	70.8766
827.525	69.6142
830.905	69.7899
834.282	68.0006
837.66	67.5772
841.035	66.4994
844.41	65.4975
847.782	64.1296
851.155	63.7755
854.525	61.0985
857.895	59.1964
861.262	56.7332
864.628	54.3588
867.994	52.5997
871.357	51.2131
874.719	49.5455
878.082	48.6959
881.441	47.483
884.799	48.0494
888.156	46.4915
891.512	45.9359
894.866	44.3763
898.22	43.7766
901.573	43.0006
904.924	42.5649
908.271	43.0716
911.62	44.5454
914.966	45.2742
918.312	45.1138
921.656	46.2822
925	45.153
928.341	43.5085
931.68	43.6254
935.019	41.8678
938.358	40.1675
941.694	39.3641
945.028	37.5559
948.362	35.1234
951.694	33.0341
955.026	31.2667
958.356	29.67
961.684	27.6643
965.012	26.7243
968.337	26.962
971.661	24.5546
974.985	23.6131
978.306	21.8752
981.626	21.3129
984.947	21.0445
988.264	20.0647
991.581	18.7481
994.896	17.9336
998.212	14.6758
1001.52	11.4581
1004.84	9.08405
1008.15	10.8395
1011.45	16.077
1014.76	24.2706
1018.07	33.6945
1021.37	42.696
1024.68	51.7922
1027.98	60.3363
1031.28	67.1673
1034.58	71.7602
1037.88	74.7951
1041.18	77.9581
1044.47	78.8479
1047.77	80.0297
1051.06	79.9978
1054.35	75.4797
1057.64	70.9078
1060.94	65.3953
1064.22	57.7338
1067.51	48.4543
1070.8	38.194
1074.08	30.4899
1077.36	20.6808
1080.65	12.808
1083.93	5.99808
1087.21	5.10598
1090.49	8.07512
1093.76	10.0867
1097.04	11.5507
1100.31	12.2375
1103.59	13.0036
1106.86	15.4124
1110.13	15.4911
1113.4	13.9948
1116.66	14.506
1119.93	12.2465
1123.2	12.2886
1126.46	9.81619
1129.72	10.5179
1132.99	9.82798
1136.25	7.90015
1139.51	7.41082
1142.77	6.83459
1146.02	6.76353
1149.28	6.09087
1152.53	4.55754
1155.78	4.60453
1159.04	4.10947
1162.29	3.51858
1165.54	2.40283
1168.78	3.46543
1172.03	2.86964
1175.27	2.33361
1178.52	2.40413
1181.76	3.09854
1185	5.38401
1188.24	6.48963
1191.48	7.62544
1194.72	8.5048
1197.96	9.83566
1201.19	11.1212
1204.43	12.0535
1207.66	13.376
1210.89	14.8023
1214.12	16.3562
1217.35	18.4568
1220.58	19.2951
1223.81	20.0534
1227.03	20.6735
1230.26	21.2489
1233.48	22.2753
1236.7	22.8053
1239.92	24.7377
1243.14	25.5536
1246.36	24.908
1249.57	25.9174
1252.79	24.2218
1256	24.0581
1259.22	25.638
1262.43	26.537
1265.64	26.0935
1268.85	26.5587
1272.06	28.221
1275.26	29.0754
1278.47	30.6055
1281.67	30.4439
1284.88	31.1815
1288.08	33.201
1291.28	34.2065
1294.48	37.1521
1297.68	37.4426
1300.87	39.992
1304.07	41.5851
1307.26	42.8105
1310.46	45.3679
1313.65	47.0838
1316.84	48.7841
1320.03	50.0146
1323.22	49.6266
1326.4	50.9539
1329.59	52.0019
1332.78	51.986
1335.96	51.7537
1339.14	51.4795
1342.32	49.5273
1345.5	48.7942
1348.68	49.4441
1351.86	47.6387
1355.03	46.2757
1358.21	45.4095
1361.38	44.6441
1364.56	41.0657
1367.73	39.6829
1370.9	37.4455
1374.07	36.3276
1377.23	33.5565
1380.4	34.3752
1383.57	33.7069
1386.73	33.6549
1389.89	34.1845
1393.05	34.8802
1396.21	34.462
1399.37	35.7237
1402.53	35.6624
1405.69	36.7027
1408.84	37.0489
1412	37.7845
1415.15	39.3876
1418.3	40.7603
1421.45	42.3007
1424.6	44.1149
1427.75	45.9838
1430.9	48.2107
1434.04	51.451
1437.19	52.8311
1440.33	52.7304
1443.47	52.5466
1446.62	53.1105
1449.76	54.3915
1452.9	55.0112
1456.03	55.0223
1459.17	56.8524
1462.3	58.0818
1465.44	58.2749
1468.57	58.2295
1471.7	58.2924
1474.83	56.91
1477.96	57.1458
1481.09	56.1049
1484.22	55.9112
1487.34	54.1029
1490.47	50.938
1493.59	48.1647
1496.71	45.3313
1499.83	43.0703
1502.95	40.6428
1506.07	37.7351
1509.19	36.0331
1512.3	32.5064
1515.42	27.4855
1518.53	24.7918
1521.65	22.8117
1524.76	22.3984
1527.87	22.4118
1530.98	21.7036
1534.08	22.9007
1537.19	24.3996
1540.3	25.8671
1543.4	27.0397
1546.5	28.5694
1549.61	31.0202
1552.71	32.8084
1555.81	34.0466
1558.9	34.3994
1562	33.0909
1565.1	34.3663
1568.19	34.4312
1571.29	33.8309
1574.38	35.0199
1577.47	36.3425
1580.56	36.188
1583.65	36.1561
1586.74	36.8326
1589.82	36.7703
1592.91	37.9241
1595.99	41.0968
1599.08	41.3362
1602.16	41.4272
1605.24	42.391
1608.32	42.9968
1611.4	44.134
1614.48	45.4643
1617.55	44.8852
1620.63	44.6485
1623.7	44.2468
1626.77	44.9785
1629.84	45.0586
1632.92	44.4751
1635.98	43.3628
1639.05	44.0349
1642.12	44.4499
1645.19	44.0556
1648.25	44.7297
1651.31	45.695
1654.38	46.5033
1657.44	44.8704
1660.5	43.6257
1663.56	42.5828
1666.61	41.9588
1669.67	40.589
1672.72	38.8799
1675.78	36.6807
1678.83	35.3655
1681.88	31.9498
1684.93	29.1526
1687.98	26.8533
1691.03	22.406
1694.08	20.1153
1697.13	17.6246
1700.17	16.0338
1703.21	15.5944
1706.26	13.2067
1709.3	11.927
1712.34	11.4737
1715.38	11.3303
1718.42	9.45185
1721.45	9.23123
1724.49	8.304
1727.52	8.78995
1730.56	6.40416
1733.59	5.61276
1736.62	6.94287
1739.65	7.64219
1742.68	7.24785
1745.71	7.80109
1748.74	7.64094
1751.76	7.11242
1754.79	6.21075
1757.81	5.57819
1760.83	5.80355
1763.85	5.74191
1766.87	5.64435
1769.89	6.28463
1772.91	6.69612
1775.93	6.76279
1778.94	6.91263
1781.95	5.46522
1784.97	5.65772
1787.98	6.25876
1790.99	6.19606
1794	5.04659
1797.01	4.66674
1800.02	3.17773
1803.02	2.82689
1806.03	2.65933
1809.03	4.11874
1812.03	4.63663
1815.04	4.95888
1818.04	4.60741
1821.04	3.40289
1824.04	3.6437
1827.03	2.79755
1830.03	2.63315
1833.02	3.32199
1836.02	3.24788
1839.01	3.00102
1842	3.52832
1844.99	3.50513
1847.98	2.82456
1850.97	2.48672
1853.96	2.17992
1856.95	2.59008
1859.93	2.62496
1862.91	1.79946
1865.9	0.750164
1868.88	0.463632
1871.86	-0.140337
1874.84	1.06479
1877.82	3.10333
1880.79	4.14997
1882.53	4.58509
1885.52	3.5305
1888.51	4.61689
1891.49	4.22859
1894.48	4.37858
1897.46	4.98527
1900.45	5.61365
1903.43	5.52883
1906.41	6.88954
1909.39	5.68721
1912.37	4.66717
1915.35	5.14487
1918.32	4.57558
1921.3	5.33658
1924.27	5.28665
1927.25	4.76757
1930.22	4.83669
1933.19	3.34449
1936.16	4.17262
1939.13	4.37868
1942.1	5.3003
1945.06	6.42143
1948.03	7.4344
1950.99	8.02858
1953.96	7.62022
1956.92	7.39887
1959.88	8.76329
1962.84	8.71153
1965.8	8.25462
1968.76	9.17077
1971.72	8.21115
1974.67	8.15797
1977.63	7.19985
1980.58	7.38973
1983.53	7.91628
1986.48	7.78222
1989.43	8.62736
1992.39	8.17273
1995.33	7.99218
1998.28	8.17319
2001.23	8.72928
2004.17	9.10562
2007.11	8.08467
2010.06	7.9951
2013	8.44816
2015.94	8.99886
2018.88	8.1292
2021.82	7.26757
2024.76	7.20487
2027.69	7.36898
2030.63	7.39511
2033.56	6.24315
2036.5	4.77495
2039.43	4.27691
2042.36	4.59994
2045.29	4.8873
2048.22	4.75443
2051.14	4.38186
2054.07	4.46129
2057	4.43479
2059.92	4.69653
2062.85	5.54098
2065.77	7.0566
2068.69	8.27476
2071.61	9.30092
2074.53	9.37633
2077.45	8.42204
2080.36	8.42396
2083.28	9.60738
2086.19	10.2898
2089.11	10.2477
2092.02	10.2842
2094.93	11.504
2097.84	12.259
2100.75	11.5265
2103.66	11.7402
2106.57	12.5612
2109.48	12.5217
2112.38	14.7832
2115.29	16.5208
2118.19	16.2961
2121.09	16.3117
2123.99	18.1489
2126.89	20.2954
2129.79	23.2578
2132.69	24.9639
2135.59	26.2392
2138.48	27.5296
2141.38	28.5478
2144.27	28.12
2147.16	29.0629
2150.06	30.866
2152.95	31.5674
2155.83	31.7277
2158.72	32.6529
2161.61	32.5864
2164.5	32.9408
2167.38	33.135
2170.27	32.4633
2173.15	32.8057
2176.03	33.7432
2178.91	32.9328
2181.79	31.9392
2184.67	32.3548
2187.55	30.8381
2190.43	29.4094
2193.3	28.8274
2196.18	28.6381
2199.05	28.2464
2201.92	26.6065
2204.8	25.871
2207.67	24.4815
2210.54	22.8473
2213.4	21.6985
2216.27	20.5084
2219.14	20.6067
2222	20.243
2224.87	19.3654
2227.73	17.8595
2230.59	17.0741
2233.46	16.2756
2236.32	16.2786
2239.18	15.7958
2242.03	14.7634
2244.89	15.2132
2247.75	15.3587
2250.6	14.6995
2253.45	16.4047
2256.31	15.9048
2259.16	14.2547
2262.01	13.5242
2264.86	14.0694
2267.71	14.001
2270.56	14.3405
2273.4	13.7842
2276.25	13.4216
2279.09	11.6263
2281.94	9.93169
2284.78	9.84952
2287.62	11.369
2290.46	9.37555
2293.3	7.96125
2296.14	6.54279
2298.98	5.94376
2301.81	6.50378
2304.65	6.77727
2307.48	7.23592
2310.32	6.62097
2313.15	6.85629
2315.98	8.46707
2318.81	7.98708
2321.64	7.96161
2324.47	9.12943
2327.3	8.17077
2330.12	6.6373
2332.95	6.77041
2335.77	7.12923
2338.59	6.39914
2341.42	6.18739
2344.24	4.97587
2347.06	4.12514
2349.88	2.55741
2352.69	2.4607
2355.51	1.92738
2358.33	1.3126
2361.14	-0.0647655
2363.96	0.565751
2366.77	0.857509
2369.58	1.0244
2372.39	1.48814
2375.2	1.44545
2378.01	1.0732
2380.82	2.26596
2383.63	1.75162
2386.43	2.36501
2389.24	2.54738
2392.04	3.85006
2394.84	3.79471
2397.64	3.67466
2400.45	4.15669
2403.25	5.07168
2406.04	5.97463
2408.84	7.1268
2411.64	7.79488
2414.43	8.17332
2417.23	9.42179
2420.02	9.25039
2422.82	9.42159
2425.61	9.37052
2428.4	8.11486
2431.19	7.60003
2433.98	7.59389
2436.76	7.37742
2439.55	7.38758
2442.34	7.17785
2445.12	6.36499
2447.9	5.7944
2450.69	3.60383
2453.47	2.71993
2456.25	2.40121
2459.03	2.16716
2461.81	2.43759
2464.59	2.79139
2467.36	2.92136
2470.14	2.46151
2472.91	2.99113
2475.69	3.75316
2478.46	4.65037
2481.23	4.95216
2484	4.86745
2486.77	5.3375
2489.54	4.21373
2492.31	4.02077
2495.08	4.57442
2497.84	4.79831
2500.61	6.4754
2503.37	6.54017
2506.13	6.04619
2508.89	5.94911
2511.66	5.37672
2514.42	4.44164
2517.17	3.40846
2519.93	2.60256
2522.69	3.13374
2525.44	3.26077
2528.2	3.35165
2530.95	3.28712
2533.71	3.00444
2536.46	2.56827
2539.21	2.03953
2541.96	2.29499
2544.71	2.9563
2547.46	4.43054
2550.2	4.34742
2552.95	4.51221
2555.69	5.70817
2558.44	6.62177
2561.18	6.46441
2563.92	7.26849
2566.67	8.4223
2569.41	7.79717
2572.14	7.10891
2574.88	6.29828
2577.62	6.01846
2580.36	5.82167
2583.09	5.45562
2585.83	5.08326
2588.56	3.77959
2591.29	3.87477
2594.02	3.45854
2596.75	2.95609
2599.48	1.88177
2602.21	2.72788
2604.94	1.77516
2607.67	2.11245
2610.39	3.08128
2613.12	3.05741
2615.84	3.69419
2618.56	3.85061
2621.28	3.7546
2624	3.55368
2626.72	2.64545
2629.44	2.31311
2632.16	2.07352
2634.88	2.55995
2637.59	2.09154
2640.31	1.70946
2643.02	2.1111
2645.73	3.63289
2648.45	3.7519
2651.16	3.57202
2653.87	3.20433
2656.58	3.15179
2659.28	3.48353
2661.99	3.30905
2664.7	3.77877
2667.4	4.60607
2670.11	4.84582
2672.81	4.6577
2675.51	5.46205
2678.21	6.98239
2680.92	6.09055
2683.62	6.4992
2686.31	5.52902
2689.01	6.20315
2691.71	5.47369
2694.4	6.58576
2697.1	6.29776
2699.79	6.43223
2702.48	6.37545
2705.18	6.73328
2707.87	6.75188
2710.56	6.68048
2713.25	5.33398
2715.93	4.85381
2718.62	4.39652
2721.31	4.46113
2723.99	4.74231
2726.68	4.42978
2729.36	4.79285
2732.04	4.59085
2734.72	4.36954
2737.4	5.2445
2740.08	5.24158
2742.76	5.87517
2745.44	5.24341
2748.12	5.3364
2750.79	5.60872
2753.47	5.88519
2756.14	6.07782
2758.81	5.05739
2761.48	5.56415
2764.16	4.15575
2766.83	4.00891
2769.49	3.35057
2772.16	2.94362
2774.83	1.86232
2777.5	1.38272
2780.16	0.953022
2782.83	1.18591
2785.49	-0.0375367
2788.15	-0.870812
2790.81	-0.095259
2793.47	-0.431
2796.13	0.958513
2798.79	1.26876
2801.45	1.38212
2804.11	0.807515
2806.76	0.9523
2809.42	1.71618
2812.07	2.51517
2814.73	3.79178
2817.38	3.46765
2820.03	3.92992
2822.68	5.00017
2825.33	6.06782
2827.98	7.28059
2830.62	8.86704
2833.27	11.0116
2835.92	12.0646
2838.56	13.2547
2841.2	15.0982
2843.85	16.8374
2846.49	18.827
2849.13	22.6721
2851.77	25.7584
2854.41	29.2687
2857.05	33.4078
2859.68	36.1257
2862.32	39.38
2864.96	42.5519
2867.59	44.0485
2870.22	47.8129
2872.86	49.7034
2875.49	52.9212
2878.12	56.2976
2880.75	58.3227
2883.38	60.3556
2886.01	63.398
2888.63	65.7447
2891.26	68.1652
2893.88	71.1049
2896.51	74.6679
2899.13	78.2771
2901.76	82.4908
2904.38	87.5543
2907	92.968
2909.62	98.8836
2912.24	105.002
2914.85	111.558
2917.47	115.767
2920.09	120.573
2922.7	124.257
2925.31	126.322
2927.93	128.602
2930.54	130.149
2933.15	130.586
2935.76	129.831
2938.37	129.729
2940.98	128.417
2943.59	126.296
2946.2	122.978
2948.8	118.926
2951.41	114.542
2954.01	110.477
2956.62	106.122
2959.22	100.605
2961.82	97.5081
2964.42	93.7411
2967.02	90.1974
2969.62	85.7749
2972.21	81.8316
2974.81	76.5652
2977.41	72.052
2980	68.2263
2982.6	62.1368
2985.19	57.2165
2987.78	51.168
2990.37	46.6114
2992.96	42.0563
2995.55	38.1499
2998.14	33.3362
3000.73	29.3987
3003.32	26.4279
3005.9	23.8509
3008.49	21.0271
3011.07	18.6296
3013.66	16.9438
3016.24	14.6782
3018.82	13.9656
3021.4	12.9405
3023.98	12.0825
3026.56	11.8056
3029.14	10.1237
3031.71	9.28875
3034.29	8.84328
3036.86	7.69442
3039.44	6.55779
3042.01	6.60928
3044.59	5.67651
3047.16	5.22469
3049.73	4.87968
3052.3	5.2531
3054.87	5.63262
3057.43	5.04146
3060	5.25799
3062.57	4.91091
3065.13	5.1712
3067.7	6.74355
3070.26	7.01505
3072.82	7.92701
3075.39	8.60977
3077.95	8.70168
3080.51	9.78411
3083.07	9.51818
3085.62	8.86806
3088.18	7.87135
3090.74	7.00629
3093.29	5.18684
3095.85	4.79584
3098.4	3.907
3100.95	3.63253
3103.51	2.97863
3106.06	3.18402
3108.61	2.40178
3111.16	1.78671
3113.71	2.12173
3116.25	2.59064
3118.8	2.58443
3121.34	3.0983
3123.89	4.21735
3126.43	5.28123
3128.98	6.77549
3131.52	8.55643
3134.06	10.2035
3136.6	11.5252
3139.14	12.9998
3141.68	14.103
3144.22	15.2876
3146.75	16.0454
3149.29	17.1778