File: data/Raman/poly_smoothed/Mb_30_27_23_1x_45s_532 nm_x100_100%_600 gr_mm_01.txt
#Acq. time (s)=	45
#Accumulations=	2
#Range (cm-¹)=	200...3150
#Windows=	2
#Auto scanning=	Off
#Autofocus=	Off
#Macrospot=	Off
#AutoExposure=	Off
#Spike filter=	Multiple accum.
#Delay time (s)=	0
#Binning=	1
#Readout mode=	Signal
#DeNoise=	Off
#ICS correction=	On
#Dark correction=	Off
#Inst. Process=	Off
#Detector Gain=	Best Dynamic Range
#Detector ADC=	20 kHz
#Detector temperature (°C)=	-69.85
#Instrument=	LabRAM HR Evol
#Detector=	Synapse
#Objective=	x100
#Grating=	600 gr/mm
#ND Filter=	100%
#Laser (nm)=	532
#Hole=	100.021
#Range=	Auto
#Laser Pol.=	No
#Raman. Pol.=	No
#Laser Pol. (°)=	-0.0007625
#Raman Pol. (°)=	89.9995
#Collection=	Microscope
#StageXY=	Marzhauser
#StageZ=	Marzhauser
#X (µm)=	-6362.2
#Y (µm)=	862.1
#Z (µm)=	-65.2
#Full time(mm:ss)=	3:19
#Project=
#Sample=
#Site=
#Title=	Mb_30_27_23_2x_45s_532 nm_x100_100%_600 gr_mm
#Remark=
#Date=	13.07.2022 10:18
#Acquired=	13.07.2022 10:18:44
#Base:Fit=	10.08.2022 10:40:03
#Base:Sub=	10.08.2022 10:40:17
#Filter:Polynom=	16.08.2022 10:16:15
#AxisType[0]=Intens
#AxisUnit[0]=Cnt
#AxisType[1]=Spectr
#AxisUnit[1]=1/cm
200.563	10.6569
204.194	11.6316
207.821	10.6658
211.449	10.3578
215.074	10.6994
218.699	10.2114
222.321	10.7075
225.941	7.52993
229.562	7.16936
233.18	7.34165
236.796	8.87911
240.411	8.66588
244.026	9.42614
247.638	9.287
251.248	9.1633
254.857	8.74287
258.465	7.93334
262.071	8.74347
265.678	8.27295
269.282	10.1261
272.884	10.9776
276.484	11.2749
280.084	11.6528
283.682	12.0737
287.276	11.8854
290.871	12.0379
294.465	12.2356
298.057	14.1403
301.648	14.1402
305.237	15.39
308.823	16.1671
312.41	16.7234
315.995	18.2131
319.579	18.6475
323.16	19.3769
326.741	19.3181
330.321	18.2449
333.897	18.5869
337.474	16.0627
341.048	15.8566
344.622	15.8096
348.192	15.5288
351.764	14.9745
355.332	14.6652
358.901	13.3539
362.466	12.2347
366.03	11.4156
369.594	8.69839
373.155	6.7185
376.715	7.28436
380.273	7.34639
383.832	5.93091
387.388	4.87685
390.942	5.38585
394.495	5.79248
398.047	6.14996
401.597	5.87705
405.145	7.14574
408.693	5.96011
412.239	5.70834
415.783	5.98552
419.327	6.73443
422.869	7.51081
426.409	7.48051
429.948	8.93247
433.486	7.94168
437.022	7.72365
440.558	6.73376
444.089	7.03933
447.622	7.36511
451.153	6.14187
454.682	6.27537
458.208	8.02522
461.735	9.75843
465.259	11.2571
468.783	10.6246
472.306	11.653
475.825	12.0912
479.346	15.0108
482.862	14.7838
486.38	16.0038
489.894	17.201
493.407	17.6069
496.92	18.9661
500.43	19.5795
503.939	19.3721
507.448	19.1903
510.954	16.6987
514.459	15.7762
517.962	13.9899
521.466	11.382
524.966	11.1962
528.466	9.81678
531.964	10.2766
535.46	9.79592
538.955	8.28999
542.449	8.9474
545.942	8.18695
549.433	7.10446
552.923	6.18344
556.412	6.98684
559.899	7.58216
563.385	5.19739
566.867	5.89191
570.35	5.78331
573.832	5.55973
577.313	7.62695
580.79	7.39639
584.268	6.66837
587.745	5.33987
591.218	5.32245
594.692	2.92646
598.164	2.6855
601.634	3.12587
605.104	3.34486
608.57	2.60492
612.037	3.64083
615.501	3.96278
618.966	4.83584
622.427	4.80891
625.887	5.08532
629.348	5.76354
632.806	7.37336
636.262	10.0032
639.716	10.0599
643.172	13.955
646.624	14.2038
650.075	14.7726
653.524	15.9805
656.972	16.8502
660.419	17.6974
663.865	18.6505
667.309	20.4554
670.752	20.227
674.194	20.5902
677.634	21.5872
681.073	22.0875
684.511	24.0119
687.947	25.0563
691.382	26.0465
694.816	26.7497
698.247	27.6808
701.678	28.7248
705.108	29.7333
708.534	29.6776
711.962	31.524
715.388	33.4456
718.81	33.299
722.234	32.9023
725.654	33.9511
729.075	34.7708
732.492	32.8017
735.91	33.0476
739.325	33.9233
742.741	35.7012
746.153	37.8802
749.564	40.8416
752.976	44.7174
756.385	48.0371
759.792	49.3413
763.2	52.0942
766.604	55.8181
770.008	58.3525
773.41	63.1996
776.811	66.2411
780.21	68.0242
783.608	70.7554
787.005	73.0785
790.401	75.3725
793.795	77.1152
797.188	77.7366
800.58	76.6176
803.971	74.5341
807.36	74.524
810.748	73.1058
814.135	71.9604
817.518	69.1666
820.902	68.5795
824.285	67.9524
827.665	67.7844
831.045	67.5101
834.424	66.1319
837.8	63.3397
841.177	61.6737
844.55	58.6451
847.924	57.9115
851.295	56.2932
854.666	54.7107
858.034	54.0849
861.403	52.9852
864.769	51.3331
868.133	49.6077
871.498	48.8062
874.86	48.2004
878.221	47.0758
881.58	45.7522
884.938	43.9833
888.297	43.7105
891.653	43.0351
895.007	42.8161
898.36	42.7325
901.712	42.09
905.063	42.1166
908.412	41.8608
911.76	40.8015
915.107	40.3821
918.452	39.3489
921.797	38.4324
925.138	36.923
928.48	36.7263
931.82	36.3545
935.16	36.3507
938.496	36.6993
941.833	35.7381
945.168	33.5149
948.5	30.8538
951.834	31.0732
955.163	31.9616
958.494	30.073
961.821	29.1361
965.15	29.1971
968.474	29.876
971.8	28.3426
975.123	28.2169
978.446	27.8921
981.766	26.3012
985.084	25.2687
988.402	24.9026
991.72	22.9494
995.035	21.8866
998.349	20.3445
1001.66	18.411
1004.97	18.0176
1008.28	17.6434
1011.59	18.8677
1014.9	20.1958
1018.21	20.5952
1021.51	20.983
1024.81	20.2054
1028.12	20.0515
1031.42	21.8492
1034.72	21.7045
1038.02	22.7637
1041.31	23.2301
1044.61	24.5405
1047.91	24.579
1051.2	23.4764
1054.49	22.9466
1057.78	21.6685
1061.07	20.7961
1064.36	18.4779
1067.65	16.9651
1070.93	16.4574
1074.22	15.5046
1077.5	12.9037
1080.78	10.8852
1084.06	9.50562
1087.34	9.33739
1090.62	9.69092
1093.9	10.9919
1097.17	10.8931
1100.45	9.56206
1103.72	9.01582
1106.99	8.48204
1110.27	9.75087
1113.53	9.25606
1116.8	9.23281
1120.07	9.13307
1123.33	8.10364
1126.6	7.92847
1129.86	5.75615
1133.12	5.06009
1136.38	5.74835
1139.64	4.8984
1142.9	5.23829
1146.16	5.04732
1149.41	6.29013
1152.67	6.28854
1155.92	5.31095
1159.17	3.36867
1162.42	3.886
1165.67	3.74394
1168.92	3.63447
1172.16	3.54896
1175.41	4.19706
1178.65	3.18715
1181.9	3.67959
1185.14	4.42359
1188.38	4.49269
1191.62	3.57841
1194.86	2.98371
1198.09	3.48359
1201.33	4.95686
1204.56	5.9398
1207.8	6.39072
1211.03	7.64496
1214.26	10.4859
1217.49	12.771
1220.71	14.4672
1223.94	16.879
1227.16	19.3781
1230.39	21.1699
1233.61	23.8224
1236.83	24.1974
1240.05	26.3878
1243.27	28.0197
1246.49	29.2553
1249.71	31.3623
1252.92	33.0311
1256.14	33.8449
1259.35	35.3923
1262.56	39.2034
1265.77	41.4094
1268.98	40.8086
1272.19	42.739
1275.4	44.5569
1278.6	45.9867
1281.81	46.319
1285.01	46.4813
1288.21	46.5057
1291.41	46.8552
1294.61	47.4803
1297.81	48.5768
1301.01	50.0727
1304.2	51.2009
1307.4	51.6774
1310.59	52.1662
1313.78	53.2356
1316.97	52.7231
1320.16	55.1185
1323.35	55.9596
1326.54	57.0136
1329.72	56.9324
1332.91	56.9773
1336.09	57.1647
1339.27	57.5549
1342.45	54.705
1345.64	52.1394
1348.81	49.5378
1351.99	48.6259
1355.17	46.5159
1358.34	42.8853
1361.51	39.7555
1364.69	37.5503
1367.86	34.3346
1371.03	32.5816
1374.2	31.0206
1377.37	29.5749
1380.53	27.599
1383.7	26.5772
1386.86	26.8215
1390.02	27.0894
1393.19	27.025
1396.35	27.8074
1399.51	28.7777
1402.66	29.8159
1405.82	31.0904
1408.97	30.8323
1412.13	32.5694
1415.28	34.0738
1418.43	35.6285
1421.59	38.1346
1424.73	43.0071
1427.88	44.866
1431.03	48.9114
1434.18	50.7798
1437.32	53.6469
1440.46	55.8641
1443.61	57.6619
1446.75	58.463
1449.89	60.2314
1453.03	59.7599
1456.16	57.986
1459.3	57.4486
1462.44	56.75
1465.57	54.985
1468.7	52.4366
1471.83	49.6933
1474.96	46.6125
1478.09	42.7015
1481.22	39.6108
1484.35	35.5073
1487.47	32.0802
1490.6	30.7405
1493.72	27.9277
1496.84	25.2548
1499.96	22.7082
1503.08	21.6851
1506.2	19.9419
1509.32	20.0202
1512.44	18.4158
1515.55	17.9476
1518.66	20.0038
1521.78	21.1996
1524.89	21.7103
1528	21.695
1531.11	22.4742
1534.21	22.6087
1537.32	23.7358
1540.43	24.9959
1543.53	26.1089
1546.63	25.9849
1549.74	26.3228
1552.84	27.4996
1555.94	27.1462
1559.03	26.8111
1562.13	27.9242
1565.23	30.0789
1568.32	30.1074
1571.42	31.2018
1574.51	32.6331
1577.6	33.0305
1580.69	34.952
1583.78	37.3848
1586.87	39.1687
1589.95	40.2119
1593.04	41.4723
1596.12	42.3702
1599.21	42.985
1602.29	40.6613
1605.37	40.398
1608.45	40.2846
1611.53	38.902
1614.6	38.3534
1617.68	38.3632
1620.75	38.5831
1623.83	39.8989
1626.9	41.0331
1629.97	42.133
1633.04	43.9126
1636.11	45.3543
1639.18	48.2906
1642.25	51.6428
1645.31	54.7596
1648.38	57.3008
1651.44	59.4485
1654.5	61.4451
1657.56	61.6402
1660.62	62.6063
1663.68	60.9129
1666.74	59.0701
1669.8	56.1193
1672.85	53.5663
1675.91	50.1269
1678.96	46.2607
1682.01	43.6422
1685.06	40.3276
1688.11	36.3751
1691.16	32.6884
1694.21	30.1484
1697.25	27.3942
1700.3	26.3588
1703.34	23.7187
1706.39	21.814
1709.43	18.5613
1712.47	17.8624
1715.51	17.6884
1718.54	16.9137
1721.58	15.8135
1724.62	15.2004
1727.65	13.0931
1730.68	11.8287
1733.72	11.2263
1736.75	9.20839
1739.78	8.10215
1742.81	7.028
1745.84	6.1496
1748.86	6.40585
1751.89	6.51948
1754.91	6.89739
1757.93	5.8969
1760.96	5.5219
1763.98	5.72025
1767	5.26058
1770.02	6.52192
1773.03	7.01549
1776.05	7.28592
1779.07	6.34046
1782.08	5.37494
1785.09	5.36086
1788.11	5.89543
1791.12	6.07738
1794.13	5.96153
1797.13	5.83117
1800.14	5.67857
1803.15	4.42861
1806.15	3.88736
1809.16	3.26518
1812.16	3.36967
1815.16	2.65445
1818.16	2.78409
1821.16	2.50169
1824.16	2.27822
1827.16	2.02514
1830.16	1.92356
1833.15	2.03291
1836.14	2.38918
1839.14	3.76641
1842.13	4.84707
1845.12	4.37897
1848.11	4.07148
1851.1	4.93836
1854.08	6.6555
1857.07	7.38758
1860.05	8.19094
1863.04	8.95334
1866.02	9.24766
1869	9.08187
1871.98	9.06421
1874.96	8.62742
1877.94	7.49269
1880.92	6.77874
1882.51	6.49792
1885.5	5.42042
1888.48	5.44962
1891.47	5.14987
1894.46	4.10333
1897.44	3.05409
1900.42	1.5955
1903.41	0.816007
1906.39	1.15924
1909.37	1.71418
1912.35	1.91134
1915.32	1.55877
1918.3	1.41743
1921.27	2.88622
1924.25	4.08855
1927.22	4.71352
1930.19	3.57054
1933.17	3.50577
1936.14	3.22028
1939.11	3.27043
1942.07	3.26513
1945.04	4.19187
1948.01	5.04279
1950.97	4.3471
1953.93	5.27674
1956.9	5.88689
1959.86	6.2079
1962.82	6.40767
1965.78	5.49305
1968.74	4.57441
1971.69	3.97128
1974.65	3.38087
1977.6	3.47207
1980.56	3.73215
1983.51	3.76674
1986.46	3.75618
1989.41	2.98341
1992.36	3.62655
1995.31	3.5801
1998.26	3.18949
2001.2	2.04468
2004.15	1.89733
2007.09	2.68524
2010.04	2.76362
2012.98	2.9929
2015.92	4.63609
2018.86	5.00389
2021.8	5.94446
2024.73	5.72838
2027.67	5.65087
2030.61	5.18545
2033.54	6.03481
2036.47	5.80037
2039.4	5.53785
2042.33	6.48958
2045.27	7.44249
2048.19	7.40675
2051.12	8.24944
2054.05	9.46305
2056.97	8.8164
2059.9	8.25184
2062.82	8.74352
2065.74	8.22925
2068.67	8.47395
2071.59	8.67276
2074.51	8.73076
2077.42	9.78901
2080.34	11.8204
2083.26	12.8047
2086.17	13.4681
2089.09	14.5304
2092	14.8354
2094.91	14.6853
2097.82	15.0842
2100.73	15.2431
2103.64	16.4216
2106.55	17.2207
2109.45	18.4987
2112.36	20.2367
2115.26	22.163
2118.17	22.344
2121.07	24.1348
2123.97	25.9231
2126.87	27.7709
2129.77	28.6782
2132.67	31.0289
2135.56	33.2666
2138.46	35.0128
2141.35	38.5302
2144.25	41.5917
2147.14	45.1095
2150.03	48.0967
2152.92	50.8733
2155.81	52.8344
2158.7	54.1171
2161.59	56.5207
2164.47	58.2537
2167.36	58.381
2170.24	59.682
2173.13	59.5096
2176.01	61.4337
2178.89	60.9569
2181.77	61.172
2184.65	59.6721
2187.53	58.1173
2190.4	57.2704
2193.28	56.0427
2196.16	54.547
2199.03	52.8102
2201.9	49.7198
2204.77	47.9448
2207.64	45.1984
2210.51	42.556
2213.38	40.845
2216.25	38.4285
2219.12	36.5659
2221.98	34.9321
2224.85	32.8707
2227.71	29.8314
2230.57	27.5752
2233.43	26.558
2236.29	23.6861
2239.15	21.4618
2242.01	20.6063
2244.87	19.5053
2247.72	18.3692
2250.58	16.5442
2253.43	15.7802
2256.29	15.2027
2259.14	14.2196
2261.99	13.3409
2264.84	13.3145
2267.69	12.4106
2270.53	11.67
2273.38	10.1619
2276.23	10.0098
2279.07	9.33117
2281.91	9.43831
2284.76	9.00452
2287.6	10.1793
2290.44	9.21946
2293.28	7.78258
2296.12	6.57881
2298.96	8.0315
2301.79	8.5496
2304.63	8.14449
2307.46	7.46245
2310.3	8.63403
2313.13	9.23182
2315.96	9.42712
2318.79	9.70292
2321.62	9.17599
2324.45	9.50169
2327.27	9.49626
2330.1	9.06142
2332.92	9.65919
2335.75	9.38137
2338.57	8.76861
2341.39	8.97004
2344.21	8.29708
2347.04	8.72194
2349.85	7.86025
2352.67	6.89676
2355.49	5.9341
2358.3	6.14433
2361.12	4.38528
2363.93	3.91635
2366.75	5.23261
2369.56	5.18499
2372.37	4.10586
2375.18	4.28751
2377.99	4.48114
2380.8	4.39634
2383.6	4.46386
2386.41	4.47835
2389.21	4.52119
2392.02	4.99983
2394.82	4.87156
2397.62	4.28683
2400.42	4.99601
2403.22	4.89082
2406.02	4.2716
2408.82	4.29381
2411.62	4.16746
2414.41	4.53239
2417.21	4.83243
2420	4.30841
2422.79	4.15507
2425.59	4.9622
2428.38	4.00262
2431.17	3.57079
2433.95	4.09617
2436.74	4.85727
2439.53	5.06388
2442.31	6.00546
2445.1	6.7584
2447.88	6.8716
2450.67	6.84816
2453.45	6.93462
2456.23	6.70359
2459.01	6.28585
2461.79	5.8819
2464.57	4.95135
2467.34	4.0444
2470.12	3.12216
2472.89	2.41604
2475.67	2.17563
2478.44	2.10351
2481.21	1.34957
2483.98	1.70184
2486.75	2.06971
2489.52	1.36206
2492.29	1.37319
2495.05	0.866475
2497.82	0.671732
2500.58	0.613864
2503.35	0.606426
2506.11	0.696782
2508.87	1.30139
2511.63	1.49355
2514.39	0.413874
2517.15	0.853288
2519.91	1.1393
2522.67	0.994204
2525.42	1.51991
2528.18	1.22025
2530.93	1.41612
2533.69	1.21049
2536.44	1.23322
2539.19	2.77371
2541.94	3.02194
2544.69	2.36594
2547.44	2.90006
2550.18	3.69532
2552.93	4.6466
2555.67	5.29582
2558.42	6.07501
2561.16	6.71565
2563.9	6.62236
2566.64	7.31773
2569.38	7.60725
2572.12	7.91408
2574.86	8.362
2577.6	7.77535
2580.33	7.79383
2583.07	8.46517
2585.8	9.40033
2588.54	9.03547
2591.27	8.70653
2594	8.04454
2596.73	7.58408
2599.46	7.66157
2602.19	6.90621
2604.92	5.96704
2607.64	4.99098
2610.37	4.40434
2613.09	3.85684
2615.82	4.06908
2618.54	4.51626
2621.26	4.06454
2623.98	4.1836
2626.7	4.14037
2629.42	3.72978
2632.14	4.09139
2634.86	4.35399
2637.57	3.87286
2640.29	4.79809
2643	4.43256
2645.71	5.47092
2648.43	6.94279
2651.14	7.12422
2653.85	6.72199
2656.56	5.93925
2659.26	5.81551
2661.97	5.51482
2664.68	5.07408
2667.38	5.00884
2670.09	5.55278
2672.79	5.01279
2675.49	4.50697
2678.19	4.50071
2680.89	4.73663
2683.59	4.88516
2686.29	4.61824
2688.99	4.89959
2691.69	6.23963
2694.38	5.72444
2697.08	7.24586
2699.77	7.04736
2702.46	7.70679
2705.15	8.18297
2707.85	7.97562
2710.54	8.45023
2713.22	8.89167
2715.91	8.44605
2718.6	7.80879
2721.29	7.53983
2723.97	8.2085
2726.66	7.90496
2729.34	8.52985
2732.02	8.19705
2734.7	7.72828
2737.38	6.76337
2740.06	5.08873
2742.74	4.38119
2745.42	5.28009
2748.09	4.6737
2750.77	4.41007
2753.45	4.61785
2756.12	4.29599
2758.79	4.39387
2761.46	3.80091
2764.14	2.8243
2766.8	3.05144
2769.47	2.86575
2772.14	2.46974
2774.81	1.96086
2777.48	2.65006
2780.14	1.87347
2782.8	1.74263
2785.47	1.61088
2788.13	1.80964
2790.79	2.21496
2793.45	2.73192
2796.11	2.09981
2798.77	1.51842
2801.43	0.965212
2804.09	0.137821
2806.74	0.197148
2809.4	-0.390256
2812.05	-0.230766
2814.71	-0.32404
2817.36	0.519334
2820.01	1.72712
2822.66	3.00647
2825.31	3.96705
2827.96	6.69658
2830.6	9.32941
2833.25	12.1993
2835.9	14.9512
2838.54	18.4155
2841.18	22.8784
2843.83	27.1271
2846.47	32.0386
2849.11	37.8558
2851.75	44.3455
2854.39	50.6677
2857.03	56.4174
2859.66	61.9397
2862.3	67.0023
2864.94	72.3554
2867.57	76.2168
2870.2	80.482
2872.84	83.4789
2875.47	86.9059
2878.1	90.422
2880.73	93.5625
2883.36	96.8923
2885.99	99.503
2888.61	101.545
2891.24	103.606
2893.86	106.71
2896.49	110.481
2899.11	114.863
2901.73	121.298
2904.36	127.611
2906.98	134.047
2909.6	141.015
2912.21	149.823
2914.83	157.492
2917.45	165.904
2920.07	172.816
2922.68	179.396
2925.29	184.551
2927.91	189.226
2930.52	192.807
2933.13	193.772
2935.74	194.286
2938.35	193.706
2940.96	190.582
2943.57	185.987
2946.18	181.418
2948.78	175.888
2951.39	168.067
2953.99	161.317
2956.59	155.056
2959.2	149.053
2961.8	141.798
2964.4	133.527
2967	126.845
2969.6	118.452
2972.19	111.064
2974.79	103.546
2977.39	96.9269
2979.98	89.5144
2982.58	81.9493
2985.17	73.8689
2987.76	66.2031
2990.35	59.1471
2992.94	52.4642
2995.53	45.7807
2998.12	39.4882
3000.71	33.3349
3003.3	27.3011
3005.88	22.3316
3008.47	17.8738
3011.05	14.7445
3013.64	11.3944
3016.22	9.18606
3018.8	7.37895
3021.38	5.53713
3023.96	4.22086
3026.54	2.59677
3029.12	0.934978
3031.69	1.50675
3034.27	1.8298
3036.84	2.11352
3039.42	2.3012
3041.99	2.09269
3044.57	2.00798
3047.14	2.51757
3049.71	3.13717
3052.28	2.99429
3054.85	3.00639
3057.41	3.76291
3059.98	3.48569
3062.55	3.99112
3065.11	3.57237
3067.68	3.4508
3070.24	2.55827
3072.8	2.0952
3075.36	1.91583
3077.93	2.04984
3080.49	1.78593
3083.04	2.07408
3085.6	1.97507
3088.16	1.53909
3090.72	1.11116
3093.27	1.25877
3095.83	2.50436
3098.38	2.49786
3100.93	3.58286
3103.49	3.27508
3106.04	4.13768
3108.59	5.48564
3111.14	6.29995
3113.69	6.65667
3116.23	7.86
3118.78	8.94368
3121.33	10.623
3123.87	11.7071
3126.41	12.9435
3128.96	13.5154
3131.5	14.4545
3134.04	16.2484
3136.58	17.9736
3139.12	19.5357
3141.66	20.6115
3144.2	20.8337
3146.74	20.9772
3149.27	22.4093