File: data/Raman/poly_smoothed/Mb_30_27_20_1x_45s_532 nm_x100_100%_600 gr_mm_01.txt
#Acq. time (s)=	45
#Accumulations=	2
#Range (cm-¹)=	200...3150
#Windows=	2
#Auto scanning=	Off
#Autofocus=	Off
#Macrospot=	Off
#AutoExposure=	Off
#Spike filter=	Multiple accum.
#Delay time (s)=	0
#Binning=	1
#Readout mode=	Signal
#DeNoise=	Off
#ICS correction=	On
#Dark correction=	Off
#Inst. Process=	Off
#Detector Gain=	Best Dynamic Range
#Detector ADC=	20 kHz
#Detector temperature (°C)=	-69.85
#Instrument=	LabRAM HR Evol
#Detector=	Synapse
#Objective=	x100
#Grating=	600 gr/mm
#ND Filter=	100%
#Laser (nm)=	532
#Hole=	100.021
#Range=	Auto
#Laser Pol.=	No
#Raman. Pol.=	No
#Laser Pol. (°)=	-0.0007625
#Raman Pol. (°)=	89.9995
#Collection=	Microscope
#StageXY=	Marzhauser
#StageZ=	Marzhauser
#X (µm)=	-6400.4
#Y (µm)=	884.2
#Z (µm)=	-64.65
#Full time(mm:ss)=	3:18
#Project=
#Sample=
#Site=
#Title=	Mb_30_27_20_2x_45s_532 nm_x100_100%_600 gr_mm
#Remark=
#Date=	13.07.2022 10:07
#Acquired=	13.07.2022 10:07:16
#Base:Fit=	10.08.2022 10:40:03
#Base:Sub=	10.08.2022 10:40:17
#Filter:Polynom=	16.08.2022 10:16:15
#AxisType[0]=Intens
#AxisUnit[0]=Cnt
#AxisType[1]=Spectr
#AxisUnit[1]=1/cm
200.563	15.2877
204.194	20.8453
207.821	20.9322
211.449	20.4485
215.074	19.4442
218.699	18.8874
222.321	18.4322
225.941	17.9566
229.562	17.4497
233.18	18.2717
236.796	16.6949
240.411	15.4212
244.026	14.2723
247.638	14.1549
251.248	13.0521
254.857	11.203
258.465	8.08475
262.071	6.3273
265.678	5.43587
269.282	5.1627
272.884	4.57806
276.484	4.97568
280.084	4.95637
283.682	5.67183
287.276	4.42062
290.871	4.17304
294.465	3.7316
298.057	4.69145
301.648	6.24208
305.237	6.84199
308.823	8.70282
312.41	8.97462
315.995	9.44091
319.579	9.53794
323.16	9.19361
326.741	8.70197
330.321	8.04076
333.897	8.86438
337.474	8.06866
341.048	7.07042
344.622	6.6462
348.192	7.9628
351.764	8.18404
355.332	8.63854
358.901	8.43255
362.466	9.21291
366.03	9.1394
369.594	8.94597
373.155	8.37177
376.715	10.5434
380.273	9.91302
383.832	9.67147
387.388	8.59194
390.942	9.0196
394.495	8.21164
398.047	8.16982
401.597	7.38426
405.145	7.02584
408.693	5.56929
412.239	5.42535
415.783	4.41827
419.327	4.14906
422.869	4.48426
426.409	2.68557
429.948	4.11921
433.486	4.14777
437.022	6.35112
440.558	6.71021
444.089	6.38091
447.622	7.27288
451.153	7.12123
454.682	6.69564
458.208	7.74051
461.735	8.58251
465.259	7.83979
468.783	8.36818
472.306	9.88007
475.825	11.7507
479.346	14.6099
482.862	16.0216
486.38	17.5781
489.894	18.4011
493.407	20.3708
496.92	21.0603
500.43	21.6781
503.939	22.0649
507.448	21.5839
510.954	22.0261
514.459	21.8138
517.962	22.7439
521.466	23.4075
524.966	24.272
528.466	23.5285
531.964	21.936
535.46	20.4787
538.955	17.9174
542.449	19.2466
545.942	18.0644
549.433	17.0478
552.923	17.4276
556.412	16.8331
559.899	15.8923
563.385	12.9413
566.867	10.7291
570.35	10.1248
573.832	11.809
577.313	13.314
580.79	15.7468
584.268	14.1786
587.745	12.8691
591.218	13.1243
594.692	14.5255
598.164	14.1737
601.634	14.3842
605.104	13.5423
608.57	13.4251
612.037	12.8448
615.501	11.4287
618.966	11.66
622.427	11.4561
625.887	11.8712
629.348	11.165
632.806	11.2327
636.262	10.3981
639.716	8.10257
643.172	6.83671
646.624	6.96299
650.075	6.44273
653.524	11.6362
656.972	14.5021
660.419	16.632
663.865	19.1279
667.309	20.1579
670.752	21.3934
674.194	24.5092
677.634	26.0559
681.073	28.241
684.511	29.0388
687.947	29.9099
691.382	31.6292
694.816	33.4217
698.247	36.5264
701.678	37.5654
705.108	39.4844
708.534	40.9358
711.962	39.6124
715.388	36.101
718.81	35.7001
722.234	37.3241
725.654	42.8254
729.075	48.3691
732.492	52.2223
735.91	55.1197
739.325	58.2578
742.741	60.4284
746.153	63.0088
749.564	66.3981
752.976	69.5017
756.385	70.6154
759.792	72.5434
763.2	75.8072
766.604	77.4306
770.008	80.1302
773.41	82.0881
776.811	83.6986
780.21	83.9709
783.608	83.8247
787.005	81.8277
790.401	80.6527
793.795	76.3046
797.188	71.8225
800.58	71.5094
803.971	74.9644
807.36	77.5742
810.748	78.9794
814.135	77.3864
817.518	73.9317
820.902	72.2201
824.285	70.1216
827.665	68.1509
831.045	67.0289
834.424	65.1166
837.8	62.2242
841.177	60.2081
844.55	57.8598
847.924	56.7261
851.295	55.4128
854.666	54.0101
858.034	51.801
861.403	49.6764
864.769	47.7328
868.133	47.367
871.498	47.104
874.86	46.6873
878.221	45.8807
881.58	48.2394
884.938	48.5089
888.297	48.3569
891.653	49.9395
895.007	49.3137
898.36	48.5784
901.712	48.1928
905.063	48.8842
908.412	48.7638
911.76	49.8928
915.107	49.9969
918.452	49.3541
921.797	49.6712
925.138	49.5084
928.48	48.9814
931.82	46.658
935.16	44.9302
938.496	44.2692
941.833	43.6391
945.168	42.5992
948.5	41.5791
951.834	41.3561
955.163	39.5493
958.494	37.9737
961.821	36.7314
965.15	35.7985
968.474	33.3771
971.8	33.865
975.123	33.7703
978.446	32.6913
981.766	32.0378
985.084	32.1464
988.402	31.8391
991.72	31.0457
995.035	28.9626
998.349	28.7226
1001.66	26.3654
1004.97	25.686
1008.28	24.7982
1011.59	26.4518
1014.9	30.2642
1018.21	35.5049
1021.51	39.9538
1024.81	42.5784
1028.12	44.9259
1031.42	46.1456
1034.72	47.351
1038.02	48.0041
1041.31	48.7874
1044.61	47.6454
1047.91	48.161
1051.2	46.9424
1054.49	44.0647
1057.78	41.7664
1061.07	38.6477
1064.36	35.6921
1067.65	29.7965
1070.93	24.635
1074.22	18.4419
1077.5	15.2214
1080.78	11.2009
1084.06	7.14523
1087.34	6.77334
1090.62	8.40779
1093.9	11.0261
1097.17	12.0266
1100.45	12.3655
1103.72	12.9127
1106.99	13.6049
1110.27	12.5083
1113.53	12.4529
1116.8	12.1353
1120.07	11.2943
1123.33	9.15531
1126.6	8.31966
1129.86	7.79341
1133.12	6.62588
1136.38	7.25286
1139.64	6.49254
1142.9	5.35501
1146.16	3.07781
1149.41	3.60866
1152.67	3.21041
1155.92	3.14508
1159.17	1.59611
1162.42	2.10242
1165.67	1.92059
1168.92	2.49607
1172.16	2.3151
1175.41	2.14244
1178.65	1.95033
1181.9	2.9794
1185.14	3.39573
1188.38	3.36055
1191.62	2.77212
1194.86	1.8669
1198.09	1.5518
1201.33	-0.20754
1204.56	0.615015
1207.8	0.654283
1211.03	1.4296
1214.26	3.70217
1217.49	5.41137
1220.71	7.58637
1223.94	9.92342
1227.16	11.5796
1230.39	14.1228
1233.61	14.3677
1236.83	16.2268
1240.05	18.5958
1243.27	19.6713
1246.49	21.3049
1249.71	21.4771
1252.92	23.2561
1256.14	24.8029
1259.35	26.0663
1262.56	26.4708
1265.77	26.9671
1268.98	28.0239
1272.19	27.4984
1275.4	26.6847
1278.6	27.0228
1281.81	27.081
1285.01	28.8744
1288.21	29.6485
1291.41	30.5858
1294.61	32.6624
1297.81	33.4603
1301.01	33.7784
1304.2	33.762
1307.4	34.4556
1310.59	36.3256
1313.78	36.5938
1316.97	36.0688
1320.16	38.8954
1323.35	37.861
1326.54	38.713
1329.72	38.6267
1332.91	39.0924
1336.09	38.9033
1339.27	36.8084
1342.45	35.4332
1345.64	35.1726
1348.81	33.1823
1351.99	31.5779
1355.17	29.7707
1358.34	27.3346
1361.51	27.3987
1364.69	26.0231
1367.86	24.7711
1371.03	24.5707
1374.2	23.5819
1377.37	21.5337
1380.53	22.2718
1383.7	22.3862
1386.86	24.484
1390.02	24.8883
1393.19	25.4672
1396.35	26.4247
1399.51	27.5358
1402.66	27.7081
1405.82	27.3176
1408.97	27.3374
1412.13	27.8984
1415.28	27.391
1418.43	28.3564
1421.59	30.5403
1424.73	33.2779
1427.88	36.1298
1431.03	37.8609
1434.18	38.4364
1437.32	40.3401
1440.46	41.275
1443.61	40.7584
1446.75	42.3485
1449.89	41.725
1453.03	41.1072
1456.16	40.2764
1459.3	40.5945
1462.44	40.97
1465.57	40.3341
1468.7	38.5961
1471.83	37.1187
1474.96	36.3083
1478.09	33.5559
1481.22	31.7899
1484.35	29.2297
1487.47	28.8974
1490.6	26.2356
1493.72	24.8778
1496.84	23.6643
1499.96	22.5363
1503.08	20.3588
1506.2	18.7986
1509.32	16.134
1512.44	13.4143
1515.55	12.0514
1518.66	12.0239
1521.78	10.9394
1524.89	11.1918
1528	11.431
1531.11	12.5
1534.21	14.7816
1537.32	16.0083
1540.43	17.3084
1543.53	19.9316
1546.63	20.26
1549.74	21.9148
1552.84	23.269
1555.94	23.8529
1559.03	25.0491
1562.13	25.4026
1565.23	27.1724
1568.32	27.1853
1571.42	26.977
1574.51	28.562
1577.6	29.4342
1580.69	28.7826
1583.78	29.8412
1586.87	30.594
1589.95	31.7303
1593.04	32.4345
1596.12	32.7792
1599.21	32.8127
1602.29	33.9143
1605.37	35.6357
1608.45	35.756
1611.53	35.5874
1614.6	35.0686
1617.68	34.2631
1620.75	35.0841
1623.83	35.8709
1626.9	36.4927
1629.97	38.5085
1633.04	38.7616
1636.11	40.712
1639.18	43.0931
1642.25	45.722
1645.31	45.9383
1648.38	47.907
1651.44	47.3645
1654.5	47.8381
1657.56	47.2315
1660.62	46.6829
1663.68	44.875
1666.74	41.3238
1669.8	39.273
1672.85	37.4785
1675.91	34.8533
1678.96	32.1406
1682.01	28.3561
1685.06	24.1137
1688.11	20.1789
1691.16	16.5121
1694.21	14.5309
1697.25	12.8953
1700.3	12.776
1703.34	9.74233
1706.39	8.23111
1709.43	7.06525
1712.47	7.39705
1715.51	6.25595
1718.54	4.96425
1721.58	4.58662
1724.62	3.35844
1727.65	2.39946
1730.68	1.96758
1733.72	0.935525
1736.75	0.674777
1739.78	0.203488
1742.81	1.56046
1745.84	2.44913
1748.86	2.95352
1751.89	2.49356
1754.91	1.99985
1757.93	2.17116
1760.96	1.82118
1763.98	1.91128
1767	1.5875
1770.02	2.12707
1773.03	2.32851
1776.05	2.9146
1779.07	2.39907
1782.08	1.95817
1785.09	3.00975
1788.11	3.34838
1791.12	3.30255
1794.13	3.79916
1797.13	3.88917
1800.14	4.10794
1803.15	3.38791
1806.15	3.77064
1809.16	4.21362
1812.16	4.70722
1815.16	5.83592
1818.16	5.51979
1821.16	4.73115
1824.16	4.33149
1827.16	4.73217
1830.16	4.52417
1833.15	3.53854
1836.14	2.77917
1839.14	3.0324
1842.13	3.17765
1845.12	2.77668
1848.11	3.10949
1851.1	3.0671
1854.08	3.24477
1857.07	4.25153
1860.05	4.89271
1863.04	4.96747
1866.02	4.73506
1869	4.15253
1871.98	4.89173
1874.96	5.08813
1877.94	4.5233
1880.92	5.45752
1882.51	5.65197
1885.5	5.64807
1888.48	4.6947
1891.47	4.71597
1894.46	4.60768
1897.44	5.35244
1900.42	5.53912
1903.41	5.0638
1906.39	3.81763
1909.37	4.0574
1912.35	4.23636
1915.32	3.79025
1918.3	4.10719
1921.27	3.63619
1924.25	3.862
1927.22	2.9877
1930.19	3.08278
1933.17	2.15822
1936.14	0.501334
1939.11	0.883821
1942.07	0.409165
1945.04	-0.00094026
1948.01	-0.279907
1950.97	0.134468
1953.93	1.2784
1956.9	1.03991
1959.86	0.691892
1962.82	1.36669
1965.78	1.45984
1968.74	2.29878
1971.69	2.77857
1974.65	2.88067
1977.6	2.18009
1980.56	2.30923
1983.51	2.56416
1986.46	2.78631
1989.41	2.46394
1992.36	2.39744
1995.31	3.35562
1998.26	3.51583
2001.2	3.64119
2004.15	3.77744
2007.09	4.63942
2010.04	4.47064
2012.98	5.51214
2015.92	4.05087
2018.86	4.12071
2021.8	4.64326
2024.73	4.74268
2027.67	4.52714
2030.61	5.7135
2033.54	6.16006
2036.47	6.74366
2039.4	7.03285
2042.33	7.10909
2045.27	7.02802
2048.19	6.41049
2051.12	6.76413
2054.05	7.50572
2056.97	6.94069
2059.9	6.94863
2062.82	7.82333
2065.74	8.74456
2068.67	8.64837
2071.59	8.33625
2074.51	8.73486
2077.42	9.89574
2080.34	9.94001
2083.26	9.34185
2086.17	9.184
2089.09	9.25851
2092	10.4581
2094.91	11.3751
2097.82	11.5208
2100.73	12.5482
2103.64	13.7155
2106.55	14.0988
2109.45	14.5939
2112.36	15.4555
2115.26	16.5953
2118.17	17.4176
2121.07	19.1042
2123.97	20.5833
2126.87	21.8174
2129.77	23.7016
2132.67	24.9077
2135.56	27.8466
2138.46	29.4201
2141.35	30.1524
2144.25	32.4545
2147.14	34.2496
2150.03	36.3723
2152.92	38.0089
2155.81	39.0903
2158.7	40.9026
2161.59	43.1637
2164.47	43.7495
2167.36	43.1706
2170.24	43.6969
2173.13	44.5189
2176.01	44.3099
2178.89	44.9169
2181.77	44.481
2184.65	43.7896
2187.53	43.7215
2190.4	43.1669
2193.28	42.2911
2196.16	40.7805
2199.03	39.1709
2201.9	36.8789
2204.77	34.8904
2207.64	33.6833
2210.51	32.0225
2213.38	29.8154
2216.25	27.7461
2219.12	26.6071
2221.98	24.7206
2224.85	22.6231
2227.71	21.2098
2230.57	19.536
2233.43	17.4172
2236.29	15.9027
2239.15	14.7682
2242.01	13.9682
2244.87	13.5395
2247.72	14.001
2250.58	12.0873
2253.43	10.7462
2256.29	10.739
2259.14	10.8991
2261.99	10.5264
2264.84	10.5337
2267.69	10.3212
2270.53	9.77714
2273.38	9.56584
2276.23	9.60121
2279.07	9.25552
2281.91	8.38387
2284.76	7.26009
2287.6	7.26329
2290.44	5.6516
2293.28	3.72024
2296.12	3.04392
2298.96	3.82806
2301.79	4.68074
2304.63	5.23111
2307.46	5.66113
2310.3	5.65367
2313.13	5.6613
2315.96	6.08229
2318.79	6.21462
2321.62	6.45323
2324.45	7.63348
2327.27	7.80356
2330.1	9.05156
2332.92	8.11488
2335.75	7.94046
2338.57	7.76386
2341.39	6.83269
2344.21	5.73304
2347.04	5.11281
2349.85	3.31491
2352.67	2.2818
2355.49	1.61761
2358.3	0.751119
2361.12	-0.350851
2363.93	0.529222
2366.75	2.04059
2369.56	2.80243
2372.37	2.64516
2375.18	2.45021
2377.99	2.02537
2380.8	1.75391
2383.6	2.0538
2386.41	2.7897
2389.21	3.30087
2392.02	3.47203
2394.82	4.25522
2397.62	3.74654
2400.42	3.52576
2403.22	3.56546
2406.02	3.56271
2408.82	3.88272
2411.62	4.45358
2414.41	5.00221
2417.21	5.56392
2420	5.66202
2422.79	7.02204
2425.59	8.20498
2428.38	7.73505
2431.17	6.40078
2433.95	6.05144
2436.74	6.21207
2439.53	5.25223
2442.31	4.53214
2445.1	3.28858
2447.88	2.55916
2450.67	3.43588
2453.45	3.04225
2456.23	2.80262
2459.01	2.73959
2461.79	2.65972
2464.57	1.91445
2467.34	2.16353
2470.12	2.19501
2472.89	3.17111
2475.67	3.05886
2478.44	3.96068
2481.21	4.77882
2483.98	4.70421
2486.75	4.70857
2489.52	5.30748
2492.29	5.35071
2495.05	4.59416
2497.82	3.52247
2500.58	4.05207
2503.35	4.18406
2506.11	4.78762
2508.87	3.67192
2511.63	3.26109
2514.39	2.89096
2517.15	3.1238
2519.91	2.88212
2522.67	2.45314
2525.42	2.36856
2528.18	3.1632
2530.93	3.32229
2533.69	3.42509
2536.44	3.83086
2539.19	4.12015
2541.94	4.03626
2544.69	4.41452
2547.44	4.18688
2550.18	4.7608
2552.93	5.4647
2555.67	6.27321
2558.42	6.62333
2561.16	7.29337
2563.9	7.92253
2566.64	8.15809
2569.38	8.83799
2572.12	8.31604
2574.86	8.41115
2577.6	7.27207
2580.33	7.01783
2583.07	6.14328
2585.8	6.05783
2588.54	5.78908
2591.27	5.85371
2594	6.23065
2596.73	6.36187
2599.46	5.88272
2602.19	5.10148
2604.92	4.27
2607.64	4.37803
2610.37	4.06003
2613.09	3.25203
2615.82	4.27283
2618.54	5.29733
2621.26	5.25541
2623.98	5.49159
2626.7	5.84489
2629.42	5.97134
2632.14	5.64949
2634.86	5.53189
2637.57	5.55309
2640.29	6.3153
2643	6.82644
2645.71	6.66317
2648.43	6.51201
2651.14	7.33912
2653.85	8.0987
2656.56	8.78503
2659.26	9.64976
2661.97	9.56424
2664.68	9.41699
2667.38	9.14038
2670.09	9.60801
2672.79	9.32282
2675.49	9.10904
2678.19	9.49704
2680.89	10.1081
2683.59	11.3705
2686.29	11.2072
2688.99	10.8785
2691.69	10.4005
2694.38	9.87746
2697.08	9.33989
2699.77	8.84408
2702.46	8.61942
2705.15	7.80678
2707.85	6.94827
2710.54	5.88512
2713.22	4.25293
2715.91	4.25453
2718.6	4.57319
2721.29	4.17375
2723.97	4.57326
2726.66	4.3198
2729.34	4.14126
2732.02	4.38094
2734.7	4.61208
2737.38	5.42915
2740.06	6.6311
2742.74	6.87093
2745.42	6.53724
2748.09	6.57579
2750.77	7.29959
2753.45	6.78489
2756.12	6.81589
2758.79	6.57141
2761.46	7.21011
2764.14	6.79107
2766.8	6.68498
2769.47	5.65114
2772.14	5.85789
2774.81	5.14167
2777.48	4.24609
2780.14	3.80905
2782.8	4.10463
2785.47	4.16541
2788.13	3.82541
2790.79	3.35366
2793.45	3.02402
2796.11	2.0187
2798.77	1.47148
2801.43	1.57302
2804.09	1.61205
2806.74	0.63793
2809.4	0.496903
2812.05	0.802457
2814.71	1.47792
2817.36	2.01953
2820.01	3.61459
2822.66	4.8053
2825.31	6.8023
2827.96	8.51884
2830.6	11.7398
2833.25	14.5184
2835.9	18.1337
2838.54	22.3363
2841.18	24.4507
2843.83	27.5429
2846.47	30.3979
2849.11	34.112
2851.75	37.3376
2854.39	41.0406
2857.03	44.3171
2859.66	47.2475
2862.3	49.9813
2864.94	53.6135
2867.57	57.1326
2870.2	59.2727
2872.84	61.311
2875.47	64.0952
2878.1	65.6163
2880.73	67.7699
2883.36	70.6508
2885.99	74.2266
2888.61	76.5941
2891.24	81.1844
2893.86	85.625
2896.49	90.2909
2899.11	95.5159
2901.73	100.85
2904.36	106.117
2906.98	111.261
2909.6	117.459
2912.21	125.142
2914.83	132.218
2917.45	138.176
2920.07	144.806
2922.68	148.877
2925.29	152.856
2927.91	155.379
2930.52	156.378
2933.13	156.763
2935.74	155.192
2938.35	154.145
2940.96	151.722
2943.57	148.601
2946.18	144.065
2948.78	139.303
2951.39	134.437
2953.99	128.718
2956.59	123.246
2959.2	117.634
2961.8	110.852
2964.4	105.827
2967	99.6003
2969.6	93.0122
2972.19	87.536
2974.79	82.3878
2977.39	77.8067
2979.98	71.713
2982.58	65.3233
2985.17	60.5614
2987.76	54.9275
2990.35	49.7696
2992.94	43.7053
2995.53	38.1448
2998.12	32.6773
3000.71	28.4272
3003.3	23.8702
3005.88	19.4999
3008.47	15.6399
3011.05	12.3378
3013.64	10.9033
3016.22	8.82525
3018.8	7.70815
3021.38	5.36952
3023.96	4.9228
3026.54	3.45695
3029.12	2.94843
3031.69	2.07985
3034.27	2.17121
3036.84	2.44874
3039.42	3.01602
3041.99	3.41777
3044.57	3.05837
3047.14	3.49849
3049.71	4.30551
3052.28	4.65219
3054.85	4.55937
3057.41	3.79352
3059.98	4.02369
3062.55	3.60639
3065.11	3.19468
3067.68	2.32656
3070.24	2.46216
3072.8	2.82246
3075.36	2.9722
3077.93	2.35893
3080.49	1.89364
3083.04	0.378218
3085.6	0.352885
3088.16	0.849941
3090.72	-0.275318
3093.27	0.24131
3095.83	0.775798
3098.38	0.789643
3100.93	0.536143
3103.49	0.559695
3106.04	1.14093
3108.59	1.84827
3111.14	2.71169
3113.69	3.54519
3116.23	4.30459
3118.78	5.26314
3121.33	5.71389
3123.87	7.03007
3126.41	7.38439
3128.96	8.33763
3131.5	9.49616
3134.04	10.3876
3136.58	11.0111
3139.12	11.5759
3141.66	11.7818
3144.2	12.312
3146.74	13.0438
3149.27	12.5113