File: data/Raman/poly_smoothed/Mb_30_27_25_1x_45s_532 nm_x100_100%_600 gr_mm_02.txt
#Acq. time (s)=	45
#Accumulations=	2
#Range (cm-¹)=	200...3150
#Windows=	2
#Auto scanning=	Off
#Autofocus=	Off
#Macrospot=	Off
#AutoExposure=	Off
#Spike filter=	Multiple accum.
#Delay time (s)=	0
#Binning=	1
#Readout mode=	Signal
#DeNoise=	Off
#ICS correction=	On
#Dark correction=	Off
#Inst. Process=	Off
#Detector Gain=	Best Dynamic Range
#Detector ADC=	20 kHz
#Detector temperature (°C)=	-69.85
#Instrument=	LabRAM HR Evol
#Detector=	Synapse
#Objective=	x100
#Grating=	600 gr/mm
#ND Filter=	100%
#Laser (nm)=	532
#Hole=	100.021
#Range=	Auto
#Laser Pol.=	No
#Raman. Pol.=	No
#Laser Pol. (°)=	-0.0007625
#Raman Pol. (°)=	89.9995
#Collection=	Microscope
#StageXY=	Marzhauser
#StageZ=	Marzhauser
#X (µm)=	-6389
#Y (µm)=	849.3
#Z (µm)=	-64.55
#Full time(mm:ss)=	3:19
#Project=
#Sample=
#Site=
#Title=	Mb_30_27_25_2x_45s_532 nm_x100_100%_600 gr_mm
#Remark=
#Date=	13.07.2022 10:33
#Acquired=	13.07.2022 10:33:35
#Base:Fit=	10.08.2022 10:40:03
#Base:Sub=	10.08.2022 10:40:17
#Filter:Polynom=	16.08.2022 10:16:15
#AxisType[0]=Intens
#AxisUnit[0]=Cnt
#AxisType[1]=Spectr
#AxisUnit[1]=1/cm
200.563	11.18
204.194	10.4333
207.821	8.49115
211.449	6.77385
215.074	6.48716
218.699	5.56945
222.321	5.87591
225.941	3.92566
229.562	3.59767
233.18	3.69957
236.796	3.939
240.411	3.51078
244.026	2.77415
247.638	3.21774
251.248	3.17364
254.857	3.60788
258.465	3.44091
262.071	4.34829
265.678	3.50082
269.282	4.34785
272.884	3.52001
276.484	3.26413
280.084	4.6623
283.682	5.76215
287.276	5.62081
290.871	4.78594
294.465	6.48134
298.057	7.66518
301.648	9.54773
305.237	11.2109
308.823	11.7459
312.41	11.701
315.995	12.4842
319.579	14.1753
323.16	14.1461
326.741	17.0162
330.321	17.6732
333.897	20.7866
337.474	21.9401
341.048	24.7729
344.622	24.9617
348.192	26.4577
351.764	27.233
355.332	26.6825
358.901	25.1606
362.466	24.4351
366.03	22.898
369.594	22.0785
373.155	20.7127
376.715	19.6671
380.273	19.8365
383.832	18.6034
387.388	18.9182
390.942	17.7464
394.495	17.857
398.047	16.2207
401.597	16.3895
405.145	17.1343
408.693	17.35
412.239	19.3822
415.783	20.7494
419.327	21.3691
422.869	21.3561
426.409	22.3303
429.948	22.9666
433.486	22.3259
437.022	21.8329
440.558	19.9346
444.089	20.1416
447.622	20.5685
451.153	21.9439
454.682	21.7384
458.208	24.4314
461.735	25.4453
465.259	27.9064
468.783	30.4379
472.306	33.1629
475.825	34.846
479.346	35.6136
482.862	37.2596
486.38	38.5789
489.894	39.9455
493.407	39.425
496.92	41.2241
500.43	42.3462
503.939	40.9638
507.448	40.8591
510.954	39.1629
514.459	37.3559
517.962	35.6582
521.466	33.3142
524.966	32.4709
528.466	31.1258
531.964	28.796
535.46	28.2908
538.955	25.1988
542.449	23.5819
545.942	22.4833
549.433	20.807
552.923	20.5306
556.412	18.5472
559.899	16.8573
563.385	14.4772
566.867	12.0745
570.35	10.2223
573.832	8.6869
577.313	8.12881
580.79	7.37873
584.268	8.17124
587.745	6.05486
591.218	4.62684
594.692	5.43476
598.164	7.13297
601.634	7.65994
605.104	8.04403
608.57	8.76373
612.037	9.44165
615.501	8.45173
618.966	8.93392
622.427	9.94929
625.887	11.5677
629.348	13.8097
632.806	13.8359
636.262	14.5643
639.716	15.9394
643.172	16.7298
646.624	16.7846
650.075	16.68
653.524	16.3593
656.972	17.32
660.419	17.294
663.865	16.8122
667.309	17.3984
670.752	16.9266
674.194	18.0104
677.634	19.7602
681.073	21.8902
684.511	22.488
687.947	23.7166
691.382	25.1374
694.816	26.5788
698.247	27.9097
701.678	29.4803
705.108	31.6376
708.534	34.5206
711.962	36.3033
715.388	37.6311
718.81	38.6714
722.234	40.3862
725.654	41.8149
729.075	41.5541
732.492	42.2767
735.91	43.3308
739.325	44.7636
742.741	45.1321
746.153	46.2827
749.564	47.8611
752.976	49.1154
756.385	51.7607
759.792	53.2314
763.2	56.5718
766.604	57.5818
770.008	60.2
773.41	63.1147
776.811	65.4775
780.21	67.8515
783.608	69.1429
787.005	71.2734
790.401	73.8624
793.795	76.4611
797.188	77.1317
800.58	77.6783
803.971	78.6415
807.36	78.2099
810.748	78.2172
814.135	78.6167
817.518	78.666
820.902	79.4631
824.285	79.1576
827.665	79.3344
831.045	77.8945
834.424	76.0201
837.8	73.9573
841.177	71.5447
844.55	70.3201
847.924	68.8479
851.295	65.81
854.666	64.5998
858.034	63.757
861.403	63.104
864.769	61.8669
868.133	61.4085
871.498	62.3098
874.86	62.9637
878.221	63.053
881.58	64.6919
884.938	66.2238
888.297	67.8748
891.653	68.4255
895.007	68.6435
898.36	69.3848
901.712	70.5851
905.063	69.7407
908.412	68.018
911.76	64.7716
915.107	62.3525
918.452	60.3369
921.797	57.1264
925.138	55.8562
928.48	54.0973
931.82	50.8671
935.16	48.8074
938.496	47.8897
941.833	47.183
945.168	45.204
948.5	45.2254
951.834	45.1629
955.163	45.3271
958.494	43.2723
961.821	44.733
965.15	46.683
968.474	47.5973
971.8	48.4981
975.123	48.9785
978.446	49.4192
981.766	50.1331
985.084	49.2761
988.402	48.6433
991.72	48.764
995.035	48.0371
998.349	48.9251
1001.66	48.8463
1004.97	49.8089
1008.28	52.6064
1011.59	56.1559
1014.9	61.0066
1018.21	66.3022
1021.51	70.8018
1024.81	74.2688
1028.12	77.3483
1031.42	80.8935
1034.72	82.1268
1038.02	81.889
1041.31	80.837
1044.61	82.7648
1047.91	82.7695
1051.2	82.8505
1054.49	83.794
1057.78	84.3577
1061.07	84.0582
1064.36	83.8734
1067.65	83.1751
1070.93	84.2712
1074.22	82.8645
1077.5	81.4877
1080.78	81.0828
1084.06	81.7436
1087.34	85.0317
1090.62	88.1325
1093.9	90.4046
1097.17	90.3592
1100.45	90.0171
1103.72	91.2523
1106.99	89.5963
1110.27	87.6301
1113.53	85.1739
1116.8	80.4993
1120.07	74.6582
1123.33	70.6393
1126.6	66.8066
1129.86	63.521
1133.12	62.0317
1136.38	58.4168
1139.64	54.1942
1142.9	49.5631
1146.16	43.9767
1149.41	39.863
1152.67	33.6458
1155.92	29.3956
1159.17	25.5471
1162.42	21.7393
1165.67	18.7981
1168.92	14.8657
1172.16	11.6328
1175.41	9.44693
1178.65	7.43696
1181.9	8.40803
1185.14	8.80946
1188.38	9.36781
1191.62	10.0412
1194.86	10.3095
1198.09	11.5054
1201.33	14.27
1204.56	16.6564
1207.8	20.285
1211.03	24.5925
1214.26	28.7026
1217.49	30.7356
1220.71	33.6473
1223.94	36.56
1227.16	41.2418
1230.39	45.257
1233.61	48.9774
1236.83	53.3672
1240.05	54.9947
1243.27	57.4949
1246.49	59.6669
1249.71	61.3895
1252.92	62.0964
1256.14	64.2403
1259.35	66.1038
1262.56	68.3051
1265.77	69.773
1268.98	70.3459
1272.19	73.2248
1275.4	75.4144
1278.6	78.3556
1281.81	80.7908
1285.01	80.8578
1288.21	84.6964
1291.41	85.4084
1294.61	87.1074
1297.81	88.2767
1301.01	90.4134
1304.2	92.4245
1307.4	93.9091
1310.59	94.3087
1313.78	94.4278
1316.97	95.043
1320.16	93.8382
1323.35	93.009
1326.54	92.4238
1329.72	90.3062
1332.91	89.789
1336.09	89.0034
1339.27	88.2364
1342.45	86.4085
1345.64	84.0529
1348.81	84.0633
1351.99	83.4716
1355.17	81.6155
1358.34	79.6497
1361.51	78.8055
1364.69	76.1329
1367.86	74.4133
1371.03	71.2591
1374.2	68.8464
1377.37	67.5651
1380.53	67.6186
1383.7	65.0713
1386.86	65.2584
1390.02	61.8231
1393.19	60.8556
1396.35	59.712
1399.51	59.7646
1402.66	58.562
1405.82	58.7013
1408.97	60.0499
1412.13	60.587
1415.28	62.0437
1418.43	64.642
1421.59	67.4768
1424.73	71.8651
1427.88	75.934
1431.03	80.5169
1434.18	85.4056
1437.32	89.2956
1440.46	92.1242
1443.61	93.6598
1446.75	95.5654
1449.89	96.8353
1453.03	95.9845
1456.16	95.3025
1459.3	91.2444
1462.44	87.4591
1465.57	83.0848
1468.7	76.4825
1471.83	72.3305
1474.96	64.8997
1478.09	58.1265
1481.22	52.6264
1484.35	46.9167
1487.47	39.8329
1490.6	34.2724
1493.72	30.0411
1496.84	26.885
1499.96	24.0967
1503.08	21.4049
1506.2	20.021
1509.32	19.2217
1512.44	18.794
1515.55	17.4884
1518.66	17.8718
1521.78	18.5791
1524.89	19.4915
1528	19.5446
1531.11	18.2801
1534.21	18.885
1537.32	18.8136
1540.43	19.5896
1543.53	20.5888
1546.63	21.003
1549.74	22.6157
1552.84	22.9039
1555.94	23.3291
1559.03	25.0858
1562.13	26.5959
1565.23	28.0565
1568.32	30.8008
1571.42	34.2379
1574.51	36.5139
1577.6	38.4564
1580.69	42.0207
1583.78	45.1086
1586.87	48.104
1589.95	50.9177
1593.04	52.9436
1596.12	55.2246
1599.21	56.1724
1602.29	56.2948
1605.37	55.3953
1608.45	55.2452
1611.53	55.6604
1614.6	55.9566
1617.68	55.0875
1620.75	54.2507
1623.83	55.2899
1626.9	56.8428
1629.97	58.2147
1633.04	62.1024
1636.11	65.829
1639.18	69.4521
1642.25	72.5572
1645.31	77.3404
1648.38	81.0016
1651.44	83.1092
1654.5	86.242
1657.56	87.0971
1660.62	86.3524
1663.68	85.7692
1666.74	83.5236
1669.8	80.4103
1672.85	76.378
1675.91	71.9398
1678.96	66.2621
1682.01	61.5657
1685.06	56.6544
1688.11	50.1752
1691.16	43.1827
1694.21	37.6745
1697.25	33.3734
1700.3	30.9881
1703.34	27.8886
1706.39	24.9017
1709.43	22.4797
1712.47	19.5754
1715.51	17.5404
1718.54	17.2857
1721.58	16.52
1724.62	15.7345
1727.65	14.9127
1730.68	14.1992
1733.72	12.6886
1736.75	11.888
1739.78	11.9954
1742.81	10.8337
1745.84	9.13267
1748.86	8.64164
1751.89	8.25265
1754.91	7.9646
1757.93	7.73063
1760.96	6.64071
1763.98	4.7843
1767	5.37962
1770.02	5.07761
1773.03	4.41993
1776.05	3.64932
1779.07	3.29115
1782.08	2.38704
1785.09	2.49685
1788.11	2.67829
1791.12	3.32096
1794.13	3.24259
1797.13	3.56386
1800.14	3.69524
1803.15	4.19656
1806.15	3.88192
1809.16	3.96311
1812.16	2.92955
1815.16	2.95027
1818.16	2.10327
1821.16	1.0737
1824.16	1.26607
1827.16	0.465825
1830.16	0.579489
1833.15	0.449287
1836.14	-0.0779627
1839.14	0.927553
1842.13	1.61742
1845.12	1.6921
1848.11	2.39212
1851.1	2.35003
1854.08	2.32862
1857.07	2.91425
1860.05	3.91138
1863.04	4.10535
1866.02	3.99093
1869	4.18786
1871.98	4.79715
1874.96	4.9744
1877.94	4.74698
1880.92	4.18233
1882.51	4.10542
1885.5	4.17046
1888.48	3.76858
1891.47	3.28387
1894.46	3.15181
1897.44	3.52382
1900.42	4.23273
1903.41	4.46845
1906.39	5.21754
1909.37	5.33869
1912.35	6.49508
1915.32	6.40899
1918.3	5.75442
1921.27	5.10058
1924.25	5.07588
1927.22	5.68423
1930.19	5.69548
1933.17	3.8189
1936.14	3.06374
1939.11	2.54854
1942.07	2.75193
1945.04	2.90142
1948.01	2.23369
1950.97	2.10454
1953.93	1.92702
1956.9	2.48433
1959.86	3.1756
1962.82	3.4714
1965.78	4.11122
1968.74	5.42097
1971.69	5.4243
1974.65	6.5547
1977.6	7.00606
1980.56	7.58545
1983.51	7.33966
1986.46	7.32857
1989.41	6.64499
1992.36	6.46601
1995.31	6.72002
1998.26	6.68831
2001.2	5.9558
2004.15	4.05562
2007.09	3.21054
2010.04	2.4417
2012.98	1.47689
2015.92	1.3873
2018.86	0.667499
2021.8	1.12994
2024.73	1.55245
2027.67	1.55604
2030.61	2.55029
2033.54	3.03407
2036.47	3.91932
2039.4	4.82493
2042.33	6.74649
2045.27	7.23121
2048.19	9.42276
2051.12	11.134
2054.05	12.5626
2056.97	12.5783
2059.9	14.4382
2062.82	15.4711
2065.74	15.7548
2068.67	15.6995
2071.59	15.5611
2074.51	14.5911
2077.42	14.0861
2080.34	14.6612
2083.26	14.3746
2086.17	15.7322
2089.09	16.201
2092	16.2562
2094.91	17.3766
2097.82	17.6696
2100.73	18.7895
2103.64	20.9488
2106.55	23.1949
2109.45	24.928
2112.36	27.1506
2115.26	29.0613
2118.17	31.7662
2121.07	34.4542
2123.97	36.6184
2126.87	38.3231
2129.77	41.3111
2132.67	43.5703
2135.56	46.1456
2138.46	47.6883
2141.35	50.8628
2144.25	53.8526
2147.14	57.923
2150.03	60.9217
2152.92	65.2098
2155.81	69.4532
2158.7	72.0674
2161.59	74.4112
2164.47	76.8565
2167.36	78.7794
2170.24	80.6658
2173.13	81.9882
2176.01	83.4608
2178.89	82.6279
2181.77	81.3586
2184.65	79.9909
2187.53	78.5159
2190.4	76.2948
2193.28	73.0052
2196.16	69.4242
2199.03	65.597
2201.9	61.0977
2204.77	57.9295
2207.64	54.3125
2210.51	50.8623
2213.38	47.8496
2216.25	44.4122
2219.12	41.8974
2221.98	39.3351
2224.85	36.5635
2227.71	33.5646
2230.57	30.864
2233.43	29.5849
2236.29	28.3798
2239.15	26.719
2242.01	25.035
2244.87	24.4775
2247.72	23.6114
2250.58	22.4186
2253.43	20.4699
2256.29	19.7371
2259.14	18.3915
2261.99	17.6197
2264.84	15.8233
2267.69	15.1771
2270.53	14.9247
2273.38	14.5784
2276.23	14.5755
2279.07	14.1431
2281.91	13.2899
2284.76	12.2882
2287.6	12.3383
2290.44	12.0092
2293.28	11.2234
2296.12	9.64417
2298.96	9.84667
2301.79	10.3125
2304.63	10.6675
2307.46	10.4713
2310.3	11.7028
2313.13	10.5116
2315.96	9.76995
2318.79	8.96727
2321.62	8.46893
2324.45	7.65533
2327.27	8.12016
2330.1	7.67247
2332.92	7.31558
2335.75	6.62887
2338.57	6.39647
2341.39	6.8482
2344.21	6.24915
2347.04	5.80631
2349.85	5.57737
2352.67	4.61743
2355.49	4.36462
2358.3	4.07172
2361.12	2.69626
2363.93	2.65538
2366.75	2.57417
2369.56	2.50711
2372.37	2.36168
2375.18	2.38008
2377.99	2.83079
2380.8	2.24409
2383.6	1.38764
2386.41	0.682104
2389.21	1.07664
2392.02	1.37781
2394.82	1.76026
2397.62	2.12432
2400.42	1.10402
2403.22	1.84355
2406.02	2.04901
2408.82	2.71109
2411.62	3.63793
2414.41	4.40411
2417.21	4.85246
2420	4.08768
2422.79	4.63202
2425.59	5.13134
2428.38	4.83324
2431.17	4.55946
2433.95	4.73783
2436.74	3.59977
2439.53	3.2753
2442.31	3.80496
2445.1	3.48125
2447.88	3.14838
2450.67	2.01974
2453.45	1.90285
2456.23	1.7918
2459.01	2.85301
2461.79	2.72775
2464.57	2.17071
2467.34	3.05321
2470.12	2.67471
2472.89	3.3805
2475.67	4.25589
2478.44	4.87065
2481.21	5.3799
2483.98	5.45008
2486.75	6.22527
2489.52	6.18189
2492.29	6.52787
2495.05	6.3796
2497.82	6.36267
2500.58	6.57996
2503.35	5.87308
2506.11	4.49851
2508.87	4.19479
2511.63	3.58857
2514.39	2.36557
2517.15	1.96053
2519.91	1.5549
2522.67	1.31895
2525.42	0.753233
2528.18	0.0478378
2530.93	-0.763412
2533.69	-0.770184
2536.44	-0.299405
2539.19	0.0432828
2541.94	1.01157
2544.69	2.09542
2547.44	2.27909
2550.18	3.17522
2552.93	4.18993
2555.67	4.48639
2558.42	5.24526
2561.16	5.75436
2563.9	6.0042
2566.64	6.19905
2569.38	5.41719
2572.12	4.62057
2574.86	4.72604
2577.6	3.60416
2580.33	3.47896
2583.07	2.70438
2585.8	2.57032
2588.54	1.86756
2591.27	1.35559
2594	0.172225
2596.73	0.091459
2599.46	0.558199
2602.19	1.09241
2604.92	2.08146
2607.64	2.44753
2610.37	2.31307
2613.09	2.60273
2615.82	2.65049
2618.54	2.71888
2621.26	2.61909
2623.98	3.16069
2626.7	4.10991
2629.42	5.09627
2632.14	5.30908
2634.86	5.32856
2637.57	5.46344
2640.29	5.5612
2643	5.35019
2645.71	5.64585
2648.43	5.43405
2651.14	3.91869
2653.85	4.33598
2656.56	3.45193
2659.26	3.17305
2661.97	2.88569
2664.68	2.87717
2667.38	2.45599
2670.09	1.87826
2672.79	1.68077
2675.49	1.47988
2678.19	0.850475
2680.89	0.145876
2683.59	-0.0874293
2686.29	0.189989
2688.99	1.27704
2691.69	2.09029
2694.38	1.87311
2697.08	2.35929
2699.77	3.15502
2702.46	4.10368
2705.15	5.30778
2707.85	6.73992
2710.54	8.4354
2713.22	9.22786
2715.91	10.1777
2718.6	12.0224
2721.29	12.5166
2723.97	12.2313
2726.66	12.5484
2729.34	12.6928
2732.02	12.1779
2734.7	11.5306
2737.38	11.306
2740.06	11.3861
2742.74	10.7014
2745.42	9.9045
2748.09	9.45596
2750.77	8.62486
2753.45	7.12849
2756.12	5.99117
2758.79	4.80735
2761.46	4.05275
2764.14	3.74645
2766.8	3.65881
2769.47	2.65602
2772.14	2.90876
2774.81	2.05181
2777.48	2.18808
2780.14	1.79289
2782.8	1.90114
2785.47	1.93387
2788.13	1.40241
2790.79	2.09222
2793.45	2.67708
2796.11	3.13062
2798.77	3.36794
2801.43	3.97524
2804.09	5.09194
2806.74	5.79736
2809.4	5.62321
2812.05	7.01007
2814.71	8.09212
2817.36	10.054
2820.01	13.176
2822.66	16.9532
2825.31	20.8566
2827.96	24.1933
2830.6	29.6788
2833.25	34.5013
2835.9	39.9657
2838.54	47.3556
2841.18	55.9079
2843.83	65.9656
2846.47	76.5251
2849.11	88.5042
2851.75	101.545
2854.39	114.302
2857.03	126.861
2859.66	140.258
2862.3	152.983
2864.94	165.322
2867.57	176.586
2870.2	187.885
2872.84	197.98
2875.47	209.171
2878.1	219.85
2880.73	229.692
2883.36	239.072
2885.99	246.436
2888.61	253.142
2891.24	259.804
2893.86	264.952
2896.49	271.562
2899.11	276.279
2901.73	282.934
2904.36	288.966
2906.98	296.425
2909.6	302.318
2912.21	309.622
2914.83	317.014
2917.45	321.367
2920.07	326.099
2922.68	330.354
2925.29	333.273
2927.91	332.716
2930.52	331.013
2933.13	328.135
2935.74	323.433
2938.35	316.88
2940.96	309.74
2943.57	301.276
2946.18	290.621
2948.78	279.611
2951.39	266.958
2953.99	254.602
2956.59	242.334
2959.2	229.337
2961.8	216.776
2964.4	203.87
2967	190.96
2969.6	179.052
2972.19	167.501
2974.79	155.469
2977.39	145.44
2979.98	134.297
2982.58	123.898
2985.17	113.464
2987.76	102.89
2990.35	92.0785
2992.94	82.6649
2995.53	72.5597
2998.12	63.0808
3000.71	54.0253
3003.3	45.9245
3005.88	38.4984
3008.47	31.7736
3011.05	26.1649
3013.64	20.7885
3016.22	16.1575
3018.8	12.2337
3021.38	8.64886
3023.96	6.08103
3026.54	4.15978
3029.12	1.79497
3031.69	-0.586569
3034.27	-1.71968
3036.84	-1.78877
3039.42	-2.1978
3041.99	-1.60001
3044.57	-0.811347
3047.14	0.199661
3049.71	1.26214
3052.28	1.85917
3054.85	3.30357
3057.41	3.39219
3059.98	4.08033
3062.55	3.77833
3065.11	3.98922
3067.68	4.03232
3070.24	4.59689
3072.8	4.08598
3075.36	3.27164
3077.93	3.01284
3080.49	2.59229
3083.04	2.09648
3085.6	1.6437
3088.16	1.36934
3090.72	0.758471
3093.27	0.087134
3095.83	1.03429
3098.38	2.53989
3100.93	3.25755
3103.49	4.07863
3106.04	5.71427
3108.59	7.4055
3111.14	9.09506
3113.69	11.0448
3116.23	13.1465
3118.78	15.5342
3121.33	17.7046
3123.87	20.2092
3126.41	22.0019
3128.96	24.4808
3131.5	26.6361
3134.04	28.1899
3136.58	30.4719
3139.12	32.6308
3141.66	34.9548
3144.2	36.5673
3146.74	38.1668
3149.27	40.2312