File: data/Raman/poly_smoothed/Mb_40_24_19_1x_45s_532 nm_x100_100%_600 gr_mm_01.txt
#Acq. time (s)=	45
#Accumulations=	2
#Range (cm-¹)=	200...3150
#Windows=	2
#Auto scanning=	Off
#Autofocus=	Off
#Macrospot=	Off
#AutoExposure=	Off
#Spike filter=	Multiple accum.
#Delay time (s)=	0
#Binning=	1
#Readout mode=	Signal
#DeNoise=	Off
#ICS correction=	On
#Dark correction=	Off
#Inst. Process=	Off
#Detector Gain=	Best Dynamic Range
#Detector ADC=	20 kHz
#Detector temperature (°C)=	-70.08
#Instrument=	LabRAM HR Evol
#Detector=	Synapse
#Objective=	x100
#Grating=	600 gr/mm
#ND Filter=	100%
#Laser (nm)=	532
#Hole=	100.021
#Range=	Auto
#Laser Pol.=	No
#Raman. Pol.=	No
#Laser Pol. (°)=	-0.0007625
#Raman Pol. (°)=	89.9995
#Collection=	Microscope
#StageXY=	Marzhauser
#StageZ=	Marzhauser
#X (µm)=	-2534.3
#Y (µm)=	-115
#Z (µm)=	-10.55
#Full time(mm:ss)=	3:19
#Project=
#Sample=
#Site=
#Title=	Mb_40_24_19_2x_45s_532 nm_x100_100%_600 gr_mm
#Remark=
#Date=	14.07.2022 12:04
#Acquired=	14.07.2022 12:04:09
#Base:Fit=	10.08.2022 10:47:00
#Base:Sub=	10.08.2022 10:47:12
#Filter:Polynom=	16.08.2022 10:11:48
#AxisType[0]=Intens
#AxisUnit[0]=Cnt
#AxisType[1]=Spectr
#AxisUnit[1]=1/cm
200.554	57.9594
204.183	57.6498
207.813	51.6028
211.439	44.8271
215.065	40.6997
218.688	38.1623
222.312	35.3599
225.933	29.7432
229.552	28.4
233.171	26.7795
236.787	25.594
240.402	23.4863
244.015	19.5387
247.627	17.7029
251.24	14.9556
254.849	12.6236
258.457	11.0907
262.063	12.5734
265.668	11.9919
269.271	10.3725
272.873	9.50655
276.474	8.77218
280.073	6.17665
283.671	3.86704
287.268	2.39986
290.863	-0.635584
294.456	0.366547
298.049	0.0598219
301.637	1.57346
305.227	2.48368
308.815	1.44925
312.402	3.09243
315.987	5.00682
319.569	7.08749
323.151	8.28331
326.733	8.70031
330.31	9.16141
333.889	9.73421
337.464	10.4705
341.039	9.72575
344.611	8.88367
348.184	10.4109
351.754	10.8239
355.324	9.8536
358.89	8.66615
362.455	8.56124
366.021	4.31689
369.584	3.83931
373.145	4.54723
376.707	5.36931
380.265	4.57122
383.822	2.93426
387.378	1.36507
390.934	3.9077
394.487	2.46344
398.038	3.06228
401.588	4.96032
405.137	4.4117
408.685	5.27109
412.23	6.73793
415.775	7.42445
419.318	8.29717
422.86	8.35112
426.401	8.85226
429.94	9.59529
433.478	12.3696
437.012	14.8094
440.547	16.3976
444.081	18.9616
447.613	17.7255
451.142	17.7885
454.672	18.952
458.2	21.9858
461.725	21.5169
465.251	20.6904
468.775	20.8065
472.296	21.7271
475.817	22.3914
479.335	23.5321
482.854	23.7147
486.37	25.9279
489.886	27.144
493.398	29.205
496.91	30.6593
500.422	33.1738
503.93	35.8125
507.438	38.7803
510.946	40.8057
514.45	43.6857
517.954	45.5505
521.456	50.215
524.956	53.1483
528.456	54.183
531.956	52.6489
535.452	52.4876
538.947	51.9714
542.441	52.4579
545.934	51.1027
549.425	48.8258
552.915	45.8032
556.403	45.3361
559.889	42.6005
563.375	40.9539
566.859	38.5639
570.342	37.0016
573.824	33.4755
577.303	31.0283
580.782	27.3904
584.26	24.6219
587.734	23.9105
591.21	22.0349
594.684	22.4546
598.154	23.4388
601.626	24.6361
605.094	24.6818
608.562	26.3163
612.027	26.966
615.493	27.6496
618.956	26.6891
622.419	28.717
625.879	29.8325
629.338	31.6064
632.797	28.7892
636.254	29.9888
639.708	29.613
643.162	30.7461
646.614	30.1364
650.067	26.4551
653.516	23.1176
656.964	19.7115
660.411	16.2543
663.857	13.4055
667.301	10.7148
670.744	9.0518
674.186	9.30789
677.626	8.81681
681.065	10.4268
684.503	8.37239
687.939	8.74253
691.372	11.1954
694.806	11.7115
698.239	12.4008
701.67	13.2135
705.098	16.0594
708.526	19.6497
711.954	22.2556
715.378	23.5343
718.802	25.0522
722.226	27.4943
725.646	28.7692
729.067	29.5456
732.484	27.4128
735.902	28.2699
739.317	29.4233
742.731	32.0116
746.145	35.0864
749.556	37.3273
752.966	41.8713
756.377	45.5438
759.784	50.1497
763.19	49.3743
766.594	52.0716
770	55.6437
773.402	59.3236
776.803	59.6919
780.202	63
783.6	66.0367
786.997	66.3359
790.393	67.7274
793.787	68.6346
797.18	67.2009
800.572	67.2359
803.963	65.8105
807.35	64.4274
810.738	60.3808
814.125	58.9264
817.51	57.9572
820.894	59.0667
824.275	61.3581
827.657	65.8219
831.037	71.0961
834.414	76.7661
837.792	80.954
841.167	85.9884
844.542	89.69
847.914	91.2505
851.287	96.4922
854.656	100.139
858.026	100.899
861.393	101.964
864.761	100.269
868.125	96.9788
871.489	94.7543
874.85	93.4777
878.213	89.7054
881.572	84.2099
884.931	79.4919
888.287	71.664
891.643	64.9111
894.997	62.3143
898.352	59.2113
901.704	58.9716
905.055	57.0127
908.404	57.2407
911.75	56.7611
915.097	59.325
918.443	59.6184
921.787	60.9255
925.13	61.7238
928.472	63.0854
931.813	62.862
935.15	63.8326
938.488	60.8337
941.825	57.6376
945.158	55.8326
948.493	51.7153
951.824	51.5832
955.156	51.8047
958.486	47.5236
961.814	44.4188
965.142	43.372
968.467	44.9218
971.79	46.173
975.115	48.6848
978.436	49.3606
981.756	48.9938
985.077	47.457
988.394	44.9162
991.71	44.8438
995.025	43.8026
998.341	42.7835
1001.65	40.8457
1004.97	39.5719
1008.28	42.5982
1011.58	45.8011
1014.89	54.3243
1018.2	59.9995
1021.5	66.5878
1024.81	76.4142
1028.11	83.7844
1031.41	90.268
1034.71	97.8679
1038.01	101.747
1041.31	106.56
1044.6	112.14
1047.9	117.108
1051.19	119.155
1054.48	118.318
1057.77	115.816
1061.06	111.585
1064.35	105.278
1067.64	97.3994
1070.93	90.2205
1074.21	81.5581
1077.49	70.7392
1080.78	60.9893
1084.06	53.3531
1087.34	49.2275
1090.61	48.1247
1093.89	48.0756
1097.17	47.1256
1100.44	45.9037
1103.71	44.719
1106.99	45.2842
1110.26	44.4369
1113.52	41.8672
1116.79	40.3938
1120.06	39.0738
1123.32	39.6717
1126.59	39.1975
1129.85	36.8726
1133.11	36.4971
1136.37	34.9654
1139.63	31.4377
1142.89	28.9191
1146.15	25.2881
1149.4	23.1823
1152.66	19.4141
1155.91	15.7704
1159.16	12.8502
1162.41	10.298
1165.66	8.56106
1168.91	8.12336
1172.16	6.87116
1175.4	6.63959
1178.65	7.2264
1181.89	7.65975
1185.13	8.55459
1188.37	10.642
1191.61	14.2976
1194.85	16.9648
1198.08	20.913
1201.32	27.2669
1204.55	31.0761
1207.79	35.9783
1211.02	38.783
1214.25	43.3075
1217.48	47.0259
1220.71	51.4893
1223.93	55.7281
1227.16	61.0448
1230.38	65.9129
1233.6	69.3756
1236.83	72.8295
1240.05	77.7605
1243.26	80.3443
1246.48	85.5785
1249.7	86.7223
1252.92	90.8215
1256.13	92.6633
1259.34	98.1802
1262.55	101.334
1265.76	107.132
1268.97	113.147
1272.18	121.573
1275.39	127.723
1278.59	136.626
1281.8	141.985
1285	147.041
1288.2	153.262
1291.4	156.386
1294.6	159.747
1297.8	163.121
1301	164.174
1304.19	165.079
1307.39	163.781
1310.58	160.424
1313.77	158.96
1316.96	155.787
1320.15	152.313
1323.34	148.442
1326.53	144.372
1329.72	139.282
1332.9	136.267
1336.08	133.4
1339.27	134.252
1342.45	131.877
1345.63	131.679
1348.8	132.781
1351.98	133.632
1355.16	133.479
1358.33	131.791
1361.51	131.184
1364.68	131.3
1367.85	131.187
1371.02	130.609
1374.19	130.976
1377.36	133.432
1380.52	135.496
1383.69	136.05
1386.85	137.487
1390.02	138.812
1393.18	142.445
1396.34	145.341
1399.5	149.823
1402.65	157.418
1405.81	167.299
1408.97	178.455
1412.12	191.343
1415.27	205.64
1418.43	217.772
1421.58	231.892
1424.73	244.69
1427.87	258.58
1431.02	273.051
1434.17	285.697
1437.31	296.076
1440.46	302.905
1443.6	306.855
1446.74	308.555
1449.88	305.784
1453.02	299.609
1456.16	291.097
1459.29	278.12
1462.43	262.035
1465.56	247.149
1468.69	229.849
1471.83	210.56
1474.95	190.224
1478.08	173.235
1481.21	156.807
1484.34	139.464
1487.47	120.347
1490.59	107.617
1493.71	93.4451
1496.84	81.9442
1499.96	74.0586
1503.07	68.4486
1506.19	64.0742
1509.31	58.997
1512.43	55.2997
1515.54	52.5811
1518.65	50.2677
1521.77	49.2279
1524.88	49.436
1527.99	51.9008
1531.1	53.569
1534.21	59.0813
1537.31	63.515
1540.42	67.5136
1543.52	73.0811
1546.63	78.751
1549.73	82.4666
1552.83	87.3402
1555.93	92.6466
1559.03	96.9708
1562.12	100.898
1565.22	105.599
1568.31	110.69
1571.41	117.477
1574.5	124.38
1577.59	133.05
1580.68	139.208
1583.77	145.955
1586.86	149.838
1589.95	153.324
1593.03	155.969
1596.11	159.65
1599.2	164.064
1602.28	165.595
1605.36	166.036
1608.44	167.125
1611.52	168.012
1614.6	168.81
1617.67	170.089
1620.75	172.635
1623.82	172.751
1626.89	173.446
1629.96	173.943
1633.04	174.834
1636.11	175.099
1639.17	175.159
1642.24	176.95
1645.31	179.438
1648.37	180.854
1651.43	178.737
1654.5	175.693
1657.56	170.185
1660.62	164.947
1663.67	157.752
1666.73	150.228
1669.79	143.261
1672.84	133.304
1675.9	124.858
1678.95	114.217
1682	106.819
1685.05	98.9301
1688.1	91.1512
1691.15	84.1407
1694.2	78.2753
1697.25	71.8938
1700.29	66.0251
1703.33	63.0676
1706.38	59.3617
1709.42	56.7601
1712.46	54.1023
1715.5	51.5658
1718.54	49.0681
1721.57	46.9078
1724.61	44.0031
1727.64	42.0428
1730.68	39.1497
1733.71	38.634
1736.74	36.1829
1739.77	34.527
1742.8	32.9744
1745.83	30.0229
1748.85	28.9858
1751.88	26.6309
1754.91	24.774
1757.93	23.1734
1760.95	19.0898
1763.97	17.0437
1766.99	16.0784
1770.01	15.006
1773.03	13.8902
1776.04	14.655
1779.06	14.1846
1782.07	13.9404
1785.09	12.9224
1788.1	10.6584
1791.11	9.40504
1794.12	8.65331
1797.13	7.98866
1800.13	8.34042
1803.14	7.64279
1806.15	6.01853
1809.15	5.22187
1812.15	4.19811
1815.16	4.3684
1818.15	5.12559
1821.16	4.9344
1824.15	4.86099
1827.15	5.01523
1830.15	4.10829
1833.14	3.82081
1836.14	3.22842
1839.13	3.92257
1842.12	3.96497
1845.11	4.74624
1848.1	6.22261
1851.09	5.51835
1854.08	6.25679
1857.06	5.92908
1860.05	7.22918
1863.03	7.96686
1866.01	8.73596
1869	9.37313
1871.98	10.2254
1874.96	11.1037
1877.93	11.4078
1880.91	10.7977
1882.47	11.9607
1885.46	12.3545
1888.44	13.4069
1891.43	13.3075
1894.42	12.9457
1897.4	13.3594
1900.39	11.4037
1903.37	11.2432
1906.35	10.476
1909.33	10.5729
1912.31	10.146
1915.29	11.2212
1918.26	11.677
1921.24	11.4131
1924.21	11.6907
1927.19	9.7568
1930.16	8.77815
1933.13	8.22871
1936.1	7.66785
1939.07	6.50062
1942.04	6.43483
1945	7.66337
1947.97	7.94075
1950.93	8.8333
1953.9	8.45893
1956.86	8.77007
1959.82	7.81597
1962.78	9.4194
1965.74	9.81932
1968.7	10.8463
1971.65	11.3601
1974.61	10.7765
1977.57	12.4937
1980.52	11.8283
1983.47	11.6637
1986.42	10.4127
1989.37	10.2442
1992.32	7.96028
1995.27	5.92988
1998.22	4.65032
2001.17	3.31508
2004.11	2.58111
2007.05	3.63032
2010	3.32352
2012.94	3.66411
2015.88	4.04487
2018.82	5.41614
2021.76	6.60383
2024.7	6.74726
2027.63	8.03222
2030.57	8.43925
2033.5	9.81352
2036.44	11.0012
2039.37	13.5325
2042.3	14.7082
2045.23	17.3992
2048.16	19.4106
2051.08	20.2816
2054.01	21.2404
2056.94	21.7861
2059.86	20.7016
2062.79	19.9475
2065.71	21.4818
2068.63	22.193
2071.55	24.9629
2074.47	24.4163
2077.39	24.5492
2080.31	24.4582
2083.22	24.8906
2086.13	25.3416
2089.05	25.3171
2091.96	26.2979
2094.87	26.3901
2097.78	27.6962
2100.69	31.0753
2103.6	34.0045
2106.51	37.0775
2109.42	40.6336
2112.32	44.168
2115.23	50.017
2118.13	54.7409
2121.03	58.2715
2123.93	62.4921
2126.83	67.4002
2129.73	71.1539
2132.63	75.6573
2135.53	81.7775
2138.42	87.8988
2141.32	93.1608
2144.21	97.0492
2147.1	100.61
2150	104.03
2152.89	107.55
2155.78	111.601
2158.66	115.797
2161.55	118.867
2164.44	121.259
2167.32	123.113
2170.21	124.474
2173.09	125.835
2175.97	124.325
2178.85	123.216
2181.73	123.118
2184.61	121.844
2187.49	119.396
2190.37	115.943
2193.24	112.234
2196.12	107.602
2198.99	102.892
2201.87	97.9374
2204.74	93.1616
2207.61	87.4216
2210.48	82.0825
2213.35	76.5014
2216.21	72.0509
2219.08	67.8262
2221.95	61.908
2224.81	57.3544
2227.67	54.6745
2230.54	50.4969
2233.4	46.0647
2236.26	41.3656
2239.11	36.8217
2241.97	33.8825
2244.83	31.7639
2247.69	30.1085
2250.54	29.5938
2253.4	27.3192
2256.25	26.4071
2259.1	25.5665
2261.95	23.9307
2264.8	22.9619
2267.65	22.3187
2270.5	21.9341
2273.34	19.552
2276.19	17.0145
2279.03	17.3539
2281.88	16.3123
2284.72	15.3718
2287.56	13.2811
2290.4	11.6162
2293.24	8.01715
2296.08	7.41514
2298.92	7.97249
2301.76	5.53186
2304.59	3.18764
2307.43	1.7272
2310.26	0.150987
2313.09	1.15835
2315.92	-0.434894
2318.75	-1.04583
2321.58	0.273474
2324.41	-0.913934
2327.24	0.170316
2330.06	0.0216879
2332.89	-0.513599
2335.71	-0.376006
2338.54	-0.539463
2341.36	-1.05462
2344.18	-0.892272
2347	0.090339
2349.82	-0.437655
2352.64	-0.977327
2355.45	0.594363
2358.27	1.20988
2361.08	2.42086
2363.9	2.78623
2366.71	5.00997
2369.52	5.71598
2372.33	4.70788
2375.14	5.32279
2377.95	4.84651
2380.76	5.837
2383.57	4.84177
2386.37	4.32025
2389.18	4.34323
2391.98	5.00989
2394.79	3.40027
2397.59	4.36957
2400.39	3.37894
2403.19	3.59186
2405.99	3.01777
2408.78	3.51132
2411.58	3.93885
2414.38	2.67628
2417.17	2.99816
2419.97	3.08249
2422.76	5.05631
2425.55	5.33303
2428.34	4.90416
2431.13	4.98244
2433.92	5.18662
2436.71	6.24133
2439.49	5.00423
2442.28	5.92409
2445.06	6.34458
2447.85	5.58595
2450.63	6.1137
2453.41	4.05399
2456.19	3.33889
2458.97	5.13314
2461.75	6.93881
2464.53	8.03625
2467.31	9.22483
2470.08	9.47704
2472.86	9.03794
2475.63	8.89227
2478.4	9.8208
2481.17	9.80358
2483.94	9.63986
2486.72	10.0152
2489.48	11.0392
2492.25	10.4637
2495.02	8.94274
2497.79	7.29231
2500.55	6.4661
2503.31	6.18754
2506.08	4.72781
2508.84	3.27173
2511.6	2.00772
2514.36	-0.174323
2517.12	-1.47052
2519.88	-2.61132
2522.63	-2.69918
2525.39	-0.0543165
2528.14	0.403822
2530.9	1.19948
2533.65	1.06359
2536.4	1.59926
2539.15	2.52468
2541.9	3.68655
2544.65	4.58866
2547.4	5.09483
2550.15	5.57684
2552.89	5.28695
2555.64	6.42455
2558.38	7.09839
2561.12	5.42663
2563.87	5.8064
2566.61	5.93659
2569.35	5.9208
2572.09	5.25086
2574.83	6.50695
2577.56	6.98482
2580.3	6.76663
2583.04	7.57921
2585.77	7.61828
2588.5	8.49878
2591.23	8.50452
2593.97	8.34918
2596.7	8.68215
2599.43	9.09306
2602.15	9.26979
2604.88	9.66546
2607.61	10.2657
2610.33	10.5598
2613.06	9.56854
2615.78	9.40259
2618.51	9.71941
2621.23	10.8887
2623.95	12.3322
2626.67	12.3928
2629.39	12.0289
2632.1	13.1769
2634.82	14.8026
2637.54	16.5403
2640.25	19.0269
2642.97	20.2682
2645.68	20.184
2648.39	21.038
2651.1	19.8215
2653.81	19.0407
2656.52	18.3914
2659.23	17.9295
2661.94	18.011
2664.64	18.294
2667.35	17.0157
2670.05	15.8141
2672.76	15.3661
2675.46	15.1047
2678.16	15.1721
2680.86	14.9634
2683.56	16.2
2686.26	17.8653
2688.96	18.2259
2691.65	18.9021
2694.35	20.5339
2697.04	22.0696
2699.74	25.2011
2702.43	27.9988
2705.12	29.436
2707.81	30.5847
2710.5	32.6132
2713.19	34.0226
2715.88	33.9981
2718.57	34.6675
2721.25	37.0921
2723.94	37.5819
2726.62	37.4143
2729.3	36.6349
2731.99	35.378
2734.67	32.6905
2737.35	30.8173
2740.03	29.966
2742.71	28.1127
2745.38	25.6779
2748.06	24.4459
2750.74	21.0761
2753.41	18.7523
2756.09	16.5585
2758.76	15.5571
2761.43	12.9831
2764.1	10.1404
2766.77	7.94775
2769.44	6.05728
2772.11	4.20616
2774.77	2.91118
2777.44	2.68439
2780.11	2.24725
2782.77	2.31628
2785.43	4.56343
2788.1	5.01254
2790.76	5.99596
2793.42	6.70351
2796.08	7.77158
2798.74	8.06144
2801.4	9.5343
2804.05	11.9847
2806.71	12.0896
2809.36	10.856
2812.02	12.0889
2814.67	15.2643
2817.32	19.9356
2819.97	26.9876
2822.62	35.5831
2825.27	47.6455
2827.92	62.0676
2830.57	80.1986
2833.22	99.9334
2835.86	119.673
2838.51	140.485
2841.15	163.254
2843.79	185.412
2846.43	207.863
2849.08	234.142
2851.72	260.301
2854.36	286.614
2856.99	312.877
2859.63	337.631
2862.27	361.685
2864.9	384.604
2867.54	403.508
2870.17	418.594
2872.8	432.535
2875.43	445.683
2878.07	461.279
2880.7	477.081
2883.32	492.68
2885.95	508.405
2888.58	527.085
2891.21	544.964
2893.83	562.315
2896.46	577.976
2899.08	593.338
2901.7	612.229
2904.32	630.962
2906.94	652.099
2909.56	675.931
2912.18	701.567
2914.8	728.494
2917.42	752.532
2920.03	773.491
2922.65	789.911
2925.26	802.467
2927.88	808.254
2930.49	804.343
2933.1	797.23
2935.71	784.992
2938.32	767.813
2940.93	745.724
2943.54	720.389
2946.14	691.267
2948.75	659.765
2951.35	627.976
2953.96	594.484
2956.56	559.787
2959.16	525.04
2961.77	493.232
2964.37	466.81
2966.96	439.573
2969.56	416.122
2972.16	394.987
2974.76	374.498
2977.35	356.739
2979.95	337.15
2982.54	316.054
2985.14	296.207
2987.73	273.993
2990.32	252.041
2992.91	228.5
2995.5	207.381
2998.09	185.264
3000.68	162.664
3003.26	141.309
3005.85	120.976
3008.43	103.352
3011.02	86.2814
3013.6	72.3985
3016.19	59.4364
3018.77	47.5294
3021.35	38.9395
3023.93	30.3866
3026.5	23.8933
3029.08	19.178
3031.66	15.2991
3034.24	12.7282
3036.81	11.9481
3039.39	12.1839
3041.96	11.7101
3044.53	11.0899
3047.1	11.2825
3049.67	13.8159
3052.24	14.7057
3054.81	16.0775
3057.38	16.7762
3059.95	16.4109
3062.52	15.9824
3065.08	14.9761
3067.65	13.8591
3070.21	12.3506
3072.77	11.8931
3075.33	11.1815
3077.89	8.86026
3080.45	6.97077
3083.01	5.47127
3085.57	3.25633
3088.13	1.83719
3090.68	0.537808
3093.24	0.736695
3095.79	0.0271552
3098.35	0.426946
3100.9	0.497861
3103.45	0.7497
3106	1.60991
3108.55	2.72737
3111.1	5.02836
3113.65	7.76023
3116.2	9.45666
3118.75	12.5178
3121.29	14.6004
3123.84	17.1687
3126.38	19.4244
3128.92	22.5415
3131.47	24.7231
3134.01	27.4907
3136.55	30.9758
3139.09	34.0199
3141.63	35.1814
3144.17	37.9798
3146.7	40.3546
3149.24	40.6763