File: data/Raman/poly_smoothed/Mb_40_y_49_1x_45s_532 nm_x100_100%_600 gr_mm_01.txt
#Acq. time (s)=	45
#Accumulations=	2
#Range (cm-¹)=	200...3150
#Windows=	2
#Auto scanning=	Off
#Autofocus=	Off
#Macrospot=	Off
#AutoExposure=	Off
#Spike filter=	Multiple accum.
#Delay time (s)=	0
#Binning=	1
#Readout mode=	Signal
#DeNoise=	Off
#ICS correction=	On
#Dark correction=	Off
#Inst. Process=	Off
#Detector Gain=	Best Dynamic Range
#Detector ADC=	20 kHz
#Detector temperature (°C)=	-69.85
#Instrument=	LabRAM HR Evol
#Detector=	Synapse
#Objective=	x100
#Grating=	600 gr/mm
#ND Filter=	100%
#Laser (nm)=	532
#Hole=	100.021
#Range=	Auto
#Laser Pol.=	No
#Raman. Pol.=	No
#Laser Pol. (°)=	-0.0007625
#Raman Pol. (°)=	89.9995
#Collection=	Microscope
#StageXY=	Marzhauser
#StageZ=	Marzhauser
#X (µm)=	-1141.9
#Y (µm)=	679.4
#Z (µm)=	584.35
#Full time(mm:ss)=	3:18
#Project=
#Sample=
#Site=
#Title=	Mb_40_y_49_2x_45s_532 nm_x100_100%_600 gr_mm
#Remark=
#Date=	19.07.2022 13:44
#Acquired=	19.07.2022 13:44:29
#Edit:Spike=	19.07.2022 13:46:35
#Edit:Spike=	19.07.2022 13:46:36
#Edit:Spike=	19.07.2022 13:46:37
#Base:Fit=	10.08.2022 10:52:48
#Base:Sub=	10.08.2022 10:52:53
#Filter:Polynom=	16.08.2022 10:09:04
#AxisType[0]=Intens
#AxisUnit[0]=Cnt
#AxisType[1]=Spectr
#AxisUnit[1]=1/cm
200.423	86.8629
204.052	84.4718
207.682	79.8481
211.308	74.7182
214.935	68.1283
218.558	65.1307
222.18	61.9393
225.802	53.9157
229.421	49.6733
233.039	47.2108
236.657	43.143
240.272	37.8468
243.885	34.9579
247.497	32.0675
251.11	29.109
254.719	28.0164
258.327	25.6256
261.933	23.1133
265.538	22.2316
269.141	18.4818
272.744	16.7057
276.344	14.703
279.944	15.2571
283.542	13.7368
287.138	11.2652
290.733	11.2679
294.327	10.8792
297.919	9.8825
301.508	9.63845
305.098	10.8142
308.686	11.2688
312.273	9.8218
315.858	9.81861
319.44	9.82907
323.022	9.02483
326.604	7.22886
330.181	7.8738
333.76	9.62383
337.335	10.1088
340.91	9.86982
344.483	8.90215
348.055	7.43237
351.625	6.08073
355.195	4.98558
358.762	3.51168
362.329	2.97136
365.893	3.14072
369.455	2.97539
373.017	3.86675
376.578	3.85574
380.137	5.79566
383.694	4.76801
387.249	5.84452
390.806	6.02209
394.359	6.36016
397.91	7.05732
401.46	5.79777
405.009	6.41483
408.557	5.80231
412.103	6.80313
415.647	8.00404
419.191	11.118
422.733	12.4594
426.273	11.4715
429.812	11.67
433.35	12.2538
436.885	10.1636
440.42	10.0375
443.954	9.24535
447.486	10.3267
451.015	10.1691
454.545	10.4385
458.073	11.3897
461.598	11.7772
465.124	12.9031
468.648	15.4044
472.169	16.571
475.69	19.2295
479.208	21.34
482.727	22.6049
486.243	26.0722
489.759	27.9631
493.272	30.1192
496.783	33.3139
500.295	37.027
503.804	39.1772
507.311	39.232
510.819	40.313
514.324	39.0184
517.827	39.1157
521.329	36.7734
524.83	35.8029
528.329	35.2373
531.829	33.4328
535.326	30.9005
538.821	29.3248
542.315	27.5638
545.808	27.2595
549.299	26.089
552.789	26.5264
556.278	24.2914
559.763	22.294
563.249	21.7085
566.733	17.2734
570.217	16.3241
573.699	13.0408
577.177	12.2633
580.656	13.2726
584.134	14.0637
587.609	11.0806
591.084	10.1455
594.558	9.19868
598.029	10.0744
601.5	11.6038
604.968	10.023
608.437	9.36472
611.902	12.1272
615.368	12.4005
618.831	14.5747
622.294	16.9516
625.755	20.2913
629.213	21.765
632.673	23.8011
636.129	19.2457
639.584	19.1105
643.037	17.917
646.491	18.9606
649.942	17.9115
653.392	17.2811
656.84	17.3466
660.287	16.0949
663.732	15.4056
667.177	14.8852
670.62	15.2751
674.061	15.8535
677.502	17.778
680.941	20.0098
684.379	22.6162
687.815	23.7239
691.248	25.6472
694.682	28.7804
698.115	31.308
701.546	35.5798
704.974	39.0609
708.402	43.7086
711.83	46.3244
715.254	49.2726
718.679	49.7472
722.102	51.679
725.522	53.8927
728.943	56.3687
732.361	56.6494
735.779	55.5647
739.194	54.739
742.608	53.8049
746.022	53.3048
749.433	53.8473
752.843	57.5977
756.254	60.2673
759.661	62.2899
763.067	63.2449
766.471	64.8808
769.877	66.4934
773.279	65.8469
776.68	66.7434
780.079	68.4237
783.478	69.6348
786.875	73.5961
790.27	75.125
793.665	78.5361
797.058	77.8039
800.45	80.6485
803.84	80.4023
807.23	81.7072
810.616	81.3307
814.002	80.6259
817.388	79.8177
820.772	78.222
824.153	78.1157
827.535	76.8432
830.915	76.7492
834.292	76.97
837.67	76.8997
841.047	74.367
844.42	72.8203
847.794	71.5023
851.165	68.1813
854.534	67.9919
857.905	66.5066
861.272	65.6017
864.639	65.4876
868.004	64.5942
871.367	63.4016
874.731	62.4911
878.092	62.3851
881.451	60.5641
884.809	56.3568
888.166	54.5969
891.522	55.6072
894.878	57.1293
898.231	59.1941
901.583	57.8656
904.934	58.4064
908.283	57.2708
911.631	56.9556
914.976	57.5065
918.322	58.4177
921.666	58.9139
925.009	60.0531
928.351	62.5358
931.692	63.4851
935.029	65.57
938.367	68.2931
941.704	68.9042
945.038	67.4518
948.372	66.8529
951.705	67.1097
955.035	64.8692
958.366	64.9876
961.693	60.8753
965.021	60.4054
968.346	63.1291
971.67	68.0023
974.995	66.6655
978.316	66.4791
981.638	66.6208
984.957	63.0707
988.274	59.0174
991.59	54.6398
994.907	47.0928
998.221	39.9911
1001.53	29.9985
1004.85	24.8946
1008.16	33.974
1011.46	59.9211
1014.77	96.4113
1018.08	137.173
1021.38	178.713
1024.69	219.385
1027.99	256.334
1031.29	289.054
1034.59	315.152
1037.89	334.163
1041.19	347.858
1044.48	355.793
1047.78	357.385
1051.07	349.024
1054.36	334.131
1057.66	313.275
1060.94	287.2
1064.23	252.367
1067.52	211.246
1070.81	166.788
1074.09	122.681
1077.38	79.6461
1080.66	41.2291
1083.94	13.8171
1087.22	4.57778
1090.5	9.00072
1093.77	19.1222
1097.05	23.4194
1100.32	29.8637
1103.6	31.8676
1106.87	35.603
1110.14	35.5551
1113.41	34.5276
1116.67	34.0038
1119.94	35.0953
1123.21	35.8923
1126.47	34.3549
1129.73	33.7717
1133	31.7199
1136.26	30.0368
1139.52	29.614
1142.77	27.8271
1146.03	25.7376
1149.29	22.5366
1152.54	20.9827
1155.79	19.1725
1159.04	16.4759
1162.3	13.7114
1165.55	11.9436
1168.79	10.2116
1172.04	9.70464
1175.28	8.66853
1178.53	8.4884
1181.77	8.11514
1185.01	8.25529
1188.25	7.99227
1191.49	9.63948
1194.73	9.3017
1197.97	11.9911
1201.2	13.8497
1204.44	16.4606
1207.67	21.8885
1210.9	25.0195
1214.13	28.3595
1217.36	33.5576
1220.59	36.231
1223.82	40.3429
1227.04	44.1277
1230.26	48.3477
1233.49	56.0544
1236.71	61.3269
1239.93	66.2927
1243.15	69.7644
1246.37	73.4556
1249.58	77.1815
1252.8	81.2138
1256.01	86.3274
1259.23	88.3024
1262.44	91.2311
1265.65	94.1537
1268.86	97.6963
1272.07	100.532
1275.27	103.553
1278.48	107.688
1281.68	111.676
1284.89	115.203
1288.09	116.565
1291.29	117.347
1294.49	118.826
1297.69	121.537
1300.88	122.186
1304.08	123.366
1307.27	124.711
1310.47	127.164
1313.66	126.49
1316.85	125.019
1320.04	123.397
1323.23	120.878
1326.41	117.401
1329.6	114.38
1332.78	112.781
1335.97	110.127
1339.15	107.258
1342.33	105.917
1345.51	102.765
1348.69	100.021
1351.87	97.1089
1355.04	94.2966
1358.22	90.9019
1361.39	86.2184
1364.57	81.6962
1367.74	76.7538
1370.91	74.5641
1374.07	71.569
1377.24	68.2063
1380.41	66.5398
1383.57	63.5015
1386.74	63.1399
1389.9	62.7363
1393.06	62.2742
1396.22	64.7499
1399.38	67.7369
1402.54	72.1563
1405.7	78.0779
1408.85	85.6029
1412.01	91.7496
1415.16	99.4499
1418.31	105.495
1421.46	114.467
1424.61	124.376
1427.76	133.279
1430.91	142.588
1434.05	153.203
1437.2	159.408
1440.34	164.31
1443.49	167.903
1446.63	168.587
1449.77	168.492
1452.91	166.788
1456.04	163.397
1459.18	156.972
1462.31	150.156
1465.45	142.763
1468.58	135.146
1471.71	127.674
1474.84	119.562
1477.97	110.098
1481.1	99.1569
1484.23	89.5233
1487.35	79.6446
1490.48	70.9474
1493.6	64.737
1496.72	57.9718
1499.84	56.5529
1502.96	52.2307
1506.08	49.5783
1509.2	48.6032
1512.31	47.9191
1515.43	45.5581
1518.54	45.8377
1521.66	45.2134
1524.77	45.5609
1527.88	45.7981
1530.99	45.6145
1534.09	47.2564
1537.2	47.4627
1540.31	49.6229
1543.41	50.8595
1546.51	53.1991
1549.62	55.1352
1552.72	55.7523
1555.82	56.9333
1558.91	59.977
1562.01	61.4612
1565.11	64.5754
1568.2	66.6865
1571.3	71.5787
1574.39	76.5721
1577.48	78.0976
1580.57	81.5698
1583.66	86.435
1586.75	91.1936
1589.83	94.1057
1592.92	96.8725
1596	100.129
1599.09	100.863
1602.17	102.176
1605.25	101.317
1608.33	102.672
1611.41	101.675
1614.48	100.981
1617.56	101.318
1620.64	101.902
1623.71	104.467
1626.78	105.489
1629.86	107.617
1632.92	110.728
1635.99	113.459
1639.06	114.889
1642.13	118.93
1645.19	120.885
1648.26	122.488
1651.32	122.962
1654.38	124.904
1657.45	127.006
1660.51	126.783
1663.57	125.015
1666.62	122.683
1669.68	118.292
1672.73	112.069
1675.79	104.197
1678.84	96.8252
1681.89	87.8052
1684.94	77.5862
1687.99	69.2852
1691.04	60.6998
1694.09	52.101
1697.14	45.0823
1700.18	37.1053
1703.22	31.7142
1706.27	26.4246
1709.31	19.821
1712.35	14.9738
1715.39	11.9314
1718.43	8.55891
1721.46	5.87604
1724.5	5.90538
1727.53	5.34105
1730.57	5.1155
1733.6	6.07098
1736.63	6.21145
1739.66	5.85704
1742.69	4.90716
1745.72	4.70516
1748.74	5.65079
1751.77	5.25383
1754.8	4.59122
1757.82	3.41728
1760.84	3.56882
1763.86	4.29274
1766.88	3.21999
1769.9	3.96516
1772.92	4.38822
1775.93	4.18402
1778.95	3.88695
1781.96	3.13564
1784.98	3.68259
1787.99	4.895
1791	3.99492
1794.01	4.58191
1797.02	3.5326
1800.03	3.33752
1803.03	3.77981
1806.04	2.43719
1809.04	2.32483
1812.04	1.60644
1815.05	1.291
1818.05	1.36275
1821.05	1.55007
1824.05	0.619194
1827.04	-0.0887538
1830.04	-0.440814
1833.03	-0.728382
1836.03	-1.24591
1839.02	-1.43653
1842.01	-1.71597
1845	-0.817234
1847.99	-0.817306
1850.98	-1.45714
1853.97	-1.4467
1856.95	0.409232
1859.94	1.16807
1862.92	0.353816
1865.91	0.445438
1868.89	1.34482
1871.87	3.36861
1874.85	4.64484
1877.83	6.10809
1880.8	6.84439
1882.56	8.75426
1885.54	9.6555
1888.53	9.65158
1891.52	9.8786
1894.5	10.4156
1897.49	10.3466
1900.47	10.3896
1903.45	11.177
1906.43	11.0131
1909.41	12.323
1912.39	12.291
1915.37	13.0789
1918.35	12.9382
1921.32	12.5089
1924.3	14.355
1927.27	15.2579
1930.24	14.5236
1933.21	14.4164
1936.18	14.9725
1939.15	15.0064
1942.12	15.885
1945.09	16.0509
1948.05	16.0511
1951.02	15.985
1953.98	15.0217
1956.94	14.4121
1959.91	11.8633
1962.87	10.6211
1965.82	10.6208
1968.78	10.1007
1971.74	10.427
1974.7	10.136
1977.65	11.6357
1980.6	12.2541
1983.56	12.0765
1986.51	12.9181
1989.46	15.2633
1992.41	15.7775
1995.36	16.468
1998.3	14.9497
2001.25	13.6687
2004.2	14.0489
2007.14	14.1357
2010.08	14.3165
2013.02	14.6731
2015.97	13.9625
2018.9	13.7898
2021.84	14.062
2024.78	14.4436
2027.72	14.8593
2030.65	14.0459
2033.59	14.105
2036.52	16.251
2039.45	17.7653
2042.38	18.7107
2045.31	21.0067
2048.24	22.0484
2051.17	23.572
2054.1	24.7575
2057.02	26.1226
2059.95	28.1197
2062.87	30.1297
2065.79	30.6953
2068.71	32.0299
2071.63	33.9006
2074.55	36.4369
2077.47	39.2336
2080.39	41.0893
2083.3	43.536
2086.22	45.8606
2089.13	47.8586
2092.05	50.3145
2094.96	54.8273
2097.87	57.5155
2100.78	58.2156
2103.69	60.6922
2106.59	64.8715
2109.5	67.5907
2112.41	70.15
2115.31	72.4588
2118.21	76.913
2121.12	81.7058
2124.02	86.1727
2126.92	89.6004
2129.82	94.7285
2132.71	100.37
2135.61	107.022
2138.51	111.646
2141.4	118.309
2144.29	124.795
2147.19	131.642
2150.08	136.721
2152.97	142.261
2155.86	148.322
2158.75	151.746
2161.64	156.268
2164.52	160.916
2167.41	163.632
2170.29	165.535
2173.17	164.674
2176.06	164.793
2178.94	163.927
2181.82	161.707
2184.7	159.926
2187.57	156.884
2190.45	154.574
2193.33	150.665
2196.2	144.936
2199.08	141.13
2201.95	136.575
2204.82	131.393
2207.69	126.875
2210.56	120.432
2213.43	117.499
2216.3	112.926
2219.16	108.408
2222.03	105.277
2224.89	100.859
2227.75	97.1194
2230.62	93.9936
2233.48	90.4818
2236.34	86.5193
2239.2	81.5901
2242.06	75.8866
2244.91	71.1368
2247.77	66.905
2250.62	61.0024
2253.48	54.8885
2256.33	49.8629
2259.18	45.7542
2262.03	42.9509
2264.88	39.2496
2267.73	36.4213
2270.58	33.4995
2273.43	31.972
2276.27	30.7106
2279.12	28.4395
2281.96	27.3694
2284.8	26.9542
2287.64	26.4118
2290.49	25.9828
2293.32	25.3916
2296.16	24.8604
2299	27.3969
2301.84	27.6527
2304.67	27.7994
2307.51	27.9337
2310.34	27.0448
2313.17	26.7174
2316	25.8135
2318.83	22.9993
2321.66	21.6341
2324.49	19.4239
2327.32	20.0696
2330.15	21.1027
2332.97	21.0491
2335.79	18.494
2338.62	18.5147
2341.44	16.0337
2344.26	13.4777
2347.08	12.6872
2349.9	9.80887
2352.72	8.29852
2355.53	7.68158
2358.35	7.80825
2361.17	6.75871
2363.98	5.73079
2366.79	7.37337
2369.6	6.58713
2372.42	5.8517
2375.22	6.25342
2378.03	6.58217
2380.84	6.14217
2383.65	6.62781
2386.45	7.3106
2389.26	8.45282
2392.06	8.98632
2394.87	10.8754
2397.67	10.5948
2400.47	10.2795
2403.27	9.09373
2406.07	8.23646
2408.86	7.21362
2411.66	6.52376
2414.46	8.3102
2417.25	9.43942
2420.05	9.46524
2422.84	11.5023
2425.63	10.6817
2428.42	10.6986
2431.21	9.75402
2434	10.247
2436.79	8.74716
2439.57	9.53782
2442.36	9.32764
2445.14	9.1613
2447.93	8.05304
2450.71	7.69799
2453.49	7.6194
2456.27	7.26759
2459.05	5.31642
2461.83	3.9987
2464.61	2.90939
2467.39	1.56179
2470.16	0.786881
2472.94	0.158213
2475.71	0.114089
2478.48	1.06554
2481.25	3.44503
2484.02	3.19964
2486.8	2.62773
2489.56	1.63346
2492.33	1.19762
2495.1	2.18842
2497.86	4.44982
2500.63	3.64491
2503.39	4.02663
2506.16	6.02686
2508.92	5.42509
2511.68	5.02092
2514.44	5.17187
2517.2	5.47215
2519.95	6.66955
2522.71	7.95885
2525.47	7.26543
2528.22	6.37877
2530.98	7.04114
2533.73	6.60393
2536.48	6.98592
2539.23	7.85399
2541.98	8.49469
2544.73	8.62137
2547.48	7.97439
2550.23	8.31277
2552.97	6.0767
2555.72	6.03177
2558.46	5.57824
2561.2	6.9336
2563.95	5.52301
2566.69	4.63809
2569.43	4.53258
2572.17	3.52725
2574.91	2.59674
2577.64	2.48292
2580.38	2.51351
2583.11	1.1943
2585.85	1.48614
2588.58	0.710844
2591.31	-0.299868
2594.04	-1.90235
2596.78	-1.62095
2599.51	-1.20914
2602.23	-0.946534
2604.96	-0.529849
2607.69	-0.796965
2610.41	-1.35503
2613.14	0.161279
2615.86	0.775322
2618.58	1.46934
2621.3	0.959319
2624.03	2.23486
2626.75	2.56871
2629.46	3.54761
2632.18	3.89175
2634.9	5.62665
2637.61	7.32696
2640.33	7.835
2643.04	8.5244
2645.76	10.0569
2648.47	9.491
2651.18	9.6722
2653.89	10.1586
2656.6	9.32573
2659.31	8.83379
2662.01	8.81022
2664.72	8.64235
2667.43	7.53018
2670.13	7.3172
2672.83	7.98901
2675.53	7.6058
2678.24	6.73285
2680.94	6.57228
2683.64	6.76373
2686.34	6.13797
2689.03	5.84142
2691.73	7.04599
2694.43	6.56095
2697.12	6.82707
2699.81	9.00272
2702.51	8.89883
2705.2	9.6695
2707.89	7.7665
2710.58	8.70327
2713.27	9.10117
2715.96	9.36157
2718.64	10.32
2721.33	10.7128
2724.01	11.7716
2726.7	13.3868
2729.38	13.7152
2732.06	14.0692
2734.75	14.8298
2737.43	14.8475
2740.11	14.1946
2742.78	12.4788
2745.46	12.5687
2748.14	12.1212
2750.81	11.6981
2753.49	9.78194
2756.16	8.92297
2758.84	7.15347
2761.51	6.32967
2764.18	5.08148
2766.85	3.78882
2769.52	2.22914
2772.19	-0.32015
2774.85	0.145053
2777.52	0.625107
2780.18	-0.426023
2782.85	-0.10592
2785.51	-1.04874
2788.17	-0.809242
2790.84	-0.393978
2793.5	-0.27929
2796.16	0.845514
2798.81	1.36499
2801.47	2.00018
2804.13	3.51511
2806.79	4.21183
2809.44	3.32384
2812.09	4.71353
2814.75	6.3472
2817.4	9.48195
2820.05	15.4259
2822.7	21.209
2825.35	30.267
2828	40.0472
2830.65	47.9448
2833.29	57.8454
2835.94	67.387
2838.58	77.3078
2841.23	87.5061
2843.87	95.9643
2846.51	107.159
2849.15	118.857
2851.79	131.891
2854.43	146.872
2857.07	161.433
2859.71	175.187
2862.34	189.264
2864.98	200.909
2867.61	210.363
2870.25	216.569
2872.88	223.414
2875.51	229.047
2878.14	235.565
2880.77	242.652
2883.4	249.106
2886.03	256.675
2888.65	261.829
2891.28	269.088
2893.91	274.798
2896.53	281.171
2899.15	288.835
2901.78	296.961
2904.4	304.67
2907.02	316.565
2909.64	330.86
2912.26	347.448
2914.87	365.051
2917.49	382.729
2920.11	399.963
2922.72	414.198
2925.34	426.748
2927.95	436.098
2930.56	439.826
2933.17	442.649
2935.78	443.825
2938.39	442.066
2941	436.154
2943.61	428.487
2946.22	417.196
2948.82	404.685
2951.43	390.521
2954.03	372.967
2956.64	354.903
2959.24	338.014
2961.84	318.745
2964.44	300.397
2967.04	282.884
2969.64	266.862
2972.24	252.442
2974.83	236.627
2977.43	221.942
2980.02	208.201
2982.62	192.984
2985.21	179.085
2987.8	163.737
2990.4	149.417
2992.99	136.449
2995.57	124.4
2998.16	112.973
3000.75	102.27
3003.34	92.4572
3005.92	82.2047
3008.51	72.4184
3011.09	64.8203
3013.68	56.3298
3016.26	50.2198
3018.84	42.8636
3021.42	37.7258
3024	33.0027
3026.58	30.0143
3029.16	26.3636
3031.73	25.2447
3034.31	23.2936
3036.89	23.3001
3039.46	23.5496
3042.03	24.6669
3044.61	24.4402
3047.18	24.4229
3049.75	25.1378
3052.32	25.7665
3054.89	26.9028
3057.45	27.7581
3060.02	27.6034
3062.59	27.3438
3065.15	27.0333
3067.72	25.9498
3070.28	24.465
3072.84	23.4385
3075.41	20.8543
3077.97	17.8602
3080.53	14.8861
3083.09	11.2025
3085.64	8.31977
3088.2	6.85097
3090.76	4.23055
3093.31	2.13842
3095.87	1.23975
3098.42	1.17087
3100.97	1.08009
3103.53	1.22689
3106.08	0.15738
3108.63	-0.401519
3111.18	0.620416
3113.73	1.41372
3116.27	1.98161
3118.82	3.46949
3121.37	3.66551
3123.91	4.55659
3126.45	4.92803
3129	4.53756
3131.54	5.50383
3134.08	6.28654
3136.62	5.90341
3139.16	5.99382
3141.7	6.00258
3144.24	5.76383
3146.78	6.06221
3149.31	6.60212