File: data/Raman/poly_smoothed/Mb_40_24_30_1x_45s_532 nm_x100_100%_600 gr_mm_01.txt
#Acq. time (s)=	45
#Accumulations=	2
#Range (cm-¹)=	200...3150
#Windows=	2
#Auto scanning=	Off
#Autofocus=	Off
#Macrospot=	Off
#AutoExposure=	Off
#Spike filter=	Multiple accum.
#Delay time (s)=	0
#Binning=	1
#Readout mode=	Signal
#DeNoise=	Off
#ICS correction=	On
#Dark correction=	Off
#Inst. Process=	Off
#Detector Gain=	Best Dynamic Range
#Detector ADC=	20 kHz
#Detector temperature (°C)=	-70.08
#Instrument=	LabRAM HR Evol
#Detector=	Synapse
#Objective=	x100
#Grating=	600 gr/mm
#ND Filter=	100%
#Laser (nm)=	532
#Hole=	100.021
#Range=	Auto
#Laser Pol.=	No
#Raman. Pol.=	No
#Laser Pol. (°)=	-0.0007625
#Raman Pol. (°)=	89.9995
#Collection=	Microscope
#StageXY=	Marzhauser
#StageZ=	Marzhauser
#X (µm)=	-2454.8
#Y (µm)=	-111.7
#Z (µm)=	-10.1
#Full time(mm:ss)=	3:19
#Project=
#Sample=
#Site=
#Title=	Mb_40_24_30_2x_45s_532 nm_x100_100%_600 gr_mm
#Remark=
#Date=	14.07.2022 12:54
#Acquired=	14.07.2022 12:54:42
#Edit:Spike=	10.08.2022 10:43:18
#Edit:Spike=	10.08.2022 10:43:20
#Edit:Spike=	10.08.2022 10:43:21
#Base:Fit=	10.08.2022 10:47:00
#Base:Sub=	10.08.2022 10:47:12
#Filter:Polynom=	16.08.2022 10:11:48
#AxisType[0]=Intens
#AxisUnit[0]=Cnt
#AxisType[1]=Spectr
#AxisUnit[1]=1/cm
200.554	-4.40645
204.183	4.96622
207.813	9.58726
211.439	13.2499
215.065	16.6407
218.688	18.6375
222.312	19.8151
225.933	20.0097
229.552	20.0909
233.171	19.7106
236.787	19.9748
240.402	20.1665
244.015	20.4497
247.627	18.5955
251.24	14.6745
254.849	13.935
258.457	12.3807
262.063	11.1348
265.668	9.53471
269.271	8.57633
272.873	9.1766
276.474	10.0954
280.073	11.8371
283.671	11.3608
287.268	9.20427
290.863	10.2929
294.456	9.25376
298.049	9.83313
301.637	7.1428
305.227	6.71852
308.815	10.3376
312.402	12.3595
315.987	15.3567
319.569	17.9695
323.151	20.927
326.733	22.2461
330.31	22.4131
333.889	21.2617
337.464	20.1132
341.039	20.4159
344.611	20.1993
348.184	20.3987
351.754	19.0742
355.324	18.6079
358.89	19.013
362.455	18.577
366.021	16.9562
369.584	14.4831
373.145	12.0441
376.707	8.64959
380.265	7.83329
383.822	6.42976
387.378	4.71563
390.934	3.7371
394.487	7.48753
398.038	8.55461
401.588	8.30606
405.137	10.3378
408.685	10.8522
412.23	9.00852
415.775	7.13101
419.318	7.13639
422.86	6.88129
426.401	7.14065
429.94	6.65937
433.478	6.38723
437.012	5.64278
440.547	4.84684
444.081	4.7029
447.613	2.97928
451.142	3.12686
454.672	3.55547
458.2	3.54257
461.725	4.95869
465.251	5.95786
468.775	7.80531
472.296	7.91184
475.817	9.02525
479.335	12.0538
482.854	14.4333
486.37	17.4743
489.886	21.0587
493.398	24.7918
496.91	25.44
500.422	26.823
503.93	30.3657
507.438	31.4131
510.946	31.3091
514.45	32.6578
517.954	30.7813
521.456	30.9809
524.956	30.5041
528.456	28.7336
531.956	28.0104
535.452	27.4127
538.947	26.2647
542.441	23.3312
545.934	21.6085
549.425	20.6552
552.915	19.4677
556.403	16.9378
559.889	15.9468
563.375	15.313
566.859	14.3561
570.342	12.7499
573.824	10.9965
577.303	9.22122
580.782	7.16582
584.26	7.64821
587.734	7.89591
591.21	6.48733
594.684	4.66635
598.154	5.63987
601.626	7.93448
605.094	7.6246
608.562	9.10423
612.027	10.2874
615.493	10.1183
618.956	12.4546
622.419	12.5968
625.879	15.2619
629.338	16.7976
632.797	17.3456
636.254	17.2383
639.708	18.9965
643.162	19.41
646.614	18.2786
650.067	17.3804
653.516	17.4942
656.964	15.1531
660.411	13.092
663.857	13.5654
667.301	14.117
670.744	16.341
674.186	15.5275
677.626	15.525
681.065	18.8773
684.503	21.9409
687.939	23.8231
691.372	25.8237
694.806	27.205
698.239	28.9663
701.67	30.8894
705.098	34.3004
708.526	37.8032
711.954	40.4373
715.378	40.1471
718.802	41.2061
722.226	43.6623
725.646	42.9052
729.067	41.2658
732.484	41.8723
735.902	41.9645
739.317	41.4375
742.731	40.3873
746.145	42.1113
749.556	43.7712
752.966	44.6962
756.377	45.2897
759.784	46.0574
763.19	48.6512
766.594	51.391
770	54.0325
773.402	55.7656
776.803	57.7145
780.202	58.8554
783.6	61.2011
786.997	64.9396
790.393	67.2361
793.787	69.2653
797.18	69.6222
800.572	69.3953
803.963	69.1972
807.35	68.96
810.738	69.4956
814.125	68.6261
817.51	69.1718
820.894	69.908
824.275	69.9618
827.657	68.8053
831.037	68.975
834.414	67.868
837.792	67.0361
841.167	67.0885
844.542	67.9464
847.914	67.9694
851.287	65.4355
854.656	61.8325
858.026	62.2753
861.393	59.9554
864.761	58.529
868.125	57.787
871.489	58.0565
874.85	55.5792
878.213	53.9057
881.572	51.9879
884.931	51.3854
888.287	51.4437
891.643	51.0568
894.997	48.532
898.352	48.1157
901.704	47.6719
905.055	47.252
908.404	46.6336
911.75	47.6257
915.097	48.5189
918.443	49.1397
921.787	48.699
925.13	48.6535
928.472	47.5957
931.813	43.9277
935.15	40.1806
938.488	39.6679
941.825	37.3382
945.158	34.5027
948.493	32.3627
951.824	32.235
955.156	32.5977
958.486	31.4473
961.814	30.1575
965.142	31.8761
968.467	31.9454
971.79	32.2044
975.115	33.9521
978.436	34.748
981.756	36.5084
985.077	37.6837
988.394	38.835
991.71	40.8426
995.025	42.2975
998.341	43.2773
1001.65	42.2567
1004.97	42.6586
1008.28	41.8071
1011.58	42.1879
1014.89	42.1541
1018.2	42.8971
1021.5	44.3504
1024.81	45.4683
1028.11	46.1365
1031.41	48.183
1034.71	50.6511
1038.01	50.3395
1041.31	49.7328
1044.6	52.5717
1047.9	53.1196
1051.19	49.6394
1054.48	49.2633
1057.77	48.3987
1061.06	45.9541
1064.35	44.0885
1067.64	42.066
1070.93	40.3754
1074.21	37.5069
1077.49	35.9362
1080.78	31.9978
1084.06	30.7063
1087.34	30.7845
1090.61	29.2835
1093.89	28.5013
1097.17	28.2547
1100.44	26.2934
1103.71	27.2896
1106.99	26.6395
1110.26	26.2625
1113.52	26.4723
1116.79	26.1048
1120.06	26.6858
1123.32	26.2449
1126.59	24.1868
1129.85	22.9826
1133.11	22.5397
1136.37	22.1766
1139.63	20.0692
1142.89	19.4187
1146.15	17.1643
1149.4	14.7381
1152.66	12.5444
1155.91	10.0144
1159.16	9.56578
1162.41	8.4753
1165.66	7.54647
1168.91	6.38617
1172.16	5.78322
1175.4	5.19974
1178.65	4.46046
1181.89	4.64798
1185.13	4.71771
1188.37	5.965
1191.61	8.133
1194.85	11.1725
1198.08	13.3289
1201.32	16.6383
1204.55	18.759
1207.79	22.2631
1211.02	27.0894
1214.25	29.8358
1217.48	31.7822
1220.71	36.0411
1223.93	40.2558
1227.16	43.292
1230.38	47.7827
1233.6	52.9412
1236.83	58.5742
1240.05	64.3602
1243.26	66.6435
1246.48	69.6485
1249.7	71.2865
1252.92	72.1352
1256.13	74.4022
1259.34	75.9602
1262.55	79.6133
1265.76	81.5789
1268.97	86.5492
1272.18	89.4393
1275.39	91.5056
1278.59	93.3337
1281.8	97.0559
1285	99.273
1288.2	101.792
1291.4	103.576
1294.6	105.08
1297.8	105.95
1301	107.287
1304.19	108.104
1307.39	108.494
1310.58	109.646
1313.77	110.602
1316.96	109.56
1320.15	107.595
1323.34	102.736
1326.53	98.0324
1329.72	95.1589
1332.9	94.199
1336.08	92.3066
1339.27	90.1401
1342.45	86.6176
1345.63	85.3931
1348.8	81.7475
1351.98	77.6171
1355.16	75.3325
1358.33	72.7025
1361.51	70.8447
1364.68	68.0938
1367.85	66.5892
1371.02	64.5343
1374.19	63.988
1377.36	63.2349
1380.52	63.5845
1383.69	63.9954
1386.85	64.8771
1390.02	64.3709
1393.18	64.496
1396.34	64.049
1399.5	63.3026
1402.65	64.6812
1405.81	67.9481
1408.97	72.126
1412.12	75.3797
1415.27	80.3553
1418.43	85.7179
1421.58	91.9365
1424.73	97.7189
1427.87	103.436
1431.02	111.777
1434.17	119.998
1437.31	126.383
1440.46	131.836
1443.6	138.134
1446.74	140.106
1449.88	142.083
1453.02	141.53
1456.16	141.445
1459.29	139.33
1462.43	134.717
1465.56	128.111
1468.69	119.59
1471.83	110.341
1474.95	101.518
1478.08	92.1187
1481.21	83.0526
1484.34	74.5774
1487.47	66.4565
1490.59	58.8522
1493.71	52.6018
1496.84	47.7056
1499.96	42.1319
1503.07	38.6283
1506.19	37.0946
1509.31	36.1451
1512.43	34.8757
1515.54	33.4138
1518.65	35.7751
1521.77	34.4041
1524.88	33.3946
1527.99	36.5633
1531.1	38.7849
1534.21	40.9453
1537.31	42.5039
1540.42	43.0372
1543.52	43.9301
1546.63	44.7813
1549.73	46.5623
1552.83	45.5263
1555.93	46.5778
1559.03	49.3176
1562.12	49.6292
1565.22	51.2411
1568.31	54.6809
1571.41	58.6799
1574.5	63.0782
1577.59	66.7164
1580.68	72.4688
1583.77	75.4714
1586.86	79.4213
1589.95	82.1163
1593.03	85.5859
1596.11	87.966
1599.2	89.8762
1602.28	92.5726
1605.36	93.6485
1608.44	93.6407
1611.52	94.8852
1614.6	97.3965
1617.67	97.641
1620.75	99.6237
1623.82	100.979
1626.89	101.429
1629.96	102.858
1633.04	106.23
1636.11	109.322
1639.17	111.973
1642.24	116.622
1645.31	120.225
1648.37	122.8
1651.43	122.16
1654.5	123.387
1657.56	120.762
1660.62	117.971
1663.67	115.41
1666.73	111.045
1669.79	107.07
1672.84	99.5444
1675.9	92.8059
1678.95	86.0036
1682	78.4401
1685.05	72.2525
1688.1	65.5517
1691.15	58.9133
1694.2	52.0768
1697.25	46.0681
1700.29	40.6823
1703.33	36.9482
1706.38	32.1409
1709.42	28.5069
1712.46	26.167
1715.5	23.6363
1718.54	20.4343
1721.57	17.3726
1724.61	14.9729
1727.64	13.2154
1730.68	13.5696
1733.71	13.0662
1736.74	12.9863
1739.77	13.7479
1742.8	12.3002
1745.83	11.4099
1748.85	11.9506
1751.88	11.2594
1754.91	10.6304
1757.93	10.0635
1760.95	9.18439
1763.97	7.6843
1766.99	6.92928
1770.01	5.68645
1773.03	5.07618
1776.04	3.68518
1779.06	2.71746
1782.07	0.926685
1785.09	1.74051
1788.1	1.2926
1791.11	0.84586
1794.12	0.162477
1797.13	-1.4176
1800.13	-1.26664
1803.14	-0.939287
1806.15	0.104981
1809.15	0.18553
1812.15	0.69604
1815.16	0.675954
1818.15	0.730465
1821.16	1.89569
1824.15	2.62864
1827.15	3.09607
1830.15	3.63964
1833.14	3.92029
1836.14	3.51779
1839.13	2.87068
1842.12	3.80022
1845.11	4.28416
1848.1	4.02264
1851.09	3.71311
1854.08	4.85204
1857.06	5.34551
1860.05	5.04422
1863.03	4.58469
1866.01	3.41401
1869	3.55678
1871.98	3.57061
1874.96	3.25265
1877.93	3.48971
1880.91	2.85918
1882.47	2.59138
1885.46	1.94887
1888.44	2.20772
1891.43	3.22986
1894.42	3.11864
1897.4	2.13364
1900.39	2.04026
1903.37	2.00251
1906.35	2.40426
1909.33	2.69128
1912.31	2.62214
1915.29	3.6767
1918.26	3.49933
1921.24	4.10122
1924.21	4.40712
1927.19	5.33643
1930.16	6.00109
1933.13	5.88724
1936.1	6.07955
1939.07	5.43081
1942.04	6.2427
1945	5.89102
1947.97	5.1025
1950.93	3.68361
1953.9	3.66577
1956.86	3.4561
1959.82	1.9157
1962.78	1.70926
1965.74	0.566468
1968.7	-0.335164
1971.65	-0.628181
1974.61	-0.242189
1977.57	-0.183258
1980.52	-0.567971
1983.47	-0.386504
1986.42	0.171597
1989.37	0.617329
1992.32	1.20309
1995.27	1.64948
1998.22	2.30004
2001.17	4.09237
2004.11	6.06271
2007.05	6.96919
2010	8.23245
2012.94	8.62489
2015.88	10.0149
2018.82	8.92014
2021.76	9.2806
2024.7	10.5964
2027.63	11.1255
2030.57	10.4969
2033.5	11.0231
2036.44	12.3982
2039.37	12.9423
2042.3	14.4631
2045.23	14.7316
2048.16	15.6772
2051.08	16.7903
2054.01	16.1737
2056.94	17.4418
2059.86	18.7064
2062.79	19.7716
2065.71	20.1221
2068.63	21.4695
2071.55	22.9259
2074.47	24.052
2077.39	26.3965
2080.31	27.3787
2083.22	27.6275
2086.13	28.8522
2089.05	31.504
2091.96	32.2698
2094.87	34.9741
2097.78	36.5177
2100.69	39.1616
2103.6	41.5644
2106.51	44.4003
2109.42	47.6373
2112.32	49.8187
2115.23	53.2011
2118.13	55.7292
2121.03	59.3762
2123.93	62.4115
2126.83	66.7176
2129.73	71.548
2132.63	75.5549
2135.53	79.1626
2138.42	83.8963
2141.32	88.6072
2144.21	92.6189
2147.1	97.9346
2150	102.203
2152.89	104.955
2155.78	108.562
2158.66	111.827
2161.55	114.506
2164.44	116.558
2167.32	118.574
2170.21	118.901
2173.09	118.615
2175.97	118.493
2178.85	117.487
2181.73	116.356
2184.61	115.162
2187.49	114.554
2190.37	112.163
2193.24	110.466
2196.12	107.962
2198.99	103.887
2201.87	99.3864
2204.74	94.7929
2207.61	90.2366
2210.48	84.7212
2213.35	79.1693
2216.21	75.84
2219.08	70.6432
2221.95	65.1336
2224.81	59.9802
2227.67	55.9157
2230.54	50.7518
2233.4	46.8808
2236.26	43.6016
2239.11	39.1312
2241.97	36.5935
2244.83	34.2594
2247.69	32.4784
2250.54	32.2177
2253.4	32.5234
2256.25	31.8415
2259.1	31.1288
2261.95	29.2877
2264.8	28.4371
2267.65	27.2024
2270.5	25.0655
2273.34	24.5923
2276.19	23.5816
2279.03	22.4836
2281.88	21.3474
2284.72	20.6241
2287.56	19.452
2290.4	16.6313
2293.24	14.8414
2296.08	13.1375
2298.92	13.0921
2301.76	12.6925
2304.59	13.0863
2307.43	13.2056
2310.26	12.7668
2313.09	12.8164
2315.92	12.7559
2318.75	13.7022
2321.58	12.908
2324.41	11.1206
2327.24	10.0612
2330.06	9.92218
2332.89	10.7488
2335.71	12.1989
2338.54	11.0738
2341.36	10.9469
2344.18	10.5302
2347	9.75006
2349.82	8.48454
2352.64	7.5529
2355.45	6.47269
2358.27	5.88894
2361.08	5.56699
2363.9	6.10943
2366.71	6.83994
2369.52	6.47924
2372.33	6.46594
2375.14	5.90184
2377.95	4.6405
2380.76	3.30652
2383.57	4.34035
2386.37	4.50634
2389.18	3.60163
2391.98	3.65719
2394.79	4.23957
2397.59	4.65796
2400.39	5.8898
2403.19	7.42023
2405.99	7.2791
2408.78	7.45358
2411.58	8.22752
2414.38	8.11703
2417.17	8.50169
2419.97	9.14861
2422.76	10.5195
2425.55	11.2016
2428.34	12.2492
2431.13	12.9527
2433.92	13.0631
2436.71	13.4166
2439.49	12.569
2442.28	12.7508
2445.06	11.3866
2447.85	11.2102
2450.63	11.0715
2453.41	10.5962
2456.19	9.15419
2458.97	7.01314
2461.75	5.58579
2464.53	5.7107
2467.31	4.47969
2470.08	4.0415
2472.86	3.02872
2475.63	2.79861
2478.4	3.18746
2481.17	2.03683
2483.94	1.59832
2486.72	1.53754
2489.48	2.36206
2492.25	1.42024
2495.02	2.10307
2497.79	2.28163
2500.55	2.77739
2503.31	2.6392
2506.08	3.16701
2508.84	3.14402
2511.6	2.84466
2514.36	2.89556
2517.12	2.26959
2519.88	1.85836
2522.63	1.61267
2525.39	2.26631
2528.14	2.82079
2530.9	2.84506
2533.65	4.49896
2536.4	5.27617
2539.15	5.91508
2541.9	6.11673
2544.65	6.43658
2547.4	6.56385
2550.15	6.7015
2552.89	5.92342
2555.64	5.52144
2558.38	4.85153
2561.12	4.09107
2563.87	3.51078
2566.61	2.8618
2569.35	2.49129
2572.09	1.62877
2574.83	1.21298
2577.56	0.778589
2580.3	-0.0232354
2583.04	0.166472
2585.77	1.16178
2588.5	2.50344
2591.23	2.81786
2593.97	3.67238
2596.7	3.67983
2599.43	3.97282
2602.15	5.71441
2604.88	5.78818
2607.61	4.91359
2610.33	4.68058
2613.06	5.86253
2615.78	7.54526
2618.51	7.83388
2621.23	7.99157
2623.95	8.14243
2626.67	8.24883
2629.39	7.94161
2632.1	7.30917
2634.82	7.07278
2637.54	7.81428
2640.25	7.33111
2642.97	7.6906
2645.68	8.54061
2648.39	9.09154
2651.1	8.85452
2653.81	9.60682
2656.52	9.36911
2659.23	8.07285
2661.94	7.4758
2664.64	7.70446
2667.35	6.6037
2670.05	6.63655
2672.76	5.01966
2675.46	4.67765
2678.16	5.25119
2680.86	5.75122
2683.56	6.16083
2686.26	5.97883
2688.96	5.97587
2691.65	5.04547
2694.35	4.75754
2697.04	4.41968
2699.74	5.28408
2702.43	6.65945
2705.12	7.15399
2707.81	9.03945
2710.5	10.0048
2713.19	10.9769
2715.88	10.9289
2718.57	11.3057
2721.25	12.0581
2723.94	12.046
2726.62	12.9637
2729.3	12.3855
2731.99	12.0045
2734.67	12.4669
2737.35	12.3983
2740.03	12.4605
2742.71	11.107
2745.38	10.2113
2748.06	8.75961
2750.74	8.51575
2753.41	6.89364
2756.09	6.27959
2758.76	4.1479
2761.43	3.85506
2764.1	3.24881
2766.77	1.93
2769.44	1.31227
2772.11	1.05935
2774.77	1.27124
2777.44	0.143731
2780.11	0.187155
2782.77	1.19728
2785.43	1.42797
2788.1	1.21707
2790.76	1.49469
2793.42	1.43084
2796.08	2.47759
2798.74	2.59665
2801.4	3.54858
2804.05	2.80885
2806.71	2.30956
2809.36	2.36503
2812.02	1.31174
2814.67	2.36018
2817.32	4.55068
2819.97	5.45766
2822.62	8.21812
2825.27	11.3583
2827.92	15.5971
2830.57	19.7296
2833.22	25.315
2835.86	32.5335
2838.51	40.9676
2841.15	49.9201
2843.79	59.0069
2846.43	69.6049
2849.08	79.9525
2851.72	90.703
2854.36	101.585
2856.99	112.514
2859.63	123.79
2862.27	134.611
2864.9	143.164
2867.54	152.762
2870.17	160.643
2872.8	168.035
2875.43	174.661
2878.07	182.554
2880.7	189.37
2883.32	195.683
2885.95	203.642
2888.58	210.693
2891.21	217.876
2893.83	226.253
2896.46	235.193
2899.08	246.17
2901.7	257.951
2904.32	271.856
2906.94	285.96
2909.56	301.097
2912.18	316.631
2914.8	333.065
2917.42	348.365
2920.03	361.79
2922.65	372.666
2925.26	380.792
2927.88	386.125
2930.49	388.245
2933.1	389.057
2935.71	385.517
2938.32	379.727
2940.93	371.515
2943.54	359.63
2946.14	346.838
2948.75	334.124
2951.35	318.635
2953.96	300.937
2956.56	283.557
2959.16	268.302
2961.77	251.981
2964.37	236.782
2966.96	222.921
2969.56	209.118
2972.16	195.758
2974.76	182.951
2977.35	171.88
2979.95	159.718
2982.54	146.833
2985.14	133.437
2987.73	120.649
2990.32	108.937
2992.91	99.0694
2995.5	88.2471
2998.09	76.8008
3000.68	67.1517
3003.26	57.1743
3005.85	48.8195
3008.43	40.9062
3011.02	33.2546
3013.6	27.1003
3016.19	20.6044
3018.77	15.6861
3021.35	11.9889
3023.93	9.30736
3026.5	6.44543
3029.08	5.50747
3031.66	3.00075
3034.24	1.35799
3036.81	2.13934
3039.39	2.33597
3041.96	2.87411
3044.53	2.82089
3047.1	4.15861
3049.67	5.46223
3052.24	7.04094
3054.81	9.16531
3057.38	9.80955
3059.95	9.66346
3062.52	10.4031
3065.08	9.72995
3067.65	9.08906
3070.21	7.53602
3072.77	6.65473
3075.33	6.17924
3077.89	6.2911
3080.45	6.72666
3083.01	6.42311
3085.57	6.58979
3088.13	6.962
3090.68	8.55496
3093.24	9.94189
3095.79	10.8259
3098.35	12.7815
3100.9	13.4359
3103.45	15.4675
3106	17.1438
3108.55	19.3959
3111.1	21.125
3113.65	23.3362
3116.2	24.7117
3118.75	26.4988
3121.29	27.6489
3123.84	29.298
3126.38	30.3236
3128.92	31.4999
3131.47	33.0817
3134.01	35.4613
3136.55	39.0994
3139.09	43.3873
3141.63	47.0069
3144.17	51.1828
3146.7	56.2572
3149.24	60.7819