File: data/Raman/poly_smoothed/Mb_40_y_38_1x_45s_532 nm_x100_100%_600 gr_mm_02.txt
#Acq. time (s)=	45
#Accumulations=	2
#Range (cm-¹)=	200...3150
#Windows=	2
#Auto scanning=	Off
#Autofocus=	Off
#Macrospot=	Off
#AutoExposure=	Off
#Spike filter=	Multiple accum.
#Delay time (s)=	0
#Binning=	1
#Readout mode=	Signal
#DeNoise=	Off
#ICS correction=	On
#Dark correction=	Off
#Inst. Process=	Off
#Detector Gain=	Best Dynamic Range
#Detector ADC=	20 kHz
#Detector temperature (°C)=	-69.85
#Instrument=	LabRAM HR Evol
#Detector=	Synapse
#Objective=	x100
#Grating=	600 gr/mm
#ND Filter=	100%
#Laser (nm)=	532
#Hole=	100.021
#Range=	Auto
#Laser Pol.=	No
#Raman. Pol.=	No
#Laser Pol. (°)=	-0.0007625
#Raman Pol. (°)=	89.9995
#Collection=	Microscope
#StageXY=	Marzhauser
#StageZ=	Marzhauser
#X (µm)=	-1080.6
#Y (µm)=	595.5
#Z (µm)=	584.35
#Full time(mm:ss)=	3:18
#Project=
#Sample=
#Site=
#Title=	Mb_40_y_38_2x_45s_532 nm_x100_100%_600 gr_mm
#Remark=
#Date=	19.07.2022 12:34
#Acquired=	19.07.2022 12:34:10
#Base:Fit=	10.08.2022 10:52:48
#Base:Sub=	10.08.2022 10:52:53
#Filter:Polynom=	16.08.2022 10:09:04
#AxisType[0]=Intens
#AxisUnit[0]=Cnt
#AxisType[1]=Spectr
#AxisUnit[1]=1/cm
200.423	46.2892
204.052	38.1235
207.682	31.4472
211.308	25.3256
214.935	20.274
218.558	15.6768
222.18	11.9201
225.802	8.43888
229.421	6.77149
233.039	5.62227
236.657	3.66559
240.272	1.14748
243.885	1.23913
247.497	-0.468006
251.11	-2.06414
254.719	-0.590081
258.327	-0.142481
261.933	0.209605
265.538	2.5459
269.141	4.12129
272.744	5.30334
276.344	6.98545
279.944	7.43423
283.542	8.06585
287.138	10.0617
290.733	10.1736
294.327	10.9923
297.919	12.845
301.508	14.612
305.098	15.4784
308.686	16.8204
312.273	17.6715
315.858	18.4909
319.44	20.3439
323.022	19.4849
326.604	19.8567
330.181	20.9966
333.76	20.7806
337.335	21.0484
340.91	21.0875
344.483	21.7805
348.055	18.9256
351.625	19.7614
355.195	18.6822
358.762	17.5199
362.329	16.43
365.893	15.6025
369.455	15.0555
373.017	12.5337
376.578	12.0373
380.137	10.632
383.694	10.0361
387.249	9.06391
390.806	9.85433
394.359	10.7867
397.91	9.76825
401.46	9.69306
405.009	9.72601
408.557	9.5638
412.103	10.1795
415.647	10.6799
419.191	11.6809
422.733	10.2903
426.273	9.78377
429.812	8.21621
433.35	6.61743
436.885	5.5423
440.42	5.32292
443.954	4.88584
447.486	4.43365
451.015	5.24619
454.545	7.26798
458.073	7.31212
461.598	8.16859
465.124	10.3134
468.648	11.628
472.169	13.1575
475.69	15.8106
479.208	20.3706
482.727	22.3447
486.243	24.1685
489.759	25.8066
493.272	27.5463
496.783	28.8153
500.295	30.6461
503.804	32.4249
507.311	31.2323
510.819	30.413
514.324	29.6835
517.827	28.6777
521.329	27.9383
524.83	26.3818
528.329	25.5617
531.829	25.5481
535.326	24.8466
538.821	23.7692
542.315	22.0137
545.808	20.8547
549.299	19.7944
552.789	20.1813
556.278	20.6912
559.763	19.898
563.249	19.1127
566.733	17.947
570.217	16.9725
573.699	14.4912
577.177	14.0472
580.656	12.0703
584.134	11.3649
587.609	10.1419
591.084	9.82067
594.558	7.4749
598.029	8.13863
601.5	6.56862
604.968	5.5135
608.437	6.2936
611.902	6.92376
615.368	11.4075
618.831	11.1819
622.294	12.5412
625.755	10.8878
629.213	12.2826
632.673	13.7087
636.129	16.7339
639.584	17.0018
643.037	17.2878
646.491	14.5858
649.942	14.8044
653.392	14.7689
656.84	15.4094
660.287	15.5092
663.732	15.7484
667.177	15.682
670.62	15.9483
674.061	15.7985
677.502	14.6905
680.941	16.6174
684.379	19.5971
687.815	21.6101
691.248	26.3081
694.682	29.4016
698.115	32.6906
701.546	33.9692
704.974	36.1376
708.402	39.5299
711.83	41.811
715.254	45.1492
718.679	45.8984
722.102	45.0278
725.522	45.924
728.943	43.8969
732.361	43.378
735.779	44.7075
739.194	45.0802
742.608	45.1296
746.022	46.0313
749.433	46.9342
752.843	48.772
756.254	49.269
759.661	51.1931
763.067	52.1451
766.471	53.8046
769.877	56.8905
773.279	57.6484
776.68	57.3439
780.079	57.9245
783.478	60.8763
786.875	64.3903
790.27	66.3361
793.665	65.0688
797.058	65.2527
800.45	63.8393
803.84	63.5313
807.23	64.8353
810.616	62.8754
814.002	61.6045
817.388	61.7838
820.772	61.5087
824.153	61.2316
827.535	60.5802
830.915	59.5361
834.292	59.1325
837.67	58.2886
841.047	55.8554
844.42	53.3316
847.794	50.71
851.165	49.3715
854.534	47.6719
857.905	45.8838
861.272	45.877
864.639	44.7265
868.004	45.9956
871.367	45.5227
874.731	44.2663
878.092	43.3008
881.451	45.1667
884.809	46.9412
888.166	47.8715
891.522	47.5937
894.878	46.3518
898.231	44.2212
901.583	42.4635
904.934	41.3546
908.283	40.7459
911.631	40.7092
914.976	40.855
918.322	40.4431
921.666	37.1521
925.009	34.8646
928.351	34.5173
931.692	34.3244
935.029	32.4861
938.367	32.6416
941.704	33.1457
945.038	31.9194
948.372	30.5003
951.705	30.9952
955.035	30.5375
958.366	27.9311
961.693	27.9392
965.021	28.3944
968.346	27.662
971.67	27.7706
974.995	26.4695
978.316	27.8774
981.638	27.2156
984.957	30.2916
988.274	33.0306
991.59	32.3657
994.907	29.3335
998.221	24.4541
1001.53	16.2317
1004.85	13.9959
1008.16	17.2661
1011.46	34.4237
1014.77	60.0465
1018.08	90.7932
1021.38	122.325
1024.69	151.571
1027.99	177.146
1031.29	198.98
1034.59	217.089
1037.89	228.75
1041.19	237.531
1044.48	241.876
1047.78	241.328
1051.07	236.999
1054.36	228.308
1057.66	216.941
1060.94	200.157
1064.23	178.165
1067.52	153.216
1070.81	123.632
1074.09	91.2832
1077.38	60.3399
1080.66	32.9699
1083.94	11.1703
1087.22	2.19208
1090.5	3.33866
1093.77	11.8572
1097.05	19.1717
1100.32	23.9664
1103.6	27.518
1106.87	30.4162
1110.14	31.1658
1113.41	32.7069
1116.67	32.2849
1119.94	31.7294
1123.21	32.2151
1126.47	29.2626
1129.73	27.9266
1133	25.645
1136.26	24.7382
1139.52	23.4635
1142.77	21.7475
1146.03	21.5331
1149.29	18.5031
1152.54	16.9542
1155.79	14.8371
1159.04	11.7246
1162.3	8.20432
1165.55	5.49198
1168.79	4.9378
1172.04	5.06764
1175.28	4.86252
1178.53	5.02799
1181.77	4.4619
1185.01	5.57934
1188.25	5.73904
1191.49	4.95554
1194.73	4.85078
1197.97	4.26153
1201.2	5.89899
1204.44	6.10097
1207.67	7.24543
1210.9	9.87234
1214.13	13.1188
1217.36	16.097
1220.59	19.7469
1223.82	23.8342
1227.04	27.0027
1230.26	31.293
1233.49	35.993
1236.71	39.7388
1239.93	44.0004
1243.15	48.1594
1246.37	51.1963
1249.58	53.795
1252.8	56.1993
1256.01	58.4338
1259.23	60.4404
1262.44	63.7309
1265.65	64.5137
1268.86	64.8997
1272.07	66.4175
1275.27	67.1914
1278.48	71.5945
1281.68	74.1672
1284.89	75.5411
1288.09	77.1082
1291.29	78.7023
1294.49	79.2335
1297.69	79.7631
1300.88	80.8919
1304.08	82.2702
1307.27	82.2249
1310.47	83.744
1313.66	84.3148
1316.85	85.1581
1320.04	85.2592
1323.23	86.3415
1326.41	85.4737
1329.6	86.0169
1332.78	84.4867
1335.97	84.6612
1339.15	82.5731
1342.33	80.3178
1345.51	77.3307
1348.69	75.7803
1351.87	73.8351
1355.04	72.6586
1358.22	71.7473
1361.39	68.8436
1364.57	66.2381
1367.74	63.3493
1370.91	61.041
1374.07	57.9519
1377.24	55.8624
1380.41	53.7768
1383.57	53.4563
1386.74	52.6622
1389.9	54.112
1393.06	55.4216
1396.22	56.5558
1399.38	57.7338
1402.54	58.7964
1405.7	61.2902
1408.85	63.0142
1412.01	66.0459
1415.16	70.1788
1418.31	73.6219
1421.46	78.6192
1424.61	84.204
1427.76	92.4249
1430.91	98.1025
1434.05	103.745
1437.2	109.025
1440.34	114.373
1443.49	116.506
1446.63	117.556
1449.77	118.076
1452.91	116.958
1456.04	113.581
1459.18	110.633
1462.31	106.867
1465.45	101.375
1468.58	94.8077
1471.71	87.2635
1474.84	80.476
1477.97	74.5571
1481.1	66.6632
1484.23	59.6898
1487.35	53.518
1490.48	47.9396
1493.6	43.953
1496.72	40.7672
1499.84	39.2317
1502.96	38.089
1506.08	36.2761
1509.2	35.7217
1512.31	34.5116
1515.43	33.8621
1518.54	33.4143
1521.66	31.0207
1524.77	30.8804
1527.88	30.3681
1530.99	30.4668
1534.09	29.8356
1537.2	30.628
1540.31	31.6602
1543.41	33.4643
1546.51	34.8558
1549.62	37.4377
1552.72	40.1587
1555.82	39.9019
1558.91	41.5007
1562.01	43.559
1565.11	45.3488
1568.2	47.2019
1571.3	50.1829
1574.39	52.4229
1577.48	54.8809
1580.57	56.9542
1583.66	60.2612
1586.75	61.1464
1589.83	61.6257
1592.92	63.5087
1596	64.7811
1599.09	64.5898
1602.17	63.5651
1605.25	63.3721
1608.33	62.9307
1611.41	63.0924
1614.48	62.9335
1617.56	64.5301
1620.64	64.6633
1623.71	66.1874
1626.78	68.1246
1629.86	69.1007
1632.92	71.5167
1635.99	73.6645
1639.06	75.8129
1642.13	76.4526
1645.19	79.6273
1648.26	82.4203
1651.32	83.9264
1654.38	85.0498
1657.45	85.0489
1660.51	84.2172
1663.57	81.5364
1666.62	78.1448
1669.68	74.0693
1672.73	68.9291
1675.79	63.3143
1678.84	57.9724
1681.89	51.8729
1684.94	45.681
1687.99	39.397
1691.04	35.2578
1694.09	30.1341
1697.14	24.2871
1700.18	21.6288
1703.22	18.3729
1706.27	15.711
1709.31	12.9287
1712.35	10.6917
1715.39	8.4838
1718.43	7.52462
1721.46	7.9076
1724.5	7.77454
1727.53	6.85246
1730.57	6.74105
1733.6	6.87462
1736.63	5.76636
1739.66	5.00973
1742.69	4.22484
1745.72	4.86263
1748.74	3.86481
1751.77	3.71612
1754.8	2.84655
1757.82	2.42051
1760.84	1.08538
1763.86	0.996733
1766.88	0.439753
1769.9	0.0148581
1772.92	-0.0817593
1775.93	-0.743202
1778.95	-1.23833
1781.96	-0.827838
1784.98	-0.624675
1787.99	0.148569
1791	0.759268
1794.01	0.560021
1797.02	1.42729
1800.03	1.39955
1803.03	2.51236
1806.04	2.29971
1809.04	1.67386
1812.04	1.32941
1815.05	1.48971
1818.05	1.19023
1821.05	1.83633
1824.05	1.8704
1827.04	2.11706
1830.04	1.83356
1833.03	2.01522
1836.03	2.05213
1839.02	2.03906
1842.01	2.21589
1845	3.0759
1847.99	3.1878
1850.98	4.07506
1853.97	4.75327
1856.95	4.72375
1859.94	5.63932
1862.92	6.27535
1865.91	6.19494
1868.89	7.7085
1871.87	7.76066
1874.85	7.64989
1877.83	6.85219
1880.8	5.80108
1882.56	6.07557
1885.54	6.66285
1888.53	6.74518
1891.52	6.10828
1894.5	4.99673
1897.49	4.25385
1900.47	3.74787
1903.45	3.39775
1906.43	3.59016
1909.41	2.03998
1912.39	2.37595
1915.37	2.89297
1918.35	2.77093
1921.32	3.6566
1924.3	3.85342
1927.27	3.93877
1930.24	2.93891
1933.21	4.88704
1936.18	5.08221
1939.15	4.71075
1942.12	4.41993
1945.09	5.23827
1948.05	4.58086
1951.02	4.90765
1953.98	7.67925
1956.94	7.99883
1959.91	8.3425
1962.87	7.28677
1965.82	6.0621
1968.78	5.82959
1971.74	5.8333
1974.7	5.1295
1977.65	4.91864
1980.6	4.58747
1983.56	5.08032
1986.51	5.11355
1989.46	6.66961
1992.41	6.83394
1995.36	6.40454
1998.3	6.41176
2001.25	7.66308
2004.2	9.39908
2007.14	10.5059
2010.08	11.3326
2013.02	12.2849
2015.97	14.6709
2018.9	17.1545
2021.84	17.7471
2024.78	19.539
2027.72	20.2064
2030.65	19.9669
2033.59	21.3374
2036.52	19.5967
2039.45	20.4898
2042.38	20.695
2045.31	19.6935
2048.24	17.6695
2051.17	17.7978
2054.1	17.565
2057.02	17.1045
2059.95	18.4811
2062.87	18.0911
2065.79	17.0324
2068.71	17.5561
2071.63	18.4363
2074.55	20.3725
2077.47	21.5576
2080.39	22.938
2083.3	24.1027
2086.22	25.6472
2089.13	27.514
2092.05	28.7899
2094.96	30.4272
2097.87	33.0773
2100.78	35.8155
2103.69	38.5859
2106.59	39.8517
2109.5	41.4757
2112.41	43.7523
2115.31	45.2928
2118.21	47.5596
2121.12	49.9879
2124.02	53.4217
2126.92	57.0801
2129.82	61.2024
2132.71	64.6941
2135.61	68.6935
2138.51	73.2653
2141.4	78.1454
2144.29	82.3652
2147.19	87.0314
2150.08	88.5257
2152.97	91.3557
2155.86	93.9608
2158.75	95.6909
2161.64	98.153
2164.52	100.876
2167.41	102.305
2170.29	102.482
2173.17	102.844
2176.06	100.376
2178.94	98.6321
2181.82	96.7605
2184.7	93.9321
2187.57	90.5088
2190.45	88.5348
2193.33	85.829
2196.2	83.7462
2199.08	82.274
2201.95	80.1218
2204.82	78.6503
2207.69	77.0108
2210.56	74.5338
2213.43	72.3713
2216.3	68.4222
2219.16	65.7399
2222.03	64.0827
2224.89	62.2777
2227.75	59.2661
2230.62	57.8663
2233.48	56.6286
2236.34	54.7018
2239.2	50.8889
2242.06	46.7202
2244.91	43.6337
2247.77	40.5911
2250.62	37.9536
2253.48	35.021
2256.33	33.2331
2259.18	30.9509
2262.03	29.6532
2264.88	28.3559
2267.73	27.5626
2270.58	26.0988
2273.43	25.3264
2276.27	25.7202
2279.12	23.5594
2281.96	21.8475
2284.8	19.9758
2287.64	20.2693
2290.49	19.6152
2293.32	18.0104
2296.16	17.7198
2299	17.9905
2301.84	19.791
2304.67	18.8197
2307.51	17.1569
2310.34	17.2041
2313.17	17.7973
2316	17.922
2318.83	19.2263
2321.66	19.3064
2324.49	17.1514
2327.32	16.7634
2330.15	16.3235
2332.97	16.501
2335.79	16.056
2338.62	15.1522
2341.44	14.1761
2344.26	13.6398
2347.08	11.6679
2349.9	9.77252
2352.72	7.35153
2355.53	6.07527
2358.35	5.12454
2361.17	3.63003
2363.98	3.85298
2366.79	4.9204
2369.6	5.05122
2372.42	5.39289
2375.22	5.20783
2378.03	6.91022
2380.84	8.16835
2383.65	7.70242
2386.45	8.38233
2389.26	7.29322
2392.06	6.50935
2394.87	5.56748
2397.67	5.02361
2400.47	5.77858
2403.27	6.17913
2406.07	5.66945
2408.86	7.11886
2411.66	6.48641
2414.46	6.27845
2417.25	5.86453
2420.05	5.95933
2422.84	5.4452
2425.63	6.00304
2428.42	8.43725
2431.21	8.43908
2434	8.65812
2436.79	9.96829
2439.57	11.9193
2442.36	13.3036
2445.14	12.927
2447.93	13.1582
2450.71	12.2304
2453.49	11.5974
2456.27	11.6268
2459.05	10.3431
2461.83	10.2379
2464.61	8.73593
2467.39	8.84851
2470.16	8.92961
2472.94	8.34892
2475.71	8.51488
2478.48	7.52053
2481.25	6.65626
2484.02	6.87021
2486.8	7.69087
2489.56	8.39216
2492.33	7.82087
2495.1	7.55704
2497.86	6.85195
2500.63	6.36166
2503.39	6.25591
2506.16	6.30721
2508.92	4.357
2511.68	2.82316
2514.44	1.6112
2517.2	1.28033
2519.95	2.21628
2522.71	2.47539
2525.47	2.23552
2528.22	2.12394
2530.98	2.23863
2533.73	2.4061
2536.48	3.30629
2539.23	3.5383
2541.98	4.60238
2544.73	5.79737
2547.48	6.52995
2550.23	8.57018
2552.97	10.7173
2555.72	10.9202
2558.46	11.4029
2561.2	12.1314
2563.95	12.6257
2566.69	13.0214
2569.43	12.6333
2572.17	12.338
2574.91	11.2396
2577.64	10.3886
2580.38	9.5344
2583.11	9.33464
2585.85	8.88045
2588.58	7.63183
2591.31	6.00683
2594.04	4.81059
2596.78	4.24904
2599.51	3.7641
2602.23	3.78999
2604.96	3.22781
2607.69	2.79764
2610.41	2.06084
2613.14	3.07131
2615.86	3.88033
2618.58	3.98048
2621.3	3.96597
2624.03	3.85091
2626.75	4.94723
2629.46	5.09094
2632.18	5.01763
2634.9	4.76828
2637.61	5.01009
2640.33	4.89771
2643.04	5.54309
2645.76	5.86008
2648.47	5.53619
2651.18	5.5169
2653.89	4.70011
2656.6	4.72676
2659.31	4.50204
2662.01	5.09628
2664.72	4.68796
2667.43	4.99726
2670.13	4.12953
2672.83	4.34764
2675.53	4.95524
2678.24	5.08366
2680.94	5.58109
2683.64	5.81892
2686.34	5.72492
2689.03	5.54557
2691.73	6.72337
2694.43	7.14818
2697.12	7.59269
2699.81	9.14156
2702.51	10.1915
2705.2	10.6663
2707.89	11.9687
2710.58	13.4538
2713.27	13.6046
2715.96	13.757
2718.64	13.615
2721.33	12.9043
2724.01	12.7667
2726.7	12.6726
2729.38	11.1542
2732.06	10.3522
2734.75	9.26344
2737.43	8.09305
2740.11	7.29261
2742.78	5.82505
2745.46	4.88894
2748.14	3.82726
2750.81	3.04682
2753.49	2.43458
2756.16	2.76068
2758.84	2.64662
2761.51	1.69836
2764.18	1.28141
2766.85	1.1615
2769.52	1.16798
2772.19	1.87694
2774.85	2.16619
2777.52	2.28249
2780.18	1.72643
2782.85	1.71188
2785.51	0.577964
2788.17	0.63961
2790.84	0.489977
2793.5	-0.238446
2796.16	0.315084
2798.81	1.31989
2801.47	0.239422
2804.13	0.23392
2806.79	-0.106284
2809.44	-1.22242
2812.09	-0.682806
2814.75	0.975281
2817.4	3.19294
2820.05	6.84119
2822.7	9.84552
2825.35	13.708
2828	18.4419
2830.65	24.1948
2833.29	30.4438
2835.94	35.3058
2838.58	40.6888
2841.23	47.3118
2843.87	52.5123
2846.51	58.7311
2849.15	65.587
2851.79	71.9129
2854.43	79.2903
2857.07	86.7096
2859.71	93.1907
2862.34	100.4
2864.98	106.895
2867.61	111.775
2870.25	115.085
2872.88	118.691
2875.51	122.976
2878.14	128.8
2880.77	133.089
2883.4	137.08
2886.03	140.996
2888.65	144.503
2891.28	148.469
2893.91	151.983
2896.53	156.148
2899.15	160.145
2901.78	164.558
2904.4	171.053
2907.02	178.401
2909.64	186.545
2912.26	196.425
2914.87	206.411
2917.49	215.671
2920.11	225.049
2922.72	232.418
2925.34	238.47
2927.95	244.295
2930.56	248.427
2933.17	248.248
2935.78	248.076
2938.39	248.209
2941	245.318
2943.61	240.04
2946.22	233.275
2948.82	225.393
2951.43	217.591
2954.03	208.311
2956.64	197.808
2959.24	187.747
2961.84	177.04
2964.44	167.192
2967.04	157.71
2969.64	149.575
2972.24	141.089
2974.83	132.131
2977.43	123.679
2980.02	114.071
2982.62	104.551
2985.21	95.6661
2987.8	86.3622
2990.4	77.3353
2992.99	69.3612
2995.57	61.0359
2998.16	54.3199
3000.75	46.8223
3003.34	40.8485
3005.92	35.1069
3008.51	29.5276
3011.09	24.1813
3013.68	19.9161
3016.26	16.2303
3018.84	12.7624
3021.42	10.036
3024	7.80388
3026.58	6.71614
3029.16	5.29684
3031.73	3.68824
3034.31	3.90804
3036.89	3.35513
3039.46	3.4258
3042.03	3.28689
3044.61	3.8602
3047.18	5.42562
3049.75	5.4703
3052.32	5.06514
3054.89	5.38414
3057.45	6.23331
3060.02	6.24187
3062.59	6.68271
3065.15	7.21197
3067.72	7.30012
3070.28	6.85888
3072.84	5.89725
3075.41	4.73166
3077.97	4.07857
3080.53	2.93814
3083.09	2.50491
3085.64	1.60197
3088.2	1.08685
3090.76	0.541236
3093.31	0.361891
3095.87	0.46046
3098.42	0.549125
3100.97	0.600914
3103.53	0.820497
3106.08	0.430316
3108.63	1.16094
3111.18	0.0411219
3113.73	0.225343
3116.27	1.36457
3118.82	2.16576
3121.37	3.04625
3123.91	3.44586
3126.45	4.39316
3129	4.98807
3131.54	5.5564
3134.08	5.15442
3136.62	5.92784
3139.16	6.10191
3141.7	7.06561
3144.24	8.07625
3146.78	8.25471
3149.31	8.30488