File: data/Raman/poly_smoothed/Mb_40_y_42_1x_45s_532 nm_x100_100%_600 gr_mm_01.txt
#Acq. time (s)=	45
#Accumulations=	2
#Range (cm-¹)=	200...3150
#Windows=	2
#Auto scanning=	Off
#Autofocus=	Off
#Macrospot=	Off
#AutoExposure=	Off
#Spike filter=	Multiple accum.
#Delay time (s)=	0
#Binning=	1
#Readout mode=	Signal
#DeNoise=	Off
#ICS correction=	On
#Dark correction=	Off
#Inst. Process=	Off
#Detector Gain=	Best Dynamic Range
#Detector ADC=	20 kHz
#Detector temperature (°C)=	-69.85
#Instrument=	LabRAM HR Evol
#Detector=	Synapse
#Objective=	x100
#Grating=	600 gr/mm
#ND Filter=	100%
#Laser (nm)=	532
#Hole=	100.021
#Range=	Auto
#Laser Pol.=	No
#Raman. Pol.=	No
#Laser Pol. (°)=	-0.0007625
#Raman Pol. (°)=	89.9995
#Collection=	Microscope
#StageXY=	Marzhauser
#StageZ=	Marzhauser
#X (µm)=	-1070.8
#Y (µm)=	605.9
#Z (µm)=	584.65
#Full time(mm:ss)=	3:18
#Project=
#Sample=
#Site=
#Title=	Mb_40_y_42_2x_45s_532 nm_x100_100%_600 gr_mm
#Remark=
#Date=	19.07.2022 12:53
#Acquired=	19.07.2022 12:53:13
#Base:Fit=	10.08.2022 10:52:48
#Base:Sub=	10.08.2022 10:52:53
#Filter:Polynom=	16.08.2022 10:09:04
#AxisType[0]=Intens
#AxisUnit[0]=Cnt
#AxisType[1]=Spectr
#AxisUnit[1]=1/cm
200.423	69.0754
204.052	58.2523
207.682	48.4008
211.308	39.7116
214.935	31.3469
218.558	25.8267
222.18	18.525
225.802	14.285
229.421	9.78871
233.039	7.50183
236.657	5.58495
240.272	5.16225
243.885	3.8467
247.497	2.93863
251.11	3.0476
254.719	2.48859
258.327	3.29154
261.933	3.7394
265.538	4.89131
269.141	5.22509
272.744	6.1825
276.344	6.5847
279.944	7.29002
283.542	6.98288
287.138	7.76552
290.733	7.45344
294.327	8.2193
297.919	8.67934
301.508	9.14593
305.098	8.60935
308.686	8.2518
312.273	6.56097
315.858	6.22565
319.44	6.32445
323.022	7.41677
326.604	7.97456
330.181	7.53052
333.76	7.20339
337.335	7.46605
340.91	6.3799
344.483	6.4192
348.055	6.61918
351.625	7.7315
355.195	8.06855
358.762	6.23685
362.329	5.32797
365.893	6.4645
369.455	7.08959
373.017	8.50168
376.578	9.04679
380.137	8.05685
383.694	8.30308
387.249	8.46249
390.806	8.54166
394.359	7.15897
397.91	6.74795
401.46	5.90515
405.009	7.24562
408.557	8.30371
412.103	9.94488
415.647	10.095
419.191	11.3636
422.733	13.2414
426.273	13.6283
429.812	14.7992
433.35	15.8041
436.885	15.4347
440.42	17.3165
443.954	18.0292
447.486	18.0836
451.015	19.4278
454.545	21.6579
458.073	21.7463
461.598	21.1824
465.124	21.778
468.648	23.3559
472.169	24.2905
475.69	25.6218
479.208	23.7898
482.727	24.7497
486.243	26.61
489.759	27.8133
493.272	30.9428
496.783	31.0515
500.295	32.2046
503.804	33.5512
507.311	34.6594
510.819	34.9786
514.324	36.1104
517.827	37.2527
521.329	36.5178
524.83	35.5877
528.329	34.2346
531.829	30.5138
535.326	27.4165
538.821	25.6594
542.315	22.4271
545.808	19.8659
549.299	18.4767
552.789	17.3093
556.278	13.8678
559.763	11.8742
563.249	8.91011
566.733	7.8662
570.217	8.86678
573.699	8.7425
577.177	8.79933
580.656	8.88694
584.134	9.85177
587.609	11.6327
591.084	12.6495
594.558	13.8472
598.029	14.8613
601.5	16.532
604.968	17.3046
608.437	15.8986
611.902	16.8755
615.368	16.1569
618.831	16.4943
622.294	16.4152
625.755	16.9599
629.213	17.3847
632.673	18.5504
636.129	17.5552
639.584	15.4064
643.037	12.9029
646.491	13.3295
649.942	12.8394
653.392	14.1191
656.84	14.7977
660.287	14.8035
663.732	15.1364
667.177	16.412
670.62	16.9213
674.061	21.0287
677.502	23.0433
680.941	26.238
684.379	29.6529
687.815	32.5598
691.248	36.3241
694.682	39.3873
698.115	41.8249
701.546	44.5896
704.974	47.1623
708.402	49.0518
711.83	51.2849
715.254	52.5919
718.679	52.2585
722.102	51.4108
725.522	50.4362
728.943	50.3259
732.361	48.7228
735.779	48.3267
739.194	47.9524
742.608	46.8403
746.022	47.6876
749.433	46.4715
752.843	48.2054
756.254	52.6594
759.661	54.9711
763.067	55.4288
766.471	57.2598
769.877	60.7553
773.279	62.6334
776.68	65.3752
780.079	65.4699
783.478	66.8999
786.875	69.7418
790.27	71.7071
793.665	72.9938
797.058	75.8072
800.45	75.2061
803.84	75.7798
807.23	75.2197
810.616	73.5932
814.002	70.8301
817.388	70.6023
820.772	69.6472
824.153	68.9558
827.535	68.3863
830.915	67.3279
834.292	66.3893
837.67	67.2989
841.047	65.5301
844.42	62.096
847.794	61.4642
851.165	62.5417
854.534	62.5439
857.905	60.7881
861.272	59.6718
864.639	58.1068
868.004	55.9543
871.367	56.2931
874.731	56.3216
878.092	56.2106
881.451	52.4181
884.809	49.8494
888.166	47.9869
891.522	45.5333
894.878	42.7949
898.231	43.7327
901.583	42.0741
904.934	41.2436
908.283	41.1729
911.631	40.6687
914.976	38.9678
918.322	38.4101
921.666	39.1371
925.009	39.625
928.351	40.4331
931.692	40.9699
935.029	41.5648
938.367	39.49
941.704	38.1207
945.038	37.0874
948.372	37.5066
951.705	37.8691
955.035	36.0022
958.366	33.8206
961.693	32.0962
965.021	31.3343
968.346	31.4941
971.67	32.868
974.995	33.2698
978.316	31.8874
981.638	31.7022
984.957	30.6375
988.274	31.4766
991.59	31.3858
994.907	28.0757
998.221	21.5773
1001.53	16.4201
1004.85	13.2168
1008.16	20.9534
1011.46	39.4798
1014.77	67.3058
1018.08	100.677
1021.38	132.96
1024.69	164.962
1027.99	196.043
1031.29	221.218
1034.59	240.793
1037.89	255.191
1041.19	265.766
1044.48	271.237
1047.78	272.246
1051.07	266.494
1054.36	256.254
1057.66	241.69
1060.94	221.089
1064.23	195.871
1067.52	167.21
1070.81	132.721
1074.09	96.4929
1077.38	61.8953
1080.66	31.5987
1083.94	10.9004
1087.22	0.427574
1090.5	3.2669
1093.77	9.8195
1097.05	16.5899
1100.32	21.2127
1103.6	25.5731
1106.87	29.5876
1110.14	30.8774
1113.41	31.1062
1116.67	31.7642
1119.94	32.6201
1123.21	33.9829
1126.47	35.3768
1129.73	34.4587
1133	32.6367
1136.26	32.3377
1139.52	30.5502
1142.77	28.7397
1146.03	26.598
1149.29	23.1855
1152.54	20.8731
1155.79	19.9788
1159.04	15.1498
1162.3	11.0628
1165.55	7.9921
1168.79	6.02112
1172.04	5.6299
1175.28	5.31998
1178.53	6.8344
1181.77	5.45093
1185.01	3.07671
1188.25	2.98226
1191.49	1.38044
1194.73	4.07339
1197.97	2.64286
1201.2	4.07895
1204.44	5.54261
1207.67	7.06309
1210.9	9.25696
1214.13	12.0868
1217.36	16.5404
1220.59	21.5879
1223.82	25.9208
1227.04	31.0147
1230.26	34.3581
1233.49	38.8805
1236.71	41.5413
1239.93	44.2219
1243.15	47.2273
1246.37	51.2516
1249.58	55.4765
1252.8	57.7361
1256.01	63.0816
1259.23	65.8936
1262.44	72.5791
1265.65	77.865
1268.86	82.5049
1272.07	87.2458
1275.27	91.1487
1278.48	94.1039
1281.68	100.56
1284.89	104.965
1288.09	109.035
1291.29	111.366
1294.49	114.917
1297.69	118.355
1300.88	118.188
1304.08	118.381
1307.27	117.931
1310.47	116.267
1313.66	114.84
1316.85	112.179
1320.04	108.721
1323.23	104.505
1326.41	99.7325
1329.6	95.5216
1332.78	91.8122
1335.97	89.7896
1339.15	87.4808
1342.33	84.231
1345.51	79.3993
1348.69	75.3312
1351.87	71.6024
1355.04	68.5614
1358.22	66.1126
1361.39	63.0174
1364.57	59.1439
1367.74	58.8001
1370.91	56.7345
1374.07	56.2648
1377.24	53.9612
1380.41	54.8931
1383.57	57.0518
1386.74	58.8078
1389.9	60.1705
1393.06	63.5502
1396.22	65.7507
1399.38	67.142
1402.54	72.2956
1405.7	78.3392
1408.85	83.9486
1412.01	91.4448
1415.16	101.171
1418.31	108.279
1421.46	118.321
1424.61	126.826
1427.76	134.5
1430.91	141.529
1434.05	148.594
1437.2	153.899
1440.34	156.752
1443.49	158.68
1446.63	159.316
1449.77	158.639
1452.91	155.256
1456.04	150.168
1459.18	144.375
1462.31	137.47
1465.45	127.703
1468.58	117.267
1471.71	106.424
1474.84	95.7312
1477.97	86.3924
1481.1	78.3046
1484.23	70.9549
1487.35	63.3204
1490.48	57.5155
1493.6	52.1024
1496.72	47.363
1499.84	43.2723
1502.96	39.5504
1506.08	36.7479
1509.2	37.1162
1512.31	37.3514
1515.43	36.6594
1518.54	36.7785
1521.66	38.2315
1524.77	40.5039
1527.88	41.7443
1530.99	41.9878
1534.09	44.3945
1537.2	45.4207
1540.31	46.0973
1543.41	47.7259
1546.51	48.7894
1549.62	51.2949
1552.72	51.987
1555.82	53.3551
1558.91	54.5087
1562.01	55.4006
1565.11	55.8414
1568.2	56.9294
1571.3	58.0371
1574.39	60.0801
1577.48	62.3596
1580.57	65.0403
1583.66	66.1737
1586.75	68.2667
1589.83	70.2397
1592.92	71.4273
1596	71.8333
1599.09	72.3498
1602.17	73.3469
1605.25	73.4386
1608.33	72.8067
1611.41	72.9815
1614.48	73.3894
1617.56	74.487
1620.64	74.9876
1623.71	76.6578
1626.78	78.3328
1629.86	78.1474
1632.92	80.4545
1635.99	81.9517
1639.06	84.9342
1642.13	89.3929
1645.19	91.1238
1648.26	94.5861
1651.32	96.4993
1654.38	96.8172
1657.45	96.6475
1660.51	95.1821
1663.57	92.8901
1666.62	89.0809
1669.68	86.9318
1672.73	82.7033
1675.79	78.913
1678.84	71.8113
1681.89	65.7163
1684.94	59.8799
1687.99	54.0604
1691.04	48.5568
1694.09	43.9744
1697.14	39.0108
1700.18	34.7094
1703.22	29.3257
1706.27	26.7504
1709.31	22.9684
1712.35	20.6191
1715.39	18.4252
1718.43	16.1514
1721.46	14.4721
1724.5	14.3199
1727.53	11.176
1730.57	10.0123
1733.6	9.38337
1736.63	8.50901
1739.66	7.15767
1742.69	7.37347
1745.72	7.62277
1748.74	6.29977
1751.77	4.26006
1754.8	4.2362
1757.82	4.46899
1760.84	3.92618
1763.86	3.99439
1766.88	4.21317
1769.9	4.15299
1772.92	3.90087
1775.93	3.33928
1778.95	3.69274
1781.96	3.22183
1784.98	3.45011
1787.99	4.16784
1791	3.98352
1794.01	3.96497
1797.02	5.12994
1800.03	6.24904
1803.03	6.08511
1806.04	6.18751
1809.04	6.0552
1812.04	5.29154
1815.05	4.43677
1818.05	4.25791
1821.05	3.60842
1824.05	2.86933
1827.04	1.74587
1830.04	1.71946
1833.03	1.52061
1836.03	1.00889
1839.02	1.27586
1842.01	0.871245
1845	-0.595914
1847.99	-0.715719
1850.98	-0.928224
1853.97	-1.0365
1856.95	-0.824646
1859.94	-0.29213
1862.92	0.37339
1865.91	0.282713
1868.89	0.426515
1871.87	0.921551
1874.85	1.67941
1877.83	0.728209
1880.8	1.3636
1882.56	1.11719
1885.54	1.6821
1888.53	2.12578
1891.52	2.28807
1894.5	1.83035
1897.49	1.30375
1900.47	2.95818
1903.45	3.86375
1906.43	4.00813
1909.41	5.10439
1912.39	5.63039
1915.37	5.39635
1918.35	5.39782
1921.32	6.46334
1924.3	5.44709
1927.27	6.12185
1930.24	5.7136
1933.21	6.47253
1936.18	6.96549
1939.15	5.68939
1942.12	5.94035
1945.09	6.90539
1948.05	7.261
1951.02	6.87473
1953.98	7.07061
1956.94	7.66929
1959.91	8.13629
1962.87	7.14879
1965.82	6.50406
1968.78	7.58877
1971.74	8.14919
1974.7	8.00605
1977.65	7.94633
1980.6	7.36608
1983.56	6.04595
1986.51	5.01117
1989.46	4.40947
1992.41	4.18783
1995.36	3.24638
1998.3	2.41116
2001.25	2.95116
2004.2	3.09033
2007.14	2.57925
2010.08	2.64532
2013.02	2.93614
2015.97	3.14116
2018.9	3.20345
2021.84	3.40441
2024.78	4.27211
2027.72	5.47323
2030.65	6.00248
2033.59	6.22213
2036.52	8.00149
2039.45	9.79582
2042.38	10.879
2045.31	10.7297
2048.24	11.5398
2051.17	12.5023
2054.1	12.8217
2057.02	14.2643
2059.95	15.8144
2062.87	16.5143
2065.79	18.2143
2068.71	19.5406
2071.63	20.9734
2074.55	22.5242
2077.47	22.9349
2080.39	24.8964
2083.3	26.7147
2086.22	27.0778
2089.13	28.7655
2092.05	29.7064
2094.96	31.6693
2097.87	33.2544
2100.78	35.8836
2103.69	37.37
2106.59	40.2226
2109.5	42.2698
2112.41	44.9797
2115.31	47.1091
2118.21	50.8345
2121.12	54.4248
2124.02	56.9925
2126.92	60.2217
2129.82	64.0782
2132.71	68.7091
2135.61	72.1581
2138.51	76.4134
2141.4	80.6729
2144.29	85.5904
2147.19	89.7094
2150.08	94.2973
2152.97	97.5717
2155.86	101.096
2158.75	104.319
2161.64	108.325
2164.52	110.635
2167.41	113.43
2170.29	114.999
2173.17	116.567
2176.06	115.406
2178.94	116.157
2181.82	115.469
2184.7	114.739
2187.57	112.949
2190.45	109.939
2193.33	104.748
2196.2	100.209
2199.08	96.1116
2201.95	91.6175
2204.82	86.1179
2207.69	81.4887
2210.56	77.3373
2213.43	73.0958
2216.3	68.7722
2219.16	64.8548
2222.03	60.82
2224.89	58.381
2227.75	55.3214
2230.62	53.3485
2233.48	49.9523
2236.34	47.7685
2239.2	46.1146
2242.06	44.1367
2244.91	42.6
2247.77	40.4748
2250.62	39.0506
2253.48	36.6177
2256.33	33.8329
2259.18	32.7419
2262.03	30.5664
2264.88	28.7043
2267.73	26.8997
2270.58	25.5629
2273.43	23.3471
2276.27	21.1131
2279.12	19.5252
2281.96	17.9319
2284.8	17.2564
2287.64	16.1684
2290.49	14.6547
2293.32	12.8876
2296.16	12.9853
2299	14.0042
2301.84	14.3796
2304.67	14.7234
2307.51	15.6415
2310.34	15.7357
2313.17	15.6785
2316	15.5839
2318.83	15.4095
2321.66	15.8965
2324.49	16.5026
2327.32	17.2817
2330.15	16.605
2332.97	15.7536
2335.79	14.0182
2338.62	13.3752
2341.44	12.7454
2344.26	10.3422
2347.08	7.96532
2349.9	5.7662
2352.72	4.48748
2355.53	2.45625
2358.35	1.09146
2361.17	0.327345
2363.98	0.8928
2366.79	1.85185
2369.6	1.29533
2372.42	1.10506
2375.22	0.851084
2378.03	0.391127
2380.84	1.07899
2383.65	1.38337
2386.45	2.05722
2389.26	2.95608
2392.06	4.30881
2394.87	4.55032
2397.67	5.66489
2400.47	5.83557
2403.27	6.89209
2406.07	7.92494
2408.86	7.80247
2411.66	8.85195
2414.46	8.49692
2417.25	8.55325
2420.05	8.72301
2422.84	9.87109
2425.63	10.5659
2428.42	10.1477
2431.21	10.6746
2434	9.74964
2436.79	9.54361
2439.57	8.5766
2442.36	8.77664
2445.14	7.76109
2447.93	6.47114
2450.71	6.50687
2453.49	7.22748
2456.27	7.20403
2459.05	5.80543
2461.83	5.22663
2464.61	4.27289
2467.39	4.97753
2470.16	6.00478
2472.94	6.64407
2475.71	6.78768
2478.48	7.59459
2481.25	7.00244
2484.02	6.564
2486.8	6.3316
2489.56	6.63055
2492.33	6.04355
2495.1	5.3506
2497.86	5.23481
2500.63	4.60126
2503.39	3.56989
2506.16	2.87291
2508.92	2.26243
2511.68	1.24216
2514.44	0.711877
2517.2	0.331348
2519.95	1.29794
2522.71	1.55197
2525.47	0.653606
2528.22	-0.390862
2530.98	0.393694
2533.73	2.33272
2536.48	4.47514
2539.23	4.74223
2541.98	5.51182
2544.73	5.61221
2547.48	5.11657
2550.23	4.99396
2552.97	6.06586
2555.72	6.55571
2558.46	6.86468
2561.2	6.39002
2563.95	7.44759
2566.69	7.02823
2569.43	6.99433
2572.17	7.89185
2574.91	7.49666
2577.64	8.00727
2580.38	7.99114
2583.11	8.71426
2585.85	9.40269
2588.58	8.78215
2591.31	8.22085
2594.04	6.95654
2596.78	6.70657
2599.51	6.78406
2602.23	6.53202
2604.96	5.10058
2607.69	4.31902
2610.41	4.64718
2613.14	4.73345
2615.86	4.92689
2618.58	5.36844
2621.3	5.47142
2624.03	6.31447
2626.75	5.29088
2629.46	4.95503
2632.18	6.28363
2634.9	7.02415
2637.61	6.42361
2640.33	7.35503
2643.04	6.91415
2645.76	7.2124
2648.47	7.45101
2651.18	7.32665
2653.89	7.02266
2656.6	6.2426
2659.31	6.14063
2662.01	6.05043
2664.72	5.479
2667.43	6.09188
2670.13	6.22434
2672.83	5.64835
2675.53	6.69894
2678.24	7.23985
2680.94	7.4753
2683.64	7.68497
2686.34	8.62149
2689.03	8.51286
2691.73	9.00211
2694.43	8.96166
2697.12	9.89856
2699.81	11.6162
2702.51	12.1193
2705.2	12.663
2707.89	13.79
2710.58	14.2647
2713.27	15.0306
2715.96	16.8769
2718.64	16.6999
2721.33	17.2987
2724.01	17.8714
2726.7	17.8422
2729.38	16.7557
2732.06	16.5577
2734.75	16.0013
2737.43	15.1792
2740.11	14.6077
2742.78	14.1718
2745.46	14.1528
2748.14	12.0772
2750.81	11.5389
2753.49	9.66687
2756.16	9.26586
2758.84	9.56687
2761.51	8.29622
2764.18	8.20006
2766.85	7.62557
2769.52	6.42567
2772.19	6.07337
2774.85	5.26454
2777.52	4.62046
2780.18	3.42454
2782.85	2.51388
2785.51	1.81257
2788.17	1.0953
2790.84	0.649646
2793.5	-0.0391913
2796.16	-0.486734
2798.81	-0.808742
2801.47	-1.00694
2804.13	-0.810591
2806.79	-1.91174
2809.44	-3.04847
2812.09	-3.83216
2814.75	-1.16901
2817.4	3.2814
2820.05	9.62282
2822.7	17.7879
2825.35	26.7959
2828	37.403
2830.65	48.3919
2833.29	60.3638
2835.94	71.0998
2838.58	83.1988
2841.23	93.8473
2843.87	102.889
2846.51	113.104
2849.15	124.478
2851.79	138.286
2854.43	153.566
2857.07	166.941
2859.71	179.89
2862.34	190.095
2864.98	198.876
2867.61	206.381
2870.25	211.972
2872.88	216.579
2875.51	221.165
2878.14	225.566
2880.77	229.517
2883.4	232.5
2886.03	235.658
2888.65	237.195
2891.28	238.904
2893.91	239.902
2896.53	239.663
2899.15	240.099
2901.78	240.341
2904.4	241.789
2907.02	243.733
2909.64	248.965
2912.26	256.892
2914.87	267.059
2917.49	278.519
2920.11	286.752
2922.72	293.777
2925.34	299.707
2927.95	304.576
2930.56	307.583
2933.17	309.408
2935.78	309.202
2938.39	305.262
2941	300.787
2943.61	294.291
2946.22	285.313
2948.82	275.793
2951.43	265.504
2954.03	252.327
2956.64	240.234
2959.24	227.653
2961.84	214.1
2964.44	202.562
2967.04	190.479
2969.64	178.647
2972.24	166.735
2974.83	155.651
2977.43	143.974
2980.02	132.346
2982.62	120.787
2985.21	110.806
2987.8	100.094
2990.4	89.9825
2992.99	80.2984
2995.57	70.9446
2998.16	62.4128
3000.75	54.0837
3003.34	46.006
3005.92	40.0661
3008.51	34.2145
3011.09	28.5237
3013.68	23.4264
3016.26	18.7152
3018.84	14.9792
3021.42	12.6289
3024	9.93385
3026.58	8.69605
3029.16	7.05512
3031.73	6.35184
3034.31	5.84252
3036.89	5.54351
3039.46	5.60516
3042.03	6.72338
3044.61	7.86745
3047.18	7.56099
3049.75	7.96626
3052.32	7.98699
3054.89	8.67067
3057.45	8.60762
3060.02	8.37906
3062.59	8.22079
3065.15	7.93161
3067.72	7.0169
3070.28	6.61416
3072.84	5.42479
3075.41	4.28778
3077.97	3.05024
3080.53	2.10469
3083.09	1.58878
3085.64	0.366677
3088.2	0.617712
3090.76	0.667255
3093.31	0.696196
3095.87	1.586
3098.42	2.75352
3100.97	3.54578
3103.53	4.78212
3106.08	6.22844
3108.63	7.36237
3111.18	9.01819
3113.73	11.501
3116.27	13.2204
3118.82	14.8649
3121.37	16.4907
3123.91	18.4817
3126.45	19.4521
3129	20.9781
3131.54	22.6352
3134.08	24.3507
3136.62	26.4646
3139.16	27.0736
3141.7	28.8345
3144.24	30.2543
3146.78	32.2226
3149.31	33.508