File: data/Raman/poly_smoothed/Mb_40_24_40_1x_45s_532 nm_x100_100%_600 gr_mm_01.txt
#Acq. time (s)=	45
#Accumulations=	2
#Range (cm-¹)=	200...3150
#Windows=	2
#Auto scanning=	Off
#Autofocus=	Off
#Macrospot=	Off
#AutoExposure=	Off
#Spike filter=	Multiple accum.
#Delay time (s)=	0
#Binning=	1
#Readout mode=	Signal
#DeNoise=	Off
#ICS correction=	On
#Dark correction=	Off
#Inst. Process=	Off
#Detector Gain=	Best Dynamic Range
#Detector ADC=	20 kHz
#Detector temperature (°C)=	-70.08
#Instrument=	LabRAM HR Evol
#Detector=	Synapse
#Objective=	x100
#Grating=	600 gr/mm
#ND Filter=	100%
#Laser (nm)=	532
#Hole=	100.021
#Range=	Auto
#Laser Pol.=	No
#Raman. Pol.=	No
#Laser Pol. (°)=	-0.0007625
#Raman Pol. (°)=	89.9995
#Collection=	Microscope
#StageXY=	Marzhauser
#StageZ=	Marzhauser
#X (µm)=	-2483.4
#Y (µm)=	-55.7
#Z (µm)=	-10.55
#Full time(mm:ss)=	3:19
#Project=
#Sample=
#Site=
#Title=	Mb_40_24_40_2x_45s_532 nm_x100_100%_600 gr_mm
#Remark=
#Date=	14.07.2022 13:52
#Acquired=	14.07.2022 13:52:03
#Edit:Spike=	14.07.2022 13:56:19
#Base:Fit=	10.08.2022 10:47:00
#Base:Sub=	10.08.2022 10:47:12
#Filter:Polynom=	16.08.2022 10:11:48
#AxisType[0]=Intens
#AxisUnit[0]=Cnt
#AxisType[1]=Spectr
#AxisUnit[1]=1/cm
200.554	7.19929
204.183	9.03042
207.813	12.4992
211.439	12.7181
215.065	11.7627
218.688	10.1468
222.312	10.37
225.933	8.98372
229.552	6.83539
233.171	7.5631
236.787	7.85929
240.402	5.44269
244.015	6.11277
247.627	5.56595
251.24	4.02728
254.849	4.02245
258.457	4.85133
262.063	4.63002
265.668	5.63091
269.271	8.12627
272.873	8.81511
276.474	11.5499
280.073	11.5756
283.671	11.6496
287.268	12.0821
290.863	14.0302
294.456	13.1099
298.049	12.3773
301.637	14.488
305.227	16.5412
308.815	15.8594
312.402	17.1292
315.987	16.2252
319.569	18.0217
323.151	19.7545
326.733	16.8876
330.31	16.6236
333.889	15.4039
337.464	16.0476
341.039	14.5066
344.611	14.6528
348.184	14.0039
351.754	11.3925
355.324	11.9221
358.89	10.9675
362.455	10.2921
366.021	8.41564
369.584	6.74591
373.145	5.03336
376.707	4.24421
380.265	2.52542
383.822	2.87518
387.378	4.22103
390.934	5.55495
394.487	4.35028
398.038	2.75714
401.588	3.21848
405.137	5.2076
408.685	5.96969
412.23	4.74752
415.775	4.27447
419.318	4.3758
422.86	4.58536
426.401	5.42596
429.94	4.25915
433.478	3.4594
437.012	3.61147
440.547	4.61321
444.081	6.28503
447.613	4.90558
451.142	4.02517
454.672	4.98528
458.2	3.98794
461.725	5.70603
465.251	7.42723
468.775	8.90607
472.296	11.6854
475.817	13.7839
479.335	15.1499
482.854	17.2599
486.37	18.1897
489.886	21.5107
493.398	25.4179
496.91	27.5848
500.422	28.8175
503.93	29.7694
507.438	31.7163
510.946	30.5748
514.45	31.205
517.954	29.9859
521.456	32.4433
524.956	33.1836
528.456	32.1085
531.956	30.8768
535.452	29.1599
538.947	29.1131
542.441	29.216
545.934	27.6684
549.425	27.2526
552.915	26.591
556.403	24.8258
559.889	24.0874
563.375	21.3831
566.859	19.7593
570.342	16.6463
573.824	15.7129
577.303	13.7361
580.782	14.9289
584.26	12.2359
587.734	10.6638
591.21	9.52647
594.684	7.70694
598.154	6.85995
601.626	7.52052
605.094	7.35059
608.562	7.64771
612.027	6.76115
615.493	5.45468
618.956	5.99273
622.419	7.00253
625.879	7.2303
629.338	8.95281
632.797	10.5951
636.254	9.87181
639.708	11.0289
643.162	12.8
646.614	13.2734
650.067	10.3464
653.516	9.73244
656.964	10.4202
660.411	8.53742
663.857	8.21712
667.301	8.36186
670.744	8.37134
674.186	10.3197
677.626	11.702
681.065	10.1427
684.503	9.87177
687.939	11.1753
691.372	13.55
694.806	13.2641
698.239	13.9566
701.67	16.4282
705.098	17.6665
708.526	20.6049
711.954	22.1658
715.378	23.8557
718.802	23.6739
722.226	25.18
725.646	27.0763
729.067	26.6579
732.484	25.9068
735.902	24.879
739.317	26.3776
742.731	29.0262
746.145	30.2328
749.556	33.0644
752.966	38.4172
756.377	43.3147
759.784	46.8143
763.19	49.4591
766.594	52.4928
770	56.3915
773.402	59.1721
776.803	63.1555
780.202	65.4356
783.6	68.8367
786.997	71.0399
790.393	72.6723
793.787	74.7816
797.18	76.5847
800.572	76.1725
803.963	75.7639
807.35	76.4493
810.738	75.5639
814.125	75.7201
817.51	74.9216
820.894	76.3294
824.275	77.3101
827.657	76.7641
831.037	76.016
834.414	75.1969
837.792	75.0718
841.167	72.2987
844.542	70.165
847.914	68.3749
851.287	65.0305
854.656	62.5396
858.026	61.4026
861.393	61.6813
864.761	59.6764
868.125	58.9391
871.489	58.1184
874.85	57.3586
878.213	56.3889
881.572	55.7279
884.931	56.1992
888.287	55.6282
891.643	58.6655
894.997	58.6894
898.352	59.8957
901.704	61.4976
905.055	62.0328
908.404	62.4556
911.75	60.9943
915.097	61.7141
918.443	60.8995
921.787	61.312
925.13	59.1678
928.472	58.4894
931.813	55.555
935.15	54.0218
938.488	52.7709
941.825	50.0424
945.158	46.9084
948.493	44.4033
951.824	43.2731
955.156	41.9892
958.486	37.2599
961.814	37.2431
965.142	37.7476
968.467	41.0872
971.79	45.5722
975.115	47.9052
978.436	48.5937
981.756	51.6394
985.077	50.4415
988.394	53.244
991.71	55.9692
995.025	57.6469
998.341	58.0308
1001.65	57.2627
1004.97	56.3765
1008.28	56.7181
1011.58	60.7315
1014.89	63.1693
1018.2	68.2327
1021.5	71.961
1024.81	74.6201
1028.11	76.8488
1031.41	79.9564
1034.71	81.9778
1038.01	82.007
1041.31	82.6976
1044.6	86.3347
1047.9	88.4282
1051.19	87.8837
1054.48	86.5351
1057.77	83.8123
1061.06	82.0915
1064.35	75.501
1067.64	73.9934
1070.93	72.8081
1074.21	68.8237
1077.49	63.2859
1080.78	59.7048
1084.06	57.9295
1087.34	59.2663
1090.61	59.3809
1093.89	60.7169
1097.17	62.9879
1100.44	62.1459
1103.71	60.9534
1106.99	60.3343
1110.26	57.5632
1113.52	49.0081
1116.79	38.5835
1120.06	31.5322
1123.32	31.0618
1126.59	35.4724
1129.85	42.2076
1133.11	62.4363
1136.37	84.7069
1139.63	104.79
1142.89	123.605
1146.15	139.029
1149.4	149.948
1152.66	156.828
1155.91	159.833
1159.16	162.267
1162.41	162.804
1165.66	158.424
1168.91	152.882
1172.16	145.65
1175.4	135.228
1178.65	120.34
1181.89	104.206
1185.13	85.9512
1188.37	63.6674
1191.61	40.3209
1194.85	16.2975
1198.08	8.2925
1201.32	8.46955
1204.55	11.1885
1207.79	18.1389
1211.02	32.5414
1214.25	47.8616
1217.48	57.4656
1220.71	66.5175
1223.93	72.9362
1227.16	77.5964
1230.38	82.6733
1233.6	87.1082
1236.83	91.1864
1240.05	96.6843
1243.26	101.369
1246.48	105.982
1249.7	111.113
1252.92	114.94
1256.13	120.129
1259.34	123.265
1262.55	128.195
1265.76	132.457
1268.97	138.187
1272.18	145.771
1275.39	149.116
1278.59	155.927
1281.8	161.561
1285	163.495
1288.2	167.615
1291.4	171.698
1294.6	175.685
1297.8	176.86
1301	178.626
1304.19	180.383
1307.39	181.003
1310.58	180.704
1313.77	179.445
1316.96	177.825
1320.15	175.598
1323.34	172.784
1326.53	168.748
1329.72	163.971
1332.9	159.96
1336.08	154.797
1339.27	149.388
1342.45	143.316
1345.63	138.199
1348.8	132.15
1351.98	124.653
1355.16	119.583
1358.33	115.076
1361.51	108.81
1364.68	104.555
1367.85	100.342
1371.02	98.9601
1374.19	94.8889
1377.36	94.3366
1380.52	96.9218
1383.69	98.1023
1386.85	101.122
1390.02	101.279
1393.18	101.928
1396.34	103.708
1399.5	103.792
1402.65	107.765
1405.81	111.37
1408.97	115.966
1412.12	122.849
1415.27	130.206
1418.43	138.374
1421.58	146.513
1424.73	158.121
1427.87	168.35
1431.02	180.133
1434.17	190.283
1437.31	199.447
1440.46	205.152
1443.6	209.154
1446.74	210.563
1449.88	209.447
1453.02	207.083
1456.16	202.927
1459.29	197.259
1462.43	189.174
1465.56	177.235
1468.69	164.789
1471.83	153.253
1474.95	140.963
1478.08	128.475
1481.21	116.23
1484.34	104.396
1487.47	94.368
1490.59	86.5112
1493.71	80.6744
1496.84	73.9708
1499.96	66.4718
1503.07	65.1251
1506.19	61.3812
1509.31	57.6335
1512.43	55.1988
1515.54	50.972
1518.65	47.645
1521.77	46.1419
1524.88	44.5052
1527.99	44.9213
1531.1	43.6565
1534.21	44.3645
1537.31	46.6192
1540.42	50.041
1543.52	51.9142
1546.63	56.4914
1549.73	60.1903
1552.83	64.826
1555.93	68.7659
1559.03	73.7442
1562.12	79.5316
1565.22	85.7746
1568.31	91.6155
1571.41	97.8501
1574.5	104.429
1577.59	111.443
1580.68	119.885
1583.77	125.473
1586.86	129.027
1589.95	132.818
1593.03	134.659
1596.11	138.362
1599.2	137.193
1602.28	136.848
1605.36	136.07
1608.44	135.191
1611.52	135.058
1614.6	135.82
1617.67	136.975
1620.75	138.275
1623.82	140.945
1626.89	142.506
1629.96	145.604
1633.04	148.473
1636.11	151.599
1639.17	155.42
1642.24	159.967
1645.31	165.997
1648.37	171.289
1651.43	174.678
1654.5	177.236
1657.56	177.792
1660.62	173.935
1663.67	169.777
1666.73	163.774
1669.79	154.837
1672.84	145.135
1675.9	135.318
1678.95	124.509
1682	112.717
1685.05	101.853
1688.1	90.442
1691.15	81.5416
1694.2	69.579
1697.25	60.4284
1700.29	51.9309
1703.33	45.0277
1706.38	37.6073
1709.42	31.601
1712.46	26.1182
1715.5	22.4175
1718.54	18.4982
1721.57	15.6949
1724.61	13
1727.64	12.7092
1730.68	11.1345
1733.71	8.58348
1736.74	6.76802
1739.77	5.77372
1742.8	5.85119
1745.83	4.71396
1748.85	4.80359
1751.88	5.15206
1754.91	3.98817
1757.93	3.10402
1760.95	2.87902
1763.97	2.47517
1766.99	2.53622
1770.01	3.14623
1773.03	4.54808
1776.04	3.72813
1779.06	3.8586
1782.07	2.92529
1785.09	1.94596
1788.1	3.1268
1791.11	3.19923
1794.12	4.07014
1797.13	4.14841
1800.13	4.2659
1803.14	3.68734
1806.15	2.46461
1809.15	3.28986
1812.15	3.49043
1815.16	4.42097
1818.15	4.68545
1821.16	4.58048
1824.15	4.63049
1827.15	3.89536
1830.15	3.56419
1833.14	3.07931
1836.14	2.35848
1839.13	0.667674
1842.12	0.510403
1845.11	-0.0110245
1848.1	-0.142737
1851.09	-0.686337
1854.08	-0.0149664
1857.06	1.10934
1860.05	3.04134
1863.03	3.93381
1866.01	4.36614
1869	4.25226
1871.98	3.85359
1874.96	3.38708
1877.93	4.16934
1880.91	6.3061
1882.47	7.39335
1885.46	6.98852
1888.44	7.73317
1891.43	6.95366
1894.42	6.62658
1897.4	5.15114
1900.39	4.56349
1903.37	3.44024
1906.35	3.38667
1909.33	2.18203
1912.31	1.52615
1915.29	2.75491
1918.26	3.35866
1921.24	3.33345
1924.21	4.2582
1927.19	4.72227
1930.16	3.90224
1933.13	4.45766
1936.1	4.31413
1939.07	4.61421
1942.04	6.25876
1945	5.7164
1947.97	5.57261
1950.93	6.19852
1953.9	6.52732
1956.86	6.28573
1959.82	6.04913
1962.78	5.56675
1965.74	5.93107
1968.7	4.75465
1971.65	4.57158
1974.61	5.26859
1977.57	5.87237
1980.52	6.07667
1983.47	4.93947
1986.42	5.41862
1989.37	6.51727
1992.32	5.74461
1995.27	6.34468
1998.22	5.20426
2001.17	6.59294
2004.11	7.06667
2007.05	9.55844
2010	10.7563
2012.94	11.345
2015.88	11.7335
2018.82	10.6945
2021.76	11.7405
2024.7	12.3862
2027.63	14.0064
2030.57	14.4895
2033.5	15.3645
2036.44	16.1087
2039.37	16.3909
2042.3	18.2408
2045.23	20.8948
2048.16	24.1752
2051.08	25.2668
2054.01	26.2886
2056.94	29.1541
2059.86	30.7511
2062.79	33.2151
2065.71	34.7419
2068.63	37.1921
2071.55	40.6374
2074.47	42.8032
2077.39	46.5792
2080.31	48.7476
2083.22	51.3084
2086.13	52.413
2089.05	53.2691
2091.96	54.9066
2094.87	57.7849
2097.78	60.9646
2100.69	65.001
2103.6	68.7454
2106.51	70.6137
2109.42	73.7715
2112.32	78.3565
2115.23	83.4363
2118.13	89.2977
2121.03	93.7357
2123.93	99.0422
2126.83	107.066
2129.73	113.278
2132.63	121.798
2135.53	130.677
2138.42	141.201
2141.32	149.552
2144.21	157.336
2147.1	165.693
2150	174.608
2152.89	181.648
2155.78	188.202
2158.66	193.429
2161.55	197.835
2164.44	202.965
2167.32	206.268
2170.21	206.232
2173.09	204.731
2175.97	201.328
2178.85	198.223
2181.73	192.884
2184.61	187.128
2187.49	181.319
2190.37	176.644
2193.24	170.073
2196.12	164.992
2198.99	158.338
2201.87	150.602
2204.74	145.022
2207.61	140.493
2210.48	133.625
2213.35	125.753
2216.21	118.373
2219.08	113.918
2221.95	107.464
2224.81	101.753
2227.67	95.8447
2230.54	91.2923
2233.4	84.3894
2236.26	78.0474
2239.11	72.5724
2241.97	67.0301
2244.83	63.7542
2247.69	59.2662
2250.54	55.726
2253.4	52.1377
2256.25	48.9735
2259.1	47.2862
2261.95	46.2971
2264.8	42.7819
2267.65	39.9808
2270.5	37.5257
2273.34	35.8655
2276.19	35.756
2279.03	34.1502
2281.88	32.712
2284.72	30.4447
2287.56	30.0556
2290.4	28.0511
2293.24	26.6606
2296.08	25.183
2298.92	24.2656
2301.76	24.4601
2304.59	23.6166
2307.43	22.7228
2310.26	22.9265
2313.09	22.6831
2315.92	21.3422
2318.75	20.1459
2321.58	19.1464
2324.41	19.4249
2327.24	18.0899
2330.06	17.5396
2332.89	16.3835
2335.71	15.1291
2338.54	14.0637
2341.36	11.5113
2344.18	10.1574
2347	9.9737
2349.82	9.18489
2352.64	6.78723
2355.45	6.35302
2358.27	5.51551
2361.08	5.90873
2363.9	5.3729
2366.71	5.10915
2369.52	5.91527
2372.33	6.36153
2375.14	5.45256
2377.95	5.5059
2380.76	5.14346
2383.57	5.15992
2386.37	4.70022
2389.18	4.39275
2391.98	5.32574
2394.79	5.7762
2397.59	5.58049
2400.39	5.07482
2403.19	5.66972
2405.99	4.73053
2408.78	4.81995
2411.58	5.68293
2414.38	6.62093
2417.17	7.10941
2419.97	6.19331
2422.76	6.60302
2425.55	8.05213
2428.34	8.67073
2431.13	9.14044
2433.92	8.58918
2436.71	9.59948
2439.49	10.0137
2442.28	8.88628
2445.06	7.74458
2447.85	8.40391
2450.63	8.26385
2453.41	6.74086
2456.19	6.93161
2458.97	7.17686
2461.75	8.64117
2464.53	8.09077
2467.31	7.40372
2470.08	6.19129
2472.86	6.77984
2475.63	6.8181
2478.4	6.46487
2481.17	5.35802
2483.94	4.39431
2486.72	3.24287
2489.48	3.12783
2492.25	4.40658
2495.02	4.4762
2497.79	4.27622
2500.55	3.01243
2503.31	3.54879
2506.08	3.0878
2508.84	2.58407
2511.6	2.96935
2514.36	4.7573
2517.12	4.49829
2519.88	4.93894
2522.63	6.62002
2525.39	7.96048
2528.14	9.08013
2530.9	9.30864
2533.65	7.79944
2536.4	7.57006
2539.15	6.23983
2541.9	7.47656
2544.65	5.89744
2547.4	5.32728
2550.15	3.91308
2552.89	2.96925
2555.64	3.28885
2558.38	2.51919
2561.12	2.04301
2563.87	2.57872
2566.61	4.02125
2569.35	4.79933
2572.09	5.84356
2574.83	5.46346
2577.56	6.51919
2580.3	6.04247
2583.04	6.33353
2585.77	7.33619
2588.5	7.03974
2591.23	7.52609
2593.97	7.78236
2596.7	8.03926
2599.43	6.21512
2602.15	5.67897
2604.88	5.48387
2607.61	5.13871
2610.33	4.49594
2613.06	2.20898
2615.78	3.17039
2618.51	2.37311
2621.23	3.17674
2623.95	4.36443
2626.67	4.72031
2629.39	5.46104
2632.1	5.82469
2634.82	5.30766
2637.54	4.21951
2640.25	4.07985
2642.97	4.26218
2645.68	5.0422
2648.39	4.93604
2651.1	4.7921
2653.81	5.43313
2656.52	6.32267
2659.23	6.27504
2661.94	5.50067
2664.64	5.64317
2667.35	5.76578
2670.05	6.14792
2672.76	6.04148
2675.46	5.26431
2678.16	5.70461
2680.86	4.88752
2683.56	5.95709
2686.26	6.14961
2688.96	7.55009
2691.65	8.22225
2694.35	7.42484
2697.04	6.5967
2699.74	6.95712
2702.43	7.6795
2705.12	8.89282
2707.81	10.4208
2710.5	11.8115
2713.19	12.5613
2715.88	14.1053
2718.57	15.198
2721.25	15.0129
2723.94	14.744
2726.62	13.9347
2729.3	14.7004
2731.99	13.5961
2734.67	12.3123
2737.35	11.9254
2740.03	9.26766
2742.71	8.33654
2745.38	8.05663
2748.06	7.08265
2750.74	6.18325
2753.41	4.65036
2756.09	3.34545
2758.76	1.91193
2761.43	0.73561
2764.1	-0.506055
2766.77	-0.516702
2769.44	-0.976246
2772.11	-0.842227
2774.77	-1.17116
2777.44	-0.210092
2780.11	0.528853
2782.77	0.806903
2785.43	0.709355
2788.1	1.09587
2790.76	0.734064
2793.42	0.998647
2796.08	1.35829
2798.74	1.66467
2801.4	2.08463
2804.05	1.00462
2806.71	0.17729
2809.36	0.065253
2812.02	-0.128387
2814.67	0.879742
2817.32	3.72276
2819.97	6.31165
2822.62	11.7312
2825.27	18.4226
2827.92	25.1101
2830.57	34.8885
2833.22	47.0711
2835.86	58.8031
2838.51	72.4488
2841.15	85.8976
2843.79	102.494
2846.43	117.989
2849.08	135.339
2851.72	152.509
2854.36	170.461
2856.99	187.26
2859.63	203.912
2862.27	218.526
2864.9	232.056
2867.54	245.201
2870.17	257.051
2872.8	269.593
2875.43	281.745
2878.07	292.352
2880.7	303.641
2883.32	316.539
2885.95	328.409
2888.58	341.936
2891.21	357.002
2893.83	372.893
2896.46	389.862
2899.08	409.027
2901.7	429.135
2904.32	451.548
2906.94	475.384
2909.56	501.392
2912.18	526.497
2914.8	550.398
2917.42	573.494
2920.03	591.91
2922.65	608.099
2925.26	620.858
2927.88	628.097
2930.49	632.982
2933.1	631.893
2935.71	625.627
2938.32	614.471
2940.93	600.307
2943.54	581.358
2946.14	561.963
2948.75	537.994
2951.35	513.698
2953.96	487.33
2956.56	461.522
2959.16	435.36
2961.77	412.318
2964.37	390.036
2966.96	368.074
2969.56	346.624
2972.16	326.584
2974.76	308.18
2977.35	288.826
2979.95	270.475
2982.54	251.982
2985.14	234.063
2987.73	216.11
2990.32	197.568
2992.91	179.129
2995.5	160.584
2998.09	142.339
3000.68	124.969
3003.26	109.461
3005.85	93.283
3008.43	79.0394
3011.02	64.7792
3013.6	52.96
3016.19	42.4091
3018.77	32.2559
3021.35	25.9301
3023.93	20.8525
3026.5	15.8189
3029.08	12.2662
3031.66	10.7415
3034.24	9.5113
3036.81	8.96187
3039.39	9.35466
3041.96	10.133
3044.53	11.1913
3047.1	12.4048
3049.67	13.9895
3052.24	14.6454
3054.81	14.9753
3057.38	14.9087
3059.95	14.2394
3062.52	12.1471
3065.08	11.2987
3067.65	10.5082
3070.21	9.96068
3072.77	8.45293
3075.33	7.53465
3077.89	5.99869
3080.45	4.63413
3083.01	2.90853
3085.57	2.69051
3088.13	2.1295
3090.68	2.24929
3093.24	2.52285
3095.79	2.76532
3098.35	4.09376
3100.9	4.02073
3103.45	4.42582
3106	6.94514
3108.55	8.39832
3111.1	9.93855
3113.65	12.044
3116.2	12.7557
3118.75	14.3891
3121.29	15.715
3123.84	17.7629
3126.38	20.2565
3128.92	24.1336
3131.47	26.8723
3134.01	28.622
3136.55	30.8626
3139.09	33.0686
3141.63	35.1228
3144.17	37.5723
3146.7	39.7222
3149.24	41.4667