File: data/Raman/poly_smoothed/Mb_40_24_15_1x_45s_532 nm_x100_100%_600 gr_mm_01.txt
#Acq. time (s)=	45
#Accumulations=	2
#Range (cm-¹)=	200...3150
#Windows=	2
#Auto scanning=	Off
#Autofocus=	Off
#Macrospot=	Off
#AutoExposure=	Off
#Spike filter=	Multiple accum.
#Delay time (s)=	0
#Binning=	1
#Readout mode=	Signal
#DeNoise=	Off
#ICS correction=	On
#Dark correction=	Off
#Inst. Process=	Off
#Detector Gain=	Best Dynamic Range
#Detector ADC=	20 kHz
#Detector temperature (°C)=	-70.08
#Instrument=	LabRAM HR Evol
#Detector=	Synapse
#Objective=	x100
#Grating=	600 gr/mm
#ND Filter=	100%
#Laser (nm)=	532
#Hole=	100.021
#Range=	Auto
#Laser Pol.=	No
#Raman. Pol.=	No
#Laser Pol. (°)=	-0.0007625
#Raman Pol. (°)=	89.9995
#Collection=	Microscope
#StageXY=	Marzhauser
#StageZ=	Marzhauser
#X (µm)=	-2560
#Y (µm)=	-84.4
#Z (µm)=	-10.6
#Full time(mm:ss)=	3:19
#Project=
#Sample=
#Site=
#Title=	Mb_40_24_15_2x_45s_532 nm_x100_100%_600 gr_mm
#Remark=
#Date=	14.07.2022 11:47
#Acquired=	14.07.2022 11:47:23
#Base:Fit=	10.08.2022 10:47:00
#Base:Sub=	10.08.2022 10:47:12
#Filter:Polynom=	16.08.2022 10:11:48
#AxisType[0]=Intens
#AxisUnit[0]=Cnt
#AxisType[1]=Spectr
#AxisUnit[1]=1/cm
200.554	24.156
204.183	20.7575
207.813	17.448
211.439	14.7244
215.065	13.4299
218.688	12.7156
222.312	12.7627
225.933	13.6648
229.552	13.3819
233.171	13.8462
236.787	12.4054
240.402	10.0852
244.015	11.5939
247.627	11.0344
251.24	8.49671
254.849	9.66076
258.457	11.4862
262.063	12.7054
265.668	12.5145
269.271	9.38172
272.873	7.73568
276.474	6.9281
280.073	8.16899
283.671	5.99642
287.268	5.18178
290.863	5.79656
294.456	7.50532
298.049	7.25795
301.637	11.0961
305.227	13.4942
308.815	16.9868
312.402	17.7415
315.987	20.3188
319.569	22.4126
323.151	22.9473
326.733	22.2514
330.31	24.3801
333.889	23.8226
337.464	23.4111
341.039	23.2171
344.611	22.4039
348.184	20.1122
351.754	16.6303
355.324	12.273
358.89	10.7644
362.455	7.7053
366.021	6.83561
369.584	3.16936
373.145	2.37466
376.707	0.197688
380.265	0.81512
383.822	-0.646826
387.378	0.834957
390.934	4.15223
394.487	4.87088
398.038	5.98156
401.588	7.73434
405.137	9.95374
408.685	13.2748
412.23	13.6107
415.775	14.9695
419.318	17.9817
422.86	19.1083
426.401	17.5281
429.94	17.1818
433.478	16.4615
437.012	17.1483
440.547	16.9211
444.081	16.5539
447.613	17.7815
451.142	18.2699
454.672	17.6305
458.2	14.2232
461.725	15.2176
465.251	14.0409
468.775	12.1121
472.296	13.1089
475.817	13.2136
479.335	14.889
482.854	14.685
486.37	16.2552
489.886	18.3305
493.398	19.2425
496.91	20.6721
500.422	23.2377
503.93	25.2653
507.438	27.3346
510.946	28.4533
514.45	33.3872
517.954	39.9612
521.456	44.7515
524.956	48.7763
528.456	50.4992
531.956	50.3664
535.452	51.8425
538.947	49.4475
542.441	47.2641
545.934	45.8227
549.425	43.7613
552.915	39.9788
556.403	37.0927
559.889	34.4924
563.375	30.6455
566.859	25.9422
570.342	21.5295
573.824	14.8721
577.303	10.302
580.782	7.47926
584.26	5.56015
587.734	5.53288
591.21	2.60353
594.684	1.27744
598.154	2.60955
601.626	5.84528
605.094	5.20141
608.562	6.19957
612.027	8.98269
615.493	9.16074
618.956	11.1352
622.419	13.0487
625.879	14.6523
629.338	17.1098
632.797	18.6045
636.254	19.956
639.708	17.7485
643.162	16.449
646.614	16.4462
650.067	16.3687
653.516	14.9211
656.964	12.1374
660.411	10.8062
663.857	10.7774
667.301	8.63389
670.744	6.92557
674.186	7.17559
677.626	5.57407
681.065	8.21777
684.503	10.9034
687.939	13.2592
691.372	13.5618
694.806	17.2835
698.239	16.4515
701.67	16.9941
705.098	19.4368
708.526	22.8498
711.954	24.7991
715.378	26.4232
718.802	26.1871
722.226	25.4367
725.646	23.6891
729.067	22.9775
732.484	22.9628
735.902	23.0234
739.317	23.8558
742.731	26.245
746.145	28.8298
749.556	31.5076
752.966	36.0044
756.377	40.8455
759.784	44.7849
763.19	48.8514
766.594	54.4479
770	57.842
773.402	60.2566
776.803	61.1532
780.202	64.5001
783.6	65.345
786.997	69.3996
790.393	73.4378
793.787	76.7553
797.18	78.2135
800.572	78.7776
803.963	77.5472
807.35	74.589
810.738	73.1919
814.125	72.4357
817.51	71.6717
820.894	73.3573
824.275	76.6259
827.657	80.5116
831.037	85.8124
834.414	91.7134
837.792	94.0225
841.167	97.2834
844.542	100.152
847.914	101.209
851.287	102.074
854.656	100.285
858.026	97.9645
861.393	94.2346
864.761	92.4915
868.125	89.1189
871.489	88.5834
874.85	87.3014
878.213	81.4509
881.572	75.1951
884.931	68.9484
888.287	62.0243
891.643	55.2158
894.997	50.6275
898.352	49.6938
901.704	49.0187
905.055	53.848
908.404	56.5785
911.75	60.4154
915.097	62.3146
918.443	64.6549
921.787	64.9899
925.13	66.6768
928.472	67.9263
931.813	67.3129
935.15	65.7893
938.488	66.7399
941.825	62.7963
945.158	58.1408
948.493	54.0942
951.824	52.5989
955.156	47.6407
958.486	42.8537
961.814	39.1747
965.142	39.2985
968.467	40.7762
971.79	41.996
975.115	44.3178
978.436	48.5413
981.756	50.6477
985.077	52.255
988.394	53.1221
991.71	52.4363
995.025	52.8882
998.341	53.8569
1001.65	52.0505
1004.97	51.9919
1008.28	55.857
1011.58	59.2561
1014.89	66.2526
1018.2	72.7694
1021.5	76.4986
1024.81	79.6468
1028.11	86.0798
1031.41	96.492
1034.71	101.557
1038.01	107.263
1041.31	112.982
1044.6	121.062
1047.9	125.921
1051.19	127.375
1054.48	127.644
1057.77	126.781
1061.06	123.259
1064.35	119.074
1067.64	113.256
1070.93	106.785
1074.21	96.4051
1077.49	89.364
1080.78	81.1888
1084.06	73.3602
1087.34	69.2952
1090.61	67.7227
1093.89	67.5115
1097.17	67.9313
1100.44	68.3204
1103.71	69.472
1106.99	69.0252
1110.26	70.3108
1113.52	69.5359
1116.79	67.2263
1120.06	64.7564
1123.32	62.0687
1126.59	59.9594
1129.85	54.296
1133.11	51.9398
1136.37	50.5802
1139.63	46.5609
1142.89	43.778
1146.15	40.3417
1149.4	35.9959
1152.66	28.5538
1155.91	23.1017
1159.16	18.5489
1162.41	13.7389
1165.66	10.2609
1168.91	9.13781
1172.16	8.45475
1175.4	7.07076
1178.65	7.99551
1181.89	8.30356
1185.13	9.85601
1188.37	8.64503
1191.61	8.22426
1194.85	9.68175
1198.08	10.4542
1201.32	12.5014
1204.55	15.9219
1207.79	21.1094
1211.02	26.6083
1214.25	35.2706
1217.48	41.126
1220.71	47.318
1223.93	55.9554
1227.16	62.1981
1230.38	66.3436
1233.6	71.8099
1236.83	78.243
1240.05	82.8331
1243.26	89.8135
1246.48	95.8658
1249.7	97.2688
1252.92	100.862
1256.13	102.176
1259.34	107.883
1262.55	112.43
1265.76	118.295
1268.97	124.684
1272.18	132.423
1275.39	140.12
1278.59	147.099
1281.8	157.487
1285	164.478
1288.2	170.939
1291.4	177.615
1294.6	182.325
1297.8	186.123
1301	189.367
1304.19	191.73
1307.39	191.599
1310.58	190.188
1313.77	188.16
1316.96	184.249
1320.15	179.61
1323.34	175.349
1326.53	166.361
1329.72	157.911
1332.9	150.164
1336.08	145.49
1339.27	142.395
1342.45	136.825
1345.63	135.488
1348.8	132.461
1351.98	132.02
1355.16	129.93
1358.33	127.807
1361.51	124.555
1364.68	123.695
1367.85	124.473
1371.02	125.467
1374.19	124.783
1377.36	126.26
1380.52	128.756
1383.69	133.053
1386.85	136.073
1390.02	141.046
1393.18	145.984
1396.34	150.403
1399.5	155.381
1402.65	161.94
1405.81	171.609
1408.97	183.266
1412.12	198.567
1415.27	214.975
1418.43	231.734
1421.58	249.629
1424.73	268.623
1427.87	286.974
1431.02	301.012
1434.17	313.367
1437.31	323.946
1440.46	330.147
1443.6	332.097
1446.74	329.717
1449.88	324.395
1453.02	316.27
1456.16	305.764
1459.29	290.518
1462.43	272.518
1465.56	253.503
1468.69	229.903
1471.83	206.691
1474.95	182.088
1478.08	160.407
1481.21	142.637
1484.34	124.067
1487.47	107.135
1490.59	92.6336
1493.71	79.8346
1496.84	69.1525
1499.96	60.9124
1503.07	55.1124
1506.19	49.0683
1509.31	47.2603
1512.43	44.0987
1515.54	42.1166
1518.65	42.1344
1521.77	42.7437
1524.88	46.3604
1527.99	48.4608
1531.1	49.3049
1534.21	52.4123
1537.31	55.9687
1540.42	60.1737
1543.52	64.0374
1546.63	66.3718
1549.73	70.4855
1552.83	73.36
1555.93	77.5658
1559.03	80.7602
1562.12	84.2567
1565.22	87.4325
1568.31	91.2835
1571.41	97.5214
1574.5	104.189
1577.59	111.082
1580.68	118.313
1583.77	126.49
1586.86	133.575
1589.95	139.578
1593.03	145.514
1596.11	150.929
1599.2	155.495
1602.28	159.2
1605.36	161.055
1608.44	163.747
1611.52	166.547
1614.6	169.09
1617.67	169.965
1620.75	171.002
1623.82	171.161
1626.89	173.053
1629.96	173.622
1633.04	173.807
1636.11	173.906
1639.17	174.797
1642.24	175.292
1645.31	177.314
1648.37	178.289
1651.43	177.316
1654.5	174.561
1657.56	171.673
1660.62	166.494
1663.67	160.174
1666.73	151.206
1669.79	142.792
1672.84	133.134
1675.9	123.861
1678.95	111.821
1682	101.449
1685.05	93.1506
1688.1	84.0368
1691.15	74.4189
1694.2	65.7416
1697.25	59.3567
1700.29	53.6202
1703.33	48.2877
1706.38	42.5846
1709.42	39.6856
1712.46	36.2735
1715.5	34.9314
1718.54	34.2585
1721.57	33.4429
1724.61	30.5161
1727.64	29.651
1730.68	28.7547
1733.71	26.9826
1736.74	24.6546
1739.77	22.5781
1742.8	20.4569
1745.83	17.7334
1748.85	16.6459
1751.88	15.1725
1754.91	13.3249
1757.93	12.656
1760.95	10.447
1763.97	9.20523
1766.99	8.15443
1770.01	6.48467
1773.03	6.51009
1776.04	4.68801
1779.06	3.31445
1782.07	2.38218
1785.09	1.71238
1788.1	2.39581
1791.11	1.16012
1794.12	0.818458
1797.13	-0.837801
1800.13	-1.62573
1803.14	-1.33281
1806.15	-1.45497
1809.15	-1.20071
1812.15	-1.80923
1815.16	-1.80853
1818.15	-2.56255
1821.16	-1.60669
1824.15	-0.631269
1827.15	-0.0339654
1830.15	-0.730051
1833.14	0.746378
1836.14	1.5287
1839.13	2.28371
1842.12	1.57752
1845.11	1.06554
1848.1	1.70408
1851.09	2.76307
1854.08	3.6559
1857.06	5.09759
1860.05	5.02479
1863.03	5.432
1866.01	5.32157
1869	5.808
1871.98	5.56351
1874.96	7.1456
1877.93	7.69678
1880.91	6.97596
1882.47	5.85388
1885.46	6.07204
1888.44	7.27346
1891.43	8.48685
1894.42	9.75908
1897.4	9.60453
1900.39	8.72851
1903.37	8.0562
1906.35	6.68464
1909.33	6.57648
1912.31	6.3281
1915.29	5.8466
1918.26	8.05124
1921.24	9.25038
1924.21	7.26499
1927.19	7.66734
1930.16	6.753
1933.13	7.02378
1936.1	7.29299
1939.07	7.29335
1942.04	5.84038
1945	6.62068
1947.97	7.44433
1950.93	7.00664
1953.9	5.90484
1956.86	7.81112
1959.82	8.26102
1962.78	7.67969
1965.74	8.58257
1968.7	8.34668
1971.65	8.89663
1974.61	9.2605
1977.57	8.56947
1980.52	9.47137
1983.47	10.9203
1986.42	11.5995
1989.37	12.075
1992.32	11.2792
1995.27	11.5251
1998.22	10.3848
2001.17	9.76681
2004.11	9.74829
2007.05	9.44116
2010	9.7252
2012.94	9.00789
2015.88	8.70865
2018.82	10.1575
2021.76	10.4855
2024.7	10.109
2027.63	10.7578
2030.57	9.6329
2033.5	9.90827
2036.44	12.2761
2039.37	14.2189
2042.3	16.0152
2045.23	17.7322
2048.16	18.204
2051.08	18.2701
2054.01	19.4113
2056.94	20.9474
2059.86	21.7367
2062.79	21.6369
2065.71	22.9136
2068.63	23.6081
2071.55	24.0574
2074.47	26.6718
2077.39	28.7725
2080.31	29.996
2083.22	32.6686
2086.13	35.5127
2089.05	37.8339
2091.96	40.9422
2094.87	43.0436
2097.78	45.3663
2100.69	47.7872
2103.6	52.4875
2106.51	58.4545
2109.42	63.0624
2112.32	66.3371
2115.23	70.5985
2118.13	72.967
2121.03	74.8668
2123.93	80.8661
2126.83	85.9813
2129.73	91.1934
2132.63	96.9168
2135.53	102.72
2138.42	107.619
2141.32	114.098
2144.21	119.085
2147.1	125.35
2150	130.334
2152.89	136.378
2155.78	142.277
2158.66	146.305
2161.55	149.839
2164.44	152.946
2167.32	154.916
2170.21	157.401
2173.09	158.246
2175.97	158.828
2178.85	157.469
2181.73	152.022
2184.61	148.942
2187.49	146.017
2190.37	140.997
2193.24	136.529
2196.12	132.391
2198.99	126.366
2201.87	119.959
2204.74	115.317
2207.61	108.02
2210.48	103.092
2213.35	96.6618
2216.21	90.2687
2219.08	85.7345
2221.95	80.7898
2224.81	75.4493
2227.67	71.7282
2230.54	65.8878
2233.4	63.0307
2236.26	58.7631
2239.11	55.8974
2241.97	52.079
2244.83	48.2373
2247.69	46.2653
2250.54	42.9506
2253.4	42.1576
2256.25	40.8131
2259.1	38.3136
2261.95	36.1562
2264.8	34.934
2267.65	33.7099
2270.5	32.2377
2273.34	31.5013
2276.19	31.3542
2279.03	28.4228
2281.88	26.2043
2284.72	24.5495
2287.56	23.6593
2290.4	21.2306
2293.24	17.3896
2296.08	16.5767
2298.92	15.1641
2301.76	16.5625
2304.59	17.6927
2307.43	15.8276
2310.26	15.2747
2313.09	14.2046
2315.92	13.8516
2318.75	12.9762
2321.58	12.3394
2324.41	11.5529
2327.24	11.3043
2330.06	10.5314
2332.89	11.1783
2335.71	10.6404
2338.54	9.66095
2341.36	8.9094
2344.18	7.74759
2347	5.81467
2349.82	3.48411
2352.64	1.33115
2355.45	0.242976
2358.27	-1.22919
2361.08	-1.39504
2363.9	-1.79956
2366.71	-0.129325
2369.52	0.418218
2372.33	1.91897
2375.14	1.48684
2377.95	1.92644
2380.76	1.75205
2383.57	3.08386
2386.37	4.57137
2389.18	4.5573
2391.98	5.94197
2394.79	7.90432
2397.59	9.18753
2400.39	9.40477
2403.19	10.5435
2405.99	10.54
2408.78	11.4005
2411.58	10.6605
2414.38	9.11517
2417.17	8.51477
2419.97	8.14536
2422.76	9.05041
2425.55	9.79239
2428.34	8.67483
2431.13	7.96412
2433.92	8.50717
2436.71	7.63451
2439.49	8.29064
2442.28	8.47478
2445.06	9.11986
2447.85	9.08722
2450.63	8.90857
2453.41	9.2237
2456.19	8.41741
2458.97	9.24785
2461.75	9.08514
2464.53	8.4196
2467.31	6.74589
2470.08	7.10051
2472.86	6.51642
2475.63	5.45874
2478.4	5.0243
2481.17	4.11163
2483.94	4.21559
2486.72	5.22929
2489.48	6.00961
2492.25	5.5376
2495.02	3.41901
2497.79	2.70298
2500.55	3.16992
2503.31	3.89021
2506.08	3.42516
2508.84	3.78409
2511.6	3.42343
2514.36	3.23349
2517.12	1.89296
2519.88	1.60684
2522.63	1.00165
2525.39	1.79281
2528.14	2.28529
2530.9	1.37201
2533.65	1.48894
2536.4	1.8919
2539.15	1.60376
2541.9	2.21391
2544.65	3.14734
2547.4	5.35029
2550.15	6.02304
2552.89	6.7106
2555.64	7.9437
2558.38	7.42988
2561.12	7.99157
2563.87	8.2366
2566.61	8.10778
2569.35	8.03292
2572.09	8.34623
2574.83	7.97026
2577.56	7.51955
2580.3	6.91079
2583.04	6.47619
2585.77	6.13422
2588.5	6.69236
2591.23	6.9717
2593.97	7.57649
2596.7	7.14809
2599.43	7.76645
2602.15	7.92724
2604.88	8.66929
2607.61	9.15711
2610.33	10.1323
2613.06	10.463
2615.78	11.4572
2618.51	10.8166
2621.23	12.0812
2623.95	11.8286
2626.67	12.2181
2629.39	11.0375
2632.1	9.8566
2634.82	9.82512
2637.54	9.67516
2640.25	9.64449
2642.97	9.76851
2645.68	9.04504
2648.39	8.72987
2651.1	9.26616
2653.81	9.70183
2656.52	9.66252
2659.23	8.34312
2661.94	8.43062
2664.64	9.29069
2667.35	9.90252
2670.05	9.64967
2672.76	10.5156
2675.46	12.072
2678.16	12.1516
2680.86	13.1341
2683.56	12.9495
2686.26	14.2733
2688.96	15.3266
2691.65	16.6318
2694.35	18.2116
2697.04	20.349
2699.74	21.8547
2702.43	24.4124
2705.12	26.0523
2707.81	28.3876
2710.5	29.7163
2713.19	30.7683
2715.88	32.2408
2718.57	34.1184
2721.25	35.0979
2723.94	34.7678
2726.62	34.4296
2729.3	35.4024
2731.99	36.0633
2734.67	34.7872
2737.35	33.0489
2740.03	31.9844
2742.71	29.5261
2745.38	26.7452
2748.06	24.2987
2750.74	22.06
2753.41	20.1203
2756.09	18.1628
2758.76	16.0685
2761.43	12.9671
2764.1	10.4697
2766.77	8.81295
2769.44	5.97799
2772.11	3.73187
2774.77	3.55889
2777.44	1.98413
2780.11	1.35869
2782.77	0.186957
2785.43	0.342969
2788.1	-0.0437687
2790.76	0.781426
2793.42	1.79545
2796.08	4.75138
2798.74	5.4751
2801.4	6.25089
2804.05	6.41888
2806.71	8.10089
2809.36	5.87281
2812.02	5.52053
2814.67	8.79597
2817.32	14.642
2819.97	25.1784
2822.62	39.7462
2825.27	58.3393
2827.92	80.304
2830.57	105.652
2833.22	131.35
2835.86	159.275
2838.51	188.219
2841.15	216.791
2843.79	243.323
2846.43	271.295
2849.08	299.496
2851.72	332.09
2854.36	367.066
2856.99	402.047
2859.63	433.714
2862.27	460.395
2864.9	485.136
2867.54	504.768
2870.17	520.837
2872.8	535.363
2875.43	547.248
2878.07	559.504
2880.7	572.196
2883.32	585.78
2885.95	600.74
2888.58	613.927
2891.21	626.512
2893.83	637.839
2896.46	648.776
2899.08	659.18
2901.7	669.874
2904.32	681.898
2906.94	696.805
2909.56	712.903
2912.18	734.748
2914.8	758.658
2917.42	782.888
2920.03	804.135
2922.65	819.536
2925.26	828.164
2927.88	832.613
2930.49	832.539
2933.1	824.716
2935.71	811.553
2938.32	792.721
2940.93	767.36
2943.54	739.539
2946.14	709.793
2948.75	678.389
2951.35	644.279
2953.96	608.184
2956.56	570.493
2959.16	537.136
2961.77	502.97
2964.37	470.759
2966.96	443.106
2969.56	416.946
2972.16	392.507
2974.76	370.697
2977.35	350.765
2979.95	330.043
2982.54	309.412
2985.14	288.513
2987.73	266.702
2990.32	244.449
2992.91	223.298
2995.5	200.039
2998.09	177.003
3000.68	155.485
3003.26	134.14
3005.85	115.609
3008.43	100.292
3011.02	87.8625
3013.6	75.3558
3016.19	64.5807
3018.77	52.8063
3021.35	46.1794
3023.93	40.1242
3026.5	32.7464
3029.08	28.9851
3031.66	25.7757
3034.24	24.5829
3036.81	24.3451
3039.39	24.768
3041.96	24.9722
3044.53	26.1437
3047.1	27.3482
3049.67	27.971
3052.24	28.0451
3054.81	28.0599
3057.38	27.3592
3059.95	25.2189
3062.52	24.2788
3065.08	21.9439
3067.65	20.2163
3070.21	19.2698
3072.77	18.2039
3075.33	16.6754
3077.89	13.7609
3080.45	10.5262
3083.01	7.71475
3085.57	5.63369
3088.13	3.15551
3090.68	0.329569
3093.24	0.227853
3095.79	-0.510174
3098.35	-0.791938
3100.9	-1.04654
3103.45	-0.11499
3106	0.62584
3108.55	3.00102
3111.1	4.47498
3113.65	5.8192
3116.2	8.52262
3118.75	11.3008
3121.29	13.1722
3123.84	16.0958
3126.38	18.5696
3128.92	20.4644
3131.47	23.0638
3134.01	26.1147
3136.55	28.9724
3139.09	31.8987
3141.63	34.0347
3144.17	36.0655
3146.7	37.4419
3149.24	39.0815