File: data/Raman/poly_smoothed/Mb_40_y_07_1x_45s_532 nm_x100_100%_600 gr_mm_01.txt
#Acq. time (s)=	45
#Accumulations=	2
#Range (cm-¹)=	200...3150
#Windows=	2
#Auto scanning=	Off
#Autofocus=	Off
#Macrospot=	Off
#AutoExposure=	Off
#Spike filter=	Multiple accum.
#Delay time (s)=	0
#Binning=	1
#Readout mode=	Signal
#DeNoise=	Off
#ICS correction=	On
#Dark correction=	Off
#Inst. Process=	Off
#Detector Gain=	Best Dynamic Range
#Detector ADC=	20 kHz
#Detector temperature (°C)=	-69.85
#Instrument=	LabRAM HR Evol
#Detector=	Synapse
#Objective=	x100
#Grating=	600 gr/mm
#ND Filter=	100%
#Laser (nm)=	532
#Hole=	100.021
#Range=	Auto
#Laser Pol.=	No
#Raman. Pol.=	No
#Laser Pol. (°)=	-0.0007625
#Raman Pol. (°)=	89.9995
#Collection=	Microscope
#StageXY=	Marzhauser
#StageZ=	Marzhauser
#X (µm)=	-1041.8
#Y (µm)=	690.3
#Z (µm)=	584.15
#Full time(mm:ss)=	3:18
#Project=
#Sample=
#Site=
#Title=	Mb_40_y_07_2x_45s_532 nm_x100_100%_600 gr_mm
#Remark=
#Date=	19.07.2022 09:23
#Acquired=	19.07.2022 09:23:49
#Base:Fit=	10.08.2022 10:52:48
#Base:Sub=	10.08.2022 10:52:53
#Filter:Polynom=	16.08.2022 10:09:04
#AxisType[0]=Intens
#AxisUnit[0]=Cnt
#AxisType[1]=Spectr
#AxisUnit[1]=1/cm
200.423	31.3204
204.052	26.75
207.682	23.2498
211.308	21.6882
214.935	19.5468
218.558	17.5275
222.18	14.806
225.802	14.4062
229.421	11.0783
233.039	9.87902
236.657	7.83344
240.272	6.89726
243.885	6.1789
247.497	6.23069
251.11	5.77746
254.719	4.52279
258.327	3.90398
261.933	5.09683
265.538	6.76439
269.141	8.56581
272.744	11.0755
276.344	11.6522
279.944	11.8582
283.542	12.0346
287.138	13.8906
290.733	15.4945
294.327	16.915
297.919	18.3001
301.508	18.8658
305.098	18.4018
308.686	18.5457
312.273	19.593
315.858	19.3443
319.44	18.1546
323.022	17.2592
326.604	15.5383
330.181	15.2175
333.76	13.5046
337.335	11.3179
340.91	10.696
344.483	9.31292
348.055	8.44116
351.625	7.53309
355.195	5.15686
358.762	5.37069
362.329	5.42663
365.893	6.61891
369.455	6.11791
373.017	8.50855
376.578	8.96188
380.137	10.5205
383.694	12.1584
387.249	14.6361
390.806	15.6459
394.359	17.676
397.91	19.8527
401.46	21.0628
405.009	20.3132
408.557	20.2284
412.103	19.7702
415.647	19.7098
419.191	17.8244
422.733	16.0255
426.273	16.1796
429.812	14.6295
433.35	13.9176
436.885	11.2352
440.42	9.04766
443.954	9.13012
447.486	11.9465
451.015	11.1559
454.545	10.5095
458.073	11.2723
461.598	10.6152
465.124	10.8794
468.648	11.1183
472.169	11.5087
475.69	11.5884
479.208	13.63
482.727	14.0344
486.243	14.1782
489.759	15.3502
493.272	16.7917
496.783	17.4461
500.295	18.6554
503.804	19.9031
507.311	20.4645
510.819	20.206
514.324	19.5335
517.827	19.7765
521.329	19.3311
524.83	17.983
528.329	17.4393
531.829	17.6239
535.326	16.417
538.821	13.4498
542.315	11.8632
545.808	10.993
549.299	9.81364
552.789	7.76149
556.278	6.46326
559.763	4.76544
563.249	4.3937
566.733	3.00898
570.217	1.61457
573.699	2.4301
577.177	3.58032
580.656	2.60168
584.134	3.49324
587.609	3.2839
591.084	2.45456
594.558	2.2452
598.029	1.40482
601.5	2.2421
604.968	2.30797
608.437	2.32675
611.902	2.19223
615.368	3.79397
618.831	4.64565
622.294	3.07106
625.755	2.98899
629.213	4.17171
632.673	4.6912
636.129	5.19341
639.584	6.06368
643.037	8.08323
646.491	8.42427
649.942	9.86056
653.392	10.8743
656.84	12.3132
660.287	14.668
663.732	17.2002
667.177	17.7284
670.62	20.0926
674.061	20.5351
677.502	21.104
680.941	21.4064
684.379	22.571
687.815	24.3007
691.248	26.0365
694.682	27.8936
698.115	27.7777
701.546	29.1253
704.974	29.4813
708.402	29.4754
711.83	32.4817
715.254	34.6771
718.679	34.9486
722.102	34.6035
725.522	34.9321
728.943	35.429
732.361	35.1614
735.779	36.3791
739.194	39.173
742.608	40.3467
746.022	43.0391
749.433	44.2028
752.843	45.5834
756.254	47.8792
759.661	50.2135
763.067	53.5871
766.471	57.9246
769.877	61.2653
773.279	62.4642
776.68	64.3629
780.079	66.035
783.478	67.9614
786.875	70.5822
790.27	71.687
793.665	72.716
797.058	73.0067
800.45	71.5023
803.84	68.0531
807.23	67.15
810.616	67.4068
814.002	67.0677
817.388	66.634
820.772	65.7099
824.153	65.2282
827.535	65.4222
830.915	64.4507
834.292	63.7351
837.67	62.7759
841.047	61.9804
844.42	60.5709
847.794	58.46
851.165	55.2844
854.534	53.8778
857.905	52.3881
861.272	51.1304
864.639	49.1187
868.004	48.3535
871.367	46.7306
874.731	46.4186
878.092	45.4524
881.451	43.6449
884.809	41.9881
888.166	41.3213
891.522	41.4424
894.878	41.5345
898.231	41.0649
901.583	40.8673
904.934	40.4734
908.283	41.9412
911.631	40.8315
914.976	40.2122
918.322	39.6746
921.666	37.9028
925.009	37.6205
928.351	35.3824
931.692	34.1216
935.029	34.1631
938.367	34.0693
941.704	33.3463
945.038	33.8572
948.372	33.4579
951.705	33.3399
955.035	33.7232
958.366	33.5478
961.693	32.0289
965.021	31.7862
968.346	30.5201
971.67	30.1942
974.995	28.4472
978.316	27.6407
981.638	28.0615
984.957	28.2081
988.274	27.7505
991.59	26.3022
994.907	23.2637
998.221	20.2065
1001.53	17.2545
1004.85	14.8952
1008.16	16.5702
1011.46	21.4964
1014.77	31.256
1018.08	44.5491
1021.38	55.364
1024.69	69.1887
1027.99	80.6524
1031.29	90.5201
1034.59	99.4073
1037.89	104.464
1041.19	106.618
1044.48	108.441
1047.78	109.208
1051.07	106.439
1054.36	102.027
1057.66	97.1491
1060.94	89.1106
1064.23	82.0192
1067.52	69.8716
1070.81	58.1354
1074.09	43.8864
1077.38	30.064
1080.66	19.6969
1083.94	9.7211
1087.22	5.47911
1090.5	6.87172
1093.77	8.46504
1097.05	9.98584
1100.32	11.0395
1103.6	13.0083
1106.87	14.0789
1110.14	14.8488
1113.41	15.6315
1116.67	15.2354
1119.94	14.6883
1123.21	15.3081
1126.47	14.9388
1129.73	14.1129
1133	12.7974
1136.26	11.7864
1139.52	11.823
1142.77	12.2629
1146.03	13.1873
1149.29	11.9375
1152.54	11.4914
1155.79	9.2716
1159.04	7.9929
1162.3	8.41997
1165.55	6.8805
1168.79	6.65705
1172.04	6.02693
1175.28	4.90412
1178.53	4.94393
1181.77	6.26861
1185.01	8.65339
1188.25	8.57081
1191.49	9.31129
1194.73	8.20535
1197.97	9.78887
1201.2	9.68094
1204.44	9.65676
1207.67	10.1718
1210.9	10.6747
1214.13	12.8422
1217.36	16.8512
1220.59	19.4271
1223.82	21.5892
1227.04	23.7963
1230.26	25.1362
1233.49	26.7631
1236.71	28.4054
1239.93	30.4052
1243.15	31.5639
1246.37	33.1167
1249.58	35.3784
1252.8	37.5603
1256.01	37.7154
1259.23	40.827
1262.44	42.73
1265.65	42.3528
1268.86	42.8966
1272.07	43.6984
1275.27	44.8055
1278.48	46.3818
1281.68	46.8815
1284.89	48.0664
1288.09	49.9822
1291.29	51.9977
1294.49	53.8292
1297.69	54.2807
1300.88	54.4335
1304.08	55.2669
1307.27	56.078
1310.47	56.5584
1313.66	55.7959
1316.85	55.2639
1320.04	55.5578
1323.23	57.6552
1326.41	56.4877
1329.6	57.2623
1332.78	55.0886
1335.97	54.3263
1339.15	54.38
1342.33	51.8634
1345.51	50.0261
1348.69	48.9862
1351.87	47.4198
1355.04	45.3387
1358.22	43.8762
1361.39	42.0413
1364.57	41.2995
1367.74	38.604
1370.91	37.0078
1374.07	35.4202
1377.24	35.9341
1380.41	35.8067
1383.57	35.3519
1386.74	32.9844
1389.9	33.4881
1393.06	33.3704
1396.22	33.5642
1399.38	35.2916
1402.54	35.6498
1405.7	37.0158
1408.85	38.3377
1412.01	40.6629
1415.16	42.331
1418.31	45.409
1421.46	47.4457
1424.61	50.6076
1427.76	53.455
1430.91	56.2071
1434.05	58.9772
1437.2	60.7494
1440.34	63.8041
1443.49	65.1819
1446.63	68.2074
1449.77	69.6629
1452.91	70.2121
1456.04	70.584
1459.18	69.3305
1462.31	66.1454
1465.45	65.0735
1468.58	63.3744
1471.71	61.1954
1474.84	58.9611
1477.97	55.96
1481.1	52.2229
1484.23	48.2564
1487.35	45.7712
1490.48	44.0041
1493.6	42.4557
1496.72	39.7003
1499.84	36.9967
1502.96	35.3876
1506.08	31.4202
1509.2	29.9336
1512.31	28.0031
1515.43	26.3314
1518.54	24.4345
1521.66	24.1529
1524.77	23.1949
1527.88	21.7489
1530.99	21.9726
1534.09	21.3773
1537.2	21.0146
1540.31	20.0414
1543.41	22.4526
1546.51	23.7085
1549.62	24.5844
1552.72	26.0955
1555.82	26.5835
1558.91	27.272
1562.01	29.2244
1565.11	32.1194
1568.2	34.3095
1571.3	36.6958
1574.39	37.6894
1577.48	39.3417
1580.57	38.6638
1583.66	40.1001
1586.75	41.169
1589.83	42.4477
1592.92	42.312
1596	44.0873
1599.09	44.1464
1602.17	43.2312
1605.25	42.8997
1608.33	43.2925
1611.41	42.235
1614.48	42.1868
1617.56	42.883
1620.64	44.7244
1623.71	44.841
1626.78	45.5508
1629.86	45.7408
1632.92	45.4897
1635.99	48.2491
1639.06	48.5443
1642.13	50.0737
1645.19	51.2774
1648.26	51.6518
1651.32	51.8837
1654.38	51.9485
1657.45	52.9123
1660.51	52.6118
1663.57	49.9086
1666.62	48.7944
1669.68	47.9042
1672.73	46.5632
1675.79	44.3586
1678.84	41.304
1681.89	39.9871
1684.94	35.9502
1687.99	33.5544
1691.04	31.1511
1694.09	27.9732
1697.14	24.8422
1700.18	21.3065
1703.22	18.9093
1706.27	16.2568
1709.31	14.1072
1712.35	12.6141
1715.39	10.2342
1718.43	8.59504
1721.46	6.86484
1724.5	5.72033
1727.53	4.93217
1730.57	4.31629
1733.6	3.80326
1736.63	2.65426
1739.66	1.91749
1742.69	3.04249
1745.72	4.67787
1748.74	5.07239
1751.77	4.63642
1754.8	4.50656
1757.82	5.54156
1760.84	4.88539
1763.86	5.35171
1766.88	5.4877
1769.9	5.06588
1772.92	4.3847
1775.93	4.04907
1778.95	3.95337
1781.96	3.26933
1784.98	3.29909
1787.99	3.09262
1791	2.98096
1794.01	3.46218
1797.02	2.84548
1800.03	3.39541
1803.03	3.79251
1806.04	4.22733
1809.04	3.79651
1812.04	3.42693
1815.05	3.26066
1818.05	4.45816
1821.05	5.15803
1824.05	4.57555
1827.04	4.51646
1830.04	4.49322
1833.03	4.49053
1836.03	4.04046
1839.02	3.12069
1842.01	2.74937
1845	1.49069
1847.99	0.682182
1850.98	0.843857
1853.97	1.21563
1856.95	1.49386
1859.94	2.20527
1862.92	2.74522
1865.91	3.96454
1868.89	3.3065
1871.87	2.90081
1874.85	3.31116
1877.83	4.25059
1880.8	4.25499
1882.56	3.99497
1885.54	4.73583
1888.53	5.49631
1891.52	6.04543
1894.5	5.05217
1897.49	3.56195
1900.47	3.42628
1903.45	4.02837
1906.43	3.55872
1909.41	3.45273
1912.39	3.13861
1915.37	3.03505
1918.35	3.27439
1921.32	3.51102
1924.3	3.11185
1927.27	3.13503
1930.24	3.02904
1933.21	3.15232
1936.18	3.80028
1939.15	3.63169
1942.12	3.5068
1945.09	4.59615
1948.05	4.46677
1951.02	4.88422
1953.98	3.44751
1956.94	3.37041
1959.91	3.00977
1962.87	1.91084
1965.82	0.687507
1968.78	0.167223
1971.74	1.10934
1974.7	1.04606
1977.65	0.855728
1980.6	-0.163169
1983.56	-0.434942
1986.51	0.124393
1989.46	0.340831
1992.41	0.165536
1995.36	1.91772
1998.3	2.75115
2001.25	4.1852
2004.2	5.11192
2007.14	6.15044
2010.08	5.99292
2013.02	6.77941
2015.97	7.185
2018.9	7.2224
2021.84	6.73403
2024.78	7.02451
2027.72	5.98908
2030.65	5.63799
2033.59	4.80085
2036.52	3.94567
2039.45	4.13642
2042.38	3.65505
2045.31	2.52267
2048.24	1.93059
2051.17	1.22737
2054.1	1.57982
2057.02	2.52479
2059.95	2.55092
2062.87	3.6541
2065.79	4.32285
2068.71	5.13156
2071.63	5.9692
2074.55	6.42771
2077.47	8.49359
2080.39	9.24408
2083.3	10.1773
2086.22	11.497
2089.13	12.8963
2092.05	14.6255
2094.96	15.525
2097.87	17.3407
2100.78	18.5504
2103.69	19.7394
2106.59	21.6045
2109.5	23.8024
2112.41	24.7802
2115.31	26.6866
2118.21	28.7206
2121.12	31.6615
2124.02	33.3232
2126.92	35.8763
2129.82	37.8139
2132.71	39.9816
2135.61	42.205
2138.51	45.2204
2141.4	47.8757
2144.29	51.4847
2147.19	54.0526
2150.08	56.5074
2152.97	58.5974
2155.86	61.8706
2158.75	64.0498
2161.64	65.5904
2164.52	66.5879
2167.41	67.6109
2170.29	67.1469
2173.17	66.6828
2176.06	66.2091
2178.94	65.5578
2181.82	64.0337
2184.7	62.7024
2187.57	61.3686
2190.45	59.4639
2193.33	57.3031
2196.2	54.85
2199.08	52.9076
2201.95	50.9504
2204.82	48.4873
2207.69	46.2342
2210.56	43.7257
2213.43	41.5223
2216.3	38.9925
2219.16	37.1391
2222.03	35.037
2224.89	33.4547
2227.75	30.2535
2230.62	27.6187
2233.48	25.4186
2236.34	22.9242
2239.2	21.1542
2242.06	20.0621
2244.91	18.2057
2247.77	17.2139
2250.62	15.7737
2253.48	15.5226
2256.33	15.8809
2259.18	14.9629
2262.03	14.4948
2264.88	14.41
2267.73	13.9448
2270.58	13.6994
2273.43	13.0719
2276.27	12.2247
2279.12	11.2009
2281.96	10.3504
2284.8	9.22659
2287.64	8.17472
2290.49	6.21849
2293.32	4.53017
2296.16	3.47148
2299	3.11972
2301.84	3.59116
2304.67	4.82424
2307.51	5.1843
2310.34	5.70249
2313.17	5.58903
2316	6.01157
2318.83	6.29553
2321.66	7.58378
2324.49	7.90264
2327.32	6.72462
2330.15	6.68781
2332.97	6.52989
2335.79	6.76003
2338.62	6.11825
2341.44	5.11057
2344.26	4.31099
2347.08	4.27546
2349.9	3.3121
2352.72	1.8595
2355.53	0.832745
2358.35	-0.475322
2361.17	-1.24964
2363.98	-1.02144
2366.79	-0.895448
2369.6	0.175471
2372.42	0.631409
2375.22	1.19137
2378.03	1.97823
2380.84	1.64743
2383.65	1.30423
2386.45	2.01375
2389.26	2.98895
2392.06	3.13608
2394.87	3.01272
2397.67	4.02576
2400.47	4.38892
2403.27	5.01135
2406.07	4.66464
2408.86	4.8992
2411.66	4.69479
2414.46	5.0474
2417.25	5.33598
2420.05	4.99093
2422.84	4.8839
2425.63	3.71232
2428.42	3.56548
2431.21	3.08637
2434	2.66986
2436.79	2.07701
2439.57	2.26807
2442.36	2.9591
2445.14	1.85057
2447.93	1.60554
2450.71	0.99236
2453.49	1.70714
2456.27	1.67124
2459.05	1.88227
2461.83	2.47652
2464.61	3.06153
2467.39	3.6463
2470.16	3.60166
2472.94	3.67507
2475.71	3.98328
2478.48	4.53899
2481.25	4.95234
2484.02	4.81381
2486.8	4.98551
2489.56	4.28489
2492.33	4.26661
2495.1	2.704
2497.86	2.58581
2500.63	3.07704
2503.39	3.87909
2506.16	3.44236
2508.92	3.42322
2511.68	2.98473
2514.44	2.29723
2517.2	2.3998
2519.95	3.17826
2522.71	3.07974
2525.47	3.22139
2528.22	3.98339
2530.98	4.85219
2533.73	5.02554
2536.48	6.10126
2539.23	6.7076
2541.98	6.94102
2544.73	7.49449
2547.48	6.95935
2550.23	6.28931
2552.97	6.91063
2555.72	7.08773
2558.46	7.38697
2561.2	7.40059
2563.95	7.25477
2566.69	8.46659
2569.43	7.9043
2572.17	8.1438
2574.91	7.07997
2577.64	6.8667
2580.38	6.27485
2583.11	4.68317
2585.85	3.72681
2588.58	2.99258
2591.31	2.47747
2594.04	2.12886
2596.78	1.64562
2599.51	1.71757
2602.23	1.39473
2604.96	1.52231
2607.69	1.04604
2610.41	0.560866
2613.14	0.791045
2615.86	1.81669
2618.58	2.75957
2621.3	3.79441
2624.03	4.49482
2626.75	5.5378
2629.46	6.72466
2632.18	7.70698
2634.9	8.02171
2637.61	8.16876
2640.33	9.5841
2643.04	9.45321
2645.76	8.95946
2648.47	8.57595
2651.18	7.71337
2653.89	7.9814
2656.6	8.63942
2659.31	7.66015
2662.01	7.48021
2664.72	7.3516
2667.43	6.86838
2670.13	6.55334
2672.83	6.58597
2675.53	6.788
2678.24	7.03649
2680.94	7.01772
2683.64	7.35298
2686.34	6.90854
2689.03	8.3422
2691.73	8.80718
2694.43	9.67658
2697.12	9.95204
2699.81	9.63318
2702.51	9.58307
2705.2	9.47076
2707.89	9.5985
2710.58	8.97322
2713.27	9.41853
2715.96	10.6441
2718.64	10.1668
2721.33	10.6349
2724.01	10.5412
2726.7	11.3322
2729.38	11.1969
2732.06	10.7887
2734.75	9.76156
2737.43	9.24856
2740.11	8.76784
2742.78	7.92812
2745.46	7.20458
2748.14	7.13374
2750.81	6.87607
2753.49	7.76021
2756.16	7.54784
2758.84	7.1294
2761.51	6.50385
2764.18	6.78189
2766.85	6.10799
2769.52	6.20895
2772.19	5.36432
2774.85	5.33898
2777.52	6.11535
2780.18	6.42127
2782.85	6.8745
2785.51	7.14224
2788.17	7.35592
2790.84	7.89666
2793.5	6.20633
2796.16	5.14082
2798.81	3.88655
2801.47	3.20273
2804.13	2.48019
2806.79	1.49498
2809.44	0.749686
2812.09	0.953449
2814.75	1.3661
2817.4	2.39294
2820.05	3.85623
2822.7	5.57206
2825.35	7.61064
2828	10.1235
2830.65	12.2989
2833.29	15.209
2835.94	18.8514
2838.58	23.1163
2841.23	27.7769
2843.87	32.4912
2846.51	36.912
2849.15	41.8506
2851.79	46.67
2854.43	52.1895
2857.07	56.3877
2859.71	60.236
2862.34	64.3323
2864.98	67.4745
2867.61	70.4233
2870.25	72.6671
2872.88	75.0668
2875.51	78.0208
2878.14	80.0789
2880.77	82.6563
2883.4	84.2614
2886.03	86.3822
2888.65	88.8239
2891.28	91.2719
2893.91	93.4375
2896.53	97.0997
2899.15	100.84
2901.78	104.803
2904.4	110.247
2907.02	116.344
2909.64	122.442
2912.26	128.297
2914.87	136.209
2917.49	142.25
2920.11	148.586
2922.72	154.622
2925.34	159.344
2927.95	162.863
2930.56	165.726
2933.17	167.132
2935.78	167.872
2938.39	167.737
2941	165.509
2943.61	162.497
2946.22	158.232
2948.82	153.533
2951.43	146.976
2954.03	140.478
2956.64	134.623
2959.24	127.817
2961.84	120.398
2964.44	112.416
2967.04	105.679
2969.64	99.9894
2972.24	93.2129
2974.83	86.3145
2977.43	80.0172
2980.02	72.7135
2982.62	66.4703
2985.21	59.8884
2987.8	54.161
2990.4	48.481
2992.99	42.1739
2995.57	38.0256
2998.16	33.2
3000.75	29.2089
3003.34	24.7677
3005.92	20.4874
3008.51	16.6922
3011.09	14.4545
3013.68	11.3598
3016.26	9.19704
3018.84	8.24338
3021.42	6.70174
3024	5.37274
3026.58	3.45773
3029.16	2.57085
3031.73	2.83659
3034.31	3.33738
3036.89	3.68855
3039.46	2.9337
3042.03	2.91856
3044.61	2.69371
3047.18	2.54579
3049.75	2.76618
3052.32	3.45074
3054.89	3.11089
3057.45	3.14128
3060.02	3.45276
3062.59	4.06451
3065.15	3.48815
3067.72	3.27542
3070.28	3.54368
3072.84	3.56342
3075.41	3.37438
3077.97	2.39362
3080.53	2.24862
3083.09	1.58671
3085.64	1.33621
3088.2	0.174852
3090.76	-0.181046
3093.31	0.356027
3095.87	0.684705
3098.42	0.675782
3100.97	1.27489
3103.53	1.34728
3106.08	1.8709
3108.63	2.11504
3111.18	3.52306
3113.73	4.05891
3116.27	5.30415
3118.82	5.88747
3121.37	7.01439
3123.91	8.76031
3126.45	9.5655
3129	9.90824
3131.54	12.0132
3134.08	12.3848
3136.62	12.4521
3139.16	12.5612
3141.7	13.0352
3144.24	12.5843
3146.78	11.8942
3149.31	13.2725