File: data/Raman/poly_smoothed/Mb_40_y_17_1x_45s_532 nm_x100_100%_600 gr_mm_01.txt
#Acq. time (s)=	45
#Accumulations=	2
#Range (cm-¹)=	200...3150
#Windows=	2
#Auto scanning=	Off
#Autofocus=	Off
#Macrospot=	Off
#AutoExposure=	Off
#Spike filter=	Multiple accum.
#Delay time (s)=	0
#Binning=	1
#Readout mode=	Signal
#DeNoise=	Off
#ICS correction=	On
#Dark correction=	Off
#Inst. Process=	Off
#Detector Gain=	Best Dynamic Range
#Detector ADC=	20 kHz
#Detector temperature (°C)=	-69.85
#Instrument=	LabRAM HR Evol
#Detector=	Synapse
#Objective=	x100
#Grating=	600 gr/mm
#ND Filter=	100%
#Laser (nm)=	532
#Hole=	100.021
#Range=	Auto
#Laser Pol.=	No
#Raman. Pol.=	No
#Laser Pol. (°)=	-0.0007625
#Raman Pol. (°)=	89.9995
#Collection=	Microscope
#StageXY=	Marzhauser
#StageZ=	Marzhauser
#X (µm)=	-1074.4
#Y (µm)=	643.8
#Z (µm)=	584.35
#Full time(mm:ss)=	3:18
#Project=
#Sample=
#Site=
#Title=	Mb_40_y_17_2x_45s_532 nm_x100_100%_600 gr_mm
#Remark=
#Date=	19.07.2022 10:24
#Acquired=	19.07.2022 10:24:50
#Base:Fit=	10.08.2022 10:52:48
#Base:Sub=	10.08.2022 10:52:53
#Filter:Polynom=	16.08.2022 10:09:04
#AxisType[0]=Intens
#AxisUnit[0]=Cnt
#AxisType[1]=Spectr
#AxisUnit[1]=1/cm
200.423	57.3605
204.052	45.3124
207.682	38.0215
211.308	32.9617
214.935	28.8699
218.558	24.5807
222.18	21.3947
225.802	18.4935
229.421	14.3141
233.039	14.0592
236.657	12.7964
240.272	11.0442
243.885	8.69712
247.497	8.1229
251.11	6.71708
254.719	5.68643
258.327	5.3336
261.933	6.77612
265.538	6.63179
269.141	5.10944
272.744	3.42206
276.344	3.11097
279.944	4.40323
283.542	5.58597
287.138	4.93847
290.733	6.21403
294.327	8.14473
297.919	9.08652
301.508	11.095
305.098	7.80057
308.686	9.42378
312.273	11.6652
315.858	13.2372
319.44	15.5512
323.022	16.5527
326.604	16.9417
330.181	17.5553
333.76	16.5093
337.335	17.6228
340.91	16.1987
344.483	17.1972
348.055	16.5676
351.625	16.2098
355.195	13.6116
358.762	11.7122
362.329	11.7862
365.893	12.9872
369.455	13.0604
373.017	11.3471
376.578	11.4174
380.137	13.4944
383.694	14.008
387.249	14.7457
390.806	15.1063
394.359	15.1579
397.91	16.9651
401.46	16.7471
405.009	16.6957
408.557	17.1092
412.103	17.8848
415.647	16.8695
419.191	17.5784
422.733	16.3483
426.273	14.9096
429.812	13.2096
433.35	11.8728
436.885	10.0432
440.42	8.53381
443.954	5.90227
447.486	5.27379
451.015	5.25325
454.545	4.68259
458.073	3.51334
461.598	5.77873
465.124	6.19284
468.648	7.43778
472.169	8.20081
475.69	8.28185
479.208	8.31189
482.727	9.49512
486.243	13.0014
489.759	13.0842
493.272	15.4756
496.783	17.9605
500.295	18.7433
503.804	19.3334
507.311	20.334
510.819	21.3399
514.324	22.8226
517.827	23.0024
521.329	22.7736
524.83	22.7306
528.329	22.1234
531.829	22.2338
535.326	21.7581
538.821	21.1038
542.315	21.454
545.808	21.1844
549.299	19.3431
552.789	18.3079
556.278	18.1631
559.763	17.7777
563.249	16.7099
566.733	15.3498
570.217	13.1836
573.699	11.1323
577.177	10.6444
580.656	9.13579
584.134	6.27049
587.609	5.821
591.084	5.19602
594.558	5.20797
598.029	4.96824
601.5	4.97421
604.968	5.57484
608.437	6.53233
611.902	7.37622
615.368	7.17427
618.831	8.77327
622.294	8.74194
625.755	8.72567
629.213	9.96988
632.673	9.43199
636.129	10.3424
639.584	12.4723
643.037	13.0069
646.491	13.7011
649.942	14.7148
653.392	14.5262
656.84	16.5325
660.287	18.0736
663.732	18.1051
667.177	18.1369
670.62	19.4679
674.061	20.4774
677.502	23.0849
680.941	25.2414
684.379	27.7598
687.815	29.866
691.248	30.9804
694.682	32.6184
698.115	31.8805
701.546	33.7629
704.974	34.3888
708.402	33.5088
711.83	35.7156
715.254	38.377
718.679	39.2263
722.102	40.9787
725.522	41.6265
728.943	42.2278
732.361	42.0441
735.779	43.1855
739.194	43.3426
742.608	42.9794
746.022	44.6201
749.433	45.6839
752.843	48.757
756.254	50.1421
759.661	51.4085
763.067	52.9179
766.471	54.8491
769.877	57.0083
773.279	59.4896
776.68	61.7527
780.079	64.3868
783.478	66.7022
786.875	69.4067
790.27	71.9596
793.665	74.7545
797.058	77.4104
800.45	77.3907
803.84	78.8062
807.23	79.4205
810.616	78.3827
814.002	78.5264
817.388	77.2
820.772	77.4433
824.153	75.9967
827.535	75.1054
830.915	73.7719
834.292	71.6311
837.67	71.2024
841.047	67.7612
844.42	66.6038
847.794	65.0017
851.165	64.7801
854.534	63.2022
857.905	59.4518
861.272	59.1542
864.639	56.262
868.004	55.3002
871.367	53.3711
874.731	52.6446
878.092	51.7428
881.451	53.0571
884.809	51.3481
888.166	49.8774
891.522	47.7809
894.878	46.1607
898.231	45.2372
901.583	44.6514
904.934	43.8313
908.283	43.3844
911.631	42.7606
914.976	42.9466
918.322	43.1163
921.666	45.1184
925.009	46.4884
928.351	46.9477
931.692	45.3935
935.029	44.8398
938.367	44.0479
941.704	42.8131
945.038	41.9188
948.372	40.9729
951.705	40.2673
955.035	39.5185
958.366	40.0907
961.693	39.4056
965.021	37.6069
968.346	35.3031
971.67	32.9953
974.995	29.7964
978.316	29.8579
981.638	28.3062
984.957	27.0834
988.274	26.205
991.59	23.697
994.907	21.0337
998.221	18.0409
1001.53	16.266
1004.85	16.0983
1008.16	18.0004
1011.46	25.0329
1014.77	36.331
1018.08	49.6087
1021.38	63.3068
1024.69	76.586
1027.99	88.979
1031.29	98.6784
1034.59	109.386
1037.89	115.643
1041.19	120.113
1044.48	121.891
1047.78	120.975
1051.07	118.716
1054.36	113.686
1057.66	107.521
1060.94	98.4137
1064.23	88.0338
1067.52	75.4737
1070.81	60.4057
1074.09	45.5344
1077.38	31.6419
1080.66	19.0388
1083.94	11.4505
1087.22	7.64934
1090.5	9.80267
1093.77	12.1766
1097.05	14.9181
1100.32	17.658
1103.6	19.0223
1106.87	19.7071
1110.14	20.4905
1113.41	21.3784
1116.67	21.702
1119.94	20.7462
1123.21	19.0742
1126.47	17.6482
1129.73	15.8206
1133	13.7765
1136.26	12.2928
1139.52	11.1204
1142.77	10.9719
1146.03	10.8168
1149.29	8.67328
1152.54	7.33522
1155.79	6.7286
1159.04	6.57572
1162.3	4.8763
1165.55	3.82623
1168.79	3.77281
1172.04	4.99676
1175.28	5.6574
1178.53	5.1516
1181.77	5.11641
1185.01	5.24798
1188.25	4.53123
1191.49	4.54258
1194.73	6.69981
1197.97	6.07473
1201.2	7.263
1204.44	6.38685
1207.67	9.55772
1210.9	11.7413
1214.13	15.0221
1217.36	17.3686
1220.59	19.9805
1223.82	22.5538
1227.04	23.7813
1230.26	26.6201
1233.49	29.2489
1236.71	29.8775
1239.93	30.1434
1243.15	31.2583
1246.37	31.8428
1249.58	32.7563
1252.8	32.2706
1256.01	32.4599
1259.23	33.4284
1262.44	34.3355
1265.65	34.2983
1268.86	36.681
1272.07	39.9414
1275.27	42.6152
1278.48	44.1216
1281.68	45.2813
1284.89	47.7278
1288.09	51.109
1291.29	51.307
1294.49	52.9619
1297.69	55.4251
1300.88	55.1389
1304.08	55.7856
1307.27	56.2447
1310.47	56.1228
1313.66	55.1688
1316.85	52.6131
1320.04	51.2335
1323.23	49.6963
1326.41	48.2863
1329.6	45.224
1332.78	44.4159
1335.97	44.6163
1339.15	43.007
1342.33	40.5631
1345.51	39.9891
1348.69	39.8161
1351.87	37.774
1355.04	35.7278
1358.22	33.4418
1361.39	32.4748
1364.57	31.4687
1367.74	29.0984
1370.91	27.0146
1374.07	25.6661
1377.24	24.9437
1380.41	24.0569
1383.57	24.4351
1386.74	24.2083
1389.9	24.1261
1393.06	23.9887
1396.22	24.6572
1399.38	26.7144
1402.54	27.8698
1405.7	30.1098
1408.85	32.5237
1412.01	36.3178
1415.16	39.973
1418.31	42.9927
1421.46	46.2667
1424.61	49.9133
1427.76	53.3494
1430.91	57.2377
1434.05	60.719
1437.2	63.8516
1440.34	65.4679
1443.49	65.6438
1446.63	66.1723
1449.77	65.9267
1452.91	64.319
1456.04	63.164
1459.18	62.0831
1462.31	58.2421
1465.45	56.473
1468.58	55.2562
1471.71	51.7415
1474.84	48.291
1477.97	44.5611
1481.1	41.5739
1484.23	37.5626
1487.35	33.4966
1490.48	29.5087
1493.6	25.1662
1496.72	22.2785
1499.84	18.5578
1502.96	16.4164
1506.08	13.6161
1509.2	12.7355
1512.31	12.563
1515.43	10.9548
1518.54	9.88324
1521.66	10.6896
1524.77	9.56869
1527.88	11.0144
1530.99	14.1451
1534.09	15.3503
1537.2	17.43
1540.31	19.7357
1543.41	23.0745
1546.51	24.5727
1549.62	24.8939
1552.72	25.9523
1555.82	26.5785
1558.91	27.3533
1562.01	26.1733
1565.11	26.0655
1568.2	25.6508
1571.3	25.3534
1574.39	25.227
1577.48	25.4551
1580.57	26.0042
1583.66	26.5448
1586.75	28.0365
1589.83	28.3927
1592.92	29.7102
1596	31.0381
1599.09	32.0425
1602.17	31.9712
1605.25	32.4769
1608.33	31.3708
1611.41	31.0511
1614.48	32.5828
1617.56	34.4207
1620.64	34.7211
1623.71	35.6803
1626.78	36.9829
1629.86	38.5581
1632.92	39.5099
1635.99	39.9818
1639.06	42.2645
1642.13	43.4996
1645.19	46.5002
1648.26	47.252
1651.32	49.0869
1654.38	50.6161
1657.45	50.539
1660.51	48.8833
1663.57	46.7808
1666.62	44.9231
1669.68	42.3063
1672.73	39.641
1675.79	34.9917
1678.84	30.9118
1681.89	27.692
1684.94	24.1024
1687.99	19.9444
1691.04	17.8986
1694.09	15.4224
1697.14	12.0533
1700.18	9.56879
1703.22	7.82005
1706.27	6.12501
1709.31	5.28459
1712.35	6.04432
1715.39	6.65
1718.43	6.46069
1721.46	6.60244
1724.5	7.57409
1727.53	7.08421
1730.57	6.65926
1733.6	6.23436
1736.63	5.48367
1739.66	5.14616
1742.69	5.82776
1745.72	4.99614
1748.74	4.99921
1751.77	3.77814
1754.8	3.4131
1757.82	1.45426
1760.84	0.449415
1763.86	-0.063745
1766.88	0.283657
1769.9	-0.769274
1772.92	-1.36313
1775.93	-0.300021
1778.95	-0.829205
1781.96	-0.684086
1784.98	0.459034
1787.99	0.877229
1791	1.48553
1794.01	0.817612
1797.02	1.40264
1800.03	1.60515
1803.03	1.7177
1806.04	2.26089
1809.04	2.49357
1812.04	2.91561
1815.05	2.44302
1818.05	2.66943
1821.05	2.21918
1824.05	2.75324
1827.04	2.17018
1830.04	1.64809
1833.03	1.03796
1836.03	0.212011
1839.02	0.522584
1842.01	0.156715
1845	-0.0881901
1847.99	-0.0773017
1850.98	0.494566
1853.97	1.71331
1856.95	3.07016
1859.94	3.63269
1862.92	4.21772
1865.91	4.022
1868.89	4.24521
1871.87	5.305
1874.85	5.71055
1877.83	6.9486
1880.8	7.02516
1882.56	6.93896
1885.54	7.94593
1888.53	7.94883
1891.52	7.51453
1894.5	7.62125
1897.49	7.43889
1900.47	5.45486
1903.45	4.61984
1906.43	3.75484
1909.41	4.43915
1912.39	4.37636
1915.37	3.53291
1918.35	2.46679
1921.32	3.09595
1924.3	2.60213
1927.27	2.15985
1930.24	2.55667
1933.21	1.00797
1936.18	0.918153
1939.15	1.21017
1942.12	1.37893
1945.09	2.00476
1948.05	2.06839
1951.02	1.2878
1953.98	0.471909
1956.94	0.487659
1959.91	1.21468
1962.87	0.430752
1965.82	0.570857
1968.78	1.09525
1971.74	1.21525
1974.7	1.37178
1977.65	2.60616
1980.6	2.36909
1983.56	1.61627
1986.51	1.24163
1989.46	2.34737
1992.41	2.48998
1995.36	2.5235
1998.3	3.62233
2001.25	4.04998
2004.2	4.06738
2007.14	4.07672
2010.08	5.11786
2013.02	4.68628
2015.97	5.17988
2018.9	5.59816
2021.84	5.20622
2024.78	5.18307
2027.72	5.84265
2030.65	6.92486
2033.59	6.97584
2036.52	7.33665
2039.45	8.58076
2042.38	8.31046
2045.31	8.21754
2048.24	8.76562
2051.17	8.17452
2054.1	8.69026
2057.02	10.3041
2059.95	11.6697
2062.87	11.9854
2065.79	12.6198
2068.71	11.692
2071.63	12.1024
2074.55	12.2123
2077.47	13.2702
2080.39	14.0333
2083.3	13.8449
2086.22	15.8777
2089.13	16.805
2092.05	16.5965
2094.96	17.1783
2097.87	17.6977
2100.78	19.1642
2103.69	20.1299
2106.59	22.4162
2109.5	24.5635
2112.41	25.8082
2115.31	26.3227
2118.21	30.4479
2121.12	32.0298
2124.02	35.1068
2126.92	37.3966
2129.82	40.6231
2132.71	42.8751
2135.61	46.4957
2138.51	47.9526
2141.4	50.0264
2144.29	52.1669
2147.19	54.2322
2150.08	56.1623
2152.97	56.8359
2155.86	58.5236
2158.75	58.8085
2161.64	58.8893
2164.52	59.3813
2167.41	60.1683
2170.29	61.2304
2173.17	62.2897
2176.06	62.5747
2178.94	61.7675
2181.82	59.9717
2184.7	58.5918
2187.57	59.2209
2190.45	58.0763
2193.33	56.4889
2196.2	55.5785
2199.08	54.2628
2201.95	53.7295
2204.82	51.7068
2207.69	49.9502
2210.56	46.0888
2213.43	44.7438
2216.3	42.5787
2219.16	40.6268
2222.03	38.2565
2224.89	36.8816
2227.75	34.8417
2230.62	33.2113
2233.48	31.9008
2236.34	30.8753
2239.2	27.9113
2242.06	26.2227
2244.91	23.9573
2247.77	22.1228
2250.62	20.2461
2253.48	19.3797
2256.33	18.3147
2259.18	17.9021
2262.03	16.5073
2264.88	16.3779
2267.73	15.3147
2270.58	13.6802
2273.43	13.3749
2276.27	12.5623
2279.12	12.2906
2281.96	12.307
2284.8	13.2909
2287.64	13.5984
2290.49	13.3446
2293.32	12.9169
2296.16	12.2268
2299	12.8633
2301.84	13.138
2304.67	14.0921
2307.51	12.9584
2310.34	12.4811
2313.17	12.2701
2316	11.7392
2318.83	12.5646
2321.66	12.193
2324.49	11.6594
2327.32	11.3347
2330.15	11.6294
2332.97	11.0031
2335.79	9.78659
2338.62	8.69708
2341.44	7.95677
2344.26	7.61986
2347.08	7.35745
2349.9	6.49433
2352.72	5.87648
2355.53	5.80004
2358.35	5.09957
2361.17	4.11867
2363.98	4.71277
2366.79	4.81271
2369.6	5.4967
2372.42	5.98511
2375.22	5.32734
2378.03	4.42003
2380.84	4.72353
2383.65	3.83403
2386.45	4.60502
2389.26	5.02927
2392.06	5.31989
2394.87	5.74439
2397.67	6.23648
2400.47	6.50318
2403.27	6.86346
2406.07	6.82962
2408.86	6.99837
2411.66	8.55143
2414.46	10.2829
2417.25	10.5624
2420.05	11.7184
2422.84	11.6561
2425.63	12.0834
2428.42	12.086
2431.21	11.9928
2434	12.0741
2436.79	12.6878
2439.57	12.9241
2442.36	11.9043
2445.14	11.4836
2447.93	11.0011
2450.71	10.4112
2453.49	9.79716
2456.27	9.40989
2459.05	8.5747
2461.83	8.81985
2464.61	8.42579
2467.39	8.43134
2470.16	8.41953
2472.94	7.32169
2475.71	7.6554
2478.48	7.38314
2481.25	6.61318
2484.02	5.49741
2486.8	4.49692
2489.56	3.33906
2492.33	3.4158
2495.1	3.12701
2497.86	2.71511
2500.63	2.47891
2503.39	2.79215
2506.16	3.4036
2508.92	2.66106
2511.68	2.94978
2514.44	3.18669
2517.2	3.10338
2519.95	4.02475
2522.71	5.17669
2525.47	6.0841
2528.22	6.75859
2530.98	7.34254
2533.73	8.41477
2536.48	7.71764
2539.23	7.4671
2541.98	6.8634
2544.73	5.9233
2547.48	4.73852
2550.23	3.30827
2552.97	3.29373
2555.72	2.45221
2558.46	2.78279
2561.2	2.41144
2563.95	2.13314
2566.69	1.93269
2569.43	1.82924
2572.17	1.70482
2574.91	1.53972
2577.64	1.79194
2580.38	2.9476
2583.11	3.12288
2585.85	5.06172
2588.58	6.07847
2591.31	6.72598
2594.04	6.07567
2596.78	5.98493
2599.51	5.89753
2602.23	5.89867
2604.96	5.6846
2607.69	5.94416
2610.41	5.00152
2613.14	4.28886
2615.86	4.3542
2618.58	4.54676
2621.3	4.93369
2624.03	5.55922
2626.75	6.16387
2629.46	5.63044
2632.18	5.8297
2634.9	4.83231
2637.61	4.8905
2640.33	5.33274
2643.04	5.80525
2645.76	6.94495
2648.47	7.39957
2651.18	7.27595
2653.89	6.645
2656.6	6.29471
2659.31	5.8111
2662.01	5.2808
2664.72	5.68707
2667.43	5.78043
2670.13	5.48066
2672.83	5.27357
2675.53	4.88636
2678.24	4.91058
2680.94	5.41756
2683.64	6.08524
2686.34	6.56994
2689.03	7.24075
2691.73	7.46415
2694.43	7.56982
2697.12	7.58735
2699.81	7.41366
2702.51	7.86949
2705.2	8.47135
2707.89	9.37513
2710.58	9.17969
2713.27	9.33368
2715.96	9.76362
2718.64	9.44465
2721.33	9.06301
2724.01	8.51355
2726.7	8.05826
2729.38	8.64377
2732.06	8.82535
2734.75	8.73085
2737.43	7.52743
2740.11	7.57933
2742.78	7.22004
2745.46	5.5203
2748.14	4.97306
2750.81	4.68718
2753.49	4.42489
2756.16	3.80524
2758.84	3.9225
2761.51	4.00233
2764.18	3.84186
2766.85	4.1406
2769.52	4.35535
2772.19	4.07938
2774.85	5.10138
2777.52	4.88659
2780.18	6.05953
2782.85	6.4042
2785.51	5.15592
2788.17	4.71581
2790.84	5.10721
2793.5	5.8307
2796.16	5.89629
2798.81	5.66468
2801.47	5.28196
2804.13	3.85101
2806.79	2.66449
2809.44	1.69126
2812.09	1.51343
2814.75	2.94648
2817.4	3.12234
2820.05	4.33143
2822.7	6.5177
2825.35	8.93298
2828	10.8129
2830.65	13.3085
2833.29	16.2729
2835.94	18.3124
2838.58	22.961
2841.23	26.8902
2843.87	30.6108
2846.51	34.638
2849.15	38.596
2851.79	42.3794
2854.43	47.9126
2857.07	52.9299
2859.71	58.0018
2862.34	61.2747
2864.98	66.1842
2867.61	68.5056
2870.25	71.5666
2872.88	74.8399
2875.51	77.7218
2878.14	80.8651
2880.77	82.5042
2883.4	84.4622
2886.03	86.3189
2888.65	88.2154
2891.28	89.7057
2893.91	91.5837
2896.53	93.8422
2899.15	95.702
2901.78	99.8827
2904.4	104.307
2907.02	107.556
2909.64	112.661
2912.26	118.817
2914.87	125.166
2917.49	131.517
2920.11	137.418
2922.72	141.396
2925.34	144.959
2927.95	148.418
2930.56	149.998
2933.17	150.693
2935.78	151.475
2938.39	150.679
2941	149.269
2943.61	145.582
2946.22	140.996
2948.82	136.644
2951.43	131.651
2954.03	124.942
2956.64	118.963
2959.24	112.011
2961.84	105.266
2964.44	100.302
2967.04	94.6647
2969.64	87.9216
2972.24	83.2866
2974.83	78.6025
2977.43	73.0114
2980.02	67.2546
2982.62	61.2615
2985.21	55.4285
2987.8	49.7672
2990.4	45.5221
2992.99	40.7682
2995.57	36.2897
2998.16	32.4728
3000.75	28.2478
3003.34	23.8977
3005.92	19.4955
3008.51	15.6923
3011.09	12.6831
3013.68	9.57796
3016.26	7.53549
3018.84	5.88883
3021.42	4.78542
3024	3.72155
3026.58	3.70372
3029.16	3.46298
3031.73	3.30439
3034.31	3.25205
3036.89	2.96199
3039.46	3.91491
3042.03	3.96017
3044.61	4.85
3047.18	5.40166
3049.75	5.53054
3052.32	6.09845
3054.89	5.53834
3057.45	5.5863
3060.02	5.42327
3062.59	5.28672
3065.15	4.669
3067.72	4.53999
3070.28	4.06236
3072.84	2.90054
3075.41	2.67231
3077.97	1.94486
3080.53	1.91016
3083.09	1.82757
3085.64	2.00581
3088.2	1.77578
3090.76	1.61205
3093.31	1.3465
3095.87	2.17814
3098.42	2.57463
3100.97	3.37599
3103.53	4.02209
3106.08	4.77549
3108.63	5.51324
3111.18	6.09935
3113.73	7.03058
3116.27	8.12039
3118.82	9.69594
3121.37	11.1249
3123.91	12.475
3126.45	13.1071
3129	14.1317
3131.54	14.6187
3134.08	14.8082
3136.62	15.6145
3139.16	15.5128
3141.7	15.2352
3144.24	14.5769
3146.78	12.8875
3149.31	10.949