File: data/Raman/poly_smoothed/Mb_40_24_50_1x_45s_532 nm_x100_100%_600 gr_mm_01.txt
#Acq. time (s)=	45
#Accumulations=	2
#Range (cm-¹)=	200...3150
#Windows=	2
#Auto scanning=	Off
#Autofocus=	Off
#Macrospot=	Off
#AutoExposure=	Off
#Spike filter=	Multiple accum.
#Delay time (s)=	0
#Binning=	1
#Readout mode=	Signal
#DeNoise=	Off
#ICS correction=	On
#Dark correction=	Off
#Inst. Process=	Off
#Detector Gain=	Best Dynamic Range
#Detector ADC=	20 kHz
#Detector temperature (°C)=	-70.08
#Instrument=	LabRAM HR Evol
#Detector=	Synapse
#Objective=	x100
#Grating=	600 gr/mm
#ND Filter=	100%
#Laser (nm)=	532
#Hole=	100.021
#Range=	Auto
#Laser Pol.=	No
#Raman. Pol.=	No
#Laser Pol. (°)=	-0.0007625
#Raman Pol. (°)=	89.9995
#Collection=	Microscope
#StageXY=	Marzhauser
#StageZ=	Marzhauser
#X (µm)=	-2444
#Y (µm)=	-28.7
#Z (µm)=	-10.1
#Full time(mm:ss)=	3:19
#Project=
#Sample=
#Site=
#Title=	Mb_40_24_50_2x_45s_532 nm_x100_100%_600 gr_mm
#Remark=
#Date=	14.07.2022 14:32
#Acquired=	14.07.2022 14:32:21
#Base:Fit=	10.08.2022 10:47:01
#Base:Sub=	10.08.2022 10:47:12
#Filter:Polynom=	16.08.2022 10:11:48
#AxisType[0]=Intens
#AxisUnit[0]=Cnt
#AxisType[1]=Spectr
#AxisUnit[1]=1/cm
200.554	8.32026
204.183	10.1408
207.813	9.85249
211.439	9.07159
215.065	7.09083
218.688	4.63135
222.312	4.88342
225.933	3.96445
229.552	4.00181
233.171	4.60505
236.787	5.36997
240.402	6.8425
244.015	7.53577
247.627	9.15427
251.24	10.6942
254.849	10.8308
258.457	12.5667
262.063	13.9431
265.668	15.3203
269.271	17.1005
272.873	19.117
276.474	20.1062
280.073	19.3069
283.671	20.4883
287.268	21.028
290.863	19.4888
294.456	18.8127
298.049	18.7632
301.637	17.3817
305.227	15.4157
308.815	17.1971
312.402	17.6736
315.987	17.2194
319.569	18.8754
323.151	19.1378
326.733	21.734
330.31	22.1917
333.889	22.5593
337.464	23.5046
341.039	23.7361
344.611	23.348
348.184	23.8446
351.754	23.1437
355.324	22.728
358.89	21.2457
362.455	20.2748
366.021	18.464
369.584	17.2971
373.145	16.5095
376.707	15.2476
380.265	14.2193
383.822	13.5118
387.378	10.0056
390.934	9.96068
394.487	9.88144
398.038	10.612
401.588	9.25219
405.137	8.42864
408.685	8.81408
412.23	9.14111
415.775	9.08238
419.318	7.99717
422.86	8.50228
426.401	7.72588
429.94	7.94956
433.478	8.08159
437.012	7.16447
440.547	5.09543
444.081	4.41006
447.613	3.80452
451.142	2.87706
454.672	3.55834
458.2	6.06371
461.725	5.27829
465.251	6.4839
468.775	7.0835
472.296	7.60934
475.817	8.20888
479.335	10.405
482.854	9.61336
486.37	9.50217
489.886	8.51908
493.398	10.9565
496.91	11.3938
500.422	12.3333
503.93	12.8771
507.438	12.3226
510.946	13.373
514.45	13.7031
517.954	14.3845
521.456	13.2972
524.956	11.2667
528.456	11.004
531.956	11.5706
535.452	11.5934
538.947	11.7953
542.441	11.3349
545.934	10.4104
549.425	9.39082
552.915	10.1884
556.403	10.2175
559.889	8.5958
563.375	8.26597
566.859	6.50599
570.342	5.33147
573.824	3.89515
577.303	4.0159
580.782	4.04209
584.26	3.36267
587.734	2.78664
591.21	1.96868
594.684	1.98689
598.154	2.02211
601.626	1.27879
605.094	0.910335
608.562	1.55524
612.027	1.92163
615.493	2.1751
618.956	1.30209
622.419	0.510848
625.879	1.07661
629.338	0.40971
632.797	1.99463
636.254	2.66082
639.708	3.29256
643.162	3.74418
646.614	3.96575
650.067	5.29795
653.516	6.64695
656.964	8.56246
660.411	9.17779
663.857	11.0564
667.301	11.4486
670.744	12.2961
674.186	13.162
677.626	13.2328
681.065	15.0776
684.503	16.0512
687.939	17.4654
691.372	18.7453
694.806	19.2292
698.239	19.2622
701.67	19.5572
705.098	20.7298
708.526	21.5376
711.954	22.4992
715.378	23.7437
718.802	24.9218
722.226	26.2699
725.646	26.8633
729.067	28.3211
732.484	29.0305
735.902	30.9533
739.317	33.0569
742.731	34.6471
746.145	35.9233
749.556	38.3372
752.966	40.5978
756.377	43.7059
759.784	45.3745
763.19	49.9523
766.594	55.0565
770	58.3269
773.402	60.5493
776.803	62.8682
780.202	65.726
783.6	68.3547
786.997	71.5304
790.393	74.3743
793.787	75.637
797.18	78.1467
800.572	78.8099
803.963	79.6671
807.35	79.2337
810.738	77.8895
814.125	77.3203
817.51	77.1936
820.894	76.5153
824.275	75.5984
827.657	74.0561
831.037	73.127
834.414	71.41
837.792	69.2466
841.167	65.6892
844.542	62.8529
847.914	61.7985
851.287	58.4029
854.656	56.2988
858.026	52.8361
861.393	51.9653
864.761	50.0025
868.125	48.2919
871.489	47.5894
874.85	46.4401
878.213	45.6561
881.572	44.9968
884.931	45.9639
888.287	45.9044
891.643	46.391
894.997	46.1467
898.352	46.6942
901.704	46.9764
905.055	46.2485
908.404	46.1601
911.75	45.1098
915.097	42.9307
918.443	41.0873
921.787	39.0853
925.13	37.6125
928.472	37.7663
931.813	36.3795
935.15	35.9439
938.488	35.4826
941.825	33.4771
945.158	32.3053
948.493	30.4998
951.824	29.3369
955.156	29.9709
958.486	28.8889
961.814	29.1802
965.142	28.1947
968.467	28.536
971.79	27.1691
975.115	26.6552
978.436	25.3225
981.756	23.6356
985.077	23.0948
988.394	21.0691
991.71	19.6509
995.025	18.4893
998.341	18.2688
1001.65	18.017
1004.97	18.3011
1008.28	17.8449
1011.58	18.3994
1014.89	19.4439
1018.2	19.3049
1021.5	19.2137
1024.81	18.7068
1028.11	19.1967
1031.41	19.3295
1034.71	20.1894
1038.01	19.8808
1041.31	20.4405
1044.6	19.7245
1047.9	20.8672
1051.19	20.9581
1054.48	19.6324
1057.77	18.5194
1061.06	18.3576
1064.35	16.9403
1067.64	15.3881
1070.93	13.7119
1074.21	12.1308
1077.49	10.5332
1080.78	8.89007
1084.06	8.50536
1087.34	6.8088
1090.61	5.30113
1093.89	4.46572
1097.17	2.72294
1100.44	2.51328
1103.71	3.16504
1106.99	2.04666
1110.26	2.54515
1113.52	1.82408
1116.79	1.60547
1120.06	1.96865
1123.32	2.57921
1126.59	3.6642
1129.85	5.06663
1133.11	5.2441
1136.37	6.70069
1139.63	7.35464
1142.89	7.4574
1146.15	8.554
1149.4	9.10303
1152.66	9.21812
1155.91	9.25251
1159.16	9.73253
1162.41	9.51651
1165.66	8.70768
1168.91	8.47396
1172.16	8.77462
1175.4	7.84339
1178.65	7.72062
1181.89	7.63083
1185.13	5.62438
1188.37	4.25947
1191.61	4.1479
1194.85	2.99858
1198.08	2.85103
1201.32	2.17381
1204.55	2.81716
1207.79	4.42564
1211.02	5.16618
1214.25	6.55165
1217.48	7.13168
1220.71	8.94473
1223.93	11.2095
1227.16	12.0434
1230.38	13.6555
1233.6	14.6059
1236.83	16.0559
1240.05	18.0259
1243.26	19.4356
1246.48	20.11
1249.7	21.5933
1252.92	21.4741
1256.13	21.9656
1259.34	22.4986
1262.55	22.0097
1265.76	23.0917
1268.97	24.3896
1272.18	23.8546
1275.39	24.3863
1278.59	24.967
1281.8	25.7656
1285	27.925
1288.2	28.2327
1291.4	28.4822
1294.6	28.6876
1297.8	29.2433
1301	29.581
1304.19	29.0361
1307.39	28.1872
1310.58	27.8671
1313.77	27.5528
1316.96	27.0303
1320.15	27.1477
1323.34	25.9989
1326.53	24.7889
1329.72	24.7289
1332.9	23.7866
1336.08	23.4697
1339.27	23.5515
1342.45	23.3429
1345.63	23.9953
1348.8	22.8261
1351.98	22.1899
1355.16	22.7482
1358.33	24.188
1361.51	23.6696
1364.68	24.302
1367.85	23.3708
1371.02	22.4519
1374.19	23.0839
1377.36	23.7496
1380.52	23.2154
1383.69	23.2055
1386.85	22.8893
1390.02	22.773
1393.18	22.4476
1396.34	20.7537
1399.5	19.7321
1402.65	18.5815
1405.81	19.0583
1408.97	20.0547
1412.12	20.5947
1415.27	21.5887
1418.43	22.2583
1421.58	24.1234
1424.73	25.0755
1427.87	26.7511
1431.02	28.7044
1434.17	30.5922
1437.31	31.7622
1440.46	32.9972
1443.6	33.9432
1446.74	34.312
1449.88	33.7565
1453.02	34.5383
1456.16	35.1114
1459.29	35.4866
1462.43	35.9633
1465.56	34.843
1468.69	32.92
1471.83	31.2396
1474.95	30.7877
1478.08	30.1299
1481.21	29.2371
1484.34	29.6356
1487.47	28.96
1490.59	27.5189
1493.71	27.3806
1496.84	26.2504
1499.96	24.9479
1503.07	24.3786
1506.19	22.8081
1509.31	20.6533
1512.43	18.5766
1515.54	16.5058
1518.65	13.8243
1521.77	11.9517
1524.88	9.57948
1527.99	8.26328
1531.1	8.54028
1534.21	8.92672
1537.31	8.11185
1540.42	8.08591
1543.52	7.98649
1546.63	7.84887
1549.73	8.50442
1552.83	10.1269
1555.93	9.9037
1559.03	10.8968
1562.12	12.8988
1565.22	14.4113
1568.31	15.6517
1571.41	16.7378
1574.5	19.0032
1577.59	20.6732
1580.68	21.8109
1583.77	21.9414
1586.86	22.6606
1589.95	24.7581
1593.03	26.3716
1596.11	26.3232
1599.2	26.4566
1602.28	27.1583
1605.36	26.5201
1608.44	26.6591
1611.52	26.7557
1614.6	25.7664
1617.67	24.6498
1620.75	24.4161
1623.82	23.5442
1626.89	22.2635
1629.96	22.1259
1633.04	22.3412
1636.11	23.3692
1639.17	23.4022
1642.24	23.1751
1645.31	22.9839
1648.37	23.3585
1651.43	23.3237
1654.5	22.9446
1657.56	22.8592
1660.62	23.7087
1663.67	23.3593
1666.73	23.2168
1669.79	21.4408
1672.84	19.8238
1675.9	17.6238
1678.95	16.2809
1682	14.6919
1685.05	13.4945
1688.1	11.6868
1691.15	10.6718
1694.2	10.3974
1697.25	8.62843
1700.29	7.89114
1703.33	7.37384
1706.38	7.64055
1709.42	7.42114
1712.46	6.65113
1715.5	5.61888
1718.54	4.9527
1721.57	5.30279
1724.61	5.0681
1727.64	5.49263
1730.68	5.15693
1733.71	5.17806
1736.74	5.54488
1739.77	5.91641
1742.8	6.40577
1745.83	5.80712
1748.85	5.42932
1751.88	5.33204
1754.91	5.70439
1757.93	5.64055
1760.95	4.94475
1763.97	5.23647
1766.99	4.52221
1770.01	3.91714
1773.03	2.54655
1776.04	2.89454
1779.06	1.83783
1782.07	-0.0384876
1785.09	-1.11555
1788.1	-1.33011
1791.11	-0.270076
1794.12	1.07387
1797.13	1.55248
1800.13	1.43384
1803.14	1.71219
1806.15	1.88851
1809.15	3.6286
1812.15	4.15245
1815.16	4.86876
1818.15	5.20937
1821.16	5.54956
1824.15	5.68397
1827.15	5.33123
1830.15	5.13202
1833.14	5.65565
1836.14	5.90978
1839.13	5.43613
1842.12	4.77538
1845.11	4.65451
1848.1	3.54703
1851.09	2.28681
1854.08	1.14024
1857.06	1.67539
1860.05	2.78208
1863.03	4.02906
1866.01	4.64679
1869	4.46273
1871.98	3.84825
1874.96	3.66646
1877.93	4.03171
1880.91	4.83807
1882.47	4.13328
1885.46	4.55543
1888.44	5.02213
1891.43	5.09585
1894.42	4.95805
1897.4	5.18971
1900.39	5.58716
1903.37	6.14473
1906.35	6.4216
1909.33	5.69579
1912.31	5.04346
1915.29	4.42245
1918.26	4.22706
1921.24	3.91379
1924.21	3.48015
1927.19	4.13883
1930.16	4.33258
1933.13	5.0077
1936.1	4.71825
1939.07	4.78971
1942.04	3.95078
1945	3.68517
1947.97	3.66267
1950.93	3.87946
1953.9	3.74966
1956.86	4.0706
1959.82	4.6566
1962.78	4.84135
1965.74	4.90955
1968.7	4.55399
1971.65	4.32723
1974.61	4.10551
1977.57	3.74689
1980.52	3.18568
1983.47	2.86038
1986.42	1.85324
1989.37	2.5012
1992.32	3.10466
1995.27	2.35097
1998.22	3.04367
2001.17	3.76839
2004.11	4.13327
2007.05	3.75208
2010	2.80614
2012.94	3.44314
2015.88	3.67579
2018.82	4.58511
2021.76	4.08584
2024.7	5.01186
2027.63	5.11657
2030.57	5.29851
2033.5	5.19913
2036.44	5.55231
2039.37	5.66087
2042.3	6.09135
2045.23	6.65323
2048.16	7.29654
2051.08	7.79572
2054.01	8.04848
2056.94	8.23486
2059.86	9.12632
2062.79	9.68011
2065.71	9.99836
2068.63	10.1638
2071.55	10.3759
2074.47	10.7669
2077.39	11.0728
2080.31	10.5372
2083.22	11.4149
2086.13	11.306
2089.05	10.738
2091.96	10.4618
2094.87	10.3303
2097.78	10.4204
2100.69	10.3243
2103.6	10.4206
2106.51	11.1533
2109.42	11.5244
2112.32	12.1024
2115.23	13.0204
2118.13	13.4476
2121.03	14.3414
2123.93	14.8131
2126.83	16.6332
2129.73	18.7627
2132.63	19.9253
2135.53	21.9324
2138.42	23.1585
2141.32	24.3201
2144.21	26.3337
2147.1	27.5673
2150	28.7679
2152.89	29.0491
2155.78	30.1963
2158.66	30.0687
2161.55	31.0926
2164.44	31.7603
2167.32	31.4663
2170.21	30.637
2173.09	30.8168
2175.97	30.1471
2178.85	28.416
2181.73	27.7635
2184.61	26.4633
2187.49	25.8549
2190.37	24.4364
2193.24	24.3552
2196.12	24.2287
2198.99	24.081
2201.87	22.9767
2204.74	22.4808
2207.61	21.6112
2210.48	21.1838
2213.35	20.9274
2216.21	19.9509
2219.08	19.3946
2221.95	19.1112
2224.81	18.6132
2227.67	18.2985
2230.54	17.8091
2233.4	17.4136
2236.26	16.465
2239.11	15.4826
2241.97	14.9048
2244.83	13.809
2247.69	12.76
2250.54	12.6043
2253.4	12.3457
2256.25	11.9637
2259.1	11.117
2261.95	10.8192
2264.8	10.3519
2267.65	9.68542
2270.5	9.15689
2273.34	8.19137
2276.19	7.33617
2279.03	7.96906
2281.88	7.97685
2284.72	7.37639
2287.56	6.79559
2290.4	6.10338
2293.24	5.26943
2296.08	5.57444
2298.92	6.78403
2301.76	7.34205
2304.59	8.34511
2307.43	8.48831
2310.26	8.58011
2313.09	8.45386
2315.92	8.06254
2318.75	8.87132
2321.58	8.87635
2324.41	8.88761
2327.24	8.19589
2330.06	7.20359
2332.89	6.38619
2335.71	5.74319
2338.54	4.91468
2341.36	3.91801
2344.18	2.57046
2347	2.74201
2349.82	2.17772
2352.64	1.66579
2355.45	0.558598
2358.27	-0.266046
2361.08	-0.665881
2363.9	0.880517
2366.71	2.50003
2369.52	2.6059
2372.33	3.28216
2375.14	3.93775
2377.95	4.60869
2380.76	4.31162
2383.57	4.08877
2386.37	4.61161
2389.18	6.02988
2391.98	5.64145
2394.79	5.3137
2397.59	5.44929
2400.39	5.1875
2403.19	4.74507
2405.99	3.81017
2408.78	2.90812
2411.58	3.33388
2414.38	2.96242
2417.17	3.36178
2419.97	2.85125
2422.76	2.89423
2425.55	2.14649
2428.34	1.79175
2431.13	2.33617
2433.92	2.64209
2436.71	2.33931
2439.49	3.21696
2442.28	3.36712
2445.06	3.85289
2447.85	4.1137
2450.63	3.8388
2453.41	3.83005
2456.19	5.25493
2458.97	5.40232
2461.75	5.24436
2464.53	5.6451
2467.31	4.42712
2470.08	3.62655
2472.86	3.41794
2475.63	3.53342
2478.4	3.93061
2481.17	3.9053
2483.94	3.40799
2486.72	2.44367
2489.48	2.14314
2492.25	1.02495
2495.02	0.978488
2497.79	0.818848
2500.55	0.644465
2503.31	0.257378
2506.08	0.573286
2508.84	0.509812
2511.6	0.401231
2514.36	0.291906
2517.12	0.705181
2519.88	1.48636
2522.63	1.76121
2525.39	2.40243
2528.14	2.88662
2530.9	2.86315
2533.65	2.97856
2536.4	3.27625
2539.15	3.94843
2541.9	3.84325
2544.65	4.32354
2547.4	4.36908
2550.15	4.4773
2552.89	4.11411
2555.64	3.99713
2558.38	4.41367
2561.12	3.99147
2563.87	3.76365
2566.61	4.1166
2569.35	4.16449
2572.09	3.83345
2574.83	2.65241
2577.56	2.46052
2580.3	2.16943
2583.04	2.5188
2585.77	3.02225
2588.5	3.01599
2591.23	3.45119
2593.97	3.9508
2596.7	4.27239
2599.43	4.17636
2602.15	4.41903
2604.88	3.87645
2607.61	3.16609
2610.33	3.44229
2613.06	3.8147
2615.78	3.58303
2618.51	3.08167
2621.23	2.67157
2623.95	3.22996
2626.67	2.93237
2629.39	3.57228
2632.1	2.95269
2634.82	2.77006
2637.54	2.30496
2640.25	1.56582
2642.97	1.82194
2645.68	2.31899
2648.39	2.61066
2651.1	3.18548
2653.81	3.65297
2656.52	4.5013
2659.23	5.02637
2661.94	4.87239
2664.64	4.58102
2667.35	3.44634
2670.05	3.10532
2672.76	2.71925
2675.46	3.00764
2678.16	2.82712
2680.86	2.64945
2683.56	2.86576
2686.26	2.73445
2688.96	3.32736
2691.65	3.87343
2694.35	4.40862
2697.04	4.69276
2699.74	4.57386
2702.43	5.12994
2705.12	6.02295
2707.81	6.40068
2710.5	7.03061
2713.19	7.57924
2715.88	8.02393
2718.57	8.36661
2721.25	8.41231
2723.94	8.10257
2726.62	7.82807
2729.3	6.49867
2731.99	5.33017
2734.67	5.45932
2737.35	5.95734
2740.03	6.02992
2742.71	5.99365
2745.38	6.05053
2748.06	6.04273
2750.74	5.48636
2753.41	5.24922
2756.09	4.91282
2758.76	4.07969
2761.43	3.83727
2764.1	3.89504
2766.77	3.92429
2769.44	5.03716
2772.11	4.6495
2774.77	4.50213
2777.44	4.42561
2780.11	3.69208
2782.77	3.03599
2785.43	2.55985
2788.1	2.01574
2790.76	1.37106
2793.42	1.03915
2796.08	1.0568
2798.74	1.72174
2801.4	2.78733
2804.05	2.4795
2806.71	2.26824
2809.36	2.28887
2812.02	2.00959
2814.67	1.94718
2817.32	2.2438
2819.97	2.80034
2822.62	3.89612
2825.27	5.87616
2827.92	8.20446
2830.57	10.2754
2833.22	13.1319
2835.86	16.0041
2838.51	18.3278
2841.15	20.7271
2843.79	23.1827
2846.43	26.1229
2849.08	29.2622
2851.72	32.5987
2854.36	36.1901
2856.99	39.4041
2859.63	43.2594
2862.27	46.5113
2864.9	49.4718
2867.54	51.6328
2870.17	53.4259
2872.8	55.4465
2875.43	57.2483
2878.07	59.7723
2880.7	61.4222
2883.32	64.0234
2885.95	66.2406
2888.58	68.0005
2891.21	70.2339
2893.83	72.6549
2896.46	73.8894
2899.08	77.1002
2901.7	79.6885
2904.32	82.1751
2906.94	85.1758
2909.56	87.4387
2912.18	89.7213
2914.8	92.6568
2917.42	95.3723
2920.03	96.7484
2922.65	98.7278
2925.26	100.616
2927.88	100.789
2930.49	99.9893
2933.1	99.3992
2935.71	98.2137
2938.32	96.8198
2940.93	93.6909
2943.54	91.4066
2946.14	88.8443
2948.75	84.6539
2951.35	81.369
2953.96	77.285
2956.56	73.7571
2959.16	69.7219
2961.77	66.5378
2964.37	63.4689
2966.96	60.5128
2969.56	56.9021
2972.16	54.0429
2974.76	51.0609
2977.35	48.3782
2979.95	45.6741
2982.54	42.6095
2985.14	39.9454
2987.73	37.6068
2990.32	34.6499
2992.91	31.2554
2995.5	28.8767
2998.09	26.708
3000.68	23.6473
3003.26	21.6891
3005.85	19.1443
3008.43	17.5257
3011.02	15.3092
3013.6	13.1084
3016.19	11.4486
3018.77	10.0235
3021.35	8.71193
3023.93	8.30726
3026.5	7.9018
3029.08	6.79588
3031.66	6.77107
3034.24	6.75806
3036.81	6.25628
3039.39	5.96037
3041.96	6.61178
3044.53	7.07854
3047.1	6.69148
3049.67	6.73185
3052.24	7.26119
3054.81	6.85842
3057.38	6.40642
3059.95	5.61536
3062.52	4.88368
3065.08	4.73651
3067.65	4.27999
3070.21	4.11029
3072.77	3.58303
3075.33	3.13372
3077.89	2.75105
3080.45	2.49905
3083.01	2.438
3085.57	2.37589
3088.13	2.71484
3090.68	2.70084
3093.24	2.71301
3095.79	2.7115
3098.35	2.23353
3100.9	2.29807
3103.45	3.20045
3106	3.26021
3108.55	3.59135
3111.1	3.2264
3113.65	3.33983
3116.2	2.88668
3118.75	2.89357
3121.29	2.96083
3123.84	2.58053
3126.38	3.15897
3128.92	3.49465
3131.47	4.25488
3134.01	4.30053
3136.55	4.27669
3139.09	4.98849
3141.63	5.49627
3144.17	6.12978
3146.7	6.02408
3149.24	4.90956