File: data/Raman/poly_smoothed/Mb_40_y_21_1x_45s_532 nm_x100_100%_600 gr_mm_01.txt
#Acq. time (s)=	45
#Accumulations=	2
#Range (cm-¹)=	200...3150
#Windows=	2
#Auto scanning=	Off
#Autofocus=	Off
#Macrospot=	Off
#AutoExposure=	Off
#Spike filter=	Multiple accum.
#Delay time (s)=	0
#Binning=	1
#Readout mode=	Signal
#DeNoise=	Off
#ICS correction=	On
#Dark correction=	Off
#Inst. Process=	Off
#Detector Gain=	Best Dynamic Range
#Detector ADC=	20 kHz
#Detector temperature (°C)=	-69.85
#Instrument=	LabRAM HR Evol
#Detector=	Synapse
#Objective=	x100
#Grating=	600 gr/mm
#ND Filter=	100%
#Laser (nm)=	532
#Hole=	100.021
#Range=	Auto
#Laser Pol.=	No
#Raman. Pol.=	No
#Laser Pol. (°)=	-0.0007625
#Raman Pol. (°)=	89.9995
#Collection=	Microscope
#StageXY=	Marzhauser
#StageZ=	Marzhauser
#X (µm)=	-1025.3
#Y (µm)=	658
#Z (µm)=	584.35
#Full time(mm:ss)=	3:18
#Project=
#Sample=
#Site=
#Title=	Mb_40_y_21_2x_45s_532 nm_x100_100%_600 gr_mm
#Remark=
#Date=	19.07.2022 10:40
#Acquired=	19.07.2022 10:40:51
#Base:Fit=	10.08.2022 10:52:48
#Base:Sub=	10.08.2022 10:52:53
#Filter:Polynom=	16.08.2022 10:09:04
#AxisType[0]=Intens
#AxisUnit[0]=Cnt
#AxisType[1]=Spectr
#AxisUnit[1]=1/cm
200.423	39.9339
204.052	34.8499
207.682	30.0387
211.308	24.8435
214.935	22.0706
218.558	18.7307
222.18	15.4035
225.802	12.9813
229.421	10.25
233.039	8.29482
236.657	6.17309
240.272	5.42237
243.885	5.16048
247.497	2.88715
251.11	1.29461
254.719	1.24652
258.327	1.30576
261.933	-0.212234
265.538	-0.247236
269.141	3.02624
272.744	3.77789
276.344	3.18313
279.944	3.01285
283.542	4.32796
287.138	5.17098
290.733	6.7621
294.327	7.88316
297.919	8.70603
301.508	12.0141
305.098	13.9188
308.686	15.2775
312.273	15.7981
315.858	16.9786
319.44	17.1105
323.022	16.8175
326.604	18.5494
330.181	18.3293
333.76	16.1664
337.335	14.1668
340.91	13.5712
344.483	13.7574
348.055	12.3944
351.625	10.8925
355.195	11.621
358.762	11.469
362.329	11.5167
365.893	11.9047
369.455	11.0409
373.017	11.6001
376.578	13.34
380.137	14.0238
383.694	13.5815
387.249	14.2309
390.806	16.1682
394.359	17.2699
397.91	18.4705
401.46	19.0569
405.009	20.175
408.557	20.5068
412.103	21.4042
415.647	19.6148
419.191	18.6391
422.733	17.2939
426.273	16.4297
429.812	15.3308
433.35	14.1057
436.885	11.6663
440.42	11.6523
443.954	12.3246
447.486	11.2998
451.015	10.9172
454.545	11.5492
458.073	11.6148
461.598	12.5616
465.124	11.9402
468.648	12.0359
472.169	13.5612
475.69	16.2108
479.208	19.6187
482.727	23.0506
486.243	25.1051
489.759	27.4237
493.272	30.2336
496.783	31.9879
500.295	32.7685
503.804	33.8599
507.311	35.6974
510.819	36.0838
514.324	36.0022
517.827	36.2597
521.329	36.9894
524.83	36.2051
528.329	36.157
531.829	34.4553
535.326	33.0508
538.821	31.044
542.315	29.7408
545.808	26.3174
549.299	24.6643
552.789	22.5633
556.278	21.0322
559.763	19.1145
563.249	18.0356
566.733	16.7056
570.217	15.6811
573.699	14.4212
577.177	13.6811
580.656	14.1419
584.134	11.457
587.609	9.85138
591.084	7.2313
594.558	7.22628
598.029	6.49254
601.5	7.28764
604.968	7.0076
608.437	7.39429
611.902	5.63809
615.368	4.7042
618.831	3.8909
622.294	4.77237
625.755	5.45694
629.213	5.89606
632.673	7.78046
636.129	6.94911
639.584	8.95133
643.037	9.94432
646.491	10.6118
649.942	10.7588
653.392	12.0576
656.84	11.4865
660.287	10.5072
663.732	9.81377
667.177	7.93503
670.62	6.58003
674.061	8.45335
677.502	10.5343
680.941	11.3792
684.379	11.2237
687.815	11.8455
691.248	13.8383
694.682	13.8733
698.115	14.3902
701.546	16.2784
704.974	20.5184
708.402	24.8754
711.83	28.4316
715.254	32.6841
718.679	34.7145
722.102	36.5409
725.522	37.6078
728.943	37.839
732.361	37.8984
735.779	37.7641
739.194	38.5632
742.608	36.7977
746.022	37.5784
749.433	38.2185
752.843	39.4684
756.254	39.7161
759.661	42.2781
763.067	42.1236
766.471	43.2636
769.877	44.8007
773.279	45.8988
776.68	45.792
780.079	46.7215
783.478	50.3501
786.875	54.1699
790.27	57.2293
793.665	58.3954
797.058	60.657
800.45	60.3661
803.84	60.4243
807.23	58.657
810.616	58.7008
814.002	58.8554
817.388	59.5932
820.772	60.7921
824.153	61.0954
827.535	60.2725
830.915	59.9349
834.292	59.0733
837.67	57.2583
841.047	55.1503
844.42	52.9265
847.794	51.0764
851.165	49.5726
854.534	45.6923
857.905	44.3185
861.272	42.0183
864.639	40.2
868.004	38.1536
871.367	34.6254
874.731	32.7749
878.092	31.2142
881.451	29.7796
884.809	27.8791
888.166	27.0795
891.522	25.4636
894.878	25.9949
898.231	25.8728
901.583	26.4193
904.934	28.0296
908.283	26.3334
911.631	25.8565
914.976	26.4422
918.322	25.2126
921.666	25.4628
925.009	26.113
928.351	26.4714
931.692	26.1435
935.029	25.8495
938.367	25.189
941.704	24.5008
945.038	24.6575
948.372	24.7269
951.705	25.2543
955.035	25.3965
958.366	24.9828
961.693	22.1069
965.021	20.628
968.346	20.2257
971.67	20.1158
974.995	21.1526
978.316	21.5492
981.638	23.7671
984.957	24.3599
988.274	24.8657
991.59	23.938
994.907	21.2304
998.221	16.0451
1001.53	8.49055
1004.85	3.45876
1008.16	6.02929
1011.46	20.4503
1014.77	43.1227
1018.08	75.1168
1021.38	108.591
1024.69	139.55
1027.99	167.983
1031.29	190.411
1034.59	209.017
1037.89	221.991
1041.19	231.141
1044.48	236.04
1047.78	238.825
1051.07	235.842
1054.36	227.953
1057.66	214.731
1060.94	197.638
1064.23	174.811
1067.52	147.395
1070.81	118.488
1074.09	86.1619
1077.38	54.4655
1080.66	23.9635
1083.94	0.778655
1087.22	-9.51063
1090.5	-7.73562
1093.77	0.221365
1097.05	7.09834
1100.32	13.5939
1103.6	16.7437
1106.87	16.6845
1110.14	17.4401
1113.41	17.7388
1116.67	18.2203
1119.94	18.0066
1123.21	16.6622
1126.47	15.8683
1129.73	16.0954
1133	15.7914
1136.26	15.6231
1139.52	16.1555
1142.77	14.2255
1146.03	12.4315
1149.29	13.2397
1152.54	13.0162
1155.79	11.0098
1159.04	9.80939
1162.3	6.79485
1165.55	7.99688
1168.79	7.22437
1172.04	7.98938
1175.28	7.09504
1178.53	5.53838
1181.77	4.2469
1185.01	2.31527
1188.25	1.96824
1191.49	1.97997
1194.73	1.84178
1197.97	2.55029
1201.2	4.64369
1204.44	5.30184
1207.67	9.49573
1210.9	13.2172
1214.13	16.7827
1217.36	19.5496
1220.59	22.0694
1223.82	24.2753
1227.04	28.4387
1230.26	34.9089
1233.49	37.8266
1236.71	41.8564
1239.93	45.3894
1243.15	50.2216
1246.37	51.1347
1249.58	53.0483
1252.8	55.3729
1256.01	57.0658
1259.23	59.2488
1262.44	61.7536
1265.65	64.2192
1268.86	66.9975
1272.07	69.6083
1275.27	72.0553
1278.48	74.8393
1281.68	78.0651
1284.89	79.468
1288.09	80.4671
1291.29	82.2116
1294.49	83.0299
1297.69	82.7737
1300.88	83.4797
1304.08	85.3648
1307.27	87.7851
1310.47	88.5926
1313.66	87.5016
1316.85	87.3296
1320.04	88.2812
1323.23	87.5284
1326.41	87.6032
1329.6	88.7586
1332.78	86.6297
1335.97	85.0522
1339.15	85.0463
1342.33	82.8538
1345.51	79.9955
1348.69	77.0361
1351.87	73.8736
1355.04	69.5684
1358.22	65.7166
1361.39	61.2274
1364.57	57.3418
1367.74	55.9151
1370.91	51.8586
1374.07	47.9631
1377.24	45.9208
1380.41	44.8414
1383.57	45.5268
1386.74	45.6171
1389.9	44.5891
1393.06	45.3408
1396.22	46.049
1399.38	48.9404
1402.54	51.2807
1405.7	54.462
1408.85	57.3177
1412.01	61.3274
1415.16	66.376
1418.31	72.7523
1421.46	77.9211
1424.61	86.2285
1427.76	92.5918
1430.91	98.4788
1434.05	105.306
1437.2	113.307
1440.34	118.402
1443.49	122.754
1446.63	126.264
1449.77	126.917
1452.91	127.387
1456.04	127.6
1459.18	126.68
1462.31	124.695
1465.45	121.874
1468.58	116.565
1471.71	111.629
1474.84	106.872
1477.97	98.6998
1481.1	92.6026
1484.23	86.3905
1487.35	79.2754
1490.48	72.7248
1493.6	68.4438
1496.72	62.911
1499.84	59.4891
1502.96	55.4379
1506.08	51.0406
1509.2	46.3502
1512.31	43.8411
1515.43	41.4788
1518.54	38.3934
1521.66	36.0086
1524.77	36.3725
1527.88	33.3202
1530.99	33.0836
1534.09	33.9465
1537.2	35.5796
1540.31	38.9754
1543.41	40.8676
1546.51	41.769
1549.62	43.3281
1552.72	44.7553
1555.82	45.2653
1558.91	47.4636
1562.01	48.5736
1565.11	48.7909
1568.2	50.1399
1571.3	51.9096
1574.39	54.8449
1577.48	56.9981
1580.57	58.8917
1583.66	61.1812
1586.75	63.9823
1589.83	66.4673
1592.92	66.4244
1596	66.532
1599.09	66.8688
1602.17	65.6815
1605.25	65.3316
1608.33	64.7393
1611.41	66.2577
1614.48	66.995
1617.56	67.2662
1620.64	66.6203
1623.71	68.3288
1626.78	69.9428
1629.86	71.962
1632.92	72.8031
1635.99	74.3991
1639.06	77.6162
1642.13	80.0683
1645.19	82.7684
1648.26	86.1668
1651.32	88.5938
1654.38	90.3393
1657.45	92.0888
1660.51	91.8682
1663.57	89.5791
1666.62	86.55
1669.68	82.7226
1672.73	78.5404
1675.79	74.6323
1678.84	69.7685
1681.89	64.4201
1684.94	58.0406
1687.99	52.6501
1691.04	45.5177
1694.09	39.3377
1697.14	33.9713
1700.18	29.3404
1703.22	25.0003
1706.27	20.9073
1709.31	17.1957
1712.35	15.7657
1715.39	13.1548
1718.43	12.6406
1721.46	12.3354
1724.5	11.4084
1727.53	10.5781
1730.57	9.59673
1733.6	8.40724
1736.63	7.2063
1739.66	6.28343
1742.69	7.85116
1745.72	7.3521
1748.74	7.55176
1751.77	7.61348
1754.8	7.49456
1757.82	7.00148
1760.84	6.34875
1763.86	5.22864
1766.88	4.06134
1769.9	3.43552
1772.92	2.82062
1775.93	2.47242
1778.95	1.37459
1781.96	3.43039
1784.98	3.57127
1787.99	5.63581
1791	6.20583
1794.01	7.35067
1797.02	7.36117
1800.03	7.15878
1803.03	6.79431
1806.04	6.27975
1809.04	6.92335
1812.04	6.03221
1815.05	5.64745
1818.05	5.9833
1821.05	5.85492
1824.05	5.74778
1827.04	5.90377
1830.04	6.15655
1833.03	5.95235
1836.03	6.50288
1839.02	5.64348
1842.01	5.59153
1845	6.42431
1847.99	6.70634
1850.98	7.81445
1853.97	9.62374
1856.95	10.6599
1859.94	11.1027
1862.92	11.3134
1865.91	12.1017
1868.89	11.7702
1871.87	12.0318
1874.85	12.6956
1877.83	12.0218
1880.8	12.2473
1882.56	12.0558
1885.54	10.5764
1888.53	10.7069
1891.52	10.0802
1894.5	9.79602
1897.49	9.52266
1900.47	9.42221
1903.45	10.6447
1906.43	10.7126
1909.41	9.66443
1912.39	9.15309
1915.37	10.6757
1918.35	9.59362
1921.32	9.24377
1924.3	8.57393
1927.27	7.4372
1930.24	6.43811
1933.21	5.36927
1936.18	6.30154
1939.15	5.23193
1942.12	4.30675
1945.09	4.27441
1948.05	3.52471
1951.02	3.46352
1953.98	3.02708
1956.94	2.72443
1959.91	1.92297
1962.87	2.16499
1965.82	2.85089
1968.78	4.13496
1971.74	4.85527
1974.7	5.56556
1977.65	5.5533
1980.6	5.72923
1983.56	5.48097
1986.51	5.77956
1989.46	5.87936
1992.41	5.36338
1995.36	5.68901
1998.3	6.68597
2001.25	7.43488
2004.2	8.26179
2007.14	9.25761
2010.08	9.27865
2013.02	9.07098
2015.97	8.76845
2018.9	9.12311
2021.84	11.05
2024.78	11.3054
2027.72	10.5458
2030.65	11.3881
2033.59	12.2055
2036.52	13.3724
2039.45	14.0575
2042.38	12.937
2045.31	12.8384
2048.24	13.8052
2051.17	14.274
2054.1	14.2677
2057.02	14.1113
2059.95	15.0579
2062.87	17.4111
2065.79	18.2053
2068.71	19.7362
2071.63	20.3013
2074.55	20.6095
2077.47	21.4753
2080.39	22.7341
2083.3	24.2439
2086.22	26.8226
2089.13	28.4519
2092.05	30.0308
2094.96	31.3791
2097.87	32.0873
2100.78	33.6118
2103.69	35.7727
2106.59	37.9287
2109.5	39.5966
2112.41	43.4664
2115.31	46.5929
2118.21	50.7349
2121.12	54.3968
2124.02	58.0804
2126.92	62.6403
2129.82	67.5774
2132.71	72.1733
2135.61	75.79
2138.51	79.2
2141.4	82.5861
2144.29	87.387
2147.19	91.3879
2150.08	96.0204
2152.97	100.273
2155.86	103.576
2158.75	106.744
2161.64	109.498
2164.52	110.401
2167.41	111.982
2170.29	112.907
2173.17	114.208
2176.06	113.143
2178.94	113.372
2181.82	112.355
2184.7	111.365
2187.57	108.788
2190.45	106.582
2193.33	104.363
2196.2	101.433
2199.08	97.3032
2201.95	92.297
2204.82	87.5536
2207.69	83.703
2210.56	80.6303
2213.43	76.3153
2216.3	72.0953
2219.16	68.2256
2222.03	64.7547
2224.89	60.8711
2227.75	57.2856
2230.62	52.9021
2233.48	49.3398
2236.34	45.1691
2239.2	42.0873
2242.06	39.1977
2244.91	35.9669
2247.77	32.8844
2250.62	31.4253
2253.48	30.0492
2256.33	28.9297
2259.18	27.5667
2262.03	27.5674
2264.88	25.7912
2267.73	24.0914
2270.58	23.5485
2273.43	23.544
2276.27	23.0439
2279.12	23.6863
2281.96	21.9864
2284.8	20.0761
2287.64	18.9367
2290.49	17.66
2293.32	16.1534
2296.16	14.4548
2299	13.4834
2301.84	13.1954
2304.67	12.2374
2307.51	11.9362
2310.34	11.3319
2313.17	11.2305
2316	10.6066
2318.83	11.2133
2321.66	10.5014
2324.49	9.08787
2327.32	8.64483
2330.15	8.30498
2332.97	7.4452
2335.79	6.46473
2338.62	6.52896
2341.44	5.79129
2344.26	5.3573
2347.08	5.58195
2349.9	5.54691
2352.72	4.07612
2355.53	3.44556
2358.35	3.55979
2361.17	3.05542
2363.98	3.29996
2366.79	2.71095
2369.6	3.29638
2372.42	2.81746
2375.22	3.97205
2378.03	3.74627
2380.84	3.34236
2383.65	2.89349
2386.45	3.87732
2389.26	2.46819
2392.06	2.29249
2394.87	3.00973
2397.67	2.95544
2400.47	4.15214
2403.27	3.62916
2406.07	4.45467
2408.86	4.57883
2411.66	3.66287
2414.46	4.69857
2417.25	5.47564
2420.05	5.73163
2422.84	5.58891
2425.63	5.8549
2428.42	6.45022
2431.21	6.07764
2434	6.98695
2436.79	7.10355
2439.57	6.81749
2442.36	6.91141
2445.14	6.36147
2447.93	6.43033
2450.71	5.63346
2453.49	6.12308
2456.27	6.44665
2459.05	7.14613
2461.83	7.74591
2464.61	7.92053
2467.39	6.8607
2470.16	5.8186
2472.94	4.56187
2475.71	3.76473
2478.48	3.2988
2481.25	2.86314
2484.02	3.98534
2486.8	2.51131
2489.56	2.85123
2492.33	3.29646
2495.1	3.31127
2497.86	3.45858
2500.63	2.57994
2503.39	1.85871
2506.16	1.64063
2508.92	2.23764
2511.68	2.16912
2514.44	1.85413
2517.2	1.82146
2519.95	2.96264
2522.71	4.08393
2525.47	4.00059
2528.22	3.76909
2530.98	4.66638
2533.73	5.14582
2536.48	4.36355
2539.23	4.15062
2541.98	5.14512
2544.73	5.56539
2547.48	6.10785
2550.23	7.07749
2552.97	6.95135
2555.72	6.72266
2558.46	7.01793
2561.2	7.64793
2563.95	7.13993
2566.69	7.24362
2569.43	7.35795
2572.17	8.14476
2574.91	9.31952
2577.64	10.4155
2580.38	9.69021
2583.11	9.86138
2585.85	11.1452
2588.58	12.2212
2591.31	11.8676
2594.04	11.3853
2596.78	11.225
2599.51	11.4992
2602.23	10.9595
2604.96	9.53065
2607.69	9.19129
2610.41	8.80024
2613.14	8.421
2615.86	7.24662
2618.58	7.18881
2621.3	6.4245
2624.03	7.03887
2626.75	6.76595
2629.46	6.36322
2632.18	7.37182
2634.9	7.0758
2637.61	7.93438
2640.33	8.63056
2643.04	9.69262
2645.76	9.87624
2648.47	11.0152
2651.18	12.7234
2653.89	13.5583
2656.6	13.8549
2659.31	13.1815
2662.01	12.6272
2664.72	13.1638
2667.43	13.1304
2670.13	12.8286
2672.83	12.7481
2675.53	13.1781
2678.24	12.7976
2680.94	14.0275
2683.64	14.0449
2686.34	14.319
2689.03	14.0914
2691.73	13.8421
2694.43	13.4868
2697.12	12.7871
2699.81	12.8859
2702.51	13.0575
2705.2	12.1731
2707.89	11.5275
2710.58	12.4249
2713.27	12.8005
2715.96	13.2527
2718.64	14.3655
2721.33	14.3337
2724.01	13.8021
2726.7	13.9959
2729.38	14.3014
2732.06	14.2538
2734.75	14.2542
2737.43	14.0184
2740.11	13.7037
2742.78	13.5347
2745.46	12.9513
2748.14	12.4397
2750.81	11.8892
2753.49	11.4257
2756.16	10.0041
2758.84	9.46554
2761.51	8.21443
2764.18	7.32134
2766.85	5.28355
2769.52	3.53329
2772.19	3.43367
2774.85	3.26473
2777.52	3.38474
2780.18	2.81718
2782.85	4.03408
2785.51	3.72572
2788.17	2.43313
2790.84	2.12879
2793.5	1.20079
2796.16	1.13103
2798.81	0.919049
2801.47	1.15025
2804.13	0.320232
2806.79	-0.654378
2809.44	-1.62736
2812.09	-1.90068
2814.75	-0.649924
2817.4	0.975332
2820.05	4.96464
2822.7	9.95911
2825.35	15.388
2828	21.3582
2830.65	28.8127
2833.29	36.8048
2835.94	45.7199
2838.58	54.9298
2841.23	64.7845
2843.87	74.3657
2846.51	84.1744
2849.15	93.7676
2851.79	103.664
2854.43	115.339
2857.07	126.723
2859.71	137.327
2862.34	146.46
2864.98	153.696
2867.61	159.84
2870.25	164.942
2872.88	168.577
2875.51	172.969
2878.14	177.728
2880.77	182.761
2883.4	187.891
2886.03	192.42
2888.65	197.767
2891.28	202.657
2893.91	207.798
2896.53	213.4
2899.15	218.488
2901.78	225.44
2904.4	234.458
2907.02	243.176
2909.64	252.727
2912.26	264.28
2914.87	276.806
2917.49	289.83
2920.11	300.84
2922.72	310.396
2925.34	317.274
2927.95	323.604
2930.56	328.473
2933.17	330.271
2935.78	328.347
2938.39	326.515
2941	322.931
2943.61	316.391
2946.22	308.17
2948.82	297.039
2951.43	286.467
2954.03	273.407
2956.64	260.543
2959.24	246.934
2961.84	233.23
2964.44	218.315
2967.04	205.295
2969.64	192.085
2972.24	178.884
2974.83	166.394
2977.43	155.045
2980.02	143.659
2982.62	131.501
2985.21	119.769
2987.8	107.992
2990.4	96.9621
2992.99	86.0223
2995.57	76.8491
2998.16	66.2859
3000.75	58.0628
3003.34	50.51
3005.92	42.364
3008.51	34.8203
3011.09	28.4384
3013.68	22.5748
3016.26	17.6515
3018.84	13.9931
3021.42	11.1324
3024	7.51847
3026.58	5.66015
3029.16	3.70679
3031.73	2.27461
3034.31	1.51691
3036.89	0.858539
3039.46	0.830696
3042.03	1.035
3044.61	0.444219
3047.18	-0.213349
3049.75	-0.384389
3052.32	-0.554103
3054.89	-0.720588
3057.45	0.149712
3060.02	0.550032
3062.59	0.836345
3065.15	1.02798
3067.72	0.686284
3070.28	0.983647
3072.84	0.204708
3075.41	0.0213668
3077.97	-0.319893
3080.53	0.396545
3083.09	0.86813
3085.64	0.616197
3088.2	0.727114
3090.76	0.0707807
3093.31	-0.431793
3095.87	-0.058841
3098.42	-0.0654783
3100.97	-0.203498
3103.53	0.225813
3106.08	-1.34277
3108.63	-0.423241
3111.18	-0.0798091
3113.73	1.05468
3116.27	3.10691
3118.82	3.73433
3121.37	5.5106
3123.91	6.95231
3126.45	8.29251
3129	10.0181
3131.54	11.6679
3134.08	13.2037
3136.62	15.619
3139.16	17.5881
3141.7	19.5456
3144.24	21.4053
3146.78	22.0046
3149.31	21.8244