File: data/Raman/poly_smoothed/Mb_40_y_02_1x_45s_532 nm_x100_100%_600 gr_mm_01.txt
#Acq. time (s)=	45
#Accumulations=	2
#Range (cm-¹)=	200...3150
#Windows=	2
#Auto scanning=	Off
#Autofocus=	Off
#Macrospot=	Off
#AutoExposure=	Off
#Spike filter=	Multiple accum.
#Delay time (s)=	0
#Binning=	1
#Readout mode=	Signal
#DeNoise=	Off
#ICS correction=	On
#Dark correction=	Off
#Inst. Process=	Off
#Detector Gain=	Best Dynamic Range
#Detector ADC=	20 kHz
#Detector temperature (°C)=	-69.85
#Instrument=	LabRAM HR Evol
#Detector=	Synapse
#Objective=	x100
#Grating=	600 gr/mm
#ND Filter=	100%
#Laser (nm)=	532
#Hole=	100.021
#Range=	Auto
#Laser Pol.=	No
#Raman. Pol.=	No
#Laser Pol. (°)=	-0.0007625
#Raman Pol. (°)=	89.9995
#Collection=	Microscope
#StageXY=	Marzhauser
#StageZ=	Marzhauser
#X (µm)=	-1246.7
#Y (µm)=	2711.7
#Z (µm)=	587.1
#Full time(mm:ss)=	3:18
#Project=
#Sample=
#Site=
#Title=	Mb_40_y_02_2x_45s_532 nm_x100_100%_600 gr_mm
#Remark=
#Date=	18.07.2022 15:15
#Acquired=	18.07.2022 15:15:14
#Base:Fit=	10.08.2022 10:52:48
#Base:Sub=	10.08.2022 10:52:53
#Filter:Polynom=	16.08.2022 10:09:04
#AxisType[0]=Intens
#AxisUnit[0]=Cnt
#AxisType[1]=Spectr
#AxisUnit[1]=1/cm
200.419	28.5601
204.048	30.7135
207.678	30.4509
211.304	30.7312
214.928	31.466
218.554	30.6009
222.176	27.1732
225.798	23.2232
229.417	21.0109
233.035	18.8878
236.653	17.9928
240.268	16.7808
243.881	17.3482
247.493	17.5474
251.103	17.7962
254.715	15.8847
258.322	14.3855
261.929	13.9711
265.534	14.739
269.137	14.4993
272.739	14.3237
276.34	15.0044
279.939	15.8975
283.537	14.3991
287.134	14.0382
290.729	14.9582
294.323	14.7702
297.913	13.3551
301.504	14.4975
305.093	12.6663
308.682	12.4806
312.268	11.8928
315.852	12.5606
319.436	11.3421
323.018	11.8616
326.597	11.296
330.177	11.6265
333.753	12.4279
337.331	11.8617
340.906	10.1099
344.478	9.38891
348.051	10.2878
351.621	9.66047
355.189	9.3222
358.757	9.66598
362.323	7.67141
365.889	7.97171
369.451	8.11484
373.012	7.75685
376.574	9.37053
380.133	10.4897
383.69	10.5817
387.245	11.4614
390.8	13.0171
394.353	12.543
397.906	13.1053
401.456	12.7595
405.005	11.2997
408.552	10.8211
412.099	9.83259
415.643	9.69993
419.187	10.1436
422.728	9.72829
426.269	8.15462
429.806	6.75501
433.344	6.27408
436.881	5.35242
440.416	4.63247
443.949	3.66941
447.48	3.56877
451.011	3.8079
454.541	5.93906
458.069	7.13732
461.594	7.98665
465.119	8.25316
468.642	9.2711
472.165	8.98523
475.684	11.3613
479.204	11.3758
482.721	11.8096
486.239	13.2206
489.753	14.7953
493.268	16.972
496.779	17.1688
500.289	17.6163
503.8	18.2527
507.307	18.7701
510.813	20.3717
514.32	19.6914
517.823	20.8406
521.325	19.7188
524.826	20.7643
528.325	20.4274
531.823	18.7354
535.32	18.5698
538.815	20.1865
542.309	18.0594
545.802	15.8681
549.293	13.8475
552.783	13.9431
556.271	12.2348
559.759	10.8168
563.245	10.7318
566.729	8.68112
570.213	7.87361
573.693	5.40338
577.173	5.37791
580.652	5.27231
584.13	6.03553
587.605	6.38063
591.08	5.71027
594.552	6.46638
598.025	6.05716
601.496	6.40144
604.964	7.21507
608.433	7.37524
611.898	7.78574
615.364	8.19709
618.827	8.44375
622.288	8.15158
625.75	8.36257
629.209	8.52402
632.667	9.47258
636.125	10.207
639.58	11.6494
643.033	13.2267
646.485	14.3355
649.936	14.5828
653.388	14.3006
656.836	14.3046
660.283	15.7958
663.728	17.111
667.173	16.0887
670.616	16.3565
674.057	16.8937
677.498	19.3949
680.937	21.7209
684.375	23.8495
687.809	26.8212
691.244	27.745
694.678	28.9194
698.111	31.7106
701.54	33.8877
704.97	35.91
708.398	38.1616
711.826	38.9691
715.25	39.6081
718.675	41.613
722.096	42.2832
725.518	43.6142
728.937	42.8339
732.357	43.649
735.773	42.9418
739.19	43.6788
742.604	41.9578
746.018	42.3407
749.429	41.5181
752.839	44.9871
756.248	49.0182
759.657	51.8471
763.063	53.9663
766.468	56.2855
769.871	57.0807
773.273	59.7117
776.676	61.3223
780.075	65.0372
783.474	66.9262
786.871	67.8856
790.266	70.0567
793.661	70.7289
797.054	71.598
800.446	73.4467
803.834	72.943
807.224	72.9663
810.612	70.5388
813.998	69.7373
817.384	69.6667
820.766	69.4726
824.149	69.152
827.531	68.7595
830.909	69.059
834.288	68.4754
837.666	67.5681
841.041	63.6872
844.416	61.9336
847.788	59.5879
851.161	55.0157
854.53	52.5589
857.901	49.6399
861.268	46.0251
864.633	46.2181
868	44.1213
871.363	40.9083
874.725	39.5157
878.088	37.8722
881.447	37.0667
884.805	35.8945
888.162	35.0286
891.518	33.881
894.872	34.5299
898.225	35.1585
901.577	38.3305
904.928	39.7787
908.277	39.1066
911.625	40.078
914.972	41.9511
918.318	43.0394
921.662	44.6777
925.005	45.7931
928.347	47.9142
931.686	48.6969
935.025	50.1319
938.363	51.6602
941.698	51.2053
945.034	52.2332
948.368	51.984
951.699	50.3924
955.031	50.3885
958.36	50.629
961.689	49.6102
965.016	49.5226
968.343	48.243
971.666	46.3281
974.991	45.3155
978.312	43.0374
981.632	42.6318
984.953	39.9503
988.27	36.7549
991.587	33.407
994.902	31.2139
998.216	27.6513
1001.53	22.9916
1004.84	20.9
1008.15	26.4749
1011.46	37.6113
1014.77	57.0779
1018.07	78.8933
1021.38	100.925
1024.68	123.554
1027.99	142.632
1031.29	159.525
1034.59	173.856
1037.89	183.222
1041.18	189.839
1044.48	194.141
1047.77	194.815
1051.07	191.859
1054.36	184.943
1057.65	174.458
1060.94	159.464
1064.23	142.702
1067.52	120.94
1070.8	98.484
1074.09	75.406
1077.37	53.2607
1080.65	34.3276
1083.93	22.3113
1087.21	16.4561
1090.49	18.5451
1093.77	22.1054
1097.04	28.5901
1100.32	31.1443
1103.59	35.0879
1106.86	37.1324
1110.13	36.554
1113.4	37.0478
1116.67	36.606
1119.94	34.8601
1123.2	34.8543
1126.47	33.1375
1129.73	30.3397
1132.99	26.9701
1136.25	22.8835
1139.51	18.7014
1142.77	17.0291
1146.03	14.7297
1149.28	11.7732
1152.54	8.97279
1155.79	6.44946
1159.04	4.57575
1162.29	4.24486
1165.54	3.27641
1168.79	2.29446
1172.04	1.8127
1175.28	3.70284
1178.53	4.94457
1181.77	6.97997
1185.01	9.28919
1188.25	10.3
1191.49	11.5898
1194.73	13.787
1197.96	15.2724
1201.2	17.0405
1204.43	20.037
1207.66	21.3057
1210.9	23.9708
1214.13	26.9427
1217.36	30.1985
1220.58	35.0072
1223.81	37.0928
1227.04	40.4551
1230.26	43.104
1233.48	46.3659
1236.71	47.8227
1239.93	50.2035
1243.14	51.9297
1246.36	53.2865
1249.58	54.8118
1252.8	54.6758
1256.01	56.5636
1259.22	58.5839
1262.43	61.6124
1265.64	63.2375
1268.85	64.2699
1272.06	68.4556
1275.27	71.4915
1278.48	74.3266
1281.68	75.9039
1284.88	77.0916
1288.08	79.4405
1291.28	81.6897
1294.48	83.5702
1297.68	84.9611
1300.88	86.2039
1304.07	87.464
1307.27	87.9103
1310.46	87.5062
1313.65	86.5722
1316.85	83.5488
1320.03	82.3285
1323.22	80.6836
1326.41	79.8375
1329.6	79.1629
1332.78	76.987
1335.96	76.2144
1339.15	75.6128
1342.33	73.9218
1345.51	73.2759
1348.69	70.2369
1351.86	69.1144
1355.04	64.9503
1358.21	61.9997
1361.39	57.6483
1364.56	55.7207
1367.73	53.7009
1370.9	51.4017
1374.07	49.6866
1377.24	47.7745
1380.41	46.2488
1383.57	45.0363
1386.73	46.5685
1389.9	46.8317
1393.06	47.0069
1396.22	48.4232
1399.38	49.7103
1402.54	52.0235
1405.69	54.576
1408.85	55.7226
1412	57.919
1415.16	61.4949
1418.31	66.585
1421.46	70.6669
1424.61	75.5954
1427.76	79.7062
1430.9	84.2918
1434.05	86.6493
1437.2	89.9306
1440.34	92.575
1443.48	96.656
1446.62	98.5188
1449.76	98.6211
1452.9	99.1298
1456.04	98.5383
1459.17	96.6329
1462.31	95.4717
1465.44	91.6111
1468.58	88.1443
1471.71	83.7474
1474.84	78.8527
1477.97	71.9167
1481.1	65.5528
1484.22	58.7058
1487.35	54.3264
1490.47	50.9794
1493.59	46.2413
1496.72	43.6721
1499.84	39.4673
1502.96	36.3351
1506.08	32.5667
1509.19	27.9917
1512.31	26.6977
1515.42	25.7808
1518.54	25.8959
1521.65	25.1607
1524.76	26.8405
1527.87	25.4083
1530.98	26.5483
1534.09	26.1751
1537.2	28.3817
1540.3	29.775
1543.41	32.7006
1546.51	33.8587
1549.61	33.7678
1552.71	34.9192
1555.81	37.6372
1558.91	40.0612
1562.01	43.2746
1565.1	46.2292
1568.2	48.0823
1571.29	49.9323
1574.38	52.3622
1577.48	54.1808
1580.57	56.9824
1583.65	58.8116
1586.74	62.025
1589.83	63.633
1592.92	63.5232
1596	63.6697
1599.08	63.9323
1602.16	62.8713
1605.24	59.6885
1608.32	60.4527
1611.4	59.6044
1614.48	58.6156
1617.56	58.6383
1620.63	58.8296
1623.71	59.566
1626.78	59.4811
1629.85	62.6217
1632.92	65.5464
1635.99	68.4562
1639.06	70.7358
1642.12	73.2901
1645.19	76.3276
1648.25	78.8252
1651.32	80.498
1654.38	82.4159
1657.44	82.8504
1660.5	81.9408
1663.56	80.6166
1666.62	77.9559
1669.67	74.5823
1672.73	70.6085
1675.79	65.2828
1678.84	59.772
1681.89	55.2837
1684.94	50.3568
1687.99	45.8246
1691.04	41.4983
1694.08	38.3217
1697.13	33.9721
1700.18	29.798
1703.22	25.5143
1706.26	24.7912
1709.3	21.2085
1712.35	17.4983
1715.39	15.7497
1718.42	13.1241
1721.46	12.0543
1724.5	11.205
1727.53	10.3646
1730.56	9.98559
1733.6	8.91654
1736.63	7.79533
1739.66	7.55261
1742.69	6.43657
1745.71	4.96016
1748.74	4.16058
1751.77	2.94471
1754.79	2.8747
1757.81	4.0501
1760.84	3.47231
1763.86	4.04183
1766.88	4.33924
1769.9	3.67235
1772.91	3.51079
1775.93	4.13433
1778.95	4.35913
1781.96	3.57094
1784.97	3.02751
1787.99	3.55487
1791	4.49051
1794.01	4.77935
1797.01	5.15585
1800.02	4.88994
1803.03	5.36375
1806.03	5.74653
1809.04	5.84953
1812.04	6.1075
1815.04	5.81319
1818.04	5.55688
1821.04	5.86631
1824.04	6.09782
1827.04	6.57178
1830.03	7.40618
1833.03	7.05818
1836.02	7.95708
1839.02	8.54632
1842.01	9.76881
1845	9.50535
1847.99	10.2196
1850.98	10.9151
1853.96	9.57258
1856.95	10.2067
1859.94	8.79745
1862.92	9.02286
1865.9	9.34703
1868.88	8.72183
1871.86	7.3931
1874.84	7.21949
1877.82	7.41325
1880.8	6.90261
1882.58	8.13176
1885.57	9.08718
1888.56	7.94358
1891.54	6.97924
1894.53	7.08323
1897.51	6.43573
1900.5	7.23867
1903.48	7.10618
1906.46	7.28351
1909.44	7.46025
1912.42	8.07926
1915.4	8.58178
1918.37	8.22613
1921.35	7.97682
1924.32	6.74482
1927.3	5.86803
1930.27	5.0912
1933.24	3.97836
1936.21	4.26645
1939.18	2.66109
1942.15	1.03678
1945.11	1.10679
1948.08	1.17873
1951.04	1.32122
1954.01	1.71664
1956.97	2.81599
1959.93	0.198168
1962.89	-1.201
1965.85	-0.602542
1968.81	1.82751
1971.77	2.06352
1974.72	3.08648
1977.68	3.28352
1980.63	2.87613
1983.58	3.82023
1986.53	5.9963
1989.48	6.07338
1992.43	7.02019
1995.38	7.3427
1998.33	7.73109
2001.27	8.21355
2004.22	7.6024
2007.16	7.66647
2010.11	7.69526
2013.05	6.94926
2015.99	7.89148
2018.93	8.22611
2021.87	8.05858
2024.8	8.58929
2027.74	8.06016
2030.68	7.49475
2033.61	8.5452
2036.54	9.70503
2039.48	11.6264
2042.41	12.8275
2045.34	14.1295
2048.27	13.0666
2051.19	12.9659
2054.12	14.0452
2057.05	15.9158
2059.97	17.22
2062.9	17.8612
2065.82	18.4622
2068.74	19.0852
2071.66	19.7955
2074.58	20.1304
2077.5	19.8833
2080.41	21.21
2083.33	22.6877
2086.24	23.6874
2089.16	25.1174
2092.07	26.8031
2094.98	28.5513
2097.89	30.6523
2100.8	34.2012
2103.71	37.0515
2106.62	39.8708
2109.53	42.9746
2112.43	45.8365
2115.33	48.1701
2118.24	51.0663
2121.14	54.2744
2124.04	58.9585
2126.94	62.8567
2129.84	66.5605
2132.74	69.8693
2135.63	74.4002
2138.53	78.6219
2141.43	82.6978
2144.32	86.096
2147.21	90.9969
2150.1	96.5163
2152.99	100.593
2155.88	102.645
2158.77	105.126
2161.66	108.914
2164.55	111.218
2167.43	114.641
2170.31	114.87
2173.2	114.466
2176.08	113.055
2178.96	111.037
2181.84	109.05
2184.72	106.834
2187.6	104.999
2190.47	102.585
2193.35	98.932
2196.23	95.169
2199.1	92.1601
2201.97	89.3162
2204.84	86.3092
2207.71	83.7811
2210.58	80.5513
2213.45	76.1925
2216.32	72.8282
2219.19	69.906
2222.05	66.5822
2224.92	63.5133
2227.78	60.4281
2230.64	56.8111
2233.5	54.4223
2236.36	50.5437
2239.22	45.6539
2242.08	42.1867
2244.94	38.6917
2247.79	35.2966
2250.65	33.0675
2253.5	31.0386
2256.36	28.0794
2259.21	25.0594
2262.06	24.4592
2264.91	22.4648
2267.76	20.5923
2270.6	18.9784
2273.45	17.9479
2276.3	15.9749
2279.14	13.9735
2281.98	11.9552
2284.83	11.8445
2287.67	12.2124
2290.51	11.4193
2293.35	9.48667
2296.19	8.30616
2299.02	9.14481
2301.86	9.81774
2304.7	9.46519
2307.53	8.94246
2310.36	9.05089
2313.2	10.4813
2316.03	10.4935
2318.86	11.5464
2321.69	10.9675
2324.51	10.661
2327.34	10.8475
2330.17	10.215
2332.99	11.2293
2335.82	8.95783
2338.64	7.73122
2341.46	7.78934
2344.28	6.7495
2347.1	6.04457
2349.92	6.1407
2352.74	5.59255
2355.56	4.78704
2358.37	2.92399
2361.19	1.87566
2364	1.23442
2366.82	3.14786
2369.63	3.08539
2372.44	2.78743
2375.25	2.80213
2378.06	4.06953
2380.86	5.18839
2383.67	5.01376
2386.48	5.33995
2389.28	4.26835
2392.09	5.57732
2394.89	5.61114
2397.69	5.72845
2400.49	4.80261
2403.29	5.56058
2406.09	5.08786
2408.89	5.60089
2411.69	6.12395
2414.48	6.77713
2417.28	7.8362
2420.07	7.98514
2422.86	7.71963
2425.65	6.7824
2428.45	7.10291
2431.23	6.77117
2434.02	7.41013
2436.81	7.14462
2439.6	6.87387
2442.38	6.2446
2445.17	7.45752
2447.95	7.00571
2450.73	5.92818
2453.52	4.54057
2456.3	3.75915
2459.08	3.81084
2461.85	3.51327
2464.63	1.15927
2467.41	1.31664
2470.19	0.528309
2472.96	0.619201
2475.73	-0.569361
2478.51	-0.0487454
2481.28	0.0120773
2484.05	-0.360584
2486.82	-1.06737
2489.59	-1.36771
2492.35	-1.72817
2495.12	-1.38864
2497.89	-0.533384
2500.65	-2.03252
2503.42	-1.35035
2506.18	-0.906346
2508.94	-0.720818
2511.7	0.17124
2514.46	0.389909
2517.22	-0.385455
2519.98	-0.826786
2522.73	0.182221
2525.49	0.412751
2528.25	0.954928
2531	1.01556
2533.75	2.68577
2536.5	2.02635
2539.25	2.3302
2542.01	2.61714
2544.75	3.62193
2547.5	3.54021
2550.25	4.18493
2553	3.64362
2555.74	4.59639
2558.49	4.49637
2561.23	3.94765
2563.97	3.79297
2566.71	2.76587
2569.45	2.29444
2572.19	2.84968
2574.93	2.74781
2577.67	2.86492
2580.4	2.19509
2583.14	2.15985
2585.87	1.8706
2588.6	1.5451
2591.34	1.47214
2594.07	2.24656
2596.8	2.38189
2599.53	3.28215
2602.26	2.74683
2604.98	2.61883
2607.71	2.5867
2610.44	1.7992
2613.16	2.31716
2615.88	1.47336
2618.61	1.63097
2621.33	2.13663
2624.05	1.40154
2626.77	0.203604
2629.49	0.190661
2632.21	0.430838
2634.92	1.35788
2637.64	1.81727
2640.35	2.77329
2643.07	3.33987
2645.78	2.8845
2648.49	3.31677
2651.2	3.34513
2653.91	4.08651
2656.62	3.62472
2659.33	3.91222
2662.04	4.00722
2664.74	3.78112
2667.45	3.93872
2670.15	4.06191
2672.86	3.70711
2675.56	3.39188
2678.26	4.08285
2680.96	3.98925
2683.66	4.27234
2686.36	4.80706
2689.06	5.22542
2691.75	5.45234
2694.45	6.21502
2697.14	6.93556
2699.84	8.41393
2702.53	8.63505
2705.22	9.81511
2707.91	9.76653
2710.6	10.5869
2713.29	11.0176
2715.98	11.145
2718.67	12.3053
2721.35	12.8384
2724.04	11.8742
2726.72	11.3385
2729.4	10.9718
2732.09	9.31353
2734.77	9.18226
2737.45	7.53283
2740.13	6.35903
2742.81	5.89892
2745.48	4.84274
2748.16	4.64706
2750.84	4.16741
2753.51	3.59513
2756.19	3.31182
2758.86	3.27194
2761.53	2.27856
2764.2	1.98166
2766.87	2.6074
2769.54	3.62839
2772.21	4.34961
2774.88	4.70919
2777.54	5.94614
2780.21	6.66598
2782.87	7.17612
2785.53	7.1083
2788.2	6.3512
2790.86	4.41013
2793.52	4.90446
2796.18	4.13649
2798.84	3.85487
2801.49	4.38287
2804.15	4.19463
2806.81	3.98636
2809.46	4.36029
2812.12	3.96104
2814.77	4.07148
2817.42	3.88533
2820.07	5.00307
2822.72	7.93414
2825.37	9.93738
2828.02	13.5181
2830.67	18.3526
2833.31	23.5484
2835.96	28.405
2838.61	33.6441
2841.25	39.8877
2843.89	46.0417
2846.53	51.8038
2849.17	59.1977
2851.81	65.1973
2854.45	72.5341
2857.09	79.8013
2859.73	86.6372
2862.36	92.2736
2865	98.5376
2867.64	104.303
2870.27	108.712
2872.9	114.032
2875.53	117.74
2878.16	121.832
2880.79	125.974
2883.42	130.34
2886.05	135.75
2888.68	140.984
2891.3	146.423
2893.93	153.364
2896.55	160.308
2899.18	168.102
2901.8	175.308
2904.42	183.61
2907.04	193.498
2909.66	204.212
2912.28	215.223
2914.9	225.143
2917.51	235.907
2920.13	245.848
2922.74	254.872
2925.36	262.352
2927.97	269.401
2930.59	273.453
2933.2	275.506
2935.81	276.512
2938.42	275.402
2941.02	272.593
2943.63	267.104
2946.24	259.919
2948.85	252.455
2951.45	243.654
2954.05	234.022
2956.66	224.179
2959.26	213.326
2961.86	200.485
2964.46	188.797
2967.06	177.641
2969.66	167.168
2972.26	157.732
2974.85	147.751
2977.45	137.957
2980.05	128.925
2982.64	120.532
2985.23	111.281
2987.83	102.668
2990.42	93.8625
2993.01	85.1436
2995.6	76.9162
2998.19	68.7824
3000.77	62.4201
3003.36	55.1958
3005.95	49.3183
3008.53	43.1967
3011.12	39.0304
3013.7	34.311
3016.28	30.199
3018.86	26.9169
3021.44	23.6962
3024.02	21.3753
3026.6	20.3694
3029.18	19.247
3031.76	18.0577
3034.33	17.1932
3036.91	16.4672
3039.48	15.7977
3042.05	14.6853
3044.63	13.4828
3047.2	12.6277
3049.77	11.7649
3052.34	11.5253
3054.91	10.4886
3057.48	9.38747
3060.04	8.34682
3062.61	7.58576
3065.17	6.08013
3067.74	4.9406
3070.3	5.43626
3072.87	4.06009
3075.43	3.56481
3077.99	3.74124
3080.55	3.55497
3083.11	3.39692
3085.67	3.03288
3088.22	3.44678
3090.78	2.4203
3093.34	2.64348
3095.89	2.8209
3098.44	2.20561
3101	2.10319
3103.55	1.89947
3106.1	2.1581
3108.65	2.64156
3111.2	2.99081
3113.75	4.47991
3116.3	3.58884
3118.84	3.68732
3121.39	3.58084
3123.93	3.44817
3126.48	2.26851
3129.02	2.26724
3131.56	3.106
3134.1	4.00326
3136.64	3.43764
3139.18	4.2254
3141.72	4.03328
3144.26	3.49449
3146.8	3.72663
3149.33	3.90474