File: data/Raman/poly_smoothed/Mb_40_24_41_1x_45s_532 nm_x100_100%_600 gr_mm_01.txt
#Acq. time (s)=	45
#Accumulations=	2
#Range (cm-¹)=	200...3150
#Windows=	2
#Auto scanning=	Off
#Autofocus=	Off
#Macrospot=	Off
#AutoExposure=	Off
#Spike filter=	Multiple accum.
#Delay time (s)=	0
#Binning=	1
#Readout mode=	Signal
#DeNoise=	Off
#ICS correction=	On
#Dark correction=	Off
#Inst. Process=	Off
#Detector Gain=	Best Dynamic Range
#Detector ADC=	20 kHz
#Detector temperature (°C)=	-70.08
#Instrument=	LabRAM HR Evol
#Detector=	Synapse
#Objective=	x100
#Grating=	600 gr/mm
#ND Filter=	100%
#Laser (nm)=	532
#Hole=	100.021
#Range=	Auto
#Laser Pol.=	No
#Raman. Pol.=	No
#Laser Pol. (°)=	-0.0007625
#Raman Pol. (°)=	89.9995
#Collection=	Microscope
#StageXY=	Marzhauser
#StageZ=	Marzhauser
#X (µm)=	-2492.9
#Y (µm)=	-45.6
#Z (µm)=	-10.55
#Full time(mm:ss)=	3:19
#Project=
#Sample=
#Site=
#Title=	Mb_40_24_41_2x_45s_532 nm_x100_100%_600 gr_mm
#Remark=
#Date=	14.07.2022 13:56
#Acquired=	14.07.2022 13:56:33
#Edit:Spike=	14.07.2022 13:57:53
#Base:Fit=	10.08.2022 10:47:00
#Base:Sub=	10.08.2022 10:47:12
#Filter:Polynom=	16.08.2022 10:11:48
#AxisType[0]=Intens
#AxisUnit[0]=Cnt
#AxisType[1]=Spectr
#AxisUnit[1]=1/cm
200.554	42.3254
204.183	33.0461
207.813	28.0275
211.439	21.9332
215.065	17.6016
218.688	14.208
222.312	10.8779
225.933	9.29071
229.552	6.64257
233.171	4.83653
236.787	3.0784
240.402	2.00721
244.015	2.0649
247.627	1.96057
251.24	3.26453
254.849	1.92749
258.457	4.14268
262.063	6.79084
265.668	8.05384
269.271	11.3192
272.873	11.9376
276.474	13.6626
280.073	15.7013
283.671	16.0377
287.268	15.6839
290.863	17.6972
294.456	17.7677
298.049	18.9225
301.637	22.1037
305.227	23.5303
308.815	23.7582
312.402	23.6201
315.987	25.4739
319.569	25.6728
323.151	27.2542
326.733	27.9762
330.31	28.5338
333.889	29.4295
337.464	28.575
341.039	28.6453
344.611	27.5877
348.184	28.4256
351.754	27.5228
355.324	25.2637
358.89	21.8412
362.455	20.0214
366.021	18.7083
369.584	14.3899
373.145	12.8657
376.707	11.8251
380.265	11.1984
383.822	10.343
387.378	9.51758
390.934	11.1629
394.487	9.29103
398.038	10.5193
401.588	11.5412
405.137	12.3676
408.685	11.3729
412.23	10.0818
415.775	10.5783
419.318	10.0228
422.86	11.4671
426.401	10.0706
429.94	8.61081
433.478	8.0801
437.012	7.81863
440.547	6.50915
444.081	8.1944
447.613	7.12019
451.142	8.99366
454.672	9.43471
458.2	8.96192
461.725	9.61385
465.251	11.0174
468.775	12.5258
472.296	14.2929
475.817	17.6164
479.335	18.8327
482.854	20.6449
486.37	22.3784
489.886	23.5868
493.398	23.9013
496.91	26.4694
500.422	28.9108
503.93	29.3909
507.438	30.4418
510.946	31.2782
514.45	31.0191
517.954	32.3431
521.456	35.7528
524.956	36.1558
528.456	38.0545
531.956	38.1486
535.452	37.6515
538.947	38.5037
542.441	38.3917
545.934	38.1355
549.425	37.1094
552.915	37.307
556.403	36.939
559.889	35.0629
563.375	35.4749
566.859	33.7299
570.342	32.8973
573.824	32.2369
577.303	30.5956
580.782	29.3232
584.26	26.6055
587.734	23.4705
591.21	19.9704
594.684	20.7471
598.154	18.8927
601.626	18.7573
605.094	18.0951
608.562	16.7964
612.027	14.8594
615.493	14.6309
618.956	13.2411
622.419	12.5879
625.879	13.1216
629.338	14.6284
632.797	12.9488
636.254	11.1212
639.708	12.9464
643.162	11.5484
646.614	9.59439
650.067	9.16387
653.516	9.22701
656.964	8.02256
660.411	7.13425
663.857	5.9664
667.301	3.66129
670.744	3.9161
674.186	5.03918
677.626	5.00789
681.065	6.52458
684.503	7.47833
687.939	9.54463
691.372	9.53445
694.806	12.0494
698.239	14.4479
701.67	16.5079
705.098	17.8311
708.526	17.6657
711.954	17.0659
715.378	15.967
718.802	15.78
722.226	14.3093
725.646	13.0982
729.067	13.1963
732.484	13.433
735.902	14.5773
739.317	16.7472
742.731	18.7528
746.145	21.4373
749.556	23.7504
752.966	28.1968
756.377	32.5633
759.784	34.8311
763.19	40.5748
766.594	44.0864
770	47.3681
773.402	50.0339
776.803	52.3511
780.202	55.7409
783.6	57.971
786.997	57.575
790.393	57.252
793.787	59.56
797.18	60.995
800.572	60.6819
803.963	61.5456
807.35	61.0457
810.738	61.121
814.125	61.2622
817.51	61.8881
820.894	64.7555
824.275	65.7234
827.657	68.5694
831.037	70.7296
834.414	71.8866
837.792	72.673
841.167	71.4947
844.542	69.402
847.914	67.5014
851.287	63.9954
854.656	63.1028
858.026	60.1288
861.393	59.5526
864.761	57.886
868.125	57.5097
871.489	55.3505
874.85	54.7912
878.213	52.0798
881.572	48.9752
884.931	46.9341
888.287	46.3757
891.643	45.1712
894.997	44.8517
898.352	45.2606
901.704	47.7064
905.055	50.0526
908.404	51.9591
911.75	51.8426
915.097	54.4497
918.443	53.7005
921.787	52.0964
925.13	52.2036
928.472	50.7223
931.813	50.022
935.15	48.784
938.488	46.8352
941.825	46.9243
945.158	42.9574
948.493	40.2172
951.824	38.7034
955.156	36.9665
958.486	32.0559
961.814	29.9924
965.142	33.201
968.467	36.9399
971.79	42.2813
975.115	44.5166
978.436	49.1166
981.756	50.1473
985.077	50.8544
988.394	52.9888
991.71	54.228
995.025	55.4464
998.341	55.6085
1001.65	53.5496
1004.97	54.2135
1008.28	59.6622
1011.58	60.5089
1014.89	63.1365
1018.2	65.7944
1021.5	70.9443
1024.81	71.5262
1028.11	74.6893
1031.41	78.034
1034.71	80.1754
1038.01	80.1685
1041.31	80.0637
1044.6	85.0475
1047.9	88.0633
1051.19	87.5248
1054.48	86.2475
1057.77	84.1565
1061.06	78.7684
1064.35	74.7457
1067.64	68.7836
1070.93	64.8871
1074.21	57.9781
1077.49	52.0282
1080.78	47.0142
1084.06	44.0975
1087.34	42.9725
1090.61	41.8592
1093.89	40.3273
1097.17	40.3178
1100.44	39.9702
1103.71	40.292
1106.99	41.1623
1110.26	40.2729
1113.52	40.1164
1116.79	42.1402
1120.06	40.9799
1123.32	39.8873
1126.59	39.2847
1129.85	39.5479
1133.11	39.3707
1136.37	37.994
1139.63	34.4657
1142.89	31.3366
1146.15	29.3427
1149.4	26.0684
1152.66	23.0321
1155.91	17.4573
1159.16	15.002
1162.41	13.446
1165.66	10.1671
1168.91	8.13864
1172.16	9.22085
1175.4	9.06483
1178.65	10.3356
1181.89	11.3566
1185.13	15.3077
1188.37	19.1554
1191.61	21.3488
1194.85	24.1572
1198.08	29.1944
1201.32	30.9119
1204.55	35.2381
1207.79	40.1855
1211.02	44.6992
1214.25	48.2495
1217.48	51.9595
1220.71	54.5531
1223.93	59.0854
1227.16	62.5314
1230.38	66.0512
1233.6	69.6013
1236.83	72.827
1240.05	77.0576
1243.26	79.6169
1246.48	84.3944
1249.7	89.044
1252.92	94.8393
1256.13	100.281
1259.34	103.962
1262.55	109.039
1265.76	118.739
1268.97	125.457
1272.18	131.727
1275.39	137.497
1278.59	142.343
1281.8	145.354
1285	151.105
1288.2	157.11
1291.4	158.833
1294.6	163.014
1297.8	166.835
1301	168.989
1304.19	169.774
1307.39	170.899
1310.58	171.881
1313.77	168.376
1316.96	165.317
1320.15	162.87
1323.34	157.752
1326.53	155.492
1329.72	154.109
1332.9	152.038
1336.08	147.952
1339.27	144.624
1342.45	143.059
1345.63	142.124
1348.8	137.383
1351.98	134.972
1355.16	130.994
1358.33	128.954
1361.51	131.59
1364.68	132.278
1367.85	129.2
1371.02	128.103
1374.19	130.679
1377.36	130.697
1380.52	130.343
1383.69	132.038
1386.85	133.437
1390.02	132.256
1393.18	132.464
1396.34	137.236
1399.5	141.621
1402.65	148.489
1405.81	157.231
1408.97	166.588
1412.12	177.711
1415.27	186.29
1418.43	197.293
1421.58	208.771
1424.73	221.609
1427.87	231.404
1431.02	241.772
1434.17	251.654
1437.31	259.233
1440.46	263.985
1443.6	263.115
1446.74	260.892
1449.88	256.587
1453.02	251.166
1456.16	242.143
1459.29	231.644
1462.43	219.559
1465.56	205.576
1468.69	190.386
1471.83	177.76
1474.95	164.17
1478.08	151.401
1481.21	141.033
1484.34	130.432
1487.47	121.247
1490.59	112.891
1493.71	104.111
1496.84	98.464
1499.96	95.0415
1503.07	91.1664
1506.19	87.8968
1509.31	84.7464
1512.43	84.353
1515.54	81.7886
1518.65	79.0173
1521.77	77.8689
1524.88	78.6953
1527.99	79.6116
1531.1	82.5575
1534.21	83.0329
1537.31	85.4489
1540.42	88.8662
1543.52	90.9007
1546.63	92.6902
1549.73	95.3706
1552.83	98.8212
1555.93	101.678
1559.03	104.936
1562.12	108.118
1565.22	112.536
1568.31	116.934
1571.41	122.245
1574.5	130.065
1577.59	135.281
1580.68	142.219
1583.77	149.512
1586.86	157.169
1589.95	162.074
1593.03	165.453
1596.11	168.581
1599.2	173.672
1602.28	176.524
1605.36	179.882
1608.44	182.088
1611.52	181.891
1614.6	183.201
1617.67	184.935
1620.75	183.944
1623.82	183.961
1626.89	184.871
1629.96	183.755
1633.04	182.71
1636.11	181.281
1639.17	178.865
1642.24	178.583
1645.31	180.525
1648.37	179.336
1651.43	179.373
1654.5	178.669
1657.56	175.206
1660.62	172.058
1663.67	165.789
1666.73	157.443
1669.79	149.555
1672.84	143.141
1675.9	135.18
1678.95	125.879
1682	114.31
1685.05	105.312
1688.1	96.9858
1691.15	88.8812
1694.2	81.6742
1697.25	74.4273
1700.29	67.6069
1703.33	62.8386
1706.38	55.7295
1709.42	50.8892
1712.46	45.7206
1715.5	42.6437
1718.54	40.5119
1721.57	37.5333
1724.61	35.1379
1727.64	32.7541
1730.68	30.5959
1733.71	29.4483
1736.74	28.5938
1739.77	28.0762
1742.8	27.3166
1745.83	26.4788
1748.85	26.1572
1751.88	22.9951
1754.91	22.9191
1757.93	22.048
1760.95	21.5418
1763.97	20.1976
1766.99	19.0442
1770.01	18.6367
1773.03	18.5624
1776.04	18.094
1779.06	17.281
1782.07	14.0406
1785.09	12.8182
1788.1	11.0645
1791.11	11.2149
1794.12	9.56321
1797.13	9.34541
1800.13	8.64353
1803.14	7.7345
1806.15	7.65757
1809.15	7.66782
1812.15	8.82031
1815.16	7.92631
1818.15	7.90131
1821.16	8.40976
1824.15	8.08252
1827.15	7.40379
1830.15	6.56405
1833.14	5.29811
1836.14	5.46805
1839.13	4.80247
1842.12	4.99202
1845.11	4.03131
1848.1	2.57205
1851.09	3.33584
1854.08	2.97439
1857.06	1.84735
1860.05	3.7939
1863.03	4.85157
1866.01	6.43883
1869	6.31318
1871.98	7.0645
1874.96	7.95679
1877.93	9.22034
1880.91	10.4467
1882.47	10.895
1885.46	11.6217
1888.44	11.836
1891.43	11.1412
1894.42	9.46926
1897.4	8.16768
1900.39	6.33072
1903.37	5.50889
1906.35	4.40004
1909.33	4.83573
1912.31	5.47525
1915.29	5.41808
1918.26	5.23287
1921.24	6.56766
1924.21	7.80871
1927.19	8.06711
1930.16	8.90506
1933.13	11.2468
1936.1	13.0417
1939.07	12.5966
1942.04	12.1961
1945	12.4722
1947.97	13.131
1950.93	12.4385
1953.9	12.4801
1956.86	12.8177
1959.82	12.0487
1962.78	10.9712
1965.74	8.96386
1968.7	7.39375
1971.65	5.01991
1974.61	4.97494
1977.57	3.96284
1980.52	3.9076
1983.47	4.29087
1986.42	4.43583
1989.37	4.26883
1992.32	4.80448
1995.27	5.07773
1998.22	6.80484
2001.17	8.22114
2004.11	9.26415
2007.05	9.5388
2010	9.59462
2012.94	11.2258
2015.88	12.0003
2018.82	13.1684
2021.76	15.7477
2024.7	16.9067
2027.63	17.2042
2030.57	16.9594
2033.5	17.4046
2036.44	17.6483
2039.37	18.1207
2042.3	19.2524
2045.23	19.8544
2048.16	20.014
2051.08	20.5079
2054.01	21.8542
2056.94	22.4246
2059.86	22.7241
2062.79	24.5315
2065.71	24.834
2068.63	25.7127
2071.55	27.4294
2074.47	29.2559
2077.39	30.4058
2080.31	31.0017
2083.22	34.8913
2086.13	35.8201
2089.05	36.9081
2091.96	38.8431
2094.87	39.5617
2097.78	40.1247
2100.69	41.9944
2103.6	44.7635
2106.51	47.3268
2109.42	49.6004
2112.32	54.2696
2115.23	57.7244
2118.13	60.3493
2121.03	62.8586
2123.93	67.1924
2126.83	71.457
2129.73	75.5112
2132.63	79.913
2135.53	84.7173
2138.42	89.3934
2141.32	95.617
2144.21	101.308
2147.1	105.922
2150	109.05
2152.89	114.601
2155.78	118.933
2158.66	120.02
2161.55	121.753
2164.44	122.502
2167.32	125.003
2170.21	127.288
2173.09	127.553
2175.97	126.247
2178.85	124.568
2181.73	125.367
2184.61	122.378
2187.49	118.447
2190.37	113.916
2193.24	108.849
2196.12	104.753
2198.99	100.224
2201.87	96.5444
2204.74	91.9519
2207.61	87.2612
2210.48	84.1889
2213.35	79.4685
2216.21	74.6559
2219.08	71.1647
2221.95	67.721
2224.81	63.3896
2227.67	60.2433
2230.54	57.0477
2233.4	54.8642
2236.26	52.6232
2239.11	51.3442
2241.97	49.5832
2244.83	44.4711
2247.69	41.9871
2250.54	40.2082
2253.4	36.8834
2256.25	33.1625
2259.1	30.7024
2261.95	29.0676
2264.8	26.1252
2267.65	25.5573
2270.5	25.2063
2273.34	23.5201
2276.19	21.5556
2279.03	20.8936
2281.88	20.0893
2284.72	20.9131
2287.56	18.9291
2290.4	18.3301
2293.24	16.2827
2296.08	16.8803
2298.92	17.5179
2301.76	18.1029
2304.59	18.2773
2307.43	16.2718
2310.26	14.6816
2313.09	12.9416
2315.92	11.5461
2318.75	10.5454
2321.58	9.47593
2324.41	9.48989
2327.24	8.8035
2330.06	7.51648
2332.89	8.46558
2335.71	8.12823
2338.54	7.55532
2341.36	8.82313
2344.18	9.45335
2347	9.00322
2349.82	8.71298
2352.64	6.99129
2355.45	6.18561
2358.27	5.67141
2361.08	6.45305
2363.9	7.51669
2366.71	7.8666
2369.52	7.77854
2372.33	6.79542
2375.14	6.82731
2377.95	5.79743
2380.76	5.93758
2383.57	6.86339
2386.37	5.97084
2389.18	5.13516
2391.98	5.1427
2394.79	4.92196
2397.59	4.51731
2400.39	4.86901
2403.19	5.89994
2405.99	4.55197
2408.78	4.96946
2411.58	5.69973
2414.38	4.72161
2417.17	4.48044
2419.97	3.31846
2422.76	4.07592
2425.55	5.99771
2428.34	7.25134
2431.13	6.49988
2433.92	7.71969
2436.71	8.06968
2439.49	8.79897
2442.28	10.2033
2445.06	11.2029
2447.85	11.4225
2450.63	9.69309
2453.41	10.1894
2456.19	10.7804
2458.97	11.1792
2461.75	11.8043
2464.53	10.8815
2467.31	10.9825
2470.08	9.76109
2472.86	9.62422
2475.63	9.03703
2478.4	7.87383
2481.17	6.5194
2483.94	5.76459
2486.72	4.88569
2489.48	4.54007
2492.25	5.3742
2495.02	4.843
2497.79	4.76555
2500.55	3.49592
2503.31	3.23014
2506.08	2.50977
2508.84	2.0943
2511.6	1.3178
2514.36	2.3019
2517.12	1.61223
2519.88	2.74567
2522.63	5.35219
2525.39	5.8993
2528.14	5.75303
2530.9	6.58899
2533.65	5.78267
2536.4	5.91295
2539.15	5.64438
2541.9	6.51264
2544.65	6.91795
2547.4	7.85876
2550.15	9.43032
2552.89	9.36549
2555.64	10.2785
2558.38	12.3772
2561.12	13.8998
2563.87	13.3451
2566.61	14.1678
2569.35	14.0986
2572.09	13.2888
2574.83	14.8058
2577.56	13.8168
2580.3	15.4129
2583.04	15.9693
2585.77	17.3686
2588.5	17.6646
2591.23	17.5071
2593.97	15.5892
2596.7	13.4032
2599.43	11.6102
2602.15	10.5147
2604.88	10.5373
2607.61	9.6651
2610.33	9.34302
2613.06	9.27708
2615.78	8.0139
2618.51	7.43248
2621.23	6.57209
2623.95	5.34831
2626.67	5.17621
2629.39	3.74392
2632.1	3.10748
2634.82	1.59953
2637.54	1.03949
2640.25	0.96419
2642.97	1.6223
2645.68	2.83361
2648.39	3.77718
2651.1	4.83947
2653.81	4.16069
2656.52	5.10008
2659.23	4.87285
2661.94	4.63441
2664.64	5.00707
2667.35	5.22581
2670.05	6.56213
2672.76	8.30062
2675.46	7.37009
2678.16	7.87177
2680.86	7.40615
2683.56	7.00917
2686.26	8.96832
2688.96	10.2329
2691.65	10.8717
2694.35	12.1004
2697.04	14.0035
2699.74	15.938
2702.43	16.8202
2705.12	19.4794
2707.81	20.1126
2710.5	21.6161
2713.19	22.6034
2715.88	23.3236
2718.57	24.3578
2721.25	24.4666
2723.94	24.0602
2726.62	22.6345
2729.3	21.5376
2731.99	20.5316
2734.67	18.006
2737.35	15.3555
2740.03	12.8673
2742.71	10.6468
2745.38	8.88593
2748.06	7.06621
2750.74	5.36426
2753.41	6.59457
2756.09	5.74337
2758.76	4.729
2761.43	4.06378
2764.1	2.68343
2766.77	1.58943
2769.44	0.818789
2772.11	1.84773
2774.77	1.91202
2777.44	2.92463
2780.11	3.89131
2782.77	4.5635
2785.43	5.29442
2788.1	4.35734
2790.76	3.40102
2793.42	2.7271
2796.08	2.62853
2798.74	1.76276
2801.4	1.96039
2804.05	1.62721
2806.71	2.53118
2809.36	1.30458
2812.02	0.346082
2814.67	-0.0837559
2817.32	2.65851
2819.97	7.35081
2822.62	9.49565
2825.27	16.3231
2827.92	24.3392
2830.57	36.0752
2833.22	49.1669
2835.86	64.7328
2838.51	81.0236
2841.15	98.6357
2843.79	117.009
2846.43	136.741
2849.08	155.977
2851.72	175.927
2854.36	196.763
2856.99	216.603
2859.63	236.806
2862.27	255.045
2864.9	272.76
2867.54	288.294
2870.17	303.67
2872.8	314.779
2875.43	325.335
2878.07	337.067
2880.7	348.629
2883.32	361.747
2885.95	376.185
2888.58	390.671
2891.21	404.984
2893.83	421.6
2896.46	438.738
2899.08	456.208
2901.7	475.681
2904.32	497.871
2906.94	521.206
2909.56	545.79
2912.18	569.904
2914.8	592.601
2917.42	613.424
2920.03	631.828
2922.65	646.195
2925.26	657.194
2927.88	663.159
2930.49	663.047
2933.1	658.028
2935.71	649.015
2938.32	634.552
2940.93	616.998
2943.54	596.383
2946.14	573.09
2948.75	548.05
2951.35	522.45
2953.96	493.197
2956.56	464.547
2959.16	438.295
2961.77	412.271
2964.37	388.777
2966.96	369.188
2969.56	348.652
2972.16	328.135
2974.76	309.71
2977.35	291.046
2979.95	272.195
2982.54	254.49
2985.14	237.105
2987.73	217.784
2990.32	198.368
2992.91	178.622
2995.5	158.966
2998.09	141.63
3000.68	121.354
3003.26	103.998
3005.85	87.3694
3008.43	70.9517
3011.02	56.9362
3013.6	45.0313
3016.19	34.875
3018.77	25.3844
3021.35	18.0915
3023.93	11.6181
3026.5	7.2195
3029.08	3.81215
3031.66	1.26565
3034.24	-0.726098
3036.81	-0.584899
3039.39	-0.654591
3041.96	0.756421
3044.53	2.98813
3047.1	5.13567
3049.67	7.01185
3052.24	7.91376
3054.81	8.65587
3057.38	10.8895
3059.95	10.7589
3062.52	11.122
3065.08	11.4294
3067.65	11.7037
3070.21	11.1229
3072.77	9.77083
3075.33	8.6528
3077.89	7.88675
3080.45	6.23819
3083.01	4.41621
3085.57	3.35128
3088.13	2.38582
3090.68	1.84298
3093.24	1.74954
3095.79	2.81017
3098.35	3.09
3100.9	4.24127
3103.45	6.09346
3106	8.03959
3108.55	10.2479
3111.1	12.6414
3113.65	14.4989
3116.2	17.3893
3118.75	21.5425
3121.29	25.0008
3123.84	28.9613
3126.38	34.1394
3128.92	37.2693
3131.47	41.8242
3134.01	44.9233
3136.55	49.2473
3139.09	53.8733
3141.63	58.9338
3144.17	63.6697
3146.7	68.6902
3149.24	74.9444