File: data/Raman/poly_smoothed/Mb_40_y_47_1x_45s_532 nm_x100_100%_600 gr_mm_01.txt
#Acq. time (s)=	45
#Accumulations=	2
#Range (cm-¹)=	200...3150
#Windows=	2
#Auto scanning=	Off
#Autofocus=	Off
#Macrospot=	Off
#AutoExposure=	Off
#Spike filter=	Multiple accum.
#Delay time (s)=	0
#Binning=	1
#Readout mode=	Signal
#DeNoise=	Off
#ICS correction=	On
#Dark correction=	Off
#Inst. Process=	Off
#Detector Gain=	Best Dynamic Range
#Detector ADC=	20 kHz
#Detector temperature (°C)=	-69.85
#Instrument=	LabRAM HR Evol
#Detector=	Synapse
#Objective=	x100
#Grating=	600 gr/mm
#ND Filter=	100%
#Laser (nm)=	532
#Hole=	100.021
#Range=	Auto
#Laser Pol.=	No
#Raman. Pol.=	No
#Laser Pol. (°)=	-0.0007625
#Raman Pol. (°)=	89.9995
#Collection=	Microscope
#StageXY=	Marzhauser
#StageZ=	Marzhauser
#X (µm)=	-1149.5
#Y (µm)=	682.7
#Z (µm)=	584.8
#Full time(mm:ss)=	3:18
#Project=
#Sample=
#Site=
#Title=	Mb_40_y_47_2x_45s_532 nm_x100_100%_600 gr_mm
#Remark=
#Date=	19.07.2022 13:30
#Acquired=	19.07.2022 13:30:00
#Base:Fit=	10.08.2022 10:52:48
#Base:Sub=	10.08.2022 10:52:53
#Filter:Polynom=	16.08.2022 10:09:04
#AxisType[0]=Intens
#AxisUnit[0]=Cnt
#AxisType[1]=Spectr
#AxisUnit[1]=1/cm
200.423	26.276
204.052	25.3852
207.682	22.2046
211.308	17.8343
214.935	15.7388
218.558	15.3372
222.18	12.0067
225.802	9.90644
229.421	7.31423
233.039	6.14458
236.657	5.54768
240.272	6.36092
243.885	5.85178
247.497	5.40992
251.11	3.63475
254.719	3.91812
258.327	6.5239
261.933	8.23829
265.538	9.56587
269.141	9.08804
272.744	9.80253
276.344	8.31345
279.944	8.44822
283.542	8.8448
287.138	6.9982
290.733	7.40631
294.327	6.99693
297.919	6.57218
301.508	8.47081
305.098	8.23266
308.686	7.35056
312.273	5.54122
315.858	6.3729
319.44	7.49884
323.022	8.13933
326.604	8.13199
330.181	7.90236
333.76	7.89998
337.335	9.17128
340.91	11.5994
344.483	13.3247
348.055	11.9024
351.625	12.6499
355.195	11.3839
358.762	11.4349
362.329	11.7943
365.893	12.1533
369.455	12.9301
373.017	13.5082
376.578	14.0761
380.137	13.9534
383.694	14.3042
387.249	15.3988
390.806	15.8363
394.359	15.5375
397.91	14.5681
401.46	14.0762
405.009	12.6116
408.557	10.2732
412.103	9.51726
415.647	9.0803
419.191	8.59246
422.733	8.43438
426.273	8.82829
429.812	9.53881
433.35	7.18503
436.885	6.02647
440.42	5.33268
443.954	4.85487
447.486	5.86563
451.015	5.5254
454.545	7.14128
458.073	6.38102
461.598	7.22866
465.124	7.75241
468.648	9.34587
472.169	11.2347
475.69	11.7664
479.208	12.9638
482.727	14.9083
486.243	14.6905
489.759	17.0356
493.272	19.7875
496.783	22.1385
500.295	24.7374
503.804	26.083
507.311	28.6001
510.819	30.9562
514.324	32.6924
517.827	33.3255
521.329	32.5044
524.83	31.8837
528.329	31.2358
531.829	31.5091
535.326	29.6862
538.821	27.6228
542.315	27.2977
545.808	25.9063
549.299	23.9449
552.789	21.2785
556.278	18.691
559.763	15.4555
563.249	15.3208
566.733	15.285
570.217	14.0894
573.699	14.8131
577.177	15.3196
580.656	17.1369
584.134	16.7314
587.609	17.2896
591.084	16.428
594.558	15.642
598.029	14.6955
601.5	13.0499
604.968	12.65
608.437	12.7389
611.902	13.5405
615.368	11.5646
618.831	10.4941
622.294	9.45743
625.755	8.99599
629.213	9.04797
632.673	7.28452
636.129	6.61889
639.584	4.91018
643.037	5.06211
646.491	5.64976
649.942	8.31828
653.392	9.65203
656.84	10.9961
660.287	13.8069
663.732	15.1638
667.177	16.5094
670.62	17.4442
674.061	18.9948
677.502	19.9135
680.941	21.6763
684.379	22.52
687.815	23.555
691.248	24.4292
694.682	24.2476
698.115	24.2638
701.546	26.5273
704.974	27.8365
708.402	31.2426
711.83	34.7167
715.254	35.9718
718.679	38.1045
722.102	39.0074
725.522	39.7228
728.943	41.6168
732.361	42.8416
735.779	45.6153
739.194	45.0886
742.608	46.1214
746.022	48.485
749.433	51.1994
752.843	53.2177
756.254	55.885
759.661	56.5236
763.067	57.6734
766.471	57.6236
769.877	56.9483
773.279	57.7513
776.68	59.5315
780.079	61.4677
783.478	63.5897
786.875	66.5225
790.27	69.564
793.665	69.2071
797.058	70.3592
800.45	70.1197
803.84	70.8692
807.23	71.2056
810.616	71.1314
814.002	71.0552
817.388	69.5019
820.772	67.8971
824.153	67.2167
827.535	67.851
830.915	66.2321
834.292	64.274
837.67	62.3604
841.047	57.6094
844.42	54.6529
847.794	54.1322
851.165	52.4718
854.534	49.1677
857.905	48.1353
861.272	44.9352
864.639	43.8095
868.004	43.3925
871.367	43.0803
874.731	40.7639
878.092	39.786
881.451	39.9581
884.809	40.971
888.166	42.4148
891.522	40.826
894.878	40.4151
898.231	40.0866
901.583	40.6618
904.934	40.2151
908.283	40.2229
911.631	40.6479
914.976	39.966
918.322	39.972
921.666	39.6234
925.009	39.7739
928.351	41.1313
931.692	41.872
935.029	40.256
938.367	39.6243
941.704	38.7162
945.038	37.6706
948.372	36.6533
951.705	35.7677
955.035	35.9985
958.366	33.9669
961.693	33.8358
965.021	35.1081
968.346	33.9241
971.67	32.9712
974.995	32.0278
978.316	32.4065
981.638	31.46
984.957	30.3554
988.274	29.905
991.59	29.8391
994.907	26.4228
998.221	21.7656
1001.53	16.9098
1004.85	15.1523
1008.16	21.5211
1011.46	34.9632
1014.77	57.5672
1018.08	81.7127
1021.38	105.877
1024.69	128.09
1027.99	149.791
1031.29	167.041
1034.59	181.65
1037.89	191.614
1041.19	198.015
1044.48	202.489
1047.78	202.047
1051.07	197.622
1054.36	189.192
1057.66	176.773
1060.94	161.411
1064.23	141.87
1067.52	120.096
1070.81	96.3585
1074.09	69.4618
1077.38	43.9609
1080.66	23.1087
1083.94	8.4166
1087.22	2.39496
1090.5	6.22873
1093.77	12.4388
1097.05	18.2599
1100.32	22.5259
1103.6	25.2473
1106.87	27.6315
1110.14	29.3973
1113.41	29.1092
1116.67	29.6412
1119.94	29.5424
1123.21	30.015
1126.47	29.6883
1129.73	27.7463
1133	25.3872
1136.26	23.7919
1139.52	21.9909
1142.77	17.5814
1146.03	16.0627
1149.29	13.3754
1152.54	10.046
1155.79	6.03412
1159.04	3.37299
1162.3	0.335637
1165.55	-1.71599
1168.79	-0.680042
1172.04	0.728329
1175.28	1.11302
1178.53	0.508525
1181.77	2.86235
1185.01	3.99448
1188.25	4.84986
1191.49	5.53557
1194.73	5.48822
1197.97	7.40542
1201.2	9.34153
1204.44	11.8028
1207.67	12.9885
1210.9	13.4117
1214.13	16.3672
1217.36	19.6462
1220.59	22.6227
1223.82	24.8936
1227.04	29.3946
1230.26	33.1587
1233.49	36.2335
1236.71	40.1312
1239.93	45.4418
1243.15	49.4131
1246.37	53.0493
1249.58	59.026
1252.8	62.3776
1256.01	64.3783
1259.23	67.3512
1262.44	72.8532
1265.65	75.8513
1268.86	78.8034
1272.07	81.2942
1275.27	83.3883
1278.48	86.2184
1281.68	87.4147
1284.89	88.8399
1288.09	88.1788
1291.29	90.8486
1294.49	92.8368
1297.69	94.4178
1300.88	94.3238
1304.08	94.2024
1307.27	95.4628
1310.47	96.9319
1313.66	97.5211
1316.85	99.1761
1320.04	98.5539
1323.23	97.752
1326.41	97.6353
1329.6	94.7327
1332.78	92.0741
1335.97	89.8067
1339.15	88.2601
1342.33	85.5475
1345.51	82.7708
1348.69	78.8979
1351.87	75.5123
1355.04	73.0268
1358.22	69.3511
1361.39	66.12
1364.57	63.9224
1367.74	61.1852
1370.91	57.8898
1374.07	56.3159
1377.24	54.6722
1380.41	54.2688
1383.57	54.1179
1386.74	56.0163
1389.9	56.1891
1393.06	58.8721
1396.22	59.2173
1399.38	61.3054
1402.54	63.5894
1405.7	65.8275
1408.85	69.5568
1412.01	74.874
1415.16	79.3243
1418.31	85.2965
1421.46	91.212
1424.61	97.0434
1427.76	105.504
1430.91	111.501
1434.05	117.896
1437.2	122.531
1440.34	127.424
1443.49	129.962
1446.63	129.958
1449.77	130.405
1452.91	129.532
1456.04	126.318
1459.18	123.938
1462.31	119.992
1465.45	115.795
1468.58	111.319
1471.71	105.812
1474.84	98.3213
1477.97	91.2161
1481.1	84.622
1484.23	77.036
1487.35	70.8531
1490.48	63.5115
1493.6	57.3708
1496.72	52.7643
1499.84	46.9719
1502.96	43.9483
1506.08	40.932
1509.2	37.5572
1512.31	35.1503
1515.43	31.9896
1518.54	31.9239
1521.66	30.3569
1524.77	28.7019
1527.88	28.6254
1530.99	28.0241
1534.09	28.3278
1537.2	28.6554
1540.31	31.9118
1543.41	35.2809
1546.51	36.8774
1549.62	37.7028
1552.72	39.5428
1555.82	42.5996
1558.91	44.0136
1562.01	47.2893
1565.11	49.5902
1568.2	53.5188
1571.3	56.2055
1574.39	59.9909
1577.48	62.5797
1580.57	65.4817
1583.66	68.2098
1586.75	69.6016
1589.83	71.6847
1592.92	73.5919
1596	75.9672
1599.09	74.259
1602.17	74.2172
1605.25	73.6535
1608.33	71.2934
1611.41	70.6922
1614.48	70.1612
1617.56	71.1817
1620.64	71.8708
1623.71	71.8442
1626.78	73.2768
1629.86	75.2925
1632.92	77.601
1635.99	79.18
1639.06	81.4132
1642.13	82.4924
1645.19	84.8686
1648.26	86.5491
1651.32	86.3679
1654.38	87.198
1657.45	85.4839
1660.51	84.471
1663.57	83.5373
1666.62	81.3218
1669.68	79.0414
1672.73	74.2174
1675.79	69.8133
1678.84	64.107
1681.89	58.891
1684.94	53.3813
1687.99	49.7558
1691.04	44.7267
1694.09	41.5582
1697.14	37.6955
1700.18	33.1292
1703.22	30.2277
1706.27	25.3158
1709.31	22.8053
1712.35	19.8186
1715.39	17.319
1718.43	15.9254
1721.46	14.945
1724.5	13.3306
1727.53	11.0555
1730.57	9.96711
1733.6	9.21006
1736.63	8.32557
1739.66	7.16121
1742.69	6.28351
1745.72	6.25136
1748.74	5.35544
1751.77	5.76421
1754.8	4.85171
1757.82	5.65697
1760.84	5.08854
1763.86	4.61783
1766.88	5.03289
1769.9	4.12318
1772.92	3.53721
1775.93	3.65427
1778.95	2.53334
1781.96	2.15841
1784.98	1.9733
1787.99	2.56059
1791	1.73623
1794.01	2.33554
1797.02	2.22129
1800.03	1.68877
1803.03	0.753423
1806.04	0.946901
1809.04	0.316901
1812.04	-0.122854
1815.05	-0.316669
1818.05	0.700149
1821.05	0.802971
1824.05	0.810226
1827.04	0.997129
1830.04	0.822152
1833.03	-0.118984
1836.03	0.239853
1839.02	1.48359
1842.01	2.96838
1845	3.47214
1847.99	4.06863
1850.98	5.39579
1853.97	6.46851
1856.95	7.24965
1859.94	8.84993
1862.92	9.83076
1865.91	9.83309
1868.89	10.6692
1871.87	10.4845
1874.85	9.07945
1877.83	9.22122
1880.8	8.33311
1882.56	7.35798
1885.54	7.16743
1888.53	5.93698
1891.52	5.51465
1894.5	4.3346
1897.49	2.72112
1900.47	2.02167
1903.45	0.784062
1906.43	-0.533095
1909.41	0.231183
1912.39	0.297095
1915.37	-0.162037
1918.35	0.218924
1921.32	0.801752
1924.3	1.59452
1927.27	1.55325
1930.24	1.89413
1933.21	2.61269
1936.18	2.9917
1939.15	3.63761
1942.12	3.73522
1945.09	4.5039
1948.05	5.34312
1951.02	4.84284
1953.98	3.95497
1956.94	4.2674
1959.91	3.10153
1962.87	3.66224
1965.82	3.98848
1968.78	3.47477
1971.74	3.73046
1974.7	3.80092
1977.65	3.11398
1980.6	2.85608
1983.56	2.40295
1986.51	2.43344
1989.46	2.61973
1992.41	4.05467
1995.36	4.15495
1998.3	3.62185
2001.25	3.97
2004.2	4.61793
2007.14	4.5974
2010.08	4.54802
2013.02	5.30792
2015.97	5.0607
2018.9	5.36074
2021.84	4.78074
2024.78	4.69791
2027.72	5.23106
2030.65	5.10177
2033.59	6.07797
2036.52	7.34676
2039.45	8.8599
2042.38	9.58178
2045.31	10.8834
2048.24	12.1883
2051.17	13.4746
2054.1	14.563
2057.02	15.9947
2059.95	17.2072
2062.87	18.2996
2065.79	19.1753
2068.71	18.5542
2071.63	20.7328
2074.55	21.7449
2077.47	23.7658
2080.39	24.8527
2083.3	27.7655
2086.22	29.9252
2089.13	31.7281
2092.05	33.5689
2094.96	36.4546
2097.87	39.4187
2100.78	43.1499
2103.69	47.0959
2106.59	50.6381
2109.5	54.1591
2112.41	56.5468
2115.31	59.3848
2118.21	63.1682
2121.12	66.3939
2124.02	70.3784
2126.92	73.4267
2129.82	78.7417
2132.71	81.4009
2135.61	85.4055
2138.51	88.9769
2141.4	92.5668
2144.29	96.2566
2147.19	100.887
2150.08	103.145
2152.97	106.143
2155.86	109.721
2158.75	111.451
2161.64	112.776
2164.52	115.146
2167.41	117.124
2170.29	117.922
2173.17	117.62
2176.06	116.811
2178.94	115.157
2181.82	113.14
2184.7	111.122
2187.57	109.226
2190.45	106.595
2193.33	103.006
2196.2	100.516
2199.08	95.5513
2201.95	93.5264
2204.82	88.5296
2207.69	84.1069
2210.56	80.2605
2213.43	74.8675
2216.3	71.6682
2219.16	66.9002
2222.03	61.9295
2224.89	58.754
2227.75	54.4773
2230.62	51.0836
2233.48	47.4258
2236.34	44.9061
2239.2	41.0651
2242.06	36.6157
2244.91	34.1023
2247.77	33.2127
2250.62	30.4801
2253.48	28.6548
2256.33	27.9037
2259.18	25.4042
2262.03	23.0047
2264.88	21.2127
2267.73	20.98
2270.58	19.525
2273.43	19.612
2276.27	18.5972
2279.12	17.1685
2281.96	15.205
2284.8	14.2193
2287.64	12.7972
2290.49	11.4075
2293.32	9.36701
2296.16	8.57954
2299	8.72663
2301.84	7.38287
2304.67	7.71541
2307.51	8.03221
2310.34	6.66412
2313.17	6.59393
2316	6.42806
2318.83	8.17301
2321.66	7.32131
2324.49	7.8622
2327.32	7.56252
2330.15	7.19711
2332.97	6.97393
2335.79	7.04972
2338.62	7.03237
2341.44	6.65898
2344.26	6.74986
2347.08	5.56855
2349.9	4.61507
2352.72	3.60464
2355.53	2.4081
2358.35	1.82772
2361.17	1.05124
2363.98	1.38024
2366.79	2.22516
2369.6	2.49809
2372.42	3.34331
2375.22	3.92805
2378.03	3.34525
2380.84	3.66242
2383.65	3.93119
2386.45	4.81211
2389.26	4.78749
2392.06	5.07154
2394.87	5.28582
2397.67	2.97816
2400.47	2.36344
2403.27	1.58465
2406.07	1.86551
2408.86	2.18366
2411.66	3.0574
2414.46	3.01276
2417.25	3.02793
2420.05	2.84357
2422.84	3.38354
2425.63	3.96185
2428.42	4.85438
2431.21	4.42446
2434	5.01255
2436.79	5.30137
2439.57	5.59262
2442.36	5.4057
2445.14	5.71408
2447.93	6.24943
2450.71	6.4671
2453.49	6.11979
2456.27	5.13988
2459.05	5.70233
2461.83	4.21375
2464.61	3.20973
2467.39	3.05857
2470.16	3.30751
2472.94	3.94976
2475.71	5.11533
2478.48	4.85867
2481.25	5.37174
2484.02	4.50898
2486.8	4.64668
2489.56	5.64347
2492.33	4.72124
2495.1	4.12253
2497.86	2.91097
2500.63	2.22525
2503.39	1.81907
2506.16	1.57083
2508.92	1.779
2511.68	1.28804
2514.44	1.26275
2517.2	0.466034
2519.95	-0.762151
2522.71	-0.313353
2525.47	0.526293
2528.22	0.727288
2530.98	1.06303
2533.73	2.64784
2536.48	3.41804
2539.23	5.21775
2541.98	6.24551
2544.73	6.23276
2547.48	6.24635
2550.23	6.84739
2552.97	6.59803
2555.72	8.04313
2558.46	7.64064
2561.2	6.27234
2563.95	7.0597
2566.69	6.4946
2569.43	5.69269
2572.17	5.83183
2574.91	5.82658
2577.64	5.2109
2580.38	4.47163
2583.11	3.59349
2585.85	2.82773
2588.58	3.76055
2591.31	4.27004
2594.04	4.98518
2596.78	4.92076
2599.51	6.91272
2602.23	6.09144
2604.96	6.34519
2607.69	6.418
2610.41	6.2912
2613.14	6.63734
2615.86	7.35042
2618.58	6.96512
2621.3	6.39042
2624.03	6.89483
2626.75	7.13284
2629.46	7.24938
2632.18	7.78923
2634.9	7.5186
2637.61	7.18139
2640.33	7.88103
2643.04	8.61523
2645.76	8.8147
2648.47	8.28152
2651.18	7.86441
2653.89	8.80152
2656.6	9.20775
2659.31	9.99528
2662.01	9.43123
2664.72	9.18544
2667.43	9.29391
2670.13	9.13458
2672.83	8.81102
2675.53	9.10828
2678.24	9.41445
2680.94	9.77947
2683.64	10.4398
2686.34	10.6835
2689.03	10.974
2691.73	11.5899
2694.43	12.0013
2697.12	11.7778
2699.81	11.2215
2702.51	11.3159
2705.2	11.9663
2707.89	12.3929
2710.58	12.2732
2713.27	12.009
2715.96	12.7572
2718.64	14.1597
2721.33	13.7129
2724.01	13.2727
2726.7	12.9863
2729.38	11.6285
2732.06	10.4545
2734.75	10.2195
2737.43	9.56833
2740.11	8.85072
2742.78	8.84256
2745.46	7.75824
2748.14	7.89166
2750.81	6.53034
2753.49	6.54759
2756.16	6.33397
2758.84	5.85558
2761.51	4.85636
2764.18	3.77526
2766.85	3.57574
2769.52	2.71697
2772.19	2.52603
2774.85	2.6519
2777.52	2.73622
2780.18	3.35072
2782.85	4.03049
2785.51	3.44639
2788.17	3.56971
2790.84	3.80032
2793.5	4.47671
2796.16	4.54144
2798.81	4.28186
2801.47	4.35717
2804.13	4.20027
2806.79	3.34743
2809.44	2.31211
2812.09	2.52743
2814.75	3.70717
2817.4	5.64115
2820.05	8.94937
2822.7	13.0254
2825.35	16.8047
2828	22.3167
2830.65	28.6139
2833.29	35.201
2835.94	42.4558
2838.58	51.0474
2841.23	60.4987
2843.87	70.1591
2846.51	81.6452
2849.15	93.4395
2851.79	104.935
2854.43	115.744
2857.07	127.11
2859.71	136.634
2862.34	145.422
2864.98	152.782
2867.61	159.272
2870.25	164.901
2872.88	170.259
2875.51	176.088
2878.14	181.238
2880.77	186.74
2883.4	192.29
2886.03	198.104
2888.65	203.529
2891.28	209.668
2893.91	216.434
2896.53	222.635
2899.15	230.206
2901.78	239.032
2904.4	249.231
2907.02	259.548
2909.64	271.771
2912.26	283.5
2914.87	293.765
2917.49	304.11
2920.11	312.875
2922.72	320.195
2925.34	325.234
2927.95	328.672
2930.56	330.747
2933.17	331.45
2935.78	329.595
2938.39	326.043
2941	320.516
2943.61	312.51
2946.22	303.26
2948.82	292.276
2951.43	280.981
2954.03	269.417
2956.64	256.65
2959.24	242.813
2961.84	229.848
2964.44	216.59
2967.04	202.896
2969.64	189.528
2972.24	175.519
2974.83	162.825
2977.43	149.567
2980.02	137.072
2982.62	125.584
2985.21	113.937
2987.8	101.578
2990.4	90.8175
2992.99	81.5216
2995.57	72.5892
2998.16	62.9466
3000.75	54.2304
3003.34	46.28
3005.92	39.7981
3008.51	33.0528
3011.09	28.0643
3013.68	23.7265
3016.26	19.502
3018.84	16.0513
3021.42	13.1846
3024	10.3756
3026.58	7.78746
3029.16	5.51869
3031.73	4.10475
3034.31	3.03753
3036.89	3.59393
3039.46	4.42299
3042.03	4.89305
3044.61	5.72958
3047.18	6.08347
3049.75	6.24557
3052.32	7.53042
3054.89	7.51232
3057.45	7.05327
3060.02	6.65664
3062.59	6.26067
3065.15	5.31839
3067.72	5.37521
3070.28	5.10497
3072.84	4.03994
3075.41	3.42618
3077.97	2.35895
3080.53	1.42871
3083.09	0.578103
3085.64	-0.356751
3088.2	-1.64237
3090.76	-1.1351
3093.31	-0.864775
3095.87	-0.374251
3098.42	0.269916
3100.97	1.4208
3103.53	2.62228
3106.08	4.03454
3108.63	4.30822
3111.18	6.74255
3113.73	9.14857
3116.27	9.77865
3118.82	10.6486
3121.37	12.3486
3123.91	13.6278
3126.45	15.1041
3129	17.3538
3131.54	18.8481
3134.08	19.4175
3136.62	21.042
3139.16	22.5323
3141.7	23.0014
3144.24	23.6654
3146.78	23.9788
3149.31	24.5648