File: data/Raman/poly_smoothed/Mb_40_24_04_1x_45s_532 nm_x100_100%_600 gr_mm_01.txt
#Acq. time (s)=	45
#Accumulations=	2
#Range (cm-¹)=	200...3150
#Windows=	2
#Auto scanning=	Off
#Autofocus=	Off
#Macrospot=	Off
#AutoExposure=	Off
#Spike filter=	Multiple accum.
#Delay time (s)=	0
#Binning=	1
#Readout mode=	Signal
#DeNoise=	Off
#ICS correction=	On
#Dark correction=	Off
#Inst. Process=	Off
#Detector Gain=	Best Dynamic Range
#Detector ADC=	20 kHz
#Detector temperature (°C)=	-70.08
#Instrument=	LabRAM HR Evol
#Detector=	Synapse
#Objective=	x100
#Grating=	600 gr/mm
#ND Filter=	100%
#Laser (nm)=	532
#Hole=	100.021
#Range=	Auto
#Laser Pol.=	No
#Raman. Pol.=	No
#Laser Pol. (°)=	-0.0007625
#Raman Pol. (°)=	89.9995
#Collection=	Microscope
#StageXY=	Marzhauser
#StageZ=	Marzhauser
#X (µm)=	-2531
#Y (µm)=	-32.9
#Z (µm)=	-10.05
#Full time(mm:ss)=	3:18
#Project=
#Sample=
#Site=
#Title=	Mb_40_24_04_2x_45s_532 nm_x100_100%_600 gr_mm
#Remark=
#Date=	14.07.2022 10:59
#Acquired=	14.07.2022 10:59:22
#Base:Fit=	10.08.2022 10:47:00
#Base:Sub=	10.08.2022 10:47:12
#Filter:Polynom=	16.08.2022 10:11:48
#AxisType[0]=Intens
#AxisUnit[0]=Cnt
#AxisType[1]=Spectr
#AxisUnit[1]=1/cm
200.554	22.1726
204.183	20.3231
207.813	16.6659
211.439	14.58
215.065	10.988
218.688	9.51501
222.312	7.63009
225.933	5.7417
229.552	6.09813
233.171	6.65634
236.787	6.18553
240.402	6.40949
244.015	5.53783
247.627	5.27068
251.24	5.64581
254.849	7.70971
258.457	9.13241
262.063	6.36108
265.668	7.00899
269.271	7.74201
272.873	6.19948
276.474	6.0571
280.073	5.43168
283.671	5.68182
287.268	4.78843
290.863	6.29503
294.456	6.1861
298.049	6.73648
301.637	5.80964
305.227	8.34793
308.815	10.8345
312.402	11.0972
315.987	13.9595
319.569	16.946
323.151	19.2794
326.733	20.787
330.31	20.8368
333.889	22.8288
337.464	24.0628
341.039	25.9559
344.611	26.4235
348.184	25.5966
351.754	24.5912
355.324	24.9309
358.89	23.6456
362.455	23.046
366.021	23.2943
369.584	22.153
373.145	23.6653
376.707	23.7826
380.265	22.5202
383.822	21.7404
387.378	23.0804
390.934	25.9438
394.487	27.3265
398.038	27.5523
401.588	29.1513
405.137	28.7059
408.685	28.4344
412.23	31.1926
415.775	31.2379
419.318	31.3143
422.86	32.1053
426.401	31.552
429.94	31.2071
433.478	28.8554
437.012	26.3815
440.547	23.6238
444.081	23.2991
447.613	21.4582
451.142	20.8758
454.672	20.5549
458.2	21.5053
461.725	22.8487
465.251	23.1147
468.775	25.3738
472.296	26.8312
475.817	31.2033
479.335	31.3868
482.854	32.9125
486.37	35.5759
489.886	37.9042
493.398	42.335
496.91	46.8549
500.422	49.2067
503.93	50.232
507.438	52.6205
510.946	53.274
514.45	54.9387
517.954	54.2596
521.456	53.8521
524.956	53.3116
528.456	53.595
531.956	53.85
535.452	53.1113
538.947	51.7495
542.441	48.9671
545.934	46.2322
549.425	43.9993
552.915	41.1361
556.403	38.2653
559.889	34.4749
563.375	29.4019
566.859	27.8801
570.342	24.5955
573.824	21.0793
577.303	19.9351
580.782	16.9738
584.26	13.3537
587.734	10.2482
591.21	7.67849
594.684	7.09695
598.154	6.35401
601.626	8.31666
605.094	7.49316
608.562	7.95592
612.027	7.78517
615.493	9.92752
618.956	8.32609
622.419	6.6757
625.879	5.36107
629.338	5.01758
632.797	7.6338
636.254	8.27868
639.708	8.55913
643.162	8.57164
646.614	7.89745
650.067	6.35881
653.516	4.59592
656.964	4.00088
660.411	4.56944
663.857	3.14523
667.301	2.53666
670.744	2.02488
674.186	3.16159
677.626	3.81341
681.065	3.92311
684.503	5.82636
687.939	5.09064
691.372	5.35106
694.806	6.43777
698.239	7.48072
701.67	8.63731
705.098	8.75522
708.526	7.87386
711.954	9.31077
715.378	9.43877
718.802	10.0729
722.226	9.45322
725.646	9.14214
729.067	9.52606
732.484	8.05136
735.902	9.48941
739.317	11.7967
742.731	15.2379
746.145	17.5264
749.556	21.2441
752.966	26.2181
756.377	29.8967
759.784	33.0581
763.19	36.6786
766.594	40.5081
770	45.0218
773.402	49.156
776.803	52.6688
780.202	56.3924
783.6	58.5653
786.997	59.6668
790.393	59.4421
793.787	60.5765
797.18	60.5232
800.572	60.7467
803.963	59.997
807.35	58.714
810.738	58.1885
814.125	56.3308
817.51	55.3026
820.894	55.7445
824.275	57.2533
827.657	60.1475
831.037	64.1911
834.414	66.2806
837.792	69.1507
841.167	71.0213
844.542	73.0886
847.914	73.8802
851.287	74.5064
854.656	76.061
858.026	76.4304
861.393	75.3694
864.761	74.6985
868.125	72.5309
871.489	70.0663
874.85	69.1972
878.213	63.7965
881.572	60.4932
884.931	57.0241
888.287	54.7034
891.643	49.971
894.997	47.339
898.352	46.7663
901.704	49.1124
905.055	49.5249
908.404	50.2137
911.75	51.3945
915.097	53.2678
918.443	54.5471
921.787	54.779
925.13	54.9803
928.472	52.7126
931.813	52.141
935.15	49.787
938.488	49.4285
941.825	47.2536
945.158	44.7307
948.493	40.8929
951.824	38.0299
955.156	34.8626
958.486	31.0259
961.814	28.0936
965.142	29.0434
968.467	29.6806
971.79	33.5434
975.115	34.2905
978.436	36.7029
981.756	39.1332
985.077	37.6541
988.394	37.3598
991.71	36.2239
995.025	35.6349
998.341	32.9802
1001.65	27.7432
1004.97	24.7643
1008.28	27.2062
1011.58	29.7594
1014.89	34.652
1018.2	43.3015
1021.5	50.1476
1024.81	56.1963
1028.11	62.7458
1031.41	69.2442
1034.71	74.5056
1038.01	79.0972
1041.31	84.2153
1044.6	90.5177
1047.9	96.4757
1051.19	99.2266
1054.48	100.428
1057.77	98.9757
1061.06	96.724
1064.35	89.9892
1067.64	81.9949
1070.93	73.2496
1074.21	64.4205
1077.49	55.0932
1080.78	45.1631
1084.06	38.8697
1087.34	37.5437
1090.61	38.2188
1093.89	37.7317
1097.17	38.8432
1100.44	39.7054
1103.71	39.9392
1106.99	41.694
1110.26	43.3049
1113.52	43.6858
1116.79	41.1592
1120.06	41.3036
1123.32	41.8986
1126.59	42.9618
1129.85	41.3461
1133.11	41.4057
1136.37	41.5048
1139.63	38.3443
1142.89	33.5236
1146.15	28.7217
1149.4	25.2626
1152.66	21.4793
1155.91	18.3989
1159.16	14.9813
1162.41	10.9246
1165.66	9.44875
1168.91	6.89834
1172.16	4.33626
1175.4	6.23343
1178.65	3.01612
1181.89	1.44655
1185.13	0.670728
1188.37	1.38516
1191.61	0.737278
1194.85	2.06747
1198.08	4.82805
1201.32	5.38675
1204.55	7.62644
1207.79	11.3838
1211.02	14.5731
1214.25	18.2811
1217.48	21.6352
1220.71	24.2155
1223.93	29.7355
1227.16	35.2541
1230.38	43.1311
1233.6	47.9907
1236.83	54.6049
1240.05	60.3489
1243.26	65.5103
1246.48	70.0831
1249.7	73.4845
1252.92	78.4338
1256.13	83.1002
1259.34	83.8577
1262.55	89.0353
1265.76	93.0708
1268.97	98.288
1272.18	105.334
1275.39	108.576
1278.59	112.741
1281.8	115.186
1285	120.383
1288.2	125.279
1291.4	128.695
1294.6	130.15
1297.8	132.179
1301	133.365
1304.19	136.026
1307.39	135.99
1310.58	133.791
1313.77	131.216
1316.96	129.014
1320.15	127.857
1323.34	123.141
1326.53	119.543
1329.72	116.773
1332.9	113.104
1336.08	108.644
1339.27	105.687
1342.45	104.733
1345.63	103.21
1348.8	102.723
1351.98	101.188
1355.16	101.68
1358.33	101.448
1361.51	100.837
1364.68	103.96
1367.85	104.826
1371.02	102.646
1374.19	103.856
1377.36	104.672
1380.52	104.561
1383.69	106.532
1386.85	107.173
1390.02	108.263
1393.18	109.809
1396.34	111.869
1399.5	116.114
1402.65	118.881
1405.81	124.652
1408.97	129.648
1412.12	137.741
1415.27	148.421
1418.43	159.351
1421.58	170.479
1424.73	183.348
1427.87	196.861
1431.02	209.076
1434.17	220.293
1437.31	227.219
1440.46	232.475
1443.6	234.392
1446.74	232.89
1449.88	229.409
1453.02	223.713
1456.16	214.904
1459.29	204.556
1462.43	192.388
1465.56	180.064
1468.69	164.037
1471.83	146.035
1474.95	130.056
1478.08	114.698
1481.21	98.5187
1484.34	84.0055
1487.47	72.4654
1490.59	59.8577
1493.71	54.0807
1496.84	49.5377
1499.96	45.0196
1503.07	41.2312
1506.19	37.691
1509.31	34.8788
1512.43	32.9431
1515.54	31.9435
1518.65	31.8371
1521.77	31.9404
1524.88	32.1381
1527.99	32.315
1531.1	35.2962
1534.21	38.6573
1537.31	42.1844
1540.42	45.4788
1543.52	46.5916
1546.63	49.8121
1549.73	51.5218
1552.83	53.4225
1555.93	55.129
1559.03	56.5725
1562.12	58.3335
1565.22	62.8042
1568.31	68.2631
1571.41	73.315
1574.5	78.0417
1577.59	83.2569
1580.68	87.9456
1583.77	95.001
1586.86	101.369
1589.95	105.997
1593.03	111.461
1596.11	114.77
1599.2	117.6
1602.28	121.775
1605.36	125.136
1608.44	128.851
1611.52	131.665
1614.6	131.998
1617.67	133.897
1620.75	134.843
1623.82	135.789
1626.89	134.322
1629.96	134.546
1633.04	135.241
1636.11	136.633
1639.17	136.123
1642.24	137.476
1645.31	140.27
1648.37	141.317
1651.43	138.467
1654.5	136.302
1657.56	131.484
1660.62	128.177
1663.67	122.254
1666.73	116.55
1669.79	110.652
1672.84	103.003
1675.9	96.6221
1678.95	89.5158
1682	81.3214
1685.05	74.5432
1688.1	69.0318
1691.15	63.3024
1694.2	56.8202
1697.25	53.8503
1700.29	51.0406
1703.33	47.1215
1706.38	46.0492
1709.42	43.7791
1712.46	41.1704
1715.5	40.3497
1718.54	39.7636
1721.57	37.3596
1724.61	34.9831
1727.64	31.717
1730.68	31.2196
1733.71	29.2107
1736.74	27.9356
1739.77	25.764
1742.8	23.46
1745.83	21.0221
1748.85	17.9548
1751.88	16.5795
1754.91	14.1229
1757.93	13.3527
1760.95	12.1163
1763.97	11.974
1766.99	10.3327
1770.01	9.99091
1773.03	8.77761
1776.04	6.96136
1779.06	6.15203
1782.07	6.02503
1785.09	4.07467
1788.1	4.68119
1791.11	4.31119
1794.12	2.68719
1797.13	1.48567
1800.13	1.75764
1803.14	2.04271
1806.15	1.83536
1809.15	0.348216
1812.15	0.0867865
1815.16	-0.746136
1818.15	-1.12948
1821.16	-1.53697
1824.15	-0.524849
1827.15	-0.829796
1830.15	-0.438251
1833.14	-0.610708
1836.14	1.03861
1839.13	1.00245
1842.12	1.89759
1845.11	2.76694
1848.1	2.98791
1851.09	4.25718
1854.08	6.15158
1857.06	6.45728
1860.05	7.58151
1863.03	8.97495
1866.01	9.83421
1869	9.65437
1871.98	10.0727
1874.96	12.0666
1877.93	13.0967
1880.91	13.6499
1882.47	13.5636
1885.46	13.8011
1888.44	12.9598
1891.43	13.4567
1894.42	14.629
1897.4	14.1509
1900.39	13.9843
1903.37	15.3647
1906.35	15.0644
1909.33	14.696
1912.31	12.9816
1915.29	10.6881
1918.26	10.1996
1921.24	9.29014
1924.21	9.31349
1927.19	8.40833
1930.16	7.33828
1933.13	7.42461
1936.1	6.94538
1939.07	6.51753
1942.04	5.577
1945	4.70391
1947.97	5.25221
1950.93	4.11542
1953.9	3.32379
1956.86	2.46079
1959.82	2.74677
1962.78	3.65341
1965.74	5.44063
1968.7	6.00462
1971.65	7.06749
1974.61	8.80819
1977.57	8.68651
1980.52	9.76099
1983.47	10.2625
1986.42	11.9099
1989.37	11.6013
1992.32	11.8564
1995.27	11.485
1998.22	11.7644
2001.17	11.8346
2004.11	11.1046
2007.05	10.7828
2010	11.5903
2012.94	11.1787
2015.88	9.47379
2018.82	9.82125
2021.76	8.9573
2024.7	8.85382
2027.63	9.3828
2030.57	10.164
2033.5	10.8439
2036.44	12.3001
2039.37	14.6679
2042.3	15.6941
2045.23	17.3473
2048.16	19.4569
2051.08	23.2769
2054.01	26.1242
2056.94	28.5691
2059.86	30.3395
2062.79	32.3295
2065.71	34.7058
2068.63	37.2435
2071.55	40.6871
2074.47	43.0618
2077.39	46.6736
2080.31	49.7102
2083.22	52.0707
2086.13	54.4739
2089.05	56.8484
2091.96	61.1292
2094.87	63.2413
2097.78	65.4299
2100.69	68.7782
2103.6	71.7499
2106.51	74.7632
2109.42	78.5701
2112.32	82.5694
2115.23	86.59
2118.13	90.23
2121.03	93.8986
2123.93	99.7556
2126.83	105.249
2129.73	109.441
2132.63	114.436
2135.53	118.525
2138.42	123.385
2141.32	128.509
2144.21	132.982
2147.1	137.318
2150	140.184
2152.89	142.035
2155.78	143.91
2158.66	144.738
2161.55	145.463
2164.44	147.44
2167.32	146.903
2170.21	146.127
2173.09	144.519
2175.97	142.653
2178.85	141.636
2181.73	138.129
2184.61	134.209
2187.49	129.182
2190.37	124.049
2193.24	120.293
2196.12	116.248
2198.99	110.877
2201.87	104.632
2204.74	100.752
2207.61	96.9521
2210.48	91.8817
2213.35	88.039
2216.21	82.644
2219.08	78.2387
2221.95	73.772
2224.81	70.4118
2227.67	65.8085
2230.54	62.0705
2233.4	62.1796
2236.26	58.8001
2239.11	56.0257
2241.97	51.6981
2244.83	48.6694
2247.69	45.4027
2250.54	42.913
2253.4	39.7074
2256.25	36.3771
2259.1	35.2505
2261.95	32.289
2264.8	29.9806
2267.65	27.1675
2270.5	25.9359
2273.34	24.4314
2276.19	23.5345
2279.03	21.8291
2281.88	20.571
2284.72	18.6279
2287.56	17.664
2290.4	17.2545
2293.24	15.9134
2296.08	14.0785
2298.92	14.2512
2301.76	16.2567
2304.59	16.0563
2307.43	16.549
2310.26	14.9765
2313.09	14.0974
2315.92	13.9319
2318.75	13.4776
2321.58	13.1264
2324.41	12.9498
2327.24	13.7011
2330.06	13.525
2332.89	12.398
2335.71	11.2304
2338.54	10.8903
2341.36	9.59563
2344.18	7.69356
2347	7.06665
2349.82	6.14888
2352.64	3.50471
2355.45	3.34419
2358.27	3.80053
2361.08	3.81431
2363.9	4.20907
2366.71	5.57405
2369.52	6.83138
2372.33	8.43841
2375.14	8.8291
2377.95	9.36981
2380.76	9.82822
2383.57	9.89911
2386.37	10.1432
2389.18	11.1033
2391.98	13.1847
2394.79	12.8903
2397.59	13.0857
2400.39	12.9504
2403.19	12.2764
2405.99	12.2699
2408.78	12.4259
2411.58	13.4119
2414.38	14.0411
2417.17	14.1179
2419.97	14.5888
2422.76	15.8745
2425.55	16.2962
2428.34	18.4638
2431.13	16.7104
2433.92	16.5913
2436.71	16.7614
2439.49	15.945
2442.28	14.9066
2445.06	14.7537
2447.85	11.9883
2450.63	10.6115
2453.41	8.54829
2456.19	8.06995
2458.97	7.15822
2461.75	6.23552
2464.53	5.98163
2467.31	4.87369
2470.08	5.03552
2472.86	5.09693
2475.63	4.82349
2478.4	5.7863
2481.17	5.67766
2483.94	5.43726
2486.72	6.55764
2489.48	6.91582
2492.25	7.37281
2495.02	7.67658
2497.79	7.97741
2500.55	7.99198
2503.31	8.47278
2506.08	7.76265
2508.84	6.24822
2511.6	6.00949
2514.36	5.54202
2517.12	3.15865
2519.88	2.87338
2522.63	2.45862
2525.39	3.62248
2528.14	3.07639
2530.9	1.87417
2533.65	1.4704
2536.4	1.03688
2539.15	1.23299
2541.9	0.641059
2544.65	2.55549
2547.4	4.42189
2550.15	5.23326
2552.89	6.85834
2555.64	7.85109
2558.38	9.81463
2561.12	9.61408
2563.87	8.85565
2566.61	9.94473
2569.35	9.43916
2572.09	8.53125
2574.83	9.82208
2577.56	8.41375
2580.3	7.7264
2583.04	5.72008
2585.77	5.28501
2588.5	5.25574
2591.23	4.25329
2593.97	3.50495
2596.7	3.1562
2599.43	4.18036
2602.15	3.28059
2604.88	4.07242
2607.61	5.79601
2610.33	6.67586
2613.06	7.92868
2615.78	7.23374
2618.51	7.43149
2621.23	7.39079
2623.95	7.09187
2626.67	7.39351
2629.39	6.19904
2632.1	7.21018
2634.82	7.93815
2637.54	7.41878
2640.25	7.71858
2642.97	9.20363
2645.68	9.01469
2648.39	9.20397
2651.1	8.58732
2653.81	9.21323
2656.52	9.98934
2659.23	9.88126
2661.94	10.9554
2664.64	10.8447
2667.35	10.2725
2670.05	10.3505
2672.76	12.0867
2675.46	10.8566
2678.16	10.1695
2680.86	11.6468
2683.56	12.6407
2686.26	12.7881
2688.96	12.9011
2691.65	12.0693
2694.35	13.1897
2697.04	13.6503
2699.74	14.8432
2702.43	16.4403
2705.12	17.1497
2707.81	18.6027
2710.5	20.1196
2713.19	20.5673
2715.88	21.4522
2718.57	21.1882
2721.25	21.0462
2723.94	21.1965
2726.62	19.9615
2729.3	20.1495
2731.99	20.0375
2734.67	19.276
2737.35	18.2365
2740.03	17.8271
2742.71	17.3706
2745.38	16.2719
2748.06	15.26
2750.74	14.4441
2753.41	13.1332
2756.09	11.0827
2758.76	10.1914
2761.43	8.01183
2764.1	7.48472
2766.77	7.1476
2769.44	5.21306
2772.11	3.69933
2774.77	3.49483
2777.44	2.00519
2780.11	1.49341
2782.77	1.20353
2785.43	0.0125556
2788.1	0.136907
2790.76	-0.0131158
2793.42	1.33638
2796.08	2.49891
2798.74	2.3494
2801.4	2.64315
2804.05	3.89379
2806.71	4.17799
2809.36	4.34613
2812.02	5.51088
2814.67	8.17311
2817.32	12.4172
2819.97	17.9303
2822.62	26.6185
2825.27	37.5265
2827.92	50.6705
2830.57	66.7313
2833.22	81.9109
2835.86	99.1045
2838.51	119.396
2841.15	140.038
2843.79	160.923
2846.43	182.918
2849.08	205.75
2851.72	227.759
2854.36	250.143
2856.99	271.645
2859.63	291.146
2862.27	309.657
2864.9	326.143
2867.54	341.549
2870.17	354.969
2872.8	366.466
2875.43	375.564
2878.07	386.608
2880.7	398.373
2883.32	411.992
2885.95	424.788
2888.58	440.042
2891.21	453.949
2893.83	468.496
2896.46	484.318
2899.08	500.508
2901.7	518.358
2904.32	535.915
2906.94	554.083
2909.56	573.687
2912.18	593.947
2914.8	613.928
2917.42	630.087
2920.03	642.598
2922.65	652.162
2925.26	658.205
2927.88	661.283
2930.49	658.44
2933.1	651.43
2935.71	639.49
2938.32	624.091
2940.93	604.18
2943.54	581.843
2946.14	559.199
2948.75	532.561
2951.35	504.354
2953.96	477.675
2956.56	449.177
2959.16	422
2961.77	398.042
2964.37	373.213
2966.96	351.093
2969.56	329.57
2972.16	311.022
2974.76	293.747
2977.35	277.225
2979.95	259.754
2982.54	241.769
2985.14	225.197
2987.73	208.851
2990.32	192.749
2992.91	176.246
2995.5	159.272
2998.09	142.259
3000.68	126.777
3003.26	111.705
3005.85	95.8804
3008.43	81.2252
3011.02	68.4089
3013.6	56.6927
3016.19	46.5885
3018.77	38.4385
3021.35	30.2704
3023.93	24.5864
3026.5	18.5955
3029.08	13.375
3031.66	9.98322
3034.24	5.99278
3036.81	4.77236
3039.39	4.20077
3041.96	3.81941
3044.53	4.58276
3047.1	5.05406
3049.67	6.23445
3052.24	6.83541
3054.81	7.83163
3057.38	9.00171
3059.95	9.18262
3062.52	9.92299
3065.08	10.2436
3067.65	8.76258
3070.21	8.13625
3072.77	8.27418
3075.33	8.08553
3077.89	7.63035
3080.45	6.0146
3083.01	3.83737
3085.57	2.12456
3088.13	0.613603
3090.68	-0.0934944
3093.24	-0.8707
3095.79	-0.633074
3098.35	0.934155
3100.9	2.12942
3103.45	3.19825
3106	4.14447
3108.55	5.37995
3111.1	6.51829
3113.65	8.79189
3116.2	9.43312
3118.75	11.5342
3121.29	13.6147
3123.84	15.5271
3126.38	17.6198
3128.92	19.9322
3131.47	22.5619
3134.01	25.218
3136.55	27.318
3139.09	28.092
3141.63	30.5316
3144.17	33.6563
3146.7	37.8417
3149.24	43.7438