File: data/Raman/poly_smoothed/Mb_40_24_34_1x_45s_532 nm_x100_100%_600 gr_mm_01.txt
#Acq. time (s)=	45
#Accumulations=	2
#Range (cm-¹)=	200...3150
#Windows=	2
#Auto scanning=	Off
#Autofocus=	Off
#Macrospot=	Off
#AutoExposure=	Off
#Spike filter=	Multiple accum.
#Delay time (s)=	0
#Binning=	1
#Readout mode=	Signal
#DeNoise=	Off
#ICS correction=	On
#Dark correction=	Off
#Inst. Process=	Off
#Detector Gain=	Best Dynamic Range
#Detector ADC=	20 kHz
#Detector temperature (°C)=	-70.08
#Instrument=	LabRAM HR Evol
#Detector=	Synapse
#Objective=	x100
#Grating=	600 gr/mm
#ND Filter=	100%
#Laser (nm)=	532
#Hole=	100.021
#Range=	Auto
#Laser Pol.=	No
#Raman. Pol.=	No
#Laser Pol. (°)=	-0.0007625
#Raman Pol. (°)=	89.9995
#Collection=	Microscope
#StageXY=	Marzhauser
#StageZ=	Marzhauser
#X (µm)=	-2487.1
#Y (µm)=	-82.7
#Z (µm)=	-10.3
#Full time(mm:ss)=	3:19
#Project=
#Sample=
#Site=
#Title=	Mb_40_24_34_2x_45s_532 nm_x100_100%_600 gr_mm
#Remark=
#Date=	14.07.2022 13:11
#Acquired=	14.07.2022 13:11:47
#Base:Fit=	10.08.2022 10:47:00
#Base:Sub=	10.08.2022 10:47:12
#Filter:Polynom=	16.08.2022 10:11:48
#AxisType[0]=Intens
#AxisUnit[0]=Cnt
#AxisType[1]=Spectr
#AxisUnit[1]=1/cm
200.554	30.5435
204.183	25.0943
207.813	24.1074
211.439	21.6007
215.065	19.6904
218.688	17.0116
222.312	14.3858
225.933	9.99093
229.552	5.8794
233.171	4.18411
236.787	5.59216
240.402	7.29444
244.015	6.82639
247.627	7.90617
251.24	8.48331
254.849	9.11975
258.457	8.89185
262.063	8.39768
265.668	8.46724
269.271	8.47173
272.873	10.3273
276.474	10.199
280.073	9.12312
283.671	8.9551
287.268	7.83156
290.863	7.36206
294.456	7.22142
298.049	6.48839
301.637	5.85996
305.227	4.40856
308.815	4.76748
312.402	3.34866
315.987	4.65358
319.569	5.76894
323.151	10.1586
326.733	11.3979
330.31	12.5335
333.889	13.2381
337.464	13.5307
341.039	13.285
344.611	15.2903
348.184	13.9573
351.754	13.7174
355.324	13.3637
358.89	12.2422
362.455	11.6562
366.021	8.71636
369.584	7.68818
373.145	5.74091
376.707	6.81367
380.265	6.37093
383.822	5.599
387.378	7.69606
390.934	8.93783
394.487	8.3967
398.038	10.3976
401.588	12.6448
405.137	15.9714
408.685	17.6419
412.23	19.6044
415.775	17.8192
419.318	20.2283
422.86	21.1662
426.401	21.8374
429.94	22.8276
433.478	22.0191
437.012	22.8573
440.547	23.3942
444.081	22.5217
447.613	20.7602
451.142	20.2704
454.672	18.8039
458.2	21.4096
461.725	20.8082
465.251	20.9507
468.775	22.1429
472.296	24.2386
475.817	26.1073
479.335	28.7311
482.854	29.8589
486.37	31.207
489.886	34.3187
493.398	35.216
496.91	35.5943
500.422	36.2332
503.93	39.948
507.438	39.8406
510.946	41.0547
514.45	40.8608
517.954	40.9434
521.456	41.7252
524.956	38.9947
528.456	37.3162
531.956	36.1592
535.452	35.0057
538.947	34.6459
542.441	35.3864
545.934	34.7715
549.425	33.1313
552.915	33.3855
556.403	33.1238
559.889	30.8517
563.375	30.9475
566.859	27.0247
570.342	23.9188
573.824	18.4777
577.303	17.3551
580.782	15.9123
584.26	15.1451
587.734	12.4541
591.21	9.7486
594.684	8.86812
598.154	9.90713
601.626	12.2102
605.094	14.2209
608.562	14.224
612.027	16.3172
615.493	15.2148
618.956	18.7645
622.419	20.0847
625.879	21.1834
629.338	21.8915
632.797	21.3373
636.254	22.4523
639.708	20.8351
643.162	19.863
646.614	16.1883
650.067	13.4353
653.516	11.2157
656.964	8.78282
660.411	7.75486
663.857	7.03153
667.301	5.09814
670.744	3.7484
674.186	3.37144
677.626	3.95125
681.065	6.31934
684.503	7.63019
687.939	9.53479
691.372	8.14532
694.806	8.62682
698.239	7.81497
701.67	8.6244
705.098	8.87606
708.526	8.19679
711.954	7.61214
715.378	8.21386
718.802	7.81543
722.226	7.40847
725.646	7.89755
729.067	8.00146
732.484	7.64517
735.902	11.8708
739.317	14.732
742.731	17.3161
746.145	22.6918
749.556	23.3277
752.966	28.4706
756.377	32.5875
759.784	37.0492
763.19	39.5217
766.594	44.6811
770	46.2024
773.402	49.2686
776.803	50.2573
780.202	51.4399
783.6	52.9071
786.997	55.8204
790.393	55.6643
793.787	54.058
797.18	53.9043
800.572	53.7338
803.963	52.9723
807.35	52.844
810.738	53.0337
814.125	53.1707
817.51	55.5869
820.894	58.1778
824.275	58.6835
827.657	62.3356
831.037	64.7442
834.414	64.2681
837.792	65.5119
841.167	64.9623
844.542	65.5398
847.914	66.0514
851.287	65.6665
854.656	64.3858
858.026	64.7003
861.393	64.175
864.761	61.4695
868.125	61.2102
871.489	58.7598
874.85	54.2018
878.213	51.9569
881.572	49.3761
884.931	45.6898
888.287	43.6422
891.643	40.8458
894.997	38.7065
898.352	38.7862
901.704	37.4744
905.055	37.2433
908.404	36.4246
911.75	36.1425
915.097	33.035
918.443	31.9431
921.787	31.3435
925.13	30.598
928.472	29.5168
931.813	27.3628
935.15	24.8562
938.488	23.3661
941.825	20.4967
945.158	16.3178
948.493	15.0034
951.824	17.212
955.156	14.8587
958.486	13.9469
961.814	16.0211
965.142	23.019
968.467	33.0004
971.79	43.4271
975.115	53.1409
978.436	60.7217
981.756	68.4763
985.077	73.3314
988.394	75.0669
991.71	75.9035
995.025	77.4002
998.341	77.5498
1001.65	75.1785
1004.97	72.1909
1008.28	67.6586
1011.58	66.2573
1014.89	64.3056
1018.2	61.6669
1021.5	59.8927
1024.81	56.4013
1028.11	54.7053
1031.41	57.7544
1034.71	56.0376
1038.01	55.0131
1041.31	57.1613
1044.6	62.3846
1047.9	67.7647
1051.19	68.853
1054.48	70.9932
1057.77	71.1379
1061.06	69.7462
1064.35	68.4996
1067.64	65.7226
1070.93	62.2169
1074.21	59.0452
1077.49	55.8082
1080.78	49.1212
1084.06	45.5694
1087.34	44.0197
1090.61	42.7606
1093.89	41.5906
1097.17	41.8107
1100.44	42.5758
1103.71	42.6633
1106.99	41.1254
1110.26	41.5501
1113.52	40.8283
1116.79	38.1941
1120.06	35.4795
1123.32	32.5506
1126.59	31.9155
1129.85	32.0996
1133.11	31.6679
1136.37	31.1073
1139.63	28.0261
1142.89	26.1144
1146.15	23.472
1149.4	18.6573
1152.66	17.5887
1155.91	14.2953
1159.16	11.201
1162.41	9.45911
1165.66	9.11368
1168.91	7.23974
1172.16	6.44251
1175.4	7.96023
1178.65	8.7835
1181.89	10.2352
1185.13	9.24604
1188.37	12.2965
1191.61	12.4583
1194.85	12.9439
1198.08	15.2333
1201.32	19.3946
1204.55	23.2826
1207.79	28.1165
1211.02	34.7243
1214.25	40.7918
1217.48	46.6138
1220.71	53.5371
1223.93	61.4741
1227.16	67.854
1230.38	75.9477
1233.6	84.392
1236.83	88.7492
1240.05	97.1329
1243.26	102.116
1246.48	106.093
1249.7	112.784
1252.92	118.554
1256.13	124.228
1259.34	128.532
1262.55	132.893
1265.76	135.705
1268.97	141.664
1272.18	147.211
1275.39	155.045
1278.59	160.62
1281.8	166.238
1285	172.462
1288.2	179.83
1291.4	186.012
1294.6	190.169
1297.8	192.55
1301	195.499
1304.19	195.795
1307.39	196.044
1310.58	196.277
1313.77	193.451
1316.96	192.148
1320.15	189.705
1323.34	186.645
1326.53	184.745
1329.72	180.933
1332.9	178.209
1336.08	174.229
1339.27	169.903
1342.45	166.576
1345.63	163.878
1348.8	160.521
1351.98	160.097
1355.16	156.83
1358.33	153.387
1361.51	149.473
1364.68	149.267
1367.85	148.013
1371.02	146.097
1374.19	144.543
1377.36	143.345
1380.52	144.541
1383.69	145.059
1386.85	145.883
1390.02	147.987
1393.18	149.787
1396.34	151.879
1399.5	154.411
1402.65	158.668
1405.81	164.053
1408.97	167.798
1412.12	174.588
1415.27	181.366
1418.43	192.313
1421.58	203.47
1424.73	215.981
1427.87	227.37
1431.02	240.454
1434.17	250.836
1437.31	258.971
1440.46	264.89
1443.6	271.26
1446.74	273.95
1449.88	272.375
1453.02	270.012
1456.16	264.805
1459.29	259.812
1462.43	250.198
1465.56	239.089
1468.69	227.545
1471.83	213.873
1474.95	200.746
1478.08	187.407
1481.21	174.409
1484.34	160.388
1487.47	149.616
1490.59	139.622
1493.71	131.727
1496.84	125.698
1499.96	117.553
1503.07	113.588
1506.19	109.171
1509.31	106.253
1512.43	99.9174
1515.54	95.3422
1518.65	94.1563
1521.77	92.0164
1524.88	89.7551
1527.99	87.9442
1531.1	89.1387
1534.21	92.5926
1537.31	95.8398
1540.42	100.903
1543.52	106.27
1546.63	112.301
1549.73	117.75
1552.83	121.879
1555.93	127.741
1559.03	134.185
1562.12	139.985
1565.22	145.017
1568.31	152.606
1571.41	161.681
1574.5	169.633
1577.59	176.615
1580.68	184.47
1583.77	191.704
1586.86	197.075
1589.95	201.551
1593.03	205.973
1596.11	210.172
1599.2	209.196
1602.28	209.38
1605.36	209.771
1608.44	208.457
1611.52	207.5
1614.6	206.629
1617.67	205.237
1620.75	203.083
1623.82	199.553
1626.89	198.114
1629.96	197.32
1633.04	195.151
1636.11	194.549
1639.17	194.58
1642.24	198.559
1645.31	201.072
1648.37	202.126
1651.43	202.068
1654.5	201.238
1657.56	200.729
1660.62	196.011
1663.67	190.269
1666.73	185.633
1669.79	176.855
1672.84	166.55
1675.9	153.565
1678.95	142.784
1682	130.775
1685.05	117.432
1688.1	105.87
1691.15	96.3048
1694.2	84.5305
1697.25	73.4497
1700.29	65.2151
1703.33	57.475
1706.38	48.2278
1709.42	44.3088
1712.46	40.5274
1715.5	36.4424
1718.54	33.4246
1721.57	30.7818
1724.61	27.4337
1727.64	26.1342
1730.68	24.6971
1733.71	23.3457
1736.74	21.0507
1739.77	20.9598
1742.8	20.8637
1745.83	18.6114
1748.85	16.803
1751.88	15.3117
1754.91	14.5674
1757.93	12.4023
1760.95	13.0885
1763.97	12.8991
1766.99	12.0717
1770.01	10.3535
1773.03	10.0344
1776.04	9.1652
1779.06	7.4408
1782.07	6.86855
1785.09	7.17577
1788.1	6.38609
1791.11	6.75171
1794.12	4.83403
1797.13	3.85612
1800.13	3.23364
1803.14	2.05222
1806.15	1.29952
1809.15	0.53503
1812.15	-0.439883
1815.16	-0.201315
1818.15	-0.206383
1821.16	0.45302
1824.15	-0.683969
1827.15	-1.95239
1830.15	0.804959
1833.14	2.72794
1836.14	3.99473
1839.13	5.30253
1842.12	8.16171
1845.11	10.3492
1848.1	11.3284
1851.09	11.5435
1854.08	12.9497
1857.06	14.5343
1860.05	15.192
1863.03	16.7089
1866.01	17.7842
1869	16.4532
1871.98	16.5506
1874.96	16.4509
1877.93	15.8148
1880.91	15.1922
1882.47	14.5006
1885.46	13.4154
1888.44	13.0363
1891.43	10.3254
1894.42	8.29009
1897.4	6.21471
1900.39	7.24027
1903.37	8.16515
1906.35	7.54677
1909.33	8.44102
1912.31	9.00629
1915.29	9.01844
1918.26	7.68938
1921.24	5.7478
1924.21	5.02359
1927.19	5.59958
1930.16	3.39749
1933.13	3.37381
1936.1	3.65101
1939.07	3.01369
1942.04	0.881045
1945	1.06107
1947.97	1.0435
1950.93	1.16543
1953.9	2.75856
1956.86	2.13603
1959.82	2.05186
1962.78	2.48153
1965.74	2.17554
1968.7	3.44778
1971.65	3.30538
1974.61	5.31659
1977.57	6.77747
1980.52	8.27212
1983.47	8.13217
1986.42	8.79653
1989.37	9.83361
1992.32	10.0843
1995.27	12.8641
1998.22	14.3281
2001.17	14.2404
2004.11	14.2599
2007.05	14.5453
2010	13.8406
2012.94	13.1704
2015.88	12.6999
2018.82	12.3861
2021.76	13.3561
2024.7	13.8981
2027.63	13.7393
2030.57	13.8202
2033.5	15.086
2036.44	15.9835
2039.37	16.1985
2042.3	15.694
2045.23	19.1062
2048.16	20.4623
2051.08	21.6884
2054.01	22.5118
2056.94	24.4479
2059.86	26.7063
2062.79	30.7607
2065.71	32.6849
2068.63	35.7366
2071.55	35.4207
2074.47	37.8913
2077.39	39.3137
2080.31	41.5957
2083.22	43.1435
2086.13	43.5846
2089.05	45.4397
2091.96	48.3772
2094.87	51.9173
2097.78	55.1704
2100.69	58.2725
2103.6	59.8298
2106.51	62.9538
2109.42	67.6888
2112.32	71.9373
2115.23	76.9985
2118.13	82.8681
2121.03	88.4226
2123.93	93.4678
2126.83	100.675
2129.73	106.467
2132.63	114.24
2135.53	121.199
2138.42	129.707
2141.32	137.467
2144.21	144.89
2147.1	151.086
2150	157.961
2152.89	165.298
2155.78	170.96
2158.66	176.351
2161.55	182.205
2164.44	185.693
2167.32	188.555
2170.21	191.31
2173.09	191.123
2175.97	192.189
2178.85	190.528
2181.73	186.394
2184.61	182.545
2187.49	178.474
2190.37	173.661
2193.24	168.247
2196.12	162.898
2198.99	154.76
2201.87	148.736
2204.74	142.945
2207.61	135.594
2210.48	128.285
2213.35	120.354
2216.21	114.062
2219.08	106.453
2221.95	100.248
2224.81	92.3927
2227.67	85.6387
2230.54	80.7811
2233.4	74.9748
2236.26	69.3193
2239.11	64.1842
2241.97	57.8378
2244.83	54.1734
2247.69	49.204
2250.54	44.4067
2253.4	42.8339
2256.25	41.1706
2259.1	38.1334
2261.95	35.6322
2264.8	34.3033
2267.65	33.4964
2270.5	33.2399
2273.34	34.1308
2276.19	31.7457
2279.03	28.736
2281.88	28.6726
2284.72	26.8976
2287.56	25.243
2290.4	22.8525
2293.24	19.9983
2296.08	19.3969
2298.92	20.1621
2301.76	19.2572
2304.59	18.2177
2307.43	16.578
2310.26	14.7825
2313.09	14.4274
2315.92	13.0353
2318.75	12.6086
2321.58	14.0889
2324.41	14.4026
2327.24	13.7033
2330.06	14.1245
2332.89	14.9358
2335.71	14.9902
2338.54	14.724
2341.36	12.7359
2344.18	10.3234
2347	9.37256
2349.82	8.78879
2352.64	8.32016
2355.45	7.91293
2358.27	6.1821
2361.08	4.782
2363.9	4.92207
2366.71	5.60694
2369.52	5.83865
2372.33	5.45788
2375.14	3.69843
2377.95	1.74685
2380.76	1.78281
2383.57	1.42656
2386.37	1.40594
2389.18	3.5407
2391.98	3.69398
2394.79	4.74457
2397.59	5.7596
2400.39	6.1103
2403.19	6.47298
2405.99	6.59022
2408.78	6.17398
2411.58	5.96616
2414.38	7.96289
2417.17	7.50045
2419.97	8.05847
2422.76	8.71855
2425.55	8.29768
2428.34	8.65922
2431.13	9.64917
2433.92	9.59679
2436.71	9.58731
2439.49	9.64403
2442.28	7.84125
2445.06	6.34388
2447.85	4.42024
2450.63	4.35072
2453.41	3.95177
2456.19	3.62142
2458.97	3.34401
2461.75	2.32262
2464.53	1.63439
2467.31	1.32479
2470.08	0.895075
2472.86	0.460057
2475.63	0.959487
2478.4	0.562067
2481.17	1.16088
2483.94	-0.0217206
2486.72	0.981073
2489.48	1.57641
2492.25	2.74866
2495.02	3.06695
2497.79	4.04605
2500.55	3.0111
2503.31	4.84091
2506.08	4.46644
2508.84	3.27974
2511.6	2.67043
2514.36	2.468
2517.12	2.72278
2519.88	2.81409
2522.63	2.50798
2525.39	1.66778
2528.14	1.37066
2530.9	0.336378
2533.65	2.45591
2536.4	1.45422
2539.15	3.38969
2541.9	3.61137
2544.65	4.83983
2547.4	6.33084
2550.15	7.41372
2552.89	8.6179
2555.64	10.6835
2558.38	12.0094
2561.12	13.8631
2563.87	15.2417
2566.61	15.7819
2569.35	16.5006
2572.09	16.9173
2574.83	17.1302
2577.56	17.7304
2580.3	16.0987
2583.04	16.9384
2585.77	17.1296
2588.5	14.8709
2591.23	12.571
2593.97	11.4349
2596.7	11.3933
2599.43	10.1591
2602.15	9.271
2604.88	9.26417
2607.61	9.0441
2610.33	8.46689
2613.06	8.42528
2615.78	7.78958
2618.51	7.05825
2621.23	7.51547
2623.95	7.59291
2626.67	7.73529
2629.39	7.80317
2632.1	6.97958
2634.82	9.95374
2637.54	9.4493
2640.25	11.4033
2642.97	12.9701
2645.68	12.6133
2648.39	12.9851
2651.1	13.3331
2653.81	12.5343
2656.52	14.156
2659.23	15.8262
2661.94	15.869
2664.64	16.3529
2667.35	16.2816
2670.05	15.2685
2672.76	15.5302
2675.46	15.3527
2678.16	13.9119
2680.86	13.6028
2683.56	13.2648
2686.26	13.0938
2688.96	12.6821
2691.65	13.3717
2694.35	12.8535
2697.04	13.0109
2699.74	14.6354
2702.43	15.197
2705.12	16.776
2707.81	17.9227
2710.5	18.3017
2713.19	18.5206
2715.88	19.8724
2718.57	21.7582
2721.25	23.7282
2723.94	23.629
2726.62	22.1845
2729.3	21.4196
2731.99	20.778
2734.67	18.3562
2737.35	17.0527
2740.03	16.3355
2742.71	14.3968
2745.38	12.3709
2748.06	11.3625
2750.74	10.7311
2753.41	9.88263
2756.09	9.09086
2758.76	7.53585
2761.43	7.18776
2764.1	6.02081
2766.77	5.87206
2769.44	6.00527
2772.11	4.95901
2774.77	3.70874
2777.44	3.38114
2780.11	3.48153
2782.77	2.73149
2785.43	1.98498
2788.1	2.00542
2790.76	0.896631
2793.42	0.833453
2796.08	0.453836
2798.74	-0.648681
2801.4	-0.159454
2804.05	1.10434
2806.71	0.913409
2809.36	0.348856
2812.02	0.0170892
2814.67	0.913017
2817.32	3.2562
2819.97	6.53723
2822.62	13.2717
2825.27	22.1134
2827.92	33.9408
2830.57	45.4795
2833.22	58.045
2835.86	72.6941
2838.51	87.8814
2841.15	105.556
2843.79	124.592
2846.43	145.386
2849.08	165.642
2851.72	189.177
2854.36	212.301
2856.99	233.818
2859.63	255.392
2862.27	274.605
2864.9	292.82
2867.54	308.897
2870.17	324.059
2872.8	337.594
2875.43	349.957
2878.07	361.625
2880.7	373.849
2883.32	388.272
2885.95	402.298
2888.58	417.46
2891.21	434.422
2893.83	452.132
2896.46	468.861
2899.08	488.994
2901.7	511.679
2904.32	535.76
2906.94	562.762
2909.56	592.776
2912.18	620.943
2914.8	650.68
2917.42	678.39
2920.03	701.572
2922.65	721.428
2925.26	734.997
2927.88	742.779
2930.49	746.623
2933.1	744.961
2935.71	738.495
2938.32	726.162
2940.93	708.841
2943.54	685.437
2946.14	661.205
2948.75	631.888
2951.35	601.738
2953.96	570.672
2956.56	537.253
2959.16	505.961
2961.77	473.444
2964.37	443.726
2966.96	416.065
2969.56	391.633
2972.16	368.303
2974.76	346.492
2977.35	325.245
2979.95	301.79
2982.54	278.767
2985.14	255.963
2987.73	233.864
2990.32	212.376
2992.91	191.138
2995.5	171.63
2998.09	152.32
3000.68	134.068
3003.26	115.764
3005.85	99.3013
3008.43	83.3619
3011.02	68.7997
3013.6	56.2888
3016.19	44.6698
3018.77	33.9459
3021.35	25.403
3023.93	18.3658
3026.5	11.5694
3029.08	7.86875
3031.66	5.06264
3034.24	5.03552
3036.81	4.01458
3039.39	3.51635
3041.96	2.43685
3044.53	2.50212
3047.1	2.36881
3049.67	4.3245
3052.24	6.20873
3054.81	7.20137
3057.38	7.72904
3059.95	7.78908
3062.52	8.44605
3065.08	7.9729
3067.65	8.08967
3070.21	7.81458
3072.77	7.72074
3075.33	6.79026
3077.89	5.04637
3080.45	3.84356
3083.01	2.14751
3085.57	0.776806
3088.13	-1.04063
3090.68	-0.505291
3093.24	-1.38668
3095.79	0.246665
3098.35	0.67075
3100.9	2.11853
3103.45	3.33492
3106	4.28858
3108.55	5.93025
3111.1	7.00527
3113.65	10.9471
3116.2	12.8625
3118.75	15.6923
3121.29	18.9839
3123.84	22.4302
3126.38	26.0156
3128.92	31.0603
3131.47	35.5084
3134.01	39.9406
3136.55	44.4412
3139.09	48.9043
3141.63	52.4616
3144.17	56.6951
3146.7	61.721
3149.24	67.3755