File: data/Raman/poly_smoothed/Mb_40_24_18_1x_45s_532 nm_x100_100%_600 gr_mm_01.txt
#Acq. time (s)=	45
#Accumulations=	2
#Range (cm-¹)=	200...3150
#Windows=	2
#Auto scanning=	Off
#Autofocus=	Off
#Macrospot=	Off
#AutoExposure=	Off
#Spike filter=	Multiple accum.
#Delay time (s)=	0
#Binning=	1
#Readout mode=	Signal
#DeNoise=	Off
#ICS correction=	On
#Dark correction=	Off
#Inst. Process=	Off
#Detector Gain=	Best Dynamic Range
#Detector ADC=	20 kHz
#Detector temperature (°C)=	-70.08
#Instrument=	LabRAM HR Evol
#Detector=	Synapse
#Objective=	x100
#Grating=	600 gr/mm
#ND Filter=	100%
#Laser (nm)=	532
#Hole=	100.021
#Range=	Auto
#Laser Pol.=	No
#Raman. Pol.=	No
#Laser Pol. (°)=	-0.0007625
#Raman Pol. (°)=	89.9995
#Collection=	Microscope
#StageXY=	Marzhauser
#StageZ=	Marzhauser
#X (µm)=	-2535.5
#Y (µm)=	-119.3
#Z (µm)=	-10.6
#Full time(mm:ss)=	3:18
#Project=
#Sample=
#Site=
#Title=	Mb_40_24_18_2x_45s_532 nm_x100_100%_600 gr_mm
#Remark=
#Date=	14.07.2022 12:00
#Acquired=	14.07.2022 12:00:06
#Base:Fit=	10.08.2022 10:47:00
#Base:Sub=	10.08.2022 10:47:12
#Filter:Polynom=	16.08.2022 10:11:48
#AxisType[0]=Intens
#AxisUnit[0]=Cnt
#AxisType[1]=Spectr
#AxisUnit[1]=1/cm
200.554	100.843
204.183	86.7008
207.813	77.4957
211.439	67.7215
215.065	61.2491
218.688	52.7824
222.312	46.5081
225.933	43.7154
229.552	38.8677
233.171	35.0507
236.787	34.1149
240.402	32.9026
244.015	29.6854
247.627	29.015
251.24	27.8424
254.849	28.744
258.457	28.4268
262.063	28.3018
265.668	25.2191
269.271	23.8796
272.873	23.3939
276.474	19.689
280.073	17.9416
283.671	16.7873
287.268	13.5645
290.863	13.9165
294.456	10.8458
298.049	11.239
301.637	9.559
305.227	10.6267
308.815	10.4075
312.402	12.9502
315.987	13.8626
319.569	15.5516
323.151	17.1406
326.733	18.061
330.31	18.3113
333.889	20.5008
337.464	21.1874
341.039	19.4583
344.611	18.9964
348.184	18.8386
351.754	14.7992
355.324	12.4295
358.89	10.7418
362.455	8.53853
366.021	7.6223
369.584	5.86116
373.145	4.76089
376.707	4.52681
380.265	4.57389
383.822	4.43167
387.378	6.82463
390.934	6.25357
394.487	8.65193
398.038	8.17873
401.588	9.00814
405.137	8.35597
408.685	9.12471
412.23	9.06299
415.775	9.99094
419.318	11.5647
422.86	11.2722
426.401	10.128
429.94	8.45622
433.478	8.33101
437.012	9.13201
440.547	8.3606
444.081	6.14748
447.613	7.18662
451.142	7.36894
454.672	6.98817
458.2	6.96314
461.725	7.10194
465.251	8.60106
468.775	12.5899
472.296	16.3542
475.817	17.6067
479.335	19.6783
482.854	20.2477
486.37	22.1042
489.886	24.5389
493.398	27.6199
496.91	31.8726
500.422	35.3421
503.93	37.9886
507.438	40.9714
510.946	44.7904
514.45	47.2505
517.954	51.0135
521.456	52.1954
524.956	53.2437
528.456	56.0399
531.956	56.8631
535.452	56.8671
538.947	55.2011
542.441	55.2289
545.934	55.6438
549.425	57.1923
552.915	55.3131
556.403	55.576
559.889	52.7271
563.375	52.7636
566.859	48.8154
570.342	43.8382
573.824	42.8554
577.303	40.925
580.782	39.0114
584.26	38.7802
587.734	36.3793
591.21	35.3818
594.684	33.5657
598.154	33.1824
601.626	31.391
605.094	31.1558
608.562	31.7648
612.027	31.4089
615.493	32.9367
618.956	29.7633
622.419	31.2689
625.879	34.8456
629.338	34.2815
632.797	34.7626
636.254	33.115
639.708	31.3007
643.162	30.0659
646.614	28.66
650.067	26.8373
653.516	22.9101
656.964	22.5602
660.411	22.7571
663.857	21.2302
667.301	20.734
670.744	18.4021
674.186	17.0772
677.626	18.0985
681.065	20.8577
684.503	22.5302
687.939	24.8174
691.372	27.2014
694.806	26.5172
698.239	26.9784
701.67	28.0403
705.098	28.4492
708.526	32.8704
711.954	32.4619
715.378	31.8489
718.802	30.3491
722.226	30.3912
725.646	29.1354
729.067	28.6435
732.484	29.5754
735.902	30.0734
739.317	30.5077
742.731	34.5606
746.145	35.6494
749.556	37.0249
752.966	41.073
756.377	43.0591
759.784	46.9032
763.19	50.9432
766.594	53.0708
770	54.8317
773.402	58.3002
776.803	58.6837
780.202	61.1031
783.6	61.1176
786.997	62.8205
790.393	64.2623
793.787	65.4267
797.18	62.4456
800.572	62.4579
803.963	62.1187
807.35	61.165
810.738	62.4472
814.125	61.47
817.51	63.8907
820.894	64.5615
824.275	68.0882
827.657	70.1171
831.037	72.4157
834.414	72.5919
837.792	73.9338
841.167	76.7615
844.542	78.3072
847.914	80.2273
851.287	83.4705
854.656	84.0031
858.026	82.7261
861.393	82.4676
864.761	77.9127
868.125	74.6008
871.489	71.9902
874.85	68.6639
878.213	64.3556
881.572	59.9697
884.931	56.2435
888.287	50.91
891.643	48.1288
894.997	45.5732
898.352	43.2643
901.704	43.1903
905.055	42.0741
908.404	43.1354
911.75	41.6208
915.097	43.3862
918.443	44.6954
921.787	45.6406
925.13	47.8199
928.472	48.1814
931.813	47.9564
935.15	47.3731
938.488	44.6426
941.825	40.3296
945.158	34.3096
948.493	28.7242
951.824	26.7671
955.156	23.3335
958.486	18.6919
961.814	16.5331
965.142	16.7232
968.467	18.3474
971.79	21.3902
975.115	22.4612
978.436	23.2499
981.756	23.4433
985.077	24.6524
988.394	24.7638
991.71	25.1448
995.025	26.5675
998.341	26.9525
1001.65	26.4592
1004.97	27.8831
1008.28	31.6205
1011.58	38.7137
1014.89	44.4933
1018.2	52.221
1021.5	56.6734
1024.81	62.4799
1028.11	69.6231
1031.41	77.2629
1034.71	84.1261
1038.01	89.8603
1041.31	94.7827
1044.6	101.317
1047.9	103.523
1051.19	103.895
1054.48	100.147
1057.77	96.1018
1061.06	90.2052
1064.35	83.2517
1067.64	74.9833
1070.93	67.9686
1074.21	57.5336
1077.49	49.7291
1080.78	39.4298
1084.06	33.3388
1087.34	28.9532
1090.61	26.2159
1093.89	27.836
1097.17	27.416
1100.44	28.9988
1103.71	28.4802
1106.99	29.1329
1110.26	29.0991
1113.52	27.2523
1116.79	27.276
1120.06	25.5538
1123.32	22.904
1126.59	22.2876
1129.85	21.4404
1133.11	18.8659
1136.37	16.6645
1139.63	16.4376
1142.89	14.1156
1146.15	14.4083
1149.4	13.518
1152.66	12.7561
1155.91	8.88514
1159.16	5.88841
1162.41	4.01424
1165.66	1.84984
1168.91	2.70193
1172.16	2.60032
1175.4	3.17757
1178.65	2.37533
1181.89	3.31421
1185.13	2.69129
1188.37	3.16978
1191.61	3.17941
1194.85	3.17207
1198.08	2.98196
1201.32	5.47453
1204.55	6.08704
1207.79	10.2105
1211.02	12.9938
1214.25	14.8958
1217.48	17.6649
1220.71	23.0401
1223.93	29.552
1227.16	37.0396
1230.38	41.6908
1233.6	49.7165
1236.83	56.3259
1240.05	63.9114
1243.26	70.5455
1246.48	75.0728
1249.7	79.8031
1252.92	83.0581
1256.13	87.1775
1259.34	90.7904
1262.55	95.877
1265.76	100.372
1268.97	104.056
1272.18	111.048
1275.39	117.372
1278.59	123.682
1281.8	128.282
1285	132.123
1288.2	137.561
1291.4	141.494
1294.6	146.37
1297.8	151.239
1301	154.711
1304.19	156.493
1307.39	159.165
1310.58	160.955
1313.77	160.914
1316.96	159.679
1320.15	157.952
1323.34	155.159
1326.53	151.195
1329.72	146.453
1332.9	139.77
1336.08	135.862
1339.27	132.035
1342.45	128.698
1345.63	125.954
1348.8	125.408
1351.98	123.287
1355.16	123.007
1358.33	121.63
1361.51	121.378
1364.68	121.848
1367.85	122.576
1371.02	125.18
1374.19	127.461
1377.36	129.243
1380.52	131.517
1383.69	134.021
1386.85	139.137
1390.02	143.47
1393.18	147.339
1396.34	151.305
1399.5	156.141
1402.65	162.831
1405.81	170.98
1408.97	178.483
1412.12	188.539
1415.27	199.845
1418.43	213.338
1421.58	226.716
1424.73	241.319
1427.87	259.428
1431.02	272.97
1434.17	288.177
1437.31	296.275
1440.46	304.53
1443.6	308.718
1446.74	310.106
1449.88	309.527
1453.02	305.903
1456.16	297.119
1459.29	286.387
1462.43	273.505
1465.56	259.762
1468.69	241.935
1471.83	220.549
1474.95	202.803
1478.08	181.935
1481.21	163.404
1484.34	145.023
1487.47	127.652
1490.59	114.494
1493.71	101.081
1496.84	90.3978
1499.96	82.9057
1503.07	78.0549
1506.19	71.1826
1509.31	65.1311
1512.43	60.1522
1515.54	55.0043
1518.65	52.4421
1521.77	53.0438
1524.88	53.7899
1527.99	55.5114
1531.1	57.388
1534.21	60.0468
1537.31	63.9395
1540.42	68.8459
1543.52	73.0473
1546.63	74.8434
1549.73	78.5085
1552.83	82.236
1555.93	86.9204
1559.03	90.7099
1562.12	95.9074
1565.22	100.869
1568.31	106.718
1571.41	113.743
1574.5	123.395
1577.59	131.72
1580.68	139.282
1583.77	146.4
1586.86	152.749
1589.95	158.091
1593.03	163.681
1596.11	169.751
1599.2	174.535
1602.28	178.716
1605.36	182.246
1608.44	185.02
1611.52	187.428
1614.6	190.385
1617.67	189.078
1620.75	188.425
1623.82	187.88
1626.89	189.999
1629.96	191.506
1633.04	190.651
1636.11	189.246
1639.17	188.531
1642.24	188.138
1645.31	188.147
1648.37	185.68
1651.43	183.308
1654.5	179.709
1657.56	173.729
1660.62	165.46
1663.67	157.237
1666.73	150.161
1669.79	141.52
1672.84	131.754
1675.9	121.849
1678.95	114.411
1682	104.536
1685.05	93.4447
1688.1	84.855
1691.15	76.4128
1694.2	68.7095
1697.25	63.7786
1700.29	60.0781
1703.33	55.735
1706.38	51.1455
1709.42	47.1528
1712.46	44.1886
1715.5	39.2572
1718.54	36.1061
1721.57	33.3162
1724.61	32.3677
1727.64	29.1581
1730.68	28.3876
1733.71	26.2825
1736.74	25.1238
1739.77	24.8547
1742.8	22.6432
1745.83	20.2984
1748.85	18.1328
1751.88	15.9685
1754.91	14.4302
1757.93	13.4585
1760.95	11.3117
1763.97	10.8218
1766.99	9.0636
1770.01	8.76977
1773.03	8.02591
1776.04	6.72921
1779.06	6.66235
1782.07	4.86056
1785.09	2.79619
1788.1	1.9267
1791.11	1.46841
1794.12	1.4673
1797.13	0.428385
1800.13	1.267
1803.14	0.368097
1806.15	1.51191
1809.15	1.28944
1812.15	1.43775
1815.16	0.340831
1818.15	1.00581
1821.16	0.69653
1824.15	1.15643
1827.15	2.00481
1830.15	1.52676
1833.14	0.132211
1836.14	-0.881907
1839.13	-0.290177
1842.12	0.941916
1845.11	1.84176
1848.1	2.2962
1851.09	1.40807
1854.08	2.16604
1857.06	1.69793
1860.05	3.4757
1863.03	3.70427
1866.01	4.23031
1869	5.73891
1871.98	6.69589
1874.96	8.06679
1877.93	8.47236
1880.91	9.58554
1882.47	9.5822
1885.46	8.75265
1888.44	9.45253
1891.43	8.8461
1894.42	7.94365
1897.4	8.19712
1900.39	8.81273
1903.37	8.88127
1906.35	9.42121
1909.33	11.3355
1912.31	11.5456
1915.29	12.3408
1918.26	11.9857
1921.24	12.7865
1924.21	11.67
1927.19	12.4014
1930.16	11.6282
1933.13	10.5591
1936.1	9.88625
1939.07	9.04881
1942.04	10.0196
1945	9.52183
1947.97	10.2876
1950.93	9.67019
1953.9	9.09534
1956.86	6.21037
1959.82	6.59434
1962.78	4.77127
1965.74	4.22265
1968.7	4.76423
1971.65	4.73556
1974.61	4.45211
1977.57	5.29172
1980.52	4.82509
1983.47	6.26929
1986.42	7.02374
1989.37	6.49636
1992.32	7.73748
1995.27	8.27144
1998.22	6.57986
2001.17	6.7291
2004.11	6.01364
2007.05	7.87941
2010	10.046
2012.94	10.96
2015.88	12.3289
2018.82	14.3039
2021.76	16.0673
2024.7	16.4514
2027.63	17.2029
2030.57	17.5246
2033.5	19.4684
2036.44	19.5856
2039.37	19.7603
2042.3	19.4339
2045.23	20.2771
2048.16	20.8409
2051.08	21.0363
2054.01	20.3291
2056.94	21.2328
2059.86	23.0928
2062.79	23.7756
2065.71	25.1275
2068.63	27.0584
2071.55	27.7213
2074.47	29.4626
2077.39	30.8737
2080.31	34.1734
2083.22	36.1105
2086.13	37.6478
2089.05	38.9944
2091.96	42.3102
2094.87	44.3634
2097.78	46.2078
2100.69	47.9724
2103.6	50.1357
2106.51	52.6191
2109.42	53.5897
2112.32	55.9236
2115.23	59.3239
2118.13	61.5388
2121.03	63.789
2123.93	67.0444
2126.83	71.0829
2129.73	76.2399
2132.63	81.1472
2135.53	85.4219
2138.42	90.847
2141.32	95.9796
2144.21	101.525
2147.1	108.25
2150	112.948
2152.89	116.619
2155.78	119.374
2158.66	122.585
2161.55	125.346
2164.44	128.495
2167.32	130.573
2170.21	131.362
2173.09	131.339
2175.97	130.955
2178.85	127.984
2181.73	126.613
2184.61	124.357
2187.49	120.597
2190.37	115.817
2193.24	112.449
2196.12	108.589
2198.99	106.092
2201.87	100.805
2204.74	98.3335
2207.61	93.5278
2210.48	90.0495
2213.35	86.569
2216.21	82.5394
2219.08	77.1903
2221.95	74.0893
2224.81	69.426
2227.67	66.3387
2230.54	62.3315
2233.4	58.9794
2236.26	56.6141
2239.11	53.6774
2241.97	49.5444
2244.83	46.6699
2247.69	42.8309
2250.54	40.5693
2253.4	39.1055
2256.25	37.2212
2259.1	33.5026
2261.95	31.7918
2264.8	33.1641
2267.65	32.6425
2270.5	30.946
2273.34	29.3158
2276.19	28.0521
2279.03	26.0717
2281.88	24.7887
2284.72	23.6512
2287.56	21.7674
2290.4	20.2661
2293.24	18.5273
2296.08	16.9996
2298.92	15.7328
2301.76	15.8158
2304.59	14.5095
2307.43	14.2315
2310.26	13.1479
2313.09	11.9095
2315.92	12.2522
2318.75	12.4222
2321.58	14.055
2324.41	11.0945
2327.24	9.20664
2330.06	9.2397
2332.89	10.9778
2335.71	11.0824
2338.54	10.1276
2341.36	10.7011
2344.18	8.53046
2347	7.84021
2349.82	7.02298
2352.64	6.75481
2355.45	6.14774
2358.27	3.26214
2361.08	3.61374
2363.9	3.38084
2366.71	4.51724
2369.52	5.16925
2372.33	5.22772
2375.14	6.92071
2377.95	7.58206
2380.76	8.56653
2383.57	9.35487
2386.37	9.74088
2389.18	10.5736
2391.98	10.1249
2394.79	8.60868
2397.59	8.94291
2400.39	9.35576
2403.19	8.51125
2405.99	7.42211
2408.78	6.79317
2411.58	5.56982
2414.38	4.16609
2417.17	3.59377
2419.97	4.1929
2422.76	2.96646
2425.55	1.65516
2428.34	0.946517
2431.13	1.56938
2433.92	1.8938
2436.71	2.84664
2439.49	3.54304
2442.28	3.03686
2445.06	3.44803
2447.85	4.02637
2450.63	3.97872
2453.41	4.35854
2456.19	4.96117
2458.97	6.50695
2461.75	5.36689
2464.53	5.88313
2467.31	6.8938
2470.08	7.24232
2472.86	6.48624
2475.63	6.71736
2478.4	6.43606
2481.17	6.03024
2483.94	6.25484
2486.72	6.444
2489.48	7.32259
2492.25	7.02523
2495.02	6.19333
2497.79	4.87052
2500.55	4.28251
2503.31	2.55888
2506.08	2.5328
2508.84	2.11743
2511.6	1.62913
2514.36	1.10311
2517.12	1.60538
2519.88	1.10514
2522.63	2.33962
2525.39	3.00673
2528.14	1.52127
2530.9	1.45449
2533.65	2.34234
2536.4	2.97661
2539.15	2.53651
2541.9	2.48189
2544.65	2.74118
2547.4	2.889
2550.15	2.2718
2552.89	1.94545
2555.64	3.20707
2558.38	3.04966
2561.12	2.87814
2563.87	3.26484
2566.61	4.51647
2569.35	5.41421
2572.09	7.95109
2574.83	9.30907
2577.56	10.1943
2580.3	11.1868
2583.04	11.9712
2585.77	14.6282
2588.5	14.2833
2591.23	14.5793
2593.97	14.3582
2596.7	14.4067
2599.43	14.455
2602.15	14.7717
2604.88	13.1727
2607.61	11.5113
2610.33	9.89053
2613.06	6.85127
2615.78	5.06916
2618.51	2.95092
2621.23	2.61477
2623.95	2.10497
2626.67	1.74952
2629.39	2.61968
2632.1	2.32014
2634.82	3.45252
2637.54	2.48843
2640.25	3.71291
2642.97	4.2302
2645.68	5.68043
2648.39	7.52191
2651.1	9.88682
2653.81	10.4486
2656.52	11.1967
2659.23	11.8979
2661.94	10.7808
2664.64	10.8206
2667.35	9.36764
2670.05	9.75948
2672.76	9.88442
2675.46	9.95072
2678.16	8.57191
2680.86	8.0413
2683.56	8.33179
2686.26	10.4756
2688.96	10.8161
2691.65	11.7201
2694.35	13.1023
2697.04	15.7121
2699.74	17.6515
2702.43	19.5085
2705.12	21.2846
2707.81	24.0754
2710.5	26.685
2713.19	29.2611
2715.88	31.5812
2718.57	31.7298
2721.25	32.2541
2723.94	32.1503
2726.62	30.62
2729.3	29.6943
2731.99	29.0739
2734.67	27.1363
2737.35	24.7921
2740.03	20.6804
2742.71	17.732
2745.38	14.4391
2748.06	12.3476
2750.74	11.6703
2753.41	9.56427
2756.09	8.09109
2758.76	5.85912
2761.43	4.37556
2764.1	4.18929
2766.77	3.87059
2769.44	2.19251
2772.11	2.5885
2774.77	1.92263
2777.44	1.86693
2780.11	1.86505
2782.77	2.03305
2785.43	2.89306
2788.1	2.31699
2790.76	1.02839
2793.42	1.7066
2796.08	0.917392
2798.74	0.324219
2801.4	-0.789291
2804.05	-1.35045
2806.71	-2.67601
2809.36	-2.56953
2812.02	-1.75854
2814.67	-0.16582
2817.32	5.03662
2819.97	14.0537
2822.62	24.9369
2825.27	39.1384
2827.92	56.154
2830.57	74.7831
2833.22	96.2668
2835.86	120.886
2838.51	144.735
2841.15	169.202
2843.79	192.993
2846.43	218.048
2849.08	245.722
2851.72	273.522
2854.36	302.231
2856.99	330.919
2859.63	359.285
2862.27	383.131
2864.9	404.152
2867.54	425.261
2870.17	443.287
2872.8	458.017
2875.43	471.723
2878.07	486.214
2880.7	502.688
2883.32	519.529
2885.95	535.412
2888.58	549.895
2891.21	564.93
2893.83	580.935
2896.46	597.022
2899.08	615.385
2901.7	630.034
2904.32	647.886
2906.94	668.804
2909.56	691.086
2912.18	716.437
2914.8	741.676
2917.42	765.346
2920.03	785.291
2922.65	799.929
2925.26	810.401
2927.88	813.531
2930.49	812.55
2933.1	804.637
2935.71	790.753
2938.32	772.564
2940.93	748.53
2943.54	720.737
2946.14	690.008
2948.75	655.047
2951.35	619.269
2953.96	582.439
2956.56	547.936
2959.16	514.327
2961.77	481.098
2964.37	451.426
2966.96	423.803
2969.56	400.075
2972.16	377.571
2974.76	357.799
2977.35	336.441
2979.95	315.725
2982.54	295.381
2985.14	275.493
2987.73	255.208
2990.32	235.067
2992.91	213.2
2995.5	191.464
2998.09	170.238
3000.68	149.292
3003.26	127.673
3005.85	108.37
3008.43	89.6287
3011.02	72.1924
3013.6	58.2054
3016.19	47.1389
3018.77	35.666
3021.35	27.0112
3023.93	17.8842
3026.5	11.6757
3029.08	6.65997
3031.66	3.26953
3034.24	-0.249981
3036.81	-0.579629
3039.39	-0.553111
3041.96	-0.234131
3044.53	0.98415
3047.1	2.52588
3049.67	5.50651
3052.24	6.83171
3054.81	8.76871
3057.38	8.86501
3059.95	9.59275
3062.52	10.0067
3065.08	9.48475
3067.65	8.97613
3070.21	9.20242
3072.77	8.24422
3075.33	6.94209
3077.89	6.95657
3080.45	4.73876
3083.01	2.59532
3085.57	2.07888
3088.13	2.23954
3090.68	1.83896
3093.24	1.28363
3095.79	0.936109
3098.35	1.14249
3100.9	3.93398
3103.45	6.52525
3106	8.35715
3108.55	10.279
3111.1	13.264
3113.65	16.4157
3116.2	19.9496
3118.75	22.014
3121.29	25.4561
3123.84	28.9733
3126.38	32.5742
3128.92	36.8146
3131.47	39.817
3134.01	43.3346
3136.55	48.2458
3139.09	52.8412
3141.63	57.3451
3144.17	61.9597
3146.7	66.6736
3149.24	71.0685