File: data/Raman/poly_smoothed/Mb_40_24_24_1x_45s_532 nm_x100_100%_600 gr_mm_01.txt
#Acq. time (s)=	45
#Accumulations=	2
#Range (cm-¹)=	200...3150
#Windows=	2
#Auto scanning=	Off
#Autofocus=	Off
#Macrospot=	Off
#AutoExposure=	Off
#Spike filter=	Multiple accum.
#Delay time (s)=	0
#Binning=	1
#Readout mode=	Signal
#DeNoise=	Off
#ICS correction=	On
#Dark correction=	Off
#Inst. Process=	Off
#Detector Gain=	Best Dynamic Range
#Detector ADC=	20 kHz
#Detector temperature (°C)=	-70.08
#Instrument=	LabRAM HR Evol
#Detector=	Synapse
#Objective=	x100
#Grating=	600 gr/mm
#ND Filter=	100%
#Laser (nm)=	532
#Hole=	100.021
#Range=	Auto
#Laser Pol.=	No
#Raman. Pol.=	No
#Laser Pol. (°)=	-0.0007625
#Raman Pol. (°)=	89.9995
#Collection=	Microscope
#StageXY=	Marzhauser
#StageZ=	Marzhauser
#X (µm)=	-2531.1
#Y (µm)=	-103.8
#Z (µm)=	-10.65
#Full time(mm:ss)=	3:05
#Project=
#Sample=
#Site=
#Title=	Mb_40_24_24_2x_45s_532 nm_x100_100%_600 gr_mm
#Remark=
#Date=	14.07.2022 12:29
#Acquired=	14.07.2022 12:29:50
#Base:Fit=	10.08.2022 10:47:00
#Base:Sub=	10.08.2022 10:47:12
#Filter:Polynom=	16.08.2022 10:11:48
#AxisType[0]=Intens
#AxisUnit[0]=Cnt
#AxisType[1]=Spectr
#AxisUnit[1]=1/cm
200.554	1.45627
204.183	5.69742
207.813	9.28194
211.439	13.1138
215.065	17.9049
218.688	18.9545
222.312	20.9948
225.933	22.5119
229.552	22.8964
233.171	21.6163
236.787	22.3955
240.402	24.3029
244.015	24.8477
247.627	25.5913
251.24	26.4257
254.849	27.3887
258.457	29.0284
262.063	29.659
265.668	31.9525
269.271	31.9586
272.873	32.4189
276.474	31.8917
280.073	32.1211
283.671	34.0863
287.268	34.4691
290.863	35.4499
294.456	36.01
298.049	34.5818
301.637	35.2657
305.227	32.6884
308.815	29.8078
312.402	28.8645
315.987	25.8579
319.569	22.987
323.151	20.7075
326.733	21.6844
330.31	21.0109
333.889	21.4482
337.464	21.9253
341.039	21.6794
344.611	19.5829
348.184	19.2307
351.754	17.8776
355.324	15.5886
358.89	14.5148
362.455	16.1553
366.021	17.8909
369.584	17.8479
373.145	19.3542
376.707	16.7891
380.265	16.4537
383.822	15.6668
387.378	16.2235
390.934	16.2452
394.487	17.1932
398.038	16.4955
401.588	16.3522
405.137	16.6552
408.685	16.9285
412.23	17.1739
415.775	19.7291
419.318	21.7198
422.86	22.5881
426.401	23.2662
429.94	22.9935
433.478	21.6594
437.012	19.0942
440.547	16.0314
444.081	15.5963
447.613	16.2837
451.142	14.1038
454.672	13.9373
458.2	11.9907
461.725	11.0096
465.251	11.3315
468.775	12.3336
472.296	11.8641
475.817	11.2959
479.335	12.718
482.854	13.3757
486.37	14.9396
489.886	16.7107
493.398	19.2749
496.91	21.2
500.422	24.8691
503.93	27.8337
507.438	29.4044
510.946	31.1676
514.45	34.0512
517.954	35.1291
521.456	35.7692
524.956	35.2858
528.456	35.6291
531.956	36.821
535.452	35.1054
538.947	33.9608
542.441	30.9541
545.934	29.971
549.425	30.1566
552.915	29.9033
556.403	26.3957
559.889	24.3481
563.375	24.363
566.859	22.3672
570.342	21.2792
573.824	19.6643
577.303	17.6141
580.782	14.8656
584.26	14.2086
587.734	12.9279
591.21	12.749
594.684	13.0541
598.154	14.173
601.626	14.2256
605.094	14.643
608.562	12.6765
612.027	11.1457
615.493	9.37151
618.956	9.17396
622.419	8.56283
625.879	7.18796
629.338	6.19379
632.797	7.48448
636.254	8.48507
639.708	7.6576
643.162	7.9141
646.614	7.40221
650.067	6.55523
653.516	6.17188
656.964	4.60373
660.411	4.05901
663.857	4.23884
667.301	2.82521
670.744	4.29366
674.186	3.04918
677.626	3.82211
681.065	3.98117
684.503	5.41318
687.939	5.33674
691.372	4.32514
694.806	4.2853
698.239	4.73803
701.67	4.81817
705.098	6.14779
708.526	5.67157
711.954	7.22207
715.378	9.98054
718.802	10.6476
722.226	11.3283
725.646	11.1208
729.067	12.6224
732.484	13.0194
735.902	13.9218
739.317	15.4556
742.731	19.3557
746.145	22.9638
749.556	24.5592
752.966	27.752
756.377	32.0073
759.784	36.3079
763.19	40.8055
766.594	44.7628
770	46.4783
773.402	47.4389
776.803	50.9208
780.202	53.4806
783.6	56.5396
786.997	58.3534
790.393	60.55
793.787	60.8407
797.18	61.2681
800.572	60.7401
803.963	60.0536
807.35	58.1115
810.738	55.1314
814.125	53.8888
817.51	53.587
820.894	56.501
824.275	57.55
827.657	59.6385
831.037	60.8463
834.414	62.7772
837.792	65.0031
841.167	65.8575
844.542	65.8703
847.914	66.1419
851.287	66.6433
854.656	66.6134
858.026	67.5634
861.393	68.5246
864.761	68.0476
868.125	67.9468
871.489	66.7443
874.85	64.1942
878.213	61.9723
881.572	58.2174
884.931	54.8675
888.287	50.6803
891.643	45.92
894.997	45.2924
898.352	45.4877
901.704	47.3591
905.055	45.6418
908.404	43.3613
911.75	44.958
915.097	44.425
918.443	41.6607
921.787	39.9461
925.13	40.3918
928.472	41.2044
931.813	42.0851
935.15	42.6073
938.488	42.292
941.825	41.9285
945.158	41.786
948.493	39.3501
951.824	37.4416
955.156	34.6846
958.486	30.4027
961.814	28.4452
965.142	28.3304
968.467	30.2471
971.79	32.7972
975.115	35.1285
978.436	35.5027
981.756	36.2675
985.077	35.3426
988.394	32.3047
991.71	29.8657
995.025	28.7745
998.341	25.4763
1001.65	24.1846
1004.97	24.1514
1008.28	26.8909
1011.58	28.8163
1014.89	33.1971
1018.2	36.3819
1021.5	40.5128
1024.81	42.0569
1028.11	46.3746
1031.41	51.3179
1034.71	56.4596
1038.01	58.9143
1041.31	62.5973
1044.6	67.8456
1047.9	72.1157
1051.19	72.7307
1054.48	71.7952
1057.77	70.8495
1061.06	67.986
1064.35	63.8912
1067.64	58.1328
1070.93	52.8415
1074.21	47.3025
1077.49	43.3887
1080.78	38.1496
1084.06	33.3015
1087.34	29.6458
1090.61	30.0439
1093.89	31.3188
1097.17	33.711
1100.44	34.9432
1103.71	36.7675
1106.99	39.6063
1110.26	40.0578
1113.52	41.2048
1116.79	40.4505
1120.06	38.711
1123.32	36.8014
1126.59	35.432
1129.85	34.6662
1133.11	31.9028
1136.37	31.8583
1139.63	28.1726
1142.89	21.5854
1146.15	19.5864
1149.4	17.1684
1152.66	13.7616
1155.91	10.3772
1159.16	7.10397
1162.41	3.9683
1165.66	2.52296
1168.91	2.60183
1172.16	3.17244
1175.4	5.56178
1178.65	8.51023
1181.89	9.26995
1185.13	10.8253
1188.37	11.8194
1191.61	13.8219
1194.85	16.0728
1198.08	16.8321
1201.32	17.6819
1204.55	19.6548
1207.79	20.4729
1211.02	23.015
1214.25	25.3957
1217.48	26.0634
1220.71	27.3177
1223.93	30.5735
1227.16	33.2424
1230.38	36.632
1233.6	39.5033
1236.83	41.0913
1240.05	43.2731
1243.26	45.7913
1246.48	48.59
1249.7	51.3048
1252.92	52.0767
1256.13	53.3498
1259.34	56.4092
1262.55	60.2861
1265.76	65.1785
1268.97	69.6498
1272.18	74.8262
1275.39	77.3727
1278.59	81.2364
1281.8	83.9648
1285	89.5068
1288.2	93.0067
1291.4	97.9219
1294.6	100.42
1297.8	102.938
1301	105.235
1304.19	107.269
1307.39	108.072
1310.58	105.91
1313.77	105.207
1316.96	103.162
1320.15	102.354
1323.34	100.156
1326.53	95.7762
1329.72	92.2291
1332.9	89.1308
1336.08	89.1562
1339.27	88.4185
1342.45	87.7852
1345.63	87.6557
1348.8	85.3041
1351.98	84.358
1355.16	84.5849
1358.33	83.4532
1361.51	83.3515
1364.68	82.0607
1367.85	82.9282
1371.02	81.5394
1374.19	82.747
1377.36	82.1061
1380.52	82.8421
1383.69	82.9601
1386.85	84.6682
1390.02	86.2987
1393.18	89.2916
1396.34	93.0998
1399.5	95.8165
1402.65	102.878
1405.81	108.853
1408.97	116.189
1412.12	125.979
1415.27	137.003
1418.43	146.824
1421.58	156.28
1424.73	168.184
1427.87	178.763
1431.02	188.124
1434.17	195.44
1437.31	201.462
1440.46	205.271
1443.6	207.433
1446.74	207.719
1449.88	204.907
1453.02	199.676
1456.16	191.673
1459.29	184.106
1462.43	172.017
1465.56	162.035
1468.69	149.324
1471.83	135.886
1474.95	123.644
1478.08	110.646
1481.21	99.0679
1484.34	87.0176
1487.47	78.4181
1490.59	70.3104
1493.71	63.6597
1496.84	56.2728
1499.96	50.9805
1503.07	47.6875
1506.19	44.3114
1509.31	42.4599
1512.43	41.449
1515.54	39.9011
1518.65	38.6234
1521.77	38.515
1524.88	37.414
1527.99	38.0337
1531.1	39.9209
1534.21	41.3846
1537.31	43.4748
1540.42	46.3236
1543.52	49.6198
1546.63	50.4438
1549.73	51.8775
1552.83	53.497
1555.93	54.4251
1559.03	55.0637
1562.12	59.5792
1565.22	63.5623
1568.31	64.8214
1571.41	69.1499
1574.5	71.4957
1577.59	75.7103
1580.68	80.5625
1583.77	86.1733
1586.86	89.2769
1589.95	90.7656
1593.03	92.7224
1596.11	93.8895
1599.2	95.2605
1602.28	95.9102
1605.36	97.0976
1608.44	97.4706
1611.52	98.4521
1614.6	100.192
1617.67	99.6881
1620.75	97.6244
1623.82	96.957
1626.89	96.1341
1629.96	94.9158
1633.04	93.7458
1636.11	94.1661
1639.17	94.7071
1642.24	94.1993
1645.31	94.8046
1648.37	93.9821
1651.43	93.0548
1654.5	91.6713
1657.56	89.012
1660.62	86.9421
1663.67	80.9574
1666.73	75.3008
1669.79	71.1619
1672.84	68.1895
1675.9	63.5694
1678.95	60.5578
1682	56.0408
1685.05	51.0472
1688.1	47.2595
1691.15	43.0632
1694.2	39.3728
1697.25	37.2406
1700.29	34.0714
1703.33	30.9173
1706.38	28.4324
1709.42	27.7776
1712.46	27.1498
1715.5	26.47
1718.54	25.3825
1721.57	25.6633
1724.61	24.0445
1727.64	24.0806
1730.68	22.6523
1733.71	21.955
1736.74	20.6275
1739.77	19.4132
1742.8	18.9028
1745.83	19.2793
1748.85	17.6326
1751.88	15.9908
1754.91	13.8426
1757.93	10.4085
1760.95	8.38804
1763.97	7.6369
1766.99	5.96772
1770.01	5.72843
1773.03	4.67557
1776.04	4.47507
1779.06	3.07871
1782.07	2.89764
1785.09	3.82767
1788.1	3.73103
1791.11	3.63511
1794.12	3.4675
1797.13	3.42907
1800.13	4.24522
1803.14	4.08598
1806.15	3.37834
1809.15	3.52789
1812.15	2.43202
1815.16	1.80766
1818.15	1.63149
1821.16	1.11415
1824.15	0.688184
1827.15	1.05318
1830.15	0.795794
1833.14	0.482966
1836.14	-0.277674
1839.13	1.02021
1842.12	1.74069
1845.11	1.20601
1848.1	1.28441
1851.09	2.23288
1854.08	2.32349
1857.06	4.18724
1860.05	5.02874
1863.03	3.99416
1866.01	3.38389
1869	4.34758
1871.98	4.87649
1874.96	5.31572
1877.93	5.0538
1880.91	3.92151
1882.47	5.53885
1885.46	5.53919
1888.44	6.24087
1891.43	6.0059
1894.42	7.53307
1897.4	8.06106
1900.39	8.13117
1903.37	7.86035
1906.35	7.56062
1909.33	6.80149
1912.31	7.11213
1915.29	5.56832
1918.26	4.68883
1921.24	4.74416
1924.21	4.74129
1927.19	3.45237
1930.16	3.59824
1933.13	2.75392
1936.1	2.27672
1939.07	4.16563
1942.04	3.79223
1945	5.62127
1947.97	6.64284
1950.93	7.22477
1953.9	9.8775
1956.86	10.512
1959.82	10.1983
1962.78	9.04473
1965.74	11.083
1968.7	11.2455
1971.65	11.3207
1974.61	10.3813
1977.57	10.1821
1980.52	9.63247
1983.47	9.22717
1986.42	8.76683
1989.37	7.66245
1992.32	6.03024
1995.27	5.40563
1998.22	4.8184
2001.17	3.87657
2004.11	3.7966
2007.05	3.19275
2010	3.44769
2012.94	3.63544
2015.88	5.19139
2018.82	7.34151
2021.76	7.91961
2024.7	8.88121
2027.63	9.26304
2030.57	9.78514
2033.5	11.3606
2036.44	10.917
2039.37	11.7124
2042.3	11.9411
2045.23	11.9671
2048.16	13.0356
2051.08	13.9847
2054.01	14.7734
2056.94	14.5656
2059.86	13.6517
2062.79	13.3839
2065.71	14.3585
2068.63	15.3575
2071.55	15.2515
2074.47	14.3203
2077.39	13.5414
2080.31	14.2493
2083.22	16.9542
2086.13	19.3886
2089.05	20.0178
2091.96	21.2803
2094.87	22.9005
2097.78	25.1145
2100.69	25.853
2103.6	27.942
2106.51	28.4038
2109.42	29.7087
2112.32	32.5922
2115.23	34.0471
2118.13	35.3757
2121.03	39.0083
2123.93	41.8044
2126.83	44.5126
2129.73	46.7256
2132.63	48.8789
2135.53	52.5842
2138.42	54.278
2141.32	56.667
2144.21	58.6135
2147.1	61.4681
2150	64.1139
2152.89	67.5497
2155.78	70.7631
2158.66	71.8962
2161.55	72.9055
2164.44	75.4568
2167.32	75.6587
2170.21	75.9314
2173.09	75.6162
2175.97	75.5387
2178.85	74.884
2181.73	74.3589
2184.61	72.3667
2187.49	69.1713
2190.37	66.1514
2193.24	63.3393
2196.12	60.1009
2198.99	57.8943
2201.87	53.7843
2204.74	50.6779
2207.61	49.1514
2210.48	47.7146
2213.35	47.5013
2216.21	45.2104
2219.08	43.9267
2221.95	42.6552
2224.81	40.5975
2227.67	39.2969
2230.54	37.6531
2233.4	36.9846
2236.26	35.1958
2239.11	32.6247
2241.97	30.486
2244.83	27.2861
2247.69	24.891
2250.54	23.2456
2253.4	21.2528
2256.25	18.6733
2259.1	16.1806
2261.95	14.6765
2264.8	12.2781
2267.65	11.6702
2270.5	11.4553
2273.34	10.1493
2276.19	10.5147
2279.03	12.4573
2281.88	12.13
2284.72	12.5337
2287.56	11.3722
2290.4	11.81
2293.24	9.79948
2296.08	9.09795
2298.92	8.99769
2301.76	9.73871
2304.59	9.24537
2307.43	8.50256
2310.26	7.50961
2313.09	6.06258
2315.92	7.25426
2318.75	8.67835
2321.58	8.44976
2324.41	8.4555
2327.24	7.56333
2330.06	6.79321
2332.89	6.47289
2335.71	6.30886
2338.54	6.78383
2341.36	6.07496
2344.18	5.86823
2347	6.39828
2349.82	7.17905
2352.64	6.57515
2355.45	5.61971
2358.27	4.51521
2361.08	2.97442
2363.9	2.37508
2366.71	2.82773
2369.52	2.75781
2372.33	2.92844
2375.14	1.96797
2377.95	2.723
2380.76	1.98951
2383.57	1.71092
2386.37	1.8419
2389.18	3.15878
2391.98	2.26883
2394.79	2.27757
2397.59	2.26036
2400.39	3.72943
2403.19	3.56823
2405.99	3.23007
2408.78	4.1043
2411.58	3.8761
2414.38	4.58442
2417.17	5.464
2419.97	5.29451
2422.76	5.06993
2425.55	4.74726
2428.34	4.39686
2431.13	4.2444
2433.92	4.90696
2436.71	5.54828
2439.49	6.01058
2442.28	5.68817
2445.06	5.10431
2447.85	5.48927
2450.63	4.31715
2453.41	5.25062
2456.19	4.33332
2458.97	3.28665
2461.75	2.2893
2464.53	3.02146
2467.31	2.62762
2470.08	2.62468
2472.86	1.5587
2475.63	1.44718
2478.4	1.01733
2481.17	-0.11617
2483.94	0.757309
2486.72	0.824975
2489.48	1.03553
2492.25	1.09348
2495.02	0.457272
2497.79	0.962812
2500.55	1.42132
2503.31	2.23983
2506.08	1.88931
2508.84	1.89114
2511.6	2.72999
2514.36	2.39789
2517.12	0.756996
2519.88	0.949056
2522.63	-0.133344
2525.39	0.635405
2528.14	0.676592
2530.9	1.10587
2533.65	2.49089
2536.4	2.51209
2539.15	3.37896
2541.9	3.31033
2544.65	3.98749
2547.4	4.23148
2550.15	6.10474
2552.89	6.78832
2555.64	7.20262
2558.38	7.8233
2561.12	6.99805
2563.87	6.38108
2566.61	6.14858
2569.35	6.34137
2572.09	5.86558
2574.83	4.66335
2577.56	3.56823
2580.3	3.35139
2583.04	2.69499
2585.77	1.6644
2588.5	0.263924
2591.23	0.838327
2593.97	1.01748
2596.7	0.413832
2599.43	0.108692
2602.15	0.773505
2604.88	0.778434
2607.61	1.31497
2610.33	1.34295
2613.06	1.67007
2615.78	1.5936
2618.51	2.32224
2621.23	2.30249
2623.95	3.06347
2626.67	3.77539
2629.39	2.94764
2632.1	3.47393
2634.82	5.41182
2637.54	5.4194
2640.25	5.06282
2642.97	5.16616
2645.68	6.33025
2648.39	6.65939
2651.1	5.73869
2653.81	5.13083
2656.52	5.19854
2659.23	5.63875
2661.94	5.06377
2664.64	5.44223
2667.35	6.50164
2670.05	7.09248
2672.76	8.08868
2675.46	7.23273
2678.16	6.73809
2680.86	7.12673
2683.56	7.28554
2686.26	8.26383
2688.96	9.94672
2691.65	11.7357
2694.35	12.2521
2697.04	13.8835
2699.74	15.3925
2702.43	17.2849
2705.12	18.3518
2707.81	17.8776
2710.5	20.109
2713.19	20.2255
2715.88	20.8166
2718.57	21.1057
2721.25	20.6642
2723.94	20.9719
2726.62	20.7826
2729.3	21.2399
2731.99	20.9792
2734.67	20.0885
2737.35	18.5293
2740.03	16.5168
2742.71	14.8565
2745.38	12.8367
2748.06	11.9399
2750.74	9.94507
2753.41	8.6965
2756.09	8.30817
2758.76	6.93916
2761.43	5.50052
2764.1	3.84442
2766.77	3.04735
2769.44	2.39372
2772.11	1.49668
2774.77	2.39001
2777.44	2.21602
2780.11	1.26855
2782.77	1.34122
2785.43	2.19721
2788.1	2.24157
2790.76	2.5046
2793.42	3.3869
2796.08	3.21273
2798.74	3.43286
2801.4	3.7941
2804.05	3.26273
2806.71	2.75867
2809.36	2.22601
2812.02	1.46424
2814.67	3.42475
2817.32	7.97768
2819.97	17.576
2822.62	28.3153
2825.27	41.8076
2827.92	57.1469
2830.57	74.5694
2833.22	93.7125
2835.86	112.665
2838.51	133.207
2841.15	152.71
2843.79	169.976
2846.43	186.974
2849.08	205.755
2851.72	224.356
2854.36	246.569
2856.99	267.047
2859.63	285.447
2862.27	302.08
2864.9	315.05
2867.54	325.689
2870.17	333.419
2872.8	339.369
2875.43	345.062
2878.07	350.651
2880.7	357.893
2883.32	364.534
2885.95	370.991
2888.58	377.692
2891.21	382.137
2893.83	388.659
2896.46	390.308
2899.08	392.477
2901.7	394.941
2904.32	397.95
2906.94	401.882
2909.56	408.528
2912.18	418.491
2914.8	431.515
2917.42	444.401
2920.03	456.566
2922.65	463.445
2925.26	466.952
2927.88	468.71
2930.49	465.576
2933.1	461.079
2935.71	451.563
2938.32	439.912
2940.93	426.604
2943.54	411.162
2946.14	393.166
2948.75	373.181
2951.35	352.756
2953.96	330.171
2956.56	308.275
2959.16	286.997
2961.77	264.601
2964.37	245.813
2966.96	230.603
2969.56	215.598
2972.16	203.554
2974.76	192.321
2977.35	181.649
2979.95	170.279
2982.54	157.499
2985.14	145.641
2987.73	133.463
2990.32	120.602
2992.91	107.881
2995.5	96.3731
2998.09	85.2657
3000.68	74.5902
3003.26	64.187
3005.85	56.3794
3008.43	45.8207
3011.02	38.0918
3013.6	31.0478
3016.19	23.4666
3018.77	17.3736
3021.35	12.6049
3023.93	9.55715
3026.5	6.25848
3029.08	4.57788
3031.66	3.28053
3034.24	2.66519
3036.81	2.30256
3039.39	2.47163
3041.96	1.55212
3044.53	2.55918
3047.1	3.4249
3049.67	4.85478
3052.24	4.88573
3054.81	4.74071
3057.38	6.35147
3059.95	7.15797
3062.52	7.6922
3065.08	7.73035
3067.65	7.81775
3070.21	7.55866
3072.77	7.20071
3075.33	6.44105
3077.89	5.045
3080.45	3.92183
3083.01	3.4002
3085.57	2.48614
3088.13	1.08249
3090.68	0.255636
3093.24	-0.607662
3095.79	-1.40587
3098.35	-0.494172
3100.9	-0.251469
3103.45	0.933303
3106	0.744252
3108.55	2.0172
3111.1	2.76816
3113.65	4.07439
3116.2	6.12671
3118.75	8.02983
3121.29	10.1248
3123.84	12.4876
3126.38	14.5056
3128.92	17.2829
3131.47	20.5158
3134.01	23.8149
3136.55	26.9108
3139.09	30.4668
3141.63	34.1413
3144.17	37.5901
3146.7	40.7847
3149.24	44.2921