File: data/Raman/poly_smoothed/Mb_40_y_11_1x_45s_532 nm_x100_100%_600 gr_mm_01.txt
#Acq. time (s)=	45
#Accumulations=	2
#Range (cm-¹)=	200...3150
#Windows=	2
#Auto scanning=	Off
#Autofocus=	Off
#Macrospot=	Off
#AutoExposure=	Off
#Spike filter=	Multiple accum.
#Delay time (s)=	0
#Binning=	1
#Readout mode=	Signal
#DeNoise=	Off
#ICS correction=	On
#Dark correction=	Off
#Inst. Process=	Off
#Detector Gain=	Best Dynamic Range
#Detector ADC=	20 kHz
#Detector temperature (°C)=	-69.85
#Instrument=	LabRAM HR Evol
#Detector=	Synapse
#Objective=	x100
#Grating=	600 gr/mm
#ND Filter=	100%
#Laser (nm)=	532
#Hole=	100.021
#Range=	Auto
#Laser Pol.=	No
#Raman. Pol.=	No
#Laser Pol. (°)=	-0.0007625
#Raman Pol. (°)=	89.9995
#Collection=	Microscope
#StageXY=	Marzhauser
#StageZ=	Marzhauser
#X (µm)=	-1022.8
#Y (µm)=	687.7
#Z (µm)=	584.55
#Full time(mm:ss)=	3:19
#Project=
#Sample=
#Site=
#Title=	Mb_40_y_11_2x_45s_532 nm_x100_100%_600 gr_mm
#Remark=
#Date=	19.07.2022 09:41
#Acquired=	19.07.2022 09:41:46
#Base:Fit=	10.08.2022 10:52:48
#Base:Sub=	10.08.2022 10:52:53
#Filter:Polynom=	16.08.2022 10:09:04
#AxisType[0]=Intens
#AxisUnit[0]=Cnt
#AxisType[1]=Spectr
#AxisUnit[1]=1/cm
200.423	34.2959
204.052	26.1957
207.682	20.2425
211.308	16.0041
214.935	12.5317
218.558	9.21719
222.18	6.29877
225.802	4.94934
229.421	3.16714
233.039	2.11916
236.657	3.1906
240.272	1.46277
243.885	2.74114
247.497	3.37332
251.11	4.99048
254.719	6.88509
258.327	6.81571
261.933	8.73466
265.538	8.91211
269.141	10.7025
272.744	10.7978
276.344	11.2764
279.944	11.3443
283.542	12.3441
287.138	12.7387
290.733	13.2076
294.327	12.3967
297.919	11.4765
301.508	10.942
305.098	10.2779
308.686	9.74497
312.273	9.97106
315.858	11.2619
319.44	11.2687
323.022	11.9586
326.604	12.5762
330.181	11.8648
333.76	11.7677
337.335	10.6789
340.91	12.2657
344.483	12.5944
348.055	11.5526
351.625	10.9165
355.195	10.2639
358.762	9.92361
362.329	8.90485
365.893	9.64096
369.455	9.7115
373.017	9.95152
376.578	10.5547
380.137	9.10979
383.694	9.87607
387.249	8.47907
390.806	8.70321
394.359	7.70813
397.91	8.17239
401.46	8.29421
405.009	9.43947
408.557	9.33896
412.103	8.28134
415.647	8.73135
419.191	8.68645
422.733	8.48691
426.273	9.89868
429.812	9.97844
433.35	8.4256
436.885	8.09914
440.42	7.67395
443.954	7.35713
447.486	6.88697
451.015	7.25654
454.545	7.62536
458.073	7.79551
461.598	8.44358
465.124	7.80456
468.648	7.18628
472.169	7.5277
475.69	7.34489
479.208	7.92102
482.727	9.81405
486.243	13.0139
489.759	12.6263
493.272	12.4625
496.783	13.2304
500.295	14.7057
503.804	17.1649
507.311	17.0574
510.819	16.1407
514.324	16.4104
517.827	18.5934
521.329	17.6547
524.83	17.2896
528.329	16.2276
531.829	14.9377
535.326	14.2373
538.821	13.4512
542.315	11.641
545.808	12.3089
549.299	11.3876
552.789	9.12401
556.278	9.01157
559.763	8.05479
563.249	9.24225
566.733	8.94101
570.217	8.57831
573.699	6.63896
577.177	5.25663
580.656	5.26546
584.134	5.89179
587.609	4.74925
591.084	3.15023
594.558	2.46097
598.029	2.75623
601.5	3.12265
604.968	4.09122
608.437	5.44729
611.902	5.32057
615.368	6.33139
618.831	5.99293
622.294	5.22935
625.755	5.23997
629.213	5.71782
632.673	6.76201
636.129	7.2518
639.584	8.37493
643.037	8.96462
646.491	10.3503
649.942	10.9754
653.392	12.1601
656.84	12.6231
660.287	14.4657
663.732	14.0882
667.177	13.6053
670.62	13.7514
674.061	14.088
677.502	16.7445
680.941	18.3841
684.379	18.8685
687.815	21.9344
691.248	24.4585
694.682	25.1145
698.115	25.7691
701.546	27.4273
704.974	27.6583
708.402	29.5882
711.83	32.1362
715.254	33.7228
718.679	36.1065
722.102	36.8369
725.522	37.7429
728.943	39.9884
732.361	41.0097
735.779	41.2779
739.194	42.7312
742.608	42.8329
746.022	43.661
749.433	44.127
752.843	44.6874
756.254	45.9222
759.661	48.2412
763.067	50.3856
766.471	52.9542
769.877	55.5861
773.279	57.4971
776.68	59.9752
780.079	62.3357
783.478	65.0492
786.875	67.7664
790.27	69.9443
793.665	72.5644
797.058	73.9729
800.45	75.5988
803.84	76.0903
807.23	77.9159
810.616	76.4641
814.002	76.566
817.388	73.5724
820.772	72.3281
824.153	69.8059
827.535	66.788
830.915	64.5145
834.292	61.8324
837.67	58.1406
841.047	56.3023
844.42	54.7014
847.794	52.5701
851.165	51.3496
854.534	50.5014
857.905	48.8268
861.272	48.0526
864.639	46.7665
868.004	44.9482
871.367	45.7514
874.731	45.8332
878.092	46.7811
881.451	47.8033
884.809	48.5483
888.166	48.827
891.522	49.0334
894.878	49.2785
898.231	49.1661
901.583	49.3112
904.934	49.3182
908.283	49.2051
911.631	50.1823
914.976	49.1372
918.322	49.4477
921.666	49.55
925.009	49.027
928.351	47.6162
931.692	48.5728
935.029	48.2581
938.367	49.1997
941.704	47.6059
945.038	45.38
948.372	43.7803
951.705	44.0127
955.035	43.6004
958.366	41.994
961.693	39.5926
965.021	37.8821
968.346	36.7249
971.67	35.4706
974.995	34.8696
978.316	32.6244
981.638	32.0139
984.957	31.0812
988.274	29.9069
991.59	29.6536
994.907	28.1581
998.221	25.6511
1001.53	23.4241
1004.85	21.3478
1008.16	22.5429
1011.46	29.0078
1014.77	39.5733
1018.08	52.4193
1021.38	64.0191
1024.69	75.2868
1027.99	86.6179
1031.29	95.2529
1034.59	101.471
1037.89	104.952
1041.19	107.721
1044.48	108.649
1047.78	109.103
1051.07	106.356
1054.36	102.857
1057.66	96.3276
1060.94	89.5631
1064.23	81.0575
1067.52	69.3933
1070.81	58.2956
1074.09	46.6487
1077.38	34.2149
1080.66	24.8053
1083.94	17.0948
1087.22	13.3203
1090.5	13.833
1093.77	16.7606
1097.05	17.9829
1100.32	21.4937
1103.6	23.5782
1106.87	25.1482
1110.14	26.6671
1113.41	25.5314
1116.67	26.4938
1119.94	26.1843
1123.21	27.397
1126.47	26.9805
1129.73	26.2609
1133	27.1073
1136.26	26.1975
1139.52	26.0239
1142.77	24.0597
1146.03	20.7739
1149.29	19.0457
1152.54	17.728
1155.79	17.0629
1159.04	15.9387
1162.3	14.2865
1165.55	12.4925
1168.79	12.7917
1172.04	9.62376
1175.28	9.43953
1178.53	9.55849
1181.77	9.03235
1185.01	11.058
1188.25	10.6331
1191.49	10.6808
1194.73	11.1251
1197.97	12.5394
1201.2	13.2849
1204.44	13.2003
1207.67	12.7368
1210.9	13.5105
1214.13	14.9049
1217.36	16.2382
1220.59	16.6053
1223.82	16.3227
1227.04	18.5241
1230.26	20.0998
1233.49	22.3928
1236.71	24.7366
1239.93	25.8873
1243.15	27.487
1246.37	28.6687
1249.58	29.9246
1252.8	30.8922
1256.01	31.974
1259.23	33.8414
1262.44	35.7316
1265.65	37.7208
1268.86	38.4145
1272.07	37.8365
1275.27	38.0927
1278.48	39.5708
1281.68	38.8915
1284.89	40.325
1288.09	40.2353
1291.29	41.5686
1294.49	41.5736
1297.69	42.5637
1300.88	43.2865
1304.08	43.7727
1307.27	43.9338
1310.47	43.3944
1313.66	43.3447
1316.85	43.6218
1320.04	43.3387
1323.23	43.5648
1326.41	43.5319
1329.6	44.2146
1332.78	44.8138
1335.97	44.9578
1339.15	45.5388
1342.33	44.6487
1345.51	43.7304
1348.69	42.9064
1351.87	42.5076
1355.04	42.3241
1358.22	43.019
1361.39	39.9374
1364.57	38.3745
1367.74	37.199
1370.91	35.8908
1374.07	35.5087
1377.24	34.7044
1380.41	32.4179
1383.57	32.0892
1386.74	31.0623
1389.9	30.1984
1393.06	29.2546
1396.22	29.0391
1399.38	28.5969
1402.54	28.8914
1405.7	29.5306
1408.85	31.0192
1412.01	33.4404
1415.16	35.8662
1418.31	38.9684
1421.46	43.0876
1424.61	46.1821
1427.76	48.526
1430.91	52.554
1434.05	55.9297
1437.2	58.6112
1440.34	61.467
1443.49	64.7108
1446.63	65.5817
1449.77	65.8629
1452.91	66.1735
1456.04	65.7093
1459.18	65.783
1462.31	65.9778
1465.45	64.4589
1468.58	62.3786
1471.71	60.3803
1474.84	57.4543
1477.97	54.0852
1481.1	51.6609
1484.23	49.4582
1487.35	50.0141
1490.48	47.4004
1493.6	45.2327
1496.72	42.188
1499.84	39.0591
1502.96	36.5595
1506.08	35.6628
1509.2	34.858
1512.31	32.0117
1515.43	29.4584
1518.54	29.2918
1521.66	26.9811
1524.77	24.9597
1527.88	24.569
1530.99	25.3639
1534.09	25.3675
1537.2	25.0876
1540.31	25.7782
1543.41	25.9663
1546.51	25.8553
1549.62	25.7819
1552.72	25.567
1555.82	26.6339
1558.91	27.5127
1562.01	26.5165
1565.11	27.0223
1568.2	25.6033
1571.3	24.6924
1574.39	24.8199
1577.48	26.087
1580.57	27.3535
1583.66	28.5112
1586.75	28.4664
1589.83	30.7262
1592.92	32.8899
1596	34.3108
1599.09	35.008
1602.17	35.0662
1605.25	35.3656
1608.33	35.7486
1611.41	36.46
1614.48	35.9941
1617.56	36.2307
1620.64	37.3775
1623.71	36.5589
1626.78	37.8414
1629.86	39.052
1632.92	38.6412
1635.99	37.9735
1639.06	38.9536
1642.13	38.7357
1645.19	39.4453
1648.26	40.8488
1651.32	41.211
1654.38	41.227
1657.45	40.5609
1660.51	41.129
1663.57	41.4115
1666.62	41.0372
1669.68	38.1699
1672.73	36.9844
1675.79	35.5197
1678.84	33.1045
1681.89	29.8308
1684.94	27.3703
1687.99	25.2416
1691.04	22.8268
1694.09	20.8917
1697.14	19.4303
1700.18	17.9199
1703.22	16.3276
1706.27	13.8466
1709.31	11.1939
1712.35	10.0178
1715.39	8.36975
1718.43	8.00367
1721.46	7.5615
1724.5	6.46134
1727.53	5.56657
1730.57	6.60466
1733.6	6.73587
1736.63	6.96663
1739.66	7.15454
1742.69	6.69504
1745.72	7.98273
1748.74	9.73557
1751.77	9.50704
1754.8	8.88918
1757.82	8.64094
1760.84	7.70254
1763.86	7.65108
1766.88	6.68847
1769.9	6.80165
1772.92	6.24494
1775.93	5.78528
1778.95	4.42445
1781.96	3.94378
1784.98	3.80456
1787.99	3.96838
1791	4.09663
1794.01	4.15658
1797.02	4.28651
1800.03	4.08931
1803.03	4.06181
1806.04	3.6379
1809.04	3.21106
1812.04	3.08061
1815.05	3.28393
1818.05	3.02807
1821.05	3.47667
1824.05	3.81449
1827.04	3.52862
1830.04	3.00947
1833.03	2.91884
1836.03	2.87391
1839.02	3.03755
1842.01	3.70379
1845	4.08884
1847.99	4.76681
1850.98	5.53207
1853.97	4.93184
1856.95	5.63365
1859.94	5.83194
1862.92	5.01498
1865.91	5.25055
1868.89	4.5979
1871.87	4.66969
1874.85	4.42801
1877.83	3.24524
1880.8	2.30492
1882.56	3.09101
1885.54	3.54811
1888.53	3.69764
1891.52	3.48097
1894.5	3.60732
1897.49	2.9425
1900.47	2.91317
1903.45	3.79825
1906.43	4.67823
1909.41	5.14525
1912.39	5.86744
1915.37	6.80239
1918.35	7.0105
1921.32	7.222
1924.3	7.42179
1927.27	6.86194
1930.24	7.1507
1933.21	6.18032
1936.18	6.32409
1939.15	6.19687
1942.12	5.75006
1945.09	6.60145
1948.05	6.51483
1951.02	5.31536
1953.98	4.8574
1956.94	5.0794
1959.91	4.58708
1962.87	3.52611
1965.82	2.7005
1968.78	1.83834
1971.74	2.13053
1974.7	1.97661
1977.65	2.08932
1980.6	3.19916
1983.56	2.64059
1986.51	2.95566
1989.46	2.58818
1992.41	2.64093
1995.36	2.36404
1998.3	1.98197
2001.25	1.73488
2004.2	2.57043
2007.14	3.05102
2010.08	4.08345
2013.02	3.72715
2015.97	3.87095
2018.9	3.57049
2021.84	2.07653
2024.78	1.9964
2027.72	2.62913
2030.65	3.56057
2033.59	3.5951
2036.52	3.13485
2039.45	3.87873
2042.38	3.50743
2045.31	3.62603
2048.24	3.04635
2051.17	4.14834
2054.1	4.46203
2057.02	4.95775
2059.95	5.5794
2062.87	7.19239
2065.79	7.50433
2068.71	8.29749
2071.63	9.25467
2074.55	9.95481
2077.47	11.8233
2080.39	12.7604
2083.3	13.849
2086.22	14.3622
2089.13	16.4019
2092.05	17.4923
2094.96	19.3899
2097.87	20.8214
2100.78	22.5116
2103.69	23.1548
2106.59	23.8531
2109.5	24.1851
2112.41	25.3163
2115.31	25.9083
2118.21	27.298
2121.12	29.0449
2124.02	31.4698
2126.92	33.7137
2129.82	36.2381
2132.71	38.3719
2135.61	39.1167
2138.51	40.7913
2141.4	41.6997
2144.29	44.2769
2147.19	46.9803
2150.08	48.6282
2152.97	50.9909
2155.86	52.8981
2158.75	55.1761
2161.64	57.1972
2164.52	57.4367
2167.41	57.6789
2170.29	57.7403
2173.17	57.7896
2176.06	57.2448
2178.94	56.926
2181.82	55.9702
2184.7	54.6212
2187.57	53.9962
2190.45	51.5951
2193.33	50.6569
2196.2	48.3978
2199.08	46.6402
2201.95	44.4952
2204.82	40.7561
2207.69	38.26
2210.56	35.6715
2213.43	33.122
2216.3	31.8577
2219.16	29.4198
2222.03	27.7479
2224.89	27.3785
2227.75	26.2277
2230.62	24.2825
2233.48	23.066
2236.34	21.4017
2239.2	20.3264
2242.06	19.9135
2244.91	19.3939
2247.77	19.3895
2250.62	19.2723
2253.48	18.9311
2256.33	18.7772
2259.18	18.3925
2262.03	16.9071
2264.88	17.3366
2267.73	16.7099
2270.58	15.3196
2273.43	14.0986
2276.27	12.371
2279.12	12.246
2281.96	11.5043
2284.8	10.3408
2287.64	8.90224
2290.49	6.44358
2293.32	5.02789
2296.16	4.00628
2299	3.74945
2301.84	2.87241
2304.67	2.79153
2307.51	3.71516
2310.34	3.31311
2313.17	3.7382
2316	3.46164
2318.83	4.00618
2321.66	4.96935
2324.49	5.12541
2327.32	5.91401
2330.15	5.46733
2332.97	5.9459
2335.79	5.96444
2338.62	5.43316
2341.44	5.41654
2344.26	5.78647
2347.08	5.27308
2349.9	4.7797
2352.72	3.98652
2355.53	3.46426
2358.35	2.6378
2361.17	1.67729
2363.98	1.08336
2366.79	1.9468
2369.6	1.68499
2372.42	1.40242
2375.22	2.33787
2378.03	1.98088
2380.84	1.16044
2383.65	0.0763345
2386.45	0.146558
2389.26	1.08651
2392.06	1.07916
2394.87	0.640889
2397.67	0.148826
2400.47	1.30065
2403.27	2.03702
2406.07	2.67296
2408.86	4.49615
2411.66	5.12105
2414.46	5.91472
2417.25	5.72006
2420.05	6.69793
2422.84	6.021
2425.63	5.92617
2428.42	6.85552
2431.21	5.79881
2434	6.30322
2436.79	6.11999
2439.57	5.63239
2442.36	5.98285
2445.14	5.24712
2447.93	3.82146
2450.71	3.83617
2453.49	4.55227
2456.27	4.77964
2459.05	4.26179
2461.83	3.94557
2464.61	3.24221
2467.39	4.29025
2470.16	5.09337
2472.94	3.87385
2475.71	4.38049
2478.48	4.74818
2481.25	4.17746
2484.02	3.30589
2486.8	3.50466
2489.56	3.27658
2492.33	2.80817
2495.1	2.97771
2497.86	1.9541
2500.63	1.08704
2503.39	1.15918
2506.16	0.942552
2508.92	1.32075
2511.68	1.17593
2514.44	0.834347
2517.2	0.982073
2519.95	1.2477
2522.71	0.460519
2525.47	0.451456
2528.22	0.959901
2530.98	1.19908
2533.73	0.767643
2536.48	0.281638
2539.23	0.724874
2541.98	1.16169
2544.73	2.15829
2547.48	2.59131
2550.23	3.85532
2552.97	4.43617
2555.72	4.81307
2558.46	4.76804
2561.2	4.82128
2563.95	4.97956
2566.69	6.00147
2569.43	7.54025
2572.17	7.90543
2574.91	8.3847
2577.64	9.01202
2580.38	8.46568
2583.11	8.4489
2585.85	8.93456
2588.58	8.69338
2591.31	8.50921
2594.04	7.58784
2596.78	7.21324
2599.51	7.32529
2602.23	6.17943
2604.96	6.06892
2607.69	6.47939
2610.41	6.76964
2613.14	6.93957
2615.86	6.92947
2618.58	6.56984
2621.3	6.44655
2624.03	5.44998
2626.75	5.11604
2629.46	4.95241
2632.18	4.90872
2634.9	5.54658
2637.61	5.8003
2640.33	5.92173
2643.04	6.2871
2645.76	5.53993
2648.47	5.89278
2651.18	5.86682
2653.89	4.86541
2656.6	4.065
2659.31	3.34268
2662.01	3.07232
2664.72	2.96146
2667.43	2.73927
2670.13	2.36643
2672.83	2.1187
2675.53	3.12963
2678.24	3.82159
2680.94	4.24407
2683.64	4.10661
2686.34	4.40437
2689.03	4.24699
2691.73	5.36583
2694.43	5.0818
2697.12	5.61157
2699.81	7.1171
2702.51	7.86864
2705.2	8.66576
2707.89	8.49367
2710.58	9.23631
2713.27	9.3162
2715.96	10.0953
2718.64	8.95935
2721.33	8.85468
2724.01	8.20925
2726.7	7.50939
2729.38	7.50294
2732.06	7.14089
2734.75	7.17928
2737.43	7.77206
2740.11	7.93614
2742.78	8.31152
2745.46	8.29334
2748.14	7.29664
2750.81	6.65375
2753.49	5.84463
2756.16	5.11298
2758.84	5.10335
2761.51	5.41822
2764.18	4.08279
2766.85	3.52612
2769.52	3.55141
2772.19	3.25344
2774.85	3.59982
2777.52	3.95755
2780.18	4.7643
2782.85	4.59826
2785.51	5.03612
2788.17	5.03553
2790.84	4.73241
2793.5	4.96419
2796.16	4.83315
2798.81	4.65011
2801.47	4.4154
2804.13	4.6777
2806.79	4.9052
2809.44	3.83976
2812.09	3.72419
2814.75	3.6216
2817.4	4.65326
2820.05	4.57664
2822.7	5.41009
2825.35	6.921
2828	7.9474
2830.65	9.72888
2833.29	12.7077
2835.94	14.7789
2838.58	18.3498
2841.23	22.0513
2843.87	26.06
2846.51	29.6745
2849.15	33.5841
2851.79	36.3818
2854.43	40.0249
2857.07	43.1489
2859.71	45.5268
2862.34	48.9524
2864.98	52.6234
2867.61	55.3084
2870.25	57.252
2872.88	59.4837
2875.51	61.6597
2878.14	63.5195
2880.77	66.1235
2883.4	68.4698
2886.03	70.3902
2888.65	73.5963
2891.28	76.3801
2893.91	79.2661
2896.53	82.241
2899.15	85.0817
2901.78	89.5337
2904.4	94.92
2907.02	99.3214
2909.64	104.016
2912.26	108.807
2914.87	113.056
2917.49	116.899
2920.11	121.55
2922.72	124.737
2925.34	126.826
2927.95	128.468
2930.56	129.56
2933.17	130.321
2935.78	129.524
2938.39	127.016
2941	124.117
2943.61	121.125
2946.22	118.395
2948.82	114.263
2951.43	109.742
2954.03	104.922
2956.64	98.9383
2959.24	93.6985
2961.84	88.4072
2964.44	83.1365
2967.04	77.961
2969.64	73.6734
2972.24	69.1319
2974.83	64.0014
2977.43	59.7164
2980.02	55.2498
2982.62	51.344
2985.21	48.0978
2987.8	43.3793
2990.4	39.4424
2992.99	36.4211
2995.57	33.8499
2998.16	30.3707
3000.75	26.0568
3003.34	22.5845
3005.92	20.1549
3008.51	18.3193
3011.09	15.3185
3013.68	12.7682
3016.26	10.3605
3018.84	8.25254
3021.42	6.80186
3024	4.57168
3026.58	4.95272
3029.16	4.16153
3031.73	4.24513
3034.31	4.30307
3036.89	4.1987
3039.46	3.11379
3042.03	3.54814
3044.61	4.57137
3047.18	5.2447
3049.75	5.70531
3052.32	5.09043
3054.89	5.62764
3057.45	6.82472
3060.02	6.66329
3062.59	7.0046
3065.15	7.43024
3067.72	6.8013
3070.28	6.35457
3072.84	6.17915
3075.41	5.50182
3077.97	4.91866
3080.53	4.76528
3083.09	4.28276
3085.64	3.23808
3088.2	3.50383
3090.76	2.53513
3093.31	2.28801
3095.87	1.81878
3098.42	1.02426
3100.97	0.879551
3103.53	1.68872
3106.08	2.77643
3108.63	3.91973
3111.18	4.10775
3113.73	4.62744
3116.27	5.56215
3118.82	7.73805
3121.37	9.29429
3123.91	10.8958
3126.45	12.2937
3129	13.2441
3131.54	14.5299
3134.08	15.3165
3136.62	16.7769
3139.16	17.815
3141.7	18.6871
3144.24	18.8798
3146.78	19.2675
3149.31	20.5615