File: data/Raman/poly_smoothed/Mb_40_y_24_1x_45s_532 nm_x100_100%_600 gr_mm_01.txt
#Acq. time (s)=	45
#Accumulations=	2
#Range (cm-¹)=	200...3150
#Windows=	2
#Auto scanning=	Off
#Autofocus=	Off
#Macrospot=	Off
#AutoExposure=	Off
#Spike filter=	Multiple accum.
#Delay time (s)=	0
#Binning=	1
#Readout mode=	Signal
#DeNoise=	Off
#ICS correction=	On
#Dark correction=	Off
#Inst. Process=	Off
#Detector Gain=	Best Dynamic Range
#Detector ADC=	20 kHz
#Detector temperature (°C)=	-69.85
#Instrument=	LabRAM HR Evol
#Detector=	Synapse
#Objective=	x100
#Grating=	600 gr/mm
#ND Filter=	100%
#Laser (nm)=	532
#Hole=	100.021
#Range=	Auto
#Laser Pol.=	No
#Raman. Pol.=	No
#Laser Pol. (°)=	-0.0007625
#Raman Pol. (°)=	89.9995
#Collection=	Microscope
#StageXY=	Marzhauser
#StageZ=	Marzhauser
#X (µm)=	-1015
#Y (µm)=	633.7
#Z (µm)=	583.85
#Full time(mm:ss)=	3:18
#Project=
#Sample=
#Site=
#Title=	Mb_40_y_24_2x_45s_532 nm_x100_100%_600 gr_mm
#Remark=
#Date=	19.07.2022 10:57
#Acquired=	19.07.2022 10:57:32
#Base:Fit=	10.08.2022 10:52:48
#Base:Sub=	10.08.2022 10:52:53
#Filter:Polynom=	16.08.2022 10:09:04
#AxisType[0]=Intens
#AxisUnit[0]=Cnt
#AxisType[1]=Spectr
#AxisUnit[1]=1/cm
200.423	5.32261
204.052	9.01047
207.682	10.7705
211.308	12.43
214.935	12.6957
218.558	13.2349
222.18	13.754
225.802	11.6178
229.421	11.9192
233.039	9.63001
236.657	8.31158
240.272	8.18971
243.885	6.02504
247.497	5.96785
251.11	5.10725
254.719	3.58898
258.327	3.92539
261.933	2.22541
265.538	2.22747
269.141	1.6189
272.744	1.46898
276.344	0.173294
279.944	1.59568
283.542	4.0999
287.138	4.53529
290.733	6.57635
294.327	8.09176
297.919	8.36989
301.508	9.83839
305.098	9.79528
308.686	12.133
312.273	11.591
315.858	12.435
319.44	11.9017
323.022	11.4377
326.604	13.5163
330.181	13.5114
333.76	14.3115
337.335	13.6796
340.91	12.456
344.483	11.5866
348.055	9.78202
351.625	8.8779
355.195	9.20981
358.762	8.55112
362.329	6.91693
365.893	7.07871
369.455	5.86004
373.017	6.8608
376.578	7.17114
380.137	8.599
383.694	8.90314
387.249	8.81089
390.806	9.27708
394.359	10.1243
397.91	9.9596
401.46	9.06337
405.009	9.4592
408.557	7.71938
412.103	8.09819
415.647	9.04015
419.191	9.18466
422.733	7.57072
426.273	7.07652
429.812	5.94314
433.35	4.36183
436.885	3.02024
440.42	4.1204
443.954	3.94123
447.486	3.14032
451.015	3.04118
454.545	3.51256
458.073	4.85789
461.598	6.84615
465.124	7.9626
468.648	10.5758
472.169	12.4989
475.69	14.5177
479.208	15.2729
482.727	17.1698
486.243	20.1345
489.759	22.3114
493.272	24.8316
496.783	25.6314
500.295	27.5917
503.804	28.5408
507.311	29.2266
510.819	28.2949
514.324	26.33
517.827	26.9295
521.329	27.192
524.83	24.9852
528.329	23.6964
531.829	21.866
535.326	20.0189
538.821	17.5306
542.315	16.4725
545.808	13.6922
549.299	12.5251
552.789	12.248
556.278	11.2836
559.763	9.31278
563.249	8.33823
566.733	8.27714
570.217	9.15205
573.699	8.1851
577.177	7.13537
580.656	5.62446
584.134	5.44918
587.609	5.42395
591.084	6.26705
594.558	4.16229
598.029	3.62313
601.5	5.27571
604.968	7.05836
608.437	4.999
611.902	4.93352
615.368	4.86055
618.831	5.36942
622.294	3.45622
625.755	3.40743
629.213	2.72974
632.673	3.86139
636.129	3.63956
639.584	3.00062
643.037	3.72493
646.491	4.64187
649.942	4.66803
653.392	4.51473
656.84	5.16001
660.287	4.71741
663.732	5.33307
667.177	6.31453
670.62	6.94611
674.061	8.85448
677.502	7.43478
680.941	8.16531
684.379	8.58534
687.815	10.856
691.248	10.7736
694.682	11.0934
698.115	13.378
701.546	14.9597
704.974	16.4589
708.402	18.2865
711.83	20.438
715.254	22.1153
718.679	24.6801
722.102	24.4305
725.522	27.0681
728.943	28.2314
732.361	27.9804
735.779	28.0921
739.194	29.8029
742.608	30.5474
746.022	30.4452
749.433	30.9404
752.843	32.6104
756.254	33.7147
759.661	34.383
763.067	35.9267
766.471	38.0455
769.877	40.5713
773.279	43.9479
776.68	47.0134
780.079	49.9068
783.478	52.3331
786.875	55.6277
790.27	58.3248
793.665	62.8492
797.058	65.0924
800.45	67.0155
803.84	67.3363
807.23	68.7047
810.616	68.638
814.002	68.2107
817.388	67.635
820.772	68.0683
824.153	66.572
827.535	63.9048
830.915	62.5119
834.292	59.8064
837.67	56.1696
841.047	54.7348
844.42	52.3013
847.794	49.8345
851.165	46.2913
854.534	43.0179
857.905	41.4241
861.272	38.5206
864.639	37.2236
868.004	37.4078
871.367	38.6107
874.731	38.4125
878.092	38.07
881.451	35.8838
884.809	34.2734
888.166	34.0557
891.522	35.2007
894.878	36.542
898.231	36.9862
901.583	37.3204
904.934	37.9181
908.283	36.7731
911.631	36.6501
914.976	36.9775
918.322	36.1149
921.666	37.138
925.009	38.4222
928.351	37.3292
931.692	38.1873
935.029	37.2567
938.367	36.8782
941.704	37.1764
945.038	35.9084
948.372	36.4319
951.705	36.5214
955.035	35.1225
958.366	32.2303
961.693	29.5597
965.021	29.184
968.346	30.1775
971.67	30.0841
974.995	30.0825
978.316	29.8413
981.638	30.4236
984.957	29.4284
988.274	28.5329
991.59	26.055
994.907	24.0693
998.221	20.5198
1001.53	17.1225
1004.85	14.6433
1008.16	19.1989
1011.46	28.4748
1014.77	42.4769
1018.08	57.7668
1021.38	73.5306
1024.69	89.4279
1027.99	102.054
1031.29	115.031
1034.59	123.839
1037.89	130.427
1041.19	133.936
1044.48	138.209
1047.78	140.392
1051.07	137.549
1054.36	132.552
1057.66	125.959
1060.94	115.316
1064.23	103.227
1067.52	87.0795
1070.81	70.3729
1074.09	52.2337
1077.38	36.031
1080.66	20.1545
1083.94	8.60563
1087.22	5.83806
1090.5	8.01011
1093.77	13.0483
1097.05	16.7499
1100.32	20.2617
1103.6	22.3872
1106.87	22.8356
1110.14	23.4667
1113.41	23.6074
1116.67	24.0224
1119.94	23.1019
1123.21	22.3394
1126.47	23.2244
1129.73	21.9424
1133	20.0815
1136.26	18.6714
1139.52	16.4617
1142.77	13.8933
1146.03	10.7133
1149.29	8.01591
1152.54	6.47495
1155.79	4.14772
1159.04	0.808171
1162.3	-1.62067
1165.55	-4.21272
1168.79	-1.98325
1172.04	-1.54174
1175.28	1.02236
1178.53	2.504
1181.77	3.42834
1185.01	4.3587
1188.25	5.21021
1191.49	5.00208
1194.73	6.64842
1197.97	8.41377
1201.2	10.7462
1204.44	12.657
1207.67	14.4507
1210.9	16.1976
1214.13	17.9899
1217.36	21.1442
1220.59	23.6474
1223.82	25.2548
1227.04	27.9091
1230.26	33.0582
1233.49	35.98
1236.71	36.3425
1239.93	39.0493
1243.15	41.0753
1246.37	43.1746
1249.58	47.806
1252.8	49.1951
1256.01	52.8902
1259.23	54.38
1262.44	56.4175
1265.65	58.9251
1268.86	60.9374
1272.07	64.1644
1275.27	69.2506
1278.48	73.7771
1281.68	77.6465
1284.89	81.4005
1288.09	84.1192
1291.29	85.873
1294.49	87.4919
1297.69	89.1341
1300.88	90.1325
1304.08	91.4719
1307.27	92.9144
1310.47	94.5535
1313.66	92.7746
1316.85	90.8749
1320.04	90.4054
1323.23	89.6142
1326.41	87.7874
1329.6	83.353
1332.78	79.551
1335.97	77.3399
1339.15	74.0128
1342.33	72.3278
1345.51	69.4821
1348.69	67.1143
1351.87	66.354
1355.04	65.6905
1358.22	62.8909
1361.39	58.965
1364.57	56.2997
1367.74	50.7711
1370.91	47.6442
1374.07	43.8248
1377.24	42.2031
1380.41	41.075
1383.57	38.8556
1386.74	38.3544
1389.9	37.6599
1393.06	36.9032
1396.22	37.213
1399.38	38.2401
1402.54	39.0261
1405.7	40.2117
1408.85	45.2232
1412.01	52.4927
1415.16	58.4137
1418.31	64.2582
1421.46	72.7646
1424.61	79.733
1427.76	89.5747
1430.91	99.2526
1434.05	105.393
1437.2	111.569
1440.34	116.118
1443.49	119.018
1446.63	121.324
1449.77	122.173
1452.91	122.204
1456.04	119.036
1459.18	115.266
1462.31	109.605
1465.45	105.086
1468.58	97.4412
1471.71	88.4533
1474.84	78.9679
1477.97	70.5542
1481.1	63.4034
1484.23	56.24
1487.35	50.038
1490.48	43.0446
1493.6	39.3331
1496.72	34.0683
1499.84	32.3855
1502.96	29.204
1506.08	27.4825
1509.2	24.5068
1512.31	24.4542
1515.43	24.0508
1518.54	23.3716
1521.66	23.2021
1524.77	23.6338
1527.88	23.7159
1530.99	25.004
1534.09	25.9726
1537.2	26.1979
1540.31	26.677
1543.41	28.0761
1546.51	27.1193
1549.62	27.6975
1552.72	28.801
1555.82	28.7921
1558.91	30.5622
1562.01	32.1971
1565.11	33.7881
1568.2	37.7669
1571.3	40.6093
1574.39	43.6772
1577.48	46.0988
1580.57	49.8108
1583.66	54.3179
1586.75	57.9422
1589.83	61.4682
1592.92	62.3659
1596	65.0113
1599.09	67.3605
1602.17	68.2024
1605.25	69.4628
1608.33	69.2856
1611.41	68.9096
1614.48	67.6942
1617.56	67.8683
1620.64	69.3708
1623.71	69.8256
1626.78	71.0531
1629.86	71.804
1632.92	73.7949
1635.99	75.2865
1639.06	76.6632
1642.13	79.595
1645.19	82.5541
1648.26	84.77
1651.32	85.2129
1654.38	87.5732
1657.45	88.1471
1660.51	88.1458
1663.57	86.2234
1666.62	84.1288
1669.68	80.1984
1672.73	76.9344
1675.79	71.4828
1678.84	64.7527
1681.89	58.7454
1684.94	51.9193
1687.99	46.837
1691.04	40.7848
1694.09	34.8921
1697.14	31.0851
1700.18	26.8648
1703.22	24.1067
1706.27	21.2679
1709.31	17.9924
1712.35	16.2068
1715.39	14.8312
1718.43	14.3077
1721.46	12.1925
1724.5	11.6176
1727.53	11.9871
1730.57	12.0571
1733.6	12.2608
1736.63	13.1862
1739.66	13.0985
1742.69	12.2907
1745.72	11.0702
1748.74	10.0024
1751.77	8.10711
1754.8	7.10161
1757.82	5.63186
1760.84	4.56865
1763.86	3.00316
1766.88	1.86915
1769.9	1.70071
1772.92	2.87495
1775.93	2.88784
1778.95	2.83058
1781.96	1.85145
1784.98	1.54793
1787.99	0.69021
1791	0.966839
1794.01	0.700488
1797.02	1.29818
1800.03	1.84631
1803.03	2.11045
1806.04	2.27731
1809.04	2.30165
1812.04	1.49829
1815.05	2.84265
1818.05	1.90117
1821.05	1.95781
1824.05	2.02335
1827.04	1.22609
1830.04	1.37521
1833.03	1.43113
1836.03	0.828551
1839.02	1.74275
1842.01	2.00869
1845	2.15078
1847.99	2.13563
1850.98	1.16328
1853.97	1.50901
1856.95	1.50548
1859.94	2.80062
1862.92	2.68138
1865.91	3.4677
1868.89	4.25563
1871.87	4.64554
1874.85	4.17368
1877.83	4.23966
1880.8	4.2517
1882.56	3.84789
1885.54	3.50967
1888.53	3.1321
1891.52	2.32751
1894.5	1.56594
1897.49	1.50453
1900.47	1.67074
1903.45	1.51891
1906.43	1.51562
1909.41	1.48581
1912.39	1.54763
1915.37	1.02833
1918.35	-0.00590158
1921.32	-0.726335
1924.3	-0.675277
1927.27	0.720239
1930.24	1.72297
1933.21	1.52899
1936.18	2.74924
1939.15	4.23642
1942.12	4.96687
1945.09	4.73091
1948.05	6.01512
1951.02	7.2495
1953.98	6.20182
1956.94	6.09671
1959.91	6.565
1962.87	6.86712
1965.82	7.62464
1968.78	8.06971
1971.74	8.15956
1974.7	8.57161
1977.65	8.57814
1980.6	9.04577
1983.56	7.91132
1986.51	8.24216
1989.46	6.9233
1992.41	6.89843
1995.36	6.67183
1998.3	6.83316
2001.25	7.56479
2004.2	6.64634
2007.14	6.68048
2010.08	7.79117
2013.02	8.01059
2015.97	8.31146
2018.9	8.37074
2021.84	8.43611
2024.78	7.64295
2027.72	7.55295
2030.65	8.41189
2033.59	8.94415
2036.52	9.6068
2039.45	11.1028
2042.38	11.9656
2045.31	13.7617
2048.24	15.3406
2051.17	16.4558
2054.1	16.5819
2057.02	17.995
2059.95	20.5107
2062.87	22.3838
2065.79	24.5483
2068.71	25.7105
2071.63	26.6652
2074.55	28.0274
2077.47	29.1647
2080.39	31.3906
2083.3	32.1208
2086.22	34.4873
2089.13	36.2726
2092.05	37.9802
2094.96	40.5173
2097.87	44.2261
2100.78	47.7275
2103.69	52.8101
2106.59	56.073
2109.5	59.94
2112.41	64.9339
2115.31	69.1011
2118.21	72.4418
2121.12	75.7599
2124.02	80.413
2126.92	85.3492
2129.82	91.6963
2132.71	96.1143
2135.61	101.104
2138.51	104.497
2141.4	108.766
2144.29	113.394
2147.19	117.046
2150.08	121.24
2152.97	124.927
2155.86	127.912
2158.75	131.529
2161.64	134.293
2164.52	135.656
2167.41	137.451
2170.29	139.031
2173.17	138.887
2176.06	137.217
2178.94	135.342
2181.82	132.33
2184.7	130.095
2187.57	127.333
2190.45	124.448
2193.33	120.198
2196.2	116.972
2199.08	112.898
2201.95	108.844
2204.82	103.903
2207.69	99.2427
2210.56	94.7782
2213.43	90.0736
2216.3	85.3743
2219.16	80.1387
2222.03	74.9644
2224.89	70.5054
2227.75	66.2839
2230.62	62.2767
2233.48	57.5685
2236.34	53.5056
2239.2	49.5197
2242.06	44.9803
2244.91	40.5081
2247.77	37.6976
2250.62	34.9099
2253.48	33.2891
2256.33	32.0892
2259.18	31.2606
2262.03	28.7839
2264.88	26.5298
2267.73	26.595
2270.58	25.258
2273.43	24.3026
2276.27	23.3391
2279.12	22.0446
2281.96	21.2195
2284.8	20.0407
2287.64	18.862
2290.49	17.3483
2293.32	14.4414
2296.16	13.306
2299	12.8456
2301.84	13.5566
2304.67	12.9781
2307.51	11.9992
2310.34	11.8214
2313.17	11.1343
2316	11.2755
2318.83	9.75981
2321.66	9.57914
2324.49	9.94519
2327.32	10.0948
2330.15	9.33925
2332.97	8.28742
2335.79	8.09763
2338.62	7.989
2341.44	6.71114
2344.26	5.4531
2347.08	5.29563
2349.9	3.97977
2352.72	3.40543
2355.53	2.43082
2358.35	1.44085
2361.17	1.1436
2363.98	2.18193
2366.79	3.14898
2369.6	5.33664
2372.42	6.11191
2375.22	6.78315
2378.03	7.9781
2380.84	8.65806
2383.65	9.09956
2386.45	8.54965
2389.26	8.76926
2392.06	9.87366
2394.87	10.1212
2397.67	10.9081
2400.47	11.2614
2403.27	10.4895
2406.07	10.5018
2408.86	9.78532
2411.66	10.8625
2414.46	11.9869
2417.25	11.566
2420.05	11.61
2422.84	12.0505
2425.63	12.2038
2428.42	12.0165
2431.21	11.9264
2434	11.1082
2436.79	10.887
2439.57	11.0105
2442.36	11.266
2445.14	10.2736
2447.93	10.6893
2450.71	9.21135
2453.49	7.76711
2456.27	7.38319
2459.05	7.46346
2461.83	7.27806
2464.61	7.24122
2467.39	7.45404
2470.16	6.65672
2472.94	6.79551
2475.71	7.64234
2478.48	8.58582
2481.25	8.81923
2484.02	8.43221
2486.8	7.74419
2489.56	8.05896
2492.33	6.93129
2495.1	6.12085
2497.86	5.39794
2500.63	4.687
2503.39	4.36892
2506.16	3.26746
2508.92	3.49347
2511.68	1.94907
2514.44	2.10316
2517.2	0.860066
2519.95	1.14261
2522.71	1.69324
2525.47	1.94039
2528.22	2.53551
2530.98	2.63118
2533.73	2.82595
2536.48	3.12823
2539.23	4.45113
2541.98	5.29409
2544.73	6.72844
2547.48	6.81238
2550.23	8.16569
2552.97	7.9115
2555.72	7.78032
2558.46	7.13841
2561.2	6.6451
2563.95	6.5331
2566.69	5.43323
2569.43	5.83218
2572.17	6.48967
2574.91	6.34757
2577.64	6.82963
2580.38	6.47936
2583.11	5.96985
2585.85	5.28246
2588.58	6.02981
2591.31	6.13273
2594.04	6.01635
2596.78	6.17434
2599.51	6.33168
2602.23	6.99379
2604.96	7.32497
2607.69	7.31452
2610.41	7.43514
2613.14	7.14159
2615.86	6.21438
2618.58	5.19478
2621.3	4.39238
2624.03	3.57525
2626.75	2.79768
2629.46	2.58798
2632.18	3.02355
2634.9	3.1433
2637.61	2.57404
2640.33	2.30995
2643.04	1.14749
2645.76	0.365301
2648.47	0.543936
2651.18	1.45629
2653.89	2.35844
2656.6	3.50574
2659.31	4.66197
2662.01	6.37993
2664.72	7.10465
2667.43	8.23548
2670.13	8.85883
2672.83	8.51531
2675.53	8.4578
2678.24	8.33325
2680.94	8.16586
2683.64	9.08572
2686.34	8.46242
2689.03	7.88694
2691.73	7.12124
2694.43	7.18375
2697.12	7.41125
2699.81	6.97797
2702.51	6.81356
2705.2	6.92362
2707.89	7.499
2710.58	7.68929
2713.27	9.06771
2715.96	9.39676
2718.64	10.2661
2721.33	11.3303
2724.01	11.5502
2726.7	13.0849
2729.38	13.1755
2732.06	13.2396
2734.75	13.5311
2737.43	12.0425
2740.11	11.6789
2742.78	11.216
2745.46	10.9712
2748.14	9.55725
2750.81	8.16269
2753.49	7.33475
2756.16	7.03966
2758.84	7.56452
2761.51	6.62865
2764.18	5.62605
2766.85	5.00377
2769.52	5.40059
2772.19	4.45209
2774.85	3.61738
2777.52	2.7878
2780.18	2.13758
2782.85	1.77715
2785.51	1.32183
2788.17	1.07801
2790.84	0.808748
2793.5	0.484402
2796.16	0.58945
2798.81	-0.0696008
2801.47	-0.834968
2804.13	-0.680285
2806.79	-1.26147
2809.44	-1.46894
2812.09	-1.49797
2814.75	-1.19367
2817.4	1.21371
2820.05	5.88192
2822.7	12.613
2825.35	19.2638
2828	27.2048
2830.65	37.4132
2833.29	48.2035
2835.94	59.9698
2838.58	72.0098
2841.23	85.1391
2843.87	99.1315
2846.51	113.957
2849.15	129.815
2851.79	144.783
2854.43	159.091
2857.07	174.141
2859.71	188.031
2862.34	200.989
2864.98	212.591
2867.61	222.828
2870.25	230.803
2872.88	237.682
2875.51	244.2
2878.14	249.959
2880.77	256.473
2883.4	264.762
2886.03	271.934
2888.65	278.736
2891.28	285.336
2893.91	291.903
2896.53	299.461
2899.15	307.542
2901.78	316.471
2904.4	326.257
2907.02	337.888
2909.64	350.753
2912.26	364.547
2914.87	377.415
2917.49	389.766
2920.11	400.862
2922.72	410.416
2925.34	418.094
2927.95	423.066
2930.56	425.199
2933.17	426.65
2935.78	424.624
2938.39	420.628
2941	413.318
2943.61	404.603
2946.22	392.279
2948.82	379.057
2951.43	363.386
2954.03	346.657
2956.64	328.712
2959.24	309.759
2961.84	292.097
2964.44	272.295
2967.04	254.34
2969.64	236.672
2972.24	220.639
2974.83	204.883
2977.43	189.339
2980.02	172.197
2982.62	156.87
2985.21	141.736
2987.8	128.371
2990.4	114.825
2992.99	102.635
2995.57	92.5701
2998.16	81.8353
3000.75	71.9957
3003.34	62.7071
3005.92	53.7349
3008.51	46.3989
3011.09	39.786
3013.68	33.8646
3016.26	29.4511
3018.84	25.2927
3021.42	22.268
3024	18.7379
3026.58	16.4702
3029.16	14.3114
3031.73	13.2695
3034.31	13.7263
3036.89	13.3932
3039.46	13.7793
3042.03	14.1873
3044.61	14.5577
3047.18	15.016
3049.75	15.6723
3052.32	16.3272
3054.89	16.2461
3057.45	15.996
3060.02	15.1368
3062.59	13.411
3065.15	13.363
3067.72	12.1241
3070.28	10.8866
3072.84	9.33788
3075.41	8.06499
3077.97	6.66123
3080.53	5.41123
3083.09	3.46541
3085.64	2.93759
3088.2	1.69588
3090.76	2.27192
3093.31	2.28749
3095.87	1.29843
3098.42	1.94707
3100.97	1.25985
3103.53	1.3969
3106.08	1.49831
3108.63	1.73072
3111.18	1.35554
3113.73	2.04437
3116.27	1.63529
3118.82	2.09235
3121.37	2.37327
3123.91	3.52481
3126.45	4.2976
3129	5.32955
3131.54	5.99328
3134.08	6.85799
3136.62	7.69145
3139.16	9.45997
3141.7	11.701
3144.24	14.5532
3146.78	17.6882
3149.31	20.6335