File: data/Raman/poly_smoothed/Mb_40_24_07_1x_45s_532 nm_x100_100%_600 gr_mm_01.txt
#Acq. time (s)=	45
#Accumulations=	2
#Range (cm-¹)=	200...3150
#Windows=	2
#Auto scanning=	Off
#Autofocus=	Off
#Macrospot=	Off
#AutoExposure=	Off
#Spike filter=	Multiple accum.
#Delay time (s)=	0
#Binning=	1
#Readout mode=	Signal
#DeNoise=	Off
#ICS correction=	On
#Dark correction=	Off
#Inst. Process=	Off
#Detector Gain=	Best Dynamic Range
#Detector ADC=	20 kHz
#Detector temperature (°C)=	-70.08
#Instrument=	LabRAM HR Evol
#Detector=	Synapse
#Objective=	x100
#Grating=	600 gr/mm
#ND Filter=	100%
#Laser (nm)=	532
#Hole=	100.021
#Range=	Auto
#Laser Pol.=	No
#Raman. Pol.=	No
#Laser Pol. (°)=	-0.0007625
#Raman Pol. (°)=	89.9995
#Collection=	Microscope
#StageXY=	Marzhauser
#StageZ=	Marzhauser
#X (µm)=	-2515.4
#Y (µm)=	-23.3
#Z (µm)=	-10.2
#Full time(mm:ss)=	3:18
#Project=
#Sample=
#Site=
#Title=	Mb_40_24_07_2x_45s_532 nm_x100_100%_600 gr_mm
#Remark=
#Date=	14.07.2022 11:14
#Acquired=	14.07.2022 11:14:12
#Base:Fit=	10.08.2022 10:47:00
#Base:Sub=	10.08.2022 10:47:12
#Filter:Polynom=	16.08.2022 10:11:48
#AxisType[0]=Intens
#AxisUnit[0]=Cnt
#AxisType[1]=Spectr
#AxisUnit[1]=1/cm
200.554	76.578
204.183	68.0482
207.813	57.5693
211.439	48.4999
215.065	39.5804
218.688	31.6144
222.312	25.2059
225.933	19.7023
229.552	16.9879
233.171	13.9183
236.787	14.3113
240.402	10.8866
244.015	10.5832
247.627	10.1821
251.24	10.8115
254.849	8.35688
258.457	12.1101
262.063	14.6008
265.668	13.0022
269.271	13.8044
272.873	15.5855
276.474	16.9768
280.073	17.0054
283.671	16.5329
287.268	15.491
290.863	13.8482
294.456	13.8195
298.049	12.1107
301.637	12.5126
305.227	11.9021
308.815	9.7739
312.402	11.367
315.987	12.5727
319.569	13.4505
323.151	14.4413
326.733	14.2877
330.31	13.8575
333.889	14.3525
337.464	13.2628
341.039	14.1346
344.611	12.1718
348.184	13.4118
351.754	10.4107
355.324	8.94817
358.89	7.65574
362.455	6.2323
366.021	4.68947
369.584	4.85149
373.145	4.75485
376.707	3.94276
380.265	3.99775
383.822	3.19948
387.378	2.35167
390.934	3.60966
394.487	3.83351
398.038	4.25168
401.588	6.48244
405.137	7.61313
408.685	7.32198
412.23	9.33255
415.775	8.42999
419.318	6.85472
422.86	7.02272
426.401	8.16198
429.94	8.50715
433.478	7.81269
437.012	5.15204
440.547	5.7617
444.081	6.03574
447.613	8.12426
451.142	8.40707
454.672	9.89155
458.2	10.9719
461.725	12.1085
465.251	13.5984
468.775	13.1431
472.296	14.9659
475.817	15.5834
479.335	18.1176
482.854	17.8914
486.37	18.7943
489.886	18.9156
493.398	18.9738
496.91	20.4828
500.422	20.9795
503.93	20.6992
507.438	22.8261
510.946	23.3474
514.45	23.8154
517.954	23.3131
521.456	24.6758
524.956	25.6558
528.456	26.6305
531.956	27.1696
535.452	26.6983
538.947	25.8333
542.441	27.0505
545.934	29.2214
549.425	26.7366
552.915	24.7565
556.403	23.1818
559.889	23.5155
563.375	20.7697
566.859	20.4256
570.342	18.1892
573.824	17.5368
577.303	16.3256
580.782	16.8437
584.26	15.0441
587.734	14.298
591.21	11.6643
594.684	10.7984
598.154	9.61683
601.626	9.86376
605.094	11.0603
608.562	11.5053
612.027	10.2576
615.493	8.85558
618.956	10.5557
622.419	9.13392
625.879	8.73116
629.338	9.5431
632.797	6.98908
636.254	5.25069
639.708	3.85274
643.162	4.62109
646.614	4.33554
650.067	3.0826
653.516	3.3916
656.964	3.02513
660.411	3.03371
663.857	3.29342
667.301	3.1142
670.744	3.64274
674.186	3.30896
677.626	4.63162
681.065	6.1695
684.503	9.81585
687.939	10.2175
691.372	12.0023
694.806	11.6235
698.239	11.684
701.67	13.2398
705.098	14.9659
708.526	14.3339
711.954	14.3455
715.378	13.1284
718.802	12.8554
722.226	12.1201
725.646	12.1783
729.067	12.1491
732.484	10.7394
735.902	13.1201
739.317	14.3412
742.731	17.0824
746.145	19.9709
749.556	24.4809
752.966	27.9499
756.377	32.3855
759.784	35.0413
763.19	39.5541
766.594	43.7637
770	48.3532
773.402	52.3829
776.803	56.0788
780.202	57.5719
783.6	62.0163
786.997	63.5388
790.393	67.1015
793.787	67.3828
797.18	68.7766
800.572	69.6543
803.963	68.002
807.35	65.2752
810.738	62.0234
814.125	59.5303
817.51	57.7808
820.894	57.1639
824.275	58.1535
827.657	57.6202
831.037	58.8995
834.414	59.7902
837.792	60.4231
841.167	62.1632
844.542	62.2841
847.914	64.0097
851.287	64.5794
854.656	64.0706
858.026	64.6505
861.393	63.624
864.761	62.1054
868.125	61.0867
871.489	60.9631
874.85	59.8977
878.213	56.6986
881.572	52.7061
884.931	47.0309
888.287	43.4118
891.643	40.0456
894.997	38.5283
898.352	35.6191
901.704	34.4873
905.055	34.4085
908.404	35.6855
911.75	36.5832
915.097	38.5733
918.443	37.8426
921.787	40.9406
925.13	38.7232
928.472	37.2631
931.813	37.3407
935.15	36.2545
938.488	36.6897
941.825	38.4128
945.158	37.5456
948.493	34.489
951.824	34.574
955.156	32.5206
958.486	30.3741
961.814	29.268
965.142	27.5615
968.467	29.7934
971.79	31.7104
975.115	32.2598
978.436	33.4527
981.756	32.0418
985.077	31.3377
988.394	31.5426
991.71	30.8879
995.025	31.2471
998.341	30.3414
1001.65	29.0638
1004.97	27.7956
1008.28	30.0198
1011.58	33.9193
1014.89	38.4481
1018.2	43.7825
1021.5	49.7394
1024.81	54.2749
1028.11	55.4274
1031.41	57.3544
1034.71	61.6479
1038.01	64.9727
1041.31	67.5281
1044.6	70.4103
1047.9	73.7376
1051.19	73.5621
1054.48	71.5566
1057.77	68.8755
1061.06	63.996
1064.35	63.2888
1067.64	58.6477
1070.93	54.5184
1074.21	47.5291
1077.49	42.2532
1080.78	35.8008
1084.06	32.4097
1087.34	29.1801
1090.61	29.4872
1093.89	28.8342
1097.17	27.0831
1100.44	24.4733
1103.71	22.7805
1106.99	21.19
1110.26	20.4497
1113.52	20.6552
1116.79	20.8901
1120.06	19.7641
1123.32	17.7865
1126.59	17.5168
1129.85	14.9563
1133.11	13.327
1136.37	12.981
1139.63	12.4854
1142.89	12.3268
1146.15	10.8766
1149.4	7.99679
1152.66	7.38238
1155.91	5.59242
1159.16	4.93607
1162.41	4.40191
1165.66	2.59878
1168.91	1.02914
1172.16	0.746107
1175.4	0.384007
1178.65	1.15695
1181.89	1.19507
1185.13	2.58987
1188.37	4.49718
1191.61	4.93882
1194.85	6.29235
1198.08	7.94528
1201.32	10.5339
1204.55	11.6311
1207.79	12.2022
1211.02	12.7394
1214.25	15.1356
1217.48	16.0941
1220.71	16.8055
1223.93	17.4502
1227.16	17.585
1230.38	19.0321
1233.6	21.6344
1236.83	21.7353
1240.05	26.3303
1243.26	27.6654
1246.48	29.2691
1249.7	31.1672
1252.92	33.9962
1256.13	37.7623
1259.34	40.2133
1262.55	44.2293
1265.76	49.8154
1268.97	56.2302
1272.18	59.9892
1275.39	65.8502
1278.59	71.2304
1281.8	72.8221
1285	75.1329
1288.2	76.2874
1291.4	78.6996
1294.6	78.9398
1297.8	81.9905
1301	81.5526
1304.19	81.0403
1307.39	80.2652
1310.58	82.2514
1313.77	84.0181
1316.96	80.1558
1320.15	78.0945
1323.34	75.5106
1326.53	74.6248
1329.72	74.0871
1332.9	73.3019
1336.08	72.7454
1339.27	73.2451
1342.45	73.8096
1345.63	74.8595
1348.8	75.8785
1351.98	74.9961
1355.16	76.1292
1358.33	75.5891
1361.51	75.1797
1364.68	76.4528
1367.85	77.0915
1371.02	77.104
1374.19	78.283
1377.36	78.2262
1380.52	78.623
1383.69	79.7069
1386.85	79.5715
1390.02	81.6893
1393.18	81.7828
1396.34	83.1254
1399.5	85.7526
1402.65	89.9195
1405.81	93.6463
1408.97	98.7942
1412.12	105.454
1415.27	111.677
1418.43	119.238
1421.58	126.4
1424.73	134.619
1427.87	140.68
1431.02	147.116
1434.17	153.556
1437.31	158.535
1440.46	161.906
1443.6	164.439
1446.74	161.879
1449.88	161.65
1453.02	157.855
1456.16	153.433
1459.29	145.686
1462.43	137.765
1465.56	128.199
1468.69	120.979
1471.83	110.873
1474.95	101.093
1478.08	91.5108
1481.21	83.0609
1484.34	75.091
1487.47	68.7704
1490.59	60.2902
1493.71	50.9118
1496.84	43.4616
1499.96	37.8332
1503.07	32.9596
1506.19	27.9277
1509.31	25.3435
1512.43	21.6505
1515.54	19.4737
1518.65	17.242
1521.77	15.8939
1524.88	15.2649
1527.99	16.1344
1531.1	17.2513
1534.21	19.3314
1537.31	20.3541
1540.42	23.4381
1543.52	27.6472
1546.63	31.0347
1549.73	35.6337
1552.83	39.846
1555.93	42.5047
1559.03	46.7053
1562.12	50.6608
1565.22	53.9131
1568.31	55.4451
1571.41	59.9181
1574.5	63.9137
1577.59	70.1095
1580.68	77.2348
1583.77	81.6788
1586.86	84.9664
1589.95	87.6767
1593.03	90.0595
1596.11	92.3116
1599.2	95.5314
1602.28	99.5911
1605.36	100.063
1608.44	100.374
1611.52	100.661
1614.6	100.388
1617.67	98.4369
1620.75	98.2789
1623.82	97.3404
1626.89	95.9015
1629.96	94.378
1633.04	92.2639
1636.11	91.5435
1639.17	91.1951
1642.24	90.2885
1645.31	89.3972
1648.37	88.4433
1651.43	89.0667
1654.5	87.6765
1657.56	85.8853
1660.62	79.5814
1663.67	75.7509
1666.73	72.4331
1669.79	68.3526
1672.84	66.6643
1675.9	63.0835
1678.95	59.5716
1682	54.3129
1685.05	50.9747
1688.1	48.7688
1691.15	44.9789
1694.2	42.3501
1697.25	38.9484
1700.29	35.7116
1703.33	32.2781
1706.38	31.5229
1709.42	28.6865
1712.46	27.7923
1715.5	26.6891
1718.54	25.9392
1721.57	24.5632
1724.61	24.1761
1727.64	23.329
1730.68	21.2651
1733.71	18.3862
1736.74	16.4639
1739.77	17.6824
1742.8	17.1094
1745.83	16.8804
1748.85	17.034
1751.88	17.1729
1754.91	15.6864
1757.93	14.265
1760.95	13.5311
1763.97	12.8313
1766.99	12.0155
1770.01	9.62096
1773.03	7.80804
1776.04	6.28895
1779.06	4.88808
1782.07	4.05792
1785.09	2.86312
1788.1	2.55371
1791.11	2.91508
1794.12	1.68919
1797.13	0.963632
1800.13	0.767167
1803.14	0.553572
1806.15	-0.436394
1809.15	0.115747
1812.15	1.11116
1815.16	3.68988
1818.15	3.70188
1821.16	3.58871
1824.15	3.86511
1827.15	4.08027
1830.15	2.94688
1833.14	3.83419
1836.14	4.49974
1839.13	5.11291
1842.12	3.58002
1845.11	2.66796
1848.1	1.62943
1851.09	0.538672
1854.08	1.59052
1857.06	1.86322
1860.05	2.83642
1863.03	4.3971
1866.01	3.49862
1869	2.74993
1871.98	3.2109
1874.96	4.07263
1877.93	4.82714
1880.91	4.75276
1882.47	5.14834
1885.46	5.96038
1888.44	7.03609
1891.43	7.14549
1894.42	6.82676
1897.4	7.30394
1900.39	7.79198
1903.37	8.44648
1906.35	8.59882
1909.33	8.11573
1912.31	6.65855
1915.29	6.21882
1918.26	6.66525
1921.24	8.26271
1924.21	8.71462
1927.19	11.2135
1930.16	10.2034
1933.13	10.8371
1936.1	11.413
1939.07	10.23
1942.04	11.4336
1945	12.9411
1947.97	12.475
1950.93	12.3874
1953.9	12.5807
1956.86	12.959
1959.82	12.3267
1962.78	11.9566
1965.74	10.284
1968.7	9.67365
1971.65	9.95949
1974.61	9.43712
1977.57	9.29113
1980.52	8.4732
1983.47	8.67285
1986.42	8.49086
1989.37	9.73015
1992.32	9.0313
1995.27	9.46935
1998.22	10.3611
2001.17	10.0623
2004.11	10.7312
2007.05	11.3363
2010	12.3488
2012.94	12.4584
2015.88	13.1244
2018.82	11.4484
2021.76	11.1542
2024.7	11.4419
2027.63	11.1003
2030.57	11.4425
2033.5	10.1803
2036.44	10.9918
2039.37	10.1626
2042.3	11.1402
2045.23	10.8352
2048.16	10.1647
2051.08	9.84889
2054.01	9.31107
2056.94	9.21433
2059.86	9.24881
2062.79	9.60404
2065.71	10.9121
2068.63	12.2363
2071.55	13.9416
2074.47	13.9179
2077.39	14.9908
2080.31	15.9055
2083.22	15.9384
2086.13	17.4291
2089.05	17.9395
2091.96	18.3849
2094.87	19.9314
2097.78	23.8006
2100.69	25.4544
2103.6	26.5357
2106.51	28.5093
2109.42	29.8083
2112.32	30.8145
2115.23	31.1683
2118.13	32.4603
2121.03	34.1958
2123.93	34.6865
2126.83	37.3756
2129.73	38.9181
2132.63	41.7842
2135.53	44.049
2138.42	46.9983
2141.32	49.4381
2144.21	50.9585
2147.1	53.0642
2150	55.5126
2152.89	56.6071
2155.78	59.2672
2158.66	60.4083
2161.55	62.0821
2164.44	63.72
2167.32	65.1988
2170.21	63.6612
2173.09	62.9359
2175.97	63.1975
2178.85	63.0475
2181.73	63.1459
2184.61	60.7648
2187.49	59.0366
2190.37	57.744
2193.24	54.6637
2196.12	52.0782
2198.99	49.4641
2201.87	46.4572
2204.74	44.0556
2207.61	42.3431
2210.48	39.5851
2213.35	36.0906
2216.21	33.8642
2219.08	31.8085
2221.95	29.4824
2224.81	30.2385
2227.67	29.1702
2230.54	27.2237
2233.4	24.5703
2236.26	23.9235
2239.11	21.2203
2241.97	19.6543
2244.83	19.3189
2247.69	19.5786
2250.54	19.8728
2253.4	18.5876
2256.25	18.4106
2259.1	16.6095
2261.95	15.371
2264.8	13.9804
2267.65	11.923
2270.5	11.563
2273.34	10.876
2276.19	10.0948
2279.03	10.8258
2281.88	9.64491
2284.72	9.00559
2287.56	9.26797
2290.4	9.35783
2293.24	10.7071
2296.08	10.415
2298.92	10.1981
2301.76	9.82348
2304.59	10.3982
2307.43	11.5884
2310.26	11.9821
2313.09	12.6407
2315.92	13.0096
2318.75	12.8757
2321.58	11.3239
2324.41	10.0947
2327.24	8.43693
2330.06	6.55802
2332.89	6.97704
2335.71	5.48382
2338.54	5.35434
2341.36	4.76678
2344.18	3.9885
2347	3.365
2349.82	4.33828
2352.64	2.83876
2355.45	2.13048
2358.27	1.85625
2361.08	1.71183
2363.9	3.79603
2366.71	4.77323
2369.52	5.91864
2372.33	5.48618
2375.14	6.95267
2377.95	6.23632
2380.76	5.76108
2383.57	5.70392
2386.37	5.27909
2389.18	5.72077
2391.98	6.05252
2394.79	6.18572
2397.59	7.20533
2400.39	8.16467
2403.19	8.58184
2405.99	6.87766
2408.78	8.73208
2411.58	9.99251
2414.38	10.4323
2417.17	11.2811
2419.97	12.4254
2422.76	12.1506
2425.55	11.5487
2428.34	11.6187
2431.13	11.9318
2433.92	10.5181
2436.71	9.74491
2439.49	8.86685
2442.28	6.48265
2445.06	5.62211
2447.85	5.82654
2450.63	6.34098
2453.41	7.13001
2456.19	5.66444
2458.97	5.78225
2461.75	6.58343
2464.53	5.5281
2467.31	4.03026
2470.08	2.88557
2472.86	2.20946
2475.63	2.94242
2478.4	3.89544
2481.17	3.87761
2483.94	4.91356
2486.72	3.52225
2489.48	3.3022
2492.25	2.00639
2495.02	1.27845
2497.79	1.33768
2500.55	0.873581
2503.31	0.382952
2506.08	-0.303675
2508.84	0.782301
2511.6	1.22505
2514.36	2.64353
2517.12	3.72887
2519.88	4.28166
2522.63	4.85092
2525.39	4.99265
2528.14	5.83999
2530.9	4.9888
2533.65	5.02355
2536.4	6.16553
2539.15	5.81724
2541.9	5.42532
2544.65	5.2421
2547.4	6.04832
2550.15	6.87578
2552.89	6.05043
2555.64	6.37094
2558.38	5.82515
2561.12	5.11387
2563.87	4.93439
2566.61	5.42928
2569.35	6.15663
2572.09	4.9395
2574.83	5.14838
2577.56	5.79103
2580.3	6.17639
2583.04	6.01859
2585.77	7.63289
2588.5	6.92479
2591.23	6.1545
2593.97	6.12535
2596.7	5.94048
2599.43	6.09093
2602.15	4.99853
2604.88	5.28128
2607.61	4.57951
2610.33	4.74503
2613.06	5.15534
2615.78	4.46233
2618.51	5.00561
2621.23	4.23641
2623.95	4.15225
2626.67	3.4156
2629.39	3.68277
2632.1	3.60163
2634.82	2.74673
2637.54	2.22601
2640.25	2.20405
2642.97	2.53995
2645.68	2.89425
2648.39	2.92012
2651.1	3.30205
2653.81	3.28629
2656.52	3.4139
2659.23	4.02143
2661.94	4.05885
2664.64	4.25344
2667.35	5.09066
2670.05	6.2102
2672.76	8.22266
2675.46	8.50897
2678.16	9.22938
2680.86	10.6826
2683.56	9.93481
2686.26	10.6964
2688.96	10.9963
2691.65	10.7455
2694.35	9.99247
2697.04	10.3465
2699.74	10.2096
2702.43	10.251
2705.12	11.4583
2707.81	10.6705
2710.5	10.6632
2713.19	11.1517
2715.88	10.6632
2718.57	10.2273
2721.25	9.97445
2723.94	10.0522
2726.62	10.2554
2729.3	10.333
2731.99	9.95934
2734.67	10.2645
2737.35	11.2173
2740.03	10.0414
2742.71	9.07146
2745.38	9.07432
2748.06	9.57997
2750.74	8.60484
2753.41	7.07341
2756.09	6.35363
2758.76	6.18663
2761.43	6.01367
2764.1	5.80297
2766.77	5.3593
2769.44	4.27558
2772.11	3.25784
2774.77	1.88848
2777.44	2.41928
2780.11	2.01428
2782.77	3.26069
2785.43	2.61396
2788.1	2.41903
2790.76	3.05849
2793.42	3.81059
2796.08	3.04155
2798.74	1.41498
2801.4	1.74691
2804.05	1.30803
2806.71	0.668672
2809.36	1.2953
2812.02	1.24807
2814.67	1.8866
2817.32	3.40061
2819.97	4.37048
2822.62	9.62998
2825.27	14.3881
2827.92	20.318
2830.57	28.2462
2833.22	36.0345
2835.86	44.634
2838.51	54.3758
2841.15	66.4682
2843.79	78.7773
2846.43	90.8211
2849.08	102.694
2851.72	115.455
2854.36	129.668
2856.99	141.007
2859.63	152.998
2862.27	164.443
2864.9	174.894
2867.54	184.322
2870.17	193.624
2872.8	202.505
2875.43	210.231
2878.07	218.198
2880.7	224.735
2883.32	232.556
2885.95	242.462
2888.58	251.371
2891.21	260.353
2893.83	271.473
2896.46	281.547
2899.08	292.521
2901.7	303.987
2904.32	317.277
2906.94	330.438
2909.56	345.122
2912.18	359.699
2914.8	374.246
2917.42	386.286
2920.03	396.12
2922.65	404.277
2925.26	410.246
2927.88	413.597
2930.49	413.081
2933.1	410.886
2935.71	405.823
2938.32	395.745
2940.93	382.929
2943.54	367.913
2946.14	352.302
2948.75	334.875
2951.35	316.576
2953.96	297.98
2956.56	281.019
2959.16	263.21
2961.77	245.715
2964.37	229.737
2966.96	216.25
2969.56	203.493
2972.16	191.961
2974.76	181.878
2977.35	171.636
2979.95	161.042
2982.54	150.931
2985.14	140.226
2987.73	130.849
2990.32	121.846
2992.91	112.609
2995.5	102.089
2998.09	92.5044
3000.68	81.2861
3003.26	71.2603
3005.85	62.8
3008.43	52.8079
3011.02	43.9387
3013.6	35.8392
3016.19	29.0642
3018.77	23.3675
3021.35	18.7845
3023.93	14.0205
3026.5	10.0508
3029.08	6.97786
3031.66	4.2693
3034.24	2.28629
3036.81	0.461763
3039.39	0.306043
3041.96	-0.220838
3044.53	-0.399317
3047.1	-0.101397
3049.67	0.677212
3052.24	1.51907
3054.81	2.06257
3057.38	2.2406
3059.95	1.78725
3062.52	1.92844
3065.08	3.20903
3067.65	3.50824
3070.21	3.52549
3072.77	3.83093
3075.33	4.09812
3077.89	5.22751
3080.45	5.10682
3083.01	5.75791
3085.57	5.46056
3088.13	4.55977
3090.68	5.66759
3093.24	6.39477
3095.79	6.99428
3098.35	7.5404
3100.9	8.14043
3103.45	9.44607
3106	10.636
3108.55	12.2729
3111.1	13.8043
3113.65	15.3223
3116.2	17.7453
3118.75	19.9021
3121.29	21.6646
3123.84	25.3114
3126.38	28.2531
3128.92	32.045
3131.47	35.7664
3134.01	40.0334
3136.55	43.3191
3139.09	47.5181
3141.63	51.1374
3144.17	54.9387
3146.7	59.2215
3149.24	62.4101