File: data/Raman/poly_smoothed/Mb_40_24_46_1x_45s_532 nm_x100_100%_600 gr_mm_01.txt
#Acq. time (s)=	45
#Accumulations=	2
#Range (cm-¹)=	200...3150
#Windows=	2
#Auto scanning=	Off
#Autofocus=	Off
#Macrospot=	Off
#AutoExposure=	Off
#Spike filter=	Multiple accum.
#Delay time (s)=	0
#Binning=	1
#Readout mode=	Signal
#DeNoise=	Off
#ICS correction=	On
#Dark correction=	Off
#Inst. Process=	Off
#Detector Gain=	Best Dynamic Range
#Detector ADC=	20 kHz
#Detector temperature (°C)=	-70.08
#Instrument=	LabRAM HR Evol
#Detector=	Synapse
#Objective=	x100
#Grating=	600 gr/mm
#ND Filter=	100%
#Laser (nm)=	532
#Hole=	100.021
#Range=	Auto
#Laser Pol.=	No
#Raman. Pol.=	No
#Laser Pol. (°)=	-0.0007625
#Raman Pol. (°)=	89.9995
#Collection=	Microscope
#StageXY=	Marzhauser
#StageZ=	Marzhauser
#X (µm)=	-2462.3
#Y (µm)=	-29.2
#Z (µm)=	-10.25
#Full time(mm:ss)=	3:18
#Project=
#Sample=
#Site=
#Title=	Mb_40_24_46_2x_45s_532 nm_x100_100%_600 gr_mm
#Remark=
#Date=	14.07.2022 14:16
#Acquired=	14.07.2022 14:16:06
#Base:Fit=	10.08.2022 10:47:00
#Base:Sub=	10.08.2022 10:47:12
#Filter:Polynom=	16.08.2022 10:11:48
#AxisType[0]=Intens
#AxisUnit[0]=Cnt
#AxisType[1]=Spectr
#AxisUnit[1]=1/cm
200.554	44.8926
204.183	41.2019
207.813	35.7189
211.439	29.4902
215.065	25.92
218.688	22.1933
222.312	21.2419
225.933	19.455
229.552	16.2243
233.171	15.0893
236.787	14.4226
240.402	12.9599
244.015	12.2173
247.627	12.1885
251.24	13.619
254.849	11.4594
258.457	9.93841
262.063	10.6921
265.668	11.4657
269.271	12.1109
272.873	13.3305
276.474	14.2935
280.073	13.7066
283.671	11.4572
287.268	11.5596
290.863	9.91574
294.456	10.6268
298.049	11.6966
301.637	13.613
305.227	14.0728
308.815	13.5266
312.402	14.1031
315.987	12.0897
319.569	13.1774
323.151	12.5022
326.733	12.9859
330.31	14.4528
333.889	15.3807
337.464	16.7396
341.039	17.2117
344.611	17.1163
348.184	17.8823
351.754	18.4821
355.324	16.6213
358.89	15.0841
362.455	14.999
366.021	13.7234
369.584	10.8516
373.145	9.6022
376.707	8.87799
380.265	7.96216
383.822	7.9635
387.378	6.23687
390.934	4.2954
394.487	4.86663
398.038	3.57053
401.588	3.17098
405.137	1.738
408.685	2.72045
412.23	3.31743
415.775	4.0712
419.318	5.63845
422.86	6.34916
426.401	6.93494
429.94	6.10008
433.478	6.90644
437.012	6.70134
440.547	6.37935
444.081	6.25067
447.613	5.10691
451.142	6.10748
454.672	5.09543
458.2	4.42672
461.725	4.23809
465.251	5.35774
468.775	6.15606
472.296	8.03749
475.817	7.90001
479.335	9.71781
482.854	12.5619
486.37	12.1115
489.886	14.5079
493.398	16.3621
496.91	18.8531
500.422	19.148
503.93	20.4232
507.438	22.1459
510.946	23.368
514.45	23.1098
517.954	21.9922
521.456	21.4131
524.956	22.3597
528.456	23.0501
531.956	21.6899
535.452	20.6171
538.947	20.4584
542.441	19.0862
545.934	18.8587
549.425	18.6437
552.915	17.9621
556.403	16.3297
559.889	14.6817
563.375	14.7388
566.859	15.1849
570.342	15.3152
573.824	15.0583
577.303	14.0926
580.782	12.2846
584.26	8.84047
587.734	9.80476
591.21	9.04531
594.684	8.08809
598.154	5.9086
601.626	6.50569
605.094	5.67725
608.562	5.57366
612.027	5.82442
615.493	5.47963
618.956	6.01401
622.419	6.27247
625.879	6.14618
629.338	6.80218
632.797	6.23359
636.254	5.06869
639.708	4.9054
643.162	5.36487
646.614	7.25093
650.067	7.8312
653.516	8.73903
656.964	12.7239
660.411	12.5983
663.857	11.1254
667.301	12.7292
670.744	14.6182
674.186	14.8772
677.626	14.8636
681.065	14.2016
684.503	15.1105
687.939	16.1421
691.372	16.7108
694.806	19.004
698.239	18.6777
701.67	17.0732
705.098	19.0163
708.526	18.1229
711.954	18.5432
715.378	18.1904
718.802	16.6109
722.226	17.109
725.646	17.9336
729.067	19.2089
732.484	22.1112
735.902	23.4151
739.317	26.4453
742.731	28.243
746.145	28.2462
749.556	31.797
752.966	34.2827
756.377	35.6388
759.784	39.1655
763.19	40.6083
766.594	45.2541
770	48.0523
773.402	53.0713
776.803	54.7235
780.202	56.1099
783.6	56.4126
786.997	59.2477
790.393	60.6683
793.787	59.2344
797.18	59.5936
800.572	58.9188
803.963	59.5578
807.35	60.3021
810.738	61.4723
814.125	60.9773
817.51	62.6008
820.894	64.5855
824.275	65.6067
827.657	67.9428
831.037	69.0607
834.414	68.7437
837.792	68.644
841.167	68.2638
844.542	69.2381
847.914	68.8102
851.287	69.8149
854.656	68.3656
858.026	66.5429
861.393	62.4922
864.761	61.1954
868.125	59.9424
871.489	55.7847
874.85	52.0865
878.213	47.8978
881.572	44.0377
884.931	42.7931
888.287	38.8576
891.643	36.8509
894.997	34.7426
898.352	33.4852
901.704	34.7841
905.055	33.4128
908.404	33.6149
911.75	33.3116
915.097	30.67
918.443	30.7927
921.787	31.86
925.13	32.2771
928.472	31.8187
931.813	30.8266
935.15	32.3963
938.488	31.4458
941.825	30.4065
945.158	29.3937
948.493	29.6927
951.824	27.6811
955.156	25.7449
958.486	23.6139
961.814	22.5962
965.142	22.5344
968.467	21.4022
971.79	19.0926
975.115	20.3374
978.436	19.5484
981.756	19.5274
985.077	18.1306
988.394	16.0073
991.71	16.3803
995.025	16.3646
998.341	14.2075
1001.65	14.2211
1004.97	12.8815
1008.28	11.1678
1011.58	11.2366
1014.89	13.5752
1018.2	14.2978
1021.5	17.6399
1024.81	18.924
1028.11	22.7957
1031.41	25.2967
1034.71	27.2348
1038.01	28.4236
1041.31	31.0501
1044.6	31.7722
1047.9	33.2667
1051.19	31.9528
1054.48	34.304
1057.77	34.1073
1061.06	33.0767
1064.35	31.7092
1067.64	29.9531
1070.93	28.7398
1074.21	27.0503
1077.49	22.8406
1080.78	19.5327
1084.06	17.443
1087.34	14.9775
1090.61	13.9844
1093.89	14.4884
1097.17	12.6688
1100.44	13.1805
1103.71	13.6367
1106.99	11.9528
1110.26	12.83
1113.52	11.3368
1116.79	10.2745
1120.06	9.30505
1123.32	8.19532
1126.59	6.8297
1129.85	6.21559
1133.11	6.88664
1136.37	6.88542
1139.63	7.88319
1142.89	8.55305
1146.15	7.90999
1149.4	6.65989
1152.66	4.94904
1155.91	4.63189
1159.16	4.02033
1162.41	2.5647
1165.66	4.00773
1168.91	3.7797
1172.16	4.99162
1175.4	6.29896
1178.65	6.89739
1181.89	8.2866
1185.13	6.46201
1188.37	4.38422
1191.61	6.85196
1194.85	6.46152
1198.08	7.68957
1201.32	8.11426
1204.55	9.20542
1207.79	9.02521
1211.02	10.9765
1214.25	12.9011
1217.48	15.0357
1220.71	17.7736
1223.93	20.2912
1227.16	22.2578
1230.38	23.2547
1233.6	25.8393
1236.83	26.7414
1240.05	28.8298
1243.26	30.1479
1246.48	33.7207
1249.7	35.5416
1252.92	37.6163
1256.13	38.5202
1259.34	39.2175
1262.55	39.9737
1265.76	41.5973
1268.97	43.8038
1272.18	45.5635
1275.39	47.3063
1278.59	49.932
1281.8	52.4282
1285	54.2816
1288.2	59.1559
1291.4	61.7646
1294.6	65.6624
1297.8	67.8309
1301	69.0496
1304.19	71.6767
1307.39	72.4094
1310.58	73.4311
1313.77	73.5436
1316.96	72.0625
1320.15	71.4698
1323.34	71.0408
1326.53	71.196
1329.72	70.877
1332.9	68.6692
1336.08	67.5772
1339.27	64.7523
1342.45	64.541
1345.63	63.6331
1348.8	61.118
1351.98	61.6906
1355.16	62.0384
1358.33	62.0636
1361.51	63.4565
1364.68	62.4713
1367.85	61.6329
1371.02	61.2826
1374.19	60.2634
1377.36	58.8322
1380.52	60.0342
1383.69	59.169
1386.85	57.7755
1390.02	55.4803
1393.18	55.6877
1396.34	54.3438
1399.5	54.457
1402.65	56.136
1405.81	57.0953
1408.97	60.8288
1412.12	63.8118
1415.27	68.4825
1418.43	75.2659
1421.58	80.7688
1424.73	88.217
1427.87	95.7892
1431.02	103.141
1434.17	106.977
1437.31	112.455
1440.46	115.055
1443.6	118.048
1446.74	118.537
1449.88	119.838
1453.02	120.058
1456.16	118.423
1459.29	115.483
1462.43	111.078
1465.56	105.895
1468.69	98.9583
1471.83	91.8167
1474.95	83.7211
1478.08	79.4161
1481.21	73.2409
1484.34	66.0721
1487.47	60.5616
1490.59	55.0853
1493.71	50.8528
1496.84	46.7269
1499.96	44.4006
1503.07	40.5387
1506.19	37.1604
1509.31	33.2435
1512.43	29.276
1515.54	26.2728
1518.65	26.2146
1521.77	26.1562
1524.88	27.0145
1527.99	28.8571
1531.1	29.4467
1534.21	29
1537.31	30.9614
1540.42	31.7843
1543.52	32.5225
1546.63	34.3019
1549.73	35.9466
1552.83	37.8432
1555.93	40.523
1559.03	40.7754
1562.12	43.33
1565.22	45.0293
1568.31	47.7708
1571.41	51.7598
1574.5	55.2208
1577.59	57.5755
1580.68	60.288
1583.77	64.3637
1586.86	65.9005
1589.95	68.1138
1593.03	71.6676
1596.11	73.9419
1599.2	74.7155
1602.28	74.8574
1605.36	74.0535
1608.44	73.8019
1611.52	73.6377
1614.6	73.7985
1617.67	74.1863
1620.75	74.6085
1623.82	74.6728
1626.89	73.0642
1629.96	73.791
1633.04	74.7531
1636.11	73.995
1639.17	74.5027
1642.24	75.0612
1645.31	73.8525
1648.37	73.287
1651.43	72.0525
1654.5	70.0655
1657.56	69.1937
1660.62	66.6516
1663.67	63.3084
1666.73	60.6771
1669.79	56.3731
1672.84	51.7256
1675.9	47.7319
1678.95	42.7845
1682	38.6243
1685.05	36.5627
1688.1	33.5206
1691.15	31.0533
1694.2	28.7625
1697.25	27.1208
1700.29	24.5503
1703.33	23.8648
1706.38	24.0412
1709.42	23.7218
1712.46	23.1243
1715.5	21.642
1718.54	20.9518
1721.57	20.0582
1724.61	20.7067
1727.64	19.8047
1730.68	19.6674
1733.71	19.4063
1736.74	17.8543
1739.77	16.8677
1742.8	15.8236
1745.83	14.6565
1748.85	13.234
1751.88	12.0412
1754.91	9.73608
1757.93	8.28111
1760.95	6.93538
1763.97	4.73601
1766.99	3.66317
1770.01	2.24931
1773.03	1.18534
1776.04	1.92493
1779.06	2.11406
1782.07	2.64699
1785.09	1.90568
1788.1	1.92155
1791.11	1.37695
1794.12	1.73869
1797.13	1.31222
1800.13	1.79638
1803.14	1.90583
1806.15	2.85224
1809.15	2.25268
1812.15	3.47357
1815.16	2.89897
1818.15	2.65277
1821.16	2.42206
1824.15	1.30089
1827.15	1.22714
1830.15	1.04456
1833.14	0.296731
1836.14	0.742917
1839.13	0.612398
1842.12	1.04772
1845.11	1.4331
1848.1	2.76799
1851.09	3.66753
1854.08	2.89915
1857.06	3.73945
1860.05	4.28769
1863.03	4.19956
1866.01	3.83567
1869	2.67698
1871.98	3.75235
1874.96	5.25784
1877.93	4.35873
1880.91	4.46706
1882.47	5.5702
1885.46	4.91193
1888.44	5.19643
1891.43	6.17747
1894.42	6.54113
1897.4	6.67316
1900.39	7.76026
1903.37	7.27619
1906.35	7.80092
1909.33	8.04564
1912.31	7.87399
1915.29	8.27956
1918.26	8.11344
1921.24	8.53036
1924.21	7.79626
1927.19	8.2219
1930.16	8.36171
1933.13	7.89289
1936.1	6.38298
1939.07	5.83863
1942.04	5.53473
1945	6.33364
1947.97	6.45034
1950.93	7.57533
1953.9	8.28872
1956.86	8.25555
1959.82	9.35309
1962.78	9.73204
1965.74	8.37754
1968.7	7.69619
1971.65	9.07358
1974.61	9.69906
1977.57	10.6263
1980.52	10.5086
1983.47	9.62844
1986.42	9.65742
1989.37	8.91717
1992.32	8.57749
1995.27	8.17704
1998.22	7.56016
2001.17	7.45277
2004.11	7.16968
2007.05	7.52151
2010	9.18844
2012.94	9.90729
2015.88	10.2235
2018.82	11.4982
2021.76	12.499
2024.7	12.9383
2027.63	13.5573
2030.57	13.2884
2033.5	13.3602
2036.44	13.8034
2039.37	14.1118
2042.3	15.9545
2045.23	17.3475
2048.16	18.1412
2051.08	17.3194
2054.01	17.5082
2056.94	17.6203
2059.86	17.5251
2062.79	17.9312
2065.71	18.7464
2068.63	19.2193
2071.55	19.979
2074.47	20.5541
2077.39	21.2839
2080.31	22.5543
2083.22	22.8654
2086.13	22.7483
2089.05	23.5584
2091.96	25.8663
2094.87	27.0062
2097.78	28.1975
2100.69	28.8923
2103.6	30.4817
2106.51	31.7524
2109.42	32.5735
2112.32	32.8608
2115.23	34.342
2118.13	35.455
2121.03	36.9819
2123.93	40.5787
2126.83	42.2438
2129.73	43.8068
2132.63	45.5838
2135.53	48.4093
2138.42	51.2029
2141.32	53.9284
2144.21	55.7701
2147.1	58.3181
2150	60.9054
2152.89	63.1063
2155.78	66.2427
2158.66	69.1152
2161.55	70.6713
2164.44	73.2411
2167.32	73.6337
2170.21	73.7875
2173.09	74.7105
2175.97	73.9652
2178.85	72.2101
2181.73	70.5876
2184.61	69.5998
2187.49	66.7382
2190.37	65.7206
2193.24	63.1228
2196.12	59.0886
2198.99	55.9142
2201.87	52.5421
2204.74	50.1934
2207.61	48.2015
2210.48	46.4725
2213.35	44.315
2216.21	41.243
2219.08	40.1599
2221.95	38.2834
2224.81	36.9792
2227.67	35.0567
2230.54	34.0359
2233.4	31.9498
2236.26	30.4603
2239.11	30.4834
2241.97	30.8812
2244.83	29.7762
2247.69	28.3792
2250.54	28.0512
2253.4	26.8086
2256.25	25.2119
2259.1	23.4148
2261.95	21.7286
2264.8	19.544
2267.65	18.7957
2270.5	17.9738
2273.34	17.6521
2276.19	17.0179
2279.03	16.7614
2281.88	16.8488
2284.72	15.6081
2287.56	15.546
2290.4	14.2951
2293.24	13.1244
2296.08	12.578
2298.92	12.6878
2301.76	12.7494
2304.59	12.6717
2307.43	12.9532
2310.26	13.0121
2313.09	12.0397
2315.92	11.9423
2318.75	12.2354
2321.58	12.025
2324.41	11.5283
2327.24	10.0831
2330.06	10.425
2332.89	9.45935
2335.71	9.92808
2338.54	10.4762
2341.36	10.1572
2344.18	8.62527
2347	9.11352
2349.82	7.92421
2352.64	7.45866
2355.45	5.78437
2358.27	4.1104
2361.08	4.1244
2363.9	4.62721
2366.71	5.07693
2369.52	4.27337
2372.33	4.49245
2375.14	4.1186
2377.95	3.9508
2380.76	5.50594
2383.57	6.35009
2386.37	7.38902
2389.18	7.95414
2391.98	7.06459
2394.79	6.54565
2397.59	6.72668
2400.39	7.92527
2403.19	8.3416
2405.99	8.1937
2408.78	7.51153
2411.58	7.20401
2414.38	6.16289
2417.17	6.02752
2419.97	4.91676
2422.76	4.09676
2425.55	3.0965
2428.34	3.10171
2431.13	3.53212
2433.92	3.85481
2436.71	3.25943
2439.49	2.98632
2442.28	2.87544
2445.06	3.7714
2447.85	4.44777
2450.63	4.58947
2453.41	5.04859
2456.19	5.4893
2458.97	5.15729
2461.75	4.45947
2464.53	5.00873
2467.31	5.64485
2470.08	6.23771
2472.86	6.17679
2475.63	5.63668
2478.4	5.21377
2481.17	4.8048
2483.94	4.57654
2486.72	4.19288
2489.48	2.50187
2492.25	2.04952
2495.02	1.24196
2497.79	1.17454
2500.55	1.69139
2503.31	0.831888
2506.08	0.265537
2508.84	0.697394
2511.6	0.260147
2514.36	0.809419
2517.12	1.30219
2519.88	1.88234
2522.63	1.52719
2525.39	0.622313
2528.14	0.572726
2530.9	0.689001
2533.65	1.61321
2536.4	1.66087
2539.15	2.68824
2541.9	2.29805
2544.65	2.1767
2547.4	2.80943
2550.15	3.02368
2552.89	3.56845
2555.64	4.91257
2558.38	5.69475
2561.12	5.57248
2563.87	6.246
2566.61	8.223
2569.35	7.92
2572.09	8.13327
2574.83	7.40616
2577.56	6.051
2580.3	6.06528
2583.04	5.88435
2585.77	6.69942
2588.5	4.79201
2591.23	4.81775
2593.97	5.09302
2596.7	4.84392
2599.43	4.04689
2602.15	3.15162
2604.88	2.51151
2607.61	1.69387
2610.33	1.54065
2613.06	1.31576
2615.78	0.0505853
2618.51	0.991929
2621.23	0.86465
2623.95	1.81159
2626.67	2.43664
2629.39	2.85351
2632.1	4.25283
2634.82	4.57885
2637.54	4.60788
2640.25	4.6786
2642.97	5.38803
2645.68	6.09086
2648.39	6.70575
2651.1	6.88235
2653.81	7.66974
2656.52	6.72295
2659.23	6.45079
2661.94	6.24395
2664.64	5.8678
2667.35	6.28826
2670.05	5.73683
2672.76	5.65426
2675.46	4.73497
2678.16	4.28718
2680.86	4.53349
2683.56	4.73523
2686.26	6.31752
2688.96	6.27761
2691.65	7.68737
2694.35	8.12665
2697.04	9.15716
2699.74	10.0505
2702.43	10.8971
2705.12	11.3805
2707.81	11.8773
2710.5	13.4062
2713.19	13.1624
2715.88	14.6732
2718.57	15.5258
2721.25	15.1134
2723.94	15.0027
2726.62	15.557
2729.3	15.2103
2731.99	16.7572
2734.67	15.3858
2737.35	15.2402
2740.03	15.5441
2742.71	14.9677
2745.38	15.0485
2748.06	14.9351
2750.74	14.0854
2753.41	12.7496
2756.09	11.8229
2758.76	11.4945
2761.43	9.86594
2764.1	8.67951
2766.77	7.8878
2769.44	6.9824
2772.11	5.10431
2774.77	5.18614
2777.44	4.60033
2780.11	4.04152
2782.77	4.28647
2785.43	2.95814
2788.1	1.69142
2790.76	1.73663
2793.42	2.43042
2796.08	2.45975
2798.74	2.74846
2801.4	3.39817
2804.05	3.74505
2806.71	4.92234
2809.36	5.06597
2812.02	4.91396
2814.67	5.26163
2817.32	7.5453
2819.97	9.35458
2822.62	12.427
2825.27	15.9931
2827.92	21.7464
2830.57	29.1869
2833.22	35.7877
2835.86	43.6876
2838.51	51.251
2841.15	60.1762
2843.79	69.0322
2846.43	80.0498
2849.08	90.3689
2851.72	100.215
2854.36	111.443
2856.99	122.112
2859.63	130.443
2862.27	138.909
2864.9	146.589
2867.54	154
2870.17	161.134
2872.8	166.564
2875.43	171.158
2878.07	176.536
2880.7	183.509
2883.32	189.788
2885.95	197.327
2888.58	204.543
2891.21	211.115
2893.83	217.85
2896.46	226.026
2899.08	233.624
2901.7	242.582
2904.32	252.582
2906.94	262.143
2909.56	273.046
2912.18	283.618
2914.8	292.603
2917.42	302.512
2920.03	310.04
2922.65	315.081
2925.26	319.654
2927.88	321.743
2930.49	321.897
2933.1	320.017
2935.71	316.112
2938.32	310.129
2940.93	302.098
2943.54	294.012
2946.14	285.36
2948.75	274.936
2951.35	263.401
2953.96	250.014
2956.56	237.981
2959.16	226.84
2961.77	215.586
2964.37	204.016
2966.96	193.191
2969.56	183.439
2972.16	173.017
2974.76	163.631
2977.35	153.96
2979.95	144.92
2982.54	135.417
2985.14	125.982
2987.73	115.271
2990.32	104.517
2992.91	94.3649
2995.5	84.7294
2998.09	75.393
3000.68	65.8317
3003.26	57.392
3005.85	50.3289
3008.43	43.6101
3011.02	36.978
3013.6	30.9679
3016.19	25.2695
3018.77	20.5534
3021.35	16.172
3023.93	13.0315
3026.5	9.6018
3029.08	6.65248
3031.66	4.98083
3034.24	2.96387
3036.81	1.54575
3039.39	1.05601
3041.96	-0.0373324
3044.53	0.311362
3047.1	0.144404
3049.67	-0.0888309
3052.24	-0.687931
3054.81	0.238486
3057.38	1.58682
3059.95	2.11043
3062.52	2.57903
3065.08	2.7746
3067.65	3.71926
3070.21	3.50362
3072.77	3.51489
3075.33	3.54801
3077.89	3.50237
3080.45	2.1546
3083.01	2.09745
3085.57	1.79379
3088.13	0.681802
3090.68	0.0838584
3093.24	0.14793
3095.79	-0.142951
3098.35	0.381039
3100.9	1.51799
3103.45	2.27976
3106	2.82087
3108.55	3.3575
3111.1	3.59676
3113.65	5.4757
3116.2	5.92658
3118.75	6.92511
3121.29	8.05812
3123.84	8.82504
3126.38	10.3422
3128.92	11.2717
3131.47	12.8371
3134.01	14.1204
3136.55	14.9048
3139.09	15.4674
3141.63	15.9546
3144.17	16.3865
3146.7	17.3325
3149.24	18.4967