File: data/Raman/poly_smoothed/Mb_40_y_18_1x_45s_532 nm_x100_100%_600 gr_mm_01.txt
#Acq. time (s)=	45
#Accumulations=	2
#Range (cm-¹)=	200...3150
#Windows=	2
#Auto scanning=	Off
#Autofocus=	Off
#Macrospot=	Off
#AutoExposure=	Off
#Spike filter=	Multiple accum.
#Delay time (s)=	0
#Binning=	1
#Readout mode=	Signal
#DeNoise=	Off
#ICS correction=	On
#Dark correction=	Off
#Inst. Process=	Off
#Detector Gain=	Best Dynamic Range
#Detector ADC=	20 kHz
#Detector temperature (°C)=	-69.85
#Instrument=	LabRAM HR Evol
#Detector=	Synapse
#Objective=	x100
#Grating=	600 gr/mm
#ND Filter=	100%
#Laser (nm)=	532
#Hole=	100.021
#Range=	Auto
#Laser Pol.=	No
#Raman. Pol.=	No
#Laser Pol. (°)=	-0.0007625
#Raman Pol. (°)=	89.9995
#Collection=	Microscope
#StageXY=	Marzhauser
#StageZ=	Marzhauser
#X (µm)=	-1055
#Y (µm)=	624.9
#Z (µm)=	584.35
#Full time(mm:ss)=	3:18
#Project=
#Sample=
#Site=
#Title=	Mb_40_y_18_2x_45s_532 nm_x100_100%_600 gr_mm
#Remark=
#Date=	19.07.2022 10:28
#Acquired=	19.07.2022 10:28:31
#Base:Fit=	10.08.2022 10:52:48
#Base:Sub=	10.08.2022 10:52:53
#Filter:Polynom=	16.08.2022 10:09:04
#AxisType[0]=Intens
#AxisUnit[0]=Cnt
#AxisType[1]=Spectr
#AxisUnit[1]=1/cm
200.423	39.5347
204.052	34.4222
207.682	29.3233
211.308	26.232
214.935	22.9506
218.558	18.5603
222.18	14.4366
225.802	12.901
229.421	12.1119
233.039	11.1622
236.657	9.26582
240.272	7.66293
243.885	6.70727
247.497	5.09081
251.11	3.70637
254.719	2.37664
258.327	4.50385
261.933	4.50164
265.538	4.60916
269.141	4.65364
272.744	4.5621
276.344	5.00612
279.944	5.83979
283.542	6.37964
287.138	7.64603
290.733	8.18398
294.327	8.39852
297.919	9.0723
301.508	7.27462
305.098	8.37327
308.686	8.98807
312.273	10.1063
315.858	11.6138
319.44	12.3197
323.022	11.9364
326.604	11.5413
330.181	12.0871
333.76	11.3732
337.335	10.3719
340.91	9.10668
344.483	8.85919
348.055	7.94884
351.625	6.77207
355.195	5.84156
358.762	5.63581
362.329	4.505
365.893	3.43079
369.455	1.80122
373.017	3.47856
376.578	0.924421
380.137	-0.230002
383.694	1.12772
387.249	2.10675
390.806	3.19263
394.359	4.40239
397.91	3.42526
401.46	4.81664
405.009	5.26382
408.557	7.30141
412.103	7.84846
415.647	9.23609
419.191	9.57812
422.733	10.8766
426.273	10.1791
429.812	9.45771
433.35	8.0163
436.885	8.5927
440.42	7.95379
443.954	7.7039
447.486	8.78808
451.015	8.50639
454.545	9.55009
458.073	10.4041
461.598	11.0039
465.124	13.0073
468.648	13.8212
472.169	15.3983
475.69	16.1796
479.208	16.5298
482.727	16.9959
486.243	18.6325
489.759	19.6049
493.272	21.7837
496.783	23.5863
500.295	27.0211
503.804	27.8138
507.311	28.1046
510.819	29.9177
514.324	29.3623
517.827	29.2486
521.329	30.5108
524.83	31.1003
528.329	30.3703
531.829	27.791
535.326	26.4076
538.821	24.4916
542.315	22.5479
545.808	21.4637
549.299	17.8551
552.789	15.663
556.278	13.4823
559.763	13.2901
563.249	11.7969
566.733	9.18405
570.217	7.90845
573.699	4.97363
577.177	5.01405
580.656	4.97716
584.134	6.26041
587.609	7.99387
591.084	7.81711
594.558	7.63882
598.029	9.22398
601.5	11.2753
604.968	12.9353
608.437	12.8335
611.902	11.9334
615.368	11.0306
618.831	12.3018
622.294	13.9109
625.755	13.6376
629.213	13.1408
632.673	12.8375
636.129	12.3117
639.584	13.815
643.037	14.174
646.491	13.4807
649.942	13.8839
653.392	12.7123
656.84	11.0528
660.287	10.2689
663.732	12.0507
667.177	12.9813
670.62	13.7182
674.061	14.9092
677.502	16.7122
680.941	19.185
684.379	22.9084
687.815	24.7676
691.248	26.9436
694.682	28.7423
698.115	31.3655
701.546	34.9627
704.974	39.3589
708.402	41.0617
711.83	41.7446
715.254	43.3032
718.679	44.3764
722.102	45.9131
725.522	46.1893
728.943	49.3101
732.361	50.6136
735.779	50.7628
739.194	49.9918
742.608	51.3648
746.022	51.9589
749.433	52.1357
752.843	54.1896
756.254	55.412
759.661	58.2586
763.067	60.5449
766.471	63.3552
769.877	66.1067
773.279	67.396
776.68	71.0714
780.079	73.0317
783.478	74.3328
786.875	78.1342
790.27	80.5565
793.665	81.61
797.058	83.6465
800.45	84.3158
803.84	84.746
807.23	83.8739
810.616	84.693
814.002	83.9907
817.388	83.0362
820.772	80.4048
824.153	78.5882
827.535	75.5813
830.915	71.1905
834.292	68.6765
837.67	64.5336
841.047	61.8035
844.42	59.7595
847.794	56.7967
851.165	53.8796
854.534	51.4687
857.905	51.3146
861.272	48.8962
864.639	48.4118
868.004	49.8021
871.367	50.5691
874.731	51.2136
878.092	52.1664
881.451	52.2977
884.809	52.0399
888.166	52.9835
891.522	52.8097
894.878	52.5042
898.231	53.1659
901.583	52.5968
904.934	52.491
908.283	52.6076
911.631	51.6075
914.976	51.9708
918.322	51.1481
921.666	51.0075
925.009	49.9209
928.351	49.9528
931.692	48.4649
935.029	48.6869
938.367	47.3026
941.704	46.6186
945.038	45.6103
948.372	46.3643
951.705	46.4154
955.035	44.2157
958.366	41.5716
961.693	38.6035
965.021	36.0957
968.346	34.1022
971.67	32.9414
974.995	32.5359
978.316	31.8564
981.638	29.3129
984.957	26.6666
988.274	26.0229
991.59	23.1942
994.907	19.7859
998.221	15.3417
1001.53	9.26865
1004.85	7.03476
1008.16	12.5195
1011.46	26.0762
1014.77	44.5423
1018.08	68.5657
1021.38	92.9656
1024.69	115.877
1027.99	139.387
1031.29	156.051
1034.59	170.248
1037.89	182.431
1041.19	188.798
1044.48	192.812
1047.78	195.74
1051.07	192.254
1054.36	186.137
1057.66	174.45
1060.94	158.532
1064.23	141.107
1067.52	120.6
1070.81	98.6074
1074.09	74.6813
1077.38	51.9505
1080.66	31.8819
1083.94	16.8752
1087.22	11.4536
1090.5	11.8831
1093.77	15.6371
1097.05	19.8798
1100.32	23.6009
1103.6	25.4103
1106.87	28.1938
1110.14	29.3348
1113.41	27.9727
1116.67	28.0483
1119.94	26.0252
1123.21	24.4391
1126.47	23.4102
1129.73	21.5178
1133	19.8092
1136.26	19.3007
1139.52	17.4017
1142.77	15.4632
1146.03	14.6071
1149.29	14.7647
1152.54	13.223
1155.79	11.3844
1159.04	10.352
1162.3	7.10682
1165.55	5.52479
1168.79	5.17465
1172.04	3.88835
1175.28	3.93139
1178.53	4.4114
1181.77	5.76306
1185.01	6.29048
1188.25	5.36054
1191.49	4.84184
1194.73	4.76926
1197.97	4.32117
1201.2	5.89806
1204.44	5.43637
1207.67	7.56529
1210.9	10.1406
1214.13	14.1005
1217.36	17.5147
1220.59	20.3552
1223.82	22.1733
1227.04	27.3193
1230.26	30.429
1233.49	31.6053
1236.71	33.6814
1239.93	35.8224
1243.15	36.5497
1246.37	38.4907
1249.58	38.6403
1252.8	40.3227
1256.01	42.4086
1259.23	45.2425
1262.44	48.0579
1265.65	49.2432
1268.86	52.0304
1272.07	53.6216
1275.27	54.3252
1278.48	54.8618
1281.68	56.8133
1284.89	59.6023
1288.09	61.0267
1291.29	61.5126
1294.49	63.1514
1297.69	64.4512
1300.88	64.6081
1304.08	66.5562
1307.27	69.0564
1310.47	68.5595
1313.66	67.1982
1316.85	66.4585
1320.04	65.4084
1323.23	65.4632
1326.41	63.5574
1329.6	61.5654
1332.78	60.0512
1335.97	59.9779
1339.15	58.591
1342.33	57.6757
1345.51	56.5359
1348.69	55.3133
1351.87	52.6542
1355.04	51.3909
1358.22	49.7774
1361.39	48.4767
1364.57	46.3355
1367.74	44.1664
1370.91	42.2508
1374.07	41.544
1377.24	40.6327
1380.41	41.6056
1383.57	42.4404
1386.74	42.6082
1389.9	43.6388
1393.06	45.0949
1396.22	45.7621
1399.38	47.1066
1402.54	49.3112
1405.7	49.9643
1408.85	52.8014
1412.01	57.2773
1415.16	61.7485
1418.31	67.4112
1421.46	71.785
1424.61	76.4203
1427.76	80.3596
1430.91	84.4512
1434.05	89.7398
1437.2	91.0063
1440.34	92.9674
1443.49	94.7383
1446.63	93.9174
1449.77	93.6201
1452.91	92.2368
1456.04	90.5761
1459.18	86.7828
1462.31	82.6377
1465.45	78.1545
1468.58	74.9389
1471.71	70.1218
1474.84	64.2279
1477.97	59.5834
1481.1	55.4474
1484.23	50.1395
1487.35	46.2994
1490.48	42.7957
1493.6	38.306
1496.72	36.0875
1499.84	32.6171
1502.96	28.6968
1506.08	27.7093
1509.2	26.2106
1512.31	24.2099
1515.43	21.639
1518.54	21.7778
1521.66	22.0531
1524.77	20.7777
1527.88	20.4231
1530.99	20.7316
1534.09	19.9366
1537.2	21.2808
1540.31	21.9691
1543.41	24.3775
1546.51	24.1242
1549.62	25.3805
1552.72	26.516
1555.82	28.9686
1558.91	29.1317
1562.01	30.5535
1565.11	32.6995
1568.2	34.2187
1571.3	36.6378
1574.39	38.6523
1577.48	40.5498
1580.57	43.4062
1583.66	45.3115
1586.75	46.8905
1589.83	48.6756
1592.92	49.9204
1596	51.7686
1599.09	52.4433
1602.17	52.6136
1605.25	52.0541
1608.33	51.8652
1611.41	51.5019
1614.48	50.051
1617.56	48.2096
1620.64	49.0281
1623.71	48.0788
1626.78	49.561
1629.86	49.7054
1632.92	50.3783
1635.99	51.2235
1639.06	53.592
1642.13	54.1274
1645.19	54.884
1648.26	58.4389
1651.32	60.2354
1654.38	61.6178
1657.45	61.9659
1660.51	60.74
1663.57	60.1681
1666.62	59.1476
1669.68	57.8341
1672.73	56.1138
1675.79	52.7926
1678.84	49.6253
1681.89	44.75
1684.94	41.395
1687.99	37.0886
1691.04	32.2283
1694.09	28.3564
1697.14	25.4502
1700.18	22.4702
1703.22	18.8511
1706.27	15.0544
1709.31	11.1383
1712.35	8.7579
1715.39	6.7457
1718.43	6.50869
1721.46	4.96276
1724.5	4.77193
1727.53	4.57749
1730.57	5.32436
1733.6	5.00656
1736.63	5.30043
1739.66	5.27998
1742.69	5.11798
1745.72	5.96269
1748.74	5.94263
1751.77	5.99923
1754.8	6.19968
1757.82	5.08763
1760.84	5.15652
1763.86	3.91798
1766.88	3.24026
1769.9	1.7611
1772.92	1.78233
1775.93	0.584879
1778.95	0.0463105
1781.96	0.161374
1784.98	0.28269
1787.99	0.807999
1791	1.00727
1794.01	1.33293
1797.02	1.8337
1800.03	2.86131
1803.03	3.4154
1806.04	3.91748
1809.04	4.18177
1812.04	4.14139
1815.05	4.30742
1818.05	5.36652
1821.05	5.72132
1824.05	5.65561
1827.04	5.24838
1830.04	5.03121
1833.03	4.30219
1836.03	4.02325
1839.02	3.52537
1842.01	3.6081
1845	2.47909
1847.99	1.64086
1850.98	1.51691
1853.97	1.61246
1856.95	1.35352
1859.94	1.284
1862.92	1.93762
1865.91	1.77922
1868.89	2.4255
1871.87	2.86544
1874.85	3.59482
1877.83	3.59903
1880.8	3.27862
1882.56	2.77447
1885.54	2.78903
1888.53	4.31338
1891.52	4.42922
1894.5	3.77394
1897.49	3.51604
1900.47	3.74741
1903.45	4.28917
1906.43	3.96305
1909.41	3.54032
1912.39	3.17467
1915.37	1.9478
1918.35	0.714095
1921.32	1.33788
1924.3	2.18017
1927.27	1.6307
1930.24	1.67794
1933.21	2.59651
1936.18	2.95261
1939.15	3.63734
1942.12	4.23895
1945.09	3.41717
1948.05	2.67517
1951.02	1.08898
1953.98	1.49434
1956.94	2.58562
1959.91	3.54249
1962.87	4.1057
1965.82	3.85386
1968.78	4.06762
1971.74	4.22791
1974.7	5.33641
1977.65	4.66459
1980.6	5.22717
1983.56	5.31559
1986.51	5.02872
1989.46	5.00102
1992.41	5.74386
1995.36	5.91236
1998.3	5.96412
2001.25	6.27011
2004.2	6.94111
2007.14	5.84752
2010.08	4.88274
2013.02	5.44588
2015.97	4.01661
2018.9	3.86607
2021.84	4.07173
2024.78	4.28205
2027.72	4.98402
2030.65	5.80718
2033.59	5.41099
2036.52	5.94678
2039.45	6.45958
2042.38	7.99845
2045.31	7.7815
2048.24	9.14294
2051.17	9.8586
2054.1	12.5015
2057.02	12.7841
2059.95	13.6333
2062.87	14.2558
2065.79	14.5425
2068.71	15.9592
2071.63	16.7549
2074.55	18.5755
2077.47	19.4658
2080.39	19.3905
2083.3	20.2626
2086.22	20.3413
2089.13	20.8732
2092.05	21.9709
2094.96	22.2498
2097.87	23.2079
2100.78	23.7426
2103.69	25.5406
2106.59	26.316
2109.5	28.1621
2112.41	29.301
2115.31	30.6102
2118.21	33.1687
2121.12	36.0219
2124.02	39.7134
2126.92	41.9218
2129.82	44.6813
2132.71	48.0579
2135.61	51.8313
2138.51	56.7739
2141.4	60.0332
2144.29	63.2626
2147.19	66.6693
2150.08	67.8438
2152.97	70.0735
2155.86	71.4858
2158.75	73.549
2161.64	75.2938
2164.52	76.1239
2167.41	76.7296
2170.29	76.6787
2173.17	76.9139
2176.06	76.3978
2178.94	75.7509
2181.82	74.7542
2184.7	73.1607
2187.57	71.7686
2190.45	70.0743
2193.33	69.0821
2196.2	66.2735
2199.08	64.4383
2201.95	62.7614
2204.82	59.8038
2207.69	57.4822
2210.56	54.5209
2213.43	50.162
2216.3	47.9725
2219.16	44.7497
2222.03	41.3299
2224.89	37.652
2227.75	36.0285
2230.62	33.9291
2233.48	31.9046
2236.34	30.0907
2239.2	28.4863
2242.06	27.715
2244.91	25.9897
2247.77	25.2883
2250.62	23.2698
2253.48	21.9562
2256.33	20.0916
2259.18	18.8183
2262.03	17.9843
2264.88	17.77
2267.73	16.5208
2270.58	16.5814
2273.43	15.0938
2276.27	14.7476
2279.12	13.5375
2281.96	12.5772
2284.8	12.1342
2287.64	10.6403
2290.49	10.1253
2293.32	8.51188
2296.16	9.31989
2299	10.0194
2301.84	9.89796
2304.67	10.4924
2307.51	10.8377
2310.34	11.454
2313.17	10.9699
2316	10.2667
2318.83	9.43182
2321.66	8.35408
2324.49	7.90532
2327.32	7.52925
2330.15	7.61792
2332.97	6.59688
2335.79	6.22101
2338.62	5.27285
2341.44	4.3855
2344.26	3.37859
2347.08	3.21584
2349.9	3.3677
2352.72	3.80909
2355.53	3.44452
2358.35	3.51919
2361.17	2.6035
2363.98	3.36671
2366.79	4.64539
2369.6	4.57276
2372.42	5.67624
2375.22	6.63409
2378.03	6.40377
2380.84	5.68267
2383.65	4.9058
2386.45	4.51896
2389.26	4.42742
2392.06	4.69628
2394.87	5.0251
2397.67	4.9471
2400.47	4.40232
2403.27	3.95278
2406.07	4.05311
2408.86	4.6258
2411.66	4.95565
2414.46	5.66782
2417.25	6.65105
2420.05	7.36225
2422.84	7.86349
2425.63	8.39438
2428.42	9.10848
2431.21	9.46535
2434	9.22982
2436.79	10.2214
2439.57	8.33375
2442.36	8.67821
2445.14	8.61276
2447.93	7.30086
2450.71	6.06836
2453.49	5.96343
2456.27	4.37736
2459.05	3.71409
2461.83	3.47069
2464.61	3.09359
2467.39	3.0564
2470.16	1.24356
2472.94	0.997201
2475.71	0.941495
2478.48	0.400454
2481.25	-0.156917
2484.02	-0.076554
2486.8	-0.892456
2489.56	-0.637905
2492.33	-0.276881
2495.1	-0.0636304
2497.86	0.176809
2500.63	-0.0419056
2503.39	0.335216
2506.16	1.34304
2508.92	1.98885
2511.68	3.33834
2514.44	3.38032
2517.2	3.55411
2519.95	4.33866
2522.71	4.86972
2525.47	5.35463
2528.22	5.81919
2530.98	6.59768
2533.73	7.32939
2536.48	6.37117
2539.23	7.06011
2541.98	6.99356
2544.73	6.75533
2547.48	5.97748
2550.23	5.42398
2552.97	4.72933
2555.72	4.71345
2558.46	4.61526
2561.2	4.04088
2563.95	4.80146
2566.69	4.88878
2569.43	5.52597
2572.17	6.026
2574.91	6.62268
2577.64	6.25955
2580.38	5.45355
2583.11	6.2678
2585.85	5.49977
2588.58	6.63093
2591.31	5.63219
2594.04	5.6639
2596.78	5.40901
2599.51	4.9181
2602.23	5.48792
2604.96	5.35851
2607.69	6.42478
2610.41	6.12129
2613.14	5.39418
2615.86	6.09688
2618.58	5.99941
2621.3	5.97635
2624.03	6.82144
2626.75	7.99348
2629.46	8.14253
2632.18	9.14097
2634.9	9.46481
2637.61	9.98209
2640.33	9.64876
2643.04	9.46444
2645.76	9.43717
2648.47	9.44718
2651.18	10.2872
2653.89	10.1003
2656.6	9.69211
2659.31	9.52508
2662.01	9.31353
2664.72	7.9277
2667.43	8.87943
2670.13	9.03889
2672.83	8.96765
2675.53	8.91049
2678.24	8.05462
2680.94	8.78254
2683.64	9.31141
2686.34	8.95096
2689.03	9.71807
2691.73	10.1262
2694.43	10.3352
2697.12	11.2844
2699.81	12.1403
2702.51	12.3021
2705.2	12.9384
2707.89	13.4714
2710.58	14.159
2713.27	14.4266
2715.96	14.9974
2718.64	14.7543
2721.33	14.7367
2724.01	14.6829
2726.7	14.5545
2729.38	13.0028
2732.06	12.6886
2734.75	12.4307
2737.43	11.6944
2740.11	9.94745
2742.78	7.99666
2745.46	6.45556
2748.14	5.35169
2750.81	3.80415
2753.49	3.23984
2756.16	2.57158
2758.84	2.06234
2761.51	2.39805
2764.18	1.8473
2766.85	1.55217
2769.52	1.70605
2772.19	2.19331
2774.85	1.32988
2777.52	1.74427
2780.18	1.76449
2782.85	1.78103
2785.51	2.19618
2788.17	2.3476
2790.84	2.81906
2793.5	3.08425
2796.16	2.93263
2798.81	3.25821
2801.47	2.81866
2804.13	2.28159
2806.79	1.7422
2809.44	1.01886
2812.09	1.76514
2814.75	3.44293
2817.4	5.25648
2820.05	8.25403
2822.7	11.7028
2825.35	14.7325
2828	18.7374
2830.65	23.01
2833.29	28.2177
2835.94	33.7167
2838.58	38.6547
2841.23	44.569
2843.87	50.2478
2846.51	54.7967
2849.15	60.8674
2851.79	66.9982
2854.43	73.7365
2857.07	80.0185
2859.71	86.4711
2862.34	91.7176
2864.98	96.0624
2867.61	99.8948
2870.25	103.248
2872.88	105.399
2875.51	108.225
2878.14	111.057
2880.77	113.096
2883.4	115.576
2886.03	116.877
2888.65	118.882
2891.28	120.301
2893.91	123.177
2896.53	125.167
2899.15	128.418
2901.78	131.186
2904.4	135.06
2907.02	139.087
2909.64	144.303
2912.26	150.915
2914.87	157.063
2917.49	165.517
2920.11	171.49
2922.72	178.296
2925.34	182.94
2927.95	185.881
2930.56	188.36
2933.17	189.37
2935.78	189.119
2938.39	188.138
2941	185.268
2943.61	181.118
2946.22	175.475
2948.82	168.01
2951.43	162.151
2954.03	154.453
2956.64	145.886
2959.24	138.39
2961.84	129.745
2964.44	122.077
2967.04	115.212
2969.64	107.963
2972.24	100.973
2974.83	94.6275
2977.43	88.2434
2980.02	81.9579
2982.62	76.8476
2985.21	69.6733
2987.8	64.1199
2990.4	57.3819
2992.99	50.7676
2995.57	44.0172
2998.16	39.1571
3000.75	34.1028
3003.34	28.4578
3005.92	24.133
3008.51	19.8356
3011.09	15.9018
3013.68	13.4691
3016.26	10.7302
3018.84	8.26213
3021.42	6.07692
3024	4.97003
3026.58	3.30014
3029.16	2.9557
3031.73	2.5733
3034.31	1.94908
3036.89	2.01907
3039.46	2.6033
3042.03	3.46438
3044.61	3.70861
3047.18	4.14548
3049.75	4.67096
3052.32	5.1323
3054.89	4.56967
3057.45	3.69266
3060.02	4.43998
3062.59	4.61036
3065.15	4.74349
3067.72	5.22319
3070.28	5.58773
3072.84	5.10122
3075.41	5.01721
3077.97	4.13299
3080.53	3.13233
3083.09	2.72546
3085.64	2.87074
3088.2	2.2197
3090.76	1.82176
3093.31	2.30401
3095.87	2.51713
3098.42	2.79542
3100.97	3.70007
3103.53	5.2447
3106.08	5.64894
3108.63	6.08456
3111.18	8.56041
3113.73	9.7109
3116.27	10.4292
3118.82	11.1168
3121.37	12.2325
3123.91	13.3981
3126.45	14.275
3129	16.9753
3131.54	17.7418
3134.08	19.0517
3136.62	20.4127
3139.16	21.6368
3141.7	23.4355
3144.24	25.0996
3146.78	27.2257
3149.31	28.9791