File: data/Raman/poly_smoothed/Mb_40_24_47_1x_45s_532 nm_x100_100%_600 gr_mm_01.txt
#Acq. time (s)=	45
#Accumulations=	2
#Range (cm-¹)=	200...3150
#Windows=	2
#Auto scanning=	Off
#Autofocus=	Off
#Macrospot=	Off
#AutoExposure=	Off
#Spike filter=	Multiple accum.
#Delay time (s)=	0
#Binning=	1
#Readout mode=	Signal
#DeNoise=	Off
#ICS correction=	On
#Dark correction=	Off
#Inst. Process=	Off
#Detector Gain=	Best Dynamic Range
#Detector ADC=	20 kHz
#Detector temperature (°C)=	-70.08
#Instrument=	LabRAM HR Evol
#Detector=	Synapse
#Objective=	x100
#Grating=	600 gr/mm
#ND Filter=	100%
#Laser (nm)=	532
#Hole=	100.021
#Range=	Auto
#Laser Pol.=	No
#Raman. Pol.=	No
#Laser Pol. (°)=	-0.0007625
#Raman Pol. (°)=	89.9995
#Collection=	Microscope
#StageXY=	Marzhauser
#StageZ=	Marzhauser
#X (µm)=	-2459
#Y (µm)=	-41.6
#Z (µm)=	-10
#Full time(mm:ss)=	3:19
#Project=
#Sample=
#Site=
#Title=	Mb_40_24_47_2x_45s_532 nm_x100_100%_600 gr_mm
#Remark=
#Date=	14.07.2022 14:19
#Acquired=	14.07.2022 14:19:54
#Base:Fit=	10.08.2022 10:47:00
#Base:Sub=	10.08.2022 10:47:12
#Filter:Polynom=	16.08.2022 10:11:48
#AxisType[0]=Intens
#AxisUnit[0]=Cnt
#AxisType[1]=Spectr
#AxisUnit[1]=1/cm
200.554	0.605674
204.183	3.47472
207.813	5.51061
211.439	5.74826
215.065	4.46305
218.688	6.2169
222.312	5.47934
225.933	4.97985
229.552	4.61611
233.171	3.83018
236.787	4.74352
240.402	4.25184
244.015	4.28212
247.627	4.48125
251.24	2.59956
254.849	2.19164
258.457	1.80698
262.063	1.94668
265.668	1.38763
269.271	1.85698
272.873	3.07338
276.474	3.52045
280.073	4.4049
283.671	4.63365
287.268	5.5015
290.863	5.26943
294.456	6.67869
298.049	6.99675
301.637	7.77002
305.227	11.0117
308.815	14.1183
312.402	16.6813
315.987	18.4507
319.569	20.8281
323.151	23.0423
326.733	23.1271
330.31	23.3848
333.889	24.456
337.464	24.9228
341.039	24.011
344.611	23.982
348.184	23.9439
351.754	22.9474
355.324	21.7577
358.89	20.9776
362.455	19.3792
366.021	18.4377
369.584	17.7217
373.145	16.8201
376.707	16.2642
380.265	16.9134
383.822	16.6026
387.378	15.4962
390.934	15.3499
394.487	15.8128
398.038	16.079
401.588	16.1308
405.137	14.6727
408.685	14.2057
412.23	13.2889
415.775	13.1209
419.318	12.5888
422.86	11.7164
426.401	10.4272
429.94	8.38118
433.478	6.54131
437.012	4.04979
440.547	2.13543
444.081	3.14639
447.613	5.61294
451.142	6.01891
454.672	7.33323
458.2	8.26224
461.725	9.71197
465.251	13.3204
468.775	13.6581
472.296	14.2329
475.817	16.2383
479.335	16.2279
482.854	17.868
486.37	20.1655
489.886	21.4767
493.398	22.7624
496.91	23.1528
500.422	23.4736
503.93	23.6735
507.438	23.2351
510.946	23.3039
514.45	22.3098
517.954	21.8938
521.456	20.1236
524.956	20.8861
528.456	22.2096
531.956	21.7422
535.452	22.0173
538.947	21.7681
542.441	20.0581
545.934	20.4533
549.425	20.2127
552.915	19.0243
556.403	17.3762
559.889	15.7576
563.375	16.9584
566.859	15.856
570.342	15.8976
573.824	14.6661
577.303	13.608
580.782	11.3338
584.26	10.3945
587.734	8.77947
591.21	9.12624
594.684	9.91157
598.154	10.5642
601.626	10.8904
605.094	10.9765
608.562	11.7506
612.027	11.8219
615.493	11.3066
618.956	12.4705
622.419	12.8332
625.879	12.3423
629.338	12.5523
632.797	14.6331
636.254	15.0551
639.708	15.1128
643.162	16.8028
646.614	18.2003
650.067	18.3376
653.516	18.4729
656.964	19.3531
660.411	17.4489
663.857	16.9797
667.301	16.9268
670.744	17.221
674.186	18.5466
677.626	21.0169
681.065	22.3461
684.503	24.0281
687.939	24.9083
691.372	28.116
694.806	31.0069
698.239	30.9423
701.67	32.7972
705.098	36.0663
708.526	38.6972
711.954	40.4981
715.378	43.1874
718.802	45.8433
722.226	45.667
725.646	48.3457
729.067	48.9446
732.484	49.3132
735.902	50.673
739.317	51.974
742.731	52.1854
746.145	50.0329
749.556	51.801
752.966	53.4599
756.377	56.4
759.784	57.4796
763.19	59.0883
766.594	60.4106
770	62.9588
773.402	65.4251
776.803	67.7962
780.202	69.2265
783.6	71.9076
786.997	75.1684
790.393	77.3976
793.787	79.0488
797.18	80.7903
800.572	81.3253
803.963	81.3877
807.35	81.9857
810.738	82.2331
814.125	80.794
817.51	80.6524
820.894	80.4339
824.275	78.0484
827.657	75.3361
831.037	74.4882
834.414	73.4253
837.792	72.0033
841.167	69.6715
844.542	66.4446
847.914	63.0936
851.287	62.0921
854.656	59.7731
858.026	57.6156
861.393	55.8804
864.761	55.1224
868.125	54.4085
871.489	53.2241
874.85	51.5818
878.213	51.1698
881.572	50.2929
884.931	49.2771
888.287	49.1223
891.643	49.8824
894.997	50.3175
898.352	51.5448
901.704	53.755
905.055	54.4312
908.404	53.0479
911.75	55.1769
915.097	55.7077
918.443	54.6899
921.787	53.4894
925.13	52.8264
928.472	52.0462
931.813	50.4883
935.15	48.4072
938.488	45.9461
941.825	45.6279
945.158	45.2721
948.493	42.9635
951.824	41.2561
955.156	37.4908
958.486	35.0084
961.814	33.5274
965.142	31.7007
968.467	33.1719
971.79	34.1737
975.115	36.969
978.436	36.9853
981.756	38.1713
985.077	38.5497
988.394	36.8107
991.71	38.025
995.025	39.221
998.341	37.1478
1001.65	36.2547
1004.97	34.5154
1008.28	33.767
1011.58	32.3226
1014.89	31.9175
1018.2	32.4004
1021.5	32.2586
1024.81	32.6282
1028.11	31.3391
1031.41	31.5364
1034.71	31.0138
1038.01	30.3221
1041.31	29.7974
1044.6	31.1857
1047.9	31.4028
1051.19	31.6483
1054.48	30.8087
1057.77	29.5329
1061.06	28.7099
1064.35	27.9724
1067.64	27.2721
1070.93	26.726
1074.21	24.4931
1077.49	22.9615
1080.78	20.6376
1084.06	18.8342
1087.34	18.1073
1090.61	16.3271
1093.89	16.5575
1097.17	15.5194
1100.44	14.809
1103.71	12.9671
1106.99	13.3189
1110.26	14.2235
1113.52	14.7421
1116.79	14.101
1120.06	13.0569
1123.32	12.3213
1126.59	10.8752
1129.85	10.0727
1133.11	9.60412
1136.37	7.48484
1139.63	8.67889
1142.89	8.21099
1146.15	7.79211
1149.4	5.70524
1152.66	5.04282
1155.91	5.0246
1159.16	5.0053
1162.41	4.31441
1165.66	3.10091
1168.91	2.738
1172.16	0.671305
1175.4	0.474889
1178.65	0.202063
1181.89	0.267599
1185.13	0.620645
1188.37	0.568784
1191.61	2.47237
1194.85	2.45485
1198.08	2.23314
1201.32	3.89185
1204.55	4.57782
1207.79	6.24554
1211.02	7.98583
1214.25	8.7855
1217.48	9.94702
1220.71	13.0269
1223.93	16.7141
1227.16	19.2874
1230.38	23.7227
1233.6	28.6639
1236.83	31.4709
1240.05	34.5167
1243.26	36.6626
1246.48	38.9906
1249.7	39.6631
1252.92	40.5517
1256.13	41.7612
1259.34	42.4868
1262.55	43.3578
1265.76	44.5256
1268.97	45.5878
1272.18	47.1283
1275.39	47.7679
1278.59	49.8311
1281.8	50.0831
1285	51.135
1288.2	51.3726
1291.4	53.2392
1294.6	53.968
1297.8	54.8027
1301	56.9148
1304.19	58.1878
1307.39	58.6271
1310.58	59.1237
1313.77	58.1256
1316.96	57.642
1320.15	57.7468
1323.34	56.0156
1326.53	55.0916
1329.72	54.7365
1332.9	53.6732
1336.08	53.3671
1339.27	51.9619
1342.45	50.9692
1345.63	50.5554
1348.8	49.9423
1351.98	49.2523
1355.16	48.3553
1358.33	46.2753
1361.51	44.568
1364.68	42.6054
1367.85	40.5157
1371.02	40.6924
1374.19	37.8301
1377.36	36.8643
1380.52	35.11
1383.69	31.7461
1386.85	31.7165
1390.02	30.3569
1393.18	30.4818
1396.34	30.9304
1399.5	31.5376
1402.65	31.9545
1405.81	33.1457
1408.97	33.9846
1412.12	35.6864
1415.27	38.2127
1418.43	41.7347
1421.58	44.6299
1424.73	47.9277
1427.87	52.739
1431.02	56.846
1434.17	59.9869
1437.31	63.8021
1440.46	65.3565
1443.6	67.4162
1446.74	69.5369
1449.88	70.4521
1453.02	70.4095
1456.16	70.2117
1459.29	68.5245
1462.43	66.209
1465.56	65.6657
1468.69	61.9903
1471.83	57.9305
1474.95	53.4276
1478.08	49.4417
1481.21	46.0003
1484.34	42.1295
1487.47	39.7402
1490.59	37.2638
1493.71	34.0478
1496.84	31.4333
1499.96	29.3884
1503.07	27.9114
1506.19	26.5088
1509.31	23.4852
1512.43	22.0468
1515.54	20.5266
1518.65	19.3112
1521.77	19.7899
1524.88	19.0014
1527.99	18.7917
1531.1	18.2779
1534.21	19.1222
1537.31	18.5733
1540.42	18.7225
1543.52	20.3388
1546.63	21.4869
1549.73	22.8343
1552.83	24.5626
1555.93	27.6638
1559.03	29.6816
1562.12	31.6358
1565.22	34.7807
1568.31	36.7977
1571.41	38.9455
1574.5	42.1189
1577.59	44.3731
1580.68	46.3655
1583.77	48.3156
1586.86	50.4554
1589.95	51.8483
1593.03	53.4697
1596.11	54.3469
1599.2	53.1771
1602.28	51.8194
1605.36	51.534
1608.44	51.9406
1611.52	50.5872
1614.6	49.1297
1617.67	48.7211
1620.75	47.9699
1623.82	48.0611
1626.89	48.0391
1629.96	49.4677
1633.04	50.8255
1636.11	51.8344
1639.17	54.3525
1642.24	56.0501
1645.31	57.8516
1648.37	60.8947
1651.43	62.9785
1654.5	65.0122
1657.56	66.2591
1660.62	66.7439
1663.67	67.2189
1666.73	65.3601
1669.79	63.8165
1672.84	60.7684
1675.9	57.7804
1678.95	55.8479
1682	51.5349
1685.05	46.8609
1688.1	41.655
1691.15	38.1006
1694.2	32.7315
1697.25	28.9858
1700.29	25.4246
1703.33	21.5306
1706.38	19.4881
1709.42	16.6934
1712.46	14.9913
1715.5	13.9267
1718.54	11.735
1721.57	10.3232
1724.61	10.1012
1727.64	9.53598
1730.68	8.96597
1733.71	7.99036
1736.74	7.22911
1739.77	6.62441
1742.8	5.61939
1745.83	4.90108
1748.85	4.11057
1751.88	3.95045
1754.91	4.36716
1757.93	4.47438
1760.95	3.97123
1763.97	3.21894
1766.99	3.16491
1770.01	2.55278
1773.03	1.42223
1776.04	2.46861
1779.06	2.53915
1782.07	3.26009
1785.09	3.14753
1788.1	2.81108
1791.11	2.03064
1794.12	1.51294
1797.13	1.7081
1800.13	3.24581
1803.14	3.43716
1806.15	3.17683
1809.15	3.50142
1812.15	3.10085
1815.16	2.6822
1818.15	1.89706
1821.16	2.08005
1824.15	2.03111
1827.15	2.37886
1830.15	2.52784
1833.14	2.25365
1836.14	2.20965
1839.13	2.67788
1842.12	1.90514
1845.11	1.28508
1848.1	0.874723
1851.09	1.40779
1854.08	0.882255
1857.06	1.27784
1860.05	1.1163
1863.03	1.23204
1866.01	2.48177
1869	2.21066
1871.98	3.60368
1874.96	4.46833
1877.93	3.76381
1880.91	4.58938
1882.47	3.38343
1885.46	3.51654
1888.44	3.69362
1891.43	3.79823
1894.42	3.91091
1897.4	3.07598
1900.39	3.47612
1903.37	4.13619
1906.35	3.95393
1909.33	3.68635
1912.31	3.53528
1915.29	3.88927
1918.26	3.88902
1921.24	3.5013
1924.21	3.83902
1927.19	3.7584
1930.16	4.63593
1933.13	4.80446
1936.1	6.08544
1939.07	4.67848
1942.04	4.01764
1945	4.61907
1947.97	4.62807
1950.93	5.1496
1953.9	4.62005
1956.86	4.82381
1959.82	5.31862
1962.78	5.77616
1965.74	6.39744
1968.7	5.90875
1971.65	6.49924
1974.61	7.57054
1977.57	8.0257
1980.52	7.98236
1983.47	8.01898
1986.42	7.86967
1989.37	7.92162
1992.32	7.88332
1995.27	8.72234
1998.22	8.08142
2001.17	8.60849
2004.11	7.31895
2007.05	5.74546
2010	5.24336
2012.94	3.68394
2015.88	3.90847
2018.82	2.49561
2021.76	2.46401
2024.7	2.52945
2027.63	2.13897
2030.57	2.43752
2033.5	3.43701
2036.44	4.29031
2039.37	4.29161
2042.3	5.86174
2045.23	8.10264
2048.16	9.26755
2051.08	10.6003
2054.01	11.7489
2056.94	13.2158
2059.86	14.0374
2062.79	16.06
2065.71	17.9774
2068.63	18.3934
2071.55	17.7494
2074.47	18.8692
2077.39	18.368
2080.31	19.5651
2083.22	19.7176
2086.13	19.9272
2089.05	20.4318
2091.96	20.5506
2094.87	21.493
2097.78	22.204
2100.69	22.9949
2103.6	24.1425
2106.51	25.2771
2109.42	25.9259
2112.32	27.5937
2115.23	29.2334
2118.13	32.1442
2121.03	33.6889
2123.93	36.0208
2126.83	38.3587
2129.73	41.0407
2132.63	43.733
2135.53	46.9037
2138.42	48.7377
2141.32	50.7417
2144.21	54.6547
2147.1	57.6791
2150	59.0952
2152.89	62.7138
2155.78	64.9227
2158.66	66.535
2161.55	67.6275
2164.44	68.1445
2167.32	69.1541
2170.21	69.2672
2173.09	68.6106
2175.97	66.0767
2178.85	64.4272
2181.73	62.9637
2184.61	61.1416
2187.49	60.7694
2190.37	58.4507
2193.24	55.9904
2196.12	53.9675
2198.99	51.5815
2201.87	48.9274
2204.74	45.9502
2207.61	43.7298
2210.48	42.5569
2213.35	41.0951
2216.21	40.0744
2219.08	38.1919
2221.95	37.8884
2224.81	37.0436
2227.67	34.5983
2230.54	31.91
2233.4	30.469
2236.26	29.083
2239.11	27.5234
2241.97	25.3729
2244.83	23.2504
2247.69	21.9144
2250.54	21.3623
2253.4	19.8013
2256.25	18.1798
2259.1	17.2443
2261.95	15.9087
2264.8	14.726
2267.65	14.2133
2270.5	13.0585
2273.34	11.4855
2276.19	10.9058
2279.03	10.9675
2281.88	10.4009
2284.72	11.8712
2287.56	11.5405
2290.4	9.24279
2293.24	8.19242
2296.08	7.62385
2298.92	7.46737
2301.76	8.52472
2304.59	9.31417
2307.43	8.80308
2310.26	8.97995
2313.09	8.86949
2315.92	8.55058
2318.75	7.933
2321.58	7.10404
2324.41	6.13021
2327.24	7.21337
2330.06	7.37504
2332.89	6.78157
2335.71	6.13816
2338.54	5.66393
2341.36	4.3168
2344.18	4.25932
2347	4.17058
2349.82	3.28006
2352.64	2.9342
2355.45	1.99792
2358.27	0.911097
2361.08	1.75728
2363.9	1.82867
2366.71	3.98407
2369.52	5.03698
2372.33	5.44086
2375.14	4.86128
2377.95	4.20248
2380.76	3.9115
2383.57	4.24844
2386.37	4.41694
2389.18	4.51627
2391.98	4.68433
2394.79	5.57428
2397.59	5.33223
2400.39	4.66588
2403.19	3.9762
2405.99	4.02725
2408.78	3.95116
2411.58	4.23176
2414.38	3.4525
2417.17	3.27865
2419.97	3.63015
2422.76	4.58576
2425.55	4.44851
2428.34	4.39046
2431.13	5.05192
2433.92	4.65312
2436.71	4.68323
2439.49	4.63507
2442.28	3.80622
2445.06	4.17381
2447.85	4.26905
2450.63	5.61716
2453.41	5.38738
2456.19	5.0431
2458.97	5.01498
2461.75	5.2678
2464.53	4.51242
2467.31	3.87099
2470.08	3.58299
2472.86	2.89496
2475.63	2.95388
2478.4	3.36049
2481.17	4.10343
2483.94	3.49779
2486.72	4.11023
2489.48	3.65405
2492.25	3.0271
2495.02	2.42108
2497.79	2.24466
2500.55	2.47023
2503.31	1.51921
2506.08	1.22014
2508.84	0.944904
2511.6	0.985801
2514.36	1.20045
2517.12	0.516411
2519.88	2.32743
2522.63	1.42943
2525.39	1.91134
2528.14	2.46023
2530.9	2.98863
2533.65	3.80087
2536.4	5.31016
2539.15	5.68267
2541.9	5.17906
2544.65	6.51982
2547.4	7.247
2550.15	8.29932
2552.89	7.40574
2555.64	7.56097
2558.38	6.91171
2561.12	7.02629
2563.87	6.01788
2566.61	5.00821
2569.35	4.77738
2572.09	3.05923
2574.83	2.42627
2577.56	2.03414
2580.3	0.816685
2583.04	0.660287
2585.77	0.196438
2588.5	0.498105
2591.23	-0.35338
2593.97	0.266953
2596.7	1.47109
2599.43	1.48282
2602.15	1.88802
2604.88	2.51768
2607.61	2.63585
2610.33	2.98551
2613.06	4.03081
2615.78	5.24771
2618.51	5.78233
2621.23	6.43977
2623.95	6.99398
2626.67	7.90103
2629.39	8.08967
2632.1	7.93448
2634.82	8.07746
2637.54	6.72434
2640.25	5.93847
2642.97	5.3689
2645.68	4.96136
2648.39	5.36751
2651.1	5.24606
2653.81	4.59029
2656.52	3.56103
2659.23	3.07657
2661.94	3.26607
2664.64	2.26273
2667.35	2.00046
2670.05	2.86007
2672.76	3.3444
2675.46	4.17804
2678.16	3.91638
2680.86	4.37475
2683.56	4.45982
2686.26	5.91825
2688.96	6.36002
2691.65	7.17973
2694.35	7.84012
2697.04	7.78496
2699.74	8.32684
2702.43	7.85766
2705.12	8.57815
2707.81	9.33337
2710.5	10.2148
2713.19	12.1868
2715.88	11.2104
2718.57	10.3669
2721.25	10.2988
2723.94	10.5829
2726.62	10.3898
2729.3	9.3587
2731.99	9.24566
2734.67	9.09631
2737.35	9.58899
2740.03	7.6688
2742.71	6.41769
2745.38	4.5956
2748.06	3.93911
2750.74	3.71886
2753.41	3.99252
2756.09	2.95806
2758.76	2.72557
2761.43	2.33893
2764.1	0.833628
2766.77	0.69855
2769.44	0.911025
2772.11	1.24142
2774.77	1.76195
2777.44	1.80098
2780.11	1.96208
2782.77	1.8802
2785.43	2.45506
2788.1	2.6284
2790.76	2.69194
2793.42	2.62738
2796.08	3.47139
2798.74	4.53647
2801.4	4.70244
2804.05	5.0225
2806.71	5.03842
2809.36	4.61336
2812.02	4.18241
2814.67	4.05415
2817.32	4.53026
2819.97	5.8903
2822.62	7.63773
2825.27	8.33375
2827.92	10.024
2830.57	11.4504
2833.22	14.7387
2835.86	18.4212
2838.51	21.8821
2841.15	27.0213
2843.79	31.6463
2846.43	37.2465
2849.08	42.7429
2851.72	48.0573
2854.36	55.0028
2856.99	60.779
2859.63	66.6366
2862.27	72.4069
2864.9	78.0093
2867.54	82.828
2870.17	87.1659
2872.8	91.1072
2875.43	94.3041
2878.07	98.2625
2880.7	101.891
2883.32	106.427
2885.95	109.838
2888.58	113.316
2891.21	115.827
2893.83	119.785
2896.46	124.935
2899.08	130.578
2901.7	136.006
2904.32	141.606
2906.94	150.068
2909.56	157.155
2912.18	166.372
2914.8	174.225
2917.42	181.227
2920.03	188.012
2922.65	193.111
2925.26	197.772
2927.88	200.122
2930.49	202.507
2933.1	202.472
2935.71	201.524
2938.32	197.433
2940.93	192.687
2943.54	187.446
2946.14	182.145
2948.75	175.317
2951.35	167.413
2953.96	160.06
2956.56	153.041
2959.16	145.3
2961.77	137.852
2964.37	129.759
2966.96	122.984
2969.56	116.975
2972.16	110.665
2974.76	104.357
2977.35	98.5331
2979.95	92.6446
2982.54	85.6266
2985.14	79.2968
2987.73	71.7426
2990.32	64.397
2992.91	57.5524
2995.5	51.5959
2998.09	45.6897
3000.68	39.0873
3003.26	32.9867
3005.85	29.985
3008.43	25.631
3011.02	22.1757
3013.6	19.6822
3016.19	17.2381
3018.77	16.0703
3021.35	14.1225
3023.93	11.0327
3026.5	9.07179
3029.08	8.64853
3031.66	8.66158
3034.24	7.525
3036.81	6.9512
3039.39	7.37113
3041.96	8.06456
3044.53	8.79655
3047.1	8.35995
3049.67	7.64352
3052.24	7.2849
3054.81	8.12338
3057.38	8.53914
3059.95	9.1503
3062.52	8.22187
3065.08	7.32689
3067.65	7.64373
3070.21	6.94293
3072.77	5.9784
3075.33	5.21234
3077.89	4.24223
3080.45	3.35021
3083.01	2.90403
3085.57	1.54986
3088.13	1.65413
3090.68	2.25782
3093.24	2.36877
3095.79	2.52799
3098.35	2.8415
3100.9	3.32896
3103.45	3.53485
3106	3.80488
3108.55	4.16072
3111.1	4.89743
3113.65	5.59211
3116.2	6.5768
3118.75	7.57184
3121.29	8.54936
3123.84	8.91826
3126.38	10.1574
3128.92	11.2302
3131.47	11.5853
3134.01	12.7168
3136.55	14.5351
3139.09	16.1931
3141.63	18.9645
3144.17	22.001
3146.7	24.0009
3149.24	27.0025