File: data/Raman/poly_smoothed/Mb_40_y_20_1x_45s_532 nm_x100_100%_600 gr_mm_01.txt
#Acq. time (s)=	45
#Accumulations=	2
#Range (cm-¹)=	200...3150
#Windows=	2
#Auto scanning=	Off
#Autofocus=	Off
#Macrospot=	Off
#AutoExposure=	Off
#Spike filter=	Multiple accum.
#Delay time (s)=	0
#Binning=	1
#Readout mode=	Signal
#DeNoise=	Off
#ICS correction=	On
#Dark correction=	Off
#Inst. Process=	Off
#Detector Gain=	Best Dynamic Range
#Detector ADC=	20 kHz
#Detector temperature (°C)=	-69.85
#Instrument=	LabRAM HR Evol
#Detector=	Synapse
#Objective=	x100
#Grating=	600 gr/mm
#ND Filter=	100%
#Laser (nm)=	532
#Hole=	100.021
#Range=	Auto
#Laser Pol.=	No
#Raman. Pol.=	No
#Laser Pol. (°)=	-0.0007625
#Raman Pol. (°)=	89.9995
#Collection=	Microscope
#StageXY=	Marzhauser
#StageZ=	Marzhauser
#X (µm)=	-1028.7
#Y (µm)=	655.3
#Z (µm)=	584.35
#Full time(mm:ss)=	3:18
#Project=
#Sample=
#Site=
#Title=	Mb_40_y_20_2x_45s_532 nm_x100_100%_600 gr_mm
#Remark=
#Date=	19.07.2022 10:36
#Acquired=	19.07.2022 10:36:00
#Base:Fit=	10.08.2022 10:52:48
#Base:Sub=	10.08.2022 10:52:53
#Filter:Polynom=	16.08.2022 10:09:04
#AxisType[0]=Intens
#AxisUnit[0]=Cnt
#AxisType[1]=Spectr
#AxisUnit[1]=1/cm
200.423	24.2911
204.052	18.4901
207.682	14.9338
211.308	12.3192
214.935	10.4862
218.558	7.6522
222.18	6.7999
225.802	4.26061
229.421	4.51606
233.039	5.28848
236.657	3.38609
240.272	3.33674
243.885	3.7885
247.497	3.21101
251.11	2.27071
254.719	2.89754
258.327	1.64454
261.933	1.91379
265.538	0.867595
269.141	1.4479
272.744	1.00552
276.344	3.50567
279.944	5.62056
283.542	5.43905
287.138	6.08877
290.733	7.52113
294.327	9.51962
297.919	10.0085
301.508	12.5419
305.098	14.0644
308.686	13.653
312.273	15.9908
315.858	17.9449
319.44	19.0023
323.022	20.033
326.604	20.831
330.181	22.0076
333.76	23.1708
337.335	21.4345
340.91	20.4543
344.483	19.2587
348.055	16.9476
351.625	17.0335
355.195	16.4468
358.762	15.9179
362.329	14.5859
365.893	14.3955
369.455	14.4177
373.017	14.1048
376.578	13.5309
380.137	13.8161
383.694	16.0677
387.249	16.7273
390.806	17.0962
394.359	18.5305
397.91	21.7528
401.46	23.7711
405.009	24.235
408.557	25.3715
412.103	26.9683
415.647	26.4358
419.191	26.0216
422.733	27.3834
426.273	26.2719
429.812	24.7454
433.35	23.4405
436.885	22.6984
440.42	23.4022
443.954	22.5584
447.486	22.587
451.015	22.5907
454.545	23.8158
458.073	24.2917
461.598	25.9604
465.124	27.4515
468.648	30.5355
472.169	32.2607
475.69	33.1408
479.208	34.8429
482.727	36.7309
486.243	37.0168
489.759	37.7743
493.272	37.3538
496.783	37.1831
500.295	34.3641
503.804	35.4326
507.311	35.0468
510.819	34.145
514.324	31.6004
517.827	32.7956
521.329	32.9024
524.83	34.1786
528.329	34.3563
531.829	33.4131
535.326	33.0045
538.821	34.018
542.315	34.3853
545.808	33.3083
549.299	34.3045
552.789	33.7434
556.278	32.0916
559.763	30.1676
563.249	28.7697
566.733	25.5854
570.217	24.0125
573.699	21.2106
577.177	19.008
580.656	15.5346
584.134	13.0862
587.609	12.0471
591.084	8.33239
594.558	5.74594
598.029	2.68369
601.5	3.16743
604.968	4.11993
608.437	4.95564
611.902	5.64208
615.368	4.89427
618.831	4.32893
622.294	4.06678
625.755	5.57989
629.213	4.80925
632.673	6.41176
636.129	7.05468
639.584	7.21205
643.037	6.79594
646.491	7.76069
649.942	7.58373
653.392	6.55149
656.84	6.2092
660.287	5.6063
663.732	5.41939
667.177	6.96209
670.62	7.48399
674.061	8.98252
677.502	9.36093
680.941	11.3743
684.379	13.5453
687.815	17.1892
691.248	20.0747
694.682	22.0129
698.115	26.695
701.546	28.9562
704.974	33.3599
708.402	36.3817
711.83	41.6147
715.254	43.6147
718.679	47.0313
722.102	48.4366
725.522	48.6366
728.943	46.9639
732.361	48.1059
735.779	46.3822
739.194	45.4249
742.608	45.3317
746.022	44.7606
749.433	46.7031
752.843	47.7636
756.254	48.0711
759.661	48.1656
763.067	48.116
766.471	48.0678
769.877	48.3995
773.279	49.8049
776.68	49.815
780.079	53.2091
783.478	53.1018
786.875	53.8015
790.27	52.3448
793.665	53.7594
797.058	56.8427
800.45	57.5126
803.84	59.6766
807.23	58.2613
810.616	58.9368
814.002	59.811
817.388	61.3544
820.772	61.632
824.153	62.4778
827.535	61.9172
830.915	63.3154
834.292	63.7591
837.67	62.4625
841.047	58.8728
844.42	58.1033
847.794	57.1348
851.165	54.3352
854.534	51.5914
857.905	49.6985
861.272	46.0933
864.639	40.7929
868.004	37.8455
871.367	36.0683
874.731	35.8425
878.092	34.8215
881.451	32.2856
884.809	31.5027
888.166	30.9765
891.522	29.4189
894.878	29.0609
898.231	28.2728
901.583	27.9434
904.934	26.9271
908.283	27.1624
911.631	28.1224
914.976	28.9019
918.322	28.8844
921.666	30.0423
925.009	29.64
928.351	32.1666
931.692	33.1676
935.029	33.4937
938.367	34.2232
941.704	34.8072
945.038	36.4346
948.372	34.3286
951.705	35.197
955.035	36.7353
958.366	35.7581
961.693	33.7256
965.021	34.6936
968.346	36.3473
971.67	35.791
974.995	36.1829
978.316	33.9111
981.638	33.653
984.957	31.1229
988.274	30.2529
991.59	26.0468
994.907	18.4638
998.221	10.4472
1001.53	0.80113
1004.85	-4.32057
1008.16	0.0206249
1011.46	20.3552
1014.77	54.0345
1018.08	94.0967
1021.38	136.85
1024.69	178.306
1027.99	216.28
1031.29	250.444
1034.59	279.494
1037.89	302.121
1041.19	317.488
1044.48	329.688
1047.78	333.791
1051.07	330.471
1054.36	318.287
1057.66	300.704
1060.94	277.343
1064.23	245.65
1067.52	209.585
1070.81	168.057
1074.09	123.567
1077.38	77.8871
1080.66	40.9418
1083.94	11.0406
1087.22	-2.48924
1090.5	-1.41664
1093.77	5.72964
1097.05	12.8044
1100.32	20.3143
1103.6	24.623
1106.87	29.1096
1110.14	32.0524
1113.41	32.5669
1116.67	33.3383
1119.94	34.0178
1123.21	33.7255
1126.47	34.344
1129.73	31.88
1133	30.7855
1136.26	29.6891
1139.52	30.0263
1142.77	27.6717
1146.03	26.9849
1149.29	26.2067
1152.54	24.4636
1155.79	22.2796
1159.04	20.0837
1162.3	16.0522
1165.55	12.2455
1168.79	13.2394
1172.04	12.3668
1175.28	13.3929
1178.53	13.0683
1181.77	14.4447
1185.01	14.6904
1188.25	14.5491
1191.49	14.5369
1194.73	14.6714
1197.97	16.1519
1201.2	18.2073
1204.44	19.7538
1207.67	19.9908
1210.9	22.2339
1214.13	22.871
1217.36	26.492
1220.59	28.4287
1223.82	32.2588
1227.04	35.898
1230.26	38.6651
1233.49	42.281
1236.71	44.9326
1239.93	46.7967
1243.15	50.6847
1246.37	53.7517
1249.58	57.1335
1252.8	58.1227
1256.01	64.4144
1259.23	69.5422
1262.44	76.4643
1265.65	83.7319
1268.86	90.959
1272.07	94.4009
1275.27	98.9472
1278.48	103.925
1281.68	106.488
1284.89	109.492
1288.09	111.092
1291.29	111.472
1294.49	111.829
1297.69	112.717
1300.88	112.641
1304.08	114.211
1307.27	113.947
1310.47	113.423
1313.66	113.885
1316.85	111.524
1320.04	109.842
1323.23	109.331
1326.41	107.2
1329.6	104.947
1332.78	105.482
1335.97	106.183
1339.15	105.181
1342.33	105.505
1345.51	104.175
1348.69	99.8539
1351.87	98.8899
1355.04	95.8788
1358.22	94.3718
1361.39	91.2854
1364.57	87.2848
1367.74	83.1705
1370.91	78.2198
1374.07	74.1307
1377.24	70.223
1380.41	68.9506
1383.57	67.7101
1386.74	66.915
1389.9	66.7362
1393.06	68.4538
1396.22	69.034
1399.38	71.8189
1402.54	75.5212
1405.7	82.3611
1408.85	90.9838
1412.01	98.3262
1415.16	106.943
1418.31	118.64
1421.46	127.757
1424.61	140.786
1427.76	152.298
1430.91	165.6
1434.05	175.743
1437.2	184.403
1440.34	189.054
1443.49	194.568
1446.63	195.768
1449.77	195.021
1452.91	194.43
1456.04	191.48
1459.18	188.574
1462.31	185.243
1465.45	177.682
1468.58	171.355
1471.71	165.415
1474.84	156.653
1477.97	147.872
1481.1	140.489
1484.23	130.714
1487.35	122.277
1490.48	112.558
1493.6	103.855
1496.72	95.5013
1499.84	88.5059
1502.96	80.8051
1506.08	75.4396
1509.2	67.2444
1512.31	60.7614
1515.43	54.7059
1518.54	48.3646
1521.66	45.7483
1524.77	42.9465
1527.88	40.5657
1530.99	39.3929
1534.09	38.9257
1537.2	41.8208
1540.31	44.2365
1543.41	45.8343
1546.51	48.991
1549.62	49.964
1552.72	51.9234
1555.82	54.5448
1558.91	55.7696
1562.01	57.4302
1565.11	59.5343
1568.2	61.9258
1571.3	64.8926
1574.39	67.9734
1577.48	72.0651
1580.57	76.279
1583.66	79.5927
1586.75	80.6529
1589.83	84.9256
1592.92	86.6732
1596	88.2116
1599.09	88.3467
1602.17	89.5064
1605.25	89.1616
1608.33	85.9796
1611.41	86.1902
1614.48	84.6731
1617.56	83.7444
1620.64	84.3467
1623.71	83.3346
1626.78	83.3129
1629.86	83.6927
1632.92	83.8003
1635.99	85.1394
1639.06	85.7309
1642.13	88.0724
1645.19	89.5546
1648.26	89.8707
1651.32	92.8428
1654.38	92.6113
1657.45	92.9139
1660.51	91.1973
1663.57	90.2813
1666.62	88.2757
1669.68	83.0833
1672.73	80.0234
1675.79	76.7104
1678.84	72.4193
1681.89	66.5632
1684.94	61.3512
1687.99	56.6645
1691.04	50.969
1694.09	45.9844
1697.14	42.8226
1700.18	37.7291
1703.22	32.7559
1706.27	28.7857
1709.31	27.5801
1712.35	24.2157
1715.39	19.9103
1718.43	19.0008
1721.46	16.5686
1724.5	15.0313
1727.53	14.8992
1730.57	13.532
1733.6	12.8178
1736.63	10.789
1739.66	10.9347
1742.69	10.3634
1745.72	10.6092
1748.74	10.6705
1751.77	11.0616
1754.8	11.4675
1757.82	10.4125
1760.84	8.21954
1763.86	5.68553
1766.88	6.2369
1769.9	6.00067
1772.92	4.14766
1775.93	3.32671
1778.95	2.80272
1781.96	3.45444
1784.98	3.57376
1787.99	2.72232
1791	2.56671
1794.01	2.72236
1797.02	3.26429
1800.03	2.27508
1803.03	2.63274
1806.04	2.46619
1809.04	2.70385
1812.04	4.24837
1815.05	3.76586
1818.05	3.01817
1821.05	3.66995
1824.05	4.56176
1827.04	5.46426
1830.04	5.46627
1833.03	5.43944
1836.03	4.94844
1839.02	5.02404
1842.01	4.62799
1845	3.76028
1847.99	3.43725
1850.98	4.06617
1853.97	3.60369
1856.95	5.20712
1859.94	4.11109
1862.92	3.39063
1865.91	3.94341
1868.89	4.59585
1871.87	3.73279
1874.85	1.80267
1877.83	1.85658
1880.8	0.835231
1882.56	1.13699
1885.54	0.515109
1888.53	0.401107
1891.52	1.24764
1894.5	0.442133
1897.49	2.15524
1900.47	3.12117
1903.45	4.55617
1906.43	5.16262
1909.41	5.78525
1912.39	5.62026
1915.37	4.84882
1918.35	7.10594
1921.32	6.87074
1924.3	6.49973
1927.27	7.47056
1930.24	9.11207
1933.21	8.69984
1936.18	8.72197
1939.15	8.09127
1942.12	5.93838
1945.09	5.53513
1948.05	5.06509
1951.02	5.56483
1953.98	6.62681
1956.94	7.14815
1959.91	4.84824
1962.87	4.21997
1965.82	5.34167
1968.78	6.79261
1971.74	8.25
1974.7	8.1295
1977.65	8.27546
1980.6	7.5803
1983.56	8.39054
1986.51	8.94501
1989.46	9.01273
1992.41	8.62145
1995.36	8.29945
1998.3	9.39717
2001.25	10.8389
2004.2	11.0964
2007.14	9.86215
2010.08	7.73282
2013.02	7.99072
2015.97	8.19139
2018.9	7.3926
2021.84	8.43137
2024.78	9.04219
2027.72	8.17281
2030.65	8.02491
2033.59	8.32218
2036.52	10.3935
2039.45	12.2482
2042.38	13.4033
2045.31	12.6053
2048.24	13.2506
2051.17	14.0994
2054.1	16.0532
2057.02	17.6143
2059.95	18.9953
2062.87	19.8141
2065.79	22.2587
2068.71	23.6587
2071.63	24.6679
2074.55	24.0788
2077.47	24.1389
2080.39	24.659
2083.3	26.0671
2086.22	28.1286
2089.13	29.343
2092.05	30.3604
2094.96	32.9108
2097.87	34.0075
2100.78	36.1728
2103.69	39.0609
2106.59	42.4059
2109.5	44.6391
2112.41	46.5364
2115.31	48.525
2118.21	49.8479
2121.12	53.2329
2124.02	56.0532
2126.92	58.6667
2129.82	63.0793
2132.71	68.9042
2135.61	73.0461
2138.51	77.6094
2141.4	82.1867
2144.29	87.1246
2147.19	91.3275
2150.08	97.0476
2152.97	102.926
2155.86	107.774
2158.75	111.59
2161.64	115.643
2164.52	117.088
2167.41	119.199
2170.29	120.743
2173.17	121.376
2176.06	121.109
2178.94	120.952
2181.82	118.366
2184.7	114.967
2187.57	110.869
2190.45	107.055
2193.33	103.59
2196.2	99.9024
2199.08	97.675
2201.95	94.9182
2204.82	91.4744
2207.69	87.2391
2210.56	84.3101
2213.43	82.9695
2216.3	79.6588
2219.16	78.2982
2222.03	75.4609
2224.89	72.7913
2227.75	69.1294
2230.62	66.0641
2233.48	61.0868
2236.34	57.5349
2239.2	54.4292
2242.06	50.8207
2244.91	48.5596
2247.77	45.3011
2250.62	42.6236
2253.48	39.1083
2256.33	36.9709
2259.18	33.9113
2262.03	31.501
2264.88	29.2175
2267.73	28.1607
2270.58	25.6484
2273.43	24.4176
2276.27	23.8492
2279.12	23.6105
2281.96	22.9342
2284.8	21.401
2287.64	19.8649
2290.49	18.6904
2293.32	15.9596
2296.16	14.6586
2299	15.0731
2301.84	13.5804
2304.67	13.0242
2307.51	13.6986
2310.34	13.5605
2313.17	14.2878
2316	14.5033
2318.83	13.8854
2321.66	14.5897
2324.49	12.794
2327.32	12.1167
2330.15	11.4341
2332.97	10.7389
2335.79	10.1202
2338.62	9.41516
2341.44	8.92657
2344.26	8.70127
2347.08	8.05634
2349.9	7.17593
2352.72	6.8988
2355.53	6.94617
2358.35	7.15714
2361.17	6.04435
2363.98	4.88557
2366.79	7.10557
2369.6	7.29309
2372.42	8.20709
2375.22	7.71252
2378.03	7.46705
2380.84	7.26522
2383.65	6.0831
2386.45	4.63415
2389.26	4.76237
2392.06	3.79618
2394.87	4.16462
2397.67	5.24326
2400.47	4.29438
2403.27	4.79728
2406.07	5.43008
2408.86	5.76594
2411.66	6.01811
2414.46	6.63233
2417.25	7.50462
2420.05	8.25922
2422.84	8.14143
2425.63	8.90739
2428.42	8.09117
2431.21	9.33351
2434	9.37004
2436.79	9.06658
2439.57	7.17519
2442.36	8.01882
2445.14	6.40841
2447.93	6.08106
2450.71	4.11424
2453.49	3.76007
2456.27	3.89639
2459.05	4.42601
2461.83	4.40226
2464.61	4.00316
2467.39	3.02396
2470.16	3.49286
2472.94	3.42188
2475.71	3.26698
2478.48	3.19006
2481.25	2.58665
2484.02	2.45613
2486.8	3.12207
2489.56	3.21361
2492.33	2.94999
2495.1	4.01899
2497.86	3.92455
2500.63	2.66843
2503.39	1.06992
2506.16	1.02853
2508.92	1.53822
2511.68	0.239654
2514.44	-0.0942502
2517.2	0.305052
2519.95	-0.752388
2522.71	-1.38225
2525.47	-0.381984
2528.22	-0.0749188
2530.98	1.35642
2533.73	1.77565
2536.48	2.99991
2539.23	3.02042
2541.98	3.16222
2544.73	3.37116
2547.48	4.61745
2550.23	4.92842
2552.97	6.41622
2555.72	6.09502
2558.46	5.27443
2561.2	6.12203
2563.95	6.69124
2566.69	7.44369
2569.43	7.94189
2572.17	8.55573
2574.91	8.77527
2577.64	7.80419
2580.38	8.64682
2583.11	9.72717
2585.85	8.91265
2588.58	7.41873
2591.31	7.50614
2594.04	7.342
2596.78	8.30358
2599.51	9.1968
2602.23	8.07293
2604.96	6.2576
2607.69	6.13809
2610.41	6.4511
2613.14	5.7197
2615.86	5.53516
2618.58	5.40024
2621.3	4.96258
2624.03	4.68369
2626.75	5.30876
2629.46	6.36743
2632.18	7.11722
2634.9	7.86851
2637.61	8.52278
2640.33	8.82918
2643.04	8.91521
2645.76	9.38966
2648.47	9.23233
2651.18	8.3968
2653.89	8.16641
2656.6	7.73985
2659.31	8.55206
2662.01	10.9995
2664.72	12.4266
2667.43	12.6069
2670.13	12.921
2672.83	13.0731
2675.53	12.5872
2678.24	13.9076
2680.94	13.8383
2683.64	15.1629
2686.34	15.9037
2689.03	16.6151
2691.73	18.95
2694.43	18.1804
2697.12	18.941
2699.81	21.1343
2702.51	21.0055
2705.2	20.4255
2707.89	20.1408
2710.58	19.6491
2713.27	19.4939
2715.96	19.1952
2718.64	19.1471
2721.33	18.0986
2724.01	17.4283
2726.7	18.1039
2729.38	17.2626
2732.06	17.2824
2734.75	15.2889
2737.43	13.3227
2740.11	12.1753
2742.78	12.0534
2745.46	11.3813
2748.14	11.4316
2750.81	11.1147
2753.49	9.20021
2756.16	7.20869
2758.84	6.20325
2761.51	4.44292
2764.18	4.34738
2766.85	3.56566
2769.52	3.14765
2772.19	2.92765
2774.85	1.57428
2777.52	1.25274
2780.18	0.839547
2782.85	0.229156
2785.51	-0.192984
2788.17	0.276973
2790.84	0.589499
2793.5	0.875669
2796.16	2.25936
2798.81	2.16959
2801.47	2.06767
2804.13	2.25245
2806.79	1.70324
2809.44	1.15326
2812.09	1.40448
2814.75	3.13986
2817.4	8.08058
2820.05	16.2751
2822.7	27.3854
2825.35	40.2565
2828	53.2888
2830.65	69.1111
2833.29	84.7202
2835.94	101.298
2838.58	116.784
2841.23	132.903
2843.87	147.58
2846.51	161.126
2849.15	176.736
2851.79	194.299
2854.43	213.481
2857.07	230.316
2859.71	246.204
2862.34	260.927
2864.98	271.932
2867.61	280.39
2870.25	287.055
2872.88	291.359
2875.51	296.016
2878.14	302.778
2880.77	309.846
2883.4	314.657
2886.03	317.847
2888.65	321.026
2891.28	322.087
2893.91	323.05
2896.53	323.806
2899.15	325.421
2901.78	326.624
2904.4	328.735
2907.02	332.021
2909.64	335.831
2912.26	344.968
2914.87	356.436
2917.49	367.125
2920.11	376.643
2922.72	381.969
2925.34	388.079
2927.95	392.145
2930.56	394.088
2933.17	393.522
2935.78	390.038
2938.39	384.39
2941	377.578
2943.61	367.532
2946.22	356.343
2948.82	342.204
2951.43	326.062
2954.03	309.813
2956.64	292.529
2959.24	277.28
2961.84	260.344
2964.44	244.882
2967.04	229.321
2969.64	214.709
2972.24	201.158
2974.83	187.926
2977.43	174.071
2980.02	161.174
2982.62	147.653
2985.21	133.831
2987.8	122.591
2990.4	110.983
2992.99	100.772
2995.57	90.372
2998.16	80.2105
3000.75	70.1585
3003.34	61.4381
3005.92	53.2925
3008.51	44.8273
3011.09	37.1593
3013.68	29.5177
3016.26	22.8409
3018.84	18.4918
3021.42	14.3582
3024	10.5509
3026.58	7.39374
3029.16	5.05907
3031.73	3.55637
3034.31	3.3114
3036.89	3.00595
3039.46	2.03701
3042.03	0.628175
3044.61	0.871168
3047.18	0.248307
3049.75	1.61579
3052.32	2.99487
3054.89	3.79987
3057.45	5.50172
3060.02	5.40937
3062.59	5.15372
3065.15	4.81072
3067.72	5.00487
3070.28	5.17875
3072.84	3.86456
3075.41	2.82983
3077.97	2.44704
3080.53	2.15397
3083.09	1.21884
3085.64	0.881887
3088.2	1.18582
3090.76	1.03402
3093.31	-0.00487648
3095.87	0.0481802
3098.42	0.619355
3100.97	0.0346564
3103.53	-0.0959156
3106.08	0.593045
3108.63	2.28746
3111.18	3.27379
3113.73	4.71073
3116.27	5.57272
3118.82	7.55595
3121.37	9.63037
3123.91	10.3137
3126.45	13.1214
3129	14.4975
3131.54	16.8325
3134.08	18.8367
3136.62	20.5284
3139.16	23.3695
3141.7	25.369
3144.24	27.588
3146.78	29.7958
3149.31	31.2712