File: data/Raman/poly_smoothed/Mb_40_24_49_1x_45s_532 nm_x100_100%_600 gr_mm_01.txt
#Acq. time (s)=	45
#Accumulations=	2
#Range (cm-¹)=	200...3150
#Windows=	2
#Auto scanning=	Off
#Autofocus=	Off
#Macrospot=	Off
#AutoExposure=	Off
#Spike filter=	Multiple accum.
#Delay time (s)=	0
#Binning=	1
#Readout mode=	Signal
#DeNoise=	Off
#ICS correction=	On
#Dark correction=	Off
#Inst. Process=	Off
#Detector Gain=	Best Dynamic Range
#Detector ADC=	20 kHz
#Detector temperature (°C)=	-70.08
#Instrument=	LabRAM HR Evol
#Detector=	Synapse
#Objective=	x100
#Grating=	600 gr/mm
#ND Filter=	100%
#Laser (nm)=	532
#Hole=	100.021
#Range=	Auto
#Laser Pol.=	No
#Raman. Pol.=	No
#Laser Pol. (°)=	-0.0007625
#Raman Pol. (°)=	89.9995
#Collection=	Microscope
#StageXY=	Marzhauser
#StageZ=	Marzhauser
#X (µm)=	-2446.7
#Y (µm)=	-59.7
#Z (µm)=	-10.15
#Full time(mm:ss)=	3:19
#Project=
#Sample=
#Site=
#Title=	Mb_40_24_49_2x_45s_532 nm_x100_100%_600 gr_mm
#Remark=
#Date=	14.07.2022 14:28
#Acquired=	14.07.2022 14:28:25
#Base:Fit=	10.08.2022 10:47:00
#Base:Sub=	10.08.2022 10:47:12
#Filter:Polynom=	16.08.2022 10:11:48
#AxisType[0]=Intens
#AxisUnit[0]=Cnt
#AxisType[1]=Spectr
#AxisUnit[1]=1/cm
200.554	38.1031
204.183	29.3347
207.813	23.1918
211.439	20.4053
215.065	19.7169
218.688	20.3744
222.312	21.2842
225.933	22.3573
229.552	22.2531
233.171	20.4555
236.787	19.1524
240.402	20.2209
244.015	19.1203
247.627	18.9714
251.24	19.5161
254.849	20.2481
258.457	19.8293
262.063	18.6445
265.668	19.4348
269.271	22.5651
272.873	21.0007
276.474	18.9392
280.073	14.9975
283.671	14.45
287.268	12.9977
290.863	12.7371
294.456	13.4497
298.049	13.0059
301.637	15.6234
305.227	15.6153
308.815	16.6025
312.402	17.8286
315.987	19.2615
319.569	18.7003
323.151	18.4797
326.733	19.7916
330.31	18.321
333.889	18.5808
337.464	18.6986
341.039	18.6322
344.611	16.5992
348.184	14.7394
351.754	13.2775
355.324	15.6069
358.89	13.7435
362.455	12.7983
366.021	11.4281
369.584	12.2932
373.145	11.7111
376.707	10.9897
380.265	9.56586
383.822	9.95079
387.378	11.1752
390.934	13.4579
394.487	13.7894
398.038	15.0401
401.588	16.3868
405.137	16.9457
408.685	16.8061
412.23	15.5411
415.775	14.8493
419.318	13.3982
422.86	10.6058
426.401	8.56446
429.94	7.61
433.478	6.6892
437.012	6.28775
440.547	7.14163
444.081	7.71332
447.613	8.58907
451.142	9.59876
454.672	11.0454
458.2	12.7075
461.725	13.75
465.251	16.0495
468.775	17.6927
472.296	21.3505
475.817	23.6817
479.335	24.8011
482.854	27.0171
486.37	29.2954
489.886	31.2466
493.398	31.7269
496.91	33.1368
500.422	33.2585
503.93	33.9455
507.438	34.0107
510.946	34.2865
514.45	35.3604
517.954	35.5336
521.456	34.1281
524.956	34.0623
528.456	34.1599
531.956	33.3197
535.452	32.6101
538.947	30.7505
542.441	30.3921
545.934	30.1577
549.425	27.8587
552.915	25.8869
556.403	24.4972
559.889	22.0131
563.375	20.2073
566.859	16.4077
570.342	14.7442
573.824	12.5159
577.303	10.758
580.782	9.72229
584.26	7.94085
587.734	6.6321
591.21	5.24775
594.684	4.85254
598.154	4.14426
601.626	5.29026
605.094	4.51424
608.562	6.4448
612.027	6.63689
615.493	8.08629
618.956	8.27697
622.419	6.81895
625.879	8.12303
629.338	10.2319
632.797	11.5405
636.254	10.0378
639.708	11.4818
643.162	11.4963
646.614	11.7645
650.067	10.7736
653.516	10.913
656.964	12.0127
660.411	12.0996
663.857	13.0663
667.301	13.3018
670.744	12.3773
674.186	12.6046
677.626	14.073
681.065	15.7283
684.503	17.5386
687.939	18.7707
691.372	19.7409
694.806	19.8063
698.239	21.3165
701.67	21.4205
705.098	21.4409
708.526	22.0657
711.954	23.5795
715.378	24.6328
718.802	25.2774
722.226	25.0791
725.646	25.6594
729.067	27.1507
732.484	29.1536
735.902	30.6974
739.317	32.4507
742.731	33.7027
746.145	35.1531
749.556	36.405
752.966	37.0262
756.377	40.2064
759.784	43.278
763.19	45.4731
766.594	47.3836
770	49.6013
773.402	51.5926
776.803	53.1695
780.202	54.8022
783.6	55.6417
786.997	58.5991
790.393	61.4327
793.787	63.9286
797.18	66.4979
800.572	67.1371
803.963	66.7917
807.35	68.2312
810.738	68.8935
814.125	69.7182
817.51	68.7748
820.894	65.9325
824.275	66.2169
827.657	66.0189
831.037	67.6303
834.414	64.4038
837.792	62.9858
841.167	61.4899
844.542	60.5016
847.914	57.7862
851.287	57.7363
854.656	56.3831
858.026	55.0825
861.393	54.9471
864.761	53.765
868.125	53.0551
871.489	55.0794
874.85	55.1752
878.213	55.7189
881.572	53.4894
884.931	51.8093
888.287	51.9296
891.643	51.2091
894.997	50.4928
898.352	49.7949
901.704	49.045
905.055	50.8814
908.404	50.6294
911.75	50.6248
915.097	49.7929
918.443	47.0825
921.787	47.7145
925.13	48.8125
928.472	48.3369
931.813	46.1596
935.15	43.7313
938.488	42.0871
941.825	40.6561
945.158	37.9071
948.493	36.2175
951.824	36.6462
955.156	36.3863
958.486	34.859
961.814	32.7999
965.142	32.3515
968.467	33.7599
971.79	34.1881
975.115	35.9605
978.436	36.4986
981.756	39.9945
985.077	40.5837
988.394	41.9772
991.71	41.942
995.025	41.8638
998.341	43.4967
1001.65	44.7529
1004.97	46.7769
1008.28	48.9612
1011.58	50.0231
1014.89	52.5868
1018.2	55.5795
1021.5	59.3396
1024.81	62.5956
1028.11	64.1461
1031.41	68.0254
1034.71	70.0216
1038.01	70.9691
1041.31	69.7411
1044.6	71.6055
1047.9	72.5819
1051.19	70.6504
1054.48	69.148
1057.77	68.6575
1061.06	65.0265
1064.35	61.6278
1067.64	56.2841
1070.93	51.7418
1074.21	46.5916
1077.49	43.0053
1080.78	40.962
1084.06	38.7
1087.34	36.6114
1090.61	36.3467
1093.89	36.0544
1097.17	35.5488
1100.44	36.3003
1103.71	36.9685
1106.99	35.0968
1110.26	34.0744
1113.52	34.4436
1116.79	31.731
1120.06	29.7543
1123.32	29.4947
1126.59	27.9178
1129.85	26.0097
1133.11	21.9856
1136.37	19.9768
1139.63	18.8923
1142.89	14.8943
1146.15	13.3891
1149.4	10.6492
1152.66	8.32221
1155.91	5.69695
1159.16	5.19025
1162.41	4.08067
1165.66	1.71601
1168.91	1.38566
1172.16	2.31861
1175.4	3.9829
1178.65	4.48664
1181.89	5.3879
1185.13	7.60622
1188.37	11.4724
1191.61	12.812
1194.85	15.0643
1198.08	17.9189
1201.32	19.2085
1204.55	21.7673
1207.79	24.4436
1211.02	28.7599
1214.25	34.4225
1217.48	40.4741
1220.71	44.1161
1223.93	49.0534
1227.16	54.422
1230.38	57.8685
1233.6	60.8439
1236.83	65.4924
1240.05	69.3529
1243.26	72.1639
1246.48	75.5226
1249.7	80.0858
1252.92	83.2573
1256.13	86.4253
1259.34	90.2125
1262.55	94.9002
1265.76	99.698
1268.97	101.404
1272.18	103.389
1275.39	104.277
1278.59	105.856
1281.8	108.469
1285	112.633
1288.2	115.442
1291.4	116.903
1294.6	118.64
1297.8	117.945
1301	117.149
1304.19	118.883
1307.39	118.129
1310.58	115.279
1313.77	112.773
1316.96	112.269
1320.15	110.393
1323.34	107.962
1326.53	106.116
1329.72	104.813
1332.9	102.728
1336.08	99.7144
1339.27	96.5791
1342.45	92.7221
1345.63	89.1397
1348.8	85.3574
1351.98	81.1491
1355.16	77.7669
1358.33	74.4508
1361.51	71.9579
1364.68	70.3079
1367.85	68.3338
1371.02	65.1243
1374.19	63.7787
1377.36	63.5178
1380.52	65.2282
1383.69	65.2942
1386.85	64.8039
1390.02	65.124
1393.18	67.9156
1396.34	65.7336
1399.5	69.3691
1402.65	73.6918
1405.81	80.7783
1408.97	88.8018
1412.12	95.8557
1415.27	103.993
1418.43	111.458
1421.58	119.546
1424.73	127.521
1427.87	135.745
1431.02	142.942
1434.17	149.332
1437.31	156.735
1440.46	159.945
1443.6	164.718
1446.74	166.353
1449.88	164.88
1453.02	162.617
1456.16	158.834
1459.29	153.851
1462.43	145.55
1465.56	136.259
1468.69	125.8
1471.83	113.015
1474.95	104.384
1478.08	97.0306
1481.21	89.7839
1484.34	81.0621
1487.47	72.0584
1490.59	63.1512
1493.71	55.1502
1496.84	47.7878
1499.96	42.6149
1503.07	38.5661
1506.19	35.4855
1509.31	33.8011
1512.43	31.4532
1515.54	28.7584
1518.65	28.3847
1521.77	29.3881
1524.88	27.5455
1527.99	28.4722
1531.1	31.258
1534.21	32.4824
1537.31	34.4518
1540.42	37.4677
1543.52	41.0658
1546.63	42.9176
1549.73	46.0023
1552.83	50.0219
1555.93	53.6383
1559.03	55.8758
1562.12	57.888
1565.22	61.5382
1568.31	64.5462
1571.41	68.7086
1574.5	72.5504
1577.59	77.2052
1580.68	81.904
1583.77	86.3694
1586.86	89.388
1589.95	90.8874
1593.03	92.8977
1596.11	90.8771
1599.2	91.408
1602.28	95.6037
1605.36	99.4369
1608.44	101.892
1611.52	104.173
1614.6	108.391
1617.67	110.29
1620.75	113.874
1623.82	117.765
1626.89	121.516
1629.96	124.199
1633.04	126.975
1636.11	131.332
1639.17	134.554
1642.24	137.671
1645.31	139.766
1648.37	141.296
1651.43	142.769
1654.5	141.775
1657.56	140.873
1660.62	136.904
1663.67	130.737
1666.73	123.412
1669.79	114.328
1672.84	107.325
1675.9	104.835
1678.95	97.2722
1682	88.498
1685.05	80.07
1688.1	72.5191
1691.15	63.2765
1694.2	55.5311
1697.25	49.3628
1700.29	43.9352
1703.33	38.2637
1706.38	33.4347
1709.42	29.2411
1712.46	25.7801
1715.5	22.5739
1718.54	21.5956
1721.57	20.0337
1724.61	19.5384
1727.64	18.8861
1730.68	18.0929
1733.71	18.0314
1736.74	18.0113
1739.77	17.7214
1742.8	17.2974
1745.83	16.7783
1748.85	15.7482
1751.88	14.1903
1754.91	13.5035
1757.93	12.6161
1760.95	11.3897
1763.97	9.31729
1766.99	7.8721
1770.01	6.3055
1773.03	5.65678
1776.04	4.61101
1779.06	3.07906
1782.07	2.96487
1785.09	2.02581
1788.1	2.27124
1791.11	1.57097
1794.12	1.47535
1797.13	1.51653
1800.13	2.83239
1803.14	2.74655
1806.15	2.82854
1809.15	3.13424
1812.15	3.98619
1815.16	4.20274
1818.15	3.30232
1821.16	2.81989
1824.15	2.73782
1827.15	2.62182
1830.15	2.15322
1833.14	2.86815
1836.14	2.33152
1839.13	1.27569
1842.12	0.109595
1845.11	-0.152061
1848.1	-0.348582
1851.09	-0.189462
1854.08	-0.0563051
1857.06	0.0407087
1860.05	1.12483
1863.03	1.83668
1866.01	2.0861
1869	3.12851
1871.98	4.66844
1874.96	5.31749
1877.93	5.15741
1880.91	5.76493
1882.47	6.77162
1885.46	7.40328
1888.44	7.75577
1891.43	7.65041
1894.42	8.81151
1897.4	8.91409
1900.39	7.91555
1903.37	7.10492
1906.35	5.40483
1909.33	4.48235
1912.31	3.553
1915.29	2.39615
1918.26	2.21651
1921.24	2.43541
1924.21	0.818819
1927.19	0.416604
1930.16	0.779893
1933.13	1.50173
1936.1	0.91376
1939.07	0.581877
1942.04	0.936206
1945	1.88789
1947.97	1.84557
1950.93	3.1482
1953.9	4.23383
1956.86	4.62322
1959.82	4.32788
1962.78	5.08048
1965.74	4.70581
1968.7	4.91255
1971.65	4.55731
1974.61	3.84999
1977.57	4.24113
1980.52	5.11889
1983.47	5.48941
1986.42	4.96052
1989.37	4.59108
1992.32	4.07634
1995.27	3.9646
1998.22	3.24329
2001.17	2.8352
2004.11	2.58875
2007.05	2.69549
2010	1.43311
2012.94	2.18401
2015.88	3.16661
2018.82	3.41956
2021.76	4.87393
2024.7	5.64116
2027.63	5.5907
2030.57	5.85429
2033.5	6.8925
2036.44	8.31336
2039.37	8.67379
2042.3	10.9514
2045.23	12.3443
2048.16	13.7044
2051.08	14.8929
2054.01	15.3181
2056.94	16.2839
2059.86	16.211
2062.79	16.8747
2065.71	18.4975
2068.63	18.3521
2071.55	19.6997
2074.47	20.605
2077.39	21.6444
2080.31	23.9484
2083.22	26.0458
2086.13	28.3577
2089.05	30.9684
2091.96	33.3495
2094.87	35.8807
2097.78	39.0586
2100.69	41.7068
2103.6	45.8921
2106.51	49.9565
2109.42	54.173
2112.32	59.1106
2115.23	63.4956
2118.13	68.2092
2121.03	72.4261
2123.93	77.3183
2126.83	82.3723
2129.73	88.2084
2132.63	93.0225
2135.53	99.0092
2138.42	103.954
2141.32	108.478
2144.21	114.647
2147.1	119.538
2150	124.373
2152.89	128.229
2155.78	131.32
2158.66	134.815
2161.55	137.91
2164.44	138.592
2167.32	139.381
2170.21	139.743
2173.09	140.02
2175.97	140.282
2178.85	138.416
2181.73	136.662
2184.61	134.022
2187.49	129.966
2190.37	126.541
2193.24	121.602
2196.12	117.519
2198.99	113.419
2201.87	107.6
2204.74	102.882
2207.61	98.2211
2210.48	92.4362
2213.35	87.3363
2216.21	82.8246
2219.08	78.0632
2221.95	72.1777
2224.81	68.1005
2227.67	63.3219
2230.54	58.2435
2233.4	54.0423
2236.26	49.7422
2239.11	45.8192
2241.97	42.9291
2244.83	39.4727
2247.69	36.7451
2250.54	33.7526
2253.4	31.2674
2256.25	28.8342
2259.1	27.4513
2261.95	25.9854
2264.8	23.6859
2267.65	22.6191
2270.5	21.0512
2273.34	19.696
2276.19	17.966
2279.03	16.3509
2281.88	14.903
2284.72	14.4225
2287.56	12.5849
2290.4	10.6336
2293.24	8.34288
2296.08	7.88439
2298.92	6.80251
2301.76	6.65463
2304.59	6.05299
2307.43	5.6031
2310.26	5.641
2313.09	5.25415
2315.92	6.19536
2318.75	6.99991
2321.58	7.04946
2324.41	6.64307
2327.24	5.98681
2330.06	6.97972
2332.89	7.30067
2335.71	6.99389
2338.54	7.58659
2341.36	7.6125
2344.18	6.1238
2347	5.1909
2349.82	3.83549
2352.64	3.12935
2355.45	1.90417
2358.27	0.480916
2361.08	-0.385625
2363.9	-0.860825
2366.71	0.0503845
2369.52	-0.536843
2372.33	-1.16462
2375.14	-0.64403
2377.95	-1.37669
2380.76	-0.949297
2383.57	0.789586
2386.37	0.252351
2389.18	-0.605343
2391.98	-1.10123
2394.79	-0.554201
2397.59	0.525041
2400.39	0.557595
2403.19	1.42409
2405.99	2.46092
2408.78	2.98829
2411.58	2.5632
2414.38	1.49526
2417.17	1.46152
2419.97	1.54159
2422.76	1.8536
2425.55	1.64555
2428.34	1.96654
2431.13	2.21179
2433.92	2.85585
2436.71	3.33753
2439.49	3.75573
2442.28	4.33551
2445.06	3.95634
2447.85	5.15631
2450.63	5.54202
2453.41	5.11548
2456.19	4.52125
2458.97	5.85178
2461.75	6.51816
2464.53	6.78761
2467.31	5.6756
2470.08	6.35584
2472.86	6.65307
2475.63	6.49989
2478.4	6.03514
2481.17	5.36607
2483.94	5.02737
2486.72	4.54014
2489.48	4.24662
2492.25	4.56295
2495.02	4.88491
2497.79	3.74987
2500.55	4.34488
2503.31	4.18751
2506.08	3.76913
2508.84	3.89097
2511.6	4.27154
2514.36	3.98837
2517.12	3.57941
2519.88	2.88948
2522.63	2.55765
2525.39	2.9596
2528.14	3.6339
2530.9	3.49132
2533.65	3.16124
2536.4	3.76475
2539.15	3.74502
2541.9	3.77838
2544.65	4.32443
2547.4	5.51909
2550.15	5.18563
2552.89	4.99274
2555.64	6.1952
2558.38	7.29138
2561.12	7.283
2563.87	7.46603
2566.61	7.18603
2569.35	6.89857
2572.09	6.37689
2574.83	6.4373
2577.56	6.12142
2580.3	5.86795
2583.04	5.43398
2585.77	6.10827
2588.5	6.13009
2591.23	5.58547
2593.97	5.40426
2596.7	5.64226
2599.43	4.72677
2602.15	5.06155
2604.88	4.51516
2607.61	4.4854
2610.33	4.82791
2613.06	5.0368
2615.78	4.96743
2618.51	4.84628
2621.23	5.98492
2623.95	5.98373
2626.67	6.44754
2629.39	7.01291
2632.1	6.46357
2634.82	6.35288
2637.54	5.87779
2640.25	5.71848
2642.97	6.29982
2645.68	6.49191
2648.39	7.0046
2651.1	8.099
2653.81	7.79163
2656.52	6.64415
2659.23	6.38051
2661.94	6.98902
2664.64	7.55462
2667.35	8.53426
2670.05	8.18929
2672.76	8.00875
2675.46	8.50162
2678.16	8.32683
2680.86	8.22781
2683.56	8.52259
2686.26	9.83261
2688.96	11.1924
2691.65	11.8275
2694.35	12.411
2697.04	11.8106
2699.74	10.8839
2702.43	11.8866
2705.12	11.4528
2707.81	11.8648
2710.5	11.9211
2713.19	11.632
2715.88	12.3042
2718.57	12.9867
2721.25	13.1515
2723.94	13.7582
2726.62	14.9232
2729.3	15.2075
2731.99	15.127
2734.67	14.1611
2737.35	13.324
2740.03	12.404
2742.71	11.8464
2745.38	10.0318
2748.06	9.26681
2750.74	9.52832
2753.41	9.22206
2756.09	7.9991
2758.76	7.47894
2761.43	6.59075
2764.1	6.42304
2766.77	6.64696
2769.44	5.93762
2772.11	5.95015
2774.77	5.34044
2777.44	4.31834
2780.11	4.6127
2782.77	4.48945
2785.43	4.10088
2788.1	4.31092
2790.76	4.40396
2793.42	4.06105
2796.08	2.99579
2798.74	2.30643
2801.4	1.0996
2804.05	0.096105
2806.71	-0.545649
2809.36	-2.19323
2812.02	-1.84389
2814.67	-1.06098
2817.32	0.430559
2819.97	3.33182
2822.62	7.31757
2825.27	12.4146
2827.92	18.6143
2830.57	25.8194
2833.22	34.0672
2835.86	43.0294
2838.51	52.1984
2841.15	63.2979
2843.79	74.2606
2846.43	87.2584
2849.08	100.932
2851.72	115.229
2854.36	129.547
2856.99	144.266
2859.63	157.205
2862.27	169.88
2864.9	180.65
2867.54	191.603
2870.17	201.409
2872.8	209.896
2875.43	217.531
2878.07	226.302
2880.7	233.936
2883.32	241.549
2885.95	250.384
2888.58	259.036
2891.21	266.987
2893.83	277.429
2896.46	288.613
2899.08	301.302
2901.7	313.383
2904.32	328.382
2906.94	344.762
2909.56	362.639
2912.18	381.107
2914.8	398.528
2917.42	415.338
2920.03	429.278
2922.65	440.846
2925.26	450.089
2927.88	456.27
2930.49	458.392
2933.1	457.884
2935.71	453.085
2938.32	445.074
2940.93	435.604
2943.54	423.55
2946.14	406.86
2948.75	389.929
2951.35	372.97
2953.96	352.943
2956.56	334.26
2959.16	314.279
2961.77	295.505
2964.37	277.72
2966.96	259.518
2969.56	243.739
2972.16	229.875
2974.76	214.76
2977.35	200.295
2979.95	185.727
2982.54	172.087
2985.14	156.781
2987.73	143.353
2990.32	129.761
2992.91	115.422
2995.5	102.748
2998.09	90.251
3000.68	78.0855
3003.26	66.9388
3005.85	57.1135
3008.43	47.4964
3011.02	38.9158
3013.6	32.216
3016.19	26.4199
3018.77	20.1388
3021.35	14.8018
3023.93	11.9975
3026.5	9.04665
3029.08	6.41625
3031.66	5.33933
3034.24	4.40819
3036.81	3.82697
3039.39	4.35301
3041.96	4.6162
3044.53	5.23408
3047.1	4.9472
3049.67	5.57266
3052.24	6.11677
3054.81	6.05555
3057.38	6.43253
3059.95	6.40414
3062.52	6.62971
3065.08	6.54033
3067.65	5.44833
3070.21	4.94835
3072.77	4.51034
3075.33	3.49364
3077.89	2.72432
3080.45	1.47757
3083.01	0.0371058
3085.57	-0.191904
3088.13	-1.18054
3090.68	-1.97785
3093.24	-2.27888
3095.79	-1.66866
3098.35	-1.92163
3100.9	-0.499381
3103.45	0.658173
3106	1.75105
3108.55	4.04267
3111.1	6.32118
3113.65	8.50519
3116.2	11.0315
3118.75	12.8862
3121.29	14.85
3123.84	17.7942
3126.38	19.9015
3128.92	21.7934
3131.47	24.07
3134.01	26.6895
3136.55	28.4015
3139.09	30.2193
3141.63	30.7813
3144.17	31.5391
3146.7	31.8393
3149.24	32.1364