File: data/Raman/poly_smoothed/Mb_40_y_30_1x_45s_532 nm_x100_100%_600 gr_mm_01.txt
#Acq. time (s)=	45
#Accumulations=	2
#Range (cm-¹)=	200...3150
#Windows=	2
#Auto scanning=	Off
#Autofocus=	Off
#Macrospot=	Off
#AutoExposure=	Off
#Spike filter=	Multiple accum.
#Delay time (s)=	0
#Binning=	1
#Readout mode=	Signal
#DeNoise=	Off
#ICS correction=	On
#Dark correction=	Off
#Inst. Process=	Off
#Detector Gain=	Best Dynamic Range
#Detector ADC=	20 kHz
#Detector temperature (°C)=	-69.85
#Instrument=	LabRAM HR Evol
#Detector=	Synapse
#Objective=	x100
#Grating=	600 gr/mm
#ND Filter=	100%
#Laser (nm)=	532
#Hole=	100.021
#Range=	Auto
#Laser Pol.=	No
#Raman. Pol.=	No
#Laser Pol. (°)=	-0.0007625
#Raman Pol. (°)=	89.9995
#Collection=	Microscope
#StageXY=	Marzhauser
#StageZ=	Marzhauser
#X (µm)=	-1105.8
#Y (µm)=	563.5
#Z (µm)=	584.3
#Full time(mm:ss)=	3:18
#Project=
#Sample=
#Site=
#Title=	Mb_40_y_30_2x_45s_532 nm_x100_100%_600 gr_mm
#Remark=
#Date=	19.07.2022 11:55
#Acquired=	19.07.2022 11:55:32
#Base:Fit=	10.08.2022 10:52:48
#Base:Sub=	10.08.2022 10:52:53
#Filter:Polynom=	16.08.2022 10:09:04
#AxisType[0]=Intens
#AxisUnit[0]=Cnt
#AxisType[1]=Spectr
#AxisUnit[1]=1/cm
200.423	36.7917
204.052	25.8849
207.682	19.2457
211.308	13.3436
214.935	8.60189
218.558	5.73582
222.18	2.60217
225.802	0.44975
229.421	0.198487
233.039	1.17322
236.657	3.48607
240.272	5.0557
243.885	6.45123
247.497	8.02791
251.11	11.0829
254.719	12.7521
258.327	15.832
261.933	18.4253
265.538	20.435
269.141	23.3751
272.744	24.3927
276.344	24.8498
279.944	25.9226
283.542	26.9675
287.138	28.2179
290.733	28.1899
294.327	28.5894
297.919	28.4973
301.508	29.1113
305.098	29.3765
308.686	28.7403
312.273	27.2331
315.858	27.7138
319.44	27.4234
323.022	26.4126
326.604	26.9968
330.181	25.4361
333.76	24.3121
337.335	24.8948
340.91	25.1618
344.483	25.8512
348.055	23.9765
351.625	25.0869
355.195	22.9345
358.762	22.1427
362.329	19.9163
365.893	20.1671
369.455	21.1385
373.017	20.0793
376.578	19.9511
380.137	19.6427
383.694	19.267
387.249	19.4434
390.806	19.443
394.359	19.0199
397.91	16.2765
401.46	17.0672
405.009	18.6655
408.557	18.9874
412.103	20.7611
415.647	20.518
419.191	21.2421
422.733	21.9734
426.273	20.4179
429.812	18.832
433.35	17.5553
436.885	16.7009
440.42	16.5105
443.954	15.4007
447.486	15.2256
451.015	14.1839
454.545	13.958
458.073	12.3847
461.598	11.1964
465.124	11.3417
468.648	11.0742
472.169	11.4539
475.69	12.5429
479.208	14.316
482.727	15.4324
486.243	16.6877
489.759	18.9693
493.272	18.9256
496.783	19.1747
500.295	19.7556
503.804	19.4421
507.311	18.6304
510.819	17.5518
514.324	16.2713
517.827	15.651
521.329	15.3112
524.83	14.6444
528.329	15.171
531.829	14.5108
535.326	12.2765
538.821	9.17268
542.315	8.31947
545.808	6.35165
549.299	5.78699
552.789	4.40306
556.278	4.7205
559.763	4.04923
563.249	4.25575
566.733	3.42526
570.217	4.24765
573.699	3.89429
577.177	3.27443
580.656	3.55623
584.134	3.88796
587.609	4.66057
591.084	5.03893
594.558	5.53852
598.029	6.07309
601.5	7.18972
604.968	8.008
608.437	8.95219
611.902	9.04324
615.368	8.379
618.831	6.80628
622.294	7.38089
625.755	9.43507
629.213	9.35721
632.673	9.51677
636.129	9.41021
639.584	9.43114
643.037	9.65472
646.491	10.5992
649.942	9.69362
653.392	10.7868
656.84	11.7827
660.287	11.6129
663.732	12.879
667.177	13.3845
670.62	15.0172
674.061	16.3473
677.502	17.7622
680.941	20.242
684.379	21.3707
687.815	22.3859
691.248	25.0963
694.682	24.6249
698.115	23.8
701.546	25.8693
704.974	27.9125
708.402	29.5047
711.83	30.7706
715.254	29.935
718.679	31.0164
722.102	31.1083
725.522	31.3013
728.943	32.0653
732.361	31.5234
735.779	32.2194
739.194	34.3133
742.608	34.6626
746.022	35.0233
749.433	37.6414
752.843	40.1404
756.254	43.336
759.661	43.8534
763.067	46.6144
766.471	48.8998
769.877	49.4449
773.279	51.597
776.68	54.1473
780.079	54.9612
783.478	58.8282
786.875	61.5932
790.27	64.8565
793.665	65.0102
797.058	65.954
800.45	67.0143
803.84	68.3202
807.23	67.9382
810.616	68.3248
814.002	68.5451
817.388	68.0609
820.772	67.0964
824.153	66.2966
827.535	64.4083
830.915	63.8324
834.292	63.0209
837.67	59.5966
841.047	57.4043
844.42	55.2209
847.794	53.3038
851.165	48.9357
854.534	46.9983
857.905	44.8874
861.272	43.7435
864.639	41.6422
868.004	41.6558
871.367	39.981
874.731	38.519
878.092	37.0521
881.451	35.8469
884.809	34.9445
888.166	34.3357
891.522	33.4988
894.878	34.6307
898.231	35.7569
901.583	35.7259
904.934	35.5795
908.283	36.1993
911.631	35.5339
914.976	36.0135
918.322	37.187
921.666	38.1427
925.009	38.2491
928.351	36.9197
931.692	36.0398
935.029	35.958
938.367	35.4581
941.704	34.4279
945.038	34.3252
948.372	34.5399
951.705	34.9851
955.035	33.588
958.366	30.5144
961.693	29.2369
965.021	27.9043
968.346	28.3181
971.67	26.2139
974.995	25.4127
978.316	24.6511
981.638	23.1307
984.957	20.2967
988.274	19.1529
991.59	16.203
994.907	15.4555
998.221	13.667
1001.53	11.2543
1004.85	8.48264
1008.16	9.13218
1011.46	12.2992
1014.77	17.4682
1018.08	24.5325
1021.38	32.0298
1024.69	40.2181
1027.99	47.7846
1031.29	54.3491
1034.59	59.0098
1037.89	62.2073
1041.19	65.2196
1044.48	68.6375
1047.78	67.4796
1051.07	67.4202
1054.36	65.0191
1057.66	62.274
1060.94	57.8571
1064.23	51.8339
1067.52	46.1497
1070.81	39.4077
1074.09	31.0611
1077.38	23.0452
1080.66	15.7927
1083.94	10.1813
1087.22	5.90902
1090.5	6.43455
1093.77	7.67414
1097.05	8.50661
1100.32	9.77748
1103.6	10.9768
1106.87	12.4994
1110.14	13.3205
1113.41	14.87
1116.67	15.2156
1119.94	16.2032
1123.21	16.5012
1126.47	15.599
1129.73	15.6374
1133	15.6212
1136.26	15.5214
1139.52	14.9011
1142.77	13.424
1146.03	12.2999
1149.29	11.4393
1152.54	9.22507
1155.79	6.59653
1159.04	3.59511
1162.3	1.92575
1165.55	1.97576
1168.79	2.93786
1172.04	3.06731
1175.28	3.70142
1178.53	2.20983
1181.77	2.4289
1185.01	3.295
1188.25	4.94389
1191.49	6.5028
1194.73	6.47396
1197.97	7.18064
1201.2	7.42429
1204.44	8.35174
1207.67	8.77942
1210.9	8.99978
1214.13	8.90125
1217.36	9.49012
1220.59	9.20643
1223.82	9.32164
1227.04	9.73496
1230.26	10.406
1233.49	11.3019
1236.71	13.0735
1239.93	16.3767
1243.15	19.8206
1246.37	22.7902
1249.58	24.8595
1252.8	26.6785
1256.01	28.3476
1259.23	28.9323
1262.44	31.1868
1265.65	33.0997
1268.86	35.6071
1272.07	37.4131
1275.27	38.3565
1278.48	38.7572
1281.68	39.4367
1284.89	39.3543
1288.09	40.2714
1291.29	40.1036
1294.49	39.8974
1297.69	38.8214
1300.88	38.9884
1304.08	39.1895
1307.27	40.3358
1310.47	41.8413
1313.66	42.6196
1316.85	42.5307
1320.04	43.041
1323.23	43.9908
1326.41	45.0058
1329.6	44.2423
1332.78	43.3592
1335.97	43.4305
1339.15	42.5076
1342.33	42.0724
1345.51	42.6708
1348.69	42.5382
1351.87	41.2212
1355.04	40.2247
1358.22	38.6645
1361.39	38.0544
1364.57	36.2708
1367.74	35.1881
1370.91	32.7486
1374.07	31.1278
1377.24	29.913
1380.41	30.8127
1383.57	31.3887
1386.74	30.9162
1389.9	31.3436
1393.06	31.7854
1396.22	32.8766
1399.38	33.3252
1402.54	33.7061
1405.7	33.2672
1408.85	34.2604
1412.01	35.975
1415.16	36.269
1418.31	38.5403
1421.46	40.9296
1424.61	44.1026
1427.76	45.4069
1430.91	47.2173
1434.05	49.6992
1437.2	50.5005
1440.34	51.8353
1443.49	51.237
1446.63	50.2313
1449.77	49.2773
1452.91	50.5713
1456.04	50.6937
1459.18	50.531
1462.31	49.7712
1465.45	49.1785
1468.58	48.1996
1471.71	47.0026
1474.84	42.8219
1477.97	40.8242
1481.1	38.3116
1484.23	36.5022
1487.35	34.2969
1490.48	33.7801
1493.6	32.3112
1496.72	30.6437
1499.84	29.5563
1502.96	28.4895
1506.08	27.5317
1509.2	27.7023
1512.31	25.8299
1515.43	24.8803
1518.54	24.2188
1521.66	22.3374
1524.77	22.1055
1527.88	23.0483
1530.99	24.4304
1534.09	25.1436
1537.2	27.1713
1540.31	28.0604
1543.41	28.9432
1546.51	28.0812
1549.62	27.7419
1552.72	27.4408
1555.82	28.3469
1558.91	28.0075
1562.01	29.435
1565.11	29.039
1568.2	29.5247
1571.3	28.9184
1574.39	29.0514
1577.48	29.414
1580.57	29.2928
1583.66	29.7087
1586.75	29.7153
1589.83	30.1367
1592.92	32.057
1596	32.6649
1599.09	32.628
1602.17	33.9174
1605.25	35.3151
1608.33	36.746
1611.41	37.6321
1614.48	39.5643
1617.56	38.6795
1620.64	40.5866
1623.71	40.1345
1626.78	41.707
1629.86	41.1576
1632.92	41.919
1635.99	41.33
1639.06	40.2131
1642.13	40.0679
1645.19	39.6868
1648.26	38.3436
1651.32	36.8585
1654.38	36.7341
1657.45	34.9911
1660.51	34.4321
1663.57	34.3685
1666.62	33.6223
1669.68	31.984
1672.73	30.3024
1675.79	28.1696
1678.84	26.171
1681.89	24.552
1684.94	22.675
1687.99	21.7442
1691.04	20.0504
1694.09	18.7006
1697.14	16.666
1700.18	15.0778
1703.22	13.2868
1706.27	11.8143
1709.31	10.7797
1712.35	8.87511
1715.39	9.63415
1718.43	9.67414
1721.46	9.72249
1724.5	9.29506
1727.53	8.77233
1730.57	8.90056
1733.6	8.80754
1736.63	8.24327
1739.66	7.12477
1742.69	6.11536
1745.72	5.69917
1748.74	4.95581
1751.77	3.67716
1754.8	3.70309
1757.82	3.2558
1760.84	3.40337
1763.86	2.65125
1766.88	1.751
1769.9	1.19963
1772.92	2.17732
1775.93	2.10412
1778.95	2.5071
1781.96	3.48062
1784.98	4.18334
1787.99	5.37068
1791	6.09466
1794.01	6.56925
1797.02	6.87376
1800.03	5.83113
1803.03	5.13976
1806.04	5.23375
1809.04	4.24128
1812.04	3.99747
1815.05	3.70072
1818.05	3.5289
1821.05	3.20954
1824.05	2.79479
1827.04	3.30213
1830.04	3.102
1833.03	2.89238
1836.03	3.10282
1839.02	3.1344
1842.01	3.47523
1845	3.71673
1847.99	3.63091
1850.98	3.67117
1853.97	3.99313
1856.95	4.02251
1859.94	4.2378
1862.92	5.28306
1865.91	5.9403
1868.89	5.8536
1871.87	5.42266
1874.85	4.69364
1877.83	5.14958
1880.8	4.3637
1882.56	4.76854
1885.54	4.55603
1888.53	4.35632
1891.52	5.06367
1894.5	5.21939
1897.49	5.69805
1900.47	6.03017
1903.45	6.62616
1906.43	7.43847
1909.41	8.66517
1912.39	8.9729
1915.37	8.59384
1918.35	8.26762
1921.32	8.51752
1924.3	7.65984
1927.27	7.84415
1930.24	7.37409
1933.21	6.94312
1936.18	6.36191
1939.15	5.44563
1942.12	4.63561
1945.09	4.07345
1948.05	3.55213
1951.02	3.422
1953.98	2.75258
1956.94	2.28869
1959.91	2.36712
1962.87	2.59485
1965.82	2.39033
1968.78	2.458
1971.74	2.22879
1974.7	2.76511
1977.65	2.82785
1980.6	3.75022
1983.56	4.22572
1986.51	5.4334
1989.46	5.5777
1992.41	5.91521
1995.36	6.21605
1998.3	6.85827
2001.25	6.84511
2004.2	7.40848
2007.14	8.51215
2010.08	9.14328
2013.02	9.7886
2015.97	10.5812
2018.9	11.9042
2021.84	11.5983
2024.78	11.3891
2027.72	11.4856
2030.65	12.3326
2033.59	12.3113
2036.52	11.5066
2039.45	10.6268
2042.38	9.74507
2045.31	9.50022
2048.24	9.07129
2051.17	9.32174
2054.1	9.79681
2057.02	9.55904
2059.95	9.95232
2062.87	9.74566
2065.79	9.47062
2068.71	9.34874
2071.63	10.4018
2074.55	11.5679
2077.47	13.1685
2080.39	14.0888
2083.3	14.717
2086.22	16.7074
2089.13	18.167
2092.05	19.3365
2094.96	20.1107
2097.87	20.8655
2100.78	21.8125
2103.69	22.6793
2106.59	21.6927
2109.5	22.4214
2112.41	22.6275
2115.31	23.1865
2118.21	23.7953
2121.12	24.1978
2124.02	25.0231
2126.92	25.3859
2129.82	25.8976
2132.71	28.2181
2135.61	29.3123
2138.51	30.7822
2141.4	32.5805
2144.29	35.9164
2147.19	37.9711
2150.08	40.2293
2152.97	41.1666
2155.86	43.6679
2158.75	46.1649
2161.64	46.4936
2164.52	47.325
2167.41	47.2085
2170.29	48.1823
2173.17	47.4761
2176.06	46.6182
2178.94	45.23
2181.82	44.0453
2184.7	42.7561
2187.57	42.5698
2190.45	41.0318
2193.33	39.4654
2196.2	38.3931
2199.08	36.8655
2201.95	36.511
2204.82	35.7912
2207.69	34.1927
2210.56	33.1691
2213.43	32.4818
2216.3	30.6644
2219.16	29.5703
2222.03	27.6412
2224.89	26.3391
2227.75	25.4982
2230.62	23.5976
2233.48	22.5869
2236.34	21.3825
2239.2	20.8431
2242.06	20.0265
2244.91	19.2089
2247.77	18.5868
2250.62	17.6326
2253.48	17.3293
2256.33	18.225
2259.18	17.6311
2262.03	17.607
2264.88	17.7833
2267.73	17.8821
2270.58	18.1284
2273.43	17.1335
2276.27	16.6828
2279.12	15.7098
2281.96	14.6189
2284.8	13.4261
2287.64	12.7542
2290.49	11.58
2293.32	9.15222
2296.16	7.6544
2299	8.14351
2301.84	9.26005
2304.67	8.74472
2307.51	9.5406
2310.34	9.62636
2313.17	10.3713
2316	9.62487
2318.83	9.79541
2321.66	9.988
2324.49	10.3651
2327.32	10.2816
2330.15	10.8698
2332.97	11.405
2335.79	11.2337
2338.62	10.7358
2341.44	9.19103
2344.26	7.45281
2347.08	7.06959
2349.9	6.14418
2352.72	5.28665
2355.53	4.03808
2358.35	3.1748
2361.17	1.66698
2363.98	0.443495
2366.79	1.94362
2369.6	2.55293
2372.42	2.17702
2375.22	1.54086
2378.03	1.52784
2380.84	1.21906
2383.65	0.983436
2386.45	1.36768
2389.26	1.75197
2392.06	1.57573
2394.87	1.38809
2397.67	1.35598
2400.47	1.56247
2403.27	1.66614
2406.07	1.38966
2408.86	1.53956
2411.66	1.21916
2414.46	1.49122
2417.25	1.69478
2420.05	1.29797
2422.84	1.15061
2425.63	1.92665
2428.42	1.70391
2431.21	2.37472
2434	3.08404
2436.79	3.05629
2439.57	2.87008
2442.36	2.60541
2445.14	2.41205
2447.93	1.87257
2450.71	1.36694
2453.49	1.27182
2456.27	2.01591
2459.05	2.00952
2461.83	1.23375
2464.61	1.62478
2467.39	1.56834
2470.16	1.38039
2472.94	1.88265
2475.71	1.8754
2478.48	2.11219
2481.25	1.52252
2484.02	2.14153
2486.8	1.90053
2489.56	2.23355
2492.33	3.34461
2495.1	3.81679
2497.86	3.294
2500.63	3.36511
2503.39	3.7687
2506.16	3.56591
2508.92	3.23458
2511.68	3.06075
2514.44	2.83291
2517.2	3.42839
2519.95	3.50149
2522.71	4.21618
2525.47	5.54734
2528.22	5.08626
2530.98	4.60931
2533.73	5.43545
2536.48	6.1579
2539.23	7.00908
2541.98	7.24869
2544.73	6.73282
2547.48	6.2058
2550.23	5.69204
2552.97	5.20192
2555.72	5.00611
2558.46	5.36964
2561.2	5.22565
2563.95	4.58208
2566.69	4.26238
2569.43	3.64151
2572.17	3.76253
2574.91	3.36371
2577.64	3.01092
2580.38	2.56778
2583.11	3.26811
2585.85	3.47457
2588.58	2.80617
2591.31	3.97584
2594.04	4.00438
2596.78	4.52325
2599.51	5.13551
2602.23	5.8981
2604.96	6.05056
2607.69	5.51887
2610.41	5.06621
2613.14	5.0381
2615.86	5.23185
2618.58	4.89103
2621.3	5.01639
2624.03	5.60568
2626.75	5.62177
2629.46	5.56438
2632.18	4.80263
2634.9	4.75204
2637.61	4.42564
2640.33	4.06897
2643.04	4.44107
2645.76	4.52144
2648.47	4.68687
2651.18	3.37453
2653.89	2.55325
2656.6	2.6043
2659.31	3.28914
2662.01	3.28893
2664.72	2.77867
2667.43	2.95018
2670.13	2.93361
2672.83	3.11214
2675.53	2.98393
2678.24	3.37581
2680.94	3.22892
2683.64	2.7947
2686.34	3.13475
2689.03	3.11429
2691.73	3.40176
2694.43	3.43087
2697.12	3.64345
2699.81	3.87532
2702.51	4.26994
2705.2	4.34203
2707.89	4.70069
2710.58	5.06027
2713.27	4.98003
2715.96	4.7355
2718.64	5.19597
2721.33	5.12125
2724.01	5.12951
2726.7	5.74991
2729.38	5.09429
2732.06	5.16678
2734.75	4.82661
2737.43	4.65425
2740.11	4.21945
2742.78	3.85159
2745.46	2.25482
2748.14	1.73218
2750.81	1.21084
2753.49	1.86568
2756.16	0.895
2758.84	0.498702
2761.51	0.0508522
2764.18	0.45242
2766.85	0.0706961
2769.52	0.177129
2772.19	0.0664626
2774.85	0.532089
2777.52	0.446597
2780.18	0.713757
2782.85	0.909883
2785.51	0.487894
2788.17	0.421439
2790.84	1.51985
2793.5	1.56807
2796.16	1.52167
2798.81	2.23908
2801.47	2.49095
2804.13	2.64209
2806.79	2.25155
2809.44	2.14923
2812.09	2.77117
2814.75	3.95994
2817.4	5.45958
2820.05	5.86511
2822.7	7.40591
2825.35	9.45614
2828	12.2028
2830.65	14.4148
2833.29	16.4414
2835.94	18.5306
2838.58	21.0867
2841.23	24.2291
2843.87	26.8537
2846.51	29.1353
2849.15	32.5438
2851.79	36.7315
2854.43	40.0111
2857.07	42.4623
2859.71	44.3797
2862.34	48.3876
2864.98	50.9803
2867.61	52.8406
2870.25	54.7387
2872.88	57.1665
2875.51	58.5623
2878.14	60.2187
2880.77	62.018
2883.4	63.6465
2886.03	64.8438
2888.65	67.674
2891.28	68.9254
2893.91	70.9231
2896.53	72.5231
2899.15	75.4313
2901.78	76.9071
2904.4	79.3121
2907.02	82.2964
2909.64	85.1947
2912.26	89.7761
2914.87	93.4088
2917.49	97.6505
2920.11	100.144
2922.72	102.329
2925.34	104.787
2927.95	107.093
2930.56	107.651
2933.17	108.62
2935.78	109.113
2938.39	108.545
2941	106.502
2943.61	104.568
2946.22	101.894
2948.82	99.4096
2951.43	96.2073
2954.03	93.0343
2956.64	88.2654
2959.24	84.3338
2961.84	80.8262
2964.44	76.7039
2967.04	72.2459
2969.64	69.0343
2972.24	65.4254
2974.83	62.0245
2977.43	58.1896
2980.02	54.167
2982.62	50.9965
2985.21	46.7484
2987.8	43.0606
2990.4	39.5749
2992.99	35.9326
2995.57	32.8073
2998.16	30.0428
3000.75	28.0822
3003.34	24.6862
3005.92	21.0374
3008.51	19.3351
3011.09	17.7196
3013.68	15.8035
3016.26	13.9561
3018.84	13.2624
3021.42	12.2154
3024	10.9791
3026.58	9.55248
3029.16	8.05817
3031.73	7.39246
3034.31	6.45044
3036.89	6.11109
3039.46	5.53597
3042.03	5.08079
3044.61	4.60048
3047.18	4.89159
3049.75	4.3913
3052.32	3.78363
3054.89	3.88077
3057.45	4.38601
3060.02	5.15087
3062.59	5.81896
3065.15	5.46518
3067.72	5.72126
3070.28	5.67184
3072.84	5.79861
3075.41	6.0164
3077.97	5.65731
3080.53	5.83342
3083.09	4.66758
3085.64	4.03031
3088.2	3.93518
3090.76	3.47235
3093.31	3.26601
3095.87	3.16845
3098.42	2.57975
3100.97	2.42146
3103.53	2.03794
3106.08	1.17587
3108.63	1.7013
3111.18	1.75905
3113.73	2.11769
3116.27	1.56808
3118.82	2.19283
3121.37	2.06425
3123.91	2.43583
3126.45	1.85358
3129	1.51242
3131.54	0.673558
3134.08	-0.394902
3136.62	-0.492327
3139.16	-0.743079
3141.7	-0.848126
3144.24	-0.922785
3146.78	-0.688643
3149.31	-1.6639