File: data/Raman/poly_smoothed/Mb_40_24_37_1x_45s_532 nm_x100_100%_600 gr_mm_01.txt
#Acq. time (s)=	45
#Accumulations=	2
#Range (cm-¹)=	200...3150
#Windows=	2
#Auto scanning=	Off
#Autofocus=	Off
#Macrospot=	Off
#AutoExposure=	Off
#Spike filter=	Multiple accum.
#Delay time (s)=	0
#Binning=	1
#Readout mode=	Signal
#DeNoise=	Off
#ICS correction=	On
#Dark correction=	Off
#Inst. Process=	Off
#Detector Gain=	Best Dynamic Range
#Detector ADC=	20 kHz
#Detector temperature (°C)=	-70.08
#Instrument=	LabRAM HR Evol
#Detector=	Synapse
#Objective=	x100
#Grating=	600 gr/mm
#ND Filter=	100%
#Laser (nm)=	532
#Hole=	100.021
#Range=	Auto
#Laser Pol.=	No
#Raman. Pol.=	No
#Laser Pol. (°)=	-0.0007625
#Raman Pol. (°)=	89.9995
#Collection=	Microscope
#StageXY=	Marzhauser
#StageZ=	Marzhauser
#X (µm)=	-2498
#Y (µm)=	-71.4
#Z (µm)=	-10.4
#Full time(mm:ss)=	3:18
#Project=
#Sample=
#Site=
#Title=	Mb_40_24_37_2x_45s_532 nm_x100_100%_600 gr_mm
#Remark=
#Date=	14.07.2022 13:28
#Acquired=	14.07.2022 13:28:40
#Base:Fit=	10.08.2022 10:47:00
#Base:Sub=	10.08.2022 10:47:12
#Filter:Polynom=	16.08.2022 10:11:48
#AxisType[0]=Intens
#AxisUnit[0]=Cnt
#AxisType[1]=Spectr
#AxisUnit[1]=1/cm
200.554	20.1071
204.183	16.067
207.813	14.1937
211.439	13.1424
215.065	12.0055
218.688	12.4008
222.312	12.1856
225.933	10.6922
229.552	11.3245
233.171	10.1365
236.787	11.0758
240.402	11.4841
244.015	12.2476
247.627	12.77
251.24	13.0846
254.849	13.4856
258.457	15.0227
262.063	17.1298
265.668	16.7531
269.271	17.7248
272.873	18.2161
276.474	17.3127
280.073	16.2808
283.671	14.6867
287.268	12.1119
290.863	12.0932
294.456	12.6289
298.049	13.0552
301.637	13.1669
305.227	13.2481
308.815	13.5765
312.402	14.5094
315.987	15.2552
319.569	16.0004
323.151	16.7011
326.733	17.6238
330.31	18.5106
333.889	19.0491
337.464	21.0747
341.039	21.9629
344.611	22.9786
348.184	23.6758
351.754	22.7011
355.324	22.4658
358.89	22.8135
362.455	21.7704
366.021	23.4543
369.584	23.2567
373.145	22.9193
376.707	25.1188
380.265	23.7856
383.822	25.5615
387.378	26.2362
390.934	26.529
394.487	27.6396
398.038	28.7691
401.588	27.4396
405.137	26.0256
408.685	25.5971
412.23	25.8011
415.775	24.8463
419.318	22.9893
422.86	22.3377
426.401	21.6795
429.94	19.9412
433.478	18.422
437.012	16.6408
440.547	14.8446
444.081	14.8995
447.613	14.9509
451.142	13.8837
454.672	16.2622
458.2	17.4981
461.725	19.3982
465.251	19.6053
468.775	19.0982
472.296	22.0624
475.817	23.5725
479.335	26.7423
482.854	27.59
486.37	27.035
489.886	28.2625
493.398	29.7139
496.91	31.8433
500.422	32.6867
503.93	31.9495
507.438	32.0116
510.946	33.4716
514.45	31.7015
517.954	30.6287
521.456	30.6792
524.956	30.5912
528.456	31.6986
531.956	32.9346
535.452	30.643
538.947	30.6488
542.441	31.2151
545.934	28.1677
549.425	25.2537
552.915	21.5187
556.403	20.5271
559.889	19.2622
563.375	17.1031
566.859	13.4834
570.342	12.114
573.824	10.8641
577.303	8.51978
580.782	8.79449
584.26	7.40517
587.734	5.08811
591.21	4.97843
594.684	3.65394
598.154	4.83296
601.626	4.90691
605.094	7.46463
608.562	9.46326
612.027	11.1954
615.493	12.6934
618.956	14.0047
622.419	13.1218
625.879	13.9041
629.338	13.8857
632.797	12.8223
636.254	11.7764
639.708	12.1239
643.162	11.6748
646.614	11.3159
650.067	9.57442
653.516	9.81915
656.964	10.3668
660.411	11.7476
663.857	11.782
667.301	10.7632
670.744	9.99924
674.186	11.2907
677.626	13.4961
681.065	17.7151
684.503	19.8171
687.939	22.3379
691.372	26.1889
694.806	26.9449
698.239	30.1097
701.67	34.0825
705.098	36.6835
708.526	38.3278
711.954	39.495
715.378	39.5981
718.802	39.2252
722.226	38.8337
725.646	39.2712
729.067	37.6267
732.484	36.2742
735.902	36.45
739.317	36.261
742.731	38.4842
746.145	39.0369
749.556	38.6082
752.966	41.0234
756.377	44.6091
759.784	47.3461
763.19	50.0942
766.594	53.2456
770	53.4285
773.402	55.0652
776.803	56.5715
780.202	58.2564
783.6	61.3052
786.997	64.144
790.393	65.4524
793.787	64.8757
797.18	64.271
800.572	63.4993
803.963	64.7593
807.35	64.6546
810.738	65.4582
814.125	65.2458
817.51	65.9754
820.894	66.5943
824.275	68.7593
827.657	71.774
831.037	73.0579
834.414	75.2897
837.792	76.9083
841.167	76.7757
844.542	75.7998
847.914	74.7255
851.287	73.5611
854.656	71.7897
858.026	69.9073
861.393	67.8816
864.761	66.0481
868.125	64.6534
871.489	62.3662
874.85	57.9007
878.213	57.0554
881.572	53.213
884.931	52.0999
888.287	51.676
891.643	52.5052
894.997	52.8198
898.352	51.4166
901.704	53.4834
905.055	54.6814
908.404	55.3042
911.75	56.1704
915.097	56.6405
918.443	56.486
921.787	56.1159
925.13	56.9137
928.472	55.8211
931.813	53.502
935.15	52.8259
938.488	50.4845
941.825	49.0958
945.158	46.3815
948.493	43.9872
951.824	42.8868
955.156	40.9351
958.486	40.4921
961.814	39.0506
965.142	37.7242
968.467	38.9809
971.79	39.8948
975.115	41.6203
978.436	42.3155
981.756	43.5011
985.077	43.8168
988.394	46.2378
991.71	48.1977
995.025	50.1482
998.341	49.4637
1001.65	50.3849
1004.97	50.4406
1008.28	50.1852
1011.58	51.5832
1014.89	53.5029
1018.2	58.2789
1021.5	61.0196
1024.81	62.757
1028.11	66.4941
1031.41	69.9458
1034.71	70.0297
1038.01	69.488
1041.31	70.1077
1044.6	71.3344
1047.9	71.6259
1051.19	71.5932
1054.48	69.103
1057.77	66.4195
1061.06	63.9498
1064.35	60.2009
1067.64	57.858
1070.93	53.7226
1074.21	49.3178
1077.49	44.4443
1080.78	39.788
1084.06	37.4845
1087.34	34.8682
1090.61	35.1064
1093.89	37.3562
1097.17	36.6214
1100.44	36.7577
1103.71	37.7547
1106.99	38.1934
1110.26	36.5381
1113.52	34.7413
1116.79	33.1914
1120.06	32.4771
1123.32	31.5908
1126.59	29.221
1129.85	27.3648
1133.11	24.5506
1136.37	21.6995
1139.63	18.6007
1142.89	17.6266
1146.15	14.8345
1149.4	13.0042
1152.66	10.3901
1155.91	8.21901
1159.16	5.33323
1162.41	3.37419
1165.66	2.10783
1168.91	1.96241
1172.16	3.4509
1175.4	1.82188
1178.65	1.97027
1181.89	4.34435
1185.13	5.32982
1188.37	4.80265
1191.61	6.16962
1194.85	8.18625
1198.08	10.138
1201.32	12.1108
1204.55	15.737
1207.79	19.0509
1211.02	22.2443
1214.25	25.3691
1217.48	30.5121
1220.71	33.2103
1223.93	37.5644
1227.16	41.2076
1230.38	43.9212
1233.6	47.0057
1236.83	49.0833
1240.05	51.9957
1243.26	54.8571
1246.48	58.0303
1249.7	61.2113
1252.92	63.7864
1256.13	66.6413
1259.34	69.2552
1262.55	70.9735
1265.76	72.625
1268.97	75.9552
1272.18	78.5229
1275.39	81.6505
1278.59	82.4945
1281.8	86.5215
1285	89.047
1288.2	91.3089
1291.4	92.1593
1294.6	92.0878
1297.8	91.1793
1301	91.2423
1304.19	91.2421
1307.39	89.9635
1310.58	89.1201
1313.77	88.432
1316.96	87.8047
1320.15	85.7629
1323.34	85.3841
1326.53	83.6138
1329.72	82.3597
1332.9	80.6271
1336.08	79.9241
1339.27	77.9767
1342.45	75.6451
1345.63	74.1493
1348.8	73.0336
1351.98	72.456
1355.16	70.4103
1358.33	70.5481
1361.51	70.7037
1364.68	68.5672
1367.85	65.2743
1371.02	64.3144
1374.19	63.5599
1377.36	63.4468
1380.52	61.9522
1383.69	63.0632
1386.85	62.6971
1390.02	63.1407
1393.18	64.6944
1396.34	65.3765
1399.5	65.9152
1402.65	67.0515
1405.81	68.6151
1408.97	70.7759
1412.12	74.8446
1415.27	79.0355
1418.43	83.8948
1421.58	88.4037
1424.73	95.7821
1427.87	102.791
1431.02	108.739
1434.17	116.155
1437.31	123.198
1440.46	126.123
1443.6	128.781
1446.74	130.682
1449.88	132.248
1453.02	131.387
1456.16	129.03
1459.29	127.005
1462.43	123.736
1465.56	117.117
1468.69	110.575
1471.83	102.644
1474.95	94.0792
1478.08	83.6609
1481.21	74.9013
1484.34	67.8076
1487.47	61.0895
1490.59	54.3842
1493.71	47.0094
1496.84	40.6965
1499.96	36.0918
1503.07	30.9112
1506.19	26.4353
1509.31	24.0347
1512.43	21.2801
1515.54	18.0252
1518.65	14.6936
1521.77	13.2719
1524.88	13.4918
1527.99	13.5574
1531.1	14.3143
1534.21	15.817
1537.31	16.6423
1540.42	18.6224
1543.52	20.1968
1546.63	24.0642
1549.73	26.7357
1552.83	30.0497
1555.93	32.9621
1559.03	38.9538
1562.12	42.0845
1565.22	45.0133
1568.31	47.4452
1571.41	51.583
1574.5	55.9116
1577.59	60.3039
1580.68	63.7767
1583.77	68.0885
1586.86	69.962
1589.95	71.7902
1593.03	72.6731
1596.11	72.9209
1599.2	73.7993
1602.28	71.7107
1605.36	70.6234
1608.44	70.879
1611.52	70.7455
1614.6	70.1601
1617.67	70.8406
1620.75	71.1359
1623.82	72.9712
1626.89	74.4533
1629.96	76.4354
1633.04	79.8004
1636.11	82.0748
1639.17	85.0586
1642.24	89.2069
1645.31	93.4155
1648.37	96.6659
1651.43	98.8515
1654.5	100.38
1657.56	101.982
1660.62	101.073
1663.67	97.7035
1666.73	94.3103
1669.79	89.1329
1672.84	84.8751
1675.9	79.4428
1678.95	72.9486
1682	66.502
1685.05	61.1095
1688.1	54.7097
1691.15	48.4194
1694.2	42.9021
1697.25	38.5031
1700.29	33.1732
1703.33	29.4406
1706.38	26.5218
1709.42	23.2968
1712.46	21.3614
1715.5	19.5189
1718.54	18.3398
1721.57	16.4924
1724.61	14.8297
1727.64	13.9427
1730.68	14.3751
1733.71	14.2718
1736.74	13.6143
1739.77	14.0679
1742.8	13.7643
1745.83	13.7751
1748.85	13.4107
1751.88	12.5483
1754.91	12.3634
1757.93	13.5607
1760.95	13.0169
1763.97	11.0132
1766.99	11.1167
1770.01	10.0741
1773.03	9.76152
1776.04	9.13736
1779.06	9.24889
1782.07	8.68826
1785.09	7.89456
1788.1	6.68738
1791.11	5.06843
1794.12	3.02409
1797.13	1.69231
1800.13	0.672342
1803.14	1.75273
1806.15	1.8804
1809.15	1.86387
1812.15	1.8032
1815.16	2.13999
1818.15	1.51956
1821.16	1.6025
1824.15	1.90556
1827.15	2.65108
1830.15	3.09743
1833.14	3.34393
1836.14	2.85029
1839.13	3.17212
1842.12	3.85137
1845.11	4.40514
1848.1	4.43215
1851.09	5.10825
1854.08	4.97868
1857.06	4.67202
1860.05	4.18613
1863.03	2.49961
1866.01	1.97609
1869	2.31478
1871.98	1.76637
1874.96	1.62011
1877.93	1.72309
1880.91	1.65086
1882.47	1.66423
1885.46	2.08642
1888.44	2.87769
1891.43	3.75321
1894.42	3.71135
1897.4	4.00953
1900.39	3.85699
1903.37	3.83573
1906.35	3.77579
1909.33	3.83703
1912.31	3.06815
1915.29	3.26543
1918.26	3.1231
1921.24	2.99124
1924.21	3.34822
1927.19	2.70368
1930.16	2.7929
1933.13	2.60235
1936.1	2.56219
1939.07	2.79256
1942.04	3.25886
1945	2.23691
1947.97	2.18829
1950.93	1.73326
1953.9	2.52756
1956.86	2.84939
1959.82	3.75129
1962.78	3.8988
1965.74	4.39456
1968.7	3.94452
1971.65	4.56388
1974.61	5.54926
1977.57	6.32479
1980.52	7.46557
1983.47	7.91334
1986.42	8.32498
1989.37	8.76511
1992.32	8.49111
1995.27	9.47637
1998.22	9.64313
2001.17	10.3895
2004.11	9.38812
2007.05	10.2471
2010	10.4998
2012.94	10.7333
2015.88	9.56317
2018.82	8.64237
2021.76	9.47215
2024.7	9.51897
2027.63	8.65111
2030.57	8.19886
2033.5	8.78323
2036.44	9.07463
2039.37	10.3219
2042.3	10.1871
2045.23	11.4817
2048.16	13.3263
2051.08	14.3382
2054.01	15.04
2056.94	16.2461
2059.86	17.3433
2062.79	19.2555
2065.71	21.3379
2068.63	22.7099
2071.55	23.8387
2074.47	25.5907
2077.39	26.7714
2080.31	28.5402
2083.22	30.063
2086.13	31.085
2089.05	31.3962
2091.96	32.9587
2094.87	33.3508
2097.78	33.4813
2100.69	35.5665
2103.6	36.8001
2106.51	38.5762
2109.42	39.5597
2112.32	42.2075
2115.23	44.0773
2118.13	46.3143
2121.03	48.9462
2123.93	51.6005
2126.83	55.5501
2129.73	58.179
2132.63	62.2178
2135.53	66.8276
2138.42	71.5745
2141.32	75.7902
2144.21	80.0211
2147.1	83.2724
2150	87.3709
2152.89	89.6889
2155.78	92.8978
2158.66	93.7949
2161.55	96.928
2164.44	97.7522
2167.32	98.8892
2170.21	99.3126
2173.09	98.9907
2175.97	98.2733
2178.85	97.6002
2181.73	96.4324
2184.61	95.3879
2187.49	93.475
2190.37	91.406
2193.24	88.8102
2196.12	86.5322
2198.99	83.4962
2201.87	81.2425
2204.74	78.9858
2207.61	76.8152
2210.48	73.5182
2213.35	70.9346
2216.21	68.1197
2219.08	64.832
2221.95	61.8526
2224.81	58.6483
2227.67	55.0661
2230.54	50.8359
2233.4	48.8428
2236.26	44.5242
2239.11	41.295
2241.97	39.4647
2244.83	37.957
2247.69	36.4046
2250.54	35.1099
2253.4	33.6761
2256.25	31.7931
2259.1	30.5845
2261.95	29.4732
2264.8	28.4425
2267.65	26.3076
2270.5	25.6968
2273.34	24.3751
2276.19	22.9633
2279.03	22.6332
2281.88	21.495
2284.72	20.2127
2287.56	18.9811
2290.4	17.9189
2293.24	15.3157
2296.08	13.6569
2298.92	14.3008
2301.76	14.3704
2304.59	15.3084
2307.43	14.9023
2310.26	15.0226
2313.09	15.203
2315.92	16.0696
2318.75	15.8263
2321.58	15.6606
2324.41	15.4348
2327.24	15.6758
2330.06	16.315
2332.89	16.0349
2335.71	15.4115
2338.54	15.3997
2341.36	14.8579
2344.18	13.4642
2347	12.4797
2349.82	11.3966
2352.64	10.1328
2355.45	8.94812
2358.27	8.56641
2361.08	7.66003
2363.9	8.80865
2366.71	9.64546
2369.52	9.56468
2372.33	9.76305
2375.14	9.70037
2377.95	9.4754
2380.76	9.53706
2383.57	10.708
2386.37	10.7606
2389.18	11.766
2391.98	12.0092
2394.79	12.8472
2397.59	13.499
2400.39	13.6949
2403.19	13.6058
2405.99	12.3358
2408.78	11.1216
2411.58	9.87997
2414.38	8.29389
2417.17	7.56978
2419.97	7.15784
2422.76	6.74431
2425.55	5.69002
2428.34	5.43204
2431.13	4.56249
2433.92	2.96406
2436.71	2.65833
2439.49	2.07333
2442.28	2.772
2445.06	1.77656
2447.85	2.29439
2450.63	2.04855
2453.41	2.75502
2456.19	4.18083
2458.97	4.15238
2461.75	4.51728
2464.53	4.93562
2467.31	5.015
2470.08	5.13368
2472.86	4.68004
2475.63	4.06595
2478.4	5.00522
2481.17	5.02947
2483.94	5.58043
2486.72	5.99233
2489.48	5.70847
2492.25	4.88685
2495.02	4.92958
2497.79	4.08919
2500.55	2.08956
2503.31	1.66597
2506.08	1.28178
2508.84	0.922225
2511.6	-0.315594
2514.36	-1.65548
2517.12	-1.4524
2519.88	-2.22625
2522.63	-1.65412
2525.39	-2.22661
2528.14	-1.89777
2530.9	-1.19795
2533.65	-0.100465
2536.4	0.571452
2539.15	1.60337
2541.9	3.35182
2544.65	3.84681
2547.4	4.1755
2550.15	4.50494
2552.89	5.65609
2555.64	6.28706
2558.38	6.2726
2561.12	6.82711
2563.87	6.44331
2566.61	5.53799
2569.35	5.89343
2572.09	5.87736
2574.83	5.80701
2577.56	4.11498
2580.3	3.76739
2583.04	3.44224
2585.77	3.14886
2588.5	3.04359
2591.23	2.72656
2593.97	2.95797
2596.7	3.14481
2599.43	2.71573
2602.15	2.34883
2604.88	2.23759
2607.61	1.70809
2610.33	1.20467
2613.06	0.694342
2615.78	1.07751
2618.51	0.638817
2621.23	1.13624
2623.95	1.8445
2626.67	1.68079
2629.39	1.93233
2632.1	1.74038
2634.82	1.45392
2637.54	1.36493
2640.25	1.74885
2642.97	1.09019
2645.68	1.83398
2648.39	2.01591
2651.1	2.04999
2653.81	1.38592
2656.52	1.68389
2659.23	1.99944
2661.94	2.10776
2664.64	2.26202
2667.35	1.54007
2670.05	2.78426
2672.76	2.31894
2675.46	2.67325
2678.16	2.26095
2680.86	2.05858
2683.56	1.78337
2686.26	1.83547
2688.96	2.25192
2691.65	2.19891
2694.35	3.29682
2697.04	4.33011
2699.74	4.43182
2702.43	5.65097
2705.12	5.40314
2707.81	5.73089
2710.5	6.58167
2713.19	6.34037
2715.88	6.75248
2718.57	6.63246
2721.25	7.45745
2723.94	8.37025
2726.62	7.58965
2729.3	7.38766
2731.99	7.17073
2734.67	7.35158
2737.35	7.31641
2740.03	6.77318
2742.71	5.56579
2745.38	4.53864
2748.06	3.80989
2750.74	3.70992
2753.41	3.07967
2756.09	3.93182
2758.76	4.62839
2761.43	4.12647
2764.1	2.76558
2766.77	1.85023
2769.44	1.28947
2772.11	0.651788
2774.77	0.328785
2777.44	0.445258
2780.11	0.79189
2782.77	1.03299
2785.43	0.353067
2788.1	0.281504
2790.76	-0.369141
2793.42	-0.965707
2796.08	-0.674913
2798.74	-0.306074
2801.4	0.380766
2804.05	0.307034
2806.71	0.91576
2809.36	0.623659
2812.02	1.59441
2814.67	2.25906
2817.32	3.80252
2819.97	6.81152
2822.62	9.42183
2825.27	12.3487
2827.92	16.9168
2830.57	22.4333
2833.22	29.7835
2835.86	35.9995
2838.51	43.602
2841.15	51.3734
2843.79	59.7433
2846.43	68.7292
2849.08	78.0044
2851.72	88.3568
2854.36	98.8076
2856.99	108.503
2859.63	119.009
2862.27	127.89
2864.9	137.523
2867.54	145.64
2870.17	152.181
2872.8	160.566
2875.43	166.269
2878.07	171.405
2880.7	177.64
2883.32	184.536
2885.95	190.514
2888.58	196.951
2891.21	203.112
2893.83	210.692
2896.46	218.16
2899.08	225.656
2901.7	234.865
2904.32	244.615
2906.94	256.484
2909.56	269.915
2912.18	283.706
2914.8	296.364
2917.42	307.834
2920.03	318.346
2922.65	326.861
2925.26	333.737
2927.88	336.843
2930.49	338.809
2933.1	337.406
2935.71	334.243
2938.32	328.724
2940.93	320.624
2943.54	311.513
2946.14	301.08
2948.75	287.786
2951.35	274.645
2953.96	260.457
2956.56	247.522
2959.16	234.433
2961.77	220.281
2964.37	209.117
2966.96	198.5
2969.56	188.977
2972.16	179.276
2974.76	170.252
2977.35	159.747
2979.95	149.431
2982.54	139.24
2985.14	129.586
2987.73	119.295
2990.32	109.495
2992.91	99.3707
2995.5	89.3404
2998.09	79.797
3000.68	70.8091
3003.26	60.8267
3005.85	52.1356
3008.43	44.1815
3011.02	36.9808
3013.6	30.2704
3016.19	25.2637
3018.77	21.6563
3021.35	17.3411
3023.93	13.9553
3026.5	12.1756
3029.08	11.2594
3031.66	10.6402
3034.24	10.7194
3036.81	10.1168
3039.39	9.69208
3041.96	10.6089
3044.53	11.1786
3047.1	11.5202
3049.67	12.9189
3052.24	13.0243
3054.81	13.4725
3057.38	13.4705
3059.95	12.6751
3062.52	11.623
3065.08	10.1
3067.65	9.06568
3070.21	7.70922
3072.77	6.4512
3075.33	5.58826
3077.89	4.53662
3080.45	3.75084
3083.01	1.97772
3085.57	1.36774
3088.13	0.752947
3090.68	0.49707
3093.24	0.781985
3095.79	0.0412987
3098.35	-0.206395
3100.9	-0.0680235
3103.45	0.892916
3106	1.19973
3108.55	-0.0213302
3111.1	-0.1274
3113.65	0.422836
3116.2	1.2033
3118.75	1.21749
3121.29	1.21495
3123.84	1.27877
3126.38	1.41441
3128.92	2.69989
3131.47	3.22858
3134.01	4.14831
3136.55	4.54882
3139.09	5.35225
3141.63	6.27591
3144.17	7.5153
3146.7	9.81912
3149.24	11.3454