File: data/Raman/poly_smoothed/Mb_40_24_16_1x_45s_532 nm_x100_100%_600 gr_mm_01.txt
#Acq. time (s)=	45
#Accumulations=	2
#Range (cm-¹)=	200...3150
#Windows=	2
#Auto scanning=	Off
#Autofocus=	Off
#Macrospot=	Off
#AutoExposure=	Off
#Spike filter=	Multiple accum.
#Delay time (s)=	0
#Binning=	1
#Readout mode=	Signal
#DeNoise=	Off
#ICS correction=	On
#Dark correction=	Off
#Inst. Process=	Off
#Detector Gain=	Best Dynamic Range
#Detector ADC=	20 kHz
#Detector temperature (°C)=	-70.08
#Instrument=	LabRAM HR Evol
#Detector=	Synapse
#Objective=	x100
#Grating=	600 gr/mm
#ND Filter=	100%
#Laser (nm)=	532
#Hole=	100.021
#Range=	Auto
#Laser Pol.=	No
#Raman. Pol.=	No
#Laser Pol. (°)=	-0.0007625
#Raman Pol. (°)=	89.9995
#Collection=	Microscope
#StageXY=	Marzhauser
#StageZ=	Marzhauser
#X (µm)=	-2557.3
#Y (µm)=	-91.6
#Z (µm)=	-10.75
#Full time(mm:ss)=	3:18
#Project=
#Sample=
#Site=
#Title=	Mb_40_24_16_2x_45s_532 nm_x100_100%_600 gr_mm
#Remark=
#Date=	14.07.2022 11:51
#Acquired=	14.07.2022 11:51:04
#Base:Fit=	10.08.2022 10:47:00
#Base:Sub=	10.08.2022 10:47:12
#Filter:Polynom=	16.08.2022 10:11:48
#AxisType[0]=Intens
#AxisUnit[0]=Cnt
#AxisType[1]=Spectr
#AxisUnit[1]=1/cm
200.554	30.0418
204.183	21.4819
207.813	19.379
211.439	17.5993
215.065	18.2671
218.688	19.5968
222.312	19.6245
225.933	21.2566
229.552	26.1353
233.171	28.1948
236.787	28.8744
240.402	33.1446
244.015	32.917
247.627	37.9508
251.24	43.2905
254.849	47.9626
258.457	52.8901
262.063	56.5975
265.668	58.1033
269.271	57.3453
272.873	60.3865
276.474	61.7937
280.073	63.9043
283.671	67.3149
287.268	70.8084
290.863	74.2702
294.456	77.5268
298.049	80.9114
301.637	86.3935
305.227	90.7898
308.815	91.5288
312.402	94.6591
315.987	96.4314
319.569	96.3864
323.151	94.7614
326.733	92.876
330.31	87.4599
333.889	87.3137
337.464	84.9174
341.039	83.5804
344.611	78.6792
348.184	73.3149
351.754	67.4427
355.324	59.3155
358.89	53.6291
362.455	44.7339
366.021	39.2939
369.584	36.8832
373.145	30.6091
376.707	26.9941
380.265	26.4461
383.822	26.8322
387.378	26.294
390.934	26.0716
394.487	25.0546
398.038	23.1972
401.588	19.8246
405.137	20.1414
408.685	19.0115
412.23	20.0998
415.775	19.3272
419.318	19.7801
422.86	25.6617
426.401	23.9051
429.94	23.6183
433.478	23.0469
437.012	22.3831
440.547	19.4019
444.081	16.9563
447.613	14.5936
451.142	12.0842
454.672	11.4955
458.2	7.91031
461.725	8.29809
465.251	8.15609
468.775	8.51906
472.296	8.07554
475.817	4.38564
479.335	2.6062
482.854	-0.124114
486.37	-0.29915
489.886	1.30475
493.398	3.03821
496.91	6.67957
500.422	12.9757
503.93	16.8403
507.438	21.3425
510.946	26.9555
514.45	27.491
517.954	31.3938
521.456	31.3818
524.956	31.749
528.456	34.3175
531.956	35.0584
535.452	33.395
538.947	30.7867
542.441	31.1193
545.934	29.8458
549.425	28.8868
552.915	27.042
556.403	25.466
559.889	22.2863
563.375	20.5762
566.859	19.2158
570.342	17.5855
573.824	16.9083
577.303	17.5165
580.782	19.7293
584.26	21.7486
587.734	21.8096
591.21	23.6526
594.684	24.0924
598.154	23.4431
601.626	22.4005
605.094	23.1024
608.562	21.5935
612.027	23.805
615.493	24.9703
618.956	23.5716
622.419	23.8611
625.879	25.3131
629.338	27.5864
632.797	27.9318
636.254	30.3515
639.708	30.9289
643.162	27.3826
646.614	24.3992
650.067	23.8045
653.516	21.0196
656.964	18.871
660.411	18.1222
663.857	16.5231
667.301	15.0801
670.744	12.65
674.186	12.2893
677.626	13.1982
681.065	15.0975
684.503	15.2365
687.939	16.7915
691.372	19.4397
694.806	21.4441
698.239	20.1723
701.67	19.7962
705.098	24.3229
708.526	28.7751
711.954	31.8992
715.378	34.3281
718.802	33.481
722.226	34.3486
725.646	33.1776
729.067	33.7855
732.484	36.2042
735.902	37.3577
739.317	38.8451
742.731	39.6873
746.145	39.727
749.556	42.3696
752.966	46.4625
756.377	49.429
759.784	51.6105
763.19	53.7163
766.594	56.2727
770	57.9333
773.402	56.2821
776.803	55.9739
780.202	54.6277
783.6	55.7268
786.997	57.9604
790.393	62.1043
793.787	62.5562
797.18	63.4366
800.572	65.314
803.963	66.0045
807.35	67.0411
810.738	67.0419
814.125	68.8704
817.51	69.6203
820.894	73.2895
824.275	71.514
827.657	74.2663
831.037	77.5126
834.414	84.3692
837.792	85.7531
841.167	86.9662
844.542	86.9961
847.914	87.7673
851.287	92.0217
854.656	91.6226
858.026	92.8221
861.393	93.0151
864.761	91.2865
868.125	91.4841
871.489	88.9016
874.85	87.6081
878.213	83.7749
881.572	79.6264
884.931	72.1005
888.287	67.1655
891.643	60.5523
894.997	56.9389
898.352	52.1409
901.704	50.824
905.055	47.5006
908.404	47.6141
911.75	46.806
915.097	46.6507
918.443	47.2427
921.787	45.1894
925.13	44.5257
928.472	45.6076
931.813	45.9524
935.15	44.5865
938.488	41.1606
941.825	39.7842
945.158	37.9449
948.493	35.8992
951.824	31.5589
955.156	25.9467
958.486	20.7873
961.814	17.5789
965.142	18.881
968.467	20.6557
971.79	22.2841
975.115	24.4924
978.436	25.8566
981.756	28.22
985.077	30.7692
988.394	32.5103
991.71	32.2721
995.025	33.6611
998.341	34.2208
1001.65	32.6366
1004.97	31.4524
1008.28	36.2336
1011.58	40.1004
1014.89	43.3616
1018.2	46.5587
1021.5	53.3972
1024.81	60.4532
1028.11	64.4511
1031.41	67.2809
1034.71	69.172
1038.01	74.0238
1041.31	77.1838
1044.6	84.0857
1047.9	88.3606
1051.19	87.982
1054.48	86.9531
1057.77	85.365
1061.06	81.9645
1064.35	78.0801
1067.64	72.2947
1070.93	64.8837
1074.21	58.0191
1077.49	53.0093
1080.78	44.9037
1084.06	38.7243
1087.34	37.649
1090.61	40.4726
1093.89	39.6877
1097.17	39.8046
1100.44	37.4115
1103.71	39.3472
1106.99	35.5838
1110.26	34.1814
1113.52	31.4424
1116.79	27.8607
1120.06	26.0906
1123.32	21.7671
1126.59	21.1966
1129.85	22.97
1133.11	20.0011
1136.37	17.7171
1139.63	15.3684
1142.89	15.9244
1146.15	14.4639
1149.4	12.4908
1152.66	10.8155
1155.91	10.352
1159.16	9.74855
1162.41	6.9686
1165.66	5.83976
1168.91	5.12323
1172.16	5.20289
1175.4	6.42943
1178.65	6.2364
1181.89	6.60234
1185.13	7.2638
1188.37	4.9512
1191.61	5.35485
1194.85	6.18657
1198.08	7.44645
1201.32	7.42896
1204.55	8.9723
1207.79	14.0886
1211.02	20.5912
1214.25	25.3879
1217.48	35.1599
1220.71	44.0095
1223.93	53.2707
1227.16	63.1286
1230.38	71.9845
1233.6	78.2792
1236.83	87.4802
1240.05	94.0465
1243.26	99.4221
1246.48	104.234
1249.7	111.607
1252.92	116.757
1256.13	122.974
1259.34	125.562
1262.55	128.218
1265.76	130.645
1268.97	131.865
1272.18	132.226
1275.39	134.644
1278.59	133.77
1281.8	133.914
1285	137.82
1288.2	143.981
1291.4	150.789
1294.6	153.135
1297.8	156.777
1301	159.009
1304.19	163.027
1307.39	164.105
1310.58	164.235
1313.77	166.626
1316.96	166.26
1320.15	163.457
1323.34	160.312
1326.53	158.19
1329.72	158.101
1332.9	153.284
1336.08	149.863
1339.27	146.246
1342.45	144.339
1345.63	139.887
1348.8	136.736
1351.98	134.898
1355.16	133.379
1358.33	130.845
1361.51	134.034
1364.68	133.39
1367.85	133.548
1371.02	135.524
1374.19	133.079
1377.36	135.813
1380.52	138.55
1383.69	139.536
1386.85	143.516
1390.02	146.726
1393.18	149.257
1396.34	149.455
1399.5	155.76
1402.65	162.346
1405.81	169.894
1408.97	177.737
1412.12	186.73
1415.27	199.461
1418.43	211.579
1421.58	226.726
1424.73	241.025
1427.87	258.013
1431.02	275.189
1434.17	288.75
1437.31	301.512
1440.46	310.336
1443.6	314.676
1446.74	315.85
1449.88	312.066
1453.02	308.846
1456.16	300.952
1459.29	290.841
1462.43	276.022
1465.56	258.486
1468.69	239.411
1471.83	215.894
1474.95	196.386
1478.08	178.818
1481.21	160.256
1484.34	140.126
1487.47	123.606
1490.59	110.85
1493.71	97.1297
1496.84	84.7127
1499.96	79.392
1503.07	72.5559
1506.19	67.3915
1509.31	64.9781
1512.43	62.6158
1515.54	60.6184
1518.65	59.1226
1521.77	57.4079
1524.88	57.4694
1527.99	60.4619
1531.1	61.5595
1534.21	62.4183
1537.31	67.8203
1540.42	71.4182
1543.52	78.748
1546.63	82.1821
1549.73	89.5744
1552.83	98.3501
1555.93	105.317
1559.03	112.431
1562.12	121.188
1565.22	126.995
1568.31	133.828
1571.41	142.305
1574.5	150.121
1577.59	159.97
1580.68	168.596
1583.77	174.736
1586.86	182.156
1589.95	186.225
1593.03	189.94
1596.11	191.206
1599.2	192.973
1602.28	194.062
1605.36	193.509
1608.44	190.11
1611.52	188.044
1614.6	188.21
1617.67	187.496
1620.75	187.215
1623.82	185.376
1626.89	183.876
1629.96	182.999
1633.04	182.994
1636.11	181.598
1639.17	180.206
1642.24	180.237
1645.31	180.533
1648.37	179.494
1651.43	175.584
1654.5	175.762
1657.56	170.573
1660.62	164.168
1663.67	159.653
1666.73	152.561
1669.79	144.509
1672.84	134.642
1675.9	124.326
1678.95	111.591
1682	100.649
1685.05	91.604
1688.1	83.3383
1691.15	74.36
1694.2	66.2093
1697.25	61.4893
1700.29	52.3545
1703.33	48.0215
1706.38	44.546
1709.42	40.9594
1712.46	36.032
1715.5	36.0193
1718.54	35.1314
1721.57	34.6581
1724.61	34.6353
1727.64	32.3201
1730.68	32.428
1733.71	29.6594
1736.74	29.1839
1739.77	25.8513
1742.8	24.571
1745.83	23.9762
1748.85	20.689
1751.88	17.6558
1754.91	17.5028
1757.93	17.0478
1760.95	13.2736
1763.97	10.9073
1766.99	7.73277
1770.01	6.65432
1773.03	3.7836
1776.04	1.35912
1779.06	1.23376
1782.07	1.09666
1785.09	1.59593
1788.1	2.68234
1791.11	4.10936
1794.12	3.82814
1797.13	4.01827
1800.13	2.66704
1803.14	1.76357
1806.15	-0.00564992
1809.15	-0.0155481
1812.15	-0.317292
1815.16	0.395543
1818.15	0.567447
1821.16	1.6017
1824.15	0.0419556
1827.15	1.51365
1830.15	1.71595
1833.14	2.90974
1836.14	3.0989
1839.13	5.79643
1842.12	6.27845
1845.11	7.41009
1848.1	7.64758
1851.09	9.04245
1854.08	9.06348
1857.06	10.7035
1860.05	10.0545
1863.03	10.3386
1866.01	11.4789
1869	10.3204
1871.98	11.2986
1874.96	10.5311
1877.93	10.8068
1880.91	10.2067
1882.47	10.6886
1885.46	10.3717
1888.44	10.5521
1891.43	9.28133
1894.42	8.9808
1897.4	9.69997
1900.39	9.91518
1903.37	9.69056
1906.35	9.9496
1909.33	9.15413
1912.31	8.72533
1915.29	7.74193
1918.26	6.49434
1921.24	3.93121
1924.21	3.78764
1927.19	3.52452
1930.16	4.70538
1933.13	4.49098
1936.1	4.88886
1939.07	5.83475
1942.04	7.66423
1945	8.91417
1947.97	9.50897
1950.93	9.42691
1953.9	10.6646
1956.86	10.6608
1959.82	9.82542
1962.78	8.84876
1965.74	7.67594
1968.7	6.92233
1971.65	8.43604
1974.61	7.28127
1977.57	7.51608
1980.52	5.52704
1983.47	4.04593
1986.42	3.75844
1989.37	2.21264
1992.32	1.63744
1995.27	3.16572
1998.22	4.19248
2001.17	5.87015
2004.11	6.74958
2007.05	8.5386
2010	10.4185
2012.94	10.9889
2015.88	9.31763
2018.82	10.3342
2021.76	9.39227
2024.7	11.1968
2027.63	11.0913
2030.57	11.7122
2033.5	12.701
2036.44	13.3105
2039.37	14.3213
2042.3	17.2731
2045.23	20.4873
2048.16	22.4778
2051.08	23.6721
2054.01	25.3515
2056.94	27.5716
2059.86	31.6532
2062.79	35.3127
2065.71	38.0352
2068.63	39.8699
2071.55	41.9156
2074.47	42.7108
2077.39	43.9539
2080.31	43.2257
2083.22	43.6865
2086.13	42.9151
2089.05	43.6238
2091.96	42.5011
2094.87	43.7736
2097.78	43.4613
2100.69	43.5023
2103.6	43.6159
2106.51	45.4367
2109.42	45.4006
2112.32	48.7675
2115.23	52.7078
2118.13	58.0823
2121.03	62.4169
2123.93	66.2157
2126.83	70.8208
2129.73	75.6942
2132.63	83.0079
2135.53	88.2257
2138.42	92.8107
2141.32	98.0116
2144.21	103.136
2147.1	109.028
2150	114.824
2152.89	118.629
2155.78	123.394
2158.66	127.367
2161.55	129.737
2164.44	131.888
2167.32	132.657
2170.21	133.308
2173.09	132.141
2175.97	131.505
2178.85	131.177
2181.73	129.983
2184.61	127.6
2187.49	126.537
2190.37	122.975
2193.24	119.027
2196.12	115.073
2198.99	109.808
2201.87	106.268
2204.74	101.912
2207.61	96.2781
2210.48	91.3149
2213.35	85.9356
2216.21	84.3201
2219.08	81.185
2221.95	79.2435
2224.81	75.313
2227.67	73.749
2230.54	71.9418
2233.4	69.0016
2236.26	66.2146
2239.11	63.3273
2241.97	59.0838
2244.83	55.6888
2247.69	55.4264
2250.54	51.5766
2253.4	52.0337
2256.25	47.859
2259.1	46.0602
2261.95	44.301
2264.8	40.509
2267.65	39.1891
2270.5	34.1509
2273.34	32.3586
2276.19	29.2361
2279.03	28.3513
2281.88	27.321
2284.72	27.5942
2287.56	28.7646
2290.4	28.3363
2293.24	26.059
2296.08	26.6646
2298.92	27.33
2301.76	27.3441
2304.59	25.4372
2307.43	25.1016
2310.26	24.4693
2313.09	23.4778
2315.92	23.3237
2318.75	22.4665
2321.58	21.8452
2324.41	17.7144
2327.24	14.2401
2330.06	12.3194
2332.89	11.5686
2335.71	9.13363
2338.54	7.06211
2341.36	4.85113
2344.18	2.05513
2347	2.41999
2349.82	1.4335
2352.64	1.39694
2355.45	0.201798
2358.27	0.61684
2361.08	0.23221
2363.9	1.73604
2366.71	3.9689
2369.52	1.72806
2372.33	2.67803
2375.14	3.8351
2377.95	4.14443
2380.76	4.49187
2383.57	4.73205
2386.37	5.2286
2389.18	7.16255
2391.98	5.70892
2394.79	6.76156
2397.59	7.42779
2400.39	9.25334
2403.19	10.7027
2405.99	12.4168
2408.78	12.97
2411.58	13.7127
2414.38	16.253
2417.17	18.0417
2419.97	19.0823
2422.76	20.7855
2425.55	21.2686
2428.34	21.7187
2431.13	22.5025
2433.92	23.4379
2436.71	22.2794
2439.49	21.1698
2442.28	20.5863
2445.06	20.0481
2447.85	20.8787
2450.63	22.4516
2453.41	19.8889
2456.19	21.4696
2458.97	18.4325
2461.75	18.0303
2464.53	16.6383
2467.31	15.3245
2470.08	15.5093
2472.86	14.3681
2475.63	12.0343
2478.4	9.92589
2481.17	10.2384
2483.94	10.7329
2486.72	11.1299
2489.48	8.35184
2492.25	9.54865
2495.02	9.95351
2497.79	8.38547
2500.55	10.1613
2503.31	11.4628
2506.08	11.7938
2508.84	14.2821
2511.6	13.4888
2514.36	16.5233
2517.12	17.964
2519.88	18.9812
2522.63	20.0999
2525.39	21.5694
2528.14	20.3552
2530.9	21.9113
2533.65	21.3164
2536.4	22.8903
2539.15	25.3767
2541.9	27.0418
2544.65	28.1489
2547.4	29.1024
2550.15	30.4688
2552.89	30.8694
2555.64	31.2601
2558.38	32.29
2561.12	33.6298
2563.87	33.0583
2566.61	33.211
2569.35	34.2611
2572.09	30.6563
2574.83	29.1092
2577.56	28.0797
2580.3	26.2125
2583.04	25.431
2585.77	25.0822
2588.5	23.3942
2591.23	22.066
2593.97	20.5234
2596.7	20.7368
2599.43	21.7061
2602.15	22.4116
2604.88	25.7615
2607.61	25.9267
2610.33	25.5915
2613.06	24.723
2615.78	23.7605
2618.51	25.6786
2621.23	25.9295
2623.95	28.0686
2626.67	28.3481
2629.39	26.1691
2632.1	25.0658
2634.82	25.0342
2637.54	23.2859
2640.25	21.6504
2642.97	20.3516
2645.68	20.8426
2648.39	21.8903
2651.1	23.4332
2653.81	25.3142
2656.52	24.4133
2659.23	27.198
2661.94	29.5221
2664.64	31.3718
2667.35	34.1745
2670.05	34.6491
2672.76	36.2344
2675.46	35.3748
2678.16	36.6016
2680.86	34.8988
2683.56	36.3735
2686.26	36.3937
2688.96	36.7192
2691.65	34.2321
2694.35	32.1909
2697.04	32.4749
2699.74	33.8008
2702.43	33.7121
2705.12	33.5302
2707.81	34.6245
2710.5	36.8451
2713.19	38.8297
2715.88	38.1084
2718.57	39.3635
2721.25	38.3409
2723.94	41.2727
2726.62	41.7683
2729.3	43.2201
2731.99	41.8111
2734.67	43.2855
2737.35	42.9109
2740.03	40.7614
2742.71	39.5632
2745.38	38.1596
2748.06	35.0028
2750.74	33.12
2753.41	30.3026
2756.09	26.5888
2758.76	24.3714
2761.43	21.84
2764.1	20.5893
2766.77	18.2994
2769.44	16.1655
2772.11	14.37
2774.77	12.1755
2777.44	7.70511
2780.11	4.61934
2782.77	2.62945
2785.43	1.09077
2788.1	-0.120836
2790.76	1.79455
2793.42	1.14518
2796.08	0.661592
2798.74	0.279777
2801.4	1.24497
2804.05	-0.57083
2806.71	-0.158748
2809.36	0.312607
2812.02	0.511075
2814.67	3.44545
2817.32	5.99786
2819.97	11.503
2822.62	20.3714
2825.27	33.998
2827.92	48.6461
2830.57	66.908
2833.22	84.7939
2835.86	104.829
2838.51	127.856
2841.15	151.295
2843.79	174.8
2846.43	203.43
2849.08	228.747
2851.72	256.243
2854.36	282.046
2856.99	310.119
2859.63	333.608
2862.27	358.372
2864.9	380.528
2867.54	400.54
2870.17	418.84
2872.8	435.931
2875.43	451.849
2878.07	464.527
2880.7	482.09
2883.32	500.374
2885.95	518.493
2888.58	538.008
2891.21	557.588
2893.83	577.419
2896.46	597.578
2899.08	620.422
2901.7	644.078
2904.32	669.466
2906.94	692.69
2909.56	719.156
2912.18	745.3
2914.8	768.323
2917.42	791.671
2920.03	810.789
2922.65	825.074
2925.26	831.89
2927.88	834.197
2930.49	828.475
2933.1	817.253
2935.71	800.828
2938.32	778.333
2940.93	751.171
2943.54	721.403
2946.14	689.65
2948.75	654.445
2951.35	620.086
2953.96	584.834
2956.56	549.293
2959.16	518.503
2961.77	487.054
2964.37	459.134
2966.96	433.009
2969.56	409.542
2972.16	387.605
2974.76	368.105
2977.35	347.167
2979.95	328.975
2982.54	309.447
2985.14	288.975
2987.73	265.452
2990.32	240.312
2992.91	215.467
2995.5	191.995
2998.09	169.44
3000.68	146.553
3003.26	125.05
3005.85	103.917
3008.43	86.9602
3011.02	69.6278
3013.6	55.9342
3016.19	44.9531
3018.77	34.4673
3021.35	25.7371
3023.93	18.952
3026.5	13.3064
3029.08	9.12211
3031.66	6.62877
3034.24	4.33817
3036.81	3.54603
3039.39	3.25084
3041.96	3.81383
3044.53	6.80928
3047.1	7.91092
3049.67	6.51606
3052.24	4.38043
3054.81	6.03149
3057.38	6.36141
3059.95	6.91225
3062.52	7.35723
3065.08	8.21138
3067.65	8.71726
3070.21	7.97944
3072.77	6.30477
3075.33	4.9433
3077.89	4.49857
3080.45	3.32455
3083.01	1.44466
3085.57	1.13426
3088.13	-0.80439
3090.68	-0.219327
3093.24	0.872298
3095.79	0.385514
3098.35	1.69707
3100.9	0.866747
3103.45	1.45608
3106	3.5398
3108.55	6.13525
3111.1	7.57694
3113.65	10.8956
3116.2	14.7519
3118.75	17.7938
3121.29	22.2247
3123.84	27.8497
3126.38	33.3737
3128.92	39.8506
3131.47	45.3148
3134.01	50.2129
3136.55	55.5411
3139.09	63.2241
3141.63	70.3477
3144.17	77.5324
3146.7	84.0846
3149.24	90.5599