File: data/Raman/poly_smoothed/Mb_40_24_20_1x_45s_532 nm_x100_100%_600 gr_mm_01.txt
#Acq. time (s)=	45
#Accumulations=	2
#Range (cm-¹)=	200...3150
#Windows=	2
#Auto scanning=	Off
#Autofocus=	Off
#Macrospot=	Off
#AutoExposure=	Off
#Spike filter=	Multiple accum.
#Delay time (s)=	0
#Binning=	1
#Readout mode=	Signal
#DeNoise=	Off
#ICS correction=	On
#Dark correction=	Off
#Inst. Process=	Off
#Detector Gain=	Best Dynamic Range
#Detector ADC=	20 kHz
#Detector temperature (°C)=	-70.08
#Instrument=	LabRAM HR Evol
#Detector=	Synapse
#Objective=	x100
#Grating=	600 gr/mm
#ND Filter=	100%
#Laser (nm)=	532
#Hole=	100.021
#Range=	Auto
#Laser Pol.=	No
#Raman. Pol.=	No
#Laser Pol. (°)=	-0.0007625
#Raman Pol. (°)=	89.9995
#Collection=	Microscope
#StageXY=	Marzhauser
#StageZ=	Marzhauser
#X (µm)=	-2511
#Y (µm)=	-127.6
#Z (µm)=	-10.65
#Full time(mm:ss)=	3:09
#Project=
#Sample=
#Site=
#Title=	Mb_40_24_20_2x_45s_532 nm_x100_100%_600 gr_mm
#Remark=
#Date=	14.07.2022 12:12
#Acquired=	14.07.2022 12:12:07
#Base:Fit=	10.08.2022 10:47:00
#Base:Sub=	10.08.2022 10:47:12
#Filter:Polynom=	16.08.2022 10:11:48
#AxisType[0]=Intens
#AxisUnit[0]=Cnt
#AxisType[1]=Spectr
#AxisUnit[1]=1/cm
200.554	39.5834
204.183	26.0347
207.813	19.337
211.439	16.216
215.065	14.6196
218.688	15.0301
222.312	16.1209
225.933	16.6049
229.552	17.7873
233.171	16.6427
236.787	16.133
240.402	18.7398
244.015	20.2712
247.627	21.9024
251.24	25.3455
254.849	32.4335
258.457	38.5764
262.063	44.7161
265.668	49.8257
269.271	54.9725
272.873	59.249
276.474	58.872
280.073	59.3904
283.671	59.5938
287.268	61.886
290.863	66.2838
294.456	69.56
298.049	74.8854
301.637	78.5918
305.227	82.6632
308.815	82.9214
312.402	85.0294
315.987	83.2099
319.569	81.8734
323.151	81.0838
326.733	79.0293
330.31	79.8577
333.889	76.843
337.464	76.2192
341.039	76.1937
344.611	72.3109
348.184	67.1313
351.754	62.6167
355.324	58.443
358.89	51.4986
362.455	45.623
366.021	41.6559
369.584	38.7397
373.145	33.4306
376.707	33.3008
380.265	31.5736
383.822	30.4762
387.378	31.3708
390.934	30.4549
394.487	29.0986
398.038	28.8571
401.588	29.4756
405.137	30.2509
408.685	31.7256
412.23	33.8022
415.775	33.247
419.318	32.3934
422.86	33.1476
426.401	33.3204
429.94	31.0111
433.478	28.7605
437.012	27.556
440.547	24.8177
444.081	24.1857
447.613	19.9677
451.142	19.6274
454.672	16.2343
458.2	10.7406
461.725	10.8029
465.251	9.75825
468.775	8.11679
472.296	7.9785
475.817	7.73092
479.335	7.27438
482.854	7.11523
486.37	9.94755
489.886	13.1861
493.398	15.7955
496.91	18.6216
500.422	20.1464
503.93	19.2099
507.438	20.539
510.946	21.5555
514.45	21.6533
517.954	20.3107
521.456	20.2198
524.956	18.5854
528.456	14.7526
531.956	15.051
535.452	15.771
538.947	13.8676
542.441	10.9843
545.934	10.8121
549.425	12.1677
552.915	9.59429
556.403	7.51589
559.889	7.05561
563.375	5.66387
566.859	3.8775
570.342	3.99905
573.824	5.03314
577.303	5.55892
580.782	4.64039
584.26	5.08298
587.734	2.00602
591.21	2.25005
594.684	2.02286
598.154	1.10804
601.626	1.12265
605.094	1.51196
608.562	3.16241
612.027	4.47746
615.493	7.64622
618.956	9.14065
622.419	9.96486
625.879	10.6225
629.338	11.3348
632.797	12.3312
636.254	12.8493
639.708	10.8127
643.162	12.099
646.614	11.3032
650.067	11.3034
653.516	13.2246
656.964	12.9436
660.411	12.2672
663.857	11.7053
667.301	12.2929
670.744	8.96521
674.186	7.64059
677.626	9.49115
681.065	10.3154
684.503	11.5636
687.939	12.3815
691.372	13.4039
694.806	13.6682
698.239	14.2004
701.67	11.8806
705.098	12.8491
708.526	13.5363
711.954	12.5593
715.378	14.3915
718.802	14.3563
722.226	12.7307
725.646	12.0971
729.067	12.4892
732.484	12.3147
735.902	13.4123
739.317	12.7533
742.731	11.6762
746.145	11.8121
749.556	14.7138
752.966	17.2297
756.377	19.6251
759.784	22.2598
763.19	27.1575
766.594	29.4847
770	31.6298
773.402	31.4162
776.803	34.17
780.202	33.8845
783.6	35.6219
786.997	37.97
790.393	41.3757
793.787	41.3046
797.18	40.0985
800.572	39.4428
803.963	37.3442
807.35	37.9497
810.738	37.9926
814.125	37.0855
817.51	38.142
820.894	35.9863
824.275	36.2055
827.657	37.8171
831.037	38.551
834.414	39.7592
837.792	40.2578
841.167	43.0858
844.542	44.114
847.914	44.7093
851.287	43.9795
854.656	43.6962
858.026	42.1238
861.393	41.0505
864.761	38.5414
868.125	38.3882
871.489	38.1049
874.85	34.93
878.213	33.2278
881.572	30.9495
884.931	31.6767
888.287	31.0231
891.643	31.3509
894.997	31.6689
898.352	32.5656
901.704	31.6534
905.055	33.2634
908.404	34.9615
911.75	36.0071
915.097	36.5438
918.443	37.7048
921.787	38.6086
925.13	39.1685
928.472	37.9817
931.813	36.9039
935.15	35.2543
938.488	33.1671
941.825	31.4946
945.158	29.9011
948.493	29.1229
951.824	28.9479
955.156	25.8375
958.486	24.8343
961.814	24.0713
965.142	26.1062
968.467	26.7058
971.79	27.9687
975.115	29.9041
978.436	29.6646
981.756	29.5987
985.077	29.5739
988.394	29.9826
991.71	27.0016
995.025	29.8437
998.341	28.3077
1001.65	26.9644
1004.97	27.1633
1008.28	26.7436
1011.58	28.3606
1014.89	30.1217
1018.2	29.2795
1021.5	31.9983
1024.81	33.6549
1028.11	35.4939
1031.41	38.0126
1034.71	37.4573
1038.01	39.6444
1041.31	44.3652
1044.6	45.3071
1047.9	44.9665
1051.19	44.8491
1054.48	44.2654
1057.77	42.4495
1061.06	38.812
1064.35	37.4
1067.64	34.4135
1070.93	33.2204
1074.21	33.1288
1077.49	28.9985
1080.78	27.1853
1084.06	25.946
1087.34	26.7851
1090.61	25.8687
1093.89	25.0603
1097.17	23.1268
1100.44	21.3727
1103.71	21.668
1106.99	22.7358
1110.26	22.726
1113.52	22.2496
1116.79	21.6543
1120.06	22.2036
1123.32	21.2607
1126.59	18.7679
1129.85	19.9777
1133.11	21.0256
1136.37	18.971
1139.63	18.5121
1142.89	17.9123
1146.15	16.0223
1149.4	15.0532
1152.66	14.7751
1155.91	11.6265
1159.16	12.4168
1162.41	11.3315
1165.66	9.87575
1168.91	8.59782
1172.16	5.67306
1175.4	2.96444
1178.65	0.710412
1181.89	1.4981
1185.13	2.22383
1188.37	3.73531
1191.61	5.17062
1194.85	8.22171
1198.08	12.2601
1201.32	16.0451
1204.55	19.6493
1207.79	24.2562
1211.02	28.9391
1214.25	34.2236
1217.48	39.7659
1220.71	46.676
1223.93	53.0685
1227.16	58.2306
1230.38	65.4851
1233.6	69.5722
1236.83	76.6519
1240.05	82.6598
1243.26	86.5527
1246.48	92.1876
1249.7	94.8125
1252.92	98.3708
1256.13	100.756
1259.34	103.968
1262.55	108.262
1265.76	112.097
1268.97	115.138
1272.18	119.297
1275.39	121.592
1278.59	125.219
1281.8	125.706
1285	127.975
1288.2	131.718
1291.4	135
1294.6	138.532
1297.8	141.714
1301	142.132
1304.19	143.64
1307.39	143.046
1310.58	143.819
1313.77	148.919
1316.96	150.845
1320.15	150.832
1323.34	150.136
1326.53	150.146
1329.72	147.418
1332.9	145.202
1336.08	144.465
1339.27	141.503
1342.45	140.564
1345.63	137.405
1348.8	136.226
1351.98	134.24
1355.16	131.596
1358.33	129.577
1361.51	125.885
1364.68	122.293
1367.85	118.778
1371.02	116.694
1374.19	114.3
1377.36	111.109
1380.52	108.239
1383.69	108.079
1386.85	108.723
1390.02	110.762
1393.18	112.817
1396.34	114.307
1399.5	115.869
1402.65	118.308
1405.81	122.196
1408.97	126.552
1412.12	134.693
1415.27	142.685
1418.43	150.564
1421.58	158.322
1424.73	169.325
1427.87	178.275
1431.02	188.267
1434.17	195.327
1437.31	199.88
1440.46	204.886
1443.6	206.544
1446.74	208.055
1449.88	206.325
1453.02	204.113
1456.16	198.803
1459.29	194.166
1462.43	186.939
1465.56	178.565
1468.69	169.174
1471.83	158.998
1474.95	148.489
1478.08	135.669
1481.21	125.806
1484.34	116.749
1487.47	108.37
1490.59	101.27
1493.71	94.8956
1496.84	88.0811
1499.96	83.1982
1503.07	82.8221
1506.19	78.6426
1509.31	75.3557
1512.43	72.5492
1515.54	69.3013
1518.65	68.4469
1521.77	67.5845
1524.88	69.359
1527.99	71.7571
1531.1	73.4507
1534.21	76.8276
1537.31	77.672
1540.42	82.7462
1543.52	87.669
1546.63	94.1727
1549.73	97.9809
1552.83	102.161
1555.93	106.531
1559.03	110.023
1562.12	114.598
1565.22	119.777
1568.31	125.842
1571.41	128.711
1574.5	134.285
1577.59	139.648
1580.68	143.366
1583.77	147.571
1586.86	149.972
1589.95	152.825
1593.03	155.695
1596.11	157.929
1599.2	158.15
1602.28	157.863
1605.36	154.967
1608.44	153.311
1611.52	152.74
1614.6	152.676
1617.67	152.013
1620.75	151.437
1623.82	150.036
1626.89	149.017
1629.96	147.608
1633.04	145.767
1636.11	147.327
1639.17	146.25
1642.24	150.004
1645.31	150.749
1648.37	150.889
1651.43	152.498
1654.5	151.809
1657.56	150.816
1660.62	148.204
1663.67	145.728
1666.73	139.203
1669.79	131.027
1672.84	122.574
1675.9	113.448
1678.95	103.604
1682	94.348
1685.05	87.3181
1688.1	79.1905
1691.15	70.9755
1694.2	65.1123
1697.25	58.6254
1700.29	51.3323
1703.33	46.2232
1706.38	42.3674
1709.42	37.7449
1712.46	33.4503
1715.5	32.7066
1718.54	31.3626
1721.57	29.7249
1724.61	29.4696
1727.64	28.6889
1730.68	27.3252
1733.71	26.7896
1736.74	26.6898
1739.77	23.8987
1742.8	21.4024
1745.83	19.9515
1748.85	17.1043
1751.88	17.024
1754.91	16.3226
1757.93	15.3782
1760.95	16.5798
1763.97	13.8467
1766.99	13.6647
1770.01	12.4494
1773.03	11.6536
1776.04	10.5499
1779.06	9.63361
1782.07	8.31918
1785.09	8.34208
1788.1	8.69252
1791.11	7.59597
1794.12	6.02381
1797.13	4.88002
1800.13	4.03044
1803.14	3.14739
1806.15	4.09795
1809.15	3.17255
1812.15	2.67411
1815.16	2.34996
1818.15	2.46678
1821.16	2.44285
1824.15	3.76889
1827.15	5.60775
1830.15	6.07076
1833.14	7.17196
1836.14	6.56836
1839.13	6.24539
1842.12	6.79431
1845.11	6.78194
1848.1	6.5945
1851.09	5.48029
1854.08	4.62693
1857.06	3.10688
1860.05	3.1792
1863.03	2.66835
1866.01	0.94228
1869	-0.314036
1871.98	0.427109
1874.96	1.19493
1877.93	2.64597
1880.91	3.52879
1882.47	2.53355
1885.46	4.5163
1888.44	6.53648
1891.43	8.24528
1894.42	9.22475
1897.4	8.755
1900.39	10.1242
1903.37	11.1424
1906.35	11.0756
1909.33	13.4404
1912.31	15.0827
1915.29	15.3496
1918.26	15.2878
1921.24	15.0375
1924.21	13.9691
1927.19	14.73
1930.16	14.4287
1933.13	13.9495
1936.1	11.9145
1939.07	10.6993
1942.04	10.283
1945	8.93443
1947.97	7.50743
1950.93	5.86662
1953.9	5.57414
1956.86	5.80601
1959.82	4.82875
1962.78	4.28318
1965.74	4.32856
1968.7	3.33577
1971.65	3.22517
1974.61	4.8582
1977.57	6.25899
1980.52	8.92073
1983.47	10.121
1986.42	10.9113
1989.37	12.1273
1992.32	11.9263
1995.27	12.6916
1998.22	14.0838
2001.17	14.4136
2004.11	14.4112
2007.05	14.5652
2010	15.0748
2012.94	14.8952
2015.88	14.9758
2018.82	15.2712
2021.76	15.97
2024.7	16.0764
2027.63	17.2324
2030.57	14.985
2033.5	14.722
2036.44	14.943
2039.37	16.1182
2042.3	15.3271
2045.23	15.5351
2048.16	15.9271
2051.08	15.8787
2054.01	15.6554
2056.94	15.8159
2059.86	16.7591
2062.79	16.5952
2065.71	18.297
2068.63	21.6338
2071.55	22.7021
2074.47	24.1229
2077.39	25.0121
2080.31	28.7566
2083.22	31.3139
2086.13	33.7759
2089.05	38.4319
2091.96	39.4741
2094.87	40.6294
2097.78	42.7105
2100.69	46.2857
2103.6	49.1127
2106.51	52.2779
2109.42	55.1651
2112.32	57.3841
2115.23	61.0099
2118.13	64.6569
2121.03	68.2764
2123.93	73.5167
2126.83	77.8802
2129.73	81.9324
2132.63	86.8166
2135.53	92.6058
2138.42	99.5697
2141.32	102.398
2144.21	106.37
2147.1	109.287
2150	114.126
2152.89	120.202
2155.78	125.015
2158.66	127.671
2161.55	131.488
2164.44	132.32
2167.32	134.26
2170.21	136.201
2173.09	138.405
2175.97	136.4
2178.85	135.077
2181.73	135.017
2184.61	133.958
2187.49	130.581
2190.37	128.046
2193.24	124.575
2196.12	121.039
2198.99	115.17
2201.87	110.215
2204.74	105.928
2207.61	100.582
2210.48	95.1378
2213.35	87.8134
2216.21	82.7861
2219.08	77.9398
2221.95	75.3857
2224.81	70.2401
2227.67	65.5488
2230.54	60.5185
2233.4	56.3556
2236.26	51.4566
2239.11	47.3698
2241.97	46.123
2244.83	43.1092
2247.69	41.1028
2250.54	39.3304
2253.4	37.4292
2256.25	35.9692
2259.1	33.513
2261.95	33.2857
2264.8	29.133
2267.65	26.6267
2270.5	24.5123
2273.34	23.1533
2276.19	21.5653
2279.03	19.6916
2281.88	17.4744
2284.72	15.3965
2287.56	14.4197
2290.4	14.3101
2293.24	12.5084
2296.08	10.0013
2298.92	9.62097
2301.76	9.29325
2304.59	9.5757
2307.43	9.97306
2310.26	10.9455
2313.09	11.7572
2315.92	12.6652
2318.75	12.703
2321.58	13.4829
2324.41	12.2811
2327.24	11.8487
2330.06	11.2015
2332.89	10.2471
2335.71	9.37504
2338.54	8.17651
2341.36	6.61948
2344.18	5.76338
2347	3.41438
2349.82	2.1118
2352.64	2.30014
2355.45	1.53773
2358.27	2.47247
2361.08	2.05618
2363.9	0.67432
2366.71	2.31186
2369.52	3.16923
2372.33	4.4365
2375.14	3.74904
2377.95	5.10168
2380.76	4.95894
2383.57	6.20437
2386.37	6.52777
2389.18	6.38525
2391.98	6.14918
2394.79	5.65989
2397.59	5.1705
2400.39	4.23674
2403.19	3.63472
2405.99	2.30004
2408.78	2.87882
2411.58	5.27336
2414.38	4.36247
2417.17	5.51101
2419.97	6.66932
2422.76	6.69716
2425.55	6.39358
2428.34	5.83149
2431.13	5.2347
2433.92	5.57879
2436.71	5.11171
2439.49	5.2535
2442.28	4.98197
2445.06	4.32566
2447.85	4.49705
2450.63	3.43531
2453.41	3.90868
2456.19	2.01502
2458.97	1.75333
2461.75	1.47953
2464.53	0.630724
2467.31	1.63177
2470.08	3.57202
2472.86	5.34635
2475.63	6.60163
2478.4	8.6927
2481.17	9.24911
2483.94	9.73412
2486.72	8.00448
2489.48	9.11414
2492.25	6.90424
2495.02	7.65904
2497.79	6.8605
2500.55	7.4006
2503.31	6.45927
2506.08	5.72242
2508.84	5.948
2511.6	5.20775
2514.36	5.12817
2517.12	4.31312
2519.88	5.79238
2522.63	5.38869
2525.39	6.17305
2528.14	5.65867
2530.9	6.86407
2533.65	6.04758
2536.4	7.49631
2539.15	8.33626
2541.9	9.09108
2544.65	9.60319
2547.4	9.87496
2550.15	10.9922
2552.89	10.8759
2555.64	10.016
2558.38	10.0019
2561.12	10.391
2563.87	11.2462
2566.61	11.0355
2569.35	9.31558
2572.09	8.93154
2574.83	8.6099
2577.56	8.51737
2580.3	8.50537
2583.04	8.06774
2585.77	7.43794
2588.5	7.62909
2591.23	6.67169
2593.97	4.44194
2596.7	3.5137
2599.43	2.80851
2602.15	1.81396
2604.88	2.50741
2607.61	3.12969
2610.33	4.13424
2613.06	4.31039
2615.78	4.96756
2618.51	5.49375
2621.23	5.80123
2623.95	7.63942
2626.67	7.22512
2629.39	7.95247
2632.1	8.08866
2634.82	7.06269
2637.54	7.78945
2640.25	7.18065
2642.97	7.42353
2645.68	7.49352
2648.39	6.89367
2651.1	4.58961
2653.81	3.96057
2656.52	2.90412
2659.23	2.01292
2661.94	2.83331
2664.64	2.05814
2667.35	1.56882
2670.05	0.708988
2672.76	3.45359
2675.46	3.31605
2678.16	2.28628
2680.86	4.0573
2683.56	6.31274
2686.26	7.21178
2688.96	7.34329
2691.65	7.42322
2694.35	8.22177
2697.04	10.0802
2699.74	10.4449
2702.43	10.9262
2705.12	11.3928
2707.81	11.7905
2710.5	11.8432
2713.19	11.8639
2715.88	11.537
2718.57	12.458
2721.25	13.1794
2723.94	13.1278
2726.62	14.4683
2729.3	15.0448
2731.99	14.384
2734.67	13.8831
2737.35	14.1699
2740.03	13.9591
2742.71	12.6071
2745.38	12.0677
2748.06	11.5601
2750.74	10.1137
2753.41	8.68448
2756.09	8.33749
2758.76	7.5786
2761.43	8.25059
2764.1	7.21927
2766.77	5.75106
2769.44	5.06644
2772.11	3.73243
2774.77	2.94717
2777.44	3.06383
2780.11	1.32578
2782.77	0.923389
2785.43	1.41124
2788.1	0.514409
2790.76	0.400759
2793.42	1.05725
2796.08	0.387149
2798.74	-0.823465
2801.4	-1.39815
2804.05	-2.27319
2806.71	-3.15115
2809.36	-3.02779
2812.02	-3.04798
2814.67	-1.3859
2817.32	0.149715
2819.97	3.07978
2822.62	6.3012
2825.27	12.2625
2827.92	17.1236
2830.57	23.9637
2833.22	30.0092
2835.86	36.7468
2838.51	46.6294
2841.15	54.9842
2843.79	64.5432
2846.43	74.9409
2849.08	86.6281
2851.72	98.4785
2854.36	110.626
2856.99	122.796
2859.63	134.017
2862.27	144.716
2864.9	156.481
2867.54	165.792
2870.17	174.501
2872.8	183.014
2875.43	190.934
2878.07	199
2880.7	206.04
2883.32	215.373
2885.95	222.691
2888.58	232.139
2891.21	243.202
2893.83	254.311
2896.46	266.05
2899.08	279.241
2901.7	292.97
2904.32	308.441
2906.94	325.287
2909.56	344.163
2912.18	365.094
2914.8	383.416
2917.42	401.335
2920.03	416.927
2922.65	431.211
2925.26	441.821
2927.88	449.29
2930.49	452.057
2933.1	449.457
2935.71	444.324
2938.32	435.736
2940.93	424.286
2943.54	409.551
2946.14	395.093
2948.75	376.147
2951.35	356.476
2953.96	337.62
2956.56	317.636
2959.16	298.541
2961.77	280.92
2964.37	262.476
2966.96	244.945
2969.56	228.763
2972.16	216.117
2974.76	201.677
2977.35	187.806
2979.95	173.977
2982.54	160.497
2985.14	147.915
2987.73	133.499
2990.32	118.748
2992.91	104.691
2995.5	88.6739
2998.09	75.9365
3000.68	64.1038
3003.26	51.7336
3005.85	41.9253
3008.43	33.6315
3011.02	26.3763
3013.6	17.8089
3016.19	12.9657
3018.77	9.38506
3021.35	6.31099
3023.93	3.85806
3026.5	2.04708
3029.08	-0.158224
3031.66	-0.974843
3034.24	-0.17112
3036.81	0.790414
3039.39	2.75741
3041.96	4.05292
3044.53	6.1259
3047.1	6.86297
3049.67	8.9636
3052.24	8.99187
3054.81	7.76619
3057.38	6.94459
3059.95	7.72163
3062.52	8.45676
3065.08	7.85623
3067.65	9.39615
3070.21	7.72368
3072.77	8.14914
3075.33	6.87282
3077.89	5.75591
3080.45	5.32222
3083.01	3.80438
3085.57	2.57836
3088.13	2.45647
3090.68	1.79698
3093.24	2.03445
3095.79	4.39423
3098.35	5.88172
3100.9	6.85245
3103.45	8.99716
3106	10.91
3108.55	13.9137
3111.1	16.2274
3113.65	18.978
3116.2	21.4816
3118.75	23.5487
3121.29	27.4883
3123.84	30.6746
3126.38	34.3487
3128.92	38.1701
3131.47	42.8079
3134.01	44.707
3136.55	49.3328
3139.09	52.9892
3141.63	56.8844
3144.17	59.9909
3146.7	63.7722
3149.24	66.4151