File: data/Raman/poly_smoothed/Mb_40_y_11_2x_45s_532 nm_x100_100%_600 gr_mm.txt
#Acq. time (s)=	45
#Accumulations=	2
#Range (cm-¹)=	200...3150
#Windows=	2
#Auto scanning=	Off
#Autofocus=	Off
#Macrospot=	Off
#AutoExposure=	Off
#Spike filter=	Multiple accum.
#Delay time (s)=	0
#Binning=	1
#Readout mode=	Signal
#DeNoise=	Off
#ICS correction=	On
#Dark correction=	Off
#Inst. Process=	Off
#Detector Gain=	Best Dynamic Range
#Detector ADC=	20 kHz
#Detector temperature (°C)=	-69.85
#Instrument=	LabRAM HR Evol
#Detector=	Synapse
#Objective=	x100
#Grating=	600 gr/mm
#ND Filter=	100%
#Laser (nm)=	532
#Hole=	100.021
#Range=	Auto
#Laser Pol.=	No
#Raman. Pol.=	No
#Laser Pol. (°)=	-0.0007625
#Raman Pol. (°)=	89.9995
#Collection=	Microscope
#StageXY=	Marzhauser
#StageZ=	Marzhauser
#X (µm)=	-1019.1
#Y (µm)=	686.2
#Z (µm)=	584.55
#Full time(mm:ss)=	3:06
#Project=
#Sample=
#Site=
#Title=	Mb_40_y_11_2x_45s_532 nm_x100_100%_600 gr_mm
#Remark=
#Date=	19.07.2022 09:46
#Acquired=	19.07.2022 09:46:09
#Base:Fit=	10.08.2022 10:52:48
#Base:Sub=	10.08.2022 10:52:53
#Filter:Polynom=	16.08.2022 10:09:04
#AxisType[0]=Intens
#AxisUnit[0]=Cnt
#AxisType[1]=Spectr
#AxisUnit[1]=1/cm
200.423	8.19604
204.052	8.34351
207.682	9.61814
211.308	10.4984
214.935	10.964
218.558	10.2444
222.18	9.04268
225.802	7.1771
229.421	6.2399
233.039	5.9961
236.657	6.61234
240.272	6.5288
243.885	7.54549
247.497	8.04925
251.11	8.12361
254.719	8.86623
258.327	9.06301
261.933	9.46441
265.538	9.30634
269.141	10.1672
272.744	9.82078
276.344	9.4152
279.944	10.0545
283.542	10.1638
287.138	11.572
290.733	11.4106
294.327	11.0053
297.919	10.9197
301.508	11.627
305.098	10.5709
308.686	10.3245
312.273	10.3922
315.858	9.90195
319.44	10.8133
323.022	11.8198
326.604	12.5124
330.181	13.5705
333.76	14.6544
337.335	15.1359
340.91	15.3907
344.483	15.0457
348.055	14.1315
351.625	14.4281
355.195	14.53
358.762	13.9767
362.329	12.9085
365.893	11.9131
369.455	10.6108
373.017	10.188
376.578	8.83846
380.137	8.09597
383.694	8.2389
387.249	7.40604
390.806	5.88293
394.359	5.51849
397.91	5.0802
401.46	4.83724
405.009	5.42277
408.557	5.70873
412.103	5.78386
415.647	5.70756
419.191	5.80483
422.733	5.27889
426.273	5.17016
429.812	5.21243
433.35	6.14376
436.885	6.02245
440.42	6.6726
443.954	7.06429
447.486	7.04104
451.015	6.2619
454.545	6.87934
458.073	7.19216
461.598	6.94797
465.124	8.01983
468.648	7.95615
472.169	7.66173
475.69	7.57329
479.208	8.37384
482.727	8.86189
486.243	10.2658
489.759	11.4535
493.272	12.1656
496.783	11.1183
500.295	11.5313
503.804	10.5956
507.311	11.4612
510.819	12.3483
514.324	12.3673
517.827	13.4077
521.329	13.0629
524.83	12.7686
528.329	12.3589
531.829	12.1273
535.326	10.9666
538.821	10.7186
542.315	9.5585
545.808	8.75146
549.299	8.01795
552.789	6.41815
556.278	5.39453
559.763	3.64936
563.249	2.86583
566.733	3.051
570.217	2.2327
573.699	2.35255
577.177	1.94968
580.656	2.24708
584.134	1.75057
587.609	1.90541
591.084	2.42124
594.558	3.22552
598.029	3.26934
601.5	3.9147
604.968	4.90033
608.437	4.53376
611.902	5.97834
615.368	6.88424
618.831	7.92248
622.294	8.41582
625.755	8.74608
629.213	10.2483
632.673	10.7705
636.129	11.0419
639.584	12.4689
643.037	13.343
646.491	14.5855
649.942	15.807
653.392	18.2389
656.84	19.824
660.287	20.9031
663.732	21.539
667.177	23.3837
670.62	24.8422
674.061	25.6356
677.502	26.1374
680.941	27.8596
684.379	29.4438
687.815	31.0503
691.248	31.946
694.682	34.3988
698.115	37.0479
701.546	37.8982
704.974	38.2016
708.402	40.158
711.83	41.021
715.254	42.6755
718.679	43.7134
722.102	43.7668
725.522	44.8605
728.943	44.5763
732.361	46.1679
735.779	47.819
739.194	48.6283
742.608	49.5345
746.022	51.5782
749.433	52.6877
752.843	53.4619
756.254	54.8551
759.661	57.1648
763.067	58.7422
766.471	62.0906
769.877	64.6591
773.279	67.2968
776.68	70.5378
780.079	73.9104
783.478	77.7966
786.875	79.7709
790.27	82.6063
793.665	84.762
797.058	86.902
800.45	88.2032
803.84	88.5282
807.23	89.1383
810.616	89.2241
814.002	88.3528
817.388	87.9737
820.772	86.4647
824.153	85.3799
827.535	84.7274
830.915	82.0029
834.292	80.0267
837.67	77.7494
841.047	75.2831
844.42	73.127
847.794	71.4715
851.165	69.8934
854.534	67.9927
857.905	65.8325
861.272	64.72
864.639	62.5466
868.004	60.3695
871.367	59.2888
874.731	57.3708
878.092	54.8981
881.451	54.2001
884.809	53.7767
888.166	53.2597
891.522	52.7108
894.878	51.6904
898.231	51.2894
901.583	51.7274
904.934	52.6094
908.283	52.4559
911.631	52.9204
914.976	52.8718
918.322	52.3695
921.666	51.8053
925.009	52.3024
928.351	52.6064
931.692	51.9084
935.029	51.4222
938.367	50.449
941.704	48.2392
945.038	46.5375
948.372	44.8414
951.705	43.35
955.035	41.1858
958.366	40.3233
961.693	39.4928
965.021	39.1132
968.346	37.3823
971.67	35.3704
974.995	33.8245
978.316	31.3025
981.638	29.9474
984.957	27.7726
988.274	26.9275
991.59	24.0235
994.907	22.8023
998.221	21.9575
1001.53	20.3463
1004.85	20.6661
1008.16	20.5921
1011.46	20.5857
1014.77	20.015
1018.08	18.9521
1021.38	18.4229
1024.69	18.1935
1027.99	18.1876
1031.29	18.5186
1034.59	18.0102
1037.89	17.7406
1041.19	19.0597
1044.48	19.0004
1047.78	19.8617
1051.07	19.8219
1054.36	20.0357
1057.66	18.6125
1060.94	17.6101
1064.23	16.2963
1067.52	15.3156
1070.81	13.8215
1074.09	12.9529
1077.38	12.5114
1080.66	11.6898
1083.94	11.8622
1087.22	11.0472
1090.5	9.41883
1093.77	8.13542
1097.05	7.3799
1100.32	6.09546
1103.6	6.05424
1106.87	5.02748
1110.14	4.1609
1113.41	3.96224
1116.67	3.44108
1119.94	4.36361
1123.21	5.14695
1126.47	5.52032
1129.73	6.547
1133	5.56397
1136.26	4.69559
1139.52	4.29684
1142.77	3.96692
1146.03	4.31533
1149.29	4.40673
1152.54	3.22299
1155.79	3.53119
1159.04	3.27846
1162.3	4.35866
1165.55	4.02108
1168.79	4.61776
1172.04	5.27254
1175.28	5.86916
1178.53	6.22569
1181.77	5.89746
1185.01	6.09795
1188.25	5.82767
1191.49	5.79277
1194.73	6.47846
1197.97	6.86825
1201.2	6.91305
1204.44	7.54553
1207.67	8.18402
1210.9	7.49055
1214.13	7.18484
1217.36	6.90303
1220.59	6.1261
1223.82	6.12431
1227.04	5.13022
1230.26	3.80221
1233.49	3.85124
1236.71	3.4921
1239.93	3.98789
1243.15	4.34576
1246.37	4.05352
1249.58	3.67135
1252.8	3.79109
1256.01	2.66287
1259.23	1.57944
1262.44	1.64307
1265.65	1.20017
1268.86	1.65862
1272.07	1.59207
1275.27	1.53539
1278.48	1.05681
1281.68	1.92648
1284.89	1.52176
1288.09	1.39053
1291.29	1.68806
1294.49	1.02736
1297.69	1.19346
1300.88	1.74185
1304.08	2.10166
1307.27	1.84763
1310.47	3.13613
1313.66	4.47151
1316.85	5.0293
1320.04	6.61644
1323.23	6.62085
1326.41	6.44828
1329.6	6.94963
1332.78	6.69731
1335.97	6.53303
1339.15	6.9301
1342.33	8.26109
1345.51	7.85083
1348.69	8.18755
1351.87	8.39803
1355.04	8.39944
1358.22	9.13379
1361.39	8.13989
1364.57	7.42919
1367.74	7.53941
1370.91	6.54486
1374.07	6.04027
1377.24	5.56482
1380.41	4.75072
1383.57	4.56869
1386.74	4.57059
1389.9	4.68256
1393.06	4.04811
1396.22	2.69381
1399.38	2.84991
1402.54	2.03908
1405.7	1.67094
1408.85	1.50849
1412.01	1.54391
1415.16	2.29571
1418.31	4.18351
1421.46	5.12844
1424.61	5.85575
1427.76	6.63474
1430.91	8.44581
1434.05	8.60699
1437.2	9.32992
1440.34	9.12912
1443.49	9.94548
1446.63	11.235
1449.77	10.5523
1452.91	10.4077
1456.04	9.42423
1459.18	9.29856
1462.31	9.85825
1465.45	9.3751
1468.58	8.56932
1471.71	7.47131
1474.84	6.94006
1477.97	7.41861
1481.1	6.63284
1484.23	6.56369
1487.35	6.10018
1490.48	5.8341
1493.6	6.10706
1496.72	6.0793
1499.84	7.02231
1502.96	6.75589
1506.08	6.87416
1509.2	6.2237
1512.31	5.87758
1515.43	5.57614
1518.54	6.07506
1521.66	5.41348
1524.77	4.81285
1527.88	3.61226
1530.99	3.81208
1534.09	4.22039
1537.2	5.6178
1540.31	5.95009
1543.41	5.41289
1546.51	6.03776
1549.62	5.97152
1552.72	5.7171
1555.82	5.50386
1558.91	5.80062
1562.01	5.96656
1565.11	5.50313
1568.2	5.90954
1571.3	7.26022
1574.39	6.90545
1577.48	7.96051
1580.57	7.91534
1583.66	7.48187
1586.75	8.1822
1589.83	8.77217
1592.92	8.88638
1596	9.17616
1599.09	8.91172
1602.17	8.83335
1605.25	8.81004
1608.33	9.25659
1611.41	9.73028
1614.48	8.66204
1617.56	7.86207
1620.64	6.68657
1623.71	5.2044
1626.78	4.43726
1629.86	4.23182
1632.92	3.67809
1635.99	3.66522
1639.06	2.97403
1642.13	2.20254
1645.19	1.90773
1648.26	1.77193
1651.32	1.88841
1654.38	2.8694
1657.45	2.69916
1660.51	2.53646
1663.57	3.06051
1666.62	2.0532
1669.68	2.07144
1672.73	2.71813
1675.79	2.6598
1678.84	2.75762
1681.89	2.45074
1684.94	3.16439
1687.99	3.26622
1691.04	2.71995
1694.09	3.2237
1697.14	3.69275
1700.18	4.24187
1703.22	4.76919
1706.27	5.50355
1709.31	4.75423
1712.35	5.17559
1715.39	4.96021
1718.43	4.34192
1721.46	4.77165
1724.5	4.23787
1727.53	4.57721
1730.57	4.45403
1733.6	4.03126
1736.63	3.16423
1739.66	2.02784
1742.69	1.37842
1745.72	1.71121
1748.74	2.02575
1751.77	1.73343
1754.8	2.11998
1757.82	2.885
1760.84	2.94616
1763.86	3.81525
1766.88	3.88778
1769.9	5.23428
1772.92	5.91877
1775.93	6.68712
1778.95	7.15363
1781.96	7.07521
1784.98	6.60313
1787.99	6.27202
1791	6.48155
1794.01	6.49641
1797.02	6.18927
1800.03	4.89064
1803.03	4.83278
1806.04	5.32046
1809.04	4.82956
1812.04	5.4161
1815.05	5.84624
1818.05	6.6211
1821.05	6.62025
1824.05	6.69205
1827.04	7.21249
1830.04	6.97662
1833.03	6.46228
1836.03	6.2943
1839.02	5.95649
1842.01	6.03389
1845	6.28951
1847.99	5.6476
1850.98	5.19771
1853.97	4.33417
1856.95	5.23052
1859.94	4.32112
1862.92	3.81094
1865.91	4.56728
1868.89	5.46423
1871.87	4.6934
1874.85	5.80405
1877.83	7.64716
1880.8	7.16583
1882.56	7.71524
1885.54	7.84036
1888.53	7.56082
1891.52	8.08852
1894.5	8.61887
1897.49	9.15038
1900.47	9.51413
1903.45	9.08463
1906.43	9.95293
1909.41	10.3663
1912.39	9.74027
1915.37	8.7773
1918.35	8.41531
1921.32	8.13383
1924.3	7.20799
1927.27	6.46252
1930.24	6.42317
1933.21	5.84562
1936.18	6.69583
1939.15	7.7303
1942.12	7.66469
1945.09	8.44344
1948.05	8.68365
1951.02	8.21926
1953.98	7.67694
1956.94	8.38147
1959.91	9.46165
1962.87	10.1075
1965.82	10.0871
1968.78	10.1192
1971.74	10.0485
1974.7	8.8312
1977.65	9.5186
1980.6	7.79655
1983.56	6.75157
1986.51	5.72005
1989.46	3.68514
1992.41	3.67347
1995.36	1.80892
1998.3	0.951069
2001.25	0.665961
2004.2	0.945359
2007.14	1.49834
2010.08	1.3266
2013.02	2.31897
2015.97	3.16264
2018.9	4.57459
2021.84	5.59631
2024.78	5.20808
2027.72	6.51054
2030.65	7.76646
2033.59	8.76616
2036.52	8.98547
2039.45	8.69973
2042.38	9.0916
2045.31	10.3441
2048.24	10.6751
2051.17	12.1636
2054.1	12.6514
2057.02	13.2035
2059.95	13.2562
2062.87	13.2966
2065.79	13.1817
2068.71	13.0316
2071.63	13.2842
2074.55	13.1826
2077.47	12.4862
2080.39	11.5834
2083.3	12.4455
2086.22	11.6906
2089.13	11.7654
2092.05	12.3596
2094.96	11.9428
2097.87	9.91649
2100.78	11.2307
2103.69	10.6133
2106.59	9.96352
2109.5	8.42508
2112.41	8.34293
2115.31	8.6747
2118.21	8.8471
2121.12	8.7338
2124.02	8.52861
2126.92	7.33106
2129.82	6.97422
2132.71	7.01745
2135.61	8.42324
2138.51	8.18842
2141.4	8.6542
2144.29	7.83261
2147.19	7.48814
2150.08	7.47615
2152.97	7.94099
2155.86	7.47252
2158.75	7.74048
2161.64	7.38566
2164.52	8.09544
2167.41	8.26455
2170.29	8.69122
2173.17	9.76195
2176.06	9.95038
2178.94	9.28004
2181.82	9.52242
2184.7	10.4043
2187.57	9.81477
2190.45	9.48019
2193.33	9.23855
2196.2	9.1235
2199.08	10.0321
2201.95	10.4775
2204.82	11.3315
2207.69	11.878
2210.56	11.5173
2213.43	11.3474
2216.3	10.9045
2219.16	11.9305
2222.03	11.731
2224.89	11.8741
2227.75	11.1739
2230.62	10.9723
2233.48	10.8836
2236.34	11.7343
2239.2	11.7231
2242.06	12.1316
2244.91	12.5188
2247.77	12.2863
2250.62	11.6612
2253.48	11.9941
2256.33	11.5175
2259.18	10.9384
2262.03	10.8147
2264.88	11.7171
2267.73	11.6555
2270.58	11.6312
2273.43	12.5591
2276.27	12.4248
2279.12	12.3368
2281.96	11.8899
2284.8	11.67
2287.64	12.1665
2290.49	12.8041
2293.32	11.0485
2296.16	10.8771
2299	10.775
2301.84	12.0765
2304.67	12.8159
2307.51	13.3733
2310.34	13.6261
2313.17	14.8232
2316	15.6412
2318.83	15.5744
2321.66	15.4411
2324.49	16.3142
2327.32	15.945
2330.15	16.9828
2332.97	17.8882
2335.79	16.9792
2338.62	15.7459
2341.44	15.1087
2344.26	13.386
2347.08	12.8587
2349.9	10.3649
2352.72	9.77466
2355.53	8.58353
2358.35	7.39101
2361.17	5.80373
2363.98	5.19321
2366.79	4.54891
2369.6	4.04801
2372.42	4.62287
2375.22	4.58155
2378.03	4.5565
2380.84	4.80173
2383.65	5.89936
2386.45	5.10873
2389.26	6.27037
2392.06	7.12
2394.87	9.00924
2397.67	10.4411
2400.47	11.4342
2403.27	11.6538
2406.07	10.9368
2408.86	11.7812
2411.66	12.5062
2414.46	12.4992
2417.25	12.7051
2420.05	11.6779
2422.84	12.3286
2425.63	12.1303
2428.42	11.908
2431.21	11.6006
2434	11.719
2436.79	10.6135
2439.57	11.0322
2442.36	10.1781
2445.14	9.49515
2447.93	9.6456
2450.71	8.98214
2453.49	9.53713
2456.27	9.65819
2459.05	9.33617
2461.83	8.76886
2464.61	8.24141
2467.39	7.78903
2470.16	8.50722
2472.94	7.5634
2475.71	7.12847
2478.48	7.12104
2481.25	5.96753
2484.02	5.25892
2486.8	4.91446
2489.56	5.30213
2492.33	6.20333
2495.1	5.56675
2497.86	5.62549
2500.63	4.60999
2503.39	4.04254
2506.16	3.09852
2508.92	2.40569
2511.68	2.15788
2514.44	3.02481
2517.2	3.50387
2519.95	3.94037
2522.71	3.76619
2525.47	2.77191
2528.22	3.12153
2530.98	3.4348
2533.73	3.41379
2536.48	3.94879
2539.23	4.05794
2541.98	4.76394
2544.73	4.90777
2547.48	4.3838
2550.23	4.46298
2552.97	5.06128
2555.72	5.48253
2558.46	5.6461
2561.2	5.63401
2563.95	4.9724
2566.69	3.83598
2569.43	3.28054
2572.17	4.25803
2574.91	3.85542
2577.64	3.9721
2580.38	4.58885
2583.11	4.58065
2585.85	5.4439
2588.58	5.71006
2591.31	5.61753
2594.04	5.32016
2596.78	6.12985
2599.51	5.35969
2602.23	5.61754
2604.96	6.76078
2607.69	6.65251
2610.41	6.9013
2613.14	5.21709
2615.86	4.80281
2618.58	5.47084
2621.3	4.49925
2624.03	3.94527
2626.75	3.65302
2629.46	2.81265
2632.18	2.72839
2634.9	2.69514
2637.61	2.51941
2640.33	2.23949
2643.04	2.47282
2645.76	2.13873
2648.47	2.57447
2651.18	2.67045
2653.89	3.01557
2656.6	2.93267
2659.31	2.70469
2662.01	3.06073
2664.72	4.56853
2667.43	4.46574
2670.13	5.23922
2672.83	5.93179
2675.53	6.12453
2678.24	5.85237
2680.94	5.65266
2683.64	5.5867
2686.34	5.45306
2689.03	5.80457
2691.73	5.33623
2694.43	4.67459
2697.12	4.07604
2699.81	3.79481
2702.51	3.42382
2705.2	4.01461
2707.89	3.66559
2710.58	3.00258
2713.27	2.67605
2715.96	2.84085
2718.64	1.86935
2721.33	2.33129
2724.01	0.891327
2726.7	1.28794
2729.38	2.043
2732.06	1.98225
2734.75	2.28511
2737.43	1.99652
2740.11	1.91499
2742.78	1.65294
2745.46	1.92251
2748.14	2.10885
2750.81	2.10139
2753.49	2.07485
2756.16	1.8164
2758.84	1.83533
2761.51	1.1364
2764.18	1.36686
2766.85	1.44938
2769.52	1.88621
2772.19	1.42422
2774.85	1.48895
2777.52	2.12815
2780.18	1.68341
2782.85	1.42899
2785.51	1.64964
2788.17	2.12492
2790.84	2.25492
2793.5	2.61583
2796.16	2.59146
2798.81	2.67306
2801.47	2.87324
2804.13	3.39393
2806.79	3.28291
2809.44	3.32183
2812.09	3.25086
2814.75	3.59719
2817.4	3.45349
2820.05	3.18289
2822.7	3.0228
2825.35	2.55704
2828	2.37846
2830.65	3.08331
2833.29	3.20762
2835.94	3.33829
2838.58	3.23632
2841.23	3.48191
2843.87	3.23745
2846.51	3.74699
2849.15	3.94132
2851.79	5.31162
2854.43	4.71284
2857.07	4.80223
2859.71	4.96821
2862.34	4.99924
2864.98	4.95522
2867.61	6.21685
2870.25	5.95136
2872.88	5.43673
2875.51	5.73456
2878.14	5.1542
2880.77	5.47374
2883.4	5.14227
2886.03	5.25413
2888.65	5.173
2891.28	5.82116
2893.91	6.23203
2896.53	6.29509
2899.15	6.26666
2901.78	6.5536
2904.4	6.70877
2907.02	6.11892
2909.64	6.08531
2912.26	5.42744
2914.87	4.98015
2917.49	4.96232
2920.11	5.36489
2922.72	6.12991
2925.34	6.63697
2927.95	7.0427
2930.56	8.46291
2933.17	8.15931
2935.78	7.47571
2938.39	6.93436
2941	7.17913
2943.61	7.32158
2946.22	8.27335
2948.82	8.95345
2951.43	9.53351
2954.03	10.0116
2956.64	10.0756
2959.24	9.98599
2961.84	8.99128
2964.44	8.73867
2967.04	8.24231
2969.64	7.16077
2972.24	5.85131
2974.83	5.09932
2977.43	3.58777
2980.02	3.24466
2982.62	3.48649
2985.21	3.44063
2987.8	3.47119
2990.4	3.29734
2992.99	2.75781
2995.57	2.46115
2998.16	1.18873
3000.75	1.07165
3003.34	1.0939
3005.92	2.22118
3008.51	2.55116
3011.09	3.17922
3013.68	4.4632
3016.26	4.56251
3018.84	4.70761
3021.42	4.53817
3024	4.35036
3026.58	4.1606
3029.16	3.66895
3031.73	3.20093
3034.31	2.53891
3036.89	2.2809
3039.46	1.96404
3042.03	2.14965
3044.61	2.76408
3047.18	2.94276
3049.75	2.93857
3052.32	2.93309
3054.89	3.34208
3057.45	4.26722
3060.02	3.69624
3062.59	4.51288
3065.15	5.11691
3067.72	6.10619
3070.28	6.76551
3072.84	7.86644
3075.41	7.96875
3077.97	7.81833
3080.53	6.86704
3083.09	7.59526
3085.64	6.84439
3088.2	6.8323
3090.76	6.29729
3093.31	6.55507
3095.87	6.09998
3098.42	5.49412
3100.97	5.65267
3103.53	5.14173
3106.08	4.00625
3108.63	3.67175
3111.18	3.78527
3113.73	3.28093
3116.27	3.0885
3118.82	3.26261
3121.37	3.24959
3123.91	3.26866
3126.45	2.89112
3129	2.69862
3131.54	2.49123
3134.08	1.76632
3136.62	1.10819
3139.16	0.788866
3141.7	0.222113
3144.24	-0.0201765
3146.78	-0.500829
3149.31	-2.90931