File: data/Raman/poly_smoothed/Mb_40_y_29_1x_45s_532 nm_x100_100%_600 gr_mm_01.txt
#Acq. time (s)=	45
#Accumulations=	2
#Range (cm-¹)=	200...3150
#Windows=	2
#Auto scanning=	Off
#Autofocus=	Off
#Macrospot=	Off
#AutoExposure=	Off
#Spike filter=	Multiple accum.
#Delay time (s)=	0
#Binning=	1
#Readout mode=	Signal
#DeNoise=	Off
#ICS correction=	On
#Dark correction=	Off
#Inst. Process=	Off
#Detector Gain=	Best Dynamic Range
#Detector ADC=	20 kHz
#Detector temperature (°C)=	-69.85
#Instrument=	LabRAM HR Evol
#Detector=	Synapse
#Objective=	x100
#Grating=	600 gr/mm
#ND Filter=	100%
#Laser (nm)=	532
#Hole=	100.021
#Range=	Auto
#Laser Pol.=	No
#Raman. Pol.=	No
#Laser Pol. (°)=	-0.0007625
#Raman Pol. (°)=	89.9995
#Collection=	Microscope
#StageXY=	Marzhauser
#StageZ=	Marzhauser
#X (µm)=	-1100.8
#Y (µm)=	557.4
#Z (µm)=	583.95
#Full time(mm:ss)=	3:18
#Project=
#Sample=
#Site=
#Title=	Mb_40_y_29_2x_45s_532 nm_x100_100%_600 gr_mm
#Remark=
#Date=	19.07.2022 11:51
#Acquired=	19.07.2022 11:51:40
#Base:Fit=	10.08.2022 10:52:48
#Base:Sub=	10.08.2022 10:52:53
#Filter:Polynom=	16.08.2022 10:09:04
#AxisType[0]=Intens
#AxisUnit[0]=Cnt
#AxisType[1]=Spectr
#AxisUnit[1]=1/cm
200.423	39.1414
204.052	32.5174
207.682	27.4314
211.308	20.9333
214.935	17.0171
218.558	16.8282
222.18	14.0106
225.802	11.3752
229.421	8.04957
233.039	7.84745
236.657	7.62607
240.272	7.17745
243.885	6.93108
247.497	7.21081
251.11	7.40867
254.719	8.10953
258.327	8.45346
261.933	9.78192
265.538	9.99358
269.141	8.7961
272.744	8.76135
276.344	8.05172
279.944	8.12272
283.542	9.3359
287.138	9.34238
290.733	8.9753
294.327	7.49483
297.919	7.72237
301.508	9.59536
305.098	9.66009
308.686	10.7024
312.273	11.3766
315.858	10.7056
319.44	12.1321
323.022	13.1991
326.604	13.9416
330.181	13.5875
333.76	14.1288
337.335	13.5912
340.91	13.5533
344.483	14.4812
348.055	13.2997
351.625	12.2418
355.195	11.3022
358.762	11.5087
362.329	10.5645
365.893	9.80536
369.455	9.51953
373.017	9.41062
376.578	8.06095
380.137	7.00719
383.694	5.59918
387.249	4.76048
390.806	6.16995
394.359	5.56399
397.91	5.8329
401.46	5.32129
405.009	6.21992
408.557	5.7647
412.103	5.01455
415.647	5.10729
419.191	4.78405
422.733	5.57223
426.273	5.4877
429.812	5.28981
433.35	4.16038
436.885	3.68546
440.42	4.03018
443.954	2.79632
447.486	2.10794
451.015	1.9569
454.545	4.57156
458.073	3.85434
461.598	3.47542
465.124	2.42774
468.648	2.71352
472.169	4.77457
475.69	4.59305
479.208	6.60879
482.727	8.62033
486.243	10.2071
489.759	12.849
493.272	13.6734
496.783	13.0647
500.295	13.8508
503.804	15.5402
507.311	16.9367
510.819	16.8434
514.324	18.667
517.827	18.2109
521.329	17.8208
524.83	17.1695
528.329	17.355
531.829	16.105
535.326	16.2523
538.821	16.7933
542.315	15.0127
545.808	14.8855
549.299	12.6551
552.789	10.359
556.278	10.4478
559.763	9.31346
563.249	8.55674
566.733	8.96153
570.217	7.46028
573.699	7.60503
577.177	7.62876
580.656	6.12192
584.134	5.97874
587.609	5.8693
591.084	6.27873
594.558	6.29808
598.029	5.84787
601.5	7.17764
604.968	6.07521
608.437	7.84227
611.902	7.99236
615.368	7.5768
618.831	8.91235
622.294	8.61974
625.755	8.93104
629.213	8.6916
632.673	7.72702
636.129	5.7999
639.584	5.79584
643.037	6.19781
646.491	6.48098
649.942	6.94595
653.392	7.98133
656.84	9.10482
660.287	9.94235
663.732	9.32172
667.177	9.19829
670.62	9.95805
674.061	10.9816
677.502	13.5867
680.941	14.1353
684.379	18.1938
687.815	20.8655
691.248	23.2259
694.682	26.2872
698.115	28.404
701.546	29.8261
704.974	32.4341
708.402	35.4063
711.83	37.7783
715.254	39.9174
718.679	42.9586
722.102	44.6643
725.522	47.526
728.943	48.2849
732.361	49.9842
735.779	50.5082
739.194	52.1172
742.608	51.3571
746.022	51.904
749.433	53.071
752.843	54.4693
756.254	56.9939
759.661	58.5818
763.067	58.387
766.471	60.5418
769.877	61.2509
773.279	61.8904
776.68	63.4483
780.079	63.9492
783.478	64.4378
786.875	65.6694
790.27	67.1979
793.665	71.2505
797.058	73.0256
800.45	75.8404
803.84	76.092
807.23	75.3428
810.616	76.6537
814.002	77.1375
817.388	77.2303
820.772	76.494
824.153	76.9522
827.535	74.3651
830.915	75.2968
834.292	74.483
837.67	71.327
841.047	69.0458
844.42	67.5563
847.794	64.5471
851.165	61.2927
854.534	59.2937
857.905	56.6702
861.272	54.1599
864.639	51.5983
868.004	50.4861
871.367	48.9365
874.731	48.3263
878.092	47.9714
881.451	49.0236
884.809	47.829
888.166	47.1924
891.522	45.5754
894.878	44.9779
898.231	44.8362
901.583	44.1976
904.934	44.3967
908.283	44.9054
911.631	44.3543
914.976	44.5339
918.322	44.292
921.666	43.813
925.009	44.9504
928.351	44.2121
931.692	42.9543
935.029	43.7663
938.367	43.4109
941.704	43.4624
945.038	43.7447
948.372	43.48
951.705	44.8043
955.035	45.6022
958.366	47.421
961.693	49.2009
965.021	49.5802
968.346	48.4334
971.67	47.9658
974.995	45.3745
978.316	44.6563
981.638	44.3796
984.957	43.5677
988.274	42.43
991.59	39.3325
994.907	35.1001
998.221	31.0146
1001.53	26.0712
1004.85	21.6922
1008.16	24.0164
1011.46	30.4481
1014.77	45.4133
1018.08	62.5458
1021.38	79.4154
1024.69	97.7899
1027.99	112.299
1031.29	125.229
1034.59	138.772
1037.89	147.05
1041.19	153.165
1044.48	156.545
1047.78	157.592
1051.07	153.715
1054.36	148.208
1057.66	138.141
1060.94	129.379
1064.23	116.628
1067.52	100.566
1070.81	82.8228
1074.09	63.4231
1077.38	45.1584
1080.66	27.7748
1083.94	15.9059
1087.22	11.0892
1090.5	12.184
1093.77	15.2505
1097.05	19.7088
1100.32	20.9267
1103.6	22.6977
1106.87	22.4318
1110.14	22.796
1113.41	23.5522
1116.67	25.7187
1119.94	25.9117
1123.21	25.3589
1126.47	24.4564
1129.73	23.2322
1133	21.3633
1136.26	19.6761
1139.52	17.8061
1142.77	16.4264
1146.03	14.186
1149.29	13.46
1152.54	11.9596
1155.79	11.2771
1159.04	8.72563
1162.3	7.19771
1165.55	6.55167
1168.79	5.7306
1172.04	6.35619
1175.28	6.27232
1178.53	6.50827
1181.77	7.71247
1185.01	9.18688
1188.25	9.97909
1191.49	12.6058
1194.73	13.6756
1197.97	14.2377
1201.2	15.2034
1204.44	17.9179
1207.67	18.3006
1210.9	20.1903
1214.13	22.4892
1217.36	25.3317
1220.59	28.4416
1223.82	32.2022
1227.04	37.3728
1230.26	41.0138
1233.49	44.187
1236.71	46.1246
1239.93	48.9559
1243.15	51.9884
1246.37	54.0773
1249.58	56.4985
1252.8	57.652
1256.01	58.2138
1259.23	60.1539
1262.44	60.6031
1265.65	61.5097
1268.86	62.1935
1272.07	61.3712
1275.27	61.686
1278.48	63.0242
1281.68	65.6324
1284.89	65.7379
1288.09	64.8741
1291.29	65.0125
1294.49	65.2477
1297.69	66.4903
1300.88	67.7234
1304.08	67.6833
1307.27	69.9641
1310.47	70.9541
1313.66	72.3728
1316.85	72.8682
1320.04	74.6507
1323.23	73.5659
1326.41	73.2062
1329.6	74.284
1332.78	73.4364
1335.97	72.6784
1339.15	70.603
1342.33	69.4033
1345.51	69.0197
1348.69	67.1749
1351.87	64.8719
1355.04	63.6776
1358.22	61.4028
1361.39	57.2984
1364.57	54.0984
1367.74	50.5014
1370.91	47.7389
1374.07	45.0647
1377.24	43.6862
1380.41	42.3584
1383.57	41.9212
1386.74	42.3611
1389.9	41.2567
1393.06	41.7117
1396.22	41.9022
1399.38	42.9753
1402.54	44.4934
1405.7	47.6824
1408.85	49.5517
1412.01	51.8508
1415.16	55.4524
1418.31	58.4175
1421.46	64.123
1424.61	67.951
1427.76	71.534
1430.91	76.2041
1434.05	80.6513
1437.2	84.2419
1440.34	86.067
1443.49	86.9905
1446.63	86.6465
1449.77	85.6956
1452.91	84.058
1456.04	83.5035
1459.18	81.0586
1462.31	78.9117
1465.45	76.707
1468.58	72.4833
1471.71	69.6743
1474.84	65.6282
1477.97	62.2302
1481.1	59.3527
1484.23	56.5734
1487.35	54.0633
1490.48	51.7837
1493.6	50.0076
1496.72	47.8237
1499.84	46.8226
1502.96	44.7559
1506.08	42.4496
1509.2	41.9332
1512.31	41.5276
1515.43	40.2596
1518.54	38.8254
1521.66	37.6435
1524.77	36.0064
1527.88	36.1704
1530.99	36.4365
1534.09	37.5489
1537.2	37.4925
1540.31	37.5316
1543.41	38.0435
1546.51	37.9579
1549.62	38.7897
1552.72	38.945
1555.82	38.5187
1558.91	39.7758
1562.01	41.2783
1565.11	41.7671
1568.2	43.24
1571.3	43.6754
1574.39	46.4716
1577.48	47.9178
1580.57	49.8753
1583.66	50.9117
1586.75	52.4556
1589.83	53.8492
1592.92	55.2363
1596	56.9524
1599.09	57.497
1602.17	57.5801
1605.25	57.4567
1608.33	57.6933
1611.41	57.2987
1614.48	56.831
1617.56	58.0739
1620.64	58.8756
1623.71	59.8118
1626.78	59.6699
1629.86	60.6947
1632.92	61.3322
1635.99	65.6709
1639.06	66.1752
1642.13	68.4142
1645.19	70.549
1648.26	71.6689
1651.32	73.5705
1654.38	73.1884
1657.45	72.5955
1660.51	71.5263
1663.57	70.4967
1666.62	70.2126
1669.68	67.8545
1672.73	65.1175
1675.79	61.7348
1678.84	58.5793
1681.89	56.3095
1684.94	52.912
1687.99	49.3826
1691.04	45.9723
1694.09	43.1033
1697.14	39.0013
1700.18	36.8792
1703.22	33.4615
1706.27	31.916
1709.31	29.2353
1712.35	25.952
1715.39	22.8688
1718.43	20.2598
1721.46	18.526
1724.5	16.1532
1727.53	14.6534
1730.57	14.1115
1733.6	12.0252
1736.63	9.87138
1739.66	8.53697
1742.69	8.50232
1745.72	7.58521
1748.74	7.01565
1751.77	7.41843
1754.8	7.29436
1757.82	8.21032
1760.84	7.96367
1763.86	8.75116
1766.88	8.6385
1769.9	8.60799
1772.92	9.62063
1775.93	10.345
1778.95	9.85233
1781.96	9.09214
1784.98	7.89012
1787.99	8.31886
1791	8.85209
1794.01	9.50597
1797.02	9.04227
1800.03	8.95163
1803.03	8.08567
1806.04	6.9514
1809.04	5.68992
1812.04	4.54225
1815.05	5.09902
1818.05	5.02329
1821.05	4.59543
1824.05	3.85392
1827.04	3.9224
1830.04	3.9153
1833.03	3.69056
1836.03	3.51947
1839.02	4.01675
1842.01	4.36005
1845	4.62139
1847.99	4.5059
1850.98	5.24134
1853.97	5.76989
1856.95	6.00905
1859.94	5.43764
1862.92	5.97895
1865.91	6.49703
1868.89	6.2141
1871.87	6.38518
1874.85	5.97934
1877.83	5.38254
1880.8	5.29805
1882.56	5.44867
1885.54	5.16262
1888.53	5.80767
1891.52	4.55212
1894.5	4.38381
1897.49	4.08215
1900.47	4.27898
1903.45	5.05402
1906.43	5.61981
1909.41	6.15052
1912.39	6.69525
1915.37	7.12746
1918.35	7.62921
1921.32	8.35843
1924.3	9.19068
1927.27	8.81886
1930.24	7.93632
1933.21	8.13758
1936.18	8.03588
1939.15	6.7978
1942.12	6.36895
1945.09	5.91029
1948.05	5.34023
1951.02	3.86507
1953.98	3.2428
1956.94	2.03702
1959.91	0.846871
1962.87	0.586459
1965.82	0.147856
1968.78	1.07372
1971.74	1.16721
1974.7	1.69507
1977.65	1.31155
1980.6	1.72304
1983.56	2.16086
1986.51	3.36708
1989.46	4.79995
1992.41	6.5277
1995.36	8.09732
1998.3	8.50096
2001.25	10.157
2004.2	10.7793
2007.14	10.39
2010.08	11.5366
2013.02	12.2197
2015.97	12.4876
2018.9	11.6791
2021.84	11.4009
2024.78	11.255
2027.72	11.851
2030.65	11.8698
2033.59	12.3305
2036.52	12.6709
2039.45	12.4406
2042.38	11.7082
2045.31	11.0049
2048.24	10.9645
2051.17	11.1609
2054.1	12.089
2057.02	12.6963
2059.95	13.032
2062.87	14.8502
2065.79	15.3746
2068.71	16.3709
2071.63	17.6414
2074.55	18.9812
2077.47	19.397
2080.39	20.5978
2083.3	22.255
2086.22	23.6968
2089.13	25.1438
2092.05	26.8148
2094.96	29.4561
2097.87	31.4103
2100.78	33.0849
2103.69	34.3015
2106.59	35.5496
2109.5	36.1267
2112.41	37.3609
2115.31	39.1553
2118.21	41.9449
2121.12	44.288
2124.02	47.3285
2126.92	49.7806
2129.82	53.3279
2132.71	56.7646
2135.61	60.9832
2138.51	64.5284
2141.4	68.4956
2144.29	72.5965
2147.19	75.9543
2150.08	79.6071
2152.97	83.5713
2155.86	86.68
2158.75	89.428
2161.64	91.7622
2164.52	93.0327
2167.41	94.7388
2170.29	94.3943
2173.17	94.7514
2176.06	93.5154
2178.94	91.484
2181.82	90.0978
2184.7	87.9054
2187.57	85.9651
2190.45	83.2405
2193.33	79.8784
2196.2	77.4743
2199.08	74.3102
2201.95	72.7314
2204.82	69.2555
2207.69	66.3031
2210.56	62.7878
2213.43	60.112
2216.3	58.2146
2219.16	55.2664
2222.03	52.3596
2224.89	49.5516
2227.75	47.1568
2230.62	45.2229
2233.48	42.5297
2236.34	40.1371
2239.2	37.9433
2242.06	36.3651
2244.91	34.1982
2247.77	32.8696
2250.62	31.3283
2253.48	29.9012
2256.33	27.8804
2259.18	27.1245
2262.03	25.5633
2264.88	24.6339
2267.73	23.2109
2270.58	21.9278
2273.43	21.1305
2276.27	20.1816
2279.12	20.0089
2281.96	18.4878
2284.8	18.3436
2287.64	17.0036
2290.49	15.7416
2293.32	14.0075
2296.16	13.8091
2299	13.9509
2301.84	13.9396
2304.67	14.2476
2307.51	14.3193
2310.34	15.3165
2313.17	15.3133
2316	15.265
2318.83	15.5758
2321.66	14.2404
2324.49	13.986
2327.32	12.7366
2330.15	12.1971
2332.97	11.2613
2335.79	10.6024
2338.62	10.1034
2341.44	10.3931
2344.26	9.01637
2347.08	7.75738
2349.9	5.89337
2352.72	3.80644
2355.53	3.06112
2358.35	1.76292
2361.17	0.301442
2363.98	-0.0260027
2366.79	0.849197
2369.6	1.58936
2372.42	1.35548
2375.22	1.52323
2378.03	1.76895
2380.84	2.63321
2383.65	2.50794
2386.45	3.28769
2389.26	3.88214
2392.06	3.97027
2394.87	4.00697
2397.67	5.51123
2400.47	6.74917
2403.27	7.24674
2406.07	7.3618
2408.86	7.87516
2411.66	7.7115
2414.46	7.2812
2417.25	6.9517
2420.05	6.70027
2422.84	6.41242
2425.63	5.7205
2428.42	4.84417
2431.21	4.75078
2434	4.93776
2436.79	4.63182
2439.57	4.32488
2442.36	3.48966
2445.14	3.37763
2447.93	3.24244
2450.71	3.30152
2453.49	3.19998
2456.27	3.09399
2459.05	3.01525
2461.83	3.717
2464.61	4.70465
2467.39	5.38629
2470.16	5.58396
2472.94	4.74154
2475.71	4.77334
2478.48	4.97416
2481.25	4.84196
2484.02	4.72107
2486.8	4.83458
2489.56	4.29457
2492.33	4.72324
2495.1	4.80856
2497.86	4.91821
2500.63	4.12887
2503.39	3.21677
2506.16	2.58791
2508.92	2.00989
2511.68	1.80165
2514.44	1.81574
2517.2	1.95482
2519.95	2.78436
2522.71	3.12451
2525.47	3.80451
2528.22	4.46225
2530.98	4.69105
2533.73	4.5424
2536.48	4.27705
2539.23	4.30511
2541.98	3.85579
2544.73	4.09064
2547.48	4.71293
2550.23	5.3458
2552.97	6.96936
2555.72	7.63928
2558.46	8.58291
2561.2	8.90706
2563.95	8.17962
2566.69	7.51289
2569.43	6.87206
2572.17	6.66883
2574.91	6.71022
2577.64	6.86073
2580.38	7.69099
2583.11	7.39501
2585.85	7.78874
2588.58	7.61626
2591.31	6.56704
2594.04	5.99251
2596.78	4.98675
2599.51	4.0214
2602.23	2.40797
2604.96	1.74345
2607.69	1.61568
2610.41	0.861616
2613.14	1.66755
2615.86	1.31361
2618.58	1.2902
2621.3	0.309186
2624.03	-0.0829193
2626.75	0.0819557
2629.46	0.153285
2632.18	0.458817
2634.9	1.037
2637.61	1.86241
2640.33	2.04323
2643.04	2.6916
2645.76	3.33083
2648.47	3.87042
2651.18	4.4407
2653.89	4.09457
2656.6	3.79385
2659.31	3.85566
2662.01	3.83126
2664.72	4.32288
2667.43	3.96715
2670.13	3.65314
2672.83	3.96412
2675.53	2.99307
2678.24	1.43307
2680.94	1.34138
2683.64	0.823651
2686.34	0.392674
2689.03	0.796427
2691.73	1.42905
2694.43	2.0055
2697.12	1.39412
2699.81	2.19914
2702.51	2.64207
2705.2	2.44505
2707.89	2.12539
2710.58	2.54253
2713.27	2.16864
2715.96	1.58901
2718.64	1.20255
2721.33	1.72526
2724.01	2.88304
2726.7	3.2501
2729.38	3.25292
2732.06	4.29877
2734.75	3.95142
2737.43	3.11596
2740.11	2.62284
2742.78	2.98061
2745.46	3.64526
2748.14	4.23678
2750.81	4.74017
2753.49	4.78658
2756.16	6.00818
2758.84	5.74924
2761.51	6.42637
2764.18	6.28067
2766.85	6.22314
2769.52	6.16218
2772.19	5.41601
2774.85	5.13303
2777.52	4.91636
2780.18	3.67957
2782.85	3.44913
2785.51	3.33023
2788.17	2.67475
2790.84	2.46058
2793.5	1.63406
2796.16	0.833785
2798.81	0.501668
2801.47	0.223286
2804.13	0.155173
2806.79	0.247755
2809.44	0.0879498
2812.09	-0.398443
2814.75	-0.506077
2817.4	1.24333
2820.05	2.81543
2822.7	5.39593
2825.35	7.23625
2828	10.8853
2830.65	13.9233
2833.29	18.9339
2835.94	22.9702
2838.58	26.4343
2841.23	31.2987
2843.87	34.8125
2846.51	40.0255
2849.15	46.2002
2851.79	51.8086
2854.43	57.9973
2857.07	63.968
2859.71	70.4974
2862.34	77.064
2864.98	81.8084
2867.61	86.9537
2870.25	90.8549
2872.88	94.7683
2875.51	98.8714
2878.14	102.315
2880.77	105.816
2883.4	109.524
2886.03	113.657
2888.65	118.341
2891.28	122.311
2893.91	127.249
2896.53	130.85
2899.15	135.154
2901.78	140.757
2904.4	146.156
2907.02	152.925
2909.64	161.51
2912.26	171.15
2914.87	180.611
2917.49	188.818
2920.11	198.536
2922.72	206.394
2925.34	213.16
2927.95	218.607
2930.56	222.065
2933.17	224.558
2935.78	225.071
2938.39	224.992
2941	221.727
2943.61	218.048
2946.22	212.2
2948.82	206.516
2951.43	199.011
2954.03	188.987
2956.64	177.931
2959.24	168.072
2961.84	157.944
2964.44	148.109
2967.04	137.785
2969.64	127.875
2972.24	119.31
2974.83	111.304
2977.43	103.549
2980.02	95.043
2982.62	87.4351
2985.21	80.8317
2987.8	74.2056
2990.4	67.6021
2992.99	61.6835
2995.57	54.9924
2998.16	49.9577
3000.75	45.9734
3003.34	41.3404
3005.92	36.8946
3008.51	33.3854
3011.09	28.7767
3013.68	24.9295
3016.26	21.1053
3018.84	18.2547
3021.42	15.3365
3024	12.9272
3026.58	10.1698
3029.16	8.88884
3031.73	7.20717
3034.31	5.48446
3036.89	4.83883
3039.46	4.97402
3042.03	5.28289
3044.61	5.25866
3047.18	5.98731
3049.75	6.03407
3052.32	5.61158
3054.89	5.72609
3057.45	6.24177
3060.02	7.08131
3062.59	8.19983
3065.15	8.35805
3067.72	8.31975
3070.28	8.43252
3072.84	8.14912
3075.41	7.26073
3077.97	6.66692
3080.53	5.88545
3083.09	5.07625
3085.64	3.53503
3088.2	2.92076
3090.76	2.5758
3093.31	1.667
3095.87	0.344126
3098.42	-0.178981
3100.97	1.09525
3103.53	0.681423
3106.08	0.291065
3108.63	0.0287304
3111.18	0.348072
3113.73	0.0415749
3116.27	0.509669
3118.82	1.72784
3121.37	2.48889
3123.91	3.15534
3126.45	4.0312
3129	4.63652
3131.54	5.6026
3134.08	6.69804
3136.62	7.11779
3139.16	7.3082
3141.7	7.76584
3144.24	7.88246
3146.78	7.55089
3149.31	8.0078