File: data/Raman/poly_smoothed/Mb_40_y_38_1x_45s_532 nm_x100_100%_600 gr_mm_01.txt
#Acq. time (s)=	45
#Accumulations=	2
#Range (cm-¹)=	200...3150
#Windows=	2
#Auto scanning=	Off
#Autofocus=	Off
#Macrospot=	Off
#AutoExposure=	Off
#Spike filter=	Multiple accum.
#Delay time (s)=	0
#Binning=	1
#Readout mode=	Signal
#DeNoise=	Off
#ICS correction=	On
#Dark correction=	Off
#Inst. Process=	Off
#Detector Gain=	Best Dynamic Range
#Detector ADC=	20 kHz
#Detector temperature (°C)=	-69.85
#Instrument=	LabRAM HR Evol
#Detector=	Synapse
#Objective=	x100
#Grating=	600 gr/mm
#ND Filter=	100%
#Laser (nm)=	532
#Hole=	100.021
#Range=	Auto
#Laser Pol.=	No
#Raman. Pol.=	No
#Laser Pol. (°)=	-0.0007625
#Raman Pol. (°)=	89.9995
#Collection=	Microscope
#StageXY=	Marzhauser
#StageZ=	Marzhauser
#X (µm)=	-1081.3
#Y (µm)=	597.2
#Z (µm)=	584.85
#Full time(mm:ss)=	3:18
#Project=
#Sample=
#Site=
#Title=	Mb_40_y_38_2x_45s_532 nm_x100_100%_600 gr_mm
#Remark=
#Date=	19.07.2022 12:30
#Acquired=	19.07.2022 12:30:22
#Base:Fit=	10.08.2022 10:52:48
#Base:Sub=	10.08.2022 10:52:53
#Filter:Polynom=	16.08.2022 10:09:04
#AxisType[0]=Intens
#AxisUnit[0]=Cnt
#AxisType[1]=Spectr
#AxisUnit[1]=1/cm
200.423	36.7083
204.052	36.3456
207.682	35.5579
211.308	33.4145
214.935	30.5147
218.558	27.0228
222.18	23.9678
225.802	22.87
229.421	20.4882
233.039	20.3982
236.657	19.5367
240.272	17.0912
243.885	15.2616
247.497	12.0975
251.11	11.0628
254.719	8.06938
258.327	7.21945
261.933	7.67361
265.538	8.36538
269.141	7.01214
272.744	7.4104
276.344	5.48354
279.944	5.16298
283.542	3.91643
287.138	3.6626
290.733	4.96775
294.327	4.72578
297.919	6.43482
301.508	7.3805
305.098	7.2619
308.686	9.27808
312.273	10.4152
315.858	11.8773
319.44	13.1179
323.022	12.6427
326.604	13.1316
330.181	13.1809
333.76	13.4879
337.335	15.0668
340.91	14.676
344.483	14.2966
348.055	15.1002
351.625	12.6294
355.195	10.0681
358.762	9.66263
362.329	6.59724
365.893	3.97021
369.455	4.23758
373.017	5.24404
376.578	5.09115
380.137	4.60785
383.694	4.54704
387.249	6.08967
390.806	7.39362
394.359	8.64998
397.91	11.2016
401.46	12.8946
405.009	17.132
408.557	15.4406
412.103	17.1309
415.647	19.3552
419.191	19.7654
422.733	21.9278
426.273	23.0808
429.812	25.962
433.35	25.8722
436.885	25.1651
440.42	24.1021
443.954	24.4806
447.486	23.2745
451.015	22.3283
454.545	21.2836
458.073	20.5429
461.598	20.5036
465.124	20.1796
468.648	18.3752
472.169	16.3083
475.69	17.7668
479.208	17.2728
482.727	16.2719
486.243	16.2797
489.759	12.3294
493.272	10.1813
496.783	10.7356
500.295	11.4584
503.804	12.5305
507.311	13.4747
510.819	14.4842
514.324	15.3197
517.827	14.8246
521.329	14.7581
524.83	15.1088
528.329	13.0279
531.829	13.1038
535.326	11.637
538.821	10.4966
542.315	9.70544
545.808	9.27968
549.299	8.64195
552.789	7.81607
556.278	5.58081
559.763	4.36438
563.249	4.56085
566.733	3.97674
570.217	3.31035
573.699	2.88074
577.177	3.68978
580.656	4.67956
584.134	3.71492
587.609	3.46577
591.084	3.33231
594.558	2.38939
598.029	0.955644
601.5	1.92115
604.968	2.45204
608.437	3.82235
611.902	2.53377
615.368	2.45742
618.831	0.309923
622.294	0.885799
625.755	2.56995
629.213	4.45327
632.673	6.66793
636.129	7.67089
639.584	10.0812
643.037	11.1832
646.491	13.5408
649.942	12.6247
653.392	14.4143
656.84	12.8877
660.287	12.9188
663.732	13.0399
667.177	13.2143
670.62	13.7909
674.061	13.0287
677.502	15.3121
680.941	16.7399
684.379	18.1542
687.815	21.7484
691.248	22.5483
694.682	24.0297
698.115	23.1811
701.546	27.6717
704.974	29.3548
708.402	33.3144
711.83	37.1347
715.254	38.5214
718.679	38.0472
722.102	37.3794
725.522	36.6983
728.943	35.4859
732.361	34.5971
735.779	35.6756
739.194	35.5825
742.608	35.4354
746.022	35.7072
749.433	35.9623
752.843	36.3931
756.254	37.5642
759.661	38.8811
763.067	40.1881
766.471	41.8567
769.877	44.9452
773.279	44.6609
776.68	44.8493
780.079	47.2073
783.478	50.1388
786.875	53.0651
790.27	53.3436
793.665	55.4831
797.058	56.1593
800.45	56.5211
803.84	57.3477
807.23	57.2966
810.616	56.2053
814.002	54.4247
817.388	53.1027
820.772	51.4263
824.153	51.3614
827.535	49.619
830.915	48.2407
834.292	43.9582
837.67	40.4384
841.047	35.4134
844.42	30.7644
847.794	28.5141
851.165	25.8548
854.534	24.1326
857.905	22.246
861.272	19.1916
864.639	18.8185
868.004	18.7903
871.367	17.6725
874.731	18.4147
878.092	21.7331
881.451	24.1296
884.809	25.916
888.166	23.406
891.522	22.9661
894.878	22.1605
898.231	21.8085
901.583	20.9738
904.934	21.3765
908.283	18.3201
911.631	16.2049
914.976	14.5894
918.322	12.1056
921.666	10.6729
925.009	10.6473
928.351	8.78523
931.692	7.35579
935.029	7.25412
938.367	6.44536
941.704	5.02953
945.038	4.46337
948.372	6.1918
951.705	5.19659
955.035	6.86831
958.366	8.33389
961.693	6.54607
965.021	7.11186
968.346	6.21589
971.67	6.45707
974.995	5.50531
978.316	6.94444
981.638	6.07206
984.957	4.83246
988.274	4.30132
991.59	3.39608
994.907	2.55443
998.221	-1.51934
1001.53	-3.97838
1004.85	-4.91152
1008.16	2.07447
1011.46	19.6852
1014.77	47.0838
1018.08	79.9784
1021.38	109.397
1024.69	139.959
1027.99	168.29
1031.29	193.857
1034.59	213.772
1037.89	228.724
1041.19	239.094
1044.48	246.32
1047.78	251.596
1051.07	249.628
1054.36	242.974
1057.66	231.586
1060.94	215.461
1064.23	192.422
1067.52	169.517
1070.81	140.171
1074.09	111.145
1077.38	82.9722
1080.66	59.5554
1083.94	44.4229
1087.22	35.5399
1090.5	41.8846
1093.77	53.0341
1097.05	62.2218
1100.32	68.9741
1103.6	75.6231
1106.87	84.1625
1110.14	90.6516
1113.41	96.3788
1116.67	101.29
1119.94	109.924
1123.21	115.063
1126.47	120.966
1129.73	127.498
1133	131.029
1136.26	133.266
1139.52	137.12
1142.77	139.572
1146.03	141.933
1149.29	144.166
1152.54	143.662
1155.79	147.399
1159.04	150.207
1162.3	154.558
1165.55	159.334
1168.79	164.974
1172.04	171.044
1175.28	175.65
1178.53	178.286
1181.77	182.487
1185.01	188.752
1188.25	197.441
1191.49	205.19
1194.73	214.931
1197.97	219.663
1201.2	227.091
1204.44	233.334
1207.67	242.787
1210.9	249.732
1214.13	258.949
1217.36	269.739
1220.59	279.559
1223.82	290.119
1227.04	302.158
1230.26	314.069
1233.49	326.431
1236.71	340.492
1239.93	353.02
1243.15	366.92
1246.37	379.936
1249.58	390.707
1252.8	401.424
1256.01	416.809
1259.23	435.299
1262.44	451.945
1265.65	470.305
1268.86	486.465
1272.07	501.375
1275.27	519.62
1278.48	536.623
1281.68	554.544
1284.89	569.83
1288.09	585.486
1291.29	601.685
1294.49	618.807
1297.69	633.747
1300.88	649.449
1304.08	663.14
1307.27	674.565
1310.47	686.13
1313.66	697.298
1316.85	707.978
1320.04	716.152
1323.23	723.848
1326.41	725.999
1329.6	731.125
1332.78	736.201
1335.97	740.991
1339.15	742.193
1342.33	741.596
1345.51	740.04
1348.69	737.518
1351.87	734.015
1355.04	730.372
1358.22	722.734
1361.39	716.404
1364.57	706.383
1367.74	700.078
1370.91	692.124
1374.07	682.813
1377.24	672.387
1380.41	664.118
1383.57	653.352
1386.74	642.834
1389.9	629.863
1393.06	619.949
1396.22	607.205
1399.38	597.108
1402.54	588.033
1405.7	578.735
1408.85	570.971
1412.01	563.17
1415.16	555.892
1418.31	549.539
1421.46	544.481
1424.61	539.2
1427.76	536.364
1430.91	532.952
1434.05	530.459
1437.2	526.384
1440.34	522.9
1443.49	517.935
1446.63	512.468
1449.77	507.847
1452.91	498.981
1456.04	491.837
1459.18	483.815
1462.31	473.212
1465.45	463.443
1468.58	454.97
1471.71	447.62
1474.84	439.879
1477.97	433.487
1481.1	428.454
1484.23	422.428
1487.35	416.033
1490.48	410.777
1493.6	407.762
1496.72	407.237
1499.84	406.424
1502.96	404.816
1506.08	408.218
1509.2	406.437
1512.31	406.635
1515.43	406.956
1518.54	409.685
1521.66	414.161
1524.77	422.636
1527.88	429.637
1530.99	435.943
1534.09	446.848
1537.2	459.794
1540.31	471.97
1543.41	488.832
1546.51	505.79
1549.62	524.334
1552.72	541.638
1555.82	561.238
1558.91	581.056
1562.01	602.85
1565.11	624.482
1568.2	647.336
1571.3	669.265
1574.39	692.166
1577.48	711.132
1580.57	727.137
1583.66	739.105
1586.75	748.87
1589.83	755.909
1592.92	755.806
1596	753.864
1599.09	745.451
1602.17	732.582
1605.25	713.436
1608.33	689.747
1611.41	663.397
1614.48	634.646
1617.56	600.646
1620.64	564.84
1623.71	531.295
1626.78	496.329
1629.86	461.023
1632.92	429.495
1635.99	400.131
1639.06	372.75
1642.13	347.604
1645.19	324.194
1648.26	303.293
1651.32	285.2
1654.38	265.969
1657.45	249.227
1660.51	233.608
1663.57	219.579
1666.62	202.649
1669.68	186.087
1672.73	170.896
1675.79	156.113
1678.84	143.352
1681.89	126.453
1684.94	112.471
1687.99	98.253
1691.04	84.2942
1694.09	72.9817
1697.14	62.4262
1700.18	52.0165
1703.22	43.4436
1706.27	36.008
1709.31	29.3381
1712.35	23.6583
1715.39	19.5466
1718.43	16.6612
1721.46	12.4448
1724.5	10.1589
1727.53	7.16315
1730.57	4.31349
1733.6	2.24461
1736.63	0.996975
1739.66	-2.0435
1742.69	-2.71069
1745.72	-3.19821
1748.74	-1.90377
1751.77	-2.04896
1754.8	-1.80532
1757.82	-2.5095
1760.84	-1.70392
1763.86	-0.456526
1766.88	0.111253
1769.9	0.0832744
1772.92	0.168116
1775.93	0.466218
1778.95	0.574668
1781.96	0.981191
1784.98	1.59649
1787.99	2.81704
1791	3.85194
1794.01	4.95939
1797.02	5.55524
1800.03	5.68491
1803.03	4.63242
1806.04	5.24181
1809.04	6.7399
1812.04	6.8488
1815.05	6.39968
1818.05	7.80828
1821.05	7.40633
1824.05	7.14975
1827.04	7.41667
1830.04	9.59224
1833.03	11.0668
1836.03	12.4209
1839.02	13.1998
1842.01	11.8617
1845	11.1891
1847.99	10.3487
1850.98	11.0666
1853.97	12.2986
1856.95	10.0787
1859.94	11.2058
1862.92	11.3396
1865.91	11.4506
1868.89	13.6971
1871.87	12.4869
1874.85	9.36222
1877.83	10.6064
1880.8	12.0847
1882.56	11.4162
1885.54	10.6066
1888.53	8.30411
1891.52	9.98117
1894.5	8.67549
1897.49	8.05859
1900.47	10.5266
1903.45	8.17239
1906.43	5.23294
1909.41	5.45853
1912.39	5.23904
1915.37	4.68052
1918.35	4.61772
1921.32	6.66383
1924.3	8.21379
1927.27	5.97339
1930.24	7.13498
1933.21	10.0592
1936.18	10.6739
1939.15	11.5332
1942.12	12.1053
1945.09	9.42174
1948.05	10.7133
1951.02	10.882
1953.98	11.1978
1956.94	8.10191
1959.91	11.0035
1962.87	10.8622
1965.82	12.4074
1968.78	11.9954
1971.74	11.6614
1974.7	11.5493
1977.65	12.9224
1980.6	16.3912
1983.56	19.5211
1986.51	20.9461
1989.46	23.4753
1992.41	23.8232
1995.36	28.1942
1998.3	29.8689
2001.25	30.239
2004.2	34.6374
2007.14	35.2764
2010.08	35.5296
2013.02	34.5863
2015.97	31.8886
2018.9	31.5028
2021.84	32.2874
2024.78	33.592
2027.72	35.845
2030.65	36.9983
2033.59	36.8139
2036.52	36.6722
2039.45	39.3052
2042.38	39.4955
2045.31	41.2736
2048.24	43.1954
2051.17	46.2591
2054.1	44.0737
2057.02	44.1374
2059.95	42.8373
2062.87	43.2554
2065.79	44.7035
2068.71	46.2962
2071.63	46.0113
2074.55	48.1603
2077.47	47.4532
2080.39	45.0084
2083.3	47.0344
2086.22	49.2399
2089.13	51.0588
2092.05	52.3462
2094.96	53.2424
2097.87	56.0075
2100.78	59.3372
2103.69	59.3571
2106.59	63.6284
2109.5	65.4695
2112.41	68.1821
2115.31	70.0997
2118.21	73.4793
2121.12	74.5713
2124.02	76.519
2126.92	77.7929
2129.82	80.6892
2132.71	85.3914
2135.61	91.2672
2138.51	94.6056
2141.4	99.2173
2144.29	106.236
2147.19	110.861
2150.08	119.31
2152.97	128.095
2155.86	131.116
2158.75	135.855
2161.64	137.743
2164.52	142.571
2167.41	148.322
2170.29	153.867
2173.17	155.555
2176.06	154.81
2178.94	153.991
2181.82	149.832
2184.7	147.359
2187.57	145.155
2190.45	140.782
2193.33	136.688
2196.2	133.708
2199.08	131.487
2201.95	130.965
2204.82	126.036
2207.69	124.166
2210.56	120.678
2213.43	119.835
2216.3	116.081
2219.16	114.467
2222.03	112.511
2224.89	108.414
2227.75	107.17
2230.62	107.199
2233.48	104.633
2236.34	103.922
2239.2	99.6883
2242.06	93.6227
2244.91	90.2312
2247.77	83.2319
2250.62	79.3468
2253.48	73.2207
2256.33	71.9238
2259.18	70.7401
2262.03	67.4071
2264.88	66.4277
2267.73	65.8132
2270.58	62.522
2273.43	60.5067
2276.27	59.3653
2279.12	55.8379
2281.96	54.2278
2284.8	51.4975
2287.64	50.9199
2290.49	52.19
2293.32	50.5601
2296.16	50.0508
2299	49.0232
2301.84	49.5569
2304.67	50.0501
2307.51	50.4332
2310.34	48.8453
2313.17	47.5425
2316	46.6639
2318.83	44.6374
2321.66	44.3139
2324.49	44.8189
2327.32	48.2444
2330.15	46.5929
2332.97	43.6974
2335.79	42.5194
2338.62	39.3546
2341.44	38.0482
2344.26	35.3094
2347.08	29.9433
2349.9	24.7183
2352.72	23.8286
2355.53	20.6715
2358.35	16.8683
2361.17	11.9419
2363.98	9.52007
2366.79	9.28596
2369.6	8.0782
2372.42	7.28823
2375.22	7.32907
2378.03	7.66378
2380.84	6.42702
2383.65	7.89987
2386.45	9.01364
2389.26	9.90584
2392.06	12.081
2394.87	14.2516
2397.67	17.6439
2400.47	18.0472
2403.27	19.7041
2406.07	20.6546
2408.86	22.0413
2411.66	23.0345
2414.46	22.4272
2417.25	24.908
2420.05	23.7258
2422.84	23.0859
2425.63	20.5931
2428.42	19.2874
2431.21	17.4756
2434	18.6251
2436.79	18.6164
2439.57	15.891
2442.36	16.8604
2445.14	16.8364
2447.93	16.4611
2450.71	15.4104
2453.49	14.8082
2456.27	14.8693
2459.05	13.3738
2461.83	13.5191
2464.61	13.6213
2467.39	11.1052
2470.16	7.52438
2472.94	9.13012
2475.71	8.41503
2478.48	7.01208
2481.25	8.33304
2484.02	5.66669
2486.8	2.52814
2489.56	2.26116
2492.33	2.69423
2495.1	1.63357
2497.86	1.19476
2500.63	2.75327
2503.39	4.29358
2506.16	4.13718
2508.92	4.79235
2511.68	6.02851
2514.44	7.9469
2517.2	10.2377
2519.95	13.4343
2522.71	16.2903
2525.47	19.2047
2528.22	20.8429
2530.98	21.9149
2533.73	23.0786
2536.48	24.6495
2539.23	29.0265
2541.98	29.4133
2544.73	30.1006
2547.48	30.9994
2550.23	32.3639
2552.97	30.4656
2555.72	31.7328
2558.46	31.4515
2561.2	32.0104
2563.95	29.3882
2566.69	26.9991
2569.43	24.4981
2572.17	19.4006
2574.91	16.242
2577.64	15.8093
2580.38	13.4773
2583.11	13.5058
2585.85	11.267
2588.58	8.7006
2591.31	8.32924
2594.04	8.25258
2596.78	6.73538
2599.51	6.71518
2602.23	8.02367
2604.96	8.45213
2607.69	8.91762
2610.41	11.9668
2613.14	11.4541
2615.86	10.9104
2618.58	11.7585
2621.3	12.6486
2624.03	13.3683
2626.75	15.3717
2629.46	17.1477
2632.18	15.7022
2634.9	17.762
2637.61	17.9778
2640.33	19.6239
2643.04	19.6649
2645.76	20.7529
2648.47	19.6417
2651.18	18.9011
2653.89	18.7459
2656.6	18.0941
2659.31	20.6051
2662.01	21.1646
2664.72	23.3265
2667.43	24.7
2670.13	26.6177
2672.83	28.8749
2675.53	30.4134
2678.24	27.2512
2680.94	26.1948
2683.64	27.9138
2686.34	29.2801
2689.03	29.4858
2691.73	33.6712
2694.43	33.8991
2697.12	35.2624
2699.81	34.0243
2702.51	32.5626
2705.2	33.4752
2707.89	32.499
2710.58	29.4967
2713.27	28.519
2715.96	25.9031
2718.64	25.5504
2721.33	26.0049
2724.01	25.6456
2726.7	26.5372
2729.38	24.1598
2732.06	22.4465
2734.75	21.254
2737.43	21.7882
2740.11	18.4061
2742.78	19.0598
2745.46	17.686
2748.14	18.4342
2750.81	18.8315
2753.49	16.8713
2756.16	18.5417
2758.84	19.0709
2761.51	17.3817
2764.18	16.0714
2766.85	14.1232
2769.52	13.6693
2772.19	13.0995
2774.85	12.4816
2777.52	12.2353
2780.18	12.4171
2782.85	14.8674
2785.51	12.092
2788.17	10.8205
2790.84	9.45929
2793.5	7.39423
2796.16	6.62452
2798.81	4.66593
2801.47	4.47438
2804.13	5.12967
2806.79	3.61478
2809.44	0.872289
2812.09	0.30321
2814.75	-1.31783
2817.4	3.53988
2820.05	8.72431
2822.7	11.2356
2825.35	15.5639
2828	19.2323
2830.65	26.1679
2833.29	34.0499
2835.94	40.2169
2838.58	49.2972
2841.23	55.2794
2843.87	62.8936
2846.51	69.4579
2849.15	76.4696
2851.79	85.2177
2854.43	91.4551
2857.07	100.603
2859.71	107.043
2862.34	112.317
2864.98	118.048
2867.61	123.086
2870.25	124.526
2872.88	126.852
2875.51	132.201
2878.14	135.736
2880.77	140.857
2883.4	143.432
2886.03	148.177
2888.65	154.181
2891.28	160.084
2893.91	165.963
2896.53	170.721
2899.15	177.492
2901.78	184.42
2904.4	193
2907.02	201.296
2909.64	210.673
2912.26	222.335
2914.87	230.654
2917.49	241.773
2920.11	251.575
2922.72	259.831
2925.34	263.576
2927.95	267.883
2930.56	270.137
2933.17	267.281
2935.78	265.346
2938.39	262.356
2941	255.177
2943.61	246.911
2946.22	238.878
2948.82	230.672
2951.43	223.429
2954.03	211.588
2956.64	195.83
2959.24	184.712
2961.84	172.935
2964.44	162.567
2967.04	153.865
2969.64	142.684
2972.24	133.874
2974.83	125.41
2977.43	116.15
2980.02	108.239
2982.62	100.603
2985.21	89.4952
2987.8	78.4612
2990.4	67.4044
2992.99	57.7418
2995.57	49.6432
2998.16	41.5516
3000.75	35.2277
3003.34	27.9399
3005.92	23.149
3008.51	18.1763
3011.09	15.204
3013.68	10.4609
3016.26	7.27939
3018.84	5.68903
3021.42	2.84545
3024	2.63136
3026.58	0.254763
3029.16	1.03887
3031.73	2.40254
3034.31	1.79127
3036.89	3.27045
3039.46	5.36658
3042.03	6.22505
3044.61	4.12959
3047.18	2.33905
3049.75	2.24952
3052.32	2.36625
3054.89	2.56714
3057.45	3.04206
3060.02	2.18231
3062.59	4.47094
3065.15	4.01845
3067.72	4.7875
3070.28	6.0345
3072.84	5.89326
3075.41	6.61824
3077.97	6.84766
3080.53	8.95598
3083.09	9.8557
3085.64	11.3598
3088.2	15.4195
3090.76	19.9279
3093.31	22.0731
3095.87	25.1783
3098.42	26.2882
3100.97	29.6961
3103.53	30.9918
3106.08	34.1282
3108.63	35.7439
3111.18	39.361
3113.73	42.9363
3116.27	46.3685
3118.82	49.2495
3121.37	52.4561
3123.91	55.8447
3126.45	59.9281
3129	61.094
3131.54	61.9641
3134.08	64.8238
3136.62	69.7972
3139.16	70.4492
3141.7	77.2961
3144.24	81.9476
3146.78	84.8339
3149.31	84.5605