File: data/Raman/poly_smoothed/Mb_40_24_21_1x_45s_532 nm_x100_100%_600 gr_mm_01.txt
#Acq. time (s)=	45
#Accumulations=	2
#Range (cm-¹)=	200...3150
#Windows=	2
#Auto scanning=	Off
#Autofocus=	Off
#Macrospot=	Off
#AutoExposure=	Off
#Spike filter=	Multiple accum.
#Delay time (s)=	0
#Binning=	1
#Readout mode=	Signal
#DeNoise=	Off
#ICS correction=	On
#Dark correction=	Off
#Inst. Process=	Off
#Detector Gain=	Best Dynamic Range
#Detector ADC=	20 kHz
#Detector temperature (°C)=	-70.08
#Instrument=	LabRAM HR Evol
#Detector=	Synapse
#Objective=	x100
#Grating=	600 gr/mm
#ND Filter=	100%
#Laser (nm)=	532
#Hole=	100.021
#Range=	Auto
#Laser Pol.=	No
#Raman. Pol.=	No
#Laser Pol. (°)=	-0.0007625
#Raman Pol. (°)=	89.9995
#Collection=	Microscope
#StageXY=	Marzhauser
#StageZ=	Marzhauser
#X (µm)=	-2518.2
#Y (µm)=	-108.9
#Z (µm)=	-10.7
#Full time(mm:ss)=	3:18
#Project=
#Sample=
#Site=
#Title=	Mb_40_24_21_2x_45s_532 nm_x100_100%_600 gr_mm
#Remark=
#Date=	14.07.2022 12:15
#Acquired=	14.07.2022 12:15:49
#Base:Fit=	10.08.2022 10:47:00
#Base:Sub=	10.08.2022 10:47:12
#Filter:Polynom=	16.08.2022 10:11:48
#AxisType[0]=Intens
#AxisUnit[0]=Cnt
#AxisType[1]=Spectr
#AxisUnit[1]=1/cm
200.554	10.0137
204.183	11.968
207.813	9.05793
211.439	7.52773
215.065	6.56292
218.688	7.61422
222.312	7.65404
225.933	8.87284
229.552	10.7218
233.171	9.76779
236.787	9.93108
240.402	10.5835
244.015	8.92279
247.627	7.6318
251.24	7.6994
254.849	9.3319
258.457	8.04582
262.063	7.4995
265.668	8.16873
269.271	8.52377
272.873	8.60296
276.474	8.97171
280.073	10.4046
283.671	8.99804
287.268	7.10031
290.863	8.44666
294.456	8.36168
298.049	9.27753
301.637	11.7218
305.227	15.1064
308.815	16.6169
312.402	18.6533
315.987	21.9913
319.569	25.1032
323.151	26.0177
326.733	27.1336
330.31	26.7091
333.889	26.6451
337.464	27.6653
341.039	26.1648
344.611	26.5162
348.184	26.4829
351.754	25.4708
355.324	26.4711
358.89	24.7626
362.455	25.3068
366.021	22.7715
369.584	20.1998
373.145	17.2808
376.707	16.3055
380.265	13.6525
383.822	11.687
387.378	11.6632
390.934	11.4392
394.487	9.37488
398.038	7.51616
401.588	6.64688
405.137	8.72774
408.685	8.85945
412.23	7.03979
415.775	4.87643
419.318	6.30477
422.86	7.74124
426.401	8.5568
429.94	9.84361
433.478	12.0057
437.012	14.4334
440.547	15.3048
444.081	16.1194
447.613	17.8951
451.142	17.3039
454.672	17.9584
458.2	17.8492
461.725	19.508
465.251	20.5941
468.775	21.4832
472.296	22.0016
475.817	23.826
479.335	24.6738
482.854	28.0234
486.37	30.3631
489.886	32.6091
493.398	35.7203
496.91	35.7409
500.422	35.3468
503.93	38.4961
507.438	40.1819
510.946	40.8366
514.45	39.6944
517.954	39.7605
521.456	37.7383
524.956	35.3501
528.456	33.71
531.956	30.7604
535.452	27.0674
538.947	24.3394
542.441	22.2208
545.934	19.321
549.425	18.6454
552.915	15.3559
556.403	15.1958
559.889	15.4144
563.375	14.7284
566.859	12.6936
570.342	12.3057
573.824	10.645
577.303	7.65667
580.782	6.53745
584.26	6.26132
587.734	6.0597
591.21	6.07943
594.684	6.22511
598.154	6.28114
601.626	6.69768
605.094	7.60132
608.562	6.67075
612.027	5.53308
615.493	5.59103
618.956	4.73789
622.419	3.86494
625.879	5.46213
629.338	6.49238
632.797	9.14358
636.254	10.4024
639.708	11.0354
643.162	11.0607
646.614	10.736
650.067	10.9102
653.516	10.2431
656.964	10.7853
660.411	10.7783
663.857	11.2989
667.301	12.5385
670.744	13.406
674.186	14.7299
677.626	15.6163
681.065	16.8806
684.503	16.6154
687.939	17.5785
691.372	18.6748
694.806	19.887
698.239	19.8945
701.67	18.0488
705.098	16.5846
708.526	19.3034
711.954	20.6859
715.378	21.0318
718.802	21.0344
722.226	22.4825
725.646	23.7331
729.067	25.2626
732.484	28.2572
735.902	30.5725
739.317	32.3369
742.731	34.6639
746.145	38.6332
749.556	39.4538
752.966	40.6978
756.377	43.4015
759.784	47.2408
763.19	49.114
766.594	51.2282
770	55.1685
773.402	57.0778
776.803	58.2496
780.202	57.4374
783.6	56.8917
786.997	58.7187
790.393	59.8037
793.787	62.1425
797.18	61.5232
800.572	62.5218
803.963	62.629
807.35	62.5168
810.738	63.0048
814.125	64.7579
817.51	66.6227
820.894	65.2328
824.275	64.5472
827.657	65.8708
831.037	66.2707
834.414	65.9392
837.792	65.2685
841.167	65.9165
844.542	62.776
847.914	62.6056
851.287	62.6171
854.656	60.4631
858.026	58.6465
861.393	57.8923
864.761	57.4134
868.125	56.9896
871.489	54.4672
874.85	52.7509
878.213	48.6249
881.572	44.5777
884.931	43.8852
888.287	40.5702
891.643	40.9699
894.997	41.1603
898.352	40.3554
901.704	39.1394
905.055	39.8452
908.404	40.2633
911.75	42.0468
915.097	42.7181
918.443	43.8377
921.787	43.4502
925.13	42.7081
928.472	43.463
931.813	44.2511
935.15	45.0263
938.488	45.4637
941.825	45.1995
945.158	42.9323
948.493	42.1575
951.824	40.0471
955.156	40.2501
958.486	37.562
961.814	36.2417
965.142	36.9191
968.467	38.2637
971.79	40.1071
975.115	42.4071
978.436	44.0771
981.756	45.8407
985.077	46.3479
988.394	47.3265
991.71	48.4582
995.025	49.8793
998.341	48.8297
1001.65	48.8168
1004.97	47.5451
1008.28	47.9951
1011.58	49.0166
1014.89	49.6831
1018.2	50.5091
1021.5	49.1558
1024.81	48.4928
1028.11	48.6
1031.41	52.4268
1034.71	54.4734
1038.01	55.3288
1041.31	56.1297
1044.6	58.2495
1047.9	60.7618
1051.19	61.2274
1054.48	60.9851
1057.77	61.6471
1061.06	57.9318
1064.35	54.7653
1067.64	51.4272
1070.93	48.8629
1074.21	43.9947
1077.49	41.0827
1080.78	39.9881
1084.06	38.5743
1087.34	36.4599
1090.61	36.0711
1093.89	35.3994
1097.17	34.3872
1100.44	33.4675
1103.71	34.3653
1106.99	35.0639
1110.26	35.5466
1113.52	38.222
1116.79	38.3055
1120.06	38.8937
1123.32	39.5953
1126.59	37.5239
1129.85	34.9817
1133.11	31.957
1136.37	29.9012
1139.63	26.4813
1142.89	22.542
1146.15	20.5967
1149.4	17.7795
1152.66	13.8435
1155.91	11.4164
1159.16	9.14003
1162.41	7.41492
1165.66	4.22438
1168.91	2.29411
1172.16	3.6593
1175.4	4.7095
1178.65	4.74979
1181.89	5.69289
1185.13	8.80608
1188.37	9.02206
1191.61	11.6433
1194.85	15.032
1198.08	19.9281
1201.32	23.8089
1204.55	28.2999
1207.79	32.1326
1211.02	36.9672
1214.25	43.1416
1217.48	47.072
1220.71	52.0361
1223.93	57.8445
1227.16	61.9848
1230.38	65.3456
1233.6	69.1503
1236.83	72.2777
1240.05	78.6097
1243.26	84.061
1246.48	88.3379
1249.7	91.7081
1252.92	95.2257
1256.13	98.0791
1259.34	99.6521
1262.55	101.911
1265.76	103.325
1268.97	105.11
1272.18	110.561
1275.39	113.78
1278.59	118.089
1281.8	119.93
1285	121.806
1288.2	123.704
1291.4	125.255
1294.6	126.554
1297.8	126.623
1301	126.94
1304.19	128.932
1307.39	128.298
1310.58	128.68
1313.77	129.846
1316.96	129.582
1320.15	128.363
1323.34	128.856
1326.53	127.382
1329.72	125.732
1332.9	123.187
1336.08	120.341
1339.27	117.49
1342.45	114.966
1345.63	111.783
1348.8	108.656
1351.98	105.865
1355.16	102.994
1358.33	99.1767
1361.51	95.3645
1364.68	93.222
1367.85	89.5661
1371.02	88.0841
1374.19	86.9188
1377.36	85.5803
1380.52	85.9394
1383.69	87.0425
1386.85	85.8597
1390.02	87.3888
1393.18	88.0504
1396.34	91.5311
1399.5	93.9543
1402.65	95.7298
1405.81	99.6366
1408.97	104.939
1412.12	108.867
1415.27	115.193
1418.43	121.365
1421.58	127.751
1424.73	135.189
1427.87	144.596
1431.02	153.067
1434.17	160.356
1437.31	165.635
1440.46	171.27
1443.6	174.453
1446.74	174.83
1449.88	175.823
1453.02	173.922
1456.16	170.33
1459.29	165.779
1462.43	159.046
1465.56	150.623
1468.69	140.946
1471.83	132.102
1474.95	121.874
1478.08	111.633
1481.21	102.57
1484.34	92.9035
1487.47	84.5353
1490.59	76.9332
1493.71	70.6839
1496.84	64.6391
1499.96	60.3241
1503.07	57.0468
1506.19	56.0102
1509.31	53.4218
1512.43	50.3487
1515.54	49.7129
1518.65	49.576
1521.77	50.496
1524.88	51.5705
1527.99	52.6569
1531.1	53.5142
1534.21	55.1992
1537.31	55.8206
1540.42	57.3226
1543.52	59.7912
1546.63	61.2518
1549.73	65.0578
1552.83	67.3146
1555.93	69.2886
1559.03	72.0952
1562.12	73.2983
1565.22	76.1396
1568.31	78.5338
1571.41	82.3689
1574.5	88.2171
1577.59	94.0627
1580.68	98.8243
1583.77	103.141
1586.86	104.721
1589.95	108.82
1593.03	112.561
1596.11	115.901
1599.2	117.199
1602.28	118.618
1605.36	119.074
1608.44	120.27
1611.52	120.109
1614.6	121.883
1617.67	122.222
1620.75	123.086
1623.82	125.201
1626.89	126.986
1629.96	129.441
1633.04	133.034
1636.11	136.699
1639.17	138.719
1642.24	141.989
1645.31	145.402
1648.37	147.905
1651.43	149.177
1654.5	148.343
1657.56	144.042
1660.62	138.169
1663.67	135.189
1666.73	129.418
1669.79	121.954
1672.84	114.028
1675.9	108.394
1678.95	99.6433
1682	90.7356
1685.05	81.4234
1688.1	73.0826
1691.15	66.1364
1694.2	60.1019
1697.25	53.8368
1700.29	48.3799
1703.33	45.7921
1706.38	42.8125
1709.42	40.0111
1712.46	37.0204
1715.5	33.6623
1718.54	32.8214
1721.57	31.0996
1724.61	28.1233
1727.64	26.4066
1730.68	23.8953
1733.71	22.531
1736.74	21.9711
1739.77	21.5862
1742.8	19.5152
1745.83	18.4121
1748.85	18.8746
1751.88	18.1686
1754.91	16.9185
1757.93	14.8772
1760.95	13.475
1763.97	11.9191
1766.99	11.067
1770.01	9.0509
1773.03	7.65805
1776.04	8.17072
1779.06	8.19979
1782.07	6.92061
1785.09	7.16539
1788.1	6.72736
1791.11	6.12009
1794.12	7.44714
1797.13	7.6343
1800.13	6.8369
1803.14	6.81611
1806.15	6.71916
1809.15	7.19171
1812.15	8.17423
1815.16	8.89764
1818.15	8.94657
1821.16	8.98733
1824.15	8.70817
1827.15	9.78418
1830.15	8.61191
1833.14	8.29309
1836.14	7.961
1839.13	7.74025
1842.12	8.79268
1845.11	8.05315
1848.1	7.59188
1851.09	6.5398
1854.08	6.08649
1857.06	5.20922
1860.05	5.77024
1863.03	4.10732
1866.01	3.54959
1869	3.04978
1871.98	2.62975
1874.96	1.52576
1877.93	2.10143
1880.91	2.2988
1882.47	2.90818
1885.46	2.88749
1888.44	1.84174
1891.43	2.26652
1894.42	3.47526
1897.4	4.1563
1900.39	5.03368
1903.37	5.89467
1906.35	8.08456
1909.33	8.826
1912.31	9.81456
1915.29	9.1735
1918.26	8.66868
1921.24	8.85362
1924.21	9.03014
1927.19	9.41701
1930.16	8.46877
1933.13	8.24971
1936.1	7.38386
1939.07	6.55841
1942.04	6.91674
1945	6.8644
1947.97	5.2577
1950.93	4.61553
1953.9	2.9889
1956.86	2.46218
1959.82	1.92005
1962.78	1.62039
1965.74	1.56162
1968.7	1.67664
1971.65	2.3902
1974.61	1.62633
1977.57	1.82593
1980.52	1.91421
1983.47	2.61277
1986.42	3.50207
1989.37	3.98634
1992.32	4.89316
1995.27	5.04939
1998.22	5.00496
2001.17	5.14974
2004.11	7.17503
2007.05	8.25159
2010	8.30076
2012.94	9.91807
2015.88	10.1994
2018.82	11.0214
2021.76	12.4644
2024.7	13.5873
2027.63	14.9389
2030.57	15.8003
2033.5	17.3022
2036.44	18.5542
2039.37	18.4202
2042.3	18.6497
2045.23	18.2411
2048.16	18.0382
2051.08	19.6629
2054.01	21.1762
2056.94	23.5731
2059.86	24.8368
2062.79	25.7603
2065.71	26.4973
2068.63	27.7501
2071.55	29.0211
2074.47	30.6143
2077.39	32.1859
2080.31	33.5339
2083.22	35.0258
2086.13	37.3443
2089.05	39.635
2091.96	42.1517
2094.87	44.6202
2097.78	46.4227
2100.69	49.4416
2103.6	52.9194
2106.51	55.8192
2109.42	54.7863
2112.32	57.8106
2115.23	61.4788
2118.13	64.2233
2121.03	67.3003
2123.93	73.1854
2126.83	79.6635
2129.73	84.2672
2132.63	89.7014
2135.53	94.467
2138.42	100.727
2141.32	106.485
2144.21	113.171
2147.1	120.23
2150	126.331
2152.89	132.235
2155.78	136.054
2158.66	141.228
2161.55	145.65
2164.44	149.149
2167.32	152.202
2170.21	152.842
2173.09	152.877
2175.97	150.945
2178.85	147.564
2181.73	144.376
2184.61	142.115
2187.49	137.515
2190.37	132.597
2193.24	128.904
2196.12	124.699
2198.99	119.748
2201.87	113.822
2204.74	108.527
2207.61	102.642
2210.48	97.1746
2213.35	93.814
2216.21	89.02
2219.08	83.6023
2221.95	78.9302
2224.81	74.5875
2227.67	70.363
2230.54	66.743
2233.4	62.2467
2236.26	58.4448
2239.11	54.4503
2241.97	50.5865
2244.83	46.7052
2247.69	44.4742
2250.54	41.1928
2253.4	40.2975
2256.25	38.2051
2259.1	36.5149
2261.95	35.7656
2264.8	33.7985
2267.65	31.952
2270.5	30.2509
2273.34	28.4022
2276.19	26.382
2279.03	25.5733
2281.88	26.0445
2284.72	23.5905
2287.56	21.3481
2290.4	19.0898
2293.24	17.0954
2296.08	15.1289
2298.92	14.565
2301.76	13.2852
2304.59	11.9648
2307.43	11.5746
2310.26	11.0447
2313.09	11.1238
2315.92	12.2793
2318.75	11.5969
2321.58	11.9152
2324.41	11.5811
2327.24	11.3796
2330.06	10.7627
2332.89	9.90804
2335.71	9.7685
2338.54	10.3905
2341.36	10.4785
2344.18	9.36288
2347	8.89102
2349.82	9.21182
2352.64	6.50852
2355.45	5.96225
2358.27	5.37779
2361.08	5.02185
2363.9	6.83899
2366.71	7.92275
2369.52	7.70818
2372.33	7.52219
2375.14	7.70076
2377.95	8.39052
2380.76	10.0494
2383.57	10.7309
2386.37	9.4862
2389.18	8.8338
2391.98	9.46007
2394.79	8.12276
2397.59	6.40769
2400.39	5.86007
2403.19	6.52193
2405.99	7.37409
2408.78	7.66026
2411.58	6.84457
2414.38	6.85832
2417.17	7.13793
2419.97	7.58876
2422.76	8.9275
2425.55	9.73782
2428.34	11.2416
2431.13	12.1485
2433.92	12.566
2436.71	12.7353
2439.49	12.5589
2442.28	13.388
2445.06	12.0986
2447.85	11.2017
2450.63	9.13963
2453.41	7.81633
2456.19	6.16036
2458.97	4.29275
2461.75	2.97262
2464.53	0.618682
2467.31	-0.857744
2470.08	0.37923
2472.86	-0.454283
2475.63	-1.53571
2478.4	-0.982988
2481.17	-0.877555
2483.94	0.0187721
2486.72	0.5246
2489.48	1.88742
2492.25	2.29854
2495.02	2.92609
2497.79	4.13231
2500.55	4.67644
2503.31	4.23998
2506.08	4.27172
2508.84	3.85465
2511.6	3.48647
2514.36	2.71319
2517.12	2.15493
2519.88	3.43887
2522.63	3.61933
2525.39	2.91467
2528.14	1.87664
2530.9	2.31797
2533.65	2.21546
2536.4	3.16581
2539.15	5.22707
2541.9	5.95168
2544.65	8.19665
2547.4	10.1166
2550.15	11.8046
2552.89	11.2401
2555.64	11.0039
2558.38	11.4639
2561.12	10.6893
2563.87	11.2379
2566.61	11.7082
2569.35	10.8983
2572.09	10.5491
2574.83	9.95263
2577.56	10.4076
2580.3	9.38894
2583.04	8.37168
2585.77	6.96808
2588.5	6.78038
2591.23	5.18572
2593.97	4.77023
2596.7	4.3254
2599.43	4.57122
2602.15	5.60476
2604.88	6.48141
2607.61	6.5912
2610.33	6.69475
2613.06	6.44988
2615.78	6.34569
2618.51	6.2658
2621.23	6.07353
2623.95	5.66645
2626.67	6.45279
2629.39	6.36381
2632.1	7.55363
2634.82	7.33573
2637.54	7.35441
2640.25	6.88807
2642.97	6.04918
2645.68	6.42238
2648.39	6.59656
2651.1	6.23731
2653.81	6.45146
2656.52	6.67203
2659.23	6.58007
2661.94	7.30115
2664.64	7.82092
2667.35	7.72322
2670.05	7.57409
2672.76	7.77351
2675.46	7.03741
2678.16	6.48076
2680.86	6.99992
2683.56	7.39659
2686.26	7.82761
2688.96	7.25608
2691.65	7.14147
2694.35	7.54445
2697.04	6.70451
2699.74	5.46106
2702.43	5.00786
2705.12	4.99631
2707.81	4.02664
2710.5	4.64891
2713.19	5.4554
2715.88	5.7125
2718.57	4.64341
2721.25	5.88818
2723.94	5.80399
2726.62	5.1059
2729.3	5.76039
2731.99	5.79526
2734.67	6.09115
2737.35	6.43262
2740.03	5.62919
2742.71	5.86452
2745.38	7.41722
2748.06	7.35234
2750.74	7.20423
2753.41	8.20639
2756.09	7.32867
2758.76	6.40194
2761.43	5.6757
2764.1	4.44821
2766.77	3.60962
2769.44	2.53405
2772.11	2.18685
2774.77	1.66177
2777.44	0.930347
2780.11	0.135779
2782.77	-1.58656
2785.43	-2.32714
2788.1	-2.66377
2790.76	-3.88788
2793.42	-2.27245
2796.08	-1.24689
2798.74	-1.78593
2801.4	-0.556635
2804.05	-1.02297
2806.71	-0.874669
2809.36	0.192411
2812.02	0.0135117
2814.67	0.846029
2817.32	2.79945
2819.97	6.05732
2822.62	8.73175
2825.27	12.9169
2827.92	17.8312
2830.57	23.9295
2833.22	31.1537
2835.86	38.626
2838.51	47.1248
2841.15	57.8627
2843.79	67.6938
2846.43	78.6023
2849.08	90.704
2851.72	102.829
2854.36	115.655
2856.99	127.282
2859.63	139.865
2862.27	151.091
2864.9	162.111
2867.54	170.242
2870.17	179.51
2872.8	188.656
2875.43	197.004
2878.07	206.127
2880.7	214.266
2883.32	222.572
2885.95	231.1
2888.58	240.828
2891.21	251.021
2893.83	263.47
2896.46	276.29
2899.08	290.456
2901.7	307.405
2904.32	325.198
2906.94	344.735
2909.56	364.166
2912.18	384.259
2914.8	403.993
2917.42	422.251
2920.03	439.064
2922.65	452.854
2925.26	462.317
2927.88	469.454
2930.49	472.445
2933.1	471.557
2935.71	470.396
2938.32	463.994
2940.93	452.498
2943.54	438.87
2946.14	422.574
2948.75	404.647
2951.35	386.552
2953.96	365.865
2956.56	346.946
2959.16	327.894
2961.77	308.141
2964.37	289.493
2966.96	272.692
2969.56	255.763
2972.16	241.021
2974.76	225.961
2977.35	211.122
2979.95	196.683
2982.54	180.856
2985.14	165.999
2987.73	151.306
2990.32	136.96
2992.91	123.622
2995.5	111.504
2998.09	98.1159
3000.68	86.2804
3003.26	73.415
3005.85	62.2135
3008.43	53.4401
3011.02	43.7156
3013.6	35.0161
3016.19	28.415
3018.77	23.2793
3021.35	18.6492
3023.93	13.4989
3026.5	8.6897
3029.08	5.38046
3031.66	3.95593
3034.24	2.52174
3036.81	1.52707
3039.39	1.71415
3041.96	2.19481
3044.53	2.91805
3047.1	4.21686
3049.67	5.43042
3052.24	7.00739
3054.81	7.5942
3057.38	8.84708
3059.95	9.40615
3062.52	10.2298
3065.08	11.2536
3067.65	10.6535
3070.21	10.4583
3072.77	10.5075
3075.33	8.78347
3077.89	8.11621
3080.45	7.90507
3083.01	5.38819
3085.57	4.32007
3088.13	1.77705
3090.68	0.117636
3093.24	-0.394062
3095.79	-1.15704
3098.35	-1.43368
3100.9	-0.30742
3103.45	-0.895335
3106	-0.318427
3108.55	0.798425
3111.1	1.89443
3113.65	4.65345
3116.2	6.63451
3118.75	7.45707
3121.29	9.6933
3123.84	11.6573
3126.38	13.6889
3128.92	15.5232
3131.47	17.3928
3134.01	19.598
3136.55	22.2481
3139.09	24.0208
3141.63	25.6996
3144.17	26.2532
3146.7	27.1003
3149.24	26.5271