File: data/Raman/poly_smoothed/Mb_40_y_10_1x_45s_532 nm_x100_100%_600 gr_mm_01.txt
#Acq. time (s)=	45
#Accumulations=	2
#Range (cm-¹)=	200...3150
#Windows=	2
#Auto scanning=	Off
#Autofocus=	Off
#Macrospot=	Off
#AutoExposure=	Off
#Spike filter=	Multiple accum.
#Delay time (s)=	0
#Binning=	1
#Readout mode=	Signal
#DeNoise=	Off
#ICS correction=	On
#Dark correction=	Off
#Inst. Process=	Off
#Detector Gain=	Best Dynamic Range
#Detector ADC=	20 kHz
#Detector temperature (°C)=	-69.85
#Instrument=	LabRAM HR Evol
#Detector=	Synapse
#Objective=	x100
#Grating=	600 gr/mm
#ND Filter=	100%
#Laser (nm)=	532
#Hole=	100.021
#Range=	Auto
#Laser Pol.=	No
#Raman. Pol.=	No
#Laser Pol. (°)=	-0.0007625
#Raman Pol. (°)=	89.9995
#Collection=	Microscope
#StageXY=	Marzhauser
#StageZ=	Marzhauser
#X (µm)=	-1032.9
#Y (µm)=	687.7
#Z (µm)=	584.55
#Full time(mm:ss)=	3:18
#Project=
#Sample=
#Site=
#Title=	Mb_40_y_10_2x_45s_532 nm_x100_100%_600 gr_mm
#Remark=
#Date=	19.07.2022 09:37
#Acquired=	19.07.2022 09:37:16
#Base:Fit=	10.08.2022 10:52:48
#Base:Sub=	10.08.2022 10:52:53
#Filter:Polynom=	16.08.2022 10:09:04
#AxisType[0]=Intens
#AxisUnit[0]=Cnt
#AxisType[1]=Spectr
#AxisUnit[1]=1/cm
200.423	4.98405
204.052	6.08466
207.682	9.82624
211.308	12.3986
214.935	13.5853
218.558	14.5005
222.18	11.4798
225.802	12.1182
229.421	12.0076
233.039	11.5932
236.657	11.4847
240.272	11.9786
243.885	10.4734
247.497	10.1977
251.11	9.67872
254.719	8.06374
258.327	7.28474
261.933	7.08962
265.538	5.41764
269.141	5.5832
272.744	4.68147
276.344	4.30716
279.944	4.53216
283.542	6.36309
287.138	6.4306
290.733	6.45063
294.327	7.68123
297.919	6.56829
301.508	7.01775
305.098	7.34089
308.686	7.303
312.273	9.40697
315.858	11.0932
319.44	11.6657
323.022	11.5559
326.604	13.0321
330.181	14.6234
333.76	14.8379
337.335	15.7926
340.91	15.7438
344.483	15.3013
348.055	16.7434
351.625	16.135
355.195	14.5139
358.762	14.8977
362.329	16.6487
365.893	16.3731
369.455	16.1859
373.017	16.9586
376.578	16.0494
380.137	16.0673
383.694	17.0908
387.249	17.4078
390.806	17.4994
394.359	18.216
397.91	20.1305
401.46	22.8172
405.009	22.5323
408.557	23.4473
412.103	24.2065
415.647	23.4942
419.191	24.2819
422.733	22.0221
426.273	20.3623
429.812	18.8908
433.35	17.1197
436.885	16.2021
440.42	15.2805
443.954	13.6524
447.486	15.2061
451.015	14.6002
454.545	13.4176
458.073	13.0584
461.598	13.4918
465.124	13.4104
468.648	16.1131
472.169	17.665
475.69	22.0639
479.208	24.2418
482.727	27.6715
486.243	31.2697
489.759	35.9339
493.272	36.9046
496.783	39.2881
500.295	40.0446
503.804	41.9479
507.311	42.6119
510.819	42.8112
514.324	43.4132
517.827	44.0592
521.329	44.0102
524.83	44.0919
528.329	42.027
531.829	40.5248
535.326	39.4685
538.821	39.2962
542.315	37.1684
545.808	36.0139
549.299	35.3634
552.789	33.1532
556.278	30.9968
559.763	28.6371
563.249	24.8158
566.733	23.0516
570.217	21.385
573.699	21.0707
577.177	18.5282
580.656	15.7187
584.134	14.2291
587.609	10.8175
591.084	6.39498
594.558	5.85587
598.029	5.25809
601.5	4.5973
604.968	4.67166
608.437	5.11532
611.902	5.32315
615.368	5.19928
618.831	5.95024
622.294	5.2047
625.755	5.42622
629.213	7.11641
632.673	6.84684
636.129	8.49647
639.584	8.49996
643.037	9.68036
646.491	8.07629
649.942	9.30539
653.392	9.61996
656.84	10.4336
660.287	11.147
663.732	11.6233
667.177	11.6408
670.62	11.8634
674.061	12.4028
677.502	15.228
680.941	17.6596
684.379	20.7004
687.815	23.3575
691.248	26.4568
694.682	28.7276
698.115	32.4946
701.546	36.9696
704.974	40.4892
708.402	44.2904
711.83	49.8189
715.254	52.066
718.679	54.1432
722.102	54.9269
725.522	55.1935
728.943	55.3442
732.361	53.2132
735.779	54.1318
739.194	53.7706
742.608	52.1033
746.022	51.3632
749.433	49.7126
752.843	48.5194
756.254	48.3304
759.661	47.5341
763.067	47.784
766.471	48.9858
769.877	49.7077
773.279	52.2527
776.68	53.0382
780.079	56.3036
783.478	57.432
786.875	59.6493
790.27	61.277
793.665	62.6122
797.058	62.707
800.45	64.1192
803.84	64.5278
807.23	65.5443
810.616	66.1197
814.002	64.2834
817.388	65.2003
820.772	63.9717
824.153	63.9635
827.535	62.3163
830.915	63.6927
834.292	62.1927
837.67	60.662
841.047	59.072
844.42	59.2534
847.794	58.2455
851.165	55.2724
854.534	52.2742
857.905	49.8392
861.272	49.4784
864.639	49.1473
868.004	47.4486
871.367	46.7751
874.731	43.6453
878.092	43.1834
881.451	43.9679
884.809	43.0044
888.166	41.867
891.522	41.4668
894.878	40.7496
898.231	40.9527
901.583	40.931
904.934	40.5683
908.283	40.7929
911.631	40.4569
914.976	40.4567
918.322	38.1078
921.666	38.2119
925.009	40.2582
928.351	41.1378
931.692	38.6306
935.029	38.2088
938.367	40.1231
941.704	40.3119
945.038	40.2495
948.372	38.6983
951.705	36.8934
955.035	36.3902
958.366	36.2247
961.693	35.6913
965.021	34.1442
968.346	34.1291
971.67	36.135
974.995	37.1325
978.316	37.3318
981.638	38.5186
984.957	39.294
988.274	36.8013
991.59	36.9729
994.907	34.1593
998.221	29.7259
1001.53	22.6786
1004.85	18.4642
1008.16	21.4306
1011.46	35.6796
1014.77	61.6447
1018.08	94.3065
1021.38	125.756
1024.69	156.28
1027.99	183.255
1031.29	205.811
1034.59	225.951
1037.89	239.473
1041.19	249.513
1044.48	255.854
1047.78	257.638
1051.07	254.871
1054.36	247.145
1057.66	233.292
1060.94	215.069
1064.23	193.321
1067.52	164.932
1070.81	134.352
1074.09	101.18
1077.38	66.3041
1080.66	35.2896
1083.94	13.1263
1087.22	2.43296
1090.5	5.14718
1093.77	11.4693
1097.05	18.8869
1100.32	22.1582
1103.6	24.164
1106.87	24.772
1110.14	25.7625
1113.41	25.7469
1116.67	26.9543
1119.94	25.6592
1123.21	26.4632
1126.47	25.7915
1129.73	25.1297
1133	26.015
1136.26	24.2264
1139.52	23.0073
1142.77	20.606
1146.03	19.1045
1149.29	16.323
1152.54	14.7604
1155.79	11.9925
1159.04	8.55345
1162.3	6.36482
1165.55	5.98663
1168.79	4.68662
1172.04	5.12621
1175.28	6.2268
1178.53	5.16687
1181.77	5.47818
1185.01	5.13526
1188.25	5.87944
1191.49	5.74364
1194.73	4.97427
1197.97	5.54432
1201.2	6.04854
1204.44	10.0899
1207.67	13.028
1210.9	16.2352
1214.13	22.1204
1217.36	25.932
1220.59	30.1484
1223.82	33.4968
1227.04	39.0154
1230.26	41.9028
1233.49	45.0998
1236.71	49.0092
1239.93	53.7273
1243.15	59.0531
1246.37	63.4731
1249.58	69.0082
1252.8	72.8888
1256.01	76.1155
1259.23	78.9166
1262.44	81.0117
1265.65	83.4824
1268.86	87.0393
1272.07	90.153
1275.27	91.7365
1278.48	93.7933
1281.68	96.2291
1284.89	99.5453
1288.09	101.717
1291.29	105.984
1294.49	106.873
1297.69	106.975
1300.88	107.421
1304.08	109.648
1307.27	110.681
1310.47	110.51
1313.66	110.721
1316.85	109.859
1320.04	111.136
1323.23	110.058
1326.41	110.586
1329.6	108.902
1332.78	107.24
1335.97	104.302
1339.15	100.474
1342.33	96.9494
1345.51	93.6023
1348.69	88.5666
1351.87	83.1556
1355.04	78.0877
1358.22	75.0225
1361.39	70.7084
1364.57	67.2592
1367.74	63.1867
1370.91	59.6901
1374.07	56.1022
1377.24	55.6796
1380.41	55.0396
1383.57	54.8204
1386.74	53.9741
1389.9	52.6043
1393.06	54.7711
1396.22	55.6375
1399.38	58.7504
1402.54	60.6618
1405.7	63.1627
1408.85	64.1048
1412.01	67.1789
1415.16	71.0017
1418.31	75.1295
1421.46	80.4319
1424.61	87.8295
1427.76	94.9231
1430.91	103.357
1434.05	109.225
1437.2	115.511
1440.34	118.415
1443.49	121.648
1446.63	122.841
1449.77	122.998
1452.91	123.821
1456.04	120.639
1459.18	116.276
1462.31	110.917
1465.45	105.691
1468.58	100.965
1471.71	93.866
1474.84	86.2525
1477.97	79.2891
1481.1	70.4523
1484.23	62.8157
1487.35	57.1336
1490.48	52.288
1493.6	47.8676
1496.72	43.4334
1499.84	41.3528
1502.96	39.9877
1506.08	35.6701
1509.2	33.3473
1512.31	30.9599
1515.43	27.687
1518.54	24.3981
1521.66	23.5432
1524.77	23.7704
1527.88	23.8806
1530.99	24.2226
1534.09	24.3238
1537.2	24.8806
1540.31	26.925
1543.41	29.8578
1546.51	31.6878
1549.62	34.1382
1552.72	37.4832
1555.82	41.0265
1558.91	43.3256
1562.01	48.6915
1565.11	53.1871
1568.2	56.3446
1571.3	59.3292
1574.39	64.655
1577.48	67.7929
1580.57	70.2035
1583.66	73.0974
1586.75	76.5179
1589.83	77.8626
1592.92	78.7697
1596	80.3804
1599.09	81.2551
1602.17	81.7126
1605.25	81.5908
1608.33	80.5684
1611.41	80.1385
1614.48	79.657
1617.56	79.8502
1620.64	81.7191
1623.71	83.2079
1626.78	85.4964
1629.86	88.5004
1632.92	92.3282
1635.99	96.1479
1639.06	100.027
1642.13	104.766
1645.19	109.009
1648.26	112.674
1651.32	115.993
1654.38	116.405
1657.45	117.321
1660.51	115.608
1663.57	113.326
1666.62	108.843
1669.68	103.669
1672.73	97.3001
1675.79	90.6951
1678.84	83.6505
1681.89	75.2249
1684.94	67.5739
1687.99	58.9754
1691.04	50.5811
1694.09	43.9326
1697.14	36.9822
1700.18	32.1173
1703.22	26.2309
1706.27	22.5345
1709.31	18.0986
1712.35	15.9907
1715.39	13.8685
1718.43	11.2222
1721.46	10.087
1724.5	8.69559
1727.53	7.40398
1730.57	6.03098
1733.6	5.46687
1736.63	5.53349
1739.66	6.4594
1742.69	7.63069
1745.72	6.86432
1748.74	6.6011
1751.77	7.94324
1754.8	7.27396
1757.82	6.3682
1760.84	5.47602
1763.86	5.6461
1766.88	5.57651
1769.9	5.88883
1772.92	5.52961
1775.93	5.63673
1778.95	5.64679
1781.96	4.65125
1784.98	4.30052
1787.99	4.00169
1791	3.80222
1794.01	3.78587
1797.02	4.00066
1800.03	3.71558
1803.03	2.52936
1806.04	1.94458
1809.04	2.33762
1812.04	2.87776
1815.05	2.49223
1818.05	1.77193
1821.05	1.41277
1824.05	1.27921
1827.04	0.461895
1830.04	-0.0702746
1833.03	-0.261644
1836.03	0.551778
1839.02	1.23403
1842.01	1.44674
1845	1.24366
1847.99	1.69829
1850.98	1.95246
1853.97	1.69115
1856.95	1.58371
1859.94	1.82786
1862.92	2.39181
1865.91	2.38937
1868.89	3.02148
1871.87	3.12807
1874.85	2.79599
1877.83	2.6747
1880.8	2.59291
1882.56	3.93919
1885.54	3.64361
1888.53	3.4337
1891.52	4.091
1894.5	3.42352
1897.49	4.11848
1900.47	4.38847
1903.45	4.99986
1906.43	6.05535
1909.41	7.12282
1912.39	5.2366
1915.37	4.91944
1918.35	5.68018
1921.32	6.17044
1924.3	6.14888
1927.27	6.05817
1930.24	5.9723
1933.21	6.23214
1936.18	6.27723
1939.15	6.32544
1942.12	5.14726
1945.09	4.68969
1948.05	4.17321
1951.02	3.71311
1953.98	4.33542
1956.94	3.9869
1959.91	2.95574
1962.87	3.89263
1965.82	3.61991
1968.78	3.85983
1971.74	4.41846
1974.7	4.41746
1977.65	4.93724
1980.6	4.73016
1983.56	4.29852
1986.51	5.71612
1989.46	7.48829
1992.41	8.13256
1995.36	7.75076
1998.3	7.17761
2001.25	7.2263
2004.2	5.90805
2007.14	6.26115
2010.08	6.32904
2013.02	6.82762
2015.97	6.71194
2018.9	6.3769
2021.84	6.92782
2024.78	8.03176
2027.72	9.19987
2030.65	9.49042
2033.59	10.4022
2036.52	10.8002
2039.45	11.1149
2042.38	12.5306
2045.31	14.4491
2048.24	14.4579
2051.17	15.839
2054.1	17.6835
2057.02	19.7105
2059.95	21.3396
2062.87	22.3663
2065.79	23.3597
2068.71	24.3298
2071.63	26.0987
2074.55	27.7509
2077.47	30.4822
2080.39	33.3994
2083.3	35.9301
2086.22	36.4147
2089.13	39.4112
2092.05	42.2902
2094.96	45.9627
2097.87	49.7531
2100.78	52.2557
2103.69	55.6845
2106.59	59.9589
2109.5	64.1809
2112.41	67.7669
2115.31	72.0584
2118.21	77.4195
2121.12	82.2374
2124.02	88.2205
2126.92	94.6127
2129.82	101.436
2132.71	108.282
2135.61	115.56
2138.51	122.396
2141.4	130.274
2144.29	134.786
2147.19	140.364
2150.08	146.556
2152.97	151.426
2155.86	155.457
2158.75	159.759
2161.64	162.543
2164.52	166.61
2167.41	168.742
2170.29	168.499
2173.17	168.946
2176.06	168.124
2178.94	166.401
2181.82	163.334
2184.7	160.729
2187.57	156.258
2190.45	152.029
2193.33	147.019
2196.2	141.53
2199.08	136.98
2201.95	131.691
2204.82	126.045
2207.69	119.834
2210.56	112.936
2213.43	106.366
2216.3	99.1826
2219.16	93.9897
2222.03	87.1935
2224.89	81.7473
2227.75	78.0413
2230.62	72.1601
2233.48	68.7695
2236.34	65.1039
2239.2	61.0196
2242.06	56.7243
2244.91	53.7752
2247.77	51.0841
2250.62	48.6036
2253.48	45.809
2256.33	43.2325
2259.18	40.9427
2262.03	39.4878
2264.88	37.0587
2267.73	36.0858
2270.58	33.8895
2273.43	32.1675
2276.27	30.9103
2279.12	29.2877
2281.96	27.4742
2284.8	25.5548
2287.64	23.7456
2290.49	22.0357
2293.32	20.0389
2296.16	18.8257
2299	20.0861
2301.84	20.1803
2304.67	19.5189
2307.51	19.892
2310.34	18.6256
2313.17	17.9933
2316	18.1363
2318.83	17.9447
2321.66	16.8495
2324.49	17.4531
2327.32	16.3064
2330.15	15.5312
2332.97	15.5148
2335.79	13.9778
2338.62	12.3857
2341.44	11.7964
2344.26	10.4352
2347.08	8.35359
2349.9	6.96081
2352.72	4.82751
2355.53	3.51804
2358.35	1.95974
2361.17	0.917159
2363.98	0.275915
2366.79	1.58083
2369.6	1.13513
2372.42	0.928961
2375.22	-0.0831728
2378.03	-0.493301
2380.84	0.274195
2383.65	0.731577
2386.45	1.50932
2389.26	1.33662
2392.06	3.04268
2394.87	5.12449
2397.67	5.24537
2400.47	5.91589
2403.27	7.56595
2406.07	8.0558
2408.86	8.90969
2411.66	8.18426
2414.46	8.87821
2417.25	9.21185
2420.05	8.85614
2422.84	8.30601
2425.63	8.59988
2428.42	8.00559
2431.21	6.65299
2434	5.66247
2436.79	4.85946
2439.57	4.63003
2442.36	4.38619
2445.14	4.2808
2447.93	4.43704
2450.71	4.236
2453.49	4.42907
2456.27	3.71986
2459.05	4.28291
2461.83	6.04394
2464.61	6.79402
2467.39	7.82601
2470.16	8.46964
2472.94	9.92165
2475.71	9.69465
2478.48	8.94081
2481.25	8.6144
2484.02	8.74721
2486.8	8.47792
2489.56	8.37117
2492.33	8.55117
2495.1	8.22948
2497.86	6.99428
2500.63	6.07455
2503.39	6.01987
2506.16	4.98142
2508.92	4.51174
2511.68	4.68403
2514.44	4.71003
2517.2	3.97733
2519.95	3.46204
2522.71	3.74499
2525.47	3.95985
2528.22	4.79493
2530.98	5.64404
2533.73	6.41986
2536.48	5.90315
2539.23	5.50654
2541.98	5.19883
2544.73	5.45495
2547.48	6.49798
2550.23	6.94666
2552.97	6.91589
2555.72	6.22001
2558.46	5.8985
2561.2	5.74753
2563.95	5.43737
2566.69	5.47811
2569.43	5.62207
2572.17	5.54222
2574.91	5.00297
2577.64	4.96134
2580.38	5.62953
2583.11	4.31478
2585.85	3.21529
2588.58	3.78841
2591.31	3.79296
2594.04	4.20487
2596.78	4.48833
2599.51	4.08263
2602.23	4.43131
2604.96	4.00566
2607.69	3.815
2610.41	4.51125
2613.14	4.40038
2615.86	3.72172
2618.58	3.34967
2621.3	2.35213
2624.03	3.05922
2626.75	3.92732
2629.46	4.41192
2632.18	3.91809
2634.9	4.81341
2637.61	3.78618
2640.33	3.77544
2643.04	3.94613
2645.76	3.06011
2648.47	3.03492
2651.18	3.16301
2653.89	3.79502
2656.6	4.72717
2659.31	6.20914
2662.01	5.51052
2664.72	5.82453
2667.43	5.20425
2670.13	6.43641
2672.83	5.61819
2675.53	6.69537
2678.24	6.03258
2680.94	5.97448
2683.64	6.15582
2686.34	5.89273
2689.03	5.76399
2691.73	4.82089
2694.43	4.23084
2697.12	3.0316
2699.81	2.71948
2702.51	3.04331
2705.2	3.53102
2707.89	3.45336
2710.58	3.89218
2713.27	4.5716
2715.96	5.15793
2718.64	6.39488
2721.33	6.26793
2724.01	7.12913
2726.7	6.72539
2729.38	6.03733
2732.06	5.82173
2734.75	4.38978
2737.43	3.9298
2740.11	4.31468
2742.78	5.1754
2745.46	4.2839
2748.14	3.12881
2750.81	2.10193
2753.49	1.48606
2756.16	2.1064
2758.84	1.04382
2761.51	0.672138
2764.18	0.406946
2766.85	1.35873
2769.52	1.33417
2772.19	1.88633
2774.85	1.64661
2777.52	2.23846
2780.18	2.89669
2782.85	2.57904
2785.51	2.98924
2788.17	3.16518
2790.84	3.15461
2793.5	2.58612
2796.16	1.94563
2798.81	1.48338
2801.47	1.26635
2804.13	2.45799
2806.79	3.40072
2809.44	1.98497
2812.09	1.93962
2814.75	1.34414
2817.4	2.71232
2820.05	5.473
2822.7	7.21568
2825.35	11.2823
2828	15.1808
2830.65	19.8732
2833.29	26.3975
2835.94	33.7325
2838.58	40.4013
2841.23	48.3008
2843.87	58.0481
2846.51	67.7674
2849.15	78.5327
2851.79	88.6412
2854.43	100.359
2857.07	111.773
2859.71	121.808
2862.34	130.934
2864.98	139.339
2867.61	148.041
2870.25	155.812
2872.88	161.36
2875.51	168.188
2878.14	173.52
2880.77	179.238
2883.4	186.718
2886.03	192.7
2888.65	199.517
2891.28	205.442
2893.91	212.097
2896.53	219.628
2899.15	229.07
2901.78	239.845
2904.4	251.108
2907.02	263.506
2909.64	279.413
2912.26	294.612
2914.87	309.427
2917.49	323.316
2920.11	337.065
2922.72	348.488
2925.34	357.663
2927.95	366.595
2930.56	371.976
2933.17	375.471
2935.78	375.833
2938.39	373.977
2941	370.279
2943.61	363.385
2946.22	355.847
2948.82	345.521
2951.43	332.23
2954.03	317.738
2956.64	303.862
2959.24	290.362
2961.84	276.205
2964.44	260.818
2967.04	246.264
2969.64	231.35
2972.24	218.261
2974.83	205.729
2977.43	192.039
2980.02	177.475
2982.62	164.763
2985.21	153.288
2987.8	140.431
2990.4	127.909
2992.99	115.365
2995.57	102.806
2998.16	92.6218
3000.75	82.3167
3003.34	73.2922
3005.92	64.2063
3008.51	55.4657
3011.09	47.2225
3013.68	39.2944
3016.26	33.3053
3018.84	28.8703
3021.42	24.8932
3024	21.2107
3026.58	16.4316
3029.16	14.5328
3031.73	13.0497
3034.31	11.6291
3036.89	10.6009
3039.46	9.93299
3042.03	10.44
3044.61	11.0846
3047.18	12.9205
3049.75	13.0896
3052.32	13.7528
3054.89	14.0023
3057.45	14.4097
3060.02	14.5954
3062.59	14.4659
3065.15	13.7082
3067.72	13.2895
3070.28	12.286
3072.84	11.416
3075.41	10.5505
3077.97	8.61576
3080.53	7.79065
3083.09	6.38223
3085.64	4.80698
3088.2	3.98223
3090.76	3.23404
3093.31	2.53495
3095.87	1.11276
3098.42	0.293377
3100.97	0.884199
3103.53	0.254821
3106.08	0.795324
3108.63	1.46701
3111.18	1.67687
3113.73	1.99103
3116.27	2.08818
3118.82	1.64148
3121.37	2.14459
3123.91	2.42471
3126.45	3.28644
3129	4.28526
3131.54	5.94217
3134.08	5.71005
3136.62	6.49409
3139.16	7.10065
3141.7	8.46892
3144.24	10.4068
3146.78	12.2145
3149.31	13.1409