File: data/Raman/poly_smoothed/Mb_40_y_39_1x_45s_532 nm_x100_100%_600 gr_mm_01.txt
#Acq. time (s)=	45
#Accumulations=	2
#Range (cm-¹)=	200...3150
#Windows=	2
#Auto scanning=	Off
#Autofocus=	Off
#Macrospot=	Off
#AutoExposure=	Off
#Spike filter=	Multiple accum.
#Delay time (s)=	0
#Binning=	1
#Readout mode=	Signal
#DeNoise=	Off
#ICS correction=	On
#Dark correction=	Off
#Inst. Process=	Off
#Detector Gain=	Best Dynamic Range
#Detector ADC=	20 kHz
#Detector temperature (°C)=	-69.85
#Instrument=	LabRAM HR Evol
#Detector=	Synapse
#Objective=	x100
#Grating=	600 gr/mm
#ND Filter=	100%
#Laser (nm)=	532
#Hole=	100.021
#Range=	Auto
#Laser Pol.=	No
#Raman. Pol.=	No
#Laser Pol. (°)=	-0.0007625
#Raman Pol. (°)=	89.9995
#Collection=	Microscope
#StageXY=	Marzhauser
#StageZ=	Marzhauser
#X (µm)=	-1076.7
#Y (µm)=	598.4
#Z (µm)=	583.95
#Full time(mm:ss)=	3:18
#Project=
#Sample=
#Site=
#Title=	Mb_40_y_39_2x_45s_532 nm_x100_100%_600 gr_mm
#Remark=
#Date=	19.07.2022 12:38
#Acquired=	19.07.2022 12:38:29
#Base:Fit=	10.08.2022 10:52:48
#Base:Sub=	10.08.2022 10:52:53
#Filter:Polynom=	16.08.2022 10:09:04
#AxisType[0]=Intens
#AxisUnit[0]=Cnt
#AxisType[1]=Spectr
#AxisUnit[1]=1/cm
200.423	0.282372
204.052	1.44768
207.682	2.10678
211.308	3.51324
214.935	3.85896
218.558	5.04231
222.18	6.18481
225.802	5.13705
229.421	5.23074
233.039	7.21016
236.657	8.13058
240.272	8.62225
243.885	8.63727
247.497	6.89761
251.11	5.45959
254.719	6.3957
258.327	6.46696
261.933	7.18607
265.538	7.78904
269.141	6.65184
272.744	6.63282
276.344	7.41665
279.944	6.41546
283.542	4.8725
287.138	5.24062
290.733	5.48944
294.327	5.15248
297.919	6.00691
301.508	5.28717
305.098	6.04066
308.686	5.81824
312.273	6.44278
315.858	7.16837
319.44	7.58254
323.022	8.43819
326.604	9.39497
330.181	9.04907
333.76	8.56999
337.335	8.18136
340.91	9.84599
344.483	12.6024
348.055	12.1787
351.625	13.862
355.195	14.5166
358.762	12.9506
362.329	12.2425
365.893	11.0769
369.455	9.91758
373.017	9.02979
376.578	10.2714
380.137	9.99063
383.694	10.3086
387.249	10.3404
390.806	9.93999
394.359	10.9448
397.91	9.58977
401.46	9.60833
405.009	7.85937
408.557	7.51802
412.103	8.71557
415.647	7.65993
419.191	7.01121
422.733	7.41655
426.273	6.94847
429.812	7.92897
433.35	6.90822
436.885	4.33372
440.42	3.87405
443.954	4.03451
447.486	3.12708
451.015	2.17368
454.545	2.2215
458.073	3.7964
461.598	4.44808
465.124	7.26671
468.648	8.13599
472.169	8.9768
475.69	8.26132
479.208	11.0397
482.727	12.8664
486.243	14.4484
489.759	15.094
493.272	17.2181
496.783	18.9726
500.295	18.7078
503.804	16.5844
507.311	16.8965
510.819	18.311
514.324	17.8476
517.827	16.1294
521.329	15.537
524.83	14.5923
528.329	13.4183
531.829	13.6522
535.326	12.7285
538.821	12.127
542.315	11.2492
545.808	10.1707
549.299	9.15521
552.789	8.74286
556.278	7.30604
559.763	5.20301
563.249	6.64143
566.733	7.41688
570.217	6.91047
573.699	5.66671
577.177	5.04184
580.656	4.4587
584.134	2.10434
587.609	0.0882438
591.084	0.702846
594.558	0.373528
598.029	1.0821
601.5	1.90892
604.968	2.99583
608.437	2.72742
611.902	2.52096
615.368	4.24078
618.831	4.74812
622.294	6.17963
625.755	5.55119
629.213	6.64411
632.673	8.26736
636.129	9.1094
639.584	8.75574
643.037	8.91719
646.491	10.6329
649.942	12.0933
653.392	11.6296
656.84	14.5909
660.287	14.0241
663.732	13.028
667.177	13.4029
670.62	14.0874
674.061	15.98
677.502	17.0465
680.941	19.1107
684.379	22.051
687.815	22.9338
691.248	23.7206
694.682	25.9793
698.115	28.3916
701.546	28.5029
704.974	31.2874
708.402	33.2106
711.83	35.0831
715.254	37.4242
718.679	39.3583
722.102	39.6373
725.522	41.6816
728.943	44.8423
732.361	46.8382
735.779	46.6642
739.194	48.532
742.608	47.9632
746.022	46.607
749.433	47.6155
752.843	47.616
756.254	48.997
759.661	48.5247
763.067	48.5004
766.471	50.9634
769.877	51.079
773.279	51.2249
776.68	52.6089
780.079	53.051
783.478	52.8431
786.875	54.311
790.27	54.0625
793.665	55.2529
797.058	56.4097
800.45	57.829
803.84	58.8515
807.23	59.1717
810.616	61.3654
814.002	61.6218
817.388	61.6918
820.772	61.7809
824.153	60.4926
827.535	58.2241
830.915	54.8327
834.292	53.4833
837.67	52.6719
841.047	50.417
844.42	48.1147
847.794	47.1277
851.165	47.0918
854.534	44.7953
857.905	44.0038
861.272	43.056
864.639	41.345
868.004	41.6096
871.367	42.4822
874.731	41.1569
878.092	41.8832
881.451	42.7368
884.809	42.2932
888.166	41.9524
891.522	42.9271
894.878	44.6246
898.231	42.9942
901.583	43.0301
904.934	42.9562
908.283	41.0946
911.631	39.8364
914.976	40.1368
918.322	39.9631
921.666	39.0021
925.009	38.1266
928.351	37.7504
931.692	38.4159
935.029	38.2536
938.367	37.8986
941.704	38.9578
945.038	37.502
948.372	36.758
951.705	35.2155
955.035	33.2163
958.366	30.541
961.693	30.886
965.021	27.5269
968.346	27.127
971.67	26.644
974.995	25.7622
978.316	24.8232
981.638	22.3449
984.957	23.6889
988.274	22.7204
991.59	21.8819
994.907	19.6324
998.221	14.8653
1001.53	12.7755
1004.85	11.6046
1008.16	14.4252
1011.46	25.2648
1014.77	40.6814
1018.08	57.2381
1021.38	72.0681
1024.69	87.0847
1027.99	99.2323
1031.29	110.261
1034.59	118.34
1037.89	124.861
1041.19	130.571
1044.48	133.585
1047.78	133.155
1051.07	131.862
1054.36	127.086
1057.66	119.261
1060.94	109.606
1064.23	98.1082
1067.52	84.006
1070.81	67.6884
1074.09	50.8185
1077.38	34.2703
1080.66	19.7238
1083.94	9.90829
1087.22	6.99409
1090.5	9.6008
1093.77	14.6185
1097.05	18.761
1100.32	18.5871
1103.6	20.0987
1106.87	23.2928
1110.14	23.2453
1113.41	24.3072
1116.67	24.5544
1119.94	25.1649
1123.21	25.8364
1126.47	25.5169
1129.73	25.5195
1133	25.2269
1136.26	22.2256
1139.52	20.7913
1142.77	17.7669
1146.03	15.2966
1149.29	13.3283
1152.54	10.1503
1155.79	9.2867
1159.04	6.4891
1162.3	6.4532
1165.55	6.55665
1168.79	7.86359
1172.04	9.73164
1175.28	9.61799
1178.53	8.83934
1181.77	9.23776
1185.01	11.3456
1188.25	12.9535
1191.49	14.1002
1194.73	15.0857
1197.97	15.6972
1201.2	16.3402
1204.44	17.2042
1207.67	17.89
1210.9	17.297
1214.13	17.6468
1217.36	18.3358
1220.59	18.7199
1223.82	19.2862
1227.04	20.3971
1230.26	21.4476
1233.49	24.0282
1236.71	27.8609
1239.93	30.8402
1243.15	32.9107
1246.37	33.4754
1249.58	35.2151
1252.8	37.6998
1256.01	38.3807
1259.23	41.7294
1262.44	44.8142
1265.65	50.0769
1268.86	52.6782
1272.07	55.1269
1275.27	57.1454
1278.48	59.6345
1281.68	62.1571
1284.89	63.1916
1288.09	63.8215
1291.29	64.2385
1294.49	65.1937
1297.69	64.1416
1300.88	63.8697
1304.08	64.0936
1307.27	63.9374
1310.47	64.1117
1313.66	64.2702
1316.85	63.1204
1320.04	60.5724
1323.23	58.1787
1326.41	57.5216
1329.6	56.5697
1332.78	56.2313
1335.97	55.4548
1339.15	54.5182
1342.33	55.7321
1345.51	54.7489
1348.69	53.2161
1351.87	53.1274
1355.04	53.0679
1358.22	52.6473
1361.39	50.4698
1364.57	48.2824
1367.74	45.8153
1370.91	43.3345
1374.07	40.757
1377.24	39.8934
1380.41	39.2477
1383.57	38.8846
1386.74	39.4398
1389.9	39.0302
1393.06	39.2592
1396.22	39.6356
1399.38	40.2666
1402.54	42.1892
1405.7	42.9882
1408.85	46.9236
1412.01	48.5594
1415.16	52.2882
1418.31	56.1073
1421.46	60.9831
1424.61	64.514
1427.76	69.1168
1430.91	72.5921
1434.05	76.9078
1437.2	81.2131
1440.34	83.2696
1443.49	85.113
1446.63	85.3321
1449.77	84.6934
1452.91	85.7631
1456.04	83.7406
1459.18	82.8031
1462.31	81.3346
1465.45	78.59
1468.58	77.391
1471.71	76.5668
1474.84	74.1347
1477.97	70.0513
1481.1	68.5183
1484.23	65.2711
1487.35	63.1756
1490.48	57.5279
1493.6	53.9085
1496.72	50.6942
1499.84	47.0088
1502.96	42.8425
1506.08	41.5572
1509.2	39.7074
1512.31	37.6529
1515.43	34.6024
1518.54	31.5682
1521.66	29.94
1524.77	27.8153
1527.88	27.1063
1530.99	27.6164
1534.09	26.4288
1537.2	27.3357
1540.31	28.8979
1543.41	30.4218
1546.51	32.211
1549.62	33.3053
1552.72	33.2315
1555.82	33.037
1558.91	33.6899
1562.01	33.2789
1565.11	33.4153
1568.2	33.7679
1571.3	33.6509
1574.39	33.6964
1577.48	35.2227
1580.57	37.154
1583.66	37.3298
1586.75	38.5865
1589.83	41.0107
1592.92	41.6763
1596	43.6033
1599.09	44.74
1602.17	45.9933
1605.25	46.7474
1608.33	45.8023
1611.41	44.8306
1614.48	45.1839
1617.56	45.5874
1620.64	44.6177
1623.71	44.6712
1626.78	43.8362
1629.86	44.7954
1632.92	45.521
1635.99	47.0105
1639.06	48.0312
1642.13	49.6585
1645.19	49.4675
1648.26	49.7797
1651.32	51.2976
1654.38	51.6556
1657.45	52.3388
1660.51	51.7944
1663.57	51.4323
1666.62	49.5273
1669.68	45.925
1672.73	43.3018
1675.79	38.313
1678.84	34.2658
1681.89	30.9422
1684.94	28.9413
1687.99	24.9901
1691.04	21.3934
1694.09	18.3556
1697.14	14.0022
1700.18	13.0985
1703.22	12.1209
1706.27	12.2174
1709.31	10.7992
1712.35	9.84544
1715.39	8.17583
1718.43	8.26674
1721.46	8.43449
1724.5	8.91777
1727.53	9.81293
1730.57	10.0044
1733.6	9.26855
1736.63	8.96228
1739.66	5.11225
1742.69	4.61895
1745.72	5.5299
1748.74	5.88735
1751.77	6.30662
1754.8	6.89187
1757.82	8.00137
1760.84	7.24221
1763.86	7.37738
1766.88	7.60381
1769.9	7.18541
1772.92	7.62423
1775.93	6.68138
1778.95	6.05243
1781.96	5.48145
1784.98	5.315
1787.99	6.07431
1791	5.54329
1794.01	7.11003
1797.02	7.41051
1800.03	7.71375
1803.03	7.13619
1806.04	6.85968
1809.04	5.31676
1812.04	5.32869
1815.05	4.61582
1818.05	6.77338
1821.05	6.93739
1824.05	6.40116
1827.04	6.70251
1830.04	6.75139
1833.03	7.55826
1836.03	6.50751
1839.02	6.26383
1842.01	5.20826
1845	4.65977
1847.99	3.47768
1850.98	4.06529
1853.97	4.34238
1856.95	4.56471
1859.94	4.70942
1862.92	5.80551
1865.91	6.10233
1868.89	6.72757
1871.87	6.31987
1874.85	7.21919
1877.83	7.46895
1880.8	7.22957
1882.56	7.3285
1885.54	7.77276
1888.53	8.17844
1891.52	8.068
1894.5	7.61999
1897.49	6.29001
1900.47	6.45852
1903.45	5.29445
1906.43	5.20739
1909.41	4.78045
1912.39	4.09916
1915.37	3.7749
1918.35	2.83591
1921.32	2.66948
1924.3	3.39995
1927.27	3.54168
1930.24	2.46297
1933.21	2.52482
1936.18	1.69624
1939.15	1.60894
1942.12	2.27832
1945.09	3.77631
1948.05	4.25891
1951.02	4.69599
1953.98	5.02421
1956.94	5.28386
1959.91	4.30835
1962.87	5.43707
1965.82	4.53319
1968.78	3.53033
1971.74	4.14561
1974.7	3.61779
1977.65	2.08566
1980.6	2.05757
1983.56	1.12648
1986.51	0.950975
1989.46	1.39923
1992.41	0.646443
1995.36	0.840443
1998.3	1.20388
2001.25	0.417412
2004.2	0.697853
2007.14	0.824401
2010.08	2.21668
2013.02	2.42893
2015.97	3.78602
2018.9	4.87296
2021.84	4.33393
2024.78	4.55152
2027.72	4.90258
2030.65	5.72603
2033.59	6.73788
2036.52	7.62439
2039.45	8.34595
2042.38	8.61551
2045.31	9.46746
2048.24	9.54662
2051.17	10.2469
2054.1	11.6974
2057.02	10.9526
2059.95	11.7722
2062.87	13.0849
2065.79	12.7672
2068.71	14.9131
2071.63	15.779
2074.55	16.559
2077.47	17.4157
2080.39	15.9157
2083.3	17.8423
2086.22	18.9705
2089.13	21.4735
2092.05	21.3473
2094.96	22.8883
2097.87	26.0889
2100.78	26.6721
2103.69	27.9464
2106.59	29.2424
2109.5	31.1186
2112.41	32.1766
2115.31	33.8068
2118.21	36.5547
2121.12	37.5793
2124.02	40.8079
2126.92	43.3742
2129.82	45.4942
2132.71	48.3134
2135.61	51.2576
2138.51	54.8872
2141.4	57.1752
2144.29	59.0107
2147.19	62.4032
2150.08	64.3472
2152.97	67.6878
2155.86	71.9173
2158.75	74.5137
2161.64	76.3891
2164.52	78.8671
2167.41	81.603
2170.29	80.719
2173.17	79.8397
2176.06	80.1191
2178.94	79.7483
2181.82	78.4692
2184.7	78.3666
2187.57	75.8515
2190.45	74.3477
2193.33	72.9602
2196.2	71.6064
2199.08	68.6619
2201.95	64.6941
2204.82	63.9159
2207.69	61.4094
2210.56	58.8743
2213.43	56.0569
2216.3	53.8956
2219.16	52.084
2222.03	50.2459
2224.89	48.7572
2227.75	48.0157
2230.62	45.868
2233.48	43.1422
2236.34	40.9158
2239.2	38.5549
2242.06	37.3971
2244.91	36.5809
2247.77	34.4893
2250.62	31.5706
2253.48	31.1556
2256.33	29.2334
2259.18	27.1028
2262.03	27.1831
2264.88	27.4592
2267.73	27.6029
2270.58	26.7598
2273.43	26.0796
2276.27	24.4515
2279.12	21.9337
2281.96	20.6718
2284.8	20.373
2287.64	20.2417
2290.49	20.2754
2293.32	17.2761
2296.16	17.0557
2299	16.3811
2301.84	16.5214
2304.67	17.8635
2307.51	18.7511
2310.34	20.6087
2313.17	20.2528
2316	20.2144
2318.83	19.0844
2321.66	19.323
2324.49	18.842
2327.32	17.6754
2330.15	18.1
2332.97	16.9033
2335.79	16.0142
2338.62	13.2375
2341.44	11.1002
2344.26	8.72492
2347.08	7.5075
2349.9	6.62395
2352.72	6.49626
2355.53	5.66053
2358.35	4.82095
2361.17	3.80938
2363.98	4.0536
2366.79	6.69601
2369.6	8.12865
2372.42	9.1406
2375.22	10.3961
2378.03	12.7159
2380.84	12.1542
2383.65	12.8394
2386.45	13.6019
2389.26	13.5537
2392.06	13.5555
2394.87	12.151
2397.67	12.0803
2400.47	11.3203
2403.27	10.9525
2406.07	10.8851
2408.86	10.482
2411.66	11.3876
2414.46	12.1695
2417.25	11.1286
2420.05	11.2855
2422.84	11.0746
2425.63	11.3206
2428.42	10.1559
2431.21	10.3924
2434	9.49306
2436.79	9.15035
2439.57	8.06462
2442.36	9.40854
2445.14	10.174
2447.93	9.0289
2450.71	8.64123
2453.49	7.56037
2456.27	6.70013
2459.05	5.94883
2461.83	5.69785
2464.61	5.03583
2467.39	4.83255
2470.16	4.85472
2472.94	5.33902
2475.71	5.85388
2478.48	7.49649
2481.25	8.67225
2484.02	9.20932
2486.8	8.03143
2489.56	8.02454
2492.33	7.69265
2495.1	7.86986
2497.86	6.89461
2500.63	7.58032
2503.39	8.22597
2506.16	8.62637
2508.92	9.38127
2511.68	9.23094
2514.44	7.07475
2517.2	6.8418
2519.95	7.54589
2522.71	7.12101
2525.47	6.90643
2528.22	6.31837
2530.98	5.4851
2533.73	5.2752
2536.48	6.16106
2539.23	6.76072
2541.98	7.7149
2544.73	7.90404
2547.48	8.55498
2550.23	7.53782
2552.97	6.90539
2555.72	6.69604
2558.46	7.40388
2561.2	5.99304
2563.95	6.16285
2566.69	7.18154
2569.43	8.29782
2572.17	8.33612
2574.91	7.14248
2577.64	7.89047
2580.38	7.01225
2583.11	7.36792
2585.85	6.1128
2588.58	4.91976
2591.31	3.28009
2594.04	2.27665
2596.78	1.92386
2599.51	2.60808
2602.23	2.26999
2604.96	3.54543
2607.69	4.0964
2610.41	4.33585
2613.14	4.48547
2615.86	4.54652
2618.58	5.90688
2621.3	7.51393
2624.03	7.33386
2626.75	7.49185
2629.46	8.32489
2632.18	9.62924
2634.9	10.6139
2637.61	10.6088
2640.33	10.678
2643.04	11.269
2645.76	11.0555
2648.47	10.1177
2651.18	9.67485
2653.89	9.24875
2656.6	9.94563
2659.31	9.20762
2662.01	9.91551
2664.72	9.62038
2667.43	9.296
2670.13	10.2201
2672.83	10.3023
2675.53	9.18865
2678.24	10.0127
2680.94	8.987
2683.64	8.87265
2686.34	9.48112
2689.03	8.46323
2691.73	8.10353
2694.43	8.03926
2697.12	8.96329
2699.81	8.85125
2702.51	8.75681
2705.2	8.6556
2707.89	8.15927
2710.58	8.09751
2713.27	8.07085
2715.96	9.51931
2718.64	9.34056
2721.33	9.55869
2724.01	9.1674
2726.7	8.09784
2729.38	8.93158
2732.06	7.68456
2734.75	7.2039
2737.43	6.29843
2740.11	5.39699
2742.78	4.45531
2745.46	3.29571
2748.14	3.20179
2750.81	2.768
2753.49	2.18377
2756.16	1.50447
2758.84	2.02035
2761.51	1.65505
2764.18	1.40195
2766.85	0.607588
2769.52	-0.367349
2772.19	-0.995991
2774.85	-0.759688
2777.52	-0.0415772
2780.18	-0.203643
2782.85	-0.466518
2785.51	0.449287
2788.17	0.181352
2790.84	-0.0792991
2793.5	1.13127
2796.16	1.22239
2798.81	-0.0248175
2801.47	-0.924371
2804.13	-1.5952
2806.79	-2.19705
2809.44	-2.14723
2812.09	-1.88889
2814.75	-0.834588
2817.4	1.21483
2820.05	3.54841
2822.7	6.92724
2825.35	10.079
2828	13.6604
2830.65	18.2104
2833.29	23.2681
2835.94	27.6895
2838.58	31.801
2841.23	37.6157
2843.87	42.4119
2846.51	49.3145
2849.15	55.2581
2851.79	60.7438
2854.43	67.0459
2857.07	72.5298
2859.71	76.9623
2862.34	82.3974
2864.98	85.9673
2867.61	89.504
2870.25	93.57
2872.88	96.4957
2875.51	99.7184
2878.14	102.804
2880.77	104.824
2883.4	108.501
2886.03	111.54
2888.65	113.969
2891.28	115.086
2893.91	118.473
2896.53	120.751
2899.15	122.941
2901.78	126.309
2904.4	130.644
2907.02	136.809
2909.64	144.022
2912.26	150.818
2914.87	158.438
2917.49	166.906
2920.11	173.335
2922.72	178.49
2925.34	184.583
2927.95	187.336
2930.56	189.032
2933.17	191.562
2935.78	191.517
2938.39	191.49
2941	188.965
2943.61	185.591
2946.22	183.304
2948.82	178.387
2951.43	170.456
2954.03	163.205
2956.64	155.2
2959.24	146.482
2961.84	139.443
2964.44	130.938
2967.04	123.558
2969.64	115.609
2972.24	108.055
2974.83	101.518
2977.43	93.9929
2980.02	87.4437
2982.62	78.7158
2985.21	70.8687
2987.8	63.1421
2990.4	55.3449
2992.99	49.0568
2995.57	43.5747
2998.16	38.003
3000.75	32.6165
3003.34	28.9059
3005.92	24.8291
3008.51	20.8506
3011.09	18.3042
3013.68	14.482
3016.26	11.6932
3018.84	9.42834
3021.42	8.21658
3024	6.66719
3026.58	4.97336
3029.16	3.47267
3031.73	2.47213
3034.31	1.94416
3036.89	3.00008
3039.46	2.5681
3042.03	1.42092
3044.61	1.04251
3047.18	1.32966
3049.75	1.53999
3052.32	2.04501
3054.89	1.65327
3057.45	2.25302
3060.02	1.82428
3062.59	2.8895
3065.15	3.24295
3067.72	2.62703
3070.28	2.61061
3072.84	1.89396
3075.41	2.3316
3077.97	1.98663
3080.53	2.09142
3083.09	2.88732
3085.64	2.41439
3088.2	2.31067
3090.76	2.15322
3093.31	2.51442
3095.87	3.37593
3098.42	4.35731
3100.97	5.11825
3103.53	4.68962
3106.08	5.13102
3108.63	6.64691
3111.18	8.04792
3113.73	8.86611
3116.27	10.2898
3118.82	11.2009
3121.37	11.896
3123.91	13.681
3126.45	13.4816
3129	13.7203
3131.54	14.4631
3134.08	16.0849
3136.62	17.3619
3139.16	19.1992
3141.7	20.4383
3144.24	21.9211
3146.78	22.7992
3149.31	25.3701