File: data/Raman/poly_smoothed/Mb_40_y_45_1x_45s_532 nm_x100_100%_600 gr_mm_01.txt
#Acq. time (s)=	45
#Accumulations=	2
#Range (cm-¹)=	200...3150
#Windows=	2
#Auto scanning=	Off
#Autofocus=	Off
#Macrospot=	Off
#AutoExposure=	Off
#Spike filter=	Multiple accum.
#Delay time (s)=	0
#Binning=	1
#Readout mode=	Signal
#DeNoise=	Off
#ICS correction=	On
#Dark correction=	Off
#Inst. Process=	Off
#Detector Gain=	Best Dynamic Range
#Detector ADC=	20 kHz
#Detector temperature (°C)=	-69.85
#Instrument=	LabRAM HR Evol
#Detector=	Synapse
#Objective=	x100
#Grating=	600 gr/mm
#ND Filter=	100%
#Laser (nm)=	532
#Hole=	100.021
#Range=	Auto
#Laser Pol.=	No
#Raman. Pol.=	No
#Laser Pol. (°)=	-0.0007625
#Raman Pol. (°)=	89.9995
#Collection=	Microscope
#StageXY=	Marzhauser
#StageZ=	Marzhauser
#X (µm)=	-1149.3
#Y (µm)=	672.7
#Z (µm)=	584.4
#Full time(mm:ss)=	3:18
#Project=
#Sample=
#Site=
#Title=	Mb_40_y_45_2x_45s_532 nm_x100_100%_600 gr_mm
#Remark=
#Date=	19.07.2022 13:14
#Acquired=	19.07.2022 13:14:16
#Edit:Spike=	19.07.2022 13:18:17
#Edit:Spike=	19.07.2022 13:18:18
#Base:Fit=	10.08.2022 10:52:48
#Base:Sub=	10.08.2022 10:52:53
#Filter:Polynom=	16.08.2022 10:09:04
#AxisType[0]=Intens
#AxisUnit[0]=Cnt
#AxisType[1]=Spectr
#AxisUnit[1]=1/cm
200.423	17.4873
204.052	17.4147
207.682	18.0157
211.308	18.7061
214.935	17.8926
218.558	18.3904
222.18	18.3602
225.802	17.675
229.421	15.5844
233.039	14.2373
236.657	13.1125
240.272	11.5915
243.885	9.28248
247.497	9.4989
251.11	7.20989
254.719	6.81953
258.327	7.54087
261.933	5.78968
265.538	5.63315
269.141	5.45555
272.744	4.90321
276.344	4.54807
279.944	5.57326
283.542	8.44882
287.138	8.82692
290.733	10.2533
294.327	13.5371
297.919	14.9524
301.508	15.1563
305.098	16.3495
308.686	17.7954
312.273	19.4237
315.858	19.5986
319.44	18.7641
323.022	19.4236
326.604	17.9114
330.181	17.9784
333.76	16.5194
337.335	15.853
340.91	14.7081
344.483	15.6823
348.055	13.1432
351.625	12.0199
355.195	9.81683
358.762	8.98533
362.329	7.12694
365.893	7.31878
369.455	6.50285
373.017	6.01699
376.578	7.04034
380.137	7.79787
383.694	7.48253
387.249	6.28562
390.806	6.33927
394.359	6.75138
397.91	9.57511
401.46	8.84744
405.009	8.34084
408.557	7.23135
412.103	7.94411
415.647	7.51218
419.191	7.49754
422.733	5.71333
426.273	5.06618
429.812	6.24258
433.35	5.43803
436.885	6.10021
440.42	3.8448
443.954	3.22528
447.486	2.57621
451.015	1.4794
454.545	2.3819
458.073	2.52241
461.598	3.14358
465.124	4.10352
468.648	3.84124
472.169	3.24936
475.69	2.65086
479.208	5.40443
482.727	5.52806
486.243	5.67337
489.759	7.4623
493.272	7.96532
496.783	7.84631
500.295	8.91738
503.804	7.77842
507.311	7.18726
510.819	6.24387
514.324	7.89483
517.827	9.3131
521.329	9.30979
524.83	9.01298
528.329	9.55377
531.829	9.32784
535.326	10.3447
538.821	10.4941
542.315	8.90389
545.808	9.06857
549.299	10.4909
552.789	9.58799
556.278	7.61034
559.763	8.85867
563.249	8.4546
566.733	7.79964
570.217	5.99043
573.699	5.62208
577.177	5.81183
580.656	4.42173
584.134	4.59606
587.609	3.34395
591.084	2.62275
594.558	2.4144
598.029	2.33716
601.5	3.47714
604.968	4.36069
608.437	3.99071
611.902	4.61517
615.368	5.25928
618.831	5.11723
622.294	3.32861
625.755	3.30646
629.213	2.80826
632.673	4.58902
636.129	4.81746
639.584	5.6438
643.037	5.40705
646.491	6.10827
649.942	6.02286
653.392	6.84728
656.84	5.60363
660.287	7.3574
663.732	10.2829
667.177	10.6077
670.62	9.23787
674.061	9.97109
677.502	11.1269
680.941	10.8722
684.379	12.9569
687.815	14.5047
691.248	15.7529
694.682	16.2281
698.115	16.8685
701.546	18.3622
704.974	19.2948
708.402	21.4782
711.83	22.5694
715.254	24.8932
718.679	26.6503
722.102	27.4089
725.522	27.7968
728.943	29.7254
732.361	31.0918
735.779	32.2918
739.194	34.5874
742.608	36.5899
746.022	38.5125
749.433	41.0498
752.843	41.941
756.254	44.459
759.661	46.1214
763.067	47.6286
766.471	51.7365
769.877	53.6871
773.279	55.1671
776.68	56.5893
780.079	58.9099
783.478	62.4108
786.875	63.8854
790.27	64.3052
793.665	66.429
797.058	67.0501
800.45	66.3579
803.84	66.1489
807.23	65.6116
810.616	65.321
814.002	64.2679
817.388	63.1242
820.772	60.9999
824.153	59.0036
827.535	56.7827
830.915	55.676
834.292	54.5753
837.67	52.9102
841.047	50.9162
844.42	49.8045
847.794	49.2365
851.165	48.1904
854.534	48.1287
857.905	47.7597
861.272	48.4629
864.639	47.6082
868.004	46.5133
871.367	47.7402
874.731	48.1408
878.092	47.6976
881.451	46.2765
884.809	46.6121
888.166	45.4902
891.522	45.195
894.878	44.411
898.231	42.2187
901.583	39.5619
904.934	38.2868
908.283	37.1437
911.631	37.4961
914.976	38.3674
918.322	38.0706
921.666	38.349
925.009	37.8409
928.351	39.2067
931.692	39.8496
935.029	40.4383
938.367	40.1453
941.704	38.1381
945.038	36.4096
948.372	35.9484
951.705	36.5657
955.035	36.515
958.366	34.2996
961.693	32.4201
965.021	31.347
968.346	30.6803
971.67	29.3486
974.995	28.9987
978.316	26.9015
981.638	23.8235
984.957	23.116
988.274	20.9508
991.59	17.9968
994.907	13.6275
998.221	8.85338
1001.53	3.82377
1004.85	4.05983
1008.16	9.35966
1011.46	20.0807
1014.77	34.2098
1018.08	50.2447
1021.38	65.5906
1024.69	80.6871
1027.99	95.4147
1031.29	107.629
1034.59	116.738
1037.89	123.114
1041.19	126.751
1044.48	132.152
1047.78	131.555
1051.07	129.768
1054.36	124.068
1057.66	115.894
1060.94	104.438
1064.23	90.3151
1067.52	74.8255
1070.81	57.3306
1074.09	39.881
1077.38	25.0301
1080.66	13.2842
1083.94	6.50461
1087.22	5.63917
1090.5	8.7598
1093.77	11.5471
1097.05	15.366
1100.32	17.3318
1103.6	18.9059
1106.87	20.2994
1110.14	20.3846
1113.41	21.4023
1116.67	20.6296
1119.94	19.1975
1123.21	18.9189
1126.47	18.6034
1129.73	16.4606
1133	14.7774
1136.26	12.5073
1139.52	10.7761
1142.77	9.23694
1146.03	8.50043
1149.29	7.31488
1152.54	6.77278
1155.79	8.26081
1159.04	8.68731
1162.3	7.74153
1165.55	7.27612
1168.79	7.79191
1172.04	9.01089
1175.28	9.98934
1178.53	11.0267
1181.77	11.8103
1185.01	12.0071
1188.25	12.8044
1191.49	12.0315
1194.73	11.3095
1197.97	10.8227
1201.2	13.4959
1204.44	15.9959
1207.67	15.8869
1210.9	17.2837
1214.13	19.0126
1217.36	20.2671
1220.59	22.2583
1223.82	23.8437
1227.04	26.117
1230.26	29.2967
1233.49	30.2824
1236.71	29.841
1239.93	31.5448
1243.15	32.9513
1246.37	34.4261
1249.58	35.0709
1252.8	36.3127
1256.01	38.025
1259.23	38.567
1262.44	38.0217
1265.65	39.2716
1268.86	39.7597
1272.07	41.4507
1275.27	43.3836
1278.48	47.4462
1281.68	50.3668
1284.89	51.2869
1288.09	51.6155
1291.29	52.5662
1294.49	52.9752
1297.69	53.6275
1300.88	54.517
1304.08	53.7747
1307.27	51.5935
1310.47	50.3865
1313.66	48.9975
1316.85	48.5028
1320.04	48.8611
1323.23	47.0988
1326.41	45.6544
1329.6	45.6587
1332.78	46.5879
1335.97	47.1105
1339.15	46.5492
1342.33	47.2225
1345.51	46.8091
1348.69	48.1382
1351.87	49.4053
1355.04	49.2785
1358.22	49.69
1361.39	46.3073
1364.57	44.8097
1367.74	44.5466
1370.91	42.9959
1374.07	41.8659
1377.24	40.1309
1380.41	38.5503
1383.57	37.1913
1386.74	37.6756
1389.9	37.4569
1393.06	36.5181
1396.22	35.5723
1399.38	36.1686
1402.54	36.8541
1405.7	38.0871
1408.85	41.9009
1412.01	42.9906
1415.16	47.4581
1418.31	49.939
1421.46	53.5608
1424.61	57.2806
1427.76	60.9275
1430.91	64.7666
1434.05	67.5784
1437.2	71.6225
1440.34	74.3696
1443.49	76.7659
1446.63	78.5382
1449.77	80.4314
1452.91	80.9651
1456.04	81.9129
1459.18	82.7974
1462.31	83.2566
1465.45	82.3891
1468.58	82.1255
1471.71	79.5159
1474.84	77.1494
1477.97	75.26
1481.1	71.3753
1484.23	68.1468
1487.35	63.554
1490.48	61.4305
1493.6	59.943
1496.72	57.4493
1499.84	55.1171
1502.96	52.9232
1506.08	50.7732
1509.2	47.9257
1512.31	45.4352
1515.43	42.5908
1518.54	40.3625
1521.66	37.5777
1524.77	36.811
1527.88	33.9743
1530.99	32.1757
1534.09	31.7355
1537.2	32.9177
1540.31	33.0752
1543.41	32.709
1546.51	32.2838
1549.62	31.3979
1552.72	30.2997
1555.82	29.1835
1558.91	27.7397
1562.01	27.5186
1565.11	29.3938
1568.2	33.9163
1571.3	34.8988
1574.39	36.601
1577.48	36.5814
1580.57	38.2515
1583.66	39.8082
1586.75	41.2408
1589.83	41.2476
1592.92	43.8638
1596	45.609
1599.09	44.2337
1602.17	44.8146
1605.25	45.1554
1608.33	45.6703
1611.41	46.1823
1614.48	45.6558
1617.56	45.3446
1620.64	45.5077
1623.71	44.7625
1626.78	44.1092
1629.86	43.7341
1632.92	42.8584
1635.99	42.1056
1639.06	43.1457
1642.13	44.6606
1645.19	46.1747
1648.26	46.2719
1651.32	46.6599
1654.38	45.7804
1657.45	45.5073
1660.51	45.4184
1663.57	44.6094
1666.62	43.3934
1669.68	41.2971
1672.73	38.7302
1675.79	36.5966
1678.84	35.5621
1681.89	32.9875
1684.94	30.4289
1687.99	27.7429
1691.04	25.6051
1694.09	23.7577
1697.14	22.8416
1700.18	19.9943
1703.22	18.8609
1706.27	17.0558
1709.31	14.7218
1712.35	14.3176
1715.39	15.3006
1718.43	14.7934
1721.46	13.3714
1724.5	12.6577
1727.53	11.0394
1730.57	9.96169
1733.6	8.73839
1736.63	7.59202
1739.66	7.34968
1742.69	7.26638
1745.72	7.04721
1748.74	6.96374
1751.77	6.8404
1754.8	6.6446
1757.82	6.27427
1760.84	6.03388
1763.86	5.36919
1766.88	4.83084
1769.9	4.78929
1772.92	6.15055
1775.93	7.04889
1778.95	7.48603
1781.96	8.28191
1784.98	9.29237
1787.99	10.2254
1791	9.51304
1794.01	8.9588
1797.02	8.91177
1800.03	7.41889
1803.03	6.63483
1806.04	6.26628
1809.04	6.47551
1812.04	5.88209
1815.05	5.19225
1818.05	4.21324
1821.05	3.16313
1824.05	3.37728
1827.04	2.46985
1830.04	2.7001
1833.03	2.96457
1836.03	1.78883
1839.02	2.2365
1842.01	3.23655
1845	3.76469
1847.99	4.32428
1850.98	4.75066
1853.97	5.54649
1856.95	6.15244
1859.94	7.111
1862.92	7.48375
1865.91	7.70017
1868.89	9.17427
1871.87	8.85686
1874.85	8.02236
1877.83	8.88319
1880.8	8.9063
1882.56	8.40748
1885.54	6.78645
1888.53	6.77783
1891.52	5.77885
1894.5	5.68301
1897.49	3.63268
1900.47	3.66031
1903.45	3.97986
1906.43	2.60576
1909.41	2.27398
1912.39	1.82894
1915.37	1.67555
1918.35	1.0725
1921.32	0.362215
1924.3	-0.259525
1927.27	0.534228
1930.24	-0.32541
1933.21	-0.93297
1936.18	-1.05784
1939.15	0.41329
1942.12	1.3599
1945.09	0.691338
1948.05	2.62651
1951.02	4.20029
1953.98	3.59533
1956.94	3.38724
1959.91	3.12121
1962.87	2.97819
1965.82	3.54184
1968.78	3.54903
1971.74	3.10359
1974.7	4.31433
1977.65	5.32876
1980.6	5.22611
1983.56	5.19425
1986.51	6.98415
1989.46	6.5887
1992.41	5.02684
1995.36	4.49708
1998.3	3.97019
2001.25	4.07288
2004.2	3.69934
2007.14	4.38699
2010.08	5.75969
2013.02	6.24429
2015.97	6.43779
2018.9	7.45505
2021.84	7.736
2024.78	7.97761
2027.72	8.06471
2030.65	9.2859
2033.59	8.92014
2036.52	10.1493
2039.45	10.9923
2042.38	11.133
2045.31	12.8489
2048.24	12.8426
2051.17	13.7196
2054.1	13.5811
2057.02	13.3571
2059.95	13.7364
2062.87	14.2545
2065.79	13.8828
2068.71	12.6921
2071.63	11.4629
2074.55	11.0089
2077.47	10.8247
2080.39	10.849
2083.3	11.8465
2086.22	11.9959
2089.13	13.005
2092.05	13.5757
2094.96	14.1931
2097.87	15.5767
2100.78	17.3645
2103.69	18.8377
2106.59	18.8521
2109.5	19.484
2112.41	20.6302
2115.31	20.5769
2118.21	21.6346
2121.12	22.6593
2124.02	23.6292
2126.92	23.7265
2129.82	22.9722
2132.71	24.586
2135.61	24.5765
2138.51	23.7889
2141.4	24.719
2144.29	26.9909
2147.19	28.6343
2150.08	30.4954
2152.97	33.3703
2155.86	34.2166
2158.75	36.5312
2161.64	38.3157
2164.52	40.7686
2167.41	42.9973
2170.29	45.4884
2173.17	46.3581
2176.06	46.0968
2178.94	45.1907
2181.82	44.6271
2184.7	43.9213
2187.57	43.365
2190.45	42.9326
2193.33	40.7099
2196.2	39.3423
2199.08	36.498
2201.95	34.3818
2204.82	33.1036
2207.69	31.5067
2210.56	30.0315
2213.43	30.1997
2216.3	27.4804
2219.16	27.0479
2222.03	25.068
2224.89	24.3154
2227.75	23.5872
2230.62	23.0604
2233.48	23.3475
2236.34	23.0037
2239.2	22.4
2242.06	21.8107
2244.91	20.6627
2247.77	19.0123
2250.62	17.4711
2253.48	15.3755
2256.33	13.8186
2259.18	13.3565
2262.03	11.4083
2264.88	9.78235
2267.73	8.53588
2270.58	6.90978
2273.43	6.09033
2276.27	6.81349
2279.12	6.56795
2281.96	6.82794
2284.8	6.08173
2287.64	5.61792
2290.49	5.28253
2293.32	4.63705
2296.16	5.5552
2299	7.38496
2301.84	8.8021
2304.67	9.79451
2307.51	10.7379
2310.34	11.3874
2313.17	10.7578
2316	11.0522
2318.83	11.0843
2321.66	9.0951
2324.49	8.17246
2327.32	8.6398
2330.15	8.27867
2332.97	7.54121
2335.79	7.22444
2338.62	6.88745
2341.44	6.37252
2344.26	6.4194
2347.08	5.56116
2349.9	3.82014
2352.72	4.29322
2355.53	4.9797
2358.35	4.44569
2361.17	4.02876
2363.98	4.97794
2366.79	6.26336
2369.6	6.60067
2372.42	7.91651
2375.22	7.5377
2378.03	6.23176
2380.84	5.71851
2383.65	6.24709
2386.45	6.52677
2389.26	5.38502
2392.06	4.47567
2394.87	4.79466
2397.67	5.92085
2400.47	4.64936
2403.27	4.84261
2406.07	4.81237
2408.86	4.5639
2411.66	4.29669
2414.46	4.15114
2417.25	4.7094
2420.05	5.0388
2422.84	6.16494
2425.63	6.31932
2428.42	5.47055
2431.21	5.42242
2434	6.90194
2436.79	7.41013
2439.57	6.81637
2442.36	5.98824
2445.14	4.34261
2447.93	3.82179
2450.71	4.19165
2453.49	4.93167
2456.27	5.33927
2459.05	5.43041
2461.83	4.6841
2464.61	5.19199
2467.39	6.30297
2470.16	5.21319
2472.94	5.63828
2475.71	5.09739
2478.48	4.7268
2481.25	3.96301
2484.02	4.68698
2486.8	4.3028
2489.56	3.93384
2492.33	3.46315
2495.1	2.94349
2497.86	3.78625
2500.63	3.79385
2503.39	4.55117
2506.16	3.22253
2508.92	2.5798
2511.68	3.02799
2514.44	3.80869
2517.2	5.19455
2519.95	5.0381
2522.71	6.00337
2525.47	4.84513
2528.22	5.31974
2530.98	5.44186
2533.73	4.45818
2536.48	4.09537
2539.23	3.85293
2541.98	3.60322
2544.73	4.89189
2547.48	4.2596
2550.23	5.72389
2552.97	5.48155
2555.72	4.67802
2558.46	5.22515
2561.2	6.03805
2563.95	6.68466
2566.69	7.468
2569.43	8.14046
2572.17	8.55804
2574.91	10.1956
2577.64	10.9633
2580.38	11.3953
2583.11	10.502
2585.85	10.7516
2588.58	10.1479
2591.31	8.92669
2594.04	8.43142
2596.78	6.70136
2599.51	5.35856
2602.23	3.9132
2604.96	3.72962
2607.69	2.10749
2610.41	2.10314
2613.14	1.40348
2615.86	0.561238
2618.58	0.33324
2621.3	-0.402107
2624.03	0.515238
2626.75	0.739856
2629.46	1.27097
2632.18	2.03718
2634.9	3.31191
2637.61	4.24782
2640.33	6.60665
2643.04	7.02857
2645.76	8.20027
2648.47	8.63965
2651.18	10.7111
2653.89	11.1706
2656.6	11.4697
2659.31	12.5065
2662.01	13.2465
2664.72	12.339
2667.43	13.5896
2670.13	15.0987
2672.83	15.1815
2675.53	14.2157
2678.24	13.8439
2680.94	13.3202
2683.64	12.7176
2686.34	12.0565
2689.03	12.4975
2691.73	11.5709
2694.43	10.8552
2697.12	11.4296
2699.81	10.2722
2702.51	10.0927
2705.2	10.939
2707.89	11.4896
2710.58	11.4927
2713.27	11.3464
2715.96	10.8777
2718.64	11.7654
2721.33	12.4119
2724.01	12.0914
2726.7	12.5509
2729.38	12.0261
2732.06	12.2424
2734.75	12.7738
2737.43	12.6043
2740.11	10.9818
2742.78	10.3879
2745.46	9.51611
2748.14	8.34938
2750.81	7.64788
2753.49	7.31091
2756.16	6.53748
2758.84	6.1877
2761.51	5.47127
2764.18	4.72216
2766.85	4.25171
2769.52	4.59801
2772.19	5.07832
2774.85	5.11035
2777.52	4.43076
2780.18	4.08142
2782.85	5.29308
2785.51	5.65498
2788.17	4.93029
2790.84	5.6501
2793.5	5.75924
2796.16	6.93908
2798.81	7.65965
2801.47	8.4095
2804.13	8.16768
2806.79	7.36682
2809.44	7.3763
2812.09	7.49622
2814.75	7.9405
2817.4	9.47412
2820.05	10.2813
2822.7	11.4236
2825.35	13.8521
2828	15.0928
2830.65	16.9814
2833.29	19.8709
2835.94	23.2601
2838.58	26.5512
2841.23	29.357
2843.87	32.3797
2846.51	36.2223
2849.15	40.087
2851.79	43.1628
2854.43	48.0699
2857.07	52.8954
2859.71	56.582
2862.34	60.952
2864.98	63.961
2867.61	67.2055
2870.25	68.7723
2872.88	70.3687
2875.51	72.3024
2878.14	73.5507
2880.77	75.5439
2883.4	76.5088
2886.03	77.7232
2888.65	78.9553
2891.28	80.6993
2893.91	80.4109
2896.53	82.6169
2899.15	85.612
2901.78	88.3776
2904.4	90.3401
2907.02	93.1417
2909.64	97.0484
2912.26	100.43
2914.87	105.584
2917.49	110.094
2920.11	114.443
2922.72	117.158
2925.34	119.198
2927.95	121.101
2930.56	122.528
2933.17	122.783
2935.78	121.325
2938.39	120.202
2941	117.694
2943.61	115.15
2946.22	111.108
2948.82	107.273
2951.43	103.157
2954.03	98.8718
2956.64	93.3739
2959.24	89.3623
2961.84	84.8869
2964.44	79.7677
2967.04	75.4624
2969.64	71.6071
2972.24	68.1535
2974.83	63.7562
2977.43	59.111
2980.02	56.1236
2982.62	51.0181
2985.21	46.3813
2987.8	42.7803
2990.4	38.5426
2992.99	36.0897
2995.57	31.9489
2998.16	28.8531
3000.75	26.7256
3003.34	22.4968
3005.92	20.0011
3008.51	17.4202
3011.09	13.9687
3013.68	12.3092
3016.26	9.76476
3018.84	8.14312
3021.42	7.89601
3024	6.41217
3026.58	5.7189
3029.16	4.0997
3031.73	3.25772
3034.31	2.93661
3036.89	2.34092
3039.46	2.96774
3042.03	3.10307
3044.61	2.48374
3047.18	2.93882
3049.75	3.4193
3052.32	3.54955
3054.89	3.66357
3057.45	4.44963
3060.02	4.63037
3062.59	3.95636
3065.15	4.12329
3067.72	3.54541
3070.28	2.62605
3072.84	2.40404
3075.41	2.52252
3077.97	1.99134
3080.53	1.67914
3083.09	1.79952
3085.64	1.12658
3088.2	0.482974
3090.76	0.293912
3093.31	0.0763804
3095.87	0.852259
3098.42	2.05091
3100.97	4.69669
3103.53	4.96801
3106.08	5.58577
3108.63	6.20689
3111.18	8.21861
3113.73	9.42649
3116.27	10.2648
3118.82	11.5747
3121.37	11.9816
3123.91	12.0899
3126.45	13.1865
3129	14.5929
3131.54	15.0268
3134.08	15.2793
3136.62	15.6013
3139.16	14.4789
3141.7	14.2174
3144.24	13.7242
3146.78	12.8973
3149.31	12.4011