File: data/Raman/poly_smoothed/Mb_40_y_37_1x_45s_532 nm_x100_100%_600 gr_mm_01.txt
#Acq. time (s)=	45
#Accumulations=	2
#Range (cm-¹)=	200...3150
#Windows=	2
#Auto scanning=	Off
#Autofocus=	Off
#Macrospot=	Off
#AutoExposure=	Off
#Spike filter=	Multiple accum.
#Delay time (s)=	0
#Binning=	1
#Readout mode=	Signal
#DeNoise=	Off
#ICS correction=	On
#Dark correction=	Off
#Inst. Process=	Off
#Detector Gain=	Best Dynamic Range
#Detector ADC=	20 kHz
#Detector temperature (°C)=	-69.85
#Instrument=	LabRAM HR Evol
#Detector=	Synapse
#Objective=	x100
#Grating=	600 gr/mm
#ND Filter=	100%
#Laser (nm)=	532
#Hole=	100.021
#Range=	Auto
#Laser Pol.=	No
#Raman. Pol.=	No
#Laser Pol. (°)=	-0.0007625
#Raman Pol. (°)=	89.9995
#Collection=	Microscope
#StageXY=	Marzhauser
#StageZ=	Marzhauser
#X (µm)=	-1093
#Y (µm)=	590
#Z (µm)=	584.7
#Full time(mm:ss)=	3:18
#Project=
#Sample=
#Site=
#Title=	Mb_40_y_37_2x_45s_532 nm_x100_100%_600 gr_mm
#Remark=
#Date=	19.07.2022 12:25
#Acquired=	19.07.2022 12:25:37
#Base:Fit=	10.08.2022 10:52:48
#Base:Sub=	10.08.2022 10:52:53
#Filter:Polynom=	16.08.2022 10:09:04
#AxisType[0]=Intens
#AxisUnit[0]=Cnt
#AxisType[1]=Spectr
#AxisUnit[1]=1/cm
200.423	40.3513
204.052	35.2498
207.682	31.2462
211.308	26.1784
214.935	22.1809
218.558	19.0706
222.18	14.9051
225.802	13.1805
229.421	12.3489
233.039	10.358
236.657	10.0075
240.272	8.74753
243.885	8.51004
247.497	7.97413
251.11	8.48476
254.719	9.9703
258.327	10.4737
261.933	10.7592
265.538	10.1194
269.141	10.5529
272.744	9.49082
276.344	8.50652
279.944	9.72454
283.542	9.68156
287.138	9.80179
290.733	11.6083
294.327	10.2389
297.919	9.14043
301.508	9.99413
305.098	9.55065
308.686	8.63268
312.273	8.82361
315.858	10.4536
319.44	9.26338
323.022	11.3559
326.604	12.2277
330.181	13.5684
333.76	14.8437
337.335	14.5502
340.91	14.318
344.483	13.9262
348.055	12.508
351.625	13.1578
355.195	11.3835
358.762	10.0646
362.329	10.6196
365.893	11.2011
369.455	12.3475
373.017	10.6752
376.578	11.4806
380.137	10.2543
383.694	9.68626
387.249	8.90623
390.806	8.7607
394.359	8.75356
397.91	8.43206
401.46	9.26877
405.009	9.70782
408.557	10.5343
412.103	10.7679
415.647	11.8481
419.191	11.7635
422.733	10.5731
426.273	9.43423
429.812	9.00858
433.35	8.83704
436.885	9.12509
440.42	8.97141
443.954	7.25679
447.486	7.41866
451.015	5.72487
454.545	5.77204
458.073	5.69282
461.598	5.4071
465.124	5.78538
468.648	7.95256
472.169	9.2464
475.69	10.4976
479.208	12.3477
482.727	15.0265
486.243	17.908
489.759	20.2133
493.272	21.4984
496.783	23.8486
500.295	25.6734
503.804	27.9718
507.311	29.5368
510.819	30.1925
514.324	31.0006
517.827	29.32
521.329	29.6379
524.83	27.9976
528.329	26.1809
531.829	23.6797
535.326	22.1353
538.821	20.9541
542.315	18.6514
545.808	18.1762
549.299	16.1678
552.789	14.5107
556.278	13.8761
559.763	12.1327
563.249	11.1801
566.733	11.5256
570.217	11.4666
573.699	9.80802
577.177	9.5756
580.656	9.43873
584.134	10.5583
587.609	10.8377
591.084	11.3096
594.558	9.64453
598.029	8.84781
601.5	8.1268
604.968	7.96595
608.437	8.12667
611.902	7.64193
615.368	7.42222
618.831	5.39079
622.294	4.21882
625.755	5.11169
629.213	5.1759
632.673	6.46189
636.129	7.60569
639.584	8.27392
643.037	8.80764
646.491	9.6717
649.942	11.2692
653.392	12.8547
656.84	12.047
660.287	13.5218
663.732	14.0444
667.177	15.5914
670.62	17.2989
674.061	17.6135
677.502	17.3301
680.941	19.0053
684.379	21.4565
687.815	23.141
691.248	25.5087
694.682	26.762
698.115	28.385
701.546	29.6097
704.974	31.2041
708.402	34.4051
711.83	36.4924
715.254	38.6391
718.679	39.9276
722.102	42.6928
725.522	44.5909
728.943	45.3996
732.361	45.4869
735.779	46.9054
739.194	47.5589
742.608	47.459
746.022	48.3516
749.433	49.3965
752.843	51.2582
756.254	53.4253
759.661	55.234
763.067	56.8246
766.471	61.9223
769.877	64.0172
773.279	66.1144
776.68	67.3376
780.079	68.3779
783.478	70.6828
786.875	72.1087
790.27	73.7646
793.665	75.5674
797.058	76.8655
800.45	78.7502
803.84	79.6626
807.23	80.1038
810.616	79.9852
814.002	80.5579
817.388	79.2034
820.772	79.8735
824.153	78.7508
827.535	76.768
830.915	74.7708
834.292	74.0712
837.67	72.6138
841.047	71.2754
844.42	68.014
847.794	64.6876
851.165	61.6126
854.534	57.9275
857.905	53.9434
861.272	50.1712
864.639	47.7793
868.004	46.926
871.367	45.131
874.731	44.9508
878.092	45.0515
881.451	44.9762
884.809	46.058
888.166	45.3471
891.522	44.981
894.878	45.3627
898.231	47.0323
901.583	49.7717
904.934	51.1385
908.283	53.3773
911.631	52.5879
914.976	52.983
918.322	51.559
921.666	51.9396
925.009	51.5955
928.351	49.2345
931.692	47.1178
935.029	47.1433
938.367	45.8443
941.704	45.8126
945.038	43.9741
948.372	42.6152
951.705	41.739
955.035	40.3459
958.366	39.0016
961.693	36.1066
965.021	35.1616
968.346	33.6289
971.67	33.0337
974.995	31.8697
978.316	32.8967
981.638	32.7848
984.957	32.6261
988.274	31.4108
991.59	29.325
994.907	25.7582
998.221	23.777
1001.53	20.011
1004.85	19.6778
1008.16	22.3448
1011.46	33.9144
1014.77	51.0896
1018.08	69.5311
1021.38	88.323
1024.69	103.795
1027.99	117.36
1031.29	129.502
1034.59	139.574
1037.89	145.961
1041.19	149.561
1044.48	151.536
1047.78	151.773
1051.07	148.487
1054.36	142.518
1057.66	132.689
1060.94	123.135
1064.23	109.341
1067.52	95.2154
1070.81	78.4546
1074.09	59.0914
1077.38	43.1959
1080.66	28.3588
1083.94	17.8623
1087.22	14.3432
1090.5	17.1737
1093.77	22.9003
1097.05	26.4792
1100.32	26.316
1103.6	27.2233
1106.87	26.9091
1110.14	27.1842
1113.41	25.5622
1116.67	25.5098
1119.94	24.9709
1123.21	24.2353
1126.47	22.678
1129.73	19.8892
1133	19.5009
1136.26	16.3414
1139.52	13.6726
1142.77	12.8125
1146.03	12.4681
1149.29	10.4286
1152.54	9.09174
1155.79	6.80367
1159.04	4.78146
1162.3	5.37919
1165.55	3.11484
1168.79	3.46037
1172.04	5.30455
1175.28	5.40104
1178.53	5.10093
1181.77	5.76828
1185.01	7.31707
1188.25	9.03763
1191.49	11.0838
1194.73	11.599
1197.97	14.3173
1201.2	16.739
1204.44	18.8807
1207.67	21.7057
1210.9	23.7132
1214.13	25.0193
1217.36	26.2898
1220.59	29.7459
1223.82	33.5476
1227.04	36.659
1230.26	39.3253
1233.49	40.4319
1236.71	42.879
1239.93	46.38
1243.15	49.5656
1246.37	51.5321
1249.58	54.122
1252.8	55.1264
1256.01	55.6496
1259.23	58.1341
1262.44	60.2425
1265.65	62.2959
1268.86	65.0524
1272.07	65.3941
1275.27	67.7585
1278.48	70.6134
1281.68	72.468
1284.89	74.1871
1288.09	74.3945
1291.29	74.8372
1294.49	76.3356
1297.69	76.6988
1300.88	78.5179
1304.08	80.5655
1307.27	83.0962
1310.47	82.5858
1313.66	83.5634
1316.85	84.9769
1320.04	84.7062
1323.23	82.8315
1326.41	82.486
1329.6	81.0341
1332.78	80.1305
1335.97	79.7093
1339.15	79.2797
1342.33	76.4621
1345.51	71.8489
1348.69	69.0566
1351.87	66.4645
1355.04	62.7986
1358.22	61.4
1361.39	57.8922
1364.57	55.0559
1367.74	52.6868
1370.91	50.2033
1374.07	47.4917
1377.24	45.4549
1380.41	46.6631
1383.57	47.4177
1386.74	46.9748
1389.9	46.3442
1393.06	46.1802
1396.22	46.9178
1399.38	48.2125
1402.54	50.068
1405.7	51.9144
1408.85	54.4813
1412.01	56.4451
1415.16	59.8032
1418.31	60.9822
1421.46	63.7628
1424.61	68.0831
1427.76	73.5422
1430.91	78.3235
1434.05	83.5763
1437.2	88.4165
1440.34	91.0849
1443.49	93.6035
1446.63	93.3307
1449.77	92.3782
1452.91	91.6083
1456.04	92.1288
1459.18	91.9869
1462.31	88.9048
1465.45	85.3576
1468.58	82.3789
1471.71	78.0429
1474.84	73.9524
1477.97	68.4457
1481.1	63.1663
1484.23	60.1742
1487.35	55.8547
1490.48	52.8271
1493.6	48.8293
1496.72	45.3459
1499.84	42.8235
1502.96	41.3683
1506.08	40.2058
1509.2	38.254
1512.31	35.8511
1515.43	33.9183
1518.54	31.3552
1521.66	29.9987
1524.77	29.8963
1527.88	30.4707
1530.99	31.712
1534.09	32.6989
1537.2	33.0999
1540.31	32.6942
1543.41	34.9969
1546.51	36.4155
1549.62	37.4651
1552.72	39.9959
1555.82	42.9505
1558.91	44.9535
1562.01	45.9512
1565.11	47.9195
1568.2	48.804
1571.3	50.5883
1574.39	52.7556
1577.48	54.7272
1580.57	56.3369
1583.66	57.5557
1586.75	58.2895
1589.83	58.5855
1592.92	60.2034
1596	60.8615
1599.09	61.8566
1602.17	62.0535
1605.25	61.7667
1608.33	60.4633
1611.41	59.8339
1614.48	59.3487
1617.56	60.8694
1620.64	62.5869
1623.71	62.9574
1626.78	64.4306
1629.86	66.0884
1632.92	68.6282
1635.99	70.2936
1639.06	74.0647
1642.13	76.2897
1645.19	79.8502
1648.26	81.0696
1651.32	81.5155
1654.38	80.6662
1657.45	80.1191
1660.51	79.1904
1663.57	77.6048
1666.62	75.5016
1669.68	72.7341
1672.73	68.7534
1675.79	63.2326
1678.84	58.5962
1681.89	53.2733
1684.94	47.9165
1687.99	42.5888
1691.04	38.9866
1694.09	34.6269
1697.14	30.074
1700.18	26.6359
1703.22	24.3404
1706.27	22.5508
1709.31	21.9861
1712.35	19.7218
1715.39	16.7871
1718.43	14.3396
1721.46	12.1775
1724.5	10.8533
1727.53	10.6995
1730.57	9.64198
1733.6	10.0706
1736.63	9.9233
1739.66	9.28418
1742.69	8.79323
1745.72	8.30189
1748.74	7.18271
1751.77	6.95144
1754.8	6.6549
1757.82	6.05959
1760.84	5.3565
1763.86	5.30671
1766.88	5.35612
1769.9	5.80413
1772.92	4.8766
1775.93	6.13056
1778.95	6.73924
1781.96	6.57253
1784.98	5.93949
1787.99	4.7886
1791	3.88823
1794.01	4.52032
1797.02	5.70764
1800.03	6.64989
1803.03	6.29422
1806.04	6.70508
1809.04	7.15469
1812.04	6.60609
1815.05	6.737
1818.05	7.28272
1821.05	7.33444
1824.05	7.1524
1827.04	6.32192
1830.04	6.61028
1833.03	7.0757
1836.03	6.52127
1839.02	6.36821
1842.01	6.10708
1845	5.49027
1847.99	4.95229
1850.98	4.54587
1853.97	4.86001
1856.95	3.89762
1859.94	2.93175
1862.92	2.00717
1865.91	2.18532
1868.89	1.46702
1871.87	0.354579
1874.85	-0.0906108
1877.83	-0.335753
1880.8	0.0891989
1882.56	0.497687
1885.54	0.661484
1888.53	1.58764
1891.52	1.36402
1894.5	2.14657
1897.49	3.14712
1900.47	4.34337
1903.45	4.82127
1906.43	5.15249
1909.41	5.8796
1912.39	6.693
1915.37	7.85097
1918.35	8.43506
1921.32	9.44701
1924.3	9.3879
1927.27	10.1976
1930.24	9.45741
1933.21	9.29063
1936.18	8.22864
1939.15	7.88813
1942.12	7.20069
1945.09	7.41064
1948.05	7.67733
1951.02	6.30232
1953.98	6.58636
1956.94	5.80467
1959.91	5.29234
1962.87	4.61686
1965.82	3.77551
1968.78	4.09041
1971.74	4.35593
1974.7	4.07268
1977.65	4.26717
1980.6	5.00552
1983.56	5.12377
1986.51	5.4144
1989.46	5.28024
1992.41	5.71467
1995.36	5.8364
1998.3	4.86976
2001.25	5.02611
2004.2	5.59971
2007.14	5.44345
2010.08	4.92478
2013.02	5.7757
2015.97	5.76693
2018.9	4.9446
2021.84	4.48187
2024.78	5.59404
2027.72	6.52695
2030.65	6.49886
2033.59	5.82459
2036.52	7.59977
2039.45	9.3774
2042.38	10.9538
2045.31	13.5593
2048.24	14.309
2051.17	16.2966
2054.1	16.5157
2057.02	17.6337
2059.95	18.7125
2062.87	20.1244
2065.79	21.5437
2068.71	22.3692
2071.63	24.3075
2074.55	26.1834
2077.47	28.2205
2080.39	28.7383
2083.3	30.2902
2086.22	33.256
2089.13	34.4149
2092.05	36.6029
2094.96	39.5455
2097.87	41.8716
2100.78	44.37
2103.69	45.7931
2106.59	50.0321
2109.5	53.6539
2112.41	57.494
2115.31	60.3662
2118.21	63.6621
2121.12	68.2642
2124.02	71.2193
2126.92	75.2211
2129.82	79.9521
2132.71	84.2698
2135.61	88.7771
2138.51	93.7413
2141.4	97.2666
2144.29	101.27
2147.19	105.171
2150.08	109.104
2152.97	112.404
2155.86	115.525
2158.75	117.222
2161.64	119.352
2164.52	121.751
2167.41	121.542
2170.29	121.944
2173.17	121.431
2176.06	118.899
2178.94	117.995
2181.82	116.285
2184.7	113.49
2187.57	110.584
2190.45	108.948
2193.33	105.491
2196.2	102.166
2199.08	98.893
2201.95	94.3086
2204.82	89.9539
2207.69	86.006
2210.56	80.8934
2213.43	76.5097
2216.3	72.6923
2219.16	68.9064
2222.03	64.9241
2224.89	60.984
2227.75	56.4649
2230.62	54.0263
2233.48	50.9794
2236.34	47.0026
2239.2	43.771
2242.06	40.563
2244.91	37.7306
2247.77	35.1007
2250.62	32.6061
2253.48	31.1005
2256.33	29.0968
2259.18	27.5963
2262.03	26.3157
2264.88	24.6649
2267.73	24.3951
2270.58	22.4873
2273.43	20.9616
2276.27	20.7387
2279.12	20.3848
2281.96	20.3093
2284.8	20.0754
2287.64	19.8349
2290.49	18.7328
2293.32	16.7091
2296.16	15.7763
2299	15.3479
2301.84	15.3039
2304.67	14.1979
2307.51	13.8169
2310.34	13.4036
2313.17	13.2408
2316	12.3514
2318.83	11.436
2321.66	10.6588
2324.49	10.3816
2327.32	8.85828
2330.15	7.80381
2332.97	7.97455
2335.79	7.89385
2338.62	7.42009
2341.44	7.01041
2344.26	6.01788
2347.08	5.19018
2349.9	5.00974
2352.72	3.93535
2355.53	4.4377
2358.35	2.8356
2361.17	1.28915
2363.98	1.47512
2366.79	2.33632
2369.6	1.62621
2372.42	1.85496
2375.22	1.44143
2378.03	1.5884
2380.84	2.24537
2383.65	1.44863
2386.45	0.69806
2389.26	0.862113
2392.06	1.24433
2394.87	1.35517
2397.67	0.326545
2400.47	0.79508
2403.27	1.24437
2406.07	0.587278
2408.86	0.767763
2411.66	-0.0366254
2414.46	0.871049
2417.25	1.77469
2420.05	2.76057
2422.84	3.46502
2425.63	3.52073
2428.42	3.40178
2431.21	3.81004
2434	3.95905
2436.79	3.59291
2439.57	2.53548
2442.36	2.3788
2445.14	2.548
2447.93	2.64218
2450.71	2.27854
2453.49	2.60485
2456.27	2.64631
2459.05	2.66471
2461.83	3.17764
2464.61	2.4928
2467.39	2.89367
2470.16	2.10743
2472.94	0.907502
2475.71	0.959188
2478.48	2.28005
2481.25	2.46681
2484.02	2.18956
2486.8	2.31596
2489.56	2.39252
2492.33	1.74315
2495.1	1.83968
2497.86	1.59715
2500.63	0.551859
2503.39	0.67897
2506.16	0.353152
2508.92	0.444551
2511.68	2.13289
2514.44	2.29746
2517.2	2.77524
2519.95	3.3487
2522.71	3.64659
2525.47	3.57949
2528.22	4.47866
2530.98	5.40656
2533.73	4.65229
2536.48	4.38251
2539.23	3.67176
2541.98	4.16785
2544.73	4.92369
2547.48	5.17528
2550.23	4.81501
2552.97	5.55589
2555.72	5.70173
2558.46	4.63552
2561.2	4.50385
2563.95	5.26119
2566.69	4.89232
2569.43	4.79299
2572.17	5.12989
2574.91	4.92883
2577.64	4.92887
2580.38	5.23411
2583.11	4.87278
2585.85	4.11299
2588.58	3.71751
2591.31	3.21659
2594.04	2.89026
2596.78	2.99749
2599.51	2.65979
2602.23	2.28215
2604.96	2.12948
2607.69	1.58671
2610.41	1.30667
2613.14	1.82818
2615.86	0.975845
2618.58	1.37236
2621.3	1.86159
2624.03	1.79355
2626.75	1.39883
2629.46	2.27925
2632.18	2.55307
2634.9	2.29088
2637.61	2.16643
2640.33	2.73762
2643.04	2.80327
2645.76	2.09692
2648.47	2.4581
2651.18	2.16324
2653.89	2.28874
2656.6	2.53843
2659.31	2.12253
2662.01	2.39453
2664.72	2.31239
2667.43	2.33223
2670.13	1.98548
2672.83	1.98805
2675.53	1.47383
2678.24	1.10898
2680.94	1.45819
2683.64	2.43427
2686.34	3.51005
2689.03	3.89295
2691.73	3.91925
2694.43	3.9445
2697.12	5.60073
2699.81	5.39854
2702.51	5.77362
2705.2	6.14332
2707.89	5.97124
2710.58	7.13015
2713.27	7.52375
2715.96	8.54402
2718.64	8.76639
2721.33	8.48337
2724.01	7.61492
2726.7	7.01861
2729.38	5.91726
2732.06	6.1866
2734.75	5.38115
2737.43	4.85416
2740.11	4.30737
2742.78	3.37554
2745.46	2.8103
2748.14	3.30659
2750.81	3.39815
2753.49	3.35158
2756.16	2.40044
2758.84	2.85864
2761.51	2.939
2764.18	1.67702
2766.85	1.40181
2769.52	0.887696
2772.19	0.619591
2774.85	1.37265
2777.52	2.08114
2780.18	1.53157
2782.85	1.09773
2785.51	0.799634
2788.17	0.429251
2790.84	0.487926
2793.5	0.274318
2796.16	0.277748
2798.81	0.249394
2801.47	-0.48993
2804.13	-1.04674
2806.79	-1.02014
2809.44	-1.38872
2812.09	-0.307823
2814.75	0.236491
2817.4	2.26227
2820.05	4.44703
2822.7	7.06516
2825.35	9.42925
2828	13.2261
2830.65	18.4123
2833.29	23.8084
2835.94	29.2146
2838.58	35.0573
2841.23	42.1282
2843.87	49.6527
2846.51	56.9409
2849.15	66.0713
2851.79	74.2911
2854.43	82.7718
2857.07	91.324
2859.71	99.1052
2862.34	106.214
2864.98	111.824
2867.61	117.77
2870.25	123.255
2872.88	128.852
2875.51	132.914
2878.14	137.522
2880.77	141.67
2883.4	146.383
2886.03	150.177
2888.65	153.559
2891.28	159.466
2893.91	165.336
2896.53	171.189
2899.15	177.061
2901.78	184.557
2904.4	193.801
2907.02	203.317
2909.64	213.89
2912.26	225.061
2914.87	236.552
2917.49	247.533
2920.11	257.059
2922.72	264.739
2925.34	271.456
2927.95	277.055
2930.56	280.443
2933.17	282.763
2935.78	281.491
2938.39	279.018
2941	273.776
2943.61	267.602
2946.22	260.239
2948.82	250.539
2951.43	241.277
2954.03	231.116
2956.64	219.634
2959.24	207.649
2961.84	196.454
2964.44	184.825
2967.04	173.361
2969.64	163.085
2972.24	153.034
2974.83	143.37
2977.43	133.768
2980.02	124.709
2982.62	115.129
2985.21	105.139
2987.8	96.9357
2990.4	87.5186
2992.99	78.5052
2995.57	69.8598
2998.16	60.7555
3000.75	53.1545
3003.34	46.3061
3005.92	39.8959
3008.51	33.889
3011.09	28.6912
3013.68	24.5842
3016.26	20.4339
3018.84	17.1813
3021.42	14.0347
3024	12.0265
3026.58	8.84633
3029.16	7.54321
3031.73	6.84268
3034.31	7.28116
3036.89	7.00018
3039.46	7.62856
3042.03	7.50935
3044.61	8.43114
3047.18	9.30111
3049.75	10.111
3052.32	10.3087
3054.89	10.2089
3057.45	10.8008
3060.02	11.0985
3062.59	11.4469
3065.15	12.0772
3067.72	12.2724
3070.28	11.015
3072.84	9.9519
3075.41	9.58677
3077.97	8.87279
3080.53	7.61959
3083.09	6.68647
3085.64	6.01595
3088.2	4.79448
3090.76	4.06278
3093.31	4.35719
3095.87	4.85796
3098.42	4.19534
3100.97	5.07719
3103.53	5.98465
3106.08	6.91631
3108.63	9.11916
3111.18	10.0296
3113.73	11.7011
3116.27	12.9185
3118.82	15.0234
3121.37	16.7332
3123.91	18.547
3126.45	19.4532
3129	19.9148
3131.54	21.0627
3134.08	21.815
3136.62	22.3326
3139.16	23.2944
3141.7	23.5493
3144.24	22.8881
3146.78	21.9896
3149.31	20.1726