File: data/Raman/poly_smoothed/Mb_40_24_10_1x_45s_532 nm_x100_100%_600 gr_mm_01.txt
#Acq. time (s)=	45
#Accumulations=	2
#Range (cm-¹)=	200...3150
#Windows=	2
#Auto scanning=	Off
#Autofocus=	Off
#Macrospot=	Off
#AutoExposure=	Off
#Spike filter=	Multiple accum.
#Delay time (s)=	0
#Binning=	1
#Readout mode=	Signal
#DeNoise=	Off
#ICS correction=	On
#Dark correction=	Off
#Inst. Process=	Off
#Detector Gain=	Best Dynamic Range
#Detector ADC=	20 kHz
#Detector temperature (°C)=	-70.08
#Instrument=	LabRAM HR Evol
#Detector=	Synapse
#Objective=	x100
#Grating=	600 gr/mm
#ND Filter=	100%
#Laser (nm)=	532
#Hole=	100.021
#Range=	Auto
#Laser Pol.=	No
#Raman. Pol.=	No
#Laser Pol. (°)=	-0.0007625
#Raman Pol. (°)=	89.9995
#Collection=	Microscope
#StageXY=	Marzhauser
#StageZ=	Marzhauser
#X (µm)=	-2541.1
#Y (µm)=	-60.7
#Z (µm)=	-10.7
#Full time(mm:ss)=	3:18
#Project=
#Sample=
#Site=
#Title=	Mb_40_24_10_2x_45s_532 nm_x100_100%_600 gr_mm
#Remark=
#Date=	14.07.2022 11:26
#Acquired=	14.07.2022 11:26:23
#Base:Fit=	10.08.2022 10:47:00
#Base:Sub=	10.08.2022 10:47:12
#Filter:Polynom=	16.08.2022 10:11:48
#AxisType[0]=Intens
#AxisUnit[0]=Cnt
#AxisType[1]=Spectr
#AxisUnit[1]=1/cm
200.554	42.2619
204.183	34.9451
207.813	29.6893
211.439	26.6989
215.065	23.645
218.688	19.7052
222.312	18.6546
225.933	15.5779
229.552	13.6212
233.171	12.2433
236.787	10.8258
240.402	10.6753
244.015	10.4986
247.627	12.1392
251.24	12.0204
254.849	13.9759
258.457	15.3258
262.063	18.6897
265.668	19.2111
269.271	17.9538
272.873	16.9585
276.474	15.9805
280.073	13.8821
283.671	14.6722
287.268	13.5728
290.863	12.5264
294.456	12.7859
298.049	12.9192
301.637	11.0049
305.227	12.2289
308.815	12.4645
312.402	12.0155
315.987	10.3353
319.569	10.7227
323.151	10.7496
326.733	11.334
330.31	12.864
333.889	15.2895
337.464	15.9194
341.039	16.0204
344.611	16.5144
348.184	16.4724
351.754	16.0564
355.324	15.247
358.89	14.424
362.455	14.3719
366.021	12.8793
369.584	12.5544
373.145	11.7137
376.707	11.3505
380.265	11.7813
383.822	12.3991
387.378	12.3953
390.934	12.0315
394.487	13.1817
398.038	12.2402
401.588	11.7591
405.137	11.5367
408.685	11.0933
412.23	9.79158
415.775	9.52334
419.318	9.89186
422.86	8.94866
426.401	7.30317
429.94	6.59585
433.478	6.14867
437.012	6.27827
440.547	4.58594
444.081	4.01998
447.613	4.01364
451.142	4.62038
454.672	5.78188
458.2	6.74537
461.725	7.71807
465.251	8.80633
468.775	9.79537
472.296	12.7891
475.817	14.3121
479.335	16.7995
482.854	19.5528
486.37	20.0111
489.886	20.9696
493.398	22.0951
496.91	24.3016
500.422	25.3
503.93	24.4654
507.438	23.4204
510.946	23.2373
514.45	22.0733
517.954	20.8884
521.456	19.7646
524.956	18.8519
528.456	17.6282
531.956	17.2371
535.452	16.5568
538.947	14.5708
542.441	13.1948
545.934	11.8777
549.425	11.403
552.915	12.0976
556.403	11.9699
559.889	10.6949
563.375	10.1607
566.859	10.0988
570.342	7.69333
573.824	7.34833
577.303	6.81503
580.782	6.40782
584.26	5.77113
587.734	5.32709
591.21	4.66242
594.684	3.49743
598.154	4.71661
601.626	3.95394
605.094	3.18973
608.562	3.78242
612.027	4.74476
615.493	2.69233
618.956	3.16268
622.419	2.64469
625.879	2.02245
629.338	1.98914
632.797	3.09612
636.254	3.37779
639.708	3.74648
643.162	2.823
646.614	1.97174
650.067	2.99353
653.516	2.71765
656.964	1.44413
660.411	3.47962
663.857	4.48792
667.301	5.37328
670.744	5.86387
674.186	6.69311
677.626	8.46757
681.065	10.0317
684.503	12.5628
687.939	13.6749
691.372	16.3399
694.806	18.2717
698.239	19.7105
701.67	20.9198
705.098	22.6647
708.526	23.7522
711.954	25.3996
715.378	25.8124
718.802	26.4888
722.226	27.4291
725.646	27.3655
729.067	28.0404
732.484	29.3325
735.902	31.183
739.317	32.3084
742.731	35.4662
746.145	35.8149
749.556	38.0826
752.966	39.2785
756.377	40.6979
759.784	45.1123
763.19	47.7857
766.594	52.0874
770	55.333
773.402	57.887
776.803	59.8313
780.202	60.6246
783.6	61.7076
786.997	63.2976
790.393	64.0163
793.787	66.4105
797.18	66.0016
800.572	66.1601
803.963	64.9647
807.35	64.5408
810.738	64.4239
814.125	63.6854
817.51	62.8557
820.894	63.5452
824.275	63.0129
827.657	62.3096
831.037	62.0381
834.414	63.5248
837.792	61.0693
841.167	61.1979
844.542	60.6236
847.914	59.9685
851.287	59.1788
854.656	58.6028
858.026	57.2311
861.393	56.2081
864.761	55.3222
868.125	54.5859
871.489	54.161
874.85	52.9531
878.213	52.0524
881.572	50.0233
884.931	48.2823
888.287	46.8708
891.643	45.934
894.997	44.8028
898.352	45.0297
901.704	45.2765
905.055	45.945
908.404	46.3695
911.75	45.0424
915.097	44.5138
918.443	43.7587
921.787	42.6945
925.13	41.9483
928.472	41.8632
931.813	40.3743
935.15	40.3471
938.488	40.1763
941.825	38.567
945.158	37.622
948.493	36.7216
951.824	36.3529
955.156	36.7679
958.486	36.2063
961.814	36.3771
965.142	35.1141
968.467	37.3245
971.79	37.4061
975.115	39.3429
978.436	39.2142
981.756	39.4706
985.077	38.4353
988.394	38.0703
991.71	36.2103
995.025	35.0093
998.341	35.017
1001.65	34.8237
1004.97	33.777
1008.28	33.2885
1011.58	31.7221
1014.89	31.9695
1018.2	33.2586
1021.5	32.9228
1024.81	35.5016
1028.11	37.9939
1031.41	38.8211
1034.71	40.1489
1038.01	41.2772
1041.31	43.746
1044.6	45.2199
1047.9	44.4997
1051.19	44.39
1054.48	43.5698
1057.77	42.8521
1061.06	41.3345
1064.35	39.8809
1067.64	37.9966
1070.93	36.3779
1074.21	34.2315
1077.49	32.559
1080.78	31.4769
1084.06	28.9856
1087.34	28.2801
1090.61	27.0249
1093.89	26.0006
1097.17	26.3637
1100.44	26.2989
1103.71	26.1836
1106.99	25.0805
1110.26	25.143
1113.52	23.9034
1116.79	22.9966
1120.06	22.3499
1123.32	19.9304
1126.59	17.776
1129.85	15.3446
1133.11	13.2333
1136.37	10.9973
1139.63	9.8603
1142.89	8.81889
1146.15	8.36416
1149.4	7.66557
1152.66	6.96464
1155.91	6.18634
1159.16	6.22184
1162.41	6.35224
1165.66	6.1088
1168.91	5.7791
1172.16	6.22102
1175.4	6.72473
1178.65	7.94588
1181.89	7.39211
1185.13	8.39212
1188.37	9.0621
1191.61	10.5158
1194.85	9.92863
1198.08	11.0902
1201.32	12.6253
1204.55	12.8523
1207.79	13.6393
1211.02	14.2032
1214.25	15.1357
1217.48	17.5817
1220.71	20.4594
1223.93	22.784
1227.16	25.008
1230.38	27.4938
1233.6	29.6859
1236.83	32.0176
1240.05	34.255
1243.26	38.7502
1246.48	41.2361
1249.7	42.3194
1252.92	44.931
1256.13	45.5788
1259.34	46.4158
1262.55	49.2155
1265.76	50.6592
1268.97	52.3566
1272.18	55.5533
1275.39	58.4036
1278.59	61.01
1281.8	61.3029
1285	62.6462
1288.2	64.3181
1291.4	65.3348
1294.6	67.4701
1297.8	66.4217
1301	64.5694
1304.19	64.3738
1307.39	63.0847
1310.58	62.247
1313.77	60.6273
1316.96	60.3172
1320.15	59.5288
1323.34	56.058
1326.53	53.8529
1329.72	51.5395
1332.9	49.8652
1336.08	49.0395
1339.27	48.2126
1342.45	47.2399
1345.63	46.985
1348.8	45.7752
1351.98	44.379
1355.16	42.3858
1358.33	41.0335
1361.51	40.834
1364.68	38.9482
1367.85	37.6392
1371.02	37.785
1374.19	35.3346
1377.36	33.9269
1380.52	34.4897
1383.69	34.257
1386.85	34.4906
1390.02	33.5181
1393.18	34.3416
1396.34	33.3654
1399.5	34.113
1402.65	35.739
1405.81	37.4689
1408.97	39.7921
1412.12	44.4863
1415.27	48.4996
1418.43	52.4377
1421.58	55.2147
1424.73	58.6643
1427.87	62.8243
1431.02	65.6531
1434.17	69.4582
1437.31	71.4843
1440.46	72.8855
1443.6	74.9495
1446.74	76.3455
1449.88	77.2762
1453.02	77.9602
1456.16	76.4222
1459.29	73.3664
1462.43	69.1867
1465.56	64.5085
1468.69	60.1753
1471.83	54.7223
1474.95	48.9768
1478.08	44.7421
1481.21	38.3541
1484.34	33.308
1487.47	29.9984
1490.59	26.4209
1493.71	21.4837
1496.84	20.0169
1499.96	17.3779
1503.07	15.1689
1506.19	13.5402
1509.31	11.4317
1512.43	9.45336
1515.54	8.44058
1518.65	7.60796
1521.77	9.1435
1524.88	9.7442
1527.99	11.715
1531.1	12.3464
1534.21	12.7327
1537.31	13.8138
1540.42	15.2685
1543.52	18.1847
1546.63	20.0483
1549.73	20.9822
1552.83	23.2415
1555.93	24.276
1559.03	25.0687
1562.12	26.228
1565.22	28.0048
1568.31	29.8296
1571.41	32.2143
1574.5	34.0927
1577.59	35.6103
1580.68	39.1884
1583.77	40.5736
1586.86	40.7173
1589.95	40.8585
1593.03	42.1193
1596.11	42.6196
1599.2	43.4149
1602.28	42.93
1605.36	42.7541
1608.44	42.2055
1611.52	41.9254
1614.6	43.1952
1617.67	44.1296
1620.75	44.2589
1623.82	44.3917
1626.89	45.5109
1629.96	48.0681
1633.04	48.5971
1636.11	51.2693
1639.17	52.8874
1642.24	56.3461
1645.31	57.8913
1648.37	60.459
1651.43	63.4329
1654.5	66.1296
1657.56	66.2075
1660.62	65.7126
1663.67	64.2464
1666.73	62.4044
1669.79	59.9605
1672.84	56.6445
1675.9	52.3543
1678.95	49.5034
1682	47.0806
1685.05	42.5768
1688.1	39.3757
1691.15	35.249
1694.2	32.2548
1697.25	28.4122
1700.29	25.1438
1703.33	21.8133
1706.38	19.053
1709.42	16.1239
1712.46	13.1765
1715.5	11.0087
1718.54	8.13482
1721.57	7.07025
1724.61	6.07408
1727.64	5.51682
1730.68	4.1772
1733.71	2.85401
1736.74	2.39782
1739.77	0.901929
1742.8	0.27202
1745.83	0.319512
1748.85	1.2901
1751.88	0.79054
1754.91	1.68905
1757.93	1.59526
1760.95	2.13655
1763.97	1.65473
1766.99	1.64307
1770.01	2.36484
1773.03	2.26865
1776.04	3.30089
1779.06	2.04955
1782.07	1.09147
1785.09	0.873465
1788.1	1.06585
1791.11	0.919543
1794.12	1.12056
1797.13	1.26364
1800.13	1.10937
1803.14	1.55795
1806.15	1.17841
1809.15	0.823269
1812.15	0.905088
1815.16	1.90122
1818.15	2.02187
1821.16	1.69933
1824.15	2.16044
1827.15	2.29283
1830.15	3.10779
1833.14	4.33026
1836.14	4.72331
1839.13	4.84307
1842.12	5.12869
1845.11	5.51823
1848.1	5.98432
1851.09	4.94694
1854.08	5.17081
1857.06	3.8811
1860.05	2.8495
1863.03	2.19169
1866.01	1.80533
1869	2.11968
1871.98	1.48887
1874.96	1.2198
1877.93	1.64683
1880.91	1.35772
1882.47	1.87438
1885.46	2.33124
1888.44	2.16787
1891.43	2.55488
1894.42	3.34865
1897.4	4.0583
1900.39	4.48527
1903.37	4.20858
1906.35	4.4934
1909.33	4.7893
1912.31	5.14145
1915.29	4.58001
1918.26	5.60763
1921.24	4.9581
1924.21	4.56444
1927.19	4.02327
1930.16	3.53786
1933.13	3.19535
1936.1	3.26605
1939.07	3.45168
1942.04	4.01033
1945	3.19167
1947.97	3.45047
1950.93	3.83762
1953.9	4.09811
1956.86	5.43447
1959.82	5.01345
1962.78	4.88247
1965.74	4.83459
1968.7	3.95849
1971.65	3.48946
1974.61	3.24094
1977.57	2.98704
1980.52	3.77296
1983.47	4.39348
1986.42	4.98054
1989.37	6.07984
1992.32	6.93583
1995.27	7.51297
1998.22	6.98782
2001.17	7.42681
2004.11	8.06941
2007.05	8.78999
2010	9.30983
2012.94	9.95875
2015.88	10.343
2018.82	11.5952
2021.76	12.8594
2024.7	13.8969
2027.63	14.8612
2030.57	15.0082
2033.5	14.3873
2036.44	14.1173
2039.37	13.5649
2042.3	14.7989
2045.23	15.7005
2048.16	16.4833
2051.08	16.7244
2054.01	16.3491
2056.94	16.2672
2059.86	16.5402
2062.79	17.2076
2065.71	17.0998
2068.63	17.8814
2071.55	18.3761
2074.47	20.0571
2077.39	20.87
2080.31	21.3848
2083.22	21.582
2086.13	23.7011
2089.05	26.6746
2091.96	27.8446
2094.87	29.6926
2097.78	31.3763
2100.69	32.1966
2103.6	33.8267
2106.51	34.3259
2109.42	36.0808
2112.32	37.8408
2115.23	41.4454
2118.13	43.0196
2121.03	43.9731
2123.93	45.892
2126.83	47.6594
2129.73	50.5176
2132.63	54.2095
2135.53	57.2003
2138.42	60.4045
2141.32	63.0125
2144.21	65.8767
2147.1	68.79
2150	71.5317
2152.89	74.3394
2155.78	78.1498
2158.66	80.9243
2161.55	82.503
2164.44	83.7985
2167.32	84.6157
2170.21	85.2995
2173.09	84.7386
2175.97	84.7174
2178.85	83.9309
2181.73	83.4085
2184.61	82.3655
2187.49	80.3303
2190.37	77.1846
2193.24	75.7493
2196.12	72.6236
2198.99	70.046
2201.87	67.258
2204.74	63.5832
2207.61	59.8684
2210.48	56.8698
2213.35	53.9116
2216.21	52.2131
2219.08	50.0728
2221.95	47.5765
2224.81	44.5619
2227.67	42.4517
2230.54	39.8652
2233.4	38.0882
2236.26	35.497
2239.11	33.975
2241.97	32.2395
2244.83	30.6476
2247.69	29.7502
2250.54	28.9281
2253.4	27.2635
2256.25	25.829
2259.1	24.6638
2261.95	23.6341
2264.8	22.8505
2267.65	22.3503
2270.5	22.5575
2273.34	23.0123
2276.19	22.3245
2279.03	22.3531
2281.88	21.329
2284.72	21.4644
2287.56	20.8037
2290.4	20.0746
2293.24	17.8339
2296.08	17.9378
2298.92	17.7994
2301.76	17.623
2304.59	16.8998
2307.43	16.9284
2310.26	16.443
2313.09	15.6908
2315.92	15.1294
2318.75	14.5485
2321.58	14.1859
2324.41	13.9179
2327.24	13.5131
2330.06	13.1367
2332.89	12.942
2335.71	13.2197
2338.54	13.8308
2341.36	14.025
2344.18	13.4266
2347	12.541
2349.82	12.9156
2352.64	12.0896
2355.45	11.1989
2358.27	10.223
2361.08	8.93962
2363.9	9.066
2366.71	9.81238
2369.52	9.6511
2372.33	8.1836
2375.14	8.01484
2377.95	7.51702
2380.76	6.27484
2383.57	5.85396
2386.37	6.34835
2389.18	6.97418
2391.98	7.20311
2394.79	7.18801
2397.59	7.22089
2400.39	7.02635
2403.19	6.99921
2405.99	8.5543
2408.78	8.41026
2411.58	10.3554
2414.38	11.0339
2417.17	11.4279
2419.97	11.242
2422.76	10.889
2425.55	11.2266
2428.34	10.5286
2431.13	9.83265
2433.92	9.53386
2436.71	9.52433
2439.49	9.15055
2442.28	8.34421
2445.06	9.02923
2447.85	8.58579
2450.63	9.22218
2453.41	9.01619
2456.19	9.97112
2458.97	8.86218
2461.75	8.65769
2464.53	8.92943
2467.31	8.65122
2470.08	8.37589
2472.86	8.21448
2475.63	8.10293
2478.4	7.65547
2481.17	7.09999
2483.94	6.24554
2486.72	6.09457
2489.48	6.09911
2492.25	5.12628
2495.02	4.50602
2497.79	3.73855
2500.55	2.85318
2503.31	2.76496
2506.08	2.88076
2508.84	3.2089
2511.6	3.51242
2514.36	3.53669
2517.12	3.25658
2519.88	2.84868
2522.63	2.43317
2525.39	2.20705
2528.14	2.92607
2530.9	3.69481
2533.65	3.26042
2536.4	3.4137
2539.15	2.97931
2541.9	2.33135
2544.65	2.29772
2547.4	2.31268
2550.15	2.44955
2552.89	3.69911
2555.64	3.42629
2558.38	2.64007
2561.12	3.04313
2563.87	2.39167
2566.61	1.77218
2569.35	1.91277
2572.09	2.21364
2574.83	1.74333
2577.56	2.51796
2580.3	2.13825
2583.04	1.44096
2585.77	1.59737
2588.5	1.06223
2591.23	0.86842
2593.97	1.01704
2596.7	0.949097
2599.43	0.244495
2602.15	0.712209
2604.88	0.735346
2607.61	0.484207
2610.33	0.541697
2613.06	0.461967
2615.78	0.676885
2618.51	1.55393
2621.23	0.659022
2623.95	0.52895
2626.67	1.10903
2629.39	1.72363
2632.1	2.26538
2634.82	3.33509
2637.54	4.39419
2640.25	5.12199
2642.97	6.43203
2645.68	7.38788
2648.39	8.09471
2651.1	7.63658
2653.81	7.65444
2656.52	6.46931
2659.23	6.00676
2661.94	5.84696
2664.64	5.61516
2667.35	5.25225
2670.05	5.28696
2672.76	4.32152
2675.46	4.1103
2678.16	3.99773
2680.86	4.02556
2683.56	3.704
2686.26	3.52461
2688.96	2.58608
2691.65	2.76903
2694.35	3.11775
2697.04	3.37068
2699.74	3.25696
2702.43	4.32337
2705.12	4.53749
2707.81	4.82866
2710.5	5.34367
2713.19	5.59458
2715.88	5.90743
2718.57	5.64396
2721.25	5.36349
2723.94	5.13148
2726.62	5.88549
2729.3	5.65692
2731.99	5.64504
2734.67	5.1562
2737.35	5.16645
2740.03	5.30781
2742.71	4.95352
2745.38	4.52971
2748.06	4.07132
2750.74	3.05197
2753.41	2.18035
2756.09	1.8246
2758.76	2.17435
2761.43	1.63195
2764.1	1.10016
2766.77	0.774796
2769.44	0.558689
2772.11	0.586747
2774.77	0.253234
2777.44	0.948941
2780.11	0.537146
2782.77	0.788123
2785.43	0.385868
2788.1	0.874998
2790.76	1.11915
2793.42	1.42073
2796.08	1.20861
2798.74	1.74225
2801.4	2.35592
2804.05	2.48125
2806.71	2.58847
2809.36	2.557
2812.02	2.81872
2814.67	3.54739
2817.32	3.78873
2819.97	5.87434
2822.62	8.71163
2825.27	10.2908
2827.92	12.3821
2830.57	16.3973
2833.22	20.1758
2835.86	24.0856
2838.51	28.564
2841.15	33.646
2843.79	38.7252
2846.43	45.1859
2849.08	51.2175
2851.72	57.8848
2854.36	64.9133
2856.99	71.4351
2859.63	78.0033
2862.27	84.3343
2864.9	90.8616
2867.54	95.5575
2870.17	100.239
2872.8	104.415
2875.43	108.921
2878.07	112.741
2880.7	116.163
2883.32	119.944
2885.95	123.779
2888.58	127.965
2891.21	132.617
2893.83	138.007
2896.46	144.59
2899.08	151.158
2901.7	158.276
2904.32	166.084
2906.94	174.314
2909.56	183.219
2912.18	192.878
2914.8	202.619
2917.42	211.12
2920.03	218.544
2922.65	224.837
2925.26	231.236
2927.88	234.877
2930.49	236.98
2933.1	237.946
2935.71	236.441
2938.32	233.205
2940.93	228.652
2943.54	222.138
2946.14	214.199
2948.75	206.112
2951.35	196.989
2953.96	188.931
2956.56	178.593
2959.16	169.298
2961.77	159.484
2964.37	151.535
2966.96	142.412
2969.56	134.325
2972.16	126.82
2974.76	118.65
2977.35	111.721
2979.95	104.09
2982.54	96.8527
2985.14	90.4441
2987.73	83.9549
2990.32	76.4674
2992.91	70.3532
2995.5	63.7572
2998.09	57.5141
3000.68	50.9174
3003.26	45.0629
3005.85	39.6447
3008.43	34.6972
3011.02	29.8938
3013.6	26.36
3016.19	22.5061
3018.77	19.5117
3021.35	16.2478
3023.93	15.3471
3026.5	14.0951
3029.08	12.6551
3031.66	11.5404
3034.24	10.5746
3036.81	10.1481
3039.39	9.77404
3041.96	10.9752
3044.53	11.0263
3047.1	11.645
3049.67	11.5713
3052.24	11.4487
3054.81	11.5594
3057.38	11.7097
3059.95	11.2514
3062.52	10.543
3065.08	9.82267
3067.65	8.56927
3070.21	7.50879
3072.77	6.47101
3075.33	6.22875
3077.89	5.40577
3080.45	4.71046
3083.01	3.97008
3085.57	2.89247
3088.13	1.74765
3090.68	0.802159
3093.24	0.718698
3095.79	0.529499
3098.35	1.37679
3100.9	2.32706
3103.45	3.33315
3106	3.25761
3108.55	3.33113
3111.1	3.2189
3113.65	3.62644
3116.2	4.4353
3118.75	4.26998
3121.29	4.05433
3123.84	4.17749
3126.38	3.83264
3128.92	3.9057
3131.47	3.61259
3134.01	3.49131
3136.55	3.90379
3139.09	4.05079
3141.63	3.68809
3144.17	3.55608
3146.7	4.4963
3149.24	7.62121