File: data/Raman/poly_smoothed/Mb_40_24_02_1x_45s_532 nm_x100_100%_600 gr_mm_01.txt
#Acq. time (s)=	45
#Accumulations=	2
#Range (cm-¹)=	200...3150
#Windows=	2
#Auto scanning=	Off
#Autofocus=	Off
#Macrospot=	Off
#AutoExposure=	Off
#Spike filter=	Multiple accum.
#Delay time (s)=	0
#Binning=	1
#Readout mode=	Signal
#DeNoise=	Off
#ICS correction=	On
#Dark correction=	Off
#Inst. Process=	Off
#Detector Gain=	Best Dynamic Range
#Detector ADC=	20 kHz
#Detector temperature (°C)=	-70.08
#Instrument=	LabRAM HR Evol
#Detector=	Synapse
#Objective=	x100
#Grating=	600 gr/mm
#ND Filter=	100%
#Laser (nm)=	532
#Hole=	100.021
#Range=	Auto
#Laser Pol.=	No
#Raman. Pol.=	No
#Laser Pol. (°)=	-0.0007625
#Raman Pol. (°)=	89.9995
#Collection=	Microscope
#StageXY=	Marzhauser
#StageZ=	Marzhauser
#X (µm)=	-2543
#Y (µm)=	-28.5
#Z (µm)=	-10.35
#Full time(mm:ss)=	3:18
#Project=
#Sample=
#Site=
#Title=	Mb_40_24_02_2x_45s_532 nm_x100_100%_600 gr_mm
#Remark=
#Date=	14.07.2022 10:49
#Acquired=	14.07.2022 10:49:18
#Base:Fit=	10.08.2022 10:47:00
#Base:Sub=	10.08.2022 10:47:12
#Filter:Polynom=	16.08.2022 10:11:48
#AxisType[0]=Intens
#AxisUnit[0]=Cnt
#AxisType[1]=Spectr
#AxisUnit[1]=1/cm
200.554	48.8682
204.183	34.3443
207.813	25.4202
211.439	18.2293
215.065	14.0254
218.688	9.19358
222.312	8.10245
225.933	6.92421
229.552	6.51912
233.171	4.39215
236.787	3.53236
240.402	3.67179
244.015	3.82187
247.627	3.83535
251.24	4.77149
254.849	5.82959
258.457	6.70408
262.063	5.74969
265.668	7.37359
269.271	8.24888
272.873	7.33069
276.474	7.00872
280.073	5.55296
283.671	3.0023
287.268	1.70575
290.863	2.83505
294.456	4.72518
298.049	4.49827
301.637	7.22911
305.227	9.13739
308.815	11.327
312.402	15.8467
315.987	17.473
319.569	20.093
323.151	21.6081
326.733	26.1802
330.31	28.4889
333.889	28.3733
337.464	29.5009
341.039	31.7691
344.611	32.5639
348.184	34.1444
351.754	35.8842
355.324	37.911
358.89	34.3174
362.455	32.0822
366.021	29.0544
369.584	27.3202
373.145	25.8085
376.707	25.4888
380.265	24.3538
383.822	23.3073
387.378	21.9903
390.934	22.087
394.487	19.491
398.038	18.4461
401.588	17.2137
405.137	15.1896
408.685	14.5242
412.23	14.2072
415.775	13.7616
419.318	12.5024
422.86	14.4196
426.401	16.2444
429.94	17.5682
433.478	18.0858
437.012	19.303
440.547	19.7124
444.081	17.1914
447.613	16.5658
451.142	15.7754
454.672	17.5356
458.2	17.1746
461.725	17.9765
465.251	19.8732
468.775	20.3581
472.296	20.6854
475.817	20.2643
479.335	21.6242
482.854	21.5697
486.37	23.6286
489.886	24.7654
493.398	25.676
496.91	28.5964
500.422	30.5164
503.93	32.144
507.438	33.1532
510.946	35.1491
514.45	35.0389
517.954	35.8953
521.456	36.4417
524.956	35.2182
528.456	35.5767
531.956	35.9213
535.452	34.6822
538.947	32.4736
542.441	32.9424
545.934	31.0692
549.425	30.6179
552.915	28.4402
556.403	26.7925
559.889	24.3775
563.375	23.3559
566.859	21.0084
570.342	18.3567
573.824	16.6802
577.303	16.2308
580.782	17.5312
584.26	17.1952
587.734	16.8438
591.21	13.4171
594.684	13.3572
598.154	12.1156
601.626	10.4192
605.094	9.32697
608.562	9.96672
612.027	13.1021
615.493	13.5229
618.956	11.5832
622.419	12.627
625.879	13.8889
629.338	13.9976
632.797	14.2464
636.254	15.8021
639.708	14.6498
643.162	12.4964
646.614	12.0915
650.067	11.2342
653.516	11.9891
656.964	12.9322
660.411	15.2271
663.857	15.5702
667.301	14.4481
670.744	13.8601
674.186	12.8004
677.626	12.1553
681.065	12.0613
684.503	12.575
687.939	13.8298
691.372	15.1571
694.806	18.3802
698.239	20.97
701.67	20.5199
705.098	22.8015
708.526	24.0698
711.954	24.0652
715.378	24.6689
718.802	25.156
722.226	23.9352
725.646	21.6131
729.067	23.5144
732.484	23.244
735.902	23.5839
739.317	23.7163
742.731	25.5153
746.145	26.3771
749.556	28.3144
752.966	30.7272
756.377	32.3242
759.784	34.7115
763.19	35.9596
766.594	38.0928
770	41.1606
773.402	43.0109
776.803	45.042
780.202	47.2475
783.6	49.4441
786.997	52.9712
790.393	56.3441
793.787	59.3515
797.18	60.7054
800.572	62.9218
803.963	63.9659
807.35	65.7863
810.738	66.0962
814.125	68.1267
817.51	69.0422
820.894	69.0867
824.275	71.2364
827.657	72.4616
831.037	73.9753
834.414	74.7549
837.792	75.3941
841.167	75.2125
844.542	75.2855
847.914	73.7079
851.287	75.5586
854.656	71.4022
858.026	68.9875
861.393	68.0199
864.761	67.5251
868.125	66.7645
871.489	65.2106
874.85	62.8513
878.213	61.3255
881.572	60.0528
884.931	58.612
888.287	55.5888
891.643	54.2334
894.997	52.7246
898.352	52.0088
901.704	48.1917
905.055	46.3038
908.404	46.9783
911.75	46.2148
915.097	46.6887
918.443	46.5285
921.787	46.79
925.13	46.3085
928.472	44.9749
931.813	42.5755
935.15	41.3795
938.488	39.5654
941.825	36.182
945.158	32.8317
948.493	30.1925
951.824	29.437
955.156	31.134
958.486	28.4059
961.814	28.3405
965.142	28.6019
968.467	30.4859
971.79	33.3118
975.115	37.3646
978.436	40.4932
981.756	41.4498
985.077	42.0487
988.394	41.8945
991.71	41.976
995.025	41.6948
998.341	42.3957
1001.65	41.0349
1004.97	40.6235
1008.28	41.8277
1011.58	41.765
1014.89	44.0624
1018.2	46.4594
1021.5	49.2427
1024.81	50.5739
1028.11	55.3431
1031.41	58.3667
1034.71	59.9374
1038.01	59.4147
1041.31	59.679
1044.6	64.0268
1047.9	65.1576
1051.19	66.789
1054.48	67.715
1057.77	67.42
1061.06	63.6375
1064.35	59.9128
1067.64	52.8453
1070.93	49.2932
1074.21	46.3718
1077.49	41.6807
1080.78	37.7356
1084.06	33.3177
1087.34	32.3374
1090.61	31.2093
1093.89	30.5095
1097.17	32.9211
1100.44	34.9627
1103.71	33.1348
1106.99	32.4886
1110.26	31.7827
1113.52	28.0876
1116.79	27.2881
1120.06	25.5497
1123.32	24.1054
1126.59	23.2987
1129.85	21.3218
1133.11	20.3189
1136.37	19.6167
1139.63	17.507
1142.89	14.8564
1146.15	12.2804
1149.4	10.5994
1152.66	9.79391
1155.91	6.93952
1159.16	4.72047
1162.41	3.09872
1165.66	3.7544
1168.91	2.0284
1172.16	2.2479
1175.4	3.89
1178.65	4.12943
1181.89	5.43317
1185.13	5.36581
1188.37	6.9098
1191.61	6.90608
1194.85	9.47761
1198.08	10.5895
1201.32	12.5317
1204.55	15.9272
1207.79	18.7295
1211.02	21.2853
1214.25	24.2105
1217.48	25.6818
1220.71	28.667
1223.93	30.7144
1227.16	34.0925
1230.38	37.8754
1233.6	43.0411
1236.83	46.7789
1240.05	52.1828
1243.26	58.1231
1246.48	62.5251
1249.7	66.6498
1252.92	72.1282
1256.13	75.216
1259.34	78.9761
1262.55	81.4236
1265.76	85.5528
1268.97	89.4009
1272.18	93.2375
1275.39	94.5764
1278.59	96.3578
1281.8	96.75
1285	99.5888
1288.2	100.152
1291.4	99.9569
1294.6	99.0197
1297.8	98.8247
1301	99.1557
1304.19	98.0455
1307.39	98.1898
1310.58	98.934
1313.77	98.9328
1316.96	98.6682
1320.15	98.2318
1323.34	98.6345
1326.53	98.0278
1329.72	97.2833
1332.9	96.7397
1336.08	94.8184
1339.27	93.2536
1342.45	92.658
1345.63	92.2035
1348.8	88.4453
1351.98	86.8796
1355.16	84.6357
1358.33	83.2536
1361.51	80.2613
1364.68	79.2629
1367.85	78.4011
1371.02	79.0169
1374.19	77.8166
1377.36	78.1267
1380.52	79.0008
1383.69	80.1376
1386.85	84.0157
1390.02	85.6904
1393.18	86.163
1396.34	88.7308
1399.5	91.8944
1402.65	95.6003
1405.81	96.8187
1408.97	100.516
1412.12	105.396
1415.27	110.684
1418.43	118.307
1421.58	124.283
1424.73	130.4
1427.87	137.175
1431.02	143.047
1434.17	149.414
1437.31	152.41
1440.46	157.701
1443.6	160.036
1446.74	159.768
1449.88	160.284
1453.02	157.442
1456.16	155.101
1459.29	148.842
1462.43	142.315
1465.56	134.978
1468.69	122.996
1471.83	112.492
1474.95	102.748
1478.08	93.2301
1481.21	83.6599
1484.34	73.9044
1487.47	68.2371
1490.59	61.158
1493.71	54.9446
1496.84	50.3065
1499.96	45.8474
1503.07	43.2839
1506.19	39.0328
1509.31	36.0121
1512.43	33.4772
1515.54	32.5677
1518.65	30.6229
1521.77	29.2344
1524.88	30.531
1527.99	30.8675
1531.1	30.7994
1534.21	31.2813
1537.31	32.5417
1540.42	33.5636
1543.52	34.3107
1546.63	37.4421
1549.73	41.6141
1552.83	45.25
1555.93	47.6067
1559.03	49.5987
1562.12	52.5851
1565.22	55.6971
1568.31	60.0086
1571.41	64.6063
1574.5	68.8702
1577.59	73.8862
1580.68	77.411
1583.77	82.0806
1586.86	85.7563
1589.95	89.8393
1593.03	91.7681
1596.11	92.7998
1599.2	94.5959
1602.28	94.7548
1605.36	95.5281
1608.44	94.6104
1611.52	95.4511
1614.6	96.1461
1617.67	96.0824
1620.75	98.8001
1623.82	98.3211
1626.89	98.344
1629.96	97.9975
1633.04	97.218
1636.11	99.8794
1639.17	103.801
1642.24	107.861
1645.31	108.901
1648.37	110.157
1651.43	110.107
1654.5	109.737
1657.56	109.246
1660.62	108.377
1663.67	104.644
1666.73	100.281
1669.79	96.4867
1672.84	90.4039
1675.9	84.5067
1678.95	79.6111
1682	72.1497
1685.05	67.125
1688.1	60.8128
1691.15	56.5815
1694.2	50.9884
1697.25	44.2792
1700.29	40.254
1703.33	35.9323
1706.38	33.341
1709.42	32.1076
1712.46	30.9214
1715.5	28.9941
1718.54	26.2692
1721.57	24.6288
1724.61	23.8852
1727.64	22.8804
1730.68	21.6901
1733.71	20.6921
1736.74	18.7637
1739.77	18.3118
1742.8	17.032
1745.83	14.6299
1748.85	14.1553
1751.88	12.9235
1754.91	12.6981
1757.93	11.2437
1760.95	9.77537
1763.97	7.72615
1766.99	7.04323
1770.01	5.85183
1773.03	5.09222
1776.04	4.1211
1779.06	3.41655
1782.07	3.37467
1785.09	3.13566
1788.1	1.52169
1791.11	1.44488
1794.12	1.69199
1797.13	2.29753
1800.13	1.79098
1803.14	1.7284
1806.15	0.981991
1809.15	0.875519
1812.15	0.661075
1815.16	1.85332
1818.15	2.46291
1821.16	2.65155
1824.15	2.304
1827.15	3.07832
1830.15	3.34931
1833.14	3.26481
1836.14	3.44105
1839.13	4.3844
1842.12	3.45859
1845.11	2.83472
1848.1	2.87851
1851.09	2.3772
1854.08	1.80816
1857.06	1.67805
1860.05	0.429172
1863.03	-0.629063
1866.01	0.279195
1869	0.996914
1871.98	1.29135
1874.96	2.53157
1877.93	2.72566
1880.91	3.5874
1882.47	3.97506
1885.46	6.3281
1888.44	7.48042
1891.43	8.43572
1894.42	9.71428
1897.4	12.4148
1900.39	13.6201
1903.37	14.5845
1906.35	14.9472
1909.33	16.3906
1912.31	16.7092
1915.29	16.5776
1918.26	17.2959
1921.24	17.6227
1924.21	17.2967
1927.19	17.1943
1930.16	16.5245
1933.13	15.416
1936.1	15.4275
1939.07	15.54
1942.04	15.1882
1945	14.0714
1947.97	14.4248
1950.93	14.3396
1953.9	14.3018
1956.86	13.5415
1959.82	13.8362
1962.78	13.1496
1965.74	13.0734
1968.7	12.5244
1971.65	11.9646
1974.61	11.4767
1977.57	11.0705
1980.52	11.2768
1983.47	9.86567
1986.42	9.51241
1989.37	9.27814
1992.32	9.97426
1995.27	9.29594
1998.22	9.39169
2001.17	9.09404
2004.11	9.94329
2007.05	10.4998
2010	11.7413
2012.94	11.35
2015.88	11.3279
2018.82	11.2203
2021.76	12.5198
2024.7	11.9078
2027.63	12.2886
2030.57	13.7864
2033.5	13.9393
2036.44	15.0798
2039.37	14.4137
2042.3	14.7242
2045.23	14.9742
2048.16	16.0434
2051.08	16.2781
2054.01	17.2552
2056.94	16.9641
2059.86	17.3534
2062.79	17.8887
2065.71	18.4045
2068.63	20.8642
2071.55	20.8518
2074.47	21.9862
2077.39	22.0981
2080.31	22.706
2083.22	23.6121
2086.13	23.655
2089.05	25.4705
2091.96	26.0716
2094.87	26.7328
2097.78	29.532
2100.69	32.0091
2103.6	34.3877
2106.51	34.6269
2109.42	37.1134
2112.32	39.6689
2115.23	43.4406
2118.13	46.2309
2121.03	49.0409
2123.93	53.1116
2126.83	56.7604
2129.73	60.0259
2132.63	65.0623
2135.53	68.5652
2138.42	72.3936
2141.32	75.2792
2144.21	78.1327
2147.1	81.9911
2150	84.7872
2152.89	88.1277
2155.78	90.6395
2158.66	92.0593
2161.55	94.1897
2164.44	95.4914
2167.32	97.7101
2170.21	98.0958
2173.09	97.1797
2175.97	94.5608
2178.85	93.3354
2181.73	92.286
2184.61	90
2187.49	86.446
2190.37	84.1104
2193.24	81.9007
2196.12	78.6483
2198.99	73.2663
2201.87	68.8863
2204.74	64.3454
2207.61	60.4782
2210.48	57.3111
2213.35	53.5136
2216.21	50.0144
2219.08	46.6889
2221.95	44.4039
2224.81	42.4481
2227.67	40.7535
2230.54	38.3148
2233.4	37.3052
2236.26	36.5752
2239.11	34.4719
2241.97	32.0967
2244.83	28.914
2247.69	27.1526
2250.54	26.4025
2253.4	24.9654
2256.25	23.7997
2259.1	23.1679
2261.95	21.5254
2264.8	20.1981
2267.65	16.9626
2270.5	15.99
2273.34	15.1154
2276.19	12.8543
2279.03	12.4499
2281.88	10.8796
2284.72	8.7307
2287.56	8.51226
2290.4	8.28923
2293.24	6.26695
2296.08	6.05284
2298.92	5.34353
2301.76	6.08677
2304.59	6.09126
2307.43	4.71307
2310.26	4.39274
2313.09	3.82103
2315.92	4.27171
2318.75	4.53059
2321.58	3.8468
2324.41	5.01506
2327.24	4.40886
2330.06	3.92317
2332.89	4.02282
2335.71	4.21508
2338.54	3.88516
2341.36	3.11098
2344.18	3.17643
2347	4.39852
2349.82	4.62403
2352.64	3.88042
2355.45	3.76357
2358.27	4.04562
2361.08	2.79095
2363.9	3.1567
2366.71	2.66009
2369.52	3.52437
2372.33	2.42519
2375.14	2.10473
2377.95	3.21257
2380.76	2.67515
2383.57	2.82067
2386.37	2.19778
2389.18	1.05228
2391.98	0.272507
2394.79	0.0428199
2397.59	0.875701
2400.39	1.41601
2403.19	1.36164
2405.99	1.479
2408.78	3.11668
2411.58	4.17623
2414.38	5.33824
2417.17	4.85706
2419.97	5.04329
2422.76	4.97119
2425.55	4.9928
2428.34	4.92877
2431.13	5.71613
2433.92	5.67733
2436.71	5.9144
2439.49	5.69347
2442.28	5.66855
2445.06	5.72522
2447.85	5.46162
2450.63	5.39291
2453.41	4.2724
2456.19	4.66251
2458.97	3.99856
2461.75	4.23725
2464.53	4.03517
2467.31	3.96399
2470.08	3.70049
2472.86	3.22944
2475.63	2.85194
2478.4	2.9465
2481.17	2.8353
2483.94	2.424
2486.72	-0.239705
2489.48	0.623287
2492.25	1.02079
2495.02	2.25619
2497.79	2.69125
2500.55	2.12881
2503.31	1.93272
2506.08	0.594595
2508.84	0.781787
2511.6	1.53045
2514.36	2.92852
2517.12	2.94359
2519.88	3.08151
2522.63	4.52867
2525.39	5.78457
2528.14	5.51599
2530.9	5.20315
2533.65	4.99756
2536.4	4.15139
2539.15	4.50079
2541.9	5.14334
2544.65	5.74281
2547.4	7.1443
2550.15	6.34042
2552.89	6.70459
2555.64	6.61453
2558.38	7.86273
2561.12	8.12256
2563.87	7.56559
2566.61	6.60595
2569.35	6.42009
2572.09	6.60642
2574.83	6.94231
2577.56	6.5177
2580.3	6.2504
2583.04	6.19189
2585.77	6.34605
2588.5	6.36206
2591.23	7.03402
2593.97	7.04731
2596.7	6.77207
2599.43	6.34411
2602.15	4.97863
2604.88	5.62464
2607.61	5.20738
2610.33	6.28004
2613.06	6.76372
2615.78	6.60231
2618.51	7.37033
2621.23	7.73591
2623.95	6.43775
2626.67	6.26501
2629.39	5.67873
2632.1	5.48426
2634.82	5.74427
2637.54	7.18748
2640.25	7.95375
2642.97	6.65608
2645.68	5.91038
2648.39	6.28948
2651.1	6.56786
2653.81	6.95395
2656.52	7.41636
2659.23	7.69139
2661.94	8.58852
2664.64	6.25927
2667.35	5.60763
2670.05	5.52439
2672.76	6.23155
2675.46	7.10297
2678.16	7.79795
2680.86	8.41253
2683.56	8.17643
2686.26	7.63278
2688.96	7.18208
2691.65	7.13878
2694.35	7.45103
2697.04	7.38066
2699.74	6.84111
2702.43	7.18289
2705.12	7.2499
2707.81	6.51101
2710.5	6.20887
2713.19	6.69357
2715.88	7.69227
2718.57	7.54124
2721.25	7.22863
2723.94	7.38065
2726.62	7.71139
2729.3	7.81714
2731.99	7.54585
2734.67	9.37779
2737.35	9.42714
2740.03	10.0116
2742.71	10.3709
2745.38	10.0069
2748.06	9.12293
2750.74	8.53116
2753.41	7.3452
2756.09	7.53144
2758.76	6.70843
2761.43	4.89268
2764.1	4.2785
2766.77	2.0996
2769.44	1.80643
2772.11	1.41176
2774.77	1.44689
2777.44	0.420045
2780.11	-0.460987
2782.77	-1.27643
2785.43	-2.0793
2788.1	-1.97046
2790.76	-1.5906
2793.42	-0.4171
2796.08	-0.726981
2798.74	0.109905
2801.4	0.984955
2804.05	1.82773
2806.71	1.86536
2809.36	2.28347
2812.02	3.72392
2814.67	4.54111
2817.32	5.27579
2819.97	8.26571
2822.62	11.3431
2825.27	15.8432
2827.92	20.3523
2830.57	25.8606
2833.22	32.6849
2835.86	39.6143
2838.51	46.8016
2841.15	55.4233
2843.79	63.5502
2846.43	72.1308
2849.08	82.0194
2851.72	93.7131
2854.36	104.298
2856.99	115.457
2859.63	125.174
2862.27	134.791
2864.9	145.692
2867.54	155.874
2870.17	163.953
2872.8	172.985
2875.43	179.907
2878.07	187.881
2880.7	194.238
2883.32	202.692
2885.95	210.904
2888.58	220.331
2891.21	230.287
2893.83	239.563
2896.46	250.224
2899.08	261.713
2901.7	272.262
2904.32	286.247
2906.94	300.506
2909.56	314.569
2912.18	329.438
2914.8	345.653
2917.42	360.022
2920.03	372.479
2922.65	382.119
2925.26	390.118
2927.88	395.399
2930.49	397.733
2933.1	395.845
2935.71	391.369
2938.32	383.897
2940.93	372.122
2943.54	359.916
2946.14	344.99
2948.75	329.774
2951.35	313.603
2953.96	296.386
2956.56	278.463
2959.16	261.213
2961.77	244.272
2964.37	229.417
2966.96	214.189
2969.56	200.807
2972.16	187.491
2974.76	177.593
2977.35	167.034
2979.95	156.476
2982.54	145.105
2985.14	134.618
2987.73	124.486
2990.32	113.326
2992.91	101.831
2995.5	91.8413
2998.09	81.9784
3000.68	71.6516
3003.26	61.7904
3005.85	53.0348
3008.43	44.7826
3011.02	37.3221
3013.6	29.1358
3016.19	23.8297
3018.77	18.7198
3021.35	14.5373
3023.93	9.6757
3026.5	7.19909
3029.08	4.42462
3031.66	2.97022
3034.24	1.81383
3036.81	2.18863
3039.39	2.27612
3041.96	2.50845
3044.53	3.20362
3047.1	4.29989
3049.67	4.82188
3052.24	5.04485
3054.81	5.53234
3057.38	5.37098
3059.95	5.84827
3062.52	5.58466
3065.08	5.71619
3067.65	6.32313
3070.21	6.47034
3072.77	5.04737
3075.33	4.6268
3077.89	4.1888
3080.45	3.84491
3083.01	2.37164
3085.57	1.06569
3088.13	0.165902
3090.68	1.13182
3093.24	0.256628
3095.79	0.473482
3098.35	-0.231705
3100.9	0.442254
3103.45	0.783303
3106	2.06557
3108.55	3.79622
3111.1	4.07822
3113.65	5.46573
3116.2	6.63715
3118.75	7.89348
3121.29	10.1648
3123.84	11.8462
3126.38	14.6737
3128.92	16.8632
3131.47	19.923
3134.01	22.2653
3136.55	24.3071
3139.09	27.2998
3141.63	28.8327
3144.17	31.1322
3146.7	33.6827
3149.24	35.3088