File: data/Raman/poly_smoothed/Mb_40_y_22_1x_45s_532 nm_x100_100%_600 gr_mm_01.txt
#Acq. time (s)=	45
#Accumulations=	2
#Range (cm-¹)=	200...3150
#Windows=	2
#Auto scanning=	Off
#Autofocus=	Off
#Macrospot=	Off
#AutoExposure=	Off
#Spike filter=	Multiple accum.
#Delay time (s)=	0
#Binning=	1
#Readout mode=	Signal
#DeNoise=	Off
#ICS correction=	On
#Dark correction=	Off
#Inst. Process=	Off
#Detector Gain=	Best Dynamic Range
#Detector ADC=	20 kHz
#Detector temperature (°C)=	-69.85
#Instrument=	LabRAM HR Evol
#Detector=	Synapse
#Objective=	x100
#Grating=	600 gr/mm
#ND Filter=	100%
#Laser (nm)=	532
#Hole=	100.021
#Range=	Auto
#Laser Pol.=	No
#Raman. Pol.=	No
#Laser Pol. (°)=	-0.0007625
#Raman Pol. (°)=	89.9995
#Collection=	Microscope
#StageXY=	Marzhauser
#StageZ=	Marzhauser
#X (µm)=	-1016.1
#Y (µm)=	659.5
#Z (µm)=	584.35
#Full time(mm:ss)=	3:18
#Project=
#Sample=
#Site=
#Title=	Mb_40_y_22_2x_45s_532 nm_x100_100%_600 gr_mm
#Remark=
#Date=	19.07.2022 10:45
#Acquired=	19.07.2022 10:45:04
#Base:Fit=	10.08.2022 10:52:48
#Base:Sub=	10.08.2022 10:52:53
#Filter:Polynom=	16.08.2022 10:09:04
#AxisType[0]=Intens
#AxisUnit[0]=Cnt
#AxisType[1]=Spectr
#AxisUnit[1]=1/cm
200.423	31.2017
204.052	21.5652
207.682	15.4158
211.308	10.9616
214.935	8.22807
218.558	5.60082
222.18	4.68461
225.802	4.63112
229.421	4.9433
233.039	6.41713
236.657	7.72883
240.272	9.10747
243.885	10.1586
247.497	8.02328
251.11	8.97339
254.719	13.6841
258.327	17.1646
261.933	21.4401
265.538	23.4591
269.141	26.1271
272.744	27.5379
276.344	29.4547
279.944	30.53
283.542	32.1366
287.138	33.6876
290.733	33.9568
294.327	33.1817
297.919	33.7253
301.508	34.738
305.098	33.8794
308.686	33.6014
312.273	33.0624
315.858	32.6826
319.44	32.5163
323.022	31.0653
326.604	28.9942
330.181	26.7752
333.76	21.9573
337.335	20.0138
340.91	21.6902
344.483	22.4317
348.055	20.8326
351.625	19.1274
355.195	17.8982
358.762	17.5159
362.329	17.2022
365.893	16.7913
369.455	17.2424
373.017	15.3537
376.578	13.7466
380.137	12.4399
383.694	12.7203
387.249	12.914
390.806	10.8256
394.359	9.54135
397.91	9.20274
401.46	9.26962
405.009	9.23808
408.557	9.0574
412.103	8.3222
415.647	7.08336
419.191	6.50069
422.733	5.30803
426.273	5.84864
429.812	4.47477
433.35	3.95265
436.885	6.1181
440.42	7.34962
443.954	9.66309
447.486	11.9289
451.015	13.369
454.545	15.3781
458.073	16.3649
461.598	16.3218
465.124	17.1259
468.648	17.0485
472.169	17.0946
475.69	17.11
479.208	16.6152
482.727	17.6255
486.243	17.3438
489.759	17.7534
493.272	17.2173
496.783	17.6804
500.295	17.2717
503.804	18.2406
507.311	17.1938
510.819	17.0706
514.324	16.9585
517.827	13.8683
521.329	15.3357
524.83	16.6775
528.329	16.8002
531.829	16.4796
535.326	15.7114
538.821	15.7495
542.315	15.2607
545.808	13.9381
549.299	12.991
552.789	13.6295
556.278	13.2857
559.763	14.4736
563.249	13.9751
566.733	13.9143
570.217	12.1473
573.699	11.1765
577.177	11.6914
580.656	12.209
584.134	12.0586
587.609	11.1179
591.084	9.81279
594.558	7.16671
598.029	5.0526
601.5	4.00653
604.968	4.98041
608.437	5.80077
611.902	3.46109
615.368	3.26117
618.831	3.28054
622.294	3.45944
625.755	3.97548
629.213	4.78726
632.673	5.86437
636.129	7.77
639.584	8.18302
643.037	10.1333
646.491	12.2078
649.942	14.3826
653.392	16.7739
656.84	17.3046
660.287	19.9961
663.732	22.0982
667.177	23.6349
670.62	23.8177
674.061	22.9079
677.502	23.3842
680.941	24.0479
684.379	25.8418
687.815	28.1202
691.248	29.1253
694.682	29.3652
698.115	30.6519
701.546	32.6316
704.974	32.9319
708.402	32.6716
711.83	32.8908
715.254	33.7959
718.679	33.1009
722.102	34.6323
725.522	35.1698
728.943	35.8735
732.361	37.2381
735.779	38.1548
739.194	39.7603
742.608	40.9641
746.022	43.0418
749.433	44.6972
752.843	46.8716
756.254	48.5108
759.661	50.8142
763.067	54.5592
766.471	58.9559
769.877	61.964
773.279	66.2507
776.68	69.6646
780.079	72.1173
783.478	74.6804
786.875	76.8104
790.27	78.3561
793.665	81.1707
797.058	81.6882
800.45	82.1812
803.84	81.6543
807.23	82.6091
810.616	82.9525
814.002	82.7977
817.388	83.7473
820.772	83.0743
824.153	81.0371
827.535	79.7145
830.915	78.7343
834.292	76.1648
837.67	74.7181
841.047	72.0475
844.42	71.7446
847.794	70.1076
851.165	68.4594
854.534	65.947
857.905	63.0222
861.272	60.0134
864.639	59.3555
868.004	57.9078
871.367	56.942
874.731	55.3671
878.092	54.3213
881.451	53.6717
884.809	52.7765
888.166	50.9665
891.522	51.083
894.878	50.7992
898.231	49.5292
901.583	49.1499
904.934	48.3686
908.283	47.4703
911.631	47.8921
914.976	47.7879
918.322	48.3253
921.666	48.6047
925.009	48.6352
928.351	48.4488
931.692	48.1898
935.029	47.0587
938.367	45.8059
941.704	44.9758
945.038	44.7406
948.372	44.7965
951.705	42.6578
955.035	41.8523
958.366	40.3696
961.693	38.8381
965.021	36.1138
968.346	34.0837
971.67	32.8836
974.995	33.0301
978.316	31.7919
981.638	31.0691
984.957	29.4965
988.274	28.9781
991.59	27.7575
994.907	24.5264
998.221	23.9977
1001.53	21.6546
1004.85	20.9907
1008.16	21.6086
1011.46	25.2246
1014.77	30.5774
1018.08	34.832
1021.38	38.5928
1024.69	43.7467
1027.99	48.5817
1031.29	51.2821
1034.59	53.7988
1037.89	54.8258
1041.19	55.939
1044.48	56.342
1047.78	56.5753
1051.07	54.7267
1054.36	53.7345
1057.66	50.8153
1060.94	46.0518
1064.23	42.8211
1067.52	38.1579
1070.81	32.8534
1074.09	27.4138
1077.38	22.8805
1080.66	19.1698
1083.94	15.5118
1087.22	15.7071
1090.5	15.5726
1093.77	15.7461
1097.05	17.5672
1100.32	15.693
1103.6	15.503
1106.87	17.3402
1110.14	17.2947
1113.41	15.2333
1116.67	14.662
1119.94	14.3795
1123.21	13.7618
1126.47	11.4126
1129.73	11.5674
1133	11.4832
1136.26	12.5111
1139.52	11.8237
1142.77	12.8801
1146.03	13.2906
1149.29	13.0101
1152.54	11.723
1155.79	11.1384
1159.04	9.15238
1162.3	8.688
1165.55	7.78428
1168.79	7.37291
1172.04	6.09071
1175.28	6.37862
1178.53	6.65259
1181.77	6.91551
1185.01	8.29107
1188.25	8.1934
1191.49	5.87718
1194.73	6.71991
1197.97	6.12138
1201.2	5.50042
1204.44	4.99142
1207.67	5.95207
1210.9	7.0829
1214.13	8.63859
1217.36	7.7355
1220.59	9.03839
1223.82	10.0359
1227.04	10.2216
1230.26	10.7008
1233.49	12.0163
1236.71	11.9399
1239.93	13.3574
1243.15	16.0467
1246.37	15.5717
1249.58	16.3544
1252.8	17.7638
1256.01	18.4294
1259.23	19.8247
1262.44	19.8604
1265.65	19.4684
1268.86	20.916
1272.07	22.1244
1275.27	22.9856
1278.48	23.3904
1281.68	23.2324
1284.89	22.9977
1288.09	24.0797
1291.29	23.7322
1294.49	23.2743
1297.69	23.9418
1300.88	22.2454
1304.08	23.5917
1307.27	25.6133
1310.47	27.4716
1313.66	27.0167
1316.85	26.4815
1320.04	26.5381
1323.23	26.8767
1326.41	26.993
1329.6	27.2529
1332.78	26.3864
1335.97	26.4751
1339.15	26.5407
1342.33	27.1139
1345.51	27.6533
1348.69	27.7173
1351.87	28.1698
1355.04	27.6042
1358.22	25.42
1361.39	24.7545
1364.57	24.8102
1367.74	23.1431
1370.91	21.1251
1374.07	20.2564
1377.24	20.2743
1380.41	20.5748
1383.57	21.8864
1386.74	21.3981
1389.9	20.4391
1393.06	20.4157
1396.22	20.3213
1399.38	21.5136
1402.54	20.7576
1405.7	21.061
1408.85	20.6898
1412.01	22.0387
1415.16	23.0777
1418.31	24.454
1421.46	25.8922
1424.61	28.3826
1427.76	30.7387
1430.91	32.9937
1434.05	34.6064
1437.2	35.8392
1440.34	37.2348
1443.49	38.3788
1446.63	38.8811
1449.77	39.9753
1452.91	39.9818
1456.04	39.1021
1459.18	39.7108
1462.31	39.0565
1465.45	38.5767
1468.58	36.8074
1471.71	36.6068
1474.84	35.3345
1477.97	33.6386
1481.1	31.6206
1484.23	31.4238
1487.35	29.0402
1490.48	27.9623
1493.6	26.5645
1496.72	25.7139
1499.84	23.793
1502.96	21.3127
1506.08	18.79
1509.2	17.1606
1512.31	17.4455
1515.43	14.8225
1518.54	13.439
1521.66	11.9406
1524.77	10.5702
1527.88	8.8459
1530.99	7.9457
1534.09	8.04838
1537.2	8.82066
1540.31	9.776
1543.41	9.71267
1546.51	11.0334
1549.62	12.4946
1552.72	14.2061
1555.82	14.0895
1558.91	16.2044
1562.01	17.8199
1565.11	17.3134
1568.2	19.7129
1571.3	21.7438
1574.39	22.9808
1577.48	24.5373
1580.57	25.9741
1583.66	27.5201
1586.75	28.6138
1589.83	29.2252
1592.92	29.1037
1596	29.5283
1599.09	30.089
1602.17	30.4634
1605.25	30.4863
1608.33	30.077
1611.41	29.8449
1614.48	28.2046
1617.56	27.0177
1620.64	26.9737
1623.71	25.6569
1626.78	24.9396
1629.86	24.0819
1632.92	23.4038
1635.99	23.3691
1639.06	22.8713
1642.13	23.0418
1645.19	25.0843
1648.26	24.4517
1651.32	24.7592
1654.38	24.8343
1657.45	24.141
1660.51	24.1644
1663.57	23.176
1666.62	23.196
1669.68	23.3438
1672.73	24.4031
1675.79	24.7155
1678.84	24.2604
1681.89	22.6769
1684.94	20.8068
1687.99	19.6752
1691.04	19.4028
1694.09	17.8717
1697.14	15.5436
1700.18	14.4403
1703.22	12.7805
1706.27	11.5355
1709.31	10.429
1712.35	9.1507
1715.39	7.71408
1718.43	7.16356
1721.46	4.93632
1724.5	4.61368
1727.53	5.94176
1730.57	6.2816
1733.6	5.54846
1736.63	5.24248
1739.66	6.58458
1742.69	7.16639
1745.72	7.76275
1748.74	8.55454
1751.77	7.75715
1754.8	7.35349
1757.82	6.90359
1760.84	6.08443
1763.86	6.32807
1766.88	5.67825
1769.9	3.74321
1772.92	3.59619
1775.93	2.52279
1778.95	2.45324
1781.96	1.40447
1784.98	0.91518
1787.99	0.247933
1791	0.684559
1794.01	0.847371
1797.02	1.46819
1800.03	2.01496
1803.03	2.83962
1806.04	2.57997
1809.04	3.21341
1812.04	3.27994
1815.05	4.13636
1818.05	4.78057
1821.05	4.50612
1824.05	4.18174
1827.04	5.2981
1830.04	5.42872
1833.03	5.92278
1836.03	6.22777
1839.02	6.7332
1842.01	6.7498
1845	6.82139
1847.99	7.41782
1850.98	7.95426
1853.97	9.21127
1856.95	7.69151
1859.94	8.32082
1862.92	8.00976
1865.91	7.13615
1868.89	4.99596
1871.87	4.33032
1874.85	3.94825
1877.83	3.97399
1880.8	3.67743
1882.56	3.33526
1885.54	3.21086
1888.53	3.46192
1891.52	3.74721
1894.5	3.22361
1897.49	4.34463
1900.47	4.55722
1903.45	5.38443
1906.43	6.07657
1909.41	7.59075
1912.39	8.19145
1915.37	8.89023
1918.35	9.93044
1921.32	10.7373
1924.3	9.73199
1927.27	8.39495
1930.24	8.34429
1933.21	8.33482
1936.18	7.82804
1939.15	7.42286
1942.12	7.07252
1945.09	7.06813
1948.05	7.42532
1951.02	7.25027
1953.98	7.91719
1956.94	7.20119
1959.91	7.16025
1962.87	7.24648
1965.82	7.2304
1968.78	7.10197
1971.74	7.34491
1974.7	8.05465
1977.65	9.66496
1980.6	8.59543
1983.56	8.35472
1986.51	7.82539
1989.46	8.01722
1992.41	8.5249
1995.36	7.40799
1998.3	6.70052
2001.25	7.04852
2004.2	6.76815
2007.14	6.62395
2010.08	6.07105
2013.02	5.63158
2015.97	5.29499
2018.9	5.07379
2021.84	5.50649
2024.78	5.72015
2027.72	6.40058
2030.65	6.97737
2033.59	6.96879
2036.52	8.19909
2039.45	9.66709
2042.38	11.4698
2045.31	12.0128
2048.24	12.7106
2051.17	13.0281
2054.1	11.984
2057.02	12.138
2059.95	11.8052
2062.87	12.4
2065.79	11.5069
2068.71	9.63369
2071.63	9.04124
2074.55	9.04336
2077.47	7.87493
2080.39	8.73993
2083.3	8.69684
2086.22	9.48758
2089.13	9.16961
2092.05	9.85959
2094.96	10.2778
2097.87	11.7604
2100.78	13.0838
2103.69	13.0662
2106.59	13.2654
2109.5	13.867
2112.41	14.315
2115.31	14.7764
2118.21	14.3343
2121.12	15.0815
2124.02	15.2419
2126.92	15.2376
2129.82	15.4386
2132.71	15.7116
2135.61	17.0253
2138.51	18.2475
2141.4	19.3331
2144.29	21.5084
2147.19	22.7985
2150.08	25.6001
2152.97	28.136
2155.86	30.303
2158.75	31.127
2161.64	31.5167
2164.52	31.8219
2167.41	32.561
2170.29	33.1987
2173.17	33.3189
2176.06	33.368
2178.94	32.4539
2181.82	31.0846
2184.7	31.3195
2187.57	30.609
2190.45	29.1412
2193.33	27.9221
2196.2	25.9053
2199.08	24.1362
2201.95	22.2467
2204.82	21.0869
2207.69	19.9346
2210.56	19.3399
2213.43	18.3633
2216.3	18.4638
2219.16	17.5082
2222.03	17.6794
2224.89	16.6688
2227.75	15.6993
2230.62	14.4648
2233.48	14.2616
2236.34	13.9824
2239.2	13.864
2242.06	13.8445
2244.91	13.8566
2247.77	12.9984
2250.62	13.625
2253.48	14.4781
2256.33	14.9413
2259.18	13.9786
2262.03	14.7954
2264.88	14.984
2267.73	14.6636
2270.58	14.7434
2273.43	15.4782
2276.27	15.717
2279.12	15.7004
2281.96	15.8626
2284.8	16.273
2287.64	16.2697
2290.49	16.1887
2293.32	14.833
2296.16	13.9233
2299	14.0091
2301.84	13.5678
2304.67	13.8532
2307.51	12.9881
2310.34	13.7686
2313.17	13.5444
2316	12.4072
2318.83	11.461
2321.66	11.5402
2324.49	10.4557
2327.32	9.78319
2330.15	8.90461
2332.97	9.15163
2335.79	7.89535
2338.62	7.32953
2341.44	6.89764
2344.26	5.77837
2347.08	4.90797
2349.9	4.85824
2352.72	4.18114
2355.53	3.36533
2358.35	3.23003
2361.17	2.61702
2363.98	2.02601
2366.79	3.55485
2369.6	3.76545
2372.42	3.8564
2375.22	3.74712
2378.03	3.4062
2380.84	3.14772
2383.65	1.95508
2386.45	1.67049
2389.26	2.03546
2392.06	1.6894
2394.87	2.03053
2397.67	2.71016
2400.47	2.32825
2403.27	3.10426
2406.07	3.32888
2408.86	4.58612
2411.66	5.91414
2414.46	6.52658
2417.25	7.19975
2420.05	8.11031
2422.84	8.19648
2425.63	8.87926
2428.42	10.3715
2431.21	10.2566
2434	9.68209
2436.79	9.8793
2439.57	9.51575
2442.36	9.57239
2445.14	8.38444
2447.93	6.94804
2450.71	6.02271
2453.49	5.33057
2456.27	4.39227
2459.05	3.15659
2461.83	2.58287
2464.61	2.14
2467.39	1.34443
2470.16	0.965213
2472.94	1.37455
2475.71	1.98143
2478.48	2.21431
2481.25	1.98667
2484.02	1.88256
2486.8	2.20992
2489.56	2.37703
2492.33	2.83046
2495.1	3.32263
2497.86	3.37179
2500.63	2.6303
2503.39	3.31281
2506.16	2.53146
2508.92	2.63424
2511.68	2.36772
2514.44	2.26481
2517.2	2.06763
2519.95	1.87911
2522.71	1.79375
2525.47	1.65155
2528.22	1.3424
2530.98	1.79485
2533.73	2.28258
2536.48	2.09713
2539.23	1.33142
2541.98	2.10982
2544.73	2.19555
2547.48	2.06102
2550.23	1.78622
2552.97	1.58585
2555.72	1.65026
2558.46	2.92827
2561.2	3.74037
2563.95	2.97892
2566.69	3.55332
2569.43	3.89689
2572.17	4.11082
2574.91	5.24567
2577.64	4.43195
2580.38	3.78444
2583.11	3.70305
2585.85	3.28949
2588.58	3.60399
2591.31	3.35751
2594.04	3.08528
2596.78	2.48369
2599.51	2.9404
2602.23	3.16813
2604.96	2.16455
2607.69	1.93873
2610.41	2.68451
2613.14	3.49358
2615.86	5.1024
2618.58	5.96037
2621.3	7.50345
2624.03	8.18634
2626.75	8.14961
2629.46	8.23121
2632.18	7.49812
2634.9	7.39622
2637.61	6.90785
2640.33	5.71472
2643.04	5.4455
2645.76	4.69137
2648.47	4.67078
2651.18	5.35821
2653.89	5.00965
2656.6	4.73934
2659.31	4.00364
2662.01	5.31968
2664.72	5.17509
2667.43	5.84591
2670.13	5.24563
2672.83	5.90949
2675.53	6.90826
2678.24	8.81429
2680.94	9.44698
2683.64	9.15112
2686.34	9.2188
2689.03	9.02519
2691.73	8.60719
2694.43	7.41856
2697.12	7.18894
2699.81	5.80328
2702.51	5.45095
2705.2	4.61112
2707.89	3.92402
2710.58	4.55526
2713.27	4.46965
2715.96	3.97236
2718.64	4.35502
2721.33	4.72122
2724.01	4.98258
2726.7	4.98112
2729.38	4.87815
2732.06	5.07264
2734.75	4.62576
2737.43	4.40215
2740.11	4.93982
2742.78	4.34154
2745.46	4.00433
2748.14	3.11172
2750.81	3.14994
2753.49	3.82762
2756.16	3.86254
2758.84	2.68289
2761.51	2.82409
2764.18	2.23757
2766.85	1.98718
2769.52	1.76771
2772.19	2.23204
2774.85	2.14221
2777.52	2.9586
2780.18	3.07252
2782.85	3.82077
2785.51	4.82604
2788.17	5.13797
2790.84	5.54868
2793.5	5.24116
2796.16	5.2896
2798.81	5.23876
2801.47	4.47152
2804.13	4.18562
2806.79	3.85482
2809.44	3.27829
2812.09	2.7412
2814.75	2.95272
2817.4	3.08896
2820.05	3.33199
2822.7	3.00422
2825.35	3.51539
2828	3.79873
2830.65	5.38096
2833.29	7.15155
2835.94	8.38317
2838.58	10.0454
2841.23	11.6358
2843.87	13.2137
2846.51	15.6312
2849.15	17.9947
2851.79	21.0076
2854.43	23.1262
2857.07	25.5224
2859.71	28.2439
2862.34	30.201
2864.98	31.8126
2867.61	32.5431
2870.25	32.8727
2872.88	33.7161
2875.51	34.5
2878.14	35.2431
2880.77	36.0876
2883.4	36.6692
2886.03	36.8911
2888.65	37.7508
2891.28	39.0074
2893.91	40.2073
2896.53	41.7244
2899.15	42.5797
2901.78	44.3344
2904.4	46.3456
2907.02	48.14
2909.64	49.7449
2912.26	52.3041
2914.87	55.9199
2917.49	59.9421
2920.11	61.6585
2922.72	63.3992
2925.34	64.6364
2927.95	64.8272
2930.56	65.2044
2933.17	65.1999
2935.78	64.8268
2938.39	64.9937
2941	63.7007
2943.61	62.4939
2946.22	60.7368
2948.82	59.1488
2951.43	57.2682
2954.03	54.3958
2956.64	52.6753
2959.24	50.0529
2961.84	47.1556
2964.44	45.4268
2967.04	43.2787
2969.64	42.2764
2972.24	40.0623
2974.83	38.3359
2977.43	36.5657
2980.02	35.22
2982.62	32.5597
2985.21	29.3197
2987.8	27.564
2990.4	24.7786
2992.99	22.1582
2995.57	19.7008
2998.16	16.8005
3000.75	15.1896
3003.34	13.0507
3005.92	11.078
3008.51	8.97166
3011.09	6.53058
3013.68	5.16558
3016.26	2.22683
3018.84	0.407146
3021.42	0.823476
3024	0.207659
3026.58	0.715948
3029.16	0.506273
3031.73	1.14378
3034.31	1.10118
3036.89	1.41067
3039.46	1.82162
3042.03	2.43612
3044.61	3.48526
3047.18	3.53162
3049.75	4.70584
3052.32	5.31578
3054.89	5.64634
3057.45	5.76805
3060.02	6.20283
3062.59	7.24441
3065.15	7.36743
3067.72	7.86088
3070.28	7.01628
3072.84	5.70364
3075.41	5.55598
3077.97	4.58262
3080.53	4.07018
3083.09	4.70078
3085.64	4.03766
3088.2	4.09355
3090.76	4.06185
3093.31	3.99916
3095.87	4.82914
3098.42	4.9021
3100.97	5.79894
3103.53	6.77976
3106.08	7.77664
3108.63	8.60805
3111.18	10.1936
3113.73	11.3517
3116.27	12.2748
3118.82	13.0345
3121.37	14.2692
3123.91	15.0633
3126.45	16.5367
3129	16.3764
3131.54	16.9317
3134.08	16.8379
3136.62	17.3401
3139.16	16.764
3141.7	16.7988
3144.24	16.9414
3146.78	17.5325
3149.31	17.5047