File: data/Raman/poly_smoothed/Mb_40_24_01_1x_45s_532 nm_x100_100%_600 gr_mm_02.txt
#Acq. time (s)=	45
#Accumulations=	2
#Range (cm-¹)=	200...3150
#Windows=	2
#Auto scanning=	Off
#Autofocus=	Off
#Macrospot=	Off
#AutoExposure=	Off
#Spike filter=	Multiple accum.
#Delay time (s)=	0
#Binning=	1
#Readout mode=	Signal
#DeNoise=	Off
#ICS correction=	On
#Dark correction=	Off
#Inst. Process=	Off
#Detector Gain=	Best Dynamic Range
#Detector ADC=	20 kHz
#Detector temperature (°C)=	-70.08
#Instrument=	LabRAM HR Evol
#Detector=	Synapse
#Objective=	x100
#Grating=	600 gr/mm
#ND Filter=	100%
#Laser (nm)=	532
#Hole=	100.021
#Range=	Auto
#Laser Pol.=	No
#Raman. Pol.=	No
#Laser Pol. (°)=	-0.0007625
#Raman Pol. (°)=	89.9995
#Collection=	Microscope
#StageXY=	Marzhauser
#StageZ=	Marzhauser
#X (µm)=	-2554.1
#Y (µm)=	-24.1
#Z (µm)=	-10.35
#Full time(mm:ss)=	3:19
#Project=
#Sample=
#Site=
#Title=	Mb_40_24_01_2x_45s_532 nm_x100_100%_600 gr_mm
#Remark=
#Date=	14.07.2022 10:42
#Acquired=	14.07.2022 10:42:40
#Base:Fit=	10.08.2022 10:47:00
#Base:Sub=	10.08.2022 10:47:12
#Filter:Polynom=	16.08.2022 10:11:48
#AxisType[0]=Intens
#AxisUnit[0]=Cnt
#AxisType[1]=Spectr
#AxisUnit[1]=1/cm
200.554	46.374
204.183	35.1175
207.813	29.5668
211.439	25.5486
215.065	22.3737
218.688	18.2927
222.312	16.6436
225.933	16.6797
229.552	13.2157
233.171	12.1026
236.787	11.6764
240.402	9.7649
244.015	7.45022
247.627	5.95062
251.24	4.91704
254.849	4.35638
258.457	4.83889
262.063	5.54296
265.668	8.5999
269.271	6.61928
272.873	8.17154
276.474	5.7275
280.073	3.96267
283.671	4.07791
287.268	4.22758
290.863	5.25105
294.456	6.83609
298.049	6.84935
301.637	6.94254
305.227	7.59303
308.815	8.78251
312.402	11.6566
315.987	11.6835
319.569	11.6658
323.151	13.2813
326.733	12.5501
330.31	11.5385
333.889	13.6939
337.464	15.4835
341.039	19.3486
344.611	18.0223
348.184	18.4484
351.754	18.5997
355.324	17.252
358.89	15.0177
362.455	14.4992
366.021	13.7149
369.584	13.4022
373.145	13.8762
376.707	14.8779
380.265	16.3878
383.822	16.4334
387.378	16.9697
390.934	18.9497
394.487	18.0739
398.038	18.2864
401.588	17.9966
405.137	18.0002
408.685	18.589
412.23	18.4072
415.775	19.0221
419.318	19.5255
422.86	20.2195
426.401	19.327
429.94	17.7095
433.478	16.9861
437.012	18.3725
440.547	16.3005
444.081	15.6729
447.613	17.1315
451.142	18.4348
454.672	19.3375
458.2	19.2751
461.725	22.6541
465.251	23.885
468.775	25.9476
472.296	27.8071
475.817	28.9374
479.335	30.4101
482.854	32.6205
486.37	34.0854
489.886	35.1096
493.398	34.1087
496.91	35.0451
500.422	37.4968
503.93	37.1886
507.438	39.7466
510.946	40.7782
514.45	42.1947
517.954	45.8807
521.456	46.1817
524.956	46.2654
528.456	46.7372
531.956	45.8051
535.452	43.9509
538.947	43.6658
542.441	42.8035
545.934	45.3521
549.425	46.089
552.915	45.3423
556.403	45.1649
559.889	46.2848
563.375	45.0323
566.859	42.2538
570.342	38.3352
573.824	32.3618
577.303	27.888
580.782	25.9089
584.26	23.3571
587.734	22.0616
591.21	20.3738
594.684	19.1365
598.154	19.1186
601.626	17.6701
605.094	17.278
608.562	16.4158
612.027	16.9957
615.493	14.9944
618.956	14.8006
622.419	18.5932
625.879	22.8729
629.338	24.2556
632.797	27.3321
636.254	29.466
639.708	29.1452
643.162	30.8557
646.614	30.4247
650.067	28.1388
653.516	26.6509
656.964	23.4082
660.411	20.4441
663.857	19.9625
667.301	15.8489
670.744	12.9429
674.186	12.5283
677.626	11.7884
681.065	13.3554
684.503	12.6333
687.939	11.1064
691.372	10.9399
694.806	9.4316
698.239	10.2877
701.67	10.3639
705.098	13.2448
708.526	14.8833
711.954	14.3025
715.378	14.8332
718.802	16.7267
722.226	16.0313
725.646	15.6992
729.067	16.9095
732.484	18.5992
735.902	19.7353
739.317	19.4666
742.731	18.9737
746.145	20.8642
749.556	23.0697
752.966	25.3082
756.377	32.9951
759.784	35.8996
763.19	37.1427
766.594	41.5737
770	43.4186
773.402	45.4456
776.803	50.2684
780.202	55.0489
783.6	59.4191
786.997	62.328
790.393	64.1569
793.787	65.2327
797.18	66.9299
800.572	68.9816
803.963	69.9456
807.35	68.4489
810.738	66.0012
814.125	65.5262
817.51	65.9144
820.894	64.204
824.275	66.2075
827.657	70.4516
831.037	75.5911
834.414	80.0307
837.792	83.6105
841.167	86.9664
844.542	86.6909
847.914	88.9774
851.287	90.0063
854.656	91.5183
858.026	91.503
861.393	92.5154
864.761	89.4551
868.125	88.0426
871.489	82.384
874.85	78.346
878.213	74.6639
881.572	66.6217
884.931	59.5136
888.287	50.1762
891.643	44.1711
894.997	38.9488
898.352	38.6789
901.704	39.61
905.055	41.0296
908.404	44.1519
911.75	45.2916
915.097	46.0173
918.443	46.4906
921.787	45.317
925.13	44.4942
928.472	43.0664
931.813	41.0992
935.15	41.2346
938.488	39.1335
941.825	37.1749
945.158	32.0847
948.493	28.3898
951.824	24.3127
955.156	20.5851
958.486	18.4513
961.814	14.9281
965.142	15.6939
968.467	20.5646
971.79	26.9299
975.115	30.1756
978.436	35.0102
981.756	39.2887
985.077	40.7759
988.394	40.7009
991.71	42.565
995.025	40.721
998.341	39.2876
1001.65	36.5084
1004.97	34.436
1008.28	31.7386
1011.58	35.3445
1014.89	41.667
1018.2	49.9886
1021.5	57.787
1024.81	66.2129
1028.11	72.5005
1031.41	78.5965
1034.71	83.7882
1038.01	90.4178
1041.31	96.7341
1044.6	101.899
1047.9	107.116
1051.19	108.622
1054.48	108.768
1057.77	105.148
1061.06	101.345
1064.35	96.1778
1067.64	88.9595
1070.93	80.2472
1074.21	69.6725
1077.49	58.821
1080.78	47.8469
1084.06	38.8489
1087.34	33.781
1090.61	31.9808
1093.89	33.8628
1097.17	35.9298
1100.44	35.9011
1103.71	35.8963
1106.99	34.3183
1110.26	32.1111
1113.52	29.4871
1116.79	27.4629
1120.06	24.2858
1123.32	21.9031
1126.59	19.5834
1129.85	18.5501
1133.11	17.9532
1136.37	16.2117
1139.63	15.4459
1142.89	13.2946
1146.15	11.4708
1149.4	8.0966
1152.66	5.80262
1155.91	5.75444
1159.16	5.13967
1162.41	2.76592
1165.66	1.26506
1168.91	2.77876
1172.16	2.20994
1175.4	1.19278
1178.65	0.986688
1181.89	1.62053
1185.13	3.98383
1188.37	4.6096
1191.61	3.771
1194.85	3.81143
1198.08	4.89897
1201.32	8.17624
1204.55	12.0604
1207.79	14.9366
1211.02	18.7939
1214.25	22.0073
1217.48	24.4992
1220.71	28.1279
1223.93	31.2911
1227.16	34.9727
1230.38	39.4056
1233.6	42.8288
1236.83	46.0947
1240.05	49.8301
1243.26	52.983
1246.48	55.6497
1249.7	57.5255
1252.92	59.6623
1256.13	60.0238
1259.34	65.1657
1262.55	68.5953
1265.76	70.4204
1268.97	74.7226
1272.18	78.9696
1275.39	84.8328
1278.59	91.4163
1281.8	95.622
1285	101.793
1288.2	107.637
1291.4	110.737
1294.6	115.996
1297.8	121.196
1301	126.161
1304.19	128.744
1307.39	130.099
1310.58	129.761
1313.77	129.195
1316.96	128.629
1320.15	125.441
1323.34	122.001
1326.53	120.006
1329.72	115.85
1332.9	111.538
1336.08	111.344
1339.27	109.872
1342.45	106.592
1345.63	105.14
1348.8	104.297
1351.98	102.68
1355.16	103.842
1358.33	102.959
1361.51	102.898
1364.68	102.746
1367.85	104.482
1371.02	106.281
1374.19	109.598
1377.36	110.97
1380.52	112.921
1383.69	114.493
1386.85	116.775
1390.02	120.342
1393.18	123.435
1396.34	125.562
1399.5	129.263
1402.65	135.245
1405.81	141.362
1408.97	148.569
1412.12	158.463
1415.27	166.096
1418.43	176.074
1421.58	184.556
1424.73	196.862
1427.87	207.756
1431.02	218.312
1434.17	227.636
1437.31	233.449
1440.46	237.77
1443.6	239.395
1446.74	238.816
1449.88	236.411
1453.02	230.721
1456.16	221.478
1459.29	212.563
1462.43	198.336
1465.56	186.833
1468.69	170.331
1471.83	155.47
1474.95	138.639
1478.08	122.608
1481.21	108.174
1484.34	93.8678
1487.47	82.5826
1490.59	71.7309
1493.71	63.3355
1496.84	57.9502
1499.96	55.2182
1503.07	53.1512
1506.19	51.7604
1509.31	50.4615
1512.43	49.1379
1515.54	46.7027
1518.65	46.4332
1521.77	46.9198
1524.88	47.0721
1527.99	47.0118
1531.1	47.5753
1534.21	50.6841
1537.31	54.5894
1540.42	57.5878
1543.52	59.9597
1546.63	62.0274
1549.73	63.3644
1552.83	65.3279
1555.93	69.2319
1559.03	72.1984
1562.12	75.7199
1565.22	82.0299
1568.31	86.1881
1571.41	94.1067
1574.5	99.0642
1577.59	103.511
1580.68	108.378
1583.77	114.258
1586.86	116.643
1589.95	119.704
1593.03	123.762
1596.11	128.648
1599.2	130.769
1602.28	132.162
1605.36	134.557
1608.44	136.198
1611.52	136.348
1614.6	134.698
1617.67	133.001
1620.75	134.061
1623.82	133.856
1626.89	134.213
1629.96	134.55
1633.04	136.92
1636.11	137.445
1639.17	137.623
1642.24	138.502
1645.31	138.737
1648.37	136.775
1651.43	133.718
1654.5	133.166
1657.56	130.724
1660.62	126.611
1663.67	123.101
1666.73	118.048
1669.79	112.533
1672.84	106.557
1675.9	100.183
1678.95	94.4089
1682	87.2023
1685.05	79.2137
1688.1	74.2061
1691.15	69.7941
1694.2	63.9523
1697.25	60.054
1700.29	57.1673
1703.33	52.4586
1706.38	48.6851
1709.42	46.4664
1712.46	42.8238
1715.5	39.3414
1718.54	36.7622
1721.57	34.4509
1724.61	32.3751
1727.64	30.161
1730.68	28.3157
1733.71	27.1029
1736.74	26.4294
1739.77	24.5604
1742.8	21.8445
1745.83	20.0558
1748.85	19.1851
1751.88	20.1286
1754.91	17.3032
1757.93	16.267
1760.95	14.3959
1763.97	13.6538
1766.99	11.0978
1770.01	9.40236
1773.03	9.09718
1776.04	6.78558
1779.06	7.04086
1782.07	6.94791
1785.09	6.59766
1788.1	6.47113
1791.11	6.58081
1794.12	5.30816
1797.13	4.73351
1800.13	4.92338
1803.14	4.14928
1806.15	3.54294
1809.15	3.60849
1812.15	1.60965
1815.16	0.545361
1818.15	-0.574697
1821.16	0.196091
1824.15	1.54947
1827.15	2.05631
1830.15	1.68695
1833.14	1.25773
1836.14	1.34424
1839.13	3.02058
1842.12	4.76193
1845.11	7.06028
1848.1	8.08502
1851.09	7.92141
1854.08	9.82502
1857.06	11.1414
1860.05	13.4826
1863.03	12.9743
1866.01	13.3274
1869	14.4844
1871.98	14.0065
1874.96	14.2949
1877.93	14.0792
1880.91	12.5745
1882.47	11.8175
1885.46	10.9397
1888.44	11.2011
1891.43	10.2804
1894.42	9.74336
1897.4	9.44927
1900.39	7.55632
1903.37	6.29246
1906.35	6.2592
1909.33	6.12191
1912.31	6.81443
1915.29	7.42795
1918.26	6.06601
1921.24	3.75658
1924.21	3.871
1927.19	5.6556
1930.16	6.05023
1933.13	5.89561
1936.1	5.50733
1939.07	5.38732
1942.04	5.23118
1945	4.90428
1947.97	4.2645
1950.93	4.13408
1953.9	4.45452
1956.86	4.5896
1959.82	6.36815
1962.78	7.21848
1965.74	8.42519
1968.7	8.7028
1971.65	10.9667
1974.61	10.908
1977.57	10.5766
1980.52	11.3515
1983.47	12.5698
1986.42	13.4726
1989.37	13.6855
1992.32	13.4463
1995.27	15.3161
1998.22	17.0761
2001.17	17.899
2004.11	18.8193
2007.05	17.942
2010	18.6667
2012.94	17.4799
2015.88	18.2944
2018.82	18.5083
2021.76	18.7841
2024.7	18.1726
2027.63	20.2198
2030.57	20.5502
2033.5	21.3698
2036.44	19.6928
2039.37	21.6762
2042.3	20.1648
2045.23	19.3728
2048.16	18.6888
2051.08	18.2388
2054.01	20.232
2056.94	19.6893
2059.86	20.2725
2062.79	19.3563
2065.71	21.315
2068.63	23.569
2071.55	25.7697
2074.47	28.0077
2077.39	29.6056
2080.31	31.1963
2083.22	34.4098
2086.13	36.5949
2089.05	39.6543
2091.96	42.9806
2094.87	45.5767
2097.78	47.087
2100.69	49.531
2103.6	49.9938
2106.51	52.8895
2109.42	54.974
2112.32	57.4292
2115.23	59.6584
2118.13	61.5182
2121.03	62.8531
2123.93	66.1189
2126.83	68.2422
2129.73	70.801
2132.63	74.1397
2135.53	76.9189
2138.42	81.3065
2141.32	85.059
2144.21	89.3736
2147.1	92.1109
2150	95.1871
2152.89	99.4486
2155.78	102.438
2158.66	104.334
2161.55	106.53
2164.44	109.929
2167.32	111.514
2170.21	111.526
2173.09	111.625
2175.97	110.276
2178.85	110.389
2181.73	108.294
2184.61	105.09
2187.49	101.918
2190.37	99.9374
2193.24	96.563
2196.12	93.2372
2198.99	89.573
2201.87	86.5326
2204.74	83.5372
2207.61	78.9566
2210.48	74.6851
2213.35	72.4283
2216.21	67.0855
2219.08	63.5739
2221.95	60.5251
2224.81	57.6794
2227.67	54.8497
2230.54	54.1102
2233.4	54.1628
2236.26	52.0793
2239.11	50.0817
2241.97	47.0007
2244.83	45.309
2247.69	42.5019
2250.54	41.3415
2253.4	38.9149
2256.25	37.2985
2259.1	36.7914
2261.95	34.1153
2264.8	32.3665
2267.65	31.093
2270.5	29.1486
2273.34	27.5857
2276.19	25.3834
2279.03	23.1152
2281.88	21.8125
2284.72	21.4287
2287.56	18.6916
2290.4	17.7205
2293.24	15.8966
2296.08	15.8403
2298.92	16.6557
2301.76	16.2049
2304.59	16.4374
2307.43	16.9387
2310.26	17.8318
2313.09	17.6096
2315.92	17.1476
2318.75	18.3219
2321.58	17.925
2324.41	17.7317
2327.24	17.8923
2330.06	17.6595
2332.89	18.458
2335.71	17.5704
2338.54	18.0659
2341.36	17.7887
2344.18	17.4589
2347	16.2644
2349.82	15.7374
2352.64	14.7412
2355.45	13.766
2358.27	11.8932
2361.08	9.36264
2363.9	8.6893
2366.71	7.7244
2369.52	7.01666
2372.33	7.30303
2375.14	7.1332
2377.95	5.12048
2380.76	3.10967
2383.57	2.4197
2386.37	2.3268
2389.18	1.18137
2391.98	0.990532
2394.79	-0.319706
2397.59	-1.2311
2400.39	-0.253198
2403.19	1.0115
2405.99	1.99285
2408.78	3.4563
2411.58	4.93325
2414.38	6.34397
2417.17	7.30638
2419.97	10.5326
2422.76	10.6744
2425.55	10.565
2428.34	11.6592
2431.13	11.6543
2433.92	11.2107
2436.71	12.4342
2439.49	11.912
2442.28	11.5152
2445.06	10.629
2447.85	10.3878
2450.63	9.84446
2453.41	9.60188
2456.19	9.12538
2458.97	9.32116
2461.75	7.18876
2464.53	6.07616
2467.31	7.07811
2470.08	7.0693
2472.86	7.17476
2475.63	7.30905
2478.4	8.31663
2481.17	7.74582
2483.94	7.99906
2486.72	8.63938
2489.48	8.53505
2492.25	8.53869
2495.02	8.27391
2497.79	7.16929
2500.55	6.81694
2503.31	5.90407
2506.08	4.90906
2508.84	3.98397
2511.6	4.28432
2514.36	2.67363
2517.12	2.61795
2519.88	2.37603
2522.63	1.95457
2525.39	2.08605
2528.14	1.54584
2530.9	1.3649
2533.65	2.6922
2536.4	3.27721
2539.15	4.21293
2541.9	6.29861
2544.65	6.27131
2547.4	8.25884
2550.15	8.48915
2552.89	10.3958
2555.64	11.0802
2558.38	10.8158
2561.12	10.4225
2563.87	9.70425
2566.61	9.80243
2569.35	8.66301
2572.09	5.74356
2574.83	5.00002
2577.56	4.88269
2580.3	3.66499
2583.04	3.12322
2585.77	2.78949
2588.5	1.98052
2591.23	1.19116
2593.97	2.03318
2596.7	2.40641
2599.43	2.92832
2602.15	3.23442
2604.88	3.42842
2607.61	4.08368
2610.33	3.57684
2613.06	3.4023
2615.78	3.25177
2618.51	3.482
2621.23	3.08706
2623.95	2.52098
2626.67	2.94578
2629.39	2.31642
2632.1	2.76873
2634.82	2.16767
2637.54	0.565713
2640.25	1.38089
2642.97	2.79739
2645.68	3.27759
2648.39	4.4005
2651.1	4.87267
2653.81	5.20936
2656.52	4.70039
2659.23	5.02038
2661.94	4.87987
2664.64	4.81541
2667.35	3.82337
2670.05	4.92423
2672.76	4.79334
2675.46	3.9484
2678.16	2.72658
2680.86	2.13313
2683.56	2.90612
2686.26	3.16773
2688.96	3.29516
2691.65	4.19601
2694.35	5.14843
2697.04	5.16523
2699.74	6.8185
2702.43	7.58024
2705.12	8.99923
2707.81	11.5498
2710.5	14.6453
2713.19	16.4435
2715.88	17.9318
2718.57	19.2488
2721.25	19.5051
2723.94	19.0138
2726.62	19.1727
2729.3	19.0751
2731.99	19.4722
2734.67	18.2725
2737.35	15.9921
2740.03	12.7905
2742.71	10.4811
2745.38	9.36142
2748.06	6.49529
2750.74	4.19986
2753.41	2.85398
2756.09	1.50428
2758.76	-0.388398
2761.43	-0.62677
2764.1	-1.51157
2766.77	-1.4705
2769.44	-0.730148
2772.11	-0.49955
2774.77	1.31429
2777.44	2.03649
2780.11	3.52861
2782.77	3.49325
2785.43	4.65601
2788.1	4.60166
2790.76	5.03431
2793.42	6.37504
2796.08	6.13741
2798.74	5.46151
2801.4	4.23934
2804.05	3.55892
2806.71	2.18006
2809.36	1.8402
2812.02	-0.590374
2814.67	-1.11354
2817.32	2.24063
2819.97	6.09526
2822.62	13.2449
2825.27	22.7077
2827.92	35.0052
2830.57	47.2419
2833.22	60.8601
2835.86	74.2612
2838.51	90.699
2841.15	106.369
2843.79	123.815
2846.43	140.427
2849.08	159.155
2851.72	179.116
2854.36	199.005
2856.99	217.805
2859.63	234.806
2862.27	251.434
2864.9	268.146
2867.54	282.187
2870.17	293.809
2872.8	305.099
2875.43	316.103
2878.07	327.556
2880.7	340.399
2883.32	352.665
2885.95	364.262
2888.58	376.882
2891.21	389.131
2893.83	400.7
2896.46	412.617
2899.08	423.354
2901.7	435.74
2904.32	450.587
2906.94	465.345
2909.56	482.882
2912.18	500.841
2914.8	521.392
2917.42	538.64
2920.03	553.897
2922.65	564.457
2925.26	572.844
2927.88	576.901
2930.49	575.613
2933.1	568.567
2935.71	558.821
2938.32	545.514
2940.93	527.799
2943.54	509.017
2946.14	484.942
2948.75	460.196
2951.35	434.086
2953.96	407.845
2956.56	382.356
2959.16	356.878
2961.77	332.096
2964.37	310.374
2966.96	290.772
2969.56	273.383
2972.16	257.659
2974.76	244.871
2977.35	233.072
2979.95	219.846
2982.54	207.283
2985.14	195.03
2987.73	180.287
2990.32	166.234
2992.91	150.821
2995.5	135.659
2998.09	119.527
3000.68	105.102
3003.26	89.6366
3005.85	76.8088
3008.43	62.9257
3011.02	49.7053
3013.6	40.9778
3016.19	31.2966
3018.77	24.007
3021.35	17.388
3023.93	12.1865
3026.5	7.14665
3029.08	3.18129
3031.66	0.0483496
3034.24	-1.20139
3036.81	-0.829736
3039.39	0.0164128
3041.96	0.052587
3044.53	-0.0118635
3047.1	1.87468
3049.67	2.2037
3052.24	3.26936
3054.81	3.9323
3057.38	3.56583
3059.95	3.08872
3062.52	3.02978
3065.08	2.12123
3067.65	2.23858
3070.21	1.79327
3072.77	1.67444
3075.33	2.11391
3077.89	1.62076
3080.45	1.59342
3083.01	0.30638
3085.57	0.555749
3088.13	-0.138688
3090.68	-0.969091
3093.24	0.0729143
3095.79	1.9191
3098.35	3.10285
3100.9	4.47586
3103.45	4.8065
3106	5.86925
3108.55	7.20046
3111.1	8.86884
3113.65	10.6804
3116.2	11.7839
3118.75	13.882
3121.29	15.2388
3123.84	18.1244
3126.38	20.0557
3128.92	23.0717
3131.47	26.607
3134.01	28.9778
3136.55	31.1253
3139.09	34.6922
3141.63	37.2429
3144.17	41.0734
3146.7	45.5666
3149.24	49.1923