File: data/Raman/poly_smoothed/Mb_40_y_33_1x_45s_532 nm_x100_100%_600 gr_mm_01.txt
#Acq. time (s)=	45
#Accumulations=	2
#Range (cm-¹)=	200...3150
#Windows=	2
#Auto scanning=	Off
#Autofocus=	Off
#Macrospot=	Off
#AutoExposure=	Off
#Spike filter=	Multiple accum.
#Delay time (s)=	0
#Binning=	1
#Readout mode=	Signal
#DeNoise=	Off
#ICS correction=	On
#Dark correction=	Off
#Inst. Process=	Off
#Detector Gain=	Best Dynamic Range
#Detector ADC=	20 kHz
#Detector temperature (°C)=	-69.85
#Instrument=	LabRAM HR Evol
#Detector=	Synapse
#Objective=	x100
#Grating=	600 gr/mm
#ND Filter=	100%
#Laser (nm)=	532
#Hole=	100.021
#Range=	Auto
#Laser Pol.=	No
#Raman. Pol.=	No
#Laser Pol. (°)=	-0.0007625
#Raman Pol. (°)=	89.9995
#Collection=	Microscope
#StageXY=	Marzhauser
#StageZ=	Marzhauser
#X (µm)=	-1106.5
#Y (µm)=	575.8
#Z (µm)=	584.1
#Full time(mm:ss)=	3:18
#Project=
#Sample=
#Site=
#Title=	Mb_40_y_33_2x_45s_532 nm_x100_100%_600 gr_mm
#Remark=
#Date=	19.07.2022 12:08
#Acquired=	19.07.2022 12:08:01
#Base:Fit=	10.08.2022 10:52:48
#Base:Sub=	10.08.2022 10:52:53
#Filter:Polynom=	16.08.2022 10:09:04
#AxisType[0]=Intens
#AxisUnit[0]=Cnt
#AxisType[1]=Spectr
#AxisUnit[1]=1/cm
200.423	51.2246
204.052	41.8832
207.682	34.2457
211.308	28.6242
214.935	22.9797
218.558	18.6195
222.18	12.7561
225.802	10.0881
229.421	7.38524
233.039	5.39085
236.657	6.39888
240.272	6.08039
243.885	5.63342
247.497	6.34148
251.11	6.42333
254.719	6.15529
258.327	6.97938
261.933	7.3661
265.538	8.01749
269.141	8.40074
272.744	8.92326
276.344	7.97553
279.944	6.91049
283.542	6.28848
287.138	5.74042
290.733	5.01452
294.327	6.4973
297.919	6.12719
301.508	4.82792
305.098	4.53247
308.686	2.86095
312.273	3.73134
315.858	4.50189
319.44	5.25839
323.022	6.76444
326.604	9.17089
330.181	9.90173
333.76	10.3296
337.335	10.8766
340.91	12.054
344.483	12.3066
348.055	13.2156
351.625	13.9399
355.195	14.25
358.762	12.6679
362.329	11.7326
365.893	11.0986
369.455	10.4142
373.017	11.6339
376.578	9.84472
380.137	9.91847
383.694	8.01152
387.249	6.78856
390.806	4.96642
394.359	3.06815
397.91	2.56693
401.46	1.75246
405.009	0.960639
408.557	0.7769
412.103	2.24491
415.647	3.04554
419.191	2.22349
422.733	3.43477
426.273	4.97521
429.812	6.73099
433.35	6.33915
436.885	6.97426
440.42	6.77934
443.954	8.01919
447.486	8.31601
451.015	7.90856
454.545	8.53051
458.073	9.54466
461.598	10.7189
465.124	11.5297
468.648	11.7562
472.169	10.9317
475.69	10.5
479.208	10.5715
482.727	10.9998
486.243	12.2141
489.759	12.6334
493.272	13.4838
496.783	15.5862
500.295	16.0124
503.804	16.1718
507.311	16.8303
510.819	18.3717
514.324	17.4991
517.827	16.8941
521.329	15.8729
524.83	16.1563
528.329	19.2015
531.829	18.4887
535.326	17.2661
538.821	17.9184
542.315	18.0536
545.808	16.9168
549.299	15.8648
552.789	14.272
556.278	12.2012
559.763	11.8216
563.249	10.7276
566.733	9.89262
570.217	8.30471
573.699	7.36517
577.177	5.07831
580.656	4.67095
584.134	4.29251
587.609	4.78155
591.084	3.54933
594.558	2.72784
598.029	1.69056
601.5	1.51436
604.968	2.84418
608.437	3.96319
611.902	6.24815
615.368	7.29897
618.831	6.81744
622.294	6.49811
625.755	7.45703
629.213	8.09766
632.673	9.79496
636.129	10.225
639.584	9.50645
643.037	8.70715
646.491	9.23671
649.942	9.5918
653.392	9.31315
656.84	11.1934
660.287	12.086
663.732	13.2284
667.177	14.6616
670.62	16.6258
674.061	17.3207
677.502	18.3108
680.941	19.5029
684.379	21.2379
687.815	24.4639
691.248	26.7075
694.682	29.7582
698.115	33.2696
701.546	34.0449
704.974	35.8291
708.402	39.0779
711.83	39.8892
715.254	41.3408
718.679	41.1675
722.102	40.7365
725.522	41.3635
728.943	41.9855
732.361	43.8457
735.779	45.0485
739.194	46.1609
742.608	47.8923
746.022	49.1357
749.433	50.2478
752.843	51.9511
756.254	53.2927
759.661	56.76
763.067	57.4428
766.471	60.3032
769.877	61.621
773.279	64.618
776.68	67.0729
780.079	68.7643
783.478	70.4649
786.875	71.2231
790.27	72.2036
793.665	72.8902
797.058	73.6068
800.45	73.8853
803.84	75.3052
807.23	75.4143
810.616	75.3075
814.002	75.123
817.388	74.6604
820.772	74.1756
824.153	73.8363
827.535	72.8009
830.915	71.8388
834.292	71.2378
837.67	70.6033
841.047	69.4491
844.42	67.9967
847.794	66.5479
851.165	63.7402
854.534	60.7946
857.905	59.1557
861.272	57.4601
864.639	55.9586
868.004	54.2764
871.367	53.695
874.731	52.3597
878.092	51.0687
881.451	49.7348
884.809	48.9562
888.166	47.1659
891.522	45.845
894.878	46.7178
898.231	46.2852
901.583	45.3189
904.934	45.4993
908.283	44.7874
911.631	44.0225
914.976	43.3415
918.322	43.2225
921.666	42.3004
925.009	41.4122
928.351	40.2145
931.692	39.2486
935.029	38.6184
938.367	40.6518
941.704	41.8562
945.038	41.024
948.372	40.5477
951.705	41.3173
955.035	41.1939
958.366	38.9245
961.693	38.5606
965.021	38.2923
968.346	37.3065
971.67	37.2421
974.995	36.8585
978.316	36.806
981.638	35.9136
984.957	33.3745
988.274	31.5363
991.59	28.9903
994.907	27.2759
998.221	22.7877
1001.53	19.374
1004.85	17.8333
1008.16	20.948
1011.46	29.034
1014.77	40.3673
1018.08	55.1277
1021.38	67.422
1024.69	78.8337
1027.99	89.9408
1031.29	101.066
1034.59	107.003
1037.89	112.442
1041.19	115.864
1044.48	118.18
1047.78	116.087
1051.07	112.549
1054.36	108.617
1057.66	101.239
1060.94	92.6966
1064.23	80.5068
1067.52	68.2672
1070.81	53.576
1074.09	38.9992
1077.38	25.955
1080.66	14.3721
1083.94	6.00517
1087.22	3.30266
1090.5	7.23392
1093.77	11.1089
1097.05	13.2054
1100.32	15.0659
1103.6	16.1411
1106.87	18.5445
1110.14	20.3897
1113.41	20.894
1116.67	23.003
1119.94	22.7634
1123.21	23.209
1126.47	23.5616
1129.73	21.9854
1133	22.6192
1136.26	23.1452
1139.52	20.7079
1142.77	19.1724
1146.03	17.5134
1149.29	15.8863
1152.54	14.6037
1155.79	13.4742
1159.04	11.7632
1162.3	9.20748
1165.55	9.15012
1168.79	8.54963
1172.04	7.35273
1175.28	4.41521
1178.53	3.06813
1181.77	3.23309
1185.01	3.15903
1188.25	3.79998
1191.49	3.98945
1194.73	4.78103
1197.97	4.965
1201.2	4.77447
1204.44	6.50714
1207.67	8.72769
1210.9	12.1226
1214.13	15.3939
1217.36	19.1918
1220.59	20.9013
1223.82	23.2279
1227.04	26.9287
1230.26	29.9098
1233.49	32.2122
1236.71	33.6552
1239.93	35.4762
1243.15	37.1931
1246.37	40.2495
1249.58	41.0454
1252.8	43.2703
1256.01	44.4733
1259.23	45.6022
1262.44	47.4028
1265.65	47.3251
1268.86	49.3102
1272.07	49.5913
1275.27	50.0143
1278.48	51.2644
1281.68	52.4641
1284.89	53.5796
1288.09	56.2443
1291.29	57.8916
1294.49	56.2079
1297.69	55.019
1300.88	53.8926
1304.08	54.4754
1307.27	55.118
1310.47	56.5418
1313.66	56.3917
1316.85	55.6804
1320.04	56.0692
1323.23	56.6694
1326.41	57.4359
1329.6	57.8349
1332.78	56.5308
1335.97	54.3693
1339.15	55.0822
1342.33	53.9091
1345.51	51.7037
1348.69	50.3539
1351.87	49.7402
1355.04	48.4039
1358.22	46.8165
1361.39	45.327
1364.57	43.8036
1367.74	42.4889
1370.91	40.2701
1374.07	38.7453
1377.24	38.3352
1380.41	37.5881
1383.57	38.129
1386.74	37.0229
1389.9	36.4424
1393.06	35.2983
1396.22	35.8549
1399.38	37.4605
1402.54	37.7349
1405.7	38.5323
1408.85	39.7384
1412.01	40.9134
1415.16	43.5813
1418.31	46.5416
1421.46	48.2405
1424.61	51.7889
1427.76	55.7498
1430.91	59.3772
1434.05	62.4517
1437.2	66.5089
1440.34	67.6303
1443.49	69.7237
1446.63	71.6972
1449.77	70.9826
1452.91	70.0572
1456.04	67.5518
1459.18	65.8017
1462.31	62.6245
1465.45	59.1801
1468.58	55.1522
1471.71	50.5013
1474.84	48.8938
1477.97	46.5059
1481.1	42.7168
1484.23	39.0681
1487.35	37.0506
1490.48	33.4488
1493.6	31.8981
1496.72	31.6261
1499.84	30.7782
1502.96	29.1399
1506.08	27.3702
1509.2	27.2966
1512.31	26.5027
1515.43	25.4891
1518.54	24.4037
1521.66	24.4008
1524.77	23.8261
1527.88	23.9411
1530.99	22.005
1534.09	22.1395
1537.2	21.569
1540.31	20.5003
1543.41	21.8549
1546.51	22.2516
1549.62	24.2915
1552.72	25.0597
1555.82	24.9683
1558.91	25.701
1562.01	27.0711
1565.11	28.3223
1568.2	30.4512
1571.3	34.0392
1574.39	36.9139
1577.48	37.2369
1580.57	38.5062
1583.66	40.1275
1586.75	40.8598
1589.83	41.6128
1592.92	42.7824
1596	43.4554
1599.09	43.6282
1602.17	44.0712
1605.25	42.8688
1608.33	41.2388
1611.41	41.0385
1614.48	40.3924
1617.56	41.4695
1620.64	42.8726
1623.71	43.7321
1626.78	44.1434
1629.86	46.1661
1632.92	47.8927
1635.99	49.9445
1639.06	51.5461
1642.13	51.8468
1645.19	56.0553
1648.26	58.1696
1651.32	59.4455
1654.38	61.3682
1657.45	60.0749
1660.51	59.8215
1663.57	59.6465
1666.62	60.0475
1669.68	57.5268
1672.73	55.4383
1675.79	52.7249
1678.84	50.1566
1681.89	46.4632
1684.94	42.3888
1687.99	39.9935
1691.04	36.9847
1694.09	33.3917
1697.14	30.637
1700.18	26.135
1703.22	24.5041
1706.27	22.107
1709.31	18.1513
1712.35	15.8593
1715.39	12.9142
1718.43	11.9581
1721.46	10.617
1724.5	8.84754
1727.53	7.78082
1730.57	6.01925
1733.6	5.12649
1736.63	4.45275
1739.66	4.59164
1742.69	4.87469
1745.72	5.06991
1748.74	5.17018
1751.77	4.36715
1754.8	3.60618
1757.82	3.12456
1760.84	3.19271
1763.86	3.56922
1766.88	3.16051
1769.9	3.30155
1772.92	3.39613
1775.93	4.06762
1778.95	4.94426
1781.96	4.36745
1784.98	3.57468
1787.99	3.68153
1791	3.15989
1794.01	2.64313
1797.02	2.26864
1800.03	1.71896
1803.03	2.00316
1806.04	2.73685
1809.04	3.06478
1812.04	3.73051
1815.05	3.60548
1818.05	3.33754
1821.05	2.89005
1824.05	2.49304
1827.04	2.4712
1830.04	2.52138
1833.03	2.93499
1836.03	3.86057
1839.02	4.3392
1842.01	4.33448
1845	4.44628
1847.99	5.02722
1850.98	4.25301
1853.97	5.46592
1856.95	4.62832
1859.94	4.32404
1862.92	4.72453
1865.91	5.00483
1868.89	4.62647
1871.87	4.69818
1874.85	4.76494
1877.83	4.90399
1880.8	4.32909
1882.56	3.95639
1885.54	3.69063
1888.53	2.62525
1891.52	2.23079
1894.5	2.01285
1897.49	1.52575
1900.47	1.95603
1903.45	2.73894
1906.43	4.03101
1909.41	3.90568
1912.39	3.58442
1915.37	3.332
1918.35	3.39176
1921.32	3.62907
1924.3	3.74937
1927.27	4.01288
1930.24	3.37895
1933.21	3.72615
1936.18	3.65318
1939.15	2.73053
1942.12	2.08183
1945.09	2.41294
1948.05	2.36063
1951.02	1.97434
1953.98	1.76652
1956.94	1.02497
1959.91	0.230833
1962.87	0.179763
1965.82	0.826589
1968.78	0.905158
1971.74	1.48211
1974.7	1.91556
1977.65	3.40086
1980.6	3.58643
1983.56	3.95466
1986.51	4.20001
1989.46	4.39904
1992.41	4.92038
1995.36	5.12559
1998.3	4.78685
2001.25	4.36613
2004.2	4.21098
2007.14	5.15392
2010.08	5.47852
2013.02	5.23332
2015.97	6.33097
2018.9	6.83284
2021.84	6.53359
2024.78	5.67224
2027.72	5.84927
2030.65	5.64981
2033.59	6.14552
2036.52	6.44346
2039.45	6.8242
2042.38	7.28667
2045.31	7.7264
2048.24	8.53626
2051.17	9.11094
2054.1	9.42498
2057.02	9.11813
2059.95	9.50409
2062.87	9.64958
2065.79	10.0941
2068.71	9.94214
2071.63	10.7367
2074.55	12.268
2077.47	13.5678
2080.39	14.9639
2083.3	17.0049
2086.22	18.4942
2089.13	19.7541
2092.05	20.9443
2094.96	22.1729
2097.87	23.8433
2100.78	25.1185
2103.69	25.7888
2106.59	26.7524
2109.5	27.7235
2112.41	29.5089
2115.31	30.9286
2118.21	32.4268
2121.12	34.8396
2124.02	37.2583
2126.92	38.9683
2129.82	41.1372
2132.71	43.2878
2135.61	45.6514
2138.51	48.9536
2141.4	52.4649
2144.29	56.6976
2147.19	59.3939
2150.08	62.7884
2152.97	67.133
2155.86	69.8853
2158.75	72.4674
2161.64	76.0475
2164.52	77.4748
2167.41	78.7568
2170.29	79.9517
2173.17	79.5949
2176.06	79.4208
2178.94	78.211
2181.82	78.0993
2184.7	77.414
2187.57	74.8999
2190.45	72.4475
2193.33	69.3308
2196.2	65.5903
2199.08	62.5808
2201.95	59.3573
2204.82	56.0281
2207.69	53.4097
2210.56	51.2162
2213.43	48.6025
2216.3	45.6372
2219.16	43.0525
2222.03	40.6473
2224.89	39.3208
2227.75	37.0561
2230.62	35.5634
2233.48	33.0136
2236.34	32.3981
2239.2	30.863
2242.06	29.0761
2244.91	27.2718
2247.77	24.6825
2250.62	22.9803
2253.48	21.4677
2256.33	19.3193
2259.18	18.5198
2262.03	16.9618
2264.88	15.1705
2267.73	14.7339
2270.58	13.3162
2273.43	12.2666
2276.27	11.8318
2279.12	11.3269
2281.96	10.8243
2284.8	9.83901
2287.64	8.56584
2290.49	7.25815
2293.32	6.35276
2296.16	6.25988
2299	7.27477
2301.84	8.50711
2304.67	9.69256
2307.51	10.3553
2310.34	9.22454
2313.17	9.64621
2316	9.73993
2318.83	9.53861
2321.66	9.44678
2324.49	9.75065
2327.32	9.58237
2330.15	8.94412
2332.97	8.39577
2335.79	8.16213
2338.62	7.56217
2341.44	6.26204
2344.26	4.86725
2347.08	4.05778
2349.9	2.67576
2352.72	1.48605
2355.53	0.381951
2358.35	-0.0294813
2361.17	-0.227534
2363.98	0.0464712
2366.79	1.68548
2369.6	2.50689
2372.42	2.58904
2375.22	3.22141
2378.03	3.34723
2380.84	3.0993
2383.65	3.71191
2386.45	4.95839
2389.26	4.96405
2392.06	4.62723
2394.87	5.45988
2397.67	5.41087
2400.47	5.99528
2403.27	5.94066
2406.07	6.51381
2408.86	5.58059
2411.66	5.02444
2414.46	4.9714
2417.25	4.61892
2420.05	4.30647
2422.84	4.15461
2425.63	3.89305
2428.42	3.61072
2431.21	3.72752
2434	3.11665
2436.79	3.20967
2439.57	3.73138
2442.36	3.64111
2445.14	3.95072
2447.93	4.30887
2450.71	3.85507
2453.49	4.39145
2456.27	4.36574
2459.05	3.61716
2461.83	4.29596
2464.61	4.51708
2467.39	4.59236
2470.16	4.77729
2472.94	4.6523
2475.71	4.79416
2478.48	4.53103
2481.25	4.33539
2484.02	4.47935
2486.8	4.68839
2489.56	5.05095
2492.33	4.3937
2495.1	4.65252
2497.86	4.47504
2500.63	4.24994
2503.39	3.7079
2506.16	4.10316
2508.92	4.16081
2511.68	4.24886
2514.44	4.31621
2517.2	3.60101
2519.95	3.32834
2522.71	3.20048
2525.47	3.46891
2528.22	3.65036
2530.98	2.83548
2533.73	3.0228
2536.48	2.66204
2539.23	2.09205
2541.98	2.25508
2544.73	2.51262
2547.48	3.09847
2550.23	2.6209
2552.97	2.40787
2555.72	2.55149
2558.46	2.37064
2561.2	2.76188
2563.95	2.91342
2566.69	3.32652
2569.43	3.66981
2572.17	4.94058
2574.91	6.15136
2577.64	6.32692
2580.38	6.5769
2583.11	6.86123
2585.85	6.93629
2588.58	6.79951
2591.31	7.14613
2594.04	7.13086
2596.78	6.07406
2599.51	5.87978
2602.23	6.24334
2604.96	5.56337
2607.69	5.77744
2610.41	6.07003
2613.14	4.77875
2615.86	3.7511
2618.58	2.88756
2621.3	2.65455
2624.03	2.92014
2626.75	2.69473
2629.46	3.09191
2632.18	2.4983
2634.9	2.49495
2637.61	2.32261
2640.33	2.50655
2643.04	1.45199
2645.76	1.05813
2648.47	1.57695
2651.18	2.07631
2653.89	1.60304
2656.6	1.33186
2659.31	1.52696
2662.01	2.12891
2664.72	2.42227
2667.43	2.80636
2670.13	3.25285
2672.83	2.79091
2675.53	2.1997
2678.24	1.72044
2680.94	1.62897
2683.64	2.2872
2686.34	2.20894
2689.03	2.50459
2691.73	2.84637
2694.43	3.34366
2697.12	3.79816
2699.81	4.18744
2702.51	4.66035
2705.2	5.39537
2707.89	4.83145
2710.58	5.45474
2713.27	5.80345
2715.96	6.43857
2718.64	6.4588
2721.33	6.35825
2724.01	7.29249
2726.7	7.96605
2729.38	7.6767
2732.06	6.83665
2734.75	6.90453
2737.43	6.05499
2740.11	6.36551
2742.78	5.6821
2745.46	5.05719
2748.14	5.25337
2750.81	4.30449
2753.49	3.87264
2756.16	4.036
2758.84	3.91118
2761.51	4.13986
2764.18	3.27322
2766.85	3.55179
2769.52	2.94692
2772.19	1.86676
2774.85	1.19814
2777.52	0.472296
2780.18	0.54073
2782.85	0.576774
2785.51	0.532918
2788.17	0.0748691
2790.84	0.379873
2793.5	0.109869
2796.16	0.0639671
2798.81	0.353079
2801.47	0.482813
2804.13	0.500282
2806.79	-0.217846
2809.44	-1.33613
2812.09	-0.909053
2814.75	-0.175779
2817.4	1.1427
2820.05	3.47937
2822.7	6.07381
2825.35	9.45047
2828	13.0252
2830.65	17.0097
2833.29	21.1198
2835.94	25.6757
2838.58	30.4599
2841.23	35.3883
2843.87	40.9065
2846.51	46.688
2849.15	52.6519
2851.79	58.224
2854.43	64.333
2857.07	70.3953
2859.71	76.6428
2862.34	81.386
2864.98	85.767
2867.61	88.8671
2870.25	91.871
2872.88	93.9438
2875.51	96.4027
2878.14	98.5752
2880.77	101.788
2883.4	103.547
2886.03	106.167
2888.65	108.471
2891.28	112.233
2893.91	115.475
2896.53	118.31
2899.15	121.648
2901.78	126.229
2904.4	131.674
2907.02	138.773
2909.64	145.447
2912.26	152.567
2914.87	159.912
2917.49	166.915
2920.11	173.933
2922.72	181.017
2925.34	185.856
2927.95	189.462
2930.56	192.099
2933.17	193.029
2935.78	191.88
2938.39	190.426
2941	186.543
2943.61	182.394
2946.22	177.213
2948.82	171.587
2951.43	164.797
2954.03	156.393
2956.64	148.632
2959.24	139.821
2961.84	131.49
2964.44	123.91
2967.04	116.8
2969.64	109.583
2972.24	101.824
2974.83	94.9099
2977.43	87.3253
2980.02	79.984
2982.62	73.0789
2985.21	67.5112
2987.8	61.2946
2990.4	54.8284
2992.99	48.6623
2995.57	42.6167
2998.16	37.1318
3000.75	31.9492
3003.34	27.1499
3005.92	22.8036
3008.51	19.2699
3011.09	15.1075
3013.68	11.6959
3016.26	8.87599
3018.84	6.85976
3021.42	4.91827
3024	3.94072
3026.58	2.63516
3029.16	2.63535
3031.73	2.18931
3034.31	2.55752
3036.89	2.89034
3039.46	3.66752
3042.03	4.27848
3044.61	4.70193
3047.18	5.09021
3049.75	5.86156
3052.32	5.97666
3054.89	5.7365
3057.45	5.67317
3060.02	5.35556
3062.59	5.33455
3065.15	4.95679
3067.72	3.89656
3070.28	3.62028
3072.84	2.96863
3075.41	1.74197
3077.97	0.641623
3080.53	0.374435
3083.09	-0.203145
3085.64	-1.01048
3088.2	-1.43307
3090.76	-0.24492
3093.31	-0.106316
3095.87	0.826924
3098.42	1.38207
3100.97	1.72874
3103.53	2.14727
3106.08	2.66054
3108.63	3.04792
3111.18	3.99676
3113.73	4.36928
3116.27	4.42668
3118.82	4.81911
3121.37	5.39054
3123.91	6.3945
3126.45	7.05031
3129	7.94737
3131.54	9.18529
3134.08	9.82874
3136.62	10.5848
3139.16	11.8702
3141.7	13.7113
3144.24	15.7003
3146.78	17.8366
3149.31	20.1854