File: data/Raman/poly_smoothed/Mb_40_24_35_1x_45s_532 nm_x100_100%_600 gr_mm_01.txt
#Acq. time (s)=	45
#Accumulations=	2
#Range (cm-¹)=	200...3150
#Windows=	2
#Auto scanning=	Off
#Autofocus=	Off
#Macrospot=	Off
#AutoExposure=	Off
#Spike filter=	Multiple accum.
#Delay time (s)=	0
#Binning=	1
#Readout mode=	Signal
#DeNoise=	Off
#ICS correction=	On
#Dark correction=	Off
#Inst. Process=	Off
#Detector Gain=	Best Dynamic Range
#Detector ADC=	20 kHz
#Detector temperature (°C)=	-70.08
#Instrument=	LabRAM HR Evol
#Detector=	Synapse
#Objective=	x100
#Grating=	600 gr/mm
#ND Filter=	100%
#Laser (nm)=	532
#Hole=	100.021
#Range=	Auto
#Laser Pol.=	No
#Raman. Pol.=	No
#Laser Pol. (°)=	-0.0007625
#Raman Pol. (°)=	89.9995
#Collection=	Microscope
#StageXY=	Marzhauser
#StageZ=	Marzhauser
#X (µm)=	-2492.9
#Y (µm)=	-79
#Z (µm)=	-10.45
#Full time(mm:ss)=	3:19
#Project=
#Sample=
#Site=
#Title=	Mb_40_24_35_2x_45s_532 nm_x100_100%_600 gr_mm
#Remark=
#Date=	14.07.2022 13:15
#Acquired=	14.07.2022 13:15:35
#Edit:Spike=	14.07.2022 13:18:05
#Base:Fit=	10.08.2022 10:47:00
#Base:Sub=	10.08.2022 10:47:12
#Filter:Polynom=	16.08.2022 10:11:48
#AxisType[0]=Intens
#AxisUnit[0]=Cnt
#AxisType[1]=Spectr
#AxisUnit[1]=1/cm
200.554	32.9841
204.183	32.0219
207.813	31.6671
211.439	29.79
215.065	27.9755
218.688	28.318
222.312	27.9211
225.933	25.7242
229.552	23.0925
233.171	20.1774
236.787	18.6971
240.402	17.7134
244.015	16.2491
247.627	14.1664
251.24	11.7781
254.849	10.3725
258.457	9.44685
262.063	9.08664
265.668	8.30942
269.271	8.60366
272.873	5.50348
276.474	5.54541
280.073	3.16368
283.671	1.32681
287.268	0.90921
290.863	1.0296
294.456	2.2292
298.049	4.51599
301.637	6.11807
305.227	8.27963
308.815	10.8175
312.402	11.6014
315.987	14.8922
319.569	16.3403
323.151	19.9686
326.733	20.2531
330.31	22.6477
333.889	25.2087
337.464	25.0438
341.039	24.432
344.611	25.4467
348.184	24.5229
351.754	23.0046
355.324	19.0912
358.89	15.0875
362.455	10.791
366.021	9.59329
369.584	9.20215
373.145	9.6694
376.707	9.25302
380.265	9.34115
383.822	8.28874
387.378	8.97434
390.934	11.387
394.487	12.3113
398.038	11.2872
401.588	12.3455
405.137	14.1219
408.685	14.06
412.23	14.6502
415.775	15.2956
419.318	18.302
422.86	18.9003
426.401	18.175
429.94	18.5668
433.478	19.7142
437.012	18.3235
440.547	16.9074
444.081	17.7266
447.613	18.3178
451.142	20.202
454.672	22.3653
458.2	24.3935
461.725	23.999
465.251	24.9122
468.775	26.625
472.296	28.3405
475.817	29.8448
479.335	31.6659
482.854	33.0431
486.37	36.4955
489.886	38.3569
493.398	41.9989
496.91	44.0046
500.422	44.75
503.93	47.9862
507.438	50.4682
510.946	52.2295
514.45	53.6912
517.954	56.2875
521.456	56.4174
524.956	56.8569
528.456	56.9648
531.956	57.187
535.452	57.1564
538.947	53.8633
542.441	50.9459
545.934	49.3989
549.425	45.9939
552.915	45.2907
556.403	41.6343
559.889	39.4283
563.375	37.1757
566.859	34.602
570.342	33.0018
573.824	29.786
577.303	28.3197
580.782	28.7477
584.26	27.5222
587.734	26.9805
591.21	26.8979
594.684	26.2996
598.154	26.6386
601.626	28.1686
605.094	29.1458
608.562	28.445
612.027	29.489
615.493	29.5393
618.956	27.6034
622.419	26.3778
625.879	26.5346
629.338	27.4244
632.797	29.0421
636.254	28.1424
639.708	26.925
643.162	25.0735
646.614	23.4557
650.067	21.9547
653.516	21.6742
656.964	18.7795
660.411	16.58
663.857	15.8198
667.301	14.3605
670.744	12.5987
674.186	11.5941
677.626	12.6408
681.065	14.5085
684.503	15.2422
687.939	16.4002
691.372	15.7516
694.806	15.8782
698.239	15.8214
701.67	20.0998
705.098	21.7737
708.526	27.0461
711.954	30.2952
715.378	31.8637
718.802	31.9164
722.226	31.53
725.646	30.4552
729.067	32.2747
732.484	32.6918
735.902	33.8922
739.317	31.5287
742.731	33.3866
746.145	34.7041
749.556	37.2277
752.966	40.0566
756.377	42.417
759.784	45.2558
763.19	48.0125
766.594	48.7762
770	49.7453
773.402	51.3804
776.803	52.6191
780.202	53.5324
783.6	56.2085
786.997	57.9533
790.393	58.9959
793.787	61.2706
797.18	62.2342
800.572	60.21
803.963	60.2032
807.35	61.4776
810.738	59.751
814.125	57.7137
817.51	58.7359
820.894	58.963
824.275	62.3002
827.657	66.5306
831.037	69.1599
834.414	69.75
837.792	70.6189
841.167	70.9539
844.542	71.4132
847.914	71.9628
851.287	71.1746
854.656	70.7391
858.026	70.2743
861.393	69.703
864.761	69.3779
868.125	68.0879
871.489	68.4003
874.85	66.0559
878.213	64.9346
881.572	60.3841
884.931	55.3249
888.287	53.977
891.643	51.2413
894.997	48.5304
898.352	46.5593
901.704	47.0807
905.055	49.6814
908.404	50.216
911.75	50.9989
915.097	52.3244
918.443	50.3626
921.787	50.7887
925.13	51.2466
928.472	51.8822
931.813	50.0737
935.15	49.8966
938.488	50.3962
941.825	50.466
945.158	50.3869
948.493	47.1486
951.824	44.9068
955.156	40.4753
958.486	36.1472
961.814	36.2428
965.142	38.6684
968.467	40.1299
971.79	43.7952
975.115	47.77
978.436	48.5735
981.756	51.9116
985.077	51.9763
988.394	53.7394
991.71	53.7283
995.025	51.8928
998.341	51.7307
1001.65	50.0879
1004.97	48.2737
1008.28	50.6473
1011.58	54.6844
1014.89	58.0324
1018.2	63.5596
1021.5	70.501
1024.81	75.5137
1028.11	77.5868
1031.41	81.6705
1034.71	85.227
1038.01	89.0048
1041.31	95.4814
1044.6	99.3225
1047.9	102.559
1051.19	103.275
1054.48	103.852
1057.77	102.6
1061.06	98.5213
1064.35	95.0984
1067.64	86.2333
1070.93	79.2267
1074.21	69.8769
1077.49	64.1506
1080.78	56.8172
1084.06	48.978
1087.34	46.2605
1090.61	44.5467
1093.89	44.2864
1097.17	43.1315
1100.44	42.7078
1103.71	42.369
1106.99	40.4882
1110.26	40.8453
1113.52	39.0977
1116.79	37.0866
1120.06	35.2536
1123.32	33.0803
1126.59	30.1721
1129.85	29.252
1133.11	27.2772
1136.37	27.0338
1139.63	25.1301
1142.89	21.2048
1146.15	18.5275
1149.4	15.0463
1152.66	13.3277
1155.91	9.80366
1159.16	8.2354
1162.41	5.49706
1165.66	5.5392
1168.91	2.36256
1172.16	3.39522
1175.4	4.27395
1178.65	3.81557
1181.89	4.76995
1185.13	8.38513
1188.37	10.789
1191.61	12.4339
1194.85	13.9525
1198.08	15.2474
1201.32	18.8844
1204.55	21.6037
1207.79	24.9587
1211.02	29.9576
1214.25	33.0929
1217.48	34.791
1220.71	41.3812
1223.93	45.4876
1227.16	47.2062
1230.38	50.5011
1233.6	54.0123
1236.83	56.8262
1240.05	61.164
1243.26	66.3436
1246.48	70.5009
1249.7	74.8694
1252.92	78.3464
1256.13	81.4404
1259.34	87.9529
1262.55	94.4866
1265.76	97.9656
1268.97	106.838
1272.18	113.4
1275.39	119.206
1278.59	127.175
1281.8	132.944
1285	138.436
1288.2	144.767
1291.4	149.072
1294.6	150.319
1297.8	152.093
1301	154.496
1304.19	152.836
1307.39	149.983
1310.58	148.714
1313.77	147.607
1316.96	145.212
1320.15	143.014
1323.34	139.122
1326.53	132.642
1329.72	127.821
1332.9	122.498
1336.08	119.897
1339.27	116.838
1342.45	113.405
1345.63	110.607
1348.8	110.156
1351.98	109.287
1355.16	109.364
1358.33	108.477
1361.51	105.368
1364.68	106.179
1367.85	105.934
1371.02	106.25
1374.19	106.899
1377.36	107.184
1380.52	111.048
1383.69	113.628
1386.85	118.531
1390.02	121.338
1393.18	124.657
1396.34	127.812
1399.5	132.289
1402.65	137.163
1405.81	146.129
1408.97	153.849
1412.12	166.205
1415.27	178.091
1418.43	190.481
1421.58	203.124
1424.73	216.759
1427.87	230.194
1431.02	242.503
1434.17	252.192
1437.31	260.975
1440.46	265.627
1443.6	269.276
1446.74	267.591
1449.88	263.593
1453.02	257.032
1456.16	248.427
1459.29	236.187
1462.43	223.876
1465.56	205.847
1468.69	186.464
1471.83	167.24
1474.95	149.076
1478.08	132.266
1481.21	116.383
1484.34	102.141
1487.47	89.8842
1490.59	79.5004
1493.71	70.1415
1496.84	60.4653
1499.96	55.7132
1503.07	51.4632
1506.19	48.1598
1509.31	46.7323
1512.43	44.1511
1515.54	42.021
1518.65	40.8044
1521.77	41.0563
1524.88	41.996
1527.99	43.8519
1531.1	44.6704
1534.21	47.6981
1537.31	50.9836
1540.42	54.8749
1543.52	56.9814
1546.63	59.688
1549.73	65.8555
1552.83	70.8859
1555.93	76.1312
1559.03	81.2002
1562.12	86.8806
1565.22	91.7753
1568.31	97.4311
1571.41	101.453
1574.5	108.209
1577.59	116.088
1580.68	122.883
1583.77	131.089
1586.86	135.759
1589.95	141.38
1593.03	146.704
1596.11	149.577
1599.2	153.647
1602.28	154.708
1605.36	153.73
1608.44	153.755
1611.52	152.793
1614.6	153.917
1617.67	153.355
1620.75	153.238
1623.82	152.015
1626.89	150.675
1629.96	151.657
1633.04	152.855
1636.11	153.604
1639.17	154.923
1642.24	155.232
1645.31	157.518
1648.37	159.353
1651.43	160.996
1654.5	160.351
1657.56	160.242
1660.62	156.266
1663.67	152.77
1666.73	146.754
1669.79	139.125
1672.84	131.911
1675.9	122.969
1678.95	111.461
1682	102.133
1685.05	93.2503
1688.1	84.6295
1691.15	76.8408
1694.2	68.8627
1697.25	63
1700.29	57.9383
1703.33	54.5638
1706.38	51.0346
1709.42	48.1957
1712.46	47.4015
1715.5	44.6583
1718.54	45.4263
1721.57	42.3428
1724.61	40.6005
1727.64	37.7068
1730.68	36.8614
1733.71	35.2826
1736.74	33.1979
1739.77	29.9181
1742.8	26.8762
1745.83	25.4078
1748.85	21.549
1751.88	19.1143
1754.91	16.1791
1757.93	14.5304
1760.95	13.1285
1763.97	11.2035
1766.99	9.48888
1770.01	8.927
1773.03	9.38205
1776.04	8.05842
1779.06	6.13737
1782.07	6.63119
1785.09	7.50811
1788.1	7.44645
1791.11	6.5527
1794.12	4.39167
1797.13	3.35489
1800.13	4.08388
1803.14	2.95013
1806.15	2.93082
1809.15	2.57091
1812.15	1.59949
1815.16	0.324976
1818.15	0.808996
1821.16	0.617647
1824.15	-0.207865
1827.15	-0.456641
1830.15	-1.16358
1833.14	-1.26566
1836.14	-2.55124
1839.13	-1.78879
1842.12	-0.232051
1845.11	0.0724225
1848.1	-0.335057
1851.09	-1.02833
1854.08	-0.387976
1857.06	1.81206
1860.05	2.81691
1863.03	1.32441
1866.01	2.23145
1869	2.67824
1871.98	2.66762
1874.96	2.77142
1877.93	3.13108
1880.91	3.16074
1882.47	2.98082
1885.46	3.31672
1888.44	4.03824
1891.43	3.65174
1894.42	5.4256
1897.4	4.55155
1900.39	4.74636
1903.37	5.69175
1906.35	4.91138
1909.33	5.36672
1912.31	7.05868
1915.29	6.0554
1918.26	5.96795
1921.24	6.21458
1924.21	6.11506
1927.19	5.68031
1930.16	4.77547
1933.13	4.60169
1936.1	3.7743
1939.07	4.22675
1942.04	3.1418
1945	3.04475
1947.97	2.94795
1950.93	2.91991
1953.9	4.64871
1956.86	4.29073
1959.82	4.54402
1962.78	5.56462
1965.74	6.99662
1968.7	7.73694
1971.65	8.11657
1974.61	10.0499
1977.57	8.72478
1980.52	9.41302
1983.47	9.76367
1986.42	9.45963
1989.37	9.40803
1992.32	9.32203
1995.27	7.62594
1998.22	7.41596
2001.17	5.43478
2004.11	6.22568
2007.05	5.49372
2010	5.19145
2012.94	4.3291
2015.88	2.96534
2018.82	2.6309
2021.76	1.79701
2024.7	3.78069
2027.63	4.56538
2030.57	5.58034
2033.5	5.83616
2036.44	6.83391
2039.37	8.44952
2042.3	10.9711
2045.23	13.1248
2048.16	15.3997
2051.08	17.018
2054.01	19.7751
2056.94	20.7462
2059.86	21.0595
2062.79	22.0744
2065.71	23.1618
2068.63	24.4413
2071.55	25.9283
2074.47	27.1483
2077.39	29.625
2080.31	30.8765
2083.22	32.294
2086.13	33.3948
2089.05	35.5567
2091.96	39.6284
2094.87	41.8137
2097.78	44.0029
2100.69	45.6056
2103.6	46.7694
2106.51	50.4851
2109.42	56.338
2112.32	61.0603
2115.23	64.5403
2118.13	69.8882
2121.03	73.6548
2123.93	75.8482
2126.83	79.1458
2129.73	83.1182
2132.63	87.2962
2135.53	92.0728
2138.42	97.5315
2141.32	103.743
2144.21	109.744
2147.1	116.034
2150	119.099
2152.89	123.256
2155.78	127.386
2158.66	132.182
2161.55	135.994
2164.44	138.538
2167.32	138.805
2170.21	139.983
2173.09	139.894
2175.97	138.548
2178.85	137.28
2181.73	134.679
2184.61	131.12
2187.49	127.33
2190.37	123.01
2193.24	117.362
2196.12	111.605
2198.99	107.257
2201.87	101.712
2204.74	96.6021
2207.61	91.9304
2210.48	87.3536
2213.35	83.0585
2216.21	77.2261
2219.08	70.9083
2221.95	65.1477
2224.81	62.0483
2227.67	57.6058
2230.54	52.7153
2233.4	47.1415
2236.26	43.0336
2239.11	38.5185
2241.97	34.9102
2244.83	31.1226
2247.69	27.2888
2250.54	24.6572
2253.4	22.1289
2256.25	20.0669
2259.1	19.5762
2261.95	18.8379
2264.8	17.6037
2267.65	17.6436
2270.5	16.9369
2273.34	16.5314
2276.19	15.7184
2279.03	14.6517
2281.88	13.8918
2284.72	11.8351
2287.56	11.9222
2290.4	11.3383
2293.24	10.1041
2296.08	9.63738
2298.92	8.11823
2301.76	7.9476
2304.59	9.02141
2307.43	10.4416
2310.26	9.54129
2313.09	8.42063
2315.92	8.31037
2318.75	8.35982
2321.58	7.82555
2324.41	7.23561
2327.24	8.02088
2330.06	8.27335
2332.89	8.29691
2335.71	7.61732
2338.54	6.58739
2341.36	4.63728
2344.18	3.85302
2347	2.04249
2349.82	1.49382
2352.64	1.01259
2355.45	0.37192
2358.27	0.497811
2361.08	-0.695287
2363.9	-0.536462
2366.71	-0.0804494
2369.52	-0.0931321
2372.33	0.62061
2375.14	0.72657
2377.95	0.67614
2380.76	0.345769
2383.57	1.15646
2386.37	1.72841
2389.18	1.6942
2391.98	2.13989
2394.79	2.94839
2397.59	3.82381
2400.39	3.69505
2403.19	5.21938
2405.99	6.46222
2408.78	7.46828
2411.58	8.37859
2414.38	8.54306
2417.17	8.64178
2419.97	8.80394
2422.76	8.41709
2425.55	7.84336
2428.34	6.50239
2431.13	5.42539
2433.92	4.23822
2436.71	3.56658
2439.49	3.58821
2442.28	3.32078
2445.06	2.02642
2447.85	1.92729
2450.63	1.10007
2453.41	1.46387
2456.19	1.05274
2458.97	0.484608
2461.75	-0.0724963
2464.53	-0.335816
2467.31	-0.425297
2470.08	-0.731674
2472.86	0.176894
2475.63	0.152064
2478.4	0.437124
2481.17	-0.0323795
2483.94	-0.957667
2486.72	-1.86558
2489.48	-1.1613
2492.25	-0.862124
2495.02	-0.800529
2497.79	-0.845389
2500.55	-0.872073
2503.31	-0.806989
2506.08	-0.319541
2508.84	0.797739
2511.6	2.79171
2514.36	2.6398
2517.12	3.38362
2519.88	3.91825
2522.63	4.063
2525.39	5.35241
2528.14	5.9439
2530.9	5.65397
2533.65	7.26506
2536.4	8.07829
2539.15	8.60609
2541.9	10.2592
2544.65	10.1968
2547.4	10.5869
2550.15	9.77847
2552.89	9.95752
2555.64	9.65538
2558.38	10.4615
2561.12	9.35463
2563.87	7.50315
2566.61	7.20228
2569.35	6.43461
2572.09	6.92902
2574.83	7.39732
2577.56	7.56649
2580.3	7.61349
2583.04	7.43908
2585.77	7.07495
2588.5	7.18795
2591.23	8.56426
2593.97	10.3167
2596.7	10.6277
2599.43	10.8365
2602.15	11.1717
2604.88	11.4847
2607.61	11.4635
2610.33	11.0057
2613.06	11.0486
2615.78	10.6315
2618.51	9.91441
2621.23	9.40204
2623.95	9.56651
2626.67	8.82086
2629.39	8.71829
2632.1	8.99992
2634.82	10.1693
2637.54	10.7135
2640.25	11.2987
2642.97	11.8668
2645.68	12.3322
2648.39	12.8691
2651.1	13.4957
2653.81	14.6142
2656.52	15.9531
2659.23	15.8944
2661.94	15.1943
2664.64	13.8746
2667.35	14.1288
2670.05	13.996
2672.76	13.2923
2675.46	13.1785
2678.16	14.0095
2680.86	14.6293
2683.56	14.303
2686.26	15.301
2688.96	15.4646
2691.65	15.6063
2694.35	16.2027
2697.04	16.8281
2699.74	17.6399
2702.43	19.7942
2705.12	20.4676
2707.81	21.9516
2710.5	22.0839
2713.19	22.6549
2715.88	24.6695
2718.57	26.1392
2721.25	26.1448
2723.94	26.1126
2726.62	26.3359
2729.3	25.9019
2731.99	26.5035
2734.67	25.8057
2737.35	24.5559
2740.03	24.792
2742.71	24.4371
2745.38	23.1946
2748.06	20.6535
2750.74	18.7426
2753.41	16.4178
2756.09	13.2959
2758.76	11.9673
2761.43	9.78216
2764.1	8.14655
2766.77	8.20181
2769.44	7.29134
2772.11	5.36525
2774.77	4.65191
2777.44	3.94633
2780.11	5.1321
2782.77	5.30646
2785.43	5.47948
2788.1	5.19104
2790.76	5.19038
2793.42	5.78489
2796.08	6.34251
2798.74	5.94485
2801.4	5.84108
2804.05	6.25969
2806.71	5.721
2809.36	4.01484
2812.02	2.38029
2814.67	3.15797
2817.32	7.44843
2819.97	16.0413
2822.62	27.2939
2825.27	40.1053
2827.92	56.0481
2830.57	75.3428
2833.22	94.5453
2835.86	113.662
2838.51	134.604
2841.15	157.087
2843.79	180.474
2846.43	202.75
2849.08	225.129
2851.72	249.691
2854.36	274.513
2856.99	298.537
2859.63	321.193
2862.27	340.352
2864.9	357.132
2867.54	372.572
2870.17	387.258
2872.8	397.935
2875.43	410.677
2878.07	422.728
2880.7	436.178
2883.32	452.216
2885.95	464.094
2888.58	476.753
2891.21	489.563
2893.83	501.359
2896.46	513.75
2899.08	526.333
2901.7	539.737
2904.32	556.525
2906.94	573.359
2909.56	592.224
2912.18	612.356
2914.8	634.368
2917.42	654.629
2920.03	671.663
2922.65	682.777
2925.26	690.996
2927.88	693.945
2930.49	692.579
2933.1	686.839
2935.71	676.31
2938.32	662.34
2940.93	642.821
2943.54	619.263
2946.14	593.636
2948.75	564.192
2951.35	532.922
2953.96	501.095
2956.56	469.468
2959.16	438.581
2961.77	408.93
2964.37	380.991
2966.96	357.021
2969.56	335.141
2972.16	314.454
2974.76	295.036
2977.35	278.011
2979.95	259.99
2982.54	240.013
2985.14	221.265
2987.73	203.032
2990.32	184.23
2992.91	165.354
2995.5	147.322
2998.09	130.152
3000.68	114.362
3003.26	97.6059
3005.85	81.7227
3008.43	68.3232
3011.02	54.647
3013.6	43.3728
3016.19	32.8377
3018.77	23.9008
3021.35	16.2917
3023.93	10.837
3026.5	6.01877
3029.08	2.77685
3031.66	1.16017
3034.24	-0.0584613
3036.81	-0.539547
3039.39	0.0545753
3041.96	0.0460738
3044.53	0.987687
3047.1	1.22289
3049.67	3.35397
3052.24	5.77464
3054.81	5.94448
3057.38	6.62679
3059.95	8.25155
3062.52	9.49843
3065.08	9.36066
3067.65	9.21637
3070.21	9.04755
3072.77	7.42695
3075.33	6.36883
3077.89	5.37097
3080.45	3.86776
3083.01	2.54131
3085.57	1.47332
3088.13	2.27809
3090.68	3.34749
3093.24	3.29017
3095.79	4.6943
3098.35	6.19771
3100.9	8.90596
3103.45	11.027
3106	11.7531
3108.55	13.8353
3111.1	17.2862
3113.65	20.03
3116.2	22.6402
3118.75	25.6472
3121.29	29.93
3123.84	34.0317
3126.38	38.1855
3128.92	41.8267
3131.47	45.9457
3134.01	50.1652
3136.55	54.7592
3139.09	60.0031
3141.63	66.3894
3144.17	73.3319
3146.7	82.0768
3149.24	89.2828