File: data/Raman/poly_smoothed/Mb_40_y_01_1x_45s_532 nm_x100_100%_600 gr_mm_01.txt
#Acq. time (s)=	45
#Accumulations=	2
#Range (cm-¹)=	200...3150
#Windows=	2
#Auto scanning=	Off
#Autofocus=	Off
#Macrospot=	Off
#AutoExposure=	Off
#Spike filter=	Multiple accum.
#Delay time (s)=	0
#Binning=	1
#Readout mode=	Signal
#DeNoise=	Off
#ICS correction=	On
#Dark correction=	Off
#Inst. Process=	Off
#Detector Gain=	Best Dynamic Range
#Detector ADC=	20 kHz
#Detector temperature (°C)=	-69.85
#Instrument=	LabRAM HR Evol
#Detector=	Synapse
#Objective=	x100
#Grating=	600 gr/mm
#ND Filter=	100%
#Laser (nm)=	532
#Hole=	100.021
#Range=	Auto
#Laser Pol.=	No
#Raman. Pol.=	No
#Laser Pol. (°)=	-0.0007625
#Raman Pol. (°)=	89.9995
#Collection=	Microscope
#StageXY=	Marzhauser
#StageZ=	Marzhauser
#X (µm)=	-1241.5
#Y (µm)=	2717.7
#Z (µm)=	587.3
#Full time(mm:ss)=	3:18
#Project=
#Sample=
#Site=
#Title=	Mb_40_y_01_2x_45s_532 nm_x100_100%_600 gr_mm
#Remark=
#Date=	18.07.2022 15:10
#Acquired=	18.07.2022 15:10:40
#Base:Fit=	10.08.2022 10:52:48
#Base:Sub=	10.08.2022 10:52:53
#Filter:Polynom=	16.08.2022 10:09:04
#AxisType[0]=Intens
#AxisUnit[0]=Cnt
#AxisType[1]=Spectr
#AxisUnit[1]=1/cm
200.419	48.6377
204.048	42.8239
207.678	34.6336
211.304	28.4679
214.928	23.7643
218.554	17.652
222.176	14.2722
225.798	10.2077
229.417	7.33885
233.035	6.24717
236.653	5.37083
240.268	4.51248
243.881	3.66586
247.493	4.63169
251.103	5.10126
254.715	5.2386
258.322	4.29213
261.929	4.69037
265.534	6.93339
269.137	6.76257
272.739	5.9035
276.34	5.90481
279.939	6.38083
283.537	6.36799
287.134	5.7487
290.729	5.09796
294.323	5.78429
297.913	5.31605
301.504	6.42995
305.093	6.25849
308.682	6.26802
312.268	6.08728
315.852	6.74152
319.436	7.53202
323.018	9.58506
326.597	8.63375
330.177	9.13846
333.753	8.84748
337.331	8.6842
340.906	8.5558
344.478	8.25362
348.051	7.89606
351.621	8.70811
355.189	6.49906
358.757	5.55921
362.323	6.30249
365.889	7.19675
369.451	8.40754
373.012	7.91107
376.574	7.74096
380.133	8.77874
383.69	9.37818
387.245	9.75093
390.8	8.60871
394.353	6.45707
397.906	7.96903
401.456	8.95142
405.005	8.66815
408.552	8.44293
412.099	7.53514
415.643	6.86291
419.187	7.44455
422.728	5.86468
426.269	8.41178
429.806	8.47132
433.344	7.80423
436.881	8.65676
440.416	8.67865
443.949	8.19147
447.48	9.30044
451.011	10.6052
454.541	10.811
458.069	9.94715
461.594	9.95862
465.119	8.99085
468.642	9.91882
472.165	9.99616
475.684	10.2638
479.204	11.8894
482.721	13.6075
486.239	15.3407
489.753	16.4818
493.268	15.8348
496.779	17.1665
500.289	17.486
503.8	18.6808
507.307	20.0309
510.813	19.9202
514.32	20.3406
517.823	19.5818
521.325	19.176
524.826	20.1076
528.325	18.584
531.823	17.6606
535.32	16.4284
538.815	14.6857
542.309	13.062
545.802	11.5549
549.293	10.5084
552.783	10.1484
556.271	8.30274
559.759	7.20346
563.245	7.35391
566.729	6.49788
570.213	6.4153
573.693	6.51957
577.173	6.07542
580.652	6.0152
584.13	5.20211
587.605	5.79728
591.08	3.85117
594.552	3.10302
598.025	2.51865
601.496	3.45778
604.964	5.0164
608.433	5.11383
611.898	4.87288
615.364	5.68282
618.827	7.33213
622.288	7.01131
625.75	7.57939
629.209	7.48044
632.667	7.74882
636.125	7.69035
639.58	7.48407
643.033	9.56589
646.485	10.5806
649.936	12.2193
653.388	12.5181
656.836	14.3164
660.283	13.6229
663.728	14.5794
667.173	14.6347
670.616	13.7597
674.057	13.9984
677.498	13.5736
680.937	14.4254
684.375	16.2721
687.809	18.1549
691.244	18.176
694.678	19.7824
698.111	19.5574
701.54	22.5514
704.97	24.9081
708.398	25.6483
711.826	27.2256
715.25	29.0954
718.675	30.675
722.096	31.8707
725.518	32.768
728.937	34.7831
732.357	35.5666
735.773	36.1258
739.19	36.4961
742.604	37.8303
746.018	38.5097
749.429	40.679
752.839	39.8418
756.248	41.5196
759.657	42.6418
763.063	42.0954
766.468	43.4293
769.871	45.1338
773.273	46.2577
776.676	47.1791
780.075	47.9826
783.474	51.9195
786.871	55.8041
790.266	57.8193
793.661	59.6308
797.054	60.6572
800.446	62.7826
803.834	62.0924
807.224	61.4527
810.612	61.8446
813.998	62.9531
817.384	61.7109
820.766	60.7529
824.149	62.1967
827.531	60.6579
830.909	60.4121
834.288	59.1159
837.666	57.1737
841.041	54.3415
844.416	50.9921
847.788	49.6153
851.161	48.2597
854.53	45.7353
857.901	42.6592
861.268	42.1724
864.633	42.3526
868	43.3383
871.363	41.7452
874.725	40.1243
878.088	40.1156
881.447	39.3384
884.805	38.6473
888.162	38.4541
891.518	37.0786
894.872	37.0177
898.225	37.034
901.577	35.8
904.928	37.3768
908.277	37.5368
911.625	38.5681
914.972	37.7336
918.318	36.6862
921.662	35.8207
925.005	36.8571
928.347	38.2396
931.686	37.7759
935.025	36.7139
938.363	36.4161
941.698	36.5073
945.034	36.8748
948.368	35.5295
951.699	31.7824
955.031	31.4217
958.36	29.8605
961.689	31.5917
965.016	30.1579
968.343	29.7381
971.666	28.2421
974.991	25.9488
978.312	23.63
981.632	21.9779
984.953	20.7907
988.27	19.1801
991.587	17.1511
994.902	13.0708
998.216	11.9242
1001.53	8.84393
1004.84	8.49794
1008.15	10.4896
1011.46	16.5551
1014.77	22.9681
1018.07	32.3416
1021.38	40.1957
1024.68	47.1245
1027.99	54.2468
1031.29	60.9775
1034.59	67.1211
1037.89	71.1131
1041.18	74.6357
1044.48	76.8848
1047.77	76.5941
1051.07	73.9395
1054.36	71.506
1057.65	66.3549
1060.94	59.9617
1064.23	50.6969
1067.52	42.4491
1070.8	33.5163
1074.09	24.1023
1077.37	14.1238
1080.65	6.1083
1083.93	0.0863021
1087.21	-1.22426
1090.49	0.337365
1093.77	0.451991
1097.04	1.59101
1100.32	3.8432
1103.59	3.24831
1106.86	5.06086
1110.13	5.28332
1113.4	7.9167
1116.67	7.44253
1119.94	8.54483
1123.2	9.33947
1126.47	10.4519
1129.73	11.9073
1132.99	13.698
1136.25	14.5931
1139.51	13.3423
1142.77	12.6322
1146.03	12.72
1149.28	11.9599
1152.54	12.3641
1155.79	11.0564
1159.04	10.345
1162.29	9.44597
1165.54	8.69879
1168.79	7.20419
1172.04	5.55962
1175.28	4.03191
1178.53	3.78723
1181.77	1.9872
1185.01	0.234851
1188.25	1.7069
1191.49	2.77139
1194.73	2.19466
1197.96	1.63336
1201.2	3.33318
1204.43	4.8461
1207.66	6.81622
1210.9	8.66492
1214.13	10.1148
1217.36	11.1632
1220.58	12.2887
1223.81	13.5266
1227.04	15.7163
1230.26	18.3363
1233.48	19.5038
1236.71	19.0172
1239.93	19.5604
1243.14	20.204
1246.36	20.475
1249.58	20.4967
1252.8	20.4314
1256.01	20.6937
1259.22	20.8514
1262.43	23.1341
1265.64	24.4007
1268.85	26.7158
1272.06	27.2106
1275.27	27.7836
1278.48	29.8855
1281.68	31.3358
1284.88	32.0364
1288.08	33.4942
1291.28	35.1617
1294.48	37.1838
1297.68	38.9097
1300.88	39.2979
1304.07	41.3976
1307.27	42.1853
1310.46	41.6024
1313.65	39.8938
1316.85	37.8994
1320.03	38.1019
1323.22	35.7014
1326.41	36.6912
1329.6	36.3928
1332.78	35.3157
1335.96	33.9689
1339.15	33.7079
1342.33	32.3939
1345.51	28.7921
1348.69	27.4764
1351.86	25.9548
1355.04	25.2621
1358.21	22.8278
1361.39	21.5167
1364.56	21.0595
1367.73	22.6224
1370.9	23.429
1374.07	24.1244
1377.24	24.4539
1380.41	25.4708
1383.57	25.9468
1386.73	24.2372
1389.9	23.5685
1393.06	25.0916
1396.22	26.6299
1399.38	27.0135
1402.54	28.8179
1405.69	30.3309
1408.85	30.4552
1412	31.1696
1415.16	32.2241
1418.31	33.6312
1421.46	33.1873
1424.61	35.0589
1427.76	37.4064
1430.9	38.6764
1434.05	40.6046
1437.2	41.4395
1440.34	43.4656
1443.48	43.8031
1446.62	44.679
1449.76	45.3959
1452.9	46.6078
1456.04	48.1047
1459.17	46.3073
1462.31	47.5363
1465.44	46.6501
1468.58	47.7804
1471.71	47.4567
1474.84	46.1748
1477.97	43.8496
1481.1	42.662
1484.22	40.3772
1487.35	37.7781
1490.47	34.2118
1493.59	31.7229
1496.72	29.6885
1499.84	25.9363
1502.96	24.7587
1506.08	23.3928
1509.19	20.9829
1512.31	19.785
1515.42	17.2703
1518.54	16.7929
1521.65	15.829
1524.76	17.0792
1527.87	18.0961
1530.98	18.0204
1534.09	19.1416
1537.2	19.9076
1540.3	20.2049
1543.41	22.0595
1546.51	23.1939
1549.61	23.9104
1552.71	24.3294
1555.81	25.8078
1558.91	26.2077
1562.01	25.3809
1565.1	25.3333
1568.2	26.1532
1571.29	26.5021
1574.38	26.3996
1577.48	27.1018
1580.57	28.1746
1583.65	30.2225
1586.74	29.98
1589.83	30.7034
1592.92	32.0652
1596	30.5496
1599.08	30.4048
1602.16	30.3909
1605.24	28.9682
1608.32	27.9385
1611.4	28.0309
1614.48	27.599
1617.56	27.9003
1620.63	29.0257
1623.71	28.1181
1626.78	28.9972
1629.85	30.3447
1632.92	30.3507
1635.99	30.8013
1639.06	31.7881
1642.12	32.1766
1645.19	33.137
1648.25	34.3444
1651.32	35.4462
1654.38	36.9803
1657.44	38.361
1660.5	37.9757
1663.56	38.894
1666.62	38.0981
1669.67	35.8492
1672.73	33.5152
1675.79	32.612
1678.84	29.8893
1681.89	26.8575
1684.94	25.0505
1687.99	22.9931
1691.04	20.6705
1694.08	17.3992
1697.13	16.0972
1700.18	13.5323
1703.22	11.0741
1706.26	9.29013
1709.3	8.36439
1712.35	6.4873
1715.39	5.61074
1718.42	5.76144
1721.46	6.18092
1724.5	6.20821
1727.53	7.24424
1730.56	7.54017
1733.6	7.34089
1736.63	8.8532
1739.66	9.02677
1742.69	8.27888
1745.71	8.25448
1748.74	8.56378
1751.77	9.08106
1754.79	8.25425
1757.81	7.87198
1760.84	6.42361
1763.86	5.55302
1766.88	3.61364
1769.9	2.6146
1772.91	2.28143
1775.93	1.42051
1778.95	1.20133
1781.96	1.87592
1784.97	2.90598
1787.99	2.93835
1791	3.82112
1794.01	3.90345
1797.01	3.9724
1800.02	3.02733
1803.03	3.32322
1806.03	3.2671
1809.04	3.86612
1812.04	5.1683
1815.04	5.41782
1818.04	5.06171
1821.04	5.66164
1824.04	6.24623
1827.04	7.02878
1830.03	7.54552
1833.03	7.34267
1836.02	7.23047
1839.02	7.44881
1842.01	7.97662
1845	8.0655
1847.99	7.98821
1850.98	8.06375
1853.96	8.31459
1856.95	8.92577
1859.94	9.32802
1862.92	8.99873
1865.9	8.65622
1868.88	7.75788
1871.86	7.28721
1874.84	7.18886
1877.82	7.86688
1880.8	7.28685
1882.58	7.81033
1885.57	6.81367
1888.56	6.36728
1891.54	6.18565
1894.53	7.50076
1897.51	7.78268
1900.5	9.29451
1903.48	8.99253
1906.46	8.31427
1909.44	8.02266
1912.42	8.30821
1915.4	8.25614
1918.37	8.21169
1921.35	8.09768
1924.32	7.84896
1927.3	8.55137
1930.27	7.57269
1933.24	7.87512
1936.21	8.66395
1939.18	8.57964
1942.15	7.71797
1945.11	8.10116
1948.08	6.43182
1951.04	5.02833
1954.01	3.98946
1956.97	3.04068
1959.93	2.02221
1962.89	1.5295
1965.85	2.37181
1968.81	3.17211
1971.77	3.1463
1974.72	3.00639
1977.68	2.21975
1980.63	1.7168
1983.58	1.70262
1986.53	1.70561
1989.48	2.52946
1992.43	2.71083
1995.38	3.24333
1998.33	2.71353
2001.27	2.88803
2004.22	3.737
2007.16	4.68723
2010.11	4.2902
2013.05	4.28707
2015.99	4.54283
2018.93	3.71866
2021.87	4.23854
2024.8	4.13588
2027.74	4.35305
2030.68	4.66961
2033.61	5.08059
2036.54	4.77141
2039.48	6.48841
2042.41	6.38081
2045.34	6.52606
2048.27	6.68885
2051.19	6.21114
2054.12	5.7554
2057.05	6.07913
2059.97	7.46359
2062.9	9.00841
2065.82	9.0403
2068.74	8.53856
2071.66	8.82142
2074.58	10.0664
2077.5	9.44546
2080.41	9.7585
2083.33	9.70745
2086.24	10.3003
2089.16	10.0476
2092.07	11.8997
2094.98	12.2651
2097.89	12.2491
2100.8	13.2224
2103.71	13.5835
2106.62	15.5696
2109.53	17.6691
2112.43	19.2057
2115.33	20.9152
2118.24	21.1339
2121.14	22.5213
2124.04	24.624
2126.94	26.7138
2129.84	28.2357
2132.74	29.9475
2135.63	31.0637
2138.53	32.0004
2141.43	34.0108
2144.32	35.4964
2147.21	36.2568
2150.1	37.2093
2152.99	39.2149
2155.88	40.1362
2158.77	41.9116
2161.66	42.5996
2164.55	43.1724
2167.43	42.2801
2170.31	43.7184
2173.2	44.8237
2176.08	45.1808
2178.96	45.9757
2181.84	44.689
2184.72	44.2587
2187.6	42.7195
2190.47	41.0704
2193.35	40.2506
2196.23	37.6414
2199.1	36.6044
2201.97	35.5255
2204.84	33.9252
2207.71	32.5702
2210.58	30.3347
2213.45	28.88
2216.32	28.8176
2219.19	28.0489
2222.05	27.1045
2224.92	25.8853
2227.78	23.4997
2230.64	22.2673
2233.5	20.2812
2236.36	18.6866
2239.22	18.1214
2242.08	17.1886
2244.94	16.0746
2247.79	15.0951
2250.65	14.3522
2253.5	13.0317
2256.36	11.3549
2259.21	10.9474
2262.06	10.5614
2264.91	10.2769
2267.76	11.4223
2270.6	11.7643
2273.45	12.2493
2276.3	12.2228
2279.14	12.8721
2281.98	13.044
2284.83	13.7257
2287.67	12.8334
2290.51	12.1015
2293.35	10.5116
2296.19	9.42819
2299.02	9.28904
2301.86	9.30987
2304.7	9.78738
2307.53	10.035
2310.36	8.26448
2313.2	7.8363
2316.03	7.7262
2318.86	7.64049
2321.69	6.76555
2324.51	6.30557
2327.34	6.23879
2330.17	6.39529
2332.99	6.70306
2335.82	6.88748
2338.64	7.62843
2341.46	8.1393
2344.28	7.51462
2347.1	6.84807
2349.92	7.03367
2352.74	5.88862
2355.56	4.73783
2358.37	3.545
2361.19	2.65204
2364	2.69059
2366.82	3.45575
2369.63	2.70778
2372.44	2.45996
2375.25	2.14743
2378.06	1.06655
2380.86	0.668524
2383.67	0.224675
2386.48	1.08053
2389.28	0.975535
2392.09	0.819224
2394.89	1.37634
2397.69	1.15016
2400.49	2.41084
2403.29	2.45025
2406.09	3.20852
2408.89	4.04543
2411.69	3.1541
2414.48	4.03738
2417.28	5.0183
2420.07	4.68135
2422.86	4.86481
2425.65	4.52241
2428.45	4.0352
2431.23	3.77814
2434.02	3.56468
2436.81	2.01906
2439.6	2.45725
2442.38	2.25282
2445.17	1.35137
2447.95	0.695018
2450.73	0.786309
2453.52	1.49336
2456.3	0.652918
2459.08	-0.421366
2461.85	-0.281689
2464.63	-0.183798
2467.41	0.175551
2470.19	0.956001
2472.96	1.11657
2475.73	2.31677
2478.51	2.0186
2481.28	3.08281
2484.05	4.0806
2486.82	4.16625
2489.59	3.9561
2492.35	3.35384
2495.12	4.07203
2497.89	4.72015
2500.65	5.66195
2503.42	5.40167
2506.18	5.76488
2508.94	5.57503
2511.7	5.11769
2514.46	5.42933
2517.22	6.31759
2519.98	6.58431
2522.73	4.86218
2525.49	5.13569
2528.25	4.94834
2531	4.93104
2533.75	5.20566
2536.5	4.64268
2539.25	4.74485
2542.01	4.49052
2544.75	4.83568
2547.5	4.55593
2550.25	3.90164
2553	2.56492
2555.74	1.07469
2558.49	1.06648
2561.23	0.897109
2563.97	0.810363
2566.71	0.693373
2569.45	0.245297
2572.19	-0.000543478
2574.93	0.0755953
2577.67	1.20829
2580.4	2.05135
2583.14	3.37293
2585.87	4.07905
2588.6	3.87635
2591.34	5.51279
2594.07	7.11125
2596.8	6.77691
2599.53	8.01622
2602.26	8.27589
2604.98	7.66981
2607.71	7.23235
2610.44	7.17541
2613.16	6.51507
2615.88	5.35543
2618.61	5.26359
2621.33	3.84951
2624.05	3.51082
2626.77	2.83605
2629.49	1.71183
2632.21	1.65457
2634.92	1.25543
2637.64	1.23213
2640.35	2.38421
2643.07	2.56095
2645.78	3.02828
2648.49	3.99595
2651.2	4.75953
2653.91	5.11995
2656.62	5.70935
2659.33	5.88901
2662.04	5.66937
2664.74	5.68629
2667.45	6.0898
2670.15	4.9988
2672.86	5.32737
2675.56	4.7465
2678.26	5.48385
2680.96	5.77153
2683.66	5.43353
2686.36	5.2397
2689.06	4.94681
2691.75	5.27319
2694.45	5.59223
2697.14	6.13843
2699.84	6.65532
2702.53	7.48599
2705.22	8.40524
2707.91	8.40484
2710.6	7.9495
2713.29	8.79536
2715.98	9.06508
2718.67	8.25941
2721.35	8.00268
2724.04	7.36689
2726.72	7.51015
2729.4	7.92386
2732.09	7.23456
2734.77	6.80696
2737.45	6.47232
2740.13	5.88132
2742.81	6.17203
2745.48	6.38795
2748.16	5.95886
2750.84	5.56588
2753.51	5.60466
2756.19	4.78879
2758.86	4.66675
2761.53	4.92892
2764.2	4.86086
2766.87	5.17215
2769.54	5.35592
2772.21	5.10922
2774.88	5.20008
2777.54	5.17028
2780.21	5.66714
2782.87	5.65742
2785.53	6.15093
2788.2	5.77079
2790.86	6.62955
2793.52	7.0314
2796.18	5.79196
2798.84	5.15169
2801.49	4.98531
2804.15	5.04402
2806.81	3.73859
2809.46	2.88091
2812.12	2.36151
2814.77	2.30216
2817.42	1.78986
2820.07	1.88087
2822.72	2.54775
2825.37	3.92868
2828.02	6.27301
2830.67	9.33245
2833.31	12.3702
2835.96	15.2951
2838.61	17.522
2841.25	20.6116
2843.89	24.2516
2846.53	27.5512
2849.17	30.7607
2851.81	34.6107
2854.45	38.3199
2857.09	41.4968
2859.73	44.7653
2862.36	47.6632
2865	51.1686
2867.64	53.6151
2870.27	55.9446
2872.9	57.5993
2875.53	60.0426
2878.16	62.1421
2880.79	64.2186
2883.42	66.3948
2886.05	68.5286
2888.68	70.2191
2891.3	72.7148
2893.93	74.3884
2896.55	76.577
2899.18	77.9247
2901.8	79.3937
2904.42	80.8842
2907.04	83.5923
2909.66	86.2157
2912.28	90.256
2914.9	93.348
2917.51	97.8986
2920.13	101.869
2922.74	104.813
2925.36	108.407
2927.97	110.215
2930.59	112.337
2933.2	112.673
2935.81	112.727
2938.42	111.267
2941.02	110.911
2943.63	108.454
2946.24	106.171
2948.85	102.177
2951.45	98.4013
2954.05	92.9185
2956.66	88.6125
2959.26	83.6753
2961.86	79.0856
2964.46	73.7439
2967.06	68.3195
2969.66	63.6112
2972.26	59.7276
2974.85	56.6376
2977.45	52.7795
2980.05	48.7122
2982.64	44.8132
2985.23	39.8276
2987.83	36.652
2990.42	33.3696
2993.01	28.5425
2995.6	25.2845
2998.19	21.6381
3000.77	18.5989
3003.36	16.0252
3005.95	13.525
3008.53	11.2565
3011.12	9.82617
3013.7	8.01429
3016.28	5.70938
3018.86	4.94409
3021.44	3.91297
3024.02	2.95317
3026.6	2.42881
3029.18	1.3511
3031.76	1.4682
3034.33	1.98185
3036.91	2.22503
3039.48	2.35824
3042.05	1.26469
3044.63	1.20401
3047.2	1.57988
3049.77	1.85391
3052.34	2.61983
3054.91	1.96195
3057.48	1.37012
3060.04	1.53844
3062.61	1.06823
3065.17	1.29375
3067.74	1.23794
3070.3	1.07456
3072.87	0.763461
3075.43	0.761745
3077.99	0.290811
3080.55	0.376301
3083.11	-0.0596633
3085.67	-0.362872
3088.22	-0.179814
3090.78	0.241953
3093.34	0.644002
3095.89	1.78671
3098.44	1.91043
3101	2.2985
3103.55	2.24903
3106.1	3.50434
3108.65	3.57591
3111.2	4.45408
3113.75	5.93435
3116.3	6.05776
3118.84	7.33399
3121.39	8.59082
3123.93	9.36987
3126.48	10.6326
3129.02	11.4112
3131.56	12.4472
3134.1	13.0162
3136.64	13.9574
3139.18	15.5512
3141.72	15.8217
3144.26	16.3653
3146.8	16.7849
3149.33	15.764