File: data/Raman/poly_smoothed/Mb_40_y_28_1x_45s_532 nm_x100_100%_600 gr_mm_01.txt
#Acq. time (s)=	45
#Accumulations=	2
#Range (cm-¹)=	200...3150
#Windows=	2
#Auto scanning=	Off
#Autofocus=	Off
#Macrospot=	Off
#AutoExposure=	Off
#Spike filter=	Multiple accum.
#Delay time (s)=	0
#Binning=	1
#Readout mode=	Signal
#DeNoise=	Off
#ICS correction=	On
#Dark correction=	Off
#Inst. Process=	Off
#Detector Gain=	Best Dynamic Range
#Detector ADC=	20 kHz
#Detector temperature (°C)=	-69.85
#Instrument=	LabRAM HR Evol
#Detector=	Synapse
#Objective=	x100
#Grating=	600 gr/mm
#ND Filter=	100%
#Laser (nm)=	532
#Hole=	100.021
#Range=	Auto
#Laser Pol.=	No
#Raman. Pol.=	No
#Laser Pol. (°)=	-0.0007625
#Raman Pol. (°)=	89.9995
#Collection=	Microscope
#StageXY=	Marzhauser
#StageZ=	Marzhauser
#X (µm)=	-1094.2
#Y (µm)=	573.8
#Z (µm)=	584.5
#Full time(mm:ss)=	3:18
#Project=
#Sample=
#Site=
#Title=	Mb_40_y_28_2x_45s_532 nm_x100_100%_600 gr_mm
#Remark=
#Date=	19.07.2022 11:42
#Acquired=	19.07.2022 11:42:56
#Base:Fit=	10.08.2022 10:52:48
#Base:Sub=	10.08.2022 10:52:53
#Filter:Polynom=	16.08.2022 10:09:04
#AxisType[0]=Intens
#AxisUnit[0]=Cnt
#AxisType[1]=Spectr
#AxisUnit[1]=1/cm
200.423	64.0117
204.052	55.6639
207.682	50.551
211.308	44.9576
214.935	39.2951
218.558	34.5717
222.18	30.8008
225.802	25.4597
229.421	22.2767
233.039	19.8465
236.657	18.0352
240.272	15.5673
243.885	13.9078
247.497	12.0447
251.11	10.0801
254.719	9.47584
258.327	8.67998
261.933	6.73041
265.538	5.4417
269.141	4.37675
272.744	4.68193
276.344	5.16474
279.944	4.24629
283.542	4.76916
287.138	3.47369
290.733	3.2761
294.327	4.16305
297.919	2.16606
301.508	3.13963
305.098	3.43595
308.686	3.64022
312.273	4.62257
315.858	3.95145
319.44	5.11457
323.022	5.50337
326.604	6.26424
330.181	7.13937
333.76	7.89291
337.335	6.84794
340.91	7.81579
344.483	8.46013
348.055	8.44118
351.625	9.15243
355.195	9.007
358.762	10.2394
362.329	10.3158
365.893	9.86285
369.455	10.1315
373.017	9.94539
376.578	9.62143
380.137	10.6506
383.694	10.0543
387.249	9.51977
390.806	9.06152
394.359	7.90269
397.91	6.04257
401.46	5.3219
405.009	4.74985
408.557	4.47106
412.103	4.16383
415.647	4.16341
419.191	3.6802
422.733	4.23657
426.273	4.98946
429.812	6.04566
433.35	7.26215
436.885	7.26187
440.42	6.84953
443.954	6.00674
447.486	5.95489
451.015	6.68048
454.545	7.85481
458.073	8.65031
461.598	9.09181
465.124	10.7052
468.648	10.5492
472.169	11.5346
475.69	12.4365
479.208	13.1925
482.727	14.3469
486.243	16.1625
489.759	17.0495
493.272	16.4499
496.783	17.0898
500.295	18.4567
503.804	19.3753
507.311	22.7817
510.819	24.6965
514.324	25.5358
517.827	25.6523
521.329	26.8769
524.83	25.5735
528.329	24.5964
531.829	25.4695
535.326	25.3314
538.821	25.3633
542.315	22.983
545.808	22.4867
549.299	21.2309
552.789	19.3365
556.278	17.789
559.763	17.1614
563.249	14.9293
566.733	11.9581
570.217	9.03382
573.699	7.43935
577.177	4.017
580.656	2.00851
584.134	1.28135
587.609	-0.189007
591.084	0.848419
594.558	0.81083
598.029	1.33622
601.5	2.42464
604.968	2.37289
608.437	3.4749
611.902	3.24646
615.368	3.58181
618.831	5.69989
622.294	6.58528
625.755	6.43753
629.213	6.52001
632.673	8.46577
636.129	9.91297
639.584	9.16305
643.037	9.56454
646.491	9.89385
649.942	10.976
653.392	10.5037
656.84	11.9202
660.287	11.8535
663.732	9.85309
667.177	9.96316
670.62	9.96059
674.061	11.0852
677.502	11.4115
680.941	12.8272
684.379	13.7536
687.815	16.0236
691.248	17.6178
694.682	18.835
698.115	21.7371
701.546	26.1813
704.974	30.5253
708.402	32.8949
711.83	34.6698
715.254	37.6685
718.679	40.3603
722.102	41.0719
725.522	43.0861
728.943	44.9968
732.361	45.6208
735.779	46.2682
739.194	45.4123
742.608	44.8263
746.022	42.6837
749.433	40.398
752.843	41.7364
756.254	43.1574
759.661	42.2221
763.067	44.3031
766.471	46.071
769.877	48.7864
773.279	51.3394
776.68	53.9176
780.079	56.6538
783.478	60.786
786.875	62.6182
790.27	65.2715
793.665	65.8237
797.058	67.7608
800.45	69.4493
803.84	70.4975
807.23	70.87
810.616	69.791
814.002	68.5642
817.388	66.7119
820.772	65.796
824.153	63.767
827.535	62.512
830.915	61.2103
834.292	59.9602
837.67	59.4514
841.047	57.9458
844.42	55.2855
847.794	54.5918
851.165	54.0256
854.534	52.49
857.905	49.8616
861.272	48.7265
864.639	47.2534
868.004	45.6698
871.367	44.4943
874.731	43.9123
878.092	42.6786
881.451	42.4905
884.809	41.8031
888.166	41.5188
891.522	38.9806
894.878	39.6375
898.231	40.4387
901.583	39.9486
904.934	39.0569
908.283	39.0435
911.631	39.1608
914.976	38.1418
918.322	38.8009
921.666	39.3346
925.009	37.3783
928.351	37.0527
931.692	37.3978
935.029	35.3018
938.367	34.6445
941.704	33.6737
945.038	32.7126
948.372	32.2423
951.705	32.3632
955.035	32.3545
958.366	31.1834
961.693	30.3451
965.021	31.1998
968.346	31.9041
971.67	32.5595
974.995	33.6529
978.316	34.6835
981.638	36.286
984.957	36.7891
988.274	37.243
991.59	35.5827
994.907	34.8511
998.221	31.9746
1001.53	26.6036
1004.85	23.7724
1008.16	25.3313
1011.46	36.3989
1014.77	52.2739
1018.08	69.1746
1021.38	85.0607
1024.69	100.75
1027.99	113.695
1031.29	125.937
1034.59	134.119
1037.89	140.889
1041.19	144.452
1044.48	147.188
1047.78	147.822
1051.07	143.686
1054.36	139.007
1057.66	131.2
1060.94	120.186
1064.23	105.334
1067.52	90.441
1070.81	72.1086
1074.09	51.8972
1077.38	33.5006
1080.66	16.9967
1083.94	5.73918
1087.22	2.20085
1090.5	5.70448
1093.77	10.2903
1097.05	13.2059
1100.32	15.1768
1103.6	16.9621
1106.87	17.8727
1110.14	18.1341
1113.41	19.0929
1116.67	20.8116
1119.94	20.1554
1123.21	19.4749
1126.47	18.8103
1129.73	17.8316
1133	17.5725
1136.26	15.319
1139.52	14.1899
1142.77	11.5811
1146.03	11.1203
1149.29	10.104
1152.54	7.30832
1155.79	4.6692
1159.04	3.27897
1162.3	2.87083
1165.55	1.30064
1168.79	1.59992
1172.04	2.40928
1175.28	2.04771
1178.53	4.07918
1181.77	5.70206
1185.01	5.92809
1188.25	7.14876
1191.49	7.5334
1194.73	8.41765
1197.97	7.83632
1201.2	9.07775
1204.44	9.9453
1207.67	10.507
1210.9	11.8984
1214.13	12.3065
1217.36	14.2255
1220.59	16.7241
1223.82	19.655
1227.04	22.2809
1230.26	25.5381
1233.49	28.118
1236.71	31.7848
1239.93	37.5308
1243.15	40.9029
1246.37	43.5075
1249.58	48.5623
1252.8	50.6986
1256.01	54.3578
1259.23	56.3575
1262.44	59.7691
1265.65	61.85
1268.86	63.5506
1272.07	65.753
1275.27	68.6649
1278.48	71.1339
1281.68	72.4334
1284.89	73.7478
1288.09	75.699
1291.29	77.7033
1294.49	79.0054
1297.69	79.3216
1300.88	79.4003
1304.08	80.8798
1307.27	80.8983
1310.47	80.7732
1313.66	80.8549
1316.85	80.1216
1320.04	80.6139
1323.23	79.0278
1326.41	78.2703
1329.6	77.1897
1332.78	74.6444
1335.97	72.1588
1339.15	69.4092
1342.33	66.7206
1345.51	64.4194
1348.69	61.6804
1351.87	58.9581
1355.04	56.6281
1358.22	54.101
1361.39	51.9099
1364.57	49.8456
1367.74	47.3855
1370.91	44.379
1374.07	40.8823
1377.24	37.7762
1380.41	37.8276
1383.57	37.5491
1386.74	38.0102
1389.9	38.1226
1393.06	38.4968
1396.22	40.4929
1399.38	41.9124
1402.54	44.1109
1405.7	46.059
1408.85	48.4108
1412.01	49.9059
1415.16	53.4906
1418.31	56.1005
1421.46	60.4199
1424.61	64.343
1427.76	67.9971
1430.91	73.6448
1434.05	78.2098
1437.2	81.3032
1440.34	84.1504
1443.49	86.9103
1446.63	86.294
1449.77	86.117
1452.91	86.0135
1456.04	85.4928
1459.18	84.7488
1462.31	81.7954
1465.45	79.0625
1468.58	76.1849
1471.71	72.4003
1474.84	69.0469
1477.97	64.6049
1481.1	60.3219
1484.23	54.9407
1487.35	49.6999
1490.48	45.1028
1493.6	40.9909
1496.72	36.7935
1499.84	29.6181
1502.96	28.2479
1506.08	31.1052
1509.2	31.7354
1512.31	32.4702
1515.43	32.8867
1518.54	34.733
1521.66	35.2934
1524.77	35.9261
1527.88	37.7426
1530.99	39.548
1534.09	41.2432
1537.2	42.6898
1540.31	45.5144
1543.41	46.7965
1546.51	46.9749
1549.62	47.0385
1552.72	47.2035
1555.82	46.5609
1558.91	44.4935
1562.01	42.1867
1565.11	41.2633
1568.2	41.3821
1571.3	39.9968
1574.39	39.5388
1577.48	39.5619
1580.57	46.316
1583.66	48.8263
1586.75	49.7896
1589.83	52.1356
1592.92	54.9643
1596	55.7933
1599.09	55.7953
1602.17	56.2431
1605.25	55.6079
1608.33	56.637
1611.41	54.5861
1614.48	55.4066
1617.56	55.2882
1620.64	55.5632
1623.71	58.2065
1626.78	60.0141
1629.86	62.9025
1632.92	64.3927
1635.99	67.325
1639.06	70.3358
1642.13	72.6308
1645.19	75.1449
1648.26	79.2497
1651.32	80.3043
1654.38	82.4749
1657.45	84.5125
1660.51	84.4133
1663.57	83.2499
1666.62	80.7221
1669.68	77.2431
1672.73	72.1701
1675.79	67.4298
1678.84	62.0067
1681.89	56.2267
1684.94	50.1466
1687.99	44.3112
1691.04	39.2022
1694.09	33.7507
1697.14	29.4541
1700.18	25.2794
1703.22	21.9307
1706.27	17.1562
1709.31	15.1104
1712.35	13.0567
1715.39	9.8382
1718.43	9.24159
1721.46	8.36742
1724.5	7.83338
1727.53	5.86238
1730.57	5.34791
1733.6	4.81616
1736.63	4.55836
1739.66	4.55828
1742.69	4.87936
1745.72	5.06888
1748.74	5.32646
1751.77	5.96857
1754.8	5.71863
1757.82	5.21356
1760.84	5.00743
1763.86	4.15152
1766.88	3.15751
1769.9	3.14256
1772.92	3.38673
1775.93	2.88574
1778.95	3.565
1781.96	3.70098
1784.98	3.90527
1787.99	3.11899
1791	3.34223
1794.01	3.5203
1797.02	3.72366
1800.03	2.47981
1803.03	2.67044
1806.04	3.38191
1809.04	3.18562
1812.04	3.80403
1815.05	3.28709
1818.05	2.7366
1821.05	3.13131
1824.05	3.16945
1827.04	3.29092
1830.04	3.19766
1833.03	3.80815
1836.03	3.45505
1839.02	4.15634
1842.01	3.9728
1845	3.03105
1847.99	2.68694
1850.98	1.63729
1853.97	1.9687
1856.95	0.451077
1859.94	1.37546
1862.92	1.4216
1865.91	1.4183
1868.89	1.34854
1871.87	1.20119
1874.85	0.726526
1877.83	0.32031
1880.8	-0.00300966
1882.56	1.0968
1885.54	1.14511
1888.53	1.29557
1891.52	1.98273
1894.5	2.93285
1897.49	2.97412
1900.47	3.76564
1903.45	4.30537
1906.43	4.56223
1909.41	4.59334
1912.39	5.0366
1915.37	4.86871
1918.35	4.40865
1921.32	3.82336
1924.3	3.2525
1927.27	2.10682
1930.24	2.32226
1933.21	1.91973
1936.18	2.52487
1939.15	2.64508
1942.12	1.51941
1945.09	1.03457
1948.05	1.71683
1951.02	2.14267
1953.98	3.65803
1956.94	4.24117
1959.91	3.94201
1962.87	5.37934
1965.82	5.65551
1968.78	5.68181
1971.74	6.34583
1974.7	7.39509
1977.65	7.57804
1980.6	7.92755
1983.56	8.00811
1986.51	8.55306
1989.46	8.4166
1992.41	7.62832
1995.36	7.56857
1998.3	6.67957
2001.25	5.60847
2004.2	5.2642
2007.14	5.06486
2010.08	5.16661
2013.02	4.14097
2015.97	3.70016
2018.9	4.8127
2021.84	5.30878
2024.78	5.28066
2027.72	5.0552
2030.65	5.44679
2033.59	6.49954
2036.52	5.86372
2039.45	6.34482
2042.38	7.27525
2045.31	7.53906
2048.24	7.75565
2051.17	8.00289
2054.1	8.2675
2057.02	10.0319
2059.95	10.0935
2062.87	10.2276
2065.79	10.7486
2068.71	10.8299
2071.63	11.8471
2074.55	13.0263
2077.47	14.8884
2080.39	15.5021
2083.3	18.5113
2086.22	20.1265
2089.13	22.1117
2092.05	23.521
2094.96	25.3138
2097.87	25.8639
2100.78	27.272
2103.69	28.7225
2106.59	30.6637
2109.5	32.3039
2112.41	33.9704
2115.31	34.1401
2118.21	35.8368
2121.12	37.712
2124.02	41.1544
2126.92	44.1525
2129.82	46.5797
2132.71	49.9547
2135.61	53.3178
2138.51	57.9922
2141.4	63.5684
2144.29	68.8068
2147.19	72.5918
2150.08	77.1179
2152.97	81.0599
2155.86	84.4734
2158.75	86.7172
2161.64	89.2644
2164.52	91.4126
2167.41	92.5925
2170.29	93.345
2173.17	93.9477
2176.06	93.3787
2178.94	91.6352
2181.82	88.9579
2184.7	86.3263
2187.57	83.0287
2190.45	79.8373
2193.33	77.2304
2196.2	73.4801
2199.08	69.7726
2201.95	67.542
2204.82	64.8808
2207.69	61.8347
2210.56	59.6747
2213.43	55.9042
2216.3	51.8168
2219.16	48.6001
2222.03	45.8469
2224.89	43.0731
2227.75	41.7612
2230.62	40.344
2233.48	37.9033
2236.34	36.7655
2239.2	34.4887
2242.06	32.3729
2244.91	30.8264
2247.77	29.7276
2250.62	28.67
2253.48	27.0677
2256.33	24.7224
2259.18	22.6454
2262.03	20.7269
2264.88	19.2327
2267.73	18.5723
2270.58	18.7614
2273.43	18.8349
2276.27	17.8305
2279.12	16.009
2281.96	14.3717
2284.8	12.9181
2287.64	12.3594
2290.49	12.0122
2293.32	10.3166
2296.16	9.522
2299	9.80452
2301.84	10.3802
2304.67	9.90774
2307.51	10.5955
2310.34	9.75646
2313.17	10.1913
2316	10.1847
2318.83	9.55156
2321.66	8.72447
2324.49	7.64328
2327.32	6.48333
2330.15	6.33758
2332.97	6.16453
2335.79	6.09925
2338.62	6.41862
2341.44	5.64844
2344.26	4.41676
2347.08	3.34527
2349.9	2.25059
2352.72	1.53963
2355.53	1.53779
2358.35	1.53356
2361.17	0.923238
2363.98	0.765065
2366.79	2.1251
2369.6	1.95409
2372.42	1.94328
2375.22	2.74336
2378.03	3.13404
2380.84	3.34918
2383.65	4.07113
2386.45	3.86138
2389.26	4.53037
2392.06	5.21377
2394.87	4.75834
2397.67	4.70724
2400.47	4.8685
2403.27	4.77403
2406.07	5.4297
2408.86	5.38173
2411.66	5.15674
2414.46	5.20141
2417.25	5.59914
2420.05	5.99851
2422.84	6.64324
2425.63	6.69971
2428.42	6.27723
2431.21	5.56259
2434	3.71881
2436.79	4.44723
2439.57	4.43383
2442.36	4.54382
2445.14	4.68694
2447.93	5.25876
2450.71	5.45924
2453.49	4.59259
2456.27	5.05882
2459.05	4.48079
2461.83	3.68943
2464.61	2.97984
2467.39	3.09172
2470.16	3.00483
2472.94	2.60977
2475.71	3.10692
2478.48	3.01331
2481.25	3.00234
2484.02	2.91876
2486.8	3.23538
2489.56	3.33694
2492.33	3.34786
2495.1	3.21937
2497.86	2.69294
2500.63	3.14062
2503.39	3.57246
2506.16	3.15556
2508.92	3.83971
2511.68	4.47625
2514.44	5.70136
2517.2	6.42579
2519.95	6.39277
2522.71	5.71216
2525.47	5.63712
2528.22	5.64003
2530.98	5.285
2533.73	4.37335
2536.48	3.57606
2539.23	3.21722
2541.98	1.84997
2544.73	2.65373
2547.48	2.49141
2550.23	2.26866
2552.97	1.86264
2555.72	1.56348
2558.46	2.13831
2561.2	1.84537
2563.95	1.77844
2566.69	1.50072
2569.43	1.74787
2572.17	1.51899
2574.91	1.71542
2577.64	2.58777
2580.38	2.7186
2583.11	3.59407
2585.85	3.06076
2588.58	3.71662
2591.31	4.05094
2594.04	4.76435
2596.78	5.19244
2599.51	4.73069
2602.23	5.19033
2604.96	5.33304
2607.69	5.77442
2610.41	5.90259
2613.14	5.85175
2615.86	5.34709
2618.58	4.7911
2621.3	4.12543
2624.03	4.00455
2626.75	4.27004
2629.46	3.33678
2632.18	3.31424
2634.9	2.21997
2637.61	2.5136
2640.33	2.66258
2643.04	2.67587
2645.76	2.56941
2648.47	2.4004
2651.18	2.61538
2653.89	3.12144
2656.6	3.17042
2659.31	3.35748
2662.01	3.94352
2664.72	4.80083
2667.43	4.04371
2670.13	4.51688
2672.83	4.54136
2675.53	4.16839
2678.24	3.43474
2680.94	3.23443
2683.64	3.67926
2686.34	4.1644
2689.03	4.16438
2691.73	4.57353
2694.43	5.02483
2697.12	5.31421
2699.81	6.49663
2702.51	6.48247
2705.2	6.7305
2707.89	6.65431
2710.58	6.7638
2713.27	6.84598
2715.96	7.15808
2718.64	7.58191
2721.33	7.50858
2724.01	7.60271
2726.7	7.61382
2729.38	8.90151
2732.06	8.50616
2734.75	8.69065
2737.43	10.2154
2740.11	10.1125
2742.78	9.52896
2745.46	9.10843
2748.14	9.63089
2750.81	9.42442
2753.49	9.80701
2756.16	9.1457
2758.84	9.0853
2761.51	8.21396
2764.18	7.81156
2766.85	6.54215
2769.52	5.24515
2772.19	4.81228
2774.85	4.00844
2777.52	2.19493
2780.18	1.65141
2782.85	0.713406
2785.51	0.185057
2788.17	-0.314217
2790.84	-0.609825
2793.5	-0.378269
2796.16	-0.426241
2798.81	-0.878892
2801.47	-0.706037
2804.13	-0.766233
2806.79	-0.654733
2809.44	-1.56948
2812.09	-1.46394
2814.75	-1.21085
2817.4	-0.354804
2820.05	1.87452
2822.7	4.77411
2825.35	7.53294
2828	10.9937
2830.65	14.8282
2833.29	17.8034
2835.94	22.1667
2838.58	26.2342
2841.23	31.8542
2843.87	37.1347
2846.51	43.5388
2849.15	50.025
2851.79	56.8511
2854.43	63.3218
2857.07	69.8471
2859.71	76.1678
2862.34	82.6417
2864.98	87.9656
2867.61	92.4824
2870.25	97.8222
2872.88	101.278
2875.51	104.386
2878.14	108.593
2880.77	111.149
2883.4	115.799
2886.03	120.126
2888.65	123.269
2891.28	125.425
2893.91	129.224
2896.53	133.096
2899.15	137.335
2901.78	143.192
2904.4	150.381
2907.02	158.959
2909.64	167.477
2912.26	177.659
2914.87	187.431
2917.49	195.613
2920.11	204.878
2922.72	213.215
2925.34	219.446
2927.95	224.851
2930.56	228.581
2933.17	230.395
2935.78	230.031
2938.39	228.379
2941	225.179
2943.61	220.42
2946.22	214.175
2948.82	207.502
2951.43	198.381
2954.03	188.456
2956.64	178.396
2959.24	168.67
2961.84	159.099
2964.44	149.234
2967.04	140.381
2969.64	133.005
2972.24	124.364
2974.83	116.657
2977.43	108.227
2980.02	99.6932
2982.62	91.0823
2985.21	83.1922
2987.8	75.6046
2990.4	68.3701
2992.99	61.7882
2995.57	54.5127
2998.16	48.0337
3000.75	42.0122
3003.34	36.1361
3005.92	30.4777
3008.51	26.0286
3011.09	21.3462
3013.68	18.0788
3016.26	14.7918
3018.84	12.6238
3021.42	10.1337
3024	8.81959
3026.58	6.84633
3029.16	5.55304
3031.73	5.33163
3034.31	4.47727
3036.89	4.04008
3039.46	3.58212
3042.03	3.81541
3044.61	4.10153
3047.18	5.49739
3049.75	6.2321
3052.32	6.99291
3054.89	7.55657
3057.45	7.37383
3060.02	7.29413
3062.59	7.38661
3065.15	6.75815
3067.72	6.57348
3070.28	5.74277
3072.84	5.06244
3075.41	5.06097
3077.97	4.72968
3080.53	4.49652
3083.09	3.50657
3085.64	1.90307
3088.2	0.984516
3090.76	0.288057
3093.31	-0.542901
3095.87	-0.712133
3098.42	-0.156452
3100.97	-0.224907
3103.53	-0.266403
3106.08	0.751951
3108.63	1.45349
3111.18	2.42044
3113.73	3.64335
3116.27	4.1198
3118.82	5.0024
3121.37	5.75449
3123.91	6.69978
3126.45	8.44461
3129	9.70635
3131.54	11.0241
3134.08	12.1025
3136.62	14.1563
3139.16	16.2153
3141.7	17.5201
3144.24	18.5763
3146.78	20.62
3149.31	22.3235