File: data/Raman/poly_smoothed/Mb_40_y_36_1x_45s_532 nm_x100_100%_600 gr_mm_01.txt
#Acq. time (s)=	45
#Accumulations=	2
#Range (cm-¹)=	200...3150
#Windows=	2
#Auto scanning=	Off
#Autofocus=	Off
#Macrospot=	Off
#AutoExposure=	Off
#Spike filter=	Multiple accum.
#Delay time (s)=	0
#Binning=	1
#Readout mode=	Signal
#DeNoise=	Off
#ICS correction=	On
#Dark correction=	Off
#Inst. Process=	Off
#Detector Gain=	Best Dynamic Range
#Detector ADC=	20 kHz
#Detector temperature (°C)=	-69.85
#Instrument=	LabRAM HR Evol
#Detector=	Synapse
#Objective=	x100
#Grating=	600 gr/mm
#ND Filter=	100%
#Laser (nm)=	532
#Hole=	100.021
#Range=	Auto
#Laser Pol.=	No
#Raman. Pol.=	No
#Laser Pol. (°)=	-0.0007625
#Raman Pol. (°)=	89.9995
#Collection=	Microscope
#StageXY=	Marzhauser
#StageZ=	Marzhauser
#X (µm)=	-1093.6
#Y (µm)=	588.4
#Z (µm)=	584.5
#Full time(mm:ss)=	3:19
#Project=
#Sample=
#Site=
#Title=	Mb_40_y_36_2x_45s_532 nm_x100_100%_600 gr_mm
#Remark=
#Date=	19.07.2022 12:21
#Acquired=	19.07.2022 12:21:18
#Base:Fit=	10.08.2022 10:52:48
#Base:Sub=	10.08.2022 10:52:53
#Filter:Polynom=	16.08.2022 10:09:04
#AxisType[0]=Intens
#AxisUnit[0]=Cnt
#AxisType[1]=Spectr
#AxisUnit[1]=1/cm
200.423	24.0653
204.052	20.1271
207.682	18.1609
211.308	15.5249
214.935	12.6723
218.558	10.3134
222.18	9.1051
225.802	6.42962
229.421	6.96434
233.039	5.33924
236.657	5.11682
240.272	5.07282
243.885	4.73607
247.497	4.05387
251.11	3.41732
254.719	3.5456
258.327	1.65762
261.933	1.63893
265.538	3.13821
269.141	3.21965
272.744	2.04126
276.344	3.03059
279.944	2.52389
283.542	2.98407
287.138	4.81805
290.733	6.10038
294.327	6.33518
297.919	7.31914
301.508	9.11266
305.098	10.8778
308.686	12.5336
312.273	14.1221
315.858	13.5578
319.44	13.5324
323.022	12.9817
326.604	13.8031
330.181	13.4131
333.76	13.6721
337.335	13.0991
340.91	11.9374
344.483	9.42194
348.055	10.0485
351.625	9.84499
355.195	9.78358
358.762	9.47256
362.329	9.29402
365.893	8.8438
369.455	8.81619
373.017	8.76673
376.578	8.67966
380.137	10.617
383.694	9.90777
387.249	10.8187
390.806	9.79691
394.359	9.49158
397.91	8.63647
401.46	7.74526
405.009	5.68052
408.557	6.75963
412.103	6.39191
415.647	7.0415
419.191	8.88165
422.733	9.01986
426.273	8.32315
429.812	7.14619
433.35	7.71098
436.885	7.85729
440.42	9.7911
443.954	11.1997
447.486	10.8289
451.015	11.1238
454.545	11.1562
458.073	12.6799
461.598	13.6091
465.124	14.4051
468.648	15.314
472.169	14.2688
475.69	13.5876
479.208	14.2329
482.727	15.2966
486.243	16.1026
489.759	16.6101
493.272	18.5343
496.783	20.2784
500.295	21.4114
503.804	23.9127
507.311	23.2653
510.819	24.0203
514.324	22.8949
517.827	21.3802
521.329	22.5395
524.83	23.7693
528.329	24.7153
531.829	24.2727
535.326	24.8265
538.821	24.0754
542.315	23.6943
545.808	22.818
549.299	22.4938
552.789	22.3325
556.278	21.0561
559.763	19.9286
563.249	20.1514
566.733	19.0699
570.217	19.3894
573.699	18.2437
577.177	18.7149
580.656	19.0323
584.134	17.4
587.609	16.9314
591.084	16.0768
594.558	17.504
598.029	17.9659
601.5	16.3272
604.968	15.5709
608.437	15.5227
611.902	14.8006
615.368	14.4355
618.831	14.1054
622.294	12.4696
625.755	10.8286
629.213	9.98906
632.673	11.2123
636.129	12.4565
639.584	10.1255
643.037	10.263
646.491	9.24049
649.942	10.6807
653.392	12.3551
656.84	12.8963
660.287	14.2536
663.732	14.7061
667.177	16.421
670.62	18.9411
674.061	22.1896
677.502	25.7665
680.941	27.3201
684.379	28.8753
687.815	29.4148
691.248	31.6896
694.682	35.1241
698.115	36.5831
701.546	37.947
704.974	38.9302
708.402	39.9159
711.83	40.6289
715.254	40.3433
718.679	42.9217
722.102	42.3926
725.522	40.5224
728.943	41.7817
732.361	43.3178
735.779	43.9844
739.194	43.4513
742.608	43.9944
746.022	44.5014
749.433	46.8206
752.843	49.6618
756.254	52.5633
759.661	54.6828
763.067	58.2747
766.471	59.84
769.877	62.7234
773.279	65.3214
776.68	67.9343
780.079	70.1021
783.478	72.7237
786.875	74.4792
790.27	76.9955
793.665	78.6128
797.058	79.1961
800.45	80.3701
803.84	79.6537
807.23	78.2495
810.616	78.6964
814.002	80.056
817.388	79.5223
820.772	79.4549
824.153	77.5271
827.535	77.8895
830.915	77.5553
834.292	77.2249
837.67	75.8003
841.047	74.7793
844.42	72.1754
847.794	69.7742
851.165	67.5015
854.534	64.666
857.905	61.486
861.272	59.9423
864.639	58.7832
868.004	57.1604
871.367	55.1415
874.731	52.9603
878.092	50.369
881.451	48.7847
884.809	47.9157
888.166	47.8796
891.522	48.8126
894.878	47.4458
898.231	47.0736
901.583	48.3412
904.934	45.9986
908.283	45.7126
911.631	46.4905
914.976	46.8228
918.322	47.08
921.666	47.2557
925.009	46.4291
928.351	44.6504
931.692	45.2917
935.029	44.7513
938.367	43.9208
941.704	43.426
945.038	44.3114
948.372	43.891
951.705	42.7187
955.035	41.4942
958.366	41.747
961.693	41.266
965.021	40.1233
968.346	38.5977
971.67	37.0092
974.995	33.7571
978.316	32.8659
981.638	33.5403
984.957	31.2941
988.274	29.2994
991.59	27.4718
994.907	26.1799
998.221	22.6143
1001.53	19.2208
1004.85	16.3747
1008.16	18.1069
1011.46	25.2458
1014.77	34.8097
1018.08	45.1705
1021.38	55.6649
1024.69	66.9092
1027.99	76.4774
1031.29	83.9642
1034.59	89.8909
1037.89	94.5101
1041.19	96.621
1044.48	96.281
1047.78	95.4375
1051.07	93.4327
1054.36	90.2109
1057.66	85.8861
1060.94	80.3507
1064.23	71.3095
1067.52	61.3958
1070.81	49.3149
1074.09	37.7734
1077.38	26.9244
1080.66	17.0568
1083.94	10.6632
1087.22	9.68149
1090.5	9.91962
1093.77	12.0195
1097.05	13.879
1100.32	15.6215
1103.6	15.4677
1106.87	16.7334
1110.14	15.4879
1113.41	16.3389
1116.67	17.0328
1119.94	17.237
1123.21	15.9912
1126.47	16.8921
1129.73	16.7534
1133	16.1741
1136.26	15.56
1139.52	13.7991
1142.77	11.803
1146.03	9.16231
1149.29	8.67125
1152.54	7.64108
1155.79	7.10309
1159.04	7.35928
1162.3	7.96249
1165.55	7.17462
1168.79	5.93134
1172.04	5.55055
1175.28	5.63027
1178.53	6.73348
1181.77	6.41766
1185.01	7.53855
1188.25	9.60183
1191.49	10.7972
1194.73	11.5251
1197.97	11.8084
1201.2	11.8698
1204.44	12.8269
1207.67	12.9756
1210.9	13.6281
1214.13	14.0576
1217.36	14.4448
1220.59	13.6318
1223.82	16.0503
1227.04	18.8263
1230.26	21.5954
1233.49	24.0598
1236.71	26.1515
1239.93	29.3217
1243.15	31.4536
1246.37	33.0555
1249.58	34.8913
1252.8	37.2137
1256.01	39.3155
1259.23	41.6006
1262.44	43.498
1265.65	45.2005
1268.86	45.7325
1272.07	46.9585
1275.27	47.7027
1278.48	49.1518
1281.68	49.382
1284.89	49.3443
1288.09	49.9978
1291.29	49.3562
1294.49	48.3438
1297.69	48.1122
1300.88	47.86
1304.08	48.7974
1307.27	47.1053
1310.47	47.7545
1313.66	45.5908
1316.85	45.6397
1320.04	46.2769
1323.23	46.2683
1326.41	44.5771
1329.6	44.6932
1332.78	43.318
1335.97	42.0061
1339.15	42.8281
1342.33	40.8575
1345.51	40.8974
1348.69	40.323
1351.87	40.1185
1355.04	38.4342
1358.22	36.7891
1361.39	36.1984
1364.57	34.6696
1367.74	32.7597
1370.91	31.1621
1374.07	29.3502
1377.24	28.7756
1380.41	26.8257
1383.57	26.4712
1386.74	25.772
1389.9	25.5772
1393.06	25.2864
1396.22	26.8029
1399.38	26.0308
1402.54	27.5794
1405.7	30.1082
1408.85	32.8757
1412.01	35.3631
1415.16	37.8282
1418.31	42.1243
1421.46	44.769
1424.61	48.9627
1427.76	52.8793
1430.91	57.6792
1434.05	60.0995
1437.2	63.5598
1440.34	64.9413
1443.49	66.0269
1446.63	67.5289
1449.77	69.6117
1452.91	68.5009
1456.04	67.3797
1459.18	66.4892
1462.31	65.481
1465.45	63.1986
1468.58	60.1785
1471.71	57.4948
1474.84	54.8727
1477.97	52.3523
1481.1	50.4243
1484.23	46.9135
1487.35	43.3956
1490.48	41.8439
1493.6	39.51
1496.72	36.7158
1499.84	34.272
1502.96	32.1552
1506.08	30.24
1509.2	27.9996
1512.31	24.8289
1515.43	21.5466
1518.54	20.4364
1521.66	19.8573
1524.77	19.5107
1527.88	18.1946
1530.99	17.2636
1534.09	17.0741
1537.2	19.7144
1540.31	21.3585
1543.41	21.8805
1546.51	22.4769
1549.62	23.088
1552.72	23.5355
1555.82	24.2051
1558.91	25.3049
1562.01	26.6275
1565.11	28.6925
1568.2	30.5322
1571.3	32.4257
1574.39	33.1663
1577.48	33.5567
1580.57	34.3641
1583.66	35.4242
1586.75	35.5783
1589.83	36.2421
1592.92	37.9048
1596	39.5048
1599.09	42.0374
1602.17	42.0926
1605.25	41.6002
1608.33	42.702
1611.41	43.3287
1614.48	43.6396
1617.56	42.8688
1620.64	43.9587
1623.71	43.6718
1626.78	43.4825
1629.86	44.1319
1632.92	45.7669
1635.99	46.9275
1639.06	49.045
1642.13	49.2125
1645.19	48.3698
1648.26	49.5852
1651.32	48.8621
1654.38	49.4845
1657.45	48.6372
1660.51	48.6433
1663.57	47.3441
1666.62	46.1141
1669.68	43.7267
1672.73	40.9028
1675.79	37.4852
1678.84	34.2287
1681.89	31.7596
1684.94	29.5554
1687.99	26.9079
1691.04	23.9206
1694.09	21.2999
1697.14	19.6248
1700.18	16.1671
1703.22	13.689
1706.27	12.0857
1709.31	9.47652
1712.35	6.94591
1715.39	5.23115
1718.43	5.14644
1721.46	4.78024
1724.5	4.45875
1727.53	4.49336
1730.57	4.5241
1733.6	4.10642
1736.63	4.69565
1739.66	3.06658
1742.69	2.85504
1745.72	3.69807
1748.74	5.15128
1751.77	5.76153
1754.8	6.77106
1757.82	7.94255
1760.84	8.3944
1763.86	8.86252
1766.88	8.30388
1769.9	8.11523
1772.92	7.66533
1775.93	6.91334
1778.95	6.5041
1781.96	6.45178
1784.98	5.9112
1787.99	5.98418
1791	7.09842
1794.01	6.20356
1797.02	5.4339
1800.03	4.99656
1803.03	5.32628
1806.04	4.09539
1809.04	3.85491
1812.04	3.75973
1815.05	4.15646
1818.05	5.10147
1821.05	5.5752
1824.05	6.45718
1827.04	7.57374
1830.04	7.35318
1833.03	7.85928
1836.03	8.5248
1839.02	8.20664
1842.01	7.95811
1845	8.69639
1847.99	9.09928
1850.98	8.80391
1853.97	9.09127
1856.95	9.01271
1859.94	9.02231
1862.92	8.75987
1865.91	8.54587
1868.89	7.31233
1871.87	7.31613
1874.85	6.68141
1877.83	6.30669
1880.8	5.42122
1882.56	5.27676
1885.54	4.27632
1888.53	3.79428
1891.52	3.41789
1894.5	3.25147
1897.49	2.99834
1900.47	1.48446
1903.45	1.66607
1906.43	2.20575
1909.41	3.4861
1912.39	3.47737
1915.37	4.03057
1918.35	4.85551
1921.32	5.7246
1924.3	7.05105
1927.27	7.75323
1930.24	8.24678
1933.21	7.71205
1936.18	7.23173
1939.15	6.90885
1942.12	5.88085
1945.09	5.07983
1948.05	5.25227
1951.02	4.04313
1953.98	4.33865
1956.94	2.93786
1959.91	2.58939
1962.87	2.5586
1965.82	3.38966
1968.78	3.71928
1971.74	3.94213
1974.7	4.31165
1977.65	5.18355
1980.6	6.40655
1983.56	6.86278
1986.51	8.57895
1989.46	9.56029
1992.41	9.41634
1995.36	10.5104
1998.3	10.279
2001.25	10.0485
2004.2	11.0052
2007.14	11.4467
2010.08	11.9084
2013.02	11.4821
2015.97	11.6104
2018.9	11.2725
2021.84	11.6273
2024.78	11.6061
2027.72	11.1986
2030.65	10.5828
2033.59	11.3586
2036.52	11.4488
2039.45	11.8546
2042.38	10.7377
2045.31	10.4834
2048.24	10.2396
2051.17	10.5778
2054.1	10.3679
2057.02	11.2208
2059.95	10.8765
2062.87	10.1502
2065.79	11.0284
2068.71	11.8677
2071.63	13.3288
2074.55	14.3224
2077.47	16.7044
2080.39	17.225
2083.3	17.6876
2086.22	18.2671
2089.13	19.0071
2092.05	21.0132
2094.96	21.4983
2097.87	22.9616
2100.78	24.3197
2103.69	25.8737
2106.59	28.277
2109.5	29.4635
2112.41	30.2561
2115.31	31.6867
2118.21	33.1266
2121.12	35.1095
2124.02	36.6682
2126.92	38.6897
2129.82	40.119
2132.71	41.4537
2135.61	44.2384
2138.51	46.9693
2141.4	49.5071
2144.29	52.5986
2147.19	54.8482
2150.08	57.045
2152.97	58.993
2155.86	61.0968
2158.75	62.8529
2161.64	64.2119
2164.52	65.8203
2167.41	66.9602
2170.29	67.9187
2173.17	68.5526
2176.06	68.7449
2178.94	67.4985
2181.82	66.7135
2184.7	66.0588
2187.57	65.1137
2190.45	63.7367
2193.33	61.9131
2196.2	60.3551
2199.08	57.5521
2201.95	54.8179
2204.82	52.8303
2207.69	49.7778
2210.56	47.5418
2213.43	44.9216
2216.3	42.2481
2219.16	39.2393
2222.03	37.127
2224.89	35.0942
2227.75	32.9942
2230.62	31.0162
2233.48	29.6376
2236.34	28.1426
2239.2	27.16
2242.06	25.2255
2244.91	24.1059
2247.77	23.2547
2250.62	23.1066
2253.48	23.2807
2256.33	23.1814
2259.18	22.536
2262.03	21.4941
2264.88	21.028
2267.73	20.2648
2270.58	18.6855
2273.43	18.513
2276.27	16.0772
2279.12	14.4813
2281.96	13.7205
2284.8	12.6889
2287.64	12.1452
2290.49	10.5148
2293.32	8.76073
2296.16	7.44434
2299	6.70606
2301.84	7.51682
2304.67	6.67552
2307.51	7.13952
2310.34	7.64043
2313.17	8.04132
2316	8.34273
2318.83	7.84183
2321.66	7.95775
2324.49	8.39965
2327.32	8.8853
2330.15	8.04659
2332.97	8.19623
2335.79	8.52164
2338.62	7.61896
2341.44	6.71517
2344.26	6.24864
2347.08	4.89956
2349.9	5.13476
2352.72	4.35787
2355.53	3.66393
2358.35	3.21465
2361.17	2.23859
2363.98	1.93073
2366.79	2.33527
2369.6	2.3073
2372.42	3.26827
2375.22	3.25345
2378.03	3.13726
2380.84	2.67207
2383.65	2.1617
2386.45	2.84737
2389.26	2.89238
2392.06	3.73948
2394.87	3.75906
2397.67	3.30619
2400.47	3.14968
2403.27	3.88951
2406.07	4.03257
2408.86	3.91198
2411.66	4.89571
2414.46	5.75287
2417.25	5.61855
2420.05	6.23745
2422.84	6.32263
2425.63	6.60165
2428.42	6.81956
2431.21	6.8085
2434	6.38981
2436.79	5.77481
2439.57	6.11786
2442.36	6.16347
2445.14	5.03319
2447.93	4.23743
2450.71	4.81221
2453.49	5.08219
2456.27	4.85138
2459.05	4.24514
2461.83	4.55198
2464.61	3.97021
2467.39	4.90215
2470.16	4.56867
2472.94	4.98448
2475.71	4.42959
2478.48	4.62612
2481.25	3.69974
2484.02	2.89607
2486.8	2.93238
2489.56	3.55047
2492.33	3.02927
2495.1	2.97069
2497.86	3.1796
2500.63	2.2426
2503.39	0.778395
2506.16	0.872817
2508.92	-0.412095
2511.68	-0.891073
2514.44	-0.414861
2517.2	0.415259
2519.95	1.18195
2522.71	1.57799
2525.47	1.90102
2528.22	2.07718
2530.98	1.64734
2533.73	1.96129
2536.48	3.21061
2539.23	2.70095
2541.98	2.93355
2544.73	3.19193
2547.48	3.68681
2550.23	3.51766
2552.97	4.51338
2555.72	4.5537
2558.46	4.78697
2561.2	4.07314
2563.95	4.53601
2566.69	4.8816
2569.43	3.66981
2572.17	3.47846
2574.91	3.44704
2577.64	3.97557
2580.38	4.69612
2583.11	5.50189
2585.85	6.10493
2588.58	6.3655
2591.31	5.76014
2594.04	5.50447
2596.78	4.85022
2599.51	5.16054
2602.23	5.74593
2604.96	5.56208
2607.69	5.01509
2610.41	5.23036
2613.14	5.12752
2615.86	5.99715
2618.58	5.87031
2621.3	5.72896
2624.03	5.54981
2626.75	5.89096
2629.46	6.27346
2632.18	6.98972
2634.9	6.013
2637.61	6.80358
2640.33	6.83267
2643.04	6.81174
2645.76	7.31969
2648.47	7.13087
2651.18	7.24395
2653.89	6.36056
2656.6	6.08815
2659.31	5.75587
2662.01	5.05139
2664.72	4.9045
2667.43	4.86008
2670.13	3.41092
2672.83	2.80432
2675.53	1.92142
2678.24	1.37932
2680.94	1.83825
2683.64	2.01154
2686.34	2.13565
2689.03	1.59733
2691.73	2.18603
2694.43	2.05357
2697.12	2.67056
2699.81	3.19979
2702.51	3.75533
2705.2	4.15524
2707.89	4.36389
2710.58	5.02651
2713.27	5.63269
2715.96	5.72018
2718.64	6.68208
2721.33	7.75017
2724.01	8.21174
2726.7	8.04206
2729.38	7.61355
2732.06	7.81658
2734.75	6.94924
2737.43	6.86359
2740.11	7.13515
2742.78	6.13823
2745.46	6.74886
2748.14	5.93379
2750.81	5.70773
2753.49	5.44672
2756.16	4.97749
2758.84	4.66305
2761.51	4.63969
2764.18	4.12769
2766.85	4.40857
2769.52	3.62562
2772.19	2.77551
2774.85	2.58802
2777.52	3.09296
2780.18	3.32731
2782.85	2.31352
2785.51	1.36293
2788.17	0.862526
2790.84	0.606075
2793.5	-0.0314554
2796.16	0.157159
2798.81	-0.438828
2801.47	-0.879343
2804.13	0.211378
2806.79	-0.649828
2809.44	-1.48597
2812.09	-1.33969
2814.75	-1.78591
2817.4	-1.27551
2820.05	-0.289947
2822.7	0.747951
2825.35	2.65111
2828	4.80605
2830.65	7.4442
2833.29	9.59097
2835.94	11.6129
2838.58	13.6658
2841.23	17.2135
2843.87	21.0709
2846.51	24.2717
2849.15	27.7205
2851.79	31.9818
2854.43	37.0402
2857.07	40.7207
2859.71	43.8119
2862.34	47.2902
2864.98	49.6375
2867.61	52.1202
2870.25	53.7046
2872.88	55.3531
2875.51	57.0017
2878.14	58.7727
2880.77	60.0118
2883.4	62.7338
2886.03	65.2629
2888.65	67.8332
2891.28	71.5398
2893.91	73.9493
2896.53	76.5938
2899.15	80.1721
2901.78	84.4646
2904.4	89.9064
2907.02	96.5565
2909.64	103
2912.26	109.229
2914.87	115.598
2917.49	121.686
2920.11	126.467
2922.72	131.89
2925.34	136.809
2927.95	140.344
2930.56	142.924
2933.17	144.042
2935.78	145.197
2938.39	144.924
2941	142.427
2943.61	139.319
2946.22	135.832
2948.82	130.937
2951.43	125.437
2954.03	120.477
2956.64	115.386
2959.24	108.765
2961.84	103.4
2964.44	97.4431
2967.04	91.3802
2969.64	85.8686
2972.24	80.5847
2974.83	74.841
2977.43	68.969
2980.02	62.5398
2982.62	57.582
2985.21	52.7447
2987.8	48.5663
2990.4	43.2073
2992.99	38.3066
2995.57	33.93
2998.16	28.778
3000.75	25.0623
3003.34	20.1933
3005.92	16.4697
3008.51	13.0718
3011.09	9.89433
3013.68	8.41122
3016.26	6.48506
3018.84	5.04922
3021.42	4.40955
3024	2.4911
3026.58	1.76151
3029.16	0.575023
3031.73	0.568071
3034.31	0.797232
3036.89	0.374643
3039.46	0.418003
3042.03	-0.273893
3044.61	0.530998
3047.18	1.41962
3049.75	1.06399
3052.32	0.92868
3054.89	1.14551
3057.45	1.21896
3060.02	1.33969
3062.59	1.50347
3065.15	0.932399
3067.72	0.636319
3070.28	1.05244
3072.84	1.24829
3075.41	0.714855
3077.97	0.72012
3080.53	0.355828
3083.09	0.0349987
3085.64	-0.37131
3088.2	-0.910823
3090.76	-0.222291
3093.31	-0.309185
3095.87	-0.516912
3098.42	-0.962727
3100.97	-1.38713
3103.53	-1.02372
3106.08	-0.800933
3108.63	0.34696
3111.18	1.04001
3113.73	1.28671
3116.27	2.3047
3118.82	3.24531
3121.37	4.29571
3123.91	5.42595
3126.45	5.63144
3129	7.37596
3131.54	8.8534
3134.08	10.199
3136.62	11.3247
3139.16	12.0496
3141.7	13.584
3144.24	14.5056
3146.78	15.0898
3149.31	14.298