File: data/Raman/poly_smoothed/Mb_40_y_23_1x_45s_532 nm_x100_100%_600 gr_mm_01.txt
#Acq. time (s)=	45
#Accumulations=	2
#Range (cm-¹)=	200...3150
#Windows=	2
#Auto scanning=	Off
#Autofocus=	Off
#Macrospot=	Off
#AutoExposure=	Off
#Spike filter=	Multiple accum.
#Delay time (s)=	0
#Binning=	1
#Readout mode=	Signal
#DeNoise=	Off
#ICS correction=	On
#Dark correction=	Off
#Inst. Process=	Off
#Detector Gain=	Best Dynamic Range
#Detector ADC=	20 kHz
#Detector temperature (°C)=	-69.85
#Instrument=	LabRAM HR Evol
#Detector=	Synapse
#Objective=	x100
#Grating=	600 gr/mm
#ND Filter=	100%
#Laser (nm)=	532
#Hole=	100.021
#Range=	Auto
#Laser Pol.=	No
#Raman. Pol.=	No
#Laser Pol. (°)=	-0.0007625
#Raman Pol. (°)=	89.9995
#Collection=	Microscope
#StageXY=	Marzhauser
#StageZ=	Marzhauser
#X (µm)=	-1016.1
#Y (µm)=	639.3
#Z (µm)=	583.85
#Full time(mm:ss)=	3:19
#Project=
#Sample=
#Site=
#Title=	Mb_40_y_23_2x_45s_532 nm_x100_100%_600 gr_mm
#Remark=
#Date=	19.07.2022 10:53
#Acquired=	19.07.2022 10:53:29
#Base:Fit=	10.08.2022 10:52:48
#Base:Sub=	10.08.2022 10:52:53
#Filter:Polynom=	16.08.2022 10:09:04
#AxisType[0]=Intens
#AxisUnit[0]=Cnt
#AxisType[1]=Spectr
#AxisUnit[1]=1/cm
200.423	11.4552
204.052	15.8911
207.682	17.8001
211.308	18.7221
214.935	18.4077
218.558	16.3731
222.18	14.3473
225.802	12.901
229.421	11.3136
233.039	9.08471
236.657	10.2982
240.272	10.8042
243.885	10.7276
247.497	9.73773
251.11	8.82458
254.719	8.50189
258.327	5.75407
261.933	4.60848
265.538	5.04551
269.141	5.36196
272.744	5.2708
276.344	6.39754
279.944	7.45829
283.542	7.36101
287.138	7.94195
290.733	8.26611
294.327	7.41343
297.919	7.6745
301.508	7.09435
305.098	6.08798
308.686	5.936
312.273	5.81061
315.858	6.17878
319.44	5.54188
323.022	6.78915
326.604	7.24033
330.181	6.49337
333.76	5.45241
337.335	4.9228
340.91	4.4756
344.483	3.40693
348.055	2.62016
351.625	1.78853
355.195	3.04555
358.762	3.17028
362.329	2.39064
365.893	0.750173
369.455	0.479126
373.017	1.48621
376.578	2.22718
380.137	2.41745
383.694	3.14985
387.249	4.38738
390.806	4.49663
394.359	5.05892
397.91	5.22512
401.46	6.64137
405.009	7.52093
408.557	8.76297
412.103	9.73381
415.647	10.9531
419.191	11.7687
422.733	11.5158
426.273	12.6285
429.812	13.6733
433.35	12.9523
436.885	12.2182
440.42	11.353
443.954	11.3854
447.486	9.58353
451.015	8.01988
454.545	8.53306
458.073	7.75853
461.598	7.9006
465.124	8.65903
468.648	7.78673
472.169	8.27563
475.69	8.10921
479.208	9.79182
482.727	10.7077
486.243	12.6372
489.759	14.7873
493.272	16.4765
496.783	19.2108
500.295	19.9799
503.804	21.2676
507.311	21.749
510.819	23.0487
514.324	24.1708
517.827	25.3241
521.329	24.4299
524.83	23.7011
528.329	23.1274
531.829	22.5332
535.326	20.3716
538.821	17.8115
542.315	15.972
545.808	13.6067
549.299	12.8921
552.789	11.0743
556.278	8.63832
559.763	5.8897
563.249	4.86864
566.733	4.35234
570.217	4.54022
573.699	3.20072
577.177	2.14424
580.656	1.49535
584.134	0.24063
587.609	0.246561
591.084	1.21106
594.558	2.14589
598.029	3.45966
601.5	3.69165
604.968	5.11588
608.437	4.85493
611.902	7.85691
615.368	8.41857
618.831	8.05877
622.294	8.74952
625.755	9.23272
629.213	9.82199
632.673	10.1204
636.129	10.6303
639.584	10.4569
643.037	12.1273
646.491	13.2621
649.942	16.2574
653.392	17.1649
656.84	17.0107
660.287	18.3302
663.732	17.4922
667.177	18.8219
670.62	20.2282
674.061	22.3763
677.502	23.1345
680.941	23.5311
684.379	25.5371
687.815	29.231
691.248	31.2743
694.682	33.5755
698.115	35.2868
701.546	37.3496
704.974	37.939
708.402	39.9503
711.83	40.981
715.254	42.9719
718.679	46.7308
722.102	48.3073
725.522	50.8495
728.943	52.1673
732.361	52.9173
735.779	53.4647
739.194	54.3866
742.608	54.7663
746.022	55.4535
749.433	56.6226
752.843	59.55
756.254	60.4266
759.661	62.3529
763.067	63.1632
766.471	65.533
769.877	68.5133
773.279	70.892
776.68	71.9265
780.079	73.6642
783.478	75.0856
786.875	76.4676
790.27	77.316
793.665	78.7969
797.058	81.3796
800.45	82.2229
803.84	82.0427
807.23	80.0204
810.616	79.589
814.002	79.7263
817.388	79.1167
820.772	79.0987
824.153	77.7253
827.535	75.1823
830.915	73.9642
834.292	73.6959
837.67	72.8852
841.047	72.3058
844.42	69.5763
847.794	68.416
851.165	66.1447
854.534	64.8978
857.905	63.657
861.272	61.8051
864.639	60.8876
868.004	58.6335
871.367	57.2345
874.731	56.5286
878.092	54.6026
881.451	52.5193
884.809	51.5415
888.166	50.55
891.522	49.2942
894.878	48.0221
898.231	47.7718
901.583	46.0853
904.934	45.1099
908.283	44.0576
911.631	44.0423
914.976	44.3642
918.322	45.4492
921.666	44.5896
925.009	43.8942
928.351	43.369
931.692	44.5468
935.029	44.6502
938.367	45.6119
941.704	44.7644
945.038	43.9531
948.372	43.16
951.705	42.8736
955.035	42.2079
958.366	40.3818
961.693	39.2565
965.021	38.6172
968.346	37.9835
971.67	36.3104
974.995	36.582
978.316	35.0298
981.638	33.9331
984.957	33.2814
988.274	30.3588
991.59	29.981
994.907	27.3907
998.221	24.743
1001.53	19.5204
1004.85	16.0593
1008.16	19.7965
1011.46	28.2858
1014.77	44.1328
1018.08	61.5318
1021.38	78.8661
1024.69	94.5534
1027.99	110.346
1031.29	122.922
1034.59	133.242
1037.89	139.81
1041.19	145.01
1044.48	147.635
1047.78	148.834
1051.07	145.539
1054.36	140.436
1057.66	132.257
1060.94	120.444
1064.23	108.503
1067.52	94.6073
1070.81	78.0199
1074.09	58.4634
1077.38	39.3011
1080.66	23.2535
1083.94	10.8274
1087.22	5.58402
1090.5	6.03775
1093.77	11.2015
1097.05	14.6446
1100.32	17.1633
1103.6	18.8777
1106.87	19.3498
1110.14	19.9085
1113.41	20.4887
1116.67	20.9563
1119.94	21.3155
1123.21	21.1138
1126.47	21.1454
1129.73	21.4555
1133	20.344
1136.26	19.073
1139.52	19.1045
1142.77	18.4964
1146.03	18.0958
1149.29	14.5091
1152.54	11.9
1155.79	9.53825
1159.04	7.61956
1162.3	4.3788
1165.55	2.40545
1168.79	2.68888
1172.04	1.73164
1175.28	1.63329
1178.53	0.672326
1181.77	1.39665
1185.01	2.00105
1188.25	0.698936
1191.49	2.03309
1194.73	2.74124
1197.97	2.72556
1201.2	4.29487
1204.44	6.50521
1207.67	8.49427
1210.9	9.52396
1214.13	11.1183
1217.36	12.2589
1220.59	13.5989
1223.82	16.1163
1227.04	17.4387
1230.26	18.336
1233.49	20.2102
1236.71	22.2275
1239.93	25.5221
1243.15	27.369
1246.37	29.7465
1249.58	32.165
1252.8	32.9828
1256.01	34.0767
1259.23	36.9083
1262.44	37.9413
1265.65	39.5309
1268.86	40.7223
1272.07	41.859
1275.27	43.8936
1278.48	46.1502
1281.68	47.0536
1284.89	49.8637
1288.09	51.0601
1291.29	50.6826
1294.49	52.079
1297.69	52.214
1300.88	52.4134
1304.08	52.4863
1307.27	52.2388
1310.47	51.6829
1313.66	53.2242
1316.85	54.0554
1320.04	53.955
1323.23	52.8803
1326.41	53.7374
1329.6	52.7208
1332.78	50.7882
1335.97	51.248
1339.15	50.581
1342.33	49.0567
1345.51	49.3605
1348.69	47.8006
1351.87	46.6326
1355.04	45.4469
1358.22	44.1573
1361.39	43.3394
1364.57	42.6288
1367.74	38.1167
1370.91	35.6612
1374.07	34.2551
1377.24	32.1241
1380.41	30.5449
1383.57	28.3821
1386.74	28.1272
1389.9	28.3952
1393.06	28.4603
1396.22	27.5895
1399.38	28.7822
1402.54	29.7355
1405.7	32.3672
1408.85	33.8189
1412.01	36.9877
1415.16	40.0785
1418.31	44.4466
1421.46	48.8599
1424.61	54.4361
1427.76	57.9643
1430.91	64.045
1434.05	69.3966
1437.2	73.5211
1440.34	76.2669
1443.49	77.5421
1446.63	80.6594
1449.77	81.4946
1452.91	80.5718
1456.04	80.4963
1459.18	78.9584
1462.31	79.7359
1465.45	78.3465
1468.58	75.7602
1471.71	73.0269
1474.84	70.5391
1477.97	67.3037
1481.1	62.8297
1484.23	60.6734
1487.35	57.1317
1490.48	53.1855
1493.6	49.6808
1496.72	45.5526
1499.84	41.4912
1502.96	37.1293
1506.08	34.6677
1509.2	30.9825
1512.31	26.6651
1515.43	22.0971
1518.54	20.9143
1521.66	18.3729
1524.77	16.1708
1527.88	13.8984
1530.99	13.5123
1534.09	13.1904
1537.2	14.0746
1540.31	14.0644
1543.41	14.819
1546.51	16.6828
1549.62	17.2963
1552.72	19.4523
1555.82	20.7565
1558.91	22.7901
1562.01	24.5863
1565.11	24.6711
1568.2	25.6598
1571.3	26.0987
1574.39	27.656
1577.48	29.7748
1580.57	32.4667
1583.66	33.9674
1586.75	35.0439
1589.83	36.5657
1592.92	37.3827
1596	39.7989
1599.09	40.0518
1602.17	40.7476
1605.25	40.5126
1608.33	41.0975
1611.41	40.5664
1614.48	40.6811
1617.56	40.8756
1620.64	41.8992
1623.71	42.9144
1626.78	43.8987
1629.86	44.6833
1632.92	46.6205
1635.99	47.6287
1639.06	50.5069
1642.13	53.1047
1645.19	54.411
1648.26	56.0598
1651.32	57.6466
1654.38	58.1539
1657.45	57.6685
1660.51	56.1375
1663.57	55.0323
1666.62	52.7747
1669.68	51.6433
1672.73	48.7271
1675.79	46.0992
1678.84	42.229
1681.89	38.3238
1684.94	34.5821
1687.99	29.9365
1691.04	26.2558
1694.09	23.9124
1697.14	18.7262
1700.18	14.4711
1703.22	13.9706
1706.27	13.418
1709.31	13.8722
1712.35	12.5124
1715.39	13.1046
1718.43	11.7623
1721.46	10.7084
1724.5	9.27841
1727.53	9.90039
1730.57	10.4384
1733.6	9.71585
1736.63	9.22331
1739.66	8.85649
1742.69	8.5757
1745.72	9.44678
1748.74	8.47947
1751.77	8.5897
1754.8	6.90395
1757.82	6.37768
1760.84	4.44004
1763.86	3.58709
1766.88	1.60337
1769.9	0.157923
1772.92	-1.73588
1775.93	1.03939
1778.95	2.33801
1781.96	2.05821
1784.98	1.85372
1787.99	1.56867
1791	1.21863
1794.01	0.648236
1797.02	0.314732
1800.03	0.234753
1803.03	0.502734
1806.04	1.03232
1809.04	0.507363
1812.04	0.240928
1815.05	0.29795
1818.05	1.28404
1821.05	1.26344
1824.05	0.899256
1827.04	0.490684
1830.04	0.71907
1833.03	1.29929
1836.03	2.44186
1839.02	3.41507
1842.01	3.17285
1845	3.64036
1847.99	4.4902
1850.98	4.34975
1853.97	5.10304
1856.95	5.49234
1859.94	5.47071
1862.92	6.38842
1865.91	5.34
1868.89	4.60405
1871.87	4.98942
1874.85	5.32864
1877.83	4.88381
1880.8	4.28825
1882.56	4.64635
1885.54	4.96208
1888.53	5.09117
1891.52	5.04125
1894.5	4.92292
1897.49	4.57433
1900.47	5.06745
1903.45	5.80221
1906.43	5.81568
1909.41	6.8238
1912.39	6.16492
1915.37	5.96382
1918.35	6.43043
1921.32	7.26888
1924.3	7.22809
1927.27	8.09211
1930.24	8.03966
1933.21	9.58598
1936.18	9.82811
1939.15	9.00222
1942.12	9.14921
1945.09	8.43424
1948.05	7.03767
1951.02	7.95092
1953.98	7.13439
1956.94	7.43915
1959.91	7.67586
1962.87	7.24586
1965.82	6.41852
1968.78	7.15526
1971.74	6.61699
1974.7	6.23455
1977.65	6.08066
1980.6	5.82241
1983.56	6.74753
1986.51	6.88953
1989.46	7.81033
1992.41	7.77314
1995.36	8.03841
1998.3	7.71364
2001.25	8.56788
2004.2	10.2099
2007.14	10.3599
2010.08	10.0873
2013.02	10.6664
2015.97	10.1888
2018.9	10.2984
2021.84	10.6403
2024.78	11.2655
2027.72	10.9133
2030.65	11.1797
2033.59	10.8522
2036.52	12.3529
2039.45	13.4907
2042.38	14.1392
2045.31	13.7468
2048.24	14.1187
2051.17	15.5852
2054.1	16.3549
2057.02	16.7417
2059.95	16.9908
2062.87	17.7546
2065.79	18.9416
2068.71	19.44
2071.63	20.6753
2074.55	22.366
2077.47	24.4616
2080.39	25.0532
2083.3	27.1126
2086.22	28.1838
2089.13	30.69
2092.05	32.689
2094.96	35.3086
2097.87	37.094
2100.78	38.9011
2103.69	41.1087
2106.59	44.4431
2109.5	47.233
2112.41	48.132
2115.31	50.2736
2118.21	53.1718
2121.12	55.0404
2124.02	56.8446
2126.92	59.7349
2129.82	61.3626
2132.71	64.2286
2135.61	67.2711
2138.51	69.6959
2141.4	72.5347
2144.29	76.239
2147.19	78.2701
2150.08	81.5423
2152.97	85.1759
2155.86	88.8914
2158.75	92.7065
2161.64	94.7419
2164.52	97.7642
2167.41	99.99
2170.29	100.591
2173.17	101.398
2176.06	102.206
2178.94	101.873
2181.82	99.9814
2184.7	98.3674
2187.57	96.5013
2190.45	93.2105
2193.33	89.0051
2196.2	86.122
2199.08	82.3599
2201.95	79.1357
2204.82	77.9271
2207.69	74.2773
2210.56	70.1428
2213.43	67.2585
2216.3	63.8126
2219.16	60.4934
2222.03	57.4938
2224.89	54.4671
2227.75	51.4404
2230.62	48.8773
2233.48	46.0902
2236.34	44.1242
2239.2	40.8605
2242.06	38.8412
2244.91	36.9767
2247.77	34.198
2250.62	32.6775
2253.48	29.7958
2256.33	28.1613
2259.18	26.631
2262.03	24.3068
2264.88	23.5492
2267.73	22.9136
2270.58	23.0139
2273.43	24.2382
2276.27	23.1927
2279.12	21.4228
2281.96	21.3808
2284.8	21.0432
2287.64	19.8674
2290.49	17.8671
2293.32	15.4629
2296.16	13.8321
2299	13.0363
2301.84	13.1189
2304.67	12.8406
2307.51	12.994
2310.34	13.2599
2313.17	13.0352
2316	12.2495
2318.83	12.327
2321.66	10.9929
2324.49	10.0991
2327.32	9.9444
2330.15	8.94085
2332.97	8.05164
2335.79	7.42431
2338.62	7.56392
2341.44	7.99919
2344.26	7.56147
2347.08	5.08202
2349.9	4.09044
2352.72	3.89058
2355.53	3.05284
2358.35	1.93515
2361.17	0.969422
2363.98	0.946067
2366.79	2.47953
2369.6	3.98795
2372.42	5.08259
2375.22	6.52307
2378.03	6.97875
2380.84	6.77917
2383.65	6.03607
2386.45	6.58188
2389.26	6.80417
2392.06	7.13404
2394.87	7.22701
2397.67	7.29413
2400.47	7.23899
2403.27	7.05096
2406.07	7.51872
2408.86	7.18321
2411.66	6.91827
2414.46	6.87523
2417.25	6.33835
2420.05	6.36483
2422.84	6.90933
2425.63	7.03755
2428.42	7.97065
2431.21	8.5741
2434	8.30776
2436.79	8.14684
2439.57	8.1571
2442.36	7.48352
2445.14	5.92205
2447.93	4.3049
2450.71	3.65148
2453.49	3.1951
2456.27	2.96885
2459.05	3.04983
2461.83	3.1129
2464.61	2.70743
2467.39	3.00131
2470.16	2.35865
2472.94	2.92114
2475.71	2.85873
2478.48	2.90141
2481.25	2.57408
2484.02	3.39907
2486.8	2.41562
2489.56	3.51125
2492.33	4.18109
2495.1	4.41688
2497.86	4.83857
2500.63	4.49634
2503.39	2.85662
2506.16	2.36909
2508.92	1.74609
2511.68	0.839191
2514.44	0.284667
2517.2	0.295359
2519.95	0.396811
2522.71	0.504238
2525.47	0.929598
2528.22	1.24762
2530.98	2.11465
2533.73	1.97543
2536.48	2.18304
2539.23	1.93809
2541.98	2.42178
2544.73	2.68304
2547.48	2.63448
2550.23	4.00268
2552.97	4.03861
2555.72	4.18382
2558.46	4.69366
2561.2	4.87574
2563.95	5.04493
2566.69	5.21695
2569.43	5.66033
2572.17	5.23404
2574.91	5.00635
2577.64	3.90182
2580.38	3.89119
2583.11	3.30611
2585.85	3.07111
2588.58	3.52808
2591.31	2.7782
2594.04	2.99042
2596.78	3.1224
2599.51	2.86362
2602.23	2.35423
2604.96	1.87948
2607.69	1.43802
2610.41	2.47709
2613.14	1.58011
2615.86	2.2054
2618.58	2.3467
2621.3	2.55572
2624.03	3.39889
2626.75	4.83703
2629.46	5.6063
2632.18	6.20566
2634.9	6.18804
2637.61	6.73489
2640.33	6.66142
2643.04	6.61996
2645.76	6.10793
2648.47	6.09233
2651.18	6.15076
2653.89	5.40136
2656.6	5.1128
2659.31	4.98796
2662.01	5.05177
2664.72	4.34667
2667.43	3.1422
2670.13	2.66279
2672.83	2.51849
2675.53	2.33597
2678.24	2.45275
2680.94	1.97202
2683.64	2.63589
2686.34	2.55611
2689.03	2.58182
2691.73	3.72929
2694.43	3.7835
2697.12	4.02606
2699.81	4.45191
2702.51	4.76578
2705.2	6.28499
2707.89	6.19425
2710.58	6.83754
2713.27	7.18376
2715.96	8.15993
2718.64	8.12197
2721.33	8.40272
2724.01	8.90281
2726.7	8.94658
2729.38	9.09845
2732.06	9.537
2734.75	9.76417
2737.43	9.63556
2740.11	9.28754
2742.78	8.58579
2745.46	7.88409
2748.14	7.41413
2750.81	6.7464
2753.49	6.12045
2756.16	4.88906
2758.84	4.14435
2761.51	2.63633
2764.18	2.38488
2766.85	1.43091
2769.52	2.12465
2772.19	2.1602
2774.85	1.52626
2777.52	2.31903
2780.18	3.34001
2782.85	3.57506
2785.51	3.34407
2788.17	3.5561
2790.84	4.45422
2793.5	5.57706
2796.16	5.81605
2798.81	6.83953
2801.47	6.18096
2804.13	6.4154
2806.79	6.97812
2809.44	6.63703
2812.09	6.33949
2814.75	6.82258
2817.4	7.36756
2820.05	9.10235
2822.7	11.1142
2825.35	15.2172
2828	19.4526
2830.65	24.4621
2833.29	30.2139
2835.94	36.9087
2838.58	43.6546
2841.23	51.324
2843.87	58.0415
2846.51	64.2904
2849.15	71.6167
2851.79	79.4024
2854.43	87.2685
2857.07	95.2051
2859.71	102.069
2862.34	108.45
2864.98	114.162
2867.61	118.277
2870.25	122.133
2872.88	125.343
2875.51	129.075
2878.14	132.507
2880.77	136.185
2883.4	140.805
2886.03	145.052
2888.65	149.018
2891.28	153.673
2893.91	158.216
2896.53	163.686
2899.15	168.859
2901.78	174.335
2904.4	179.731
2907.02	186.104
2909.64	192.28
2912.26	201.83
2914.87	208.905
2917.49	217.494
2920.11	224.582
2922.72	230.622
2925.34	235.643
2927.95	239.15
2930.56	241.531
2933.17	242.743
2935.78	241.814
2938.39	240.288
2941	237.391
2943.61	233.101
2946.22	227.442
2948.82	220.561
2951.43	212.142
2954.03	203.593
2956.64	194.815
2959.24	184.507
2961.84	173.833
2964.44	162.875
2967.04	152.08
2969.64	142.136
2972.24	133.634
2974.83	124.111
2977.43	115.857
2980.02	106.155
2982.62	97.8202
2985.21	89.2994
2987.8	80.8493
2990.4	73.4464
2992.99	65.4574
2995.57	59.0759
2998.16	52.8813
3000.75	46.3962
3003.34	42.1029
3005.92	37.5102
3008.51	33.0507
3011.09	29.2808
3013.68	26.5141
3016.26	23.2094
3018.84	19.4944
3021.42	17.3944
3024	14.1518
3026.58	12.2708
3029.16	9.6994
3031.73	8.01972
3034.31	7.02278
3036.89	6.39054
3039.46	5.96578
3042.03	6.12031
3044.61	5.56288
3047.18	6.2121
3049.75	5.77627
3052.32	5.38184
3054.89	5.51371
3057.45	5.24454
3060.02	5.68349
3062.59	5.19997
3065.15	4.52797
3067.72	5.15592
3070.28	5.0908
3072.84	4.99989
3075.41	4.85097
3077.97	3.71364
3080.53	2.78789
3083.09	2.22427
3085.64	1.32556
3088.2	0.316902
3090.76	-0.454147
3093.31	-0.264289
3095.87	0.118395
3098.42	0.46129
3100.97	0.699073
3103.53	1.45112
3106.08	2.47595
3108.63	2.21556
3111.18	2.95995
3113.73	2.88058
3116.27	3.02659
3118.82	3.38837
3121.37	3.97247
3123.91	4.70545
3126.45	5.16451
3129	6.15736
3131.54	6.59968
3134.08	7.11232
3136.62	7.46646
3139.16	8.02739
3141.7	8.25449
3144.24	8.63484
3146.78	9.79632
3149.31	10.4635