File: data/Raman/poly_smoothed/Mb_40_24_39_1x_45s_532 nm_x100_100%_600 gr_mm_02.txt
#Acq. time (s)=	45
#Accumulations=	2
#Range (cm-¹)=	200...3150
#Windows=	2
#Auto scanning=	Off
#Autofocus=	Off
#Macrospot=	Off
#AutoExposure=	Off
#Spike filter=	Multiple accum.
#Delay time (s)=	0
#Binning=	1
#Readout mode=	Signal
#DeNoise=	Off
#ICS correction=	On
#Dark correction=	Off
#Inst. Process=	Off
#Detector Gain=	Best Dynamic Range
#Detector ADC=	20 kHz
#Detector temperature (°C)=	-70.08
#Instrument=	LabRAM HR Evol
#Detector=	Synapse
#Objective=	x100
#Grating=	600 gr/mm
#ND Filter=	100%
#Laser (nm)=	532
#Hole=	100.021
#Range=	Auto
#Laser Pol.=	No
#Raman. Pol.=	No
#Laser Pol. (°)=	-0.0007625
#Raman Pol. (°)=	89.9995
#Collection=	Microscope
#StageXY=	Marzhauser
#StageZ=	Marzhauser
#X (µm)=	-2507.1
#Y (µm)=	-53.1
#Z (µm)=	-10.8
#Full time(mm:ss)=	3:09
#Project=
#Sample=
#Site=
#Title=	Mb_40_24_39_2x_45s_532 nm_x100_100%_600 gr_mm
#Remark=
#Date=	14.07.2022 13:47
#Acquired=	14.07.2022 13:47:25
#Edit:Spike=	14.07.2022 13:48:32
#Base:Fit=	10.08.2022 10:47:00
#Base:Sub=	10.08.2022 10:47:12
#Filter:Polynom=	16.08.2022 10:11:48
#AxisType[0]=Intens
#AxisUnit[0]=Cnt
#AxisType[1]=Spectr
#AxisUnit[1]=1/cm
200.554	112.381
204.183	90.9547
207.813	71.029
211.439	54.9861
215.065	42.0833
218.688	31.0494
222.312	25.3234
225.933	18.1287
229.552	14.1844
233.171	12.2811
236.787	12.5404
240.402	12.3723
244.015	12.8006
247.627	16.0291
251.24	17.6799
254.849	22.148
258.457	27.8188
262.063	32.9948
265.668	35.4325
269.271	39.9008
272.873	43.0079
276.474	44.0566
280.073	47.186
283.671	51.5634
287.268	55.4218
290.863	59.9906
294.456	63.2063
298.049	69.72
301.637	77.4233
305.227	83.5618
308.815	93.5045
312.402	98.5129
315.987	103.589
319.569	107.653
323.151	109.258
326.733	109.823
330.31	105.203
333.889	99.8926
337.464	96.145
341.039	89.9777
344.611	82.8529
348.184	76.8799
351.754	66.1694
355.324	57.2125
358.89	48.5028
362.455	38.5605
366.021	29.7189
369.584	24.2395
373.145	17.0137
376.707	11.4272
380.265	6.41669
383.822	6.45651
387.378	11.7048
390.934	14.1111
394.487	15.899
398.038	17.9896
401.588	18.8472
405.137	20.5626
408.685	19.7722
412.23	21.7497
415.775	20.8904
419.318	20.3135
422.86	22.8531
426.401	22.4827
429.94	20.421
433.478	19.4463
437.012	16.5788
440.547	14.3684
444.081	13.9456
447.613	11.4749
451.142	11.1488
454.672	12.8146
458.2	9.74333
461.725	8.39789
465.251	10.2014
468.775	12.9675
472.296	15.1151
475.817	15.5523
479.335	15.3991
482.854	16.812
486.37	20.5101
489.886	23.9131
493.398	24.3195
496.91	26.7975
500.422	26.8108
503.93	28.7913
507.438	30.1829
510.946	28.8587
514.45	26.5794
517.954	25.2392
521.456	23.6118
524.956	22.9491
528.456	24.3582
531.956	24.6452
535.452	23.8068
538.947	24.1934
542.441	23.0592
545.934	21.712
549.425	21.0418
552.915	21.0346
556.403	18.6665
559.889	15.9171
563.375	15.2388
566.859	16.4695
570.342	15.2296
573.824	12.6893
577.303	10.9289
580.782	9.46066
584.26	9.26557
587.734	8.14383
591.21	5.69195
594.684	5.14079
598.154	3.46362
601.626	5.67889
605.094	8.64756
608.562	10.3983
612.027	12.7695
615.493	12.0334
618.956	12.7599
622.419	13.0613
625.879	15.5222
629.338	16.0515
632.797	16.119
636.254	16.7708
639.708	19.0655
643.162	19.3125
646.614	17.2578
650.067	18.2297
653.516	15.426
656.964	12.2336
660.411	11.0787
663.857	10.2081
667.301	8.76062
670.744	9.61919
674.186	12.1988
677.626	16.9527
681.065	22.4786
684.503	25.5423
687.939	28.3453
691.372	28.5236
694.806	23.4455
698.239	21.8672
701.67	18.2262
705.098	22.2296
708.526	29.3304
711.954	39.5265
715.378	45.6113
718.802	50.7521
722.226	54.7314
725.646	57.4944
729.067	60.0552
732.484	62.6258
735.902	62.97
739.317	62.1722
742.731	64.3402
746.145	66.6518
749.556	70.2696
752.966	74.9406
756.377	78.4754
759.784	81.77
763.19	82.5652
766.594	81.9461
770	78.637
773.402	73.1961
776.803	68.5226
780.202	67.2987
783.6	70.0081
786.997	75.3172
790.393	85.3889
793.787	89.3601
797.18	89.5589
800.572	91.1548
803.963	91.2976
807.35	90.8434
810.738	90.5546
814.125	87.7058
817.51	85.3698
820.894	84.3486
824.275	83.6959
827.657	84.7828
831.037	83.2135
834.414	83.246
837.792	82.1428
841.167	81.7096
844.542	80.7816
847.914	79.6206
851.287	77.4313
854.656	75.5215
858.026	75.1087
861.393	74.0465
864.761	74.9426
868.125	73.5523
871.489	72.5003
874.85	70.8395
878.213	69.1095
881.572	69.8987
884.931	69.2928
888.287	69.1572
891.643	68.2661
894.997	66.042
898.352	65.1947
901.704	66.1061
905.055	66.6982
908.404	67.1431
911.75	65.3934
915.097	63.9985
918.443	63.2069
921.787	61.7102
925.13	58.7771
928.472	55.8393
931.813	51.9186
935.15	47.6715
938.488	41.6954
941.825	36.3151
945.158	33.0814
948.493	29.1077
951.824	25.8269
955.156	26.0465
958.486	26.5092
961.814	29.9495
965.142	37.0458
968.467	44.7549
971.79	52.4146
975.115	59.0262
978.436	64.6055
981.756	66.4161
985.077	70.2858
988.394	72.8945
991.71	72.9332
995.025	73.1337
998.341	69.4634
1001.65	66.2128
1004.97	63.0725
1008.28	61.1386
1011.58	60.4963
1014.89	61.6518
1018.2	59.3704
1021.5	60.1946
1024.81	63.5181
1028.11	62.9602
1031.41	64.4665
1034.71	67.8655
1038.01	70.7551
1041.31	74.3574
1044.6	80.7363
1047.9	82.0312
1051.19	85.0647
1054.48	85.5698
1057.77	81.4507
1061.06	80.8216
1064.35	77.7214
1067.64	74.7247
1070.93	69.5446
1074.21	64.7178
1077.49	59.8135
1080.78	54.0565
1084.06	51.361
1087.34	49.8856
1090.61	49.9091
1093.89	49.9209
1097.17	52.16
1100.44	53.4008
1103.71	52.5522
1106.99	50.3631
1110.26	48.6646
1113.52	47.8158
1116.79	41.2403
1120.06	38.4834
1123.32	35.7498
1126.59	34.8832
1129.85	35.5345
1133.11	33.1871
1136.37	32.3853
1139.63	32.2785
1142.89	32.8541
1146.15	31.0709
1149.4	29.6404
1152.66	25.4614
1155.91	23.484
1159.16	19.0399
1162.41	15.3887
1165.66	12.91
1168.91	11.7719
1172.16	12.7224
1175.4	14.8045
1178.65	17.2814
1181.89	19.4566
1185.13	21.777
1188.37	22.3835
1191.61	22.8062
1194.85	22.4148
1198.08	21.5473
1201.32	20.6102
1204.55	23.7247
1207.79	31.7759
1211.02	42.9128
1214.25	56.3775
1217.48	69.1683
1220.71	82.2395
1223.93	93.3995
1227.16	104.281
1230.38	113.283
1233.6	118.831
1236.83	123.4
1240.05	126.738
1243.26	130.239
1246.48	134.483
1249.7	138.956
1252.92	141.705
1256.13	142.698
1259.34	143.791
1262.55	141.396
1265.76	136.817
1268.97	132.808
1272.18	130.852
1275.39	126.889
1278.59	125.266
1281.8	126.177
1285	133.797
1288.2	140.553
1291.4	147.756
1294.6	149.77
1297.8	151.127
1301	154.236
1304.19	156.091
1307.39	157.215
1310.58	156.145
1313.77	152.366
1316.96	150.894
1320.15	151.519
1323.34	149.53
1326.53	145.882
1329.72	140.793
1332.9	136.485
1336.08	132.523
1339.27	130.136
1342.45	127.743
1345.63	127.989
1348.8	128.058
1351.98	130.167
1355.16	128.161
1358.33	130.312
1361.51	132.392
1364.68	133.394
1367.85	133.702
1371.02	132.986
1374.19	131.769
1377.36	134.629
1380.52	138.36
1383.69	142.053
1386.85	142.66
1390.02	142.551
1393.18	143.205
1396.34	142.794
1399.5	144.741
1402.65	147.07
1405.81	147.274
1408.97	151.367
1412.12	158.656
1415.27	168.834
1418.43	179.491
1421.58	192.75
1424.73	207.368
1427.87	221.702
1431.02	235.617
1434.17	249.552
1437.31	260.152
1440.46	269.046
1443.6	274.421
1446.74	277.219
1449.88	277.213
1453.02	273.319
1456.16	267.639
1459.29	256.365
1462.43	239.929
1465.56	223.519
1468.69	204.293
1471.83	185.081
1474.95	165.622
1478.08	147.827
1481.21	128.796
1484.34	113.078
1487.47	98.8616
1490.59	86.5737
1493.71	79.8027
1496.84	72.5922
1499.96	69.4417
1503.07	66.9293
1506.19	63.3361
1509.31	64.0721
1512.43	62.3959
1515.54	61.9656
1518.65	61.7423
1521.77	61.9845
1524.88	62.9711
1527.99	62.4677
1531.1	61.1182
1534.21	63.5586
1537.31	63.3554
1540.42	65.1717
1543.52	68.8824
1546.63	72.9676
1549.73	77.3741
1552.83	82.1617
1555.93	86.3709
1559.03	92.4764
1562.12	97.6715
1565.22	103.521
1568.31	111.808
1571.41	120.087
1574.5	125.05
1577.59	131.899
1580.68	139.137
1583.77	148.774
1586.86	159.72
1589.95	170.143
1593.03	178.521
1596.11	187.604
1599.2	193.285
1602.28	196.774
1605.36	198.573
1608.44	199.634
1611.52	198.312
1614.6	196.742
1617.67	192.639
1620.75	187.038
1623.82	182.074
1626.89	176.636
1629.96	170.277
1633.04	162.395
1636.11	155.218
1639.17	147.485
1642.24	141.278
1645.31	133.457
1648.37	127.051
1651.43	122.486
1654.5	120.248
1657.56	120.146
1660.62	119.622
1663.67	116.706
1666.73	113.886
1669.79	109.927
1672.84	106.176
1675.9	100.941
1678.95	94.9197
1682	87.8107
1685.05	81.0937
1688.1	77.3606
1691.15	70.76
1694.2	64.0458
1697.25	61.1159
1700.29	56.5906
1703.33	53.2449
1706.38	50.682
1709.42	48.0488
1712.46	47.1459
1715.5	45.9532
1718.54	45.483
1721.57	42.8291
1724.61	42.1826
1727.64	42.2742
1730.68	41.0563
1733.71	39.2817
1736.74	37.3375
1739.77	36.1692
1742.8	34.1322
1745.83	32.3186
1748.85	29.2484
1751.88	27.0838
1754.91	24.03
1757.93	21.3403
1760.95	19.0767
1763.97	17.0025
1766.99	13.2812
1770.01	11.27
1773.03	9.7757
1776.04	6.98739
1779.06	6.35637
1782.07	6.11868
1785.09	5.56087
1788.1	3.93221
1791.11	4.0624
1794.12	3.28319
1797.13	2.50168
1800.13	2.70021
1803.14	2.96792
1806.15	1.90191
1809.15	1.90882
1812.15	0.811835
1815.16	0.308775
1818.15	-0.636554
1821.16	-0.0563617
1824.15	-0.415848
1827.15	-0.683466
1830.15	-1.6433
1833.14	-1.87272
1836.14	-1.38949
1839.13	-1.28574
1842.12	-1.86804
1845.11	-2.50254
1848.1	-3.00389
1851.09	-1.92646
1854.08	-1.06217
1857.06	-0.642818
1860.05	-0.606218
1863.03	0.609641
1866.01	2.34971
1869	2.85609
1871.98	3.20905
1874.96	4.63308
1877.93	4.83684
1880.91	5.33774
1882.47	5.70637
1885.46	6.66099
1888.44	6.38829
1891.43	7.08833
1894.42	8.81673
1897.4	9.17667
1900.39	9.74835
1903.37	10.6869
1906.35	10.1085
1909.33	9.82153
1912.31	9.72309
1915.29	9.36815
1918.26	9.45364
1921.24	10.4775
1924.21	11.8259
1927.19	9.97237
1930.16	9.75266
1933.13	10.3112
1936.1	10.9382
1939.07	9.63568
1942.04	8.57431
1945	9.04007
1947.97	7.65417
1950.93	6.62852
1953.9	6.11053
1956.86	5.2348
1959.82	4.82677
1962.78	4.50636
1965.74	4.07038
1968.7	3.57519
1971.65	4.49619
1974.61	4.47227
1977.57	4.37459
1980.52	3.36633
1983.47	3.50382
1986.42	2.88777
1989.37	2.39638
1992.32	3.25726
1995.27	3.51357
1998.22	3.43627
2001.17	2.73745
2004.11	5.03328
2007.05	4.16222
2010	3.66968
2012.94	3.14114
2015.88	3.76039
2018.82	3.91341
2021.76	4.54655
2024.7	5.45547
2027.63	7.16886
2030.57	6.81167
2033.5	8.28923
2036.44	9.35281
2039.37	9.74473
2042.3	9.85912
2045.23	9.64617
2048.16	8.59813
2051.08	7.30362
2054.01	6.54257
2056.94	6.38136
2059.86	6.63176
2062.79	6.79329
2065.71	6.5205
2068.63	5.80847
2071.55	5.80053
2074.47	6.92464
2077.39	6.46133
2080.31	7.39461
2083.22	10.1223
2086.13	12.9521
2089.05	14.6593
2091.96	14.9898
2094.87	16.5573
2097.78	17.8515
2100.69	17.6701
2103.6	17.8795
2106.51	20.8612
2109.42	21.2889
2112.32	19.9937
2115.23	21.7191
2118.13	22.5348
2121.03	23.9509
2123.93	23.9878
2126.83	25.1856
2129.73	26.9218
2132.63	28.6187
2135.53	29.8353
2138.42	30.7796
2141.32	32.9095
2144.21	35.2147
2147.1	37.0994
2150	39.2627
2152.89	41.5266
2155.78	43.1468
2158.66	45.3046
2161.55	45.7503
2164.44	46.2074
2167.32	47.5466
2170.21	48.4608
2173.09	47.8259
2175.97	48.736
2178.85	48.572
2181.73	47.5201
2184.61	45.7402
2187.49	45.4841
2190.37	43.8301
2193.24	42.2754
2196.12	41.8077
2198.99	40.1877
2201.87	40.5797
2204.74	40.1734
2207.61	38.8354
2210.48	37.7686
2213.35	37.1251
2216.21	37.3578
2219.08	36.5978
2221.95	35.6703
2224.81	35.4661
2227.67	34.2751
2230.54	32.6406
2233.4	30.6407
2236.26	29.3628
2239.11	28.2157
2241.97	27.487
2244.83	26.0249
2247.69	24.4141
2250.54	23.0983
2253.4	21.6716
2256.25	20.4322
2259.1	17.9891
2261.95	16.6333
2264.8	15.4149
2267.65	15.5064
2270.5	15.6075
2273.34	15.2892
2276.19	14.933
2279.03	14.481
2281.88	15.5916
2284.72	15.7336
2287.56	16.9528
2290.4	16.3512
2293.24	14.8695
2296.08	14.2786
2298.92	14.0752
2301.76	14.2984
2304.59	14.9877
2307.43	17.3347
2310.26	17.7243
2313.09	18.118
2315.92	16.6941
2318.75	17.6103
2321.58	15.8734
2324.41	12.4032
2327.24	10.2914
2330.06	8.9416
2332.89	6.48545
2335.71	5.39478
2338.54	4.66256
2341.36	3.12649
2344.18	2.48921
2347	1.4051
2349.82	1.40627
2352.64	0.747464
2355.45	0.457556
2358.27	-0.479761
2361.08	-0.292897
2363.9	1.14694
2366.71	2.85032
2369.52	3.25716
2372.33	5.23755
2375.14	6.22621
2377.95	6.2717
2380.76	6.42338
2383.57	5.72249
2386.37	5.39639
2389.18	5.43744
2391.98	4.59813
2394.79	3.52709
2397.59	3.73041
2400.39	3.76878
2403.19	3.90194
2405.99	4.00336
2408.78	5.21213
2411.58	5.87037
2414.38	6.77715
2417.17	7.88127
2419.97	8.6312
2422.76	9.38558
2425.55	10.1855
2428.34	12.543
2431.13	13.9549
2433.92	14.9277
2436.71	15.1886
2439.49	16.1611
2442.28	15.1199
2445.06	14.5918
2447.85	14.2192
2450.63	12.6515
2453.41	11.6718
2456.19	10.6596
2458.97	9.91727
2461.75	7.60419
2464.53	7.58097
2467.31	7.19162
2470.08	6.73495
2472.86	5.03191
2475.63	5.41092
2478.4	3.86896
2481.17	3.02289
2483.94	2.54689
2486.72	3.84775
2489.48	3.62192
2492.25	3.23105
2495.02	4.34514
2497.79	4.17694
2500.55	4.40196
2503.31	5.17559
2506.08	5.91687
2508.84	7.03198
2511.6	6.06856
2514.36	5.96369
2517.12	5.14838
2519.88	6.04658
2522.63	6.54773
2525.39	6.56875
2528.14	7.57943
2530.9	8.08865
2533.65	9.5591
2536.4	8.62632
2539.15	7.77393
2541.9	7.9125
2544.65	7.27276
2547.4	7.70007
2550.15	9.50342
2552.89	9.5747
2555.64	10.3641
2558.38	9.4799
2561.12	10.226
2563.87	9.2552
2566.61	10.7914
2569.35	10.6835
2572.09	11.4297
2574.83	12.5338
2577.56	13.0926
2580.3	12.2446
2583.04	12.294
2585.77	13.2439
2588.5	12.8078
2591.23	11.3491
2593.97	12.0415
2596.7	12.4862
2599.43	11.7792
2602.15	11.0656
2604.88	10.3703
2607.61	10.3261
2610.33	9.95793
2613.06	9.96226
2615.78	9.34973
2618.51	8.94199
2621.23	8.44477
2623.95	7.47506
2626.67	7.81456
2629.39	8.44193
2632.1	8.36869
2634.82	7.41125
2637.54	5.86504
2640.25	6.2632
2642.97	5.24309
2645.68	4.58601
2648.39	3.4057
2651.1	2.62324
2653.81	3.05031
2656.52	1.88718
2659.23	1.5391
2661.94	1.16454
2664.64	0.875565
2667.35	1.74145
2670.05	1.15961
2672.76	1.43742
2675.46	1.41671
2678.16	1.43567
2680.86	2.53129
2683.56	3.01431
2686.26	5.21393
2688.96	6.47151
2691.65	6.95202
2694.35	8.97256
2697.04	9.48679
2699.74	10.1492
2702.43	11.4639
2705.12	14.4207
2707.81	15.9518
2710.5	18.891
2713.19	20.3169
2715.88	21.736
2718.57	22.3303
2721.25	23.5664
2723.94	24.5352
2726.62	24.5341
2729.3	24.948
2731.99	24.6778
2734.67	24.5439
2737.35	22.1499
2740.03	20.2161
2742.71	18.628
2745.38	17.2993
2748.06	14.8231
2750.74	11.6456
2753.41	9.19707
2756.09	6.5037
2758.76	4.67883
2761.43	3.54636
2764.1	2.81661
2766.77	1.62409
2769.44	1.32001
2772.11	0.757562
2774.77	-0.501154
2777.44	-1.35958
2780.11	-1.62186
2782.77	-1.09127
2785.43	-0.138551
2788.1	0.840982
2790.76	-0.0474429
2793.42	0.830562
2796.08	1.34551
2798.74	2.58133
2801.4	3.53952
2804.05	3.77373
2806.71	4.59381
2809.36	4.85314
2812.02	4.72121
2814.67	4.7913
2817.32	8.20639
2819.97	14.1494
2822.62	21.4118
2825.27	31.9763
2827.92	46.0454
2830.57	61.9451
2833.22	81.7616
2835.86	104.965
2838.51	128.878
2841.15	155.385
2843.79	182.161
2846.43	210.528
2849.08	238.078
2851.72	265.298
2854.36	293.916
2856.99	320.213
2859.63	346.448
2862.27	368.265
2864.9	388.373
2867.54	404.534
2870.17	421.511
2872.8	434.302
2875.43	444.505
2878.07	455.383
2880.7	467.338
2883.32	477.444
2885.95	490.699
2888.58	502.746
2891.21	516.648
2893.83	530.617
2896.46	547.541
2899.08	567.501
2901.7	585.777
2904.32	604.853
2906.94	624.414
2909.56	644.394
2912.18	664.474
2914.8	681.631
2917.42	697.571
2920.03	709.503
2922.65	716.08
2925.26	716.58
2927.88	710.846
2930.49	702.289
2933.1	689.69
2935.71	671.501
2938.32	649.102
2940.93	626.769
2943.54	602.062
2946.14	574.318
2948.75	545.338
2951.35	516.827
2953.96	486.304
2956.56	457.66
2959.16	431.348
2961.77	406.625
2964.37	382.905
2966.96	359.697
2969.56	339.035
2972.16	320.73
2974.76	301.977
2977.35	283.258
2979.95	263.518
2982.54	244.143
2985.14	225.548
2987.73	203.917
2990.32	182.172
2992.91	161.271
2995.5	141.978
2998.09	125.088
3000.68	107.233
3003.26	93.6082
3005.85	80.6494
3008.43	67.9715
3011.02	56.6837
3013.6	46.4297
3016.19	38.6405
3018.77	30.3323
3021.35	25.1757
3023.93	22.6818
3026.5	19.9812
3029.08	19.6239
3031.66	19.6678
3034.24	21.0695
3036.81	23.5768
3039.39	25.344
3041.96	27.6317
3044.53	31.508
3047.1	34.4267
3049.67	36.7246
3052.24	38.976
3054.81	39.323
3057.38	39.8023
3059.95	40.0495
3062.52	40.2422
3065.08	38.546
3067.65	36.615
3070.21	31.9053
3072.77	27.4145
3075.33	22.5447
3077.89	19.1211
3080.45	15.4657
3083.01	11.8415
3085.57	9.95405
3088.13	8.21034
3090.68	8.35561
3093.24	7.10118
3095.79	6.71943
3098.35	6.97336
3100.9	8.53248
3103.45	9.40094
3106	10.6954
3108.55	12.7214
3111.1	13.8967
3113.65	16.2212
3116.2	18.0666
3118.75	21.0139
3121.29	24.9033
3123.84	28.8432
3126.38	32.517
3128.92	34.8937
3131.47	37.0168
3134.01	40.9181
3136.55	45.4123
3139.09	50.3328
3141.63	55.9099
3144.17	61.7292
3146.7	68.2201
3149.24	75.5029