File: data/Raman/poly_smoothed/Mb_40_y_44_1x_45s_532 nm_x100_100%_600 gr_mm_01.txt
#Acq. time (s)=	45
#Accumulations=	2
#Range (cm-¹)=	200...3150
#Windows=	2
#Auto scanning=	Off
#Autofocus=	Off
#Macrospot=	Off
#AutoExposure=	Off
#Spike filter=	Multiple accum.
#Delay time (s)=	0
#Binning=	1
#Readout mode=	Signal
#DeNoise=	Off
#ICS correction=	On
#Dark correction=	Off
#Inst. Process=	Off
#Detector Gain=	Best Dynamic Range
#Detector ADC=	20 kHz
#Detector temperature (°C)=	-69.85
#Instrument=	LabRAM HR Evol
#Detector=	Synapse
#Objective=	x100
#Grating=	600 gr/mm
#ND Filter=	100%
#Laser (nm)=	532
#Hole=	100.021
#Range=	Auto
#Laser Pol.=	No
#Raman. Pol.=	No
#Laser Pol. (°)=	-0.0007625
#Raman Pol. (°)=	89.9995
#Collection=	Microscope
#StageXY=	Marzhauser
#StageZ=	Marzhauser
#X (µm)=	-1152.4
#Y (µm)=	674.7
#Z (µm)=	584.9
#Full time(mm:ss)=	3:18
#Project=
#Sample=
#Site=
#Title=	Mb_40_y_44_2x_45s_532 nm_x100_100%_600 gr_mm
#Remark=
#Date=	19.07.2022 13:10
#Acquired=	19.07.2022 13:10:04
#Base:Fit=	10.08.2022 10:52:48
#Base:Sub=	10.08.2022 10:52:53
#Filter:Polynom=	16.08.2022 10:09:04
#AxisType[0]=Intens
#AxisUnit[0]=Cnt
#AxisType[1]=Spectr
#AxisUnit[1]=1/cm
200.423	29.826
204.052	23.6914
207.682	19.0146
211.308	13.8882
214.935	10.7808
218.558	9.9041
222.18	8.10751
225.802	6.34676
229.421	7.24524
233.039	5.72242
236.657	4.56909
240.272	4.60761
243.885	2.23034
247.497	1.68897
251.11	2.42939
254.719	3.65366
258.327	4.72585
261.933	5.71117
265.538	6.47736
269.141	7.75399
272.744	6.9884
276.344	8.00889
279.944	10.2971
283.542	10.7204
287.138	10.1572
290.733	12.8485
294.327	13.2925
297.919	15.6274
301.508	19.1904
305.098	22.5408
308.686	22.1572
312.273	24.41
315.858	26.7495
319.44	26.9102
323.022	25.3337
326.604	25.0069
330.181	24.5274
333.76	23.8928
337.335	24.5385
340.91	23.7711
344.483	23.8041
348.055	22.1365
351.625	20.9236
355.195	20.3451
358.762	20.0547
362.329	21.3028
365.893	20.7519
369.455	21.1504
373.017	21.0914
376.578	22.9252
380.137	23.8945
383.694	24.5765
387.249	26.7116
390.806	27.3777
394.359	27.1098
397.91	26.6321
401.46	27.0387
405.009	25.9431
408.557	24.8033
412.103	25.2771
415.647	24.6469
419.191	23.4547
422.733	21.9779
426.273	18.5837
429.812	17.022
433.35	14.8645
436.885	12.5679
440.42	11.2478
443.954	11.3235
447.486	11.0406
451.015	9.76107
454.545	8.87554
458.073	9.87032
461.598	11.4956
465.124	11.5267
468.648	12.9709
472.169	13.2376
475.69	16.9475
479.208	19.2864
482.727	20.3349
486.243	20.5922
489.759	23.0281
493.272	24.7512
496.783	25.4677
500.295	26.7542
503.804	26.9262
507.311	26.8135
510.819	27.8884
514.324	26.7349
517.827	25.8685
521.329	25.6606
524.83	26.0664
528.329	26.9325
531.829	26.7942
535.326	26.2728
538.821	25.0992
542.315	23.7967
545.808	22.9059
549.299	21.1489
552.789	18.5286
556.278	17.7823
559.763	17.28
563.249	18.1213
566.733	16.6515
570.217	14.7883
573.699	12.8733
577.177	10.8978
580.656	9.60118
584.134	9.32496
587.609	10.2256
591.084	9.70347
594.558	9.30604
598.029	8.05007
601.5	6.89649
604.968	6.51544
608.437	8.15797
611.902	7.81326
615.368	7.21509
618.831	6.64522
622.294	5.65506
625.755	4.06011
629.213	3.87311
632.673	3.74105
636.129	3.1226
639.584	2.90332
643.037	4.15721
646.491	4.32694
649.942	5.68251
653.392	5.1444
656.84	4.56728
660.287	3.51316
663.732	4.22437
667.177	4.68499
670.62	6.38713
674.061	9.0079
677.502	10.3347
680.941	12.3487
684.379	13.5429
687.815	16.1068
691.248	18.8227
694.682	19.8931
698.115	20.8666
701.546	24.9153
704.974	28.0229
708.402	29.9436
711.83	31.7622
715.254	33.9761
718.679	35.3451
722.102	38.3158
725.522	39.3517
728.943	41.9533
732.361	44.1494
735.779	44.4586
739.194	43.135
742.608	42.5606
746.022	44.007
749.433	46.8135
752.843	47.9205
756.254	51.2855
759.661	52.7102
763.067	53.3676
766.471	54.6497
769.877	55.1498
773.279	56.92
776.68	57.673
780.079	59.2344
783.478	61.5944
786.875	63.4749
790.27	63.1374
793.665	62.7655
797.058	61.9254
800.45	63.1762
803.84	63.4339
807.23	62.7287
810.616	62.1908
814.002	62.4909
817.388	60.3314
820.772	57.2851
824.153	56.3226
827.535	56.5676
830.915	54.7198
834.292	53.8631
837.67	53.3205
841.047	52.8665
844.42	51.7224
847.794	49.4038
851.165	49.3812
854.534	47.4934
857.905	45.9908
861.272	44.9505
864.639	42.5147
868.004	40.4467
871.367	38.0303
874.731	36.8452
878.092	35.9039
881.451	35.6496
884.809	36.0842
888.166	35.6725
891.522	37.1619
894.878	36.3213
898.231	34.7693
901.583	36.3123
904.934	35.2678
908.283	36.7191
911.631	36.4373
914.976	36.5522
918.322	37.7654
921.666	36.0437
925.009	36.0225
928.351	36.1169
931.692	36.201
935.029	36.7014
938.367	36.1622
941.704	34.903
945.038	32.6274
948.372	32.1609
951.705	31.5733
955.035	32.0925
958.366	30.3509
961.693	30.001
965.021	30.1647
968.346	31.1855
971.67	31.701
974.995	31.058
978.316	31.0683
981.638	31.6705
984.957	30.4211
988.274	28.1308
991.59	26.3695
994.907	21.8035
998.221	16.3718
1001.53	8.22187
1004.85	7.67209
1008.16	12.9986
1011.46	27.0665
1014.77	47.6131
1018.08	71.0113
1021.38	93.9104
1024.69	115.256
1027.99	136.556
1031.29	153.079
1034.59	165.92
1037.89	175.829
1041.19	182.52
1044.48	186.524
1047.78	186.112
1051.07	183.381
1054.36	177.588
1057.66	166.479
1060.94	152.757
1064.23	136.473
1067.52	115.443
1070.81	93.2265
1074.09	67.8374
1077.38	43.8644
1080.66	23.8513
1083.94	9.18618
1087.22	5.80203
1090.5	8.5602
1093.77	14.8654
1097.05	20.1771
1100.32	23.3225
1103.6	24.5903
1106.87	25.953
1110.14	26.5383
1113.41	25.4817
1116.67	25.0659
1119.94	24.4758
1123.21	22.1852
1126.47	21.0638
1129.73	20.817
1133	19.6011
1136.26	18.1763
1139.52	17.3404
1142.77	16.1299
1146.03	15.2221
1149.29	15.0137
1152.54	13.6979
1155.79	10.2562
1159.04	8.7181
1162.3	6.74282
1165.55	6.78353
1168.79	7.99428
1172.04	7.99315
1175.28	8.19613
1178.53	6.38789
1181.77	6.17188
1185.01	6.51608
1188.25	6.85827
1191.49	7.84594
1194.73	10.3687
1197.97	11.9241
1201.2	13.8588
1204.44	15.8598
1207.67	18.4037
1210.9	21.4281
1214.13	24.3875
1217.36	27.72
1220.59	33.1884
1223.82	36.275
1227.04	39.1978
1230.26	41.616
1233.49	42.2569
1236.71	44.8403
1239.93	46.7755
1243.15	48.9824
1246.37	50.8947
1249.58	53.3643
1252.8	55.0264
1256.01	57.6614
1259.23	59.7378
1262.44	61.9513
1265.65	63.3516
1268.86	65.6372
1272.07	67.749
1275.27	68.4391
1278.48	70.1039
1281.68	72.5937
1284.89	75.2894
1288.09	76.4618
1291.29	77.8875
1294.49	79.2762
1297.69	79.5851
1300.88	81.5674
1304.08	81.1789
1307.27	81.6225
1310.47	81.5147
1313.66	82.3051
1316.85	84.3051
1320.04	85.1475
1323.23	86.4596
1326.41	88.9937
1329.6	89.3576
1332.78	87.742
1335.97	86.4644
1339.15	83.7904
1342.33	81.5743
1345.51	78.8972
1348.69	75.9754
1351.87	73.4912
1355.04	71.3409
1358.22	69.8342
1361.39	67.5183
1364.57	63.9652
1367.74	62.1257
1370.91	59.8964
1374.07	56.5746
1377.24	56.2726
1380.41	54.0107
1383.57	53.5069
1386.74	53.4479
1389.9	52.1753
1393.06	55.3206
1396.22	56.456
1399.38	58.487
1402.54	59.7467
1405.7	61.8413
1408.85	64.2039
1412.01	68.1903
1415.16	73.3588
1418.31	78.0136
1421.46	83.356
1424.61	88.6068
1427.76	93.0785
1430.91	99.8683
1434.05	103.176
1437.2	106.736
1440.34	109.909
1443.49	111.492
1446.63	112.911
1449.77	112.852
1452.91	111.708
1456.04	109.486
1459.18	105.694
1462.31	102.573
1465.45	99.6922
1468.58	96.8781
1471.71	91.3411
1474.84	87.3701
1477.97	82.5879
1481.1	79.307
1484.23	74.3995
1487.35	71.2002
1490.48	68.2603
1493.6	64.9588
1496.72	60.6868
1499.84	57.339
1502.96	55.1304
1506.08	53.5192
1509.2	52.5916
1512.31	50.8638
1515.43	50.2564
1518.54	49.6178
1521.66	49.1056
1524.77	47.8151
1527.88	46.7643
1530.99	45.3403
1534.09	45.816
1537.2	45.681
1540.31	47.1205
1543.41	48.7603
1546.51	48.9166
1549.62	49.1411
1552.72	50.1667
1555.82	49.2472
1558.91	49.3709
1562.01	50.0984
1565.11	51.2678
1568.2	51.2238
1571.3	52.9403
1574.39	54.9787
1577.48	56.595
1580.57	58.5911
1583.66	60.9878
1586.75	62.3893
1589.83	64.5248
1592.92	66.4295
1596	68.5552
1599.09	69.5282
1602.17	69.8082
1605.25	71.3415
1608.33	72.9468
1611.41	73.1973
1614.48	73.0443
1617.56	72.9739
1620.64	72.9231
1623.71	71.4686
1626.78	72.4472
1629.86	72.3882
1632.92	74.2951
1635.99	75.3716
1639.06	77.2235
1642.13	77.4255
1645.19	78.5676
1648.26	79.8898
1651.32	81.0131
1654.38	81.2888
1657.45	79.606
1660.51	78.2217
1663.57	75.9697
1666.62	74.9256
1669.68	73.9588
1672.73	69.1159
1675.79	64.565
1678.84	60.1134
1681.89	55.9372
1684.94	49.8884
1687.99	45.5428
1691.04	41.1018
1694.09	36.6653
1697.14	32.7974
1700.18	30.9905
1703.22	29.2582
1706.27	27.177
1709.31	25.9998
1712.35	24.8309
1715.39	23.8715
1718.43	22.3749
1721.46	20.77
1724.5	20.7931
1727.53	21.0548
1730.57	19.3387
1733.6	17.6385
1736.63	15.8348
1739.66	14.7728
1742.69	15.1437
1745.72	13.5221
1748.74	11.1248
1751.77	9.86039
1754.8	8.36822
1757.82	8.32465
1760.84	9.15859
1763.86	8.11442
1766.88	7.58049
1769.9	6.88984
1772.92	6.50969
1775.93	7.45619
1778.95	7.88509
1781.96	9.32879
1784.98	8.90603
1787.99	8.87823
1791	9.27068
1794.01	9.43356
1797.02	9.41838
1800.03	9.89738
1803.03	10.4908
1806.04	9.80836
1809.04	9.16761
1812.04	10.1858
1815.05	10.5601
1818.05	10.5901
1821.05	9.56438
1824.05	9.23559
1827.04	7.5001
1830.04	7.65445
1833.03	7.99453
1836.03	7.33524
1839.02	6.65945
1842.01	6.85176
1845	7.27543
1847.99	7.62318
1850.98	8.52005
1853.97	8.47889
1856.95	7.97057
1859.94	7.66979
1862.92	6.74355
1865.91	7.39132
1868.89	8.05104
1871.87	8.61934
1874.85	9.30532
1877.83	9.7623
1880.8	10.1446
1882.56	10.7648
1885.54	10.9122
1888.53	10.8872
1891.52	10.6285
1894.5	9.36804
1897.49	8.39514
1900.47	7.81539
1903.45	7.71981
1906.43	8.14024
1909.41	7.655
1912.39	6.50408
1915.37	6.64399
1918.35	6.57293
1921.32	6.19587
1924.3	5.63976
1927.27	3.8308
1930.24	1.7213
1933.21	0.747084
1936.18	0.532088
1939.15	0.19849
1942.12	0.646918
1945.09	1.35032
1948.05	1.22833
1951.02	-0.0626787
1953.98	1.83402
1956.94	2.06398
1959.91	2.1783
1962.87	2.46085
1965.82	2.16666
1968.78	1.95275
1971.74	3.50732
1974.7	4.22272
1977.65	4.47716
1980.6	4.55666
1983.56	4.06565
1986.51	4.77084
1989.46	5.27881
1992.41	6.93561
1995.36	7.4018
1998.3	6.39345
2001.25	6.7282
2004.2	7.50316
2007.14	7.93534
2010.08	8.48416
2013.02	9.15927
2015.97	10.513
2018.9	10.4044
2021.84	10.3429
2024.78	10.5297
2027.72	12.2164
2030.65	13.3483
2033.59	13.3933
2036.52	13.3826
2039.45	14.543
2042.38	15.0193
2045.31	15.0373
2048.24	14.8521
2051.17	14.9148
2054.1	15.1525
2057.02	15.7528
2059.95	16.3274
2062.87	17.1492
2065.79	17.9063
2068.71	16.9926
2071.63	17.0979
2074.55	17.426
2077.47	17.7699
2080.39	18.7698
2083.3	20.7932
2086.22	22.1374
2089.13	23.7828
2092.05	26.4475
2094.96	28.8877
2097.87	31.0168
2100.78	34.2022
2103.69	36.22
2106.59	39.9577
2109.5	42.515
2112.41	46.3089
2115.31	48.0687
2118.21	52.0998
2121.12	54.8783
2124.02	58.8539
2126.92	61.6728
2129.82	64.8932
2132.71	68.8244
2135.61	71.127
2138.51	73.734
2141.4	75.5874
2144.29	79.0241
2147.19	80.5766
2150.08	82.7465
2152.97	86.0661
2155.86	88.4008
2158.75	90.593
2161.64	93.8135
2164.52	94.5808
2167.41	95.7478
2170.29	96.1007
2173.17	96.6858
2176.06	96.126
2178.94	95.1374
2181.82	93.2278
2184.7	92.2645
2187.57	89.9529
2190.45	89.3204
2193.33	86.9482
2196.2	84.5782
2199.08	80.8664
2201.95	77.3434
2204.82	73.7236
2207.69	70.3023
2210.56	67.0174
2213.43	63.4015
2216.3	59.5039
2219.16	55.8902
2222.03	53.7406
2224.89	50.2807
2227.75	47.4772
2230.62	44.2344
2233.48	42.232
2236.34	37.8391
2239.2	35.0949
2242.06	31.2218
2244.91	29.6635
2247.77	26.4376
2250.62	25.2102
2253.48	23.7094
2256.33	21.7311
2259.18	20.669
2262.03	19.3694
2264.88	17.084
2267.73	16.7136
2270.58	15.3555
2273.43	14.1668
2276.27	14.7365
2279.12	12.8018
2281.96	11.9107
2284.8	11.4524
2287.64	9.42227
2290.49	8.34218
2293.32	6.93283
2296.16	6.32122
2299	5.93028
2301.84	6.17829
2304.67	6.16001
2307.51	5.92537
2310.34	6.4285
2313.17	6.66802
2316	7.64842
2318.83	8.03779
2321.66	8.32947
2324.49	7.47565
2327.32	7.97594
2330.15	7.57423
2332.97	8.44425
2335.79	8.59857
2338.62	7.36388
2341.44	6.60806
2344.26	5.87465
2347.08	5.34081
2349.9	5.00028
2352.72	4.01044
2355.53	3.21943
2358.35	2.37881
2361.17	1.34342
2363.98	1.73515
2366.79	2.53682
2369.6	2.80445
2372.42	2.34072
2375.22	2.33823
2378.03	0.669605
2380.84	0.655488
2383.65	0.797487
2386.45	-0.0618998
2389.26	0.334786
2392.06	0.606034
2394.87	1.26723
2397.67	0.737483
2400.47	0.591056
2403.27	1.80909
2406.07	1.76354
2408.86	2.35478
2411.66	2.85584
2414.46	3.68417
2417.25	4.28678
2420.05	4.19285
2422.84	4.47329
2425.63	4.95667
2428.42	3.39126
2431.21	4.08445
2434	4.07031
2436.79	4.46033
2439.57	3.86221
2442.36	3.21645
2445.14	1.73783
2447.93	1.40778
2450.71	1.90845
2453.49	2.15486
2456.27	2.83826
2459.05	2.3268
2461.83	2.91558
2464.61	2.53408
2467.39	2.3766
2470.16	3.33544
2472.94	4.08488
2475.71	3.97486
2478.48	3.92646
2481.25	3.7158
2484.02	3.58674
2486.8	3.04959
2489.56	3.61168
2492.33	2.98677
2495.1	2.84229
2497.86	2.74596
2500.63	3.01027
2503.39	3.16116
2506.16	2.57414
2508.92	1.73279
2511.68	2.17363
2514.44	1.7206
2517.2	2.31483
2519.95	2.13745
2522.71	2.08383
2525.47	2.58812
2528.22	2.97691
2530.98	2.52178
2533.73	2.13326
2536.48	2.79635
2539.23	2.6379
2541.98	1.5799
2544.73	1.79787
2547.48	1.90613
2550.23	2.44038
2552.97	3.13914
2555.72	2.71865
2558.46	1.83238
2561.2	2.42475
2563.95	1.51202
2566.69	1.41646
2569.43	2.68124
2572.17	1.96196
2574.91	1.68374
2577.64	2.70642
2580.38	2.4023
2583.11	2.76517
2585.85	2.33428
2588.58	2.52231
2591.31	3.07806
2594.04	2.99919
2596.78	3.34363
2599.51	2.31337
2602.23	1.9538
2604.96	0.897111
2607.69	0.680961
2610.41	0.97623
2613.14	1.70921
2615.86	1.23857
2618.58	1.48995
2621.3	0.908113
2624.03	0.539649
2626.75	1.41602
2629.46	1.72736
2632.18	1.66856
2634.9	3.22753
2637.61	4.31419
2640.33	5.77299
2643.04	5.71865
2645.76	5.87453
2648.47	7.09119
2651.18	6.33872
2653.89	5.86302
2656.6	6.54438
2659.31	6.95453
2662.01	6.89989
2664.72	6.82856
2667.43	6.13957
2670.13	6.99658
2672.83	6.04062
2675.53	6.8265
2678.24	6.91415
2680.94	7.07955
2683.64	7.39349
2686.34	8.06079
2689.03	7.46555
2691.73	8.6285
2694.43	9.22849
2697.12	10.155
2699.81	10.8039
2702.51	12.3064
2705.2	13.0514
2707.89	12.8317
2710.58	12.6687
2713.27	13.9469
2715.96	13.2595
2718.64	13.7234
2721.33	14.7822
2724.01	14.8826
2726.7	15.4492
2729.38	14.8839
2732.06	15.1212
2734.75	13.8882
2737.43	13.0001
2740.11	11.862
2742.78	10.9464
2745.46	9.44946
2748.14	7.49647
2750.81	6.35802
2753.49	5.25549
2756.16	4.76987
2758.84	3.44917
2761.51	2.12086
2764.18	1.57988
2766.85	2.33232
2769.52	3.33444
2772.19	3.14197
2774.85	3.44799
2777.52	2.97432
2780.18	3.15122
2782.85	4.2615
2785.51	4.79962
2788.17	5.00646
2790.84	5.16771
2793.5	6.69794
2796.16	6.90825
2798.81	7.36591
2801.47	7.39672
2804.13	8.00173
2806.79	8.23783
2809.44	7.67746
2812.09	6.90539
2814.75	8.1693
2817.4	8.77919
2820.05	11.0245
2822.7	14.889
2825.35	18.8955
2828	23.7996
2830.65	29.3683
2833.29	34.2144
2835.94	39.5783
2838.58	43.9595
2841.23	50.335
2843.87	57.4584
2846.51	64.6176
2849.15	71.9741
2851.79	78.4238
2854.43	85.5178
2857.07	93.4809
2859.71	101.029
2862.34	107.48
2864.98	114.163
2867.61	118.657
2870.25	123.168
2872.88	126.478
2875.51	130.602
2878.14	134.548
2880.77	137.862
2883.4	141.586
2886.03	145.834
2888.65	149.33
2891.28	152.426
2893.91	156.189
2896.53	161.299
2899.15	165.26
2901.78	171.704
2904.4	177.048
2907.02	184.151
2909.64	191.61
2912.26	198.822
2914.87	206.41
2917.49	213.542
2920.11	220.228
2922.72	225.857
2925.34	230.888
2927.95	234.153
2930.56	235.579
2933.17	235.906
2935.78	236.093
2938.39	233.423
2941	228.842
2943.61	222.986
2946.22	215.537
2948.82	207.887
2951.43	199.209
2954.03	190.596
2956.64	182.138
2959.24	173.137
2961.84	162.714
2964.44	153.914
2967.04	144.636
2969.64	135.407
2972.24	127.325
2974.83	118.777
2977.43	110.254
2980.02	101.985
2982.62	93.4609
2985.21	85.7915
2987.8	78.1397
2990.4	70.6597
2992.99	63.8461
2995.57	57.3728
2998.16	51.2992
3000.75	45.6749
3003.34	38.88
3005.92	34.0957
3008.51	29.5088
3011.09	25.6085
3013.68	22.2208
3016.26	18.7044
3018.84	17.2201
3021.42	15.1866
3024	12.6451
3026.58	10.3264
3029.16	8.84304
3031.73	7.50998
3034.31	6.98509
3036.89	6.42568
3039.46	6.80704
3042.03	7.71174
3044.61	7.75667
3047.18	8.28166
3049.75	8.72894
3052.32	8.05105
3054.89	7.3099
3057.45	7.0885
3060.02	7.49062
3062.59	6.36673
3065.15	5.9356
3067.72	4.51648
3070.28	5.06928
3072.84	4.21111
3075.41	3.8366
3077.97	3.04984
3080.53	2.26398
3083.09	1.54101
3085.64	-0.0618826
3088.2	-0.427718
3090.76	-0.894487
3093.31	-0.335938
3095.87	-0.497874
3098.42	0.40204
3100.97	1.13863
3103.53	1.74231
3106.08	2.90357
3108.63	4.03561
3111.18	5.43175
3113.73	5.88489
3116.27	6.11352
3118.82	6.8501
3121.37	8.04973
3123.91	8.565
3126.45	9.06942
3129	10.1188
3131.54	11.8183
3134.08	13.0296
3136.62	13.3198
3139.16	14.3226
3141.7	14.9613
3144.24	15.6594
3146.78	16.3585
3149.31	17.0891