File: data/Raman/poly_smoothed/Mb_40_y_25_1x_45s_532 nm_x100_100%_600 gr_mm_01.txt
#Acq. time (s)=	45
#Accumulations=	2
#Range (cm-¹)=	200...3150
#Windows=	2
#Auto scanning=	Off
#Autofocus=	Off
#Macrospot=	Off
#AutoExposure=	Off
#Spike filter=	Multiple accum.
#Delay time (s)=	0
#Binning=	1
#Readout mode=	Signal
#DeNoise=	Off
#ICS correction=	On
#Dark correction=	Off
#Inst. Process=	Off
#Detector Gain=	Best Dynamic Range
#Detector ADC=	20 kHz
#Detector temperature (°C)=	-69.85
#Instrument=	LabRAM HR Evol
#Detector=	Synapse
#Objective=	x100
#Grating=	600 gr/mm
#ND Filter=	100%
#Laser (nm)=	532
#Hole=	100.021
#Range=	Auto
#Laser Pol.=	No
#Raman. Pol.=	No
#Laser Pol. (°)=	-0.0007625
#Raman Pol. (°)=	89.9995
#Collection=	Microscope
#StageXY=	Marzhauser
#StageZ=	Marzhauser
#X (µm)=	-1066
#Y (µm)=	564.9
#Z (µm)=	584.5
#Full time(mm:ss)=	3:18
#Project=
#Sample=
#Site=
#Title=	Mb_40_y_25_2x_45s_532 nm_x100_100%_600 gr_mm
#Remark=
#Date=	19.07.2022 11:06
#Acquired=	19.07.2022 11:06:55
#Base:Fit=	10.08.2022 10:52:48
#Base:Sub=	10.08.2022 10:52:53
#Filter:Polynom=	16.08.2022 10:09:04
#AxisType[0]=Intens
#AxisUnit[0]=Cnt
#AxisType[1]=Spectr
#AxisUnit[1]=1/cm
200.423	-0.449047
204.052	2.55551
207.682	4.74388
211.308	5.65129
214.935	5.23316
218.558	7.14984
222.18	8.00935
225.802	5.71124
229.421	6.56693
233.039	5.36847
236.657	6.69646
240.272	7.8409
243.885	9.10245
247.497	8.78726
251.11	9.30578
254.719	9.62598
258.327	10.3526
261.933	10.3513
265.538	10.0624
269.141	10.064
272.744	8.27882
276.344	7.89098
279.944	8.65894
283.542	9.6453
287.138	10.1665
290.733	9.80468
294.327	8.99233
297.919	9.01264
301.508	10.3425
305.098	13.0185
308.686	13.8288
312.273	14.0491
315.858	14.3236
319.44	14.3792
323.022	15.6534
326.604	17.9955
330.181	19.1927
333.76	19.404
337.335	22.4498
340.91	22.7426
344.483	23.2348
348.055	23.0674
351.625	21.9061
355.195	19.8427
358.762	18.9304
362.329	17.3924
365.893	16.0204
369.455	13.2721
373.017	10.3478
376.578	9.71641
380.137	9.51089
383.694	8.30203
387.249	9.1085
390.806	10.672
394.359	10.606
397.91	8.08992
401.46	7.65662
405.009	7.27515
408.557	7.09453
412.103	9.41584
415.647	9.46213
419.191	8.58107
422.733	10.3427
426.273	12.182
429.812	12.9921
433.35	13.0392
436.885	12.6113
440.42	12.1064
443.954	12.5061
447.486	13.2929
451.015	13.3701
454.545	13.3652
458.073	14.7629
461.598	16.6957
465.124	17.4153
468.648	18.63
472.169	19.3158
475.69	21.3664
479.208	23.1645
482.727	23.6464
486.243	24.8869
489.759	27.9329
493.272	27.0627
496.783	27.2845
500.295	28.4253
503.804	27.5444
507.311	27.3623
510.819	26.6606
514.324	25.71
517.827	22.8595
521.329	23.3416
524.83	21.9217
528.329	20.0168
531.829	18.5744
535.326	18.3404
538.821	16.462
542.315	16.5961
545.808	16.1113
549.299	15.4388
552.789	13.9073
556.278	12.1039
559.763	10.7563
563.249	11.1228
566.733	10.2199
570.217	10.2842
573.699	10.5048
577.177	9.75852
580.656	7.70581
584.134	7.81975
587.609	6.15192
591.084	5.46538
594.558	4.59021
598.029	4.21385
601.5	3.26706
604.968	3.92763
608.437	4.54503
611.902	5.48983
615.368	5.52778
618.831	6.61499
622.294	6.9018
625.755	7.92823
629.213	10.1918
632.673	11.7458
636.129	13.0342
639.584	12.5902
643.037	12.3239
646.491	14.3201
649.942	14.6907
653.392	14.7616
656.84	16.3625
660.287	16.8661
663.732	16.5366
667.177	16.7052
670.62	15.573
674.061	16.821
677.502	17.3709
680.941	18.2497
684.379	17.1966
687.815	18.9614
691.248	20.2802
694.682	20.4857
698.115	18.7124
701.546	18.9823
704.974	22.2551
708.402	24.4513
711.83	26.8578
715.254	28.1276
718.679	30.3475
722.102	30.7321
725.522	30.7437
728.943	32.3371
732.361	34.2857
735.779	36.726
739.194	38.1309
742.608	39.722
746.022	40.9928
749.433	41.8279
752.843	43.6287
756.254	46.6338
759.661	48.1285
763.067	47.6185
766.471	49.8537
769.877	51.7607
773.279	50.2067
776.68	53.0116
780.079	54.3428
783.478	56.2786
786.875	60.5635
790.27	63.0393
793.665	65.144
797.058	67.1252
800.45	69.3355
803.84	71.4847
807.23	71.4261
810.616	72.4728
814.002	75.43
817.388	77.3123
820.772	77.7087
824.153	78.2171
827.535	77.5239
830.915	77.516
834.292	75.8389
837.67	73.3569
841.047	70.5468
844.42	66.6525
847.794	64.1935
851.165	61.8067
854.534	59.2076
857.905	58.2863
861.272	58.1653
864.639	56.4785
868.004	54.6066
871.367	56.2135
874.731	57.5861
878.092	56.4668
881.451	56.6442
884.809	55.2095
888.166	55.2555
891.522	55.7038
894.878	55.4863
898.231	56.3569
901.583	55.5984
904.934	54.8693
908.283	54.0163
911.631	51.6624
914.976	50.3079
918.322	48.9285
921.666	47.4938
925.009	46.1444
928.351	45.5968
931.692	46.2247
935.029	45.0161
938.367	44.2796
941.704	46.1012
945.038	45.7526
948.372	44.2607
951.705	45.3203
955.035	45.6949
958.366	45.1549
961.693	45.3965
965.021	47.1864
968.346	48.5704
971.67	49.4123
974.995	51.7827
978.316	50.5405
981.638	50.0992
984.957	47.5283
988.274	46.4389
991.59	44.6369
994.907	42.4727
998.221	39.781
1001.53	36.229
1004.85	34.2552
1008.16	34.4545
1011.46	39.7896
1014.77	49.5261
1018.08	60.1618
1021.38	70.6332
1024.69	82.7588
1027.99	92.9743
1031.29	101.527
1034.59	110.276
1037.89	118.191
1041.19	122.791
1044.48	128.174
1047.78	128.886
1051.07	128.873
1054.36	126.842
1057.66	121.103
1060.94	112.194
1064.23	101.634
1067.52	89.9205
1070.81	77.359
1074.09	63.4262
1077.38	49.3485
1080.66	36.4987
1083.94	27.34
1087.22	21.6788
1090.5	20.1175
1093.77	21.8987
1097.05	20.9673
1100.32	20.6279
1103.6	21.4154
1106.87	23.3252
1110.14	22.6764
1113.41	21.5053
1116.67	21.3933
1119.94	21.5374
1123.21	21.6518
1126.47	23.2933
1129.73	22.0237
1133	21.3565
1136.26	20.1457
1139.52	18.2726
1142.77	15.5543
1146.03	15.9883
1149.29	14.3291
1152.54	12.8108
1155.79	10.3407
1159.04	7.54747
1162.3	6.88659
1165.55	4.80003
1168.79	3.17184
1172.04	3.87683
1175.28	2.89929
1178.53	2.92712
1181.77	3.92395
1185.01	3.48834
1188.25	3.87012
1191.49	3.05763
1194.73	3.73365
1197.97	4.26603
1201.2	6.14178
1204.44	7.47721
1207.67	7.99037
1210.9	9.96991
1214.13	11.0792
1217.36	13.1619
1220.59	12.7586
1223.82	15.4944
1227.04	14.318
1230.26	15.1135
1233.49	16.345
1236.71	17.4473
1239.93	20.0186
1243.15	21.0216
1246.37	21.038
1249.58	23.6098
1252.8	23.7945
1256.01	26.8026
1259.23	27.6368
1262.44	31.1256
1265.65	33.9437
1268.86	36.7556
1272.07	40.5088
1275.27	42.867
1278.48	49.082
1281.68	52.0086
1284.89	54.6935
1288.09	56.7231
1291.29	59.3956
1294.49	60.331
1297.69	59.6817
1300.88	60.2413
1304.08	60.9661
1307.27	62.0542
1310.47	62.975
1313.66	62.7809
1316.85	62.552
1320.04	60.203
1323.23	56.8126
1326.41	54.5861
1329.6	52.4283
1332.78	49.8093
1335.97	49.324
1339.15	47.8122
1342.33	47.9131
1345.51	44.7411
1348.69	43.7814
1351.87	41.8246
1355.04	40.4445
1358.22	38.839
1361.39	35.0586
1364.57	31.3926
1367.74	28.7556
1370.91	27.1787
1374.07	24.2734
1377.24	22.8965
1380.41	22.5934
1383.57	23.1449
1386.74	23.0837
1389.9	24.3373
1393.06	23.6348
1396.22	23.55
1399.38	24.876
1402.54	29.2368
1405.7	34.5532
1408.85	40.7897
1412.01	47.6449
1415.16	54.6895
1418.31	62.2797
1421.46	69.2053
1424.61	77.2723
1427.76	85.2987
1430.91	91.4348
1434.05	96.198
1437.2	100.994
1440.34	103.168
1443.49	103.688
1446.63	103.322
1449.77	101.509
1452.91	99.5131
1456.04	94.6016
1459.18	90.753
1462.31	84.4376
1465.45	78.3188
1468.58	71.2628
1471.71	62.5227
1474.84	55.4176
1477.97	50.386
1481.1	45.2924
1484.23	41.3956
1487.35	35.2677
1490.48	29.9896
1493.6	26.6022
1496.72	24.8036
1499.84	22.3512
1502.96	20.9706
1506.08	19.2292
1509.2	20.1798
1512.31	17.743
1515.43	16.4224
1518.54	16.7068
1521.66	15.153
1524.77	14.8053
1527.88	15.2827
1530.99	16.037
1534.09	15.5618
1537.2	16.8715
1540.31	17.2862
1543.41	17.9871
1546.51	19.5755
1549.62	19.8451
1552.72	23.1073
1555.82	22.6329
1558.91	25.3362
1562.01	26.0422
1565.11	27.2121
1568.2	29.9255
1571.3	32.7338
1574.39	36.4148
1577.48	38.5731
1580.57	41.7968
1583.66	42.3661
1586.75	43.0339
1589.83	42.9694
1592.92	44.4406
1596	44.4009
1599.09	42.574
1602.17	41.1689
1605.25	40.8198
1608.33	39.7816
1611.41	38.69
1614.48	37.1919
1617.56	37.8201
1620.64	36.9327
1623.71	35.5818
1626.78	34.8093
1629.86	34.1742
1632.92	35.4251
1635.99	36.5792
1639.06	37.0703
1642.13	37.4463
1645.19	37.5893
1648.26	38.9994
1651.32	36.871
1654.38	36.4006
1657.45	35.7338
1660.51	33.0456
1663.57	34.374
1666.62	33.4592
1669.68	30.1922
1672.73	27.3764
1675.79	26.0594
1678.84	24.1941
1681.89	22.2242
1684.94	20.4761
1687.99	17.2458
1691.04	16.4294
1694.09	14.5424
1697.14	11.4972
1700.18	10.165
1703.22	10.0824
1706.27	9.42424
1709.31	8.21759
1712.35	6.36147
1715.39	5.57464
1718.43	3.36879
1721.46	4.37123
1724.5	3.37837
1727.53	3.25336
1730.57	4.34226
1733.6	4.55303
1736.63	5.02645
1739.66	4.85464
1742.69	3.88023
1745.72	3.22974
1748.74	4.05351
1751.77	3.78142
1754.8	2.20657
1757.82	2.3831
1760.84	0.846284
1763.86	-0.811547
1766.88	-0.73684
1769.9	-0.71603
1772.92	-0.1003
1775.93	0.261798
1778.95	0.184237
1781.96	0.0403663
1784.98	0.573407
1787.99	0.451012
1791	0.989429
1794.01	1.3229
1797.02	1.13106
1800.03	1.92225
1803.03	2.33482
1806.04	3.79442
1809.04	4.70703
1812.04	5.34277
1815.05	6.26809
1818.05	5.49156
1821.05	5.2135
1824.05	5.9885
1827.04	5.75001
1830.04	6.19041
1833.03	4.59207
1836.03	4.11503
1839.02	3.38304
1842.01	5.6988
1845	7.09206
1847.99	8.03429
1850.98	8.62084
1853.97	9.74492
1856.95	7.90083
1859.94	7.48248
1862.92	7.7962
1865.91	7.19796
1868.89	7.23147
1871.87	8.78929
1874.85	9.05671
1877.83	9.61818
1880.8	10.8437
1882.56	9.72607
1885.54	10.253
1888.53	10.3075
1891.52	10.8241
1894.5	12.0756
1897.49	11.8495
1900.47	10.6778
1903.45	11.1254
1906.43	9.22334
1909.41	9.64213
1912.39	10.3961
1915.37	10.7693
1918.35	10.6754
1921.32	11.4799
1924.3	9.12808
1927.27	7.15802
1930.24	4.8749
1933.21	4.2823
1936.18	3.69038
1939.15	4.52336
1942.12	4.75924
1945.09	5.97232
1948.05	4.39175
1951.02	4.16375
1953.98	6.06097
1956.94	6.11668
1959.91	7.18743
1962.87	6.99931
1965.82	8.5775
1968.78	8.27682
1971.74	8.23533
1974.7	9.5143
1977.65	9.03593
1980.6	8.79251
1983.56	11.0106
1986.51	9.74169
1989.46	10.2299
1992.41	12.0426
1995.36	10.0573
1998.3	9.93051
2001.25	8.6526
2004.2	10.2991
2007.14	11.4465
2010.08	12.2594
2013.02	11.4741
2015.97	10.4754
2018.9	10.3957
2021.84	11.583
2024.78	13.7034
2027.72	14.2388
2030.65	11.7549
2033.59	12.4241
2036.52	13.3849
2039.45	12.1983
2042.38	12.7516
2045.31	14.5143
2048.24	14.2718
2051.17	13.0106
2054.1	13.7766
2057.02	14.5868
2059.95	15.0011
2062.87	15.7305
2065.79	17.1435
2068.71	17.5258
2071.63	19.1276
2074.55	20.5062
2077.47	21.5812
2080.39	21.9852
2083.3	22.4775
2086.22	24.8798
2089.13	26.5593
2092.05	29.2774
2094.96	31.9705
2097.87	32.8912
2100.78	33.0411
2103.69	34.5075
2106.59	37.2319
2109.5	37.3045
2112.41	36.2779
2115.31	37.704
2118.21	38.1573
2121.12	37.7864
2124.02	37.3072
2126.92	37.9261
2129.82	39.0157
2132.71	39.4134
2135.61	40.0473
2138.51	40.8349
2141.4	43.5214
2144.29	47.0938
2147.19	47.7707
2150.08	48.6893
2152.97	50.1804
2155.86	51.4995
2158.75	54.1392
2161.64	53.7999
2164.52	55.2448
2167.41	57.0668
2170.29	57.3478
2173.17	58.8071
2176.06	59.99
2178.94	59.9933
2181.82	58.3692
2184.7	58.2964
2187.57	58.7826
2190.45	57.0551
2193.33	56.6676
2196.2	56.9894
2199.08	55.4247
2201.95	54.3792
2204.82	54.0019
2207.69	54.1426
2210.56	53.2372
2213.43	51.9854
2216.3	48.6609
2219.16	48.1626
2222.03	47.7145
2224.89	46.8914
2227.75	46.294
2230.62	44.7243
2233.48	43.696
2236.34	43.606
2239.2	41.3065
2242.06	41.6693
2244.91	39.2229
2247.77	39.1196
2250.62	37.8007
2253.48	36.1824
2256.33	36.7382
2259.18	35.3347
2262.03	32.7782
2264.88	31.1536
2267.73	30.0024
2270.58	26.9731
2273.43	25.897
2276.27	24.2418
2279.12	21.836
2281.96	20.3947
2284.8	20.7278
2287.64	21.7932
2290.49	20.2096
2293.32	19.3291
2296.16	20.4224
2299	20.0762
2301.84	19.9492
2304.67	19.9629
2307.51	19.4929
2310.34	19.8281
2313.17	19.8154
2316	18.3546
2318.83	18.0201
2321.66	17.326
2324.49	17.1809
2327.32	16.6041
2330.15	15.4202
2332.97	14.0758
2335.79	12.6997
2338.62	10.4522
2341.44	9.93385
2344.26	9.18504
2347.08	9.62366
2349.9	9.27291
2352.72	8.87611
2355.53	8.21393
2358.35	8.2552
2361.17	8.6632
2363.98	10.5899
2366.79	11.6151
2369.6	11.826
2372.42	11.9238
2375.22	11.5156
2378.03	12.134
2380.84	11.0545
2383.65	9.61892
2386.45	9.39922
2389.26	9.1792
2392.06	7.54034
2394.87	7.63052
2397.67	5.9232
2400.47	3.807
2403.27	3.85245
2406.07	2.81265
2408.86	3.18527
2411.66	3.39346
2414.46	3.68273
2417.25	2.91235
2420.05	3.34123
2422.84	3.5739
2425.63	4.34477
2428.42	6.12007
2431.21	7.48324
2434	8.77937
2436.79	9.42096
2439.57	9.26462
2442.36	9.77327
2445.14	11.2099
2447.93	10.6362
2450.71	10.3317
2453.49	9.03066
2456.27	8.58543
2459.05	7.32169
2461.83	6.8853
2464.61	6.73829
2467.39	6.56075
2470.16	8.2875
2472.94	8.45814
2475.71	8.41471
2478.48	8.22773
2481.25	7.04788
2484.02	4.7461
2486.8	5.95132
2489.56	6.55654
2492.33	5.23019
2495.1	5.06641
2497.86	4.76375
2500.63	5.03022
2503.39	3.36994
2506.16	4.17309
2508.92	5.39684
2511.68	5.37788
2514.44	4.77848
2517.2	3.29887
2519.95	4.72372
2522.71	4.6569
2525.47	5.2272
2528.22	4.91431
2530.98	5.53332
2533.73	7.34596
2536.48	8.14614
2539.23	9.40827
2541.98	9.65809
2544.73	10.3429
2547.48	9.47676
2550.23	9.10497
2552.97	11.3973
2555.72	13.1977
2558.46	11.329
2561.2	13.0946
2563.95	13.5092
2566.69	15.2775
2569.43	14.7868
2572.17	14.5501
2574.91	14.6909
2577.64	15.0997
2580.38	14.0212
2583.11	13.8969
2585.85	13.8638
2588.58	13.0595
2591.31	10.6843
2594.04	9.61673
2596.78	8.32742
2599.51	6.89467
2602.23	6.17438
2604.96	5.42134
2607.69	5.59286
2610.41	5.5128
2613.14	2.34482
2615.86	2.79805
2618.58	3.61131
2621.3	5.87611
2624.03	5.45703
2626.75	6.98704
2629.46	7.56297
2632.18	6.74891
2634.9	6.80052
2637.61	5.92763
2640.33	6.77794
2643.04	6.69109
2645.76	6.45952
2648.47	6.53365
2651.18	5.88922
2653.89	3.50043
2656.6	3.27165
2659.31	3.98953
2662.01	4.36669
2664.72	3.64809
2667.43	3.31005
2670.13	3.14163
2672.83	2.34959
2675.53	1.80701
2678.24	1.4971
2680.94	2.74401
2683.64	3.19176
2686.34	5.85183
2689.03	7.01015
2691.73	8.4692
2694.43	9.49032
2697.12	8.30962
2699.81	8.23226
2702.51	8.68106
2705.2	10.3453
2707.89	10.7005
2710.58	13.3135
2713.27	13.5751
2715.96	13.3987
2718.64	14.2387
2721.33	16.4903
2724.01	17.848
2726.7	17.8226
2729.38	17.5276
2732.06	16.2457
2734.75	14.5982
2737.43	13.4071
2740.11	13.0077
2742.78	12.082
2745.46	11.2726
2748.14	11.118
2750.81	10.0097
2753.49	6.74872
2756.16	5.4479
2758.84	3.65157
2761.51	2.0122
2764.18	0.177489
2766.85	0.932875
2769.52	1.15128
2772.19	1.03495
2774.85	1.59544
2777.52	2.5033
2780.18	1.51483
2782.85	2.81466
2785.51	2.958
2788.17	4.39415
2790.84	2.72983
2793.5	3.64184
2796.16	4.64793
2798.81	5.49584
2801.47	6.36998
2804.13	8.44959
2806.79	6.65522
2809.44	6.44171
2812.09	7.08712
2814.75	8.40765
2817.4	11.2522
2820.05	16.9157
2822.7	26.0817
2825.35	36.3568
2828	47.3874
2830.65	58.564
2833.29	69.4048
2835.94	80.6027
2838.58	93.2383
2841.23	104.92
2843.87	115.375
2846.51	126.214
2849.15	137.591
2851.79	148.262
2854.43	159.639
2857.07	171.267
2859.71	181.741
2862.34	189.731
2864.98	195.209
2867.61	200.034
2870.25	203.235
2872.88	206.307
2875.51	209.615
2878.14	214.209
2880.77	218.082
2883.4	220.599
2886.03	224.507
2888.65	226.862
2891.28	228.415
2893.91	229.69
2896.53	231.764
2899.15	233.469
2901.78	232.45
2904.4	233.619
2907.02	235.317
2909.64	238.812
2912.26	242.107
2914.87	247.041
2917.49	251.457
2920.11	255.216
2922.72	257.537
2925.34	256.842
2927.95	257.392
2930.56	257.147
2933.17	254.624
2935.78	252.447
2938.39	247.719
2941	241.542
2943.61	233.994
2946.22	224.253
2948.82	214.718
2951.43	202.915
2954.03	191.096
2956.64	181.749
2959.24	168.935
2961.84	158.52
2964.44	146.942
2967.04	137.466
2969.64	129.326
2972.24	120.929
2974.83	110.994
2977.43	102.398
2980.02	94.5909
2982.62	85.994
2985.21	78.5607
2987.8	71.1768
2990.4	63.9118
2992.99	58.1841
2995.57	51.0223
2998.16	46.3122
3000.75	41.1152
3003.34	35.4458
3005.92	29.9679
3008.51	24.9072
3011.09	20.7137
3013.68	17.0929
3016.26	11.7211
3018.84	10.892
3021.42	8.93772
3024	6.6006
3026.58	5.41232
3029.16	4.15563
3031.73	2.81098
3034.31	2.46336
3036.89	2.73587
3039.46	3.40654
3042.03	4.93035
3044.61	5.82541
3047.18	7.99982
3049.75	8.37894
3052.32	9.09408
3054.89	9.52724
3057.45	10.5092
3060.02	11.4198
3062.59	10.5578
3065.15	8.87566
3067.72	7.95837
3070.28	7.46458
3072.84	6.06127
3075.41	6.43843
3077.97	4.92779
3080.53	3.82666
3083.09	3.64701
3085.64	1.63469
3088.2	1.09399
3090.76	0.992873
3093.31	0.552253
3095.87	-0.665312
3098.42	1.09155
3100.97	1.86487
3103.53	1.00723
3106.08	1.56258
3108.63	2.37748
3111.18	2.03828
3113.73	2.58629
3116.27	3.16264
3118.82	3.88883
3121.37	3.66011
3123.91	3.64163
3126.45	2.87893
3129	2.95261
3131.54	2.84535
3134.08	1.9491
3136.62	2.77558
3139.16	2.4177
3141.7	0.590863
3144.24	-1.02869
3146.78	-2.75446
3149.31	-4.96666