File: data/Raman/poly_smoothed/Mb_40_y_46_1x_45s_532 nm_x100_100%_600 gr_mm_01.txt
#Acq. time (s)=	45
#Accumulations=	2
#Range (cm-¹)=	200...3150
#Windows=	2
#Auto scanning=	Off
#Autofocus=	Off
#Macrospot=	Off
#AutoExposure=	Off
#Spike filter=	Multiple accum.
#Delay time (s)=	0
#Binning=	1
#Readout mode=	Signal
#DeNoise=	Off
#ICS correction=	On
#Dark correction=	Off
#Inst. Process=	Off
#Detector Gain=	Best Dynamic Range
#Detector ADC=	20 kHz
#Detector temperature (°C)=	-69.85
#Instrument=	LabRAM HR Evol
#Detector=	Synapse
#Objective=	x100
#Grating=	600 gr/mm
#ND Filter=	100%
#Laser (nm)=	532
#Hole=	100.021
#Range=	Auto
#Laser Pol.=	No
#Raman. Pol.=	No
#Laser Pol. (°)=	-0.0007625
#Raman Pol. (°)=	89.9995
#Collection=	Microscope
#StageXY=	Marzhauser
#StageZ=	Marzhauser
#X (µm)=	-1148.4
#Y (µm)=	682
#Z (µm)=	585.1
#Full time(mm:ss)=	3:18
#Project=
#Sample=
#Site=
#Title=	Mb_40_y_46_2x_45s_532 nm_x100_100%_600 gr_mm
#Remark=
#Date=	19.07.2022 13:24
#Acquired=	19.07.2022 13:24:49
#Base:Fit=	10.08.2022 10:52:48
#Base:Sub=	10.08.2022 10:52:53
#Filter:Polynom=	16.08.2022 10:09:04
#AxisType[0]=Intens
#AxisUnit[0]=Cnt
#AxisType[1]=Spectr
#AxisUnit[1]=1/cm
200.423	93.927
204.052	81.0162
207.682	72.3284
211.308	64.7303
214.935	58.5771
218.558	53.142
222.18	48.6847
225.802	42.6828
229.421	37.0607
233.039	31.4382
236.657	27.3854
240.272	24.7803
243.885	22.0074
247.497	17.8755
251.11	15.3225
254.719	12.04
258.327	12.0901
261.933	11.375
265.538	8.73811
269.141	7.72125
272.744	5.0112
276.344	3.26497
279.944	3.77738
283.542	2.68306
287.138	3.48556
290.733	5.51412
294.327	5.31005
297.919	7.27608
301.508	9.54229
305.098	10.1526
308.686	11.4622
312.273	10.8158
315.858	10.7172
319.44	11.7072
323.022	13.8902
326.604	14.6
330.181	13.6029
333.76	12.9848
337.335	11.7755
340.91	11.2807
344.483	10.4441
348.055	7.92151
351.625	5.63703
355.195	4.10221
358.762	4.0656
362.329	3.3142
365.893	4.13811
369.455	3.69977
373.017	3.65605
376.578	4.72274
380.137	4.45595
383.694	6.07503
387.249	9.25059
390.806	9.044
394.359	8.8313
397.91	10.1601
401.46	10.5564
405.009	12.3687
408.557	12.4228
412.103	13.3676
415.647	15.0878
419.191	17.3107
422.733	18.5441
426.273	18.4698
429.812	19.4255
433.35	17.7584
436.885	17.6706
440.42	18.4224
443.954	18.2264
447.486	18.8302
451.015	17.0759
454.545	17.0872
458.073	17.0429
461.598	19.103
465.124	19.8149
468.648	19.7638
472.169	19.5091
475.69	18.3546
479.208	17.5872
482.727	19.2405
486.243	20.6514
489.759	22.7038
493.272	25.5794
496.783	27.1975
500.295	31.2773
503.804	32.4282
507.311	33.2279
510.819	33.219
514.324	35.8955
517.827	36.3752
521.329	35.2661
524.83	34.3059
528.329	33.4903
531.829	31.2502
535.326	30.1211
538.821	29.7478
542.315	29.1363
545.808	27.5276
549.299	23.9441
552.789	21.6968
556.278	19.9831
559.763	18.0053
563.249	15.7016
566.733	14.5366
570.217	14.0114
573.699	11.1981
577.177	9.61981
580.656	7.86645
584.134	6.60669
587.609	6.45585
591.084	2.30778
594.558	3.77618
598.029	3.46424
601.5	3.01073
604.968	2.83618
608.437	1.3675
611.902	1.22684
615.368	2.38071
618.831	2.95656
622.294	7.18327
625.755	8.56037
629.213	7.9866
632.673	7.61889
636.129	8.50228
639.584	7.99918
643.037	8.84827
646.491	9.5291
649.942	10.8407
653.392	12.9017
656.84	11.6143
660.287	12.1406
663.732	10.3225
667.177	10.2786
670.62	11.4876
674.061	13.0641
677.502	14.8176
680.941	18.1998
684.379	17.8726
687.815	19.0573
691.248	19.8828
694.682	21.4035
698.115	26.1461
701.546	28.3722
704.974	31.3076
708.402	35.2479
711.83	35.8246
715.254	37.2044
718.679	37.9051
722.102	38.1741
725.522	38.9842
728.943	40.0313
732.361	40.987
735.779	41.1763
739.194	40.3734
742.608	40.1949
746.022	39.234
749.433	39.5925
752.843	41.6554
756.254	45.4605
759.661	47.8817
763.067	48.1508
766.471	50.2174
769.877	49.7417
773.279	49.5717
776.68	50.9264
780.079	54.829
783.478	54.9828
786.875	57.9093
790.27	58.8206
793.665	60.3309
797.058	59.918
800.45	59.0947
803.84	56.2922
807.23	59.5941
810.616	60.7633
814.002	61.047
817.388	60.6293
820.772	60.621
824.153	60.3054
827.535	60.5072
830.915	59.3684
834.292	60.9699
837.67	62.1284
841.047	61.398
844.42	60.2634
847.794	57.6602
851.165	55.4263
854.534	55.3748
857.905	54.4429
861.272	52.59
864.639	49.6585
868.004	47.0774
871.367	47.0349
874.731	44.5997
878.092	43.1445
881.451	42.2949
884.809	40.6464
888.166	45.8951
891.522	43.8198
894.878	44.0555
898.231	42.43
901.583	41.3396
904.934	42.5026
908.283	42.9058
911.631	44.0267
914.976	45.5722
918.322	46.7319
921.666	46.8032
925.009	48.2336
928.351	50.7109
931.692	52.1379
935.029	53.3689
938.367	57.6442
941.704	55.7892
945.038	53.4294
948.372	52.661
951.705	53.0713
955.035	52.8096
958.366	51.0251
961.693	51.8929
965.021	52.8875
968.346	54.7829
971.67	55.5869
974.995	56.2092
978.316	56.3686
981.638	54.4965
984.957	55.8869
988.274	54.4846
991.59	50.506
994.907	46.15
998.221	37.0908
1001.53	29.0993
1004.85	26.8356
1008.16	37.9181
1011.46	65.6237
1014.77	104.151
1018.08	148.172
1021.38	190.942
1024.69	226.95
1027.99	264.964
1031.29	295.386
1034.59	321.511
1037.89	340.886
1041.19	356.049
1044.48	365.544
1047.78	367.717
1051.07	360.72
1054.36	346.54
1057.66	325.915
1060.94	298.686
1064.23	266.393
1067.52	227.431
1070.81	182.863
1074.09	136.699
1077.38	89.1702
1080.66	50.1779
1083.94	25.6546
1087.22	17.3079
1090.5	22.8755
1093.77	33.3703
1097.05	40.8922
1100.32	44.7485
1103.6	49.4015
1106.87	50.0986
1110.14	52.4348
1113.41	51.4955
1116.67	51.0833
1119.94	52.228
1123.21	52.3745
1126.47	52.9644
1129.73	52.1083
1133	48.7003
1136.26	46.0175
1139.52	43.4855
1142.77	38.4983
1146.03	33.24
1149.29	26.9815
1152.54	22.764
1155.79	19.34
1159.04	15.752
1162.3	11.0518
1165.55	9.90208
1168.79	10.6783
1172.04	10.5492
1175.28	10.1147
1178.53	8.12309
1181.77	8.98516
1185.01	9.49543
1188.25	9.87274
1191.49	10.5468
1194.73	13.4004
1197.97	16.2677
1201.2	21.873
1204.44	24.7203
1207.67	29.9219
1210.9	33.1885
1214.13	38.0732
1217.36	45.2674
1220.59	50.4037
1223.82	55.75
1227.04	62.4445
1230.26	71.5773
1233.49	79.1989
1236.71	86.0987
1239.93	92.4854
1243.15	98.7149
1246.37	105.384
1249.58	111.377
1252.8	114.221
1256.01	114.206
1259.23	119.809
1262.44	126.237
1265.65	130.412
1268.86	134.368
1272.07	139.823
1275.27	144.602
1278.48	149.86
1281.68	154.673
1284.89	159.898
1288.09	165.294
1291.29	168.162
1294.49	173.251
1297.69	175.896
1300.88	177.497
1304.08	180.641
1307.27	183.344
1310.47	184.998
1313.66	185.947
1316.85	183.027
1320.04	181.614
1323.23	176.619
1326.41	170.269
1329.6	162.252
1332.78	156.873
1335.97	154.305
1339.15	150.26
1342.33	143.946
1345.51	139.119
1348.69	134.508
1351.87	130.582
1355.04	126.176
1358.22	121.566
1361.39	118.36
1364.57	113.267
1367.74	109.263
1370.91	107.221
1374.07	105.378
1377.24	103.876
1380.41	103.545
1383.57	103.062
1386.74	104.397
1389.9	104.862
1393.06	106.541
1396.22	107.821
1399.38	111.452
1402.54	114.639
1405.7	122.353
1408.85	131.518
1412.01	141.831
1415.16	149.782
1418.31	158.117
1421.46	172.688
1424.61	184.392
1427.76	196.579
1430.91	210.115
1434.05	221.096
1437.2	229.402
1440.34	235.398
1443.49	238.526
1446.63	239.839
1449.77	238.076
1452.91	233.651
1456.04	226.252
1459.18	217.623
1462.31	207.638
1465.45	195.374
1468.58	183.092
1471.71	168.021
1474.84	154.771
1477.97	142.984
1481.1	129.634
1484.23	118.674
1487.35	107.521
1490.48	97.3103
1493.6	87.5717
1496.72	79.7911
1499.84	75.6038
1502.96	70.5681
1506.08	68.8328
1509.2	65.5529
1512.31	59.7966
1515.43	57.9018
1518.54	54.8562
1521.66	53.281
1524.77	53.8476
1527.88	53.3845
1530.99	53.689
1534.09	56.7122
1537.2	61.0768
1540.31	64.8257
1543.41	69.4223
1546.51	73.8258
1549.62	78.6042
1552.72	84.5792
1555.82	89.6059
1558.91	94.6677
1562.01	98.4665
1565.11	103.132
1568.2	106.721
1571.3	110.316
1574.39	116.351
1577.48	121.622
1580.57	125.394
1583.66	128.076
1586.75	131.327
1589.83	134.413
1592.92	136.042
1596	135.446
1599.09	137.431
1602.17	137.79
1605.25	136.955
1608.33	137.913
1611.41	139.073
1614.48	141.126
1617.56	142.545
1620.64	144.345
1623.71	146.648
1626.78	148.341
1629.86	152.247
1632.92	156.449
1635.99	159.74
1639.06	164.071
1642.13	168.583
1645.19	173.344
1648.26	174.923
1651.32	179.927
1654.38	179.778
1657.45	179.708
1660.51	178.392
1663.57	174.394
1666.62	169.083
1669.68	162.137
1672.73	152.269
1675.79	143.672
1678.84	135.155
1681.89	125.738
1684.94	115.211
1687.99	104.939
1691.04	94.6853
1694.09	83.4229
1697.14	74.194
1700.18	64.5132
1703.22	57.1206
1706.27	52.7719
1709.31	45.2329
1712.35	39.5064
1715.39	35.1367
1718.43	30.9533
1721.46	27.5027
1724.5	24.3837
1727.53	21.2002
1730.57	18.8396
1733.6	12.7762
1736.63	12.7845
1739.66	14.6877
1742.69	15.914
1745.72	16.7115
1748.74	17.7524
1751.77	19.8166
1754.8	21.624
1757.82	20.0519
1760.84	19.9198
1763.86	18.8507
1766.88	18.6584
1769.9	17.2479
1772.92	16.8194
1775.93	16.0567
1778.95	16.1582
1781.96	13.98
1784.98	13.0824
1787.99	11.1959
1791	10.2116
1794.01	7.71156
1797.02	5.5703
1800.03	3.6289
1803.03	1.20094
1806.04	-1.25082
1809.04	1.59829
1812.04	1.82017
1815.05	1.18726
1818.05	1.76064
1821.05	2.68688
1824.05	3.33911
1827.04	4.89386
1830.04	6.27236
1833.03	5.85418
1836.03	6.49749
1839.02	8.07347
1842.01	7.5973
1845	6.74161
1847.99	7.50754
1850.98	7.39721
1853.97	8.12359
1856.95	7.01161
1859.94	7.14904
1862.92	6.26338
1865.91	7.01811
1868.89	6.4557
1871.87	6.71889
1874.85	6.02477
1877.83	4.75148
1880.8	4.17592
1882.56	2.72195
1885.54	2.63967
1888.53	4.03476
1891.52	5.5567
1894.5	6.80859
1897.49	8.23261
1900.47	8.93668
1903.45	9.67256
1906.43	8.87681
1909.41	9.16626
1912.39	9.09042
1915.37	8.29581
1918.35	8.57756
1921.32	8.83201
1924.3	8.5689
1927.27	7.37765
1930.24	4.59894
1933.21	4.69699
1936.18	3.43095
1939.15	3.2393
1942.12	3.57332
1945.09	4.26912
1948.05	3.41919
1951.02	2.74274
1953.98	2.82703
1956.94	3.59773
1959.91	3.93475
1962.87	4.51728
1965.82	3.87463
1968.78	5.53665
1971.74	5.0486
1974.7	6.25552
1977.65	7.71331
1980.6	7.02626
1983.56	8.78397
1986.51	10.8547
1989.46	10.3074
1992.41	10.8793
1995.36	10.5277
1998.3	10.6896
2001.25	10.269
2004.2	11.857
2007.14	13.9972
2010.08	14.5067
2013.02	15.8484
2015.97	16.0287
2018.9	17.1128
2021.84	15.6842
2024.78	15.7903
2027.72	15.096
2030.65	13.211
2033.59	13.9712
2036.52	13.0048
2039.45	12.9027
2042.38	13.0184
2045.31	13.3652
2048.24	14.1403
2051.17	13.3918
2054.1	14.9578
2057.02	16.4636
2059.95	18.8383
2062.87	20.9158
2065.79	22.4216
2068.71	25.5975
2071.63	27.074
2074.55	31.9801
2077.47	34.0637
2080.39	35.6646
2083.3	39.319
2086.22	44.1177
2089.13	46.664
2092.05	48.6894
2094.96	49.8644
2097.87	54.4341
2100.78	57.7478
2103.69	62.0107
2106.59	66.9768
2109.5	70.0751
2112.41	75.3515
2115.31	79.2029
2118.21	83.5577
2121.12	89.9226
2124.02	94.7092
2126.92	101.536
2129.82	108.205
2132.71	113.609
2135.61	120.949
2138.51	127.474
2141.4	132.465
2144.29	139.794
2147.19	146.23
2150.08	152.361
2152.97	158.726
2155.86	165.108
2158.75	170.248
2161.64	173.629
2164.52	177.157
2167.41	180.085
2170.29	183.63
2173.17	183.982
2176.06	182.961
2178.94	181.987
2181.82	180.707
2184.7	177.429
2187.57	173.689
2190.45	169.423
2193.33	165.256
2196.2	159.908
2199.08	154.343
2201.95	146.352
2204.82	140.143
2207.69	135.087
2210.56	127.369
2213.43	121.612
2216.3	114.788
2219.16	108.722
2222.03	103.904
2224.89	99.2096
2227.75	95.485
2230.62	90.6489
2233.48	84.6771
2236.34	81.383
2239.2	77.0528
2242.06	73.0002
2244.91	68.6932
2247.77	66.1916
2250.62	62.5487
2253.48	60.2205
2256.33	56.4638
2259.18	53.8896
2262.03	51.4462
2264.88	49.7963
2267.73	47.1426
2270.58	42.8107
2273.43	40.1733
2276.27	37.5748
2279.12	34.71
2281.96	31.4136
2284.8	29.5218
2287.64	28.3216
2290.49	27.185
2293.32	26.1951
2296.16	25.6336
2299	24.0167
2301.84	22.2836
2304.67	21.1335
2307.51	20.4157
2310.34	20.3938
2313.17	19.2358
2316	20.0258
2318.83	19.0074
2321.66	18.3319
2324.49	18.2043
2327.32	17.6734
2330.15	16.4902
2332.97	15.3136
2335.79	14.4347
2338.62	12.6367
2341.44	11.0162
2344.26	10.3167
2347.08	8.66494
2349.9	8.37699
2352.72	7.85697
2355.53	7.31173
2358.35	5.9454
2361.17	2.82884
2363.98	2.01044
2366.79	2.56657
2369.6	2.36023
2372.42	1.7045
2375.22	1.44985
2378.03	2.00072
2380.84	2.59082
2383.65	2.81298
2386.45	3.79142
2389.26	3.32462
2392.06	3.4102
2394.87	4.9789
2397.67	4.05403
2400.47	3.92371
2403.27	3.22993
2406.07	5.50848
2408.86	6.92028
2411.66	7.58389
2414.46	8.08604
2417.25	8.4801
2420.05	9.44216
2422.84	8.47646
2425.63	6.64447
2428.42	6.39284
2431.21	6.58751
2434	6.57142
2436.79	6.59426
2439.57	4.89478
2442.36	4.7879
2445.14	4.50695
2447.93	5.00455
2450.71	5.96846
2453.49	7.7157
2456.27	7.74707
2459.05	9.92412
2461.83	10.8344
2464.61	12.5025
2467.39	12.4093
2470.16	13.399
2472.94	13.9513
2475.71	15.0142
2478.48	15.1488
2481.25	13.948
2484.02	12.5325
2486.8	12.0032
2489.56	10.851
2492.33	8.85323
2495.1	6.87676
2497.86	6.23895
2500.63	4.34817
2503.39	2.87224
2506.16	1.19096
2508.92	0.280011
2511.68	0.900421
2514.44	0.493735
2517.2	0.0234623
2519.95	1.66877
2522.71	3.22099
2525.47	5.053
2528.22	4.64521
2530.98	4.52009
2533.73	5.44767
2536.48	5.83941
2539.23	5.15995
2541.98	4.76146
2544.73	4.73255
2547.48	4.63925
2550.23	4.93825
2552.97	5.36772
2555.72	5.91945
2558.46	6.20977
2561.2	5.87538
2563.95	6.20106
2566.69	8.91419
2569.43	9.81483
2572.17	10.5214
2574.91	11.9388
2577.64	12.2585
2580.38	14.0089
2583.11	14.9485
2585.85	16.0366
2588.58	16.347
2591.31	16.2672
2594.04	15.242
2596.78	14.0562
2599.51	16.2647
2602.23	14.7462
2604.96	12.7574
2607.69	10.8952
2610.41	9.17964
2613.14	9.15061
2615.86	8.09806
2618.58	8.04697
2621.3	6.81431
2624.03	6.01032
2626.75	5.41094
2629.46	6.20985
2632.18	7.66243
2634.9	9.1123
2637.61	9.93887
2640.33	10.6958
2643.04	10.3524
2645.76	11.3804
2648.47	11.6963
2651.18	10.7407
2653.89	9.21044
2656.6	7.70967
2659.31	7.33689
2662.01	7.42035
2664.72	7.20104
2667.43	6.55554
2670.13	5.0128
2672.83	4.43047
2675.53	4.91319
2678.24	5.93196
2680.94	7.11217
2683.64	7.60237
2686.34	7.57735
2689.03	9.31993
2691.73	10.0301
2694.43	12.692
2697.12	15.2484
2699.81	16.7749
2702.51	18.1553
2705.2	19.821
2707.89	20.3444
2710.58	20.9801
2713.27	22.7903
2715.96	21.8912
2718.64	21.565
2721.33	20.6124
2724.01	19.7654
2726.7	19.2318
2729.38	17.842
2732.06	15.9924
2734.75	15.6831
2737.43	14.2417
2740.11	11.6055
2742.78	11.0068
2745.46	9.55676
2748.14	8.12334
2750.81	6.03193
2753.49	3.8185
2756.16	3.7223
2758.84	2.80333
2761.51	1.29552
2764.18	1.5902
2766.85	1.55283
2769.52	0.991802
2772.19	1.67234
2774.85	0.972458
2777.52	1.48204
2780.18	0.448094
2782.85	-0.0354129
2785.51	-1.30044
2788.17	-1.10533
2790.84	-2.69576
2793.5	-2.3917
2796.16	-1.93006
2798.81	-1.78913
2801.47	-1.06048
2804.13	-2.02112
2806.79	-1.61025
2809.44	-1.01002
2812.09	-1.6953
2814.75	-1.14795
2817.4	1.39281
2820.05	7.45876
2822.7	15.2311
2825.35	24.5528
2828	34.5804
2830.65	46.7378
2833.29	58.6042
2835.94	71.339
2838.58	86.0688
2841.23	100.655
2843.87	116.042
2846.51	131.795
2849.15	148.291
2851.79	165.446
2854.43	183.024
2857.07	200.566
2859.71	217.238
2862.34	232.06
2864.98	245.619
2867.61	257.071
2870.25	267.391
2872.88	276.697
2875.51	285.686
2878.14	293.573
2880.77	302.515
2883.4	312.52
2886.03	321.884
2888.65	331.083
2891.28	340.736
2893.91	349.869
2896.53	359.852
2899.15	371.374
2901.78	384.095
2904.4	399.166
2907.02	416.43
2909.64	435.466
2912.26	455.905
2914.87	475.357
2917.49	494.327
2920.11	513.205
2922.72	528.76
2925.34	541.078
2927.95	550.448
2930.56	555.837
2933.17	557.094
2935.78	557.267
2938.39	551.04
2941	541.861
2943.61	528.958
2946.22	513.2
2948.82	495.501
2951.43	474.689
2954.03	452.249
2956.64	427.969
2959.24	404.627
2961.84	379.786
2964.44	355.554
2967.04	333.655
2969.64	314.032
2972.24	295.115
2974.83	275.513
2977.43	255.224
2980.02	234.966
2982.62	216.697
2985.21	199.531
2987.8	180.334
2990.4	163.313
2992.99	145.727
2995.57	130.572
2998.16	115.01
3000.75	101.229
3003.34	86.2188
3005.92	72.8587
3008.51	61.9226
3011.09	51.2858
3013.68	42.1234
3016.26	32.938
3018.84	24.711
3021.42	17.8759
3024	12.0534
3026.58	6.84508
3029.16	5.95017
3031.73	5.04155
3034.31	3.81045
3036.89	3.24674
3039.46	2.92798
3042.03	3.59867
3044.61	3.95488
3047.18	5.70145
3049.75	6.23594
3052.32	7.58165
3054.89	8.01841
3057.45	9.12845
3060.02	8.51374
3062.59	9.00275
3065.15	8.04332
3067.72	7.68929
3070.28	7.62527
3072.84	6.19773
3075.41	5.5287
3077.97	3.40311
3080.53	2.40962
3083.09	1.01892
3085.64	-0.200412
3088.2	-1.23219
3090.76	-1.02743
3093.31	-0.944444
3095.87	-0.556822
3098.42	-1.54356
3100.97	-0.515795
3103.53	-0.658021
3106.08	1.09162
3108.63	1.67159
3111.18	2.79499
3113.73	4.7076
3116.27	5.59855
3118.82	6.97546
3121.37	8.63029
3123.91	10.4633
3126.45	13.8153
3129	15.2939
3131.54	19.1476
3134.08	21.334
3136.62	24.229
3139.16	27.3784
3141.7	30.4948
3144.24	33.9803
3146.78	38.4232
3149.31	44.0672