File: data/Raman/poly_smoothed/Mb_40_y_16_1x_45s_532 nm_x100_100%_600 gr_mm_01.txt
#Acq. time (s)=	45
#Accumulations=	2
#Range (cm-¹)=	200...3150
#Windows=	2
#Auto scanning=	Off
#Autofocus=	Off
#Macrospot=	Off
#AutoExposure=	Off
#Spike filter=	Multiple accum.
#Delay time (s)=	0
#Binning=	1
#Readout mode=	Signal
#DeNoise=	Off
#ICS correction=	On
#Dark correction=	Off
#Inst. Process=	Off
#Detector Gain=	Best Dynamic Range
#Detector ADC=	20 kHz
#Detector temperature (°C)=	-69.85
#Instrument=	LabRAM HR Evol
#Detector=	Synapse
#Objective=	x100
#Grating=	600 gr/mm
#ND Filter=	100%
#Laser (nm)=	532
#Hole=	100.021
#Range=	Auto
#Laser Pol.=	No
#Raman. Pol.=	No
#Laser Pol. (°)=	-0.0007625
#Raman Pol. (°)=	89.9995
#Collection=	Microscope
#StageXY=	Marzhauser
#StageZ=	Marzhauser
#X (µm)=	-1064.4
#Y (µm)=	650.5
#Z (µm)=	584.55
#Full time(mm:ss)=	3:18
#Project=
#Sample=
#Site=
#Title=	Mb_40_y_16_2x_45s_532 nm_x100_100%_600 gr_mm
#Remark=
#Date=	19.07.2022 10:20
#Acquired=	19.07.2022 10:20:52
#Base:Fit=	10.08.2022 10:52:48
#Base:Sub=	10.08.2022 10:52:53
#Filter:Polynom=	16.08.2022 10:09:04
#AxisType[0]=Intens
#AxisUnit[0]=Cnt
#AxisType[1]=Spectr
#AxisUnit[1]=1/cm
200.423	12.8926
204.052	13.9414
207.682	14.774
211.308	13.5177
214.935	11.403
218.558	12.0544
222.18	9.60445
225.802	9.79085
229.421	11.0468
233.039	10.6535
236.657	10.8086
240.272	11.1367
243.885	10.4752
247.497	8.81915
251.11	8.19246
254.719	8.43315
258.327	8.91347
261.933	7.73638
265.538	7.01478
269.141	6.68779
272.744	8.70536
276.344	8.23567
279.944	8.19334
283.542	8.83083
287.138	7.79112
290.733	7.84376
294.327	6.06399
297.919	6.31044
301.508	6.98757
305.098	8.60893
308.686	7.89678
312.273	8.59519
315.858	10.697
319.44	11.5256
323.022	11.9235
326.604	13.3546
330.181	11.5562
333.76	11.1177
337.335	10.6327
340.91	10.4931
344.483	9.29482
348.055	9.42054
351.625	9.55475
355.195	8.43841
358.762	6.72974
362.329	6.20462
365.893	5.06999
369.455	2.437
373.017	2.3688
376.578	1.43237
380.137	1.44523
383.694	1.69645
387.249	2.63125
390.806	3.62738
394.359	4.37546
397.91	5.57732
401.46	7.31615
405.009	7.79924
408.557	9.66026
412.103	10.5736
415.647	10.479
419.191	10.5001
422.733	11.2866
426.273	11.8512
429.812	12.6527
433.35	12.4477
436.885	11.955
440.42	11.2507
443.954	9.9227
447.486	10.4707
451.015	9.72714
454.545	8.97259
458.073	9.18461
461.598	10.4097
465.124	9.71179
468.648	9.70678
472.169	10.9878
475.69	10.8755
479.208	11.4677
482.727	11.5808
486.243	11.8325
489.759	12.0273
493.272	11.7293
496.783	13.6936
500.295	14.2908
503.804	14.984
507.311	15.3738
510.819	16.603
514.324	18.5939
517.827	18.3642
521.329	18.9015
524.83	19.3267
528.329	20.2264
531.829	19.8738
535.326	20.3875
538.821	19.7435
542.315	18.4097
545.808	16.3353
549.299	13.0118
552.789	11.3218
556.278	9.20198
559.763	8.71841
563.249	6.41691
566.733	5.56372
570.217	3.60363
573.699	2.19881
577.177	3.18848
580.656	1.76998
584.134	2.07224
587.609	1.38185
591.084	0.512072
594.558	-0.171033
598.029	1.94394
601.5	2.78532
604.968	3.96022
608.437	6.64586
611.902	8.20005
615.368	9.65787
618.831	10.8539
622.294	12.3933
625.755	12.2803
629.213	12.8134
632.673	13.2134
636.129	15.7496
639.584	15.078
643.037	15.8739
646.491	15.3848
649.942	15.8806
653.392	16.3266
656.84	15.9873
660.287	15.0683
663.732	14.436
667.177	12.6994
670.62	12.7943
674.061	12.1178
677.502	13.1017
680.941	13.845
684.379	15.0491
687.815	18.4868
691.248	19.6391
694.682	23.1222
698.115	25.1046
701.546	28.1417
704.974	31.5005
708.402	33.65
711.83	35.5287
715.254	38.8359
718.679	40.4455
722.102	40.0543
725.522	39.0668
728.943	39.9615
732.361	41.184
735.779	42.2636
739.194	43.9567
742.608	45.2953
746.022	46.401
749.433	48.8055
752.843	50.1687
756.254	53.1213
759.661	55.7181
763.067	58.6574
766.471	61.2722
769.877	64.9624
773.279	67.1245
776.68	68.9786
780.079	71.9734
783.478	73.7332
786.875	74.8513
790.27	76.0988
793.665	76.9308
797.058	75.8251
800.45	75.2591
803.84	73.2601
807.23	72.5502
810.616	71.4942
814.002	72.4959
817.388	72.6934
820.772	72.3017
824.153	72.3702
827.535	71.5003
830.915	71.7396
834.292	71.5682
837.67	71.6977
841.047	69.7503
844.42	70.731
847.794	70.3022
851.165	68.6308
854.534	67.9953
857.905	67.1746
861.272	64.4366
864.639	61.1257
868.004	60.8353
871.367	58.948
874.731	57.3452
878.092	56.5841
881.451	55.7342
884.809	55.6307
888.166	55.4684
891.522	55.9497
894.878	56.0382
898.231	55.6385
901.583	55.1552
904.934	56.4376
908.283	53.8732
911.631	54.0663
914.976	53.2195
918.322	52.716
921.666	51.4218
925.009	51.5166
928.351	51.2812
931.692	48.2936
935.029	47.5322
938.367	45.9973
941.704	44.0656
945.038	43.9349
948.372	42.8022
951.705	44.3653
955.035	43.9817
958.366	45.9002
961.693	46.1987
965.021	47.3996
968.346	47.4914
971.67	47.162
974.995	48.3588
978.316	49.3861
981.638	48.3719
984.957	47.2543
988.274	44.1858
991.59	42.3672
994.907	40.519
998.221	36.8967
1001.53	32.5303
1004.85	28.7022
1008.16	31.3498
1011.46	38.6712
1014.77	52.451
1018.08	68.1549
1021.38	85.0538
1024.69	101.875
1027.99	117.016
1031.29	130.97
1034.59	141.439
1037.89	148.976
1041.19	154.038
1044.48	154.489
1047.78	154.695
1051.07	151.116
1054.36	146.979
1057.66	140.356
1060.94	129.089
1064.23	114.481
1067.52	98.2878
1070.81	82.3272
1074.09	65.2371
1077.38	48.6372
1080.66	33.3715
1083.94	21.9423
1087.22	17.8028
1090.5	20.4338
1093.77	23.7087
1097.05	27.238
1100.32	29.5177
1103.6	31.9834
1106.87	35.8
1110.14	37.4373
1113.41	36.8948
1116.67	34.7839
1119.94	33.318
1123.21	31.4733
1126.47	30.0436
1129.73	28.9842
1133	27.7281
1136.26	26.994
1139.52	25.2475
1142.77	22.6263
1146.03	19.4996
1149.29	16.8645
1152.54	15.0387
1155.79	13.486
1159.04	10.9979
1162.3	9.04401
1165.55	8.82488
1168.79	9.05294
1172.04	9.5843
1175.28	9.43229
1178.53	10.2964
1181.77	12.958
1185.01	14.7516
1188.25	14.3681
1191.49	16.3955
1194.73	15.8429
1197.97	16.6038
1201.2	16.9141
1204.44	17.9618
1207.67	20.5212
1210.9	23.6215
1214.13	27.1267
1217.36	29.7932
1220.59	31.089
1223.82	33.3843
1227.04	35.0531
1230.26	39.5558
1233.49	42.2118
1236.71	44.6955
1239.93	48.5803
1243.15	51.1096
1246.37	53.8406
1249.58	56.1773
1252.8	58.2705
1256.01	61.4714
1259.23	63.1288
1262.44	67.0296
1265.65	68.6593
1268.86	69.1833
1272.07	70.8245
1275.27	70.8108
1278.48	69.8478
1281.68	70.3547
1284.89	72.9883
1288.09	74.0335
1291.29	74.6271
1294.49	73.7716
1297.69	73.7016
1300.88	73.8121
1304.08	73.2764
1307.27	72.9263
1310.47	72.4611
1313.66	72.6042
1316.85	71.2363
1320.04	71.6193
1323.23	71.7187
1326.41	71.6853
1329.6	70.1181
1332.78	68.0458
1335.97	67.2606
1339.15	66.4332
1342.33	64.1633
1345.51	62.1771
1348.69	61.0085
1351.87	58.6521
1355.04	57.5855
1358.22	56.5449
1361.39	54.8892
1364.57	54.5147
1367.74	53.055
1370.91	52.2743
1374.07	50.163
1377.24	48.9003
1380.41	47.5483
1383.57	45.4122
1386.74	45.7003
1389.9	45.65
1393.06	47.2061
1396.22	48.0436
1399.38	48.418
1402.54	48.9948
1405.7	50.2287
1408.85	50.1512
1412.01	53.2357
1415.16	54.7303
1418.31	58.6967
1421.46	62.5106
1424.61	65.4391
1427.76	70.1803
1430.91	75.8441
1434.05	81.7512
1437.2	85.8096
1440.34	88.6878
1443.49	92.207
1446.63	92.7979
1449.77	93.3081
1452.91	92.5429
1456.04	91.43
1459.18	89.1497
1462.31	88.1922
1465.45	85.6943
1468.58	82.4544
1471.71	78.8308
1474.84	74.459
1477.97	69.4763
1481.1	64.3947
1484.23	59.3333
1487.35	54.4202
1490.48	49.8469
1493.6	44.8936
1496.72	40.8203
1499.84	35.9831
1502.96	35.2858
1506.08	34.6802
1509.2	33.6924
1512.31	32.7163
1515.43	30.0062
1518.54	28.1427
1521.66	27.8115
1524.77	27.0492
1527.88	28.7151
1530.99	28.9549
1534.09	29.1579
1537.2	28.9116
1540.31	28.9593
1543.41	29.3482
1546.51	30.3157
1549.62	32.2854
1552.72	32.3504
1555.82	33.299
1558.91	33.4818
1562.01	33.9585
1565.11	34.4296
1568.2	35.8665
1571.3	36.5015
1574.39	38.3036
1577.48	41.3291
1580.57	43.4061
1583.66	45.8481
1586.75	47.8496
1589.83	49.4213
1592.92	50.0911
1596	52.4774
1599.09	52.5875
1602.17	53.3619
1605.25	52.022
1608.33	50.9006
1611.41	49.2151
1614.48	49.8253
1617.56	50.8367
1620.64	52.3061
1623.71	52.644
1626.78	53.7217
1629.86	55.3004
1632.92	56.1833
1635.99	57.402
1639.06	58.9671
1642.13	61.4319
1645.19	62.7854
1648.26	63.8949
1651.32	64.9086
1654.38	64.9687
1657.45	65.4063
1660.51	65.337
1663.57	64.1063
1666.62	62.4632
1669.68	59.5909
1672.73	55.6159
1675.79	50.0266
1678.84	45.1369
1681.89	41.995
1684.94	37.4246
1687.99	34.3766
1691.04	30.3149
1694.09	26.0677
1697.14	21.8653
1700.18	18.9747
1703.22	16.1157
1706.27	12.9104
1709.31	12.5967
1712.35	10.4602
1715.39	9.32376
1718.43	7.35893
1721.46	5.54938
1724.5	4.83581
1727.53	4.41821
1730.57	4.11956
1733.6	3.71396
1736.63	3.76223
1739.66	2.8858
1742.69	2.95457
1745.72	2.13832
1748.74	2.31111
1751.77	3.0135
1754.8	3.15224
1757.82	2.46906
1760.84	1.33044
1763.86	1.3283
1766.88	0.914483
1769.9	0.209294
1772.92	0.391385
1775.93	0.0578635
1778.95	-0.0566561
1781.96	0.503119
1784.98	1.03263
1787.99	0.681236
1791	-0.0579886
1794.01	-0.501715
1797.02	-0.651529
1800.03	-0.12052
1803.03	0.392387
1806.04	-0.190043
1809.04	0.08696
1812.04	0.340345
1815.05	1.21848
1818.05	2.00904
1821.05	1.93591
1824.05	2.65843
1827.04	2.12592
1830.04	0.429889
1833.03	0.969252
1836.03	1.54675
1839.02	1.51662
1842.01	1.45576
1845	1.5409
1847.99	1.61127
1850.98	0.776106
1853.97	0.38195
1856.95	0.601936
1859.94	0.483737
1862.92	0.741962
1865.91	0.87065
1868.89	1.82065
1871.87	1.88394
1874.85	2.56992
1877.83	3.43236
1880.8	3.26135
1882.56	3.51072
1885.54	3.74155
1888.53	3.62044
1891.52	3.7497
1894.5	3.94728
1897.49	3.86545
1900.47	3.3613
1903.45	3.22497
1906.43	4.20434
1909.41	4.3826
1912.39	4.68324
1915.37	4.32189
1918.35	4.18992
1921.32	2.53213
1924.3	3.04163
1927.27	3.35802
1930.24	4.26752
1933.21	4.53461
1936.18	3.80658
1939.15	4.05174
1942.12	4.05999
1945.09	3.90473
1948.05	3.96752
1951.02	5.4691
1953.98	5.0511
1956.94	4.83328
1959.91	4.91529
1962.87	5.02008
1965.82	5.92063
1968.78	5.74632
1971.74	4.28839
1974.7	4.81848
1977.65	4.4425
1980.6	5.20757
1983.56	5.13677
1986.51	4.40149
1989.46	3.13884
1992.41	2.57958
1995.36	2.56817
1998.3	2.42675
2001.25	3.26911
2004.2	3.3331
2007.14	2.80524
2010.08	4.10006
2013.02	4.99565
2015.97	6.52199
2018.9	7.38483
2021.84	10.0352
2024.78	11.7659
2027.72	12.3961
2030.65	12.4253
2033.59	12.8231
2036.52	13.914
2039.45	13.7597
2042.38	13.7735
2045.31	13.576
2048.24	13.4337
2051.17	12.9298
2054.1	14.1448
2057.02	13.2575
2059.95	13.0055
2062.87	12.1771
2065.79	13.0624
2068.71	14.3075
2071.63	14.2579
2074.55	15.7719
2077.47	17.0928
2080.39	17.937
2083.3	19.3216
2086.22	21.3729
2089.13	22.9547
2092.05	24.1044
2094.96	25.2745
2097.87	26.9005
2100.78	27.996
2103.69	29.2218
2106.59	31.8141
2109.5	32.8839
2112.41	35.0002
2115.31	35.767
2118.21	37.8526
2121.12	39.4678
2124.02	43.3878
2126.92	46.0132
2129.82	48.1755
2132.71	51.9545
2135.61	55.5719
2138.51	59.0063
2141.4	61.7388
2144.29	64.7628
2147.19	67.8433
2150.08	70.1252
2152.97	72.6382
2155.86	75.9301
2158.75	78.0562
2161.64	80.2754
2164.52	83.002
2167.41	84.918
2170.29	85.5514
2173.17	85.287
2176.06	84.6785
2178.94	84.4282
2181.82	81.2582
2184.7	79.1363
2187.57	76.7913
2190.45	74.1982
2193.33	72.3164
2196.2	69.9713
2199.08	66.265
2201.95	63.6999
2204.82	60.5494
2207.69	56.477
2210.56	54.6452
2213.43	51.6547
2216.3	49.2052
2219.16	47.3349
2222.03	44.5252
2224.89	43.2254
2227.75	42.5426
2230.62	41.3308
2233.48	39.6023
2236.34	37.2401
2239.2	34.9103
2242.06	32.3406
2244.91	30.0796
2247.77	28.5302
2250.62	28.0509
2253.48	25.8023
2256.33	25.0374
2259.18	23.3426
2262.03	21.9481
2264.88	20.6181
2267.73	19.4076
2270.58	18.0359
2273.43	18.1871
2276.27	18.4289
2279.12	18.7644
2281.96	18.5685
2284.8	18.4802
2287.64	17.897
2290.49	17.1851
2293.32	16.3304
2296.16	17.1202
2299	16.1161
2301.84	16.8171
2304.67	15.8996
2307.51	15.6819
2310.34	15.4887
2313.17	15.2731
2316	15.8637
2318.83	15.5648
2321.66	14.9605
2324.49	14.4759
2327.32	13.0679
2330.15	12.119
2332.97	11.3824
2335.79	11.7619
2338.62	11.3541
2341.44	11.6155
2344.26	11.3992
2347.08	9.73523
2349.9	8.71337
2352.72	9.18042
2355.53	8.19407
2358.35	6.72032
2361.17	6.8978
2363.98	7.22682
2366.79	8.70803
2369.6	9.25164
2372.42	8.10386
2375.22	6.80486
2378.03	6.2198
2380.84	5.45058
2383.65	4.2246
2386.45	3.69196
2389.26	3.40935
2392.06	2.57012
2394.87	1.85983
2397.67	1.68621
2400.47	2.13782
2403.27	3.06602
2406.07	3.43305
2408.86	2.83345
2411.66	2.22069
2414.46	2.30416
2417.25	3.08154
2420.05	4.61501
2422.84	6.28214
2425.63	6.97354
2428.42	8.75826
2431.21	9.5487
2434	10.3926
2436.79	10.5091
2439.57	9.69409
2442.36	9.04141
2445.14	8.73133
2447.93	8.90893
2450.71	8.78859
2453.49	9.16875
2456.27	9.02982
2459.05	9.0942
2461.83	9.21425
2464.61	8.99994
2467.39	8.73985
2470.16	8.07643
2472.94	7.63067
2475.71	7.19631
2478.48	6.24764
2481.25	5.49802
2484.02	5.44855
2486.8	5.20153
2489.56	3.91198
2492.33	3.01505
2495.1	2.66598
2497.86	2.34034
2500.63	1.31301
2503.39	1.82636
2506.16	0.855918
2508.92	0.814009
2511.68	2.00215
2514.44	2.35345
2517.2	3.51264
2519.95	2.99342
2522.71	3.92973
2525.47	4.95785
2528.22	5.95831
2530.98	6.27585
2533.73	6.93423
2536.48	7.62569
2539.23	7.88262
2541.98	8.59693
2544.73	8.47518
2547.48	8.53721
2550.23	9.82479
2552.97	9.04639
2555.72	7.44413
2558.46	7.01249
2561.2	7.58595
2563.95	7.05171
2566.69	6.08886
2569.43	5.92535
2572.17	5.41006
2574.91	4.58431
2577.64	4.76007
2580.38	4.33877
2583.11	3.26043
2585.85	2.35102
2588.58	2.43313
2591.31	2.5501
2594.04	1.72305
2596.78	1.70314
2599.51	1.47125
2602.23	1.82751
2604.96	1.96189
2607.69	2.36127
2610.41	3.12229
2613.14	3.46332
2615.86	3.96391
2618.58	4.16244
2621.3	4.30077
2624.03	4.97173
2626.75	4.92274
2629.46	5.02604
2632.18	4.40617
2634.9	5.31579
2637.61	5.90806
2640.33	5.87758
2643.04	6.15869
2645.76	5.71396
2648.47	5.20427
2651.18	4.84999
2653.89	5.40798
2656.6	5.16222
2659.31	5.38532
2662.01	5.39917
2664.72	5.34058
2667.43	5.03515
2670.13	5.23079
2672.83	4.73147
2675.53	5.18766
2678.24	5.51534
2680.94	5.8076
2683.64	6.59269
2686.34	7.35154
2689.03	7.58307
2691.73	7.592
2694.43	8.9465
2697.12	8.77768
2699.81	8.93866
2702.51	9.65299
2705.2	9.9446
2707.89	10.113
2710.58	10.3493
2713.27	10.0745
2715.96	10.015
2718.64	9.87773
2721.33	9.6195
2724.01	9.91492
2726.7	9.64071
2729.38	8.73301
2732.06	8.1563
2734.75	7.7566
2737.43	7.04531
2740.11	7.51028
2742.78	7.53403
2745.46	8.30308
2748.14	9.08612
2750.81	8.75359
2753.49	8.19987
2756.16	8.61878
2758.84	8.31669
2761.51	7.01099
2764.18	7.02762
2766.85	7.11334
2769.52	7.32292
2772.19	7.22334
2774.85	5.60216
2777.52	5.51197
2780.18	4.6164
2782.85	3.49716
2785.51	1.72922
2788.17	1.95593
2790.84	1.18935
2793.5	0.276718
2796.16	-0.898725
2798.81	-0.923576
2801.47	-0.749604
2804.13	-1.41893
2806.79	-1.2999
2809.44	-0.445406
2812.09	-0.491002
2814.75	0.882167
2817.4	2.10807
2820.05	6.13675
2822.7	9.58668
2825.35	13.4064
2828	19.0595
2830.65	24.6798
2833.29	29.6652
2835.94	35.0708
2838.58	40.7423
2841.23	46.8268
2843.87	52.9043
2846.51	58.3791
2849.15	64.5782
2851.79	72.129
2854.43	79.5256
2857.07	85.8864
2859.71	92.0966
2862.34	98.6001
2864.98	104.066
2867.61	108.041
2870.25	112.085
2872.88	116.587
2875.51	120.671
2878.14	123.844
2880.77	126.529
2883.4	128.938
2886.03	131.557
2888.65	133.178
2891.28	135.856
2893.91	138.499
2896.53	140.631
2899.15	142.632
2901.78	146.593
2904.4	150.446
2907.02	155.524
2909.64	161.063
2912.26	167.652
2914.87	174.008
2917.49	180.45
2920.11	185.878
2922.72	190.043
2925.34	194.403
2927.95	197.55
2930.56	198.819
2933.17	198.635
2935.78	198.178
2938.39	195.949
2941	192.316
2943.61	187.907
2946.22	182.297
2948.82	176.035
2951.43	168.839
2954.03	161.034
2956.64	153.114
2959.24	144.738
2961.84	136.551
2964.44	129.177
2967.04	122.773
2969.64	115.89
2972.24	109.045
2974.83	102.124
2977.43	94.0725
2980.02	86.9059
2982.62	79.9228
2985.21	73.3527
2987.8	65.8013
2990.4	59.742
2992.99	53.2307
2995.57	46.5059
2998.16	41.466
3000.75	35.9469
3003.34	30.9901
3005.92	28.1823
3008.51	23.871
3011.09	20.3065
3013.68	17.1476
3016.26	15.2651
3018.84	13.338
3021.42	12.6312
3024	11.8863
3026.58	11.1319
3029.16	10.2942
3031.73	10.6457
3034.31	9.96454
3036.89	10.2538
3039.46	10.8195
3042.03	11.8516
3044.61	13.1511
3047.18	13.2908
3049.75	12.3912
3052.32	11.7938
3054.89	10.9381
3057.45	9.9021
3060.02	9.8842
3062.59	9.46851
3065.15	8.86447
3067.72	8.93815
3070.28	9.23796
3072.84	8.96697
3075.41	7.56223
3077.97	6.79819
3080.53	6.03709
3083.09	4.38619
3085.64	3.7935
3088.2	2.6004
3090.76	1.87711
3093.31	2.01199
3095.87	2.26915
3098.42	2.30682
3100.97	3.31262
3103.53	3.56696
3106.08	3.76571
3108.63	3.50628
3111.18	2.86925
3113.73	3.08673
3116.27	3.10025
3118.82	4.00735
3121.37	4.77654
3123.91	6.13378
3126.45	6.50889
3129	7.93899
3131.54	8.89984
3134.08	9.32213
3136.62	9.58802
3139.16	9.98908
3141.7	10.8095
3144.24	11.8021
3146.78	13.485
3149.31	15.313