File: data/Raman/poly_smoothed/Mb_40_y_34_1x_45s_532 nm_x100_100%_600 gr_mm_01.txt
#Acq. time (s)=	45
#Accumulations=	2
#Range (cm-¹)=	200...3150
#Windows=	2
#Auto scanning=	Off
#Autofocus=	Off
#Macrospot=	Off
#AutoExposure=	Off
#Spike filter=	Multiple accum.
#Delay time (s)=	0
#Binning=	1
#Readout mode=	Signal
#DeNoise=	Off
#ICS correction=	On
#Dark correction=	Off
#Inst. Process=	Off
#Detector Gain=	Best Dynamic Range
#Detector ADC=	20 kHz
#Detector temperature (°C)=	-69.85
#Instrument=	LabRAM HR Evol
#Detector=	Synapse
#Objective=	x100
#Grating=	600 gr/mm
#ND Filter=	100%
#Laser (nm)=	532
#Hole=	100.021
#Range=	Auto
#Laser Pol.=	No
#Raman. Pol.=	No
#Laser Pol. (°)=	-0.0007625
#Raman Pol. (°)=	89.9995
#Collection=	Microscope
#StageXY=	Marzhauser
#StageZ=	Marzhauser
#X (µm)=	-1110.8
#Y (µm)=	584.4
#Z (µm)=	584.15
#Full time(mm:ss)=	3:18
#Project=
#Sample=
#Site=
#Title=	Mb_40_y_34_2x_45s_532 nm_x100_100%_600 gr_mm
#Remark=
#Date=	19.07.2022 12:11
#Acquired=	19.07.2022 12:11:53
#Base:Fit=	10.08.2022 10:52:48
#Base:Sub=	10.08.2022 10:52:53
#Filter:Polynom=	16.08.2022 10:09:04
#AxisType[0]=Intens
#AxisUnit[0]=Cnt
#AxisType[1]=Spectr
#AxisUnit[1]=1/cm
200.423	16.8008
204.052	11.4075
207.682	7.84251
211.308	5.92887
214.935	3.11638
218.558	0.651423
222.18	1.34668
225.802	2.85228
229.421	2.93225
233.039	4.53841
236.657	6.61761
240.272	7.23431
243.885	8.59056
247.497	8.10911
251.11	10.2935
254.719	11.7685
258.327	13.1156
261.933	14.7409
265.538	16.985
269.141	16.9933
272.744	17.8312
276.344	18.8327
279.944	17.5902
283.542	18.5945
287.138	18.2257
290.733	17.8469
294.327	16.8358
297.919	16.7767
301.508	16.4096
305.098	16.3542
308.686	17.7093
312.273	19.5894
315.858	19.8423
319.44	20.4869
323.022	20.1408
326.604	20.5034
330.181	19.995
333.76	20.5811
337.335	20.42
340.91	20.8069
344.483	21.3768
348.055	22.5398
351.625	23.3214
355.195	22.7725
358.762	20.8078
362.329	20.3805
365.893	18.3242
369.455	18.5328
373.017	18.3053
376.578	17.5874
380.137	15.859
383.694	15.6404
387.249	15.7831
390.806	14.1946
394.359	13.6511
397.91	13.048
401.46	13.0267
405.009	12.0514
408.557	10.086
412.103	8.9604
415.647	8.73122
419.191	7.76166
422.733	7.55481
426.273	6.99978
429.812	6.33671
433.35	5.61388
436.885	4.64574
440.42	3.9984
443.954	3.73408
447.486	4.9423
451.015	6.1565
454.545	7.21113
458.073	9.5069
461.598	9.67829
465.124	8.88665
468.648	8.80039
472.169	9.50923
475.69	9.23828
479.208	10.7471
482.727	13.1817
486.243	14.3771
489.759	14.4914
493.272	15.4275
496.783	14.9927
500.295	15.9746
503.804	16.4076
507.311	16.4922
510.819	16.1933
514.324	14.4252
517.827	13.496
521.329	10.3033
524.83	10.7967
528.329	12.5371
531.829	12.6339
535.326	12.3617
538.821	10.6123
542.315	9.10274
545.808	7.61038
549.299	6.00311
552.789	4.66083
556.278	3.57312
559.763	3.07633
563.249	3.56399
566.733	4.4584
570.217	3.57508
573.699	3.97275
577.177	4.06575
580.656	4.48646
584.134	5.37449
587.609	5.53665
591.084	6.14104
594.558	6.20522
598.029	4.5323
601.5	4.2188
604.968	4.16467
608.437	4.50782
611.902	5.04091
615.368	4.39497
618.831	4.59334
622.294	5.24742
625.755	5.22213
629.213	5.82025
632.673	5.06091
636.129	5.40243
639.584	5.03061
643.037	4.98469
646.491	4.49102
649.942	4.78691
653.392	4.15712
656.84	3.9978
660.287	4.5071
663.732	4.48754
667.177	4.391
670.62	5.05139
674.061	7.67182
677.502	8.88366
680.941	9.69116
684.379	11.9583
687.815	12.4947
691.248	13.4805
694.682	15.454
698.115	16.1775
701.546	19.0192
704.974	21.6334
708.402	24.6476
711.83	25.5132
715.254	25.3773
718.679	27.3289
722.102	30.207
725.522	29.7097
728.943	31.0494
732.361	31.6762
735.779	32.9428
739.194	34.6547
742.608	36.5939
746.022	37.5279
749.433	40.4406
752.843	44.0771
756.254	47.7887
759.661	50.8963
763.067	52.4579
766.471	54.6743
769.877	55.5636
773.279	57.2155
776.68	58.8996
780.079	61.5636
783.478	62.8352
786.875	65.8916
790.27	67.2791
793.665	68.8576
797.058	69.2222
800.45	70.6585
803.84	71.8507
807.23	71.3019
810.616	69.8707
814.002	69.3913
817.388	70.1
820.772	69.6366
824.153	68.8428
827.535	66.3085
830.915	67.52
834.292	66.1783
837.67	64.2247
841.047	61.9019
844.42	59.1407
847.794	56.3479
851.165	53.8755
854.534	51.5249
857.905	50.0081
861.272	48.1057
864.639	46.1539
868.004	46.3046
871.367	45.5086
874.731	43.6869
878.092	41.6286
881.451	41.2563
884.809	39.9687
888.166	39.6608
891.522	38.6815
894.878	37.4593
898.231	37.0034
901.583	36.7933
904.934	35.8262
908.283	38.4877
911.631	40.6494
914.976	42.2593
918.322	42.9847
921.666	43.6414
925.009	42.1915
928.351	42.7041
931.692	42.0957
935.029	40.085
938.367	40.6258
941.704	40.2015
945.038	39.3565
948.372	38.357
951.705	36.8588
955.035	33.3438
958.366	31.747
961.693	29.7033
965.021	29.3664
968.346	25.7896
971.67	23.721
974.995	21.1303
978.316	19.2015
981.638	18.6669
984.957	18.7281
988.274	18.5889
991.59	17.7966
994.907	15.767
998.221	13.3374
1001.53	9.99251
1004.85	7.70795
1008.16	8.99649
1011.46	13.6383
1014.77	20.2189
1018.08	28.5607
1021.38	37.2793
1024.69	46.2143
1027.99	54.7461
1031.29	59.8519
1034.59	65.8252
1037.89	69.8305
1041.19	72.5815
1044.48	74.5967
1047.78	73.893
1051.07	72.4503
1054.36	70.54
1057.66	66.1319
1060.94	60.4615
1064.23	54.0055
1067.52	45.0189
1070.81	36.6322
1074.09	28.2073
1077.38	19.3537
1080.66	8.87695
1083.94	2.63196
1087.22	2.98447
1090.5	6.16206
1093.77	9.26656
1097.05	11.6985
1100.32	14.5807
1103.6	17.9863
1106.87	17.9901
1110.14	18.0211
1113.41	19.2607
1116.67	20.4322
1119.94	20.4295
1123.21	21.2514
1126.47	20.683
1129.73	20.8739
1133	19.8504
1136.26	18.7293
1139.52	15.7923
1142.77	13.8295
1146.03	13.333
1149.29	11.5867
1152.54	8.70696
1155.79	5.80399
1159.04	2.45551
1162.3	1.20153
1165.55	3.21076
1168.79	4.35054
1172.04	4.33242
1175.28	4.20912
1178.53	3.43921
1181.77	4.63377
1185.01	3.04426
1188.25	3.29589
1191.49	4.08654
1194.73	6.68315
1197.97	8.0735
1201.2	9.01001
1204.44	10.873
1207.67	11.886
1210.9	12.472
1214.13	15.1056
1217.36	15.8221
1220.59	16.5507
1223.82	18.223
1227.04	17.1342
1230.26	17.8853
1233.49	18.4409
1236.71	19.6632
1239.93	21.376
1243.15	22.7217
1246.37	23.7291
1249.58	25.7968
1252.8	27.7504
1256.01	27.4175
1259.23	28.699
1262.44	30.6091
1265.65	30.617
1268.86	32.0417
1272.07	32.6895
1275.27	33.4508
1278.48	34.4424
1281.68	35.7788
1284.89	36.4773
1288.09	37.34
1291.29	38.5764
1294.49	38.9599
1297.69	40.3382
1300.88	42.0015
1304.08	42.1007
1307.27	42.1802
1310.47	44.7382
1313.66	45.1273
1316.85	44.4414
1320.04	45.9877
1323.23	45.8226
1326.41	46.1883
1329.6	44.1896
1332.78	41.0724
1335.97	42.3488
1339.15	43.2184
1342.33	43.5237
1345.51	41.9547
1348.69	41.5303
1351.87	41.3543
1355.04	41.3724
1358.22	40.411
1361.39	38.9674
1364.57	37.3515
1367.74	36.1559
1370.91	34.9473
1374.07	34.271
1377.24	34.5883
1380.41	32.6892
1383.57	30.4226
1386.74	28.1441
1389.9	27.8334
1393.06	27.6492
1396.22	26.7957
1399.38	27.6654
1402.54	27.1293
1405.7	26.2424
1408.85	24.7132
1412.01	29.0691
1415.16	32.4194
1418.31	34.1088
1421.46	35.7491
1424.61	37.9874
1427.76	40.851
1430.91	44.219
1434.05	46.2851
1437.2	48.3838
1440.34	49.8951
1443.49	50.0905
1446.63	50.2606
1449.77	50.639
1452.91	49.3525
1456.04	48.0403
1459.18	45.8495
1462.31	45.2075
1465.45	44.5926
1468.58	44.3
1471.71	42.6371
1474.84	41.5472
1477.97	39.0979
1481.1	37.412
1484.23	35.1073
1487.35	33.2573
1490.48	31.2795
1493.6	29.4775
1496.72	28.9554
1499.84	27.9119
1502.96	29.1567
1506.08	28.4317
1509.2	25.81
1512.31	24.7248
1515.43	23.1314
1518.54	21.9346
1521.66	20.18
1524.77	18.5804
1527.88	17.3156
1530.99	15.9275
1534.09	16.0349
1537.2	15.4917
1540.31	15.7491
1543.41	15.8956
1546.51	16.7924
1549.62	17.7938
1552.72	18.1202
1555.82	18.8252
1558.91	19.2385
1562.01	20.4525
1565.11	22.0617
1568.2	22.8092
1571.3	23.4016
1574.39	25.0287
1577.48	26.2758
1580.57	28.3744
1583.66	26.5262
1586.75	27.1008
1589.83	28.8061
1592.92	29.4057
1596	29.8956
1599.09	30.6345
1602.17	30.3498
1605.25	29.7211
1608.33	30.007
1611.41	29.7792
1614.48	30.2333
1617.56	31.1103
1620.64	32.5502
1623.71	34.1539
1626.78	34.6149
1629.86	35.6019
1632.92	36.3329
1635.99	37.3963
1639.06	37.7024
1642.13	37.3262
1645.19	37.4904
1648.26	39.5694
1651.32	41.7509
1654.38	41.7185
1657.45	41.5132
1660.51	40.8249
1663.57	40.082
1666.62	39.69
1669.68	38.9392
1672.73	37.0172
1675.79	33.9946
1678.84	30.4693
1681.89	27.8602
1684.94	24.802
1687.99	21.1565
1691.04	18.8552
1694.09	16.2092
1697.14	14.5584
1700.18	12.9214
1703.22	10.9072
1706.27	8.43216
1709.31	6.4741
1712.35	4.77117
1715.39	4.16037
1718.43	4.05518
1721.46	3.96713
1724.5	4.13254
1727.53	3.7839
1730.57	3.64385
1733.6	3.81833
1736.63	4.49775
1739.66	4.94851
1742.69	5.67591
1745.72	4.82356
1748.74	4.4675
1751.77	4.31152
1754.8	4.66974
1757.82	3.56013
1760.84	3.02899
1763.86	2.61239
1766.88	2.97205
1769.9	2.41454
1772.92	2.41779
1775.93	1.69721
1778.95	0.479125
1781.96	1.04024
1784.98	0.431521
1787.99	0.591657
1791	0.828658
1794.01	0.290346
1797.02	0.599772
1800.03	0.728142
1803.03	-0.262314
1806.04	0.460537
1809.04	0.804217
1812.04	1.21691
1815.05	1.37681
1818.05	1.47695
1821.05	1.31948
1824.05	1.90158
1827.04	2.13123
1830.04	2.22751
1833.03	2.14701
1836.03	2.50379
1839.02	2.80679
1842.01	3.58364
1845	3.20201
1847.99	2.80684
1850.98	3.04926
1853.97	3.56176
1856.95	2.71825
1859.94	2.53648
1862.92	2.38741
1865.91	2.40728
1868.89	3.10464
1871.87	2.99478
1874.85	2.34281
1877.83	2.31532
1880.8	1.89411
1882.56	0.840722
1885.54	0.26955
1888.53	0.308161
1891.52	0.384181
1894.5	1.52398
1897.49	1.55028
1900.47	1.75451
1903.45	1.84924
1906.43	2.77726
1909.41	3.23417
1912.39	3.91808
1915.37	3.814
1918.35	3.07876
1921.32	2.73698
1924.3	3.03257
1927.27	3.3986
1930.24	3.16241
1933.21	3.63051
1936.18	3.9496
1939.15	3.85091
1942.12	3.62862
1945.09	2.88688
1948.05	3.09037
1951.02	2.42938
1953.98	2.29028
1956.94	2.01066
1959.91	3.62639
1962.87	4.2992
1965.82	5.11031
1968.78	5.48469
1971.74	5.35681
1974.7	6.15048
1977.65	6.68152
1980.6	7.51726
1983.56	7.91125
1986.51	7.91356
1989.46	8.4874
1992.41	8.27143
1995.36	7.84563
1998.3	8.31987
2001.25	8.20168
2004.2	8.53979
2007.14	8.12278
2010.08	7.11623
2013.02	6.41146
2015.97	6.51398
2018.9	6.38217
2021.84	6.33679
2024.78	5.17084
2027.72	6.71284
2030.65	7.15189
2033.59	7.0009
2036.52	6.75844
2039.45	7.2237
2042.38	7.94399
2045.31	8.3773
2048.24	8.6946
2051.17	8.9585
2054.1	9.40417
2057.02	10.1312
2059.95	10.8233
2062.87	11.3335
2065.79	10.7104
2068.71	11.794
2071.63	13.2644
2074.55	14.0039
2077.47	14.7293
2080.39	15.0705
2083.3	15.1497
2086.22	16.5212
2089.13	17.4192
2092.05	18.9199
2094.96	19.5187
2097.87	20.6747
2100.78	21.9648
2103.69	23.3161
2106.59	24.2147
2109.5	24.7954
2112.41	25.5681
2115.31	27.4123
2118.21	29.0679
2121.12	30.7519
2124.02	31.6669
2126.92	33.262
2129.82	35.3435
2132.71	37.3861
2135.61	38.9897
2138.51	41.341
2141.4	44.2543
2144.29	46.5622
2147.19	48.9177
2150.08	51.4028
2152.97	53.5938
2155.86	54.5005
2158.75	56.1105
2161.64	58.3541
2164.52	58.5679
2167.41	59.8403
2170.29	60.9294
2173.17	61.45
2176.06	61.0023
2178.94	59.9251
2181.82	59.7345
2184.7	59.2661
2187.57	58.4326
2190.45	57.2831
2193.33	55.5854
2196.2	53.3082
2199.08	51.2756
2201.95	50.3201
2204.82	48.1329
2207.69	45.7516
2210.56	44.4706
2213.43	42.8343
2216.3	40.9351
2219.16	39.0663
2222.03	36.3982
2224.89	34.3099
2227.75	32.9045
2230.62	31.3478
2233.48	29.12
2236.34	27.6147
2239.2	25.8028
2242.06	24.3738
2244.91	22.6019
2247.77	21.4713
2250.62	19.8619
2253.48	19.0082
2256.33	18.5681
2259.18	17.681
2262.03	16.5599
2264.88	16.0289
2267.73	16.7008
2270.58	16.072
2273.43	15.8839
2276.27	14.9745
2279.12	14.7135
2281.96	15.2684
2284.8	14.4221
2287.64	13.9136
2290.49	13.0669
2293.32	11.0922
2296.16	11.0933
2299	11.0886
2301.84	10.8474
2304.67	11.5546
2307.51	11.8607
2310.34	12.6164
2313.17	13.2104
2316	13.0589
2318.83	12.5076
2321.66	12.4568
2324.49	12.861
2327.32	13.4742
2330.15	13.1683
2332.97	13.0576
2335.79	12.4135
2338.62	11.7255
2341.44	10.5681
2344.26	9.7636
2347.08	9.17508
2349.9	7.701
2352.72	6.1349
2355.53	4.12042
2358.35	2.77959
2361.17	1.27102
2363.98	1.3774
2366.79	2.01115
2369.6	2.32258
2372.42	2.33313
2375.22	2.03657
2378.03	2.52974
2380.84	3.34353
2383.65	3.31977
2386.45	3.39422
2389.26	3.72602
2392.06	3.9937
2394.87	3.85381
2397.67	3.34423
2400.47	2.64537
2403.27	3.13159
2406.07	2.93849
2408.86	3.49134
2411.66	3.37451
2414.46	4.14477
2417.25	3.85647
2420.05	3.57555
2422.84	4.03155
2425.63	4.15433
2428.42	4.8579
2431.21	5.06143
2434	5.61584
2436.79	6.5989
2439.57	7.46284
2442.36	8.23739
2445.14	8.79147
2447.93	8.89537
2450.71	9.27527
2453.49	8.75524
2456.27	8.68396
2459.05	8.13811
2461.83	7.46365
2464.61	7.11522
2467.39	7.84821
2470.16	8.09794
2472.94	8.1925
2475.71	7.94499
2478.48	8.86197
2481.25	8.39716
2484.02	8.31907
2486.8	7.76102
2489.56	7.5656
2492.33	7.82299
2495.1	8.04294
2497.86	8.02212
2500.63	8.37034
2503.39	7.69214
2506.16	7.96906
2508.92	7.2318
2511.68	6.46332
2514.44	5.65184
2517.2	4.80454
2519.95	4.96245
2522.71	4.3905
2525.47	4.1252
2528.22	3.8484
2530.98	4.14427
2533.73	3.88971
2536.48	3.78777
2539.23	4.31809
2541.98	4.83094
2544.73	5.22388
2547.48	5.74397
2550.23	6.18389
2552.97	6.76654
2555.72	6.6144
2558.46	6.80274
2561.2	6.85624
2563.95	7.50079
2566.69	7.42139
2569.43	6.73273
2572.17	6.01072
2574.91	5.63694
2577.64	4.77531
2580.38	3.41882
2583.11	3.21163
2585.85	2.94314
2588.58	2.40825
2591.31	1.30851
2594.04	0.629906
2596.78	0.696414
2599.51	0.899951
2602.23	0.398523
2604.96	0.913352
2607.69	1.63151
2610.41	2.60595
2613.14	2.74112
2615.86	3.42405
2618.58	3.48018
2621.3	2.87598
2624.03	3.16843
2626.75	3.8573
2629.46	4.47305
2632.18	4.5008
2634.9	4.97747
2637.61	4.83159
2640.33	4.74248
2643.04	4.87951
2645.76	5.1304
2648.47	4.98414
2651.18	5.19803
2653.89	5.06942
2656.6	4.57364
2659.31	5.04489
2662.01	5.11032
2664.72	4.81138
2667.43	4.48893
2670.13	5.13121
2672.83	5.31996
2675.53	5.18194
2678.24	5.43256
2680.94	4.61627
2683.64	4.55578
2686.34	4.37667
2689.03	4.39689
2691.73	4.97268
2694.43	4.70761
2697.12	4.23829
2699.81	3.84532
2702.51	3.50126
2705.2	3.47847
2707.89	3.45809
2710.58	3.78384
2713.27	3.297
2715.96	3.73809
2718.64	3.49997
2721.33	3.61897
2724.01	2.99929
2726.7	2.60969
2729.38	2.29318
2732.06	1.9776
2734.75	1.8064
2737.43	1.08877
2740.11	1.1866
2742.78	1.27537
2745.46	0.666526
2748.14	0.658685
2750.81	0.612841
2753.49	0.753172
2756.16	0.353532
2758.84	0.0729727
2761.51	-0.231742
2764.18	-0.504276
2766.85	-0.173048
2769.52	-0.135768
2772.19	-0.0166996
2774.85	0.319366
2777.52	0.895893
2780.18	1.26161
2782.85	1.2037
2785.51	0.992043
2788.17	0.897174
2790.84	0.897306
2793.5	0.75488
2796.16	0.863807
2798.81	0.384949
2801.47	0.655016
2804.13	1.07094
2806.79	0.547285
2809.44	-0.504993
2812.09	-0.6287
2814.75	-0.179923
2817.4	-0.391844
2820.05	1.68897
2822.7	4.0734
2825.35	5.4314
2828	7.90068
2830.65	10.454
2833.29	13.4368
2835.94	16.8823
2838.58	20.2226
2841.23	23.2906
2843.87	26.5425
2846.51	30.2461
2849.15	34.1066
2851.79	38.6883
2854.43	42.3481
2857.07	46.8565
2859.71	50.5105
2862.34	54.4906
2864.98	57.1565
2867.61	60.2076
2870.25	61.7224
2872.88	63.7656
2875.51	65.9345
2878.14	68.5923
2880.77	70.4568
2883.4	73.0964
2886.03	75.011
2888.65	76.8686
2891.28	79.2301
2893.91	81.5379
2896.53	83.1657
2899.15	86.5283
2901.78	89.5097
2904.4	91.7346
2907.02	95.6236
2909.64	100.208
2912.26	105.087
2914.87	110.787
2917.49	115.992
2920.11	120.451
2922.72	123.978
2925.34	127.151
2927.95	128.86
2930.56	129.694
2933.17	130.347
2935.78	129.346
2938.39	128.417
2941	127.042
2943.61	124.45
2946.22	120.055
2948.82	115.913
2951.43	111.517
2954.03	106.275
2956.64	101.178
2959.24	95.638
2961.84	90.0666
2964.44	85.3489
2967.04	79.9051
2969.64	75.7066
2972.24	71.6387
2974.83	67.3243
2977.43	62.6837
2980.02	58.119
2982.62	52.97
2985.21	48.2871
2987.8	43.1339
2990.4	38.1758
2992.99	33.0207
2995.57	28.7057
2998.16	25.0201
3000.75	21.229
3003.34	18.371
3005.92	14.9159
3008.51	11.8012
3011.09	9.27071
3013.68	7.67571
3016.26	5.58312
3018.84	3.27684
3021.42	2.20437
3024	1.60939
3026.58	1.43394
3029.16	1.24597
3031.73	1.20347
3034.31	1.39972
3036.89	2.08105
3039.46	2.40799
3042.03	2.45025
3044.61	3.21379
3047.18	3.47636
3049.75	3.93716
3052.32	4.2342
3054.89	4.71008
3057.45	4.81103
3060.02	4.9459
3062.59	4.35184
3065.15	3.93032
3067.72	3.46203
3070.28	3.42237
3072.84	3.08263
3075.41	3.64196
3077.97	2.70972
3080.53	1.80971
3083.09	1.25842
3085.64	0.714134
3088.2	0.734904
3090.76	0.649704
3093.31	0.337372
3095.87	1.12249
3098.42	0.851582
3100.97	0.496345
3103.53	1.06562
3106.08	1.86372
3108.63	2.16241
3111.18	2.76975
3113.73	3.27738
3116.27	3.65761
3118.82	3.71334
3121.37	3.64245
3123.91	4.25173
3126.45	4.73983
3129	5.35043
3131.54	6.00145
3134.08	6.91284
3136.62	8.03973
3139.16	8.12616
3141.7	8.14192
3144.24	8.54232
3146.78	8.52354
3149.31	8.23395