File: data/Raman/poly_smoothed/Mb_40_y_06_1x_45s_532 nm_x100_100%_600 gr_mm_01.txt
#Acq. time (s)=	45
#Accumulations=	2
#Range (cm-¹)=	200...3150
#Windows=	2
#Auto scanning=	Off
#Autofocus=	Off
#Macrospot=	Off
#AutoExposure=	Off
#Spike filter=	Multiple accum.
#Delay time (s)=	0
#Binning=	1
#Readout mode=	Signal
#DeNoise=	Off
#ICS correction=	On
#Dark correction=	Off
#Inst. Process=	Off
#Detector Gain=	Best Dynamic Range
#Detector ADC=	20 kHz
#Detector temperature (°C)=	-69.85
#Instrument=	LabRAM HR Evol
#Detector=	Synapse
#Objective=	x100
#Grating=	600 gr/mm
#ND Filter=	100%
#Laser (nm)=	532
#Hole=	100.021
#Range=	Auto
#Laser Pol.=	No
#Raman. Pol.=	No
#Laser Pol. (°)=	-0.0007625
#Raman Pol. (°)=	89.9995
#Collection=	Microscope
#StageXY=	Marzhauser
#StageZ=	Marzhauser
#X (µm)=	-1054.1
#Y (µm)=	689.3
#Z (µm)=	584.15
#Full time(mm:ss)=	3:18
#Project=
#Sample=
#Site=
#Title=	Mb_40_y_06_2x_45s_532 nm_x100_100%_600 gr_mm
#Remark=
#Date=	19.07.2022 09:14
#Acquired=	19.07.2022 09:14:20
#Base:Fit=	10.08.2022 10:52:48
#Base:Sub=	10.08.2022 10:52:53
#Filter:Polynom=	16.08.2022 10:09:04
#AxisType[0]=Intens
#AxisUnit[0]=Cnt
#AxisType[1]=Spectr
#AxisUnit[1]=1/cm
200.423	53.5146
204.052	52.0856
207.682	45.466
211.308	38.6578
214.935	32.7245
218.558	27.9254
222.18	22.5605
225.802	17.8818
229.421	14.7072
233.039	12.6867
236.657	10.1419
240.272	8.99622
243.885	8.14995
247.497	7.62596
251.11	7.97812
254.719	9.07243
258.327	10.6547
261.933	10.1062
265.538	10.4536
269.141	11.0693
272.744	11.6937
276.344	11.3465
279.944	14.5836
283.542	15.1609
287.138	14.9216
290.733	13.6786
294.327	14.866
297.919	15.197
301.508	14.2274
305.098	13.3461
308.686	11.5761
312.273	12.3758
315.858	11.4525
319.44	12.5688
323.022	12.839
326.604	12.3432
330.181	14.1674
333.76	13.6224
337.335	13.8178
340.91	14.7015
344.483	12.2295
348.055	10.0068
351.625	8.87844
355.195	7.96531
358.762	8.25432
362.329	8.61401
365.893	8.83001
369.455	8.76514
373.017	8.86405
376.578	8.63785
380.137	11.4004
383.694	11.0109
387.249	9.04119
390.806	9.25242
394.359	10.4203
397.91	10.8213
401.46	10.061
405.009	9.44987
408.557	10.6862
412.103	10.3058
415.647	10.1039
419.191	9.90852
422.733	9.10104
426.273	7.24552
429.812	5.69756
433.35	3.06813
436.885	2.57793
440.42	1.14073
443.954	1.53523
447.486	2.07483
451.015	1.85462
454.545	1.85599
458.073	0.955644
461.598	1.76595
465.124	3.3854
468.648	5.41297
472.169	5.39998
475.69	5.95845
479.208	7.37945
482.727	8.2054
486.243	9.127
489.759	12.2444
493.272	13.3177
496.783	15.8438
500.295	17.2517
503.804	18.8397
507.311	20.7807
510.819	20.8119
514.324	19.7876
517.827	18.6593
521.329	17.6315
524.83	17.4257
528.329	15.922
531.829	15.5598
535.326	13.1923
538.821	11.8417
542.315	11.0726
545.808	10.6788
549.299	9.62454
552.789	9.36632
556.278	6.971
559.763	6.65993
563.249	6.0706
566.733	6.00832
570.217	5.16822
573.699	5.10478
577.177	5.69429
580.656	4.52355
584.134	6.66087
587.609	5.42958
591.084	5.89012
594.558	6.13492
598.029	7.14677
601.5	6.89194
604.968	7.01735
608.437	6.974
611.902	7.17723
615.368	8.03354
618.831	10.0484
622.294	11.8351
625.755	13.4918
629.213	14.5136
632.673	14.6627
636.129	15.5237
639.584	14.0126
643.037	14.8553
646.491	15.5873
649.942	15.3679
653.392	13.7502
656.84	13.9676
660.287	13.3422
663.732	13.6834
667.177	13.3556
670.62	13.732
674.061	15.6973
677.502	17.2592
680.941	20.0388
684.379	20.9742
687.815	21.6889
691.248	22.2129
694.682	24.3154
698.115	27.322
701.546	28.7936
704.974	30.4085
708.402	31.7971
711.83	34.0132
715.254	35.0603
718.679	35.7557
722.102	36.9084
725.522	38.4361
728.943	38.9536
732.361	40.3275
735.779	40.3209
739.194	40.1149
742.608	39.9233
746.022	40.5797
749.433	42.7266
752.843	44.0333
756.254	46.9195
759.661	49.2528
763.067	51.3697
766.471	54.528
769.877	55.7451
773.279	56.3161
776.68	58.8533
780.079	61.8056
783.478	63.0902
786.875	65.3445
790.27	66.3328
793.665	68.0802
797.058	68.3741
800.45	70.4683
803.84	72.3462
807.23	72.1225
810.616	70.4514
814.002	69.4204
817.388	69.423
820.772	66.8336
824.153	65.7449
827.535	64.7381
830.915	64.9445
834.292	64.0507
837.67	63.8687
841.047	62.3736
844.42	60.7531
847.794	59.5122
851.165	58.7768
854.534	56.6045
857.905	55.3744
861.272	51.1602
864.639	48.9555
868.004	46.8188
871.367	45.1223
874.731	43.7674
878.092	42.9886
881.451	42.583
884.809	43.895
888.166	43.8794
891.522	42.0404
894.878	41.7726
898.231	43.2857
901.583	42.5474
904.934	41.0295
908.283	42.5325
911.631	41.6491
914.976	42.4952
918.322	44.0742
921.666	44.0845
925.009	41.7954
928.351	41.2591
931.692	40.4055
935.029	40.1727
938.367	37.9618
941.704	36.5414
945.038	36.7892
948.372	36.9435
951.705	36.0854
955.035	36.9366
958.366	38.2584
961.693	39.5418
965.021	41.3942
968.346	42.0236
971.67	42.716
974.995	43.2916
978.316	44.4258
981.638	44.1
984.957	43.3394
988.274	43.2352
991.59	42.2397
994.907	41.0358
998.221	38.5267
1001.53	33.5724
1004.85	28.8144
1008.16	29.4703
1011.46	36.9514
1014.77	51.5837
1018.08	65.2223
1021.38	81.3897
1024.69	95.2673
1027.99	109.54
1031.29	120.975
1034.59	131.452
1037.89	138.639
1041.19	144.823
1044.48	147.213
1047.78	148.123
1051.07	145.504
1054.36	139.958
1057.66	133.393
1060.94	124.951
1064.23	112.916
1067.52	99.5505
1070.81	83.6469
1074.09	67.846
1077.38	51.082
1080.66	34.9779
1083.94	24.68
1087.22	19.1005
1090.5	20.5467
1093.77	24.8713
1097.05	27.6401
1100.32	29.2101
1103.6	28.775
1106.87	30.3033
1110.14	29.8958
1113.41	28.1148
1116.67	26.3027
1119.94	24.6463
1123.21	22.1779
1126.47	19.515
1129.73	17.0377
1133	13.6788
1136.26	12.096
1139.52	12.6136
1142.77	10.0389
1146.03	8.69972
1149.29	7.33081
1152.54	4.4489
1155.79	3.78017
1159.04	2.63342
1162.3	1.76854
1165.55	2.13729
1168.79	2.81704
1172.04	3.93662
1175.28	5.14043
1178.53	4.70054
1181.77	5.91698
1185.01	8.0651
1188.25	9.65244
1191.49	9.03953
1194.73	10.3379
1197.97	12.5703
1201.2	14.2981
1204.44	15.3809
1207.67	18.7475
1210.9	22.084
1214.13	25.9904
1217.36	29.9798
1220.59	34.0117
1223.82	36.4011
1227.04	39.5067
1230.26	42.931
1233.49	45.3837
1236.71	48.1261
1239.93	50.448
1243.15	51.3118
1246.37	54.5351
1249.58	54.7874
1252.8	57.4317
1256.01	58.3441
1259.23	59.25
1262.44	61.907
1265.65	63.4088
1268.86	64.9001
1272.07	65.8942
1275.27	67.4551
1278.48	69.2127
1281.68	70.6402
1284.89	72.5473
1288.09	74.9465
1291.29	77.2265
1294.49	78.5869
1297.69	79.2716
1300.88	79.7243
1304.08	80.3845
1307.27	81.3852
1310.47	80.7556
1313.66	80.3722
1316.85	80.7045
1320.04	78.5688
1323.23	79.0123
1326.41	76.5187
1329.6	74.8855
1332.78	73.6243
1335.97	70.7063
1339.15	68.5506
1342.33	63.9826
1345.51	60.2616
1348.69	57.8925
1351.87	54.6202
1355.04	51.4938
1358.22	48.2561
1361.39	45.7638
1364.57	42.3337
1367.74	39.5011
1370.91	37.1975
1374.07	35.4948
1377.24	33.9366
1380.41	33.7302
1383.57	32.063
1386.74	33.6792
1389.9	34.2741
1393.06	36.6165
1396.22	38.992
1399.38	40.6576
1402.54	43.0092
1405.7	45.5487
1408.85	49.0408
1412.01	51.8889
1415.16	55.3429
1418.31	58.1967
1421.46	64.0834
1424.61	70.6864
1427.76	74.694
1430.91	79.1013
1434.05	82.4809
1437.2	85.3205
1440.34	87.7584
1443.49	90.2717
1446.63	91.0287
1449.77	91.2173
1452.91	89.0606
1456.04	86.3495
1459.18	84.1803
1462.31	82.7132
1465.45	79.3776
1468.58	73.68
1471.71	69.4363
1474.84	63.3056
1477.97	56.6396
1481.1	51.7778
1484.23	46.4958
1487.35	42.8857
1490.48	38.4367
1493.6	36.2793
1496.72	34.0952
1499.84	31.74
1502.96	30.2035
1506.08	27.8821
1509.2	28.6445
1512.31	27.6274
1515.43	27.3141
1518.54	27.9301
1521.66	27.9369
1524.77	28.2374
1527.88	29.1561
1530.99	29.6415
1534.09	30.8491
1537.2	32.3787
1540.31	33.9447
1543.41	34.2164
1546.51	34.8951
1549.62	35.4788
1552.72	34.4048
1555.82	35.3813
1558.91	36.9585
1562.01	38.7665
1565.11	40.5179
1568.2	40.5355
1571.3	43.6682
1574.39	45.1976
1577.48	47.1103
1580.57	49.0076
1583.66	51.5038
1586.75	53.046
1589.83	54.4679
1592.92	55.8776
1596	56.9211
1599.09	57.8615
1602.17	59.0379
1605.25	56.5699
1608.33	57.1109
1611.41	56.9819
1614.48	56.8489
1617.56	55.8571
1620.64	56.3088
1623.71	57.8844
1626.78	59.6666
1629.86	62.4807
1632.92	66.2665
1635.99	69.8576
1639.06	71.4624
1642.13	74.3622
1645.19	77.2219
1648.26	79.4553
1651.32	81.6605
1654.38	83.462
1657.45	84.5938
1660.51	84.0453
1663.57	82.6126
1666.62	81.2666
1669.68	78.1683
1672.73	73.9808
1675.79	68.9868
1678.84	62.6847
1681.89	57.8046
1684.94	52.7496
1687.99	46.3721
1691.04	41.3797
1694.09	36.3426
1697.14	33.163
1700.18	29.4447
1703.22	25.4657
1706.27	21.5553
1709.31	19.2316
1712.35	16.8241
1715.39	14.5467
1718.43	13.1555
1721.46	11.0487
1724.5	10.5882
1727.53	9.64729
1730.57	9.25571
1733.6	7.99022
1736.63	6.70745
1739.66	6.56123
1742.69	7.02721
1745.72	7.04247
1748.74	7.69234
1751.77	8.22517
1754.8	9.48955
1757.82	9.03465
1760.84	8.34639
1763.86	6.90262
1766.88	7.13516
1769.9	5.9705
1772.92	4.48015
1775.93	4.05032
1778.95	3.78488
1781.96	3.71266
1784.98	3.6459
1787.99	3.70882
1791	2.38951
1794.01	1.5963
1797.02	1.95356
1800.03	2.14292
1803.03	1.75128
1806.04	1.48662
1809.04	1.48023
1812.04	2.0794
1815.05	3.4573
1818.05	3.42342
1821.05	4.23236
1824.05	4.74937
1827.04	4.27013
1830.04	4.78383
1833.03	5.50716
1836.03	5.15737
1839.02	4.72313
1842.01	4.61846
1845	4.44209
1847.99	5.07885
1850.98	6.02666
1853.97	6.04463
1856.95	6.15413
1859.94	7.21988
1862.92	7.48795
1865.91	7.21409
1868.89	8.26239
1871.87	8.37099
1874.85	8.22268
1877.83	8.77587
1880.8	8.32815
1882.56	8.95027
1885.54	9.18215
1888.53	9.12964
1891.52	9.05621
1894.5	9.35621
1897.49	9.59307
1900.47	10.3387
1903.45	10.1169
1906.43	9.77877
1909.41	9.44582
1912.39	9.09084
1915.37	8.66759
1918.35	7.42574
1921.32	7.75832
1924.3	7.69818
1927.27	7.62056
1930.24	8.55955
1933.21	7.16964
1936.18	6.59277
1939.15	5.81393
1942.12	5.41492
1945.09	4.10058
1948.05	3.42882
1951.02	3.64414
1953.98	2.97866
1956.94	3.15244
1959.91	3.79001
1962.87	4.44992
1965.82	5.4234
1968.78	5.06796
1971.74	4.20361
1974.7	3.3923
1977.65	2.56593
1980.6	2.66706
1983.56	2.01306
1986.51	2.0575
1989.46	2.80423
1992.41	3.44283
1995.36	4.36785
1998.3	4.21091
2001.25	4.74178
2004.2	4.97779
2007.14	6.0778
2010.08	7.28421
2013.02	7.93538
2015.97	8.39998
2018.9	7.83001
2021.84	8.92203
2024.78	8.85766
2027.72	9.41407
2030.65	10.1372
2033.59	10.1455
2036.52	11.2108
2039.45	11.244
2042.38	11.3248
2045.31	11.7873
2048.24	12.7913
2051.17	13.4187
2054.1	14.1513
2057.02	14.9333
2059.95	15.8055
2062.87	15.9869
2065.79	16.7688
2068.71	17.4606
2071.63	17.2632
2074.55	19.2462
2077.47	22.1224
2080.39	23.5541
2083.3	23.9118
2086.22	24.3731
2089.13	25.7029
2092.05	25.6701
2094.96	26.5687
2097.87	28.9488
2100.78	30.9385
2103.69	33.4119
2106.59	36.8891
2109.5	40.1292
2112.41	42.3511
2115.31	45.7117
2118.21	47.4006
2121.12	49.5269
2124.02	52.4585
2126.92	54.739
2129.82	58.1719
2132.71	59.6871
2135.61	61.5486
2138.51	65.6702
2141.4	69.0242
2144.29	73.006
2147.19	78.0988
2150.08	81.6219
2152.97	83.4821
2155.86	86.8418
2158.75	90.2563
2161.64	91.6874
2164.52	94.9489
2167.41	97.1553
2170.29	98.4174
2173.17	100.624
2176.06	100.88
2178.94	101.292
2181.82	99.7067
2184.7	97.775
2187.57	94.9656
2190.45	92.7395
2193.33	90.1008
2196.2	87.5135
2199.08	85.5449
2201.95	82.5619
2204.82	79.0173
2207.69	77.6836
2210.56	74.6472
2213.43	70.8953
2216.3	67.8688
2219.16	64.1463
2222.03	60.9315
2224.89	57.9652
2227.75	55.163
2230.62	51.1057
2233.48	48.7746
2236.34	46.3055
2239.2	43.6359
2242.06	40.9151
2244.91	37.9779
2247.77	34.4144
2250.62	32.8559
2253.48	31.0884
2256.33	28.939
2259.18	27.4631
2262.03	26.4543
2264.88	25.5303
2267.73	24.501
2270.58	22.5395
2273.43	21.653
2276.27	20.7074
2279.12	18.5652
2281.96	17.2267
2284.8	16.2277
2287.64	14.6611
2290.49	13.8809
2293.32	11.9504
2296.16	11.4168
2299	12.1745
2301.84	12.9943
2304.67	14.3708
2307.51	15.0397
2310.34	16.0916
2313.17	16.5382
2316	16.5732
2318.83	17.4006
2321.66	16.9571
2324.49	16.8407
2327.32	15.9021
2330.15	16.3408
2332.97	14.9538
2335.79	13.8504
2338.62	12.1046
2341.44	11.4928
2344.26	10.7461
2347.08	9.19554
2349.9	7.49837
2352.72	5.03599
2355.53	2.84349
2358.35	1.30947
2361.17	0.310537
2363.98	0.643071
2366.79	1.67222
2369.6	2.52315
2372.42	2.78525
2375.22	3.80139
2378.03	4.90051
2380.84	5.03276
2383.65	6.20933
2386.45	6.29045
2389.26	6.20018
2392.06	7.13532
2394.87	7.21883
2397.67	6.98584
2400.47	7.2686
2403.27	7.27373
2406.07	8.05836
2408.86	8.52793
2411.66	9.03918
2414.46	8.7122
2417.25	8.58543
2420.05	8.52767
2422.84	8.65698
2425.63	8.54913
2428.42	9.33674
2431.21	10.0883
2434	10.7473
2436.79	11.8654
2439.57	12.4475
2442.36	12.4745
2445.14	12.6699
2447.93	12.9575
2450.71	12.7321
2453.49	12.4407
2456.27	12.1653
2459.05	12.3163
2461.83	12.6677
2464.61	11.2566
2467.39	11.0542
2470.16	10.269
2472.94	9.05973
2475.71	8.67562
2478.48	8.25789
2481.25	6.87335
2484.02	6.20643
2486.8	4.48407
2489.56	4.0727
2492.33	3.05708
2495.1	2.03158
2497.86	1.75077
2500.63	2.00929
2503.39	0.872487
2506.16	0.818379
2508.92	0.329149
2511.68	0.770332
2514.44	2.46531
2517.2	2.87772
2519.95	3.37164
2522.71	4.0157
2525.47	4.70448
2528.22	5.27018
2530.98	5.87774
2533.73	5.3095
2536.48	5.89811
2539.23	6.33777
2541.98	6.93822
2544.73	7.44488
2547.48	7.98561
2550.23	7.66183
2552.97	8.33678
2555.72	8.68104
2558.46	8.19219
2561.2	7.23299
2563.95	7.00774
2566.69	8.37285
2569.43	8.13153
2572.17	8.17537
2574.91	9.07375
2577.64	9.95615
2580.38	9.64366
2583.11	8.73805
2585.85	7.54236
2588.58	6.45562
2591.31	5.45669
2594.04	4.85206
2596.78	3.14006
2599.51	2.6249
2602.23	2.59557
2604.96	1.82902
2607.69	1.10528
2610.41	0.286805
2613.14	-0.271356
2615.86	-0.345857
2618.58	-0.869137
2621.3	-0.988898
2624.03	-1.7569
2626.75	-1.73178
2629.46	-0.285735
2632.18	0.150817
2634.9	0.775462
2637.61	1.65886
2640.33	3.00707
2643.04	3.91215
2645.76	4.28948
2648.47	5.38895
2651.18	5.67593
2653.89	6.38719
2656.6	6.43148
2659.31	6.78637
2662.01	6.90589
2664.72	6.75288
2667.43	6.99266
2670.13	7.45539
2672.83	5.92305
2675.53	5.49852
2678.24	5.11733
2680.94	5.60018
2683.64	3.95352
2686.34	4.21384
2689.03	3.84277
2691.73	3.02644
2694.43	3.17584
2697.12	3.08566
2699.81	2.60731
2702.51	3.37821
2705.2	2.968
2707.89	3.67964
2710.58	4.56921
2713.27	4.8415
2715.96	5.71976
2718.64	5.78379
2721.33	5.84028
2724.01	5.46568
2726.7	5.49353
2729.38	6.24439
2732.06	6.38825
2734.75	6.44296
2737.43	5.32512
2740.11	6.3037
2742.78	7.23029
2745.46	7.61284
2748.14	8.79336
2750.81	8.60462
2753.49	8.62358
2756.16	8.11172
2758.84	7.69335
2761.51	7.47949
2764.18	8.23821
2766.85	7.20216
2769.52	7.3453
2772.19	7.11743
2774.85	6.44329
2777.52	6.1326
2780.18	5.50108
2782.85	4.43535
2785.51	3.64294
2788.17	3.15144
2790.84	2.8046
2793.5	1.54799
2796.16	0.397379
2798.81	-0.796193
2801.47	-1.4609
2804.13	-1.60047
2806.79	-0.961456
2809.44	-1.1688
2812.09	-0.424149
2814.75	0.0529247
2817.4	0.973093
2820.05	3.26433
2822.7	5.5779
2825.35	7.93702
2828	11.5247
2830.65	14.2688
2833.29	18.134
2835.94	21.9833
2838.58	26.5522
2841.23	30.8239
2843.87	35.6558
2846.51	40.6129
2849.15	45.9533
2851.79	52.9766
2854.43	58.4646
2857.07	64.0187
2859.71	69.3151
2862.34	75.3269
2864.98	80.9838
2867.61	85.2284
2870.25	89.6074
2872.88	93.6448
2875.51	97.4589
2878.14	101.71
2880.77	105.7
2883.4	109.188
2886.03	112.042
2888.65	115.414
2891.28	119.961
2893.91	124.174
2896.53	129.11
2899.15	134.514
2901.78	139.928
2904.4	146.29
2907.02	154.227
2909.64	163.139
2912.26	173.961
2914.87	183.603
2917.49	194.86
2920.11	203.085
2922.72	211.613
2925.34	219.674
2927.95	225.492
2930.56	229.217
2933.17	232.425
2935.78	233.825
2938.39	234.439
2941	232.335
2943.61	228.881
2946.22	223.132
2948.82	216.623
2951.43	209.294
2954.03	201.807
2956.64	192.613
2959.24	183.343
2961.84	173.88
2964.44	163.62
2967.04	155.572
2969.64	147.087
2972.24	137.764
2974.83	130.08
2977.43	121.586
2980.02	112.684
2982.62	103.571
2985.21	95.4348
2987.8	88.2612
2990.4	80.9576
2992.99	73.9903
2995.57	66.7986
2998.16	60.8465
3000.75	55.3095
3003.34	47.6162
3005.92	42.2354
3008.51	35.9765
3011.09	31.2577
3013.68	26.548
3016.26	23.7482
3018.84	21.0348
3021.42	18.2419
3024	16.1014
3026.58	15.2358
3029.16	13.9831
3031.73	13.1576
3034.31	11.6852
3036.89	11.2203
3039.46	10.5486
3042.03	10.4039
3044.61	11.1298
3047.18	12.0647
3049.75	13.1731
3052.32	13.8422
3054.89	13.9251
3057.45	13.2708
3060.02	13.0102
3062.59	12.7071
3065.15	10.9717
3067.72	9.60084
3070.28	9.02609
3072.84	7.3639
3075.41	6.9899
3077.97	4.96163
3080.53	3.33414
3083.09	2.47901
3085.64	1.02892
3088.2	1.60618
3090.76	1.373
3093.31	0.771386
3095.87	0.221827
3098.42	-0.205861
3100.97	-0.0210016
3103.53	-0.132455
3106.08	1.20153
3108.63	2.01694
3111.18	1.45145
3113.73	2.52651
3116.27	3.24215
3118.82	3.36254
3121.37	3.98717
3123.91	5.06885
3126.45	6.18289
3129	6.65706
3131.54	7.02084
3134.08	8.11859
3136.62	8.523
3139.16	10.448
3141.7	11.6655
3144.24	14.2665
3146.78	16.2539
3149.31	17.9076