File: data/Raman/poly_smoothed/Mb_40_24_45_1x_45s_532 nm_x100_100%_600 gr_mm_01.txt
#Acq. time (s)=	45
#Accumulations=	2
#Range (cm-¹)=	200...3150
#Windows=	2
#Auto scanning=	Off
#Autofocus=	Off
#Macrospot=	Off
#AutoExposure=	Off
#Spike filter=	Multiple accum.
#Delay time (s)=	0
#Binning=	1
#Readout mode=	Signal
#DeNoise=	Off
#ICS correction=	On
#Dark correction=	Off
#Inst. Process=	Off
#Detector Gain=	Best Dynamic Range
#Detector ADC=	20 kHz
#Detector temperature (°C)=	-70.08
#Instrument=	LabRAM HR Evol
#Detector=	Synapse
#Objective=	x100
#Grating=	600 gr/mm
#ND Filter=	100%
#Laser (nm)=	532
#Hole=	100.021
#Range=	Auto
#Laser Pol.=	No
#Raman. Pol.=	No
#Laser Pol. (°)=	-0.0007625
#Raman Pol. (°)=	89.9995
#Collection=	Microscope
#StageXY=	Marzhauser
#StageZ=	Marzhauser
#X (µm)=	-2470.6
#Y (µm)=	-28.8
#Z (µm)=	-10.25
#Full time(mm:ss)=	3:19
#Project=
#Sample=
#Site=
#Title=	Mb_40_24_45_2x_45s_532 nm_x100_100%_600 gr_mm
#Remark=
#Date=	14.07.2022 14:12
#Acquired=	14.07.2022 14:12:06
#Base:Fit=	10.08.2022 10:47:00
#Base:Sub=	10.08.2022 10:47:12
#Filter:Polynom=	16.08.2022 10:11:48
#AxisType[0]=Intens
#AxisUnit[0]=Cnt
#AxisType[1]=Spectr
#AxisUnit[1]=1/cm
200.554	22.6019
204.183	17.1851
207.813	15.4571
211.439	13.1821
215.065	11.3729
218.688	8.95048
222.312	7.02573
225.933	6.17053
229.552	6.02808
233.171	3.99119
236.787	3.80219
240.402	4.95625
244.015	5.4701
247.627	5.36462
251.24	5.83862
254.849	5.9994
258.457	5.81244
262.063	7.65361
265.668	8.05307
269.271	9.77689
272.873	9.40944
276.474	10.3747
280.073	10.2703
283.671	12.8182
287.268	12.0622
290.863	14.7898
294.456	15.913
298.049	15.4925
301.637	16.9402
305.227	18.1735
308.815	17.8253
312.402	19.3193
315.987	19.2682
319.569	19.6101
323.151	19.3074
326.733	21.2988
330.31	19.4085
333.889	17.8247
337.464	15.6814
341.039	12.969
344.611	10.1362
348.184	9.82493
351.754	9.70147
355.324	9.14209
358.89	8.51165
362.455	7.01921
366.021	8.54788
369.584	8.52817
373.145	10.491
376.707	11.7457
380.265	13.7162
383.822	13.916
387.378	15.9058
390.934	19.5058
394.487	19.8217
398.038	19.7321
401.588	21.0844
405.137	23.1791
408.685	23.8599
412.23	26.298
415.775	23.962
419.318	22.6776
422.86	21.6136
426.401	21.1528
429.94	20.9167
433.478	23.4735
437.012	24.085
440.547	23.178
444.081	21.7187
447.613	20.674
451.142	20.2448
454.672	20.7294
458.2	20.7009
461.725	19.2605
465.251	18.4554
468.775	18.3448
472.296	18.8248
475.817	19.3924
479.335	18.3982
482.854	18.5498
486.37	17.9073
489.886	18.7998
493.398	18.9533
496.91	19.1944
500.422	18.89
503.93	19.3773
507.438	22.1424
510.946	23.8717
514.45	25.7368
517.954	27.6845
521.456	29.83
524.956	30.7524
528.456	31.0914
531.956	29.9527
535.452	29.9921
538.947	29.6562
542.441	29.0117
545.934	26.9337
549.425	25.3219
552.915	25.8527
556.403	25.9505
559.889	25.0064
563.375	23.3391
566.859	20.7375
570.342	18.3677
573.824	15.1919
577.303	13.6337
580.782	13.0857
584.26	13.7514
587.734	11.7546
591.21	13.0392
594.684	12.2987
598.154	12.0152
601.626	11.0291
605.094	11.1209
608.562	9.2649
612.027	7.25986
615.493	8.88852
618.956	5.5962
622.419	5.93961
625.879	3.53084
629.338	2.89692
632.797	3.11055
636.254	4.07768
639.708	4.19183
643.162	5.1147
646.614	4.00326
650.067	3.60858
653.516	3.12522
656.964	2.76134
660.411	3.20836
663.857	2.54953
667.301	4.01199
670.744	4.3105
674.186	6.03373
677.626	6.07966
681.065	6.90476
684.503	7.00766
687.939	7.53238
691.372	7.76467
694.806	8.47698
698.239	12.4809
701.67	13.1363
705.098	14.1482
708.526	16.16
711.954	16.0487
715.378	17.3013
718.802	16.444
722.226	17.889
725.646	17.1498
729.067	16.8165
732.484	14.3334
735.902	14.2923
739.317	14.6353
742.731	16.0653
746.145	18.0642
749.556	19.9839
752.966	23.8276
756.377	26.7064
759.784	30.5273
763.19	32.6973
766.594	36.7948
770	39.9461
773.402	41.3185
776.803	44.2871
780.202	47.7443
783.6	50.3394
786.997	52.9606
790.393	54.792
793.787	54.9326
797.18	54.2729
800.572	53.2755
803.963	53.5394
807.35	52.1045
810.738	49.2294
814.125	47.8088
817.51	48.1826
820.894	48.5065
824.275	47.5491
827.657	47.6377
831.037	47.296
834.414	46.837
837.792	48.3301
841.167	47.0741
844.542	46.7289
847.914	43.9273
851.287	42.2088
854.656	39.1962
858.026	37.6289
861.393	36.3621
864.761	35.2052
868.125	34.4093
871.489	31.5717
874.85	30.8469
878.213	31.1421
881.572	31.1327
884.931	30.1657
888.287	29.6075
891.643	29.2978
894.997	29.6245
898.352	27.9278
901.704	29.8096
905.055	30.5574
908.404	29.6296
911.75	30.7893
915.097	30.2609
918.443	30.449
921.787	31.0989
925.13	30.6491
928.472	30.1365
931.813	28.5888
935.15	27.7451
938.488	27.8074
941.825	28.6552
945.158	26.2477
948.493	26.6865
951.824	25.5029
955.156	24.7852
958.486	24.6486
961.814	25.4865
965.142	25.4666
968.467	26.0313
971.79	25.2006
975.115	23.5666
978.436	22.5045
981.756	21.4404
985.077	20.4894
988.394	17.6409
991.71	16.0129
995.025	13.1177
998.341	11.9083
1001.65	10.6912
1004.97	7.95153
1008.28	8.18881
1011.58	10.4734
1014.89	13.8339
1018.2	17.7151
1021.5	21.9385
1024.81	26.3115
1028.11	28.8332
1031.41	34.4063
1034.71	40.9931
1038.01	44.0591
1041.31	47.4111
1044.6	51
1047.9	51.7344
1051.19	53.1049
1054.48	52.0173
1057.77	50.8714
1061.06	49.095
1064.35	45.1956
1067.64	41.0123
1070.93	36.325
1074.21	31.7422
1077.49	28.5067
1080.78	24.8879
1084.06	20.6641
1087.34	17.2024
1090.61	17.9234
1093.89	17.6836
1097.17	16.5599
1100.44	18.6659
1103.71	17.6315
1106.99	19.98
1110.26	22.2584
1113.52	23.7701
1116.79	23.2956
1120.06	23.3011
1123.32	23.5732
1126.59	23.2132
1129.85	23.9964
1133.11	24.0968
1136.37	22.0888
1139.63	20.907
1142.89	18.823
1146.15	17.0214
1149.4	15.0393
1152.66	13.3678
1155.91	11.7188
1159.16	8.82667
1162.41	6.20133
1165.66	4.91031
1168.91	3.65695
1172.16	2.27276
1175.4	1.30593
1178.65	-0.913273
1181.89	-0.949741
1185.13	0.841472
1188.37	4.71679
1191.61	5.61506
1194.85	6.64212
1198.08	7.70934
1201.32	9.97144
1204.55	11.9138
1207.79	14.8755
1211.02	17.2134
1214.25	19.2248
1217.48	20.1528
1220.71	24.6156
1223.93	28.476
1227.16	29.1997
1230.38	31.7588
1233.6	34.7434
1236.83	38.948
1240.05	42.5186
1243.26	47.4332
1246.48	48.871
1249.7	48.9602
1252.92	50.8558
1256.13	53.8335
1259.34	58.3858
1262.55	62.149
1265.76	66.5143
1268.97	70.0996
1272.18	74.0473
1275.39	76.8784
1278.59	80.1428
1281.8	82.2494
1285	85.1778
1288.2	87.1644
1291.4	88.8078
1294.6	89.1801
1297.8	90.1778
1301	90.4961
1304.19	90.4757
1307.39	88.4272
1310.58	88.0568
1313.77	88.3944
1316.96	85.8945
1320.15	82.3452
1323.34	80.7778
1326.53	77.2259
1329.72	74.2347
1332.9	72.4581
1336.08	71.0485
1339.27	68.4772
1342.45	67.7431
1345.63	68.8225
1348.8	69.9102
1351.98	69.4872
1355.16	70.0332
1358.33	70.9913
1361.51	72.7502
1364.68	72.0114
1367.85	70.4164
1371.02	70.6108
1374.19	69.6029
1377.36	69.1186
1380.52	69.3532
1383.69	68.3603
1386.85	67.444
1390.02	68.6656
1393.18	67.7627
1396.34	66.2264
1399.5	66.2073
1402.65	66.3651
1405.81	69.244
1408.97	70.8962
1412.12	74.0904
1415.27	80.5689
1418.43	88.1975
1421.58	94.3016
1424.73	98.947
1427.87	105.357
1431.02	113.732
1434.17	119.068
1437.31	123.296
1440.46	124.82
1443.6	125.296
1446.74	126.958
1449.88	126.273
1453.02	123.613
1456.16	119.623
1459.29	114.375
1462.43	107.518
1465.56	101.163
1468.69	93.2773
1471.83	84.982
1474.95	76.5025
1478.08	70.4915
1481.21	62.9809
1484.34	55.6701
1487.47	48.978
1490.59	45.6127
1493.71	40.7991
1496.84	36.8543
1499.96	33.3153
1503.07	30.4949
1506.19	30.6666
1509.31	30.5018
1512.43	28.2892
1515.54	26.7945
1518.65	27.8391
1521.77	28.1286
1524.88	29.4026
1527.99	30.2635
1531.1	33.0681
1534.21	33.8355
1537.31	34.6638
1540.42	37.9932
1543.52	40.3715
1546.63	43.1012
1549.73	44.9548
1552.83	46.9383
1555.93	49.1898
1559.03	48.9538
1562.12	51.6692
1565.22	52.7501
1568.31	54.7727
1571.41	55.8295
1574.5	57.2261
1577.59	60.1393
1580.68	62.2681
1583.77	64.3316
1586.86	65.0693
1589.95	65.883
1593.03	67.0679
1596.11	67.9186
1599.2	68.104
1602.28	67.6763
1605.36	68.304
1608.44	68.716
1611.52	69.8673
1614.6	71.4181
1617.67	72.3206
1620.75	73.2656
1623.82	75.5952
1626.89	75.6206
1629.96	76.5806
1633.04	77.0294
1636.11	77.7106
1639.17	78.0848
1642.24	78.4196
1645.31	79.3339
1648.37	79.5357
1651.43	80.3282
1654.5	80.329
1657.56	77.7131
1660.62	76.0049
1663.67	74.5108
1666.73	70.7032
1669.79	67.9454
1672.84	64.4861
1675.9	60.1241
1678.95	56.4016
1682	51.1909
1685.05	46.6223
1688.1	41.6275
1691.15	37.0569
1694.2	33.5204
1697.25	31.2753
1700.29	27.958
1703.33	25.8017
1706.38	23.6715
1709.42	21.9585
1712.46	19.5259
1715.5	19.9647
1718.54	20.1754
1721.57	19.122
1724.61	18.7267
1727.64	17.8265
1730.68	17.1008
1733.71	16.5555
1736.74	16.5035
1739.77	15.6343
1742.8	14.5292
1745.83	13.382
1748.85	11.581
1751.88	8.83757
1754.91	7.30132
1757.93	5.83522
1760.95	4.55662
1763.97	3.46681
1766.99	3.45564
1770.01	4.26652
1773.03	4.25536
1776.04	4.51838
1779.06	4.1976
1782.07	3.97143
1785.09	5.98045
1788.1	6.6252
1791.11	7.71523
1794.12	6.98077
1797.13	6.16549
1800.13	6.90388
1803.14	6.67564
1806.15	5.87771
1809.15	5.45661
1812.15	4.53742
1815.16	3.66507
1818.15	2.99377
1821.16	2.99299
1824.15	2.91843
1827.15	3.03896
1830.15	2.07781
1833.14	1.44793
1836.14	0.773546
1839.13	1.3772
1842.12	2.27383
1845.11	2.70905
1848.1	3.17039
1851.09	3.04989
1854.08	2.39925
1857.06	3.01999
1860.05	2.73589
1863.03	3.60097
1866.01	2.93555
1869	3.76243
1871.98	4.81791
1874.96	5.06836
1877.93	4.86349
1880.91	4.85528
1882.47	4.27455
1885.46	4.2688
1888.44	5.03027
1891.43	6.63162
1894.42	6.59194
1897.4	6.82961
1900.39	5.26545
1903.37	5.8412
1906.35	6.23716
1909.33	6.68982
1912.31	8.1665
1915.29	8.1906
1918.26	7.84654
1921.24	8.73418
1924.21	7.66809
1927.19	6.14635
1930.16	6.38989
1933.13	5.45887
1936.1	5.48339
1939.07	5.25339
1942.04	5.22297
1945	5.30893
1947.97	4.54137
1950.93	4.7514
1953.9	5.13265
1956.86	5.03811
1959.82	5.54387
1962.78	5.4397
1965.74	3.70792
1968.7	3.06224
1971.65	3.60903
1974.61	2.94768
1977.57	3.09205
1980.52	2.75294
1983.47	3.42125
1986.42	4.34783
1989.37	3.40364
1992.32	3.47295
1995.27	3.87416
1998.22	3.15121
2001.17	2.99112
2004.11	3.63108
2007.05	3.44637
2010	3.36035
2012.94	4.00047
2015.88	4.0617
2018.82	5.30338
2021.76	6.54663
2024.7	6.92938
2027.63	8.33025
2030.57	9.96515
2033.5	10.9101
2036.44	12.1027
2039.37	13.1513
2042.3	14.2931
2045.23	14.9236
2048.16	15.3318
2051.08	15.6554
2054.01	16.977
2056.94	18.5022
2059.86	20.2515
2062.79	20.9194
2065.71	21.7144
2068.63	22.569
2071.55	23.8968
2074.47	24.0279
2077.39	25.6104
2080.31	26.5087
2083.22	27.4687
2086.13	28.7789
2089.05	32.0031
2091.96	35.3907
2094.87	38.4306
2097.78	42.2003
2100.69	45.3917
2103.6	48.3553
2106.51	51.7266
2109.42	53.8596
2112.32	56.6218
2115.23	60.1423
2118.13	62.689
2121.03	66.5533
2123.93	70.7077
2126.83	75.575
2129.73	78.9655
2132.63	82.3388
2135.53	85.9044
2138.42	89.5049
2141.32	93.1548
2144.21	95.2539
2147.1	98.2109
2150	101.623
2152.89	103.53
2155.78	106.185
2158.66	107.864
2161.55	110.009
2164.44	110.833
2167.32	110.519
2170.21	109.553
2173.09	108.347
2175.97	107.691
2178.85	105.173
2181.73	101.986
2184.61	99.1105
2187.49	96.177
2190.37	92.821
2193.24	88.8376
2196.12	85.4876
2198.99	81.4228
2201.87	77.2724
2204.74	73.3505
2207.61	68.7903
2210.48	64.59
2213.35	60.6857
2216.21	57.1762
2219.08	54.0336
2221.95	51.4902
2224.81	48.2724
2227.67	45.2689
2230.54	43.9229
2233.4	41.6922
2236.26	39.1154
2239.11	37.9974
2241.97	36.7072
2244.83	34.8243
2247.69	33.1498
2250.54	30.1246
2253.4	28.6336
2256.25	26.6277
2259.1	25.1308
2261.95	23.181
2264.8	21.6661
2267.65	20.4575
2270.5	19.5715
2273.34	18.7326
2276.19	17.3883
2279.03	16.0384
2281.88	15.8367
2284.72	14.433
2287.56	14.3431
2290.4	12.6998
2293.24	12.2629
2296.08	12.0551
2298.92	13.1482
2301.76	13.9615
2304.59	14.3407
2307.43	14.3844
2310.26	13.8513
2313.09	13.4532
2315.92	12.5074
2318.75	10.5748
2321.58	10.359
2324.41	9.8067
2327.24	9.33387
2330.06	9.98498
2332.89	9.39271
2335.71	9.60729
2338.54	9.42635
2341.36	9.68241
2344.18	8.29825
2347	7.47923
2349.82	7.45517
2352.64	7.24316
2355.45	7.33367
2358.27	6.95791
2361.08	5.35178
2363.9	5.63458
2366.71	6.4407
2369.52	6.47892
2372.33	6.09181
2375.14	5.69291
2377.95	5.27194
2380.76	4.72256
2383.57	3.78621
2386.37	3.5487
2389.18	3.85546
2391.98	4.41941
2394.79	5.64825
2397.59	5.44818
2400.39	4.77393
2403.19	4.37083
2405.99	4.96026
2408.78	5.25988
2411.58	6.14233
2414.38	6.06894
2417.17	6.59064
2419.97	6.67505
2422.76	5.88377
2425.55	5.73668
2428.34	4.55708
2431.13	4.27995
2433.92	4.88838
2436.71	5.31126
2439.49	5.41366
2442.28	5.65757
2445.06	5.82824
2447.85	5.34258
2450.63	4.86883
2453.41	4.74176
2456.19	4.15045
2458.97	3.71301
2461.75	3.65618
2464.53	3.23559
2467.31	1.88506
2470.08	2.29479
2472.86	1.77642
2475.63	2.04432
2478.4	1.90067
2481.17	2.2518
2483.94	0.494757
2486.72	1.4878
2489.48	0.64074
2492.25	2.25149
2495.02	3.47673
2497.79	4.14908
2500.55	4.6292
2503.31	5.15409
2506.08	5.27489
2508.84	5.92131
2511.6	4.92055
2514.36	4.47177
2517.12	4.80075
2519.88	4.006
2522.63	3.73936
2525.39	2.78477
2528.14	2.93285
2530.9	2.73234
2533.65	1.89212
2536.4	1.89331
2539.15	2.00569
2541.9	1.99576
2544.65	2.31622
2547.4	2.96538
2550.15	3.25738
2552.89	3.66772
2555.64	5.58759
2558.38	6.74337
2561.12	7.45284
2563.87	8.49353
2566.61	8.09646
2569.35	7.74575
2572.09	9.04487
2574.83	8.81697
2577.56	9.13527
2580.3	7.94815
2583.04	7.77413
2585.77	7.02767
2588.5	6.7078
2591.23	6.08792
2593.97	5.44561
2596.7	4.71829
2599.43	5.09834
2602.15	5.10718
2604.88	4.97801
2607.61	4.93421
2610.33	4.89733
2613.06	5.11737
2615.78	5.28826
2618.51	5.54577
2621.23	5.27962
2623.95	4.74803
2626.67	3.99142
2629.39	4.13402
2632.1	4.0574
2634.82	3.82073
2637.54	4.19286
2640.25	3.89179
2642.97	2.6973
2645.68	1.38972
2648.39	1.26538
2651.1	0.35491
2653.81	0.817522
2656.52	1.50518
2659.23	1.24524
2661.94	1.41938
2664.64	1.16937
2667.35	1.95849
2670.05	2.77229
2672.76	2.75881
2675.46	3.6532
2678.16	5.00462
2680.86	6.17049
2683.56	6.38098
2686.26	6.65586
2688.96	7.14369
2691.65	7.56131
2694.35	7.78898
2697.04	8.59662
2699.74	10.0223
2702.43	11.6056
2705.12	12.3016
2707.81	13.1284
2710.5	14.1958
2713.19	15.14
2715.88	15.6747
2718.57	16.6855
2721.25	16.2776
2723.94	15.1617
2726.62	14.5076
2729.3	13.9088
2731.99	14.1526
2734.67	13.9143
2737.35	12.2933
2740.03	11.3347
2742.71	10.9483
2745.38	10.5499
2748.06	8.88055
2750.74	7.42386
2753.41	6.30823
2756.09	4.61367
2758.76	3.37343
2761.43	3.73418
2764.1	3.68292
2766.77	3.49074
2769.44	3.12558
2772.11	2.96223
2774.77	3.65475
2777.44	4.19878
2780.11	4.43775
2782.77	4.23345
2785.43	3.49587
2788.1	3.5134
2790.76	2.45815
2793.42	3.0009
2796.08	2.58223
2798.74	1.7699
2801.4	0.557107
2804.05	-0.621782
2806.71	-0.893418
2809.36	-1.97635
2812.02	-1.82518
2814.67	-1.65682
2817.32	1.11486
2819.97	3.98951
2822.62	8.8206
2825.27	14.2267
2827.92	21.6068
2830.57	30.4202
2833.22	39.3363
2835.86	48.7519
2838.51	59.6613
2841.15	70.3497
2843.79	81.7259
2846.43	93.0356
2849.08	105.508
2851.72	117.325
2854.36	130.799
2856.99	141.045
2859.63	152.203
2862.27	161.797
2864.9	172.122
2867.54	181.246
2870.17	188.531
2872.8	196.544
2875.43	203.263
2878.07	210.791
2880.7	219.491
2883.32	227.425
2885.95	234.214
2888.58	243.498
2891.21	252.058
2893.83	260.805
2896.46	268.356
2899.08	278.534
2901.7	287.615
2904.32	297.966
2906.94	308.434
2909.56	321.336
2912.18	333.634
2914.8	344.29
2917.42	355.378
2920.03	363.335
2922.65	369.016
2925.26	373.032
2927.88	375.401
2930.49	375.823
2933.1	372.146
2935.71	367.655
2938.32	360.865
2940.93	353.277
2943.54	343.707
2946.14	332.585
2948.75	319.233
2951.35	304.461
2953.96	290.472
2956.56	275.632
2959.16	260.901
2961.77	245.417
2964.37	230.908
2966.96	215.584
2969.56	203.039
2972.16	191.318
2974.76	179.135
2977.35	166.772
2979.95	155.752
2982.54	144.066
2985.14	131.521
2987.73	120.702
2990.32	109.397
2992.91	98.2256
2995.5	88.2433
2998.09	79.3043
3000.68	70.3749
3003.26	62.0684
3005.85	54.1768
3008.43	46.6169
3011.02	39.7012
3013.6	33.0209
3016.19	27.9678
3018.77	23.7497
3021.35	19.2708
3023.93	13.6953
3026.5	9.479
3029.08	7.32359
3031.66	5.57362
3034.24	4.18761
3036.81	3.34033
3039.39	2.43361
3041.96	2.9193
3044.53	2.68301
3047.1	3.46624
3049.67	4.93599
3052.24	5.12699
3054.81	5.30462
3057.38	5.9713
3059.95	7.5626
3062.52	8.37911
3065.08	9.35674
3067.65	9.66133
3070.21	11.0106
3072.77	11.8334
3075.33	12.9651
3077.89	13.9415
3080.45	14.3385
3083.01	14.4156
3085.57	14.1778
3088.13	15.289
3090.68	17.0075
3093.24	18.1258
3095.79	18.9873
3098.35	19.96
3100.9	21.631
3103.45	23.4325
3106	25.0395
3108.55	27.0959
3111.1	29.7657
3113.65	32.8769
3116.2	36.2036
3118.75	38.6044
3121.29	41.6103
3123.84	44.5469
3126.38	48.1962
3128.92	50.8134
3131.47	52.8717
3134.01	56.7784
3136.55	60.5409
3139.09	63.3362
3141.63	65.8417
3144.17	68.6118
3146.7	70.9744
3149.24	72.4096