File: data/Raman/poly_smoothed/Mb_40_24_17_1x_45s_532 nm_x100_100%_600 gr_mm_01.txt
#Acq. time (s)=	45
#Accumulations=	2
#Range (cm-¹)=	200...3150
#Windows=	2
#Auto scanning=	Off
#Autofocus=	Off
#Macrospot=	Off
#AutoExposure=	Off
#Spike filter=	Multiple accum.
#Delay time (s)=	0
#Binning=	1
#Readout mode=	Signal
#DeNoise=	Off
#ICS correction=	On
#Dark correction=	Off
#Inst. Process=	Off
#Detector Gain=	Best Dynamic Range
#Detector ADC=	20 kHz
#Detector temperature (°C)=	-70.08
#Instrument=	LabRAM HR Evol
#Detector=	Synapse
#Objective=	x100
#Grating=	600 gr/mm
#ND Filter=	100%
#Laser (nm)=	532
#Hole=	100.021
#Range=	Auto
#Laser Pol.=	No
#Raman. Pol.=	No
#Laser Pol. (°)=	-0.0007625
#Raman Pol. (°)=	89.9995
#Collection=	Microscope
#StageXY=	Marzhauser
#StageZ=	Marzhauser
#X (µm)=	-2560.4
#Y (µm)=	-110.3
#Z (µm)=	-10.65
#Full time(mm:ss)=	3:18
#Project=
#Sample=
#Site=
#Title=	Mb_40_24_17_2x_45s_532 nm_x100_100%_600 gr_mm
#Remark=
#Date=	14.07.2022 11:56
#Acquired=	14.07.2022 11:56:02
#Base:Fit=	10.08.2022 10:47:00
#Base:Sub=	10.08.2022 10:47:12
#Filter:Polynom=	16.08.2022 10:11:48
#AxisType[0]=Intens
#AxisUnit[0]=Cnt
#AxisType[1]=Spectr
#AxisUnit[1]=1/cm
200.554	41.8136
204.183	39.4382
207.813	33.2696
211.439	28.3345
215.065	26.5611
218.688	21.8793
222.312	19.2617
225.933	15.6572
229.552	15.4145
233.171	14.4964
236.787	13.648
240.402	14.7149
244.015	13.6581
247.627	11.5344
251.24	10.6241
254.849	9.39617
258.457	9.96626
262.063	9.58636
265.668	8.32664
269.271	7.06326
272.873	9.11397
276.474	7.63785
280.073	7.95762
283.671	8.29177
287.268	6.79457
290.863	7.62972
294.456	9.00681
298.049	11.0457
301.637	16.2232
305.227	18.9685
308.815	23.0407
312.402	27.7905
315.987	30.4825
319.569	33.6379
323.151	35.9172
326.733	38.2227
330.31	40.0227
333.889	39.7618
337.464	40.0101
341.039	38.8213
344.611	36.594
348.184	32.7038
351.754	29.6097
355.324	28.265
358.89	24.776
362.455	20.7894
366.021	16.6339
369.584	13.4438
373.145	10.4222
376.707	9.96752
380.265	7.31207
383.822	7.53003
387.378	7.72377
390.934	6.61121
394.487	6.37887
398.038	5.83268
401.588	5.34363
405.137	5.00065
408.685	6.35395
412.23	7.88675
415.775	10.4869
419.318	12.0535
422.86	12.9933
426.401	14.4996
429.94	14.2252
433.478	16.6234
437.012	15.9299
440.547	18.8542
444.081	19.913
447.613	17.2687
451.142	16.9029
454.672	18.2236
458.2	20.282
461.725	20.4303
465.251	21.7857
468.775	23.4715
472.296	22.9839
475.817	25.1471
479.335	26.096
482.854	27.4866
486.37	30.0804
489.886	32.7752
493.398	35.2636
496.91	37.2248
500.422	40.2874
503.93	41.3913
507.438	44.9275
510.946	48.2997
514.45	51.7377
517.954	56.3444
521.456	58.3735
524.956	56.893
528.456	58.3179
531.956	58.782
535.452	60.2733
538.947	61.3106
542.441	59.2629
545.934	57.0587
549.425	56.6907
552.915	54.6834
556.403	53.0505
559.889	49.2637
563.375	44.5885
566.859	40.4447
570.342	35.276
573.824	30.2858
577.303	26.1845
580.782	22.7234
584.26	19.2164
587.734	15.7971
591.21	10.9872
594.684	9.76473
598.154	9.74882
601.626	11.2121
605.094	13.5458
608.562	13.095
612.027	12.4308
615.493	13.7354
618.956	14.944
622.419	12.7779
625.879	15.6891
629.338	19.6122
632.797	24.5023
636.254	27.7834
639.708	27.8883
643.162	30.0437
646.614	30.2975
650.067	33.5239
653.516	32.7542
656.964	31.6427
660.411	30.1664
663.857	26.674
667.301	25.016
670.744	20.4731
674.186	18.1585
677.626	16.662
681.065	15.0211
684.503	13.6149
687.939	13.9817
691.372	11.2671
694.806	7.27582
698.239	4.12569
701.67	3.07362
705.098	2.29084
708.526	2.59132
711.954	9.56402
715.378	9.87532
718.802	7.66696
722.226	8.17315
725.646	9.71232
729.067	11.1219
732.484	11.6863
735.902	12.84
739.317	13.6219
742.731	16.7346
746.145	20.1317
749.556	24.5179
752.966	30.2584
756.377	32.4757
759.784	36.8777
763.19	41.4277
766.594	43.9689
770	46.5365
773.402	51.5479
776.803	53.6564
780.202	55.471
783.6	58.2863
786.997	59.1566
790.393	60.9803
793.787	62.4496
797.18	60.0295
800.572	59.4462
803.963	60.4062
807.35	62.1614
810.738	61.2786
814.125	59.1292
817.51	60.7582
820.894	63.705
824.275	68.1556
827.657	73.4878
831.037	80.391
834.414	88.2989
837.792	90.677
841.167	94.6395
844.542	99.1257
847.914	101.121
851.287	102.768
854.656	104.471
858.026	105.55
861.393	103.325
864.761	101.527
868.125	97.2685
871.489	92.372
874.85	87.5059
878.213	79.2192
881.572	73.6325
884.931	66.0842
888.287	60.9458
891.643	52.9338
894.997	46.1452
898.352	46.3685
901.704	47.7164
905.055	48.8684
908.404	50.1329
911.75	53.9015
915.097	55.5616
918.443	56.6652
921.787	58.4955
925.13	60.5214
928.472	60.8549
931.813	59.6529
935.15	59.7242
938.488	57.7935
941.825	55.001
945.158	51.9504
948.493	48.0577
951.824	44.6279
955.156	40.8224
958.486	36.7401
961.814	36.0687
965.142	40.1058
968.467	42.6839
971.79	46.3429
975.115	52.0246
978.436	57.7992
981.756	60.641
985.077	61.7157
988.394	63.3818
991.71	67.4854
995.025	69.2622
998.341	69.102
1001.65	67.5749
1004.97	70.3471
1008.28	72.1516
1011.58	76.1968
1014.89	84.2459
1018.2	93.2567
1021.5	99.3353
1024.81	106.783
1028.11	112.878
1031.41	121.585
1034.71	126.193
1038.01	127.883
1041.31	129.591
1044.6	135.471
1047.9	135.762
1051.19	136.327
1054.48	134.695
1057.77	129.667
1061.06	123.937
1064.35	118.789
1067.64	110.409
1070.93	101.873
1074.21	92.0827
1077.49	82.8337
1080.78	73.8673
1084.06	68.883
1087.34	65.9093
1090.61	64.571
1093.89	66.9789
1097.17	65.207
1100.44	66.0021
1103.71	65.1389
1106.99	64.6626
1110.26	63.5794
1113.52	59.2153
1116.79	54.6876
1120.06	49.7727
1123.32	48.0892
1126.59	46.5288
1129.85	45.6875
1133.11	45.7131
1136.37	42.3145
1139.63	41.9024
1142.89	39.738
1146.15	36.1193
1149.4	30.0179
1152.66	26.3198
1155.91	23.5024
1159.16	18.8818
1162.41	14.8057
1165.66	11.1148
1168.91	9.53693
1172.16	10.3919
1175.4	9.3805
1178.65	10.9798
1181.89	11.6244
1185.13	11.6383
1188.37	13.6684
1191.61	15.1148
1194.85	15.7933
1198.08	18.5352
1201.32	23.3978
1204.55	30.0967
1207.79	33.5664
1211.02	40.3048
1214.25	47.1506
1217.48	55.4611
1220.71	64.2515
1223.93	69.4179
1227.16	75.0865
1230.38	80.7032
1233.6	88.65
1236.83	96.5127
1240.05	103.635
1243.26	110.399
1246.48	119.203
1249.7	127.021
1252.92	135.903
1256.13	142.679
1259.34	149.807
1262.55	156.884
1265.76	165.698
1268.97	173.986
1272.18	179.916
1275.39	188.2
1278.59	196.42
1281.8	203.03
1285	207.171
1288.2	212.291
1291.4	216.596
1294.6	220.338
1297.8	221.257
1301	221.518
1304.19	219.448
1307.39	218.663
1310.58	218.994
1313.77	217.1
1316.96	214.211
1320.15	210.457
1323.34	208.191
1326.53	202.201
1329.72	197.052
1332.9	193.48
1336.08	187.36
1339.27	182.925
1342.45	179.472
1345.63	175.747
1348.8	172.478
1351.98	170.897
1355.16	166.965
1358.33	159.364
1361.51	156.218
1364.68	155.907
1367.85	152.758
1371.02	151.55
1374.19	152.94
1377.36	153.151
1380.52	156.462
1383.69	161.317
1386.85	166.086
1390.02	173.336
1393.18	179.008
1396.34	185.199
1399.5	192.909
1402.65	199.375
1405.81	210.101
1408.97	219.036
1412.12	230.255
1415.27	241.945
1418.43	256.031
1421.58	270.277
1424.73	288.541
1427.87	305.396
1431.02	316.816
1434.17	329.703
1437.31	343.097
1440.46	351.129
1443.6	352.452
1446.74	348.536
1449.88	344.947
1453.02	338.165
1456.16	329.825
1459.29	316.919
1462.43	300.98
1465.56	282.987
1468.69	264.692
1471.83	241.31
1474.95	218.344
1478.08	195.55
1481.21	173.481
1484.34	151.248
1487.47	132.363
1490.59	115.103
1493.71	100.447
1496.84	90.6866
1499.96	80.6857
1503.07	74.57
1506.19	68.0025
1509.31	64.3797
1512.43	60.5428
1515.54	57.2482
1518.65	54.8001
1521.77	52.9014
1524.88	54.2777
1527.99	58.454
1531.1	60.888
1534.21	64.8646
1537.31	70.5239
1540.42	76.2688
1543.52	84.7781
1546.63	92.4594
1549.73	98.3149
1552.83	106.081
1555.93	111.703
1559.03	117.107
1562.12	119.507
1565.22	126.339
1568.31	136.25
1571.41	146.943
1574.5	155.028
1577.59	164.601
1580.68	175.414
1583.77	183.702
1586.86	193.196
1589.95	199.233
1593.03	202.327
1596.11	203.47
1599.2	203.799
1602.28	204.215
1605.36	206.388
1608.44	205.004
1611.52	205.256
1614.6	205.953
1617.67	208.676
1620.75	211.012
1623.82	212.985
1626.89	213.113
1629.96	215.046
1633.04	216.091
1636.11	216.914
1639.17	220.024
1642.24	227.435
1645.31	233.528
1648.37	235.718
1651.43	235.614
1654.5	236.659
1657.56	233.54
1660.62	227.187
1663.67	217.514
1666.73	204.19
1669.79	190.906
1672.84	177.605
1675.9	164.119
1678.95	151.405
1682	136.192
1685.05	123.207
1688.1	110.755
1691.15	100.294
1694.2	91.3352
1697.25	80.8103
1700.29	72.7196
1703.33	64.6952
1706.38	58.0805
1709.42	53.3864
1712.46	49.9625
1715.5	47.3513
1718.54	44.4664
1721.57	43.1008
1724.61	39.8943
1727.64	38.2096
1730.68	36.3076
1733.71	32.875
1736.74	30.7859
1739.77	27.9623
1742.8	25.0316
1745.83	22.7422
1748.85	21.3032
1751.88	18.7914
1754.91	19.1043
1757.93	17.3942
1760.95	16.1033
1763.97	12.516
1766.99	11.6836
1770.01	10.0351
1773.03	8.44696
1776.04	7.2144
1779.06	5.55702
1782.07	3.68388
1785.09	2.89787
1788.1	2.16281
1791.11	1.45331
1794.12	0.796177
1797.13	0.705779
1800.13	-0.374335
1803.14	-1.52145
1806.15	-0.382346
1809.15	-0.15809
1812.15	0.609082
1815.16	2.55388
1818.15	1.82403
1821.16	3.07747
1824.15	3.88238
1827.15	5.66196
1830.15	6.86109
1833.14	8.28312
1836.14	8.2743
1839.13	7.09046
1842.12	6.28438
1845.11	7.1291
1848.1	7.5388
1851.09	6.73063
1854.08	5.55636
1857.06	6.67298
1860.05	6.7553
1863.03	6.15844
1866.01	5.35716
1869	4.52373
1871.98	4.90367
1874.96	3.86285
1877.93	3.98293
1880.91	3.14953
1882.47	3.14844
1885.46	3.51407
1888.44	3.99374
1891.43	4.46594
1894.42	4.57967
1897.4	4.08619
1900.39	5.00011
1903.37	6.01251
1906.35	5.38825
1909.33	4.37329
1912.31	3.38921
1915.29	6.99273
1918.26	7.97027
1921.24	7.14472
1924.21	6.46696
1927.19	5.68955
1930.16	6.03845
1933.13	4.66763
1936.1	6.05537
1939.07	5.8722
1942.04	5.53699
1945	6.74241
1947.97	5.15658
1950.93	4.91963
1953.9	5.71751
1956.86	5.21516
1959.82	5.83357
1962.78	5.7116
1965.74	5.70364
1968.7	5.74265
1971.65	6.7877
1974.61	8.28512
1977.57	9.30583
1980.52	10.1178
1983.47	12.9241
1986.42	14.8532
1989.37	15.6792
1992.32	16.404
1995.27	16.4625
1998.22	16.4508
2001.17	17.4712
2004.11	18.8839
2007.05	22.5351
2010	22.3132
2012.94	22.3463
2015.88	24.0851
2018.82	24.1326
2021.76	24.6668
2024.7	23.9313
2027.63	24.1468
2030.57	24.8063
2033.5	25.2186
2036.44	23.3431
2039.37	25.1072
2042.3	24.7061
2045.23	29.1129
2048.16	31.8954
2051.08	32.7645
2054.01	35.939
2056.94	36.3541
2059.86	38.5228
2062.79	39.4885
2065.71	40.1723
2068.63	42.859
2071.55	44.4047
2074.47	48.3448
2077.39	51.7641
2080.31	52.8999
2083.22	56.5863
2086.13	60.4517
2089.05	62.7178
2091.96	66.1779
2094.87	69.3182
2097.78	74.5874
2100.69	78.3433
2103.6	83.8559
2106.51	86.8784
2109.42	91.6291
2112.32	97.6256
2115.23	105.629
2118.13	110.85
2121.03	115.464
2123.93	122.972
2126.83	127.91
2129.73	132.983
2132.63	140.707
2135.53	148.102
2138.42	157.046
2141.32	165.05
2144.21	175.611
2147.1	182.482
2150	188.947
2152.89	198.75
2155.78	208.644
2158.66	214.318
2161.55	219.387
2164.44	224.505
2167.32	229.647
2170.21	231.707
2173.09	232.198
2175.97	231.889
2178.85	229.605
2181.73	225.465
2184.61	220.275
2187.49	214.556
2190.37	207.597
2193.24	201.686
2196.12	192.259
2198.99	184.081
2201.87	176.673
2204.74	167.671
2207.61	159.5
2210.48	150.75
2213.35	144.212
2216.21	137.007
2219.08	130.147
2221.95	124.664
2224.81	118.752
2227.67	111.195
2230.54	104.661
2233.4	98.9955
2236.26	94.2088
2239.11	89.5933
2241.97	83.6639
2244.83	79.1529
2247.69	73.3814
2250.54	68.3377
2253.4	65.11
2256.25	61.2358
2259.1	58.2584
2261.95	55.4459
2264.8	53.4786
2267.65	50.3402
2270.5	48.8975
2273.34	45.1161
2276.19	43.434
2279.03	41.8642
2281.88	40.1964
2284.72	37.9263
2287.56	36.5169
2290.4	31.8754
2293.24	28.2823
2296.08	26.1103
2298.92	25.6174
2301.76	22.9601
2304.59	22.2654
2307.43	21.0156
2310.26	20.8765
2313.09	20.6848
2315.92	19.0457
2318.75	17.0429
2321.58	16.7045
2324.41	17.2922
2327.24	18.0281
2330.06	16.7512
2332.89	16.1555
2335.71	16.4275
2338.54	14.9302
2341.36	12.8129
2344.18	11.3072
2347	9.19033
2349.82	6.82182
2352.64	6.61893
2355.45	5.00416
2358.27	3.26563
2361.08	2.81956
2363.9	3.57634
2366.71	4.74034
2369.52	5.09814
2372.33	4.68569
2375.14	5.75335
2377.95	6.0248
2380.76	5.0951
2383.57	5.32513
2386.37	4.11844
2389.18	4.67258
2391.98	5.61649
2394.79	6.60028
2397.59	8.03462
2400.39	7.1693
2403.19	7.54475
2405.99	6.9336
2408.78	5.76115
2411.58	5.43384
2414.38	5.12111
2417.17	6.71002
2419.97	8.17138
2422.76	8.7574
2425.55	8.3701
2428.34	9.99516
2431.13	10.3938
2433.92	10.3665
2436.71	10.4725
2439.49	10.6274
2442.28	10.0654
2445.06	10.7549
2447.85	10.7497
2450.63	11.2178
2453.41	10.9333
2456.19	9.69681
2458.97	9.58976
2461.75	7.96346
2464.53	8.62286
2467.31	8.93926
2470.08	8.34067
2472.86	7.89649
2475.63	6.75822
2478.4	6.46211
2481.17	5.53249
2483.94	4.06685
2486.72	3.26535
2489.48	3.78709
2492.25	2.51335
2495.02	4.23438
2497.79	4.09608
2500.55	3.19477
2503.31	3.86096
2506.08	4.59972
2508.84	5.22012
2511.6	4.73399
2514.36	3.68233
2517.12	3.14377
2519.88	3.21848
2522.63	1.56894
2525.39	0.17587
2528.14	0.37698
2530.9	1.09614
2533.65	1.26556
2536.4	1.4402
2539.15	0.908652
2541.9	1.82489
2544.65	2.51224
2547.4	2.24404
2550.15	4.07189
2552.89	4.61045
2555.64	7.04447
2558.38	8.34638
2561.12	9.79845
2563.87	10.1449
2566.61	10.2116
2569.35	11.569
2572.09	12.0065
2574.83	10.822
2577.56	10.1027
2580.3	8.94111
2583.04	8.38157
2585.77	9.14554
2588.5	7.91063
2591.23	7.43273
2593.97	7.70192
2596.7	7.95271
2599.43	6.68396
2602.15	5.5522
2604.88	5.54817
2607.61	6.02173
2610.33	4.73533
2613.06	4.41199
2615.78	4.07948
2618.51	3.66264
2621.23	2.6747
2623.95	2.40979
2626.67	3.18922
2629.39	3.32663
2632.1	2.14186
2634.82	2.15247
2637.54	2.80593
2640.25	3.56646
2642.97	4.67268
2645.68	6.37202
2648.39	6.42012
2651.1	8.82942
2653.81	10.1038
2656.52	11.8818
2659.23	11.4068
2661.94	11.4241
2664.64	9.60783
2667.35	9.41447
2670.05	9.25238
2672.76	9.80915
2675.46	8.83196
2678.16	8.89256
2680.86	9.09913
2683.56	8.46182
2686.26	8.12937
2688.96	9.42108
2691.65	10.5054
2694.35	9.65268
2697.04	10.2709
2699.74	11.9289
2702.43	14.7957
2705.12	16.2279
2707.81	18.6754
2710.5	19.8553
2713.19	20.5615
2715.88	21.5353
2718.57	22.7825
2721.25	21.1311
2723.94	21.2346
2726.62	20.3956
2729.3	19.3081
2731.99	19.4195
2734.67	19.4845
2737.35	19.4114
2740.03	17.3663
2742.71	16.7206
2745.38	15.4345
2748.06	15.1712
2750.74	12.7103
2753.41	10.4044
2756.09	9.11445
2758.76	7.53172
2761.43	6.82669
2764.1	6.55179
2766.77	6.81096
2769.44	6.99826
2772.11	5.06204
2774.77	4.16178
2777.44	3.66594
2780.11	2.27596
2782.77	1.13749
2785.43	0.418909
2788.1	0.0627456
2790.76	0.506221
2793.42	-0.295855
2796.08	-0.613568
2798.74	-0.632826
2801.4	-0.0430073
2804.05	0.927546
2806.71	-0.170126
2809.36	-0.118993
2812.02	-1.05568
2814.67	-1.41954
2817.32	-0.349781
2819.97	6.5742
2822.62	16.4915
2825.27	28.3123
2827.92	44.4311
2830.57	63.3136
2833.22	82.9204
2835.86	105.007
2838.51	126.374
2841.15	152.082
2843.79	178.255
2846.43	204.787
2849.08	235.077
2851.72	265.585
2854.36	296.795
2856.99	326.43
2859.63	357.4
2862.27	385.853
2864.9	413.287
2867.54	437.997
2870.17	460.357
2872.8	477.606
2875.43	496.424
2878.07	514.549
2880.7	531.267
2883.32	552.595
2885.95	571.584
2888.58	593.265
2891.21	615.237
2893.83	638.197
2896.46	660.864
2899.08	685.412
2901.7	712.605
2904.32	741.678
2906.94	772.885
2909.56	808.526
2912.18	843.95
2914.8	877.966
2917.42	911.08
2920.03	940.097
2922.65	963.407
2925.26	979.754
2927.88	986.33
2930.49	986.981
2933.1	979.028
2935.71	965.028
2938.32	945.419
2940.93	918.374
2943.54	885.796
2946.14	851.787
2948.75	813.225
2951.35	773.979
2953.96	732.062
2956.56	691.803
2959.16	651.834
2961.77	615.326
2964.37	578.96
2966.96	545.859
2969.56	516.532
2972.16	489.7
2974.76	466.647
2977.35	441.344
2979.95	415.457
2982.54	391.184
2985.14	364.465
2987.73	336.462
2990.32	308.887
2992.91	280.693
2995.5	253.354
2998.09	228.721
3000.68	204.008
3003.26	178.761
3005.85	155.75
3008.43	137.058
3011.02	117.709
3013.6	100.099
3016.19	85.4953
3018.77	72.2177
3021.35	61.0396
3023.93	50.7088
3026.5	43.2005
3029.08	36.09
3031.66	33.2016
3034.24	30.6446
3036.81	28.7603
3039.39	28.6293
3041.96	28.1498
3044.53	28.4637
3047.1	29.0402
3049.67	29.3291
3052.24	29.6117
3054.81	30.9386
3057.38	31.1373
3059.95	31.4254
3062.52	30.4601
3065.08	29.6041
3067.65	28.4466
3070.21	26.3972
3072.77	23.1833
3075.33	19.1241
3077.89	16.6338
3080.45	14.5382
3083.01	10.9884
3085.57	9.46208
3088.13	6.45785
3090.68	4.868
3093.24	2.70699
3095.79	1.67081
3098.35	2.32967
3100.9	4.69931
3103.45	5.52249
3106	6.67268
3108.55	7.7491
3111.1	8.1007
3113.65	11.2536
3116.2	13.4286
3118.75	15.9307
3121.29	18.4377
3123.84	21.621
3126.38	23.7491
3128.92	26.5808
3131.47	29.1533
3134.01	30.5011
3136.55	33.0165
3139.09	36.6124
3141.63	38.6235
3144.17	41.0502
3146.7	43.238
3149.24	49.4179