File: data/Raman/poly_smoothed/Mb_40_y_26_1x_45s_532 nm_x100_100%_600 gr_mm_01.txt
#Acq. time (s)=	45
#Accumulations=	2
#Range (cm-¹)=	200...3150
#Windows=	2
#Auto scanning=	Off
#Autofocus=	Off
#Macrospot=	Off
#AutoExposure=	Off
#Spike filter=	Multiple accum.
#Delay time (s)=	0
#Binning=	1
#Readout mode=	Signal
#DeNoise=	Off
#ICS correction=	On
#Dark correction=	Off
#Inst. Process=	Off
#Detector Gain=	Best Dynamic Range
#Detector ADC=	20 kHz
#Detector temperature (°C)=	-69.85
#Instrument=	LabRAM HR Evol
#Detector=	Synapse
#Objective=	x100
#Grating=	600 gr/mm
#ND Filter=	100%
#Laser (nm)=	532
#Hole=	100.021
#Range=	Auto
#Laser Pol.=	No
#Raman. Pol.=	No
#Laser Pol. (°)=	-0.0007625
#Raman Pol. (°)=	89.9995
#Collection=	Microscope
#StageXY=	Marzhauser
#StageZ=	Marzhauser
#X (µm)=	-1077.6
#Y (µm)=	566.2
#Z (µm)=	584.5
#Full time(mm:ss)=	3:19
#Project=
#Sample=
#Site=
#Title=	Mb_40_y_26_2x_45s_532 nm_x100_100%_600 gr_mm
#Remark=
#Date=	19.07.2022 11:15
#Acquired=	19.07.2022 11:15:11
#Base:Fit=	10.08.2022 10:52:48
#Base:Sub=	10.08.2022 10:52:53
#Filter:Polynom=	16.08.2022 10:09:04
#AxisType[0]=Intens
#AxisUnit[0]=Cnt
#AxisType[1]=Spectr
#AxisUnit[1]=1/cm
200.423	6.94567
204.052	6.5398
207.682	7.49788
211.308	7.47475
214.935	5.67021
218.558	7.17782
222.18	6.75578
225.802	6.07699
229.421	6.00098
233.039	6.9468
236.657	6.59931
240.272	7.52148
243.885	7.88461
247.497	8.17337
251.11	8.91626
254.719	10.4291
258.327	11.3239
261.933	12.5342
265.538	13.8741
269.141	16.646
272.744	16.4824
276.344	15.992
279.944	16.4223
283.542	17.4164
287.138	17.6405
290.733	18.3749
294.327	18.9472
297.919	19.4688
301.508	19.4461
305.098	19.5162
308.686	19.267
312.273	16.9171
315.858	15.6975
319.44	15.5593
323.022	15.7334
326.604	15.233
330.181	15.6404
333.76	16.1414
337.335	15.7862
340.91	16.16
344.483	14.7284
348.055	13.57
351.625	13.3909
355.195	12.4916
358.762	11.2866
362.329	10.7187
365.893	10.1618
369.455	10.6553
373.017	9.1669
376.578	9.14598
380.137	9.77784
383.694	10.0664
387.249	10.3558
390.806	9.56266
394.359	9.19434
397.91	8.56246
401.46	7.7572
405.009	10.4641
408.557	12.0258
412.103	13.7942
415.647	14.7748
419.191	16.8759
422.733	16.4454
426.273	16.2483
429.812	16.2804
433.35	14.9512
436.885	13.086
440.42	11.3854
443.954	10.3966
447.486	10.4284
451.015	10.5907
454.545	9.64591
458.073	7.24332
461.598	6.34134
465.124	7.56371
468.648	7.3383
472.169	5.93594
475.69	6.20963
479.208	6.31867
482.727	7.7044
486.243	8.83986
489.759	12.4931
493.272	14.7862
496.783	17.4041
500.295	19.9403
503.804	21.1574
507.311	22.7365
510.819	23.8259
514.324	24.7005
517.827	23.6006
521.329	22.4647
524.83	21.7468
528.329	21.8072
531.829	22.8066
535.326	22.3081
538.821	20.1957
542.315	17.2238
545.808	16.5005
549.299	15.9306
552.789	14.1487
556.278	11.6987
559.763	11.2061
563.249	10.233
566.733	11.0789
570.217	11.1288
573.699	11.2217
577.177	11.7754
580.656	11.5496
584.134	12.014
587.609	10.8316
591.084	11.5758
594.558	10.918
598.029	11.1716
601.5	10.7157
604.968	9.73141
608.437	8.96989
611.902	9.55679
615.368	7.78336
618.831	6.71743
622.294	5.47881
625.755	4.67376
629.213	3.0938
632.673	3.83292
636.129	5.19031
639.584	6.71233
643.037	7.00066
646.491	8.26889
649.942	9.94131
653.392	12.205
656.84	13.3455
660.287	15.6953
663.732	17.4062
667.177	19.5736
670.62	21.1793
674.061	23.7215
677.502	25.965
680.941	26.7971
684.379	28.2078
687.815	29.4792
691.248	30.6641
694.682	30.0647
698.115	30.355
701.546	31.2636
704.974	30.9808
708.402	31.8238
711.83	32.2517
715.254	33.6517
718.679	37.1143
722.102	37.4628
725.522	37.4656
728.943	38.4535
732.361	40.2269
735.779	42.0627
739.194	42.5937
742.608	44.707
746.022	47.8238
749.433	50.5452
752.843	52.3916
756.254	55.1259
759.661	56.901
763.067	58.646
766.471	60.4075
769.877	62.2989
773.279	64.3914
776.68	65.2117
780.079	66.0394
783.478	68.417
786.875	69.4662
790.27	68.0807
793.665	68.0736
797.058	69.4727
800.45	69.4969
803.84	69.8711
807.23	68.3685
810.616	67.915
814.002	68.0695
817.388	68.4323
820.772	68.9094
824.153	68.774
827.535	69.1406
830.915	70.2838
834.292	69.3233
837.67	68.0353
841.047	67.0196
844.42	66.5289
847.794	65.3336
851.165	63.7928
854.534	63.127
857.905	63.713
861.272	61.6234
864.639	61.0671
868.004	60.6375
871.367	58.2308
874.731	56.305
878.092	56.0998
881.451	55.6505
884.809	53.8533
888.166	53.0747
891.522	51.7619
894.878	51.8486
898.231	51.1973
901.583	51.0428
904.934	50.8131
908.283	49.9778
911.631	47.9624
914.976	46.858
918.322	44.2953
921.666	42.3155
925.009	41.5273
928.351	39.669
931.692	37.5616
935.029	36.8433
938.367	35.8332
941.704	35.2443
945.038	34.4784
948.372	33.6646
951.705	32.0672
955.035	31.3267
958.366	28.7328
961.693	27.2232
965.021	26.0803
968.346	25.6107
971.67	26.4586
974.995	26.2293
978.316	25.7571
981.638	25.2789
984.957	25.2339
988.274	25.622
991.59	23.5767
994.907	22.7017
998.221	21.8562
1001.53	19.1888
1004.85	19.8506
1008.16	20.4838
1011.46	25.1486
1014.77	29.549
1018.08	35.8205
1021.38	42.6603
1024.69	47.3119
1027.99	52.9443
1031.29	56.4475
1034.59	58.483
1037.89	60.4292
1041.19	60.4208
1044.48	61.7613
1047.78	61.0593
1051.07	59.0618
1054.36	55.3817
1057.66	49.6646
1060.94	46.1098
1064.23	41.5549
1067.52	35.3266
1070.81	28.3122
1074.09	22.7481
1077.38	16.2839
1080.66	10.8367
1083.94	7.32014
1087.22	5.99539
1090.5	6.79821
1093.77	9.17302
1097.05	10.4083
1100.32	11.2697
1103.6	10.5027
1106.87	11.7464
1110.14	11.4396
1113.41	12.5907
1116.67	12.9297
1119.94	11.9459
1123.21	10.7129
1126.47	10.4387
1129.73	8.82364
1133	7.35692
1136.26	6.7351
1139.52	7.10174
1142.77	6.64869
1146.03	6.37375
1149.29	5.49154
1152.54	6.36884
1155.79	5.44946
1159.04	5.36487
1162.3	4.3276
1165.55	3.33089
1168.79	3.80077
1172.04	4.37789
1175.28	4.16996
1178.53	4.12914
1181.77	3.70199
1185.01	3.90587
1188.25	3.59846
1191.49	3.58245
1194.73	4.58259
1197.97	3.29431
1201.2	4.53966
1204.44	5.68181
1207.67	6.01242
1210.9	7.19635
1214.13	8.29975
1217.36	9.19707
1220.59	10.4905
1223.82	11.7798
1227.04	14.3989
1230.26	15.5345
1233.49	17.6705
1236.71	17.5805
1239.93	17.9989
1243.15	18.7879
1246.37	19.5691
1249.58	20.4454
1252.8	19.6986
1256.01	20.3054
1259.23	20.7439
1262.44	21.88
1265.65	20.2017
1268.86	21.3838
1272.07	22.219
1275.27	22.9891
1278.48	23.5257
1281.68	24.8272
1284.89	24.7042
1288.09	25.7011
1291.29	25.6527
1294.49	25.6502
1297.69	26.9221
1300.88	28.608
1304.08	29.1093
1307.27	27.6767
1310.47	28.8514
1313.66	29.0253
1316.85	29.3591
1320.04	29.0309
1323.23	28.3171
1326.41	28.7593
1329.6	27.1729
1332.78	26.1673
1335.97	26.6143
1339.15	26.7333
1342.33	25.05
1345.51	24.1272
1348.69	22.8672
1351.87	22.1942
1355.04	21.2119
1358.22	20.3141
1361.39	20.3838
1364.57	17.8617
1367.74	17.1349
1370.91	16.2629
1374.07	16.4081
1377.24	15.977
1380.41	14.866
1383.57	14.2451
1386.74	14.6319
1389.9	16.0073
1393.06	16.7984
1396.22	16.7109
1399.38	16.4864
1402.54	16.565
1405.7	17.7204
1408.85	19.8993
1412.01	21.3256
1415.16	23.3885
1418.31	24.2449
1421.46	25.4584
1424.61	26.7713
1427.76	30.028
1430.91	31.6769
1434.05	34.0999
1437.2	35.0804
1440.34	36.8327
1443.49	37.1006
1446.63	37.082
1449.77	37.256
1452.91	36.4938
1456.04	36.5302
1459.18	37.2948
1462.31	36.8858
1465.45	37.4516
1468.58	37.0789
1471.71	37.1299
1474.84	36.8241
1477.97	36.3205
1481.1	34.8247
1484.23	34.3432
1487.35	33.0436
1490.48	31.7629
1493.6	29.6329
1496.72	28.2769
1499.84	27.2989
1502.96	25.7986
1506.08	24.727
1509.2	22.6188
1512.31	20.7711
1515.43	19.1743
1518.54	16.9927
1521.66	14.5878
1524.77	12.4272
1527.88	11.34
1530.99	10.9181
1534.09	10.3944
1537.2	9.69483
1540.31	9.92696
1543.41	11.0273
1546.51	10.9038
1549.62	10.6536
1552.72	10.3592
1555.82	10.5199
1558.91	11.0394
1562.01	11.9147
1565.11	13.3989
1568.2	13.3686
1571.3	14.354
1574.39	15.3449
1577.48	16.608
1580.57	17.5302
1583.66	18.5983
1586.75	19.4924
1589.83	20.8811
1592.92	21.8179
1596	21.5206
1599.09	21.7452
1602.17	21.6304
1605.25	20.7227
1608.33	18.7633
1611.41	18.3976
1614.48	17.8317
1617.56	16.0946
1620.64	16.7385
1623.71	15.365
1626.78	15.6513
1629.86	15.6715
1632.92	17.3393
1635.99	17.9901
1639.06	19.0946
1642.13	19.4759
1645.19	19.3761
1648.26	20.2443
1651.32	21.622
1654.38	21.4927
1657.45	21.7805
1660.51	22.6805
1663.57	23.0977
1666.62	22.8786
1669.68	20.6621
1672.73	20.0967
1675.79	18.7734
1678.84	17.8627
1681.89	16.9166
1684.94	15.4862
1687.99	14.5527
1691.04	12.2569
1694.09	11.3881
1697.14	10.847
1700.18	10.8946
1703.22	10.5075
1706.27	11.0042
1709.31	10.4079
1712.35	9.10683
1715.39	8.00522
1718.43	7.06271
1721.46	6.37499
1724.5	5.62683
1727.53	5.23391
1730.57	4.05618
1733.6	3.98711
1736.63	2.32413
1739.66	2.464
1742.69	2.31598
1745.72	2.13378
1748.74	2.86087
1751.77	3.21589
1754.8	3.32146
1757.82	3.70338
1760.84	2.80243
1763.86	3.00934
1766.88	4.70807
1769.9	5.50683
1772.92	6.37758
1775.93	7.15752
1778.95	7.25826
1781.96	6.87692
1784.98	5.93107
1787.99	5.75402
1791	5.72502
1794.01	6.18181
1797.02	5.77054
1800.03	5.43242
1803.03	4.19173
1806.04	3.59083
1809.04	2.37657
1812.04	2.68938
1815.05	2.48589
1818.05	2.64433
1821.05	3.33968
1824.05	4.24741
1827.04	3.73779
1830.04	4.58407
1833.03	4.63893
1836.03	4.6113
1839.02	5.60632
1842.01	5.77303
1845	6.54651
1847.99	6.71734
1850.98	7.10314
1853.97	5.73612
1856.95	4.71444
1859.94	4.45127
1862.92	3.52753
1865.91	3.32393
1868.89	2.4107
1871.87	2.26268
1874.85	2.39399
1877.83	2.00866
1880.8	2.44796
1882.56	3.15705
1885.54	3.82126
1888.53	4.45051
1891.52	4.88309
1894.5	5.77404
1897.49	5.76244
1900.47	5.91191
1903.45	6.25274
1906.43	5.74548
1909.41	6.43485
1912.39	6.28521
1915.37	7.13406
1918.35	6.52757
1921.32	5.59451
1924.3	4.26186
1927.27	3.63548
1930.24	2.63888
1933.21	1.86523
1936.18	1.48891
1939.15	1.98307
1942.12	1.2634
1945.09	2.08498
1948.05	2.13522
1951.02	2.65196
1953.98	3.32437
1956.94	3.62977
1959.91	3.78433
1962.87	5.01846
1965.82	4.92641
1968.78	5.76889
1971.74	6.2864
1974.7	5.99859
1977.65	6.22421
1980.6	6.25179
1983.56	6.05469
1986.51	6.26206
1989.46	6.24326
1992.41	6.74573
1995.36	6.57256
1998.3	7.02117
2001.25	6.32594
2004.2	5.85892
2007.14	5.68999
2010.08	5.38317
2013.02	6.14254
2015.97	5.95989
2018.9	6.06699
2021.84	5.90942
2024.78	5.88355
2027.72	5.09778
2030.65	5.693
2033.59	6.4255
2036.52	5.92085
2039.45	5.36392
2042.38	5.65181
2045.31	5.88268
2048.24	5.9308
2051.17	6.25156
2054.1	6.94948
2057.02	6.83598
2059.95	7.39645
2062.87	8.61208
2065.79	9.70371
2068.71	9.97319
2071.63	10.0081
2074.55	10.5808
2077.47	11.7607
2080.39	11.8651
2083.3	12.7537
2086.22	14.1569
2089.13	14.452
2092.05	15.1962
2094.96	16.3592
2097.87	16.7588
2100.78	17.0927
2103.69	18.635
2106.59	18.3808
2109.5	19.3604
2112.41	21.2393
2115.31	22.1247
2118.21	22.193
2121.12	23.4452
2124.02	23.7837
2126.92	23.69
2129.82	24.962
2132.71	26.3872
2135.61	27.8809
2138.51	28.295
2141.4	29.1719
2144.29	30.3343
2147.19	31.336
2150.08	32.8346
2152.97	34.3565
2155.86	36.613
2158.75	37.7287
2161.64	38.9422
2164.52	41.3467
2167.41	42.5737
2170.29	41.8574
2173.17	42.3211
2176.06	42.6952
2178.94	42.0925
2181.82	41.5548
2184.7	40.4232
2187.57	38.6348
2190.45	37.5061
2193.33	35.9946
2196.2	33.3686
2199.08	32.5579
2201.95	30.8857
2204.82	28.953
2207.69	26.7848
2210.56	25.6986
2213.43	24.8887
2216.3	22.9463
2219.16	21.713
2222.03	21.842
2224.89	21.3364
2227.75	20.2675
2230.62	20.3792
2233.48	20.7252
2236.34	19.8485
2239.2	18.9522
2242.06	18.2645
2244.91	18.4929
2247.77	17.7836
2250.62	17.3833
2253.48	16.8253
2256.33	15.9084
2259.18	14.5538
2262.03	12.9822
2264.88	12.4684
2267.73	11.1633
2270.58	10.113
2273.43	9.27194
2276.27	9.14953
2279.12	8.60926
2281.96	7.96669
2284.8	6.90867
2287.64	6.72735
2290.49	7.09435
2293.32	5.21342
2296.16	4.76555
2299	5.73837
2301.84	7.61969
2304.67	7.91529
2307.51	8.26641
2310.34	8.70216
2313.17	9.71313
2316	10.456
2318.83	10.0682
2321.66	9.80811
2324.49	9.08914
2327.32	8.46997
2330.15	7.80644
2332.97	6.62685
2335.79	5.4399
2338.62	4.39691
2341.44	4.20584
2344.26	4.33245
2347.08	3.05693
2349.9	2.31004
2352.72	1.3002
2355.53	0.319485
2358.35	-0.113127
2361.17	-1.52401
2363.98	-2.22624
2366.79	-0.616993
2369.6	0.230128
2372.42	0.593634
2375.22	0.257246
2378.03	0.402614
2380.84	0.88948
2383.65	1.53016
2386.45	1.76167
2389.26	1.87787
2392.06	2.28245
2394.87	2.78345
2397.67	1.89568
2400.47	1.81138
2403.27	2.15865
2406.07	2.31128
2408.86	3.45452
2411.66	4.08006
2414.46	3.38567
2417.25	3.54334
2420.05	4.02685
2422.84	4.7598
2425.63	5.5578
2428.42	5.63911
2431.21	4.61701
2434	5.27025
2436.79	5.65108
2439.57	5.74718
2442.36	5.46592
2445.14	5.68069
2447.93	6.20715
2450.71	6.58089
2453.49	6.83323
2456.27	6.43394
2459.05	6.45614
2461.83	6.66315
2464.61	6.62013
2467.39	6.53441
2470.16	6.06234
2472.94	5.93571
2475.71	5.60922
2478.48	4.68271
2481.25	3.86111
2484.02	4.32176
2486.8	4.69002
2489.56	4.59463
2492.33	4.84698
2495.1	3.79121
2497.86	2.91253
2500.63	2.70162
2503.39	2.85286
2506.16	2.63924
2508.92	2.4601
2511.68	2.07768
2514.44	2.08219
2517.2	1.91841
2519.95	2.30271
2522.71	2.92472
2525.47	3.05191
2528.22	3.79576
2530.98	4.26532
2533.73	4.49309
2536.48	5.18464
2539.23	5.25063
2541.98	5.94477
2544.73	5.35934
2547.48	5.07603
2550.23	5.73966
2552.97	6.08932
2555.72	6.30484
2558.46	6.66639
2561.2	6.04935
2563.95	5.54682
2566.69	5.90969
2569.43	4.63044
2572.17	4.4231
2574.91	4.17783
2577.64	4.06279
2580.38	2.93891
2583.11	2.31973
2585.85	3.25205
2588.58	3.29756
2591.31	2.25054
2594.04	2.28558
2596.78	2.4233
2599.51	2.41749
2602.23	2.85998
2604.96	2.34051
2607.69	2.01491
2610.41	2.35044
2613.14	2.00577
2615.86	1.49197
2618.58	2.33875
2621.3	2.22172
2624.03	1.50795
2626.75	0.702904
2629.46	0.725744
2632.18	0.623247
2634.9	-0.126963
2637.61	-0.145214
2640.33	-0.305892
2643.04	-0.628349
2645.76	-0.789598
2648.47	-0.715873
2651.18	-0.259628
2653.89	-0.0318164
2656.6	-0.00869268
2659.31	0.411592
2662.01	2.15948
2664.72	2.55086
2667.43	3.44555
2670.13	3.43062
2672.83	3.74305
2675.53	4.34808
2678.24	4.90581
2680.94	4.89715
2683.64	5.67972
2686.34	5.65826
2689.03	4.94277
2691.73	4.88624
2694.43	5.2548
2697.12	5.73956
2699.81	4.71071
2702.51	4.76159
2705.2	5.01799
2707.89	5.04903
2710.58	5.47579
2713.27	5.18447
2715.96	5.13552
2718.64	4.5723
2721.33	4.68866
2724.01	4.72934
2726.7	4.61451
2729.38	4.56613
2732.06	4.66727
2734.75	3.61191
2737.43	3.158
2740.11	3.53252
2742.78	3.15641
2745.46	3.044
2748.14	2.46434
2750.81	1.45514
2753.49	1.08912
2756.16	1.19777
2758.84	1.10058
2761.51	0.425644
2764.18	0.111932
2766.85	0.450168
2769.52	1.70163
2772.19	1.70659
2774.85	1.38874
2777.52	1.92003
2780.18	1.25852
2782.85	1.51041
2785.51	1.47665
2788.17	1.83899
2790.84	2.01446
2793.5	2.58489
2796.16	2.99705
2798.81	2.80591
2801.47	3.13994
2804.13	3.69114
2806.79	3.329
2809.44	1.70045
2812.09	2.12158
2814.75	2.23039
2817.4	3.65229
2820.05	5.2593
2822.7	7.32759
2825.35	8.48962
2828	10.3791
2830.65	12.9785
2833.29	14.6791
2835.94	16.4247
2838.58	18.3518
2841.23	20.5417
2843.87	22.5102
2846.51	24.4769
2849.15	27.1766
2851.79	29.6132
2854.43	32.4231
2857.07	35.791
2859.71	38.3514
2862.34	40.7677
2864.98	43.8105
2867.61	45.6961
2870.25	47.4487
2872.88	49.6593
2875.51	51.4638
2878.14	53.4043
2880.77	56.1703
2883.4	58.8404
2886.03	59.9019
2888.65	60.4103
2891.28	61.0124
2893.91	62.7953
2896.53	64.238
2899.15	64.9708
2901.78	66.667
2904.4	68.2314
2907.02	70.8581
2909.64	73.872
2912.26	76.3356
2914.87	79.469
2917.49	82.8566
2920.11	85.7541
2922.72	88.3022
2925.34	89.9514
2927.95	92.0316
2930.56	92.993
2933.17	93.5023
2935.78	92.7754
2938.39	91.6
2941	90.2374
2943.61	87.6581
2946.22	84.5265
2948.82	79.9679
2951.43	75.6541
2954.03	72.0156
2956.64	67.9749
2959.24	64.7319
2961.84	59.6249
2964.44	55.8524
2967.04	52.2435
2969.64	48.7144
2972.24	45.3794
2974.83	42.103
2977.43	38.5193
2980.02	35.3545
2982.62	32.7644
2985.21	29.4459
2987.8	27.0974
2990.4	24.2383
2992.99	22.3748
2995.57	19.7829
2998.16	17.162
3000.75	14.8756
3003.34	13.2453
3005.92	11.1448
3008.51	9.22232
3011.09	7.67409
3013.68	5.75079
3016.26	4.43228
3018.84	3.25659
3021.42	2.82818
3024	1.80677
3026.58	1.98485
3029.16	1.79659
3031.73	1.04861
3034.31	0.824893
3036.89	1.2385
3039.46	0.50155
3042.03	1.1186
3044.61	1.61792
3047.18	1.89388
3049.75	2.41894
3052.32	2.68356
3054.89	2.7089
3057.45	2.96898
3060.02	3.1202
3062.59	3.0366
3065.15	2.94362
3067.72	3.20852
3070.28	2.99252
3072.84	2.39468
3075.41	1.52024
3077.97	1.20219
3080.53	1.32837
3083.09	1.80931
3085.64	2.05829
3088.2	1.29711
3090.76	0.602878
3093.31	0.215285
3095.87	0.000578208
3098.42	0.106006
3100.97	-0.166504
3103.53	-0.211083
3106.08	0.435216
3108.63	1.19006
3111.18	1.84487
3113.73	2.32706
3116.27	3.22947
3118.82	3.74568
3121.37	4.73406
3123.91	5.44436
3126.45	6.01672
3129	7.50137
3131.54	8.72392
3134.08	10.1574
3136.62	11.3387
3139.16	13.3134
3141.7	14.8793
3144.24	16.0038
3146.78	17.5953
3149.31	20.0042