File: data/Raman/poly_smoothed/Mb_40_24_11_1x_45s_532 nm_x100_100%_600 gr_mm_01.txt
#Acq. time (s)=	45
#Accumulations=	2
#Range (cm-¹)=	200...3150
#Windows=	2
#Auto scanning=	Off
#Autofocus=	Off
#Macrospot=	Off
#AutoExposure=	Off
#Spike filter=	Multiple accum.
#Delay time (s)=	0
#Binning=	1
#Readout mode=	Signal
#DeNoise=	Off
#ICS correction=	On
#Dark correction=	Off
#Inst. Process=	Off
#Detector Gain=	Best Dynamic Range
#Detector ADC=	20 kHz
#Detector temperature (°C)=	-70.08
#Instrument=	LabRAM HR Evol
#Detector=	Synapse
#Objective=	x100
#Grating=	600 gr/mm
#ND Filter=	100%
#Laser (nm)=	532
#Hole=	100.021
#Range=	Auto
#Laser Pol.=	No
#Raman. Pol.=	No
#Laser Pol. (°)=	-0.0007625
#Raman Pol. (°)=	89.9995
#Collection=	Microscope
#StageXY=	Marzhauser
#StageZ=	Marzhauser
#X (µm)=	-2541.1
#Y (µm)=	-66.8
#Z (µm)=	-10.8
#Full time(mm:ss)=	3:19
#Project=
#Sample=
#Site=
#Title=	Mb_40_24_11_2x_45s_532 nm_x100_100%_600 gr_mm
#Remark=
#Date=	14.07.2022 11:30
#Acquired=	14.07.2022 11:30:25
#Base:Fit=	10.08.2022 10:47:00
#Base:Sub=	10.08.2022 10:47:12
#Filter:Polynom=	16.08.2022 10:11:48
#AxisType[0]=Intens
#AxisUnit[0]=Cnt
#AxisType[1]=Spectr
#AxisUnit[1]=1/cm
200.554	92.6067
204.183	78.634
207.813	64.9274
211.439	54.0207
215.065	43.8051
218.688	36.7886
222.312	30.3114
225.933	26.5888
229.552	22.2985
233.171	18.0746
236.787	15.7688
240.402	13.5507
244.015	12.5341
247.627	11.7462
251.24	12.9777
254.849	13.3851
258.457	15.214
262.063	17.2346
265.668	18.9488
269.271	17.9583
272.873	17.5907
276.474	18.2977
280.073	17.8143
283.671	14.8885
287.268	11.0091
290.863	8.78895
294.456	8.6508
298.049	10.4176
301.637	11.4181
305.227	12.4926
308.815	16.2284
312.402	18.9479
315.987	22.2979
319.569	23.3826
323.151	27.7041
326.733	28.9204
330.31	31.2139
333.889	34.3063
337.464	36.1329
341.039	38.5148
344.611	39.194
348.184	37.7369
351.754	36.3673
355.324	33.2265
358.89	30.5365
362.455	28.6232
366.021	24.0565
369.584	19.5591
373.145	12.6787
376.707	9.82402
380.265	8.20656
383.822	6.73493
387.378	6.99327
390.934	6.90596
394.487	5.79566
398.038	5.70261
401.588	5.18029
405.137	4.98701
408.685	5.87697
412.23	4.29831
415.775	4.12168
419.318	3.5335
422.86	3.73575
426.401	4.4225
429.94	5.21204
433.478	3.95115
437.012	1.53486
440.547	2.51156
444.081	3.80949
447.613	3.90821
451.142	1.94841
454.672	2.58517
458.2	1.77697
461.725	3.85293
465.251	5.63642
468.775	7.0757
472.296	8.88958
475.817	11.1776
479.335	13.4385
482.854	14.2979
486.37	18.5843
489.886	21.5835
493.398	25.1542
496.91	26.2226
500.422	30.1138
503.93	34.3576
507.438	38.231
510.946	39.2912
514.45	43.4567
517.954	44.5436
521.456	45.015
524.956	48.3006
528.456	49.676
531.956	47.2817
535.452	45.7059
538.947	43.431
542.441	42.1791
545.934	39.6783
549.425	36.7955
552.915	33.9211
556.403	32.4187
559.889	29.6034
563.375	26.4385
566.859	23.8667
570.342	20.7973
573.824	18.1094
577.303	15.7715
580.782	13.5725
584.26	12.2059
587.734	10.8534
591.21	9.18068
594.684	7.54278
598.154	7.24809
601.626	8.60544
605.094	6.49023
608.562	6.30113
612.027	7.58775
615.493	4.91997
618.956	4.58613
622.419	4.94348
625.879	4.13498
629.338	4.10075
632.797	5.4355
636.254	3.99946
639.708	4.17904
643.162	4.47705
646.614	3.49807
650.067	4.37036
653.516	4.85477
656.964	4.27021
660.411	3.19536
663.857	2.07175
667.301	1.02086
670.744	1.09851
674.186	2.54974
677.626	4.14415
681.065	5.73336
684.503	7.28592
687.939	7.66626
691.372	10.1564
694.806	8.92229
698.239	5.2864
701.67	4.78883
705.098	11.1103
708.526	16.5454
711.954	23.8112
715.378	28.3768
718.802	33.4814
722.226	36.449
725.646	38.2081
729.067	42.3171
732.484	46.4784
735.902	49.0508
739.317	47.7194
742.731	47.544
746.145	48.1079
749.556	50.4401
752.966	50.8917
756.377	53.4844
759.784	56.1424
763.19	55.0804
766.594	55.2075
770	54.8166
773.402	53.9115
776.803	48.7656
780.202	45.7186
783.6	48.9051
786.997	54.1152
790.393	57.7495
793.787	59.2172
797.18	60.7412
800.572	63.3407
803.963	63.0187
807.35	60.9266
810.738	58.0129
814.125	57.3944
817.51	57.4176
820.894	55.5026
824.275	56.0349
827.657	58.4399
831.037	61.0161
834.414	63.8305
837.792	67.347
841.167	70.3597
844.542	71.6236
847.914	71.4983
851.287	73.3249
854.656	71.8586
858.026	69.9173
861.393	67.6008
864.761	67.0246
868.125	65.3964
871.489	62.035
874.85	61.3265
878.213	58.7335
881.572	56.0878
884.931	50.5945
888.287	45.8713
891.643	41.3342
894.997	37.5922
898.352	37.218
901.704	37.6081
905.055	37.0148
908.404	39.5143
911.75	41.6408
915.097	42.7106
918.443	43.5652
921.787	44.7355
925.13	47.1348
928.472	47.9391
931.813	46.4869
935.15	45.7423
938.488	43.1961
941.825	43.5782
945.158	42.4707
948.493	43.4188
951.824	42.631
955.156	41.9096
958.486	38.2427
961.814	36.1754
965.142	37.6706
968.467	40.2105
971.79	44.5171
975.115	48.3179
978.436	50.8154
981.756	52.061
985.077	53.6997
988.394	55.8064
991.71	56.2161
995.025	54.8608
998.341	53.7099
1001.65	52.6505
1004.97	51.785
1008.28	52.4342
1011.58	52.648
1014.89	56.0426
1018.2	59.3792
1021.5	64.8069
1024.81	69.2268
1028.11	72.4788
1031.41	75.9828
1034.71	79.4579
1038.01	80.5334
1041.31	82.4474
1044.6	86.2352
1047.9	89.5173
1051.19	89.2417
1054.48	87.3722
1057.77	84.1939
1061.06	78.7667
1064.35	74.6314
1067.64	70.2871
1070.93	67.1431
1074.21	59.3549
1077.49	54.3462
1080.78	48.7372
1084.06	44.4557
1087.34	44.4635
1090.61	45.5429
1093.89	46.0852
1097.17	47.9204
1100.44	48.8887
1103.71	48.1389
1106.99	47.7448
1110.26	46.6213
1113.52	46.0347
1116.79	45.185
1120.06	42.8899
1123.32	41.1774
1126.59	36.4139
1129.85	34.873
1133.11	32.6846
1136.37	31.4935
1139.63	31.4298
1142.89	30.826
1146.15	29.3704
1149.4	27.4595
1152.66	23.985
1155.91	19.6896
1159.16	17.5929
1162.41	15.4596
1165.66	13.8206
1168.91	13.6619
1172.16	12.2894
1175.4	10.6333
1178.65	10.5068
1181.89	8.66861
1185.13	8.36768
1188.37	9.48218
1191.61	10.5003
1194.85	13.1916
1198.08	15.0126
1201.32	14.7262
1204.55	16.5537
1207.79	22.0216
1211.02	30.2568
1214.25	40.3766
1217.48	48.1861
1220.71	55.5047
1223.93	64.0771
1227.16	72.8887
1230.38	79.2505
1233.6	84.7597
1236.83	90.4573
1240.05	97.264
1243.26	101.133
1246.48	105.142
1249.7	110.443
1252.92	114.129
1256.13	119.095
1259.34	120.442
1262.55	123.3
1265.76	128.98
1268.97	131.652
1272.18	133.584
1275.39	137.332
1278.59	140.505
1281.8	145.021
1285	150.123
1288.2	158.831
1291.4	163.561
1294.6	166.061
1297.8	168.659
1301	171.195
1304.19	170.129
1307.39	169.132
1310.58	167.13
1313.77	164.114
1316.96	162.633
1320.15	160.495
1323.34	154.971
1326.53	150.898
1329.72	146.546
1332.9	143.75
1336.08	138.75
1339.27	135.357
1342.45	133.763
1345.63	132.296
1348.8	131.91
1351.98	132.649
1355.16	130.702
1358.33	130.261
1361.51	129.475
1364.68	128.971
1367.85	128.733
1371.02	126.032
1374.19	123.661
1377.36	124.172
1380.52	123.203
1383.69	123.922
1386.85	125.322
1390.02	126.706
1393.18	126.325
1396.34	127.465
1399.5	131.163
1402.65	133.248
1405.81	139.894
1408.97	147.075
1412.12	155.065
1415.27	165.672
1418.43	179.225
1421.58	193.256
1424.73	208.891
1427.87	223.471
1431.02	236.52
1434.17	249.778
1437.31	259.093
1440.46	264.3
1443.6	268.344
1446.74	269.276
1449.88	266.804
1453.02	263.264
1456.16	256.72
1459.29	245.79
1462.43	234.301
1465.56	219.325
1468.69	202.3
1471.83	185.691
1474.95	169.203
1478.08	151.81
1481.21	133.08
1484.34	115.688
1487.47	103.048
1490.59	91.4255
1493.71	83.2841
1496.84	75.8269
1499.96	70.0615
1503.07	63.4809
1506.19	57.5479
1509.31	52.6265
1512.43	46.6479
1515.54	43.0602
1518.65	42.0718
1521.77	40.4091
1524.88	41.0185
1527.99	42.0763
1531.1	43.706
1534.21	46.3666
1537.31	50.1918
1540.42	53.7033
1543.52	59.3333
1546.63	64.9107
1549.73	69.9588
1552.83	75.2173
1555.93	79.1579
1559.03	85.437
1562.12	91.9412
1565.22	97.8494
1568.31	105.056
1571.41	110.894
1574.5	117.175
1577.59	121.058
1580.68	127.185
1583.77	133.16
1586.86	138.861
1589.95	144.321
1593.03	149.971
1596.11	154.887
1599.2	157
1602.28	159.602
1605.36	160.929
1608.44	162.556
1611.52	163.774
1614.6	165.101
1617.67	165.831
1620.75	167.37
1623.82	166.774
1626.89	167.593
1629.96	167.565
1633.04	168.365
1636.11	168.434
1639.17	166.495
1642.24	166.397
1645.31	166.331
1648.37	165.626
1651.43	166.726
1654.5	164.788
1657.56	162.931
1660.62	159.519
1663.67	153.829
1666.73	147.237
1669.79	139.248
1672.84	131.778
1675.9	122.063
1678.95	112.669
1682	103.339
1685.05	94.1524
1688.1	86.6899
1691.15	78.6195
1694.2	71.152
1697.25	63.3195
1700.29	58.0964
1703.33	54.3211
1706.38	48.8113
1709.42	45.2164
1712.46	43.4392
1715.5	41.8618
1718.54	41.7526
1721.57	39.9053
1724.61	37.8459
1727.64	35.7696
1730.68	34.5707
1733.71	32.0632
1736.74	30.2711
1739.77	27.5362
1742.8	26.1262
1745.83	24.3347
1748.85	21.8437
1751.88	18.7158
1754.91	15.7974
1757.93	14.2052
1760.95	12.7698
1763.97	10.4662
1766.99	8.02869
1770.01	7.77923
1773.03	5.86231
1776.04	7.2337
1779.06	7.25952
1782.07	6.83874
1785.09	7.57425
1788.1	7.13205
1791.11	6.69182
1794.12	5.59084
1797.13	3.9714
1800.13	4.33672
1803.14	3.88388
1806.15	3.94569
1809.15	3.17756
1812.15	4.07081
1815.16	3.12297
1818.15	2.36547
1821.16	1.36496
1824.15	1.82456
1827.15	0.611563
1830.15	0.831171
1833.14	1.52612
1836.14	0.939549
1839.13	2.84139
1842.12	3.63974
1845.11	4.611
1848.1	5.11912
1851.09	5.57915
1854.08	3.93809
1857.06	4.01436
1860.05	3.63511
1863.03	3.37206
1866.01	3.04075
1869	2.69901
1871.98	2.96471
1874.96	2.155
1877.93	1.7515
1880.91	3.06272
1882.47	3.45815
1885.46	2.49486
1888.44	0.821119
1891.43	2.1166
1894.42	2.47595
1897.4	3.26591
1900.39	4.24541
1903.37	4.60164
1906.35	4.14555
1909.33	4.89998
1912.31	6.31235
1915.29	7.32677
1918.26	8.20008
1921.24	6.62507
1924.21	6.97141
1927.19	6.71013
1930.16	7.53482
1933.13	7.70904
1936.1	7.95442
1939.07	8.17923
1942.04	7.53756
1945	7.46415
1947.97	7.13204
1950.93	8.09444
1953.9	7.10287
1956.86	6.21886
1959.82	4.52926
1962.78	4.58626
1965.74	5.8583
1968.7	5.78799
1971.65	5.03065
1974.61	3.61209
1977.57	2.75712
1980.52	2.23014
1983.47	1.97088
1986.42	3.11849
1989.37	2.66663
1992.32	1.9817
1995.27	1.65595
1998.22	2.72291
2001.17	1.54164
2004.11	2.77204
2007.05	3.41953
2010	2.92919
2012.94	3.45983
2015.88	4.09438
2018.82	4.29202
2021.76	5.0556
2024.7	6.35974
2027.63	7.62039
2030.57	9.12378
2033.5	9.21536
2036.44	11.5262
2039.37	12.7758
2042.3	14.0921
2045.23	14.6279
2048.16	16.4151
2051.08	18.9726
2054.01	19.4371
2056.94	21.1312
2059.86	23.1025
2062.79	24.4818
2065.71	25.4687
2068.63	26.3316
2071.55	28.0842
2074.47	30.454
2077.39	31.5996
2080.31	33.0358
2083.22	35.0575
2086.13	34.9878
2089.05	36.9419
2091.96	38.9404
2094.87	41.5578
2097.78	43.8691
2100.69	45.9863
2103.6	51.1
2106.51	54.1444
2109.42	58.5639
2112.32	60.1047
2115.23	63.8656
2118.13	68.3109
2121.03	72.783
2123.93	77.6924
2126.83	83.9377
2129.73	89.4428
2132.63	95.5131
2135.53	101.196
2138.42	107.267
2141.32	113.723
2144.21	119.783
2147.1	124.675
2150	131.742
2152.89	136.365
2155.78	140.216
2158.66	145.628
2161.55	150.581
2164.44	153.191
2167.32	156.828
2170.21	156.989
2173.09	158.745
2175.97	157.699
2178.85	154.848
2181.73	151.038
2184.61	147.244
2187.49	143.022
2190.37	138.888
2193.24	134.553
2196.12	130.612
2198.99	125.543
2201.87	118.254
2204.74	112.689
2207.61	107.18
2210.48	100.921
2213.35	95.1536
2216.21	90.4907
2219.08	85.7365
2221.95	80.7717
2224.81	74.2616
2227.67	69.6323
2230.54	67.4382
2233.4	62.2934
2236.26	56.5998
2239.11	53.0285
2241.97	48.6825
2244.83	45.6071
2247.69	42.4182
2250.54	39.1045
2253.4	36.6976
2256.25	35.146
2259.1	34.0549
2261.95	32.5953
2264.8	31.7097
2267.65	31.1594
2270.5	31.1799
2273.34	29.9379
2276.19	29.477
2279.03	27.037
2281.88	25.6295
2284.72	24.5664
2287.56	23.0507
2290.4	20.0153
2293.24	18.1984
2296.08	17.4302
2298.92	16.7232
2301.76	15.6845
2304.59	13.5245
2307.43	11.6016
2310.26	11.6493
2313.09	10.8199
2315.92	10.6276
2318.75	11.3613
2321.58	10.0457
2324.41	9.64975
2327.24	8.80006
2330.06	7.86932
2332.89	7.56682
2335.71	7.99551
2338.54	8.31437
2341.36	6.94901
2344.18	6.20156
2347	5.07359
2349.82	3.55018
2352.64	4.03656
2355.45	1.83359
2358.27	2.06573
2361.08	2.0099
2363.9	2.24945
2366.71	3.38412
2369.52	2.73429
2372.33	3.38241
2375.14	2.91422
2377.95	2.93246
2380.76	4.49056
2383.57	4.75253
2386.37	4.60625
2389.18	5.31721
2391.98	5.51577
2394.79	5.28461
2397.59	4.72077
2400.39	5.15786
2403.19	6.28884
2405.99	7.63016
2408.78	9.29219
2411.58	9.01978
2414.38	9.15596
2417.17	8.94211
2419.97	9.81303
2422.76	8.82664
2425.55	10.0099
2428.34	10.8709
2431.13	11.2433
2433.92	11.6956
2436.71	10.8851
2439.49	10.3527
2442.28	10.3835
2445.06	8.58736
2447.85	8.99107
2450.63	9.13056
2453.41	7.94563
2456.19	8.84263
2458.97	8.18583
2461.75	7.58386
2464.53	6.76131
2467.31	6.72452
2470.08	6.14379
2472.86	6.92649
2475.63	6.86352
2478.4	6.3906
2481.17	4.90769
2483.94	5.5165
2486.72	4.25379
2489.48	4.17272
2492.25	3.48582
2495.02	3.17013
2497.79	2.35309
2500.55	2.26395
2503.31	0.872978
2506.08	0.606884
2508.84	0.291373
2511.6	0.200627
2514.36	0.324915
2517.12	1.2235
2519.88	0.870917
2522.63	2.24657
2525.39	1.9916
2528.14	1.4915
2530.9	3.4
2533.65	3.78223
2536.4	4.87854
2539.15	6.39004
2541.9	6.67766
2544.65	8.19692
2547.4	6.84316
2550.15	6.84099
2552.89	6.53036
2555.64	6.41176
2558.38	7.00727
2561.12	5.92597
2563.87	6.28414
2566.61	7.32147
2569.35	8.52676
2572.09	7.80135
2574.83	9.00566
2577.56	9.65472
2580.3	10.3827
2583.04	9.65474
2585.77	10.7516
2588.5	10.2807
2591.23	9.54585
2593.97	9.29509
2596.7	10.0322
2599.43	9.63085
2602.15	8.97983
2604.88	8.68923
2607.61	8.47143
2610.33	7.60684
2613.06	6.47738
2615.78	5.00419
2618.51	5.78714
2621.23	6.6215
2623.95	7.60763
2626.67	7.0984
2629.39	6.97469
2632.1	8.69418
2634.82	8.61502
2637.54	8.06817
2640.25	8.30184
2642.97	7.85981
2645.68	8.70851
2648.39	8.5222
2651.1	7.76031
2653.81	5.89675
2656.52	5.9789
2659.23	6.88944
2661.94	7.21583
2664.64	5.74778
2667.35	4.74079
2670.05	3.69851
2672.76	3.24368
2675.46	4.5373
2678.16	4.05847
2680.86	6.13901
2683.56	6.64478
2686.26	8.98028
2688.96	9.11452
2691.65	9.23274
2694.35	9.98911
2697.04	11.8428
2699.74	13.5406
2702.43	13.8405
2705.12	13.9018
2707.81	15.1742
2710.5	17.6652
2713.19	19.7597
2715.88	20.6555
2718.57	21.393
2721.25	22.4707
2723.94	22.6982
2726.62	23.1059
2729.3	21.6762
2731.99	21.3944
2734.67	20.2844
2737.35	19.3458
2740.03	19.2888
2742.71	17.1624
2745.38	15.4277
2748.06	13.8465
2750.74	11.942
2753.41	10.755
2756.09	8.52455
2758.76	6.46615
2761.43	6.7107
2764.1	5.07428
2766.77	3.74061
2769.44	2.84522
2772.11	1.69926
2774.77	1.27221
2777.44	1.33532
2780.11	1.08121
2782.77	0.229777
2785.43	0.550379
2788.1	0.37005
2790.76	0.892057
2793.42	1.38441
2796.08	1.01266
2798.74	1.71023
2801.4	1.87964
2804.05	1.84184
2806.71	1.37581
2809.36	0.614611
2812.02	2.38821
2814.67	3.68996
2817.32	5.64928
2819.97	11.0368
2822.62	17.9427
2825.27	27.4148
2827.92	38.5328
2830.57	53.9586
2833.22	70.6773
2835.86	87.3948
2838.51	106.093
2841.15	127.386
2843.79	151.706
2846.43	175.114
2849.08	200.035
2851.72	224.079
2854.36	249.561
2856.99	274.932
2859.63	298.902
2862.27	322.484
2864.9	344.521
2867.54	362.299
2870.17	379.301
2872.8	394.391
2875.43	408.038
2878.07	420.664
2880.7	434.477
2883.32	447.645
2885.95	463.379
2888.58	478.691
2891.21	495.01
2893.83	513.262
2896.46	532.324
2899.08	552.01
2901.7	573.805
2904.32	598.708
2906.94	624.993
2909.56	651.838
2912.18	678.606
2914.8	705.947
2917.42	730.715
2920.03	752.128
2922.65	768.475
2925.26	779.02
2927.88	784.57
2930.49	783.024
2933.1	774.88
2935.71	761.427
2938.32	742.664
2940.93	719.39
2943.54	694.213
2946.14	665.2
2948.75	634.144
2951.35	601.538
2953.96	567.16
2956.56	533.513
2959.16	500.684
2961.77	471.564
2964.37	442.744
2966.96	417.529
2969.56	394.587
2972.16	373.725
2974.76	353.842
2977.35	334.324
2979.95	314.503
2982.54	292.84
2985.14	271.674
2987.73	249.313
2990.32	227.722
2992.91	205.341
2995.5	183.139
2998.09	161.507
3000.68	142.272
3003.26	122.905
3005.85	105.162
3008.43	89.6259
3011.02	73.6779
3013.6	60.2481
3016.19	48.2954
3018.77	38.2487
3021.35	29.2998
3023.93	24.189
3026.5	19.8732
3029.08	17.5545
3031.66	15.6659
3034.24	14.9859
3036.81	16.3156
3039.39	16.7693
3041.96	17.4612
3044.53	18.8983
3047.1	20.9392
3049.67	22.7591
3052.24	25.0383
3054.81	26.2807
3057.38	26.8938
3059.95	27.3697
3062.52	26.9764
3065.08	25.4105
3067.65	23.8632
3070.21	21.202
3072.77	18.5772
3075.33	15.2435
3077.89	12.5326
3080.45	10.6936
3083.01	7.96396
3085.57	6.10234
3088.13	5.50488
3090.68	4.57537
3093.24	3.22436
3095.79	1.69563
3098.35	2.68152
3100.9	2.9928
3103.45	5.11567
3106	7.4356
3108.55	10.9958
3111.1	13.822
3113.65	18.4866
3116.2	21.1835
3118.75	25.0445
3121.29	28.8919
3123.84	32.0176
3126.38	35.3025
3128.92	39.5047
3131.47	42.6727
3134.01	46.6237
3136.55	50.7527
3139.09	55.1623
3141.63	58.7261
3144.17	61.1665
3146.7	63.0429
3149.24	62.6663