File: data/Raman/poly_smoothed/Mb_40_24_22_1x_45s_532 nm_x100_100%_600 gr_mm_01.txt
#Acq. time (s)=	45
#Accumulations=	2
#Range (cm-¹)=	200...3150
#Windows=	2
#Auto scanning=	Off
#Autofocus=	Off
#Macrospot=	Off
#AutoExposure=	Off
#Spike filter=	Multiple accum.
#Delay time (s)=	0
#Binning=	1
#Readout mode=	Signal
#DeNoise=	Off
#ICS correction=	On
#Dark correction=	Off
#Inst. Process=	Off
#Detector Gain=	Best Dynamic Range
#Detector ADC=	20 kHz
#Detector temperature (°C)=	-70.08
#Instrument=	LabRAM HR Evol
#Detector=	Synapse
#Objective=	x100
#Grating=	600 gr/mm
#ND Filter=	100%
#Laser (nm)=	532
#Hole=	100.021
#Range=	Auto
#Laser Pol.=	No
#Raman. Pol.=	No
#Laser Pol. (°)=	-0.0007625
#Raman Pol. (°)=	89.9995
#Collection=	Microscope
#StageXY=	Marzhauser
#StageZ=	Marzhauser
#X (µm)=	-2521.1
#Y (µm)=	-104.7
#Z (µm)=	-10.7
#Full time(mm:ss)=	3:19
#Project=
#Sample=
#Site=
#Title=	Mb_40_24_22_2x_45s_532 nm_x100_100%_600 gr_mm
#Remark=
#Date=	14.07.2022 12:19
#Acquired=	14.07.2022 12:19:37
#Base:Fit=	10.08.2022 10:47:00
#Base:Sub=	10.08.2022 10:47:12
#Filter:Polynom=	16.08.2022 10:11:48
#AxisType[0]=Intens
#AxisUnit[0]=Cnt
#AxisType[1]=Spectr
#AxisUnit[1]=1/cm
200.554	21.5262
204.183	16.7417
207.813	11.9625
211.439	8.53726
215.065	6.41974
218.688	5.74868
222.312	6.9241
225.933	9.27552
229.552	10.6578
233.171	10.0639
236.787	9.57243
240.402	8.0552
244.015	7.84241
247.627	9.781
251.24	11.3946
254.849	12.0371
258.457	14.251
262.063	15.4721
265.668	17.0174
269.271	17.8388
272.873	16.122
276.474	17.8785
280.073	17.3046
283.671	18.9597
287.268	18.7999
290.863	18.2621
294.456	21.9135
298.049	23.3741
301.637	24.9455
305.227	26.0823
308.815	30.3004
312.402	31.5486
315.987	33.6982
319.569	31.8414
323.151	32.6579
326.733	32.3613
330.31	32.1996
333.889	33.1544
337.464	33.3615
341.039	31.5773
344.611	33.3577
348.184	33.539
351.754	33.1086
355.324	32.2049
358.89	32.2029
362.455	30.6422
366.021	31.5399
369.584	29.2581
373.145	28.3989
376.707	27.8704
380.265	27.3453
383.822	25.8405
387.378	26.1662
390.934	25.2355
394.487	25.4267
398.038	24.5898
401.588	24.9784
405.137	25.419
408.685	25.5099
412.23	24.9586
415.775	25.1772
419.318	23.4522
422.86	22.8729
426.401	23.2379
429.94	21.4728
433.478	21.2353
437.012	21.886
440.547	21.4978
444.081	21.5327
447.613	20.0281
451.142	18.8004
454.672	17.9465
458.2	17.7909
461.725	17.8123
465.251	19.7888
468.775	19.5289
472.296	22.7722
475.817	23.7444
479.335	23.9572
482.854	24.5748
486.37	26.5918
489.886	27.6891
493.398	29.5373
496.91	29.9051
500.422	31.2707
503.93	31.6989
507.438	29.2149
510.946	28.3817
514.45	26.4557
517.954	26.2876
521.456	25.5323
524.956	25.1733
528.456	22.8952
531.956	20.5604
535.452	19.385
538.947	20.0772
542.441	21.5109
545.934	21.142
549.425	20.6825
552.915	20.9763
556.403	19.5048
559.889	18.2027
563.375	16.4739
566.859	15.3348
570.342	13.2804
573.824	10.2154
577.303	11.0678
580.782	10.5025
584.26	9.65105
587.734	9.28382
591.21	7.56741
594.684	6.2941
598.154	5.2867
601.626	5.41107
605.094	6.16267
608.562	7.77886
612.027	7.77316
615.493	8.42492
618.956	8.95932
622.419	11.2127
625.879	11.7817
629.338	13.2849
632.797	11.6807
636.254	14.1029
639.708	14.7967
643.162	14.6027
646.614	14.377
650.067	14.1928
653.516	13.7407
656.964	14.2011
660.411	17.5737
663.857	18.403
667.301	20.4916
670.744	22.5399
674.186	24.8828
677.626	25.6944
681.065	28.0723
684.503	29.1314
687.939	30.7248
691.372	30.2126
694.806	30.3215
698.239	32.067
701.67	33.0461
705.098	34.4789
708.526	34.9643
711.954	36.1267
715.378	37.1618
718.802	38.708
722.226	38.309
725.646	36.991
729.067	38.6083
732.484	39.3925
735.902	38.4073
739.317	37.6876
742.731	40.429
746.145	42.5793
749.556	45.6199
752.966	47.9734
756.377	50.4426
759.784	53.2517
763.19	54.8722
766.594	58.4484
770	62.3482
773.402	64.1822
776.803	64.6369
780.202	66.8054
783.6	70.4907
786.997	72.5469
790.393	75.0906
793.787	75.0955
797.18	75.6095
800.572	75.0908
803.963	73.2264
807.35	72.2839
810.738	71.0242
814.125	69.9447
817.51	66.5063
820.894	64.6783
824.275	64.3686
827.657	64.5947
831.037	64.3706
834.414	62.9446
837.792	64.1195
841.167	63.5911
844.542	63.9272
847.914	64.7275
851.287	64.958
854.656	63.8278
858.026	60.7737
861.393	60.132
864.761	60.2831
868.125	57.7356
871.489	56.3238
874.85	56.494
878.213	55.0321
881.572	53.7093
884.931	52.1355
888.287	50.7408
891.643	49.2812
894.997	47.4206
898.352	46.9726
901.704	44.4707
905.055	43.5711
908.404	42.0314
911.75	41.5446
915.097	40.7996
918.443	40.971
921.787	41.3628
925.13	38.9054
928.472	37.5069
931.813	36.997
935.15	35.1162
938.488	31.6224
941.825	29.3598
945.158	27.5527
948.493	25.2598
951.824	27.1913
955.156	26.9553
958.486	26.0368
961.814	25.2617
965.142	25.5617
968.467	26.4643
971.79	26.6284
975.115	27.3407
978.436	27.2562
981.756	28.7943
985.077	29.322
988.394	27.9255
991.71	28.082
995.025	27.2884
998.341	24.5788
1001.65	23.0239
1004.97	21.6675
1008.28	18.0903
1011.58	18.4945
1014.89	17.2407
1018.2	16.282
1021.5	16.4785
1024.81	17.2246
1028.11	18.2482
1031.41	19.4275
1034.71	21.3672
1038.01	20.9758
1041.31	20.8355
1044.6	21.7333
1047.9	23.8149
1051.19	24.1985
1054.48	24.8611
1057.77	24.6348
1061.06	26.713
1064.35	24.9484
1067.64	22.9276
1070.93	20.1174
1074.21	18.8699
1077.49	16.5677
1080.78	15.5136
1084.06	14.8926
1087.34	12.7685
1090.61	12.5378
1093.89	13.6596
1097.17	13.8571
1100.44	13.2611
1103.71	13.8064
1106.99	15.513
1110.26	14.3987
1113.52	13.1228
1116.79	13.9831
1120.06	13.2178
1123.32	12.5035
1126.59	12.7773
1129.85	11.8501
1133.11	10.6327
1136.37	9.87316
1139.63	9.55706
1142.89	9.80245
1146.15	9.28342
1149.4	9.47384
1152.66	7.85806
1155.91	6.0548
1159.16	4.10692
1162.41	4.29781
1165.66	3.13778
1168.91	4.00001
1172.16	6.00038
1175.4	7.06774
1178.65	8.56409
1181.89	9.99931
1185.13	11.9722
1188.37	12.9676
1191.61	15.5182
1194.85	16.5053
1198.08	18.0812
1201.32	18.4138
1204.55	18.4312
1207.79	18.4747
1211.02	18.1217
1214.25	19.2516
1217.48	21.6882
1220.71	23.1388
1223.93	21.9693
1227.16	21.5865
1230.38	21.7252
1233.6	22.2633
1236.83	22.9191
1240.05	26.479
1243.26	27.9636
1246.48	28.6984
1249.7	30.5808
1252.92	31.5789
1256.13	33.6589
1259.34	34.5113
1262.55	35.3219
1265.76	37.9599
1268.97	40.3695
1272.18	41.2646
1275.39	42.2053
1278.59	42.9333
1281.8	46.5993
1285	50.7145
1288.2	53.2224
1291.4	57.6585
1294.6	60.5177
1297.8	61.8846
1301	62.4399
1304.19	63.8222
1307.39	66.6713
1310.58	68.6546
1313.77	70.7964
1316.96	71.0358
1320.15	71.2437
1323.34	69.6041
1326.53	69.3465
1329.72	68.8176
1332.9	67.089
1336.08	65.3967
1339.27	63.3384
1342.45	61.1931
1345.63	60.3781
1348.8	57.7911
1351.98	57.1436
1355.16	57.3272
1358.33	58.0779
1361.51	58.2172
1364.68	59.6416
1367.85	59.0495
1371.02	58.7995
1374.19	58.4077
1377.36	58.2576
1380.52	59.1748
1383.69	59.6954
1386.85	58.1852
1390.02	57.32
1393.18	56.8454
1396.34	56.9036
1399.5	58.7453
1402.65	59.8681
1405.81	61.2119
1408.97	63.4765
1412.12	65.9633
1415.27	66.9009
1418.43	68.1828
1421.58	72.9972
1424.73	77.4346
1427.87	82.2497
1431.02	88.5648
1434.17	92.8172
1437.31	97.2863
1440.46	99.7208
1443.6	103.029
1446.74	104.964
1449.88	106.751
1453.02	108.098
1456.16	109.762
1459.29	109
1462.43	107.745
1465.56	107.036
1468.69	104.474
1471.83	103.078
1474.95	101.62
1478.08	98.2875
1481.21	92.9705
1484.34	88.6667
1487.47	82.9202
1490.59	76.4644
1493.71	70.6104
1496.84	66.4171
1499.96	62.077
1503.07	58.2444
1506.19	53.4977
1509.31	49.5323
1512.43	42.8271
1515.54	38.0546
1518.65	33.7381
1521.77	32.9841
1524.88	31.894
1527.99	31.3563
1531.1	31.4682
1534.21	31.9774
1537.31	33.5044
1540.42	36.1654
1543.52	36.6249
1546.63	38.5638
1549.73	41.9873
1552.83	43.2517
1555.93	44.3499
1559.03	46.3889
1562.12	48.3526
1565.22	50.6649
1568.31	53.7311
1571.41	56.5461
1574.5	60.1451
1577.59	65.4074
1580.68	68.373
1583.77	72.7592
1586.86	75.9781
1589.95	78.004
1593.03	80.9863
1596.11	82.8862
1599.2	83.5092
1602.28	82.735
1605.36	81.5804
1608.44	80.3879
1611.52	78.1205
1614.6	75.5928
1617.67	74.4073
1620.75	72.2827
1623.82	71.3026
1626.89	69.2509
1629.96	67.3632
1633.04	64.891
1636.11	64.524
1639.17	63.5873
1642.24	62.9295
1645.31	64.2494
1648.37	65.533
1651.43	65.7351
1654.5	64.1418
1657.56	65.675
1660.62	64.2314
1663.67	61.7859
1666.73	57.3131
1669.79	54.8039
1672.84	51.8269
1675.9	47.0577
1678.95	43.6417
1682	39.8734
1685.05	35.4377
1688.1	32.5308
1691.15	29.7777
1694.2	27.3885
1697.25	24.9017
1700.29	22.4142
1703.33	19.8439
1706.38	18.2352
1709.42	17.342
1712.46	16.8887
1715.5	17.7023
1718.54	17.5807
1721.57	17.967
1724.61	16.7399
1727.64	16.4366
1730.68	16.429
1733.71	14.885
1736.74	11.2051
1739.77	10.0191
1742.8	9.86042
1745.83	9.3826
1748.85	8.14759
1751.88	8.06508
1754.91	6.75798
1757.93	7.14737
1760.95	7.11872
1763.97	6.61056
1766.99	4.96361
1770.01	3.89303
1773.03	3.3144
1776.04	3.36536
1779.06	2.75657
1782.07	2.81609
1785.09	3.14132
1788.1	3.2147
1791.11	3.25551
1794.12	2.76663
1797.13	1.98436
1800.13	2.18867
1803.14	1.67669
1806.15	0.509071
1809.15	-0.645057
1812.15	0.341461
1815.16	0.851221
1818.15	0.828264
1821.16	1.20503
1824.15	1.58906
1827.15	1.33954
1830.15	1.60516
1833.14	2.4422
1836.14	2.1301
1839.13	2.55123
1842.12	2.39868
1845.11	2.59974
1848.1	3.26349
1851.09	3.22959
1854.08	3.24436
1857.06	3.8003
1860.05	3.36108
1863.03	3.98121
1866.01	4.09709
1869	4.16947
1871.98	4.81678
1874.96	5.47864
1877.93	5.63726
1880.91	5.69245
1882.47	5.80228
1885.46	5.62876
1888.44	5.14117
1891.43	3.98899
1894.42	3.56114
1897.4	3.33984
1900.39	2.61456
1903.37	2.39463
1906.35	1.42027
1909.33	1.28251
1912.31	2.41319
1915.29	2.63
1918.26	2.53989
1921.24	2.45082
1924.21	2.49155
1927.19	1.95608
1930.16	2.72298
1933.13	3.16368
1936.1	2.915
1939.07	4.75237
1942.04	5.22067
1945	7.07669
1947.97	7.45577
1950.93	7.28609
1953.9	7.16521
1956.86	8.06799
1959.82	8.51781
1962.78	7.54581
1965.74	6.32728
1968.7	5.96636
1971.65	6.50168
1974.61	5.36342
1977.57	4.23969
1980.52	3.6716
1983.47	4.66906
1986.42	4.0903
1989.37	3.75871
1992.32	2.33082
1995.27	1.8124
1998.22	0.97199
2001.17	1.96498
2004.11	1.65157
2007.05	0.941832
2010	2.94748
2012.94	3.87477
2015.88	4.21252
2018.82	4.50824
2021.76	4.27026
2024.7	4.93249
2027.63	6.48712
2030.57	6.33978
2033.5	6.27697
2036.44	6.12187
2039.37	7.33554
2042.3	9.28142
2045.23	9.39888
2048.16	9.71375
2051.08	10.0485
2054.01	11.3734
2056.94	11.3812
2059.86	12.4021
2062.79	14.058
2065.71	15.4145
2068.63	16.5328
2071.55	17.3411
2074.47	18.295
2077.39	19.432
2080.31	21.2303
2083.22	22.6044
2086.13	22.8425
2089.05	23.5692
2091.96	23.9725
2094.87	25.2825
2097.78	26.6012
2100.69	27.1614
2103.6	27.7045
2106.51	29.0563
2109.42	30.8391
2112.32	32.0585
2115.23	32.488
2118.13	33.182
2121.03	33.6485
2123.93	35.033
2126.83	37.4001
2129.73	38.3607
2132.63	41.4175
2135.53	43.9935
2138.42	46.6091
2141.32	48.6787
2144.21	50.861
2147.1	53.6759
2150	55.9687
2152.89	57.4666
2155.78	57.9398
2158.66	60.0703
2161.55	60.8388
2164.44	61.9459
2167.32	62.9538
2170.21	64.6038
2173.09	63.8621
2175.97	63.8213
2178.85	64.3457
2181.73	62.0962
2184.61	59.8929
2187.49	57.7475
2190.37	56.7063
2193.24	54.0994
2196.12	52.2757
2198.99	50.0008
2201.87	48.3696
2204.74	47.2996
2207.61	44.4866
2210.48	43.4048
2213.35	40.9122
2216.21	39.1318
2219.08	37.2224
2221.95	35.8488
2224.81	33.8891
2227.67	32.3565
2230.54	30.7636
2233.4	29.0152
2236.26	26.9847
2239.11	25.6287
2241.97	23.5482
2244.83	21.5785
2247.69	20.0029
2250.54	18.9061
2253.4	17.079
2256.25	16.7035
2259.1	15.615
2261.95	15.3369
2264.8	14.379
2267.65	14.7306
2270.5	14.7891
2273.34	14.5419
2276.19	13.2391
2279.03	13.2211
2281.88	13.7296
2284.72	13.7986
2287.56	13.173
2290.4	12.3899
2293.24	10.4966
2296.08	10.1182
2298.92	10.5629
2301.76	9.85549
2304.59	9.30406
2307.43	9.07563
2310.26	8.43389
2313.09	8.71158
2315.92	9.581
2318.75	10.7013
2321.58	10.6166
2324.41	9.51095
2327.24	11.3773
2330.06	11.0751
2332.89	10.7399
2335.71	11.4352
2338.54	11.5728
2341.36	10.3064
2344.18	9.42162
2347	8.16333
2349.82	8.08957
2352.64	6.5225
2355.45	5.37595
2358.27	3.94131
2361.08	2.72572
2363.9	2.76641
2366.71	2.3326
2369.52	1.55397
2372.33	-0.096747
2375.14	0.340689
2377.95	0.229411
2380.76	0.535923
2383.57	1.34132
2386.37	1.9715
2389.18	1.12008
2391.98	2.12953
2394.79	3.12994
2397.59	3.4683
2400.39	4.2327
2403.19	6.15524
2405.99	8.0274
2408.78	7.98182
2411.58	8.8725
2414.38	9.10793
2417.17	9.11409
2419.97	9.17667
2422.76	9.87298
2425.55	10.6961
2428.34	9.51923
2431.13	8.2035
2433.92	6.61985
2436.71	6.45346
2439.49	5.75802
2442.28	5.50818
2445.06	4.87872
2447.85	5.13791
2450.63	4.75103
2453.41	4.47462
2456.19	3.73088
2458.97	4.28488
2461.75	3.88509
2464.53	3.53028
2467.31	3.75883
2470.08	5.59318
2472.86	5.47146
2475.63	5.61758
2478.4	5.33021
2481.17	5.7709
2483.94	4.67994
2486.72	5.76818
2489.48	4.80724
2492.25	3.71549
2495.02	2.14881
2497.79	0.602688
2500.55	-1.07569
2503.31	-0.380286
2506.08	0.643127
2508.84	0.173628
2511.6	0.3693
2514.36	0.934523
2517.12	1.46282
2519.88	0.52464
2522.63	0.318517
2525.39	0.644307
2528.14	2.17623
2530.9	2.74325
2533.65	4.03453
2536.4	5.6281
2539.15	6.68545
2541.9	7.08609
2544.65	7.14365
2547.4	8.11812
2550.15	7.85859
2552.89	7.87063
2555.64	7.92533
2558.38	6.50967
2561.12	5.5282
2563.87	4.18274
2566.61	4.61281
2569.35	5.34049
2572.09	5.86689
2574.83	5.21765
2577.56	4.42981
2580.3	3.67806
2583.04	3.87407
2585.77	2.91453
2588.5	1.44074
2591.23	2.32472
2593.97	4.03766
2596.7	4.76878
2599.43	4.03008
2602.15	4.82882
2604.88	6.05037
2607.61	5.8917
2610.33	5.00013
2613.06	5.19902
2615.78	5.67823
2618.51	6.68847
2621.23	5.70586
2623.95	5.92857
2626.67	5.91259
2629.39	6.24349
2632.1	7.10906
2634.82	8.01417
2637.54	7.46247
2640.25	7.75841
2642.97	7.62608
2645.68	7.8674
2648.39	8.72964
2651.1	8.90691
2653.81	9.71428
2656.52	9.54524
2659.23	9.06651
2661.94	9.63677
2664.64	10.3805
2667.35	10.1567
2670.05	10.3387
2672.76	10.6889
2675.46	9.72698
2678.16	9.79481
2680.86	9.09434
2683.56	7.89267
2686.26	7.83533
2688.96	6.04207
2691.65	7.52344
2694.35	6.61231
2697.04	6.76062
2699.74	6.40618
2702.43	5.63467
2705.12	5.62934
2707.81	4.94851
2710.5	4.86873
2713.19	5.33868
2715.88	5.17991
2718.57	5.37016
2721.25	4.87241
2723.94	4.81653
2726.62	5.82309
2729.3	6.22376
2731.99	6.80369
2734.67	6.39735
2737.35	5.87457
2740.03	6.19797
2742.71	6.32189
2745.38	6.0791
2748.06	6.47012
2750.74	5.84076
2753.41	6.9808
2756.09	7.37268
2758.76	7.4367
2761.43	6.3958
2764.1	6.28953
2766.77	4.9824
2769.44	4.34502
2772.11	3.66954
2774.77	2.8936
2777.44	2.21069
2780.11	1.06774
2782.77	0.980214
2785.43	1.52487
2788.1	0.780013
2790.76	0.718426
2793.42	0.192475
2796.08	-0.559388
2798.74	-0.184325
2801.4	-0.0844699
2804.05	0.355248
2806.71	0.972375
2809.36	0.637949
2812.02	0.725549
2814.67	1.37192
2817.32	2.85195
2819.97	6.2923
2822.62	10.2717
2825.27	14.7511
2827.92	19.1899
2830.57	24.6394
2833.22	32.5247
2835.86	40.2808
2838.51	48.0798
2841.15	54.8613
2843.79	64.1622
2846.43	73.2816
2849.08	82.5653
2851.72	92.1978
2854.36	101.623
2856.99	111.45
2859.63	120.552
2862.27	128.308
2864.9	136.436
2867.54	142.138
2870.17	146.372
2872.8	151.495
2875.43	156.395
2878.07	161.482
2880.7	166.709
2883.32	173.676
2885.95	179.444
2888.58	185.413
2891.21	191.622
2893.83	197.913
2896.46	203.551
2899.08	209.746
2901.7	215.837
2904.32	223.586
2906.94	231.214
2909.56	239.069
2912.18	246.618
2914.8	253.301
2917.42	261.625
2920.03	268.81
2922.65	272.869
2925.26	276.099
2927.88	277.337
2930.49	275.909
2933.1	273.098
2935.71	269.521
2938.32	265.296
2940.93	258.842
2943.54	251.898
2946.14	243.799
2948.75	234.571
2951.35	224.795
2953.96	215.347
2956.56	204.112
2959.16	193.014
2961.77	181.778
2964.37	171.437
2966.96	161.811
2969.56	152.144
2972.16	142.093
2974.76	132.698
2977.35	124.298
2979.95	116.389
2982.54	108.035
2985.14	98.5097
2987.73	88.9188
2990.32	79.9747
2992.91	70.8347
2995.5	62.0655
2998.09	54.2488
3000.68	46.9462
3003.26	40.1945
3005.85	34.0263
3008.43	28.4892
3011.02	23.2737
3013.6	19.7595
3016.19	15.966
3018.77	11.7683
3021.35	8.77083
3023.93	5.9829
3026.5	3.64909
3029.08	1.50006
3031.66	0.632233
3034.24	0.828099
3036.81	0.562152
3039.39	2.29387
3041.96	3.97066
3044.53	5.06436
3047.1	4.97577
3049.67	4.81465
3052.24	5.18555
3054.81	6.40857
3057.38	6.91483
3059.95	7.08613
3062.52	7.07065
3065.08	7.21005
3067.65	7.73896
3070.21	7.15065
3072.77	6.4722
3075.33	5.27262
3077.89	4.50563
3080.45	3.14203
3083.01	3.3587
3085.57	2.75623
3088.13	1.91959
3090.68	1.48019
3093.24	1.76022
3095.79	2.12102
3098.35	2.77664
3100.9	4.31182
3103.45	5.68768
3106	6.352
3108.55	6.71057
3111.1	8.03539
3113.65	9.60946
3116.2	10.7942
3118.75	11.7815
3121.29	12.2739
3123.84	14.0208
3126.38	16.4017
3128.92	17.8324
3131.47	19.5161
3134.01	21.3123
3136.55	22.8074
3139.09	25.4275
3141.63	28.0515
3144.17	30.7866
3146.7	34.044
3149.24	37.2365