File: data/Raman/poly_smoothed/Mb_40_y_31_1x_45s_532 nm_x100_100%_600 gr_mm_01.txt
#Acq. time (s)=	45
#Accumulations=	2
#Range (cm-¹)=	200...3150
#Windows=	2
#Auto scanning=	Off
#Autofocus=	Off
#Macrospot=	Off
#AutoExposure=	Off
#Spike filter=	Multiple accum.
#Delay time (s)=	0
#Binning=	1
#Readout mode=	Signal
#DeNoise=	Off
#ICS correction=	On
#Dark correction=	Off
#Inst. Process=	Off
#Detector Gain=	Best Dynamic Range
#Detector ADC=	20 kHz
#Detector temperature (°C)=	-69.85
#Instrument=	LabRAM HR Evol
#Detector=	Synapse
#Objective=	x100
#Grating=	600 gr/mm
#ND Filter=	100%
#Laser (nm)=	532
#Hole=	100.021
#Range=	Auto
#Laser Pol.=	No
#Raman. Pol.=	No
#Laser Pol. (°)=	-0.0007625
#Raman Pol. (°)=	89.9995
#Collection=	Microscope
#StageXY=	Marzhauser
#StageZ=	Marzhauser
#X (µm)=	-1122.1
#Y (µm)=	567
#Z (µm)=	584.2
#Full time(mm:ss)=	3:18
#Project=
#Sample=
#Site=
#Title=	Mb_40_y_31_2x_45s_532 nm_x100_100%_600 gr_mm
#Remark=
#Date=	19.07.2022 12:00
#Acquired=	19.07.2022 12:00:04
#Base:Fit=	10.08.2022 10:52:48
#Base:Sub=	10.08.2022 10:52:53
#Filter:Polynom=	16.08.2022 10:09:04
#AxisType[0]=Intens
#AxisUnit[0]=Cnt
#AxisType[1]=Spectr
#AxisUnit[1]=1/cm
200.423	49.0752
204.052	37.7502
207.682	29.1665
211.308	21.8339
214.935	16.2478
218.558	11.1362
222.18	7.28438
225.802	6.11116
229.421	4.87664
233.039	3.46122
236.657	2.21807
240.272	1.19925
243.885	0.123459
247.497	0.0730908
251.11	2.36471
254.719	3.82888
258.327	3.89325
261.933	5.74454
265.538	7.19612
269.141	9.17299
272.744	9.13166
276.344	9.66448
279.944	10.2133
283.542	9.62308
287.138	9.05339
290.733	8.89919
294.327	10.7662
297.919	11.2969
301.508	12.1001
305.098	12.5511
308.686	13.1866
312.273	13.0065
315.858	12.4335
319.44	10.72
323.022	10.3688
326.604	9.43643
330.181	8.58854
333.76	8.4271
337.335	9.01409
340.91	7.80838
344.483	7.50637
348.055	7.16962
351.625	8.62996
355.195	8.03095
358.762	7.86318
362.329	7.75547
365.893	7.93275
369.455	7.17174
373.017	8.33865
376.578	8.78293
380.137	10.7355
383.694	10.4293
387.249	10.1069
390.806	10.2341
394.359	7.9387
397.91	7.4694
401.46	6.55833
405.009	6.59376
408.557	5.7112
412.103	5.66438
415.647	5.4514
419.191	5.85137
422.733	5.78464
426.273	6.16813
429.812	6.72316
433.35	8.90178
436.885	9.00516
440.42	10.2589
443.954	8.81411
447.486	8.9949
451.015	9.19756
454.545	9.52504
458.073	10.3022
461.598	9.714
465.124	9.66787
468.648	10.1453
472.169	9.45153
475.69	10.3238
479.208	12.0074
482.727	12.2477
486.243	13.9683
489.759	13.2199
493.272	14.3915
496.783	15.9918
500.295	17.0309
503.804	17.4579
507.311	19.552
510.819	20.6473
514.324	21.4879
517.827	20.6945
521.329	21.8362
524.83	20.1265
528.329	20.0708
531.829	18.369
535.326	18.3017
538.821	19.7268
542.315	21.1087
545.808	21.8847
549.299	21.7801
552.789	21.5652
556.278	21.2503
559.763	20.7338
563.249	19.5766
566.733	19.3958
570.217	17.2357
573.699	15.0154
577.177	15.5954
580.656	14.9947
584.134	13.1618
587.609	11.0124
591.084	10.9682
594.558	8.79067
598.029	7.98773
601.5	7.3801
604.968	7.02407
608.437	6.67502
611.902	5.67086
615.368	5.35015
618.831	6.00409
622.294	7.63127
625.755	10.2062
629.213	11.5942
632.673	13.2095
636.129	13.9163
639.584	14.263
643.037	15.1615
646.491	15.9149
649.942	17.0397
653.392	18.0195
656.84	19.53
660.287	21.8347
663.732	22.9624
667.177	23.8093
670.62	25.4112
674.061	27.9502
677.502	29.5816
680.941	31.6464
684.379	33.4543
687.815	33.884
691.248	34.2278
694.682	35.117
698.115	35.4496
701.546	37.7482
704.974	41.1746
708.402	43.8014
711.83	46.5087
715.254	47.5271
718.679	47.9689
722.102	49.5982
725.522	49.415
728.943	50.97
732.361	50.7901
735.779	51.7057
739.194	52.8214
742.608	54.9644
746.022	56.045
749.433	57.2192
752.843	60.5625
756.254	61.6528
759.661	63.1304
763.067	65.2604
766.471	67.7851
769.877	69.0394
773.279	72.075
776.68	74.2135
780.079	76.959
783.478	79.6774
786.875	81.2766
790.27	84.526
793.665	85.5973
797.058	86.1499
800.45	86.5785
803.84	88.5565
807.23	88.7417
810.616	88.4364
814.002	87.9166
817.388	86.5794
820.772	85.4284
824.153	84.9519
827.535	81.7725
830.915	79.9151
834.292	77.9461
837.67	77.0783
841.047	74.2135
844.42	73.3349
847.794	72.9692
851.165	69.6909
854.534	68.584
857.905	66.0032
861.272	63.8438
864.639	62.493
868.004	59.3712
871.367	56.5643
874.731	55.559
878.092	53.3924
881.451	53.2342
884.809	51.8283
888.166	52.4077
891.522	51.6681
894.878	51.3807
898.231	51.0812
901.583	50.7811
904.934	51.1851
908.283	51.3083
911.631	51.8708
914.976	53.6491
918.322	55.4211
921.666	56.5157
925.009	56.9599
928.351	57.1979
931.692	56.3661
935.029	55.3346
938.367	57.5013
941.704	55.4513
945.038	52.0931
948.372	49.5649
951.705	47.2513
955.035	45.7543
958.366	44.9859
961.693	43.4191
965.021	43.898
968.346	42.526
971.67	42.5106
974.995	42.1648
978.316	40.8094
981.638	38.7567
984.957	39.3359
988.274	37.5531
991.59	36.9251
994.907	34.661
998.221	32.1568
1001.53	28.1005
1004.85	25.6384
1008.16	26.5725
1011.46	35.0374
1014.77	46.9199
1018.08	61.2675
1021.38	73.118
1024.69	83.2193
1027.99	93.36
1031.29	101.982
1034.59	109.458
1037.89	115.967
1041.19	119.903
1044.48	120.064
1047.78	120.062
1051.07	118.58
1054.36	114.256
1057.66	107.1
1060.94	96.6168
1064.23	86.4144
1067.52	74.6931
1070.81	60.625
1074.09	44.7667
1077.38	31.069
1080.66	19.365
1083.94	10.4818
1087.22	7.06761
1090.5	9.88656
1093.77	13.9584
1097.05	16.2396
1100.32	16.9817
1103.6	17.2466
1106.87	16.3711
1110.14	16.1809
1113.41	15.8849
1116.67	15.6047
1119.94	15.6984
1123.21	15.1877
1126.47	14.8248
1129.73	15.4129
1133	14.7357
1136.26	13.7587
1139.52	13.2559
1142.77	13.8428
1146.03	12.2136
1149.29	10.9204
1152.54	11.1901
1155.79	10.2808
1159.04	10.6846
1162.3	7.72541
1165.55	6.69849
1168.79	5.33538
1172.04	4.80144
1175.28	4.56812
1178.53	4.68799
1181.77	4.79328
1185.01	3.48981
1188.25	3.23619
1191.49	3.33966
1194.73	3.63133
1197.97	3.96991
1201.2	5.09495
1204.44	6.81648
1207.67	9.08456
1210.9	9.56032
1214.13	12.6139
1217.36	14.8951
1220.59	18.1316
1223.82	21.695
1227.04	24.0193
1230.26	27.7397
1233.49	30.6196
1236.71	32.5677
1239.93	32.8515
1243.15	35.2537
1246.37	37.996
1249.58	38.1202
1252.8	41.5927
1256.01	44.5023
1259.23	46.4667
1262.44	47.0296
1265.65	47.6966
1268.86	49.5727
1272.07	50.3869
1275.27	52.7271
1278.48	55.2313
1281.68	56.6632
1284.89	57.9063
1288.09	58.4416
1291.29	60.3929
1294.49	60.906
1297.69	61.1596
1300.88	61.6732
1304.08	61.775
1307.27	60.568
1310.47	59.2942
1313.66	57.898
1316.85	55.9978
1320.04	56.1377
1323.23	55.8746
1326.41	53.8404
1329.6	52.0571
1332.78	51.5368
1335.97	50.0991
1339.15	47.5136
1342.33	46.9261
1345.51	44.9514
1348.69	43.8676
1351.87	41.8991
1355.04	40.9351
1358.22	40.9671
1361.39	37.8857
1364.57	36.2794
1367.74	33.9156
1370.91	31.7144
1374.07	30.4491
1377.24	29.1583
1380.41	27.7369
1383.57	27.5349
1386.74	26.4369
1389.9	28.832
1393.06	28.3318
1396.22	31.1535
1399.38	31.7905
1402.54	32.9433
1405.7	34.282
1408.85	36.8385
1412.01	39.3223
1415.16	43.4982
1418.31	45.567
1421.46	48.9053
1424.61	52.7232
1427.76	56.2384
1430.91	60.101
1434.05	64.9628
1437.2	66.1991
1440.34	68.3386
1443.49	68.1401
1446.63	68.2536
1449.77	68.2007
1452.91	65.9819
1456.04	65.3143
1459.18	62.6192
1462.31	59.9412
1465.45	57.3381
1468.58	53.8698
1471.71	49.392
1474.84	44.9388
1477.97	40.4395
1481.1	37.0835
1484.23	33.4653
1487.35	30.8657
1490.48	27.4622
1493.6	25.2916
1496.72	22.8722
1499.84	21.6853
1502.96	20.8539
1506.08	20.932
1509.2	21.1109
1512.31	19.5606
1515.43	18.6591
1518.54	18.3654
1521.66	18.781
1524.77	20.0151
1527.88	20.8798
1530.99	21.9218
1534.09	23.0755
1537.2	22.8795
1540.31	25.4678
1543.41	26.5305
1546.51	28.2705
1549.62	29.7127
1552.72	29.8077
1555.82	31.0996
1558.91	31.6058
1562.01	32.2779
1565.11	34.0259
1568.2	35.5297
1571.3	35.3093
1574.39	36.81
1577.48	37.469
1580.57	39.4773
1583.66	41.8021
1586.75	41.9257
1589.83	43.4313
1592.92	43.7174
1596	45.3735
1599.09	44.7197
1602.17	43.8981
1605.25	44.1459
1608.33	43.399
1611.41	43.5389
1614.48	43.8487
1617.56	45.8567
1620.64	47.1544
1623.71	47.5037
1626.78	48.5768
1629.86	50.6657
1632.92	53.3453
1635.99	55.6944
1639.06	59.0022
1642.13	61.1138
1645.19	63.4234
1648.26	66.2461
1651.32	69.1742
1654.38	70.5468
1657.45	72.7089
1660.51	73.6304
1663.57	71.6525
1666.62	69.9806
1669.68	66.9287
1672.73	63.8306
1675.79	59.5229
1678.84	55.1735
1681.89	51.1711
1684.94	46.4396
1687.99	42.0053
1691.04	38.3968
1694.09	34.8139
1697.14	30.4945
1700.18	27.2244
1703.22	23.0977
1706.27	19.777
1709.31	16.4952
1712.35	14.2634
1715.39	13.2419
1718.43	11.1769
1721.46	10.2935
1724.5	7.77654
1727.53	7.37633
1730.57	6.53715
1733.6	5.8208
1736.63	4.88226
1739.66	4.52127
1742.69	3.80798
1745.72	3.55723
1748.74	4.74024
1751.77	4.50029
1754.8	4.30881
1757.82	4.96186
1760.84	5.43643
1763.86	6.13081
1766.88	5.71387
1769.9	5.63002
1772.92	5.6032
1775.93	4.75214
1778.95	5.64266
1781.96	5.28799
1784.98	4.89247
1787.99	5.40979
1791	5.25777
1794.01	5.00288
1797.02	4.07305
1800.03	4.02963
1803.03	3.58286
1806.04	2.45065
1809.04	2.08059
1812.04	2.11565
1815.05	2.78666
1818.05	3.05293
1821.05	3.52827
1824.05	3.93016
1827.04	4.13836
1830.04	2.97765
1833.03	3.25896
1836.03	3.76168
1839.02	3.50123
1842.01	2.92116
1845	3.54419
1847.99	3.17313
1850.98	3.63319
1853.97	3.53082
1856.95	3.63946
1859.94	3.16219
1862.92	2.60177
1865.91	2.88896
1868.89	2.91795
1871.87	2.03231
1874.85	2.46513
1877.83	2.32401
1880.8	3.42083
1882.56	4.30923
1885.54	5.90867
1888.53	5.97494
1891.52	5.68046
1894.5	5.82434
1897.49	6.19335
1900.47	5.99557
1903.45	5.78984
1906.43	6.20157
1909.41	6.18997
1912.39	5.5512
1915.37	6.01789
1918.35	5.29342
1921.32	5.32191
1924.3	5.0158
1927.27	4.00461
1930.24	4.21286
1933.21	3.4682
1936.18	3.81794
1939.15	3.69754
1942.12	3.30621
1945.09	3.78714
1948.05	4.87463
1951.02	4.49262
1953.98	4.5675
1956.94	4.32365
1959.91	2.31376
1962.87	0.884223
1965.82	0.99995
1968.78	1.75565
1971.74	1.24881
1974.7	1.63096
1977.65	1.56638
1980.6	2.32722
1983.56	2.71481
1986.51	3.39921
1989.46	4.05097
1992.41	4.86616
1995.36	5.10478
1998.3	5.34199
2001.25	5.19174
2004.2	6.59424
2007.14	7.10071
2010.08	7.51693
2013.02	8.37293
2015.97	8.49309
2018.9	9.0969
2021.84	7.14816
2024.78	6.19129
2027.72	6.50791
2030.65	5.94609
2033.59	6.20161
2036.52	7.47391
2039.45	9.30912
2042.38	9.17437
2045.31	10.5343
2048.24	10.8284
2051.17	10.4878
2054.1	11.3308
2057.02	12.1806
2059.95	13.0946
2062.87	13.0234
2065.79	12.9492
2068.71	12.9861
2071.63	14.4646
2074.55	16.2235
2077.47	16.6247
2080.39	17.6016
2083.3	20.7151
2086.22	21.8215
2089.13	22.4369
2092.05	24.0068
2094.96	24.4079
2097.87	26.8623
2100.78	28.4532
2103.69	30.5376
2106.59	33.3341
2109.5	36.2384
2112.41	38.1067
2115.31	39.7023
2118.21	40.9327
2121.12	42.9304
2124.02	45.1149
2126.92	48.3952
2129.82	50.3566
2132.71	53.5383
2135.61	55.9812
2138.51	60.0614
2141.4	64.0216
2144.29	69.5854
2147.19	73.2391
2150.08	76.7994
2152.97	81.451
2155.86	84.6804
2158.75	86.7468
2161.64	87.7363
2164.52	89.4853
2167.41	90.6659
2170.29	92.333
2173.17	92.2337
2176.06	92.73
2178.94	92.3582
2181.82	91.2616
2184.7	89.2232
2187.57	86.9826
2190.45	84.4979
2193.33	82.1683
2196.2	78.5297
2199.08	75.7444
2201.95	73.0736
2204.82	70.2242
2207.69	66.6326
2210.56	64.3512
2213.43	61.5712
2216.3	58.1014
2219.16	54.8531
2222.03	51.3131
2224.89	48.3737
2227.75	44.1226
2230.62	40.8945
2233.48	39.0183
2236.34	36.6042
2239.2	35.2047
2242.06	33.307
2244.91	31.7967
2247.77	31.101
2250.62	30.6076
2253.48	28.8955
2256.33	28.6607
2259.18	27.9643
2262.03	27.3296
2264.88	25.8346
2267.73	24.4936
2270.58	23.0903
2273.43	21.759
2276.27	20.3314
2279.12	18.9119
2281.96	17.6711
2284.8	17.0379
2287.64	16.5208
2290.49	14.0959
2293.32	12.6256
2296.16	11.4485
2299	11.4739
2301.84	12.6393
2304.67	12.6553
2307.51	12.4891
2310.34	12.955
2313.17	14.0274
2316	13.9812
2318.83	14.7202
2321.66	13.7015
2324.49	13.7123
2327.32	14.4408
2330.15	12.4426
2332.97	11.5765
2335.79	9.73574
2338.62	9.24945
2341.44	8.15393
2344.26	6.78865
2347.08	5.52832
2349.9	5.09508
2352.72	3.52458
2355.53	3.34146
2358.35	2.62505
2361.17	1.4287
2363.98	3.55955
2366.79	5.6891
2369.6	6.82856
2372.42	6.45901
2375.22	6.88815
2378.03	6.55564
2380.84	6.56967
2383.65	6.86741
2386.45	7.18719
2389.26	5.54418
2392.06	4.79115
2394.87	4.60039
2397.67	5.25855
2400.47	4.10538
2403.27	4.36055
2406.07	3.96904
2408.86	4.48667
2411.66	3.57472
2414.46	3.70513
2417.25	3.96901
2420.05	4.02203
2422.84	5.12038
2425.63	5.65592
2428.42	6.30426
2431.21	7.16386
2434	7.69592
2436.79	7.33737
2439.57	6.38297
2442.36	6.00403
2445.14	5.74885
2447.93	5.10181
2450.71	5.51123
2453.49	5.23425
2456.27	4.70551
2459.05	3.88996
2461.83	3.60702
2464.61	3.08745
2467.39	2.47719
2470.16	1.40416
2472.94	1.38208
2475.71	1.48286
2478.48	1.51154
2481.25	0.627417
2484.02	2.34622
2486.8	2.62045
2489.56	2.61876
2492.33	2.65822
2495.1	2.11691
2497.86	2.50672
2500.63	2.62717
2503.39	3.37914
2506.16	2.72898
2508.92	3.10894
2511.68	2.96545
2514.44	3.99773
2517.2	4.3881
2519.95	4.49977
2522.71	4.40994
2525.47	3.46262
2528.22	2.9483
2530.98	2.38099
2533.73	1.96296
2536.48	1.45249
2539.23	0.352046
2541.98	1.54063
2544.73	1.89928
2547.48	1.66388
2550.23	2.32444
2552.97	2.77762
2555.72	2.11011
2558.46	2.81031
2561.2	2.71595
2563.95	2.8271
2566.69	2.83939
2569.43	3.81151
2572.17	2.86579
2574.91	2.30333
2577.64	2.55597
2580.38	2.34228
2583.11	2.45281
2585.85	2.21194
2588.58	2.18129
2591.31	1.80501
2594.04	0.665128
2596.78	0.861785
2599.51	0.809605
2602.23	1.05763
2604.96	0.647584
2607.69	0.780941
2610.41	0.931723
2613.14	0.839336
2615.86	1.50226
2618.58	1.98594
2621.3	1.42122
2624.03	1.19012
2626.75	1.81152
2629.46	1.33937
2632.18	0.765035
2634.9	0.535567
2637.61	0.633649
2640.33	0.0662759
2643.04	0.695379
2645.76	1.38239
2648.47	2.50098
2651.18	3.46424
2653.89	3.90471
2656.6	4.53831
2659.31	3.94202
2662.01	3.94108
2664.72	4.92484
2667.43	5.29745
2670.13	4.8249
2672.83	4.68194
2675.53	5.60404
2678.24	6.23255
2680.94	6.01374
2683.64	6.3837
2686.34	6.13885
2689.03	5.5119
2691.73	5.37426
2694.43	4.46491
2697.12	4.11024
2699.81	4.30552
2702.51	4.60941
2705.2	4.83379
2707.89	4.34618
2710.58	4.77758
2713.27	5.07166
2715.96	5.02905
2718.64	4.84374
2721.33	3.66749
2724.01	3.38141
2726.7	3.32117
2729.38	3.14013
2732.06	2.88318
2734.75	3.6679
2737.43	4.23009
2740.11	3.72144
2742.78	4.27877
2745.46	4.17164
2748.14	3.90687
2750.81	3.10044
2753.49	2.56439
2756.16	2.03179
2758.84	1.62562
2761.51	1.00182
2764.18	1.48664
2766.85	1.61641
2769.52	1.70512
2772.19	0.935869
2774.85	1.27403
2777.52	1.03196
2780.18	1.39753
2782.85	0.916449
2785.51	1.04747
2788.17	1.29953
2790.84	2.98488
2793.5	3.1676
2796.16	2.47444
2798.81	2.48386
2801.47	2.22151
2804.13	2.51954
2806.79	2.62455
2809.44	2.48392
2812.09	1.2358
2814.75	1.3901
2817.4	1.51565
2820.05	2.49481
2822.7	3.01762
2825.35	4.86139
2828	7.81636
2830.65	11.2013
2833.29	14.7168
2835.94	18.7406
2838.58	22.5523
2841.23	26.8946
2843.87	31.7629
2846.51	36.6267
2849.15	42.4126
2851.79	49.2513
2854.43	55.082
2857.07	60.2577
2859.71	64.9103
2862.34	69.6378
2864.98	74.2805
2867.61	78.5479
2870.25	83.3331
2872.88	86.3363
2875.51	89.2738
2878.14	93.2178
2880.77	96.8837
2883.4	99.9231
2886.03	103.678
2888.65	107.749
2891.28	112.346
2893.91	117.378
2896.53	122.633
2899.15	129.326
2901.78	134.802
2904.4	141.812
2907.02	149.676
2909.64	158.564
2912.26	168.143
2914.87	178.051
2917.49	186.019
2920.11	193.766
2922.72	201.028
2925.34	207.027
2927.95	211.483
2930.56	214.541
2933.17	215.939
2935.78	215.58
2938.39	213.824
2941	211.155
2943.61	206.814
2946.22	199.312
2948.82	192.957
2951.43	185.026
2954.03	176.323
2956.64	167.447
2959.24	159.076
2961.84	150.132
2964.44	141.034
2967.04	132.638
2969.64	124.64
2972.24	116.628
2974.83	109.632
2977.43	102.511
2980.02	95.6993
2982.62	88.4262
2985.21	81.5786
2987.8	75.2248
2990.4	68.8415
2992.99	62.4302
2995.57	55.3174
2998.16	50.1705
3000.75	45.1923
3003.34	40.2585
3005.92	34.881
3008.51	30.989
3011.09	25.6531
3013.68	22.733
3016.26	18.8256
3018.84	15.6989
3021.42	11.642
3024	9.99484
3026.58	7.81146
3029.16	5.78295
3031.73	4.75409
3034.31	4.63685
3036.89	4.41988
3039.46	4.75898
3042.03	5.04611
3044.61	5.22582
3047.18	5.27473
3049.75	6.03903
3052.32	6.32561
3054.89	6.69914
3057.45	6.65046
3060.02	7.12388
3062.59	8.34329
3065.15	8.11757
3067.72	7.92541
3070.28	7.19997
3072.84	5.98969
3075.41	4.79529
3077.97	4.12918
3080.53	3.30102
3083.09	1.82882
3085.64	1.14727
3088.2	1.24547
3090.76	0.505
3093.31	-0.516571
3095.87	0.368519
3098.42	0.296264
3100.97	0.0487714
3103.53	-0.38056
3106.08	-0.360838
3108.63	0.0481362
3111.18	0.437126
3113.73	0.694014
3116.27	1.27891
3118.82	1.51678
3121.37	2.13568
3123.91	3.67759
3126.45	3.48346
3129	3.96146
3131.54	3.92796
3134.08	4.74265
3136.62	5.72301
3139.16	5.82772
3141.7	6.49684
3144.24	6.54603
3146.78	6.64032
3149.31	5.18492