File: data/Raman/poly_smoothed/Mb_40_y_41_1x_45s_532 nm_x100_100%_600 gr_mm_01.txt
#Acq. time (s)=	45
#Accumulations=	2
#Range (cm-¹)=	200...3150
#Windows=	2
#Auto scanning=	Off
#Autofocus=	Off
#Macrospot=	Off
#AutoExposure=	Off
#Spike filter=	Multiple accum.
#Delay time (s)=	0
#Binning=	1
#Readout mode=	Signal
#DeNoise=	Off
#ICS correction=	On
#Dark correction=	Off
#Inst. Process=	Off
#Detector Gain=	Best Dynamic Range
#Detector ADC=	20 kHz
#Detector temperature (°C)=	-69.85
#Instrument=	LabRAM HR Evol
#Detector=	Synapse
#Objective=	x100
#Grating=	600 gr/mm
#ND Filter=	100%
#Laser (nm)=	532
#Hole=	100.021
#Range=	Auto
#Laser Pol.=	No
#Raman. Pol.=	No
#Laser Pol. (°)=	-0.0007625
#Raman Pol. (°)=	89.9995
#Collection=	Microscope
#StageXY=	Marzhauser
#StageZ=	Marzhauser
#X (µm)=	-1074.2
#Y (µm)=	596.9
#Z (µm)=	584.6
#Full time(mm:ss)=	3:18
#Project=
#Sample=
#Site=
#Title=	Mb_40_y_41_2x_45s_532 nm_x100_100%_600 gr_mm
#Remark=
#Date=	19.07.2022 12:48
#Acquired=	19.07.2022 12:48:25
#Base:Fit=	10.08.2022 10:52:48
#Base:Sub=	10.08.2022 10:52:53
#Filter:Polynom=	16.08.2022 10:09:04
#AxisType[0]=Intens
#AxisUnit[0]=Cnt
#AxisType[1]=Spectr
#AxisUnit[1]=1/cm
200.423	22.145
204.052	18.2247
207.682	13.7287
211.308	10.8505
214.935	10.3347
218.558	9.05159
222.18	8.69427
225.802	8.08532
229.421	4.89474
233.039	3.77192
236.657	3.87968
240.272	4.26464
243.885	4.35904
247.497	3.55002
251.11	4.45994
254.719	5.21641
258.327	3.90034
261.933	5.09674
265.538	5.42075
269.141	5.31613
272.744	4.76556
276.344	6.36875
279.944	6.43219
283.542	6.11834
287.138	7.01396
290.733	7.25898
294.327	7.45045
297.919	7.02769
301.508	7.49263
305.098	9.5153
308.686	9.67035
312.273	10.3244
315.858	9.60086
319.44	7.8082
323.022	10.0575
326.604	12.0452
330.181	13.3158
333.76	13.6654
337.335	14.5673
340.91	15.767
344.483	14.7273
348.055	13.988
351.625	12.1053
355.195	12.4436
358.762	13.4046
362.329	12.5306
365.893	11.3223
369.455	11.5882
373.017	11.5347
376.578	10.8761
380.137	8.75918
383.694	7.60635
387.249	8.70405
390.806	10.0642
394.359	10.7722
397.91	9.3408
401.46	8.08063
405.009	8.33616
408.557	9.11068
412.103	10.6645
415.647	9.95976
419.191	9.47373
422.733	8.51872
426.273	8.2281
429.812	7.0636
433.35	5.45234
436.885	4.42552
440.42	5.34245
443.954	5.43516
447.486	4.69337
451.015	4.21062
454.545	5.89845
458.073	7.17318
461.598	8.58423
465.124	8.25937
468.648	9.48568
472.169	10.5062
475.69	11.8992
479.208	13.0149
482.727	12.7161
486.243	13.6183
489.759	13.9598
493.272	14.243
496.783	14.2271
500.295	14.0485
503.804	14.1783
507.311	14.2173
510.819	15.9351
514.324	14.5519
517.827	15.1372
521.329	13.7308
524.83	13.7851
528.329	12.7818
531.829	12.8365
535.326	13.0638
538.821	12.3996
542.315	11.2705
545.808	10.5924
549.299	10.3512
552.789	13.4988
556.278	15.4654
559.763	16.7558
563.249	18.2138
566.733	19.1889
570.217	20.5181
573.699	21.4726
577.177	22.157
580.656	22.6089
584.134	23.3594
587.609	23.5927
591.084	21.5052
594.558	20.6404
598.029	17.6695
601.5	16.277
604.968	14.3909
608.437	10.5772
611.902	9.7552
615.368	8.51943
618.831	6.97552
622.294	6.19751
625.755	3.53233
629.213	3.87431
632.673	5.87673
636.129	9.21496
639.584	11.4555
643.037	12.2909
646.491	12.8735
649.942	12.9245
653.392	14.9702
656.84	15.9862
660.287	15.557
663.732	15.7587
667.177	17.125
670.62	18.2574
674.061	17.5934
677.502	18.9676
680.941	20.1137
684.379	22.19
687.815	21.3658
691.248	23.3309
694.682	26.0039
698.115	28.4973
701.546	29.6471
704.974	31.3193
708.402	32.8565
711.83	35.2673
715.254	37.055
718.679	36.945
722.102	38.1186
725.522	39.3522
728.943	39.7118
732.361	41.0541
735.779	43.7982
739.194	44.5734
742.608	45.4368
746.022	47.6138
749.433	50.0396
752.843	52.997
756.254	53.4269
759.661	56.5273
763.067	57.8156
766.471	59.1628
769.877	60.1677
773.279	62.0382
776.68	63.7171
780.079	64.7263
783.478	66.363
786.875	66.9868
790.27	67.6026
793.665	66.8802
797.058	65.397
800.45	63.8465
803.84	64.8362
807.23	65.6567
810.616	66.0405
814.002	66.1477
817.388	65.7305
820.772	65.6488
824.153	64.8627
827.535	64.3444
830.915	64.0501
834.292	61.8316
837.67	60.6102
841.047	59.2374
844.42	57.097
847.794	55.0874
851.165	53.6662
854.534	51.1506
857.905	49.7656
861.272	50.6061
864.639	50.2614
868.004	48.8294
871.367	46.7803
874.731	45.4324
878.092	44.0081
881.451	44.6243
884.809	45.6404
888.166	44.8091
891.522	45.5112
894.878	45.1786
898.231	44.7292
901.583	45.0581
904.934	45.3768
908.283	45.7859
911.631	45.7564
914.976	44.5268
918.322	44.221
921.666	44.8256
925.009	44.1203
928.351	44.6505
931.692	45.5247
935.029	45.8944
938.367	46.4536
941.704	47.1442
945.038	46.4609
948.372	45.0867
951.705	44.0752
955.035	43.4098
958.366	40.2057
961.693	38.2691
965.021	35.5743
968.346	32.4709
971.67	31.6773
974.995	29.7649
978.316	27.2101
981.638	24.4215
984.957	23.9647
988.274	23.0258
991.59	19.9036
994.907	16.0271
998.221	12.9561
1001.53	10.2079
1004.85	8.29728
1008.16	11.9237
1011.46	19.7061
1014.77	30.212
1018.08	42.2923
1021.38	53.4971
1024.69	65.2229
1027.99	76.7296
1031.29	86.6034
1034.59	95.3335
1037.89	100.263
1041.19	103.98
1044.48	106.787
1047.78	107.83
1051.07	108.502
1054.36	103.755
1057.66	98.823
1060.94	90.9217
1064.23	82.3265
1067.52	72.0877
1070.81	58.4168
1074.09	44.7938
1077.38	31.0216
1080.66	20.3845
1083.94	12.0475
1087.22	8.11267
1090.5	9.06261
1093.77	11.7356
1097.05	15.337
1100.32	17.1203
1103.6	18.4076
1106.87	20.5734
1110.14	22.8176
1113.41	24.5838
1116.67	24.8245
1119.94	25.0959
1123.21	25.0585
1126.47	24.5686
1129.73	22.2922
1133	19.675
1136.26	17.4959
1139.52	15.8048
1142.77	15.0524
1146.03	13.0448
1149.29	10.5582
1152.54	7.98833
1155.79	6.82169
1159.04	5.11503
1162.3	2.16661
1165.55	0.591616
1168.79	1.55275
1172.04	3.56883
1175.28	4.08917
1178.53	4.69067
1181.77	4.22841
1185.01	3.68032
1188.25	6.21857
1191.49	6.85312
1194.73	6.298
1197.97	6.8709
1201.2	6.8133
1204.44	6.41967
1207.67	4.10466
1210.9	3.93375
1214.13	5.4046
1217.36	6.53731
1220.59	7.0358
1223.82	7.42822
1227.04	7.72241
1230.26	7.54491
1233.49	7.74927
1236.71	9.33269
1239.93	10.5599
1243.15	9.98621
1246.37	11.0205
1249.58	10.6473
1252.8	11.7127
1256.01	11.1142
1259.23	15.9089
1262.44	19.6685
1265.65	24.3991
1268.86	27.5885
1272.07	31.6512
1275.27	35.4006
1278.48	37.6774
1281.68	39.1629
1284.89	40.9009
1288.09	42.5285
1291.29	44.3852
1294.49	46.3069
1297.69	46.3063
1300.88	46.9859
1304.08	46.4412
1307.27	45.6731
1310.47	46.3251
1313.66	45.4252
1316.85	42.6681
1320.04	39.7727
1323.23	37.6459
1326.41	34.7811
1329.6	32.3591
1332.78	29.6575
1335.97	30.5275
1339.15	31.9485
1342.33	29.5301
1345.51	27.9719
1348.69	27.296
1351.87	26.9452
1355.04	25.6528
1358.22	22.7839
1361.39	21.8644
1364.57	20.1564
1367.74	18.515
1370.91	17.4398
1374.07	16.7855
1377.24	16.2259
1380.41	15.9024
1383.57	16.1255
1386.74	16.424
1389.9	17.0634
1393.06	16.3866
1396.22	16.8415
1399.38	18.0309
1402.54	20.1562
1405.7	24.3317
1408.85	30.4939
1412.01	36.5654
1415.16	43.0652
1418.31	48.6493
1421.46	55.9105
1424.61	64.1777
1427.76	72.3499
1430.91	79.4193
1434.05	85.3682
1437.2	89.3559
1440.34	95.6315
1443.49	99.0748
1446.63	101.914
1449.77	102.469
1452.91	104.017
1456.04	101.853
1459.18	99.0968
1462.31	95.7224
1465.45	89.3877
1468.58	83.1285
1471.71	76.4209
1474.84	69.9221
1477.97	65.226
1481.1	60.1667
1484.23	55.0386
1487.35	47.9513
1490.48	41.5978
1493.6	36.7145
1496.72	33.3334
1499.84	29.5494
1502.96	26.6427
1506.08	23.3802
1509.2	20.0723
1512.31	18.1332
1515.43	17.6812
1518.54	18.5866
1521.66	17.5934
1524.77	16.8676
1527.88	17.8319
1530.99	17.6847
1534.09	17.3206
1537.2	17.6164
1540.31	18.4295
1543.41	19.3745
1546.51	21.4965
1549.62	22.0556
1552.72	21.6772
1555.82	22.9682
1558.91	21.9782
1562.01	22.6325
1565.11	22.3241
1568.2	24.0466
1571.3	23.9706
1574.39	24.1132
1577.48	24.0605
1580.57	24.0867
1583.66	25.2545
1586.75	25.4075
1589.83	26.2506
1592.92	27.9866
1596	27.8669
1599.09	27.469
1602.17	28.3315
1605.25	28.5417
1608.33	27.9801
1611.41	28.4842
1614.48	29.3518
1617.56	29.3144
1620.64	29.0887
1623.71	29.3197
1626.78	29.576
1629.86	28.6029
1632.92	28.2464
1635.99	28.4278
1639.06	27.9103
1642.13	27.5399
1645.19	27.8647
1648.26	28.5585
1651.32	29.3273
1654.38	28.5467
1657.45	28.6025
1660.51	28.1428
1663.57	27.4537
1666.62	27.8159
1669.68	26.5404
1672.73	25.227
1675.79	23.8572
1678.84	22.2059
1681.89	20.5396
1684.94	19.5018
1687.99	17.6495
1691.04	15.9542
1694.09	14.7926
1697.14	13.0712
1700.18	10.8569
1703.22	8.7576
1706.27	7.41423
1709.31	6.16264
1712.35	5.89443
1715.39	3.63975
1718.43	3.19436
1721.46	3.04147
1724.5	2.04608
1727.53	1.12478
1730.57	1.10746
1733.6	0.672281
1736.63	-0.0413743
1739.66	0.943393
1742.69	1.73474
1745.72	1.63043
1748.74	1.62795
1751.77	2.57273
1754.8	3.69637
1757.82	5.29857
1760.84	6.221
1763.86	5.64638
1766.88	5.41234
1769.9	5.56616
1772.92	4.63662
1775.93	5.6022
1778.95	5.14878
1781.96	4.91552
1784.98	5.03254
1787.99	3.88993
1791	3.3399
1794.01	3.23448
1797.02	3.3577
1800.03	3.26175
1803.03	2.53372
1806.04	2.25704
1809.04	1.22741
1812.04	1.53559
1815.05	2.76711
1818.05	2.96301
1821.05	2.1861
1824.05	2.03105
1827.04	2.91219
1830.04	3.64307
1833.03	3.51884
1836.03	3.01426
1839.02	1.88631
1842.01	2.03097
1845	1.53293
1847.99	2.12004
1850.98	2.38149
1853.97	3.07512
1856.95	2.79603
1859.94	3.0239
1862.92	2.52931
1865.91	2.76447
1868.89	2.35617
1871.87	2.02135
1874.85	1.3429
1877.83	1.25956
1880.8	1.6397
1882.56	1.13069
1885.54	1.38713
1888.53	1.13843
1891.52	1.02762
1894.5	1.33225
1897.49	1.89282
1900.47	2.65788
1903.45	2.4947
1906.43	1.90297
1909.41	1.85257
1912.39	1.75698
1915.37	2.06052
1918.35	2.74639
1921.32	3.35579
1924.3	3.90805
1927.27	4.92447
1930.24	4.18636
1933.21	4.60768
1936.18	3.96257
1939.15	2.90507
1942.12	3.26979
1945.09	4.01201
1948.05	4.4998
1951.02	4.73399
1953.98	4.81912
1956.94	4.70057
1959.91	5.21427
1962.87	5.3282
1965.82	5.39901
1968.78	5.25582
1971.74	5.66292
1974.7	5.73336
1977.65	5.12242
1980.6	5.49868
1983.56	5.18003
1986.51	5.45007
1989.46	6.70436
1992.41	7.18602
1995.36	8.54664
1998.3	9.55738
2001.25	8.00378
2004.2	8.21905
2007.14	9.356
2010.08	10.3112
2013.02	10.7112
2015.97	10.1194
2018.9	10.9393
2021.84	10.0494
2024.78	9.93873
2027.72	10.596
2030.65	10.4238
2033.59	10.378
2036.52	9.94188
2039.45	10.5612
2042.38	11.8003
2045.31	12.2842
2048.24	12.1506
2051.17	13.1876
2054.1	14.1946
2057.02	15.0304
2059.95	15.9863
2062.87	16.5153
2065.79	17.5341
2068.71	16.9095
2071.63	16.9033
2074.55	17.0935
2077.47	16.895
2080.39	17.5454
2083.3	16.3822
2086.22	15.5976
2089.13	14.3907
2092.05	14.6585
2094.96	14.6496
2097.87	15.4774
2100.78	15.8557
2103.69	16.146
2106.59	15.9571
2109.5	18.3862
2112.41	21.0525
2115.31	22.1075
2118.21	24.5003
2121.12	26.0922
2124.02	28.5153
2126.92	31.0029
2129.82	31.6603
2132.71	33.2926
2135.61	35.2968
2138.51	36.7671
2141.4	37.9411
2144.29	40.2289
2147.19	41.9278
2150.08	43.8664
2152.97	45.087
2155.86	47.0763
2158.75	47.7735
2161.64	48.4364
2164.52	49.0905
2167.41	49.8401
2170.29	50.3416
2173.17	49.5113
2176.06	49.8588
2178.94	50.2733
2181.82	51.0287
2184.7	50.9377
2187.57	50.0389
2190.45	49.4128
2193.33	49.0612
2196.2	48.2027
2199.08	46.7115
2201.95	45.484
2204.82	44.5069
2207.69	42.795
2210.56	41.0599
2213.43	39.3969
2216.3	37.4866
2219.16	35.4767
2222.03	33.4636
2224.89	31.5382
2227.75	28.5811
2230.62	26.4788
2233.48	25.2532
2236.34	22.6268
2239.2	21.7543
2242.06	20.3581
2244.91	19.4251
2247.77	18.1586
2250.62	17.8645
2253.48	18.0452
2256.33	16.9087
2259.18	16.6035
2262.03	16.1752
2264.88	15.233
2267.73	15.1443
2270.58	15.0126
2273.43	14.1552
2276.27	14.0528
2279.12	13.6112
2281.96	12.298
2284.8	11.2009
2287.64	10.2546
2290.49	8.54529
2293.32	6.77952
2296.16	5.3398
2299	7.17396
2301.84	7.94054
2304.67	8.0441
2307.51	9.27245
2310.34	9.64037
2313.17	10.3695
2316	10.1611
2318.83	10.5644
2321.66	10.5999
2324.49	10.3958
2327.32	10.6778
2330.15	11.18
2332.97	12.461
2335.79	12.5073
2338.62	12.6114
2341.44	11.5468
2344.26	11.4504
2347.08	10.0465
2349.9	7.198
2352.72	5.97155
2355.53	4.04977
2358.35	3.51381
2361.17	1.66633
2363.98	1.84703
2366.79	2.55793
2369.6	1.94721
2372.42	1.48699
2375.22	1.59592
2378.03	0.981882
2380.84	0.121847
2383.65	-0.241903
2386.45	-0.30132
2389.26	-0.34195
2392.06	-0.11694
2394.87	0.357506
2397.67	1.50933
2400.47	1.89054
2403.27	2.33528
2406.07	1.70668
2408.86	1.30673
2411.66	1.1184
2414.46	1.48871
2417.25	1.44712
2420.05	2.27208
2422.84	3.89498
2425.63	4.82537
2428.42	5.00332
2431.21	5.32362
2434	4.81895
2436.79	5.29952
2439.57	5.41244
2442.36	6.40876
2445.14	6.69515
2447.93	6.09805
2450.71	5.31487
2453.49	5.47162
2456.27	5.32802
2459.05	4.69853
2461.83	4.45664
2464.61	3.92375
2467.39	3.74561
2470.16	3.20609
2472.94	2.73773
2475.71	2.02884
2478.48	3.08432
2481.25	2.77805
2484.02	3.5512
2486.8	3.61017
2489.56	4.55161
2492.33	3.55151
2495.1	3.48217
2497.86	3.33484
2500.63	4.30116
2503.39	4.6009
2506.16	5.65699
2508.92	6.59374
2511.68	5.95873
2514.44	5.8278
2517.2	5.25431
2519.95	5.05345
2522.71	4.68938
2525.47	4.03256
2528.22	3.56945
2530.98	2.92328
2533.73	3.56709
2536.48	3.89447
2539.23	3.61059
2541.98	2.95572
2544.73	3.03917
2547.48	3.27206
2550.23	2.83187
2552.97	2.6837
2555.72	2.80807
2558.46	2.82761
2561.2	2.17653
2563.95	2.91149
2566.69	4.4995
2569.43	4.43923
2572.17	3.96161
2574.91	3.22259
2577.64	3.14425
2580.38	3.19792
2583.11	3.14078
2585.85	3.27135
2588.58	3.34684
2591.31	3.66834
2594.04	3.52056
2596.78	3.53029
2599.51	3.07892
2602.23	2.85618
2604.96	2.44564
2607.69	1.70975
2610.41	2.64094
2613.14	2.38874
2615.86	3.99643
2618.58	3.49252
2621.3	4.24072
2624.03	4.37067
2626.75	3.5538
2629.46	3.99671
2632.18	4.23912
2634.9	4.08341
2637.61	4.50648
2640.33	4.8072
2643.04	5.4741
2645.76	6.1333
2648.47	5.56947
2651.18	6.44021
2653.89	5.90193
2656.6	4.9535
2659.31	4.12043
2662.01	3.83335
2664.72	4.19107
2667.43	3.73841
2670.13	3.81319
2672.83	3.90417
2675.53	4.79289
2678.24	5.97424
2680.94	6.92943
2683.64	6.77055
2686.34	6.19592
2689.03	5.95966
2691.73	6.06604
2694.43	7.70695
2697.12	8.57566
2699.81	10.8772
2702.51	13.2086
2705.2	14.5722
2707.89	16.2679
2710.58	17.0799
2713.27	17.4308
2715.96	17.8009
2718.64	17.8845
2721.33	18.082
2724.01	18.2065
2726.7	18.2745
2729.38	17.7463
2732.06	16.475
2734.75	16.0959
2737.43	14.8402
2740.11	13.7173
2742.78	13.2536
2745.46	12.5597
2748.14	10.1731
2750.81	7.86847
2753.49	6.14062
2756.16	5.42138
2758.84	4.53683
2761.51	4.0701
2764.18	2.43744
2766.85	2.33267
2769.52	3.01328
2772.19	2.35508
2774.85	1.54914
2777.52	1.70217
2780.18	1.20489
2782.85	1.46616
2785.51	1.25801
2788.17	1.64485
2790.84	1.45288
2793.5	1.16998
2796.16	1.90033
2798.81	3.44358
2801.47	3.89444
2804.13	2.93111
2806.79	1.86007
2809.44	0.448717
2812.09	-0.0613375
2814.75	1.65774
2817.4	8.98337
2820.05	18.1753
2822.7	29.688
2825.35	42.5764
2828	56.5392
2830.65	71.027
2833.29	88.1599
2835.94	103.055
2838.58	117.733
2841.23	130.514
2843.87	142.108
2846.51	151.608
2849.15	163.973
2851.79	177.705
2854.43	194.672
2857.07	210.276
2859.71	223.767
2862.34	235.883
2864.98	242.314
2867.61	245.695
2870.25	247.337
2872.88	247.714
2875.51	249.445
2878.14	251.126
2880.77	254.81
2883.4	255.309
2886.03	254.309
2888.65	251.594
2891.28	247.766
2893.91	242.321
2896.53	235.675
2899.15	228.279
2901.78	219.298
2904.4	210.45
2907.02	202.557
2909.64	196.939
2912.26	194.995
2914.87	198.892
2917.49	202.144
2920.11	204.428
2922.72	205.341
2925.34	204.203
2927.95	203.185
2930.56	199.37
2933.17	197.162
2935.78	193.661
2938.39	189.576
2941	183.494
2943.61	177.066
2946.22	169.962
2948.82	162.019
2951.43	154.076
2954.03	143.926
2956.64	135.445
2959.24	126.373
2961.84	118.155
2964.44	109.412
2967.04	103.185
2969.64	95.9073
2972.24	88.2996
2974.83	81.9758
2977.43	75.562
2980.02	69.7089
2982.62	63.7494
2985.21	59.37
2987.8	53.539
2990.4	48.4002
2992.99	43.3954
2995.57	38.4851
2998.16	34.0947
3000.75	30.4977
3003.34	25.9529
3005.92	23.4295
3008.51	20.5668
3011.09	17.1304
3013.68	14.7184
3016.26	11.8851
3018.84	9.74812
3021.42	8.99478
3024	7.07508
3026.58	6.50051
3029.16	5.66989
3031.73	4.14111
3034.31	2.73723
3036.89	3.05065
3039.46	2.68224
3042.03	2.89544
3044.61	3.49357
3047.18	2.89315
3049.75	2.62838
3052.32	2.38392
3054.89	2.27463
3057.45	2.51479
3060.02	3.50393
3062.59	4.54628
3065.15	5.09221
3067.72	4.54181
3070.28	4.96466
3072.84	4.94617
3075.41	4.68285
3077.97	5.23028
3080.53	5.1173
3083.09	5.06074
3085.64	4.30651
3088.2	3.39982
3090.76	2.21861
3093.31	1.31099
3095.87	2.20001
3098.42	1.87876
3100.97	2.60441
3103.53	3.44272
3106.08	3.14484
3108.63	3.51267
3111.18	3.37938
3113.73	3.67081
3116.27	5.70051
3118.82	6.54419
3121.37	7.50958
3123.91	8.35385
3126.45	8.94339
3129	9.03981
3131.54	10.1596
3134.08	11.7797
3136.62	12.0724
3139.16	11.664
3141.7	11.2986
3144.24	10.5437
3146.78	10.5751
3149.31	10.2518