File: data/Raman/poly_smoothed/Mb_40_24_05_1x_45s_532 nm_x100_100%_600 gr_mm_01.txt
#Acq. time (s)=	45
#Accumulations=	2
#Range (cm-¹)=	200...3150
#Windows=	2
#Auto scanning=	Off
#Autofocus=	Off
#Macrospot=	Off
#AutoExposure=	Off
#Spike filter=	Multiple accum.
#Delay time (s)=	0
#Binning=	1
#Readout mode=	Signal
#DeNoise=	Off
#ICS correction=	On
#Dark correction=	Off
#Inst. Process=	Off
#Detector Gain=	Best Dynamic Range
#Detector ADC=	20 kHz
#Detector temperature (°C)=	-70.08
#Instrument=	LabRAM HR Evol
#Detector=	Synapse
#Objective=	x100
#Grating=	600 gr/mm
#ND Filter=	100%
#Laser (nm)=	532
#Hole=	100.021
#Range=	Auto
#Laser Pol.=	No
#Raman. Pol.=	No
#Laser Pol. (°)=	-0.0007625
#Raman Pol. (°)=	89.9995
#Collection=	Microscope
#StageXY=	Marzhauser
#StageZ=	Marzhauser
#X (µm)=	-2527.7
#Y (µm)=	-36.9
#Z (µm)=	-10.05
#Full time(mm:ss)=	3:18
#Project=
#Sample=
#Site=
#Title=	Mb_40_24_05_2x_45s_532 nm_x100_100%_600 gr_mm
#Remark=
#Date=	14.07.2022 11:04
#Acquired=	14.07.2022 11:04:46
#Base:Fit=	10.08.2022 10:47:00
#Base:Sub=	10.08.2022 10:47:12
#Filter:Polynom=	16.08.2022 10:11:48
#AxisType[0]=Intens
#AxisUnit[0]=Cnt
#AxisType[1]=Spectr
#AxisUnit[1]=1/cm
200.554	43.0434
204.183	36.0829
207.813	30.1622
211.439	25.7739
215.065	23.5123
218.688	19.4864
222.312	15.9985
225.933	14.6326
229.552	11.5305
233.171	11.7482
236.787	11.2286
240.402	11.7588
244.015	11.7606
247.627	10.2283
251.24	10.0101
254.849	11.3238
258.457	11.7044
262.063	14.8251
265.668	15.9142
269.271	16.4197
272.873	13.2051
276.474	10.7832
280.073	10.2384
283.671	9.82244
287.268	9.25683
290.863	10.2597
294.456	11.0751
298.049	11.1539
301.637	13.0058
305.227	12.9279
308.815	12.0121
312.402	10.7557
315.987	11.6582
319.569	11.9728
323.151	11.7917
326.733	12.4358
330.31	11.329
333.889	10.1375
337.464	8.34653
341.039	7.57029
344.611	6.47564
348.184	6.27706
351.754	5.07287
355.324	4.35732
358.89	2.35437
362.455	2.03963
366.021	-0.211128
369.584	1.80149
373.145	3.45681
376.707	5.75778
380.265	8.09051
383.822	8.75169
387.378	9.1813
390.934	9.52365
394.487	10.1782
398.038	11.0805
401.588	12.0648
405.137	11.0679
408.685	9.84537
412.23	9.93936
415.775	12.3614
419.318	10.2211
422.86	10.3579
426.401	8.6828
429.94	7.70697
433.478	8.11833
437.012	6.85482
440.547	4.78755
444.081	6.53344
447.613	6.64718
451.142	9.61746
454.672	12.254
458.2	13.5442
461.725	15.7772
465.251	18.4629
468.775	19.1236
472.296	19.3696
475.817	21.2931
479.335	23.5238
482.854	25.8466
486.37	23.6877
489.886	24.1051
493.398	24.283
496.91	25.0232
500.422	27.5199
503.93	26.7192
507.438	24.4103
510.946	24.5723
514.45	23.9806
517.954	22.49
521.456	23.3406
524.956	23.4819
528.456	26.5533
531.956	28.8285
535.452	31.0003
538.947	31.6269
542.441	33.5055
545.934	34.1995
549.425	35.979
552.915	34.3257
556.403	32.5217
559.889	31.3214
563.375	31.565
566.859	28.1802
570.342	25.6315
573.824	23.549
577.303	22.7653
580.782	19.8748
584.26	17.058
587.734	13.4863
591.21	9.7548
594.684	5.84837
598.154	6.51069
601.626	6.9461
605.094	6.83974
608.562	7.86128
612.027	8.32393
615.493	9.26862
618.956	9.65632
622.419	10.6995
625.879	13.0919
629.338	11.5489
632.797	10.9562
636.254	10.8542
639.708	10.6831
643.162	11.0818
646.614	10.4418
650.067	10.2132
653.516	9.029
656.964	8.03177
660.411	6.88127
663.857	4.32358
667.301	1.23421
670.744	-0.179269
674.186	-0.409096
677.626	-0.658567
681.065	1.78014
684.503	3.82774
687.939	5.12162
691.372	8.67423
694.806	11.3935
698.239	12.739
701.67	15.8664
705.098	18.1657
708.526	20.393
711.954	19.9896
715.378	22.5781
718.802	23.9624
722.226	25.4481
725.646	25.4588
729.067	25.3141
732.484	26.9045
735.902	27.7846
739.317	27.2082
742.731	29.8253
746.145	32.6345
749.556	33.9589
752.966	35.8221
756.377	38.3707
759.784	41.873
763.19	46.0847
766.594	48.7212
770	51.9815
773.402	55.7408
776.803	58.1553
780.202	59.3416
783.6	60.1392
786.997	64.5071
790.393	63.4323
793.787	66.411
797.18	66.3184
800.572	67.662
803.963	66.2165
807.35	66.4146
810.738	67.7305
814.125	68.8372
817.51	68.1023
820.894	68.3279
824.275	70.8368
827.657	74.5719
831.037	76.9246
834.414	76.9987
837.792	78.9398
841.167	81.3216
844.542	80.914
847.914	80.959
851.287	80.179
854.656	80.0417
858.026	79.0846
861.393	77.9488
864.761	76.6355
868.125	75.9814
871.489	74.4056
874.85	73.2991
878.213	72.6779
881.572	70.2598
884.931	67.0897
888.287	64.8581
891.643	59.9902
894.997	55.8461
898.352	51.566
901.704	52.0678
905.055	55.4351
908.404	55.4699
911.75	56.4723
915.097	56.0645
918.443	55.3923
921.787	55.6127
925.13	53.3702
928.472	53.2788
931.813	54.0769
935.15	53.4802
938.488	52.5612
941.825	49.4483
945.158	45.0155
948.493	42.6007
951.824	41.4511
955.156	39.6755
958.486	39.1428
961.814	37.5136
965.142	37.5223
968.467	38.6706
971.79	40.9741
975.115	41.4917
978.436	44.768
981.756	45.4582
985.077	45.5972
988.394	45.1215
991.71	44.7022
995.025	44.4631
998.341	42.2127
1001.65	40.2323
1004.97	39.4261
1008.28	39.8854
1011.58	43.0544
1014.89	45.3038
1018.2	47.3012
1021.5	49.2647
1024.81	50.3589
1028.11	54.1138
1031.41	57.7843
1034.71	60.6522
1038.01	66.0089
1041.31	71.5219
1044.6	74.6695
1047.9	74.9446
1051.19	76.5535
1054.48	77.391
1057.77	76.8336
1061.06	75.644
1064.35	72.4938
1067.64	68.2661
1070.93	65.2266
1074.21	61.9508
1077.49	54.4282
1080.78	49.2283
1084.06	45.1957
1087.34	43.8333
1090.61	45.692
1093.89	45.6831
1097.17	44.726
1100.44	43.0376
1103.71	40.5678
1106.99	41.4508
1110.26	38.2655
1113.52	34.6874
1116.79	33.0607
1120.06	31.7698
1123.32	27.4887
1126.59	23.3794
1129.85	24.2077
1133.11	24.0989
1136.37	22.8838
1139.63	20.0614
1142.89	18.682
1146.15	15.7016
1149.4	14.4268
1152.66	11.7812
1155.91	12.3134
1159.16	8.35176
1162.41	10.0948
1165.66	9.90708
1168.91	11.0669
1172.16	11.8182
1175.4	11.1696
1178.65	11.356
1181.89	13.951
1185.13	17.3901
1188.37	19.9253
1191.61	21.6237
1194.85	24.449
1198.08	27.1274
1201.32	29.548
1204.55	29.2804
1207.79	31.0993
1211.02	31.7458
1214.25	34.6214
1217.48	37.994
1220.71	40.802
1223.93	44.2436
1227.16	48.559
1230.38	51.3782
1233.6	54.6503
1236.83	56.5609
1240.05	59.1347
1243.26	62.127
1246.48	63.7761
1249.7	67.1089
1252.92	68.8045
1256.13	71.3229
1259.34	74.2719
1262.55	78.5591
1265.76	79.9328
1268.97	82.2265
1272.18	85.2371
1275.39	88.9583
1278.59	90.8515
1281.8	92.7555
1285	97.4178
1288.2	102.63
1291.4	107.964
1294.6	113.989
1297.8	118.576
1301	122.384
1304.19	126.767
1307.39	127.426
1310.58	128.595
1313.77	126.984
1316.96	125.502
1320.15	124.788
1323.34	123.788
1326.53	120.64
1329.72	117.728
1332.9	115.254
1336.08	111.911
1339.27	108.556
1342.45	106.717
1345.63	104.04
1348.8	102.859
1351.98	101.584
1355.16	101.603
1358.33	102.188
1361.51	104.861
1364.68	106.649
1367.85	108.121
1371.02	108.921
1374.19	111.822
1377.36	112.568
1380.52	115.666
1383.69	119.424
1386.85	120.433
1390.02	121.053
1393.18	121.318
1396.34	124.094
1399.5	124.936
1402.65	128.633
1405.81	132.948
1408.97	140.259
1412.12	146.411
1415.27	153.802
1418.43	162.142
1421.58	172.006
1424.73	181.704
1427.87	194.3
1431.02	206.08
1434.17	217.164
1437.31	226.075
1440.46	232.421
1443.6	235.878
1446.74	237.409
1449.88	236.224
1453.02	236.801
1456.16	232.021
1459.29	227.577
1462.43	218.281
1465.56	206.169
1468.69	192.079
1471.83	179.014
1474.95	164.678
1478.08	149.865
1481.21	137.927
1484.34	125.216
1487.47	112.965
1490.59	103.893
1493.71	93.2607
1496.84	88.2028
1499.96	83.1936
1503.07	77.4723
1506.19	73.7638
1509.31	71.142
1512.43	68.8297
1515.54	65.7204
1518.65	61.8752
1521.77	60.1226
1524.88	59.9053
1527.99	59.6683
1531.1	60.396
1534.21	60.5509
1537.31	59.8782
1540.42	58.6079
1543.52	59.6687
1546.63	59.7437
1549.73	61.5801
1552.83	62.9647
1555.93	65.5965
1559.03	69.3755
1562.12	73.4535
1565.22	77.4006
1568.31	82.6555
1571.41	88.8558
1574.5	97.4333
1577.59	105.096
1580.68	113.119
1583.77	120.58
1586.86	127.346
1589.95	135.033
1593.03	141.671
1596.11	146.54
1599.2	149.919
1602.28	154.259
1605.36	156.451
1608.44	159.952
1611.52	162.62
1614.6	163.141
1617.67	162.472
1620.75	162.103
1623.82	162.615
1626.89	163.204
1629.96	162.167
1633.04	161.399
1636.11	158.719
1639.17	157.819
1642.24	155.067
1645.31	153.224
1648.37	150.9
1651.43	148.278
1654.5	143.41
1657.56	139.046
1660.62	131.916
1663.67	126.469
1666.73	119.586
1669.79	111.257
1672.84	105.164
1675.9	99.9398
1678.95	92.6088
1682	85.6288
1685.05	79.4239
1688.1	74.5774
1691.15	67.981
1694.2	63.7835
1697.25	61.3754
1700.29	58.1962
1703.33	55.2668
1706.38	52.7173
1709.42	48.9766
1712.46	46.7236
1715.5	43.5449
1718.54	39.8706
1721.57	36.9679
1724.61	34.7347
1727.64	33.0219
1730.68	31.4413
1733.71	28.3962
1736.74	25.6979
1739.77	25.5052
1742.8	24.0476
1745.83	23.376
1748.85	22.8197
1751.88	20.8151
1754.91	18.844
1757.93	17.8886
1760.95	17.7725
1763.97	17.2637
1766.99	15.7391
1770.01	14.6019
1773.03	13.8784
1776.04	13.0164
1779.06	12.285
1782.07	10.7029
1785.09	10.0547
1788.1	7.75293
1791.11	6.08571
1794.12	5.30757
1797.13	4.63901
1800.13	5.12916
1803.14	4.32726
1806.15	3.6836
1809.15	2.24929
1812.15	2.28618
1815.16	2.06182
1818.15	0.501293
1821.16	0.410442
1824.15	1.71322
1827.15	0.0711047
1830.15	-0.157315
1833.14	0.691056
1836.14	1.8712
1839.13	2.15793
1842.12	2.58004
1845.11	3.33714
1848.1	4.72776
1851.09	5.56432
1854.08	5.28496
1857.06	5.17347
1860.05	3.98817
1863.03	4.33911
1866.01	5.17372
1869	6.29873
1871.98	5.80931
1874.96	7.28024
1877.93	7.9944
1880.91	6.59841
1882.47	6.14313
1885.46	5.91615
1888.44	5.82254
1891.43	7.17688
1894.42	7.44492
1897.4	5.91568
1900.39	5.01479
1903.37	5.56763
1906.35	6.48091
1909.33	5.00097
1912.31	5.55962
1915.29	5.64471
1918.26	5.49432
1921.24	5.57065
1924.21	4.30429
1927.19	4.18058
1930.16	3.195
1933.13	3.66792
1936.1	4.50094
1939.07	5.10307
1942.04	5.29699
1945	5.66817
1947.97	7.47617
1950.93	6.00512
1953.9	6.7171
1956.86	6.56885
1959.82	7.53549
1962.78	7.95117
1965.74	7.5258
1968.7	6.89086
1971.65	7.19843
1974.61	5.80582
1977.57	4.85226
1980.52	3.43183
1983.47	4.12682
1986.42	3.47461
1989.37	2.09952
1992.32	3.26904
1995.27	2.92832
1998.22	4.0927
2001.17	5.77872
2004.11	6.9396
2007.05	8.42145
2010	7.61989
2012.94	7.65226
2015.88	9.6293
2018.82	10.5632
2021.76	11.1981
2024.7	10.5191
2027.63	11.0541
2030.57	11.2981
2033.5	12.27
2036.44	13.411
2039.37	14.3755
2042.3	16.3076
2045.23	16.0236
2048.16	15.3218
2051.08	16.1645
2054.01	16.0753
2056.94	17.6271
2059.86	18.0182
2062.79	18.3614
2065.71	19.7214
2068.63	21.8429
2071.55	23.4785
2074.47	22.5473
2077.39	22.0498
2080.31	22.2027
2083.22	22.7167
2086.13	23.5318
2089.05	23.3416
2091.96	22.4876
2094.87	21.7487
2097.78	22.8103
2100.69	23.5025
2103.6	24.7712
2106.51	25.7659
2109.42	28.3042
2112.32	31.2914
2115.23	31.8071
2118.13	32.3962
2121.03	35.8887
2123.93	37.2738
2126.83	39.5059
2129.73	41.7972
2132.63	43.0475
2135.53	45.4467
2138.42	48.3605
2141.32	50.9581
2144.21	52.0027
2147.1	53.9457
2150	58.1652
2152.89	61.0402
2155.78	63.0693
2158.66	64.3532
2161.55	66.6122
2164.44	66.4201
2167.32	69.1326
2170.21	68.6043
2173.09	68.7674
2175.97	66.7563
2178.85	65.1603
2181.73	65.0129
2184.61	61.4657
2187.49	60.7554
2190.37	59.7977
2193.24	57.3269
2196.12	55.1867
2198.99	52.7896
2201.87	49.2579
2204.74	46.4014
2207.61	43.7643
2210.48	41.4533
2213.35	39.4197
2216.21	38.9208
2219.08	38.3424
2221.95	37.7911
2224.81	35.8847
2227.67	34.5632
2230.54	33.1618
2233.4	30.2841
2236.26	29.6544
2239.11	27.0488
2241.97	24.2223
2244.83	21.6326
2247.69	18.8809
2250.54	19.2933
2253.4	18.0822
2256.25	16.8964
2259.1	16.9754
2261.95	15.8803
2264.8	14.8383
2267.65	12.903
2270.5	11.691
2273.34	11.174
2276.19	10.792
2279.03	9.74694
2281.88	8.96841
2284.72	8.99051
2287.56	9.61732
2290.4	8.89526
2293.24	7.58948
2296.08	5.9462
2298.92	7.26294
2301.76	6.86592
2304.59	6.12249
2307.43	6.91803
2310.26	7.97538
2313.09	7.26562
2315.92	8.11422
2318.75	8.96388
2321.58	8.07985
2324.41	7.799
2327.24	7.72528
2330.06	7.8656
2332.89	7.2279
2335.71	7.83733
2338.54	8.10418
2341.36	7.41563
2344.18	6.98088
2347	5.14584
2349.82	2.6853
2352.64	2.55936
2355.45	2.22254
2358.27	1.62204
2361.08	0.885055
2363.9	0.584107
2366.71	2.47835
2369.52	2.43883
2372.33	1.62105
2375.14	1.92423
2377.95	2.46711
2380.76	2.63549
2383.57	2.81979
2386.37	2.50884
2389.18	2.98961
2391.98	2.19029
2394.79	2.59508
2397.59	3.04196
2400.39	4.18145
2403.19	4.44205
2405.99	5.18504
2408.78	5.70788
2411.58	6.40862
2414.38	4.53614
2417.17	5.77471
2419.97	6.75549
2422.76	7.6452
2425.55	8.0497
2428.34	8.42041
2431.13	8.19746
2433.92	7.24473
2436.71	7.05352
2439.49	6.85387
2442.28	7.35896
2445.06	7.02296
2447.85	7.7078
2450.63	6.72125
2453.41	6.12453
2456.19	4.68182
2458.97	3.89362
2461.75	2.24345
2464.53	1.99954
2467.31	2.01451
2470.08	1.78302
2472.86	1.61757
2475.63	1.32466
2478.4	0.650603
2481.17	0.94851
2483.94	2.55359
2486.72	4.22529
2489.48	2.70508
2492.25	1.65089
2495.02	-0.0101477
2497.79	1.04784
2500.55	2.81172
2503.31	4.80013
2506.08	6.64594
2508.84	8.08737
2511.6	10.3936
2514.36	11.0792
2517.12	11.9925
2519.88	11.9659
2522.63	12.5102
2525.39	13.3764
2528.14	13.7756
2530.9	14.33
2533.65	15.0858
2536.4	13.1896
2539.15	12.4913
2541.9	11.5739
2544.65	10.734
2547.4	9.8164
2550.15	10.5736
2552.89	10.7786
2555.64	8.00222
2558.38	6.75172
2561.12	6.35286
2563.87	6.7799
2566.61	7.67084
2569.35	6.95855
2572.09	6.81104
2574.83	6.09466
2577.56	5.96626
2580.3	5.31912
2583.04	5.12521
2585.77	3.69675
2588.5	4.79375
2591.23	5.50339
2593.97	5.42818
2596.7	5.48272
2599.43	5.52589
2602.15	5.61824
2604.88	6.68616
2607.61	8.06911
2610.33	8.40186
2613.06	8.64951
2615.78	9.65161
2618.51	10.1617
2621.23	10.6709
2623.95	10.9967
2626.67	11.9748
2629.39	11.6329
2632.1	12.361
2634.82	12.9708
2637.54	13.0912
2640.25	11.3646
2642.97	10.9534
2645.68	10.8596
2648.39	8.02052
2651.1	8.66607
2653.81	7.48525
2656.52	7.17979
2659.23	5.51553
2661.94	4.05883
2664.64	4.61692
2667.35	3.27074
2670.05	3.18559
2672.76	2.63918
2675.46	2.0081
2678.16	0.418031
2680.86	0.785044
2683.56	1.85483
2686.26	4.21166
2688.96	6.07577
2691.65	8.03598
2694.35	10.594
2697.04	13.6065
2699.74	15.9815
2702.43	17.5931
2705.12	18.9345
2707.81	19.7037
2710.5	21.2102
2713.19	22.4143
2715.88	23.3748
2718.57	25.2672
2721.25	26.4615
2723.94	27.4151
2726.62	25.6441
2729.3	25.8134
2731.99	25.2673
2734.67	24.239
2737.35	23.3528
2740.03	22.8694
2742.71	22.3222
2745.38	21.5485
2748.06	21.4158
2750.74	21.1814
2753.41	20.77
2756.09	21.1116
2758.76	21.8309
2761.43	21.115
2764.1	20.2569
2766.77	18.7226
2769.44	18.0792
2772.11	15.574
2774.77	14.5944
2777.44	13.9566
2780.11	12.6998
2782.77	11.8119
2785.43	11.3941
2788.1	9.65802
2790.76	9.54606
2793.42	9.10086
2796.08	9.28284
2798.74	8.53812
2801.4	8.38922
2804.05	7.4977
2806.71	7.28167
2809.36	7.24528
2812.02	6.81173
2814.67	8.64276
2817.32	10.547
2819.97	15.0821
2822.62	20.3972
2825.27	27.3833
2827.92	36.1849
2830.57	48.1856
2833.22	59.3952
2835.86	72.7749
2838.51	86.4584
2841.15	103.365
2843.79	120.213
2846.43	137.924
2849.08	156.982
2851.72	176.87
2854.36	196.527
2856.99	215.293
2859.63	234.123
2862.27	250.875
2864.9	267.474
2867.54	282.696
2870.17	297.224
2872.8	310.062
2875.43	321.478
2878.07	332.585
2880.7	346.54
2883.32	359.66
2885.95	373.455
2888.58	387.087
2891.21	401.451
2893.83	416.87
2896.46	433.684
2899.08	448.08
2901.7	465.932
2904.32	485.935
2906.94	505.708
2909.56	526.286
2912.18	545.822
2914.8	566.383
2917.42	585.672
2920.03	600.209
2922.65	613.489
2925.26	623.481
2927.88	628.844
2930.49	629.272
2933.1	626.338
2935.71	616.327
2938.32	602.788
2940.93	586.102
2943.54	568.102
2946.14	545.131
2948.75	520.223
2951.35	493.522
2953.96	466.027
2956.56	440.798
2959.16	415.753
2961.77	392.103
2964.37	369.351
2966.96	350.948
2969.56	330.531
2972.16	312.679
2974.76	296.895
2977.35	281.107
2979.95	265.871
2982.54	249.925
2985.14	234.356
2987.73	219.113
2990.32	202.628
2992.91	185.004
2995.5	169.022
2998.09	152.843
3000.68	135.452
3003.26	120.876
3005.85	105.787
3008.43	91.3955
3011.02	77.3196
3013.6	66.2999
3016.19	58.17
3018.77	49.9199
3021.35	42.2389
3023.93	34.3163
3026.5	28.3644
3029.08	23.4068
3031.66	19.3716
3034.24	15.38
3036.81	12.4752
3039.39	11.1825
3041.96	9.79078
3044.53	8.59798
3047.1	8.40231
3049.67	7.89145
3052.24	7.79321
3054.81	7.00766
3057.38	8.43803
3059.95	8.56255
3062.52	8.45264
3065.08	8.16914
3067.65	8.85966
3070.21	8.33354
3072.77	7.93961
3075.33	7.89129
3077.89	7.98449
3080.45	6.30817
3083.01	5.00505
3085.57	3.03912
3088.13	2.3761
3090.68	1.8859
3093.24	1.69018
3095.79	1.33564
3098.35	1.26844
3100.9	2.31551
3103.45	3.74918
3106	4.97611
3108.55	7.85283
3111.1	9.28817
3113.65	11.4249
3116.2	14.427
3118.75	16.2696
3121.29	18.1086
3123.84	20.5241
3126.38	22.6923
3128.92	26.0467
3131.47	29.4657
3134.01	30.8594
3136.55	33.8726
3139.09	36.4621
3141.63	38.0989
3144.17	39.919
3146.7	40.7242
3149.24	42.2509