File: data/Raman/poly_smoothed/Mb_40_24_38_1x_45s_532 nm_x100_100%_600 gr_mm_01.txt
#Acq. time (s)=	45
#Accumulations=	2
#Range (cm-¹)=	200...3150
#Windows=	2
#Auto scanning=	Off
#Autofocus=	Off
#Macrospot=	Off
#AutoExposure=	Off
#Spike filter=	Multiple accum.
#Delay time (s)=	0
#Binning=	1
#Readout mode=	Signal
#DeNoise=	Off
#ICS correction=	On
#Dark correction=	Off
#Inst. Process=	Off
#Detector Gain=	Best Dynamic Range
#Detector ADC=	20 kHz
#Detector temperature (°C)=	-69.85
#Instrument=	LabRAM HR Evol
#Detector=	Synapse
#Objective=	x100
#Grating=	600 gr/mm
#ND Filter=	100%
#Laser (nm)=	532
#Hole=	100.021
#Range=	Auto
#Laser Pol.=	No
#Raman. Pol.=	No
#Laser Pol. (°)=	-0.0007625
#Raman Pol. (°)=	89.9995
#Collection=	Microscope
#StageXY=	Marzhauser
#StageZ=	Marzhauser
#X (µm)=	-2505.2
#Y (µm)=	-58.1
#Z (µm)=	-10.45
#Full time(mm:ss)=	3:18
#Project=
#Sample=
#Site=
#Title=	Mb_40_24_38_2x_45s_532 nm_x100_100%_600 gr_mm
#Remark=
#Date=	14.07.2022 13:36
#Acquired=	14.07.2022 13:36:45
#Base:Fit=	10.08.2022 10:47:00
#Base:Sub=	10.08.2022 10:47:12
#Filter:Polynom=	16.08.2022 10:11:48
#AxisType[0]=Intens
#AxisUnit[0]=Cnt
#AxisType[1]=Spectr
#AxisUnit[1]=1/cm
200.554	6.91146
204.183	11.6298
207.813	12.9915
211.439	13.7255
215.065	12.5831
218.688	10.5508
222.312	9.11921
225.933	7.22802
229.552	6.11953
233.171	5.98253
236.787	6.59922
240.402	4.76099
244.015	5.49244
247.627	5.82982
251.24	5.03025
254.849	5.87931
258.457	5.28344
262.063	5.09476
265.668	6.5006
269.271	7.93506
272.873	9.73985
276.474	11.096
280.073	11.9916
283.671	11.639
287.268	12.9443
290.863	13.5708
294.456	14.4145
298.049	15.0475
301.637	13.7474
305.227	12.3822
308.815	13.5321
312.402	14.2544
315.987	13.4615
319.569	13.4941
323.151	12.8288
326.733	12.3993
330.31	11.7035
333.889	12.3642
337.464	12.149
341.039	12.3717
344.611	11.8439
348.184	9.21137
351.754	8.79928
355.324	10.0523
358.89	9.22188
362.455	7.40402
366.021	6.31582
369.584	7.47412
373.145	7.20917
376.707	8.56659
380.265	9.10017
383.822	8.89604
387.378	9.05123
390.934	11.6757
394.487	11.7594
398.038	12.0292
401.588	12.3045
405.137	11.0375
408.685	11.3973
412.23	13.781
415.775	14.7442
419.318	15.4568
422.86	14.0886
426.401	13.6956
429.94	12.46
433.478	9.83649
437.012	8.74877
440.547	9.6849
444.081	10.2265
447.613	8.96168
451.142	8.60844
454.672	10.0453
458.2	11.4804
461.725	13.3391
465.251	14.6879
468.775	13.5238
472.296	15.3141
475.817	16.1655
479.335	18.4313
482.854	19.0931
486.37	21.0633
489.886	22.2296
493.398	23.1136
496.91	24.6149
500.422	25.382
503.93	24.6206
507.438	23.8451
510.946	23.7869
514.45	24.9619
517.954	25.4678
521.456	24.4089
524.956	25.1709
528.456	27.7717
531.956	27.7117
535.452	27.1008
538.947	27.2033
542.441	27.4005
545.934	26.2651
549.425	27.1718
552.915	25.9129
556.403	25.2407
559.889	24.492
563.375	23.9276
566.859	22.145
570.342	19.2812
573.824	18.2285
577.303	16.6641
580.782	14.0804
584.26	11.6585
587.734	9.97991
591.21	8.90499
594.684	8.35693
598.154	8.63308
601.626	8.83078
605.094	7.96023
608.562	8.86188
612.027	10.8754
615.493	9.03445
618.956	9.27325
622.419	8.99033
625.879	9.89297
629.338	10.5713
632.797	12.382
636.254	15.424
639.708	15.4355
643.162	16.6074
646.614	16.8521
650.067	18.0152
653.516	19.1282
656.964	21.1696
660.411	23.0748
663.857	23.18
667.301	24.8691
670.744	26.4698
674.186	28.8521
677.626	28.8554
681.065	29.1797
684.503	30.5723
687.939	31.1512
691.372	32.9897
694.806	34.0731
698.239	33.8314
701.67	33.0863
705.098	33.7639
708.526	34.4743
711.954	35.9075
715.378	37.2363
718.802	38.1334
722.226	39.0418
725.646	39.5337
729.067	41.5684
732.484	41.7041
735.902	43.3441
739.317	45.505
742.731	48.5216
746.145	50.6408
749.556	52.7751
752.966	56.0901
756.377	58.9497
759.784	62.1485
763.19	63.7604
766.594	67.1665
770	69.8877
773.402	71.0644
776.803	72.0677
780.202	71.806
783.6	72.4481
786.997	74.3542
790.393	75.2617
793.787	76.1424
797.18	75.2156
800.572	74.4799
803.963	74.2871
807.35	72.9797
810.738	71.7637
814.125	70.7708
817.51	69.1192
820.894	69.1962
824.275	70.0731
827.657	70.9356
831.037	70.7773
834.414	71.7007
837.792	71.8479
841.167	71.4042
844.542	71.479
847.914	72.5521
851.287	71.6486
854.656	69.7499
858.026	67.775
861.393	63.9978
864.761	62.4264
868.125	62.5356
871.489	61.4213
874.85	59.637
878.213	58.706
881.572	57.974
884.931	58.1443
888.287	56.4924
891.643	54.6498
894.997	52.5859
898.352	51.1876
901.704	51.8706
905.055	51.6683
908.404	50.9438
911.75	50.622
915.097	51.0358
918.443	51.247
921.787	52.7248
925.13	53.3268
928.472	53.2422
931.813	51.7138
935.15	49.8225
938.488	47.4258
941.825	45.7407
945.158	42.4703
948.493	44.0616
951.824	45.1688
955.156	44.8845
958.486	43.3597
961.814	41.2959
965.142	40.7665
968.467	41.7534
971.79	40.8515
975.115	41.613
978.436	40.298
981.756	40.7615
985.077	38.9392
988.394	37.7756
991.71	35.3314
995.025	37.2459
998.341	36.7444
1001.65	35.6189
1004.97	33.5664
1008.28	33.5126
1011.58	32.5146
1014.89	33.9037
1018.2	34.5298
1021.5	34.5272
1024.81	36.39
1028.11	36.9657
1031.41	39.9603
1034.71	39.5469
1038.01	40.0065
1041.31	39.7459
1044.6	42.4817
1047.9	44.0434
1051.19	43.979
1054.48	42.5336
1057.77	42.4206
1061.06	40.392
1064.35	40.4002
1067.64	39.5929
1070.93	38.8409
1074.21	36.1995
1077.49	35.6019
1080.78	34.1038
1084.06	33.2661
1087.34	34.6944
1090.61	35.2716
1093.89	34.5852
1097.17	35.8168
1100.44	35.3944
1103.71	35.3952
1106.99	34.6302
1110.26	34.1186
1113.52	32.9342
1116.79	31.0365
1120.06	29.1551
1123.32	27.7967
1126.59	26.6404
1129.85	23.3839
1133.11	21.2557
1136.37	20.7749
1139.63	19.2187
1142.89	16.9982
1146.15	15.2679
1149.4	11.4955
1152.66	8.70677
1155.91	7.33713
1159.16	6.34694
1162.41	5.64844
1165.66	5.16558
1168.91	3.23462
1172.16	3.70432
1175.4	3.90782
1178.65	5.68847
1181.89	6.59415
1185.13	8.51028
1188.37	9.5589
1191.61	10.9926
1194.85	13.595
1198.08	14.4367
1201.32	17.8093
1204.55	20.7199
1207.79	23.9815
1211.02	26.1274
1214.25	29.0531
1217.48	31.4034
1220.71	33.6512
1223.93	35.021
1227.16	36.1295
1230.38	39.0269
1233.6	40.0224
1236.83	42.031
1240.05	43.945
1243.26	44.8818
1246.48	45.8686
1249.7	46.9828
1252.92	49.9456
1256.13	52.0294
1259.34	54.393
1262.55	56.9219
1265.76	60.0117
1268.97	61.8173
1272.18	63.6562
1275.39	66.7765
1278.59	67.5089
1281.8	70.5878
1285	72.384
1288.2	75.4923
1291.4	76.7391
1294.6	77.4682
1297.8	76.3473
1301	76.643
1304.19	76.9735
1307.39	76.9127
1310.58	75.5788
1313.77	75.4756
1316.96	75.232
1320.15	72.4616
1323.34	69.8248
1326.53	67.9136
1329.72	66.0049
1332.9	64.2418
1336.08	61.1374
1339.27	60.538
1342.45	60.6557
1345.63	58.7775
1348.8	56.5791
1351.98	55.7348
1355.16	54.1433
1358.33	54.5018
1361.51	53.602
1364.68	53.1406
1367.85	50.8879
1371.02	48.7156
1374.19	46.2882
1377.36	46.0179
1380.52	45.5419
1383.69	45.5293
1386.85	44.4811
1390.02	44.6608
1393.18	45.9901
1396.34	44.4764
1399.5	45.1472
1402.65	43.9702
1405.81	46.0543
1408.97	47.7961
1412.12	50.6091
1415.27	54.8306
1418.43	62.1022
1421.58	66.9678
1424.73	71.5533
1427.87	77.2749
1431.02	82.6878
1434.17	87.4891
1437.31	92.6695
1440.46	95.4519
1443.6	98.639
1446.74	99.3033
1449.88	99.2569
1453.02	98.9594
1456.16	96.9217
1459.29	94.8716
1462.43	91.5494
1465.56	87.1956
1468.69	81.7569
1471.83	76.2877
1474.95	70.1884
1478.08	64.883
1481.21	59.1208
1484.34	55.0463
1487.47	49.9989
1490.59	46.6456
1493.71	43.4959
1496.84	38.7479
1499.96	35.8023
1503.07	33.2884
1506.19	30.3948
1509.31	27.64
1512.43	25.7829
1515.54	25.9775
1518.65	24.9158
1521.77	22.9015
1524.88	21.268
1527.99	20.8142
1531.1	21.3574
1534.21	21.4378
1537.31	22.8914
1540.42	23.0457
1543.52	23.5421
1546.63	26.5559
1549.73	29.0416
1552.83	30.3282
1555.93	32.0501
1559.03	33.3094
1562.12	33.8552
1565.22	35.2925
1568.31	37.1737
1571.41	37.5476
1574.5	39.978
1577.59	43.2219
1580.68	46.1842
1583.77	48.1472
1586.86	50.7785
1589.95	53.9122
1593.03	56.3583
1596.11	56.5997
1599.2	58.3117
1602.28	60.1293
1605.36	60.6793
1608.44	60.5899
1611.52	60.2788
1614.6	61.4811
1617.67	61.9106
1620.75	62.4797
1623.82	63.4763
1626.89	62.4954
1629.96	62.9891
1633.04	63.7456
1636.11	64.5056
1639.17	66.6507
1642.24	67.9743
1645.31	69.1495
1648.37	69.8105
1651.43	70.9596
1654.5	71.3287
1657.56	72.8998
1660.62	72.2414
1663.67	71.3619
1666.73	69.258
1669.79	66.7972
1672.84	63.8628
1675.9	60.5658
1678.95	56.0043
1682	50.9576
1685.05	45.815
1688.1	41.7375
1691.15	37.8121
1694.2	33.0139
1697.25	31.4427
1700.29	28.972
1703.33	27.7078
1706.38	26.376
1709.42	24.9081
1712.46	24.186
1715.5	23.3729
1718.54	22.27
1721.57	19.431
1724.61	18.0252
1727.64	17.6369
1730.68	17.3549
1733.71	16.2901
1736.74	15.9492
1739.77	15.2781
1742.8	15.1735
1745.83	13.6848
1748.85	11.4319
1751.88	9.9509
1754.91	8.13475
1757.93	6.22618
1760.95	4.45399
1763.97	4.26507
1766.99	3.62937
1770.01	2.71176
1773.03	3.21092
1776.04	3.52839
1779.06	4.327
1782.07	3.47529
1785.09	4.61225
1788.1	4.93072
1791.11	5.06453
1794.12	4.12026
1797.13	3.75168
1800.13	4.4166
1803.14	5.14993
1806.15	5.1913
1809.15	5.64243
1812.15	6.31306
1815.16	5.6323
1818.15	5.08444
1821.16	4.03007
1824.15	4.08132
1827.15	3.37443
1830.15	2.22913
1833.14	2.44666
1836.14	2.31214
1839.13	3.06059
1842.12	4.1819
1845.11	3.37287
1848.1	3.66176
1851.09	4.00852
1854.08	4.25412
1857.06	5.32115
1860.05	5.12037
1863.03	5.1211
1866.01	5.38983
1869	5.73471
1871.98	6.01876
1874.96	5.42738
1877.93	5.51829
1880.91	4.97791
1882.47	4.38797
1885.46	3.14264
1888.44	2.23802
1891.43	1.49979
1894.42	1.54406
1897.4	1.72195
1900.39	1.80467
1903.37	2.57903
1906.35	3.61935
1909.33	3.27121
1912.31	3.2582
1915.29	2.99808
1918.26	3.06034
1921.24	2.50032
1924.21	3.23488
1927.19	4.30138
1930.16	4.36961
1933.13	5.00512
1936.1	6.1366
1939.07	6.32075
1942.04	5.98485
1945	5.84928
1947.97	6.11936
1950.93	4.97789
1953.9	4.4295
1956.86	5.38915
1959.82	4.71089
1962.78	5.6144
1965.74	5.57044
1968.7	6.01211
1971.65	6.62166
1974.61	6.81395
1977.57	7.64651
1980.52	7.57719
1983.47	6.43175
1986.42	6.22623
1989.37	6.57081
1992.32	7.29735
1995.27	7.22763
1998.22	6.63725
2001.17	5.79414
2004.11	5.5073
2007.05	5.1971
2010	4.14034
2012.94	2.8119
2015.88	2.94308
2018.82	3.34364
2021.76	2.77595
2024.7	2.9872
2027.63	3.48395
2030.57	3.26762
2033.5	3.54774
2036.44	4.27788
2039.37	4.86402
2042.3	6.08703
2045.23	7.05138
2048.16	8.8024
2051.08	8.726
2054.01	9.25526
2056.94	10.9292
2059.86	13.0447
2062.79	14.721
2065.71	14.8244
2068.63	13.6215
2071.55	14.3528
2074.47	15.6276
2077.39	15.9876
2080.31	17.783
2083.22	17.9793
2086.13	20.2836
2089.05	22.2419
2091.96	24.3518
2094.87	26.1351
2097.78	27.7686
2100.69	30.0434
2103.6	31.9342
2106.51	34.5302
2109.42	35.9486
2112.32	36.7038
2115.23	40.2072
2118.13	43.0959
2121.03	46.0648
2123.93	49.508
2126.83	54.1385
2129.73	57.3871
2132.63	61.5793
2135.53	64.8201
2138.42	67.168
2141.32	70.1244
2144.21	75.0718
2147.1	78.4121
2150	82.6605
2152.89	87.2148
2155.78	90.4139
2158.66	92.601
2161.55	94.1675
2164.44	96.3991
2167.32	98.6227
2170.21	98.4398
2173.09	97.6495
2175.97	95.8937
2178.85	94.276
2181.73	92.0232
2184.61	88.7194
2187.49	86.9189
2190.37	84.1728
2193.24	81.8432
2196.12	79.6593
2198.99	76.8885
2201.87	73.4508
2204.74	70.2665
2207.61	65.6996
2210.48	61.0825
2213.35	57.9515
2216.21	54.0985
2219.08	51.5006
2221.95	48.5517
2224.81	45.228
2227.67	41.62
2230.54	39.0138
2233.4	37.1952
2236.26	35.0723
2239.11	31.6523
2241.97	28.911
2244.83	27.2274
2247.69	25.2912
2250.54	23.575
2253.4	22.2151
2256.25	21.7613
2259.1	21.8642
2261.95	21.3161
2264.8	22.0166
2267.65	22.6543
2270.5	21.769
2273.34	20.24
2276.19	19.9339
2279.03	17.9699
2281.88	17.631
2284.72	16.2314
2287.56	13.7918
2290.4	12.4068
2293.24	11.2684
2296.08	10.8115
2298.92	11.4797
2301.76	10.7076
2304.59	10.6113
2307.43	9.21489
2310.26	8.25348
2313.09	9.16751
2315.92	9.25791
2318.75	8.66648
2321.58	9.11012
2324.41	8.34125
2327.24	7.94173
2330.06	7.40364
2332.89	7.73777
2335.71	7.29477
2338.54	6.14674
2341.36	6.04026
2344.18	4.71645
2347	3.78552
2349.82	3.21834
2352.64	2.60278
2355.45	1.41393
2358.27	0.865057
2361.08	0.552971
2363.9	1.15818
2366.71	2.17556
2369.52	1.60838
2372.33	1.01315
2375.14	1.74066
2377.95	1.26665
2380.76	2.38723
2383.57	2.94238
2386.37	3.12242
2389.18	3.27164
2391.98	4.00079
2394.79	4.15958
2397.59	5.05128
2400.39	4.91735
2403.19	5.28985
2405.99	5.76368
2408.78	5.79009
2411.58	6.57025
2414.38	6.51081
2417.17	7.74661
2419.97	7.88338
2422.76	7.90686
2425.55	7.52576
2428.34	6.89051
2431.13	6.17603
2433.92	7.06453
2436.71	6.29827
2439.49	6.02262
2442.28	6.49093
2445.06	6.73111
2447.85	5.92997
2450.63	5.54992
2453.41	5.28971
2456.19	5.47766
2458.97	5.25055
2461.75	4.52101
2464.53	4.38268
2467.31	4.17195
2470.08	3.38198
2472.86	3.94527
2475.63	4.80947
2478.4	3.80711
2481.17	4.09714
2483.94	3.5475
2486.72	3.6951
2489.48	3.15432
2492.25	2.82159
2495.02	3.40568
2497.79	3.30603
2500.55	3.48541
2503.31	3.83555
2506.08	3.63021
2508.84	3.72443
2511.6	2.59887
2514.36	1.64452
2517.12	1.26996
2519.88	1.20478
2522.63	1.48689
2525.39	1.87776
2528.14	1.96812
2530.9	3.00621
2533.65	3.75138
2536.4	3.77864
2539.15	4.97819
2541.9	4.75486
2544.65	3.78493
2547.4	2.9754
2550.15	3.38936
2552.89	3.26318
2555.64	2.92375
2558.38	3.17183
2561.12	2.79199
2563.87	1.76162
2566.61	1.54985
2569.35	0.844626
2572.09	-0.537419
2574.83	0.211867
2577.56	0.040571
2580.3	0.175171
2583.04	2.11449
2585.77	3.03945
2588.5	4.26411
2591.23	5.03399
2593.97	6.11826
2596.7	6.70604
2599.43	7.95414
2602.15	8.25492
2604.88	7.69071
2607.61	7.33716
2610.33	6.41989
2613.06	6.95711
2615.78	6.9553
2618.51	6.63928
2621.23	6.44527
2623.95	5.93948
2626.67	5.9833
2629.39	6.10406
2632.1	7.34813
2634.82	6.82987
2637.54	6.07726
2640.25	6.81588
2642.97	8.50483
2645.68	9.13248
2648.39	10.1957
2651.1	9.82214
2653.81	9.77322
2656.52	10.0613
2659.23	9.86302
2661.94	8.63456
2664.64	8.84085
2667.35	7.19784
2670.05	6.49875
2672.76	6.10457
2675.46	5.76865
2678.16	5.33476
2680.86	5.20886
2683.56	4.8848
2686.26	4.63262
2688.96	4.04607
2691.65	4.33072
2694.35	5.82892
2697.04	5.90146
2699.74	6.03331
2702.43	6.52298
2705.12	8.3528
2707.81	9.61901
2710.5	11.1847
2713.19	10.9995
2715.88	11.0622
2718.57	11.5835
2721.25	11.9637
2723.94	12.45
2726.62	12.1482
2729.3	12.3145
2731.99	12.75
2734.67	12.6597
2737.35	12.6568
2740.03	12.3938
2742.71	11.778
2745.38	10.2486
2748.06	8.75996
2750.74	6.56856
2753.41	5.86558
2756.09	5.65595
2758.76	4.95689
2761.43	3.76851
2764.1	2.826
2766.77	2.29945
2769.44	1.3441
2772.11	1.0649
2774.77	0.394156
2777.44	-0.222241
2780.11	-0.485161
2782.77	-0.0206521
2785.43	-0.0616891
2788.1	-0.196874
2790.76	0.972615
2793.42	0.264716
2796.08	0.887193
2798.74	0.286434
2801.4	0.701458
2804.05	1.89349
2806.71	2.04346
2809.36	0.863734
2812.02	0.997246
2814.67	0.435409
2817.32	1.70705
2819.97	3.29358
2822.62	5.80303
2825.27	8.38341
2827.92	12.2955
2830.57	16.6485
2833.22	21.4698
2835.86	27.6415
2838.51	34.5439
2841.15	41.0831
2843.79	49.466
2846.43	56.8277
2849.08	65.0599
2851.72	72.4425
2854.36	81.7094
2856.99	90.185
2859.63	97.7381
2862.27	105.755
2864.9	113.256
2867.54	120.367
2870.17	126.384
2872.8	129.406
2875.43	134.344
2878.07	139.275
2880.7	143.586
2883.32	148.796
2885.95	154.859
2888.58	160.65
2891.21	166.723
2893.83	173.511
2896.46	180.593
2899.08	188.643
2901.7	197.293
2904.32	206.545
2906.94	216.954
2909.56	225.555
2912.18	235.588
2914.8	245.749
2917.42	255.329
2920.03	263.512
2922.65	270.722
2925.26	275.116
2927.88	278.063
2930.49	280.373
2933.1	279.117
2935.71	277.214
2938.32	273.668
2940.93	268.152
2943.54	261.371
2946.14	253.503
2948.75	245.074
2951.35	236.077
2953.96	227.068
2956.56	217.129
2959.16	207.131
2961.77	197.296
2964.37	186.933
2966.96	178.063
2969.56	168.195
2972.16	158.848
2974.76	149.179
2977.35	140.396
2979.95	130.675
2982.54	120.554
2985.14	109.596
2987.73	99.7523
2990.32	90.1261
2992.91	80.9078
2995.5	72.1731
2998.09	63.2385
3000.68	54.6097
3003.26	46.0621
3005.85	39.7869
3008.43	32.6547
3011.02	27.5754
3013.6	22.8322
3016.19	18.4049
3018.77	14.9656
3021.35	10.4342
3023.93	7.39219
3026.5	6.26003
3029.08	4.35398
3031.66	3.19035
3034.24	2.96583
3036.81	2.50671
3039.39	1.87579
3041.96	2.81179
3044.53	3.85012
3047.1	3.25503
3049.67	3.51076
3052.24	4.45013
3054.81	4.01424
3057.38	4.02259
3059.95	4.37422
3062.52	3.8745
3065.08	4.49183
3067.65	3.59574
3070.21	3.0573
3072.77	2.81367
3075.33	3.13148
3077.89	2.4677
3080.45	1.81604
3083.01	1.16788
3085.57	1.23705
3088.13	1.88962
3090.68	2.70612
3093.24	2.14852
3095.79	3.4036
3098.35	4.13915
3100.9	4.92551
3103.45	6.06015
3106	7.57594
3108.55	7.74134
3111.1	9.06689
3113.65	10.9282
3116.2	11.8611
3118.75	13.815
3121.29	16.1332
3123.84	18.0797
3126.38	19.7609
3128.92	21.4768
3131.47	23.393
3134.01	26.3079
3136.55	28.8887
3139.09	30.8611
3141.63	33.1253
3144.17	35.2743
3146.7	36.8951
3149.24	36.7189