File: data/Raman/poly_smoothed/Mb_40_y_15_1x_45s_532 nm_x100_100%_600 gr_mm_01.txt
#Acq. time (s)=	45
#Accumulations=	2
#Range (cm-¹)=	200...3150
#Windows=	2
#Auto scanning=	Off
#Autofocus=	Off
#Macrospot=	Off
#AutoExposure=	Off
#Spike filter=	Multiple accum.
#Delay time (s)=	0
#Binning=	1
#Readout mode=	Signal
#DeNoise=	Off
#ICS correction=	On
#Dark correction=	Off
#Inst. Process=	Off
#Detector Gain=	Best Dynamic Range
#Detector ADC=	20 kHz
#Detector temperature (°C)=	-69.85
#Instrument=	LabRAM HR Evol
#Detector=	Synapse
#Objective=	x100
#Grating=	600 gr/mm
#ND Filter=	100%
#Laser (nm)=	532
#Hole=	100.021
#Range=	Auto
#Laser Pol.=	No
#Raman. Pol.=	No
#Laser Pol. (°)=	-0.0007625
#Raman Pol. (°)=	89.9995
#Collection=	Microscope
#StageXY=	Marzhauser
#StageZ=	Marzhauser
#X (µm)=	-1056.5
#Y (µm)=	659.8
#Z (µm)=	584.55
#Full time(mm:ss)=	3:18
#Project=
#Sample=
#Site=
#Title=	Mb_40_y_15_2x_45s_532 nm_x100_100%_600 gr_mm
#Remark=
#Date=	19.07.2022 10:15
#Acquired=	19.07.2022 10:15:51
#Base:Fit=	10.08.2022 10:52:48
#Base:Sub=	10.08.2022 10:52:53
#Filter:Polynom=	16.08.2022 10:09:04
#AxisType[0]=Intens
#AxisUnit[0]=Cnt
#AxisType[1]=Spectr
#AxisUnit[1]=1/cm
200.423	27.8278
204.052	27.1507
207.682	25.1262
211.308	23.6731
214.935	22.5389
218.558	22.0404
222.18	20.3532
225.802	21.3107
229.421	21.1025
233.039	18.9375
236.657	17.0195
240.272	15.2626
243.885	12.9829
247.497	11.8133
251.11	11.8784
254.719	11.351
258.327	10.2847
261.933	10.7736
265.538	11.1971
269.141	10.5358
272.744	9.24334
276.344	10.2189
279.944	11.23
283.542	11.8727
287.138	11.3707
290.733	11.1894
294.327	10.9685
297.919	11.63
301.508	12.1381
305.098	10.4711
308.686	10.7869
312.273	10.419
315.858	10.5163
319.44	7.38016
323.022	4.63846
326.604	4.22778
330.181	3.07574
333.76	2.40993
337.335	2.77799
340.91	3.03938
344.483	1.69659
348.055	1.16532
351.625	1.89304
355.195	1.93345
358.762	1.74646
362.329	3.1489
365.893	4.40037
369.455	5.87135
373.017	6.9419
376.578	7.20257
380.137	8.41379
383.694	8.42846
387.249	9.60995
390.806	9.69894
394.359	11.6061
397.91	11.3832
401.46	11.8864
405.009	11.1261
408.557	11.3368
412.103	12.7501
415.647	12.4599
419.191	10.8261
422.733	11.0978
426.273	10.2248
429.812	9.32183
433.35	8.23071
436.885	6.92918
440.42	7.39648
443.954	5.27194
447.486	2.98152
451.015	3.18509
454.545	2.25351
458.073	2.47175
461.598	1.84926
465.124	1.52736
468.648	0.801093
472.169	2.22634
475.69	5.26499
479.208	6.12645
482.727	6.97207
486.243	8.36919
489.759	8.99969
493.272	10.3684
496.783	13.2608
500.295	14.2689
503.804	13.9227
507.311	15.7256
510.819	17.4255
514.324	17.1735
517.827	17.2379
521.329	17.7655
524.83	16.7623
528.329	15.9255
531.829	14.6066
535.326	14.7084
538.821	13.8044
542.315	14.1121
545.808	15.4732
549.299	14.3798
552.789	13.0154
556.278	13.2353
559.763	13.0849
563.249	11.6769
566.733	10.1606
570.217	9.69743
573.699	8.72694
577.177	7.6042
580.656	6.08544
584.134	5.44025
587.609	5.32514
591.084	5.05218
594.558	5.14214
598.029	5.39843
601.5	6.01806
604.968	6.1769
608.437	7.44602
611.902	8.99662
615.368	9.52242
618.831	10.3325
622.294	11.6201
625.755	10.3069
629.213	11.2563
632.673	10.221
636.129	11.0527
639.584	9.96752
643.037	8.86229
646.491	7.42437
649.942	7.38621
653.392	7.09603
656.84	6.02975
660.287	5.9751
663.732	7.81224
667.177	7.80757
670.62	10.2153
674.061	10.7857
677.502	11.9544
680.941	14.8443
684.379	16.6074
687.815	18.7166
691.248	21.1117
694.682	23.3822
698.115	26.1705
701.546	28.7906
704.974	31.4157
708.402	34.0021
711.83	36.0801
715.254	39.126
718.679	40.5418
722.102	41.8166
725.522	41.2643
728.943	41.3814
732.361	43.0141
735.779	43.5915
739.194	43.7674
742.608	44.428
746.022	45.7145
749.433	45.3013
752.843	45.1622
756.254	44.9559
759.661	45.1148
763.067	45.9558
766.471	48.4288
769.877	50.6196
773.279	52.4141
776.68	53.0464
780.079	56.2919
783.478	60.0855
786.875	62.2189
790.27	63.2011
793.665	63.7734
797.058	65.3307
800.45	66.1811
803.84	66.3204
807.23	66.6281
810.616	67.3876
814.002	67.6011
817.388	66.5489
820.772	64.6054
824.153	63.5954
827.535	62.966
830.915	60.7856
834.292	59.4733
837.67	57.8107
841.047	56.7352
844.42	54.6228
847.794	53.3385
851.165	51.7262
854.534	47.7172
857.905	46.4997
861.272	43.031
864.639	41.4358
868.004	39.9225
871.367	37.2403
874.731	36.5009
878.092	35.7269
881.451	36.3791
884.809	35.7122
888.166	36.5752
891.522	35.4705
894.878	35.0006
898.231	35.141
901.583	34.4186
904.934	34.3996
908.283	34.5251
911.631	34.0938
914.976	33.6925
918.322	33.7649
921.666	34.1353
925.009	33.4663
928.351	32.2239
931.692	30.4177
935.029	29.3225
938.367	27.3112
941.704	26.9919
945.038	26.3537
948.372	27.087
951.705	28.1975
955.035	28.1945
958.366	28.2859
961.693	28.4007
965.021	27.81
968.346	27.2375
971.67	23.9706
974.995	23.4704
978.316	25.0206
981.638	23.7155
984.957	21.459
988.274	20.6979
991.59	18.8724
994.907	18.3933
998.221	13.7557
1001.53	9.09988
1004.85	5.59584
1008.16	7.99478
1011.46	17.0325
1014.77	31.6157
1018.08	49.2855
1021.38	67.9478
1024.69	86.1244
1027.99	102.211
1031.29	117.369
1034.59	129.617
1037.89	138.342
1041.19	145.14
1044.48	147.11
1047.78	146.551
1051.07	142.875
1054.36	137.914
1057.66	130.555
1060.94	118.03
1064.23	103.458
1067.52	87.0501
1070.81	68.9688
1074.09	49.6596
1077.38	29.1523
1080.66	11.7001
1083.94	-0.421497
1087.22	-5.35601
1090.5	-3.42236
1093.77	0.5139
1097.05	3.80145
1100.32	8.264
1103.6	12.5525
1106.87	14.7599
1110.14	16.2674
1113.41	17.8959
1116.67	19.5117
1119.94	20.5031
1123.21	20.2229
1126.47	19.9208
1129.73	19.947
1133	19.0896
1136.26	16.9509
1139.52	16.3534
1142.77	15.8299
1146.03	15.0648
1149.29	12.3718
1152.54	10.4193
1155.79	8.55924
1159.04	7.67596
1162.3	6.10646
1165.55	3.87691
1168.79	3.35037
1172.04	2.75175
1175.28	2.27764
1178.53	2.96321
1181.77	4.18889
1185.01	3.30769
1188.25	4.41502
1191.49	5.2094
1194.73	5.87131
1197.97	6.1493
1201.2	5.93688
1204.44	5.45992
1207.67	6.73559
1210.9	7.22962
1214.13	8.3315
1217.36	10.4841
1220.59	12.4321
1223.82	13.6586
1227.04	15.0999
1230.26	16.5663
1233.49	18.0589
1236.71	20.4173
1239.93	21.6025
1243.15	23.1669
1246.37	24.1736
1249.58	26.4606
1252.8	26.6392
1256.01	27.3188
1259.23	27.7286
1262.44	27.478
1265.65	30.9766
1268.86	36.3029
1272.07	41.3187
1275.27	45.9401
1278.48	49.7906
1281.68	51.9667
1284.89	54.4492
1288.09	56.7731
1291.29	59.5692
1294.49	63.201
1297.69	64.8865
1300.88	67.6194
1304.08	68.6074
1307.27	70.783
1310.47	70.2025
1313.66	69.9487
1316.85	68.716
1320.04	68.6188
1323.23	67.4038
1326.41	64.3917
1329.6	59.5671
1332.78	55.2199
1335.97	52.3588
1339.15	48.7314
1342.33	48.9098
1345.51	49.9073
1348.69	46.8224
1351.87	44.6459
1355.04	42.1742
1358.22	40.468
1361.39	38.6321
1364.57	35.0985
1367.74	33.2979
1370.91	32.7214
1374.07	31.5765
1377.24	30.9716
1380.41	30.1229
1383.57	29.7439
1386.74	28.1742
1389.9	28.7552
1393.06	29.5265
1396.22	30.0864
1399.38	31.9265
1402.54	34.5928
1405.7	36.5961
1408.85	40.3275
1412.01	43.1468
1415.16	46.421
1418.31	49.6262
1421.46	54.7795
1424.61	58.6189
1427.76	63.9625
1430.91	69.4096
1434.05	75.8876
1437.2	80.2296
1440.34	81.9967
1443.49	85.7041
1446.63	86.3835
1449.77	88.4168
1452.91	88.1841
1456.04	87.0074
1459.18	85.986
1462.31	85.9631
1465.45	84.7589
1468.58	82.6961
1471.71	80.7371
1474.84	79.3944
1477.97	77.4024
1481.1	74.4673
1484.23	71.5704
1487.35	67.9912
1490.48	62.4444
1493.6	60.0187
1496.72	56.3517
1499.84	51.441
1502.96	46.558
1506.08	42.5825
1509.2	40.3049
1512.31	37.0277
1515.43	33.8608
1518.54	29.0345
1521.66	26.3814
1524.77	23.4054
1527.88	21.6359
1530.99	20.697
1534.09	20.8627
1537.2	21.9871
1540.31	23.0773
1543.41	24.77
1546.51	26.2431
1549.62	28.1835
1552.72	29.2371
1555.82	30.4036
1558.91	31.1152
1562.01	31.9117
1565.11	32.6482
1568.2	31.853
1571.3	33.2677
1574.39	34.499
1577.48	35.6509
1580.57	35.7561
1583.66	38.4264
1586.75	40.7743
1589.83	42.4011
1592.92	43.7163
1596	44.257
1599.09	45.1025
1602.17	45.6818
1605.25	47.2443
1608.33	47.2059
1611.41	47.0207
1614.48	48.1822
1617.56	47.585
1620.64	48.4537
1623.71	48.6575
1626.78	48.9557
1629.86	50.4422
1632.92	51.0749
1635.99	50.8124
1639.06	51.3881
1642.13	52.5743
1645.19	53.6193
1648.26	54.0391
1651.32	55.871
1654.38	56.056
1657.45	55.8621
1660.51	55.7331
1663.57	54.0979
1666.62	53.0994
1669.68	50.3625
1672.73	47.5334
1675.79	45.0405
1678.84	40.787
1681.89	35.5508
1684.94	30.9757
1687.99	27.6059
1691.04	24.2272
1694.09	21.1309
1697.14	18.25
1700.18	15.8834
1703.22	13.1682
1706.27	12.3494
1709.31	9.85918
1712.35	7.24851
1715.39	7.48647
1718.43	6.92796
1721.46	6.18233
1724.5	6.26611
1727.53	5.72803
1730.57	5.46169
1733.6	5.51498
1736.63	6.28895
1739.66	5.76368
1742.69	4.98631
1745.72	4.05461
1748.74	4.30843
1751.77	3.65678
1754.8	3.39492
1757.82	4.00924
1760.84	3.72657
1763.86	4.00101
1766.88	4.17074
1769.9	3.53993
1772.92	3.59459
1775.93	3.96099
1778.95	4.34893
1781.96	3.95603
1784.98	4.58727
1787.99	5.31407
1791	5.30699
1794.01	5.89595
1797.02	6.3067
1800.03	7.16527
1803.03	6.74913
1806.04	6.85618
1809.04	6.70456
1812.04	5.96679
1815.05	5.34079
1818.05	5.01245
1821.05	5.94486
1824.05	5.43819
1827.04	5.76706
1830.04	5.99012
1833.03	4.73921
1836.03	4.62222
1839.02	4.584
1842.01	4.69134
1845	4.83287
1847.99	4.82858
1850.98	4.48515
1853.97	3.84087
1856.95	3.76957
1859.94	3.54886
1862.92	2.84061
1865.91	2.95439
1868.89	2.94527
1871.87	2.72761
1874.85	2.59255
1877.83	2.31549
1880.8	2.75534
1882.56	2.86217
1885.54	3.3692
1888.53	4.09564
1891.52	4.78989
1894.5	4.49098
1897.49	5.19359
1900.47	6.23835
1903.45	6.60802
1906.43	6.42397
1909.41	5.98773
1912.39	5.21413
1915.37	5.09766
1918.35	4.7133
1921.32	5.19266
1924.3	5.0351
1927.27	3.93596
1930.24	4.08848
1933.21	3.35338
1936.18	2.65117
1939.15	2.19671
1942.12	1.96726
1945.09	2.52188
1948.05	2.85237
1951.02	3.89227
1953.98	3.82413
1956.94	3.81442
1959.91	5.66394
1962.87	5.65454
1965.82	5.84195
1968.78	6.09293
1971.74	5.95979
1974.7	5.26141
1977.65	4.29382
1980.6	3.49028
1983.56	2.9611
1986.51	3.56644
1989.46	3.36143
1992.41	3.62454
1995.36	4.4178
1998.3	3.55201
2001.25	3.76009
2004.2	3.82282
2007.14	3.39095
2010.08	3.72301
2013.02	4.90975
2015.97	5.43322
2018.9	6.14216
2021.84	7.0486
2024.78	7.84966
2027.72	7.99268
2030.65	8.57284
2033.59	9.00289
2036.52	8.44259
2039.45	8.21193
2042.38	8.56945
2045.31	7.47558
2048.24	7.19816
2051.17	7.14605
2054.1	5.90989
2057.02	6.52159
2059.95	7.12005
2062.87	7.42714
2065.79	8.31415
2068.71	8.25071
2071.63	9.2199
2074.55	10.1378
2077.47	10.5454
2080.39	11.4329
2083.3	12.7789
2086.22	13.6766
2089.13	15.2161
2092.05	17.1897
2094.96	18.5271
2097.87	19.275
2100.78	20.1732
2103.69	22.3624
2106.59	23.8884
2109.5	24.8357
2112.41	27.3433
2115.31	28.8306
2118.21	29.578
2121.12	31.6957
2124.02	32.8602
2126.92	34.4516
2129.82	37.0978
2132.71	38.6881
2135.61	40.2716
2138.51	41.3777
2141.4	43.1488
2144.29	45.4028
2147.19	47.4115
2150.08	50.0783
2152.97	52.6898
2155.86	53.6041
2158.75	55.4617
2161.64	56.6795
2164.52	58.6125
2167.41	59.9168
2170.29	60.5141
2173.17	61.2933
2176.06	62.657
2178.94	61.8938
2181.82	62.2173
2184.7	61.9274
2187.57	61.1069
2190.45	59.5248
2193.33	57.3714
2196.2	56.4406
2199.08	54.379
2201.95	52.2639
2204.82	49.1237
2207.69	46.0708
2210.56	42.9892
2213.43	39.9551
2216.3	37.4204
2219.16	35.242
2222.03	32.1215
2224.89	29.4711
2227.75	27.2905
2230.62	25.2928
2233.48	23.3592
2236.34	21.7199
2239.2	18.8584
2242.06	17.9833
2244.91	17.6432
2247.77	17.0304
2250.62	16.6022
2253.48	17.4283
2256.33	17.3941
2259.18	17.1106
2262.03	16.2694
2264.88	15.7103
2267.73	15.7625
2270.58	14.6695
2273.43	14.6881
2276.27	13.1348
2279.12	11.7132
2281.96	10.5112
2284.8	9.39614
2287.64	9.43074
2290.49	8.89143
2293.32	7.10776
2296.16	7.29558
2299	6.69254
2301.84	6.67952
2304.67	6.57031
2307.51	6.22562
2310.34	6.82888
2313.17	7.37866
2316	8.54559
2318.83	8.68519
2321.66	8.76795
2324.49	9.29818
2327.32	8.37103
2330.15	7.78097
2332.97	7.39996
2335.79	7.01274
2338.62	7.11733
2341.44	7.01785
2344.26	6.50387
2347.08	5.43489
2349.9	4.60302
2352.72	4.23597
2355.53	3.66043
2358.35	3.1832
2361.17	2.3549
2363.98	2.18018
2366.79	3.77801
2369.6	3.52203
2372.42	3.30963
2375.22	3.40799
2378.03	3.56077
2380.84	3.58518
2383.65	4.04404
2386.45	2.74296
2389.26	2.7952
2392.06	2.8881
2394.87	2.74008
2397.67	2.78684
2400.47	3.72952
2403.27	4.38278
2406.07	5.06695
2408.86	6.42252
2411.66	6.61262
2414.46	6.60361
2417.25	6.93059
2420.05	6.80894
2422.84	6.73066
2425.63	7.12635
2428.42	5.74923
2431.21	5.19107
2434	4.46588
2436.79	4.44462
2439.57	3.22899
2442.36	2.46696
2445.14	2.24947
2447.93	1.61178
2450.71	1.32147
2453.49	-0.152912
2456.27	-0.228705
2459.05	0.588274
2461.83	0.677493
2464.61	0.737755
2467.39	0.97108
2470.16	2.18323
2472.94	2.32334
2475.71	3.27384
2478.48	3.00811
2481.25	2.39009
2484.02	3.15155
2486.8	2.49175
2489.56	2.54282
2492.33	2.40274
2495.1	2.415
2497.86	2.12968
2500.63	2.38658
2503.39	2.7586
2506.16	2.57153
2508.92	2.27072
2511.68	2.15676
2514.44	1.98517
2517.2	2.16018
2519.95	2.09398
2522.71	1.96113
2525.47	2.56479
2528.22	2.44536
2530.98	2.51883
2533.73	1.79021
2536.48	1.83123
2539.23	2.22891
2541.98	1.79656
2544.73	1.0761
2547.48	0.286765
2550.23	0.0176992
2552.97	0.51838
2555.72	-0.388857
2558.46	0.339818
2561.2	0.963962
2563.95	1.04665
2566.69	1.7966
2569.43	2.16299
2572.17	1.53064
2574.91	1.43238
2577.64	1.61723
2580.38	1.85135
2583.11	2.00584
2585.85	3.23631
2588.58	2.95422
2591.31	2.80404
2594.04	3.59202
2596.78	3.29339
2599.51	3.59388
2602.23	3.18159
2604.96	3.5656
2607.69	3.05234
2610.41	2.12356
2613.14	2.36219
2615.86	2.60275
2618.58	3.06807
2621.3	2.97202
2624.03	2.98453
2626.75	3.0006
2629.46	3.33597
2632.18	4.32019
2634.9	4.35161
2637.61	4.16139
2640.33	4.38417
2643.04	4.54657
2645.76	3.98366
2648.47	4.05726
2651.18	4.25678
2653.89	4.83077
2656.6	3.98377
2659.31	4.56148
2662.01	4.02458
2664.72	3.8416
2667.43	3.48379
2670.13	3.0571
2672.83	3.22585
2675.53	2.51796
2678.24	2.36605
2680.94	2.63259
2683.64	1.94791
2686.34	2.01337
2689.03	2.01719
2691.73	2.56679
2694.43	3.72214
2697.12	4.38656
2699.81	5.17505
2702.51	5.97739
2705.2	6.85617
2707.89	7.00744
2710.58	7.01731
2713.27	8.66252
2715.96	9.21098
2718.64	9.63093
2721.33	10.7065
2724.01	10.8212
2726.7	9.86016
2729.38	8.60486
2732.06	8.65812
2734.75	8.02366
2737.43	6.52739
2740.11	6.18519
2742.78	4.52836
2745.46	3.91537
2748.14	3.28505
2750.81	2.79441
2753.49	2.02601
2756.16	1.94399
2758.84	1.82878
2761.51	1.82534
2764.18	1.51514
2766.85	1.28432
2769.52	1.67908
2772.19	2.20639
2774.85	1.76539
2777.52	1.92632
2780.18	1.78111
2782.85	2.13408
2785.51	2.13095
2788.17	0.956416
2790.84	0.513103
2793.5	0.284213
2796.16	0.777558
2798.81	0.918026
2801.47	1.38039
2804.13	2.11644
2806.79	2.11314
2809.44	1.8452
2812.09	2.20266
2814.75	2.67941
2817.4	3.74225
2820.05	6.83877
2822.7	10.4498
2825.35	14.6799
2828	18.7318
2830.65	23.9507
2833.29	29.3816
2835.94	35.0322
2838.58	39.9767
2841.23	44.3728
2843.87	49.4746
2846.51	54.562
2849.15	60.1718
2851.79	66.0622
2854.43	71.9564
2857.07	78.1891
2859.71	82.8791
2862.34	87.6081
2864.98	91.0107
2867.61	94.1212
2870.25	95.7799
2872.88	97.741
2875.51	100.321
2878.14	102.705
2880.77	104.543
2883.4	106.305
2886.03	108.038
2888.65	109.514
2891.28	111.666
2893.91	114.372
2896.53	116.42
2899.15	117.97
2901.78	120.814
2904.4	123.542
2907.02	127.523
2909.64	132.359
2912.26	137.484
2914.87	142.755
2917.49	148.147
2920.11	152.621
2922.72	156.681
2925.34	158.814
2927.95	161.185
2930.56	162.996
2933.17	163.494
2935.78	163.926
2938.39	162.785
2941	159.619
2943.61	155.981
2946.22	150.621
2948.82	145.438
2951.43	139.47
2954.03	133.611
2956.64	127.744
2959.24	120.765
2961.84	114.602
2964.44	108.144
2967.04	102.288
2969.64	96.515
2972.24	89.6065
2974.83	83.6324
2977.43	76.7975
2980.02	70.6288
2982.62	64.9699
2985.21	59.6931
2987.8	53.3059
2990.4	48.4917
2992.99	43.1668
2995.57	38.3065
2998.16	32.6543
3000.75	28.9785
3003.34	24.5151
3005.92	21.019
3008.51	17.831
3011.09	14.7317
3013.68	12.4678
3016.26	9.66945
3018.84	7.84928
3021.42	6.98166
3024	5.86755
3026.58	4.60337
3029.16	3.74528
3031.73	2.49365
3034.31	1.04742
3036.89	0.928704
3039.46	1.5391
3042.03	1.21345
3044.61	2.34321
3047.18	2.82958
3049.75	4.42955
3052.32	4.57033
3054.89	5.10066
3057.45	4.8455
3060.02	6.01594
3062.59	6.4406
3065.15	6.2615
3067.72	5.88358
3070.28	5.86288
3072.84	6.02667
3075.41	5.10771
3077.97	4.52041
3080.53	3.95325
3083.09	3.67272
3085.64	2.77174
3088.2	1.92654
3090.76	0.661249
3093.31	0.0989506
3095.87	-1.15182
3098.42	-1.01829
3100.97	-0.945868
3103.53	-0.934128
3106.08	-0.623137
3108.63	0.165358
3111.18	1.88938
3113.73	2.87015
3116.27	3.77494
3118.82	4.16184
3121.37	5.40323
3123.91	6.72885
3126.45	6.92753
3129	7.63881
3131.54	9.05222
3134.08	10.6132
3136.62	11.5213
3139.16	12.8288
3141.7	13.4858
3144.24	13.6253
3146.78	13.4666
3149.31	12.4443