File: data/Raman/poly_smoothed/Mb_40_y_22_1x_45s_532 nm_x100_100%_600 gr_mm_02.txt
#Acq. time (s)=	45
#Accumulations=	2
#Range (cm-¹)=	200...3150
#Windows=	2
#Auto scanning=	Off
#Autofocus=	Off
#Macrospot=	Off
#AutoExposure=	Off
#Spike filter=	Multiple accum.
#Delay time (s)=	0
#Binning=	1
#Readout mode=	Signal
#DeNoise=	Off
#ICS correction=	On
#Dark correction=	Off
#Inst. Process=	Off
#Detector Gain=	Best Dynamic Range
#Detector ADC=	20 kHz
#Detector temperature (°C)=	-69.85
#Instrument=	LabRAM HR Evol
#Detector=	Synapse
#Objective=	x100
#Grating=	600 gr/mm
#ND Filter=	100%
#Laser (nm)=	532
#Hole=	100.021
#Range=	Auto
#Laser Pol.=	No
#Raman. Pol.=	No
#Laser Pol. (°)=	-0.0007625
#Raman Pol. (°)=	89.9995
#Collection=	Microscope
#StageXY=	Marzhauser
#StageZ=	Marzhauser
#X (µm)=	-1013.6
#Y (µm)=	642.3
#Z (µm)=	584.35
#Full time(mm:ss)=	3:18
#Project=
#Sample=
#Site=
#Title=	Mb_40_y_22_2x_45s_532 nm_x100_100%_600 gr_mm
#Remark=
#Date=	19.07.2022 10:49
#Acquired=	19.07.2022 10:49:10
#Base:Fit=	10.08.2022 10:52:48
#Base:Sub=	10.08.2022 10:52:53
#Filter:Polynom=	16.08.2022 10:09:04
#AxisType[0]=Intens
#AxisUnit[0]=Cnt
#AxisType[1]=Spectr
#AxisUnit[1]=1/cm
200.423	23.8475
204.052	22.3639
207.682	20.5424
211.308	17.2165
214.935	14.9678
218.558	13.2381
222.18	13.4853
225.802	13.3969
229.421	13.1989
233.039	12.129
236.657	11.9814
240.272	10.07
243.885	9.87595
247.497	7.59363
251.11	6.7922
254.719	6.15551
258.327	6.05212
261.933	6.69669
265.538	6.82558
269.141	7.95288
272.744	9.35038
276.344	7.5442
279.944	8.05304
283.542	8.07124
287.138	6.60962
290.733	7.74885
294.327	7.82119
297.919	9.29027
301.508	12.6323
305.098	13.4233
308.686	12.8343
312.273	14.2928
315.858	15.7641
319.44	15.6347
323.022	15.7725
326.604	16.432
330.181	15.2406
333.76	16.3962
337.335	14.7508
340.91	15.2459
344.483	14.5141
348.055	13.4344
351.625	12.3696
355.195	12.8381
358.762	12.0839
362.329	10.9667
365.893	10.5684
369.455	9.99471
373.017	11.3433
376.578	10.9948
380.137	13.7972
383.694	12.7462
387.249	12.516
390.806	11.613
394.359	10.3752
397.91	12.5326
401.46	13.5906
405.009	14.2566
408.557	13.5739
412.103	14.0775
415.647	12.7296
419.191	12.4291
422.733	11.4102
426.273	10.981
429.812	10.886
433.35	8.88144
436.885	7.70014
440.42	5.6919
443.954	4.52866
447.486	4.98578
451.015	4.68696
454.545	3.7312
458.073	5.19357
461.598	6.35847
465.124	7.25268
468.648	8.8377
472.169	10.3741
475.69	12.0958
479.208	12.8967
482.727	15.3942
486.243	15.6462
489.759	16.8431
493.272	16.9791
496.783	16.7177
500.295	16.9417
503.804	16.1947
507.311	16.2143
510.819	16.1821
514.324	15.7161
517.827	16.407
521.329	15.3816
524.83	12.7627
528.329	12.434
531.829	13.0065
535.326	11.4777
538.821	9.82157
542.315	9.14323
545.808	9.88294
549.299	9.98479
552.789	8.64647
556.278	8.90602
559.763	6.96088
563.249	5.11631
566.733	3.57851
570.217	2.91241
573.699	3.04821
577.177	2.4388
580.656	2.69023
584.134	2.48402
587.609	0.914772
591.084	1.91734
594.558	3.31244
598.029	3.14893
601.5	5.37913
604.968	5.07172
608.437	3.97981
611.902	3.63775
615.368	4.78199
618.831	3.92064
622.294	4.27158
625.755	5.02284
629.213	5.74089
632.673	5.31513
636.129	4.67663
639.584	5.00115
643.037	4.96167
646.491	6.3333
649.942	8.20878
653.392	8.59512
656.84	10.6264
660.287	11.9604
663.732	13.2295
667.177	14.7255
670.62	15.4182
674.061	17.8228
677.502	19.2217
680.941	19.3112
684.379	21.0995
687.815	23.1933
691.248	23.8634
694.682	26.0362
698.115	28.4407
701.546	29.5138
704.974	32.1899
708.402	34.7298
711.83	36.838
715.254	39.0125
718.679	39.9318
722.102	41.8701
725.522	43.3988
728.943	45.8342
732.361	47.1663
735.779	47.4471
739.194	49.129
742.608	50.2355
746.022	52.4352
749.433	53.9738
752.843	54.4881
756.254	54.4435
759.661	55.6475
763.067	55.9227
766.471	57.9016
769.877	59.7714
773.279	62.375
776.68	63.4455
780.079	64.7929
783.478	66.4956
786.875	69.6992
790.27	71.9358
793.665	74.2343
797.058	75.2473
800.45	74.957
803.84	77.0469
807.23	76.2856
810.616	75.9084
814.002	76.4692
817.388	74.735
820.772	73.8951
824.153	72.5477
827.535	70.7791
830.915	69.0354
834.292	66.1995
837.67	63.7458
841.047	61.602
844.42	60.0486
847.794	57.5524
851.165	54.9943
854.534	52.8291
857.905	51.1248
861.272	48.7095
864.639	45.6149
868.004	44.5207
871.367	43.826
874.731	43.3636
878.092	42.197
881.451	39.5772
884.809	40.8626
888.166	40.3582
891.522	40.4048
894.878	41.2604
898.231	41.8706
901.583	42.637
904.934	42.8835
908.283	44.933
911.631	45.3691
914.976	46.246
918.322	48.301
921.666	47.6104
925.009	47.7769
928.351	48.2834
931.692	47.7915
935.029	47.5379
938.367	47.2136
941.704	46.3959
945.038	42.9857
948.372	42.3344
951.705	41.0863
955.035	38.8785
958.366	38.0578
961.693	36.5267
965.021	34.5766
968.346	34.6317
971.67	31.9269
974.995	31.5152
978.316	31.4631
981.638	29.9885
984.957	29.6305
988.274	29.1307
991.59	26.8965
994.907	26.4911
998.221	24.3376
1001.53	20.8198
1004.85	18.6059
1008.16	19.2126
1011.46	24.4796
1014.77	33.1185
1018.08	42.5637
1021.38	51.8213
1024.69	61.9609
1027.99	70.2657
1031.29	76.9755
1034.59	82.8394
1037.89	87.6946
1041.19	91.1471
1044.48	92.3642
1047.78	91.8139
1051.07	90.1264
1054.36	87.6196
1057.66	83.3948
1060.94	76.7598
1064.23	69.9056
1067.52	60.1135
1070.81	48.9576
1074.09	36.8983
1077.38	25.7598
1080.66	14.5924
1083.94	6.11434
1087.22	3.49813
1090.5	3.48813
1093.77	5.65678
1097.05	8.58935
1100.32	10.4793
1103.6	12.6108
1106.87	13.8793
1110.14	13.7973
1113.41	14.4435
1116.67	15.294
1119.94	16.4241
1123.21	16.3731
1126.47	17.1484
1129.73	17.0133
1133	17.1143
1136.26	16.7398
1139.52	15.6985
1142.77	15.1123
1146.03	14.4748
1149.29	11.4776
1152.54	11.6209
1155.79	10.3867
1159.04	9.14703
1162.3	8.68544
1165.55	8.45504
1168.79	8.13282
1172.04	8.4135
1175.28	8.75524
1178.53	8.07208
1181.77	6.5066
1185.01	6.29195
1188.25	6.21023
1191.49	5.91715
1194.73	5.8827
1197.97	6.14748
1201.2	6.8943
1204.44	9.12553
1207.67	10.5489
1210.9	11.0446
1214.13	10.7578
1217.36	10.7655
1220.59	12.7543
1223.82	13.837
1227.04	14.0425
1230.26	15.7931
1233.49	18.1498
1236.71	18.2834
1239.93	19.26
1243.15	20.3587
1246.37	21.2031
1249.58	21.7785
1252.8	20.996
1256.01	20.6593
1259.23	21.3461
1262.44	22.6611
1265.65	24.5191
1268.86	25.4796
1272.07	27.505
1275.27	29.3597
1278.48	30.9738
1281.68	32.2574
1284.89	33.4251
1288.09	34.36
1291.29	34.9268
1294.49	35.4435
1297.69	36.0477
1300.88	34.9921
1304.08	34.1495
1307.27	34.7411
1310.47	36.1521
1313.66	35.9496
1316.85	35.7557
1320.04	36.4955
1323.23	36.8016
1326.41	36.9313
1329.6	36.7685
1332.78	36.9232
1335.97	37.8869
1339.15	38.6958
1342.33	39.9522
1345.51	40.3483
1348.69	40.4691
1351.87	40.4519
1355.04	38.7391
1358.22	38.0819
1361.39	38.3501
1364.57	38.499
1367.74	36.1603
1370.91	35.479
1374.07	34.33
1377.24	33.0333
1380.41	31.5201
1383.57	30.9751
1386.74	29.9902
1389.9	29.9235
1393.06	27.5227
1396.22	27.4945
1399.38	28.1053
1402.54	27.8018
1405.7	28.6935
1408.85	30.0573
1412.01	32.3909
1415.16	33.5581
1418.31	33.7818
1421.46	33.9453
1424.61	35.8642
1427.76	37.2402
1430.91	40.4982
1434.05	42.6706
1437.2	44.3273
1440.34	45.6917
1443.49	45.3359
1446.63	45.8141
1449.77	46.2259
1452.91	45.7009
1456.04	45.3613
1459.18	44.5423
1462.31	43.3571
1465.45	44.1593
1468.58	43.7893
1471.71	44.322
1474.84	44.784
1477.97	43.956
1481.1	43.7825
1484.23	43.0512
1487.35	42.5478
1490.48	40.0416
1493.6	37.9959
1496.72	36.2039
1499.84	35.2682
1502.96	33.0098
1506.08	31.7968
1509.2	30.3049
1512.31	28.2453
1515.43	25.5117
1518.54	22.6527
1521.66	21.0561
1524.77	19.88
1527.88	18.7694
1530.99	18.2008
1534.09	17.8359
1537.2	17.8288
1540.31	17.5612
1543.41	18.4974
1546.51	18.481
1549.62	19.1345
1552.72	20.9466
1555.82	20.7312
1558.91	22.3855
1562.01	23.256
1565.11	23.3426
1568.2	23.1114
1571.3	24.4751
1574.39	26.9319
1577.48	28.2824
1580.57	29.8338
1583.66	31.3242
1586.75	33.0098
1589.83	34.5652
1592.92	33.595
1596	33.872
1599.09	33.7406
1602.17	34.436
1605.25	33.923
1608.33	33.4846
1611.41	32.5978
1614.48	32.0253
1617.56	31.1945
1620.64	30.5257
1623.71	28.8521
1626.78	29.7276
1629.86	30.4281
1632.92	30.3605
1635.99	31.0235
1639.06	31.4484
1642.13	32.0805
1645.19	33.7027
1648.26	35.7161
1651.32	36.1005
1654.38	35.5844
1657.45	35.7079
1660.51	36.0804
1663.57	35.8119
1666.62	34.5788
1669.68	32.8441
1672.73	30.8907
1675.79	28.9926
1678.84	27.0363
1681.89	24.9014
1684.94	22.694
1687.99	19.7987
1691.04	16.8343
1694.09	14.0537
1697.14	12.067
1700.18	11.0674
1703.22	10.1115
1706.27	9.05035
1709.31	8.88558
1712.35	9.27209
1715.39	8.10525
1718.43	8.2191
1721.46	7.65938
1724.5	7.07587
1727.53	7.37589
1730.57	7.84926
1733.6	8.36768
1736.63	9.07679
1739.66	7.8214
1742.69	7.68744
1745.72	6.47477
1748.74	6.64617
1751.77	7.65852
1754.8	7.20722
1757.82	7.32869
1760.84	6.92735
1763.86	6.87244
1766.88	6.01146
1769.9	6.05403
1772.92	6.89797
1775.93	6.61435
1778.95	6.52752
1781.96	7.46345
1784.98	7.57329
1787.99	7.14497
1791	6.46293
1794.01	6.09659
1797.02	5.23439
1800.03	4.59633
1803.03	3.72974
1806.04	3.16346
1809.04	2.84811
1812.04	1.84727
1815.05	1.42913
1818.05	1.32946
1821.05	2.05895
1824.05	3.08372
1827.04	2.48622
1830.04	2.7979
1833.03	1.70608
1836.03	2.03645
1839.02	2.6638
1842.01	2.82415
1845	3.57479
1847.99	3.81374
1850.98	4.4606
1853.97	3.89234
1856.95	4.7338
1859.94	5.61585
1862.92	5.81754
1865.91	5.44366
1868.89	4.92316
1871.87	4.28623
1874.85	4.23102
1877.83	4.48586
1880.8	5.25703
1882.56	5.25615
1885.54	5.23336
1888.53	5.43264
1891.52	4.58298
1894.5	3.5264
1897.49	3.44726
1900.47	2.8978
1903.45	3.4281
1906.43	2.8506
1909.41	3.08208
1912.39	3.64396
1915.37	4.44084
1918.35	4.99282
1921.32	5.83326
1924.3	4.82653
1927.27	5.14632
1930.24	7.23794
1933.21	8.23028
1936.18	8.40134
1939.15	7.77351
1942.12	7.93016
1945.09	8.4938
1948.05	8.46345
1951.02	8.61936
1953.98	8.15021
1956.94	7.73001
1959.91	6.50275
1962.87	6.07335
1965.82	6.74649
1968.78	6.24856
1971.74	6.53074
1974.7	7.30376
1977.65	6.59394
1980.6	6.06679
1983.56	6.5055
1986.51	6.93313
1989.46	6.5542
1992.41	7.34819
1995.36	7.81205
1998.3	8.40965
2001.25	9.22021
2004.2	10.0282
2007.14	9.94109
2010.08	9.10732
2013.02	9.20073
2015.97	9.37837
2018.9	9.14514
2021.84	8.79495
2024.78	7.86683
2027.72	8.43583
2030.65	8.16807
2033.59	9.49375
2036.52	10.4318
2039.45	10.4655
2042.38	10.0211
2045.31	10.8976
2048.24	10.8644
2051.17	10.4136
2054.1	11.1877
2057.02	11.9102
2059.95	12.3451
2062.87	12.4843
2065.79	13.8642
2068.71	13.6944
2071.63	13.6691
2074.55	13.4807
2077.47	13.7065
2080.39	15.5144
2083.3	15.035
2086.22	15.2781
2089.13	15.8696
2092.05	15.9757
2094.96	16.5288
2097.87	17.735
2100.78	19.6017
2103.69	20.8161
2106.59	22.1567
2109.5	22.3554
2112.41	24.7622
2115.31	26.461
2118.21	28.0007
2121.12	30.0123
2124.02	31.5864
2126.92	33.7615
2129.82	35.5042
2132.71	37.2287
2135.61	39.7337
2138.51	40.7717
2141.4	41.0805
2144.29	42.3657
2147.19	44.0272
2150.08	45.2903
2152.97	46.8178
2155.86	48.1926
2158.75	49.2442
2161.64	50.001
2164.52	51.2404
2167.41	52.2807
2170.29	52.9445
2173.17	53.3311
2176.06	52.5145
2178.94	51.9615
2181.82	51.7136
2184.7	51.8211
2187.57	50.4349
2190.45	49.1278
2193.33	46.6615
2196.2	45.4874
2199.08	43.7826
2201.95	41.1681
2204.82	38.6783
2207.69	35.3549
2210.56	33.2404
2213.43	31.0076
2216.3	30.1775
2219.16	27.5486
2222.03	26.5892
2224.89	25.3636
2227.75	24.6663
2230.62	23.1829
2233.48	22.0257
2236.34	21.5339
2239.2	20.0856
2242.06	20.3888
2244.91	19.2357
2247.77	17.4246
2250.62	17.1452
2253.48	16.2879
2256.33	16.5469
2259.18	15.5268
2262.03	15.2593
2264.88	14.7832
2267.73	15.8955
2270.58	14.419
2273.43	14.6141
2276.27	15.0325
2279.12	14.9481
2281.96	14.8062
2284.8	15.283
2287.64	14.7856
2290.49	14.0593
2293.32	12.7051
2296.16	12.1417
2299	12.7284
2301.84	11.7669
2304.67	11.4413
2307.51	11.5345
2310.34	10.7229
2313.17	9.83999
2316	9.36756
2318.83	8.14232
2321.66	8.15417
2324.49	7.81914
2327.32	7.48446
2330.15	6.98868
2332.97	5.74922
2335.79	5.59997
2338.62	5.5243
2341.44	4.58966
2344.26	4.17267
2347.08	3.63431
2349.9	3.78667
2352.72	2.54018
2355.53	2.00122
2358.35	1.45363
2361.17	1.19495
2363.98	2.45655
2366.79	4.45657
2369.6	4.69918
2372.42	4.7165
2375.22	5.29463
2378.03	4.78229
2380.84	5.51642
2383.65	5.29371
2386.45	5.58938
2389.26	6.26619
2392.06	6.54391
2394.87	6.25344
2397.67	5.90983
2400.47	5.33044
2403.27	5.03352
2406.07	5.50522
2408.86	4.78772
2411.66	4.93596
2414.46	5.08994
2417.25	4.81338
2420.05	4.45995
2422.84	3.84206
2425.63	4.84145
2428.42	5.30217
2431.21	6.51834
2434	7.31665
2436.79	6.95506
2439.57	5.66164
2442.36	6.08956
2445.14	4.99548
2447.93	5.63596
2450.71	4.66438
2453.49	4.78171
2456.27	4.86484
2459.05	4.30929
2461.83	3.14039
2464.61	2.16454
2467.39	1.76084
2470.16	1.70736
2472.94	1.00243
2475.71	1.75005
2478.48	1.57364
2481.25	0.871401
2484.02	0.250347
2486.8	-0.00538125
2489.56	-0.184716
2492.33	0.181121
2495.1	-0.129773
2497.86	-0.690971
2500.63	-1.01192
2503.39	-0.723797
2506.16	-0.911287
2508.92	-1.05005
2511.68	-0.753129
2514.44	-0.312308
2517.2	-0.357741
2519.95	-0.0681091
2522.71	0.0710342
2525.47	0.505981
2528.22	0.544161
2530.98	1.05889
2533.73	2.70613
2536.48	2.75396
2539.23	3.73814
2541.98	4.38247
2544.73	4.524
2547.48	3.53412
2550.23	3.69622
2552.97	3.73822
2555.72	3.12137
2558.46	2.84895
2561.2	2.87636
2563.95	2.82324
2566.69	2.38887
2569.43	2.99891
2572.17	2.69767
2574.91	2.77663
2577.64	2.661
2580.38	2.50097
2583.11	3.13327
2585.85	3.40214
2588.58	3.50421
2591.31	3.21159
2594.04	3.15394
2596.78	2.91845
2599.51	2.79762
2602.23	2.71582
2604.96	2.41645
2607.69	2.15087
2610.41	2.28572
2613.14	2.49594
2615.86	3.23662
2618.58	3.84415
2621.3	3.82998
2624.03	4.28216
2626.75	5.28868
2629.46	5.32274
2632.18	5.32867
2634.9	4.96468
2637.61	5.40788
2640.33	4.76483
2643.04	5.793
2645.76	5.53532
2648.47	6.43157
2651.18	6.13514
2653.89	5.60324
2656.6	4.70901
2659.31	4.27321
2662.01	4.00345
2664.72	4.18991
2667.43	3.84683
2670.13	4.09928
2672.83	3.79142
2675.53	4.27169
2678.24	4.78232
2680.94	5.95637
2683.64	5.40723
2686.34	5.81495
2689.03	5.77703
2691.73	6.48569
2694.43	6.00786
2697.12	5.68285
2699.81	5.9436
2702.51	6.017
2705.2	5.60317
2707.89	5.27551
2710.58	5.63125
2713.27	4.89444
2715.96	5.27513
2718.64	5.47684
2721.33	4.9757
2724.01	5.15882
2726.7	5.90917
2729.38	5.44656
2732.06	5.56103
2734.75	5.9385
2737.43	6.7677
2740.11	6.68845
2742.78	7.04248
2745.46	7.83611
2748.14	7.72648
2750.81	7.09726
2753.49	7.64804
2756.16	7.40611
2758.84	6.46865
2761.51	6.14228
2764.18	6.07609
2766.85	5.28819
2769.52	3.83505
2772.19	2.58402
2774.85	1.5652
2777.52	1.28013
2780.18	0.980179
2782.85	1.0622
2785.51	0.372439
2788.17	0.129181
2790.84	-0.195885
2793.5	-0.673406
2796.16	-1.01438
2798.81	-0.733813
2801.47	-0.34425
2804.13	-0.000799468
2806.79	-0.21993
2809.44	0.37604
2812.09	1.04951
2814.75	2.04948
2817.4	2.96413
2820.05	4.44342
2822.7	6.63916
2825.35	9.28286
2828	10.9181
2830.65	13.1176
2833.29	15.7081
2835.94	17.7119
2838.58	20.8218
2841.23	24.9725
2843.87	28.5717
2846.51	31.6736
2849.15	35.229
2851.79	37.7464
2854.43	41.5754
2857.07	44.1803
2859.71	47.164
2862.34	49.5338
2864.98	52.1867
2867.61	54.457
2870.25	55.0886
2872.88	57.9038
2875.51	59.5458
2878.14	60.9679
2880.77	63.236
2883.4	64.4398
2886.03	67.3275
2888.65	68.9342
2891.28	71.3392
2893.91	72.8395
2896.53	75.6915
2899.15	78.2259
2901.78	80.6567
2904.4	84.2159
2907.02	87.4063
2909.64	92.2861
2912.26	95.3497
2914.87	99.5419
2917.49	103.649
2920.11	107.994
2922.72	110.933
2925.34	113.497
2927.95	114.5
2930.56	115.924
2933.17	116.607
2935.78	116.025
2938.39	115.478
2941	112.84
2943.61	111.282
2946.22	107.319
2948.82	103.893
2951.43	100.843
2954.03	95.9828
2956.64	90.8838
2959.24	85.6324
2961.84	80.0268
2964.44	74.9277
2967.04	70.7937
2969.64	66.6686
2972.24	62.841
2974.83	59.2267
2977.43	53.6677
2980.02	49.9295
2982.62	46.4974
2985.21	43.5929
2987.8	40.28
2990.4	36.9333
2992.99	33.2754
2995.57	30.5843
2998.16	26.965
3000.75	23.5956
3003.34	20.8245
3005.92	18.1757
3008.51	15.4547
3011.09	13.1986
3013.68	12.3764
3016.26	9.87444
3018.84	7.35591
3021.42	5.91462
3024	4.9911
3026.58	4.17571
3029.16	3.76413
3031.73	1.85565
3034.31	1.61522
3036.89	1.48708
3039.46	1.22752
3042.03	1.24782
3044.61	1.31104
3047.18	2.1925
3049.75	2.12032
3052.32	2.10105
3054.89	1.71146
3057.45	1.25029
3060.02	-0.307864
3062.59	-0.364758
3065.15	-0.287597
3067.72	-0.115932
3070.28	0.844308
3072.84	1.59653
3075.41	1.80677
3077.97	1.95157
3080.53	2.57598
3083.09	2.41794
3085.64	2.68884
3088.2	3.05391
3090.76	3.21131
3093.31	3.08387
3095.87	4.23609
3098.42	4.90279
3100.97	5.40163
3103.53	5.02809
3106.08	4.97085
3108.63	4.87031
3111.18	4.421
3113.73	4.37961
3116.27	3.43368
3118.82	2.93546
3121.37	2.38891
3123.91	2.6334
3126.45	3.38322
3129	4.04194
3131.54	4.04395
3134.08	4.33622
3136.62	4.37946
3139.16	3.95976
3141.7	3.92854
3144.24	4.14649
3146.78	5.04999
3149.31	4.73032