File: data/Raman/poly_smoothed/Mb_40_24_08_1x_45s_532 nm_x100_100%_600 gr_mm_01.txt
#Acq. time (s)=	45
#Accumulations=	2
#Range (cm-¹)=	200...3150
#Windows=	2
#Auto scanning=	Off
#Autofocus=	Off
#Macrospot=	Off
#AutoExposure=	Off
#Spike filter=	Multiple accum.
#Delay time (s)=	0
#Binning=	1
#Readout mode=	Signal
#DeNoise=	Off
#ICS correction=	On
#Dark correction=	Off
#Inst. Process=	Off
#Detector Gain=	Best Dynamic Range
#Detector ADC=	20 kHz
#Detector temperature (°C)=	-70.08
#Instrument=	LabRAM HR Evol
#Detector=	Synapse
#Objective=	x100
#Grating=	600 gr/mm
#ND Filter=	100%
#Laser (nm)=	532
#Hole=	100.021
#Range=	Auto
#Laser Pol.=	No
#Raman. Pol.=	No
#Laser Pol. (°)=	-0.0007625
#Raman Pol. (°)=	89.9995
#Collection=	Microscope
#StageXY=	Marzhauser
#StageZ=	Marzhauser
#X (µm)=	-2513.1
#Y (µm)=	-39.8
#Z (µm)=	-10.2
#Full time(mm:ss)=	3:18
#Project=
#Sample=
#Site=
#Title=	Mb_40_24_08_2x_45s_532 nm_x100_100%_600 gr_mm
#Remark=
#Date=	14.07.2022 11:18
#Acquired=	14.07.2022 11:18:07
#Base:Fit=	10.08.2022 10:47:00
#Base:Sub=	10.08.2022 10:47:12
#Filter:Polynom=	16.08.2022 10:11:48
#AxisType[0]=Intens
#AxisUnit[0]=Cnt
#AxisType[1]=Spectr
#AxisUnit[1]=1/cm
200.554	13.3266
204.183	17.3871
207.813	17.0434
211.439	16.4907
215.065	16.528
218.688	16.2777
222.312	16.0271
225.933	15.7101
229.552	14.1884
233.171	14.2547
236.787	12.8332
240.402	11.6256
244.015	10.9836
247.627	8.85779
251.24	5.7067
254.849	4.81289
258.457	5.66553
262.063	6.92083
265.668	7.50892
269.271	6.3491
272.873	5.08537
276.474	3.56075
280.073	2.60859
283.671	1.05213
287.268	0.0469771
290.863	0.0306305
294.456	1.45015
298.049	2.6263
301.637	4.01761
305.227	5.34958
308.815	6.3211
312.402	9.12937
315.987	10.1483
319.569	10.7024
323.151	10.6191
326.733	11.0352
330.31	11.5821
333.889	13.5741
337.464	12.5847
341.039	12.8815
344.611	11.8189
348.184	12.0042
351.754	9.61868
355.324	7.15286
358.89	7.16579
362.455	6.53537
366.021	5.37944
369.584	5.13365
373.145	3.31248
376.707	3.77536
380.265	3.69537
383.822	3.89711
387.378	5.02378
390.934	5.47233
394.487	6.28094
398.038	6.73862
401.588	6.73658
405.137	5.74847
408.685	5.88903
412.23	6.83871
415.775	7.77665
419.318	7.97843
422.86	6.26652
426.401	7.75215
429.94	7.2561
433.478	8.36933
437.012	7.49202
440.547	9.00378
444.081	11.1701
447.613	12.8143
451.142	13.6635
454.672	13.8941
458.2	13.0748
461.725	13.7898
465.251	12.9016
468.775	14.3483
472.296	17.5054
475.817	19.121
479.335	19.3348
482.854	19.7488
486.37	21.0385
489.886	21.9054
493.398	24.1587
496.91	26.4774
500.422	26.9165
503.93	29.056
507.438	29.6045
510.946	30.977
514.45	32.7933
517.954	32.5822
521.456	33.637
524.956	34.1368
528.456	34.8272
531.956	33.3103
535.452	31.8486
538.947	30.1029
542.441	28.6241
545.934	26.9466
549.425	24.615
552.915	23.3065
556.403	21.6429
559.889	20.2826
563.375	16.6801
566.859	12.4763
570.342	9.08298
573.824	8.221
577.303	6.94412
580.782	5.41823
584.26	5.3791
587.734	5.05807
591.21	5.78164
594.684	5.98321
598.154	6.13899
601.626	7.04801
605.094	8.03348
608.562	10.7481
612.027	12.4248
615.493	14.5766
618.956	15.5589
622.419	17.5684
625.879	19.7779
629.338	20.3582
632.797	20.5594
636.254	20.3433
639.708	19.361
643.162	20.4833
646.614	18.8859
650.067	17.808
653.516	16.2988
656.964	14.169
660.411	14.7838
663.857	14.0504
667.301	13.3574
670.744	12.6053
674.186	14.364
677.626	16.458
681.065	16.5607
684.503	17.4652
687.939	18.2497
691.372	18.3858
694.806	18.6474
698.239	18.0053
701.67	19.6942
705.098	19.8178
708.526	21.008
711.954	22.1395
715.378	24.2346
718.802	25.9459
722.226	25.9642
725.646	26.3507
729.067	27.0217
732.484	27.9097
735.902	29.6211
739.317	29.4323
742.731	31.4685
746.145	34.0036
749.556	37.6337
752.966	41.0475
756.377	46.5676
759.784	50.0472
763.19	54.0553
766.594	56.1134
770	58.0266
773.402	59.4052
776.803	58.6211
780.202	60.1408
783.6	61.5006
786.997	62.0828
790.393	62.3246
793.787	63.4016
797.18	62.9389
800.572	63.682
803.963	61.3118
807.35	60.7444
810.738	61.5038
814.125	62.1154
817.51	63.3274
820.894	62.8497
824.275	64.5507
827.657	64.5178
831.037	67.0447
834.414	68.3172
837.792	68.4631
841.167	72.5199
844.542	72.6298
847.914	73.3137
851.287	72.8792
854.656	72.7342
858.026	70.2591
861.393	66.5757
864.761	66.5311
868.125	64.0875
871.489	62.5329
874.85	61.0536
878.213	59.4361
881.572	56.7722
884.931	55.4989
888.287	54.0701
891.643	53.0672
894.997	50.4398
898.352	50.114
901.704	48.6685
905.055	47.1904
908.404	47.619
911.75	46.8414
915.097	46.9703
918.443	46.9794
921.787	47.0876
925.13	46.3118
928.472	44.9284
931.813	44.4671
935.15	44.1821
938.488	42.8955
941.825	40.472
945.158	38.3166
948.493	36.8561
951.824	35.2151
955.156	33.5324
958.486	31.287
961.814	29.0852
965.142	30.4467
968.467	31.7881
971.79	34.7104
975.115	36.6669
978.436	40.1374
981.756	42.3132
985.077	42.7249
988.394	44.7831
991.71	45.2365
995.025	46.2639
998.341	46.6716
1001.65	47.2388
1004.97	48.0715
1008.28	48.4326
1011.58	51.352
1014.89	54.958
1018.2	59.3612
1021.5	61.2838
1024.81	62.7184
1028.11	65.3798
1031.41	68.139
1034.71	68.1662
1038.01	69.1933
1041.31	70.5621
1044.6	72.5963
1047.9	73.8977
1051.19	75.7974
1054.48	73.4445
1057.77	72.1995
1061.06	69.8571
1064.35	66.9476
1067.64	62.1059
1070.93	57.8579
1074.21	53.561
1077.49	49.6353
1080.78	44.7911
1084.06	43.705
1087.34	42.0556
1090.61	43.1043
1093.89	43.8353
1097.17	43.9711
1100.44	45.2554
1103.71	45.316
1106.99	44.4503
1110.26	42.4571
1113.52	40.0216
1116.79	39.2951
1120.06	36.7515
1123.32	33.9883
1126.59	32.4914
1129.85	29.7394
1133.11	27.1113
1136.37	23.7764
1139.63	21.1265
1142.89	18.0861
1146.15	14.2655
1149.4	11.2121
1152.66	8.49808
1155.91	3.45226
1159.16	2.28337
1162.41	2.45227
1165.66	2.49037
1168.91	1.06976
1172.16	1.98416
1175.4	2.41505
1178.65	3.36093
1181.89	5.47643
1185.13	7.27662
1188.37	9.17526
1191.61	10.4639
1194.85	13.2368
1198.08	16.4174
1201.32	18.9576
1204.55	20.8578
1207.79	24.362
1211.02	27.89
1214.25	31.8849
1217.48	36.3662
1220.71	41.5367
1223.93	44.818
1227.16	48.1425
1230.38	51.6816
1233.6	56.0591
1236.83	58.7543
1240.05	64.8978
1243.26	68.0697
1246.48	70.5476
1249.7	75.5391
1252.92	79.6463
1256.13	82.5246
1259.34	86.6339
1262.55	91.5858
1265.76	94.3907
1268.97	97.8755
1272.18	100.546
1275.39	105.65
1278.59	107.833
1281.8	109.822
1285	112.508
1288.2	115.637
1291.4	116.97
1294.6	119.232
1297.8	120.548
1301	120.24
1304.19	121.042
1307.39	122.326
1310.58	121.293
1313.77	121.198
1316.96	120.07
1320.15	118.679
1323.34	115.045
1326.53	112.757
1329.72	109.793
1332.9	106.697
1336.08	105.456
1339.27	103.285
1342.45	100.963
1345.63	97.0306
1348.8	95.6245
1351.98	92.3951
1355.16	90.4527
1358.33	86.4814
1361.51	84.5341
1364.68	81.8414
1367.85	80.0704
1371.02	78.5251
1374.19	78.7111
1377.36	79.9532
1380.52	81.6998
1383.69	84.4427
1386.85	86.4909
1390.02	87.3138
1393.18	89.6217
1396.34	90.7901
1399.5	92.1179
1402.65	93.789
1405.81	97.2811
1408.97	102.166
1412.12	108.06
1415.27	113.522
1418.43	119.974
1421.58	128.545
1424.73	138.967
1427.87	149.292
1431.02	158.891
1434.17	165.918
1437.31	172.683
1440.46	179.188
1443.6	182.555
1446.74	184.503
1449.88	183.413
1453.02	181.911
1456.16	178.155
1459.29	170.161
1462.43	161.281
1465.56	152.347
1468.69	140.992
1471.83	127.792
1474.95	114.096
1478.08	100.294
1481.21	86.5769
1484.34	73.7085
1487.47	63.5448
1490.59	54.7439
1493.71	47.9666
1496.84	41.8859
1499.96	40.5142
1503.07	37.6841
1506.19	34.3586
1509.31	31.231
1512.43	29.7189
1515.54	28.8111
1518.65	27.7224
1521.77	26.6814
1524.88	26.0611
1527.99	27.5403
1531.1	28.4724
1534.21	28.9396
1537.31	31.1278
1540.42	34.3083
1543.52	36.1877
1546.63	37.9787
1549.73	40.6958
1552.83	42.5663
1555.93	45.8607
1559.03	50.4561
1562.12	55.3633
1565.22	59.3763
1568.31	65.4324
1571.41	70.9985
1574.5	77.5027
1577.59	83.2477
1580.68	89.9485
1583.77	94.2715
1586.86	99.1593
1589.95	103.398
1593.03	106.768
1596.11	110.326
1599.2	112.004
1602.28	111.632
1605.36	111.895
1608.44	110.808
1611.52	110.264
1614.6	110.803
1617.67	110.981
1620.75	110.832
1623.82	112.813
1626.89	113.697
1629.96	114.952
1633.04	118.84
1636.11	121.717
1639.17	125.385
1642.24	129.124
1645.31	133.793
1648.37	137.484
1651.43	139.814
1654.5	141.629
1657.56	142.911
1660.62	140.165
1663.67	138.386
1666.73	134.583
1669.79	129.753
1672.84	124.506
1675.9	115.823
1678.95	107.075
1682	99.2944
1685.05	91.5105
1688.1	83.1119
1691.15	75.1374
1694.2	67.5999
1697.25	60.3338
1700.29	54.5079
1703.33	48.3382
1706.38	43.9225
1709.42	39.7083
1712.46	35.2146
1715.5	32.1543
1718.54	29.0732
1721.57	27.8644
1724.61	25.8756
1727.64	25.9515
1730.68	24.7493
1733.71	23.9238
1736.74	22.56
1739.77	21.3634
1742.8	20.8563
1745.83	20.448
1748.85	18.8285
1751.88	16.5259
1754.91	15.9554
1757.93	15.0251
1760.95	14.0449
1763.97	11.4789
1766.99	10.7676
1770.01	7.86408
1773.03	7.22593
1776.04	7.87751
1779.06	6.05852
1782.07	4.38303
1785.09	3.08735
1788.1	2.86905
1791.11	2.72761
1794.12	2.68533
1797.13	2.57095
1800.13	2.73732
1803.14	1.80902
1806.15	0.891734
1809.15	1.25165
1812.15	2.00541
1815.16	2.95611
1818.15	3.20946
1821.16	2.93947
1824.15	3.45681
1827.15	4.26903
1830.15	4.257
1833.14	5.71319
1836.14	5.96817
1839.13	6.0598
1842.12	6.56006
1845.11	7.1732
1848.1	8.37212
1851.09	7.36975
1854.08	6.0798
1857.06	4.87438
1860.05	3.98396
1863.03	2.96397
1866.01	1.41914
1869	0.895261
1871.98	1.16943
1874.96	1.34323
1877.93	0.771796
1880.91	1.6226
1882.47	2.09675
1885.46	3.18503
1888.44	2.51522
1891.43	3.06058
1894.42	3.25439
1897.4	3.47342
1900.39	3.72304
1903.37	4.75184
1906.35	6.79764
1909.33	6.52151
1912.31	6.55816
1915.29	6.87251
1918.26	6.89591
1921.24	5.73875
1924.21	4.70406
1927.19	3.37547
1930.16	4.85343
1933.13	4.83365
1936.1	4.38258
1939.07	3.5974
1942.04	3.54181
1945	3.7259
1947.97	3.29678
1950.93	3.69876
1953.9	3.75014
1956.86	3.50406
1959.82	2.28084
1962.78	0.999882
1965.74	1.57444
1968.7	0.0555258
1971.65	0.479012
1974.61	0.989641
1977.57	1.53257
1980.52	1.60165
1983.47	1.07365
1986.42	0.853282
1989.37	0.724441
1992.32	1.18018
1995.27	1.42625
1998.22	2.33397
2001.17	3.79184
2004.11	4.8956
2007.05	4.89455
2010	6.48341
2012.94	6.7241
2015.88	8.311
2018.82	9.99904
2021.76	10.5443
2024.7	11.2861
2027.63	11.5737
2030.57	12.0552
2033.5	12.2126
2036.44	12.4491
2039.37	13.6605
2042.3	13.3311
2045.23	13.152
2048.16	13.4118
2051.08	13.3838
2054.01	13.6823
2056.94	13.8194
2059.86	14.8988
2062.79	14.6004
2065.71	15.1173
2068.63	15.072
2071.55	15.6258
2074.47	15.6181
2077.39	17.524
2080.31	18.7474
2083.22	19.1915
2086.13	20.5007
2089.05	23.3242
2091.96	25.4265
2094.87	27.3354
2097.78	30.7794
2100.69	33.862
2103.6	37.5226
2106.51	40.736
2109.42	44.102
2112.32	47.8323
2115.23	53.6708
2118.13	57.4267
2121.03	62.8399
2123.93	69.0192
2126.83	75.4065
2129.73	80.1257
2132.63	85.2679
2135.53	90.5052
2138.42	94.4359
2141.32	99.3658
2144.21	104.248
2147.1	109.084
2150	113.504
2152.89	117.7
2155.78	122.158
2158.66	126.593
2161.55	131.279
2164.44	132.91
2167.32	135.498
2170.21	136.592
2173.09	136.557
2175.97	136.175
2178.85	134.743
2181.73	132.401
2184.61	129.45
2187.49	126.873
2190.37	123.181
2193.24	119.289
2196.12	115.33
2198.99	110.646
2201.87	104.977
2204.74	98.1616
2207.61	92.4333
2210.48	86.9407
2213.35	82.5323
2216.21	79.0671
2219.08	75.6301
2221.95	72.7814
2224.81	69.6416
2227.67	65.0748
2230.54	61.6113
2233.4	57.6358
2236.26	55.5044
2239.11	51.1092
2241.97	47.5215
2244.83	44.7776
2247.69	42.5124
2250.54	39.363
2253.4	36.54
2256.25	33.9181
2259.1	31.3912
2261.95	29.3581
2264.8	26.6726
2267.65	24.4692
2270.5	21.189
2273.34	19.278
2276.19	18.592
2279.03	16.9762
2281.88	17.7006
2284.72	17.2052
2287.56	16.7897
2290.4	16.0441
2293.24	13.8082
2296.08	12.2472
2298.92	12.9431
2301.76	14.3232
2304.59	16.6514
2307.43	15.9763
2310.26	15.6563
2313.09	15.7797
2315.92	16.5363
2318.75	14.8341
2321.58	13.2474
2324.41	12.6794
2327.24	11.4263
2330.06	10.1748
2332.89	9.48947
2335.71	8.11174
2338.54	8.10018
2341.36	6.43899
2344.18	5.75836
2347	5.06942
2349.82	2.90889
2352.64	2.94906
2355.45	1.8285
2358.27	0.806176
2361.08	-0.498387
2363.9	0.394809
2366.71	3.17929
2369.52	3.56088
2372.33	4.38419
2375.14	4.41048
2377.95	3.81068
2380.76	5.42972
2383.57	5.89277
2386.37	5.41904
2389.18	4.76802
2391.98	6.32012
2394.79	6.42413
2397.59	6.38829
2400.39	6.53199
2403.19	7.06989
2405.99	7.6935
2408.78	7.69948
2411.58	8.00015
2414.38	8.19368
2417.17	7.83741
2419.97	6.60888
2422.76	6.88976
2425.55	6.13187
2428.34	6.14478
2431.13	5.84517
2433.92	6.85488
2436.71	6.74492
2439.49	7.58378
2442.28	7.87398
2445.06	8.09609
2447.85	8.13551
2450.63	7.48375
2453.41	7.9615
2456.19	7.64393
2458.97	7.04293
2461.75	6.84914
2464.53	5.39056
2467.31	5.16944
2470.08	4.81011
2472.86	4.43008
2475.63	4.30088
2478.4	3.8204
2481.17	2.50793
2483.94	1.74095
2486.72	2.24005
2489.48	1.46236
2492.25	1.77288
2495.02	1.83979
2497.79	1.52139
2500.55	2.07011
2503.31	2.06725
2506.08	1.8669
2508.84	0.892543
2511.6	-0.160521
2514.36	0.37087
2517.12	1.25214
2519.88	0.525017
2522.63	1.95401
2525.39	0.938971
2528.14	1.42237
2530.9	1.05639
2533.65	2.59394
2536.4	3.75075
2539.15	4.86058
2541.9	5.01296
2544.65	5.31478
2547.4	4.97747
2550.15	5.52264
2552.89	6.55911
2555.64	6.83971
2558.38	6.65448
2561.12	6.49447
2563.87	6.0658
2566.61	5.42657
2569.35	5.06313
2572.09	4.99952
2574.83	4.99858
2577.56	4.62785
2580.3	4.73575
2583.04	5.49812
2585.77	4.89271
2588.5	5.3836
2591.23	5.69773
2593.97	6.14271
2596.7	6.77371
2599.43	7.5622
2602.15	7.83782
2604.88	7.65447
2607.61	7.42431
2610.33	6.9602
2613.06	6.07235
2615.78	5.11439
2618.51	5.38356
2621.23	4.8296
2623.95	4.08947
2626.67	4.26259
2629.39	3.98916
2632.1	4.32743
2634.82	3.9837
2637.54	4.66066
2640.25	3.66004
2642.97	4.80343
2645.68	4.62522
2648.39	4.99248
2651.1	3.95117
2653.81	3.78181
2656.52	4.12799
2659.23	4.81669
2661.94	5.63825
2664.64	6.45952
2667.35	6.47601
2670.05	6.98821
2672.76	7.38641
2675.46	8.55176
2678.16	9.22621
2680.86	9.80962
2683.56	9.74563
2686.26	10.5713
2688.96	11.1702
2691.65	11.36
2694.35	12.3861
2697.04	13.1233
2699.74	14.3439
2702.43	14.391
2705.12	15.651
2707.81	15.7441
2710.5	15.5237
2713.19	16.1591
2715.88	16.1856
2718.57	16.8217
2721.25	17.749
2723.94	18.2309
2726.62	19.1218
2729.3	19.3335
2731.99	19.2348
2734.67	17.965
2737.35	17.8606
2740.03	17.4492
2742.71	17.6084
2745.38	17.0736
2748.06	15.9318
2750.74	15.7074
2753.41	14.6065
2756.09	14.3302
2758.76	12.6757
2761.43	11.4347
2764.1	9.49408
2766.77	7.81169
2769.44	6.62497
2772.11	5.23573
2774.77	4.34478
2777.44	3.88515
2780.11	3.27229
2782.77	2.90934
2785.43	2.81794
2788.1	1.81282
2790.76	1.31234
2793.42	0.87517
2796.08	0.512213
2798.74	0.352877
2801.4	0.731166
2804.05	1.56589
2806.71	2.14036
2809.36	2.63273
2812.02	3.06976
2814.67	3.73371
2817.32	5.46874
2819.97	8.39701
2822.62	12.5869
2825.27	17.0844
2827.92	23.9162
2830.57	33.1424
2833.22	42.9529
2835.86	54.0271
2838.51	65.9414
2841.15	78.6841
2843.79	92.3988
2846.43	107.24
2849.08	123.412
2851.72	140.035
2854.36	156.943
2856.99	174.469
2859.63	190.549
2862.27	207.683
2864.9	223.134
2867.54	236.398
2870.17	248.896
2872.8	260.09
2875.43	270.708
2878.07	281.891
2880.7	292.109
2883.32	304.736
2885.95	316.48
2888.58	329.282
2891.21	341.978
2893.83	356.742
2896.46	370.967
2899.08	386.079
2901.7	401.733
2904.32	420.756
2906.94	441.536
2909.56	463.444
2912.18	487.036
2914.8	509.786
2917.42	530.515
2920.03	549.791
2922.65	566.776
2925.26	577.775
2927.88	586.162
2930.49	590.853
2933.1	589.99
2935.71	584.827
2938.32	577.878
2940.93	565.296
2943.54	548.819
2946.14	532.169
2948.75	511.141
2951.35	489.144
2953.96	464.636
2956.56	440.701
2959.16	415.838
2961.77	391.636
2964.37	370.481
2966.96	349.674
2969.56	331.675
2972.16	313.616
2974.76	297.397
2977.35	279.878
2979.95	261.341
2982.54	243.684
2985.14	226.758
2987.73	208.167
2990.32	189.7
2992.91	171.806
2995.5	155.114
2998.09	137.812
3000.68	121.83
3003.26	106.028
3005.85	90.7077
3008.43	78.5328
3011.02	66.0064
3013.6	55.6486
3016.19	46.669
3018.77	39.4996
3021.35	32.5208
3023.93	27.2667
3026.5	23.0349
3029.08	20.2235
3031.66	17.0075
3034.24	15.8539
3036.81	14.9073
3039.39	14.1359
3041.96	12.9814
3044.53	12.205
3047.1	12.6456
3049.67	13.1775
3052.24	13.598
3054.81	13.2879
3057.38	13.6947
3059.95	14.6321
3062.52	14.2387
3065.08	13.7752
3067.65	13.0812
3070.21	12.8426
3072.77	12.2699
3075.33	10.6263
3077.89	10.0428
3080.45	8.17348
3083.01	6.92469
3085.57	4.50543
3088.13	3.16541
3090.68	1.93582
3093.24	0.8395
3095.79	0.121427
3098.35	-0.227421
3100.9	0.483955
3103.45	0.856488
3106	0.672584
3108.55	1.3632
3111.1	3.45343
3113.65	5.26626
3116.2	7.53622
3118.75	9.26643
3121.29	10.842
3123.84	12.5889
3126.38	13.9134
3128.92	16.9912
3131.47	19.4849
3134.01	21.393
3136.55	23.0197
3139.09	25.5729
3141.63	26.7113
3144.17	28.1304
3146.7	29.4951
3149.24	32.1778