File: data/Raman/poly_smoothed/Mb_40_y_05_1x_45s_532 nm_x100_100%_600 gr_mm_01.txt
#Acq. time (s)=	45
#Accumulations=	2
#Range (cm-¹)=	200...3150
#Windows=	2
#Auto scanning=	Off
#Autofocus=	Off
#Macrospot=	Off
#AutoExposure=	Off
#Spike filter=	Multiple accum.
#Delay time (s)=	0
#Binning=	1
#Readout mode=	Signal
#DeNoise=	Off
#ICS correction=	On
#Dark correction=	Off
#Inst. Process=	Off
#Detector Gain=	Best Dynamic Range
#Detector ADC=	20 kHz
#Detector temperature (°C)=	-69.85
#Instrument=	LabRAM HR Evol
#Detector=	Synapse
#Objective=	x100
#Grating=	600 gr/mm
#ND Filter=	100%
#Laser (nm)=	532
#Hole=	100.021
#Range=	Auto
#Laser Pol.=	No
#Raman. Pol.=	No
#Laser Pol. (°)=	-0.0007625
#Raman Pol. (°)=	89.9995
#Collection=	Microscope
#StageXY=	Marzhauser
#StageZ=	Marzhauser
#X (µm)=	-1258.7
#Y (µm)=	2696.8
#Z (µm)=	586.8
#Full time(mm:ss)=	3:18
#Project=
#Sample=
#Site=
#Title=	Mb_40_y_05_2x_45s_532 nm_x100_100%_600 gr_mm
#Remark=
#Date=	18.07.2022 15:28
#Acquired=	18.07.2022 15:28:24
#Base:Fit=	10.08.2022 10:52:48
#Base:Sub=	10.08.2022 10:52:53
#Filter:Polynom=	16.08.2022 10:09:04
#AxisType[0]=Intens
#AxisUnit[0]=Cnt
#AxisType[1]=Spectr
#AxisUnit[1]=1/cm
200.419	68.1826
204.048	52.532
207.678	42.4005
211.304	34.1368
214.928	28.4763
218.554	23.2847
222.176	18.9715
225.798	15.5553
229.417	13.0539
233.035	11.2893
236.653	9.92583
240.268	8.64662
243.881	8.92486
247.493	8.6004
251.103	8.76857
254.715	8.89457
258.322	10.9834
261.929	12.0045
265.534	15.6239
269.137	16.9144
272.739	15.9715
276.34	14.9503
279.939	14.6671
283.537	13.4623
287.134	12.0214
290.729	13.9882
294.323	13.8223
297.913	12.68
301.504	13.3642
305.093	14.0271
308.682	11.6398
312.268	11.8407
315.852	11.397
319.436	11.622
323.018	11.1784
326.597	11.3632
330.177	12.6503
333.753	12.6922
337.331	10.9366
340.906	10.7627
344.478	11.2278
348.051	11.4002
351.621	11.5711
355.189	10.6803
358.757	9.55428
362.323	7.79329
365.889	6.05769
369.451	5.45498
373.012	1.44868
376.574	-0.884571
380.133	0.892736
383.69	4.55259
387.245	6.71346
390.8	10.1997
394.353	12.4803
397.906	14.8612
401.456	17.6316
405.005	19.0686
408.552	21.3947
412.099	24.0093
415.643	25.3337
419.187	25.8794
422.728	25.3997
426.269	26.2156
429.806	26.3427
433.344	25.5552
436.881	26.2461
440.416	24.9902
443.949	23.3272
447.48	20.764
451.011	17.8727
454.541	14.1901
458.069	11.756
461.594	9.97211
465.119	13.7154
468.642	15.6444
472.165	14.6567
475.684	15.5041
479.204	17.2418
482.721	16.6477
486.239	17.2009
489.753	18.3103
493.268	19.6339
496.779	20.4632
500.289	21.3088
503.8	22.742
507.307	22.668
510.813	23.0588
514.32	25.4645
517.823	26.7996
521.325	27.6154
524.826	29.1546
528.325	29.36
531.823	29.4084
535.32	29.6202
538.815	29.1462
542.309	28.0321
545.802	26.5821
549.293	25.698
552.783	24.6313
556.271	23.6724
559.759	22.6377
563.245	22.0555
566.729	21.0305
570.213	20.4855
573.693	19.7548
577.173	18.3507
580.652	16.2067
584.13	14.6504
587.605	13.8676
591.08	10.6165
594.552	8.91609
598.025	9.17536
601.496	8.96177
604.964	7.49057
608.433	6.88603
611.898	5.92937
615.364	5.57592
618.827	4.90694
622.288	5.27086
625.75	5.08518
629.209	4.35063
632.667	6.30072
636.125	6.8958
639.58	9.10992
643.033	9.69004
646.485	11.81
649.936	14.6985
653.388	15.6814
656.836	17.9663
660.283	18.0792
663.728	20.0575
667.173	22.3358
670.616	23.614
674.057	24.2179
677.498	26.6507
680.937	29.4844
684.375	31.8314
687.809	33.1744
691.244	33.626
694.678	35.234
698.111	38.3201
701.54	40.5342
704.97	42.2855
708.398	44.2868
711.826	46.5673
715.25	48.5493
718.675	50.8377
722.096	52.6531
725.518	53.8875
728.937	52.916
732.357	52.2956
735.773	52.2424
739.19	53.0147
742.604	54.3237
746.018	55.5343
749.429	58.9096
752.839	59.85
756.248	62.0576
759.657	63.9246
763.063	63.7524
766.468	66.2813
769.871	68.1773
773.273	70.5124
776.676	75.0042
780.075	78.0294
783.474	79.9896
786.871	83.4977
790.266	86.8133
793.661	89.4761
797.054	90.1963
800.446	91.1348
803.834	90.3131
807.224	88.4991
810.612	86.8136
813.998	84.5489
817.384	84.3495
820.766	84.3782
824.149	84.7541
827.531	83.0915
830.909	80.7485
834.288	78.2627
837.666	75.5381
841.041	73.0479
844.416	69.4946
847.788	68.5437
851.161	66.9875
854.53	65.3037
857.901	64.6281
861.268	63.4855
864.633	62.0716
868	60.7383
871.363	60.7216
874.725	59.9456
878.088	58.4109
881.447	56.8089
884.805	55.97
888.162	54.7461
891.518	54.4177
894.872	53.8112
898.225	54.6464
901.577	55.0303
904.928	54.0531
908.277	53.1963
911.625	53.5346
914.972	51.7435
918.318	51.2465
921.662	50.4459
925.005	49.8599
928.347	49.2082
931.686	47.8804
935.025	48.3053
938.363	49.7159
941.698	46.7832
945.034	44.7245
948.368	42.6899
951.699	41.4429
955.031	41.9781
958.36	40.0067
961.689	38.1495
965.016	37.4858
968.343	37.9527
971.666	38.2682
974.991	39.0722
978.312	38.9929
981.632	40.3836
984.953	39.6724
988.27	39.6697
991.587	40.4716
994.902	38.2513
998.216	34.2724
1001.53	29.0534
1004.84	28.5449
1008.15	32.9908
1011.46	43.788
1014.77	59.4956
1018.07	76.7943
1021.38	90.593
1024.68	104.743
1027.99	118.407
1031.29	131.271
1034.59	140.139
1037.89	146.581
1041.18	150.011
1044.48	153.245
1047.77	151.059
1051.07	147.917
1054.36	142.591
1057.65	133.902
1060.94	122.044
1064.23	109.115
1067.52	93.8832
1070.8	77.5767
1074.09	59.3392
1077.37	42.2828
1080.65	25.9827
1083.93	17.7147
1087.21	14.0032
1090.49	16.807
1093.77	19.9884
1097.04	21.7458
1100.32	24.4291
1103.59	26.0061
1106.86	27.1763
1110.13	28.445
1113.4	28.1572
1116.67	28.9945
1119.94	29.6329
1123.2	28.2671
1126.47	26.2892
1129.73	25.969
1132.99	25.9052
1136.25	24.4253
1139.51	23.8261
1142.77	22.3826
1146.03	22.4505
1149.28	21.3053
1152.54	19.4273
1155.79	16.8249
1159.04	14.4484
1162.29	11.3778
1165.54	9.0978
1168.79	7.98308
1172.04	5.48646
1175.28	4.56666
1178.53	5.06081
1181.77	5.00059
1185.01	4.46819
1188.25	4.46965
1191.49	4.78916
1194.73	5.9379
1197.96	8.54866
1201.2	10.3614
1204.43	12.2908
1207.66	15.0111
1210.9	17.9927
1214.13	22.6441
1217.36	28.134
1220.58	32.38
1223.81	34.9973
1227.04	38.9331
1230.26	42.6172
1233.48	45.531
1236.71	48.1755
1239.93	50.4134
1243.14	53.1706
1246.36	56.0941
1249.58	58.5414
1252.8	58.6457
1256.01	60.4167
1259.22	62.073
1262.43	62.4021
1265.64	63.4745
1268.85	65.3554
1272.06	67.9681
1275.27	69.904
1278.48	72.198
1281.68	73.0502
1284.88	74.9403
1288.08	76.4629
1291.28	79.3554
1294.48	81.2974
1297.68	81.081
1300.88	81.637
1304.07	84.0808
1307.27	85.3305
1310.46	85.8014
1313.65	84.6285
1316.85	83.5293
1320.03	83.0165
1323.22	83.0555
1326.41	82.0367
1329.6	79.3825
1332.78	78.7044
1335.96	77.3795
1339.15	74.034
1342.33	72.2546
1345.51	69.525
1348.69	66.4512
1351.86	63.0992
1355.04	60.7948
1358.21	58.973
1361.39	55.8797
1364.56	54.1725
1367.73	50.9583
1370.9	49.9558
1374.07	48.4815
1377.24	47.9494
1380.41	46.7686
1383.57	46.0372
1386.73	45.2334
1389.9	45.2081
1393.06	45.8999
1396.22	47.4692
1399.38	49.1247
1402.54	52.276
1405.69	55.6806
1408.85	58.8388
1412	62.0928
1415.16	63.405
1418.31	65.8417
1421.46	64.7311
1424.61	71.3306
1427.76	77.0073
1430.9	84.2069
1434.05	89.5126
1437.2	95.0878
1440.34	97.8822
1443.48	100.109
1446.62	100.177
1449.76	100.204
1452.9	98.3249
1456.04	95.5225
1459.17	92.8027
1462.31	90.2911
1465.44	85.6108
1468.58	80.588
1471.71	76.222
1474.84	71.2752
1477.97	65.817
1481.1	59.936
1484.22	56.0982
1487.35	50.5464
1490.47	44.9681
1493.59	40.2087
1496.72	36.2187
1499.84	34.9191
1502.96	35.3727
1506.08	36.9016
1509.19	35.4967
1512.31	34.074
1515.42	33.294
1518.54	31.3297
1521.65	31.2042
1524.76	30.573
1527.87	31.2842
1530.98	31.7221
1534.09	31.6022
1537.2	32.028
1540.3	33.7497
1543.41	34.9563
1546.51	35.7167
1549.61	37.7508
1552.71	39.3544
1555.81	40.7078
1558.91	43.421
1562.01	45.9931
1565.1	46.4996
1568.2	48.1331
1571.29	50.2543
1574.38	52.3085
1577.48	55.0302
1580.57	57.7865
1583.65	60.3666
1586.74	61.1016
1589.83	62.9081
1592.92	64.7637
1596	65.0553
1599.08	65.5464
1602.16	65.2864
1605.24	64.3008
1608.32	63.3784
1611.4	61.7053
1614.48	61.2145
1617.56	61.3062
1620.63	61.3388
1623.71	62.2477
1626.78	62.3522
1629.85	63.0641
1632.92	64.2984
1635.99	65.6519
1639.06	67.4409
1642.12	69.5984
1645.19	72.084
1648.25	74.3438
1651.32	75.6911
1654.38	77.3414
1657.44	78.8412
1660.5	79.5385
1663.56	79.2696
1666.62	76.6661
1669.67	74.0916
1672.73	70.7079
1675.79	65.8165
1678.84	62.1013
1681.89	57.1536
1684.94	51.3082
1687.99	45.5773
1691.04	41.503
1694.08	35.0591
1697.13	30.0679
1700.18	25.0838
1703.22	21.8973
1706.26	18.9735
1709.3	16.4501
1712.35	14.9186
1715.39	13.9812
1718.42	11.9568
1721.46	10.4752
1724.5	9.45271
1727.53	8.12274
1730.56	8.74809
1733.6	8.98468
1736.63	8.59765
1739.66	7.25759
1742.69	5.78296
1745.71	5.46497
1748.74	4.98113
1751.77	3.96088
1754.79	3.8139
1757.81	3.16824
1760.84	1.94542
1763.86	1.88272
1766.88	1.03197
1769.9	0.968598
1772.91	1.1272
1775.93	1.62464
1778.95	3.16613
1781.96	3.50612
1784.97	3.8598
1787.99	5.50135
1791	5.53615
1794.01	5.68928
1797.01	5.828
1800.02	5.92962
1803.03	6.05975
1806.03	7.06937
1809.04	6.8528
1812.04	6.79489
1815.04	6.39724
1818.04	5.71479
1821.04	4.97222
1824.04	5.17232
1827.04	5.92971
1830.03	6.38968
1833.03	5.81019
1836.02	6.27558
1839.02	5.6433
1842.01	5.71392
1845	4.98346
1847.99	4.93677
1850.98	5.16066
1853.96	4.42551
1856.95	2.96733
1859.94	2.54338
1862.92	3.15796
1865.9	2.48739
1868.88	2.8646
1871.86	3.58056
1874.84	3.71672
1877.82	3.87502
1880.8	4.80208
1882.58	3.86311
1885.57	5.18425
1888.56	5.61888
1891.54	6.50125
1894.53	7.16433
1897.51	8.99475
1900.5	8.85626
1903.48	9.15599
1906.46	9.17845
1909.44	9.32072
1912.42	8.59602
1915.4	8.67457
1918.37	9.36033
1921.35	9.35273
1924.32	8.58715
1927.3	7.41337
1930.27	6.6909
1933.24	6.21117
1936.21	4.77097
1939.18	4.21254
1942.15	3.30913
1945.11	2.37344
1948.08	3.16214
1951.04	3.7783
1954.01	4.26849
1956.97	4.86337
1959.93	5.9666
1962.89	7.31476
1965.85	6.47999
1968.81	6.43498
1971.77	6.60719
1974.72	6.2846
1977.68	6.67759
1980.63	6.25595
1983.58	6.96325
1986.53	7.15547
1989.48	8.39996
1992.43	8.09925
1995.38	8.22469
1998.33	8.37348
2001.27	9.29423
2004.22	8.64209
2007.16	8.43232
2010.11	9.69852
2013.05	11.1122
2015.99	12.3836
2018.93	13.5045
2021.87	15.2847
2024.8	15.5917
2027.74	16.0409
2030.68	16.229
2033.61	16.8715
2036.54	16.0849
2039.48	15.4692
2042.41	15.7028
2045.34	16.1623
2048.27	15.547
2051.19	15.8739
2054.12	16.3949
2057.05	16.2532
2059.97	17.095
2062.9	18.4267
2065.82	19.6064
2068.74	20.8153
2071.66	22.0189
2074.58	22.9222
2077.5	24.1458
2080.41	25.5002
2083.33	28.2308
2086.24	29.8042
2089.16	31.0581
2092.07	33.4584
2094.98	34.6855
2097.89	35.3494
2100.8	37.0421
2103.71	38.8716
2106.62	41.0968
2109.53	42.6152
2112.43	45.4966
2115.33	48.361
2118.24	50.8761
2121.14	53.7229
2124.04	55.9426
2126.94	59.523
2129.84	63.5612
2132.74	68.7043
2135.63	71.5472
2138.53	74.5241
2141.43	78.3179
2144.32	82.0912
2147.21	86.2255
2150.1	89.9986
2152.99	94.4479
2155.88	98.3441
2158.77	100.085
2161.66	102.217
2164.55	104.228
2167.43	105.72
2170.31	107.335
2173.2	107.573
2176.08	106.901
2178.96	106.414
2181.84	104.867
2184.72	102.884
2187.6	101.136
2190.47	98.5607
2193.35	95.5438
2196.23	93.0794
2199.1	90.9727
2201.97	87.7407
2204.84	83.2157
2207.71	79.1605
2210.58	75.4946
2213.45	71.3862
2216.32	68.6439
2219.19	64.6689
2222.05	60.8002
2224.92	57.998
2227.78	54.3038
2230.64	50.2755
2233.5	47.8028
2236.36	45.573
2239.22	42.4761
2242.08	38.8418
2244.94	35.3435
2247.79	33.3788
2250.65	32.2953
2253.5	30.8977
2256.36	28.4559
2259.21	27.3631
2262.06	26.3519
2264.91	25.187
2267.76	24.6365
2270.6	22.8933
2273.45	20.6191
2276.3	18.0441
2279.14	17.088
2281.98	16.6554
2284.83	15.6714
2287.67	14.9649
2290.51	14.2633
2293.35	13.384
2296.19	12.683
2299.02	12.8701
2301.86	13.7979
2304.7	14.4035
2307.53	13.8991
2310.36	14.1208
2313.2	14.1062
2316.03	14.52
2318.86	15.1662
2321.69	14.5035
2324.51	14.4997
2327.34	14.013
2330.17	14.1035
2332.99	14.2338
2335.82	14.5861
2338.64	14.0282
2341.46	12.0771
2344.28	10.6645
2347.1	10.1212
2349.92	10.1147
2352.74	9.32249
2355.56	8.03805
2358.37	6.2809
2361.19	4.45336
2364	3.55798
2366.82	3.43145
2369.63	3.24774
2372.44	2.67585
2375.25	2.28203
2378.06	1.48626
2380.86	0.790675
2383.67	-0.0541078
2386.48	-0.228291
2389.28	-0.346296
2392.09	-0.724337
2394.89	-0.515696
2397.69	-0.68731
2400.49	0.318519
2403.29	0.18099
2406.09	0.643642
2408.89	1.23491
2411.69	0.423957
2414.48	1.6472
2417.28	2.65152
2420.07	3.31175
2422.86	3.35183
2425.65	4.48282
2428.45	4.2849
2431.23	4.53863
2434.02	4.27589
2436.81	4.44238
2439.6	4.68621
2442.38	5.22148
2445.17	4.52723
2447.95	4.18293
2450.73	3.60783
2453.52	3.75274
2456.3	3.32405
2459.08	2.77378
2461.85	1.05332
2464.63	0.857623
2467.41	0.709341
2470.19	0.64055
2472.96	0.247606
2475.73	1.59632
2478.51	1.90625
2481.28	1.63923
2484.05	2.60597
2486.82	3.10796
2489.59	3.60185
2492.35	4.01925
2495.12	4.1841
2497.89	4.01808
2500.65	3.87052
2503.42	4.16762
2506.18	4.05293
2508.94	3.98654
2511.7	3.77714
2514.46	3.93956
2517.22	3.35577
2519.98	3.4372
2522.73	2.95114
2525.49	2.05863
2528.25	1.47002
2531	1.7897
2533.75	2.43109
2536.5	2.36928
2539.25	3.17587
2542.01	3.39808
2544.75	4.22578
2547.5	2.9715
2550.25	3.73456
2553	4.32819
2555.74	4.23287
2558.49	4.4542
2561.23	4.57185
2563.97	4.33033
2566.71	4.33578
2569.45	4.16608
2572.19	4.40466
2574.93	4.1571
2577.67	4.3822
2580.4	3.29589
2583.14	3.48982
2585.87	3.48201
2588.6	3.17803
2591.34	2.48241
2594.07	2.39541
2596.8	2.20892
2599.53	1.96193
2602.26	1.66339
2604.98	2.2847
2607.71	2.68306
2610.44	1.97951
2613.16	1.26373
2615.88	0.35762
2618.61	1.49399
2621.33	1.25635
2624.05	1.76895
2626.77	1.12383
2629.49	0.532073
2632.21	0.397511
2634.92	0.152889
2637.64	0.429976
2640.35	0.170437
2643.07	0.040528
2645.78	-0.0136334
2648.49	0.0113817
2651.2	0.171166
2653.91	0.354398
2656.62	0.265596
2659.33	0.618606
2662.04	0.808946
2664.74	0.731053
2667.45	1.95751
2670.15	1.6215
2672.86	2.63455
2675.56	2.80318
2678.26	2.27581
2680.96	1.85164
2683.66	2.004
2686.36	2.48229
2689.06	1.95472
2691.75	1.15411
2694.45	1.05089
2697.14	0.911964
2699.84	1.15917
2702.53	1.02022
2705.22	1.33389
2707.91	1.62259
2710.6	2.33739
2713.29	3.03324
2715.98	4.42776
2718.67	4.74379
2721.35	5.4658
2724.04	6.56674
2726.72	6.88235
2729.4	7.57958
2732.09	8.33444
2734.77	8.6625
2737.45	8.4344
2740.13	9.017
2742.81	7.4404
2745.48	6.7427
2748.16	5.76288
2750.84	5.46811
2753.51	4.62108
2756.19	3.49917
2758.86	4.21218
2761.53	3.80274
2764.2	2.35367
2766.87	1.4788
2769.54	1.13713
2772.21	0.76811
2774.88	0.945504
2777.54	0.254158
2780.21	0.00520402
2782.87	-0.00279176
2785.53	0.121432
2788.2	0.00409046
2790.86	0.0920112
2793.52	0.211219
2796.18	-0.0209426
2798.84	-0.0572324
2801.49	-0.874307
2804.15	-1.23714
2806.81	-1.54838
2809.46	-1.37718
2812.12	-0.427734
2814.77	0.874414
2817.42	2.40832
2820.07	5.07192
2822.72	7.82098
2825.37	10.6912
2828.02	12.7563
2830.67	16.0903
2833.31	21.0734
2835.96	25.4787
2838.61	30.6087
2841.25	35.9726
2843.89	41.9616
2846.53	49.4499
2849.17	57.1401
2851.81	63.9025
2854.45	71.2048
2857.09	78.475
2859.73	85.6847
2862.36	91.903
2865	98.1523
2867.64	102.969
2870.27	108.047
2872.9	112.383
2875.53	116.438
2878.16	119.874
2880.79	124.602
2883.42	128.356
2886.05	131.963
2888.68	134.26
2891.3	137.999
2893.93	141.507
2896.55	146.321
2899.18	151.84
2901.8	158.119
2904.42	165.059
2907.04	171.989
2909.66	180.104
2912.28	189.498
2914.9	197.727
2917.51	206.001
2920.13	214.219
2922.74	221.238
2925.36	226.799
2927.97	231.257
2930.59	234.56
2933.2	235.907
2935.81	236.938
2938.42	235.109
2941.02	233.608
2943.63	229.97
2946.24	224.749
2948.85	217.149
2951.45	209.318
2954.05	201.213
2956.66	192.237
2959.26	183.224
2961.86	173.397
2964.46	163.202
2967.06	153.871
2969.66	143.586
2972.26	133.717
2974.85	123.951
2977.45	114.392
2980.05	106.109
2982.64	97.0194
2985.23	88.6394
2987.83	79.8747
2990.42	72.1706
2993.01	65.5267
2995.6	59.2578
2998.19	52.8791
3000.77	47.5966
3003.36	43.9319
3005.95	39.8915
3008.53	35.1984
3011.12	31.2517
3013.7	28.6456
3016.28	25.6688
3018.86	22.8376
3021.44	20.1472
3024.02	17.2717
3026.6	15.6235
3029.18	14.1504
3031.76	12.5447
3034.33	11.1133
3036.91	9.78132
3039.48	9.29573
3042.05	9.66506
3044.63	8.81237
3047.2	9.10658
3049.77	9.22173
3052.34	9.91134
3054.91	10.076
3057.48	9.94311
3060.04	10.3374
3062.61	10.901
3065.17	12.2785
3067.74	12.7897
3070.3	11.6005
3072.87	10.7252
3075.43	9.90523
3077.99	8.20825
3080.55	7.39495
3083.11	5.69143
3085.67	4.89226
3088.22	3.38598
3090.78	3.0186
3093.34	2.91831
3095.89	2.65149
3098.44	2.12527
3101	2.35731
3103.55	2.34991
3106.1	2.78373
3108.65	3.29798
3111.2	3.7775
3113.75	4.48354
3116.3	5.19008
3118.84	5.44439
3121.39	6.56594
3123.93	7.64099
3126.48	8.41491
3129.02	8.81074
3131.56	8.98543
3134.1	9.22322
3136.64	10.1709
3139.18	10.7354
3141.72	11.5696
3144.26	12.7171
3146.8	14.4597
3149.33	16.0799