File: data/Raman/poly_smoothed/Mb_40_y_08_1x_45s_532 nm_x100_100%_600 gr_mm_01.txt
#Acq. time (s)=	45
#Accumulations=	2
#Range (cm-¹)=	200...3150
#Windows=	2
#Auto scanning=	Off
#Autofocus=	Off
#Macrospot=	Off
#AutoExposure=	Off
#Spike filter=	Multiple accum.
#Delay time (s)=	0
#Binning=	1
#Readout mode=	Signal
#DeNoise=	Off
#ICS correction=	On
#Dark correction=	Off
#Inst. Process=	Off
#Detector Gain=	Best Dynamic Range
#Detector ADC=	20 kHz
#Detector temperature (°C)=	-69.85
#Instrument=	LabRAM HR Evol
#Detector=	Synapse
#Objective=	x100
#Grating=	600 gr/mm
#ND Filter=	100%
#Laser (nm)=	532
#Hole=	100.021
#Range=	Auto
#Laser Pol.=	No
#Raman. Pol.=	No
#Laser Pol. (°)=	-0.0007625
#Raman Pol. (°)=	89.9995
#Collection=	Microscope
#StageXY=	Marzhauser
#StageZ=	Marzhauser
#X (µm)=	-1035.2
#Y (µm)=	687.8
#Z (µm)=	584.15
#Full time(mm:ss)=	3:19
#Project=
#Sample=
#Site=
#Title=	Mb_40_y_08_2x_45s_532 nm_x100_100%_600 gr_mm
#Remark=
#Date=	19.07.2022 09:29
#Acquired=	19.07.2022 09:29:13
#Base:Fit=	10.08.2022 10:52:48
#Base:Sub=	10.08.2022 10:52:53
#Filter:Polynom=	16.08.2022 10:09:04
#AxisType[0]=Intens
#AxisUnit[0]=Cnt
#AxisType[1]=Spectr
#AxisUnit[1]=1/cm
200.423	24.4771
204.052	24.7947
207.682	23.0716
211.308	20.1724
214.935	17.2157
218.558	13.5268
222.18	12.7884
225.802	10.2112
229.421	8.75395
233.039	8.55804
236.657	7.89702
240.272	6.16172
243.885	4.88011
247.497	4.03085
251.11	2.83224
254.719	4.5455
258.327	5.92637
261.933	5.24114
265.538	7.1834
269.141	9.10063
272.744	10.0945
276.344	13.2753
279.944	14.2141
283.542	13.7598
287.138	13.9633
290.733	13.0804
294.327	12.2352
297.919	11.3744
301.508	11.7011
305.098	12.1955
308.686	14.1088
312.273	14.2409
315.858	12.5183
319.44	13.2527
323.022	11.9826
326.604	10.8659
330.181	10.2283
333.76	8.56873
337.335	8.60805
340.91	6.03697
344.483	5.49561
348.055	4.33503
351.625	2.128
355.195	3.88728
358.762	4.66509
362.329	6.43274
365.893	5.91607
369.455	4.85099
373.017	4.34074
376.578	4.41463
380.137	5.52915
383.694	7.52241
387.249	9.49784
390.806	11.5499
394.359	11.0768
397.91	12.1378
401.46	13.4031
405.009	14.8301
408.557	15.5458
412.103	15.3446
415.647	16.3336
419.191	15.4191
422.733	16.3897
426.273	16.982
429.812	15.4411
433.35	16.9037
436.885	16.9545
440.42	18.8299
443.954	20.7935
447.486	20.6203
451.015	20.7169
454.545	19.7401
458.073	21.9873
461.598	21.9398
465.124	23.09
468.648	24.2058
472.169	23.7388
475.69	25.4437
479.208	26.0232
482.727	26.8061
486.243	29.0216
489.759	30.7348
493.272	32.137
496.783	31.6547
500.295	32.804
503.804	32.5428
507.311	32.1727
510.819	32.0421
514.324	31.2242
517.827	30.8539
521.329	30.7762
524.83	29.1742
528.329	29.7545
531.829	29.136
535.326	27.5422
538.821	26.131
542.315	25.1707
545.808	21.2013
549.299	20.3371
552.789	18.1929
556.278	15.4726
559.763	13.8904
563.249	14.5161
566.733	11.8572
570.217	12.2233
573.699	9.91891
577.177	9.44659
580.656	8.78897
584.134	8.15723
587.609	7.52951
591.084	7.72959
594.558	6.46035
598.029	5.58204
601.5	7.18256
604.968	8.22111
608.437	9.84737
611.902	10.0377
615.368	10.6217
618.831	11.0304
622.294	10.1836
625.755	10.7008
629.213	10.5237
632.673	8.95919
636.129	7.96164
639.584	7.01017
643.037	6.28498
646.491	6.76318
649.942	7.38199
653.392	7.45072
656.84	7.76883
660.287	7.93385
663.732	7.85998
667.177	8.72381
670.62	9.82033
674.061	9.59522
677.502	11.2788
680.941	12.1607
684.379	14.8286
687.815	18.8014
691.248	22.4847
694.682	25.8546
698.115	27.7771
701.546	32.075
704.974	35.0508
708.402	38.7459
711.83	41.6828
715.254	41.4824
718.679	43.4846
722.102	43.6695
725.522	45.2184
728.943	46.605
732.361	48.7616
735.779	49.1035
739.194	49.607
742.608	49.2188
746.022	50.0144
749.433	51.3983
752.843	52.7517
756.254	52.9377
759.661	54.2773
763.067	57.2465
766.471	59.2983
769.877	61.8091
773.279	64.4253
776.68	64.2306
780.079	65.0165
783.478	66.3128
786.875	67.1149
790.27	68.3451
793.665	67.2609
797.058	68.9998
800.45	69.7328
803.84	70.209
807.23	70.688
810.616	70.0551
814.002	69.7506
817.388	67.3916
820.772	65.2154
824.153	64.8101
827.535	63.6484
830.915	63.3724
834.292	61.7373
837.67	59.5297
841.047	58.6561
844.42	57.4418
847.794	54.8008
851.165	51.1971
854.534	48.4363
857.905	46.5483
861.272	44.5031
864.639	44.5099
868.004	43.9703
871.367	42.9849
874.731	43.575
878.092	42.1527
881.451	42.1468
884.809	42.0254
888.166	42.0659
891.522	40.658
894.878	39.4851
898.231	37.6039
901.583	39.1828
904.934	39.6433
908.283	40.6006
911.631	41.3199
914.976	42.3413
918.322	40.9352
921.666	40.6343
925.009	40.5691
928.351	40.566
931.692	39.7603
935.029	38.894
938.367	39.5293
941.704	39.2399
945.038	38.4037
948.372	37.4808
951.705	37.9155
955.035	38.298
958.366	38.3153
961.693	37.4808
965.021	38.9564
968.346	39.6767
971.67	38.9914
974.995	39.8545
978.316	41.0432
981.638	42.6519
984.957	43.0813
988.274	41.0599
991.59	39.3251
994.907	34.4653
998.221	29.6241
1001.53	23.3537
1004.85	17.9464
1008.16	21.1337
1011.46	34.9082
1014.77	58.5199
1018.08	87.8688
1021.38	117.893
1024.69	144.578
1027.99	169.726
1031.29	192.567
1034.59	209.793
1037.89	222.892
1041.19	230.849
1044.48	235.824
1047.78	237.643
1051.07	231.95
1054.36	224.322
1057.66	212.965
1060.94	194.43
1064.23	172.351
1067.52	144.583
1070.81	116.725
1074.09	85.352
1077.38	56.3455
1080.66	30.4054
1083.94	13.1615
1087.22	5.72894
1090.5	9.49061
1093.77	16.3763
1097.05	23.6405
1100.32	28.1706
1103.6	29.7224
1106.87	31.4278
1110.14	31.9378
1113.41	32.2286
1116.67	31.8285
1119.94	31.7856
1123.21	32.2464
1126.47	33.4462
1129.73	34.0654
1133	32.3977
1136.26	30.5143
1139.52	28.4495
1142.77	24.7046
1146.03	24.4625
1149.29	23.1069
1152.54	21.6236
1155.79	17.4325
1159.04	16.1936
1162.3	13.5596
1165.55	12.548
1168.79	11.4902
1172.04	9.59097
1175.28	9.45676
1178.53	8.80851
1181.77	7.44645
1185.01	4.85543
1188.25	5.18983
1191.49	4.60525
1194.73	5.49079
1197.97	5.88881
1201.2	10.3539
1204.44	14.5841
1207.67	18.1794
1210.9	19.8894
1214.13	21.6415
1217.36	26.016
1220.59	29.8322
1223.82	34.9244
1227.04	38.9843
1230.26	40.6005
1233.49	45.6571
1236.71	51.2595
1239.93	56.9456
1243.15	61.2727
1246.37	66.4319
1249.58	70.8019
1252.8	72.5531
1256.01	74.5876
1259.23	76.6446
1262.44	77.8785
1265.65	81.0216
1268.86	84.5515
1272.07	85.6268
1275.27	88.8277
1278.48	91.3109
1281.68	94.0627
1284.89	95.4356
1288.09	94.2747
1291.29	96.5253
1294.49	98.723
1297.69	99.6865
1300.88	100.558
1304.08	101.825
1307.27	103.333
1310.47	105.634
1313.66	107.897
1316.85	109.058
1320.04	110.088
1323.23	109.931
1326.41	110.612
1329.6	108.696
1332.78	106.542
1335.97	104.011
1339.15	102.597
1342.33	100.18
1345.51	98.8464
1348.69	94.8961
1351.87	92.2642
1355.04	88.7562
1358.22	85.5037
1361.39	82.0532
1364.57	77.1211
1367.74	73.7031
1370.91	69.9251
1374.07	65.619
1377.24	62.9158
1380.41	59.203
1383.57	56.3973
1386.74	54.6968
1389.9	54.3352
1393.06	52.0733
1396.22	51.7174
1399.38	50.9335
1402.54	49.8127
1405.7	51.3298
1408.85	52.3717
1412.01	54.9862
1415.16	58.268
1418.31	62.9913
1421.46	69.0195
1424.61	76.1798
1427.76	83.5073
1430.91	90.4931
1434.05	96.997
1437.2	103.223
1440.34	107.553
1443.49	110.557
1446.63	112.33
1449.77	112.741
1452.91	113.314
1456.04	114.21
1459.18	111.414
1462.31	109.481
1465.45	105.387
1468.58	102.014
1471.71	97.7311
1474.84	94.5119
1477.97	89.4153
1481.1	85.2431
1484.23	79.1863
1487.35	73.5598
1490.48	68.3074
1493.6	63.0608
1496.72	58.7952
1499.84	55.6279
1502.96	51.7385
1506.08	47.5382
1509.2	45.1555
1512.31	40.8842
1515.43	37.0798
1518.54	34.1108
1521.66	33.4747
1524.77	32.7109
1527.88	31.1125
1530.99	31.5571
1534.09	33.0237
1537.2	34.4643
1540.31	36.4846
1543.41	39.2556
1546.51	42.855
1549.62	46.4513
1552.72	48.2369
1555.82	49.0657
1558.91	50.0673
1562.01	51.5263
1565.11	53.1958
1568.2	53.7891
1571.3	55.8072
1574.39	58.5656
1577.48	59.7545
1580.57	63.8862
1583.66	65.4183
1586.75	66.146
1589.83	67.7848
1592.92	68.2579
1596	70.0995
1599.09	70.6345
1602.17	72.2198
1605.25	71.2459
1608.33	71.666
1611.41	72.8197
1614.48	73.0046
1617.56	73.9766
1620.64	74.5247
1623.71	75.6617
1626.78	77.4765
1629.86	81.2233
1632.92	84.2217
1635.99	88.4402
1639.06	91.1001
1642.13	96.9417
1645.19	99.5032
1648.26	102.325
1651.32	105.02
1654.38	107.242
1657.45	107.832
1660.51	105.962
1663.57	104.772
1666.62	100.727
1669.68	96.6655
1672.73	92.7843
1675.79	87.795
1678.84	81.64
1681.89	73.1567
1684.94	66.8587
1687.99	59.528
1691.04	52.1548
1694.09	44.1231
1697.14	38.1185
1700.18	32.5006
1703.22	29.2369
1706.27	25.8489
1709.31	21.8567
1712.35	18.7184
1715.39	16.2187
1718.43	12.8959
1721.46	9.91508
1724.5	10.2053
1727.53	8.87926
1730.57	7.73573
1733.6	6.12971
1736.63	5.76068
1739.66	5.82681
1742.69	5.57099
1745.72	6.72048
1748.74	6.97135
1751.77	7.73048
1754.8	7.75262
1757.82	8.17111
1760.84	8.12702
1763.86	8.83283
1766.88	7.16958
1769.9	6.99169
1772.92	6.12004
1775.93	6.97064
1778.95	7.24142
1781.96	7.48988
1784.98	7.28224
1787.99	5.76926
1791	4.87175
1794.01	4.56705
1797.02	5.06015
1800.03	4.01724
1803.03	2.30379
1806.04	3.36624
1809.04	4.16217
1812.04	3.83122
1815.05	5.0684
1818.05	5.14369
1821.05	5.36132
1824.05	6.35474
1827.04	5.65643
1830.04	4.96543
1833.03	4.0267
1836.03	4.08342
1839.02	4.0159
1842.01	3.95034
1845	3.89392
1847.99	3.51874
1850.98	4.42404
1853.97	4.71999
1856.95	3.64794
1859.94	3.85369
1862.92	3.95609
1865.91	4.96426
1868.89	6.76068
1871.87	7.24885
1874.85	7.88032
1877.83	8.61822
1880.8	9.65356
1882.56	9.30149
1885.54	9.87945
1888.53	10.5681
1891.52	10.4729
1894.5	10.0577
1897.49	9.56814
1900.47	9.24299
1903.45	8.70649
1906.43	8.88521
1909.41	10.2941
1912.39	9.88719
1915.37	9.7112
1918.35	7.66961
1921.32	6.95122
1924.3	5.35305
1927.27	5.05293
1930.24	3.50679
1933.21	4.04174
1936.18	4.80337
1939.15	4.40532
1942.12	3.99685
1945.09	3.22631
1948.05	1.77835
1951.02	2.1332
1953.98	-0.0748307
1956.94	-0.321238
1959.91	2.47808
1962.87	3.97378
1965.82	5.05884
1968.78	7.01351
1971.74	9.95022
1974.7	12.1676
1977.65	13.0534
1980.6	13.651
1983.56	13.4607
1986.51	13.306
1989.46	13.9686
1992.41	12.8055
1995.36	13.1433
1998.3	15.2833
2001.25	14.4962
2004.2	14.9623
2007.14	15.9679
2010.08	14.8382
2013.02	13.9255
2015.97	13.2918
2018.9	13.6173
2021.84	13.8196
2024.78	14.7025
2027.72	15.6622
2030.65	18.5372
2033.59	19.9512
2036.52	19.2954
2039.45	20.4973
2042.38	22.3116
2045.31	23.3783
2048.24	24.5611
2051.17	25.0011
2054.1	25.1967
2057.02	24.7752
2059.95	25.9456
2062.87	26.5551
2065.79	27.5761
2068.71	28.928
2071.63	29.8184
2074.55	29.9163
2077.47	32.3279
2080.39	33.8855
2083.3	35.7929
2086.22	39.1899
2089.13	41.2911
2092.05	43.8926
2094.96	45.907
2097.87	49.9417
2100.78	51.7997
2103.69	54.0303
2106.59	57.4213
2109.5	60.8487
2112.41	65.3302
2115.31	70.9061
2118.21	74.5469
2121.12	79.576
2124.02	83.5693
2126.92	88.286
2129.82	94.4651
2132.71	99.732
2135.61	104.751
2138.51	108.895
2141.4	115.3
2144.29	121.208
2147.19	128.439
2150.08	133.496
2152.97	138.282
2155.86	143.924
2158.75	147.555
2161.64	149.174
2164.52	152.581
2167.41	154.864
2170.29	155.38
2173.17	155.222
2176.06	154.915
2178.94	152.085
2181.82	149.762
2184.7	146.6
2187.57	143.312
2190.45	139.943
2193.33	136.59
2196.2	131.669
2199.08	127.416
2201.95	122.58
2204.82	116.041
2207.69	111.159
2210.56	106.47
2213.43	102.065
2216.3	97.4961
2219.16	92.2831
2222.03	86.4486
2224.89	81.2657
2227.75	76.6765
2230.62	71.1637
2233.48	65.8058
2236.34	62.8902
2239.2	57.9414
2242.06	53.3767
2244.91	48.2681
2247.77	44.4052
2250.62	40.6762
2253.48	39.673
2256.33	37.0875
2259.18	35.5825
2262.03	34.5546
2264.88	33.3734
2267.73	32.3653
2270.58	32.534
2273.43	30.4247
2276.27	30.3494
2279.12	30.1388
2281.96	30.9751
2284.8	30.5102
2287.64	29.7027
2290.49	27.1989
2293.32	24.4425
2296.16	22.5502
2299	21.5745
2301.84	21.1896
2304.67	20.0344
2307.51	18.3517
2310.34	16.5406
2313.17	15.1898
2316	14.6636
2318.83	13.8746
2321.66	13.6515
2324.49	12.4976
2327.32	12.398
2330.15	11.2932
2332.97	11.1947
2335.79	11.6392
2338.62	11.5919
2341.44	11.4977
2344.26	10.9579
2347.08	11.3112
2349.9	11.4247
2352.72	10.806
2355.53	8.37275
2358.35	6.33007
2361.17	4.09757
2363.98	3.07748
2366.79	3.19501
2369.6	3.40921
2372.42	3.83936
2375.22	2.6826
2378.03	1.46775
2380.84	2.35039
2383.65	2.17849
2386.45	3.06798
2389.26	4.07093
2392.06	4.24298
2394.87	5.3795
2397.67	6.49226
2400.47	7.27413
2403.27	8.85427
2406.07	9.31995
2408.86	9.79993
2411.66	10.4169
2414.46	11.0301
2417.25	11.4971
2420.05	12.6406
2422.84	11.5776
2425.63	11.281
2428.42	11.847
2431.21	12.0407
2434	12.8084
2436.79	12.9225
2439.57	12.0529
2442.36	11.6939
2445.14	11.1627
2447.93	10.6057
2450.71	9.74216
2453.49	10.0636
2456.27	9.27787
2459.05	8.57124
2461.83	7.73517
2464.61	7.82244
2467.39	7.14954
2470.16	7.08553
2472.94	6.80578
2475.71	6.47902
2478.48	5.31259
2481.25	4.16602
2484.02	4.25228
2486.8	3.26413
2489.56	3.20589
2492.33	3.25532
2495.1	3.02998
2497.86	3.76651
2500.63	3.38102
2503.39	2.01728
2506.16	1.38556
2508.92	1.22329
2511.68	1.71775
2514.44	0.931763
2517.2	0.532212
2519.95	0.739845
2522.71	0.699032
2525.47	1.06148
2528.22	1.70477
2530.98	3.12151
2533.73	4.79554
2536.48	6.38941
2539.23	6.81488
2541.98	6.69072
2544.73	6.8147
2547.48	6.82029
2550.23	8.00174
2552.97	7.92658
2555.72	7.79621
2558.46	8.0178
2561.2	7.91527
2563.95	8.10948
2566.69	5.8576
2569.43	5.03498
2572.17	4.02776
2574.91	3.73609
2577.64	2.6203
2580.38	2.61044
2583.11	1.68192
2585.85	0.829073
2588.58	0.641775
2591.31	1.4727
2594.04	1.97781
2596.78	3.02988
2599.51	3.82899
2602.23	3.6216
2604.96	4.32839
2607.69	3.83546
2610.41	4.43566
2613.14	5.18268
2615.86	5.43493
2618.58	6.30668
2621.3	6.40227
2624.03	6.00705
2626.75	4.77175
2629.46	4.91449
2632.18	2.36801
2634.9	2.53443
2637.61	1.83363
2640.33	1.86163
2643.04	1.91764
2645.76	1.16074
2648.47	1.72903
2651.18	1.36326
2653.89	2.28521
2656.6	3.43804
2659.31	4.102
2662.01	3.10905
2664.72	3.99643
2667.43	4.70329
2670.13	6.42058
2672.83	5.85546
2675.53	5.69833
2678.24	6.08784
2680.94	6.51091
2683.64	5.7424
2686.34	4.64805
2689.03	4.61501
2691.73	5.15418
2694.43	5.99905
2697.12	5.04086
2699.81	5.2654
2702.51	6.21222
2705.2	7.28187
2707.89	7.79317
2710.58	8.31063
2713.27	8.44389
2715.96	8.89597
2718.64	9.37545
2721.33	10.2677
2724.01	9.85055
2726.7	10.6377
2729.38	11.0723
2732.06	11.5259
2734.75	11.5044
2737.43	11.2618
2740.11	10.5313
2742.78	10.5979
2745.46	10.0801
2748.14	10.1177
2750.81	9.86236
2753.49	11.2041
2756.16	11.4963
2758.84	11.2815
2761.51	11.2607
2764.18	10.3888
2766.85	9.0711
2769.52	8.40485
2772.19	7.07607
2774.85	5.73035
2777.52	6.09022
2780.18	5.73311
2782.85	4.97619
2785.51	5.343
2788.17	5.14653
2790.84	4.44426
2793.5	4.13513
2796.16	2.57934
2798.81	3.15057
2801.47	2.60704
2804.13	3.23385
2806.79	2.08729
2809.44	2.13114
2812.09	1.31607
2814.75	1.3376
2817.4	1.33563
2820.05	3.4502
2822.7	6.0939
2825.35	10.2247
2828	14.3612
2830.65	18.8348
2833.29	23.2229
2835.94	30.0287
2838.58	36.7381
2841.23	47.3114
2843.87	56.2343
2846.51	64.5653
2849.15	73.9616
2851.79	84.6947
2854.43	94.2231
2857.07	103.463
2859.71	113.212
2862.34	121.796
2864.98	129.821
2867.61	136.831
2870.25	143.084
2872.88	149.344
2875.51	154.027
2878.14	159.634
2880.77	164.876
2883.4	170.576
2886.03	177.504
2888.65	183.364
2891.28	191.429
2893.91	198.731
2896.53	205.8
2899.15	214.907
2901.78	226.322
2904.4	240.363
2907.02	253.829
2909.64	266.597
2912.26	283.635
2914.87	299.185
2917.49	313.687
2920.11	327.733
2922.72	340.805
2925.34	351.642
2927.95	360.607
2930.56	365.797
2933.17	369.93
2935.78	369.689
2938.39	368.352
2941	364.229
2943.61	356.648
2946.22	347.062
2948.82	337.305
2951.43	324.797
2954.03	310.328
2956.64	296.667
2959.24	279.531
2961.84	264.549
2964.44	250.397
2967.04	236.857
2969.64	221.576
2972.24	206.148
2974.83	192.896
2977.43	179.463
2980.02	164.895
2982.62	152.046
2985.21	139.36
2987.8	125.508
2990.4	113.356
2992.99	100.449
2995.57	89.721
2998.16	79.1454
3000.75	70.4219
3003.34	62.1115
3005.92	52.832
3008.51	45.5537
3011.09	38.7093
3013.68	32.6354
3016.26	25.5541
3018.84	21.4725
3021.42	18.2803
3024	15.0984
3026.58	13.7739
3029.16	12.3925
3031.73	12.441
3034.31	12.2383
3036.89	13.6638
3039.46	12.7142
3042.03	13.1501
3044.61	13.3087
3047.18	13.5819
3049.75	14.0246
3052.32	14.5958
3054.89	15.3098
3057.45	14.7909
3060.02	15.6892
3062.59	15.6892
3065.15	14.8067
3067.72	13.6913
3070.28	12.7343
3072.84	10.954
3075.41	8.29359
3077.97	6.51019
3080.53	4.88956
3083.09	2.53733
3085.64	1.99409
3088.2	0.43593
3090.76	0.571821
3093.31	0.702361
3095.87	1.70894
3098.42	1.53674
3100.97	0.544648
3103.53	0.196435
3106.08	0.0643867
3108.63	0.861873
3111.18	2.10657
3113.73	3.10051
3116.27	4.05158
3118.82	6.1263
3121.37	7.19729
3123.91	8.36228
3126.45	8.9607
3129	11.065
3131.54	11.5957
3134.08	12.021
3136.62	12.4989
3139.16	13.0471
3141.7	12.9253
3144.24	11.9878
3146.78	10.9231
3149.31	8.45916