File: data/Raman/poly_smoothed/Mb_40_y_12_1x_45s_532 nm_x100_100%_600 gr_mm_02.txt
#Acq. time (s)=	45
#Accumulations=	2
#Range (cm-¹)=	200...3150
#Windows=	2
#Auto scanning=	Off
#Autofocus=	Off
#Macrospot=	Off
#AutoExposure=	Off
#Spike filter=	Multiple accum.
#Delay time (s)=	0
#Binning=	1
#Readout mode=	Signal
#DeNoise=	Off
#ICS correction=	On
#Dark correction=	Off
#Inst. Process=	Off
#Detector Gain=	Best Dynamic Range
#Detector ADC=	20 kHz
#Detector temperature (°C)=	-69.85
#Instrument=	LabRAM HR Evol
#Detector=	Synapse
#Objective=	x100
#Grating=	600 gr/mm
#ND Filter=	100%
#Laser (nm)=	532
#Hole=	100.021
#Range=	Auto
#Laser Pol.=	No
#Raman. Pol.=	No
#Laser Pol. (°)=	-0.0007625
#Raman Pol. (°)=	89.9995
#Collection=	Microscope
#StageXY=	Marzhauser
#StageZ=	Marzhauser
#X (µm)=	-1060.6
#Y (µm)=	720.4
#Z (µm)=	584.55
#Full time(mm:ss)=	3:19
#Project=
#Sample=
#Site=
#Title=	Mb_40_y_12_2x_45s_532 nm_x100_100%_600 gr_mm
#Remark=
#Date=	19.07.2022 09:53
#Acquired=	19.07.2022 09:53:25
#Base:Fit=	10.08.2022 10:52:48
#Base:Sub=	10.08.2022 10:52:53
#Filter:Polynom=	16.08.2022 10:09:04
#AxisType[0]=Intens
#AxisUnit[0]=Cnt
#AxisType[1]=Spectr
#AxisUnit[1]=1/cm
200.423	17.4717
204.052	13.9239
207.682	11.0036
211.308	8.61379
214.935	7.58217
218.558	4.75347
222.18	4.46481
225.802	5.19004
229.421	5.3909
233.039	3.77183
236.657	3.46608
240.272	4.1129
243.885	4.85838
247.497	2.92976
251.11	-0.0379213
254.719	3.321
258.327	5.64008
261.933	7.19162
265.538	9.9573
269.141	13.0278
272.744	14.7559
276.344	16.1729
279.944	17.0155
283.542	19.2239
287.138	18.2459
290.733	18.5125
294.327	17.9288
297.919	17.5864
301.508	17.2498
305.098	16.4351
308.686	14.9235
312.273	14.0167
315.858	14.6374
319.44	13.2325
323.022	12.082
326.604	11.7412
330.181	9.98132
333.76	7.87346
337.335	5.22578
340.91	7.59587
344.483	8.70915
348.055	8.93343
351.625	8.02831
355.195	9.11766
358.762	9.02211
362.329	9.12637
365.893	8.3488
369.455	7.66322
373.017	4.78343
376.578	2.1748
380.137	2.09394
383.694	2.68271
387.249	4.15397
390.806	3.65495
394.359	4.56484
397.91	3.78222
401.46	6.23836
405.009	7.88154
408.557	9.53778
412.103	9.97857
415.647	10.705
419.191	11.6317
422.733	10.4488
426.273	11.8807
429.812	10.5143
433.35	10.1978
436.885	9.50468
440.42	9.75959
443.954	8.87544
447.486	9.36107
451.015	7.8274
454.545	7.35387
458.073	5.69433
461.598	7.1136
465.124	11.2498
468.648	15.1623
472.169	17.3169
475.69	16.2071
479.208	16.2894
482.727	17.0965
486.243	17.9651
489.759	19.2956
493.272	20.9443
496.783	21.2518
500.295	22.8203
503.804	22.7286
507.311	22.992
510.819	22.452
514.324	21.1196
517.827	20.4791
521.329	19.5758
524.83	20.1867
528.329	17.153
531.829	15.8702
535.326	14.523
538.821	13.2463
542.315	11.7977
545.808	13.2145
549.299	12.5191
552.789	12.4832
556.278	10.7136
559.763	8.24739
563.249	6.41105
566.733	5.94302
570.217	4.59299
573.699	4.64742
577.177	4.70006
580.656	4.38485
584.134	4.07052
587.609	4.24371
591.084	3.71222
594.558	5.63059
598.029	6.33748
601.5	7.25719
604.968	9.70503
608.437	8.97092
611.902	9.36075
615.368	8.208
618.831	10.1204
622.294	10.2043
625.755	10.4603
629.213	10.4296
632.673	10.6
636.129	8.22504
639.584	7.83719
643.037	7.01695
646.491	7.11007
649.942	6.64282
653.392	7.05994
656.84	6.34791
660.287	5.51767
663.732	4.96736
667.177	4.32844
670.62	3.96878
674.061	4.41063
677.502	5.35984
680.941	8.35609
684.379	9.19091
687.815	11.8547
691.248	14.7949
694.682	16.5709
698.115	18.364
701.546	22.3473
704.974	25.2107
708.402	27.759
711.83	29.6049
715.254	31.773
718.679	32.7248
722.102	34.378
725.522	36.4614
728.943	37.8523
732.361	38.8012
735.779	39.1649
739.194	41.0753
742.608	41.7646
746.022	41.5876
749.433	43.3141
752.843	44.3617
756.254	44.5127
759.661	44.8307
763.067	46.5079
766.471	48.9359
769.877	50.4463
773.279	50.729
776.68	52.6581
780.079	53.066
783.478	57.4433
786.875	58.3856
790.27	58.5485
793.665	58.6642
797.058	58.8477
800.45	59.1282
803.84	60.1971
807.23	58.0376
810.616	57.5217
814.002	56.913
817.388	55.0439
820.772	55.6518
824.153	53.8706
827.535	52.7974
830.915	51.7609
834.292	51.0233
837.67	49.4794
841.047	47.2541
844.42	45.9766
847.794	45.0001
851.165	43.6868
854.534	42.581
857.905	40.4356
861.272	39.7849
864.639	38.768
868.004	35.1525
871.367	33.5341
874.731	31.2154
878.092	31.3999
881.451	32.2865
884.809	33.4461
888.166	31.9842
891.522	30.3091
894.878	31.4107
898.231	30.9176
901.583	31.1649
904.934	33.0124
908.283	33.558
911.631	35.1021
914.976	35.785
918.322	36.9947
921.666	38.1036
925.009	40.2141
928.351	42.6424
931.692	42.2796
935.029	43.0756
938.367	43.6461
941.704	43.8606
945.038	41.2887
948.372	39.1888
951.705	39.7213
955.035	39.1633
958.366	40.0342
961.693	40.0292
965.021	38.413
968.346	36.3282
971.67	36.9097
974.995	37.5155
978.316	37.1364
981.638	35.9157
984.957	35.889
988.274	33.1272
991.59	31.163
994.907	28.0363
998.221	23.8066
1001.53	18.0466
1004.85	14.425
1008.16	17.9244
1011.46	28.6906
1014.77	46.3135
1018.08	64.3209
1021.38	84.0667
1024.69	101.969
1027.99	119.502
1031.29	135.252
1034.59	145.957
1037.89	154.478
1041.19	160.165
1044.48	162.377
1047.78	162.898
1051.07	161.593
1054.36	156.145
1057.66	146.019
1060.94	133.473
1064.23	116.306
1067.52	97.2715
1070.81	77.3334
1074.09	56.2522
1077.38	35.2788
1080.66	16.754
1083.94	4.32757
1087.22	-0.196062
1090.5	1.93371
1093.77	7.93483
1097.05	9.61606
1100.32	12.2624
1103.6	14.7305
1106.87	16.3958
1110.14	17.5417
1113.41	17.5595
1116.67	17.8171
1119.94	18.447
1123.21	17.0192
1126.47	16.3688
1129.73	15.0607
1133	14.1979
1136.26	13.9937
1139.52	12.4945
1142.77	11.9557
1146.03	10.8689
1149.29	10.8848
1152.54	9.48421
1155.79	9.76502
1159.04	7.82799
1162.3	5.30656
1165.55	4.52418
1168.79	4.08567
1172.04	4.40788
1175.28	2.9768
1178.53	2.80885
1181.77	2.61311
1185.01	3.44819
1188.25	2.30157
1191.49	1.2639
1194.73	1.1926
1197.97	1.99868
1201.2	2.52488
1204.44	3.33332
1207.67	4.52933
1210.9	7.06115
1214.13	9.58753
1217.36	12.4423
1220.59	13.5493
1223.82	15.6457
1227.04	16.668
1230.26	19.0795
1233.49	21.0507
1236.71	24.3322
1239.93	25.1849
1243.15	29.1491
1246.37	30.1752
1249.58	31.7207
1252.8	34.4822
1256.01	35.2712
1259.23	37.842
1262.44	40.0371
1265.65	41.0926
1268.86	43.8308
1272.07	47.6672
1275.27	50.4513
1278.48	53.702
1281.68	53.8268
1284.89	55.4113
1288.09	56.9505
1291.29	57.7638
1294.49	57.5519
1297.69	57.0209
1300.88	56.5514
1304.08	56.8106
1307.27	56.1277
1310.47	55.9839
1313.66	55.8862
1316.85	55.8386
1320.04	54.2737
1323.23	55.156
1326.41	53.8871
1329.6	54.627
1332.78	54.0264
1335.97	54.4004
1339.15	54.1763
1342.33	52.3278
1345.51	52.4199
1348.69	51.4849
1351.87	50.4276
1355.04	47.9765
1358.22	45.0512
1361.39	42.4721
1364.57	41.0805
1367.74	39.3374
1370.91	37.395
1374.07	35.4639
1377.24	32.4193
1380.41	30.1497
1383.57	28.9228
1386.74	27.9473
1389.9	29.2511
1393.06	30.0421
1396.22	30.4645
1399.38	34.0497
1402.54	36.1195
1405.7	39.3535
1408.85	41.6622
1412.01	45.6152
1415.16	49.6052
1418.31	53.2439
1421.46	58.4299
1424.61	65.3679
1427.76	71.3366
1430.91	76.7599
1434.05	81.7811
1437.2	86.8319
1440.34	90.5466
1443.49	91.6153
1446.63	92.6702
1449.77	91.9208
1452.91	88.8522
1456.04	85.8684
1459.18	82.7702
1462.31	79.7346
1465.45	75.8967
1468.58	71.1036
1471.71	65.8629
1474.84	61.1702
1477.97	54.8716
1481.1	48.2263
1484.23	42.5671
1487.35	38.8166
1490.48	35.2244
1493.6	30.988
1496.72	27.627
1499.84	25.9138
1502.96	25.6845
1506.08	22.6981
1509.2	21.9865
1512.31	20.1971
1515.43	18.5605
1518.54	17.4324
1521.66	17.7952
1524.77	18.8702
1527.88	19.0017
1530.99	18.3624
1534.09	19.1316
1537.2	21.0045
1540.31	20.7863
1543.41	21.4293
1546.51	23.2101
1549.62	24.2466
1552.72	25.1735
1555.82	26.8829
1558.91	29.3173
1562.01	31.3121
1565.11	32.6353
1568.2	34.4857
1571.3	36.5936
1574.39	39.009
1577.48	40.9325
1580.57	41.1937
1583.66	42.3979
1586.75	44.1003
1589.83	44.7526
1592.92	45.0256
1596	48.1804
1599.09	48.343
1602.17	47.1531
1605.25	44.3009
1608.33	43.5362
1611.41	43.9343
1614.48	43.9893
1617.56	43.2995
1620.64	43.9486
1623.71	45.5105
1626.78	48.1867
1629.86	50.6444
1632.92	52.6259
1635.99	54.5212
1639.06	55.6571
1642.13	58.545
1645.19	59.9033
1648.26	61.7819
1651.32	61.2352
1654.38	61.5056
1657.45	62.8808
1660.51	62.1689
1663.57	60.6184
1666.62	57.856
1669.68	54.891
1672.73	49.9238
1675.79	44.7653
1678.84	40.697
1681.89	36.9193
1684.94	33.0806
1687.99	31.0597
1691.04	28.0145
1694.09	26.1226
1697.14	23.9011
1700.18	21.6439
1703.22	20.6404
1706.27	18.105
1709.31	15.5966
1712.35	14.1886
1715.39	13.3092
1718.43	12.4289
1721.46	11.5877
1724.5	11.5913
1727.53	12.5363
1730.57	13.0511
1733.6	12.1547
1736.63	11.3081
1739.66	9.41514
1742.69	8.75263
1745.72	7.05883
1748.74	6.87119
1751.77	7.12426
1754.8	6.9172
1757.82	7.0649
1760.84	7.02894
1763.86	8.23312
1766.88	8.70133
1769.9	8.39807
1772.92	8.41243
1775.93	7.64792
1778.95	7.4683
1781.96	6.95285
1784.98	6.34171
1787.99	6.01549
1791	5.62459
1794.01	4.59311
1797.02	4.99475
1800.03	4.51509
1803.03	4.30922
1806.04	4.09565
1809.04	3.34191
1812.04	2.52721
1815.05	1.68674
1818.05	1.35663
1821.05	0.385258
1824.05	0.427103
1827.04	0.400581
1830.04	0.598088
1833.03	-0.157319
1836.03	0.252092
1839.02	0.490294
1842.01	1.22991
1845	2.18859
1847.99	2.7705
1850.98	2.89658
1853.97	3.40789
1856.95	4.40849
1859.94	5.18155
1862.92	5.59266
1865.91	5.97532
1868.89	5.78984
1871.87	6.55493
1874.85	7.47682
1877.83	6.79869
1880.8	7.95963
1882.56	7.80586
1885.54	7.89585
1888.53	9.29445
1891.52	8.53955
1894.5	8.55678
1897.49	8.84759
1900.47	9.02111
1903.45	8.54513
1906.43	8.31477
1909.41	7.58507
1912.39	6.52467
1915.37	6.18302
1918.35	5.49053
1921.32	5.80445
1924.3	4.46362
1927.27	3.62135
1930.24	2.721
1933.21	2.20246
1936.18	0.621694
1939.15	-0.154743
1942.12	0.363496
1945.09	1.08307
1948.05	1.46654
1951.02	2.58188
1953.98	2.99602
1956.94	3.64812
1959.91	4.56335
1962.87	5.1821
1965.82	5.04208
1968.78	5.79988
1971.74	4.69128
1974.7	4.71956
1977.65	3.63204
1980.6	3.34757
1983.56	2.91452
1986.51	3.42641
1989.46	3.78548
1992.41	4.63117
1995.36	4.40429
1998.3	3.51872
2001.25	3.82613
2004.2	4.42036
2007.14	4.61249
2010.08	5.78923
2013.02	6.74057
2015.97	8.16183
2018.9	9.02926
2021.84	8.66414
2024.78	9.73372
2027.72	9.89998
2030.65	11.2671
2033.59	11.7154
2036.52	11.8139
2039.45	12.7078
2042.38	12.6583
2045.31	12.4472
2048.24	12.3915
2051.17	13.3452
2054.1	13.9384
2057.02	15.3581
2059.95	17.1729
2062.87	17.7158
2065.79	17.9047
2068.71	18.5701
2071.63	18.316
2074.55	19.2216
2077.47	20.7692
2080.39	21.9953
2083.3	23.1323
2086.22	23.2433
2089.13	23.6491
2092.05	23.5667
2094.96	24.6631
2097.87	26.8194
2100.78	28.9207
2103.69	30.0979
2106.59	32.3384
2109.5	33.6439
2112.41	36.0218
2115.31	37.4689
2118.21	39.7936
2121.12	41.8336
2124.02	45.7988
2126.92	48.7182
2129.82	51.2988
2132.71	55.096
2135.61	58.4678
2138.51	61.4279
2141.4	64.888
2144.29	68.7607
2147.19	73.5873
2150.08	77.2072
2152.97	79.6558
2155.86	82.0983
2158.75	84.1305
2161.64	85.7665
2164.52	87.9233
2167.41	89.7266
2170.29	90.4996
2173.17	91.4444
2176.06	89.9869
2178.94	90.8718
2181.82	89.0708
2184.7	87.745
2187.57	84.9725
2190.45	83.1066
2193.33	79.5771
2196.2	77.4133
2199.08	74.4474
2201.95	72.1399
2204.82	67.7384
2207.69	63.7299
2210.56	60.8732
2213.43	58.3947
2216.3	55.3624
2219.16	52.6219
2222.03	49.3954
2224.89	46.0519
2227.75	44.2389
2230.62	41.7693
2233.48	37.9852
2236.34	36.1987
2239.2	33.6584
2242.06	32.1674
2244.91	30.1782
2247.77	29.5178
2250.62	29.6054
2253.48	27.6067
2256.33	26.7737
2259.18	25.026
2262.03	23.6915
2264.88	23.5084
2267.73	22.6093
2270.58	20.8513
2273.43	18.3434
2276.27	17.5086
2279.12	16.8609
2281.96	16.4913
2284.8	14.3426
2287.64	12.6951
2290.49	11.6802
2293.32	9.54669
2296.16	10.0355
2299	10.195
2301.84	9.95273
2304.67	9.99354
2307.51	10.8188
2310.34	11.2468
2313.17	12.3627
2316	13.3495
2318.83	14.1408
2321.66	14.9714
2324.49	14.1009
2327.32	14.6461
2330.15	15.2164
2332.97	14.9542
2335.79	13.2559
2338.62	11.777
2341.44	10.2235
2344.26	9.14154
2347.08	8.44762
2349.9	6.84062
2352.72	5.01842
2355.53	3.2575
2358.35	2.76445
2361.17	1.95868
2363.98	1.49691
2366.79	3.14607
2369.6	2.0261
2372.42	1.6798
2375.22	2.90938
2378.03	2.78793
2380.84	2.6338
2383.65	3.99645
2386.45	5.50969
2389.26	5.98136
2392.06	5.6968
2394.87	5.29637
2397.67	5.67887
2400.47	5.30327
2403.27	4.82528
2406.07	4.84946
2408.86	3.78778
2411.66	4.27424
2414.46	4.35682
2417.25	4.11322
2420.05	4.78397
2422.84	4.51014
2425.63	4.45235
2428.42	3.10633
2431.21	2.9248
2434	2.85561
2436.79	2.14289
2439.57	2.91484
2442.36	3.41157
2445.14	3.62326
2447.93	3.33052
2450.71	3.87656
2453.49	5.44504
2456.27	5.78903
2459.05	5.23024
2461.83	5.45432
2464.61	4.70687
2467.39	5.61152
2470.16	5.82511
2472.94	4.80907
2475.71	4.28175
2478.48	4.41949
2481.25	3.92521
2484.02	3.83485
2486.8	3.12877
2489.56	2.98669
2492.33	2.27584
2495.1	1.19399
2497.86	1.80111
2500.63	2.22407
2503.39	1.70381
2506.16	1.99059
2508.92	2.16742
2511.68	1.76984
2514.44	2.4409
2517.2	2.99475
2519.95	3.84995
2522.71	4.72031
2525.47	4.98525
2528.22	5.77568
2530.98	6.28891
2533.73	6.16299
2536.48	7.50892
2539.23	7.34755
2541.98	7.44138
2544.73	7.08243
2547.48	7.20416
2550.23	6.94222
2552.97	7.19074
2555.72	8.14757
2558.46	8.4713
2561.2	9.06302
2563.95	9.41219
2566.69	8.28425
2569.43	8.40754
2572.17	8.84874
2574.91	8.02654
2577.64	8.92116
2580.38	8.61467
2583.11	8.89542
2585.85	8.59225
2588.58	8.15663
2591.31	9.05224
2594.04	9.18248
2596.78	7.92233
2599.51	6.86682
2602.23	6.13447
2604.96	5.38627
2607.69	5.3715
2610.41	4.1341
2613.14	2.4729
2615.86	2.70495
2618.58	2.85509
2621.3	2.64077
2624.03	1.95247
2626.75	1.43506
2629.46	0.415563
2632.18	-0.737603
2634.9	0.0944048
2637.61	1.10872
2640.33	2.31074
2643.04	2.22733
2645.76	2.59478
2648.47	3.12627
2651.18	4.14478
2653.89	5.12274
2656.6	5.83984
2659.31	6.24848
2662.01	5.57781
2664.72	5.24123
2667.43	5.6557
2670.13	6.1004
2672.83	6.59007
2675.53	6.85235
2678.24	6.32216
2680.94	6.71552
2683.64	7.8304
2686.34	7.97574
2689.03	7.09373
2691.73	7.99517
2694.43	8.51005
2697.12	8.73015
2699.81	9.29257
2702.51	10.1597
2705.2	10.8145
2707.89	12.1511
2710.58	12.0708
2713.27	12.5574
2715.96	13.7369
2718.64	13.6747
2721.33	12.9926
2724.01	13.0379
2726.7	12.2461
2729.38	11.6391
2732.06	11.3154
2734.75	10.3549
2737.43	9.32025
2740.11	8.54558
2742.78	7.9604
2745.46	7.26385
2748.14	5.3406
2750.81	4.84777
2753.49	4.30941
2756.16	3.11009
2758.84	2.80789
2761.51	1.70944
2764.18	1.44029
2766.85	0.386945
2769.52	1.75111
2772.19	1.2843
2774.85	1.26242
2777.52	1.91057
2780.18	1.93478
2782.85	1.84986
2785.51	2.10688
2788.17	2.00199
2790.84	1.69575
2793.5	0.937504
2796.16	0.731883
2798.81	0.315047
2801.47	0.452604
2804.13	0.393491
2806.79	0.716462
2809.44	-0.43306
2812.09	-2.06189
2814.75	-1.54959
2817.4	-0.472282
2820.05	2.25848
2822.7	6.31076
2825.35	11.8289
2828	17.8616
2830.65	24.6216
2833.29	32.6936
2835.94	42.0188
2838.58	50.6074
2841.23	58.7953
2843.87	67.6924
2846.51	75.5295
2849.15	84.5176
2851.79	93.0367
2854.43	101.929
2857.07	111.664
2859.71	121.386
2862.34	129.845
2864.98	137.192
2867.61	142.8
2870.25	147.182
2872.88	149.988
2875.51	151.883
2878.14	156.072
2880.77	159.934
2883.4	163.289
2886.03	166.943
2888.65	169.854
2891.28	171.757
2893.91	174.06
2896.53	176.136
2899.15	177.798
2901.78	180.563
2904.4	182.017
2907.02	185.78
2909.64	191.809
2912.26	198.228
2914.87	206.601
2917.49	214.277
2920.11	222.503
2922.72	228.579
2925.34	232.918
2927.95	236.105
2930.56	238.219
2933.17	238.244
2935.78	236.641
2938.39	233.143
2941	229.982
2943.61	224.795
2946.22	218.046
2948.82	210.004
2951.43	199.523
2954.03	188.084
2956.64	177.929
2959.24	167.075
2961.84	155.501
2964.44	145.868
2967.04	135.599
2969.64	126.765
2972.24	119.216
2974.83	112.6
2977.43	104.066
2980.02	97.1101
2982.62	88.6535
2985.21	81.0088
2987.8	73.7745
2990.4	67.254
2992.99	60.8086
2995.57	53.8441
2998.16	48.051
3000.75	42.8323
3003.34	37.762
3005.92	33.3675
3008.51	27.5193
3011.09	23.2756
3013.68	19.5496
3016.26	15.8422
3018.84	13.55
3021.42	10.997
3024	9.32963
3026.58	8.36756
3029.16	7.42121
3031.73	6.36158
3034.31	6.59228
3036.89	6.50557
3039.46	5.58124
3042.03	6.0727
3044.61	6.40866
3047.18	6.93204
3049.75	7.83965
3052.32	8.30739
3054.89	8.47337
3057.45	8.0821
3060.02	8.04668
3062.59	9.51741
3065.15	8.77897
3067.72	7.73753
3070.28	6.9262
3072.84	6.64459
3075.41	5.85162
3077.97	4.56581
3080.53	3.94605
3083.09	3.13582
3085.64	2.95253
3088.2	2.4096
3090.76	1.38006
3093.31	0.695304
3095.87	0.262463
3098.42	0.66621
3100.97	0.677487
3103.53	1.71664
3106.08	2.61271
3108.63	3.71138
3111.18	4.1489
3113.73	5.68276
3116.27	6.10893
3118.82	7.21374
3121.37	8.75958
3123.91	10.8722
3126.45	12.8173
3129	13.6427
3131.54	14.9938
3134.08	16.1784
3136.62	18.0839
3139.16	18.8358
3141.7	20.4999
3144.24	21.5145
3146.78	22.7135
3149.31	25.7618