File: data/Raman/poly_smoothed/Mb_40_y_04_1x_45s_532 nm_x100_100%_600 gr_mm_01.txt
#Acq. time (s)=	45
#Accumulations=	2
#Range (cm-¹)=	200...3150
#Windows=	2
#Auto scanning=	Off
#Autofocus=	Off
#Macrospot=	Off
#AutoExposure=	Off
#Spike filter=	Multiple accum.
#Delay time (s)=	0
#Binning=	1
#Readout mode=	Signal
#DeNoise=	Off
#ICS correction=	On
#Dark correction=	Off
#Inst. Process=	Off
#Detector Gain=	Best Dynamic Range
#Detector ADC=	20 kHz
#Detector temperature (°C)=	-69.85
#Instrument=	LabRAM HR Evol
#Detector=	Synapse
#Objective=	x100
#Grating=	600 gr/mm
#ND Filter=	100%
#Laser (nm)=	532
#Hole=	100.021
#Range=	Auto
#Laser Pol.=	No
#Raman. Pol.=	No
#Laser Pol. (°)=	-0.0007625
#Raman Pol. (°)=	89.9995
#Collection=	Microscope
#StageXY=	Marzhauser
#StageZ=	Marzhauser
#X (µm)=	-1254.9
#Y (µm)=	2703.8
#Z (µm)=	587.1
#Full time(mm:ss)=	3:18
#Project=
#Sample=
#Site=
#Title=	Mb_40_y_04_2x_45s_532 nm_x100_100%_600 gr_mm
#Remark=
#Date=	18.07.2022 15:23
#Acquired=	18.07.2022 15:23:14
#Base:Fit=	10.08.2022 10:52:48
#Base:Sub=	10.08.2022 10:52:53
#Filter:Polynom=	16.08.2022 10:09:04
#AxisType[0]=Intens
#AxisUnit[0]=Cnt
#AxisType[1]=Spectr
#AxisUnit[1]=1/cm
200.419	52.6578
204.048	48.3183
207.678	42.794
211.304	38.9753
214.928	37.0994
218.554	34.0658
222.176	29.8666
225.798	28.8015
229.417	28.597
233.035	28.4642
236.653	24.7587
240.268	21.8244
243.881	20.8913
247.493	19.3493
251.103	17.6634
254.715	17.6288
258.322	15.0319
261.929	14.6944
265.534	14.8909
269.137	14.4923
272.739	13.3519
276.34	12.5269
279.939	11.2417
283.537	11.4335
287.134	11.8554
290.729	11.8753
294.323	10.1486
297.913	11.9813
301.504	13.5181
305.093	13.5263
308.682	13.7559
312.268	15.5137
315.852	17.1138
319.436	18.2518
323.018	17.3397
326.597	16.6956
330.177	17.0501
333.753	17.4931
337.331	15.835
340.906	15.3086
344.478	13.6645
348.051	13.2607
351.621	10.9691
355.189	10.3895
358.757	9.59091
362.323	8.9591
365.889	9.31657
369.451	8.45702
373.012	9.9677
376.574	9.65937
380.133	9.96988
383.69	9.59572
387.245	11.5072
390.8	11.9702
394.353	11.9602
397.906	14.0675
401.456	14.5657
405.005	16.135
408.552	15.7444
412.099	15.1023
415.643	16.2234
419.187	15.0855
422.728	12.4173
426.269	11.9003
429.806	10.3712
433.344	8.13791
436.881	6.23341
440.416	5.69027
443.949	6.80088
447.48	6.56541
451.011	5.75092
454.541	4.52451
458.069	4.0084
461.594	4.12455
465.119	4.10481
468.642	2.82691
472.165	1.88619
475.684	2.95058
479.204	3.9536
482.721	5.28196
486.239	7.4101
489.753	9.68376
493.268	11.2163
496.779	14.5578
500.289	17.2243
503.8	18.57
507.307	20.2826
510.813	21.2519
514.32	22.3874
517.823	23.8952
521.325	26.0666
524.826	27.5272
528.325	26.3516
531.823	25.5488
535.32	23.8687
538.815	22.6647
542.309	20.8896
545.802	19.949
549.293	17.5665
552.783	15.8784
556.271	13.1863
559.759	10.8656
563.245	9.80193
566.729	7.97452
570.213	8.3975
573.693	7.28191
577.173	6.90795
580.652	5.41819
584.13	4.13353
587.605	2.24695
591.08	2.53311
594.552	1.92079
598.025	1.87244
601.496	2.47582
604.964	3.2486
608.433	2.10237
611.898	2.59825
615.364	2.1668
618.827	3.45019
622.288	3.42222
625.75	5.41467
629.209	6.23119
632.667	7.42649
636.125	7.68422
639.58	9.50767
643.033	9.63161
646.485	10.5542
649.936	11.7022
653.388	13.0956
656.836	13.8026
660.283	12.5531
663.728	13.9102
667.173	14.7779
670.616	16.967
674.057	19.2553
677.498	20.5
680.937	23.1605
684.375	25.076
687.809	27.9858
691.244	29.2907
694.678	32.6654
698.111	35.9763
701.54	37.1448
704.97	40.7326
708.398	42.595
711.826	45.1294
715.25	46.5882
718.675	48.1968
722.096	47.8359
725.518	46.7392
728.937	46.7732
732.357	45.5573
735.773	44.1656
739.19	43.9991
742.604	43.1889
746.018	44.5364
749.429	45.9525
752.839	46.3974
756.248	49.2575
759.657	51.9007
763.063	53.4792
766.468	56.6512
769.871	60.5528
773.273	62.8909
776.676	65.5586
780.075	69.2796
783.474	72.2409
786.871	74.3573
790.266	76.4976
793.661	77.4865
797.054	77.4705
800.446	77.4853
803.834	76.4098
807.224	75.2738
810.612	73.9266
813.998	72.3997
817.384	71.625
820.766	70.1906
824.149	70.1293
827.531	69.8183
830.909	67.3928
834.288	67.4212
837.666	66.0382
841.041	64.5798
844.416	62.4125
847.788	60.432
851.161	59.8808
854.53	57.3324
857.901	56.5994
861.268	54.8949
864.633	52.4794
868	51.359
871.363	49.9722
874.725	48.4478
878.088	48.2278
881.447	46.1226
884.805	45.7205
888.162	46.8168
891.518	46.1625
894.872	45.2463
898.225	45.0932
901.577	45.522
904.928	46.2518
908.277	45.5954
911.625	45.6672
914.972	45.3756
918.318	45.5423
921.662	44.0221
925.005	43.5598
928.347	42.5271
931.686	43.2227
935.025	42.1275
938.363	42.529
941.698	41.8832
945.034	39.5896
948.368	39.4898
951.699	40.1092
955.031	40.228
958.36	39.2779
961.689	38.3753
965.016	37.7787
968.343	37.5284
971.666	36.9598
974.991	35.5537
978.312	34.8678
981.632	33.8252
984.953	32.7206
988.27	32.5248
991.587	30.3871
994.902	27.7671
998.216	24.2682
1001.53	18.765
1004.84	16.0659
1008.15	19.5722
1011.46	31.695
1014.77	49.0267
1018.07	66.3425
1021.38	85.7219
1024.68	102.928
1027.99	119.633
1031.29	134.709
1034.59	146.378
1037.89	154.972
1041.18	160.805
1044.48	166.057
1047.77	166.312
1051.07	162.759
1054.36	155.561
1057.65	146.366
1060.94	134.041
1064.23	119.702
1067.52	102.239
1070.8	83.5041
1074.09	62.5996
1077.37	43.7109
1080.65	27.3007
1083.93	14.0487
1087.21	10.0887
1090.49	12.3546
1093.77	15.8939
1097.04	18.6262
1100.32	20.8302
1103.59	23.5616
1106.86	25.0126
1110.13	24.7612
1113.4	25.9383
1116.67	26.0286
1119.94	26.5131
1123.2	26.0017
1126.47	25.2608
1129.73	24.6664
1132.99	21.66
1136.25	19.9217
1139.51	17.9561
1142.77	15.6141
1146.03	13.0529
1149.28	9.60296
1152.54	8.0588
1155.79	7.14013
1159.04	4.39256
1162.29	4.15642
1165.54	2.95872
1168.79	2.4645
1172.04	4.29371
1175.28	4.33171
1178.53	5.99846
1181.77	6.71137
1185.01	7.01752
1188.25	7.24668
1191.49	8.4244
1194.73	7.80963
1197.96	7.79478
1201.2	9.21695
1204.43	9.95093
1207.66	13.0439
1210.9	16.7707
1214.13	19.183
1217.36	21.8832
1220.58	24.5332
1223.81	26.1602
1227.04	27.575
1230.26	31.0382
1233.48	34.3908
1236.71	36.6932
1239.93	41.3352
1243.14	44.7825
1246.36	48.1624
1249.58	49.7517
1252.8	51.3822
1256.01	54.273
1259.22	56.5282
1262.43	60.2012
1265.64	61.9062
1268.85	62.733
1272.06	62.9603
1275.27	65.3554
1278.48	68.6249
1281.68	72.87
1284.88	76.8711
1288.08	81.513
1291.28	83.1435
1294.48	84.8376
1297.68	86.2952
1300.88	84.6482
1304.07	85.8894
1307.27	85.9984
1310.46	85.5636
1313.65	83.979
1316.85	82.2168
1320.03	82.2516
1323.22	80.1193
1326.41	76.7266
1329.6	75.3854
1332.78	73.7759
1335.96	72.7128
1339.15	70.159
1342.33	67.9347
1345.51	63.518
1348.69	61.1882
1351.86	58.8552
1355.04	58.3952
1358.21	56.8848
1361.39	53.7972
1364.56	53.0566
1367.73	50.3552
1370.9	47.5574
1374.07	46.038
1377.24	43.4498
1380.41	43.7403
1383.57	43.0455
1386.73	42.8636
1389.9	43.3894
1393.06	42.8706
1396.22	43.4644
1399.38	43.7095
1402.54	44.8099
1405.69	47.2848
1408.85	49.849
1412	52.0008
1415.16	55.2316
1418.31	60.6854
1421.46	64.4564
1424.61	68.7086
1427.76	73.0908
1430.9	77.1804
1434.05	82.1183
1437.2	84.2952
1440.34	87.5968
1443.48	88.7566
1446.62	89.4413
1449.76	89.6235
1452.9	88.6619
1456.04	86.5174
1459.17	84.5194
1462.31	79.7474
1465.44	74.8748
1468.58	69.3892
1471.71	64.4745
1474.84	59.0626
1477.97	53.1696
1481.1	49.2581
1484.22	44.0371
1487.35	39.6757
1490.47	35.949
1493.59	33.8689
1496.72	30.9183
1499.84	28.1274
1502.96	26.5783
1506.08	26.0755
1509.19	24.8702
1512.31	23.3473
1515.42	22.2701
1518.54	21.1126
1521.65	20.0638
1524.76	21.142
1527.87	21.5612
1530.98	21.6466
1534.09	23.1171
1537.2	25.3155
1540.3	26.8265
1543.41	28.955
1546.51	31.2382
1549.61	33.8213
1552.71	33.9825
1555.81	36.4078
1558.91	38.4968
1562.01	38.9929
1565.1	39.4104
1568.2	41.195
1571.29	43.3454
1574.38	45.3267
1577.48	47.3147
1580.57	49.2863
1583.65	49.7025
1586.74	49.9505
1589.83	51.8746
1592.92	53.1605
1596	53.3772
1599.08	53.1023
1602.16	54.6425
1605.24	52.9972
1608.32	54.2052
1611.4	55.0663
1614.48	56.2932
1617.56	56.299
1620.63	57.4976
1623.71	58.7792
1626.78	58.6784
1629.85	60.2046
1632.92	62.8498
1635.99	63.9767
1639.06	65.0563
1642.12	68.0318
1645.19	71.5718
1648.25	73.3677
1651.32	74.8599
1654.38	76.9334
1657.44	76.4652
1660.5	77.0299
1663.56	77.2502
1666.62	74.8949
1669.67	71.0418
1672.73	68.0306
1675.79	64.1401
1678.84	59.7446
1681.89	53.7212
1684.94	48.9805
1687.99	43.87
1691.04	39.8896
1694.08	33.9106
1697.13	29.3751
1700.18	23.8343
1703.22	19.7901
1706.26	16.0389
1709.3	13.5696
1712.35	10.7374
1715.39	8.36132
1718.42	7.17746
1721.46	4.89751
1724.5	5.41633
1727.53	4.53609
1730.56	4.17121
1733.6	5.00374
1736.63	5.44607
1739.66	5.77173
1742.69	6.37612
1745.71	6.7831
1748.74	7.26967
1751.77	5.77431
1754.79	5.15938
1757.81	5.39971
1760.84	5.62627
1763.86	5.26305
1766.88	4.35685
1769.9	3.34715
1772.91	2.14325
1775.93	1.38324
1778.95	1.81236
1781.96	1.75056
1784.97	1.68529
1787.99	0.319674
1791	-0.528201
1794.01	-0.165598
1797.01	0.368751
1800.02	1.23578
1803.03	0.819802
1806.03	1.80763
1809.04	2.02406
1812.04	1.41417
1815.04	2.04538
1818.04	1.58603
1821.04	0.584905
1824.04	1.02306
1827.04	0.0646196
1830.03	0.932485
1833.03	0.919513
1836.02	0.351667
1839.02	0.504151
1842.01	0.209452
1845	0.206802
1847.99	0.635459
1850.98	0.883866
1853.96	1.05043
1856.95	1.01108
1859.94	0.43747
1862.92	0.147421
1865.9	1.87724
1868.88	2.00518
1871.86	2.31614
1874.84	2.85128
1877.82	4.39679
1880.8	4.09234
1882.58	3.50665
1885.57	3.34159
1888.56	3.28875
1891.54	2.95427
1894.53	3.27251
1897.51	4.11778
1900.5	4.0406
1903.48	4.03372
1906.46	4.74172
1909.44	4.60674
1912.42	5.27125
1915.4	4.04874
1918.37	4.09284
1921.35	4.56587
1924.32	4.27413
1927.3	4.35969
1930.27	3.56831
1933.24	3.74539
1936.21	3.79371
1939.18	3.96974
1942.15	3.68096
1945.11	3.64153
1948.08	4.34619
1951.04	4.03168
1954.01	3.25869
1956.97	3.32824
1959.93	3.11717
1962.89	3.10626
1965.85	4.32982
1968.81	4.88917
1971.77	5.60597
1974.72	5.46388
1977.68	6.51371
1980.63	7.29336
1983.58	6.20248
1986.53	5.47945
1989.48	5.5047
1992.43	5.85302
1995.38	5.14584
1998.33	5.21948
2001.27	4.29755
2004.22	5.23108
2007.16	5.18743
2010.11	5.06878
2013.05	5.01308
2015.99	5.19234
2018.93	5.17884
2021.87	5.8684
2024.8	6.51647
2027.74	6.84552
2030.68	7.3707
2033.61	8.40432
2036.54	9.60735
2039.48	10.6009
2042.41	11.596
2045.34	12.97
2048.27	13.475
2051.19	13.6724
2054.12	13.5114
2057.05	13.526
2059.97	14.9857
2062.9	16.2233
2065.82	16.8496
2068.74	16.7078
2071.66	17.7557
2074.58	18.8553
2077.5	20.3593
2080.41	22.0616
2083.33	22.7981
2086.24	24.6642
2089.16	26.0494
2092.07	28.6581
2094.98	30.6594
2097.89	32.34
2100.8	34.1104
2103.71	36.0696
2106.62	37.8328
2109.53	40.1661
2112.43	42.4018
2115.33	45.1192
2118.24	46.3383
2121.14	48.0163
2124.04	51.3729
2126.94	54.4729
2129.84	58.3694
2132.74	61.7684
2135.63	66.3551
2138.53	69.5406
2141.43	72.6477
2144.32	77.7393
2147.21	81.9104
2150.1	86.184
2152.99	89.1209
2155.88	92.828
2158.77	96.4955
2161.66	99.9633
2164.55	102.616
2167.43	103.017
2170.31	102.693
2173.2	102.596
2176.08	101.612
2178.96	101.499
2181.84	101.108
2184.72	98.1186
2187.6	96.108
2190.47	91.9454
2193.35	89.3927
2196.23	85.678
2199.1	81.9165
2201.97	78.5785
2204.84	75.1569
2207.71	71.4047
2210.58	67.6833
2213.45	63.5678
2216.32	60.1736
2219.19	57.0767
2222.05	54.3401
2224.92	52.1287
2227.78	49.5678
2230.64	47.4427
2233.5	44.0691
2236.36	40.6971
2239.22	37.4702
2242.08	35.496
2244.94	33.2874
2247.79	31.7432
2250.65	29.8053
2253.5	28.1051
2256.36	26.6239
2259.21	24.6933
2262.06	22.3833
2264.91	20.7534
2267.76	19.4092
2270.6	18.3683
2273.45	17.8144
2276.3	16.0261
2279.14	15.5323
2281.98	13.6485
2284.83	13.7804
2287.67	13.3869
2290.51	13.4865
2293.35	12.573
2296.19	9.88057
2299.02	10.1785
2301.86	10.427
2304.7	10.2231
2307.53	9.78839
2310.36	9.56073
2313.2	10.0456
2316.03	9.90553
2318.86	10.6546
2321.69	11.1256
2324.51	11.1463
2327.34	11.3113
2330.17	9.91648
2332.99	8.69842
2335.82	7.57173
2338.64	6.35773
2341.46	5.79482
2344.28	4.58386
2347.1	3.2331
2349.92	3.59777
2352.74	3.27294
2355.56	2.4128
2358.37	1.59939
2361.19	1.37793
2364	1.40352
2366.82	1.84024
2369.63	2.11479
2372.44	2.01658
2375.25	3.12155
2378.06	3.48539
2380.86	3.88107
2383.67	4.70174
2386.48	5.02578
2389.28	5.09577
2392.09	4.48543
2394.89	4.37008
2397.69	4.70909
2400.49	4.58703
2403.29	3.97186
2406.09	3.84064
2408.89	4.7134
2411.69	4.99536
2414.48	4.36401
2417.28	6.18876
2420.07	6.6449
2422.86	5.72938
2425.65	6.42368
2428.45	7.37563
2431.23	7.89354
2434.02	8.15336
2436.81	7.58054
2439.6	7.45111
2442.38	8.23022
2445.17	7.85973
2447.95	6.6304
2450.73	6.3902
2453.52	5.42438
2456.3	4.89371
2459.08	4.46076
2461.85	3.9773
2464.63	3.43039
2467.41	2.54316
2470.19	1.50234
2472.96	1.49022
2475.73	0.950396
2478.51	1.08836
2481.28	0.574204
2484.05	0.910626
2486.82	1.20628
2489.59	0.873531
2492.35	1.16861
2495.12	2.19412
2497.89	2.30067
2500.65	2.39381
2503.42	1.964
2506.18	1.80199
2508.94	1.9487
2511.7	3.01566
2514.46	3.34185
2517.22	3.70157
2519.98	3.5113
2522.73	4.54819
2525.49	4.46649
2528.25	4.29608
2531	4.58431
2533.75	5.15813
2536.5	5.23677
2539.25	5.58563
2542.01	5.8821
2544.75	5.93798
2547.5	6.31972
2550.25	6.33043
2553	6.32508
2555.74	5.6347
2558.49	5.22794
2561.23	5.42055
2563.97	5.95899
2566.71	4.79916
2569.45	4.67899
2572.19	3.97423
2574.93	4.57143
2577.67	4.18595
2580.4	5.00855
2583.14	4.90419
2585.87	4.18916
2588.6	4.05081
2591.34	4.22733
2594.07	4.28361
2596.8	5.23087
2599.53	5.36683
2602.26	4.86443
2604.98	3.80438
2607.71	4.06426
2610.44	3.7838
2613.16	3.52571
2615.88	2.98051
2618.61	2.33259
2621.33	2.17825
2624.05	1.87579
2626.77	2.07999
2629.49	1.89823
2632.21	1.32908
2634.92	0.980143
2637.64	1.91485
2640.35	2.23032
2643.07	3.39214
2645.78	3.47673
2648.49	4.23928
2651.2	3.80477
2653.91	4.06522
2656.62	5.07467
2659.33	6.15956
2662.04	6.73012
2664.74	6.66727
2667.45	5.81135
2670.15	5.27566
2672.86	5.24245
2675.56	4.42354
2678.26	4.03805
2680.96	4.04891
2683.66	4.32595
2686.36	3.89359
2689.06	4.43909
2691.75	3.61098
2694.45	3.56381
2697.14	3.04697
2699.84	3.02986
2702.53	4.03452
2705.22	3.5356
2707.91	3.76764
2710.6	3.4584
2713.29	3.8742
2715.98	4.24015
2718.67	4.74357
2721.35	5.55427
2724.04	6.15979
2726.72	6.66464
2729.4	6.49403
2732.09	6.4478
2734.77	6.67743
2737.45	5.82867
2740.13	5.92433
2742.81	6.01807
2745.48	6.5027
2748.16	7.04396
2750.84	6.74635
2753.51	6.18936
2756.19	5.60403
2758.86	5.85661
2761.53	5.37832
2764.2	4.98465
2766.87	4.47045
2769.54	3.70852
2772.21	3.0216
2774.88	2.88145
2777.54	2.8004
2780.21	2.05346
2782.87	1.89153
2785.53	1.84209
2788.2	1.73849
2790.86	0.797605
2793.52	0.898044
2796.18	-0.437153
2798.84	-0.194484
2801.49	-1.46268
2804.15	-1.23739
2806.81	-1.28878
2809.46	-2.06017
2812.12	-1.97448
2814.77	-2.67092
2817.42	-2.14135
2820.07	0.363006
2822.72	4.17557
2825.37	8.03838
2828.02	12.2995
2830.67	18.1595
2833.31	22.4738
2835.96	28.4288
2838.61	34.7112
2841.25	41.5037
2843.89	48.0451
2846.53	56.2148
2849.17	63.9271
2851.81	71.402
2854.45	79.6568
2857.09	87.4729
2859.73	94.3758
2862.36	101.238
2865	107.705
2867.64	112.754
2870.27	116.6
2872.9	120.508
2875.53	123.781
2878.16	126.334
2880.79	129.283
2883.42	133.154
2886.05	136.974
2888.68	140.77
2891.3	143.537
2893.93	147.181
2896.55	150.459
2899.18	153.147
2901.8	158.274
2904.42	163.786
2907.04	170.212
2909.66	177.862
2912.28	185.007
2914.9	192.909
2917.51	201.198
2920.13	207.669
2922.74	213.298
2925.36	217.575
2927.97	221.371
2930.59	223.122
2933.2	223.718
2935.81	223.997
2938.42	221.848
2941.02	218.297
2943.63	214.586
2946.24	208.178
2948.85	201.707
2951.45	193.972
2954.05	186.089
2956.66	177.782
2959.26	168.544
2961.86	158.124
2964.46	149.26
2967.06	140.831
2969.66	133.372
2972.26	125.194
2974.85	116.105
2977.45	107.79
2980.05	99.1357
2982.64	90.8483
2985.23	83.5405
2987.83	75.9219
2990.42	67.9861
2993.01	60.8848
2995.6	54.1815
2998.19	48.003
3000.77	42.1297
3003.36	36.3934
3005.95	31.8773
3008.53	26.8647
3011.12	21.7192
3013.7	17.9773
3016.28	14.7901
3018.86	12.6811
3021.44	9.75446
3024.02	8.45863
3026.6	6.75152
3029.18	5.42453
3031.76	5.65727
3034.33	4.94684
3036.91	4.45273
3039.48	3.93981
3042.05	4.6065
3044.63	5.19949
3047.2	5.8049
3049.77	6.82733
3052.34	6.35379
3054.91	6.16761
3057.48	6.74454
3060.04	6.82438
3062.61	6.95218
3065.17	5.96581
3067.74	5.6394
3070.3	4.21097
3072.87	3.32946
3075.43	2.58185
3077.99	2.79441
3080.55	1.77207
3083.11	2.42342
3085.67	1.54594
3088.22	1.55689
3090.78	0.341035
3093.34	1.16098
3095.89	1.6304
3098.44	1.04525
3101	0.424075
3103.55	0.446911
3106.1	-0.318552
3108.65	-0.0988324
3111.2	0.159969
3113.75	0.243387
3116.3	0.171997
3118.84	1.30582
3121.39	2.36561
3123.93	2.8055
3126.48	4.34587
3129.02	4.68122
3131.56	5.94797
3134.1	7.05268
3136.64	9.68224
3139.18	12.3124
3141.72	15.3534
3144.26	18.7439
3146.8	22.0963
3149.33	27.0264