File: data/Raman/poly_smoothed/Mb_40_24_01_1x_45s_532 nm_x100_100%_600 gr_mm_01.txt
#Acq. time (s)=	45
#Accumulations=	2
#Range (cm-¹)=	200...3150
#Windows=	2
#Auto scanning=	Off
#Autofocus=	Off
#Macrospot=	Off
#AutoExposure=	Off
#Spike filter=	Multiple accum.
#Delay time (s)=	0
#Binning=	1
#Readout mode=	Signal
#DeNoise=	Off
#ICS correction=	On
#Dark correction=	Off
#Inst. Process=	Off
#Detector Gain=	Best Dynamic Range
#Detector ADC=	20 kHz
#Detector temperature (°C)=	-70.08
#Instrument=	LabRAM HR Evol
#Detector=	Synapse
#Objective=	x100
#Grating=	600 gr/mm
#ND Filter=	100%
#Laser (nm)=	532
#Hole=	100.021
#Range=	Auto
#Laser Pol.=	No
#Raman. Pol.=	No
#Laser Pol. (°)=	-0.0007625
#Raman Pol. (°)=	89.9995
#Collection=	Microscope
#StageXY=	Marzhauser
#StageZ=	Marzhauser
#X (µm)=	-2476.2
#Y (µm)=	-37.2
#Z (µm)=	-9.9
#Full time(mm:ss)=	3:19
#Project=
#Sample=
#Site=
#Title=	Mb_40_24_01_2x_45s_532 nm_x100_100%_600 gr_mm
#Remark=
#Date=	14.07.2022 10:37
#Acquired=	14.07.2022 10:37:11
#Edit:Spike=	14.07.2022 10:38:50
#Base:Fit=	10.08.2022 10:47:00
#Base:Sub=	10.08.2022 10:47:12
#Filter:Polynom=	16.08.2022 10:11:48
#AxisType[0]=Intens
#AxisUnit[0]=Cnt
#AxisType[1]=Spectr
#AxisUnit[1]=1/cm
200.554	21.0968
204.183	18.9102
207.813	18.1624
211.439	16.8497
215.065	14.8245
218.688	11.1877
222.312	10.5196
225.933	8.54937
229.552	5.5475
233.171	5.11677
236.787	5.8348
240.402	6.49259
244.015	6.94564
247.627	7.15836
251.24	7.40755
254.849	7.1748
258.457	8.67051
262.063	10.0508
265.668	13.3573
269.271	13.5343
272.873	13.4828
276.474	15.3467
280.073	15.6822
283.671	15.7516
287.268	15.2796
290.863	13.5883
294.456	13.5697
298.049	12.8397
301.637	12.4331
305.227	10.5722
308.815	8.51086
312.402	5.69028
315.987	3.12526
319.569	4.30419
323.151	6.54465
326.733	7.53856
330.31	8.85071
333.889	8.27871
337.464	8.9859
341.039	9.87097
344.611	11.058
348.184	11.9479
351.754	13.1769
355.324	11.4446
358.89	11.6718
362.455	9.74579
366.021	10.258
369.584	9.53698
373.145	7.65035
376.707	6.91267
380.265	7.92365
383.822	6.09434
387.378	5.34811
390.934	4.0308
394.487	2.49204
398.038	2.62282
401.588	4.20728
405.137	7.47266
408.685	8.48269
412.23	10.3582
415.775	11.5191
419.318	10.8113
422.86	11.0705
426.401	10.2236
429.94	11.6831
433.478	10.6627
437.012	10.5006
440.547	9.64052
444.081	8.97003
447.613	9.23233
451.142	7.58883
454.672	9.0981
458.2	7.07729
461.725	6.947
465.251	6.89221
468.775	5.72377
472.296	6.77398
475.817	8.10484
479.335	8.70578
482.854	10.1957
486.37	12.3437
489.886	14.8906
493.398	14.8793
496.91	16.1213
500.422	17.8075
503.93	16.2215
507.438	17.5398
510.946	16.596
514.45	17.5345
517.954	19.11
521.456	18.6593
524.956	18.6758
528.456	19.2729
531.956	18.997
535.452	18.811
538.947	19.8958
542.441	21.5002
545.934	21.5267
549.425	21.9905
552.915	21.9112
556.403	20.6595
559.889	20.0347
563.375	20.7483
566.859	22.4488
570.342	20.3888
573.824	18.5071
577.303	17.1963
580.782	16.8401
584.26	15.3944
587.734	12.5804
591.21	11.2414
594.684	9.11188
598.154	7.25969
601.626	5.34294
605.094	5.13672
608.562	3.24943
612.027	5.44209
615.493	3.50759
618.956	2.57551
622.419	3.26666
625.879	4.76836
629.338	5.2691
632.797	6.92577
636.254	7.7173
639.708	9.57215
643.162	9.02349
646.614	11.6873
650.067	12.4408
653.516	14.0483
656.964	15.5822
660.411	19.3094
663.857	21.0441
667.301	21.4091
670.744	20.8887
674.186	21.1318
677.626	21.1516
681.065	22.8269
684.503	23.5801
687.939	24.516
691.372	25.998
694.806	26.2549
698.239	25.5672
701.67	25.1306
705.098	26.212
708.526	28.3322
711.954	31.1677
715.378	31.0529
718.802	31.1042
722.226	32.205
725.646	31.0004
729.067	30.4018
732.484	32.2934
735.902	34.576
739.317	37.5051
742.731	38.4796
746.145	37.9706
749.556	39.8318
752.966	41.1455
756.377	45.2756
759.784	49.3699
763.19	52.6476
766.594	55.8293
770	59.4671
773.402	63.1812
776.803	65.6061
780.202	66.856
783.6	70.4152
786.997	73.3135
790.393	74.9277
793.787	75.1523
797.18	76.5361
800.572	74.854
803.963	75.213
807.35	72.7779
810.738	70.7291
814.125	69.9767
817.51	67.2421
820.894	66.234
824.275	65.3113
827.657	63.0248
831.037	61.6585
834.414	62.4263
837.792	62.2935
841.167	62.5743
844.542	62.1999
847.914	60.7908
851.287	60.8737
854.656	58.0799
858.026	58.5599
861.393	54.4739
864.761	52.6098
868.125	50.8474
871.489	49.5083
874.85	48.2923
878.213	47.7814
881.572	46.8893
884.931	43.8132
888.287	42.8083
891.643	42.8292
894.997	42.1552
898.352	41.5108
901.704	41.3642
905.055	40.6805
908.404	42.4064
911.75	43.3755
915.097	45.0204
918.443	44.598
921.787	43.3738
925.13	40.8778
928.472	41.9619
931.813	40.8098
935.15	39.0006
938.488	37.4115
941.825	35.5819
945.158	35.4828
948.493	34.1153
951.824	35.1976
955.156	35.8351
958.486	34.0715
961.814	31.7322
965.142	30.5562
968.467	30.5837
971.79	28.9573
975.115	27.9951
978.436	26.2472
981.756	25.8899
985.077	24.0104
988.394	24.2126
991.71	24.2201
995.025	22.7274
998.341	19.613
1001.65	17.225
1004.97	15.9777
1008.28	18.0385
1011.58	17.4369
1014.89	18.4
1018.2	19.7729
1021.5	21.8491
1024.81	24.6727
1028.11	26.3736
1031.41	26.5924
1034.71	27.8659
1038.01	26.352
1041.31	25.328
1044.6	25.7526
1047.9	26.5607
1051.19	26.1088
1054.48	25.6817
1057.77	24.3088
1061.06	24.898
1064.35	23.9182
1067.64	22.33
1070.93	20.3441
1074.21	18.8746
1077.49	17.5201
1080.78	15.5966
1084.06	16.0916
1087.34	17.9271
1090.61	18.4179
1093.89	18.5822
1097.17	20.182
1100.44	19.3611
1103.71	18.7703
1106.99	19.4352
1110.26	18.8644
1113.52	16.9005
1116.79	18.2643
1120.06	19.0367
1123.32	18.4656
1126.59	18.565
1129.85	19.4015
1133.11	18.138
1136.37	18.041
1139.63	16.6386
1142.89	15.3931
1146.15	13.5457
1149.4	9.99585
1152.66	8.71664
1155.91	8.65692
1159.16	8.32505
1162.41	8.80679
1165.66	8.1007
1168.91	7.04938
1172.16	5.38533
1175.4	4.84702
1178.65	3.61455
1181.89	2.23908
1185.13	1.25968
1188.37	2.65889
1191.61	1.184
1194.85	0.585717
1198.08	3.252
1201.32	3.42055
1204.55	3.14453
1207.79	3.50085
1211.02	4.12371
1214.25	5.06331
1217.48	7.27173
1220.71	8.89167
1223.93	11.8909
1227.16	12.2666
1230.38	14.3439
1233.6	16.7289
1236.83	20.9205
1240.05	22.9905
1243.26	24.8329
1246.48	27.1688
1249.7	30.1438
1252.92	31.2273
1256.13	33.5312
1259.34	34.2407
1262.55	34.0266
1265.76	34.6284
1268.97	36.5395
1272.18	38.2199
1275.39	41.6584
1278.59	42.7612
1281.8	44.7373
1285	46.8423
1288.2	50.9589
1291.4	54.6754
1294.6	58.4396
1297.8	61.0295
1301	63.5126
1304.19	65.4217
1307.39	67.019
1310.58	68.2158
1313.77	69.6145
1316.96	69.2347
1320.15	69.2153
1323.34	68.8976
1326.53	69.9809
1329.72	66.363
1332.9	64.3095
1336.08	60.26
1339.27	58.2224
1342.45	56.1544
1345.63	55.2878
1348.8	55.5299
1351.98	55.2128
1355.16	52.0326
1358.33	53.0779
1361.51	54.1232
1364.68	53.2458
1367.85	52.1088
1371.02	52.2071
1374.19	51.5002
1377.36	51.1815
1380.52	51.0388
1383.69	49.628
1386.85	49.93
1390.02	50.4757
1393.18	51.5651
1396.34	50.4089
1399.5	52.382
1402.65	54.5833
1405.81	54.5623
1408.97	54.347
1412.12	57.2204
1415.27	58.1894
1418.43	61.1413
1421.58	63.8516
1424.73	67.3013
1427.87	71.1556
1431.02	75.4019
1434.17	80.2423
1437.31	82.7819
1440.46	83.7908
1443.6	86.3562
1446.74	87.0884
1449.88	88.7529
1453.02	88.6175
1456.16	87.2006
1459.29	83.6291
1462.43	82.0326
1465.56	80.9259
1468.69	77.5724
1471.83	73.0734
1474.95	67.3322
1478.08	63.0968
1481.21	58.3355
1484.34	51.8298
1487.47	45.7685
1490.59	40.4339
1493.71	37.039
1496.84	32.5287
1499.96	32.376
1503.07	31.0164
1506.19	29.3226
1509.31	26.5062
1512.43	25.2535
1515.54	22.7343
1518.65	20.9739
1521.77	20.8145
1524.88	21.2314
1527.99	20.4226
1531.1	19.9083
1534.21	19.8984
1537.31	22.9208
1540.42	25.8651
1543.52	25.9912
1546.63	28.8483
1549.73	33.1288
1552.83	35.8999
1555.93	38.635
1559.03	41.6608
1562.12	45.6349
1565.22	47.7264
1568.31	52.328
1571.41	55.6887
1574.5	57.8251
1577.59	61.2333
1580.68	61.8628
1583.77	62.8254
1586.86	63.7354
1589.95	63.7338
1593.03	64.4467
1596.11	63.9856
1599.2	64.6715
1602.28	64.2943
1605.36	61.083
1608.44	59.0908
1611.52	58.8289
1614.6	58.805
1617.67	57.7328
1620.75	57.2759
1623.82	58.0115
1626.89	58.198
1629.96	57.5415
1633.04	58.126
1636.11	57.5395
1639.17	57.9314
1642.24	57.7219
1645.31	57.9248
1648.37	56.3269
1651.43	56.807
1654.5	56.8067
1657.56	56.8017
1660.62	56.1287
1663.67	54.442
1666.73	55.0246
1669.79	54.1569
1672.84	52.0071
1675.9	49.3688
1678.95	46.6561
1682	46.0247
1685.05	44.5767
1688.1	44.2172
1691.15	39.9393
1694.2	38.2174
1697.25	34.8825
1700.29	32.1538
1703.33	29.7735
1706.38	27.6591
1709.42	24.9986
1712.46	24.2116
1715.5	23.156
1718.54	20.8082
1721.57	19.3655
1724.61	17.3039
1727.64	15.3595
1730.68	14.5294
1733.71	12.9027
1736.74	10.0041
1739.77	9.78965
1742.8	7.89524
1745.83	5.71049
1748.85	4.81952
1751.88	4.83744
1754.91	3.45015
1757.93	3.63903
1760.95	1.2707
1763.97	0.295018
1766.99	-0.381057
1770.01	-1.28638
1773.03	-2.10558
1776.04	0.720455
1779.06	2.86794
1782.07	4.08548
1785.09	4.29827
1788.1	5.46928
1791.11	5.17135
1794.12	4.3153
1797.13	5.17115
1800.13	5.29114
1803.14	5.23045
1806.15	5.99692
1809.15	6.05252
1812.15	5.45073
1815.16	6.86938
1818.15	5.94547
1821.16	6.45298
1824.15	5.58069
1827.15	5.65504
1830.15	5.2365
1833.14	4.70168
1836.14	4.76176
1839.13	5.56664
1842.12	4.46663
1845.11	3.75521
1848.1	4.03575
1851.09	4.74955
1854.08	4.78559
1857.06	2.85323
1860.05	0.612161
1863.03	0.511429
1866.01	2.00038
1869	3.94357
1871.98	5.41207
1874.96	7.38754
1877.93	8.96609
1880.91	11.2998
1882.47	11.1646
1885.46	11.9786
1888.44	12.387
1891.43	13.7805
1894.42	15.3909
1897.4	14.3417
1900.39	14.6392
1903.37	14.9999
1906.35	15.1488
1909.33	14.1112
1912.31	12.464
1915.29	9.13387
1918.26	8.41196
1921.24	7.89482
1924.21	7.50846
1927.19	5.61734
1930.16	4.77109
1933.13	4.25538
1936.1	7.57127
1939.07	8.93243
1942.04	9.37153
1945	10.2322
1947.97	10.3365
1950.93	10.8816
1953.9	9.98551
1956.86	9.44809
1959.82	8.9139
1962.78	10.6758
1965.74	12.2206
1968.7	11.8096
1971.65	10.6343
1974.61	11.6418
1977.57	11.4023
1980.52	11.5085
1983.47	10.4052
1986.42	10.0892
1989.37	10.7133
1992.32	9.97511
1995.27	11.1305
1998.22	9.8037
2001.17	9.64966
2004.11	10.495
2007.05	11.1665
2010	11.7297
2012.94	10.6696
2015.88	11.4685
2018.82	10.6354
2021.76	11.2336
2024.7	13.1012
2027.63	13.4833
2030.57	14.992
2033.5	16.7627
2036.44	17.5594
2039.37	16.9658
2042.3	15.4719
2045.23	17.9071
2048.16	18.927
2051.08	19.5558
2054.01	19.6522
2056.94	19.1017
2059.86	21.1671
2062.79	20.6822
2065.71	22.3054
2068.63	22.9654
2071.55	23.0385
2074.47	23.3065
2077.39	21.4465
2080.31	20.5304
2083.22	19.4116
2086.13	19.354
2089.05	21.8029
2091.96	22.2006
2094.87	23.382
2097.78	22.7896
2100.69	24.0104
2103.6	22.9139
2106.51	24.3316
2109.42	23.8468
2112.32	24.8366
2115.23	26.0415
2118.13	27.7625
2121.03	29.6386
2123.93	32.2557
2126.83	34.3077
2129.73	37.0921
2132.63	40.4449
2135.53	43.4143
2138.42	45.9165
2141.32	47.4858
2144.21	48.5379
2147.1	49.013
2150	51.0951
2152.89	53.3698
2155.78	53.7077
2158.66	57.0603
2161.55	58.8794
2164.44	58.043
2167.32	58.919
2170.21	59.7587
2173.09	61.0686
2175.97	61.7959
2178.85	61.2661
2181.73	61.5088
2184.61	60.8074
2187.49	61.5336
2190.37	60.8247
2193.24	59.569
2196.12	58.4193
2198.99	54.6675
2201.87	52.6126
2204.74	49.6606
2207.61	46.6485
2210.48	43.8292
2213.35	41.4651
2216.21	39.5605
2219.08	37.9189
2221.95	35.0988
2224.81	32.5276
2227.67	30.4627
2230.54	29.9158
2233.4	27.5495
2236.26	27.4225
2239.11	25.9444
2241.97	25.1891
2244.83	24.5017
2247.69	23.7249
2250.54	23.1331
2253.4	21.5703
2256.25	21.452
2259.1	20.938
2261.95	19.84
2264.8	18.8984
2267.65	18.355
2270.5	16.5374
2273.34	15.399
2276.19	14.4576
2279.03	13.6451
2281.88	12.8662
2284.72	12.1343
2287.56	12.1005
2290.4	13.2064
2293.24	11.0753
2296.08	10.8842
2298.92	11.9034
2301.76	12.9775
2304.59	14.273
2307.43	15.3432
2310.26	14.9952
2313.09	14.1825
2315.92	13.9213
2318.75	12.7108
2321.58	11.0272
2324.41	10.6477
2327.24	10.8221
2330.06	11.1377
2332.89	11.2395
2335.71	11.6636
2338.54	10.1565
2341.36	9.0323
2344.18	7.30919
2347	6.92038
2349.82	8.81052
2352.64	8.98466
2355.45	8.99695
2358.27	8.26714
2361.08	8.25506
2363.9	8.70939
2366.71	10.0829
2369.52	10.7061
2372.33	11.0098
2375.14	9.85367
2377.95	8.70918
2380.76	7.40946
2383.57	5.58243
2386.37	4.47305
2389.18	3.88337
2391.98	3.5204
2394.79	3.91722
2397.59	4.90204
2400.39	4.46607
2403.19	4.12904
2405.99	5.09495
2408.78	5.06904
2411.58	5.42166
2414.38	6.95063
2417.17	8.5427
2419.97	9.04166
2422.76	9.07278
2425.55	8.42115
2428.34	8.97879
2431.13	9.30885
2433.92	9.59942
2436.71	9.54584
2439.49	9.03275
2442.28	8.50749
2445.06	8.9886
2447.85	9.82959
2450.63	8.79437
2453.41	9.3987
2456.19	8.40592
2458.97	8.80667
2461.75	8.8948
2464.53	8.24102
2467.31	8.05518
2470.08	8.09859
2472.86	7.68182
2475.63	8.53835
2478.4	9.61217
2481.17	8.29325
2483.94	7.28249
2486.72	5.51469
2489.48	5.12485
2492.25	5.00979
2495.02	3.52456
2497.79	2.40616
2500.55	1.88905
2503.31	0.988905
2506.08	0.499888
2508.84	-0.699746
2511.6	0.441606
2514.36	-0.0276608
2517.12	-0.49418
2519.88	0.129366
2522.63	0.461394
2525.39	-0.0420602
2528.14	1.99368
2530.9	3.00252
2533.65	4.20362
2536.4	5.17029
2539.15	6.06658
2541.9	6.76076
2544.65	8.64862
2547.4	9.26294
2550.15	9.46279
2552.89	10.5591
2555.64	11.3125
2558.38	12.021
2561.12	11.5857
2563.87	11.4193
2566.61	10.7857
2569.35	9.29527
2572.09	9.29724
2574.83	8.01929
2577.56	8.39439
2580.3	7.96199
2583.04	5.81634
2585.77	5.83044
2588.5	5.77789
2591.23	3.80294
2593.97	3.9876
2596.7	5.52091
2599.43	3.84399
2602.15	3.05773
2604.88	1.70127
2607.61	1.49749
2610.33	2.11874
2613.06	4.5208
2615.78	3.96907
2618.51	5.29113
2621.23	4.82054
2623.95	4.14945
2626.67	2.9413
2629.39	2.69793
2632.1	3.97822
2634.82	4.84649
2637.54	5.80031
2640.25	7.31967
2642.97	7.22713
2645.68	7.59682
2648.39	7.4646
2651.1	8.43445
2653.81	9.02617
2656.52	9.81164
2659.23	8.66669
2661.94	9.03143
2664.64	7.65483
2667.35	6.86935
2670.05	6.87854
2672.76	5.76365
2675.46	7.40254
2678.16	8.08837
2680.86	8.48239
2683.56	9.03551
2686.26	7.75486
2688.96	6.70498
2691.65	7.18384
2694.35	8.61653
2697.04	10.2611
2699.74	11.429
2702.43	11.9618
2705.12	14.3024
2707.81	15.0756
2710.5	15.2009
2713.19	16.0888
2715.88	16.3859
2718.57	14.6588
2721.25	14.4462
2723.94	14.2234
2726.62	12.4997
2729.3	12.4287
2731.99	11.0317
2734.67	9.34563
2737.35	7.62144
2740.03	8.05613
2742.71	7.1877
2745.38	7.60064
2748.06	6.83863
2750.74	6.00967
2753.41	5.85171
2756.09	5.03112
2758.76	4.2239
2761.43	4.74129
2764.1	4.2017
2766.77	3.7381
2769.44	4.07561
2772.11	4.0049
2774.77	5.14838
2777.44	5.25749
2780.11	6.04826
2782.77	5.35971
2785.43	5.04364
2788.1	7.02913
2790.76	7.8978
2793.42	8.31413
2796.08	8.3001
2798.74	8.15095
2801.4	8.00073
2804.05	8.64061
2806.71	8.93247
2809.36	8.5348
2812.02	10.9969
2814.67	10.3601
2817.32	10.6029
2819.97	10.8999
2822.62	12.4806
2825.27	13.9384
2827.92	15.3632
2830.57	16.9162
2833.22	20.362
2835.86	23.2573
2838.51	29.202
2841.15	33.247
2843.79	37.7605
2846.43	44.5139
2849.08	51.0102
2851.72	57.2391
2854.36	64.9455
2856.99	73.4216
2859.63	80.4275
2862.27	87.9564
2864.9	95.1285
2867.54	101.728
2870.17	107.992
2872.8	113.682
2875.43	118.738
2878.07	124.035
2880.7	127.615
2883.32	131.961
2885.95	136.95
2888.58	143.271
2891.21	147.153
2893.83	152.762
2896.46	159.67
2899.08	165.888
2901.7	172.812
2904.32	181.44
2906.94	188.48
2909.56	197.73
2912.18	207.72
2914.8	216.726
2917.42	226.72
2920.03	234.52
2922.65	240.954
2925.26	246.225
2927.88	249.543
2930.49	252.186
2933.1	252.078
2935.71	249.628
2938.32	246.958
2940.93	240.947
2943.54	233.376
2946.14	226.822
2948.75	218.026
2951.35	209.23
2953.96	200.491
2956.56	191.163
2959.16	182.605
2961.77	172.995
2964.37	164.097
2966.96	156.062
2969.56	148.093
2972.16	139.901
2974.76	132.692
2977.35	126.493
2979.95	117.953
2982.54	110.606
2985.14	102.136
2987.73	94.0976
2990.32	86.1027
2992.91	77.5384
2995.5	70.2135
2998.09	61.8397
3000.68	54.1589
3003.26	45.2056
3005.85	37.6817
3008.43	32.0533
3011.02	26.3537
3013.6	21.1227
3016.19	17.4475
3018.77	13.9077
3021.35	10.7235
3023.93	7.65279
3026.5	5.18981
3029.08	3.83426
3031.66	3.07546
3034.24	1.50544
3036.81	0.83999
3039.39	0.138274
3041.96	0.839464
3044.53	0.263029
3047.1	-0.121026
3049.67	-0.677578
3052.24	-0.772826
3054.81	-0.259833
3057.38	-0.554561
3059.95	-0.100782
3062.52	0.963954
3065.08	0.693095
3067.65	0.952252
3070.21	1.29086
3072.77	1.17041
3075.33	1.93122
3077.89	2.18048
3080.45	2.93382
3083.01	3.58218
3085.57	3.50308
3088.13	5.44541
3090.68	4.66476
3093.24	5.82111
3095.79	4.98171
3098.35	4.33507
3100.9	4.70081
3103.45	3.33294
3106	3.41041
3108.55	1.97805
3111.1	2.37762
3113.65	2.86129
3116.2	2.71761
3118.75	3.27163
3121.29	3.16009
3123.84	3.61555
3126.38	3.26908
3128.92	3.36421
3131.47	3.46699
3134.01	4.17502
3136.55	5.87577
3139.09	8.48523
3141.63	10.165
3144.17	12.6101
3146.7	14.8548
3149.24	17.557