File: data/Raman/poly_smoothed/Mb_40_24_27_1x_45s_532 nm_x100_100%_600 gr_mm_01.txt
#Acq. time (s)=	45
#Accumulations=	2
#Range (cm-¹)=	200...3150
#Windows=	2
#Auto scanning=	Off
#Autofocus=	Off
#Macrospot=	Off
#AutoExposure=	Off
#Spike filter=	Multiple accum.
#Delay time (s)=	0
#Binning=	1
#Readout mode=	Signal
#DeNoise=	Off
#ICS correction=	On
#Dark correction=	Off
#Inst. Process=	Off
#Detector Gain=	Best Dynamic Range
#Detector ADC=	20 kHz
#Detector temperature (°C)=	-69.85
#Instrument=	LabRAM HR Evol
#Detector=	Synapse
#Objective=	x100
#Grating=	600 gr/mm
#ND Filter=	100%
#Laser (nm)=	532
#Hole=	100.021
#Range=	Auto
#Laser Pol.=	No
#Raman. Pol.=	No
#Laser Pol. (°)=	-0.0007625
#Raman Pol. (°)=	89.9995
#Collection=	Microscope
#StageXY=	Marzhauser
#StageZ=	Marzhauser
#X (µm)=	-2494.2
#Y (µm)=	-112.4
#Z (µm)=	-10.6
#Full time(mm:ss)=	3:18
#Project=
#Sample=
#Site=
#Title=	Mb_40_24_27_2x_45s_532 nm_x100_100%_600 gr_mm
#Remark=
#Date=	14.07.2022 12:42
#Acquired=	14.07.2022 12:42:28
#Edit:Spike=	10.08.2022 10:43:09
#Edit:Spike=	10.08.2022 10:43:10
#Edit:Spike=	10.08.2022 10:43:12
#Edit:Spike=	10.08.2022 10:43:42
#Edit:Spike=	10.08.2022 10:43:43
#Base:Fit=	10.08.2022 10:47:00
#Base:Sub=	10.08.2022 10:47:12
#Filter:Polynom=	16.08.2022 10:11:48
#AxisType[0]=Intens
#AxisUnit[0]=Cnt
#AxisType[1]=Spectr
#AxisUnit[1]=1/cm
200.554	55.1234
204.183	46.6575
207.813	37.5658
211.439	28.6044
215.065	22.1609
218.688	16.1804
222.312	12.1295
225.933	9.86492
229.552	8.37702
233.171	5.96413
236.787	5.28079
240.402	6.08433
244.015	5.90802
247.627	6.641
251.24	7.04877
254.849	10.6828
258.457	12.6081
262.063	13.8301
265.668	15.9053
269.271	15.1874
272.873	16.6813
276.474	17.1815
280.073	16.9019
283.671	14.5611
287.268	14.2766
290.863	12.2245
294.456	11.3416
298.049	8.63893
301.637	9.69085
305.227	9.05954
308.815	9.32975
312.402	11.3785
315.987	11.1299
319.569	11.8684
323.151	13.8104
326.733	14.7179
330.31	17.1087
333.889	17.3841
337.464	18.342
341.039	19.0809
344.611	21.0068
348.184	20.633
351.754	18.3869
355.324	18.1093
358.89	17.4328
362.455	16.9806
366.021	15.7317
369.584	13.312
373.145	11.5312
376.707	11.1686
380.265	12.0881
383.822	10.3493
387.378	9.4077
390.934	10.1707
394.487	10.2452
398.038	9.72487
401.588	10.2505
405.137	12.3954
408.685	14.189
412.23	13.4736
415.775	14.0413
419.318	13.5851
422.86	13.5302
426.401	14.544
429.94	13.5817
433.478	13.9928
437.012	11.1178
440.547	9.55204
444.081	10.7381
447.613	9.67718
451.142	9.32182
454.672	8.70023
458.2	8.09736
461.725	7.7514
465.251	7.68361
468.775	7.36551
472.296	7.56591
475.817	7.07643
479.335	9.44202
482.854	11.5266
486.37	14.6951
489.886	17.6729
493.398	20.0784
496.91	24.7504
500.422	27.3788
503.93	30.2822
507.438	31.9487
510.946	32.4137
514.45	32.6653
517.954	33.6086
521.456	34.5594
524.956	35.6848
528.456	36.4578
531.956	37.6596
535.452	34.7165
538.947	32.6411
542.441	29.9683
545.934	28.7223
549.425	26.5523
552.915	26.1591
556.403	26.1401
559.889	23.9632
563.375	24.9326
566.859	24.5416
570.342	23.5407
573.824	21.1915
577.303	20.5733
580.782	21.3726
584.26	21.8724
587.734	18.2667
591.21	14.7304
594.684	11.1926
598.154	10.3357
601.626	11.3057
605.094	11.2926
608.562	10.9146
612.027	11.3704
615.493	9.29996
618.956	8.2111
622.419	8.08141
625.879	8.20541
629.338	9.21105
632.797	8.77342
636.254	10.5319
639.708	13.256
643.162	14.4537
646.614	15.9107
650.067	15.3847
653.516	14.8641
656.964	13.5343
660.411	13.5411
663.857	13.0815
667.301	11.7493
670.744	11.3067
674.186	11.0966
677.626	10.7626
681.065	12.3
684.503	15.4713
687.939	15.9607
691.372	18.1684
694.806	17.1654
698.239	15.7247
701.67	15.4152
705.098	18.8118
708.526	20.1866
711.954	23.4208
715.378	25.1561
718.802	26.7134
722.226	30.4277
725.646	31.7958
729.067	33.194
732.484	31.8239
735.902	33.8568
739.317	33.3248
742.731	35.9717
746.145	38.4778
749.556	42.8425
752.966	46.3559
756.377	50.4625
759.784	54.7025
763.19	57.857
766.594	60.7699
770	63.6849
773.402	66.3716
776.803	68.3687
780.202	69.8626
783.6	72.8402
786.997	76.1756
790.393	81.5188
793.787	85.3328
797.18	86.3618
800.572	86.3969
803.963	88.3923
807.35	87.4893
810.738	85.5819
814.125	82.9215
817.51	82.3979
820.894	81.8112
824.275	81.7299
827.657	80.3945
831.037	79.6982
834.414	78.0024
837.792	74.7347
841.167	72.279
844.542	69.9938
847.914	67.3401
851.287	65.2952
854.656	63.4887
858.026	61.0479
861.393	58.2174
864.761	58.3694
868.125	56.8303
871.489	56.2807
874.85	56.9562
878.213	55.0669
881.572	55.7364
884.931	57.0298
888.287	57.2845
891.643	57.3418
894.997	57.6744
898.352	58.8246
901.704	60.5003
905.055	61.7442
908.404	60.929
911.75	62.855
915.097	63.2778
918.443	61.8439
921.787	60.3918
925.13	60.9459
928.472	59.335
931.813	57.7603
935.15	54.1753
938.488	51.0359
941.825	49.4733
945.158	48.1686
948.493	44.1726
951.824	42.9032
955.156	41.2125
958.486	38.4678
961.814	36.3812
965.142	35.9323
968.467	35.6828
971.79	36.827
975.115	37.9574
978.436	39.3051
981.756	40.6697
985.077	41.5519
988.394	43.8707
991.71	44.4695
995.025	45.593
998.341	45.1999
1001.65	44.0526
1004.97	42.1863
1008.28	43.1746
1011.58	43.4865
1014.89	46.211
1018.2	47.7994
1021.5	49.036
1024.81	50.2579
1028.11	51.575
1031.41	51.686
1034.71	51.421
1038.01	50.9554
1041.31	48.0966
1044.6	49.4651
1047.9	51.1
1051.19	52.0805
1054.48	51.6239
1057.77	52.3898
1061.06	52.062
1064.35	50.9757
1067.64	50.7151
1070.93	51.0438
1074.21	47.8167
1077.49	47.3291
1080.78	42.8492
1084.06	38.4935
1087.34	37.5094
1090.61	38.826
1093.89	39.4212
1097.17	38.792
1100.44	38.8371
1103.71	40.3562
1106.99	39.6605
1110.26	38.8431
1113.52	37.7472
1116.79	36.5682
1120.06	33.9609
1123.32	33.4642
1126.59	32.831
1129.85	33.1127
1133.11	31.0335
1136.37	29.8427
1139.63	27.8731
1142.89	26.0928
1146.15	25.1762
1149.4	22.8411
1152.66	18.1248
1155.91	14.6735
1159.16	11.6146
1162.41	7.57709
1165.66	6.63855
1168.91	5.43256
1172.16	3.89094
1175.4	2.7927
1178.65	4.84983
1181.89	4.38068
1185.13	4.96908
1188.37	5.12534
1191.61	6.21632
1194.85	8.46577
1198.08	8.94905
1201.32	11.4379
1204.55	14.6432
1207.79	17.927
1211.02	21.493
1214.25	24.7107
1217.48	28.8009
1220.71	31.7676
1223.93	36.6336
1227.16	41.4559
1230.38	47.7601
1233.6	51.9332
1236.83	58.5508
1240.05	62.1701
1243.26	65.7991
1246.48	68.4689
1249.7	70.9386
1252.92	74.4297
1256.13	75.9222
1259.34	78.4951
1262.55	80.1472
1265.76	84.7272
1268.97	88.1142
1272.18	93.0531
1275.39	96.7453
1278.59	98.3082
1281.8	101.763
1285	105.293
1288.2	107.569
1291.4	111.208
1294.6	111.012
1297.8	111.478
1301	112.741
1304.19	117.077
1307.39	119.086
1310.58	121.382
1313.77	122.927
1316.96	121.895
1320.15	120.425
1323.34	113.913
1326.53	112.696
1329.72	114.689
1332.9	112.706
1336.08	113.681
1339.27	112.923
1342.45	112.363
1345.63	111.532
1348.8	110.15
1351.98	112.372
1355.16	107.068
1358.33	102.678
1361.51	100.111
1364.68	97.8921
1367.85	94.0132
1371.02	87.6448
1374.19	83.9723
1377.36	81.2379
1380.52	79.8577
1383.69	77.9571
1386.85	74.8235
1390.02	73.0126
1393.18	70.325
1396.34	67.4273
1399.5	65.024
1402.65	65.7162
1405.81	72.5156
1408.97	74.4953
1412.12	76.887
1415.27	81.7637
1418.43	89.099
1421.58	97.2729
1424.73	107.929
1427.87	117.769
1431.02	128.095
1434.17	136.097
1437.31	142.995
1440.46	148.338
1443.6	151.233
1446.74	153.097
1449.88	154.703
1453.02	153.629
1456.16	151.473
1459.29	148.605
1462.43	141.458
1465.56	135.499
1468.69	127.338
1471.83	117.83
1474.95	108.293
1478.08	98.0028
1481.21	86.9222
1484.34	77.1451
1487.47	69.7132
1490.59	64.7116
1493.71	59.9677
1496.84	54.739
1499.96	52.3346
1503.07	48.8858
1506.19	45.0619
1509.31	43.1598
1512.43	38.49
1515.54	35.2621
1518.65	31.6046
1521.77	31.178
1524.88	29.1786
1527.99	30.236
1531.1	30.097
1534.21	32.7521
1537.31	31.9702
1540.42	32.3003
1543.52	34.2372
1546.63	34.5115
1549.73	36.6146
1552.83	37.8455
1555.93	42.1241
1559.03	46.9363
1562.12	53.0532
1565.22	58.9247
1568.31	63.3286
1571.41	67.8371
1574.5	72.2551
1577.59	78.1918
1580.68	83.6233
1583.77	88.9417
1586.86	93.3186
1589.95	98.6041
1593.03	104.428
1596.11	107.401
1599.2	109.456
1602.28	112.105
1605.36	113.333
1608.44	113.774
1611.52	112.835
1614.6	111.57
1617.67	110.696
1620.75	109.782
1623.82	110.093
1626.89	110.925
1629.96	113.007
1633.04	115.216
1636.11	116.342
1639.17	118.212
1642.24	120.574
1645.31	120.904
1648.37	123.143
1651.43	125.155
1654.5	126.182
1657.56	125.928
1660.62	128.252
1663.67	126.203
1666.73	122.731
1669.79	115.629
1672.84	109.321
1675.9	102.475
1678.95	95.303
1682	87.9449
1685.05	79.6768
1688.1	71.5402
1691.15	64.5067
1694.2	56.82
1697.25	50.6589
1700.29	44.8616
1703.33	40.4894
1706.38	36.0256
1709.42	30.7966
1712.46	27.8281
1715.5	26.2958
1718.54	22.3076
1721.57	20.7169
1724.61	19.0704
1727.64	18.2923
1730.68	16.9929
1733.71	16.1401
1736.74	14.4757
1739.77	12.9082
1742.8	12.3576
1745.83	11.221
1748.85	10.4191
1751.88	9.83645
1754.91	9.90155
1757.93	9.73539
1760.95	8.96758
1763.97	8.59408
1766.99	7.5651
1770.01	6.71786
1773.03	5.95253
1776.04	5.55609
1779.06	5.2049
1782.07	4.16377
1785.09	3.13173
1788.1	2.60823
1791.11	1.34649
1794.12	1.34562
1797.13	1.65555
1800.13	1.35049
1803.14	0.641856
1806.15	0.652695
1809.15	0.690103
1812.15	1.02706
1815.16	2.40524
1818.15	2.42741
1821.16	2.51088
1824.15	3.0938
1827.15	4.02669
1830.15	3.62182
1833.14	3.67581
1836.14	3.67255
1839.13	4.95739
1842.12	4.76812
1845.11	5.23966
1848.1	5.45876
1851.09	7.03253
1854.08	6.23142
1857.06	5.79588
1860.05	5.22399
1863.03	4.48567
1866.01	3.8708
1869	3.26296
1871.98	2.52525
1874.96	1.19177
1877.93	0.33131
1880.91	0.047556
1882.47	-0.29363
1885.46	0.0186468
1888.44	0.28311
1891.43	-1.09891
1894.42	-0.813257
1897.4	-1.33021
1900.39	-1.19862
1903.37	-0.660595
1906.35	-0.650192
1909.33	0.951612
1912.31	2.53909
1915.29	2.74436
1918.26	2.936
1921.24	3.06398
1924.21	3.54969
1927.19	3.36233
1930.16	3.31125
1933.13	2.56776
1936.1	2.26749
1939.07	2.47493
1942.04	4.10658
1945	3.73929
1947.97	4.26025
1950.93	5.38916
1953.9	5.03994
1956.86	5.97883
1959.82	6.69116
1962.78	6.95546
1965.74	6.83737
1968.7	7.74999
1971.65	7.53585
1974.61	7.66164
1977.57	6.69497
1980.52	6.84503
1983.47	5.67657
1986.42	5.38704
1989.37	4.33456
1992.32	4.87246
1995.27	4.66334
1998.22	4.64105
2001.17	4.08873
2004.11	4.36067
2007.05	4.65258
2010	5.83944
2012.94	5.94884
2015.88	5.76205
2018.82	5.45253
2021.76	6.0063
2024.7	6.87932
2027.63	8.82528
2030.57	10.6693
2033.5	11.7714
2036.44	13.4891
2039.37	14.7249
2042.3	16.2927
2045.23	17.5326
2048.16	18.1901
2051.08	19.5291
2054.01	21.9721
2056.94	23.0369
2059.86	24.4204
2062.79	26.9908
2065.71	28.0555
2068.63	29.8888
2071.55	32.8823
2074.47	36.0889
2077.39	38.9624
2080.31	41.9376
2083.22	44.4764
2086.13	47.7594
2089.05	51.0017
2091.96	53.8878
2094.87	58.9986
2097.78	63.5564
2100.69	68.2473
2103.6	71.3931
2106.51	77.3613
2109.42	82.3255
2112.32	87.6079
2115.23	93.3164
2118.13	98.7007
2121.03	103.266
2123.93	110.879
2126.83	117.273
2129.73	124.605
2132.63	130.815
2135.53	138.125
2138.42	145.29
2141.32	153.048
2144.21	160.035
2147.1	166.833
2150	172.4
2152.89	176.796
2155.78	180.851
2158.66	183.433
2161.55	184.878
2164.44	186.629
2167.32	188.963
2170.21	189.94
2173.09	188.219
2175.97	185.351
2178.85	182.684
2181.73	179.104
2184.61	175.881
2187.49	170.717
2190.37	165.333
2193.24	161.266
2196.12	156.524
2198.99	151.102
2201.87	143.865
2204.74	135.11
2207.61	128.797
2210.48	122.08
2213.35	114.693
2216.21	107.862
2219.08	100.813
2221.95	93.6575
2224.81	87.4188
2227.67	79.2785
2230.54	72.6989
2233.4	67.1652
2236.26	63.6615
2239.11	59.9734
2241.97	54.355
2244.83	49.3459
2247.69	46.7426
2250.54	45.442
2253.4	43.0022
2256.25	40.9173
2259.1	38.3372
2261.95	37.3939
2264.8	34.0537
2267.65	31.9526
2270.5	28.541
2273.34	27.1833
2276.19	26.8665
2279.03	25.9572
2281.88	24.6778
2284.72	21.6516
2287.56	19.7783
2290.4	17.9228
2293.24	14.7002
2296.08	13.3722
2298.92	12.9545
2301.76	13.786
2304.59	14.6463
2307.43	14.6418
2310.26	13.4698
2313.09	13.4471
2315.92	13.7281
2318.75	14.9614
2321.58	13.7867
2324.41	12.466
2327.24	11.9001
2330.06	11.309
2332.89	10.2289
2335.71	9.00908
2338.54	9.84405
2341.36	9.37562
2344.18	9.07123
2347	7.24689
2349.82	6.0228
2352.64	3.75406
2355.45	1.63693
2358.27	1.32475
2361.08	0.571236
2363.9	1.08612
2366.71	2.68525
2369.52	3.21325
2372.33	2.70336
2375.14	3.06527
2377.95	3.48554
2380.76	4.77577
2383.57	6.40533
2386.37	7.17441
2389.18	6.96242
2391.98	6.79811
2394.79	8.13491
2397.59	9.21278
2400.39	8.27053
2403.19	10.4319
2405.99	10.3153
2408.78	9.99341
2411.58	9.41408
2414.38	9.70264
2417.17	8.5295
2419.97	8.04651
2422.76	6.11648
2425.55	5.89472
2428.34	5.63428
2431.13	5.56916
2433.92	5.90836
2436.71	5.15045
2439.49	3.98112
2442.28	3.63036
2445.06	3.61958
2447.85	4.85756
2450.63	4.37267
2453.41	3.43444
2456.19	3.21536
2458.97	2.30047
2461.75	2.85132
2464.53	2.98891
2467.31	3.37838
2470.08	4.43152
2472.86	3.79771
2475.63	2.49021
2478.4	2.27184
2481.17	2.78327
2483.94	2.60542
2486.72	2.60752
2489.48	2.22181
2492.25	1.95191
2495.02	1.78499
2497.79	2.08244
2500.55	1.72665
2503.31	0.0444149
2506.08	-0.873774
2508.84	-0.770985
2511.6	-0.394837
2514.36	0.237565
2517.12	0.274947
2519.88	0.110604
2522.63	0.420419
2525.39	0.960072
2528.14	1.70908
2530.9	2.45532
2533.65	4.04166
2536.4	5.05408
2539.15	4.71777
2541.9	3.56135
2544.65	3.5333
2547.4	4.2573
2550.15	5.3943
2552.89	5.79689
2555.64	5.63405
2558.38	5.48395
2561.12	4.80399
2563.87	4.43752
2566.61	4.39647
2569.35	4.17552
2572.09	4.93223
2574.83	4.51981
2577.56	4.65867
2580.3	4.48271
2583.04	5.17398
2585.77	4.80401
2588.5	4.39974
2591.23	4.50895
2593.97	4.37589
2596.7	3.4541
2599.43	3.06536
2602.15	2.9843
2604.88	2.64994
2607.61	0.870214
2610.33	0.285634
2613.06	1.3074
2615.78	3.28496
2618.51	4.77404
2621.23	3.83896
2623.95	3.7601
2626.67	4.2971
2629.39	4.81299
2632.1	5.45801
2634.82	6.34107
2637.54	7.28006
2640.25	7.27493
2642.97	8.30865
2645.68	9.2768
2648.39	9.55672
2651.1	10.0182
2653.81	7.47152
2656.52	7.10923
2659.23	7.38635
2661.94	6.06163
2664.64	5.25287
2667.35	4.46584
2670.05	4.00195
2672.76	3.87276
2675.46	3.41547
2678.16	4.36726
2680.86	5.35365
2683.56	5.98554
2686.26	4.65918
2688.96	5.59221
2691.65	6.38847
2694.35	6.75536
2697.04	7.51818
2699.74	8.79164
2702.43	11.6197
2705.12	12.9089
2707.81	14.3926
2710.5	15.6102
2713.19	16.5557
2715.88	17.5934
2718.57	16.6325
2721.25	17.3694
2723.94	18.3201
2726.62	17.7874
2729.3	17.128
2731.99	16.5731
2734.67	15.8708
2737.35	15.4771
2740.03	13.9467
2742.71	12.5722
2745.38	11.1615
2748.06	9.27181
2750.74	8.385
2753.41	6.57977
2756.09	4.86519
2758.76	3.95547
2761.43	3.16778
2764.1	3.02476
2766.77	2.5847
2769.44	2.31892
2772.11	1.18997
2774.77	0.751662
2777.44	1.04002
2780.11	1.1166
2782.77	1.63892
2785.43	1.34395
2788.1	1.80218
2790.76	0.783974
2793.42	-0.58068
2796.08	0.278911
2798.74	0.0626419
2801.4	-1.47636
2804.05	-1.47536
2806.71	-2.26034
2809.36	-2.48689
2812.02	-2.3466
2814.67	-0.588003
2817.32	2.36973
2819.97	6.6545
2822.62	12.8608
2825.27	20.4231
2827.92	30.7978
2830.57	40.8958
2833.22	53.9291
2835.86	67.3782
2838.51	81.7758
2841.15	98.373
2843.79	118.108
2846.43	136.384
2849.08	154.391
2851.72	171.504
2854.36	190.883
2856.99	208.812
2859.63	226.189
2862.27	241.174
2864.9	254.25
2867.54	268.36
2870.17	279.28
2872.8	289.323
2875.43	298.934
2878.07	308.181
2880.7	317.749
2883.32	327.918
2885.95	337.741
2888.58	348.888
2891.21	360.722
2893.83	373.322
2896.46	384.148
2899.08	398.033
2901.7	413.678
2904.32	431.841
2906.94	451.341
2909.56	471.258
2912.18	489.505
2914.8	507.968
2917.42	525.791
2920.03	541.994
2922.65	553.407
2925.26	561.3
2927.88	566.757
2930.49	568.239
2933.1	565.05
2935.71	557.287
2938.32	546.521
2940.93	533.452
2943.54	516.397
2946.14	499.04
2948.75	477.791
2951.35	456.553
2953.96	433.574
2956.56	410.476
2959.16	386.716
2961.77	362.519
2964.37	340.892
2966.96	321.351
2969.56	301.037
2972.16	282.551
2974.76	264.912
2977.35	246.863
2979.95	229.701
2982.54	211.867
2985.14	193.38
2987.73	175.062
2990.32	158.212
2992.91	141.512
2995.5	123.696
2998.09	109.324
3000.68	93.9986
3003.26	81.1938
3005.85	68.1637
3008.43	56.6892
3011.02	45.9302
3013.6	36.7963
3016.19	28.3693
3018.77	21.4983
3021.35	17.1347
3023.93	11.4175
3026.5	7.61017
3029.08	6.36688
3031.66	4.81173
3034.24	4.24748
3036.81	4.41145
3039.39	4.60768
3041.96	5.35665
3044.53	4.87081
3047.1	6.42141
3049.67	7.79703
3052.24	8.74014
3054.81	10.0562
3057.38	10.3407
3059.95	10.36
3062.52	10.9089
3065.08	9.96679
3067.65	9.63181
3070.21	8.4976
3072.77	8.16416
3075.33	6.70944
3077.89	5.4978
3080.45	4.96231
3083.01	5.50441
3085.57	5.10862
3088.13	4.49422
3090.68	5.62683
3093.24	5.55485
3095.79	6.15219
3098.35	7.60821
3100.9	8.6068
3103.45	10.3881
3106	12.0639
3108.55	13.7658
3111.1	16.0041
3113.65	18.0432
3116.2	20.552
3118.75	22.1121
3121.29	24.419
3123.84	27.293
3126.38	29.7667
3128.92	32.5422
3131.47	35.4648
3134.01	38.9106
3136.55	41.817
3139.09	43.4107
3141.63	46.7523
3144.17	49.8337
3146.7	52.5708
3149.24	53.857