File: data/Raman/poly_smoothed/Mb_40_y_14_1x_45s_532 nm_x100_100%_600 gr_mm_01.txt
#Acq. time (s)=	45
#Accumulations=	2
#Range (cm-¹)=	200...3150
#Windows=	2
#Auto scanning=	Off
#Autofocus=	Off
#Macrospot=	Off
#AutoExposure=	Off
#Spike filter=	Multiple accum.
#Delay time (s)=	0
#Binning=	1
#Readout mode=	Signal
#DeNoise=	Off
#ICS correction=	On
#Dark correction=	Off
#Inst. Process=	Off
#Detector Gain=	Best Dynamic Range
#Detector ADC=	20 kHz
#Detector temperature (°C)=	-69.85
#Instrument=	LabRAM HR Evol
#Detector=	Synapse
#Objective=	x100
#Grating=	600 gr/mm
#ND Filter=	100%
#Laser (nm)=	532
#Hole=	100.021
#Range=	Auto
#Laser Pol.=	No
#Raman. Pol.=	No
#Laser Pol. (°)=	-0.0007625
#Raman Pol. (°)=	89.9995
#Collection=	Microscope
#StageXY=	Marzhauser
#StageZ=	Marzhauser
#X (µm)=	-1071.5
#Y (µm)=	674.7
#Z (µm)=	584.55
#Full time(mm:ss)=	3:18
#Project=
#Sample=
#Site=
#Title=	Mb_40_y_14_2x_45s_532 nm_x100_100%_600 gr_mm
#Remark=
#Date=	19.07.2022 10:08
#Acquired=	19.07.2022 10:08:44
#Base:Fit=	10.08.2022 10:52:48
#Base:Sub=	10.08.2022 10:52:53
#Filter:Polynom=	16.08.2022 10:09:04
#AxisType[0]=Intens
#AxisUnit[0]=Cnt
#AxisType[1]=Spectr
#AxisUnit[1]=1/cm
200.423	-1.62572
204.052	1.60639
207.682	5.65458
211.308	7.97089
214.935	9.38556
218.558	11.8123
222.18	10.7752
225.802	11.3249
229.421	10.4533
233.039	9.99294
236.657	8.65821
240.272	6.99723
243.885	7.39901
247.497	6.13442
251.11	4.6865
254.719	5.42866
258.327	3.72995
261.933	2.01241
265.538	1.17044
269.141	1.10683
272.744	0.399894
276.344	-0.308532
279.944	0.302592
283.542	1.64212
287.138	2.54474
290.733	3.29409
294.327	4.08805
297.919	4.22037
301.508	4.8438
305.098	6.25519
308.686	4.36476
312.273	4.09946
315.858	4.13408
319.44	3.52458
323.022	4.61677
326.604	5.21574
330.181	7.22351
333.76	8.41916
337.335	8.20047
340.91	8.95931
344.483	10.3517
348.055	10.3722
351.625	11.3156
355.195	10.3351
358.762	11.087
362.329	11.079
365.893	11.887
369.455	10.9066
373.017	11.1007
376.578	11.6247
380.137	10.9066
383.694	9.41761
387.249	9.22645
390.806	9.32496
394.359	8.40169
397.91	8.73028
401.46	8.80115
405.009	9.77998
408.557	11.801
412.103	12.9158
415.647	12.3769
419.191	12.2722
422.733	11.3076
426.273	10.5575
429.812	11.1664
433.35	11.5297
436.885	10.6666
440.42	9.84343
443.954	8.61846
447.486	8.31612
451.015	7.12287
454.545	6.77349
458.073	5.44766
461.598	6.37868
465.124	7.39514
468.648	8.7836
472.169	10.4413
475.69	12.4596
479.208	15.1969
482.727	17.6699
486.243	17.9276
489.759	22.0032
493.272	24.7678
496.783	26.7725
500.295	26.4367
503.804	26.0782
507.311	26.5674
510.819	26.4181
514.324	25.7545
517.827	26.8352
521.329	27.1102
524.83	27.3411
528.329	24.4313
531.829	22.3828
535.326	19.8298
538.821	17.969
542.315	15.7311
545.808	15.2325
549.299	15.031
552.789	13.6841
556.278	13.4033
559.763	13.04
563.249	12.5026
566.733	12.6897
570.217	13.1048
573.699	15.4922
577.177	15.4334
580.656	13.2247
584.134	11.9834
587.609	11.1868
591.084	10.6802
594.558	9.18551
598.029	9.27633
601.5	8.77814
604.968	9.39431
608.437	10.1366
611.902	8.21892
615.368	5.78324
618.831	4.04817
622.294	2.85924
625.755	3.56821
629.213	4.60655
632.673	6.10338
636.129	7.81514
639.584	8.3429
643.037	9.50012
646.491	10.3538
649.942	11.3122
653.392	11.9309
656.84	13.5939
660.287	13.3013
663.732	13.757
667.177	14.8182
670.62	16.2429
674.061	16.9378
677.502	17.9819
680.941	19.7725
684.379	21.5846
687.815	23.6249
691.248	25.1482
694.682	26.4886
698.115	26.3823
701.546	28.8025
704.974	31.5509
708.402	35.5252
711.83	39.2543
715.254	40.9807
718.679	42.4447
722.102	42.9629
725.522	44.6577
728.943	46.2618
732.361	47.1034
735.779	48.8752
739.194	49.0988
742.608	50.9441
746.022	53.203
749.433	54.5195
752.843	57.151
756.254	57.5429
759.661	60.2744
763.067	64.2481
766.471	66.4255
769.877	69.3446
773.279	71.0107
776.68	73.3136
780.079	74.3965
783.478	74.4325
786.875	76.3015
790.27	78.9588
793.665	79.415
797.058	78.3388
800.45	78.4592
803.84	77.9139
807.23	78.1872
810.616	77.5109
814.002	75.9736
817.388	75.631
820.772	76.043
824.153	74.384
827.535	73.6221
830.915	73.4688
834.292	74.0834
837.67	74.021
841.047	71.8628
844.42	71.9789
847.794	70.0538
851.165	67.452
854.534	64.8567
857.905	62.2395
861.272	60.1496
864.639	55.9496
868.004	52.9693
871.367	52.2601
874.731	49.9925
878.092	48.675
881.451	48.5139
884.809	47.8479
888.166	45.4352
891.522	46.1699
894.878	46.173
898.231	46.9461
901.583	48.1249
904.934	47.6553
908.283	47.6911
911.631	47.755
914.976	49.3931
918.322	48.1482
921.666	47.3885
925.009	47.0182
928.351	46.02
931.692	45.1965
935.029	44.3542
938.367	43.6289
941.704	43.1614
945.038	41.9251
948.372	41.9737
951.705	41.1849
955.035	40.9681
958.366	41.1189
961.693	40.7855
965.021	39.5263
968.346	38.6522
971.67	39.3635
974.995	40.9272
978.316	40.2972
981.638	39.8577
984.957	39.5525
988.274	37.712
991.59	35.3473
994.907	33.2426
998.221	29.6536
1001.53	25.5917
1004.85	23.6175
1008.16	26.1063
1011.46	34.2718
1014.77	47.343
1018.08	61.0318
1021.38	77.2792
1024.69	92.2284
1027.99	104.02
1031.29	114.614
1034.59	122.232
1037.89	129.548
1041.19	134.121
1044.48	136.144
1047.78	136.802
1051.07	133.872
1054.36	128.975
1057.66	121.284
1060.94	111.774
1064.23	100.684
1067.52	86.6872
1070.81	70.3499
1074.09	52.1264
1077.38	36.5341
1080.66	23.373
1083.94	12.9047
1087.22	8.75979
1090.5	11.6387
1093.77	14.0801
1097.05	16.2115
1100.32	18.8753
1103.6	19.1387
1106.87	19.8806
1110.14	21.158
1113.41	21.9571
1116.67	21.7642
1119.94	21.9248
1123.21	22.6829
1126.47	22.6655
1129.73	21.0327
1133	20.9826
1136.26	20.4596
1139.52	22.2594
1142.77	22.239
1146.03	19.8327
1149.29	17.9908
1152.54	15.6464
1155.79	14.1637
1159.04	13.3247
1162.3	11.1601
1165.55	9.03206
1168.79	8.06724
1172.04	7.22629
1175.28	6.55479
1178.53	6.28072
1181.77	6.24035
1185.01	6.11415
1188.25	6.88998
1191.49	6.60734
1194.73	7.49265
1197.97	7.42241
1201.2	10.1123
1204.44	12.5633
1207.67	14.8473
1210.9	17.0065
1214.13	18.5745
1217.36	20.955
1220.59	23.5957
1223.82	24.86
1227.04	28.0929
1230.26	29.8194
1233.49	32.7587
1236.71	35.0567
1239.93	38.0299
1243.15	40.2907
1246.37	43.1818
1249.58	44.427
1252.8	46.9504
1256.01	48.5877
1259.23	52.3325
1262.44	53.7349
1265.65	55.4038
1268.86	57.3966
1272.07	60.0079
1275.27	61.6006
1278.48	63.5116
1281.68	65.7167
1284.89	66.9637
1288.09	67.7574
1291.29	66.7164
1294.49	68.2176
1297.69	68.934
1300.88	68.9518
1304.08	68.9794
1307.27	69.4268
1310.47	70.4322
1313.66	69.495
1316.85	68.7251
1320.04	68.2049
1323.23	68.5354
1326.41	67.9469
1329.6	66.1372
1332.78	65.7083
1335.97	65.0093
1339.15	63.3224
1342.33	58.864
1345.51	55.8702
1348.69	53.8124
1351.87	51.2645
1355.04	48.872
1358.22	47.357
1361.39	44.5792
1364.57	41.1314
1367.74	40.0182
1370.91	37.9732
1374.07	37.6989
1377.24	35.7628
1380.41	35.7613
1383.57	36.2159
1386.74	37.7927
1389.9	38.7292
1393.06	39.0829
1396.22	40.7317
1399.38	43.3496
1402.54	43.3362
1405.7	44.027
1408.85	44.9357
1412.01	46.1467
1415.16	47.1752
1418.31	48.5192
1421.46	52.5381
1424.61	57.2687
1427.76	60.6706
1430.91	63.2256
1434.05	67.6562
1437.2	70.8697
1440.34	74.1461
1443.49	76.005
1446.63	77.3834
1449.77	78.5841
1452.91	79.3952
1456.04	78.2339
1459.18	77.813
1462.31	76.2278
1465.45	74.5744
1468.58	72.8459
1471.71	68.8504
1474.84	63.9725
1477.97	60.0752
1481.1	54.3991
1484.23	49.5405
1487.35	44.6463
1490.48	41.2846
1493.6	38.2376
1496.72	34.8176
1499.84	32.3592
1502.96	28.3645
1506.08	26.612
1509.2	25.0052
1512.31	24.7521
1515.43	22.4632
1518.54	20.9845
1521.66	19.556
1524.77	19.6167
1527.88	19.6448
1530.99	19.765
1534.09	19.6652
1537.2	21.5537
1540.31	23.1349
1543.41	24.5632
1546.51	26.5569
1549.62	28.5509
1552.72	30.4155
1555.82	31.8929
1558.91	31.5938
1562.01	32.8177
1565.11	34.5609
1568.2	35.8724
1571.3	37.3417
1574.39	38.8079
1577.48	41.5003
1580.57	43.1457
1583.66	45.8482
1586.75	47.3651
1589.83	49.1664
1592.92	50.526
1596	50.3878
1599.09	51.1478
1602.17	50.3845
1605.25	50.0912
1608.33	50.0152
1611.41	49.9424
1614.48	50.2361
1617.56	51.1555
1620.64	52.0485
1623.71	53.0581
1626.78	53.7973
1629.86	54.9584
1632.92	56.2595
1635.99	57.4981
1639.06	58.6553
1642.13	61.1597
1645.19	62.0918
1648.26	63.2886
1651.32	64.6072
1654.38	65.9756
1657.45	67.2542
1660.51	68.3263
1663.57	68.1232
1666.62	66.5238
1669.68	64.2339
1672.73	61.2842
1675.79	57.6225
1678.84	54.643
1681.89	50.0335
1684.94	44.9526
1687.99	40.0883
1691.04	35.4866
1694.09	32.0373
1697.14	28.1949
1700.18	24.5169
1703.22	21.9921
1706.27	19.6934
1709.31	17.4464
1712.35	14.0928
1715.39	12.3925
1718.43	11.3676
1721.46	9.75883
1724.5	9.45921
1727.53	10.2299
1730.57	10.8029
1733.6	11.4054
1736.63	11.7074
1739.66	11.9084
1742.69	12.5457
1745.72	11.9886
1748.74	11.2353
1751.77	11.3628
1754.8	9.95248
1757.82	8.67811
1760.84	8.1439
1763.86	7.88814
1766.88	7.7899
1769.9	7.26508
1772.92	6.32409
1775.93	5.49637
1778.95	4.63644
1781.96	2.86786
1784.98	2.15656
1787.99	1.69505
1791	1.70039
1794.01	1.38402
1797.02	0.702935
1800.03	0.210205
1803.03	0.136312
1806.04	0.526765
1809.04	1.49649
1812.04	1.66517
1815.05	2.16492
1818.05	2.47949
1821.05	2.72986
1824.05	3.64098
1827.04	4.23824
1830.04	4.28265
1833.03	4.35399
1836.03	4.72507
1839.02	4.61132
1842.01	5.17286
1845	5.86483
1847.99	5.62566
1850.98	5.55037
1853.97	5.25459
1856.95	4.76537
1859.94	4.5471
1862.92	4.98031
1865.91	4.93818
1868.89	4.27095
1871.87	4.4814
1874.85	4.00219
1877.83	4.12991
1880.8	4.57041
1882.56	4.99189
1885.54	4.74055
1888.53	4.6631
1891.52	4.36141
1894.5	3.88451
1897.49	3.83863
1900.47	3.70933
1903.45	3.28247
1906.43	3.64119
1909.41	4.58369
1912.39	5.41859
1915.37	5.97023
1918.35	6.29814
1921.32	6.27111
1924.3	6.67481
1927.27	5.90169
1930.24	5.49515
1933.21	5.00122
1936.18	4.06423
1939.15	3.65785
1942.12	4.12885
1945.09	3.63863
1948.05	3.41031
1951.02	3.04908
1953.98	2.8733
1956.94	2.49312
1959.91	2.71505
1962.87	1.98026
1965.82	1.07464
1968.78	1.35226
1971.74	1.64029
1974.7	2.64031
1977.65	2.7027
1980.6	3.4488
1983.56	4.28592
1986.51	4.31839
1989.46	5.18419
1992.41	5.11523
1995.36	5.50154
1998.3	5.30125
2001.25	5.32353
2004.2	5.11267
2007.14	5.23287
2010.08	7.24163
2013.02	7.84174
2015.97	7.84822
2018.9	8.51793
2021.84	7.0821
2024.78	8.09849
2027.72	7.95401
2030.65	8.53169
2033.59	9.10592
2036.52	9.13255
2039.45	9.87628
2042.38	10.7493
2045.31	11.3294
2048.24	10.7766
2051.17	10.8955
2054.1	11.692
2057.02	12.1201
2059.95	12.6836
2062.87	13.9668
2065.79	14.6583
2068.71	16.1856
2071.63	17.3236
2074.55	18.4065
2077.47	20.0859
2080.39	22.0631
2083.3	23.2049
2086.22	24.0697
2089.13	25.2407
2092.05	27.8203
2094.96	29.1269
2097.87	32.0635
2100.78	35.3316
2103.69	37.1122
2106.59	39.0251
2109.5	41.4259
2112.41	43.0746
2115.31	46.0835
2118.21	49.4408
2121.12	52.1526
2124.02	55.3077
2126.92	57.493
2129.82	61.6662
2132.71	64.8856
2135.61	68.5241
2138.51	71.5702
2141.4	75.1758
2144.29	78.8946
2147.19	82.1318
2150.08	84.7756
2152.97	87.8455
2155.86	89.8714
2158.75	92.3609
2161.64	93.845
2164.52	96.3269
2167.41	97.0689
2170.29	97.6354
2173.17	97.2952
2176.06	96.5041
2178.94	96.1294
2181.82	94.777
2184.7	93.0124
2187.57	90.8475
2190.45	87.687
2193.33	83.4988
2196.2	81.1149
2199.08	78.2252
2201.95	74.5125
2204.82	70.1718
2207.69	66.6048
2210.56	63.2405
2213.43	60.9977
2216.3	57.62
2219.16	53.9679
2222.03	49.9026
2224.89	46.8878
2227.75	44.8932
2230.62	41.7272
2233.48	38.8559
2236.34	39.1376
2239.2	37.7624
2242.06	36.7992
2244.91	35.1601
2247.77	33.0681
2250.62	31.6703
2253.48	30.2362
2256.33	28.7709
2259.18	26.4731
2262.03	25.2744
2264.88	24.7848
2267.73	24.1348
2270.58	23.9069
2273.43	22.5151
2276.27	21.3485
2279.12	21.3113
2281.96	21.0672
2284.8	19.4692
2287.64	18.5636
2290.49	17.0116
2293.32	15.2954
2296.16	14.6919
2299	15.0345
2301.84	15.6052
2304.67	16.4889
2307.51	17.1192
2310.34	16.2367
2313.17	16.7475
2316	16.117
2318.83	15.2204
2321.66	13.798
2324.49	12.6574
2327.32	12.6824
2330.15	12.2888
2332.97	11.3529
2335.79	10.603
2338.62	10.3062
2341.44	8.3292
2344.26	7.46211
2347.08	6.94745
2349.9	5.57007
2352.72	3.75983
2355.53	2.29618
2358.35	1.34718
2361.17	0.200476
2363.98	0.96385
2366.79	2.17279
2369.6	2.78476
2372.42	3.17103
2375.22	3.90905
2378.03	5.08769
2380.84	6.9905
2383.65	6.76961
2386.45	6.96931
2389.26	6.90338
2392.06	7.25708
2394.87	7.81369
2397.67	7.88052
2400.47	7.68337
2403.27	8.13669
2406.07	7.94885
2408.86	8.05172
2411.66	7.89835
2414.46	8.11746
2417.25	7.35357
2420.05	6.71708
2422.84	6.11504
2425.63	5.70092
2428.42	6.17399
2431.21	5.9377
2434	5.44211
2436.79	6.38463
2439.57	6.56219
2442.36	7.13587
2445.14	8.3152
2447.93	9.037
2450.71	8.45942
2453.49	7.7667
2456.27	6.64069
2459.05	6.17181
2461.83	6.32524
2464.61	6.89405
2467.39	6.65838
2470.16	6.11904
2472.94	5.55416
2475.71	5.66486
2478.48	5.09055
2481.25	5.01691
2484.02	4.20857
2486.8	3.18794
2489.56	1.34919
2492.33	0.53614
2495.1	0.621695
2497.86	-0.0588294
2500.63	-0.299712
2503.39	0.422958
2506.16	1.27263
2508.92	1.20605
2511.68	2.43351
2514.44	2.40342
2517.2	2.55782
2519.95	2.7411
2522.71	2.94488
2525.47	3.59895
2528.22	4.91218
2530.98	5.65496
2533.73	6.34857
2536.48	6.40232
2539.23	7.84804
2541.98	8.68067
2544.73	8.87094
2547.48	8.68388
2550.23	7.92624
2552.97	7.3527
2555.72	5.94351
2558.46	4.72171
2561.2	4.29357
2563.95	4.83735
2566.69	4.59319
2569.43	5.12805
2572.17	5.04711
2574.91	5.70617
2577.64	6.08098
2580.38	6.54462
2583.11	6.63615
2585.85	7.08399
2588.58	6.42856
2591.31	6.31519
2594.04	7.04921
2596.78	6.46773
2599.51	6.21998
2602.23	6.72984
2604.96	7.16924
2607.69	6.66001
2610.41	5.98878
2613.14	6.3032
2615.86	5.45285
2618.58	5.24497
2621.3	4.89329
2624.03	4.68017
2626.75	4.36517
2629.46	4.45388
2632.18	4.06682
2634.9	4.63643
2637.61	4.93861
2640.33	5.18444
2643.04	5.05878
2645.76	6.07321
2648.47	6.01234
2651.18	5.53977
2653.89	4.23303
2656.6	3.84606
2659.31	3.34422
2662.01	3.48617
2664.72	2.52583
2667.43	2.98234
2670.13	2.74968
2672.83	2.54317
2675.53	3.1993
2678.24	3.98514
2680.94	4.57367
2683.64	5.74505
2686.34	6.64275
2689.03	7.17964
2691.73	6.62315
2694.43	6.19
2697.12	6.43995
2699.81	7.07181
2702.51	7.27634
2705.2	7.41776
2707.89	6.10488
2710.58	6.14467
2713.27	5.9621
2715.96	5.38198
2718.64	4.44369
2721.33	4.2024
2724.01	5.0636
2726.7	4.7119
2729.38	5.01529
2732.06	4.86674
2734.75	5.05911
2737.43	4.84506
2740.11	5.72357
2742.78	6.89577
2745.46	7.05772
2748.14	8.07905
2750.81	6.71304
2753.49	6.54028
2756.16	5.87536
2758.84	5.2239
2761.51	4.98572
2764.18	4.71467
2766.85	3.3025
2769.52	2.01217
2772.19	1.18305
2774.85	0.691821
2777.52	-0.238833
2780.18	-0.344316
2782.85	-0.845982
2785.51	-0.409314
2788.17	-0.623838
2790.84	-0.323743
2793.5	-0.422923
2796.16	-0.591898
2798.81	-0.815442
2801.47	-0.375753
2804.13	1.1755
2806.79	1.41596
2809.44	0.518156
2812.09	0.0256556
2814.75	0.570044
2817.4	0.965447
2820.05	3.71786
2822.7	6.20375
2825.35	9.54347
2828	12.9299
2830.65	16.2153
2833.29	20.7396
2835.94	25.1147
2838.58	30.093
2841.23	34.9651
2843.87	40.4087
2846.51	47.0016
2849.15	52.9532
2851.79	59.9004
2854.43	66.5187
2857.07	74.0262
2859.71	80.745
2862.34	87.2126
2864.98	92.9797
2867.61	97.9948
2870.25	101.04
2872.88	103.972
2875.51	106.764
2878.14	110.622
2880.77	113.588
2883.4	117.041
2886.03	120.387
2888.65	123.559
2891.28	127.463
2893.91	130.58
2896.53	134.261
2899.15	138.887
2901.78	143.393
2904.4	150.681
2907.02	158.241
2909.64	166.774
2912.26	176.688
2914.87	186.231
2917.49	195.444
2920.11	205.079
2922.72	212.46
2925.34	218.076
2927.95	223.042
2930.56	225.449
2933.17	227.506
2935.78	226.861
2938.39	224.974
2941	221.899
2943.61	217.402
2946.22	210.401
2948.82	202.341
2951.43	194.018
2954.03	183.887
2956.64	173.145
2959.24	162.809
2961.84	153.499
2964.44	143.26
2967.04	133.992
2969.64	125.218
2972.24	117.076
2974.83	108.953
2977.43	101.107
2980.02	93.2619
2982.62	85.5236
2985.21	78.4601
2987.8	69.8961
2990.4	62.5804
2992.99	56.0497
2995.57	49.9041
2998.16	43.4965
3000.75	37.3986
3003.34	31.9934
3005.92	27.6614
3008.51	23.0883
3011.09	18.5216
3013.68	14.9361
3016.26	11.4493
3018.84	9.04688
3021.42	6.29338
3024	5.08803
3026.58	3.34731
3029.16	2.89576
3031.73	3.21371
3034.31	2.27267
3036.89	2.7524
3039.46	2.07769
3042.03	2.32172
3044.61	1.86209
3047.18	3.03152
3049.75	2.93889
3052.32	3.53554
3054.89	3.01094
3057.45	2.5148
3060.02	1.93034
3062.59	2.44708
3065.15	2.67349
3067.72	2.32724
3070.28	2.01628
3072.84	2.05753
3075.41	1.81598
3077.97	1.67593
3080.53	0.84909
3083.09	-0.0287548
3085.64	-0.191665
3088.2	-0.286457
3090.76	0.313065
3093.31	0.229005
3095.87	-0.190125
3098.42	-0.255996
3100.97	0.170536
3103.53	-0.170686
3106.08	1.79352
3108.63	2.25019
3111.18	2.04798
3113.73	2.55171
3116.27	2.95468
3118.82	2.80262
3121.37	3.4022
3123.91	4.51905
3126.45	4.66639
3129	4.9352
3131.54	5.50987
3134.08	6.45869
3136.62	6.41388
3139.16	6.79493
3141.7	6.90405
3144.24	7.32899
3146.78	7.93543
3149.31	9.29771