File: data/Raman/poly_smoothed/Mb_40_24_42_1x_45s_532 nm_x100_100%_600 gr_mm_01.txt
#Acq. time (s)=	45
#Accumulations=	2
#Range (cm-¹)=	200...3150
#Windows=	2
#Auto scanning=	Off
#Autofocus=	Off
#Macrospot=	Off
#AutoExposure=	Off
#Spike filter=	Multiple accum.
#Delay time (s)=	0
#Binning=	1
#Readout mode=	Signal
#DeNoise=	Off
#ICS correction=	On
#Dark correction=	Off
#Inst. Process=	Off
#Detector Gain=	Best Dynamic Range
#Detector ADC=	20 kHz
#Detector temperature (°C)=	-70.08
#Instrument=	LabRAM HR Evol
#Detector=	Synapse
#Objective=	x100
#Grating=	600 gr/mm
#ND Filter=	100%
#Laser (nm)=	532
#Hole=	100.021
#Range=	Auto
#Laser Pol.=	No
#Raman. Pol.=	No
#Laser Pol. (°)=	-0.0007625
#Raman Pol. (°)=	89.9995
#Collection=	Microscope
#StageXY=	Marzhauser
#StageZ=	Marzhauser
#X (µm)=	-2491.4
#Y (µm)=	-29.7
#Z (µm)=	-10.1
#Full time(mm:ss)=	3:15
#Project=
#Sample=
#Site=
#Title=	Mb_40_24_42_2x_45s_532 nm_x100_100%_600 gr_mm
#Remark=
#Date=	14.07.2022 14:00
#Acquired=	14.07.2022 14:00:31
#Edit:Spike=	10.08.2022 10:43:35
#Edit:Spike=	10.08.2022 10:43:36
#Base:Fit=	10.08.2022 10:47:00
#Base:Sub=	10.08.2022 10:47:12
#Filter:Polynom=	16.08.2022 10:11:48
#AxisType[0]=Intens
#AxisUnit[0]=Cnt
#AxisType[1]=Spectr
#AxisUnit[1]=1/cm
200.554	12.244
204.183	16.6896
207.813	18.1675
211.439	18.1887
215.065	16.9448
218.688	16.1983
222.312	15.7382
225.933	13.7322
229.552	11.6798
233.171	8.78989
236.787	8.96602
240.402	9.76195
244.015	8.33477
247.627	6.94394
251.24	5.04124
254.849	2.38331
258.457	2.04482
262.063	3.03392
265.668	5.87632
269.271	6.96739
272.873	7.61682
276.474	9.85274
280.073	10.924
283.671	11.3012
287.268	12
290.863	13.109
294.456	10.0721
298.049	11.1223
301.637	11.5196
305.227	12.2807
308.815	11.9375
312.402	12.1081
315.987	10.7255
319.569	9.7464
323.151	10.9896
326.733	11.0807
330.31	10.9233
333.889	11.2248
337.464	11.4798
341.039	9.68594
344.611	8.60694
348.184	9.18705
351.754	11.0142
355.324	11.1519
358.89	11.5579
362.455	10.8914
366.021	11.3717
369.584	10.6152
373.145	9.0703
376.707	8.82071
380.265	6.37552
383.822	6.18605
387.378	4.86889
390.934	5.74339
394.487	6.54737
398.038	7.13921
401.588	5.23352
405.137	6.1078
408.685	7.39014
412.23	7.80027
415.775	8.01961
419.318	9.09029
422.86	7.9591
426.401	7.42139
429.94	6.03258
433.478	5.81413
437.012	8.33086
440.547	8.14239
444.081	8.25962
447.613	8.19866
451.142	8.72135
454.672	9.34339
458.2	9.60299
461.725	9.37708
465.251	8.7469
468.775	11.5186
472.296	14.4114
475.817	15.6371
479.335	20.1323
482.854	22.1458
486.37	21.8798
489.886	24.4095
493.398	28.1894
496.91	28.4901
500.422	31.0038
503.93	32.2852
507.438	34.986
510.946	33.5215
514.45	34.1741
517.954	34.2957
521.456	33.6518
524.956	33.8765
528.456	33.7011
531.956	32.5663
535.452	30.6717
538.947	27.8145
542.441	25.5226
545.934	24.4957
549.425	23.9017
552.915	23.8607
556.403	23.4712
559.889	22.5981
563.375	22.1245
566.859	18.2494
570.342	16.5254
573.824	13.8163
577.303	13.759
580.782	11.3949
584.26	11.6645
587.734	11.8091
591.21	10.8774
594.684	9.88283
598.154	7.61314
601.626	7.50106
605.094	5.91605
608.562	5.1292
612.027	6.2781
615.493	-2.59699
618.956	-5.4188
622.419	1.4509
625.879	8.67963
629.338	17.2926
632.797	25.2232
636.254	31.0609
639.708	36.1663
643.162	40.7449
646.614	42.1732
650.067	43.3833
653.516	44.3214
656.964	43.982
660.411	44.0791
663.857	44.4609
667.301	43.3929
670.744	41.0417
674.186	40.1819
677.626	37.3717
681.065	34.2237
684.503	28.3615
687.939	24.0373
691.372	18.5929
694.806	14.2514
698.239	6.72927
701.67	6.41845
705.098	14.7098
708.526	17.6295
711.954	19.7131
715.378	22.3193
718.802	23.7852
722.226	22.378
725.646	21.169
729.067	20.3806
732.484	20.8085
735.902	21.6298
739.317	21.8145
742.731	23.472
746.145	25.6119
749.556	27.6566
752.966	30.0901
756.377	34.4565
759.784	36.9796
763.19	37.8421
766.594	42.8023
770	45.9991
773.402	49.0193
776.803	51.2215
780.202	54.3938
783.6	56.7398
786.997	59.4589
790.393	63.5536
793.787	66.2198
797.18	69.1775
800.572	71.1957
803.963	73.6187
807.35	74.2525
810.738	73.474
814.125	74.5883
817.51	75.5158
820.894	75.3772
824.275	76.9108
827.657	77.5932
831.037	78.6485
834.414	78.0751
837.792	79.4729
841.167	79.0716
844.542	76.3427
847.914	74.985
851.287	72.2579
854.656	69.3711
858.026	67.8088
861.393	66.3887
864.761	65.1324
868.125	62.1263
871.489	61.2583
874.85	60.661
878.213	57.3841
881.572	55.2263
884.931	54.3639
888.287	52.0443
891.643	47.8513
894.997	46.4742
898.352	46.9154
901.704	45.5043
905.055	48.2359
908.404	49.5119
911.75	49.4771
915.097	49.5579
918.443	50.6106
921.787	51.1223
925.13	48.0171
928.472	45.8495
931.813	44.6497
935.15	44.6315
938.488	45.5644
941.825	42.4237
945.158	39.101
948.493	36.1803
951.824	36.3235
955.156	35.0311
958.486	32.8327
961.814	31.0364
965.142	31.2247
968.467	33.2792
971.79	34.2026
975.115	35.2851
978.436	37.0054
981.756	38.9659
985.077	39.8614
988.394	39.4327
991.71	39.6877
995.025	41.728
998.341	41.5582
1001.65	41.9864
1004.97	42.3558
1008.28	42.3121
1011.58	45.3403
1014.89	49.2186
1018.2	52.7412
1021.5	53.0974
1024.81	56.1136
1028.11	59.6393
1031.41	64.8788
1034.71	67.65
1038.01	70.3844
1041.31	71.5085
1044.6	76.2307
1047.9	77.2315
1051.19	77.1196
1054.48	74.6421
1057.77	71.7895
1061.06	70.2907
1064.35	66.4196
1067.64	61.6029
1070.93	58.9446
1074.21	56.4837
1077.49	53.4141
1080.78	51.2508
1084.06	48.5683
1087.34	46.4984
1090.61	46.2411
1093.89	48.4028
1097.17	49.8171
1100.44	48.7287
1103.71	50.0939
1106.99	49.9725
1110.26	49.8972
1113.52	48.4068
1116.79	48.0687
1120.06	45.6245
1123.32	45.2166
1126.59	40.8747
1129.85	36.8474
1133.11	32.8454
1136.37	30.1971
1139.63	30.0005
1142.89	27.2621
1146.15	23.4788
1149.4	20.3994
1152.66	18.138
1155.91	15.5561
1159.16	12.0573
1162.41	8.96465
1165.66	5.8658
1168.91	6.75102
1172.16	5.32944
1175.4	6.72244
1178.65	6.44127
1181.89	5.90259
1185.13	7.26482
1188.37	9.11585
1191.61	11.2069
1194.85	13.1081
1198.08	16.5572
1201.32	20.2647
1204.55	22.8077
1207.79	25.3439
1211.02	28.5611
1214.25	33.3019
1217.48	38.8042
1220.71	42.9306
1223.93	46.9018
1227.16	50.9122
1230.38	54.2099
1233.6	59.6205
1236.83	62.6691
1240.05	68.329
1243.26	72.2218
1246.48	75.0773
1249.7	78.8011
1252.92	82.0685
1256.13	86.4082
1259.34	90.161
1262.55	96.0031
1265.76	101.402
1268.97	104.975
1272.18	109.083
1275.39	114.26
1278.59	119.534
1281.8	124.426
1285	127.049
1288.2	130.803
1291.4	133.003
1294.6	135.576
1297.8	139.975
1301	140.632
1304.19	139.521
1307.39	140.507
1310.58	138.354
1313.77	137.535
1316.96	135.025
1320.15	132.637
1323.34	128.249
1326.53	123.05
1329.72	120.009
1332.9	115.53
1336.08	113.88
1339.27	110.187
1342.45	107.274
1345.63	103.327
1348.8	99.978
1351.98	99.3422
1355.16	97.8111
1358.33	96.4477
1361.51	94.7721
1364.68	92.6213
1367.85	90.6169
1371.02	88.7754
1374.19	87.8062
1377.36	89.1494
1380.52	89.6893
1383.69	89.6114
1386.85	90.0615
1390.02	91.1839
1393.18	93.0726
1396.34	94.7571
1399.5	97.6494
1402.65	101.055
1405.81	107.121
1408.97	113.837
1412.12	120.804
1415.27	131.402
1418.43	139.263
1421.58	150.027
1424.73	160.967
1427.87	174.633
1431.02	186.722
1434.17	195.339
1437.31	204.809
1440.46	211.754
1443.6	217.006
1446.74	219.768
1449.88	219.291
1453.02	217.421
1456.16	213.061
1459.29	205.913
1462.43	196.115
1465.56	184.966
1468.69	171.206
1471.83	157.328
1474.95	142.077
1478.08	128.376
1481.21	113.56
1484.34	99.6702
1487.47	87.6639
1490.59	77.6187
1493.71	68.4184
1496.84	60.5658
1499.96	54.7227
1503.07	49.5888
1506.19	46.4516
1509.31	41.367
1512.43	37.6255
1515.54	36.2841
1518.65	35.76
1521.77	36.0508
1524.88	34.9147
1527.99	35.7441
1531.1	38.5701
1534.21	41.5699
1537.31	43.0549
1540.42	43.9861
1543.52	45.5679
1546.63	48.2015
1549.73	50.3725
1552.83	53.3701
1555.93	55.1423
1559.03	59.5879
1562.12	61.6331
1565.22	66.8974
1568.31	70.6876
1571.41	75.5161
1574.5	80.7411
1577.59	86.277
1580.68	93.5225
1583.77	96.7731
1586.86	101.016
1589.95	106.888
1593.03	111.809
1596.11	115.414
1599.2	116.507
1602.28	118.656
1605.36	122.107
1608.44	124.42
1611.52	125.118
1614.6	125.98
1617.67	126.666
1620.75	128.377
1623.82	131.892
1626.89	132.692
1629.96	133.349
1633.04	135.21
1636.11	136.349
1639.17	138.216
1642.24	140.055
1645.31	142.025
1648.37	143.09
1651.43	143.799
1654.5	144.662
1657.56	142.102
1660.62	138.006
1663.67	134.361
1666.73	127.274
1669.79	120.951
1672.84	114.332
1675.9	106.277
1678.95	98.2161
1682	91.2563
1685.05	84.7376
1688.1	76.9651
1691.15	69.9844
1694.2	62.5011
1697.25	57.0653
1700.29	51.7312
1703.33	46.4092
1706.38	42.3286
1709.42	38.1268
1712.46	35.1027
1715.5	31.8266
1718.54	28.0894
1721.57	26.1828
1724.61	24.3003
1727.64	23.8556
1730.68	21.0778
1733.71	19.6156
1736.74	17.5116
1739.77	17.0984
1742.8	16.7826
1745.83	16.3592
1748.85	15.4174
1751.88	13.7988
1754.91	13.1355
1757.93	13.397
1760.95	12.0645
1763.97	10.2338
1766.99	8.69804
1770.01	8.3652
1773.03	8.62889
1776.04	7.54022
1779.06	7.51911
1782.07	6.73423
1785.09	5.90016
1788.1	5.54184
1791.11	4.4432
1794.12	3.9977
1797.13	3.31696
1800.13	3.0803
1803.14	2.89322
1806.15	1.22406
1809.15	2.50764
1812.15	2.39889
1815.16	1.4898
1818.15	1.6361
1821.16	0.588123
1824.15	1.24272
1827.15	1.59723
1830.15	1.95256
1833.14	2.05195
1836.14	1.01004
1839.13	1.19402
1842.12	1.84611
1845.11	2.41928
1848.1	2.34031
1851.09	3.45342
1854.08	4.09451
1857.06	3.62529
1860.05	3.0144
1863.03	2.33154
1866.01	2.79468
1869	2.90067
1871.98	3.10193
1874.96	4.35099
1877.93	4.18719
1880.91	6.16594
1882.47	5.89083
1885.46	7.0071
1888.44	8.10133
1891.43	8.7876
1894.42	8.81601
1897.4	9.29556
1900.39	10.0306
1903.37	9.14163
1906.35	9.01772
1909.33	9.23374
1912.31	9.98014
1915.29	10.3559
1918.26	10.2401
1921.24	11.0693
1924.21	10.9778
1927.19	9.85835
1930.16	8.99007
1933.13	8.23153
1936.1	7.33902
1939.07	6.67397
1942.04	6.13476
1945	6.33348
1947.97	6.15334
1950.93	5.85094
1953.9	4.15927
1956.86	3.41376
1959.82	2.96157
1962.78	1.70135
1965.74	0.334678
1968.7	-0.0954162
1971.65	-0.854193
1974.61	-0.800333
1977.57	-0.490801
1980.52	-0.520145
1983.47	-0.148223
1986.42	1.12585
1989.37	0.448836
1992.32	0.661572
1995.27	0.848383
1998.22	1.79428
2001.17	1.88257
2004.11	2.15227
2007.05	1.54729
2010	1.74011
2012.94	2.94843
2015.88	3.57874
2018.82	4.39866
2021.76	4.42158
2024.7	5.94313
2027.63	6.96532
2030.57	7.79574
2033.5	8.60958
2036.44	9.39253
2039.37	9.64828
2042.3	10.1127
2045.23	10.8132
2048.16	12.7306
2051.08	13.2392
2054.01	12.8879
2056.94	14.2603
2059.86	15.5187
2062.79	16.4011
2065.71	18.6601
2068.63	20.0378
2071.55	21.7164
2074.47	22.8728
2077.39	24.7878
2080.31	26.9226
2083.22	29.8592
2086.13	32.2352
2089.05	34.9229
2091.96	37.2666
2094.87	39.8043
2097.78	42.6539
2100.69	43.7768
2103.6	46.1849
2106.51	48.4883
2109.42	51.3814
2112.32	54.1356
2115.23	56.7927
2118.13	60.4848
2121.03	65.4536
2123.93	68.9443
2126.83	73.0734
2129.73	78.5862
2132.63	83.6516
2135.53	89.3221
2138.42	93.2622
2141.32	98.9154
2144.21	103.122
2147.1	108.541
2150	114.068
2152.89	120.047
2155.78	125.078
2158.66	128.895
2161.55	132.993
2164.44	135.281
2167.32	137.682
2170.21	138.428
2173.09	138.897
2175.97	138.745
2178.85	137.694
2181.73	135.877
2184.61	132.494
2187.49	129.108
2190.37	124.055
2193.24	118.429
2196.12	113.426
2198.99	108.202
2201.87	102.502
2204.74	96.3542
2207.61	90.4058
2210.48	84.5048
2213.35	79.3286
2216.21	73.7049
2219.08	70.5247
2221.95	66.7122
2224.81	64.1289
2227.67	59.5423
2230.54	56.0352
2233.4	52.0484
2236.26	49.5907
2239.11	47.2525
2241.97	44.4682
2244.83	43.3163
2247.69	41.6573
2250.54	39.8279
2253.4	37.7155
2256.25	35.3119
2259.1	31.0954
2261.95	29.1978
2264.8	28.7432
2267.65	27.6439
2270.5	25.5871
2273.34	24.3863
2276.19	23.871
2279.03	22.1787
2281.88	21.9889
2284.72	20.4305
2287.56	19.0223
2290.4	17.5113
2293.24	16.0201
2296.08	15.3036
2298.92	13.8856
2301.76	14.2099
2304.59	13.6895
2307.43	14.6279
2310.26	14.4504
2313.09	14.9652
2315.92	15.7673
2318.75	15.3364
2321.58	15.0566
2324.41	14.3784
2327.24	13.6674
2330.06	12.5253
2332.89	12.7879
2335.71	12.4923
2338.54	10.9299
2341.36	10.9757
2344.18	9.90177
2347	8.2045
2349.82	7.44722
2352.64	6.07511
2355.45	3.84362
2358.27	2.73491
2361.08	1.52945
2363.9	0.818712
2366.71	1.01136
2369.52	1.5034
2372.33	1.25794
2375.14	1.46128
2377.95	2.30146
2380.76	2.9793
2383.57	4.19116
2386.37	4.69982
2389.18	5.60199
2391.98	6.56818
2394.79	5.68027
2397.59	5.95192
2400.39	5.90049
2403.19	6.30216
2405.99	5.96595
2408.78	5.65854
2411.58	4.81538
2414.38	3.73867
2417.17	4.34056
2419.97	3.47184
2422.76	3.4733
2425.55	3.10137
2428.34	2.69562
2431.13	2.36047
2433.92	2.42811
2436.71	2.74553
2439.49	2.3339
2442.28	2.3421
2445.06	2.6853
2447.85	3.10543
2450.63	3.08209
2453.41	2.21458
2456.19	2.35657
2458.97	2.16718
2461.75	1.61829
2464.53	0.638191
2467.31	0.901559
2470.08	0.0329911
2472.86	0.942306
2475.63	0.894057
2478.4	1.47249
2481.17	1.43878
2483.94	1.6176
2486.72	2.93579
2489.48	2.11076
2492.25	2.52451
2495.02	3.15163
2497.79	2.81813
2500.55	2.09402
2503.31	1.59294
2506.08	1.45965
2508.84	0.669653
2511.6	1.13028
2514.36	-0.329972
2517.12	-0.705758
2519.88	-1.49942
2522.63	-1.79738
2525.39	-1.73754
2528.14	-2.07019
2530.9	-1.52859
2533.65	-0.0191748
2536.4	1.17224
2539.15	2.2999
2541.9	3.46673
2544.65	3.24872
2547.4	4.38827
2550.15	4.68821
2552.89	4.95669
2555.64	6.43372
2558.38	5.65272
2561.12	6.34003
2563.87	5.85772
2566.61	5.51894
2569.35	6.23883
2572.09	5.92307
2574.83	6.13437
2577.56	6.02483
2580.3	5.12955
2583.04	5.16569
2585.77	4.53077
2588.5	3.63868
2591.23	3.98555
2593.97	4.96636
2596.7	6.33317
2599.43	6.72421
2602.15	6.66173
2604.88	5.95042
2607.61	5.98137
2610.33	5.28393
2613.06	5.45694
2615.78	5.20324
2618.51	3.92224
2621.23	3.89794
2623.95	3.42814
2626.67	2.69171
2629.39	3.02802
2632.1	4.35098
2634.82	4.60792
2637.54	5.57404
2640.25	5.88177
2642.97	6.56804
2645.68	8.10214
2648.39	8.20845
2651.1	8.49394
2653.81	8.82628
2656.52	9.49845
2659.23	10.5556
2661.94	9.51697
2664.64	10.0647
2667.35	9.42119
2670.05	8.81996
2672.76	9.02106
2675.46	7.96536
2678.16	7.30097
2680.86	7.328
2683.56	7.46821
2686.26	7.07501
2688.96	6.69623
2691.65	6.3524
2694.35	7.62983
2697.04	11.072
2699.74	12.6511
2702.43	13.9216
2705.12	16.8885
2707.81	18.0483
2710.5	20.4401
2713.19	21.9255
2715.88	23.4987
2718.57	24.3471
2721.25	24.5788
2723.94	25.0396
2726.62	24.8822
2729.3	23.9905
2731.99	23.1756
2734.67	22.8512
2737.35	21.6818
2740.03	19.968
2742.71	18.3386
2745.38	17.4297
2748.06	14.5752
2750.74	11.831
2753.41	9.41322
2756.09	7.61399
2758.76	7.05823
2761.43	6.49333
2764.1	5.58316
2766.77	4.35532
2769.44	3.29515
2772.11	2.76264
2774.77	1.33348
2777.44	0.916955
2780.11	1.09111
2782.77	1.4963
2785.43	1.27876
2788.1	1.29011
2790.76	1.16811
2793.42	2.00188
2796.08	2.85794
2798.74	3.67338
2801.4	4.54303
2804.05	4.43004
2806.71	4.45313
2809.36	2.77425
2812.02	0.604606
2814.67	2.57379
2817.32	8.15721
2819.97	16.9669
2822.62	27.3518
2825.27	40.2931
2827.92	54.3077
2830.57	70.3531
2833.22	87.3837
2835.86	105.558
2838.51	124.582
2841.15	143.782
2843.79	163.716
2846.43	183.32
2849.08	202.23
2851.72	223.282
2854.36	246.223
2856.99	267.93
2859.63	288.538
2862.27	307.392
2864.9	323.176
2867.54	336.654
2870.17	347.882
2872.8	357.336
2875.43	367.544
2878.07	378.588
2880.7	390.223
2883.32	402.847
2885.95	412.862
2888.58	424.6
2891.21	435.557
2893.83	445.915
2896.46	457.071
2899.08	469.108
2901.7	479.032
2904.32	491.778
2906.94	505.766
2909.56	521.044
2912.18	538.885
2914.8	559.018
2917.42	578.045
2920.03	594.347
2922.65	605.558
2925.26	613.64
2927.88	617.77
2930.49	616.201
2933.1	613.336
2935.71	604.826
2938.32	592.825
2940.93	576.793
2943.54	557.598
2946.14	536.859
2948.75	514.787
2951.35	491.15
2953.96	464.999
2956.56	437.947
2959.16	411.577
2961.77	386.237
2964.37	363.128
2966.96	341.108
2969.56	321.794
2972.16	304.98
2974.76	288.735
2977.35	271.017
2979.95	254.766
2982.54	237.085
2985.14	219.454
2987.73	201.73
2990.32	182.985
2992.91	165.985
2995.5	149.11
2998.09	133.176
3000.68	116.473
3003.26	101.352
3005.85	88.1094
3008.43	75.9657
3011.02	64.1245
3013.6	52.2624
3016.19	41.6722
3018.77	32.1644
3021.35	26.1171
3023.93	20.6164
3026.5	16.5602
3029.08	13.4355
3031.66	11.508
3034.24	10.793
3036.81	10.5095
3039.39	9.14684
3041.96	9.15521
3044.53	10.0762
3047.1	10.3024
3049.67	11.067
3052.24	11.9395
3054.81	12.162
3057.38	11.9608
3059.95	11.7507
3062.52	11.2601
3065.08	10.3697
3067.65	9.34964
3070.21	8.58575
3072.77	6.49748
3075.33	5.77102
3077.89	4.77883
3080.45	2.80283
3083.01	1.63914
3085.57	1.20206
3088.13	1.19206
3090.68	0.67199
3093.24	0.496101
3095.79	0.509561
3098.35	0.98974
3100.9	2.00058
3103.45	3.07699
3106	4.979
3108.55	6.71477
3111.1	8.45579
3113.65	9.93771
3116.2	11.1184
3118.75	12.2193
3121.29	13.7799
3123.84	15.4727
3126.38	17.9254
3128.92	20.0761
3131.47	22.5557
3134.01	24.6352
3136.55	27.2075
3139.09	29.969
3141.63	31.481
3144.17	33.8063
3146.7	35.9816
3149.24	37.6622