File: data/Raman/poly_smoothed/Mb_40_24_48_1x_45s_532 nm_x100_100%_600 gr_mm_01.txt
#Acq. time (s)=	45
#Accumulations=	2
#Range (cm-¹)=	200...3150
#Windows=	2
#Auto scanning=	Off
#Autofocus=	Off
#Macrospot=	Off
#AutoExposure=	Off
#Spike filter=	Multiple accum.
#Delay time (s)=	0
#Binning=	1
#Readout mode=	Signal
#DeNoise=	Off
#ICS correction=	On
#Dark correction=	Off
#Inst. Process=	Off
#Detector Gain=	Best Dynamic Range
#Detector ADC=	20 kHz
#Detector temperature (°C)=	-70.08
#Instrument=	LabRAM HR Evol
#Detector=	Synapse
#Objective=	x100
#Grating=	600 gr/mm
#ND Filter=	100%
#Laser (nm)=	532
#Hole=	100.021
#Range=	Auto
#Laser Pol.=	No
#Raman. Pol.=	No
#Laser Pol. (°)=	-0.0007625
#Raman Pol. (°)=	89.9995
#Collection=	Microscope
#StageXY=	Marzhauser
#StageZ=	Marzhauser
#X (µm)=	-2453
#Y (µm)=	-49.2
#Z (µm)=	-10.05
#Full time(mm:ss)=	3:19
#Project=
#Sample=
#Site=
#Title=	Mb_40_24_48_2x_45s_532 nm_x100_100%_600 gr_mm
#Remark=
#Date=	14.07.2022 14:24
#Acquired=	14.07.2022 14:24:21
#Base:Fit=	10.08.2022 10:47:00
#Base:Sub=	10.08.2022 10:47:12
#Filter:Polynom=	16.08.2022 10:11:48
#AxisType[0]=Intens
#AxisUnit[0]=Cnt
#AxisType[1]=Spectr
#AxisUnit[1]=1/cm
200.554	1.87985
204.183	4.13124
207.813	3.96731
211.439	2.54014
215.065	1.40663
218.688	3.60569
222.312	2.80308
225.933	2.65424
229.552	1.66667
233.171	1.33171
236.787	1.96282
240.402	2.25176
244.015	3.45836
247.627	5.13991
251.24	6.55926
254.849	6.81582
258.457	6.31397
262.063	6.73807
265.668	7.64663
269.271	7.85776
272.873	8.37499
276.474	8.49234
280.073	9.74754
283.671	10.9815
287.268	11.352
290.863	10.576
294.456	9.17476
298.049	8.55197
301.637	8.71092
305.227	8.84057
308.815	7.60203
312.402	5.78268
315.987	6.93054
319.569	5.82899
323.151	6.53412
326.733	7.32002
330.31	6.76574
333.889	6.0155
337.464	5.7152
341.039	5.61219
344.611	5.3976
348.184	4.82055
351.754	4.91382
355.324	6.24369
358.89	6.91379
362.455	7.13999
366.021	8.09098
369.584	8.7076
373.145	7.59045
376.707	7.84964
380.265	7.93773
383.822	5.09896
387.378	4.86969
390.934	5.32176
394.487	5.13312
398.038	3.08283
401.588	5.5196
405.137	6.64587
408.685	6.14733
412.23	5.92516
415.775	4.69871
419.318	4.1177
422.86	4.64805
426.401	4.16018
429.94	4.78748
433.478	4.54882
437.012	3.54516
440.547	4.7972
444.081	6.39423
447.613	6.29838
451.142	7.35186
454.672	7.23954
458.2	6.39637
461.725	6.75191
465.251	7.49902
468.775	6.23976
472.296	5.75206
475.817	6.0755
479.335	6.18985
482.854	5.36862
486.37	7.11782
489.886	7.77913
493.398	5.80773
496.91	6.82029
500.422	5.83636
503.93	5.60354
507.438	7.05115
510.946	6.09704
514.45	6.50764
517.954	7.42967
521.456	8.17547
524.956	9.46653
528.456	9.63484
531.956	9.9821
535.452	9.91172
538.947	9.68998
542.441	8.81623
545.934	9.16955
549.425	9.00407
552.915	8.63559
556.403	8.25806
559.889	7.83917
563.375	7.41279
566.859	6.33114
570.342	5.64483
573.824	5.87408
577.303	4.32528
580.782	4.08418
584.26	4.75059
587.734	3.28103
591.21	4.53533
594.684	5.41967
598.154	6.67184
601.626	8.83301
605.094	9.61229
608.562	10.734
612.027	11.4758
615.493	11.37
618.956	11.6766
622.419	12.6006
625.879	14.6022
629.338	14.8187
632.797	17.2314
636.254	18.4967
639.708	18.5641
643.162	18.1705
646.614	16.7097
650.067	16.764
653.516	17.1343
656.964	16.188
660.411	15.958
663.857	16.7605
667.301	17.6107
670.744	18.8989
674.186	19.6029
677.626	22.9815
681.065	24.4813
684.503	26.6357
687.939	28.0874
691.372	30.7195
694.806	31.5434
698.239	32.3532
701.67	34.4555
705.098	36.5863
708.526	40.1346
711.954	42.972
715.378	44.0493
718.802	46.5607
722.226	46.3624
725.646	47.1684
729.067	45.3089
732.484	46.0719
735.902	45.3015
739.317	45.3375
742.731	47.0511
746.145	49.1039
749.556	50.8069
752.966	51.5946
756.377	53.5589
759.784	54.6266
763.19	58.4845
766.594	59.7007
770	62.9279
773.402	65.6869
776.803	67.4436
780.202	70.9153
783.6	72.8711
786.997	77.0035
790.393	79.7953
793.787	81.9022
797.18	82.6252
800.572	82.3346
803.963	81.9366
807.35	82.1324
810.738	81.7265
814.125	82.4919
817.51	81.7229
820.894	80.7314
824.275	81.75
827.657	80.5689
831.037	79.5526
834.414	76.6349
837.792	75.3914
841.167	74.4124
844.542	72.9145
847.914	74.1381
851.287	73.4277
854.656	71.4813
858.026	70.3705
861.393	68.5523
864.761	66.9426
868.125	64.4349
871.489	63.2645
874.85	61.9118
878.213	58.5394
881.572	56.5385
884.931	56.0726
888.287	55.9253
891.643	54.5559
894.997	55.8045
898.352	55.1495
901.704	53.9529
905.055	54.6297
908.404	52.5808
911.75	51.522
915.097	51.6437
918.443	51.7036
921.787	51.2883
925.13	50.0693
928.472	49.9888
931.813	49.1449
935.15	46.7964
938.488	45.9478
941.825	44.5231
945.158	40.6637
948.493	39.252
951.824	39.242
955.156	36.9918
958.486	34.0531
961.814	32.5595
965.142	31.8622
968.467	29.6431
971.79	28.5135
975.115	28.0336
978.436	27.268
981.756	27.6341
985.077	27.3941
988.394	26.9473
991.71	26.5551
995.025	26.2593
998.341	25.1723
1001.65	24.1208
1004.97	23.5106
1008.28	22.8279
1011.58	23.4145
1014.89	25.0255
1018.2	24.2354
1021.5	26.4767
1024.81	26.0698
1028.11	26.2765
1031.41	28.3065
1034.71	27.817
1038.01	28.3893
1041.31	27.8699
1044.6	29.2185
1047.9	29.0647
1051.19	27.9166
1054.48	26.8462
1057.77	27.1446
1061.06	28.0781
1064.35	28.8896
1067.64	28.271
1070.93	26.2828
1074.21	25.3112
1077.49	23.3291
1080.78	20.9228
1084.06	20.916
1087.34	18.7179
1090.61	18.5172
1093.89	18.9945
1097.17	18.5955
1100.44	19.2886
1103.71	18.8751
1106.99	17.1697
1110.26	18.4883
1113.52	17.2772
1116.79	15.9227
1120.06	17.1054
1123.32	15.6989
1126.59	15.6941
1129.85	14.8694
1133.11	13.307
1136.37	14.9102
1139.63	15.8878
1142.89	16.0516
1146.15	15.3972
1149.4	13.9582
1152.66	13.2203
1155.91	11.8828
1159.16	11.0393
1162.41	10.5702
1165.66	8.99012
1168.91	7.72153
1172.16	6.8565
1175.4	6.32058
1178.65	5.62091
1181.89	5.05266
1185.13	4.05456
1188.37	4.39052
1191.61	5.69282
1194.85	4.3582
1198.08	5.47032
1201.32	5.25745
1204.55	5.45237
1207.79	6.55039
1211.02	6.68135
1214.25	9.75852
1217.48	11.883
1220.71	12.0835
1223.93	13.5071
1227.16	15.6937
1230.38	19.0399
1233.6	21.3412
1236.83	23.0789
1240.05	23.8372
1243.26	25.4016
1246.48	25.6507
1249.7	27.3306
1252.92	28.7007
1256.13	30.7374
1259.34	32.9303
1262.55	33.1452
1265.76	33.766
1268.97	34.1214
1272.18	33.5552
1275.39	34.212
1278.59	33.5578
1281.8	33.7213
1285	34.4883
1288.2	35.1327
1291.4	34.8999
1294.6	36.495
1297.8	37.3947
1301	38.5532
1304.19	38.388
1307.39	40.3391
1310.58	39.7374
1313.77	38.5655
1316.96	37.8763
1320.15	38.2382
1323.34	37.3987
1326.53	37.3668
1329.72	35.8891
1332.9	34.4111
1336.08	34.7572
1339.27	32.7748
1342.45	31.7041
1345.63	32.3587
1348.8	32.0437
1351.98	33.016
1355.16	33.1918
1358.33	33.0556
1361.51	33.6994
1364.68	34.2072
1367.85	35.649
1371.02	37.3494
1374.19	39.9027
1377.36	40.3738
1380.52	40.2581
1383.69	39.1561
1386.85	39.3379
1390.02	39.6053
1393.18	39.4223
1396.34	40.2824
1399.5	40.5795
1402.65	40.4361
1405.81	40.0026
1408.97	40.4482
1412.12	42.131
1415.27	44.8688
1418.43	46.3437
1421.58	49.218
1424.73	51.9723
1427.87	54.0837
1431.02	56.6942
1434.17	58.6726
1437.31	60.3424
1440.46	61.6831
1443.6	63.7597
1446.74	64.6296
1449.88	64.4353
1453.02	63.5462
1456.16	61.2753
1459.29	58.7219
1462.43	56.2149
1465.56	55.2371
1468.69	51.3545
1471.83	47.5399
1474.95	44.9432
1478.08	40.7905
1481.21	36.857
1484.34	33.2022
1487.47	31.3256
1490.59	28.5303
1493.71	25.9596
1496.84	24.3765
1499.96	23.8501
1503.07	22.8244
1506.19	21.989
1509.31	21.5059
1512.43	21.0836
1515.54	19.6858
1518.65	19.3532
1521.77	20.0079
1524.88	20.4809
1527.99	19.2842
1531.1	19.1552
1534.21	20.1197
1537.31	19.9271
1540.42	20.9148
1543.52	21.8679
1546.63	21.8985
1549.73	22.3506
1552.83	22.7661
1555.93	25.5976
1559.03	26.6823
1562.12	26.8248
1565.22	26.6607
1568.31	28.6401
1571.41	32.884
1574.5	34.9604
1577.59	36.7516
1580.68	38.8711
1583.77	41.0799
1586.86	42.377
1589.95	43.3192
1593.03	43.1786
1596.11	43.3971
1599.2	44.2338
1602.28	44.0126
1605.36	42.9245
1608.44	42.0227
1611.52	41.934
1614.6	40.909
1617.67	41.9266
1620.75	40.6953
1623.82	41.3076
1626.89	41.1885
1629.96	40.808
1633.04	38.7862
1636.11	38.297
1639.17	38.5593
1642.24	40.4812
1645.31	41.9836
1648.37	42.258
1651.43	42.084
1654.5	42.3268
1657.56	41.7768
1660.62	41.7058
1663.67	40.2633
1666.73	38.4719
1669.79	37.5856
1672.84	36.4674
1675.9	35.1504
1678.95	32.9554
1682	31.5314
1685.05	29.3157
1688.1	27.2474
1691.15	23.5285
1694.2	20.8471
1697.25	18.092
1700.29	16.0487
1703.33	14.3129
1706.38	12.0619
1709.42	11.2175
1712.46	11.4443
1715.5	11.2791
1718.54	10.6679
1721.57	9.36467
1724.61	8.23663
1727.64	7.97388
1730.68	7.85649
1733.71	7.51881
1736.74	7.37906
1739.77	6.19276
1742.8	6.59189
1745.83	7.20927
1748.85	6.49552
1751.88	5.65054
1754.91	5.14075
1757.93	5.01399
1760.95	3.89988
1763.97	3.84128
1766.99	3.33989
1770.01	3.25819
1773.03	3.29408
1776.04	4.43698
1779.06	4.76663
1782.07	5.07266
1785.09	5.08995
1788.1	5.41752
1791.11	5.81183
1794.12	5.71534
1797.13	7.0651
1800.13	7.34682
1803.14	7.15253
1806.15	6.28766
1809.15	5.67033
1812.15	5.32477
1815.16	4.12793
1818.15	4.26512
1821.16	3.51144
1824.15	2.94914
1827.15	3.42096
1830.15	3.24823
1833.14	3.54573
1836.14	3.87662
1839.13	3.81609
1842.12	3.28304
1845.11	3.35303
1848.1	2.98922
1851.09	2.81061
1854.08	2.42569
1857.06	1.64789
1860.05	2.07431
1863.03	2.52299
1866.01	2.83844
1869	3.05361
1871.98	3.64876
1874.96	2.94469
1877.93	2.62499
1880.91	2.50281
1882.47	2.29425
1885.46	2.30586
1888.44	2.72751
1891.43	3.24024
1894.42	4.66416
1897.4	4.89796
1900.39	5.37208
1903.37	6.16241
1906.35	5.74929
1909.33	5.07777
1912.31	4.81935
1915.29	4.97714
1918.26	5.26288
1921.24	4.59153
1924.21	5.10813
1927.19	5.21673
1930.16	4.69821
1933.13	5.5232
1936.1	4.95355
1939.07	4.96131
1942.04	4.40456
1945	4.00343
1947.97	3.81371
1950.93	3.46841
1953.9	2.80487
1956.86	3.33256
1959.82	3.68375
1962.78	4.92162
1965.74	5.11827
1968.7	4.59646
1971.65	5.08649
1974.61	5.50649
1977.57	4.99465
1980.52	4.02858
1983.47	3.41691
1986.42	4.12439
1989.37	4.78173
1992.32	4.82325
1995.27	3.92104
1998.22	4.3399
2001.17	5.11649
2004.11	5.2321
2007.05	5.00374
2010	5.29339
2012.94	4.82714
2015.88	4.66338
2018.82	3.72869
2021.76	4.75238
2024.7	4.78983
2027.63	4.93477
2030.57	5.6451
2033.5	6.70538
2036.44	6.66885
2039.37	7.58563
2042.3	8.50677
2045.23	9.05925
2048.16	8.67526
2051.08	9.60864
2054.01	8.814
2056.94	9.44091
2059.86	10.6312
2062.79	11.0394
2065.71	11.1347
2068.63	11.3307
2071.55	12.3475
2074.47	13.0344
2077.39	13.0917
2080.31	14.1771
2083.22	14.6014
2086.13	14.5663
2089.05	15.1204
2091.96	15.1916
2094.87	16.6504
2097.78	17.0841
2100.69	17.5649
2103.6	18.9439
2106.51	19.57
2109.42	20.6597
2112.32	22.0153
2115.23	22.9059
2118.13	24.1869
2121.03	25.6463
2123.93	27.1428
2126.83	29.027
2129.73	30.8787
2132.63	31.8552
2135.53	33.4696
2138.42	34.5751
2141.32	36.6816
2144.21	37.5299
2147.1	39.3792
2150	40.3577
2152.89	42.0288
2155.78	42.5845
2158.66	43.461
2161.55	43.5842
2164.44	43.794
2167.32	43.9974
2170.21	44.1125
2173.09	43.9793
2175.97	43.8541
2178.85	43.0345
2181.73	42.2725
2184.61	40.9215
2187.49	39.8559
2190.37	38.3591
2193.24	37.0893
2196.12	35.7283
2198.99	33.6004
2201.87	32.4652
2204.74	31.7472
2207.61	30.7276
2210.48	28.6985
2213.35	27.0245
2216.21	25.3068
2219.08	24.9719
2221.95	22.9615
2224.81	21.5117
2227.67	21.4737
2230.54	19.8578
2233.4	18.9304
2236.26	18.0478
2239.11	17.9056
2241.97	16.7926
2244.83	15.4656
2247.69	14.7116
2250.54	14.8934
2253.4	13.3931
2256.25	12.7644
2259.1	11.944
2261.95	10.9342
2264.8	10.3548
2267.65	9.89703
2270.5	10.0633
2273.34	10.0058
2276.19	9.81312
2279.03	8.03624
2281.88	7.10896
2284.72	6.70672
2287.56	6.48817
2290.4	6.08017
2293.24	5.80473
2296.08	6.43305
2298.92	7.14
2301.76	6.80136
2304.59	8.27878
2307.43	9.56189
2310.26	10.577
2313.09	11.7296
2315.92	11.2902
2318.75	12.1258
2321.58	11.9221
2324.41	10.3494
2327.24	10.2411
2330.06	10.3204
2332.89	9.28377
2335.71	9.09491
2338.54	8.26894
2341.36	7.5648
2344.18	5.47691
2347	4.66371
2349.82	3.55183
2352.64	3.09553
2355.45	2.68364
2358.27	3.39973
2361.08	3.57316
2363.9	4.08942
2366.71	5.30527
2369.52	5.90558
2372.33	7.18326
2375.14	7.88772
2377.95	7.90192
2380.76	7.71273
2383.57	6.90766
2386.37	7.0575
2389.18	7.072
2391.98	5.88461
2394.79	6.30837
2397.59	5.71817
2400.39	5.39793
2403.19	5.24731
2405.99	4.66046
2408.78	3.31451
2411.58	2.83399
2414.38	2.97516
2417.17	2.35042
2419.97	2.04302
2422.76	2.31076
2425.55	3.35386
2428.34	3.91366
2431.13	2.90548
2433.92	2.29527
2436.71	1.66008
2439.49	2.45332
2442.28	2.29675
2445.06	2.37746
2447.85	1.79909
2450.63	2.36447
2453.41	3.7031
2456.19	3.94432
2458.97	3.98018
2461.75	5.07553
2464.53	6.24579
2467.31	5.71013
2470.08	6.27588
2472.86	5.84619
2475.63	5.81618
2478.4	6.00456
2481.17	5.98672
2483.94	5.75899
2486.72	6.73589
2489.48	6.92108
2492.25	6.91352
2495.02	6.45583
2497.79	5.77393
2500.55	4.91882
2503.31	4.35831
2506.08	4.29119
2508.84	3.56429
2511.6	2.73608
2514.36	2.17592
2517.12	2.13382
2519.88	3.48415
2522.63	3.86784
2525.39	3.80206
2528.14	4.07249
2530.9	4.86284
2533.65	4.36134
2536.4	4.4003
2539.15	4.6715
2541.9	5.2426
2544.65	6.12684
2547.4	7.00306
2550.15	7.38919
2552.89	8.12541
2555.64	8.91406
2558.38	8.73334
2561.12	9.29081
2563.87	9.53737
2566.61	10.0704
2569.35	9.68374
2572.09	9.23919
2574.83	9.6847
2577.56	9.2418
2580.3	9.24325
2583.04	9.28525
2585.77	9.85022
2588.5	9.5732
2591.23	8.95301
2593.97	8.23272
2596.7	7.48922
2599.43	6.97012
2602.15	5.69634
2604.88	6.09995
2607.61	5.69949
2610.33	4.61922
2613.06	4.70757
2615.78	5.33878
2618.51	5.7349
2621.23	7.06048
2623.95	7.83334
2626.67	8.75588
2629.39	9.27761
2632.1	8.80658
2634.82	9.83642
2637.54	10.9331
2640.25	10.8546
2642.97	11.1782
2645.68	11.4011
2648.39	11.6469
2651.1	12.1919
2653.81	11.4141
2656.52	11.3624
2659.23	11.3045
2661.94	10.2869
2664.64	9.77964
2667.35	9.05967
2670.05	9.00631
2672.76	8.9229
2675.46	8.01571
2678.16	8.17537
2680.86	9.06618
2683.56	9.56139
2686.26	9.7908
2688.96	9.55159
2691.65	8.26508
2694.35	8.34432
2697.04	8.16434
2699.74	8.95594
2702.43	11.0318
2705.12	9.97985
2707.81	10.3359
2710.5	11.7135
2713.19	11.7332
2715.88	12.1333
2718.57	12.5438
2721.25	12.5722
2723.94	14.1992
2726.62	13.9742
2729.3	13.6923
2731.99	13.3678
2734.67	13.4535
2737.35	12.9414
2740.03	12.7042
2742.71	11.9758
2745.38	12.0035
2748.06	11.4233
2750.74	10.3611
2753.41	9.69923
2756.09	9.63802
2758.76	8.85241
2761.43	9.29872
2764.1	8.49012
2766.77	8.21894
2769.44	6.09069
2772.11	4.9625
2774.77	4.90992
2777.44	4.83825
2780.11	4.71112
2782.77	4.36862
2785.43	2.51364
2788.1	1.95608
2790.76	1.70084
2793.42	1.20332
2796.08	0.576273
2798.74	1.74557
2801.4	2.46898
2804.05	2.31198
2806.71	2.92243
2809.36	2.88297
2812.02	2.96037
2814.67	3.6101
2817.32	5.24386
2819.97	7.78827
2822.62	9.66181
2825.27	11.4133
2827.92	13.4955
2830.57	16.0416
2833.22	19.0074
2835.86	22.7095
2838.51	27.7236
2841.15	32.1121
2843.79	37.3284
2846.43	40.8402
2849.08	45.5836
2851.72	49.724
2854.36	55.8446
2856.99	60.6059
2859.63	65.2605
2862.27	69.5109
2864.9	72.2819
2867.54	75.684
2870.17	77.455
2872.8	79.7129
2875.43	82.3209
2878.07	84.1113
2880.7	86.6153
2883.32	89.6207
2885.95	91.5724
2888.58	92.9677
2891.21	93.4144
2893.83	96.9734
2896.46	100.692
2899.08	104.234
2901.7	108.271
2904.32	111.385
2906.94	115.425
2909.56	120.443
2912.18	124.864
2914.8	129.14
2917.42	133.732
2920.03	136.749
2922.65	139.53
2925.26	141.699
2927.88	142.336
2930.49	142.286
2933.1	142.19
2935.71	140.359
2938.32	137.514
2940.93	134.38
2943.54	130.849
2946.14	127.047
2948.75	121.567
2951.35	115.304
2953.96	109.833
2956.56	104.826
2959.16	100.008
2961.77	94.4632
2964.37	88.316
2966.96	82.1643
2969.56	77.0822
2972.16	72.3822
2974.76	67.9577
2977.35	63.0982
2979.95	58.7339
2982.54	54.0969
2985.14	49.6072
2987.73	45.1353
2990.32	40.2969
2992.91	35.6454
2995.5	30.8139
2998.09	27.4452
3000.68	23.1023
3003.26	19.6727
3005.85	16.9763
3008.43	14.3545
3011.02	11.514
3013.6	9.18149
3016.19	7.29466
3018.77	5.57343
3021.35	3.67609
3023.93	3.02261
3026.5	1.87912
3029.08	0.879305
3031.66	0.455337
3034.24	0.341912
3036.81	0.546524
3039.39	0.822546
3041.96	1.08581
3044.53	1.77288
3047.1	1.42334
3049.67	2.10834
3052.24	2.32537
3054.81	1.39848
3057.38	1.50481
3059.95	1.75148
3062.52	1.79702
3065.08	1.41275
3067.65	1.67512
3070.21	1.12663
3072.77	1.17863
3075.33	0.86802
3077.89	1.0322
3080.45	-0.0832639
3083.01	-0.415677
3085.57	-0.804097
3088.13	-0.533134
3090.68	-0.953842
3093.24	-0.490379
3095.79	0.266749
3098.35	-0.0322445
3100.9	-0.547659
3103.45	-0.120053
3106	0.723653
3108.55	0.544834
3111.1	0.575783
3113.65	0.926074
3116.2	0.616687
3118.75	0.623558
3121.29	1.5565
3123.84	1.82224
3126.38	1.82189
3128.92	2.32789
3131.47	2.43159
3134.01	2.40481
3136.55	2.6925
3139.09	3.41444
3141.63	3.7732
3144.17	4.59366
3146.7	6.43882
3149.24	8.13743