File: data/Raman/poly_smoothed/Mb_40_24_25_1x_45s_532 nm_x100_100%_600 gr_mm_01.txt
#Acq. time (s)=	45
#Accumulations=	2
#Range (cm-¹)=	200...3150
#Windows=	2
#Auto scanning=	Off
#Autofocus=	Off
#Macrospot=	Off
#AutoExposure=	Off
#Spike filter=	Multiple accum.
#Delay time (s)=	0
#Binning=	1
#Readout mode=	Signal
#DeNoise=	Off
#ICS correction=	On
#Dark correction=	Off
#Inst. Process=	Off
#Detector Gain=	Best Dynamic Range
#Detector ADC=	20 kHz
#Detector temperature (°C)=	-70.08
#Instrument=	LabRAM HR Evol
#Detector=	Synapse
#Objective=	x100
#Grating=	600 gr/mm
#ND Filter=	100%
#Laser (nm)=	532
#Hole=	100.021
#Range=	Auto
#Laser Pol.=	No
#Raman. Pol.=	No
#Laser Pol. (°)=	-0.0007625
#Raman Pol. (°)=	89.9995
#Collection=	Microscope
#StageXY=	Marzhauser
#StageZ=	Marzhauser
#X (µm)=	-2509.9
#Y (µm)=	-102.1
#Z (µm)=	-10.45
#Full time(mm:ss)=	3:18
#Project=
#Sample=
#Site=
#Title=	Mb_40_24_25_2x_45s_532 nm_x100_100%_600 gr_mm
#Remark=
#Date=	14.07.2022 12:34
#Acquired=	14.07.2022 12:34:23
#Base:Fit=	10.08.2022 10:47:00
#Base:Sub=	10.08.2022 10:47:12
#Filter:Polynom=	16.08.2022 10:11:48
#AxisType[0]=Intens
#AxisUnit[0]=Cnt
#AxisType[1]=Spectr
#AxisUnit[1]=1/cm
200.554	51.737
204.183	47.7162
207.813	38.2238
211.439	32.1415
215.065	27.0539
218.688	21.5952
222.312	18.3842
225.933	15.2036
229.552	14.5475
233.171	12.1499
236.787	10.5902
240.402	11.3601
244.015	12.0995
247.627	13.7496
251.24	14.6057
254.849	15.3957
258.457	17.3351
262.063	19.7845
265.668	19.5681
269.271	19.623
272.873	20.4796
276.474	21.0473
280.073	22.9968
283.671	21.3314
287.268	21.7008
290.863	19.9847
294.456	20.3167
298.049	21.1901
301.637	21.8936
305.227	19.6348
308.815	19.4455
312.402	20.0154
315.987	19.7336
319.569	18.7737
323.151	20.6508
326.733	23.4184
330.31	23.6853
333.889	24.8932
337.464	25.1475
341.039	25.4846
344.611	25.6368
348.184	22.7224
351.754	20.3569
355.324	18.6224
358.89	16.9411
362.455	17.7073
366.021	16.1094
369.584	15.0996
373.145	12.719
376.707	10.3667
380.265	9.18964
383.822	10.0053
387.378	8.98891
390.934	7.42355
394.487	4.05434
398.038	3.25848
401.588	4.22614
405.137	6.01708
408.685	6.89503
412.23	7.72194
415.775	8.16719
419.318	9.56276
422.86	10.982
426.401	11.4662
429.94	11.067
433.478	11.0537
437.012	11.0735
440.547	12.6172
444.081	12.3147
447.613	11.3647
451.142	12.3809
454.672	11.6558
458.2	13.2426
461.725	12.7263
465.251	12.6725
468.775	13.2955
472.296	12.7429
475.817	11.5328
479.335	10.3589
482.854	13.2337
486.37	14.9965
489.886	16.0956
493.398	15.962
496.91	16.7958
500.422	17.6851
503.93	21.0139
507.438	22.2965
510.946	24.2783
514.45	23.9353
517.954	24.4561
521.456	27.5478
524.956	27.5919
528.456	28.6457
531.956	28.086
535.452	27.4213
538.947	27.8175
542.441	26.2645
545.934	24.9284
549.425	24.081
552.915	23.6756
556.403	22.9517
559.889	22.871
563.375	21.065
566.859	21.7413
570.342	20.7344
573.824	19.3585
577.303	17.8343
580.782	17.9791
584.26	20.2409
587.734	20.6254
591.21	19.4713
594.684	18.7832
598.154	17.3318
601.626	16.2862
605.094	14.8643
608.562	13.1979
612.027	11.5075
615.493	9.33585
618.956	6.5921
622.419	4.88527
625.879	5.92436
629.338	5.23283
632.797	7.97339
636.254	8.00042
639.708	8.68589
643.162	8.99581
646.614	9.33196
650.067	11.177
653.516	13.0983
656.964	14.1704
660.411	14.7078
663.857	16.0896
667.301	18.4978
670.744	20.4173
674.186	21.3371
677.626	24.3655
681.065	24.5784
684.503	22.9591
687.939	22.9665
691.372	22.884
694.806	26.056
698.239	27.1332
701.67	27.134
705.098	28.0332
708.526	29.5882
711.954	33.6171
715.378	36.1443
718.802	35.6257
722.226	35.3079
725.646	37.2962
729.067	38.5279
732.484	39.8375
735.902	42.4612
739.317	43.0262
742.731	42.513
746.145	44.5882
749.556	47.0385
752.966	48.4959
756.377	51.2744
759.784	51.3477
763.19	51.4289
766.594	51.3044
770	53.448
773.402	54.1353
776.803	54.3033
780.202	54.6473
783.6	55.3739
786.997	55.2065
790.393	55.4857
793.787	58.2577
797.18	61.0948
800.572	61.5459
803.963	63.7782
807.35	66.0324
810.738	70.2958
814.125	70.4589
817.51	74.6108
820.894	75.7532
824.275	76.846
827.657	77.2826
831.037	79.2601
834.414	79.0453
837.792	78.7664
841.167	77.3242
844.542	77.2818
847.914	74.5228
851.287	74.3585
854.656	71.0258
858.026	68.9385
861.393	66.3955
864.761	65.4834
868.125	63.4257
871.489	60.349
874.85	58.8974
878.213	58.3427
881.572	55.4043
884.931	52.5901
888.287	50.3727
891.643	47.0009
894.997	46.8796
898.352	44.3266
901.704	43.3446
905.055	42.7023
908.404	40.1385
911.75	37.8652
915.097	39.0651
918.443	39.0252
921.787	37.851
925.13	37.8758
928.472	35.8983
931.813	35.5197
935.15	36.1471
938.488	34.3819
941.825	33.5757
945.158	33.468
948.493	31.8226
951.824	29.6951
955.156	26.32
958.486	23.4593
961.814	20.9044
965.142	19.1563
968.467	16.387
971.79	16.1997
975.115	16.4597
978.436	13.9355
981.756	11.0755
985.077	10.7446
988.394	8.34817
991.71	7.45435
995.025	10.1077
998.341	11.4193
1001.65	9.31885
1004.97	10.2367
1008.28	12.0545
1011.58	14.6352
1014.89	16.4501
1018.2	19.3107
1021.5	23.0013
1024.81	25.1715
1028.11	30.3999
1031.41	34.2374
1034.71	35.6749
1038.01	37.6233
1041.31	39.025
1044.6	43.7228
1047.9	47.6188
1051.19	47.4819
1054.48	45.9667
1057.77	44.8116
1061.06	44.8823
1064.35	45.5137
1067.64	44.272
1070.93	44.4428
1074.21	43.7082
1077.49	42.9927
1080.78	40.8778
1084.06	38.5866
1087.34	38.6569
1090.61	37.8589
1093.89	36.4076
1097.17	36.5476
1100.44	37.3691
1103.71	38.793
1106.99	39.3519
1110.26	39.9025
1113.52	40.4992
1116.79	40.502
1120.06	39.7797
1123.32	41.3811
1126.59	41.6473
1129.85	42.8631
1133.11	42.7325
1136.37	43.2509
1139.63	44.6603
1142.89	46.3372
1146.15	45.8234
1149.4	46.1736
1152.66	48.1444
1155.91	48.9484
1159.16	49.1057
1162.41	50.0356
1165.66	49.6712
1168.91	49.3789
1172.16	49.1642
1175.4	52.3307
1178.65	54.005
1181.89	59.3663
1185.13	60.8187
1188.37	62.6108
1191.61	65.5085
1194.85	68.0834
1198.08	71.3986
1201.32	74.7004
1204.55	80.62
1207.79	83.3342
1211.02	86.7992
1214.25	88.6738
1217.48	89.2863
1220.71	94.0731
1223.93	97.4912
1227.16	103.793
1230.38	108.811
1233.6	112.64
1236.83	114.595
1240.05	120.679
1243.26	121.118
1246.48	123.925
1249.7	127.819
1252.92	132.07
1256.13	136.225
1259.34	141.392
1262.55	146.718
1265.76	153.213
1268.97	161.099
1272.18	169.942
1275.39	181.015
1278.59	189.044
1281.8	195.04
1285	201.859
1288.2	206.765
1291.4	213.575
1294.6	218.494
1297.8	225.321
1301	231.664
1304.19	233.466
1307.39	237.939
1310.58	239.503
1313.77	240.187
1316.96	242.196
1320.15	242.052
1323.34	239.201
1326.53	237.092
1329.72	235.805
1332.9	234.392
1336.08	235.542
1339.27	235.124
1342.45	235.81
1345.63	237.293
1348.8	238.716
1351.98	238.002
1355.16	238.15
1358.33	235.766
1361.51	236.201
1364.68	233.565
1367.85	233.563
1371.02	232.076
1374.19	227.131
1377.36	223.952
1380.52	221.322
1383.69	217.897
1386.85	214.585
1390.02	210.97
1393.18	206.42
1396.34	201.971
1399.5	197.091
1402.65	193.634
1405.81	193.378
1408.97	194.662
1412.12	195.019
1415.27	198.728
1418.43	201.641
1421.58	206.701
1424.73	212.922
1427.87	218.818
1431.02	224.378
1434.17	230.531
1437.31	235.439
1440.46	239.552
1443.6	240.515
1446.74	240.824
1449.88	239.623
1453.02	236.733
1456.16	233.994
1459.29	229.783
1462.43	222.28
1465.56	213.058
1468.69	202.824
1471.83	192.757
1474.95	182.134
1478.08	175.5
1481.21	164.123
1484.34	155.866
1487.47	147.996
1490.59	139.536
1493.71	132.984
1496.84	127.121
1499.96	122.63
1503.07	119.275
1506.19	118.598
1509.31	117.595
1512.43	117.605
1515.54	118.053
1518.65	117.109
1521.77	118.823
1524.88	120.241
1527.99	123.178
1531.1	126.976
1534.21	132.777
1537.31	136.95
1540.42	141.915
1543.52	148.651
1546.63	153.867
1549.73	159.078
1552.83	166.312
1555.93	173.953
1559.03	182.078
1562.12	192.854
1565.22	202.214
1568.31	214.531
1571.41	225.486
1574.5	239.562
1577.59	251.268
1580.68	263.838
1583.77	276.183
1586.86	286.9
1589.95	294.926
1593.03	301.711
1596.11	304.121
1599.2	304.736
1602.28	301.46
1605.36	295.924
1608.44	287.564
1611.52	279.736
1614.6	268.851
1617.67	255.344
1620.75	239.274
1623.82	224.191
1626.89	210.95
1629.96	195.711
1633.04	181.809
1636.11	169.955
1639.17	155.899
1642.24	144.628
1645.31	133.898
1648.37	123.576
1651.43	116.205
1654.5	107.776
1657.56	101.796
1660.62	95.8056
1663.67	90.5619
1666.73	84.6845
1669.79	78.3522
1672.84	71.0262
1675.9	63.1707
1678.95	57.3116
1682	54.0562
1685.05	52.2552
1688.1	47.6654
1691.15	42.2733
1694.2	36.9419
1697.25	33.7442
1700.29	31.596
1703.33	27.5403
1706.38	23.9699
1709.42	21.2534
1712.46	17.7683
1715.5	15.029
1718.54	13.1603
1721.57	11.3118
1724.61	8.3692
1727.64	6.58448
1730.68	4.04756
1733.71	2.87285
1736.74	1.71497
1739.77	0.979263
1742.8	-0.969331
1745.83	-1.4042
1748.85	-1.10927
1751.88	-0.46223
1754.91	1.08566
1757.93	1.44871
1760.95	0.559736
1763.97	0.717318
1766.99	1.475
1770.01	2.38835
1773.03	2.23893
1776.04	2.01126
1779.06	1.5455
1782.07	1.85023
1785.09	3.03476
1788.1	2.89449
1791.11	3.09356
1794.12	3.59162
1797.13	3.86134
1800.13	3.13751
1803.14	2.75497
1806.15	2.3051
1809.15	1.42231
1812.15	1.89699
1815.16	2.74099
1818.15	3.31823
1821.16	4.38419
1824.15	4.53407
1827.15	4.82886
1830.15	3.88165
1833.14	3.2865
1836.14	4.20468
1839.13	4.42683
1842.12	4.27549
1845.11	5.7136
1848.1	7.25575
1851.09	8.41035
1854.08	10.5747
1857.06	11.7491
1860.05	12.1867
1863.03	11.3247
1866.01	11.343
1869	11.4134
1871.98	12.1521
1874.96	11.2622
1877.93	10.7736
1880.91	11.2084
1882.47	11.4773
1885.46	11.8925
1888.44	12.4079
1891.43	12.4278
1894.42	11.972
1897.4	10.5833
1900.39	10.3589
1903.37	10.0557
1906.35	11.4367
1909.33	11.5257
1912.31	12.5855
1915.29	14.8651
1918.26	15.1814
1921.24	13.98
1924.21	15.1239
1927.19	15.3294
1930.16	13.5261
1933.13	11.234
1936.1	9.28762
1939.07	7.8671
1942.04	8.65017
1945	8.47803
1947.97	7.31862
1950.93	7.10914
1953.9	8.29966
1956.86	6.8108
1959.82	6.74202
1962.78	5.57392
1965.74	5.81883
1968.7	4.35975
1971.65	3.62492
1974.61	3.70604
1977.57	4.48154
1980.52	4.3674
1983.47	4.24551
1986.42	3.18274
1989.37	3.43373
1992.32	2.72054
1995.27	3.20793
1998.22	3.4727
2001.17	3.05575
2004.11	2.47621
2007.05	1.97382
2010	2.60786
2012.94	3.55106
2015.88	4.98051
2018.82	6.14333
2021.76	6.75038
2024.7	9.28763
2027.63	10.3065
2030.57	11.1961
2033.5	12.0508
2036.44	14.4852
2039.37	15.9629
2042.3	15.9926
2045.23	18.6192
2048.16	20.6638
2051.08	22.3417
2054.01	23.1501
2056.94	23.5801
2059.86	24.6501
2062.79	25.7515
2065.71	26.0771
2068.63	27.0787
2071.55	26.5866
2074.47	25.2183
2077.39	23.8697
2080.31	23.8162
2083.22	24.8142
2086.13	27.1966
2089.05	27.0466
2091.96	27.4076
2094.87	28.6176
2097.78	30.0593
2100.69	31.7509
2103.6	32.9735
2106.51	35.4326
2109.42	36.3378
2112.32	37.3039
2115.23	41.0348
2118.13	43.324
2121.03	44.8954
2123.93	45.9
2126.83	49.4512
2129.73	51.3804
2132.63	54.4173
2135.53	57.6905
2138.42	60.8838
2141.32	63.4096
2144.21	64.1449
2147.1	66.8665
2150	69.6022
2152.89	72.7153
2155.78	76.1537
2158.66	77.2431
2161.55	78.8718
2164.44	81.0436
2167.32	81.6837
2170.21	81.9249
2173.09	82.0636
2175.97	81.3825
2178.85	79.7859
2181.73	77.3288
2184.61	76.6732
2187.49	74.5794
2190.37	69.9927
2193.24	69.1137
2196.12	66.8524
2198.99	66.7447
2201.87	65.0391
2204.74	61.2044
2207.61	59.2816
2210.48	55.4794
2213.35	52.9538
2216.21	51.7015
2219.08	50.6405
2221.95	50.5548
2224.81	49.1436
2227.67	48.0852
2230.54	45.5663
2233.4	44.3634
2236.26	42.2175
2239.11	39.9219
2241.97	37.6325
2244.83	35.5588
2247.69	32.7985
2250.54	31.7269
2253.4	30.569
2256.25	28.3284
2259.1	25.8515
2261.95	24.5317
2264.8	23.7233
2267.65	23.6437
2270.5	21.8346
2273.34	19.6828
2276.19	17.0303
2279.03	15.766
2281.88	14.738
2284.72	13.8829
2287.56	14.5641
2290.4	13.5867
2293.24	10.89
2296.08	9.85445
2298.92	11.0369
2301.76	10.9473
2304.59	10.5461
2307.43	11.2437
2310.26	12.0579
2313.09	11.6344
2315.92	13.2661
2318.75	12.4597
2321.58	14.0532
2324.41	14.1868
2327.24	14.575
2330.06	15.5556
2332.89	15.3147
2335.71	14.9438
2338.54	13.1709
2341.36	13.1619
2344.18	11.7194
2347	10.8202
2349.82	9.43729
2352.64	8.45645
2355.45	5.88405
2358.27	4.64454
2361.08	2.66701
2363.9	2.62226
2366.71	3.147
2369.52	2.60702
2372.33	2.13825
2375.14	2.29785
2377.95	2.76684
2380.76	2.73705
2383.57	2.37521
2386.37	1.87334
2389.18	1.00516
2391.98	1.70958
2394.79	0.618425
2397.59	0.167468
2400.39	0.498809
2403.19	2.60488
2405.99	4.43033
2408.78	5.51351
2411.58	7.27395
2414.38	7.44025
2417.17	6.76601
2419.97	7.15081
2422.76	7.71894
2425.55	7.25685
2428.34	8.06449
2431.13	9.67914
2433.92	9.59419
2436.71	8.84462
2439.49	10.102
2442.28	8.83735
2445.06	10.7452
2447.85	9.63221
2450.63	8.17577
2453.41	6.29968
2456.19	5.93742
2458.97	5.82274
2461.75	4.52785
2464.53	3.39273
2467.31	3.5384
2470.08	4.09747
2472.86	4.31942
2475.63	3.07667
2478.4	2.88309
2481.17	2.2516
2483.94	2.08603
2486.72	2.22687
2489.48	2.61771
2492.25	2.86234
2495.02	2.91836
2497.79	3.429
2500.55	3.62532
2503.31	2.78844
2506.08	3.73412
2508.84	4.25182
2511.6	4.01522
2514.36	4.09023
2517.12	2.80372
2519.88	3.39155
2522.63	3.38521
2525.39	3.54946
2528.14	3.71409
2530.9	3.53075
2533.65	3.7381
2536.4	3.43845
2539.15	2.71853
2541.9	2.18425
2544.65	2.55325
2547.4	1.78027
2550.15	2.70441
2552.89	2.76983
2555.64	2.26842
2558.38	2.93808
2561.12	2.94493
2563.87	1.86105
2566.61	2.48349
2569.35	3.9185
2572.09	3.61255
2574.83	5.423
2577.56	5.50311
2580.3	5.48189
2583.04	6.18461
2585.77	6.97861
2588.5	7.41475
2591.23	8.87657
2593.97	9.26251
2596.7	9.03778
2599.43	7.93529
2602.15	8.30098
2604.88	7.70529
2607.61	9.00026
2610.33	8.2754
2613.06	7.47833
2615.78	7.45758
2618.51	7.55228
2621.23	6.47509
2623.95	5.81308
2626.67	4.91796
2629.39	5.0335
2632.1	3.78959
2634.82	5.53094
2637.54	4.47254
2640.25	4.86705
2642.97	3.76822
2645.68	3.43992
2648.39	2.85355
2651.1	3.38868
2653.81	3.86417
2656.52	3.21733
2659.23	3.81248
2661.94	3.1399
2664.64	2.55198
2667.35	4.61941
2670.05	5.82747
2672.76	7.72453
2675.46	8.23295
2678.16	8.37589
2680.86	9.41836
2683.56	9.27748
2686.26	11.3467
2688.96	11.3002
2691.65	11.0487
2694.35	11.3683
2697.04	12.6554
2699.74	14.196
2702.43	16.2227
2705.12	16.8598
2707.81	17.9422
2710.5	19.526
2713.19	21.7479
2715.88	22.2405
2718.57	22.3738
2721.25	23.3013
2723.94	22.7192
2726.62	22.2986
2729.3	19.9181
2731.99	19.7904
2734.67	18.5776
2737.35	15.4272
2740.03	14.3399
2742.71	13.0845
2745.38	12.0443
2748.06	8.33169
2750.74	7.2638
2753.41	6.03468
2756.09	3.73634
2758.76	3.65953
2761.43	2.77323
2764.1	3.66708
2766.77	4.94771
2769.44	2.93136
2772.11	3.5564
2774.77	3.4384
2777.44	4.00975
2780.11	3.84496
2782.77	3.77037
2785.43	4.3615
2788.1	3.75365
2790.76	2.99494
2793.42	2.8547
2796.08	1.75587
2798.74	2.13006
2801.4	2.46137
2804.05	2.12646
2806.71	2.11661
2809.36	0.379473
2812.02	-2.27284
2814.67	-1.79278
2817.32	2.65697
2819.97	8.56436
2822.62	18.4543
2825.27	29.8669
2827.92	42.611
2830.57	57.8385
2833.22	72.6848
2835.86	88.2396
2838.51	105.861
2841.15	123.975
2843.79	140.557
2846.43	157.257
2849.08	174.827
2851.72	193.919
2854.36	212.177
2856.99	230.216
2859.63	246.555
2862.27	261.334
2864.9	273.68
2867.54	282.47
2870.17	287.74
2872.8	290.628
2875.43	294.443
2878.07	299.775
2880.7	305.086
2883.32	311.834
2885.95	318.075
2888.58	323.435
2891.21	327.081
2893.83	330.285
2896.46	336.031
2899.08	340.096
2901.7	343.149
2904.32	347.765
2906.94	352.172
2909.56	358.334
2912.18	367.675
2914.8	375.774
2917.42	383.686
2920.03	390.779
2922.65	394.201
2925.26	395.314
2927.88	394.415
2930.49	389.731
2933.1	382.232
2935.71	373.59
2938.32	363.033
2940.93	352.384
2943.54	339.748
2946.14	324.63
2948.75	309.508
2951.35	290.609
2953.96	273.334
2956.56	256.343
2959.16	240.394
2961.77	225.513
2964.37	210.001
2966.96	197.662
2969.56	185.393
2972.16	173.283
2974.76	163.261
2977.35	152.375
2979.95	141.318
2982.54	130.514
2985.14	118.567
2987.73	106.719
2990.32	96.9035
2992.91	85.8801
2995.5	75.6383
2998.09	66.8902
3000.68	60.2226
3003.26	52.8772
3005.85	46.5128
3008.43	39.9919
3011.02	33.2458
3013.6	28.233
3016.19	22.3315
3018.77	18.7259
3021.35	15.9735
3023.93	13.1899
3026.5	11.247
3029.08	8.84578
3031.66	6.56399
3034.24	4.1456
3036.81	2.47525
3039.39	2.77657
3041.96	1.93309
3044.53	0.718606
3047.1	1.19388
3049.67	2.13317
3052.24	2.65643
3054.81	2.54411
3057.38	2.85217
3059.95	4.06537
3062.52	5.31733
3065.08	6.55193
3067.65	6.88938
3070.21	7.82932
3072.77	9.01864
3075.33	8.64764
3077.89	8.53066
3080.45	7.74045
3083.01	7.1301
3085.57	7.18469
3088.13	6.66331
3090.68	6.78024
3093.24	6.10678
3095.79	7.37905
3098.35	7.977
3100.9	10.3042
3103.45	12.301
3106	14.4004
3108.55	17.6702
3111.1	18.8992
3113.65	20.3028
3116.2	21.3956
3118.75	23.3108
3121.29	25.4198
3123.84	28.1678
3126.38	31.1573
3128.92	34.8241
3131.47	37.4904
3134.01	39.7232
3136.55	40.4034
3139.09	42.3082
3141.63	43.8396
3144.17	46.1632
3146.7	49.1066
3149.24	52.7029