File: data/Raman/poly_smoothed/Mb_40_y_45_1x_45s_532 nm_x100_100%_600 gr_mm_02.txt
#Acq. time (s)=	45
#Accumulations=	2
#Range (cm-¹)=	200...3150
#Windows=	2
#Auto scanning=	Off
#Autofocus=	Off
#Macrospot=	Off
#AutoExposure=	Off
#Spike filter=	Multiple accum.
#Delay time (s)=	0
#Binning=	1
#Readout mode=	Signal
#DeNoise=	Off
#ICS correction=	On
#Dark correction=	Off
#Inst. Process=	Off
#Detector Gain=	Best Dynamic Range
#Detector ADC=	20 kHz
#Detector temperature (°C)=	-69.85
#Instrument=	LabRAM HR Evol
#Detector=	Synapse
#Objective=	x100
#Grating=	600 gr/mm
#ND Filter=	100%
#Laser (nm)=	532
#Hole=	100.021
#Range=	Auto
#Laser Pol.=	No
#Raman. Pol.=	No
#Laser Pol. (°)=	-0.0007625
#Raman Pol. (°)=	89.9995
#Collection=	Microscope
#StageXY=	Marzhauser
#StageZ=	Marzhauser
#X (µm)=	-1149.3
#Y (µm)=	674
#Z (µm)=	584.85
#Full time(mm:ss)=	3:18
#Project=
#Sample=
#Site=
#Title=	Mb_40_y_45_2x_45s_532 nm_x100_100%_600 gr_mm
#Remark=
#Date=	19.07.2022 13:19
#Acquired=	19.07.2022 13:19:11
#Base:Fit=	10.08.2022 10:52:48
#Base:Sub=	10.08.2022 10:52:53
#Filter:Polynom=	16.08.2022 10:09:04
#AxisType[0]=Intens
#AxisUnit[0]=Cnt
#AxisType[1]=Spectr
#AxisUnit[1]=1/cm
200.423	9.91621
204.052	9.11375
207.682	8.9247
211.308	9.67927
214.935	9.78921
218.558	10.089
222.18	9.76611
225.802	10.312
229.421	9.28387
233.039	8.83308
236.657	8.0355
240.272	7.68698
243.885	6.42552
247.497	5.42624
251.11	3.00315
254.719	2.50058
258.327	2.88555
261.933	3.67258
265.538	3.11264
269.141	4.96085
272.744	4.06176
276.344	2.4241
279.944	1.53207
283.542	2.1105
287.138	3.93448
290.733	3.88475
294.327	5.3743
297.919	7.68111
301.508	7.5062
305.098	7.44128
308.686	7.92106
312.273	8.25641
315.858	7.98255
319.44	8.88667
323.022	9.64065
326.604	10.0681
330.181	9.68833
333.76	8.66483
337.335	8.58947
340.91	9.44357
344.483	9.47463
348.055	10.3698
351.625	11.0522
355.195	10.4865
358.762	10.4515
362.329	10.3337
365.893	10.0637
369.455	10.403
373.017	10.6724
376.578	12.2256
380.137	13.0386
383.694	13.3277
387.249	12.0902
390.806	11.4232
394.359	11.9074
397.91	11.8277
401.46	12.0907
405.009	11.2466
408.557	11.1419
412.103	10.5885
415.647	9.36308
419.191	8.52769
422.733	8.10561
426.273	7.21476
429.812	6.35485
433.35	5.56973
436.885	6.9137
440.42	6.02389
443.954	6.19306
447.486	5.31415
451.015	4.4657
454.545	4.62878
458.073	5.89933
461.598	8.55868
465.124	9.47311
468.648	9.66088
472.169	9.91421
475.69	10.1265
479.208	12.1992
482.727	12.5325
486.243	11.8763
489.759	12.3799
493.272	12.9297
496.783	14.5602
500.295	14.6571
503.804	15.3193
507.311	14.8856
510.819	14.5942
514.324	14.3462
517.827	13.808
521.329	13.9766
524.83	12.5249
528.329	11.4626
531.829	11.7365
535.326	11.1883
538.821	10.1986
542.315	12.0491
545.808	10.4789
549.299	10.1217
552.789	9.78059
556.278	10.3495
559.763	9.0321
563.249	9.60665
566.733	8.30806
570.217	8.39345
573.699	8.93128
577.177	8.17134
580.656	7.90589
584.134	6.90593
587.609	5.58292
591.084	4.36936
594.558	4.93108
598.029	3.83935
601.5	3.64673
604.968	2.6387
608.437	2.69054
611.902	3.41681
615.368	4.58294
618.831	3.91337
622.294	5.30704
625.755	5.97121
629.213	7.60877
632.673	8.06917
636.129	9.3436
639.584	10.6329
643.037	11.2591
646.491	12.6197
649.942	11.4588
653.392	12.913
656.84	14.0158
660.287	13.4174
663.732	14.0539
667.177	12.7026
670.62	13.0972
674.061	12.8147
677.502	13.9596
680.941	14.8516
684.379	15.4482
687.815	16.6764
691.248	18.4278
694.682	22.6399
698.115	25.1384
701.546	26.5057
704.974	28.5336
708.402	31.2998
711.83	34.8694
715.254	37.1875
718.679	38.7305
722.102	40.4997
725.522	40.5346
728.943	41.4589
732.361	42.0637
735.779	43.16
739.194	44.2185
742.608	45.6975
746.022	45.7779
749.433	47.0107
752.843	48.1166
756.254	50.2158
759.661	51.6609
763.067	54.379
766.471	57.2714
769.877	60.1006
773.279	62.495
776.68	66.9067
780.079	68.8063
783.478	70.852
786.875	72.1557
790.27	73.8491
793.665	76.1588
797.058	77.6484
800.45	77.6802
803.84	76.6822
807.23	75.6147
810.616	74.8712
814.002	73.5094
817.388	73.0739
820.772	71.6835
824.153	71.0095
827.535	68.8083
830.915	67.8077
834.292	66.4532
837.67	66.0176
841.047	62.7567
844.42	60.8048
847.794	58.1753
851.165	56.7163
854.534	54.7711
857.905	52.7087
861.272	50.2038
864.639	47.6697
868.004	46.6872
871.367	45.4402
874.731	44.5174
878.092	44.1654
881.451	42.719
884.809	42.2879
888.166	41.6672
891.522	42.0631
894.878	42.0412
898.231	41.8524
901.583	42.3211
904.934	43.5883
908.283	42.3357
911.631	42.4537
914.976	42.2677
918.322	41.5299
921.666	40.5459
925.009	38.4958
928.351	38.5505
931.692	39.4204
935.029	38.926
938.367	36.0554
941.704	33.9359
945.038	33.8048
948.372	35.2599
951.705	35.4172
955.035	35.9455
958.366	36.194
961.693	36.6439
965.021	37.2136
968.346	36.2474
971.67	36.4592
974.995	37.6257
978.316	36.1175
981.638	36.0859
984.957	35.3264
988.274	33.5164
991.59	30.8209
994.907	27.7935
998.221	21.8495
1001.53	17.2503
1004.85	14.0554
1008.16	18.4852
1011.46	30.0686
1014.77	43.9906
1018.08	59.7803
1021.38	76.0648
1024.69	93.5041
1027.99	111.073
1031.29	124.068
1034.59	135.013
1037.89	142.619
1041.19	147.65
1044.48	150.167
1047.78	150.247
1051.07	145.177
1054.36	140.545
1057.66	131.748
1060.94	118.629
1064.23	105.717
1067.52	89.5391
1070.81	70.8948
1074.09	51.947
1077.38	33.2213
1080.66	18.2054
1083.94	8.50098
1087.22	6.68579
1090.5	7.95906
1093.77	11.4444
1097.05	14.0438
1100.32	14.753
1103.6	16.4938
1106.87	19.3525
1110.14	18.8233
1113.41	18.1138
1116.67	17.4261
1119.94	16.6679
1123.21	14.8627
1126.47	12.4519
1129.73	10.8532
1133	8.61138
1136.26	8.00097
1139.52	7.47926
1142.77	6.00086
1146.03	5.86194
1149.29	5.21811
1152.54	5.65424
1155.79	4.66689
1159.04	4.5026
1162.3	3.73603
1165.55	3.40402
1168.79	4.40729
1172.04	4.43692
1175.28	4.97956
1178.53	4.98759
1181.77	5.47816
1185.01	7.76983
1188.25	7.13892
1191.49	6.68949
1194.73	5.65514
1197.97	5.12967
1201.2	5.51765
1204.44	6.33246
1207.67	7.97146
1210.9	10.2084
1214.13	11.9708
1217.36	14.3872
1220.59	16.9692
1223.82	18.8961
1227.04	20.7029
1230.26	22.3697
1233.49	24.7088
1236.71	26.0532
1239.93	29.5006
1243.15	31.2368
1246.37	33.1756
1249.58	34.2148
1252.8	34.4996
1256.01	35.1606
1259.23	37.3177
1262.44	37.7743
1265.65	38.5678
1268.86	39.0927
1272.07	40.9473
1275.27	42.8088
1278.48	44.6488
1281.68	47.4973
1284.89	49.3998
1288.09	50.4587
1291.29	51.2715
1294.49	51.1961
1297.69	52.6597
1300.88	53.4205
1304.08	55.2593
1307.27	54.5738
1310.47	55.7548
1313.66	56.12
1316.85	56.3602
1320.04	55.5997
1323.23	53.6294
1326.41	51.4467
1329.6	50.6919
1332.78	51.0534
1335.97	48.9759
1339.15	49.0004
1342.33	46.3723
1345.51	46.1231
1348.69	44.4658
1351.87	43.6805
1355.04	41.1214
1358.22	38.6063
1361.39	35.3763
1364.57	33.1761
1367.74	32.0041
1370.91	31.0481
1374.07	28.9267
1377.24	28.1894
1380.41	27.1123
1383.57	25.4828
1386.74	24.6169
1389.9	24.426
1393.06	24.1232
1396.22	24.4977
1399.38	25.3612
1402.54	26.357
1405.7	30.1504
1408.85	33.6537
1412.01	36.2542
1415.16	39.7898
1418.31	43.6609
1421.46	45.1061
1424.61	47.5982
1427.76	50.5232
1430.91	54.3285
1434.05	57.5663
1437.2	59.7268
1440.34	64.0942
1443.49	67.466
1446.63	68.759
1449.77	69.3442
1452.91	68.443
1456.04	68.4756
1459.18	67.434
1462.31	66.5151
1465.45	66.2663
1468.58	64.0497
1471.71	60.4777
1474.84	59.4943
1477.97	56.0652
1481.1	52.3036
1484.23	48.7439
1487.35	44.2488
1490.48	40.5788
1493.6	36.311
1496.72	31.2221
1499.84	26.705
1502.96	23.8
1506.08	22.574
1509.2	21.3442
1512.31	18.0464
1515.43	15.1359
1518.54	12.8657
1521.66	11.2496
1524.77	10.6228
1527.88	8.99753
1530.99	10.2134
1534.09	12.0149
1537.2	13.5882
1540.31	15.0571
1543.41	17.0978
1546.51	18.0753
1549.62	19.637
1552.72	20.4711
1555.82	21.03
1558.91	23.6439
1562.01	25.1007
1565.11	26.2663
1568.2	27.8467
1571.3	29.4897
1574.39	30.4257
1577.48	31.9654
1580.57	34.8851
1583.66	35.8073
1586.75	37.5151
1589.83	36.9853
1592.92	38.4613
1596	40.4632
1599.09	41.4066
1602.17	42.5892
1605.25	43.6086
1608.33	44.4949
1611.41	43.6351
1614.48	44.5126
1617.56	45.2511
1620.64	46.7037
1623.71	47.3496
1626.78	46.4113
1629.86	46.5883
1632.92	47.3787
1635.99	47.6162
1639.06	45.1017
1642.13	45.2903
1645.19	45.5616
1648.26	45.5763
1651.32	45.0805
1654.38	44.8733
1657.45	44.7892
1660.51	44.1054
1663.57	43.2424
1666.62	40.76
1669.68	38.5876
1672.73	36.5322
1675.79	35.2713
1678.84	33.0167
1681.89	29.9044
1684.94	26.8066
1687.99	25.2058
1691.04	23.8514
1694.09	21.4057
1697.14	19.528
1700.18	16.7602
1703.22	15.2718
1706.27	15.3656
1709.31	12.9066
1712.35	11.0966
1715.39	10.4315
1718.43	9.46637
1721.46	8.47225
1724.5	7.48525
1727.53	7.01604
1730.57	6.31628
1733.6	6.04495
1736.63	6.27985
1739.66	4.37825
1742.69	4.22092
1745.72	5.96399
1748.74	4.96551
1751.77	5.02666
1754.8	3.85837
1757.82	3.4165
1760.84	3.8052
1763.86	5.44515
1766.88	4.48294
1769.9	4.76056
1772.92	4.19053
1775.93	4.33253
1778.95	3.97508
1781.96	3.55345
1784.98	3.8264
1787.99	3.36476
1791	3.72879
1794.01	3.20038
1797.02	3.57331
1800.03	3.39057
1803.03	2.92914
1806.04	2.16671
1809.04	2.80297
1812.04	1.57405
1815.05	1.11911
1818.05	1.44155
1821.05	1.83055
1824.05	1.9098
1827.04	3.16488
1830.04	3.76429
1833.03	4.33235
1836.03	5.31089
1839.02	4.21758
1842.01	3.06193
1845	3.22535
1847.99	3.03158
1850.98	2.60071
1853.97	2.57092
1856.95	3.4648
1859.94	4.12321
1862.92	4.56935
1865.91	4.48609
1868.89	3.9712
1871.87	3.5159
1874.85	2.69644
1877.83	3.61226
1880.8	4.43578
1882.56	4.68314
1885.54	5.08172
1888.53	5.18443
1891.52	5.07911
1894.5	5.11607
1897.49	5.4637
1900.47	6.19868
1903.45	5.2572
1906.43	5.66055
1909.41	4.08302
1912.39	2.86487
1915.37	4.07751
1918.35	3.96234
1921.32	2.79823
1924.3	3.4257
1927.27	2.91441
1930.24	3.84622
1933.21	3.10282
1936.18	2.30306
1939.15	1.42345
1942.12	1.11811
1945.09	2.13289
1948.05	2.57292
1951.02	2.84451
1953.98	3.63074
1956.94	3.05766
1959.91	3.44164
1962.87	2.94248
1965.82	3.78035
1968.78	5.10681
1971.74	6.23241
1974.7	6.85003
1977.65	6.96169
1980.6	6.89139
1983.56	7.6986
1986.51	8.28311
1989.46	8.20475
1992.41	8.04767
1995.36	8.89656
1998.3	9.1406
2001.25	9.32001
2004.2	9.89393
2007.14	10.0762
2010.08	9.99862
2013.02	10.6238
2015.97	11.097
2018.9	10.6052
2021.84	11.0156
2024.78	11.6286
2027.72	12.8834
2030.65	12.9409
2033.59	13.2551
2036.52	13.105
2039.45	13.7727
2042.38	14.7734
2045.31	14.931
2048.24	14.2558
2051.17	13.3551
2054.1	12.4811
2057.02	12.3319
2059.95	12.0272
2062.87	11.8168
2065.79	12.1263
2068.71	12.1161
2071.63	11.9888
2074.55	12.9844
2077.47	13.9723
2080.39	15.0796
2083.3	14.979
2086.22	16.4613
2089.13	17.1579
2092.05	18.327
2094.96	19.1121
2097.87	21.1083
2100.78	22.0926
2103.69	21.7588
2106.59	22.7201
2109.5	23.9204
2112.41	24.5165
2115.31	25.0355
2118.21	25.6258
2121.12	26.3359
2124.02	27.3409
2126.92	28.5157
2129.82	29.3777
2132.71	30.3687
2135.61	31.4406
2138.51	33.6553
2141.4	34.6184
2144.29	35.4773
2147.19	38.2208
2150.08	41.172
2152.97	42.8791
2155.86	44.5169
2158.75	46.959
2161.64	47.1182
2164.52	49.0429
2167.41	50.6884
2170.29	51.8267
2173.17	51.9926
2176.06	52.294
2178.94	51.293
2181.82	51.4055
2184.7	51.1166
2187.57	51.2868
2190.45	50.2637
2193.33	48.8901
2196.2	46.9483
2199.08	44.925
2201.95	43.3176
2204.82	41.2272
2207.69	39.2831
2210.56	38.4638
2213.43	36.013
2216.3	36.1189
2219.16	36.0103
2222.03	34.2302
2224.89	32.0725
2227.75	31.5017
2230.62	30.6392
2233.48	28.8782
2236.34	28.6283
2239.2	26.4247
2242.06	25.3233
2244.91	24.2846
2247.77	21.754
2250.62	20.8875
2253.48	20.8959
2256.33	20.0186
2259.18	19.0408
2262.03	18.7917
2264.88	18.1865
2267.73	16.7286
2270.58	16.2717
2273.43	14.8645
2276.27	15.1901
2279.12	15.9616
2281.96	15.7945
2284.8	15.5688
2287.64	15.1145
2290.49	14.3428
2293.32	13.0829
2296.16	13.3289
2299	13.3844
2301.84	12.5493
2304.67	11.7118
2307.51	12.0042
2310.34	11.219
2313.17	10.6952
2316	10.7111
2318.83	10.6294
2321.66	10.7139
2324.49	10.8307
2327.32	10.6086
2330.15	10.7066
2332.97	10.4551
2335.79	10.0658
2338.62	9.98973
2341.44	9.73917
2344.26	10.3405
2347.08	10.141
2349.9	9.35857
2352.72	8.83587
2355.53	8.31554
2358.35	7.24092
2361.17	6.70349
2363.98	5.23979
2366.79	6.33556
2369.6	4.40247
2372.42	3.69987
2375.22	4.76632
2378.03	4.14784
2380.84	3.14312
2383.65	3.05232
2386.45	3.1658
2389.26	2.79349
2392.06	4.10444
2394.87	4.28447
2397.67	4.82388
2400.47	4.68024
2403.27	4.70256
2406.07	5.10651
2408.86	4.92239
2411.66	4.78429
2414.46	4.91167
2417.25	5.40894
2420.05	5.46766
2422.84	5.66669
2425.63	5.18786
2428.42	4.8351
2431.21	4.29884
2434	3.90989
2436.79	3.52661
2439.57	2.57409
2442.36	3.90353
2445.14	4.60534
2447.93	4.32187
2450.71	4.1683
2453.49	4.58099
2456.27	4.98897
2459.05	4.97032
2461.83	5.04945
2464.61	4.79038
2467.39	4.52483
2470.16	3.93654
2472.94	3.81289
2475.71	4.56355
2478.48	4.39397
2481.25	4.48089
2484.02	4.63511
2486.8	4.74285
2489.56	5.21996
2492.33	5.53368
2495.1	5.76594
2497.86	4.48034
2500.63	4.21377
2503.39	4.56423
2506.16	4.90945
2508.92	5.60103
2511.68	6.47264
2514.44	6.26005
2517.2	5.65222
2519.95	4.75742
2522.71	4.73563
2525.47	4.0579
2528.22	4.40885
2530.98	4.78955
2533.73	5.1763
2536.48	5.2628
2539.23	4.85897
2541.98	4.44276
2544.73	3.81939
2547.48	2.34962
2550.23	2.70985
2552.97	2.14103
2555.72	1.97982
2558.46	1.56764
2561.2	0.943955
2563.95	-0.254126
2566.69	-1.1453
2569.43	-0.414074
2572.17	0.454221
2574.91	0.75029
2577.64	1.73078
2580.38	2.15982
2583.11	2.57676
2585.85	3.02499
2588.58	3.62293
2591.31	3.88549
2594.04	4.16816
2596.78	5.06118
2599.51	5.50315
2602.23	5.81587
2604.96	5.21538
2607.69	5.46213
2610.41	5.60173
2613.14	5.01301
2615.86	5.10649
2618.58	5.69499
2621.3	4.83266
2624.03	4.30078
2626.75	5.13314
2629.46	4.89716
2632.18	4.809
2634.9	5.30407
2637.61	6.30656
2640.33	7.31418
2643.04	8.21293
2645.76	8.70038
2648.47	7.95767
2651.18	7.15241
2653.89	7.19529
2656.6	6.62929
2659.31	6.28824
2662.01	5.48993
2664.72	5.28006
2667.43	4.56662
2670.13	4.42067
2672.83	4.41482
2675.53	3.52265
2678.24	3.01093
2680.94	2.10156
2683.64	2.23067
2686.34	2.31218
2689.03	1.7877
2691.73	2.72685
2694.43	3.03247
2697.12	2.97464
2699.81	4.33923
2702.51	4.76035
2705.2	5.657
2707.89	6.45647
2710.58	7.06415
2713.27	7.9104
2715.96	8.81667
2718.64	9.06664
2721.33	10.1692
2724.01	10.4745
2726.7	10.6692
2729.38	10.4704
2732.06	11.1419
2734.75	11.0525
2737.43	10.3251
2740.11	9.74693
2742.78	9.5482
2745.46	8.38409
2748.14	6.81489
2750.81	6.39246
2753.49	5.89046
2756.16	4.73779
2758.84	4.19103
2761.51	3.01728
2764.18	3.68567
2766.85	2.99102
2769.52	2.17251
2772.19	2.74653
2774.85	2.77458
2777.52	3.27892
2780.18	3.46158
2782.85	2.3909
2785.51	1.96501
2788.17	1.24949
2790.84	0.546878
2793.5	1.1251
2796.16	0.417831
2798.81	0.54968
2801.47	0.379741
2804.13	0.255438
2806.79	0.755169
2809.44	-0.0958649
2812.09	0.0453185
2814.75	1.58987
2817.4	3.42277
2820.05	5.84646
2822.7	9.21736
2825.35	13.33
2828	16.7611
2830.65	20.2972
2833.29	23.6241
2835.94	28.5816
2838.58	32.3379
2841.23	35.5537
2843.87	38.9183
2846.51	41.5961
2849.15	44.7732
2851.79	48.5934
2854.43	53.5002
2857.07	58.5247
2859.71	62.1294
2862.34	66.4086
2864.98	70.5262
2867.61	72.6149
2870.25	75.2719
2872.88	77.7986
2875.51	79.3433
2878.14	81.6894
2880.77	84.0302
2883.4	87.0603
2886.03	89.9284
2888.65	91.6011
2891.28	92.0926
2893.91	93.0343
2896.53	94.3326
2899.15	95.4154
2901.78	97.2678
2904.4	98.421
2907.02	100.172
2909.64	102.373
2912.26	106.182
2914.87	111.799
2917.49	116.041
2920.11	121.202
2922.72	124.988
2925.34	128.561
2927.95	131.157
2930.56	132.783
2933.17	133.301
2935.78	133.829
2938.39	132.792
2941	131.321
2943.61	129.694
2946.22	127.864
2948.82	123.895
2951.43	120.085
2954.03	115.953
2956.64	110.699
2959.24	106.026
2961.84	101.549
2964.44	96.1748
2967.04	90.7424
2969.64	85.2537
2972.24	80.5166
2974.83	75.8094
2977.43	71.618
2980.02	66.4726
2982.62	62.3363
2985.21	58.1341
2987.8	53.758
2990.4	48.8512
2992.99	44.0927
2995.57	39.9671
2998.16	36.236
3000.75	32.1713
3003.34	28.7995
3005.92	25.8945
3008.51	22.4348
3011.09	20.3464
3013.68	18.5887
3016.26	16.0108
3018.84	13.7558
3021.42	12.4342
3024	10.7815
3026.58	9.50434
3029.16	8.32905
3031.73	7.34713
3034.31	7.82443
3036.89	7.15971
3039.46	6.74423
3042.03	6.80104
3044.61	6.66675
3047.18	6.63111
3049.75	6.51799
3052.32	6.00695
3054.89	5.85845
3057.45	6.09419
3060.02	5.94286
3062.59	4.79534
3065.15	3.98672
3067.72	2.88754
3070.28	2.28336
3072.84	2.36007
3075.41	2.18965
3077.97	0.935943
3080.53	1.35467
3083.09	1.18678
3085.64	1.3474
3088.2	1.15143
3090.76	1.27635
3093.31	2.01815
3095.87	2.63986
3098.42	2.39966
3100.97	2.6482
3103.53	2.412
3106.08	2.47109
3108.63	2.41533
3111.18	2.37225
3113.73	1.6692
3116.27	1.78747
3118.82	1.28843
3121.37	0.658051
3123.91	-0.213085
3126.45	-1.99903
3129	-2.0425
3131.54	-2.03078
3134.08	-1.53136
3136.62	-1.6471
3139.16	-2.49803
3141.7	-2.64372
3144.24	-2.75965
3146.78	-2.38559
3149.31	-1.39968