File: data/Raman/poly_smoothed/Mb_40_24_29_1x_45s_532 nm_x100_100%_600 gr_mm_01.txt
#Acq. time (s)=	45
#Accumulations=	2
#Range (cm-¹)=	200...3150
#Windows=	2
#Auto scanning=	Off
#Autofocus=	Off
#Macrospot=	Off
#AutoExposure=	Off
#Spike filter=	Multiple accum.
#Delay time (s)=	0
#Binning=	1
#Readout mode=	Signal
#DeNoise=	Off
#ICS correction=	On
#Dark correction=	Off
#Inst. Process=	Off
#Detector Gain=	Best Dynamic Range
#Detector ADC=	20 kHz
#Detector temperature (°C)=	-70.08
#Instrument=	LabRAM HR Evol
#Detector=	Synapse
#Objective=	x100
#Grating=	600 gr/mm
#ND Filter=	100%
#Laser (nm)=	532
#Hole=	100.021
#Range=	Auto
#Laser Pol.=	No
#Raman. Pol.=	No
#Laser Pol. (°)=	-0.0007625
#Raman Pol. (°)=	89.9995
#Collection=	Microscope
#StageXY=	Marzhauser
#StageZ=	Marzhauser
#X (µm)=	-2466.1
#Y (µm)=	-120.1
#Z (µm)=	-10.1
#Full time(mm:ss)=	3:20
#Project=
#Sample=
#Site=
#Title=	Mb_40_24_29_2x_45s_532 nm_x100_100%_600 gr_mm
#Remark=
#Date=	14.07.2022 12:50
#Acquired=	14.07.2022 12:50:36
#Base:Fit=	10.08.2022 10:47:00
#Base:Sub=	10.08.2022 10:47:12
#Filter:Polynom=	16.08.2022 10:11:48
#AxisType[0]=Intens
#AxisUnit[0]=Cnt
#AxisType[1]=Spectr
#AxisUnit[1]=1/cm
200.554	17.5484
204.183	11.375
207.813	11.047
211.439	17.19
215.065	26.0557
218.688	37.0387
222.312	46.6783
225.933	55.9365
229.552	65.0248
233.171	74.7478
236.787	81.3111
240.402	87.6918
244.015	95.5296
247.627	102.699
251.24	111.039
254.849	121.281
258.457	131.482
262.063	138.864
265.668	145.424
269.271	148.98
272.873	152.578
276.474	156.92
280.073	163.252
283.671	165.726
287.268	172.207
290.863	184.06
294.456	198.174
298.049	209.141
301.637	221.329
305.227	230.242
308.815	238.819
312.402	246.632
315.987	252.962
319.569	256.073
323.151	257.229
326.733	255.773
330.31	254.275
333.889	252.511
337.464	243.419
341.039	238.839
344.611	232.416
348.184	225.07
351.754	211.385
355.324	195.58
358.89	180.069
362.455	167.314
366.021	151.164
369.584	136
373.145	126.101
376.707	120.049
380.265	113.893
383.822	109.475
387.378	105.946
390.934	106.103
394.487	106.396
398.038	108.404
401.588	108.975
405.137	109.979
408.685	111.302
412.23	112.561
415.775	113.318
419.318	113.557
422.86	112.903
426.401	112.736
429.94	109.611
433.478	106.243
437.012	101.031
440.547	92.7064
444.081	86.0329
447.613	79.5493
451.142	70.6782
454.672	60.4954
458.2	51.6859
461.725	44.1908
465.251	39.5054
468.775	37.0658
472.296	34.4437
475.817	33.0544
479.335	33.0397
482.854	31.0733
486.37	29.9178
489.886	28.3239
493.398	30.0601
496.91	27.8333
500.422	27.0529
503.93	25.9684
507.438	23.1119
510.946	21.365
514.45	19.0825
517.954	16.7484
521.456	13.4672
524.956	11.6913
528.456	9.07704
531.956	7.33908
535.452	4.98516
538.947	0.881293
542.441	0.316266
545.934	0.0108121
549.425	-0.463442
552.915	-0.737424
556.403	1.04815
559.889	4.08829
563.375	5.83439
566.859	9.55888
570.342	10.422
573.824	11.0613
577.303	11.5089
580.782	12.937
584.26	12.0013
587.734	12.4862
591.21	11.1105
594.684	9.95994
598.154	11.1431
601.626	10.4463
605.094	8.51023
608.562	9.45996
612.027	7.40951
615.493	5.86218
618.956	6.07804
622.419	3.13461
625.879	2.96492
629.338	5.76213
632.797	5.8714
636.254	6.67425
639.708	8.06251
643.162	7.24867
646.614	8.39604
650.067	8.65999
653.516	9.77447
656.964	9.08335
660.411	9.27101
663.857	7.28295
667.301	7.76594
670.744	5.88391
674.186	9.54972
677.626	12.002
681.065	13.0785
684.503	13.9401
687.939	15.4533
691.372	13.9229
694.806	15.2209
698.239	13.1036
701.67	13.4007
705.098	14.115
708.526	13.9906
711.954	15.9762
715.378	15.7668
718.802	13.8305
722.226	11.4402
725.646	11.0501
729.067	10.1607
732.484	11.4694
735.902	12.1848
739.317	13.5464
742.731	15.9722
746.145	18.166
749.556	22.555
752.966	29.3825
756.377	34.9702
759.784	42.1476
763.19	42.1347
766.594	46.0432
770	48.8641
773.402	49.9426
776.803	49.9519
780.202	51.0971
783.6	53.7802
786.997	56.788
790.393	57.4938
793.787	57.404
797.18	56.4109
800.572	54.3336
803.963	51.8328
807.35	49.2683
810.738	49.1604
814.125	48.7715
817.51	49.4334
820.894	50.5209
824.275	53.2966
827.657	52.091
831.037	53.9657
834.414	52.8967
837.792	49.9308
841.167	48.5709
844.542	46.2973
847.914	45.4584
851.287	45.9346
854.656	43.4613
858.026	41.328
861.393	40.0044
864.761	40.026
868.125	38.8836
871.489	39.0797
874.85	39.1437
878.213	38.7424
881.572	39.2835
884.931	37.9101
888.287	38.3572
891.643	37.6345
894.997	36.5839
898.352	38.6242
901.704	40.5639
905.055	42.9641
908.404	42.6663
911.75	43.0064
915.097	41.5377
918.443	38.2517
921.787	36.3661
925.13	38.1923
928.472	37.5945
931.813	35.1178
935.15	32.5873
938.488	28.7935
941.825	25.0482
945.158	20.3911
948.493	18.8376
951.824	18.1974
955.156	18.9006
958.486	16.1659
961.814	14.4817
965.142	17.5429
968.467	20.8563
971.79	24.8337
975.115	30.742
978.436	34.834
981.756	39.8489
985.077	44.9227
988.394	46.3814
991.71	44.9329
995.025	47.1691
998.341	46.6444
1001.65	47.6318
1004.97	50.0831
1008.28	50.4788
1011.58	48.8655
1014.89	50.2986
1018.2	52.6946
1021.5	53.4233
1024.81	52.9068
1028.11	52.2735
1031.41	54.7085
1034.71	54.4083
1038.01	55.8171
1041.31	59.1876
1044.6	63.3893
1047.9	66.236
1051.19	68.0496
1054.48	66.8804
1057.77	67.8573
1061.06	63.2257
1064.35	60.6087
1067.64	57.3736
1070.93	54.2783
1074.21	52.694
1077.49	50.8095
1080.78	50.5431
1084.06	50.1685
1087.34	49.982
1090.61	49.2442
1093.89	52.3122
1097.17	53.8457
1100.44	54.2125
1103.71	55.2496
1106.99	54.7617
1110.26	55.3438
1113.52	54.7834
1116.79	55.8869
1120.06	56.6672
1123.32	54.5745
1126.59	52.3324
1129.85	48.1376
1133.11	44.2188
1136.37	41.4718
1139.63	36.109
1142.89	30.9041
1146.15	29.2573
1149.4	24.1056
1152.66	21.0504
1155.91	16.9707
1159.16	14.7463
1162.41	14.0772
1165.66	9.73102
1168.91	8.50708
1172.16	9.49324
1175.4	9.61176
1178.65	11.2304
1181.89	12.9835
1185.13	14.8405
1188.37	17.0923
1191.61	20.6016
1194.85	25.3805
1198.08	32.1724
1201.32	35.9592
1204.55	41.7356
1207.79	44.5703
1211.02	51.0487
1214.25	59.6829
1217.48	66.8702
1220.71	74.8016
1223.93	81.6747
1227.16	91.5775
1230.38	99.0283
1233.6	106.365
1236.83	115.852
1240.05	125.887
1243.26	135.159
1246.48	145.565
1249.7	156.335
1252.92	164.723
1256.13	171.776
1259.34	179.502
1262.55	188.607
1265.76	196.623
1268.97	203.839
1272.18	210.275
1275.39	216.797
1278.59	222.578
1281.8	225.063
1285	230.853
1288.2	233.024
1291.4	236.439
1294.6	237.892
1297.8	238.173
1301	237.949
1304.19	239.803
1307.39	241.022
1310.58	238.6
1313.77	237.059
1316.96	234.958
1320.15	234.883
1323.34	232.421
1326.53	226.967
1329.72	223.087
1332.9	218.976
1336.08	215.087
1339.27	211.458
1342.45	207.035
1345.63	200.485
1348.8	191.666
1351.98	185.901
1355.16	181.73
1358.33	174.414
1361.51	169.724
1364.68	162.327
1367.85	158.91
1371.02	155.128
1374.19	150.626
1377.36	149.167
1380.52	147.172
1383.69	145.561
1386.85	144.574
1390.02	143.126
1393.18	141.858
1396.34	142.252
1399.5	144.703
1402.65	145.433
1405.81	149.34
1408.97	156.259
1412.12	165.465
1415.27	175.935
1418.43	189.606
1421.58	202.084
1424.73	216.885
1427.87	232.815
1431.02	248.006
1434.17	261.119
1437.31	273.248
1440.46	282.855
1443.6	291.85
1446.74	295.175
1449.88	297.786
1453.02	295.988
1456.16	293.546
1459.29	284.984
1462.43	275.885
1465.56	265.614
1468.69	250.977
1471.83	235.647
1474.95	218.701
1478.08	203.244
1481.21	188.436
1484.34	175.091
1487.47	162.954
1490.59	153.985
1493.71	146.366
1496.84	137.549
1499.96	130.852
1503.07	124.671
1506.19	120.313
1509.31	113.651
1512.43	111.206
1515.54	108.243
1518.65	105.251
1521.77	105.076
1524.88	104.115
1527.99	104.57
1531.1	105.268
1534.21	108.315
1537.31	111.34
1540.42	117.4
1543.52	122.774
1546.63	126.406
1549.73	132.51
1552.83	140.68
1555.93	147.396
1559.03	153.965
1562.12	158.58
1565.22	166.326
1568.31	174.928
1571.41	183.454
1574.5	193.175
1577.59	203.396
1580.68	213.787
1583.77	219.909
1586.86	226.501
1589.95	234.816
1593.03	237.303
1596.11	241.29
1599.2	239.03
1602.28	237.485
1605.36	237.238
1608.44	235.999
1611.52	232.522
1614.6	230.561
1617.67	231.479
1620.75	228.645
1623.82	227.6
1626.89	228.627
1629.96	228.724
1633.04	229.633
1636.11	230.52
1639.17	235.269
1642.24	241.975
1645.31	249.018
1648.37	254.118
1651.43	257.801
1654.5	260.376
1657.56	258.676
1660.62	255.068
1663.67	252.876
1666.73	244.131
1669.79	232.851
1672.84	219.725
1675.9	204.363
1678.95	190.475
1682	174.072
1685.05	156.924
1688.1	141.732
1691.15	127.843
1694.2	114.431
1697.25	100.483
1700.29	87.3086
1703.33	78.1799
1706.38	68.2508
1709.42	59.865
1712.46	53.6183
1715.5	49.5096
1718.54	44.2018
1721.57	40.1656
1724.61	35.0485
1727.64	33.4667
1730.68	30.954
1733.71	28.7072
1736.74	25.5976
1739.77	25.0828
1742.8	22.5044
1745.83	19.6857
1748.85	18.0959
1751.88	17.0271
1754.91	16.19
1757.93	14.7713
1760.95	13.8491
1763.97	14.0295
1766.99	14.076
1770.01	13.0476
1773.03	11.9488
1776.04	11.2023
1779.06	11.6053
1782.07	10.937
1785.09	10.478
1788.1	10.5991
1791.11	10.8146
1794.12	9.66387
1797.13	8.57685
1800.13	8.51006
1803.14	7.61496
1806.15	6.27998
1809.15	4.51156
1812.15	3.75567
1815.16	2.55682
1818.15	1.28927
1821.16	0.878684
1824.15	0.647117
1827.15	1.22822
1830.15	0.635355
1833.14	-0.687198
1836.14	0.192027
1839.13	2.333
1842.12	3.39183
1845.11	2.94613
1848.1	3.20012
1851.09	4.32075
1854.08	7.54623
1857.06	9.94644
1860.05	11.5656
1863.03	11.1233
1866.01	12.1752
1869	11.277
1871.98	13.2515
1874.96	13.337
1877.93	13.1157
1880.91	12.867
1882.47	11.9546
1885.46	10.0808
1888.44	10.159
1891.43	8.6301
1894.42	8.41695
1897.4	10.2024
1900.39	9.67192
1903.37	9.45446
1906.35	9.68315
1909.33	9.1485
1912.31	8.14032
1915.29	6.69831
1918.26	5.74953
1921.24	8.15252
1924.21	9.65066
1927.19	9.21777
1930.16	5.86985
1933.13	4.03502
1936.1	5.8029
1939.07	5.12696
1942.04	6.08098
1945	6.51266
1947.97	6.05024
1950.93	4.86237
1953.9	4.53943
1956.86	2.67589
1959.82	3.02055
1962.78	3.68524
1965.74	5.65255
1968.7	7.53304
1971.65	8.12313
1974.61	8.41442
1977.57	10.0778
1980.52	9.55135
1983.47	9.06464
1986.42	10.1971
1989.37	9.49967
1992.32	10.1278
1995.27	12.1517
1998.22	12.8969
2001.17	12.327
2004.11	11.494
2007.05	11.8707
2010	12.1501
2012.94	12.2463
2015.88	12.7186
2018.82	11.3206
2021.76	10.9549
2024.7	9.74511
2027.63	10.3937
2030.57	10.7991
2033.5	13.0337
2036.44	13.9558
2039.37	15.8288
2042.3	16.8469
2045.23	19.974
2048.16	22.9724
2051.08	25.6939
2054.01	27.2872
2056.94	30.1205
2059.86	32.2461
2062.79	35.7025
2065.71	40.4693
2068.63	43.9094
2071.55	47.5784
2074.47	50.7632
2077.39	53.7166
2080.31	57.8875
2083.22	61.1851
2086.13	65.8322
2089.05	69.2812
2091.96	72.9052
2094.87	77.1118
2097.78	81.9208
2100.69	89.5168
2103.6	95.4223
2106.51	103.475
2109.42	110.783
2112.32	117.541
2115.23	125.558
2118.13	133.543
2121.03	140.907
2123.93	148.682
2126.83	156.872
2129.73	168.149
2132.63	179.202
2135.53	189.402
2138.42	199.479
2141.32	209.881
2144.21	220.118
2147.1	230.103
2150	237.651
2152.89	247.132
2155.78	253.723
2158.66	261.802
2161.55	267.154
2164.44	270.616
2167.32	273.547
2170.21	276.22
2173.09	275.863
2175.97	275.616
2178.85	272.059
2181.73	266.02
2184.61	260.232
2187.49	252.417
2190.37	244.508
2193.24	234.893
2196.12	227.081
2198.99	217.563
2201.87	207.616
2204.74	197.396
2207.61	188.107
2210.48	178.85
2213.35	167.828
2216.21	159.015
2219.08	148.902
2221.95	140.152
2224.81	131.73
2227.67	124.582
2230.54	115.633
2233.4	106.999
2236.26	99.2285
2239.11	92.6301
2241.97	85.6171
2244.83	79.5573
2247.69	73.4221
2250.54	68.3914
2253.4	63.592
2256.25	60.0678
2259.1	56.1965
2261.95	52.5804
2264.8	48.3865
2267.65	44.6256
2270.5	43.1993
2273.34	38.8464
2276.19	36.5045
2279.03	35.3047
2281.88	33.6908
2284.72	32.502
2287.56	29.7709
2290.4	26.6073
2293.24	23.3711
2296.08	23.5504
2298.92	22.2733
2301.76	21.5818
2304.59	20.3586
2307.43	18.5908
2310.26	17.104
2313.09	16.6008
2315.92	16.1127
2318.75	16.8219
2321.58	16.7547
2324.41	16.4137
2327.24	14.417
2330.06	12.1123
2332.89	11.8908
2335.71	11.683
2338.54	10.1947
2341.36	7.89677
2344.18	5.37108
2347	5.44759
2349.82	5.24856
2352.64	2.85808
2355.45	1.8406
2358.27	0.704974
2361.08	0.580777
2363.9	2.19587
2366.71	3.10535
2369.52	3.38184
2372.33	3.14126
2375.14	1.45665
2377.95	1.40251
2380.76	1.80394
2383.57	2.68722
2386.37	3.1405
2389.18	2.04381
2391.98	3.15244
2394.79	2.81913
2397.59	3.17217
2400.39	4.2456
2403.19	3.20095
2405.99	3.40318
2408.78	3.16812
2411.58	2.85538
2414.38	2.43915
2417.17	1.86569
2419.97	2.14347
2422.76	1.88857
2425.55	2.62961
2428.34	2.40057
2431.13	3.16543
2433.92	3.41937
2436.71	2.13139
2439.49	2.65555
2442.28	3.17506
2445.06	3.02636
2447.85	1.97345
2450.63	2.52664
2453.41	1.57828
2456.19	1.38517
2458.97	2.67495
2461.75	4.63885
2464.53	5.31958
2467.31	5.3731
2470.08	5.40575
2472.86	6.33409
2475.63	7.53116
2478.4	6.60441
2481.17	5.38736
2483.94	5.67023
2486.72	5.84241
2489.48	6.42787
2492.25	5.57137
2495.02	4.85968
2497.79	5.07562
2500.55	5.46142
2503.31	3.54329
2506.08	1.91328
2508.84	1.82499
2511.6	0.622967
2514.36	1.48371
2517.12	0.496063
2519.88	1.8773
2522.63	1.88224
2525.39	1.37658
2528.14	1.71302
2530.9	2.43313
2533.65	3.43668
2536.4	3.42552
2539.15	4.41482
2541.9	4.91641
2544.65	5.72808
2547.4	6.08216
2550.15	8.43588
2552.89	10.4151
2555.64	10.9829
2558.38	12.4463
2561.12	12.3534
2563.87	13.0349
2566.61	12.9481
2569.35	12.5441
2572.09	12.5503
2574.83	13.4243
2577.56	12.8459
2580.3	13.1075
2583.04	12.2281
2585.77	10.8802
2588.5	8.54323
2591.23	5.60469
2593.97	5.70856
2596.7	5.30196
2599.43	5.47914
2602.15	5.78541
2604.88	5.48581
2607.61	5.15579
2610.33	5.90584
2613.06	7.21578
2615.78	8.68055
2618.51	8.19024
2621.23	8.81851
2623.95	8.0739
2626.67	6.98524
2629.39	6.98469
2632.1	7.61252
2634.82	8.60656
2637.54	9.61414
2640.25	10.7686
2642.97	10.2861
2645.68	10.6628
2648.39	10.5047
2651.1	11.0437
2653.81	10.7683
2656.52	10.7181
2659.23	11.0983
2661.94	11.4463
2664.64	11.4708
2667.35	13.5904
2670.05	14.3808
2672.76	16.5691
2675.46	15.2509
2678.16	15.5053
2680.86	15.4913
2683.56	15.2064
2686.26	14.5519
2688.96	12.1453
2691.65	10.4017
2694.35	11.7984
2697.04	12.9041
2699.74	15.9388
2702.43	15.957
2705.12	17.8213
2707.81	18.7225
2710.5	19.9959
2713.19	20.8601
2715.88	23.9983
2718.57	25.5191
2721.25	25.474
2723.94	24.7552
2726.62	24.9162
2729.3	25.466
2731.99	26.3401
2734.67	27.0052
2737.35	25.3536
2740.03	23.4143
2742.71	23.5094
2745.38	21.5105
2748.06	20.2662
2750.74	17.3951
2753.41	14.891
2756.09	13.1729
2758.76	11.9952
2761.43	11.4764
2764.1	10.7509
2766.77	9.46397
2769.44	7.10027
2772.11	5.67491
2774.77	3.87778
2777.44	3.38941
2780.11	2.33079
2782.77	1.12886
2785.43	-0.195304
2788.1	-0.545274
2790.76	-2.30576
2793.42	-1.39729
2796.08	-0.447057
2798.74	0.423625
2801.4	-0.589734
2804.05	-1.41154
2806.71	-1.97872
2809.36	-1.45565
2812.02	-1.17563
2814.67	-0.737194
2817.32	2.6521
2819.97	8.1959
2822.62	16.3332
2825.27	26.085
2827.92	38.2755
2830.57	51.7566
2833.22	65.737
2835.86	82.806
2838.51	101.114
2841.15	122.394
2843.79	143.156
2846.43	166.599
2849.08	192.136
2851.72	216.6
2854.36	241.903
2856.99	268.039
2859.63	292.562
2862.27	316.434
2864.9	337.129
2867.54	356.399
2870.17	374.95
2872.8	392.47
2875.43	409.517
2878.07	424.413
2880.7	440.273
2883.32	459.029
2885.95	477.959
2888.58	496.812
2891.21	517.674
2893.83	538.559
2896.46	560.697
2899.08	585.871
2901.7	612.909
2904.32	640.213
2906.94	670.345
2909.56	703.382
2912.18	736.96
2914.8	770.968
2917.42	801.648
2920.03	827.049
2922.65	847.679
2925.26	863.775
2927.88	873.49
2930.49	878.006
2933.1	876.546
2935.71	867.648
2938.32	853.713
2940.93	833.626
2943.54	808.068
2946.14	780.649
2948.75	750.32
2951.35	715.047
2953.96	678.619
2956.56	641.201
2959.16	603.731
2961.77	567.952
2964.37	534.297
2966.96	502.161
2969.56	469.291
2972.16	439.583
2974.76	410.801
2977.35	383.504
2979.95	354.056
2982.54	323.813
2985.14	294.134
2987.73	267.352
2990.32	241.062
2992.91	213.307
2995.5	187.922
2998.09	164.184
3000.68	141.068
3003.26	119.808
3005.85	99.1733
3008.43	81.6319
3011.02	65.4822
3013.6	49.9497
3016.19	36.7795
3018.77	27.8914
3021.35	18.7761
3023.93	12.2255
3026.5	7.84009
3029.08	4.84486
3031.66	3.52863
3034.24	3.40502
3036.81	3.47274
3039.39	5.51961
3041.96	6.75855
3044.53	9.01305
3047.1	11.1665
3049.67	12.7583
3052.24	16.0724
3054.81	16.2126
3057.38	18.7839
3059.95	18.9379
3062.52	18.4917
3065.08	17.6298
3067.65	16.9707
3070.21	15.7983
3072.77	13.4848
3075.33	10.1037
3077.89	7.65556
3080.45	4.66002
3083.01	3.07318
3085.57	0.922782
3088.13	0.265728
3090.68	1.28076
3093.24	0.518499
3095.79	0.954739
3098.35	0.5137
3100.9	1.67977
3103.45	3.84603
3106	5.39068
3108.55	7.61506
3111.1	11.7623
3113.65	14.5451
3116.2	18.2612
3118.75	21.5387
3121.29	25.9133
3123.84	29.5663
3126.38	34.1619
3128.92	39.378
3131.47	44.1489
3134.01	48.3305
3136.55	53.8637
3139.09	58.8843
3141.63	65.1027
3144.17	70.3393
3146.7	75.804
3149.24	81.4245