File: data/Raman/poly_smoothed/Mb_40_24_26_1x_45s_532 nm_x100_100%_600 gr_mm_01.txt
#Acq. time (s)=	45
#Accumulations=	2
#Range (cm-¹)=	200...3150
#Windows=	2
#Auto scanning=	Off
#Autofocus=	Off
#Macrospot=	Off
#AutoExposure=	Off
#Spike filter=	Multiple accum.
#Delay time (s)=	0
#Binning=	1
#Readout mode=	Signal
#DeNoise=	Off
#ICS correction=	On
#Dark correction=	Off
#Inst. Process=	Off
#Detector Gain=	Best Dynamic Range
#Detector ADC=	20 kHz
#Detector temperature (°C)=	-70.08
#Instrument=	LabRAM HR Evol
#Detector=	Synapse
#Objective=	x100
#Grating=	600 gr/mm
#ND Filter=	100%
#Laser (nm)=	532
#Hole=	100.021
#Range=	Auto
#Laser Pol.=	No
#Raman. Pol.=	No
#Laser Pol. (°)=	-0.0007625
#Raman Pol. (°)=	89.9995
#Collection=	Microscope
#StageXY=	Marzhauser
#StageZ=	Marzhauser
#X (µm)=	-2504.3
#Y (µm)=	-108.7
#Z (µm)=	-10.95
#Full time(mm:ss)=	3:18
#Project=
#Sample=
#Site=
#Title=	Mb_40_24_26_2x_45s_532 nm_x100_100%_600 gr_mm
#Remark=
#Date=	14.07.2022 12:38
#Acquired=	14.07.2022 12:38:26
#Base:Fit=	10.08.2022 10:47:00
#Base:Sub=	10.08.2022 10:47:12
#Filter:Polynom=	16.08.2022 10:11:48
#AxisType[0]=Intens
#AxisUnit[0]=Cnt
#AxisType[1]=Spectr
#AxisUnit[1]=1/cm
200.554	3.07341
204.183	4.47942
207.813	3.08604
211.439	3.3646
215.065	4.68173
218.688	4.11742
222.312	4.32302
225.933	5.38617
229.552	8.07199
233.171	10.1535
236.787	12.5297
240.402	13.1457
244.015	13.9055
247.627	15.3133
251.24	16.006
254.849	16.8795
258.457	17.2926
262.063	20.3835
265.668	21.461
269.271	23.5772
272.873	24.8588
276.474	25.1305
280.073	24.0738
283.671	22.1452
287.268	22.4891
290.863	21.7139
294.456	21.9912
298.049	23.8873
301.637	23.0806
305.227	21.1713
308.815	20.2934
312.402	20.1868
315.987	19.6004
319.569	19.5285
323.151	19.3865
326.733	18.0552
330.31	19.1725
333.889	20.0604
337.464	20.0088
341.039	20.8341
344.611	19.9163
348.184	20.4373
351.754	20.3399
355.324	19.3266
358.89	18.1793
362.455	14.3425
366.021	12.3669
369.584	12.1233
373.145	12.9871
376.707	13.4243
380.265	13.6755
383.822	13.8651
387.378	14.2819
390.934	13.6937
394.487	15.0574
398.038	14.8978
401.588	14.1764
405.137	16.4023
408.685	17.9394
412.23	17.9072
415.775	18.8659
419.318	20.9742
422.86	21.7897
426.401	21.7113
429.94	21.0621
433.478	19.1218
437.012	18.673
440.547	18.2228
444.081	15.6698
447.613	12.9081
451.142	12.1765
454.672	13.8417
458.2	14.3984
461.725	14.1482
465.251	15.4463
468.775	14.2893
472.296	15.395
475.817	15.2542
479.335	16.7964
482.854	17.1471
486.37	17.7687
489.886	19.0805
493.398	18.9419
496.91	19.3289
500.422	20.0803
503.93	23.2002
507.438	25.0137
510.946	24.7722
514.45	24.5431
517.954	24.5926
521.456	24.7906
524.956	24.6417
528.456	23.731
531.956	22.4182
535.452	20.9112
538.947	20.5308
542.441	19.7601
545.934	17.4241
549.425	17.1055
552.915	15.4466
556.403	12.7039
559.889	10.8761
563.375	10.3966
566.859	8.89669
570.342	7.08907
573.824	5.00885
577.303	4.28176
580.782	3.89003
584.26	4.03566
587.734	3.24134
591.21	2.93339
594.684	1.33989
598.154	1.53368
601.626	1.65266
605.094	2.18403
608.562	0.710856
612.027	0.797747
615.493	0.180534
618.956	-0.366076
622.419	1.3926
625.879	1.73986
629.338	1.16009
632.797	3.37188
636.254	3.85134
639.708	3.61828
643.162	4.40646
646.614	4.74314
650.067	4.77416
653.516	6.28694
656.964	6.17935
660.411	8.16105
663.857	11.0843
667.301	12.2037
670.744	12.757
674.186	15.1081
677.626	16.5726
681.065	17.715
684.503	19.8608
687.939	20.2844
691.372	20.9379
694.806	21.6024
698.239	22.5246
701.67	22.762
705.098	22.2172
708.526	21.7827
711.954	20.982
715.378	21.2199
718.802	21.5506
722.226	19.718
725.646	19.8553
729.067	18.6097
732.484	18.9454
735.902	19.3853
739.317	21.5123
742.731	23.5963
746.145	25.032
749.556	27.3165
752.966	30.1885
756.377	33.1462
759.784	37.3637
763.19	40.5818
766.594	42.8237
770	45.3664
773.402	48.1801
776.803	52.0859
780.202	54.141
783.6	55.8571
786.997	57.611
790.393	58.2711
793.787	57.5988
797.18	59.2234
800.572	58.1618
803.963	58.6555
807.35	59.4773
810.738	58.3467
814.125	58.588
817.51	60.0681
820.894	61.1098
824.275	62.7268
827.657	60.785
831.037	60.3249
834.414	59.8722
837.792	58.2494
841.167	57.7608
844.542	56.5053
847.914	53.874
851.287	52.5312
854.656	51.5266
858.026	49.3958
861.393	48.1328
864.761	49.3057
868.125	49.1527
871.489	47.1021
874.85	44.9476
878.213	44.4448
881.572	43.2459
884.931	43.1721
888.287	44.4567
891.643	45.0853
894.997	45.7445
898.352	47.2677
901.704	48.0026
905.055	47.2985
908.404	45.8305
911.75	44.1477
915.097	44.7393
918.443	43.3605
921.787	42.2322
925.13	42.366
928.472	41.7528
931.813	40.6208
935.15	38.2493
938.488	36.6747
941.825	35.3057
945.158	35.2938
948.493	35.0454
951.824	34.4941
955.156	31.4956
958.486	29.5656
961.814	27.8777
965.142	26.1876
968.467	26.5057
971.79	26.2686
975.115	25.6226
978.436	26.3234
981.756	26.6912
985.077	25.0253
988.394	24.6322
991.71	24.6966
995.025	25.0841
998.341	25.6827
1001.65	24.7166
1004.97	24.3421
1008.28	24.5653
1011.58	24.8624
1014.89	24.8938
1018.2	25.1787
1021.5	25.5313
1024.81	28.354
1028.11	32.1755
1031.41	33.9486
1034.71	35.1993
1038.01	36.226
1041.31	39.2148
1044.6	41.7054
1047.9	43.3911
1051.19	45.5268
1054.48	45.9984
1057.77	46.8937
1061.06	44.3149
1064.35	42.1818
1067.64	39.2426
1070.93	38.4786
1074.21	37.9339
1077.49	34.6822
1080.78	30.3627
1084.06	27.3999
1087.34	23.0094
1090.61	21.262
1093.89	20.1838
1097.17	19.4076
1100.44	19.401
1103.71	20.6073
1106.99	23.2434
1110.26	23.6937
1113.52	24.0294
1116.79	23.445
1120.06	24.3486
1123.32	25.0209
1126.59	24.1952
1129.85	22.5061
1133.11	21.7291
1136.37	23.152
1139.63	22.2038
1142.89	22.27
1146.15	21.3552
1149.4	20.6428
1152.66	19.7505
1155.91	15.3565
1159.16	12.4792
1162.41	10.4609
1165.66	7.53573
1168.91	6.53715
1172.16	7.76462
1175.4	9.45262
1178.65	7.97116
1181.89	7.08229
1185.13	7.53499
1188.37	7.08763
1191.61	7.41448
1194.85	6.77656
1198.08	7.43888
1201.32	9.30444
1204.55	10.8391
1207.79	13.479
1211.02	16.6146
1214.25	19.2226
1217.48	22.43
1220.71	24.1206
1223.93	26.8208
1227.16	28.3441
1230.38	31.1602
1233.6	31.722
1236.83	33.7329
1240.05	36.8166
1243.26	37.1037
1246.48	38.9308
1249.7	41.5649
1252.92	40.5736
1256.13	39.5246
1259.34	41.771
1262.55	44.7742
1265.76	48.6081
1268.97	52.3899
1272.18	55.0522
1275.39	58.7388
1278.59	62.4822
1281.8	63.7776
1285	66.0035
1288.2	67.3761
1291.4	68.8261
1294.6	70.2937
1297.8	71.1074
1301	72.006
1304.19	70.3187
1307.39	69.066
1310.58	68.4055
1313.77	67.6132
1316.96	65.6873
1320.15	62.0336
1323.34	59.2129
1326.53	57.5657
1329.72	53.2473
1332.9	52.385
1336.08	52.5251
1339.27	53.832
1342.45	55.442
1345.63	55.4358
1348.8	54.897
1351.98	55.2212
1355.16	54.7754
1358.33	53.3499
1361.51	51.4439
1364.68	49.9817
1367.85	49.7464
1371.02	49.164
1374.19	47.5886
1377.36	48.1158
1380.52	48.5304
1383.69	47.5036
1386.85	47.588
1390.02	47.593
1393.18	47.5332
1396.34	46.592
1399.5	46.9186
1402.65	52.1013
1405.81	56.1135
1408.97	61.4803
1412.12	68.2984
1415.27	75.0714
1418.43	82.5896
1421.58	89.4755
1424.73	96.2455
1427.87	103.817
1431.02	109.431
1434.17	115.091
1437.31	119.867
1440.46	125.011
1443.6	128.728
1446.74	129.472
1449.88	130.047
1453.02	128.863
1456.16	124.791
1459.29	118.632
1462.43	109.834
1465.56	102.812
1468.69	93.9514
1471.83	83.5412
1474.95	76.0646
1478.08	69.02
1481.21	63.8724
1484.34	55.0114
1487.47	47.1987
1490.59	41.8154
1493.71	36.9594
1496.84	31.7453
1499.96	27.7251
1503.07	26.6215
1506.19	25.4088
1509.31	25.0805
1512.43	24.7113
1515.54	26.1006
1518.65	26.8536
1521.77	26.9191
1524.88	27.4136
1527.99	28.8161
1531.1	27.9456
1534.21	28.1429
1537.31	28.4957
1540.42	28.5036
1543.52	28.3614
1546.63	29.1897
1549.73	30.6749
1552.83	32.4591
1555.93	32.8395
1559.03	33.9161
1562.12	33.1436
1565.22	35.0652
1568.31	36.3196
1571.41	36.6654
1574.5	38.8109
1577.59	41.5877
1580.68	43.0605
1583.77	44.6656
1586.86	45.7274
1589.95	47.1141
1593.03	48.7944
1596.11	50.8693
1599.2	51.3027
1602.28	52.4969
1605.36	53.6444
1608.44	54.4449
1611.52	54.9859
1614.6	55.8133
1617.67	55.5951
1620.75	57.3322
1623.82	59.5988
1626.89	59.4187
1629.96	59.5649
1633.04	59.9848
1636.11	60.6517
1639.17	60.7136
1642.24	61.01
1645.31	60.2081
1648.37	60.356
1651.43	60.7299
1654.5	59.0987
1657.56	57.5766
1660.62	55.4148
1663.67	52.1531
1666.73	50.7919
1669.79	48.9367
1672.84	46.6012
1675.9	43.4193
1678.95	41.52
1682	40.4537
1685.05	38.0062
1688.1	35.2031
1691.15	32.9291
1694.2	31.1035
1697.25	29.7895
1700.29	28.9265
1703.33	26.6539
1706.38	24.3357
1709.42	24.3894
1712.46	24.0248
1715.5	22.303
1718.54	20.9577
1721.57	20.1039
1724.61	18.6019
1727.64	17.3755
1730.68	15.8341
1733.71	14.2164
1736.74	13.0875
1739.77	11.6198
1742.8	11.1916
1745.83	11.1487
1748.85	10.1905
1751.88	10.3824
1754.91	10.9197
1757.93	9.43952
1760.95	9.25005
1763.97	9.22602
1766.99	9.3289
1770.01	9.11944
1773.03	9.16566
1776.04	8.2774
1779.06	8.05997
1782.07	8.55884
1785.09	8.94547
1788.1	7.66965
1791.11	6.20499
1794.12	5.78336
1797.13	5.3855
1800.13	5.06367
1803.14	5.92352
1806.15	5.41578
1809.15	5.01245
1812.15	4.61815
1815.16	5.09905
1818.15	4.50894
1821.16	3.28827
1824.15	3.83742
1827.15	3.34319
1830.15	3.34148
1833.14	3.25496
1836.14	2.44289
1839.13	2.37717
1842.12	2.55846
1845.11	1.5642
1848.1	1.51783
1851.09	1.23251
1854.08	0.978957
1857.06	1.03101
1860.05	1.64315
1863.03	2.35274
1866.01	2.08188
1869	3.17916
1871.98	5.00123
1874.96	5.22513
1877.93	5.77804
1880.91	5.71232
1882.47	5.35578
1885.46	4.86659
1888.44	4.61716
1891.43	4.02636
1894.42	3.69118
1897.4	3.26515
1900.39	3.20161
1903.37	3.22947
1906.35	3.42279
1909.33	3.23509
1912.31	4.26396
1915.29	4.27634
1918.26	4.32926
1921.24	5.89123
1924.21	5.0709
1927.19	5.87341
1930.16	5.90052
1933.13	5.71828
1936.1	4.90997
1939.07	5.22131
1942.04	5.43719
1945	5.00902
1947.97	4.04536
1950.93	4.56362
1953.9	3.65465
1956.86	2.80736
1959.82	2.19708
1962.78	1.23451
1965.74	0.0435752
1968.7	-0.0256386
1971.65	-0.434826
1974.61	-0.0749186
1977.57	-0.698856
1980.52	0.180583
1983.47	0.380815
1986.42	1.00891
1989.37	0.97628
1992.32	1.42811
1995.27	1.22188
1998.22	0.312775
2001.17	0.846568
2004.11	0.986693
2007.05	0.792317
2010	0.160762
2012.94	1.11039
2015.88	0.92294
2018.82	1.36549
2021.76	1.437
2024.7	1.57557
2027.63	0.98515
2030.57	0.41894
2033.5	0.449372
2036.44	1.74813
2039.37	1.99372
2042.3	1.63226
2045.23	2.30636
2048.16	3.12696
2051.08	3.75952
2054.01	4.22118
2056.94	4.96422
2059.86	5.40018
2062.79	5.6566
2065.71	7.1549
2068.63	7.16178
2071.55	8.23131
2074.47	9.67772
2077.39	9.31757
2080.31	9.89176
2083.22	10.4992
2086.13	9.78804
2089.05	10.1283
2091.96	9.99835
2094.87	10.9583
2097.78	12.7322
2100.69	14.4655
2103.6	16.7646
2106.51	19.2094
2109.42	20.5472
2112.32	21.5781
2115.23	23.4468
2118.13	25.3937
2121.03	27.3913
2123.93	29.227
2126.83	31.8221
2129.73	34.1223
2132.63	36.0948
2135.53	38.9866
2138.42	41.4157
2141.32	43.6308
2144.21	46.0917
2147.1	47.0263
2150	48.5339
2152.89	49.2731
2155.78	50.2577
2158.66	51.73
2161.55	53.9508
2164.44	54.9303
2167.32	56.6407
2170.21	57.4952
2173.09	57.2527
2175.97	55.5834
2178.85	53.5111
2181.73	51.7687
2184.61	49.7347
2187.49	48.229
2190.37	46.3799
2193.24	43.7928
2196.12	42.2496
2198.99	39.1476
2201.87	37.8564
2204.74	35.2278
2207.61	33.5118
2210.48	31.2599
2213.35	27.9347
2216.21	25.3526
2219.08	23.3504
2221.95	22.8437
2224.81	22.6878
2227.67	21.3983
2230.54	19.3906
2233.4	18.8199
2236.26	18.4165
2239.11	17.65
2241.97	16.6667
2244.83	14.948
2247.69	13.6686
2250.54	13.2485
2253.4	12.9568
2256.25	12.0381
2259.1	10.8725
2261.95	10.2683
2264.8	10.0447
2267.65	10.287
2270.5	9.69204
2273.34	9.12294
2276.19	8.42025
2279.03	7.85416
2281.88	7.02193
2284.72	6.9669
2287.56	6.44914
2290.4	6.42797
2293.24	5.25881
2296.08	4.47809
2298.92	3.9775
2301.76	3.56803
2304.59	4.57526
2307.43	4.95555
2310.26	4.20422
2313.09	4.61089
2315.92	4.32164
2318.75	5.01994
2321.58	4.65334
2324.41	4.00129
2327.24	3.95459
2330.06	4.70953
2332.89	4.67558
2335.71	4.72135
2338.54	4.55957
2341.36	4.35645
2344.18	4.258
2347	3.36715
2349.82	4.18561
2352.64	3.60654
2355.45	2.18513
2358.27	0.732749
2361.08	0.693806
2363.9	1.30315
2366.71	1.92595
2369.52	1.31902
2372.33	1.82605
2375.14	2.83878
2377.95	2.465
2380.76	2.90194
2383.57	3.08375
2386.37	3.45949
2389.18	3.54657
2391.98	2.71616
2394.79	2.51451
2397.59	2.97044
2400.39	2.87357
2403.19	3.01524
2405.99	3.33758
2408.78	3.18299
2411.58	3.85168
2414.38	4.49667
2417.17	4.60398
2419.97	4.00556
2422.76	4.53429
2425.55	4.53584
2428.34	5.50021
2431.13	6.5202
2433.92	5.25363
2436.71	5.99593
2439.49	5.00574
2442.28	5.88292
2445.06	5.53699
2447.85	5.60872
2450.63	5.32147
2453.41	5.36262
2456.19	5.13782
2458.97	4.79611
2461.75	3.73803
2464.53	2.93438
2467.31	1.4546
2470.08	1.19924
2472.86	1.20598
2475.63	0.305922
2478.4	-0.662855
2481.17	-1.52112
2483.94	-1.86189
2486.72	-1.00371
2489.48	-0.682763
2492.25	0.847684
2495.02	0.941611
2497.79	0.59208
2500.55	0.671925
2503.31	1.31997
2506.08	1.52169
2508.84	2.70084
2511.6	4.81011
2514.36	5.42386
2517.12	5.91516
2519.88	6.65768
2522.63	7.30108
2525.39	7.12762
2528.14	6.57829
2530.9	5.083
2533.65	4.72098
2536.4	4.28152
2539.15	4.38649
2541.9	4.24862
2544.65	4.83238
2547.4	5.09168
2550.15	6.05381
2552.89	8.11856
2555.64	8.80578
2558.38	9.98779
2561.12	10.6958
2563.87	10.3211
2566.61	11.3011
2569.35	12.2098
2572.09	13.0775
2574.83	13.6436
2577.56	14.6782
2580.3	14.9438
2583.04	15.1287
2585.77	15.4742
2588.5	15.8093
2591.23	14.7908
2593.97	13.5493
2596.7	12.6272
2599.43	12.0519
2602.15	12.0681
2604.88	11.5198
2607.61	11.9635
2610.33	12.0472
2613.06	11.4684
2615.78	12.1478
2618.51	13.3211
2621.23	12.8969
2623.95	13.1666
2626.67	12.6447
2629.39	13.0852
2632.1	13.4651
2634.82	13.7714
2637.54	13.9839
2640.25	14.7331
2642.97	15.6373
2645.68	16.6288
2648.39	17.2935
2651.1	17.3821
2653.81	17.5291
2656.52	16.7342
2659.23	16.9244
2661.94	16.3729
2664.64	16.6523
2667.35	17.3117
2670.05	16.7575
2672.76	16.5502
2675.46	17.3328
2678.16	17.2257
2680.86	17.4589
2683.56	18.0564
2686.26	18.3553
2688.96	18.8711
2691.65	20.5869
2694.35	21.9534
2697.04	23.8428
2699.74	24.6765
2702.43	25.5829
2705.12	27.5392
2707.81	29.5921
2710.5	31.1111
2713.19	32.0272
2715.88	33.2124
2718.57	33.3338
2721.25	34.0442
2723.94	33.9397
2726.62	34.0428
2729.3	33.3064
2731.99	33.1043
2734.67	30.9867
2737.35	30.3635
2740.03	29.2538
2742.71	27.4714
2745.38	26.491
2748.06	24.83
2750.74	23.8113
2753.41	22.2982
2756.09	21.0191
2758.76	19.8255
2761.43	18.8629
2764.1	17.6895
2766.77	16.425
2769.44	14.955
2772.11	14.8135
2774.77	13.9778
2777.44	13.4343
2780.11	13.5508
2782.77	12.7626
2785.43	12.5278
2788.1	12.5351
2790.76	12.1706
2793.42	12.2644
2796.08	12.5442
2798.74	12.2709
2801.4	12.337
2804.05	12.1575
2806.71	10.9074
2809.36	9.27252
2812.02	7.952
2814.67	9.48211
2817.32	15.3693
2819.97	24.6849
2822.62	37.1335
2825.27	51.08
2827.92	66.3441
2830.57	82.5452
2833.22	99.536
2835.86	116.701
2838.51	134.016
2841.15	150.722
2843.79	166.435
2846.43	180.122
2849.08	193.737
2851.72	208.714
2854.36	225.814
2856.99	243.546
2859.63	259.743
2862.27	273.254
2864.9	283.555
2867.54	290.355
2870.17	295.894
2872.8	299.665
2875.43	302.993
2878.07	308.068
2880.7	315.129
2883.32	321.055
2885.95	325.048
2888.58	327.341
2891.21	329.156
2893.83	329.012
2896.46	325.529
2899.08	321.561
2901.7	317.438
2904.32	313.159
2906.94	309.449
2909.56	306.505
2912.18	305.773
2914.8	309.168
2917.42	314.581
2920.03	318.724
2922.65	319.627
2925.26	318.629
2927.88	315.879
2930.49	311.823
2933.1	305.918
2935.71	299.3
2938.32	290.11
2940.93	279.918
2943.54	269.457
2946.14	258.173
2948.75	244.541
2951.35	230.768
2953.96	216.993
2956.56	202.68
2959.16	187.748
2961.77	173.505
2964.37	161.683
2966.96	151.011
2969.56	141.529
2972.16	132.432
2974.76	123.197
2977.35	114.659
2979.95	106.78
2982.54	97.8736
2985.14	88.7172
2987.73	78.9334
2990.32	70.1813
2992.91	61.9205
2995.5	53.6655
2998.09	45.7598
3000.68	39.7538
3003.26	32.6249
3005.85	27.9372
3008.43	22.0632
3011.02	17.5918
3013.6	12.8446
3016.19	10.3885
3018.77	7.68182
3021.35	4.64901
3023.93	2.8361
3026.5	1.80754
3029.08	1.28386
3031.66	1.65596
3034.24	1.05249
3036.81	1.1284
3039.39	1.82763
3041.96	1.52468
3044.53	2.24392
3047.1	1.72154
3049.67	1.27698
3052.24	1.23388
3054.81	1.52294
3057.38	1.20387
3059.95	2.4915
3062.52	3.12624
3065.08	3.02981
3067.65	3.0582
3070.21	2.82748
3072.77	2.32334
3075.33	3.07349
3077.89	2.76026
3080.45	1.98753
3083.01	1.6036
3085.57	1.46249
3088.13	1.25519
3090.68	1.56663
3093.24	1.0636
3095.79	0.203996
3098.35	0.928585
3100.9	0.759153
3103.45	0.719027
3106	1.30173
3108.55	1.26894
3111.1	0.931906
3113.65	0.954491
3116.2	1.84416
3118.75	2.28359
3121.29	3.53982
3123.84	4.94451
3126.38	5.43961
3128.92	6.3471
3131.47	7.88631
3134.01	10.0359
3136.55	11.8804
3139.09	13.934
3141.63	15.3119
3144.17	17.0177
3146.7	18.0758
3149.24	20.5127