File: data/Raman/poly_smoothed/Mb_40_24_14_1x_45s_532 nm_x100_100%_600 gr_mm_01.txt
#Acq. time (s)=	45
#Accumulations=	2
#Range (cm-¹)=	200...3150
#Windows=	2
#Auto scanning=	Off
#Autofocus=	Off
#Macrospot=	Off
#AutoExposure=	Off
#Spike filter=	Multiple accum.
#Delay time (s)=	0
#Binning=	1
#Readout mode=	Signal
#DeNoise=	Off
#ICS correction=	On
#Dark correction=	Off
#Inst. Process=	Off
#Detector Gain=	Best Dynamic Range
#Detector ADC=	20 kHz
#Detector temperature (°C)=	-70.08
#Instrument=	LabRAM HR Evol
#Detector=	Synapse
#Objective=	x100
#Grating=	600 gr/mm
#ND Filter=	100%
#Laser (nm)=	532
#Hole=	100.021
#Range=	Auto
#Laser Pol.=	No
#Raman. Pol.=	No
#Laser Pol. (°)=	-0.0007625
#Raman Pol. (°)=	89.9995
#Collection=	Microscope
#StageXY=	Marzhauser
#StageZ=	Marzhauser
#X (µm)=	-2564.7
#Y (µm)=	-87.7
#Z (µm)=	-10.65
#Full time(mm:ss)=	3:18
#Project=
#Sample=
#Site=
#Title=	Mb_40_24_14_2x_45s_532 nm_x100_100%_600 gr_mm
#Remark=
#Date=	14.07.2022 11:42
#Acquired=	14.07.2022 11:42:50
#Edit:Spike=	14.07.2022 11:45:19
#Base:Fit=	10.08.2022 10:47:00
#Base:Sub=	10.08.2022 10:47:12
#Filter:Polynom=	16.08.2022 10:11:48
#AxisType[0]=Intens
#AxisUnit[0]=Cnt
#AxisType[1]=Spectr
#AxisUnit[1]=1/cm
200.554	29.9508
204.183	31.551
207.813	30.1985
211.439	28.8093
215.065	27.2947
218.688	27.3856
222.312	26.9903
225.933	25.7336
229.552	23.8458
233.171	19.7214
236.787	19.5318
240.402	18.0366
244.015	16.8305
247.627	14.812
251.24	13.2148
254.849	11.6164
258.457	11.5998
262.063	13.1153
265.668	11.3539
269.271	11.5766
272.873	12.1476
276.474	12.1128
280.073	11.9168
283.671	12.7424
287.268	12.1132
290.863	11.8574
294.456	13.8547
298.049	14.0538
301.637	15.9097
305.227	17.6884
308.815	18.5973
312.402	17.7817
315.987	18.8776
319.569	20.0026
323.151	21.9917
326.733	22.7339
330.31	22.8385
333.889	23.3923
337.464	23.3148
341.039	25.4526
344.611	24.4648
348.184	25.5349
351.754	25.792
355.324	26.2822
358.89	25.9271
362.455	24.8993
366.021	23.6015
369.584	20.715
373.145	20.3295
376.707	19.3201
380.265	19.9323
383.822	18.6565
387.378	15.2907
390.934	15.0599
394.487	13.843
398.038	11.5546
401.588	10.3724
405.137	10.0788
408.685	8.27523
412.23	8.56662
415.775	7.19337
419.318	5.24937
422.86	4.97064
426.401	4.98713
429.94	3.86461
433.478	2.52154
437.012	2.33848
440.547	3.24747
444.081	1.53186
447.613	0.639778
451.142	0.514255
454.672	1.6839
458.2	1.35802
461.725	2.29394
465.251	3.05875
468.775	2.56744
472.296	1.84581
475.817	5.94985
479.335	5.88325
482.854	6.72485
486.37	9.42895
489.886	10.6968
493.398	11.6916
496.91	14.5776
500.422	16.5194
503.93	16.599
507.438	17.3325
510.946	19.9764
514.45	18.9315
517.954	19.2737
521.456	19.3981
524.956	19.7401
528.456	19.6718
531.956	19.0869
535.452	19.6596
538.947	17.2689
542.441	15.9756
545.934	16.0412
549.425	14.3489
552.915	13.7553
556.403	15.5039
559.889	15.4219
563.375	15.0208
566.859	13.3949
570.342	12.4096
573.824	11.6368
577.303	10.5157
580.782	8.69239
584.26	8.25065
587.734	6.18053
591.21	5.44094
594.684	4.82067
598.154	6.56334
601.626	5.65067
605.094	5.59673
608.562	5.74795
612.027	6.25096
615.493	7.93897
618.956	8.66635
622.419	10.3525
625.879	12.5978
629.338	14.6586
632.797	16.5387
636.254	17.3862
639.708	19.2589
643.162	19.5638
646.614	18.5541
650.067	19.762
653.516	19.5597
656.964	19.1596
660.411	19.4935
663.857	17.7681
667.301	17.7164
670.744	18.5558
674.186	18.7145
677.626	20.4751
681.065	21.4131
684.503	23.1944
687.939	23.841
691.372	25.026
694.806	25.4546
698.239	27.8847
701.67	28.7858
705.098	31.5844
708.526	32.6565
711.954	34.6391
715.378	37.0941
718.802	37.4121
722.226	38.2666
725.646	36.838
729.067	37.6691
732.484	38.8683
735.902	39.7157
739.317	40.9777
742.731	42.6928
746.145	44.7144
749.556	46.9569
752.966	48.5114
756.377	52.6169
759.784	55.3843
763.19	58.7478
766.594	61.1628
770	64.55
773.402	67.454
776.803	70.1529
780.202	72.8865
783.6	74.5595
786.997	75.6928
790.393	76.347
793.787	77.2406
797.18	77.3337
800.572	76.0443
803.963	74.3856
807.35	71.9046
810.738	70.997
814.125	70.8918
817.51	70.6682
820.894	68.9772
824.275	69.4178
827.657	68.8186
831.037	69.0329
834.414	68.6381
837.792	69.4565
841.167	71.1744
844.542	71.3929
847.914	73.5061
851.287	74.2141
854.656	75.3141
858.026	72.6778
861.393	71.3215
864.761	68.2882
868.125	66.2278
871.489	64.1073
874.85	63.3075
878.213	61.17
881.572	58.4627
884.931	56.6605
888.287	53.693
891.643	52.1455
894.997	50.2419
898.352	49.9075
901.704	48.159
905.055	49.1583
908.404	49.701
911.75	50.6501
915.097	51.8283
918.443	51.6421
921.787	53.4066
925.13	53.6778
928.472	53.7629
931.813	53.3977
935.15	51.5415
938.488	48.0556
941.825	45.8081
945.158	45.2568
948.493	42.0669
951.824	40.8005
955.156	38.2484
958.486	35.6719
961.814	32.4921
965.142	32.2452
968.467	31.5888
971.79	30.015
975.115	29.1614
978.436	30.0549
981.756	29.7279
985.077	28.3804
988.394	28.1516
991.71	26.9821
995.025	26.8062
998.341	25.8327
1001.65	25.5971
1004.97	25.0802
1008.28	25.4753
1011.58	23.7061
1014.89	25.2309
1018.2	24.5654
1021.5	26.9767
1024.81	27.4434
1028.11	28.8808
1031.41	30.0419
1034.71	32.4887
1038.01	33.7708
1041.31	33.4791
1044.6	35.7292
1047.9	37.1618
1051.19	37.5553
1054.48	36.4193
1057.77	36.3632
1061.06	36.729
1064.35	31.6001
1067.64	28.4759
1070.93	26.4441
1074.21	23.9781
1077.49	21.0951
1080.78	18.4009
1084.06	15.9856
1087.34	13.1756
1090.61	11.3451
1093.89	10.0277
1097.17	10.7024
1100.44	11
1103.71	10.4945
1106.99	11.4662
1110.26	12.8846
1113.52	12.4704
1116.79	13.044
1120.06	13.0701
1123.32	13.5974
1126.59	15.6439
1129.85	17.2351
1133.11	16.6349
1136.37	19.4762
1139.63	21.4601
1142.89	20.8827
1146.15	20.4388
1149.4	20.1528
1152.66	18.4116
1155.91	17.8933
1159.16	15.951
1162.41	14.8972
1165.66	12.9685
1168.91	10.727
1172.16	8.68643
1175.4	7.89662
1178.65	6.39903
1181.89	5.64679
1185.13	5.2672
1188.37	5.11696
1191.61	5.5024
1194.85	5.26252
1198.08	6.14231
1201.32	7.14321
1204.55	6.87663
1207.79	6.62578
1211.02	9.24055
1214.25	11.6837
1217.48	14.7393
1220.71	16.8806
1223.93	18.7131
1227.16	18.459
1230.38	19.5993
1233.6	19.6006
1236.83	20.5921
1240.05	20.9678
1243.26	21.6679
1246.48	21.5483
1249.7	19.4554
1252.92	20.0677
1256.13	21.0158
1259.34	22.1328
1262.55	23.1182
1265.76	25.3851
1268.97	25.2372
1272.18	26.2153
1275.39	26.0925
1278.59	28.1812
1281.8	28.1117
1285	30.7693
1288.2	33.0746
1291.4	35.7243
1294.6	38.1658
1297.8	39.8262
1301	40.9977
1304.19	42.3357
1307.39	42.2303
1310.58	42.1866
1313.77	42.5391
1316.96	42.1353
1320.15	41.4966
1323.34	41.7981
1326.53	40.6352
1329.72	38.6859
1332.9	38.6713
1336.08	39.104
1339.27	37.6426
1342.45	37.4917
1345.63	36.3018
1348.8	35.0446
1351.98	34.8573
1355.16	33.5139
1358.33	34.1563
1361.51	34.064
1364.68	35.0636
1367.85	35.0535
1371.02	36.2128
1374.19	36.1944
1377.36	36.429
1380.52	38.1823
1383.69	39.1937
1386.85	37.951
1390.02	37.0078
1393.18	36.2219
1396.34	36.3309
1399.5	36.0169
1402.65	36.9265
1405.81	38.2425
1408.97	39.4798
1412.12	42.6376
1415.27	45.1118
1418.43	45.9792
1421.58	49.0821
1424.73	52.0465
1427.87	54.8038
1431.02	58.5976
1434.17	62.2053
1437.31	64.1803
1440.46	66.377
1443.6	67.7431
1446.74	68.5715
1449.88	69.2567
1453.02	68.6824
1456.16	67.0771
1459.29	64.0876
1462.43	59.3681
1465.56	55.9219
1468.69	52.4799
1471.83	49.3927
1474.95	45.1318
1478.08	42.5277
1481.21	41.3688
1484.34	38.0707
1487.47	34.3675
1490.59	32.5364
1493.71	29.1843
1496.84	27.4317
1499.96	26.6394
1503.07	26.0317
1506.19	25.6329
1509.31	23.7863
1512.43	22.4547
1515.54	21.0804
1518.65	19.2501
1521.77	18.6036
1524.88	18.1608
1527.99	19.2285
1531.1	17.502
1534.21	17.0762
1537.31	17.1325
1540.42	18.2373
1543.52	19.3559
1546.63	20.2874
1549.73	23.3295
1552.83	25.1227
1555.93	25.2553
1559.03	27.575
1562.12	27.099
1565.22	27.4946
1568.31	28.6997
1571.41	29.58
1574.5	29.9767
1577.59	32.1353
1580.68	33.5252
1583.77	34.0728
1586.86	36.5413
1589.95	39.5531
1593.03	41.4395
1596.11	41.9681
1599.2	42.0135
1602.28	43.1937
1605.36	42.4577
1608.44	42.1683
1611.52	42.4329
1614.6	41.7627
1617.67	41.6559
1620.75	42.3826
1623.82	42.0179
1626.89	42.7756
1629.96	40.9622
1633.04	40.7154
1636.11	39.6309
1639.17	38.1975
1642.24	39.49
1645.31	37.6833
1648.37	35.9231
1651.43	35.8041
1654.5	37.3204
1657.56	36.4226
1660.62	37.4021
1663.67	37.8898
1666.73	36.5124
1669.79	32.9241
1672.84	29.5575
1675.9	27.8701
1678.95	26.4415
1682	23.15
1685.05	21.8146
1688.1	20.6988
1691.15	18.2329
1694.2	17.3816
1697.25	15.6083
1700.29	14.156
1703.33	13.2663
1706.38	12.2316
1709.42	12.3245
1712.46	11.3856
1715.5	10.8473
1718.54	10.0527
1721.57	8.7259
1724.61	7.71437
1727.64	8.86877
1730.68	7.88753
1733.71	7.74274
1736.74	6.60538
1739.77	5.68845
1742.8	3.93922
1745.83	3.25119
1748.85	4.42618
1751.88	4.17263
1754.91	3.75665
1757.93	3.09319
1760.95	3.15856
1763.97	2.62708
1766.99	3.21955
1770.01	2.72322
1773.03	2.30843
1776.04	3.3423
1779.06	3.39731
1782.07	3.49078
1785.09	3.24497
1788.1	3.22869
1791.11	2.99802
1794.12	3.01625
1797.13	2.92465
1800.13	2.81961
1803.14	3.40335
1806.15	3.19767
1809.15	3.07883
1812.15	2.60501
1815.16	2.77825
1818.15	2.17866
1821.16	2.73103
1824.15	2.42354
1827.15	2.55458
1830.15	2.61813
1833.14	2.56708
1836.14	3.74517
1839.13	4.68601
1842.12	5.31171
1845.11	4.16372
1848.1	3.33891
1851.09	2.76607
1854.08	2.37303
1857.06	2.29579
1860.05	2.56657
1863.03	2.38561
1866.01	2.76649
1869	3.96179
1871.98	5.1917
1874.96	5.9783
1877.93	5.97447
1880.91	5.85918
1882.47	5.61982
1885.46	4.91246
1888.44	4.73759
1891.43	4.32551
1894.42	4.52056
1897.4	5.32298
1900.39	5.45132
1903.37	7.019
1906.35	7.87753
1909.33	7.07719
1912.31	6.36547
1915.29	4.19009
1918.26	3.87423
1921.24	3.93419
1924.21	3.82794
1927.19	3.23328
1930.16	3.47471
1933.13	4.0681
1936.1	5.26588
1939.07	5.85818
1942.04	6.68091
1945	4.72173
1947.97	5.50241
1950.93	5.88805
1953.9	4.10292
1956.86	2.90867
1959.82	2.8986
1962.78	2.35751
1965.74	2.94535
1968.7	3.52272
1971.65	4.06377
1974.61	4.31113
1977.57	4.89634
1980.52	5.47643
1983.47	4.65101
1986.42	5.18073
1989.37	4.97198
1992.32	5.06012
1995.27	4.27812
1998.22	3.61261
2001.17	4.42452
2004.11	5.35844
2007.05	7.01339
2010	7.25019
2012.94	7.38303
2015.88	6.94815
2018.82	7.54041
2021.76	8.47169
2024.7	8.20309
2027.63	7.02468
2030.57	8.07512
2033.5	8.04918
2036.44	8.00476
2039.37	8.28344
2042.3	8.27377
2045.23	8.20224
2048.16	7.68701
2051.08	7.88638
2054.01	8.13213
2056.94	8.08961
2059.86	8.24895
2062.79	8.30504
2065.71	8.60691
2068.63	9.10395
2071.55	9.94883
2074.47	11.1151
2077.39	11.7702
2080.31	12.1348
2083.22	12.8876
2086.13	13.572
2089.05	14.8654
2091.96	16.4042
2094.87	15.7676
2097.78	17.1879
2100.69	17.7122
2103.6	17.9791
2106.51	18.7945
2109.42	19.5235
2112.32	19.0611
2115.23	19.8145
2118.13	20.0273
2121.03	20.6007
2123.93	22.9518
2126.83	25.16
2129.73	26.811
2132.63	28.2362
2135.53	28.7001
2138.42	31.0167
2141.32	30.7867
2144.21	32.9735
2147.1	34.309
2150	35.3182
2152.89	36.9057
2155.78	37.1841
2158.66	38.1442
2161.55	40.5291
2164.44	40.6636
2167.32	41.6135
2170.21	40.6582
2173.09	39.253
2175.97	39.1091
2178.85	37.8474
2181.73	36.8378
2184.61	35.4402
2187.49	34.3769
2190.37	33.9749
2193.24	33.0062
2196.12	32.6742
2198.99	31.8697
2201.87	29.0883
2204.74	28.7628
2207.61	28.435
2210.48	28.1484
2213.35	27.4871
2216.21	26.645
2219.08	25.7722
2221.95	25.0449
2224.81	23.2866
2227.67	22.625
2230.54	22.2271
2233.4	20.0896
2236.26	17.8127
2239.11	15.9966
2241.97	14.2195
2244.83	12.8784
2247.69	12.2632
2250.54	11.3787
2253.4	10.4045
2256.25	9.62217
2259.1	9.21403
2261.95	8.87546
2264.8	8.09323
2267.65	8.34304
2270.5	8.59247
2273.34	9.01787
2276.19	9.23718
2279.03	9.71022
2281.88	10.0485
2284.72	10.979
2287.56	10.6875
2290.4	9.45497
2293.24	7.7518
2296.08	7.41121
2298.92	8.76597
2301.76	7.27528
2304.59	7.3909
2307.43	8.37213
2310.26	8.34935
2313.09	8.61921
2315.92	8.93778
2318.75	9.22158
2321.58	9.54329
2324.41	10.3022
2327.24	10.5115
2330.06	11.0009
2332.89	9.95589
2335.71	10.386
2338.54	9.84149
2341.36	8.6188
2344.18	6.71066
2347	7.06604
2349.82	6.51697
2352.64	7.25005
2355.45	6.62122
2358.27	5.48544
2361.08	4.21187
2363.9	3.91652
2366.71	3.63881
2369.52	3.99071
2372.33	3.36014
2375.14	3.60355
2377.95	3.92159
2380.76	3.97054
2383.57	4.87046
2386.37	5.19367
2389.18	5.44848
2391.98	6.55242
2394.79	5.77785
2397.59	5.55379
2400.39	4.75612
2403.19	4.90299
2405.99	4.5377
2408.78	3.95319
2411.58	4.487
2414.38	4.42018
2417.17	5.71877
2419.97	5.47969
2422.76	6.10156
2425.55	7.02686
2428.34	6.98768
2431.13	6.12702
2433.92	6.69265
2436.71	7.08189
2439.49	7.74503
2442.28	8.1054
2445.06	7.66713
2447.85	7.22188
2450.63	7.1933
2453.41	6.17774
2456.19	6.60578
2458.97	6.8129
2461.75	6.27673
2464.53	5.36538
2467.31	5.48984
2470.08	5.35401
2472.86	5.60377
2475.63	5.34577
2478.4	4.36259
2481.17	3.90264
2483.94	3.56713
2486.72	3.56767
2489.48	3.18612
2492.25	3.64403
2495.02	5.48225
2497.79	5.21897
2500.55	4.88239
2503.31	5.41382
2506.08	5.51651
2508.84	6.09922
2511.6	5.84528
2514.36	5.46604
2517.12	4.80756
2519.88	4.36607
2522.63	4.25799
2525.39	5.49716
2528.14	4.87201
2530.9	4.96525
2533.65	4.30754
2536.4	4.99438
2539.15	4.61501
2541.9	3.76584
2544.65	2.72224
2547.4	1.86271
2550.15	1.59014
2552.89	2.32025
2555.64	1.84289
2558.38	2.74304
2561.12	2.86185
2563.87	3.33086
2566.61	2.63453
2569.35	3.1203
2572.09	4.64239
2574.83	5.36938
2577.56	6.29771
2580.3	6.49271
2583.04	5.25594
2585.77	6.0427
2588.5	5.80846
2591.23	6.28857
2593.97	6.91061
2596.7	5.77248
2599.43	5.84557
2602.15	4.69044
2604.88	5.2824
2607.61	3.50217
2610.33	4.25399
2613.06	4.22884
2615.78	3.85329
2618.51	3.75229
2621.23	4.02158
2623.95	3.407
2626.67	3.60003
2629.39	4.10497
2632.1	4.15809
2634.82	5.66043
2637.54	7.98021
2640.25	9.36894
2642.97	10.5673
2645.68	9.9789
2648.39	9.55259
2651.1	10.5674
2653.81	10.123
2656.52	10.9145
2659.23	11.2228
2661.94	10.0477
2664.64	10.0219
2667.35	10.5935
2670.05	10.6002
2672.76	10.6699
2675.46	11.8373
2678.16	11.9404
2680.86	10.4454
2683.56	10.309
2686.26	10.6049
2688.96	10.3281
2691.65	10.7744
2694.35	11.3143
2697.04	11.6274
2699.74	11.9196
2702.43	13.1871
2705.12	13.7078
2707.81	14.3201
2710.5	13.9066
2713.19	14.8365
2715.88	16.2504
2718.57	15.8951
2721.25	15.3481
2723.94	14.698
2726.62	14.1463
2729.3	13.4042
2731.99	12.4249
2734.67	12.8026
2737.35	12.3547
2740.03	11.8302
2742.71	11.2405
2745.38	10.4781
2748.06	10.5243
2750.74	10.8409
2753.41	10.6987
2756.09	9.41056
2758.76	8.70856
2761.43	7.48117
2764.1	6.3792
2766.77	5.98962
2769.44	6.75755
2772.11	7.56449
2774.77	6.79007
2777.44	5.95517
2780.11	6.02408
2782.77	5.24726
2785.43	4.31803
2788.1	2.7332
2790.76	2.08315
2793.42	1.38134
2796.08	1.69577
2798.74	2.3948
2801.4	2.90117
2804.05	3.82519
2806.71	4.59908
2809.36	5.1846
2812.02	6.11607
2814.67	6.89804
2817.32	8.66537
2819.97	11.6645
2822.62	14.7111
2825.27	18.5018
2827.92	21.7963
2830.57	25.9652
2833.22	30.3113
2835.86	35.4817
2838.51	38.9103
2841.15	44.0556
2843.79	50.038
2846.43	56.5871
2849.08	62.3463
2851.72	68.8181
2854.36	75.7446
2856.99	81.3883
2859.63	86.8845
2862.27	92.9988
2864.9	97.0548
2867.54	102.147
2870.17	105.165
2872.8	109.207
2875.43	112.125
2878.07	115.33
2880.7	118.588
2883.32	121.934
2885.95	126.802
2888.58	129.075
2891.21	132.391
2893.83	135.477
2896.46	138.876
2899.08	143.046
2901.7	147.066
2904.32	152.225
2906.94	156.81
2909.56	162.739
2912.18	169.132
2914.8	174.88
2917.42	179.587
2920.03	183.174
2922.65	186.301
2925.26	189.175
2927.88	189.175
2930.49	188.302
2933.1	186.818
2935.71	184.118
2938.32	179.593
2940.93	173.738
2943.54	167.518
2946.14	160.523
2948.75	153.524
2951.35	146.088
2953.96	138.307
2956.56	130.759
2959.16	121.966
2961.77	113.924
2964.37	107.489
2966.96	101.706
2969.56	95.421
2972.16	89.2031
2974.76	85.265
2977.35	79.8841
2979.95	75.429
2982.54	69.8768
2985.14	66.34
2987.73	61.8813
2990.32	55.8894
2992.91	50.2404
2995.5	46.3021
2998.09	41.8956
3000.68	37.363
3003.26	32.6341
3005.85	29.4085
3008.43	25.8263
3011.02	21.5544
3013.6	18.5634
3016.19	15.4419
3018.77	12.701
3021.35	10.8042
3023.93	8.49795
3026.5	6.94749
3029.08	6.64042
3031.66	4.73184
3034.24	4.12138
3036.81	4.40085
3039.39	5.18387
3041.96	5.04807
3044.53	5.01236
3047.1	5.33638
3049.67	5.78996
3052.24	5.38392
3054.81	5.40849
3057.38	6.56683
3059.95	5.9589
3062.52	5.673
3065.08	5.35356
3067.65	5.64101
3070.21	5.45774
3072.77	3.88756
3075.33	3.51563
3077.89	3.79644
3080.45	2.81762
3083.01	1.8588
3085.57	0.702277
3088.13	0.332411
3090.68	0.872386
3093.24	0.946743
3095.79	1.48469
3098.35	0.440112
3100.9	1.0046
3103.45	1.15524
3106	0.658045
3108.55	-0.215232
3111.1	1.05242
3113.65	1.24062
3116.2	1.48444
3118.75	2.37496
3121.29	1.96462
3123.84	2.68016
3126.38	3.77852
3128.92	3.71076
3131.47	4.72528
3134.01	5.46549
3136.55	7.07459
3139.09	8.17004
3141.63	9.34046
3144.17	11.2276
3146.7	13.6037
3149.24	14.8696