File: data/Raman/poly_smoothed/Mb_40_y_43_1x_45s_532 nm_x100_100%_600 gr_mm_01.txt
#Acq. time (s)=	45
#Accumulations=	2
#Range (cm-¹)=	200...3150
#Windows=	2
#Auto scanning=	Off
#Autofocus=	Off
#Macrospot=	Off
#AutoExposure=	Off
#Spike filter=	Multiple accum.
#Delay time (s)=	0
#Binning=	1
#Readout mode=	Signal
#DeNoise=	Off
#ICS correction=	On
#Dark correction=	Off
#Inst. Process=	Off
#Detector Gain=	Best Dynamic Range
#Detector ADC=	20 kHz
#Detector temperature (°C)=	-69.85
#Instrument=	LabRAM HR Evol
#Detector=	Synapse
#Objective=	x100
#Grating=	600 gr/mm
#ND Filter=	100%
#Laser (nm)=	532
#Hole=	100.021
#Range=	Auto
#Laser Pol.=	No
#Raman. Pol.=	No
#Laser Pol. (°)=	-0.0007625
#Raman Pol. (°)=	89.9995
#Collection=	Microscope
#StageXY=	Marzhauser
#StageZ=	Marzhauser
#X (µm)=	-1072.1
#Y (µm)=	611.1
#Z (µm)=	584.45
#Full time(mm:ss)=	3:18
#Project=
#Sample=
#Site=
#Title=	Mb_40_y_43_2x_45s_532 nm_x100_100%_600 gr_mm
#Remark=
#Date=	19.07.2022 12:59
#Acquired=	19.07.2022 12:59:19
#Base:Fit=	10.08.2022 10:52:48
#Base:Sub=	10.08.2022 10:52:53
#Filter:Polynom=	16.08.2022 10:09:04
#AxisType[0]=Intens
#AxisUnit[0]=Cnt
#AxisType[1]=Spectr
#AxisUnit[1]=1/cm
200.423	51.9292
204.052	42.5598
207.682	37.8612
211.308	32.0941
214.935	27.9235
218.558	23.0459
222.18	19.813
225.802	15.0675
229.421	12.643
233.039	10.766
236.657	6.97312
240.272	6.21331
243.885	5.43045
247.497	5.34969
251.11	5.32903
254.719	5.71053
258.327	5.51685
261.933	3.82648
265.538	3.61465
269.141	1.66495
272.744	3.93606
276.344	4.82075
279.944	5.09798
283.542	5.15041
287.138	6.42573
290.733	7.3706
294.327	6.21299
297.919	6.87047
301.508	9.08749
305.098	9.65614
308.686	8.88092
312.273	8.58472
315.858	10.1805
319.44	10.6157
323.022	11.113
326.604	13.5405
330.181	16.1609
333.76	17.3942
337.335	17.2007
340.91	18.2099
344.483	16.9083
348.055	15.4802
351.625	14.2769
355.195	13.7033
358.762	13.6515
362.329	12.665
365.893	9.96211
369.455	7.65121
373.017	6.08205
376.578	6.16765
380.137	5.52477
383.694	4.89162
387.249	6.58824
390.806	4.35745
394.359	3.68013
397.91	4.68991
401.46	5.60369
405.009	8.86507
408.557	9.76402
412.103	12.3438
415.647	13.246
419.191	13.1318
422.733	13.71
426.273	12.7741
429.812	12.3412
433.35	10.0865
436.885	10.6936
440.42	7.94836
443.954	7.90342
447.486	8.12791
451.015	5.50738
454.545	6.69062
458.073	6.89866
461.598	9.02248
465.124	10.3007
468.648	11.581
472.169	14.3324
475.69	16.4125
479.208	17.323
482.727	20.3315
486.243	22.7042
489.759	25.3435
493.272	26.4701
496.783	26.4183
500.295	27.1165
503.804	27.669
507.311	28.2671
510.819	29.0363
514.324	27.506
517.827	25.5341
521.329	24.2142
524.83	24.2829
528.329	23.7704
531.829	24.3635
535.326	22.5101
538.821	21.1774
542.315	20.7652
545.808	21.2462
549.299	22.8505
552.789	22.6212
556.278	25.2449
559.763	25.7911
563.249	24.626
566.733	22.4644
570.217	20.0386
573.699	20.3638
577.177	20.4201
580.656	18.6601
584.134	16.9692
587.609	15.4023
591.084	12.6846
594.558	10.8334
598.029	9.74339
601.5	10.5757
604.968	9.91841
608.437	9.0721
611.902	9.5815
615.368	9.45482
618.831	7.87152
622.294	8.12847
625.755	9.00742
629.213	9.99878
632.673	12.5261
636.129	14.0551
639.584	15.2175
643.037	16.0324
646.491	14.2978
649.942	15.0431
653.392	15.8617
656.84	15.5591
660.287	16.7838
663.732	17.3138
667.177	16.4764
670.62	18.2295
674.061	18.5839
677.502	23.1158
680.941	26.7179
684.379	30.4777
687.815	33.5174
691.248	35.4526
694.682	37.936
698.115	40.7064
701.546	43.4156
704.974	46.1468
708.402	50.6078
711.83	53.0122
715.254	52.9242
718.679	52.9257
722.102	53.0969
725.522	53.2563
728.943	51.8283
732.361	50.2085
735.779	49.3791
739.194	47.8543
742.608	50.2891
746.022	51.6283
749.433	52.7276
752.843	52.8089
756.254	56.3888
759.661	57.6461
763.067	59.7756
766.471	62.5908
769.877	65.1605
773.279	66.7503
776.68	68.0546
780.079	71.4082
783.478	72.6492
786.875	74.5308
790.27	76.9173
793.665	78.3218
797.058	77.9716
800.45	78.7038
803.84	79.2243
807.23	78.5327
810.616	75.9269
814.002	72.9497
817.388	72.3219
820.772	71.3757
824.153	70.9047
827.535	69.5982
830.915	66.1275
834.292	62.3128
837.67	61.6604
841.047	59.6683
844.42	56.4209
847.794	55.2587
851.165	53.702
854.534	50.9943
857.905	48.5946
861.272	48.1502
864.639	46.2445
868.004	44.6273
871.367	46.1488
874.731	48.4432
878.092	48.9905
881.451	49.68
884.809	47.5429
888.166	46.0317
891.522	44.7461
894.878	44.4297
898.231	40.4094
901.583	40.7869
904.934	40.0362
908.283	40.1217
911.631	38.2146
914.976	35.7089
918.322	36.6162
921.666	37.058
925.009	35.9273
928.351	35.0439
931.692	35.6629
935.029	34.1219
938.367	33.5995
941.704	33.5321
945.038	33.9204
948.372	34.5677
951.705	34.4834
955.035	36.4555
958.366	34.6828
961.693	33.5108
965.021	33.2501
968.346	30.0479
971.67	29.7121
974.995	29.8019
978.316	28.0991
981.638	28.6308
984.957	28.2835
988.274	27.2182
991.59	24.0991
994.907	21.2066
998.221	18.027
1001.53	13.0897
1004.85	11.3221
1008.16	16.1149
1011.46	33.4764
1014.77	54.9045
1018.08	79.0047
1021.38	104.919
1024.69	130.803
1027.99	152.942
1031.29	173.437
1034.59	188.814
1037.89	201.566
1041.19	209.906
1044.48	213.588
1047.78	212.472
1051.07	209.303
1054.36	201.971
1057.66	189.309
1060.94	174.21
1064.23	156.276
1067.52	132.375
1070.81	108.397
1074.09	80.5853
1077.38	55.7713
1080.66	32.8822
1083.94	16.7413
1087.22	9.69262
1090.5	10.6272
1093.77	15.2694
1097.05	18.6199
1100.32	22.4268
1103.6	26.8323
1106.87	27.9311
1110.14	29.0584
1113.41	27.2702
1116.67	25.6577
1119.94	25.8028
1123.21	23.6346
1126.47	22.8752
1129.73	24.1361
1133	20.8471
1136.26	18.8205
1139.52	18.3913
1142.77	17.4436
1146.03	17.6595
1149.29	14.4493
1152.54	13.1231
1155.79	11.994
1159.04	9.74392
1162.3	6.95345
1165.55	3.90377
1168.79	4.29509
1172.04	4.76823
1175.28	5.25213
1178.53	5.81096
1181.77	4.28771
1185.01	1.96184
1188.25	0.423144
1191.49	-1.25272
1194.73	-1.19442
1197.97	0.108225
1201.2	2.65264
1204.44	3.49667
1207.67	5.22683
1210.9	7.50494
1214.13	10.097
1217.36	14.1995
1220.59	16.712
1223.82	18.7284
1227.04	21.7355
1230.26	24.2171
1233.49	27.0342
1236.71	29.9753
1239.93	32.4164
1243.15	34.3423
1246.37	35.6943
1249.58	36.5966
1252.8	36.9117
1256.01	38.807
1259.23	41.2254
1262.44	42.4578
1265.65	46.4192
1268.86	50.6004
1272.07	53.7882
1275.27	58.9523
1278.48	63.0293
1281.68	67.9503
1284.89	70.2278
1288.09	72.3288
1291.29	74.1779
1294.49	75.4448
1297.69	77.2972
1300.88	78.0569
1304.08	78.2164
1307.27	78.9536
1310.47	76.5002
1313.66	74.3925
1316.85	74.1171
1320.04	73.0612
1323.23	69.6654
1326.41	67.8697
1329.6	66.4692
1332.78	67.6865
1335.97	68.8613
1339.15	68.873
1342.33	69.5099
1345.51	70.2163
1348.69	69.3814
1351.87	68.3759
1355.04	66.2475
1358.22	64.0382
1361.39	60.2429
1364.57	57.3987
1367.74	54.9178
1370.91	51.2721
1374.07	49.0281
1377.24	47.5365
1380.41	45.3388
1383.57	43.5782
1386.74	43.1042
1389.9	43.2714
1393.06	44.2661
1396.22	46.5102
1399.38	48.4934
1402.54	52.6333
1405.7	59.1246
1408.85	66.3254
1412.01	72.9283
1415.16	80.6823
1418.31	89.7662
1421.46	95.5593
1424.61	104.843
1427.76	111.327
1430.91	118.323
1434.05	126.806
1437.2	131.402
1440.34	135.158
1443.49	138.684
1446.63	138.875
1449.77	138.984
1452.91	138.533
1456.04	135.736
1459.18	131.235
1462.31	125.8
1465.45	121.203
1468.58	113.565
1471.71	103.768
1474.84	97.8193
1477.97	91.3655
1481.1	83.3833
1484.23	76.0338
1487.35	67.2192
1490.48	59.1734
1493.6	52.5891
1496.72	45.9284
1499.84	42.3893
1502.96	40.3671
1506.08	37.0499
1509.2	34.1674
1512.31	30.8994
1515.43	27.9211
1518.54	26.3016
1521.66	24.7414
1524.77	25.5474
1527.88	25.4395
1530.99	26.9951
1534.09	28.2926
1537.2	30.2648
1540.31	31.1324
1543.41	33.4143
1546.51	34.394
1549.62	36.4029
1552.72	37.7216
1555.82	38.9631
1558.91	37.4193
1562.01	39.0151
1565.11	39.4506
1568.2	41.764
1571.3	43.1562
1574.39	45.5369
1577.48	48.7536
1580.57	50.4716
1583.66	51.1536
1586.75	51.4001
1589.83	51.5681
1592.92	53.2442
1596	54.6189
1599.09	56.5935
1602.17	57.4054
1605.25	57.4894
1608.33	57.309
1611.41	56.25
1614.48	55.1976
1617.56	54.7507
1620.64	53.4207
1623.71	52.8988
1626.78	54.3364
1629.86	53.6468
1632.92	53.7378
1635.99	54.3339
1639.06	55.5947
1642.13	56.9782
1645.19	57.458
1648.26	58.7081
1651.32	60.1156
1654.38	58.7908
1657.45	57.5987
1660.51	55.6771
1663.57	54.5602
1666.62	51.4905
1669.68	50.6326
1672.73	49.1205
1675.79	45.9239
1678.84	41.1093
1681.89	37.5512
1684.94	32.8559
1687.99	30.7795
1691.04	27.6744
1694.09	26.7369
1697.14	23.8543
1700.18	22.4326
1703.22	22.6511
1706.27	19.6777
1709.31	19.3243
1712.35	18.1118
1715.39	16.9807
1718.43	15.5023
1721.46	14.1997
1724.5	12.95
1727.53	11.151
1730.57	10.1818
1733.6	8.79839
1736.63	8.8714
1739.66	9.16178
1742.69	9.22739
1745.72	8.52028
1748.74	7.98681
1751.77	6.94067
1754.8	6.92166
1757.82	6.76528
1760.84	7.34267
1763.86	6.63711
1766.88	6.26395
1769.9	5.30491
1772.92	5.17288
1775.93	5.46631
1778.95	5.66594
1781.96	4.73017
1784.98	4.45621
1787.99	4.71886
1791	4.85031
1794.01	3.55108
1797.02	4.65632
1800.03	4.70176
1803.03	5.12775
1806.04	4.94986
1809.04	5.50658
1812.04	5.88474
1815.05	6.3345
1818.05	6.72655
1821.05	6.77138
1824.05	7.50018
1827.04	8.002
1830.04	7.8808
1833.03	8.06456
1836.03	6.30248
1839.02	5.06696
1842.01	3.43191
1845	2.95288
1847.99	2.96404
1850.98	3.3638
1853.97	2.29116
1856.95	1.93027
1859.94	1.83949
1862.92	2.29467
1865.91	1.46004
1868.89	1.42682
1871.87	1.29314
1874.85	1.7479
1877.83	2.21189
1880.8	1.63782
1882.56	1.83517
1885.54	1.33048
1888.53	2.05529
1891.52	2.69467
1894.5	2.72952
1897.49	3.35657
1900.47	3.03673
1903.45	3.18109
1906.43	3.33616
1909.41	3.24587
1912.39	5.13954
1915.37	5.87101
1918.35	5.98471
1921.32	6.50092
1924.3	6.55361
1927.27	5.98257
1930.24	5.29638
1933.21	5.45934
1936.18	5.70317
1939.15	6.44954
1942.12	6.88954
1945.09	7.0646
1948.05	8.2806
1951.02	7.56538
1953.98	7.23559
1956.94	6.56206
1959.91	6.84534
1962.87	6.33668
1965.82	7.44707
1968.78	7.3538
1971.74	7.51784
1974.7	7.36532
1977.65	8.24024
1980.6	7.16012
1983.56	6.67007
1986.51	6.62639
1989.46	6.37279
1992.41	5.10687
1995.36	5.20038
1998.3	4.0005
2001.25	4.15514
2004.2	4.29364
2007.14	5.23754
2010.08	6.33811
2013.02	6.49789
2015.97	6.62417
2018.9	7.49403
2021.84	9.01179
2024.78	8.99184
2027.72	10.8493
2030.65	12.6191
2033.59	13.3032
2036.52	13.3379
2039.45	14.5827
2042.38	15.2939
2045.31	15.1382
2048.24	15.068
2051.17	14.5924
2054.1	14.7006
2057.02	15.6997
2059.95	17.4871
2062.87	18.2914
2065.79	18.3026
2068.71	19.4663
2071.63	19.5878
2074.55	20.5722
2077.47	20.4663
2080.39	21.2549
2083.3	21.222
2086.22	21.2361
2089.13	22.5921
2092.05	23.3771
2094.96	25.3937
2097.87	27.0366
2100.78	27.7294
2103.69	27.9591
2106.59	29.3089
2109.5	30.8558
2112.41	31.555
2115.31	34.0756
2118.21	35.3713
2121.12	38.0141
2124.02	40.7728
2126.92	44.2664
2129.82	47.5208
2132.71	51.797
2135.61	54.605
2138.51	58.3618
2141.4	62.1928
2144.29	64.5672
2147.19	67.7535
2150.08	70.551
2152.97	72.8689
2155.86	75.6005
2158.75	78.2206
2161.64	80.7263
2164.52	82.0508
2167.41	83.3929
2170.29	83.2218
2173.17	85.1011
2176.06	84.383
2178.94	82.613
2181.82	81.3889
2184.7	80.3909
2187.57	79.9837
2190.45	78.9578
2193.33	76.6994
2196.2	74.931
2199.08	72.1996
2201.95	68.6916
2204.82	66.9846
2207.69	64.6611
2210.56	60.7971
2213.43	58.5506
2216.3	54.8231
2219.16	52.3879
2222.03	49.0274
2224.89	46.2601
2227.75	44.5069
2230.62	43.6308
2233.48	41.2916
2236.34	38.2527
2239.2	35.4359
2242.06	33.649
2244.91	31.4129
2247.77	28.8069
2250.62	27.7545
2253.48	27.3964
2256.33	27.0335
2259.18	25.859
2262.03	25.5694
2264.88	23.4221
2267.73	21.9217
2270.58	20.5316
2273.43	19.8198
2276.27	18.3038
2279.12	16.5534
2281.96	15.7785
2284.8	15.2315
2287.64	14.0023
2290.49	11.9758
2293.32	11.5256
2296.16	11.4727
2299	12.016
2301.84	10.4765
2304.67	10.0568
2307.51	9.97612
2310.34	10.5909
2313.17	9.74401
2316	11.022
2318.83	12.0248
2321.66	12.6362
2324.49	13.5909
2327.32	14.0334
2330.15	13.8536
2332.97	14.1946
2335.79	14.1466
2338.62	13.1623
2341.44	12.5682
2344.26	11.5949
2347.08	10.8965
2349.9	9.44956
2352.72	8.82619
2355.53	8.25501
2358.35	6.5968
2361.17	7.17839
2363.98	8.12873
2366.79	8.73633
2369.6	8.88724
2372.42	7.83409
2375.22	8.16247
2378.03	7.08561
2380.84	6.91083
2383.65	7.44599
2386.45	7.20807
2389.26	8.07212
2392.06	7.55017
2394.87	7.71941
2397.67	7.01533
2400.47	7.11574
2403.27	7.48957
2406.07	6.28257
2408.86	5.93333
2411.66	5.66926
2414.46	5.49545
2417.25	5.77597
2420.05	6.07589
2422.84	7.33706
2425.63	7.10173
2428.42	7.30915
2431.21	6.79889
2434	6.85234
2436.79	6.3841
2439.57	5.62599
2442.36	5.56971
2445.14	4.88195
2447.93	4.61047
2450.71	4.72861
2453.49	4.92649
2456.27	5.06502
2459.05	5.83128
2461.83	5.51506
2464.61	4.79519
2467.39	4.65863
2470.16	4.03716
2472.94	3.32452
2475.71	4.16948
2478.48	3.671
2481.25	3.42113
2484.02	3.0788
2486.8	3.69431
2489.56	3.89577
2492.33	2.80172
2495.1	2.27445
2497.86	2.64966
2500.63	3.69251
2503.39	3.78762
2506.16	3.49111
2508.92	3.57357
2511.68	4.26899
2514.44	4.16801
2517.2	4.13527
2519.95	4.08601
2522.71	5.71772
2525.47	5.43175
2528.22	5.57404
2530.98	4.67737
2533.73	4.12016
2536.48	3.77222
2539.23	3.34626
2541.98	4.63435
2544.73	4.6531
2547.48	4.6931
2550.23	4.97632
2552.97	5.13484
2555.72	5.11374
2558.46	4.12763
2561.2	4.85541
2563.95	4.59748
2566.69	4.8041
2569.43	4.37597
2572.17	3.8088
2574.91	2.68489
2577.64	2.48693
2580.38	2.64979
2583.11	3.51325
2585.85	4.45219
2588.58	5.77276
2591.31	6.4246
2594.04	6.98355
2596.78	7.4086
2599.51	6.98982
2602.23	7.81579
2604.96	7.87292
2607.69	9.21583
2610.41	10.1983
2613.14	8.54188
2615.86	7.88818
2618.58	7.65984
2621.3	6.93045
2624.03	4.0626
2626.75	4.14488
2629.46	3.64147
2632.18	3.41246
2634.9	3.49774
2637.61	2.87894
2640.33	3.17374
2643.04	3.99005
2645.76	4.96614
2648.47	7.11396
2651.18	7.60808
2653.89	8.81569
2656.6	9.36768
2659.31	9.76945
2662.01	9.13283
2664.72	9.1659
2667.43	9.38998
2670.13	9.39616
2672.83	9.17957
2675.53	9.18015
2678.24	8.06785
2680.94	7.83562
2683.64	8.8799
2686.34	9.04335
2689.03	8.49052
2691.73	8.83402
2694.43	9.75963
2697.12	10.9555
2699.81	11.917
2702.51	12.7529
2705.2	14.2889
2707.89	16.1851
2710.58	17.9053
2713.27	19.9402
2715.96	19.9186
2718.64	20.2171
2721.33	20.5803
2724.01	20.1438
2726.7	19.9692
2729.38	19.9334
2732.06	18.3462
2734.75	16.8397
2737.43	15.3461
2740.11	13.3357
2742.78	10.9175
2745.46	9.20564
2748.14	8.71452
2750.81	7.37101
2753.49	5.10854
2756.16	3.80643
2758.84	2.39523
2761.51	1.71929
2764.18	1.21681
2766.85	0.879066
2769.52	1.3933
2772.19	2.74633
2774.85	2.5008
2777.52	2.34691
2780.18	1.65778
2782.85	1.0919
2785.51	1.21424
2788.17	2.3372
2790.84	2.63553
2793.5	2.64012
2796.16	2.81956
2798.81	2.17795
2801.47	1.81156
2804.13	-0.135417
2806.79	-1.89501
2809.44	-3.64963
2812.09	-2.19343
2814.75	1.24744
2817.4	6.18227
2820.05	14.529
2822.7	24.9333
2825.35	36.1546
2828	49.198
2830.65	62.6833
2833.29	77.47
2835.94	90.5734
2838.58	103.658
2841.23	115.81
2843.87	125.704
2846.51	134.829
2849.15	147.172
2851.79	161.566
2854.43	177.019
2857.07	191.623
2859.71	205.172
2862.34	215.448
2864.98	223.055
2867.61	227.677
2870.25	230.912
2872.88	233.448
2875.51	236.341
2878.14	240.82
2880.77	243.995
2883.4	244.662
2886.03	245.267
2888.65	244.447
2891.28	241.349
2893.91	238.763
2896.53	234.64
2899.15	230.66
2901.78	225.54
2904.4	221.039
2907.02	217.75
2909.64	217.783
2912.26	222.158
2914.87	230.21
2917.49	237.856
2920.11	244.731
2922.72	249.241
2925.34	252.407
2927.95	253.124
2930.56	253.851
2933.17	253.095
2935.78	250.829
2938.39	247.103
2941	241.478
2943.61	233.806
2946.22	223.121
2948.82	212.106
2951.43	200.975
2954.03	188.955
2956.64	176.564
2959.24	164.704
2961.84	153.703
2964.44	143.1
2967.04	133.42
2969.64	122.935
2972.24	115.388
2974.83	106.868
2977.43	98.2877
2980.02	90.761
2982.62	83.3673
2985.21	75.0835
2987.8	67.3414
2990.4	58.9506
2992.99	52.9524
2995.57	47.4684
2998.16	41.5084
3000.75	34.4978
3003.34	29.147
3005.92	23.6355
3008.51	18.8056
3011.09	14.86
3013.68	11.8619
3016.26	9.12643
3018.84	6.30968
3021.42	3.6697
3024	1.63685
3026.58	0.694802
3029.16	-0.21988
3031.73	-0.63039
3034.31	-0.0296293
3036.89	-0.046746
3039.46	0.771454
3042.03	0.808432
3044.61	1.1971
3047.18	2.15743
3049.75	2.80288
3052.32	3.80916
3054.89	5.26059
3057.45	6.12464
3060.02	6.74736
3062.59	7.56083
3065.15	7.09255
3067.72	7.49084
3070.28	7.30745
3072.84	7.07575
3075.41	6.87712
3077.97	6.69358
3080.53	5.80742
3083.09	4.34204
3085.64	3.62687
3088.2	3.58606
3090.76	3.06205
3093.31	4.07063
3095.87	3.55793
3098.42	4.92181
3100.97	5.5083
3103.53	6.58886
3106.08	8.01105
3108.63	10.29
3111.18	12.2386
3113.73	14.0237
3116.27	16.4496
3118.82	18.4191
3121.37	20.929
3123.91	23.1129
3126.45	24.9043
3129	26.5108
3131.54	29.5176
3134.08	32.3568
3136.62	34.6545
3139.16	36.7408
3141.7	38.992
3144.24	40.7048
3146.78	42.435
3149.31	44.6901