File: data/Raman/poly_smoothed/Mb_40_24_44_1x_45s_532 nm_x100_100%_600 gr_mm_01.txt
#Acq. time (s)=	45
#Accumulations=	2
#Range (cm-¹)=	200...3150
#Windows=	2
#Auto scanning=	Off
#Autofocus=	Off
#Macrospot=	Off
#AutoExposure=	Off
#Spike filter=	Multiple accum.
#Delay time (s)=	0
#Binning=	1
#Readout mode=	Signal
#DeNoise=	Off
#ICS correction=	On
#Dark correction=	Off
#Inst. Process=	Off
#Detector Gain=	Best Dynamic Range
#Detector ADC=	20 kHz
#Detector temperature (°C)=	-70.08
#Instrument=	LabRAM HR Evol
#Detector=	Synapse
#Objective=	x100
#Grating=	600 gr/mm
#ND Filter=	100%
#Laser (nm)=	532
#Hole=	100.021
#Range=	Auto
#Laser Pol.=	No
#Raman. Pol.=	No
#Laser Pol. (°)=	-0.0007625
#Raman Pol. (°)=	89.9995
#Collection=	Microscope
#StageXY=	Marzhauser
#StageZ=	Marzhauser
#X (µm)=	-2469.5
#Y (µm)=	-41.1
#Z (µm)=	-10.1
#Full time(mm:ss)=	3:19
#Project=
#Sample=
#Site=
#Title=	Mb_40_24_44_2x_45s_532 nm_x100_100%_600 gr_mm
#Remark=
#Date=	14.07.2022 14:07
#Acquired=	14.07.2022 14:07:58
#Base:Fit=	10.08.2022 10:47:00
#Base:Sub=	10.08.2022 10:47:12
#Filter:Polynom=	16.08.2022 10:11:48
#AxisType[0]=Intens
#AxisUnit[0]=Cnt
#AxisType[1]=Spectr
#AxisUnit[1]=1/cm
200.554	17.9409
204.183	18.6731
207.813	18.5945
211.439	16.3213
215.065	13.1299
218.688	9.9069
222.312	7.49965
225.933	8.0911
229.552	8.55243
233.171	8.59907
236.787	8.21902
240.402	6.53587
244.015	6.36468
247.627	6.66172
251.24	7.49672
254.849	8.96747
258.457	9.71393
262.063	11.0978
265.668	12.7482
269.271	14.2859
272.873	15.8165
276.474	15.0154
280.073	15.4495
283.671	15.1598
287.268	15.0368
290.863	13.8656
294.456	12.7229
298.049	10.5853
301.637	11.1883
305.227	11.1996
308.815	12.1025
312.402	14.548
315.987	13.4226
319.569	13.1537
323.151	13.2795
326.733	13.0634
330.31	12.7965
333.889	13.2579
337.464	14.1941
341.039	14.4766
344.611	13.9811
348.184	14.0524
351.754	14.2325
355.324	12.4962
358.89	11.8308
362.455	8.79099
366.021	7.9873
369.584	6.37611
373.145	5.29646
376.707	4.47657
380.265	4.00834
383.822	5.59397
387.378	5.05752
390.934	5.54526
394.487	5.19269
398.038	5.51997
401.588	4.93663
405.137	4.7291
408.685	5.71161
412.23	6.29214
415.775	5.94071
419.318	5.71738
422.86	5.80176
426.401	5.58593
429.94	4.33481
433.478	4.79365
437.012	4.90237
440.547	4.2028
444.081	3.00495
447.613	2.222
451.142	1.59779
454.672	1.41625
458.2	2.61331
461.725	4.33034
465.251	5.06732
468.775	7.15452
472.296	7.97156
475.817	8.3258
479.335	9.3326
482.854	10.7419
486.37	12.7598
489.886	14.354
493.398	15.0368
496.91	16.0035
500.422	18.4683
503.93	20.8329
507.438	22.1068
510.946	23.7922
514.45	24.3819
517.954	25.7478
521.456	27.4527
524.956	28.0495
528.456	27.5644
531.956	27.2978
535.452	27.3341
538.947	26.1151
542.441	25.3695
545.934	26.2538
549.425	26.1555
552.915	24.835
556.403	22.4893
559.889	20.1035
563.375	17.586
566.859	16.2236
570.342	14.5827
573.824	12.0907
577.303	10.584
580.782	10.1632
584.26	8.74572
587.734	7.3289
591.21	6.00304
594.684	3.6163
598.154	3.93953
601.626	2.69577
605.094	4.39053
608.562	6.32092
612.027	6.52439
615.493	6.79132
618.956	6.5558
622.419	8.22709
625.879	9.18851
629.338	11.7504
632.797	12.8959
636.254	12.5156
639.708	14.3146
643.162	15.6835
646.614	15.6305
650.067	16.9115
653.516	18.91
656.964	19.2704
660.411	19.3129
663.857	18.7255
667.301	18.1112
670.744	16.5787
674.186	15.0769
677.626	14.7057
681.065	13.9401
684.503	14.2689
687.939	14.9307
691.372	16.7892
694.806	16.5418
698.239	17.2279
701.67	17.8634
705.098	19.3615
708.526	22.5191
711.954	24.6008
715.378	27.1604
718.802	28.015
722.226	28.5255
725.646	30.881
729.067	31.7104
732.484	32.5277
735.902	33.2175
739.317	34.7314
742.731	35.9143
746.145	37.54
749.556	38.4519
752.966	39.1922
756.377	39.9776
759.784	42.6981
763.19	44.3729
766.594	45.4675
770	49.4578
773.402	52.286
776.803	55.2007
780.202	58.6668
783.6	60.2959
786.997	63.77
790.393	65.5851
793.787	67.3424
797.18	66.786
800.572	67.8875
803.963	68.7952
807.35	69.3755
810.738	69.8378
814.125	69.5104
817.51	67.8319
820.894	68.0967
824.275	69.4566
827.657	66.102
831.037	64.5278
834.414	63.8998
837.792	64.3232
841.167	63.9477
844.542	61.4873
847.914	60.4456
851.287	56.9134
854.656	55.0641
858.026	51.9136
861.393	49.47
864.761	46.1305
868.125	44.0252
871.489	41.3211
874.85	39.3769
878.213	39.4291
881.572	38.2374
884.931	37.4127
888.287	36.741
891.643	35.4805
894.997	35.823
898.352	36.2468
901.704	34.1318
905.055	35.9024
908.404	35.5307
911.75	37.0159
915.097	38.4098
918.443	39.2843
921.787	37.8356
925.13	36.8204
928.472	35.3881
931.813	33.152
935.15	32.2715
938.488	30.0159
941.825	30.0101
945.158	29.773
948.493	30.0332
951.824	28.4128
955.156	27.8907
958.486	26.7836
961.814	25.0463
965.142	23.979
968.467	24.3396
971.79	23.9752
975.115	24.0082
978.436	23.0111
981.756	21.7122
985.077	21.0987
988.394	21.6293
991.71	21.4906
995.025	20.7821
998.341	19.0578
1001.65	17.9018
1004.97	17.6019
1008.28	17.9281
1011.58	17.5399
1014.89	18.4194
1018.2	18.9263
1021.5	19.6312
1024.81	22.1193
1028.11	24.5546
1031.41	25.7619
1034.71	27.624
1038.01	29.4383
1041.31	30.0735
1044.6	31.1166
1047.9	31.6414
1051.19	31.5811
1054.48	30.0778
1057.77	29.0028
1061.06	28.2481
1064.35	27.6352
1067.64	25.9444
1070.93	25.8064
1074.21	23.6549
1077.49	19.8491
1080.78	17.871
1084.06	16.6688
1087.34	15.6736
1090.61	13.9576
1093.89	12.3279
1097.17	11.9472
1100.44	12.5277
1103.71	14.3354
1106.99	15.017
1110.26	15.2169
1113.52	14.7172
1116.79	16.2309
1120.06	14.7796
1123.32	14.5121
1126.59	14.63
1129.85	13.6918
1133.11	12.2926
1136.37	12.0078
1139.63	12.2982
1142.89	11.2134
1146.15	9.94357
1149.4	9.78097
1152.66	8.98495
1155.91	7.09501
1159.16	5.0995
1162.41	3.79781
1165.66	2.76584
1168.91	1.99794
1172.16	2.2042
1175.4	3.24937
1178.65	2.62501
1181.89	2.12593
1185.13	3.50274
1188.37	4.35567
1191.61	5.2159
1194.85	7.04056
1198.08	8.59776
1201.32	9.67449
1204.55	11.6636
1207.79	11.9258
1211.02	11.6607
1214.25	13.2459
1217.48	15.2411
1220.71	15.6144
1223.93	17.5856
1227.16	19.6023
1230.38	21.5836
1233.6	22.9101
1236.83	25.5796
1240.05	28.8599
1243.26	30.8974
1246.48	32.9193
1249.7	36.2144
1252.92	37.0437
1256.13	37.4924
1259.34	39.4628
1262.55	43.2636
1265.76	46.8486
1268.97	48.6505
1272.18	51.1739
1275.39	52.3344
1278.59	54.4678
1281.8	56.0437
1285	56.8273
1288.2	58.7641
1291.4	61.0015
1294.6	60.6293
1297.8	59.9976
1301	60.6094
1304.19	60.6524
1307.39	60.6571
1310.58	61.0346
1313.77	60.7979
1316.96	60.4544
1320.15	57.7342
1323.34	54.9683
1326.53	52.9961
1329.72	51.2351
1332.9	48.7572
1336.08	47.6394
1339.27	48.5181
1342.45	49.0402
1345.63	48.4902
1348.8	48.0581
1351.98	48.482
1355.16	50.0256
1358.33	50.423
1361.51	50.8392
1364.68	52.1851
1367.85	52.6855
1371.02	52.5127
1374.19	51.7065
1377.36	50.0989
1380.52	52.4936
1383.69	52.1234
1386.85	52.3026
1390.02	52.7565
1393.18	51.851
1396.34	50.0584
1399.5	49.3845
1402.65	49.3818
1405.81	50.4772
1408.97	51.0234
1412.12	52.8295
1415.27	56.0059
1418.43	59.5798
1421.58	62.7944
1424.73	66.7318
1427.87	70.5135
1431.02	74.8036
1434.17	80.7963
1437.31	84.6971
1440.46	88.154
1443.6	90.7332
1446.74	91.9842
1449.88	92.4829
1453.02	92.9815
1456.16	92.97
1459.29	92.5147
1462.43	89.7089
1465.56	86.4291
1468.69	82.6426
1471.83	77.4468
1474.95	73.0309
1478.08	68.1376
1481.21	63.4406
1484.34	58.2704
1487.47	53.4933
1490.59	49.2288
1493.71	44.5365
1496.84	41.5154
1499.96	37.6023
1503.07	35.5131
1506.19	34.2005
1509.31	32.3641
1512.43	31.7001
1515.54	30.3146
1518.65	29.2234
1521.77	28.9679
1524.88	29.0915
1527.99	28.6621
1531.1	29.9352
1534.21	31.6626
1537.31	32.9283
1540.42	36.2006
1543.52	38.4494
1546.63	41.3424
1549.73	42.2281
1552.83	43.9873
1555.93	46.591
1559.03	46.993
1562.12	46.8173
1565.22	48.6812
1568.31	49.7134
1571.41	53.1494
1574.5	56.0907
1577.59	57.6053
1580.68	58.5474
1583.77	61.5385
1586.86	62.5851
1589.95	65.4224
1593.03	65.71
1596.11	66.858
1599.2	68.3356
1602.28	69.0997
1605.36	68.4924
1608.44	70.5885
1611.52	72.582
1614.6	73.7333
1617.67	74.0425
1620.75	75.4391
1623.82	74.2353
1626.89	74.5169
1629.96	74.44
1633.04	75.1811
1636.11	74.6623
1639.17	75.3107
1642.24	76.2331
1645.31	76.6312
1648.37	76.0904
1651.43	75.1036
1654.5	73.8432
1657.56	71.1415
1660.62	69.5474
1663.67	66.5997
1666.73	62.6005
1669.79	58.2955
1672.84	55.0791
1675.9	51.578
1678.95	47.2777
1682	43.1051
1685.05	41.1005
1688.1	35.9021
1691.15	32.6088
1694.2	30.2206
1697.25	27.5897
1700.29	25.5188
1703.33	25.077
1706.38	23.7446
1709.42	23.2106
1712.46	20.8668
1715.5	20.0749
1718.54	20.1322
1721.57	19.5795
1724.61	18.8422
1727.64	19.0434
1730.68	19.651
1733.71	18.9145
1736.74	19.149
1739.77	18.4786
1742.8	17.4222
1745.83	18.2355
1748.85	17.8923
1751.88	16.1573
1754.91	14.8011
1757.93	14.6261
1760.95	13.8366
1763.97	13.0977
1766.99	13.611
1770.01	12.2758
1773.03	12.1632
1776.04	11.2853
1779.06	10.9761
1782.07	10.5588
1785.09	10.0345
1788.1	8.9962
1791.11	9.19256
1794.12	8.16531
1797.13	7.31997
1800.13	7.30824
1803.14	8.34132
1806.15	8.0385
1809.15	8.16554
1812.15	8.55116
1815.16	8.59074
1818.15	8.32275
1821.16	8.46119
1824.15	9.1939
1827.15	9.61564
1830.15	10.5279
1833.14	10.8711
1836.14	11.0162
1839.13	11.0086
1842.12	10.5068
1845.11	11.044
1848.1	11.8457
1851.09	12.5786
1854.08	12.7295
1857.06	11.203
1860.05	10.0766
1863.03	8.28715
1866.01	7.39798
1869	5.54015
1871.98	4.74029
1874.96	4.287
1877.93	3.34876
1880.91	2.371
1882.47	2.58274
1885.46	2.71918
1888.44	2.25061
1891.43	3.63304
1894.42	5.14111
1897.4	5.60129
1900.39	5.31923
1903.37	5.97308
1906.35	7.50249
1909.33	8.35439
1912.31	8.67669
1915.29	10.4862
1918.26	12.1564
1921.24	12.8661
1924.21	13.433
1927.19	13.9604
1930.16	12.2587
1933.13	11.9217
1936.1	11.3283
1939.07	10.5563
1942.04	9.99607
1945	8.48566
1947.97	7.12852
1950.93	7.42788
1953.9	7.47463
1956.86	8.15497
1959.82	8.33889
1962.78	9.00832
1965.74	9.84513
1968.7	9.4898
1971.65	7.87243
1974.61	6.90141
1977.57	7.61558
1980.52	7.87634
1983.47	8.44066
1986.42	8.99812
1989.37	10.5136
1992.32	10.4957
1995.27	10.6859
1998.22	11.2164
2001.17	12.4984
2004.11	12.8835
2007.05	13.0494
2010	14.0988
2012.94	13.8373
2015.88	13.3541
2018.82	13.0146
2021.76	14.2326
2024.7	15.399
2027.63	15.8607
2030.57	16.7041
2033.5	15.491
2036.44	14.3954
2039.37	13.8051
2042.3	12.063
2045.23	11.3288
2048.16	11.4217
2051.08	12.6179
2054.01	13.2906
2056.94	13.6967
2059.86	12.8358
2062.79	13.48
2065.71	13.4178
2068.63	15.9688
2071.55	17.6609
2074.47	18.2811
2077.39	19.4778
2080.31	20.5734
2083.22	21.6848
2086.13	23.1397
2089.05	23.464
2091.96	24.7233
2094.87	25.1426
2097.78	26.0305
2100.69	25.7265
2103.6	26.3525
2106.51	26.7159
2109.42	27.6984
2112.32	29.3589
2115.23	31.3441
2118.13	32.7466
2121.03	34.592
2123.93	36.7368
2126.83	38.082
2129.73	39.952
2132.63	42.319
2135.53	45.8956
2138.42	48.5538
2141.32	51.5406
2144.21	53.0501
2147.1	54.6067
2150	57.0407
2152.89	59.0468
2155.78	61.5852
2158.66	61.2204
2161.55	62.7054
2164.44	63.6857
2167.32	63.4785
2170.21	64.1365
2173.09	63.417
2175.97	61.9079
2178.85	61.1441
2181.73	60.1698
2184.61	58.9161
2187.49	56.486
2190.37	54.6844
2193.24	53.4193
2196.12	51.1884
2198.99	49.1909
2201.87	47.6568
2204.74	46.0482
2207.61	43.1555
2210.48	41.8121
2213.35	40.125
2216.21	39.0241
2219.08	37.6317
2221.95	36.034
2224.81	34.3502
2227.67	33.1781
2230.54	31.5651
2233.4	30.4041
2236.26	28.5921
2239.11	27.2494
2241.97	25.0237
2244.83	23.3042
2247.69	21.6533
2250.54	20.2819
2253.4	19.6474
2256.25	19.2622
2259.1	18.0445
2261.95	16.5966
2264.8	14.5305
2267.65	13.8596
2270.5	14.143
2273.34	13.5469
2276.19	13.2952
2279.03	13.0858
2281.88	13.4494
2284.72	13.2777
2287.56	12.2906
2290.4	11.1907
2293.24	8.64963
2296.08	9.38912
2298.92	11.3219
2301.76	12.2395
2304.59	11.9103
2307.43	11.4937
2310.26	12.1891
2313.09	12.4294
2315.92	12.7051
2318.75	13.4367
2321.58	14.9169
2324.41	14.4749
2327.24	13.1816
2330.06	10.9049
2332.89	10.5127
2335.71	10.5352
2338.54	9.84572
2341.36	8.08082
2344.18	7.21959
2347	6.31754
2349.82	4.86732
2352.64	4.43317
2355.45	3.62849
2358.27	2.51904
2361.08	1.7354
2363.9	2.55767
2366.71	4.20325
2369.52	3.41722
2372.33	2.89731
2375.14	3.97972
2377.95	3.79958
2380.76	4.94932
2383.57	6.1255
2386.37	6.99372
2389.18	7.69841
2391.98	7.94867
2394.79	7.57513
2397.59	6.37373
2400.39	7.34872
2403.19	7.73614
2405.99	6.88737
2408.78	6.33071
2411.58	6.49609
2414.38	6.14719
2417.17	7.01162
2419.97	6.91251
2422.76	6.53676
2425.55	5.49702
2428.34	5.29908
2431.13	4.78944
2433.92	4.56629
2436.71	3.86048
2439.49	3.74858
2442.28	5.06321
2445.06	5.42351
2447.85	4.35905
2450.63	4.93798
2453.41	4.17912
2456.19	4.01803
2458.97	4.18548
2461.75	3.67748
2464.53	2.44077
2467.31	2.34388
2470.08	2.28913
2472.86	1.65842
2475.63	2.3932
2478.4	2.68348
2481.17	2.99374
2483.94	3.27145
2486.72	3.28057
2489.48	2.84186
2492.25	2.99712
2495.02	2.98407
2497.79	2.88925
2500.55	2.714
2503.31	2.7396
2506.08	3.79098
2508.84	4.93365
2511.6	6.08872
2514.36	5.17394
2517.12	5.17756
2519.88	5.10514
2522.63	4.56905
2525.39	4.90585
2528.14	4.37194
2530.9	4.21219
2533.65	4.64552
2536.4	5.21377
2539.15	5.74819
2541.9	5.81235
2544.65	6.51547
2547.4	5.34724
2550.15	4.80663
2552.89	4.25185
2555.64	2.62275
2558.38	1.49357
2561.12	1.21947
2563.87	0.171766
2566.61	-0.698292
2569.35	-1.33934
2572.09	-1.46347
2574.83	-1.32907
2577.56	-1.13477
2580.3	-1.25913
2583.04	-1.91677
2585.77	-2.46259
2588.5	-1.61942
2591.23	-1.97641
2593.97	-0.862207
2596.7	-0.597221
2599.43	-0.219405
2602.15	0.997125
2604.88	2.30105
2607.61	3.27205
2610.33	3.48938
2613.06	3.9972
2615.78	3.8248
2618.51	3.61062
2621.23	2.63858
2623.95	3.33821
2626.67	3.62825
2629.39	4.20341
2632.1	4.10209
2634.82	4.27216
2637.54	4.92277
2640.25	4.77306
2642.97	4.91977
2645.68	4.30898
2648.39	3.61855
2651.1	3.38776
2653.81	3.09382
2656.52	3.8915
2659.23	2.98277
2661.94	3.60555
2664.64	3.95338
2667.35	4.37382
2670.05	4.64406
2672.76	4.42269
2675.46	4.52233
2678.16	4.66252
2680.86	4.79969
2683.56	4.25242
2686.26	5.24918
2688.96	4.95229
2691.65	5.52184
2694.35	5.70246
2697.04	5.96392
2699.74	7.06898
2702.43	8.12074
2705.12	7.85661
2707.81	8.16305
2710.5	7.99893
2713.19	8.45837
2715.88	7.43529
2718.57	7.3113
2721.25	7.06703
2723.94	6.23039
2726.62	6.34051
2729.3	6.62404
2731.99	7.16139
2734.67	7.22305
2737.35	6.45898
2740.03	6.95955
2742.71	6.227
2745.38	6.81333
2748.06	6.73482
2750.74	5.86022
2753.41	5.73595
2756.09	4.77714
2758.76	5.91395
2761.43	5.39086
2764.1	6.35023
2766.77	6.73778
2769.44	6.04968
2772.11	6.23801
2774.77	5.71157
2777.44	3.97112
2780.11	3.13069
2782.77	2.28227
2785.43	1.80127
2788.1	1.42547
2790.76	1.53
2793.42	2.01378
2796.08	2.42934
2798.74	1.40187
2801.4	0.808137
2804.05	0.370582
2806.71	0.358348
2809.36	0.0645978
2812.02	-0.154033
2814.67	-0.397355
2817.32	0.327345
2819.97	2.06086
2822.62	3.41912
2825.27	6.86227
2827.92	10.3657
2830.57	14.6376
2833.22	18.2673
2835.86	22.2059
2838.51	25.536
2841.15	31.1385
2843.79	37.0173
2846.43	43.2563
2849.08	49.0712
2851.72	55.0532
2854.36	62.1563
2856.99	67.6789
2859.63	73.6585
2862.27	78.4288
2864.9	84.0457
2867.54	89.3337
2870.17	93.736
2872.8	99.0083
2875.43	102.618
2878.07	105.986
2880.7	110.323
2883.32	115.488
2885.95	120.421
2888.58	126.31
2891.21	131.155
2893.83	136.127
2896.46	142.464
2899.08	147.929
2901.7	154.209
2904.32	161.321
2906.94	168.691
2909.56	176.394
2912.18	184.344
2914.8	192.214
2917.42	198.603
2920.03	204.268
2922.65	209.364
2925.26	212.091
2927.88	213.759
2930.49	214.308
2933.1	213.719
2935.71	211.483
2938.32	207.568
2940.93	201.821
2943.54	195.66
2946.14	189.395
2948.75	181.594
2951.35	173.904
2953.96	164.508
2956.56	155.835
2959.16	147.367
2961.77	137.889
2964.37	130.484
2966.96	122.751
2969.56	114.644
2972.16	109.614
2974.76	102.968
2977.35	96.8919
2979.95	89.5505
2982.54	82.5038
2985.14	75.2247
2987.73	68.0545
2990.32	60.5773
2992.91	54.2346
2995.5	47.8071
2998.09	41.9629
3000.68	36.0584
3003.26	30.3954
3005.85	25.7921
3008.43	21.0624
3011.02	16.7503
3013.6	13.2916
3016.19	9.65591
3018.77	7.1677
3021.35	4.4448
3023.93	2.35405
3026.5	1.80527
3029.08	1.19244
3031.66	1.20168
3034.24	1.98418
3036.81	2.82794
3039.39	2.24968
3041.96	2.22143
3044.53	1.75662
3047.1	1.98684
3049.67	1.40158
3052.24	1.79715
3054.81	1.98107
3057.38	2.71122
3059.95	2.38909
3062.52	2.88245
3065.08	2.87097
3067.65	2.4187
3070.21	2.43522
3072.77	2.1768
3075.33	1.29136
3077.89	1.233
3080.45	0.774517
3083.01	1.25947
3085.57	0.795667
3088.13	1.00981
3090.68	1.54641
3093.24	2.53842
3095.79	3.10992
3098.35	4.40266
3100.9	3.97227
3103.45	4.11872
3106	4.97474
3108.55	6.01405
3111.1	7.3304
3113.65	7.57795
3116.2	8.49564
3118.75	9.84845
3121.29	11.7353
3123.84	13.6602
3126.38	15.9575
3128.92	16.7231
3131.47	19.0173
3134.01	20.9546
3136.55	22.977
3139.09	25.8476
3141.63	28.3202
3144.17	30.8554
3146.7	33.7498
3149.24	36.4735