File: data/Raman/poly_smoothed/Mb_40_y_03_1x_45s_532 nm_x100_100%_600 gr_mm_01.txt
#Acq. time (s)=	45
#Accumulations=	2
#Range (cm-¹)=	200...3150
#Windows=	2
#Auto scanning=	Off
#Autofocus=	Off
#Macrospot=	Off
#AutoExposure=	Off
#Spike filter=	Multiple accum.
#Delay time (s)=	0
#Binning=	1
#Readout mode=	Signal
#DeNoise=	Off
#ICS correction=	On
#Dark correction=	Off
#Inst. Process=	Off
#Detector Gain=	Best Dynamic Range
#Detector ADC=	20 kHz
#Detector temperature (°C)=	-69.85
#Instrument=	LabRAM HR Evol
#Detector=	Synapse
#Objective=	x100
#Grating=	600 gr/mm
#ND Filter=	100%
#Laser (nm)=	532
#Hole=	100.021
#Range=	Auto
#Laser Pol.=	No
#Raman. Pol.=	No
#Laser Pol. (°)=	-0.0007625
#Raman Pol. (°)=	89.9995
#Collection=	Microscope
#StageXY=	Marzhauser
#StageZ=	Marzhauser
#X (µm)=	-1250.4
#Y (µm)=	2709
#Z (µm)=	587.1
#Full time(mm:ss)=	3:18
#Project=
#Sample=
#Site=
#Title=	Mb_40_y_03_2x_45s_532 nm_x100_100%_600 gr_mm
#Remark=
#Date=	18.07.2022 15:18
#Acquired=	18.07.2022 15:18:54
#Base:Fit=	10.08.2022 10:52:48
#Base:Sub=	10.08.2022 10:52:53
#Filter:Polynom=	16.08.2022 10:09:04
#AxisType[0]=Intens
#AxisUnit[0]=Cnt
#AxisType[1]=Spectr
#AxisUnit[1]=1/cm
200.419	4.51475
204.048	5.86152
207.678	4.64785
211.304	4.61994
214.928	4.90913
218.554	5.08228
222.176	3.80177
225.798	1.95327
229.417	2.95718
233.035	2.7729
236.653	2.69172
240.268	3.21487
243.881	3.61773
247.493	3.5785
251.103	3.70638
254.715	3.74839
258.322	4.09291
261.929	5.27464
265.534	6.91902
269.137	7.20338
272.739	6.73793
276.34	7.33528
279.939	6.87311
283.537	8.07428
287.134	7.57708
290.729	7.43362
294.323	7.62734
297.913	7.72279
301.504	7.09029
305.093	7.43908
308.682	7.7482
312.268	7.16611
315.852	7.66231
319.436	7.65474
323.018	7.11626
326.597	6.78482
330.177	5.57005
333.753	5.38045
337.331	4.27282
340.906	5.85599
344.478	5.22487
348.051	5.75724
351.621	6.51422
355.189	6.41654
358.757	4.98367
362.323	5.70316
365.889	6.55793
369.451	7.34328
373.012	8.24463
376.574	7.18457
380.133	7.63912
383.69	8.20001
387.245	6.98503
390.8	8.85257
394.353	10.1508
397.906	10.4192
401.456	10.683
405.005	11.4113
408.552	11.2297
412.099	9.83284
415.643	9.48334
419.187	9.30855
422.728	10.8345
426.269	10.8356
429.806	11.3137
433.344	10.819
436.881	11.6028
440.416	12.3535
443.949	11.963
447.48	12.0629
451.011	11.63
454.541	11.6444
458.069	11.176
461.594	11.2715
465.119	9.71662
468.642	9.50828
472.165	9.74622
475.684	9.79561
479.204	11.4842
482.721	10.5271
486.239	10.0797
489.753	9.78418
493.268	10.374
496.779	10.5623
500.289	11.4604
503.8	12.7159
507.307	13.5385
510.813	15.3625
514.32	16.0789
517.823	17.4349
521.325	19.6121
524.826	19.7376
528.325	19.882
531.823	20.6882
535.32	19.9624
538.815	20.0752
542.309	21.2876
545.802	20.0014
549.293	19.6212
552.783	16.9264
556.271	15.7982
559.759	14.0095
563.245	12.2303
566.729	11.3342
570.213	9.18348
573.693	9.25556
577.173	8.47078
580.652	6.48612
584.13	5.69056
587.605	5.03939
591.08	4.76749
594.552	5.04515
598.025	5.72803
601.496	5.51667
604.964	5.69001
608.433	7.46539
611.898	8.00782
615.364	9.82881
618.827	12.304
622.288	12.4792
625.75	12.9267
629.209	13.2948
632.667	13.7983
636.125	14.1208
639.58	13.9795
643.033	15.5572
646.485	16.6665
649.936	17.8133
653.388	17.8298
656.836	18.0057
660.283	18.3085
663.728	18.808
667.173	20.3437
670.616	20.7371
674.057	22.0479
677.498	23.1789
680.937	25.6687
684.375	28.3736
687.809	28.3178
691.244	31.2267
694.678	32.458
698.111	33.9271
701.54	35.8052
704.97	36.6386
708.398	38.555
711.826	40.8967
715.25	42.9161
718.675	43.6544
722.096	45.228
725.518	46.7482
728.937	46.9061
732.357	46.6298
735.773	46.3815
739.19	46.4842
742.604	47.6084
746.018	48.657
749.429	51.3228
752.839	52.2464
756.248	52.7844
759.657	55.6655
763.063	58.3166
766.468	61.2431
769.871	62.5139
773.273	63.9615
776.676	65.1832
780.075	66.6408
783.474	70.098
786.871	71.7227
790.266	74.3334
793.661	75.6693
797.054	76.704
800.446	78.7841
803.834	79.1779
807.224	78.4002
810.612	78.4875
813.998	77.4017
817.384	76.2109
820.766	76.4297
824.149	76.0318
827.531	75.3184
830.909	74.292
834.288	73.1354
837.666	71.0124
841.041	70.3375
844.416	67.8375
847.788	64.9326
851.161	62.4338
854.53	59.8085
857.901	56.9445
861.268	55.1768
864.633	52.4
868	50.1235
871.363	47.9592
874.725	47.2567
878.088	46.4764
881.447	47.0752
884.805	47.3438
888.162	44.8809
891.518	45.3088
894.872	46.5456
898.225	47.6677
901.577	47.6419
904.928	49.328
908.277	50.0413
911.625	50.8385
914.972	51.6272
918.318	51.1696
921.662	50.8701
925.005	50.5444
928.347	49.0464
931.686	47.7779
935.025	47.4535
938.363	45.5332
941.698	43.9169
945.034	40.9313
948.368	39.4707
951.699	39.1296
955.031	37.1248
958.36	36.1646
961.689	34.4011
965.016	33.1814
968.343	31.2524
971.666	30.1154
974.991	29.0002
978.312	27.6707
981.632	27.1336
984.953	26.8548
988.27	25.6824
991.587	24.8182
994.902	23.3401
998.216	21.0781
1001.53	16.6829
1004.84	15.9745
1008.15	16.8014
1011.46	21.2914
1014.77	28.4618
1018.07	35.71
1021.38	43.6013
1024.68	49.6939
1027.99	58.9371
1031.29	66.3371
1034.59	70.5359
1037.89	73.9256
1041.18	76.7341
1044.48	77.9801
1047.77	77.5695
1051.07	75.6237
1054.36	73.1836
1057.65	69.4842
1060.94	65.0462
1064.23	58.8767
1067.52	50.5056
1070.8	40.8965
1074.09	31.4415
1077.37	21.7739
1080.65	12.771
1083.93	6.09047
1087.21	5.00039
1090.49	6.55788
1093.77	9.83293
1097.04	9.42635
1100.32	10.2696
1103.59	10.7554
1106.86	10.5886
1110.13	10.8391
1113.4	10.0355
1116.67	9.9815
1119.94	9.38138
1123.2	8.48324
1126.47	9.41862
1129.73	9.1952
1132.99	10.7829
1136.25	11.6573
1139.51	10.8426
1142.77	10.5288
1146.03	10.1013
1149.28	10.0644
1152.54	8.88563
1155.79	8.36203
1159.04	7.6
1162.29	7.9878
1165.54	7.96699
1168.79	8.17736
1172.04	8.62207
1175.28	7.76897
1178.53	6.79447
1181.77	5.22197
1185.01	5.55238
1188.25	4.65782
1191.49	3.76135
1194.73	2.81793
1197.96	2.13978
1201.2	1.13744
1204.43	1.57295
1207.66	2.86664
1210.9	3.64513
1214.13	5.75121
1217.36	7.11201
1220.58	7.34965
1223.81	8.9925
1227.04	9.90481
1230.26	10.9481
1233.48	12.1237
1236.71	13.0349
1239.93	14.1875
1243.14	14.457
1246.36	16.0936
1249.58	18.0278
1252.8	20.8461
1256.01	21.5355
1259.22	21.9109
1262.43	23.5553
1265.64	24.6206
1268.85	24.1957
1272.06	26.5319
1275.27	26.8149
1278.48	28.2718
1281.68	29.2779
1284.88	32.1461
1288.08	34.3313
1291.28	37.4484
1294.48	39.7352
1297.68	40.6125
1300.88	40.8329
1304.07	40.9509
1307.27	41.6137
1310.46	41.8431
1313.65	41.9785
1316.85	40.2659
1320.03	39.2029
1323.22	38.4422
1326.41	38.8901
1329.6	38.3568
1332.78	36.7135
1335.96	34.871
1339.15	33.0164
1342.33	30.1874
1345.51	27.975
1348.69	27.0747
1351.86	27.1542
1355.04	26.89
1358.21	26.6529
1361.39	27.0875
1364.56	27.2885
1367.73	27.3842
1370.9	27.8566
1374.07	27.4013
1377.24	27.8183
1380.41	27.5285
1383.57	28.1612
1386.73	28.9747
1389.9	29.3275
1393.06	28.1557
1396.22	28.3082
1399.38	28.8806
1402.54	29.27
1405.69	29.8442
1408.85	27.6883
1412	25.9703
1415.16	25.987
1418.31	26.2772
1421.46	28.2796
1424.61	31.7483
1427.76	35.241
1430.9	38.6384
1434.05	41.2572
1437.2	42.975
1440.34	44.0782
1443.48	47.089
1446.62	46.5245
1449.76	46.9243
1452.9	48.0311
1456.04	48.5137
1459.17	47.6509
1462.31	46.5888
1465.44	45.7431
1468.58	44.3191
1471.71	42.2562
1474.84	41.6272
1477.97	38.1124
1481.1	35.5043
1484.22	31.9244
1487.35	29.5272
1490.47	28.6592
1493.59	26.6234
1496.72	25.5299
1499.84	26.4198
1502.96	25.814
1506.08	27.1837
1509.19	26.6744
1512.31	25.3899
1515.42	24.9076
1518.54	23.051
1521.65	22.5568
1524.76	21.8746
1527.87	22.5605
1530.98	23.75
1534.09	24.0502
1537.2	24.1105
1540.3	24.6389
1543.41	25.022
1546.51	24.7705
1549.61	26.0546
1552.71	25.2622
1555.81	25.4024
1558.91	25.5324
1562.01	24.855
1565.1	24.7888
1568.2	25.0216
1571.29	26.5549
1574.38	27.6544
1577.48	28.9242
1580.57	29.446
1583.65	30.255
1586.74	29.3076
1589.83	29.9829
1592.92	31.4869
1596	32.8687
1599.08	34.0416
1602.16	34.571
1605.24	35.2486
1608.32	35.4598
1611.4	34.9187
1614.48	34.0974
1617.56	35.5281
1620.63	34.9493
1623.71	35.421
1626.78	36.2723
1629.85	37.7362
1632.92	38.7072
1635.99	38.8171
1639.06	40.2121
1642.12	40.4902
1645.19	40.9838
1648.25	40.5005
1651.32	40.5268
1654.38	39.3281
1657.44	38.5632
1660.5	37.3809
1663.56	36.3675
1666.62	35.8318
1669.67	34.5649
1672.73	32.8638
1675.79	29.773
1678.84	28.6621
1681.89	26.702
1684.94	24.6839
1687.99	22.6964
1691.04	21.5397
1694.08	19.3233
1697.13	17.5284
1700.18	16.0057
1703.22	14.5805
1706.26	12.937
1709.3	11.7042
1712.35	11.4785
1715.39	9.65118
1718.42	9.32621
1721.46	9.01488
1724.5	7.13714
1727.53	7.54739
1730.56	5.99384
1733.6	5.49952
1736.63	4.30677
1739.66	4.17113
1742.69	4.29138
1745.71	4.13695
1748.74	4.42357
1751.77	5.00477
1754.79	5.45102
1757.81	6.00305
1760.84	6.373
1763.86	5.96659
1766.88	5.84406
1769.9	5.88909
1772.91	6.69786
1775.93	6.46333
1778.95	6.59859
1781.96	6.93801
1784.97	7.72429
1787.99	8.57329
1791	8.17786
1794.01	8.23026
1797.01	7.77395
1800.02	7.45361
1803.03	7.24101
1806.03	5.81424
1809.04	4.97155
1812.04	4.627
1815.04	4.53396
1818.04	4.5256
1821.04	4.67262
1824.04	4.45121
1827.04	4.85883
1830.03	5.57833
1833.03	6.31503
1836.02	6.52682
1839.02	6.62664
1842.01	6.47734
1845	6.43903
1847.99	6.4785
1850.98	5.65727
1853.96	4.97191
1856.95	5.0222
1859.94	3.86758
1862.92	2.56653
1865.9	2.11951
1868.88	1.81561
1871.86	2.05137
1874.84	1.11549
1877.82	0.30458
1880.8	0.399325
1882.58	0.230322
1885.57	0.568093
1888.56	0.8119
1891.54	1.04567
1894.53	1.91132
1897.51	3.00299
1900.5	4.59668
1903.48	6.30924
1906.46	6.88719
1909.44	6.74908
1912.42	6.98659
1915.4	7.22515
1918.37	7.57771
1921.35	7.79293
1924.32	7.25791
1927.3	7.87764
1930.27	8.02528
1933.24	7.85726
1936.21	7.70217
1939.18	8.06673
1942.15	7.55077
1945.11	7.65717
1948.08	7.47546
1951.04	7.17338
1954.01	6.04291
1956.97	5.41247
1959.93	6.10828
1962.89	5.7097
1965.85	5.73383
1968.81	5.69126
1971.77	5.82118
1974.72	5.93349
1977.68	5.57814
1980.63	4.89425
1983.58	4.41252
1986.53	5.13739
1989.48	5.36181
1992.43	5.19964
1995.38	5.85162
1998.33	6.70444
2001.27	7.03716
2004.22	7.531
2007.16	7.29042
2010.11	7.06281
2013.05	6.78906
2015.99	6.72508
2018.93	6.57322
2021.87	6.764
2024.8	7.39114
2027.74	6.73329
2030.68	7.54012
2033.61	7.80745
2036.54	7.12682
2039.48	7.17203
2042.41	7.74532
2045.34	8.22608
2048.27	8.85045
2051.19	9.65957
2054.12	9.09597
2057.05	10.368
2059.97	10.9004
2062.9	10.7475
2065.82	11.7551
2068.74	12.9671
2071.66	13.1357
2074.58	13.5058
2077.5	13.2759
2080.41	14.3927
2083.33	15.0784
2086.24	15.2487
2089.16	15.7399
2092.07	17.1344
2094.98	18.4618
2097.89	18.8124
2100.8	18.9559
2103.71	20.1761
2106.62	21.0032
2109.53	22.1059
2112.43	22.6099
2115.33	23.8104
2118.24	26.4508
2121.14	27.2793
2124.04	28.5376
2126.94	30.5507
2129.84	31.8933
2132.74	33.5957
2135.63	35.2365
2138.53	36.7474
2141.43	38.6347
2144.32	40.2666
2147.21	42.8976
2150.1	44.1927
2152.99	45.4488
2155.88	46.869
2158.77	47.4967
2161.66	49.5759
2164.55	51.4143
2167.43	53.1887
2170.31	53.2457
2173.2	53.1906
2176.08	52.8048
2178.96	53.9262
2181.84	53.3551
2184.72	53.1264
2187.6	52.9668
2190.47	51.2737
2193.35	50.5718
2196.23	49.8061
2199.1	48.4717
2201.97	46.6571
2204.84	44.5633
2207.71	41.9902
2210.58	40.2023
2213.45	38.3583
2216.32	36.0899
2219.19	33.6988
2222.05	31.3587
2224.92	29.9144
2227.78	27.926
2230.64	26.1911
2233.5	25.1543
2236.36	23.1628
2239.22	21.5363
2242.08	19.2777
2244.94	18.6739
2247.79	18.6068
2250.65	17.8201
2253.5	16.2612
2256.36	14.9196
2259.21	14.1251
2262.06	13.8333
2264.91	12.4895
2267.76	10.9666
2270.6	10.5309
2273.45	9.98331
2276.3	9.85857
2279.14	9.66814
2281.98	8.7913
2284.83	7.69035
2287.67	7.59537
2290.51	6.44986
2293.35	5.04
2296.19	4.91419
2299.02	5.96799
2301.86	6.70113
2304.7	7.02764
2307.53	7.23194
2310.36	7.30267
2313.2	8.14996
2316.03	8.33362
2318.86	8.72338
2321.69	7.57378
2324.51	7.55512
2327.34	6.79154
2330.17	7.2235
2332.99	7.29844
2335.82	6.89384
2338.64	7.18604
2341.46	7.17017
2344.28	7.00419
2347.1	5.15953
2349.92	3.93875
2352.74	3.91267
2355.56	3.28338
2358.37	3.23925
2361.19	2.26814
2364	2.55156
2366.82	3.32433
2369.63	2.38519
2372.44	2.43428
2375.25	1.83775
2378.06	1.31071
2380.86	1.38619
2383.67	1.3388
2386.48	0.775272
2389.28	1.51255
2392.09	1.27225
2394.89	2.06773
2397.69	2.38351
2400.49	3.30822
2403.29	4.42707
2406.09	5.00093
2408.89	5.50411
2411.69	5.51922
2414.48	6.04433
2417.28	5.7015
2420.07	6.65339
2422.86	7.25823
2425.65	6.697
2428.45	6.55025
2431.23	5.77174
2434.02	4.57643
2436.81	4.63229
2439.6	4.5574
2442.38	4.77671
2445.17	4.30808
2447.95	4.8128
2450.73	4.82322
2453.52	5.42768
2456.3	5.18023
2459.08	4.91044
2461.85	4.13879
2464.63	4.44469
2467.41	4.59566
2470.19	5.1297
2472.96	5.09432
2475.73	4.4173
2478.51	3.63974
2481.28	3.61445
2484.05	3.54878
2486.82	3.37181
2489.59	4.10552
2492.35	3.93131
2495.12	4.38391
2497.89	4.02488
2500.65	4.32175
2503.42	4.17148
2506.18	4.36212
2508.94	4.27571
2511.7	4.00551
2514.46	4.60508
2517.22	4.81432
2519.98	5.2714
2522.73	4.7323
2525.49	4.41953
2528.25	4.4264
2531	4.37385
2533.75	3.85698
2536.5	3.914
2539.25	4.50376
2542.01	4.15583
2544.75	3.61896
2547.5	3.24306
2550.25	3.68003
2553	3.53523
2555.74	4.18263
2558.49	4.06811
2561.23	3.98282
2563.97	2.99749
2566.71	2.6615
2569.45	3.08316
2572.19	2.59074
2574.93	3.5903
2577.67	3.76382
2580.4	4.0037
2583.14	4.27126
2585.87	4.62917
2588.6	5.13155
2591.34	4.38339
2594.07	3.7168
2596.8	4.14496
2599.53	3.59645
2602.26	3.16222
2604.98	3.53927
2607.71	3.04629
2610.44	2.36499
2613.16	1.98745
2615.88	2.49265
2618.61	2.56023
2621.33	2.13932
2624.05	1.45972
2626.77	0.319061
2629.49	0.127408
2632.21	0.626727
2634.92	1.07903
2637.64	1.64653
2640.35	1.97388
2643.07	2.83694
2645.78	2.88455
2648.49	2.64192
2651.2	2.66485
2653.91	3.26924
2656.62	3.24908
2659.33	3.27755
2662.04	4.04033
2664.74	3.89365
2667.45	3.45041
2670.15	3.28429
2672.86	3.43101
2675.56	4.27469
2678.26	4.43801
2680.96	5.66468
2683.66	5.58435
2686.36	4.49055
2689.06	3.63731
2691.75	3.93513
2694.45	3.54575
2697.14	4.18594
2699.84	4.17328
2702.53	3.74682
2705.22	4.34868
2707.91	4.09632
2710.6	3.765
2713.29	3.98774
2715.98	4.00919
2718.67	3.65685
2721.35	2.96163
2724.04	3.17387
2726.72	3.13653
2729.4	2.72044
2732.09	2.96284
2734.77	2.68972
2737.45	3.14752
2740.13	3.06178
2742.81	2.82227
2745.48	3.02315
2748.16	2.97645
2750.84	2.50277
2753.51	2.11445
2756.19	2.4652
2758.86	1.62909
2761.53	1.48573
2764.2	1.1979
2766.87	0.53823
2769.54	0.541231
2772.21	0.996957
2774.88	0.364578
2777.54	0.582499
2780.21	0.115933
2782.87	-0.0894138
2785.53	-0.392336
2788.2	0.0453624
2790.86	0.043559
2793.52	-0.52187
2796.18	-0.226295
2798.84	-0.301915
2801.49	-0.0416966
2804.15	-0.430316
2806.81	-1.08281
2809.46	-1.50726
2812.12	-1.15435
2814.77	-0.50689
2817.42	0.151485
2820.07	0.76534
2822.72	2.32309
2825.37	4.52589
2828.02	6.76607
2830.67	9.3151
2833.31	11.9916
2835.96	14.7121
2838.61	17.8551
2841.25	20.1414
2843.89	22.3201
2846.53	25.4121
2849.17	28.89
2851.81	31.8193
2854.45	35.3442
2857.09	39.2536
2859.73	43.3608
2862.36	46.8583
2865	49.7168
2867.64	52.627
2870.27	54.5851
2872.9	57.2117
2875.53	59.6587
2878.16	62.0049
2880.79	64.3408
2883.42	65.948
2886.05	68.3354
2888.68	70.9431
2891.3	73.753
2893.93	75.699
2896.55	77.799
2899.18	80.1362
2901.8	82.4026
2904.42	85.6701
2907.04	88.0338
2909.66	93.1197
2912.28	97.9431
2914.9	101.652
2917.51	106.288
2920.13	110.551
2922.74	114.189
2925.36	117.095
2927.97	119.125
2930.59	120.508
2933.2	120.674
2935.81	120.64
2938.42	119.455
2941.02	118.002
2943.63	115.473
2946.24	111.765
2948.85	107.403
2951.45	103.153
2954.05	98.9092
2956.66	94.3635
2959.26	89.4479
2961.86	84.0586
2964.46	80.6067
2967.06	75.9993
2969.66	71.9208
2972.26	67.2587
2974.85	63.2331
2977.45	58.7721
2980.05	54.3516
2982.64	50.0894
2985.23	45.9907
2987.83	41.959
2990.42	37.8407
2993.01	34.3303
2995.6	30.6079
2998.19	27.2148
3000.77	24.2812
3003.36	21.9283
3005.95	19.3295
3008.53	16.2306
3011.12	14.1237
3013.7	13.0295
3016.28	11.9836
3018.86	10.8372
3021.44	9.57664
3024.02	8.72241
3026.6	7.92114
3029.18	7.28799
3031.76	7.07433
3034.33	6.97991
3036.91	6.54231
3039.48	7.33777
3042.05	7.94666
3044.63	7.34574
3047.2	7.75649
3049.77	8.6997
3052.34	8.97833
3054.91	8.36145
3057.48	7.95972
3060.04	7.55436
3062.61	7.1385
3065.17	6.99431
3067.74	6.5849
3070.3	6.51731
3072.87	6.90471
3075.43	6.32547
3077.99	6.45976
3080.55	6.07217
3083.11	5.99814
3085.67	6.30807
3088.22	6.40918
3090.78	6.63749
3093.34	8.0283
3095.89	9.26728
3098.44	10.204
3101	12.136
3103.55	14.1701
3106.1	14.7611
3108.65	16.4512
3111.2	17.2555
3113.75	17.7195
3116.3	18.3007
3118.84	18.4362
3121.39	19.6014
3123.93	20.291
3126.48	20.8114
3129.02	22.2336
3131.56	23.3968
3134.1	24.2947
3136.64	25.2272
3139.18	25.8864
3141.72	27.1507
3144.26	28.5965
3146.8	30.4464
3149.33	31.8855