File: data/Raman/poly_smoothed/Mb_40_y_19_1x_45s_532 nm_x100_100%_600 gr_mm_01.txt
#Acq. time (s)=	45
#Accumulations=	2
#Range (cm-¹)=	200...3150
#Windows=	2
#Auto scanning=	Off
#Autofocus=	Off
#Macrospot=	Off
#AutoExposure=	Off
#Spike filter=	Multiple accum.
#Delay time (s)=	0
#Binning=	1
#Readout mode=	Signal
#DeNoise=	Off
#ICS correction=	On
#Dark correction=	Off
#Inst. Process=	Off
#Detector Gain=	Best Dynamic Range
#Detector ADC=	20 kHz
#Detector temperature (°C)=	-69.85
#Instrument=	LabRAM HR Evol
#Detector=	Synapse
#Objective=	x100
#Grating=	600 gr/mm
#ND Filter=	100%
#Laser (nm)=	532
#Hole=	100.021
#Range=	Auto
#Laser Pol.=	No
#Raman. Pol.=	No
#Laser Pol. (°)=	-0.0007625
#Raman Pol. (°)=	89.9995
#Collection=	Microscope
#StageXY=	Marzhauser
#StageZ=	Marzhauser
#X (µm)=	-1038.8
#Y (µm)=	647.7
#Z (µm)=	584.35
#Full time(mm:ss)=	3:19
#Project=
#Sample=
#Site=
#Title=	Mb_40_y_19_2x_45s_532 nm_x100_100%_600 gr_mm
#Remark=
#Date=	19.07.2022 10:32
#Acquired=	19.07.2022 10:32:20
#Base:Fit=	10.08.2022 10:52:48
#Base:Sub=	10.08.2022 10:52:53
#Filter:Polynom=	16.08.2022 10:09:04
#AxisType[0]=Intens
#AxisUnit[0]=Cnt
#AxisType[1]=Spectr
#AxisUnit[1]=1/cm
200.423	30.9642
204.052	32.8057
207.682	31.682
211.308	29.3825
214.935	27.6227
218.558	27.4008
222.18	26.4308
225.802	23.2861
229.421	21.1451
233.039	19.612
236.657	17.0874
240.272	16.0709
243.885	15.4533
247.497	14.3512
251.11	12.1596
254.719	11.1812
258.327	8.36036
261.933	7.77157
265.538	5.458
269.141	5.68882
272.744	5.41154
276.344	6.07174
279.944	6.03697
283.542	5.58155
287.138	5.06073
290.733	5.05601
294.327	5.35051
297.919	6.26112
301.508	8.47868
305.098	10.7366
308.686	10.1724
312.273	11.17
315.858	10.8163
319.44	12.0877
323.022	13.3853
326.604	14.3225
330.181	13.004
333.76	12.1851
337.335	12.0039
340.91	10.7534
344.483	10.1911
348.055	9.68823
351.625	9.12887
355.195	7.95358
358.762	7.40905
362.329	6.48243
365.893	5.23363
369.455	5.27406
373.017	4.12475
376.578	3.64009
380.137	3.4777
383.694	4.10757
387.249	3.77232
390.806	4.94179
394.359	4.01074
397.91	4.63303
401.46	5.92572
405.009	5.30776
408.557	7.55285
412.103	8.1162
415.647	7.65433
419.191	8.55906
422.733	8.79409
426.273	10.5979
429.812	9.44122
433.35	10.2548
436.885	9.41917
440.42	9.66561
443.954	10.3847
447.486	10.2054
451.015	9.50994
454.545	8.66552
458.073	8.17912
461.598	7.59407
465.124	8.17732
468.648	9.91447
472.169	9.66489
475.69	10.5683
479.208	10.6452
482.727	12.4163
486.243	14.7383
489.759	16.31
493.272	18.2739
496.783	19.8252
500.295	19.7569
503.804	18.7566
507.311	19.8958
510.819	21.2605
514.324	23.4575
517.827	23.6749
521.329	23.3672
524.83	22.6819
528.329	20.9123
531.829	20.064
535.326	18.2262
538.821	17.1862
542.315	16.6833
545.808	16.5095
549.299	15.4819
552.789	15.3923
556.278	13.7558
559.763	11.628
563.249	10.9507
566.733	8.22959
570.217	8.6347
573.699	8.61656
577.177	7.83855
580.656	5.69867
584.134	4.76057
587.609	4.90144
591.084	5.15428
594.558	6.1732
598.029	7.31366
601.5	5.43449
604.968	4.36326
608.437	3.41388
611.902	2.79121
615.368	3.26451
618.831	4.96275
622.294	4.44259
625.755	3.91933
629.213	3.80756
632.673	4.65503
636.129	5.0368
639.584	4.77543
643.037	3.56748
646.491	4.14851
649.942	4.23241
653.392	4.05512
656.84	3.87569
660.287	3.90505
663.732	5.0153
667.177	4.16341
670.62	4.78777
674.061	4.79837
677.502	5.78119
680.941	7.57196
684.379	8.89061
687.815	12.0767
691.248	14.8004
694.682	16.6842
698.115	18.8943
701.546	21.805
704.974	24.2954
708.402	25.4551
711.83	27.3863
715.254	30.0874
718.679	31.0257
722.102	31.6765
725.522	31.2187
728.943	30.8585
732.361	31.0534
735.779	29.1051
739.194	27.9741
742.608	27.8396
746.022	27.2526
749.433	28.3786
752.843	29.6208
756.254	30.2839
759.661	31.95
763.067	34.5965
766.471	39.2455
769.877	41.8834
773.279	44.8483
776.68	46.5687
780.079	47.4324
783.478	49.8223
786.875	52.9912
790.27	56.6494
793.665	58.6198
797.058	59.0081
800.45	59.038
803.84	58.4225
807.23	58.0536
810.616	58.0925
814.002	57.1264
817.388	57.891
820.772	56.6436
824.153	56.6434
827.535	56.2705
830.915	55.5574
834.292	53.783
837.67	52.4564
841.047	49.9281
844.42	48.6923
847.794	46.4858
851.165	44.7191
854.534	43.4569
857.905	44.2477
861.272	41.7741
864.639	41.3186
868.004	42.2025
871.367	43.1196
874.731	44.5378
878.092	42.8741
881.451	40.2704
884.809	39.9529
888.166	39.1307
891.522	38.9592
894.878	37.6561
898.231	38.6355
901.583	38.1013
904.934	36.9213
908.283	36.0106
911.631	34.1549
914.976	33.3073
918.322	33.2524
921.666	32.0956
925.009	32.0007
928.351	31.9762
931.692	32.0995
935.029	33.0689
938.367	31.2939
941.704	31.169
945.038	30.6834
948.372	32.484
951.705	33.5756
955.035	33.5351
958.366	31.2747
961.693	27.7617
965.021	26.6475
968.346	26.9194
971.67	24.0844
974.995	25.2164
978.316	25.1033
981.638	25.3069
984.957	24.5311
988.274	22.697
991.59	20.5661
994.907	18.1427
998.221	13.5042
1001.53	8.78312
1004.85	6.00196
1008.16	11.2035
1011.46	26.2379
1014.77	46.7075
1018.08	72.0107
1021.38	100.435
1024.69	129.88
1027.99	158.734
1031.29	183.651
1034.59	204.555
1037.89	219.235
1041.19	229.994
1044.48	236.618
1047.78	238.522
1051.07	235.627
1054.36	230.187
1057.66	217.99
1060.94	201.209
1064.23	180.46
1067.52	155.641
1070.81	128.454
1074.09	97.2563
1077.38	66.9909
1080.66	41.4629
1083.94	20.3872
1087.22	7.53947
1090.5	5.07697
1093.77	11.3423
1097.05	15.2315
1100.32	21.34
1103.6	28.0063
1106.87	33.3427
1110.14	38.5921
1113.41	40.1471
1116.67	40.5452
1119.94	39.9713
1123.21	39.9308
1126.47	37.4129
1129.73	34.9281
1133	33.7056
1136.26	31.9606
1139.52	29.6667
1142.77	27.9036
1146.03	24.6224
1149.29	20.2667
1152.54	15.7495
1155.79	13.0357
1159.04	10.281
1162.3	5.31552
1165.55	2.70284
1168.79	2.27098
1172.04	4.56971
1175.28	6.04999
1178.53	6.51912
1181.77	8.45852
1185.01	8.97978
1188.25	11.1913
1191.49	9.96804
1194.73	7.79958
1197.97	7.64368
1201.2	6.77214
1204.44	7.51401
1207.67	7.34704
1210.9	9.8675
1214.13	12.6945
1217.36	15.0196
1220.59	16.6671
1223.82	17.5398
1227.04	18.6373
1230.26	20.2021
1233.49	25.6806
1236.71	28.4832
1239.93	30.8208
1243.15	33.6208
1246.37	36.9752
1249.58	38.3546
1252.8	38.2109
1256.01	41.3633
1259.23	47.1507
1262.44	55.6994
1265.65	62.9776
1268.86	69.5549
1272.07	77.0295
1275.27	83.4736
1278.48	89.8582
1281.68	94.7176
1284.89	100.111
1288.09	104.107
1291.29	106.61
1294.49	106.301
1297.69	106.195
1300.88	104.296
1304.08	103.864
1307.27	100.551
1310.47	97.1994
1313.66	93.4949
1316.85	86.839
1320.04	80.3935
1323.23	75.5895
1326.41	68.5228
1329.6	61.4287
1332.78	57.1632
1335.97	60.5822
1339.15	62.7202
1342.33	64.4611
1345.51	64.2622
1348.69	61.6028
1351.87	62.0208
1355.04	60.6616
1358.22	59.3842
1361.39	58.022
1364.57	57.5512
1367.74	55.191
1370.91	53.927
1374.07	53.572
1377.24	53.6377
1380.41	51.9611
1383.57	51.824
1386.74	52.5924
1389.9	53.6665
1393.06	54.2184
1396.22	53.941
1399.38	54.7285
1402.54	59.2736
1405.7	66.213
1408.85	76.613
1412.01	88.7336
1415.16	102.458
1418.31	113.615
1421.46	125.309
1424.61	136.718
1427.76	147.904
1430.91	160.437
1434.05	171.528
1437.2	179.993
1440.34	187.912
1443.49	193.626
1446.63	197.137
1449.77	197.528
1452.91	194.163
1456.04	189.093
1459.18	182.363
1462.31	173.409
1465.45	161.183
1468.58	147.516
1471.71	132.2
1474.84	117.918
1477.97	105.883
1481.1	95.1456
1484.23	86.1687
1487.35	73.9139
1490.48	64.7193
1493.6	56.2556
1496.72	47.4636
1499.84	39.0997
1502.96	31.7635
1506.08	28.1907
1509.2	24.9895
1512.31	21.0838
1515.43	20.0029
1518.54	20.0783
1521.66	19.5033
1524.77	18.5746
1527.88	18.4909
1530.99	19.1101
1534.09	21.323
1537.2	22.3752
1540.31	24.7081
1543.41	27.6041
1546.51	30.7055
1549.62	32.9163
1552.72	35.2635
1555.82	36.3043
1558.91	38.8989
1562.01	40.6983
1565.11	42.2546
1568.2	44.345
1571.3	45.4086
1574.39	46.3686
1577.48	48.1047
1580.57	50.3644
1583.66	52.122
1586.75	52.4729
1589.83	52.9973
1592.92	53.459
1596	54.259
1599.09	53.6073
1602.17	54.057
1605.25	55.1716
1608.33	55.8044
1611.41	56.1689
1614.48	56.9405
1617.56	57.246
1620.64	59.0054
1623.71	61.2898
1626.78	60.8223
1629.86	61.4486
1632.92	62.1204
1635.99	64.1299
1639.06	65.1016
1642.13	68.0291
1645.19	69.0095
1648.26	71.1319
1651.32	72.4582
1654.38	73.4148
1657.45	71.9565
1660.51	71.5974
1663.57	70.9206
1666.62	68.764
1669.68	67.3217
1672.73	65.3957
1675.79	60.8433
1678.84	57.6358
1681.89	53.3891
1684.94	48.7113
1687.99	43.0569
1691.04	37.6767
1694.09	34.4214
1697.14	27.9216
1700.18	23.4651
1703.22	20.1475
1706.27	18.1987
1709.31	16.9715
1712.35	15.2523
1715.39	14.1238
1718.43	12.5675
1721.46	10.9919
1724.5	10.0457
1727.53	8.87752
1730.57	8.23659
1733.6	7.267
1736.63	8.42044
1739.66	7.85454
1742.69	6.14218
1745.72	6.1405
1748.74	4.38337
1751.77	4.21463
1754.8	3.34178
1757.82	1.55665
1760.84	-0.305869
1763.86	-1.41744
1766.88	-1.73027
1769.9	-1.62068
1772.92	-1.29618
1775.93	0.487893
1778.95	1.07362
1781.96	1.63438
1784.98	1.81307
1787.99	2.83076
1791	2.3697
1794.01	2.71672
1797.02	3.04062
1800.03	3.32728
1803.03	4.12863
1806.04	4.71268
1809.04	4.03327
1812.04	4.56669
1815.05	4.43589
1818.05	4.55222
1821.05	4.28016
1824.05	4.1341
1827.04	3.45505
1830.04	2.74177
1833.03	2.76123
1836.03	2.09987
1839.02	2.60027
1842.01	1.94063
1845	1.8172
1847.99	1.44363
1850.98	0.888358
1853.97	1.41126
1856.95	1.97001
1859.94	1.99755
1862.92	1.11422
1865.91	1.26538
1868.89	2.27661
1871.87	3.90893
1874.85	3.90002
1877.83	4.81083
1880.8	5.97045
1882.56	5.76161
1885.54	5.68524
1888.53	5.64347
1891.52	5.61631
1894.5	5.0659
1897.49	4.48706
1900.47	4.76321
1903.45	4.9567
1906.43	4.84066
1909.41	4.17398
1912.39	3.98045
1915.37	3.56953
1918.35	3.20726
1921.32	1.64079
1924.3	1.94486
1927.27	0.902373
1930.24	-0.0867686
1933.21	0.123203
1936.18	-0.0756137
1939.15	1.36728
1942.12	1.25565
1945.09	1.82822
1948.05	2.822
1951.02	3.64907
1953.98	2.18363
1956.94	1.89228
1959.91	2.60149
1962.87	3.25366
1965.82	3.06105
1968.78	2.67091
1971.74	2.87282
1974.7	2.83882
1977.65	4.31394
1980.6	4.82109
1983.56	4.31808
1986.51	4.53747
1989.46	4.18083
1992.41	4.15588
1995.36	4.16446
1998.3	5.10188
2001.25	6.25145
2004.2	5.7707
2007.14	6.85905
2010.08	6.12515
2013.02	7.41396
2015.97	8.06215
2018.9	8.41105
2021.84	8.75838
2024.78	8.46131
2027.72	9.00682
2030.65	10.2296
2033.59	10.0284
2036.52	10.8418
2039.45	11.3789
2042.38	12.6198
2045.31	13.391
2048.24	13.6652
2051.17	14.1785
2054.1	14.8876
2057.02	15.8934
2059.95	16.7511
2062.87	17.9489
2065.79	19.9158
2068.71	21.0605
2071.63	22.5124
2074.55	22.1568
2077.47	24.2381
2080.39	25.9581
2083.3	27.804
2086.22	29.4049
2089.13	30.3926
2092.05	32.6133
2094.96	33.5723
2097.87	35.8794
2100.78	37.8566
2103.69	39.2002
2106.59	41.1475
2109.5	43.0808
2112.41	45.4988
2115.31	48.0307
2118.21	51.4182
2121.12	53.9914
2124.02	58.061
2126.92	61.2639
2129.82	65.5106
2132.71	69.605
2135.61	73.5386
2138.51	76.4273
2141.4	80.702
2144.29	82.9402
2147.19	87.5288
2150.08	90.8658
2152.97	93.766
2155.86	97.4129
2158.75	99.8568
2161.64	102.731
2164.52	104.323
2167.41	104.247
2170.29	106.033
2173.17	105.641
2176.06	104.298
2178.94	103.285
2181.82	102.469
2184.7	101.781
2187.57	99.8289
2190.45	97.4996
2193.33	94.742
2196.2	92.8236
2199.08	90.1409
2201.95	86.6216
2204.82	83.5256
2207.69	79.8995
2210.56	75.6326
2213.43	72.4055
2216.3	69.2361
2219.16	65.8439
2222.03	62.7759
2224.89	59.1772
2227.75	56.7155
2230.62	54.0565
2233.48	50.0769
2236.34	45.356
2239.2	42.4303
2242.06	39.9625
2244.91	36.0035
2247.77	32.9977
2250.62	31.8424
2253.48	29.3567
2256.33	28.467
2259.18	26.7939
2262.03	25.6067
2264.88	25.2288
2267.73	24.5213
2270.58	23.6929
2273.43	23.8367
2276.27	22.9158
2279.12	22.1569
2281.96	21.397
2284.8	20.4825
2287.64	19.1539
2290.49	18.1821
2293.32	15.4793
2296.16	15.3302
2299	15.3294
2301.84	14.5248
2304.67	14.4822
2307.51	14.329
2310.34	13.4524
2313.17	13.2036
2316	13.1084
2318.83	13.641
2321.66	13.6355
2324.49	13.6484
2327.32	13.4405
2330.15	12.4869
2332.97	12.6597
2335.79	12.1676
2338.62	11.4776
2341.44	11.2552
2344.26	10.3314
2347.08	10.2802
2349.9	9.817
2352.72	8.48793
2355.53	8.17558
2358.35	7.07841
2361.17	4.77435
2363.98	3.87694
2366.79	4.33125
2369.6	4.54151
2372.42	4.03997
2375.22	2.81642
2378.03	1.71629
2380.84	0.910859
2383.65	0.902328
2386.45	0.372653
2389.26	1.86026
2392.06	2.38567
2394.87	2.29831
2397.67	2.03506
2400.47	1.7522
2403.27	2.22254
2406.07	2.88767
2408.86	3.47484
2411.66	4.69448
2414.46	5.03705
2417.25	6.51603
2420.05	6.56955
2422.84	6.74477
2425.63	8.52082
2428.42	8.3415
2431.21	7.36318
2434	8.34173
2436.79	8.84314
2439.57	8.2671
2442.36	8.10337
2445.14	7.82405
2447.93	7.56478
2450.71	7.37169
2453.49	7.27237
2456.27	6.97041
2459.05	6.4105
2461.83	5.78033
2464.61	6.44293
2467.39	4.98589
2470.16	3.96136
2472.94	5.24562
2475.71	4.52051
2478.48	3.15686
2481.25	2.20602
2484.02	2.04738
2486.8	2.95721
2489.56	3.20987
2492.33	2.70478
2495.1	1.522
2497.86	0.766275
2500.63	2.06076
2503.39	1.6273
2506.16	0.784944
2508.92	1.12643
2511.68	1.43946
2514.44	1.36836
2517.2	1.46468
2519.95	1.10749
2522.71	0.813246
2525.47	1.24377
2528.22	2.24469
2530.98	2.83912
2533.73	2.93158
2536.48	2.22829
2539.23	2.35065
2541.98	2.27588
2544.73	1.99649
2547.48	2.16071
2550.23	2.45583
2552.97	2.8437
2555.72	2.34012
2558.46	1.1789
2561.2	1.02608
2563.95	1.99689
2566.69	2.6497
2569.43	3.28319
2572.17	3.30309
2574.91	3.79453
2577.64	5.12252
2580.38	6.2891
2583.11	7.79819
2585.85	8.216
2588.58	8.12364
2591.31	8.75866
2594.04	9.38747
2596.78	9.54328
2599.51	9.4674
2602.23	9.0977
2604.96	9.7694
2607.69	10.0419
2610.41	9.14051
2613.14	8.50525
2615.86	8.84762
2618.58	8.55978
2621.3	8.73353
2624.03	7.16165
2626.75	7.35181
2629.46	7.94498
2632.18	8.09981
2634.9	7.5401
2637.61	8.07498
2640.33	8.42912
2643.04	9.14324
2645.76	9.89307
2648.47	9.50077
2651.18	9.51929
2653.89	10.4242
2656.6	10.4879
2659.31	11.5572
2662.01	11.8545
2664.72	12.5166
2667.43	11.5785
2670.13	11.4292
2672.83	10.7016
2675.53	10.4057
2678.24	11.2487
2680.94	10.6278
2683.64	11.3417
2686.34	12.199
2689.03	13.6645
2691.73	14.8141
2694.43	15.7175
2697.12	18.5839
2699.81	20.9331
2702.51	23.1336
2705.2	25.7887
2707.89	29.1455
2710.58	30.5776
2713.27	32.8233
2715.96	34.244
2718.64	35.3521
2721.33	36.1101
2724.01	36.1502
2726.7	36.0887
2729.38	33.4604
2732.06	31.6148
2734.75	29.4827
2737.43	27.3211
2740.11	23.8463
2742.78	21.3221
2745.46	18.2531
2748.14	14.4816
2750.81	11.9129
2753.49	10.1826
2756.16	7.54731
2758.84	6.50772
2761.51	3.87898
2764.18	3.14439
2766.85	2.44947
2769.52	2.48154
2772.19	2.77316
2774.85	1.35085
2777.52	-0.151413
2780.18	-0.462564
2782.85	-0.258546
2785.51	-0.0768169
2788.17	-0.146292
2790.84	0.601086
2793.5	1.71824
2796.16	2.6971
2798.81	3.9637
2801.47	3.05674
2804.13	0.690003
2806.79	-1.72344
2809.44	-4.82545
2812.09	-6.93721
2814.75	-3.01054
2817.4	8.1342
2820.05	25.5003
2822.7	45.8195
2825.35	67.4454
2828	93.5447
2830.65	120.131
2833.29	146.994
2835.94	173.476
2838.58	198.563
2841.23	222.011
2843.87	243.297
2846.51	261.09
2849.15	281.466
2851.79	307.394
2854.43	337.007
2857.07	365.614
2859.71	390.432
2862.34	410.565
2864.98	424.665
2867.61	433.031
2870.25	437.194
2872.88	439.931
2875.51	442.904
2878.14	448.339
2880.77	454.28
2883.4	458.551
2886.03	457.23
2888.65	454.206
2891.28	447.873
2893.91	440.203
2896.53	428.565
2899.15	415.94
2901.78	403.11
2904.4	389.533
2907.02	377.941
2909.64	369.946
2912.26	369.265
2914.87	377.538
2917.49	387.584
2920.11	395.181
2922.72	397.749
2925.34	398.129
2927.95	397.4
2930.56	394.359
2933.17	391.159
2935.78	386.003
2938.39	379.791
2941	370.08
2943.61	358.108
2946.22	344.657
2948.82	327.964
2951.43	312.505
2954.03	296.309
2956.64	278.814
2959.24	260.759
2961.84	242.358
2964.44	225.145
2967.04	210.906
2969.64	196.352
2972.24	182.893
2974.83	169.727
2977.43	156.572
2980.02	143.702
2982.62	129.165
2985.21	115.818
2987.8	102.915
2990.4	91.9156
2992.99	82.5963
2995.57	73.2829
2998.16	64.6199
3000.75	56.4469
3003.34	48.9389
3005.92	42.333
3008.51	36.8582
3011.09	31.2922
3013.68	27.1521
3016.26	23.508
3018.84	19.0543
3021.42	13.8697
3024	10.4862
3026.58	8.57847
3029.16	7.19683
3031.73	6.45257
3034.31	5.28918
3036.89	4.38535
3039.46	3.78442
3042.03	2.4271
3044.61	1.50516
3047.18	1.7066
3049.75	2.56204
3052.32	4.1815
3054.89	5.43652
3057.45	5.93668
3060.02	7.25523
3062.59	7.77871
3065.15	8.93491
3067.72	10.0952
3070.28	9.84977
3072.84	9.61254
3075.41	8.87641
3077.97	7.95607
3080.53	6.92634
3083.09	6.12308
3085.64	5.63936
3088.2	6.16215
3090.76	6.29335
3093.31	6.79458
3095.87	7.73474
3098.42	7.62639
3100.97	8.10603
3103.53	8.39902
3106.08	10.0209
3108.63	12.1108
3111.18	14.3375
3113.73	15.9277
3116.27	17.7533
3118.82	20.4728
3121.37	23.59
3123.91	25.9759
3126.45	28.3403
3129	31.2129
3131.54	32.7858
3134.08	34.3925
3136.62	37.2492
3139.16	39.3045
3141.7	42.0785
3144.24	45.1152
3146.78	48.1863
3149.31	51.2954