File: data/Raman/poly_smoothed/Mb_40_y_27_1x_45s_532 nm_x100_100%_600 gr_mm_01.txt
#Acq. time (s)=	45
#Accumulations=	2
#Range (cm-¹)=	200...3150
#Windows=	2
#Auto scanning=	Off
#Autofocus=	Off
#Macrospot=	Off
#AutoExposure=	Off
#Spike filter=	Multiple accum.
#Delay time (s)=	0
#Binning=	1
#Readout mode=	Signal
#DeNoise=	Off
#ICS correction=	On
#Dark correction=	Off
#Inst. Process=	Off
#Detector Gain=	Best Dynamic Range
#Detector ADC=	20 kHz
#Detector temperature (°C)=	-69.85
#Instrument=	LabRAM HR Evol
#Detector=	Synapse
#Objective=	x100
#Grating=	600 gr/mm
#ND Filter=	100%
#Laser (nm)=	532
#Hole=	100.021
#Range=	Auto
#Laser Pol.=	No
#Raman. Pol.=	No
#Laser Pol. (°)=	-0.0007625
#Raman Pol. (°)=	89.9995
#Collection=	Microscope
#StageXY=	Marzhauser
#StageZ=	Marzhauser
#X (µm)=	-1075
#Y (µm)=	571.3
#Z (µm)=	584.5
#Full time(mm:ss)=	3:19
#Project=
#Sample=
#Site=
#Title=	Mb_40_y_27_2x_45s_532 nm_x100_100%_600 gr_mm
#Remark=
#Date=	19.07.2022 11:22
#Acquired=	19.07.2022 11:22:12
#Base:Fit=	10.08.2022 10:52:48
#Base:Sub=	10.08.2022 10:52:53
#Filter:Polynom=	16.08.2022 10:09:04
#AxisType[0]=Intens
#AxisUnit[0]=Cnt
#AxisType[1]=Spectr
#AxisUnit[1]=1/cm
200.423	12.5619
204.052	11.2064
207.682	8.87761
211.308	6.90734
214.935	5.59667
218.558	4.68841
222.18	1.59686
225.802	1.74273
229.421	0.293445
233.039	1.11338
236.657	2.45243
240.272	2.51885
243.885	2.57827
247.497	3.28401
251.11	3.55018
254.719	2.40564
258.327	2.90257
261.933	4.27641
265.538	4.10978
269.141	3.58076
272.744	5.02318
276.344	6.0525
279.944	7.66428
283.542	7.79742
287.138	9.65704
290.733	9.12382
294.327	10.1506
297.919	10.8882
301.508	12.228
305.098	11.9201
308.686	12.0068
312.273	13.2975
315.858	14.1312
319.44	14.9708
323.022	16.0609
326.604	14.8399
330.181	14.6202
333.76	14.1264
337.335	12.7424
340.91	11.3014
344.483	11.3589
348.055	11.0584
351.625	8.99582
355.195	8.44396
358.762	7.96845
362.329	7.70064
365.893	8.01237
369.455	7.06665
373.017	6.48402
376.578	6.38659
380.137	5.88611
383.694	6.08884
387.249	5.65564
390.806	5.09268
394.359	6.13934
397.91	7.20957
401.46	7.00352
405.009	8.10203
408.557	7.37863
412.103	6.64275
415.647	8.3309
419.191	8.62987
422.733	9.44315
426.273	10.0259
429.812	11.3008
433.35	13.0314
436.885	12.0448
440.42	12.1513
443.954	14.6925
447.486	15.2338
451.015	14.8868
454.545	14.8147
458.073	14.2859
461.598	14.8984
465.124	14.3134
468.648	14.5539
472.169	15.7197
475.69	16.1135
479.208	15.9748
482.727	16.5825
486.243	16.4305
489.759	16.0558
493.272	16.1029
496.783	17.0999
500.295	18.7509
503.804	21.1806
507.311	22.7756
510.819	23.4228
514.324	24.5867
517.827	26.0053
521.329	26.8046
524.83	26.0857
528.329	24.6124
531.829	22.8019
535.326	19.6762
538.821	17.6513
542.315	16.1905
545.808	15.0682
549.299	12.9706
552.789	11.6183
556.278	10.6778
559.763	10.7768
563.249	9.39663
566.733	7.62654
570.217	8.28827
573.699	8.88078
577.177	8.63415
580.656	9.25592
584.134	10.8703
587.609	10.9519
591.084	11.4615
594.558	12.7739
598.029	13.0755
601.5	15.0685
604.968	15.2678
608.437	14.7166
611.902	12.5579
615.368	13.0755
618.831	13.0754
622.294	11.7375
625.755	11.8885
629.213	12.1642
632.673	12.303
636.129	14.2465
639.584	16.0857
643.037	19.0033
646.491	20.7258
649.942	21.3188
653.392	22.1084
656.84	22.7683
660.287	22.4599
663.732	23.1853
667.177	25.2468
670.62	26.8845
674.061	27.2549
677.502	29.8533
680.941	31.8684
684.379	33.2882
687.815	34.6236
691.248	34.7086
694.682	36.18
698.115	37.2767
701.546	38.4319
704.974	39.3396
708.402	41.3934
711.83	43.947
715.254	45.5322
718.679	47.7261
722.102	49.3577
725.522	51.3443
728.943	52.5026
732.361	52.9609
735.779	53.5171
739.194	54.2101
742.608	53.8773
746.022	54.6248
749.433	55.8167
752.843	57.7185
756.254	59.472
759.661	61.9607
763.067	64.7422
766.471	65.8462
769.877	68.1307
773.279	69.8094
776.68	72.8448
780.079	75.2575
783.478	77.1929
786.875	79.8528
790.27	83.8611
793.665	85.1195
797.058	86.6415
800.45	86.9419
803.84	86.7608
807.23	86.218
810.616	87.2056
814.002	85.6377
817.388	85.4182
820.772	83.6287
824.153	81.5584
827.535	79.5976
830.915	78.4547
834.292	77.6576
837.67	75.9035
841.047	72.9704
844.42	70.6974
847.794	68.3607
851.165	65.5827
854.534	63.0638
857.905	62.324
861.272	60.4128
864.639	59.3482
868.004	58.5405
871.367	58.5218
874.731	56.8646
878.092	55.0869
881.451	55.2159
884.809	54.7897
888.166	53.5301
891.522	54.2244
894.878	54.1552
898.231	52.4955
901.583	53.2596
904.934	51.7585
908.283	50.8291
911.631	50.0356
914.976	49.9748
918.322	49.3319
921.666	47.3949
925.009	45.4976
928.351	43.4102
931.692	42.8697
935.029	41.644
938.367	39.7383
941.704	38.0227
945.038	38.2092
948.372	37.3983
951.705	37.6756
955.035	36.9821
958.366	36.2894
961.693	35.6311
965.021	35.6637
968.346	34.5421
971.67	35.2386
974.995	33.2576
978.316	31.2278
981.638	29.6711
984.957	26.8488
988.274	25.743
991.59	23.7447
994.907	22.0577
998.221	19.857
1001.53	16.1315
1004.85	13.9548
1008.16	15.002
1011.46	20.89
1014.77	28.3588
1018.08	36.6823
1021.38	46.4349
1024.69	56.1371
1027.99	64.2269
1031.29	70.3131
1034.59	75.6044
1037.89	78.7382
1041.19	80.6045
1044.48	82.4451
1047.78	82.5302
1051.07	80.3027
1054.36	76.7791
1057.66	71.9084
1060.94	64.9568
1064.23	57.9054
1067.52	48.919
1070.81	39.5743
1074.09	30.0698
1077.38	19.9944
1080.66	11.1785
1083.94	4.71536
1087.22	0.787699
1090.5	2.38085
1093.77	5.04325
1097.05	7.44199
1100.32	8.35223
1103.6	10.2141
1106.87	11.3231
1110.14	11.3902
1113.41	12.6179
1116.67	13.0713
1119.94	12.8497
1123.21	13.5661
1126.47	13.1196
1129.73	13.136
1133	12.561
1136.26	12.3897
1139.52	10.6634
1142.77	9.94326
1146.03	9.99738
1149.29	9.09885
1152.54	7.6541
1155.79	5.13285
1159.04	3.17271
1162.3	2.62642
1165.55	2.79059
1168.79	2.28141
1172.04	3.45502
1175.28	3.75373
1178.53	3.37145
1181.77	3.34901
1185.01	3.83445
1188.25	4.23559
1191.49	4.85668
1194.73	5.63636
1197.97	4.7152
1201.2	5.86613
1204.44	5.96954
1207.67	6.98796
1210.9	7.8893
1214.13	8.54428
1217.36	9.21101
1220.59	11.8474
1223.82	12.6827
1227.04	13.6561
1230.26	14.0167
1233.49	15.3668
1236.71	16.7696
1239.93	17.9971
1243.15	18.7641
1246.37	18.7572
1249.58	19.8401
1252.8	20.623
1256.01	19.2266
1259.23	18.8725
1262.44	18.8714
1265.65	21.1308
1268.86	22.3397
1272.07	24.571
1275.27	25.7942
1278.48	28.1156
1281.68	31.1124
1284.89	33.094
1288.09	34.8821
1291.29	35.5536
1294.49	37.3696
1297.69	37.4329
1300.88	37.4479
1304.08	38.3339
1307.27	39.2083
1310.47	40.2682
1313.66	41.2185
1316.85	41.5742
1320.04	40.8042
1323.23	40.0955
1326.41	39.1684
1329.6	37.3312
1332.78	36.0257
1335.97	35.9866
1339.15	35.9202
1342.33	35.6235
1345.51	34.8718
1348.69	34.1551
1351.87	33.3349
1355.04	32.3738
1358.22	31.1031
1361.39	28.8947
1364.57	27.7681
1367.74	26.2199
1370.91	25.1717
1374.07	23.9023
1377.24	22.2009
1380.41	21.1769
1383.57	21.0188
1386.74	21.572
1389.9	21.8985
1393.06	21.5645
1396.22	20.3271
1399.38	20.7441
1402.54	20.9891
1405.7	22.7196
1408.85	24.6682
1412.01	26.4367
1415.16	27.8306
1418.31	28.9856
1421.46	31.7901
1424.61	34.2274
1427.76	37.0234
1430.91	39.2225
1434.05	42.4996
1437.2	44.0129
1440.34	46.2329
1443.49	47.1967
1446.63	48.0273
1449.77	49.1405
1452.91	49.0086
1456.04	48.4693
1459.18	47.7189
1462.31	47.4566
1465.45	47.3904
1468.58	46.1789
1471.71	43.7766
1474.84	41.8835
1477.97	39.6828
1481.1	38.5729
1484.23	36.981
1487.35	35.6918
1490.48	32.7114
1493.6	31.0161
1496.72	29.0973
1499.84	28.2642
1502.96	25.8056
1506.08	25.5597
1509.2	24.6425
1512.31	21.9362
1515.43	19.357
1518.54	17.7211
1521.66	17.321
1524.77	16.4824
1527.88	15.0445
1530.99	15.1759
1534.09	15.0176
1537.2	15.0693
1540.31	17.1384
1543.41	18.4259
1546.51	18.9952
1549.62	19.622
1552.72	19.455
1555.82	21.5742
1558.91	22.7153
1562.01	23.6429
1565.11	24.1701
1568.2	24.4987
1571.3	25.7904
1574.39	26.8715
1577.48	27.4662
1580.57	28.4909
1583.66	28.7099
1586.75	27.7035
1589.83	28.1237
1592.92	28.5977
1596	28.2621
1599.09	27.9354
1602.17	27.6247
1605.25	27.7712
1608.33	29.4493
1611.41	30.1518
1614.48	31.1804
1617.56	31.3714
1620.64	31.709
1623.71	32.129
1626.78	32.8054
1629.86	34.7099
1632.92	35.8093
1635.99	36.7365
1639.06	37.0847
1642.13	38.2913
1645.19	39.0806
1648.26	39.1329
1651.32	38.9694
1654.38	38.5886
1657.45	37.4124
1660.51	36.9052
1663.57	34.5393
1666.62	33.5741
1669.68	30.5656
1672.73	28.7044
1675.79	25.4715
1678.84	23.9545
1681.89	22.3714
1684.94	20.5149
1687.99	18.3989
1691.04	16.6339
1694.09	14.837
1697.14	13.2357
1700.18	12.6157
1703.22	12.0428
1706.27	11.0008
1709.31	10.3221
1712.35	9.44272
1715.39	8.59374
1718.43	7.59528
1721.46	5.81075
1724.5	5.84649
1727.53	5.45414
1730.57	4.68989
1733.6	4.46422
1736.63	4.48933
1739.66	3.44262
1742.69	2.74933
1745.72	2.52478
1748.74	1.10853
1751.77	1.26866
1754.8	1.549
1757.82	1.57411
1760.84	0.457089
1763.86	0.468861
1766.88	-0.697312
1769.9	-0.290141
1772.92	-0.647154
1775.93	0.654545
1778.95	1.10534
1781.96	0.207243
1784.98	0.358314
1787.99	0.405805
1791	0.664062
1794.01	1.35968
1797.02	2.90163
1800.03	3.76584
1803.03	4.33878
1806.04	5.39686
1809.04	6.06021
1812.04	6.97349
1815.05	7.53016
1818.05	7.86758
1821.05	8.63234
1824.05	9.2475
1827.04	9.22089
1830.04	8.38092
1833.03	8.16835
1836.03	7.45364
1839.02	6.64347
1842.01	6.29477
1845	6.06471
1847.99	5.94964
1850.98	5.44286
1853.97	4.00821
1856.95	3.56305
1859.94	3.49243
1862.92	2.95072
1865.91	2.41803
1868.89	2.35863
1871.87	2.69745
1874.85	2.44912
1877.83	3.17703
1880.8	3.97503
1882.56	3.80822
1885.54	4.50402
1888.53	4.22597
1891.52	5.07841
1894.5	5.50634
1897.49	5.43201
1900.47	4.5456
1903.45	4.65476
1906.43	4.78868
1909.41	5.08268
1912.39	5.59419
1915.37	6.39524
1918.35	6.22324
1921.32	5.63679
1924.3	4.05819
1927.27	4.76506
1930.24	3.68282
1933.21	2.34691
1936.18	2.34593
1939.15	1.56419
1942.12	2.09629
1945.09	2.22228
1948.05	3.10034
1951.02	2.53098
1953.98	2.72836
1956.94	2.50993
1959.91	2.73838
1962.87	3.28932
1965.82	2.89911
1968.78	2.64412
1971.74	1.79258
1974.7	2.16865
1977.65	3.07182
1980.6	3.58443
1983.56	4.04542
1986.51	4.9296
1989.46	4.35451
1992.41	3.28609
1995.36	3.38731
1998.3	3.03467
2001.25	3.99915
2004.2	3.6309
2007.14	3.94952
2010.08	4.93215
2013.02	5.95337
2015.97	5.63922
2018.9	5.95913
2021.84	6.48855
2024.78	6.68198
2027.72	6.71447
2030.65	6.63019
2033.59	6.44298
2036.52	5.92726
2039.45	5.72638
2042.38	6.08892
2045.31	6.89269
2048.24	6.78001
2051.17	7.24016
2054.1	6.84946
2057.02	7.0611
2059.95	7.39361
2062.87	7.61881
2065.79	8.49065
2068.71	9.92758
2071.63	9.67521
2074.55	11.0831
2077.47	11.2904
2080.39	12.0548
2083.3	13.4009
2086.22	13.8574
2089.13	14.4549
2092.05	16.0026
2094.96	16.912
2097.87	17.9714
2100.78	18.3283
2103.69	20.032
2106.59	21.2135
2109.5	22.3955
2112.41	22.5413
2115.31	24.1401
2118.21	24.8794
2121.12	26.2327
2124.02	28.0849
2126.92	29.4908
2129.82	31.4646
2132.71	33.1766
2135.61	35.0064
2138.51	36.6489
2141.4	38.5303
2144.29	40.8135
2147.19	42.3702
2150.08	43.9864
2152.97	46.0396
2155.86	48.2941
2158.75	49.6514
2161.64	51.7186
2164.52	53.7168
2167.41	54.8771
2170.29	55.1088
2173.17	55.4986
2176.06	55.3695
2178.94	54.1078
2181.82	53.6168
2184.7	53.5435
2187.57	52.6555
2190.45	51.4746
2193.33	50.4632
2196.2	47.7201
2199.08	46.1932
2201.95	45.6611
2204.82	44.123
2207.69	43.0289
2210.56	41.2988
2213.43	38.9438
2216.3	36.2923
2219.16	34.9572
2222.03	34.2363
2224.89	33.4061
2227.75	32.1687
2230.62	31.1589
2233.48	29.2251
2236.34	27.5222
2239.2	25.3286
2242.06	23.1163
2244.91	21.7204
2247.77	20.5392
2250.62	19.6237
2253.48	19.3361
2256.33	18.047
2259.18	16.1294
2262.03	14.8564
2264.88	14.8212
2267.73	15.7229
2270.58	15.9864
2273.43	16.6504
2276.27	15.4513
2279.12	15.0958
2281.96	13.4523
2284.8	12.204
2287.64	11.6213
2290.49	11.3913
2293.32	10.4965
2296.16	9.51166
2299	9.59634
2301.84	10.1979
2304.67	10.339
2307.51	10.8589
2310.34	10.7885
2313.17	10.847
2316	11.3174
2318.83	12.321
2321.66	13.0046
2324.49	13.0579
2327.32	13.4304
2330.15	14.1457
2332.97	13.8314
2335.79	13.1449
2338.62	12.716
2341.44	12.7563
2344.26	11.3652
2347.08	10.0228
2349.9	8.72269
2352.72	7.57063
2355.53	5.61224
2358.35	4.3128
2361.17	2.88717
2363.98	2.42373
2366.79	2.31365
2369.6	2.17591
2372.42	2.44373
2375.22	1.84653
2378.03	1.84314
2380.84	2.01236
2383.65	3.19199
2386.45	3.96671
2389.26	3.9611
2392.06	4.85081
2394.87	5.35297
2397.67	6.03995
2400.47	5.86449
2403.27	5.86865
2406.07	6.43581
2408.86	6.66512
2411.66	7.15967
2414.46	7.88737
2417.25	8.03983
2420.05	8.74203
2422.84	7.97245
2425.63	6.90738
2428.42	6.22521
2431.21	6.31182
2434	5.79568
2436.79	4.66673
2439.57	5.14361
2442.36	5.02429
2445.14	5.61989
2447.93	5.51432
2450.71	5.96419
2453.49	5.73756
2456.27	5.79107
2459.05	5.73523
2461.83	5.76706
2464.61	5.19624
2467.39	4.65687
2470.16	4.36803
2472.94	3.39568
2475.71	3.1442
2478.48	3.06607
2481.25	3.24634
2484.02	3.18494
2486.8	3.11548
2489.56	3.48638
2492.33	2.67899
2495.1	1.33813
2497.86	1.74029
2500.63	1.81131
2503.39	1.73674
2506.16	1.0816
2508.92	0.598961
2511.68	1.35655
2514.44	1.12976
2517.2	0.847951
2519.95	0.679197
2522.71	0.441261
2525.47	0.193623
2528.22	0.371111
2530.98	0.590347
2533.73	-0.441011
2536.48	-0.251816
2539.23	0.515274
2541.98	1.59204
2544.73	1.71758
2547.48	2.19749
2550.23	2.9457
2552.97	3.82461
2555.72	5.26169
2558.46	7.03694
2561.2	6.53877
2563.95	6.80288
2566.69	7.61423
2569.43	7.48565
2572.17	6.86532
2574.91	7.27394
2577.64	7.50654
2580.38	6.67449
2583.11	5.70032
2585.85	5.94026
2588.58	5.79775
2591.31	5.12506
2594.04	5.20005
2596.78	4.70076
2599.51	4.96893
2602.23	4.2327
2604.96	4.89863
2607.69	4.73161
2610.41	2.79409
2613.14	2.81182
2615.86	3.3381
2618.58	3.56536
2621.3	4.1735
2624.03	4.6067
2626.75	3.87122
2629.46	3.12056
2632.18	2.98041
2634.9	2.63245
2637.61	3.07241
2640.33	3.31998
2643.04	3.73675
2645.76	3.63461
2648.47	3.24498
2651.18	3.74108
2653.89	3.66463
2656.6	4.01477
2659.31	4.88244
2662.01	4.71293
2664.72	5.30209
2667.43	5.84986
2670.13	5.60612
2672.83	5.50895
2675.53	5.99942
2678.24	6.17366
2680.94	6.15003
2683.64	5.4515
2686.34	5.17129
2689.03	5.49917
2691.73	5.27971
2694.43	4.5027
2697.12	5.39526
2699.81	5.06156
2702.51	5.52471
2705.2	5.80701
2707.89	5.98461
2710.58	6.28695
2713.27	6.03405
2715.96	6.62884
2718.64	7.70179
2721.33	8.87027
2724.01	8.91376
2726.7	9.53237
2729.38	8.78076
2732.06	9.28298
2734.75	8.68206
2737.43	7.7113
2740.11	7.80983
2742.78	6.86624
2745.46	5.66947
2748.14	4.55411
2750.81	4.18409
2753.49	3.40657
2756.16	2.64008
2758.84	1.72847
2761.51	1.4478
2764.18	1.90453
2766.85	1.04497
2769.52	0.303699
2772.19	0.797659
2774.85	1.53555
2777.52	1.17023
2780.18	1.21795
2782.85	1.95099
2785.51	2.27166
2788.17	2.4082
2790.84	2.10542
2793.5	1.81435
2796.16	1.84901
2798.81	1.36461
2801.47	1.60747
2804.13	1.32202
2806.79	0.691724
2809.44	-0.107812
2812.09	-0.177176
2814.75	0.436044
2817.4	1.11096
2820.05	1.6287
2822.7	3.65807
2825.35	5.79588
2828	8.53243
2830.65	11.174
2833.29	13.9043
2835.94	17.0942
2838.58	19.8451
2841.23	23.0525
2843.87	26.2344
2846.51	30.3708
2849.15	34.296
2851.79	37.8899
2854.43	42.3636
2857.07	46.5583
2859.71	50.8881
2862.34	54.2356
2864.98	57.7587
2867.61	60.5183
2870.25	62.7712
2872.88	64.5384
2875.51	67.1615
2878.14	69.5868
2880.77	71.4317
2883.4	73.5409
2886.03	75.4313
2888.65	77.7576
2891.28	79.5748
2893.91	81.4751
2896.53	84.2832
2899.15	87.6561
2901.78	89.6742
2904.4	92.8821
2907.02	97.089
2909.64	100.896
2912.26	105.885
2914.87	111.393
2917.49	116.408
2920.11	121.417
2922.72	125.697
2925.34	129.005
2927.95	131.749
2930.56	133.794
2933.17	134.346
2935.78	133.616
2938.39	133.135
2941	131.226
2943.61	128.202
2946.22	124.412
2948.82	119.694
2951.43	115.254
2954.03	110.075
2956.64	105.07
2959.24	100.773
2961.84	94.9039
2964.44	89.2157
2967.04	83.5993
2969.64	78.8831
2972.24	73.9159
2974.83	69.7556
2977.43	65.4587
2980.02	61.0822
2982.62	57.5298
2985.21	53.3254
2987.8	48.6548
2990.4	44.2902
2992.99	40.2834
2995.57	36.3724
2998.16	32.7021
3000.75	29.4644
3003.34	26.1593
3005.92	23.0407
3008.51	19.7075
3011.09	16.9684
3013.68	15.0944
3016.26	12.6451
3018.84	10.4304
3021.42	8.4185
3024	6.46497
3026.58	4.71391
3029.16	2.88574
3031.73	2.34654
3034.31	1.81576
3036.89	1.27151
3039.46	1.32511
3042.03	1.81514
3044.61	2.79542
3047.18	3.70999
3049.75	3.78969
3052.32	4.21716
3054.89	4.77966
3057.45	5.18603
3060.02	5.39092
3062.59	5.61741
3065.15	6.35536
3067.72	6.57293
3070.28	7.07897
3072.84	6.79146
3075.41	6.3181
3077.97	5.33454
3080.53	4.09991
3083.09	3.62651
3085.64	2.92145
3088.2	3.095
3090.76	2.79511
3093.31	2.62331
3095.87	2.72031
3098.42	3.56016
3100.97	3.78086
3103.53	4.5826
3106.08	6.03425
3108.63	6.92336
3111.18	7.08867
3113.73	7.97337
3116.27	8.84127
3118.82	9.72391
3121.37	10.9516
3123.91	12.3311
3126.45	13.2685
3129	13.4703
3131.54	14.7292
3134.08	15.2592
3136.62	15.7711
3139.16	16.5724
3141.7	17.547
3144.24	18.6653
3146.78	19.5891
3149.31	20.3726