File: data/Raman/poly_smoothed/Mb_40_24_13_1x_45s_532 nm_x100_100%_600 gr_mm_01.txt
#Acq. time (s)=	45
#Accumulations=	2
#Range (cm-¹)=	200...3150
#Windows=	2
#Auto scanning=	Off
#Autofocus=	Off
#Macrospot=	Off
#AutoExposure=	Off
#Spike filter=	Multiple accum.
#Delay time (s)=	0
#Binning=	1
#Readout mode=	Signal
#DeNoise=	Off
#ICS correction=	On
#Dark correction=	Off
#Inst. Process=	Off
#Detector Gain=	Best Dynamic Range
#Detector ADC=	20 kHz
#Detector temperature (°C)=	-70.08
#Instrument=	LabRAM HR Evol
#Detector=	Synapse
#Objective=	x100
#Grating=	600 gr/mm
#ND Filter=	100%
#Laser (nm)=	532
#Hole=	100.021
#Range=	Auto
#Laser Pol.=	No
#Raman. Pol.=	No
#Laser Pol. (°)=	-0.0007625
#Raman Pol. (°)=	89.9995
#Collection=	Microscope
#StageXY=	Marzhauser
#StageZ=	Marzhauser
#X (µm)=	-2558
#Y (µm)=	-86.2
#Z (µm)=	-10.7
#Full time(mm:ss)=	3:18
#Project=
#Sample=
#Site=
#Title=	Mb_40_24_13_2x_45s_532 nm_x100_100%_600 gr_mm
#Remark=
#Date=	14.07.2022 11:38
#Acquired=	14.07.2022 11:38:36
#Edit:Spike=	14.07.2022 11:41:56
#Edit:Spike=	14.07.2022 11:41:58
#Base:Fit=	10.08.2022 10:47:00
#Base:Sub=	10.08.2022 10:47:12
#Filter:Polynom=	16.08.2022 10:11:48
#AxisType[0]=Intens
#AxisUnit[0]=Cnt
#AxisType[1]=Spectr
#AxisUnit[1]=1/cm
200.554	37.3067
204.183	40.6089
207.813	38.9273
211.439	35.3143
215.065	30.0829
218.688	26.4256
222.312	23.1246
225.933	21.1201
229.552	17.9673
233.171	15.7337
236.787	14.6497
240.402	11.9267
244.015	10.8141
247.627	9.53382
251.24	7.67441
254.849	7.58512
258.457	7.8229
262.063	7.77515
265.668	8.65891
269.271	11.3557
272.873	12.8388
276.474	13.4917
280.073	14.9406
283.671	13.4872
287.268	11.9133
290.863	10.1268
294.456	9.62138
298.049	9.86325
301.637	7.92327
305.227	9.58887
308.815	9.99735
312.402	10.2744
315.987	9.45215
319.569	10.1518
323.151	11.3521
326.733	11.498
330.31	10.5938
333.889	14.1779
337.464	14.2542
341.039	15.0449
344.611	14.947
348.184	14.7078
351.754	12.9611
355.324	13.0682
358.89	12.9394
362.455	11.107
366.021	10.6563
369.584	9.39643
373.145	6.76431
376.707	6.83509
380.265	7.08693
383.822	9.27292
387.378	9.46183
390.934	9.9474
394.487	11.8414
398.038	11.6364
401.588	12.3164
405.137	14.0619
408.685	13.6236
412.23	13.5656
415.775	12.6175
419.318	14.4219
422.86	14.9317
426.401	11.7084
429.94	11.6232
433.478	10.0141
437.012	8.32818
440.547	6.49648
444.081	7.16479
447.613	7.82399
451.142	6.60184
454.672	7.83792
458.2	6.81772
461.725	7.74002
465.251	8.855
468.775	10.7523
472.296	12.8547
475.817	16.2437
479.335	18.0435
482.854	22.1193
486.37	25.7181
489.886	27.1575
493.398	29.1007
496.91	32.2102
500.422	34.9178
503.93	38.503
507.438	40.22
510.946	42.4834
514.45	44.3753
517.954	46.7031
521.456	45.9725
524.956	47.919
528.456	49.2646
531.956	49.3945
535.452	48.3155
538.947	47.3301
542.441	46.6818
545.934	42.5107
549.425	39.1225
552.915	35.55
556.403	34.889
559.889	31.1679
563.375	29.7348
566.859	26.2749
570.342	23.4936
573.824	19.245
577.303	14.9108
580.782	13.2353
584.26	11.5449
587.734	8.94313
591.21	9.93768
594.684	10.4615
598.154	11.5669
601.626	11.7079
605.094	11.9874
608.562	11.8173
612.027	13.7671
615.493	15.8135
618.956	17.1413
622.419	19.4401
625.879	21.1245
629.338	21.2943
632.797	22.5468
636.254	23.1791
639.708	22.0848
643.162	23.4284
646.614	22.7102
650.067	21.6695
653.516	18.5036
656.964	15.9384
660.411	12.3168
663.857	9.66472
667.301	7.77793
670.744	7.87325
674.186	6.57929
677.626	5.97574
681.065	7.04383
684.503	5.19226
687.939	3.66037
691.372	2.114
694.806	0.996684
698.239	1.51763
701.67	2.38297
705.098	5.0558
708.526	7.97824
711.954	10.6454
715.378	12.5547
718.802	14.7001
722.226	16.4977
725.646	17.3422
729.067	17.3684
732.484	17.3605
735.902	17.9119
739.317	17.6598
742.731	18.567
746.145	19.3689
749.556	22.2558
752.966	25.1936
756.377	27.611
759.784	30.6666
763.19	33.4908
766.594	35.2636
770	35.063
773.402	36.8944
776.803	38.4883
780.202	38.4587
783.6	41.3787
786.997	45.1791
790.393	46.3223
793.787	47.7836
797.18	46.8921
800.572	47.2126
803.963	47.4621
807.35	47.2428
810.738	47.0221
814.125	46.3694
817.51	47.143
820.894	48.422
824.275	51.156
827.657	54.8455
831.037	57.2585
834.414	58.4826
837.792	60.9004
841.167	62.8082
844.542	62.9733
847.914	62.9355
851.287	62.1474
854.656	59.422
858.026	57.5285
861.393	55.0229
864.761	52.2937
868.125	49.9826
871.489	45.6379
874.85	39.7745
878.213	36.8386
881.572	34.5209
884.931	31.6709
888.287	28.4364
891.643	26.2006
894.997	24.1759
898.352	25.0805
901.704	26.826
905.055	29.0048
908.404	31.0342
911.75	32.5384
915.097	34.6889
918.443	33.6026
921.787	34.2351
925.13	35.5545
928.472	34.9384
931.813	33.041
935.15	30.312
938.488	28.3534
941.825	27.8736
945.158	24.5119
948.493	22.6804
951.824	20.9736
955.156	15.8062
958.486	15.6038
961.814	14.1951
965.142	14.6278
968.467	15.2776
971.79	18.0506
975.115	21.2223
978.436	21.2453
981.756	22.3322
985.077	22.7587
988.394	22.8295
991.71	23.5889
995.025	22.4917
998.341	19.424
1001.65	19.019
1004.97	18.5137
1008.28	19.319
1011.58	23.006
1014.89	28.2387
1018.2	34.4757
1021.5	41.0585
1024.81	47.6076
1028.11	53.7984
1031.41	60.3092
1034.71	63.5529
1038.01	67.5204
1041.31	72.2092
1044.6	77.9276
1047.9	81.5815
1051.19	84.1222
1054.48	82.7522
1057.77	80.9113
1061.06	78.3666
1064.35	74.318
1067.64	68.8668
1070.93	61.2947
1074.21	54.7983
1077.49	47.9347
1080.78	41.482
1084.06	37.2707
1087.34	35.3958
1090.61	35.682
1093.89	37.4838
1097.17	37.7638
1100.44	39.2754
1103.71	38.9709
1106.99	39.8362
1110.26	37.2521
1113.52	35.1433
1116.79	33.7797
1120.06	30.8448
1123.32	29.9348
1126.59	29.1854
1129.85	27.9465
1133.11	24.8285
1136.37	21.872
1139.63	19.626
1142.89	16.5824
1146.15	13.9431
1149.4	11.5921
1152.66	8.7083
1155.91	7.03243
1159.16	6.06177
1162.41	5.11507
1165.66	5.14368
1168.91	4.69387
1172.16	4.93054
1175.4	6.29588
1178.65	6.26709
1181.89	6.28471
1185.13	7.54493
1188.37	7.44678
1191.61	7.9024
1194.85	10.4141
1198.08	12.954
1201.32	17.5583
1204.55	21.1981
1207.79	24.7928
1211.02	28.6506
1214.25	32.9002
1217.48	38.2284
1220.71	45.8467
1223.93	52.2538
1227.16	58.5877
1230.38	64.3895
1233.6	69.8972
1236.83	75.2673
1240.05	80.5849
1243.26	87.582
1246.48	90.9918
1249.7	95.0818
1252.92	99.6323
1256.13	104.997
1259.34	108.544
1262.55	114.257
1265.76	119.106
1268.97	124.041
1272.18	130.74
1275.39	136.292
1278.59	144.03
1281.8	147.83
1285	151.896
1288.2	155.944
1291.4	161.227
1294.6	164.517
1297.8	167.621
1301	169.554
1304.19	169.813
1307.39	167.923
1310.58	166.791
1313.77	164.274
1316.96	160.416
1320.15	159.415
1323.34	155.377
1326.53	150.252
1329.72	147.495
1332.9	144.848
1336.08	141.624
1339.27	138.482
1342.45	136.019
1345.63	133.311
1348.8	132.57
1351.98	131.043
1355.16	131.993
1358.33	133.092
1361.51	133.749
1364.68	134.573
1367.85	135.428
1371.02	138.309
1374.19	140.353
1377.36	141.059
1380.52	143.877
1383.69	147.376
1386.85	151.263
1390.02	154.679
1393.18	157.134
1396.34	160.925
1399.5	165.486
1402.65	169.274
1405.81	176.01
1408.97	182.274
1412.12	190.383
1415.27	197.696
1418.43	210.071
1421.58	222.662
1424.73	234.938
1427.87	246.704
1431.02	257.529
1434.17	268.624
1437.31	276.482
1440.46	281.219
1443.6	284.876
1446.74	284.841
1449.88	282.956
1453.02	276.321
1456.16	268.98
1459.29	258.612
1462.43	246.103
1465.56	230.659
1468.69	214.977
1471.83	199.117
1474.95	182.941
1478.08	166.264
1481.21	150.656
1484.34	137.268
1487.47	126.149
1490.59	116.598
1493.71	108.673
1496.84	102.433
1499.96	97.2634
1503.07	91.6601
1506.19	89.8474
1509.31	90.0318
1512.43	88.7121
1515.54	87.5702
1518.65	88.7865
1521.77	88.1609
1524.88	88.7618
1527.99	89.3454
1531.1	90.8455
1534.21	92.1333
1537.31	93.2559
1540.42	98.8127
1543.52	102.539
1546.63	106.269
1549.73	107.617
1552.83	109.254
1555.93	112.288
1559.03	116.399
1562.12	120.878
1565.22	124.888
1568.31	128.9
1571.41	132.412
1574.5	137.824
1577.59	145.438
1580.68	151.237
1583.77	158.243
1586.86	164.102
1589.95	168.562
1593.03	174.756
1596.11	179.608
1599.2	183.099
1602.28	185.803
1605.36	187.066
1608.44	187.943
1611.52	190.086
1614.6	190.087
1617.67	190.412
1620.75	190.241
1623.82	189.023
1626.89	187.956
1629.96	188.5
1633.04	190.21
1636.11	190.76
1639.17	191.777
1642.24	192.614
1645.31	193.638
1648.37	194.391
1651.43	195.834
1654.5	195.701
1657.56	192.176
1660.62	187.649
1663.67	186.656
1666.73	181.282
1669.79	176.462
1672.84	169.527
1675.9	161.593
1678.95	151.068
1682	141.818
1685.05	134.677
1688.1	126.855
1691.15	118.515
1694.2	111.838
1697.25	104.534
1700.29	97.4782
1703.33	91.37
1706.38	86.3641
1709.42	83.2874
1712.46	79.9365
1715.5	75.7201
1718.54	73.9654
1721.57	72.9171
1724.61	70.7135
1727.64	69.74
1730.68	67.4968
1733.71	65.2624
1736.74	65.0105
1739.77	64.9905
1742.8	62.8363
1745.83	62.6774
1748.85	59.2709
1751.88	56.3876
1754.91	55.9575
1757.93	55.3586
1760.95	55.3627
1763.97	53.3532
1766.99	51.8172
1770.01	49.9163
1773.03	48.1343
1776.04	46.8499
1779.06	45.3801
1782.07	45.4814
1785.09	44.4729
1788.1	43.6983
1791.11	43.2135
1794.12	43.0441
1797.13	40.4874
1800.13	40.3241
1803.14	39.9781
1806.15	39.2497
1809.15	39.2705
1812.15	36.8408
1815.16	36.567
1818.15	36.2927
1821.16	35.0989
1824.15	35.3187
1827.15	35.3683
1830.15	36.3449
1833.14	35.1945
1836.14	34.1269
1839.13	33.6283
1842.12	32.4049
1845.11	31.3598
1848.1	30.9387
1851.09	28.4261
1854.08	26.8323
1857.06	24.8418
1860.05	22.2112
1863.03	21.4902
1866.01	19.5989
1869	18.819
1871.98	18.2727
1874.96	18.392
1877.93	18.0353
1880.91	18.5318
1882.47	18.0934
1885.46	17.0383
1888.44	19.8943
1891.43	21.3862
1894.42	22.2978
1897.4	23.3634
1900.39	23.3027
1903.37	24.0066
1906.35	23.3197
1909.33	23.2034
1912.31	22.8459
1915.29	21.5283
1918.26	19.8276
1921.24	16.8023
1924.21	15.6354
1927.19	14.8075
1930.16	14.2813
1933.13	12.9138
1936.1	11.725
1939.07	11.2491
1942.04	10.7956
1945	11.4896
1947.97	9.64593
1950.93	9.92618
1953.9	9.29671
1956.86	7.64612
1959.82	8.21659
1962.78	9.02294
1965.74	7.94143
1968.7	6.4674
1971.65	5.84268
1974.61	5.60181
1977.57	4.92834
1980.52	2.69847
1983.47	2.29295
1986.42	1.16809
1989.37	1.09283
1992.32	0.190537
1995.27	1.26106
1998.22	1.52325
2001.17	2.09496
2004.11	2.28314
2007.05	2.33429
2010	3.24294
2012.94	3.94526
2015.88	4.30258
2018.82	3.83219
2021.76	2.06369
2024.7	2.28501
2027.63	2.67294
2030.57	2.60605
2033.5	2.66326
2036.44	2.16844
2039.37	2.32477
2042.3	1.97084
2045.23	1.29817
2048.16	0.35704
2051.08	0.0274191
2054.01	0.327471
2056.94	1.99729
2059.86	1.99468
2062.79	2.3288
2065.71	2.76772
2068.63	3.78291
2071.55	5.42342
2074.47	7.43259
2077.39	10.0927
2080.31	11.4055
2083.22	12.1262
2086.13	13.2347
2089.05	14.874
2091.96	16.3398
2094.87	19.1111
2097.78	23.0694
2100.69	25.1459
2103.6	27.3645
2106.51	31.0681
2109.42	34.529
2112.32	37.134
2115.23	39.2186
2118.13	42.0455
2121.03	45.1851
2123.93	48.6683
2126.83	52.1633
2129.73	55.5572
2132.63	60.4293
2135.53	64.9365
2138.42	70.0234
2141.32	73.6347
2144.21	79.0493
2147.1	82.9266
2150	86.1978
2152.89	88.8411
2155.78	91.6672
2158.66	94.1518
2161.55	96.5224
2164.44	99.1063
2167.32	100.387
2170.21	101
2173.09	102.358
2175.97	101.912
2178.85	100.454
2181.73	99.1614
2184.61	95.9936
2187.49	92.8405
2190.37	90.4149
2193.24	86.9957
2196.12	83.7205
2198.99	81.6206
2201.87	79.1039
2204.74	76.3258
2207.61	73.0331
2210.48	67.8257
2213.35	62.8195
2216.21	59.1455
2219.08	55.4399
2221.95	53.0731
2224.81	48.8955
2227.67	46.3765
2230.54	43.0882
2233.4	39.2331
2236.26	37.2371
2239.11	33.2056
2241.97	30.4518
2244.83	27.7912
2247.69	26.4485
2250.54	23.9136
2253.4	22.6223
2256.25	22.808
2259.1	23.4225
2261.95	21.6486
2264.8	21.7642
2267.65	23.2315
2270.5	23.813
2273.34	23.1819
2276.19	22.9678
2279.03	21.6314
2281.88	20.3506
2284.72	20.2446
2287.56	21.0624
2290.4	20.262
2293.24	18.1647
2296.08	17.3277
2298.92	17.9377
2301.76	17.3175
2304.59	16.7134
2307.43	14.9798
2310.26	13.8649
2313.09	12.497
2315.92	12.6324
2318.75	11.6433
2321.58	11.9254
2324.41	10.9519
2327.24	9.29604
2330.06	7.62314
2332.89	6.41594
2335.71	6.44431
2338.54	5.14426
2341.36	4.25707
2344.18	2.81307
2347	1.11624
2349.82	0.535699
2352.64	-0.845984
2355.45	-0.685474
2358.27	-1.10138
2361.08	-1.39886
2363.9	-0.555065
2366.71	0.996416
2369.52	1.55809
2372.33	1.56097
2375.14	1.21581
2377.95	2.20063
2380.76	3.36302
2383.57	4.38184
2386.37	5.9917
2389.18	7.23953
2391.98	8.46214
2394.79	9.12155
2397.59	9.10586
2400.39	9.91335
2403.19	11.0512
2405.99	11.5771
2408.78	13.3815
2411.58	13.3578
2414.38	14.0842
2417.17	14.5177
2419.97	14.4736
2422.76	14.7913
2425.55	14.567
2428.34	14.0602
2431.13	12.9722
2433.92	12.8225
2436.71	10.8588
2439.49	10.9343
2442.28	9.13661
2445.06	8.50113
2447.85	7.64274
2450.63	8.44202
2453.41	7.4102
2456.19	7.55458
2458.97	6.73328
2461.75	6.55643
2464.53	5.4624
2467.31	5.46255
2470.08	6.39933
2472.86	5.539
2475.63	6.34403
2478.4	6.05286
2481.17	5.80938
2483.94	6.52057
2486.72	5.96898
2489.48	7.32211
2492.25	7.35962
2495.02	6.59551
2497.79	6.53763
2500.55	7.18563
2503.31	5.81119
2506.08	5.25517
2508.84	4.70852
2511.6	4.29779
2514.36	4.99599
2517.12	4.89933
2519.88	5.21855
2522.63	5.13129
2525.39	5.02686
2528.14	4.6713
2530.9	5.0359
2533.65	4.30108
2536.4	3.57812
2539.15	3.18398
2541.9	3.24696
2544.65	3.40022
2547.4	4.29408
2550.15	4.2017
2552.89	5.6326
2555.64	6.09598
2558.38	6.45281
2561.12	5.27947
2563.87	5.36358
2566.61	4.7187
2569.35	5.11555
2572.09	5.20291
2574.83	4.78212
2577.56	5.42191
2580.3	5.63544
2583.04	4.85183
2585.77	4.63279
2588.5	3.0006
2591.23	3.67233
2593.97	2.47859
2596.7	1.28368
2599.43	0.54465
2602.15	0.376504
2604.88	0.86487
2607.61	1.15882
2610.33	0.549275
2613.06	0.478683
2615.78	0.0848901
2618.51	-0.0143242
2621.23	0.158611
2623.95	-0.10276
2626.67	-0.676459
2629.39	-0.43218
2632.1	-0.635701
2634.82	-0.00153314
2637.54	-0.0831419
2640.25	-0.651266
2642.97	-0.270026
2645.68	0.63007
2648.39	0.215116
2651.1	0.547593
2653.81	1.09369
2656.52	1.41927
2659.23	1.98923
2661.94	2.31959
2664.64	2.89142
2667.35	3.24765
2670.05	2.74782
2672.76	1.79496
2675.46	1.17429
2678.16	2.1003
2680.86	2.77375
2683.56	2.60094
2686.26	3.29457
2688.96	4.61167
2691.65	4.97875
2694.35	7.69683
2697.04	8.06618
2699.74	8.65155
2702.43	9.63335
2705.12	11.1048
2707.81	14.1156
2710.5	15.664
2713.19	16.1834
2715.88	17.5286
2718.57	17.2371
2721.25	18.097
2723.94	19.3863
2726.62	19.4171
2729.3	18.8988
2731.99	18.0996
2734.67	16.0454
2737.35	14.493
2740.03	12.7281
2742.71	10.2494
2745.38	9.25923
2748.06	7.32181
2750.74	6.6083
2753.41	6.72228
2756.09	5.52588
2758.76	4.74459
2761.43	3.41588
2764.1	2.30239
2766.77	1.43056
2769.44	0.129627
2772.11	1.35855
2774.77	0.984486
2777.44	0.614385
2780.11	0.695321
2782.77	1.5207
2785.43	2.20662
2788.1	2.98716
2790.76	4.80833
2793.42	4.72063
2796.08	4.53233
2798.74	4.60324
2801.4	3.10051
2804.05	2.20175
2806.71	-0.215749
2809.36	-0.370856
2812.02	-0.740867
2814.67	0.0653406
2817.32	4.32376
2819.97	10.0819
2822.62	18.245
2825.27	28.8314
2827.92	42.0401
2830.57	57.0679
2833.22	72.9986
2835.86	90.3566
2838.51	108.363
2841.15	128.366
2843.79	147.271
2846.43	168.393
2849.08	189.494
2851.72	211.491
2854.36	233.611
2856.99	254.944
2859.63	274.906
2862.27	293.954
2864.9	308.843
2867.54	324.825
2870.17	338.045
2872.8	350.133
2875.43	362.593
2878.07	373.622
2880.7	387.136
2883.32	400.146
2885.95	412.655
2888.58	425.084
2891.21	438.324
2893.83	451.161
2896.46	463.493
2899.08	475.236
2901.7	489.928
2904.32	505.619
2906.94	521.924
2909.56	540.958
2912.18	560.079
2914.8	579.635
2917.42	598.064
2920.03	614.044
2922.65	625.6
2925.26	634.314
2927.88	637.621
2930.49	637.045
2933.1	632.624
2935.71	622.276
2938.32	608.638
2940.93	588.821
2943.54	567.95
2946.14	545.111
2948.75	517.587
2951.35	487.947
2953.96	460.617
2956.56	431.982
2959.16	403.442
2961.77	376.48
2964.37	353.38
2966.96	332.896
2969.56	312.431
2972.16	294.404
2974.76	277.219
2977.35	261.083
2979.95	246.454
2982.54	232.002
2985.14	215.496
2987.73	198.353
2990.32	182.486
2992.91	164.744
2995.5	146.894
2998.09	129.431
3000.68	114.491
3003.26	97.6954
3005.85	82.5979
3008.43	68.032
3011.02	55.0959
3013.6	43.4754
3016.19	33.351
3018.77	25.1409
3021.35	17.0769
3023.93	11.8041
3026.5	6.89324
3029.08	4.42704
3031.66	1.92367
3034.24	1.65367
3036.81	1.56349
3039.39	2.65139
3041.96	4.47148
3044.53	6.13596
3047.1	6.68501
3049.67	7.10178
3052.24	9.9379
3054.81	10.7662
3057.38	9.43754
3059.95	9.42444
3062.52	10.6664
3065.08	10.0058
3067.65	9.74749
3070.21	10.2473
3072.77	9.65879
3075.33	7.72628
3077.89	7.35957
3080.45	5.67547
3083.01	4.21544
3085.57	3.43768
3088.13	3.00958
3090.68	3.15075
3093.24	2.79751
3095.79	2.00272
3098.35	2.29612
3100.9	3.35103
3103.45	4.51251
3106	5.04724
3108.55	5.89646
3111.1	7.33302
3113.65	9.47916
3116.2	12.3834
3118.75	13.2089
3121.29	15.103
3123.84	18.2616
3126.38	21.9507
3128.92	25.1419
3131.47	29.0688
3134.01	31.4948
3136.55	33.8145
3139.09	37.7016
3141.63	40.9669
3144.17	44.1122
3146.7	46.8786
3149.24	48.9256