File: data/Raman/poly_smoothed/Mb_40_24_03_1x_45s_532 nm_x100_100%_600 gr_mm_01.txt
#Acq. time (s)=	45
#Accumulations=	2
#Range (cm-¹)=	200...3150
#Windows=	2
#Auto scanning=	Off
#Autofocus=	Off
#Macrospot=	Off
#AutoExposure=	Off
#Spike filter=	Multiple accum.
#Delay time (s)=	0
#Binning=	1
#Readout mode=	Signal
#DeNoise=	Off
#ICS correction=	On
#Dark correction=	Off
#Inst. Process=	Off
#Detector Gain=	Best Dynamic Range
#Detector ADC=	20 kHz
#Detector temperature (°C)=	-70.08
#Instrument=	LabRAM HR Evol
#Detector=	Synapse
#Objective=	x100
#Grating=	600 gr/mm
#ND Filter=	100%
#Laser (nm)=	532
#Hole=	100.021
#Range=	Auto
#Laser Pol.=	No
#Raman. Pol.=	No
#Laser Pol. (°)=	-0.0007625
#Raman Pol. (°)=	89.9995
#Collection=	Microscope
#StageXY=	Marzhauser
#StageZ=	Marzhauser
#X (µm)=	-2541.9
#Y (µm)=	-38.3
#Z (µm)=	-10.35
#Full time(mm:ss)=	3:19
#Project=
#Sample=
#Site=
#Title=	Mb_40_24_03_2x_45s_532 nm_x100_100%_600 gr_mm
#Remark=
#Date=	14.07.2022 10:54
#Acquired=	14.07.2022 10:54:32
#Base:Fit=	10.08.2022 10:47:00
#Base:Sub=	10.08.2022 10:47:12
#Filter:Polynom=	16.08.2022 10:11:48
#AxisType[0]=Intens
#AxisUnit[0]=Cnt
#AxisType[1]=Spectr
#AxisUnit[1]=1/cm
200.554	24.0366
204.183	19.1476
207.813	15.6851
211.439	12.4032
215.065	10.005
218.688	7.49402
222.312	5.82262
225.933	2.84107
229.552	2.78936
233.171	2.72591
236.787	3.15857
240.402	2.96457
244.015	3.4088
247.627	4.64224
251.24	6.39017
254.849	7.03602
258.457	9.37161
262.063	10.0571
265.668	10.0045
269.271	10.1548
272.873	9.66844
276.474	9.63416
280.073	7.80429
283.671	7.94396
287.268	5.88332
290.863	6.12066
294.456	5.97917
298.049	5.06078
301.637	6.07474
305.227	6.18721
308.815	7.62668
312.402	9.82867
315.987	13.4152
319.569	15.8372
323.151	18.1608
326.733	20.3823
330.31	20.9648
333.889	22.0982
337.464	23.8857
341.039	23.2497
344.611	24.1161
348.184	24.7992
351.754	24.6292
355.324	23.2238
358.89	23.6675
362.455	21.6959
366.021	21.4261
369.584	21.022
373.145	18.842
376.707	19.6067
380.265	20.3079
383.822	20.7836
387.378	19.8639
390.934	20.9603
394.487	20.5789
398.038	22.1265
401.588	22.6077
405.137	21.4963
408.685	19.8849
412.23	18.0067
415.775	15.7671
419.318	15.0667
422.86	14.848
426.401	14.289
429.94	12.136
433.478	11.2105
437.012	9.93294
440.547	8.967
444.081	9.07593
447.613	9.75352
451.142	11.1193
454.672	12.2269
458.2	12.0119
461.725	12.9937
465.251	15.2357
468.775	16.642
472.296	16.3947
475.817	16.6318
479.335	18.4396
482.854	18.98
486.37	19.7907
489.886	19.9712
493.398	20.4744
496.91	21.306
500.422	22.6434
503.93	22.8678
507.438	24.2952
510.946	22.3349
514.45	21.1965
517.954	19.3751
521.456	19.9277
524.956	20.4986
528.456	19.8325
531.956	18.9095
535.452	18.5677
538.947	17.033
542.441	16.1917
545.934	15.9047
549.425	15.5131
552.915	12.9225
556.403	10.6838
559.889	9.55345
563.375	7.52859
566.859	7.3379
570.342	5.48896
573.824	5.49086
577.303	4.75709
580.782	5.18758
584.26	5.07984
587.734	6.12188
591.21	4.50509
594.684	5.21488
598.154	4.87987
601.626	6.43888
605.094	7.30232
608.562	7.97414
612.027	9.55106
615.493	10.2961
618.956	10.6586
622.419	10.416
625.879	10.6553
629.338	11.4448
632.797	9.70636
636.254	8.5968
639.708	8.63917
643.162	8.47933
646.614	7.69252
650.067	8.16092
653.516	10.7602
656.964	10.6652
660.411	10.2278
663.857	9.00376
667.301	9.51834
670.744	9.91909
674.186	9.99432
677.626	9.71568
681.065	12.1603
684.503	15.1992
687.939	16.33
691.372	16.7614
694.806	16.1441
698.239	17.0653
701.67	16.5235
705.098	15.9714
708.526	16.4904
711.954	17.3672
715.378	17.3371
718.802	16.7515
722.226	17.1702
725.646	16.819
729.067	16.3817
732.484	18.3102
735.902	17.9351
739.317	19.0134
742.731	19.4608
746.145	20.4544
749.556	22.0183
752.966	24.6538
756.377	26.7923
759.784	29.6641
763.19	33.1598
766.594	35.594
770	38.1937
773.402	38.7115
776.803	40.0388
780.202	43.1592
783.6	46.2499
786.997	49.3432
790.393	51.8021
793.787	51.9924
797.18	53.3386
800.572	55.621
803.963	55.9283
807.35	57.1964
810.738	57.6845
814.125	58.2911
817.51	58.4818
820.894	58.1308
824.275	56.4601
827.657	57.8665
831.037	58.2978
834.414	60.0413
837.792	58.6015
841.167	57.694
844.542	56.9224
847.914	54.6734
851.287	53.6924
854.656	53.3353
858.026	51.1942
861.393	49.5639
864.761	48.8937
868.125	47.7865
871.489	44.2384
874.85	42.4465
878.213	41.0329
881.572	40.5123
884.931	38.9765
888.287	37.952
891.643	36.286
894.997	34.9401
898.352	34.7439
901.704	34.9004
905.055	35.0521
908.404	37.4349
911.75	39.0427
915.097	39.0838
918.443	38.3278
921.787	38.5632
925.13	38.6232
928.472	39.0313
931.813	37.0914
935.15	37.3934
938.488	35.0834
941.825	33.166
945.158	31.2959
948.493	29.6616
951.824	27.7419
955.156	24.9984
958.486	23.2537
961.814	19.7639
965.142	18.6647
968.467	20.7002
971.79	20.5827
975.115	21.9479
978.436	22.7242
981.756	23.5133
985.077	24.0875
988.394	23.6515
991.71	22.3739
995.025	22.2516
998.341	21.4634
1001.65	20.667
1004.97	20.5998
1008.28	21.4457
1011.58	23.387
1014.89	26.2377
1018.2	30.2549
1021.5	34.1807
1024.81	35.0773
1028.11	39.0361
1031.41	41.6243
1034.71	42.5503
1038.01	43.5773
1041.31	44.3457
1044.6	46.0548
1047.9	47.4678
1051.19	48.2606
1054.48	48.6303
1057.77	46.9026
1061.06	43.977
1064.35	40.6688
1067.64	37.0178
1070.93	33.7485
1074.21	30.936
1077.49	27.3943
1080.78	22.0867
1084.06	20.4598
1087.34	20.0277
1090.61	20.6852
1093.89	20.6291
1097.17	19.4551
1100.44	19.3538
1103.71	18.3398
1106.99	19.131
1110.26	19.6539
1113.52	18.8233
1116.79	17.4601
1120.06	16.105
1123.32	14.979
1126.59	13.921
1129.85	14.1712
1133.11	13.9667
1136.37	11.4302
1139.63	11.9835
1142.89	11.0338
1146.15	10.2965
1149.4	8.62279
1152.66	9.03553
1155.91	8.48787
1159.16	6.61515
1162.41	5.67867
1165.66	6.0697
1168.91	5.12071
1172.16	4.23891
1175.4	3.42827
1178.65	5.48061
1181.89	6.82929
1185.13	7.71772
1188.37	10.1104
1191.61	11.8978
1194.85	12.1271
1198.08	13.9228
1201.32	15.6367
1204.55	18.1116
1207.79	21.9959
1211.02	25.4682
1214.25	28.1386
1217.48	29.6285
1220.71	34.0602
1223.93	36.5809
1227.16	40.5765
1230.38	42.6674
1233.6	45.5553
1236.83	47.3883
1240.05	48.9513
1243.26	50.4275
1246.48	50.6272
1249.7	50.4338
1252.92	51.7535
1256.13	53.0398
1259.34	52.344
1262.55	54.0099
1265.76	55.4357
1268.97	56.6079
1272.18	57.5279
1275.39	59.668
1278.59	62.998
1281.8	66.2842
1285	69.6353
1288.2	72.9383
1291.4	74.6243
1294.6	76.1923
1297.8	78.2126
1301	79.9524
1304.19	81.4611
1307.39	81.6189
1310.58	82.4807
1313.77	82.8898
1316.96	82.1133
1320.15	81.7694
1323.34	82.3165
1326.53	81.8735
1329.72	79.5953
1332.9	78.6852
1336.08	76.6296
1339.27	75.1455
1342.45	73.2451
1345.63	70.9483
1348.8	68.1539
1351.98	67.032
1355.16	67.2885
1358.33	65.5495
1361.51	63.6187
1364.68	61.788
1367.85	59.8888
1371.02	60.0801
1374.19	59.209
1377.36	59.0424
1380.52	60.3047
1383.69	63.0582
1386.85	63.7368
1390.02	64.7631
1393.18	65.9328
1396.34	67.7536
1399.5	70.1053
1402.65	74.3829
1405.81	77.1902
1408.97	80.7284
1412.12	84.479
1415.27	89.0049
1418.43	92.9208
1421.58	97.5349
1424.73	102.334
1427.87	109.184
1431.02	114.854
1434.17	118.461
1437.31	121.33
1440.46	124.259
1443.6	125.178
1446.74	127.903
1449.88	127.788
1453.02	127.912
1456.16	127.098
1459.29	123.716
1462.43	121.032
1465.56	117.283
1468.69	111.334
1471.83	107.156
1474.95	101.4
1478.08	96.4147
1481.21	90.2264
1484.34	83.5183
1487.47	76.4074
1490.59	71.1479
1493.71	67.1811
1496.84	62.0151
1499.96	57.779
1503.07	54.9101
1506.19	51.1167
1509.31	47.4043
1512.43	42.6641
1515.54	39.4348
1518.65	36.2141
1521.77	36.1782
1524.88	35.7643
1527.99	35.2701
1531.1	36.1032
1534.21	36.6876
1537.31	38.4439
1540.42	39.801
1543.52	42.387
1546.63	44.3874
1549.73	46.4576
1552.83	46.9655
1555.93	48.5438
1559.03	50.2502
1562.12	51.6269
1565.22	55.0037
1568.31	59.9152
1571.41	62.8779
1574.5	65.9388
1577.59	68.935
1580.68	71.9181
1583.77	75.2513
1586.86	77.1536
1589.95	79.317
1593.03	82.1952
1596.11	83.59
1599.2	85.1668
1602.28	85.5723
1605.36	84.6216
1608.44	83.1164
1611.52	82.5105
1614.6	82.4884
1617.67	82.8255
1620.75	82.9407
1623.82	82.7464
1626.89	82.8435
1629.96	82.8541
1633.04	84.0265
1636.11	84.9143
1639.17	86.0472
1642.24	87.9117
1645.31	90.5789
1648.37	91.746
1651.43	92.9421
1654.5	93.4444
1657.56	92.4588
1660.62	90.4701
1663.67	86.9079
1666.73	84.0585
1669.79	80.7363
1672.84	75.7252
1675.9	70.3205
1678.95	63.8318
1682	58.1281
1685.05	52.7501
1688.1	48.7582
1691.15	44.305
1694.2	39.2181
1697.25	35.9892
1700.29	32.3652
1703.33	29.7778
1706.38	28.0466
1709.42	26.7678
1712.46	25.6909
1715.5	25.4395
1718.54	25.3881
1721.57	25.6084
1724.61	24.2964
1727.64	22.7459
1730.68	20.6143
1733.71	18.9912
1736.74	18.6091
1739.77	18.1969
1742.8	18.7402
1745.83	17.1653
1748.85	16.9222
1751.88	16.5618
1754.91	14.9914
1757.93	15.4525
1760.95	15.2125
1763.97	15.3295
1766.99	13.8701
1770.01	12.828
1773.03	12.8827
1776.04	12.4288
1779.06	12.6495
1782.07	12.7169
1785.09	12.2129
1788.1	11.8552
1791.11	10.9368
1794.12	10.8002
1797.13	9.80634
1800.13	9.21854
1803.14	8.49698
1806.15	8.79884
1809.15	8.35603
1812.15	8.73912
1815.16	9.1826
1818.15	9.04819
1821.16	8.50619
1824.15	9.01488
1827.15	7.91231
1830.15	8.21329
1833.14	8.90611
1836.14	8.04687
1839.13	7.3877
1842.12	7.31986
1845.11	7.32127
1848.1	7.674
1851.09	7.5602
1854.08	7.69423
1857.06	7.86422
1860.05	8.14087
1863.03	7.5869
1866.01	8.24724
1869	6.84678
1871.98	6.72783
1874.96	5.84963
1877.93	4.65436
1880.91	4.2084
1882.47	4.18647
1885.46	4.33365
1888.44	3.90479
1891.43	3.19697
1894.42	3.3142
1897.4	2.61913
1900.39	2.25558
1903.37	2.68386
1906.35	2.04825
1909.33	2.67564
1912.31	3.60351
1915.29	4.81145
1918.26	4.81125
1921.24	4.61366
1924.21	4.55562
1927.19	5.78396
1930.16	6.58315
1933.13	5.27653
1936.1	4.25092
1939.07	2.96919
1942.04	2.41643
1945	1.84594
1947.97	1.40821
1950.93	0.639238
1953.9	0.597107
1956.86	0.500588
1959.82	0.547688
1962.78	0.0637494
1965.74	0.0760226
1968.7	0.140053
1971.65	-0.460673
1974.61	0.488418
1977.57	1.23775
1980.52	1.30729
1983.47	1.39277
1986.42	1.88062
1989.37	2.19627
1992.32	2.80788
1995.27	3.83088
1998.22	4.40146
2001.17	5.05572
2004.11	3.45236
2007.05	1.75295
2010	2.14912
2012.94	1.78741
2015.88	2.65983
2018.82	2.35199
2021.76	2.29546
2024.7	2.15149
2027.63	3.06524
2030.57	3.8774
2033.5	4.2525
2036.44	4.45533
2039.37	6.24636
2042.3	6.31673
2045.23	8.25475
2048.16	9.41984
2051.08	10.6114
2054.01	12.0452
2056.94	14.1699
2059.86	16.1885
2062.79	16.7214
2065.71	18.4226
2068.63	17.8326
2071.55	18.2741
2074.47	18.8768
2077.39	18.8155
2080.31	20.0838
2083.22	21.3126
2086.13	21.141
2089.05	20.4104
2091.96	20.8126
2094.87	22.5249
2097.78	23.8003
2100.69	25.0313
2103.6	26.2083
2106.51	27.2698
2109.42	28.3752
2112.32	30.6432
2115.23	32.9369
2118.13	36.5622
2121.03	37.9907
2123.93	40.6689
2126.83	44.1184
2129.73	46.5785
2132.63	49.2529
2135.53	51.75
2138.42	54.7598
2141.32	58.4206
2144.21	61.757
2147.1	65.4038
2150	67.8311
2152.89	71.4339
2155.78	72.5097
2158.66	73.8484
2161.55	76.5405
2164.44	78.2235
2167.32	79.5418
2170.21	79.3626
2173.09	79.5483
2175.97	78.6477
2178.85	77.6206
2181.73	77.777
2184.61	75.662
2187.49	73.3999
2190.37	71.5285
2193.24	68.8573
2196.12	66.5004
2198.99	64.014
2201.87	61.4785
2204.74	58.7963
2207.61	55.8722
2210.48	52.9584
2213.35	50.0744
2216.21	45.8764
2219.08	42.6884
2221.95	41.1561
2224.81	37.9454
2227.67	34.8714
2230.54	32.9196
2233.4	30.9009
2236.26	28.7717
2239.11	25.9436
2241.97	24.119
2244.83	22.775
2247.69	21.9361
2250.54	19.9441
2253.4	18.0504
2256.25	16.4451
2259.1	14.7695
2261.95	13.9724
2264.8	13.3297
2267.65	11.4927
2270.5	10.607
2273.34	10.2906
2276.19	7.97067
2279.03	7.21335
2281.88	6.31419
2284.72	5.29432
2287.56	5.58375
2290.4	4.82051
2293.24	3.96563
2296.08	3.03337
2298.92	3.88066
2301.76	5.21168
2304.59	5.19154
2307.43	5.25806
2310.26	5.34216
2313.09	6.26283
2315.92	6.07349
2318.75	5.8046
2321.58	6.16287
2324.41	6.80545
2327.24	5.29209
2330.06	4.74949
2332.89	4.76459
2335.71	4.9842
2338.54	3.68166
2341.36	3.62848
2344.18	3.00439
2347	2.26578
2349.82	1.77823
2352.64	1.77204
2355.45	0.997776
2358.27	1.10893
2361.08	0.676258
2363.9	1.11949
2366.71	2.56127
2369.52	2.44248
2372.33	2.48332
2375.14	2.61686
2377.95	2.32705
2380.76	2.38977
2383.57	2.39819
2386.37	2.72322
2389.18	4.4537
2391.98	4.34197
2394.79	3.70975
2397.59	3.47227
2400.39	3.69847
2403.19	3.85996
2405.99	4.60486
2408.78	4.19176
2411.58	4.70426
2414.38	4.66198
2417.17	4.92813
2419.97	5.13903
2422.76	5.65239
2425.55	5.33133
2428.34	6.04835
2431.13	5.57382
2433.92	5.5767
2436.71	5.75026
2439.49	5.80846
2442.28	4.71973
2445.06	4.37498
2447.85	4.06384
2450.63	3.75902
2453.41	3.70408
2456.19	3.43911
2458.97	4.918
2461.75	3.63456
2464.53	3.55102
2467.31	2.43018
2470.08	2.12127
2472.86	2.28963
2475.63	2.13453
2478.4	1.67075
2481.17	2.05941
2483.94	1.31911
2486.72	0.220222
2489.48	0.434118
2492.25	0.726482
2495.02	0.826605
2497.79	0.7876
2500.55	0.661539
2503.31	1.11381
2506.08	1.2752
2508.84	1.80918
2511.6	2.14655
2514.36	2.54787
2517.12	3.93134
2519.88	3.93687
2522.63	4.64754
2525.39	4.88416
2528.14	5.72906
2530.9	4.39997
2533.65	4.13883
2536.4	4.40282
2539.15	5.03961
2541.9	6.07971
2544.65	5.80817
2547.4	5.53061
2550.15	3.38025
2552.89	3.24915
2555.64	2.57436
2558.38	2.96947
2561.12	3.2026
2563.87	4.57725
2566.61	5.66648
2569.35	5.07285
2572.09	6.57324
2574.83	7.13992
2577.56	7.424
2580.3	7.86079
2583.04	8.10698
2585.77	8.21801
2588.5	7.87672
2591.23	8.89653
2593.97	8.32576
2596.7	8.85675
2599.43	8.24988
2602.15	8.42419
2604.88	7.78414
2607.61	7.21669
2610.33	7.13769
2613.06	6.57605
2615.78	4.35132
2618.51	4.25532
2621.23	4.43956
2623.95	4.2456
2626.67	4.96091
2629.39	5.10882
2632.1	4.73139
2634.82	4.49677
2637.54	5.78588
2640.25	6.25276
2642.97	6.37205
2645.68	6.20117
2648.39	6.10845
2651.1	6.65623
2653.81	6.98713
2656.52	7.34817
2659.23	7.37714
2661.94	7.3574
2664.64	6.8354
2667.35	6.57582
2670.05	6.36168
2672.76	6.14883
2675.46	7.00824
2678.16	7.01594
2680.86	6.9929
2683.56	7.27568
2686.26	7.51597
2688.96	8.33296
2691.65	8.93133
2694.35	10.3478
2697.04	11.0778
2699.74	11.8261
2702.43	13.1813
2705.12	13.7605
2707.81	13.5439
2710.5	13.9025
2713.19	14.4381
2715.88	15.3843
2718.57	15.755
2721.25	15.7549
2723.94	16.6394
2726.62	16.3176
2729.3	16.3052
2731.99	15.9128
2734.67	15.7329
2737.35	14.4225
2740.03	13.9883
2742.71	14.1783
2745.38	13.8129
2748.06	13.0738
2750.74	11.5618
2753.41	11.0256
2756.09	10.2954
2758.76	9.50706
2761.43	8.43939
2764.1	7.47119
2766.77	5.78516
2769.44	4.12224
2772.11	2.89257
2774.77	1.52587
2777.44	0.509555
2780.11	0.889305
2782.77	0.835792
2785.43	0.466155
2788.1	0.943302
2790.76	1.12304
2793.42	0.314808
2796.08	1.18344
2798.74	0.757368
2801.4	1.05356
2804.05	1.02124
2806.71	1.59594
2809.36	2.75259
2812.02	4.01364
2814.67	4.62917
2817.32	6.4104
2819.97	9.70152
2822.62	13.4975
2825.27	16.7329
2827.92	21.6224
2830.57	26.2066
2833.22	31.5109
2835.86	37.6237
2838.51	43.6798
2841.15	51.6756
2843.79	59.2521
2846.43	68.7578
2849.08	76.6712
2851.72	85.2731
2854.36	94.9452
2856.99	103.49
2859.63	112.5
2862.27	119.871
2864.9	127.971
2867.54	135.787
2870.17	143.282
2872.8	149.839
2875.43	156.285
2878.07	162.668
2880.7	168.215
2883.32	175.681
2885.95	182.1
2888.58	187.95
2891.21	195.603
2893.83	201.884
2896.46	208.786
2899.08	217.656
2901.7	227.383
2904.32	237.721
2906.94	249.854
2909.56	260.638
2912.18	272.621
2914.8	284.064
2917.42	295.589
2920.03	304.726
2922.65	311.172
2925.26	315.68
2927.88	319.694
2930.49	320.986
2933.1	319.363
2935.71	315.35
2938.32	307.71
2940.93	299.32
2943.54	289.48
2946.14	278.432
2948.75	265.114
2951.35	251.491
2953.96	237.92
2956.56	223.437
2959.16	209.573
2961.77	197.154
2964.37	185.967
2966.96	175.344
2969.56	165.534
2972.16	155.912
2974.76	146.225
2977.35	137.16
2979.95	127.83
2982.54	119.635
2985.14	109.554
2987.73	101.05
2990.32	92.5836
2992.91	83.7921
2995.5	74.9465
2998.09	65.6451
3000.68	56.8198
3003.26	49.8753
3005.85	42.6955
3008.43	35.0622
3011.02	28.6033
3013.6	22.6792
3016.19	17.9375
3018.77	13.3635
3021.35	9.31706
3023.93	6.44771
3026.5	3.73189
3029.08	1.96256
3031.66	0.637634
3034.24	-0.549696
3036.81	-1.26852
3039.39	-1.38903
3041.96	-2.12508
3044.53	-0.207706
3047.1	-0.608345
3049.67	0.730285
3052.24	1.04671
3054.81	1.73715
3057.38	2.59926
3059.95	2.65251
3062.52	3.32712
3065.08	3.80893
3067.65	3.27734
3070.21	3.01568
3072.77	2.26887
3075.33	1.88185
3077.89	1.92049
3080.45	1.4627
3083.01	1.7405
3085.57	0.742579
3088.13	0.5948
3090.68	-0.029032
3093.24	-0.936346
3095.79	-1.54337
3098.35	-1.22893
3100.9	-1.47988
3103.45	-0.433407
3106	0.227116
3108.55	1.28702
3111.1	1.97609
3113.65	3.50168
3116.2	4.45445
3118.75	6.03926
3121.29	7.64544
3123.84	8.80094
3126.38	10.2963
3128.92	10.9704
3131.47	12.6193
3134.01	14.4743
3136.55	15.6514
3139.09	17.1124
3141.63	18.3852
3144.17	19.232
3146.7	19.0067
3149.24	19.6645