File: data/Raman/poly_smoothed/Mb_40_24_36_1x_45s_532 nm_x100_100%_600 gr_mm_02.txt
#Acq. time (s)=	45
#Accumulations=	2
#Range (cm-¹)=	200...3150
#Windows=	2
#Auto scanning=	Off
#Autofocus=	Off
#Macrospot=	Off
#AutoExposure=	Off
#Spike filter=	Multiple accum.
#Delay time (s)=	0
#Binning=	1
#Readout mode=	Signal
#DeNoise=	Off
#ICS correction=	On
#Dark correction=	Off
#Inst. Process=	Off
#Detector Gain=	Best Dynamic Range
#Detector ADC=	20 kHz
#Detector temperature (°C)=	-69.85
#Instrument=	LabRAM HR Evol
#Detector=	Synapse
#Objective=	x100
#Grating=	600 gr/mm
#ND Filter=	100%
#Laser (nm)=	532
#Hole=	100.021
#Range=	Auto
#Laser Pol.=	No
#Raman. Pol.=	No
#Laser Pol. (°)=	-0.0007625
#Raman Pol. (°)=	89.9995
#Collection=	Microscope
#StageXY=	Marzhauser
#StageZ=	Marzhauser
#X (µm)=	-2496.8
#Y (µm)=	-77
#Z (µm)=	-10.5
#Full time(mm:ss)=	3:19
#Project=
#Sample=
#Site=
#Title=	Mb_40_24_36_2x_45s_532 nm_x100_100%_600 gr_mm
#Remark=
#Date=	14.07.2022 13:24
#Acquired=	14.07.2022 13:24:01
#Base:Fit=	10.08.2022 10:47:00
#Base:Sub=	10.08.2022 10:47:12
#Filter:Polynom=	16.08.2022 10:11:48
#AxisType[0]=Intens
#AxisUnit[0]=Cnt
#AxisType[1]=Spectr
#AxisUnit[1]=1/cm
200.554	9.17645
204.183	8.45436
207.813	7.1692
211.439	6.12638
215.065	3.91337
218.688	4.6542
222.312	3.58779
225.933	2.42943
229.552	2.18576
233.171	1.58218
236.787	1.23802
240.402	0.630607
244.015	0.646121
247.627	0.865969
251.24	1.97947
254.849	1.21557
258.457	4.19888
262.063	4.96731
265.668	4.85858
269.271	6.07697
272.873	7.24244
276.474	7.59279
280.073	7.04009
283.671	7.83917
287.268	7.41906
290.863	6.8573
294.456	7.70281
298.049	8.88423
301.637	9.19465
305.227	9.86372
308.815	10.4134
312.402	9.51489
315.987	11.0801
319.569	11.6882
323.151	12.5758
326.733	11.3307
330.31	11.3952
333.889	11.6625
337.464	12.8412
341.039	12.8944
344.611	14.1292
348.184	13.2153
351.754	11.3029
355.324	10.2399
358.89	11.0512
362.455	8.31877
366.021	7.65287
369.584	6.10763
373.145	5.24781
376.707	4.71022
380.265	5.64602
383.822	5.60098
387.378	6.84706
390.934	6.32995
394.487	8.4406
398.038	9.07768
401.588	11.3518
405.137	11.6538
408.685	13.4211
412.23	13.7619
415.775	14.2498
419.318	16.6409
422.86	17.4457
426.401	18.0119
429.94	17.377
433.478	17.738
437.012	18.6372
440.547	19.561
444.081	18.2316
447.613	17.8753
451.142	16.2833
454.672	16.0592
458.2	15.013
461.725	14.3745
465.251	14.9489
468.775	15.8569
472.296	16.554
475.817	18.3976
479.335	19.0816
482.854	20.0843
486.37	22.2811
489.886	22.5586
493.398	24.4319
496.91	25.4021
500.422	25.5175
503.93	24.6308
507.438	25.2217
510.946	26.4287
514.45	26.5905
517.954	28.3995
521.456	28.8494
524.956	28.7803
528.456	26.8547
531.956	24.1506
535.452	22.4559
538.947	20.3233
542.441	19.9156
545.934	18.4461
549.425	17.7894
552.915	17.3169
556.403	16.6631
559.889	16.1064
563.375	14.1306
566.859	13.0773
570.342	11.2621
573.824	10.1283
577.303	8.16566
580.782	6.36055
584.26	5.16352
587.734	5.10207
591.21	5.17745
594.684	5.56581
598.154	7.80943
601.626	8.14436
605.094	10.8384
608.562	11.6319
612.027	11.6812
615.493	12.4432
618.956	13.6436
622.419	13.3256
625.879	14.3931
629.338	14.8753
632.797	16.6719
636.254	18.1571
639.708	20.3276
643.162	19.3445
646.614	19.9131
650.067	17.5845
653.516	16.6038
656.964	15.696
660.411	15.6243
663.857	15.4047
667.301	15.6353
670.744	14.4318
674.186	13.2772
677.626	12.7204
681.065	15.2312
684.503	16.0265
687.939	14.6934
691.372	15.7999
694.806	15.5746
698.239	17.1741
701.67	18.3795
705.098	19.0841
708.526	19.9285
711.954	21.0008
715.378	23.5071
718.802	25.0686
722.226	24.5365
725.646	25.1395
729.067	24.732
732.484	25.34
735.902	24.4968
739.317	24.8132
742.731	27.0555
746.145	27.5464
749.556	27.6058
752.966	29.3195
756.377	30.9326
759.784	33.8243
763.19	37.724
766.594	41.6407
770	43.1484
773.402	47.3166
776.803	49.4844
780.202	52.0684
783.6	55.6939
786.997	58.1522
790.393	59.1037
793.787	58.6554
797.18	59.1818
800.572	59.701
803.963	58.6159
807.35	57.2916
810.738	57.7647
814.125	55.6756
817.51	54.5752
820.894	52.5195
824.275	52.1416
827.657	50.6294
831.037	51.0678
834.414	53.0772
837.792	52.1386
841.167	52.6613
844.542	53.1478
847.914	54.1435
851.287	53.2066
854.656	52.564
858.026	50.4567
861.393	50.0993
864.761	49.8678
868.125	47.3469
871.489	46.2537
874.85	44.7229
878.213	42.0855
881.572	41.2492
884.931	39.2148
888.287	37.8398
891.643	37.5746
894.997	35.7063
898.352	34.0464
901.704	32.9338
905.055	31.9758
908.404	30.525
911.75	31.1838
915.097	31.6521
918.443	31.5747
921.787	30.6715
925.13	31.692
928.472	31.529
931.813	29.2724
935.15	28.4581
938.488	27.8719
941.825	27.1132
945.158	27.4324
948.493	25.9026
951.824	23.6784
955.156	22.076
958.486	20.1039
961.814	19.4556
965.142	20.2449
968.467	21.1845
971.79	21.8698
975.115	22.163
978.436	20.6028
981.756	19.8054
985.077	19.8615
988.394	19.2063
991.71	18.5425
995.025	19.5559
998.341	17.4013
1001.65	16.5612
1004.97	15.213
1008.28	15.5794
1011.58	15.2874
1014.89	18.6779
1018.2	21.4744
1021.5	24.8286
1024.81	28.2961
1028.11	29.8737
1031.41	31.8064
1034.71	33.4611
1038.01	36.0362
1041.31	36.8873
1044.6	39.5342
1047.9	41.177
1051.19	42.3642
1054.48	40.6435
1057.77	37.8981
1061.06	36.4071
1064.35	35.6249
1067.64	32.0246
1070.93	30.0922
1074.21	26.5498
1077.49	21.1303
1080.78	16.7281
1084.06	13.8805
1087.34	12.3894
1090.61	13.0373
1093.89	13.0074
1097.17	13.1269
1100.44	14.5653
1103.71	15.7145
1106.99	13.4538
1110.26	13.5602
1113.52	13.0495
1116.79	12.3191
1120.06	12.6204
1123.32	11.4522
1126.59	12.2748
1129.85	13.1415
1133.11	11.9335
1136.37	10.1111
1139.63	10.3754
1142.89	9.68743
1146.15	9.26017
1149.4	8.04972
1152.66	6.86079
1155.91	5.37955
1159.16	4.58201
1162.41	2.70853
1165.66	3.20971
1168.91	3.74153
1172.16	2.56773
1175.4	3.32923
1178.65	3.68064
1181.89	5.32127
1185.13	5.40494
1188.37	5.74662
1191.61	7.67535
1194.85	8.07635
1198.08	7.0479
1201.32	8.08919
1204.55	9.54171
1207.79	10.0626
1211.02	12.8635
1214.25	14.3168
1217.48	16.4771
1220.71	18.6817
1223.93	20.6283
1227.16	22.3306
1230.38	25.7289
1233.6	28.5687
1236.83	31.2872
1240.05	32.3906
1243.26	35.4212
1246.48	39.5431
1249.7	41.604
1252.92	44.9681
1256.13	47.4454
1259.34	49.8455
1262.55	54.6192
1265.76	57.4911
1268.97	59.3977
1272.18	62.2916
1275.39	64.5057
1278.59	67.6874
1281.8	71.8095
1285	75.8157
1288.2	80.0855
1291.4	81.5483
1294.6	84.0414
1297.8	86.8406
1301	88.2434
1304.19	88.1699
1307.39	88.6052
1310.58	88.8485
1313.77	87.6714
1316.96	86.0964
1320.15	84.3176
1323.34	81.6139
1326.53	80.3617
1329.72	79.7823
1332.9	75.5956
1336.08	73.773
1339.27	73.9009
1342.45	72.2718
1345.63	70.5007
1348.8	69.161
1351.98	67.8256
1355.16	66.1985
1358.33	65.1602
1361.51	64.1087
1364.68	64.4945
1367.85	63.1262
1371.02	62.9473
1374.19	62.5439
1377.36	61.9213
1380.52	61.8095
1383.69	61.592
1386.85	60.9358
1390.02	61.8218
1393.18	62.1725
1396.34	62.6444
1399.5	63.9704
1402.65	66.81
1405.81	70.235
1408.97	74.1811
1412.12	79.2028
1415.27	83.4142
1418.43	90.5634
1421.58	96.4808
1424.73	103.074
1427.87	110.136
1431.02	117.646
1434.17	124.554
1437.31	129.912
1440.46	133.83
1443.6	136.723
1446.74	136.659
1449.88	135.179
1453.02	135.333
1456.16	132.575
1459.29	129.076
1462.43	122.957
1465.56	116.966
1468.69	108.874
1471.83	101.708
1474.95	94.636
1478.08	87.701
1481.21	80.6935
1484.34	73.424
1487.47	67.9352
1490.59	60.4688
1493.71	56.5127
1496.84	53.6225
1499.96	49.455
1503.07	48.6912
1506.19	45.5038
1509.31	43.3216
1512.43	40.7717
1515.54	37.9567
1518.65	35.1535
1521.77	36.3688
1524.88	35.5528
1527.99	37.8711
1531.1	38.7161
1534.21	38.4795
1537.31	38.0123
1540.42	39.0696
1543.52	41.2051
1546.63	42.8893
1549.73	45.7107
1552.83	48.3161
1555.93	50.8487
1559.03	54.0305
1562.12	58.1179
1565.22	61.4573
1568.31	65.4356
1571.41	68.3561
1574.5	73.4493
1577.59	77.2161
1580.68	82.0717
1583.77	85.8018
1586.86	90.0598
1589.95	92.683
1593.03	94.8487
1596.11	97.1163
1599.2	99.3646
1602.28	98.9025
1605.36	98.0922
1608.44	96.7629
1611.52	95.3888
1614.6	93.3139
1617.67	91.9785
1620.75	90.6797
1623.82	90.1113
1626.89	90.5056
1629.96	89.1914
1633.04	88.5928
1636.11	87.1722
1639.17	85.2452
1642.24	84.5271
1645.31	83.5583
1648.37	83.9716
1651.43	83.0817
1654.5	82.123
1657.56	79.0902
1660.62	75.5338
1663.67	71.646
1666.73	67.2213
1669.79	62.1377
1672.84	58.7924
1675.9	53.5174
1678.95	49.6862
1682	46.8426
1685.05	43.1184
1688.1	40.1176
1691.15	36.119
1694.2	34.0699
1697.25	31.9338
1700.29	31.0022
1703.33	28.6801
1706.38	27.1307
1709.42	24.631
1712.46	23.1305
1715.5	22.7782
1718.54	21.851
1721.57	22.3571
1724.61	21.9805
1727.64	21.1303
1730.68	19.6737
1733.71	19.8626
1736.74	18.9842
1739.77	18.3368
1742.8	16.7156
1745.83	16.471
1748.85	14.9497
1751.88	14.0198
1754.91	13.5501
1757.93	11.9778
1760.95	11.2779
1763.97	10.7957
1766.99	10.214
1770.01	9.13754
1773.03	8.77983
1776.04	8.29618
1779.06	7.14734
1782.07	5.05365
1785.09	3.83336
1788.1	4.99862
1791.11	5.10913
1794.12	4.96715
1797.13	6.60355
1800.13	7.11487
1803.14	7.66528
1806.15	8.65395
1809.15	8.34704
1812.15	7.35745
1815.16	6.90497
1818.15	7.25995
1821.16	6.57553
1824.15	6.14748
1827.15	6.18549
1830.15	5.90668
1833.14	5.52366
1836.14	6.67345
1839.13	7.55336
1842.12	6.54187
1845.11	5.59194
1848.1	5.01832
1851.09	4.58092
1854.08	2.74065
1857.06	2.20756
1860.05	2.59301
1863.03	3.05463
1866.01	3.31939
1869	3.75046
1871.98	4.22895
1874.96	3.96934
1877.93	3.76103
1880.91	4.38152
1882.47	4.02053
1885.46	4.49041
1888.44	4.52032
1891.43	4.21536
1894.42	3.54889
1897.4	4.02447
1900.39	2.88939
1903.37	2.93675
1906.35	2.01963
1909.33	2.38386
1912.31	1.04552
1915.29	-0.00803435
1918.26	-0.457498
1921.24	0.120544
1924.21	0.061744
1927.19	0.446755
1930.16	1.13331
1933.13	1.2399
1936.1	1.92756
1939.07	1.68491
1942.04	1.76909
1945	1.98585
1947.97	3.25164
1950.93	3.53771
1953.9	3.67136
1956.86	3.58148
1959.82	3.16412
1962.78	3.66139
1965.74	4.05485
1968.7	4.57509
1971.65	2.78401
1974.61	2.96309
1977.57	3.10813
1980.52	3.08493
1983.47	2.93021
1986.42	3.15264
1989.37	3.12
1992.32	3.31209
1995.27	3.51923
1998.22	2.85188
2001.17	2.39884
2004.11	2.04935
2007.05	2.38577
2010	1.97562
2012.94	1.58412
2015.88	1.4488
2018.82	1.48417
2021.76	1.34224
2024.7	0.0697975
2027.63	-0.15699
2030.57	-0.403209
2033.5	-0.107161
2036.44	0.755263
2039.37	0.761985
2042.3	1.50318
2045.23	1.42571
2048.16	2.79058
2051.08	3.14823
2054.01	4.79601
2056.94	5.42826
2059.86	7.18564
2062.79	7.9667
2065.71	9.05535
2068.63	10.6642
2071.55	11.8177
2074.47	12.7276
2077.39	15.0181
2080.31	15.1775
2083.22	16.8984
2086.13	18.5945
2089.05	18.9895
2091.96	20.0438
2094.87	22.5643
2097.78	23.9731
2100.69	24.8988
2103.6	26.8335
2106.51	28.622
2109.42	30.3974
2112.32	31.5781
2115.23	33.6543
2118.13	34.3844
2121.03	36.3836
2123.93	38.7992
2126.83	42.1774
2129.73	44.6262
2132.63	47.1409
2135.53	49.5185
2138.42	51.8043
2141.32	54.4938
2144.21	56.8701
2147.1	59.4971
2150	62.6782
2152.89	65.5056
2155.78	67.4871
2158.66	69.1749
2161.55	71.6045
2164.44	73.4021
2167.32	73.3602
2170.21	73.6701
2173.09	72.7595
2175.97	70.6698
2178.85	68.8254
2181.73	65.671
2184.61	63.0869
2187.49	59.9057
2190.37	57.1816
2193.24	55.0653
2196.12	51.6323
2198.99	49.9918
2201.87	47.2054
2204.74	43.4015
2207.61	40.6305
2210.48	38.5821
2213.35	37.8279
2216.21	36.2397
2219.08	35.0754
2221.95	33.2999
2224.81	32.0755
2227.67	30.5075
2230.54	29.3382
2233.4	27.9823
2236.26	25.9788
2239.11	23.539
2241.97	21.545
2244.83	19.5978
2247.69	16.7592
2250.54	15.3576
2253.4	14.1076
2256.25	13.0062
2259.1	11.4581
2261.95	10.445
2264.8	10.1587
2267.65	8.6693
2270.5	7.50763
2273.34	6.7759
2276.19	5.64473
2279.03	5.16048
2281.88	4.74136
2284.72	4.61207
2287.56	4.43192
2290.4	3.67347
2293.24	2.21483
2296.08	1.63179
2298.92	1.77233
2301.76	2.97102
2304.59	3.60267
2307.43	4.52612
2310.26	5.25738
2313.09	6.66763
2315.92	7.55744
2318.75	7.63625
2321.58	7.57019
2324.41	8.74957
2327.24	9.29079
2330.06	9.35228
2332.89	9.13452
2335.71	8.36545
2338.54	8.06096
2341.36	7.47418
2344.18	6.20197
2347	7.3188
2349.82	5.86595
2352.64	5.49859
2355.45	4.58682
2358.27	2.87548
2361.08	1.52515
2363.9	1.68456
2366.71	3.8541
2369.52	3.6341
2372.33	4.31202
2375.14	2.8232
2377.95	2.28711
2380.76	1.56605
2383.57	2.142
2386.37	1.88689
2389.18	2.27321
2391.98	3.41209
2394.79	3.83239
2397.59	3.82103
2400.39	3.96919
2403.19	4.89284
2405.99	5.41445
2408.78	7.11556
2411.58	7.00869
2414.38	8.73466
2417.17	8.90791
2419.97	9.5511
2422.76	9.2941
2425.55	9.80741
2428.34	9.77172
2431.13	10.9035
2433.92	10.3207
2436.71	10.0272
2439.49	9.0421
2442.28	7.46666
2445.06	6.96381
2447.85	5.87326
2450.63	4.80143
2453.41	4.63853
2456.19	3.74331
2458.97	3.19844
2461.75	3.49823
2464.53	3.51787
2467.31	3.16255
2470.08	3.24898
2472.86	4.11445
2475.63	4.09233
2478.4	4.67136
2481.17	4.15515
2483.94	4.33496
2486.72	4.52054
2489.48	4.29854
2492.25	4.719
2495.02	5.14361
2497.79	4.64175
2500.55	4.6076
2503.31	3.74437
2506.08	4.23648
2508.84	2.94979
2511.6	2.51503
2514.36	2.764
2517.12	1.73598
2519.88	1.83213
2522.63	2.35784
2525.39	3.01655
2528.14	4.17349
2530.9	5.61694
2533.65	5.61948
2536.4	4.94499
2539.15	6.06079
2541.9	6.66239
2544.65	7.1944
2547.4	7.53409
2550.15	8.38273
2552.89	8.42927
2555.64	9.26982
2558.38	9.81515
2561.12	10.1178
2563.87	10.1618
2566.61	10.4568
2569.35	10.5333
2572.09	11.1861
2574.83	11.4011
2577.56	10.8292
2580.3	10.9089
2583.04	10.7521
2585.77	9.95464
2588.5	10.9091
2591.23	11.1652
2593.97	11.3581
2596.7	11.7566
2599.43	10.3311
2602.15	9.0395
2604.88	8.18907
2607.61	7.6436
2610.33	6.40571
2613.06	7.02571
2615.78	6.09
2618.51	4.5759
2621.23	4.6267
2623.95	4.82489
2626.67	5.13505
2629.39	5.73113
2632.1	5.66905
2634.82	5.49771
2637.54	6.87232
2640.25	6.6397
2642.97	7.21007
2645.68	7.03693
2648.39	7.94695
2651.1	8.6948
2653.81	10.462
2656.52	11.4991
2659.23	10.7752
2661.94	12.4014
2664.64	12.2096
2667.35	11.4702
2670.05	11.6509
2672.76	11.0802
2675.46	10.6307
2678.16	10.3249
2680.86	10.9608
2683.56	10.2578
2686.26	9.90631
2688.96	11.0636
2691.65	11.9357
2694.35	12.116
2697.04	13.3416
2699.74	14.5324
2702.43	15.8817
2705.12	17.2742
2707.81	16.7626
2710.5	17.4538
2713.19	18.1746
2715.88	19.2537
2718.57	20.0672
2721.25	21.6579
2723.94	22.3884
2726.62	22.9008
2729.3	22.7425
2731.99	22.1085
2734.67	21.5232
2737.35	19.3774
2740.03	18.0954
2742.71	16.3551
2745.38	15.2437
2748.06	14.1972
2750.74	12.5104
2753.41	11.0255
2756.09	10.9273
2758.76	9.72748
2761.43	9.54532
2764.1	9.96214
2766.77	8.50841
2769.44	7.04234
2772.11	5.585
2774.77	4.65053
2777.44	4.719
2780.11	4.39689
2782.77	3.72188
2785.43	4.87049
2788.1	5.07857
2790.76	5.88734
2793.42	5.46578
2796.08	4.32043
2798.74	3.31137
2801.4	3.01463
2804.05	3.1594
2806.71	2.85563
2809.36	4.07774
2812.02	3.81908
2814.67	4.38376
2817.32	6.39528
2819.97	10.8562
2822.62	16.3793
2825.27	21.6062
2827.92	29.1776
2830.57	36.7205
2833.22	45.1348
2835.86	53.1851
2838.51	63.6759
2841.15	74.0013
2843.79	83.7336
2846.43	93.6992
2849.08	103.836
2851.72	114.723
2854.36	125.159
2856.99	136.057
2859.63	146.21
2862.27	154.99
2864.9	163.927
2867.54	169.631
2870.17	176.263
2872.8	181.062
2875.43	186.712
2878.07	192.076
2880.7	197.742
2883.32	203.602
2885.95	209.819
2888.58	216.048
2891.21	221.53
2893.83	228.748
2896.46	236.037
2899.08	242.508
2901.7	249.939
2904.32	258.071
2906.94	266.411
2909.56	274.538
2912.18	285.06
2914.8	296.397
2917.42	305.097
2920.03	313.146
2922.65	320.208
2925.26	323.948
2927.88	324.258
2930.49	323.085
2933.1	320.309
2935.71	317.21
2938.32	310.13
2940.93	302.165
2943.54	290.786
2946.14	278.354
2948.75	266.308
2951.35	252.438
2953.96	239.295
2956.56	224.48
2959.16	210.63
2961.77	198.447
2964.37	185.998
2966.96	174.818
2969.56	164.118
2972.16	153.782
2974.76	145.026
2977.35	135.262
2979.95	124.82
2982.54	116.289
2985.14	106.33
2987.73	97.7155
2990.32	88.8606
2992.91	79.8242
2995.5	72.3817
2998.09	64.5212
3000.68	56.4149
3003.26	48.1592
3005.85	40.0397
3008.43	33.1442
3011.02	28.1125
3013.6	22.8136
3016.19	18.0097
3018.77	13.857
3021.35	10.5386
3023.93	8.47698
3026.5	6.7154
3029.08	4.43674
3031.66	1.42732
3034.24	-0.185366
3036.81	-1.22158
3039.39	-0.787535
3041.96	-1.43578
3044.53	-1.55227
3047.1	-1.02342
3049.67	0.466786
3052.24	1.23406
3054.81	1.1973
3057.38	1.55767
3059.95	1.57217
3062.52	1.70805
3065.08	1.25869
3067.65	0.772496
3070.21	1.64064
3072.77	1.37725
3075.33	0.897032
3077.89	0.463309
3080.45	0.328054
3083.01	0.198002
3085.57	0.767408
3088.13	0.468624
3090.68	-0.118107
3093.24	-1.2749
3095.79	-2.057
3098.35	-1.45151
3100.9	-0.793166
3103.45	0.55951
3106	0.808179
3108.55	1.80466
3111.1	3.60444
3113.65	5.38213
3116.2	7.21259
3118.75	8.39543
3121.29	10.2273
3123.84	12.3706
3126.38	14.9522
3128.92	16.6649
3131.47	19.6681
3134.01	21.4655
3136.55	23.577
3139.09	26.0984
3141.63	27.842
3144.17	28.8379
3146.7	28.4592
3149.24	28.3774