File: data/Raman/poly_smoothed/Mb_40_24_23_1x_45s_532 nm_x100_100%_600 gr_mm_01.txt
#Acq. time (s)=	45
#Accumulations=	2
#Range (cm-¹)=	200...3150
#Windows=	2
#Auto scanning=	Off
#Autofocus=	Off
#Macrospot=	Off
#AutoExposure=	Off
#Spike filter=	Multiple accum.
#Delay time (s)=	0
#Binning=	1
#Readout mode=	Signal
#DeNoise=	Off
#ICS correction=	On
#Dark correction=	Off
#Inst. Process=	Off
#Detector Gain=	Best Dynamic Range
#Detector ADC=	20 kHz
#Detector temperature (°C)=	-70.08
#Instrument=	LabRAM HR Evol
#Detector=	Synapse
#Objective=	x100
#Grating=	600 gr/mm
#ND Filter=	100%
#Laser (nm)=	532
#Hole=	100.021
#Range=	Auto
#Laser Pol.=	No
#Raman. Pol.=	No
#Laser Pol. (°)=	-0.0007625
#Raman Pol. (°)=	89.9995
#Collection=	Microscope
#StageXY=	Marzhauser
#StageZ=	Marzhauser
#X (µm)=	-2529.7
#Y (µm)=	-107.3
#Z (µm)=	-10.2
#Full time(mm:ss)=	3:19
#Project=
#Sample=
#Site=
#Title=	Mb_40_24_23_2x_45s_532 nm_x100_100%_600 gr_mm
#Remark=
#Date=	14.07.2022 12:24
#Acquired=	14.07.2022 12:24:01
#Base:Fit=	10.08.2022 10:47:00
#Base:Sub=	10.08.2022 10:47:12
#Filter:Polynom=	16.08.2022 10:11:48
#AxisType[0]=Intens
#AxisUnit[0]=Cnt
#AxisType[1]=Spectr
#AxisUnit[1]=1/cm
200.554	20.4424
204.183	22.2948
207.813	20.3246
211.439	18.9629
215.065	16.4182
218.688	15.088
222.312	14.9203
225.933	14.3123
229.552	14.4558
233.171	12.5317
236.787	13.5302
240.402	13.217
244.015	12.2158
247.627	11.5511
251.24	10.3543
254.849	9.77832
258.457	9.53839
262.063	8.36943
265.668	7.6094
269.271	7.85416
272.873	9.91151
276.474	12.6308
280.073	11.9777
283.671	11.4235
287.268	10.876
290.863	11.7044
294.456	10.6069
298.049	14.6258
301.637	16.4846
305.227	20.2523
308.815	20.8799
312.402	21.8956
315.987	22.5709
319.569	24.927
323.151	25.9626
326.733	27.4794
330.31	25.714
333.889	24.5987
337.464	23.7151
341.039	20.5616
344.611	18.3039
348.184	15.4208
351.754	13.3278
355.324	13.2474
358.89	11.0887
362.455	10.7729
366.021	8.44127
369.584	7.78918
373.145	4.91091
376.707	3.99888
380.265	1.13151
383.822	1.7818
387.378	3.98572
390.934	4.64152
394.487	4.38539
398.038	3.85088
401.588	5.55511
405.137	5.20898
408.685	6.48932
412.23	6.78096
415.775	9.73872
419.318	10.9646
422.86	12.2915
426.401	12.9786
429.94	15.3367
433.478	16.6376
437.012	19.607
440.547	19.9335
444.081	21.3351
447.613	22.0422
451.142	23.4766
454.672	23.3613
458.2	25.3388
461.725	24.1309
465.251	25.0879
468.775	25.7288
472.296	26.5327
475.817	26.1312
479.335	28.3276
482.854	26.4527
486.37	23.9485
489.886	24.287
493.398	23.6307
496.91	26.1945
500.422	28.8554
503.93	30.369
507.438	32.8388
510.946	34.066
514.45	37.2923
517.954	38.2107
521.456	40.1521
524.956	42.6052
528.456	45.4672
531.956	46.6465
535.452	48.2001
538.947	48.5923
542.441	49.6164
545.934	48.4763
549.425	48.6859
552.915	47.5003
556.403	46.5475
559.889	41.2538
563.375	35.3819
566.859	32.8869
570.342	26.8638
573.824	21.1962
577.303	17.3093
580.782	14.633
584.26	14.0896
587.734	12.4847
591.21	11.4538
594.684	11.5828
598.154	11.3805
601.626	11.9328
605.094	14.0516
608.562	16.7233
612.027	19.5586
615.493	21.3861
618.956	20.8199
622.419	22.3835
625.879	21.3327
629.338	22.0762
632.797	24.8967
636.254	25.5016
639.708	23.9079
643.162	21.8605
646.614	17.8165
650.067	16.7616
653.516	15.144
656.964	13.1139
660.411	12.5668
663.857	11.3886
667.301	10.0609
670.744	8.71621
674.186	10.0324
677.626	9.73723
681.065	12.5688
684.503	12.1962
687.939	12.1882
691.372	11.267
694.806	12.0741
698.239	10.6702
701.67	10.1022
705.098	11.678
708.526	14.7669
711.954	16.8233
715.378	18.7377
718.802	20.9772
722.226	19.8875
725.646	20.4456
729.067	19.8151
732.484	21.0708
735.902	23.5281
739.317	26.0655
742.731	28.5929
746.145	32.1593
749.556	34.5441
752.966	38.7856
756.377	46.4635
759.784	49.713
763.19	50.9266
766.594	53.324
770	53.5399
773.402	51.5774
776.803	51.8325
780.202	53.1032
783.6	51.5729
786.997	55.9518
790.393	55.8332
793.787	54.0735
797.18	52.9467
800.572	53.2176
803.963	54.5226
807.35	53.1773
810.738	52.9816
814.125	52.25
817.51	54.5971
820.894	58.7996
824.275	63.4833
827.657	66.5413
831.037	70.7807
834.414	76.949
837.792	81.1843
841.167	84.1361
844.542	83.2368
847.914	83.4506
851.287	84.6031
854.656	83.5648
858.026	84.2868
861.393	82.8948
864.761	81.8768
868.125	81.2331
871.489	81.9299
874.85	78.8537
878.213	76.3749
881.572	75.7394
884.931	71.5245
888.287	66.8579
891.643	62.4282
894.997	58.7347
898.352	60.4202
901.704	63.742
905.055	62.7967
908.404	62.115
911.75	62.7686
915.097	63.5897
918.443	64.0862
921.787	62.6886
925.13	60.2465
928.472	60.2997
931.813	60.0903
935.15	56.9779
938.488	53.4372
941.825	48.6991
945.158	46.1178
948.493	40.9424
951.824	36.0015
955.156	32.2711
958.486	26.4066
961.814	23.8626
965.142	24.7344
968.467	26.8555
971.79	30.3789
975.115	34.7447
978.436	39.0757
981.756	43.0694
985.077	44.6105
988.394	45.815
991.71	46.8444
995.025	48.2985
998.341	47.6029
1001.65	46.1825
1004.97	44.7976
1008.28	45.9347
1011.58	51.8741
1014.89	56.5609
1018.2	59.378
1021.5	64.6872
1024.81	72.9979
1028.11	84.5965
1031.41	97.5466
1034.71	108.392
1038.01	119.498
1041.31	130.156
1044.6	138.817
1047.9	147.564
1051.19	150.2
1054.48	151.069
1057.77	151.066
1061.06	150.881
1064.35	146.953
1067.64	143.795
1070.93	135.669
1074.21	123.281
1077.49	111.739
1080.78	101.768
1084.06	89.3769
1087.34	79.4541
1090.61	77.5688
1093.89	78.8308
1097.17	77.1852
1100.44	80.2742
1103.71	86.4427
1106.99	91.9911
1110.26	91.0477
1113.52	89.466
1116.79	84.7251
1120.06	80.6891
1123.32	76.0028
1126.59	69.102
1129.85	62.1065
1133.11	57.1358
1136.37	52.2948
1139.63	48.5537
1142.89	43.438
1146.15	37.5707
1149.4	27.6521
1152.66	17.8105
1155.91	10.246
1159.16	2.04748
1162.41	-6.61725
1165.66	-10.7811
1168.91	-5.90267
1172.16	-0.196312
1175.4	1.80121
1178.65	3.25373
1181.89	6.21989
1185.13	7.89453
1188.37	9.50802
1191.61	9.34058
1194.85	13.9529
1198.08	15.6903
1201.32	18.2939
1204.55	24.3447
1207.79	25.3707
1211.02	31.899
1214.25	36.7378
1217.48	43.6727
1220.71	49.2944
1223.93	55.2381
1227.16	59.6069
1230.38	66.0529
1233.6	71.5627
1236.83	79.6326
1240.05	87.4057
1243.26	95.674
1246.48	103.694
1249.7	106.482
1252.92	107.817
1256.13	111.15
1259.34	121.264
1262.55	135.553
1265.76	148.311
1268.97	164.075
1272.18	178.573
1275.39	191.091
1278.59	205.075
1281.8	216.7
1285	226.829
1288.2	235.229
1291.4	243.812
1294.6	248.388
1297.8	249.432
1301	249.994
1304.19	249.316
1307.39	247.807
1310.58	244.684
1313.77	238.862
1316.96	230.389
1320.15	220.008
1323.34	207.803
1326.53	196.036
1329.72	182.183
1332.9	174.441
1336.08	172.292
1339.27	172.753
1342.45	170.509
1345.63	168.889
1348.8	167.009
1351.98	165.831
1355.16	165.384
1358.33	163.43
1361.51	160.619
1364.68	161.064
1367.85	160.348
1371.02	159.417
1374.19	157.731
1377.36	161.39
1380.52	163.884
1383.69	167.776
1386.85	170.439
1390.02	173.023
1393.18	175.185
1396.34	178.353
1399.5	182.95
1402.65	194.132
1405.81	208.957
1408.97	226.59
1412.12	250.135
1415.27	273.476
1418.43	299.164
1421.58	325.815
1424.73	351.29
1427.87	380.497
1431.02	406.332
1434.17	429.636
1437.31	446.165
1440.46	460.729
1443.6	469.472
1446.74	471.584
1449.88	469.584
1453.02	461.929
1456.16	446.796
1459.29	425.014
1462.43	399.684
1465.56	367.697
1468.69	332.937
1471.83	296.509
1474.95	263.729
1478.08	233.735
1481.21	205.727
1484.34	182.18
1487.47	157.679
1490.59	135.405
1493.71	117.562
1496.84	102.14
1499.96	87.9293
1503.07	79.8239
1506.19	71.7721
1509.31	65.77
1512.43	61.6481
1515.54	58.3522
1518.65	58.7261
1521.77	60.0327
1524.88	60.4059
1527.99	62.9125
1531.1	65.2575
1534.21	68.2562
1537.31	71.1129
1540.42	74.0362
1543.52	77.3642
1546.63	82.5564
1549.73	88.539
1552.83	93.2817
1555.93	99.7631
1559.03	105.131
1562.12	111.162
1565.22	117.911
1568.31	126.151
1571.41	132.793
1574.5	139.946
1577.59	149.022
1580.68	157.214
1583.77	168.425
1586.86	177.892
1589.95	184.358
1593.03	192.693
1596.11	198.274
1599.2	201.923
1602.28	204.114
1605.36	204.776
1608.44	207.366
1611.52	206.981
1614.6	205.469
1617.67	204.382
1620.75	203.414
1623.82	204.364
1626.89	205.046
1629.96	207.566
1633.04	205.351
1636.11	205.373
1639.17	205.447
1642.24	207.249
1645.31	207.267
1648.37	207.962
1651.43	209.438
1654.5	206.885
1657.56	204.193
1660.62	200.4
1663.67	192.285
1666.73	184.673
1669.79	174.953
1672.84	164.301
1675.9	153.051
1678.95	142.325
1682	130.628
1685.05	119.205
1688.1	109.337
1691.15	100.556
1694.2	92.447
1697.25	86.3328
1700.29	80.6879
1703.33	75.0573
1706.38	70.5485
1709.42	65.2762
1712.46	61.0217
1715.5	57.4368
1718.54	55.6534
1721.57	53.2202
1724.61	51.4213
1727.64	47.6961
1730.68	44.316
1733.71	40.9089
1736.74	37.2429
1739.77	34.4846
1742.8	30.9581
1745.83	27.8992
1748.85	24.3008
1751.88	22.2147
1754.91	19.87
1757.93	17.5117
1760.95	15.0714
1763.97	14.9506
1766.99	12.2693
1770.01	10.4607
1773.03	9.64636
1776.04	8.61751
1779.06	8.97991
1782.07	7.9086
1785.09	6.33888
1788.1	6.21777
1791.11	5.19312
1794.12	4.3025
1797.13	2.9619
1800.13	3.02763
1803.14	1.42407
1806.15	0.816361
1809.15	0.592815
1812.15	0.428903
1815.16	-0.190105
1818.15	-0.489816
1821.16	-0.778005
1824.15	-0.794381
1827.15	1.25911
1830.15	0.421479
1833.14	0.185121
1836.14	1.66819
1839.13	2.41891
1842.12	3.09297
1845.11	4.03078
1848.1	6.30025
1851.09	7.60251
1854.08	7.57015
1857.06	6.67841
1860.05	6.55953
1863.03	6.93755
1866.01	8.57417
1869	7.66493
1871.98	6.74694
1874.96	7.87868
1877.93	7.26361
1880.91	6.79305
1882.47	4.95037
1885.46	4.74652
1888.44	4.75874
1891.43	3.62588
1894.42	3.16173
1897.4	3.79469
1900.39	2.29496
1903.37	1.38611
1906.35	1.79791
1909.33	2.26997
1912.31	1.56702
1915.29	2.02105
1918.26	2.36686
1921.24	1.37777
1924.21	0.382732
1927.19	1.83866
1930.16	3.22047
1933.13	3.58188
1936.1	4.7326
1939.07	3.75126
1942.04	3.98633
1945	3.95972
1947.97	4.99388
1950.93	4.62866
1953.9	5.45924
1956.86	7.22663
1959.82	8.63467
1962.78	8.1767
1965.74	9.04234
1968.7	8.36302
1971.65	7.70625
1974.61	6.06858
1977.57	6.52559
1980.52	5.90944
1983.47	5.57414
1986.42	5.40855
1989.37	5.43001
1992.32	3.70968
1995.27	5.1055
1998.22	5.2939
2001.17	4.99613
2004.11	4.70498
2007.05	3.99893
2010	3.78109
2012.94	4.027
2015.88	4.23862
2018.82	5.56662
2021.76	7.72313
2024.7	7.83274
2027.63	11.1315
2030.57	12.6711
2033.5	12.7739
2036.44	13.3054
2039.37	14.0981
2042.3	14.7818
2045.23	16.1022
2048.16	15.8824
2051.08	17.201
2054.01	17.7198
2056.94	19.3918
2059.86	20.7066
2062.79	21.4082
2065.71	21.6834
2068.63	23.3764
2071.55	24.0148
2074.47	25.3871
2077.39	26.9493
2080.31	27.9347
2083.22	30.9398
2086.13	33.4973
2089.05	37.0686
2091.96	41.2879
2094.87	43.8841
2097.78	47.6495
2100.69	51.2128
2103.6	53.7522
2106.51	56.9112
2109.42	61.6395
2112.32	63.8712
2115.23	68.7289
2118.13	72.0062
2121.03	76.5044
2123.93	81.7235
2126.83	86.9449
2129.73	92.3537
2132.63	96.5464
2135.53	102.851
2138.42	108.065
2141.32	117.427
2144.21	124.31
2147.1	129.757
2150	137.573
2152.89	144.781
2155.78	152.401
2158.66	155.756
2161.55	160.552
2164.44	164.252
2167.32	166.945
2170.21	168.121
2173.09	167.717
2175.97	168.049
2178.85	165.788
2181.73	163.144
2184.61	159.955
2187.49	154.245
2190.37	148.452
2193.24	142.671
2196.12	136.454
2198.99	131.236
2201.87	124.551
2204.74	118.944
2207.61	114.267
2210.48	109.434
2213.35	103.763
2216.21	96.0806
2219.08	89.9696
2221.95	85.7524
2224.81	81.6653
2227.67	75.802
2230.54	70.2025
2233.4	66.7064
2236.26	61.0423
2239.11	57.4193
2241.97	53.1249
2244.83	50.6153
2247.69	47.5197
2250.54	42.6329
2253.4	39.2727
2256.25	39.0391
2259.1	35.4701
2261.95	33.4493
2264.8	32.97
2267.65	32.1453
2270.5	29.4747
2273.34	27.7004
2276.19	24.9929
2279.03	23.7537
2281.88	22.8404
2284.72	21.0603
2287.56	20.1863
2290.4	19.7699
2293.24	18.9691
2296.08	18.0226
2298.92	17.3176
2301.76	17.3063
2304.59	16.2612
2307.43	15.5375
2310.26	16.0083
2313.09	15.4762
2315.92	15.2306
2318.75	14.5967
2321.58	14.1796
2324.41	15.8086
2327.24	16.7806
2330.06	16.0304
2332.89	15.8028
2335.71	15.8732
2338.54	13.6022
2341.36	11.7948
2344.18	11.4626
2347	10.1664
2349.82	9.4437
2352.64	9.02576
2355.45	5.12601
2358.27	2.68375
2361.08	1.77082
2363.9	1.58239
2366.71	2.70471
2369.52	4.41755
2372.33	1.88733
2375.14	2.70461
2377.95	1.82383
2380.76	1.88922
2383.57	1.66276
2386.37	1.97774
2389.18	3.00359
2391.98	4.34395
2394.79	4.86232
2397.59	6.88402
2400.39	6.67026
2403.19	7.21857
2405.99	6.9717
2408.78	6.17797
2411.58	5.82969
2414.38	6.82035
2417.17	5.57825
2419.97	5.73642
2422.76	6.72452
2425.55	6.36165
2428.34	7.98
2431.13	9.83553
2433.92	10.0534
2436.71	11.2565
2439.49	12.611
2442.28	14.0941
2445.06	14.4234
2447.85	14.3105
2450.63	14.9897
2453.41	14.144
2456.19	14.7309
2458.97	13.2151
2461.75	12.3896
2464.53	12.2158
2467.31	10.9407
2470.08	8.67657
2472.86	6.43736
2475.63	4.74606
2478.4	4.69407
2481.17	4.08436
2483.94	5.22344
2486.72	4.20516
2489.48	3.43881
2492.25	2.82902
2495.02	3.81837
2497.79	4.35519
2500.55	3.04959
2503.31	3.44508
2506.08	5.45159
2508.84	6.29542
2511.6	5.5669
2514.36	5.69377
2517.12	6.73399
2519.88	8.03901
2522.63	10.2515
2525.39	11.8661
2528.14	12.784
2530.9	14.1258
2533.65	14.4323
2536.4	14.1421
2539.15	14.3259
2541.9	14.2016
2544.65	15.6373
2547.4	15.6152
2550.15	15.0452
2552.89	15.4382
2555.64	15.1424
2558.38	15.0355
2561.12	14.1183
2563.87	13.2521
2566.61	11.8958
2569.35	10.1741
2572.09	11.0109
2574.83	12.1798
2577.56	12.7416
2580.3	13.7905
2583.04	16.6577
2585.77	17.735
2588.5	18.9793
2591.23	19.9898
2593.97	19.6293
2596.7	19.6669
2599.43	18.8002
2602.15	17.7651
2604.88	17.6772
2607.61	17.3855
2610.33	17.8012
2613.06	16.0552
2615.78	13.8906
2618.51	12.0576
2621.23	12.2416
2623.95	11.3264
2626.67	9.70699
2629.39	9.74333
2632.1	10.6485
2634.82	11.2098
2637.54	11.8388
2640.25	14.0763
2642.97	14.9423
2645.68	17.4839
2648.39	17.9836
2651.1	18.699
2653.81	18.5488
2656.52	19.1349
2659.23	19.1344
2661.94	19.8527
2664.64	19.4971
2667.35	19.2887
2670.05	20.7215
2672.76	20.6066
2675.46	21.306
2678.16	20.2532
2680.86	20.4543
2683.56	20.352
2686.26	22.1218
2688.96	23.6242
2691.65	26.6695
2694.35	30.1822
2697.04	34.8901
2699.74	40.6197
2702.43	45.5801
2705.12	51.1199
2707.81	56.9592
2710.5	61.4636
2713.19	65.3532
2715.88	67.5197
2718.57	69.4245
2721.25	70.5724
2723.94	70.2304
2726.62	69.3672
2729.3	65.395
2731.99	61.2009
2734.67	57.5311
2737.35	51.6921
2740.03	46.3561
2742.71	40.8346
2745.38	34.1814
2748.06	26.9447
2750.74	21.3438
2753.41	16.3509
2756.09	11.6061
2758.76	9.29524
2761.43	7.27597
2764.1	5.64711
2766.77	3.61199
2769.44	0.912011
2772.11	2.10865
2774.77	1.72269
2777.44	2.12248
2780.11	2.58034
2782.77	1.61279
2785.43	1.09562
2788.1	0.510701
2790.76	1.01846
2793.42	0.124746
2796.08	-0.182905
2798.74	-2.46862
2801.4	-3.55476
2804.05	-5.48647
2806.71	-9.22607
2809.36	-14.1051
2812.02	-16.791
2814.67	-10.7286
2817.32	7.61319
2819.97	33.6955
2822.62	70.0392
2825.27	112.853
2827.92	162.027
2830.57	215.934
2833.22	273.52
2835.86	332.165
2838.51	390.149
2841.15	444.46
2843.79	496.817
2846.43	544.37
2849.08	596.534
2851.72	656.403
2854.36	719.528
2856.99	781.106
2859.63	837.664
2862.27	884.464
2864.9	924.33
2867.54	954.658
2870.17	974.821
2872.8	992.685
2875.43	1010.23
2878.07	1028.83
2880.7	1049.51
2883.32	1065.22
2885.95	1080.32
2888.58	1090.97
2891.21	1098.36
2893.83	1105.24
2896.46	1104.94
2899.08	1101.49
2901.7	1097.93
2904.32	1095.09
2906.94	1094.96
2909.56	1104.21
2912.18	1121.13
2914.8	1149.46
2917.42	1175.74
2920.03	1196.06
2922.65	1205.67
2925.26	1208.49
2927.88	1203.06
2930.49	1189.04
2933.1	1169.08
2935.71	1143.42
2938.32	1110.56
2940.93	1071.48
2943.54	1028.28
2946.14	978.536
2948.75	926.598
2951.35	875.631
2953.96	821.471
2956.56	770.177
2959.16	719.221
2961.77	669.924
2964.37	628.043
2966.96	587.658
2969.56	553.259
2972.16	523.237
2974.76	492.736
2977.35	462.563
2979.95	432.354
2982.54	401.826
2985.14	370.37
2987.73	338.371
2990.32	306.374
2992.91	275.066
2995.5	245.096
2998.09	218.175
3000.68	190.87
3003.26	163.952
3005.85	140.333
3008.43	118.535
3011.02	97.7709
3013.6	80.5375
3016.19	64.185
3018.77	49.8015
3021.35	39.6917
3023.93	29.6375
3026.5	22.7354
3029.08	17.3735
3031.66	13.1538
3034.24	10.634
3036.81	7.15814
3039.39	7.88941
3041.96	8.78963
3044.53	10.5804
3047.1	12.6335
3049.67	14.5564
3052.24	15.544
3054.81	16.1995
3057.38	17.062
3059.95	16.5018
3062.52	17.0564
3065.08	16.3781
3067.65	15.051
3070.21	14.6291
3072.77	12.7972
3075.33	10.8035
3077.89	8.00735
3080.45	5.70739
3083.01	3.9135
3085.57	2.05627
3088.13	-0.0960837
3090.68	-1.0821
3093.24	-1.12028
3095.79	-2.05564
3098.35	-0.947662
3100.9	0.850957
3103.45	3.38384
3106	7.42922
3108.55	11.4878
3111.1	15.2077
3113.65	19.1619
3116.2	25.1179
3118.75	29.802
3121.29	35.1308
3123.84	42.0012
3126.38	47.9892
3128.92	54.7326
3131.47	61.9221
3134.01	69.3853
3136.55	74.7273
3139.09	80.6984
3141.63	85.8408
3144.17	91.4299
3146.7	97.0154
3149.24	102.917