File: data/Raman/poly_smoothed/Mb_40_24_33_1x_45s_532 nm_x100_100%_600 gr_mm_01.txt
#Acq. time (s)=	45
#Accumulations=	2
#Range (cm-¹)=	200...3150
#Windows=	2
#Auto scanning=	Off
#Autofocus=	Off
#Macrospot=	Off
#AutoExposure=	Off
#Spike filter=	Multiple accum.
#Delay time (s)=	0
#Binning=	1
#Readout mode=	Signal
#DeNoise=	Off
#ICS correction=	On
#Dark correction=	Off
#Inst. Process=	Off
#Detector Gain=	Best Dynamic Range
#Detector ADC=	20 kHz
#Detector temperature (°C)=	-70.08
#Instrument=	LabRAM HR Evol
#Detector=	Synapse
#Objective=	x100
#Grating=	600 gr/mm
#ND Filter=	100%
#Laser (nm)=	532
#Hole=	100.021
#Range=	Auto
#Laser Pol.=	No
#Raman. Pol.=	No
#Laser Pol. (°)=	-0.0007625
#Raman Pol. (°)=	89.9995
#Collection=	Microscope
#StageXY=	Marzhauser
#StageZ=	Marzhauser
#X (µm)=	-2491.9
#Y (µm)=	-92.1
#Z (µm)=	-10.6
#Full time(mm:ss)=	3:19
#Project=
#Sample=
#Site=
#Title=	Mb_40_24_33_2x_45s_532 nm_x100_100%_600 gr_mm
#Remark=
#Date=	14.07.2022 13:07
#Acquired=	14.07.2022 13:07:58
#Base:Fit=	10.08.2022 10:47:00
#Base:Sub=	10.08.2022 10:47:12
#Filter:Polynom=	16.08.2022 10:11:48
#AxisType[0]=Intens
#AxisUnit[0]=Cnt
#AxisType[1]=Spectr
#AxisUnit[1]=1/cm
200.554	41.3003
204.183	33.8978
207.813	28.941
211.439	24.0613
215.065	19.8449
218.688	16.8473
222.312	11.398
225.933	6.82745
229.552	4.57722
233.171	3.66392
236.787	1.85754
240.402	1.93158
244.015	0.973463
247.627	1.22753
251.24	2.83348
254.849	2.62691
258.457	4.47735
262.063	4.1211
265.668	4.31408
269.271	4.81144
272.873	4.77322
276.474	5.0381
280.073	5.91785
283.671	8.32129
287.268	9.17213
290.863	9.40843
294.456	11.1762
298.049	12.6219
301.637	14.7595
305.227	15.6519
308.815	14.7917
312.402	13.0783
315.987	13.6354
319.569	14.3245
323.151	15.7901
326.733	15.7949
330.31	15.397
333.889	15.6819
337.464	16.0614
341.039	15.1742
344.611	14.6905
348.184	13.7926
351.754	11.4226
355.324	8.79951
358.89	7.14908
362.455	7.29567
366.021	5.6363
369.584	6.71569
373.145	6.13326
376.707	5.747
380.265	7.21046
383.822	6.75158
387.378	6.36813
390.934	7.25177
394.487	6.63451
398.038	7.9486
401.588	7.6414
405.137	7.68799
408.685	10.586
412.23	11.6979
415.775	11.0018
419.318	11.4887
422.86	11.6484
426.401	11.4953
429.94	9.23648
433.478	7.65181
437.012	5.18558
440.547	4.34637
444.081	3.04328
447.613	4.38257
451.142	3.99401
454.672	5.17052
458.2	6.28943
461.725	7.2289
465.251	8.949
468.775	9.96059
472.296	11.1897
475.817	14.115
479.335	19.4316
482.854	23.6782
486.37	26.801
489.886	31.2431
493.398	35.0724
496.91	39.7102
500.422	41.1366
503.93	41.9449
507.438	44.8077
510.946	43.5227
514.45	43.2507
517.954	41.3585
521.456	40.7254
524.956	39.9371
528.456	38.7942
531.956	36.6214
535.452	36.3063
538.947	34.5755
542.441	32.7504
545.934	29.7039
549.425	27.0995
552.915	24.47
556.403	21.0374
559.889	18.3046
563.375	16.51
566.859	15.1965
570.342	11.6849
573.824	10.0518
577.303	10.1816
580.782	7.3304
584.26	7.00524
587.734	6.68466
591.21	6.66908
594.684	5.95005
598.154	6.31269
601.626	7.66082
605.094	8.74012
608.562	10.1863
612.027	11.6918
615.493	12.8526
618.956	15.1685
622.419	17.6238
625.879	19.4595
629.338	19.6301
632.797	21.8752
636.254	23.7662
639.708	23.4444
643.162	23.2243
646.614	22.6179
650.067	22.6722
653.516	21.4063
656.964	19.6044
660.411	19.295
663.857	19.7734
667.301	19.5939
670.744	18.8059
674.186	21.636
677.626	21.8459
681.065	23.8409
684.503	25.6629
687.939	27.364
691.372	28.5561
694.806	30.2428
698.239	31.6704
701.67	34.0141
705.098	37.8408
708.526	41.0865
711.954	43.2004
715.378	46.5488
718.802	49.0599
722.226	50.3499
725.646	50.6537
729.067	50.6251
732.484	51.9352
735.902	51.3327
739.317	51.7123
742.731	51.2411
746.145	53.5799
749.556	55.0215
752.966	56.2262
756.377	59.4157
759.784	62.7753
763.19	64.7804
766.594	67.8042
770	68.9887
773.402	70.4485
776.803	71.2314
780.202	72.4428
783.6	75.0007
786.997	78.4875
790.393	81.2999
793.787	82.4144
797.18	83.8177
800.572	84.8385
803.963	86.3087
807.35	86.1606
810.738	86.8246
814.125	88.4159
817.51	89.2636
820.894	90.3965
824.275	88.9049
827.657	89.8665
831.037	89.5275
834.414	89.3048
837.792	88.4069
841.167	88.0048
844.542	86.5971
847.914	85.2293
851.287	82.7237
854.656	79.9747
858.026	76.4503
861.393	73.569
864.761	73.1051
868.125	71.6105
871.489	68.6344
874.85	68.6616
878.213	68.8947
881.572	68.9493
884.931	68.0077
888.287	68.0104
891.643	68.3923
894.997	71.0182
898.352	71.7683
901.704	70.1373
905.055	69.0762
908.404	68.7589
911.75	68.0144
915.097	68.3848
918.443	67.3078
921.787	69.3823
925.13	67.1265
928.472	67.2859
931.813	65.4437
935.15	63.532
938.488	62.0251
941.825	60.8152
945.158	59.5532
948.493	57.6462
951.824	57.3196
955.156	59.9238
958.486	58.5534
961.814	57.549
965.142	58.8888
968.467	61.893
971.79	65.396
975.115	67.5081
978.436	68.8327
981.756	70.664
985.077	71.3171
988.394	74.1751
991.71	76.9145
995.025	77.8764
998.341	80.4474
1001.65	81.8638
1004.97	81.8345
1008.28	81.5813
1011.58	82.9611
1014.89	83.6632
1018.2	85.2448
1021.5	85.2778
1024.81	85.0026
1028.11	83.9566
1031.41	84.3964
1034.71	85.9298
1038.01	82.6669
1041.31	79.8198
1044.6	80.9926
1047.9	81.654
1051.19	80.9337
1054.48	79.6327
1057.77	77.7219
1061.06	77.0715
1064.35	75.6647
1067.64	74.7572
1070.93	72.8081
1074.21	71.0746
1077.49	68.191
1080.78	67.0691
1084.06	65.4153
1087.34	65.1296
1090.61	63.0468
1093.89	64.7079
1097.17	63.7696
1100.44	63.1132
1103.71	60.9316
1106.99	60.8951
1110.26	59.1148
1113.52	57.3467
1116.79	54.6538
1120.06	50.0602
1123.32	47.3381
1126.59	46.4665
1129.85	45.1939
1133.11	42.759
1136.37	40.6809
1139.63	39.2588
1142.89	36.4393
1146.15	31.6601
1149.4	27.6019
1152.66	24.0073
1155.91	19.9525
1159.16	16.4903
1162.41	13.1893
1165.66	11.4236
1168.91	8.80523
1172.16	9.34959
1175.4	9.60417
1178.65	9.24615
1181.89	9.11045
1185.13	10.7045
1188.37	11.3733
1191.61	11.3538
1194.85	12.4316
1198.08	13.281
1201.32	15.3013
1204.55	19.1865
1207.79	23.4199
1211.02	26.2099
1214.25	30.7205
1217.48	35.0034
1220.71	40.4318
1223.93	45.2032
1227.16	51.0211
1230.38	56.5107
1233.6	62.2571
1236.83	66.8844
1240.05	72.4629
1243.26	78.69
1246.48	85.7089
1249.7	91.974
1252.92	98.9599
1256.13	103.21
1259.34	107.698
1262.55	111.441
1265.76	115.04
1268.97	120.005
1272.18	123.114
1275.39	126.049
1278.59	127.649
1281.8	130.392
1285	133.769
1288.2	133.937
1291.4	134.95
1294.6	136.682
1297.8	136.443
1301	136.903
1304.19	137.418
1307.39	136.11
1310.58	133.432
1313.77	132.483
1316.96	129.566
1320.15	126.783
1323.34	123.961
1326.53	121.03
1329.72	117.146
1332.9	111.078
1336.08	104.522
1339.27	99.0903
1342.45	93.2886
1345.63	89.1844
1348.8	82.899
1351.98	77.643
1355.16	73.5836
1358.33	68.8917
1361.51	63.7498
1364.68	60.7393
1367.85	56.6783
1371.02	53.451
1374.19	50.607
1377.36	48.4835
1380.52	48.0085
1383.69	47.0613
1386.85	47.7185
1390.02	49.2773
1393.18	50.0998
1396.34	51.3517
1399.5	52.3681
1402.65	54.9647
1405.81	58.7768
1408.97	61.6865
1412.12	66.0738
1415.27	71.9156
1418.43	78.9507
1421.58	86.1572
1424.73	95.0147
1427.87	105.471
1431.02	115.854
1434.17	125.371
1437.31	133.873
1440.46	140.477
1443.6	143.363
1446.74	143.823
1449.88	142.183
1453.02	141.888
1456.16	138.96
1459.29	134.259
1462.43	127.19
1465.56	118.985
1468.69	107.14
1471.83	95.1425
1474.95	82.8021
1478.08	70.0097
1481.21	59.0121
1484.34	48.2273
1487.47	37.5483
1490.59	27.9632
1493.71	19.53
1496.84	14.395
1499.96	9.5857
1503.07	6.06061
1506.19	4.22137
1509.31	1.79789
1512.43	-1.27397
1515.54	-2.99194
1518.65	-3.62647
1521.77	-5.64527
1524.88	-3.98775
1527.99	-2.83889
1531.1	-1.06384
1534.21	1.38766
1537.31	2.63225
1540.42	5.54229
1543.52	7.17791
1546.63	9.2862
1549.73	14.0508
1552.83	19.2463
1555.93	24.0888
1559.03	28.1157
1562.12	32.0332
1565.22	35.7001
1568.31	41.5131
1571.41	46.9664
1574.5	53.1647
1577.59	58.9215
1580.68	66.741
1583.77	71.3678
1586.86	76.9473
1589.95	82.1286
1593.03	85.7004
1596.11	86.929
1599.2	89.3526
1602.28	90.0018
1605.36	91.3677
1608.44	91.3503
1611.52	94.1319
1614.6	94.9736
1617.67	97.1895
1620.75	98.9379
1623.82	103.991
1626.89	107.669
1629.96	112.305
1633.04	117.555
1636.11	124.382
1639.17	131.881
1642.24	138.574
1645.31	143.916
1648.37	150.244
1651.43	155.641
1654.5	160.852
1657.56	162.963
1660.62	163.407
1663.67	160.228
1666.73	156.195
1669.79	149.384
1672.84	141.441
1675.9	133.163
1678.95	122.027
1682	111.278
1685.05	100.406
1688.1	89.5184
1691.15	77.7751
1694.2	66.762
1697.25	57.2929
1700.29	49.5335
1703.33	43.6595
1706.38	39.9463
1709.42	36.5016
1712.46	32.8208
1715.5	29.1656
1718.54	25.7055
1721.57	23.7805
1724.61	23.3972
1727.64	23.5199
1730.68	23.713
1733.71	22.9715
1736.74	22.7298
1739.77	23.5469
1742.8	23.1775
1745.83	22.8324
1748.85	22.3718
1751.88	22.111
1754.91	22.5813
1757.93	22.6292
1760.95	22.2322
1763.97	21.2792
1766.99	20.8545
1770.01	21.4042
1773.03	22.2672
1776.04	23.4996
1779.06	24.8651
1782.07	25.1874
1785.09	25.9004
1788.1	24.6367
1791.11	23.7578
1794.12	23.2882
1797.13	24.1775
1800.13	23.9913
1803.14	24.6329
1806.15	25.3778
1809.15	24.635
1812.15	25.0226
1815.16	26.2848
1818.15	25.5771
1821.16	25.3727
1824.15	26.0034
1827.15	27.1501
1830.15	29.622
1833.14	31.293
1836.14	32.0814
1839.13	33.5774
1842.12	34.4815
1845.11	33.7201
1848.1	33.7981
1851.09	32.1042
1854.08	31.6945
1857.06	30.7351
1860.05	31.5833
1863.03	29.4551
1866.01	28.4053
1869	26.8068
1871.98	25.5051
1874.96	23.1917
1877.93	22.053
1880.91	22.2461
1882.47	21.7886
1885.46	20.5405
1888.44	19.2036
1891.43	19.489
1894.42	20.0386
1897.4	20.5249
1900.39	21.8081
1903.37	20.9926
1906.35	21.9424
1909.33	20.616
1912.31	21.0482
1915.29	19.7837
1918.26	18.03
1921.24	16.9259
1924.21	16.7308
1927.19	15.2478
1930.16	15.6041
1933.13	12.8632
1936.1	11.0815
1939.07	7.93446
1942.04	5.89538
1945	3.94173
1947.97	4.95091
1950.93	4.7262
1953.9	6.32571
1956.86	4.68664
1959.82	3.66272
1962.78	1.40187
1965.74	4.13466
1968.7	6.38798
1971.65	5.77448
1974.61	7.85133
1977.57	9.50706
1980.52	9.2447
1983.47	12.1304
1986.42	14.2506
1989.37	16.7104
1992.32	17.4769
1995.27	18.1948
1998.22	18.3669
2001.17	18.4983
2004.11	18.4269
2007.05	17.0949
2010	16.7548
2012.94	17.6279
2015.88	17.3357
2018.82	17.1555
2021.76	18.0406
2024.7	19.2751
2027.63	19.0275
2030.57	18.7108
2033.5	20.065
2036.44	22.5884
2039.37	25.0802
2042.3	25.7464
2045.23	27.804
2048.16	31.5085
2051.08	33.001
2054.01	37.1811
2056.94	40.3274
2059.86	42.2727
2062.79	42.9867
2065.71	44.0424
2068.63	46.9721
2071.55	46.8059
2074.47	48.7566
2077.39	49.6083
2080.31	49.6752
2083.22	52.7098
2086.13	53.3026
2089.05	52.7277
2091.96	54.1262
2094.87	55.9212
2097.78	59.5312
2100.69	62.1564
2103.6	66.6396
2106.51	69.9654
2109.42	76.5999
2112.32	82.0148
2115.23	89.1728
2118.13	95.1832
2121.03	102.542
2123.93	110.354
2126.83	114.829
2129.73	122.54
2132.63	130.68
2135.53	141.401
2138.42	150.029
2141.32	160.224
2144.21	169.371
2147.1	176.72
2150	184.304
2152.89	190.264
2155.78	197.775
2158.66	204.855
2161.55	211.553
2164.44	215.471
2167.32	219.665
2170.21	221.553
2173.09	221.508
2175.97	222.221
2178.85	220.423
2181.73	217.363
2184.61	214.722
2187.49	208.679
2190.37	202.034
2193.24	195.828
2196.12	188.295
2198.99	179.949
2201.87	173.959
2204.74	164.938
2207.61	154.732
2210.48	146.442
2213.35	136.552
2216.21	127.818
2219.08	118.547
2221.95	111.691
2224.81	103.753
2227.67	99.7132
2230.54	92.9948
2233.4	85.3716
2236.26	78.7456
2239.11	74.0342
2241.97	69.2334
2244.83	65.6996
2247.69	63.1239
2250.54	60.4242
2253.4	58.2609
2256.25	56.4778
2259.1	54.1011
2261.95	52.8664
2264.8	50.5422
2267.65	49.0089
2270.5	47.1058
2273.34	44.4888
2276.19	41.0653
2279.03	39.1563
2281.88	37.7806
2284.72	33.712
2287.56	31.0637
2290.4	27.5523
2293.24	26.014
2296.08	26.3256
2298.92	26.0502
2301.76	23.9696
2304.59	24.3355
2307.43	24.1861
2310.26	23.9049
2313.09	20.8902
2315.92	21.4626
2318.75	18.0633
2321.58	17.2183
2324.41	15.7064
2327.24	15.9303
2330.06	15.2802
2332.89	13.674
2335.71	13.5949
2338.54	14.3078
2341.36	12.8659
2344.18	8.91284
2347	7.92389
2349.82	5.11002
2352.64	2.30852
2355.45	1.67553
2358.27	1.53703
2361.08	3.40062
2363.9	6.92153
2366.71	8.17026
2369.52	7.70441
2372.33	9.03438
2375.14	8.55265
2377.95	8.19866
2380.76	6.65625
2383.57	6.89077
2386.37	7.64525
2389.18	7.74115
2391.98	8.41358
2394.79	8.57186
2397.59	10.0499
2400.39	9.39161
2403.19	10.3778
2405.99	7.70676
2408.78	5.23559
2411.58	4.85877
2414.38	4.26429
2417.17	5.75176
2419.97	5.67915
2422.76	7.98757
2425.55	8.40072
2428.34	9.82028
2431.13	11.582
2433.92	11.8359
2436.71	11.2753
2439.49	10.6742
2442.28	10.6779
2445.06	11.5889
2447.85	12.5698
2450.63	12.1329
2453.41	12.2787
2456.19	11.2559
2458.97	10.4419
2461.75	7.23194
2464.53	5.50275
2467.31	3.20166
2470.08	3.3876
2472.86	2.64591
2475.63	2.97297
2478.4	3.83522
2481.17	4.25743
2483.94	4.76783
2486.72	5.37182
2489.48	5.65399
2492.25	5.1041
2495.02	5.85533
2497.79	6.72316
2500.55	7.44389
2503.31	8.05001
2506.08	7.49745
2508.84	6.46051
2511.6	8.41393
2514.36	7.14616
2517.12	7.32075
2519.88	7.96832
2522.63	5.39494
2525.39	4.7876
2528.14	6.26212
2530.9	5.35469
2533.65	6.02627
2536.4	7.83257
2539.15	9.22275
2541.9	10.4309
2544.65	12.5408
2547.4	12.6135
2550.15	12.5924
2552.89	14.1653
2555.64	15.2778
2558.38	14.657
2561.12	14.2417
2563.87	15.4115
2566.61	18.1513
2569.35	15.6106
2572.09	13.8527
2574.83	11.904
2577.56	10.8381
2580.3	9.63328
2583.04	8.35357
2585.77	7.09877
2588.5	5.27136
2591.23	6.05019
2593.97	7.75668
2596.7	7.23663
2599.43	6.31954
2602.15	9.4044
2604.88	10.9407
2607.61	11.9367
2610.33	12.6654
2613.06	13.7116
2615.78	14.5869
2618.51	15.8324
2621.23	16.5599
2623.95	17.0161
2626.67	15.7385
2629.39	16.4235
2632.1	17.2843
2634.82	17.8592
2637.54	16.1762
2640.25	18.0416
2642.97	17.7
2645.68	16.8891
2648.39	17.2146
2651.1	14.8674
2653.81	14.508
2656.52	13.621
2659.23	13.1547
2661.94	12.5493
2664.64	12.7709
2667.35	10.5982
2670.05	10.399
2672.76	9.3443
2675.46	8.44188
2678.16	10.5196
2680.86	11.6425
2683.56	10.2282
2686.26	9.20924
2688.96	8.44766
2691.65	7.38379
2694.35	8.96798
2697.04	13.5142
2699.74	17.0686
2702.43	19.962
2705.12	22.6258
2707.81	22.5864
2710.5	24.1301
2713.19	24.4845
2715.88	24.6661
2718.57	26.8894
2721.25	26.0233
2723.94	25.8836
2726.62	26.9526
2729.3	25.7922
2731.99	24.2585
2734.67	22.9111
2737.35	23.4383
2740.03	22.6412
2742.71	23.809
2745.38	23.7053
2748.06	22.4843
2750.74	20.2362
2753.41	18.1728
2756.09	17.4332
2758.76	17.7092
2761.43	16.004
2764.1	14.7721
2766.77	12.3902
2769.44	10.8254
2772.11	7.49291
2774.77	6.71555
2777.44	5.34535
2780.11	3.1971
2782.77	3.04556
2785.43	2.54722
2788.1	0.899432
2790.76	1.14629
2793.42	0.936627
2796.08	2.01521
2798.74	2.66967
2801.4	1.83341
2804.05	3.21897
2806.71	3.85396
2809.36	4.64343
2812.02	6.15434
2814.67	6.61927
2817.32	8.60546
2819.97	11.6678
2822.62	16.5009
2825.27	21.4675
2827.92	27.7399
2830.57	35.0727
2833.22	44.2341
2835.86	52.4212
2838.51	62.7469
2841.15	74.0243
2843.79	87.5233
2846.43	102.203
2849.08	116.4
2851.72	133.419
2854.36	150.03
2856.99	166.432
2859.63	184.185
2862.27	199.249
2864.9	213.517
2867.54	226.908
2870.17	239.401
2872.8	249.191
2875.43	259.306
2878.07	269.644
2880.7	277.581
2883.32	287.531
2885.95	296.628
2888.58	305.678
2891.21	316.73
2893.83	328.138
2896.46	339.349
2899.08	353.044
2901.7	369.079
2904.32	386.686
2906.94	407.131
2909.56	428.209
2912.18	451.98
2914.8	475.244
2917.42	496.914
2920.03	517.031
2922.65	534.72
2925.26	550.958
2927.88	558.705
2930.49	564.216
2933.1	566.31
2935.71	560.723
2938.32	551.914
2940.93	539.087
2943.54	523.077
2946.14	504.869
2948.75	485.634
2951.35	461.132
2953.96	439.834
2956.56	414.934
2959.16	391.434
2961.77	369.647
2964.37	347.64
2966.96	324.941
2969.56	305.288
2972.16	285.93
2974.76	266.558
2977.35	248.313
2979.95	228.542
2982.54	209.105
2985.14	193.981
2987.73	176.585
2990.32	158.351
2992.91	140.41
2995.5	121.441
2998.09	104.413
3000.68	88.8618
3003.26	75.7898
3005.85	63.6419
3008.43	53.3937
3011.02	43.3691
3013.6	33.6262
3016.19	27.4451
3018.77	22.9265
3021.35	17.1389
3023.93	12.7045
3026.5	9.05222
3029.08	5.58295
3031.66	3.76117
3034.24	3.94143
3036.81	2.339
3039.39	1.84866
3041.96	2.99905
3044.53	3.03551
3047.1	4.72352
3049.67	6.00147
3052.24	6.97046
3054.81	7.0591
3057.38	7.7979
3059.95	8.50403
3062.52	9.2466
3065.08	10.1082
3067.65	10.2882
3070.21	9.83762
3072.77	7.54643
3075.33	7.05664
3077.89	5.96345
3080.45	4.58409
3083.01	2.88838
3085.57	2.37613
3088.13	1.06724
3090.68	0.00344378
3093.24	1.12512
3095.79	2.58973
3098.35	2.89153
3100.9	3.89174
3103.45	5.66528
3106	7.14888
3108.55	9.08931
3111.1	12.9302
3113.65	14.9793
3116.2	17.4677
3118.75	20.3066
3121.29	22.727
3123.84	25.4521
3126.38	28.1752
3128.92	31.1753
3131.47	35.3085
3134.01	37.454
3136.55	40.7158
3139.09	43.7139
3141.63	47.3784
3144.17	51.2605
3146.7	54.9875
3149.24	60.8028