File: data/Raman/poly_smoothed/Mb_40_y_35_1x_45s_532 nm_x100_100%_600 gr_mm_01.txt
#Acq. time (s)=	45
#Accumulations=	2
#Range (cm-¹)=	200...3150
#Windows=	2
#Auto scanning=	Off
#Autofocus=	Off
#Macrospot=	Off
#AutoExposure=	Off
#Spike filter=	Multiple accum.
#Delay time (s)=	0
#Binning=	1
#Readout mode=	Signal
#DeNoise=	Off
#ICS correction=	On
#Dark correction=	Off
#Inst. Process=	Off
#Detector Gain=	Best Dynamic Range
#Detector ADC=	20 kHz
#Detector temperature (°C)=	-69.85
#Instrument=	LabRAM HR Evol
#Detector=	Synapse
#Objective=	x100
#Grating=	600 gr/mm
#ND Filter=	100%
#Laser (nm)=	532
#Hole=	100.021
#Range=	Auto
#Laser Pol.=	No
#Raman. Pol.=	No
#Laser Pol. (°)=	-0.0007625
#Raman Pol. (°)=	89.9995
#Collection=	Microscope
#StageXY=	Marzhauser
#StageZ=	Marzhauser
#X (µm)=	-1108.8
#Y (µm)=	602.3
#Z (µm)=	583.8
#Full time(mm:ss)=	3:18
#Project=
#Sample=
#Site=
#Title=	Mb_40_y_35_2x_45s_532 nm_x100_100%_600 gr_mm
#Remark=
#Date=	19.07.2022 12:17
#Acquired=	19.07.2022 12:17:01
#Base:Fit=	10.08.2022 10:52:48
#Base:Sub=	10.08.2022 10:52:53
#Filter:Polynom=	16.08.2022 10:09:04
#AxisType[0]=Intens
#AxisUnit[0]=Cnt
#AxisType[1]=Spectr
#AxisUnit[1]=1/cm
200.423	11.0747
204.052	11.4765
207.682	11.1383
211.308	10.0935
214.935	9.81284
218.558	8.66921
222.18	6.38013
225.802	4.47846
229.421	3.13579
233.039	3.42437
236.657	2.90432
240.272	3.25567
243.885	3.85277
247.497	4.93378
251.11	6.00674
254.719	6.54031
258.327	5.07464
261.933	7.84875
265.538	10.7732
269.141	11.3031
272.744	12.8341
276.344	13.1949
279.944	14.4684
283.542	15.6918
287.138	16.5113
290.733	16.3229
294.327	16.94
297.919	16.4382
301.508	16.7433
305.098	15.4927
308.686	13.3062
312.273	12.2224
315.858	11.2065
319.44	12.753
323.022	12.2119
326.604	11.0225
330.181	9.87434
333.76	9.0232
337.335	8.89455
340.91	7.89503
344.483	6.30222
348.055	6.79506
351.625	5.98619
355.195	4.63845
358.762	5.03516
362.329	6.39468
365.893	5.09782
369.455	5.904
373.017	5.76222
376.578	6.44993
380.137	6.09304
383.694	6.15641
387.249	6.70229
390.806	6.32456
394.359	5.46487
397.91	6.07474
401.46	7.01627
405.009	8.14256
408.557	7.59789
412.103	7.72167
415.647	7.22064
419.191	7.41578
422.733	8.1771
426.273	8.99141
429.812	8.03264
433.35	8.44308
436.885	6.75979
440.42	6.73693
443.954	7.99867
447.486	7.79485
451.015	6.74766
454.545	6.61378
458.073	7.68558
461.598	7.04807
465.124	8.00453
468.648	9.06789
472.169	9.76255
475.69	9.95331
479.208	9.95286
482.727	10.0897
486.243	11.3623
489.759	12.5848
493.272	13.3435
496.783	14.0103
500.295	15.5492
503.804	16.2173
507.311	15.6621
510.819	16.3942
514.324	16.663
517.827	16.3548
521.329	16.168
524.83	16.1379
528.329	16.3352
531.829	16.0645
535.326	14.8065
538.821	13.8645
542.315	12.9776
545.808	12.1356
549.299	12.2232
552.789	12.5116
556.278	11.6601
559.763	9.8209
563.249	8.6434
566.733	6.79212
570.217	6.70547
573.699	7.10814
577.177	6.30805
580.656	5.41318
584.134	3.12001
587.609	1.91109
591.084	1.76453
594.558	1.30762
598.029	2.23492
601.5	1.95215
604.968	1.67971
608.437	1.9109
611.902	3.10366
615.368	4.98748
618.831	5.95793
622.294	6.7305
625.755	7.98606
629.213	9.04552
632.673	11.2153
636.129	10.6574
639.584	11.4477
643.037	12.5471
646.491	12.4757
649.942	13.681
653.392	16.0891
656.84	17.6136
660.287	17.6901
663.732	17.0564
667.177	17.8822
670.62	18.9594
674.061	20.4839
677.502	22.8931
680.941	25.0774
684.379	27.2868
687.815	29.7807
691.248	32.1625
694.682	34.9789
698.115	38.4313
701.546	41.5817
704.974	43.3418
708.402	43.1714
711.83	42.993
715.254	42.937
718.679	41.6217
722.102	40.7595
725.522	41.0178
728.943	40.7947
732.361	41.8488
735.779	42.9595
739.194	43.2094
742.608	42.9083
746.022	44.8491
749.433	47.2409
752.843	49.8743
756.254	52.9038
759.661	55.6601
763.067	58.1256
766.471	60.7479
769.877	62.5789
773.279	65.1542
776.68	69.0381
780.079	72.4629
783.478	73.605
786.875	75.1893
790.27	75.3801
793.665	75.1685
797.058	77.3121
800.45	77.442
803.84	76.7751
807.23	77.4512
810.616	77.1412
814.002	78.0043
817.388	77.4831
820.772	77.0591
824.153	77.4245
827.535	77.8409
830.915	77.9053
834.292	77.0077
837.67	74.001
841.047	72.2683
844.42	68.0352
847.794	64.7137
851.165	62.9112
854.534	60.1804
857.905	58.7289
861.272	56.6111
864.639	54.0745
868.004	50.1847
871.367	49.5609
874.731	48.836
878.092	47.5146
881.451	46.9784
884.809	46.8017
888.166	47.1737
891.522	47.184
894.878	48.9223
898.231	49.3164
901.583	50.5494
904.934	50.5676
908.283	50.396
911.631	50.1964
914.976	49.3901
918.322	48.59
921.666	45.6974
925.009	44.5936
928.351	43.7752
931.692	43.671
935.029	42.1983
938.367	40.919
941.704	39.319
945.038	37.2005
948.372	35.573
951.705	34.4357
955.035	34.209
958.366	34.4459
961.693	33.2817
965.021	33.3734
968.346	33.9257
971.67	32.7122
974.995	33.4463
978.316	32.174
981.638	30.0959
984.957	28.4256
988.274	26.4852
991.59	25.4794
994.907	24.1328
998.221	22.6135
1001.53	20.1593
1004.85	18.8877
1008.16	22.1788
1011.46	27.0068
1014.77	33.7038
1018.08	40.5281
1021.38	47.4981
1024.69	55.3601
1027.99	61.6587
1031.29	66.7641
1034.59	72.2524
1037.89	74.9981
1041.19	76.0861
1044.48	77.4028
1047.78	76.634
1051.07	76.0468
1054.36	72.5702
1057.66	69.0758
1060.94	62.3211
1064.23	54.2019
1067.52	46.677
1070.81	40.3901
1074.09	31.848
1077.38	23.8158
1080.66	15.4519
1083.94	9.9886
1087.22	8.40763
1090.5	9.04699
1093.77	10.1396
1097.05	9.58203
1100.32	10.8485
1103.6	11.2006
1106.87	11.7884
1110.14	11.6342
1113.41	13.4252
1116.67	12.6418
1119.94	13.9679
1123.21	14.3313
1126.47	14.2118
1129.73	13.8324
1133	13.6403
1136.26	13.3793
1139.52	12.5745
1142.77	11.9984
1146.03	12.1037
1149.29	12.4719
1152.54	11.4445
1155.79	10.0097
1159.04	9.12895
1162.3	7.83292
1165.55	7.14555
1168.79	5.66914
1172.04	5.19333
1175.28	4.35176
1178.53	2.7078
1181.77	2.9522
1185.01	4.45138
1188.25	4.54738
1191.49	4.60182
1194.73	3.4207
1197.97	4.45513
1201.2	4.64391
1204.44	4.51425
1207.67	5.41398
1210.9	6.55314
1214.13	9.01435
1217.36	11.2804
1220.59	13.1371
1223.82	15.196
1227.04	16.5047
1230.26	18.1355
1233.49	19.5735
1236.71	22.5218
1239.93	23.2595
1243.15	23.8653
1246.37	25.4852
1249.58	26.6101
1252.8	28.4924
1256.01	28.9931
1259.23	31.2135
1262.44	32.4524
1265.65	32.928
1268.86	32.4329
1272.07	34.5114
1275.27	33.0408
1278.48	34.6148
1281.68	35.4024
1284.89	36.1479
1288.09	38.516
1291.29	40.0872
1294.49	40.7088
1297.69	40.1223
1300.88	41.1432
1304.08	42.1802
1307.27	42.1922
1310.47	42.9418
1313.66	43.0887
1316.85	43.0349
1320.04	44.8437
1323.23	46.6019
1326.41	45.5019
1329.6	45.7809
1332.78	44.7396
1335.97	43.532
1339.15	41.5779
1342.33	39.8979
1345.51	36.7847
1348.69	35.9925
1351.87	33.7047
1355.04	31.4531
1358.22	31.4954
1361.39	28.5037
1364.57	27.5988
1367.74	26.188
1370.91	23.1049
1374.07	21.7894
1377.24	20.6491
1380.41	20.7784
1383.57	21.3156
1386.74	22.0628
1389.9	22.4279
1393.06	22.5968
1396.22	24.1432
1399.38	24.8525
1402.54	26.0598
1405.7	27.627
1408.85	28.767
1412.01	29.8036
1415.16	31.1095
1418.31	32.7641
1421.46	34.2612
1424.61	36.9091
1427.76	39.6028
1430.91	41.4726
1434.05	43.811
1437.2	45.4261
1440.34	46.4919
1443.49	46.5829
1446.63	46.1199
1449.77	45.0527
1452.91	45.604
1456.04	46.5086
1459.18	46.4508
1462.31	44.9581
1465.45	43.5901
1468.58	41.7616
1471.71	41.2462
1474.84	40.2374
1477.97	40.4882
1481.1	39.334
1484.23	37.553
1487.35	34.7997
1490.48	32.8832
1493.6	32.2647
1496.72	30.9936
1499.84	29.3376
1502.96	28.3554
1506.08	26.5916
1509.2	25.6835
1512.31	24.614
1515.43	24.1965
1518.54	21.9378
1521.66	21.3347
1524.77	19.6425
1527.88	19.0746
1530.99	18.6819
1534.09	19.6465
1537.2	19.6826
1540.31	20.2173
1543.41	20.9172
1546.51	21.2892
1549.62	22.3036
1552.72	22.0632
1555.82	22.5871
1558.91	22.7746
1562.01	22.4523
1565.11	23.2274
1568.2	24.1988
1571.3	25.6863
1574.39	26.7005
1577.48	27.5368
1580.57	28.8051
1583.66	30.5725
1586.75	32.7727
1589.83	33.0341
1592.92	33.8
1596	34.2303
1599.09	34.5417
1602.17	33.6066
1605.25	33.8664
1608.33	35.3779
1611.41	35.459
1614.48	34.6344
1617.56	34.4846
1620.64	34.5994
1623.71	34.4137
1626.78	34.8031
1629.86	36.2014
1632.92	37.8238
1635.99	39.281
1639.06	41.0809
1642.13	43.0134
1645.19	44.9909
1648.26	45.7892
1651.32	46.9439
1654.38	48.3868
1657.45	49.3151
1660.51	49.756
1663.57	47.7379
1666.62	46.5833
1669.68	45.016
1672.73	43.2491
1675.79	40.6261
1678.84	37.6493
1681.89	34.4829
1684.94	31.4567
1687.99	26.9092
1691.04	24.107
1694.09	22.2781
1697.14	19.1114
1700.18	16.6732
1703.22	15.0636
1706.27	13.9314
1709.31	11.4157
1712.35	10.0248
1715.39	8.16249
1718.43	6.66595
1721.46	7.19625
1724.5	6.91811
1727.53	6.59089
1730.57	6.73361
1733.6	7.02212
1736.63	7.84217
1739.66	8.0728
1742.69	9.12164
1745.72	8.73463
1748.74	8.4774
1751.77	7.46455
1754.8	6.41809
1757.82	6.89153
1760.84	5.91486
1763.86	5.9081
1766.88	6.08762
1769.9	5.25613
1772.92	3.98673
1775.93	3.21884
1778.95	2.39558
1781.96	1.02721
1784.98	0.338124
1787.99	0.659476
1791	1.46452
1794.01	2.10505
1797.02	2.35625
1800.03	2.44254
1803.03	3.61416
1806.04	5.44405
1809.04	6.23651
1812.04	7.45621
1815.05	7.11697
1818.05	6.89589
1821.05	5.92982
1824.05	5.0178
1827.04	5.2633
1830.04	4.9357
1833.03	5.44199
1836.03	4.94372
1839.02	5.14463
1842.01	4.37448
1845	4.53775
1847.99	4.13829
1850.98	3.87478
1853.97	3.41579
1856.95	2.68288
1859.94	3.6278
1862.92	3.78038
1865.91	3.47228
1868.89	2.66932
1871.87	3.63873
1874.85	4.51717
1877.83	5.43792
1880.8	4.64147
1882.56	4.48173
1885.54	4.53545
1888.53	3.35368
1891.52	3.24468
1894.5	3.09508
1897.49	3.59091
1900.47	3.60676
1903.45	3.89677
1906.43	4.13408
1909.41	4.79363
1912.39	5.38506
1915.37	6.34899
1918.35	6.67304
1921.32	6.03886
1924.3	6.72367
1927.27	6.77013
1930.24	7.22427
1933.21	7.82323
1936.18	7.22525
1939.15	7.42065
1942.12	7.5575
1945.09	7.48537
1948.05	7.42868
1951.02	6.01437
1953.98	5.88066
1956.94	5.72249
1959.91	5.22042
1962.87	4.48101
1965.82	4.67158
1968.78	5.08923
1971.74	5.21476
1974.7	5.69853
1977.65	6.25683
1980.6	6.06827
1983.56	6.56356
1986.51	6.30622
1989.46	6.00494
1992.41	5.39018
1995.36	6.17157
1998.3	5.69511
2001.25	5.46715
2004.2	5.92507
2007.14	6.52167
2010.08	6.86101
2013.02	6.88958
2015.97	6.47719
2018.9	5.97783
2021.84	6.78234
2024.78	6.52018
2027.72	7.15726
2030.65	7.48062
2033.59	7.85379
2036.52	8.55044
2039.45	8.31906
2042.38	8.661
2045.31	9.75189
2048.24	9.36312
2051.17	9.0399
2054.1	9.80218
2057.02	10.0457
2059.95	10.9362
2062.87	11.512
2065.79	12.0731
2068.71	13.301
2071.63	14.8249
2074.55	17.015
2077.47	17.6378
2080.39	19.6088
2083.3	21.2184
2086.22	23.0964
2089.13	25.2427
2092.05	26.7616
2094.96	27.7338
2097.87	28.5824
2100.78	29.4899
2103.69	30.8152
2106.59	32.0771
2109.5	32.7567
2112.41	34.0326
2115.31	35.5391
2118.21	36.5676
2121.12	37.014
2124.02	39.2573
2126.92	41.4305
2129.82	42.8251
2132.71	45.7977
2135.61	47.7319
2138.51	50.5445
2141.4	53.5643
2144.29	56.4713
2147.19	59.148
2150.08	61.9982
2152.97	64.8301
2155.86	67.7416
2158.75	70.2868
2161.64	71.5391
2164.52	73.2268
2167.41	74.7583
2170.29	75.0384
2173.17	76.3129
2176.06	76.3305
2178.94	75.8566
2181.82	75.198
2184.7	73.2792
2187.57	70.3296
2190.45	68.7875
2193.33	66.4459
2196.2	65.0457
2199.08	62.6614
2201.95	59.9544
2204.82	56.9484
2207.69	53.9809
2210.56	49.9532
2213.43	46.8266
2216.3	44.1555
2219.16	41.5604
2222.03	38.7016
2224.89	37.0958
2227.75	35.2111
2230.62	33.3036
2233.48	31.6568
2236.34	29.9743
2239.2	27.3613
2242.06	25.5752
2244.91	24.7731
2247.77	23.0449
2250.62	21.5775
2253.48	19.1726
2256.33	17.661
2259.18	15.7858
2262.03	14.8456
2264.88	14.0224
2267.73	12.9565
2270.58	11.6647
2273.43	10.2962
2276.27	8.96532
2279.12	8.20581
2281.96	7.68709
2284.8	8.78826
2287.64	8.90839
2290.49	8.09387
2293.32	7.39771
2296.16	7.91503
2299	8.0676
2301.84	8.19579
2304.67	9.07886
2307.51	9.93279
2310.34	11.4276
2313.17	11.9267
2316	11.4443
2318.83	10.7746
2321.66	10.0687
2324.49	9.84577
2327.32	9.83226
2330.15	9.29917
2332.97	9.68731
2335.79	9.87877
2338.62	9.46885
2341.44	8.27941
2344.26	6.92683
2347.08	6.03979
2349.9	5.51811
2352.72	4.24314
2355.53	3.42564
2358.35	3.1342
2361.17	1.75282
2363.98	2.10446
2366.79	1.60823
2369.6	2.09738
2372.42	3.11002
2375.22	3.46878
2378.03	3.21838
2380.84	3.26762
2383.65	2.7393
2386.45	2.77217
2389.26	3.52894
2392.06	3.84534
2394.87	3.57552
2397.67	3.16532
2400.47	3.99885
2403.27	3.89018
2406.07	4.13238
2408.86	4.2467
2411.66	4.43861
2414.46	5.22761
2417.25	5.54037
2420.05	5.54738
2422.84	5.81668
2425.63	6.93688
2428.42	7.30763
2431.21	7.19928
2434	7.29456
2436.79	6.72452
2439.57	6.98419
2442.36	7.29748
2445.14	6.91738
2447.93	7.62051
2450.71	6.78858
2453.49	5.96074
2456.27	5.37768
2459.05	4.31277
2461.83	3.22346
2464.61	2.67333
2467.39	3.05266
2470.16	2.02539
2472.94	1.68545
2475.71	2.59772
2478.48	2.7
2481.25	2.40399
2484.02	3.07048
2486.8	3.26539
2489.56	3.75656
2492.33	4.26607
2495.1	5.31456
2497.86	5.59556
2500.63	5.54379
2503.39	5.45679
2506.16	5.86352
2508.92	6.82004
2511.68	7.10173
2514.44	6.73977
2517.2	6.05216
2519.95	5.75565
2522.71	5.32129
2525.47	5.15431
2528.22	4.30468
2530.98	5.13274
2533.73	4.45758
2536.48	4.32493
2539.23	4.39891
2541.98	4.88493
2544.73	5.45411
2547.48	5.96497
2550.23	5.95152
2552.97	5.84946
2555.72	6.17188
2558.46	6.53226
2561.2	7.32509
2563.95	8.97361
2566.69	8.39165
2569.43	9.29954
2572.17	9.07694
2574.91	8.38499
2577.64	8.21235
2580.38	7.03701
2583.11	6.4079
2585.85	6.02612
2588.58	4.98314
2591.31	3.75278
2594.04	3.07426
2596.78	2.99208
2599.51	2.41641
2602.23	2.26672
2604.96	1.66148
2607.69	1.99319
2610.41	1.43176
2613.14	1.15929
2615.86	0.748699
2618.58	1.37786
2621.3	2.31769
2624.03	2.86165
2626.75	3.95038
2629.46	5.15736
2632.18	4.8608
2634.9	4.93253
2637.61	5.50064
2640.33	5.07598
2643.04	5.5319
2645.76	5.37549
2648.47	5.08632
2651.18	4.75738
2653.89	4.62867
2656.6	4.0823
2659.31	4.05205
2662.01	3.87995
2664.72	3.49245
2667.43	2.81253
2670.13	3.45476
2672.83	3.54339
2675.53	4.38709
2678.24	4.94947
2680.94	5.42554
2683.64	5.97057
2686.34	6.51686
2689.03	6.62103
2691.73	6.35495
2694.43	6.57084
2697.12	6.53668
2699.81	6.9343
2702.51	7.68942
2705.2	7.11559
2707.89	7.10518
2710.58	6.87606
2713.27	7.30744
2715.96	7.77136
2718.64	7.79914
2721.33	7.10297
2724.01	6.33811
2726.7	5.50755
2729.38	5.24048
2732.06	5.52369
2734.75	5.70447
2737.43	5.28553
2740.11	5.08029
2742.78	4.94645
2745.46	4.195
2748.14	2.88332
2750.81	3.15041
2753.49	2.07711
2756.16	1.81058
2758.84	0.975595
2761.51	1.11102
2764.18	1.0738
2766.85	1.53862
2769.52	1.36502
2772.19	2.35166
2774.85	2.29507
2777.52	2.53189
2780.18	2.65531
2782.85	2.74145
2785.51	2.47322
2788.17	1.77102
2790.84	1.79747
2793.5	2.57065
2796.16	2.46672
2798.81	1.96625
2801.47	1.41763
2804.13	0.896869
2806.79	0.725544
2809.44	0.237209
2812.09	0.0489713
2814.75	-0.207731
2817.4	0.887838
2820.05	1.5505
2822.7	2.08902
2825.35	3.93806
2828	5.79305
2830.65	6.90691
2833.29	9.50494
2835.94	12.5837
2838.58	14.9109
2841.23	18.193
2843.87	22.9625
2846.51	28.1629
2849.15	33.3173
2851.79	37.7371
2854.43	42.4309
2857.07	47.6555
2859.71	51.5398
2862.34	55.7077
2864.98	60.6278
2867.61	64.3121
2870.25	67.7975
2872.88	70.7773
2875.51	73.7272
2878.14	76.0288
2880.77	78.7177
2883.4	81.7229
2886.03	83.7776
2888.65	86.5966
2891.28	90.5051
2893.91	93.0425
2896.53	96.1254
2899.15	101.772
2901.78	108.098
2904.4	114.325
2907.02	121.708
2909.64	128.475
2912.26	135.932
2914.87	143.06
2917.49	150.956
2920.11	156.888
2922.72	162.03
2925.34	166.394
2927.95	170.336
2930.56	172.369
2933.17	173.955
2935.78	174.249
2938.39	172.534
2941	170.556
2943.61	166.714
2946.22	163.064
2948.82	158.484
2951.43	152.702
2954.03	147.274
2956.64	140.258
2959.24	133.288
2961.84	126.278
2964.44	119.696
2967.04	113.835
2969.64	105.653
2972.24	98.3223
2974.83	92.3581
2977.43	86.511
2980.02	79.9112
2982.62	72.6497
2985.21	65.322
2987.8	58.7618
2990.4	52.6886
2992.99	46.0993
2995.57	40.6463
2998.16	35.5537
3000.75	30.0885
3003.34	25.1651
3005.92	21.3592
3008.51	17.7415
3011.09	14.5301
3013.68	11.4014
3016.26	9.20076
3018.84	7.45777
3021.42	5.9655
3024	3.05701
3026.58	1.81387
3029.16	0.807647
3031.73	-0.0131551
3034.31	-0.237895
3036.89	0.539376
3039.46	1.39466
3042.03	2.31661
3044.61	2.31567
3047.18	2.43294
3049.75	2.95461
3052.32	3.66465
3054.89	3.28249
3057.45	3.56083
3060.02	3.68129
3062.59	3.89715
3065.15	3.32313
3067.72	2.7387
3070.28	2.92451
3072.84	1.98511
3075.41	2.10482
3077.97	2.52896
3080.53	1.46046
3083.09	0.390302
3085.64	-1.10951
3088.2	-0.168304
3090.76	-0.466212
3093.31	-0.786058
3095.87	-0.347513
3098.42	0.35196
3100.97	0.945249
3103.53	1.56189
3106.08	0.811903
3108.63	0.977038
3111.18	1.60268
3113.73	3.1149
3116.27	4.41109
3118.82	5.16343
3121.37	6.51923
3123.91	7.18444
3126.45	7.65898
3129	8.75058
3131.54	10.0709
3134.08	11.2706
3136.62	12.2208
3139.16	13.1826
3141.7	13.5564
3144.24	14.452
3146.78	14.6168
3149.31	12.1556