File: data/Raman/poly_smoothed/Mb_40_24_06_1x_45s_532 nm_x100_100%_600 gr_mm_01.txt
#Acq. time (s)=	45
#Accumulations=	2
#Range (cm-¹)=	200...3150
#Windows=	2
#Auto scanning=	Off
#Autofocus=	Off
#Macrospot=	Off
#AutoExposure=	Off
#Spike filter=	Multiple accum.
#Delay time (s)=	0
#Binning=	1
#Readout mode=	Signal
#DeNoise=	Off
#ICS correction=	On
#Dark correction=	Off
#Inst. Process=	Off
#Detector Gain=	Best Dynamic Range
#Detector ADC=	20 kHz
#Detector temperature (°C)=	-70.08
#Instrument=	LabRAM HR Evol
#Detector=	Synapse
#Objective=	x100
#Grating=	600 gr/mm
#ND Filter=	100%
#Laser (nm)=	532
#Hole=	100.021
#Range=	Auto
#Laser Pol.=	No
#Raman. Pol.=	No
#Laser Pol. (°)=	-0.0007625
#Raman Pol. (°)=	89.9995
#Collection=	Microscope
#StageXY=	Marzhauser
#StageZ=	Marzhauser
#X (µm)=	-2527.8
#Y (µm)=	-15.3
#Z (µm)=	-10
#Full time(mm:ss)=	3:19
#Project=
#Sample=
#Site=
#Title=	Mb_40_24_06_2x_45s_532 nm_x100_100%_600 gr_mm
#Remark=
#Date=	14.07.2022 11:08
#Acquired=	14.07.2022 11:08:31
#Base:Fit=	10.08.2022 10:47:00
#Base:Sub=	10.08.2022 10:47:12
#Filter:Polynom=	16.08.2022 10:11:48
#AxisType[0]=Intens
#AxisUnit[0]=Cnt
#AxisType[1]=Spectr
#AxisUnit[1]=1/cm
200.554	39.3523
204.183	30.1284
207.813	21.9881
211.439	17.0634
215.065	13.3804
218.688	11.7142
222.312	9.10651
225.933	6.18075
229.552	5.53582
233.171	3.09773
236.787	3.80363
240.402	4.90714
244.015	4.62931
247.627	6.15163
251.24	8.86004
254.849	11.5405
258.457	11.1315
262.063	10.8834
265.668	13.3216
269.271	13.9338
272.873	13.0692
276.474	11.9884
280.073	13.1403
283.671	12.8639
287.268	14.4801
290.863	15.9268
294.456	15.1904
298.049	16.3067
301.637	17.682
305.227	19.449
308.815	18.973
312.402	17.816
315.987	20.9793
319.569	21.8657
323.151	23.4142
326.733	25.6929
330.31	26.7916
333.889	25.4508
337.464	25.3924
341.039	25.8751
344.611	25.0489
348.184	25.644
351.754	26.7514
355.324	27.0444
358.89	23.4666
362.455	22.6033
366.021	20.2895
369.584	19.2024
373.145	18.6941
376.707	18.3394
380.265	18.2723
383.822	17.124
387.378	16.7289
390.934	15.6735
394.487	14.1625
398.038	12.6343
401.588	12.3964
405.137	11.7395
408.685	12.5605
412.23	14.3177
415.775	13.1422
419.318	12.4552
422.86	11.4616
426.401	12.9387
429.94	14.6983
433.478	14.7587
437.012	14.1929
440.547	13.5681
444.081	13.8638
447.613	14.882
451.142	17.1482
454.672	15.0283
458.2	17.5292
461.725	19.6468
465.251	21.3859
468.775	21.9263
472.296	20.2838
475.817	20.674
479.335	17.508
482.854	16.7627
486.37	16.2397
489.886	15.3315
493.398	16.9928
496.91	15.3186
500.422	14.8111
503.93	14.5643
507.438	16.4431
510.946	15.0435
514.45	15.0219
517.954	16.5301
521.456	14.3772
524.956	15.7448
528.456	16.6641
531.956	16.6347
535.452	16.1647
538.947	18.235
542.441	17.0355
545.934	20.6389
549.425	22.3402
552.915	23.6624
556.403	21.8502
559.889	20.0469
563.375	19.2376
566.859	19.3692
570.342	19.1104
573.824	17.7442
577.303	17.0168
580.782	14.8898
584.26	15.9204
587.734	15.4053
591.21	13.3396
594.684	13.4789
598.154	10.1193
601.626	9.1129
605.094	8.71102
608.562	8.64041
612.027	8.61694
615.493	6.58953
618.956	7.33199
622.419	9.04847
625.879	8.80982
629.338	9.44988
632.797	11.1214
636.254	10.564
639.708	11.1751
643.162	11.7927
646.614	14.2374
650.067	14.104
653.516	13.7918
656.964	14.1992
660.411	11.9582
663.857	9.67402
667.301	10.2456
670.744	11.1983
674.186	10.2394
677.626	10.4078
681.065	11.4078
684.503	11.7952
687.939	9.58838
691.372	12.0051
694.806	13.8578
698.239	13.6344
701.67	14.9252
705.098	14.3431
708.526	17.1358
711.954	17.7169
715.378	18.6791
718.802	20.1094
722.226	19.8976
725.646	18.4594
729.067	19.0888
732.484	19.7406
735.902	18.8522
739.317	21.8261
742.731	22.8512
746.145	24.332
749.556	25.8676
752.966	29.0355
756.377	29.7481
759.784	29.9767
763.19	31.7298
766.594	31.7804
770	31.6051
773.402	32.2751
776.803	36.0803
780.202	39.1118
783.6	40.3283
786.997	43.759
790.393	47.2209
793.787	49.4973
797.18	50.282
800.572	51.4745
803.963	52.765
807.35	52.4505
810.738	52.9249
814.125	53.8039
817.51	55.6321
820.894	57.0869
824.275	58.4063
827.657	56.7424
831.037	59.5948
834.414	58.3122
837.792	56.657
841.167	56.0567
844.542	56.1842
847.914	54.4974
851.287	53.774
854.656	54.7898
858.026	56.225
861.393	56.582
864.761	57.2928
868.125	56.2899
871.489	57.9609
874.85	55.5724
878.213	53.3084
881.572	50.41
884.931	47.949
888.287	44.0253
891.643	40.8125
894.997	38.8507
898.352	36.7783
901.704	34.1085
905.055	33.3611
908.404	31.7702
911.75	30.5753
915.097	30.1913
918.443	28.4137
921.787	28.0843
925.13	28.5757
928.472	28.4312
931.813	28.5145
935.15	30.4434
938.488	33.4462
941.825	32.5939
945.158	31.3685
948.493	30.9257
951.824	30.2781
955.156	29.5553
958.486	25.1733
961.814	24.6647
965.142	25.3551
968.467	24.7429
971.79	25.349
975.115	25.4461
978.436	25.2553
981.756	23.715
985.077	21.3421
988.394	20.5862
991.71	18.7092
995.025	18.3586
998.341	15.9709
1001.65	14.7171
1004.97	14.664
1008.28	14.0042
1011.58	14.8891
1014.89	16.2175
1018.2	17.6971
1021.5	20.5436
1024.81	21.9895
1028.11	24.586
1031.41	26.1719
1034.71	27.1327
1038.01	28.2977
1041.31	31.5826
1044.6	33.6304
1047.9	34.6751
1051.19	35.2228
1054.48	33.5091
1057.77	31.4792
1061.06	28.2778
1064.35	24.9162
1067.64	22.8685
1070.93	20.9224
1074.21	17.3517
1077.49	14.3916
1080.78	10.6591
1084.06	9.21132
1087.34	6.3978
1090.61	5.33584
1093.89	5.68972
1097.17	4.67551
1100.44	5.77847
1103.71	6.05782
1106.99	4.99776
1110.26	5.08814
1113.52	3.6154
1116.79	3.00285
1120.06	3.22124
1123.32	1.82644
1126.59	2.11344
1129.85	2.17402
1133.11	1.29988
1136.37	-0.367427
1139.63	0.147623
1142.89	-0.188162
1146.15	2.4733
1149.4	1.98146
1152.66	3.61254
1155.91	3.61563
1159.16	3.27536
1162.41	4.3624
1165.66	2.60317
1168.91	3.32311
1172.16	3.55144
1175.4	3.70172
1178.65	4.06714
1181.89	3.87248
1185.13	3.36941
1188.37	3.08295
1191.61	3.29945
1194.85	2.18726
1198.08	1.18017
1201.32	0.973296
1204.55	3.74103
1207.79	5.27654
1211.02	5.65211
1214.25	5.8874
1217.48	7.0934
1220.71	9.17969
1223.93	10.2851
1227.16	13.031
1230.38	13.649
1233.6	16.2446
1236.83	17.2283
1240.05	20.9142
1243.26	24.6698
1246.48	27.7264
1249.7	30.5131
1252.92	32.0993
1256.13	33.9303
1259.34	35.6604
1262.55	38.2755
1265.76	40.3849
1268.97	42
1272.18	45.2916
1275.39	45.9775
1278.59	49.1654
1281.8	53.0693
1285	56.672
1288.2	57.2701
1291.4	57.5495
1294.6	59.7975
1297.8	60.7717
1301	61.1763
1304.19	61.8302
1307.39	61.8002
1310.58	61.0928
1313.77	61.4352
1316.96	62.4231
1320.15	61.6072
1323.34	60.0434
1326.53	59.5938
1329.72	56.6269
1332.9	53.9351
1336.08	53.0028
1339.27	52.6881
1342.45	51.4842
1345.63	49.6953
1348.8	48.5143
1351.98	46.0828
1355.16	44.1756
1358.33	44.9228
1361.51	45.9473
1364.68	45.6876
1367.85	46.124
1371.02	48.7347
1374.19	49.5019
1377.36	49.5663
1380.52	51.214
1383.69	52.5852
1386.85	53.3992
1390.02	55.6308
1393.18	58.0252
1396.34	59.9223
1399.5	61.5073
1402.65	64.2282
1405.81	66.0041
1408.97	67.9875
1412.12	71.1657
1415.27	74.8647
1418.43	77.7225
1421.58	82.7031
1424.73	85.6061
1427.87	87.5127
1431.02	90.2872
1434.17	93.7126
1437.31	96.6916
1440.46	100.135
1443.6	102.327
1446.74	102.719
1449.88	100.642
1453.02	99.9092
1456.16	98.3102
1459.29	96.5656
1462.43	93.7692
1465.56	91.1158
1468.69	85.4529
1471.83	79.6984
1474.95	73.5579
1478.08	66.9406
1481.21	58.0083
1484.34	51.7243
1487.47	46.4259
1490.59	40.739
1493.71	37.1455
1496.84	33.2221
1499.96	29.0954
1503.07	25.0959
1506.19	21.1399
1509.31	20.8989
1512.43	18.2011
1515.54	18.6988
1518.65	20.0127
1521.77	19.2337
1524.88	20.1409
1527.99	23.7979
1531.1	26.4563
1534.21	30.578
1537.31	33.1295
1540.42	37.3276
1543.52	37.2783
1546.63	38.6547
1549.73	41.0055
1552.83	41.5421
1555.93	41.6378
1559.03	43.6174
1562.12	46.5537
1565.22	47.9201
1568.31	49.5074
1571.41	51.1473
1574.5	53.7515
1577.59	56.0011
1580.68	57.827
1583.77	60.1242
1586.86	63.2125
1589.95	65.1518
1593.03	68.4799
1596.11	71.1958
1599.2	70.5231
1602.28	71.4271
1605.36	71.5676
1608.44	72.7082
1611.52	71.6991
1614.6	73.0838
1617.67	74.5505
1620.75	72.8085
1623.82	72.4925
1626.89	70.4173
1629.96	70.5572
1633.04	70.3416
1636.11	69.7744
1639.17	71.1068
1642.24	70.118
1645.31	67.8351
1648.37	67.4193
1651.43	67.6416
1654.5	67.0312
1657.56	64.5957
1660.62	62.8817
1663.67	62.6103
1666.73	60.0924
1669.79	57.9072
1672.84	55.1752
1675.9	51.9927
1678.95	50.1315
1682	48.736
1685.05	46.9723
1688.1	44.5222
1691.15	42.3148
1694.2	39.947
1697.25	37.2177
1700.29	34.612
1703.33	32.1304
1706.38	29.787
1709.42	26.9728
1712.46	24.2908
1715.5	21.3608
1718.54	18.6347
1721.57	17.2168
1724.61	15.7161
1727.64	13.7322
1730.68	11.2906
1733.71	9.5274
1736.74	9.57722
1739.77	8.94105
1742.8	7.11381
1745.83	6.62349
1748.85	5.81958
1751.88	4.95101
1754.91	4.89091
1757.93	4.93218
1760.95	3.46317
1763.97	3.12525
1766.99	3.52205
1770.01	3.40273
1773.03	2.34896
1776.04	2.9274
1779.06	1.06884
1782.07	1.4445
1785.09	0.335851
1788.1	1.63124
1791.11	1.33656
1794.12	1.50448
1797.13	2.64496
1800.13	2.32559
1803.14	2.69391
1806.15	3.47613
1809.15	3.85834
1812.15	2.65709
1815.16	3.26566
1818.15	3.85104
1821.16	3.42363
1824.15	4.02899
1827.15	4.27762
1830.15	5.82764
1833.14	5.72081
1836.14	4.06761
1839.13	4.75687
1842.12	4.61452
1845.11	4.11914
1848.1	3.89609
1851.09	4.39261
1854.08	3.27101
1857.06	3.9552
1860.05	3.44525
1863.03	3.70702
1866.01	3.12859
1869	3.35963
1871.98	3.53088
1874.96	4.86501
1877.93	4.35524
1880.91	3.96124
1882.47	3.78204
1885.46	4.07752
1888.44	6.03041
1891.43	5.61498
1894.42	6.25268
1897.4	7.06734
1900.39	7.20955
1903.37	6.10788
1906.35	4.48265
1909.33	3.76868
1912.31	5.03244
1915.29	5.23276
1918.26	5.90833
1921.24	5.94097
1924.21	5.86221
1927.19	6.19302
1930.16	5.19974
1933.13	3.60149
1936.1	3.34117
1939.07	2.75125
1942.04	3.81481
1945	5.52481
1947.97	4.08431
1950.93	4.59195
1953.9	5.48027
1956.86	5.48268
1959.82	5.29094
1962.78	4.70781
1965.74	2.82522
1968.7	2.0126
1971.65	1.61667
1974.61	1.18677
1977.57	-0.341772
1980.52	0.397854
1983.47	1.36737
1986.42	1.85099
1989.37	3.13964
1992.32	3.32478
1995.27	3.93579
1998.22	4.24893
2001.17	2.30122
2004.11	2.67414
2007.05	3.78232
2010	4.44012
2012.94	3.82901
2015.88	5.14985
2018.82	4.84928
2021.76	3.25491
2024.7	4.31756
2027.63	3.87083
2030.57	4.98659
2033.5	5.62125
2036.44	6.1354
2039.37	6.16086
2042.3	8.80037
2045.23	10.9993
2048.16	11.8532
2051.08	13.8446
2054.01	14.535
2056.94	17.1481
2059.86	17.5888
2062.79	18.0841
2065.71	18.9109
2068.63	19.3819
2071.55	19.2196
2074.47	19.3585
2077.39	20.6684
2080.31	20.4841
2083.22	20.9194
2086.13	20.8541
2089.05	20.9786
2091.96	20.3083
2094.87	21.2274
2097.78	22.8748
2100.69	24.3206
2103.6	24.7194
2106.51	24.9459
2109.42	26.0387
2112.32	26.9104
2115.23	28.5423
2118.13	30.1173
2121.03	30.8543
2123.93	31.3782
2126.83	32.2227
2129.73	34.1952
2132.63	33.5548
2135.53	36.336
2138.42	38.0067
2141.32	38.936
2144.21	38.4607
2147.1	42.2733
2150	45.9868
2152.89	47.5873
2155.78	48.4867
2158.66	50.0355
2161.55	51.7458
2164.44	53.5958
2167.32	53.6193
2170.21	54.0625
2173.09	53.0087
2175.97	51.8967
2178.85	51.9039
2181.73	50.9706
2184.61	50.0258
2187.49	49.4116
2190.37	48.2546
2193.24	46.7804
2196.12	45.3745
2198.99	44.1333
2201.87	41.5381
2204.74	40.1287
2207.61	39.0956
2210.48	37.2081
2213.35	36.566
2216.21	36.7555
2219.08	36.5066
2221.95	34.456
2224.81	33.0282
2227.67	31.0753
2230.54	30.8812
2233.4	30.711
2236.26	28.5429
2239.11	25.5627
2241.97	23.9036
2244.83	20.7232
2247.69	19.3794
2250.54	17.9519
2253.4	16.9185
2256.25	16.6117
2259.1	15.1544
2261.95	15.0928
2264.8	14.5679
2267.65	13.5113
2270.5	14.4154
2273.34	13.9675
2276.19	15.37
2279.03	17.0708
2281.88	17.1414
2284.72	17.8516
2287.56	16.9472
2290.4	15.7649
2293.24	14.6235
2296.08	16.388
2298.92	15.9814
2301.76	17.0463
2304.59	17.6701
2307.43	15.7327
2310.26	15.9717
2313.09	14.4327
2315.92	14.5717
2318.75	13.9317
2321.58	13.6596
2324.41	13.5661
2327.24	12.7655
2330.06	11.4967
2332.89	9.83996
2335.71	9.65748
2338.54	8.73757
2341.36	9.46696
2344.18	8.57995
2347	7.74982
2349.82	6.04783
2352.64	5.0525
2355.45	3.42877
2358.27	2.24316
2361.08	2.75314
2363.9	3.66059
2366.71	4.48217
2369.52	4.93025
2372.33	6.41947
2375.14	5.84001
2377.95	3.84504
2380.76	5.57478
2383.57	5.02865
2386.37	6.30654
2389.18	6.73921
2391.98	6.17553
2394.79	5.34588
2397.59	4.81235
2400.39	5.96242
2403.19	5.90669
2405.99	7.03008
2408.78	7.50624
2411.58	8.34004
2414.38	9.30045
2417.17	10.1179
2419.97	11.3352
2422.76	11.6347
2425.55	13.0262
2428.34	12.6285
2431.13	12.3468
2433.92	11.6589
2436.71	11.7411
2439.49	12.1753
2442.28	11.4974
2445.06	10.5268
2447.85	10.5762
2450.63	9.44706
2453.41	8.92056
2456.19	6.97299
2458.97	6.68313
2461.75	5.16251
2464.53	5.52705
2467.31	5.03978
2470.08	5.57743
2472.86	5.66789
2475.63	6.01279
2478.4	6.07136
2481.17	5.9946
2483.94	4.78434
2486.72	5.77526
2489.48	5.44158
2492.25	4.46971
2495.02	3.00835
2497.79	2.95728
2500.55	3.10674
2503.31	2.83142
2506.08	1.8218
2508.84	3.31012
2511.6	3.05947
2514.36	2.75794
2517.12	2.2
2519.88	2.06646
2522.63	3.05033
2525.39	2.78459
2528.14	3.99029
2530.9	5.10011
2533.65	5.83035
2536.4	5.6479
2539.15	5.99664
2541.9	6.91024
2544.65	7.94972
2547.4	8.42111
2550.15	8.91466
2552.89	11.0913
2555.64	11.7398
2558.38	9.86107
2561.12	9.93781
2563.87	10.044
2566.61	10.675
2569.35	11.0609
2572.09	10.1638
2574.83	9.12804
2577.56	9.28295
2580.3	8.108
2583.04	7.16856
2585.77	5.42684
2588.5	5.40635
2591.23	4.3547
2593.97	5.00318
2596.7	5.43197
2599.43	5.29673
2602.15	5.54062
2604.88	5.84228
2607.61	8.2442
2610.33	8.40889
2613.06	8.82912
2615.78	9.85513
2618.51	9.26663
2621.23	9.43934
2623.95	8.24914
2626.67	8.98693
2629.39	10.5631
2632.1	11.9877
2634.82	11.4091
2637.54	10.6967
2640.25	9.89933
2642.97	9.48929
2645.68	8.66796
2648.39	8.69131
2651.1	7.77348
2653.81	6.90331
2656.52	6.14107
2659.23	6.62479
2661.94	6.51514
2664.64	6.14973
2667.35	5.4946
2670.05	5.56154
2672.76	4.23588
2675.46	4.78806
2678.16	4.78735
2680.86	4.35942
2683.56	3.52953
2686.26	4.20474
2688.96	5.38243
2691.65	7.07761
2694.35	8.23019
2697.04	9.24706
2699.74	10.6493
2702.43	10.9519
2705.12	12.2362
2707.81	13.0183
2710.5	13.6813
2713.19	14.5289
2715.88	15.1407
2718.57	14.649
2721.25	15.4875
2723.94	15.1484
2726.62	15.1497
2729.3	14.2324
2731.99	13.7495
2734.67	11.0616
2737.35	10.0525
2740.03	10.9363
2742.71	9.96038
2745.38	8.39334
2748.06	7.38407
2750.74	8.15185
2753.41	9.63537
2756.09	8.34612
2758.76	9.03544
2761.43	8.73885
2764.1	10.2212
2766.77	9.74757
2769.44	9.18655
2772.11	9.03219
2774.77	8.11744
2777.44	7.12038
2780.11	6.3645
2782.77	6.57649
2785.43	4.00662
2788.1	2.6045
2790.76	2.07894
2793.42	1.86949
2796.08	2.22855
2798.74	1.63602
2801.4	3.06887
2804.05	3.59851
2806.71	4.68719
2809.36	4.48978
2812.02	5.5854
2814.67	7.08615
2817.32	8.26328
2819.97	10.8057
2822.62	14.0723
2825.27	18.4013
2827.92	23.7915
2830.57	28.2625
2833.22	32.7399
2835.86	37.9515
2838.51	44.2881
2841.15	51.3622
2843.79	57.836
2846.43	64.7516
2849.08	73.0165
2851.72	81.217
2854.36	89.8209
2856.99	99.44
2859.63	107.681
2862.27	115.772
2864.9	123.068
2867.54	129.94
2870.17	135.543
2872.8	140.67
2875.43	144.425
2878.07	147.245
2880.7	150.3
2883.32	154.949
2885.95	159.542
2888.58	166.054
2891.21	169.513
2893.83	174.316
2896.46	180.294
2899.08	187.95
2901.7	196.563
2904.32	203.515
2906.94	212.029
2909.56	220.885
2912.18	231.17
2914.8	240.795
2917.42	248.729
2920.03	257.804
2922.65	263.77
2925.26	268.081
2927.88	269.679
2930.49	269.928
2933.1	267.073
2935.71	261.461
2938.32	255.071
2940.93	246.507
2943.54	237.467
2946.14	228.27
2948.75	217.44
2951.35	207.276
2953.96	195.74
2956.56	184.783
2959.16	175.777
2961.77	166.752
2964.37	157.539
2966.96	148.199
2969.56	140.418
2972.16	134.059
2974.76	128.126
2977.35	120.822
2979.95	115.316
2982.54	109.582
2985.14	102.662
2987.73	94.7577
2990.32	86.684
2992.91	77.9879
2995.5	70.6091
2998.09	62.4688
3000.68	55.2463
3003.26	47.5757
3005.85	41.3826
3008.43	34.7147
3011.02	28.0906
3013.6	22.3578
3016.19	19.0025
3018.77	14.8735
3021.35	11.299
3023.93	8.52256
3026.5	5.95151
3029.08	3.61481
3031.66	2.27668
3034.24	1.25704
3036.81	1.62921
3039.39	2.08082
3041.96	1.8454
3044.53	3.03686
3047.1	3.90667
3049.67	4.50896
3052.24	3.74347
3054.81	3.75316
3057.38	5.40418
3059.95	6.40158
3062.52	7.04342
3065.08	7.61663
3067.65	6.36885
3070.21	6.76026
3072.77	6.3607
3075.33	6.39775
3077.89	7.68067
3080.45	6.97321
3083.01	6.44976
3085.57	6.04501
3088.13	5.76619
3090.68	4.83326
3093.24	4.09418
3095.79	4.41694
3098.35	3.49981
3100.9	2.51225
3103.45	2.09235
3106	1.26716
3108.55	1.68299
3111.1	0.732061
3113.65	0.573938
3116.2	0.419551
3118.75	1.83736
3121.29	2.5808
3123.84	3.00899
3126.38	3.19815
3128.92	3.58735
3131.47	4.11077
3134.01	6.23627
3136.55	6.99399
3139.09	8.77
3141.63	9.6081
3144.17	10.4392
3146.7	11.15
3149.24	9.26686