File: data/Raman/poly_smoothed/Mb_40_24_31_1x_45s_532 nm_x100_100%_600 gr_mm_01.txt
#Acq. time (s)=	45
#Accumulations=	2
#Range (cm-¹)=	200...3150
#Windows=	2
#Auto scanning=	Off
#Autofocus=	Off
#Macrospot=	Off
#AutoExposure=	Off
#Spike filter=	Multiple accum.
#Delay time (s)=	0
#Binning=	1
#Readout mode=	Signal
#DeNoise=	Off
#ICS correction=	On
#Dark correction=	Off
#Inst. Process=	Off
#Detector Gain=	Best Dynamic Range
#Detector ADC=	20 kHz
#Detector temperature (°C)=	-70.08
#Instrument=	LabRAM HR Evol
#Detector=	Synapse
#Objective=	x100
#Grating=	600 gr/mm
#ND Filter=	100%
#Laser (nm)=	532
#Hole=	100.021
#Range=	Auto
#Laser Pol.=	No
#Raman. Pol.=	No
#Laser Pol. (°)=	-0.0007625
#Raman Pol. (°)=	89.9995
#Collection=	Microscope
#StageXY=	Marzhauser
#StageZ=	Marzhauser
#X (µm)=	-2452
#Y (µm)=	-95.9
#Z (µm)=	-10.7
#Full time(mm:ss)=	3:18
#Project=
#Sample=
#Site=
#Title=	Mb_40_24_31_2x_45s_532 nm_x100_100%_600 gr_mm
#Remark=
#Date=	14.07.2022 12:59
#Acquired=	14.07.2022 12:59:59
#Base:Fit=	10.08.2022 10:47:00
#Base:Sub=	10.08.2022 10:47:12
#Filter:Polynom=	16.08.2022 10:11:48
#AxisType[0]=Intens
#AxisUnit[0]=Cnt
#AxisType[1]=Spectr
#AxisUnit[1]=1/cm
200.554	30.9383
204.183	24.43
207.813	19.6767
211.439	16.3269
215.065	13.9004
218.688	12.3698
222.312	11.5633
225.933	10.539
229.552	11.2515
233.171	10.2663
236.787	10.2972
240.402	9.97684
244.015	8.63479
247.627	9.0951
251.24	10.4005
254.849	11.2224
258.457	10.5531
262.063	11.5223
265.668	13.2909
269.271	13.4442
272.873	12.2758
276.474	10.9469
280.073	9.62461
283.671	8.01471
287.268	5.94763
290.863	5.83744
294.456	6.82919
298.049	5.99335
301.637	5.4093
305.227	6.10453
308.815	6.61301
312.402	7.57241
315.987	8.96621
319.569	11.5359
323.151	12.7068
326.733	14.3113
330.31	15.5364
333.889	16.1002
337.464	17.1432
341.039	16.3494
344.611	16.3561
348.184	15.1256
351.754	15.6075
355.324	14.4814
358.89	11.9796
362.455	11.0776
366.021	11.4155
369.584	9.2396
373.145	8.2497
376.707	7.90192
380.265	7.52005
383.822	7.17304
387.378	7.50741
390.934	8.19961
394.487	8.34949
398.038	9.02482
401.588	11.6437
405.137	11.8969
408.685	12.5742
412.23	12.314
415.775	11.0588
419.318	11.5986
422.86	10.1751
426.401	9.16709
429.94	8.50531
433.478	8.30691
437.012	7.14705
440.547	6.25444
444.081	5.02623
447.613	6.74603
451.142	6.95396
454.672	6.29498
458.2	6.48098
461.725	7.49567
465.251	6.95736
468.775	9.51869
472.296	11.0589
475.817	14.5138
479.335	16.7028
482.854	18.9951
486.37	21.1518
489.886	22.6893
493.398	23.0627
496.91	25.0927
500.422	26.612
503.93	27.663
507.438	28.5974
510.946	28.8423
514.45	30.474
517.954	31.15
521.456	31.5939
524.956	32.1748
528.456	33.0137
531.956	33.7563
535.452	32.9138
538.947	26.5211
542.441	26.2471
545.934	26.5013
549.425	28.1479
552.915	29.4474
556.403	30.2419
559.889	30.0898
563.375	28.3774
566.859	27.3731
570.342	26.3716
573.824	24.2531
577.303	20.9729
580.782	18.6145
584.26	17.7544
587.734	14.3403
591.21	12.8335
594.684	9.39506
598.154	7.87768
601.626	7.84126
605.094	8.27995
608.562	7.46745
612.027	5.92008
615.493	3.36352
618.956	1.13004
622.419	-0.529736
625.879	-1.02335
629.338	4.65242
632.797	6.50226
636.254	6.10077
639.708	6.65826
643.162	4.42004
646.614	7.1959
650.067	7.73875
653.516	6.90994
656.964	6.9428
660.411	7.76401
663.857	9.5561
667.301	8.96242
670.744	8.27383
674.186	9.67214
677.626	11.1993
681.065	12.0367
684.503	16.7775
687.939	19.4138
691.372	20.9861
694.806	23.2286
698.239	24.7235
701.67	27.8181
705.098	29.0554
708.526	31.7924
711.954	33.6813
715.378	35.3525
718.802	35.0431
722.226	34.7923
725.646	35.1053
729.067	36.5119
732.484	39.0339
735.902	39.2372
739.317	40.2158
742.731	42.1224
746.145	44.2451
749.556	45.2528
752.966	48.068
756.377	51.9018
759.784	54.6209
763.19	55.4433
766.594	60.2747
770	64.7674
773.402	66.8043
776.803	69.2916
780.202	72.006
783.6	73.1742
786.997	75.1346
790.393	78.1723
793.787	79.3501
797.18	80.5582
800.572	79.2436
803.963	78.0023
807.35	77.7061
810.738	78.4205
814.125	79.0401
817.51	79.2559
820.894	79.8884
824.275	78.528
827.657	78.7383
831.037	79.6736
834.414	78.6775
837.792	77.6342
841.167	75.6077
844.542	74.6744
847.914	74.8821
851.287	73.7871
854.656	71.7745
858.026	71.427
861.393	68.8893
864.761	65.9373
868.125	65.3133
871.489	64.1819
874.85	62.8174
878.213	60.0921
881.572	59.1982
884.931	56.4585
888.287	56.5805
891.643	55.5318
894.997	56.2648
898.352	57.351
901.704	58.4838
905.055	57.386
908.404	57.6793
911.75	59.7915
915.097	60.0636
918.443	59.8158
921.787	60.6337
925.13	60.5911
928.472	60.4515
931.813	58.7404
935.15	57.6198
938.488	58.0103
941.825	56.2475
945.158	53.8177
948.493	53.2662
951.824	53.5281
955.156	52.8037
958.486	51.7285
961.814	50.3675
965.142	50.6184
968.467	52.3957
971.79	54.9025
975.115	55.7441
978.436	58.1023
981.756	59.7185
985.077	60.511
988.394	60.9725
991.71	61.5599
995.025	61.9282
998.341	61.6865
1001.65	61.5691
1004.97	62.0087
1008.28	60.4297
1011.58	62.7863
1014.89	65.9554
1018.2	69.7129
1021.5	71.0089
1024.81	71.7168
1028.11	73.3026
1031.41	75.074
1034.71	76.1602
1038.01	77.1249
1041.31	77.1162
1044.6	79.1593
1047.9	80.6687
1051.19	80.528
1054.48	79.0197
1057.77	78.1011
1061.06	77.3888
1064.35	73.921
1067.64	68.8382
1070.93	65.7125
1074.21	62.8382
1077.49	59.1152
1080.78	55.4104
1084.06	53.1257
1087.34	51.0633
1090.61	52.1065
1093.89	54.9102
1097.17	53.3524
1100.44	52.8505
1103.71	50.6121
1106.99	49.207
1110.26	47.4033
1113.52	46.6168
1116.79	44.6068
1120.06	42.0515
1123.32	40.025
1126.59	38.7688
1129.85	37.4144
1133.11	36.531
1136.37	35.3045
1139.63	30.8407
1142.89	28.3853
1146.15	25.0451
1149.4	20.7609
1152.66	17.211
1155.91	14.8824
1159.16	9.83476
1162.41	7.69851
1165.66	8.9188
1168.91	9.88165
1172.16	9.93288
1175.4	7.30697
1178.65	6.64965
1181.89	7.9004
1185.13	7.85858
1188.37	9.02534
1191.61	10.5706
1194.85	12.4075
1198.08	15.5806
1201.32	19.4987
1204.55	21.4155
1207.79	24.9464
1211.02	27.6303
1214.25	32.6325
1217.48	34.6868
1220.71	38.1081
1223.93	42.3088
1227.16	45.2194
1230.38	48.8051
1233.6	51.6851
1236.83	54.6634
1240.05	59.1152
1243.26	60.8495
1246.48	63.4304
1249.7	64.1504
1252.92	66.2827
1256.13	67.9912
1259.34	70.6384
1262.55	74.5034
1265.76	77.7663
1268.97	81.5751
1272.18	85.7936
1275.39	89.0672
1278.59	93.1116
1281.8	94.0572
1285	97.0169
1288.2	100.267
1291.4	104.279
1294.6	106.134
1297.8	105.957
1301	106.981
1304.19	107.048
1307.39	105.881
1310.58	103.234
1313.77	102.204
1316.96	99.3108
1320.15	95.3872
1323.34	92.3508
1326.53	88.7765
1329.72	86.298
1332.9	84.2674
1336.08	81.7961
1339.27	78.9392
1342.45	76.0094
1345.63	73.8453
1348.8	72.3055
1351.98	68.9464
1355.16	64.761
1358.33	63.2395
1361.51	61.3905
1364.68	59.4404
1367.85	58.6248
1371.02	56.7691
1374.19	53.9623
1377.36	53.088
1380.52	51.8496
1383.69	53.0272
1386.85	51.9866
1390.02	51.3091
1393.18	52.6697
1396.34	51.3965
1399.5	52.6887
1402.65	54.4865
1405.81	56.2549
1408.97	58.9069
1412.12	63.3633
1415.27	69.2845
1418.43	74.0787
1421.58	80.1327
1424.73	90.4305
1427.87	96.8908
1431.02	104.434
1434.17	111.374
1437.31	117.688
1440.46	122.488
1443.6	127.255
1446.74	129.473
1449.88	129.754
1453.02	128.049
1456.16	125.259
1459.29	120.444
1462.43	113.412
1465.56	103.935
1468.69	94.1854
1471.83	83.8512
1474.95	73.4288
1478.08	63.2491
1481.21	53.8151
1484.34	44.6754
1487.47	36.8221
1490.59	31.7777
1493.71	26.4624
1496.84	21.8385
1499.96	18.6798
1503.07	16.8774
1506.19	15.8326
1509.31	15.0466
1512.43	14.699
1515.54	15.1745
1518.65	15.8323
1521.77	16.4273
1524.88	16.3539
1527.99	17.2876
1531.1	17.4931
1534.21	17.539
1537.31	19.1326
1540.42	20.4026
1543.52	22.365
1546.63	24.2711
1549.73	27.0875
1552.83	28.817
1555.93	30.7055
1559.03	33.1185
1562.12	35.2085
1565.22	38.3054
1568.31	40.3161
1571.41	43.6516
1574.5	46.9248
1577.59	51.1498
1580.68	55.7715
1583.77	58.5419
1586.86	61.0934
1589.95	64.8493
1593.03	66.4839
1596.11	69.2297
1599.2	70.6232
1602.28	71.8504
1605.36	71.141
1608.44	69.9515
1611.52	72.1623
1614.6	73.1986
1617.67	74.7559
1620.75	77.591
1623.82	79.7289
1626.89	83.21
1629.96	86.1754
1633.04	88.2988
1636.11	90.0042
1639.17	92.1728
1642.24	94.4579
1645.31	97.8662
1648.37	99.6781
1651.43	102.22
1654.5	102.593
1657.56	101.894
1660.62	100.718
1663.67	98.7376
1666.73	95.7135
1669.79	91.024
1672.84	85.6813
1675.9	79.1016
1678.95	72.776
1682	66.0531
1685.05	60.9533
1688.1	57.078
1691.15	51.3326
1694.2	46.8717
1697.25	41.739
1700.29	36.5365
1703.33	31.7484
1706.38	26.634
1709.42	22.5506
1712.46	19.8473
1715.5	17.6959
1718.54	15.4652
1721.57	13.7109
1724.61	13.1748
1727.64	11.1718
1730.68	10.1136
1733.71	10.1271
1736.74	9.68789
1739.77	9.19479
1742.8	9.21588
1745.83	8.88317
1748.85	9.14296
1751.88	9.98821
1754.91	9.75813
1757.93	9.21526
1760.95	9.25546
1763.97	7.82778
1766.99	6.72028
1770.01	5.50566
1773.03	4.58634
1776.04	3.26902
1779.06	3.48778
1782.07	2.87019
1785.09	3.59509
1788.1	2.76699
1791.11	2.87078
1794.12	1.47622
1797.13	1.5926
1800.13	1.52535
1803.14	1.92389
1806.15	2.19378
1809.15	3.23729
1812.15	3.6727
1815.16	3.87768
1818.15	4.55585
1821.16	4.57604
1824.15	5.43225
1827.15	5.27951
1830.15	4.31281
1833.14	4.7627
1836.14	5.13173
1839.13	4.56783
1842.12	4.54484
1845.11	5.24011
1848.1	4.77677
1851.09	4.99422
1854.08	4.23293
1857.06	2.81015
1860.05	1.72449
1863.03	0.955846
1866.01	-0.0589156
1869	-1.06529
1871.98	-0.972306
1874.96	-2.04683
1877.93	-0.893533
1880.91	-0.00205763
1882.47	1.0636
1885.46	0.992465
1888.44	1.30153
1891.43	1.55477
1894.42	3.30808
1897.4	4.41678
1900.39	5.54334
1903.37	7.15137
1906.35	7.86409
1909.33	7.21992
1912.31	7.78864
1915.29	7.73385
1918.26	8.61996
1921.24	8.00888
1924.21	7.62135
1927.19	7.00473
1930.16	5.30919
1933.13	5.77415
1936.1	5.45975
1939.07	6.35764
1942.04	5.59644
1945	5.94422
1947.97	6.32109
1950.93	6.36308
1953.9	6.67262
1956.86	7.1521
1959.82	6.30234
1962.78	6.64611
1965.74	6.85426
1968.7	8.06872
1971.65	9.44378
1974.61	9.91744
1977.57	9.36897
1980.52	9.90018
1983.47	11.4463
1986.42	12.6819
1989.37	14.7988
1992.32	15.4469
1995.27	16.3187
1998.22	16.7635
2001.17	15.9502
2004.11	16.4146
2007.05	19.1627
2010	19.9346
2012.94	20.1176
2015.88	19.7843
2018.82	19.6326
2021.76	18.8717
2024.7	17.5855
2027.63	17.362
2030.57	16.9513
2033.5	16.905
2036.44	16.8479
2039.37	16.9122
2042.3	18.517
2045.23	18.746
2048.16	19.8155
2051.08	20.9817
2054.01	22.3902
2056.94	24.3802
2059.86	25.6321
2062.79	27.7647
2065.71	29.0642
2068.63	29.5913
2071.55	30.7175
2074.47	33.6845
2077.39	35.9872
2080.31	38.9268
2083.22	40.5499
2086.13	43.0758
2089.05	44.6283
2091.96	47.4604
2094.87	49.1669
2097.78	51.2433
2100.69	55.5106
2103.6	59.6113
2106.51	64.019
2109.42	67.6811
2112.32	70.6148
2115.23	74.7621
2118.13	79.4243
2121.03	84.9563
2123.93	89.3772
2126.83	94.1862
2129.73	98.5343
2132.63	103.593
2135.53	108.681
2138.42	114.089
2141.32	119.54
2144.21	123.694
2147.1	128.675
2150	133.763
2152.89	137.667
2155.78	140.901
2158.66	143.152
2161.55	144.803
2164.44	144.336
2167.32	144.507
2170.21	145.461
2173.09	144.52
2175.97	142.099
2178.85	139.167
2181.73	136.358
2184.61	132.648
2187.49	129.852
2190.37	125.186
2193.24	119.248
2196.12	114.409
2198.99	110.2
2201.87	105.329
2204.74	100.431
2207.61	95.977
2210.48	91.3532
2213.35	86.601
2216.21	82.0657
2219.08	79.2932
2221.95	73.7286
2224.81	69.8832
2227.67	66.0085
2230.54	61.2865
2233.4	56.845
2236.26	52.4193
2239.11	49.8597
2241.97	47.1315
2244.83	42.6541
2247.69	39.8475
2250.54	36.9347
2253.4	34.7077
2256.25	33.0386
2259.1	30.4999
2261.95	28.0927
2264.8	25.9162
2267.65	25.3032
2270.5	24.0865
2273.34	23.9969
2276.19	22.9882
2279.03	22.5165
2281.88	21.0706
2284.72	21.1309
2287.56	19.2529
2290.4	17.9157
2293.24	16.3343
2296.08	16.9492
2298.92	16.4055
2301.76	16.4146
2304.59	16.1987
2307.43	15.1686
2310.26	14.931
2313.09	13.0236
2315.92	11.6864
2318.75	10.9986
2321.58	11.3809
2324.41	11.4824
2327.24	11.2878
2330.06	9.88136
2332.89	9.76465
2335.71	8.79569
2338.54	8.30119
2341.36	8.22327
2344.18	6.61229
2347	5.12801
2349.82	4.83212
2352.64	4.82648
2355.45	4.0319
2358.27	4.14393
2361.08	4.70972
2363.9	6.50835
2366.71	9.35241
2369.52	10.0294
2372.33	10.4135
2375.14	10.2326
2377.95	10.3033
2380.76	9.74732
2383.57	10.2664
2386.37	10.8805
2389.18	10.5955
2391.98	10.2775
2394.79	9.33197
2397.59	8.30386
2400.39	7.41793
2403.19	7.25253
2405.99	6.06968
2408.78	6.21308
2411.58	5.72618
2414.38	5.2356
2417.17	4.40909
2419.97	4.49122
2422.76	4.61793
2425.55	5.15338
2428.34	5.67767
2431.13	6.67206
2433.92	7.2261
2436.71	7.42287
2439.49	6.79263
2442.28	6.66621
2445.06	6.52298
2447.85	6.30106
2450.63	5.74276
2453.41	5.34539
2456.19	4.09593
2458.97	3.10062
2461.75	2.73704
2464.53	2.70667
2467.31	3.20555
2470.08	2.45251
2472.86	2.21671
2475.63	2.27824
2478.4	1.95955
2481.17	1.91358
2483.94	1.25033
2486.72	1.89838
2489.48	1.41713
2492.25	2.02085
2495.02	2.57034
2497.79	4.06264
2500.55	4.32806
2503.31	2.81586
2506.08	3.63042
2508.84	4.04717
2511.6	4.95287
2514.36	4.66841
2517.12	4.42706
2519.88	3.73288
2522.63	2.85822
2525.39	2.24995
2528.14	1.40164
2530.9	1.82908
2533.65	1.0306
2536.4	1.18255
2539.15	0.947206
2541.9	0.0263893
2544.65	-0.549923
2547.4	-0.434775
2550.15	0.263092
2552.89	0.442964
2555.64	0.443875
2558.38	0.532836
2561.12	1.31603
2563.87	1.2472
2566.61	1.51593
2569.35	1.38117
2572.09	2.1396
2574.83	3.66986
2577.56	4.50943
2580.3	5.15494
2583.04	5.01996
2585.77	5.48909
2588.5	5.25024
2591.23	5.59993
2593.97	5.35524
2596.7	5.65327
2599.43	5.81372
2602.15	6.4969
2604.88	6.17557
2607.61	5.42036
2610.33	5.54588
2613.06	5.68043
2615.78	5.78837
2618.51	6.3298
2621.23	4.75924
2623.95	4.12262
2626.67	3.04111
2629.39	3.10258
2632.1	3.07814
2634.82	2.59731
2637.54	3.28103
2640.25	3.34145
2642.97	2.84304
2645.68	3.28633
2648.39	1.92948
2651.1	1.24001
2653.81	0.950363
2656.52	0.687485
2659.23	0.755382
2661.94	0.538498
2664.64	1.67862
2667.35	2.22579
2670.05	2.18733
2672.76	1.90778
2675.46	2.78398
2678.16	3.93833
2680.86	3.74814
2683.56	4.39525
2686.26	4.67078
2688.96	5.06725
2691.65	5.71651
2694.35	6.39607
2697.04	6.96132
2699.74	6.27712
2702.43	6.63793
2705.12	7.4203
2707.81	7.72704
2710.5	9.40751
2713.19	9.25097
2715.88	9.97933
2718.57	10.2872
2721.25	10.9621
2723.94	11.2011
2726.62	11.6843
2729.3	11.5052
2731.99	10.5317
2734.67	9.50041
2737.35	9.39921
2740.03	9.63038
2742.71	8.8445
2745.38	7.72261
2748.06	7.68174
2750.74	6.90004
2753.41	6.04838
2756.09	4.50976
2758.76	3.87828
2761.43	2.69889
2764.1	1.12673
2766.77	0.666005
2769.44	0.714594
2772.11	0.510178
2774.77	1.38658
2777.44	0.955601
2780.11	0.634625
2782.77	0.269505
2785.43	0.233902
2788.1	0.058296
2790.76	0.327634
2793.42	0.15343
2796.08	-0.781684
2798.74	-0.444183
2801.4	0.392945
2804.05	1.26642
2806.71	0.239509
2809.36	0.522831
2812.02	0.914406
2814.67	1.06204
2817.32	2.0631
2819.97	5.21136
2822.62	9.3498
2825.27	15.0764
2827.92	20.8295
2830.57	28.2556
2833.22	36.2141
2835.86	43.7495
2838.51	53.8469
2841.15	65.3479
2843.79	76.4174
2846.43	89.1504
2849.08	102.61
2851.72	115.068
2854.36	127.609
2856.99	141.783
2859.63	153.791
2862.27	165.654
2864.9	177.61
2867.54	186.966
2870.17	194.42
2872.8	201.677
2875.43	208.928
2878.07	216.025
2880.7	222.817
2883.32	231.345
2885.95	238.897
2888.58	247.771
2891.21	256.233
2893.83	264.359
2896.46	273.926
2899.08	284.503
2901.7	295.315
2904.32	308.265
2906.94	320.968
2909.56	334.543
2912.18	348.16
2914.8	361.043
2917.42	372.703
2920.03	384.183
2922.65	391.589
2925.26	396.098
2927.88	400.466
2930.49	400.436
2933.1	397.458
2935.71	391.573
2938.32	385.22
2940.93	375.833
2943.54	364.646
2946.14	351.372
2948.75	337.853
2951.35	322.864
2953.96	307.048
2956.56	290.732
2959.16	275.12
2961.77	258.964
2964.37	243.975
2966.96	229.086
2969.56	215.602
2972.16	202.424
2974.76	189.809
2977.35	176.311
2979.95	164.025
2982.54	151.004
2985.14	138.309
2987.73	126.088
2990.32	114.484
2992.91	102.888
2995.5	91.9003
2998.09	80.9639
3000.68	71.0259
3003.26	62.9549
3005.85	54.1074
3008.43	46.4331
3011.02	39.7346
3013.6	33.2055
3016.19	28.2903
3018.77	23.7624
3021.35	20.6271
3023.93	17.3531
3026.5	15.5742
3029.08	14.257
3031.66	12.4362
3034.24	12.029
3036.81	12.1756
3039.39	11.4529
3041.96	12.6623
3044.53	13.9777
3047.1	14.103
3049.67	14.8939
3052.24	14.7923
3054.81	15.7692
3057.38	16.0821
3059.95	15.274
3062.52	14.8166
3065.08	13.8642
3067.65	13.3525
3070.21	12.5041
3072.77	10.6221
3075.33	9.30415
3077.89	7.82701
3080.45	6.62721
3083.01	5.27385
3085.57	3.70596
3088.13	1.4622
3090.68	0.501867
3093.24	-0.22024
3095.79	0.0483477
3098.35	-0.108042
3100.9	-0.173751
3103.45	-0.0216631
3106	0.995503
3108.55	2.03725
3111.1	2.34602
3113.65	3.77023
3116.2	5.25941
3118.75	7.16578
3121.29	7.70512
3123.84	8.74457
3126.38	11.2565
3128.92	13.2295
3131.47	15.6493
3134.01	17.4439
3136.55	19.678
3139.09	21.1156
3141.63	23.2601
3144.17	25.0523
3146.7	27.0378
3149.24	29.9396