File: data/Raman/poly_smoothed/Mb_40_y_32_1x_45s_532 nm_x100_100%_600 gr_mm_01.txt
#Acq. time (s)=	45
#Accumulations=	2
#Range (cm-¹)=	200...3150
#Windows=	2
#Auto scanning=	Off
#Autofocus=	Off
#Macrospot=	Off
#AutoExposure=	Off
#Spike filter=	Multiple accum.
#Delay time (s)=	0
#Binning=	1
#Readout mode=	Signal
#DeNoise=	Off
#ICS correction=	On
#Dark correction=	Off
#Inst. Process=	Off
#Detector Gain=	Best Dynamic Range
#Detector ADC=	20 kHz
#Detector temperature (°C)=	-69.85
#Instrument=	LabRAM HR Evol
#Detector=	Synapse
#Objective=	x100
#Grating=	600 gr/mm
#ND Filter=	100%
#Laser (nm)=	532
#Hole=	100.021
#Range=	Auto
#Laser Pol.=	No
#Raman. Pol.=	No
#Laser Pol. (°)=	-0.0007625
#Raman Pol. (°)=	89.9995
#Collection=	Microscope
#StageXY=	Marzhauser
#StageZ=	Marzhauser
#X (µm)=	-1108.2
#Y (µm)=	572.7
#Z (µm)=	584.25
#Full time(mm:ss)=	3:18
#Project=
#Sample=
#Site=
#Title=	Mb_40_y_32_2x_45s_532 nm_x100_100%_600 gr_mm
#Remark=
#Date=	19.07.2022 12:03
#Acquired=	19.07.2022 12:03:54
#Base:Fit=	10.08.2022 10:52:48
#Base:Sub=	10.08.2022 10:52:53
#Filter:Polynom=	16.08.2022 10:09:04
#AxisType[0]=Intens
#AxisUnit[0]=Cnt
#AxisType[1]=Spectr
#AxisUnit[1]=1/cm
200.423	13.6238
204.052	15.5607
207.682	17.0933
211.308	16.6889
214.935	14.7991
218.558	12.8094
222.18	12.0972
225.802	9.25038
229.421	8.5501
233.039	7.55513
236.657	6.47963
240.272	6.10323
243.885	6.33314
247.497	5.52838
251.11	5.55995
254.719	6.23604
258.327	6.86878
261.933	6.77869
265.538	8.11498
269.141	7.36124
272.744	8.83825
276.344	9.45672
279.944	9.95738
283.542	9.10519
287.138	9.8717
290.733	8.32705
294.327	7.30086
297.919	5.76035
301.508	6.168
305.098	5.17168
308.686	6.53194
312.273	5.42874
315.858	6.50027
319.44	6.51828
323.022	5.90898
326.604	6.39852
330.181	7.98214
333.76	8.24795
337.335	9.7886
340.91	11.8782
344.483	13.9054
348.055	13.8179
351.625	15.2235
355.195	15.6963
358.762	15.1476
362.329	15.2685
365.893	14.5696
369.455	14.8423
373.017	15.0647
376.578	14.7825
380.137	14.1839
383.694	13.2348
387.249	12.0638
390.806	10.9117
394.359	10.3441
397.91	9.36662
401.46	9.53714
405.009	8.0604
408.557	8.41378
412.103	8.27206
415.647	8.43099
419.191	7.25254
422.733	7.32694
426.273	7.74506
429.812	9.83905
433.35	9.59584
436.885	9.98468
440.42	10.3984
443.954	12.0353
447.486	12.9596
451.015	14.6958
454.545	16.9143
458.073	16.8168
461.598	16.9655
465.124	18.409
468.648	18.6685
472.169	17.7026
475.69	17.747
479.208	18.1793
482.727	18.3712
486.243	19.1744
489.759	19.0986
493.272	19.8057
496.783	20.7346
500.295	19.0219
503.804	18.4282
507.311	19.1175
510.819	19.0374
514.324	19.3178
517.827	19.807
521.329	18.7873
524.83	18.7764
528.329	18.3989
531.829	17.3054
535.326	15.8206
538.821	14.0476
542.315	13.1519
545.808	11.264
549.299	10.8056
552.789	9.61576
556.278	6.37848
559.763	5.78688
563.249	5.20046
566.733	4.89886
570.217	3.84594
573.699	2.61664
577.177	2.25693
580.656	3.02713
584.134	2.77717
587.609	2.29548
591.084	4.2543
594.558	4.36622
598.029	4.84031
601.5	6.67418
604.968	8.07738
608.437	9.86176
611.902	9.34409
615.368	9.49642
618.831	10.3751
622.294	10.7361
625.755	10.8625
629.213	10.6012
632.673	10.4351
636.129	10.725
639.584	10.3341
643.037	11.8678
646.491	12.6284
649.942	12.9704
653.392	14.0846
656.84	12.9877
660.287	12.4491
663.732	12.6077
667.177	12.5042
670.62	13.6761
674.061	14.7369
677.502	15.5615
680.941	17.4375
684.379	19.1895
687.815	20.8985
691.248	21.8528
694.682	22.8673
698.115	24.0511
701.546	26.2529
704.974	28.8359
708.402	32.04
711.83	35.1714
715.254	36.0348
718.679	38.5667
722.102	39.7176
725.522	41.4724
728.943	43.1529
732.361	44.4401
735.779	46.4288
739.194	47.564
742.608	46.9364
746.022	47.1411
749.433	49.048
752.843	50.0068
756.254	51.1998
759.661	51.2847
763.067	52.9123
766.471	54.9227
769.877	55.7656
773.279	58.3306
776.68	59.7327
780.079	61.285
783.478	64.5023
786.875	67.0744
790.27	68.6791
793.665	71.6269
797.058	72.2706
800.45	72.8413
803.84	74.5015
807.23	74.4212
810.616	75.0308
814.002	75.7031
817.388	75.3016
820.772	76.792
824.153	76.7841
827.535	74.8807
830.915	73.9708
834.292	72.1982
837.67	68.5936
841.047	66.9834
844.42	63.1662
847.794	61.4895
851.165	59.0219
854.534	56.159
857.905	53.1552
861.272	49.9697
864.639	47.7261
868.004	47.2562
871.367	44.4503
874.731	44.3681
878.092	43.806
881.451	44.6764
884.809	43.9179
888.166	43.4626
891.522	42.5764
894.878	43.905
898.231	45.1004
901.583	45.6499
904.934	47.7033
908.283	47.7255
911.631	47.1453
914.976	47.0796
918.322	46.8023
921.666	44.9337
925.009	44.5073
928.351	43.0195
931.692	43.0345
935.029	42.4946
938.367	42.4129
941.704	41.2035
945.038	39.0674
948.372	38.5586
951.705	37.8952
955.035	37.3312
958.366	37.0131
961.693	36.1848
965.021	35.0762
968.346	33.6989
971.67	33.2671
974.995	34.3011
978.316	35.0189
981.638	35.4027
984.957	36.299
988.274	36.0901
991.59	35.0919
994.907	33.424
998.221	31.275
1001.53	26.4828
1004.85	23.9246
1008.16	26.8292
1011.46	34.0462
1014.77	45.8618
1018.08	59.1536
1021.38	71.5372
1024.69	82.4444
1027.99	94.3029
1031.29	104.192
1034.59	110.597
1037.89	114.988
1041.19	118.405
1044.48	119.792
1047.78	120.22
1051.07	118.375
1054.36	115.066
1057.66	107.639
1060.94	98.8328
1064.23	89.1562
1067.52	77.2426
1070.81	63.4472
1074.09	49.2193
1077.38	33.7785
1080.66	19.8248
1083.94	10.142
1087.22	7.35722
1090.5	8.03749
1093.77	12.2022
1097.05	12.7659
1100.32	13.8819
1103.6	13.7606
1106.87	15.3732
1110.14	15.2756
1113.41	14.3374
1116.67	14.0024
1119.94	15.9363
1123.21	16.3866
1126.47	16.8775
1129.73	16.4182
1133	16.2903
1136.26	15.4016
1139.52	15.2046
1142.77	14.3751
1146.03	13.3599
1149.29	12.4872
1152.54	11.8277
1155.79	9.61845
1159.04	7.69457
1162.3	6.206
1165.55	5.68935
1168.79	5.07519
1172.04	4.04964
1175.28	3.95087
1178.53	3.08086
1181.77	3.81308
1185.01	4.45743
1188.25	5.42793
1191.49	5.44567
1194.73	7.22958
1197.97	10.1689
1201.2	12.0301
1204.44	12.7675
1207.67	14.7801
1210.9	17.1284
1214.13	18.5826
1217.36	21.3706
1220.59	24.5621
1223.82	26.3225
1227.04	28.9081
1230.26	32.1754
1233.49	33.2921
1236.71	35.9798
1239.93	37.6578
1243.15	40.2212
1246.37	42.2321
1249.58	44.7273
1252.8	45.3752
1256.01	47.0605
1259.23	49.1876
1262.44	48.9569
1265.65	49.737
1268.86	50.1546
1272.07	51.9108
1275.27	51.9483
1278.48	53.8023
1281.68	55.0329
1284.89	55.6452
1288.09	57.133
1291.29	58.7392
1294.49	59.7546
1297.69	59.863
1300.88	59.9455
1304.08	60.3528
1307.27	60.8751
1310.47	60.3967
1313.66	60.474
1316.85	60.7811
1320.04	59.8699
1323.23	61.69
1326.41	62.2973
1329.6	62.4824
1332.78	61.9264
1335.97	60.3326
1339.15	58.4663
1342.33	56.6113
1345.51	54.6698
1348.69	53.7321
1351.87	50.5948
1355.04	48.086
1358.22	47.2312
1361.39	45.1519
1364.57	43.3475
1367.74	40.1659
1370.91	36.5789
1374.07	34.8903
1377.24	31.9998
1380.41	30.2778
1383.57	27.9933
1386.74	28.0959
1389.9	28.1438
1393.06	29.5912
1396.22	31.255
1399.38	33.7438
1402.54	34.6162
1405.7	38.011
1408.85	40.677
1412.01	42.818
1415.16	45.8882
1418.31	49.0345
1421.46	51.348
1424.61	55.8201
1427.76	58.0656
1430.91	61.1449
1434.05	63.9634
1437.2	66.3533
1440.34	68.464
1443.49	67.8089
1446.63	67.1888
1449.77	67.1795
1452.91	64.7645
1456.04	62.3149
1459.18	60.3242
1462.31	58.9719
1465.45	56.5514
1468.58	54.1915
1471.71	51.2592
1474.84	47.7477
1477.97	45.2596
1481.1	42.4322
1484.23	39.9869
1487.35	38.5883
1490.48	36.6805
1493.6	35.3015
1496.72	33.6332
1499.84	33.0825
1502.96	31.2125
1506.08	29.5888
1509.2	29.9949
1512.31	29.7051
1515.43	29.252
1518.54	29.4286
1521.66	28.2563
1524.77	28.1068
1527.88	27.8925
1530.99	27.6493
1534.09	28.0411
1537.2	28.4378
1540.31	28.6892
1543.41	29.5146
1546.51	30.4867
1549.62	31.0686
1552.72	31.477
1555.82	31.4997
1558.91	32.5805
1562.01	34.4696
1565.11	36.4346
1568.2	37.13
1571.3	38.8214
1574.39	39.3721
1577.48	41.068
1580.57	42.2494
1583.66	44.6328
1586.75	46.5405
1589.83	46.428
1592.92	49.4932
1596	51.0325
1599.09	51.5157
1602.17	52.5385
1605.25	51.509
1608.33	50.6396
1611.41	51.9245
1614.48	52.7382
1617.56	53.9893
1620.64	53.5157
1623.71	53.302
1626.78	53.4215
1629.86	54.2905
1632.92	56.3167
1635.99	57.9768
1639.06	60.8675
1642.13	61.1286
1645.19	63.0975
1648.26	63.3789
1651.32	63.5055
1654.38	63.9939
1657.45	63.6906
1660.51	64.0986
1663.57	63.2381
1666.62	61.5972
1669.68	59.6198
1672.73	55.9066
1675.79	52.7005
1678.84	48.8591
1681.89	44.3523
1684.94	41.7438
1687.99	38.687
1691.04	33.9091
1694.09	30.7068
1697.14	26.7495
1700.18	24.4794
1703.22	21.7077
1706.27	19.9047
1709.31	18.0323
1712.35	16.5595
1715.39	14.6176
1718.43	12.225
1721.46	11.8105
1724.5	10.8076
1727.53	10.3663
1730.57	9.78494
1733.6	9.47152
1736.63	9.07145
1739.66	8.65434
1742.69	7.5701
1745.72	7.24673
1748.74	7.19007
1751.77	7.11055
1754.8	5.88719
1757.82	4.86325
1760.84	4.88405
1763.86	4.12694
1766.88	4.52828
1769.9	4.06546
1772.92	4.17362
1775.93	3.87856
1778.95	3.53136
1781.96	2.98171
1784.98	1.97531
1787.99	2.59252
1791	2.33455
1794.01	3.62439
1797.02	3.00238
1800.03	3.32098
1803.03	3.60012
1806.04	3.54536
1809.04	3.72572
1812.04	4.24697
1815.05	3.87046
1818.05	3.93435
1821.05	3.7747
1824.05	3.20061
1827.04	3.14794
1830.04	2.39908
1833.03	2.2837
1836.03	2.64972
1839.02	3.08028
1842.01	3.25503
1845	3.23058
1847.99	3.21362
1850.98	2.12549
1853.97	1.51928
1856.95	1.26648
1859.94	1.7999
1862.92	1.99208
1865.91	2.65467
1868.89	3.05877
1871.87	2.96892
1874.85	3.30963
1877.83	2.8973
1880.8	2.75095
1882.56	2.41495
1885.54	1.15317
1888.53	1.62781
1891.52	1.70511
1894.5	1.86531
1897.49	2.68058
1900.47	1.68515
1903.45	2.00917
1906.43	3.24552
1909.41	3.21721
1912.39	3.56016
1915.37	3.77662
1918.35	3.0091
1921.32	3.11291
1924.3	2.84519
1927.27	3.05685
1930.24	3.72029
1933.21	4.02368
1936.18	3.96656
1939.15	3.25437
1942.12	3.06683
1945.09	1.89903
1948.05	1.14162
1951.02	1.12037
1953.98	1.10618
1956.94	0.762371
1959.91	1.94454
1962.87	1.26991
1965.82	0.617169
1968.78	1.51904
1971.74	0.988676
1974.7	1.1097
1977.65	1.62718
1980.6	1.75232
1983.56	1.79654
1986.51	1.93231
1989.46	1.80661
1992.41	2.55338
1995.36	3.61849
1998.3	3.34624
2001.25	2.92017
2004.2	3.76956
2007.14	2.90173
2010.08	3.17459
2013.02	3.0813
2015.97	2.94018
2018.9	2.34585
2021.84	3.40326
2024.78	4.38121
2027.72	4.37044
2030.65	5.54385
2033.59	4.89066
2036.52	4.67223
2039.45	5.63907
2042.38	5.67488
2045.31	5.19847
2048.24	4.99239
2051.17	5.13233
2054.1	5.68435
2057.02	5.77486
2059.95	6.49872
2062.87	6.9801
2065.79	7.45488
2068.71	7.71181
2071.63	8.24499
2074.55	8.88316
2077.47	10.7308
2080.39	12.9767
2083.3	13.4856
2086.22	15.1109
2089.13	15.7062
2092.05	17.2279
2094.96	19.2441
2097.87	21.3165
2100.78	22.6979
2103.69	24.9419
2106.59	25.7448
2109.5	27.7771
2112.41	29.0052
2115.31	29.8494
2118.21	32.36
2121.12	33.9766
2124.02	36.4562
2126.92	38.9008
2129.82	40.2155
2132.71	42.6339
2135.61	45.8393
2138.51	47.5451
2141.4	50.5816
2144.29	54.2349
2147.19	55.7536
2150.08	57.5781
2152.97	60.0902
2155.86	60.6892
2158.75	62.6132
2161.64	64.011
2164.52	65.7084
2167.41	67.3366
2170.29	67.1563
2173.17	67.5669
2176.06	67.3636
2178.94	66.073
2181.82	65.1886
2184.7	64.8231
2187.57	64.3094
2190.45	63.3423
2193.33	62.4259
2196.2	61.381
2199.08	58.8063
2201.95	57.4667
2204.82	56.9786
2207.69	53.7391
2210.56	50.6911
2213.43	48.9364
2216.3	45.3094
2219.16	41.7097
2222.03	39.357
2224.89	38.3524
2227.75	35.6482
2230.62	34.0483
2233.48	31.8341
2236.34	29.9736
2239.2	27.4421
2242.06	25.262
2244.91	23.4444
2247.77	21.9818
2250.62	20.6147
2253.48	20.0965
2256.33	19.8101
2259.18	19.0293
2262.03	18.8811
2264.88	18.8327
2267.73	17.7452
2270.58	17.541
2273.43	17.0279
2276.27	16.3841
2279.12	15.8739
2281.96	14.9284
2284.8	13.9188
2287.64	12.4739
2290.49	11.1792
2293.32	9.3076
2296.16	8.18547
2299	9.02772
2301.84	8.78702
2304.67	8.06723
2307.51	7.81083
2310.34	7.72879
2313.17	7.7725
2316	7.84435
2318.83	8.2765
2321.66	8.31662
2324.49	7.32908
2327.32	7.70271
2330.15	7.95773
2332.97	8.436
2335.79	7.71871
2338.62	7.28324
2341.44	6.68644
2344.26	6.90528
2347.08	6.72239
2349.9	5.72741
2352.72	3.66847
2355.53	2.1125
2358.35	0.794108
2361.17	0.100186
2363.98	1.10467
2366.79	2.01685
2369.6	2.66197
2372.42	2.32786
2375.22	2.73028
2378.03	3.51613
2380.84	3.34938
2383.65	3.88629
2386.45	3.97297
2389.26	3.02779
2392.06	2.37939
2394.87	3.1765
2397.67	3.21024
2400.47	3.28055
2403.27	3.38553
2406.07	2.85441
2408.86	2.06177
2411.66	2.54249
2414.46	2.16629
2417.25	2.66911
2420.05	3.0171
2422.84	3.21383
2425.63	3.32141
2428.42	3.36536
2431.21	3.8845
2434	4.45588
2436.79	5.17725
2439.57	5.64677
2442.36	6.05409
2445.14	5.76769
2447.93	6.22116
2450.71	6.06058
2453.49	6.38407
2456.27	5.88757
2459.05	5.38299
2461.83	5.71618
2464.61	6.02258
2467.39	5.33188
2470.16	5.42632
2472.94	5.05195
2475.71	4.86125
2478.48	4.13061
2481.25	4.42666
2484.02	3.89699
2486.8	3.58679
2489.56	2.8136
2492.33	2.5253
2495.1	2.4103
2497.86	2.50855
2500.63	2.50428
2503.39	2.48937
2506.16	2.39466
2508.92	2.35658
2511.68	2.33005
2514.44	3.31827
2517.2	3.58138
2519.95	3.77305
2522.71	3.48299
2525.47	2.95714
2528.22	3.43071
2530.98	3.45345
2533.73	3.55814
2536.48	3.22408
2539.23	5.11983
2541.98	4.12828
2544.73	4.0078
2547.48	4.20722
2550.23	4.63547
2552.97	4.96398
2555.72	6.3291
2558.46	6.71583
2561.2	7.63673
2563.95	7.93098
2566.69	8.07196
2569.43	8.86705
2572.17	8.78233
2574.91	9.00901
2577.64	9.80675
2580.38	10.2036
2583.11	9.66196
2585.85	9.43863
2588.58	9.57809
2591.31	8.43106
2594.04	8.00346
2596.78	7.2823
2599.51	7.19201
2602.23	6.86535
2604.96	7.49351
2607.69	6.35579
2610.41	5.79785
2613.14	5.44231
2615.86	5.42528
2618.58	4.57038
2621.3	4.36199
2624.03	3.19425
2626.75	2.55044
2629.46	1.61344
2632.18	1.51484
2634.9	1.22133
2637.61	0.772357
2640.33	0.763203
2643.04	0.3821
2645.76	0.792451
2648.47	1.1944
2651.18	1.48512
2653.89	1.83433
2656.6	3.00411
2659.31	4.47547
2662.01	4.93373
2664.72	6.13254
2667.43	6.59876
2670.13	6.74581
2672.83	6.7713
2675.53	6.90751
2678.24	7.2083
2680.94	7.43246
2683.64	8.03198
2686.34	8.53296
2689.03	8.624
2691.73	9.25575
2694.43	9.21372
2697.12	8.98061
2699.81	9.88647
2702.51	9.98321
2705.2	10.9101
2707.89	10.5236
2710.58	10.5617
2713.27	11.3395
2715.96	11.127
2718.64	11.9555
2721.33	12.1285
2724.01	12.7261
2726.7	11.4728
2729.38	11.3819
2732.06	11.6555
2734.75	10.0665
2737.43	9.83427
2740.11	9.18732
2742.78	9.18443
2745.46	8.19544
2748.14	8.26923
2750.81	7.50789
2753.49	7.03087
2756.16	6.46049
2758.84	5.3381
2761.51	5.20283
2764.18	4.94972
2766.85	4.40163
2769.52	3.67588
2772.19	2.45315
2774.85	1.83062
2777.52	1.82301
2780.18	1.82906
2782.85	1.18004
2785.51	1.12899
2788.17	0.88378
2790.84	0.877639
2793.5	1.24812
2796.16	2.20411
2798.81	1.80691
2801.47	1.24318
2804.13	2.60653
2806.79	2.29356
2809.44	2.38583
2812.09	2.1146
2814.75	1.84891
2817.4	2.19285
2820.05	2.26915
2822.7	3.88011
2825.35	4.82487
2828	6.37617
2830.65	7.88124
2833.29	10.8672
2835.94	14.5026
2838.58	18.3961
2841.23	22.0695
2843.87	26.0903
2846.51	29.9797
2849.15	35.2082
2851.79	40.8439
2854.43	46.0443
2857.07	50.8244
2859.71	55.7122
2862.34	60.0361
2864.98	64.2986
2867.61	68.4502
2870.25	71.5171
2872.88	73.77
2875.51	75.4084
2878.14	77.4302
2880.77	77.8541
2883.4	79.9306
2886.03	82.0346
2888.65	85.0729
2891.28	87.7023
2893.91	90.4285
2896.53	94.7351
2899.15	100.146
2901.78	104.796
2904.4	110.497
2907.02	117.037
2909.64	123.676
2912.26	131.112
2914.87	138.865
2917.49	145.063
2920.11	150.284
2922.72	156.567
2925.34	161.206
2927.95	165.948
2930.56	168.218
2933.17	170.121
2935.78	170.499
2938.39	169.976
2941	166.407
2943.61	161.974
2946.22	157.784
2948.82	152.7
2951.43	147.448
2954.03	140.727
2956.64	132.528
2959.24	125.528
2961.84	118.9
2964.44	112.096
2967.04	105.896
2969.64	99.4288
2972.24	92.9237
2974.83	85.6297
2977.43	79.2995
2980.02	73.3625
2982.62	65.4619
2985.21	59.1214
2987.8	52.3579
2990.4	46.7812
2992.99	41.0714
2995.57	36.3986
2998.16	30.6758
3000.75	25.9175
3003.34	20.4965
3005.92	15.1016
3008.51	11.7101
3011.09	8.78511
3013.68	6.31146
3016.26	3.55714
3018.84	2.12185
3021.42	0.817626
3024	0.475987
3026.58	-0.0182517
3029.16	0.336221
3031.73	0.222112
3034.31	1.0066
3036.89	1.46531
3039.46	1.29478
3042.03	2.16417
3044.61	1.63732
3047.18	1.85644
3049.75	1.7362
3052.32	1.98282
3054.89	2.84447
3057.45	3.23847
3060.02	2.80842
3062.59	2.15544
3065.15	2.18536
3067.72	1.48459
3070.28	1.98808
3072.84	1.91486
3075.41	1.09561
3077.97	1.00774
3080.53	1.14983
3083.09	0.976527
3085.64	0.335537
3088.2	0.0782013
3090.76	0.234529
3093.31	0.0746673
3095.87	-0.375428
3098.42	0.0759234
3100.97	-0.396982
3103.53	-0.460517
3106.08	-0.0146589
3108.63	0.00882493
3111.18	0.943145
3113.73	1.18181
3116.27	1.79843
3118.82	1.92813
3121.37	2.68997
3123.91	3.59038
3126.45	4.09844
3129	5.35957
3131.54	6.54307
3134.08	8.08673
3136.62	8.74368
3139.16	10.0228
3141.7	11.6813
3144.24	12.4062
3146.78	13.5054
3149.31	14.2785