File: data/Raman/poly_smoothed/Mb_40_y_09_1x_45s_532 nm_x100_100%_600 gr_mm_01.txt
#Acq. time (s)=	45
#Accumulations=	2
#Range (cm-¹)=	200...3150
#Windows=	2
#Auto scanning=	Off
#Autofocus=	Off
#Macrospot=	Off
#AutoExposure=	Off
#Spike filter=	Multiple accum.
#Delay time (s)=	0
#Binning=	1
#Readout mode=	Signal
#DeNoise=	Off
#ICS correction=	On
#Dark correction=	Off
#Inst. Process=	Off
#Detector Gain=	Best Dynamic Range
#Detector ADC=	20 kHz
#Detector temperature (°C)=	-69.85
#Instrument=	LabRAM HR Evol
#Detector=	Synapse
#Objective=	x100
#Grating=	600 gr/mm
#ND Filter=	100%
#Laser (nm)=	532
#Hole=	100.021
#Range=	Auto
#Laser Pol.=	No
#Raman. Pol.=	No
#Laser Pol. (°)=	-0.0007625
#Raman Pol. (°)=	89.9995
#Collection=	Microscope
#StageXY=	Marzhauser
#StageZ=	Marzhauser
#X (µm)=	-1031.8
#Y (µm)=	684.8
#Z (µm)=	584.55
#Full time(mm:ss)=	3:19
#Project=
#Sample=
#Site=
#Title=	Mb_40_y_09_2x_45s_532 nm_x100_100%_600 gr_mm
#Remark=
#Date=	19.07.2022 09:33
#Acquired=	19.07.2022 09:33:23
#Base:Fit=	10.08.2022 10:52:48
#Base:Sub=	10.08.2022 10:52:53
#Filter:Polynom=	16.08.2022 10:09:04
#AxisType[0]=Intens
#AxisUnit[0]=Cnt
#AxisType[1]=Spectr
#AxisUnit[1]=1/cm
200.423	29.613
204.052	27.4949
207.682	22.3709
211.308	17.5129
214.935	14.3088
218.558	12.3788
222.18	10.6356
225.802	8.67284
229.421	7.94368
233.039	7.10745
236.657	5.87454
240.272	5.71414
243.885	6.00783
247.497	6.61823
251.11	7.14274
254.719	6.91875
258.327	7.07283
261.933	7.83326
265.538	6.85196
269.141	8.28922
272.744	9.67487
276.344	10.4545
279.944	11.6744
283.542	12.1909
287.138	12.3035
290.733	11.0935
294.327	10.8606
297.919	10.7253
301.508	11.2789
305.098	11.1004
308.686	11.3777
312.273	10.9894
315.858	11.9638
319.44	11.5761
323.022	10.7758
326.604	9.5524
330.181	11.2872
333.76	10.999
337.335	8.80173
340.91	8.20788
344.483	7.55952
348.055	8.50139
351.625	7.02391
355.195	8.47689
358.762	10.5013
362.329	10.8698
365.893	10.0212
369.455	8.64844
373.017	9.87272
376.578	9.5573
380.137	10.3639
383.694	10.1443
387.249	10.337
390.806	10.7289
394.359	10.8464
397.91	12.1778
401.46	12.5493
405.009	11.7714
408.557	11.3479
412.103	11.5985
415.647	10.3368
419.191	9.61355
422.733	7.33559
426.273	6.97042
429.812	6.54768
433.35	5.1589
436.885	4.57931
440.42	3.25162
443.954	4.50504
447.486	2.18621
451.015	2.34638
454.545	3.47948
458.073	3.96095
461.598	4.87298
465.124	4.55329
468.648	6.67698
472.169	7.67644
475.69	8.8405
479.208	10.0649
482.727	12.1178
486.243	15.0265
489.759	16.0688
493.272	16.8688
496.783	19.507
500.295	19.3365
503.804	21.3302
507.311	22.5357
510.819	23.2577
514.324	23.9448
517.827	24.7971
521.329	25.0071
524.83	26.1885
528.329	25.4618
531.829	25.4204
535.326	25.3486
538.821	24.485
542.315	21.9914
545.808	19.9062
549.299	19.0865
552.789	17.0464
556.278	14.4026
559.763	11.2082
563.249	9.09886
566.733	7.91412
570.217	7.20741
573.699	6.36726
577.177	4.40405
580.656	5.36271
584.134	6.59116
587.609	6.27104
591.084	9.10189
594.558	8.64837
598.029	9.95154
601.5	10.1385
604.968	12.8945
608.437	14.4204
611.902	16.0128
615.368	17.0234
618.831	17.106
622.294	18.5165
625.755	18.9944
629.213	20.6803
632.673	19.6363
636.129	19.7617
639.584	19.3289
643.037	19.9466
646.491	19.3033
649.942	19.3495
653.392	19.8524
656.84	19.9116
660.287	19.6273
663.732	20.8944
667.177	22.7053
670.62	22.4804
674.061	24.1972
677.502	25.221
680.941	25.071
684.379	26.325
687.815	28.982
691.248	30.7422
694.682	33.2863
698.115	34.7171
701.546	36.6307
704.974	36.4629
708.402	39.7009
711.83	39.0836
715.254	39.4193
718.679	40.6652
722.102	43.9262
725.522	45.0145
728.943	45.4717
732.361	47.5391
735.779	48.04
739.194	49.4978
742.608	51.5258
746.022	53.4714
749.433	55.0881
752.843	57.6392
756.254	59.293
759.661	61.8023
763.067	63.3425
766.471	64.2518
769.877	68.396
773.279	70.8617
776.68	71.5097
780.079	73.3187
783.478	74.4741
786.875	76.4931
790.27	78.6657
793.665	78.8163
797.058	80.4937
800.45	81.9189
803.84	83.9634
807.23	84.5135
810.616	83.4478
814.002	83.6969
817.388	83.7024
820.772	80.9628
824.153	81.636
827.535	78.847
830.915	77.5587
834.292	76.2963
837.67	75.8185
841.047	73.0709
844.42	71.3848
847.794	68.164
851.165	67.0779
854.534	66.0748
857.905	64.3813
861.272	61.3342
864.639	59.5504
868.004	58.0568
871.367	57.1292
874.731	53.9493
878.092	52.7546
881.451	52.7135
884.809	52.8608
888.166	52.3659
891.522	51.0149
894.878	51.399
898.231	50.9332
901.583	49.4042
904.934	48.042
908.283	48.1954
911.631	47.6261
914.976	47.9401
918.322	47.7994
921.666	46.7544
925.009	45.6207
928.351	45.4666
931.692	45.444
935.029	45.5223
938.367	44.5305
941.704	42.8666
945.038	41.6723
948.372	40.8725
951.705	41.4912
955.035	41.9987
958.366	42.6593
961.693	40.7241
965.021	40.2073
968.346	40.8303
971.67	40.9309
974.995	40.4512
978.316	39.0845
981.638	38.3283
984.957	36.6998
988.274	35.1432
991.59	32.5575
994.907	31.9094
998.221	28.7574
1001.53	26.2713
1004.85	23.7706
1008.16	24.7384
1011.46	27.5933
1014.77	34.5865
1018.08	41.8378
1021.38	50.3561
1024.69	58.5372
1027.99	66.6633
1031.29	72.1006
1034.59	76.2349
1037.89	79.0617
1041.19	80.424
1044.48	81.5495
1047.78	82.8171
1051.07	81.5342
1054.36	78.6021
1057.66	73.7064
1060.94	67.7998
1064.23	61.4179
1067.52	53.9715
1070.81	46.203
1074.09	37.3574
1077.38	28.5023
1080.66	19.8302
1083.94	12.9221
1087.22	8.39587
1090.5	8.27403
1093.77	9.78859
1097.05	11.4591
1100.32	12.9626
1103.6	13.7925
1106.87	13.995
1110.14	14.4209
1113.41	14.3325
1116.67	15.5952
1119.94	16.4182
1123.21	17.5989
1126.47	17.2559
1129.73	18.721
1133	19.6524
1136.26	20.3527
1139.52	21.1368
1142.77	21.2876
1146.03	21.3745
1149.29	21.3072
1152.54	19.4971
1155.79	16.7956
1159.04	15.1971
1162.3	12.476
1165.55	10.2855
1168.79	9.0316
1172.04	8.57773
1175.28	7.32837
1178.53	6.72523
1181.77	5.8388
1185.01	4.99215
1188.25	5.11428
1191.49	6.2689
1194.73	6.1409
1197.97	7.92397
1201.2	8.8654
1204.44	9.90623
1207.67	11.7284
1210.9	14.2981
1214.13	16.1585
1217.36	17.1555
1220.59	18.1597
1223.82	19.489
1227.04	20.561
1230.26	21.6345
1233.49	22.1687
1236.71	22.5129
1239.93	22.6104
1243.15	22.7748
1246.37	22.7311
1249.58	23.6212
1252.8	23.452
1256.01	22.9183
1259.23	24.0845
1262.44	24.1616
1265.65	25.3223
1268.86	26.717
1272.07	27.4617
1275.27	28.3772
1278.48	29.139
1281.68	30.6499
1284.89	31.3576
1288.09	32.9984
1291.29	35.0036
1294.49	35.406
1297.69	36.1731
1300.88	37.8018
1304.08	38.0547
1307.27	39.2461
1310.47	39.8042
1313.66	38.3157
1316.85	37.5164
1320.04	37.5389
1323.23	37.5314
1326.41	37.4897
1329.6	37.2761
1332.78	36.5212
1335.97	36.9353
1339.15	36.2565
1342.33	35.3092
1345.51	34.4715
1348.69	33.236
1351.87	32.9285
1355.04	30.892
1358.22	29.427
1361.39	28.264
1364.57	27.4881
1367.74	25.3093
1370.91	23.5087
1374.07	22.8753
1377.24	21.8005
1380.41	20.4376
1383.57	19.682
1386.74	19.7726
1389.9	18.5886
1393.06	18.5547
1396.22	18.728
1399.38	19.2473
1402.54	19.5401
1405.7	19.9875
1408.85	21.0803
1412.01	22.0283
1415.16	23.5601
1418.31	24.8993
1421.46	26.654
1424.61	28.3194
1427.76	31.1672
1430.91	33.1017
1434.05	34.1776
1437.2	35.8296
1440.34	36.2076
1443.49	37.484
1446.63	36.9216
1449.77	38.574
1452.91	38.4382
1456.04	37.9415
1459.18	37.8363
1462.31	36.9848
1465.45	36.6694
1468.58	34.9336
1471.71	32.9216
1474.84	31.4259
1477.97	29.3277
1481.1	27.9501
1484.23	27.0842
1487.35	26.5115
1490.48	25.5835
1493.6	23.592
1496.72	21.7625
1499.84	20.9617
1502.96	19.8749
1506.08	18.2109
1509.2	16.3646
1512.31	14.7674
1515.43	13.1953
1518.54	12.5455
1521.66	12.1807
1524.77	10.4597
1527.88	11.2632
1530.99	12.1917
1534.09	11.7235
1537.2	11.9328
1540.31	12.5406
1543.41	12.4852
1546.51	13.2754
1549.62	13.9304
1552.72	15.3107
1555.82	17.3349
1558.91	18.5713
1562.01	19.759
1565.11	19.1421
1568.2	19.7346
1571.3	21.4394
1574.39	21.6628
1577.48	23.6636
1580.57	24.3065
1583.66	25.4301
1586.75	25.7255
1589.83	27.3892
1592.92	28.4197
1596	29.5288
1599.09	29.086
1602.17	30.0687
1605.25	30.0623
1608.33	29.0477
1611.41	29.228
1614.48	28.2255
1617.56	28.0711
1620.64	27.0262
1623.71	27.3515
1626.78	28.1845
1629.86	29.2087
1632.92	28.1994
1635.99	28.6631
1639.06	28.3807
1642.13	29.1043
1645.19	32.2201
1648.26	31.1418
1651.32	33.2639
1654.38	33.2366
1657.45	33.7295
1660.51	33.718
1663.57	32.7403
1666.62	31.8054
1669.68	30.7853
1672.73	29.1546
1675.79	28.0527
1678.84	26.5416
1681.89	24.292
1684.94	22.69
1687.99	20.5948
1691.04	19.0017
1694.09	17.272
1697.14	15.6249
1700.18	12.4204
1703.22	12.3038
1706.27	9.89834
1709.31	8.13705
1712.35	7.29875
1715.39	6.02257
1718.43	5.66104
1721.46	4.28793
1724.5	2.88398
1727.53	2.79174
1730.57	3.19575
1733.6	2.40462
1736.63	1.86381
1739.66	1.62907
1742.69	2.0644
1745.72	2.54432
1748.74	3.31021
1751.77	3.11502
1754.8	3.46316
1757.82	3.70676
1760.84	3.19281
1763.86	3.94372
1766.88	4.40684
1769.9	4.51463
1772.92	3.65888
1775.93	3.91688
1778.95	4.19492
1781.96	3.79813
1784.98	3.95283
1787.99	3.65282
1791	3.46841
1794.01	3.21961
1797.02	3.04742
1800.03	3.1675
1803.03	3.39742
1806.04	2.55004
1809.04	2.10234
1812.04	2.40332
1815.05	2.0128
1818.05	2.00093
1821.05	2.15627
1824.05	2.16396
1827.04	2.38897
1830.04	2.71015
1833.03	2.29575
1836.03	1.97447
1839.02	2.04982
1842.01	1.70762
1845	1.93528
1847.99	2.52534
1850.98	2.76095
1853.97	2.77762
1856.95	3.21743
1859.94	4.31134
1862.92	3.85115
1865.91	3.07105
1868.89	3.24428
1871.87	2.89767
1874.85	2.00733
1877.83	1.01929
1880.8	1.47104
1882.56	1.71133
1885.54	1.67125
1888.53	1.4178
1891.52	1.3959
1894.5	1.23879
1897.49	0.958494
1900.47	1.29974
1903.45	0.820116
1906.43	-0.151822
1909.41	-0.789644
1912.39	-0.249398
1915.37	0.150306
1918.35	1.12097
1921.32	0.57303
1924.3	0.456337
1927.27	1.25603
1930.24	0.883277
1933.21	0.106841
1936.18	-0.673142
1939.15	-0.206467
1942.12	0.271298
1945.09	1.28102
1948.05	1.75481
1951.02	2.90449
1953.98	3.84967
1956.94	4.00297
1959.91	4.6666
1962.87	5.67762
1965.82	5.95548
1968.78	6.38352
1971.74	7.74128
1974.7	8.48937
1977.65	7.81826
1980.6	7.67222
1983.56	7.79267
1986.51	7.97965
1989.46	7.75925
1992.41	8.04726
1995.36	7.64307
1998.3	7.61106
2001.25	7.59354
2004.2	6.15376
2007.14	6.33269
2010.08	6.10078
2013.02	5.37063
2015.97	5.83235
2018.9	6.90978
2021.84	6.47216
2024.78	6.48309
2027.72	6.67983
2030.65	6.64339
2033.59	8.17092
2036.52	8.26402
2039.45	9.36831
2042.38	10.2112
2045.31	10.5172
2048.24	10.7385
2051.17	11.3521
2054.1	12.6383
2057.02	13.8057
2059.95	14.3408
2062.87	15.501
2065.79	15.1812
2068.71	15.4802
2071.63	16.3547
2074.55	17.2226
2077.47	16.8155
2080.39	17.1679
2083.3	18.7369
2086.22	19.1759
2089.13	19.3228
2092.05	19.3527
2094.96	19.6538
2097.87	19.6578
2100.78	20.046
2103.69	21.1522
2106.59	22.3742
2109.5	22.9063
2112.41	23.2888
2115.31	24.5658
2118.21	26.2404
2121.12	27.4824
2124.02	29.0195
2126.92	30.7822
2129.82	31.534
2132.71	33.3705
2135.61	35.9617
2138.51	37.4949
2141.4	39.5971
2144.29	42.4188
2147.19	43.2405
2150.08	45.2851
2152.97	47.2856
2155.86	48.7055
2158.75	48.738
2161.64	49.474
2164.52	50.0115
2167.41	51.1556
2170.29	52.3778
2173.17	52.6409
2176.06	52.9564
2178.94	52.7237
2181.82	51.291
2184.7	50.9644
2187.57	49.8853
2190.45	47.7832
2193.33	47.054
2196.2	46.5329
2199.08	44.9151
2201.95	42.7752
2204.82	41.642
2207.69	38.6249
2210.56	36.3478
2213.43	34.6086
2216.3	31.8888
2219.16	30.5962
2222.03	29.477
2224.89	28.8371
2227.75	27.7085
2230.62	26.8818
2233.48	27.6641
2236.34	27.72
2239.2	27.1853
2242.06	26.3786
2244.91	25.479
2247.77	23.5163
2250.62	22.5509
2253.48	21.9004
2256.33	20.5453
2259.18	19.518
2262.03	18.9582
2264.88	19.4431
2267.73	18.4458
2270.58	17.0299
2273.43	16.5695
2276.27	15.5395
2279.12	14.0736
2281.96	13.0021
2284.8	11.7572
2287.64	11.2372
2290.49	10.9387
2293.32	10.2096
2296.16	10.4091
2299	11.3342
2301.84	12.105
2304.67	12.8539
2307.51	13.0961
2310.34	12.859
2313.17	12.5711
2316	11.8816
2318.83	12.061
2321.66	12.3268
2324.49	12.1801
2327.32	12.0001
2330.15	12.3597
2332.97	13.2927
2335.79	13.8314
2338.62	13.0495
2341.44	12.1244
2344.26	12.1564
2347.08	11.8563
2349.9	10.9489
2352.72	10.1824
2355.53	8.3118
2358.35	7.66509
2361.17	8.12933
2363.98	8.15992
2366.79	9.34953
2369.6	9.22972
2372.42	8.96319
2375.22	8.57932
2378.03	7.98758
2380.84	7.70906
2383.65	8.03689
2386.45	8.30932
2389.26	8.24973
2392.06	8.41772
2394.87	8.55781
2397.67	8.35781
2400.47	8.75117
2403.27	9.07823
2406.07	8.36942
2408.86	7.76345
2411.66	8.10278
2414.46	7.62613
2417.25	6.60183
2420.05	5.33163
2422.84	4.13651
2425.63	3.7841
2428.42	4.18087
2431.21	3.7667
2434	3.53328
2436.79	2.15213
2439.57	2.04588
2442.36	1.57803
2445.14	0.804516
2447.93	0.584251
2450.71	1.24401
2453.49	1.7776
2456.27	1.58468
2459.05	2.2798
2461.83	2.17588
2464.61	1.4605
2467.39	2.38891
2470.16	2.61644
2472.94	3.67056
2475.71	4.1912
2478.48	4.05538
2481.25	4.29793
2484.02	4.23448
2486.8	5.43914
2489.56	4.9599
2492.33	6.336
2495.1	7.07641
2497.86	7.69305
2500.63	8.21815
2503.39	8.30553
2506.16	7.70763
2508.92	7.23862
2511.68	6.3341
2514.44	6.10859
2517.2	7.30969
2519.95	7.99571
2522.71	7.1829
2525.47	6.40582
2528.22	5.98017
2530.98	5.40333
2533.73	4.81794
2536.48	5.28991
2539.23	5.53905
2541.98	4.73874
2544.73	4.77498
2547.48	4.52904
2550.23	4.46298
2552.97	4.5166
2555.72	3.99465
2558.46	3.9717
2561.2	3.43054
2563.95	2.799
2566.69	3.77356
2569.43	2.94224
2572.17	3.15383
2574.91	2.64867
2577.64	2.11444
2580.38	2.38577
2583.11	2.23056
2585.85	3.21147
2588.58	3.04071
2591.31	1.22631
2594.04	1.29283
2596.78	2.00182
2599.51	0.825783
2602.23	1.31816
2604.96	1.63859
2607.69	1.2503
2610.41	1.51582
2613.14	2.29785
2615.86	1.94458
2618.58	1.74702
2621.3	1.78801
2624.03	1.40216
2626.75	1.47449
2629.46	2.01096
2632.18	2.10782
2634.9	2.75356
2637.61	2.51684
2640.33	2.76358
2643.04	2.05279
2645.76	1.8248
2648.47	2.25119
2651.18	2.06144
2653.89	1.73143
2656.6	0.95345
2659.31	0.852478
2662.01	1.56354
2664.72	1.73211
2667.43	2.08729
2670.13	3.08046
2672.83	2.50334
2675.53	2.73844
2678.24	2.51032
2680.94	2.18243
2683.64	2.60003
2686.34	2.53332
2689.03	1.82447
2691.73	2.25876
2694.43	2.14756
2697.12	1.69919
2699.81	2.07738
2702.51	2.45261
2705.2	2.45968
2707.89	2.59654
2710.58	2.67853
2713.27	2.58408
2715.96	2.59677
2718.64	3.06173
2721.33	2.7444
2724.01	4.10045
2726.7	5.16922
2729.38	5.25822
2732.06	4.93914
2734.75	5.35795
2737.43	5.56243
2740.11	5.03861
2742.78	4.67385
2745.46	4.95555
2748.14	5.49651
2750.81	4.80309
2753.49	3.93592
2756.16	3.68796
2758.84	3.15793
2761.51	2.43804
2764.18	1.91303
2766.85	1.34103
2769.52	0.492429
2772.19	0.356689
2774.85	-0.125251
2777.52	-0.305283
2780.18	-0.426619
2782.85	-0.157692
2785.51	0.235667
2788.17	0.459724
2790.84	0.421686
2793.5	0.355184
2796.16	0.00244524
2798.81	0.202233
2801.47	0.998716
2804.13	0.548835
2806.79	0.860825
2809.44	0.823513
2812.09	0.574023
2814.75	1.41928
2817.4	2.01575
2820.05	2.79746
2822.7	3.11718
2825.35	4.49112
2828	6.24083
2830.65	7.68638
2833.29	9.48432
2835.94	11.3556
2838.58	14.2087
2841.23	17.0551
2843.87	19.9954
2846.51	23.368
2849.15	26.0243
2851.79	28.9128
2854.43	31.7578
2857.07	34.8761
2859.71	37.5036
2862.34	40.1962
2864.98	42.7049
2867.61	45.1834
2870.25	47.1519
2872.88	48.4781
2875.51	50.5744
2878.14	52.9087
2880.77	54.6711
2883.4	56.4146
2886.03	58.1238
2888.65	59.8786
2891.28	63.1881
2893.91	66.0329
2896.53	68.8626
2899.15	71.9026
2901.78	75.1913
2904.4	79.8449
2907.02	84.3865
2909.64	88.5424
2912.26	93.0507
2914.87	97.5771
2917.49	102.275
2920.11	106.59
2922.72	110.154
2925.34	112.642
2927.95	114.738
2930.56	116.317
2933.17	116.744
2935.78	116.175
2938.39	115.685
2941	113.595
2943.61	111.342
2946.22	109.468
2948.82	106.218
2951.43	102.835
2954.03	99.4857
2956.64	95.1002
2959.24	90.6126
2961.84	85.9943
2964.44	81.2724
2967.04	76.8192
2969.64	72.0396
2972.24	67.6768
2974.83	62.9443
2977.43	58.1736
2980.02	52.6766
2982.62	48.1077
2985.21	43.5457
2987.8	38.6701
2990.4	34.0977
2992.99	30.8472
2995.57	26.6177
2998.16	23.1763
3000.75	20.3366
3003.34	17.0082
3005.92	14.5504
3008.51	12.3417
3011.09	11.1294
3013.68	10.059
3016.26	8.05258
3018.84	6.75459
3021.42	6.08263
3024	5.88836
3026.58	4.32826
3029.16	3.53057
3031.73	2.69643
3034.31	2.95869
3036.89	2.27432
3039.46	2.05591
3042.03	1.65567
3044.61	2.25136
3047.18	1.71784
3049.75	2.51692
3052.32	2.53939
3054.89	2.97777
3057.45	2.64646
3060.02	2.77546
3062.59	3.02776
3065.15	2.67619
3067.72	2.80823
3070.28	2.81235
3072.84	2.76846
3075.41	2.47673
3077.97	1.93513
3080.53	1.47922
3083.09	1.64888
3085.64	1.04756
3088.2	0.375131
3090.76	-0.454179
3093.31	-0.695622
3095.87	-0.202672
3098.42	0.454203
3100.97	0.139501
3103.53	1.30949
3106.08	1.48473
3108.63	1.57946
3111.18	1.66524
3113.73	2.25027
3116.27	1.93242
3118.82	2.05497
3121.37	2.90629
3123.91	3.59761
3126.45	4.2337
3129	4.32056
3131.54	4.80144
3134.08	5.73672
3136.62	6.37622
3139.16	7.15512
3141.7	8.07652
3144.24	9.1695
3146.78	11.4825
3149.31	16.0389