File: data/Raman/poly_smoothed/Mb_40_24_12_1x_45s_532 nm_x100_100%_600 gr_mm_01.txt
#Acq. time (s)=	45
#Accumulations=	2
#Range (cm-¹)=	200...3150
#Windows=	2
#Auto scanning=	Off
#Autofocus=	Off
#Macrospot=	Off
#AutoExposure=	Off
#Spike filter=	Multiple accum.
#Delay time (s)=	0
#Binning=	1
#Readout mode=	Signal
#DeNoise=	Off
#ICS correction=	On
#Dark correction=	Off
#Inst. Process=	Off
#Detector Gain=	Best Dynamic Range
#Detector ADC=	20 kHz
#Detector temperature (°C)=	-69.85
#Instrument=	LabRAM HR Evol
#Detector=	Synapse
#Objective=	x100
#Grating=	600 gr/mm
#ND Filter=	100%
#Laser (nm)=	532
#Hole=	100.021
#Range=	Auto
#Laser Pol.=	No
#Raman. Pol.=	No
#Laser Pol. (°)=	-0.0007625
#Raman Pol. (°)=	89.9995
#Collection=	Microscope
#StageXY=	Marzhauser
#StageZ=	Marzhauser
#X (µm)=	-2543.3
#Y (µm)=	-80.7
#Z (µm)=	-10.7
#Full time(mm:ss)=	3:19
#Project=
#Sample=
#Site=
#Title=	Mb_40_24_12_2x_45s_532 nm_x100_100%_600 gr_mm
#Remark=
#Date=	14.07.2022 11:34
#Acquired=	14.07.2022 11:34:34
#Base:Fit=	10.08.2022 10:47:00
#Base:Sub=	10.08.2022 10:47:12
#Filter:Polynom=	16.08.2022 10:11:48
#AxisType[0]=Intens
#AxisUnit[0]=Cnt
#AxisType[1]=Spectr
#AxisUnit[1]=1/cm
200.554	19.0427
204.183	15.4468
207.813	12.7482
211.439	11.413
215.065	9.41934
218.688	9.50936
222.312	7.47856
225.933	8.03026
229.552	8.62504
233.171	6.80677
236.787	7.74022
240.402	6.08943
244.015	7.36964
247.627	7.51958
251.24	9.66227
254.849	10.028
258.457	9.91166
262.063	11.4957
265.668	12.0113
269.271	12.5838
272.873	12.0219
276.474	10.3803
280.073	11.2501
283.671	13.019
287.268	13.2692
290.863	15.3127
294.456	17.4131
298.049	18.1839
301.637	18.8364
305.227	19.9458
308.815	20.6867
312.402	20.6467
315.987	20.5221
319.569	20.0417
323.151	20.5395
326.733	20.1085
330.31	20.2316
333.889	21.8513
337.464	20.9013
341.039	21.7101
344.611	20.7216
348.184	18.4377
351.754	15.565
355.324	14.4537
358.89	13.4321
362.455	10.4651
366.021	9.96614
369.584	9.90697
373.145	8.78512
376.707	10.1642
380.265	8.69067
383.822	7.47457
387.378	7.10122
390.934	6.17424
394.487	4.47253
398.038	4.35381
401.588	4.53675
405.137	5.14344
408.685	5.96971
412.23	7.51811
415.775	7.56175
419.318	10.6276
422.86	11.6795
426.401	13.6962
429.94	14.668
433.478	15.0656
437.012	13.8127
440.547	17.0331
444.081	18.4197
447.613	17.4656
451.142	18.2753
454.672	19.7452
458.2	20.9381
461.725	21.1753
465.251	21.0559
468.775	20.3297
472.296	21.3692
475.817	20.6452
479.335	20.961
482.854	21.2398
486.37	21.1598
489.886	22.0555
493.398	22.6267
496.91	23.8806
500.422	23.4167
503.93	26.7206
507.438	26.7143
510.946	26.7028
514.45	26.2913
517.954	24.9525
521.456	24.212
524.956	24.3341
528.456	25.4562
531.956	23.6381
535.452	22.7583
538.947	21.7603
542.441	20.6646
545.934	21.0786
549.425	20.8336
552.915	19.6097
556.403	19.4122
559.889	18.8288
563.375	17.5784
566.859	15.9852
570.342	14.9438
573.824	13.7621
577.303	13.4778
580.782	13.0623
584.26	12.6214
587.734	11.5877
591.21	10.1387
594.684	7.72027
598.154	7.54653
601.626	6.19683
605.094	6.00314
608.562	7.12104
612.027	7.92437
615.493	7.36019
618.956	7.20118
622.419	7.17415
625.879	9.58264
629.338	11.1709
632.797	12.8844
636.254	11.7013
639.708	12.5921
643.162	12.7688
646.614	13.6569
650.067	15.2136
653.516	15.6752
656.964	18.2411
660.411	19.4793
663.857	19.3456
667.301	20.7391
670.744	20.9207
674.186	20.7928
677.626	22.2075
681.065	24.8584
684.503	25.6974
687.939	25.8613
691.372	27.5015
694.806	29.5442
698.239	29.5783
701.67	30.5383
705.098	30.7746
708.526	32.2722
711.954	32.8357
715.378	32.2666
718.802	31.2163
722.226	31.4601
725.646	32.4171
729.067	30.878
732.484	30.412
735.902	31.6226
739.317	32.5131
742.731	33.4519
746.145	32.9817
749.556	34.3998
752.966	34.9254
756.377	36.8061
759.784	40.305
763.19	43.0201
766.594	45.6849
770	49.4214
773.402	53.7232
776.803	57.3692
780.202	59.9223
783.6	62.2164
786.997	65.6679
790.393	67.5295
793.787	70.575
797.18	71.194
800.572	72.1359
803.963	72.2044
807.35	72.8233
810.738	70.6518
814.125	69.8632
817.51	71.0484
820.894	70.9853
824.275	66.8934
827.657	66.3421
831.037	64.1715
834.414	62.9445
837.792	61.2333
841.167	58.1455
844.542	57.7166
847.914	56.8593
851.287	55.734
854.656	54.8278
858.026	52.1413
861.393	49.3568
864.761	48.1617
868.125	46.5679
871.489	46.1429
874.85	45.3231
878.213	45.3692
881.572	44.6842
884.931	45.3093
888.287	44.0766
891.643	43.9104
894.997	44.9083
898.352	46.6808
901.704	46.2955
905.055	45.9738
908.404	45.264
911.75	46.6402
915.097	47.361
918.443	47.4478
921.787	47.2431
925.13	47.4502
928.472	48.8848
931.813	47.6524
935.15	45.6093
938.488	43.7445
941.825	41.1173
945.158	37.7525
948.493	36.605
951.824	36.5348
955.156	36.17
958.486	33.6309
961.814	32.4069
965.142	31.1724
968.467	30.1191
971.79	30.2529
975.115	30.1924
978.436	29.6719
981.756	28.4301
985.077	26.9556
988.394	26.7843
991.71	27.0253
995.025	26.3365
998.341	25.6997
1001.65	25.3827
1004.97	24.4998
1008.28	24.1344
1011.58	24.6196
1014.89	24.1344
1018.2	25.8864
1021.5	25.3909
1024.81	26.5036
1028.11	29.4435
1031.41	31.9112
1034.71	33.1996
1038.01	33.5178
1041.31	33.8651
1044.6	33.5508
1047.9	33.8193
1051.19	34.5599
1054.48	34.4785
1057.77	33.3302
1061.06	33.1564
1064.35	29.4289
1067.64	28.7272
1070.93	26.2346
1074.21	24.0952
1077.49	22.1907
1080.78	21.6451
1084.06	19.2764
1087.34	19.0789
1090.61	17.7507
1093.89	18.0119
1097.17	19.0107
1100.44	19.3386
1103.71	16.6516
1106.99	17.6244
1110.26	16.2396
1113.52	15.2179
1116.79	13.7571
1120.06	11.3385
1123.32	11.1177
1126.59	9.17945
1129.85	10.2249
1133.11	8.68135
1136.37	7.16048
1139.63	5.69843
1142.89	5.5751
1146.15	4.18627
1149.4	4.03829
1152.66	3.02466
1155.91	2.37169
1159.16	2.23729
1162.41	1.81878
1165.66	1.20069
1168.91	0.338806
1172.16	0.344579
1175.4	2.96151
1178.65	4.28193
1181.89	6.33475
1185.13	5.753
1188.37	6.54922
1191.61	6.82326
1194.85	6.1969
1198.08	7.53546
1201.32	7.7221
1204.55	9.72328
1207.79	9.74287
1211.02	10.8281
1214.25	11.2684
1217.48	12.3156
1220.71	14.1516
1223.93	14.3984
1227.16	16.3428
1230.38	17.6533
1233.6	18.7169
1236.83	20.144
1240.05	22.6747
1243.26	23.9269
1246.48	27.2126
1249.7	29.5898
1252.92	33.102
1256.13	36.4133
1259.34	37.3521
1262.55	38.7799
1265.76	39.2886
1268.97	40.1106
1272.18	41.9254
1275.39	42.4975
1278.59	44.6796
1281.8	47.5633
1285	49.096
1288.2	49.6093
1291.4	49.2932
1294.6	51.0114
1297.8	53.0765
1301	54.6566
1304.19	54.7643
1307.39	55.5574
1310.58	54.5339
1313.77	56.7889
1316.96	56.2086
1320.15	55.8625
1323.34	56.2618
1326.53	54.5577
1329.72	54.1009
1332.9	53.3972
1336.08	52.04
1339.27	50.7178
1342.45	50.1722
1345.63	48.1128
1348.8	48.3169
1351.98	46.562
1355.16	45.7533
1358.33	45.6976
1361.51	43.4869
1364.68	40.7869
1367.85	40.1832
1371.02	40.0654
1374.19	40.5463
1377.36	40.4187
1380.52	41.7669
1383.69	41.7125
1386.85	41.5579
1390.02	41.6511
1393.18	43.0727
1396.34	41.6594
1399.5	41.6438
1402.65	43.799
1405.81	45.4963
1408.97	47.195
1412.12	50.7584
1415.27	52.9863
1418.43	55.4629
1421.58	59.8703
1424.73	64.4139
1427.87	68.0376
1431.02	72.0409
1434.17	75.3169
1437.31	78.2854
1440.46	79.7392
1443.6	80.0118
1446.74	81.3796
1449.88	82.9086
1453.02	82.0592
1456.16	80.6242
1459.29	78.4098
1462.43	75.4416
1465.56	71.3032
1468.69	67.5396
1471.83	62.2218
1474.95	57.4976
1478.08	54.1714
1481.21	49.1983
1484.34	44.4617
1487.47	40.5893
1490.59	37.549
1493.71	33.6362
1496.84	32.7313
1499.96	30.5345
1503.07	28.6685
1506.19	26.4491
1509.31	24.0232
1512.43	21.1695
1515.54	18.1647
1518.65	16.7925
1521.77	15.8756
1524.88	17.0642
1527.99	16.3238
1531.1	17.0373
1534.21	17.8417
1537.31	19.2218
1540.42	20.4595
1543.52	22.6762
1546.63	24.3355
1549.73	25.1721
1552.83	27.8944
1555.93	28.3922
1559.03	29.4966
1562.12	29.428
1565.22	29.8896
1568.31	30.735
1571.41	32.1335
1574.5	32.2224
1577.59	32.6777
1580.68	34.1631
1583.77	33.7259
1586.86	34.566
1589.95	34.5229
1593.03	36.0933
1596.11	37.6916
1599.2	38.0443
1602.28	38.6551
1605.36	40.157
1608.44	41.3205
1611.52	42.0363
1614.6	42.6409
1617.67	44.4199
1620.75	45.1318
1623.82	46.214
1626.89	47.9583
1629.96	49.7071
1633.04	50.7479
1636.11	52.1034
1639.17	53.3217
1642.24	54.6348
1645.31	57.1142
1648.37	58.3294
1651.43	58.577
1654.5	58.3494
1657.56	57.7323
1660.62	57.8108
1663.67	57.4579
1666.73	54.1174
1669.79	50.6959
1672.84	47.2417
1675.9	43.1778
1678.95	39.2654
1682	34.9758
1685.05	30.7814
1688.1	26.2212
1691.15	23.8779
1694.2	20.8934
1697.25	17.7939
1700.29	15.9934
1703.33	14.872
1706.38	13.129
1709.42	12.3188
1712.46	11.8461
1715.5	11.6326
1718.54	11.4254
1721.57	12.6364
1724.61	12.5821
1727.64	12.3032
1730.68	12.151
1733.71	12.7596
1736.74	11.8791
1739.77	10.5309
1742.8	9.10785
1745.83	8.84322
1748.85	8.09651
1751.88	7.45735
1754.91	6.60687
1757.93	6.13529
1760.95	5.29583
1763.97	4.15261
1766.99	3.55306
1770.01	2.08325
1773.03	0.848205
1776.04	0.291419
1779.06	-0.677926
1782.07	-0.755272
1785.09	-0.548053
1788.1	0.122734
1791.11	0.317922
1794.12	0.881857
1797.13	2.32162
1800.13	1.93617
1803.14	2.37282
1806.15	2.84785
1809.15	4.07269
1812.15	4.31075
1815.16	4.72874
1818.15	4.76361
1821.16	4.60186
1824.15	5.10499
1827.15	5.44266
1830.15	5.61577
1833.14	6.17585
1836.14	5.81554
1839.13	5.06591
1842.12	4.68263
1845.11	4.32929
1848.1	3.95117
1851.09	4.14667
1854.08	3.3292
1857.06	4.01855
1860.05	3.77689
1863.03	3.34735
1866.01	3.89612
1869	4.17183
1871.98	3.57673
1874.96	2.81657
1877.93	2.38773
1880.91	2.88293
1882.47	2.75685
1885.46	1.94007
1888.44	2.19962
1891.43	1.83378
1894.42	2.5941
1897.4	3.78071
1900.39	4.28696
1903.37	4.74446
1906.35	5.01777
1909.33	4.53939
1912.31	3.91191
1915.29	3.87407
1918.26	4.64656
1921.24	3.54964
1924.21	3.69321
1927.19	2.87937
1930.16	3.04421
1933.13	2.96691
1936.1	4.52116
1939.07	4.83089
1942.04	5.0652
1945	5.00394
1947.97	4.9275
1950.93	5.51989
1953.9	6.1451
1956.86	5.52278
1959.82	5.26638
1962.78	6.33361
1965.74	7.39752
1968.7	8.74463
1971.65	8.61752
1974.61	7.85121
1977.57	8.06122
1980.52	7.91992
1983.47	7.96548
1986.42	7.32815
1989.37	6.74156
1992.32	6.99921
1995.27	5.86481
1998.22	5.63024
2001.17	5.68447
2004.11	5.91713
2007.05	6.10501
2010	6.64799
2012.94	6.69987
2015.88	6.3148
2018.82	5.79193
2021.76	5.59337
2024.7	5.60041
2027.63	5.58549
2030.57	6.34758
2033.5	6.65608
2036.44	7.00921
2039.37	8.16627
2042.3	8.88863
2045.23	8.39879
2048.16	8.18386
2051.08	9.46033
2054.01	10.2078
2056.94	10.5076
2059.86	10.9904
2062.79	9.78436
2065.71	9.81669
2068.63	11.1635
2071.55	12.1554
2074.47	13.2159
2077.39	13.5712
2080.31	14.0468
2083.22	16.0069
2086.13	16.1901
2089.05	16.4851
2091.96	17.447
2094.87	19.572
2097.78	21.3372
2100.69	22.7754
2103.6	23.8906
2106.51	25.8014
2109.42	28.0788
2112.32	30.088
2115.23	30.9385
2118.13	31.9047
2121.03	34.7253
2123.93	38.1013
2126.83	39.8766
2129.73	41.6458
2132.63	43.731
2135.53	45.8829
2138.42	49.0592
2141.32	51.8356
2144.21	54.0153
2147.1	55.5347
2150	58.2107
2152.89	60.0172
2155.78	62.5553
2158.66	63.6181
2161.55	65.8927
2164.44	68.3232
2167.32	69.0951
2170.21	68.958
2173.09	68.7985
2175.97	69.392
2178.85	67.7457
2181.73	66.9967
2184.61	65.3544
2187.49	63.4448
2190.37	62.0381
2193.24	59.4017
2196.12	56.5775
2198.99	53.4229
2201.87	50.1077
2204.74	47.9103
2207.61	43.8871
2210.48	40.8884
2213.35	39.048
2216.21	36.8123
2219.08	34.2314
2221.95	33.4648
2224.81	31.6679
2227.67	30.7695
2230.54	29.9918
2233.4	28.4149
2236.26	27.2606
2239.11	26.407
2241.97	25.5888
2244.83	25.0859
2247.69	24.4577
2250.54	22.8047
2253.4	21.8428
2256.25	20.9495
2259.1	20.093
2261.95	18.5655
2264.8	16.7591
2267.65	17.0652
2270.5	16.1147
2273.34	15.9054
2276.19	14.1515
2279.03	13.6644
2281.88	14.2329
2284.72	12.8035
2287.56	10.9183
2290.4	8.93726
2293.24	6.7627
2296.08	5.96435
2298.92	7.28049
2301.76	7.34298
2304.59	7.07878
2307.43	7.51035
2310.26	8.15347
2313.09	8.799
2315.92	9.77695
2318.75	9.31303
2321.58	9.01008
2324.41	9.54074
2327.24	9.62718
2330.06	9.12702
2332.89	8.84093
2335.71	10.315
2338.54	9.97127
2341.36	9.23909
2344.18	8.4336
2347	7.95
2349.82	7.33898
2352.64	5.66109
2355.45	3.91335
2358.27	1.4468
2361.08	-0.294513
2363.9	-0.311618
2366.71	1.24891
2369.52	1.49251
2372.33	0.785965
2375.14	0.0135861
2377.95	1.63292
2380.76	2.69777
2383.57	4.02475
2386.37	5.15694
2389.18	5.29851
2391.98	5.59801
2394.79	5.74706
2397.59	6.72669
2400.39	7.86274
2403.19	8.86375
2405.99	9.38395
2408.78	9.64208
2411.58	10.5001
2414.38	11.2566
2417.17	12.3248
2419.97	12.2424
2422.76	12.191
2425.55	12.2239
2428.34	11.3312
2431.13	10.375
2433.92	9.90169
2436.71	9.32224
2439.49	9.5102
2442.28	9.7665
2445.06	9.30572
2447.85	11.0167
2450.63	10.4286
2453.41	9.81972
2456.19	9.30823
2458.97	7.56025
2461.75	7.71563
2464.53	7.40226
2467.31	7.18626
2470.08	5.98179
2472.86	4.51442
2475.63	4.3517
2478.4	3.13265
2481.17	3.43255
2483.94	2.83021
2486.72	3.01369
2489.48	3.58684
2492.25	3.75809
2495.02	2.9751
2497.79	2.80327
2500.55	2.11682
2503.31	2.77442
2506.08	2.91928
2508.84	3.14663
2511.6	3.46318
2514.36	3.1465
2517.12	3.97405
2519.88	3.63931
2522.63	5.11783
2525.39	6.22377
2528.14	6.66508
2530.9	6.9093
2533.65	7.2178
2536.4	7.21818
2539.15	7.15873
2541.9	6.88042
2544.65	7.37953
2547.4	8.13779
2550.15	8.59642
2552.89	8.71299
2555.64	9.6572
2558.38	7.97636
2561.12	6.83246
2563.87	6.14166
2566.61	6.34039
2569.35	5.60363
2572.09	5.41824
2574.83	4.60221
2577.56	3.95735
2580.3	3.75786
2583.04	4.1715
2585.77	4.32638
2588.5	4.88524
2591.23	5.04057
2593.97	4.12551
2596.7	3.93429
2599.43	4.19856
2602.15	4.46826
2604.88	3.97252
2607.61	4.27289
2610.33	4.81423
2613.06	6.2439
2615.78	6.34996
2618.51	6.86657
2621.23	5.91522
2623.95	6.21108
2626.67	6.41404
2629.39	7.92013
2632.1	8.31099
2634.82	8.78442
2637.54	9.30261
2640.25	9.72872
2642.97	7.9811
2645.68	7.25761
2648.39	7.40285
2651.1	6.50987
2653.81	5.18382
2656.52	4.05752
2659.23	3.58622
2661.94	2.34281
2664.64	2.90492
2667.35	3.0579
2670.05	3.38104
2672.76	3.29576
2675.46	3.54888
2678.16	4.35351
2680.86	3.73246
2683.56	4.31051
2686.26	4.62287
2688.96	5.7454
2691.65	5.76902
2694.35	6.67698
2697.04	6.99078
2699.74	7.22554
2702.43	8.63482
2705.12	8.52159
2707.81	9.55429
2710.5	11.3566
2713.19	12.9307
2715.88	13.3759
2718.57	13.515
2721.25	14.1969
2723.94	14.7365
2726.62	14.7225
2729.3	15.3131
2731.99	15.2079
2734.67	14.7149
2737.35	14.3403
2740.03	12.8844
2742.71	10.4615
2745.38	9.2136
2748.06	7.78026
2750.74	6.30275
2753.41	5.26988
2756.09	3.16899
2758.76	2.25149
2761.43	1.32451
2764.1	0.581962
2766.77	0.85578
2769.44	1.15306
2772.11	1.42917
2774.77	1.86838
2777.44	2.46189
2780.11	2.39189
2782.77	2.80414
2785.43	3.25327
2788.1	2.99746
2790.76	3.05611
2793.42	3.36669
2796.08	2.98166
2798.74	2.15429
2801.4	0.842003
2804.05	0.64487
2806.71	-0.83535
2809.36	-1.65756
2812.02	-1.60804
2814.67	-2.87123
2817.32	-1.54821
2819.97	0.5388
2822.62	2.318
2825.27	6.5029
2827.92	10.5105
2830.57	15.4347
2833.22	20.5655
2835.86	25.7023
2838.51	32.4807
2841.15	39.1108
2843.79	47.9283
2846.43	54.6621
2849.08	63.5369
2851.72	72.5053
2854.36	80.9455
2856.99	88.9221
2859.63	96.5176
2862.27	103.852
2864.9	111.201
2867.54	117.474
2870.17	123.877
2872.8	127.696
2875.43	132.707
2878.07	136.806
2880.7	142.731
2883.32	148.1
2885.95	153.04
2888.58	158.29
2891.21	163.528
2893.83	168.133
2896.46	173.502
2899.08	178.773
2901.7	185.293
2904.32	192.31
2906.94	200.567
2909.56	209.2
2912.18	217.611
2914.8	226.797
2917.42	235.065
2920.03	241.377
2922.65	247.155
2925.26	250.674
2927.88	252.395
2930.49	253.822
2933.1	252.158
2935.71	249.19
2938.32	243.659
2940.93	238.727
2943.54	231.762
2946.14	221.884
2948.75	211.592
2951.35	200.858
2953.96	189.874
2956.56	178.951
2959.16	168.62
2961.77	159.115
2964.37	149.887
2966.96	141.555
2969.56	133.005
2972.16	126.336
2974.76	120.282
2977.35	113.227
2979.95	106.521
2982.54	99.4149
2985.14	92.2649
2987.73	84.6104
2990.32	77.2055
2992.91	70.0005
2995.5	63.5457
2998.09	55.9476
3000.68	49.5503
3003.26	42.8902
3005.85	36.1136
3008.43	29.3786
3011.02	23.7159
3013.6	19.0617
3016.19	14.3412
3018.77	10.7126
3021.35	7.35473
3023.93	5.559
3026.5	3.14089
3029.08	2.29286
3031.66	1.34767
3034.24	0.760979
3036.81	1.02615
3039.39	1.89413
3041.96	2.75461
3044.53	3.56381
3047.1	4.77678
3049.67	5.29811
3052.24	6.27671
3054.81	7.83735
3057.38	8.72707
3059.95	9.04955
3062.52	8.65536
3065.08	8.29376
3067.65	7.81824
3070.21	6.72158
3072.77	7.09024
3075.33	6.45427
3077.89	5.52852
3080.45	3.51106
3083.01	2.62008
3085.57	1.96636
3088.13	2.41024
3090.68	2.37206
3093.24	2.52465
3095.79	2.26117
3098.35	2.7484
3100.9	3.34534
3103.45	4.29758
3106	5.13215
3108.55	5.61231
3111.1	6.34031
3113.65	7.45893
3116.2	7.86604
3118.75	8.15484
3121.29	9.37233
3123.84	10.1074
3126.38	10.3578
3128.92	10.9773
3131.47	11.4987
3134.01	12.3596
3136.55	14.0852
3139.09	15.2407
3141.63	16.3215
3144.17	18.3731
3146.7	20.7479
3149.24	24.0185