File: data/Raman/poly_smoothed/Mb_40_24_28_1x_45s_532 nm_x100_100%_600 gr_mm_01.txt
#Acq. time (s)=	45
#Accumulations=	2
#Range (cm-¹)=	200...3150
#Windows=	2
#Auto scanning=	Off
#Autofocus=	Off
#Macrospot=	Off
#AutoExposure=	Off
#Spike filter=	Multiple accum.
#Delay time (s)=	0
#Binning=	1
#Readout mode=	Signal
#DeNoise=	Off
#ICS correction=	On
#Dark correction=	Off
#Inst. Process=	Off
#Detector Gain=	Best Dynamic Range
#Detector ADC=	20 kHz
#Detector temperature (°C)=	-70.31
#Instrument=	LabRAM HR Evol
#Detector=	Synapse
#Objective=	x100
#Grating=	600 gr/mm
#ND Filter=	100%
#Laser (nm)=	532
#Hole=	100.021
#Range=	Auto
#Laser Pol.=	No
#Raman. Pol.=	No
#Laser Pol. (°)=	-0.0007625
#Raman Pol. (°)=	89.9995
#Collection=	Microscope
#StageXY=	Marzhauser
#StageZ=	Marzhauser
#X (µm)=	-2481.5
#Y (µm)=	-112.4
#Z (µm)=	-10.05
#Full time(mm:ss)=	3:08
#Project=
#Sample=
#Site=
#Title=	Mb_40_24_28_2x_45s_532 nm_x100_100%_600 gr_mm
#Remark=
#Date=	14.07.2022 12:46
#Acquired=	14.07.2022 12:46:49
#Base:Fit=	10.08.2022 10:47:00
#Base:Sub=	10.08.2022 10:47:12
#Filter:Polynom=	16.08.2022 10:11:48
#AxisType[0]=Intens
#AxisUnit[0]=Cnt
#AxisType[1]=Spectr
#AxisUnit[1]=1/cm
200.554	19.2717
204.183	19.5826
207.813	19.4099
211.439	19.3831
215.065	18.6151
218.688	17.0066
222.312	14.3076
225.933	12.6958
229.552	12.0094
233.171	11.1552
236.787	9.58967
240.402	9.77903
244.015	8.8803
247.627	7.62705
251.24	5.85754
254.849	5.73934
258.457	7.2774
262.063	6.34134
265.668	6.43848
269.271	5.48148
272.873	6.71426
276.474	5.29494
280.073	4.041
283.671	5.95414
287.268	4.93217
290.863	5.6754
294.456	6.86855
298.049	6.68403
301.637	7.14741
305.227	6.91176
308.815	6.6041
312.402	7.51377
315.987	8.87084
319.569	8.36453
323.151	8.67116
326.733	8.51293
330.31	10.6407
333.889	11.6218
337.464	12.6712
341.039	12.8766
344.611	11.2
348.184	11.4221
351.754	11.4989
355.324	10.5936
358.89	9.83583
362.455	8.91802
366.021	7.95602
369.584	8.43267
373.145	6.85455
376.707	6.58221
380.265	6.51006
383.822	6.02785
387.378	4.88882
390.934	4.61519
394.487	4.58198
398.038	3.64005
401.588	2.26798
405.137	1.64144
408.685	2.42185
412.23	2.14103
415.775	1.61581
419.318	1.46352
422.86	2.44244
426.401	0.161925
429.94	0.196193
433.478	1.33342
437.012	1.87904
440.547	1.3785
444.081	1.88268
447.613	2.0521
451.142	3.25228
454.672	3.98249
458.2	4.93763
461.725	5.48687
465.251	7.76025
468.775	7.01609
472.296	8.84974
475.817	10.5775
479.335	10.9002
482.854	11.587
486.37	14.0139
489.886	15.8509
493.398	18.7763
496.91	19.7906
500.422	20.6884
503.93	22.7381
507.438	24.7191
510.946	26.2049
514.45	26.1893
517.954	27.519
521.456	28.1854
524.956	28.3687
528.456	28.0269
531.956	27.709
535.452	26.3606
538.947	26.2181
542.441	25.0516
545.934	23.8974
549.425	23.3662
552.915	21.1718
556.403	20.0859
559.889	17.5397
563.375	15.8015
566.859	14.7561
570.342	13.4226
573.824	12.8787
577.303	10.5891
580.782	8.36832
584.26	7.03242
587.734	7.07655
591.21	5.39231
594.684	5.77332
598.154	6.6738
601.626	7.7138
605.094	8.55089
608.562	9.22949
612.027	9.11448
615.493	8.48262
618.956	9.50186
622.419	10.3921
625.879	12.4154
629.338	14.7224
632.797	17.0937
636.254	17.0511
639.708	18.2132
643.162	18.0371
646.614	18.3806
650.067	18.427
653.516	18.8417
656.964	17.1294
660.411	16.4241
663.857	16.8167
667.301	18.4351
670.744	18.8338
674.186	21.4581
677.626	22.611
681.065	27.7029
684.503	30.0772
687.939	30.7974
691.372	31.3062
694.806	33.5189
698.239	34.4671
701.67	37.4642
705.098	39.213
708.526	41.1408
711.954	42.253
715.378	43.1934
718.802	45.14
722.226	46.0413
725.646	44.6571
729.067	43.6794
732.484	44.882
735.902	43.7235
739.317	43.5576
742.731	43.3068
746.145	46.9921
749.556	49.1093
752.966	50.9122
756.377	54.7626
759.784	60.6585
763.19	64.515
766.594	67.7632
770	68.8686
773.402	71.4859
776.803	74.944
780.202	78.4084
783.6	80.3852
786.997	82.675
790.393	84.2297
793.787	85.4266
797.18	86.4671
800.572	87.6871
803.963	88.0585
807.35	85.3247
810.738	85.0323
814.125	84.2028
817.51	83.0956
820.894	83.235
824.275	80.5393
827.657	81.2104
831.037	81.6394
834.414	81.2116
837.792	80.2004
841.167	79.5352
844.542	78.3831
847.914	76.5559
851.287	73.948
854.656	72.681
858.026	70.265
861.393	68.9983
864.761	67.2622
868.125	66.5206
871.489	65.3245
874.85	62.5355
878.213	61.0076
881.572	63.0961
884.931	62.204
888.287	62.0278
891.643	61.1316
894.997	60.0508
898.352	60.3784
901.704	59.6433
905.055	59.3232
908.404	59.3031
911.75	58.8077
915.097	57.786
918.443	56.8574
921.787	56.4743
925.13	55.1191
928.472	52.6886
931.813	51.623
935.15	48.1091
938.488	47.4877
941.825	45.7725
945.158	43.1913
948.493	41.0293
951.824	40.2805
955.156	39.5396
958.486	39.3872
961.814	39.7638
965.142	40.3611
968.467	39.3204
971.79	40.6592
975.115	39.894
978.436	41.8988
981.756	44.0583
985.077	43.6119
988.394	45.5754
991.71	46.044
995.025	46.0494
998.341	46.3155
1001.65	47.3046
1004.97	48.6772
1008.28	49.0321
1011.58	50.9086
1014.89	52.7819
1018.2	55.4201
1021.5	57.4516
1024.81	57.1818
1028.11	58.2123
1031.41	60.3604
1034.71	62.6597
1038.01	62.3476
1041.31	61.4012
1044.6	61.2688
1047.9	60.926
1051.19	60.9487
1054.48	59.2396
1057.77	58.7287
1061.06	58.2488
1064.35	56.3986
1067.64	54.1194
1070.93	51.3321
1074.21	48.166
1077.49	42.9706
1080.78	40.2859
1084.06	38.9144
1087.34	35.9662
1090.61	33.6736
1093.89	32.649
1097.17	31.8812
1100.44	30.5152
1103.71	28.4508
1106.99	26.3896
1110.26	25.1031
1113.52	24.8611
1116.79	24.0285
1120.06	21.171
1123.32	19.5313
1126.59	17.9058
1129.85	17.3636
1133.11	16.1984
1136.37	16.1619
1139.63	15.2363
1142.89	13.4205
1146.15	12.2355
1149.4	10.9362
1152.66	8.17787
1155.91	6.14686
1159.16	3.99227
1162.41	3.56586
1165.66	2.4613
1168.91	1.13874
1172.16	0.0175435
1175.4	1.09314
1178.65	2.32425
1181.89	1.63624
1185.13	2.43263
1188.37	3.66866
1191.61	5.13446
1194.85	5.73272
1198.08	6.52819
1201.32	6.53495
1204.55	8.66215
1207.79	11.0684
1211.02	13.3858
1214.25	16.2969
1217.48	21.0755
1220.71	24.4332
1223.93	28.4394
1227.16	32.4017
1230.38	36.6088
1233.6	40.9064
1236.83	44.3603
1240.05	49.4547
1243.26	52.9769
1246.48	57.1626
1249.7	60.3487
1252.92	63.4434
1256.13	66.6656
1259.34	68.0755
1262.55	70.5184
1265.76	74.8798
1268.97	77.8978
1272.18	79.9685
1275.39	80.6858
1278.59	82.6584
1281.8	85.2893
1285	85.5141
1288.2	85.2594
1291.4	86.6008
1294.6	86.1496
1297.8	87.9295
1301	86.0826
1304.19	86.4265
1307.39	84.8217
1310.58	84.1792
1313.77	84.0338
1316.96	83.537
1320.15	82.1902
1323.34	79.987
1326.53	74.5018
1329.72	70.9104
1332.9	69.4152
1336.08	66.8194
1339.27	64.3361
1342.45	63.07
1345.63	60.2012
1348.8	56.0031
1351.98	51.8712
1355.16	48.9185
1358.33	44.5935
1361.51	41.3163
1364.68	38.2562
1367.85	36.5864
1371.02	34.934
1374.19	35.1768
1377.36	34.932
1380.52	34.897
1383.69	35.107
1386.85	36.533
1390.02	39.9738
1393.18	40.9376
1396.34	40.7387
1399.5	40.9601
1402.65	42.1437
1405.81	44.379
1408.97	47.0923
1412.12	51.2502
1415.27	55.0616
1418.43	60.0768
1421.58	64.6147
1424.73	70.7246
1427.87	77.664
1431.02	83.4788
1434.17	88.1233
1437.31	92.8214
1440.46	97.8641
1443.6	100.823
1446.74	102.439
1449.88	101.5
1453.02	99.8783
1456.16	97.0675
1459.29	92.9406
1462.43	87.1907
1465.56	82.066
1468.69	73.2102
1471.83	65.2987
1474.95	57.372
1478.08	48.9702
1481.21	41.1625
1484.34	33.6084
1487.47	27.3104
1490.59	22.8911
1493.71	18.7448
1496.84	15.6725
1499.96	14.3962
1503.07	13.2828
1506.19	13.4121
1509.31	12.7527
1512.43	11.9919
1515.54	11.2531
1518.65	11.0962
1521.77	10.0883
1524.88	10.2779
1527.99	10.2628
1531.1	10.7586
1534.21	11.9958
1537.31	13.3272
1540.42	14.6417
1543.52	18.1962
1546.63	20.6869
1549.73	23.2778
1552.83	25.6168
1555.93	28.4376
1559.03	31.3583
1562.12	34.7986
1565.22	35.9454
1568.31	38.6907
1571.41	41.6291
1574.5	45.4029
1577.59	49.661
1580.68	54.3862
1583.77	56.1147
1586.86	57.5369
1589.95	59.7747
1593.03	61.4665
1596.11	62.3909
1599.2	61.1918
1602.28	62.5886
1605.36	63.094
1608.44	63.0801
1611.52	63.1203
1614.6	64.1217
1617.67	66.6884
1620.75	68.5262
1623.82	71.0871
1626.89	73.2412
1629.96	75.6285
1633.04	79.1572
1636.11	81.7991
1639.17	85.1746
1642.24	89.248
1645.31	93.8519
1648.37	98.0873
1651.43	101.431
1654.5	102.98
1657.56	104.052
1660.62	103.45
1663.67	103.004
1666.73	100.907
1669.79	97.1439
1672.84	90.7719
1675.9	86.6245
1678.95	81.3444
1682	74.7414
1685.05	68.0234
1688.1	61.0764
1691.15	55.8474
1694.2	48.3355
1697.25	42.9174
1700.29	36.7307
1703.33	31.5975
1706.38	27.7793
1709.42	24.8098
1712.46	22.2865
1715.5	20.0688
1718.54	18.8668
1721.57	16.6558
1724.61	15.0222
1727.64	12.8456
1730.68	11.7108
1733.71	11.0082
1736.74	11.8887
1739.77	11.6104
1742.8	11.6846
1745.83	10.6795
1748.85	10.1178
1751.88	11.0566
1754.91	11.0656
1757.93	9.68685
1760.95	9.85319
1763.97	7.82199
1766.99	6.38246
1770.01	5.97646
1773.03	5.41024
1776.04	4.99733
1779.06	4.29615
1782.07	4.07239
1785.09	3.8334
1788.1	3.74836
1791.11	2.99357
1794.12	2.73051
1797.13	2.32869
1800.13	2.05658
1803.14	1.90918
1806.15	1.89485
1809.15	2.34496
1812.15	2.7405
1815.16	2.1924
1818.15	2.20055
1821.16	2.27618
1824.15	2.49537
1827.15	2.70593
1830.15	2.98542
1833.14	2.96118
1836.14	3.25107
1839.13	2.90969
1842.12	2.9659
1845.11	3.35825
1848.1	3.19641
1851.09	2.89019
1854.08	3.34308
1857.06	4.47478
1860.05	4.84669
1863.03	6.55395
1866.01	6.59818
1869	6.25994
1871.98	5.12741
1874.96	4.78364
1877.93	4.13885
1880.91	4.42983
1882.47	4.07624
1885.46	3.36781
1888.44	3.63916
1891.43	3.20414
1894.42	3.73224
1897.4	4.45726
1900.39	4.77547
1903.37	3.72199
1906.35	3.34481
1909.33	3.52993
1912.31	3.60545
1915.29	4.73152
1918.26	5.04284
1921.24	5.30457
1924.21	6.6908
1927.19	8.38057
1930.16	8.54006
1933.13	9.05472
1936.1	9.76731
1939.07	8.85527
1942.04	9.17817
1945	10.0054
1947.97	11.7891
1950.93	11.9311
1953.9	11.2086
1956.86	10.7669
1959.82	10.7445
1962.78	10.8687
1965.74	11.562
1968.7	11.5759
1971.65	11.3415
1974.61	10.3729
1977.57	10.5863
1980.52	11.6155
1983.47	12.5667
1986.42	12.8243
1989.37	12.4837
1992.32	12.6715
1995.27	13.9613
1998.22	14.8484
2001.17	15.3708
2004.11	16.1141
2007.05	17.2533
2010	17.7487
2012.94	18.2135
2015.88	18.0681
2018.82	17.8233
2021.76	17.4891
2024.7	17.2111
2027.63	16.9772
2030.57	16.9948
2033.5	16.1961
2036.44	15.6099
2039.37	15.501
2042.3	15.5623
2045.23	16.4191
2048.16	16.999
2051.08	17.5321
2054.01	19.5819
2056.94	20.538
2059.86	21.2166
2062.79	22.0018
2065.71	23.6865
2068.63	24.6861
2071.55	26.4608
2074.47	27.761
2077.39	28.7453
2080.31	30.5839
2083.22	31.596
2086.13	33.0303
2089.05	34.3166
2091.96	37.0044
2094.87	39.9201
2097.78	42.194
2100.69	42.9811
2103.6	44.8638
2106.51	47.189
2109.42	50.2593
2112.32	53.5378
2115.23	56.7663
2118.13	59.7192
2121.03	63.8094
2123.93	66.7824
2126.83	69.6531
2129.73	72.5068
2132.63	74.7488
2135.53	78.9022
2138.42	82.1194
2141.32	86.1085
2144.21	91.1398
2147.1	95.2904
2150	99.5627
2152.89	103.425
2155.78	107.672
2158.66	111.237
2161.55	114.987
2164.44	117.179
2167.32	117.805
2170.21	119.273
2173.09	119.496
2175.97	120.201
2178.85	118.935
2181.73	117.068
2184.61	113.499
2187.49	111.888
2190.37	108.41
2193.24	103.966
2196.12	99.0409
2198.99	94.8994
2201.87	89.5945
2204.74	85.7038
2207.61	81.6027
2210.48	77.3045
2213.35	73.7695
2216.21	70.3987
2219.08	66.3744
2221.95	62.3593
2224.81	59.6867
2227.67	55.1773
2230.54	52.4693
2233.4	49.4259
2236.26	47.0521
2239.11	45.1303
2241.97	43.9878
2244.83	40.7152
2247.69	38.4977
2250.54	36.1752
2253.4	34.5993
2256.25	33.2345
2259.1	32.7161
2261.95	30.5249
2264.8	29.3695
2267.65	28.6725
2270.5	27.5574
2273.34	26.5301
2276.19	24.5071
2279.03	24.4299
2281.88	24.2552
2284.72	23.2777
2287.56	21.9953
2290.4	20.3684
2293.24	18.8518
2296.08	18.1384
2298.92	18.2895
2301.76	18.8236
2304.59	19.2601
2307.43	18.7046
2310.26	18.1387
2313.09	17.4195
2315.92	16.3168
2318.75	16.5042
2321.58	15.5089
2324.41	14.687
2327.24	13.7541
2330.06	13.0476
2332.89	12.328
2335.71	11.5261
2338.54	9.28695
2341.36	7.8032
2344.18	7.13971
2347	7.22606
2349.82	6.65298
2352.64	7.09858
2355.45	4.73927
2358.27	4.52847
2361.08	4.20551
2363.9	5.07569
2366.71	6.10021
2369.52	6.41688
2372.33	6.79466
2375.14	6.3172
2377.95	7.03837
2380.76	7.60641
2383.57	7.74827
2386.37	6.77714
2389.18	6.83006
2391.98	5.88474
2394.79	5.34139
2397.59	4.96366
2400.39	5.11787
2403.19	5.08959
2405.99	3.8351
2408.78	4.11326
2411.58	4.64351
2414.38	4.64487
2417.17	6.24796
2419.97	6.20797
2422.76	5.93177
2425.55	5.13993
2428.34	4.9362
2431.13	3.60886
2433.92	3.18167
2436.71	1.7081
2439.49	2.50372
2442.28	2.76071
2445.06	2.68623
2447.85	3.15119
2450.63	3.25994
2453.41	2.58622
2456.19	2.70884
2458.97	2.62458
2461.75	2.74309
2464.53	2.94802
2467.31	3.89264
2470.08	3.77421
2472.86	3.50817
2475.63	3.35747
2478.4	3.75824
2481.17	3.83183
2483.94	5.16587
2486.72	4.87452
2489.48	3.33371
2492.25	3.52776
2495.02	2.99234
2497.79	1.94598
2500.55	1.49897
2503.31	1.20288
2506.08	1.59124
2508.84	2.29324
2511.6	1.01301
2514.36	0.979711
2517.12	0.885565
2519.88	0.478052
2522.63	0.950511
2525.39	0.549655
2528.14	1.12275
2530.9	0.919564
2533.65	1.47189
2536.4	1.81164
2539.15	1.66216
2541.9	1.92938
2544.65	2.53418
2547.4	2.77859
2550.15	3.23885
2552.89	2.92899
2555.64	3.15
2558.38	2.5776
2561.12	3.20522
2563.87	2.83594
2566.61	2.50416
2569.35	1.84332
2572.09	1.24286
2574.83	1.28092
2577.56	1.00604
2580.3	0.447173
2583.04	0.188728
2585.77	0.27796
2588.5	0.260385
2591.23	0.96688
2593.97	1.45529
2596.7	0.643188
2599.43	0.835378
2602.15	2.37837
2604.88	1.41749
2607.61	1.59784
2610.33	1.5875
2613.06	0.515673
2615.78	1.11809
2618.51	1.15977
2621.23	1.88315
2623.95	1.68742
2626.67	1.56258
2629.39	1.65198
2632.1	1.62503
2634.82	1.70549
2637.54	1.56984
2640.25	2.32131
2642.97	1.62993
2645.68	0.972836
2648.39	1.0406
2651.1	1.41879
2653.81	1.39244
2656.52	1.81325
2659.23	2.87033
2661.94	2.98833
2664.64	2.94073
2667.35	3.78073
2670.05	4.04574
2672.76	4.06517
2675.46	4.40973
2678.16	4.23884
2680.86	5.13742
2683.56	5.90155
2686.26	6.57196
2688.96	7.32853
2691.65	7.78241
2694.35	8.95765
2697.04	9.43991
2699.74	10.0547
2702.43	9.89715
2705.12	10.8006
2707.81	11.708
2710.5	11.8984
2713.19	11.9867
2715.88	11.7234
2718.57	10.8179
2721.25	10.6517
2723.94	10.8289
2726.62	10.6183
2729.3	9.96356
2731.99	9.87261
2734.67	8.56525
2737.35	7.98519
2740.03	6.53131
2742.71	5.78618
2745.38	4.73147
2748.06	4.45773
2750.74	2.70434
2753.41	2.12091
2756.09	1.61613
2758.76	2.14303
2761.43	1.82148
2764.1	2.15122
2766.77	2.06526
2769.44	2.34617
2772.11	2.43549
2774.77	1.62911
2777.44	1.02615
2780.11	1.16458
2782.77	2.10619
2785.43	3.14317
2788.1	3.98172
2790.76	4.98438
2793.42	4.47447
2796.08	3.81846
2798.74	3.09322
2801.4	2.82591
2804.05	2.73564
2806.71	2.19366
2809.36	1.3281
2812.02	1.75064
2814.67	2.00345
2817.32	4.02943
2819.97	6.90727
2822.62	11.2059
2825.27	15.3377
2827.92	21.0301
2830.57	27.155
2833.22	34.108
2835.86	41.3885
2838.51	49.0278
2841.15	58.9063
2843.79	69.4195
2846.43	80.4519
2849.08	91.1565
2851.72	102.267
2854.36	111.811
2856.99	120.916
2859.63	130.466
2862.27	138.935
2864.9	146.601
2867.54	154.061
2870.17	159.742
2872.8	164.748
2875.43	169.951
2878.07	176.019
2880.7	181.655
2883.32	187.317
2885.95	195.3
2888.58	202.167
2891.21	208.859
2893.83	216.641
2896.46	226.029
2899.08	236.107
2901.7	246.314
2904.32	257.112
2906.94	270.918
2909.56	284.771
2912.18	298.621
2914.8	312.677
2917.42	325.637
2920.03	336.823
2922.65	347.335
2925.26	354.142
2927.88	357.752
2930.49	358.378
2933.1	356.397
2935.71	351.817
2938.32	345.748
2940.93	338.663
2943.54	329.262
2946.14	318.345
2948.75	305.657
2951.35	291.571
2953.96	276
2956.56	260.905
2959.16	246.633
2961.77	231.697
2964.37	217.555
2966.96	203.706
2969.56	191.019
2972.16	180.05
2974.76	169.425
2977.35	159.452
2979.95	149.758
2982.54	139.369
2985.14	129.546
2987.73	119.255
2990.32	107.405
2992.91	96.0227
2995.5	86.2918
2998.09	76.8362
3000.68	69.4775
3003.26	61.9877
3005.85	54.5561
3008.43	47.1895
3011.02	41.4346
3013.6	35.1877
3016.19	30.9021
3018.77	26.2852
3021.35	22.559
3023.93	19.515
3026.5	17.9381
3029.08	16.1459
3031.66	13.9331
3034.24	13.2751
3036.81	13.8011
3039.39	14.1566
3041.96	14.6114
3044.53	15.0177
3047.1	15.3102
3049.67	14.8351
3052.24	13.3867
3054.81	12.8368
3057.38	12.1687
3059.95	11.6772
3062.52	10.3697
3065.08	10.0357
3067.65	9.49828
3070.21	8.86903
3072.77	7.8167
3075.33	7.57438
3077.89	6.20568
3080.45	5.69027
3083.01	5.08159
3085.57	3.86493
3088.13	3.51592
3090.68	2.1632
3093.24	0.880158
3095.79	0.868406
3098.35	1.45777
3100.9	2.16775
3103.45	2.27781
3106	3.13608
3108.55	4.05084
3111.1	3.88122
3113.65	4.96947
3116.2	5.46324
3118.75	5.88369
3121.29	6.60202
3123.84	7.27953
3126.38	8.08124
3128.92	9.89477
3131.47	10.8298
3134.01	11.8628
3136.55	12.298
3139.09	12.1489
3141.63	11.9919
3144.17	10.7209
3146.7	9.03884
3149.24	7.97927