File: data/Raman/poly_smoothed/Mb_40_y_40_1x_45s_532 nm_x100_100%_600 gr_mm_01.txt
#Acq. time (s)=	45
#Accumulations=	2
#Range (cm-¹)=	200...3150
#Windows=	2
#Auto scanning=	Off
#Autofocus=	Off
#Macrospot=	Off
#AutoExposure=	Off
#Spike filter=	Multiple accum.
#Delay time (s)=	0
#Binning=	1
#Readout mode=	Signal
#DeNoise=	Off
#ICS correction=	On
#Dark correction=	Off
#Inst. Process=	Off
#Detector Gain=	Best Dynamic Range
#Detector ADC=	20 kHz
#Detector temperature (°C)=	-69.85
#Instrument=	LabRAM HR Evol
#Detector=	Synapse
#Objective=	x100
#Grating=	600 gr/mm
#ND Filter=	100%
#Laser (nm)=	532
#Hole=	100.021
#Range=	Auto
#Laser Pol.=	No
#Raman. Pol.=	No
#Laser Pol. (°)=	-0.0007625
#Raman Pol. (°)=	89.9995
#Collection=	Microscope
#StageXY=	Marzhauser
#StageZ=	Marzhauser
#X (µm)=	-1077.6
#Y (µm)=	600.9
#Z (µm)=	584.45
#Full time(mm:ss)=	3:18
#Project=
#Sample=
#Site=
#Title=	Mb_40_y_40_2x_45s_532 nm_x100_100%_600 gr_mm
#Remark=
#Date=	19.07.2022 12:42
#Acquired=	19.07.2022 12:42:42
#Base:Fit=	10.08.2022 10:52:48
#Base:Sub=	10.08.2022 10:52:53
#Filter:Polynom=	16.08.2022 10:09:04
#AxisType[0]=Intens
#AxisUnit[0]=Cnt
#AxisType[1]=Spectr
#AxisUnit[1]=1/cm
200.423	39.8292
204.052	32.5516
207.682	27.6053
211.308	23.6209
214.935	19.1006
218.558	15.0875
222.18	11.8551
225.802	11.2908
229.421	11.7459
233.039	9.52256
236.657	7.41122
240.272	5.87755
243.885	5.84505
247.497	5.67942
251.11	7.02205
254.719	7.01163
258.327	8.54533
261.933	9.52845
265.538	9.47088
269.141	11.2916
272.744	12.7616
276.344	13.6237
279.944	13.4277
283.542	12.5373
287.138	12.0423
290.733	13.7736
294.327	15.1361
297.919	14.5521
301.508	16.0287
305.098	17.5602
308.686	18.9107
312.273	20.0869
315.858	21.2365
319.44	19.5138
323.022	19.5709
326.604	18.9305
330.181	20.1324
333.76	19.9876
337.335	20.7628
340.91	21.3617
344.483	20.7488
348.055	19.4738
351.625	17.4623
355.195	16.9277
358.762	15.1218
362.329	13.7525
365.893	12.7063
369.455	10.2569
373.017	9.62304
376.578	9.20484
380.137	9.95818
383.694	10.3296
387.249	11.3651
390.806	12.1224
394.359	11.4085
397.91	9.39216
401.46	8.38617
405.009	8.95926
408.557	9.05457
412.103	8.99124
415.647	7.57553
419.191	7.73154
422.733	7.9445
426.273	6.81085
429.812	5.84258
433.35	4.84312
436.885	4.9075
440.42	4.1652
443.954	5.03626
447.486	4.25948
451.015	4.23412
454.545	6.69022
458.073	7.00168
461.598	7.8905
465.124	9.41372
468.648	10.3844
472.169	11.2364
475.69	11.7653
479.208	11.9622
482.727	11.6602
486.243	13.0147
489.759	14.7472
493.272	15.4426
496.783	16.3382
500.295	16.6529
503.804	17.7435
507.311	18.7314
510.819	18.8045
514.324	19.7713
517.827	21.6187
521.329	20.9505
524.83	21.2596
528.329	20.1844
531.829	19.4167
535.326	19.1621
538.821	16.996
542.315	16.3213
545.808	14.3295
549.299	11.9718
552.789	9.77705
556.278	7.32135
559.763	5.73585
563.249	3.44129
566.733	2.09424
570.217	1.37848
573.699	1.43942
577.177	0.526334
580.656	1.16709
584.134	0.975106
587.609	1.16166
591.084	0.80577
594.558	0.474689
598.029	2.01699
601.5	3.34613
604.968	3.56702
608.437	4.26884
611.902	4.52058
615.368	4.14584
618.831	4.10176
622.294	3.97071
625.755	4.04748
629.213	5.2865
632.673	5.40576
636.129	5.38652
639.584	6.16448
643.037	6.67312
646.491	7.31176
649.942	7.3273
653.392	8.54792
656.84	9.16435
660.287	9.47971
663.732	9.63455
667.177	9.01991
670.62	10.6875
674.061	11.7554
677.502	14.0557
680.941	17.1647
684.379	18.2705
687.815	21.9034
691.248	23.6436
694.682	26.3672
698.115	28.1335
701.546	29.9687
704.974	33.541
708.402	35.3273
711.83	35.4513
715.254	37.6771
718.679	38.6406
722.102	38.6311
725.522	39.4698
728.943	39.5748
732.361	39.0001
735.779	39.7956
739.194	40.348
742.608	40.0115
746.022	39.791
749.433	40.6629
752.843	42.1021
756.254	42.6097
759.661	44.2486
763.067	45.6601
766.471	46.8296
769.877	49.0389
773.279	51.2519
776.68	52.7631
780.079	54.9752
783.478	56.7543
786.875	59.7868
790.27	61.3755
793.665	61.6996
797.058	62.2339
800.45	63.6224
803.84	62.1378
807.23	62.4231
810.616	62.7715
814.002	61.1467
817.388	62.2083
820.772	62.6998
824.153	61.743
827.535	61.2768
830.915	59.338
834.292	58.9948
837.67	57.4393
841.047	55.0952
844.42	53.4074
847.794	51.0142
851.165	50.6377
854.534	49.6749
857.905	46.8634
861.272	45.6588
864.639	46.0753
868.004	46.8745
871.367	44.6431
874.731	43.4788
878.092	41.9952
881.451	40.8106
884.809	41.0421
888.166	40.0375
891.522	41.5682
894.878	41.3085
898.231	40.7848
901.583	40.6779
904.934	40.2619
908.283	41.226
911.631	40.6461
914.976	39.7636
918.322	39.0654
921.666	38.0568
925.009	38.7636
928.351	37.4605
931.692	37.4952
935.029	37.6022
938.367	36.204
941.704	35.7002
945.038	35.8959
948.372	34.8707
951.705	34.2533
955.035	33.8392
958.366	32.9214
961.693	31.8097
965.021	31.9769
968.346	31.4611
971.67	29.6518
974.995	29.5385
978.316	28.3045
981.638	28.3548
984.957	28.493
988.274	27.1536
991.59	25.2143
994.907	21.8977
998.221	18.5506
1001.53	13.5389
1004.85	12.4408
1008.16	15.4349
1011.46	24.048
1014.77	38.0484
1018.08	53.5154
1021.38	68.4641
1024.69	80.9376
1027.99	94.4923
1031.29	107.564
1034.59	117.112
1037.89	122.956
1041.19	128.352
1044.48	130.011
1047.78	130.124
1051.07	127.533
1054.36	122.328
1057.66	116.488
1060.94	106.395
1064.23	94.6357
1067.52	79.476
1070.81	64.4959
1074.09	48.3824
1077.38	32.2664
1080.66	18.9069
1083.94	10.376
1087.22	8.09501
1090.5	8.94967
1093.77	9.94348
1097.05	11.3823
1100.32	13.0251
1103.6	15.0166
1106.87	16.7458
1110.14	19.4165
1113.41	19.4223
1116.67	19.9299
1119.94	18.9515
1123.21	19.8214
1126.47	19.2335
1129.73	19.0256
1133	16.0096
1136.26	16.0098
1139.52	13.7944
1142.77	12.893
1146.03	12.189
1149.29	10.8092
1152.54	9.32599
1155.79	8.46042
1159.04	7.19466
1162.3	6.36017
1165.55	4.04402
1168.79	2.06261
1172.04	-0.159797
1175.28	-1.87598
1178.53	-0.888568
1181.77	0.259062
1185.01	1.09273
1188.25	0.613708
1191.49	1.52577
1194.73	1.54601
1197.97	2.84435
1201.2	2.92176
1204.44	2.94508
1207.67	5.10306
1210.9	5.73198
1214.13	7.86992
1217.36	8.436
1220.59	10.5847
1223.82	13.505
1227.04	16.5995
1230.26	19.5786
1233.49	21.8868
1236.71	25.3414
1239.93	26.6725
1243.15	30.0019
1246.37	31.1281
1249.58	32.0815
1252.8	33.3939
1256.01	35.1859
1259.23	37.6842
1262.44	40.2235
1265.65	41.4838
1268.86	42.2558
1272.07	42.7676
1275.27	42.7882
1278.48	44.5454
1281.68	45.677
1284.89	46.4843
1288.09	49.3425
1291.29	49.6148
1294.49	49.1068
1297.69	49.8633
1300.88	51.9913
1304.08	51.3515
1307.27	52.3136
1310.47	51.5366
1313.66	52.0484
1316.85	50.8398
1320.04	50.6874
1323.23	49.6413
1326.41	48.5309
1329.6	48.1208
1332.78	47.8692
1335.97	46.8823
1339.15	46.398
1342.33	46.402
1345.51	44.7606
1348.69	43.3414
1351.87	43.4218
1355.04	44.294
1358.22	43.8379
1361.39	42.6737
1364.57	41.7244
1367.74	41.2247
1370.91	40.4887
1374.07	38.8393
1377.24	38.1971
1380.41	36.8045
1383.57	35.1974
1386.74	35.3778
1389.9	35.6322
1393.06	35.0778
1396.22	34.7052
1399.38	36.6195
1402.54	37.5187
1405.7	40.8107
1408.85	42.938
1412.01	45.9385
1415.16	48.6331
1418.31	51.5309
1421.46	54.1654
1424.61	57.5875
1427.76	61.0099
1430.91	63.9353
1434.05	66.168
1437.2	69.2705
1440.34	71.4994
1443.49	71.0972
1446.63	72.9188
1449.77	70.7539
1452.91	70.2688
1456.04	68.4705
1459.18	67.1214
1462.31	64.801
1465.45	61.103
1468.58	58.1129
1471.71	54.387
1474.84	52.3608
1477.97	50.214
1481.1	47.4782
1484.23	44.6917
1487.35	40.4325
1490.48	38.0436
1493.6	34.4939
1496.72	31.6047
1499.84	30.4151
1502.96	28.2737
1506.08	27.2783
1509.2	27.0271
1512.31	25.2097
1515.43	24.3558
1518.54	23.7993
1521.66	24.5741
1524.77	24.6345
1527.88	25.57
1530.99	26.062
1534.09	26.3044
1537.2	26.5012
1540.31	26.0465
1543.41	28.2717
1546.51	29.9578
1549.62	31.8346
1552.72	33.282
1555.82	34.5857
1558.91	34.7443
1562.01	34.2336
1565.11	35.3856
1568.2	36.4079
1571.3	38.136
1574.39	39.5867
1577.48	40.5304
1580.57	41.1227
1583.66	41.7832
1586.75	42.1498
1589.83	41.8191
1592.92	42.8518
1596	41.9059
1599.09	41.7452
1602.17	41.525
1605.25	41.1902
1608.33	39.9408
1611.41	39.5082
1614.48	40.7986
1617.56	40.0429
1620.64	40.7829
1623.71	42.2796
1626.78	43.6624
1629.86	45.8363
1632.92	47.1056
1635.99	47.7543
1639.06	48.4633
1642.13	49.6125
1645.19	51.0482
1648.26	52.3911
1651.32	51.7016
1654.38	51.7735
1657.45	51.2577
1660.51	49.1038
1663.57	46.8319
1666.62	45.3572
1669.68	43.8602
1672.73	41.0094
1675.79	37.5501
1678.84	34.471
1681.89	30.3075
1684.94	26.0803
1687.99	24.3307
1691.04	20.9209
1694.09	18.8528
1697.14	17.9846
1700.18	17.1443
1703.22	14.9133
1706.27	12.8616
1709.31	10.8156
1712.35	9.69606
1715.39	8.36377
1718.43	8.41591
1721.46	8.21043
1724.5	8.63171
1727.53	8.1678
1730.57	7.93761
1733.6	6.64486
1736.63	5.46777
1739.66	5.72054
1742.69	6.44478
1745.72	5.2199
1748.74	3.71281
1751.77	3.14761
1754.8	2.76567
1757.82	1.61821
1760.84	1.93916
1763.86	1.43837
1766.88	1.10295
1769.9	0.581194
1772.92	-0.00619358
1775.93	-0.0587817
1778.95	0.275324
1781.96	0.600793
1784.98	2.21849
1787.99	2.83958
1791	3.60701
1794.01	3.80149
1797.02	4.00595
1800.03	4.06278
1803.03	4.62477
1806.04	3.96888
1809.04	3.64218
1812.04	4.45472
1815.05	4.80115
1818.05	4.20397
1821.05	4.32293
1824.05	5.03058
1827.04	4.57649
1830.04	4.6635
1833.03	4.65687
1836.03	4.33539
1839.02	3.84776
1842.01	4.27459
1845	4.12815
1847.99	4.37963
1850.98	5.54585
1853.97	5.68391
1856.95	6.74366
1859.94	6.94175
1862.92	5.92697
1865.91	5.51725
1868.89	5.18419
1871.87	5.67412
1874.85	5.36542
1877.83	5.05134
1880.8	5.10819
1882.56	5.46826
1885.54	4.91039
1888.53	5.25835
1891.52	5.61588
1894.5	6.65233
1897.49	6.54696
1900.47	6.52481
1903.45	6.98555
1906.43	6.35829
1909.41	6.28414
1912.39	7.9941
1915.37	8.76322
1918.35	8.91776
1921.32	9.48798
1924.3	9.02312
1927.27	9.37759
1930.24	8.55485
1933.21	7.15645
1936.18	6.63106
1939.15	6.34281
1942.12	6.1979
1945.09	5.67398
1948.05	4.8358
1951.02	5.09244
1953.98	4.38788
1956.94	4.32482
1959.91	3.89364
1962.87	5.29892
1965.82	5.60677
1968.78	6.564
1971.74	6.71796
1974.7	7.83223
1977.65	8.74535
1980.6	9.53474
1983.56	11.3176
1986.51	12.2789
1989.46	12.1334
1992.41	12.7335
1995.36	13.3485
1998.3	14.0793
2001.25	14.5421
2004.2	14.4314
2007.14	14.5061
2010.08	14.9914
2013.02	15.7873
2015.97	16.7783
2018.9	16.0994
2021.84	16.8276
2024.78	16.929
2027.72	16.9122
2030.65	18.1303
2033.59	18.9038
2036.52	18.9917
2039.45	18.9655
2042.38	19.8424
2045.31	20.2958
2048.24	20.0682
2051.17	20.3666
2054.1	21.1733
2057.02	20.6397
2059.95	21.2418
2062.87	22.6342
2065.79	22.7949
2068.71	22.7982
2071.63	22.4616
2074.55	24.2184
2077.47	24.4889
2080.39	25.866
2083.3	27.4582
2086.22	28.4587
2089.13	28.5847
2092.05	29.9242
2094.96	31.4819
2097.87	32.1175
2100.78	33.4727
2103.69	34.6833
2106.59	35.8872
2109.5	37.2489
2112.41	38.5264
2115.31	40.0765
2118.21	42.5072
2121.12	43.31
2124.02	44.7955
2126.92	46.7599
2129.82	48.479
2132.71	51.1337
2135.61	52.6504
2138.51	53.795
2141.4	55.7265
2144.29	58.3435
2147.19	59.8245
2150.08	62.1602
2152.97	64.0884
2155.86	65.7989
2158.75	66.5335
2161.64	67.8223
2164.52	68.9604
2167.41	70.0218
2170.29	70.9993
2173.17	71.4052
2176.06	70.9279
2178.94	70.9832
2181.82	70.1869
2184.7	68.9878
2187.57	67.8317
2190.45	65.3276
2193.33	63.3705
2196.2	61.9299
2199.08	60.75
2201.95	59.0591
2204.82	55.8608
2207.69	52.9062
2210.56	49.8516
2213.43	48.1118
2216.3	45.4389
2219.16	44.1894
2222.03	42.3292
2224.89	40.5574
2227.75	38.7345
2230.62	37.1954
2233.48	36.1617
2236.34	35.1162
2239.2	33.5161
2242.06	30.9995
2244.91	28.781
2247.77	26.7921
2250.62	25.336
2253.48	24.3653
2256.33	23.0685
2259.18	22.5798
2262.03	22.079
2264.88	22.0832
2267.73	20.5045
2270.58	18.6652
2273.43	17.4487
2276.27	17.1207
2279.12	15.8678
2281.96	14.8286
2284.8	14.189
2287.64	13.3861
2290.49	12.7153
2293.32	11.7213
2296.16	12.2332
2299	12.3175
2301.84	12.9794
2304.67	13.8885
2307.51	13.0496
2310.34	11.9747
2313.17	11.8152
2316	11.8217
2318.83	11.7782
2321.66	11.508
2324.49	11.7052
2327.32	12.1258
2330.15	12.0786
2332.97	11.2714
2335.79	10.1034
2338.62	8.77658
2341.44	8.71857
2344.26	7.67638
2347.08	6.17511
2349.9	4.84441
2352.72	3.17702
2355.53	1.90985
2358.35	0.823206
2361.17	0.304314
2363.98	0.840533
2366.79	2.87377
2369.6	2.47939
2372.42	1.75835
2375.22	1.71995
2378.03	0.232841
2380.84	0.3202
2383.65	1.27905
2386.45	1.56005
2389.26	2.13505
2392.06	3.20991
2394.87	4.09405
2397.67	4.22176
2400.47	3.94455
2403.27	3.67506
2406.07	3.72077
2408.86	3.66748
2411.66	3.77642
2414.46	3.65271
2417.25	4.62446
2420.05	4.92976
2422.84	4.94416
2425.63	5.14898
2428.42	5.22227
2431.21	5.36476
2434	4.61076
2436.79	3.73739
2439.57	2.62897
2442.36	2.00553
2445.14	1.78231
2447.93	2.27981
2450.71	2.37704
2453.49	2.60589
2456.27	3.21569
2459.05	2.7289
2461.83	2.71799
2464.61	2.57112
2467.39	2.48937
2470.16	2.69868
2472.94	2.64911
2475.71	2.90767
2478.48	3.78803
2481.25	4.65249
2484.02	4.70919
2486.8	5.00996
2489.56	4.61451
2492.33	4.45289
2495.1	2.99748
2497.86	2.13377
2500.63	1.38339
2503.39	1.06591
2506.16	1.69419
2508.92	2.49609
2511.68	3.11314
2514.44	3.30614
2517.2	3.43133
2519.95	3.52583
2522.71	3.88076
2525.47	3.82505
2528.22	3.88241
2530.98	4.38119
2533.73	6.06186
2536.48	5.96105
2539.23	6.28062
2541.98	6.35379
2544.73	6.5787
2547.48	6.01102
2550.23	5.5819
2552.97	5.10961
2555.72	4.84307
2558.46	4.45142
2561.2	3.73688
2563.95	3.78773
2566.69	4.08801
2569.43	4.28312
2572.17	4.39243
2574.91	4.51236
2577.64	4.37191
2580.38	3.42841
2583.11	2.79168
2585.85	1.95203
2588.58	1.39847
2591.31	1.65766
2594.04	2.2321
2596.78	2.51518
2599.51	2.84945
2602.23	3.25262
2604.96	2.51055
2607.69	2.70715
2610.41	2.24494
2613.14	2.34854
2615.86	2.69241
2618.58	2.22522
2621.3	2.03615
2624.03	2.49897
2626.75	2.41068
2629.46	2.06655
2632.18	2.23003
2634.9	1.79634
2637.61	2.14463
2640.33	1.78043
2643.04	1.63148
2645.76	1.20014
2648.47	1.29345
2651.18	1.45742
2653.89	1.44035
2656.6	1.52158
2659.31	1.9246
2662.01	2.7772
2664.72	2.50457
2667.43	3.02481
2670.13	4.25469
2672.83	4.51898
2675.53	4.96945
2678.24	5.63326
2680.94	5.62853
2683.64	6.06622
2686.34	6.93746
2689.03	7.99286
2691.73	7.93641
2694.43	8.13551
2697.12	8.69484
2699.81	8.89546
2702.51	8.52807
2705.2	8.41186
2707.89	7.81468
2710.58	8.0611
2713.27	7.62309
2715.96	7.22611
2718.64	6.73993
2721.33	6.84158
2724.01	6.66653
2726.7	6.34374
2729.38	5.39968
2732.06	5.74457
2734.75	5.89875
2737.43	7.00545
2740.11	6.86272
2742.78	6.2709
2745.46	6.14335
2748.14	6.1554
2750.81	6.10737
2753.49	6.76665
2756.16	6.59725
2758.84	6.3573
2761.51	6.16556
2764.18	6.16541
2766.85	5.46873
2769.52	5.03474
2772.19	4.95126
2774.85	3.96671
2777.52	2.58988
2780.18	1.9987
2782.85	1.0386
2785.51	0.98977
2788.17	1.47505
2790.84	1.27624
2793.5	0.801406
2796.16	1.11659
2798.81	0.884964
2801.47	1.19984
2804.13	0.783131
2806.79	0.0415327
2809.44	-0.175728
2812.09	-1.11776
2814.75	-0.659302
2817.4	1.33242
2820.05	3.51257
2822.7	5.4452
2825.35	7.50792
2828	10.4577
2830.65	13.2371
2833.29	17.0885
2835.94	20.2403
2838.58	23.6347
2841.23	26.6192
2843.87	30.3484
2846.51	35.8872
2849.15	41.8933
2851.79	47.8203
2854.43	52.8812
2857.07	57.5237
2859.71	62.9147
2862.34	66.9515
2864.98	70.8041
2867.61	74.5049
2870.25	76.9163
2872.88	79.4084
2875.51	81.9988
2878.14	84.38
2880.77	87.8651
2883.4	91.1394
2886.03	93.4023
2888.65	96.2341
2891.28	99.0833
2893.91	101.381
2896.53	104.18
2899.15	107.433
2901.78	110.803
2904.4	115.16
2907.02	120.265
2909.64	126.458
2912.26	133.045
2914.87	138.662
2917.49	144.384
2920.11	150.133
2922.72	154.123
2925.34	158.098
2927.95	160.394
2930.56	162.15
2933.17	162.614
2935.78	161.8
2938.39	160.703
2941	158.012
2943.61	155.343
2946.22	151.825
2948.82	146.384
2951.43	140.17
2954.03	132.906
2956.64	125.705
2959.24	119.687
2961.84	113.162
2964.44	105.827
2967.04	99.2487
2969.64	93.3002
2972.24	87.4195
2974.83	82.5976
2977.43	76.1934
2980.02	70.2802
2982.62	65.5701
2985.21	60.2781
2987.8	54.2455
2990.4	48.3824
2992.99	43.0648
2995.57	37.2838
2998.16	32.7516
3000.75	28.0284
3003.34	23.8063
3005.92	20.801
3008.51	17.121
3011.09	13.3183
3013.68	10.4467
3016.26	7.91641
3018.84	6.532
3021.42	5.2207
3024	4.06432
3026.58	3.14271
3029.16	2.64899
3031.73	3.02897
3034.31	3.84569
3036.89	4.60301
3039.46	4.99316
3042.03	5.74597
3044.61	6.91039
3047.18	7.29847
3049.75	6.68093
3052.32	6.20738
3054.89	6.21203
3057.45	6.20061
3060.02	6.46569
3062.59	5.89444
3065.15	5.45068
3067.72	5.14972
3070.28	4.01231
3072.84	2.62018
3075.41	2.84708
3077.97	2.71311
3080.53	1.72634
3083.09	1.39785
3085.64	0.427447
3088.2	0.358195
3090.76	0.19079
3093.31	-0.494368
3095.87	0.585561
3098.42	0.793646
3100.97	1.22407
3103.53	1.84052
3106.08	2.73762
3108.63	3.53203
3111.18	3.79043
3113.73	4.7401
3116.27	5.53289
3118.82	6.17094
3121.37	7.13542
3123.91	7.87693
3126.45	8.5663
3129	8.20943
3131.54	9.36652
3134.08	10.4434
3136.62	11.6272
3139.16	12.091
3141.7	12.6716
3144.24	13.1908
3146.78	14.2995
3149.31	17.036