File: data/Raman/poly_smoothed/Mb_40_y_48_1x_45s_532 nm_x100_100%_600 gr_mm_01.txt
#Acq. time (s)=	45
#Accumulations=	2
#Range (cm-¹)=	200...3150
#Windows=	2
#Auto scanning=	Off
#Autofocus=	Off
#Macrospot=	Off
#AutoExposure=	Off
#Spike filter=	Multiple accum.
#Delay time (s)=	0
#Binning=	1
#Readout mode=	Signal
#DeNoise=	Off
#ICS correction=	On
#Dark correction=	Off
#Inst. Process=	Off
#Detector Gain=	Best Dynamic Range
#Detector ADC=	20 kHz
#Detector temperature (°C)=	-69.85
#Instrument=	LabRAM HR Evol
#Detector=	Synapse
#Objective=	x100
#Grating=	600 gr/mm
#ND Filter=	100%
#Laser (nm)=	532
#Hole=	100.021
#Range=	Auto
#Laser Pol.=	No
#Raman. Pol.=	No
#Laser Pol. (°)=	-0.0007625
#Raman Pol. (°)=	89.9995
#Collection=	Microscope
#StageXY=	Marzhauser
#StageZ=	Marzhauser
#X (µm)=	-1148.1
#Y (µm)=	681.8
#Z (µm)=	584.65
#Full time(mm:ss)=	3:19
#Project=
#Sample=
#Site=
#Title=	Mb_40_y_48_2x_45s_532 nm_x100_100%_600 gr_mm
#Remark=
#Date=	19.07.2022 13:34
#Acquired=	19.07.2022 13:34:44
#Base:Fit=	10.08.2022 10:52:48
#Base:Sub=	10.08.2022 10:52:53
#Filter:Polynom=	16.08.2022 10:09:04
#AxisType[0]=Intens
#AxisUnit[0]=Cnt
#AxisType[1]=Spectr
#AxisUnit[1]=1/cm
200.423	75.3659
204.052	71.6137
207.682	64.1935
211.308	58.6637
214.935	54.305
218.558	49.8645
222.18	45.2369
225.802	40.4292
229.421	35.9977
233.039	33.2761
236.657	29.9016
240.272	26.7193
243.885	24.1586
247.497	20.1118
251.11	17.8702
254.719	15.2293
258.327	12.6458
261.933	12.1757
265.538	9.2955
269.141	7.73788
272.744	6.34898
276.344	4.01798
279.944	3.87976
283.542	3.36153
287.138	1.95966
290.733	1.03454
294.327	1.52194
297.919	3.71396
301.508	3.05941
305.098	3.23458
308.686	2.62348
312.273	2.27865
315.858	2.70741
319.44	5.14586
323.022	5.75982
326.604	5.32606
330.181	5.96551
333.76	4.71754
337.335	5.25024
340.91	5.93377
344.483	5.26201
348.055	4.92066
351.625	3.32357
355.195	3.03783
358.762	1.79875
362.329	1.1305
365.893	1.83245
369.455	2.76741
373.017	2.62827
376.578	1.73686
380.137	1.7952
383.694	4.42846
387.249	3.92782
390.806	2.93014
394.359	3.32519
397.91	5.53926
401.46	8.27571
405.009	10.566
408.557	12.2824
412.103	13.2809
415.647	13.8791
419.191	14.9085
422.733	15.2594
426.273	15.2606
429.812	14.0416
433.35	13.4977
436.885	13.5923
440.42	12.6956
443.954	11.0885
447.486	9.90542
451.015	9.74737
454.545	7.95272
458.073	6.7272
461.598	4.05277
465.124	4.11574
468.648	4.15233
472.169	5.95907
475.69	6.17608
479.208	7.93036
482.727	11.8564
486.243	14.7481
489.759	16.7289
493.272	19.6007
496.783	21.4267
500.295	22.5222
503.804	23.0239
507.311	25.0724
510.819	26.9496
514.324	29.4318
517.827	29.6918
521.329	31.8088
524.83	31.3252
528.329	29.1461
531.829	28.3479
535.326	26.024
538.821	22.991
542.315	21.7443
545.808	19.5111
549.299	18.4097
552.789	17.6095
556.278	17.0455
559.763	15.6183
563.249	14.1611
566.733	12.0266
570.217	11.8118
573.699	9.87904
577.177	9.20838
580.656	7.25048
584.134	6.23307
587.609	6.32478
591.084	5.72943
594.558	6.27121
598.029	7.89905
601.5	8.94107
604.968	8.99292
608.437	9.47803
611.902	9.63522
615.368	9.65874
618.831	8.95549
622.294	8.14435
625.755	7.48956
629.213	8.17362
632.673	7.41832
636.129	7.80112
639.584	8.04512
643.037	7.71171
646.491	5.71912
649.942	5.36477
653.392	4.8169
656.84	4.21535
660.287	2.61802
663.732	1.73269
667.177	1.66683
670.62	1.53707
674.061	2.64678
677.502	5.25908
680.941	9.4575
684.379	11.643
687.815	12.9095
691.248	15.8486
694.682	16.4752
698.115	18.5113
701.546	20.3832
704.974	22.3493
708.402	24.8846
711.83	27.3921
715.254	28.5618
718.679	29.6081
722.102	29.9612
725.522	31.3956
728.943	30.1881
732.361	30.2276
735.779	31.5929
739.194	29.5874
742.608	28.2053
746.022	27.1782
749.433	27.4555
752.843	29.0629
756.254	30.79
759.661	32.8081
763.067	34.6294
766.471	37.7667
769.877	37.9915
773.279	40.3668
776.68	39.7964
780.079	41.4349
783.478	44.8262
786.875	47.6326
790.27	47.9329
793.665	48.8835
797.058	50.1372
800.45	50.0113
803.84	50.2433
807.23	50.7794
810.616	49.8505
814.002	48.7688
817.388	48.1616
820.772	47.4179
824.153	45.2739
827.535	44.7275
830.915	44.0019
834.292	44.1728
837.67	43.0511
841.047	43.3901
844.42	42.3039
847.794	40.6757
851.165	38.7995
854.534	37.3695
857.905	36.1956
861.272	35.8036
864.639	36.1761
868.004	36.5516
871.367	34.6321
874.731	32.9843
878.092	32.9188
881.451	32.23
884.809	31.3505
888.166	29.358
891.522	28.5338
894.878	25.5541
898.231	27.5827
901.583	26.453
904.934	26.4379
908.283	26.8068
911.631	28.2147
914.976	28.7632
918.322	30.3978
921.666	33.8825
925.009	38.0595
928.351	40.8683
931.692	42.8292
935.029	46.6502
938.367	49.9484
941.704	51.9346
945.038	52.3057
948.372	54.0477
951.705	55.4864
955.035	55.3287
958.366	55.049
961.693	53.8538
965.021	55.8287
968.346	57.1089
971.67	58.0513
974.995	58.112
978.316	58.8232
981.638	58.1825
984.957	56.3319
988.274	54.0157
991.59	50.0353
994.907	46.2469
998.221	41.6318
1001.53	36.5509
1004.85	35.0284
1008.16	43.6191
1011.46	62.918
1014.77	90.4537
1018.08	121.927
1021.38	153.009
1024.69	183.692
1027.99	210.654
1031.29	235.699
1034.59	254.752
1037.89	267.948
1041.19	278.795
1044.48	286.983
1047.78	290.601
1051.07	285.084
1054.36	277.261
1057.66	262.098
1060.94	241.54
1064.23	216.908
1067.52	187.86
1070.81	154.694
1074.09	120.222
1077.38	86.2909
1080.66	57.0264
1083.94	37.2837
1087.22	29.3464
1090.5	32.2664
1093.77	37.0253
1097.05	42.3685
1100.32	45.567
1103.6	46.8377
1106.87	47.9101
1110.14	46.9803
1113.41	46.8732
1116.67	45.9862
1119.94	45.6387
1123.21	44.6783
1126.47	44.4922
1129.73	41.2846
1133	38.7972
1136.26	36.352
1139.52	32.829
1142.77	29.1759
1146.03	25.5102
1149.29	20.2935
1152.54	16.1967
1155.79	10.7391
1159.04	8.76806
1162.3	5.9349
1165.55	3.39727
1168.79	3.16517
1172.04	5.01425
1175.28	7.16979
1178.53	9.1643
1181.77	10.7189
1185.01	14.0408
1188.25	16.3559
1191.49	18.4361
1194.73	21.8035
1197.97	24.563
1201.2	27.2271
1204.44	30.7149
1207.67	33.9732
1210.9	39.5432
1214.13	46.2979
1217.36	51.4444
1220.59	57.1541
1223.82	62.1387
1227.04	68.3266
1230.26	74.8389
1233.49	82.207
1236.71	87.7868
1239.93	93.6222
1243.15	100.057
1246.37	106.082
1249.58	112.54
1252.8	120.392
1256.01	125.398
1259.23	130.767
1262.44	137.538
1265.65	145.297
1268.86	150.063
1272.07	154.913
1275.27	159.097
1278.48	164.11
1281.68	168.441
1284.89	174.266
1288.09	178.089
1291.29	181.569
1294.49	184.825
1297.69	186.786
1300.88	186.979
1304.08	187.535
1307.27	188.977
1310.47	187.131
1313.66	186.938
1316.85	183.241
1320.04	178.734
1323.23	176.138
1326.41	171.411
1329.6	167.004
1332.78	163.621
1335.97	158.99
1339.15	156.203
1342.33	152.553
1345.51	149.355
1348.69	143.236
1351.87	139.161
1355.04	136.085
1358.22	132.914
1361.39	129.367
1364.57	124.485
1367.74	121.466
1370.91	116.233
1374.07	113.388
1377.24	111.716
1380.41	111.6
1383.57	112.06
1386.74	111.857
1389.9	112.268
1393.06	112.804
1396.22	114.063
1399.38	118.26
1402.54	122.86
1405.7	128.583
1408.85	137.951
1412.01	146.877
1415.16	156.07
1418.31	166.01
1421.46	177.948
1424.61	191.813
1427.76	204.968
1430.91	218.522
1434.05	229.753
1437.2	239.102
1440.34	245.478
1443.49	248.696
1446.63	248.949
1449.77	247.78
1452.91	244.952
1456.04	238.3
1459.18	227.458
1462.31	215.557
1465.45	200.782
1468.58	183.175
1471.71	164.897
1474.84	146.781
1477.97	129.796
1481.1	113.369
1484.23	100.777
1487.35	87.6555
1490.48	74.7456
1493.6	65.2622
1496.72	59.5154
1499.84	55.006
1502.96	53.3993
1506.08	52.4759
1509.2	52.9042
1512.31	53.3063
1515.43	55.7457
1518.54	58.1844
1521.66	57.8811
1524.77	61.3936
1527.88	65.4251
1530.99	68.1806
1534.09	70.8798
1537.2	75.4147
1540.31	79.797
1543.41	83.8532
1546.51	87.9941
1549.62	91.8729
1552.72	97.4516
1555.82	101.971
1558.91	107.276
1562.01	112.227
1565.11	116.031
1568.2	120.877
1571.3	127.747
1574.39	133.025
1577.48	138.424
1580.57	144.473
1583.66	149.263
1586.75	154.517
1589.83	160.201
1592.92	162.503
1596	165.628
1599.09	166.496
1602.17	168.915
1605.25	170.902
1608.33	171.662
1611.41	173.248
1614.48	175.146
1617.56	175.998
1620.64	176.692
1623.71	180.624
1626.78	183.492
1629.86	185.584
1632.92	187.936
1635.99	190.82
1639.06	193.8
1642.13	198.61
1645.19	199.887
1648.26	202.187
1651.32	203.754
1654.38	204.332
1657.45	203.584
1660.51	202.271
1663.57	198.377
1666.62	193.449
1669.68	187.843
1672.73	179.227
1675.79	169.103
1678.84	158.426
1681.89	147.107
1684.94	134.732
1687.99	122.84
1691.04	112.318
1694.09	101.578
1697.14	93.2571
1700.18	83.6395
1703.22	74.08
1706.27	65.9181
1709.31	57.9622
1712.35	50.8308
1715.39	45.5486
1718.43	41.1595
1721.46	37.3452
1724.5	34.9441
1727.53	33.0893
1730.57	32.245
1733.6	30.1378
1736.63	28.4582
1739.66	27.2509
1742.69	26.7664
1745.72	25.5012
1748.74	24.5791
1751.77	23.5925
1754.8	22.8831
1757.82	23.1252
1760.84	22.3123
1763.86	22.659
1766.88	21.3361
1769.9	21.0777
1772.92	18.4235
1775.93	16.5794
1778.95	14.7038
1781.96	12.8681
1784.98	11.3806
1787.99	10.3205
1791	9.76717
1794.01	7.76005
1797.02	6.81614
1800.03	5.89085
1803.03	4.18724
1806.04	2.94674
1809.04	1.43207
1812.04	1.12526
1815.05	1.5164
1818.05	2.11573
1821.05	2.43926
1824.05	2.27577
1827.04	3.17958
1830.04	4.21046
1833.03	3.99515
1836.03	3.79198
1839.02	4.46517
1842.01	4.79738
1845	4.50003
1847.99	4.46479
1850.98	4.26993
1853.97	3.38621
1856.95	1.75461
1859.94	3.46816
1862.92	2.49879
1865.91	1.31015
1868.89	1.06421
1871.87	1.96942
1874.85	1.31713
1877.83	0.772684
1880.8	3.27986
1882.56	4.04672
1885.54	4.71466
1888.53	5.2681
1891.52	7.16931
1894.5	8.96724
1897.49	9.63419
1900.47	9.68975
1903.45	10.9295
1906.43	11.9249
1909.41	12.7884
1912.39	13.7266
1915.37	12.8421
1918.35	12.8726
1921.32	12.1579
1924.3	11.5928
1927.27	9.19395
1930.24	9.45621
1933.21	8.88285
1936.18	7.06648
1939.15	8.111
1942.12	8.93919
1945.09	8.13401
1948.05	7.61839
1951.02	7.58483
1953.98	9.10289
1956.94	7.08903
1959.91	6.04406
1962.87	5.68209
1965.82	6.54757
1968.78	4.4819
1971.74	4.31016
1974.7	3.84724
1977.65	4.3711
1980.6	5.07522
1983.56	5.09285
1986.51	5.97639
1989.46	5.45065
1992.41	6.1324
1995.36	5.99324
1998.3	6.09671
2001.25	7.07478
2004.2	8.68599
2007.14	10.533
2010.08	11.4482
2013.02	12.3153
2015.97	13.2565
2018.9	12.1165
2021.84	13.7289
2024.78	12.9184
2027.72	14.1432
2030.65	13.123
2033.59	14.0949
2036.52	14.1408
2039.45	14.4934
2042.38	16.8386
2045.31	17.9726
2048.24	17.8492
2051.17	20.1331
2054.1	20.8794
2057.02	21.5234
2059.95	21.4321
2062.87	21.5358
2065.79	24.4441
2068.71	25.9212
2071.63	29.6274
2074.55	32.0734
2077.47	34.5812
2080.39	36.3414
2083.3	39.7285
2086.22	43.5017
2089.13	46.2011
2092.05	49.198
2094.96	52.2555
2097.87	56.6406
2100.78	61.9971
2103.69	66.984
2106.59	71.4238
2109.5	76.4589
2112.41	81.6255
2115.31	85.5916
2118.21	87.4896
2121.12	91.9307
2124.02	98.1492
2126.92	102.713
2129.82	109.29
2132.71	116.363
2135.61	123.882
2138.51	132.921
2141.4	142.005
2144.29	148.355
2147.19	155.498
2150.08	162.441
2152.97	169.914
2155.86	178.363
2158.75	184.29
2161.64	192.328
2164.52	198.436
2167.41	204.133
2170.29	208.877
2173.17	211.472
2176.06	211.894
2178.94	209.882
2181.82	205.327
2184.7	200.618
2187.57	194.283
2190.45	191.414
2193.33	186.239
2196.2	178.745
2199.08	173.097
2201.95	164.936
2204.82	156.536
2207.69	148.71
2210.56	141.599
2213.43	133.218
2216.3	124.383
2219.16	117.354
2222.03	111.87
2224.89	107.557
2227.75	101.448
2230.62	97.1038
2233.48	92.6618
2236.34	87.3181
2239.2	82.199
2242.06	77.8175
2244.91	73.1274
2247.77	66.9796
2250.62	61.1835
2253.48	58.3778
2256.33	55.7766
2259.18	53.4201
2262.03	50.0274
2264.88	46.2314
2267.73	42.1762
2270.58	38.732
2273.43	33.8932
2276.27	29.13
2279.12	27.7655
2281.96	25.7405
2284.8	23.2451
2287.64	19.2605
2290.49	17.8908
2293.32	16.274
2296.16	15.3009
2299	13.5888
2301.84	13.401
2304.67	12.7966
2307.51	13.9572
2310.34	14.6988
2313.17	13.3589
2316	12.8161
2318.83	11.7264
2321.66	14.4812
2324.49	15.1606
2327.32	16.0542
2330.15	15.1003
2332.97	14.8035
2335.79	14.4597
2338.62	11.6795
2341.44	10.4663
2344.26	9.75314
2347.08	8.03948
2349.9	7.18684
2352.72	3.9266
2355.53	3.89664
2358.35	2.96671
2361.17	2.44586
2363.98	3.73581
2366.79	3.8855
2369.6	3.62972
2372.42	4.18805
2375.22	5.37369
2378.03	6.80372
2380.84	6.13988
2383.65	6.15101
2386.45	7.32413
2389.26	8.53994
2392.06	7.76798
2394.87	8.46123
2397.67	7.86568
2400.47	7.50764
2403.27	6.46531
2406.07	6.15057
2408.86	5.29727
2411.66	5.35466
2414.46	4.50299
2417.25	4.9401
2420.05	5.87775
2422.84	6.73877
2425.63	7.03176
2428.42	6.69678
2431.21	6.65229
2434	6.67437
2436.79	6.03431
2439.57	7.4335
2442.36	6.67176
2445.14	6.26296
2447.93	5.91183
2450.71	6.16262
2453.49	5.78182
2456.27	5.60668
2459.05	4.07849
2461.83	3.76912
2464.61	3.99775
2467.39	2.15716
2470.16	1.66899
2472.94	2.341
2475.71	2.46367
2478.48	2.76896
2481.25	2.65209
2484.02	3.74407
2486.8	1.58385
2489.56	2.04766
2492.33	2.04219
2495.1	2.66366
2497.86	2.16111
2500.63	2.24993
2503.39	2.35271
2506.16	1.88853
2508.92	1.58843
2511.68	0.972431
2514.44	1.65719
2517.2	2.97479
2519.95	2.4735
2522.71	3.07616
2525.47	3.10885
2528.22	3.16789
2530.98	4.09613
2533.73	4.97901
2536.48	5.09585
2539.23	4.16646
2541.98	3.78675
2544.73	4.01694
2547.48	3.92359
2550.23	4.33164
2552.97	4.24661
2555.72	5.30308
2558.46	6.75831
2561.2	7.91594
2563.95	8.09855
2566.69	9.01776
2569.43	8.77606
2572.17	9.44475
2574.91	8.72957
2577.64	10.878
2580.38	10.4792
2583.11	12.6121
2585.85	12.3186
2588.58	12.6703
2591.31	12.7395
2594.04	12.9511
2596.78	12.9591
2599.51	12.6016
2602.23	12.2351
2604.96	10.3731
2607.69	8.58983
2610.41	7.52179
2613.14	8.28486
2615.86	6.36823
2618.58	4.904
2621.3	5.50802
2624.03	4.69011
2626.75	3.35751
2629.46	2.90572
2632.18	3.75265
2634.9	3.41147
2637.61	3.77328
2640.33	3.139
2643.04	4.58934
2645.76	6.43659
2648.47	7.68019
2651.18	7.87648
2653.89	8.46791
2656.6	9.99143
2659.31	11.0159
2662.01	11.3883
2664.72	12.5895
2667.43	12.6087
2670.13	13.2103
2672.83	12.4524
2675.53	12.7135
2678.24	13.4332
2680.94	14.7499
2683.64	15.7361
2686.34	16.7233
2689.03	16.0862
2691.73	15.0987
2694.43	16.7486
2697.12	18.5777
2699.81	19.252
2702.51	20.941
2705.2	22.7144
2707.89	24.8548
2710.58	26.4885
2713.27	26.4173
2715.96	26.994
2718.64	26.8826
2721.33	26.6733
2724.01	26.4929
2726.7	25.4063
2729.38	25.5265
2732.06	24.3342
2734.75	24.4491
2737.43	22.9703
2740.11	21.7612
2742.78	21.7031
2745.46	20.8385
2748.14	19.4084
2750.81	16.1789
2753.49	13.2077
2756.16	10.8392
2758.84	10.1613
2761.51	9.5448
2764.18	7.71769
2766.85	6.9131
2769.52	6.37828
2772.19	4.91611
2774.85	3.35622
2777.52	2.39341
2780.18	1.07813
2782.85	0.983116
2785.51	0.566024
2788.17	-0.51999
2790.84	-0.00735393
2793.5	-0.225174
2796.16	2.16062
2798.81	3.33839
2801.47	3.64317
2804.13	3.59101
2806.79	4.12289
2809.44	3.61734
2812.09	3.44
2814.75	5.00233
2817.4	6.46027
2820.05	12.8715
2822.7	22.4411
2825.35	33.4488
2828	46.3671
2830.65	59.7588
2833.29	76.0793
2835.94	93.0407
2838.58	110.137
2841.23	127.789
2843.87	147.063
2846.51	166.223
2849.15	185.782
2851.79	206.714
2854.43	227.123
2857.07	249.979
2859.71	269.28
2862.34	286.982
2864.98	302.46
2867.61	315.077
2870.25	326.358
2872.88	336.041
2875.51	344.483
2878.14	351.968
2880.77	359.855
2883.4	368.443
2886.03	379.389
2888.65	388.447
2891.28	398.001
2893.91	407.817
2896.53	419.357
2899.15	432.552
2901.78	445.848
2904.4	460.734
2907.02	478.365
2909.64	497.9
2912.26	521.609
2914.87	545.723
2917.49	568.883
2920.11	588.53
2922.72	605.364
2925.34	618.463
2927.95	629.904
2930.56	636.701
2933.17	640.237
2935.78	635.906
2938.39	627.196
2941	616.029
2943.61	599.717
2946.22	581.677
2948.82	560.538
2951.43	537.883
2954.03	510.133
2956.64	482.355
2959.24	456.158
2961.84	427.367
2964.44	400.547
2967.04	375.199
2969.64	351.776
2972.24	328.087
2974.83	307.883
2977.43	286.991
2980.02	264.647
2982.62	243.528
2985.21	223.023
2987.8	202.442
2990.4	184.908
2992.99	166.988
2995.57	151.461
2998.16	132.44
3000.75	115.706
3003.34	102.179
3005.92	89.6044
3008.51	77.2128
3011.09	66.8002
3013.68	56.9666
3016.26	45.5048
3018.84	38.0482
3021.42	31.3154
3024	26.2701
3026.58	21.0669
3029.16	17.7828
3031.73	16.0704
3034.31	13.3632
3036.89	13.082
3039.46	11.6631
3042.03	12.3627
3044.61	13.6794
3047.18	14.1993
3049.75	13.9264
3052.32	16.0557
3054.89	18.0666
3057.45	18.0009
3060.02	18.7501
3062.59	17.2274
3065.15	17.2288
3067.72	16.4298
3070.28	15.3886
3072.84	14.5389
3075.41	12.8741
3077.97	10.0492
3080.53	8.34872
3083.09	6.14328
3085.64	3.93097
3088.2	2.25402
3090.76	1.14777
3093.31	0.751821
3095.87	0.211539
3098.42	-1.30189
3100.97	-0.0657842
3103.53	0.418453
3106.08	2.80719
3108.63	5.33473
3111.18	6.37693
3113.73	8.55844
3116.27	10.9875
3118.82	13.4695
3121.37	15.9405
3123.91	18.3966
3126.45	21.9336
3129	25.0487
3131.54	29.6104
3134.08	33.2515
3136.62	36.5882
3139.16	40.0711
3141.7	43.5469
3144.24	46.785
3146.78	49.4363
3149.31	52.0783