File: data/Raman/poly_smoothed/Mb_40_y_12_1x_45s_532 nm_x100_100%_600 gr_mm_01.txt
#Acq. time (s)=	45
#Accumulations=	2
#Range (cm-¹)=	200...3150
#Windows=	2
#Auto scanning=	Off
#Autofocus=	Off
#Macrospot=	Off
#AutoExposure=	Off
#Spike filter=	Multiple accum.
#Delay time (s)=	0
#Binning=	1
#Readout mode=	Signal
#DeNoise=	Off
#ICS correction=	On
#Dark correction=	Off
#Inst. Process=	Off
#Detector Gain=	Best Dynamic Range
#Detector ADC=	20 kHz
#Detector temperature (°C)=	-69.85
#Instrument=	LabRAM HR Evol
#Detector=	Synapse
#Objective=	x100
#Grating=	600 gr/mm
#ND Filter=	100%
#Laser (nm)=	532
#Hole=	100.021
#Range=	Auto
#Laser Pol.=	No
#Raman. Pol.=	No
#Laser Pol. (°)=	-0.0007625
#Raman Pol. (°)=	89.9995
#Collection=	Microscope
#StageXY=	Marzhauser
#StageZ=	Marzhauser
#X (µm)=	-1021.7
#Y (µm)=	693.6
#Z (µm)=	584.55
#Full time(mm:ss)=	3:18
#Project=
#Sample=
#Site=
#Title=	Mb_40_y_12_2x_45s_532 nm_x100_100%_600 gr_mm
#Remark=
#Date=	19.07.2022 09:49
#Acquired=	19.07.2022 09:49:33
#Base:Fit=	10.08.2022 10:52:48
#Base:Sub=	10.08.2022 10:52:53
#Filter:Polynom=	16.08.2022 10:09:04
#AxisType[0]=Intens
#AxisUnit[0]=Cnt
#AxisType[1]=Spectr
#AxisUnit[1]=1/cm
200.423	46.1671
204.052	32.0079
207.682	22.3139
211.308	17.123
214.935	13.7637
218.558	11.2168
222.18	10.8468
225.802	9.50221
229.421	10.0971
233.039	11.9534
236.657	16.3245
240.272	20.5677
243.885	25.1247
247.497	29.6304
251.11	37.69
254.719	43.1625
258.327	50.4711
261.933	57.3148
265.538	65.0084
269.141	71.4749
272.744	78.1042
276.344	83.3795
279.944	88.0232
283.542	94.9566
287.138	102.344
290.733	106.474
294.327	112.834
297.919	115.596
301.508	116.295
305.098	116.429
308.686	117.22
312.273	116.569
315.858	113.044
319.44	110.846
323.022	109.047
326.604	106.809
330.181	103.323
333.76	98.8969
337.335	97.2221
340.91	94.5346
344.483	92.699
348.055	93.3082
351.625	92.4088
355.195	92.2549
358.762	92.0874
362.329	90.346
365.893	91.1359
369.455	94.7008
373.017	97.4375
376.578	99.8001
380.137	99.0267
383.694	102.938
387.249	105.216
390.806	110.803
394.359	114.465
397.91	119.213
401.46	122.032
405.009	127.264
408.557	134.539
412.103	138.817
415.647	144.578
419.191	150.329
422.733	158.138
426.273	164.831
429.812	171.359
433.35	178.631
436.885	186.9
440.42	194.35
443.954	204.272
447.486	211.812
451.015	223.294
454.545	232.051
458.073	241.386
461.598	247.544
465.124	254.629
468.648	269.077
472.169	290.768
475.69	323.071
479.208	355.207
482.727	381.929
486.243	403.342
489.759	416.228
493.272	419.588
496.783	418.402
500.295	408.491
503.804	394.323
507.311	373.44
510.819	347.24
514.324	317.809
517.827	285.853
521.329	251.092
524.83	214.759
528.329	178.796
531.829	140.502
535.326	100.924
538.821	65.1901
542.315	32.1644
545.808	5.43802
549.299	-13.4653
552.789	-22.7047
556.278	-20.2394
559.763	-9.02317
563.249	-0.118168
566.733	4.47327
570.217	5.65693
573.699	3.98695
577.177	3.16393
580.656	3.2876
584.134	5.16046
587.609	5.00427
591.084	3.95435
594.558	6.52452
598.029	8.66536
601.5	11.5474
604.968	13.3955
608.437	14.9781
611.902	15.6545
615.368	15.4526
618.831	17.5335
622.294	19.511
625.755	20.1537
629.213	21.5176
632.673	22.1949
636.129	23.271
639.584	23.9174
643.037	25.0825
646.491	26.6459
649.942	26.9126
653.392	27.358
656.84	23.3164
660.287	24.1824
663.732	25.4241
667.177	27.2216
670.62	29.6456
674.061	30.0082
677.502	33.011
680.941	34.3863
684.379	36.7412
687.815	37.9609
691.248	38.4643
694.682	40.1989
698.115	40.9207
701.546	44.0283
704.974	46.3139
708.402	48.2465
711.83	49.8588
715.254	51.3698
718.679	53.6948
722.102	53.7521
725.522	53.5704
728.943	54.5569
732.361	55.1268
735.779	56.8482
739.194	57.3934
742.608	59.9437
746.022	63.2151
749.433	65.2867
752.843	69.3313
756.254	71.5645
759.661	74.2595
763.067	76.6926
766.471	78.2037
769.877	83.1497
773.279	85.9556
776.68	87.5989
780.079	92.5298
783.478	95.928
786.875	100.545
790.27	104.078
793.665	106.854
797.058	107.615
800.45	108.639
803.84	110.153
807.23	111.645
810.616	111.846
814.002	112.677
817.388	114.221
820.772	114.501
824.153	113.394
827.535	112.694
830.915	111.446
834.292	111.41
837.67	110.005
841.047	109.121
844.42	108.422
847.794	107.696
851.165	107.794
854.534	106.535
857.905	105.879
861.272	106.759
864.639	108.936
868.004	109.227
871.367	109.246
874.731	108.977
878.092	108.67
881.451	108.637
884.809	110.084
888.166	109.506
891.522	109.87
894.878	111.671
898.231	112.358
901.583	113.685
904.934	114.18
908.283	117.244
911.631	121.979
914.976	124.238
918.322	129.681
921.666	131.771
925.009	134.501
928.351	138.526
931.692	140.141
935.029	143.343
938.367	146.487
941.704	147.761
945.038	147.539
948.372	146.273
951.705	143.601
955.035	139.795
958.366	135.312
961.693	130.195
965.021	124.543
968.346	118.375
971.67	109.512
974.995	102.098
978.316	94.9869
981.638	86.001
984.957	79.3667
988.274	72.7186
991.59	67.3766
994.907	58.3146
998.221	48.881
1001.53	40.9481
1004.85	37.6278
1008.16	38.4083
1011.46	41.6625
1014.77	47.384
1018.08	56.8834
1021.38	65.3184
1024.69	72.4825
1027.99	81.0383
1031.29	87.9419
1034.59	92.4027
1037.89	94.9098
1041.19	96.7907
1044.48	99.3429
1047.78	98.1738
1051.07	95.6346
1054.36	90.9396
1057.66	86.2155
1060.94	78.625
1064.23	69.6821
1067.52	58.9046
1070.81	49.0879
1074.09	35.99
1077.38	22.2582
1080.66	13.8066
1083.94	8.22462
1087.22	7.27501
1090.5	8.67055
1093.77	9.74899
1097.05	10.3699
1100.32	11.0634
1103.6	11.0558
1106.87	11.3104
1110.14	12.7457
1113.41	12.4842
1116.67	11.8643
1119.94	10.7639
1123.21	13.3353
1126.47	12.9805
1129.73	13.688
1133	13.3301
1136.26	12.7416
1139.52	12.565
1142.77	11.775
1146.03	12.4328
1149.29	10.8271
1152.54	8.60661
1155.79	6.20815
1159.04	7.15359
1162.3	6.80283
1165.55	7.23981
1168.79	5.73232
1172.04	4.35877
1175.28	4.05619
1178.53	1.41003
1181.77	2.37397
1185.01	4.60878
1188.25	5.22146
1191.49	5.74311
1194.73	5.0515
1197.97	4.24803
1201.2	4.59763
1204.44	6.64651
1207.67	5.3802
1210.9	6.75611
1214.13	6.82871
1217.36	7.35582
1220.59	7.58135
1223.82	8.29179
1227.04	8.29186
1230.26	7.19955
1233.49	8.84625
1236.71	11.4496
1239.93	11.4407
1243.15	12.2396
1246.37	11.7513
1249.58	12.6777
1252.8	14.2341
1256.01	14.7589
1259.23	15.6945
1262.44	17.2805
1265.65	18.5853
1268.86	19.0791
1272.07	21.2141
1275.27	23.2805
1278.48	23.5566
1281.68	26.2061
1284.89	27.0894
1288.09	28.0262
1291.29	30.4377
1294.49	31.6646
1297.69	33.442
1300.88	34.0647
1304.08	35.5698
1307.27	36.1822
1310.47	36.9054
1313.66	39.2097
1316.85	38.6955
1320.04	38.2227
1323.23	37.5705
1326.41	35.8735
1329.6	36.169
1332.78	36.8866
1335.97	36.0586
1339.15	35.3726
1342.33	34.7656
1345.51	33.8431
1348.69	33.743
1351.87	33.568
1355.04	30.3101
1358.22	28.4531
1361.39	28.0132
1364.57	25.6492
1367.74	24.9979
1370.91	25.6146
1374.07	24.3054
1377.24	23.8787
1380.41	23.7298
1383.57	23.666
1386.74	22.8055
1389.9	22.3548
1393.06	21.6348
1396.22	20.6925
1399.38	21.9177
1402.54	22.9621
1405.7	23.7075
1408.85	23.9966
1412.01	26.0399
1415.16	28.151
1418.31	28.8352
1421.46	30.6393
1424.61	32.1199
1427.76	33.5254
1430.91	35.1344
1434.05	36.1355
1437.2	37.3735
1440.34	38.9852
1443.49	39.6323
1446.63	43.6887
1449.77	45.4051
1452.91	47.0258
1456.04	47.0652
1459.18	47.8284
1462.31	47.9695
1465.45	46.3122
1468.58	44.3834
1471.71	42.8512
1474.84	41.4867
1477.97	39.6185
1481.1	37.5855
1484.23	33.8427
1487.35	31.8604
1490.48	29.7199
1493.6	28.2812
1496.72	26.3674
1499.84	23.6694
1502.96	19.7309
1506.08	17.5118
1509.2	14.9147
1512.31	13.5407
1515.43	12.804
1518.54	12.2594
1521.66	12.7992
1524.77	13.7138
1527.88	13.6473
1530.99	14.7418
1534.09	15.2194
1537.2	15.9135
1540.31	16.0492
1543.41	17.382
1546.51	18.4791
1549.62	19.7281
1552.72	21.3712
1555.82	23.3492
1558.91	23.064
1562.01	24.9548
1565.11	26.7446
1568.2	29.8411
1571.3	31.8654
1574.39	31.2425
1577.48	31.1102
1580.57	30.7541
1583.66	33.1914
1586.75	34.1436
1589.83	35.5997
1592.92	36.1494
1596	35.9423
1599.09	35.1808
1602.17	34.9024
1605.25	33.9436
1608.33	32.3277
1611.41	32.1239
1614.48	32.4063
1617.56	32.4521
1620.64	32.1713
1623.71	32.6211
1626.78	33.3997
1629.86	33.7852
1632.92	34.5545
1635.99	35.8091
1639.06	37.456
1642.13	38.7727
1645.19	39.4845
1648.26	40.2556
1651.32	40.9958
1654.38	41.6045
1657.45	43.2145
1660.51	44.7115
1663.57	43.7219
1666.62	43.0583
1669.68	39.5508
1672.73	37.2611
1675.79	34.227
1678.84	31.7758
1681.89	28.7315
1684.94	24.914
1687.99	23.563
1691.04	19.8984
1694.09	18.7662
1697.14	17.186
1700.18	12.6655
1703.22	11.0926
1706.27	9.28259
1709.31	7.60508
1712.35	5.77482
1715.39	4.0998
1718.43	4.42248
1721.46	4.45732
1724.5	4.19297
1727.53	3.65802
1730.57	2.75347
1733.6	3.34641
1736.63	2.86353
1739.66	3.22809
1742.69	2.67581
1745.72	2.10103
1748.74	2.52723
1751.77	2.53226
1754.8	1.73282
1757.82	2.3548
1760.84	2.96714
1763.86	3.46467
1766.88	3.3054
1769.9	4.06527
1772.92	3.68296
1775.93	4.43465
1778.95	4.08848
1781.96	2.5341
1784.98	2.80005
1787.99	3.24004
1791	3.39259
1794.01	2.24097
1797.02	1.30975
1800.03	0.40008
1803.03	0.249961
1806.04	0.388372
1809.04	0.407348
1812.04	0.655092
1815.05	0.115255
1818.05	-0.198726
1821.05	0.202321
1824.05	1.06496
1827.04	1.29066
1830.04	2.56747
1833.03	3.96969
1836.03	4.0142
1839.02	4.00948
1842.01	5.86548
1845	6.18122
1847.99	5.96702
1850.98	6.50055
1853.97	6.48651
1856.95	5.87781
1859.94	6.24849
1862.92	6.1382
1865.91	5.68427
1868.89	5.01293
1871.87	5.66763
1874.85	5.58089
1877.83	5.02278
1880.8	5.40412
1882.56	5.90759
1885.54	5.97935
1888.53	5.40787
1891.52	5.53715
1894.5	6.22791
1897.49	6.13475
1900.47	6.54582
1903.45	5.73821
1906.43	4.98174
1909.41	5.08426
1912.39	5.55872
1915.37	5.65307
1918.35	4.53241
1921.32	3.78877
1924.3	4.21685
1927.27	3.46551
1930.24	3.75648
1933.21	2.96944
1936.18	1.43498
1939.15	1.76911
1942.12	1.49549
1945.09	0.884492
1948.05	1.51036
1951.02	2.2472
1953.98	1.81263
1956.94	2.29496
1959.91	2.02387
1962.87	2.47508
1965.82	2.79034
1968.78	2.3308
1971.74	2.12845
1974.7	3.08974
1977.65	2.32512
1980.6	4.04832
1983.56	4.65915
1986.51	6.27998
1989.46	7.39205
1992.41	7.32678
1995.36	9.44286
1998.3	10.1569
2001.25	10.4415
2004.2	10.1954
2007.14	10.4846
2010.08	10.2916
2013.02	11.0624
2015.97	10.4772
2018.9	11.5024
2021.84	11.666
2024.78	10.2417
2027.72	11.261
2030.65	9.72521
2033.59	8.76936
2036.52	9.38075
2039.45	8.11084
2042.38	7.56343
2045.31	8.62078
2048.24	8.4388
2051.17	8.99086
2054.1	10.0948
2057.02	11.1039
2059.95	11.5092
2062.87	10.3636
2065.79	10.4409
2068.71	12.1186
2071.63	12.1888
2074.55	12.1111
2077.47	12.1798
2080.39	13.271
2083.3	14.3383
2086.22	15.5804
2089.13	16.6189
2092.05	17.3596
2094.96	17.3887
2097.87	19.0417
2100.78	18.5843
2103.69	19.7084
2106.59	21.5849
2109.5	23.6727
2112.41	24.9735
2115.31	27.3261
2118.21	29.0609
2121.12	29.1801
2124.02	30.738
2126.92	31.4729
2129.82	32.8591
2132.71	34.0354
2135.61	36.0316
2138.51	37.4491
2141.4	39.1801
2144.29	39.9772
2147.19	41.6207
2150.08	44.9095
2152.97	47.5943
2155.86	49.471
2158.75	51.2824
2161.64	53.0159
2164.52	53.3373
2167.41	54.6111
2170.29	55.0993
2173.17	54.9632
2176.06	55.6621
2178.94	56.1945
2181.82	56.4071
2184.7	55.607
2187.57	54.1796
2190.45	51.4636
2193.33	51.4205
2196.2	50.9179
2199.08	49.0611
2201.95	48.8228
2204.82	46.1911
2207.69	44.4538
2210.56	42.1935
2213.43	39.5182
2216.3	37.2936
2219.16	35.911
2222.03	34.0014
2224.89	31.8747
2227.75	29.2652
2230.62	27.3675
2233.48	24.6853
2236.34	22.1123
2239.2	19.2898
2242.06	17.1644
2244.91	14.9096
2247.77	13.649
2250.62	13.3178
2253.48	11.7467
2256.33	11.3144
2259.18	11.0579
2262.03	10.8275
2264.88	12.0673
2267.73	12.1277
2270.58	12.8577
2273.43	12.4066
2276.27	13.0245
2279.12	13.4802
2281.96	13.6183
2284.8	13.3041
2287.64	13.849
2290.49	13.1753
2293.32	12.3522
2296.16	11.795
2299	11.7224
2301.84	12.2711
2304.67	11.6605
2307.51	10.8663
2310.34	9.97223
2313.17	9.39587
2316	9.23012
2318.83	9.21806
2321.66	8.76352
2324.49	8.02949
2327.32	8.86716
2330.15	8.4853
2332.97	8.43876
2335.79	8.48463
2338.62	7.57634
2341.44	7.34419
2344.26	6.94405
2347.08	7.61162
2349.9	5.96604
2352.72	4.00474
2355.53	4.18801
2358.35	3.5779
2361.17	2.45376
2363.98	2.04719
2366.79	2.98665
2369.6	2.70023
2372.42	2.61422
2375.22	2.36507
2378.03	1.2489
2380.84	1.36826
2383.65	0.638904
2386.45	1.03553
2389.26	0.671548
2392.06	1.41445
2394.87	1.15703
2397.67	0.533489
2400.47	0.820861
2403.27	1.42738
2406.07	1.37254
2408.86	2.21909
2411.66	2.65932
2414.46	2.67661
2417.25	3.04611
2420.05	3.50712
2422.84	4.02693
2425.63	5.05691
2428.42	4.78932
2431.21	5.60595
2434	6.04377
2436.79	5.44686
2439.57	5.22156
2442.36	5.8805
2445.14	4.60465
2447.93	3.36592
2450.71	2.21022
2453.49	2.21743
2456.27	2.08111
2459.05	1.1973
2461.83	0.756475
2464.61	0.850154
2467.39	1.01505
2470.16	1.74684
2472.94	1.58044
2475.71	1.77792
2478.48	1.53062
2481.25	2.07176
2484.02	2.19791
2486.8	2.43601
2489.56	3.42739
2492.33	4.14746
2495.1	4.90897
2497.86	5.05588
2500.63	5.3023
2503.39	5.33962
2506.16	5.42632
2508.92	5.13733
2511.68	4.15437
2514.44	3.38239
2517.2	3.2949
2519.95	2.80792
2522.71	3.21601
2525.47	3.25237
2528.22	1.96513
2530.98	2.51949
2533.73	3.00179
2536.48	2.33973
2539.23	2.61107
2541.98	2.39707
2544.73	3.02294
2547.48	4.41465
2550.23	4.34337
2552.97	4.37021
2555.72	5.48005
2558.46	5.55406
2561.2	6.40346
2563.95	6.56625
2566.69	5.98748
2569.43	4.6633
2572.17	4.2544
2574.91	3.70248
2577.64	3.44428
2580.38	2.4862
2583.11	1.43083
2585.85	1.8068
2588.58	1.96833
2591.31	2.2253
2594.04	1.47123
2596.78	1.60627
2599.51	1.98082
2602.23	2.34414
2604.96	2.28057
2607.69	4.38075
2610.41	4.71188
2613.14	5.97688
2615.86	6.15279
2618.58	6.34192
2621.3	6.64802
2624.03	7.93302
2626.75	7.9925
2629.46	7.11426
2632.18	7.155
2634.9	7.00376
2637.61	6.31805
2640.33	6.4116
2643.04	7.38522
2645.76	7.20891
2648.47	8.28525
2651.18	7.4162
2653.89	8.30647
2656.6	7.90808
2659.31	8.19867
2662.01	6.6133
2664.72	6.76541
2667.43	5.5723
2670.13	5.8112
2672.83	5.44089
2675.53	5.27669
2678.24	5.56608
2680.94	5.03399
2683.64	4.81267
2686.34	5.03907
2689.03	4.64162
2691.73	4.64663
2694.43	4.62632
2697.12	5.35078
2699.81	6.33526
2702.51	6.46202
2705.2	7.66159
2707.89	9.58047
2710.58	10.9513
2713.27	10.5808
2715.96	11.6251
2718.64	12.0111
2721.33	12.0542
2724.01	12.2162
2726.7	11.8945
2729.38	11.5407
2732.06	11.4922
2734.75	11.8778
2737.43	11.7307
2740.11	10.9846
2742.78	10.4525
2745.46	10.0148
2748.14	8.77401
2750.81	9.78489
2753.49	9.23976
2756.16	9.93385
2758.84	9.7182
2761.51	9.0224
2764.18	9.2296
2766.85	8.86804
2769.52	8.11117
2772.19	7.65916
2774.85	6.9078
2777.52	6.38777
2780.18	5.91173
2782.85	6.05823
2785.51	5.80859
2788.17	5.72763
2790.84	5.58881
2793.5	4.4414
2796.16	4.52215
2798.81	3.47364
2801.47	3.38034
2804.13	2.91103
2806.79	3.47978
2809.44	3.68114
2812.09	4.12561
2814.75	5.36081
2817.4	5.97568
2820.05	6.12754
2822.7	6.87002
2825.35	8.41744
2828	10.6378
2830.65	12.0941
2833.29	14.4218
2835.94	17.5186
2838.58	20.6219
2841.23	23.7065
2843.87	27.7524
2846.51	30.8032
2849.15	35.2784
2851.79	39.1229
2854.43	42.7938
2857.07	45.5352
2859.71	49.4035
2862.34	53.451
2864.98	56.0946
2867.61	59.3642
2870.25	62.0461
2872.88	64.2543
2875.51	66.4878
2878.14	68.3512
2880.77	69.3929
2883.4	71.4762
2886.03	73.5429
2888.65	76.302
2891.28	77.8681
2893.91	80.1827
2896.53	83.1793
2899.15	87.0959
2901.78	90.0763
2904.4	94.0608
2907.02	99.8919
2909.64	104.909
2912.26	109.927
2914.87	116.126
2917.49	121.354
2920.11	126.687
2922.72	130.985
2925.34	136.007
2927.95	138.546
2930.56	140.163
2933.17	140.367
2935.78	139.238
2938.39	138.253
2941	135.441
2943.61	132.888
2946.22	129.191
2948.82	124.497
2951.43	119.656
2954.03	114.503
2956.64	108.34
2959.24	102.671
2961.84	97.2943
2964.44	92.1571
2967.04	87.3863
2969.64	82.5294
2972.24	78.2746
2974.83	73.3799
2977.43	68.7235
2980.02	65.169
2982.62	61.8002
2985.21	58.3091
2987.8	53.1002
2990.4	46.77
2992.99	40.8174
2995.57	35.9326
2998.16	30.9476
3000.75	26.9299
3003.34	23.1658
3005.92	19.5433
3008.51	16.7267
3011.09	13.8694
3013.68	11.5492
3016.26	8.59201
3018.84	6.17309
3021.42	4.51875
3024	3.62828
3026.58	2.78344
3029.16	2.78616
3031.73	2.77868
3034.31	2.74129
3036.89	3.82845
3039.46	4.4763
3042.03	6.05303
3044.61	7.77612
3047.18	8.1236
3049.75	6.76879
3052.32	6.05972
3054.89	7.13217
3057.45	7.66629
3060.02	8.68032
3062.59	7.95713
3065.15	8.89066
3067.72	8.13345
3070.28	8.40665
3072.84	7.95789
3075.41	8.16327
3077.97	6.49146
3080.53	5.95228
3083.09	5.99787
3085.64	5.98065
3088.2	4.8113
3090.76	3.96501
3093.31	3.68799
3095.87	3.67799
3098.42	4.0156
3100.97	3.24129
3103.53	3.32234
3106.08	3.04106
3108.63	2.1266
3111.18	2.04786
3113.73	2.65921
3116.27	3.00824
3118.82	2.53648
3121.37	2.37955
3123.91	2.99277
3126.45	3.3841
3129	3.79428
3131.54	3.9718
3134.08	4.84766
3136.62	6.44112
3139.16	7.4015
3141.7	8.12288
3144.24	9.09604
3146.78	9.82976
3149.31	12.2718