File: data/Raman/poly_smoothed/Mb_40_24_32_1x_45s_532 nm_x100_100%_600 gr_mm_01.txt
#Acq. time (s)=	45
#Accumulations=	2
#Range (cm-¹)=	200...3150
#Windows=	2
#Auto scanning=	Off
#Autofocus=	Off
#Macrospot=	Off
#AutoExposure=	Off
#Spike filter=	Multiple accum.
#Delay time (s)=	0
#Binning=	1
#Readout mode=	Signal
#DeNoise=	Off
#ICS correction=	On
#Dark correction=	Off
#Inst. Process=	Off
#Detector Gain=	Best Dynamic Range
#Detector ADC=	20 kHz
#Detector temperature (°C)=	-70.08
#Instrument=	LabRAM HR Evol
#Detector=	Synapse
#Objective=	x100
#Grating=	600 gr/mm
#ND Filter=	100%
#Laser (nm)=	532
#Hole=	100.021
#Range=	Auto
#Laser Pol.=	No
#Raman. Pol.=	No
#Laser Pol. (°)=	-0.0007625
#Raman Pol. (°)=	89.9995
#Collection=	Microscope
#StageXY=	Marzhauser
#StageZ=	Marzhauser
#X (µm)=	-2469.4
#Y (µm)=	-101.5
#Z (µm)=	-10.4
#Full time(mm:ss)=	3:19
#Project=
#Sample=
#Site=
#Title=	Mb_40_24_32_2x_45s_532 nm_x100_100%_600 gr_mm
#Remark=
#Date=	14.07.2022 13:03
#Acquired=	14.07.2022 13:03:52
#Base:Fit=	10.08.2022 10:47:00
#Base:Sub=	10.08.2022 10:47:12
#Filter:Polynom=	16.08.2022 10:11:48
#AxisType[0]=Intens
#AxisUnit[0]=Cnt
#AxisType[1]=Spectr
#AxisUnit[1]=1/cm
200.554	1.45166
204.183	2.77423
207.813	2.63637
211.439	2.61769
215.065	2.19918
218.688	1.62722
222.312	2.27037
225.933	2.0182
229.552	3.41297
233.171	4.46142
236.787	5.49067
240.402	5.34361
244.015	5.65425
247.627	5.48306
251.24	5.69267
254.849	5.26659
258.457	6.29786
262.063	7.68417
265.668	9.50196
269.271	9.03252
272.873	8.38723
276.474	6.71497
280.073	7.85049
283.671	6.57876
287.268	6.10549
290.863	6.66559
294.456	5.65134
298.049	5.8843
301.637	5.93939
305.227	4.83305
308.815	6.26917
312.402	6.6302
315.987	8.06168
319.569	8.72049
323.151	8.84917
326.733	8.69556
330.31	8.4868
333.889	8.52648
337.464	9.19607
341.039	9.41758
344.611	9.89485
348.184	9.57657
351.754	9.48312
355.324	9.05717
358.89	8.75192
362.455	8.83871
366.021	8.37801
369.584	9.18276
373.145	7.48776
376.707	8.23083
380.265	6.90924
383.822	7.33077
387.378	7.66793
390.934	6.9131
394.487	7.62433
398.038	9.1871
401.588	9.27602
405.137	8.31862
408.685	8.49146
412.23	6.67037
415.775	7.26171
419.318	8.11154
422.86	8.18141
426.401	8.17886
429.94	9.22486
433.478	9.9242
437.012	9.69012
440.547	11.2256
444.081	12.3124
447.613	12.8988
451.142	13.3888
454.672	12.6778
458.2	13.8271
461.725	14.9702
465.251	16.4043
468.775	18.8286
472.296	20.0235
475.817	19.6867
479.335	20.8588
482.854	22.7978
486.37	22.1392
489.886	20.7738
493.398	20.2172
496.91	20.6751
500.422	22.0264
503.93	21.6855
507.438	21.2273
510.946	20.8178
514.45	21.2129
517.954	21.8842
521.456	20.17
524.956	19.7814
528.456	19.03
531.956	19.3978
535.452	17.9533
538.947	19.4994
542.441	20.1931
545.934	22.2473
549.425	23.804
552.915	24.4185
556.403	22.8728
559.889	22.3977
563.375	21.2673
566.859	19.7413
570.342	19.2519
573.824	16.6753
577.303	15.5687
580.782	14.0672
584.26	13.3174
587.734	12.0356
591.21	9.55751
594.684	10.1677
598.154	11.8379
601.626	11.5122
605.094	12.018
608.562	12.804
612.027	13.4465
615.493	13.6797
618.956	14.7597
622.419	14.9599
625.879	17.2118
629.338	18.7998
632.797	21.2832
636.254	21.8365
639.708	21.0686
643.162	22.7286
646.614	22.8993
650.067	23.5402
653.516	23.8233
656.964	24.4632
660.411	23.8704
663.857	23.8079
667.301	23.9987
670.744	25.062
674.186	27.5588
677.626	29.7896
681.065	32.8
684.503	35.3135
687.939	36.9219
691.372	38.7736
694.806	41.2186
698.239	42.8063
701.67	44.1834
705.098	44.9074
708.526	46.2814
711.954	48.9261
715.378	50.6324
718.802	51.3281
722.226	52.6934
725.646	53.2395
729.067	52.6987
732.484	53.5562
735.902	53.1537
739.317	51.5134
742.731	51.7352
746.145	52.3067
749.556	51.5024
752.966	53.4317
756.377	55.4566
759.784	54.4996
763.19	57.4464
766.594	59.4304
770	62.6038
773.402	62.8344
776.803	65.3013
780.202	68.0141
783.6	70.8778
786.997	74.6125
790.393	74.8109
793.787	76.2269
797.18	77.6152
800.572	78.0726
803.963	78.3672
807.35	80.3577
810.738	82.1701
814.125	80.894
817.51	80.5556
820.894	82.1999
824.275	82.7205
827.657	84.1083
831.037	83.3074
834.414	82.6905
837.792	80.2838
841.167	77.6043
844.542	75.8849
847.914	76.0482
851.287	73.0163
854.656	69.9915
858.026	66.7062
861.393	64.6752
864.761	63.1994
868.125	60.7647
871.489	58.6629
874.85	55.6685
878.213	54.3251
881.572	52.888
884.931	51.3898
888.287	51.4691
891.643	51.7814
894.997	51.5826
898.352	50.408
901.704	53.0476
905.055	55.0619
908.404	56.0297
911.75	57.3063
915.097	58.2282
918.443	58.6772
921.787	58.3614
925.13	58.5187
928.472	59.6076
931.813	57.6071
935.15	56.8156
938.488	55.587
941.825	54.19
945.158	54.4287
948.493	52.3366
951.824	49.823
955.156	47.9244
958.486	44.7193
961.814	41.9017
965.142	39.9653
968.467	37.9816
971.79	35.9991
975.115	34.9077
978.436	32.9361
981.756	31.5632
985.077	32.7851
988.394	31.8925
991.71	30.5987
995.025	31.1082
998.341	30.4751
1001.65	29.1692
1004.97	29.0942
1008.28	29.9305
1011.58	31.5679
1014.89	32.0177
1018.2	34.3962
1021.5	35.49
1024.81	35.0163
1028.11	35.1042
1031.41	33.951
1034.71	34.3638
1038.01	34.504
1041.31	33.3799
1044.6	34.2084
1047.9	34.6736
1051.19	35.2843
1054.48	35.4074
1057.77	34.5033
1061.06	32.8169
1064.35	31.096
1067.64	29.2365
1070.93	26.7157
1074.21	24.4739
1077.49	23.7435
1080.78	23.4544
1084.06	21.983
1087.34	22.6145
1090.61	22.2928
1093.89	22.4961
1097.17	22.6578
1100.44	20.5587
1103.71	18.7889
1106.99	17.716
1110.26	16.4329
1113.52	15.6754
1116.79	15.4062
1120.06	14.2582
1123.32	14.9469
1126.59	17.2947
1129.85	16.2414
1133.11	15.5025
1136.37	13.2048
1139.63	13.0796
1142.89	12.6246
1146.15	11.317
1149.4	10.5815
1152.66	11.5638
1155.91	9.80784
1159.16	8.65746
1162.41	7.68383
1165.66	7.62145
1168.91	7.0902
1172.16	6.33437
1175.4	5.52739
1178.65	4.58315
1181.89	3.34888
1185.13	4.13633
1188.37	2.6083
1191.61	3.67445
1194.85	3.13085
1198.08	3.45938
1201.32	4.4753
1204.55	7.21354
1207.79	7.23969
1211.02	9.46166
1214.25	12.2926
1217.48	14.9435
1220.71	18.2476
1223.93	20.8529
1227.16	23.4412
1230.38	27.1252
1233.6	28.6361
1236.83	30.5154
1240.05	33.5351
1243.26	35.8086
1246.48	37.3582
1249.7	37.9899
1252.92	39.1767
1256.13	41.2742
1259.34	42.2764
1262.55	43.1976
1265.76	43.1131
1268.97	43.699
1272.18	43.5615
1275.39	43.1487
1278.59	43.8015
1281.8	44.2933
1285	45.4325
1288.2	47.6305
1291.4	49.8026
1294.6	50.6581
1297.8	52.1403
1301	53.9032
1304.19	56.4281
1307.39	57.2526
1310.58	57.6446
1313.77	57.8791
1316.96	58.1877
1320.15	56.6632
1323.34	56.3302
1326.53	54.3857
1329.72	53.2713
1332.9	51.4592
1336.08	50.0774
1339.27	48.1366
1342.45	44.7843
1345.63	43.1319
1348.8	41.1752
1351.98	38.6572
1355.16	36.656
1358.33	34.4899
1361.51	32.6903
1364.68	32.0361
1367.85	31.8043
1371.02	30.8266
1374.19	29.4392
1377.36	29.4639
1380.52	29.4201
1383.69	29.6762
1386.85	28.7128
1390.02	28.5913
1393.18	26.9628
1396.34	26.7161
1399.5	26.1985
1402.65	26.9962
1405.81	27.1946
1408.97	27.8097
1412.12	28.2472
1415.27	30.7761
1418.43	33.5556
1421.58	35.6255
1424.73	38.6786
1427.87	42.4526
1431.02	44.9576
1434.17	48.9017
1437.31	51.4626
1440.46	53.3677
1443.6	55.2554
1446.74	57.4043
1449.88	57.4421
1453.02	58.7008
1456.16	57.4916
1459.29	56.3477
1462.43	53.4627
1465.56	50.3663
1468.69	48.9156
1471.83	46.3737
1474.95	43.1831
1478.08	41.0721
1481.21	38.6861
1484.34	34.5989
1487.47	31.0604
1490.59	28.3928
1493.71	28.0041
1496.84	25.4923
1499.96	23.6586
1503.07	22.1677
1506.19	21.6944
1509.31	20.7557
1512.43	19.839
1515.54	17.7235
1518.65	17.591
1521.77	17.536
1524.88	17.2013
1527.99	16.074
1531.1	15.7829
1534.21	14.6585
1537.31	14.6644
1540.42	15.149
1543.52	17.2448
1546.63	18.6797
1549.73	19.7639
1552.83	20.8626
1555.93	22.5043
1559.03	21.802
1562.12	22.7436
1565.22	25.596
1568.31	28.7323
1571.41	29.7899
1574.5	30.8105
1577.59	32.8731
1580.68	35.6888
1583.77	37.6883
1586.86	39.568
1589.95	40.6598
1593.03	42.3284
1596.11	43.2091
1599.2	42.76
1602.28	42.8396
1605.36	42.5086
1608.44	42.3903
1611.52	42.7399
1614.6	42.7513
1617.67	43.5803
1620.75	43.3337
1623.82	43.7835
1626.89	44.5782
1629.96	45.0106
1633.04	45.4699
1636.11	46.6359
1639.17	49.199
1642.24	50.8637
1645.31	50.6441
1648.37	50.9843
1651.43	51.8426
1654.5	52.3117
1657.56	52.4577
1660.62	51.1775
1663.67	49.7075
1666.73	47.975
1669.79	45.262
1672.84	40.7529
1675.9	37.2337
1678.95	34.7091
1682	31.8359
1685.05	28.5691
1688.1	24.572
1691.15	21.4282
1694.2	18.2699
1697.25	15.1987
1700.29	13.4591
1703.33	11.4443
1706.38	10.5726
1709.42	10.2947
1712.46	10.3977
1715.5	9.63907
1718.54	9.3458
1721.57	8.72299
1724.61	9.03647
1727.64	10.0429
1730.68	10.4273
1733.71	10.0678
1736.74	9.81375
1739.77	9.70075
1742.8	9.19806
1745.83	8.50832
1748.85	9.84091
1751.88	9.05651
1754.91	9.60449
1757.93	8.91537
1760.95	8.32032
1763.97	6.72092
1766.99	5.6852
1770.01	5.36577
1773.03	4.59042
1776.04	4.20203
1779.06	4.30211
1782.07	3.91037
1785.09	3.81837
1788.1	3.73797
1791.11	3.28408
1794.12	3.45154
1797.13	2.70638
1800.13	2.39183
1803.14	1.88671
1806.15	0.935675
1809.15	0.580391
1812.15	0.183437
1815.16	0.269279
1818.15	0.863804
1821.16	1.24689
1824.15	1.59305
1827.15	1.06408
1830.15	1.50082
1833.14	1.14751
1836.14	1.47138
1839.13	1.23403
1842.12	1.44466
1845.11	1.12847
1848.1	1.63864
1851.09	2.78558
1854.08	3.10238
1857.06	3.57308
1860.05	4.27156
1863.03	4.34224
1866.01	4.25055
1869	4.56886
1871.98	5.74434
1874.96	5.13552
1877.93	4.49119
1880.91	4.72567
1882.47	5.29981
1885.46	5.60316
1888.44	5.78406
1891.43	5.9716
1894.42	5.13597
1897.4	4.26704
1900.39	4.27197
1903.37	4.73689
1906.35	5.72515
1909.33	6.37778
1912.31	5.93797
1915.29	6.18658
1918.26	5.76665
1921.24	5.40768
1924.21	5.00299
1927.19	5.61334
1930.16	5.34907
1933.13	4.95011
1936.1	5.19183
1939.07	5.08632
1942.04	5.52118
1945	4.51537
1947.97	3.56913
1950.93	2.84248
1953.9	3.76381
1956.86	3.73782
1959.82	3.37871
1962.78	4.03926
1965.74	4.12121
1968.7	5.03862
1971.65	6.00391
1974.61	6.9108
1977.57	7.8103
1980.52	8.30175
1983.47	8.33135
1986.42	8.04878
1989.37	7.74971
1992.32	7.51938
1995.27	7.15268
1998.22	8.02918
2001.17	7.18524
2004.11	7.79095
2007.05	7.28276
2010	6.03434
2012.94	4.56677
2015.88	4.6387
2018.82	4.17372
2021.76	3.32692
2024.7	2.83476
2027.63	3.17173
2030.57	2.6
2033.5	2.8113
2036.44	3.38161
2039.37	3.67743
2042.3	3.79594
2045.23	4.57791
2048.16	6.03199
2051.08	6.71609
2054.01	7.86817
2056.94	9.01951
2059.86	9.40198
2062.79	10.0531
2065.71	10.1813
2068.63	10.796
2071.55	10.9139
2074.47	11.9369
2077.39	13.5524
2080.31	13.7999
2083.22	14.5748
2086.13	15.2657
2089.05	16.912
2091.96	17.0332
2094.87	17.4021
2097.78	18.9366
2100.69	20.6478
2103.6	21.524
2106.51	22.9172
2109.42	25.3036
2112.32	27.4527
2115.23	30.8635
2118.13	33.185
2121.03	34.7276
2123.93	36.1186
2126.83	38.3444
2129.73	40.5164
2132.63	42.2784
2135.53	45.207
2138.42	47.1806
2141.32	50.1989
2144.21	53.7165
2147.1	56.2361
2150	58.4951
2152.89	60.3
2155.78	61.8535
2158.66	64.0002
2161.55	65.7283
2164.44	66.8353
2167.32	68.7367
2170.21	69.1042
2173.09	68.8636
2175.97	68.5959
2178.85	67.6238
2181.73	66.9346
2184.61	65.5334
2187.49	62.832
2190.37	61.4815
2193.24	59.7133
2196.12	57.3931
2198.99	55.4178
2201.87	53.1917
2204.74	50.8681
2207.61	50.2285
2210.48	47.4962
2213.35	45.6948
2216.21	42.839
2219.08	40.7752
2221.95	38.2708
2224.81	36.2664
2227.67	34.6326
2230.54	32.7309
2233.4	30.6476
2236.26	29.6601
2239.11	27.5587
2241.97	25.4056
2244.83	23.0616
2247.69	21.9158
2250.54	20.3791
2253.4	19.6447
2256.25	18.2437
2259.1	17.1742
2261.95	16.5721
2264.8	14.9057
2267.65	14.9244
2270.5	14.8779
2273.34	14.7278
2276.19	13.9719
2279.03	13.8971
2281.88	12.237
2284.72	11.1354
2287.56	9.84064
2290.4	8.58044
2293.24	6.4293
2296.08	6.72599
2298.92	6.49192
2301.76	6.37195
2304.59	6.47501
2307.43	6.95912
2310.26	7.04444
2313.09	8.33964
2315.92	8.42055
2318.75	8.75292
2321.58	8.78073
2324.41	8.99853
2327.24	9.37644
2330.06	9.81311
2332.89	10.5444
2335.71	10.4371
2338.54	9.78368
2341.36	9.5767
2344.18	8.43223
2347	7.1675
2349.82	4.89062
2352.64	3.3008
2355.45	3.05038
2358.27	2.75899
2361.08	1.72872
2363.9	1.47965
2366.71	2.03913
2369.52	2.8694
2372.33	3.15692
2375.14	4.23187
2377.95	5.24795
2380.76	6.97288
2383.57	6.45261
2386.37	7.17341
2389.18	6.5089
2391.98	7.35099
2394.79	7.64029
2397.59	6.98235
2400.39	7.27165
2403.19	6.86667
2405.99	6.52364
2408.78	6.56841
2411.58	6.26276
2414.38	5.78108
2417.17	4.94533
2419.97	5.09181
2422.76	5.77329
2425.55	5.80059
2428.34	6.10335
2431.13	6.27829
2433.92	6.97962
2436.71	8.04831
2439.49	8.55616
2442.28	8.17689
2445.06	8.52716
2447.85	8.18828
2450.63	7.54392
2453.41	7.67579
2456.19	8.22062
2458.97	8.78593
2461.75	8.68072
2464.53	8.30025
2467.31	7.87682
2470.08	7.93452
2472.86	7.6547
2475.63	6.95994
2478.4	5.92693
2481.17	4.39332
2483.94	3.69517
2486.72	2.33225
2489.48	0.905106
2492.25	0.299925
2495.02	0.553624
2497.79	0.951591
2500.55	0.33661
2503.31	0.995549
2506.08	0.498322
2508.84	0.166242
2511.6	-0.458203
2514.36	-0.326099
2517.12	0.0246863
2519.88	1.76863
2522.63	2.6029
2525.39	4.44094
2528.14	5.15267
2530.9	6.14275
2533.65	6.28113
2536.4	6.27376
2539.15	7.05986
2541.9	6.73647
2544.65	7.26537
2547.4	6.4333
2550.15	5.80569
2552.89	5.04131
2555.64	4.11645
2558.38	5.33479
2561.12	4.9607
2563.87	4.81369
2566.61	3.94974
2569.35	3.93973
2572.09	4.17652
2574.83	3.37541
2577.56	2.6765
2580.3	1.54588
2583.04	1.37826
2585.77	1.68015
2588.5	2.14305
2591.23	2.07878
2593.97	1.77984
2596.7	2.18129
2599.43	1.97986
2602.15	2.60237
2604.88	3.13337
2607.61	3.70302
2610.33	3.79082
2613.06	3.39513
2615.78	3.6192
2618.51	3.65071
2621.23	3.86676
2623.95	4.21668
2626.67	3.64847
2629.39	3.55708
2632.1	3.40409
2634.82	3.31934
2637.54	3.43107
2640.25	2.75927
2642.97	1.09826
2645.68	1.45387
2648.39	1.02945
2651.1	1.51452
2653.81	1.8551
2656.52	2.42393
2659.23	2.29477
2661.94	1.88038
2664.64	2.83809
2667.35	3.14777
2670.05	3.05291
2672.76	3.55215
2675.46	4.13421
2678.16	4.06446
2680.86	4.29623
2683.56	4.5201
2686.26	4.92605
2688.96	4.77623
2691.65	5.01878
2694.35	5.16926
2697.04	5.10176
2699.74	4.60106
2702.43	4.1568
2705.12	4.22163
2707.81	3.34214
2710.5	3.78157
2713.19	4.45905
2715.88	3.61111
2718.57	4.01795
2721.25	3.0129
2723.94	1.92577
2726.62	1.95499
2729.3	2.05235
2731.99	2.42165
2734.67	2.70007
2737.35	2.95554
2740.03	3.08984
2742.71	2.72991
2745.38	3.25133
2748.06	3.382
2750.74	4.07204
2753.41	3.26531
2756.09	3.01472
2758.76	3.10406
2761.43	3.06448
2764.1	3.99684
2766.77	3.4284
2769.44	3.51023
2772.11	3.06856
2774.77	2.44095
2777.44	2.02993
2780.11	1.70285
2782.77	1.56293
2785.43	0.666538
2788.1	-0.141786
2790.76	0.254732
2793.42	0.682806
2796.08	1.06621
2798.74	1.00626
2801.4	1.21662
2804.05	1.26974
2806.71	2.2039
2809.36	2.57989
2812.02	1.61933
2814.67	2.06851
2817.32	2.8588
2819.97	3.26772
2822.62	4.72693
2825.27	7.44114
2827.92	10.0405
2830.57	11.6153
2833.22	13.888
2835.86	15.8279
2838.51	18.7704
2841.15	22.3381
2843.79	26.7813
2846.43	31.3209
2849.08	35.7807
2851.72	40.2118
2854.36	44.9953
2856.99	50.5848
2859.63	55.7748
2862.27	61.1158
2864.9	66.6071
2867.54	71.1895
2870.17	75.7595
2872.8	79.123
2875.43	81.5772
2878.07	84.0318
2880.7	87.0986
2883.32	90.482
2885.95	94.0743
2888.58	98.1474
2891.21	101.882
2893.83	105.828
2896.46	110.161
2899.08	115.055
2901.7	121.037
2904.32	127.395
2906.94	135.203
2909.56	143.315
2912.18	151.339
2914.8	158.429
2917.42	165.542
2920.03	172.467
2922.65	178.789
2925.26	183.134
2927.88	186.372
2930.49	187.411
2933.1	187.358
2935.71	185.366
2938.32	182.316
2940.93	177.894
2943.54	172.225
2946.14	167.005
2948.75	161.205
2951.35	154.616
2953.96	148.376
2956.56	140.853
2959.16	133.481
2961.77	125.811
2964.37	118.28
2966.96	111.27
2969.56	105.051
2972.16	98.9595
2974.76	92.1913
2977.35	85.6768
2979.95	79.1947
2982.54	73.8931
2985.14	67.6612
2987.73	61.6641
2990.32	54.6925
2992.91	48.5007
2995.5	42.2915
2998.09	35.5639
3000.68	30.1698
3003.26	25.1101
3005.85	20.0839
3008.43	16.1877
3011.02	13.1747
3013.6	11.3823
3016.19	8.00087
3018.77	5.85185
3021.35	4.29444
3023.93	3.0622
3026.5	2.32849
3029.08	2.09854
3031.66	1.8564
3034.24	1.63006
3036.81	1.80131
3039.39	2.43169
3041.96	4.3603
3044.53	5.80844
3047.1	7.128
3049.67	7.78797
3052.24	8.40408
3054.81	8.85956
3057.38	8.84078
3059.95	7.73323
3062.52	6.8616
3065.08	6.42999
3067.65	6.40832
3070.21	6.04817
3072.77	5.19403
3075.33	4.26703
3077.89	3.94942
3080.45	3.15501
3083.01	2.94981
3085.57	2.45629
3088.13	1.1801
3090.68	1.96594
3093.24	2.1969
3095.79	2.50629
3098.35	3.25024
3100.9	3.81229
3103.45	4.98282
3106	5.59396
3108.55	6.38036
3111.1	7.20034
3113.65	7.88725
3116.2	9.13966
3118.75	9.70169
3121.29	10.2176
3123.84	11.1072
3126.38	12.2279
3128.92	14.185
3131.47	15.4377
3134.01	17.0394
3136.55	17.7741
3139.09	19.4268
3141.63	21.276
3144.17	23.6697
3146.7	26.7569
3149.24	30.7618