File: data/Raman/poly_smoothed/Mb_40_y_13_1x_45s_532 nm_x100_100%_600 gr_mm_01.txt
#Acq. time (s)=	45
#Accumulations=	2
#Range (cm-¹)=	200...3150
#Windows=	2
#Auto scanning=	Off
#Autofocus=	Off
#Macrospot=	Off
#AutoExposure=	Off
#Spike filter=	Multiple accum.
#Delay time (s)=	0
#Binning=	1
#Readout mode=	Signal
#DeNoise=	Off
#ICS correction=	On
#Dark correction=	Off
#Inst. Process=	Off
#Detector Gain=	Best Dynamic Range
#Detector ADC=	20 kHz
#Detector temperature (°C)=	-69.85
#Instrument=	LabRAM HR Evol
#Detector=	Synapse
#Objective=	x100
#Grating=	600 gr/mm
#ND Filter=	100%
#Laser (nm)=	532
#Hole=	100.021
#Range=	Auto
#Laser Pol.=	No
#Raman. Pol.=	No
#Laser Pol. (°)=	-0.0007625
#Raman Pol. (°)=	89.9995
#Collection=	Microscope
#StageXY=	Marzhauser
#StageZ=	Marzhauser
#X (µm)=	-1068.4
#Y (µm)=	686.6
#Z (µm)=	584.55
#Full time(mm:ss)=	3:19
#Project=
#Sample=
#Site=
#Title=	Mb_40_y_13_2x_45s_532 nm_x100_100%_600 gr_mm
#Remark=
#Date=	19.07.2022 09:57
#Acquired=	19.07.2022 09:57:07
#Base:Fit=	10.08.2022 10:52:48
#Base:Sub=	10.08.2022 10:52:53
#Filter:Polynom=	16.08.2022 10:09:04
#AxisType[0]=Intens
#AxisUnit[0]=Cnt
#AxisType[1]=Spectr
#AxisUnit[1]=1/cm
200.423	9.35762
204.052	11.3752
207.682	12.9281
211.308	13.7123
214.935	13.0499
218.558	12.0995
222.18	10.9173
225.802	9.19431
229.421	8.24004
233.039	6.71518
236.657	5.59023
240.272	6.2854
243.885	6.30226
247.497	5.82633
251.11	3.90629
254.719	3.80943
258.327	5.00967
261.933	6.83729
265.538	8.58879
269.141	10.2967
272.744	9.81066
276.344	9.44512
279.944	10.4493
283.542	11.6313
287.138	11.8396
290.733	11.446
294.327	11.5195
297.919	11.1085
301.508	9.5341
305.098	9.19274
308.686	8.39605
312.273	8.55792
315.858	9.19318
319.44	10.1899
323.022	9.40726
326.604	10.2994
330.181	11.0038
333.76	10.7999
337.335	10.874
340.91	10.9958
344.483	11.2425
348.055	11.4339
351.625	12.9289
355.195	13.1311
358.762	11.3432
362.329	10.2373
365.893	9.68032
369.455	9.20882
373.017	6.88278
376.578	5.09182
380.137	4.74719
383.694	3.48553
387.249	3.48914
390.806	4.11301
394.359	5.29389
397.91	5.11599
401.46	7.50875
405.009	6.83662
408.557	7.05341
412.103	7.30092
415.647	6.72409
419.191	7.70727
422.733	7.75447
426.273	7.30346
429.812	7.66336
433.35	8.42829
436.885	8.89679
440.42	9.07733
443.954	7.02635
447.486	7.78458
451.015	7.86574
454.545	7.03793
458.073	5.56428
461.598	5.53929
465.124	6.12041
468.648	7.26218
472.169	7.03519
475.69	7.72975
479.208	9.29722
482.727	10.3765
486.243	11.401
489.759	11.9971
493.272	13.6836
496.783	15.1885
500.295	16.4207
503.804	18.2919
507.311	18.5987
510.819	19.5825
514.324	21.1147
517.827	23.2364
521.329	23.6989
524.83	24.116
528.329	24.1105
531.829	25.2846
535.326	26.1372
538.821	23.9987
542.315	21.2115
545.808	19.4149
549.299	17.947
552.789	16.846
556.278	14.4647
559.763	12.2597
563.249	11.2964
566.733	11.463
570.217	10.5829
573.699	8.02776
577.177	8.95533
580.656	8.65588
584.134	8.38246
587.609	7.42256
591.084	6.93835
594.558	7.51722
598.029	8.95888
601.5	9.67752
604.968	9.3996
608.437	10.6149
611.902	11.4077
615.368	11.7888
618.831	12.4584
622.294	11.0429
625.755	9.33775
629.213	9.87486
632.673	9.86575
636.129	9.90874
639.584	10.3376
643.037	9.83618
646.491	10.9902
649.942	11.7545
653.392	13.0039
656.84	13.4051
660.287	14.7033
663.732	16.0284
667.177	17.1956
670.62	18.159
674.061	20.9127
677.502	23.9018
680.941	26.5384
684.379	26.3626
687.815	27.9625
691.248	30.1904
694.682	31.4763
698.115	33.0137
701.546	34.8177
704.974	35.6296
708.402	36.7556
711.83	38.9549
715.254	41.2428
718.679	43.0963
722.102	43.2969
725.522	44.5603
728.943	44.8852
732.361	46.531
735.779	49.8627
739.194	49.651
742.608	51.7253
746.022	52.5903
749.433	54.7911
752.843	56.8378
756.254	58.6448
759.661	61.2318
763.067	61.5231
766.471	62.5853
769.877	64.4244
773.279	67.2513
776.68	69.401
780.079	72.008
783.478	74.2542
786.875	76.1326
790.27	77.8857
793.665	79.0835
797.058	80.2934
800.45	80.3136
803.84	79.9049
807.23	79.7836
810.616	80.5255
814.002	81.2648
817.388	79.6996
820.772	78.2888
824.153	75.9081
827.535	74.657
830.915	73.864
834.292	71.9422
837.67	69.3963
841.047	66.8937
844.42	64.5148
847.794	63.7678
851.165	62.9812
854.534	63.3668
857.905	63.1459
861.272	61.4195
864.639	58.8845
868.004	58.2864
871.367	57.1662
874.731	56.1323
878.092	56.4881
881.451	55.9031
884.809	55.2162
888.166	56.0569
891.522	55.5546
894.878	55.6292
898.231	54.7616
901.583	54.2808
904.934	54.2884
908.283	54.3353
911.631	53.6706
914.976	53.3201
918.322	52.8212
921.666	51.9799
925.009	52.0823
928.351	52.6151
931.692	50.5788
935.029	50.5734
938.367	49.5252
941.704	48.5994
945.038	46.5234
948.372	45.2946
951.705	44.2966
955.035	42.9853
958.366	40.6834
961.693	39.4021
965.021	37.8273
968.346	38.157
971.67	38.2218
974.995	38.8644
978.316	38.8922
981.638	38.2897
984.957	37.5349
988.274	37.0108
991.59	35.055
994.907	33.7361
998.221	31.4504
1001.53	30.22
1004.85	29.1268
1008.16	30.3413
1011.46	36.2381
1014.77	43.9799
1018.08	53.3861
1021.38	64.7296
1024.69	74.0633
1027.99	81.7701
1031.29	87.2574
1034.59	93.8776
1037.89	96.6534
1041.19	98.3696
1044.48	100.187
1047.78	100.427
1051.07	99.0908
1054.36	95.3
1057.66	89.3884
1060.94	83.8812
1064.23	75.9363
1067.52	66.7886
1070.81	55.1785
1074.09	44.0323
1077.38	33.2669
1080.66	25.3847
1083.94	21.1286
1087.22	18.7584
1090.5	21.1569
1093.77	22.8616
1097.05	25.2631
1100.32	26.6344
1103.6	28.295
1106.87	27.783
1110.14	25.8581
1113.41	27.0754
1116.67	25.984
1119.94	24.4716
1123.21	23.0972
1126.47	20.1616
1129.73	20.3965
1133	18.1315
1136.26	17.0281
1139.52	14.9325
1142.77	14.6241
1146.03	12.739
1149.29	12.3838
1152.54	10.3588
1155.79	10.5314
1159.04	11.0825
1162.3	9.72257
1165.55	9.22263
1168.79	7.22199
1172.04	7.4152
1175.28	8.42558
1178.53	6.77448
1181.77	6.54942
1185.01	6.33727
1188.25	6.72824
1191.49	8.54272
1194.73	9.4251
1197.97	9.9417
1201.2	11.165
1204.44	13.388
1207.67	15.2508
1210.9	17.1809
1214.13	18.5905
1217.36	22.1679
1220.59	23.919
1223.82	27.5725
1227.04	29.4009
1230.26	31.2558
1233.49	32.7261
1236.71	33.1567
1239.93	34.0765
1243.15	33.8607
1246.37	35.3129
1249.58	37.085
1252.8	37.7507
1256.01	38.0662
1259.23	38.3883
1262.44	41.6226
1265.65	44.7926
1268.86	45.3791
1272.07	47.7855
1275.27	49.1517
1278.48	51.2763
1281.68	54.1718
1284.89	55.2553
1288.09	56.914
1291.29	57.5985
1294.49	59.0729
1297.69	60.9511
1300.88	60.9385
1304.08	62.8109
1307.27	62.8617
1310.47	62.2721
1313.66	62.7547
1316.85	61.6724
1320.04	59.5757
1323.23	59.0275
1326.41	58.4919
1329.6	55.7604
1332.78	54.9152
1335.97	53.9937
1339.15	52.7234
1342.33	51.8193
1345.51	49.967
1348.69	48.5855
1351.87	46.4311
1355.04	44.4964
1358.22	43.4592
1361.39	41.9082
1364.57	40.623
1367.74	38.4179
1370.91	37.0262
1374.07	36.5429
1377.24	35.9755
1380.41	35.0333
1383.57	34.5716
1386.74	34.1672
1389.9	35.2131
1393.06	34.1068
1396.22	33.1753
1399.38	33.9157
1402.54	32.7516
1405.7	33.3356
1408.85	35.7132
1412.01	38.7784
1415.16	40.9058
1418.31	44.0351
1421.46	47.8913
1424.61	50.9598
1427.76	53.4141
1430.91	56.5485
1434.05	58.2595
1437.2	61.3429
1440.34	63.3445
1443.49	64.1723
1446.63	64.9613
1449.77	66.0611
1452.91	64.629
1456.04	63.4092
1459.18	61.2404
1462.31	58.2312
1465.45	55.5343
1468.58	52.6117
1471.71	48.0708
1474.84	44.739
1477.97	41.0176
1481.1	37.4297
1484.23	35.4271
1487.35	33.287
1490.48	31.1038
1493.6	29.3527
1496.72	26.8707
1499.84	24.4382
1502.96	21.539
1506.08	21.3505
1509.2	20.1105
1512.31	19.4433
1515.43	19.21
1518.54	19.3536
1521.66	20.6477
1524.77	21.2713
1527.88	20.9135
1530.99	21.4386
1534.09	22.0845
1537.2	24.1646
1540.31	26.6546
1543.41	29.2448
1546.51	30.4575
1549.62	33.574
1552.72	35.3611
1555.82	38.4564
1558.91	38.8109
1562.01	39.9118
1565.11	40.0879
1568.2	40.0076
1571.3	40.874
1574.39	40.8944
1577.48	41.0848
1580.57	43.0009
1583.66	43.5598
1586.75	44.6217
1589.83	44.7435
1592.92	45.2109
1596	45.873
1599.09	44.5356
1602.17	44.1674
1605.25	44.3693
1608.33	43.9307
1611.41	43.8038
1614.48	45.1935
1617.56	44.3641
1620.64	43.4032
1623.71	44.3178
1626.78	44.6454
1629.86	44.3299
1632.92	44.2866
1635.99	43.2924
1639.06	44.1514
1642.13	45.2807
1645.19	46.1097
1648.26	46.8084
1651.32	47.6815
1654.38	47.4264
1657.45	48.1246
1660.51	47.8927
1663.57	47.2277
1666.62	46.3481
1669.68	43.6715
1672.73	40.6723
1675.79	37.526
1678.84	35.6462
1681.89	33.0358
1684.94	29.1256
1687.99	27.39
1691.04	24.7055
1694.09	22.0897
1697.14	19.4658
1700.18	17.6595
1703.22	15.6604
1706.27	14.0378
1709.31	12.7817
1712.35	11.4048
1715.39	10.3387
1718.43	10.4358
1721.46	8.78069
1724.5	9.18629
1727.53	8.66581
1730.57	8.55235
1733.6	9.09701
1736.63	9.14064
1739.66	9.24948
1742.69	8.38828
1745.72	7.52472
1748.74	6.85534
1751.77	7.07607
1754.8	7.01286
1757.82	5.94609
1760.84	4.8575
1763.86	5.35096
1766.88	4.76001
1769.9	4.66748
1772.92	4.60827
1775.93	4.57152
1778.95	3.77105
1781.96	3.29168
1784.98	2.29006
1787.99	2.00076
1791	1.96595
1794.01	2.49633
1797.02	2.33654
1800.03	3.04946
1803.03	2.86409
1806.04	3.36897
1809.04	3.49896
1812.04	3.34598
1815.05	3.04589
1818.05	2.34771
1821.05	3.02882
1824.05	2.32968
1827.04	1.99587
1830.04	1.41182
1833.03	1.19104
1836.03	1.94049
1839.02	2.84549
1842.01	2.24965
1845	1.66487
1847.99	1.75876
1850.98	1.61915
1853.97	1.68022
1856.95	1.44764
1859.94	1.9799
1862.92	1.20219
1865.91	2.42515
1868.89	2.80077
1871.87	3.0925
1874.85	2.93861
1877.83	3.2248
1880.8	3.61081
1882.56	3.47064
1885.54	3.73179
1888.53	3.7765
1891.52	4.9456
1894.5	5.44393
1897.49	4.68401
1900.47	5.79227
1903.45	6.36127
1906.43	7.90313
1909.41	8.68661
1912.39	8.19949
1915.37	8.34486
1918.35	8.40225
1921.32	8.36736
1924.3	8.38868
1927.27	6.70648
1930.24	6.32529
1933.21	5.54255
1936.18	4.99424
1939.15	4.49789
1942.12	4.35172
1945.09	3.46258
1948.05	3.40398
1951.02	2.32309
1953.98	2.15486
1956.94	1.4475
1959.91	1.19207
1962.87	1.14833
1965.82	0.471468
1968.78	0.481406
1971.74	0.638717
1974.7	0.719077
1977.65	1.85896
1980.6	3.69516
1983.56	3.09786
1986.51	3.45497
1989.46	4.46981
1992.41	4.02896
1995.36	4.44887
1998.3	4.85211
2001.25	4.8157
2004.2	4.38843
2007.14	4.86035
2010.08	4.18147
2013.02	3.64813
2015.97	4.15927
2018.9	3.77311
2021.84	4.06494
2024.78	3.3295
2027.72	2.95901
2030.65	3.29575
2033.59	3.17908
2036.52	2.29784
2039.45	3.63978
2042.38	3.08376
2045.31	4.31457
2048.24	5.20394
2051.17	7.5039
2054.1	8.21835
2057.02	9.53195
2059.95	10.4873
2062.87	11.0984
2065.79	11.3597
2068.71	12.6553
2071.63	13.9173
2074.55	13.9717
2077.47	14.5242
2080.39	15.741
2083.3	16.0168
2086.22	17.564
2089.13	19.1925
2092.05	20.6082
2094.96	21.2538
2097.87	21.6664
2100.78	23.5061
2103.69	24.6353
2106.59	25.7444
2109.5	26.1486
2112.41	27.795
2115.31	27.9982
2118.21	30.1229
2121.12	31.5593
2124.02	32.9742
2126.92	34.6762
2129.82	37.4018
2132.71	37.9825
2135.61	40.1748
2138.51	42.0962
2141.4	44.6157
2144.29	46.5295
2147.19	48.2361
2150.08	50.0071
2152.97	51.7319
2155.86	53.0212
2158.75	54.7434
2161.64	56.9358
2164.52	57.1656
2167.41	58.142
2170.29	58.3363
2173.17	58.3585
2176.06	58.3934
2178.94	57.0634
2181.82	56.9143
2184.7	55.725
2187.57	55.6645
2190.45	54.7004
2193.33	52.5188
2196.2	51.5204
2199.08	49.5782
2201.95	47.2329
2204.82	44.8918
2207.69	43.0572
2210.56	40.8629
2213.43	39.0115
2216.3	36.3362
2219.16	33.5998
2222.03	30.9492
2224.89	29.467
2227.75	27.3101
2230.62	25.9042
2233.48	23.8835
2236.34	22.7971
2239.2	21.0549
2242.06	19.2942
2244.91	18.8185
2247.77	17.7533
2250.62	15.3418
2253.48	14.58
2256.33	13.9669
2259.18	13.3398
2262.03	12.3376
2264.88	11.4126
2267.73	11.5852
2270.58	10.6521
2273.43	10.4648
2276.27	10.6701
2279.12	10.4867
2281.96	10.4305
2284.8	10.7372
2287.64	9.35349
2290.49	9.38296
2293.32	8.58301
2296.16	9.46778
2299	10.3205
2301.84	11.0543
2304.67	11.9625
2307.51	12.1275
2310.34	11.8993
2313.17	12.0064
2316	11.5363
2318.83	11.9045
2321.66	12.6736
2324.49	11.7338
2327.32	11.6086
2330.15	11.2955
2332.97	11.0762
2335.79	10.8664
2338.62	8.97369
2341.44	7.69688
2344.26	6.87404
2347.08	6.06816
2349.9	5.97257
2352.72	5.28572
2355.53	4.57776
2358.35	4.03712
2361.17	4.01293
2363.98	3.91231
2366.79	5.02224
2369.6	4.65212
2372.42	4.85375
2375.22	5.23398
2378.03	4.81849
2380.84	4.37048
2383.65	4.71107
2386.45	5.36537
2389.26	5.28381
2392.06	4.69649
2394.87	4.77122
2397.67	4.99696
2400.47	4.53902
2403.27	3.98925
2406.07	3.12686
2408.86	2.26583
2411.66	1.86208
2414.46	1.54293
2417.25	2.33576
2420.05	2.66679
2422.84	3.5351
2425.63	2.73279
2428.42	3.06212
2431.21	1.98818
2434	2.3156
2436.79	2.71468
2439.57	3.53498
2442.36	3.6885
2445.14	3.15469
2447.93	3.0826
2450.71	3.11217
2453.49	3.11398
2456.27	2.61383
2459.05	3.00963
2461.83	4.18487
2464.61	4.37323
2467.39	3.31918
2470.16	3.07217
2472.94	2.58728
2475.71	1.68249
2478.48	1.79323
2481.25	1.79377
2484.02	1.6934
2486.8	1.64417
2489.56	1.42811
2492.33	0.449714
2495.1	0.392681
2497.86	0.443336
2500.63	-0.00427588
2503.39	0.938437
2506.16	1.72151
2508.92	1.85544
2511.68	1.61442
2514.44	2.75282
2517.2	3.13734
2519.95	3.34359
2522.71	3.99998
2525.47	5.45209
2528.22	6.4365
2530.98	6.4732
2533.73	6.79102
2536.48	6.94954
2539.23	7.34897
2541.98	6.55006
2544.73	6.98597
2547.48	7.11418
2550.23	6.37727
2552.97	5.57099
2555.72	4.71396
2558.46	3.87009
2561.2	2.72713
2563.95	2.87676
2566.69	2.41701
2569.43	2.10742
2572.17	2.33458
2574.91	1.84306
2577.64	1.74446
2580.38	2.17219
2583.11	1.6312
2585.85	1.82304
2588.58	1.55848
2591.31	1.6547
2594.04	2.84183
2596.78	2.76832
2599.51	3.02628
2602.23	3.06622
2604.96	3.40836
2607.69	3.30894
2610.41	3.05102
2613.14	3.35916
2615.86	3.04115
2618.58	2.76707
2621.3	3.13313
2624.03	3.79036
2626.75	4.51268
2629.46	4.58524
2632.18	4.57065
2634.9	3.97929
2637.61	3.54453
2640.33	3.03343
2643.04	2.79086
2645.76	2.80788
2648.47	2.72228
2651.18	3.06603
2653.89	3.80529
2656.6	4.45251
2659.31	4.4969
2662.01	4.59917
2664.72	5.18731
2667.43	5.34694
2670.13	5.42348
2672.83	4.62549
2675.53	4.39057
2678.24	3.76855
2680.94	3.78886
2683.64	5.26347
2686.34	5.73243
2689.03	6.80081
2691.73	7.1015
2694.43	6.60494
2697.12	6.29088
2699.81	5.7962
2702.51	5.62735
2705.2	6.11637
2707.89	6.16983
2710.58	6.67666
2713.27	7.24168
2715.96	7.41351
2718.64	8.34766
2721.33	8.56254
2724.01	8.23667
2726.7	8.22637
2729.38	8.5526
2732.06	8.4942
2734.75	7.42016
2737.43	6.82339
2740.11	6.16674
2742.78	5.67955
2745.46	5.99884
2748.14	6.63136
2750.81	5.67525
2753.49	4.97246
2756.16	4.20845
2758.84	3.14091
2761.51	2.36856
2764.18	2.78943
2766.85	2.36416
2769.52	2.61896
2772.19	2.81699
2774.85	1.80872
2777.52	1.63454
2780.18	1.93161
2782.85	2.20138
2785.51	1.83239
2788.17	2.02709
2790.84	2.45807
2793.5	2.70332
2796.16	3.26653
2798.81	3.14642
2801.47	3.72915
2804.13	3.98177
2806.79	3.8402
2809.44	3.10078
2812.09	2.69721
2814.75	3.20342
2817.4	2.72935
2820.05	3.80004
2822.7	5.57674
2825.35	7.49326
2828	10.4605
2830.65	13.2326
2833.29	16.1809
2835.94	19.6042
2838.58	22.4053
2841.23	26.3514
2843.87	30.222
2846.51	33.9429
2849.15	38.4662
2851.79	43.2396
2854.43	49.0409
2857.07	53.471
2859.71	57.6044
2862.34	61.2501
2864.98	64.8589
2867.61	67.5243
2870.25	69.7674
2872.88	71.0346
2875.51	72.6615
2878.14	75.5098
2880.77	78.0409
2883.4	79.6009
2886.03	81.2703
2888.65	82.9785
2891.28	85.0811
2893.91	86.4779
2896.53	88.7825
2899.15	91.1892
2901.78	93.93
2904.4	96.1747
2907.02	99.7582
2909.64	104.238
2912.26	108.668
2914.87	114.17
2917.49	118.677
2920.11	121.551
2922.72	124.811
2925.34	126.737
2927.95	129.117
2930.56	130.15
2933.17	130.528
2935.78	129.774
2938.39	129.178
2941	126.883
2943.61	124.907
2946.22	121.539
2948.82	116.266
2951.43	111.868
2954.03	107.082
2956.64	101.932
2959.24	96.6731
2961.84	91.0881
2964.44	85.8535
2967.04	81.5243
2969.64	77.2492
2972.24	73.6722
2974.83	69.504
2977.43	64.8246
2980.02	60.113
2982.62	55.5215
2985.21	50.3018
2987.8	45.4463
2990.4	41.411
2992.99	37.2469
2995.57	32.9934
2998.16	29.2249
3000.75	26.1479
3003.34	22.5381
3005.92	19.0068
3008.51	16.4517
3011.09	13.5998
3013.68	11.2093
3016.26	9.12597
3018.84	6.73242
3021.42	5.09436
3024	3.07213
3026.58	2.6257
3029.16	2.63744
3031.73	2.33367
3034.31	1.48305
3036.89	1.95706
3039.46	1.13093
3042.03	1.65294
3044.61	1.9997
3047.18	2.91025
3049.75	2.45666
3052.32	3.01974
3054.89	2.83383
3057.45	2.93366
3060.02	3.18516
3062.59	3.7019
3065.15	3.56908
3067.72	3.60271
3070.28	3.34379
3072.84	3.46478
3075.41	2.64988
3077.97	2.12082
3080.53	1.8611
3083.09	1.26267
3085.64	0.689646
3088.2	0.689422
3090.76	0.184637
3093.31	0.363439
3095.87	0.318121
3098.42	0.126135
3100.97	0.507662
3103.53	0.465439
3106.08	0.336135
3108.63	0.506338
3111.18	1.09462
3113.73	1.08483
3116.27	1.75338
3118.82	1.8892
3121.37	2.70399
3123.91	2.92138
3126.45	3.45161
3129	3.96266
3131.54	4.55874
3134.08	4.7923
3136.62	5.27527
3139.16	6.04711
3141.7	6.48814
3144.24	6.58817
3146.78	6.85397
3149.31	6.07019