File: data/Raman/poly_smoothed/Mb_40_y_50_1x_45s_532 nm_x100_100%_600 gr_mm_01.txt
#Acq. time (s)=	45
#Accumulations=	2
#Range (cm-¹)=	200...3150
#Windows=	2
#Auto scanning=	Off
#Autofocus=	Off
#Macrospot=	Off
#AutoExposure=	Off
#Spike filter=	Multiple accum.
#Delay time (s)=	0
#Binning=	1
#Readout mode=	Signal
#DeNoise=	Off
#ICS correction=	On
#Dark correction=	Off
#Inst. Process=	Off
#Detector Gain=	Best Dynamic Range
#Detector ADC=	20 kHz
#Detector temperature (°C)=	-69.85
#Instrument=	LabRAM HR Evol
#Detector=	Synapse
#Objective=	x100
#Grating=	600 gr/mm
#ND Filter=	100%
#Laser (nm)=	532
#Hole=	100.021
#Range=	Auto
#Laser Pol.=	No
#Raman. Pol.=	No
#Laser Pol. (°)=	-0.0007625
#Raman Pol. (°)=	89.9995
#Collection=	Microscope
#StageXY=	Marzhauser
#StageZ=	Marzhauser
#X (µm)=	-1141.3
#Y (µm)=	677.4
#Z (µm)=	584.75
#Full time(mm:ss)=	3:18
#Project=
#Sample=
#Site=
#Title=	Mb_40_y_50_2x_45s_532 nm_x100_100%_600 gr_mm
#Remark=
#Date=	19.07.2022 13:48
#Acquired=	19.07.2022 13:48:13
#Base:Fit=	10.08.2022 10:52:48
#Base:Sub=	10.08.2022 10:52:53
#Filter:Polynom=	16.08.2022 10:09:04
#AxisType[0]=Intens
#AxisUnit[0]=Cnt
#AxisType[1]=Spectr
#AxisUnit[1]=1/cm
200.423	32.1114
204.052	29.1347
207.682	27.06
211.308	23.8869
214.935	20.2447
218.558	19.1204
222.18	17.3257
225.802	15.6643
229.421	14.0017
233.039	11.3587
236.657	11.1968
240.272	9.90718
243.885	9.12452
247.497	7.56571
251.11	6.81826
254.719	7.52866
258.327	4.95607
261.933	4.57325
265.538	5.18434
269.141	3.5501
272.744	3.16109
276.344	4.21407
279.944	5.72832
283.542	4.36211
287.138	2.78476
290.733	2.12109
294.327	1.79754
297.919	1.40055
301.508	1.79225
305.098	3.0015
308.686	3.65872
312.273	4.42571
315.858	7.25288
319.44	9.14391
323.022	10.4729
326.604	12.5057
330.181	12.7363
333.76	13.9051
337.335	16.0645
340.91	16.1924
344.483	17.3802
348.055	15.7333
351.625	16.5204
355.195	16.7181
358.762	15.6016
362.329	15.4397
365.893	15.3226
369.455	13.3528
373.017	12.3888
376.578	11.5213
380.137	10.9639
383.694	8.70222
387.249	9.14646
390.806	8.22023
394.359	8.00918
397.91	8.09889
401.46	11.2329
405.009	10.9588
408.557	11.9851
412.103	11.8401
415.647	13.2648
419.191	14.1176
422.733	15.4221
426.273	14.4989
429.812	15.1476
433.35	13.6741
436.885	12.9205
440.42	13.8872
443.954	12.2003
447.486	11.9671
451.015	14.036
454.545	14.9576
458.073	14.2491
461.598	14.1024
465.124	14.176
468.648	15.6974
472.169	15.6063
475.69	16.1628
479.208	17.0117
482.727	17.8621
486.243	19.8847
489.759	21.7252
493.272	22.316
496.783	22.9702
500.295	22.3453
503.804	21.6622
507.311	18.5071
510.819	17.6298
514.324	16.0999
517.827	16.5728
521.329	15.7209
524.83	15.5703
528.329	15.5646
531.829	15.2801
535.326	15.0269
538.821	17.9111
542.315	17.5162
545.808	18.1474
549.299	18.3873
552.789	18.4223
556.278	18.0553
559.763	18.3461
563.249	18.6287
566.733	19.6236
570.217	20.5745
573.699	20.5226
577.177	18.5103
580.656	16.763
584.134	13.7341
587.609	10.8144
591.084	9.09963
594.558	8.24271
598.029	7.44632
601.5	6.17146
604.968	5.91415
608.437	4.60052
611.902	2.97572
615.368	2.71487
618.831	2.39478
622.294	3.96988
625.755	4.34279
629.213	4.7262
632.673	4.83395
636.129	4.75579
639.584	6.663
643.037	8.47177
646.491	9.83979
649.942	9.98648
653.392	10.9969
656.84	11.3672
660.287	12.2427
663.732	12.833
667.177	13.2561
670.62	15.2266
674.061	16.9204
677.502	19.6878
680.941	21.6392
684.379	24.8228
687.815	27.5361
691.248	30.8843
694.682	32.0729
698.115	33.3514
701.546	36.9812
704.974	39.698
708.402	42.4185
711.83	45.1384
715.254	46.131
718.679	45.6225
722.102	44.9942
725.522	45.3974
728.943	46.1516
732.361	45.0416
735.779	45.0984
739.194	45.314
742.608	45.2174
746.022	48.0092
749.433	47.539
752.843	49.6563
756.254	52.4298
759.661	53.4236
763.067	56.664
766.471	59.8565
769.877	60.8837
773.279	62.2955
776.68	65.2834
780.079	66.3837
783.478	68.5614
786.875	70.2487
790.27	71.2817
793.665	72.2908
797.058	71.0765
800.45	70.8376
803.84	70.6981
807.23	69.4027
810.616	70.223
814.002	69.6441
817.388	66.8762
820.772	66.8722
824.153	65.373
827.535	66.672
830.915	65.4157
834.292	62.0497
837.67	61.2193
841.047	59.4535
844.42	56.8829
847.794	55.4829
851.165	52.3831
854.534	51.9953
857.905	50.4703
861.272	48.5407
864.639	47.116
868.004	44.3443
871.367	43.3497
874.731	43.197
878.092	44.2903
881.451	43.0925
884.809	43.6934
888.166	42.9397
891.522	43.1102
894.878	43.4818
898.231	43.0392
901.583	43.6858
904.934	43.1635
908.283	43.2494
911.631	43.0063
914.976	42.2067
918.322	41.715
921.666	41.8718
925.009	41.4841
928.351	40.908
931.692	41.2884
935.029	42.1509
938.367	41.0995
941.704	41.2893
945.038	41.3219
948.372	41.0847
951.705	40.771
955.035	41.1157
958.366	40.8982
961.693	41.8461
965.021	42.3863
968.346	43.2665
971.67	42.07
974.995	42.1668
978.316	42.8949
981.638	42.512
984.957	42.4722
988.274	40.8598
991.59	39.4716
994.907	37.1509
998.221	31.4782
1001.53	27.9961
1004.85	26.0477
1008.16	30.5128
1011.46	41.0391
1014.77	58.2029
1018.08	76.8879
1021.38	95.4056
1024.69	113.356
1027.99	130.345
1031.29	142.653
1034.59	153.123
1037.89	161.916
1041.19	168.845
1044.48	171.203
1047.78	171.677
1051.07	167.246
1054.36	161.276
1057.66	153.558
1060.94	140.266
1064.23	124.632
1067.52	105.416
1070.81	84.7231
1074.09	64.2943
1077.38	43.3308
1080.66	26.1573
1083.94	14.5493
1087.22	7.7062
1090.5	7.95053
1093.77	13.3902
1097.05	15.7043
1100.32	18.1701
1103.6	19.7816
1106.87	21.6521
1110.14	22.5071
1113.41	22.309
1116.67	23.062
1119.94	24.8554
1123.21	24.1355
1126.47	23.5909
1129.73	23.447
1133	22.8535
1136.26	22.4606
1139.52	21.0473
1142.77	18.415
1146.03	16.4869
1149.29	14.9555
1152.54	14.5409
1155.79	11.7415
1159.04	9.32916
1162.3	8.3033
1165.55	7.2297
1168.79	6.49697
1172.04	8.22823
1175.28	8.39194
1178.53	9.10405
1181.77	11.1197
1185.01	12.4936
1188.25	13.8776
1191.49	14.7186
1194.73	15.3004
1197.97	16.8863
1201.2	18.6946
1204.44	19.9823
1207.67	23.2208
1210.9	25.8259
1214.13	27.395
1217.36	28.672
1220.59	29.4097
1223.82	30.9346
1227.04	32.4981
1230.26	32.9198
1233.49	33.9033
1236.71	34.9692
1239.93	34.9219
1243.15	38.3242
1246.37	39.9884
1249.58	40.5618
1252.8	42.343
1256.01	44.1801
1259.23	47.1097
1262.44	49.7633
1265.65	52.5617
1268.86	55.9014
1272.07	58.4478
1275.27	61.1579
1278.48	64.584
1281.68	67.5428
1284.89	69.7997
1288.09	71.4197
1291.29	73.0199
1294.49	72.9529
1297.69	73.6497
1300.88	73.5247
1304.08	72.8514
1307.27	71.8536
1310.47	71.6552
1313.66	71.8227
1316.85	70.6019
1320.04	68.8119
1323.23	68.3633
1326.41	65.5807
1329.6	64.5813
1332.78	62.8072
1335.97	62.6773
1339.15	62.7134
1342.33	60.5843
1345.51	59.9087
1348.69	57.844
1351.87	56.9086
1355.04	55.1374
1358.22	53.8179
1361.39	52.3499
1364.57	51.8856
1367.74	49.3505
1370.91	48.0794
1374.07	46.6684
1377.24	45.2828
1380.41	44.3514
1383.57	44.5531
1386.74	46.5039
1389.9	46.7128
1393.06	46.8785
1396.22	48.4988
1399.38	50.838
1402.54	53.4586
1405.7	55.2102
1408.85	59.4029
1412.01	62.2912
1415.16	66.4964
1418.31	71.2154
1421.46	76.3084
1424.61	81.5351
1427.76	87.7795
1430.91	92.1105
1434.05	96.1578
1437.2	100.431
1440.34	103.605
1443.49	105.143
1446.63	105.449
1449.77	105.747
1452.91	104.856
1456.04	103.705
1459.18	103.062
1462.31	98.9837
1465.45	96.5064
1468.58	92.2824
1471.71	88.7971
1474.84	83.704
1477.97	78.7111
1481.1	75.9631
1484.23	72.303
1487.35	66.7108
1490.48	62.6832
1493.6	59.048
1496.72	55.3819
1499.84	51.418
1502.96	47.7724
1506.08	43.3137
1509.2	40.7543
1512.31	38.7411
1515.43	35.7594
1518.54	32.7333
1521.66	30.3302
1524.77	30.3564
1527.88	28.0947
1530.99	29.2423
1534.09	30.1296
1537.2	31.2452
1540.31	31.927
1543.41	33.1786
1546.51	33.2487
1549.62	35.1419
1552.72	38.2093
1555.82	41.028
1558.91	41.9768
1562.01	41.9868
1565.11	43.0267
1568.2	45.3906
1571.3	47.7137
1574.39	49.6952
1577.48	51.8079
1580.57	52.3005
1583.66	54.7444
1586.75	57.1865
1589.83	58.411
1592.92	58.898
1596	58.3064
1599.09	60.3121
1602.17	60.6851
1605.25	61.6472
1608.33	63.5189
1611.41	63.7592
1614.48	63.5738
1617.56	62.1603
1620.64	62.6132
1623.71	62.6421
1626.78	62.9207
1629.86	63.5811
1632.92	63.8107
1635.99	63.4237
1639.06	64.2945
1642.13	66.2687
1645.19	66.4979
1648.26	67.8416
1651.32	67.191
1654.38	67.8483
1657.45	67.4061
1660.51	67.3074
1663.57	65.8971
1666.62	63.0466
1669.68	61.0639
1672.73	60.3866
1675.79	57.4501
1678.84	53.6928
1681.89	50.7603
1684.94	47.4942
1687.99	43.8351
1691.04	39.8293
1694.09	38.3548
1697.14	35.9628
1700.18	33.0964
1703.22	31.1141
1706.27	28.5281
1709.31	26.9804
1712.35	23.8774
1715.39	21.0396
1718.43	19.212
1721.46	16.6503
1724.5	15.6865
1727.53	14.8677
1730.57	14.4929
1733.6	12.5543
1736.63	12.1821
1739.66	11.4839
1742.69	10.6564
1745.72	11.5006
1748.74	10.4477
1751.77	8.49234
1754.8	9.21533
1757.82	8.71599
1760.84	8.72106
1763.86	8.48931
1766.88	8.02634
1769.9	7.48476
1772.92	6.49532
1775.93	5.96457
1778.95	4.36491
1781.96	3.35994
1784.98	2.1158
1787.99	1.21604
1791	1.37313
1794.01	2.26845
1797.02	2.8484
1800.03	3.23784
1803.03	3.60929
1806.04	3.40978
1809.04	4.01296
1812.04	4.74245
1815.05	4.96697
1818.05	4.72701
1821.05	5.0009
1824.05	5.18366
1827.04	6.66391
1830.04	6.59098
1833.03	6.87011
1836.03	6.12183
1839.02	6.08533
1842.01	5.21296
1845	4.10039
1847.99	4.20095
1850.98	2.56904
1853.97	2.60888
1856.95	2.32647
1859.94	2.73001
1862.92	3.11434
1865.91	2.94152
1868.89	3.38956
1871.87	3.64431
1874.85	3.09646
1877.83	3.48926
1880.8	2.55355
1882.56	3.15893
1885.54	2.69608
1888.53	1.908
1891.52	2.66647
1894.5	2.56333
1897.49	2.7952
1900.47	1.84027
1903.45	1.81719
1906.43	1.64461
1909.41	0.522444
1912.39	-0.102634
1915.37	-0.598888
1918.35	0.367192
1921.32	0.273403
1924.3	-0.0112112
1927.27	0.670123
1930.24	1.5767
1933.21	2.03632
1936.18	2.15252
1939.15	2.67987
1942.12	3.32779
1945.09	3.86707
1948.05	4.62819
1951.02	4.14652
1953.98	2.7675
1956.94	2.6856
1959.91	1.60223
1962.87	1.7804
1965.82	1.98946
1968.78	2.07921
1971.74	2.31305
1974.7	2.36611
1977.65	2.73941
1980.6	3.0734
1983.56	3.56466
1986.51	3.60478
1989.46	4.24273
1992.41	5.61444
1995.36	6.43392
1998.3	6.54693
2001.25	6.55304
2004.2	7.33209
2007.14	7.51086
2010.08	8.1097
2013.02	7.57824
2015.97	6.68396
2018.9	5.65831
2021.84	4.6426
2024.78	2.56747
2027.72	1.83904
2030.65	1.05125
2033.59	1.65109
2036.52	2.11455
2039.45	2.84875
2042.38	2.66975
2045.31	3.30844
2048.24	3.63567
2051.17	3.52999
2054.1	3.37103
2057.02	4.08033
2059.95	5.31442
2062.87	6.27699
2065.79	6.86816
2068.71	6.94222
2071.63	7.59955
2074.55	9.09825
2077.47	10.1945
2080.39	11.7918
2083.3	12.0982
2086.22	12.412
2089.13	14.3145
2092.05	16.4046
2094.96	18.0265
2097.87	19.5607
2100.78	20.7452
2103.69	23.3011
2106.59	25.2843
2109.5	26.9204
2112.41	27.4229
2115.31	28.8084
2118.21	31.506
2121.12	34.618
2124.02	37.1883
2126.92	39.4452
2129.82	42.2253
2132.71	44.9649
2135.61	46.9467
2138.51	49.8857
2141.4	53.3544
2144.29	57.0469
2147.19	59.9343
2150.08	62.3352
2152.97	64.1544
2155.86	67.0387
2158.75	70.1826
2161.64	72.5032
2164.52	73.9755
2167.41	73.627
2170.29	75.0841
2173.17	74.6443
2176.06	73.8854
2178.94	72.9686
2181.82	70.9739
2184.7	69.6481
2187.57	67.9454
2190.45	67.0124
2193.33	63.9411
2196.2	61.0262
2199.08	58.7123
2201.95	57.049
2204.82	53.9561
2207.69	51.0221
2210.56	47.0303
2213.43	44.373
2216.3	41.4885
2219.16	39.3301
2222.03	36.5827
2224.89	33.8877
2227.75	31.8316
2230.62	29.5133
2233.48	27.0029
2236.34	25.2486
2239.2	23.857
2242.06	22.0838
2244.91	20.4354
2247.77	19.1477
2250.62	18.3415
2253.48	16.9779
2256.33	16.9274
2259.18	16.48
2262.03	15.9734
2264.88	15.3121
2267.73	15.2942
2270.58	14.4017
2273.43	13.1937
2276.27	11.7562
2279.12	10.4314
2281.96	9.64285
2284.8	8.60237
2287.64	8.12022
2290.49	5.45157
2293.32	3.10917
2296.16	2.99695
2299	3.87424
2301.84	3.41885
2304.67	3.99273
2307.51	3.38767
2310.34	4.19397
2313.17	4.53929
2316	5.19457
2318.83	6.70646
2321.66	7.00432
2324.49	7.39928
2327.32	8.32628
2330.15	7.35883
2332.97	7.12825
2335.79	7.274
2338.62	7.21054
2341.44	6.36347
2344.26	5.5479
2347.08	4.49328
2349.9	3.94365
2352.72	1.84829
2355.53	1.11085
2358.35	0.557141
2361.17	-0.491901
2363.98	0.516616
2366.79	1.06169
2369.6	0.50596
2372.42	0.860189
2375.22	1.34742
2378.03	1.45432
2380.84	1.90786
2383.65	1.41827
2386.45	2.0225
2389.26	2.11753
2392.06	3.18631
2394.87	3.54117
2397.67	3.16203
2400.47	3.16433
2403.27	3.73828
2406.07	3.28462
2408.86	3.44607
2411.66	4.88896
2414.46	4.56292
2417.25	4.52005
2420.05	5.16042
2422.84	5.59818
2425.63	6.51268
2428.42	6.20357
2431.21	5.92322
2434	6.32086
2436.79	6.86265
2439.57	6.96808
2442.36	7.31192
2445.14	7.40931
2447.93	7.06224
2450.71	6.9948
2453.49	7.84984
2456.27	8.23674
2459.05	8.12982
2461.83	7.24042
2464.61	5.6829
2467.39	5.92006
2470.16	5.39877
2472.94	5.4807
2475.71	4.38035
2478.48	4.98496
2481.25	4.86934
2484.02	4.70971
2486.8	3.7894
2489.56	2.69206
2492.33	1.8686
2495.1	0.109761
2497.86	-0.330962
2500.63	-1.25021
2503.39	-1.16268
2506.16	-0.204011
2508.92	-0.273386
2511.68	0.0387503
2514.44	-0.0655546
2517.2	0.858324
2519.95	2.60398
2522.71	3.2064
2525.47	3.48613
2528.22	4.45867
2530.98	4.94243
2533.73	6.94561
2536.48	8.41003
2539.23	8.15531
2541.98	8.32617
2544.73	8.11022
2547.48	9.33213
2550.23	8.89486
2552.97	8.99138
2555.72	7.59471
2558.46	7.87339
2561.2	7.50528
2563.95	7.08396
2566.69	6.39325
2569.43	6.43786
2572.17	7.33528
2574.91	7.73562
2577.64	7.12863
2580.38	6.87827
2583.11	8.47176
2585.85	9.33917
2588.58	9.67614
2591.31	10.5408
2594.04	11.2955
2596.78	11.7931
2599.51	12.3107
2602.23	12.3424
2604.96	12.5726
2607.69	12.5671
2610.41	12.9843
2613.14	13.603
2615.86	13.223
2618.58	12.0763
2621.3	10.9971
2624.03	11.1245
2626.75	11.6636
2629.46	11.4666
2632.18	11.0528
2634.9	11.4086
2637.61	12.0921
2640.33	11.2699
2643.04	11.6442
2645.76	11.4204
2648.47	11.6584
2651.18	12.0086
2653.89	11.2755
2656.6	11.4335
2659.31	11.3007
2662.01	11.4202
2664.72	10.6799
2667.43	10.7283
2670.13	10.8028
2672.83	11.328
2675.53	10.4142
2678.24	10.7537
2680.94	9.48642
2683.64	8.86753
2686.34	8.9293
2689.03	8.90198
2691.73	9.51351
2694.43	10.1039
2697.12	9.71471
2699.81	11.2232
2702.51	12.0036
2705.2	12.3178
2707.89	12.9462
2710.58	13.1841
2713.27	12.5482
2715.96	13.1973
2718.64	13.5284
2721.33	12.8223
2724.01	12.2431
2726.7	11.6278
2729.38	11.3551
2732.06	11.4356
2734.75	11.0703
2737.43	10.2683
2740.11	9.59241
2742.78	9.44604
2745.46	8.59845
2748.14	7.72639
2750.81	7.71368
2753.49	6.74451
2756.16	5.76226
2758.84	5.96423
2761.51	5.99945
2764.18	6.28042
2766.85	6.34427
2769.52	6.38087
2772.19	6.40662
2774.85	5.74517
2777.52	5.97302
2780.18	5.83029
2782.85	5.52429
2785.51	4.33839
2788.17	3.48767
2790.84	3.00276
2793.5	2.2517
2796.16	2.37493
2798.81	2.59335
2801.47	1.37515
2804.13	1.10019
2806.79	1.0254
2809.44	0.722693
2812.09	0.327506
2814.75	1.86853
2817.4	3.91281
2820.05	6.80507
2822.7	11.553
2825.35	15.993
2828	21.1408
2830.65	27.5383
2833.29	34.5801
2835.94	41.8968
2838.58	49.6566
2841.23	56.4776
2843.87	63.0736
2846.51	68.587
2849.15	76.1339
2851.79	83.1197
2854.43	90.6129
2857.07	97.2025
2859.71	104.107
2862.34	110.736
2864.98	115.739
2867.61	119.81
2870.25	123.36
2872.88	126.215
2875.51	129.206
2878.14	132.636
2880.77	136.226
2883.4	139.341
2886.03	142.329
2888.65	144.496
2891.28	147.553
2893.91	150.352
2896.53	154.016
2899.15	157.902
2901.78	161.48
2904.4	166.667
2907.02	172.209
2909.64	179.128
2912.26	187.054
2914.87	194.29
2917.49	202.11
2920.11	208.871
2922.72	214.552
2925.34	219.642
2927.95	223.44
2930.56	225.538
2933.17	226.256
2935.78	224.78
2938.39	222.116
2941	218.006
2943.61	212.578
2946.22	205.324
2948.82	197.016
2951.43	188.313
2954.03	178.074
2956.64	167.928
2959.24	158.35
2961.84	147.804
2964.44	137.94
2967.04	128.252
2969.64	120.215
2972.24	111.015
2974.83	102.814
2977.43	95.0283
2980.02	86.4233
2982.62	79.5373
2985.21	71.1119
2987.8	63.5581
2990.4	57.5249
2992.99	51.4226
2995.57	45.897
2998.16	39.827
3000.75	34.2807
3003.34	29.8603
3005.92	25.7493
3008.51	21.22
3011.09	16.8769
3013.68	13.6388
3016.26	10.6747
3018.84	8.36996
3021.42	6.37498
3024	4.87441
3026.58	3.20538
3029.16	1.99265
3031.73	1.82115
3034.31	1.68382
3036.89	2.22476
3039.46	2.19093
3042.03	2.23799
3044.61	1.88073
3047.18	2.09744
3049.75	2.5611
3052.32	3.62091
3054.89	4.16768
3057.45	2.73833
3060.02	2.82922
3062.59	2.94459
3065.15	2.53483
3067.72	3.05423
3070.28	3.26771
3072.84	3.19153
3075.41	2.27312
3077.97	1.8334
3080.53	2.13446
3083.09	2.03541
3085.64	2.00136
3088.2	3.12731
3090.76	3.47313
3093.31	4.11252
3095.87	4.52345
3098.42	5.20183
3100.97	6.25457
3103.53	6.7015
3106.08	7.32734
3108.63	8.35883
3111.18	10.1129
3113.73	11.7696
3116.27	13.502
3118.82	14.1024
3121.37	15.8328
3123.91	18.6782
3126.45	19.8883
3129	22.7065
3131.54	25.0008
3134.08	26.0529
3136.62	26.5772
3139.16	28.1618
3141.7	29.763
3144.24	30.5846
3146.78	30.6393
3149.31	28.6817