File: data/Raman/poly_smoothed/Mb_40_24_09_1x_45s_532 nm_x100_100%_600 gr_mm_01.txt
#Acq. time (s)=	45
#Accumulations=	2
#Range (cm-¹)=	200...3150
#Windows=	2
#Auto scanning=	Off
#Autofocus=	Off
#Macrospot=	Off
#AutoExposure=	Off
#Spike filter=	Multiple accum.
#Delay time (s)=	0
#Binning=	1
#Readout mode=	Signal
#DeNoise=	Off
#ICS correction=	On
#Dark correction=	Off
#Inst. Process=	Off
#Detector Gain=	Best Dynamic Range
#Detector ADC=	20 kHz
#Detector temperature (°C)=	-70.08
#Instrument=	LabRAM HR Evol
#Detector=	Synapse
#Objective=	x100
#Grating=	600 gr/mm
#ND Filter=	100%
#Laser (nm)=	532
#Hole=	100.021
#Range=	Auto
#Laser Pol.=	No
#Raman. Pol.=	No
#Laser Pol. (°)=	-0.0007625
#Raman Pol. (°)=	89.9995
#Collection=	Microscope
#StageXY=	Marzhauser
#StageZ=	Marzhauser
#X (µm)=	-2538.1
#Y (µm)=	-52.7
#Z (µm)=	-10.7
#Full time(mm:ss)=	3:18
#Project=
#Sample=
#Site=
#Title=	Mb_40_24_09_2x_45s_532 nm_x100_100%_600 gr_mm
#Remark=
#Date=	14.07.2022 11:22
#Acquired=	14.07.2022 11:22:11
#Edit:Spike=	14.07.2022 11:24:41
#Edit:Spike=	14.07.2022 11:24:42
#Base:Fit=	10.08.2022 10:47:00
#Base:Sub=	10.08.2022 10:47:12
#Filter:Polynom=	16.08.2022 10:11:48
#AxisType[0]=Intens
#AxisUnit[0]=Cnt
#AxisType[1]=Spectr
#AxisUnit[1]=1/cm
200.554	33.1395
204.183	33.2444
207.813	31.4684
211.439	27.1077
215.065	23.7154
218.688	22.2402
222.312	20.1037
225.933	19.219
229.552	18.6622
233.171	17.0199
236.787	15.0933
240.402	12.3723
244.015	11.2729
247.627	10.3433
251.24	8.57856
254.849	8.67611
258.457	7.71141
262.063	10.4502
265.668	13.0244
269.271	14.1845
272.873	14.7278
276.474	13.4157
280.073	14.1522
283.671	13.1996
287.268	13.387
290.863	13.5517
294.456	13.434
298.049	14.5443
301.637	14.7073
305.227	18.0154
308.815	18.927
312.402	20.2507
315.987	18.7981
319.569	17.8564
323.151	16.5166
326.733	16.3771
330.31	15.1522
333.889	16.1834
337.464	17.1291
341.039	17.1716
344.611	17.499
348.184	17.2009
351.754	17.4098
355.324	16.2019
358.89	14.7875
362.455	13.6574
366.021	13.7929
369.584	13.5877
373.145	13.3202
376.707	12.7941
380.265	11.8215
383.822	10.772
387.378	8.03347
390.934	7.90438
394.487	8.95892
398.038	5.884
401.588	4.59162
405.137	3.5378
408.685	2.28839
412.23	3.77123
415.775	4.70568
419.318	5.47282
422.86	6.86749
426.401	9.09486
429.94	8.76034
433.478	9.07723
437.012	10.6863
440.547	10.9157
444.081	9.79838
447.613	9.62586
451.142	10.0016
454.672	11.651
458.2	11.0399
461.725	11.1995
465.251	10.8873
468.775	10.4485
472.296	9.67202
475.817	9.56041
479.335	11.7725
482.854	10.9338
486.37	10.2622
489.886	12.2395
493.398	14.1879
496.91	15.4781
500.422	18.0423
503.93	19.2557
507.438	21.0244
510.946	23.2728
514.45	23.3403
517.954	23.5194
521.456	23.0061
524.956	22.2532
528.456	20.4624
531.956	19.0318
535.452	18.7954
538.947	19.1322
542.441	17.8198
545.934	16.4626
549.425	15.362
552.915	13.4158
556.403	11.319
559.889	11.2768
563.375	10.336
566.859	7.72157
570.342	6.59483
573.824	6.25667
577.303	6.99265
580.782	7.75516
584.26	7.47997
587.734	7.75301
591.21	7.9719
594.684	7.05807
598.154	7.15418
601.626	5.64652
605.094	5.43607
608.562	5.74909
612.027	5.70705
615.493	6.78297
618.956	8.21792
622.419	8.07186
625.879	9.47504
629.338	9.56274
632.797	8.91867
636.254	10.5303
639.708	10.345
643.162	10.4114
646.614	10.074
650.067	10.8655
653.516	10.5691
656.964	12.1019
660.411	15.1652
663.857	15.6169
667.301	17.4427
670.744	17.2732
674.186	17.4628
677.626	16.9792
681.065	17.4415
684.503	19.0043
687.939	21.0855
691.372	20.4298
694.806	23.32
698.239	25.6143
701.67	28.0989
705.098	30.2088
708.526	30.3229
711.954	33.1241
715.378	34.6801
718.802	35.7228
722.226	36.6363
725.646	37.9408
729.067	39.5518
732.484	41.0216
735.902	42.5051
739.317	44.2903
742.731	45.3702
746.145	47.7715
749.556	49.4026
752.966	51.6685
756.377	51.8269
759.784	53.2279
763.19	55.9556
766.594	58.0641
770	60.2279
773.402	61.1647
776.803	63.4882
780.202	68.9847
783.6	70.2128
786.997	73.7955
790.393	74.923
793.787	76.4706
797.18	77.5307
800.572	77.1464
803.963	76.8153
807.35	74.8023
810.738	73.8423
814.125	72.9325
817.51	71.8273
820.894	71.0454
824.275	68.61
827.657	68.2473
831.037	67.617
834.414	66.8722
837.792	64.1953
841.167	64.3431
844.542	64.9909
847.914	64.1717
851.287	62.7783
854.656	61.7887
858.026	63.1123
861.393	63.3427
864.761	61.219
868.125	60.5395
871.489	61.0767
874.85	59.4325
878.213	57.5802
881.572	54.7393
884.931	53.3024
888.287	52.176
891.643	52.2446
894.997	52.8174
898.352	53.3361
901.704	53.3868
905.055	53.1073
908.404	51.1661
911.75	51.7167
915.097	50.7445
918.443	48.9951
921.787	49.18
925.13	50.0577
928.472	49.1144
931.813	48.0584
935.15	46.2249
938.488	45.0346
941.825	42.4863
945.158	39.9477
948.493	40.1407
951.824	38.2977
955.156	37.0553
958.486	35.9259
961.814	34.7371
965.142	33.687
968.467	37.5816
971.79	39.1226
975.115	39.5755
978.436	39.5721
981.756	40.3859
985.077	39.5325
988.394	38.7932
991.71	38.805
995.025	40.4013
998.341	41.557
1001.65	40.2225
1004.97	39.1058
1008.28	38.5421
1011.58	36.734
1014.89	35.6048
1018.2	34.4184
1021.5	32.8551
1024.81	31.0573
1028.11	32.1636
1031.41	31.4123
1034.71	31.1611
1038.01	31.3563
1041.31	30.6753
1044.6	30.377
1047.9	30.7318
1051.19	32.6545
1054.48	32.59
1057.77	32.5135
1061.06	31.6408
1064.35	30.0166
1067.64	30.0714
1070.93	30.2212
1074.21	29.7281
1077.49	28.7087
1080.78	27.5077
1084.06	25.7123
1087.34	25.7697
1090.61	25.5356
1093.89	26.0133
1097.17	26.6777
1100.44	28.6748
1103.71	30.8379
1106.99	31.8714
1110.26	31.4634
1113.52	29.9693
1116.79	29.3019
1120.06	28.7081
1123.32	27.3779
1126.59	26.0866
1129.85	26.9363
1133.11	26.8637
1136.37	25.5226
1139.63	22.7363
1142.89	20.6028
1146.15	18.7633
1149.4	19.4716
1152.66	17.4691
1155.91	17.4304
1159.16	14.8515
1162.41	13.4965
1165.66	12.5061
1168.91	12.7661
1172.16	13.6805
1175.4	15.4135
1178.65	17.594
1181.89	18.7539
1185.13	17.5406
1188.37	17.491
1191.61	16.2567
1194.85	15.4981
1198.08	16.0505
1201.32	13.6736
1204.55	14.5512
1207.79	16.7953
1211.02	18.8567
1214.25	19.5644
1217.48	20.5609
1220.71	23.3422
1223.93	23.2812
1227.16	25.1961
1230.38	26.4711
1233.6	26.3373
1236.83	26.3336
1240.05	27.616
1243.26	28.9192
1246.48	30.7558
1249.7	33.0407
1252.92	35.5755
1256.13	36.8838
1259.34	38.9051
1262.55	40.4644
1265.76	41.6658
1268.97	42.7888
1272.18	44.0707
1275.39	44.8602
1278.59	46.3197
1281.8	49.5732
1285	52.0198
1288.2	54.7385
1291.4	54.883
1294.6	55.0309
1297.8	54.7189
1301	54.243
1304.19	53.8983
1307.39	54.8543
1310.58	53.8141
1313.77	53.6507
1316.96	53.2732
1320.15	52.5527
1323.34	50.8926
1326.53	50.0421
1329.72	49.3243
1332.9	48.44
1336.08	47.1608
1339.27	45.9845
1342.45	44.209
1345.63	44.5637
1348.8	43.485
1351.98	43.7198
1355.16	43.0764
1358.33	42.8395
1361.51	43.2203
1364.68	41.9615
1367.85	39.9632
1371.02	40.6119
1374.19	41.0664
1377.36	42.175
1380.52	43.155
1383.69	42.0519
1386.85	43.9934
1390.02	45.3345
1393.18	46.1419
1396.34	47.2706
1399.5	46.6942
1402.65	45.7843
1405.81	47.1502
1408.97	48.1937
1412.12	48.0064
1415.27	48.4778
1418.43	47.601
1421.58	50.8867
1424.73	52.9748
1427.87	55.718
1431.02	57.9838
1434.17	59.4473
1437.31	59.6485
1440.46	60.5168
1443.6	60.6197
1446.74	62.5052
1449.88	63.3584
1453.02	62.4216
1456.16	60.1461
1459.29	57.68
1462.43	56.2087
1465.56	53.7204
1468.69	51.0008
1471.83	48.836
1474.95	44.5269
1478.08	40.4455
1481.21	39.1002
1484.34	37.8485
1487.47	35.1025
1490.59	33.4004
1493.71	33.4665
1496.84	32.8811
1499.96	32.8971
1503.07	31.9658
1506.19	31.2964
1509.31	30.1855
1512.43	28.9763
1515.54	29.0433
1518.65	28.1947
1521.77	28.3051
1524.88	27.1863
1527.99	25.8659
1531.1	23.6305
1534.21	22.7695
1537.31	21.6983
1540.42	21.2159
1543.52	19.7852
1546.63	21.0234
1549.73	19.8406
1552.83	20.6948
1555.93	21.4632
1559.03	23.041
1562.12	23.4222
1565.22	24.6804
1568.31	27.455
1571.41	28.3624
1574.5	29.9524
1577.59	32.6906
1580.68	36.186
1583.77	38.6827
1586.86	41.1753
1589.95	43.5066
1593.03	45.2692
1596.11	46.752
1599.2	47.7453
1602.28	49.0851
1605.36	49.2711
1608.44	49.794
1611.52	49.5974
1614.6	50.3621
1617.67	50.8375
1620.75	50.9473
1623.82	51.9668
1626.89	53.0354
1629.96	52.5026
1633.04	52.4583
1636.11	53.6408
1639.17	53.9072
1642.24	54.2523
1645.31	54.2963
1648.37	53.1857
1651.43	52.7573
1654.5	52.0421
1657.56	50.813
1660.62	47.9164
1663.67	43.6871
1666.73	40.5272
1669.79	36.8237
1672.84	33.9693
1675.9	30.6525
1678.95	28.8069
1682	26.4164
1685.05	23.2853
1688.1	21.1514
1691.15	18.746
1694.2	18.2056
1697.25	16.3907
1700.29	15.3134
1703.33	15.0197
1706.38	14.0021
1709.42	13.6219
1712.46	13.7352
1715.5	12.9958
1718.54	12.0938
1721.57	11.3724
1724.61	10.442
1727.64	10.3584
1730.68	9.71135
1733.71	7.57532
1736.74	6.30064
1739.77	6.07755
1742.8	6.41277
1745.83	6.62638
1748.85	6.86578
1751.88	7.2233
1754.91	6.81164
1757.93	6.15296
1760.95	5.96219
1763.97	5.10936
1766.99	4.91936
1770.01	3.36811
1773.03	2.57568
1776.04	2.38426
1779.06	2.22339
1782.07	2.22051
1785.09	2.53639
1788.1	2.54678
1791.11	2.07896
1794.12	2.6613
1797.13	3.08175
1800.13	2.8653
1803.14	2.98851
1806.15	3.44207
1809.15	4.02967
1812.15	4.42268
1815.16	4.99564
1818.15	4.73813
1821.16	5.12956
1824.15	4.95929
1827.15	4.77977
1830.15	5.79477
1833.14	5.20923
1836.14	5.0474
1839.13	5.09867
1842.12	3.61401
1845.11	2.00776
1848.1	1.68482
1851.09	2.73096
1854.08	3.38059
1857.06	3.62941
1860.05	5.02717
1863.03	4.43035
1866.01	5.95425
1869	6.18314
1871.98	6.88452
1874.96	6.55974
1877.93	7.6931
1880.91	8.28099
1882.47	7.9371
1885.46	6.86806
1888.44	5.95107
1891.43	5.14552
1894.42	4.00911
1897.4	3.18781
1900.39	3.81068
1903.37	3.31415
1906.35	2.54018
1909.33	2.34456
1912.31	1.85653
1915.29	1.3194
1918.26	1.54012
1921.24	2.46521
1924.21	2.02217
1927.19	1.90819
1930.16	2.71609
1933.13	3.64191
1936.1	3.81606
1939.07	4.27139
1942.04	4.59791
1945	4.60766
1947.97	4.88615
1950.93	4.95244
1953.9	5.03837
1956.86	5.12846
1959.82	4.19311
1962.78	3.41889
1965.74	3.59689
1968.7	3.79291
1971.65	4.20021
1974.61	4.90398
1977.57	6.08753
1980.52	8.19395
1983.47	8.85606
1986.42	8.17601
1989.37	8.89307
1992.32	8.77017
1995.27	8.04582
1998.22	7.64041
2001.17	7.78496
2004.11	7.37403
2007.05	6.53831
2010	5.76265
2012.94	5.88706
2015.88	4.9729
2018.82	4.0228
2021.76	3.47553
2024.7	3.07882
2027.63	2.50391
2030.57	2.94356
2033.5	1.56942
2036.44	1.7507
2039.37	1.28928
2042.3	1.82824
2045.23	3.48366
2048.16	3.75504
2051.08	5.41691
2054.01	6.13709
2056.94	5.94246
2059.86	6.89862
2062.79	7.51098
2065.71	7.92219
2068.63	9.6546
2071.55	10.9444
2074.47	11.0962
2077.39	12.4032
2080.31	13.5267
2083.22	14.8599
2086.13	15.962
2089.05	16.9946
2091.96	18.5261
2094.87	20.1308
2097.78	21.1403
2100.69	22.1104
2103.6	22.0817
2106.51	22.9344
2109.42	24.0421
2112.32	24.943
2115.23	26.5214
2118.13	26.9394
2121.03	27.6134
2123.93	29.7243
2126.83	30.448
2129.73	30.5846
2132.63	31.8462
2135.53	33.1304
2138.42	33.9822
2141.32	36.7138
2144.21	38.7989
2147.1	40.986
2150	42.7128
2152.89	44.8098
2155.78	46.6926
2158.66	49.5752
2161.55	50.7146
2164.44	51.4424
2167.32	50.8371
2170.21	51.1438
2173.09	50.3225
2175.97	49.633
2178.85	49.9134
2181.73	50.0998
2184.61	48.5563
2187.49	47.1425
2190.37	45.989
2193.24	44.5421
2196.12	42.3579
2198.99	40.9546
2201.87	38.4503
2204.74	37.1243
2207.61	36.0282
2210.48	33.8973
2213.35	33.0301
2216.21	31.6133
2219.08	30.6964
2221.95	28.5388
2224.81	26.9914
2227.67	25.7756
2230.54	24.3995
2233.4	21.7699
2236.26	20.5337
2239.11	18.4299
2241.97	17.1577
2244.83	16.6991
2247.69	16.5921
2250.54	16.804
2253.4	15.4184
2256.25	15.5975
2259.1	15.9701
2261.95	15.5372
2264.8	14.5561
2267.65	14.309
2270.5	14.8683
2273.34	13.681
2276.19	13.5831
2279.03	13.2835
2281.88	12.1377
2284.72	13.2938
2287.56	11.85
2290.4	10.9347
2293.24	10.5922
2296.08	10.9919
2298.92	10.8912
2301.76	10.8577
2304.59	11.5322
2307.43	10.2043
2310.26	10.6908
2313.09	11.6107
2315.92	10.8589
2318.75	11.4718
2321.58	11.0357
2324.41	11.5222
2327.24	10.3783
2330.06	10.3273
2332.89	9.65519
2335.71	8.34682
2338.54	7.27895
2341.36	6.18587
2344.18	6.08955
2347	5.7562
2349.82	4.9013
2352.64	3.42054
2355.45	2.06377
2358.27	2.13358
2361.08	2.4134
2363.9	2.61889
2366.71	4.18301
2369.52	4.7125
2372.33	4.9306
2375.14	5.75613
2377.95	6.3302
2380.76	6.64702
2383.57	7.00908
2386.37	8.03915
2389.18	9.42888
2391.98	10.8377
2394.79	11.4439
2397.59	10.7515
2400.39	11.7853
2403.19	12.1372
2405.99	12.0271
2408.78	11.6645
2411.58	13.3175
2414.38	12.9484
2417.17	12.118
2419.97	11.9844
2422.76	11.794
2425.55	12.1456
2428.34	12.2957
2431.13	12.4712
2433.92	11.8708
2436.71	11.2501
2439.49	10.2663
2442.28	9.93707
2445.06	9.90909
2447.85	8.20136
2450.63	7.00549
2453.41	6.55318
2456.19	7.15924
2458.97	5.83539
2461.75	4.67652
2464.53	3.52673
2467.31	2.55384
2470.08	2.49434
2472.86	2.76682
2475.63	1.64982
2478.4	1.78549
2481.17	1.82564
2483.94	1.51948
2486.72	2.28859
2489.48	1.34772
2492.25	1.26445
2495.02	1.74392
2497.79	1.50668
2500.55	1.26504
2503.31	0.589548
2506.08	0.682413
2508.84	1.71692
2511.6	1.47992
2514.36	1.38256
2517.12	1.19661
2519.88	1.44241
2522.63	2.12247
2525.39	2.25288
2528.14	2.06504
2530.9	2.41514
2533.65	3.57044
2536.4	3.54516
2539.15	4.26581
2541.9	5.12176
2544.65	5.78364
2547.4	6.04905
2550.15	7.23271
2552.89	7.50607
2555.64	6.78316
2558.38	6.50712
2561.12	6.39746
2563.87	5.20016
2566.61	6.46357
2569.35	6.45934
2572.09	6.12973
2574.83	6.32031
2577.56	6.76806
2580.3	6.64587
2583.04	6.32914
2585.77	6.54029
2588.5	7.34594
2591.23	6.74956
2593.97	7.2014
2596.7	7.271
2599.43	7.38676
2602.15	8.05268
2604.88	7.0952
2607.61	7.16227
2610.33	6.86498
2613.06	6.4496
2615.78	6.19026
2618.51	6.23249
2621.23	6.19083
2623.95	4.27995
2626.67	3.95476
2629.39	3.89754
2632.1	3.43358
2634.82	3.91954
2637.54	2.2422
2640.25	1.44943
2642.97	1.56376
2645.68	2.09999
2648.39	2.36085
2651.1	2.94416
2653.81	2.45623
2656.52	2.7487
2659.23	3.03544
2661.94	4.25564
2664.64	4.64282
2667.35	5.72406
2670.05	5.98399
2672.76	5.8132
2675.46	6.90645
2678.16	7.09232
2680.86	7.71774
2683.56	9.00451
2686.26	9.83785
2688.96	9.69278
2691.65	10.7818
2694.35	10.0768
2697.04	10.0053
2699.74	10.225
2702.43	10.0438
2705.12	9.11797
2707.81	9.17814
2710.5	9.47029
2713.19	8.89044
2715.88	8.30123
2718.57	8.30066
2721.25	8.4821
2723.94	9.5242
2726.62	8.80239
2729.3	7.85221
2731.99	8.40372
2734.67	8.17167
2737.35	7.47027
2740.03	7.11247
2742.71	5.92589
2745.38	6.49575
2748.06	5.43582
2750.74	5.1945
2753.41	4.75502
2756.09	4.57472
2758.76	2.72154
2761.43	2.46137
2764.1	1.55856
2766.77	1.34157
2769.44	0.608794
2772.11	0.823247
2774.77	0.473208
2777.44	-0.0215416
2780.11	0.348008
2782.77	0.802449
2785.43	1.51194
2788.1	0.982185
2790.76	1.42633
2793.42	1.33671
2796.08	1.55843
2798.74	1.9189
2801.4	1.72353
2804.05	2.232
2806.71	2.07168
2809.36	3.19143
2812.02	3.45826
2814.67	3.96845
2817.32	4.75257
2819.97	5.14988
2822.62	6.42787
2825.27	8.74761
2827.92	11.0534
2830.57	13.6846
2833.22	17.2189
2835.86	20.0515
2838.51	23.0832
2841.15	26.8267
2843.79	29.7225
2846.43	32.2707
2849.08	36.8931
2851.72	40.1251
2854.36	43.5244
2856.99	47.8836
2859.63	51.2681
2862.27	55.3782
2864.9	57.9974
2867.54	60.7822
2870.17	62.7397
2872.8	64.9686
2875.43	68.2299
2878.07	70.3858
2880.7	72.6205
2883.32	75.1653
2885.95	79.256
2888.58	82.9149
2891.21	87.5545
2893.83	91.4994
2896.46	96.1292
2899.08	100.862
2901.7	107.131
2904.32	111.479
2906.94	116.357
2909.56	122.424
2912.18	128.135
2914.8	134.336
2917.42	139.576
2920.03	145.505
2922.65	150.722
2925.26	153.496
2927.88	156.15
2930.49	156.728
2933.1	157.332
2935.71	156.538
2938.32	154.353
2940.93	150.714
2943.54	147.446
2946.14	143.264
2948.75	138.205
2951.35	132.407
2953.96	125.668
2956.56	118.509
2959.16	111.935
2961.77	105.647
2964.37	99.1105
2966.96	93.2336
2969.56	86.5951
2972.16	80.6096
2974.76	75.2596
2977.35	70.6527
2979.95	66.3195
2982.54	61.5531
2985.14	57.0391
2987.73	52.4017
2990.32	48.1571
2992.91	43.283
2995.5	39.1643
2998.09	35.2609
3000.68	31.6219
3003.26	28.3227
3005.85	25.2839
3008.43	22.6405
3011.02	19.1905
3013.6	17.0845
3016.19	15.6734
3018.77	14.1977
3021.35	12.2266
3023.93	11.2873
3026.5	10.0735
3029.08	8.61562
3031.66	6.94816
3034.24	5.33965
3036.81	4.97579
3039.39	5.15135
3041.96	4.84119
3044.53	4.1999
3047.1	4.12794
3049.67	3.04781
3052.24	3.04047
3054.81	1.43005
3057.38	0.727785
3059.95	1.52149
3062.52	1.46443
3065.08	1.59046
3067.65	1.6081
3070.21	2.6298
3072.77	3.15568
3075.33	3.28576
3077.89	4.98426
3080.45	5.42752
3083.01	5.14266
3085.57	5.04217
3088.13	5.82421
3090.68	4.3831
3093.24	4.43861
3095.79	4.32819
3098.35	4.73774
3100.9	4.43338
3103.45	4.6964
3106	5.4753
3108.55	5.22075
3111.1	5.83088
3113.65	5.93146
3116.2	5.65544
3118.75	5.91327
3121.29	6.88247
3123.84	7.63391
3126.38	7.80152
3128.92	8.41468
3131.47	9.1631
3134.01	10.1103
3136.55	10.5058
3139.09	11.7854
3141.63	11.0639
3144.17	10.1431
3146.7	8.5785
3149.24	5.73891