File: data/Raman/poly_smoothed/Mb_40_24_43_1x_45s_532 nm_x100_100%_600 gr_mm_01.txt
#Acq. time (s)=	45
#Accumulations=	2
#Range (cm-¹)=	200...3150
#Windows=	2
#Auto scanning=	Off
#Autofocus=	Off
#Macrospot=	Off
#AutoExposure=	Off
#Spike filter=	Multiple accum.
#Delay time (s)=	0
#Binning=	1
#Readout mode=	Signal
#DeNoise=	Off
#ICS correction=	On
#Dark correction=	Off
#Inst. Process=	Off
#Detector Gain=	Best Dynamic Range
#Detector ADC=	20 kHz
#Detector temperature (°C)=	-69.85
#Instrument=	LabRAM HR Evol
#Detector=	Synapse
#Objective=	x100
#Grating=	600 gr/mm
#ND Filter=	100%
#Laser (nm)=	532
#Hole=	100.021
#Range=	Auto
#Laser Pol.=	No
#Raman. Pol.=	No
#Laser Pol. (°)=	-0.0007625
#Raman Pol. (°)=	89.9995
#Collection=	Microscope
#StageXY=	Marzhauser
#StageZ=	Marzhauser
#X (µm)=	-2475.3
#Y (µm)=	-36.8
#Z (µm)=	-10.1
#Full time(mm:ss)=	3:19
#Project=
#Sample=
#Site=
#Title=	Mb_40_24_43_2x_45s_532 nm_x100_100%_600 gr_mm
#Remark=
#Date=	14.07.2022 14:04
#Acquired=	14.07.2022 14:04:12
#Base:Fit=	10.08.2022 10:47:00
#Base:Sub=	10.08.2022 10:47:12
#Filter:Polynom=	16.08.2022 10:11:48
#AxisType[0]=Intens
#AxisUnit[0]=Cnt
#AxisType[1]=Spectr
#AxisUnit[1]=1/cm
200.554	52.1467
204.183	42.4177
207.813	33.4694
211.439	26.4832
215.065	20.3431
218.688	15.7807
222.312	11.2481
225.933	7.69628
229.552	5.3288
233.171	4.44519
236.787	2.65047
240.402	3.43274
244.015	4.30779
247.627	5.88705
251.24	8.62702
254.849	11.2996
258.457	10.2019
262.063	12.2704
265.668	13.9457
269.271	12.8045
272.873	14.5365
276.474	14.8278
280.073	14.6521
283.671	13.5953
287.268	15.5526
290.863	14.7835
294.456	13.4299
298.049	13.1991
301.637	11.1839
305.227	9.82327
308.815	8.15107
312.402	8.84425
315.987	10.248
319.569	10.2338
323.151	10.5767
326.733	12.7551
330.31	13.5509
333.889	14.103
337.464	15.1811
341.039	16.5367
344.611	16.4513
348.184	15.739
351.754	14.8326
355.324	14.8112
358.89	15.4792
362.455	16.5383
366.021	16.2942
369.584	17.6458
373.145	17.4026
376.707	15.0431
380.265	13.5396
383.822	12.6901
387.378	11.7046
390.934	12.1402
394.487	12.0895
398.038	12.6522
401.588	13.388
405.137	14.1035
408.685	14.9924
412.23	16.925
415.775	15.9821
419.318	14.4075
422.86	14.5829
426.401	15.2069
429.94	14.7551
433.478	14.6458
437.012	13.5074
440.547	15.0006
444.081	17.052
447.613	16.79
451.142	15.8172
454.672	14.2913
458.2	14.4456
461.725	14.2468
465.251	15.3567
468.775	15.2739
472.296	15.6883
475.817	14.5114
479.335	15.1613
482.854	16.7715
486.37	18.3182
489.886	22.6367
493.398	25.678
496.91	25.4645
500.422	24.8486
503.93	24.6257
507.438	25.7903
510.946	27.6953
514.45	28.0735
517.954	30.5245
521.456	29.7908
524.956	28.8499
528.456	30.8346
531.956	30.4447
535.452	29.0975
538.947	29.9082
542.441	30.1613
545.934	28.7696
549.425	27.0543
552.915	24.1663
556.403	22.3772
559.889	21.1847
563.375	19.1862
566.859	18.8262
570.342	19.0322
573.824	17.9173
577.303	17.6046
580.782	16.0705
584.26	15.2727
587.734	12.7862
591.21	12.4941
594.684	11.6121
598.154	8.62814
601.626	8.65499
605.094	8.00078
608.562	6.6431
612.027	7.25556
615.493	8.15448
618.956	9.21082
622.419	10.4834
625.879	10.4666
629.338	10.7542
632.797	12.5355
636.254	12.4463
639.708	12.1196
643.162	12.9852
646.614	14.956
650.067	15.2201
653.516	16.7398
656.964	17.619
660.411	17.1427
663.857	18.6383
667.301	16.2511
670.744	15.6386
674.186	14.1679
677.626	13.8308
681.065	13.1454
684.503	14.0316
687.939	13.735
691.372	16.1818
694.806	16.0504
698.239	18.5241
701.67	19.4872
705.098	22.0162
708.526	22.5095
711.954	24.0848
715.378	25.6827
718.802	26.5435
722.226	25.0721
725.646	26.357
729.067	28.8444
732.484	30.2783
735.902	31.6856
739.317	34.9781
742.731	36.95
746.145	39.1014
749.556	41.448
752.966	45.7675
756.377	49.7248
759.784	51.4945
763.19	53.3669
766.594	56.133
770	57.2219
773.402	60.5588
776.803	62.4372
780.202	63.4209
783.6	63.941
786.997	64.7213
790.393	65.5496
793.787	65.2884
797.18	65.749
800.572	65.965
803.963	65.3927
807.35	64.4159
810.738	66.4663
814.125	66.9746
817.51	67.5073
820.894	67.0572
824.275	68.7803
827.657	70.1724
831.037	72.7795
834.414	73.323
837.792	72.4207
841.167	70.8753
844.542	70.605
847.914	68.2817
851.287	64.7989
854.656	62.365
858.026	61.0144
861.393	58.187
864.761	54.9606
868.125	52.8506
871.489	50.4099
874.85	48.4094
878.213	46.1232
881.572	43.8953
884.931	42.3789
888.287	39.7305
891.643	39.5972
894.997	37.9338
898.352	37.7283
901.704	37.8267
905.055	38.9508
908.404	40.7872
911.75	40.973
915.097	44.8115
918.443	44.9494
921.787	47.807
925.13	47.8481
928.472	46.3506
931.813	45.5242
935.15	42.5112
938.488	42.3714
941.825	40.9898
945.158	39.4646
948.493	39.77
951.824	39.2397
955.156	37.3178
958.486	33.8206
961.814	32.624
965.142	32.2668
968.467	29.6803
971.79	29.8824
975.115	29.5844
978.436	30.0128
981.756	29.5481
985.077	27.5208
988.394	28.1845
991.71	27.6413
995.025	27.1357
998.341	26.0523
1001.65	24.3544
1004.97	22.6101
1008.28	20.4309
1011.58	19.7596
1014.89	20.0254
1018.2	21.3555
1021.5	23.7329
1024.81	24.8736
1028.11	27.3565
1031.41	29.9826
1034.71	29.7062
1038.01	30.7454
1041.31	31.1153
1044.6	35.1188
1047.9	35.727
1051.19	35.8996
1054.48	37.636
1057.77	39.3029
1061.06	37.3325
1064.35	36.4021
1067.64	34.7235
1070.93	33.7127
1074.21	29.6574
1077.49	27.2886
1080.78	25.1061
1084.06	24.1041
1087.34	21.1331
1090.61	21.5355
1093.89	24.3732
1097.17	23.1444
1100.44	22.548
1103.71	21.2995
1106.99	20.9449
1110.26	21.0571
1113.52	21.2879
1116.79	20.1466
1120.06	18.574
1123.32	17.3717
1126.59	16.9885
1129.85	15.0589
1133.11	13.5172
1136.37	13.3592
1139.63	11.5069
1142.89	10.2131
1146.15	9.57918
1149.4	7.42069
1152.66	6.38555
1155.91	3.5209
1159.16	2.07568
1162.41	2.46269
1165.66	1.91374
1168.91	1.86267
1172.16	4.11317
1175.4	3.94444
1178.65	1.61026
1181.89	1.14971
1185.13	2.88068
1188.37	5.12432
1191.61	5.70077
1194.85	7.38017
1198.08	10.3208
1201.32	10.3182
1204.55	13.7205
1207.79	17.2425
1211.02	17.5367
1214.25	19.2222
1217.48	21.8129
1220.71	25.1385
1223.93	30.2771
1227.16	32.8511
1230.38	33.1865
1233.6	35.8776
1236.83	38.5493
1240.05	41.8656
1243.26	44.0962
1246.48	43.814
1249.7	44.8067
1252.92	45.2931
1256.13	46.2523
1259.34	47.3917
1262.55	49.8661
1265.76	53.0805
1268.97	54.4111
1272.18	57.0837
1275.39	61.4561
1278.59	63.1427
1281.8	63.7183
1285	66.2448
1288.2	68.1201
1291.4	70.5262
1294.6	74.3968
1297.8	78.0365
1301	81.3921
1304.19	81.297
1307.39	80.5859
1310.58	82.5381
1313.77	85.1455
1316.96	85.3786
1320.15	84.5446
1323.34	81.1571
1326.53	80.6476
1329.72	80.0879
1332.9	76.5251
1336.08	75.0399
1339.27	73.4038
1342.45	69.2124
1345.63	67.5184
1348.8	65.4135
1351.98	64.5665
1355.16	64.0423
1358.33	62.352
1361.51	61.7779
1364.68	61.2536
1367.85	61.4782
1371.02	59.9605
1374.19	59.5273
1377.36	59.0998
1380.52	60.7414
1383.69	60.267
1386.85	61.8498
1390.02	63.8086
1393.18	63.4437
1396.34	63.9542
1399.5	64.4492
1402.65	64.913
1405.81	65.8682
1408.97	68.7797
1412.12	70.4598
1415.27	75.1731
1418.43	79.3158
1421.58	85.0612
1424.73	91.7022
1427.87	97.7152
1431.02	103.69
1434.17	109.185
1437.31	113.54
1440.46	117.273
1443.6	119.956
1446.74	122.814
1449.88	121.986
1453.02	122.326
1456.16	121.761
1459.29	118.682
1462.43	112.181
1465.56	106.476
1468.69	99.0457
1471.83	91.4535
1474.95	84.5619
1478.08	76.4097
1481.21	68.4414
1484.34	61.0029
1487.47	53.5179
1490.59	46.9108
1493.71	40.804
1496.84	34.8838
1499.96	31.4761
1503.07	27.2665
1506.19	23.1399
1509.31	21.385
1512.43	20.5268
1515.54	19.2591
1518.65	18.2119
1521.77	18.2354
1524.88	19.368
1527.99	18.8326
1531.1	20.1145
1534.21	22.6752
1537.31	25.4673
1540.42	28.2685
1543.52	32.5623
1546.63	37.279
1549.73	41.1874
1552.83	43.6755
1555.93	46.1786
1559.03	49.9325
1562.12	51.4803
1565.22	54.6643
1568.31	57.2141
1571.41	59.6657
1574.5	62.5408
1577.59	64.7862
1580.68	65.1499
1583.77	67.3437
1586.86	70.4467
1589.95	70.7907
1593.03	70.9193
1596.11	72.8118
1599.2	71.454
1602.28	71.0901
1605.36	70.9428
1608.44	71.777
1611.52	72.0119
1614.6	72.5223
1617.67	72.5919
1620.75	71.7002
1623.82	72.176
1626.89	72.8692
1629.96	74.592
1633.04	75.9634
1636.11	78.7777
1639.17	78.4032
1642.24	79.2659
1645.31	79.7533
1648.37	80.6479
1651.43	79.5732
1654.5	80.5699
1657.56	80.4375
1660.62	78.5183
1663.67	77.2578
1666.73	74.9962
1669.79	72.5614
1672.84	69.5222
1675.9	63.8616
1678.95	59.3897
1682	54.147
1685.05	50.2448
1688.1	46.795
1691.15	42.2332
1694.2	38.8857
1697.25	35.9454
1700.29	34.7886
1703.33	31.7873
1706.38	29.7441
1709.42	25.8896
1712.46	23.2214
1715.5	20.304
1718.54	17.9372
1721.57	17.2372
1724.61	15.8098
1727.64	16.0893
1730.68	14.4175
1733.71	13.9646
1736.74	13.57
1739.77	13.6416
1742.8	13.3899
1745.83	13.1284
1748.85	12.7205
1751.88	12.2059
1754.91	11.1546
1757.93	11.6786
1760.95	11.9207
1763.97	10.8799
1766.99	9.86462
1770.01	9.53246
1773.03	9.07315
1776.04	7.95673
1779.06	6.36679
1782.07	4.74978
1785.09	3.24121
1788.1	2.05808
1791.11	1.86087
1794.12	1.73542
1797.13	1.4308
1800.13	0.584568
1803.14	-0.644372
1806.15	-1.0213
1809.15	-0.92436
1812.15	-0.14282
1815.16	-0.257463
1818.15	0.227797
1821.16	0.459052
1824.15	1.43941
1827.15	1.92264
1830.15	1.88222
1833.14	2.96563
1836.14	2.34854
1839.13	3.52099
1842.12	4.62721
1845.11	5.27874
1848.1	4.78463
1851.09	4.15732
1854.08	3.93973
1857.06	2.52617
1860.05	3.48239
1863.03	4.96868
1866.01	4.31051
1869	4.20178
1871.98	4.34405
1874.96	5.01689
1877.93	4.76451
1880.91	4.6341
1882.47	3.95832
1885.46	4.26302
1888.44	3.6701
1891.43	4.27776
1894.42	4.39012
1897.4	3.69339
1900.39	4.09756
1903.37	4.24842
1906.35	4.48161
1909.33	4.09461
1912.31	3.64582
1915.29	3.89583
1918.26	3.68477
1921.24	3.58843
1924.21	4.2824
1927.19	4.08849
1930.16	3.95109
1933.13	3.26863
1936.1	3.30223
1939.07	3.50422
1942.04	4.52528
1945	4.94119
1947.97	5.40237
1950.93	5.9837
1953.9	6.39488
1956.86	8.01468
1959.82	9.02746
1962.78	9.56159
1965.74	8.36274
1968.7	7.97957
1971.65	7.70602
1974.61	8.79492
1977.57	7.60673
1980.52	6.13106
1983.47	5.91679
1986.42	7.23087
1989.37	7.07103
1992.32	7.10873
1995.27	6.05555
1998.22	5.10768
2001.17	3.8188
2004.11	3.00575
2007.05	2.41386
2010	2.7584
2012.94	2.95143
2015.88	3.62215
2018.82	3.90372
2021.76	5.23687
2024.7	5.70752
2027.63	6.3203
2030.57	6.87143
2033.5	6.42996
2036.44	6.89365
2039.37	5.90677
2042.3	7.0613
2045.23	7.47459
2048.16	7.97438
2051.08	7.6521
2054.01	8.81845
2056.94	9.43345
2059.86	9.59764
2062.79	10.1888
2065.71	11.7729
2068.63	12.0044
2071.55	12.0282
2074.47	13.3236
2077.39	14.3915
2080.31	16.8668
2083.22	17.6313
2086.13	20.2766
2089.05	22.8688
2091.96	24.2975
2094.87	26.8396
2097.78	30.1058
2100.69	31.2484
2103.6	32.3658
2106.51	33.4706
2109.42	33.2013
2112.32	33.6596
2115.23	35.164
2118.13	35.6639
2121.03	36.0976
2123.93	37.4544
2126.83	39.3986
2129.73	40.0064
2132.63	42.7998
2135.53	45.3175
2138.42	47.7693
2141.32	49.4846
2144.21	51.5975
2147.1	54.1721
2150	56.6418
2152.89	59.8555
2155.78	61.3516
2158.66	63.156
2161.55	65.2464
2164.44	66.539
2167.32	69.3594
2170.21	69.311
2173.09	69.983
2175.97	68.8367
2178.85	67.0297
2181.73	66.3134
2184.61	65.2451
2187.49	63.0694
2190.37	61.694
2193.24	60.1599
2196.12	58.5403
2198.99	56.6824
2201.87	55.9919
2204.74	54.6224
2207.61	53.4695
2210.48	50.6396
2213.35	47.7801
2216.21	44.1841
2219.08	42.5405
2221.95	39.9799
2224.81	39.3838
2227.67	36.4892
2230.54	34.2908
2233.4	33.1355
2236.26	31.5036
2239.11	30.7601
2241.97	29.6304
2244.83	27.3896
2247.69	23.9989
2250.54	23.6177
2253.4	21.7588
2256.25	19.7483
2259.1	19.6588
2261.95	18.4733
2264.8	17.3146
2267.65	16.9364
2270.5	17.7735
2273.34	16.9513
2276.19	15.2384
2279.03	13.5155
2281.88	11.4187
2284.72	10.3732
2287.56	9.67558
2290.4	8.54552
2293.24	7.21383
2296.08	6.92486
2298.92	6.68537
2301.76	7.6599
2304.59	8.3757
2307.43	9.3346
2310.26	10.6848
2313.09	11.3789
2315.92	11.8122
2318.75	12.7578
2321.58	13.5577
2324.41	13.3123
2327.24	14.5085
2330.06	14.326
2332.89	15.0024
2335.71	14.6136
2338.54	14.093
2341.36	13.5209
2344.18	11.5021
2347	9.34395
2349.82	7.43742
2352.64	5.63446
2355.45	3.20184
2358.27	1.995
2361.08	1.92277
2363.9	2.05154
2366.71	2.59287
2369.52	1.81239
2372.33	1.83322
2375.14	1.43289
2377.95	2.57165
2380.76	2.93037
2383.57	1.84826
2386.37	3.40899
2389.18	4.43058
2391.98	4.00042
2394.79	4.12297
2397.59	4.77914
2400.39	5.1155
2403.19	5.16505
2405.99	5.02723
2408.78	4.46736
2411.58	4.3542
2414.38	4.19288
2417.17	4.50543
2419.97	4.99579
2422.76	4.59927
2425.55	5.88114
2428.34	6.64527
2431.13	6.29836
2433.92	5.97148
2436.71	6.91062
2439.49	6.99194
2442.28	6.88104
2445.06	7.46274
2447.85	7.58854
2450.63	7.68065
2453.41	7.44638
2456.19	6.97564
2458.97	4.97971
2461.75	4.29968
2464.53	3.17121
2467.31	2.73121
2470.08	0.974231
2472.86	0.00843779
2475.63	0.256164
2478.4	0.536076
2481.17	0.604337
2483.94	1.34828
2486.72	0.697992
2489.48	1.92923
2492.25	2.64554
2495.02	2.27814
2497.79	1.42112
2500.55	2.27162
2503.31	3.6992
2506.08	3.90204
2508.84	4.06495
2511.6	4.94625
2514.36	5.27049
2517.12	4.75461
2519.88	5.10398
2522.63	4.60513
2525.39	4.39147
2528.14	5.03044
2530.9	5.46601
2533.65	5.13214
2536.4	3.85436
2539.15	4.42454
2541.9	4.86763
2544.65	5.19076
2547.4	4.67306
2550.15	4.1505
2552.89	3.70743
2555.64	3.35529
2558.38	3.3286
2561.12	2.84363
2563.87	2.77181
2566.61	1.38454
2569.35	2.37322
2572.09	3.13246
2574.83	3.65591
2577.56	4.55616
2580.3	4.82042
2583.04	5.34387
2585.77	6.63828
2588.5	7.39783
2591.23	7.70569
2593.97	7.38878
2596.7	7.09576
2599.43	6.72743
2602.15	6.152
2604.88	6.76964
2607.61	6.15607
2610.33	5.92149
2613.06	4.23574
2615.78	3.45382
2618.51	2.75522
2621.23	3.10808
2623.95	3.47158
2626.67	2.35417
2629.39	2.29423
2632.1	1.85501
2634.82	2.48385
2637.54	3.52544
2640.25	4.55194
2642.97	5.02515
2645.68	5.72872
2648.39	7.09319
2651.1	6.88058
2653.81	6.67908
2656.52	5.83063
2659.23	6.20522
2661.94	6.00762
2664.64	5.86156
2667.35	5.62432
2670.05	5.71199
2672.76	5.77187
2675.46	6.41493
2678.16	6.36676
2680.86	6.24168
2683.56	7.10399
2686.26	7.91924
2688.96	8.69151
2691.65	8.98047
2694.35	10.4893
2697.04	10.3216
2699.74	11.2449
2702.43	12.0197
2705.12	12.3463
2707.81	12.9379
2710.5	13.3477
2713.19	12.3796
2715.88	11.6771
2718.57	11.3738
2721.25	12.5568
2723.94	12.152
2726.62	12.3009
2729.3	12.6923
2731.99	12.4253
2734.67	12.1445
2737.35	12.5697
2740.03	13.2107
2742.71	13.0169
2745.38	13.0938
2748.06	12.9623
2750.74	11.9415
2753.41	12.3542
2756.09	12.124
2758.76	10.8715
2761.43	9.33154
2764.1	7.4041
2766.77	6.85107
2769.44	6.269
2772.11	4.60584
2774.77	3.78459
2777.44	2.68035
2780.11	2.34653
2782.77	2.42847
2785.43	2.29545
2788.1	1.50935
2790.76	0.606213
2793.42	0.703047
2796.08	0.425147
2798.74	0.219482
2801.4	0.0937671
2804.05	0.494998
2806.71	0.42366
2809.36	0.604503
2812.02	0.309156
2814.67	0.78074
2817.32	1.75651
2819.97	5.09225
2822.62	6.78413
2825.27	10.3448
2827.92	15.6486
2830.57	19.9887
2833.22	26.462
2835.86	32.3321
2838.51	38.8847
2841.15	47.5661
2843.79	54.8934
2846.43	63.9492
2849.08	72.491
2851.72	80.4885
2854.36	88.2797
2856.99	97.1448
2859.63	105.993
2862.27	113.969
2864.9	121.531
2867.54	129.574
2870.17	136.419
2872.8	142.178
2875.43	148.964
2878.07	157.079
2880.7	164.312
2883.32	170.365
2885.95	179.351
2888.58	187.285
2891.21	195.239
2893.83	203.916
2896.46	212.938
2899.08	223.236
2901.7	233.338
2904.32	245.23
2906.94	257.857
2909.56	270.62
2912.18	281.889
2914.8	295.097
2917.42	305.911
2920.03	315.95
2922.65	324.559
2925.26	329.75
2927.88	334.008
2930.49	335.219
2933.1	334.088
2935.71	331.436
2938.32	326.023
2940.93	320.184
2943.54	310.614
2946.14	300.43
2948.75	289.357
2951.35	277.346
2953.96	263.34
2956.56	250.655
2959.16	237.019
2961.77	224.862
2964.37	210.888
2966.96	199.763
2969.56	189.14
2972.16	177.487
2974.76	166.113
2977.35	156.415
2979.95	146.814
2982.54	136.266
2985.14	125.25
2987.73	114.291
2990.32	104.092
2992.91	93.0324
2995.5	83.1315
2998.09	73.5161
3000.68	65.1143
3003.26	57.3052
3005.85	50.8248
3008.43	43.3677
3011.02	37.9803
3013.6	32.2002
3016.19	26.938
3018.77	22.1538
3021.35	18.4248
3023.93	14.4383
3026.5	11.4504
3029.08	9.05166
3031.66	7.38969
3034.24	5.70849
3036.81	3.81212
3039.39	2.87945
3041.96	2.93748
3044.53	2.50251
3047.1	3.21691
3049.67	4.64438
3052.24	5.8852
3054.81	6.65648
3057.38	6.90778
3059.95	7.06005
3062.52	7.32133
3065.08	8.64364
3067.65	9.65966
3070.21	9.98999
3072.77	9.58769
3075.33	10.2674
3077.89	10.329
3080.45	10.9351
3083.01	10.5512
3085.57	10.2502
3088.13	10.1917
3090.68	10.8482
3093.24	11.5146
3095.79	12.4425
3098.35	13.2902
3100.9	15.5577
3103.45	16.9666
3106	19.1833
3108.55	21.7008
3111.1	25.1786
3113.65	26.7111
3116.2	29.4381
3118.75	30.7494
3121.29	32.3947
3123.84	34.6896
3126.38	36.947
3128.92	39.0848
3131.47	41.1981
3134.01	43.5722
3136.55	45.5578
3139.09	48.0507
3141.63	49.942
3144.17	51.2119
3146.7	53.3073
3149.24	55.9265