File: data/Raman/poly_smoothed/Mb_50_18_49_1x_45s_532 nm_x100_100%_600 gr_mm_01.txt
#Acq. time (s)=	45
#Accumulations=	2
#Range (cm-¹)=	200...3150
#Windows=	2
#Auto scanning=	Off
#Autofocus=	Off
#Macrospot=	Off
#AutoExposure=	Off
#Spike filter=	Multiple accum.
#Delay time (s)=	0
#Binning=	1
#Readout mode=	Signal
#DeNoise=	Off
#ICS correction=	On
#Dark correction=	Off
#Inst. Process=	Off
#Detector Gain=	Best Dynamic Range
#Detector ADC=	20 kHz
#Detector temperature (°C)=	-69.85
#Instrument=	LabRAM HR Evol
#Detector=	Synapse
#Objective=	x100
#Grating=	600 gr/mm
#ND Filter=	100%
#Laser (nm)=	532
#Hole=	100.021
#Range=	Auto
#Laser Pol.=	No
#Raman. Pol.=	No
#Laser Pol. (°)=	-0.0007625
#Raman Pol. (°)=	89.9995
#Collection=	Microscope
#StageXY=	Marzhauser
#StageZ=	Marzhauser
#X (µm)=	28479.4
#Y (µm)=	-2956.8
#Z (µm)=	1043.55
#Full time(mm:ss)=	3:19
#Project=
#Sample=
#Site=
#Title=	Mb_50_18_49_2x_45s_532 nm_x100_100%_600 gr_mm
#Remark=
#Date=	12.07.2022 14:51
#Acquired=	12.07.2022 14:51:23
#Base:Fit=	10.08.2022 10:49:18
#Base:Sub=	10.08.2022 10:49:30
#Filter:Polynom=	16.08.2022 10:14:59
#AxisType[0]=Intens
#AxisUnit[0]=Cnt
#AxisType[1]=Spectr
#AxisUnit[1]=1/cm
200.388	4.7397
204.019	12.3634
207.646	13.2386
211.274	13.7315
214.899	13.5745
218.524	12.7677
222.146	12.8507
225.766	11.743
229.388	13.2026
233.005	12.6717
236.621	12.6303
240.236	12.451
243.852	12.3489
247.464	12.0933
251.074	10.1511
254.683	10.475
258.291	9.84695
261.897	8.55105
265.504	7.75608
269.108	7.60983
272.71	6.76552
276.311	5.80135
279.91	5.3342
283.508	7.01695
287.105	6.00168
290.698	4.66342
294.291	6.24632
297.884	7.28298
301.475	7.77704
305.064	9.73267
308.652	12.1264
312.237	13.2729
315.822	14.0003
319.406	17.6813
322.987	19.2286
326.568	20.3063
330.148	21.1563
333.724	22.2977
337.301	23.0952
340.875	23.549
344.449	23.1897
348.02	23.4387
351.592	23.9018
355.16	25.0081
358.728	24.2339
362.294	24.6855
365.858	24.944
369.422	26.1456
372.983	28.6838
376.543	28.6856
380.102	30.0157
383.661	31.7375
387.216	32.1492
390.771	34.9248
394.324	36.4095
397.875	35.5112
401.425	35.2312
404.974	35.8796
408.524	33.8349
412.07	30.7644
415.614	29.0868
419.156	27.8137
422.698	26.0175
426.238	24.8566
429.777	23.104
433.315	21.6929
436.852	21.8521
440.387	21.7081
443.919	20.0818
447.451	18.2846
450.982	18.5949
454.512	16.654
458.038	16.343
461.565	16.8908
465.091	17.2248
468.613	20.791
472.136	22.4781
475.655	24.0866
479.176	26.0365
482.692	28.71
486.21	31.7671
489.724	33.4762
493.237	35.987
496.75	37.9334
500.26	41.5432
503.771	43.5623
507.279	45.1293
510.785	46.7433
514.289	48.2403
517.793	48.2508
521.297	48.9693
524.797	47.1121
528.297	44.7744
531.795	40.8355
535.291	37.8647
538.787	35.2856
542.281	30.4471
545.773	26.7396
549.264	22.4518
552.754	20.3512
556.243	16.08
559.73	13.8229
563.216	11.0171
566.701	8.59441
570.182	8.21971
573.664	7.63485
577.145	7.72808
580.624	8.44201
584.1	7.63593
587.577	6.0967
591.052	3.75156
594.524	3.58031
597.997	4.68523
601.466	5.639
604.936	6.89214
608.403	7.86564
611.87	9.62785
615.334	11.5255
618.799	12.5986
622.26	13.4686
625.72	13.7488
629.181	13.8659
632.638	13.4176
636.095	13.5472
639.551	13.6635
643.005	12.5939
646.457	13.2245
649.908	13.9806
653.357	15.0003
656.806	15.6105
660.253	17.4009
663.7	16.3324
667.145	14.3619
670.588	13.9914
674.027	13.5449
677.468	16.7047
680.907	19.4976
684.345	20.5537
687.781	21.9004
691.216	23.4877
694.65	23.6747
698.081	27.0129
701.512	29.0139
704.942	30.869
708.371	31.7312
711.796	33.8912
715.222	35.2094
718.645	35.6499
722.068	35.3221
725.49	35.1565
728.909	35.3808
732.329	37.3802
735.745	41.4381
739.16	46.6051
742.576	52.8263
745.988	55.2728
749.401	59.5942
752.811	66.851
756.22	72.7857
759.627	77.8068
763.035	82.8054
766.44	86.8393
769.843	91.2945
773.245	94.1797
776.646	96.5033
780.046	98.1191
783.444	100.713
786.841	100.397
790.237	100.075
793.631	97.5273
797.024	94.6505
800.416	92.1418
803.807	86.6689
807.196	83.4841
810.584	77.7592
813.971	75.8887
817.354	76.4703
820.739	76.2314
824.122	76.5458
827.503	74.7938
830.882	73.4443
834.261	73.052
837.637	72.1887
841.013	72.6101
844.389	70.9375
847.761	71.0988
851.131	70.081
854.503	70.7641
857.871	69.4666
861.24	67.7843
864.606	66.259
867.97	66.047
871.336	64.8797
874.698	62.3947
878.058	60.7432
881.418	58.4203
884.778	56.754
888.135	55.2671
891.49	52.6553
894.845	50.1945
898.198	50.268
901.55	48.9694
904.901	46.072
908.25	45.1668
911.598	42.6209
914.945	40.3297
918.291	38.0106
921.635	37.3525
924.978	36.3453
928.318	35.4163
931.659	33.1022
934.998	35.3495
938.336	34.6297
941.671	33.8002
945.007	33.6345
948.339	34.1113
951.672	35.6358
955.004	34.9396
958.333	35.1364
961.662	35.5492
964.989	37.4753
968.315	39.4539
971.639	39.2289
974.962	39.4835
978.285	40.9119
981.605	40.1185
984.924	40.5149
988.243	40.435
991.56	39.8804
994.875	41.1189
998.188	43.5561
1001.5	47.7033
1004.81	50.2167
1008.12	54.2182
1011.43	57.8371
1014.74	62.1452
1018.05	65.528
1021.35	65.8721
1024.65	68.205
1027.96	71.4791
1031.26	72.5456
1034.56	73.1752
1037.86	72.2241
1041.16	70.9444
1044.45	70.5855
1047.75	68.0557
1051.04	65.4776
1054.33	62.8336
1057.62	63.4325
1060.91	60.6426
1064.2	57.7913
1067.49	54.9691
1070.77	53.7038
1074.06	52.7582
1077.34	53.0789
1080.62	54.343
1083.91	54.0986
1087.18	53.7361
1090.46	55.1855
1093.74	57.8068
1097.02	57.623
1100.29	57.9287
1103.56	58.0707
1106.84	59.5172
1110.11	56.4144
1113.38	54.53
1116.64	51.8028
1119.91	48.2764
1123.18	45.3873
1126.44	41.4911
1129.7	38.2924
1132.97	38.4805
1136.23	34.7553
1139.49	30.4864
1142.74	25.5051
1146	22.1202
1149.26	18.2329
1152.51	14.4928
1155.76	11.391
1159.01	8.12716
1162.27	5.64552
1165.51	5.15664
1168.76	5.27917
1172.01	7.71597
1175.25	7.9863
1178.5	5.82997
1181.74	7.5871
1184.98	8.42326
1188.22	8.59715
1191.46	9.21491
1194.7	9.98495
1197.94	11.0226
1201.17	11.7381
1204.41	14.0487
1207.64	17.8117
1210.87	21.1621
1214.1	22.4271
1217.33	24.1483
1220.56	26.3548
1223.79	30.4103
1227.01	34.0505
1230.23	36.949
1233.46	39.8757
1236.68	44.6269
1239.9	48.8675
1243.12	52.2893
1246.34	56.3679
1249.55	59.4627
1252.77	62.4517
1255.98	64.4399
1259.2	69.2284
1262.41	73.1012
1265.62	75.8555
1268.83	80.3259
1272.03	84.3923
1275.24	87.4142
1278.45	91.1262
1281.65	94.3075
1284.85	97.1077
1288.06	99.5905
1291.26	101.441
1294.46	102.794
1297.66	102.367
1300.85	102.18
1304.05	102.899
1307.24	102.358
1310.43	101.578
1313.63	100.193
1316.82	99.5824
1320.01	95.8515
1323.2	92.9519
1326.38	88.8193
1329.57	86.2927
1332.76	82.0616
1335.94	78.4857
1339.12	75.5086
1342.3	72.1696
1345.48	68.4184
1348.66	65.064
1351.84	59.613
1355.01	56.7653
1358.19	51.82
1361.36	47.3527
1364.53	44.479
1367.71	41.7729
1370.88	38.2499
1374.04	33.388
1377.21	30.3646
1380.38	29.5776
1383.54	28.1476
1386.71	26.6494
1389.87	26.0154
1393.03	24.5956
1396.19	24.605
1399.35	24.0543
1402.51	24.2566
1405.67	26.1883
1408.82	29.8776
1411.98	35.2418
1415.13	38.9862
1418.28	44.6111
1421.43	52.4102
1424.58	61.7442
1427.73	70.6918
1430.88	79.5382
1434.02	88.0689
1437.17	95.0961
1440.31	99.178
1443.45	102.831
1446.6	105.603
1449.74	106.274
1452.87	104.701
1456.01	104.005
1459.15	102.878
1462.28	99.018
1465.42	95.2631
1468.55	89.7075
1471.68	83.6912
1474.81	78.0268
1477.94	71.8118
1481.07	66.732
1484.2	61.2291
1487.32	55.4411
1490.45	48.9467
1493.57	43.3631
1496.69	40.2694
1499.81	38.5025
1502.93	36.3022
1506.05	34.2958
1509.17	32.0413
1512.28	28.3257
1515.4	25.407
1518.51	22.6507
1521.63	20.3029
1524.74	19.6647
1527.85	17.5023
1530.96	17.9104
1534.06	19.1448
1537.17	21.2941
1540.28	24.1378
1543.38	27.2048
1546.48	30.307
1549.59	32.8805
1552.69	34.2605
1555.79	35.7043
1558.88	36.21
1561.98	35.1146
1565.08	37.5552
1568.17	40.9239
1571.27	44.4448
1574.36	49.1956
1577.45	54.878
1580.54	58.9335
1583.63	62.6266
1586.72	65.2602
1589.8	68.8747
1592.89	70.6193
1595.97	71.6019
1599.06	71.8515
1602.14	73.5327
1605.22	73.1069
1608.3	74.6179
1611.38	74.5858
1614.46	75.1009
1617.53	75.6727
1620.61	76.8507
1623.68	77.7325
1626.75	78.466
1629.82	80.8616
1632.9	82.9356
1635.96	85.5426
1639.03	92.7601
1642.1	99.0772
1645.16	103.545
1648.23	108.702
1651.29	113.209
1654.36	114.941
1657.42	117.162
1660.48	117.799
1663.53	116.793
1666.59	113.958
1669.65	109.883
1672.7	105.039
1675.76	99.4279
1678.81	93.4344
1681.86	85.0038
1684.91	77.1542
1687.96	68.2925
1691.01	61.4485
1694.06	54.4556
1697.11	48.2109
1700.15	42.6644
1703.2	36.9139
1706.24	33.5062
1709.28	29.6201
1712.32	26.414
1715.36	23.1515
1718.4	20.5867
1721.43	18.6123
1724.47	17.0806
1727.5	15.0827
1730.54	14.269
1733.57	14.1698
1736.6	12.7235
1739.63	11.1402
1742.66	10.38
1745.69	9.08135
1748.72	8.43166
1751.74	7.04735
1754.77	5.37548
1757.79	3.87037
1760.81	3.40423
1763.83	3.13287
1766.85	3.42497
1769.87	3.16698
1772.89	4.68102
1775.91	4.89221
1778.92	4.95142
1781.94	4.82942
1784.95	3.64755
1787.96	3.30258
1790.97	4.15028
1793.98	5.03341
1796.99	4.42731
1800	4.77931
1803	5.38136
1806.01	5.08266
1809.01	5.30838
1812.02	5.77316
1815.02	6.28856
1818.02	6.11653
1821.02	5.53181
1824.02	4.45653
1827.01	4.10427
1830.01	4.52556
1833	4.95885
1836	5.5716
1838.99	6.26413
1841.98	5.79081
1844.97	6.19939
1847.96	6.39414
1850.95	6.01089
1853.94	5.12072
1856.92	4.85281
1859.91	4.57595
1862.89	3.68693
1865.88	3.35738
1868.86	3.0988
1871.84	3.05252
1874.82	3.5578
1877.8	3.41792
1880.77	3.95365
1882.51	5.08347
1885.5	5.49451
1888.48	5.89496
1891.47	5.85912
1894.46	5.72295
1897.44	6.59699
1900.42	5.98349
1903.41	6.24882
1906.39	6.92678
1909.37	7.67188
1912.35	7.98559
1915.32	7.46512
1918.3	6.59196
1921.28	6.57168
1924.25	5.07887
1927.22	4.03074
1930.2	3.50571
1933.17	1.8176
1936.14	1.37642
1939.11	0.939749
1942.08	0.687075
1945.04	0.333935
1948.01	-0.198099
1950.97	0.160014
1953.94	1.44547
1956.9	2.41403
1959.86	1.95476
1962.82	2.68747
1965.78	3.51836
1968.74	4.05437
1971.69	4.37443
1974.65	5.19433
1977.61	7.59277
1980.56	8.07522
1983.51	7.79832
1986.46	8.61506
1989.41	8.91643
1992.36	8.62298
1995.31	8.37027
1998.26	8.02534
2001.2	8.14415
2004.15	7.55625
2007.09	7.0109
2010.04	6.51025
2012.98	6.47316
2015.92	6.64201
2018.86	6.65657
2021.8	7.23772
2024.74	8.34515
2027.67	8.99667
2030.61	8.68008
2033.54	8.8268
2036.47	10.6685
2039.41	12.7908
2042.34	14.772
2045.27	16.805
2048.2	18.9958
2051.12	20.8109
2054.05	22.7739
2056.98	24.6124
2059.9	27.6462
2062.82	29.5774
2065.75	31.3875
2068.67	33.1327
2071.59	34.8388
2074.51	37.4591
2077.43	40.0689
2080.34	42.2675
2083.26	46.4416
2086.17	50.4342
2089.09	54.4928
2092	59.067
2094.91	63.4467
2097.82	69.1478
2100.73	73.3658
2103.64	80.162
2106.55	86.6281
2109.46	92.7167
2112.36	100.674
2115.27	107.82
2118.17	114.371
2121.07	121.445
2123.97	128.403
2126.87	136.177
2129.77	144.32
2132.67	152.7
2135.57	160.632
2138.46	168.147
2141.36	173.923
2144.25	181.409
2147.14	187.287
2150.03	193.368
2152.92	198.955
2155.81	204.54
2158.7	208.07
2161.59	210.004
2164.48	212.315
2167.36	212.631
2170.25	211.341
2173.13	208.298
2176.01	204.785
2178.89	200.803
2181.77	195.652
2184.65	189.947
2187.53	183.395
2190.41	176.544
2193.28	169.321
2196.16	163.498
2199.03	157.862
2201.9	151.656
2204.78	144.555
2207.65	138.133
2210.51	131.911
2213.38	125.63
2216.25	118.845
2219.12	113.076
2221.98	107.55
2224.85	101.918
2227.71	96.1682
2230.57	91.0712
2233.43	85.6123
2236.29	79.1958
2239.15	73.2168
2242.01	66.5979
2244.87	61.2744
2247.73	57.0747
2250.58	51.6798
2253.43	47.8995
2256.29	43.9685
2259.14	40.7464
2261.99	37.279
2264.84	35.4018
2267.69	33.5889
2270.54	31.6709
2273.38	29.7397
2276.23	28.4231
2279.07	27.5741
2281.92	25.9262
2284.76	24.1871
2287.6	20.8387
2290.44	18.7573
2293.28	15.5492
2296.12	14.8665
2298.96	14.47
2301.79	14.1901
2304.63	12.3912
2307.46	12.0292
2310.3	11.1514
2313.13	10.3294
2315.96	10.6961
2318.79	10.4865
2321.62	9.99134
2324.45	10.1273
2327.27	10.3346
2330.1	9.06698
2332.93	8.76522
2335.75	9.02634
2338.57	8.06844
2341.4	7.4714
2344.22	6.8189
2347.04	6.55778
2349.86	5.39455
2352.67	3.15132
2355.49	1.71896
2358.31	0.495084
2361.12	0.447976
2363.94	1.19304
2366.75	1.41425
2369.56	1.40422
2372.37	0.479537
2375.18	1.30237
2377.99	1.28752
2380.8	2.20767
2383.61	2.30266
2386.41	3.36284
2389.22	3.52329
2392.02	4.02402
2394.82	4.32141
2397.63	3.95469
2400.43	4.86717
2403.23	5.22634
2406.02	4.96751
2408.82	4.873
2411.62	5.28819
2414.41	5.16599
2417.21	4.92342
2420	5.21892
2422.79	5.25813
2425.59	5.84523
2428.38	5.54202
2431.17	5.32394
2433.96	4.60421
2436.74	4.6595
2439.53	5.56862
2442.32	5.04253
2445.1	4.76533
2447.88	5.33259
2450.67	5.45623
2453.45	6.44428
2456.23	5.66941
2459.01	5.86906
2461.79	5.64668
2464.57	5.9056
2467.34	5.8807
2470.12	6.49074
2472.89	6.21712
2475.67	5.76458
2478.44	5.26318
2481.21	4.72998
2483.98	4.40191
2486.75	4.01762
2489.52	3.75367
2492.29	3.37232
2495.06	3.07493
2497.82	3.3708
2500.59	2.21854
2503.35	1.64879
2506.11	0.66179
2508.88	-0.918924
2511.63	-1.78072
2514.39	-1.61984
2517.15	-0.581198
2519.91	-1.17792
2522.67	-1.9648
2525.42	-1.94103
2528.18	-1.52383
2530.93	-0.896681
2533.69	-0.728026
2536.44	0.682213
2539.19	1.36132
2541.94	1.74008
2544.69	2.03576
2547.44	3.42217
2550.18	4.46208
2552.93	5.3607
2555.68	6.93564
2558.42	7.50837
2561.16	8.15233
2563.9	8.96537
2566.64	9.08308
2569.38	8.32854
2572.12	8.47168
2574.86	8.26581
2577.6	8.32112
2580.34	7.82244
2583.07	7.7029
2585.81	7.26745
2588.54	6.08915
2591.27	6.22373
2594	6.7534
2596.73	5.81792
2599.46	4.97053
2602.19	4.77469
2604.92	4.72619
2607.64	4.7129
2610.37	5.03569
2613.09	4.98877
2615.82	5.21128
2618.54	4.64203
2621.26	5.17715
2623.98	5.50172
2626.7	5.37633
2629.42	4.95103
2632.14	4.90066
2634.86	4.11074
2637.57	4.45369
2640.29	3.99138
2643	3.61928
2645.72	3.79235
2648.43	4.00412
2651.14	5.02908
2653.85	4.98059
2656.56	4.33302
2659.27	4.66822
2661.97	5.1167
2664.68	5.64003
2667.38	6.22454
2670.09	7.73361
2672.79	8.51691
2675.49	8.57327
2678.2	9.44084
2680.89	9.35899
2683.59	10.028
2686.29	10.0768
2688.99	10.7309
2691.69	11.0549
2694.38	10.6632
2697.08	10.5988
2699.77	10.3865
2702.46	10.6871
2705.16	12.036
2707.85	11.2841
2710.54	11.718
2713.23	12.014
2715.92	12.6118
2718.6	12.2475
2721.29	12.446
2723.97	11.4046
2726.66	12.796
2729.34	12.7779
2732.02	12.3725
2734.7	11.3883
2737.39	10.9558
2740.06	9.38589
2742.74	8.83673
2745.42	7.46211
2748.1	6.2547
2750.77	5.98186
2753.45	4.93058
2756.12	3.91093
2758.79	3.37552
2761.47	1.99486
2764.14	1.48154
2766.81	0.901871
2769.48	0.247052
2772.14	-0.389832
2774.81	-1.07139
2777.48	-0.289795
2780.14	0.176565
2782.81	-0.243916
2785.47	-0.429516
2788.13	-0.587135
2790.79	0.0436252
2793.46	-0.271911
2796.11	-0.294963
2798.77	-0.615924
2801.43	-0.762539
2804.09	-1.24334
2806.74	-1.62458
2809.4	-2.07564
2812.05	-1.96838
2814.71	-1.13564
2817.36	1.49008
2820.01	5.97944
2822.66	12.8161
2825.31	20.9792
2827.96	29.7006
2830.61	39.8594
2833.25	51.0438
2835.9	63.1918
2838.54	75.081
2841.18	87.9983
2843.83	100.95
2846.47	114.479
2849.11	129.106
2851.75	143.604
2854.39	158.75
2857.03	171.728
2859.67	183.626
2862.3	195.157
2864.94	204.665
2867.57	213.106
2870.21	219.61
2872.84	224.313
2875.47	228.819
2878.1	234.437
2880.73	240.791
2883.36	247.46
2885.99	254.921
2888.61	262.723
2891.24	268.977
2893.87	275.92
2896.49	284.024
2899.11	292.597
2901.74	302.935
2904.36	314.268
2906.98	327.199
2909.6	341.87
2912.22	357.683
2914.83	373.053
2917.45	386.75
2920.07	398.154
2922.68	407.553
2925.3	416.223
2927.91	420.692
2930.52	422.001
2933.13	419.616
2935.74	415.65
2938.35	408.001
2940.96	399.091
2943.57	386.539
2946.18	371.757
2948.78	355.591
2951.39	338.196
2953.99	319.499
2956.6	299.911
2959.2	280.694
2961.8	261.781
2964.4	243.819
2967	226.746
2969.6	210.416
2972.2	195.798
2974.79	181.424
2977.39	167.297
2979.98	152.993
2982.58	138.664
2985.17	124.984
2987.76	112.356
2990.36	100.124
2992.95	87.3434
2995.54	76.6828
2998.12	66.4622
3000.71	56.6363
3003.3	47.9169
3005.88	39.4962
3008.47	32.1649
3011.05	25.7398
3013.64	19.3887
3016.22	14.7639
3018.8	10.8316
3021.38	7.21407
3023.96	5.44632
3026.54	3.49559
3029.12	2.21567
3031.69	2.02267
3034.27	2.7599
3036.85	3.45991
3039.42	4.81512
3041.99	7.54293
3044.57	9.70902
3047.14	11.5807
3049.71	13.7245
3052.28	14.8509
3054.85	16.7433
3057.42	17.6065
3059.98	17.8089
3062.55	16.7311
3065.11	16.7473
3067.68	15.0778
3070.24	13.4717
3072.8	11.6858
3075.37	9.77458
3077.93	7.58325
3080.49	6.29148
3083.05	4.40269
3085.61	1.9319
3088.16	0.132436
3090.72	-1.3157
3093.27	-2.49375
3095.83	-2.34783
3098.38	-1.01825
3100.94	-0.755081
3103.49	1.02584
3106.04	2.43429
3108.59	3.09964
3111.14	4.80496
3113.69	6.78519
3116.23	8.475
3118.78	10.4625
3121.33	11.9955
3123.87	13.8817
3126.42	16.3053
3128.96	18.6721
3131.5	20.551
3134.04	23.1521
3136.58	26.0431
3139.12	28.0016
3141.66	29.8985
3144.2	32.1576
3146.74	34.8709
3149.27	37.3514