File: data/Raman/poly_smoothed/Mb_50_18_40_1x_45s_532 nm_x100_100%_600 gr_mm_01.txt
#Acq. time (s)=	45
#Accumulations=	2
#Range (cm-¹)=	200...3150
#Windows=	2
#Auto scanning=	Off
#Autofocus=	Off
#Macrospot=	Off
#AutoExposure=	Off
#Spike filter=	Multiple accum.
#Delay time (s)=	0
#Binning=	1
#Readout mode=	Signal
#DeNoise=	Off
#ICS correction=	On
#Dark correction=	Off
#Inst. Process=	Off
#Detector Gain=	Best Dynamic Range
#Detector ADC=	20 kHz
#Detector temperature (°C)=	-69.85
#Instrument=	LabRAM HR Evol
#Detector=	Synapse
#Objective=	x100
#Grating=	600 gr/mm
#ND Filter=	100%
#Laser (nm)=	532
#Hole=	100.021
#Range=	Auto
#Laser Pol.=	No
#Raman. Pol.=	No
#Laser Pol. (°)=	-0.0007625
#Raman Pol. (°)=	89.9995
#Collection=	Microscope
#StageXY=	Marzhauser
#StageZ=	Marzhauser
#X (µm)=	28236.8
#Y (µm)=	-3207.7
#Z (µm)=	1040.8
#Full time(mm:ss)=	3:19
#Project=
#Sample=
#Site=
#Title=	Mb_50_18_40_2x_45s_532 nm_x100_100%_600 gr_mm
#Remark=
#Date=	12.07.2022 14:03
#Acquired=	12.07.2022 14:03:34
#Base:Fit=	10.08.2022 10:49:18
#Base:Sub=	10.08.2022 10:49:30
#Filter:Polynom=	16.08.2022 10:14:59
#AxisType[0]=Intens
#AxisUnit[0]=Cnt
#AxisType[1]=Spectr
#AxisUnit[1]=1/cm
200.388	16.6932
204.019	17.8311
207.646	18.8107
211.274	18.0431
214.899	15.9344
218.524	14.7729
222.146	12.3297
225.766	10.9887
229.388	10.5546
233.005	11.1309
236.621	9.89889
240.236	8.01841
243.852	7.40691
247.464	7.75232
251.074	8.68982
254.683	8.01157
258.291	8.64103
261.897	10.8594
265.504	9.81083
269.108	9.1293
272.71	9.84082
276.311	8.29922
279.91	8.45244
283.508	9.43427
287.105	10.0962
290.698	10.7993
294.291	12.8746
297.884	14.3996
301.475	16.0829
305.064	18.8902
308.652	20.6475
312.237	21.3829
315.822	23.1149
319.406	24.218
322.987	23.3781
326.568	25.1509
330.148	25.1263
333.724	24.3661
337.301	23.6395
340.875	24.6252
344.449	23.1561
348.02	25.8513
351.592	28.4146
355.16	30.9079
358.728	32.7438
362.294	36.4872
365.858	40.1412
369.422	45.185
372.983	48.2574
376.543	52.1792
380.102	56.4402
383.661	58.852
387.216	59.3985
390.771	59.3224
394.324	57.2851
397.875	51.9149
401.425	48.3261
404.974	44.613
408.524	38.4817
412.07	30.8906
415.614	24.686
419.156	16.711
422.698	11.6553
426.238	8.02364
429.777	4.04662
433.315	1.5789
436.852	4.09591
440.387	2.06126
443.919	0.79507
447.451	2.2931
450.982	3.77957
454.512	5.65083
458.038	7.41238
461.565	7.59236
465.091	8.84351
468.613	9.95884
472.136	9.58561
475.655	11.5907
479.176	13.9841
482.692	17.557
486.21	22.1088
489.724	27.0783
493.237	30.9591
496.75	34.0535
500.26	39.6378
503.771	45.4006
507.279	49.2601
510.785	51.0813
514.289	51.3445
517.793	53.2508
521.297	54.6388
524.797	54.0113
528.297	54.3713
531.795	52.168
535.291	49.6272
538.787	45.254
542.281	39.4523
545.773	33.3247
549.264	27.2659
552.754	21.652
556.243	16.3893
559.73	13.1589
563.216	10.2106
566.701	9.68225
570.182	8.75062
573.664	7.96685
577.145	7.44433
580.624	6.6788
584.1	10.0877
587.577	8.76861
591.052	7.64393
594.524	8.08429
597.997	8.85382
601.466	10.5684
604.936	11.7126
608.403	12.8532
611.87	13.6317
615.334	12.8719
618.799	12.0602
622.26	11.3728
625.72	9.98162
629.181	9.71641
632.638	7.57945
636.095	8.12538
639.551	6.26855
643.005	5.51103
646.457	4.27734
649.908	3.77071
653.357	3.97058
656.806	4.72078
660.253	6.42094
663.7	5.64727
667.145	5.52253
670.588	7.23074
674.027	7.24264
677.468	9.55471
680.907	13.2488
684.345	16.538
687.781	18.1692
691.216	20.5451
694.65	23.2945
698.081	24.6013
701.512	26.8921
704.942	29.384
708.371	29.9974
711.796	30.9944
715.222	32.8599
718.645	33.7123
722.068	33.9567
725.49	32.9922
728.909	34.294
732.329	36.6254
735.745	40.6583
739.16	47.3919
742.576	55.0277
745.988	62.0398
749.401	71.8495
752.811	81.3071
756.22	90.5959
759.627	96.8477
763.035	103.091
766.44	105.874
769.843	109.608
773.245	111.666
776.646	112.478
780.046	112.891
783.444	111.034
786.841	108.726
790.237	104.692
793.631	100.924
797.024	96.1248
800.416	91.2809
803.807	84.7476
807.196	79.4005
810.584	76.4881
813.971	74.1299
817.354	72.6534
820.739	74.7289
824.122	73.4116
827.503	73.4955
830.882	73.3839
834.261	72.8105
837.637	70.7419
841.013	69.7717
844.389	66.9042
847.761	62.3504
851.131	59.7797
854.503	56.3709
857.871	52.5069
861.24	50.7651
864.606	49.7268
867.97	47.8558
871.336	47.6614
874.698	46.0627
878.058	45.9096
881.418	44.1609
884.778	44.5622
888.135	42.7594
891.49	44.0715
894.845	43.2413
898.198	42.759
901.55	41.2276
904.901	39.5287
908.25	37.9047
911.598	38.0478
914.945	38.2498
918.291	37.8725
921.635	36.919
924.978	36.6082
928.318	33.3191
931.659	30.6594
934.998	29.5798
938.336	28.0382
941.671	28.3553
945.007	29.0674
948.339	28.8766
951.672	28.4037
955.004	28.5157
958.333	26.5969
961.662	24.5967
964.989	24.0307
968.315	23.2333
971.639	24.0378
974.962	24.2162
978.285	22.4771
981.605	19.7236
984.924	16.4409
988.243	14.9483
991.56	14.4786
994.875	17.4056
998.188	21.938
1001.5	25.3224
1004.81	30.7425
1008.12	35.9659
1011.43	41.1935
1014.74	47.3802
1018.05	54.3275
1021.35	59.6827
1024.65	63.7813
1027.96	66.4417
1031.26	69.6348
1034.56	70.3213
1037.86	68.8284
1041.16	67.2779
1044.45	65.7964
1047.75	63.5996
1051.04	60.1599
1054.33	56.714
1057.62	51.8397
1060.91	46.753
1064.2	42.8849
1067.49	41.1655
1070.77	38.6162
1074.06	39.3098
1077.34	42.0933
1080.62	42.7272
1083.91	41.7857
1087.18	42.2265
1090.46	42.6751
1093.74	43.0763
1097.02	43.6986
1100.29	44.6993
1103.56	42.0992
1106.84	41.4431
1110.11	38.6168
1113.38	36.0887
1116.64	32.7144
1119.91	28.6728
1123.18	26.061
1126.44	24.2404
1129.7	19.903
1132.97	18.7867
1136.23	18.6837
1139.49	18.5655
1142.74	17.0019
1146	15.4219
1149.26	13.1015
1152.51	10.6187
1155.76	9.06717
1159.01	7.7331
1162.27	5.66354
1165.51	5.73828
1168.76	7.5961
1172.01	8.87623
1175.25	10.323
1178.5	11.5766
1181.74	12.2437
1184.98	11.5448
1188.22	13.052
1191.46	13.748
1194.7	14.5359
1197.94	15.2496
1201.17	16.3077
1204.41	19.4691
1207.64	20.1569
1210.87	22.4743
1214.1	24.4744
1217.33	28.072
1220.56	28.2154
1223.79	28.0641
1227.01	28.6775
1230.23	30.4921
1233.46	32.2386
1236.68	33.7165
1239.9	35.4453
1243.12	37.3344
1246.34	39.3698
1249.55	40.8577
1252.77	43.1084
1255.98	43.4948
1259.2	45.4098
1262.41	48.375
1265.62	49.7257
1268.83	53.53
1272.03	57.6227
1275.24	59.5805
1278.45	64.138
1281.65	67.6771
1284.85	70.3493
1288.06	70.4263
1291.26	72.3306
1294.46	72.6527
1297.66	74.9279
1300.85	74.2524
1304.05	73.126
1307.24	73.725
1310.43	74.1479
1313.63	72.5421
1316.82	71.8099
1320.01	71.7152
1323.2	71.6302
1326.38	70.5542
1329.57	69.1918
1332.76	68.7104
1335.94	66.6683
1339.12	64.3148
1342.3	62.9995
1345.48	60.6423
1348.66	59.6522
1351.84	56.4252
1355.01	53.4564
1358.19	50.2961
1361.36	47.1914
1364.53	43.5083
1367.71	40.582
1370.88	36.9787
1374.04	35.2367
1377.21	32.3353
1380.38	30.1397
1383.54	27.7677
1386.71	26.1806
1389.87	23.9796
1393.03	21.9475
1396.19	23.0711
1399.35	21.6724
1402.51	22.7017
1405.67	26.908
1408.82	30.1777
1411.98	33.9678
1415.13	38.1241
1418.28	42.9966
1421.43	50.277
1424.58	58.388
1427.73	66.597
1430.88	74.4173
1434.02	82.8577
1437.17	88.6087
1440.31	92.8847
1443.45	96.5107
1446.6	99.3723
1449.74	102.064
1452.87	102.272
1456.01	102.322
1459.15	101.538
1462.28	100.708
1465.42	98.96
1468.55	97.1049
1471.68	94.1719
1474.81	90.9448
1477.94	87.4307
1481.07	83.5621
1484.2	79.1782
1487.32	72.9824
1490.45	67.6773
1493.57	63.8919
1496.69	58.7309
1499.81	55.3439
1502.93	50.5436
1506.05	46.0503
1509.17	39.2525
1512.28	32.7871
1515.4	25.27
1518.51	20.0767
1521.63	16.621
1524.74	13.6641
1527.85	10.8806
1530.96	10.8702
1534.06	12.7361
1537.17	13.4132
1540.28	15.1372
1543.38	16.9854
1546.48	18.9566
1549.59	18.0205
1552.69	20.4447
1555.79	19.8108
1558.88	21.1896
1561.98	23.2022
1565.08	25.0052
1568.17	28.6417
1571.27	32.5806
1574.36	35.6444
1577.45	39.5883
1580.54	42.8945
1583.63	46.8336
1586.72	48.6171
1589.8	52.0673
1592.89	54.3175
1595.97	55.3818
1599.06	56.0201
1602.14	56.2353
1605.22	57.593
1608.3	59.3629
1611.38	59.4731
1614.46	60.5713
1617.53	60.6996
1620.61	60.8429
1623.68	59.344
1626.75	59.6272
1629.82	60.4151
1632.9	60.5882
1635.96	62.4492
1639.03	64.4508
1642.1	66.3343
1645.16	67.8571
1648.23	69.7704
1651.29	70.7318
1654.36	71.878
1657.42	71.2735
1660.48	68.3495
1663.53	65.7444
1666.59	61.463
1669.65	56.469
1672.7	52.911
1675.76	50.0779
1678.81	45.0672
1681.86	40.8002
1684.91	36.6449
1687.96	31.8666
1691.01	27.9512
1694.06	22.6358
1697.11	19.5791
1700.15	16.9933
1703.2	15.7698
1706.24	14.6193
1709.28	12.8479
1712.32	11.4564
1715.36	11.8869
1718.4	11.2316
1721.43	11.0665
1724.47	10.1019
1727.5	9.44149
1730.54	8.35211
1733.57	6.56795
1736.6	6.10324
1739.63	6.22416
1742.66	7.92494
1745.69	7.10018
1748.72	5.99324
1751.74	4.81215
1754.77	2.80295
1757.79	3.33925
1760.81	3.23076
1763.83	2.44629
1766.85	2.43872
1769.87	2.29757
1772.89	3.51136
1775.91	3.33309
1778.92	2.78777
1781.94	2.69467
1784.95	3.54355
1787.96	3.8652
1790.97	3.50773
1793.98	2.35574
1796.99	2.21404
1800	2.07209
1803	1.54121
1806.01	3.1358
1809.01	3.1197
1812.02	2.79774
1815.02	2.52959
1818.02	1.63515
1821.02	0.746917
1824.02	0.120469
1827.01	0.175783
1830.01	0.587068
1833	0.904499
1836	1.07239
1838.99	2.35099
1841.98	2.52607
1844.97	3.67781
1847.96	4.76172
1850.95	5.41512
1853.94	5.30941
1856.92	4.9188
1859.91	6.07915
1862.89	5.53393
1865.88	6.67628
1868.86	7.66927
1871.84	7.64487
1874.82	8.34853
1877.8	9.23648
1880.77	9.77458
1882.51	9.62712
1885.5	9.44612
1888.48	8.62864
1891.47	9.11116
1894.46	8.59372
1897.44	9.21242
1900.42	10.1929
1903.41	10.6581
1906.39	10.5589
1909.37	10.3076
1912.35	10.141
1915.32	9.9483
1918.3	10.2313
1921.28	10.0056
1924.25	9.61952
1927.22	8.82699
1930.2	8.4718
1933.17	8.52705
1936.14	7.69758
1939.11	7.96901
1942.08	6.98071
1945.04	7.14779
1948.01	7.73939
1950.97	8.0249
1953.94	7.06804
1956.9	6.15226
1959.86	5.07215
1962.82	5.35571
1965.78	6.03919
1968.74	6.57836
1971.69	7.15104
1974.65	6.90301
1977.61	6.37315
1980.56	7.00846
1983.51	6.73042
1986.46	6.60539
1989.41	6.46317
1992.36	7.49048
1995.31	8.04566
1998.26	8.70082
2001.2	9.60057
2004.15	9.1548
2007.09	9.95841
2010.04	10.3861
2012.98	10.4674
2015.92	10.6515
2018.86	12.1657
2021.8	13.051
2024.74	13.9661
2027.67	15.3098
2030.61	15.9886
2033.54	17.0898
2036.47	18.8342
2039.41	18.6917
2042.34	19.6633
2045.27	20.1152
2048.2	20.7133
2051.12	20.2131
2054.05	20.3834
2056.98	20.0256
2059.9	19.999
2062.82	21.9538
2065.75	22.4646
2068.67	23.3552
2071.59	25.0178
2074.51	25.5772
2077.43	25.8138
2080.34	27.4656
2083.26	29.2913
2086.17	30.2887
2089.09	33.1097
2092	35.8569
2094.91	38.4285
2097.82	40.3675
2100.73	43.5391
2103.64	47.202
2106.55	49.6501
2109.46	51.8877
2112.36	54.2211
2115.27	59.5387
2118.17	65.1465
2121.07	69.0878
2123.97	71.9747
2126.87	77.2698
2129.77	81.8511
2132.67	87.5312
2135.57	92.3737
2138.46	95.4971
2141.36	99.6615
2144.25	103.884
2147.14	108.001
2150.03	110.235
2152.92	112.977
2155.81	115.15
2158.7	117.257
2161.59	118.613
2164.48	119.53
2167.36	118.702
2170.25	117.83
2173.13	117.037
2176.01	114.62
2178.89	111.988
2181.77	109.968
2184.65	108.258
2187.53	106.602
2190.41	102.474
2193.28	98.751
2196.16	95.4156
2199.03	92.6912
2201.9	88.167
2204.78	85.3984
2207.65	80.9357
2210.51	76.4225
2213.38	72.934
2216.25	68.9957
2219.12	64.3916
2221.98	62.0672
2224.85	58.5682
2227.71	55.3181
2230.57	51.5665
2233.43	49.0731
2236.29	45.7561
2239.15	43.2638
2242.01	40.9753
2244.87	38.3843
2247.73	36.7782
2250.58	34.9975
2253.43	33.2769
2256.29	30.6873
2259.14	30.3204
2261.99	28.5316
2264.84	27.9955
2267.69	26.7034
2270.54	24.5136
2273.38	23.3166
2276.23	21.5222
2279.07	19.3691
2281.92	16.9581
2284.76	16.4171
2287.6	15.8745
2290.44	15.2685
2293.28	13.7096
2296.12	12.8526
2298.96	13.8172
2301.79	14.1176
2304.63	14.0394
2307.46	13.9138
2310.3	13.0102
2313.13	12.3919
2315.96	11.8339
2318.79	11.377
2321.62	9.97301
2324.45	10.2987
2327.27	9.98263
2330.1	9.69428
2332.93	9.67421
2335.75	9.44824
2338.57	8.10952
2341.4	7.90372
2344.22	7.3405
2347.04	8.24213
2349.86	7.43898
2352.67	7.42463
2355.49	7.52678
2358.31	6.81471
2361.12	6.63874
2363.94	6.81629
2366.75	7.46314
2369.56	7.28004
2372.37	6.28236
2375.18	5.40827
2377.99	4.27155
2380.8	3.90815
2383.61	3.34956
2386.41	2.19753
2389.22	1.66891
2392.02	1.65225
2394.82	1.89726
2397.63	0.431553
2400.43	0.228659
2403.23	-0.175098
2406.02	-0.790147
2408.82	-0.785685
2411.62	0.154658
2414.41	-0.0893448
2417.21	-0.0759213
2420	-0.586867
2422.79	-0.0762373
2425.59	-0.285752
2428.38	0.0104805
2431.17	0.216101
2433.96	0.821824
2436.74	0.999821
2439.53	0.694043
2442.32	1.71939
2445.1	1.85866
2447.88	2.80739
2450.67	2.71721
2453.45	3.48278
2456.23	3.56893
2459.01	3.90586
2461.79	3.25862
2464.57	3.68077
2467.34	3.39808
2470.12	4.05092
2472.89	4.93497
2475.67	5.92765
2478.44	5.88142
2481.21	5.51591
2483.98	5.45404
2486.75	5.68006
2489.52	5.65047
2492.29	4.99223
2495.06	6.04605
2497.82	5.99519
2500.59	5.53837
2503.35	5.9175
2506.11	4.52333
2508.88	4.41936
2511.63	4.31941
2514.39	4.11879
2517.15	4.10973
2519.91	4.23296
2522.67	2.15007
2525.42	2.54728
2528.18	3.01786
2530.93	2.43087
2533.69	2.43777
2536.44	2.1953
2539.19	2.43783
2541.94	2.14798
2544.69	2.69601
2547.44	1.70361
2550.18	2.15038
2552.93	2.1773
2555.68	3.32278
2558.42	4.32207
2561.16	6.14228
2563.9	7.08508
2566.64	7.14878
2569.38	6.92726
2572.12	7.46894
2574.86	6.78447
2577.6	6.79724
2580.34	7.29065
2583.07	7.67134
2585.81	7.61676
2588.54	6.7937
2591.27	8.01239
2594	8.07626
2596.73	7.38595
2599.46	6.556
2602.19	5.64245
2604.92	5.41071
2607.64	5.6792
2610.37	5.43722
2613.09	6.28693
2615.82	5.7971
2618.54	5.86143
2621.26	6.16844
2623.98	6.46179
2626.7	6.58994
2629.42	5.92522
2632.14	4.14721
2634.86	3.29069
2637.57	2.18112
2640.29	2.66588
2643	1.82953
2645.72	2.16768
2648.43	3.16357
2651.14	3.42886
2653.85	2.96182
2656.56	3.17672
2659.27	3.20039
2661.97	3.11874
2664.68	3.88362
2667.38	4.12522
2670.09	4.8086
2672.79	5.59623
2675.49	6.2731
2678.2	7.06637
2680.89	6.74909
2683.59	6.03488
2686.29	6.24811
2688.99	6.69387
2691.69	6.06248
2694.38	6.91025
2697.08	7.27293
2699.77	7.9196
2702.46	9.49304
2705.16	10.1639
2707.85	11.468
2710.54	12.3023
2713.23	12.6227
2715.92	12.5971
2718.6	12.3587
2721.29	11.9653
2723.97	12.0764
2726.66	13.2802
2729.34	12.6702
2732.02	11.8947
2734.7	11.5443
2737.39	10.5365
2740.06	8.70633
2742.74	7.5354
2745.42	5.25971
2748.1	3.70812
2750.77	2.96149
2753.45	2.06186
2756.12	1.64222
2758.79	2.09873
2761.47	1.95213
2764.14	2.35688
2766.81	1.99106
2769.48	1.85668
2772.14	1.29384
2774.81	1.55915
2777.48	1.82697
2780.14	0.830635
2782.81	0.513059
2785.47	1.29621
2788.13	1.69109
2790.79	1.83943
2793.46	1.6006
2796.11	0.539829
2798.77	0.741822
2801.43	-0.266089
2804.09	-0.243243
2806.74	-0.142944
2809.4	-0.0592254
2812.05	-0.496354
2814.71	0.614493
2817.36	1.81435
2820.01	5.41222
2822.66	8.82528
2825.31	12.869
2827.96	19.0086
2830.61	25.1281
2833.25	31.8418
2835.9	39.7518
2838.54	48.0178
2841.18	57.804
2843.83	65.5266
2846.47	75.0884
2849.11	83.5677
2851.75	91.7878
2854.39	99.4486
2857.03	107.272
2859.67	114.089
2862.3	120.47
2864.94	126.828
2867.57	132.094
2870.21	136.095
2872.84	139.068
2875.47	142.462
2878.1	144.624
2880.73	147.959
2883.36	151.61
2885.99	156.259
2888.61	161.156
2891.24	166.792
2893.87	172.51
2896.49	178.721
2899.11	187.693
2901.74	196.535
2904.36	206.346
2906.98	216.797
2909.6	228.368
2912.22	238.361
2914.83	248.974
2917.45	258.451
2920.07	267.444
2922.68	274.165
2925.3	280.436
2927.91	283.162
2930.52	284.332
2933.13	283.876
2935.74	280.357
2938.35	276.204
2940.96	270.528
2943.57	261.989
2946.18	252.755
2948.78	243.856
2951.39	233.345
2953.99	222.23
2956.6	211.304
2959.2	200.244
2961.8	190.434
2964.4	180.324
2967	170.74
2969.6	161.816
2972.2	153.053
2974.79	142.688
2977.39	133.939
2979.98	124.771
2982.58	115.504
2985.17	105.718
2987.76	96.3398
2990.36	86.4702
2992.95	77.0633
2995.54	69.2389
2998.12	60.4801
3000.71	52.8541
3003.3	46.7678
3005.88	40.4593
3008.47	33.3695
3011.05	27.8007
3013.64	22.0743
3016.22	18.4516
3018.8	15.7563
3021.38	13.0525
3023.96	10.7999
3026.54	9.84822
3029.12	8.38486
3031.69	7.10018
3034.27	6.3957
3036.85	6.29356
3039.42	6.32534
3041.99	6.91154
3044.57	7.78343
3047.14	7.79714
3049.71	8.19417
3052.28	8.97266
3054.85	10.4954
3057.42	10.9502
3059.98	11.5417
3062.55	11.2538
3065.11	11.3743
3067.68	10.3701
3070.24	9.05994
3072.8	7.58512
3075.37	6.39999
3077.93	6.21685
3080.49	5.21711
3083.05	4.66825
3085.61	3.8979
3088.16	2.21913
3090.72	0.756826
3093.27	0.288347
3095.83	0.359003
3098.38	0.233548
3100.94	-0.489043
3103.49	-0.361794
3106.04	0.0532029
3108.59	0.420202
3111.14	0.913484
3113.69	1.73821
3116.23	2.64165
3118.78	4.08216
3121.33	4.71268
3123.87	5.50688
3126.42	6.61549
3128.96	7.40794
3131.5	9.05629
3134.04	10.2099
3136.58	11.4734
3139.12	13.3326
3141.66	14.2477
3144.2	15.5133
3146.74	16.9654
3149.27	19.7883