File: data/Raman/poly_smoothed/Mb_50_18_15_1x_45s_532 nm_x100_100%_600 gr_mm_01.txt
#Acq. time (s)=	45
#Accumulations=	2
#Range (cm-¹)=	200...3150
#Windows=	2
#Auto scanning=	Off
#Autofocus=	Off
#Macrospot=	Off
#AutoExposure=	Off
#Spike filter=	Multiple accum.
#Delay time (s)=	0
#Binning=	1
#Readout mode=	Signal
#DeNoise=	Off
#ICS correction=	On
#Dark correction=	Off
#Inst. Process=	Off
#Detector Gain=	Best Dynamic Range
#Detector ADC=	20 kHz
#Detector temperature (°C)=	-69.85
#Instrument=	LabRAM HR Evol
#Detector=	Synapse
#Objective=	x100
#Grating=	600 gr/mm
#ND Filter=	100%
#Laser (nm)=	532
#Hole=	100.021
#Range=	Auto
#Laser Pol.=	No
#Raman. Pol.=	No
#Laser Pol. (°)=	-0.0007625
#Raman Pol. (°)=	89.9995
#Collection=	Microscope
#StageXY=	Marzhauser
#StageZ=	Marzhauser
#X (µm)=	19311.3
#Y (µm)=	3091.4
#Z (µm)=	1046.85
#Full time(mm:ss)=	3:19
#Project=
#Sample=
#Site=
#Title=	Mb_50_18_15_2x_45s_532 nm_x100_100%_600 gr_mm
#Remark=
#Date=	12.07.2022 11:21
#Acquired=	12.07.2022 11:21:01
#Base:Fit=	10.08.2022 10:49:18
#Base:Sub=	10.08.2022 10:49:30
#Filter:Polynom=	16.08.2022 10:14:59
#AxisType[0]=Intens
#AxisUnit[0]=Cnt
#AxisType[1]=Spectr
#AxisUnit[1]=1/cm
200.388	29.4114
204.019	24.962
207.646	20.7316
211.274	17.1539
214.899	15.6142
218.524	13.8357
222.146	11.8738
225.766	10.6417
229.388	8.83217
233.005	7.96647
236.621	5.76614
240.236	5.33565
243.852	6.30078
247.464	5.60234
251.074	4.88723
254.683	4.04659
258.291	3.6015
261.897	4.71804
265.504	4.83119
269.108	5.32375
272.71	4.98083
276.311	6.11884
279.91	6.36527
283.508	7.05133
287.105	6.7923
290.698	8.18958
294.291	9.65991
297.884	11.5562
301.475	13.8238
305.064	16.4939
308.652	17.6169
312.237	18.7066
315.822	19.8079
319.406	21.1055
322.987	21.6507
326.568	22.6861
330.148	24.9596
333.724	23.0947
337.301	21.1838
340.875	18.2832
344.449	16.6744
348.02	16.8513
351.592	18.233
355.16	19.2077
358.728	19.5471
362.294	20.891
365.858	24.7189
369.422	24.3554
372.983	25.7272
376.543	26.8643
380.102	28.5213
383.661	29.2947
387.216	29.7265
390.771	30.7353
394.324	29.8694
397.875	29.9039
401.425	28.3478
404.974	25.4483
408.524	23.9508
412.07	20.7214
415.614	16.2831
419.156	13.856
422.698	10.1718
426.238	5.80323
429.777	3.75482
433.315	2.05492
436.852	1.47835
440.387	3.50238
443.919	3.31741
447.451	2.40036
450.982	3.20703
454.512	4.09379
458.038	4.87227
461.565	6.68662
465.091	7.5962
468.613	8.70804
472.136	10.8656
475.655	13.9183
479.176	16.0021
482.692	18.2223
486.21	21.4544
489.724	25.1853
493.237	28.8787
496.75	32.2858
500.26	36.1559
503.771	40.3687
507.279	41.5413
510.785	40.471
514.289	39.8975
517.793	40.2052
521.297	40.3034
524.797	40.0016
528.297	39.7551
531.795	36.2
535.291	34.0914
538.787	31.367
542.281	28.3407
545.773	23.9394
549.264	20.562
552.754	18.3824
556.243	15.6532
559.73	12.4527
563.216	11.0527
566.701	11.1119
570.182	10.1123
573.664	11.9338
577.145	10.183
580.624	10.4906
584.1	10.1897
587.577	9.04858
591.052	6.9411
594.524	4.03456
597.997	3.58622
601.466	3.89095
604.936	4.40681
608.403	4.8033
611.87	6.27683
615.334	5.458
618.799	4.58172
622.26	2.99271
625.72	4.36433
629.181	5.27758
632.638	6.03105
636.095	7.59227
639.551	8.93814
643.005	8.57102
646.457	10.406
649.908	12.7713
653.357	13.2975
656.806	15.0294
660.253	15.2163
663.7	16.2535
667.145	17.9087
670.588	16.6556
674.027	16.7484
677.468	18.2105
680.907	19.3528
684.345	19.9692
687.781	21.3102
691.216	22.2908
694.65	24.7858
698.081	25.6716
701.512	25.0511
704.942	27.5219
708.371	30.7314
711.796	33.4815
715.222	35.858
718.645	39.3906
722.068	39.9763
725.49	42.0218
728.909	44.7121
732.329	49.5027
735.745	52.6208
739.16	57.3885
742.576	62.1126
745.988	68.5499
749.401	75.2826
752.811	80.894
756.22	84.917
759.627	91.8801
763.035	96.8701
766.44	100.287
769.843	104.701
773.245	107.111
776.646	108.986
780.046	108.531
783.444	107.639
786.841	106.856
790.237	107.948
793.631	104.88
797.024	101.781
800.416	98.8676
803.807	92.3749
807.196	88.732
810.584	85.4556
813.971	81.9646
817.354	80.9538
820.739	80.0997
824.122	79.3869
827.503	77.8425
830.882	77.5684
834.261	75.6713
837.637	74.0846
841.013	72.082
844.389	71.5845
847.761	69.2662
851.131	67.1179
854.503	65.3759
857.871	64.7723
861.24	63.1052
864.606	63.0639
867.97	63.2948
871.336	62.9938
874.698	62.1544
878.058	60.6997
881.418	59.4965
884.778	58.4038
888.135	59.0413
891.49	60.2301
894.845	60.6366
898.198	60.9459
901.55	59.7046
904.901	60.0037
908.25	58.0045
911.598	57.6415
914.945	55.2972
918.291	53.1001
921.635	50.9939
924.978	49.7188
928.318	47.2787
931.659	46.0238
934.998	46.4127
938.336	44.7085
941.671	43.5771
945.007	42.6279
948.339	42.0986
951.672	40.9936
955.004	40.7991
958.333	38.5067
961.662	38.3808
964.989	37.3983
968.315	37.5813
971.639	37.2555
974.962	38.2534
978.285	39.2889
981.605	40.5167
984.924	41.9212
988.243	42.1235
991.56	42.0979
994.875	43.1969
998.188	46.2465
1001.5	51.8087
1004.81	57.0803
1008.12	60.5312
1011.43	64.0086
1014.74	66.088
1018.05	67.6071
1021.35	69.0594
1024.65	72.3493
1027.96	73.9389
1031.26	73.8339
1034.56	71.3119
1037.86	68.8557
1041.16	67.1775
1044.45	64.1276
1047.75	62.4172
1051.04	59.4948
1054.33	57.1865
1057.62	55.5076
1060.91	52.3412
1064.2	49.2271
1067.49	46.7236
1070.77	45.353
1074.06	45.8591
1077.34	47.2976
1080.62	48.5531
1083.91	48.0893
1087.18	47.4624
1090.46	47.3926
1093.74	47.2102
1097.02	46.5985
1100.29	45.27
1103.56	45.4889
1106.84	44.365
1110.11	42.2565
1113.38	40.2224
1116.64	37.3544
1119.91	35.0022
1123.18	31.9332
1126.44	28.6852
1129.7	25.2821
1132.97	21.9955
1136.23	20.5443
1139.49	18.8014
1142.74	15.9358
1146	14.5738
1149.26	12.4108
1152.51	11.2504
1155.76	11.4898
1159.01	10.15
1162.27	9.98526
1165.51	11.7259
1168.76	13.604
1172.01	16.4098
1175.25	17.6885
1178.5	18.6422
1181.74	19.9819
1184.98	20.4597
1188.22	22.0154
1191.46	24.3435
1194.7	23.9819
1197.94	22.3586
1201.17	22.946
1204.41	21.6523
1207.64	21.6987
1210.87	23.2097
1214.1	22.4965
1217.33	22.8429
1220.56	23.6329
1223.79	23.6651
1227.01	23.995
1230.23	27.6252
1233.46	28.4152
1236.68	31.2707
1239.9	34.9148
1243.12	37.0653
1246.34	40.1691
1249.55	43.0474
1252.77	45.2854
1255.98	45.4225
1259.2	46.0543
1262.41	48.625
1265.62	50.7249
1268.83	52.3342
1272.03	54.7625
1275.24	55.4872
1278.45	58.7761
1281.65	60.4388
1284.85	61.8709
1288.06	63.6527
1291.26	64.2966
1294.46	64.4854
1297.66	66.0754
1300.85	66.7748
1304.05	67.6937
1307.24	66.9346
1310.43	68.2812
1313.63	67.9711
1316.82	68.0105
1320.01	66.7763
1323.2	64.4039
1326.38	62.2646
1329.57	59.5367
1332.76	56.2841
1335.94	55.1077
1339.12	53.4638
1342.3	51.5697
1345.48	49.1144
1348.66	48.6111
1351.84	46.5846
1355.01	45.219
1358.19	44.0281
1361.36	42.8473
1364.53	41.9313
1367.71	38.7615
1370.88	37.2084
1374.04	34.3472
1377.21	32.6528
1380.38	29.9641
1383.54	28.5987
1386.71	27.2383
1389.87	25.1259
1393.03	24.5926
1396.19	21.8755
1399.35	21.7834
1402.51	21.2405
1405.67	22.2044
1408.82	25.5722
1411.98	29.6085
1415.13	32.5159
1418.28	37.4223
1421.43	41.8879
1424.58	47.8818
1427.73	54.4608
1430.88	60.0037
1434.02	64.5851
1437.17	68.6536
1440.31	71.7172
1443.45	72.9582
1446.6	73.7756
1449.74	74.1467
1452.87	73.2865
1456.01	72.1324
1459.15	70.0556
1462.28	68.269
1465.42	65.8778
1468.55	62.7155
1471.68	58.552
1474.81	54.9609
1477.94	52.3347
1481.07	48.2884
1484.2	46.4
1487.32	43.1201
1490.45	38.8425
1493.57	35.7722
1496.69	34.4862
1499.81	32.4611
1502.93	31.231
1506.05	29.0096
1509.17	27.3616
1512.28	25.0406
1515.4	23.0141
1518.51	20.8564
1521.63	20.2104
1524.74	20.243
1527.85	19.6753
1530.96	19.2135
1534.06	20.0561
1537.17	20.1629
1540.28	22.5119
1543.38	24.8431
1546.48	24.7305
1549.59	23.8932
1552.69	23.3087
1555.79	24.0686
1558.88	25.3859
1561.98	25.3729
1565.08	24.7386
1568.17	26.0053
1571.27	28.9393
1574.36	30.3273
1577.45	32.0712
1580.54	34.3251
1583.63	36.1732
1586.72	37.1283
1589.8	38.4162
1592.89	39.8848
1595.97	42.6047
1599.06	44.0933
1602.14	44.6631
1605.22	45.3617
1608.3	45.5765
1611.38	45.548
1614.46	45.5615
1617.53	46.6838
1620.61	46.3579
1623.68	45.7319
1626.75	45.9929
1629.82	46.6571
1632.9	48.7129
1635.96	49.6333
1639.03	51.3242
1642.1	53.4889
1645.16	54.1329
1648.23	56.1017
1651.29	58.0937
1654.36	58.3858
1657.42	57.8616
1660.48	55.8125
1663.53	56.1866
1666.59	54.2489
1669.65	51.116
1672.7	49.5011
1675.76	45.8307
1678.81	42.6462
1681.86	37.4591
1684.91	33.5419
1687.96	29.2882
1691.01	25.3571
1694.06	22.3577
1697.11	19.259
1700.15	18.493
1703.2	16.0188
1706.24	14.4608
1709.28	13.4675
1712.32	11.6997
1715.36	11.1427
1718.4	9.90245
1721.43	9.16642
1724.47	8.30367
1727.5	8.07695
1730.54	6.76328
1733.57	6.39873
1736.6	5.78607
1739.63	6.0281
1742.66	5.63479
1745.69	5.73294
1748.72	5.2883
1751.74	4.97454
1754.77	3.83284
1757.79	2.64411
1760.81	2.16951
1763.83	2.13935
1766.85	1.90729
1769.87	2.04935
1772.89	2.09544
1775.91	1.70435
1778.92	1.05207
1781.94	1.66785
1784.95	2.04531
1787.96	1.99227
1790.97	1.14366
1793.98	0.820246
1796.99	0.724689
1800	0.462202
1803	0.472583
1806.01	0.174339
1809.01	0.438845
1812.02	0.43561
1815.02	0.63968
1818.02	1.55549
1821.02	1.47322
1824.02	2.18937
1827.01	1.89369
1830.01	1.88059
1833	2.1064
1836	4.00133
1838.99	3.98802
1841.98	4.41223
1844.97	4.24058
1847.96	3.56791
1850.95	3.09969
1853.94	3.40162
1856.92	3.78112
1859.91	3.44264
1862.89	4.1784
1865.88	4.31779
1868.86	3.56673
1871.84	3.51321
1874.82	4.3585
1877.8	4.63829
1880.77	3.95021
1882.51	4.00401
1885.5	4.78584
1888.48	6.37665
1891.47	6.9157
1894.46	6.72464
1897.44	6.68331
1900.42	6.8182
1903.41	7.80218
1906.39	8.05804
1909.37	7.36119
1912.35	6.15684
1915.32	5.16655
1918.3	3.99944
1921.28	3.57752
1924.25	3.69523
1927.22	3.83856
1930.2	4.20118
1933.17	5.85814
1936.14	6.26662
1939.11	5.52017
1942.08	4.77301
1945.04	5.41088
1948.01	4.05749
1950.97	3.53824
1953.94	4.15561
1956.9	5.04802
1959.86	6.00438
1962.82	6.20042
1965.78	5.97551
1968.74	5.92512
1971.69	5.82663
1974.65	6.09005
1977.61	7.04279
1980.56	6.5767
1983.51	6.81937
1986.46	6.725
1989.41	6.82246
1992.36	7.94747
1995.31	7.86849
1998.26	9.22351
2001.2	9.56269
2004.15	11.5549
2007.09	12.544
2010.04	10.4334
2012.98	9.84708
2015.92	8.20769
2018.86	8.54135
2021.8	9.18488
2024.74	9.18554
2027.67	10.5553
2030.61	9.9943
2033.54	11.3259
2036.47	13.1955
2039.41	13.2982
2042.34	14.1557
2045.27	14.2259
2048.2	15.6383
2051.12	15.7837
2054.05	16.9498
2056.98	17.2282
2059.9	18.9627
2062.82	20.2611
2065.75	21.702
2068.67	24.6343
2071.59	26.0097
2074.51	27.0902
2077.43	27.8013
2080.34	28.2056
2083.26	29.7999
2086.17	31.273
2089.09	33.2461
2092	35.0667
2094.91	37.469
2097.82	39.804
2100.73	41.8943
2103.64	43.8621
2106.55	47.4949
2109.46	50.2274
2112.36	53.3543
2115.27	55.9052
2118.17	58.5096
2121.07	62.9134
2123.97	65.5956
2126.87	68.9536
2129.77	71.1916
2132.67	75.1801
2135.57	78.761
2138.46	81.9811
2141.36	84.7692
2144.25	87.2861
2147.14	90.0582
2150.03	93.2375
2152.92	95.9482
2155.81	97.4442
2158.7	98.3072
2161.59	100.14
2164.48	101.88
2167.36	101.137
2170.25	101.308
2173.13	100.778
2176.01	101.238
2178.89	100.682
2181.77	99.2064
2184.65	98.3518
2187.53	95.5675
2190.41	92.7175
2193.28	90.8389
2196.16	86.6353
2199.03	83.6085
2201.9	79.9515
2204.78	76.248
2207.65	73.0169
2210.51	71.272
2213.38	67.2313
2216.25	64.062
2219.12	60.6169
2221.98	57.3604
2224.85	54.1031
2227.71	51.2162
2230.57	47.4799
2233.43	44.8998
2236.29	41.2394
2239.15	37.4309
2242.01	35.0939
2244.87	32.3443
2247.73	30.0983
2250.58	27.2677
2253.43	26.8447
2256.29	25.6498
2259.14	23.6429
2261.99	22.4555
2264.84	21.0287
2267.69	20.8577
2270.54	20.3303
2273.38	20.1165
2276.23	20.0886
2279.07	20.7733
2281.92	20.2341
2284.76	19.4072
2287.6	19.5898
2290.44	19.3559
2293.28	16.9082
2296.12	16.0505
2298.96	15.3214
2301.79	13.6986
2304.63	12.7205
2307.46	13.1676
2310.3	13.4936
2313.13	12.8399
2315.96	12.9676
2318.79	12.7968
2321.62	13.675
2324.45	13.9173
2327.27	11.4503
2330.1	10.6655
2332.93	10.0178
2335.75	9.80128
2338.57	8.48271
2341.4	7.58263
2344.22	7.0109
2347.04	6.2545
2349.86	6.8738
2352.67	5.55229
2355.49	4.37537
2358.31	2.68891
2361.12	1.96285
2363.94	1.9109
2366.75	3.01547
2369.56	2.67249
2372.37	2.6528
2375.18	3.8361
2377.99	5.31745
2380.8	6.16313
2383.61	6.6675
2386.41	7.37403
2389.22	7.41468
2392.02	7.53864
2394.82	7.04238
2397.63	7.55178
2400.43	7.80112
2403.23	7.63837
2406.02	6.72518
2408.82	6.74416
2411.62	5.62153
2414.41	5.5251
2417.21	5.65836
2420	4.58894
2422.79	3.30934
2425.59	3.04231
2428.38	3.73963
2431.17	3.67943
2433.96	3.6286
2436.74	3.5205
2439.53	3.03909
2442.32	3.85632
2445.1	4.38815
2447.88	5.23358
2450.67	5.46983
2453.45	6.0055
2456.23	6.62328
2459.01	6.91578
2461.79	7.39258
2464.57	7.81799
2467.34	7.13457
2470.12	6.56888
2472.89	6.39346
2475.67	6.96502
2478.44	6.4955
2481.21	6.86532
2483.98	6.86612
2486.75	6.59528
2489.52	6.54176
2492.29	6.12424
2495.06	5.58984
2497.82	5.22914
2500.59	4.56708
2503.35	4.33633
2506.11	3.49538
2508.88	3.12003
2511.63	3.60845
2514.39	2.50893
2517.15	2.73459
2519.91	3.33743
2522.67	2.50241
2525.42	3.12098
2528.18	3.67356
2530.93	2.69274
2533.69	3.02106
2536.44	3.15446
2539.19	4.35782
2541.94	5.89801
2544.69	6.39257
2547.44	7.0133
2550.18	7.36506
2552.93	8.10511
2555.68	8.03693
2558.42	7.17645
2561.16	6.68816
2563.9	6.04899
2566.64	5.65407
2569.38	6.17026
2572.12	5.52212
2574.86	5.28557
2577.6	6.19665
2580.34	4.51207
2583.07	4.18966
2585.81	4.33052
2588.54	3.50994
2591.27	3.98541
2594	3.81513
2596.73	2.88416
2599.46	3.19566
2602.19	3.28347
2604.92	3.54862
2607.64	2.45502
2610.37	2.81105
2613.09	2.11584
2615.82	2.27625
2618.54	2.52418
2621.26	1.46472
2623.98	1.212
2626.7	0.194308
2629.42	-0.236619
2632.14	0.415809
2634.86	1.31064
2637.57	2.89662
2640.29	2.11045
2643	2.56512
2645.72	3.30487
2648.43	3.82817
2651.14	4.54247
2653.85	4.76603
2656.56	4.60127
2659.27	4.26311
2661.97	4.34648
2664.68	5.32335
2667.38	5.43714
2670.09	5.68464
2672.79	6.02178
2675.49	6.01668
2678.2	5.99659
2680.89	5.40578
2683.59	5.25236
2686.29	4.57095
2688.99	3.17292
2691.69	3.27686
2694.38	3.37961
2697.08	3.76327
2699.77	2.67091
2702.46	2.04795
2705.16	2.05756
2707.85	2.04584
2710.54	2.35304
2713.23	2.37734
2715.92	2.68485
2718.6	3.46797
2721.29	3.33571
2723.97	3.50857
2726.66	4.37982
2729.34	5.32182
2732.02	5.93065
2734.7	7.09547
2737.39	7.43303
2740.06	7.75168
2742.74	7.42941
2745.42	6.69371
2748.1	6.70081
2750.77	5.9236
2753.45	6.1794
2756.12	5.96536
2758.79	5.54298
2761.47	5.32906
2764.14	4.937
2766.81	4.57793
2769.48	4.1775
2772.14	4.47318
2774.81	3.87456
2777.48	3.40429
2780.14	4.00068
2782.81	4.43098
2785.47	3.75902
2788.13	2.97771
2790.79	2.98614
2793.46	3.47063
2796.11	2.49413
2798.77	3.04635
2801.43	2.49548
2804.09	2.64378
2806.74	3.33487
2809.4	3.30994
2812.05	4.1781
2814.71	4.03087
2817.36	6.7711
2820.01	10.2877
2822.66	12.6602
2825.31	17.1285
2827.96	21.2387
2830.61	25.3106
2833.25	29.895
2835.9	34.5804
2838.54	39.2
2841.18	44.5736
2843.83	50.297
2846.47	57.0612
2849.11	63.9536
2851.75	71.0622
2854.39	77.0853
2857.03	84.2916
2859.67	90.8067
2862.3	96.9604
2864.94	102.895
2867.57	107.413
2870.21	111.978
2872.84	115.545
2875.47	118.883
2878.1	122.363
2880.73	126.955
2883.36	130.728
2885.99	133.917
2888.61	138.734
2891.24	143.138
2893.87	147.112
2896.49	152.098
2899.11	158.437
2901.74	165.497
2904.36	173.076
2906.98	181.046
2909.6	190.934
2912.22	201.304
2914.83	210.176
2917.45	219.714
2920.07	227.759
2922.68	234.994
2925.3	241.782
2927.91	244.9
2930.52	246.447
2933.13	245.933
2935.74	244.501
2938.35	241.435
2940.96	236.121
2943.57	230.23
2946.18	222.481
2948.78	214.97
2951.39	207.345
2953.99	198.584
2956.6	189.409
2959.2	179.997
2961.8	172.875
2964.4	165.12
2967	157.5
2969.6	150.282
2972.2	142.645
2974.79	135.503
2977.39	127.263
2979.98	119.373
2982.58	111.875
2985.17	103.229
2987.76	95.6238
2990.36	87.1306
2992.95	78.4816
2995.54	70.4493
2998.12	62.866
3000.71	55.015
3003.3	47.3873
3005.88	40.9183
3008.47	35.6179
3011.05	30.5522
3013.64	26.1372
3016.22	21.2118
3018.8	17.5501
3021.38	14.5981
3023.96	12.9854
3026.54	11.2612
3029.12	9.50196
3031.69	9.16586
3034.27	8.22534
3036.85	7.33633
3039.42	6.62421
3041.99	5.73697
3044.57	6.84251
3047.14	6.93558
3049.71	7.61988
3052.28	7.11156
3054.85	6.17845
3057.42	5.69523
3059.98	4.8422
3062.55	5.11603
3065.11	5.37632
3067.68	5.28125
3070.24	5.0221
3072.8	4.36074
3075.37	3.48792
3077.93	2.85416
3080.49	2.85335
3083.05	2.85757
3085.61	3.04287
3088.16	2.39515
3090.72	2.21286
3093.27	2.1891
3095.83	1.69736
3098.38	1.72208
3100.94	2.80386
3103.49	2.08474
3106.04	2.71071
3108.59	3.77185
3111.14	4.57777
3113.69	4.01233
3116.23	2.87247
3118.78	2.79732
3121.33	3.45563
3123.87	4.77892
3126.42	6.22014
3128.96	7.02251
3131.5	7.92815
3134.04	8.8812
3136.58	9.09337
3139.12	11.5377
3141.66	13.4073
3144.2	14.8221
3146.74	16.0519
3149.27	19.059