File: data/Raman/poly_smoothed/Mb_50_18_50_1x_45s_532 nm_x100_100%_600 gr_mm_01.txt
#Acq. time (s)=	45
#Accumulations=	2
#Range (cm-¹)=	200...3150
#Windows=	2
#Auto scanning=	Off
#Autofocus=	Off
#Macrospot=	Off
#AutoExposure=	Off
#Spike filter=	Multiple accum.
#Delay time (s)=	0
#Binning=	1
#Readout mode=	Signal
#DeNoise=	Off
#ICS correction=	On
#Dark correction=	Off
#Inst. Process=	Off
#Detector Gain=	Best Dynamic Range
#Detector ADC=	20 kHz
#Detector temperature (°C)=	-69.85
#Instrument=	LabRAM HR Evol
#Detector=	Synapse
#Objective=	x100
#Grating=	600 gr/mm
#ND Filter=	100%
#Laser (nm)=	532
#Hole=	100.021
#Range=	Auto
#Laser Pol.=	No
#Raman. Pol.=	No
#Laser Pol. (°)=	-0.0007625
#Raman Pol. (°)=	89.9995
#Collection=	Microscope
#StageXY=	Marzhauser
#StageZ=	Marzhauser
#X (µm)=	28499.7
#Y (µm)=	-2949.4
#Z (µm)=	1044
#Full time(mm:ss)=	3:19
#Project=
#Sample=
#Site=
#Title=	Mb_50_18_50_2x_45s_532 nm_x100_100%_600 gr_mm
#Remark=
#Date=	12.07.2022 14:56
#Acquired=	12.07.2022 14:56:15
#Base:Fit=	10.08.2022 10:49:18
#Base:Sub=	10.08.2022 10:49:30
#Filter:Polynom=	16.08.2022 10:14:59
#AxisType[0]=Intens
#AxisUnit[0]=Cnt
#AxisType[1]=Spectr
#AxisUnit[1]=1/cm
200.388	32.6618
204.019	35.5854
207.646	39.232
211.274	40.6804
214.899	42.1444
218.524	42.3286
222.146	42.4001
225.766	41.5964
229.388	40.5469
233.005	39.5227
236.621	35.4512
240.236	32.6997
243.852	31.4405
247.464	29.1525
251.074	25.1948
254.683	20.568
258.291	17.1893
261.897	15.0166
265.504	12.0604
269.108	10.3354
272.71	8.13481
276.311	6.02544
279.91	5.09851
283.508	1.81125
287.105	2.96769
290.698	4.04155
294.291	5.01756
297.884	5.90116
301.475	7.78767
305.064	9.27851
308.652	11.3213
312.237	12.0584
315.822	12.4471
319.406	12.8531
322.987	12.9742
326.568	12.7677
330.148	12.0095
333.724	10.7378
337.301	8.4267
340.875	6.75634
344.449	7.07499
348.02	6.48199
351.592	6.00175
355.16	5.03243
358.728	4.45076
362.294	5.62557
365.858	5.89087
369.422	7.85738
372.983	10.322
376.543	12.4393
380.102	13.6948
383.661	15.216
387.216	17.3072
390.771	17.5391
394.324	17.3868
397.875	17.112
401.425	16.0427
404.974	15.3083
408.524	15.1596
412.07	12.9512
415.614	9.16425
419.156	7.4103
422.698	6.42861
426.238	6.04208
429.777	6.47074
433.315	6.14874
436.852	4.66027
440.387	4.21708
443.919	4.42774
447.451	6.08403
450.982	5.0161
454.512	5.67733
458.038	6.44995
461.565	6.08997
465.091	7.65991
468.613	8.66401
472.136	9.2214
475.655	10.013
479.176	10.9321
482.692	13.4208
486.21	16.4283
489.724	18.164
493.237	19.6592
496.75	21.9268
500.26	23.7933
503.771	27.0043
507.279	29.7658
510.785	30.0191
514.289	31.116
517.793	30.7901
521.297	32.1864
524.797	32.5435
528.297	33.1142
531.795	31.3997
535.291	28.4741
538.787	25.3677
542.281	22.6974
545.773	20.9007
549.264	19.0111
552.754	17.2632
556.243	14.5338
559.73	14.0177
563.216	13.3997
566.701	12.4015
570.182	12.0453
573.664	10.2757
577.145	8.27616
580.624	7.42414
584.1	7.86768
587.577	7.16845
591.052	7.10519
594.524	6.73831
597.997	6.23605
601.466	8.28082
604.936	8.4377
608.403	8.8154
611.87	9.00301
615.334	7.11427
618.799	7.80916
622.26	8.0076
625.72	9.34475
629.181	12.1894
632.638	14.7796
636.095	15.7748
639.551	17.7355
643.005	19.9602
646.457	22.5035
649.908	23.0599
653.357	23.6565
656.806	24.6802
660.253	25.5997
663.7	26.4197
667.145	27.3269
670.588	29.1291
674.027	30.0731
677.468	32.6895
680.907	33.6048
684.345	35.279
687.781	36.7515
691.216	36.9702
694.65	37.7638
698.081	40.0578
701.512	40.8796
704.942	42.658
708.371	45.13
711.796	47.1475
715.222	49.6085
718.645	52.0804
722.068	53.4939
725.49	55.343
728.909	57.7822
732.329	58.505
735.745	61.2908
739.16	65.692
742.576	70.6762
745.988	75.5914
749.401	80.245
752.811	84.6834
756.22	89.7532
759.627	94.3902
763.035	98.4302
766.44	102.647
769.843	103.402
773.245	105.88
776.646	107.796
780.046	109.491
783.444	110.13
786.841	110.818
790.237	110.118
793.631	107.327
797.024	105.266
800.416	104.334
803.807	101.659
807.196	99.8849
810.584	97.5969
813.971	96.3203
817.354	96.0558
820.739	95.1616
824.122	93.9002
827.503	93.5005
830.882	91.3058
834.261	89.528
837.637	90.0787
841.013	89.1064
844.389	86.8634
847.761	87.2047
851.131	86.3701
854.503	83.4808
857.871	83.5829
861.24	81.4752
864.606	78.7006
867.97	76.1657
871.336	73.2137
874.698	69.802
878.058	69.5366
881.418	68.0913
884.778	66.8377
888.135	64.7036
891.49	62.5598
894.845	61.9931
898.198	60.0448
901.55	58.3543
904.901	56.5393
908.25	55.4105
911.598	55.8697
914.945	55.1802
918.291	55.9277
921.635	55.7605
924.978	55.6634
928.318	56.0267
931.659	57.4408
934.998	57.0704
938.336	55.2595
941.671	54.3507
945.007	52.9927
948.339	51.9672
951.672	52.0256
955.004	52.8898
958.333	51.3451
961.662	48.1373
964.989	46.567
968.315	44.377
971.639	43.7223
974.962	43.194
978.285	41.7961
981.605	39.1928
984.924	39.2312
988.243	38.0729
991.56	39.2399
994.875	38.9876
998.188	42.1569
1001.5	45.2448
1004.81	47.9117
1008.12	52.4416
1011.43	56.168
1014.74	60.8577
1018.05	64.2551
1021.35	66.9088
1024.65	70.0773
1027.96	72.3887
1031.26	74.6371
1034.56	76.3354
1037.86	74.4208
1041.16	73.5209
1044.45	72.715
1047.75	70.9475
1051.04	68.9118
1054.33	64.8574
1057.62	61.436
1060.91	58.6522
1064.2	57.6366
1067.49	56.5886
1070.77	54.5554
1074.06	52.8526
1077.34	54.3559
1080.62	55.035
1083.91	52.9118
1087.18	51.7032
1090.46	52.0447
1093.74	51.1783
1097.02	49.9392
1100.29	50.7675
1103.56	51.2733
1106.84	50.2432
1110.11	48.3639
1113.38	46.9156
1116.64	44.1021
1119.91	42.6319
1123.18	40.6195
1126.44	37.6924
1129.7	33.2031
1132.97	28.8669
1136.23	26.2394
1139.49	24.8958
1142.74	24.1393
1146	20.8615
1149.26	17.9608
1152.51	16.3259
1155.76	13.7482
1159.01	11.7188
1162.27	9.20246
1165.51	6.65728
1168.76	5.90386
1172.01	5.29294
1175.25	6.38586
1178.5	6.95356
1181.74	7.61747
1184.98	8.50825
1188.22	8.23311
1191.46	10.0946
1194.7	11.3869
1197.94	13.8986
1201.17	16.6845
1204.41	19.0304
1207.64	20.2209
1210.87	21.1682
1214.1	23.2978
1217.33	26.881
1220.56	30.1186
1223.79	33.1506
1227.01	35.7484
1230.23	38.9105
1233.46	39.8482
1236.68	42.5042
1239.9	44.5302
1243.12	46.2702
1246.34	47.574
1249.55	49.0174
1252.77	50.65
1255.98	51.2404
1259.2	51.0865
1262.41	51.8403
1265.62	53.1864
1268.83	55.2925
1272.03	57.8176
1275.24	59.9058
1278.45	60.4803
1281.65	62.3179
1284.85	63.5629
1288.06	64.2453
1291.26	65.3372
1294.46	68.2952
1297.66	69.7208
1300.85	69.206
1304.05	69.3044
1307.24	70.5758
1310.43	69.8897
1313.63	70.6994
1316.82	71.1357
1320.01	69.6849
1323.2	68.7411
1326.38	68.4313
1329.57	66.5492
1332.76	66.0096
1335.94	65.2252
1339.12	63.1704
1342.3	61.4745
1345.48	59.7936
1348.66	57.6318
1351.84	56.1447
1355.01	53.0968
1358.19	50.0268
1361.36	47.5122
1364.53	45.4468
1367.71	42.7341
1370.88	40.9245
1374.04	38.6971
1377.21	36.1282
1380.38	34.2993
1383.54	32.7447
1386.71	30.0695
1389.87	28.4441
1393.03	26.6032
1396.19	24.482
1399.35	22.7192
1402.51	22.6664
1405.67	23.1551
1408.82	20.8171
1411.98	18.7802
1415.13	19.5892
1418.28	30.3436
1421.43	40.4092
1424.58	51.4817
1427.73	60.8505
1430.88	69.9374
1434.02	77.0034
1437.17	84.2019
1440.31	91.1455
1443.45	95.7207
1446.6	97.3991
1449.74	100.945
1452.87	100.869
1456.01	100.219
1459.15	98.2921
1462.28	97.124
1465.42	93.4831
1468.55	87.2419
1471.68	81.6522
1474.81	73.8139
1477.94	64.7102
1481.07	56.9599
1484.2	48.5546
1487.32	40.4823
1490.45	40.0084
1493.57	41.5565
1496.69	42.48
1499.81	39.646
1502.93	37.1619
1506.05	33.8991
1509.17	29.6396
1512.28	25.5647
1515.4	21.5801
1518.51	18.1854
1521.63	15.0237
1524.74	13.9027
1527.85	12.3891
1530.96	10.8975
1534.06	11.1985
1537.17	11.3722
1540.28	11.6466
1543.38	12.7268
1546.48	13.5372
1549.59	14.1505
1552.69	13.7265
1555.79	14.665
1558.88	15.3301
1561.98	16.6943
1565.08	19.3657
1568.17	22.5769
1571.27	25.5423
1574.36	29.6196
1577.45	32.5114
1580.54	35.1707
1583.63	37.0246
1586.72	39.7966
1589.8	42.3167
1592.89	45.3305
1595.97	46.9192
1599.06	48.1377
1602.14	47.9639
1605.22	47.7457
1608.3	48.3551
1611.38	48.6292
1614.46	48.743
1617.53	48.8897
1620.61	48.1374
1623.68	49.4324
1626.75	49.6273
1629.82	51.1384
1632.9	54.6976
1635.96	59.4287
1639.03	63.2231
1642.1	68.6009
1645.16	72.2266
1648.23	74.7126
1651.29	77.4298
1654.36	77.8796
1657.42	77.8604
1660.48	77.2394
1663.53	76.6399
1666.59	74.6538
1669.65	71.8004
1672.7	67.6399
1675.76	63.293
1678.81	57.0644
1681.86	51.3169
1684.91	45.0527
1687.96	40.141
1691.01	33.9847
1694.06	28.831
1697.11	24.9342
1700.15	21.3705
1703.2	18.8697
1706.24	15.7857
1709.28	14.2117
1712.32	12.3211
1715.36	10.4093
1718.4	9.41918
1721.43	6.54049
1724.47	4.32382
1727.5	4.85994
1730.54	4.83981
1733.57	4.82041
1736.6	5.3533
1739.63	6.2764
1742.66	6.36883
1745.69	6.50399
1748.72	5.28873
1751.74	5.78956
1754.77	5.49493
1757.79	5.30624
1760.81	4.72795
1763.83	4.08918
1766.85	4.14813
1769.87	4.02428
1772.89	3.38346
1775.91	2.78901
1778.92	1.4536
1781.94	0.826119
1784.95	0.332553
1787.96	-0.309504
1790.97	-0.467969
1793.98	-1.39394
1796.99	-2.39581
1800	-0.885114
1803	-0.495753
1806.01	-0.141057
1809.01	-0.306569
1812.02	0.414254
1815.02	-0.0202866
1818.02	0.297434
1821.02	0.993373
1824.02	1.83548
1827.01	2.10097
1830.01	2.04596
1833	2.72913
1836	2.91609
1838.99	3.85816
1841.98	5.6053
1844.97	6.03969
1847.96	6.51371
1850.95	6.81618
1853.94	6.58032
1856.92	6.27309
1859.91	6.3519
1862.89	6.5105
1865.88	6.02357
1868.86	5.49408
1871.84	5.58754
1874.82	5.9463
1877.8	5.67909
1880.77	5.48258
1882.51	5.44822
1885.5	5.84526
1888.48	6.26103
1891.47	6.7223
1894.46	7.43705
1897.44	6.65177
1900.42	6.25847
1903.41	6.70471
1906.39	6.18205
1909.37	6.96373
1912.35	8.44571
1915.32	9.09607
1918.3	7.88317
1921.28	8.48406
1924.25	8.21267
1927.22	7.58762
1930.2	7.1045
1933.17	7.07646
1936.14	7.57896
1939.11	6.59994
1942.08	5.93829
1945.04	6.64096
1948.01	7.31355
1950.97	8.28028
1953.94	7.75322
1956.9	8.69563
1959.86	9.29717
1962.82	9.6048
1965.78	10.4566
1968.74	10.804
1971.69	11.4365
1974.65	11.3534
1977.61	11.9186
1980.56	12.8913
1983.51	14.7156
1986.46	15.0962
1989.41	14.4971
1992.36	14.5983
1995.31	15.727
1998.26	15.1859
2001.2	14.6757
2004.15	14.3803
2007.09	14.5655
2010.04	14.9862
2012.98	15.1927
2015.92	15.8594
2018.86	16.5089
2021.8	17.0384
2024.74	16.9902
2027.67	17.2143
2030.61	17.9538
2033.54	19.4883
2036.47	20.9452
2039.41	22.1689
2042.34	24.1689
2045.27	24.9967
2048.2	25.4736
2051.12	27.15
2054.05	29.0426
2056.98	30.242
2059.9	31.1671
2062.82	33.6025
2065.75	34.0228
2068.67	35.0207
2071.59	35.5852
2074.51	37.4662
2077.43	39.2236
2080.34	41.2115
2083.26	42.9716
2086.17	43.8846
2089.09	45.0902
2092	47.1128
2094.91	49.3801
2097.82	51.4436
2100.73	54.7005
2103.64	58.4568
2106.55	61.4461
2109.46	65.456
2112.36	68.9778
2115.27	72.683
2118.17	76.0086
2121.07	80.2119
2123.97	86.4413
2126.87	92.8346
2129.77	99.2971
2132.67	104.67
2135.57	109.407
2138.46	113.247
2141.36	120.392
2144.25	126.254
2147.14	131.314
2150.03	135.784
2152.92	140.659
2155.81	143.512
2158.7	147.174
2161.59	148.951
2164.48	150.851
2167.36	151.709
2170.25	153.217
2173.13	151.98
2176.01	149.956
2178.89	147.672
2181.77	144.865
2184.65	141.001
2187.53	136.851
2190.41	133.448
2193.28	130.662
2196.16	127.215
2199.03	123.428
2201.9	117.297
2204.78	111.782
2207.65	106.987
2210.51	102.945
2213.38	98.6661
2216.25	94.4557
2219.12	89.6596
2221.98	85.6392
2224.85	81.4932
2227.71	77.1028
2230.57	73.2956
2233.43	68.8475
2236.29	65.0002
2239.15	61.0084
2242.01	55.8757
2244.87	50.991
2247.73	47.2893
2250.58	43.8106
2253.43	40.9107
2256.29	38.9348
2259.14	36.7077
2261.99	35.1903
2264.84	33.724
2267.69	31.4546
2270.54	29.5885
2273.38	27.8419
2276.23	26.8431
2279.07	25.1361
2281.92	22.3506
2284.76	22.7845
2287.6	21.5294
2290.44	19.3252
2293.28	16.7434
2296.12	16.4304
2298.96	15.3891
2301.79	14.3101
2304.63	12.9428
2307.46	11.0933
2310.3	9.46136
2313.13	9.22729
2315.96	8.86007
2318.79	8.99252
2321.62	8.97152
2324.45	9.85198
2327.27	9.93359
2330.1	9.21845
2332.93	8.258
2335.75	6.99922
2338.57	6.67156
2341.4	6.20887
2344.22	4.16972
2347.04	2.6872
2349.86	2.30127
2352.67	1.23499
2355.49	1.78811
2358.31	0.906543
2361.12	-0.300713
2363.94	1.2458
2366.75	2.07436
2369.56	2.24226
2372.37	2.43849
2375.18	1.36431
2377.99	2.6503
2380.8	3.20746
2383.61	4.33401
2386.41	4.69656
2389.22	4.59108
2392.02	4.11881
2394.82	3.64908
2397.63	3.07157
2400.43	2.55534
2403.23	2.22451
2406.02	2.45516
2408.82	1.68745
2411.62	0.96436
2414.41	0.482851
2417.21	1.23941
2420	1.17242
2422.79	1.20497
2425.59	2.65406
2428.38	1.64467
2431.17	1.85638
2433.96	2.52695
2436.74	2.47877
2439.53	2.55483
2442.32	2.23104
2445.1	2.71271
2447.88	3.29657
2450.67	3.2135
2453.45	3.13917
2456.23	2.84523
2459.01	3.49788
2461.79	2.53068
2464.57	2.05597
2467.34	2.68605
2470.12	3.07335
2472.89	3.25984
2475.67	3.12452
2478.44	3.37433
2481.21	3.9251
2483.98	3.71444
2486.75	3.8286
2489.52	3.67809
2492.29	3.3957
2495.06	2.45962
2497.82	2.45268
2500.59	3.37305
2503.35	2.87224
2506.11	1.75157
2508.88	1.34253
2511.63	0.995314
2514.39	2.54253
2517.15	2.53713
2519.91	2.99306
2522.67	3.01434
2525.42	2.29707
2528.18	2.55478
2530.93	1.74792
2533.69	3.49934
2536.44	3.28528
2539.19	3.31017
2541.94	2.66037
2544.69	2.9368
2547.44	3.61274
2550.18	3.20467
2552.93	3.78213
2555.68	3.83172
2558.42	4.11299
2561.16	4.68129
2563.9	4.86665
2566.64	4.87601
2569.38	4.65781
2572.12	3.90789
2574.86	4.41824
2577.6	4.75912
2580.34	4.26825
2583.07	5.60546
2585.81	5.11591
2588.54	5.16609
2591.27	5.23954
2594	5.38714
2596.73	5.11145
2599.46	5.42547
2602.19	4.40479
2604.92	2.78564
2607.64	3.38862
2610.37	2.54861
2613.09	2.458
2615.82	2.09552
2618.54	2.7236
2621.26	3.24939
2623.98	3.03868
2626.7	3.72721
2629.42	4.76483
2632.14	4.16916
2634.86	4.07659
2637.57	4.50903
2640.29	5.40779
2643	5.37649
2645.72	6.11697
2648.43	6.34807
2651.14	6.3841
2653.85	6.28817
2656.56	6.41569
2659.27	6.73055
2661.97	6.61103
2664.68	6.7246
2667.38	6.83074
2670.09	5.71218
2672.79	5.72752
2675.49	4.72635
2678.2	4.82862
2680.89	4.58911
2683.59	4.5278
2686.29	3.7873
2688.99	2.98549
2691.69	3.06321
2694.38	3.49311
2697.08	4.50866
2699.77	4.3339
2702.46	5.35426
2705.16	6.04484
2707.85	6.91142
2710.54	6.30805
2713.23	6.56164
2715.92	6.7596
2718.6	7.06937
2721.29	8.00553
2723.97	8.48417
2726.66	9.38296
2729.34	9.1398
2732.02	9.26881
2734.7	7.72473
2737.39	6.93135
2740.06	6.00554
2742.74	5.44889
2745.42	4.16224
2748.1	1.91432
2750.77	1.51685
2753.45	0.206835
2756.12	-0.390254
2758.79	-0.214259
2761.47	0.218779
2764.14	0.0319775
2766.81	-0.479626
2769.48	-0.64794
2772.14	-0.0853097
2774.81	0.222655
2777.48	0.456339
2780.14	0.481257
2782.81	1.63988
2785.47	2.51908
2788.13	2.6868
2790.79	3.09473
2793.46	3.94481
2796.11	4.19156
2798.77	4.32101
2801.43	4.51563
2804.09	4.48727
2806.74	4.45204
2809.4	5.01873
2812.05	5.41885
2814.71	6.55558
2817.36	8.32245
2820.01	11.6439
2822.66	14.9358
2825.31	20.2709
2827.96	24.5071
2830.61	30.2103
2833.25	36.1403
2835.9	43.7197
2838.54	52.0085
2841.18	59.999
2843.83	69.0951
2846.47	77.9883
2849.11	87.1808
2851.75	97.0024
2854.39	105.976
2857.03	115.222
2859.67	122.259
2862.3	127.901
2864.94	134.872
2867.57	139.942
2870.21	145.007
2872.84	149.675
2875.47	153.929
2878.1	159.432
2880.73	164.237
2883.36	168.137
2885.99	172.962
2888.61	178.046
2891.24	183.32
2893.87	190.742
2896.49	198.148
2899.11	207.223
2901.74	218.236
2904.36	229.055
2906.98	240.605
2909.6	251.537
2912.22	262.955
2914.83	275.468
2917.45	286.485
2920.07	294.405
2922.68	302.786
2925.3	309.274
2927.91	313.854
2930.52	316.023
2933.13	316.052
2935.74	314.413
2938.35	311.101
2940.96	305.703
2943.57	297.827
2946.18	289.228
2948.78	278.901
2951.39	268.401
2953.99	256.453
2956.6	245.75
2959.2	234.716
2961.8	222.873
2964.4	211.932
2967	200.237
2969.6	188.72
2972.2	177.272
2974.79	166.542
2977.39	157.042
2979.98	145.978
2982.58	134.811
2985.17	123.411
2987.76	112.085
2990.36	100.917
2992.95	90.5492
2995.54	80.9978
2998.12	70.5756
3000.71	63.351
3003.3	56.2888
3005.88	48.4
3008.47	42.4668
3011.05	37.1286
3013.64	32.6543
3016.22	28.5394
3018.8	25.6482
3021.38	23.6343
3023.96	21.99
3026.54	20.919
3029.12	20.8545
3031.69	20.2106
3034.27	20.2456
3036.85	20.8758
3039.42	22.0749
3041.99	22.5383
3044.57	22.3138
3047.14	23.0263
3049.71	23.4872
3052.28	23.5719
3054.85	22.2596
3057.42	22.2566
3059.98	21.5809
3062.55	20.2526
3065.11	19.948
3067.68	17.7921
3070.24	16.0774
3072.8	13.7064
3075.37	11.5097
3077.93	9.33877
3080.49	7.87285
3083.05	5.41076
3085.61	4.07588
3088.16	2.25679
3090.72	1.45879
3093.27	0.676413
3095.83	-0.457752
3098.38	-0.353125
3100.94	-0.960681
3103.49	-1.21167
3106.04	0.0137034
3108.59	1.24846
3111.14	1.91826
3113.69	2.68452
3116.23	3.79107
3118.78	5.36998
3121.33	7.05704
3123.87	7.41195
3126.42	8.46625
3128.96	9.64094
3131.5	10.8708
3134.04	11.259
3136.58	12.242
3139.12	12.4178
3141.66	11.9711
3144.2	11.2535
3146.74	10.1946
3149.27	6.5578