File: data/Raman/poly_smoothed/Mb_50_18_06_1x_45s_532 nm_x100_100%_600 gr_mm_01.txt
#Acq. time (s)=	45
#Accumulations=	2
#Range (cm-¹)=	200...3150
#Windows=	2
#Auto scanning=	Off
#Autofocus=	Off
#Macrospot=	Off
#AutoExposure=	Off
#Spike filter=	Multiple accum.
#Delay time (s)=	0
#Binning=	1
#Readout mode=	Signal
#DeNoise=	Off
#ICS correction=	On
#Dark correction=	Off
#Inst. Process=	Off
#Detector Gain=	Best Dynamic Range
#Detector ADC=	20 kHz
#Detector temperature (°C)=	-69.85
#Instrument=	LabRAM HR Evol
#Detector=	Synapse
#Objective=	x100
#Grating=	600 gr/mm
#ND Filter=	100%
#Laser (nm)=	532
#Hole=	100.021
#Range=	Auto
#Laser Pol.=	No
#Raman. Pol.=	No
#Laser Pol. (°)=	-0.0007625
#Raman Pol. (°)=	89.9995
#Collection=	Microscope
#StageXY=	Marzhauser
#StageZ=	Marzhauser
#X (µm)=	19343.2
#Y (µm)=	3069.8
#Z (µm)=	1047.55
#Full time(mm:ss)=	3:18
#Project=
#Sample=
#Site=
#Title=	Mb_50_18_06_2x_45s_532 nm_x100_100%_600 gr_mm
#Remark=
#Date=	12.07.2022 10:39
#Acquired=	12.07.2022 10:39:48
#Base:Fit=	10.08.2022 10:49:18
#Base:Sub=	10.08.2022 10:49:30
#Filter:Polynom=	16.08.2022 10:14:59
#AxisType[0]=Intens
#AxisUnit[0]=Cnt
#AxisType[1]=Spectr
#AxisUnit[1]=1/cm
200.388	12.1145
204.019	12.3135
207.646	10.3321
211.274	8.35728
214.899	6.52158
218.524	5.40548
222.146	6.07067
225.766	5.53862
229.388	5.17909
233.005	4.87408
236.621	5.83706
240.236	6.68389
243.852	8.08062
247.464	7.97996
251.074	7.89626
254.683	8.16528
258.291	9.98308
261.897	11.0857
265.504	10.4175
269.108	10.3298
272.71	10.6115
276.311	10.3773
279.91	13.7621
283.508	14.4508
287.105	15.5789
290.698	15.9711
294.291	15.4644
297.884	16.2548
301.475	17.4772
305.064	17.4527
308.652	16.8689
312.237	17.3177
315.822	17.0658
319.406	18.3044
322.987	17.3275
326.568	15.9515
330.148	14.2417
333.724	11.778
337.301	9.39986
340.875	8.11628
344.449	7.20059
348.02	7.80103
351.592	8.28683
355.16	8.27298
358.728	9.28278
362.294	11.2837
365.858	14.1705
369.422	18.4131
372.983	20.6705
376.543	22.1469
380.102	22.8875
383.661	23.0133
387.216	24.5398
390.771	24.1866
394.324	22.982
397.875	23.8105
401.425	22.4822
404.974	21.3225
408.524	18.8908
412.07	15.4795
415.614	13.3842
419.156	12.612
422.698	11.1613
426.238	8.91904
429.777	8.54394
433.315	7.72285
436.852	8.01828
440.387	8.4916
443.919	7.77425
447.451	8.51384
450.982	10.5192
454.512	10.6705
458.038	11.188
461.565	11.5903
465.091	11.9725
468.613	10.9727
472.136	12.7658
475.655	14.3719
479.176	15.6665
482.692	17.9023
486.21	20.8636
489.724	22.2842
493.237	26.1
496.75	28.5883
500.26	32.0469
503.771	35.5054
507.279	37.3574
510.785	36.5755
514.289	38.695
517.793	39.3425
521.297	38.7892
524.797	38.373
528.297	36.2015
531.795	33.309
535.291	32.2217
538.787	29.0936
542.281	26.4669
545.773	23.9671
549.264	20.9164
552.754	18.5326
556.243	16.5391
559.73	15.8074
563.216	15.48
566.701	12.8652
570.182	11.5201
573.664	11.1683
577.145	10.2495
580.624	10.0963
584.1	10.7693
587.577	9.9019
591.052	8.83951
594.524	7.95994
597.997	8.69488
601.466	7.81836
604.936	7.65581
608.403	8.92014
611.87	9.84392
615.334	10.9375
618.799	10.9174
622.26	10.3259
625.72	10.4844
629.181	11.7923
632.638	10.0679
636.095	9.55175
639.551	9.59005
643.005	9.37578
646.457	9.68976
649.908	8.81056
653.357	8.79633
656.806	9.84068
660.253	12.0437
663.7	12.8839
667.145	13.9976
670.588	15.5405
674.027	16.326
677.468	18.6752
680.907	21.3176
684.345	24.3092
687.781	27.033
691.216	28.3123
694.65	30.8176
698.081	31.9071
701.512	32.4048
704.942	32.9009
708.371	34.1914
711.796	34.8007
715.222	32.537
718.645	31.6849
722.068	32.751
725.49	34.1097
728.909	35.5862
732.329	36.8432
735.745	41.1162
739.16	44.7094
742.576	49.0925
745.988	53.7845
749.401	60.0155
752.811	64.4127
756.22	68.4936
759.627	73.6296
763.035	77.773
766.44	79.0796
769.843	81.766
773.245	83.4097
776.646	84.8942
780.046	87.3637
783.444	88.7362
786.841	87.3385
790.237	86.4415
793.631	84.5087
797.024	81.1716
800.416	79.9914
803.807	78.7406
807.196	76.4899
810.584	74.7048
813.971	72.2545
817.354	71.2569
820.739	72.676
824.122	71.4081
827.503	71.3263
830.882	71.6346
834.261	70.3734
837.637	67.3857
841.013	65.6324
844.389	63.6732
847.761	62.8228
851.131	61.3983
854.503	60.3948
857.871	59.3266
861.24	57.9663
864.606	56.2098
867.97	54.6624
871.336	53.5002
874.698	53.6299
878.058	52.9141
881.418	53.0246
884.778	53.2765
888.135	51.5697
891.49	49.309
894.845	49.094
898.198	47.7902
901.55	47.8138
904.901	47.8462
908.25	46.6092
911.598	46.0551
914.945	45.2461
918.291	43.8533
921.635	41.6119
924.978	41.5066
928.318	39.6234
931.659	38.8166
934.998	36.3699
938.336	35.2279
941.671	34.1934
945.007	32.8796
948.339	32.3211
951.672	32.7604
955.004	31.7336
958.333	30.3396
961.662	29.5405
964.989	29.3905
968.315	28.7178
971.639	28.1817
974.962	30.8875
978.285	31.0599
981.605	31.1934
984.924	33.2862
988.243	32.425
991.56	31.8506
994.875	33.8438
998.188	34.5017
1001.5	36.3329
1004.81	38.7452
1008.12	42.3795
1011.43	43.9229
1014.74	46.3836
1018.05	47.3813
1021.35	49.0871
1024.65	50.2267
1027.96	51.1854
1031.26	51.185
1034.56	50.2043
1037.86	49.2061
1041.16	48.7691
1044.45	46.8322
1047.75	45.5458
1051.04	44.3027
1054.33	43.2387
1057.62	40.1411
1060.91	36.4498
1064.2	33.3198
1067.49	30.2798
1070.77	27.5942
1074.06	26.7253
1077.34	24.9752
1080.62	24.4044
1083.91	24.2381
1087.18	22.7961
1090.46	22.0924
1093.74	23.1131
1097.02	23.4708
1100.29	23.7981
1103.56	24.1943
1106.84	24.1768
1110.11	23.2065
1113.38	22.023
1116.64	19.8939
1119.91	19.8041
1123.18	17.0744
1126.44	15.4038
1129.7	14.7966
1132.97	12.962
1136.23	12.688
1139.49	12.2345
1142.74	11.9496
1146	11.0385
1149.26	9.97268
1152.51	8.19937
1155.76	6.16937
1159.01	5.29407
1162.27	4.5348
1165.51	4.93056
1168.76	5.22838
1172.01	6.58546
1175.25	8.5881
1178.5	7.08305
1181.74	6.47709
1184.98	6.13304
1188.22	5.29337
1191.46	4.32309
1194.7	3.75178
1197.94	4.50482
1201.17	4.70687
1204.41	3.46903
1207.64	4.52957
1210.87	6.29816
1214.1	8.40026
1217.33	12.1452
1220.56	14.0569
1223.79	16.6869
1227.01	19.7166
1230.23	21.5443
1233.46	24.0745
1236.68	28.6917
1239.9	32.7993
1243.12	35.5666
1246.34	36.9546
1249.55	39.9952
1252.77	42.1072
1255.98	43.828
1259.2	44.7697
1262.41	46.5271
1265.62	48.0114
1268.83	48.3463
1272.03	49.9892
1275.24	50.9687
1278.45	51.4223
1281.65	52.8722
1284.85	53.8992
1288.06	54.8849
1291.26	56.2451
1294.46	56.3982
1297.66	57.0105
1300.85	58.2086
1304.05	58.8076
1307.24	58.9345
1310.43	59.5314
1313.63	61.1572
1316.82	61.4053
1320.01	60.6813
1323.2	57.7665
1326.38	56.9199
1329.57	55.2784
1332.76	55.0941
1335.94	52.742
1339.12	50.9382
1342.3	48.2426
1345.48	47.6501
1348.66	44.473
1351.84	41.7184
1355.01	39.8337
1358.19	38.8148
1361.36	37.8187
1364.53	34.9367
1367.71	32.5711
1370.88	31.5116
1374.04	31.1134
1377.21	30.4633
1380.38	29.2162
1383.54	28.2654
1386.71	26.6303
1389.87	25.8117
1393.03	25.9114
1396.19	25.0899
1399.35	23.9377
1402.51	24.1762
1405.67	26.5323
1408.82	28.5085
1411.98	29.6905
1415.13	30.9524
1418.28	35.5082
1421.43	39.1323
1424.58	43.3269
1427.73	47.3013
1430.88	51.3493
1434.02	57.28
1437.17	60.9583
1440.31	63.2741
1443.45	65.7581
1446.6	67.4108
1449.74	70.2014
1452.87	71.6761
1456.01	71.2697
1459.15	69.5022
1462.28	68.2508
1465.42	66.3234
1468.55	64.7693
1471.68	61.1504
1474.81	59.7985
1477.94	57.5065
1481.07	55.5835
1484.2	53.4336
1487.32	50.3491
1490.45	46.3139
1493.57	43.2432
1496.69	41.0055
1499.81	38.3388
1502.93	36.584
1506.05	34.1241
1509.17	31.3317
1512.28	28.4762
1515.4	25.4971
1518.51	23.1546
1521.63	23.238
1524.74	23.497
1527.85	23.3654
1530.96	22.2932
1534.06	23.1019
1537.17	23.8204
1540.28	25.7716
1543.38	26.4386
1546.48	27.2542
1549.59	29.1446
1552.69	29.2698
1555.79	29.7738
1558.88	30.4969
1561.98	30.5827
1565.08	30.0522
1568.17	32.499
1571.27	33.6858
1574.36	35.758
1577.45	39.1769
1580.54	41.4029
1583.63	43.3191
1586.72	45.6338
1589.8	48.0567
1592.89	50.5093
1595.97	52.7707
1599.06	54.3551
1602.14	55.0961
1605.22	54.9577
1608.3	55.3579
1611.38	57.8704
1614.46	58.2096
1617.53	58.9947
1620.61	59.303
1623.68	60.4163
1626.75	63.2044
1629.82	64.7564
1632.9	66.7186
1635.96	69.4986
1639.03	71.4534
1642.1	73.9402
1645.16	77.8526
1648.23	80.118
1651.29	81.1744
1654.36	82.3439
1657.42	82.3891
1660.48	80.7024
1663.53	78.0727
1666.59	75.6706
1669.65	71.1265
1672.7	66.9797
1675.76	61.0727
1678.81	54.2712
1681.86	48.3127
1684.91	42.7213
1687.96	37.3958
1691.01	32.8647
1694.06	28.374
1697.11	25.2124
1700.15	22.4074
1703.2	18.303
1706.24	15.3542
1709.28	12.5966
1712.32	10.8532
1715.36	9.85521
1718.4	9.44798
1721.43	9.52537
1724.47	8.60911
1727.5	7.61197
1730.54	6.27904
1733.57	6.29445
1736.6	5.06715
1739.63	5.6659
1742.66	5.44878
1745.69	5.32452
1748.72	4.42723
1751.74	2.94952
1754.77	2.80268
1757.79	3.42717
1760.81	3.67953
1763.83	3.39448
1766.85	2.37431
1769.87	1.80528
1772.89	1.12298
1775.91	0.853349
1778.92	1.02293
1781.94	1.06791
1784.95	2.18742
1787.96	3.02595
1790.97	3.98275
1793.98	5.26736
1796.99	5.9004
1800	6.08034
1803	6.86815
1806.01	7.45937
1809.01	8.08118
1812.02	9.08758
1815.02	8.96447
1818.02	8.85261
1821.02	8.46663
1824.02	8.2875
1827.01	8.81963
1830.01	8.18987
1833	7.13542
1836	6.64892
1838.99	5.51883
1841.98	4.10783
1844.97	2.45558
1847.96	1.52959
1850.95	0.705187
1853.94	-0.398023
1856.92	-0.867015
1859.91	-0.863626
1862.89	-1.07388
1865.88	-0.834251
1868.86	-0.388161
1871.84	0.549628
1874.82	1.69557
1877.8	2.57548
1880.77	2.71892
1882.51	3.22534
1885.5	3.7076
1888.48	4.65188
1891.47	6.01988
1894.46	6.71621
1897.44	7.77675
1900.42	9.41505
1903.41	9.4727
1906.39	10.8963
1909.37	11.4567
1912.35	10.5641
1915.32	10.0756
1918.3	9.60017
1921.28	10.2392
1924.25	8.91163
1927.22	8.23336
1930.2	7.4751
1933.17	6.53906
1936.14	6.75699
1939.11	5.7431
1942.08	5.92035
1945.04	5.96771
1948.01	5.06571
1950.97	4.04983
1953.94	4.13578
1956.9	4.52829
1959.86	5.28761
1962.82	6.14323
1965.78	5.81825
1968.74	5.90351
1971.69	7.23643
1974.65	8.28487
1977.61	9.24516
1980.56	9.89038
1983.51	9.5538
1986.46	10.3388
1989.41	10.5455
1992.36	10.1063
1995.31	10.1695
1998.26	9.45095
2001.2	9.4844
2004.15	9.31925
2007.09	10.058
2010.04	9.59802
2012.98	9.59948
2015.92	9.80019
2018.86	9.12165
2021.8	8.46746
2024.74	8.87234
2027.67	9.57544
2030.61	9.06734
2033.54	9.50059
2036.47	9.07223
2039.41	9.39222
2042.34	10.1958
2045.27	11.4072
2048.2	12.9079
2051.12	12.991
2054.05	14.5052
2056.98	16.3303
2059.9	16.1984
2062.82	16.6934
2065.75	18.2285
2068.67	18.8768
2071.59	19.7272
2074.51	21.1367
2077.43	22.5203
2080.34	24.4345
2083.26	24.7738
2086.17	26.8935
2089.09	28.1375
2092	28.7426
2094.91	29.5799
2097.82	30.8354
2100.73	32.2893
2103.64	34.3039
2106.55	35.4632
2109.46	37.6316
2112.36	39.0058
2115.27	41.0001
2118.17	45.0008
2121.07	46.9947
2123.97	50.5221
2126.87	53.6926
2129.77	57.3301
2132.67	61.3737
2135.57	64.0284
2138.46	68.4186
2141.36	73.3023
2144.25	78.5191
2147.14	83.4427
2150.03	86.9334
2152.92	91.1506
2155.81	94.6251
2158.7	97.7682
2161.59	99.9
2164.48	101.403
2167.36	103.465
2170.25	102.935
2173.13	103.093
2176.01	100.834
2178.89	97.1906
2181.77	94.2267
2184.65	91.768
2187.53	89.091
2190.41	85.6164
2193.28	81.7528
2196.16	79.1059
2199.03	75.9764
2201.9	72.5699
2204.78	68.7358
2207.65	65.9436
2210.51	63.4041
2213.38	60.5761
2216.25	57.5969
2219.12	54.0332
2221.98	51.6851
2224.85	49.5339
2227.71	47.3202
2230.57	46.3795
2233.43	43.1703
2236.29	41.2638
2239.15	38.0199
2242.01	33.6283
2244.87	30.8545
2247.73	26.4982
2250.58	23.7304
2253.43	21.6712
2256.29	19.5572
2259.14	18.483
2261.99	17.4031
2264.84	16.9913
2267.69	16.7087
2270.54	15.5895
2273.38	14.0297
2276.23	14.2055
2279.07	13.6495
2281.92	11.978
2284.76	11.4423
2287.6	11.1823
2290.44	10.5538
2293.28	10.1819
2296.12	10.6699
2298.96	11.0022
2301.79	11.2093
2304.63	10.3132
2307.46	10.655
2310.3	10.8652
2313.13	10.8352
2315.96	10.3409
2318.79	10.187
2321.62	9.85116
2324.45	10.437
2327.27	11.1857
2330.1	12.0011
2332.93	11.4132
2335.75	11.4056
2338.57	10.986
2341.4	9.41466
2344.22	8.79973
2347.04	8.0016
2349.86	6.08515
2352.67	4.7981
2355.49	4.04498
2358.31	3.10262
2361.12	2.82873
2363.94	1.96305
2366.75	2.04721
2369.56	1.41724
2372.37	1.10084
2375.18	1.57365
2377.99	2.02858
2380.8	1.441
2383.61	1.06423
2386.41	0.49543
2389.22	0.304074
2392.02	-0.422439
2394.82	0.0699341
2397.63	-0.205865
2400.43	-0.244575
2403.23	-1.34334
2406.02	-1.02347
2408.82	-1.91567
2411.62	-1.73151
2414.41	-1.73426
2417.21	-1.66069
2420	-1.25595
2422.79	-0.472333
2425.59	-0.278457
2428.38	0.807628
2431.17	1.39212
2433.96	0.976855
2436.74	1.65835
2439.53	2.38553
2442.32	3.1574
2445.1	3.32677
2447.88	3.40401
2450.67	3.20909
2453.45	2.56764
2456.23	3.40205
2459.01	3.75297
2461.79	3.86304
2464.57	3.82631
2467.34	4.49657
2470.12	3.23739
2472.89	2.99496
2475.67	3.13711
2478.44	2.47035
2481.21	3.27104
2483.98	3.50174
2486.75	3.61252
2489.52	3.7387
2492.29	3.53862
2495.06	3.92671
2497.82	4.0802
2500.59	3.738
2503.35	2.67959
2506.11	2.88836
2508.88	2.5904
2511.63	2.00998
2514.39	1.36553
2517.15	0.524691
2519.91	0.452167
2522.67	0.612014
2525.42	0.554847
2528.18	0.27107
2530.93	0.218621
2533.69	0.0616318
2536.44	0.544446
2539.19	0.421021
2541.94	0.926198
2544.69	1.68749
2547.44	2.43174
2550.18	3.24434
2552.93	4.29488
2555.68	5.08929
2558.42	5.57471
2561.16	5.92806
2563.9	7.59908
2566.64	7.52629
2569.38	7.70624
2572.12	8.14873
2574.86	8.07754
2577.6	8.21319
2580.34	7.55791
2583.07	7.11017
2585.81	7.00729
2588.54	6.52736
2591.27	5.84299
2594	4.9731
2596.73	4.31449
2599.46	3.92231
2602.19	3.62524
2604.92	3.15306
2607.64	3.10451
2610.37	2.8489
2613.09	2.68641
2615.82	1.51537
2618.54	0.367904
2621.26	0.876247
2623.98	1.3254
2626.7	1.97831
2629.42	2.59704
2632.14	2.97686
2634.86	3.56012
2637.57	4.21256
2640.29	4.99146
2643	5.00921
2645.72	6.37007
2648.43	6.98934
2651.14	7.40369
2653.85	7.77421
2656.56	9.00748
2659.27	8.76258
2661.97	8.84198
2664.68	9.53212
2667.38	9.53239
2670.09	9.42564
2672.79	8.71105
2675.49	8.37504
2678.2	7.72262
2680.89	7.43491
2683.59	6.76598
2686.29	7.50801
2688.99	7.84542
2691.69	8.66122
2694.38	9.29146
2697.08	9.29694
2699.77	10.2709
2702.46	10.7611
2705.16	10.8332
2707.85	10.5886
2710.54	10.1116
2713.23	10.4771
2715.92	10.111
2718.6	9.65957
2721.29	9.55099
2723.97	8.78253
2726.66	8.03211
2729.34	8.42205
2732.02	8.07279
2734.7	6.80057
2737.39	5.97589
2740.06	5.72726
2742.74	5.45932
2745.42	5.41196
2748.1	6.25894
2750.77	5.95441
2753.45	5.92926
2756.12	7.11856
2758.79	7.21182
2761.47	6.57206
2764.14	6.1537
2766.81	5.57908
2769.48	4.80973
2772.14	3.56719
2774.81	3.01884
2777.48	3.20981
2780.14	3.01784
2782.81	2.7877
2785.47	1.96718
2788.13	1.80608
2790.79	1.66635
2793.46	0.276752
2796.11	-0.208462
2798.77	-0.336177
2801.43	-0.214079
2804.09	-0.385348
2806.74	-0.182922
2809.4	0.648086
2812.05	1.01417
2814.71	1.42788
2817.36	2.56327
2820.01	3.98299
2822.66	7.5931
2825.31	10.5372
2827.96	15.4516
2830.61	19.6644
2833.25	24.7261
2835.9	29.5817
2838.54	35.8478
2841.18	42.8188
2843.83	48.8607
2846.47	54.4726
2849.11	60.1196
2851.75	66.2748
2854.39	73.3445
2857.03	78.8671
2859.67	85.0889
2862.3	90.7274
2864.94	95.3032
2867.57	99.6535
2870.21	102.413
2872.84	105.381
2875.47	107.132
2878.1	109.669
2880.73	112.722
2883.36	115.914
2885.99	119.991
2888.61	122.824
2891.24	126.666
2893.87	130.692
2896.49	133.849
2899.11	138.068
2901.74	143.328
2904.36	149.065
2906.98	155.833
2909.6	163.134
2912.22	171.443
2914.83	179.875
2917.45	187.822
2920.07	195.925
2922.68	202.189
2925.3	206.495
2927.91	208.693
2930.52	209.786
2933.13	210.4
2935.74	208.794
2938.35	206.414
2940.96	201.79
2943.57	196.035
2946.18	189.889
2948.78	181.645
2951.39	173.591
2953.99	164.438
2956.6	156.493
2959.2	147.285
2961.8	137.83
2964.4	128.607
2967	120.772
2969.6	112.434
2972.2	105.13
2974.79	97.6954
2977.39	90.5976
2979.98	83.6314
2982.58	76.4857
2985.17	69.5281
2987.76	62.1652
2990.36	54.7928
2992.95	48.8157
2995.54	42.7359
2998.12	37.2926
3000.71	31.8085
3003.3	26.5808
3005.88	21.5113
3008.47	17.4203
3011.05	14.3487
3013.64	11.7823
3016.22	9.64324
3018.8	8.47945
3021.38	7.28915
3023.96	5.23127
3026.54	3.98808
3029.12	3.31058
3031.69	3.05577
3034.27	2.92452
3036.85	3.24606
3039.42	3.77746
3041.99	3.51522
3044.57	3.97045
3047.14	5.46386
3049.71	5.76891
3052.28	6.15901
3054.85	6.43413
3057.42	6.24614
3059.98	6.01876
3062.55	6.56103
3065.11	5.1705
3067.68	4.36502
3070.24	3.65063
3072.8	3.70017
3075.37	2.96662
3077.93	2.04988
3080.49	1.2575
3083.05	0.468804
3085.61	-0.393026
3088.16	-0.205746
3090.72	-0.416809
3093.27	-0.653986
3095.83	-0.391819
3098.38	0.235916
3100.94	1.57913
3103.49	1.59906
3106.04	2.47836
3108.59	3.39375
3111.14	4.97437
3113.69	6.00309
3116.23	7.36566
3118.78	8.21291
3121.33	8.98749
3123.87	10.2098
3126.42	11.166
3128.96	11.0432
3131.5	12.5388
3134.04	13.8908
3136.58	14.8428
3139.12	15.2195
3141.66	15.7017
3144.2	16.5061
3146.74	17.3875
3149.27	18.5656