File: data/Raman/poly_smoothed/Mb_50_18_11_1x_45s_532 nm_x100_100%_600 gr_mm_01.txt
#Acq. time (s)=	45
#Accumulations=	2
#Range (cm-¹)=	200...3150
#Windows=	2
#Auto scanning=	Off
#Autofocus=	Off
#Macrospot=	Off
#AutoExposure=	Off
#Spike filter=	Multiple accum.
#Delay time (s)=	0
#Binning=	1
#Readout mode=	Signal
#DeNoise=	Off
#ICS correction=	On
#Dark correction=	Off
#Inst. Process=	Off
#Detector Gain=	Best Dynamic Range
#Detector ADC=	20 kHz
#Detector temperature (°C)=	-69.85
#Instrument=	LabRAM HR Evol
#Detector=	Synapse
#Objective=	x100
#Grating=	600 gr/mm
#ND Filter=	100%
#Laser (nm)=	532
#Hole=	100.021
#Range=	Auto
#Laser Pol.=	No
#Raman. Pol.=	No
#Laser Pol. (°)=	-0.0007625
#Raman Pol. (°)=	89.9995
#Collection=	Microscope
#StageXY=	Marzhauser
#StageZ=	Marzhauser
#X (µm)=	19299.8
#Y (µm)=	3083.5
#Z (µm)=	1047
#Full time(mm:ss)=	3:18
#Project=
#Sample=
#Site=
#Title=	Mb_50_18_11_2x_45s_532 nm_x100_100%_600 gr_mm
#Remark=
#Date=	12.07.2022 11:04
#Acquired=	12.07.2022 11:04:51
#Base:Fit=	10.08.2022 10:49:18
#Base:Sub=	10.08.2022 10:49:30
#Filter:Polynom=	16.08.2022 10:14:59
#AxisType[0]=Intens
#AxisUnit[0]=Cnt
#AxisType[1]=Spectr
#AxisUnit[1]=1/cm
200.388	-0.854276
204.019	5.59657
207.646	7.96443
211.274	9.172
214.899	10.7544
218.524	11.5592
222.146	14.1768
225.766	13.6415
229.388	13.074
233.005	12.0782
236.621	12.6973
240.236	12.5287
243.852	10.5515
247.464	10.3665
251.074	6.86265
254.683	6.18884
258.291	6.20709
261.897	6.21681
265.504	6.42107
269.108	5.13616
272.71	4.5042
276.311	3.74926
279.91	3.03966
283.508	3.21844
287.105	4.4096
290.698	4.26379
294.291	3.895
297.884	6.30391
301.475	10.4903
305.064	12.3948
308.652	13.9095
312.237	13.8476
315.822	13.9127
319.406	14.5407
322.987	14.5782
326.568	15.3849
330.148	15.5472
333.724	15.0845
337.301	13.7772
340.875	13.4304
344.449	13.2892
348.02	13.8008
351.592	12.6083
355.16	14.1784
358.728	14.892
362.294	14.1439
365.858	15.7492
369.422	17.3005
372.983	19.3677
376.543	18.521
380.102	20.1584
383.661	22.4597
387.216	24.252
390.771	23.7281
394.324	23.24
397.875	22.0403
401.425	21.1333
404.974	20.4932
408.524	19.9408
412.07	19.3304
415.614	19.2568
419.156	16.5349
422.698	14.5392
426.238	12.2592
429.777	10.8109
433.315	8.99923
436.852	8.21294
440.387	8.62929
443.919	8.66181
447.451	7.34213
450.982	6.63996
454.512	7.72172
458.038	7.78508
461.565	7.73896
465.091	8.80859
468.613	10.5854
472.136	11.1245
475.655	13.2192
479.176	13.8124
482.692	17.0404
486.21	19.2182
489.724	22.2108
493.237	24.0805
496.75	25.9578
500.26	28.7436
503.771	31.526
507.279	31.2319
510.785	32.3973
514.289	32.3574
517.793	32.7617
521.297	32.6886
524.797	33.0692
528.297	31.7707
531.795	30.534
535.291	28.2187
538.787	26.3662
542.281	22.8488
545.773	20.3219
549.264	18.5212
552.754	16.5509
556.243	13.0769
559.73	10.996
563.216	9.62953
566.701	6.54041
570.182	5.47727
573.664	4.77009
577.145	5.25671
580.624	5.13273
584.1	6.0367
587.577	5.34236
591.052	4.20569
594.524	4.66999
597.997	5.39154
601.466	6.50291
604.936	8.99675
608.403	8.55935
611.87	9.63925
615.334	10.8012
618.799	11.2769
622.26	11.974
625.72	12.4193
629.181	12.9942
632.638	12.8246
636.095	13.2207
639.551	13.2849
643.005	12.7298
646.457	12.8958
649.908	13.6637
653.357	15.3333
656.806	15.8873
660.253	16.9828
663.7	18.0735
667.145	19.9464
670.588	19.9481
674.027	19.2493
677.468	20.7759
680.907	23.6523
684.345	24.8268
687.781	26.7643
691.216	27.2048
694.65	28.7722
698.081	30.3808
701.512	32.6571
704.942	33.6912
708.371	34.4004
711.796	34.5988
715.222	34.4611
718.645	35.012
722.068	37.5958
725.49	37.2243
728.909	37.4931
732.329	39.2118
735.745	40.9382
739.16	43.5242
742.576	49.8577
745.988	56.3905
749.401	63.7101
752.811	69.2682
756.22	74.5547
759.627	79.1018
763.035	84.1582
766.44	88.3314
769.843	90.6626
773.245	93.5748
776.646	95.4434
780.046	97.0148
783.444	97.5179
786.841	97.762
790.237	97.0483
793.631	96.1091
797.024	94.2701
800.416	91.8877
803.807	88.3796
807.196	81.9602
810.584	76.5142
813.971	75.6456
817.354	76.6468
820.739	77.8197
824.122	78.8066
827.503	81.1646
830.882	81.4137
834.261	80.1313
837.637	79.0244
841.013	78.599
844.389	76.4863
847.761	74.053
851.131	72.6363
854.503	70.5855
857.871	68.057
861.24	65.6237
864.606	65.0996
867.97	63.5151
871.336	61.0219
874.698	58.8676
878.058	55.6846
881.418	52.3431
884.778	48.8632
888.135	45.425
891.49	43.8167
894.845	46.5706
898.198	46.7557
901.55	46.888
904.901	47.7799
908.25	46.0857
911.598	45.0014
914.945	43.3048
918.291	45.5521
921.635	44.3791
924.978	43.6573
928.318	43.3328
931.659	41.9191
934.998	41.1415
938.336	40.713
941.671	41.4114
945.007	40.095
948.339	37.9265
951.672	37.876
955.004	37.2252
958.333	36.8118
961.662	35.5106
964.989	35.252
968.315	34.3282
971.639	33.7406
974.962	32.8655
978.285	32.241
981.605	31.7251
984.924	30.7125
988.243	29.0244
991.56	28.7809
994.875	29.3934
998.188	31.8111
1001.5	35.8653
1004.81	38.2038
1008.12	41.7235
1011.43	43.6208
1014.74	48.7048
1018.05	52.442
1021.35	55.3394
1024.65	56.5664
1027.96	56.8083
1031.26	60.4666
1034.56	61.7087
1037.86	61.0714
1041.16	58.9459
1044.45	57.0719
1047.75	53.358
1051.04	48.7329
1054.33	45.1371
1057.62	41.7049
1060.91	38.8345
1064.2	36.2917
1067.49	32.4512
1070.77	31.3093
1074.06	30.2854
1077.34	30.4301
1080.62	30.5301
1083.91	29.7644
1087.18	29.2082
1090.46	29.1617
1093.74	29.221
1097.02	29.9865
1100.29	29.9151
1103.56	29.4854
1106.84	29.0243
1110.11	27.7737
1113.38	26.3799
1116.64	24.5702
1119.91	22.1497
1123.18	19.0989
1126.44	16.7368
1129.7	14.8322
1132.97	13.4738
1136.23	11.6034
1139.49	10.4532
1142.74	9.1571
1146	7.48793
1149.26	6.22865
1152.51	5.1975
1155.76	3.08245
1159.01	0.708377
1162.27	-0.344361
1165.51	-0.736445
1168.76	0.209183
1172.01	0.466125
1175.25	1.6956
1178.5	2.77619
1181.74	4.07283
1184.98	4.26883
1188.22	4.41647
1191.46	4.53851
1194.7	6.68767
1197.94	7.63241
1201.17	8.83578
1204.41	9.97909
1207.64	9.966
1210.87	11.9375
1214.1	14.5513
1217.33	16.9533
1220.56	18.3229
1223.79	19.8089
1227.01	21.5951
1230.23	23.7128
1233.46	26.0579
1236.68	28.1062
1239.9	29.9953
1243.12	33.7014
1246.34	35.7153
1249.55	36.4718
1252.77	37.4463
1255.98	39.1997
1259.2	40.4877
1262.41	41.3342
1265.62	43.5311
1268.83	45.5012
1272.03	48.3774
1275.24	49.6802
1278.45	49.8324
1281.65	51.4564
1284.85	52.2761
1288.06	53.1662
1291.26	54.4976
1294.46	54.3577
1297.66	52.703
1300.85	51.3125
1304.05	51.0278
1307.24	50.4275
1310.43	50.9467
1313.63	49.5492
1316.82	50.1051
1320.01	49.4433
1323.2	47.2404
1326.38	44.8441
1329.57	42.2714
1332.76	39.672
1335.94	38.481
1339.12	36.336
1342.3	35.4841
1345.48	34.8192
1348.66	33.3401
1351.84	31.7622
1355.01	29.7939
1358.19	27.7174
1361.36	25.7824
1364.53	23.3478
1367.71	21.6242
1370.88	20.9326
1374.04	19.0542
1377.21	17.5628
1380.38	17.1611
1383.54	16.8339
1386.71	16.5559
1389.87	16.1601
1393.03	15.1462
1396.19	15.0072
1399.35	14.1937
1402.51	15.477
1405.67	16.1725
1408.82	17.2575
1411.98	20.5577
1415.13	24.2733
1418.28	28.4761
1421.43	34.2825
1424.58	39.2318
1427.73	44.3272
1430.88	47.5652
1434.02	50.3868
1437.17	54.0068
1440.31	56.135
1443.45	59.1219
1446.6	61.1106
1449.74	62.0964
1452.87	59.8509
1456.01	58.4968
1459.15	56.8496
1462.28	54.923
1465.42	51.4941
1468.55	46.9858
1471.68	44.7903
1474.81	42.2739
1477.94	37.6163
1481.07	33.8083
1484.2	31.5017
1487.32	28.9437
1490.45	27.5107
1493.57	26.2205
1496.69	25.1821
1499.81	23.0776
1502.93	21.7882
1506.05	18.9864
1509.17	16.3244
1512.28	13.546
1515.4	11.6721
1518.51	11.4247
1521.63	9.76057
1524.74	7.35437
1527.85	6.63561
1530.96	5.88308
1534.06	6.21742
1537.17	7.58898
1540.28	8.13869
1543.38	8.06557
1546.48	9.51962
1549.59	11.3616
1552.69	12.4868
1555.79	13.5974
1558.88	14.4119
1561.98	16.6846
1565.08	18.5996
1568.17	21.9755
1571.27	25.6503
1574.36	27.3825
1577.45	29.4687
1580.54	31.7307
1583.63	33.722
1586.72	36.59
1589.8	38.9017
1592.89	41.7789
1595.97	42.3837
1599.06	42.4439
1602.14	42.8757
1605.22	44.1114
1608.3	45.213
1611.38	46.4474
1614.46	46.5197
1617.53	46.9028
1620.61	48.7462
1623.68	49.6846
1626.75	51.549
1629.82	52.934
1632.9	53.604
1635.96	55.4995
1639.03	58.5855
1642.1	61.2309
1645.16	63.614
1648.23	65.7233
1651.29	66.4703
1654.36	67.4881
1657.42	68.2285
1660.48	70.6248
1663.53	69.6708
1666.59	67.5147
1669.65	65.0154
1672.7	60.1292
1675.76	55.6132
1678.81	51.4371
1681.86	47.9423
1684.91	42.5279
1687.96	36.8719
1691.01	30.8385
1694.06	26.6918
1697.11	22.9356
1700.15	19.3147
1703.2	16.6512
1706.24	13.9021
1709.28	11.8234
1712.32	9.85652
1715.36	8.51852
1718.4	6.46045
1721.43	6.04613
1724.47	4.69046
1727.5	4.66673
1730.54	5.3538
1733.57	5.27159
1736.6	6.19187
1739.63	5.19851
1742.66	4.02195
1745.69	2.70313
1748.72	2.02383
1751.74	2.31379
1754.77	2.05074
1757.79	1.25364
1760.81	0.186988
1763.83	-0.614105
1766.85	-0.513572
1769.87	-0.36731
1772.89	1.09457
1775.91	1.46438
1778.92	2.26819
1781.94	2.76329
1784.95	2.56961
1787.96	3.80804
1790.97	3.29113
1793.98	2.90546
1796.99	3.75832
1800	4.19467
1803	4.20735
1806.01	3.67462
1809.01	3.55904
1812.02	2.9675
1815.02	2.32668
1818.02	2.29793
1821.02	2.18645
1824.02	1.83452
1827.01	1.42826
1830.01	0.15119
1833	-0.526037
1836	1.27554
1838.99	2.06403
1841.98	2.00507
1844.97	2.34984
1847.96	1.90934
1850.95	1.62184
1853.94	2.15317
1856.92	1.83649
1859.91	1.89878
1862.89	1.88902
1865.88	1.44692
1868.86	2.09497
1871.84	3.2379
1874.82	4.11815
1877.8	3.35257
1880.77	3.83337
1882.51	3.71493
1885.5	4.25094
1888.48	4.79133
1891.47	4.64886
1894.46	4.96868
1897.44	4.89625
1900.42	4.55178
1903.41	4.98667
1906.39	6.1444
1909.37	6.95164
1912.35	5.70265
1915.32	5.37623
1918.3	4.64995
1921.28	4.43364
1924.25	4.29625
1927.22	4.65016
1930.2	4.01229
1933.17	4.27022
1936.14	4.28677
1939.11	5.44934
1942.08	6.14534
1945.04	5.0594
1948.01	4.9581
1950.97	5.43073
1953.94	5.47182
1956.9	5.37223
1959.86	5.76524
1962.82	5.2999
1965.78	6.17966
1968.74	6.72013
1971.69	6.1671
1974.65	6.72602
1977.61	6.99743
1980.56	6.21097
1983.51	5.35538
1986.46	4.67354
1989.41	2.62761
1992.36	2.12219
1995.31	2.60762
1998.26	3.05689
2001.2	3.48701
2004.15	3.40784
2007.09	2.72675
2010.04	2.99881
2012.98	1.81169
2015.92	1.97291
2018.86	2.45812
2021.8	3.43007
2024.74	3.89682
2027.67	5.03299
2030.61	5.39042
2033.54	7.60381
2036.47	8.86363
2039.41	10.8495
2042.34	11.2528
2045.27	12.6927
2048.2	15.2955
2051.12	15.9054
2054.05	16.8864
2056.98	16.8249
2059.9	16.7147
2062.82	17.1617
2065.75	19.5245
2068.67	21.804
2071.59	22.4994
2074.51	22.6298
2077.43	22.4193
2080.34	23.1704
2083.26	23.8646
2086.17	24.5644
2089.09	25.3989
2092	24.7565
2094.91	25.0574
2097.82	26.1475
2100.73	27.2989
2103.64	29.2981
2106.55	32.2759
2109.46	34.8063
2112.36	36.9593
2115.27	39.7585
2118.17	43.0955
2121.07	45.5437
2123.97	47.4254
2126.87	50.3024
2129.77	51.6552
2132.67	56.2511
2135.57	61.7762
2138.46	65.5887
2141.36	69.0035
2144.25	72.5802
2147.14	76.2379
2150.03	80.4419
2152.92	83.725
2155.81	86.2823
2158.7	86.8081
2161.59	88.1664
2164.48	88.3263
2167.36	89.3269
2170.25	89.4518
2173.13	89.7872
2176.01	88.5478
2178.89	88.2829
2181.77	85.7051
2184.65	81.9474
2187.53	78.9774
2190.41	76.9848
2193.28	74.3463
2196.16	71.8415
2199.03	68.2283
2201.9	65.2122
2204.78	62.9998
2207.65	60.8581
2210.51	58.1345
2213.38	55.4887
2216.25	53.4455
2219.12	51.1324
2221.98	47.7595
2224.85	43.9789
2227.71	41.6312
2230.57	38.4655
2233.43	35.9637
2236.29	33.3982
2239.15	30.8776
2242.01	29.3157
2244.87	26.8361
2247.73	24.2046
2250.58	23.2243
2253.43	21.3694
2256.29	20.1006
2259.14	20.3718
2261.99	20.0106
2264.84	19.4578
2267.69	18.1944
2270.54	17.5152
2273.38	17.2823
2276.23	16.5468
2279.07	16.0013
2281.92	15.3165
2284.76	14.9835
2287.6	14.1441
2290.44	12.2197
2293.28	10.4508
2296.12	9.76794
2298.96	10.8428
2301.79	10.211
2304.63	9.6137
2307.46	9.81951
2310.3	9.50245
2313.13	9.7214
2315.96	9.37271
2318.79	9.89373
2321.62	9.54631
2324.45	8.61156
2327.27	8.70744
2330.1	8.43265
2332.93	8.22774
2335.75	8.59417
2338.57	8.24186
2341.4	7.89277
2344.22	7.96638
2347.04	7.44189
2349.86	7.8668
2352.67	7.9938
2355.49	7.21162
2358.31	7.17265
2361.12	6.01345
2363.94	5.94423
2366.75	7.30116
2369.56	6.07066
2372.37	5.63707
2375.18	5.6993
2377.99	5.57581
2380.8	5.44557
2383.61	5.81508
2386.41	3.60201
2389.22	3.37304
2392.02	2.4974
2394.82	2.98358
2397.63	3.03785
2400.43	2.98352
2403.23	3.8014
2406.02	4.86951
2408.82	5.46721
2411.62	5.90017
2414.41	6.82936
2417.21	7.1127
2420	7.46741
2422.79	7.34423
2425.59	7.84391
2428.38	8.26927
2431.17	8.36942
2433.96	8.75433
2436.74	8.28491
2439.53	8.19106
2442.32	7.53407
2445.1	7.74259
2447.88	7.10961
2450.67	6.81722
2453.45	5.32149
2456.23	4.87509
2459.01	4.12805
2461.79	2.88406
2464.57	2.44204
2467.34	1.4401
2470.12	0.784485
2472.89	0.686289
2475.67	0.302256
2478.44	-0.253501
2481.21	-1.87612
2483.98	-1.67355
2486.75	-1.4916
2489.52	-1.29039
2492.29	-0.78017
2495.06	-0.468103
2497.82	0.447147
2500.59	0.893637
2503.35	0.988949
2506.11	0.744555
2508.88	1.56358
2511.63	2.09136
2514.39	2.70531
2517.15	2.48555
2519.91	3.09148
2522.67	3.27512
2525.42	3.08411
2528.18	1.77556
2530.93	2.41309
2533.69	2.74991
2536.44	3.14093
2539.19	3.80132
2541.94	4.08653
2544.69	4.40057
2547.44	4.69803
2550.18	4.47476
2552.93	5.79472
2555.68	5.81212
2558.42	6.12288
2561.16	5.91637
2563.9	6.21752
2566.64	6.65483
2569.38	6.49647
2572.12	6.27387
2574.86	6.34558
2577.6	6.73534
2580.34	6.05805
2583.07	5.10653
2585.81	4.44361
2588.54	3.88503
2591.27	3.89069
2594	4.17813
2596.73	3.85156
2599.46	3.32769
2602.19	3.71216
2604.92	4.59254
2607.64	4.64056
2610.37	4.04656
2613.09	4.19336
2615.82	3.51927
2618.54	3.9515
2621.26	4.64068
2623.98	5.77835
2626.7	6.598
2629.42	7.54943
2632.14	7.94892
2634.86	8.60855
2637.57	9.28286
2640.29	8.40383
2643	9.67744
2645.72	9.42504
2648.43	9.14437
2651.14	8.744
2653.85	8.62634
2656.56	8.67436
2659.27	8.40001
2661.97	8.39945
2664.68	8.33249
2667.38	8.49763
2670.09	7.60395
2672.79	6.77575
2675.49	5.5714
2678.2	4.77151
2680.89	4.38598
2683.59	4.28525
2686.29	5.83225
2688.99	6.65183
2691.69	7.02104
2694.38	7.72965
2697.08	7.78931
2699.77	7.74888
2702.46	7.90257
2705.16	7.46818
2707.85	7.53042
2710.54	7.73465
2713.23	7.04525
2715.92	7.77162
2718.6	7.31887
2721.29	7.8509
2723.97	8.17167
2726.66	7.86696
2729.34	7.42872
2732.02	6.00963
2734.7	4.70572
2737.39	4.23471
2740.06	3.26916
2742.74	2.98425
2745.42	2.18255
2748.1	1.58682
2750.77	1.92451
2753.45	1.53613
2756.12	0.715416
2758.79	0.73431
2761.47	0.775166
2764.14	0.579241
2766.81	-0.164382
2769.48	-0.117659
2772.14	0.0703313
2774.81	0.566438
2777.48	0.197499
2780.14	1.09494
2782.81	1.61515
2785.47	1.94654
2788.13	2.05562
2790.79	1.10748
2793.46	1.25749
2796.11	0.418621
2798.77	0.985183
2801.43	1.07334
2804.09	0.180441
2806.74	-0.0497824
2809.4	-0.168923
2812.05	-0.87415
2814.71	-1.70752
2817.36	-1.12097
2820.01	0.330538
2822.66	3.02949
2825.31	5.91367
2827.96	9.67543
2830.61	13.2916
2833.25	16.9079
2835.9	20.5963
2838.54	25.1014
2841.18	30.2829
2843.83	35.7816
2846.47	41.2749
2849.11	46.8535
2851.75	53.0574
2854.39	58.1119
2857.03	63.2674
2859.67	68.277
2862.3	72.7763
2864.94	77.3588
2867.57	80.3075
2870.21	82.7248
2872.84	86.3488
2875.47	88.7797
2878.1	90.5566
2880.73	93.4111
2883.36	97.7727
2885.99	102.186
2888.61	105.804
2891.24	110.02
2893.87	113.238
2896.49	118.699
2899.11	123.667
2901.74	129.612
2904.36	136.923
2906.98	144.688
2909.6	153.404
2912.22	161.689
2914.83	169.369
2917.45	176.906
2920.07	185.28
2922.68	190.792
2925.3	195.626
2927.91	198.887
2930.52	200.002
2933.13	200.872
2935.74	200.345
2938.35	197.196
2940.96	193.216
2943.57	187.799
2946.18	182.753
2948.78	175.521
2951.39	168.268
2953.99	158.871
2956.6	150.702
2959.2	141.361
2961.8	133.589
2964.4	125.148
2967	117.282
2969.6	109.096
2972.2	102.581
2974.79	95.3849
2977.39	88.3413
2979.98	81.1962
2982.58	75.4149
2985.17	68.2448
2987.76	60.4364
2990.36	53.5117
2992.95	46.4721
2995.54	40.1777
2998.12	34.1549
3000.71	27.2606
3003.3	22.2011
3005.88	18.0062
3008.47	14.8774
3011.05	11.5094
3013.64	8.24014
3016.22	6.93566
3018.8	4.38445
3021.38	3.79057
3023.96	3.51117
3026.54	3.12277
3029.12	4.10309
3031.69	4.16731
3034.27	4.90766
3036.85	5.17139
3039.42	5.78463
3041.99	7.10301
3044.57	8.23366
3047.14	9.77209
3049.71	11.3773
3052.28	11.831
3054.85	12.6061
3057.42	12.6731
3059.98	12.8272
3062.55	12.3661
3065.11	11.4931
3067.68	10.7921
3070.24	10.5016
3072.8	9.51973
3075.37	8.34431
3077.93	7.34216
3080.49	6.82089
3083.05	6.37606
3085.61	6.32378
3088.16	5.92484
3090.72	6.20786
3093.27	5.94338
3095.83	5.93449
3098.38	6.76782
3100.94	8.45908
3103.49	10.4873
3106.04	12.4927
3108.59	14.9144
3111.14	16.9618
3113.69	18.9001
3116.23	20.4646
3118.78	22.1006
3121.33	23.1661
3123.87	24.6917
3126.42	26.1303
3128.96	26.7704
3131.5	28.3669
3134.04	29.756
3136.58	31.4028
3139.12	32.2972
3141.66	33.681
3144.2	35.2606
3146.74	36.8586
3149.27	38.5277