File: data/Raman/poly_smoothed/Mb_50_18_27_1x_45s_532 nm_x100_100%_600 gr_mm_01.txt
#Acq. time (s)=	45
#Accumulations=	2
#Range (cm-¹)=	200...3150
#Windows=	2
#Auto scanning=	Off
#Autofocus=	Off
#Macrospot=	Off
#AutoExposure=	Off
#Spike filter=	Multiple accum.
#Delay time (s)=	0
#Binning=	1
#Readout mode=	Signal
#DeNoise=	Off
#ICS correction=	On
#Dark correction=	Off
#Inst. Process=	Off
#Detector Gain=	Best Dynamic Range
#Detector ADC=	20 kHz
#Detector temperature (°C)=	-69.85
#Instrument=	LabRAM HR Evol
#Detector=	Synapse
#Objective=	x100
#Grating=	600 gr/mm
#ND Filter=	100%
#Laser (nm)=	532
#Hole=	100.021
#Range=	Auto
#Laser Pol.=	No
#Raman. Pol.=	No
#Laser Pol. (°)=	-0.0007625
#Raman Pol. (°)=	89.9995
#Collection=	Microscope
#StageXY=	Marzhauser
#StageZ=	Marzhauser
#X (µm)=	28317.4
#Y (µm)=	-3288.5
#Z (µm)=	1040.95
#Full time(mm:ss)=	3:19
#Project=
#Sample=
#Site=
#Title=	Mb_50_18_27_2x_45s_532 nm_x100_100%_600 gr_mm
#Remark=
#Date=	12.07.2022 12:51
#Acquired=	12.07.2022 12:51:29
#Base:Fit=	10.08.2022 10:49:18
#Base:Sub=	10.08.2022 10:49:30
#Filter:Polynom=	16.08.2022 10:14:59
#AxisType[0]=Intens
#AxisUnit[0]=Cnt
#AxisType[1]=Spectr
#AxisUnit[1]=1/cm
200.388	64.7043
204.019	59.2746
207.646	55.4526
211.274	52.76
214.899	47.9583
218.524	42.7252
222.146	36.7684
225.766	32.9871
229.388	29.2064
233.005	26.9433
236.621	25.7181
240.236	23.5308
243.852	21.437
247.464	21.5562
251.074	18.915
254.683	17.1102
258.291	17.0195
261.897	14.1568
265.504	11.8724
269.108	10.3011
272.71	9.49105
276.311	9.08595
279.91	9.19621
283.508	7.35635
287.105	7.46475
290.698	10.4402
294.291	13.3943
297.884	16.7086
301.475	17.6049
305.064	20.3221
308.652	21.4112
312.237	24.7664
315.822	28.6949
319.406	30.3059
322.987	33.3469
326.568	35.6539
330.148	34.6928
333.724	33.4639
337.301	30.2647
340.875	25.8492
344.449	24.4704
348.02	25.9243
351.592	28.1588
355.16	34.9214
358.728	40.0002
362.294	47.6421
365.858	54.1414
369.422	64.3604
372.983	72.1471
376.543	79.2972
380.102	84.2812
383.661	88.7271
387.216	90.6115
390.771	90.7602
394.324	90.3306
397.875	86.7455
401.425	82.8849
404.974	77.4695
408.524	69.7823
412.07	59.9959
415.614	48.5807
419.156	36.0802
422.698	25.4252
426.238	15.9294
429.777	8.54866
433.315	4.35539
436.852	2.69203
440.387	0.633688
443.919	0.677755
447.451	1.59229
450.982	2.7051
454.512	4.30787
458.038	3.6757
461.565	4.02511
465.091	4.75489
468.613	5.60769
472.136	8.13781
475.655	11.0474
479.176	16.8722
482.692	24.7835
486.21	31.2217
489.724	42.3322
493.237	53.0218
496.75	61.9201
500.26	70.303
503.771	78.0434
507.279	84.5109
510.785	90.0788
514.289	92.945
517.793	93.9952
521.297	95.1902
524.797	93.8169
528.297	90.7297
531.795	87.1986
535.291	80.4005
538.787	71.7336
542.281	62.915
545.773	52.8161
549.264	42.7458
552.754	31.5505
556.243	22.6272
559.73	13.305
563.216	9.2092
566.701	7.16333
570.182	7.36013
573.664	8.34994
577.145	8.525
580.624	10.1149
584.1	10.9713
587.577	12.2379
591.052	12.8701
594.524	16.8447
597.997	19.238
601.466	23.0125
604.936	26.7608
608.403	29.3589
611.87	30.4729
615.334	31.6648
618.799	32.4678
622.26	31.8814
625.72	30.6479
629.181	28.534
632.638	26.0662
636.095	23.8419
639.551	22.0498
643.005	18.6873
646.457	16.8394
649.908	15.9333
653.357	14.9198
656.806	14.1112
660.253	10.9725
663.7	8.18412
667.145	4.99962
670.588	3.28459
674.027	2.62664
677.468	3.54354
680.907	6.36353
684.345	5.91356
687.781	7.20344
691.216	6.6532
694.65	8.48707
698.081	9.41434
701.512	10.4692
704.942	11.0612
708.371	12.9954
711.796	13.7523
715.222	13.6519
718.645	14.0465
722.068	13.0326
725.49	12.5383
728.909	13.1438
732.329	16.1981
735.745	19.7373
739.16	30.1398
742.576	46.5908
745.988	63.3596
749.401	80.2678
752.811	98.9524
756.22	117.405
759.627	133.089
763.035	145.981
766.44	155.793
769.843	162.386
773.245	167.719
776.646	170.631
780.046	169.546
783.444	164.902
786.841	157.888
790.237	150.192
793.631	138.374
797.024	124.075
800.416	108.718
803.807	93.4047
807.196	77.4717
810.584	64.4134
813.971	54.3583
817.354	48.6385
820.739	45.4476
824.122	45.0112
827.503	44.1279
830.882	42.0562
834.261	41.1488
837.637	39.6103
841.013	37.3916
844.389	36.3238
847.761	36.2372
851.131	34.0108
854.503	31.7576
857.871	30.0675
861.24	28.443
864.606	25.6002
867.97	23.5996
871.336	23.1822
874.698	22.6369
878.058	21.2809
881.418	19.7353
884.778	19.7947
888.135	19.1885
891.49	18.3455
894.845	17.8771
898.198	16.5688
901.55	14.9015
904.901	14.761
908.25	14.5732
911.598	13.9414
914.945	13.5023
918.291	14.9282
921.635	16.1762
924.978	16.2667
928.318	17.1457
931.659	17.9616
934.998	17.811
938.336	18.6652
941.671	16.8823
945.007	14.5507
948.339	13.5244
951.672	10.7755
955.004	8.56935
958.333	6.15416
961.662	0.520608
964.989	-2.76178
968.315	-4.09189
971.639	-1.56571
974.962	4.55317
978.285	13.4039
981.605	23.2712
984.924	33.4294
988.243	41.6336
991.56	51.8611
994.875	60.8871
998.188	74.8604
1001.5	89.6441
1004.81	103.216
1008.12	115.563
1011.43	128.111
1014.74	138.436
1018.05	145.272
1021.35	148.737
1024.65	149.77
1027.96	148.39
1031.26	143.86
1034.56	133.854
1037.86	122.519
1041.16	108.518
1044.45	94.1922
1047.75	83.233
1051.04	76.6869
1054.33	71.0165
1057.62	66.697
1060.91	64.2673
1064.2	64.6936
1067.49	62.3834
1070.77	64.1007
1074.06	67.01
1077.34	70.9395
1080.62	74.3744
1083.91	77.3609
1087.18	78.7646
1090.46	80.9702
1093.74	83.6736
1097.02	85.8197
1100.29	84.1426
1103.56	80.5797
1106.84	76.4427
1110.11	70.7865
1113.38	64.0329
1116.64	55.8183
1119.91	46.3119
1123.18	35.5785
1126.44	29.5238
1129.7	24.6153
1132.97	20.5203
1136.23	20.1142
1139.49	18.5415
1142.74	18.5769
1146	17.4704
1149.26	16.199
1152.51	14.1042
1155.76	10.5529
1159.01	7.43183
1162.27	6.27309
1165.51	6.31839
1168.76	5.41757
1172.01	7.99536
1175.25	7.79865
1178.5	6.64866
1181.74	5.98401
1184.98	4.68044
1188.22	3.98977
1191.46	2.66507
1194.7	2.72462
1197.94	2.88688
1201.17	3.27216
1204.41	5.78888
1207.64	7.78591
1210.87	9.89339
1214.1	12.605
1217.33	16.1617
1220.56	18.4657
1223.79	22.1642
1227.01	24.9433
1230.23	29.4397
1233.46	30.9894
1236.68	34.5218
1239.9	37.266
1243.12	39.1412
1246.34	40.9702
1249.55	43.1148
1252.77	44.3653
1255.98	46.559
1259.2	47.3778
1262.41	46.5223
1265.62	46.8731
1268.83	49.5894
1272.03	52.1382
1275.24	55.5186
1278.45	58.6217
1281.65	59.9692
1284.85	62.8475
1288.06	63.9782
1291.26	68.0242
1294.46	69.831
1297.66	69.5525
1300.85	71.1339
1304.05	71.2845
1307.24	70.8142
1310.43	69.848
1313.63	68.7157
1316.82	67.5432
1320.01	66.1115
1323.2	63.5154
1326.38	61.7443
1329.57	59.2811
1332.76	57.7237
1335.94	55.5877
1339.12	52.1484
1342.3	50.2451
1345.48	46.9909
1348.66	45.6393
1351.84	42.7054
1355.01	41.2299
1358.19	38.3564
1361.36	35.9563
1364.53	35.6252
1367.71	33.5543
1370.88	32.3553
1374.04	30.9424
1377.21	30.3079
1380.38	29.6674
1383.54	29.5644
1386.71	30.2078
1389.87	29.7634
1393.03	29.4932
1396.19	31.0821
1399.35	30.8945
1402.51	34.1919
1405.67	37.7825
1408.82	42.5779
1411.98	48.9851
1415.13	55.0432
1418.28	61.9427
1421.43	69.9875
1424.58	78.3885
1427.73	88.2746
1430.88	96.0389
1434.02	102.48
1437.17	106.745
1440.31	109.572
1443.45	111.309
1446.6	111.174
1449.74	109.678
1452.87	106.171
1456.01	101.865
1459.15	96.3418
1462.28	88.6569
1465.42	80.3498
1468.55	71.3529
1471.68	61.7193
1474.81	55.9023
1477.94	49.9871
1481.07	45.9623
1484.2	41.4844
1487.32	40.722
1490.45	39.6134
1493.57	38.2311
1496.69	39.2118
1499.81	39.1364
1502.93	38.9454
1506.05	38.2379
1509.17	38.5275
1512.28	36.1128
1515.4	33.8657
1518.51	32.9805
1521.63	31.2151
1524.74	31.3645
1527.85	30.004
1530.96	28.7496
1534.06	28.3058
1537.17	28.6894
1540.28	27.8143
1543.38	27.8507
1546.48	28.9036
1549.59	29.6554
1552.69	31.5161
1555.79	32.1111
1558.88	33.3007
1561.98	35.8097
1565.08	39.08
1568.17	42.1175
1571.27	45.9517
1574.36	49.8611
1577.45	52.619
1580.54	55.9695
1583.63	60.542
1586.72	63.1673
1589.8	63.6958
1592.89	63.3969
1595.97	66.2953
1599.06	68.9422
1602.14	70.6448
1605.22	71.4241
1608.3	70.7681
1611.38	70.9499
1614.46	72.5268
1617.53	73.3025
1620.61	72.8383
1623.68	72.9032
1626.75	75.1905
1629.82	78.0863
1632.9	80.8516
1635.96	84.3651
1639.03	88.2925
1642.1	90.981
1645.16	93.8456
1648.23	95.9902
1651.29	98.4463
1654.36	99.0884
1657.42	98.5178
1660.48	96.8093
1663.53	92.9783
1666.59	87.8707
1669.65	84.2352
1672.7	80.3575
1675.76	73.933
1678.81	66.5884
1681.86	59.2046
1684.91	52.5137
1687.96	46.4403
1691.01	40.8886
1694.06	34.5829
1697.11	30.5174
1700.15	27.8409
1703.2	25.1393
1706.24	21.3864
1709.28	17.2662
1712.32	14.2862
1715.36	11.4601
1718.4	10.0582
1721.43	7.249
1724.47	5.6629
1727.5	4.81508
1730.54	3.83337
1733.57	3.43863
1736.6	3.59472
1739.63	2.6486
1742.66	3.09199
1745.69	2.40356
1748.72	2.06533
1751.74	1.18017
1754.77	1.32156
1757.79	0.507284
1760.81	0.53549
1763.83	-0.00900794
1766.85	-0.703115
1769.87	0.328366
1772.89	0.509262
1775.91	0.133881
1778.92	0.0580396
1781.94	1.41156
1784.95	1.38727
1787.96	1.24618
1790.97	2.24697
1793.98	2.8727
1796.99	3.94034
1800	5.00298
1803	5.02389
1806.01	6.07914
1809.01	7.45096
1812.02	8.2984
1815.02	9.30625
1818.02	8.76031
1821.02	9.02841
1824.02	9.15604
1827.01	9.02146
1830.01	8.79701
1833	8.63225
1836	8.64972
1838.99	7.87376
1841.98	6.89423
1844.97	6.82215
1847.96	6.47607
1850.95	5.26231
1853.94	5.77489
1856.92	4.81194
1859.91	3.2314
1862.89	2.96386
1865.88	2.86939
1868.86	2.49032
1871.84	2.47252
1874.82	2.17736
1877.8	2.70161
1880.77	3.73749
1882.51	3.98642
1885.5	4.11201
1888.48	4.28386
1891.47	4.84745
1894.46	5.6716
1897.44	7.74687
1900.42	7.86807
1903.41	8.45343
1906.39	10.194
1909.37	11.4573
1912.35	11.919
1915.32	11.5383
1918.3	11.6358
1921.28	12.5868
1924.25	12.2206
1927.22	12.1656
1930.2	11.159
1933.17	11.7989
1936.14	12.166
1939.11	12.7554
1942.08	12.3173
1945.04	12.7536
1948.01	12.4364
1950.97	12.8611
1953.94	11.747
1956.9	12.3845
1959.86	11.714
1962.82	10.9743
1965.78	11.2069
1968.74	12.8363
1971.69	11.5231
1974.65	10.6513
1977.61	12.1356
1980.56	12.2528
1983.51	12.343
1986.46	12.0744
1989.41	12.1022
1992.36	12.2601
1995.31	12.4913
1998.26	11.4833
2001.2	12.1368
2004.15	11.8698
2007.09	11.8998
2010.04	11.6688
2012.98	12.8709
2015.92	13.5095
2018.86	14.265
2021.8	15.4348
2024.74	15.8518
2027.67	16.9082
2030.61	17.1455
2033.54	18.2861
2036.47	18.7558
2039.41	20.9851
2042.34	23.1438
2045.27	22.7141
2048.2	25.0806
2051.12	26.6075
2054.05	27.4251
2056.98	29.0621
2059.9	31.0757
2062.82	31.3386
2065.75	32.4487
2068.67	33.4755
2071.59	34.3585
2074.51	35.9838
2077.43	37.3487
2080.34	39.3089
2083.26	41.6051
2086.17	43.8627
2089.09	45.6646
2092	48.1198
2094.91	49.2716
2097.82	51.0634
2100.73	54.3899
2103.64	57.5084
2106.55	60.7256
2109.46	63.1632
2112.36	66.5129
2115.27	70.7926
2118.17	75.4903
2121.07	79.5962
2123.97	84.2115
2126.87	89.1743
2129.77	94.7427
2132.67	100.211
2135.57	106.311
2138.46	112.509
2141.36	117.086
2144.25	122.873
2147.14	128.404
2150.03	133.834
2152.92	138.026
2155.81	141.849
2158.7	145.771
2161.59	146.466
2164.48	147.917
2167.36	147.111
2170.25	148.815
2173.13	147.447
2176.01	144.41
2178.89	142.416
2181.77	139.614
2184.65	137.425
2187.53	134.83
2190.41	130.004
2193.28	125.115
2196.16	122.373
2199.03	119.151
2201.9	114.319
2204.78	110.328
2207.65	106.543
2210.51	101.337
2213.38	96.5483
2216.25	92.1608
2219.12	88.5567
2221.98	84.0139
2224.85	80.8621
2227.71	75.6526
2230.57	69.978
2233.43	64.5521
2236.29	61.1086
2239.15	56.718
2242.01	52.0535
2244.87	46.9485
2247.73	43.7367
2250.58	40.715
2253.43	38.5622
2256.29	37.2384
2259.14	34.4763
2261.99	34.2427
2264.84	33.3884
2267.69	32.3908
2270.54	30.4089
2273.38	29.3929
2276.23	29.5924
2279.07	29.0254
2281.92	27.4721
2284.76	25.3748
2287.6	25.4492
2290.44	24.7526
2293.28	22.739
2296.12	22.1304
2298.96	20.4168
2301.79	18.5554
2304.63	18.0765
2307.46	16.9819
2310.3	15.2395
2313.13	13.8823
2315.96	14.3179
2318.79	13.4509
2321.62	12.5267
2324.45	11.5592
2327.27	11.6614
2330.1	11.3355
2332.93	9.79331
2335.75	9.05196
2338.57	7.67133
2341.4	7.20851
2344.22	6.63932
2347.04	5.14984
2349.86	4.18211
2352.67	2.56669
2355.49	3.30471
2358.31	3.0099
2361.12	2.57339
2363.94	3.13282
2366.75	3.49778
2369.56	2.6969
2372.37	2.83641
2375.18	2.77013
2377.99	2.66258
2380.8	3.13941
2383.61	3.96416
2386.41	4.8585
2389.22	4.03775
2392.02	4.51151
2394.82	5.65352
2397.63	6.92066
2400.43	5.4171
2403.23	6.89375
2406.02	7.35325
2408.82	7.43323
2411.62	7.78629
2414.41	8.05543
2417.21	9.23953
2420	9.42307
2422.79	9.74648
2425.59	9.59158
2428.38	8.22585
2431.17	7.63386
2433.96	8.30908
2436.74	6.86253
2439.53	5.02024
2442.32	4.56408
2445.1	4.32106
2447.88	2.92442
2450.67	3.00499
2453.45	2.40477
2456.23	1.87969
2459.01	1.40547
2461.79	1.14249
2464.57	0.266506
2467.34	-0.311233
2470.12	-0.371583
2472.89	-0.258184
2475.67	-1.06687
2478.44	-1.22595
2481.21	-1.37443
2483.98	-1.58308
2486.75	-1.56049
2489.52	-1.11246
2492.29	-1.52146
2495.06	-0.623841
2497.82	0.925236
2500.59	1.44787
2503.35	0.782734
2506.11	0.615641
2508.88	1.3461
2511.63	2.50216
2514.39	2.73667
2517.15	2.73007
2519.91	3.80138
2522.67	4.1366
2525.42	4.69424
2528.18	5.73197
2530.93	4.98017
2533.69	5.26735
2536.44	5.95272
2539.19	5.88893
2541.94	5.32328
2544.69	4.58743
2547.44	4.9701
2550.18	3.83582
2552.93	4.07415
2555.68	4.33879
2558.42	4.34778
2561.16	4.18417
2563.9	4.04509
2566.64	3.46144
2569.38	3.73934
2572.12	3.08188
2574.86	3.78243
2577.6	4.60247
2580.34	4.8101
2583.07	5.35078
2585.81	4.71175
2588.54	4.97471
2591.27	5.91987
2594	5.66329
2596.73	5.01855
2599.46	3.6632
2602.19	5.12775
2604.92	4.41677
2607.64	4.15962
2610.37	4.31877
2613.09	4.7619
2615.82	5.29127
2618.54	4.59096
2621.26	5.05196
2623.98	5.13842
2626.7	5.19943
2629.42	5.65778
2632.14	6.46986
2634.86	6.39647
2637.57	7.73001
2640.29	8.51858
2643	9.296
2645.72	10.0906
2648.43	11.4205
2651.14	11.7523
2653.85	11.6811
2656.56	11.4206
2659.27	12.015
2661.97	10.9763
2664.68	10.2055
2667.38	11.1355
2670.09	10.6464
2672.79	10.2961
2675.49	9.96556
2678.2	9.01966
2680.89	7.73132
2683.59	5.76314
2686.29	5.23822
2688.99	4.4718
2691.69	3.23277
2694.38	3.36901
2697.08	2.3034
2699.77	2.0016
2702.46	0.671394
2705.16	1.38795
2707.85	2.2967
2710.54	3.38222
2713.23	4.57468
2715.92	6.2916
2718.6	5.80254
2721.29	6.00824
2723.97	7.68769
2726.66	8.98531
2729.34	8.60028
2732.02	8.49914
2734.7	8.42532
2737.39	8.13819
2740.06	8.69691
2742.74	7.43352
2745.42	7.11234
2748.1	6.52789
2750.77	7.46023
2753.45	8.88909
2756.12	8.44792
2758.79	8.23123
2761.47	7.99903
2764.14	7.46264
2766.81	6.67686
2769.48	8.23445
2772.14	9.49311
2774.81	9.55626
2777.48	9.17104
2780.14	7.9311
2782.81	8.82224
2785.47	7.43636
2788.13	6.59954
2790.79	6.0177
2793.46	4.09831
2796.11	2.4652
2798.77	1.70788
2801.43	1.16946
2804.09	0.326506
2806.74	-1.62661
2809.4	-3.09207
2812.05	-2.15476
2814.71	-1.86022
2817.36	0.832672
2820.01	3.46045
2822.66	6.62499
2825.31	13.045
2827.96	19.5089
2830.61	26.8213
2833.25	35.2687
2835.9	42.3178
2838.54	49.8086
2841.18	58.881
2843.83	70.1416
2846.47	81.426
2849.11	91.8089
2851.75	102.065
2854.39	112.515
2857.03	122.243
2859.67	131.164
2862.3	140.4
2864.94	148.171
2867.57	153.342
2870.21	159.419
2872.84	165.614
2875.47	170.274
2878.1	173.138
2880.73	179.152
2883.36	184.007
2885.99	188.642
2888.61	194.256
2891.24	200.405
2893.87	206.942
2896.49	214.287
2899.11	222.394
2901.74	232.617
2904.36	244.812
2906.98	258.596
2909.6	273.288
2912.22	288.234
2914.83	303.348
2917.45	318.481
2920.07	332.634
2922.68	343.95
2925.3	354.542
2927.91	361.306
2930.52	367.209
2933.13	368.901
2935.74	370.105
2938.35	365.822
2940.96	357.607
2943.57	348.405
2946.18	337.293
2948.78	324.525
2951.39	310.571
2953.99	296.625
2956.6	282.131
2959.2	267.385
2961.8	253.503
2964.4	239.737
2967	225.884
2969.6	213.434
2972.2	201.647
2974.79	189.789
2977.39	178.497
2979.98	167.688
2982.58	156.649
2985.17	144.254
2987.76	133.707
2990.36	123.059
2992.95	112.185
2995.54	100.928
2998.12	89.9154
3000.71	77.8791
3003.3	67.3013
3005.88	57.5804
3008.47	48.8951
3011.05	41.402
3013.64	35.9199
3016.22	29.9588
3018.8	25.6316
3021.38	20.7466
3023.96	16.5697
3026.54	12.7339
3029.12	9.45787
3031.69	7.92809
3034.27	5.82551
3036.85	5.40978
3039.42	4.77835
3041.99	6.96504
3044.57	6.78711
3047.14	7.78742
3049.71	9.78227
3052.28	10.2664
3054.85	10.0593
3057.42	10.0223
3059.98	9.97403
3062.55	9.43451
3065.11	9.63991
3067.68	9.05617
3070.24	8.08941
3072.8	8.43799
3075.37	8.34307
3077.93	7.9562
3080.49	5.95397
3083.05	4.91008
3085.61	3.44757
3088.16	2.15172
3090.72	2.07225
3093.27	1.72476
3095.83	1.73798
3098.38	3.03641
3100.94	4.17194
3103.49	5.94599
3106.04	7.47703
3108.59	9.58143
3111.14	12.0357
3113.69	15.5107
3116.23	18.374
3118.78	21.188
3121.33	23.3934
3123.87	25.859
3126.42	27.5894
3128.96	30.7227
3131.5	33.6357
3134.04	37.0607
3136.58	39.2158
3139.12	41.65
3141.66	42.5743
3144.2	42.3061
3146.74	40.26
3149.27	37.0325