File: data/Raman/poly_smoothed/Mb_50_18_35_1x_45s_532 nm_x100_100%_600 gr_mm_01.txt
#Acq. time (s)=	45
#Accumulations=	2
#Range (cm-¹)=	200...3150
#Windows=	2
#Auto scanning=	Off
#Autofocus=	Off
#Macrospot=	Off
#AutoExposure=	Off
#Spike filter=	Multiple accum.
#Delay time (s)=	0
#Binning=	1
#Readout mode=	Signal
#DeNoise=	Off
#ICS correction=	On
#Dark correction=	Off
#Inst. Process=	Off
#Detector Gain=	Best Dynamic Range
#Detector ADC=	20 kHz
#Detector temperature (°C)=	-69.85
#Instrument=	LabRAM HR Evol
#Detector=	Synapse
#Objective=	x100
#Grating=	600 gr/mm
#ND Filter=	100%
#Laser (nm)=	532
#Hole=	100.021
#Range=	Auto
#Laser Pol.=	No
#Raman. Pol.=	No
#Laser Pol. (°)=	-0.0007625
#Raman Pol. (°)=	89.9995
#Collection=	Microscope
#StageXY=	Marzhauser
#StageZ=	Marzhauser
#X (µm)=	28307.3
#Y (µm)=	-3221.3
#Z (µm)=	1041.05
#Full time(mm:ss)=	3:19
#Project=
#Sample=
#Site=
#Title=	Mb_50_18_35_2x_45s_532 nm_x100_100%_600 gr_mm
#Remark=
#Date=	12.07.2022 13:35
#Acquired=	12.07.2022 13:35:37
#Base:Fit=	10.08.2022 10:49:18
#Base:Sub=	10.08.2022 10:49:30
#Filter:Polynom=	16.08.2022 10:14:59
#AxisType[0]=Intens
#AxisUnit[0]=Cnt
#AxisType[1]=Spectr
#AxisUnit[1]=1/cm
200.388	7.80457
204.019	14.4264
207.646	18.1456
211.274	20.1105
214.899	21.7337
218.524	24.6224
222.146	24.6212
225.766	26.4473
229.388	28.003
233.005	30.6429
236.621	33.436
240.236	36.3248
243.852	36.9837
247.464	38.0691
251.074	37.5996
254.683	36.5651
258.291	37.7992
261.897	37.5685
265.504	37.2554
269.108	36.0187
272.71	33.8469
276.311	34.4346
279.91	34.7167
283.508	33.1479
287.105	30.501
290.698	29.7542
294.291	30.4509
297.884	31.5412
301.475	31.1213
305.064	33.4498
308.652	33.6051
312.237	30.4976
315.822	31.7763
319.406	34.0081
322.987	33.9921
326.568	34.975
330.148	32.5568
333.724	27.8139
337.301	23.949
340.875	21.1771
344.449	19.9633
348.02	19.9585
351.592	22.2857
355.16	26.8459
358.728	33.5094
362.294	44.0224
365.858	51.0651
369.422	58.8759
372.983	65.9541
376.543	75.031
380.102	79.3313
383.661	82.1816
387.216	84.5505
390.771	82.8066
394.324	80.1264
397.875	76.6281
401.425	74.2119
404.974	69.3651
408.524	63.7289
412.07	53.2518
415.614	40.7549
419.156	28.7734
422.698	17.7721
426.238	11.2143
429.777	6.4743
433.315	2.96407
436.852	2.66046
440.387	1.08127
443.919	2.72269
447.451	4.48585
450.982	4.98965
454.512	5.16623
458.038	4.7151
461.565	3.4607
465.091	3.82349
468.613	0.957864
472.136	1.93938
475.655	2.98429
479.176	6.01823
482.692	10.322
486.21	18.9506
489.724	29.7249
493.237	37.1287
496.75	46.1502
500.26	53.6076
503.771	61.8531
507.279	70.8447
510.785	80.1176
514.289	86.2121
517.793	90.2377
521.297	93.3718
524.797	91.6295
528.297	87.2729
531.795	83.2085
535.291	79.0717
538.787	70.8858
542.281	61.0069
545.773	52.232
549.264	42.0536
552.754	32.8957
556.243	23.2638
559.73	18.5994
563.216	15.5158
566.701	14.9214
570.182	14.7259
573.664	18.5157
577.145	19.3003
580.624	21.5023
584.1	23.2627
587.577	24.8782
591.052	28.6846
594.524	30.9261
597.997	32.8636
601.466	31.4092
604.936	30.8283
608.403	27.9788
611.87	26.9008
615.334	24.6076
618.799	21.7041
622.26	17.7511
625.72	13.7291
629.181	10.8114
632.638	6.70662
636.095	4.20306
639.551	3.5583
643.005	2.65463
646.457	5.27563
649.908	6.70724
653.357	8.3182
656.806	7.41488
660.253	8.07248
663.7	8.95366
667.145	9.95993
670.588	13.0745
674.027	16.5281
677.468	17.5986
680.907	21.9518
684.345	25.1005
687.781	28.0027
691.216	31.5716
694.65	34.6726
698.081	36.123
701.512	36.298
704.942	36.35
708.371	37.4782
711.796	36.4002
715.222	37.2136
718.645	35.674
722.068	37.3572
725.49	37.0577
728.909	38.2625
732.329	41.8833
735.745	48.697
739.16	59.6988
742.576	75.4218
745.988	94.4788
749.401	115.358
752.811	136.93
756.22	158.244
759.627	174.748
763.035	190.613
766.44	206.072
769.843	215.185
773.245	222.467
776.646	226.752
780.046	225.749
783.444	221.381
786.841	217.05
790.237	208.435
793.631	197.157
797.024	185.373
800.416	168.341
803.807	152.304
807.196	139.688
810.584	124.387
813.971	115.425
817.354	109.602
820.739	105.94
824.122	107.224
827.503	108.665
830.882	109.936
834.261	109.881
837.637	108.327
841.013	106.596
844.389	104.271
847.761	102.814
851.131	99.8576
854.503	96.3447
857.871	93.141
861.24	88.6969
864.606	84.9892
867.97	82.7957
871.336	81.5552
874.698	78.3813
878.058	76.4008
881.418	70.5519
884.778	68.4091
888.135	66.4152
891.49	61.8718
894.845	57.4416
898.198	57.6656
901.55	56.1403
904.901	56.65
908.25	58.5882
911.598	56.2643
914.945	55.2683
918.291	54.7703
921.635	51.5556
924.978	51.5507
928.318	51.93
931.659	49.5042
934.998	46.8179
938.336	45.4357
941.671	41.8833
945.007	37.3658
948.339	37.9073
951.672	35.1047
955.004	33.9111
958.333	30.0949
961.662	25.2138
964.989	18.5222
968.315	15.3092
971.639	13.1033
974.962	12.8658
978.285	10.7625
981.605	5.69298
984.924	1.55297
988.243	1.64338
991.56	1.89901
994.875	4.15707
998.188	10.0506
1001.5	17.573
1004.81	26.3053
1008.12	36.9106
1011.43	50.3522
1014.74	60.2865
1018.05	71.7869
1021.35	81.7415
1024.65	90.6627
1027.96	99.5811
1031.26	105.653
1034.56	105.832
1037.86	104.548
1041.16	100.42
1044.45	96.7173
1047.75	90.4746
1051.04	87.1163
1054.33	82.7707
1057.62	77.4607
1060.91	72.8622
1064.2	72.1829
1067.49	75.7136
1070.77	77.0355
1074.06	78.6445
1077.34	82.5035
1080.62	85.6271
1083.91	88.9892
1087.18	90.6867
1090.46	90.8152
1093.74	88.1175
1097.02	82.1547
1100.29	79.9306
1103.56	76.3525
1106.84	66.9068
1110.11	58.6956
1113.38	46.0089
1116.64	35.3396
1119.91	25.4709
1123.18	19.9634
1126.44	14.3637
1129.7	10.3717
1132.97	8.5421
1136.23	10.8551
1139.49	10.6517
1142.74	12.2312
1146	15.0418
1149.26	14.4876
1152.51	14.5668
1155.76	15.5685
1159.01	15.4889
1162.27	14.7402
1165.51	15.0386
1168.76	13.0716
1172.01	13.7245
1175.25	15.6775
1178.5	13.8875
1181.74	15.5062
1184.98	15.5025
1188.22	15.2636
1191.46	14.4008
1194.7	15.6154
1197.94	15.3429
1201.17	17.953
1204.41	19.4742
1207.64	19.1776
1210.87	19.7421
1214.1	21.4732
1217.33	24.3236
1220.56	22.8252
1223.79	24.469
1227.01	26.538
1230.23	26.1239
1233.46	24.6444
1236.68	24.283
1239.9	27.2286
1243.12	28.2151
1246.34	30.1779
1249.55	28.9172
1252.77	30.1612
1255.98	31.8229
1259.2	31.9918
1262.41	33.9353
1265.62	36.3528
1268.83	39.4715
1272.03	41.2524
1275.24	40.5764
1278.45	43.3573
1281.65	45.6849
1284.85	46.8079
1288.06	48.3812
1291.26	52.0658
1294.46	52.3854
1297.66	52.5595
1300.85	53.6827
1304.05	53.4337
1307.24	51.0599
1310.43	50.5568
1313.63	52.2574
1316.82	52.3046
1320.01	51.252
1323.2	48.2089
1326.38	46.3315
1329.57	45.9727
1332.76	46.3691
1335.94	45.4869
1339.12	45.6942
1342.3	46.0808
1345.48	47.8739
1348.66	45.213
1351.84	43.6183
1355.01	43.2048
1358.19	41.6032
1361.36	39.1249
1364.53	36.7304
1367.71	35.038
1370.88	32.8468
1374.04	29.647
1377.21	30.5744
1380.38	28.5882
1383.54	27.0256
1386.71	28.7383
1389.87	27.0912
1393.03	27.6789
1396.19	28.0966
1399.35	29.9731
1402.51	32.0182
1405.67	34.4641
1408.82	38.7773
1411.98	45.583
1415.13	52.3809
1418.28	60.7298
1421.43	66.6322
1424.58	71.6681
1427.73	77.7651
1430.88	85.6857
1434.02	86.8216
1437.17	89.5464
1440.31	92.1593
1443.45	91.3353
1446.6	89.6303
1449.74	89.5337
1452.87	89.1538
1456.01	86.5043
1459.15	83.7647
1462.28	80.6607
1465.42	77.2058
1468.55	74.9861
1471.68	72.6732
1474.81	67.637
1477.94	63.5901
1481.07	58.5801
1484.2	54.2635
1487.32	52.978
1490.45	51.3885
1493.57	47.9188
1496.69	45.3263
1499.81	42.4813
1502.93	39.9157
1506.05	35.3679
1509.17	29.6688
1512.28	23.56
1515.4	16.6662
1518.51	10.9349
1521.63	7.84642
1524.74	4.97798
1527.85	1.97172
1530.96	1.99863
1534.06	3.03147
1537.17	4.24469
1540.28	7.5959
1543.38	9.98829
1546.48	12.7199
1549.59	17.7043
1552.69	21.5192
1555.79	25.7096
1558.88	30.5078
1561.98	32.9723
1565.08	40.1468
1568.17	45.2602
1571.27	49.2814
1574.36	51.2451
1577.45	52.2526
1580.54	54.0513
1583.63	55.9226
1586.72	58.5048
1589.8	56.6524
1592.89	57.612
1595.97	56.1667
1599.06	55.4274
1602.14	53.4535
1605.22	52.5798
1608.3	53.6694
1611.38	53.1167
1614.46	52.3264
1617.53	54.2921
1620.61	55.3107
1623.68	55.595
1626.75	57.1554
1629.82	55.1565
1632.9	55.6663
1635.96	56.7695
1639.03	55.2551
1642.1	56.3648
1645.16	53.5924
1648.23	52.4473
1651.29	52.385
1654.36	54.6685
1657.42	54.9398
1660.48	54.3071
1663.53	53.1458
1666.59	49.7409
1669.65	48.0373
1672.7	45.9829
1675.76	44.2872
1678.81	42.5327
1681.86	39.5281
1684.91	36.574
1687.96	33.4544
1691.01	32.033
1694.06	31.2774
1697.11	28.278
1700.15	25.4472
1703.2	22.5004
1706.24	19.0838
1709.28	17.1502
1712.32	12.5405
1715.36	10.7455
1718.4	10.4604
1721.43	8.79787
1724.47	8.25751
1727.5	7.62989
1730.54	6.39007
1733.57	5.30161
1736.6	4.14045
1739.63	4.68561
1742.66	3.39317
1745.69	5.18896
1748.72	5.13155
1751.74	4.69875
1754.77	3.53783
1757.79	5.43977
1760.81	4.67567
1763.83	6.76907
1766.85	8.25568
1769.87	9.29427
1772.89	9.23163
1775.91	10.8503
1778.92	12.2596
1781.94	13.5222
1784.95	14.8856
1787.96	16.5339
1790.97	19.0146
1793.98	18.9132
1796.99	19.092
1800	20.7318
1803	22.0058
1806.01	22.7719
1809.01	25.0821
1812.02	23.7941
1815.02	22.8579
1818.02	22.8736
1821.02	22.1347
1824.02	20.6338
1827.01	20.0235
1830.01	20.5883
1833	20.5837
1836	20.2237
1838.99	20.7703
1841.98	20.3139
1844.97	18.868
1847.96	18.5382
1850.95	18.6397
1853.94	18.8713
1856.92	18.4058
1859.91	18.3179
1862.89	19.7469
1865.88	22.24
1868.86	23.7819
1871.84	24.01
1874.82	25.7014
1877.8	26.8964
1880.77	26.8013
1882.51	27.5218
1885.5	25.9443
1888.48	25.0834
1891.47	25.2184
1894.46	25.5727
1897.44	24.3174
1900.42	24.2535
1903.41	22.5737
1906.39	20.2667
1909.37	21.1302
1912.35	18.4145
1915.32	14.943
1918.3	14.2212
1921.28	12.6588
1924.25	10.5555
1927.22	8.78784
1930.2	6.98628
1933.17	8.45684
1936.14	9.00054
1939.11	8.42091
1942.08	8.10689
1945.04	7.29304
1948.01	6.24551
1950.97	6.84408
1953.94	6.48628
1956.9	7.88019
1959.86	8.16919
1962.82	9.59697
1965.78	9.16477
1968.74	9.05351
1971.69	7.60054
1974.65	7.00182
1977.61	5.56516
1980.56	5.13645
1983.51	3.19915
1986.46	1.51653
1989.41	2.17504
1992.36	3.02678
1995.31	2.09695
1998.26	1.91376
2001.2	2.02665
2004.15	1.37297
2007.09	2.26086
2010.04	1.50045
2012.98	1.54656
2015.92	1.2863
2018.86	1.85275
2021.8	6.79639
2024.74	8.85733
2027.67	11.1359
2030.61	12.9233
2033.54	15.1373
2036.47	16.4904
2039.41	18.552
2042.34	20.6951
2045.27	21.1619
2048.2	22.7501
2051.12	22.429
2054.05	25.3129
2056.98	26.6332
2059.9	28.8647
2062.82	29.0982
2065.75	28.9397
2068.67	31.0659
2071.59	30.5306
2074.51	31.0456
2077.43	32.6377
2080.34	36.4844
2083.26	39.3211
2086.17	43.3409
2089.09	47.4504
2092	53.2746
2094.91	56.819
2097.82	60.3426
2100.73	65.5373
2103.64	69.3066
2106.55	73.584
2109.46	76.1956
2112.36	79.8427
2115.27	83.3766
2118.17	85.8278
2121.07	89.1721
2123.97	93.1374
2126.87	97.5433
2129.77	99.668
2132.67	102.761
2135.57	106.585
2138.46	111.694
2141.36	115.986
2144.25	119.892
2147.14	125.62
2150.03	130.286
2152.92	132.003
2155.81	134.493
2158.7	137.778
2161.59	139.564
2164.48	140.298
2167.36	140.101
2170.25	139.835
2173.13	138.002
2176.01	135.109
2178.89	134.698
2181.77	130.126
2184.65	128.297
2187.53	124.25
2190.41	121.028
2193.28	116.949
2196.16	113.791
2199.03	108.378
2201.9	105.741
2204.78	101.372
2207.65	101.587
2210.51	98.686
2213.38	97.5216
2216.25	92.3845
2219.12	88.7241
2221.98	83.364
2224.85	80.1452
2227.71	77.0584
2230.57	75.0472
2233.43	70.2934
2236.29	67.4154
2239.15	64.3074
2242.01	60.8132
2244.87	59.4922
2247.73	57.877
2250.58	55.7793
2253.43	53.0297
2256.29	53.0993
2259.14	50.34
2261.99	47.1819
2264.84	46.6077
2267.69	44.8706
2270.54	43.2001
2273.38	43.5255
2276.23	42.417
2279.07	42.3779
2281.92	40.8759
2284.76	38.702
2287.6	37.9727
2290.44	37.7653
2293.28	37.9709
2296.12	36.7324
2298.96	37.1229
2301.79	36.5668
2304.63	35.1812
2307.46	34.0306
2310.3	34.4166
2313.13	34.018
2315.96	34.1297
2318.79	32.4393
2321.62	31.2213
2324.45	29.4736
2327.27	30.256
2330.1	28.3797
2332.93	26.6268
2335.75	26.3027
2338.57	23.2227
2341.4	23.9265
2344.22	22.7816
2347.04	21.089
2349.86	20.6923
2352.67	22.5073
2355.49	20.4977
2358.31	20.537
2361.12	20.065
2363.94	17.4219
2366.75	18.2492
2369.56	18.4124
2372.37	16.1577
2375.18	13.6601
2377.99	14.223
2380.8	13.0846
2383.61	11.5896
2386.41	7.65541
2389.22	6.12753
2392.02	6.99024
2394.82	4.90961
2397.63	6.21006
2400.43	4.64794
2403.23	6.36631
2406.02	6.8428
2408.82	8.44509
2411.62	10.286
2414.41	10.9519
2417.21	12.7635
2420	15.1327
2422.79	16.9304
2425.59	16.1754
2428.38	17.0725
2431.17	16.7483
2433.96	17.5517
2436.74	18.097
2439.53	20.3158
2442.32	20.1207
2445.1	22.3787
2447.88	22.3349
2450.67	20.8755
2453.45	20.5555
2456.23	20.9112
2459.01	21.4884
2461.79	19.1759
2464.57	16.8043
2467.34	15.1411
2470.12	13.5934
2472.89	11.9919
2475.67	12.3135
2478.44	9.6412
2481.21	7.9662
2483.98	8.72537
2486.75	6.11563
2489.52	5.38794
2492.29	1.44435
2495.06	-0.921556
2497.82	-3.13966
2500.59	-4.66181
2503.35	-3.4336
2506.11	-2.86029
2508.88	-0.307571
2511.63	0.0136514
2514.39	0.350957
2517.15	-0.563464
2519.91	1.24454
2522.67	2.6942
2525.42	4.93073
2528.18	5.95826
2530.93	7.56358
2533.69	9.33022
2536.44	9.57252
2539.19	11.4194
2541.94	13.0363
2544.69	14.7544
2547.44	15.5064
2550.18	17.046
2552.93	15.9852
2555.68	16.8575
2558.42	15.9028
2561.16	15.0095
2563.9	15.5275
2566.64	15.0353
2569.38	13.7332
2572.12	13.6443
2574.86	15.0593
2577.6	13.2661
2580.34	12.0803
2583.07	10.7189
2585.81	10.7465
2588.54	9.67735
2591.27	9.30295
2594	10.0805
2596.73	8.63515
2599.46	6.83357
2602.19	4.5484
2604.92	5.65586
2607.64	4.21303
2610.37	3.63089
2613.09	4.44185
2615.82	4.0647
2618.54	3.82723
2621.26	4.15113
2623.98	5.32325
2626.7	6.79752
2629.42	6.32175
2632.14	6.10866
2634.86	5.45723
2637.57	5.73264
2640.29	7.26193
2643	9.07101
2645.72	7.71723
2648.43	8.7959
2651.14	7.70711
2653.85	8.58824
2656.56	9.25256
2659.27	10.4248
2661.97	11.6724
2664.68	11.8453
2667.38	12.3657
2670.09	13.2417
2672.79	14.3071
2675.49	13.9571
2678.2	13.4305
2680.89	14.0163
2683.59	11.6386
2686.29	12.5307
2688.99	13.4125
2691.69	13.5364
2694.38	11.8607
2697.08	10.2798
2699.77	10.1787
2702.46	9.78993
2705.16	11.3931
2707.85	11.7305
2710.54	12.8081
2713.23	13.3883
2715.92	13.2676
2718.6	15.3028
2721.29	16.5165
2723.97	17.9463
2726.66	18.6302
2729.34	17.5683
2732.02	18.4792
2734.7	17.4297
2737.39	15.5108
2740.06	14.9248
2742.74	12.8891
2745.42	10.7512
2748.1	9.63995
2750.77	8.02543
2753.45	8.12699
2756.12	6.03302
2758.79	4.71355
2761.47	4.64475
2764.14	4.92359
2766.81	4.54207
2769.48	4.25325
2772.14	4.3998
2774.81	3.90346
2777.48	3.79366
2780.14	3.17003
2782.81	2.80038
2785.47	4.57815
2788.13	5.57807
2790.79	3.94868
2793.46	3.20222
2796.11	1.79291
2798.77	0.240034
2801.43	-1.84647
2804.09	-2.78822
2806.74	-4.26889
2809.4	-6.15372
2812.05	-4.40015
2814.71	-4.26212
2817.36	-4.40538
2820.01	-1.34179
2822.66	2.75809
2825.31	7.68393
2827.96	14.6532
2830.61	20.9885
2833.25	27.6957
2835.9	35.423
2838.54	45.0896
2841.18	52.5374
2843.83	62.242
2846.47	71.6642
2849.11	82.7613
2851.75	92.365
2854.39	100.709
2857.03	107.429
2859.67	115.488
2862.3	122.315
2864.94	125.9
2867.57	132.254
2870.21	138.262
2872.84	142.254
2875.47	145.427
2878.1	148.155
2880.73	151.398
2883.36	154.925
2885.99	160.645
2888.61	163.296
2891.24	167.585
2893.87	174.066
2896.49	179.356
2899.11	187.507
2901.74	196.753
2904.36	204.153
2906.98	215.876
2909.6	230.438
2912.22	243.663
2914.83	257.8
2917.45	270.496
2920.07	282.928
2922.68	294.867
2925.3	304.492
2927.91	311.338
2930.52	317.818
2933.13	321.347
2935.74	318.206
2938.35	313.644
2940.96	307.131
2943.57	300.636
2946.18	290.46
2948.78	278.52
2951.39	265.239
2953.99	253.822
2956.6	239.205
2959.2	225.838
2961.8	212.21
2964.4	199.685
2967	186.509
2969.6	176.05
2972.2	166.512
2974.79	157.38
2977.39	146.381
2979.98	136.226
2982.58	127.232
2985.17	118.989
2987.76	110.387
2990.36	99.612
2992.95	89.9121
2995.54	79.737
2998.12	70.0986
3000.71	61.2299
3003.3	52.6134
3005.88	45.4933
3008.47	39.0809
3011.05	31.8317
3013.64	26.9451
3016.22	19.9226
3018.8	17.6534
3021.38	11.8776
3023.96	8.59152
3026.54	4.29064
3029.12	2.5254
3031.69	2.21246
3034.27	0.762193
3036.85	-0.560945
3039.42	-1.55919
3041.99	-2.88879
3044.57	-3.1319
3047.14	-2.54034
3049.71	-1.64102
3052.28	-0.0540327
3054.85	-1.59024
3057.42	-0.46144
3059.98	0.774733
3062.55	0.762657
3065.11	2.16511
3067.68	2.56643
3070.24	3.38767
3072.8	5.09081
3075.37	5.20403
3077.93	6.89209
3080.49	8.25591
3083.05	9.45669
3085.61	8.96265
3088.16	9.30527
3090.72	10.5823
3093.27	13.3539
3095.83	14.7763
3098.38	17.2661
3100.94	20.4179
3103.49	21.4379
3106.04	23.777
3108.59	27.8005
3111.14	30.2693
3113.69	31.5257
3116.23	33.3099
3118.78	36.4468
3121.33	39.7992
3123.87	42.556
3126.42	45.186
3128.96	49.5863
3131.5	54.0292
3134.04	58.1618
3136.58	61.5421
3139.12	64.9783
3141.66	69.4588
3144.2	74.2349
3146.74	82.0757
3149.27	96.4839