File: data/Raman/poly_smoothed/Mb_50_18_43_1x_45s_532 nm_x100_100%_600 gr_mm_01.txt
#Acq. time (s)=	45
#Accumulations=	2
#Range (cm-¹)=	200...3150
#Windows=	2
#Auto scanning=	Off
#Autofocus=	Off
#Macrospot=	Off
#AutoExposure=	Off
#Spike filter=	Multiple accum.
#Delay time (s)=	0
#Binning=	1
#Readout mode=	Signal
#DeNoise=	Off
#ICS correction=	On
#Dark correction=	Off
#Inst. Process=	Off
#Detector Gain=	Best Dynamic Range
#Detector ADC=	20 kHz
#Detector temperature (°C)=	-69.85
#Instrument=	LabRAM HR Evol
#Detector=	Synapse
#Objective=	x100
#Grating=	600 gr/mm
#ND Filter=	100%
#Laser (nm)=	532
#Hole=	100.021
#Range=	Auto
#Laser Pol.=	No
#Raman. Pol.=	No
#Laser Pol. (°)=	-0.0007625
#Raman Pol. (°)=	89.9995
#Collection=	Microscope
#StageXY=	Marzhauser
#StageZ=	Marzhauser
#X (µm)=	28255.4
#Y (µm)=	-3288.7
#Z (µm)=	1040.65
#Full time(mm:ss)=	3:18
#Project=
#Sample=
#Site=
#Title=	Mb_50_18_43_2x_45s_532 nm_x100_100%_600 gr_mm
#Remark=
#Date=	12.07.2022 14:19
#Acquired=	12.07.2022 14:19:18
#Base:Fit=	10.08.2022 10:49:18
#Base:Sub=	10.08.2022 10:49:30
#Filter:Polynom=	16.08.2022 10:14:59
#AxisType[0]=Intens
#AxisUnit[0]=Cnt
#AxisType[1]=Spectr
#AxisUnit[1]=1/cm
200.388	16.7185
204.019	16.945
207.646	16.2103
211.274	14.9767
214.899	11.8269
218.524	10.7127
222.146	9.23688
225.766	8.28168
229.388	6.72723
233.005	6.97408
236.621	5.74457
240.236	5.03198
243.852	4.59782
247.464	4.38312
251.074	3.06949
254.683	3.58846
258.291	4.50504
261.897	4.58371
265.504	5.31319
269.108	5.0657
272.71	6.6207
276.311	7.53275
279.91	7.78846
283.508	7.44604
287.105	7.59965
290.698	8.61852
294.291	9.14991
297.884	9.26506
301.475	10.8109
305.064	10.9974
308.652	12.1787
312.237	12.5473
315.822	13.9607
319.406	13.0932
322.987	13.7449
326.568	12.826
330.148	12.9428
333.724	13.6676
337.301	12.5864
340.875	12.7092
344.449	13.462
348.02	14.9518
351.592	16.9584
355.16	20.1301
358.728	21.4417
362.294	24.2929
365.858	27.5953
369.422	27.9897
372.983	29.2115
376.543	31.5104
380.102	31.5492
383.661	32.3729
387.216	33.4218
390.771	32.1673
394.324	30.7248
397.875	28.7594
401.425	26.3785
404.974	23.8893
408.524	20.0631
412.07	17.3258
415.614	14.3429
419.156	11.2681
422.698	7.71258
426.238	4.69698
429.777	4.70255
433.315	4.54133
436.852	3.62673
440.387	2.28873
443.919	2.25879
447.451	2.28175
450.982	1.19718
454.512	1.58656
458.038	0.552534
461.565	1.76401
465.091	3.66388
468.613	5.65222
472.136	7.18149
475.655	10.6443
479.176	13.3872
482.692	17.4263
486.21	21.1933
489.724	25.5598
493.237	31.713
496.75	35.915
500.26	38.7665
503.771	41.7311
507.279	43.4948
510.785	44.3026
514.289	45.2576
517.793	43.4231
521.297	39.3541
524.797	36.78
528.297	33.5174
531.795	31.3672
535.291	26.2374
538.787	22.4222
542.281	18.4592
545.773	14.5894
549.264	11.8716
552.754	9.8291
556.243	7.39063
559.73	5.17023
563.216	5.35814
566.701	6.17648
570.182	7.84218
573.664	9.88438
577.145	11.2454
580.624	12.8399
584.1	13.3963
587.577	14.5187
591.052	14.0388
594.524	15.5487
597.997	15.148
601.466	13.5317
604.936	13.6785
608.403	13.8777
611.87	12.6917
615.334	11.0577
618.799	8.85115
622.26	7.96425
625.72	7.14075
629.181	5.90236
632.638	3.66338
636.095	2.87102
639.551	1.72688
643.005	0.0892595
646.457	0.0950359
649.908	0.579213
653.357	2.63163
656.806	4.65504
660.253	6.16731
663.7	10.5878
667.145	12.122
670.588	15.504
674.027	18.2452
677.468	20.1474
680.907	22.8975
684.345	25.28
687.781	27.0882
691.216	30.9459
694.65	32.4563
698.081	34.43
701.512	34.9788
704.942	35.4784
708.371	36.6592
711.796	35.5034
715.222	34.8869
718.645	34.0197
722.068	34.3656
725.49	32.3172
728.909	31.1009
732.329	33.7446
735.745	37.0359
739.16	42.6269
742.576	47.6361
745.988	55.1463
749.401	62.3879
752.811	68.7826
756.22	75.7127
759.627	81.684
763.035	86.2841
766.44	91.6179
769.843	95.3027
773.245	98.3471
776.646	101.15
780.046	103.305
783.444	102.799
786.841	102.382
790.237	101.139
793.631	99.101
797.024	96.1503
800.416	93.438
803.807	90.0503
807.196	85.3415
810.584	81.471
813.971	79.0961
817.354	77.7006
820.739	77.2919
824.122	75.6342
827.503	73.3995
830.882	71.0177
834.261	68.3023
837.637	65.1475
841.013	62.2457
844.389	57.263
847.761	54.887
851.131	51.9644
854.503	49.3335
857.871	46.5351
861.24	44.3243
864.606	42.2436
867.97	39.914
871.336	38.2425
874.698	37.0189
878.058	36.8549
881.418	37.303
884.778	36.6612
888.135	37.5075
891.49	38.5561
894.845	39.9628
898.198	41.5602
901.55	42.7944
904.901	41.9173
908.25	42.4966
911.598	41.9246
914.945	40.5545
918.291	41.0765
921.635	39.2587
924.978	37.8769
928.318	36.902
931.659	34.3488
934.998	31.9921
938.336	30.0406
941.671	25.8747
945.007	22.9722
948.339	22.992
951.672	20.7328
955.004	20.2654
958.333	18.451
961.662	16.3003
964.989	16.5076
968.315	17.5907
971.639	19.4696
974.962	19.5272
978.285	19.89
981.605	19.611
984.924	18.7081
988.243	18.6717
991.56	19.567
994.875	21.1464
998.188	23.2753
1001.5	27.914
1004.81	31.3804
1008.12	37.1316
1011.43	41.7432
1014.74	45.2316
1018.05	46.8601
1021.35	49.6955
1024.65	52.5192
1027.96	53.6473
1031.26	55.1902
1034.56	54.1813
1037.86	53.6072
1041.16	51.0306
1044.45	47.8322
1047.75	45.162
1051.04	43.7666
1054.33	40.4618
1057.62	37.7518
1060.91	35.0372
1064.2	33.5415
1067.49	32.7311
1070.77	33.5605
1074.06	33.8503
1077.34	34.9539
1080.62	35.4644
1083.91	37.1363
1087.18	37.8318
1090.46	36.6557
1093.74	35.5581
1097.02	34.0053
1100.29	31.8555
1103.56	30.3486
1106.84	27.2363
1110.11	24.2165
1113.38	21.5506
1116.64	18.7944
1119.91	14.0011
1123.18	9.89422
1126.44	8.39224
1129.7	9.01105
1132.97	9.75444
1136.23	10.1278
1139.49	8.94746
1142.74	9.46995
1146	8.95675
1149.26	8.85457
1152.51	9.35723
1155.76	8.59066
1159.01	7.58801
1162.27	6.67689
1165.51	6.65253
1168.76	6.45811
1172.01	5.49527
1175.25	5.6751
1178.5	5.04638
1181.74	3.23067
1184.98	2.65641
1188.22	3.18139
1191.46	1.59855
1194.7	1.65812
1197.94	1.41713
1201.17	1.84031
1204.41	2.56341
1207.64	4.96496
1210.87	6.53038
1214.1	7.60738
1217.33	7.51633
1220.56	8.69001
1223.79	12.3181
1227.01	14.6027
1230.23	15.9613
1233.46	17.1291
1236.68	19.0402
1239.9	21.2915
1243.12	21.7946
1246.34	23.4128
1249.55	27.1275
1252.77	27.6374
1255.98	29.3125
1259.2	32.4548
1262.41	36.0752
1265.62	38.1808
1268.83	39.6291
1272.03	41.8951
1275.24	45.185
1278.45	46.9524
1281.65	47.973
1284.85	49.4408
1288.06	50.114
1291.26	49.8336
1294.46	51.1585
1297.66	51.4265
1300.85	51.741
1304.05	52.2493
1307.24	50.8392
1310.43	50.5017
1313.63	49.5294
1316.82	47.8374
1320.01	47.8945
1323.2	46.4033
1326.38	46.5036
1329.57	45.4084
1332.76	44.2044
1335.94	44.5425
1339.12	42.602
1342.3	40.6304
1345.48	39.729
1348.66	37.7539
1351.84	36.4894
1355.01	35.37
1358.19	32.0309
1361.36	29.5954
1364.53	27.6106
1367.71	27.2422
1370.88	26.7281
1374.04	25.7053
1377.21	24.1724
1380.38	23.1786
1383.54	22.0242
1386.71	21.5994
1389.87	19.9883
1393.03	19.9501
1396.19	19.7009
1399.35	20.8775
1402.51	22.5871
1405.67	24.2756
1408.82	25.713
1411.98	28.8377
1415.13	31.8697
1418.28	35.6733
1421.43	40.5883
1424.58	44.8319
1427.73	49.9155
1430.88	54.5417
1434.02	59.9637
1437.17	63.0598
1440.31	66.4329
1443.45	67.9616
1446.6	68.2311
1449.74	67.7249
1452.87	67.9289
1456.01	68.4252
1459.15	68.997
1462.28	69.1881
1465.42	68.3905
1468.55	67.4404
1471.68	65.839
1474.81	64.7508
1477.94	62.953
1481.07	59.7979
1484.2	56.8706
1487.32	54.5573
1490.45	51.9903
1493.57	48.5502
1496.69	45.6293
1499.81	42.7228
1502.93	39.0927
1506.05	36.9452
1509.17	33.8124
1512.28	29.496
1515.4	25.1878
1518.51	21.6492
1521.63	18.1372
1524.74	16.3671
1527.85	16.9935
1530.96	17.1534
1534.06	17.9035
1537.17	20.0589
1540.28	21.914
1543.38	24.3013
1546.48	25.1175
1549.59	25.3224
1552.69	27.3687
1555.79	26.3425
1558.88	28.2035
1561.98	28.2622
1565.08	29.0016
1568.17	30.9723
1571.27	32.1338
1574.36	34.6234
1577.45	36.8453
1580.54	38.9684
1583.63	41.9584
1586.72	42.6785
1589.8	43.3704
1592.89	43.0694
1595.97	43.2125
1599.06	44.0457
1602.14	45.0974
1605.22	45.5264
1608.3	44.6584
1611.38	44.9502
1614.46	45.9555
1617.53	45.8443
1620.61	46.9012
1623.68	46.3639
1626.75	48.5883
1629.82	48.9321
1632.9	49.8913
1635.96	51.1381
1639.03	53.2438
1642.1	56.6239
1645.16	59.219
1648.23	60.4609
1651.29	62.9433
1654.36	63.8146
1657.42	63.5856
1660.48	62.2566
1663.53	58.8693
1666.59	55.6824
1669.65	52.5746
1672.7	50.0485
1675.76	45.6649
1678.81	41.1719
1681.86	36.1735
1684.91	31.7876
1687.96	28.6685
1691.01	26.0169
1694.06	23.5655
1697.11	21.6702
1700.15	17.8441
1703.2	17.1329
1706.24	15.3228
1709.28	14.3402
1712.32	13.3544
1715.36	12.5593
1718.4	13.4922
1721.43	11.9447
1724.47	12.2419
1727.5	13.0174
1730.54	11.8912
1733.57	10.6465
1736.6	9.51511
1739.63	9.113
1742.66	9.08072
1745.69	8.7179
1748.72	8.70628
1751.74	7.29985
1754.77	6.78228
1757.79	7.2222
1760.81	6.76059
1763.83	5.82688
1766.85	4.77171
1769.87	3.33144
1772.89	2.31538
1775.91	2.74383
1778.92	3.07247
1781.94	2.92454
1784.95	4.09458
1787.96	4.27701
1790.97	4.78501
1793.98	4.42797
1796.99	5.72373
1800	6.49946
1803	6.89013
1806.01	7.26893
1809.01	7.31286
1812.02	7.92703
1815.02	7.77288
1818.02	7.42299
1821.02	7.00121
1824.02	6.20863
1827.01	6.15922
1830.01	5.55944
1833	3.54668
1836	2.13981
1838.99	2.16359
1841.98	1.44212
1844.97	0.496353
1847.96	0.711158
1850.95	0.58216
1853.94	-0.160691
1856.92	0.023578
1859.91	0.564486
1862.89	0.911421
1865.88	1.14318
1868.86	2.40061
1871.84	3.26924
1874.82	2.559
1877.8	3.17148
1880.77	3.17913
1882.51	3.68324
1885.5	4.19155
1888.48	4.6652
1891.47	5.9757
1894.46	7.15306
1897.44	6.32546
1900.42	6.99404
1903.41	5.33346
1906.39	6.29099
1909.37	5.61623
1912.35	4.90373
1915.32	3.94835
1918.3	3.66719
1921.28	3.54142
1924.25	3.46226
1927.22	3.86907
1930.2	4.45475
1933.17	4.85937
1936.14	4.91369
1939.11	5.32676
1942.08	5.62658
1945.04	6.06396
1948.01	5.49693
1950.97	5.73623
1953.94	6.43576
1956.9	7.24344
1959.86	7.09673
1962.82	7.93718
1965.78	7.64173
1968.74	7.39929
1971.69	6.0104
1974.65	5.44216
1977.61	4.74104
1980.56	3.71094
1983.51	2.77179
1986.46	2.72285
1989.41	3.06741
1992.36	4.52146
1995.31	5.0285
1998.26	5.99803
2001.2	6.4934
2004.15	6.63958
2007.09	7.72022
2010.04	7.52213
2012.98	8.39712
2015.92	7.07301
2018.86	6.36166
2021.8	6.49367
2024.74	5.72658
2027.67	6.44596
2030.61	6.59617
2033.54	6.37848
2036.47	7.28765
2039.41	7.54824
2042.34	7.74543
2045.27	8.46418
2048.2	8.84206
2051.12	10.0423
2054.05	10.6516
2056.98	13.3138
2059.9	15.3182
2062.82	17.7154
2065.75	18.7512
2068.67	19.6908
2071.59	21.0497
2074.51	22.9097
2077.43	24.6689
2080.34	25.9166
2083.26	26.9532
2086.17	28.1891
2089.09	28.9367
2092	30.4906
2094.91	32.7083
2097.82	35.1513
2100.73	37.6764
2103.64	39.3891
2106.55	41.9728
2109.46	45.457
2112.36	47.3786
2115.27	50.408
2118.17	53.8491
2121.07	57.3272
2123.97	61.5268
2126.87	65.5142
2129.77	69.6699
2132.67	73.0433
2135.57	77.2651
2138.46	80.1408
2141.36	83.3147
2144.25	87.346
2147.14	91.2565
2150.03	93.7319
2152.92	96.785
2155.81	98.4278
2158.7	99.71
2161.59	102.406
2164.48	103.186
2167.36	103.731
2170.25	103.65
2173.13	101.659
2176.01	100.184
2178.89	98.4069
2181.77	96.4004
2184.65	93.5335
2187.53	91.3658
2190.41	88.6316
2193.28	85.085
2196.16	81.7996
2199.03	78.1313
2201.9	74.5408
2204.78	71.0563
2207.65	68.1092
2210.51	65.1621
2213.38	62.4439
2216.25	59.726
2219.12	56.5002
2221.98	53.6517
2224.85	50.3173
2227.71	47.216
2230.57	44.2444
2233.43	42.2224
2236.29	39.7929
2239.15	37.4019
2242.01	36.1297
2244.87	33.3512
2247.73	30.4581
2250.58	28.505
2253.43	26.4894
2256.29	24.5393
2259.14	23.353
2261.99	22.1558
2264.84	20.7963
2267.69	19.8315
2270.54	18.7921
2273.38	18.3046
2276.23	17.3991
2279.07	17.1206
2281.92	16.0575
2284.76	14.7779
2287.6	14.6987
2290.44	12.9442
2293.28	10.7095
2296.12	10.1718
2298.96	10.6196
2301.79	10.9085
2304.63	11.5714
2307.46	11.8442
2310.3	12.0548
2313.13	11.1109
2315.96	9.95804
2318.79	9.23527
2321.62	9.42669
2324.45	9.71621
2327.27	10.4384
2330.1	10.4337
2332.93	9.27673
2335.75	7.34694
2338.57	6.6351
2341.4	5.90738
2344.22	4.64926
2347.04	4.16973
2349.86	3.79276
2352.67	2.98015
2355.49	2.90442
2358.31	1.5119
2361.12	0.708534
2363.94	1.83568
2366.75	1.81139
2369.56	1.83421
2372.37	1.87832
2375.18	3.51919
2377.99	4.07877
2380.8	3.78546
2383.61	3.02082
2386.41	3.34397
2389.22	4.35142
2392.02	5.9479
2394.82	6.28554
2397.63	6.16275
2400.43	5.51349
2403.23	5.36727
2406.02	4.91986
2408.82	5.31493
2411.62	5.49177
2414.41	4.90672
2417.21	5.18122
2420	5.96521
2422.79	5.19798
2425.59	4.66827
2428.38	4.13342
2431.17	3.58733
2433.96	3.05824
2436.74	2.12756
2439.53	2.93816
2442.32	3.22937
2445.1	3.54403
2447.88	2.82307
2450.67	2.80658
2453.45	1.83985
2456.23	2.18817
2459.01	2.47872
2461.79	2.61379
2464.57	2.46111
2467.34	2.78688
2470.12	2.6448
2472.89	2.45434
2475.67	2.30651
2478.44	2.42007
2481.21	1.9027
2483.98	1.77804
2486.75	1.47848
2489.52	1.2918
2492.29	1.23535
2495.06	1.56301
2497.82	1.28663
2500.59	1.1504
2503.35	0.766183
2506.11	0.00994195
2508.88	0.0884112
2511.63	0.268822
2514.39	0.708322
2517.15	1.57648
2519.91	1.53736
2522.67	1.65731
2525.42	2.73713
2528.18	2.82038
2530.93	3.45257
2533.69	3.70431
2536.44	3.30346
2539.19	3.5241
2541.94	4.09317
2544.69	4.08913
2547.44	4.18761
2550.18	4.89852
2552.93	4.70773
2555.68	5.20931
2558.42	4.76787
2561.16	5.542
2563.9	4.68402
2566.64	3.93026
2569.38	3.17532
2572.12	2.26319
2574.86	2.63893
2577.6	2.83657
2580.34	2.85316
2583.07	2.69305
2585.81	1.28367
2588.54	0.662297
2591.27	1.2586
2594	0.102435
2596.73	-0.128407
2599.46	-0.0761434
2602.19	-0.657336
2604.92	0.225523
2607.64	0.499746
2610.37	1.05989
2613.09	2.15305
2615.82	1.67181
2618.54	1.80489
2621.26	2.17536
2623.98	2.7138
2626.7	3.29956
2629.42	3.2621
2632.14	3.22146
2634.86	3.24406
2637.57	3.49969
2640.29	4.62882
2643	5.17651
2645.72	5.45286
2648.43	6.42064
2651.14	6.95053
2653.85	6.98806
2656.56	7.1331
2659.27	7.98515
2661.97	7.00782
2664.68	7.62285
2667.38	7.91548
2670.09	8.33731
2672.79	7.91152
2675.49	7.99537
2678.2	7.99773
2680.89	7.62282
2683.59	7.15273
2686.29	6.43667
2688.99	5.35591
2691.69	4.64488
2694.38	3.13587
2697.08	3.10407
2699.77	3.40294
2702.46	3.79617
2705.16	4.38825
2707.85	5.22409
2710.54	4.91894
2713.23	5.95088
2715.92	6.0748
2718.6	7.33263
2721.29	8.17535
2723.97	7.95733
2726.66	8.64591
2729.34	8.66088
2732.02	9.99939
2734.7	9.93867
2737.39	9.33496
2740.06	8.89761
2742.74	9.27173
2745.42	9.11503
2748.1	7.73385
2750.77	7.60263
2753.45	6.4315
2756.12	6.25019
2758.79	4.99138
2761.47	4.75797
2764.14	4.75489
2766.81	4.32016
2769.48	3.55774
2772.14	2.35825
2774.81	2.10175
2777.48	1.53934
2780.14	2.32252
2782.81	1.91633
2785.47	0.380609
2788.13	0.445957
2790.79	-0.0177066
2793.46	-0.598377
2796.11	-0.297381
2798.77	-0.709733
2801.43	-0.963957
2804.09	-1.44532
2806.74	-0.665501
2809.4	-0.360614
2812.05	-0.346763
2814.71	1.67633
2817.36	2.92066
2820.01	5.13845
2822.66	8.70469
2825.31	14.0162
2827.96	20.0866
2830.61	25.8589
2833.25	32.2699
2835.9	37.9905
2838.54	45.2199
2841.18	51.9408
2843.83	59.4958
2846.47	67.6183
2849.11	74.3497
2851.75	81.2341
2854.39	87.262
2857.03	93.4589
2859.67	99.5273
2862.3	105.167
2864.94	109.339
2867.57	113.234
2870.21	115.936
2872.84	118.876
2875.47	121.392
2878.1	123.853
2880.73	126.426
2883.36	129.584
2885.99	133.769
2888.61	138.242
2891.24	143.022
2893.87	148.38
2896.49	154.298
2899.11	161.053
2901.74	169.278
2904.36	178.391
2906.98	187.501
2909.6	198.23
2912.22	207.022
2914.83	216.425
2917.45	224.977
2920.07	233.713
2922.68	241.187
2925.3	245.175
2927.91	248.218
2930.52	249.674
2933.13	247.857
2935.74	245.521
2938.35	240.595
2940.96	235.015
2943.57	227.155
2946.18	219.466
2948.78	209.945
2951.39	200.473
2953.99	191.17
2956.6	181.194
2959.2	170.744
2961.8	160.96
2964.4	151.716
2967	142.596
2969.6	134.536
2972.2	125.829
2974.79	118.738
2977.39	110.937
2979.98	103.494
2982.58	95.5909
2985.17	87.8347
2987.76	79.0124
2990.36	70.9499
2992.95	62.8348
2995.54	55.5548
2998.12	47.8102
3000.71	40.9151
3003.3	34.9539
3005.88	29.5884
3008.47	24.7024
3011.05	19.2616
3013.64	15.5946
3016.22	11.6759
3018.8	8.36721
3021.38	5.62657
3023.96	3.11719
3026.54	2.07632
3029.12	1.33151
3031.69	1.3193
3034.27	2.02058
3036.85	2.55457
3039.42	2.9467
3041.99	3.21171
3044.57	4.47849
3047.14	5.72466
3049.71	6.25893
3052.28	7.36266
3054.85	8.76988
3057.42	9.17955
3059.98	9.66531
3062.55	9.6976
3065.11	9.82701
3067.68	8.72156
3070.24	8.30221
3072.8	6.91451
3075.37	6.48209
3077.93	5.44513
3080.49	3.75208
3083.05	3.20222
3085.61	2.34025
3088.16	2.32401
3090.72	2.44486
3093.27	2.64066
3095.83	3.89441
3098.38	4.94239
3100.94	6.64918
3103.49	8.37332
3106.04	10.4306
3108.59	12.8133
3111.14	15.5359
3113.69	16.8895
3116.23	19.5046
3118.78	21.0276
3121.33	22.6607
3123.87	23.851
3126.42	25.9736
3128.96	27.5635
3131.5	28.6753
3134.04	29.6887
3136.58	30.3542
3139.12	30.7661
3141.66	30.9102
3144.2	31.8013
3146.74	33.3699
3149.27	35.103