File: data/Raman/poly_smoothed/Mb_50_18_12_1x_45s_532 nm_x100_100%_600 gr_mm_01.txt
#Acq. time (s)=	45
#Accumulations=	2
#Range (cm-¹)=	200...3150
#Windows=	2
#Auto scanning=	Off
#Autofocus=	Off
#Macrospot=	Off
#AutoExposure=	Off
#Spike filter=	Multiple accum.
#Delay time (s)=	0
#Binning=	1
#Readout mode=	Signal
#DeNoise=	Off
#ICS correction=	On
#Dark correction=	Off
#Inst. Process=	Off
#Detector Gain=	Best Dynamic Range
#Detector ADC=	20 kHz
#Detector temperature (°C)=	-69.85
#Instrument=	LabRAM HR Evol
#Detector=	Synapse
#Objective=	x100
#Grating=	600 gr/mm
#ND Filter=	100%
#Laser (nm)=	532
#Hole=	100.021
#Range=	Auto
#Laser Pol.=	No
#Raman. Pol.=	No
#Laser Pol. (°)=	-0.0007625
#Raman Pol. (°)=	89.9995
#Collection=	Microscope
#StageXY=	Marzhauser
#StageZ=	Marzhauser
#X (µm)=	19303.1
#Y (µm)=	3083.9
#Z (µm)=	1046.85
#Full time(mm:ss)=	3:18
#Project=
#Sample=
#Site=
#Title=	Mb_50_18_12_2x_45s_532 nm_x100_100%_600 gr_mm
#Remark=
#Date=	12.07.2022 11:09
#Acquired=	12.07.2022 11:09:06
#Base:Fit=	10.08.2022 10:49:18
#Base:Sub=	10.08.2022 10:49:30
#Filter:Polynom=	16.08.2022 10:14:59
#AxisType[0]=Intens
#AxisUnit[0]=Cnt
#AxisType[1]=Spectr
#AxisUnit[1]=1/cm
200.388	1.33321
204.019	8.02678
207.646	11.6697
211.274	13.8732
214.899	14.5359
218.524	14.1417
222.146	13.4914
225.766	12.9792
229.388	12.3713
233.005	13.2151
236.621	11.3768
240.236	9.80072
243.852	8.70955
247.464	7.48897
251.074	5.03768
254.683	4.48672
258.291	5.71926
261.897	4.48262
265.504	3.98984
269.108	3.34187
272.71	3.29995
276.311	3.4538
279.91	4.89641
283.508	4.98821
287.105	4.19348
290.698	5.93489
294.291	7.27183
297.884	7.38936
301.475	9.50768
305.064	9.21829
308.652	11.3556
312.237	13.1768
315.822	14.9709
319.406	16.3285
322.987	16.3406
326.568	15.7707
330.148	14.6307
333.724	13.5937
337.301	14.3159
340.875	13.2024
344.449	12.7204
348.02	12.3966
351.592	13.6091
355.16	14.2893
358.728	15.4074
362.294	18.5584
365.858	18.2059
369.422	20.4456
372.983	21.0804
376.543	21.5778
380.102	22.3767
383.661	22.7645
387.216	23.8416
390.771	23.2646
394.324	24.1673
397.875	23.655
401.425	23.8377
404.974	22.4242
408.524	19.5448
412.07	16.5179
415.614	13.0456
419.156	11.1643
422.698	8.51284
426.238	5.7825
429.777	4.10524
433.315	4.03722
436.852	5.2726
440.387	4.01245
443.919	3.54857
447.451	4.89969
450.982	4.86994
454.512	3.3119
458.038	5.05587
461.565	4.61007
465.091	7.33723
468.613	9.42509
472.136	10.0767
475.655	13.3873
479.176	15.986
482.692	20.5281
486.21	23.8338
489.724	29.1641
493.237	32.1529
496.75	34.6144
500.26	36.9394
503.771	40.7208
507.279	44.238
510.785	44.9749
514.289	46.5645
517.793	46.5815
521.297	46.6601
524.797	45.2517
528.297	42.6338
531.795	39.9037
535.291	36.0016
538.787	32.5736
542.281	29.0076
545.773	24.3364
549.264	20.4784
552.754	16.6397
556.243	10.6755
559.73	7.02088
563.216	5.21472
566.701	4.03798
570.182	2.45624
573.664	2.09136
577.145	1.26766
580.624	0.371352
584.1	3.1628
587.577	3.18127
591.052	4.34299
594.524	4.89636
597.997	6.77496
601.466	8.44077
604.936	8.77521
608.403	9.72768
611.87	10.3817
615.334	11.3698
618.799	13.0953
622.26	13.9836
625.72	12.4578
629.181	12.0562
632.638	11.8535
636.095	11.3657
639.551	11.4845
643.005	12.0007
646.457	12.7704
649.908	13.0787
653.357	12.666
656.806	12.8756
660.253	14.1956
663.7	16.2369
667.145	17.8426
670.588	18.2007
674.027	18.1315
677.468	20.8242
680.907	22.9747
684.345	25.1885
687.781	25.8969
691.216	28.5873
694.65	31.0807
698.081	33.4283
701.512	34.4462
704.942	34.9037
708.371	35.2755
711.796	37.1258
715.222	39.2435
718.645	41.6533
722.068	42.1949
725.49	42.7957
728.909	42.5696
732.329	44.5609
735.745	45.826
739.16	49.6814
742.576	55.7606
745.988	60.2076
749.401	64.6742
752.811	69.9137
756.22	76.2914
759.627	82.9634
763.035	87.6565
766.44	92.2036
769.843	96.3432
773.245	99.7435
776.646	101.513
780.046	100.228
783.444	100.234
786.841	100.93
790.237	100.899
793.631	100.001
797.024	96.2442
800.416	92.9162
803.807	89.24
807.196	86.5587
810.584	84.388
813.971	81.8219
817.354	79.7963
820.739	78.6407
824.122	77.2136
827.503	76.7748
830.882	75.7519
834.261	76.8724
837.637	76.0998
841.013	74.8885
844.389	73.102
847.761	70.7936
851.131	68.5562
854.503	66.8935
857.871	64.2951
861.24	61.9927
864.606	60.7795
867.97	59.6658
871.336	57.8177
874.698	56.0794
878.058	55.2613
881.418	54.3074
884.778	52.8443
888.135	53.9404
891.49	53.7442
894.845	52.7987
898.198	51.1807
901.55	50.6625
904.901	50.2841
908.25	49.3588
911.598	49.6169
914.945	48.1989
918.291	46.6685
921.635	45.1457
924.978	44.0741
928.318	42.6862
931.659	41.1016
934.998	40.6278
938.336	40.6016
941.671	40.7887
945.007	38.8903
948.339	39.9416
951.672	40.8639
955.004	41.6928
958.333	40.3285
961.662	39.3311
964.989	39.4361
968.315	38.3043
971.639	38.7425
974.962	39.8163
978.285	39.2762
981.605	38.8522
984.924	36.4746
988.243	33.7509
991.56	31.873
994.875	33.2732
998.188	35.271
1001.5	39.6873
1004.81	42.721
1008.12	46.2602
1011.43	50.1445
1014.74	54.7419
1018.05	60.3845
1021.35	63.619
1024.65	65.58
1027.96	68.1113
1031.26	70.3918
1034.56	70.7417
1037.86	66.5754
1041.16	64.9262
1044.45	63.3679
1047.75	61.0284
1051.04	58.2274
1054.33	56.4956
1057.62	51.892
1060.91	47.8426
1064.2	44.4353
1067.49	40.921
1070.77	40.032
1074.06	43.8183
1077.34	45.6925
1080.62	46.533
1083.91	47.709
1087.18	46.8771
1090.46	47.1509
1093.74	47.6941
1097.02	47.717
1100.29	44.579
1103.56	41.6151
1106.84	40.159
1110.11	37.4316
1113.38	33.4368
1116.64	29.0236
1119.91	26.0804
1123.18	23.9019
1126.44	21.8425
1129.7	20.1212
1132.97	17.4932
1136.23	15.8183
1139.49	13.8679
1142.74	12.9676
1146	11.919
1149.26	10.9981
1152.51	11.5312
1155.76	10.5349
1159.01	7.7656
1162.27	5.46841
1165.51	4.94217
1168.76	5.71226
1172.01	6.31391
1175.25	6.44032
1178.5	4.50026
1181.74	4.38079
1184.98	4.9859
1188.22	5.26802
1191.46	5.54656
1194.7	7.2223
1197.94	9.70224
1201.17	11.6687
1204.41	13.395
1207.64	14.89
1210.87	15.8695
1214.1	18.2989
1217.33	21.8335
1220.56	24.1924
1223.79	27.2016
1227.01	29.3699
1230.23	31.7165
1233.46	33.2046
1236.68	35.353
1239.9	38.0866
1243.12	42.6317
1246.34	45.3324
1249.55	46.4117
1252.77	48.291
1255.98	49.4581
1259.2	50.9601
1262.41	53.8507
1265.62	54.2533
1268.83	55.7604
1272.03	58.6749
1275.24	61.1012
1278.45	62.4633
1281.65	64.4937
1284.85	66.1811
1288.06	66.8664
1291.26	68.4653
1294.46	70.2586
1297.66	69.7928
1300.85	67.756
1304.05	67.7599
1307.24	66.4419
1310.43	64.7265
1313.63	64.344
1316.82	63.1418
1320.01	62.2105
1323.2	61.0192
1326.38	58.0315
1329.57	56.9252
1332.76	55.1681
1335.94	51.8735
1339.12	50.2997
1342.3	47.6371
1345.48	44.1138
1348.66	43.1317
1351.84	42.1325
1355.01	40.3404
1358.19	37.8782
1361.36	35.19
1364.53	32.4841
1367.71	30.607
1370.88	27.3939
1374.04	24.7843
1377.21	22.0669
1380.38	19.6046
1383.54	18.1441
1386.71	16.114
1389.87	16.7393
1393.03	17.4288
1396.19	18.1443
1399.35	18.3196
1402.51	19.1557
1405.67	19.2296
1408.82	20.8274
1411.98	24.6996
1415.13	28.0704
1418.28	32.1983
1421.43	38.1593
1424.58	42.5081
1427.73	48.6732
1430.88	54.1211
1434.02	58.8548
1437.17	61.7804
1440.31	64.9029
1443.45	66.0291
1446.6	66.8151
1449.74	65.3811
1452.87	65.9304
1456.01	65.3483
1459.15	63.7795
1462.28	61.2988
1465.42	59.6445
1468.55	56.171
1471.68	51.8818
1474.81	48.4987
1477.94	43.349
1481.07	39.2869
1484.2	36.2272
1487.32	34.2739
1490.45	32.0823
1493.57	28.8763
1496.69	27.2137
1499.81	25.6221
1502.93	23.688
1506.05	22.1891
1509.17	20.6866
1512.28	17.7434
1515.4	14.9666
1518.51	12.8573
1521.63	12.3989
1524.74	10.9389
1527.85	10.2123
1530.96	10.974
1534.06	12.3339
1537.17	11.4576
1540.28	13.3109
1543.38	15.5304
1546.48	17.5342
1549.59	19.332
1552.69	20.1039
1555.79	22.3433
1558.88	24.0356
1561.98	25.5424
1565.08	27.8822
1568.17	29.225
1571.27	29.6025
1574.36	33.0369
1577.45	35.7879
1580.54	37.8555
1583.63	39.6281
1586.72	41.333
1589.8	42.8548
1592.89	43.6025
1595.97	45.59
1599.06	46.0107
1602.14	46.2561
1605.22	46.3448
1608.3	45.7304
1611.38	45.6579
1614.46	46.807
1617.53	47.0195
1620.61	49.2375
1623.68	51.2234
1626.75	52.683
1629.82	55.3918
1632.9	57.8161
1635.96	61.506
1639.03	64.7941
1642.1	69.5796
1645.16	72.6718
1648.23	77.0364
1651.29	81.3636
1654.36	83.9108
1657.42	85.278
1660.48	85.1549
1663.53	83.6653
1666.59	80.066
1669.65	76.7834
1672.7	72.2282
1675.76	67.2582
1678.81	61.2117
1681.86	54.3617
1684.91	48.9625
1687.96	44.7758
1691.01	39.7338
1694.06	35.4091
1697.11	32.3564
1700.15	28.4181
1703.2	24.3312
1706.24	20.9334
1709.28	21.1902
1712.32	20.9625
1715.36	21.7872
1718.4	22.4956
1721.43	22.7032
1724.47	22.5142
1727.5	21.0011
1730.54	19.6843
1733.57	17.8389
1736.6	16.2754
1739.63	14.2527
1742.66	13.3565
1745.69	12.7322
1748.72	11.8004
1751.74	9.97266
1754.77	8.94358
1757.79	7.58417
1760.81	7.37036
1763.83	5.89541
1766.85	4.73976
1769.87	3.48501
1772.89	1.67567
1775.91	0.819635
1778.92	-0.307927
1781.94	1.7462
1784.95	3.17752
1787.96	4.67435
1790.97	4.59083
1793.98	4.32476
1796.99	4.42482
1800	3.49143
1803	3.93409
1806.01	4.11008
1809.01	5.41481
1812.02	6.02202
1815.02	7.03649
1818.02	8.03321
1821.02	8.36155
1824.02	7.70484
1827.01	7.27573
1830.01	6.81248
1833	5.9069
1836	5.35695
1838.99	4.73573
1841.98	4.30544
1844.97	3.78831
1847.96	3.18042
1850.95	2.13031
1853.94	2.45695
1856.92	3.01491
1859.91	3.17176
1862.89	3.13438
1865.88	2.45973
1868.86	3.04848
1871.84	4.04525
1874.82	5.10009
1877.8	5.58228
1880.77	6.61603
1882.51	6.95408
1885.5	7.4035
1888.48	7.58527
1891.47	7.38617
1894.46	6.49484
1897.44	5.72901
1900.42	4.69678
1903.41	3.9803
1906.39	3.82653
1909.37	3.77709
1912.35	3.40175
1915.32	4.29575
1918.3	3.34274
1921.28	3.49837
1924.25	3.49792
1927.22	4.42053
1930.2	5.29246
1933.17	4.80718
1936.14	6.35974
1939.11	6.91642
1942.08	9.10348
1945.04	8.64488
1948.01	9.23357
1950.97	9.41709
1953.94	10.1852
1956.9	9.46295
1959.86	9.24417
1962.82	9.71539
1965.78	8.62148
1968.74	8.12502
1971.69	7.12345
1974.65	6.94216
1977.61	6.74102
1980.56	6.93898
1983.51	6.92574
1986.46	6.44201
1989.41	6.29598
1992.36	6.55489
1995.31	6.48868
1998.26	7.53949
2001.2	7.48939
2004.15	7.92868
2007.09	7.96366
2010.04	8.31188
2012.98	8.86144
2015.92	9.96339
2018.86	10.5287
2021.8	11.228
2024.74	11.2969
2027.67	11.8384
2030.61	12.5203
2033.54	13.2709
2036.47	13.6956
2039.41	13.4783
2042.34	13.6731
2045.27	14.2815
2048.2	15.3855
2051.12	16.2364
2054.05	17.4006
2056.98	18.0814
2059.9	19.0403
2062.82	20.0477
2065.75	20.4687
2068.67	21.8564
2071.59	23.5078
2074.51	24.1742
2077.43	25.4482
2080.34	26.8151
2083.26	28.9464
2086.17	31.5931
2089.09	33.0264
2092	35.3084
2094.91	36.9345
2097.82	40.2956
2100.73	42.0432
2103.64	44.1577
2106.55	47.2877
2109.46	49.9889
2112.36	53.8088
2115.27	57.2433
2118.17	62.4723
2121.07	66.0154
2123.97	71.1979
2126.87	76.22
2129.77	79.4361
2132.67	84.7054
2135.57	90.0694
2138.46	94.6367
2141.36	102.04
2144.25	107.7
2147.14	112.569
2150.03	117.172
2152.92	122.521
2155.81	128.247
2158.7	131.96
2161.59	134.673
2164.48	137.151
2167.36	138.65
2170.25	139.815
2173.13	139.828
2176.01	139.536
2178.89	138.272
2181.77	136.384
2184.65	134.267
2187.53	130.051
2190.41	125.294
2193.28	120.397
2196.16	116.506
2199.03	111.529
2201.9	107.548
2204.78	103.435
2207.65	98.1088
2210.51	93.6892
2213.38	90.0319
2216.25	84.8788
2219.12	81.1083
2221.98	77.2909
2224.85	73.8162
2227.71	70.5167
2230.57	66.6332
2233.43	62.7988
2236.29	59.2549
2239.15	55.0741
2242.01	51.5203
2244.87	47.8946
2247.73	43.9337
2250.58	40.2312
2253.43	36.5136
2256.29	33.0318
2259.14	29.6101
2261.99	27.1338
2264.84	25.7709
2267.69	23.868
2270.54	22.3528
2273.38	20.6339
2276.23	18.6459
2279.07	16.6168
2281.92	16.3024
2284.76	14.7291
2287.6	14.4362
2290.44	13.1113
2293.28	11.288
2296.12	11.0567
2298.96	11.8427
2301.79	12.7011
2304.63	11.8202
2307.46	11.8877
2310.3	11.8333
2313.13	12.3817
2315.96	11.7665
2318.79	11.574
2321.62	11.3155
2324.45	11.7015
2327.27	10.3629
2330.1	9.13662
2332.93	8.82171
2335.75	8.52301
2338.57	7.77759
2341.4	7.24104
2344.22	5.2416
2347.04	4.03417
2349.86	2.43412
2352.67	0.826256
2355.49	-0.107531
2358.31	-1.03268
2361.12	-1.52685
2363.94	-1.01924
2366.75	1.04499
2369.56	1.77732
2372.37	1.26909
2375.18	0.683459
2377.99	1.12474
2380.8	1.76874
2383.61	2.89811
2386.41	3.14579
2389.22	2.48585
2392.02	2.66953
2394.82	2.68593
2397.63	3.27966
2400.43	3.94144
2403.23	4.35434
2406.02	3.79997
2408.82	5.46479
2411.62	6.54393
2414.41	6.88196
2417.21	7.61613
2420	8.74148
2422.79	9.72542
2425.59	10.7571
2428.38	11.0965
2431.17	12.2771
2433.96	11.2793
2436.74	9.60167
2439.53	8.98227
2442.32	7.94155
2445.1	7.31905
2447.88	7.47887
2450.67	6.53296
2453.45	5.62819
2456.23	5.39139
2459.01	5.1504
2461.79	4.3151
2464.57	4.97804
2467.34	5.39908
2470.12	5.56289
2472.89	6.01233
2475.67	7.0336
2478.44	7.38279
2481.21	6.93566
2483.98	7.01943
2486.75	7.47685
2489.52	7.60927
2492.29	7.54025
2495.06	6.63485
2497.82	5.74565
2500.59	5.03678
2503.35	3.20433
2506.11	2.35291
2508.88	2.17861
2511.63	1.65501
2514.39	2.32876
2517.15	2.49085
2519.91	2.59841
2522.67	3.01005
2525.42	3.27345
2528.18	3.14499
2530.93	3.56603
2533.69	3.90694
2536.44	3.98216
2539.19	4.66667
2541.94	5.14343
2544.69	4.85563
2547.44	4.63116
2550.18	4.92729
2552.93	6.17219
2555.68	6.39553
2558.42	6.57097
2561.16	7.07599
2563.9	6.45502
2566.64	6.05023
2569.38	5.51281
2572.12	5.86017
2574.86	6.66899
2577.6	7.27506
2580.34	8.52893
2583.07	8.33106
2585.81	7.70182
2588.54	7.41962
2591.27	7.82157
2594	7.09848
2596.73	7.00577
2599.46	5.6649
2602.19	4.87427
2604.92	5.07948
2607.64	4.7347
2610.37	3.92432
2613.09	4.17671
2615.82	4.33607
2618.54	4.66626
2621.26	4.70428
2623.98	4.86756
2626.7	4.89012
2629.42	4.62153
2632.14	4.22433
2634.86	5.20231
2637.57	6.25696
2640.29	7.32169
2643	7.53269
2645.72	6.66911
2648.43	7.23357
2651.14	7.01727
2653.85	7.39854
2656.56	7.95203
2659.27	7.19149
2661.97	6.63483
2664.68	6.37642
2667.38	5.55856
2670.09	5.36183
2672.79	5.19671
2675.49	4.62606
2678.2	4.90915
2680.89	4.28399
2683.59	3.53436
2686.29	4.18587
2688.99	4.20997
2691.69	4.12267
2694.38	5.147
2697.08	4.34677
2699.77	4.52465
2702.46	5.25833
2705.16	5.61917
2707.85	5.9518
2710.54	6.91177
2713.23	8.18611
2715.92	9.38492
2718.6	9.5647
2721.29	9.57718
2723.97	10.324
2726.66	9.80129
2729.34	9.49531
2732.02	10.0477
2734.7	9.98835
2737.39	9.17735
2740.06	8.54446
2742.74	6.98341
2745.42	6.10703
2748.1	4.6647
2750.77	4.84819
2753.45	3.72436
2756.12	2.87797
2758.79	2.38971
2761.47	1.0434
2764.14	0.663638
2766.81	1.44364
2769.48	0.0988143
2772.14	-0.812132
2774.81	-0.866131
2777.48	-1.03462
2780.14	-0.980366
2782.81	-1.60931
2785.47	-1.88743
2788.13	-1.99136
2790.79	-2.06449
2793.46	-1.78847
2796.11	-1.11855
2798.77	-1.38238
2801.43	-1.37072
2804.09	-1.0468
2806.74	-2.38707
2809.4	-3.50298
2812.05	-3.69765
2814.71	-3.70264
2817.36	-2.60117
2820.01	-0.449155
2822.66	1.77089
2825.31	5.42542
2827.96	9.18929
2830.61	13.0923
2833.25	18.1653
2835.9	22.949
2838.54	28.6465
2841.18	34.5984
2843.83	41.5723
2846.47	48.5264
2849.11	55.951
2851.75	63.9962
2854.39	71.8141
2857.03	78.5326
2859.67	86.5606
2862.3	93.0768
2864.94	99.0224
2867.57	103.83
2870.21	107.183
2872.84	109.851
2875.47	113.398
2878.1	116.913
2880.73	121.432
2883.36	125.722
2885.99	130.139
2888.61	133.996
2891.24	138.445
2893.87	144.032
2896.49	150.951
2899.11	158.891
2901.74	167.396
2904.36	176.828
2906.98	187.691
2909.6	199.511
2912.22	212.203
2914.83	225.126
2917.45	237.837
2920.07	249.12
2922.68	259.821
2925.3	268.331
2927.91	273.849
2930.52	277.1
2933.13	278.824
2935.74	278.009
2938.35	275.739
2940.96	270.993
2943.57	264.396
2946.18	255.949
2948.78	246.55
2951.39	235.5
2953.99	223.641
2956.6	211.702
2959.2	199.869
2961.8	188.841
2964.4	177.561
2967	165.903
2969.6	156.128
2972.2	145.068
2974.79	136.01
2977.39	126.468
2979.98	116.556
2982.58	107.74
2985.17	98.0483
2987.76	88.7952
2990.36	77.9191
2992.95	68.5366
2995.54	60.07
2998.12	51.8192
3000.71	44.014
3003.3	36.8058
3005.88	29.7609
3008.47	23.669
3011.05	18.3066
3013.64	13.6077
3016.22	10.2638
3018.8	8.07246
3021.38	6.16969
3023.96	4.95141
3026.54	3.92013
3029.12	2.38307
3031.69	2.29757
3034.27	2.2831
3036.85	2.34309
3039.42	3.75437
3041.99	4.96945
3044.57	6.20393
3047.14	6.16984
3049.71	6.79611
3052.28	7.66106
3054.85	8.01656
3057.42	7.81354
3059.98	6.82869
3062.55	6.27958
3065.11	5.67249
3067.68	4.70282
3070.24	3.42159
3072.8	3.35253
3075.37	3.49399
3077.93	2.86008
3080.49	2.38309
3083.05	1.98728
3085.61	1.04055
3088.16	1.56391
3090.72	0.752032
3093.27	0.785187
3095.83	1.21036
3098.38	1.98336
3100.94	3.88832
3103.49	5.80138
3106.04	6.90558
3108.59	7.88771
3111.14	8.94573
3113.69	10.9954
3116.23	12.9542
3118.78	14.3685
3121.33	15.4391
3123.87	16.9523
3126.42	19.1459
3128.96	20.7329
3131.5	22.8368
3134.04	25.2668
3136.58	27.371
3139.12	28.5482
3141.66	30.5424
3144.2	32.3673
3146.74	33.657
3149.27	32.887