File: data/Raman/poly_smoothed/Mb_50_18_47_1x_45s_532 nm_x100_100%_600 gr_mm_01.txt
#Acq. time (s)=	45
#Accumulations=	2
#Range (cm-¹)=	200...3150
#Windows=	2
#Auto scanning=	Off
#Autofocus=	Off
#Macrospot=	Off
#AutoExposure=	Off
#Spike filter=	Multiple accum.
#Delay time (s)=	0
#Binning=	1
#Readout mode=	Signal
#DeNoise=	Off
#ICS correction=	On
#Dark correction=	Off
#Inst. Process=	Off
#Detector Gain=	Best Dynamic Range
#Detector ADC=	20 kHz
#Detector temperature (°C)=	-69.85
#Instrument=	LabRAM HR Evol
#Detector=	Synapse
#Objective=	x100
#Grating=	600 gr/mm
#ND Filter=	100%
#Laser (nm)=	532
#Hole=	100.021
#Range=	Auto
#Laser Pol.=	No
#Raman. Pol.=	No
#Laser Pol. (°)=	-0.0007625
#Raman Pol. (°)=	89.9995
#Collection=	Microscope
#StageXY=	Marzhauser
#StageZ=	Marzhauser
#X (µm)=	28458.1
#Y (µm)=	-2965.4
#Z (µm)=	1043.55
#Full time(mm:ss)=	3:19
#Project=
#Sample=
#Site=
#Title=	Mb_50_18_47_2x_45s_532 nm_x100_100%_600 gr_mm
#Remark=
#Date=	12.07.2022 14:42
#Acquired=	12.07.2022 14:42:48
#Edit:Spike=	12.07.2022 14:45:55
#Base:Fit=	10.08.2022 10:49:18
#Base:Sub=	10.08.2022 10:49:30
#Filter:Polynom=	16.08.2022 10:14:59
#AxisType[0]=Intens
#AxisUnit[0]=Cnt
#AxisType[1]=Spectr
#AxisUnit[1]=1/cm
200.388	32.2581
204.019	29.0957
207.646	27.3076
211.274	25.0176
214.899	23.7202
218.524	21.1751
222.146	18.8585
225.766	16.1623
229.388	12.9472
233.005	11.8791
236.621	9.5176
240.236	8.39581
243.852	6.92194
247.464	6.16951
251.074	5.54295
254.683	6.74873
258.291	6.84983
261.897	7.07878
265.504	4.8222
269.108	3.98862
272.71	4.5263
276.311	4.93144
279.91	3.75259
283.508	4.00974
287.105	6.58331
290.698	7.26928
294.291	8.30271
297.884	9.22609
301.475	10.0249
305.064	11.6004
308.652	11.7322
312.237	11.9829
315.822	12.4733
319.406	12.3425
322.987	11.793
326.568	11.8425
330.148	11.2306
333.724	10.956
337.301	11.7225
340.875	10.2803
344.449	9.5418
348.02	8.8255
351.592	7.54849
355.16	7.7062
358.728	7.33001
362.294	7.83348
365.858	9.48217
369.422	12.4371
372.983	13.0796
376.543	13.9961
380.102	15.776
383.661	18.2579
387.216	18.6035
390.771	19.7645
394.324	19.6949
397.875	19.3353
401.425	18.7939
404.974	18.6053
408.524	16.1539
412.07	13.6091
415.614	12.3733
419.156	9.83356
422.698	7.16003
426.238	5.3612
429.777	4.01185
433.315	3.42339
436.852	3.33332
440.387	3.87583
443.919	3.33071
447.451	3.87528
450.982	4.19216
454.512	2.36471
458.038	2.50664
461.565	2.28762
465.091	5.72866
468.613	5.47608
472.136	7.10679
475.655	7.90561
479.176	12.3558
482.692	12.4377
486.21	15.3441
489.724	17.5507
493.237	18.2899
496.75	19.7045
500.26	20.5348
503.771	23.6518
507.279	23.4351
510.785	25.5117
514.289	25.8127
517.793	23.559
521.297	23.2492
524.797	22.0175
528.297	19.199
531.795	16.9219
535.291	14.053
538.787	11.1776
542.281	10.4923
545.773	9.53029
549.264	8.09238
552.754	6.36059
556.243	4.92277
559.73	3.31696
563.216	4.26264
566.701	4.84639
570.182	3.6815
573.664	4.93112
577.145	4.53748
580.624	4.91858
584.1	7.19725
587.577	5.36542
591.052	5.33131
594.524	4.94139
597.997	4.60659
601.466	5.04361
604.936	5.68048
608.403	5.88246
611.87	4.94738
615.334	4.14347
618.799	3.81869
622.26	4.13562
625.72	5.59018
629.181	3.66872
632.638	3.64089
636.095	2.68068
639.551	3.41906
643.005	4.62356
646.457	4.77178
649.908	6.34282
653.357	9.03939
656.806	9.33335
660.253	11.9815
663.7	15.185
667.145	16.2378
670.588	17.6915
674.027	18.1771
677.468	18.3418
680.907	21.0364
684.345	23.8025
687.781	25.3446
691.216	26.5775
694.65	27.2704
698.081	27.8443
701.512	28.6835
704.942	30.4258
708.371	30.4442
711.796	30.337
715.222	28.7925
718.645	30.8308
722.068	31.7048
725.49	33.0505
728.909	32.0265
732.329	35.5241
735.745	38.8172
739.16	42.205
742.576	48.146
745.988	54.3796
749.401	59.3126
752.811	62.7673
756.22	68.0536
759.627	71.139
763.035	76.0718
766.44	81.4773
769.843	85.001
773.245	87.8273
776.646	90.3198
780.046	92.3067
783.444	92.4984
786.841	94.3489
790.237	92.5578
793.631	92.4008
797.024	89.3938
800.416	88.9094
803.807	87.1178
807.196	83.5309
810.584	78.1358
813.971	76.8224
817.354	76.3808
820.739	76.0072
824.122	75.6818
827.503	75.0736
830.882	73.5897
834.261	71.6369
837.637	69.2918
841.013	65.6971
844.389	62.3593
847.761	59.5767
851.131	56.1159
854.503	53.6992
857.871	53.1042
861.24	51.8047
864.606	49.0974
867.97	47.1021
871.336	47.2995
874.698	45.6019
878.058	44.7587
881.418	45.0316
884.778	43.9025
888.135	42.6067
891.49	42.5616
894.845	42.1396
898.198	43.0158
901.55	42.7647
904.901	42.3383
908.25	41.8623
911.598	43.0679
914.945	42.3573
918.291	39.0733
921.635	35.6374
924.978	35.9192
928.318	32.9627
931.659	32.8967
934.998	32.7838
938.336	31.8649
941.671	30.9596
945.007	29.1363
948.339	26.8425
951.672	26.2395
955.004	24.6961
958.333	24.1881
961.662	23.5353
964.989	24.9922
968.315	23.0811
971.639	23.5962
974.962	21.6873
978.285	20.5936
981.605	18.7292
984.924	16.5516
988.243	16.4693
991.56	16.836
994.875	18.0863
998.188	18.5506
1001.5	20.066
1004.81	21.2962
1008.12	23.1701
1011.43	26.1053
1014.74	28.523
1018.05	30.9233
1021.35	31.7258
1024.65	31.2041
1027.96	31.8619
1031.26	32.723
1034.56	33.1061
1037.86	33.9861
1041.16	33.3193
1044.45	31.9732
1047.75	29.9082
1051.04	27.5757
1054.33	25.7807
1057.62	23.8303
1060.91	21.2067
1064.2	21.1626
1067.49	20.8933
1070.77	21.4974
1074.06	23.2959
1077.34	22.6066
1080.62	23.4318
1083.91	22.5277
1087.18	23.0673
1090.46	23.416
1093.74	22.5484
1097.02	21.463
1100.29	20.2286
1103.56	18.2033
1106.84	16.4569
1110.11	16.4944
1113.38	14.7542
1116.64	13.0696
1119.91	11.7463
1123.18	8.77261
1126.44	7.03178
1129.7	6.05523
1132.97	6.94145
1136.23	7.20251
1139.49	6.25321
1142.74	8.15509
1146	6.44274
1149.26	5.94559
1152.51	6.97318
1155.76	7.63297
1159.01	6.04747
1162.27	6.4221
1165.51	5.74985
1168.76	4.76112
1172.01	4.28803
1175.25	2.92873
1178.5	3.7473
1181.74	3.29124
1184.98	4.58802
1188.22	4.21132
1191.46	3.31049
1194.7	4.18802
1197.94	3.56898
1201.17	2.98417
1204.41	2.95678
1207.64	4.9401
1210.87	5.84429
1214.1	7.66942
1217.33	8.1032
1220.56	9.37101
1223.79	10.4256
1227.01	10.5781
1230.23	13.3655
1233.46	13.5298
1236.68	13.5422
1239.9	13.0004
1243.12	13.0794
1246.34	13.3421
1249.55	13.4377
1252.77	14.5466
1255.98	15.8574
1259.2	17.9364
1262.41	19.1578
1265.62	20.6012
1268.83	21.4531
1272.03	24.0826
1275.24	26.5393
1278.45	27.6983
1281.65	29.7685
1284.85	30.9856
1288.06	33.5014
1291.26	35.3817
1294.46	38.2023
1297.66	37.8729
1300.85	38.2966
1304.05	38.6748
1307.24	38.5602
1310.43	39.3635
1313.63	39.1174
1316.82	39.0996
1320.01	39.5236
1323.2	39.1493
1326.38	40.0559
1329.57	39.8381
1332.76	40.6686
1335.94	40.1695
1339.12	39.311
1342.3	39.0681
1345.48	38.3391
1348.66	36.2596
1351.84	34.3216
1355.01	32.9179
1358.19	31.4919
1361.36	29.7584
1364.53	27.07
1367.71	25.1752
1370.88	24.832
1374.04	22.9204
1377.21	21.2682
1380.38	20.3709
1383.54	20.4553
1386.71	20.3543
1389.87	19.349
1393.03	19.4227
1396.19	18.561
1399.35	18.4637
1402.51	19.5239
1405.67	19.7437
1408.82	20.0773
1411.98	22.3904
1415.13	25.136
1418.28	29.444
1421.43	33.8565
1424.58	38.1562
1427.73	42.913
1430.88	46.3241
1434.02	48.803
1437.17	52.6127
1440.31	54.2999
1443.45	55.8608
1446.6	57.9389
1449.74	59.5978
1452.87	58.8449
1456.01	57.8082
1459.15	57.5209
1462.28	56.0553
1465.42	53.0552
1468.55	52.2494
1471.68	48.1468
1474.81	45.3528
1477.94	42.9852
1481.07	40.8636
1484.2	39.3738
1487.32	37.9153
1490.45	36.6526
1493.57	35.8964
1496.69	33.4426
1499.81	32.3546
1502.93	30.8882
1506.05	27.8171
1509.17	25.4556
1512.28	25.0043
1515.4	23.0341
1518.51	20.595
1521.63	18.747
1524.74	17.7131
1527.85	15.632
1530.96	15.1953
1534.06	14.7071
1537.17	16.3277
1540.28	17.9718
1543.38	19.0061
1546.48	19.8088
1549.59	20.12
1552.69	21.1608
1555.79	23.2161
1558.88	24.4908
1561.98	25.2816
1565.08	25.9199
1568.17	26.9384
1571.27	26.2506
1574.36	27.52
1577.45	29.6419
1580.54	30.5857
1583.63	32.412
1586.72	32.9097
1589.8	33.7278
1592.89	34.7989
1595.97	34.4731
1599.06	33.6352
1602.14	33.6503
1605.22	33.7947
1608.3	33.2834
1611.38	34.2209
1614.46	34.4934
1617.53	33.9391
1620.61	34.2963
1623.68	34.1716
1626.75	34.1975
1629.82	35.2029
1632.9	35.4999
1635.96	36.3064
1639.03	35.3339
1642.1	34.3465
1645.16	34.9756
1648.23	33.9829
1651.29	33.978
1654.36	34.751
1657.42	35.5319
1660.48	34.3273
1663.53	33.8993
1666.59	32.0058
1669.65	31.5558
1672.7	30.6975
1675.76	28.9112
1678.81	28.1155
1681.86	26.6484
1684.91	25.6593
1687.96	24.4646
1691.01	21.9224
1694.06	20.7564
1697.11	19.811
1700.15	17.8515
1703.2	16.2231
1706.24	15.3448
1709.28	12.4773
1712.32	11.0389
1715.36	8.49754
1718.4	6.89851
1721.43	5.06532
1724.47	2.20979
1727.5	1.90753
1730.54	1.21958
1733.57	0.204324
1736.6	0.957509
1739.63	0.222674
1742.66	1.03687
1745.69	2.48627
1748.72	2.48213
1751.74	3.49954
1754.77	4.347
1757.79	4.36731
1760.81	4.42014
1763.83	3.95633
1766.85	3.47619
1769.87	4.47729
1772.89	5.39983
1775.91	4.95242
1778.92	5.20998
1781.94	5.24413
1784.95	5.29421
1787.96	3.91461
1790.97	4.37537
1793.98	3.75382
1796.99	3.38704
1800	3.0191
1803	2.68143
1806.01	3.19791
1809.01	3.80758
1812.02	3.15356
1815.02	3.43989
1818.02	4.16931
1821.02	3.25214
1824.02	3.58901
1827.01	3.30751
1830.01	3.4398
1833	3.11828
1836	2.54752
1838.99	2.65302
1841.98	3.47379
1844.97	3.3838
1847.96	3.63963
1850.95	3.21397
1853.94	3.51417
1856.92	2.72325
1859.91	2.21439
1862.89	0.989355
1865.88	1.54938
1868.86	1.21275
1871.84	1.15713
1874.82	1.70457
1877.8	2.16102
1880.77	2.78583
1882.51	3.36277
1885.5	4.36952
1888.48	5.59953
1891.47	6.10977
1894.46	6.98497
1897.44	7.59173
1900.42	8.79211
1903.41	10.1024
1906.39	11.856
1909.37	12.8645
1912.35	12.6583
1915.32	13.1768
1918.3	11.4369
1921.28	10.5193
1924.25	10.1305
1927.22	8.42306
1930.2	6.95426
1933.17	5.74762
1936.14	6.55112
1939.11	5.79235
1942.08	4.94624
1945.04	3.72566
1948.01	3.16506
1950.97	2.3344
1953.94	1.89862
1956.9	2.52486
1959.86	3.61799
1962.82	2.40715
1965.78	3.44439
1968.74	2.46693
1971.69	4.78948
1974.65	5.04746
1977.61	6.2052
1980.56	6.80396
1983.51	5.93608
1986.46	6.5918
1989.41	6.24946
1992.36	5.8945
1995.31	6.76909
1998.26	7.83965
2001.2	6.62729
2004.15	7.39877
2007.09	6.6174
2010.04	6.73145
2012.98	5.74706
2015.92	4.82619
2018.86	4.94341
2021.8	5.26852
2024.74	6.65015
2027.67	8.21178
2030.61	9.53508
2033.54	9.43386
2036.47	11.4187
2039.41	11.7843
2042.34	12.9189
2045.27	13.6026
2048.2	14.2103
2051.12	14.4669
2054.05	14.4347
2056.98	15.0418
2059.9	15.9174
2062.82	15.8014
2065.75	15.9527
2068.67	16.9073
2071.59	17.1711
2074.51	16.5397
2077.43	17.4021
2080.34	18.8123
2083.26	19.3599
2086.17	19.9982
2089.09	21.4024
2092	22.1777
2094.91	23.7973
2097.82	26.272
2100.73	26.4163
2103.64	28.1623
2106.55	28.8774
2109.46	29.4266
2112.36	29.8704
2115.27	31.336
2118.17	31.5948
2121.07	31.5913
2123.97	32.6457
2126.87	33.607
2129.77	35.1526
2132.67	36.2198
2135.57	38.3198
2138.46	41.2397
2141.36	43.8382
2144.25	45.9359
2147.14	47.7227
2150.03	49.7264
2152.92	52.335
2155.81	52.555
2158.7	53.8712
2161.59	54.9283
2164.48	56.7987
2167.36	58.546
2170.25	59.5352
2173.13	59.9508
2176.01	59.7648
2178.89	59.6679
2181.77	58.759
2184.65	58.8545
2187.53	58.1697
2190.41	55.8313
2193.28	55.0761
2196.16	54.3604
2199.03	53.4035
2201.9	51.6211
2204.78	51.1333
2207.65	49.7644
2210.51	47.7364
2213.38	46.4614
2216.25	42.2287
2219.12	39.9903
2221.98	38.8393
2224.85	35.7722
2227.71	35.0227
2230.57	34.0031
2233.43	31.1588
2236.29	29.8194
2239.15	27.1524
2242.01	24.9902
2244.87	23.689
2247.73	23.1704
2250.58	21.399
2253.43	21.1241
2256.29	20.9886
2259.14	18.9646
2261.99	18.6293
2264.84	18.6497
2267.69	19.2501
2270.54	19.4797
2273.38	19.5848
2276.23	20.0497
2279.07	20.4239
2281.92	18.8931
2284.76	18.8354
2287.6	18.3039
2290.44	18.0944
2293.28	17.5569
2296.12	17.4783
2298.96	17.5407
2301.79	16.7221
2304.63	17.3831
2307.46	17.0244
2310.3	16.3338
2313.13	16.6793
2315.96	17.1995
2318.79	17.7896
2321.62	16.0171
2324.45	14.73
2327.27	13.5924
2330.1	13.7029
2332.93	12.896
2335.75	12.2698
2338.57	12.1968
2341.4	10.771
2344.22	10.9946
2347.04	9.66133
2349.86	8.60142
2352.67	7.18743
2355.49	6.50287
2358.31	5.27248
2361.12	4.1669
2363.94	4.53305
2366.75	5.43576
2369.56	5.20869
2372.37	5.8129
2375.18	5.46994
2377.99	5.76772
2380.8	6.74076
2383.61	7.58521
2386.41	7.55525
2389.22	7.02723
2392.02	6.05845
2394.82	7.08523
2397.63	8.90893
2400.43	9.44699
2403.23	9.00651
2406.02	9.36311
2408.82	9.68982
2411.62	10.7694
2414.41	9.68878
2417.21	9.6029
2420	8.21262
2422.79	8.16819
2425.59	6.48066
2428.38	6.66363
2431.17	5.02605
2433.96	4.21768
2436.74	3.84944
2439.53	3.74004
2442.32	2.85967
2445.1	3.47096
2447.88	2.98257
2450.67	3.00275
2453.45	3.26853
2456.23	2.75764
2459.01	2.4279
2461.79	3.0945
2464.57	3.74807
2467.34	3.40509
2470.12	3.02111
2472.89	3.30167
2475.67	3.4301
2478.44	4.43442
2481.21	4.60438
2483.98	4.84738
2486.75	5.70619
2489.52	5.64751
2492.29	5.77093
2495.06	5.47252
2497.82	4.34829
2500.59	4.19418
2503.35	4.56944
2506.11	4.96745
2508.88	4.60182
2511.63	4.56537
2514.39	4.46753
2517.15	4.35987
2519.91	3.5781
2522.67	3.79617
2525.42	3.74586
2528.18	3.09755
2530.93	2.59414
2533.69	2.94471
2536.44	2.24794
2539.19	1.97132
2541.94	2.06334
2544.69	4.0892
2547.44	4.71049
2550.18	4.90165
2552.93	4.6581
2555.68	5.52077
2558.42	5.10052
2561.16	4.27483
2563.9	3.60316
2566.64	2.79918
2569.38	3.80648
2572.12	4.15787
2574.86	4.37607
2577.6	5.36861
2580.34	5.89425
2583.07	6.83568
2585.81	7.30005
2588.54	6.74198
2591.27	6.04982
2594	6.40565
2596.73	6.07849
2599.46	6.40626
2602.19	5.64198
2604.92	5.19531
2607.64	4.54131
2610.37	5.3869
2613.09	5.79647
2615.82	4.59324
2618.54	4.72703
2621.26	5.81985
2623.98	5.05813
2626.7	4.75985
2629.42	4.32011
2632.14	3.71979
2634.86	3.46233
2637.57	4.58604
2640.29	5.51731
2643	6.09815
2645.72	6.24709
2648.43	6.68189
2651.14	5.53149
2653.85	4.80117
2656.56	4.45243
2659.27	3.97617
2661.97	5.02765
2664.68	3.73445
2667.38	3.31367
2670.09	3.07481
2672.79	4.11605
2675.49	4.37135
2678.2	4.60157
2680.89	4.90191
2683.59	5.64916
2686.29	5.49601
2688.99	5.50823
2691.69	5.05424
2694.38	4.59809
2697.08	5.60094
2699.77	4.92103
2702.46	5.25869
2705.16	6.41911
2707.85	6.35164
2710.54	7.04239
2713.23	6.97313
2715.92	6.52587
2718.6	6.28431
2721.29	7.01434
2723.97	6.61836
2726.66	6.95378
2729.34	6.85554
2732.02	5.48771
2734.7	4.96137
2737.39	4.82137
2740.06	4.12823
2742.74	3.34231
2745.42	2.72422
2748.1	3.5074
2750.77	1.85971
2753.45	0.932316
2756.12	1.90232
2758.79	1.25464
2761.47	0.964888
2764.14	0.444572
2766.81	0.281255
2769.48	0.824204
2772.14	2.34148
2774.81	3.11767
2777.48	3.06956
2780.14	3.13687
2782.81	4.09266
2785.47	5.55928
2788.13	5.4817
2790.79	4.96894
2793.46	4.66225
2796.11	4.65489
2798.77	4.21692
2801.43	3.47144
2804.09	3.18012
2806.74	3.00154
2809.4	2.54952
2812.05	1.84872
2814.71	2.38775
2817.36	2.53407
2820.01	4.62271
2822.66	6.60773
2825.31	8.60075
2827.96	12.1788
2830.61	16.1089
2833.25	19.0319
2835.9	23.8682
2838.54	28.3024
2841.18	31.624
2843.83	37.7874
2846.47	42.6749
2849.11	48.1415
2851.75	53.665
2854.39	58.394
2857.03	64.2367
2859.67	69.3327
2862.3	72.5149
2864.94	74.9022
2867.57	78.3495
2870.21	80.6797
2872.84	81.8676
2875.47	84.0288
2878.1	86.7351
2880.73	89.3466
2883.36	91.0634
2885.99	92.9734
2888.61	94.7764
2891.24	97.239
2893.87	100.162
2896.49	102.385
2899.11	104.367
2901.74	107.044
2904.36	111.608
2906.98	116.288
2909.6	120.519
2912.22	126.865
2914.83	132.352
2917.45	138.66
2920.07	143.543
2922.68	145.345
2925.3	147.481
2927.91	148.425
2930.52	148.427
2933.13	148.942
2935.74	146.964
2938.35	144.238
2940.96	141.721
2943.57	138.477
2946.18	134.075
2948.78	128.232
2951.39	124.407
2953.99	120.792
2956.6	116.315
2959.2	111.463
2961.8	105.464
2964.4	101.064
2967	97.4249
2969.6	93.8167
2972.2	88.138
2974.79	83.9148
2977.39	78.5109
2979.98	73.0351
2982.58	68.2594
2985.17	62.028
2987.76	55.3627
2990.36	49.3924
2992.95	42.7824
2995.54	37.2109
2998.12	33.1283
3000.71	26.3813
3003.3	21.7742
3005.88	18.4527
3008.47	14.3325
3011.05	11.5166
3013.64	9.69637
3016.22	8.44856
3018.8	6.56998
3021.38	5.42212
3023.96	4.59163
3026.54	3.39803
3029.12	3.69489
3031.69	2.47171
3034.27	1.33737
3036.85	0.562386
3039.42	0.24629
3041.99	1.73809
3044.57	2.59186
3047.14	3.62285
3049.71	3.15989
3052.28	3.92231
3054.85	3.81723
3057.42	4.07997
3059.98	5.62556
3062.55	6.94014
3065.11	7.38494
3067.68	7.45593
3070.24	7.88213
3072.8	9.26305
3075.37	8.69277
3077.93	9.06509
3080.49	7.70036
3083.05	6.48907
3085.61	6.35703
3088.16	5.05752
3090.72	4.73342
3093.27	4.47315
3095.83	3.70015
3098.38	3.53528
3100.94	4.85019
3103.49	4.45571
3106.04	6.04586
3108.59	5.01711
3111.14	5.59541
3113.69	6.57206
3116.23	7.54334
3118.78	8.89708
3121.33	11.0397
3123.87	12.7414
3126.42	13.4291
3128.96	14.0818
3131.5	15.8805
3134.04	17.0138
3136.58	17.6659
3139.12	18.3582
3141.66	18.5928
3144.2	19.3707
3146.74	20.3234
3149.27	21.5213