File: data/Raman/poly_smoothed/Mb_50_18_48_1x_45s_532 nm_x100_100%_600 gr_mm_01.txt
#Acq. time (s)=	45
#Accumulations=	2
#Range (cm-¹)=	200...3150
#Windows=	2
#Auto scanning=	Off
#Autofocus=	Off
#Macrospot=	Off
#AutoExposure=	Off
#Spike filter=	Multiple accum.
#Delay time (s)=	0
#Binning=	1
#Readout mode=	Signal
#DeNoise=	Off
#ICS correction=	On
#Dark correction=	Off
#Inst. Process=	Off
#Detector Gain=	Best Dynamic Range
#Detector ADC=	20 kHz
#Detector temperature (°C)=	-69.85
#Instrument=	LabRAM HR Evol
#Detector=	Synapse
#Objective=	x100
#Grating=	600 gr/mm
#ND Filter=	100%
#Laser (nm)=	532
#Hole=	100.021
#Range=	Auto
#Laser Pol.=	No
#Raman. Pol.=	No
#Laser Pol. (°)=	-0.0007625
#Raman Pol. (°)=	89.9995
#Collection=	Microscope
#StageXY=	Marzhauser
#StageZ=	Marzhauser
#X (µm)=	28476.5
#Y (µm)=	-2956.7
#Z (µm)=	1043.55
#Full time(mm:ss)=	3:18
#Project=
#Sample=
#Site=
#Title=	Mb_50_18_48_2x_45s_532 nm_x100_100%_600 gr_mm
#Remark=
#Date=	12.07.2022 14:47
#Acquired=	12.07.2022 14:47:18
#Base:Fit=	10.08.2022 10:49:18
#Base:Sub=	10.08.2022 10:49:30
#Filter:Polynom=	16.08.2022 10:14:59
#AxisType[0]=Intens
#AxisUnit[0]=Cnt
#AxisType[1]=Spectr
#AxisUnit[1]=1/cm
200.388	39.3909
204.019	29.8604
207.646	24.7236
211.274	19.6926
214.899	15.9047
218.524	13.0752
222.146	11.1093
225.766	10.0935
229.388	9.25688
233.005	7.772
236.621	6.10905
240.236	4.812
243.852	2.92137
247.464	2.03057
251.074	2.90864
254.683	2.9254
258.291	4.00716
261.897	4.71441
265.504	3.50459
269.108	2.66472
272.71	2.59886
276.311	3.42779
279.91	3.13395
283.508	3.13782
287.105	4.9504
290.698	6.37661
294.291	6.38923
297.884	7.61965
301.475	11.3226
305.064	12.8044
308.652	14.5057
312.237	15.2352
315.822	15.5253
319.406	16.4953
322.987	16.4574
326.568	16.1858
330.148	16.7619
333.724	13.7882
337.301	14.5914
340.875	15.0527
344.449	14.6911
348.02	14.5974
351.592	14.8993
355.16	16.1024
358.728	18.373
362.294	21.72
365.858	23.9785
369.422	25.125
372.983	27.2492
376.543	29.1841
380.102	30.6131
383.661	33.022
387.216	34.0187
390.771	33.9207
394.324	33.1381
397.875	31.1384
401.425	29.4541
404.974	27.1202
408.524	25.6832
412.07	22.7933
415.614	18.6688
419.156	15.2888
422.698	14.0279
426.238	13.8497
429.777	12.228
433.315	12.543
436.852	13.0016
440.387	13.9725
443.919	13.3491
447.451	15.3124
450.982	14.273
454.512	14.3453
458.038	15.6784
461.565	16.3058
465.091	15.7551
468.613	18.7087
472.136	20.5008
475.655	22.4673
479.176	26.7334
482.692	29.716
486.21	33.9225
489.724	35.8288
493.237	38.4323
496.75	42.8138
500.26	45.4506
503.771	47.7641
507.279	50.9896
510.785	53.3838
514.289	52.728
517.793	52.0267
521.297	52.535
524.797	49.7331
528.297	49.0134
531.795	45.5836
535.291	42.3875
538.787	38.5043
542.281	33.36
545.773	30.0933
549.264	23.3326
552.754	20.0667
556.243	17.6992
559.73	14.5439
563.216	14.4874
566.701	13.1844
570.182	11.8588
573.664	9.75195
577.145	9.5442
580.624	10.4197
584.1	9.75852
587.577	9.06145
591.052	7.41433
594.524	7.55425
597.997	6.15721
601.466	6.66057
604.936	6.58885
608.403	7.37572
611.87	8.25079
615.334	7.40172
618.799	7.82074
622.26	7.40209
625.72	5.05047
629.181	4.51822
632.638	3.39867
636.095	2.31704
639.551	2.38584
643.005	2.1608
646.457	3.80006
649.908	4.83203
653.357	4.59722
656.806	4.57118
660.253	4.76417
663.7	5.79478
667.145	5.02536
670.588	4.85877
674.027	6.07733
677.468	5.45736
680.907	5.16185
684.345	7.01214
687.781	9.45813
691.216	9.60433
694.65	12.8208
698.081	15.2438
701.512	17.427
704.942	18.8667
708.371	20.7354
711.796	20.1384
715.222	21.2394
718.645	21.8582
722.068	22.8711
725.49	25.0376
728.909	26.8133
732.329	28.6283
735.745	31.597
739.16	34.5943
742.576	39.1402
745.988	45.8612
749.401	51.6129
752.811	57.7538
756.22	64.3311
759.627	68.4597
763.035	72.9442
766.44	78.0893
769.843	82.7697
773.245	85.3934
776.646	88.3524
780.046	89.8634
783.444	89.9163
786.841	90.7175
790.237	90.39
793.631	88.8137
797.024	86.0194
800.416	82.6259
803.807	77.8806
807.196	74.4429
810.584	72.4322
813.971	68.9986
817.354	69.2963
820.739	68.4849
824.122	68.5569
827.503	67.7786
830.882	68.9622
834.261	67.7856
837.637	68.1973
841.013	67.7343
844.389	65.4704
847.761	62.3703
851.131	58.7533
854.503	58.0756
857.871	55.7244
861.24	53.7395
864.606	52.1738
867.97	50.065
871.336	48.5104
874.698	46.3239
878.058	42.8169
881.418	38.691
884.778	37.9708
888.135	37.3406
891.49	36.6888
894.845	35.4718
898.198	35.3887
901.55	35.8693
904.901	34.4305
908.25	33.9142
911.598	32.9899
914.945	32.7169
918.291	30.6556
921.635	29.2171
924.978	27.3596
928.318	25.9294
931.659	25.2015
934.998	24.4678
938.336	23.4293
941.671	22.8477
945.007	22.5022
948.339	21.6963
951.672	21.6507
955.004	22.5405
958.333	21.2303
961.662	22.9601
964.989	24.7355
968.315	28.081
971.639	27.9336
974.962	30.7942
978.285	32.4981
981.605	32.9816
984.924	29.3118
988.243	30.2919
991.56	30.6713
994.875	31.394
998.188	36.4012
1001.5	40.1144
1004.81	45.0626
1008.12	49.3192
1011.43	55.2968
1014.74	59.7154
1018.05	64.2975
1021.35	69.1856
1024.65	71.64
1027.96	74.1916
1031.26	74.8586
1034.56	76.2966
1037.86	75.7049
1041.16	75.2283
1044.45	74.2861
1047.75	72.7678
1051.04	69.4064
1054.33	64.3253
1057.62	59.0786
1060.91	53.7018
1064.2	49.4227
1067.49	46.7016
1070.77	46.5684
1074.06	45.7522
1077.34	47.2997
1080.62	45.5806
1083.91	44.0645
1087.18	45.4618
1090.46	47.1785
1093.74	49.3653
1097.02	49.1991
1100.29	51.2411
1103.56	52.3599
1106.84	51.9652
1110.11	50.1296
1113.38	48.3661
1116.64	47.0039
1119.91	44.5567
1123.18	42.7365
1126.44	39.4309
1129.7	35.3179
1132.97	29.579
1136.23	26.1722
1139.49	25.3445
1142.74	23.7167
1146	20.161
1149.26	16.8726
1152.51	12.979
1155.76	8.92212
1159.01	4.81704
1162.27	4.6764
1165.51	5.09377
1168.76	4.65578
1172.01	4.914
1175.25	6.02167
1178.5	7.40108
1181.74	7.06345
1184.98	7.08092
1188.22	5.49337
1191.46	4.54106
1194.7	5.62056
1197.94	7.71791
1201.17	10.5939
1204.41	11.4376
1207.64	14.162
1210.87	17.0341
1214.1	20.6194
1217.33	25.5532
1220.56	30.3203
1223.79	34.9466
1227.01	37.906
1230.23	41.9038
1233.46	46.4766
1236.68	50.1992
1239.9	56.2357
1243.12	60.7561
1246.34	64.2449
1249.55	68.7457
1252.77	72.3466
1255.98	75.1414
1259.2	78.0332
1262.41	80.9519
1265.62	84.6109
1268.83	88.2481
1272.03	93.8637
1275.24	99.1858
1278.45	102.908
1281.65	107.14
1284.85	110.897
1288.06	114.345
1291.26	117.028
1294.46	117.997
1297.66	120.42
1300.85	121.404
1304.05	120.977
1307.24	119.329
1310.43	117.354
1313.63	115.017
1316.82	113.427
1320.01	110.373
1323.2	109.274
1326.38	106.803
1329.57	103.244
1332.76	100.076
1335.94	95.0139
1339.12	93.2309
1342.3	88.5204
1345.48	85.4491
1348.66	81.8293
1351.84	77.485
1355.01	74.0872
1358.19	69.307
1361.36	65.9723
1364.53	61.2191
1367.71	55.1117
1370.88	52.6405
1374.04	50.0113
1377.21	47.0453
1380.38	42.8023
1383.54	39.1774
1386.71	36.4278
1389.87	34.3922
1393.03	33.9243
1396.19	32.6702
1399.35	33.2017
1402.51	34.1461
1405.67	37.7858
1408.82	41.6652
1411.98	45.3767
1415.13	51.8066
1418.28	60.7211
1421.43	67.8648
1424.58	80.057
1427.73	91.4771
1430.88	103.655
1434.02	113.108
1437.17	120.356
1440.31	127.991
1443.45	130.593
1446.6	135.023
1449.74	136.077
1452.87	134.794
1456.01	133.058
1459.15	130.33
1462.28	124.78
1465.42	119.101
1468.55	111.025
1471.68	104.489
1474.81	96.2464
1477.94	88.5904
1481.07	81.657
1484.2	73.6068
1487.32	67.0839
1490.45	61.9913
1493.57	57.18
1496.69	52.2883
1499.81	48.8121
1502.93	47.8291
1506.05	45.2022
1509.17	42.0197
1512.28	37.4302
1515.4	33.8056
1518.51	30.5464
1521.63	26.7906
1524.74	23.8463
1527.85	23.127
1530.96	22.6866
1534.06	22.3574
1537.17	21.9731
1540.28	22.6819
1543.38	25.1129
1546.48	26.3155
1549.59	28.0625
1552.69	28.3525
1555.79	30.4404
1558.88	30.8589
1561.98	32.6861
1565.08	37.9585
1568.17	43.4487
1571.27	48.9817
1574.36	54.8652
1577.45	61.2819
1580.54	66.9325
1583.63	71.0998
1586.72	76.1587
1589.8	81.4279
1592.89	84.6896
1595.97	86.2031
1599.06	86.2139
1602.14	86.9277
1605.22	86.9486
1608.3	87.8968
1611.38	86.8247
1614.46	86.38
1617.53	88.1484
1620.61	89.3889
1623.68	91.4792
1626.75	92.8253
1629.82	96.1181
1632.9	99.7096
1635.96	102.27
1639.03	108.284
1642.1	114.753
1645.16	120.488
1648.23	124.36
1651.29	127.709
1654.36	131.43
1657.42	132.08
1660.48	132.672
1663.53	130.217
1666.59	123.614
1669.65	117.273
1672.7	109.247
1675.76	102.75
1678.81	93.9695
1681.86	86.275
1684.91	75.6299
1687.96	67.9871
1691.01	58.9426
1694.06	52.5895
1697.11	47.1109
1700.15	41.4045
1703.2	34.7805
1706.24	28.9558
1709.28	25.4137
1712.32	22.9156
1715.36	20.5395
1718.4	19.7192
1721.43	19.063
1724.47	18.0943
1727.5	16.6091
1730.54	16.361
1733.57	14.795
1736.6	12.5931
1739.63	11.3333
1742.66	9.83888
1745.69	9.65229
1748.72	8.32935
1751.74	6.43435
1754.77	4.06971
1757.79	2.71054
1760.81	1.00534
1763.83	0.172847
1766.85	-0.450191
1769.87	0.653629
1772.89	0.115149
1775.91	-0.612204
1778.92	0.176795
1781.94	0.704617
1784.95	1.38824
1787.96	3.02338
1790.97	2.6501
1793.98	3.21008
1796.99	3.62329
1800	3.50843
1803	3.74643
1806.01	4.76814
1809.01	5.45681
1812.02	5.68476
1815.02	5.62752
1818.02	5.08926
1821.02	4.5204
1824.02	3.54608
1827.01	4.09274
1830.01	4.11428
1833	3.62845
1836	3.4509
1838.99	3.70548
1841.98	3.86042
1844.97	4.44304
1847.96	3.87006
1850.95	5.62004
1853.94	4.75926
1856.92	5.18193
1859.91	5.14298
1862.89	3.6595
1865.88	3.29206
1868.86	3.21761
1871.84	2.91211
1874.82	3.93317
1877.8	5.03263
1880.77	4.24409
1882.51	4.47132
1885.5	4.06347
1888.48	4.78107
1891.47	4.25486
1894.46	4.15008
1897.44	4.28168
1900.42	4.62233
1903.41	3.65853
1906.39	3.71868
1909.37	3.9825
1912.35	4.10962
1915.32	4.12889
1918.3	4.43555
1921.28	5.7944
1924.25	5.39667
1927.22	4.81823
1930.2	4.57308
1933.17	3.32098
1936.14	3.44022
1939.11	3.87532
1942.08	4.1735
1945.04	3.65459
1948.01	2.08434
1950.97	1.01165
1953.94	1.71318
1956.9	1.89736
1959.86	1.66665
1962.82	2.52942
1965.78	1.83136
1968.74	2.58517
1971.69	2.62494
1974.65	3.71357
1977.61	3.82571
1980.56	4.02906
1983.51	4.01236
1986.46	5.35922
1989.41	6.05069
1992.36	6.55664
1995.31	7.75463
1998.26	6.9334
2001.2	6.86233
2004.15	6.66368
2007.09	7.51601
2010.04	8.29925
2012.98	8.76142
2015.92	8.32339
2018.86	8.76997
2021.8	9.05939
2024.74	10.3032
2027.67	11.195
2030.61	11.1488
2033.54	11.7648
2036.47	12.6927
2039.41	13.962
2042.34	16.0599
2045.27	19.5136
2048.2	21.3842
2051.12	22.3871
2054.05	24.0438
2056.98	25.8964
2059.9	28.866
2062.82	30.9786
2065.75	33.5973
2068.67	35.49
2071.59	37.4866
2074.51	41.1592
2077.43	45.1455
2080.34	49.5589
2083.26	53.2328
2086.17	55.8614
2089.09	60.6872
2092	63.3725
2094.91	65.5933
2097.82	69.0555
2100.73	74.3977
2103.64	79.2815
2106.55	84.4377
2109.46	92.8156
2112.36	99.9873
2115.27	107.291
2118.17	113.75
2121.07	120.085
2123.97	126.232
2126.87	134.762
2129.77	144.289
2132.67	152.616
2135.57	160.879
2138.46	169.885
2141.36	176.831
2144.25	185.978
2147.14	195.189
2150.03	202.581
2152.92	207.58
2155.81	212.403
2158.7	217.286
2161.59	220.126
2164.48	222.154
2167.36	223.672
2170.25	225.697
2173.13	224.438
2176.01	223.472
2178.89	219.793
2181.77	216.137
2184.65	210.632
2187.53	204.735
2190.41	198.382
2193.28	191.369
2196.16	184.855
2199.03	177.311
2201.9	168.923
2204.78	162.676
2207.65	154.496
2210.51	146.453
2213.38	139.221
2216.25	131.721
2219.12	123.607
2221.98	116.598
2224.85	108.396
2227.71	102.251
2230.57	95.7499
2233.43	88.7188
2236.29	82.9529
2239.15	76.3011
2242.01	70.7996
2244.87	64.8836
2247.73	58.8105
2250.58	54.3615
2253.43	50.8063
2256.29	46.7027
2259.14	43.9106
2261.99	40.9835
2264.84	37.1531
2267.69	34.5508
2270.54	31.5624
2273.38	30.9618
2276.23	29.5333
2279.07	26.8374
2281.92	25.4223
2284.76	23.4924
2287.6	21.9433
2290.44	20.1834
2293.28	17.6519
2296.12	16.5188
2298.96	14.882
2301.79	14.4869
2304.63	13.8953
2307.46	13.0197
2310.3	12.9557
2313.13	12.4513
2315.96	11.3854
2318.79	11.9426
2321.62	11.5697
2324.45	10.2847
2327.27	9.54278
2330.1	8.89066
2332.93	8.86938
2335.75	7.54775
2338.57	6.41539
2341.4	6.07912
2344.22	4.96845
2347.04	4.35517
2349.86	3.60829
2352.67	2.26266
2355.49	0.979682
2358.31	-0.572697
2361.12	-0.953443
2363.94	-0.882034
2366.75	0.590863
2369.56	1.16734
2372.37	1.69275
2375.18	1.4952
2377.99	1.28057
2380.8	0.715641
2383.61	1.66432
2386.41	2.7196
2389.22	2.4214
2392.02	1.8335
2394.82	1.81621
2397.63	2.25389
2400.43	1.87904
2403.23	1.63541
2406.02	0.558921
2408.82	1.35862
2411.62	1.93862
2414.41	1.96446
2417.21	2.29699
2420	2.35499
2422.79	2.84207
2425.59	3.52408
2428.38	5.25728
2431.17	5.34047
2433.96	6.05132
2436.74	6.26976
2439.53	5.71896
2442.32	4.96615
2445.1	5.48884
2447.88	6.18278
2450.67	6.74124
2453.45	8.26219
2456.23	6.71095
2459.01	6.79599
2461.79	7.03365
2464.57	6.23958
2467.34	6.19528
2470.12	4.897
2472.89	4.32266
2475.67	3.63749
2478.44	2.89863
2481.21	3.14639
2483.98	3.14292
2486.75	2.43554
2489.52	3.07259
2492.29	3.37033
2495.06	3.51867
2497.82	3.01854
2500.59	2.29173
2503.35	1.94722
2506.11	2.25701
2508.88	1.93484
2511.63	1.61762
2514.39	2.18675
2517.15	2.36844
2519.91	3.13017
2522.67	3.30635
2525.42	2.68954
2528.18	3.62508
2530.93	3.86357
2533.69	4.41665
2536.44	5.13009
2539.19	5.16205
2541.94	6.17874
2544.69	5.69541
2547.44	7.10994
2550.18	7.61297
2552.93	7.60963
2555.68	7.98883
2558.42	8.8308
2561.16	9.32363
2563.9	9.24071
2566.64	9.06299
2569.38	8.80521
2572.12	8.78275
2574.86	8.34219
2577.6	9.06207
2580.34	9.1935
2583.07	8.98717
2585.81	9.28169
2588.54	9.1181
2591.27	8.27732
2594	8.91194
2596.73	10.8068
2599.46	11.0381
2602.19	11.4396
2604.92	10.8278
2607.64	11.1838
2610.37	11.369
2613.09	12.3003
2615.82	12.8376
2618.54	12.027
2621.26	11.7124
2623.98	11.3321
2626.7	11.3495
2629.42	11.5102
2632.14	11.4963
2634.86	12.0503
2637.57	12.3414
2640.29	13.1238
2643	13.1447
2645.72	13.552
2648.43	12.6863
2651.14	12.4836
2653.85	12.7157
2656.56	12.7528
2659.27	13.048
2661.97	13.3178
2664.68	13.2977
2667.38	12.6258
2670.09	12.7238
2672.79	12.5228
2675.49	13.2554
2678.2	13.4792
2680.89	12.8194
2683.59	11.5128
2686.29	11.6767
2688.99	10.3243
2691.69	10.7359
2694.38	11.7674
2697.08	12.3856
2699.77	13.2843
2702.46	14.4843
2705.16	14.9501
2707.85	16.3656
2710.54	17.5939
2713.23	17.7439
2715.92	18.7194
2718.6	19.9058
2721.29	20.7962
2723.97	21.9259
2726.66	22.3692
2729.34	22.2451
2732.02	22.0907
2734.7	22.2441
2737.39	21.1045
2740.06	20.1062
2742.74	19.2723
2745.42	17.8318
2748.1	16.2781
2750.77	15.0137
2753.45	13.4309
2756.12	11.5735
2758.79	10.4112
2761.47	8.71962
2764.14	7.00819
2766.81	6.27372
2769.48	4.91091
2772.14	4.5654
2774.81	3.54207
2777.48	1.71742
2780.14	0.244246
2782.81	-0.106766
2785.47	0.0173803
2788.13	0.573753
2790.79	0.908379
2793.46	0.250158
2796.11	1.22127
2798.77	2.18445
2801.43	1.99935
2804.09	2.1497
2806.74	2.16343
2809.4	2.73583
2812.05	1.85094
2814.71	3.14355
2817.36	5.88274
2820.01	10.772
2822.66	18.6517
2825.31	26.8757
2827.96	37.7499
2830.61	49.1706
2833.25	61.5081
2835.9	74.4828
2838.54	86.75
2841.18	101.579
2843.83	115.942
2846.47	132.286
2849.11	148.712
2851.75	164.494
2854.39	180.034
2857.03	194.144
2859.67	208.658
2862.3	221.907
2864.94	231.381
2867.57	239.649
2870.21	247.33
2872.84	253.46
2875.47	259.284
2878.1	265.299
2880.73	273.364
2883.36	280.125
2885.99	287.787
2888.61	294.359
2891.24	302.221
2893.87	310.32
2896.49	319.094
2899.11	327.844
2901.74	339.015
2904.36	351.911
2906.98	365.51
2909.6	381.156
2912.22	397.384
2914.83	413.33
2917.45	428.293
2920.07	441.807
2922.68	453.744
2925.3	462.245
2927.91	467.127
2930.52	469.283
2933.13	468.178
2935.74	463.322
2938.35	456.506
2940.96	446.238
2943.57	433.702
2946.18	418.46
2948.78	400.195
2951.39	381.161
2953.99	361.614
2956.6	341.202
2959.2	319.944
2961.8	299.785
2964.4	281.305
2967	262.912
2969.6	245.203
2972.2	229.099
2974.79	212.67
2977.39	196.409
2979.98	180.568
2982.58	164.765
2985.17	149.739
2987.76	134.187
2990.36	118.389
2992.95	103.152
2995.54	89.0715
2998.12	76.7118
3000.71	64.797
3003.3	54.3459
3005.88	44.061
3008.47	35.2146
3011.05	27.4939
3013.64	20.8227
3016.22	14.6436
3018.8	10.6262
3021.38	6.62219
3023.96	4.75974
3026.54	3.86655
3029.12	3.13116
3031.69	2.7691
3034.27	3.5532
3036.85	3.42656
3039.42	4.10157
3041.99	6.19881
3044.57	6.77884
3047.14	7.77294
3049.71	8.28126
3052.28	8.54118
3054.85	8.92314
3057.42	8.93088
3059.98	9.20922
3062.55	9.32754
3065.11	7.87797
3067.68	6.93531
3070.24	5.90012
3072.8	5.82318
3075.37	4.32356
3077.93	3.25904
3080.49	2.20211
3083.05	1.47917
3085.61	0.362822
3088.16	0.0359984
3090.72	-0.803029
3093.27	-0.52631
3095.83	-0.734649
3098.38	-0.91324
3100.94	-0.939059
3103.49	-0.456717
3106.04	0.498591
3108.59	1.33533
3111.14	3.11513
3113.69	4.20287
3116.23	6.69361
3118.78	7.70674
3121.33	9.75005
3123.87	11.8579
3126.42	13.1917
3128.96	15.1573
3131.5	17.7985
3134.04	20.3389
3136.58	21.4843
3139.12	23.0939
3141.66	24.1015
3144.2	24.28
3146.74	24.1495
3149.27	23.1672