File: data/Raman/poly_smoothed/Mb_50_18_45_1x_45s_532 nm_x100_100%_600 gr_mm_01.txt
#Acq. time (s)=	45
#Accumulations=	2
#Range (cm-¹)=	200...3150
#Windows=	2
#Auto scanning=	Off
#Autofocus=	Off
#Macrospot=	Off
#AutoExposure=	Off
#Spike filter=	Multiple accum.
#Delay time (s)=	0
#Binning=	1
#Readout mode=	Signal
#DeNoise=	Off
#ICS correction=	On
#Dark correction=	Off
#Inst. Process=	Off
#Detector Gain=	Best Dynamic Range
#Detector ADC=	20 kHz
#Detector temperature (°C)=	-69.85
#Instrument=	LabRAM HR Evol
#Detector=	Synapse
#Objective=	x100
#Grating=	600 gr/mm
#ND Filter=	100%
#Laser (nm)=	532
#Hole=	100.021
#Range=	Auto
#Laser Pol.=	No
#Raman. Pol.=	No
#Laser Pol. (°)=	-0.0007625
#Raman Pol. (°)=	89.9995
#Collection=	Microscope
#StageXY=	Marzhauser
#StageZ=	Marzhauser
#X (µm)=	28454.7
#Y (µm)=	-2984.1
#Z (µm)=	1043.05
#Full time(mm:ss)=	3:19
#Project=
#Sample=
#Site=
#Title=	Mb_50_18_45_2x_45s_532 nm_x100_100%_600 gr_mm
#Remark=
#Date=	12.07.2022 14:33
#Acquired=	12.07.2022 14:33:02
#Base:Fit=	10.08.2022 10:49:18
#Base:Sub=	10.08.2022 10:49:30
#Filter:Polynom=	16.08.2022 10:14:59
#AxisType[0]=Intens
#AxisUnit[0]=Cnt
#AxisType[1]=Spectr
#AxisUnit[1]=1/cm
200.388	19.4593
204.019	24.4018
207.646	26.5065
211.274	24.313
214.899	20.9642
218.524	19.0248
222.146	17.106
225.766	15.0184
229.388	14.3031
233.005	14.7842
236.621	14.922
240.236	15.5006
243.852	15.8004
247.464	15.8252
251.074	14.6213
254.683	15.6539
258.291	15.4458
261.897	16.1594
265.504	16.9576
269.108	16.8354
272.71	18.3504
276.311	19.5723
279.91	19.1443
283.508	18.4503
287.105	19.9148
290.698	18.7987
294.291	17.7441
297.884	16.7529
301.475	17.0581
305.064	17.4583
308.652	17.3709
312.237	17.1212
315.822	17.4892
319.406	18.2534
322.987	17.9297
326.568	17.7889
330.148	17.5029
333.724	17.1848
337.301	15.8839
340.875	16.5803
344.449	16.8515
348.02	17.0119
351.592	18.2485
355.16	19.1658
358.728	22.2068
362.294	24.8781
365.858	27.0666
369.422	30.5267
372.983	33.9051
376.543	34.1721
380.102	35.4885
383.661	36.8413
387.216	38.1983
390.771	37.8362
394.324	35.144
397.875	32.6564
401.425	31.0543
404.974	28.0332
408.524	24.9945
412.07	20.3256
415.614	17.4138
419.156	13.4358
422.698	9.8047
426.238	8.73927
429.777	7.6694
433.315	5.96389
436.852	4.00323
440.387	4.6102
443.919	4.24417
447.451	5.92208
450.982	4.7883
454.512	6.37286
458.038	6.41226
461.565	6.5227
465.091	7.49154
468.613	7.90341
472.136	9.83096
475.655	10.7262
479.176	10.9887
482.692	12.495
486.21	14.2519
489.724	17.3825
493.237	20.6702
496.75	25.172
500.26	27.1974
503.771	29.8421
507.279	33.8803
510.785	35.6225
514.289	36.7076
517.793	37.7814
521.297	37.3961
524.797	35.6913
528.297	36.2955
531.795	34.6923
535.291	31.5248
538.787	28.5434
542.281	25.503
545.773	22.3217
549.264	17.8224
552.754	13.5764
556.243	9.39115
559.73	8.31906
563.216	5.65636
566.701	3.28978
570.182	3.21356
573.664	3.47178
577.145	4.17922
580.624	4.82896
584.1	4.76255
587.577	5.9769
591.052	8.22184
594.524	9.36226
597.997	10.7514
601.466	10.8813
604.936	12.0886
608.403	12.0977
611.87	11.24
615.334	10.3847
618.799	9.59548
622.26	8.59221
625.72	7.42352
629.181	6.40088
632.638	4.78332
636.095	4.28785
639.551	4.69633
643.005	5.69307
646.457	4.98714
649.908	4.88538
653.357	4.62595
656.806	5.81715
660.253	7.43518
663.7	8.59601
667.145	10.9805
670.588	13.8342
674.027	15.5589
677.468	18.1369
680.907	19.0949
684.345	20.4125
687.781	23.1878
691.216	24.7109
694.65	27.2236
698.081	29.3773
701.512	30.7971
704.942	31.8456
708.371	34.6768
711.796	36.2997
715.222	37.6956
718.645	39.33
722.068	41.3498
725.49	40.9908
728.909	40.4599
732.329	40.8478
735.745	42.9796
739.16	46.7739
742.576	52.5461
745.988	58.7686
749.401	63.6315
752.811	68.4822
756.22	72.5727
759.627	76.1151
763.035	80.4764
766.44	82.9054
769.843	87.1981
773.245	88.6221
776.646	90.4924
780.046	91.3416
783.444	90.6121
786.841	92.4998
790.237	91.1313
793.631	88.0997
797.024	83.4296
800.416	80.246
803.807	77.4372
807.196	72.5962
810.584	69.0981
813.971	67.8187
817.354	67.3388
820.739	68.2008
824.122	67.4917
827.503	68.4178
830.882	67.2767
834.261	66.6583
837.637	66.9502
841.013	64.2676
844.389	63.6232
847.761	61.7457
851.131	57.3777
854.503	55.0974
857.871	51.2856
861.24	49.086
864.606	47.8446
867.97	48.1691
871.336	45.5651
874.698	42.8747
878.058	39.8147
881.418	38.6371
884.778	39.7638
888.135	38.0046
891.49	37.5246
894.845	39.7111
898.198	39.5759
901.55	40.5583
904.901	42.1934
908.25	42.9802
911.598	44.1901
914.945	44.3687
918.291	43.4941
921.635	41.7036
924.978	39.7229
928.318	37.2751
931.659	34.1642
934.998	31.2335
938.336	28.8846
941.671	27.6758
945.007	25.7848
948.339	22.5796
951.672	21.3929
955.004	17.814
958.333	16.0387
961.662	13.0404
964.989	12.2664
968.315	12.1218
971.639	11.6322
974.962	10.6043
978.285	10.3278
981.605	9.86034
984.924	8.65834
988.243	7.36248
991.56	5.8956
994.875	6.45623
998.188	8.01654
1001.5	9.29431
1004.81	11.8402
1008.12	15.2349
1011.43	19.0839
1014.74	22.1592
1018.05	25.4233
1021.35	29.0345
1024.65	31.4222
1027.96	32.468
1031.26	33.8543
1034.56	35.4691
1037.86	35.386
1041.16	34.9444
1044.45	35.0045
1047.75	35.2268
1051.04	32.2869
1054.33	29.9866
1057.62	28.0129
1060.91	26.6233
1064.2	25.8414
1067.49	24.3641
1070.77	23.1504
1074.06	22.3988
1077.34	23.1998
1080.62	22.5983
1083.91	21.517
1087.18	22.7091
1090.46	24.4652
1093.74	25.16
1097.02	25.8707
1100.29	25.2637
1103.56	25.8951
1106.84	24.2851
1110.11	23.5138
1113.38	23.4494
1116.64	22.266
1119.91	20.5725
1123.18	21.2327
1126.44	19.5895
1129.7	18.3622
1132.97	17.316
1136.23	18.2048
1139.49	19.549
1142.74	18.9555
1146	16.5642
1149.26	14.327
1152.51	11.2666
1155.76	8.48076
1159.01	6.50159
1162.27	5.60078
1165.51	4.5806
1168.76	7.02446
1172.01	8.1366
1175.25	6.20358
1178.5	5.97538
1181.74	5.69077
1184.98	4.07792
1188.22	5.12643
1191.46	4.85481
1194.7	5.08671
1197.94	6.43205
1201.17	6.58915
1204.41	7.51399
1207.64	9.10785
1210.87	10.4486
1214.1	12.0099
1217.33	13.7443
1220.56	15.3506
1223.79	15.9
1227.01	17.1457
1230.23	18.4763
1233.46	19.6222
1236.68	20.8259
1239.9	21.5525
1243.12	24.0189
1246.34	26.5419
1249.55	27.4523
1252.77	27.564
1255.98	27.588
1259.2	28.3497
1262.41	28.495
1265.62	30.1556
1268.83	31.9363
1272.03	32.9894
1275.24	34.3459
1278.45	36.031
1281.65	36.7815
1284.85	38.3145
1288.06	40.5203
1291.26	42.7685
1294.46	43.8318
1297.66	46.2022
1300.85	46.466
1304.05	47.6539
1307.24	46.819
1310.43	45.8878
1313.63	47.4425
1316.82	45.7797
1320.01	46.9008
1323.2	47.732
1326.38	46.0947
1329.57	43.6142
1332.76	43.8239
1335.94	43.9873
1339.12	42.0661
1342.3	41.2858
1345.48	40.4952
1348.66	39.9205
1351.84	38.9676
1355.01	39.2703
1358.19	37.7218
1361.36	35.7725
1364.53	35.6835
1367.71	34.3883
1370.88	32.0349
1374.04	31.7619
1377.21	30.103
1380.38	26.3574
1383.54	25.51
1386.71	24.0361
1389.87	24.4197
1393.03	25.0544
1396.19	24.3829
1399.35	24.4991
1402.51	24.0253
1405.67	25.5911
1408.82	29.5372
1411.98	34.2075
1415.13	38.5571
1418.28	42.8447
1421.43	48.0328
1424.58	53.5012
1427.73	58.3714
1430.88	62.2251
1434.02	65.3591
1437.17	66.2766
1440.31	69.1566
1443.45	70.0969
1446.6	69.5733
1449.74	72.0459
1452.87	72.2585
1456.01	72.5602
1459.15	72.4049
1462.28	74.5247
1465.42	72.7676
1468.55	73.0809
1471.68	72.8491
1474.81	71.3805
1477.94	70.0753
1481.07	68.0729
1484.2	67.2211
1487.32	66.186
1490.45	64.1482
1493.57	61.4904
1496.69	58.3491
1499.81	54.7348
1502.93	49.5801
1506.05	43.1349
1509.17	37.9913
1512.28	30.6997
1515.4	26.5556
1518.51	23.0954
1521.63	20.5783
1524.74	18.1475
1527.85	17.3696
1530.96	15.5083
1534.06	17.1363
1537.17	19.0696
1540.28	20.3758
1543.38	22.01
1546.48	23.6227
1549.59	25.1429
1552.69	25.9206
1555.79	25.6983
1558.88	27.1966
1561.98	28.81
1565.08	30.2614
1568.17	32.0734
1571.27	33.3272
1574.36	35.4825
1577.45	36.7598
1580.54	38.6872
1583.63	40.2285
1586.72	41.4791
1589.8	43.0449
1592.89	46.2867
1595.97	48.2792
1599.06	50.0219
1602.14	48.8629
1605.22	50.027
1608.3	50.9954
1611.38	51.7359
1614.46	47.3389
1617.53	46.3774
1620.61	48.3199
1623.68	50.0984
1626.75	51.9899
1629.82	52.7494
1632.9	53.7445
1635.96	55.8031
1639.03	58.2433
1642.1	59.4805
1645.16	60.9343
1648.23	62.0345
1651.29	62.2991
1654.36	62.6094
1657.42	61.6377
1660.48	59.6213
1663.53	57.3187
1666.59	55.2953
1669.65	52.5521
1672.7	48.3675
1675.76	42.7527
1678.81	37.919
1681.86	32.2259
1684.91	26.7472
1687.96	21.0937
1691.01	17.05
1694.06	19.1815
1697.11	17.322
1700.15	16.2692
1703.2	14.8554
1706.24	12.9133
1709.28	13.0088
1712.32	13.4734
1715.36	13.7222
1718.4	14.1605
1721.43	14.2316
1724.47	15.0485
1727.5	15.7855
1730.54	15.4868
1733.57	14.9494
1736.6	15.649
1739.63	15.4125
1742.66	14.9229
1745.69	14.0812
1748.72	13.7096
1751.74	13.3896
1754.77	12.8336
1757.79	12.2623
1760.81	12.2253
1763.83	11.7765
1766.85	9.57063
1769.87	7.58974
1772.89	7.11556
1775.91	5.55646
1778.92	4.54229
1781.94	3.84419
1784.95	3.26282
1787.96	4.21124
1790.97	3.82756
1793.98	2.85271
1796.99	3.2336
1800	3.50673
1803	3.62741
1806.01	4.42286
1809.01	4.52522
1812.02	4.84092
1815.02	4.99938
1818.02	4.67459
1821.02	5.37384
1824.02	6.95215
1827.01	7.96953
1830.01	8.91526
1833	9.0052
1836	9.26098
1838.99	8.54851
1841.98	8.61153
1844.97	8.20089
1847.96	8.24732
1850.95	8.1729
1853.94	8.94349
1856.92	7.49788
1859.91	7.52278
1862.89	7.04142
1865.88	5.94332
1868.86	6.90974
1871.84	6.62293
1874.82	6.89107
1877.8	6.59197
1880.77	6.14947
1882.51	5.31981
1885.5	5.33531
1888.48	5.28967
1891.47	5.74045
1894.46	5.68843
1897.44	6.44488
1900.42	7.05866
1903.41	6.90969
1906.39	6.27803
1909.37	5.60153
1912.35	6.57345
1915.32	6.95612
1918.3	7.19766
1921.28	7.97194
1924.25	7.46991
1927.22	6.99946
1930.2	6.90641
1933.17	6.93991
1936.14	6.29649
1939.11	6.72669
1942.08	7.59236
1945.04	7.02088
1948.01	7.32408
1950.97	6.53914
1953.94	6.03561
1956.9	5.06829
1959.86	5.23124
1962.82	4.64635
1965.78	4.07662
1968.74	4.69043
1971.69	4.20769
1974.65	4.33642
1977.61	3.26381
1980.56	4.4881
1983.51	5.10176
1986.46	5.27346
1989.41	4.70912
1992.36	5.48786
1995.31	4.92205
1998.26	5.88221
2001.2	5.85975
2004.15	5.2043
2007.09	5.48134
2010.04	5.5945
2012.98	6.98281
2015.92	6.42857
2018.86	5.79512
2021.8	7.01204
2024.74	5.67375
2027.67	6.39714
2030.61	7.10538
2033.54	7.96452
2036.47	8.02264
2039.41	9.35963
2042.34	10.6023
2045.27	12.4917
2048.2	13.8313
2051.12	14.7865
2054.05	15.522
2056.98	15.4971
2059.9	16.0419
2062.82	17.0506
2065.75	18.5645
2068.67	18.7872
2071.59	19.0648
2074.51	19.0747
2077.43	19.7075
2080.34	20.5042
2083.26	20.8832
2086.17	21.5617
2089.09	22.0442
2092	23.7602
2094.91	24.1399
2097.82	25.6501
2100.73	27.2613
2103.64	28.4559
2106.55	29.3769
2109.46	31.4633
2112.36	33.3921
2115.27	36.7628
2118.17	38.6958
2121.07	40.2665
2123.97	42.2771
2126.87	45.0039
2129.77	46.8624
2132.67	48.6442
2135.57	51.1952
2138.46	53.7691
2141.36	54.4298
2144.25	55.9604
2147.14	57.1791
2150.03	58.0365
2152.92	59.402
2155.81	60.7361
2158.7	62.3428
2161.59	62.7944
2164.48	63.9798
2167.36	63.6247
2170.25	63.7368
2173.13	64.0528
2176.01	63.0824
2178.89	62.9634
2181.77	61.491
2184.65	61.7291
2187.53	61.4246
2190.41	60.1467
2193.28	58.7558
2196.16	58.1426
2199.03	56.2112
2201.9	54.8584
2204.78	53.5223
2207.65	51.9291
2210.51	49.6633
2213.38	47.0356
2216.25	44.212
2219.12	42.562
2221.98	40.8162
2224.85	39.3687
2227.71	37.2692
2230.57	34.2495
2233.43	31.6555
2236.29	28.7587
2239.15	26.7847
2242.01	24.4943
2244.87	21.8178
2247.73	18.9483
2250.58	17.646
2253.43	16.4017
2256.29	16.2383
2259.14	15.4989
2261.99	13.5687
2264.84	12.6773
2267.69	11.9195
2270.54	10.6731
2273.38	9.23641
2276.23	7.93848
2279.07	6.85716
2281.92	4.89924
2284.76	4.56108
2287.6	4.2204
2290.44	3.01643
2293.28	2.64678
2296.12	3.16085
2298.96	2.63764
2301.79	2.28941
2304.63	2.67382
2307.46	3.35408
2310.3	2.31557
2313.13	2.5196
2315.96	2.53308
2318.79	2.8739
2321.62	4.65838
2324.45	4.94331
2327.27	4.41002
2330.1	5.03993
2332.93	4.29988
2335.75	4.91117
2338.57	3.53817
2341.4	2.84797
2344.22	2.04444
2347.04	2.50325
2349.86	1.8839
2352.67	0.533577
2355.49	0.288208
2358.31	0.74838
2361.12	0.762138
2363.94	2.7401
2366.75	4.62873
2369.56	3.50466
2372.37	4.13231
2375.18	4.88049
2377.99	4.55796
2380.8	4.92286
2383.61	4.91355
2386.41	4.85794
2389.22	5.41722
2392.02	5.48812
2394.82	4.96856
2397.63	4.9256
2400.43	4.05746
2403.23	4.00136
2406.02	3.11512
2408.82	2.66449
2411.62	2.49461
2414.41	1.00169
2417.21	1.39848
2420	0.69579
2422.79	0.818173
2425.59	1.21699
2428.38	1.40768
2431.17	1.55986
2433.96	2.24389
2436.74	2.49575
2439.53	2.90818
2442.32	3.44426
2445.1	3.80542
2447.88	1.98776
2450.67	2.50241
2453.45	3.57182
2456.23	3.48273
2459.01	4.03466
2461.79	3.47612
2464.57	2.47741
2467.34	4.29958
2470.12	3.66767
2472.89	3.76655
2475.67	3.51748
2478.44	2.98311
2481.21	2.42875
2483.98	2.44761
2486.75	2.71667
2489.52	2.32993
2492.29	2.12585
2495.06	2.06612
2497.82	2.26235
2500.59	2.52778
2503.35	2.22927
2506.11	3.0054
2508.88	2.58384
2511.63	3.19453
2514.39	2.77326
2517.15	2.83156
2519.91	3.85597
2522.67	2.70084
2525.42	2.83976
2528.18	3.74414
2530.93	4.2307
2533.69	6.05497
2536.44	6.59617
2539.19	6.67238
2541.94	7.78235
2544.69	8.35982
2547.44	8.85031
2550.18	9.20014
2552.93	8.97103
2555.68	8.60829
2558.42	7.74751
2561.16	8.23256
2563.9	8.77537
2566.64	9.0447
2569.38	8.29905
2572.12	8.30326
2574.86	7.41624
2577.6	6.16832
2580.34	5.8714
2583.07	4.82568
2585.81	4.69523
2588.54	4.29583
2591.27	2.69836
2594	3.15766
2596.73	2.82795
2599.46	1.95769
2602.19	1.25633
2604.92	1.84507
2607.64	2.32096
2610.37	2.01591
2613.09	1.85686
2615.82	1.73242
2618.54	1.89451
2621.26	1.04466
2623.98	1.38258
2626.7	2.19857
2629.42	3.05827
2632.14	3.27397
2634.86	3.92204
2637.57	4.23316
2640.29	4.17065
2643	4.94969
2645.72	6.07483
2648.43	7.08403
2651.14	6.71602
2653.85	6.03866
2656.56	5.33571
2659.27	5.15002
2661.97	5.63245
2664.68	5.32113
2667.38	6.22329
2670.09	6.40673
2672.79	6.01659
2675.49	5.63836
2678.2	6.08125
2680.89	5.85667
2683.59	6.9704
2686.29	7.01249
2688.99	7.39376
2691.69	7.7121
2694.38	7.73527
2697.08	8.23563
2699.77	8.42129
2702.46	9.38925
2705.16	10.6997
2707.85	10.8835
2710.54	11.9606
2713.23	11.974
2715.92	12.1924
2718.6	12.7496
2721.29	12.7581
2723.97	13.0969
2726.66	12.9262
2729.34	12.6193
2732.02	12.6215
2734.7	12.2268
2737.39	11.0502
2740.06	10.4464
2742.74	9.50351
2745.42	9.11472
2748.1	8.09812
2750.77	7.29758
2753.45	5.38746
2756.12	4.16536
2758.79	3.74484
2761.47	2.66973
2764.14	1.4315
2766.81	1.39664
2769.48	1.14178
2772.14	1.94197
2774.81	1.86353
2777.48	0.579378
2780.14	0.467217
2782.81	0.521537
2785.47	-0.123652
2788.13	-0.309363
2790.79	0.0472074
2793.46	0.941415
2796.11	1.2618
2798.77	1.82611
2801.43	1.52679
2804.09	0.684246
2806.74	0.0386319
2809.4	-0.438985
2812.05	-0.574836
2814.71	-0.577327
2817.36	0.515978
2820.01	2.67753
2822.66	6.07536
2825.31	9.48537
2827.96	13.5551
2830.61	20.1298
2833.25	26.2278
2835.9	32.443
2838.54	39.1693
2841.18	44.7414
2843.83	51.5465
2846.47	58.8037
2849.11	65.8834
2851.75	73.7453
2854.39	80.5585
2857.03	87.2853
2859.67	92.9326
2862.3	97.8849
2864.94	102.893
2867.57	105.557
2870.21	108.846
2872.84	110.944
2875.47	112.604
2878.1	115.979
2880.73	118.272
2883.36	121.014
2885.99	123.163
2888.61	125.9
2891.24	128.477
2893.87	133.397
2896.49	138.047
2899.11	142.048
2901.74	146.282
2904.36	151.616
2906.98	157.337
2909.6	163.31
2912.22	168.681
2914.83	176.056
2917.45	181.73
2920.07	186.369
2922.68	190.166
2925.3	192.664
2927.91	194.748
2930.52	195.338
2933.13	194.403
2935.74	191.443
2938.35	189.553
2940.96	185.969
2943.57	181.16
2946.18	174.915
2948.78	168.32
2951.39	162.01
2953.99	155.417
2956.6	148.725
2959.2	141.291
2961.8	134.273
2964.4	126.396
2967	119.957
2969.6	113.212
2972.2	106.332
2974.79	99.5253
2977.39	92.9539
2979.98	85.7082
2982.58	78.5478
2985.17	71.0239
2987.76	65.3689
2990.36	59.2735
2992.95	53.6449
2995.54	46.6673
2998.12	41.0633
3000.71	35.8561
3003.3	30.8301
3005.88	26.6412
3008.47	22.7903
3011.05	18.9537
3013.64	15.581
3016.22	12.8534
3018.8	10.012
3021.38	7.84972
3023.96	6.34804
3026.54	5.15088
3029.12	4.06434
3031.69	3.33456
3034.27	1.63861
3036.85	2.34413
3039.42	2.77864
3041.99	3.06583
3044.57	3.92578
3047.14	3.82388
3049.71	4.61468
3052.28	5.59992
3054.85	5.43937
3057.42	4.79854
3059.98	4.66658
3062.55	4.62759
3065.11	4.08773
3067.68	4.07071
3070.24	2.84362
3072.8	2.40663
3075.37	1.4243
3077.93	0.14594
3080.49	0.174067
3083.05	0.169272
3085.61	-0.121269
3088.16	-0.415014
3090.72	-0.431063
3093.27	-0.0643933
3095.83	0.343125
3098.38	1.04854
3100.94	2.24063
3103.49	2.33344
3106.04	3.44188
3108.59	5.09649
3111.14	6.27633
3113.69	8.34099
3116.23	10.0307
3118.78	11.8249
3121.33	13.2577
3123.87	15.4828
3126.42	16.9737
3128.96	18.8475
3131.5	20.0461
3134.04	22.2672
3136.58	24.0486
3139.12	25.8478
3141.66	27.8207
3144.2	29.363
3146.74	30.0493
3149.27	30.9376