File: data/Raman/poly_smoothed/Mb_50_18_29_1x_45s_532 nm_x100_100%_600 gr_mm_01.txt
#Acq. time (s)=	45
#Accumulations=	2
#Range (cm-¹)=	200...3150
#Windows=	2
#Auto scanning=	Off
#Autofocus=	Off
#Macrospot=	Off
#AutoExposure=	Off
#Spike filter=	Multiple accum.
#Delay time (s)=	0
#Binning=	1
#Readout mode=	Signal
#DeNoise=	Off
#ICS correction=	On
#Dark correction=	Off
#Inst. Process=	Off
#Detector Gain=	Best Dynamic Range
#Detector ADC=	20 kHz
#Detector temperature (°C)=	-69.85
#Instrument=	LabRAM HR Evol
#Detector=	Synapse
#Objective=	x100
#Grating=	600 gr/mm
#ND Filter=	100%
#Laser (nm)=	532
#Hole=	100.021
#Range=	Auto
#Laser Pol.=	No
#Raman. Pol.=	No
#Laser Pol. (°)=	-0.0007625
#Raman Pol. (°)=	89.9995
#Collection=	Microscope
#StageXY=	Marzhauser
#StageZ=	Marzhauser
#X (µm)=	28296.4
#Y (µm)=	-3279
#Z (µm)=	1041.35
#Full time(mm:ss)=	3:18
#Project=
#Sample=
#Site=
#Title=	Mb_50_18_29_2x_45s_532 nm_x100_100%_600 gr_mm
#Remark=
#Date=	12.07.2022 12:59
#Acquired=	12.07.2022 12:59:19
#Base:Fit=	10.08.2022 10:49:18
#Base:Sub=	10.08.2022 10:49:30
#Filter:Polynom=	16.08.2022 10:14:59
#AxisType[0]=Intens
#AxisUnit[0]=Cnt
#AxisType[1]=Spectr
#AxisUnit[1]=1/cm
200.388	-2.34782
204.019	0.145866
207.646	2.51642
211.274	3.74206
214.899	3.97517
218.524	3.02861
222.146	4.30191
225.766	4.39969
229.388	5.74456
233.005	8.24958
236.621	6.63345
240.236	7.75621
243.852	7.59171
247.464	5.93202
251.074	6.48766
254.683	5.73402
258.291	4.91009
261.897	5.173
265.504	7.02952
269.108	5.298
272.71	3.76146
276.311	4.13954
279.91	4.81435
283.508	5.65488
287.105	7.9171
290.698	10.8653
294.291	11.2068
297.884	12.1539
301.475	16.4456
305.064	19.9412
308.652	24.3652
312.237	28.7929
315.822	32.1808
319.406	35.9791
322.987	36.4115
326.568	37.6533
330.148	37.9242
333.724	37.9519
337.301	36.1983
340.875	33.8022
344.449	33.0908
348.02	32.1326
351.592	32.4395
355.16	34.2813
358.728	39.9163
362.294	47.39
365.858	54.941
369.422	62.1257
372.983	66.3425
376.543	71.4739
380.102	75.2687
383.661	79.3048
387.216	82.791
390.771	83.8768
394.324	85.1075
397.875	83.5797
401.425	79.952
404.974	75.279
408.524	69.4326
412.07	59.5153
415.614	50.3091
419.156	39.9565
422.698	29.0443
426.238	18.8705
429.777	11.7078
433.315	7.61727
436.852	4.5349
440.387	4.14757
443.919	7.10833
447.451	10.7312
450.982	11.7927
454.512	10.9143
458.038	10.6664
461.565	11.7098
465.091	12.4479
468.613	12.6449
472.136	12.4305
475.655	14.2657
479.176	17.5938
482.692	21.1848
486.21	26.0462
489.724	29.7034
493.237	35.8155
496.75	42.394
500.26	47.7021
503.771	54.6632
507.279	59.6367
510.785	64.4154
514.289	68.9564
517.793	73.1694
521.297	75.7179
524.797	75.8931
528.297	76.0022
531.795	77.0939
535.291	71.4899
538.787	65.1331
542.281	58.4933
545.773	50.2712
549.264	42.8076
552.754	34.3405
556.243	29.6469
559.73	24.8395
563.216	22.1519
566.701	18.9193
570.182	19.0901
573.664	19.0286
577.145	22.4632
580.624	23.6374
584.1	24.4211
587.577	26.4623
591.052	26.2843
594.524	26.5298
597.997	26.4932
601.466	25.8144
604.936	24.0391
608.403	23.063
611.87	20.4628
615.334	19.1425
618.799	14.4199
622.26	10.8243
625.72	7.0397
629.181	5.39901
632.638	3.5299
636.095	0.984179
639.551	0.269317
643.005	0.324642
646.457	-0.670426
649.908	2.80933
653.357	3.6536
656.806	5.06175
660.253	6.4249
663.7	7.12117
667.145	7.56699
670.588	10.7432
674.027	11.0229
677.468	13.5236
680.907	14.2999
684.345	17.4621
687.781	18.0333
691.216	20.0357
694.65	21.0628
698.081	21.989
701.512	21.9931
704.942	20.9128
708.371	21.912
711.796	21.5823
715.222	23.1165
718.645	20.5614
722.068	20.3432
725.49	18.7607
728.909	18.4597
732.329	20.2375
735.745	23.8972
739.16	29.17
742.576	38.7517
745.988	53.468
749.401	66.4127
752.811	83.0886
756.22	98.0388
759.627	110.19
763.035	121.268
766.44	132.146
769.843	140.264
773.245	145.174
776.646	149.174
780.046	148.232
783.444	149.739
786.841	145.413
790.237	139.128
793.631	131.527
797.024	123.155
800.416	111.5
803.807	97.0468
807.196	83.4774
810.584	72.1953
813.971	63.1773
817.354	56.3379
820.739	52.5629
824.122	51.7112
827.503	51.2619
830.882	47.4268
834.261	44.9973
837.637	44.9728
841.013	44.0502
844.389	40.8041
847.761	39.9666
851.131	37.1477
854.503	36.8346
857.871	36.1031
861.24	34.4646
864.606	32.1079
867.97	30.3827
871.336	27.7916
874.698	27.1173
878.058	24.4333
881.418	21.7671
884.778	20.3492
888.135	19.7197
891.49	19.2771
894.845	18.1439
898.198	17.4632
901.55	18.0645
904.901	17.2929
908.25	16.1264
911.598	16.2354
914.945	19.4791
918.291	23.0655
921.635	24.9519
924.978	25.9653
928.318	25.1088
931.659	25.3181
934.998	24.7909
938.336	24.9015
941.671	25.0872
945.007	22.8204
948.339	20.9066
951.672	19.0194
955.004	16.9702
958.333	13.7471
961.662	11.5153
964.989	10.0419
968.315	8.92032
971.639	6.43216
974.962	4.61346
978.285	3.39589
981.605	2.10628
984.924	0.529536
988.243	-0.34355
991.56	1.79711
994.875	7.16602
998.188	11.9341
1001.5	18.0548
1004.81	26.4967
1008.12	35.25
1011.43	44.8555
1014.74	55.555
1018.05	65.1982
1021.35	74.5513
1024.65	80.247
1027.96	84.8018
1031.26	87.9549
1034.56	88.7346
1037.86	87.7735
1041.16	87.0127
1044.45	81.3149
1047.75	75.584
1051.04	69.7288
1054.33	64.0756
1057.62	58.8433
1060.91	56.9063
1064.2	55.354
1067.49	54.5857
1070.77	55.893
1074.06	58.6462
1077.34	60.7783
1080.62	64.7324
1083.91	69.4883
1087.18	72.0183
1090.46	72.1873
1093.74	71.7544
1097.02	69.4761
1100.29	66.3221
1103.56	60.0214
1106.84	55.8985
1110.11	49.2883
1113.38	39.9843
1116.64	33.7788
1119.91	23.0159
1123.18	13.5301
1126.44	4.92795
1129.7	0.0354651
1132.97	-2.53748
1136.23	-0.524424
1139.49	0.465498
1142.74	2.93161
1146	5.25449
1149.26	6.51829
1152.51	9.63097
1155.76	10.3088
1159.01	12.2254
1162.27	15.7945
1165.51	17.6417
1168.76	17.5609
1172.01	18.0044
1175.25	20.377
1178.5	21.0537
1181.74	21.8204
1184.98	21.4057
1188.22	20.9896
1191.46	18.6685
1194.7	18.7086
1197.94	17.8275
1201.17	14.922
1204.41	15.7559
1207.64	14.6883
1210.87	17.1072
1214.1	18.9131
1217.33	19.4133
1220.56	19.9626
1223.79	20.1141
1227.01	20.4228
1230.23	20.5605
1233.46	21.2257
1236.68	22.174
1239.9	24.017
1243.12	25.0818
1246.34	24.1902
1249.55	24.1829
1252.77	27.2613
1255.98	26.9303
1259.2	27.1988
1262.41	26.9278
1265.62	25.6576
1268.83	25.6613
1272.03	26.6612
1275.24	29.6281
1278.45	30.7147
1281.65	31.5922
1284.85	33.1693
1288.06	35.6731
1291.26	37.4196
1294.46	38.2371
1297.66	39.8831
1300.85	40.1053
1304.05	40.296
1307.24	39.7211
1310.43	39.2062
1313.63	39.8915
1316.82	39.1589
1320.01	39.118
1323.2	39.0359
1326.38	39.2956
1329.57	39.4088
1332.76	40.2297
1335.94	38.2961
1339.12	37.0603
1342.3	36.2811
1345.48	34.9642
1348.66	34.3697
1351.84	34.4914
1355.01	33.6174
1358.19	33.5703
1361.36	31.6
1364.53	32.5571
1367.71	31.5432
1370.88	29.3768
1374.04	27.9055
1377.21	26.3877
1380.38	24.6055
1383.54	22.615
1386.71	20.2952
1389.87	18.4722
1393.03	18.8485
1396.19	17.0995
1399.35	18.0011
1402.51	18.8812
1405.67	21.5373
1408.82	25.6653
1411.98	30.2495
1415.13	32.8383
1418.28	37.9233
1421.43	43.5974
1424.58	50.2644
1427.73	56.8666
1430.88	63.3015
1434.02	68.4352
1437.17	72.7328
1440.31	73.646
1443.45	75.9862
1446.6	76.0673
1449.74	76.5456
1452.87	75.76
1456.01	74.8986
1459.15	72.9563
1462.28	71.0763
1465.42	69.698
1468.55	69.5606
1471.68	68.4802
1474.81	67.1226
1477.94	68.1707
1481.07	66.0147
1484.2	63.8013
1487.32	62.7687
1490.45	60.7428
1493.57	56.2095
1496.69	52.9254
1499.81	49.2066
1502.93	45.5108
1506.05	40.9832
1509.17	36.4835
1512.28	31.6978
1515.4	26.8573
1518.51	21.7996
1521.63	19.3911
1524.74	16.1554
1527.85	15.8367
1530.96	15.52
1534.06	17.03
1537.17	17.7425
1540.28	20.4041
1543.38	22.1031
1546.48	26.0316
1549.59	29.5687
1552.69	32.8395
1555.79	34.8408
1558.88	36.6897
1561.98	38.4906
1565.08	39.1792
1568.17	39.1609
1571.27	38.3671
1574.36	39.2285
1577.45	40.1217
1580.54	41.3238
1583.63	42.425
1586.72	42.2375
1589.8	43.0004
1592.89	43.7039
1595.97	44.6342
1599.06	45.5929
1602.14	46.2728
1605.22	45.8918
1608.3	44.1033
1611.38	44.6115
1614.46	44.1535
1617.53	44.4187
1620.61	43.9696
1623.68	45.9018
1626.75	46.4437
1629.82	47.4977
1632.9	47.7902
1635.96	49.5523
1639.03	51.052
1642.1	52.5808
1645.16	53.2737
1648.23	54.8851
1651.29	55.9286
1654.36	56.1753
1657.42	56.0834
1660.48	55.2143
1663.53	53.8405
1666.59	52.9783
1669.65	51.4854
1672.7	49.2709
1675.76	46.6096
1678.81	42.549
1681.86	37.4955
1684.91	34.6898
1687.96	30.6619
1691.01	26.2041
1694.06	23.4032
1697.11	20.3187
1700.15	18.8867
1703.2	17.7707
1706.24	16.7644
1709.28	16.72
1712.32	16.1652
1715.36	15.5874
1718.4	15.4727
1721.43	14.7894
1724.47	13.2131
1727.5	12.2898
1730.54	11.5499
1733.57	10.3454
1736.6	9.01356
1739.63	8.40381
1742.66	7.92973
1745.69	7.151
1748.72	6.24739
1751.74	3.71877
1754.77	1.99162
1757.79	0.976639
1760.81	1.13765
1763.83	-0.0443541
1766.85	-0.427391
1769.87	-1.47084
1772.89	-0.667728
1775.91	-0.290168
1778.92	-0.484892
1781.94	-0.114112
1784.95	0.46504
1787.96	1.95652
1790.97	2.63565
1793.98	2.54803
1796.99	2.27774
1800	2.1392
1803	2.25857
1806.01	3.0991
1809.01	3.17367
1812.02	3.03247
1815.02	3.9111
1818.02	4.00368
1821.02	4.59157
1824.02	4.00763
1827.01	3.64346
1830.01	4.51657
1833	5.95913
1836	5.7127
1838.99	5.14169
1841.98	4.65958
1844.97	3.86725
1847.96	3.91434
1850.95	2.76049
1853.94	2.6227
1856.92	2.40639
1859.91	3.44076
1862.89	3.40583
1865.88	3.00336
1868.86	4.48589
1871.84	5.38031
1874.82	6.92424
1877.8	7.12384
1880.77	8.30018
1882.51	8.9182
1885.5	10.4817
1888.48	11.2188
1891.47	11.7387
1894.46	10.4237
1897.44	10.3743
1900.42	11.0677
1903.41	11.2119
1906.39	10.8419
1909.37	10.1683
1912.35	9.88482
1915.32	10.2544
1918.3	9.98638
1921.28	9.1842
1924.25	7.95598
1927.22	7.50113
1930.2	5.76218
1933.17	7.67843
1936.14	7.14113
1939.11	6.33333
1942.08	7.48098
1945.04	7.24659
1948.01	8.20566
1950.97	8.68296
1953.94	9.71052
1956.9	9.47177
1959.86	7.86922
1962.82	7.63014
1965.78	8.19326
1968.74	8.24782
1971.69	9.65421
1974.65	10.2639
1977.61	9.7809
1980.56	9.56839
1983.51	11.0126
1986.46	12.0932
1989.41	10.9965
1992.36	10.0759
1995.31	10.1597
1998.26	8.70733
2001.2	8.65462
2004.15	8.57691
2007.09	7.61302
2010.04	6.55184
2012.98	5.126
2015.92	6.66326
2018.86	6.09396
2021.8	5.0382
2024.74	4.23936
2027.67	3.55381
2030.61	3.2763
2033.54	3.91267
2036.47	4.47336
2039.41	4.32947
2042.34	4.70058
2045.27	4.61385
2048.2	5.22877
2051.12	4.25959
2054.05	5.65034
2056.98	7.72983
2059.9	9.24969
2062.82	10.5256
2065.75	12.7834
2068.67	13.0394
2071.59	14.7612
2074.51	15.9683
2077.43	17.0457
2080.34	18.7281
2083.26	18.6128
2086.17	20.8393
2089.09	20.7694
2092	21.1385
2094.91	22.3714
2097.82	23.2883
2100.73	25.8472
2103.64	27.2816
2106.55	29.0399
2109.46	30.0689
2112.36	32.8267
2115.27	34.7008
2118.17	35.754
2121.07	37.1379
2123.97	39.4033
2126.87	43.0667
2129.77	46.5326
2132.67	48.4161
2135.57	51.0572
2138.46	51.8846
2141.36	53.552
2144.25	55.3777
2147.14	56.8888
2150.03	58.9986
2152.92	58.4436
2155.81	60.3669
2158.7	61.9485
2161.59	62.5287
2164.48	64.1009
2167.36	64.2953
2170.25	65.7379
2173.13	65.9632
2176.01	65.2148
2178.89	64.8968
2181.77	64.3809
2184.65	63.544
2187.53	62.0955
2190.41	59.8749
2193.28	57.6228
2196.16	55.4852
2199.03	54.8107
2201.9	52.9141
2204.78	50.0591
2207.65	46.7078
2210.51	44.9039
2213.38	43.4276
2216.25	41.1991
2219.12	39.3953
2221.98	37.3794
2224.85	34.7809
2227.71	33.4754
2230.57	30.1266
2233.43	28.147
2236.29	27.5514
2239.15	26.4118
2242.01	24.4011
2244.87	23.0451
2247.73	22.0188
2250.58	20.5413
2253.43	20.259
2256.29	19.7724
2259.14	19.0257
2261.99	18.2751
2264.84	16.7042
2267.69	16.6686
2270.54	17.8256
2273.38	17.9082
2276.23	17.8941
2279.07	18.0688
2281.92	18.5299
2284.76	17.8596
2287.6	18.0159
2290.44	17.3176
2293.28	14.0333
2296.12	11.6312
2298.96	12.578
2301.79	12.8898
2304.63	14.3305
2307.46	13.6712
2310.3	12.8928
2313.13	12.6612
2315.96	12.4941
2318.79	11.9152
2321.62	12.5152
2324.45	11.6786
2327.27	10.8221
2330.1	10.5475
2332.93	10.0722
2335.75	9.46757
2338.57	8.9624
2341.4	9.27318
2344.22	9.33257
2347.04	9.4753
2349.86	7.79521
2352.67	6.36509
2355.49	5.14911
2358.31	4.04133
2361.12	0.862172
2363.94	0.708722
2366.75	1.62634
2369.56	0.474945
2372.37	-0.78704
2375.18	-1.53686
2377.99	-1.36484
2380.8	-2.1785
2383.61	-1.91856
2386.41	-1.71793
2389.22	-0.400131
2392.02	-0.610358
2394.82	-0.688934
2397.63	0.8646
2400.43	1.81963
2403.23	1.61005
2406.02	2.35009
2408.82	4.46575
2411.62	6.20502
2414.41	6.54056
2417.21	7.08872
2420	7.43522
2422.79	8.07515
2425.59	8.41929
2428.38	7.14334
2431.17	6.85256
2433.96	6.46915
2436.74	5.52713
2439.53	5.63207
2442.32	5.3915
2445.1	6.31025
2447.88	5.36776
2450.67	5.88057
2453.45	6.54614
2456.23	6.56502
2459.01	5.68175
2461.79	5.49196
2464.57	5.68237
2467.34	4.82355
2470.12	5.23426
2472.89	5.36755
2475.67	5.79301
2478.44	5.25331
2481.21	4.96735
2483.98	4.56754
2486.75	4.24448
2489.52	3.90235
2492.29	2.00299
2495.06	1.10818
2497.82	0.838389
2500.59	1.7062
2503.35	0.877149
2506.11	1.11174
2508.88	1.65214
2511.63	1.86941
2514.39	1.44919
2517.15	1.66441
2519.91	1.89126
2522.67	3.60293
2525.42	3.81949
2528.18	5.09448
2530.93	5.87771
2533.69	6.3604
2536.44	5.94226
2539.19	7.2201
2541.94	8.45539
2544.69	8.66343
2547.44	7.78822
2550.18	8.92172
2552.93	8.26576
2555.68	8.64627
2558.42	8.42841
2561.16	8.24898
2563.9	9.43633
2566.64	9.96967
2569.38	9.36756
2572.12	8.37526
2574.86	7.99329
2577.6	8.01456
2580.34	7.70894
2583.07	8.16015
2585.81	8.46391
2588.54	8.71525
2591.27	10.3594
2594	10.4972
2596.73	11.1015
2599.46	10.972
2602.19	11.107
2604.92	10.596
2607.64	11.6614
2610.37	10.8645
2613.09	10.4622
2615.82	10.2257
2618.54	9.73982
2621.26	9.52793
2623.98	9.30326
2626.7	9.01252
2629.42	9.0038
2632.14	7.85892
2634.86	6.61255
2637.57	7.8387
2640.29	7.64943
2643	8.78962
2645.72	11.463
2648.43	12.1903
2651.14	12.0392
2653.85	13.3958
2656.56	13.487
2659.27	13.7205
2661.97	14.1972
2664.68	13.5705
2667.38	13.4897
2670.09	13.6048
2672.79	13.8929
2675.49	14.084
2678.2	13.8631
2680.89	12.9257
2683.59	12.6843
2686.29	10.7924
2688.99	10.1376
2691.69	10.1598
2694.38	10.4356
2697.08	9.9673
2699.77	10.262
2702.46	11.58
2705.16	11.4908
2707.85	12.1403
2710.54	12.5662
2713.23	12.4457
2715.92	11.061
2718.6	10.874
2721.29	9.98087
2723.97	10.117
2726.66	9.49061
2729.34	7.81481
2732.02	7.38705
2734.7	7.42036
2737.39	6.54787
2740.06	5.81528
2742.74	5.00504
2745.42	4.66312
2748.1	4.54078
2750.77	3.89071
2753.45	3.67
2756.12	3.18753
2758.79	3.33947
2761.47	2.73261
2764.14	2.53577
2766.81	2.55018
2769.48	3.12838
2772.14	3.90443
2774.81	3.49164
2777.48	4.25884
2780.14	4.44675
2782.81	5.10543
2785.47	5.20139
2788.13	5.18654
2790.79	4.63348
2793.46	2.40231
2796.11	2.56063
2798.77	2.4721
2801.43	1.53714
2804.09	1.3624
2806.74	1.16197
2809.4	0.655411
2812.05	-0.174035
2814.71	-0.353282
2817.36	0.819535
2820.01	1.36403
2822.66	3.29525
2825.31	5.4303
2827.96	8.01832
2830.61	10.7851
2833.25	13.3416
2835.9	17.9849
2838.54	19.8082
2841.18	23.2283
2843.83	27.87
2846.47	33.4207
2849.11	38.4878
2851.75	43.8624
2854.39	47.4768
2857.03	50.5459
2859.67	53.7622
2862.3	56.9416
2864.94	58.86
2867.57	61.8315
2870.21	63.9428
2872.84	64.497
2875.47	65.9186
2878.1	68.1842
2880.73	70.2715
2883.36	72.329
2885.99	74.2591
2888.61	76.376
2891.24	78.2492
2893.87	80.395
2896.49	83.0484
2899.11	87.3464
2901.74	93.9699
2904.36	99.944
2906.98	108.827
2909.6	119.539
2912.22	129.263
2914.83	138.575
2917.45	146.499
2920.07	154.17
2922.68	161.879
2925.3	168.67
2927.91	173.922
2930.52	177.146
2933.13	180.346
2935.74	181.578
2938.35	181.099
2940.96	179.275
2943.57	174.927
2946.18	169.243
2948.78	163.526
2951.39	156.193
2953.99	147.528
2956.6	139.383
2959.2	131.823
2961.8	126.597
2964.4	121.477
2967	116.655
2969.6	111.679
2972.2	107.151
2974.79	102.357
2977.39	97.3195
2979.98	91.8373
2982.58	87.4478
2985.17	81.9426
2987.76	78.1749
2990.36	71.5478
2992.95	65.3993
2995.54	60.7695
2998.12	54.3341
3000.71	47.8732
3003.3	40.3257
3005.88	34.8202
3008.47	28.4326
3011.05	23.8388
3013.64	19.2165
3016.22	15.0847
3018.8	11.949
3021.38	9.86465
3023.96	8.33806
3026.54	7.12117
3029.12	5.1002
3031.69	4.82597
3034.27	4.24621
3036.85	4.17352
3039.42	3.93739
3041.99	5.82935
3044.57	6.46443
3047.14	6.78659
3049.71	7.05939
3052.28	6.67448
3054.85	6.12541
3057.42	6.6929
3059.98	7.08442
3062.55	6.21267
3065.11	7.30029
3067.68	8.04762
3070.24	7.46472
3072.8	7.06294
3075.37	7.1819
3077.93	6.03302
3080.49	5.35197
3083.05	5.11477
3085.61	4.19086
3088.16	3.77019
3090.72	3.88824
3093.27	3.72959
3095.83	3.92426
3098.38	4.46881
3100.94	5.22517
3103.49	6.15402
3106.04	6.84288
3108.59	7.66171
3111.14	9.91258
3113.69	10.6862
3116.23	12.4076
3118.78	15.7941
3121.33	17.5265
3123.87	20.2074
3126.42	23.0022
3128.96	24.8883
3131.5	25.064
3134.04	26.9912
3136.58	29.0725
3139.12	30.6528
3141.66	32.3093
3144.2	33.0295
3146.74	33.1852
3149.27	32.3552