File: data/Raman/poly_smoothed/Mb_50_18_04_1x_45s_532 nm_x100_100%_600 gr_mm_01.txt
#Acq. time (s)=	45
#Accumulations=	2
#Range (cm-¹)=	200...3150
#Windows=	2
#Auto scanning=	Off
#Autofocus=	Off
#Macrospot=	Off
#AutoExposure=	Off
#Spike filter=	Multiple accum.
#Delay time (s)=	0
#Binning=	1
#Readout mode=	Signal
#DeNoise=	Off
#ICS correction=	On
#Dark correction=	Off
#Inst. Process=	Off
#Detector Gain=	Best Dynamic Range
#Detector ADC=	20 kHz
#Detector temperature (°C)=	-69.85
#Instrument=	LabRAM HR Evol
#Detector=	Synapse
#Objective=	x100
#Grating=	600 gr/mm
#ND Filter=	100%
#Laser (nm)=	532
#Hole=	100.021
#Range=	Auto
#Laser Pol.=	No
#Raman. Pol.=	No
#Laser Pol. (°)=	-0.0007625
#Raman Pol. (°)=	89.9995
#Collection=	Microscope
#StageXY=	Marzhauser
#StageZ=	Marzhauser
#X (µm)=	19386.9
#Y (µm)=	3036.1
#Z (µm)=	1047.65
#Full time(mm:ss)=	3:18
#Project=
#Sample=
#Site=
#Title=	Mb_50_18_04_2x_45s_532 nm_x100_100%_600 gr_mm
#Remark=
#Date=	12.07.2022 10:31
#Acquired=	12.07.2022 10:31:38
#Base:Fit=	10.08.2022 10:49:18
#Base:Sub=	10.08.2022 10:49:30
#Filter:Polynom=	16.08.2022 10:14:59
#AxisType[0]=Intens
#AxisUnit[0]=Cnt
#AxisType[1]=Spectr
#AxisUnit[1]=1/cm
200.388	19.0692
204.019	14.1673
207.646	12.0561
211.274	9.73942
214.899	8.10873
218.524	6.79057
222.146	6.83488
225.766	7.66264
229.388	8.54092
233.005	7.90707
236.621	7.5932
240.236	7.87875
243.852	6.5825
247.464	5.67496
251.074	5.17778
254.683	6.11046
258.291	5.88018
261.897	6.94087
265.504	7.49117
269.108	7.71461
272.71	7.97064
276.311	8.77188
279.91	9.09597
283.508	9.16735
287.105	10.4306
290.698	12.4005
294.291	15.3984
297.884	19.7931
301.475	21.7212
305.064	24.2085
308.652	28.402
312.237	31.7503
315.822	32.69
319.406	34.3916
322.987	34.2262
326.568	33.9651
330.148	33.0214
333.724	29.7763
337.301	26.3598
340.875	24.3932
344.449	22.1733
348.02	23.3478
351.592	26.6608
355.16	29.408
358.728	34.1604
362.294	40.7619
365.858	45.1159
369.422	51.805
372.983	57.9166
376.543	64.8291
380.102	71.435
383.661	75.5285
387.216	75.1329
390.771	75.314
394.324	74.7085
397.875	72.3547
401.425	66.3473
404.974	62.3932
408.524	57.0823
412.07	48.0811
415.614	38.1196
419.156	28.489
422.698	20.0566
426.238	13.6741
429.777	8.81423
433.315	6.34691
436.852	5.03029
440.387	4.8573
443.919	6.50695
447.451	8.11106
450.982	9.4813
454.512	10.2857
458.038	12.7769
461.565	13.9505
465.091	15.4027
468.613	15.9913
472.136	17.3438
475.655	19.1876
479.176	21.6408
482.692	24.1297
486.21	28.9867
489.724	35.4071
493.237	43.1915
496.75	50.6524
500.26	58.626
503.771	63.4683
507.279	66.8425
510.785	69.045
514.289	72.6248
517.793	73.5197
521.297	73.6742
524.797	72.796
528.297	69.1844
531.795	66.9265
535.291	62.7027
538.787	55.653
542.281	48.6761
545.773	41.6025
549.264	34.2494
552.754	26.9911
556.243	19.5309
559.73	12.917
563.216	7.89679
566.701	5.23231
570.182	4.01306
573.664	6.01545
577.145	6.08041
580.624	8.50625
584.1	8.89877
587.577	9.06833
591.052	8.16782
594.524	7.14672
597.997	9.19204
601.466	10.6919
604.936	11.7703
608.403	13.0328
611.87	14.011
615.334	14.3186
618.799	14.751
622.26	13.8393
625.72	13.6782
629.181	12.8882
632.638	11.7917
636.095	9.54446
639.551	8.635
643.005	7.42674
646.457	7.13222
649.908	8.83477
653.357	9.86399
656.806	11.0714
660.253	12.5481
663.7	12.7452
667.145	12.6887
670.588	12.909
674.027	14.6071
677.468	13.0562
680.907	13.7137
684.345	15.145
687.781	17.7825
691.216	19.1637
694.65	21.2428
698.081	22.5493
701.512	22.7948
704.942	25.158
708.371	26.6906
711.796	28.2234
715.222	30.6245
718.645	30.8047
722.068	32.2477
725.49	34.4867
728.909	34.7547
732.329	37.6878
735.745	43.9986
739.16	54.5719
742.576	66.7048
745.988	79.1447
749.401	91.6906
752.811	104.715
756.22	116.646
759.627	125.682
763.035	133.259
766.44	140.394
769.843	145.965
773.245	148.599
776.646	149.848
780.046	147.626
783.444	143.953
786.841	139.731
790.237	134.445
793.631	127.022
797.024	117.505
800.416	106.153
803.807	95.0196
807.196	84.1608
810.584	75.5115
813.971	69.678
817.354	68.4919
820.739	68.8249
824.122	68.6464
827.503	65.065
830.882	63.9692
834.261	63.0283
837.637	62.1399
841.013	60.5237
844.389	56.649
847.761	53.928
851.131	50.5285
854.503	47.0432
857.871	44.9353
861.24	41.8077
864.606	39.4527
867.97	38.3459
871.336	37.2168
874.698	34.7467
878.058	34.6443
881.418	33.3795
884.778	32.0788
888.135	31.8308
891.49	32.5368
894.845	33.2462
898.198	34.0863
901.55	33.2913
904.901	31.8259
908.25	30.9593
911.598	31.838
914.945	33.4064
918.291	34.8995
921.635	33.9189
924.978	31.688
928.318	29.2898
931.659	28.7979
934.998	28.246
938.336	28.5662
941.671	26.7767
945.007	23.2299
948.339	20.8608
951.672	19.1122
955.004	17.3496
958.333	16.1646
961.662	14.143
964.989	11.5527
968.315	10.727
971.639	11.162
974.962	9.31053
978.285	9.8213
981.605	9.78766
984.924	7.72787
988.243	7.07642
991.56	7.29168
994.875	8.95361
998.188	15.3026
1001.5	22.1793
1004.81	27.9574
1008.12	37.0851
1011.43	47.9213
1014.74	55.0916
1018.05	65.1364
1021.35	72.0021
1024.65	77.1377
1027.96	84.1212
1031.26	85.9618
1034.56	86.0491
1037.86	83.2816
1041.16	81.031
1044.45	76.952
1047.75	72.2191
1051.04	67.5608
1054.33	62.7603
1057.62	59.3649
1060.91	55.9139
1064.2	53.3436
1067.49	51.2629
1070.77	51.9705
1074.06	53.0532
1077.34	56.4008
1080.62	60.4471
1083.91	60.691
1087.18	63.3323
1090.46	65.0407
1093.74	65.3209
1097.02	62.9013
1100.29	60.2599
1103.56	55.7411
1106.84	51.5039
1110.11	46.2155
1113.38	38.4665
1116.64	32.2518
1119.91	26.03
1123.18	21.3347
1126.44	15.4647
1129.7	10.7465
1132.97	9.79359
1136.23	9.75732
1139.49	11.5446
1142.74	12.078
1146	13.111
1149.26	12.2
1152.51	11.839
1155.76	10.4125
1159.01	9.05109
1162.27	7.82721
1165.51	7.79563
1168.76	7.52885
1172.01	5.75461
1175.25	4.82799
1178.5	5.77963
1181.74	5.78693
1184.98	8.01891
1188.22	10.1829
1191.46	11.6531
1194.7	13.516
1197.94	14.8222
1201.17	17.3824
1204.41	16.9231
1207.64	16.8678
1210.87	19.3471
1214.1	21.842
1217.33	23.5159
1220.56	25.4127
1223.79	27.128
1227.01	28.1828
1230.23	29.6986
1233.46	30.6118
1236.68	30.9018
1239.9	30.155
1243.12	30.8749
1246.34	30.8876
1249.55	30.3785
1252.77	31.8097
1255.98	31.8647
1259.2	32.0287
1262.41	32.2595
1265.62	33.8997
1268.83	35.02
1272.03	36.3091
1275.24	38.688
1278.45	39.8557
1281.65	40.9022
1284.85	40.933
1288.06	43.0457
1291.26	46.2536
1294.46	47.0798
1297.66	47.7795
1300.85	49.3105
1304.05	50.4675
1307.24	51.1155
1310.43	51.639
1313.63	51.4062
1316.82	50.7346
1320.01	50.1311
1323.2	49.7597
1326.38	50.6213
1329.57	50.879
1332.76	49.6435
1335.94	49.3196
1339.12	48.232
1342.3	47.4553
1345.48	46.3008
1348.66	44.363
1351.84	43.971
1355.01	42.2077
1358.19	40.1744
1361.36	38.6811
1364.53	36.2799
1367.71	34.8234
1370.88	31.3077
1374.04	29.0119
1377.21	29.1574
1380.38	27.2434
1383.54	25.904
1386.71	22.7721
1389.87	20.753
1393.03	19.1732
1396.19	18.0346
1399.35	19.4072
1402.51	20.9603
1405.67	23.7489
1408.82	25.1784
1411.98	27.5449
1415.13	33.3558
1418.28	37.7639
1421.43	45.5403
1424.58	52.119
1427.73	57.0684
1430.88	61.3838
1434.02	65.0391
1437.17	69.4633
1440.31	73.0958
1443.45	75.3436
1446.6	77.0774
1449.74	79.2685
1452.87	78.3115
1456.01	77.7999
1459.15	77.2382
1462.28	75.8228
1465.42	75.6222
1468.55	75.6372
1471.68	74.7892
1474.81	72.5258
1477.94	72.0242
1481.07	69.6355
1484.2	66.7826
1487.32	65.306
1490.45	63.8996
1493.57	62.9068
1496.69	59.1695
1499.81	54.4934
1502.93	48.9153
1506.05	43.1353
1509.17	37.4737
1512.28	32.1006
1515.4	26.3603
1518.51	20.2217
1521.63	15.3285
1524.74	11.0391
1527.85	7.92287
1530.96	5.5865
1534.06	7.43453
1537.17	8.00997
1540.28	8.87835
1543.38	11.0559
1546.48	12.4238
1549.59	14.6046
1552.69	18.1197
1555.79	20.8454
1558.88	22.5333
1561.98	26.4535
1565.08	29.7708
1568.17	35.1894
1571.27	38.0512
1574.36	42.0528
1577.45	44.6099
1580.54	47.4945
1583.63	50.1737
1586.72	52.6367
1589.8	54.9778
1592.89	56.5751
1595.97	58.1829
1599.06	58.947
1602.14	58.1854
1605.22	58.6133
1608.3	57.511
1611.38	55.6605
1614.46	53.5897
1617.53	52.3886
1620.61	52.108
1623.68	51.2986
1626.75	50.639
1629.82	51.7951
1632.9	51.5488
1635.96	52.8501
1639.03	54.0842
1642.1	56.585
1645.16	58.8479
1648.23	59.473
1651.29	60.3412
1654.36	62.828
1657.42	62.4378
1660.48	64.7573
1663.53	65.2849
1666.59	65.2771
1669.65	63.8853
1672.7	60.176
1675.76	56.8406
1678.81	53.6389
1681.86	47.7083
1684.91	43.6899
1687.96	39.5728
1691.01	35.8589
1694.06	32.247
1697.11	28.8212
1700.15	24.425
1703.2	21.4367
1706.24	18.7789
1709.28	15.7234
1712.32	12.2664
1715.36	10.2228
1718.4	8.95977
1721.43	8.40853
1724.47	7.3704
1727.5	7.02349
1730.54	5.82499
1733.57	4.36909
1736.6	4.62651
1739.63	4.27476
1742.66	3.92276
1745.69	2.14726
1748.72	2.15084
1751.74	1.86713
1754.77	2.66333
1757.79	2.89766
1760.81	3.22671
1763.83	3.42346
1766.85	3.544
1769.87	3.69826
1772.89	2.6814
1775.91	2.179
1778.92	1.8855
1781.94	2.39777
1784.95	2.23292
1787.96	2.89849
1790.97	4.42732
1793.98	4.73911
1796.99	4.13011
1800	3.95689
1803	3.53769
1806.01	3.68204
1809.01	4.11093
1812.02	4.51853
1815.02	5.45006
1818.02	5.31142
1821.02	5.25855
1824.02	5.64212
1827.01	6.0448
1830.01	5.73114
1833	5.26392
1836	5.48012
1838.99	5.2888
1841.98	4.32809
1844.97	4.05373
1847.96	3.61055
1850.95	2.78194
1853.94	3.43004
1856.92	2.39781
1859.91	3.26515
1862.89	3.12218
1865.88	2.48966
1868.86	1.69881
1871.84	2.28877
1874.82	3.90712
1877.8	4.51159
1880.77	4.8884
1882.51	5.13632
1885.5	4.91534
1888.48	5.04734
1891.47	4.68737
1894.46	3.95869
1897.44	3.79037
1900.42	2.49378
1903.41	3.07177
1906.39	3.52959
1909.37	3.03732
1912.35	1.86524
1915.32	2.61942
1918.3	3.15771
1921.28	3.487
1924.25	3.71137
1927.22	4.13249
1930.2	4.8448
1933.17	5.20989
1936.14	4.49751
1939.11	5.14999
1942.08	6.08715
1945.04	7.52203
1948.01	7.52821
1950.97	8.2702
1953.94	8.77998
1956.9	8.0635
1959.86	8.40501
1962.82	9.03126
1965.78	8.24655
1968.74	7.11065
1971.69	5.7339
1974.65	5.07892
1977.61	4.76005
1980.56	4.24319
1983.51	2.84576
1986.46	2.50077
1989.41	2.6035
1992.36	2.02331
1995.31	0.912479
1998.26	0.0945632
2001.2	-0.124278
2004.15	0.623935
2007.09	-0.130868
2010.04	-0.188596
2012.98	0.548642
2015.92	2.24828
2018.86	4.04771
2021.8	6.1007
2024.74	7.06042
2027.67	6.13646
2030.61	8.2217
2033.54	9.41257
2036.47	9.45876
2039.41	8.7383
2042.34	8.57612
2045.27	9.40812
2048.2	10.7732
2051.12	12.2273
2054.05	12.416
2056.98	13.0459
2059.9	13.1908
2062.82	13.4747
2065.75	15.0684
2068.67	17.4035
2071.59	18.6188
2074.51	19.8247
2077.43	21.456
2080.34	22.5901
2083.26	25.3199
2086.17	27.8352
2089.09	30.0005
2092	31.9921
2094.91	32.6598
2097.82	35.5561
2100.73	37.268
2103.64	40.0116
2106.55	42.1207
2109.46	44.2335
2112.36	47.4561
2115.27	52.419
2118.17	56.5573
2121.07	60.7021
2123.97	63.6505
2126.87	68.161
2129.77	72.832
2132.67	77.0395
2135.57	82.2197
2138.46	88.6718
2141.36	92.8518
2144.25	97.5787
2147.14	102.501
2150.03	105.884
2152.92	109.141
2155.81	111.608
2158.7	113.974
2161.59	114.388
2164.48	115.573
2167.36	115.586
2170.25	116.946
2173.13	115.45
2176.01	114.148
2178.89	111.701
2181.77	110.331
2184.65	109.178
2187.53	107.21
2190.41	103.684
2193.28	99.8185
2196.16	97.4358
2199.03	93.2694
2201.9	89.9391
2204.78	86.2863
2207.65	82.6261
2210.51	80.3869
2213.38	77.6393
2216.25	73.2282
2219.12	67.8482
2221.98	63.3728
2224.85	58.9968
2227.71	54.9591
2230.57	52.0318
2233.43	48.5811
2236.29	44.9275
2239.15	42.3312
2242.01	40.2814
2244.87	37.0708
2247.73	35.8043
2250.58	33.9229
2253.43	34.3031
2256.29	32.3901
2259.14	31.2514
2261.99	30.371
2264.84	28.2505
2267.69	27.5214
2270.54	27.0728
2273.38	25.4124
2276.23	24.2197
2279.07	23.2376
2281.92	23.3724
2284.76	21.9201
2287.6	19.9236
2290.44	19.9247
2293.28	18.1409
2296.12	17.4471
2298.96	17.3159
2301.79	16.1807
2304.63	15.6432
2307.46	14.5696
2310.3	14.0139
2313.13	13.4048
2315.96	11.5767
2318.79	11.3884
2321.62	10.7999
2324.45	10.1411
2327.27	8.17013
2330.1	7.76032
2332.93	6.46954
2335.75	6.07394
2338.57	5.62569
2341.4	5.41799
2344.22	4.70957
2347.04	4.89152
2349.86	3.97804
2352.67	3.73942
2355.49	4.32687
2358.31	4.34189
2361.12	3.4587
2363.94	3.21262
2366.75	4.23001
2369.56	3.82805
2372.37	2.41027
2375.18	2.05172
2377.99	2.821
2380.8	1.97841
2383.61	1.653
2386.41	2.90612
2389.22	2.49343
2392.02	1.56841
2394.82	1.997
2397.63	3.00838
2400.43	3.3226
2403.23	3.19154
2406.02	3.60919
2408.82	3.65595
2411.62	3.11358
2414.41	2.55308
2417.21	2.682
2420	2.76632
2422.79	2.47942
2425.59	2.71089
2428.38	2.43618
2431.17	1.51065
2433.96	2.24447
2436.74	1.83398
2439.53	1.05316
2442.32	1.90552
2445.1	3.54065
2447.88	4.24526
2450.67	4.54852
2453.45	5.56289
2456.23	6.09111
2459.01	5.44525
2461.79	5.75083
2464.57	5.60728
2467.34	4.77225
2470.12	4.48237
2472.89	4.69126
2475.67	3.3477
2478.44	2.79708
2481.21	2.81429
2483.98	3.72075
2486.75	1.88222
2489.52	0.93953
2492.29	0.527169
2495.06	0.763355
2497.82	0.350156
2500.59	0.969344
2503.35	1.18843
2506.11	1.37179
2508.88	1.67647
2511.63	2.70273
2514.39	3.28093
2517.15	2.39688
2519.91	2.51763
2522.67	1.85774
2525.42	1.41966
2528.18	1.47492
2530.93	2.57558
2533.69	3.09727
2536.44	4.39712
2539.19	5.93619
2541.94	5.72369
2544.69	5.956
2547.44	6.59454
2550.18	6.80726
2552.93	7.07183
2555.68	7.54158
2558.42	7.89535
2561.16	9.11268
2563.9	10.6351
2566.64	10.8592
2569.38	10.6399
2572.12	10.3299
2574.86	10.7321
2577.6	9.90354
2580.34	9.49925
2583.07	9.2339
2585.81	8.68463
2588.54	8.64966
2591.27	8.05058
2594	7.70565
2596.73	7.33723
2599.46	6.76344
2602.19	6.05628
2604.92	5.96318
2607.64	5.77228
2610.37	4.71314
2613.09	5.60583
2615.82	6.57782
2618.54	6.22618
2621.26	6.58319
2623.98	7.01989
2626.7	7.10406
2629.42	8.34826
2632.14	8.73072
2634.86	8.47396
2637.57	8.26471
2640.29	8.59718
2643	8.92348
2645.72	9.67774
2648.43	11.3578
2651.14	12.1823
2653.85	11.5676
2656.56	12.2805
2659.27	11.2343
2661.97	11.0744
2664.68	10.1667
2667.38	9.98605
2670.09	10.1319
2672.79	10.272
2675.49	10.6592
2678.2	10.1202
2680.89	10.4216
2683.59	9.35715
2686.29	8.90476
2688.99	9.12512
2691.69	9.1281
2694.38	7.85959
2697.08	7.20593
2699.77	5.60077
2702.46	4.95633
2705.16	5.28869
2707.85	6.28161
2710.54	6.40527
2713.23	7.24108
2715.92	6.29105
2718.6	7.00644
2721.29	7.4841
2723.97	7.33621
2726.66	6.5766
2729.34	5.36964
2732.02	4.1674
2734.7	4.69059
2737.39	3.92086
2740.06	3.98412
2742.74	3.63049
2745.42	3.14051
2748.1	2.6074
2750.77	2.18826
2753.45	2.41805
2756.12	1.33761
2758.79	0.374399
2761.47	0.315608
2764.14	0.238869
2766.81	0.866436
2769.48	1.14023
2772.14	0.782943
2774.81	0.918611
2777.48	0.482099
2780.14	1.68581
2782.81	2.57612
2785.47	2.58523
2788.13	1.25803
2790.79	1.61308
2793.46	2.3856
2796.11	1.40904
2798.77	1.53034
2801.43	1.74301
2804.09	1.39973
2806.74	0.712365
2809.4	-0.0648711
2812.05	0.295439
2814.71	1.10048
2817.36	2.58307
2820.01	5.52072
2822.66	9.18371
2825.31	13.6954
2827.96	19.9775
2830.61	25.0712
2833.25	30.3
2835.9	36.6805
2838.54	44.6293
2841.18	52.2087
2843.83	60.134
2846.47	67.9752
2849.11	75.2173
2851.75	84.1964
2854.39	92.2415
2857.03	100.077
2859.67	106.168
2862.3	112.747
2864.94	117.676
2867.57	122.112
2870.21	125.385
2872.84	128.025
2875.47	131.465
2878.1	135.092
2880.73	138.696
2883.36	143.181
2885.99	149.508
2888.61	154.085
2891.24	159.524
2893.87	165.66
2896.49	171.33
2899.11	180.159
2901.74	190.075
2904.36	201.624
2906.98	213.317
2909.6	225.763
2912.22	239.469
2914.83	254.353
2917.45	267.504
2920.07	278.003
2922.68	287.221
2925.3	294.344
2927.91	300.605
2930.52	302.061
2933.13	301.037
2935.74	298.31
2938.35	294.478
2940.96	287.873
2943.57	279.148
2946.18	269.379
2948.78	257.202
2951.39	244.926
2953.99	231.482
2956.6	219.187
2959.2	206.214
2961.8	194.895
2964.4	183.317
2967	171.948
2969.6	162.779
2972.2	152.577
2974.79	143.613
2977.39	135.568
2979.98	126.419
2982.58	116.734
2985.17	106.93
2987.76	97.312
2990.36	87.4857
2992.95	77.7095
2995.54	67.2905
2998.12	59.6222
3000.71	51.3944
3003.3	44.109
3005.88	36.9075
3008.47	31.131
3011.05	24.8501
3013.64	19.9144
3016.22	16.0351
3018.8	13.1485
3021.38	9.76227
3023.96	7.40081
3026.54	5.31288
3029.12	3.7948
3031.69	4.23746
3034.27	4.23665
3036.85	3.44652
3039.42	4.5161
3041.99	5.09272
3044.57	5.60978
3047.14	5.8498
3049.71	6.99099
3052.28	6.98005
3054.85	7.5792
3057.42	8.08306
3059.98	8.18583
3062.55	9.00194
3065.11	9.40796
3067.68	9.40415
3070.24	8.71927
3072.8	7.17937
3075.37	5.72002
3077.93	5.35269
3080.49	5.37315
3083.05	4.03488
3085.61	3.71182
3088.16	2.31842
3090.72	2.36667
3093.27	2.76945
3095.83	3.03589
3098.38	2.91634
3100.94	3.84196
3103.49	4.77739
3106.04	6.16048
3108.59	7.96611
3111.14	10.7299
3113.69	11.3674
3116.23	13.1016
3118.78	14.5986
3121.33	16.8741
3123.87	18.7526
3126.42	20.9551
3128.96	21.8471
3131.5	23.3073
3134.04	24.9567
3136.58	26.8651
3139.12	29.2091
3141.66	31.0325
3144.2	32.3154
3146.74	34.542
3149.27	37.0673