File: data/Raman/poly_smoothed/Mb_50_18_10_1x_45s_532 nm_x100_100%_600 gr_mm_01.txt
#Acq. time (s)=	45
#Accumulations=	2
#Range (cm-¹)=	200...3150
#Windows=	2
#Auto scanning=	Off
#Autofocus=	Off
#Macrospot=	Off
#AutoExposure=	Off
#Spike filter=	Multiple accum.
#Delay time (s)=	0
#Binning=	1
#Readout mode=	Signal
#DeNoise=	Off
#ICS correction=	On
#Dark correction=	Off
#Inst. Process=	Off
#Detector Gain=	Best Dynamic Range
#Detector ADC=	20 kHz
#Detector temperature (°C)=	-69.62
#Instrument=	LabRAM HR Evol
#Detector=	Synapse
#Objective=	x100
#Grating=	600 gr/mm
#ND Filter=	100%
#Laser (nm)=	532
#Hole=	100.021
#Range=	Auto
#Laser Pol.=	No
#Raman. Pol.=	No
#Laser Pol. (°)=	-0.0007625
#Raman Pol. (°)=	89.9995
#Collection=	Microscope
#StageXY=	Marzhauser
#StageZ=	Marzhauser
#X (µm)=	19289.6
#Y (µm)=	3081.3
#Z (µm)=	1047
#Full time(mm:ss)=	3:18
#Project=
#Sample=
#Site=
#Title=	Mb_50_18_10_2x_45s_532 nm_x100_100%_600 gr_mm
#Remark=
#Date=	12.07.2022 11:01
#Acquired=	12.07.2022 11:01:04
#Base:Fit=	10.08.2022 10:49:18
#Base:Sub=	10.08.2022 10:49:30
#Filter:Polynom=	16.08.2022 10:14:59
#AxisType[0]=Intens
#AxisUnit[0]=Cnt
#AxisType[1]=Spectr
#AxisUnit[1]=1/cm
200.388	34.0477
204.019	27.6475
207.646	21.6261
211.274	16.8031
214.899	13.0417
218.524	9.47329
222.146	6.26851
225.766	4.58378
229.388	3.46337
233.005	1.06748
236.621	1.29374
240.236	0.382837
243.852	0.968212
247.464	1.0097
251.074	3.01801
254.683	3.39859
258.291	4.00551
261.897	1.96403
265.504	2.45334
269.108	4.68522
272.71	4.2585
276.311	3.4623
279.91	4.23613
283.508	3.91033
287.105	4.33304
290.698	5.06454
294.291	6.42143
297.884	8.288
301.475	9.80385
305.064	10.6805
308.652	11.3489
312.237	12.0251
315.822	13.2481
319.406	13.751
322.987	15.2495
326.568	14.9893
330.148	13.5994
333.724	13.5721
337.301	12.5726
340.875	12.6607
344.449	10.7591
348.02	9.58727
351.592	10.2523
355.16	12.7539
358.728	14.7937
362.294	15.6592
365.858	17.443
369.422	20.021
372.983	23.1023
376.543	24.766
380.102	26.2567
383.661	29.1568
387.216	29.1282
390.771	30.0019
394.324	28.8704
397.875	27.8014
401.425	27.3735
404.974	26.0449
408.524	23.8814
412.07	19.7359
415.614	16.4438
419.156	13.3285
422.698	10.5298
426.238	6.89119
429.777	3.90507
433.315	2.8936
436.852	2.09921
440.387	3.00728
443.919	1.50361
447.451	2.13256
450.982	2.06875
454.512	2.27655
458.038	2.75633
461.565	3.72407
465.091	5.65055
468.613	8.26119
472.136	8.3353
475.655	10.3742
479.176	13.0574
482.692	15.9098
486.21	19.9152
489.724	23.6702
493.237	27.1866
496.75	30.8671
500.26	34.0549
503.771	38.0995
507.279	38.4857
510.785	40.3614
514.289	42.1964
517.793	43.0648
521.297	41.3867
524.797	41.0956
528.297	40.9136
531.795	39.7033
535.291	39.3247
538.787	36.7018
542.281	34.0693
545.773	32.4207
549.264	29.2511
552.754	25.994
556.243	23.4948
559.73	21.2295
563.216	19.5084
566.701	17.5301
570.182	17.1949
573.664	16.965
577.145	15.2152
580.624	15.9076
584.1	13.9123
587.577	11.7343
591.052	11.0382
594.524	9.09507
597.997	8.0585
601.466	8.799
604.936	9.31563
608.403	9.32267
611.87	11.3513
615.334	11.5911
618.799	12.6235
622.26	11.6289
625.72	11.0059
629.181	11.5749
632.638	10.6318
636.095	9.94369
639.551	10.3175
643.005	10.8339
646.457	11.4317
649.908	12.1128
653.357	13.5944
656.806	14.7915
660.253	14.887
663.7	15.7139
667.145	14.0624
670.588	13.5803
674.027	15.0316
677.468	16.5458
680.907	19.6411
684.345	21.425
687.781	24.551
691.216	24.8264
694.65	26.4187
698.081	25.7528
701.512	26.1804
704.942	27.2937
708.371	27.936
711.796	26.2923
715.222	26.859
718.645	27.844
722.068	28.6682
725.49	31.101
728.909	33.4808
732.329	35.1942
735.745	38.4803
739.16	43.3515
742.576	47.6621
745.988	52.4552
749.401	57.1264
752.811	63.6303
756.22	69.4828
759.627	74.3559
763.035	78.8802
766.44	82.7282
769.843	85.3218
773.245	87.4492
776.646	90.5085
780.046	89.8189
783.444	88.6358
786.841	91.4926
790.237	91.5459
793.631	88.6909
797.024	87.6608
800.416	87.264
803.807	85.0066
807.196	82.6927
810.584	79.3529
813.971	77.4241
817.354	74.7328
820.739	74.8226
824.122	73.7058
827.503	73.0986
830.882	72.1382
834.261	71.6885
837.637	70.0625
841.013	66.5799
844.389	64.5804
847.761	62.8729
851.131	60.1316
854.503	56.7322
857.871	54.4631
861.24	53.602
864.606	50.4343
867.97	51.1814
871.336	50.6717
874.698	48.1486
878.058	47.4231
881.418	45.8747
884.778	43.8473
888.135	44.5538
891.49	43.8527
894.845	41.9532
898.198	41.1494
901.55	42.2308
904.901	43.0635
908.25	44.2256
911.598	43.5493
914.945	43.5415
918.291	41.7376
921.635	40.343
924.978	37.0698
928.318	37.1594
931.659	35.3209
934.998	33.0468
938.336	31.9254
941.671	29.3115
945.007	28.0463
948.339	26.4937
951.672	25.1492
955.004	23.6157
958.333	21.254
961.662	19.1352
964.989	18.5292
968.315	19.9225
971.639	21.1464
974.962	21.4877
978.285	23.0291
981.605	23.2705
984.924	24.0464
988.243	24.6563
991.56	25.211
994.875	25.0752
998.188	26.8362
1001.5	30.431
1004.81	35.9926
1008.12	39.615
1011.43	42.3801
1014.74	45.6837
1018.05	47.4799
1021.35	49.3363
1024.65	51.3846
1027.96	53.6784
1031.26	53.4346
1034.56	52.5076
1037.86	50.8756
1041.16	46.3133
1044.45	44.4042
1047.75	42.2419
1051.04	39.4299
1054.33	34.8627
1057.62	31.7152
1060.91	28.4196
1064.2	26.1298
1067.49	24.0229
1070.77	23.0095
1074.06	22.8756
1077.34	24.566
1080.62	25.4342
1083.91	25.682
1087.18	25.0028
1090.46	23.8931
1093.74	24.2933
1097.02	24.9649
1100.29	25.4485
1103.56	25.2477
1106.84	24.6034
1110.11	23.3245
1113.38	20.2408
1116.64	18.3888
1119.91	15.4813
1123.18	12.8611
1126.44	11.7309
1129.7	9.03883
1132.97	7.52837
1136.23	7.59347
1139.49	8.17105
1142.74	6.37708
1146	5.74224
1149.26	6.79584
1152.51	6.9907
1155.76	5.73486
1159.01	4.11685
1162.27	3.26343
1165.51	1.35901
1168.76	1.41897
1172.01	0.713923
1175.25	1.28035
1178.5	2.35475
1181.74	1.84148
1184.98	0.506455
1188.22	0.630849
1191.46	1.37221
1194.7	0.993583
1197.94	0.444245
1201.17	2.38557
1204.41	2.83757
1207.64	3.24282
1210.87	4.22295
1214.1	6.5234
1217.33	7.9222
1220.56	11.4837
1223.79	13.9356
1227.01	15.5055
1230.23	19.1237
1233.46	21.4471
1236.68	23.5902
1239.9	25.2153
1243.12	26.2398
1246.34	28.2514
1249.55	30.8339
1252.77	31.0022
1255.98	32.5227
1259.2	32.548
1262.41	34.6301
1265.62	37.9182
1268.83	40.2122
1272.03	41.7192
1275.24	44.9337
1278.45	48.6526
1281.65	50.5317
1284.85	52.6062
1288.06	55.7286
1291.26	57.9768
1294.46	58.9422
1297.66	60.3727
1300.85	62.2637
1304.05	61.232
1307.24	62.1793
1310.43	62.996
1313.63	61.4931
1316.82	59.8211
1320.01	57.7739
1323.2	56.8275
1326.38	55.0727
1329.57	53.1009
1332.76	50.2664
1335.94	49.1756
1339.12	46.9898
1342.3	46.3379
1345.48	43.8941
1348.66	41.0727
1351.84	38.246
1355.01	36.21
1358.19	32.4427
1361.36	31.539
1364.53	29.4599
1367.71	28.1401
1370.88	25.6557
1374.04	25.2046
1377.21	24.7518
1380.38	22.4257
1383.54	21.3146
1386.71	21.1382
1389.87	20.3152
1393.03	19.8846
1396.19	19.6823
1399.35	20.0162
1402.51	22.0518
1405.67	23.4511
1408.82	26.0991
1411.98	30.2449
1415.13	32.328
1418.28	37.8117
1421.43	42.6798
1424.58	47.8783
1427.73	52.1737
1430.88	56.8476
1434.02	60.9478
1437.17	65.0585
1440.31	67.5707
1443.45	68.9446
1446.6	70.4453
1449.74	70.123
1452.87	67.8002
1456.01	65.9462
1459.15	65.1788
1462.28	62.2432
1465.42	59.6877
1468.55	56.4121
1471.68	54.2128
1474.81	51.4441
1477.94	49.3504
1481.07	45.8425
1484.2	44.2723
1487.32	43.8556
1490.45	41.7111
1493.57	40.4754
1496.69	38.559
1499.81	36.0016
1502.93	32.8907
1506.05	30.6306
1509.17	27.4963
1512.28	23.9181
1515.4	20.5655
1518.51	19.0289
1521.63	16.5715
1524.74	13.7652
1527.85	11.2151
1530.96	9.74541
1534.06	9.60852
1537.17	8.44559
1540.28	8.17597
1543.38	9.3966
1546.48	11.8903
1549.59	15.0078
1552.69	14.5753
1555.79	17.3903
1558.88	19.9038
1561.98	23.2969
1565.08	26.5179
1568.17	29.3889
1571.27	32.5946
1574.36	35.4568
1577.45	38.0706
1580.54	40.3389
1583.63	43.6686
1586.72	44.4241
1589.8	46.4566
1592.89	47.2415
1595.97	47.5587
1599.06	48.2528
1602.14	46.8238
1605.22	47.07
1608.3	47.1997
1611.38	47.5998
1614.46	47.2725
1617.53	47.468
1620.61	48.7547
1623.68	49.7214
1626.75	51.6651
1629.82	53.3351
1632.9	56.5492
1635.96	60.7562
1639.03	63.9992
1642.1	66.1329
1645.16	67.505
1648.23	69.7983
1651.29	70.6604
1654.36	69.4202
1657.42	67.5177
1660.48	66.7107
1663.53	63.9121
1666.59	60.5771
1669.65	56.7013
1672.7	52.6887
1675.76	47.6346
1678.81	42.5454
1681.86	37.0318
1684.91	32.8113
1687.96	28.8672
1691.01	24.5172
1694.06	21.1126
1697.11	18.6552
1700.15	15.6506
1703.2	15.2446
1706.24	12.651
1709.28	11.7383
1712.32	11.6646
1715.36	10.2421
1718.4	10.1528
1721.43	9.87832
1724.47	9.58649
1727.5	7.43169
1730.54	7.10603
1733.57	7.20323
1736.6	7.17592
1739.63	5.69673
1742.66	6.19351
1745.69	6.48263
1748.72	6.33676
1751.74	5.61812
1754.77	5.35686
1757.79	4.74653
1760.81	4.86531
1763.83	4.90534
1766.85	5.32527
1769.87	6.3888
1772.89	5.44615
1775.91	4.61032
1778.92	4.09911
1781.94	3.81526
1784.95	3.97213
1787.96	3.78935
1790.97	3.68904
1793.98	3.59607
1796.99	3.07818
1800	2.76928
1803	1.99453
1806.01	3.95772
1809.01	4.35669
1812.02	5.05142
1815.02	5.26476
1818.02	5.63418
1821.02	5.62144
1824.02	5.73438
1827.01	5.80856
1830.01	6.67734
1833	7.51576
1836	8.12657
1838.99	8.84864
1841.98	8.13161
1844.97	7.37437
1847.96	7.67852
1850.95	7.66879
1853.94	7.44725
1856.92	7.78656
1859.91	7.00314
1862.89	6.53647
1865.88	6.60774
1868.86	5.85466
1871.84	6.58298
1874.82	6.32663
1877.8	6.43338
1880.77	7.24256
1882.51	7.27879
1885.5	7.25025
1888.48	7.68095
1891.47	8.82745
1894.46	9.57204
1897.44	10.1937
1900.42	9.56773
1903.41	9.88538
1906.39	9.83065
1909.37	9.27999
1912.35	10.2326
1915.32	10.5692
1918.3	11.699
1921.28	12.3093
1924.25	11.0562
1927.22	10.3718
1930.2	9.14529
1933.17	8.91637
1936.14	10.0904
1939.11	9.73716
1942.08	9.53094
1945.04	9.71765
1948.01	9.64708
1950.97	10.4381
1953.94	10.1341
1956.9	9.97988
1959.86	8.83142
1962.82	8.47145
1965.78	8.47534
1968.74	8.03256
1971.69	7.17842
1974.65	7.17402
1977.61	7.10944
1980.56	6.49662
1983.51	7.24278
1986.46	8.4858
1989.41	9.04167
1992.36	9.33271
1995.31	9.32465
1998.26	8.91189
2001.2	8.87568
2004.15	9.41277
2007.09	9.68273
2010.04	9.13972
2012.98	8.79045
2015.92	9.697
2018.86	9.80556
2021.8	10.3476
2024.74	10.1816
2027.67	10.131
2030.61	9.62969
2033.54	9.78813
2036.47	10.753
2039.41	12.1961
2042.34	13.2202
2045.27	13.7677
2048.2	14.3724
2051.12	15.9617
2054.05	17.2098
2056.98	19.3373
2059.9	21.3727
2062.82	22.3125
2065.75	23.4908
2068.67	24.0753
2071.59	25.5165
2074.51	27.5119
2077.43	29.0966
2080.34	30.2224
2083.26	31.8106
2086.17	33.8164
2089.09	36.688
2092	38.9026
2094.91	41.4745
2097.82	43.4658
2100.73	45.0759
2103.64	48.0648
2106.55	50.4874
2109.46	53.6002
2112.36	56.2858
2115.27	60.0067
2118.17	63.4991
2121.07	66.8186
2123.97	70.2959
2126.87	74.1299
2129.77	78.1466
2132.67	81.9465
2135.57	85.9645
2138.46	90.4814
2141.36	94.68
2144.25	97.9537
2147.14	102.53
2150.03	105.054
2152.92	107.858
2155.81	110.46
2158.7	112.419
2161.59	114.092
2164.48	114.809
2167.36	114.578
2170.25	114.659
2173.13	114.574
2176.01	113.841
2178.89	113.665
2181.77	113.177
2184.65	111.599
2187.53	107.885
2190.41	105.558
2193.28	102.541
2196.16	98.7649
2199.03	95.2631
2201.9	91.548
2204.78	88.1089
2207.65	84.5785
2210.51	80.0651
2213.38	75.5642
2216.25	72.2628
2219.12	68.4171
2221.98	63.369
2224.85	59.5599
2227.71	55.9863
2230.57	50.8696
2233.43	47.5469
2236.29	43.6053
2239.15	41.8436
2242.01	39.4265
2244.87	37.1242
2247.73	35.6493
2250.58	33.4179
2253.43	31.6269
2256.29	29.0417
2259.14	27.833
2261.99	27.0617
2264.84	26.111
2267.69	25.1481
2270.54	24.5845
2273.38	23.2856
2276.23	23.9441
2279.07	22.6757
2281.92	21.7037
2284.76	20.8486
2287.6	19.7808
2290.44	16.3303
2293.28	14.4154
2296.12	14.0137
2298.96	13.6138
2301.79	13.0896
2304.63	12.881
2307.46	11.8253
2310.3	11.1802
2313.13	10.2382
2315.96	9.48618
2318.79	9.13293
2321.62	9.22525
2324.45	9.14474
2327.27	9.65412
2330.1	9.41922
2332.93	9.41308
2335.75	8.07309
2338.57	7.89352
2341.4	8.52283
2344.22	8.44744
2347.04	8.40766
2349.86	6.90295
2352.67	6.07868
2355.49	4.97944
2358.31	3.73977
2361.12	2.6721
2363.94	3.65547
2366.75	4.76056
2369.56	5.03012
2372.37	4.46288
2375.18	3.2817
2377.99	2.64927
2380.8	2.04929
2383.61	2.58153
2386.41	3.26539
2389.22	3.94929
2392.02	4.44945
2394.82	3.45256
2397.63	3.47516
2400.43	3.35271
2403.23	3.84711
2406.02	4.05263
2408.82	4.95956
2411.62	5.28424
2414.41	4.45853
2417.21	3.85585
2420	4.92745
2422.79	5.25799
2425.59	5.41652
2428.38	5.88311
2431.17	5.34321
2433.96	3.76907
2436.74	3.06848
2439.53	1.78337
2442.32	0.53922
2445.1	-0.223178
2447.88	-0.534376
2450.67	-1.67908
2453.45	-0.408006
2456.23	-0.918453
2459.01	-0.441882
2461.79	-1.35449
2464.57	-0.995544
2467.34	-0.220181
2470.12	1.49111
2472.89	2.57273
2475.67	2.55115
2478.44	2.41743
2481.21	3.43138
2483.98	3.32188
2486.75	3.72191
2489.52	4.12765
2492.29	4.24936
2495.06	4.68748
2497.82	4.28597
2500.59	3.54737
2503.35	2.12634
2506.11	1.92439
2508.88	1.71683
2511.63	2.517
2514.39	2.53191
2517.15	2.52138
2519.91	2.51092
2522.67	3.25292
2525.42	3.48161
2528.18	3.81525
2530.93	4.31964
2533.69	5.6349
2536.44	6.1349
2539.19	7.2085
2541.94	6.72973
2544.69	7.1106
2547.44	7.68912
2550.18	6.9043
2552.93	7.43324
2555.68	7.84016
2558.42	8.82203
2561.16	9.57466
2563.9	9.78261
2566.64	9.70722
2569.38	9.56789
2572.12	9.03424
2574.86	9.82409
2577.6	10.522
2580.34	10.4171
2583.07	9.84356
2585.81	9.21573
2588.54	8.76587
2591.27	9.19021
2594	9.09332
2596.73	9.19675
2599.46	9.00077
2602.19	8.76582
2604.92	8.55851
2607.64	8.86252
2610.37	8.5348
2613.09	8.39594
2615.82	7.62423
2618.54	7.09813
2621.26	8.07861
2623.98	7.71094
2626.7	7.71851
2629.42	8.42846
2632.14	7.42695
2634.86	7.33011
2637.57	6.77543
2640.29	7.01909
2643	7.67335
2645.72	7.63178
2648.43	7.59668
2651.14	8.19028
2653.85	8.93628
2656.56	10.825
2659.27	11.3696
2661.97	11.1699
2664.68	10.8972
2667.38	11.1797
2670.09	10.9327
2672.79	10.9718
2675.49	11.3304
2678.2	10.2906
2680.89	10.1443
2683.59	9.57036
2686.29	9.76785
2688.99	9.10845
2691.69	9.06475
2694.38	9.96954
2697.08	9.8148
2699.77	9.47708
2702.46	9.81861
2705.16	10.5831
2707.85	10.4334
2710.54	10.9587
2713.23	11.773
2715.92	12.6633
2718.6	13.1021
2721.29	13.1298
2723.97	13.0626
2726.66	12.2016
2729.34	11.9119
2732.02	10.9438
2734.7	9.9783
2737.39	8.34435
2740.06	7.28808
2742.74	5.65002
2745.42	4.80292
2748.1	4.56653
2750.77	3.47359
2753.45	3.28909
2756.12	2.9869
2758.79	3.20586
2761.47	2.99475
2764.14	2.71734
2766.81	2.71351
2769.48	2.30702
2772.14	2.35283
2774.81	1.34958
2777.48	1.98435
2780.14	2.17067
2782.81	2.06006
2785.47	2.06928
2788.13	1.57094
2790.79	1.49926
2793.46	0.448931
2796.11	0.328228
2798.77	-0.22803
2801.43	-0.273386
2804.09	-0.968879
2806.74	-0.803245
2809.4	-1.77148
2812.05	-2.14918
2814.71	-1.8695
2817.36	-0.615368
2820.01	2.63823
2822.66	6.898
2825.31	12.3784
2827.96	18.1777
2830.61	24.4734
2833.25	30.588
2835.9	37.7258
2838.54	45.3107
2841.18	53.1892
2843.83	62.0116
2846.47	70.3649
2849.11	79.6382
2851.75	88.7772
2854.39	97.474
2857.03	106.661
2859.67	114.428
2862.3	121.661
2864.94	127.931
2867.57	132.413
2870.21	135.906
2872.84	139.096
2875.47	142.12
2878.1	144.952
2880.73	148.326
2883.36	151.5
2885.99	155.338
2888.61	157.926
2891.24	160.93
2893.87	164.806
2896.49	169.197
2899.11	174.228
2901.74	180.186
2904.36	187.07
2906.98	195.877
2909.6	204.597
2912.22	214.701
2914.83	224.426
2917.45	233.303
2920.07	241.718
2922.68	248.431
2925.3	253.586
2927.91	257.702
2930.52	259.796
2933.13	260.838
2935.74	260.134
2938.35	256.817
2940.96	251.368
2943.57	243.728
2946.18	234.428
2948.78	223.471
2951.39	213.552
2953.99	201.507
2956.6	189.903
2959.2	177.71
2961.8	165.03
2964.4	153.838
2967	142.37
2969.6	132.453
2972.2	122.27
2974.79	112.234
2977.39	102.5
2979.98	92.3548
2982.58	82.6829
2985.17	72.8235
2987.76	64.2752
2990.36	56.8549
2992.95	50.0861
2995.54	42.7937
2998.12	37.0627
3000.71	30.3126
3003.3	25.2889
3005.88	19.9145
3008.47	15.9663
3011.05	11.7159
3013.64	8.80936
3016.22	5.92612
3018.8	2.74359
3021.38	0.734552
3023.96	-0.420628
3026.54	-0.503044
3029.12	-0.0629355
3031.69	0.0246346
3034.27	0.165271
3036.85	0.564592
3039.42	2.14154
3041.99	3.22513
3044.57	3.97053
3047.14	5.3962
3049.71	5.70258
3052.28	6.8733
3054.85	7.63912
3057.42	8.47442
3059.98	8.54381
3062.55	8.56387
3065.11	8.37218
3067.68	7.4139
3070.24	6.66647
3072.8	5.99755
3075.37	4.00495
3077.93	3.45716
3080.49	2.88767
3083.05	1.91246
3085.61	1.15958
3088.16	1.10023
3090.72	1.20431
3093.27	1.29393
3095.83	1.42268
3098.38	3.52213
3100.94	4.91862
3103.49	5.75475
3106.04	6.72119
3108.59	7.89373
3111.14	9.00358
3113.69	10.505
3116.23	13.0694
3118.78	14.889
3121.33	17.1561
3123.87	18.4009
3126.42	19.5946
3128.96	21.2558
3131.5	23.004
3134.04	25.1045
3136.58	26.7202
3139.12	28.6118
3141.66	29.9808
3144.2	30.7742
3146.74	31.8678
3149.27	32.8086