File: data/Raman/poly_smoothed/Mb_50_18_01_1x_45s_532 nm_x100_100%_600 gr_mm_01.txt
#Acq. time (s)=	45
#Accumulations=	2
#Range (cm-¹)=	200...3150
#Windows=	2
#Auto scanning=	Off
#Autofocus=	Off
#Macrospot=	Off
#AutoExposure=	Off
#Spike filter=	Multiple accum.
#Delay time (s)=	0
#Binning=	1
#Readout mode=	Signal
#DeNoise=	Off
#ICS correction=	On
#Dark correction=	Off
#Inst. Process=	Off
#Detector Gain=	Best Dynamic Range
#Detector ADC=	20 kHz
#Detector temperature (°C)=	-69.85
#Instrument=	LabRAM HR Evol
#Detector=	Synapse
#Objective=	x100
#Grating=	600 gr/mm
#ND Filter=	100%
#Laser (nm)=	532
#Hole=	100.021
#Range=	Auto
#Laser Pol.=	No
#Raman. Pol.=	No
#Laser Pol. (°)=	-0.0007625
#Raman Pol. (°)=	89.9995
#Collection=	Microscope
#StageXY=	Marzhauser
#StageZ=	Marzhauser
#X (µm)=	19380.5
#Y (µm)=	3001.8
#Z (µm)=	1048.25
#Full time(mm:ss)=	3:09
#Project=
#Sample=
#Site=
#Title=	Mb_50_18_01_2x_45s_532 nm_x100_100%_600 gr_mm
#Remark=
#Date=	12.07.2022 10:17
#Acquired=	12.07.2022 10:17:57
#Base:Fit=	10.08.2022 10:49:18
#Base:Sub=	10.08.2022 10:49:30
#Filter:Polynom=	16.08.2022 10:14:59
#AxisType[0]=Intens
#AxisUnit[0]=Cnt
#AxisType[1]=Spectr
#AxisUnit[1]=1/cm
200.388	14.1453
204.019	22.4177
207.646	26.2246
211.274	28.5345
214.899	28.2842
218.524	26.9264
222.146	26.4026
225.766	21.5858
229.388	19.5696
233.005	17.6295
236.621	15.4539
240.236	12.2353
243.852	11.8719
247.464	9.38576
251.074	4.2157
254.683	2.80459
258.291	2.33785
261.897	1.31601
265.504	0.234447
269.108	-0.593139
272.71	-0.137168
276.311	0.604968
279.91	-0.0803732
283.508	-0.200272
287.105	1.52731
290.698	2.27274
294.291	4.23147
297.884	6.35468
301.475	7.01634
305.064	9.24388
308.652	10.1499
312.237	9.90328
315.822	10.1682
319.406	11.7789
322.987	12.484
326.568	11.296
330.148	11.9603
333.724	10.3855
337.301	7.04625
340.875	4.38842
344.449	4.60482
348.02	6.71509
351.592	11.0228
355.16	14.6205
358.728	19.9138
362.294	25.2445
365.858	31.9867
369.422	37.7822
372.983	43.4998
376.543	47.5929
380.102	51.9388
383.661	54.0359
387.216	54.895
390.771	54.5246
394.324	53.3813
397.875	49.5398
401.425	45.4882
404.974	40.9603
408.524	35.5803
412.07	30.1223
415.614	22.1437
419.156	16.2092
422.698	8.48835
426.238	2.18092
429.777	-0.365544
433.315	-0.704348
436.852	-0.430704
440.387	0.147546
443.919	1.49434
447.451	3.67976
450.982	4.77937
454.512	6.33788
458.038	5.99009
461.565	6.66015
465.091	7.29988
468.613	8.7195
472.136	8.81958
475.655	9.02499
479.176	12.6956
482.692	16.2858
486.21	21.2914
489.724	28.3052
493.237	36.9448
496.75	45.2123
500.26	52.1986
503.771	57.4003
507.279	63.2854
510.785	65.2237
514.289	69.7575
517.793	70.962
521.297	72.449
524.797	71.3728
528.297	70.9924
531.795	68.0227
535.291	62.2364
538.787	57.0163
542.281	48.4514
545.773	41.45
549.264	32.9193
552.754	23.8876
556.243	18.2517
559.73	11.6474
563.216	7.70648
566.701	5.22875
570.182	3.85143
573.664	5.11869
577.145	7.35178
580.624	9.60575
584.1	9.86379
587.577	11.8305
591.052	11.3268
594.524	12.5173
597.997	13.9372
601.466	15.7446
604.936	17.7364
608.403	18.6423
611.87	17.215
615.334	16.7423
618.799	15.8768
622.26	14.7081
625.72	13.137
629.181	9.90561
632.638	9.06235
636.095	5.86577
639.551	6.60403
643.005	4.40271
646.457	2.81738
649.908	4.47757
653.357	5.72418
656.806	6.805
660.253	8.0236
663.7	7.8286
667.145	7.98881
670.588	8.71923
674.027	10.8309
677.468	13.0895
680.907	15.2601
684.345	17.7039
687.781	20.7324
691.216	22.2312
694.65	24.6359
698.081	24.4425
701.512	26.3223
704.942	28.5581
708.371	29.8956
711.796	28.6882
715.222	29.7041
718.645	29.8404
722.068	29.7318
725.49	30.2244
728.909	31.1741
732.329	34.5524
735.745	40.0069
739.16	47.8115
742.576	57.6782
745.988	69.5722
749.401	79.4731
752.811	90.681
756.22	101.29
759.627	110.75
763.035	118.128
766.44	124.922
769.843	127.895
773.245	131.594
776.646	131.87
780.046	129.251
783.444	126.072
786.841	121.855
790.237	116.255
793.631	107.245
797.024	97.3681
800.416	88.2001
803.807	78.589
807.196	68.9107
810.584	61.3698
813.971	56.9827
817.354	52.1926
820.739	53.0992
824.122	51.0737
827.503	49.4201
830.882	49.1899
834.261	47.0451
837.637	47.1169
841.013	45.8898
844.389	44.0636
847.761	43.1876
851.131	39.6748
854.503	37.122
857.871	37.6434
861.24	36.8924
864.606	37.3932
867.97	37.6784
871.336	37.9482
874.698	36.4383
878.058	36.4618
881.418	38.8606
884.778	38.4075
888.135	38.852
891.49	39.2589
894.845	39.5601
898.198	39.3013
901.55	38.399
904.901	37.6023
908.25	35.7997
911.598	35.1158
914.945	33.4596
918.291	31.0909
921.635	29.0361
924.978	27.2258
928.318	24.4196
931.659	20.9337
934.998	16.5111
938.336	15.2736
941.671	13.3786
945.007	11.5942
948.339	9.39768
951.672	7.70487
955.004	3.79209
958.333	3.73661
961.662	2.31291
964.989	0.686529
968.315	2.92124
971.639	2.84472
974.962	5.04392
978.285	7.21761
981.605	7.3707
984.924	7.85802
988.243	11.1873
991.56	14.5146
994.875	22.0465
998.188	28.8055
1001.5	37.7833
1004.81	48.8458
1008.12	59.4057
1011.43	70.0207
1014.74	79.4728
1018.05	87.3424
1021.35	93.2995
1024.65	99.2584
1027.96	100.911
1031.26	102.232
1034.56	101.199
1037.86	97.2024
1041.16	92.6781
1044.45	86.0353
1047.75	81.3418
1051.04	74.4774
1054.33	69.4016
1057.62	63.2736
1060.91	57.8423
1064.2	53.3574
1067.49	49.4186
1070.77	49.9941
1074.06	50.3583
1077.34	52.2315
1080.62	53.8978
1083.91	55.4531
1087.18	56.4328
1090.46	57.2132
1093.74	58.1413
1097.02	57.6353
1100.29	57.5625
1103.56	55.9534
1106.84	51.993
1110.11	46.987
1113.38	42.0006
1116.64	37.9136
1119.91	31.9496
1123.18	27.211
1126.44	21.8323
1129.7	17.8859
1132.97	16.4479
1136.23	14.9756
1139.49	12.9971
1142.74	11.6366
1146	9.91953
1149.26	8.92796
1152.51	8.54769
1155.76	3.58497
1159.01	2.00832
1162.27	1.96163
1165.51	0.9777
1168.76	2.52262
1172.01	2.99404
1175.25	5.90521
1178.5	5.78896
1181.74	8.88013
1184.98	8.97137
1188.22	9.67795
1191.46	10.8071
1194.7	10.5504
1197.94	12.4353
1201.17	11.0434
1204.41	12.0877
1207.64	13.4091
1210.87	14.6868
1214.1	15.9547
1217.33	17.3706
1220.56	18.1625
1223.79	21.3588
1227.01	22.8954
1230.23	24.9145
1233.46	26.471
1236.68	27.4658
1239.9	33.3948
1243.12	37.4881
1246.34	40.3632
1249.55	44.4876
1252.77	47.2315
1255.98	52.1118
1259.2	56.3248
1262.41	59.2645
1265.62	63.6563
1268.83	67.6404
1272.03	71.094
1275.24	73.6236
1278.45	77.6205
1281.65	79.3262
1284.85	81.4206
1288.06	83.6717
1291.26	84.9583
1294.46	87.3904
1297.66	88.0473
1300.85	88.5123
1304.05	89.7139
1307.24	87.974
1310.43	87.86
1313.63	87.8984
1316.82	87.8203
1320.01	88.6382
1323.2	84.4057
1326.38	83.2275
1329.57	81.8379
1332.76	78.4126
1335.94	77.4971
1339.12	74.3153
1342.3	72.6611
1345.48	70.4715
1348.66	68.2064
1351.84	65.5403
1355.01	63.6966
1358.19	61.5661
1361.36	59.6851
1364.53	58.9778
1367.71	57.3303
1370.88	55.4141
1374.04	52.8167
1377.21	52.0343
1380.38	51.2656
1383.54	47.335
1386.71	45.3057
1389.87	43.0012
1393.03	42.2438
1396.19	40.9934
1399.35	42.0708
1402.51	43.6436
1405.67	46.6237
1408.82	48.3346
1411.98	53.0317
1415.13	60.5664
1418.28	65.999
1421.43	74.7042
1424.58	83.3868
1427.73	92.3823
1430.88	101.309
1434.02	108.89
1437.17	114.781
1440.31	119.886
1443.45	122.982
1446.6	124.168
1449.74	126.594
1452.87	125.909
1456.01	124.31
1459.15	120.662
1462.28	117.583
1465.42	113.232
1468.55	109.384
1471.68	106.461
1474.81	101.479
1477.94	97.3539
1481.07	93.0678
1484.2	87.872
1487.32	84.6661
1490.45	81.8358
1493.57	76.1271
1496.69	73.7532
1499.81	69.3187
1502.93	64.6328
1506.05	60.2332
1509.17	55.1178
1512.28	49.8574
1515.4	46.2933
1518.51	42.0791
1521.63	38.8605
1524.74	36.8657
1527.85	34.7193
1530.96	34.2423
1534.06	32.8272
1537.17	33.7229
1540.28	36.148
1543.38	36.9054
1546.48	38.6348
1549.59	40.0013
1552.69	42.6713
1555.79	43.7125
1558.88	45.5161
1561.98	46.5477
1565.08	50.0569
1568.17	52.1182
1571.27	57.9977
1574.36	61.7341
1577.45	66.3258
1580.54	70.2031
1583.63	73.7021
1586.72	77.2953
1589.8	80.3906
1592.89	84.6877
1595.97	86.5909
1599.06	87.7535
1602.14	89.2857
1605.22	89.9246
1608.3	91.2852
1611.38	91.4663
1614.46	93.4174
1617.53	92.7548
1620.61	92.9642
1623.68	95.0416
1626.75	96.1411
1629.82	97.3912
1632.9	99.2002
1635.96	102.409
1639.03	104.065
1642.1	108.601
1645.16	110.274
1648.23	112.883
1651.29	112.56
1654.36	112.378
1657.42	110.45
1660.48	107.662
1663.53	104.358
1666.59	99.4177
1669.65	93.3706
1672.7	85.0667
1675.76	76.9733
1678.81	69.9541
1681.86	61.5147
1684.91	53.4246
1687.96	47.5335
1691.01	40.5301
1694.06	34.8733
1697.11	31.8995
1700.15	27.5982
1703.2	24.1737
1706.24	21.6434
1709.28	19.8581
1712.32	19.1007
1715.36	16.4862
1718.4	16.0359
1721.43	14.1553
1724.47	15.7754
1727.5	16.3019
1730.54	15.742
1733.57	14.0906
1736.6	14.0059
1739.63	11.8433
1742.66	10.1787
1745.69	8.81116
1748.72	6.7965
1751.74	5.33061
1754.77	3.06142
1757.79	2.78935
1760.81	3.08052
1763.83	2.85967
1766.85	1.85989
1769.87	1.91979
1772.89	2.4198
1775.91	2.38852
1778.92	3.65367
1781.94	4.52294
1784.95	5.46125
1787.96	6.60822
1790.97	7.04845
1793.98	9.63757
1796.99	10.2779
1800	9.16091
1803	9.26692
1806.01	8.41723
1809.01	8.33945
1812.02	8.5524
1815.02	8.46318
1818.02	7.48785
1821.02	6.35878
1824.02	6.62547
1827.01	6.20716
1830.01	6.93576
1833	7.26005
1836	6.91627
1838.99	6.24994
1841.98	5.54536
1844.97	5.67632
1847.96	5.88881
1850.95	6.64439
1853.94	7.26436
1856.92	7.69674
1859.91	7.46656
1862.89	8.49466
1865.88	8.99844
1868.86	7.89898
1871.84	7.0897
1874.82	7.38909
1877.8	7.75404
1880.77	7.31201
1882.51	8.41193
1885.5	8.87924
1888.48	8.31575
1891.47	8.34592
1894.46	7.979
1897.44	8.6191
1900.42	7.68717
1903.41	7.04861
1906.39	5.80142
1909.37	4.89505
1912.35	4.15065
1915.32	4.05257
1918.3	2.76261
1921.28	2.02806
1924.25	3.01551
1927.22	1.77009
1930.2	1.23804
1933.17	1.89692
1936.14	1.56108
1939.11	0.46628
1942.08	0.0678362
1945.04	0.983194
1948.01	1.0403
1950.97	2.16483
1953.94	3.18655
1956.9	3.42473
1959.86	4.82463
1962.82	6.14378
1965.78	6.25352
1968.74	6.56209
1971.69	7.37808
1974.65	7.72653
1977.61	7.69771
1980.56	9.02658
1983.51	9.654
1986.46	10.6499
1989.41	9.39167
1992.36	9.62501
1995.31	9.34781
1998.26	7.95992
2001.2	6.42932
2004.15	6.27586
2007.09	6.29864
2010.04	5.36268
2012.98	5.83311
2015.92	5.08003
2018.86	4.4285
2021.8	5.61683
2024.74	6.37965
2027.67	6.76315
2030.61	7.29763
2033.54	8.7162
2036.47	9.2679
2039.41	9.3346
2042.34	10.9659
2045.27	12.8997
2048.2	13.7386
2051.12	16.4052
2054.05	18.8589
2056.98	20.4356
2059.9	22.3274
2062.82	22.5832
2065.75	22.8699
2068.67	23.6866
2071.59	24.7875
2074.51	25.3691
2077.43	27.5937
2080.34	29.4764
2083.26	30.2331
2086.17	32.5946
2089.09	34.7342
2092	37.4506
2094.91	40.4782
2097.82	43.1208
2100.73	47.2753
2103.64	51.0109
2106.55	55.0086
2109.46	58.9147
2112.36	63.7112
2115.27	68.2221
2118.17	73.6569
2121.07	80.8008
2123.97	86.4111
2126.87	93.3344
2129.77	97.8911
2132.67	103.651
2135.57	109.43
2138.46	114.841
2141.36	119.57
2144.25	124.342
2147.14	129.297
2150.03	134.932
2152.92	137.866
2155.81	142.659
2158.7	146.424
2161.59	148.753
2164.48	150.858
2167.36	150.703
2170.25	150.005
2173.13	147.394
2176.01	145.823
2178.89	142.473
2181.77	139.004
2184.65	135.103
2187.53	132.141
2190.41	129.295
2193.28	125.55
2196.16	121.056
2199.03	117.755
2201.9	113.525
2204.78	109.051
2207.65	105.06
2210.51	100.474
2213.38	95.4867
2216.25	90.4174
2219.12	86.0144
2221.98	80.7717
2224.85	75.377
2227.71	70.5976
2230.57	66.859
2233.43	62.1688
2236.29	57.3483
2239.15	51.5302
2242.01	46.6142
2244.87	42.6248
2247.73	38.355
2250.58	35.1045
2253.43	32.2652
2256.29	31.3332
2259.14	29.6936
2261.99	28.1979
2264.84	26.9883
2267.69	24.8969
2270.54	23.3293
2273.38	21.4076
2276.23	19.4992
2279.07	19.7034
2281.92	17.257
2284.76	16.2262
2287.6	14.6249
2290.44	12.2705
2293.28	10.7369
2296.12	10.0759
2298.96	11.4748
2301.79	11.0152
2304.63	10.2645
2307.46	9.00245
2310.3	8.87797
2313.13	8.64619
2315.96	7.91069
2318.79	7.52155
2321.62	8.20835
2324.45	8.40032
2327.27	9.08372
2330.1	7.78632
2332.93	6.91834
2335.75	5.81071
2338.57	5.11975
2341.4	4.55757
2344.22	4.48636
2347.04	3.67151
2349.86	3.71338
2352.67	3.07103
2355.49	2.38873
2358.31	1.81764
2361.12	1.71704
2363.94	1.45388
2366.75	2.52522
2369.56	2.94715
2372.37	1.54689
2375.18	1.54256
2377.99	1.53207
2380.8	0.729758
2383.61	-0.481282
2386.41	-0.514529
2389.22	-0.737345
2392.02	0.639387
2394.82	1.7097
2397.63	2.44247
2400.43	1.51926
2403.23	1.39703
2406.02	2.11981
2408.82	2.83639
2411.62	3.12967
2414.41	3.87818
2417.21	4.1745
2420	4.51349
2422.79	6.18663
2425.59	7.86631
2428.38	8.57182
2431.17	9.59881
2433.96	10.4744
2436.74	11.2574
2439.53	10.2462
2442.32	9.72174
2445.1	8.01829
2447.88	6.61166
2450.67	5.8719
2453.45	5.79758
2456.23	6.59433
2459.01	6.44921
2461.79	6.25171
2464.57	5.20096
2467.34	4.77532
2470.12	3.27141
2472.89	3.12292
2475.67	2.38618
2478.44	2.35203
2481.21	2.14807
2483.98	2.36346
2486.75	2.50844
2489.52	3.25553
2492.29	3.5127
2495.06	4.13342
2497.82	4.91238
2500.59	5.72799
2503.35	5.07173
2506.11	4.94306
2508.88	4.64585
2511.63	4.34488
2514.39	3.92377
2517.15	3.09924
2519.91	4.01234
2522.67	3.77724
2525.42	4.17833
2528.18	3.46443
2530.93	3.81626
2533.69	3.3889
2536.44	2.56818
2539.19	2.97936
2541.94	3.2176
2544.69	3.5193
2547.44	4.7962
2550.18	5.37032
2552.93	5.1956
2555.68	5.07288
2558.42	5.58943
2561.16	7.09341
2563.9	7.9528
2566.64	8.91113
2569.38	8.64301
2572.12	8.51461
2574.86	7.87404
2577.6	7.69979
2580.34	8.54912
2583.07	8.48726
2585.81	8.27225
2588.54	9.07209
2591.27	8.98748
2594	9.07245
2596.73	9.43629
2599.46	8.81165
2602.19	9.27659
2604.92	10.1488
2607.64	10.5295
2610.37	10.2013
2613.09	10.7188
2615.82	11.7695
2618.54	12.0051
2621.26	11.9245
2623.98	12.5641
2626.7	13.3641
2629.42	13.5154
2632.14	12.9843
2634.86	14.1305
2637.57	13.976
2640.29	14.2906
2643	15.0791
2645.72	14.9266
2648.43	14.7999
2651.14	14.7107
2653.85	14.7916
2656.56	15.5008
2659.27	15.2547
2661.97	14.9627
2664.68	15.8541
2667.38	15.2045
2670.09	15.0228
2672.79	15.7586
2675.49	15.781
2678.2	16.1855
2680.89	16.4644
2683.59	16.5438
2686.29	16.8626
2688.99	17.0191
2691.69	16.3595
2694.38	16.3577
2697.08	15.7364
2699.77	15.9249
2702.46	15.9928
2705.16	15.2559
2707.85	15.4658
2710.54	15.1377
2713.23	13.9879
2715.92	14.6843
2718.6	15.1892
2721.29	13.8948
2723.97	13.7547
2726.66	13.6788
2729.34	13.8649
2732.02	13.5554
2734.7	13.3268
2737.39	14.3505
2740.06	14.2924
2742.74	13.5895
2745.42	14.3057
2748.1	14.2978
2750.77	13.5354
2753.45	13.8334
2756.12	13.8574
2758.79	12.35
2761.47	12.1847
2764.14	11.9803
2766.81	11.1371
2769.48	10.5917
2772.14	9.75217
2774.81	9.20536
2777.48	6.86366
2780.14	6.31163
2782.81	6.28072
2785.47	5.4692
2788.13	4.51197
2790.79	4.37999
2793.46	4.33127
2796.11	4.33441
2798.77	4.51692
2801.43	4.77149
2804.09	4.32771
2806.74	4.51706
2809.4	3.67213
2812.05	4.81066
2814.71	4.45222
2817.36	7.21425
2820.01	10.7089
2822.66	14.8273
2825.31	20.6445
2827.96	26.7324
2830.61	32.33
2833.25	39.863
2835.9	48.5644
2838.54	57.9323
2841.18	65.8396
2843.83	76.0176
2846.47	85.6676
2849.11	96.1331
2851.75	106.028
2854.39	115.775
2857.03	125.399
2859.67	134.572
2862.3	141.36
2864.94	147.813
2867.57	154.724
2870.21	159.588
2872.84	162.803
2875.47	167.152
2878.1	171.352
2880.73	175.338
2883.36	181.45
2885.99	187.062
2888.61	193.492
2891.24	200.819
2893.87	209.216
2896.49	219.142
2899.11	230.7
2901.74	243.321
2904.36	256.043
2906.98	271.494
2909.6	287.998
2912.22	303.854
2914.83	320.075
2917.45	334.886
2920.07	347.308
2922.68	359.501
2925.3	367.915
2927.91	375.258
2930.52	378.886
2933.13	379.266
2935.74	374.944
2938.35	368.512
2940.96	360.872
2943.57	350.536
2946.18	338.923
2948.78	326.102
2951.39	311.245
2953.99	296.526
2956.6	281.928
2959.2	267.93
2961.8	254.154
2964.4	240.153
2967	226.686
2969.6	212.947
2972.2	201.277
2974.79	189.045
2977.39	175.798
2979.98	164.92
2982.58	152.635
2985.17	140.272
2987.76	126.883
2990.36	114.387
2992.95	102.739
2995.54	90.3353
2998.12	77.7517
3000.71	66.278
3003.3	55.7794
3005.88	46.5822
3008.47	39.7299
3011.05	32.4062
3013.64	26.5238
3016.22	20.7886
3018.8	16.3792
3021.38	12.2082
3023.96	9.30427
3026.54	6.84358
3029.12	4.29915
3031.69	2.11972
3034.27	2.26011
3036.85	2.00826
3039.42	2.06599
3041.99	2.7688
3044.57	3.56311
3047.14	3.69564
3049.71	3.68589
3052.28	4.34587
3054.85	4.77226
3057.42	4.69806
3059.98	3.87188
3062.55	4.03679
3065.11	3.57301
3067.68	3.72076
3070.24	4.19406
3072.8	4.68385
3075.37	3.6623
3077.93	2.41561
3080.49	1.41683
3083.05	1.08291
3085.61	0.346478
3088.16	0.362796
3090.72	0.136267
3093.27	1.01565
3095.83	2.02987
3098.38	4.3737
3100.94	6.37007
3103.49	8.4891
3106.04	9.91746
3108.59	11.5987
3111.14	13.3787
3113.69	14.4256
3116.23	15.473
3118.78	18.0049
3121.33	19.5167
3123.87	22.4727
3126.42	25.9396
3128.96	28.6148
3131.5	31.7625
3134.04	34.8314
3136.58	37.8984
3139.12	40.8192
3141.66	45.4546
3144.2	50.5993
3146.74	57.7584
3149.27	67.9897