File: data/Raman/poly_smoothed/Mb_50_18_16_1x_45s_532 nm_x100_100%_600 gr_mm_01.txt
#Acq. time (s)=	45
#Accumulations=	2
#Range (cm-¹)=	200...3150
#Windows=	2
#Auto scanning=	Off
#Autofocus=	Off
#Macrospot=	Off
#AutoExposure=	Off
#Spike filter=	Multiple accum.
#Delay time (s)=	0
#Binning=	1
#Readout mode=	Signal
#DeNoise=	Off
#ICS correction=	On
#Dark correction=	Off
#Inst. Process=	Off
#Detector Gain=	Best Dynamic Range
#Detector ADC=	20 kHz
#Detector temperature (°C)=	-69.85
#Instrument=	LabRAM HR Evol
#Detector=	Synapse
#Objective=	x100
#Grating=	600 gr/mm
#ND Filter=	100%
#Laser (nm)=	532
#Hole=	100.021
#Range=	Auto
#Laser Pol.=	No
#Raman. Pol.=	No
#Laser Pol. (°)=	-0.0007625
#Raman Pol. (°)=	89.9995
#Collection=	Microscope
#StageXY=	Marzhauser
#StageZ=	Marzhauser
#X (µm)=	19284.1
#Y (µm)=	3048.4
#Z (µm)=	1047.7
#Full time(mm:ss)=	3:18
#Project=
#Sample=
#Site=
#Title=	Mb_50_18_16_2x_45s_532 nm_x100_100%_600 gr_mm
#Remark=
#Date=	12.07.2022 11:24
#Acquired=	12.07.2022 11:24:49
#Base:Fit=	10.08.2022 10:49:18
#Base:Sub=	10.08.2022 10:49:30
#Filter:Polynom=	16.08.2022 10:14:59
#AxisType[0]=Intens
#AxisUnit[0]=Cnt
#AxisType[1]=Spectr
#AxisUnit[1]=1/cm
200.388	18.7213
204.019	19.3925
207.646	17.2447
211.274	15.8125
214.899	13.2793
218.524	12.4197
222.146	10.8457
225.766	8.35492
229.388	6.49524
233.005	6.04786
236.621	6.31668
240.236	4.95092
243.852	4.00264
247.464	3.37928
251.074	4.69681
254.683	2.8373
258.291	1.62251
261.897	0.805501
265.504	2.53064
269.108	2.98679
272.71	4.38743
276.311	3.90958
279.91	4.6659
283.508	5.47935
287.105	5.62957
290.698	6.33096
294.291	7.78405
297.884	9.7782
301.475	9.70558
305.064	10.5412
308.652	12.8643
312.237	12.6754
315.822	12.8417
319.406	14.8276
322.987	17.7807
326.568	16.1171
330.148	16.0119
333.724	16.7982
337.301	16.7549
340.875	15.7483
344.449	12.4554
348.02	12.4201
351.592	14.1422
355.16	16.7494
358.728	17.8689
362.294	18.34
365.858	18.8249
369.422	20.288
372.983	22.4306
376.543	24.8386
380.102	26.0132
383.661	26.8674
387.216	28.329
390.771	29.4327
394.324	29.4341
397.875	28.9344
401.425	27.5638
404.974	27.3736
408.524	28.0372
412.07	26.6583
415.614	22.545
419.156	22.75
422.698	19.0296
426.238	15.2326
429.777	14.5353
433.315	13.3792
436.852	14.7053
440.387	14.8352
443.919	12.6965
447.451	10.8193
450.982	10.8051
454.512	12.941
458.038	14.4798
461.565	15.7648
465.091	18.3696
468.613	20.9576
472.136	22.5459
475.655	23.0458
479.176	24.781
482.692	27.9304
486.21	31.882
489.724	35.9983
493.237	39.4465
496.75	40.9029
500.26	41.4896
503.771	42.4092
507.279	41.9126
510.785	41.0759
514.289	40.3041
517.793	37.7239
521.297	38.4965
524.797	37.3148
528.297	33.9939
531.795	32.617
535.291	30.2386
538.787	28.722
542.281	24.4523
545.773	21.8425
549.264	20.6773
552.754	17.505
556.243	15.2692
559.73	11.9671
563.216	12.4281
566.701	11.2979
570.182	12.2692
573.664	9.58946
577.145	7.75531
580.624	5.6385
584.1	5.96311
587.577	3.86595
591.052	1.77053
594.524	1.95909
597.997	0.625282
601.466	2.62751
604.936	3.51218
608.403	6.22277
611.87	7.96993
615.334	9.42475
618.799	10.1595
622.26	10.266
625.72	12.2016
629.181	11.7004
632.638	13.5025
636.095	13.0021
639.551	13.3105
643.005	13.7218
646.457	13.5469
649.908	13.9232
653.357	12.8127
656.806	13.0571
660.253	12.1405
663.7	12.8155
667.145	13.2837
670.588	13.6273
674.027	13.4852
677.468	15.8835
680.907	19.4094
684.345	23.0683
687.781	25.3565
691.216	26.5724
694.65	28.5244
698.081	29.8093
701.512	32.6244
704.942	34.6951
708.371	35.4534
711.796	36.755
715.222	39.6126
718.645	40.8935
722.068	41.6509
725.49	42.5421
728.909	43.6791
732.329	46.1769
735.745	47.0241
739.16	49.6836
742.576	53.6418
745.988	57.8324
749.401	61.7771
752.811	67.5873
756.22	72.3327
759.627	75.4914
763.035	79.2216
766.44	81.6619
769.843	82.3231
773.245	83.2783
776.646	84.1253
780.046	85.254
783.444	86.3223
786.841	88.5952
790.237	87.9313
793.631	86.9224
797.024	87.4576
800.416	86.8315
803.807	85.1219
807.196	84.062
810.584	82.6875
813.971	82.7414
817.354	82.9479
820.739	83.6676
824.122	84.518
827.503	84.8051
830.882	86.0397
834.261	84.3682
837.637	82.8328
841.013	80.6977
844.389	76.412
847.761	75.0858
851.131	73.8452
854.503	71.2289
857.871	70.173
861.24	67.7629
864.606	67.1862
867.97	65.0572
871.336	62.2218
874.698	60.6541
878.058	58.3971
881.418	58.0767
884.778	56.7889
888.135	56.3294
891.49	55.4682
894.845	54.5441
898.198	53.9667
901.55	51.3019
904.901	49.034
908.25	48.8074
911.598	47.5442
914.945	46.2647
918.291	44.6743
921.635	43.6392
924.978	41.9781
928.318	40.449
931.659	39.4731
934.998	36.6595
938.336	36.7868
941.671	36.2668
945.007	34.1807
948.339	33.2134
951.672	31.6247
955.004	30.6936
958.333	29.709
961.662	28.0867
964.989	29.3652
968.315	28.9934
971.639	29.078
974.962	29.3083
978.285	27.6316
981.605	25.7871
984.924	24.9572
988.243	25.4281
991.56	26.3397
994.875	26.9278
998.188	27.1638
1001.5	29.4787
1004.81	31.015
1008.12	31.9645
1011.43	32.8199
1014.74	34.6675
1018.05	39.391
1021.35	39.5909
1024.65	40.8055
1027.96	41.0303
1031.26	41.2494
1034.56	40.5563
1037.86	41.1858
1041.16	41.6502
1044.45	41.8187
1047.75	41.6214
1051.04	40.2193
1054.33	38.8213
1057.62	37.4075
1060.91	35.4459
1064.2	33.0761
1067.49	30.8357
1070.77	29.228
1074.06	27.4049
1077.34	28.1903
1080.62	27.7048
1083.91	28.1842
1087.18	27.9735
1090.46	27.8149
1093.74	29.9556
1097.02	29.3886
1100.29	28.8287
1103.56	28.9347
1106.84	27.9982
1110.11	27.0544
1113.38	26.4682
1116.64	25.6649
1119.91	23.8579
1123.18	22.6675
1126.44	21.6333
1129.7	19.838
1132.97	18.1486
1136.23	16.7396
1139.49	14.6497
1142.74	11.0203
1146	8.88585
1149.26	7.0897
1152.51	6.18884
1155.76	4.7399
1159.01	2.66365
1162.27	3.18454
1165.51	2.23733
1168.76	1.62001
1172.01	2.90726
1175.25	1.84297
1178.5	1.72325
1181.74	1.24607
1184.98	0.706362
1188.22	0.557424
1191.46	0.618048
1194.7	1.53556
1197.94	2.00363
1201.17	3.31068
1204.41	5.00436
1207.64	6.16682
1210.87	7.39691
1214.1	9.95369
1217.33	14.0358
1220.56	15.9371
1223.79	17.8611
1227.01	21.9518
1230.23	24.3041
1233.46	28.3069
1236.68	30.5947
1239.9	33.4722
1243.12	35.4432
1246.34	37.0474
1249.55	40.1639
1252.77	41.9097
1255.98	43.8363
1259.2	45.6614
1262.41	48.917
1265.62	51.7261
1268.83	55.5578
1272.03	57.8343
1275.24	61.4823
1278.45	64.8572
1281.65	66.9879
1284.85	68.0338
1288.06	70.2988
1291.26	72.4632
1294.46	74.0565
1297.66	73.3533
1300.85	73.4595
1304.05	74.6814
1307.24	74.5169
1310.43	75.5659
1313.63	74.9733
1316.82	73.1692
1320.01	71.7284
1323.2	70.2963
1326.38	69.9541
1329.57	68.7912
1332.76	67.2224
1335.94	64.4102
1339.12	63.55
1342.3	60.7977
1345.48	59.9855
1348.66	58.9068
1351.84	56.6284
1355.01	55.1845
1358.19	51.7199
1361.36	47.6408
1364.53	44.8149
1367.71	41.0273
1370.88	38.2669
1374.04	34.7988
1377.21	33.4667
1380.38	31.9003
1383.54	29.3496
1386.71	27.0348
1389.87	25.7834
1393.03	23.328
1396.19	21.4472
1399.35	20.1131
1402.51	19.7423
1405.67	20.1588
1408.82	19.5115
1411.98	21.3252
1415.13	25.5557
1418.28	29.9667
1421.43	36.14
1424.58	43.5927
1427.73	50.6988
1430.88	57.1465
1434.02	62.5429
1437.17	66.1948
1440.31	71.2413
1443.45	76.4497
1446.6	79.2943
1449.74	81.3387
1452.87	81.9816
1456.01	83.1418
1459.15	82.416
1462.28	80.0141
1465.42	78.3974
1468.55	74.261
1471.68	68.7309
1474.81	65.1614
1477.94	61.3875
1481.07	57.3576
1484.2	53.7297
1487.32	50.3387
1490.45	46.9878
1493.57	43.9503
1496.69	39.8396
1499.81	38.0044
1502.93	34.6513
1506.05	33.3441
1509.17	29.4043
1512.28	26.4019
1515.4	22.8294
1518.51	21.4429
1521.63	18.8833
1524.74	16.0296
1527.85	15.6562
1530.96	14.5408
1534.06	15.0749
1537.17	15.2056
1540.28	15.5514
1543.38	16.6299
1546.48	17.9336
1549.59	19.413
1552.69	22.1645
1555.79	24.2639
1558.88	24.6385
1561.98	25.167
1565.08	27.1794
1568.17	30.3045
1571.27	34.4341
1574.36	36.8288
1577.45	39.9876
1580.54	43.8163
1583.63	45.8256
1586.72	48.006
1589.8	50.3562
1592.89	52.5144
1595.97	53.0365
1599.06	53.5576
1602.14	55.7659
1605.22	56.5683
1608.3	56.9103
1611.38	58.9827
1614.46	59.3405
1617.53	61.4967
1620.61	62.1435
1623.68	63.4704
1626.75	64.3107
1629.82	65.7189
1632.9	66.6503
1635.96	68.417
1639.03	70.5108
1642.1	74.7366
1645.16	78.5678
1648.23	80.2951
1651.29	82.1793
1654.36	83.1384
1657.42	83.4016
1660.48	81.7219
1663.53	78.9641
1666.59	75.9778
1669.65	72.5966
1672.7	67.9193
1675.76	64.5016
1678.81	60.2683
1681.86	54.0767
1684.91	48.5198
1687.96	44.0819
1691.01	38.0241
1694.06	32.7072
1697.11	27.9738
1700.15	24.7732
1703.2	21.3573
1706.24	17.9709
1709.28	16.0945
1712.32	14.6916
1715.36	15.0803
1718.4	14.6194
1721.43	14.6639
1724.47	14.4862
1727.5	13.3908
1730.54	11.6089
1733.57	10.1238
1736.6	8.92875
1739.63	9.11683
1742.66	8.93212
1745.69	7.98299
1748.72	7.53392
1751.74	6.40299
1754.77	5.13864
1757.79	5.26005
1760.81	4.47317
1763.83	5.04544
1766.85	4.78363
1769.87	3.96472
1772.89	3.93614
1775.91	3.40591
1778.92	2.91602
1781.94	2.08282
1784.95	2.68829
1787.96	2.94465
1790.97	2.51629
1793.98	2.31314
1796.99	1.90794
1800	1.14783
1803	0.636284
1806.01	1.19144
1809.01	0.543188
1812.02	1.16994
1815.02	0.880946
1818.02	0.229237
1821.02	0.223191
1824.02	0.708611
1827.01	0.892007
1830.01	2.04723
1833	2.29412
1836	2.70905
1838.99	2.95743
1841.98	3.20839
1844.97	2.56617
1847.96	3.10471
1850.95	3.38765
1853.94	3.24972
1856.92	3.74252
1859.91	3.46822
1862.89	4.39138
1865.88	4.14912
1868.86	4.58562
1871.84	5.26262
1874.82	5.40842
1877.8	5.52228
1880.77	4.55223
1882.51	4.38376
1885.5	5.0434
1888.48	5.26367
1891.47	5.21355
1894.46	5.13546
1897.44	4.83863
1900.42	4.93007
1903.41	4.71866
1906.39	4.82654
1909.37	4.67179
1912.35	4.05652
1915.32	3.03845
1918.3	2.89253
1921.28	3.56319
1924.25	2.72941
1927.22	2.60997
1930.2	2.71703
1933.17	3.67574
1936.14	4.14161
1939.11	4.06648
1942.08	3.76231
1945.04	3.54856
1948.01	3.33952
1950.97	3.2966
1953.94	3.53188
1956.9	4.13262
1959.86	4.43345
1962.82	4.42981
1965.78	5.08609
1968.74	5.08937
1971.69	5.66113
1974.65	5.95232
1977.61	6.28885
1980.56	5.60972
1983.51	5.08842
1986.46	4.28004
1989.41	4.72189
1992.36	5.99643
1995.31	6.23708
1998.26	6.95097
2001.2	7.61257
2004.15	9.29232
2007.09	9.76515
2010.04	9.03428
2012.98	9.31778
2015.92	10.0704
2018.86	11.3069
2021.8	12.2045
2024.74	11.3463
2027.67	11.4521
2030.61	11.4177
2033.54	11.8468
2036.47	12.3243
2039.41	12.9265
2042.34	13.8989
2045.27	15.121
2048.2	14.3308
2051.12	14.6278
2054.05	15.7435
2056.98	16.4302
2059.9	17.9995
2062.82	19.6854
2065.75	21.7613
2068.67	22.3595
2071.59	25.0278
2074.51	26.5537
2077.43	28.2226
2080.34	30.2131
2083.26	32.4803
2086.17	36.3083
2089.09	38.5512
2092	41.0446
2094.91	43.5621
2097.82	46.7841
2100.73	49.0517
2103.64	52.5713
2106.55	56.3257
2109.46	59.9652
2112.36	64.3104
2115.27	67.6505
2118.17	71.4406
2121.07	75.5195
2123.97	80.582
2126.87	85.2701
2129.77	89.2704
2132.67	92.6404
2135.57	96.8279
2138.46	100.617
2141.36	104.582
2144.25	108.34
2147.14	111.337
2150.03	114.701
2152.92	118.25
2155.81	120.505
2158.7	121.815
2161.59	123.691
2164.48	125.251
2167.36	125.495
2170.25	125.086
2173.13	125.225
2176.01	124.652
2178.89	122.897
2181.77	119.991
2184.65	116.869
2187.53	114.595
2190.41	112.201
2193.28	108.655
2196.16	105.664
2199.03	101.335
2201.9	97.36
2204.78	93.7643
2207.65	89.8707
2210.51	87.2079
2213.38	83.2452
2216.25	79.787
2219.12	75.2346
2221.98	72.1833
2224.85	68.3777
2227.71	64.6372
2230.57	60.8787
2233.43	57.8678
2236.29	53.9252
2239.15	50.0436
2242.01	47.0829
2244.87	43.4497
2247.73	38.9636
2250.58	34.9831
2253.43	31.4299
2256.29	28.3034
2259.14	25.8285
2261.99	24.1203
2264.84	22.1172
2267.69	20.7778
2270.54	20.8941
2273.38	19.8599
2276.23	19.8873
2279.07	18.1111
2281.92	16.9226
2284.76	15.7824
2287.6	14.4445
2290.44	13.4151
2293.28	11.6074
2296.12	10.4492
2298.96	10.8996
2301.79	11.286
2304.63	10.4817
2307.46	10.3231
2310.3	9.18294
2313.13	8.83328
2315.96	8.17426
2318.79	7.16665
2321.62	5.5113
2324.45	5.95292
2327.27	5.56406
2330.1	6.34676
2332.93	5.9194
2335.75	5.5857
2338.57	6.25346
2341.4	5.24883
2344.22	5.50583
2347.04	3.63313
2349.86	2.33157
2352.67	1.56248
2355.49	1.27208
2358.31	0.88449
2361.12	0.64169
2363.94	1.15642
2366.75	1.49688
2369.56	3.91556
2372.37	5.32758
2375.18	5.16684
2377.99	4.7718
2380.8	4.7136
2383.61	4.88824
2386.41	5.01463
2389.22	4.80354
2392.02	4.91814
2394.82	4.37017
2397.63	4.46641
2400.43	4.25604
2403.23	4.43331
2406.02	4.49246
2408.82	3.94637
2411.62	4.0246
2414.41	2.41267
2417.21	1.48679
2420	1.52295
2422.79	0.966276
2425.59	1.04822
2428.38	0.584784
2431.17	1.92857
2433.96	2.3232
2436.74	2.60772
2439.53	3.64951
2442.32	3.77884
2445.1	4.15105
2447.88	3.42884
2450.67	3.75423
2453.45	5.27449
2456.23	6.30443
2459.01	5.0579
2461.79	5.22861
2464.57	4.53919
2467.34	5.04028
2470.12	4.7564
2472.89	4.41838
2475.67	4.23638
2478.44	3.38202
2481.21	1.16797
2483.98	0.563524
2486.75	-0.258913
2489.52	-0.248939
2492.29	0.355837
2495.06	0.275372
2497.82	0.629563
2500.59	1.16083
2503.35	1.30038
2506.11	1.31505
2508.88	2.15025
2511.63	2.45582
2514.39	2.91939
2517.15	3.50097
2519.91	4.54506
2522.67	4.88663
2525.42	4.20807
2528.18	4.56306
2530.93	4.85151
2533.69	4.77029
2536.44	4.81857
2539.19	5.46697
2541.94	5.11408
2544.69	4.13227
2547.44	3.88467
2550.18	3.19543
2552.93	2.93078
2555.68	3.39276
2558.42	4.24199
2561.16	4.84447
2563.9	4.52789
2566.64	5.25797
2569.38	5.24953
2572.12	4.49793
2574.86	4.73026
2577.6	5.0498
2580.34	4.6034
2583.07	4.95689
2585.81	4.48955
2588.54	5.25339
2591.27	5.35545
2594	6.48979
2596.73	6.75523
2599.46	5.98379
2602.19	6.44445
2604.92	6.20827
2607.64	5.72727
2610.37	4.72502
2613.09	4.48525
2615.82	4.72714
2618.54	5.18441
2621.26	6.30521
2623.98	7.47416
2626.7	8.12156
2629.42	8.12781
2632.14	7.83295
2634.86	7.61035
2637.57	7.02059
2640.29	7.14914
2643	7.04646
2645.72	6.80892
2648.43	6.24462
2651.14	7.15094
2653.85	7.29827
2656.56	7.83911
2659.27	7.80765
2661.97	7.95861
2664.68	8.19216
2667.38	7.77043
2670.09	6.38155
2672.79	5.56473
2675.49	5.25922
2678.2	4.97121
2680.89	5.23496
2683.59	4.8364
2686.29	5.27245
2688.99	5.8721
2691.69	5.86831
2694.38	5.02309
2697.08	5.91188
2699.77	6.04048
2702.46	6.22465
2705.16	6.51908
2707.85	7.33315
2710.54	7.31643
2713.23	7.8934
2715.92	8.08425
2718.6	8.51099
2721.29	9.26938
2723.97	9.48922
2726.66	10.2176
2729.34	10.6001
2732.02	10.0766
2734.7	8.98539
2737.39	8.9676
2740.06	8.51649
2742.74	7.80726
2745.42	7.92947
2748.1	8.22754
2750.77	7.63696
2753.45	7.26614
2756.12	7.31964
2758.79	6.74491
2761.47	7.07274
2764.14	6.61475
2766.81	5.49158
2769.48	4.99494
2772.14	4.27052
2774.81	3.59463
2777.48	1.99457
2780.14	1.61939
2782.81	1.33932
2785.47	0.761835
2788.13	-0.306579
2790.79	-0.939704
2793.46	0.594694
2796.11	-0.0974071
2798.77	-0.446919
2801.43	-0.584648
2804.09	0.0518423
2806.74	-0.506729
2809.4	-0.0500846
2812.05	0.910294
2814.71	1.93554
2817.36	3.27408
2820.01	5.60878
2822.66	9.96492
2825.31	14.4496
2827.96	19.8442
2830.61	26.0432
2833.25	33.0952
2835.9	39.5323
2838.54	46.9962
2841.18	55.1168
2843.83	63.0634
2846.47	71.9885
2849.11	81.9581
2851.75	91.0852
2854.39	100.69
2857.03	109.738
2859.67	117.521
2862.3	124.214
2864.94	130.251
2867.57	135.177
2870.21	140.459
2872.84	144.678
2875.47	148.397
2878.1	151.967
2880.73	155.263
2883.36	158.285
2885.99	162.974
2888.61	168.373
2891.24	172.679
2893.87	177.259
2896.49	183.496
2899.11	189.886
2901.74	197.339
2904.36	205.862
2906.98	215.188
2909.6	225.482
2912.22	235.419
2914.83	245.788
2917.45	254.786
2920.07	262.677
2922.68	267.402
2925.3	272.608
2927.91	276.62
2930.52	277.912
2933.13	278.258
2935.74	277.27
2938.35	273.213
2940.96	267.756
2943.57	260.892
2946.18	251.456
2948.78	242.443
2951.39	231.976
2953.99	220.961
2956.6	209.156
2959.2	198.767
2961.8	188.332
2964.4	178.682
2967	167.743
2969.6	157.747
2972.2	147.731
2974.79	137.827
2977.39	126.777
2979.98	116.395
2982.58	105.886
2985.17	94.6014
2987.76	84.7026
2990.36	76.1305
2992.95	66.9414
2995.54	58.5232
2998.12	50.6057
3000.71	44.0016
3003.3	36.3248
3005.88	30.4423
3008.47	24.2877
3011.05	19.7251
3013.64	16.0633
3016.22	12.1977
3018.8	9.91133
3021.38	8.30598
3023.96	6.96072
3026.54	5.37539
3029.12	5.21381
3031.69	3.80208
3034.27	3.52551
3036.85	2.95102
3039.42	2.57669
3041.99	3.84284
3044.57	3.58809
3047.14	4.4265
3049.71	5.44785
3052.28	6.63913
3054.85	7.33557
3057.42	8.33451
3059.98	9.49305
3062.55	8.83439
3065.11	9.4693
3067.68	9.57108
3070.24	9.64126
3072.8	9.50716
3075.37	9.05355
3077.93	7.8289
3080.49	6.63981
3083.05	4.94743
3085.61	3.21473
3088.16	2.14035
3090.72	0.899451
3093.27	0.97814
3095.83	0.574198
3098.38	0.67865
3100.94	1.22777
3103.49	1.20437
3106.04	1.79777
3108.59	1.71622
3111.14	2.84124
3113.69	3.35866
3116.23	3.85675
3118.78	5.36625
3121.33	6.32136
3123.87	7.13531
3126.42	8.45805
3128.96	9.8642
3131.5	11.9129
3134.04	13.0099
3136.58	14.399
3139.12	15.6169
3141.66	17.5436
3144.2	19.4265
3146.74	22.5508
3149.27	25.2681