File: data/Raman/poly_smoothed/Mb_50_18_38_2x_45s_532 nm_x100_100%_600 gr_mm.txt
#Acq. time (s)=	45
#Accumulations=	2
#Range (cm-¹)=	200...3150
#Windows=	2
#Auto scanning=	Off
#Autofocus=	Off
#Macrospot=	Off
#AutoExposure=	Off
#Spike filter=	Multiple accum.
#Delay time (s)=	0
#Binning=	1
#Readout mode=	Signal
#DeNoise=	Off
#ICS correction=	On
#Dark correction=	Off
#Inst. Process=	Off
#Detector Gain=	Best Dynamic Range
#Detector ADC=	20 kHz
#Detector temperature (°C)=	-69.85
#Instrument=	LabRAM HR Evol
#Detector=	Synapse
#Objective=	x100
#Grating=	600 gr/mm
#ND Filter=	100%
#Laser (nm)=	532
#Hole=	100.021
#Range=	Auto
#Laser Pol.=	No
#Raman. Pol.=	No
#Laser Pol. (°)=	-0.0007625
#Raman Pol. (°)=	89.9995
#Collection=	Microscope
#StageXY=	Marzhauser
#StageZ=	Marzhauser
#X (µm)=	28252.7
#Y (µm)=	-3213.6
#Z (µm)=	1041.3
#Full time(mm:ss)=	2:52
#Project=
#Sample=
#Site=
#Title=	Mb_50_18_38_2x_45s_532 nm_x100_100%_600 gr_mm
#Remark=
#Date=	12.07.2022 13:50
#Acquired=	12.07.2022 13:50:27
#Base:Fit=	10.08.2022 10:49:18
#Base:Sub=	10.08.2022 10:49:30
#Filter:Polynom=	16.08.2022 10:14:59
#AxisType[0]=Intens
#AxisUnit[0]=Cnt
#AxisType[1]=Spectr
#AxisUnit[1]=1/cm
200.388	149.38
204.019	123.655
207.646	108.945
211.274	98.2817
214.899	88.9702
218.524	82.437
222.146	76.8755
225.766	71.8142
229.388	65.0318
233.005	59.7454
236.621	54.3005
240.236	44.8567
243.852	39.4595
247.464	37.8126
251.074	33.5746
254.683	28.9459
258.291	24.6318
261.897	21.6205
265.504	17.5781
269.108	15.135
272.71	6.72859
276.311	3.86337
279.91	0.0765483
283.508	-2.81238
287.105	0.724139
290.698	4.1162
294.291	8.19053
297.884	12.2577
301.475	17.7136
305.064	24.0798
308.652	31.4943
312.237	37.1779
315.822	42.5263
319.406	47.991
322.987	53.7248
326.568	57.1116
330.148	59.9781
333.724	64.4766
337.301	70.1514
340.875	66.1534
344.449	68.4686
348.02	73.1013
351.592	81.4009
355.16	86.0306
358.728	91.8494
362.294	97.2533
365.858	105.813
369.422	114.282
372.983	125.049
376.543	133.857
380.102	138.551
383.661	150.421
387.216	162.218
390.771	170.878
394.324	179.034
397.875	184.35
401.425	186.147
404.974	189.68
408.524	189.14
412.07	184.196
415.614	179.148
419.156	174.739
422.698	167.01
426.238	159.187
429.777	155.34
433.315	152.935
436.852	152.519
440.387	149.074
443.919	146.735
447.451	144.97
450.982	143.481
454.512	142.755
458.038	143.833
461.565	141.316
465.091	143.216
468.613	146.517
472.136	152.178
475.655	156.452
479.176	154.497
482.692	156.606
486.21	156.545
489.724	158.488
493.237	158.294
496.75	157.292
500.26	156.584
503.771	156.294
507.279	151.83
510.785	147.568
514.289	146.87
517.793	143.64
521.297	138.414
524.797	132.756
528.297	125.676
531.795	117.828
535.291	110.634
538.787	100.546
542.281	90.1807
545.773	81.9868
549.264	73.1851
552.754	65.5022
556.243	57.4919
559.73	48.1418
563.216	41.5943
566.701	37.6711
570.182	36.9936
573.664	33.9699
577.145	37.8443
580.624	35.4254
584.1	36.5335
587.577	36.4949
591.052	36.5314
594.524	37.116
597.997	37.9045
601.466	35.1652
604.936	35.0534
608.403	31.0255
611.87	29.5425
615.334	28.0408
618.799	23.7268
622.26	18.1309
625.72	15.1214
629.181	13.3048
632.638	9.73103
636.095	5.53827
639.551	2.73662
643.005	1.58633
646.457	0.325905
649.908	1.60328
653.357	-0.81078
656.806	-2.15712
660.253	0.298765
663.7	-0.911266
667.145	-0.459465
670.588	3.21247
674.027	3.25994
677.468	4.98465
680.907	5.76839
684.345	6.20792
687.781	6.54228
691.216	6.67832
694.65	7.37204
698.081	9.49812
701.512	9.70642
704.942	9.60078
708.371	10.3448
711.796	12.4951
715.222	10.1945
718.645	9.07629
722.068	12.035
725.49	12.0695
728.909	12.4222
732.329	15.5868
735.745	16.9085
739.16	24.9675
742.576	38.116
745.988	49.7924
749.401	61.4119
752.811	74.2381
756.22	86.3448
759.627	97.0663
763.035	105.774
766.44	113.453
769.843	121.094
773.245	125.469
776.646	127.095
780.046	128.592
783.444	129.045
786.841	126.843
790.237	124.468
793.631	112.065
797.024	105.996
800.416	99.4453
803.807	88.2465
807.196	78.7675
810.584	71.0417
813.971	65.3008
817.354	62.3908
820.739	57.6955
824.122	57.0741
827.503	53.5715
830.882	53.7684
834.261	53.8417
837.637	53.5994
841.013	54.5785
844.389	52.657
847.761	49.9713
851.131	50.491
854.503	50.4058
857.871	47.4107
861.24	46.93
864.606	49.3758
867.97	50.5395
871.336	48.7926
874.698	48.2906
878.058	47.3501
881.418	47.893
884.778	46.197
888.135	45.9027
891.49	48.4816
894.845	52.7094
898.198	53.8116
901.55	56.1406
904.901	58.3396
908.25	63.018
911.598	66.8158
914.945	71.0132
918.291	71.1679
921.635	72.6295
924.978	73.5023
928.318	73.4425
931.659	73.8
934.998	71.7938
938.336	71.1792
941.671	68.7819
945.007	64.7936
948.339	59.6781
951.672	55.1525
955.004	50.5433
958.333	45.6441
961.662	38.2846
964.989	32.4637
968.315	28.161
971.639	25.9814
974.962	24.7987
978.285	24.3029
981.605	24.0241
984.924	24.1844
988.243	25.1915
991.56	24.4706
994.875	22.2538
998.188	28.4427
1001.5	36.6285
1004.81	46.7108
1008.12	52.1456
1011.43	60.2528
1014.74	67.926
1018.05	74.7959
1021.35	78.4662
1024.65	80.55
1027.96	82.1204
1031.26	83.7868
1034.56	87.7157
1037.86	85.1278
1041.16	80.2
1044.45	77.5273
1047.75	73.6951
1051.04	68.8299
1054.33	68.4673
1057.62	66.5912
1060.91	64.0442
1064.2	62.6276
1067.49	60.2573
1070.77	57.4251
1074.06	57.1275
1077.34	59.8334
1080.62	60.3892
1083.91	61.3164
1087.18	59.6757
1090.46	57.7876
1093.74	57.2852
1097.02	55.3835
1100.29	50.9802
1103.56	50.0344
1106.84	48.3911
1110.11	41.6182
1113.38	37.6902
1116.64	33.2667
1119.91	26.9063
1123.18	21.3151
1126.44	15.0819
1129.7	12.1579
1132.97	11.2574
1136.23	10.8724
1139.49	9.80025
1142.74	8.62977
1146	7.1859
1149.26	6.05138
1152.51	4.765
1155.76	7.05327
1159.01	6.98836
1162.27	10.8705
1165.51	12.8506
1168.76	15.9568
1172.01	17.3489
1175.25	21.8069
1178.5	22.5786
1181.74	22.4068
1184.98	26.0343
1188.22	30.0855
1191.46	32.2477
1194.7	34.412
1197.94	32.6956
1201.17	29.2542
1204.41	30.383
1207.64	31.7386
1210.87	30.6802
1214.1	30.5047
1217.33	31.096
1220.56	30.3883
1223.79	31.9057
1227.01	34.0644
1230.23	33.0588
1233.46	34.1545
1236.68	36.9205
1239.9	38.7327
1243.12	38.9965
1246.34	39.4638
1249.55	38.6721
1252.77	38.3176
1255.98	39.9551
1259.2	42.2389
1262.41	48.7622
1265.62	50.5663
1268.83	53.0806
1272.03	56.9706
1275.24	58.5167
1278.45	63.1296
1281.65	68.9792
1284.85	75.6541
1288.06	76.208
1291.26	78.6575
1294.46	82.9891
1297.66	84.8885
1300.85	90.2557
1304.05	92.2643
1307.24	96.3061
1310.43	98.2074
1313.63	103.376
1316.82	104.376
1320.01	104.803
1323.2	106.6
1326.38	107.678
1329.57	110.654
1332.76	110.724
1335.94	113.715
1339.12	117.424
1342.3	115.574
1345.48	117.409
1348.66	123.531
1351.84	125.748
1355.01	126.81
1358.19	129.109
1361.36	130.145
1364.53	129.33
1367.71	128.466
1370.88	129.939
1374.04	130.091
1377.21	127.484
1380.38	129.249
1383.54	128.789
1386.71	125.835
1389.87	123.495
1393.03	122.141
1396.19	119.49
1399.35	119.888
1402.51	118.677
1405.67	116.702
1408.82	115.279
1411.98	118.22
1415.13	120.498
1418.28	122.282
1421.43	126.953
1424.58	133.975
1427.73	139.361
1430.88	144.588
1434.02	149.591
1437.17	153.98
1440.31	159.676
1443.45	162.246
1446.6	164.161
1449.74	157.904
1452.87	157.267
1456.01	156.134
1459.15	152.286
1462.28	145.956
1465.42	142.677
1468.55	135.156
1471.68	126.457
1474.81	119.593
1477.94	111.476
1481.07	103.501
1484.2	95.458
1487.32	87.887
1490.45	83.4813
1493.57	76.105
1496.69	74.6004
1499.81	71.6137
1502.93	67.0831
1506.05	69.0341
1509.17	68.8187
1512.28	70.3127
1515.4	74.6975
1518.51	76.19
1521.63	78.0715
1524.74	82.9622
1527.85	86.299
1530.96	90.8418
1534.06	94.2793
1537.17	101.291
1540.28	106.546
1543.38	109.518
1546.48	112.976
1549.59	117.876
1552.69	120.459
1555.79	123.973
1558.88	129.844
1561.98	133.566
1565.08	136.746
1568.17	140.982
1571.27	142.303
1574.36	145.665
1577.45	147.382
1580.54	152.079
1583.63	157.494
1586.72	161.243
1589.8	162.264
1592.89	162.626
1595.97	161.111
1599.06	164.467
1602.14	162.175
1605.22	158.559
1608.3	153.83
1611.38	151.74
1614.46	149.009
1617.53	144.511
1620.61	138.78
1623.68	132.517
1626.75	126.533
1629.82	119.366
1632.9	112.979
1635.96	108.908
1639.03	98.5693
1642.1	90.1634
1645.16	83.9746
1648.23	77.1141
1651.29	70.9447
1654.36	63.9567
1657.42	58.0136
1660.48	52.6949
1663.53	46.3474
1666.59	40.8354
1669.65	37.0318
1672.7	36.4047
1675.76	33.9696
1678.81	29.7254
1681.86	29.799
1684.91	29.8322
1687.96	30.3091
1691.01	30.7707
1694.06	28.2372
1697.11	28.9398
1700.15	26.8982
1703.2	25.6104
1706.24	27.7601
1709.28	23.7583
1712.32	21.9755
1715.36	20.6066
1718.4	18.8942
1721.43	18.0609
1724.47	16.4301
1727.5	15.8726
1730.54	12.0691
1733.57	11.5362
1736.6	11.0444
1739.63	11.6492
1742.66	10.3138
1745.69	11.8567
1748.72	12.052
1751.74	12.9108
1754.77	15.3582
1757.79	15.912
1760.81	16.3458
1763.83	16.6154
1766.85	15.8897
1769.87	14.2478
1772.89	15.1794
1775.91	13.8404
1778.92	16.3031
1781.94	14.9303
1784.95	14.8133
1787.96	15.674
1790.97	16.2226
1793.98	16.3748
1796.99	15.9139
1800	15.3569
1803	12.4919
1806.01	9.80238
1809.01	7.98778
1812.02	4.85938
1815.02	2.4228
1818.02	0.562546
1821.02	0.905133
1824.02	1.57463
1827.01	1.33117
1830.01	1.20023
1833	2.71296
1836	2.53237
1838.99	5.38096
1841.98	5.1453
1844.97	5.91236
1847.96	9.61867
1850.95	12.1133
1853.94	13.2068
1856.92	13.1884
1859.91	14.425
1862.89	14.8086
1865.88	16.5598
1868.86	15.7794
1871.84	15.8716
1874.82	18.8168
1877.8	18.8401
1880.77	18.8979
1882.51	19.0903
1885.5	18.1186
1888.48	20.248
1891.47	24.8917
1894.46	26.8384
1897.44	24.4482
1900.42	22.2487
1903.41	20.7317
1906.39	20.7011
1909.37	22.4827
1912.35	21.2379
1915.32	20.6668
1918.3	19.6633
1921.28	18.555
1924.25	14.5244
1927.22	14.4801
1930.2	11.1853
1933.17	13.0668
1936.14	11.9071
1939.11	10.723
1942.08	10.0528
1945.04	13.6065
1948.01	13.5618
1950.97	13.6031
1953.94	13.7
1956.9	11.6367
1959.86	12.6497
1962.82	11.1994
1965.78	8.05436
1968.74	7.23544
1971.69	5.44539
1974.65	6.23339
1977.61	7.74757
1980.56	10.4793
1983.51	11.9214
1986.46	17.5412
1989.41	19.0503
1992.36	18.6241
1995.31	18.8187
1998.26	18.7727
2001.2	18.1649
2004.15	21.2952
2007.09	20.5064
2010.04	22.2167
2012.98	23.096
2015.92	26.0414
2018.86	25.4121
2021.8	21.6509
2024.74	22.4829
2027.67	22.5363
2030.61	23.802
2033.54	24.1435
2036.47	21.1046
2039.41	22.0246
2042.34	22.8317
2045.27	23.3638
2048.2	24.6674
2051.12	26.075
2054.05	30.0294
2056.98	31.074
2059.9	31.3479
2062.82	29.7258
2065.75	27.4515
2068.67	27.6795
2071.59	28.6177
2074.51	28.9417
2077.43	26.9896
2080.34	28.0995
2083.26	29.0421
2086.17	31.0473
2089.09	29.5964
2092	31.0132
2094.91	29.3015
2097.82	28.3229
2100.73	27.6029
2103.64	26.3529
2106.55	26.4852
2109.46	23.2615
2112.36	20.1192
2115.27	18.0903
2118.17	19.6367
2121.07	18.8969
2123.97	19.1823
2126.87	18.166
2129.77	16.3425
2132.67	15.5588
2135.57	14.9683
2138.46	12.3577
2141.36	15.4513
2144.25	15.4833
2147.14	20.7465
2150.03	22.2161
2152.92	25.8497
2155.81	28.5677
2158.7	30.0192
2161.59	28.8703
2164.48	28.0007
2167.36	29.1012
2170.25	32.7099
2173.13	34.6182
2176.01	34.8021
2178.89	33.5947
2181.77	31.4196
2184.65	33.0017
2187.53	34.0466
2190.41	37.0746
2193.28	31.5516
2196.16	31.3405
2199.03	27.597
2201.9	26.6064
2204.78	27.231
2207.65	25.809
2210.51	25.5231
2213.38	27.1361
2216.25	29.322
2219.12	28.4397
2221.98	28.948
2224.85	32.1397
2227.71	31.8928
2230.57	29.8278
2233.43	31.5776
2236.29	37.0991
2239.15	38.3317
2242.01	38.8813
2244.87	37.6708
2247.73	40.0237
2250.58	39.7053
2253.43	41.3628
2256.29	43.3442
2259.14	42.4811
2261.99	42.9645
2264.84	39.6842
2267.69	39.4889
2270.54	40.1468
2273.38	39.0906
2276.23	39.8249
2279.07	35.7586
2281.92	33.5453
2284.76	36.0023
2287.6	34.4844
2290.44	34.3892
2293.28	35.4968
2296.12	37.6793
2298.96	36.7885
2301.79	37.4489
2304.63	40.9034
2307.46	43.4208
2310.3	44.6706
2313.13	44.8238
2315.96	46.0788
2318.79	47.3
2321.62	45.0519
2324.45	45.4779
2327.27	43.1168
2330.1	44.7757
2332.93	42.5868
2335.75	34.7106
2338.57	30.9648
2341.4	26.5845
2344.22	20.6341
2347.04	17.2037
2349.86	13.3192
2352.67	13.2211
2355.49	8.1233
2358.31	7.36506
2361.12	7.26846
2363.94	5.94528
2366.75	8.15727
2369.56	7.81399
2372.37	6.31311
2375.18	9.99035
2377.99	9.52368
2380.8	12.2546
2383.61	12.7594
2386.41	11.4267
2389.22	7.7899
2392.02	8.06026
2394.82	11.8823
2397.63	12.6139
2400.43	15.1074
2403.23	14.8089
2406.02	15.7311
2408.82	21.8571
2411.62	25.0001
2414.41	30.7902
2417.21	34.2701
2420	35.7253
2422.79	37.0082
2425.59	39.7111
2428.38	41.6986
2431.17	40.7064
2433.96	39.6607
2436.74	37.9918
2439.53	38.1499
2442.32	34.3872
2445.1	34.038
2447.88	28.4013
2450.67	23.4832
2453.45	19.6758
2456.23	15.6142
2459.01	15.5081
2461.79	17.5352
2464.57	15.1344
2467.34	13.1725
2470.12	10.9176
2472.89	9.38321
2475.67	9.2387
2478.44	7.14473
2481.21	5.12448
2483.98	4.06866
2486.75	5.332
2489.52	3.40926
2492.29	3.74617
2495.06	5.06866
2497.82	1.77936
2500.59	0.749003
2503.35	1.53579
2506.11	2.75519
2508.88	0.439071
2511.63	0.0817323
2514.39	2.27826
2517.15	1.83283
2519.91	3.21802
2522.67	6.20988
2525.42	8.26263
2528.18	12.1232
2530.93	12.4546
2533.69	14.08
2536.44	12.8806
2539.19	15.6863
2541.94	17.0506
2544.69	18.6379
2547.44	20.3235
2550.18	22.4294
2552.93	25.0038
2555.68	26.1738
2558.42	25.3308
2561.16	25.7471
2563.9	24.9632
2566.64	20.3641
2569.38	21.3135
2572.12	20.445
2574.86	19.288
2577.6	17.444
2580.34	16.8268
2583.07	14.3965
2585.81	12.6099
2588.54	12.6532
2591.27	13.7875
2594	13.9122
2596.73	16.9244
2599.46	15.3608
2602.19	14.4706
2604.92	12.3045
2607.64	13.7342
2610.37	12.3249
2613.09	13.008
2615.82	14.0579
2618.54	11.5665
2621.26	8.01776
2623.98	7.52737
2626.7	5.94403
2629.42	4.95473
2632.14	5.69733
2634.86	7.79175
2637.57	13.6866
2640.29	14.0469
2643	16.0436
2645.72	15.3452
2648.43	17.0288
2651.14	18.3646
2653.85	20.1455
2656.56	20.6952
2659.27	21.8347
2661.97	23.8429
2664.68	24.2672
2667.38	24.0717
2670.09	24.9829
2672.79	24.033
2675.49	27.6384
2678.2	25.598
2680.89	25.3862
2683.59	24.6038
2686.29	21.1739
2688.99	21.3543
2691.69	22.2007
2694.38	24.3539
2697.08	24.4937
2699.77	26.8533
2702.46	27.8148
2705.16	27.0522
2707.85	24.2384
2710.54	26.0482
2713.23	24.4455
2715.92	25.0379
2718.6	25.9433
2721.29	23.49
2723.97	24.72
2726.66	24.0458
2729.34	23.9924
2732.02	21.0335
2734.7	17.2739
2737.39	17.8461
2740.06	14.613
2742.74	13.8091
2745.42	10.2367
2748.1	8.04639
2750.77	7.59637
2753.45	4.87138
2756.12	3.52858
2758.79	1.82248
2761.47	-1.31824
2764.14	0.275757
2766.81	0.424113
2769.48	2.35378
2772.14	3.08492
2774.81	5.72864
2777.48	7.02403
2780.14	7.68181
2782.81	9.37091
2785.47	9.34223
2788.13	8.77678
2790.79	8.85987
2793.46	8.06195
2796.11	4.89558
2798.77	3.64879
2801.43	3.9472
2804.09	4.44127
2806.74	4.04147
2809.4	2.75896
2812.05	2.06445
2814.71	-0.343859
2817.36	1.65287
2820.01	1.53148
2822.66	4.12836
2825.31	8.3954
2827.96	12.6128
2830.61	17.5706
2833.25	19.541
2835.9	24.6446
2838.54	30.7142
2841.18	35.4304
2843.83	41.4968
2846.47	50.0962
2849.11	55.1841
2851.75	62.8174
2854.39	65.1483
2857.03	69.9627
2859.67	73.1871
2862.3	78.2971
2864.94	84.0157
2867.57	86.7632
2870.21	87.721
2872.84	89.2136
2875.47	90.3515
2878.1	93.974
2880.73	95.1292
2883.36	96.37
2885.99	101.024
2888.61	105.499
2891.24	109.174
2893.87	109.431
2896.49	107.503
2899.11	112.763
2901.74	118.917
2904.36	123.129
2906.98	130.318
2909.6	136.649
2912.22	144.726
2914.83	151.997
2917.45	160.288
2920.07	166.421
2922.68	171.238
2925.3	175.048
2927.91	181.55
2930.52	184.149
2933.13	184.988
2935.74	187.734
2938.35	188.326
2940.96	189.245
2943.57	186.554
2946.18	184.907
2948.78	182.721
2951.39	180.15
2953.99	172.664
2956.6	165.785
2959.2	156.68
2961.8	153.524
2964.4	148.015
2967	142.859
2969.6	137.044
2972.2	132.684
2974.79	126.559
2977.39	123.124
2979.98	116.969
2982.58	109.498
2985.17	100.865
2987.76	92.8641
2990.36	87.4196
2992.95	79.3349
2995.54	70.5733
2998.12	60.5514
3000.71	55.6573
3003.3	48.0636
3005.88	39.5606
3008.47	33.3142
3011.05	25.9416
3013.64	22.1541
3016.22	18.6494
3018.8	15.5389
3021.38	11.0982
3023.96	6.16601
3026.54	4.93101
3029.12	5.96177
3031.69	6.55676
3034.27	3.95186
3036.85	3.83694
3039.42	3.34561
3041.99	5.10911
3044.57	7.31756
3047.14	7.98678
3049.71	7.40061
3052.28	5.09545
3054.85	6.99534
3057.42	8.38285
3059.98	7.67822
3062.55	13.7889
3065.11	18.2536
3067.68	22.4823
3070.24	29.7984
3072.8	31.8377
3075.37	39.0908
3077.93	42.9654
3080.49	47.7579
3083.05	52.5523
3085.61	57.5161
3088.16	66.5015
3090.72	73.2742
3093.27	77.9744
3095.83	83.0661
3098.38	88.4152
3100.94	94.5188
3103.49	102.307
3106.04	108.736
3108.59	117.377
3111.14	122.18
3113.69	129.537
3116.23	137.676
3118.78	144.921
3121.33	152.164
3123.87	161.123
3126.42	169.106
3128.96	177.461
3131.5	185.167
3134.04	190.861
3136.58	197.77
3139.12	204.084
3141.66	209.205
3144.2	213.101
3146.74	215
3149.27	216.462