File: data/Raman/poly_smoothed/Mb_50_18_24_1x_45s_532 nm_x100_100%_600 gr_mm_01.txt
#Acq. time (s)=	45
#Accumulations=	2
#Range (cm-¹)=	200...3150
#Windows=	2
#Auto scanning=	Off
#Autofocus=	Off
#Macrospot=	Off
#AutoExposure=	Off
#Spike filter=	Multiple accum.
#Delay time (s)=	0
#Binning=	1
#Readout mode=	Signal
#DeNoise=	Off
#ICS correction=	On
#Dark correction=	Off
#Inst. Process=	Off
#Detector Gain=	Best Dynamic Range
#Detector ADC=	20 kHz
#Detector temperature (°C)=	-69.85
#Instrument=	LabRAM HR Evol
#Detector=	Synapse
#Objective=	x100
#Grating=	600 gr/mm
#ND Filter=	100%
#Laser (nm)=	532
#Hole=	100.021
#Range=	Auto
#Laser Pol.=	No
#Raman. Pol.=	No
#Laser Pol. (°)=	-0.0007625
#Raman Pol. (°)=	89.9995
#Collection=	Microscope
#StageXY=	Marzhauser
#StageZ=	Marzhauser
#X (µm)=	28295.2
#Y (µm)=	-3300.8
#Z (µm)=	1040.6
#Full time(mm:ss)=	3:19
#Project=
#Sample=
#Site=
#Title=	Mb_50_18_24_2x_45s_532 nm_x100_100%_600 gr_mm
#Remark=
#Date=	12.07.2022 12:39
#Acquired=	12.07.2022 12:39:40
#Base:Fit=	10.08.2022 10:49:18
#Base:Sub=	10.08.2022 10:49:30
#Filter:Polynom=	16.08.2022 10:14:59
#AxisType[0]=Intens
#AxisUnit[0]=Cnt
#AxisType[1]=Spectr
#AxisUnit[1]=1/cm
200.388	3.70887
204.019	2.89235
207.646	3.51037
211.274	0.609345
214.899	0.331042
218.524	3.57598
222.146	4.66213
225.766	7.56141
229.388	9.03525
233.005	10.4764
236.621	12.4874
240.236	11.951
243.852	11.9482
247.464	13.0344
251.074	14.7445
254.683	13.0617
258.291	13.4868
261.897	14.9687
265.504	12.6589
269.108	11.5804
272.71	10.9023
276.311	8.62944
279.91	7.96475
283.508	6.66257
287.105	7.30668
290.698	8.13774
294.291	9.03575
297.884	9.80293
301.475	17.1788
305.064	19.9814
308.652	23.117
312.237	24.8101
315.822	26.7161
319.406	29.0041
322.987	30.4653
326.568	31.601
330.148	32.6538
333.724	33.672
337.301	32.1162
340.875	30.4248
344.449	29.0511
348.02	29.6653
351.592	29.6537
355.16	31.2504
358.728	36.7934
362.294	40.9777
365.858	45.2842
369.422	50.5696
372.983	54.8567
376.543	59.2416
380.102	62.0175
383.661	62.2141
387.216	63.0945
390.771	64.0653
394.324	63.1185
397.875	61.1986
401.425	55.2915
404.974	50.4325
408.524	46.1483
412.07	41.7045
415.614	34.3191
419.156	26.2012
422.698	19.2707
426.238	13.3958
429.777	8.82857
433.315	7.69337
436.852	6.2948
440.387	7.40719
443.919	10.019
447.451	11.9866
450.982	11.9941
454.512	13.2218
458.038	12.8475
461.565	13.7009
465.091	15.5318
468.613	14.9622
472.136	15.8623
475.655	17.7658
479.176	20.4474
482.692	22.7696
486.21	26.6698
489.724	29.0688
493.237	31.4257
496.75	36.2621
500.26	40.5404
503.771	44.5816
507.279	47.9945
510.785	51.5941
514.289	52.8759
517.793	53.2441
521.297	52.7136
524.797	52.5712
528.297	51.7919
531.795	47.6436
535.291	42.917
538.787	37.2468
542.281	31.2267
545.773	25.3696
549.264	19.9985
552.754	14.0187
556.243	8.16056
559.73	6.02109
563.216	4.27959
566.701	3.02218
570.182	2.64466
573.664	3.28887
577.145	5.20545
580.624	8.50712
584.1	11.4731
587.577	13.3446
591.052	15.3364
594.524	16.0309
597.997	16.2023
601.466	17.6429
604.936	18.6157
608.403	18.4802
611.87	17.9956
615.334	14.5295
618.799	13.4454
622.26	12.8302
625.72	11.3089
629.181	10.367
632.638	8.18598
636.095	7.05354
639.551	4.46692
643.005	4.19132
646.457	4.33025
649.908	3.53607
653.357	4.5229
656.806	6.6569
660.253	6.67988
663.7	6.98712
667.145	6.5749
670.588	8.03372
674.027	9.40615
677.468	11.1263
680.907	12.4399
684.345	12.599
687.781	13.4304
691.216	13.1521
694.65	13.3747
698.081	14.8705
701.512	14.6165
704.942	15.7213
708.371	15.3801
711.796	15.9503
715.222	17.289
718.645	17.4645
722.068	15.4741
725.49	15.681
728.909	14.2054
732.329	15.5722
735.745	19.2675
739.16	25.8048
742.576	32.8052
745.988	42.4933
749.401	54.5727
752.811	66.2866
756.22	79.0785
759.627	88.7067
763.035	97.1479
766.44	104.044
769.843	110.378
773.245	113.413
776.646	117.199
780.046	119.275
783.444	119.561
786.841	118.06
790.237	115.973
793.631	112.609
797.024	106.976
800.416	99.5229
803.807	89.3285
807.196	80.7251
810.584	73.5908
813.971	67.8462
817.354	63.3523
820.739	61.113
824.122	60.1358
827.503	59.1726
830.882	58.0208
834.261	57.6217
837.637	56.1604
841.013	54.7175
844.389	52.5732
847.761	50.1235
851.131	47.6285
854.503	46.055
857.871	43.7965
861.24	44.4883
864.606	43.8338
867.97	42.9377
871.336	42.6607
874.698	41.5306
878.058	40.9381
881.418	39.161
884.778	37.9783
888.135	35.6677
891.49	34.5423
894.845	31.1987
898.198	29.0919
901.55	26.1989
904.901	25.4045
908.25	25.3898
911.598	24.7978
914.945	24.9049
918.291	23.8714
921.635	22.926
924.978	22.9781
928.318	23.6159
931.659	22.9583
934.998	24.1567
938.336	24.8215
941.671	24.1095
945.007	24.1502
948.339	23.6814
951.672	21.9581
955.004	22.1838
958.333	20.1653
961.662	17.4818
964.989	14.7512
968.315	12.6627
971.639	9.02767
974.962	6.27436
978.285	3.7906
981.605	1.85503
984.924	-0.855326
988.243	-2.15677
991.56	-1.71643
994.875	-1.37439
998.188	2.46193
1001.5	6.73587
1004.81	12.5441
1008.12	20.1278
1011.43	26.276
1014.74	32.6232
1018.05	39.2743
1021.35	45.5497
1024.65	50.4709
1027.96	53.7768
1031.26	57.0347
1034.56	57.9357
1037.86	58.061
1041.16	56.4068
1044.45	53.6604
1047.75	50.9826
1051.04	48.7436
1054.33	45.6586
1057.62	43.4963
1060.91	40.8005
1064.2	37.4899
1067.49	36.7435
1070.77	37.3771
1074.06	39.2204
1077.34	41.1514
1080.62	42.2186
1083.91	44.3037
1087.18	45.1521
1090.46	43.4913
1093.74	42.5488
1097.02	41.3203
1100.29	41.3533
1103.56	38.4331
1106.84	33.6012
1110.11	28.5997
1113.38	23.5281
1116.64	17.331
1119.91	12.5813
1123.18	7.92878
1126.44	4.96014
1129.7	1.89058
1132.97	1.37327
1136.23	0.985473
1139.49	0.842287
1142.74	1.16504
1146	3.71473
1149.26	3.67555
1152.51	4.11364
1155.76	4.18877
1159.01	4.13948
1162.27	4.58905
1165.51	3.55575
1168.76	3.57849
1172.01	4.04867
1175.25	6.2041
1178.5	4.92445
1181.74	4.73384
1184.98	3.8728
1188.22	4.02537
1191.46	5.08143
1194.7	4.11665
1197.94	4.46899
1201.17	5.02631
1204.41	5.97027
1207.64	7.21201
1210.87	8.97651
1214.1	10.1641
1217.33	11.1962
1220.56	11.3451
1223.79	14.0679
1227.01	14.5811
1230.23	14.5371
1233.46	15.1843
1236.68	15.4988
1239.9	15.8099
1243.12	16.2916
1246.34	16.7564
1249.55	17.3911
1252.77	16.1166
1255.98	16.1809
1259.2	15.5704
1262.41	16.8798
1265.62	17.6328
1268.83	19.0962
1272.03	21.4747
1275.24	23.6976
1278.45	25.8037
1281.65	28.2986
1284.85	31.0392
1288.06	32.0401
1291.26	32.5524
1294.46	33.5031
1297.66	35.0201
1300.85	36.3585
1304.05	36.5436
1307.24	38.1717
1310.43	37.8716
1313.63	35.0403
1316.82	34.9177
1320.01	36.3398
1323.2	34.6744
1326.38	31.9131
1329.57	30.1705
1332.76	28.8446
1335.94	26.3224
1339.12	26.5152
1342.3	24.2658
1345.48	23.9189
1348.66	22.9792
1351.84	23.3531
1355.01	21.4126
1358.19	19.2236
1361.36	18.8043
1364.53	16.6607
1367.71	15.027
1370.88	14.4553
1374.04	13.5485
1377.21	12.8404
1380.38	11.9061
1383.54	12.2557
1386.71	11.5538
1389.87	9.00707
1393.03	11.2043
1396.19	13.0062
1399.35	14.0087
1402.51	13.7568
1405.67	15.3401
1408.82	17.3777
1411.98	19.9885
1415.13	23.9236
1418.28	28.5494
1421.43	31.6797
1424.58	36.6387
1427.73	40.3523
1430.88	44.5974
1434.02	48.395
1437.17	52.6665
1440.31	53.6336
1443.45	53.5905
1446.6	54.7749
1449.74	54.3638
1452.87	52.7768
1456.01	50.7321
1459.15	48.7996
1462.28	46.4898
1465.42	45.1441
1468.55	43.5457
1471.68	40.4966
1474.81	36.9253
1477.94	33.3995
1481.07	29.9737
1484.2	28.0933
1487.32	25.5137
1490.45	24.1347
1493.57	21.9709
1496.69	19.6033
1499.81	19.244
1502.93	16.9715
1506.05	15.0995
1509.17	13.6305
1512.28	11.1657
1515.4	7.18455
1518.51	5.06252
1521.63	3.78344
1524.74	2.68397
1527.85	1.58861
1530.96	1.33214
1534.06	1.80608
1537.17	4.95032
1540.28	7.06409
1543.38	8.67323
1546.48	8.20973
1549.59	10.0859
1552.69	12.6902
1555.79	13.8449
1558.88	16.9254
1561.98	18.3847
1565.08	20.2813
1568.17	22.2157
1571.27	24.3279
1574.36	26.6362
1577.45	27.6773
1580.54	28.5626
1583.63	29.6906
1586.72	29.5703
1589.8	30.6741
1592.89	30.7811
1595.97	32.4269
1599.06	32.8551
1602.14	34.1288
1605.22	32.6484
1608.3	32.4064
1611.38	33.5313
1614.46	32.1188
1617.53	31.952
1620.61	31.1647
1623.68	32.4134
1626.75	31.1156
1629.82	29.5609
1632.9	28.8102
1635.96	29.9245
1639.03	30.2607
1642.1	31.0396
1645.16	30.0049
1648.23	32.563
1651.29	33.0002
1654.36	33.4712
1657.42	33.4122
1660.48	32.8877
1663.53	32.9464
1666.59	33.5155
1669.65	33.162
1672.7	32.4492
1675.76	30.5294
1678.81	28.5724
1681.86	26.0073
1684.91	24.1868
1687.96	21.6836
1691.01	19.3322
1694.06	17.9728
1697.11	15.3942
1700.15	12.5042
1703.2	10.1554
1706.24	9.78603
1709.28	7.68737
1712.32	5.99805
1715.36	5.14841
1718.4	5.14429
1721.43	4.68863
1724.47	3.55193
1727.5	2.28545
1730.54	2.83149
1733.57	2.66206
1736.6	2.63434
1739.63	3.04967
1742.66	3.70414
1745.69	3.22462
1748.72	2.91885
1751.74	4.52282
1754.77	4.12712
1757.79	4.95189
1760.81	5.39315
1763.83	4.73883
1766.85	4.50747
1769.87	4.71419
1772.89	4.30202
1775.91	3.77783
1778.92	3.62936
1781.94	4.43629
1784.95	4.68719
1787.96	4.07229
1790.97	3.5957
1793.98	4.25759
1796.99	2.71045
1800	2.20586
1803	2.54053
1806.01	2.70663
1809.01	1.87439
1812.02	0.317739
1815.02	0.427717
1818.02	1.40563
1821.02	1.88264
1824.02	1.64634
1827.01	1.04603
1830.01	0.970369
1833	1.66481
1836	0.910206
1838.99	0.786337
1841.98	1.2992
1844.97	1.20742
1847.96	1.34228
1850.95	1.73497
1853.94	3.78454
1856.92	3.934
1859.91	4.16904
1862.89	4.32549
1865.88	5.66307
1868.86	5.82597
1871.84	4.38054
1874.82	4.76304
1877.8	5.05333
1880.77	4.95959
1882.51	4.47423
1885.5	5.3081
1888.48	6.39346
1891.47	6.36078
1894.46	6.23071
1897.44	6.39858
1900.42	7.42806
1903.41	9.58535
1906.39	8.22943
1909.37	9.20771
1912.35	9.79697
1915.32	9.4798
1918.3	9.26319
1921.28	9.49653
1924.25	10.3682
1927.22	10.4032
1930.2	9.05826
1933.17	9.01668
1936.14	8.48275
1939.11	7.07161
1942.08	5.68005
1945.04	4.86005
1948.01	5.20667
1950.97	4.70795
1953.94	3.87455
1956.9	2.79909
1959.86	3.55274
1962.82	3.64457
1965.78	5.03278
1968.74	5.86518
1971.69	6.1568
1974.65	8.24453
1977.61	9.13116
1980.56	9.66468
1983.51	10.4523
1986.46	9.02774
1989.41	8.66085
1992.36	9.22794
1995.31	10.5532
1998.26	10.3236
2001.2	9.70471
2004.15	9.52842
2007.09	10.0723
2010.04	9.71375
2012.98	8.75833
2015.92	9.07133
2018.86	8.07577
2021.8	9.01253
2024.74	8.22158
2027.67	8.30042
2030.61	9.38248
2033.54	10.2528
2036.47	12.7712
2039.41	12.8368
2042.34	13.5289
2045.27	14.354
2048.2	16.5211
2051.12	17.9276
2054.05	18.7421
2056.98	18.7812
2059.9	19.2119
2062.82	21.6077
2065.75	23.5834
2068.67	24.9358
2071.59	25.2514
2074.51	26.7365
2077.43	27.5133
2080.34	28.3825
2083.26	28.2251
2086.17	28.187
2089.09	29.1949
2092	30.2662
2094.91	31.8551
2097.82	31.9957
2100.73	34.0895
2103.64	36.2486
2106.55	36.8462
2109.46	38.0005
2112.36	38.7278
2115.27	40.9653
2118.17	43.7041
2121.07	46.7249
2123.97	49.2091
2126.87	51.812
2129.77	54.5493
2132.67	58.5526
2135.57	62.8866
2138.46	66.428
2141.36	69.9282
2144.25	72.3874
2147.14	74.5751
2150.03	75.9412
2152.92	78.2476
2155.81	80.4855
2158.7	82.2876
2161.59	84.5174
2164.48	86.9212
2167.36	86.5378
2170.25	85.9403
2173.13	85.9759
2176.01	84.8587
2178.89	81.9276
2181.77	80.8118
2184.65	79.2787
2187.53	76.5748
2190.41	75.4516
2193.28	74.3999
2196.16	72.0669
2199.03	69.9431
2201.9	68.0266
2204.78	65.3656
2207.65	61.3369
2210.51	58.6067
2213.38	54.7338
2216.25	51.2549
2219.12	47.4818
2221.98	44.1463
2224.85	41.7205
2227.71	38.7421
2230.57	36.441
2233.43	35.1831
2236.29	31.5141
2239.15	28.7784
2242.01	26.8228
2244.87	25.1684
2247.73	23.2432
2250.58	21.7486
2253.43	20.6821
2256.29	20.8178
2259.14	21.0458
2261.99	20.4762
2264.84	21.0349
2267.69	20.8257
2270.54	19.8042
2273.38	19.5198
2276.23	18.9724
2279.07	18.7539
2281.92	17.512
2284.76	16.8141
2287.6	15.414
2290.44	13.5783
2293.28	12.373
2296.12	12.4962
2298.96	12.875
2301.79	12.7588
2304.63	12.2362
2307.46	10.3991
2310.3	11.741
2313.13	10.8799
2315.96	11.8035
2318.79	13.0539
2321.62	13.5444
2324.45	14.3003
2327.27	14.8788
2330.1	14.2266
2332.93	14.4359
2335.75	15.518
2338.57	15.7481
2341.4	15.3066
2344.22	15.0048
2347.04	13.3898
2349.86	10.9729
2352.67	9.94839
2355.49	7.92606
2358.31	6.35397
2361.12	4.32246
2363.94	3.96434
2366.75	4.32482
2369.56	3.57267
2372.37	2.80474
2375.18	0.940916
2377.99	-0.127129
2380.8	0.775938
2383.61	2.30137
2386.41	1.52355
2389.22	1.59194
2392.02	0.973828
2394.82	0.322077
2397.63	0.295508
2400.43	0.542193
2403.23	1.25777
2406.02	2.43081
2408.82	2.94831
2411.62	3.19435
2414.41	3.64984
2417.21	4.2486
2420	4.4248
2422.79	5.41655
2425.59	5.70877
2428.38	6.13716
2431.17	6.06403
2433.96	6.125
2436.74	7.07293
2439.53	7.37023
2442.32	7.62632
2445.1	7.01242
2447.88	7.74248
2450.67	7.96837
2453.45	7.46166
2456.23	6.73462
2459.01	7.04631
2461.79	5.63401
2464.57	5.35945
2467.34	4.05021
2470.12	3.74814
2472.89	4.10524
2475.67	5.40695
2478.44	5.44209
2481.21	5.09694
2483.98	4.66167
2486.75	3.84579
2489.52	4.1465
2492.29	5.02594
2495.06	6.36611
2497.82	6.03651
2500.59	6.38084
2503.35	7.53196
2506.11	7.54828
2508.88	7.41949
2511.63	6.90322
2514.39	6.63655
2517.15	5.70588
2519.91	5.76332
2522.67	5.73246
2525.42	6.38873
2528.18	6.11823
2530.93	5.40587
2533.69	4.48926
2536.44	5.03507
2539.19	4.9428
2541.94	5.71494
2544.69	3.85661
2547.44	2.57679
2550.18	3.0296
2552.93	3.06026
2555.68	3.51402
2558.42	3.72308
2561.16	4.42
2563.9	4.35935
2566.64	3.86375
2569.38	4.44764
2572.12	4.89703
2574.86	5.1017
2577.6	5.27971
2580.34	5.33043
2583.07	5.48642
2585.81	6.28523
2588.54	6.61548
2591.27	7.18592
2594	7.48153
2596.73	6.66994
2599.46	5.73708
2602.19	5.18389
2604.92	4.26837
2607.64	3.51617
2610.37	2.67619
2613.09	2.73303
2615.82	3.71867
2618.54	3.20594
2621.26	2.68331
2623.98	3.04541
2626.7	3.24876
2629.42	3.95638
2632.14	4.3595
2634.86	4.60491
2637.57	5.61262
2640.29	6.83919
2643	6.73524
2645.72	7.0982
2648.43	7.76072
2651.14	8.07401
2653.85	7.43409
2656.56	7.55996
2659.27	7.32523
2661.97	6.72678
2664.68	6.40997
2667.38	6.1798
2670.09	5.63764
2672.79	5.27282
2675.49	5.2929
2678.2	5.22168
2680.89	5.55889
2683.59	5.58203
2686.29	6.17577
2688.99	6.2008
2691.69	6.69783
2694.38	6.21515
2697.08	5.5059
2699.77	6.48193
2702.46	6.17855
2705.16	6.87557
2707.85	6.69393
2710.54	6.87013
2713.23	7.74662
2715.92	7.58461
2718.6	8.87314
2721.29	8.90219
2723.97	8.14643
2726.66	7.01998
2729.34	7.24513
2732.02	6.26096
2734.7	5.38494
2737.39	5.12949
2740.06	5.29409
2742.74	6.43449
2745.42	5.61165
2748.1	5.90664
2750.77	4.94342
2753.45	4.78352
2756.12	4.7939
2758.79	4.21409
2761.47	3.79953
2764.14	3.37602
2766.81	2.99057
2769.48	2.67621
2772.14	3.07241
2774.81	3.10463
2777.48	2.75138
2780.14	2.91053
2782.81	2.68369
2785.47	1.53455
2788.13	0.028739
2790.79	0.149081
2793.46	0.237094
2796.11	0.00572652
2798.77	0.322124
2801.43	-0.180383
2804.09	0.0716317
2806.74	0.46293
2809.4	-0.0974087
2812.05	-0.659358
2814.71	0.433909
2817.36	2.06095
2820.01	2.93812
2822.66	4.66876
2825.31	7.31342
2827.96	10.8656
2830.61	13.808
2833.25	18.0175
2835.9	21.6908
2838.54	26.0026
2841.18	30.5255
2843.83	36.6859
2846.47	41.2388
2849.11	46.444
2851.75	51.8388
2854.39	57.4376
2857.03	63.2681
2859.67	67.7035
2862.3	72.7561
2864.94	76.3754
2867.57	80.2938
2870.21	84.2948
2872.84	87.2078
2875.47	89.2273
2878.1	91.7477
2880.73	94.3249
2883.36	96.3465
2885.99	98.6711
2888.61	101.535
2891.24	103.369
2893.87	107.464
2896.49	111.166
2899.11	114.755
2901.74	120.785
2904.36	128.347
2906.98	136.015
2909.6	142.307
2912.22	149.495
2914.83	158.082
2917.45	167.066
2920.07	174.581
2922.68	181.971
2925.3	188.218
2927.91	192.953
2930.52	196.494
2933.13	198.433
2935.74	198.323
2938.35	196.619
2940.96	192.981
2943.57	187.63
2946.18	181.896
2948.78	175.305
2951.39	166.836
2953.99	158.766
2956.6	151.98
2959.2	145.594
2961.8	136.335
2964.4	129.134
2967	122.328
2969.6	115.379
2972.2	107.429
2974.79	101.534
2977.39	95.3299
2979.98	89.5286
2982.58	83.4876
2985.17	77.4267
2987.76	70.8769
2990.36	65.4961
2992.95	61.0319
2995.54	55.1442
2998.12	49.1008
3000.71	43.4039
3003.3	37.7158
3005.88	32.9928
3008.47	27.9508
3011.05	24.5856
3013.64	21.1386
3016.22	18.8573
3018.8	15.7843
3021.38	12.6352
3023.96	10.2226
3026.54	8.19025
3029.12	6.09442
3031.69	3.99441
3034.27	3.04578
3036.85	2.17778
3039.42	1.70295
3041.99	1.53497
3044.57	1.61768
3047.14	2.38844
3049.71	2.97754
3052.28	4.45988
3054.85	4.83996
3057.42	5.09509
3059.98	5.09863
3062.55	5.64352
3065.11	5.97303
3067.68	5.86838
3070.24	6.07528
3072.8	5.50329
3075.37	5.77955
3077.93	6.09952
3080.49	6.12403
3083.05	5.91055
3085.61	5.6478
3088.16	4.54577
3090.72	3.55799
3093.27	3.03182
3095.83	3.11053
3098.38	3.53432
3100.94	3.45201
3103.49	4.03163
3106.04	5.56738
3108.59	6.43874
3111.14	6.72168
3113.69	7.52847
3116.23	8.17138
3118.78	9.08273
3121.33	9.63857
3123.87	11.1362
3126.42	12.7359
3128.96	13.7524
3131.5	14.9647
3134.04	17.751
3136.58	20.1415
3139.12	22.9424
3141.66	23.981
3144.2	25.3175
3146.74	26.7644
3149.27	30.1134