File: data/Raman/poly_smoothed/Mb_50_18_18_1x_45s_532 nm_x100_100%_600 gr_mm_01.txt
#Acq. time (s)=	45
#Accumulations=	2
#Range (cm-¹)=	200...3150
#Windows=	2
#Auto scanning=	Off
#Autofocus=	Off
#Macrospot=	Off
#AutoExposure=	Off
#Spike filter=	Multiple accum.
#Delay time (s)=	0
#Binning=	1
#Readout mode=	Signal
#DeNoise=	Off
#ICS correction=	On
#Dark correction=	Off
#Inst. Process=	Off
#Detector Gain=	Best Dynamic Range
#Detector ADC=	20 kHz
#Detector temperature (°C)=	-69.85
#Instrument=	LabRAM HR Evol
#Detector=	Synapse
#Objective=	x100
#Grating=	600 gr/mm
#ND Filter=	100%
#Laser (nm)=	532
#Hole=	100.021
#Range=	Auto
#Laser Pol.=	No
#Raman. Pol.=	No
#Laser Pol. (°)=	-0.0007625
#Raman Pol. (°)=	89.9995
#Collection=	Microscope
#StageXY=	Marzhauser
#StageZ=	Marzhauser
#X (µm)=	19283.8
#Y (µm)=	3015.8
#Z (µm)=	1047.7
#Full time(mm:ss)=	3:19
#Project=
#Sample=
#Site=
#Title=	Mb_50_18_18_2x_45s_532 nm_x100_100%_600 gr_mm
#Remark=
#Date=	12.07.2022 11:32
#Acquired=	12.07.2022 11:32:32
#Base:Fit=	10.08.2022 10:49:18
#Base:Sub=	10.08.2022 10:49:30
#Filter:Polynom=	16.08.2022 10:14:59
#AxisType[0]=Intens
#AxisUnit[0]=Cnt
#AxisType[1]=Spectr
#AxisUnit[1]=1/cm
200.388	-2.5737
204.019	-0.316282
207.646	2.09031
211.274	2.98407
214.899	3.63088
218.524	3.12265
222.146	2.65689
225.766	4.09988
229.388	4.17048
233.005	4.10134
236.621	6.12583
240.236	6.91603
243.852	6.7685
247.464	7.26764
251.074	7.99411
254.683	9.82091
258.291	9.12763
261.897	10.298
265.504	11.426
269.108	12.1845
272.71	10.6008
276.311	10.4778
279.91	11.2992
283.508	12.0963
287.105	14.4414
290.698	15.5868
294.291	16.6418
297.884	17.2142
301.475	19.2789
305.064	19.9032
308.652	20.262
312.237	23.2306
315.822	25.1726
319.406	27.0058
322.987	28.5224
326.568	30.0283
330.148	29.0995
333.724	29.0356
337.301	28.1604
340.875	28.9353
344.449	28.7718
348.02	29.4288
351.592	30.5946
355.16	31.3653
358.728	32.6412
362.294	33.5264
365.858	35.8033
369.422	36.6685
372.983	38.8206
376.543	41.093
380.102	42.7642
383.661	43.366
387.216	43.9841
390.771	43.3437
394.324	41.9586
397.875	40.3379
401.425	38.3661
404.974	35.8494
408.524	30.9873
412.07	27.0955
415.614	23.3739
419.156	20.1106
422.698	16.1868
426.238	15.0267
429.777	12.8931
433.315	11.4151
436.852	11.8528
440.387	13.0763
443.919	14.0309
447.451	14.5487
450.982	14.8388
454.512	16.1087
458.038	17.5947
461.565	20.3283
465.091	19.935
468.613	21.8499
472.136	22.9317
475.655	23.5115
479.176	23.6326
482.692	26.9374
486.21	28.9273
489.724	30.4065
493.237	34.3091
496.75	38.6835
500.26	41.6945
503.771	43.4331
507.279	45.5873
510.785	47.1044
514.289	47.7033
517.793	46.6009
521.297	45.5378
524.797	44.8077
528.297	42.7958
531.795	41.8506
535.291	39.9699
538.787	37.6735
542.281	33.7227
545.773	31.0326
549.264	27.403
552.754	24.2066
556.243	19.8533
559.73	16.8139
563.216	16.2328
566.701	14.6579
570.182	12.8908
573.664	10.5024
577.145	10.5132
580.624	12.1009
584.1	9.76333
587.577	7.53812
591.052	6.17893
594.524	4.75869
597.997	3.17696
601.466	1.50444
604.936	1.20427
608.403	2.24214
611.87	2.97634
615.334	3.3631
618.799	5.13959
622.26	3.9624
625.72	3.53516
629.181	4.59301
632.638	4.76421
636.095	4.88522
639.551	3.16654
643.005	3.62497
646.457	4.43144
649.908	3.83425
653.357	3.03788
656.806	3.32718
660.253	5.96579
663.7	5.90384
667.145	6.20841
670.588	5.79692
674.027	7.35623
677.468	9.93004
680.907	10.4858
684.345	14.3001
687.781	16.851
691.216	17.9957
694.65	20.1152
698.081	20.1431
701.512	22.7543
704.942	23.4849
708.371	23.3979
711.796	24.4564
715.222	23.7147
718.645	24.0431
722.068	23.045
725.49	23.7062
728.909	25.7104
732.329	26.5214
735.745	29.9769
739.16	35.3961
742.576	41.5233
745.988	47.3393
749.401	51.9557
752.811	57.8167
756.22	62.7615
759.627	67.877
763.035	73.5355
766.44	77.1379
769.843	80.8498
773.245	81.8208
776.646	80.9255
780.046	82.1875
783.444	81.2034
786.841	80.3128
790.237	77.3573
793.631	73.845
797.024	70.7621
800.416	66.3683
803.807	63.1346
807.196	60.3543
810.584	57.7749
813.971	55.0601
817.354	54.5001
820.739	54.3832
824.122	55.0005
827.503	53.9651
830.882	51.8043
834.261	50.9434
837.637	50.5532
841.013	47.4214
844.389	43.7807
847.761	43.0984
851.131	39.7744
854.503	39.2926
857.871	37.1484
861.24	35.975
864.606	34.0204
867.97	33.9673
871.336	33.2166
874.698	31.2606
878.058	30.1348
881.418	29.2136
884.778	30.2106
888.135	31.4196
891.49	30.2384
894.845	29.884
898.198	30.288
901.55	30.0912
904.901	31.2138
908.25	30.3627
911.598	28.4845
914.945	26.6679
918.291	26.1916
921.635	23.0934
924.978	21.6867
928.318	20.4403
931.659	19.3703
934.998	18.3996
938.336	17.7404
941.671	14.5224
945.007	11.6942
948.339	10.8852
951.672	9.47022
955.004	8.71814
958.333	7.51651
961.662	7.24547
964.989	5.91463
968.315	5.41438
971.639	4.46903
974.962	4.39226
978.285	3.87205
981.605	4.87185
984.924	3.46482
988.243	3.02483
991.56	2.40847
994.875	3.69231
998.188	8.5194
1001.5	14.9658
1004.81	18.7677
1008.12	24.7657
1011.43	29.7117
1014.74	34.6489
1018.05	38.5231
1021.35	41.3187
1024.65	41.8311
1027.96	45.3566
1031.26	47.3714
1034.56	47.6471
1037.86	46.0649
1041.16	44.5292
1044.45	41.8911
1047.75	39.2301
1051.04	36.453
1054.33	35.2406
1057.62	33.3475
1060.91	32.6878
1064.2	30.7182
1067.49	30.8174
1070.77	29.8806
1074.06	29.8669
1077.34	32.7125
1080.62	33.778
1083.91	32.9093
1087.18	31.5169
1090.46	32.2833
1093.74	31.3495
1097.02	29.899
1100.29	27.8235
1103.56	25.8677
1106.84	22.8562
1110.11	19.2597
1113.38	16.2106
1116.64	12.7025
1119.91	9.53832
1123.18	6.48995
1126.44	5.45525
1129.7	4.24012
1132.97	3.80411
1136.23	2.59625
1139.49	4.0527
1142.74	4.70156
1146	4.5262
1149.26	3.45743
1152.51	2.05528
1155.76	3.83026
1159.01	3.26907
1162.27	1.62817
1165.51	3.34269
1168.76	5.09651
1172.01	8.37458
1175.25	8.17534
1178.5	9.30774
1181.74	9.91451
1184.98	10.0564
1188.22	10.8567
1191.46	12.057
1194.7	12.9895
1197.94	12.9545
1201.17	14.3022
1204.41	13.5212
1207.64	13.9535
1210.87	14.7823
1214.1	14.4329
1217.33	16.9171
1220.56	17.9786
1223.79	19.4523
1227.01	19.5987
1230.23	22.1007
1233.46	23.8087
1236.68	23.7461
1239.9	22.9081
1243.12	27.2546
1246.34	30.2539
1249.55	32.5219
1252.77	34.7626
1255.98	35.4865
1259.2	36.1317
1262.41	38.4515
1265.62	42.6373
1268.83	44.6181
1272.03	47.2028
1275.24	51.4472
1278.45	55.9276
1281.65	56.9041
1284.85	59.5731
1288.06	61.9843
1291.26	64.3578
1294.46	64.9549
1297.66	65.5412
1300.85	65.7094
1304.05	63.6673
1307.24	63.3201
1310.43	63.3661
1313.63	61.9846
1316.82	61.2953
1320.01	61.9791
1323.2	61.9469
1326.38	60.9464
1329.57	60.5013
1332.76	58.5897
1335.94	55.797
1339.12	52.5119
1342.3	52.3055
1345.48	51.5192
1348.66	51.8413
1351.84	51.9101
1355.01	52.0197
1358.19	48.7161
1361.36	47.2846
1364.53	45.8965
1367.71	45.6283
1370.88	44.7343
1374.04	41.7128
1377.21	41.2259
1380.38	40.0159
1383.54	39.5984
1386.71	40.3492
1389.87	40.2142
1393.03	39.4807
1396.19	39.9342
1399.35	41.7936
1402.51	41.6728
1405.67	45.6383
1408.82	47.5683
1411.98	48.8657
1415.13	50.9786
1418.28	55.6331
1421.43	61.058
1424.58	67.0413
1427.73	72.0711
1430.88	76.5124
1434.02	80.9705
1437.17	86.452
1440.31	91.5933
1443.45	94.4784
1446.6	95.6712
1449.74	95.4528
1452.87	95.348
1456.01	94.4461
1459.15	91.9542
1462.28	90.8632
1465.42	88.5095
1468.55	85.0494
1471.68	81.7011
1474.81	79.2098
1477.94	76.1351
1481.07	73.2529
1484.2	69.5909
1487.32	65.204
1490.45	60.5979
1493.57	58.3711
1496.69	54.7528
1499.81	52.6028
1502.93	48.9083
1506.05	45.1424
1509.17	40.9535
1512.28	39.185
1515.4	35.9676
1518.51	31.9144
1521.63	28.0123
1524.74	25.573
1527.85	24.703
1530.96	23.6196
1534.06	22.151
1537.17	21.9343
1540.28	23.9566
1543.38	25.4002
1546.48	26.2732
1549.59	27.2478
1552.69	26.4213
1555.79	27.257
1558.88	28.4481
1561.98	28.8916
1565.08	31.1229
1568.17	31.815
1571.27	34.9161
1574.36	37.2404
1577.45	32.4936
1580.54	18.9377
1583.63	15.5866
1586.72	19.4474
1589.8	27.0494
1592.89	39.1681
1595.97	60.245
1599.06	84.7062
1602.14	112.921
1605.22	143.535
1608.3	195.73
1611.38	241.005
1614.46	280.885
1617.53	312.468
1620.61	336.696
1623.68	354.702
1626.75	366.485
1629.82	370.84
1632.9	368.355
1635.96	359.433
1639.03	344.526
1642.1	322.12
1645.16	292.931
1648.23	256.392
1651.29	212.893
1654.36	166.546
1657.42	127.997
1660.48	100.114
1663.53	72.0476
1666.59	50.2873
1669.65	32.9361
1672.7	22.1669
1675.76	16.3021
1678.81	18.8551
1681.86	28.2657
1684.91	35.8869
1687.96	31.6017
1691.01	27.8929
1694.06	24.3629
1697.11	21.6119
1700.15	19.4999
1703.2	17.2257
1706.24	15.7212
1709.28	15.8887
1712.32	15.4343
1715.36	13.5525
1718.4	11.8445
1721.43	10.7812
1724.47	10.1737
1727.5	9.39979
1730.54	7.2991
1733.57	7.97589
1736.6	8.87598
1739.63	9.55713
1742.66	8.92642
1745.69	7.67982
1748.72	7.66447
1751.74	7.63579
1754.77	6.99853
1757.79	5.51295
1760.81	5.8302
1763.83	5.42323
1766.85	4.73941
1769.87	5.77408
1772.89	6.27215
1775.91	7.6797
1778.92	9.12159
1781.94	9.45871
1784.95	10.7131
1787.96	9.23355
1790.97	9.52401
1793.98	9.22613
1796.99	9.50439
1800	9.53754
1803	8.87135
1806.01	10.1744
1809.01	12.0083
1812.02	12.8475
1815.02	13.6368
1818.02	13.2142
1821.02	12.5235
1824.02	11.6423
1827.01	11.2815
1830.01	11.251
1833	10.8975
1836	11.0962
1838.99	11.5854
1841.98	12.5614
1844.97	13.5013
1847.96	14.9271
1850.95	14.0904
1853.94	12.8493
1856.92	12.4193
1859.91	12.9156
1862.89	12.8703
1865.88	13.3195
1868.86	13.007
1871.84	13.578
1874.82	14.0369
1877.8	14.6727
1880.77	15.7824
1882.51	15.7117
1885.5	15.4872
1888.48	15.1545
1891.47	14.4387
1894.46	13.5027
1897.44	13.6359
1900.42	14.1941
1903.41	14.1817
1906.39	14.1973
1909.37	13.632
1912.35	13.8372
1915.32	13.7518
1918.3	13.5906
1921.28	10.441
1924.25	8.00988
1927.22	8.06209
1930.2	9.85444
1933.17	10.7449
1936.14	10.8088
1939.11	12.024
1942.08	11.5701
1945.04	10.942
1948.01	11.2607
1950.97	11.5643
1953.94	12.4984
1956.9	13.0902
1959.86	11.3137
1962.82	11.8394
1965.78	12.4743
1968.74	13.1293
1971.69	14.0162
1974.65	13.7393
1977.61	12.4969
1980.56	11.3362
1983.51	11.4132
1986.46	12.5034
1989.41	12.2476
1992.36	11.0452
1995.31	10.0222
1998.26	9.89795
2001.2	10.6227
2004.15	11.1663
2007.09	9.55859
2010.04	9.52606
2012.98	9.99941
2015.92	9.48694
2018.86	9.48328
2021.8	9.81705
2024.74	10.5963
2027.67	10.2986
2030.61	9.87203
2033.54	10.6188
2036.47	12.2649
2039.41	12.1378
2042.34	13.5882
2045.27	14.398
2048.2	15.6664
2051.12	16.9578
2054.05	18.2356
2056.98	19.8156
2059.9	20.9695
2062.82	21.0062
2065.75	21.8394
2068.67	21.8709
2071.59	23.5333
2074.51	24.4704
2077.43	25.4027
2080.34	26.2775
2083.26	27.8418
2086.17	29.6093
2089.09	29.9653
2092	30.5968
2094.91	30.4431
2097.82	31.6256
2100.73	33.568
2103.64	34.4585
2106.55	36.6967
2109.46	39.3941
2112.36	42.1014
2115.27	45.5819
2118.17	48.1447
2121.07	50.4597
2123.97	53.1357
2126.87	56.6544
2129.77	60.4456
2132.67	62.8971
2135.57	66.956
2138.46	69.1118
2141.36	73.5464
2144.25	75.9565
2147.14	78.2793
2150.03	80.6153
2152.92	82.6482
2155.81	85.2156
2158.7	86.7557
2161.59	88.2343
2164.48	88.626
2167.36	88.7188
2170.25	90.2634
2173.13	90.846
2176.01	90.3734
2178.89	88.9664
2181.77	87.7453
2184.65	86.3599
2187.53	84.0719
2190.41	80.5039
2193.28	78.6254
2196.16	75.805
2199.03	73.0662
2201.9	69.9231
2204.78	67.6616
2207.65	64.1581
2210.51	62.0622
2213.38	59.7144
2216.25	57.0761
2219.12	54.3778
2221.98	51.5075
2224.85	48.3176
2227.71	46.0039
2230.57	43.8132
2233.43	40.8322
2236.29	37.527
2239.15	36.0575
2242.01	33.4428
2244.87	32.0205
2247.73	28.1563
2250.58	25.3213
2253.43	24.2729
2256.29	23.2485
2259.14	21.196
2261.99	20.128
2264.84	18.5186
2267.69	17.966
2270.54	17.6077
2273.38	16.7013
2276.23	15.6149
2279.07	14.6366
2281.92	13.5864
2284.76	13.3167
2287.6	13.1513
2290.44	11.4688
2293.28	9.73408
2296.12	8.25955
2298.96	9.40366
2301.79	9.08885
2304.63	8.41852
2307.46	8.31541
2310.3	7.694
2313.13	8.78384
2315.96	8.22249
2318.79	7.08266
2321.62	7.13243
2324.45	8.1991
2327.27	8.14345
2330.1	8.10735
2332.93	8.24951
2335.75	7.38381
2338.57	6.91778
2341.4	5.32016
2344.22	4.11082
2347.04	3.28683
2349.86	2.78935
2352.67	3.36632
2355.49	4.21422
2358.31	4.15984
2361.12	4.29753
2363.94	4.47865
2366.75	5.01549
2369.56	5.81552
2372.37	4.76902
2375.18	4.81002
2377.99	6.07467
2380.8	5.77122
2383.61	5.45506
2386.41	5.4727
2389.22	5.9722
2392.02	4.13058
2394.82	3.83925
2397.63	3.49844
2400.43	2.62168
2403.23	2.73992
2406.02	2.21237
2408.82	2.5474
2411.62	1.76155
2414.41	1.91951
2417.21	2.11195
2420	1.65099
2422.79	2.54647
2425.59	2.51578
2428.38	1.90582
2431.17	0.875234
2433.96	0.855126
2436.74	2.16296
2439.53	1.49301
2442.32	2.48155
2445.1	3.17244
2447.88	2.84755
2450.67	3.81906
2453.45	4.31307
2456.23	2.87521
2459.01	2.73675
2461.79	2.46186
2464.57	2.00062
2467.34	3.11686
2470.12	3.83055
2472.89	3.70763
2475.67	3.48821
2478.44	3.90425
2481.21	3.0577
2483.98	2.83535
2486.75	1.53646
2489.52	1.3255
2492.29	1.73223
2495.06	0.465286
2497.82	0.0835864
2500.59	1.14423
2503.35	1.1859
2506.11	0.84639
2508.88	1.31931
2511.63	1.40516
2514.39	2.15204
2517.15	2.66427
2519.91	2.15105
2522.67	1.4967
2525.42	3.96977
2528.18	4.30721
2530.93	3.82058
2533.69	3.46972
2536.44	3.9076
2539.19	3.22062
2541.94	3.91466
2544.69	3.7227
2547.44	3.91264
2550.18	3.80151
2552.93	3.91659
2555.68	4.82086
2558.42	5.37817
2561.16	6.2907
2563.9	6.59843
2566.64	6.35594
2569.38	7.15301
2572.12	6.53581
2574.86	8.19198
2577.6	9.24502
2580.34	9.32951
2583.07	8.86389
2585.81	8.2759
2588.54	9.28834
2591.27	10.6801
2594	10.1574
2596.73	8.66116
2599.46	8.46686
2602.19	8.82793
2604.92	8.67357
2607.64	8.27212
2610.37	7.78114
2613.09	7.68411
2615.82	7.32612
2618.54	7.94312
2621.26	8.02251
2623.98	7.10363
2626.7	6.99156
2629.42	7.46647
2632.14	6.80543
2634.86	6.50414
2637.57	5.93047
2640.29	5.90129
2643	5.33533
2645.72	4.32807
2648.43	4.07482
2651.14	4.05754
2653.85	4.25813
2656.56	4.23204
2659.27	3.61333
2661.97	4.20026
2664.68	4.9606
2667.38	5.64176
2670.09	5.92878
2672.79	6.81875
2675.49	6.9529
2678.2	7.35172
2680.89	7.80109
2683.59	6.81553
2686.29	7.02887
2688.99	7.39948
2691.69	7.67536
2694.38	9.03754
2697.08	9.93111
2699.77	8.8105
2702.46	8.45847
2705.16	8.14972
2707.85	8.22673
2710.54	8.61144
2713.23	8.89696
2715.92	8.93357
2718.6	8.36101
2721.29	7.5641
2723.97	8.76165
2726.66	9.83969
2729.34	9.47781
2732.02	8.89992
2734.7	8.80593
2737.39	9.69955
2740.06	8.68507
2742.74	7.03684
2745.42	6.17837
2748.1	5.04238
2750.77	3.40335
2753.45	2.87944
2756.12	4.01666
2758.79	2.67048
2761.47	2.26587
2764.14	0.840233
2766.81	0.729445
2769.48	1.72879
2772.14	2.28646
2774.81	1.91688
2777.48	2.3469
2780.14	2.93172
2782.81	3.74095
2785.47	4.10015
2788.13	4.63418
2790.79	4.78074
2793.46	3.9048
2796.11	4.0627
2798.77	3.44239
2801.43	3.20501
2804.09	3.30659
2806.74	3.56341
2809.4	3.26148
2812.05	2.95544
2814.71	1.06555
2817.36	1.43524
2820.01	3.22825
2822.66	6.56754
2825.31	9.35491
2827.96	14.4734
2830.61	19.6508
2833.25	25.5601
2835.9	31.7247
2838.54	38.3346
2841.18	45.1628
2843.83	53.1588
2846.47	60.8245
2849.11	67.3598
2851.75	75.6934
2854.39	82.7327
2857.03	89.118
2859.67	96.0039
2862.3	100.859
2864.94	105.451
2867.57	110.831
2870.21	114.645
2872.84	116.972
2875.47	119.474
2878.1	121.194
2880.73	123.843
2883.36	127.36
2885.99	131.628
2888.61	136.745
2891.24	139.398
2893.87	143.837
2896.49	147.953
2899.11	153.482
2901.74	159.212
2904.36	164.78
2906.98	172.401
2909.6	181.297
2912.22	189.873
2914.83	199.442
2917.45	207.767
2920.07	215.686
2922.68	222.308
2925.3	227.017
2927.91	231.315
2930.52	233.565
2933.13	234.53
2935.74	233.297
2938.35	230.726
2940.96	226.938
2943.57	221.961
2946.18	215.657
2948.78	207.356
2951.39	198.862
2953.99	190.023
2956.6	180.567
2959.2	171.128
2961.8	161.714
2964.4	151.896
2967	142.297
2969.6	134.265
2972.2	126.322
2974.79	117.901
2977.39	111.252
2979.98	103.165
2982.58	94.9417
2985.17	86.2187
2987.76	77.6952
2990.36	70.3031
2992.95	62.9038
2995.54	54.9103
2998.12	47.0317
3000.71	39.698
3003.3	34.0424
3005.88	27.2828
3008.47	21.3741
3011.05	16.03
3013.64	10.9374
3016.22	8.74157
3018.8	7.04735
3021.38	4.61728
3023.96	1.91981
3026.54	0.863901
3029.12	-0.0671832
3031.69	0.921865
3034.27	0.0426633
3036.85	0.906949
3039.42	2.59923
3041.99	4.23175
3044.57	6.29931
3047.14	8.03558
3049.71	9.16118
3052.28	11.255
3054.85	13.1396
3057.42	11.8764
3059.98	12.0185
3062.55	12.3124
3065.11	11.6366
3067.68	10.4199
3070.24	8.3467
3072.8	8.21354
3075.37	6.37207
3077.93	6.31663
3080.49	6.01538
3083.05	5.84576
3085.61	4.90498
3088.16	4.28043
3090.72	4.29269
3093.27	3.65628
3095.83	4.58916
3098.38	5.6525
3100.94	7.81931
3103.49	9.53057
3106.04	10.5141
3108.59	12.3426
3111.14	12.9345
3113.69	14.414
3116.23	15.859
3118.78	17.1187
3121.33	17.4766
3123.87	19.3557
3126.42	20.6156
3128.96	20.2692
3131.5	21.3556
3134.04	22.7868
3136.58	24.6344
3139.12	25.558
3141.66	26.9733
3144.2	27.8392
3146.74	27.7912
3149.27	29.2012