File: data/Raman/poly_smoothed/Mb_50_18_23_1x_45s_532 nm_x100_100%_600 gr_mm_01.txt
#Acq. time (s)=	45
#Accumulations=	2
#Range (cm-¹)=	200...3150
#Windows=	2
#Auto scanning=	Off
#Autofocus=	Off
#Macrospot=	Off
#AutoExposure=	Off
#Spike filter=	Multiple accum.
#Delay time (s)=	0
#Binning=	1
#Readout mode=	Signal
#DeNoise=	Off
#ICS correction=	On
#Dark correction=	Off
#Inst. Process=	Off
#Detector Gain=	Best Dynamic Range
#Detector ADC=	20 kHz
#Detector temperature (°C)=	-69.85
#Instrument=	LabRAM HR Evol
#Detector=	Synapse
#Objective=	x100
#Grating=	600 gr/mm
#ND Filter=	100%
#Laser (nm)=	532
#Hole=	100.021
#Range=	Auto
#Laser Pol.=	No
#Raman. Pol.=	No
#Laser Pol. (°)=	-0.0007625
#Raman Pol. (°)=	89.9995
#Collection=	Microscope
#StageXY=	Marzhauser
#StageZ=	Marzhauser
#X (µm)=	28332.7
#Y (µm)=	-3308.3
#Z (µm)=	1040.6
#Full time(mm:ss)=	3:19
#Project=
#Sample=
#Site=
#Title=	Mb_50_18_23_2x_45s_532 nm_x100_100%_600 gr_mm
#Remark=
#Date=	12.07.2022 12:34
#Acquired=	12.07.2022 12:34:11
#Base:Fit=	10.08.2022 10:49:18
#Base:Sub=	10.08.2022 10:49:30
#Filter:Polynom=	16.08.2022 10:14:59
#AxisType[0]=Intens
#AxisUnit[0]=Cnt
#AxisType[1]=Spectr
#AxisUnit[1]=1/cm
200.388	0.430091
204.019	7.6275
207.646	13.0212
211.274	17.5408
214.899	21.6767
218.524	23.9666
222.146	23.1491
225.766	22.814
229.388	21.9605
233.005	21.437
236.621	21.4139
240.236	21.7271
243.852	21.9861
247.464	21.357
251.074	21.5139
254.683	20.5806
258.291	19.6934
261.897	17.9561
265.504	17.0176
269.108	14.9015
272.71	14.5048
276.311	12.2233
279.91	10.3087
283.508	9.23953
287.105	10.2648
290.698	10.0491
294.291	12.333
297.884	16.1915
301.475	19.9976
305.064	21.6108
308.652	25.085
312.237	28.9832
315.822	32.3147
319.406	35.4451
322.987	37.9852
326.568	40.611
330.148	44.2182
333.724	45.1443
337.301	45.5906
340.875	44.1081
344.449	42.6369
348.02	43.2578
351.592	45.0805
355.16	49.2116
358.728	55.3728
362.294	62.4659
365.858	66.8484
369.422	70.1838
372.983	76.542
376.543	81.4497
380.102	86.0328
383.661	90.3856
387.216	93.1626
390.771	94.0442
394.324	93.342
397.875	92.7865
401.425	88.9116
404.974	82.5747
408.524	76.3291
412.07	69.8649
415.614	61.5183
419.156	51.1683
422.698	39.9893
426.238	31.0324
429.777	23.6934
433.315	19.6572
436.852	16.7114
440.387	14.7112
443.919	15.0306
447.451	12.5399
450.982	10.7247
454.512	9.85373
458.038	10.4609
461.565	9.59016
465.091	9.76487
468.613	9.92898
472.136	10.3003
475.655	11.6643
479.176	15.5524
482.692	20.7631
486.21	26.1682
489.724	33.9676
493.237	44.2005
496.75	54.2079
500.26	61.2789
503.771	68.3644
507.279	74.3082
510.785	78.0291
514.289	84.5165
517.793	84.7276
521.297	86.7003
524.797	84.8321
528.297	82.2557
531.795	77.7751
535.291	71.7463
538.787	65.93
542.281	56.9268
545.773	48.9189
549.264	39.9563
552.754	30.4601
556.243	22.491
559.73	15.0161
563.216	10.2825
566.701	8.54759
570.182	6.14506
573.664	7.48735
577.145	9.63589
580.624	10.2752
584.1	12.4263
587.577	13.7962
591.052	15.5307
594.524	16.572
597.997	19.9095
601.466	20.652
604.936	19.7819
608.403	18.555
611.87	19.7222
615.334	19.6928
618.799	18.861
622.26	17.0886
625.72	15.798
629.181	12.7297
632.638	11.2636
636.095	9.97857
639.551	7.37964
643.005	6.41932
646.457	5.36575
649.908	6.23811
653.357	5.14653
656.806	6.19403
660.253	4.81092
663.7	4.37757
667.145	5.1236
670.588	4.51384
674.027	5.6868
677.468	6.20678
680.907	8.35416
684.345	8.75499
687.781	9.47341
691.216	9.80014
694.65	10.859
698.081	11.6464
701.512	11.0125
704.942	10.967
708.371	11.9783
711.796	14.6829
715.222	15.6877
718.645	18.5447
722.068	19.2405
725.49	20.0116
728.909	21.4446
732.329	23.8987
735.745	25.9919
739.16	33.2391
742.576	40.8698
745.988	51.9375
749.401	67.2088
752.811	82.0924
756.22	96.5631
759.627	111.618
763.035	124.577
766.44	134.888
769.843	141.674
773.245	145.843
776.646	148.334
780.046	148.139
783.444	145.931
786.841	140.131
790.237	134.224
793.631	125.674
797.024	113.834
800.416	101.077
803.807	87.8919
807.196	70.7146
810.584	57.801
813.971	48.1455
817.354	38.6083
820.739	33.1901
824.122	33.1419
827.503	32.9514
830.882	33.2975
834.261	36.1095
837.637	36.7401
841.013	38.3558
844.389	37.4762
847.761	38.0623
851.131	36.0302
854.503	34.8605
857.871	32.3731
861.24	30.3444
864.606	27.194
867.97	26.4497
871.336	24.6444
874.698	25.0461
878.058	23.8601
881.418	20.7647
884.778	19.7866
888.135	17.4634
891.49	17.9931
894.845	19.0195
898.198	18.6682
901.55	18.7598
904.901	21.947
908.25	21.01
911.598	22.1028
914.945	21.1809
918.291	21.7699
921.635	20.7758
924.978	22.3958
928.318	22.6328
931.659	21.9153
934.998	21.7682
938.336	19.5148
941.671	19.269
945.007	17.3635
948.339	17.1792
951.672	18.4427
955.004	14.6825
958.333	13.7328
961.662	11.1617
964.989	8.38228
968.315	7.06375
971.639	3.75063
974.962	3.86958
978.285	1.82202
981.605	-0.347888
984.924	0.658305
988.243	0.117422
991.56	-0.846646
994.875	0.564835
998.188	3.29585
1001.5	11.0267
1004.81	20.3405
1008.12	28.1655
1011.43	37.3533
1014.74	44.7364
1018.05	52.7222
1021.35	58.8725
1024.65	64.8897
1027.96	69.2793
1031.26	72.2946
1034.56	72.8416
1037.86	71.9888
1041.16	69.9166
1044.45	66.5535
1047.75	63.0481
1051.04	58.583
1054.33	56.9795
1057.62	55.8952
1060.91	55.4444
1064.2	58.1476
1067.49	58.1253
1070.77	59.9726
1074.06	62.9497
1077.34	68.6137
1080.62	72.2158
1083.91	77.3822
1087.18	78.4333
1090.46	80.6204
1093.74	78.9956
1097.02	76.5447
1100.29	71.7889
1103.56	66.0751
1106.84	58.1423
1110.11	48.8841
1113.38	40.4659
1116.64	30.3409
1119.91	21.8053
1123.18	11.0398
1126.44	6.38245
1129.7	2.40121
1132.97	0.890738
1136.23	2.23872
1139.49	3.29445
1142.74	4.18103
1146	5.73839
1149.26	6.90292
1152.51	8.53065
1155.76	10.0309
1159.01	11.9536
1162.27	13.5673
1165.51	16.5782
1168.76	18.4788
1172.01	20.0618
1175.25	21.6844
1178.5	26.1173
1181.74	26.1429
1184.98	27.314
1188.22	27.6949
1191.46	28.6015
1194.7	30.5853
1197.94	32.6831
1201.17	31.9322
1204.41	33.7481
1207.64	36.9621
1210.87	36.8301
1214.1	38.4718
1217.33	38.9779
1220.56	39.1087
1223.79	38.3023
1227.01	36.4719
1230.23	34.4309
1233.46	32.9144
1236.68	32.4821
1239.9	33.7717
1243.12	32.8582
1246.34	33.3337
1249.55	32.4598
1252.77	33.4197
1255.98	33.2496
1259.2	32.0663
1262.41	30.0482
1265.62	32.7839
1268.83	33.4799
1272.03	35.7535
1275.24	36.8428
1278.45	36.1207
1281.65	36.5833
1284.85	37.6357
1288.06	38.5514
1291.26	39.3791
1294.46	42.0631
1297.66	44.4284
1300.85	46.3926
1304.05	45.0264
1307.24	44.3432
1310.43	44.8717
1313.63	45.6298
1316.82	46.5706
1320.01	47.1569
1323.2	46.9883
1326.38	47.8305
1329.57	47.8924
1332.76	47.1729
1335.94	47.1731
1339.12	47.875
1342.3	48.7746
1345.48	49.0946
1348.66	48.9268
1351.84	47.4107
1355.01	46.0127
1358.19	43.3693
1361.36	42.4753
1364.53	40.1746
1367.71	39.7602
1370.88	38.5153
1374.04	37.7332
1377.21	36.0402
1380.38	32.5625
1383.54	31.6298
1386.71	31.3218
1389.87	29.9558
1393.03	26.2863
1396.19	25.3298
1399.35	25.2793
1402.51	26.1705
1405.67	28.6172
1408.82	30.7374
1411.98	34.8979
1415.13	39.5716
1418.28	44.2952
1421.43	49.0686
1424.58	54.7999
1427.73	60.3334
1430.88	64.9604
1434.02	69.0467
1437.17	72.7816
1440.31	74.3338
1443.45	75.1463
1446.6	75.4341
1449.74	75.5347
1452.87	74.9966
1456.01	75.3051
1459.15	75.0552
1462.28	75.9879
1465.42	74.373
1468.55	74.1142
1471.68	73.7215
1474.81	73.9942
1477.94	72.8181
1481.07	71.082
1484.2	69.1437
1487.32	66.7511
1490.45	65.3222
1493.57	63.2247
1496.69	59.9136
1499.81	57.2184
1502.93	54.7126
1506.05	50.2937
1509.17	44.0884
1512.28	38.3273
1515.4	33.3271
1518.51	27.4338
1521.63	22.8223
1524.74	20.8356
1527.85	17.6345
1530.96	15.5911
1534.06	16.2435
1537.17	17.786
1540.28	20.7534
1543.38	22.1607
1546.48	21.6291
1549.59	21.0504
1552.69	21.3272
1555.79	22.1547
1558.88	22.896
1561.98	22.9662
1565.08	25.4013
1568.17	27.4461
1571.27	30.1715
1574.36	31.6006
1577.45	34.018
1580.54	33.84
1583.63	37.0201
1586.72	39.6579
1589.8	42.8918
1592.89	44.2338
1595.97	45.3348
1599.06	47.955
1602.14	48.3414
1605.22	48.8951
1608.3	50.4123
1611.38	50.4721
1614.46	50.6082
1617.53	48.7268
1620.61	46.9181
1623.68	45.0653
1626.75	43.4525
1629.82	44.208
1632.9	43.6623
1635.96	43.3109
1639.03	41.8996
1642.1	43.7803
1645.16	42.9926
1648.23	41.976
1651.29	41.7426
1654.36	42.5682
1657.42	42.875
1660.48	44.0989
1663.53	43.286
1666.59	41.8698
1669.65	38.9948
1672.7	39.5706
1675.76	36.3295
1678.81	34.6123
1681.86	32.2614
1684.91	31.8858
1687.96	30.8427
1691.01	29.813
1694.06	27.5259
1697.11	25.3767
1700.15	23.6217
1703.2	22.711
1706.24	21.3979
1709.28	21.2671
1712.32	18.9789
1715.36	17.8416
1718.4	14.8844
1721.43	13.4194
1724.47	11.1809
1727.5	9.26
1730.54	6.50978
1733.57	5.13854
1736.6	5.32152
1739.63	4.34575
1742.66	3.84621
1745.69	3.40922
1748.72	3.3902
1751.74	4.33817
1754.77	5.12065
1757.79	6.43901
1760.81	8.0615
1763.83	8.52906
1766.85	8.45701
1769.87	7.339
1772.89	8.18898
1775.91	8.64575
1778.92	9.38419
1781.94	10.174
1784.95	10.7353
1787.96	9.90792
1790.97	10.1226
1793.98	9.2596
1796.99	8.25684
1800	7.92177
1803	7.86628
1806.01	8.65048
1809.01	10.086
1812.02	12.3511
1815.02	13.0401
1818.02	12.8732
1821.02	13.3467
1824.02	12.4992
1827.01	12.5807
1830.01	12.5619
1833	12.1461
1836	11.8143
1838.99	11.2755
1841.98	11.3779
1844.97	10.6848
1847.96	10.6265
1850.95	11.0329
1853.94	11.3456
1856.92	8.74738
1859.91	8.23767
1862.89	9.5639
1865.88	10.9434
1868.86	13.067
1871.84	13.6147
1874.82	15.5121
1877.8	17.4954
1880.77	18.4783
1882.51	19.864
1885.5	20.7376
1888.48	22.0962
1891.47	21.9434
1894.46	21.5086
1897.44	19.4104
1900.42	18.2762
1903.41	16.6088
1906.39	15.7481
1909.37	15.6839
1912.35	13.8477
1915.32	12.5091
1918.3	10.1637
1921.28	9.07862
1924.25	6.50202
1927.22	3.19932
1930.2	1.24481
1933.17	4.73233
1936.14	5.59145
1939.11	6.5683
1942.08	5.54201
1945.04	6.34124
1948.01	7.84562
1950.97	6.9443
1953.94	6.50559
1956.9	6.06084
1959.86	5.48589
1962.82	5.71714
1965.78	4.13647
1968.74	5.07291
1971.69	3.1399
1974.65	2.34595
1977.61	3.03629
1980.56	4.75433
1983.51	5.1728
1986.46	5.78712
1989.41	6.8253
1992.36	6.35698
1995.31	7.30892
1998.26	7.71941
2001.2	7.95561
2004.15	7.51039
2007.09	7.94609
2010.04	8.59764
2012.98	9.14583
2015.92	8.57334
2018.86	8.34217
2021.8	7.24043
2024.74	7.57209
2027.67	6.91605
2030.61	7.37115
2033.54	7.91325
2036.47	8.64941
2039.41	9.59531
2042.34	8.68477
2045.27	9.71097
2048.2	10.4073
2051.12	13.5738
2054.05	15.1667
2056.98	14.5795
2059.9	15.6016
2062.82	16.3387
2065.75	17.303
2068.67	19.0379
2071.59	18.4674
2074.51	18.9194
2077.43	18.0818
2080.34	18.4615
2083.26	19.3028
2086.17	18.2441
2089.09	19.7205
2092	21.3974
2094.91	22.2384
2097.82	24.6289
2100.73	25.1448
2103.64	26.2048
2106.55	27.594
2109.46	28.3351
2112.36	29.9433
2115.27	31.3938
2118.17	34.1655
2121.07	36.6261
2123.97	38.6127
2126.87	40.9166
2129.77	43.6773
2132.67	45.5515
2135.57	48.3736
2138.46	50.8713
2141.36	51.6114
2144.25	52.929
2147.14	54.8009
2150.03	55.0977
2152.92	56.9701
2155.81	56.6369
2158.7	58.177
2161.59	59.8372
2164.48	60.4702
2167.36	59.2059
2170.25	58.7757
2173.13	57.4353
2176.01	56.7278
2178.89	58.0245
2181.77	58.3268
2184.65	57.7872
2187.53	58.5893
2190.41	57.4438
2193.28	56.3456
2196.16	55.6647
2199.03	54.5142
2201.9	52.7188
2204.78	50.6328
2207.65	49.5334
2210.51	47.4436
2213.38	45.3075
2216.25	43.0833
2219.12	41.2943
2221.98	39.5524
2224.85	37.6037
2227.71	36.2128
2230.57	36.1849
2233.43	34.1637
2236.29	31.5582
2239.15	30.0866
2242.01	29.2417
2244.87	30.0295
2247.73	29.9815
2250.58	27.1708
2253.43	26.1293
2256.29	25.4008
2259.14	22.5466
2261.99	21.0808
2264.84	19.5171
2267.69	18.55
2270.54	17.6656
2273.38	16.9561
2276.23	16.3637
2279.07	16.014
2281.92	13.1746
2284.76	12.1741
2287.6	11.9744
2290.44	10.5516
2293.28	8.81919
2296.12	7.28024
2298.96	8.04486
2301.79	9.05162
2304.63	10.192
2307.46	12.0518
2310.3	12.9778
2313.13	13.3967
2315.96	12.9962
2318.79	12.9059
2321.62	14.5556
2324.45	15.3064
2327.27	15.0914
2330.1	15.421
2332.93	16.2775
2335.75	17.6199
2338.57	16.6648
2341.4	16.7948
2344.22	15.8674
2347.04	13.0233
2349.86	10.3971
2352.67	8.53195
2355.49	7.29825
2358.31	1.98304
2361.12	-2.53788
2363.94	-1.93319
2366.75	0.868742
2369.56	4.90576
2372.37	6.13272
2375.18	7.55614
2377.99	9.08073
2380.8	11.0238
2383.61	12.6321
2386.41	13.0961
2389.22	14.1481
2392.02	15.1758
2394.82	16.7127
2397.63	18.6304
2400.43	18.5975
2403.23	19.0545
2406.02	17.7758
2408.82	18.0597
2411.62	17.6447
2414.41	15.8498
2417.21	14.677
2420	14.7812
2422.79	13.016
2425.59	10.0496
2428.38	6.68222
2431.17	8.74736
2433.96	10.387
2436.74	10.5449
2439.53	9.75224
2442.32	8.8071
2445.1	7.74502
2447.88	7.78265
2450.67	7.65979
2453.45	7.6143
2456.23	6.96338
2459.01	8.62006
2461.79	9.63302
2464.57	8.96057
2467.34	9.38347
2470.12	9.40074
2472.89	10.2032
2475.67	9.28896
2478.44	9.50449
2481.21	8.5769
2483.98	7.87783
2486.75	7.41251
2489.52	6.51847
2492.29	5.65879
2495.06	4.61108
2497.82	3.91581
2500.59	3.091
2503.35	3.14719
2506.11	2.28183
2508.88	1.11288
2511.63	-0.0101671
2514.39	-0.068147
2517.15	1.45104
2519.91	2.7656
2522.67	3.58745
2525.42	5.14276
2528.18	5.54776
2530.93	4.61618
2533.69	5.29619
2536.44	5.88777
2539.19	7.11263
2541.94	7.27528
2544.69	7.44178
2547.44	8.58609
2550.18	8.12937
2552.93	8.12401
2555.68	9.04841
2558.42	8.99724
2561.16	8.47095
2563.9	8.67627
2566.64	9.5724
2569.38	8.74336
2572.12	8.7495
2574.86	8.81109
2577.6	7.84142
2580.34	9.37019
2583.07	9.49259
2585.81	9.58935
2588.54	8.59989
2591.27	7.69242
2594	6.27892
2596.73	4.97425
2599.46	6.02304
2602.19	6.24261
2604.92	7.05173
2607.64	6.24577
2610.37	5.93618
2613.09	6.19259
2615.82	5.54447
2618.54	4.83408
2621.26	4.69265
2623.98	3.79405
2626.7	4.27033
2629.42	5.88877
2632.14	5.41784
2634.86	6.89283
2637.57	6.30275
2640.29	8.79844
2643	9.31377
2645.72	9.50617
2648.43	8.8345
2651.14	8.85746
2653.85	8.41165
2656.56	7.90526
2659.27	8.99264
2661.97	10.5168
2664.68	11.8232
2667.38	13.9582
2670.09	13.453
2672.79	12.6535
2675.49	10.9809
2678.2	10.972
2680.89	10.5331
2683.59	9.73989
2686.29	9.39997
2688.99	9.00933
2691.69	9.74749
2694.38	10.5619
2697.08	7.44099
2699.77	7.1224
2702.46	7.4746
2705.16	6.364
2707.85	8.26372
2710.54	7.40718
2713.23	7.1662
2715.92	7.65118
2718.6	7.64407
2721.29	8.38423
2723.97	9.3958
2726.66	10.4921
2729.34	11.0085
2732.02	12.6126
2734.7	12.1921
2737.39	11.4978
2740.06	11.9645
2742.74	11.2449
2745.42	11.4237
2748.1	10.8176
2750.77	10.7427
2753.45	9.66702
2756.12	10.4521
2758.79	9.88944
2761.47	9.45701
2764.14	8.47755
2766.81	8.51554
2769.48	7.3344
2772.14	8.31381
2774.81	5.97424
2777.48	4.23404
2780.14	3.98094
2782.81	2.63731
2785.47	2.40727
2788.13	1.12596
2790.79	0.740749
2793.46	0.515993
2796.11	0.888831
2798.77	1.66694
2801.43	0.92199
2804.09	0.29876
2806.74	-0.235882
2809.4	-1.79265
2812.05	-2.36993
2814.71	-2.69725
2817.36	0.15954
2820.01	3.47517
2822.66	7.26243
2825.31	11.2545
2827.96	14.5045
2830.61	18.7965
2833.25	24.2883
2835.9	29.2464
2838.54	33.3495
2841.18	38.496
2843.83	43.9103
2846.47	49.8774
2849.11	55.0243
2851.75	58.7171
2854.39	64.5516
2857.03	69.4133
2859.67	75.4957
2862.3	78.9091
2864.94	81.8462
2867.57	83.4233
2870.21	85.0733
2872.84	86.891
2875.47	88.6848
2878.1	88.2592
2880.73	91.7994
2883.36	93.4349
2885.99	95.7668
2888.61	97.434
2891.24	99.7318
2893.87	103.145
2896.49	107.383
2899.11	108.921
2901.74	113.237
2904.36	117.142
2906.98	123.237
2909.6	130.674
2912.22	138.234
2914.83	146.691
2917.45	157.094
2920.07	167.593
2922.68	176.028
2925.3	183.349
2927.91	189.843
2930.52	194.382
2933.13	197.69
2935.74	199.558
2938.35	198.273
2940.96	196.087
2943.57	191.764
2946.18	185.285
2948.78	178.694
2951.39	170.96
2953.99	163.355
2956.6	154.115
2959.2	145.365
2961.8	135.47
2964.4	126.946
2967	118.176
2969.6	111.656
2972.2	105.256
2974.79	99.4268
2977.39	93.9171
2979.98	88.4331
2982.58	84.1431
2985.17	79.0456
2987.76	73.2809
2990.36	70.5595
2992.95	65.6304
2995.54	60.6861
2998.12	54.7687
3000.71	49.0939
3003.3	44.0961
3005.88	37.8774
3008.47	32.7785
3011.05	28.7524
3013.64	26.6056
3016.22	23.1526
3018.8	19.7082
3021.38	16.8575
3023.96	15.1182
3026.54	12.6941
3029.12	10.049
3031.69	8.39678
3034.27	5.94729
3036.85	4.71994
3039.42	3.94622
3041.99	2.92307
3044.57	2.1171
3047.14	1.45734
3049.71	1.26994
3052.28	1.08471
3054.85	1.3992
3057.42	1.5648
3059.98	1.54169
3062.55	2.06456
3065.11	2.91435
3067.68	3.91561
3070.24	4.03269
3072.8	4.8604
3075.37	5.34875
3077.93	4.65687
3080.49	3.92765
3083.05	2.74287
3085.61	2.55352
3088.16	3.3043
3090.72	4.23328
3093.27	4.08703
3095.83	5.19445
3098.38	4.57085
3100.94	5.77729
3103.49	6.52491
3106.04	7.47254
3108.59	8.23775
3111.14	9.19863
3113.69	11.9721
3116.23	14.0991
3118.78	17.0891
3121.33	19.7424
3123.87	22.3678
3126.42	24.5804
3128.96	26.0315
3131.5	27.3513
3134.04	28.8773
3136.58	29.7996
3139.12	29.6862
3141.66	30.3365
3144.2	31.753
3146.74	33.4853
3149.27	32.3541