File: data/Raman/poly_smoothed/Mb_50_18_05_1x_45s_532 nm_x100_100%_600 gr_mm_01.txt
#Acq. time (s)=	45
#Accumulations=	2
#Range (cm-¹)=	200...3150
#Windows=	2
#Auto scanning=	Off
#Autofocus=	Off
#Macrospot=	Off
#AutoExposure=	Off
#Spike filter=	Multiple accum.
#Delay time (s)=	0
#Binning=	1
#Readout mode=	Signal
#DeNoise=	Off
#ICS correction=	On
#Dark correction=	Off
#Inst. Process=	Off
#Detector Gain=	Best Dynamic Range
#Detector ADC=	20 kHz
#Detector temperature (°C)=	-69.85
#Instrument=	LabRAM HR Evol
#Detector=	Synapse
#Objective=	x100
#Grating=	600 gr/mm
#ND Filter=	100%
#Laser (nm)=	532
#Hole=	100.021
#Range=	Auto
#Laser Pol.=	No
#Raman. Pol.=	No
#Laser Pol. (°)=	-0.0007625
#Raman Pol. (°)=	89.9995
#Collection=	Microscope
#StageXY=	Marzhauser
#StageZ=	Marzhauser
#X (µm)=	19359.8
#Y (µm)=	3068.1
#Z (µm)=	1047.55
#Full time(mm:ss)=	3:18
#Project=
#Sample=
#Site=
#Title=	Mb_50_18_05_2x_45s_532 nm_x100_100%_600 gr_mm
#Remark=
#Date=	12.07.2022 10:35
#Acquired=	12.07.2022 10:35:41
#Base:Fit=	10.08.2022 10:49:18
#Base:Sub=	10.08.2022 10:49:30
#Filter:Polynom=	16.08.2022 10:14:59
#AxisType[0]=Intens
#AxisUnit[0]=Cnt
#AxisType[1]=Spectr
#AxisUnit[1]=1/cm
200.388	11.6626
204.019	9.48384
207.646	7.13362
211.274	5.31958
214.899	4.43143
218.524	2.61485
222.146	2.51768
225.766	1.19163
229.388	0.165347
233.005	-0.0191134
236.621	0.820132
240.236	1.40433
243.852	2.28319
247.464	3.14161
251.074	3.69079
254.683	4.79882
258.291	5.0323
261.897	5.81378
265.504	4.52068
269.108	3.79718
272.71	3.95328
276.311	3.78284
279.91	2.90974
283.508	4.44019
287.105	5.43769
290.698	6.9279
294.291	7.17436
297.884	7.46658
301.475	9.28123
305.064	12.1337
308.652	13.8507
312.237	14.9603
315.822	17.0684
319.406	19.2706
322.987	22.0896
326.568	23.3996
330.148	24.4475
333.724	25.128
337.301	23.1788
340.875	23.5608
344.449	23.6197
348.02	23.5005
351.592	24.0472
355.16	26.7985
358.728	27.5436
362.294	28.3808
365.858	30.5281
369.422	31.4751
372.983	33.156
376.543	35.0637
380.102	36.6173
383.661	36.9506
387.216	38.9671
390.771	40.5815
394.324	39.6615
397.875	38.4829
401.425	36.254
404.974	35.2846
408.524	31.4202
412.07	27.8004
415.614	24.468
419.156	21.1358
422.698	16.8249
426.238	13.8759
429.777	12.639
433.315	11.1954
436.852	9.64022
440.387	8.73644
443.919	9.08157
447.451	9.02973
450.982	10.5323
454.512	12.3748
458.038	12.5458
461.565	14.1557
465.091	15.3524
468.613	18.1277
472.136	19.9275
475.655	21.7612
479.176	24.4045
482.692	26.7477
486.21	30.8866
489.724	32.8852
493.237	35.5859
496.75	37.716
500.26	40.7159
503.771	42.0803
507.279	42.9062
510.785	43.6356
514.289	45.5208
517.793	43.4658
521.297	42.5283
524.797	41.983
528.297	40.9325
531.795	40.0608
535.291	38.3327
538.787	34.2645
542.281	30.4453
545.773	26.2507
549.264	23.5871
552.754	18.9705
556.243	16.2351
559.73	13.2429
563.216	10.7427
566.701	10.1494
570.182	8.9
573.664	8.36228
577.145	6.76237
580.624	5.99336
584.1	6.71651
587.577	8.09084
591.052	7.82389
594.524	7.06386
597.997	8.21946
601.466	9.96539
604.936	9.77337
608.403	11.2395
611.87	11.6783
615.334	11.6061
618.799	12.7458
622.26	11.4913
625.72	10.7018
629.181	11.0584
632.638	10.3774
636.095	9.14072
639.551	7.0225
643.005	6.164
646.457	5.46561
649.908	4.18254
653.357	5.08637
656.806	4.72055
660.253	6.67693
663.7	5.68334
667.145	6.61194
670.588	8.34585
674.027	8.93478
677.468	10.7053
680.907	13.6947
684.345	17.4994
687.781	20.3639
691.216	22.216
694.65	22.7068
698.081	23.7179
701.512	25.5174
704.942	27.2124
708.371	29.0398
711.796	30.052
715.222	30.0871
718.645	30.013
722.068	30.4311
725.49	33.138
728.909	34.2856
732.329	37.3402
735.745	41.6427
739.16	47.3968
742.576	52.9667
745.988	57.503
749.401	62.7292
752.811	69.1114
756.22	73.5325
759.627	77.5808
763.035	81.9715
766.44	85.2085
769.843	87.9922
773.245	89.1218
776.646	89.3133
780.046	90.2902
783.444	91.2159
786.841	92.8096
790.237	91.6445
793.631	90.9275
797.024	87.1803
800.416	85.4457
803.807	81.1301
807.196	79.9628
810.584	77.6091
813.971	75.6749
817.354	75.6888
820.739	75.2606
824.122	74.5593
827.503	71.7579
830.882	70.8252
834.261	67.9021
837.637	64.9386
841.013	61.1091
844.389	59.1984
847.761	55.5653
851.131	53.4892
854.503	49.1975
857.871	46.0716
861.24	43.3368
864.606	42.1666
867.97	41.0565
871.336	38.759
874.698	36.4098
878.058	33.4283
881.418	31.7852
884.778	29.146
888.135	28.4669
891.49	28.8377
894.845	28.4858
898.198	28.6788
901.55	29.1565
904.901	29.8036
908.25	29.6873
911.598	30.3456
914.945	31.1293
918.291	29.5007
921.635	28.1193
924.978	28.5026
928.318	26.4433
931.659	24.415
934.998	22.4671
938.336	21.4836
941.671	18.9003
945.007	17.2909
948.339	16.8684
951.672	17.4151
955.004	16.4059
958.333	15.2165
961.662	14.4005
964.989	13.6752
968.315	12.8354
971.639	13.9608
974.962	14.3344
978.285	14.2746
981.605	11.6839
984.924	10.5608
988.243	10.6545
991.56	10.3367
994.875	11.2588
998.188	11.4136
1001.5	13.0893
1004.81	14.4517
1008.12	18.7555
1011.43	21.7954
1014.74	23.9836
1018.05	26.1568
1021.35	27.9409
1024.65	28.1955
1027.96	30.396
1031.26	31.9608
1034.56	32.4372
1037.86	32.4281
1041.16	31.7522
1044.45	30.7487
1047.75	31.0446
1051.04	30.0492
1054.33	27.4481
1057.62	25.9315
1060.91	24.8237
1064.2	23.5532
1067.49	22.9267
1070.77	22.4448
1074.06	22.2384
1077.34	22.1023
1080.62	22.293
1083.91	22.3608
1087.18	21.5866
1090.46	21.6708
1093.74	21.2834
1097.02	20.7198
1100.29	18.8364
1103.56	16.3123
1106.84	15.0995
1110.11	13.6692
1113.38	11.051
1116.64	11.348
1119.91	11.9168
1123.18	12.6494
1126.44	12.0885
1129.7	11.9106
1132.97	11.7344
1136.23	13.2579
1139.49	13.3819
1142.74	13.7177
1146	12.6572
1149.26	12.0233
1152.51	11.0656
1155.76	10.2333
1159.01	9.61842
1162.27	9.33197
1165.51	8.43419
1168.76	6.95699
1172.01	7.25971
1175.25	6.3557
1178.5	4.22704
1181.74	3.35727
1184.98	2.80476
1188.22	4.28426
1191.46	2.88035
1194.7	3.97911
1197.94	5.18735
1201.17	6.6601
1204.41	6.39641
1207.64	6.07063
1210.87	7.79326
1214.1	8.25913
1217.33	9.68436
1220.56	11.442
1223.79	14.9101
1227.01	15.9851
1230.23	17.7241
1233.46	20.0371
1236.68	23.5158
1239.9	26.3505
1243.12	28.0751
1246.34	30.4343
1249.55	32.5233
1252.77	36.2668
1255.98	37.3963
1259.2	40.6161
1262.41	44.9688
1265.62	46.6586
1268.83	49.2343
1272.03	51.4855
1275.24	52.8875
1278.45	55.9453
1281.65	58.5672
1284.85	59.5794
1288.06	62.0774
1291.26	65.4158
1294.46	67.0064
1297.66	68.1751
1300.85	67.8615
1304.05	67.6536
1307.24	66.5044
1310.43	66.4394
1313.63	65.2683
1316.82	64.1378
1320.01	62.2754
1323.2	61.4218
1326.38	60.8762
1329.57	59.8575
1332.76	58.1378
1335.94	56.0075
1339.12	53.5724
1342.3	51.07
1345.48	48.8095
1348.66	45.9046
1351.84	43.3295
1355.01	41.4844
1358.19	39.4699
1361.36	37.7403
1364.53	37.3358
1367.71	36.4995
1370.88	36.5951
1374.04	33.6583
1377.21	32.8759
1380.38	31.6642
1383.54	31.2554
1386.71	29.8599
1389.87	28.7557
1393.03	27.5072
1396.19	25.8113
1399.35	26.4134
1402.51	27.7481
1405.67	29.8848
1408.82	31.3935
1411.98	33.0295
1415.13	35.5734
1418.28	39.4608
1421.43	43.7865
1424.58	47.9887
1427.73	53.9364
1430.88	58.4959
1434.02	62.7248
1437.17	68.7719
1440.31	72.9646
1443.45	78.1882
1446.6	81.5892
1449.74	84.2794
1452.87	86.1036
1456.01	87.5235
1459.15	88.6502
1462.28	89.7905
1465.42	89.871
1468.55	88.2709
1471.68	86.6763
1474.81	85.4324
1477.94	84.8553
1481.07	84.6212
1484.2	81.4642
1487.32	79.3016
1490.45	76.2693
1493.57	74.2844
1496.69	71.6507
1499.81	67.8468
1502.93	63.2177
1506.05	57.9564
1509.17	52.6617
1512.28	47.1926
1515.4	40.863
1518.51	37.077
1521.63	32.058
1524.74	27.9444
1527.85	24.7202
1530.96	20.9747
1534.06	20.095
1537.17	18.9823
1540.28	18.1479
1543.38	18.5609
1546.48	18.6332
1549.59	19.6654
1552.69	20.6197
1555.79	21.839
1558.88	22.0796
1561.98	25.5283
1565.08	27.3468
1568.17	31.1665
1571.27	36.8851
1574.36	39.5672
1577.45	43.6245
1580.54	46.2387
1583.63	49.2453
1586.72	51.6639
1589.8	54.1126
1592.89	55.5091
1595.97	57.5166
1599.06	56.8984
1602.14	56.7557
1605.22	56.9173
1608.3	57.9927
1611.38	59.8127
1614.46	59.2761
1617.53	59.7576
1620.61	59.69
1623.68	59.1534
1626.75	59.4229
1629.82	61.1516
1632.9	62.2383
1635.96	64.459
1639.03	68.4739
1642.1	71.3414
1645.16	75.7729
1648.23	76.9275
1651.29	77.9079
1654.36	76.9378
1657.42	75.5499
1660.48	73.4628
1663.53	70.3435
1666.59	66.1077
1669.65	61.7459
1672.7	56.6637
1675.76	51.0044
1678.81	46.5141
1681.86	43.1838
1684.91	39.6224
1687.96	34.8067
1691.01	28.8282
1694.06	25.4958
1697.11	20.5199
1700.15	17.3069
1703.2	15.0495
1706.24	13.7461
1709.28	11.6005
1712.32	11.1635
1715.36	10.7024
1718.4	9.93941
1721.43	8.37738
1724.47	7.83356
1727.5	6.19903
1730.54	5.41912
1733.57	5.22697
1736.6	4.55756
1739.63	3.56579
1742.66	3.35891
1745.69	2.68021
1748.72	2.8042
1751.74	2.99277
1754.77	2.48126
1757.79	2.45556
1760.81	1.87905
1763.83	1.29108
1766.85	1.12263
1769.87	1.39759
1772.89	0.91337
1775.91	0.616666
1778.92	0.899194
1781.94	1.75868
1784.95	0.990445
1787.96	1.22094
1790.97	1.42602
1793.98	1.11358
1796.99	1.61564
1800	1.75781
1803	2.29952
1806.01	1.8493
1809.01	2.53988
1812.02	2.68116
1815.02	2.08639
1818.02	2.71898
1821.02	2.74065
1824.02	3.11302
1827.01	3.22049
1830.01	3.71995
1833	4.10896
1836	5.26078
1838.99	5.55728
1841.98	6.49531
1844.97	6.1088
1847.96	5.89809
1850.95	5.36488
1853.94	5.6327
1856.92	4.14099
1859.91	3.45584
1862.89	2.9647
1865.88	1.60449
1868.86	1.42403
1871.84	1.2284
1874.82	0.0550312
1877.8	-0.499637
1880.77	-0.70876
1882.51	-0.827615
1885.5	-0.698721
1888.48	-1.16417
1891.47	-0.90645
1894.46	-0.477133
1897.44	-0.0341364
1900.42	-0.0270256
1903.41	0.376334
1906.39	1.07809
1909.37	1.68378
1912.35	1.93722
1915.32	2.66028
1918.3	3.40051
1921.28	4.08582
1924.25	3.80616
1927.22	3.20637
1930.2	2.22834
1933.17	2.34815
1936.14	2.14466
1939.11	1.71782
1942.08	2.42675
1945.04	2.86388
1948.01	2.58908
1950.97	4.47803
1953.94	5.72305
1956.9	6.14153
1959.86	6.56296
1962.82	6.9668
1965.78	6.63876
1968.74	6.3607
1971.69	5.41916
1974.65	5.08854
1977.61	5.23959
1980.56	5.94155
1983.51	7.21175
1986.46	7.75439
1989.41	7.88781
1992.36	8.32563
1995.31	7.97294
1998.26	8.27059
2001.2	7.97446
2004.15	8.36086
2007.09	9.66107
2010.04	9.61266
2012.98	10.5572
2015.92	12.1639
2018.86	13.6418
2021.8	14.168
2024.74	15.2473
2027.67	14.8511
2030.61	13.9039
2033.54	13.3883
2036.47	12.4899
2039.41	12.5282
2042.34	11.407
2045.27	11.3766
2048.2	11.7872
2051.12	11.8082
2054.05	11.802
2056.98	11.3838
2059.9	11.6584
2062.82	12.5757
2065.75	14.4878
2068.67	16.0615
2071.59	18.5872
2074.51	20.3503
2077.43	21.8327
2080.34	23.6601
2083.26	25.4484
2086.17	27.6875
2089.09	30.2523
2092	33.0468
2094.91	34.4353
2097.82	36.0592
2100.73	38.2594
2103.64	39.806
2106.55	41.6557
2109.46	44.4787
2112.36	46.299
2115.27	48.7717
2118.17	50.6421
2121.07	53.5193
2123.97	56.2087
2126.87	59.6412
2129.77	63.5728
2132.67	67.3324
2135.57	71.4592
2138.46	75.6853
2141.36	79.2803
2144.25	83.0706
2147.14	86.0697
2150.03	89.1692
2152.92	92.6073
2155.81	95.505
2158.7	98.7434
2161.59	100.608
2164.48	101.88
2167.36	102.066
2170.25	102.699
2173.13	102.473
2176.01	100.331
2178.89	97.9511
2181.77	95.2724
2184.65	93.6409
2187.53	90.4079
2190.41	87.3521
2193.28	84.1858
2196.16	81.4685
2199.03	77.6162
2201.9	74.3314
2204.78	70.7866
2207.65	67.7405
2210.51	64.3296
2213.38	62.1087
2216.25	59.0291
2219.12	56.9039
2221.98	54.6889
2224.85	52.6602
2227.71	51.4419
2230.57	49.1176
2233.43	47.3216
2236.29	44.1761
2239.15	41.8765
2242.01	39.557
2244.87	36.6024
2247.73	34.4544
2250.58	32.3101
2253.43	31.556
2256.29	30.6749
2259.14	29.8884
2261.99	28.8169
2264.84	27.6868
2267.69	28.2487
2270.54	27.5826
2273.38	26.7843
2276.23	25.5523
2279.07	25.4152
2281.92	23.788
2284.76	22.6512
2287.6	20.9616
2290.44	20.5582
2293.28	17.3949
2296.12	17.3205
2298.96	15.5566
2301.79	14.3447
2304.63	13.7419
2307.46	12.9614
2310.3	11.4269
2313.13	11.6663
2315.96	9.88686
2318.79	9.14648
2321.62	8.61986
2324.45	9.1785
2327.27	9.424
2330.1	10.0179
2332.93	10.606
2335.75	11.7422
2338.57	12.219
2341.4	12.3961
2344.22	12.3135
2347.04	11.9662
2349.86	10.6401
2352.67	9.50261
2355.49	9.64375
2358.31	9.92147
2361.12	9.42877
2363.94	10.044
2366.75	10.1359
2369.56	10.2491
2372.37	9.40067
2375.18	9.75053
2377.99	8.90829
2380.8	7.54621
2383.61	7.19201
2386.41	6.44329
2389.22	6.13359
2392.02	6.35281
2394.82	5.97031
2397.63	6.32276
2400.43	7.18022
2403.23	6.7208
2406.02	7.06988
2408.82	8.20275
2411.62	8.93061
2414.41	10.2175
2417.21	11.4011
2420	12.7883
2422.79	13.2349
2425.59	14.8931
2428.38	14.3604
2431.17	13.6116
2433.96	11.9376
2436.74	11.4907
2439.53	10.995
2442.32	10.1794
2445.1	10.0032
2447.88	7.67567
2450.67	6.52457
2453.45	5.89641
2456.23	5.0072
2459.01	4.84375
2461.79	4.8497
2464.57	4.49394
2467.34	6.16493
2470.12	5.87738
2472.89	5.84837
2475.67	5.96075
2478.44	6.7286
2481.21	7.70588
2483.98	7.97496
2486.75	7.67238
2489.52	5.45901
2492.29	5.34669
2495.06	4.10188
2497.82	2.95437
2500.59	1.73603
2503.35	2.66361
2506.11	2.58908
2508.88	2.33637
2511.63	2.62894
2514.39	2.26535
2517.15	2.24939
2519.91	2.32159
2522.67	3.42298
2525.42	4.53212
2528.18	5.30757
2530.93	5.86788
2533.69	6.78331
2536.44	7.07299
2539.19	7.84798
2541.94	8.18925
2544.69	8.14991
2547.44	8.96552
2550.18	8.07357
2552.93	8.18333
2555.68	8.46917
2558.42	7.88415
2561.16	8.03722
2563.9	8.63555
2566.64	8.46242
2569.38	8.50473
2572.12	8.92363
2574.86	9.46801
2577.6	9.48338
2580.34	9.10101
2583.07	9.31239
2585.81	9.52722
2588.54	9.37753
2591.27	10.3313
2594	10.4958
2596.73	10.637
2599.46	10.3562
2602.19	10.7382
2604.92	10.7521
2607.64	9.81326
2610.37	9.56362
2613.09	8.8081
2615.82	9.39123
2618.54	9.66279
2621.26	9.41595
2623.98	8.32747
2626.7	7.37162
2629.42	7.84941
2632.14	7.53314
2634.86	6.21975
2637.57	7.0528
2640.29	6.64898
2643	6.56942
2645.72	6.46909
2648.43	7.86806
2651.14	8.53078
2653.85	8.63304
2656.56	8.9182
2659.27	9.39486
2661.97	9.50331
2664.68	9.6798
2667.38	9.57648
2670.09	9.61217
2672.79	9.25013
2675.49	9.43839
2678.2	9.97183
2680.89	10.5415
2683.59	10.4215
2686.29	10.0223
2688.99	9.33405
2691.69	9.13143
2694.38	8.58717
2697.08	8.94173
2699.77	8.37672
2702.46	8.25162
2705.16	8.01898
2707.85	8.43974
2710.54	8.75002
2713.23	8.26413
2715.92	7.80228
2718.6	8.41117
2721.29	7.84928
2723.97	8.3516
2726.66	8.107
2729.34	8.12376
2732.02	7.91575
2734.7	7.52255
2737.39	6.63776
2740.06	5.9658
2742.74	6.11429
2745.42	6.24533
2748.1	5.98859
2750.77	5.0968
2753.45	4.42519
2756.12	4.34235
2758.79	3.8151
2761.47	3.5545
2764.14	2.65972
2766.81	3.50737
2769.48	3.18234
2772.14	2.7416
2774.81	2.62789
2777.48	1.24277
2780.14	0.784859
2782.81	1.13419
2785.47	0.999885
2788.13	0.320904
2790.79	-0.189963
2793.46	-0.18877
2796.11	-0.77843
2798.77	-1.78665
2801.43	-1.439
2804.09	-1.4937
2806.74	-1.22394
2809.4	-1.19231
2812.05	-1.56562
2814.71	-1.56928
2817.36	-0.297642
2820.01	2.11684
2822.66	4.24852
2825.31	8.40866
2827.96	12.7141
2830.61	18.8854
2833.25	23.7274
2835.9	29.1371
2838.54	35.5237
2841.18	42.7093
2843.83	49.6357
2846.47	57.4538
2849.11	64.6298
2851.75	72.6675
2854.39	80.0433
2857.03	87.1935
2859.67	93.2844
2862.3	98.7426
2864.94	104.344
2867.57	109.755
2870.21	113.49
2872.84	116.527
2875.47	119.021
2878.1	121.657
2880.73	124.955
2883.36	128.235
2885.99	131.733
2888.61	135.547
2891.24	139.3
2893.87	143.86
2896.49	149.14
2899.11	154.742
2901.74	161.522
2904.36	167.539
2906.98	174.896
2909.6	183.019
2912.22	191.681
2914.83	199.268
2917.45	207.106
2920.07	213.594
2922.68	219.477
2925.3	223.45
2927.91	225.884
2930.52	227.25
2933.13	225.673
2935.74	223.354
2938.35	219.389
2940.96	215.009
2943.57	210.093
2946.18	203.867
2948.78	196.757
2951.39	189.421
2953.99	180.165
2956.6	172.501
2959.2	164.723
2961.8	156.224
2964.4	147.856
2967	139.001
2969.6	130.883
2972.2	122.986
2974.79	115.104
2977.39	107.668
2979.98	99.2842
2982.58	91.6285
2985.17	83.062
2987.76	75.0323
2990.36	65.5312
2992.95	57.5274
2995.54	50.2387
2998.12	43.7143
3000.71	38.2459
3003.3	32.9931
3005.88	28.114
3008.47	23.4109
3011.05	19.0015
3013.64	15.3032
3016.22	12.1269
3018.8	9.88972
3021.38	8.82473
3023.96	7.94283
3026.54	7.27659
3029.12	5.41917
3031.69	4.25615
3034.27	4.0124
3036.85	4.65454
3039.42	4.42931
3041.99	5.82355
3044.57	6.49744
3047.14	7.11762
3049.71	8.41952
3052.28	8.87037
3054.85	9.10696
3057.42	9.95625
3059.98	10.4914
3062.55	10.1533
3065.11	9.61202
3067.68	8.89779
3070.24	7.66622
3072.8	6.10465
3075.37	5.33507
3077.93	3.86401
3080.49	3.04025
3083.05	1.95857
3085.61	0.856176
3088.16	0.637495
3090.72	-0.552966
3093.27	-0.390525
3095.83	-0.169278
3098.38	0.594714
3100.94	0.787366
3103.49	2.33129
3106.04	3.71956
3108.59	4.59914
3111.14	6.90967
3113.69	8.72723
3116.23	10.6599
3118.78	13.4009
3121.33	15.0534
3123.87	16.9932
3126.42	19.6167
3128.96	21.5011
3131.5	23.7063
3134.04	25.56
3136.58	27.9231
3139.12	29.878
3141.66	31.9974
3144.2	33.5706
3146.74	35.7292
3149.27	35.4545