File: data/Raman/poly_smoothed/Mb_50_18_37_1x_45s_532 nm_x100_100%_600 gr_mm_01.txt
#Acq. time (s)=	45
#Accumulations=	2
#Range (cm-¹)=	200...3150
#Windows=	2
#Auto scanning=	Off
#Autofocus=	Off
#Macrospot=	Off
#AutoExposure=	Off
#Spike filter=	Multiple accum.
#Delay time (s)=	0
#Binning=	1
#Readout mode=	Signal
#DeNoise=	Off
#ICS correction=	On
#Dark correction=	Off
#Inst. Process=	Off
#Detector Gain=	Best Dynamic Range
#Detector ADC=	20 kHz
#Detector temperature (°C)=	-69.85
#Instrument=	LabRAM HR Evol
#Detector=	Synapse
#Objective=	x100
#Grating=	600 gr/mm
#ND Filter=	100%
#Laser (nm)=	532
#Hole=	100.021
#Range=	Auto
#Laser Pol.=	No
#Raman. Pol.=	No
#Laser Pol. (°)=	-0.0007625
#Raman Pol. (°)=	89.9995
#Collection=	Microscope
#StageXY=	Marzhauser
#StageZ=	Marzhauser
#X (µm)=	28285
#Y (µm)=	-3222.9
#Z (µm)=	1041.05
#Full time(mm:ss)=	3:19
#Project=
#Sample=
#Site=
#Title=	Mb_50_18_37_2x_45s_532 nm_x100_100%_600 gr_mm
#Remark=
#Date=	12.07.2022 13:45
#Acquired=	12.07.2022 13:45:57
#Base:Fit=	10.08.2022 10:49:18
#Base:Sub=	10.08.2022 10:49:30
#Filter:Polynom=	16.08.2022 10:14:59
#AxisType[0]=Intens
#AxisUnit[0]=Cnt
#AxisType[1]=Spectr
#AxisUnit[1]=1/cm
200.388	97.0894
204.019	84.9305
207.646	77.9597
211.274	70.7665
214.899	65.4301
218.524	58.8501
222.146	52.7005
225.766	45.9907
229.388	40.8704
233.005	37.615
236.621	34.7709
240.236	30.9069
243.852	28.0333
247.464	25.4596
251.074	24.2481
254.683	23.811
258.291	22.0991
261.897	17.286
265.504	14.0817
269.108	11.5475
272.71	6.44871
276.311	4.31154
279.91	5.3515
283.508	6.66114
287.105	9.37581
290.698	11.0065
294.291	16.2975
297.884	19.6211
301.475	24.0071
305.064	29.1734
308.652	34.3506
312.237	37.378
315.822	41.9383
319.406	44.8927
322.987	48.3206
326.568	48.2363
330.148	45.6393
333.724	39.1882
337.301	32.1997
340.875	27.7741
344.449	25.0286
348.02	27.6959
351.592	34.3347
355.16	48.1961
358.728	62.5916
362.294	78.8185
365.858	93.8584
369.422	108.51
372.983	125.299
376.543	138.164
380.102	149.886
383.661	161.193
387.216	165.27
390.771	168.395
394.324	168.392
397.875	164.908
401.425	157.271
404.974	145.145
408.524	129.716
412.07	110.166
415.614	88.474
419.156	63.7031
422.698	42.8262
426.238	26.7674
429.777	14.5153
433.315	8.32956
436.852	6.5644
440.387	5.56568
443.919	4.81644
447.451	4.92846
450.982	3.13578
454.512	3.13241
458.038	4.51061
461.565	6.17159
465.091	8.49824
468.613	9.05121
472.136	11.8324
475.655	16.8876
479.176	27.5882
482.692	42.2882
486.21	59.8812
489.724	77.745
493.237	96.4049
496.75	115.423
500.26	133.313
503.771	148.433
507.279	159.214
510.785	170.392
514.289	177.907
517.793	180.906
521.297	182.476
524.797	179.329
528.297	173.627
531.795	163.936
535.291	151.132
538.787	136.284
542.281	118.593
545.773	98.7071
549.264	78.3972
552.754	59.1089
556.243	41.0189
559.73	29.5087
563.216	21.8495
566.701	19.7159
570.182	20.2542
573.664	22.0213
577.145	25.2371
580.624	27.7683
584.1	30.4875
587.577	29.669
591.052	30.7193
594.524	33.6663
597.997	38.1384
601.466	40.0666
604.936	41.5786
608.403	43.0867
611.87	44.8075
615.334	41.5366
618.799	39.0175
622.26	35.3922
625.72	31.3701
629.181	29.1825
632.638	25.2734
636.095	19.1192
639.551	15.0329
643.005	11.8306
646.457	9.36733
649.908	10.0906
653.357	7.68223
656.806	7.85986
660.253	5.07516
663.7	2.85073
667.145	0.303231
670.588	-1.16708
674.027	-1.50621
677.468	3.07257
680.907	6.23936
684.345	8.73265
687.781	11.8929
691.216	15.7201
694.65	21.4466
698.081	23.1357
701.512	24.7565
704.942	29.6486
708.371	32.057
711.796	36.999
715.222	37.1257
718.645	36.1875
722.068	33.5568
725.49	30.1454
728.909	30.5139
732.329	37.1837
735.745	49.5744
739.16	68.9774
742.576	97.8932
745.988	129.519
749.401	162.605
752.811	197.375
756.22	227.741
759.627	255.379
763.035	277.042
766.44	292.835
769.843	305.038
773.245	312.204
776.646	313.098
780.046	306.384
783.444	296.722
786.841	280.423
790.237	259.642
793.631	234.548
797.024	203.488
800.416	169.044
803.807	135.668
807.196	101.287
810.584	76.2996
813.971	59.9065
817.354	50.9266
820.739	49.1722
824.122	50.8807
827.503	55.7263
830.882	59.1262
834.261	62.0721
837.637	63.5491
841.013	60.872
844.389	59.7183
847.761	58.0856
851.131	54.2849
854.503	53.0504
857.871	50.2424
861.24	48.8597
864.606	46.8651
867.97	45.9929
871.336	41.7216
874.698	40.221
878.058	37.9711
881.418	33.8374
884.778	31.4833
888.135	27.9574
891.49	27.3781
894.845	28.4663
898.198	26.5582
901.55	26.7271
904.901	26.6953
908.25	24.9477
911.598	24.9165
914.945	24.2167
918.291	22.7371
921.635	22.7392
924.978	21.26
928.318	18.7257
931.659	13.7224
934.998	11.9625
938.336	10.9634
941.671	9.37905
945.007	7.15359
948.339	7.67327
951.672	9.46542
955.004	11.2101
958.333	10.2825
961.662	6.99861
964.989	10.1966
968.315	15.0905
971.639	17.8732
974.962	23.2827
978.285	28.3983
981.605	32.6673
984.924	35.3494
988.243	38.9254
991.56	48.9911
994.875	62.8377
998.188	85.3243
1001.5	110.159
1004.81	137.127
1008.12	163.09
1011.43	188.986
1014.74	215.729
1018.05	238.416
1021.35	255.47
1024.65	268.815
1027.96	280.462
1031.26	284.757
1034.56	281.628
1037.86	272.747
1041.16	256.886
1044.45	243.447
1047.75	229.036
1051.04	209.859
1054.33	196.37
1057.62	182.915
1060.91	172.43
1064.2	165.16
1067.49	160.672
1070.77	164.722
1074.06	170.505
1077.34	178.629
1080.62	187.25
1083.91	194.99
1087.18	199.589
1090.46	203.473
1093.74	201.584
1097.02	199.549
1100.29	191.345
1103.56	182.257
1106.84	170.149
1110.11	152.906
1113.38	132.889
1116.64	111.54
1119.91	88.3992
1123.18	69.2625
1126.44	54.3649
1129.7	42.7092
1132.97	35.6161
1136.23	32.2825
1139.49	29.6765
1142.74	29.3648
1146	27.3431
1149.26	25.5836
1152.51	22.3335
1155.76	18.8131
1159.01	19.7229
1162.27	18.0733
1165.51	18.6636
1168.76	19.3893
1172.01	22.8808
1175.25	26.204
1178.5	26.6698
1181.74	29.5059
1184.98	31.795
1188.22	36.001
1191.46	37.0575
1194.7	36.1751
1197.94	38.4805
1201.17	43.8924
1204.41	49.3404
1207.64	55.3268
1210.87	59.2218
1214.1	65.3601
1217.33	70.0327
1220.56	74.9185
1223.79	81.2643
1227.01	88.7914
1230.23	94.3553
1233.46	99.6791
1236.68	104.716
1239.9	111.139
1243.12	114.73
1246.34	119.477
1249.55	123.489
1252.77	126.945
1255.98	128.917
1259.2	131.225
1262.41	137.039
1265.62	140.214
1268.83	145.26
1272.03	147.404
1275.24	152.295
1278.45	157.209
1281.65	162.766
1284.85	167.23
1288.06	168.945
1291.26	172.117
1294.46	175.514
1297.66	175.716
1300.85	176.694
1304.05	178.182
1307.24	178.512
1310.43	175.208
1313.63	171.401
1316.82	169.124
1320.01	165.584
1323.2	159.569
1326.38	153.435
1329.57	148.431
1332.76	140.712
1335.94	132.472
1339.12	126.193
1342.3	123.254
1345.48	117.495
1348.66	111.014
1351.84	105.414
1355.01	99.1559
1358.19	93.2927
1361.36	87.4327
1364.53	82.0931
1367.71	75.0278
1370.88	70.9632
1374.04	65.8698
1377.21	61.8381
1380.38	58.0987
1383.54	55.4921
1386.71	52.138
1389.87	49.8735
1393.03	48.2733
1396.19	47.6023
1399.35	48.9193
1402.51	52.8177
1405.67	59.8766
1408.82	71.0126
1411.98	80.1907
1415.13	96.6696
1418.28	114.463
1421.43	132.942
1424.58	148.382
1427.73	167.185
1430.88	184.127
1434.02	198.424
1437.17	212.026
1440.31	222.163
1443.45	227.192
1446.6	230.979
1449.74	231.638
1452.87	229.178
1456.01	222.251
1459.15	212.622
1462.28	202.873
1465.42	189.436
1468.55	174.365
1471.68	158.481
1474.81	143.999
1477.94	131.805
1481.07	116.207
1484.2	101.679
1487.32	88.8993
1490.45	77.879
1493.57	69.9884
1496.69	62.0927
1499.81	56.5362
1502.93	50.6044
1506.05	46.4101
1509.17	40.8751
1512.28	34.9107
1515.4	31.4025
1518.51	28.2861
1521.63	27.1584
1524.74	25.9927
1527.85	26.7063
1530.96	27.6702
1534.06	28.3467
1537.17	32.0469
1540.28	35.5356
1543.38	39.7076
1546.48	42.9607
1549.59	46.9022
1552.69	49.6652
1555.79	51.294
1558.88	52.2894
1561.98	54.794
1565.08	60.4117
1568.17	69.3079
1571.27	77.5079
1574.36	85.7784
1577.45	95.8071
1580.54	102.631
1583.63	111.477
1586.72	116.682
1589.8	122.619
1592.89	128.023
1595.97	132.858
1599.06	133.282
1602.14	133.722
1605.22	134.939
1608.3	134.475
1611.38	134.302
1614.46	136.602
1617.53	138.834
1620.61	142.754
1623.68	145.767
1626.75	148.396
1629.82	152.992
1632.9	158.6
1635.96	165.607
1639.03	175.093
1642.1	187.016
1645.16	196.808
1648.23	204.151
1651.29	211.115
1654.36	216.406
1657.42	217.224
1660.48	217.063
1663.53	210.095
1666.59	204.734
1669.65	194.393
1672.7	183.201
1675.76	167.409
1678.81	153.41
1681.86	136.901
1684.91	122.155
1687.96	106.152
1691.01	93.0806
1694.06	80.0833
1697.11	68.157
1700.15	57.3579
1703.2	46.3875
1706.24	38.0097
1709.28	30.8645
1712.32	25.7386
1715.36	20.8326
1718.4	16.268
1721.43	12.578
1724.47	9.89189
1727.5	9.17958
1730.54	7.50246
1733.57	8.2617
1736.6	5.99957
1739.63	6.27752
1742.66	5.7162
1745.69	4.74206
1748.72	4.50475
1751.74	3.90052
1754.77	4.13705
1757.79	3.3035
1760.81	3.09437
1763.83	2.39503
1766.85	2.5456
1769.87	1.66163
1772.89	2.20641
1775.91	1.57487
1778.92	0.709135
1781.94	0.544344
1784.95	0.916376
1787.96	0.679522
1790.97	-0.648274
1793.98	-0.411642
1796.99	-2.01092
1800	-1.72755
1803	-1.21405
1806.01	-1.48225
1809.01	-0.915755
1812.02	-1.53447
1815.02	0.975474
1818.02	-0.286324
1821.02	-0.270248
1824.02	1.48453
1827.01	2.95194
1830.01	3.48499
1833	2.6594
1836	3.78342
1838.99	5.66642
1841.98	7.35328
1844.97	9.44722
1847.96	9.23279
1850.95	9.58094
1853.94	9.11532
1856.92	10.1348
1859.91	10.3802
1862.89	9.62888
1865.88	10.5833
1868.86	11.8011
1871.84	13.2252
1874.82	14.3683
1877.8	14.9026
1880.77	14.6138
1882.51	14.4344
1885.5	16.1327
1888.48	16.9802
1891.47	16.9733
1894.46	18.7271
1897.44	19.7447
1900.42	17.4895
1903.41	15.1502
1906.39	15.6281
1909.37	17.7249
1912.35	15.5965
1915.32	14.7251
1918.3	13.9858
1921.28	12.849
1924.25	13.1666
1927.22	13.9133
1930.2	15.4567
1933.17	14.8021
1936.14	15.2108
1939.11	17.7933
1942.08	18.9993
1945.04	19.4747
1948.01	19.9248
1950.97	21.1525
1953.94	20.8306
1956.9	23.6787
1959.86	24.7847
1962.82	26.2702
1965.78	26.4159
1968.74	25.8746
1971.69	25.7993
1974.65	25.5133
1977.61	25.6375
1980.56	27.9956
1983.51	20.6828
1986.46	9.76847
1989.41	11.3549
1992.36	21.7763
1995.31	30.3014
1998.26	38.9504
2001.2	47.6162
2004.15	53.2927
2007.09	59.1661
2010.04	64.7758
2012.98	67.5205
2015.92	68.9364
2018.86	70.636
2021.8	71.2883
2024.74	70.9176
2027.67	70.2765
2030.61	68.4677
2033.54	68.0857
2036.47	66.6181
2039.41	63.7262
2042.34	61.1709
2045.27	58.1699
2048.2	52.9268
2051.12	48.5353
2054.05	43.49
2056.98	34.3428
2059.9	43.1307
2062.82	59.8002
2065.75	64.1843
2068.67	69.3608
2071.59	71.4847
2074.51	72.9699
2077.43	77.128
2080.34	81.3278
2083.26	84.4946
2086.17	88.257
2089.09	91.9091
2092	94.7676
2094.91	99.642
2097.82	105.089
2100.73	111.061
2103.64	117.879
2106.55	124.325
2109.46	131.751
2112.36	140.758
2115.27	149.841
2118.17	159.81
2121.07	170.718
2123.97	182.39
2126.87	193.605
2129.77	204.434
2132.67	217.131
2135.57	228.026
2138.46	240.811
2141.36	252.314
2144.25	264.875
2147.14	277.882
2150.03	291.381
2152.92	302.043
2155.81	311.331
2158.7	318.55
2161.59	326.948
2164.48	331.827
2167.36	336.207
2170.25	337.924
2173.13	336.563
2176.01	334.606
2178.89	330.936
2181.77	327.17
2184.65	319.576
2187.53	312.686
2190.41	304.963
2193.28	296.043
2196.16	287.63
2199.03	276.368
2201.9	265.462
2204.78	255.288
2207.65	244.696
2210.51	233.687
2213.38	223.651
2216.25	211.79
2219.12	202.702
2221.98	191.501
2224.85	182.383
2227.71	170.695
2230.57	160.463
2233.43	150.142
2236.29	140.236
2239.15	129.652
2242.01	119.729
2244.87	110.5
2247.73	103.049
2250.58	96.1106
2253.43	89.5713
2256.29	82.1433
2259.14	79.1232
2261.99	75.1313
2264.84	70.9556
2267.69	66.4406
2270.54	61.8631
2273.38	58.9843
2276.23	55.0236
2279.07	51.8784
2281.92	49.1098
2284.76	46.9973
2287.6	44.6389
2290.44	41.0772
2293.28	36.3146
2296.12	34.7028
2298.96	32.4086
2301.79	30.4314
2304.63	28.694
2307.46	27.2738
2310.3	26.1307
2313.13	24.6428
2315.96	25.0912
2318.79	22.939
2321.62	22.8006
2324.45	21.2626
2327.27	20.4946
2330.1	19.3707
2332.93	15.7283
2335.75	13.6676
2338.57	11.3846
2341.4	8.74287
2344.22	7.98501
2347.04	6.17996
2349.86	5.33311
2352.67	4.17034
2355.49	2.89251
2358.31	1.13091
2361.12	-0.323214
2363.94	-0.0198511
2366.75	0.634817
2369.56	0.719325
2372.37	-0.0703038
2375.18	1.1465
2377.99	1.8223
2380.8	0.334406
2383.61	0.421028
2386.41	1.32097
2389.22	3.80753
2392.02	4.32878
2394.82	5.63328
2397.63	5.98712
2400.43	7.48142
2403.23	7.80874
2406.02	8.79001
2408.82	8.75097
2411.62	10.2289
2414.41	10.8503
2417.21	10.2272
2420	10.8323
2422.79	11.658
2425.59	10.9353
2428.38	10.0538
2431.17	8.065
2433.96	9.80546
2436.74	9.52506
2439.53	9.47951
2442.32	9.27076
2445.1	10.1583
2447.88	9.60111
2450.67	10.0019
2453.45	11.4035
2456.23	12.3878
2459.01	12.2145
2461.79	10.8754
2464.57	10.6354
2467.34	9.44295
2470.12	8.81249
2472.89	7.18936
2475.67	6.69097
2478.44	6.88489
2481.21	7.2947
2483.98	5.49024
2486.75	4.37892
2489.52	4.47237
2492.29	1.9332
2495.06	0.478058
2497.82	-1.08978
2500.59	0.148442
2503.35	-0.291517
2506.11	0.618213
2508.88	0.316924
2511.63	0.380971
2514.39	2.7482
2517.15	2.72968
2519.91	1.64515
2522.67	1.57618
2525.42	1.54928
2528.18	1.36369
2530.93	0.764174
2533.69	1.40459
2536.44	2.0914
2539.19	2.9036
2541.94	5.20547
2544.69	6.22338
2547.44	6.93322
2550.18	6.9298
2552.93	6.76402
2555.68	5.77167
2558.42	4.94051
2561.16	4.53841
2563.9	4.00624
2566.64	4.39581
2569.38	5.20301
2572.12	4.14178
2574.86	5.23183
2577.6	4.00913
2580.34	3.10959
2583.07	2.02067
2585.81	1.72524
2588.54	1.48749
2591.27	2.24228
2594	3.28475
2596.73	4.0958
2599.46	4.33173
2602.19	5.00213
2604.92	6.83225
2607.64	6.28038
2610.37	8.52695
2613.09	9.24718
2615.82	11.0844
2618.54	10.8319
2621.26	10.3229
2623.98	10.6121
2626.7	11.8713
2629.42	13.8032
2632.14	14.004
2634.86	13.7987
2637.57	12.6069
2640.29	13.5108
2643	14.601
2645.72	13.191
2648.43	13.2885
2651.14	12.75
2653.85	12.1623
2656.56	12.1774
2659.27	12.6392
2661.97	12.6024
2664.68	13.12
2667.38	11.5574
2670.09	12.6116
2672.79	12.9918
2675.49	12.8556
2678.2	12.6946
2680.89	13.0371
2683.59	12.7022
2686.29	12.0975
2688.99	12.585
2691.69	13.5544
2694.38	15.1535
2697.08	16.4826
2699.77	15.9952
2702.46	17.6399
2705.16	19.3199
2707.85	21.3888
2710.54	20.5739
2713.23	20.2114
2715.92	19.8888
2718.6	20.0965
2721.29	22.0839
2723.97	22.0227
2726.66	22.3767
2729.34	22.1133
2732.02	22.7729
2734.7	22.6556
2737.39	22.0014
2740.06	20.8771
2742.74	19.9074
2745.42	19.5386
2748.1	18.6618
2750.77	16.8327
2753.45	15.4501
2756.12	14.0619
2758.79	11.8275
2761.47	10.3228
2764.14	8.27788
2766.81	6.72783
2769.48	5.36291
2772.14	4.42596
2774.81	3.45668
2777.48	3.10488
2780.14	2.6617
2782.81	2.53176
2785.47	2.12017
2788.13	1.61404
2790.79	1.11822
2793.46	2.43567
2796.11	2.19409
2798.77	2.54738
2801.43	2.86561
2804.09	4.62138
2806.74	4.89843
2809.4	6.3905
2812.05	7.0294
2814.71	8.96308
2817.36	12.7029
2820.01	18.0003
2822.66	27.7382
2825.31	39.777
2827.96	54.0758
2830.61	69.206
2833.25	85.7057
2835.9	102.359
2838.54	121.045
2841.18	138.404
2843.83	156.836
2846.47	175.995
2849.11	195.448
2851.75	216.065
2854.39	236.86
2857.03	256.013
2859.67	274.252
2862.3	290.876
2864.94	306.078
2867.57	319.11
2870.21	329.643
2872.84	337.769
2875.47	344.142
2878.1	351.357
2880.73	359.563
2883.36	368.378
2885.99	378.822
2888.61	389.221
2891.24	400.255
2893.87	412.903
2896.49	428.757
2899.11	448.224
2901.74	470.731
2904.36	496.103
2906.98	527.343
2909.6	562.161
2912.22	599.486
2914.83	637.688
2917.45	674.181
2920.07	706.609
2922.68	736.215
2925.3	760.931
2927.91	778.473
2930.52	791.313
2933.13	795.252
2935.74	792.889
2938.35	786.283
2940.96	771.619
2943.57	752.194
2946.18	728.224
2948.78	699.491
2951.39	666.751
2953.99	634.623
2956.6	603.655
2959.2	571.889
2961.8	541.183
2964.4	511.634
2967	483.867
2969.6	460.003
2972.2	435.218
2974.79	411.961
2977.39	388.073
2979.98	362.489
2982.58	337.135
2985.17	312.627
2987.76	287.058
2990.36	259.373
2992.95	234.496
2995.54	211.36
2998.12	187.927
3000.71	165.466
3003.3	144.034
3005.88	124.713
3008.47	106.016
3011.05	89.3031
3013.64	74.1733
3016.22	61.4079
3018.8	52.3074
3021.38	43.6461
3023.96	36.5276
3026.54	29.6721
3029.12	24.6168
3031.69	21.4168
3034.27	18.9704
3036.85	19.4495
3039.42	19.2418
3041.99	20.4015
3044.57	21.6257
3047.14	24.3243
3049.71	24.4227
3052.28	24.2602
3054.85	25.1244
3057.42	25.3498
3059.98	25.3929
3062.55	24.6252
3065.11	22.6317
3067.68	21.9932
3070.24	19.1165
3072.8	15.9458
3075.37	12.8856
3077.93	10.4841
3080.49	8.56678
3083.05	6.08073
3085.61	2.61936
3088.16	0.325752
3090.72	-1.98295
3093.27	-2.32815
3095.83	-1.96569
3098.38	-1.03312
3100.94	-0.543116
3103.49	-0.850948
3106.04	0.885885
3108.59	1.23171
3111.14	1.80606
3113.69	1.77211
3116.23	3.0153
3118.78	3.38823
3121.33	4.60483
3123.87	6.84544
3126.42	7.56711
3128.96	9.52123
3131.5	9.76021
3134.04	11.9186
3136.58	14.6383
3139.12	17.8612
3141.66	21.1419
3144.2	24.2195
3146.74	27.3472
3149.27	30.8849