File: data/Raman/poly_smoothed/Mb_50_18_36_1x_45s_532 nm_x100_100%_600 gr_mm_01.txt
#Acq. time (s)=	45
#Accumulations=	2
#Range (cm-¹)=	200...3150
#Windows=	2
#Auto scanning=	Off
#Autofocus=	Off
#Macrospot=	Off
#AutoExposure=	Off
#Spike filter=	Multiple accum.
#Delay time (s)=	0
#Binning=	1
#Readout mode=	Signal
#DeNoise=	Off
#ICS correction=	On
#Dark correction=	Off
#Inst. Process=	Off
#Detector Gain=	Best Dynamic Range
#Detector ADC=	20 kHz
#Detector temperature (°C)=	-69.85
#Instrument=	LabRAM HR Evol
#Detector=	Synapse
#Objective=	x100
#Grating=	600 gr/mm
#ND Filter=	100%
#Laser (nm)=	532
#Hole=	100.021
#Range=	Auto
#Laser Pol.=	No
#Raman. Pol.=	No
#Laser Pol. (°)=	-0.0007625
#Raman Pol. (°)=	89.9995
#Collection=	Microscope
#StageXY=	Marzhauser
#StageZ=	Marzhauser
#X (µm)=	28286.9
#Y (µm)=	-3220.1
#Z (µm)=	1041.05
#Full time(mm:ss)=	3:19
#Project=
#Sample=
#Site=
#Title=	Mb_50_18_36_2x_45s_532 nm_x100_100%_600 gr_mm
#Remark=
#Date=	12.07.2022 13:40
#Acquired=	12.07.2022 13:40:43
#Base:Fit=	10.08.2022 10:49:18
#Base:Sub=	10.08.2022 10:49:30
#Filter:Polynom=	16.08.2022 10:14:59
#AxisType[0]=Intens
#AxisUnit[0]=Cnt
#AxisType[1]=Spectr
#AxisUnit[1]=1/cm
200.388	89.6368
204.019	79.4957
207.646	71.0278
211.274	63.9935
214.899	55.7159
218.524	47.0942
222.146	42.0271
225.766	35.1875
229.388	29.4087
233.005	23.2601
236.621	19.0355
240.236	16.5164
243.852	13.0244
247.464	11.3176
251.074	10.6549
254.683	9.88422
258.291	9.56964
261.897	7.96387
265.504	7.84791
269.108	7.39861
272.71	6.63064
276.311	5.76131
279.91	5.58035
283.508	4.68941
287.105	6.45081
290.698	7.08879
294.291	8.83166
297.884	10.5162
301.475	8.79805
305.064	9.78625
308.652	12.0618
312.237	12.7277
315.822	13.1733
319.406	12.2871
322.987	12.8115
326.568	13.3561
330.148	12.9257
333.724	9.68907
337.301	8.42403
340.875	6.56991
344.449	4.77228
348.02	2.28376
351.592	6.31204
355.16	11.5264
358.728	17.3055
362.294	21.5361
365.858	25.6122
369.422	30.9409
372.983	37.0637
376.543	40.7422
380.102	45.7027
383.661	49.3648
387.216	51.0719
390.771	50.6805
394.324	50.1959
397.875	50.2694
401.425	47.1593
404.974	42.0831
408.524	35.7959
412.07	30.9777
415.614	24.0692
419.156	14.146
422.698	6.50205
426.238	2.1754
429.777	-1.65362
433.315	-4.30017
436.852	-3.20045
440.387	-1.39199
443.919	-0.621104
447.451	0.95861
450.982	0.300226
454.512	0.462385
458.038	2.95476
461.565	3.15125
465.091	4.07214
468.613	2.96321
472.136	3.05818
475.655	6.84696
479.176	9.98467
482.692	16.0158
486.21	21.7972
489.724	26.6164
493.237	33.1389
496.75	41.346
500.26	48.1754
503.771	54.4409
507.279	60.3489
510.785	66.4224
514.289	70.2313
517.793	71.434
521.297	74.4916
524.797	74.231
528.297	73.204
531.795	71.3873
535.291	65.0326
538.787	58.2001
542.281	52.91
545.773	44.5901
549.264	37.3812
552.754	28.9122
556.243	22.6184
559.73	19.988
563.216	16.3352
566.701	14.2438
570.182	11.4743
573.664	11.2609
577.145	11.2119
580.624	10.8198
584.1	10.641
587.577	11.3467
591.052	11.1546
594.524	11.8811
597.997	13.1391
601.466	13.9896
604.936	14.5829
608.403	13.8853
611.87	13.1294
615.334	12.4303
618.799	10.8823
622.26	8.09653
625.72	8.36035
629.181	8.08456
632.638	8.09499
636.095	7.75919
639.551	7.08702
643.005	7.39187
646.457	9.17546
649.908	9.56852
653.357	11.5735
656.806	13.5786
660.253	15.205
663.7	16.1102
667.145	17.1774
670.588	20.679
674.027	21.2362
677.468	23.4898
680.907	24.1602
684.345	24.0583
687.781	22.8738
691.216	23.7008
694.65	25.1898
698.081	27.5028
701.512	26.7888
704.942	28.0421
708.371	27.8428
711.796	28.742
715.222	29.5034
718.645	29.3498
722.068	28.137
725.49	26.6435
728.909	28.7948
732.329	32.4882
735.745	39.6512
739.16	51.034
742.576	61.3572
745.988	73.8459
749.401	86.6784
752.811	101.7
756.22	110.594
759.627	119.894
763.035	129.046
766.44	135.132
769.843	141.235
773.245	146.29
776.646	147.444
780.046	145.986
783.444	143.33
786.841	138.649
790.237	131.246
793.631	123.576
797.024	114.129
800.416	102.356
803.807	90.412
807.196	78.7167
810.584	70.2534
813.971	66.1393
817.354	62.7186
820.739	61.7537
824.122	60.9128
827.503	61.7972
830.882	61.5934
834.261	60.7368
837.637	58.5744
841.013	57.4907
844.389	55.732
847.761	53.9601
851.131	49.2671
854.503	47.2626
857.871	45.606
861.24	43.8876
864.606	42.2394
867.97	41.3536
871.336	40.096
874.698	39.2817
878.058	39.2822
881.418	35.9007
884.778	34.0136
888.135	33.5976
891.49	31.8044
894.845	30.8633
898.198	31.2245
901.55	30.9435
904.901	28.8424
908.25	29.0067
911.598	26.8857
914.945	25.7848
918.291	24.6087
921.635	24.1306
924.978	21.5279
928.318	20.8874
931.659	16.4798
934.998	15.5962
938.336	16.4859
941.671	15.1177
945.007	13.2503
948.339	11.7876
951.672	12.5589
955.004	12.4773
958.333	10.7455
961.662	8.59543
964.989	6.58192
968.315	5.23945
971.639	6.03285
974.962	6.45063
978.285	4.79617
981.605	2.87472
984.924	2.66109
988.243	3.23862
991.56	6.61404
994.875	11.0126
998.188	19.1293
1001.5	28.6844
1004.81	38.8785
1008.12	47.5636
1011.43	56.5876
1014.74	66.5492
1018.05	74.3227
1021.35	79.9206
1024.65	83.9015
1027.96	88.4493
1031.26	90.7915
1034.56	90.713
1037.86	87.188
1041.16	80.8717
1044.45	75.3733
1047.75	68.0117
1051.04	60.4838
1054.33	53.0258
1057.62	49.526
1060.91	44.9664
1064.2	43.6529
1067.49	42.9459
1070.77	43.3624
1074.06	45.1391
1077.34	47.7297
1080.62	50.7575
1083.91	53.2875
1087.18	54.2141
1090.46	55.12
1093.74	52.5013
1097.02	51.7746
1100.29	48.4826
1103.56	45.1538
1106.84	41.4305
1110.11	37.2512
1113.38	32.6352
1116.64	26.536
1119.91	20.0738
1123.18	14.3247
1126.44	11.3642
1129.7	7.80324
1132.97	8.51615
1136.23	10.8249
1139.49	11.0652
1142.74	11.3179
1146	11.3077
1149.26	10.3691
1152.51	9.59721
1155.76	8.57417
1159.01	8.67552
1162.27	8.10178
1165.51	7.45569
1168.76	7.1751
1172.01	4.38117
1175.25	6.09678
1178.5	6.99097
1181.74	5.28045
1184.98	5.42403
1188.22	6.96223
1191.46	6.3587
1194.7	7.18831
1197.94	6.22825
1201.17	7.07578
1204.41	8.24464
1207.64	9.13197
1210.87	9.86532
1214.1	13.092
1217.33	14.2024
1220.56	16.5535
1223.79	20.4054
1227.01	23.4493
1230.23	25.9529
1233.46	29.5509
1236.68	33.6489
1239.9	36.7369
1243.12	38.8181
1246.34	39.1219
1249.55	39.8985
1252.77	41.4024
1255.98	45.6188
1259.2	45.8439
1262.41	47.5632
1265.62	48.2536
1268.83	48.4423
1272.03	49.5668
1275.24	50.5604
1278.45	50.7093
1281.65	52.8885
1284.85	52.2812
1288.06	53.347
1291.26	55.0984
1294.46	55.4532
1297.66	53.7712
1300.85	56.9126
1304.05	58.4857
1307.24	58.0759
1310.43	59.8535
1313.63	60.5144
1316.82	60.2594
1320.01	58.9893
1323.2	59.1474
1326.38	57.8662
1329.57	57.805
1332.76	57.534
1335.94	58.9267
1339.12	56.7079
1342.3	56.4012
1345.48	53.2421
1348.66	53.7812
1351.84	53.0042
1355.01	52.3968
1358.19	50.3676
1361.36	49.8624
1364.53	47.8569
1367.71	45.9038
1370.88	45.2838
1374.04	42.317
1377.21	41.5993
1380.38	39.3198
1383.54	37.5545
1386.71	36.4716
1389.87	34.1935
1393.03	31.2435
1396.19	28.384
1399.35	25.7544
1402.51	25.7851
1405.67	26.2412
1408.82	28.0988
1411.98	32.8157
1415.13	38.1616
1418.28	43.7066
1421.43	49.2851
1424.58	57.238
1427.73	65.1336
1430.88	74.7834
1434.02	80.4442
1437.17	86.6924
1440.31	90.5306
1443.45	94.0049
1446.6	97.1372
1449.74	98.9346
1452.87	100.144
1456.01	99.7453
1459.15	99.5822
1462.28	100.255
1465.42	98.2688
1468.55	94.7143
1471.68	91.0726
1474.81	86.165
1477.94	83.3211
1481.07	81.3307
1484.2	80.2115
1487.32	77.5651
1490.45	74.6302
1493.57	69.8162
1496.69	66.4286
1499.81	62.858
1502.93	60.0212
1506.05	54.7391
1509.17	50.5792
1512.28	43.431
1515.4	39.4546
1518.51	34.5802
1521.63	30.9353
1524.74	29.7193
1527.85	27.2598
1530.96	27.6531
1534.06	27.2989
1537.17	29.4282
1540.28	31.1236
1543.38	31.2688
1546.48	32.3421
1549.59	33.4051
1552.69	32.9894
1555.79	35.4878
1558.88	38.1065
1561.98	40.7937
1565.08	42.0436
1568.17	44.0005
1571.27	48.1467
1574.36	51.1889
1577.45	56.1009
1580.54	58.7744
1583.63	62.0492
1586.72	64.1192
1589.8	67.4832
1592.89	70.3721
1595.97	72.6594
1599.06	74.7422
1602.14	75.3691
1605.22	76.7809
1608.3	78.0649
1611.38	78.8865
1614.46	79.903
1617.53	79.9632
1620.61	79.7947
1623.68	80.0796
1626.75	77.9952
1629.82	76.4912
1632.9	77.4827
1635.96	78.009
1639.03	81.2296
1642.1	82.145
1645.16	84.1035
1648.23	84.186
1651.29	83.3799
1654.36	83.671
1657.42	82.8202
1660.48	81.2154
1663.53	78.2894
1666.59	76.4493
1669.65	73.5651
1672.7	70.0045
1675.76	65.646
1678.81	62.4148
1681.86	60.0382
1684.91	56.3035
1687.96	51.4962
1691.01	46.3736
1694.06	42.0081
1697.11	37.3262
1700.15	31.0967
1703.2	25.9123
1706.24	24.096
1709.28	22.4869
1712.32	19.4682
1715.36	16.6067
1718.4	12.7048
1721.43	11.8448
1724.47	10.4822
1727.5	9.56184
1730.54	8.97466
1733.57	8.21155
1736.6	5.95618
1739.63	5.18273
1742.66	5.25996
1745.69	4.57208
1748.72	3.69068
1751.74	4.28873
1754.77	4.27264
1757.79	4.17597
1760.81	3.20369
1763.83	2.49055
1766.85	1.16511
1769.87	0.702646
1772.89	-0.2781
1775.91	0.690002
1778.92	2.81872
1781.94	3.97146
1784.95	3.49992
1787.96	4.58899
1790.97	5.62801
1793.98	7.02098
1796.99	8.56009
1800	7.5586
1803	8.74696
1806.01	8.20737
1809.01	8.06943
1812.02	7.27903
1815.02	7.48392
1818.02	7.87625
1821.02	8.13628
1824.02	8.69071
1827.01	8.19804
1830.01	7.80195
1833	7.92186
1836	7.46642
1838.99	7.86548
1841.98	7.55159
1844.97	8.6195
1847.96	8.88736
1850.95	10.0404
1853.94	8.94305
1856.92	7.67492
1859.91	8.95642
1862.89	8.96303
1865.88	6.81731
1868.86	7.05798
1871.84	6.18435
1874.82	6.92675
1877.8	7.67889
1880.77	7.66084
1882.51	8.39187
1885.5	8.2658
1888.48	8.58871
1891.47	10.1396
1894.46	10.7766
1897.44	10.5678
1900.42	11.1182
1903.41	11.0153
1906.39	12.2048
1909.37	12.668
1912.35	13.6105
1915.32	13.5635
1918.3	13.5341
1921.28	11.2976
1924.25	9.9604
1927.22	9.88581
1930.2	9.30756
1933.17	7.89327
1936.14	5.46134
1939.11	5.61547
1942.08	5.73465
1945.04	5.0688
1948.01	5.18408
1950.97	5.1898
1953.94	4.44166
1956.9	5.8517
1959.86	4.89142
1962.82	6.32368
1965.78	7.57957
1968.74	8.30392
1971.69	8.56047
1974.65	8.64166
1977.61	9.60032
1980.56	11.1451
1983.51	12.0413
1986.46	12.0584
1989.41	12.7336
1992.36	12.6997
1995.31	12.9851
1998.26	12.4736
2001.2	13.5165
2004.15	14.1646
2007.09	14.0506
2010.04	13.8758
2012.98	14.2646
2015.92	14.9415
2018.86	15.2843
2021.8	15.5387
2024.74	14.7072
2027.67	15.0939
2030.61	15.1541
2033.54	16.6075
2036.47	18.0878
2039.41	19.1536
2042.34	20.4749
2045.27	21.3616
2048.2	21.9943
2051.12	22.5491
2054.05	23.0545
2056.98	23.7529
2059.9	24.6963
2062.82	26.0676
2065.75	25.7971
2068.67	27.8219
2071.59	29.8954
2074.51	31.4407
2077.43	33.1665
2080.34	33.8178
2083.26	36.1067
2086.17	39.4294
2089.09	41.8012
2092	43.405
2094.91	46.781
2097.82	50.8348
2100.73	55.589
2103.64	60.2816
2106.55	63.85
2109.46	67.5375
2112.36	71.3787
2115.27	74.3153
2118.17	76.7314
2121.07	78.5556
2123.97	82.6345
2126.87	87.8086
2129.77	90.6636
2132.67	94.4161
2135.57	100.254
2138.46	104.977
2141.36	110.282
2144.25	113.521
2147.14	117.292
2150.03	121.111
2152.92	123.501
2155.81	128.31
2158.7	131.651
2161.59	134.716
2164.48	137.785
2167.36	139.604
2170.25	140.355
2173.13	139.484
2176.01	136.973
2178.89	134.282
2181.77	133.701
2184.65	131.351
2187.53	127.93
2190.41	123.404
2193.28	121.151
2196.16	118.753
2199.03	113.745
2201.9	108.825
2204.78	104.843
2207.65	99.6239
2210.51	93.6954
2213.38	88.5973
2216.25	83.6417
2219.12	77.7273
2221.98	74.3647
2224.85	70.5053
2227.71	67.8694
2230.57	62.6881
2233.43	57.3292
2236.29	52.4719
2239.15	50.4655
2242.01	46.8591
2244.87	44.0664
2247.73	41.4466
2250.58	40.1096
2253.43	38.8076
2256.29	37.3366
2259.14	36.4017
2261.99	36.7512
2264.84	36.1551
2267.69	34.9321
2270.54	34.162
2273.38	34.8519
2276.23	33.7179
2279.07	31.5697
2281.92	30.0566
2284.76	28.9908
2287.6	27.6648
2290.44	25.3057
2293.28	22.1317
2296.12	21.4276
2298.96	17.5714
2301.79	16.1555
2304.63	15.1524
2307.46	14.5512
2310.3	13.7031
2313.13	12.1412
2315.96	10.8802
2318.79	10.2717
2321.62	10.2093
2324.45	11.1788
2327.27	11.5054
2330.1	11.5085
2332.93	11.886
2335.75	12.5205
2338.57	13.6244
2341.4	13.6893
2344.22	12.3728
2347.04	9.89719
2349.86	8.46566
2352.67	5.72477
2355.49	5.58909
2358.31	4.19665
2361.12	1.47989
2363.94	0.877479
2366.75	1.11779
2369.56	0.0803429
2372.37	0.374795
2375.18	0.870164
2377.99	1.52229
2380.8	1.34763
2383.61	1.87847
2386.41	4.00729
2389.22	6.24287
2392.02	7.15452
2394.82	7.81007
2397.63	7.9619
2400.43	10.428
2403.23	10.4188
2406.02	10.0193
2408.82	10.4089
2411.62	10.9287
2414.41	10.9266
2417.21	11.3428
2420	11.3477
2422.79	10.7851
2425.59	10.2225
2428.38	9.22564
2431.17	7.78574
2433.96	6.64183
2436.74	4.67321
2439.53	3.24334
2442.32	5.01954
2445.1	5.3908
2447.88	4.73847
2450.67	4.50695
2453.45	6.08866
2456.23	5.92442
2459.01	5.63395
2461.79	5.60633
2464.57	6.3468
2467.34	6.07212
2470.12	5.63048
2472.89	5.35516
2475.67	6.78298
2478.44	9.35633
2481.21	9.34272
2483.98	10.0615
2486.75	11.3927
2489.52	10.3891
2492.29	11.6524
2495.06	10.8613
2497.82	9.93069
2500.59	9.3838
2503.35	8.77591
2506.11	9.4618
2508.88	10.9066
2511.63	11.1458
2514.39	11.1496
2517.15	12.7616
2519.91	12.0879
2522.67	11.2172
2525.42	10.3677
2528.18	10.7042
2530.93	11.0205
2533.69	10.0684
2536.44	10.7113
2539.19	10.5112
2541.94	10.2397
2544.69	9.84967
2547.44	9.10957
2550.18	9.15193
2552.93	9.78574
2555.68	8.13963
2558.42	7.25326
2561.16	6.74461
2563.9	6.59685
2566.64	6.58495
2569.38	5.63925
2572.12	4.68874
2574.86	6.4536
2577.6	6.56002
2580.34	5.87158
2583.07	5.53837
2585.81	5.30136
2588.54	5.76547
2591.27	6.77061
2594	8.7786
2596.73	9.26228
2599.46	9.61329
2602.19	9.82103
2604.92	9.59243
2607.64	9.4638
2610.37	9.74532
2613.09	9.37701
2615.82	10.6148
2618.54	10.6987
2621.26	9.88717
2623.98	10.3196
2626.7	10.709
2629.42	10.8707
2632.14	10.3573
2634.86	9.73654
2637.57	10.9706
2640.29	11.7982
2643	12.1184
2645.72	11.0231
2648.43	10.742
2651.14	11.8127
2653.85	13.5053
2656.56	12.3607
2659.27	12.0347
2661.97	11.5405
2664.68	10.915
2667.38	11.1994
2670.09	11.393
2672.79	11.5614
2675.49	10.7435
2678.2	10.4703
2680.89	9.88281
2683.59	9.638
2686.29	8.539
2688.99	9.24386
2691.69	10.3192
2694.38	10.3895
2697.08	9.85629
2699.77	9.23293
2702.46	9.94773
2705.16	10.9573
2707.85	11.4507
2710.54	12.2301
2713.23	11.7418
2715.92	12.799
2718.6	13.6951
2721.29	14.2594
2723.97	14.6937
2726.66	15.5391
2729.34	15.4407
2732.02	16.3894
2734.7	15.9661
2737.39	15.5121
2740.06	13.931
2742.74	12.9128
2745.42	12.5635
2748.1	11.9713
2750.77	11.5696
2753.45	10.74
2756.12	9.19217
2758.79	6.63341
2761.47	5.95176
2764.14	4.46118
2766.81	3.81554
2769.48	3.71567
2772.14	2.24173
2774.81	1.31748
2777.48	-0.609385
2780.14	-1.01903
2782.81	-0.320321
2785.47	-1.52344
2788.13	-0.958045
2790.79	-0.76247
2793.46	-1.83894
2796.11	-2.18119
2798.77	-2.89098
2801.43	-2.35215
2804.09	-2.50232
2806.74	-3.62671
2809.4	-3.85025
2812.05	-5.09253
2814.71	-3.72307
2817.36	-3.02183
2820.01	0.531028
2822.66	6.93816
2825.31	13.8356
2827.96	21.3803
2830.61	29.2241
2833.25	38.0667
2835.9	47.865
2838.54	56.1807
2841.18	65.771
2843.83	76.2518
2846.47	88.2635
2849.11	98.0068
2851.75	109.603
2854.39	120.589
2857.03	130.111
2859.67	136.969
2862.3	144.763
2864.94	150.869
2867.57	156.005
2870.21	158.676
2872.84	161.624
2875.47	164.592
2878.1	168.169
2880.73	172.027
2883.36	176.208
2885.99	181.168
2888.61	185.584
2891.24	191.221
2893.87	196.05
2896.49	203.083
2899.11	209.863
2901.74	217.378
2904.36	228.506
2906.98	240.939
2909.6	255.356
2912.22	269.023
2914.83	282.915
2917.45	297.143
2920.07	308.987
2922.68	318.038
2925.3	325.476
2927.91	332.718
2930.52	335.681
2933.13	335.393
2935.74	333.17
2938.35	326.893
2940.96	319.401
2943.57	309.014
2946.18	297.279
2948.78	283.419
2951.39	269.293
2953.99	254.855
2956.6	240.562
2959.2	226.924
2961.8	213.635
2964.4	199.275
2967	188.137
2969.6	178.523
2972.2	168.012
2974.79	156.454
2977.39	147.468
2979.98	137.835
2982.58	128.74
2985.17	117.685
2987.76	106.74
2990.36	96.386
2992.95	85.8184
2995.54	74.2867
2998.12	63.83
3000.71	54.2493
3003.3	44.1723
3005.88	35.7195
3008.47	28.4931
3011.05	21.2192
3013.64	15.3522
3016.22	11.6896
3018.8	8.84951
3021.38	5.9087
3023.96	3.50529
3026.54	0.443213
3029.12	-0.976031
3031.69	-0.972223
3034.27	-0.434292
3036.85	-0.176675
3039.42	0.69044
3041.99	2.10225
3044.57	3.54268
3047.14	3.41796
3049.71	3.96652
3052.28	5.68038
3054.85	5.02229
3057.42	4.94023
3059.98	3.69554
3062.55	4.05932
3065.11	2.62116
3067.68	2.21955
3070.24	2.08256
3072.8	2.61897
3075.37	2.87035
3077.93	3.30081
3080.49	3.39003
3083.05	3.22474
3085.61	3.76614
3088.16	3.95654
3090.72	4.44684
3093.27	6.2232
3095.83	9.29438
3098.38	10.8619
3100.94	12.6501
3103.49	14.2588
3106.04	16.7916
3108.59	18.3596
3111.14	19.5423
3113.69	22.1355
3116.23	22.0459
3118.78	22.4737
3121.33	24.9709
3123.87	27.1648
3126.42	28.65
3128.96	31.279
3131.5	35.327
3134.04	39.4303
3136.58	42.9696
3139.12	47.1387
3141.66	51.0178
3144.2	56.595
3146.74	63.3227
3149.27	71.4115