File: data/Raman/poly_smoothed/Mb_50_18_26_1x_45s_532 nm_x100_100%_600 gr_mm_01.txt
#Acq. time (s)=	45
#Accumulations=	2
#Range (cm-¹)=	200...3150
#Windows=	2
#Auto scanning=	Off
#Autofocus=	Off
#Macrospot=	Off
#AutoExposure=	Off
#Spike filter=	Multiple accum.
#Delay time (s)=	0
#Binning=	1
#Readout mode=	Signal
#DeNoise=	Off
#ICS correction=	On
#Dark correction=	Off
#Inst. Process=	Off
#Detector Gain=	Best Dynamic Range
#Detector ADC=	20 kHz
#Detector temperature (°C)=	-69.85
#Instrument=	LabRAM HR Evol
#Detector=	Synapse
#Objective=	x100
#Grating=	600 gr/mm
#ND Filter=	100%
#Laser (nm)=	532
#Hole=	100.021
#Range=	Auto
#Laser Pol.=	No
#Raman. Pol.=	No
#Laser Pol. (°)=	-0.0007625
#Raman Pol. (°)=	89.9995
#Collection=	Microscope
#StageXY=	Marzhauser
#StageZ=	Marzhauser
#X (µm)=	28316
#Y (µm)=	-3288.7
#Z (µm)=	1040.45
#Full time(mm:ss)=	3:19
#Project=
#Sample=
#Site=
#Title=	Mb_50_18_26_2x_45s_532 nm_x100_100%_600 gr_mm
#Remark=
#Date=	12.07.2022 12:47
#Acquired=	12.07.2022 12:47:34
#Base:Fit=	10.08.2022 10:49:18
#Base:Sub=	10.08.2022 10:49:30
#Filter:Polynom=	16.08.2022 10:14:59
#AxisType[0]=Intens
#AxisUnit[0]=Cnt
#AxisType[1]=Spectr
#AxisUnit[1]=1/cm
200.388	119.257
204.019	113.194
207.646	106.937
211.274	102.867
214.899	98.2884
218.524	91.7064
222.146	85.1103
225.766	79.2447
229.388	71.6307
233.005	66.492
236.621	62.895
240.236	59.3615
243.852	57.3111
247.464	54.2532
251.074	52.2395
254.683	50.3294
258.291	49.1392
261.897	42.9906
265.504	38.898
269.108	35.235
272.71	31.8878
276.311	28.4554
279.91	25.012
283.508	23.6672
287.105	23.9622
290.698	24.7607
294.291	29.5258
297.884	34.5973
301.475	38.5379
305.064	40.7414
308.652	43.6925
312.237	47.8303
315.822	50.6195
319.406	51.5099
322.987	53.4803
326.568	53.0087
330.148	50.7681
333.724	45.9394
337.301	39.046
340.875	34.5885
344.449	32.9854
348.02	33.6512
351.592	40.4917
355.16	52.6865
358.728	69.3003
362.294	86.8237
365.858	102.09
369.422	118.987
372.983	136.89
376.543	151.521
380.102	165.739
383.661	175.675
387.216	182.744
390.771	184.36
394.324	181.841
397.875	175.758
401.425	166.768
404.974	150.331
408.524	130.746
412.07	109.103
415.614	85.2188
419.156	59.8091
422.698	38.5892
426.238	20.1095
429.777	6.55872
433.315	-1.04497
436.852	-4.59828
440.387	-5.47074
443.919	-3.94676
447.451	-0.672441
450.982	-0.68836
454.512	-0.421826
458.038	1.23161
461.565	5.31348
465.091	6.75084
468.613	8.11078
472.136	11.0185
475.655	16.1396
479.176	23.9936
482.692	37.6787
486.21	51.3054
489.724	67.7547
493.237	86.7006
496.75	106.847
500.26	125.19
503.771	141.302
507.279	154.529
510.785	168.105
514.289	174.585
517.793	181.313
521.297	184.531
524.797	182.949
528.297	182.133
531.795	175.023
535.291	161.639
538.787	147.905
542.281	130.831
545.773	113.167
549.264	93.0675
552.754	73.2645
556.243	55.9509
559.73	42.2091
563.216	33.2351
566.701	29.0664
570.182	26.8996
573.664	29.5998
577.145	34.2903
580.624	36.2843
584.1	38.7139
587.577	41.3012
591.052	44.442
594.524	46.2194
597.997	49.6775
601.466	50.844
604.936	50.5964
608.403	52.6196
611.87	51.8651
615.334	50.7563
618.799	47.2317
622.26	42.7446
625.72	39.5191
629.181	34.4753
632.638	29.0068
636.095	22.9216
639.551	19.8216
643.005	15.1398
646.457	11.0829
649.908	9.28109
653.357	7.93091
656.806	5.39267
660.253	5.80562
663.7	2.03174
667.145	1.96071
670.588	2.68959
674.027	3.65709
677.468	5.13202
680.907	10.2356
684.345	13.8932
687.781	16.4406
691.216	20.8286
694.65	24.6223
698.081	29.9089
701.512	33.7995
704.942	36.0544
708.371	39.0282
711.796	40.7495
715.222	42.8526
718.645	42.0424
722.068	42.2088
725.49	39.268
728.909	38.1509
732.329	41.7262
735.745	50.2157
739.16	66.5683
742.576	91.299
745.988	122.039
749.401	155.665
752.811	188.737
756.22	214.706
759.627	240.058
763.035	261.649
766.44	278.55
769.843	286.623
773.245	292.436
776.646	291.833
780.046	288.118
783.444	279.938
786.841	265.386
790.237	246.97
793.631	224.626
797.024	195.835
800.416	168.601
803.807	140.567
807.196	111.415
810.584	87.0672
813.971	68.0827
817.354	57.7392
820.739	55.0975
824.122	56.91
827.503	61.9675
830.882	64.8664
834.261	65.7901
837.637	63.7483
841.013	61.6559
844.389	61.2798
847.761	57.7769
851.131	55.1414
854.503	53.627
857.871	52.1751
861.24	51.3048
864.606	49.8653
867.97	47.5666
871.336	45.1507
874.698	41.3437
878.058	39.4256
881.418	36.7079
884.778	37.581
888.135	35.8003
891.49	32.1274
894.845	28.2227
898.198	25.9057
901.55	26.3534
904.901	26.1562
908.25	28.729
911.598	29.1079
914.945	28.1459
918.291	27.9797
921.635	29.1775
924.978	30.7276
928.318	30.264
931.659	30.3881
934.998	29.9438
938.336	31.0344
941.671	27.561
945.007	23.6779
948.339	21.9634
951.672	20.1587
955.004	16.1965
958.333	11.9603
961.662	9.29485
964.989	8.3789
968.315	6.85813
971.639	6.43309
974.962	5.66154
978.285	4.75049
981.605	7.8347
984.924	7.0749
988.243	9.06753
991.56	13.0345
994.875	21.9434
998.188	36.598
1001.5	59.1991
1004.81	84.8338
1008.12	113.576
1011.43	139.463
1014.74	166.833
1018.05	191.831
1021.35	211.849
1024.65	228.217
1027.96	244.616
1031.26	256.87
1034.56	260.01
1037.86	257.252
1041.16	249.827
1044.45	241.472
1047.75	229.054
1051.04	217.876
1054.33	207.02
1057.62	194.595
1060.91	185.106
1064.2	177.001
1067.49	170.335
1070.77	169.478
1074.06	173.316
1077.34	178.633
1080.62	187.307
1083.91	194.284
1087.18	199.717
1090.46	202.115
1093.74	202.582
1097.02	203.385
1100.29	198.557
1103.56	190.06
1106.84	177.766
1110.11	163.584
1113.38	146.985
1116.64	128.11
1119.91	107.217
1123.18	89.4924
1126.44	75.4248
1129.7	66.8669
1132.97	62.5464
1136.23	57.9805
1139.49	54.464
1142.74	55.1239
1146	52.1121
1149.26	50.2641
1152.51	48.5462
1155.76	47.6237
1159.01	46.7891
1162.27	46.8343
1165.51	47.7483
1168.76	50.4121
1172.01	49.9527
1175.25	52.9381
1178.5	57.1395
1181.74	58.1267
1184.98	58.8407
1188.22	61.7834
1191.46	62.7551
1194.7	63.5959
1197.94	64.7986
1201.17	67.0076
1204.41	68.3475
1207.64	72.3028
1210.87	76.4318
1214.1	80.4936
1217.33	83.8251
1220.56	86.2815
1223.79	88.2709
1227.01	93.331
1230.23	98.297
1233.46	99.8252
1236.68	104.894
1239.9	107.731
1243.12	109.269
1246.34	111.665
1249.55	111.777
1252.77	114.786
1255.98	119.3
1259.2	122.701
1262.41	126.349
1265.62	128.809
1268.83	133.2
1272.03	138.855
1275.24	145.997
1278.45	151.316
1281.65	157.874
1284.85	162.145
1288.06	168.275
1291.26	172.061
1294.46	175.904
1297.66	177.798
1300.85	179.826
1304.05	182.58
1307.24	184.293
1310.43	183.181
1313.63	182.04
1316.82	177.825
1320.01	170.196
1323.2	165.725
1326.38	159.37
1329.57	153.219
1332.76	149.649
1335.94	144.064
1339.12	140.475
1342.3	134.879
1345.48	132.672
1348.66	130.14
1351.84	125.845
1355.01	122.822
1358.19	119.332
1361.36	117.512
1364.53	114.3
1367.71	109.512
1370.88	106.165
1374.04	104.701
1377.21	102.313
1380.38	99.4063
1383.54	97.4117
1386.71	93.8992
1389.87	89.6636
1393.03	83.4203
1396.19	78.7624
1399.35	79.3865
1402.51	82.4644
1405.67	87.7677
1408.82	95.4348
1411.98	106.948
1415.13	120.353
1418.28	136.872
1421.43	153.411
1424.58	174.546
1427.73	192.178
1430.88	210.013
1434.02	226.282
1437.17	242.329
1440.31	253.637
1443.45	259.1
1446.6	261.487
1449.74	261.899
1452.87	257.424
1456.01	253.293
1459.15	244.546
1462.28	234.538
1465.42	222.765
1468.55	207.757
1471.68	195.294
1474.81	183.007
1477.94	170.367
1481.07	159.621
1484.2	149.861
1487.32	142.114
1490.45	135.308
1493.57	127.205
1496.69	121.645
1499.81	114.528
1502.93	107.759
1506.05	100.697
1509.17	94.7933
1512.28	90.0136
1515.4	84.1481
1518.51	77.4734
1521.63	72.4766
1524.74	68.3972
1527.85	65.6409
1530.96	64.6629
1534.06	65.1843
1537.17	65.4253
1540.28	66.5043
1543.38	65.8098
1546.48	70.4694
1549.59	73.9894
1552.69	74.3796
1555.79	78.2753
1558.88	80.6149
1561.98	83.6308
1565.08	86.7533
1568.17	92.6808
1571.27	100.146
1574.36	109.363
1577.45	119.737
1580.54	128.887
1583.63	138.316
1586.72	150.791
1589.8	156.333
1592.89	162.164
1595.97	166.058
1599.06	168.37
1602.14	169.461
1605.22	169.603
1608.3	169.338
1611.38	167.763
1614.46	166.815
1617.53	165.982
1620.61	166.495
1623.68	169.122
1626.75	166.939
1629.82	165.439
1632.9	166.749
1635.96	169.744
1639.03	174.705
1642.1	179.813
1645.16	185.689
1648.23	190.184
1651.29	193.456
1654.36	195.858
1657.42	195.567
1660.48	192.326
1663.53	186.652
1666.59	177.25
1669.65	166.203
1672.7	151.828
1675.76	138.68
1678.81	124.588
1681.86	108.262
1684.91	94.8287
1687.96	82.4696
1691.01	70.2828
1694.06	57.9679
1697.11	46.9553
1700.15	39.4335
1703.2	30.3928
1706.24	25.2005
1709.28	20.6601
1712.32	13.8555
1715.36	11.5754
1718.4	9.2437
1721.43	7.69829
1724.47	8.1165
1727.5	7.96946
1730.54	9.19764
1733.57	8.80853
1736.6	8.60689
1739.63	7.9095
1742.66	6.36169
1745.69	6.3094
1748.72	5.9977
1751.74	6.0817
1754.77	4.34004
1757.79	3.08465
1760.81	2.81447
1763.83	0.665371
1766.85	0.0815743
1769.87	0.23672
1772.89	1.01522
1775.91	-1.23227
1778.92	-0.603784
1781.94	-0.615714
1784.95	-0.347824
1787.96	-1.04937
1790.97	0.369979
1793.98	2.48676
1796.99	3.85619
1800	4.37246
1803	4.23116
1806.01	4.29231
1809.01	4.67135
1812.02	5.08993
1815.02	5.48997
1818.02	6.89063
1821.02	5.92319
1824.02	5.44913
1827.01	5.12712
1830.01	4.70342
1833	4.82548
1836	5.83132
1838.99	6.57614
1841.98	7.11476
1844.97	7.28536
1847.96	6.70372
1850.95	5.3841
1853.94	6.45173
1856.92	4.97202
1859.91	5.51392
1862.89	5.45561
1865.88	6.27614
1868.86	7.10394
1871.84	6.08651
1874.82	5.40457
1877.8	5.8081
1880.77	7.01591
1882.51	6.95195
1885.5	7.27913
1888.48	6.75378
1891.47	5.79042
1894.46	7.44976
1897.44	6.96794
1900.42	6.99083
1903.41	7.91304
1906.39	7.7477
1909.37	8.47449
1912.35	7.569
1915.32	7.13968
1918.3	7.27176
1921.28	6.17462
1924.25	6.24421
1927.22	7.5838
1930.2	5.95836
1933.17	6.05869
1936.14	5.63775
1939.11	6.30005
1942.08	6.77543
1945.04	6.95088
1948.01	7.98701
1950.97	8.56519
1953.94	9.66232
1956.9	10.1046
1959.86	9.33801
1962.82	10.1865
1965.78	11.3317
1968.74	11.4586
1971.69	10.6399
1974.65	11.6888
1977.61	12.9405
1980.56	12.7857
1983.51	12.9413
1986.46	11.942
1989.41	13.4686
1992.36	14.2563
1995.31	13.4001
1998.26	12.9435
2001.2	11.5297
2004.15	11.3144
2007.09	11.6356
2010.04	11.665
2012.98	12.4544
2015.92	12.2711
2018.86	11.874
2021.8	12.1936
2024.74	12.9324
2027.67	12.9565
2030.61	13.4001
2033.54	13.791
2036.47	16.6879
2039.41	19.72
2042.34	23.2609
2045.27	26.0385
2048.2	29.3924
2051.12	31.7599
2054.05	36.6854
2056.98	39.6294
2059.9	43.4411
2062.82	47.2901
2065.75	49.926
2068.67	53.2799
2071.59	55.606
2074.51	58.111
2077.43	62.2549
2080.34	64.4372
2083.26	66.7905
2086.17	70.5083
2089.09	73.1167
2092	77.1426
2094.91	81.5289
2097.82	85.272
2100.73	90.9199
2103.64	97.2881
2106.55	105.618
2109.46	114.677
2112.36	122.537
2115.27	130.775
2118.17	139.794
2121.07	149.888
2123.97	159.923
2126.87	171.399
2129.77	182.51
2132.67	192.343
2135.57	204.121
2138.46	215.264
2141.36	226.345
2144.25	236.399
2147.14	247.367
2150.03	258.618
2152.92	267.363
2155.81	275.425
2158.7	282.536
2161.59	288.149
2164.48	293.434
2167.36	296.055
2170.25	296.834
2173.13	295.967
2176.01	293.641
2178.89	289.121
2181.77	282.96
2184.65	275.532
2187.53	267.791
2190.41	259.642
2193.28	251.371
2196.16	241.66
2199.03	231.398
2201.9	221.161
2204.78	212.486
2207.65	202.663
2210.51	192.369
2213.38	182.22
2216.25	172.083
2219.12	164.259
2221.98	153.319
2224.85	143.442
2227.71	135.133
2230.57	127.789
2233.43	119.411
2236.29	111.277
2239.15	103.867
2242.01	94.4791
2244.87	86.5108
2247.73	78.6148
2250.58	71.3502
2253.43	66.0105
2256.29	60.8915
2259.14	57.224
2261.99	52.5502
2264.84	49.4835
2267.69	46.9971
2270.54	45.0913
2273.38	43.4092
2276.23	42.2591
2279.07	38.8155
2281.92	37.177
2284.76	35.0787
2287.6	33.6203
2290.44	30.4248
2293.28	27.2127
2296.12	25.2946
2298.96	24.7015
2301.79	23.5036
2304.63	22.5414
2307.46	20.1109
2310.3	17.8609
2313.13	16.6992
2315.96	13.9833
2318.79	11.8894
2321.62	10.6912
2324.45	9.36919
2327.27	8.03541
2330.1	8.05607
2332.93	8.86593
2335.75	7.57797
2338.57	6.46948
2341.4	6.04885
2344.22	5.30401
2347.04	4.53715
2349.86	3.20592
2352.67	2.97201
2355.49	1.24935
2358.31	-0.494488
2361.12	-1.43549
2363.94	-1.94561
2366.75	-1.58477
2369.56	0.110185
2372.37	0.321356
2375.18	1.02744
2377.99	1.6618
2380.8	3.11121
2383.61	1.8305
2386.41	1.37195
2389.22	0.839963
2392.02	1.88528
2394.82	3.24348
2397.63	4.58258
2400.43	4.9322
2403.23	4.2377
2406.02	4.25864
2408.82	4.59411
2411.62	5.01735
2414.41	5.17857
2417.21	6.45097
2420	6.33447
2422.79	6.83829
2425.59	8.22112
2428.38	8.75662
2431.17	9.332
2433.96	9.77716
2436.74	11.1327
2439.53	11.1882
2442.32	12.3811
2445.1	13.5574
2447.88	12.7169
2450.67	10.5479
2453.45	9.10371
2456.23	9.09968
2459.01	8.22397
2461.79	7.56148
2464.57	8.48594
2467.34	7.01152
2470.12	5.61323
2472.89	5.55539
2475.67	4.22704
2478.44	4.43929
2481.21	3.85442
2483.98	3.02101
2486.75	3.68891
2489.52	3.7548
2492.29	4.04661
2495.06	4.09654
2497.82	3.95757
2500.59	4.30906
2503.35	4.41347
2506.11	3.90435
2508.88	2.21724
2511.63	1.73825
2514.39	2.19662
2517.15	-0.164106
2519.91	0.00173788
2522.67	0.0802097
2525.42	0.183921
2528.18	-0.370563
2530.93	0.666093
2533.69	0.526207
2536.44	1.42159
2539.19	2.2134
2541.94	2.8637
2544.69	2.58976
2547.44	4.75936
2550.18	5.34536
2552.93	6.0538
2555.68	6.45486
2558.42	7.84863
2561.16	7.67601
2563.9	8.65852
2566.64	8.74438
2569.38	9.15568
2572.12	8.49434
2574.86	7.36873
2577.6	7.88758
2580.34	8.88217
2583.07	8.26689
2585.81	9.01117
2588.54	8.15827
2591.27	7.1597
2594	6.92901
2596.73	6.49025
2599.46	5.50628
2602.19	5.7414
2604.92	7.15552
2607.64	7.744
2610.37	7.29798
2613.09	8.75672
2615.82	9.4549
2618.54	8.48947
2621.26	8.41076
2623.98	8.24309
2626.7	10.2926
2629.42	11.0449
2632.14	12.7115
2634.86	12.8886
2637.57	13.354
2640.29	14.8311
2643	15.8891
2645.72	16.0167
2648.43	16.9369
2651.14	16.0108
2653.85	15.2141
2656.56	14.4967
2659.27	14.2798
2661.97	14.5574
2664.68	14.6444
2667.38	15.4208
2670.09	15.9051
2672.79	16.6007
2675.49	16.1637
2678.2	16.5389
2680.89	14.9642
2683.59	13.8807
2686.29	13.3102
2688.99	13.6282
2691.69	13.7295
2694.38	14.2504
2697.08	13.9984
2699.77	15.2712
2702.46	15.5424
2705.16	16.5708
2707.85	17.7117
2710.54	18.3697
2713.23	18.1533
2715.92	18.3477
2718.6	18.4663
2721.29	18.811
2723.97	19.7773
2726.66	19.5411
2729.34	19.6578
2732.02	18.5996
2734.7	19.0408
2737.39	18.0915
2740.06	18.2607
2742.74	17.2419
2745.42	15.2898
2748.1	13.8424
2750.77	12.997
2753.45	11.1387
2756.12	10.8692
2758.79	9.92901
2761.47	7.94663
2764.14	9.14737
2766.81	8.51231
2769.48	6.20495
2772.14	6.6732
2774.81	5.73212
2777.48	4.1858
2780.14	1.624
2782.81	1.27367
2785.47	0.95613
2788.13	-0.051564
2790.79	-0.546717
2793.46	-1.16069
2796.11	-2.0398
2798.77	-1.34881
2801.43	-0.456208
2804.09	-0.761248
2806.74	-0.641833
2809.4	-2.1605
2812.05	-1.66174
2814.71	-1.00781
2817.36	1.93369
2820.01	8.14181
2822.66	19.0321
2825.31	30.2011
2827.96	46.0489
2830.61	62.4604
2833.25	80.6667
2835.9	99.41
2838.54	118.382
2841.18	139.187
2843.83	162.615
2846.47	186.609
2849.11	210.668
2851.75	233.287
2854.39	254.537
2857.03	277.119
2859.67	296.638
2862.3	315.415
2864.94	331.804
2867.57	344.922
2870.21	356.043
2872.84	364.597
2875.47	371.5
2878.1	379.917
2880.73	387.917
2883.36	399.228
2885.99	412.246
2888.61	427
2891.24	442.306
2893.87	459.044
2896.49	477.637
2899.11	498.615
2901.74	522.857
2904.36	552.368
2906.98	586.158
2909.6	621.814
2912.22	659.465
2914.83	697.538
2917.45	734.821
2920.07	770.473
2922.68	798.569
2925.3	822.505
2927.91	841.526
2930.52	852.27
2933.13	857.228
2935.74	856.279
2938.35	846.707
2940.96	831.876
2943.57	810.823
2946.18	786.267
2948.78	757.557
2951.39	726.931
2953.99	692.614
2956.6	657.574
2959.2	622.318
2961.8	587.535
2964.4	554.904
2967	525.443
2969.6	497.509
2972.2	469.589
2974.79	443.304
2977.39	417.972
2979.98	391.445
2982.58	365.36
2985.17	337.274
2987.76	309.948
2990.36	282.837
2992.95	255.563
2995.54	229.721
2998.12	205.14
3000.71	179.379
3003.3	154.828
3005.88	134.124
3008.47	114.733
3011.05	95.4004
3013.64	81.259
3016.22	67.831
3018.8	54.1411
3021.38	43.1284
3023.96	34.1149
3026.54	27.3482
3029.12	21.735
3031.69	16.2773
3034.27	12.2385
3036.85	10.269
3039.42	9.98275
3041.99	11.3505
3044.57	10.9043
3047.14	11.6947
3049.71	12.5702
3052.28	13.6459
3054.85	13.7246
3057.42	14.628
3059.98	14.69
3062.55	12.857
3065.11	13.1565
3067.68	13.1053
3070.24	12.3177
3072.8	9.82653
3075.37	8.72436
3077.93	7.10246
3080.49	4.66993
3083.05	2.07893
3085.61	0.0790185
3088.16	-1.33658
3090.72	-2.82259
3093.27	-4.4692
3095.83	-3.49707
3098.38	-1.99013
3100.94	0.0802894
3103.49	1.74763
3106.04	2.28697
3108.59	3.86129
3111.14	7.14296
3113.69	11.006
3116.23	12.3666
3118.78	14.5726
3121.33	17.7176
3123.87	20.6111
3126.42	25.1291
3128.96	30.3094
3131.5	34.0524
3134.04	38.0861
3136.58	42.9039
3139.12	48.3497
3141.66	52.8508
3144.2	57.4743
3146.74	62.8216
3149.27	69.6115