File: data/Raman/poly_smoothed/Mb_50_18_34_1x_45s_532 nm_x100_100%_600 gr_mm_01.txt
#Acq. time (s)=	45
#Accumulations=	2
#Range (cm-¹)=	200...3150
#Windows=	2
#Auto scanning=	Off
#Autofocus=	Off
#Macrospot=	Off
#AutoExposure=	Off
#Spike filter=	Multiple accum.
#Delay time (s)=	0
#Binning=	1
#Readout mode=	Signal
#DeNoise=	Off
#ICS correction=	On
#Dark correction=	Off
#Inst. Process=	Off
#Detector Gain=	Best Dynamic Range
#Detector ADC=	20 kHz
#Detector temperature (°C)=	-69.85
#Instrument=	LabRAM HR Evol
#Detector=	Synapse
#Objective=	x100
#Grating=	600 gr/mm
#ND Filter=	100%
#Laser (nm)=	532
#Hole=	100.021
#Range=	Auto
#Laser Pol.=	No
#Raman. Pol.=	No
#Laser Pol. (°)=	-0.0007625
#Raman Pol. (°)=	89.9995
#Collection=	Microscope
#StageXY=	Marzhauser
#StageZ=	Marzhauser
#X (µm)=	28305.8
#Y (µm)=	-3227.2
#Z (µm)=	1041.05
#Full time(mm:ss)=	3:19
#Project=
#Sample=
#Site=
#Title=	Mb_50_18_34_2x_45s_532 nm_x100_100%_600 gr_mm
#Remark=
#Date=	12.07.2022 13:28
#Acquired=	12.07.2022 13:28:24
#Base:Fit=	10.08.2022 10:49:18
#Base:Sub=	10.08.2022 10:49:30
#Filter:Polynom=	16.08.2022 10:14:59
#AxisType[0]=Intens
#AxisUnit[0]=Cnt
#AxisType[1]=Spectr
#AxisUnit[1]=1/cm
200.388	55.9107
204.019	47.1663
207.646	40.0259
211.274	35.6633
214.899	32.996
218.524	32.0059
222.146	27.8903
225.766	27.0202
229.388	24.6878
233.005	22.2349
236.621	18.8417
240.236	17.3893
243.852	16.4819
247.464	16.9354
251.074	15.6568
254.683	14.6884
258.291	13.7611
261.897	11.4063
265.504	9.21618
269.108	4.70639
272.71	2.6114
276.311	2.21137
279.91	1.49357
283.508	2.18365
287.105	2.83558
290.698	6.38349
294.291	11.7149
297.884	19.4027
301.475	26.5155
305.064	31.7807
308.652	34.8151
312.237	38.8161
315.822	42.6128
319.406	44.8399
322.987	46.1834
326.568	48.9732
330.148	50.4041
333.724	49.645
337.301	45.2442
340.875	40.2969
344.449	39.05
348.02	39.7523
351.592	44.2728
355.16	53.2893
358.728	65.7767
362.294	76.6125
365.858	91.7047
369.422	104.151
372.983	118.658
376.543	127.672
380.102	136.877
383.661	143.569
387.216	147.242
390.771	148.191
394.324	144.577
397.875	138.808
401.425	130.101
404.974	117.475
408.524	103.317
412.07	87.7097
415.614	71.4738
419.156	53.6716
422.698	36.4704
426.238	20.6291
429.777	9.98776
433.315	6.40923
436.852	4.23151
440.387	5.62771
443.919	6.42653
447.451	6.02042
450.982	9.23515
454.512	10.2401
458.038	11.2658
461.565	11.7681
465.091	12.8654
468.613	14.3001
472.136	14.9129
475.655	19.2728
479.176	25.7935
482.692	33.1853
486.21	42.5132
489.724	53.8599
493.237	64.7718
496.75	78.5002
500.26	92.2327
503.771	103.031
507.279	114.023
510.785	122.571
514.289	127.631
517.793	131.865
521.297	133.166
524.797	131.423
528.297	126.659
531.795	119.149
535.291	110.397
538.787	98.5338
542.281	85.7899
545.773	72.589
549.264	59.0277
552.754	44.1675
556.243	31.9369
559.73	22.2115
563.216	16.8899
566.701	15.683
570.182	16.3227
573.664	16.2182
577.145	19.7332
580.624	23.0505
584.1	29.8373
587.577	32.8492
591.052	33.1929
594.524	37.3271
597.997	39.8192
601.466	39.7287
604.936	40.9886
608.403	41.2548
611.87	41.4881
615.334	39.1885
618.799	35.2397
622.26	32.0366
625.72	27.172
629.181	24.3441
632.638	20.3289
636.095	17.0457
639.551	13.252
643.005	12.7387
646.457	9.58651
649.908	9.05991
653.357	8.06852
656.806	7.67515
660.253	7.21149
663.7	6.64986
667.145	6.70141
670.588	7.17212
674.027	7.18124
677.468	7.84199
680.907	11.1405
684.345	12.489
687.781	14.682
691.216	16.4201
694.65	18.5875
698.081	18.7001
701.512	19.6342
704.942	22.4822
708.371	24.0974
711.796	26.2614
715.222	26.896
718.645	26.8588
722.068	24.776
725.49	24.4953
728.909	23.2185
732.329	26.0407
735.745	33.4538
739.16	47.7985
742.576	67.7046
745.988	91.955
749.401	114.892
752.811	139.716
756.22	163.175
759.627	183.722
763.035	199.691
766.44	215.288
769.843	225.258
773.245	228.8
776.646	230.252
780.046	228.806
783.444	223.989
786.841	213.27
790.237	198.524
793.631	180.126
797.024	156.797
800.416	132.726
803.807	109.776
807.196	89.3587
810.584	70.2977
813.971	55.2192
817.354	47.9523
820.739	43.4195
824.122	45.0773
827.503	46.0107
830.882	45.1488
834.261	45.3315
837.637	43.3057
841.013	43.0557
844.389	41.0319
847.761	38.747
851.131	38.9007
854.503	34.0573
857.871	31.1216
861.24	31.4887
864.606	29.6661
867.97	27.4968
871.336	25.5943
874.698	22.4577
878.058	19.5368
881.418	19.6507
884.778	18.2934
888.135	18.2812
891.49	16.0506
894.845	15.2433
898.198	15.2668
901.55	14.8819
904.901	14.6154
908.25	16.4049
911.598	15.8309
914.945	18.785
918.291	17.8247
921.635	17.9894
924.978	18.1756
928.318	18.2136
931.659	16.927
934.998	15.7125
938.336	15.9561
941.671	15.6857
945.007	14.4571
948.339	13.2686
951.672	13.1713
955.004	10.3947
958.333	7.43913
961.662	7.45985
964.989	5.64544
968.315	4.94855
971.639	2.05231
974.962	2.07904
978.285	-0.129181
981.605	-2.95695
984.924	-7.29395
988.243	-5.74186
991.56	-1.37658
994.875	6.21441
998.188	17.9477
1001.5	30.4272
1004.81	46.803
1008.12	64.7763
1011.43	83.2356
1014.74	102.592
1018.05	120.194
1021.35	135.736
1024.65	148.349
1027.96	155.983
1031.26	161.845
1034.56	164.387
1037.86	161.506
1041.16	156.102
1044.45	148.681
1047.75	139.783
1051.04	128.529
1054.33	119.072
1057.62	112.361
1060.91	105.446
1064.2	103.242
1067.49	104.779
1070.77	108.708
1074.06	113.631
1077.34	120.471
1080.62	125.454
1083.91	129.087
1087.18	133.077
1090.46	136.127
1093.74	136.857
1097.02	134.64
1100.29	129.12
1103.56	120.202
1106.84	108.771
1110.11	95.0647
1113.38	81.7065
1116.64	66.312
1119.91	49.9882
1123.18	35.5584
1126.44	24.1869
1129.7	16.3114
1132.97	11.6857
1136.23	11.8876
1139.49	10.513
1142.74	12.5771
1146	14.365
1149.26	16.5256
1152.51	17.7757
1155.76	17.0783
1159.01	17.9505
1162.27	19.7886
1165.51	21.4291
1168.76	26.5767
1172.01	30.7557
1175.25	33.8194
1178.5	36.6569
1181.74	39.6781
1184.98	41.3129
1188.22	43.7594
1191.46	48.1305
1194.7	49.4885
1197.94	49.3917
1201.17	49.3092
1204.41	47.4202
1207.64	46.2016
1210.87	47.2148
1214.1	46.7691
1217.33	46.8199
1220.56	46.6024
1223.79	48.7079
1227.01	48.9331
1230.23	48.8227
1233.46	47.3002
1236.68	46.6159
1239.9	49.305
1243.12	49.4887
1246.34	51.3564
1249.55	51.7479
1252.77	51.0019
1255.98	51.2883
1259.2	52.7576
1262.41	55.9194
1265.62	58.7998
1268.83	62.0879
1272.03	63.9152
1275.24	64.475
1278.45	65.8074
1281.65	68.1963
1284.85	69.2714
1288.06	73.1855
1291.26	74.7024
1294.46	75.6698
1297.66	75.5589
1300.85	76.504
1304.05	77.0758
1307.24	76.9768
1310.43	76.6731
1313.63	76.6764
1316.82	77.1301
1320.01	76.9579
1323.2	74.3237
1326.38	72.1128
1329.57	70.0837
1332.76	69.0397
1335.94	68.8181
1339.12	68.6731
1342.3	66.8334
1345.48	66.9939
1348.66	65.4118
1351.84	64.7266
1355.01	63.9636
1358.19	63.6526
1361.36	60.9627
1364.53	59.5147
1367.71	56.4829
1370.88	53.5687
1374.04	51.8585
1377.21	50.8955
1380.38	50.3478
1383.54	48.4039
1386.71	45.5865
1389.87	44.7689
1393.03	41.2939
1396.19	40.1396
1399.35	39.2504
1402.51	42.9422
1405.67	46.7495
1408.82	51.7972
1411.98	56.4606
1415.13	62.7454
1418.28	71.1647
1421.43	81.4835
1424.58	88.7421
1427.73	98.6059
1430.88	107.207
1434.02	113.904
1437.17	120.537
1440.31	125.017
1443.45	126.132
1446.6	128.259
1449.74	130.558
1452.87	129.457
1456.01	126.373
1459.15	124.846
1462.28	122.858
1465.42	119.412
1468.55	116.956
1471.68	114.099
1474.81	109.806
1477.94	107.951
1481.07	102.338
1484.2	98.3167
1487.32	93.8444
1490.45	89.0842
1493.57	83.8365
1496.69	80.4192
1499.81	75.7451
1502.93	71.1124
1506.05	65.6882
1509.17	59.611
1512.28	53.129
1515.4	47.696
1518.51	42.1583
1521.63	38.0354
1524.74	35.8809
1527.85	33.8006
1530.96	32.8059
1534.06	34.7602
1537.17	36.4523
1540.28	37.432
1543.38	38.3329
1546.48	41.1601
1549.59	42.3441
1552.69	42.6051
1555.79	43.8557
1558.88	45.169
1561.98	47.1647
1565.08	51.0181
1568.17	52.7914
1571.27	57.4506
1574.36	61.8747
1577.45	65.7931
1580.54	70.4927
1583.63	72.7396
1586.72	75.9456
1589.8	78.0315
1592.89	80.5741
1595.97	80.8822
1599.06	81.7805
1602.14	81.5988
1605.22	81.0471
1608.3	81.2407
1611.38	80.332
1614.46	79.4669
1617.53	78.9787
1620.61	79.9375
1623.68	80.937
1626.75	80.7437
1629.82	81.3454
1632.9	83.7103
1635.96	87.8746
1639.03	92.3783
1642.1	96.6688
1645.16	100.708
1648.23	103.744
1651.29	106.086
1654.36	109.597
1657.42	108.515
1660.48	107.415
1663.53	105.735
1666.59	102.421
1669.65	97.6392
1672.7	92.474
1675.76	87.1408
1678.81	79.8888
1681.86	72.1569
1684.91	65.9822
1687.96	58.4331
1691.01	50.8179
1694.06	45.3169
1697.11	38.2802
1700.15	32.4763
1703.2	26.7454
1706.24	23.3223
1709.28	19.6143
1712.32	16.6105
1715.36	13.1544
1718.4	11.15
1721.43	8.79729
1724.47	6.99253
1727.5	8.21986
1730.54	7.76684
1733.57	8.21682
1736.6	9.3452
1739.63	10.03
1742.66	8.84221
1745.69	8.73804
1748.72	9.26925
1751.74	8.32097
1754.77	8.53556
1757.79	9.00407
1760.81	7.24441
1763.83	5.99947
1766.85	4.81368
1769.87	3.70435
1772.89	2.69943
1775.91	2.48211
1778.92	2.33716
1781.94	2.08917
1784.95	1.08342
1787.96	0.968858
1790.97	1.34216
1793.98	1.51968
1796.99	1.28486
1800	2.41323
1803	3.61795
1806.01	4.42752
1809.01	6.3906
1812.02	6.54834
1815.02	6.90684
1818.02	6.55292
1821.02	7.90195
1824.02	8.2904
1827.01	8.81455
1830.01	9.76566
1833	9.41292
1836	10.0023
1838.99	10.6313
1841.98	11.1037
1844.97	11.6919
1847.96	11.5641
1850.95	10.8619
1853.94	11.2689
1856.92	9.41596
1859.91	9.2453
1862.89	8.56379
1865.88	8.64807
1868.86	8.58189
1871.84	9.61837
1874.82	8.59857
1877.8	8.08566
1880.77	7.32526
1882.51	6.87189
1885.5	5.68323
1888.48	6.67105
1891.47	5.91096
1894.46	5.42188
1897.44	4.93841
1900.42	4.13279
1903.41	4.58927
1906.39	3.63261
1909.37	3.89779
1912.35	4.22215
1915.32	3.87775
1918.3	3.6845
1921.28	2.33834
1924.25	2.33377
1927.22	3.17195
1930.2	2.85936
1933.17	3.42427
1936.14	3.19091
1939.11	3.68496
1942.08	2.36132
1945.04	2.83532
1948.01	3.43826
1950.97	2.20462
1953.94	2.82427
1956.9	3.63991
1959.86	4.23365
1962.82	4.84084
1965.78	4.67289
1968.74	3.89243
1971.69	4.43158
1974.65	4.30739
1977.61	5.15733
1980.56	5.55082
1983.51	8.02031
1986.46	7.31535
1989.41	6.65803
1992.36	6.00517
1995.31	5.32295
1998.26	6.56783
2001.2	6.48327
2004.15	6.70532
2007.09	5.22341
2010.04	6.15195
2012.98	6.0957
2015.92	7.11036
2018.86	6.69775
2021.8	5.31647
2024.74	5.4319
2027.67	5.62892
2030.61	6.93986
2033.54	7.79116
2036.47	8.69291
2039.41	9.12166
2042.34	10.3652
2045.27	11.0881
2048.2	12.0088
2051.12	13.5532
2054.05	14.6641
2056.98	15.9884
2059.9	15.0708
2062.82	16.095
2065.75	17.8869
2068.67	20.4035
2071.59	21.5527
2074.51	22.9421
2077.43	24.8025
2080.34	26.6972
2083.26	28.5926
2086.17	31.1133
2089.09	33.9512
2092	37.3204
2094.91	41.8188
2097.82	45.439
2100.73	47.8404
2103.64	51.2928
2106.55	55.4343
2109.46	59.502
2112.36	62.3898
2115.27	67.6899
2118.17	72.087
2121.07	77.2341
2123.97	81.4124
2126.87	85.9868
2129.77	91.8892
2132.67	95.6895
2135.57	100.973
2138.46	105.125
2141.36	109.988
2144.25	113.223
2147.14	119.065
2150.03	123.955
2152.92	128.041
2155.81	132.39
2158.7	136.233
2161.59	138.351
2164.48	140.825
2167.36	141.123
2170.25	141.595
2173.13	140.545
2176.01	141.375
2178.89	139.182
2181.77	136.726
2184.65	134.51
2187.53	131.872
2190.41	127.795
2193.28	123.296
2196.16	119.661
2199.03	116.415
2201.9	111.243
2204.78	108.689
2207.65	102.531
2210.51	97.4696
2213.38	91.6867
2216.25	86.6334
2219.12	83.2017
2221.98	77.4794
2224.85	72.9625
2227.71	68.0401
2230.57	63.0422
2233.43	59.634
2236.29	56.9132
2239.15	52.3953
2242.01	49.7851
2244.87	47.0779
2247.73	44.7695
2250.58	40.8265
2253.43	39.2969
2256.29	37.24
2259.14	34.4031
2261.99	33.4513
2264.84	32.3527
2267.69	30.9137
2270.54	29.1496
2273.38	27.6119
2276.23	25.8114
2279.07	23.9491
2281.92	23.2706
2284.76	21.071
2287.6	19.3283
2290.44	17.8771
2293.28	15.2481
2296.12	14.7118
2298.96	15.93
2301.79	17.2688
2304.63	15.9852
2307.46	15.5841
2310.3	16.4154
2313.13	15.1356
2315.96	15.2435
2318.79	13.3853
2321.62	13.637
2324.45	12.708
2327.27	11.343
2330.1	10.7593
2332.93	9.55925
2335.75	7.46374
2338.57	5.62091
2341.4	4.82255
2344.22	3.97556
2347.04	3.01737
2349.86	2.71529
2352.67	1.64096
2355.49	0.279303
2358.31	-0.28454
2361.12	-0.0531714
2363.94	1.26296
2366.75	1.58554
2369.56	1.70016
2372.37	1.1129
2375.18	1.34237
2377.99	1.8567
2380.8	2.42251
2383.61	2.51426
2386.41	2.99863
2389.22	2.66922
2392.02	3.50159
2394.82	2.01096
2397.63	2.78157
2400.43	3.05627
2403.23	2.80912
2406.02	3.37385
2408.82	4.2527
2411.62	5.78307
2414.41	5.73526
2417.21	6.55608
2420	7.53339
2422.79	7.48969
2425.59	7.61008
2428.38	7.68176
2431.17	8.23278
2433.96	8.81058
2436.74	9.29819
2439.53	10.3288
2442.32	10.3254
2445.1	9.89391
2447.88	9.30122
2450.67	8.01804
2453.45	7.7545
2456.23	6.39987
2459.01	6.12275
2461.79	5.64809
2464.57	4.31817
2467.34	2.59101
2470.12	1.37374
2472.89	0.147923
2475.67	0.516358
2478.44	1.03981
2481.21	-0.281187
2483.98	-0.863045
2486.75	-1.31315
2489.52	-1.82367
2492.29	-2.12005
2495.06	-1.9846
2497.82	-0.896122
2500.59	0.788256
2503.35	0.930383
2506.11	1.49441
2508.88	1.71364
2511.63	0.635169
2514.39	1.17184
2517.15	1.06725
2519.91	1.14413
2522.67	2.12852
2525.42	2.43077
2528.18	3.55064
2530.93	3.72317
2533.69	2.59001
2536.44	2.7887
2539.19	4.58278
2541.94	5.66107
2544.69	7.19152
2547.44	7.20645
2550.18	7.40241
2552.93	8.70396
2555.68	7.88291
2558.42	8.1777
2561.16	10.5939
2563.9	9.23052
2566.64	10.1826
2569.38	9.95089
2572.12	9.71183
2574.86	10.0118
2577.6	9.34754
2580.34	8.7591
2583.07	7.40165
2585.81	7.51971
2588.54	6.96862
2591.27	7.60379
2594	7.84133
2596.73	7.38371
2599.46	6.7569
2602.19	6.58427
2604.92	7.46687
2607.64	7.8055
2610.37	7.30028
2613.09	8.67803
2615.82	8.4163
2618.54	8.66933
2621.26	8.51492
2623.98	8.53444
2626.7	9.49921
2629.42	8.66994
2632.14	9.46311
2634.86	11.9124
2637.57	12.5842
2640.29	12.9973
2643	12.9773
2645.72	13.8059
2648.43	13.8095
2651.14	14.1322
2653.85	15.0941
2656.56	14.0453
2659.27	13.8657
2661.97	14.2884
2664.68	13.4972
2667.38	12.1907
2670.09	11.9703
2672.79	11.8037
2675.49	11.133
2678.2	11.1578
2680.89	11.1135
2683.59	10.3023
2686.29	10.1625
2688.99	9.37971
2691.69	8.95586
2694.38	8.70439
2697.08	9.53919
2699.77	10.1048
2702.46	10.323
2705.16	9.66813
2707.85	10.6924
2710.54	12.2443
2713.23	12.0324
2715.92	12.567
2718.6	13.2871
2721.29	13.3624
2723.97	14.5867
2726.66	15.2809
2729.34	14.7647
2732.02	15.2074
2734.7	15.2389
2737.39	14.9955
2740.06	14.6285
2742.74	13.6008
2745.42	11.6509
2748.1	11.0444
2750.77	10.4485
2753.45	9.73503
2756.12	9.24048
2758.79	8.29729
2761.47	6.89885
2764.14	6.41578
2766.81	4.9574
2769.48	3.16717
2772.14	2.83033
2774.81	1.98482
2777.48	1.55094
2780.14	1.57529
2782.81	1.6292
2785.47	1.34215
2788.13	1.80405
2790.79	1.41982
2793.46	1.02006
2796.11	0.989579
2798.77	1.07647
2801.43	1.14829
2804.09	0.897906
2806.74	0.462304
2809.4	1.68665
2812.05	3.22424
2814.71	5.11635
2817.36	9.02091
2820.01	12.2568
2822.66	17.8733
2825.31	24.8204
2827.96	30.6323
2830.61	37.7315
2833.25	43.9046
2835.9	51.7439
2838.54	60.9958
2841.18	70.6129
2843.83	80.9904
2846.47	91.4358
2849.11	99.3427
2851.75	108.808
2854.39	118.779
2857.03	127.929
2859.67	136.558
2862.3	144.971
2864.94	152.244
2867.57	158.872
2870.21	163.539
2872.84	168.803
2875.47	173.957
2878.1	178.021
2880.73	183.561
2883.36	188.953
2885.99	194.281
2888.61	201.033
2891.24	208.157
2893.87	216.169
2896.49	226.834
2899.11	239.161
2901.74	252.34
2904.36	269.324
2906.98	288.274
2909.6	307.836
2912.22	328.816
2914.83	351.085
2917.45	373.499
2920.07	396.096
2922.68	415.505
2925.3	431.249
2927.91	444.871
2930.52	452.302
2933.13	456.759
2935.74	458.584
2938.35	456.765
2940.96	449.497
2943.57	438.556
2946.18	424.539
2948.78	409.325
2951.39	390.839
2953.99	373.036
2956.6	355.784
2959.2	338.026
2961.8	320.735
2964.4	303.533
2967	287.644
2969.6	274.229
2972.2	260.455
2974.79	247.874
2977.39	234.772
2979.98	222.771
2982.58	211.131
2985.17	197.224
2987.76	182.554
2990.36	169.569
2992.95	154.636
2995.54	140.397
2998.12	128.159
3000.71	115.047
3003.3	100.688
3005.88	87.8263
3008.47	75.0921
3011.05	64.3161
3013.64	54.3612
3016.22	45.3371
3018.8	38.9019
3021.38	33.3802
3023.96	27.9397
3026.54	24.1132
3029.12	19.0488
3031.69	16.4802
3034.27	13.7247
3036.85	12.0754
3039.42	10.8861
3041.99	10.7417
3044.57	10.3967
3047.14	10.2614
3049.71	10.4923
3052.28	12.1615
3054.85	11.8786
3057.42	12.5001
3059.98	13.4378
3062.55	13.1578
3065.11	12.167
3067.68	11.1999
3070.24	10.0494
3072.8	8.6795
3075.37	7.95861
3077.93	5.59988
3080.49	4.77124
3083.05	4.02033
3085.61	3.27598
3088.16	2.41419
3090.72	1.61483
3093.27	0.965065
3095.83	0.576608
3098.38	0.178087
3100.94	1.49623
3103.49	1.93989
3106.04	3.08784
3108.59	5.19555
3111.14	7.09142
3113.69	9.97561
3116.23	12.3826
3118.78	15.5598
3121.33	17.8871
3123.87	21.446
3126.42	23.7891
3128.96	27.3026
3131.5	30.3795
3134.04	34.8505
3136.58	38.297
3139.12	42.2636
3141.66	46.8882
3144.2	50.662
3146.74	53.3093
3149.27	54.384