File: data/Raman/poly_smoothed/Mb_50_18_09_1x_45s_532 nm_x100_100%_600 gr_mm_01.txt
#Acq. time (s)=	45
#Accumulations=	2
#Range (cm-¹)=	200...3150
#Windows=	2
#Auto scanning=	Off
#Autofocus=	Off
#Macrospot=	Off
#AutoExposure=	Off
#Spike filter=	Multiple accum.
#Delay time (s)=	0
#Binning=	1
#Readout mode=	Signal
#DeNoise=	Off
#ICS correction=	On
#Dark correction=	Off
#Inst. Process=	Off
#Detector Gain=	Best Dynamic Range
#Detector ADC=	20 kHz
#Detector temperature (°C)=	-69.85
#Instrument=	LabRAM HR Evol
#Detector=	Synapse
#Objective=	x100
#Grating=	600 gr/mm
#ND Filter=	100%
#Laser (nm)=	532
#Hole=	100.021
#Range=	Auto
#Laser Pol.=	No
#Raman. Pol.=	No
#Laser Pol. (°)=	-0.0007625
#Raman Pol. (°)=	89.9995
#Collection=	Microscope
#StageXY=	Marzhauser
#StageZ=	Marzhauser
#X (µm)=	19328.9
#Y (µm)=	3062.8
#Z (µm)=	1047
#Full time(mm:ss)=	3:18
#Project=
#Sample=
#Site=
#Title=	Mb_50_18_09_2x_45s_532 nm_x100_100%_600 gr_mm
#Remark=
#Date=	12.07.2022 10:57
#Acquired=	12.07.2022 10:57:05
#Base:Fit=	10.08.2022 10:49:18
#Base:Sub=	10.08.2022 10:49:30
#Filter:Polynom=	16.08.2022 10:14:59
#AxisType[0]=Intens
#AxisUnit[0]=Cnt
#AxisType[1]=Spectr
#AxisUnit[1]=1/cm
200.388	9.34323
204.019	12.044
207.646	14.1288
211.274	14.8862
214.899	14.9482
218.524	16.1968
222.146	15.1023
225.766	14.7386
229.388	15.0292
233.005	14.4186
236.621	13.8082
240.236	13.0279
243.852	11.063
247.464	8.98235
251.074	5.73644
254.683	6.8797
258.291	7.0712
261.897	5.62596
265.504	7.85008
269.108	7.26307
272.71	6.69986
276.311	6.81906
279.91	4.66477
283.508	7.99023
287.105	8.87575
290.698	10.9074
294.291	14.1131
297.884	17.6896
301.475	20.7106
305.064	22.8821
308.652	23.4863
312.237	24.3181
315.822	27.3079
319.406	28.9868
322.987	28.6663
326.568	27.4477
330.148	27.0653
333.724	25.5223
337.301	24.6413
340.875	23.1126
344.449	24.8228
348.02	25.311
351.592	25.1936
355.16	25.3993
358.728	24.5582
362.294	25.988
365.858	28.4754
369.422	30.2943
372.983	32.0103
376.543	33.8443
380.102	34.8143
383.661	36.8383
387.216	38.1476
390.771	39.0342
394.324	37.6148
397.875	36.4579
401.425	35.6982
404.974	34.4018
408.524	32.324
412.07	27.5752
415.614	25.721
419.156	23.4776
422.698	22.2435
426.238	20.6189
429.777	21.5655
433.315	22.5404
436.852	21.1224
440.387	21.436
443.919	21.6718
447.451	21.6667
450.982	22.3946
454.512	22.7848
458.038	23.314
461.565	24.1209
465.091	26.0918
468.613	26.3859
472.136	28.7349
475.655	31.0616
479.176	33.2425
482.692	35.687
486.21	36.7823
489.724	40.1982
493.237	41.0153
496.75	43.419
500.26	48.0503
503.771	50.8714
507.279	52.0544
510.785	52.7905
514.289	54.1522
517.793	51.7461
521.297	50.3368
524.797	47.9549
528.297	46.3172
531.795	43.0162
535.291	38.0559
538.787	35.0318
542.281	30.0162
545.773	24.9756
549.264	19.9948
552.754	14.6621
556.243	10.7579
559.73	9.70393
563.216	9.16216
566.701	8.27192
570.182	7.51334
573.664	6.82033
577.145	7.47306
580.624	7.54949
584.1	10.0321
587.577	9.38453
591.052	7.82951
594.524	7.41813
597.997	8.23018
601.466	7.64456
604.936	7.80821
608.403	8.58374
611.87	8.81333
615.334	8.71534
618.799	7.69599
622.26	6.62148
625.72	6.286
629.181	6.82744
632.638	6.4463
636.095	6.40624
639.551	6.96865
643.005	9.31606
646.457	11.4118
649.908	10.5525
653.357	10.9959
656.806	12.5862
660.253	14.1909
663.7	13.2791
667.145	13.4643
670.588	14.6692
674.027	14.432
677.468	15.8409
680.907	17.1005
684.345	18.2224
687.781	18.5634
691.216	19.9056
694.65	22.2324
698.081	22.4323
701.512	23.6023
704.942	23.9917
708.371	24.5017
711.796	26.1525
715.222	28.0753
718.645	28.4003
722.068	29.3559
725.49	29.3468
728.909	28.5074
732.329	27.7169
735.745	31.7504
739.16	35.4669
742.576	41.4939
745.988	47.0047
749.401	52.2191
752.811	57.8682
756.22	62.8633
759.627	68.6281
763.035	73.5537
766.44	77.0165
769.843	81.3702
773.245	83.9382
776.646	86.5914
780.046	86.8539
783.444	87.778
786.841	87.3644
790.237	86.2941
793.631	86.3729
797.024	85.3311
800.416	82.151
803.807	80.8955
807.196	77.3083
810.584	75.6237
813.971	74.0855
817.354	74.8699
820.739	76.363
824.122	75.9492
827.503	75.9799
830.882	75.637
834.261	74.2589
837.637	74.7264
841.013	73.7325
844.389	71.1504
847.761	67.8271
851.131	64.3084
854.503	61.7318
857.871	59.0981
861.24	56.0069
864.606	50.4827
867.97	48.1717
871.336	44.1777
874.698	41.1748
878.058	38.0388
881.418	36.3378
884.778	35.7197
888.135	33.8708
891.49	33.1368
894.845	32.2624
898.198	31.7176
901.55	29.6577
904.901	28.6844
908.25	29.8616
911.598	30.3353
914.945	30.4622
918.291	31.6937
921.635	31.6561
924.978	31.5371
928.318	32.0831
931.659	30.8034
934.998	32.0964
938.336	32.9436
941.671	32.1729
945.007	31.7829
948.339	30.5894
951.672	32.3045
955.004	33.5302
958.333	33.385
961.662	32.265
964.989	32.8681
968.315	31.9399
971.639	30.6063
974.962	30.5173
978.285	29.6588
981.605	27.5682
984.924	26.1876
988.243	27.0926
991.56	27.0951
994.875	28.7265
998.188	31.9984
1001.5	36.0572
1004.81	39.5068
1008.12	42.206
1011.43	46.3691
1014.74	50.642
1018.05	55.2593
1021.35	60.9628
1024.65	64.265
1027.96	67.6693
1031.26	70.0274
1034.56	72.0262
1037.86	70.7058
1041.16	69.1305
1044.45	67.66
1047.75	66.771
1051.04	64.9842
1054.33	63.5665
1057.62	63.2399
1060.91	60.5535
1064.2	58.7827
1067.49	57.4636
1070.77	56.4615
1074.06	54.1574
1077.34	54.0608
1080.62	54.0887
1083.91	52.1749
1087.18	50.5642
1090.46	50.9274
1093.74	50.3022
1097.02	51.4814
1100.29	49.7284
1103.56	49.3433
1106.84	48.3453
1110.11	48.016
1113.38	45.4962
1116.64	43.6974
1119.91	40.0114
1123.18	37.2532
1126.44	34.7268
1129.7	33.6191
1132.97	31.4654
1136.23	31.3158
1139.49	27.4942
1142.74	23.3586
1146	18.463
1149.26	16.4275
1152.51	12.5347
1155.76	10.0673
1159.01	5.9666
1162.27	3.34731
1165.51	2.12685
1168.76	1.31634
1172.01	1.20732
1175.25	1.34671
1178.5	2.24036
1181.74	2.71729
1184.98	3.91608
1188.22	3.72474
1191.46	3.04498
1194.7	5.34169
1197.94	5.80413
1201.17	5.46571
1204.41	7.06217
1207.64	8.23328
1210.87	11.8378
1214.1	14.3879
1217.33	19.1014
1220.56	22.9021
1223.79	27.8864
1227.01	32.8857
1230.23	37.0284
1233.46	40.0931
1236.68	43.3056
1239.9	48.8255
1243.12	53.8755
1246.34	57.9416
1249.55	62.0317
1252.77	64.6811
1255.98	68.8249
1259.2	72.9797
1262.41	74.5313
1265.62	76.716
1268.83	79.0088
1272.03	83.8803
1275.24	85.4135
1278.45	86.4881
1281.65	88.4832
1284.85	90.1681
1288.06	92.5458
1291.26	94.3001
1294.46	95.6231
1297.66	95.942
1300.85	97.0351
1304.05	96.6332
1307.24	95.7098
1310.43	95.4554
1313.63	95.4724
1316.82	96.0169
1320.01	95.926
1323.2	94.5332
1326.38	91.7134
1329.57	89.4686
1332.76	87.5881
1335.94	85.847
1339.12	82.6105
1342.3	80.6762
1345.48	76.0663
1348.66	73.6641
1351.84	70.9561
1355.01	65.3409
1358.19	61.398
1361.36	56.5828
1364.53	50.0073
1367.71	43.7898
1370.88	39.8846
1374.04	37.036
1377.21	33.577
1380.38	31.7416
1383.54	28.2361
1386.71	26.6303
1389.87	25.9116
1393.03	24.0189
1396.19	23.2927
1399.35	22.9209
1402.51	22.6016
1405.67	25.1883
1408.82	28.7672
1411.98	32.3095
1415.13	37.4442
1418.28	44.622
1421.43	52.4761
1424.58	61.377
1427.73	71.3501
1430.88	78.3397
1434.02	86.8254
1437.17	94.0547
1440.31	98.5169
1443.45	103.99
1446.6	107.917
1449.74	111.291
1452.87	113.341
1456.01	114.475
1459.15	115.323
1462.28	114.959
1465.42	113.124
1468.55	109.615
1471.68	105.45
1474.81	100.11
1477.94	93.09
1481.07	86.2809
1484.2	79.9208
1487.32	72.118
1490.45	65.0625
1493.57	59.6734
1496.69	55.4658
1499.81	51.0711
1502.93	45.8906
1506.05	40.8613
1509.17	36.9646
1512.28	32.5395
1515.4	27.6748
1518.51	24.4691
1521.63	23.2559
1524.74	21.4907
1527.85	21.6615
1530.96	22.7606
1534.06	24.5133
1537.17	25.2552
1540.28	28.3139
1543.38	28.5096
1546.48	29.6529
1549.59	32.0593
1552.69	31.5206
1555.79	32.2122
1558.88	31.0603
1561.98	30.7973
1565.08	32.7025
1568.17	36.7709
1571.27	40.5388
1574.36	44.6972
1577.45	48.4084
1580.54	53.2382
1583.63	56.5848
1586.72	60.4845
1589.8	62.6792
1592.89	64.5416
1595.97	68.1232
1599.06	70.4891
1602.14	70.7158
1605.22	71.6096
1608.3	69.7341
1611.38	69.4388
1614.46	69.4164
1617.53	70.9816
1620.61	69.2709
1623.68	69.9174
1626.75	72.4033
1629.82	73.0549
1632.9	75.3494
1635.96	78.6779
1639.03	82.7638
1642.1	87.7094
1645.16	90.9866
1648.23	96.4783
1651.29	99.7341
1654.36	103.194
1657.42	104.534
1660.48	105.537
1663.53	104.333
1666.59	104.18
1669.65	102.283
1672.7	99.0562
1675.76	94.5374
1678.81	87.9677
1681.86	81.0471
1684.91	76.0925
1687.96	69.3275
1691.01	61.985
1694.06	55.4019
1697.11	48.4435
1700.15	43.5037
1703.2	39.8777
1706.24	35.4296
1709.28	30.2457
1712.32	25.9385
1715.36	22.4615
1718.4	18.8163
1721.43	18.0993
1724.47	16.2828
1727.5	14.9
1730.54	12.6633
1733.57	11.7813
1736.6	10.7455
1739.63	8.53612
1742.66	8.95553
1745.69	8.82607
1748.72	8.81879
1751.74	8.0445
1754.77	7.4317
1757.79	7.73506
1760.81	6.48521
1763.83	5.39361
1766.85	4.74747
1769.87	4.04651
1772.89	3.01461
1775.91	4.52941
1778.92	3.85976
1781.94	3.55688
1784.95	2.28096
1787.96	1.67398
1790.97	1.30864
1793.98	0.709378
1796.99	0.93909
1800	0.359974
1803	-1.14361
1806.01	-0.851041
1809.01	0.164197
1812.02	-0.446361
1815.02	0.990682
1818.02	2.78377
1821.02	3.09715
1824.02	2.22685
1827.01	2.7348
1830.01	3.80446
1833	4.32219
1836	4.80914
1838.99	5.26635
1841.98	5.40454
1844.97	6.12877
1847.96	5.97687
1850.95	5.36613
1853.94	4.97371
1856.92	3.92256
1859.91	3.74291
1862.89	3.01506
1865.88	2.09289
1868.86	1.56956
1871.84	1.05672
1874.82	1.57984
1877.8	1.5117
1880.77	1.44828
1882.51	1.77017
1885.5	1.92795
1888.48	0.783161
1891.47	-0.262621
1894.46	-1.122
1897.44	-0.864742
1900.42	1.37138
1903.41	2.19699
1906.39	3.06063
1909.37	4.05357
1912.35	4.23764
1915.32	5.61324
1918.3	6.07063
1921.28	5.63123
1924.25	5.18021
1927.22	4.06504
1930.2	4.79473
1933.17	5.68491
1936.14	4.53174
1939.11	5.07313
1942.08	5.35635
1945.04	4.14181
1948.01	3.73632
1950.97	3.09917
1953.94	2.32039
1956.9	2.66356
1959.86	0.221894
1962.82	-0.765114
1965.78	-0.594966
1968.74	-0.36381
1971.69	0.755422
1974.65	0.807559
1977.61	2.08484
1980.56	2.04573
1983.51	1.84621
1986.46	1.35974
1989.41	1.71418
1992.36	2.00594
1995.31	2.23281
1998.26	2.74224
2001.2	3.49203
2004.15	4.24544
2007.09	4.49284
2010.04	4.81677
2012.98	5.30921
2015.92	5.77304
2018.86	5.46006
2021.8	6.95065
2024.74	7.0982
2027.67	8.40933
2030.61	8.27539
2033.54	9.50177
2036.47	10.8086
2039.41	11.541
2042.34	12.4377
2045.27	14.8121
2048.2	17.2427
2051.12	19.1596
2054.05	20.5444
2056.98	22.4699
2059.9	23.9166
2062.82	26.9935
2065.75	29.7574
2068.67	32.4406
2071.59	34.2266
2074.51	37.3013
2077.43	40.0037
2080.34	43.2048
2083.26	46.4683
2086.17	49.9296
2089.09	53.4757
2092	58.9906
2094.91	64.0054
2097.82	69.1865
2100.73	73.4784
2103.64	78.5133
2106.55	83.4105
2109.46	88.925
2112.36	96.6295
2115.27	104.002
2118.17	109.608
2121.07	115.971
2123.97	122.034
2126.87	129.434
2129.77	138.34
2132.67	146.343
2135.57	154.432
2138.46	161.789
2141.36	167.026
2144.25	173.339
2147.14	179.142
2150.03	185.764
2152.92	191.66
2155.81	196.647
2158.7	201.464
2161.59	205.313
2164.48	207.555
2167.36	208.011
2170.25	207.957
2173.13	206.561
2176.01	206.242
2178.89	203.345
2181.77	199.912
2184.65	194.996
2187.53	188.22
2190.41	182.518
2193.28	177.7
2196.16	172.587
2199.03	166.191
2201.9	159.496
2204.78	152.776
2207.65	144.05
2210.51	137.463
2213.38	130.513
2216.25	123.45
2219.12	116.615
2221.98	109.967
2224.85	104.074
2227.71	95.4329
2230.57	89.4352
2233.43	81.1862
2236.29	74.6697
2239.15	68.3798
2242.01	63.6771
2244.87	59.4097
2247.73	55.0931
2250.58	50.5719
2253.43	46.2884
2256.29	43.3274
2259.14	40.9177
2261.99	38.6589
2264.84	36.4479
2267.69	35.3015
2270.54	33.3147
2273.38	32.9621
2276.23	32.8791
2279.07	32.2314
2281.92	31.8657
2284.76	28.8515
2287.6	27.1047
2290.44	25.2299
2293.28	22.7951
2296.12	21.0807
2298.96	20.9662
2301.79	19.165
2304.63	17.9359
2307.46	16.4768
2310.3	15.8001
2313.13	14.8288
2315.96	13.4402
2318.79	12.3731
2321.62	10.5753
2324.45	8.70837
2327.27	9.00052
2330.1	8.82606
2332.93	8.54936
2335.75	6.97859
2338.57	6.42266
2341.4	6.82157
2344.22	6.96824
2347.04	6.03097
2349.86	5.61932
2352.67	4.71406
2355.49	3.873
2358.31	3.93917
2361.12	3.43893
2363.94	3.85378
2366.75	4.80842
2369.56	5.20196
2372.37	4.71196
2375.18	4.58965
2377.99	3.58493
2380.8	3.05437
2383.61	3.14207
2386.41	3.09264
2389.22	4.66601
2392.02	4.9079
2394.82	6.60062
2397.63	6.9576
2400.43	8.46564
2403.23	8.43065
2406.02	8.76694
2408.82	9.66862
2411.62	10.1364
2414.41	10.8065
2417.21	9.78652
2420	10.5694
2422.79	9.68917
2425.59	8.69545
2428.38	8.2564
2431.17	7.18599
2433.96	5.77119
2436.74	4.84296
2439.53	4.08136
2442.32	2.55756
2445.1	1.52501
2447.88	0.33563
2450.67	-0.794436
2453.45	-1.39466
2456.23	-1.38656
2459.01	-1.54587
2461.79	-1.27372
2464.57	-2.30326
2467.34	-0.84178
2470.12	0.735741
2472.89	1.00388
2475.67	0.869574
2478.44	2.81294
2481.21	1.88858
2483.98	2.59599
2486.75	3.93757
2489.52	4.50875
2492.29	4.07727
2495.06	4.84611
2497.82	5.22232
2500.59	5.34294
2503.35	6.17398
2506.11	6.16365
2508.88	5.03868
2511.63	5.97254
2514.39	6.25985
2517.15	6.13721
2519.91	6.92318
2522.67	7.38907
2525.42	7.43971
2528.18	7.52013
2530.93	7.00055
2533.69	7.19763
2536.44	8.56452
2539.19	8.7685
2541.94	8.60054
2544.69	7.57368
2547.44	8.13155
2550.18	8.3326
2552.93	9.63914
2555.68	9.40191
2558.42	9.83943
2561.16	9.17073
2563.9	9.94987
2566.64	9.69145
2569.38	10.6893
2572.12	9.74037
2574.86	10.2569
2577.6	12.1335
2580.34	12.4817
2583.07	13.1792
2585.81	13.7521
2588.54	12.127
2591.27	11.0606
2594	10.8693
2596.73	9.68086
2599.46	9.18267
2602.19	7.8863
2604.92	7.59356
2607.64	6.45148
2610.37	6.09175
2613.09	5.85474
2615.82	6.10271
2618.54	5.77905
2621.26	6.2149
2623.98	5.72925
2626.7	5.27947
2629.42	6.5724
2632.14	6.98244
2634.86	8.31948
2637.57	9.77345
2640.29	10.6294
2643	12.7892
2645.72	13.1883
2648.43	13.4875
2651.14	15.3854
2653.85	14.5868
2656.56	14.8202
2659.27	14.6884
2661.97	14.6662
2664.68	14.6551
2667.38	15.0032
2670.09	14.4235
2672.79	14.0429
2675.49	13.8376
2678.2	14.351
2680.89	14.3034
2683.59	13.3333
2686.29	13.4662
2688.99	12.6241
2691.69	11.6133
2694.38	12.016
2697.08	12.4754
2699.77	12.367
2702.46	13.1154
2705.16	12.5916
2707.85	12.4129
2710.54	12.9229
2713.23	13.1636
2715.92	13.6975
2718.6	13.6422
2721.29	14.5208
2723.97	13.8926
2726.66	13.7411
2729.34	14.4579
2732.02	13.7402
2734.7	13.0037
2737.39	12.0091
2740.06	12.893
2742.74	12.0904
2745.42	11.4435
2748.1	9.63318
2750.77	8.56472
2753.45	7.10004
2756.12	5.84438
2758.79	4.66625
2761.47	3.88512
2764.14	2.4837
2766.81	3.15432
2769.48	2.57974
2772.14	2.4396
2774.81	2.69158
2777.48	3.89916
2780.14	2.02059
2782.81	2.10015
2785.47	2.21096
2788.13	2.15199
2790.79	1.02375
2793.46	1.01477
2796.11	0.530535
2798.77	0.683875
2801.43	-0.322719
2804.09	-0.502014
2806.74	-2.34864
2809.4	-3.8549
2812.05	-4.57926
2814.71	-5.43101
2817.36	-4.2994
2820.01	-0.689146
2822.66	5.64955
2825.31	12.7085
2827.96	23.6086
2830.61	34.3111
2833.25	45.8115
2835.9	57.831
2838.54	70.2094
2841.18	83.2593
2843.83	96.2845
2846.47	111.585
2849.11	125.925
2851.75	140.844
2854.39	154.279
2857.03	167.602
2859.67	181.929
2862.3	193.325
2864.94	202.62
2867.57	211.442
2870.21	219.272
2872.84	225.572
2875.47	233.34
2878.1	239.807
2880.73	246.609
2883.36	255.269
2885.99	262.674
2888.61	269.72
2891.24	278.107
2893.87	285.698
2896.49	293.44
2899.11	303.151
2901.74	313.261
2904.36	324.786
2906.98	336.994
2909.6	351.865
2912.22	366.55
2914.83	380.277
2917.45	393.601
2920.07	405.073
2922.68	414.579
2925.3	422.48
2927.91	428.033
2930.52	430.784
2933.13	431.078
2935.74	427.71
2938.35	421.665
2940.96	412.81
2943.57	401.852
2946.18	387.266
2948.78	370.449
2951.39	352.649
2953.99	335.033
2956.6	316.685
2959.2	297.583
2961.8	278.985
2964.4	260.762
2967	243.03
2969.6	225.516
2972.2	209.479
2974.79	195.519
2977.39	180.001
2979.98	165.309
2982.58	148.934
2985.17	134.25
2987.76	120.965
2990.36	108.254
2992.95	96.3716
2995.54	83.2985
2998.12	71.6736
3000.71	61.7718
3003.3	52.5038
3005.88	44.8147
3008.47	36.9694
3011.05	28.0777
3013.64	23.1357
3016.22	18.9454
3018.8	14.766
3021.38	11.2268
3023.96	8.04464
3026.54	5.19414
3029.12	3.70879
3031.69	1.85862
3034.27	2.58377
3036.85	1.9934
3039.42	3.01382
3041.99	3.21116
3044.57	3.98388
3047.14	5.33768
3049.71	8.22793
3052.28	9.94578
3054.85	12.1812
3057.42	12.8971
3059.98	13.2768
3062.55	12.8938
3065.11	12.5957
3067.68	12.0039
3070.24	11.7098
3072.8	11.3496
3075.37	11.1458
3077.93	11.033
3080.49	10.2172
3083.05	8.95013
3085.61	7.96563
3088.16	6.9959
3090.72	7.22684
3093.27	8.02216
3095.83	8.56578
3098.38	9.14303
3100.94	10.9788
3103.49	12.8408
3106.04	15.2136
3108.59	17.9379
3111.14	20.1156
3113.69	22.4155
3116.23	24.9167
3118.78	27.0762
3121.33	28.3998
3123.87	30.5557
3126.42	32.1837
3128.96	34.6309
3131.5	38.504
3134.04	40.6287
3136.58	43.7055
3139.12	46.9241
3141.66	50.1196
3144.2	54.1391
3146.74	59.0627
3149.27	62.7421