File: data/Raman/poly_smoothed/Mb_50_18_18_1x_45s_532 nm_x100_100%_600 gr_mm_02.txt
#Acq. time (s)=	45
#Accumulations=	2
#Range (cm-¹)=	200...3150
#Windows=	2
#Auto scanning=	Off
#Autofocus=	Off
#Macrospot=	Off
#AutoExposure=	Off
#Spike filter=	Multiple accum.
#Delay time (s)=	0
#Binning=	1
#Readout mode=	Signal
#DeNoise=	Off
#ICS correction=	On
#Dark correction=	Off
#Inst. Process=	Off
#Detector Gain=	Best Dynamic Range
#Detector ADC=	20 kHz
#Detector temperature (°C)=	-69.85
#Instrument=	LabRAM HR Evol
#Detector=	Synapse
#Objective=	x100
#Grating=	600 gr/mm
#ND Filter=	100%
#Laser (nm)=	532
#Hole=	100.021
#Range=	Auto
#Laser Pol.=	No
#Raman. Pol.=	No
#Laser Pol. (°)=	-0.0007625
#Raman Pol. (°)=	89.9995
#Collection=	Microscope
#StageXY=	Marzhauser
#StageZ=	Marzhauser
#X (µm)=	19283.8
#Y (µm)=	3015.8
#Z (µm)=	1047.7
#Full time(mm:ss)=	3:15
#Project=
#Sample=
#Site=
#Title=	Mb_50_18_18_2x_45s_532 nm_x100_100%_600 gr_mm
#Remark=
#Date=	12.07.2022 11:35
#Acquired=	12.07.2022 11:35:56
#Base:Fit=	10.08.2022 10:49:18
#Base:Sub=	10.08.2022 10:49:30
#Filter:Polynom=	16.08.2022 10:14:59
#AxisType[0]=Intens
#AxisUnit[0]=Cnt
#AxisType[1]=Spectr
#AxisUnit[1]=1/cm
200.388	11.637
204.019	9.76632
207.646	7.75087
211.274	5.67393
214.899	5.73397
218.524	5.0323
222.146	4.05595
225.766	3.92959
229.388	3.51875
233.005	3.20678
236.621	4.11666
240.236	4.04594
243.852	4.8795
247.464	5.16441
251.074	6.35248
254.683	6.15024
258.291	6.05664
261.897	7.36151
265.504	6.85757
269.108	7.78581
272.71	5.95476
276.311	4.81496
279.91	4.81729
283.508	5.03819
287.105	4.59664
290.698	5.6338
294.291	7.06851
297.884	8.78916
301.475	12.1609
305.064	13.266
308.652	14.4067
312.237	15.4146
315.822	16.7906
319.406	18.4679
322.987	20.7629
326.568	21.4876
330.148	22.1577
333.724	21.2703
337.301	21.1194
340.875	20.2862
344.449	20.7369
348.02	21.7494
351.592	22.4828
355.16	23.3418
358.728	23.3909
362.294	24.778
365.858	27.5443
369.422	29.4353
372.983	31.2387
376.543	33.4858
380.102	34.6728
383.661	36.3871
387.216	36.0155
390.771	35.4101
394.324	33.7427
397.875	32.4737
401.425	29.8695
404.974	28.5515
408.524	25.7633
412.07	21.5285
415.614	15.8362
419.156	11.497
422.698	8.52976
426.238	6.36523
429.777	5.24334
433.315	4.30807
436.852	4.33788
440.387	5.39585
443.919	5.95814
447.451	7.22277
450.982	8.26659
454.512	8.76371
458.038	9.27819
461.565	11.9484
465.091	12.8406
468.613	13.5302
472.136	13.9302
475.655	14.524
479.176	16.5539
482.692	18.6611
486.21	22.2173
489.724	25.402
493.237	27.1655
496.75	28.8633
500.26	30.2583
503.771	32.4354
507.279	34.4018
510.785	35.6064
514.289	36.0328
517.793	37.0956
521.297	38.139
524.797	38.7467
528.297	38.0775
531.795	36.8089
535.291	34.9812
538.787	32.0517
542.281	28.2834
545.773	24.3063
549.264	21.3632
552.754	17.2726
556.243	14.1941
559.73	11.0755
563.216	9.25177
566.701	8.0633
570.182	9.44231
573.664	8.45215
577.145	6.80029
580.624	6.27218
584.1	6.15386
587.577	6.13002
591.052	5.32223
594.524	6.3554
597.997	7.06296
601.466	8.66406
604.936	9.97727
608.403	10.5078
611.87	8.76633
615.334	8.25817
618.799	8.08787
622.26	7.96894
625.72	6.49496
629.181	7.35655
632.638	6.04907
636.095	6.20677
639.551	5.45034
643.005	6.56529
646.457	5.70051
649.908	5.76636
653.357	7.18989
656.806	6.46332
660.253	6.25991
663.7	5.39276
667.145	8.08168
670.588	10.5919
674.027	11.7825
677.468	14.7871
680.907	16.6811
684.345	18.9154
687.781	22.3247
691.216	23.9023
694.65	25.5612
698.081	27.2769
701.512	29.7271
704.942	30.851
708.371	32.3126
711.796	32.9945
715.222	34.0708
718.645	33.1032
722.068	32.5519
725.49	32.3215
728.909	30.4392
732.329	30.5057
735.745	32.1387
739.16	35.2446
742.576	39.6353
745.988	45.3539
749.401	50.7109
752.811	57.9931
756.22	63.1606
759.627	68.8628
763.035	73.8405
766.44	79.5186
769.843	83.6646
773.245	86.6399
776.646	87.9875
780.046	88.198
783.444	88.7166
786.841	88.1771
790.237	87.5926
793.631	85.0268
797.024	82.2139
800.416	78.1692
803.807	73.6653
807.196	69.4907
810.584	66.3421
813.971	64.9806
817.354	64.8403
820.739	65.4111
824.122	65.388
827.503	65.5043
830.882	64.8634
834.261	64.0512
837.637	63.5499
841.013	61.724
844.389	58.6593
847.761	56.8044
851.131	53.7733
854.503	50.1728
857.871	46.9053
861.24	45.9706
864.606	43.8881
867.97	43.89
871.336	42.6391
874.698	41.267
878.058	39.9435
881.418	40.0464
884.778	40.3589
888.135	39.2892
891.49	38.5114
894.845	38.4328
898.198	38.4029
901.55	38.417
904.901	38.2803
908.25	37.4466
911.598	38.0398
914.945	36.6124
918.291	36.0717
921.635	33.25
924.978	31.9583
928.318	30.8654
931.659	30.1509
934.998	29.4578
938.336	30.0682
941.671	29.4498
945.007	29.2966
948.339	28.7927
951.672	29.4431
955.004	28.1295
958.333	28.242
961.662	28.4116
964.989	27.8931
968.315	26.685
971.639	26.3794
974.962	25.6856
978.285	26.1542
981.605	25.1034
984.924	24.8781
988.243	24.3114
991.56	23.9891
994.875	24.2727
998.188	26.1533
1001.5	28.4627
1004.81	31.9323
1008.12	35.6963
1011.43	39.165
1014.74	43.0399
1018.05	45.6721
1021.35	46.9346
1024.65	50.5038
1027.96	52.7443
1031.26	52.6362
1034.56	51.9421
1037.86	50.0344
1041.16	50.0347
1044.45	47.6059
1047.75	45.5527
1051.04	43.2838
1054.33	40.736
1057.62	37.9639
1060.91	35.658
1064.2	32.2159
1067.49	31.172
1070.77	29.8844
1074.06	28.8187
1077.34	30.4018
1080.62	30.3749
1083.91	31.0323
1087.18	32.5768
1090.46	33.0449
1093.74	33.9408
1097.02	34.1506
1100.29	32.431
1103.56	32.9896
1106.84	32.4721
1110.11	29.0339
1113.38	26.154
1116.64	24.944
1119.91	22.1996
1123.18	18.6735
1126.44	16.9809
1129.7	15.4199
1132.97	13.6342
1136.23	12.3658
1139.49	11.837
1142.74	10.186
1146	8.90387
1149.26	8.40729
1152.51	5.95729
1155.76	4.46992
1159.01	3.73638
1162.27	3.10123
1165.51	3.61766
1168.76	4.14807
1172.01	3.42808
1175.25	2.05289
1178.5	1.33382
1181.74	1.61183
1184.98	2.24469
1188.22	1.30833
1191.46	1.13999
1194.7	2.59636
1197.94	2.29955
1201.17	2.39484
1204.41	4.3421
1207.64	6.0392
1210.87	7.68767
1214.1	9.35613
1217.33	11.0453
1220.56	13.3307
1223.79	14.981
1227.01	17.3441
1230.23	18.3588
1233.46	19.3863
1236.68	21.5016
1239.9	23.6075
1243.12	25.7944
1246.34	27.9798
1249.55	27.9708
1252.77	28.3025
1255.98	30.3969
1259.2	31.9686
1262.41	34.1857
1265.62	36.5202
1268.83	39.3873
1272.03	42.8512
1275.24	46.8961
1278.45	49.0861
1281.65	51.5392
1284.85	53.3067
1288.06	54.7239
1291.26	56.4998
1294.46	57.4276
1297.66	57.618
1300.85	58.7906
1304.05	58.9731
1307.24	59.4868
1310.43	57.6384
1313.63	56.4921
1316.82	55.106
1320.01	52.8796
1323.2	50.1463
1326.38	46.9827
1329.57	45.1822
1332.76	42.8761
1335.94	42.2767
1339.12	40.4753
1342.3	38.0177
1345.48	35.586
1348.66	33.899
1351.84	31.9646
1355.01	30.0377
1358.19	27.3069
1361.36	25.5224
1364.53	23.3328
1367.71	21.9081
1370.88	20.9284
1374.04	20.3434
1377.21	20.6085
1380.38	20.8822
1383.54	21.4668
1386.71	20.2523
1389.87	19.6127
1393.03	19.3269
1396.19	19.413
1399.35	19.9399
1402.51	22.4417
1405.67	25.3094
1408.82	28.6925
1411.98	32.4794
1415.13	35.937
1418.28	39.3074
1421.43	43.9622
1424.58	47.5747
1427.73	51.9014
1430.88	55.3572
1434.02	59.1438
1437.17	61.9679
1440.31	64.3849
1443.45	65.4031
1446.6	66.8474
1449.74	67.3944
1452.87	66.8401
1456.01	65.9492
1459.15	62.2643
1462.28	58.2252
1465.42	55.0637
1468.55	51.0577
1471.68	46.9366
1474.81	43.8966
1477.94	40.0486
1481.07	36.7377
1484.2	32.9481
1487.32	29.1217
1490.45	26.6974
1493.57	24.3765
1496.69	22.1901
1499.81	20.0154
1502.93	16.9957
1506.05	14.848
1509.17	13.0384
1512.28	12.2984
1515.4	11.5513
1518.51	10.7524
1521.63	11.515
1524.74	11.6382
1527.85	12.5592
1530.96	14.034
1534.06	14.726
1537.17	15.4145
1540.28	16.7184
1543.38	18.0343
1546.48	19.3503
1549.59	20.9075
1552.69	21.9473
1555.79	22.8375
1558.88	23.7357
1561.98	24.3181
1565.08	25.2189
1568.17	26.617
1571.27	27.6133
1574.36	29.6591
1577.45	30.2842
1580.54	31.5947
1583.63	33.1606
1586.72	34.5678
1589.8	36.2527
1592.89	36.8961
1595.97	37.8899
1599.06	38.1177
1602.14	39.1369
1605.22	39.4813
1608.3	39.7511
1611.38	40.5622
1614.46	41.3241
1617.53	42.9792
1620.61	42.7576
1623.68	44.4485
1626.75	45.8725
1629.82	48.0761
1632.9	49.524
1635.96	50.3219
1639.03	51.1515
1642.1	53.0983
1645.16	54.7823
1648.23	56.6717
1651.29	57.8111
1654.36	57.4094
1657.42	57.7758
1660.48	57.0307
1663.53	56.3169
1666.59	55.1551
1669.65	54.4652
1672.7	51.9629
1675.76	49.1147
1678.81	46.9054
1681.86	43.923
1684.91	40.936
1687.96	37.4521
1691.01	34.1261
1694.06	29.3752
1697.11	26.6244
1700.15	23.5657
1703.2	20.6483
1706.24	17.6467
1709.28	14.4709
1712.32	10.8893
1715.36	8.6493
1718.4	7.5958
1721.43	6.28778
1724.47	5.018
1727.5	4.53741
1730.54	3.11372
1733.57	3.60293
1736.6	4.4182
1739.63	4.58971
1742.66	5.55609
1745.69	5.38454
1748.72	5.21921
1751.74	4.82252
1754.77	4.0621
1757.79	3.93287
1760.81	3.73509
1763.83	4.00846
1766.85	3.77305
1769.87	3.91477
1772.89	3.35492
1775.91	3.80439
1778.92	3.63546
1781.94	3.83946
1784.95	3.65227
1787.96	2.97788
1790.97	4.0693
1793.98	4.49148
1796.99	4.67288
1800	3.7804
1803	2.5925
1806.01	2.9115
1809.01	3.07003
1812.02	3.28149
1815.02	2.74782
1818.02	2.10563
1821.02	0.979277
1824.02	1.32566
1827.01	0.879738
1830.01	1.60585
1833	2.15218
1836	3.33755
1838.99	4.85405
1841.98	5.22632
1844.97	5.75219
1847.96	5.97765
1850.95	5.42661
1853.94	5.1182
1856.92	5.3101
1859.91	6.11834
1862.89	6.58214
1865.88	6.15754
1868.86	5.53782
1871.84	4.55815
1874.82	4.11212
1877.8	3.57068
1880.77	3.32696
1882.51	3.09527
1885.5	3.46643
1888.48	2.40447
1891.47	2.12579
1894.46	2.28188
1897.44	3.07618
1900.42	3.6437
1903.41	4.58085
1906.39	4.75252
1909.37	4.63272
1912.35	5.75434
1915.32	4.63984
1918.3	4.24437
1921.28	3.14223
1924.25	1.94534
1927.22	1.76162
1930.2	2.72829
1933.17	3.60246
1936.14	3.87319
1939.11	3.23429
1942.08	2.48275
1945.04	3.16175
1948.01	3.47179
1950.97	4.71467
1953.94	5.32368
1956.9	5.25983
1959.86	4.29513
1962.82	4.06289
1965.78	3.95782
1968.74	3.82414
1971.69	3.45689
1974.65	3.6223
1977.61	3.93563
1980.56	4.14355
1983.51	4.56856
1986.46	4.55399
1989.41	4.23586
1992.36	4.95678
1995.31	5.14549
1998.26	5.78378
2001.2	6.25458
2004.15	6.69713
2007.09	7.07547
2010.04	6.53621
2012.98	6.68494
2015.92	7.2806
2018.86	7.76873
2021.8	8.04608
2024.74	7.50821
2027.67	7.0796
2030.61	7.33932
2033.54	7.78873
2036.47	9.03071
2039.41	8.85006
2042.34	9.29293
2045.27	9.17755
2048.2	10.1029
2051.12	10.0918
2054.05	10.8767
2056.98	10.9371
2059.9	12.0074
2062.82	12.5561
2065.75	12.682
2068.67	13.4721
2071.59	14.2495
2074.51	14.8522
2077.43	16.1683
2080.34	17.554
2083.26	18.6404
2086.17	19.5313
2089.09	21.0782
2092	23.5974
2094.91	25.0507
2097.82	25.4566
2100.73	28.2473
2103.64	30.6976
2106.55	32.2739
2109.46	34.2207
2112.36	35.903
2115.27	37.0263
2118.17	39.2543
2121.07	41.4813
2123.97	44.125
2126.87	46.61
2129.77	50.2359
2132.67	53.3491
2135.57	56.313
2138.46	59.4221
2141.36	62.4314
2144.25	66.3642
2147.14	69.6355
2150.03	72.4175
2152.92	73.8305
2155.81	75.6473
2158.7	77.9215
2161.59	77.9678
2164.48	78.5107
2167.36	78.3004
2170.25	79.2293
2173.13	79.1946
2176.01	77.3306
2178.89	76.9467
2181.77	75.6697
2184.65	73.14
2187.53	70.6393
2190.41	69.5582
2193.28	67.8335
2196.16	66.0041
2199.03	63.1009
2201.9	61.8365
2204.78	59.5618
2207.65	57.436
2210.51	55.2469
2213.38	52.8701
2216.25	50.5729
2219.12	48.2801
2221.98	45.9237
2224.85	43.3998
2227.71	41.3353
2230.57	38.5579
2233.43	37.4758
2236.29	34.7313
2239.15	32.9902
2242.01	30.8855
2244.87	26.6564
2247.73	24.7849
2250.58	22.8644
2253.43	20.5279
2256.29	19.7088
2259.14	18.6769
2261.99	18.3995
2264.84	16.7665
2267.69	15.5344
2270.54	15.5444
2273.38	15.1476
2276.23	14.506
2279.07	13.3511
2281.92	12.3194
2284.76	11.0284
2287.6	10.991
2290.44	10.0079
2293.28	9.2942
2296.12	8.5898
2298.96	8.16889
2301.79	7.90184
2304.63	7.70813
2307.46	6.57069
2310.3	6.45451
2313.13	5.96308
2315.96	5.36373
2318.79	6.15183
2321.62	6.83112
2324.45	7.44051
2327.27	7.70944
2330.1	7.82891
2332.93	7.80856
2335.75	8.71808
2338.57	8.4246
2341.4	8.84621
2344.22	8.12446
2347.04	7.62246
2349.86	6.18475
2352.67	6.14644
2355.49	5.13178
2358.31	4.29497
2361.12	4.04393
2363.94	4.21878
2366.75	4.83619
2369.56	3.2704
2372.37	2.89611
2375.18	2.10033
2377.99	3.02387
2380.8	2.96169
2383.61	3.21545
2386.41	3.31257
2389.22	3.63619
2392.02	5.06864
2394.82	6.37354
2397.63	6.81465
2400.43	6.37359
2403.23	7.07328
2406.02	7.80952
2408.82	7.89734
2411.62	8.30718
2414.41	7.91433
2417.21	8.52595
2420	7.80224
2422.79	7.56338
2425.59	7.29598
2428.38	7.44117
2431.17	7.79129
2433.96	6.84447
2436.74	4.90689
2439.53	3.16272
2442.32	2.42456
2445.1	2.09173
2447.88	1.53407
2450.67	0.866254
2453.45	0.813148
2456.23	1.36683
2459.01	1.38864
2461.79	1.31906
2464.57	1.30339
2467.34	0.935871
2470.12	0.687481
2472.89	1.47389
2475.67	1.56574
2478.44	0.919919
2481.21	1.38298
2483.98	1.14447
2486.75	0.902127
2489.52	0.969567
2492.29	1.58307
2495.06	1.9021
2497.82	2.24459
2500.59	2.01399
2503.35	1.15857
2506.11	0.793326
2508.88	-0.185036
2511.63	0.216463
2514.39	0.324597
2517.15	0.483361
2519.91	0.55103
2522.67	-0.0829735
2525.42	0.261055
2528.18	0.202126
2530.93	1.16235
2533.69	1.34994
2536.44	2.32778
2539.19	2.49132
2541.94	2.71334
2544.69	2.77847
2547.44	3.01853
2550.18	3.46158
2552.93	4.28892
2555.68	5.24578
2558.42	5.5095
2561.16	4.90643
2563.9	4.48966
2566.64	5.11515
2569.38	4.55512
2572.12	4.34315
2574.86	5.00191
2577.6	4.6051
2580.34	4.65203
2583.07	4.48723
2585.81	3.47981
2588.54	3.68845
2591.27	4.46981
2594	4.82665
2596.73	5.00088
2599.46	5.31354
2602.19	5.47953
2604.92	5.85308
2607.64	6.28863
2610.37	6.9982
2613.09	6.81328
2615.82	7.62953
2618.54	6.9902
2621.26	6.63881
2623.98	5.92728
2626.7	4.99181
2629.42	5.33714
2632.14	6.56277
2634.86	7.16612
2637.57	7.17944
2640.29	7.38809
2643	6.78021
2645.72	7.00955
2648.43	7.29802
2651.14	7.39513
2653.85	7.47015
2656.56	7.22118
2659.27	7.59253
2661.97	7.79669
2664.68	8.68943
2667.38	9.24566
2670.09	9.77957
2672.79	9.17585
2675.49	8.48097
2678.2	7.91891
2680.89	7.30844
2683.59	7.2639
2686.29	7.13042
2688.99	7.7422
2691.69	7.89866
2694.38	7.74329
2697.08	7.80721
2699.77	6.80817
2702.46	5.51685
2705.16	4.49114
2707.85	4.49484
2710.54	4.92102
2713.23	4.83449
2715.92	4.85772
2718.6	5.43822
2721.29	5.18176
2723.97	5.38203
2726.66	6.10634
2729.34	6.21854
2732.02	5.9785
2734.7	5.93441
2737.39	5.33662
2740.06	5.83929
2742.74	6.58054
2745.42	6.66827
2748.1	6.48205
2750.77	7.0275
2753.45	6.42229
2756.12	6.07303
2758.79	5.41463
2761.47	3.75117
2764.14	2.69898
2766.81	1.31259
2769.48	1.41265
2772.14	1.39617
2774.81	1.60672
2777.48	0.992714
2780.14	1.13672
2782.81	0.71105
2785.47	0.470993
2788.13	0.147585
2790.79	-0.838814
2793.46	-0.258657
2796.11	0.008855
2798.77	1.34434
2801.43	2.34577
2804.09	2.88972
2806.74	2.86136
2809.4	2.36611
2812.05	2.12148
2814.71	2.85631
2817.36	4.40273
2820.01	6.122
2822.66	9.22359
2825.31	12.2986
2827.96	16.8516
2830.61	21.0139
2833.25	27.2932
2835.9	32.0489
2838.54	36.4447
2841.18	41.5345
2843.83	47.689
2846.47	54.4181
2849.11	60.3379
2851.75	66.4606
2854.39	72.6468
2857.03	78.5713
2859.67	85.0478
2862.3	90.0137
2864.94	94.0661
2867.57	97.97
2870.21	100.459
2872.84	102.459
2875.47	105.181
2878.1	107.66
2880.73	110.421
2883.36	112.726
2885.99	117.345
2888.61	121.254
2891.24	123.721
2893.87	127.705
2896.49	130.696
2899.11	134.589
2901.74	139.2
2904.36	146.371
2906.98	152.897
2909.6	160.02
2912.22	167.299
2914.83	174.142
2917.45	181.224
2920.07	187.304
2922.68	193.115
2925.3	197.155
2927.91	199.7
2930.52	201.064
2933.13	201.298
2935.74	199.675
2938.35	197.4
2940.96	194.393
2943.57	188.98
2946.18	183.235
2948.78	176.615
2951.39	170.1
2953.99	162.015
2956.6	154.127
2959.2	145.589
2961.8	137.832
2964.4	130.098
2967	123.194
2969.6	116.12
2972.2	108.644
2974.79	102.26
2977.39	95.5222
2979.98	88.8037
2982.58	82.0302
2985.17	75.5191
2987.76	68.2383
2990.36	61.1661
2992.95	54.1715
2995.54	48.6405
2998.12	43.002
3000.71	37.6649
3003.3	32.9171
3005.88	28.6149
3008.47	24.9283
3011.05	22.1064
3013.64	19.7975
3016.22	17.4831
3018.8	14.9276
3021.38	12.0804
3023.96	10.4017
3026.54	9.58604
3029.12	9.60476
3031.69	9.32455
3034.27	8.99753
3036.85	8.85564
3039.42	9.04307
3041.99	9.31447
3044.57	9.64621
3047.14	9.84914
3049.71	9.60987
3052.28	8.78013
3054.85	8.70028
3057.42	8.47687
3059.98	8.28102
3062.55	7.08834
3065.11	6.81693
3067.68	5.93431
3070.24	5.37866
3072.8	4.74208
3075.37	4.62023
3077.93	4.0269
3080.49	3.78231
3083.05	3.99105
3085.61	4.17168
3088.16	3.8109
3090.72	4.83438
3093.27	5.89279
3095.83	7.37084
3098.38	7.84945
3100.94	8.8535
3103.49	9.90974
3106.04	11.3304
3108.59	12.3042
3111.14	13.5122
3113.69	14.8038
3116.23	15.882
3118.78	17.2143
3121.33	18.8206
3123.87	19.7045
3126.42	20.786
3128.96	21.9625
3131.5	23.4784
3134.04	25.0015
3136.58	26.6729
3139.12	28.921
3141.66	30.5007
3144.2	31.8943
3146.74	33.8084
3149.27	34.9979