File: data/Raman/poly_smoothed/Mb_50_18_03_1x_45s_532 nm_x100_100%_600 gr_mm_01.txt
#Acq. time (s)=	45
#Accumulations=	2
#Range (cm-¹)=	200...3150
#Windows=	2
#Auto scanning=	Off
#Autofocus=	Off
#Macrospot=	Off
#AutoExposure=	Off
#Spike filter=	Multiple accum.
#Delay time (s)=	0
#Binning=	1
#Readout mode=	Signal
#DeNoise=	Off
#ICS correction=	On
#Dark correction=	Off
#Inst. Process=	Off
#Detector Gain=	Best Dynamic Range
#Detector ADC=	20 kHz
#Detector temperature (°C)=	-69.85
#Instrument=	LabRAM HR Evol
#Detector=	Synapse
#Objective=	x100
#Grating=	600 gr/mm
#ND Filter=	100%
#Laser (nm)=	532
#Hole=	100.021
#Range=	Auto
#Laser Pol.=	No
#Raman. Pol.=	No
#Laser Pol. (°)=	-0.0007625
#Raman Pol. (°)=	89.9995
#Collection=	Microscope
#StageXY=	Marzhauser
#StageZ=	Marzhauser
#X (µm)=	19372.9
#Y (µm)=	3036
#Z (µm)=	1047.65
#Full time(mm:ss)=	3:18
#Project=
#Sample=
#Site=
#Title=	Mb_50_18_03_2x_45s_532 nm_x100_100%_600 gr_mm
#Remark=
#Date=	12.07.2022 10:27
#Acquired=	12.07.2022 10:27:20
#Base:Fit=	10.08.2022 10:49:18
#Base:Sub=	10.08.2022 10:49:30
#Filter:Polynom=	16.08.2022 10:14:59
#AxisType[0]=Intens
#AxisUnit[0]=Cnt
#AxisType[1]=Spectr
#AxisUnit[1]=1/cm
200.388	-8.3372
204.019	2.08382
207.646	8.43147
211.274	12.5268
214.899	13.5898
218.524	14.3421
222.146	16.4168
225.766	15.7425
229.388	17.307
233.005	16.9283
236.621	16.2922
240.236	13.9233
243.852	14.3793
247.464	14.2426
251.074	13.0404
254.683	12.182
258.291	10.3697
261.897	9.42601
265.504	9.15446
269.108	9.50912
272.71	9.41371
276.311	9.97028
279.91	12.2478
283.508	13.5247
287.105	14.1787
290.698	16.7135
294.291	17.9446
297.884	20.3142
301.475	23.0953
305.064	25.4747
308.652	28.7024
312.237	29.7444
315.822	29.3644
319.406	30.5066
322.987	30.198
326.568	29.8591
330.148	28.8504
333.724	28.1153
337.301	26.8033
340.875	23.4936
344.449	21.6152
348.02	21.6111
351.592	21.9686
355.16	24.6593
358.728	25.602
362.294	27.6966
365.858	30.3399
369.422	32.4183
372.983	35.3677
376.543	38.7738
380.102	42.2204
383.661	43.16
387.216	45.3265
390.771	44.6272
394.324	43.5173
397.875	40.8482
401.425	37.5534
404.974	33.396
408.524	29.8389
412.07	25.069
415.614	19.9174
419.156	14.3224
422.698	9.52587
426.238	5.25899
429.777	2.64189
433.315	0.903471
436.852	0.0216471
440.387	0.225761
443.919	-0.39089
447.451	-0.391104
450.982	0.508152
454.512	1.98601
458.038	4.69947
461.565	7.93103
465.091	9.76813
468.613	11.8622
472.136	13.9877
475.655	16.1609
479.176	17.1861
482.692	19.4857
486.21	21.2412
489.724	24.2726
493.237	26.9431
496.75	29.1191
500.26	32.7772
503.771	34.2738
507.279	35.7713
510.785	35.4493
514.289	36.2275
517.793	34.6312
521.297	33.3084
524.797	31.0997
528.297	29.3807
531.795	26.9762
535.291	24.6517
538.787	23.4347
542.281	20.5508
545.773	18.2436
549.264	15.3447
552.754	12.5494
556.243	8.68229
559.73	5.81557
563.216	4.58093
566.701	2.40816
570.182	3.18322
573.664	2.38889
577.145	3.79599
580.624	4.60835
584.1	7.1758
587.577	7.81464
591.052	10.0461
594.524	10.0638
597.997	11.031
601.466	11.2416
604.936	11.2544
608.403	12.4342
611.87	10.6038
615.334	10.7799
618.799	11.4118
622.26	10.0447
625.72	8.83963
629.181	7.9177
632.638	7.06923
636.095	6.07061
639.551	4.21428
643.005	1.93358
646.457	1.18781
649.908	0.462601
653.357	1.41699
656.806	2.33148
660.253	2.59712
663.7	5.31558
667.145	6.15414
670.588	7.3861
674.027	7.7009
677.468	9.45851
680.907	13.2139
684.345	14.375
687.781	16.5789
691.216	19.6505
694.65	22.035
698.081	23.5837
701.512	25.1558
704.942	25.8
708.371	26.7328
711.796	29.5711
715.222	31.2256
718.645	30.5732
722.068	30.4166
725.49	28.3702
728.909	29.1059
732.329	30.7197
735.745	35.8581
739.16	41.9216
742.576	47.278
745.988	54.7197
749.401	60.5685
752.811	65.3014
756.22	71.7442
759.627	80.4578
763.035	87.0984
766.44	91.112
769.843	95.3413
773.245	97.7178
776.646	100.317
780.046	99.7692
783.444	99.9931
786.841	100.518
790.237	97.5307
793.631	95.3279
797.024	90.6142
800.416	85.9589
803.807	81.4294
807.196	76.9778
810.584	72.8869
813.971	72.7137
817.354	71.4582
820.739	72.6766
824.122	71.6043
827.503	70.9045
830.882	70.5757
834.261	68.5372
837.637	67.5822
841.013	67.691
844.389	65.1669
847.761	62.2173
851.131	58.0215
854.503	55.7064
857.871	53.7214
861.24	51.9211
864.606	49.7691
867.97	47.5558
871.336	44.781
874.698	42.8557
878.058	42.3879
881.418	40.2565
884.778	40.9302
888.135	40.5429
891.49	40.4346
894.845	39.8218
898.198	40.2297
901.55	39.5558
904.901	37.5121
908.25	38.0907
911.598	37.8032
914.945	37.7741
918.291	36.466
921.635	36.495
924.978	36.0384
928.318	34.6132
931.659	32.7653
934.998	30.6382
938.336	29.8389
941.671	26.803
945.007	25.3967
948.339	23.5327
951.672	24.7054
955.004	23.9636
958.333	21.5789
961.662	19.4817
964.989	20.2222
968.315	20.9009
971.639	21.7729
974.962	21.5934
978.285	21.3398
981.605	22.0646
984.924	20.7765
988.243	21.0561
991.56	21.4658
994.875	23.2037
998.188	26.4421
1001.5	31.4934
1004.81	36.9305
1008.12	41.745
1011.43	45.3317
1014.74	50.8804
1018.05	55.9283
1021.35	57.6455
1024.65	60.2411
1027.96	64.1312
1031.26	63.926
1034.56	64.1724
1037.86	61.777
1041.16	59.9544
1044.45	58.8806
1047.75	57.1839
1051.04	53.61
1054.33	50.7492
1057.62	48.3184
1060.91	44.0419
1064.2	39.878
1067.49	36.2381
1070.77	34.4026
1074.06	35.2444
1077.34	38.1544
1080.62	39.4052
1083.91	39.5589
1087.18	38.4344
1090.46	37.7494
1093.74	36.888
1097.02	35.3134
1100.29	35.1875
1103.56	33.6115
1106.84	30.8698
1110.11	28.9535
1113.38	26.0695
1116.64	24.0409
1119.91	23.517
1123.18	18.8405
1126.44	15.5573
1129.7	13.0019
1132.97	13.1263
1136.23	13.5807
1139.49	11.9512
1142.74	9.48031
1146	8.98983
1149.26	10.0013
1152.51	9.70646
1155.76	9.07115
1159.01	7.29578
1162.27	5.47228
1165.51	5.61585
1168.76	7.19559
1172.01	8.86884
1175.25	8.29312
1178.5	8.85413
1181.74	9.80921
1184.98	9.51223
1188.22	11.6265
1191.46	12.2703
1194.7	12.4227
1197.94	13.5987
1201.17	14.3168
1204.41	14.1492
1207.64	16.9988
1210.87	19.7963
1214.1	21.4494
1217.33	22.2815
1220.56	24.4069
1223.79	25.7342
1227.01	29.0006
1230.23	30.719
1233.46	30.9124
1236.68	32.9017
1239.9	34.6228
1243.12	36.8025
1246.34	38.5277
1249.55	39.2587
1252.77	38.3108
1255.98	38.6271
1259.2	42.0998
1262.41	43.6986
1265.62	45.4306
1268.83	44.4975
1272.03	46.8773
1275.24	49.1556
1278.45	51.7632
1281.65	54.9226
1284.85	59.3992
1288.06	61.6661
1291.26	62.5521
1294.46	65.2869
1297.66	66.4374
1300.85	66.8264
1304.05	65.7134
1307.24	67.0673
1310.43	66.3569
1313.63	66.636
1316.82	64.8223
1320.01	63.5528
1323.2	61.8065
1326.38	59.9216
1329.57	57.2686
1332.76	55.1681
1335.94	54.6537
1339.12	52.4622
1342.3	50.0838
1345.48	47.2604
1348.66	45.5775
1351.84	45.7119
1355.01	43.0997
1358.19	41.286
1361.36	40.1467
1364.53	36.1647
1367.71	33.5463
1370.88	32.1555
1374.04	29.2968
1377.21	26.6077
1380.38	25.7927
1383.54	26.4665
1386.71	26.3163
1389.87	24.695
1393.03	23.7985
1396.19	23.1052
1399.35	23.1772
1402.51	23.2236
1405.67	24.3704
1408.82	27.1246
1411.98	31.2732
1415.13	35.5412
1418.28	39.7523
1421.43	44.4997
1424.58	48.8218
1427.73	54.4714
1430.88	58.3349
1434.02	61.2521
1437.17	64.0036
1440.31	67.1177
1443.45	70.2236
1446.6	72.7882
1449.74	72.4505
1452.87	72.541
1456.01	72.4213
1459.15	71.725
1462.28	69.8084
1465.42	67.1824
1468.55	62.6081
1471.68	59.5675
1474.81	56.3507
1477.94	51.9163
1481.07	48.9646
1484.2	45.4171
1487.32	42.1679
1490.45	39.5686
1493.57	37.9296
1496.69	35.1233
1499.81	32.0744
1502.93	29.5836
1506.05	25.6416
1509.17	23.075
1512.28	20.4046
1515.4	18.7086
1518.51	17.151
1521.63	15.3093
1524.74	14.4812
1527.85	12.7703
1530.96	14.3072
1534.06	13.7095
1537.17	15.2689
1540.28	16.6758
1543.38	16.4985
1546.48	18.6801
1549.59	20.7546
1552.69	22.6137
1555.79	23.9644
1558.88	25.3235
1561.98	26.8276
1565.08	28.5146
1568.17	30.2698
1571.27	33.514
1574.36	35.9937
1577.45	38.3534
1580.54	40.1166
1583.63	41.2079
1586.72	42.2291
1589.8	41.6621
1592.89	43.2138
1595.97	43.7497
1599.06	44.4912
1602.14	45.9617
1605.22	45.7809
1608.3	45.5009
1611.38	43.9943
1614.46	44.5686
1617.53	45.2699
1620.61	45.0762
1623.68	47.0199
1626.75	48.1644
1629.82	49.6232
1632.9	51.1356
1635.96	53.2844
1639.03	55.643
1642.1	59.309
1645.16	64.2662
1648.23	69.0968
1651.29	70.2873
1654.36	72.1288
1657.42	72.8856
1660.48	73.3959
1663.53	74.2255
1666.59	73.3844
1669.65	72.4904
1672.7	69.1463
1675.76	65.3263
1678.81	61.1502
1681.86	55.3934
1684.91	51.3344
1687.96	47.8543
1691.01	44.3599
1694.06	39.3399
1697.11	33.6197
1700.15	29.8373
1703.2	24.975
1706.24	21.3691
1709.28	19.2052
1712.32	14.7829
1715.36	12.81
1718.4	10.9465
1721.43	9.76583
1724.47	7.99596
1727.5	7.90711
1730.54	7.03171
1733.57	6.05407
1736.6	4.67256
1739.63	4.50393
1742.66	2.85342
1745.69	2.4037
1748.72	1.7999
1751.74	2.11453
1754.77	3.12287
1757.79	3.68101
1760.81	3.695
1763.83	3.17248
1766.85	1.01919
1769.87	0.703432
1772.89	0.680603
1775.91	1.07461
1778.92	1.20393
1781.94	2.72372
1784.95	3.52835
1787.96	3.08165
1790.97	3.42221
1793.98	3.77646
1796.99	4.51394
1800	3.98251
1803	3.75373
1806.01	3.21105
1809.01	3.48789
1812.02	4.07326
1815.02	3.53081
1818.02	3.42729
1821.02	3.60212
1824.02	3.32353
1827.01	4.3238
1830.01	4.28875
1833	4.18504
1836	3.5091
1838.99	3.43609
1841.98	4.55099
1844.97	4.8292
1847.96	5.68959
1850.95	6.08976
1853.94	7.35996
1856.92	7.34658
1859.91	6.95609
1862.89	6.12737
1865.88	5.54177
1868.86	5.17535
1871.84	4.02444
1874.82	4.51195
1877.8	3.55537
1880.77	4.11929
1882.51	3.8507
1885.5	2.38779
1888.48	2.1919
1891.47	1.52488
1894.46	0.855413
1897.44	1.47157
1900.42	0.829274
1903.41	0.4104
1906.39	-0.943441
1909.37	-0.543144
1912.35	-0.0752385
1915.32	0.389144
1918.3	-0.209405
1921.28	0.996921
1924.25	1.2432
1927.22	2.0402
1930.2	1.7699
1933.17	0.795831
1936.14	1.43462
1939.11	1.99305
1942.08	2.42892
1945.04	2.9377
1948.01	2.7385
1950.97	1.78542
1953.94	3.05611
1956.9	2.28293
1959.86	1.73835
1962.82	0.455828
1965.78	0.542019
1968.74	0.850732
1971.69	1.95985
1974.65	2.71419
1977.61	2.9129
1980.56	3.10565
1983.51	5.55835
1986.46	6.18649
1989.41	6.85298
1992.36	7.75765
1995.31	9.57483
1998.26	10.45
2001.2	11.7743
2004.15	12.8676
2007.09	13.3685
2010.04	13.7671
2012.98	14.6982
2015.92	14.4349
2018.86	14.754
2021.8	15.3617
2024.74	14.4061
2027.67	15.0531
2030.61	13.8506
2033.54	14.2411
2036.47	14.0608
2039.41	14.7515
2042.34	16.4535
2045.27	18.076
2048.2	18.1563
2051.12	19.0359
2054.05	20.6836
2056.98	21.2848
2059.9	22.8771
2062.82	23.8635
2065.75	25.5945
2068.67	26.8013
2071.59	27.3151
2074.51	28.4185
2077.43	29.0939
2080.34	30.8929
2083.26	31.5527
2086.17	33.1517
2089.09	36.0373
2092	36.6742
2094.91	38.9206
2097.82	39.9791
2100.73	41.9814
2103.64	44.7975
2106.55	46.7879
2109.46	49.1327
2112.36	52.3837
2115.27	54.6807
2118.17	57.9316
2121.07	60.851
2123.97	65.1667
2126.87	69.4015
2129.77	73.8206
2132.67	77.2689
2135.57	81.7103
2138.46	85.3956
2141.36	90.1378
2144.25	94.2804
2147.14	97.3164
2150.03	101.478
2152.92	105.266
2155.81	108.287
2158.7	110.784
2161.59	112.33
2164.48	115.213
2167.36	116.892
2170.25	118.091
2173.13	118.815
2176.01	115.997
2178.89	113.924
2181.77	112.114
2184.65	110.128
2187.53	108.846
2190.41	106.14
2193.28	104.076
2196.16	102.061
2199.03	98.1931
2201.9	95.2721
2204.78	91.9439
2207.65	88.6021
2210.51	85.6623
2213.38	81.9312
2216.25	77.8336
2219.12	73.8241
2221.98	71.3896
2224.85	67.9984
2227.71	64.6059
2230.57	61.7797
2233.43	59.9482
2236.29	57.2573
2239.15	51.618
2242.01	46.9576
2244.87	43.14
2247.73	38.1698
2250.58	36.6012
2253.43	34.956
2256.29	32.8602
2259.14	29.8569
2261.99	28.1507
2264.84	27.14
2267.69	24.7132
2270.54	23.8629
2273.38	22.4084
2276.23	20.7543
2279.07	21.4804
2281.92	20.9521
2284.76	20.5912
2287.6	19.571
2290.44	19.0128
2293.28	17.3543
2296.12	16.9558
2298.96	17.4345
2301.79	16.8495
2304.63	15.72
2307.46	13.9618
2310.3	13.058
2313.13	13.9627
2315.96	12.812
2318.79	12.7882
2321.62	12.7829
2324.45	11.6237
2327.27	13.0974
2330.1	12.8337
2332.93	13.0896
2335.75	13.3094
2338.57	11.6284
2341.4	11.1453
2344.22	11.2224
2347.04	11.0039
2349.86	10.6802
2352.67	9.84291
2355.49	9.17814
2358.31	7.98405
2361.12	6.53674
2363.94	5.74994
2366.75	6.01351
2369.56	5.05411
2372.37	4.09946
2375.18	3.98744
2377.99	4.12843
2380.8	3.38981
2383.61	2.74687
2386.41	2.70803
2389.22	2.33107
2392.02	3.37659
2394.82	4.21142
2397.63	4.76453
2400.43	4.65117
2403.23	4.47334
2406.02	5.24441
2408.82	5.35774
2411.62	5.09867
2414.41	6.94628
2417.21	7.50857
2420	7.63926
2422.79	7.83234
2425.59	6.63297
2428.38	6.01555
2431.17	5.66648
2433.96	6.65059
2436.74	5.03532
2439.53	5.09209
2442.32	3.33916
2445.1	3.26766
2447.88	2.78207
2450.67	2.29356
2453.45	2.3568
2456.23	1.34834
2459.01	1.26193
2461.79	1.83973
2464.57	1.51252
2467.34	1.03807
2470.12	1.49068
2472.89	2.38769
2475.67	3.33597
2478.44	2.07638
2481.21	3.19226
2483.98	2.3101
2486.75	2.85406
2489.52	3.37014
2492.29	2.96616
2495.06	4.51952
2497.82	4.12619
2500.59	3.31255
2503.35	3.95824
2506.11	1.64686
2508.88	2.03308
2511.63	2.23278
2514.39	2.71588
2517.15	2.97451
2519.91	2.02312
2522.67	1.23031
2525.42	1.78096
2528.18	2.31574
2530.93	1.72488
2533.69	1.89585
2536.44	2.61148
2539.19	2.67177
2541.94	2.95276
2544.69	3.0309
2547.44	2.80605
2550.18	3.18914
2552.93	3.34394
2555.68	5.00282
2558.42	4.36461
2561.16	5.87022
2563.9	6.28239
2566.64	6.42652
2569.38	7.57556
2572.12	7.67301
2574.86	8.27177
2577.6	9.54708
2580.34	9.63254
2583.07	9.35929
2585.81	8.81831
2588.54	8.7384
2591.27	8.76147
2594	9.06954
2596.73	9.0182
2599.46	9.33778
2602.19	8.0879
2604.92	7.03237
2607.64	6.54034
2610.37	6.89195
2613.09	6.87708
2615.82	6.21581
2618.54	6.60209
2621.26	7.31546
2623.98	7.51115
2626.7	7.79323
2629.42	8.06437
2632.14	7.74523
2634.86	7.80343
2637.57	7.43342
2640.29	6.49491
2643	5.20439
2645.72	4.62953
2648.43	4.29166
2651.14	3.31744
2653.85	4.40993
2656.56	5.08366
2659.27	5.49557
2661.97	6.27114
2664.68	5.0321
2667.38	3.99873
2670.09	3.25709
2672.79	3.16086
2675.49	3.35153
2678.2	4.33854
2680.89	5.85721
2683.59	5.91515
2686.29	6.65757
2688.99	6.67508
2691.69	6.87701
2694.38	7.65146
2697.08	8.05535
2699.77	8.23395
2702.46	9.74773
2705.16	10.6047
2707.85	11.7835
2710.54	11.778
2713.23	13.4494
2715.92	13.8217
2718.6	13.6631
2721.29	13.8859
2723.97	13.9095
2726.66	13.0332
2729.34	11.3073
2732.02	10.0106
2734.7	8.27547
2737.39	7.02379
2740.06	6.48723
2742.74	5.68925
2745.42	4.9301
2748.1	4.92307
2750.77	3.81495
2753.45	2.90646
2756.12	1.82862
2758.79	1.55007
2761.47	2.19066
2764.14	3.26782
2766.81	2.88946
2769.48	3.34296
2772.14	2.77689
2774.81	2.02417
2777.48	2.43195
2780.14	2.31082
2782.81	2.5647
2785.47	2.85877
2788.13	3.9631
2790.79	3.7717
2793.46	2.74468
2796.11	1.9718
2798.77	3.04594
2801.43	4.51263
2804.09	5.43911
2806.74	6.83787
2809.4	7.77675
2812.05	9.48588
2814.71	10.4932
2817.36	10.5223
2820.01	12.9392
2822.66	16.1999
2825.31	20.3665
2827.96	24.588
2830.61	28.7773
2833.25	33.6435
2835.9	39.3748
2838.54	45.9263
2841.18	53.2885
2843.83	59.8458
2846.47	65.6103
2849.11	74.5881
2851.75	82.4674
2854.39	89.549
2857.03	95.8282
2859.67	103.936
2862.3	111.351
2864.94	117.981
2867.57	122.819
2870.21	128.046
2872.84	132.958
2875.47	135.964
2878.1	139.204
2880.73	141.452
2883.36	144.808
2885.99	148.143
2888.61	151.161
2891.24	155.687
2893.87	161.247
2896.49	165.85
2899.11	173.546
2901.74	181.603
2904.36	189.092
2906.98	200.187
2909.6	211.174
2912.22	223.866
2914.83	237.207
2917.45	248.262
2920.07	258.686
2922.68	267.271
2925.3	274.58
2927.91	280.167
2930.52	283.294
2933.13	285.718
2935.74	284.889
2938.35	281.313
2940.96	275.37
2943.57	267.515
2946.18	258.199
2948.78	248.369
2951.39	238.753
2953.99	228.33
2956.6	216.619
2959.2	205.951
2961.8	194.947
2964.4	185.03
2967	175.091
2969.6	166.336
2972.2	157.221
2974.79	148.565
2977.39	140.517
2979.98	131.284
2982.58	122.327
2985.17	112.48
2987.76	102.169
2990.36	92.784
2992.95	83.3439
2995.54	74.4238
2998.12	65.5552
3000.71	56.2461
3003.3	48.436
3005.88	41.4209
3008.47	36.0371
3011.05	30.6637
3013.64	27.0491
3016.22	23.4227
3018.8	20.1079
3021.38	17.0493
3023.96	15.3362
3026.54	13.8855
3029.12	13.8456
3031.69	12.8903
3034.27	12.4145
3036.85	12.3382
3039.42	13.907
3041.99	13.6378
3044.57	14.3433
3047.14	14.264
3049.71	13.2672
3052.28	12.0612
3054.85	10.6606
3057.42	9.56899
3059.98	8.93718
3062.55	8.88147
3065.11	8.53425
3067.68	8.43371
3070.24	7.7588
3072.8	7.03798
3075.37	6.40589
3077.93	5.33747
3080.49	4.53634
3083.05	4.60239
3085.61	5.12572
3088.16	3.95042
3090.72	3.16624
3093.27	2.7948
3095.83	2.84115
3098.38	2.97339
3100.94	3.12178
3103.49	4.13289
3106.04	4.88864
3108.59	5.56183
3111.14	4.87259
3113.69	4.71768
3116.23	5.15705
3118.78	5.52979
3121.33	6.77599
3123.87	7.25069
3126.42	7.53684
3128.96	7.24317
3131.5	7.63571
3134.04	7.52869
3136.58	7.47414
3139.12	6.95501
3141.66	6.12259
3144.2	4.52739
3146.74	1.61528
3149.27	-0.0606363