File: data/Raman/poly_smoothed/Mb_50_18_07_1x_45s_532 nm_x100_100%_600 gr_mm_01.txt
#Acq. time (s)=	45
#Accumulations=	2
#Range (cm-¹)=	200...3150
#Windows=	2
#Auto scanning=	Off
#Autofocus=	Off
#Macrospot=	Off
#AutoExposure=	Off
#Spike filter=	Multiple accum.
#Delay time (s)=	0
#Binning=	1
#Readout mode=	Signal
#DeNoise=	Off
#ICS correction=	On
#Dark correction=	Off
#Inst. Process=	Off
#Detector Gain=	Best Dynamic Range
#Detector ADC=	20 kHz
#Detector temperature (°C)=	-69.85
#Instrument=	LabRAM HR Evol
#Detector=	Synapse
#Objective=	x100
#Grating=	600 gr/mm
#ND Filter=	100%
#Laser (nm)=	532
#Hole=	100.021
#Range=	Auto
#Laser Pol.=	No
#Raman. Pol.=	No
#Laser Pol. (°)=	-0.0007625
#Raman Pol. (°)=	89.9995
#Collection=	Microscope
#StageXY=	Marzhauser
#StageZ=	Marzhauser
#X (µm)=	19388.6
#Y (µm)=	3092.3
#Z (µm)=	1047
#Full time(mm:ss)=	3:18
#Project=
#Sample=
#Site=
#Title=	Mb_50_18_07_2x_45s_532 nm_x100_100%_600 gr_mm
#Remark=
#Date=	12.07.2022 10:44
#Acquired=	12.07.2022 10:44:21
#Base:Fit=	10.08.2022 10:49:18
#Base:Sub=	10.08.2022 10:49:30
#Filter:Polynom=	16.08.2022 10:14:59
#AxisType[0]=Intens
#AxisUnit[0]=Cnt
#AxisType[1]=Spectr
#AxisUnit[1]=1/cm
200.388	30.7411
204.019	28.8271
207.646	25.7661
211.274	22.1147
214.899	20.4239
218.524	19.5863
222.146	17.9869
225.766	13.9516
229.388	10.7663
233.005	10.7826
236.621	9.32809
240.236	8.0802
243.852	7.87529
247.464	9.59043
251.074	11.2267
254.683	11.0698
258.291	10.9509
261.897	10.9407
265.504	13.2112
269.108	15.9925
272.71	16.521
276.311	16.7866
279.91	16.2914
283.508	16.6192
287.105	16.643
290.698	16.2441
294.291	18.4095
297.884	19.8074
301.475	22.4582
305.064	24.4037
308.652	25.1295
312.237	25.9656
315.822	26.5815
319.406	29.4261
322.987	29.8828
326.568	29.4575
330.148	30.1299
333.724	29.7985
337.301	28.9519
340.875	28.3074
344.449	30.0333
348.02	30.1467
351.592	33.6432
355.16	38.6051
358.728	43.4505
362.294	48.4555
365.858	52.5617
369.422	56.4323
372.983	62.3871
376.543	68.5448
380.102	69.9827
383.661	72.6391
387.216	74.2449
390.771	73.3861
394.324	72.9032
397.875	69.0913
401.425	64.9479
404.974	59.2556
408.524	51.9619
412.07	44.764
415.614	36.5894
419.156	29.2962
422.698	20.8265
426.238	14.3082
429.777	10.5392
433.315	6.88415
436.852	5.28491
440.387	4.83621
443.919	5.57952
447.451	5.04701
450.982	6.29709
454.512	7.09774
458.038	8.67076
461.565	10.5495
465.091	11.6846
468.613	11.4294
472.136	14.6698
475.655	17.6361
479.176	20.3759
482.692	25.8125
486.21	31.744
489.724	40.3818
493.237	49.1504
496.75	56.5163
500.26	61.7552
503.771	64.8652
507.279	68.819
510.785	70.1702
514.289	69.9351
517.793	71.7376
521.297	72.0667
524.797	69.9263
528.297	67.8978
531.795	62.275
535.291	56.31
538.787	49.4137
542.281	41.6978
545.773	34.2482
549.264	25.858
552.754	18.9599
556.243	14.7643
559.73	11.565
563.216	8.49823
566.701	8.84025
570.182	10.4461
573.664	11.5287
577.145	10.6656
580.624	11.2229
584.1	14.0416
587.577	13.9792
591.052	13.1676
594.524	13.9064
597.997	14.1125
601.466	14.0908
604.936	15.711
608.403	14.0334
611.87	12.3431
615.334	11.3517
618.799	10.1381
622.26	8.25306
625.72	6.87988
629.181	4.78013
632.638	4.1362
636.095	3.68407
639.551	1.99751
643.005	3.29724
646.457	2.75435
649.908	2.55729
653.357	2.53247
656.806	1.70478
660.253	3.07823
663.7	4.67454
667.145	7.6488
670.588	8.09734
674.027	9.04303
677.468	10.2832
680.907	11.655
684.345	12.5006
687.781	11.5428
691.216	12.2203
694.65	13.503
698.081	13.6203
701.512	14.9173
704.942	16.4763
708.371	16.9792
711.796	18.5082
715.222	18.3251
718.645	19.2726
722.068	17.1208
725.49	17.8746
728.909	19.1233
732.329	22.7059
735.745	30.0912
739.16	39.7151
742.576	52.6258
745.988	66.0304
749.401	79.0073
752.811	93.6036
756.22	106.269
759.627	114.361
763.035	123.168
766.44	129.837
769.843	133.535
773.245	137.347
776.646	138.328
780.046	137.713
783.444	134.873
786.841	130.504
790.237	126.33
793.631	119.736
797.024	110.98
800.416	99.9659
803.807	89.6322
807.196	80.6788
810.584	72.7998
813.971	69.1089
817.354	66.6644
820.739	66.0154
824.122	65.5862
827.503	67.617
830.882	67.0144
834.261	69.1012
837.637	68.4499
841.013	65.9311
844.389	64.5327
847.761	62.6717
851.131	58.399
854.503	55.333
857.871	52.7365
861.24	49.3151
864.606	46.9013
867.97	44.4745
871.336	43.0131
874.698	41.4319
878.058	40.6501
881.418	39.4241
884.778	37.6698
888.135	38.3026
891.49	37.4329
894.845	38.0134
898.198	37.8792
901.55	39.9909
904.901	41.0394
908.25	42.3669
911.598	42.7602
914.945	44.2719
918.291	43.5761
921.635	40.6613
924.978	37.9256
928.318	34.8461
931.659	32.45
934.998	29.7605
938.336	27.6416
941.671	26.2798
945.007	22.9031
948.339	22.2324
951.672	21.1924
955.004	19.2166
958.333	18.0354
961.662	17.2789
964.989	17.3644
968.315	17.835
971.639	18.6434
974.962	17.7303
978.285	16.6443
981.605	16.7709
984.924	14.8734
988.243	15.8037
991.56	17.811
994.875	21.9147
998.188	27.9412
1001.5	36.3247
1004.81	45.8743
1008.12	56.3754
1011.43	67.6961
1014.74	77.8918
1018.05	86.0627
1021.35	91.7664
1024.65	96.895
1027.96	102.197
1031.26	105.31
1034.56	105.519
1037.86	101.398
1041.16	100.328
1044.45	95.5284
1047.75	90.1483
1051.04	83.3499
1054.33	77.109
1057.62	69.2767
1060.91	65.3283
1064.2	60.6221
1067.49	57.8481
1070.77	59.592
1074.06	61.7801
1077.34	63.5831
1080.62	67.5767
1083.91	68.8819
1087.18	69.6269
1090.46	72.0694
1093.74	70.4481
1097.02	69.7615
1100.29	66.6965
1103.56	65.1975
1106.84	63.3513
1110.11	61.204
1113.38	54.1516
1116.64	48.278
1119.91	41.3801
1123.18	34.8627
1126.44	28.0634
1129.7	24.3329
1132.97	21.9989
1136.23	20.0944
1139.49	19.3237
1142.74	16.2717
1146	14.0082
1149.26	10.9731
1152.51	9.56409
1155.76	7.94851
1159.01	4.88848
1162.27	3.10101
1165.51	3.33557
1168.76	5.22533
1172.01	5.18949
1175.25	7.93046
1178.5	9.55553
1181.74	10.5083
1184.98	12.2435
1188.22	14.797
1191.46	17.739
1194.7	18.21
1197.94	19.722
1201.17	19.9697
1204.41	21.6111
1207.64	23.4645
1210.87	26.4813
1214.1	28.148
1217.33	28.9667
1220.56	31.1501
1223.79	34.1109
1227.01	37.7028
1230.23	41.3753
1233.46	44.7525
1236.68	46.9115
1239.9	50.1097
1243.12	54.6494
1246.34	56.8591
1249.55	58.9448
1252.77	61.2434
1255.98	66.083
1259.2	68.2194
1262.41	70.9038
1265.62	76.5389
1268.83	79.9029
1272.03	85.5946
1275.24	87.9494
1278.45	89.8805
1281.65	92.6331
1284.85	94.8709
1288.06	98.1705
1291.26	100.58
1294.46	100.387
1297.66	100.148
1300.85	101.377
1304.05	100.999
1307.24	98.777
1310.43	99.2476
1313.63	96.3701
1316.82	94.0944
1320.01	90.757
1323.2	85.5405
1326.38	82.3213
1329.57	78.8178
1332.76	75.015
1335.94	70.5498
1339.12	66.0698
1342.3	60.5237
1345.48	56.5719
1348.66	55.7186
1351.84	52.6811
1355.01	48.7737
1358.19	44.6811
1361.36	40.9126
1364.53	37.8238
1367.71	34.5413
1370.88	31.6023
1374.04	29.507
1377.21	28.0106
1380.38	26.8062
1383.54	25.9904
1386.71	24.9864
1389.87	25.6204
1393.03	23.7727
1396.19	23.2663
1399.35	25.217
1402.51	29.5824
1405.67	33.4517
1408.82	39.1298
1411.98	45.0104
1415.13	52.4285
1418.28	61.9282
1421.43	70.9711
1424.58	81.6386
1427.73	92.3611
1430.88	100.415
1434.02	107.037
1437.17	112.534
1440.31	118.573
1443.45	123.525
1446.6	123.921
1449.74	125.204
1452.87	120.803
1456.01	114.69
1459.15	109.103
1462.28	102.255
1465.42	95.9887
1468.55	85.9745
1471.68	77.5002
1474.81	70.122
1477.94	63.237
1481.07	55.839
1484.2	49.1069
1487.32	42.5042
1490.45	37.4629
1493.57	32.5179
1496.69	27.7877
1499.81	22.9123
1502.93	20.6168
1506.05	18.5803
1509.17	15.6296
1512.28	13.6821
1515.4	12.4724
1518.51	11.4281
1521.63	10.0663
1524.74	8.58806
1527.85	9.21078
1530.96	8.98737
1534.06	11.8607
1537.17	15.2956
1540.28	18.2916
1543.38	21.0219
1546.48	21.219
1549.59	23.5194
1552.69	26.0875
1555.79	26.8483
1558.88	27.3883
1561.98	29.0301
1565.08	32.126
1568.17	35.588
1571.27	40.4748
1574.36	43.2081
1577.45	47.5964
1580.54	50.6641
1583.63	54.0093
1586.72	56.0707
1589.8	57.3452
1592.89	59.2024
1595.97	60.1426
1599.06	61.4091
1602.14	62.5035
1605.22	63.7912
1608.3	63.613
1611.38	64.7603
1614.46	66.7419
1617.53	67.9869
1620.61	68.0525
1623.68	68.778
1626.75	71.2095
1629.82	74.7749
1632.9	78.728
1635.96	83.2193
1639.03	89.2484
1642.1	95.4928
1645.16	101.165
1648.23	105.273
1651.29	108.35
1654.36	109.368
1657.42	110.848
1660.48	108.376
1663.53	105.776
1666.59	101.031
1669.65	95.6099
1672.7	89.8032
1675.76	81.1284
1678.81	72.4432
1681.86	64.4905
1684.91	56.0964
1687.96	48.0981
1691.01	39.7082
1694.06	33.3827
1697.11	27.4847
1700.15	21.3429
1703.2	18.5323
1706.24	15.6194
1709.28	11.7319
1712.32	9.21981
1715.36	8.82672
1718.4	9.43267
1721.43	8.66161
1724.47	9.1979
1727.5	8.90308
1730.54	8.85674
1733.57	8.44574
1736.6	8.02485
1739.63	7.48402
1742.66	6.26921
1745.69	5.34327
1748.72	4.58778
1751.74	3.15498
1754.77	2.37646
1757.79	2.86784
1760.81	1.06915
1763.83	1.34115
1766.85	0.300836
1769.87	0.385431
1772.89	-0.00379498
1775.91	0.490773
1778.92	0.392108
1781.94	0.101893
1784.95	1.03199
1787.96	1.53349
1790.97	2.15781
1793.98	1.33021
1796.99	3.07382
1800	2.79689
1803	2.70101
1806.01	2.03157
1809.01	3.15176
1812.02	3.00846
1815.02	3.06427
1818.02	3.33926
1821.02	3.12415
1824.02	4.15906
1827.01	4.76502
1830.01	4.62622
1833	4.33131
1836	4.68054
1838.99	4.94528
1841.98	4.18944
1844.97	5.46123
1847.96	7.15
1850.95	6.81137
1853.94	5.75406
1856.92	4.87944
1859.91	5.43823
1862.89	5.27748
1865.88	4.24124
1868.86	5.56707
1871.84	6.44533
1874.82	5.93082
1877.8	5.88821
1880.77	5.45549
1882.51	5.40088
1885.5	5.49684
1888.48	5.12403
1891.47	4.30405
1894.46	4.87186
1897.44	4.50768
1900.42	4.93206
1903.41	5.28808
1906.39	5.79299
1909.37	7.23261
1912.35	6.79564
1915.32	7.97669
1918.3	8.94042
1921.28	8.78179
1924.25	8.18361
1927.22	8.42644
1930.2	9.44633
1933.17	9.0385
1936.14	7.98432
1939.11	8.98165
1942.08	9.31343
1945.04	7.66876
1948.01	5.80127
1950.97	4.45239
1953.94	3.70565
1956.9	3.76124
1959.86	3.27186
1962.82	1.64041
1965.78	1.52949
1968.74	0.652705
1971.69	-0.303477
1974.65	0.760888
1977.61	0.973113
1980.56	1.37715
1983.51	2.47232
1986.46	3.00045
1989.41	4.37808
1992.36	5.6119
1995.31	7.17667
1998.26	8.24492
2001.2	10.4714
2004.15	10.1422
2007.09	11.1385
2010.04	11.5846
2012.98	13.0108
2015.92	12.5368
2018.86	13.0007
2021.8	12.636
2024.74	12.9847
2027.67	14.3808
2030.61	14.6051
2033.54	14.2682
2036.47	15.0893
2039.41	15.4983
2042.34	15.0702
2045.27	17.4894
2048.2	18.4971
2051.12	19.1751
2054.05	20.3912
2056.98	21.076
2059.9	23.9207
2062.82	25.949
2065.75	27.895
2068.67	28.8814
2071.59	31.3818
2074.51	33.7227
2077.43	35.299
2080.34	36.9802
2083.26	39.3638
2086.17	41.4602
2089.09	43.7804
2092	46.7258
2094.91	51.1254
2097.82	55.698
2100.73	61.8883
2103.64	67.258
2106.55	72.6494
2109.46	77.9477
2112.36	82.0773
2115.27	88.5777
2118.17	95.5076
2121.07	100.893
2123.97	106.973
2126.87	113.409
2129.77	121.301
2132.67	128.544
2135.57	135.037
2138.46	141.162
2141.36	147.127
2144.25	153.123
2147.14	159.313
2150.03	164.13
2152.92	169.917
2155.81	175.116
2158.7	178.868
2161.59	181.442
2164.48	183.899
2167.36	185.184
2170.25	185.687
2173.13	185.432
2176.01	183.168
2178.89	180.669
2181.77	176.296
2184.65	172.095
2187.53	168.141
2190.41	161.264
2193.28	155.808
2196.16	150.633
2199.03	144.486
2201.9	139.317
2204.78	132.504
2207.65	126.787
2210.51	120.702
2213.38	115.135
2216.25	109.411
2219.12	103.946
2221.98	98.0224
2224.85	92.2349
2227.71	86.4415
2230.57	80.706
2233.43	75.2188
2236.29	70.8357
2239.15	66.5787
2242.01	62.1216
2244.87	57.8529
2247.73	53.7442
2250.58	49.8481
2253.43	46.9716
2256.29	43.556
2259.14	39.986
2261.99	39.3139
2264.84	37.688
2267.69	36.35
2270.54	34.6879
2273.38	33.9657
2276.23	32.709
2279.07	31.8888
2281.92	29.7315
2284.76	28.9406
2287.6	26.7136
2290.44	25.452
2293.28	23.3598
2296.12	21.3561
2298.96	20.722
2301.79	17.8074
2304.63	16.6007
2307.46	16.2088
2310.3	14.6486
2313.13	13.0127
2315.96	9.89881
2318.79	8.61084
2321.62	7.40897
2324.45	6.17512
2327.27	6.31126
2330.1	7.48205
2332.93	8.76044
2335.75	7.66646
2338.57	7.32023
2341.4	5.62707
2344.22	7.12943
2347.04	7.72647
2349.86	6.18014
2352.67	5.63427
2355.49	6.84527
2358.31	6.67177
2361.12	7.00115
2363.94	7.74102
2366.75	7.57418
2369.56	8.09736
2372.37	8.5053
2375.18	9.60097
2377.99	8.95129
2380.8	8.23219
2383.61	7.09192
2386.41	6.42517
2389.22	7.91342
2392.02	7.87642
2394.82	8.60028
2397.63	9.10546
2400.43	8.59525
2403.23	8.94372
2406.02	7.34992
2408.82	6.45084
2411.62	6.84464
2414.41	6.72553
2417.21	6.1111
2420	4.2329
2422.79	5.00966
2425.59	4.45411
2428.38	4.40158
2431.17	4.04534
2433.96	3.92709
2436.74	4.59268
2439.53	4.51665
2442.32	3.62413
2445.1	3.51552
2447.88	3.20481
2450.67	2.83539
2453.45	1.67038
2456.23	2.38938
2459.01	2.06401
2461.79	2.75614
2464.57	2.82274
2467.34	3.34207
2470.12	3.76379
2472.89	3.58216
2475.67	4.0028
2478.44	3.79972
2481.21	4.24742
2483.98	4.81902
2486.75	4.84537
2489.52	4.98493
2492.29	3.7385
2495.06	3.76982
2497.82	3.50321
2500.59	2.88733
2503.35	2.33895
2506.11	2.14051
2508.88	1.23549
2511.63	1.17487
2514.39	0.696177
2517.15	-0.542979
2519.91	-1.37961
2522.67	-1.26485
2525.42	-1.12446
2528.18	-0.248035
2530.93	0.230559
2533.69	1.84127
2536.44	1.84233
2539.19	2.54391
2541.94	3.82685
2544.69	5.05775
2547.44	5.17971
2550.18	7.61105
2552.93	9.15339
2555.68	9.3968
2558.42	9.71733
2561.16	8.47785
2563.9	9.4766
2566.64	8.80247
2569.38	9.21861
2572.12	8.45283
2574.86	8.45458
2577.6	7.29273
2580.34	6.69938
2583.07	5.14206
2585.81	3.9349
2588.54	2.61308
2591.27	2.33979
2594	1.94431
2596.73	1.14013
2599.46	1.53174
2602.19	1.36918
2604.92	0.784612
2607.64	1.17345
2610.37	0.418128
2613.09	1.02882
2615.82	1.89838
2618.54	2.7318
2621.26	2.45383
2623.98	2.30264
2626.7	3.1842
2629.42	4.41086
2632.14	4.72058
2634.86	4.87304
2637.57	6.53227
2640.29	7.99085
2643	9.12051
2645.72	9.01147
2648.43	8.27241
2651.14	8.25244
2653.85	8.34762
2656.56	9.53127
2659.27	10.1312
2661.97	9.67698
2664.68	10.0336
2667.38	9.99312
2670.09	9.59442
2672.79	9.25398
2675.49	8.16102
2678.2	7.83316
2680.89	8.24789
2683.59	7.5853
2686.29	7.17454
2688.99	7.93511
2691.69	7.75181
2694.38	7.93908
2697.08	9.0258
2699.77	8.94124
2702.46	11.407
2705.16	12.9168
2707.85	13.3694
2710.54	12.4863
2713.23	13.3492
2715.92	14.4339
2718.6	15.0746
2721.29	15.1347
2723.97	14.698
2726.66	14.1838
2729.34	14.7668
2732.02	14.7584
2734.7	14.4523
2737.39	14.2061
2740.06	13.4588
2742.74	12.4406
2745.42	12.4075
2748.1	12.2539
2750.77	10.4266
2753.45	9.39612
2756.12	8.29746
2758.79	7.32628
2761.47	6.68929
2764.14	6.02918
2766.81	5.81486
2769.48	5.89845
2772.14	5.21977
2774.81	4.13731
2777.48	2.7879
2780.14	3.02156
2782.81	2.52785
2785.47	0.860735
2788.13	-0.249986
2790.79	-0.302344
2793.46	-0.627136
2796.11	-0.270033
2798.77	-0.567209
2801.43	-1.10575
2804.09	-1.77273
2806.74	-2.13616
2809.4	-2.79983
2812.05	-3.33644
2814.71	-1.78637
2817.36	0.749686
2820.01	5.82823
2822.66	11.9157
2825.31	19.6072
2827.96	29.1213
2830.61	40.1322
2833.25	52.2188
2835.9	64.4631
2838.54	76.1615
2841.18	88.3869
2843.83	102.513
2846.47	116.581
2849.11	129.831
2851.75	144.706
2854.39	157.953
2857.03	171.621
2859.67	183.53
2862.3	194.921
2864.94	204.422
2867.57	211.164
2870.21	217.252
2872.84	221.733
2875.47	227
2878.1	233.255
2880.73	239.458
2883.36	245.88
2885.99	252.864
2888.61	260.99
2891.24	268.256
2893.87	275.394
2896.49	284.146
2899.11	294.462
2901.74	305.674
2904.36	319.297
2906.98	334.634
2909.6	352.181
2912.22	367.583
2914.83	385.457
2917.45	401.709
2920.07	415.663
2922.68	428.16
2925.3	437.715
2927.91	442.473
2930.52	446.454
2933.13	446.282
2935.74	443.576
2938.35	436.347
2940.96	428.303
2943.57	416.497
2946.18	403.162
2948.78	388.454
2951.39	370.561
2953.99	350.664
2956.6	331.383
2959.2	313.794
2961.8	296.045
2964.4	279.233
2967	262.962
2969.6	247.018
2972.2	233.308
2974.79	218.652
2977.39	204.079
2979.98	190.899
2982.58	175.069
2985.17	160.388
2987.76	146.59
2990.36	132.574
2992.95	117.886
2995.54	105.922
2998.12	92.3389
3000.71	79.3021
3003.3	68.0816
3005.88	58.5631
3008.47	50.3969
3011.05	42.0187
3013.64	35.0225
3016.22	28.7273
3018.8	24.619
3021.38	21.7377
3023.96	18.9221
3026.54	16.2593
3029.12	15.265
3031.69	14.2164
3034.27	14.1191
3036.85	15.3672
3039.42	16.0782
3041.99	18.0217
3044.57	18.8561
3047.14	19.3264
3049.71	19.4518
3052.28	19.9035
3054.85	18.6302
3057.42	16.99
3059.98	15.8437
3062.55	14.5691
3065.11	13.9708
3067.68	12.2263
3070.24	10.8611
3072.8	8.86215
3075.37	7.33772
3077.93	5.68459
3080.49	4.18196
3083.05	2.50353
3085.61	0.281026
3088.16	-1.37428
3090.72	-3.12595
3093.27	-2.98457
3095.83	-2.21808
3098.38	-1.13569
3100.94	0.441017
3103.49	2.05965
3106.04	2.38898
3108.59	3.60142
3111.14	5.16531
3113.69	6.20008
3116.23	8.70992
3118.78	9.98452
3121.33	11.8698
3123.87	14.4843
3126.42	16.521
3128.96	18.3424
3131.5	20.3333
3134.04	22.1713
3136.58	24.9893
3139.12	26.5356
3141.66	27.1481
3144.2	28.1672
3146.74	29.1319
3149.27	29.1024