File: data/Raman/poly_smoothed/Mb_50_18_31_1x_45s_532 nm_x100_100%_600 gr_mm_01.txt
#Acq. time (s)=	45
#Accumulations=	2
#Range (cm-¹)=	200...3150
#Windows=	2
#Auto scanning=	Off
#Autofocus=	Off
#Macrospot=	Off
#AutoExposure=	Off
#Spike filter=	Multiple accum.
#Delay time (s)=	0
#Binning=	1
#Readout mode=	Signal
#DeNoise=	Off
#ICS correction=	On
#Dark correction=	Off
#Inst. Process=	Off
#Detector Gain=	Best Dynamic Range
#Detector ADC=	20 kHz
#Detector temperature (°C)=	-69.85
#Instrument=	LabRAM HR Evol
#Detector=	Synapse
#Objective=	x100
#Grating=	600 gr/mm
#ND Filter=	100%
#Laser (nm)=	532
#Hole=	100.021
#Range=	Auto
#Laser Pol.=	No
#Raman. Pol.=	No
#Laser Pol. (°)=	-0.0007625
#Raman Pol. (°)=	89.9995
#Collection=	Microscope
#StageXY=	Marzhauser
#StageZ=	Marzhauser
#X (µm)=	28336.8
#Y (µm)=	-3267.1
#Z (µm)=	1041.05
#Full time(mm:ss)=	3:18
#Project=
#Sample=
#Site=
#Title=	Mb_50_18_31_2x_45s_532 nm_x100_100%_600 gr_mm
#Remark=
#Date=	12.07.2022 13:07
#Acquired=	12.07.2022 13:07:48
#Base:Fit=	10.08.2022 10:49:18
#Base:Sub=	10.08.2022 10:49:30
#Filter:Polynom=	16.08.2022 10:14:59
#AxisType[0]=Intens
#AxisUnit[0]=Cnt
#AxisType[1]=Spectr
#AxisUnit[1]=1/cm
200.388	-8.82861
204.019	-5.51748
207.646	-5.6223
211.274	-6.12418
214.899	-6.47039
218.524	-6.72689
222.146	-6.91619
225.766	-6.977
229.388	-6.35557
233.005	-4.72021
236.621	-4.53886
240.236	-4.60889
243.852	-2.73145
247.464	-2.28594
251.074	-1.39138
254.683	-1.0264
258.291	-1.28985
261.897	-0.977896
265.504	-0.786667
269.108	-0.406854
272.71	0.264954
276.311	0.851793
279.91	1.11022
283.508	0.910461
287.105	4.22512
290.698	6.58955
294.291	9.85359
297.884	15.5881
301.475	21.9289
305.064	27.0792
308.652	32.9269
312.237	38.1531
315.822	43.7682
319.406	49.6611
322.987	53.6376
326.568	56.1355
330.148	58.6282
333.724	60.0098
337.301	58.7473
340.875	57.0262
344.449	56.3237
348.02	57.0965
351.592	59.3781
355.16	62.807
358.728	67.2669
362.294	73.8199
365.858	80.5973
369.422	87.3594
372.983	94.517
376.543	100.354
380.102	106.197
383.661	109.307
387.216	111.069
390.771	109.811
394.324	108.877
397.875	108.189
401.425	105.068
404.974	100.253
408.524	92.8467
412.07	85.3781
415.614	76.8386
419.156	67.7497
422.698	59.1738
426.238	52.1213
429.777	47.5391
433.315	44.2835
436.852	41.1303
440.387	40.4874
443.919	39.8132
447.451	42.5375
450.982	42.6763
454.512	43.4419
458.038	43.2447
461.565	41.3646
465.091	39.4242
468.613	37.3055
472.136	35.5104
475.655	34.7622
479.176	35.3844
482.692	38.4023
486.21	42.0102
489.724	47.537
493.237	54.407
496.75	61.7652
500.26	70.2936
503.771	79.3326
507.279	85.2251
510.785	90.7418
514.289	93.7825
517.793	94.3713
521.297	93.0987
524.797	91.629
528.297	89.0141
531.795	84.9422
535.291	79.7513
538.787	73.5239
542.281	67.485
545.773	60.1829
549.264	50.9461
552.754	40.6255
556.243	33.5922
559.73	27.2152
563.216	22.5186
566.701	20.1085
570.182	19.4929
573.664	21.1424
577.145	23.965
580.624	26.2035
584.1	27.7628
587.577	29.9687
591.052	31.1671
594.524	29.4676
597.997	30.1735
601.466	28.5701
604.936	28.101
608.403	26.4586
611.87	24.5559
615.334	21.936
618.799	18.2418
622.26	16.5476
625.72	13.4671
629.181	12.1543
632.638	8.64299
636.095	4.89114
639.551	2.57379
643.005	1.91848
646.457	1.24178
649.908	1.18716
653.357	0.121299
656.806	1.93997
660.253	1.91921
663.7	0.426651
667.145	1.76919
670.588	2.90522
674.027	4.91241
677.468	5.93078
680.907	6.41433
684.345	9.7422
687.781	10.2418
691.216	10.9349
694.65	12.7055
698.081	13.6635
701.512	13.0437
704.942	13.5046
708.371	13.6549
711.796	15.1068
715.222	15.1694
718.645	14.3734
722.068	13.5109
725.49	10.625
728.909	10.5753
732.329	11.8536
735.745	13.2342
739.16	19.3227
742.576	31.3423
745.988	47.6832
749.401	67.0406
752.811	87.9807
756.22	106.532
759.627	123.538
763.035	138.585
766.44	151.096
769.843	160.67
773.245	166.412
776.646	169.76
780.046	168.877
783.444	166.01
786.841	161.555
790.237	153.875
793.631	144.372
797.024	131.858
800.416	116.376
803.807	99.5471
807.196	81.3283
810.584	65.3252
813.971	54.0137
817.354	45.0427
820.739	40.8306
824.122	42.7949
827.503	45.1618
830.882	47.169
834.261	48.249
837.637	48.2716
841.013	47.0475
844.389	45.264
847.761	43.0761
851.131	40.0261
854.503	35.6896
857.871	33.771
861.24	33.3434
864.606	33.2449
867.97	35.4973
871.336	37.9829
874.698	38.9543
878.058	40.1947
881.418	41.7682
884.778	42.2966
888.135	43.331
891.49	44.3022
894.845	46.6625
898.198	47.9131
901.55	48.7097
904.901	49.584
908.25	49.841
911.598	49.4927
914.945	47.6601
918.291	47.0085
921.635	44.2211
924.978	40.5178
928.318	37.0134
931.659	32.8579
934.998	29.9815
938.336	28.12
941.671	25.9491
945.007	25.0203
948.339	24.1805
951.672	24.2037
955.004	22.7933
958.333	20.3986
961.662	18.4611
964.989	15.4094
968.315	13.8763
971.639	12.0505
974.962	10.2391
978.285	9.49435
981.605	6.0539
984.924	3.2613
988.243	0.844161
991.56	1.20201
994.875	3.08232
998.188	6.82193
1001.5	12.7355
1004.81	20.4607
1008.12	30.8912
1011.43	43.0864
1014.74	56.6184
1018.05	67.622
1021.35	80.6124
1024.65	91.4785
1027.96	104.125
1031.26	113.003
1034.56	118.29
1037.86	121.273
1041.16	121.36
1044.45	120.256
1047.75	119.126
1051.04	118.104
1054.33	118.499
1057.62	121.865
1060.91	128.779
1064.2	135.889
1067.49	146.61
1070.77	155.62
1074.06	165.085
1077.34	174.415
1080.62	182.63
1083.91	189.205
1087.18	194.243
1090.46	199.591
1093.74	202.907
1097.02	203.141
1100.29	198.8
1103.56	191.548
1106.84	181.523
1110.11	166.244
1113.38	148.189
1116.64	129.286
1119.91	110.123
1123.18	92.597
1126.44	76.4727
1129.7	64.0658
1132.97	56.769
1136.23	51.5252
1139.49	49.7334
1142.74	47.8283
1146	46.0554
1149.26	42.6482
1152.51	39.2029
1155.76	36.9871
1159.01	35.5012
1162.27	33.4282
1165.51	31.8259
1168.76	32.4836
1172.01	33.2912
1175.25	31.6307
1178.5	30.2834
1181.74	28.976
1184.98	28.1024
1188.22	25.9882
1191.46	24.1307
1194.7	23.0018
1197.94	22.6016
1201.17	21.8592
1204.41	22.3354
1207.64	22.1325
1210.87	20.9479
1214.1	20.4294
1217.33	19.5663
1220.56	21.496
1223.79	23.7356
1227.01	25.0184
1230.23	26.2774
1233.46	27.5246
1236.68	28.3502
1239.9	29.2386
1243.12	29.327
1246.34	30.2586
1249.55	28.6554
1252.77	27.0869
1255.98	26.4601
1259.2	26.973
1262.41	27.1497
1265.62	27.3783
1268.83	26.4769
1272.03	27.5685
1275.24	27.4161
1278.45	30.5846
1281.65	32.5173
1284.85	32.5273
1288.06	33.05
1291.26	32.8422
1294.46	32.9418
1297.66	33.5891
1300.85	35.1028
1304.05	36.1722
1307.24	34.0692
1310.43	36.0956
1313.63	40.3127
1316.82	42.3484
1320.01	43.9598
1323.2	45.4054
1326.38	46.5366
1329.57	46.9422
1332.76	48.1315
1335.94	51.1799
1339.12	52.3878
1342.3	54.2704
1345.48	57.9649
1348.66	60.3988
1351.84	62.0859
1355.01	65.6792
1358.19	68.405
1361.36	68.665
1364.53	68.995
1367.71	68.8887
1370.88	66.9068
1374.04	64.9439
1377.21	65.0406
1380.38	64.8609
1383.54	63.2501
1386.71	63.0051
1389.87	65.8237
1393.03	64
1396.19	61.8856
1399.35	61.3573
1402.51	62.4186
1405.67	63.1929
1408.82	65.343
1411.98	67.2299
1415.13	68.91
1418.28	70.8411
1421.43	73.4838
1424.58	74.3627
1427.73	77.4323
1430.88	81.1255
1434.02	83.2957
1437.17	83.7925
1440.31	84.7902
1443.45	86.013
1446.6	83.3553
1449.74	82.0386
1452.87	79.8941
1456.01	76.0687
1459.15	70.7307
1462.28	64.9073
1465.42	58.7089
1468.55	52.7408
1471.68	46.7587
1474.81	42.184
1477.94	37.9137
1481.07	32.3932
1484.2	26.7717
1487.32	21.7261
1490.45	16.6919
1493.57	11.9074
1496.69	8.97734
1499.81	7.02662
1502.93	5.22382
1506.05	4.73516
1509.17	4.68497
1512.28	4.88956
1515.4	4.41485
1518.51	4.1651
1521.63	4.0817
1524.74	5.1507
1527.85	4.57952
1530.96	3.2893
1534.06	1.75165
1537.17	3.24729
1540.28	4.11506
1543.38	4.88631
1546.48	5.98482
1549.59	6.31997
1552.69	6.38578
1555.79	6.87071
1558.88	7.17424
1561.98	8.53161
1565.08	10.0484
1568.17	11.351
1571.27	13.2415
1574.36	14.6661
1577.45	16.4793
1580.54	17.3331
1583.63	17.8674
1586.72	18.8311
1589.8	18.8506
1592.89	18.5858
1595.97	19.5117
1599.06	20.3558
1602.14	19.4235
1605.22	20.1925
1608.3	19.5568
1611.38	19.9131
1614.46	20.2439
1617.53	18.7126
1620.61	18.2449
1623.68	18.0555
1626.75	17.092
1629.82	15.9023
1632.9	15.1069
1635.96	14.1644
1639.03	14.3118
1642.1	14.1384
1645.16	13.6875
1648.23	13.242
1651.29	12.9273
1654.36	11.9247
1657.42	10.7892
1660.48	12.0589
1663.53	12.4502
1666.59	11.1597
1669.65	12.3931
1672.7	12.7521
1675.76	13.6976
1678.81	13.4239
1681.86	12.513
1684.91	11.5476
1687.96	11.1315
1691.01	10.7021
1694.06	9.03431
1697.11	9.32581
1700.15	8.43929
1703.2	7.65911
1706.24	7.11326
1709.28	6.90681
1712.32	6.88757
1715.36	7.15548
1718.4	5.70946
1721.43	5.14771
1724.47	5.83455
1727.5	5.21114
1730.54	5.1151
1733.57	6.16473
1736.6	6.56802
1739.63	5.78399
1742.66	4.33129
1745.69	4.47677
1748.72	4.1397
1751.74	3.17975
1754.77	3.0171
1757.79	2.51926
1760.81	3.04076
1763.83	3.30976
1766.85	2.22405
1769.87	2.11432
1772.89	3.4282
1775.91	2.87197
1778.92	2.90899
1781.94	3.02882
1784.95	3.39961
1787.96	3.44337
1790.97	3.10286
1793.98	3.31965
1796.99	4.50366
1800	5.00814
1803	4.89608
1806.01	6.17276
1809.01	5.9873
1812.02	5.67613
1815.02	5.52042
1818.02	5.85431
1821.02	6.61505
1824.02	7.81135
1827.01	8.47557
1830.01	8.41784
1833	8.36148
1836	8.61438
1838.99	9.21672
1841.98	8.97847
1844.97	8.89468
1847.96	8.93042
1850.95	7.8332
1853.94	6.27772
1856.92	4.3763
1859.91	2.8181
1862.89	2.49851
1865.88	1.77304
1868.86	2.02061
1871.84	2.47059
1874.82	2.2221
1877.8	1.96595
1880.77	1.57404
1882.51	1.95413
1885.5	1.9489
1888.48	2.1213
1891.47	3.41545
1894.46	4.53092
1897.44	5.60502
1900.42	6.04343
1903.41	6.62812
1906.39	6.16256
1909.37	6.66375
1912.35	7.05305
1915.32	6.92465
1918.3	6.85826
1921.28	6.89394
1924.25	4.60221
1927.22	4.00482
1930.2	5.21803
1933.17	4.5341
1936.14	5.3455
1939.11	4.96125
1942.08	4.92627
1945.04	3.65153
1948.01	3.12179
1950.97	2.81082
1953.94	2.81744
1956.9	3.44775
1959.86	2.62857
1962.82	2.73402
1965.78	3.22892
1968.74	3.42126
1971.69	3.25505
1974.65	3.73618
1977.61	3.24743
1980.56	3.01295
1983.51	3.1003
1986.46	4.63421
1989.41	4.06785
1992.36	4.27766
1995.31	4.15608
1998.26	4.27271
2001.2	4.96242
2004.15	4.10424
2007.09	3.17064
2010.04	3.51813
2012.98	3.73478
2015.92	3.95516
2018.86	5.10231
2021.8	6.22803
2024.74	5.30766
2027.67	5.20444
2030.61	4.17279
2033.54	4.65431
2036.47	4.76319
2039.41	4.78913
2042.34	5.66879
2045.27	5.38937
2048.2	6.10455
2051.12	5.06397
2054.05	5.69958
2056.98	6.00921
2059.9	6.84795
2062.82	7.22097
2065.75	8.02815
2068.67	8.09268
2071.59	7.77781
2074.51	7.83584
2077.43	8.58755
2080.34	7.92757
2083.26	8.37935
2086.17	8.57956
2089.09	8.39443
2092	7.76993
2094.91	6.65981
2097.82	5.41338
2100.73	4.70115
2103.64	4.96575
2106.55	5.11188
2109.46	3.26684
2112.36	3.67115
2115.27	3.64413
2118.17	3.80301
2121.07	4.0147
2123.97	5.23162
2126.87	5.97712
2129.77	7.10523
2132.67	7.99936
2135.57	9.28381
2138.46	9.29352
2141.36	9.13487
2144.25	9.86508
2147.14	10.2352
2150.03	9.06766
2152.92	9.96409
2155.81	9.80072
2158.7	9.55764
2161.59	10.0138
2164.48	9.01127
2167.36	7.79512
2170.25	7.56296
2173.13	7.20668
2176.01	6.28683
2178.89	4.4833
2181.77	3.81561
2184.65	3.5268
2187.53	3.59935
2190.41	3.12623
2193.28	4.82793
2196.16	4.89108
2199.03	4.76138
2201.9	5.60023
2204.78	5.59365
2207.65	4.56282
2210.51	5.76276
2213.38	6.1463
2216.25	6.58436
2219.12	6.56906
2221.98	6.67044
2224.85	7.26058
2227.71	7.60458
2230.57	6.98714
2233.43	6.17676
2236.29	6.00554
2239.15	5.5846
2242.01	5.88608
2244.87	5.09702
2247.73	5.18196
2250.58	4.58878
2253.43	4.35759
2256.29	4.65707
2259.14	4.74522
2261.99	4.93696
2264.84	5.1069
2267.69	4.90524
2270.54	4.79937
2273.38	4.23986
2276.23	4.94776
2279.07	5.52951
2281.92	5.87128
2284.76	6.03448
2287.6	6.20046
2290.44	5.95013
2293.28	4.16931
2296.12	5.086
2298.96	5.75841
2301.79	6.79596
2304.63	8.3282
2307.46	9.35177
2310.3	8.9068
2313.13	8.4221
2315.96	8.14217
2318.79	7.92275
2321.62	7.89496
2324.45	7.42781
2327.27	5.31134
2330.1	4.95429
2332.93	4.15804
2335.75	3.16146
2338.57	2.2459
2341.4	2.23368
2344.22	1.43582
2347.04	1.0473
2349.86	0.140446
2352.67	0.0988105
2355.49	0.295362
2358.31	0.811803
2361.12	0.863842
2363.94	1.59565
2366.75	2.97794
2369.56	3.38763
2372.37	3.49191
2375.18	3.4062
2377.99	2.69168
2380.8	2.41731
2383.61	3.20746
2386.41	3.30424
2389.22	3.42045
2392.02	3.59477
2394.82	3.76239
2397.63	4.34451
2400.43	4.08944
2403.23	3.80451
2406.02	4.00942
2408.82	4.76892
2411.62	4.95658
2414.41	4.14313
2417.21	4.67059
2420	4.8062
2422.79	5.22806
2425.59	5.79593
2428.38	6.36581
2431.17	6.11965
2433.96	6.34575
2436.74	5.81913
2439.53	6.23603
2442.32	7.25907
2445.1	7.53935
2447.88	8.17267
2450.67	8.40654
2453.45	7.75352
2456.23	7.53236
2459.01	7.79408
2461.79	7.90085
2464.57	7.68512
2467.34	6.66338
2470.12	6.56532
2472.89	6.63759
2475.67	5.34164
2478.44	4.86438
2481.21	4.53664
2483.98	4.43564
2486.75	3.58769
2489.52	2.63328
2492.29	2.45289
2495.06	2.72363
2497.82	2.71578
2500.59	2.29025
2503.35	2.29813
2506.11	2.73456
2508.88	3.23185
2511.63	3.42008
2514.39	2.40075
2517.15	2.35792
2519.91	2.44725
2522.67	2.60004
2525.42	2.97263
2528.18	2.52468
2530.93	1.81931
2533.69	1.80586
2536.44	1.23149
2539.19	1.33187
2541.94	2.01612
2544.69	1.97871
2547.44	3.1225
2550.18	3.90302
2552.93	4.20077
2555.68	4.21189
2558.42	4.65813
2561.16	4.55218
2563.9	3.82186
2566.64	4.18403
2569.38	3.80774
2572.12	4.38518
2574.86	3.13634
2577.6	3.25678
2580.34	3.3338
2583.07	3.49375
2585.81	2.77306
2588.54	2.60829
2591.27	2.28461
2594	1.538
2596.73	1.35083
2599.46	0.12977
2602.19	0.236292
2604.92	-0.0188722
2607.64	0.0954444
2610.37	0.761876
2613.09	1.44837
2615.82	2.20886
2618.54	1.88567
2621.26	1.83831
2623.98	1.83809
2626.7	2.40879
2629.42	3.34308
2632.14	3.36634
2634.86	3.62627
2637.57	4.43809
2640.29	4.73627
2643	5.4597
2645.72	5.92629
2648.43	6.32426
2651.14	6.64211
2653.85	6.62486
2656.56	7.19699
2659.27	7.46097
2661.97	7.66536
2664.68	7.70317
2667.38	7.70784
2670.09	7.75915
2672.79	7.08914
2675.49	7.46464
2678.2	8.26405
2680.89	7.61464
2683.59	7.73279
2686.29	7.78975
2688.99	8.42327
2691.69	9.34643
2694.38	9.71004
2697.08	9.26868
2699.77	9.27891
2702.46	10.097
2705.16	10.5491
2707.85	11.6004
2710.54	11.6669
2713.23	12.3917
2715.92	12.8024
2718.6	12.9298
2721.29	12.3
2723.97	10.8428
2726.66	9.63713
2729.34	8.64042
2732.02	7.43443
2734.7	6.73622
2737.39	6.16429
2740.06	6.38864
2742.74	6.02207
2745.42	6.22525
2748.1	4.40847
2750.77	4.57218
2753.45	4.27972
2756.12	3.85347
2758.79	4.25689
2761.47	5.23583
2764.14	5.21545
2766.81	5.3287
2769.48	6.26615
2772.14	6.28987
2774.81	6.63383
2777.48	6.76268
2780.14	7.12883
2782.81	6.95118
2785.47	6.25696
2788.13	5.06561
2790.79	4.59031
2793.46	3.96787
2796.11	4.44626
2798.77	4.35371
2801.43	5.38109
2804.09	5.30213
2806.74	4.63358
2809.4	5.05056
2812.05	5.47185
2814.71	5.3993
2817.36	8.82642
2820.01	13.6951
2822.66	19.5802
2825.31	26.004
2827.96	32.6839
2830.61	39.1891
2833.25	46.2838
2835.9	53.4553
2838.54	60.2267
2841.18	67.1586
2843.83	72.8018
2846.47	77.9187
2849.11	84.1719
2851.75	91.0271
2854.39	98.1626
2857.03	106.091
2859.67	113.448
2862.3	121.958
2864.94	128.521
2867.57	135.103
2870.21	140.933
2872.84	148.545
2875.47	155.208
2878.1	162.5
2880.73	170.101
2883.36	177.357
2885.99	183.192
2888.61	187.403
2891.24	190.718
2893.87	192.321
2896.49	191.593
2899.11	191.048
2901.74	189.006
2904.36	186.531
2906.98	184.921
2909.6	182.628
2912.22	183.339
2914.83	184.692
2917.45	186.575
2920.07	189.239
2922.68	191.689
2925.3	193.472
2927.91	195.268
2930.52	196.263
2933.13	196.791
2935.74	197.207
2938.35	196.851
2940.96	195.056
2943.57	193.142
2946.18	188.232
2948.78	183.044
2951.39	176.357
2953.99	168.652
2956.6	160.753
2959.2	151.846
2961.8	143.202
2964.4	135.278
2967	127.973
2969.6	121.007
2972.2	116.459
2974.79	109.103
2977.39	104.883
2979.98	99.8033
2982.58	94.9792
2985.17	90.0638
2987.76	84.3885
2990.36	78.4169
2992.95	72.7027
2995.54	67.1691
2998.12	61.8547
3000.71	57.1106
3003.3	51.6193
3005.88	45.4242
3008.47	40.1366
3011.05	34.6306
3013.64	30.5019
3016.22	26.2744
3018.8	22.3031
3021.38	18.2486
3023.96	14.7409
3026.54	12.2091
3029.12	11.2006
3031.69	9.51101
3034.27	8.05362
3036.85	6.5333
3039.42	5.13179
3041.99	3.94911
3044.57	3.81236
3047.14	4.0231
3049.71	3.2685
3052.28	2.05491
3054.85	1.04061
3057.42	0.854694
3059.98	0.997109
3062.55	0.608384
3065.11	0.690806
3067.68	0.508809
3070.24	0.890862
3072.8	1.90345
3075.37	2.86204
3077.93	3.3851
3080.49	4.46463
3083.05	4.41216
3085.61	5.8018
3088.16	7.54884
3090.72	8.88384
3093.27	10.4691
3095.83	11.5365
3098.38	12.9133
3100.94	14.0547
3103.49	15.5294
3106.04	18.0935
3108.59	20.2608
3111.14	22.7197
3113.69	24.6347
3116.23	26.4061
3118.78	28.5918
3121.33	31.2479
3123.87	33.7233
3126.42	35.9381
3128.96	38.8709
3131.5	40.3213
3134.04	43.2006
3136.58	46.0169
3139.12	48.2063
3141.66	51.8159
3144.2	54.678
3146.74	57.3583
3149.27	58.2792