File: data/Raman/poly_smoothed/Mb_50_18_02_1x_45s_532 nm_x100_100%_600 gr_mm_01.txt
#Acq. time (s)=	45
#Accumulations=	2
#Range (cm-¹)=	200...3150
#Windows=	2
#Auto scanning=	Off
#Autofocus=	Off
#Macrospot=	Off
#AutoExposure=	Off
#Spike filter=	Multiple accum.
#Delay time (s)=	0
#Binning=	1
#Readout mode=	Signal
#DeNoise=	Off
#ICS correction=	On
#Dark correction=	Off
#Inst. Process=	Off
#Detector Gain=	Best Dynamic Range
#Detector ADC=	20 kHz
#Detector temperature (°C)=	-69.85
#Instrument=	LabRAM HR Evol
#Detector=	Synapse
#Objective=	x100
#Grating=	600 gr/mm
#ND Filter=	100%
#Laser (nm)=	532
#Hole=	100.021
#Range=	Auto
#Laser Pol.=	No
#Raman. Pol.=	No
#Laser Pol. (°)=	-0.0007625
#Raman Pol. (°)=	89.9995
#Collection=	Microscope
#StageXY=	Marzhauser
#StageZ=	Marzhauser
#X (µm)=	19377
#Y (µm)=	3018.9
#Z (µm)=	1048.35
#Full time(mm:ss)=	3:19
#Project=
#Sample=
#Site=
#Title=	Mb_50_18_02_2x_45s_532 nm_x100_100%_600 gr_mm
#Remark=
#Date=	12.07.2022 10:22
#Acquired=	12.07.2022 10:22:06
#Base:Fit=	10.08.2022 10:49:18
#Base:Sub=	10.08.2022 10:49:30
#Filter:Polynom=	16.08.2022 10:14:59
#AxisType[0]=Intens
#AxisUnit[0]=Cnt
#AxisType[1]=Spectr
#AxisUnit[1]=1/cm
200.388	16.873
204.019	14.0428
207.646	12.1306
211.274	10.2553
214.899	8.20351
218.524	5.22435
222.146	3.99711
225.766	3.16835
229.388	3.80335
233.005	4.45518
236.621	6.15743
240.236	6.9602
243.852	6.57461
247.464	7.69032
251.074	7.81618
254.683	7.20693
258.291	7.55242
261.897	7.42987
265.504	7.29089
269.108	7.03927
272.71	6.92409
276.311	8.59551
279.91	10.6051
283.508	12.4069
287.105	13.8835
290.698	15.1462
294.291	17.422
297.884	19.4356
301.475	21.3781
305.064	23.7171
308.652	24.9678
312.237	25.8308
315.822	28.3688
319.406	29.8349
322.987	30.2032
326.568	29.9695
330.148	28.7228
333.724	28.0194
337.301	27.539
340.875	25.0708
344.449	24.8995
348.02	24.2442
351.592	26.4015
355.16	28.9004
358.728	32.1742
362.294	35.3424
365.858	37.8351
369.422	44.1387
372.983	48.3631
376.543	51.0765
380.102	53.2164
383.661	55.3454
387.216	56.9676
390.771	58.0345
394.324	56.8939
397.875	55.6681
401.425	52.5741
404.974	50.0531
408.524	46.7306
412.07	43.5845
415.614	39.6552
419.156	34.6612
422.698	31.1955
426.238	26.5172
429.777	22.5027
433.315	19.3861
436.852	17.947
440.387	15.0716
443.919	14.5441
447.451	15.0063
450.982	15.2958
454.512	15.7599
458.038	15.5093
461.565	15.2664
465.091	16.0512
468.613	17.5595
472.136	19.4111
475.655	20.1658
479.176	23.0821
482.692	26.1459
486.21	29.9611
489.724	32.2046
493.237	35.0612
496.75	37.6121
500.26	40.0877
503.771	40.4863
507.279	41.6403
510.785	43.4359
514.289	42.3936
517.793	42.5546
521.297	41.6009
524.797	38.5906
528.297	35.3134
531.795	33.7228
535.291	31.0111
538.787	27.4476
542.281	22.8622
545.773	18.8928
549.264	15.9744
552.754	12.8441
556.243	8.12113
559.73	6.90349
563.216	7.08731
566.701	8.08223
570.182	7.43966
573.664	7.3898
577.145	8.11838
580.624	7.62757
584.1	8.59204
587.577	8.67572
591.052	10.4001
594.524	10.1507
597.997	10.1856
601.466	9.8865
604.936	9.67086
608.403	8.50788
611.87	7.73697
615.334	7.05791
618.799	5.30986
622.26	4.54512
625.72	3.51658
629.181	2.12932
632.638	2.12634
636.095	2.16031
639.551	2.03329
643.005	2.6548
646.457	5.11177
649.908	6.19091
653.357	6.73162
656.806	7.27804
660.253	7.72461
663.7	8.26832
667.145	8.18741
670.588	9.76823
674.027	10.2544
677.468	11.6662
680.907	11.8973
684.345	12.9819
687.781	13.5948
691.216	13.6282
694.65	13.8085
698.081	12.401
701.512	12.5044
704.942	15.0765
708.371	15.7928
711.796	16.9146
715.222	17.6534
718.645	20.4156
722.068	21.4519
725.49	21.6591
728.909	23.9012
732.329	25.8925
735.745	29.6227
739.16	35.4734
742.576	40.4849
745.988	48.7563
749.401	56.2442
752.811	64.2204
756.22	71.6791
759.627	79.3127
763.035	83.1281
766.44	88.4869
769.843	91.0036
773.245	93.2086
776.646	95.0575
780.046	95.8644
783.444	96.7201
786.841	97.8683
790.237	95.2741
793.631	90.8997
797.024	86.9623
800.416	83.5432
803.807	79.0034
807.196	73.0861
810.584	69.5417
813.971	66.1563
817.354	62.8042
820.739	63.7317
824.122	62.7712
827.503	62.089
830.882	61.2137
834.261	59.3209
837.637	56.8867
841.013	54.7702
844.389	52.0907
847.761	48.0966
851.131	46.0176
854.503	43.9666
857.871	41.3539
861.24	38.9383
864.606	36.5831
867.97	33.9987
871.336	30.7007
874.698	27.293
878.058	26.4832
881.418	26.7757
884.778	25.9867
888.135	24.7859
891.49	24.9577
894.845	24.8234
898.198	24.5744
901.55	26.4355
904.901	28.7658
908.25	28.2195
911.598	28.1198
914.945	27.6354
918.291	27.746
921.635	28.9535
924.978	29.518
928.318	29.8334
931.659	28.0672
934.998	29.1061
938.336	28.9229
941.671	26.601
945.007	24.1908
948.339	23.2205
951.672	21.2257
955.004	19.5966
958.333	18.5095
961.662	18.2312
964.989	18.2769
968.315	16.8873
971.639	16.6948
974.962	16.8568
978.285	16.2702
981.605	16.3579
984.924	16.2177
988.243	16.8307
991.56	18.0243
994.875	19.0257
998.188	21.8168
1001.5	25.972
1004.81	30.9352
1008.12	34.4525
1011.43	38.4186
1014.74	42.4272
1018.05	47.4731
1021.35	48.4451
1024.65	49.5961
1027.96	49.9921
1031.26	49.6271
1034.56	47.9418
1037.86	46.5478
1041.16	43.8635
1044.45	41.5934
1047.75	38.4937
1051.04	36.7871
1054.33	35.6575
1057.62	34.5291
1060.91	33.0802
1064.2	32.9309
1067.49	32.57
1070.77	32.5271
1074.06	32.8311
1077.34	33.4256
1080.62	33.1624
1083.91	34.8685
1087.18	34.7684
1090.46	35.746
1093.74	36.1428
1097.02	35.928
1100.29	33.7126
1103.56	31.7022
1106.84	29.7385
1110.11	27.0447
1113.38	23.5146
1116.64	19.431
1119.91	15.7057
1123.18	13.5935
1126.44	12.9789
1129.7	12.7386
1132.97	13.5277
1136.23	13.0677
1139.49	14.1974
1142.74	13.4558
1146	12.2818
1149.26	10.0497
1152.51	8.72898
1155.76	7.76314
1159.01	5.78874
1162.27	4.69519
1165.51	5.17241
1168.76	4.15375
1172.01	4.52123
1175.25	3.7687
1178.5	3.39229
1181.74	3.65313
1184.98	3.28631
1188.22	3.09082
1191.46	2.23485
1194.7	1.42772
1197.94	3.46749
1201.17	6.93771
1204.41	9.81773
1207.64	12.0637
1210.87	13.0994
1214.1	16.2035
1217.33	17.9702
1220.56	19.7928
1223.79	20.8716
1227.01	22.6839
1230.23	24.9893
1233.46	28.3291
1236.68	29.0355
1239.9	31.1372
1243.12	32.4716
1246.34	33.4355
1249.55	33.1065
1252.77	32.4539
1255.98	33.8996
1259.2	33.4302
1262.41	34.1197
1265.62	35.1141
1268.83	36.0614
1272.03	38.0553
1275.24	39.1508
1278.45	40.0987
1281.65	41.6248
1284.85	40.9707
1288.06	41.0799
1291.26	41.4658
1294.46	41.3675
1297.66	42.3092
1300.85	43.4601
1304.05	45.4387
1307.24	46.6642
1310.43	46.4894
1313.63	46.1118
1316.82	45.9157
1320.01	45.9373
1323.2	45.4729
1326.38	45.5751
1329.57	44.2768
1332.76	43.6945
1335.94	42.4609
1339.12	43.0388
1342.3	42.4573
1345.48	41.5614
1348.66	39.5767
1351.84	38.3455
1355.01	36.2524
1358.19	35.8147
1361.36	34.6361
1364.53	32.8269
1367.71	31.2698
1370.88	28.8008
1374.04	27.9241
1377.21	26.582
1380.38	26.8452
1383.54	25.4583
1386.71	24.0981
1389.87	23.0909
1393.03	22.5454
1396.19	21.9631
1399.35	21.4815
1402.51	21.6252
1405.67	22.9992
1408.82	24.6756
1411.98	27.545
1415.13	30.26
1418.28	32.7731
1421.43	35.5921
1424.58	39.7342
1427.73	44.7842
1430.88	49.072
1434.02	53.0958
1437.17	56.1594
1440.31	57.2624
1443.45	58.1321
1446.6	59.5588
1449.74	60.1095
1452.87	59.1632
1456.01	60.348
1459.15	60.711
1462.28	60.3642
1465.42	59.7008
1468.55	58.9584
1471.68	57.8312
1474.81	55.5363
1477.94	55.2746
1481.07	53.8003
1484.2	53.8144
1487.32	51.4482
1490.45	48.9399
1493.57	45.8213
1496.69	43.2698
1499.81	39.8228
1502.93	36.5896
1506.05	33.0876
1509.17	29.3286
1512.28	26.1649
1515.4	22.6232
1518.51	19.5599
1521.63	17.6084
1524.74	15.9991
1527.85	13.6251
1530.96	11.9997
1534.06	12.6073
1537.17	13.6445
1540.28	14.9549
1543.38	16.7123
1546.48	18.0449
1549.59	20.3106
1552.69	22.4724
1555.79	23.877
1558.88	25.1493
1561.98	26.1258
1565.08	26.79
1568.17	28.5012
1571.27	31.391
1574.36	32.1421
1577.45	32.6837
1580.54	34.9924
1583.63	37.5219
1586.72	39.5001
1589.8	40.224
1592.89	40.8731
1595.97	40.333
1599.06	39.2755
1602.14	37.3499
1605.22	35.305
1608.3	35.4291
1611.38	36.5713
1614.46	36.609
1617.53	35.8775
1620.61	35.8423
1623.68	35
1626.75	34.0728
1629.82	34.7756
1632.9	34.9353
1635.96	34.6894
1639.03	35.9762
1642.1	37.3874
1645.16	38.4753
1648.23	39.5072
1651.29	39.7164
1654.36	40.3545
1657.42	41.1032
1660.48	39.8325
1663.53	39.1322
1666.59	38.3745
1669.65	36.8352
1672.7	34.0828
1675.76	32.3563
1678.81	29.4476
1681.86	28.3244
1684.91	26.5191
1687.96	24.1561
1691.01	21.9467
1694.06	19.3828
1697.11	16.9518
1700.15	15.3771
1703.2	13.5959
1706.24	10.7778
1709.28	8.30693
1712.32	6.32692
1715.36	5.80439
1718.4	3.9936
1721.43	2.59763
1724.47	2.55098
1727.5	1.09521
1730.54	1.80423
1733.57	1.30734
1736.6	1.93319
1739.63	1.83568
1742.66	2.06138
1745.69	2.89703
1748.72	2.45624
1751.74	2.11673
1754.77	2.13028
1757.79	2.51852
1760.81	2.97969
1763.83	3.14946
1766.85	3.10559
1769.87	1.4439
1772.89	1.2399
1775.91	1.53614
1778.92	0.130326
1781.94	0.544208
1784.95	1.3475
1787.96	1.67
1790.97	1.35226
1793.98	1.56589
1796.99	1.61446
1800	2.31928
1803	2.03647
1806.01	2.18872
1809.01	2.57882
1812.02	2.17829
1815.02	2.36947
1818.02	2.58794
1821.02	2.04929
1824.02	1.72092
1827.01	1.36964
1830.01	2.58833
1833	3.37865
1836	2.66306
1838.99	2.55019
1841.98	2.8208
1844.97	3.06772
1847.96	3.24122
1850.95	3.71134
1853.94	2.75191
1856.92	2.767
1859.91	2.75313
1862.89	2.75107
1865.88	3.4543
1868.86	2.94516
1871.84	2.31289
1874.82	2.93176
1877.8	3.7957
1880.77	3.75878
1882.51	5.33423
1885.5	4.58407
1888.48	4.67721
1891.47	3.91839
1894.46	4.27401
1897.44	4.17914
1900.42	4.5756
1903.41	5.65362
1906.39	5.52705
1909.37	4.84506
1912.35	5.48591
1915.32	5.29678
1918.3	4.83607
1921.28	5.0597
1924.25	3.53841
1927.22	2.76378
1930.2	4.06518
1933.17	4.27497
1936.14	4.42425
1939.11	3.75721
1942.08	4.06608
1945.04	4.71003
1948.01	5.18734
1950.97	4.7183
1953.94	4.46132
1956.9	4.67803
1959.86	3.81749
1962.82	3.71315
1965.78	3.47724
1968.74	3.40988
1971.69	3.15082
1974.65	4.64902
1977.61	5.92003
1980.56	5.93831
1983.51	6.48782
1986.46	7.266
1989.41	8.29062
1992.36	9.11347
1995.31	9.96604
1998.26	10.5794
2001.2	13.1418
2004.15	13.5628
2007.09	14.3489
2010.04	14.0399
2012.98	14.1059
2015.92	13.6949
2018.86	12.8142
2021.8	11.994
2024.74	12.2856
2027.67	11.4938
2030.61	11.8992
2033.54	11.4583
2036.47	12.0312
2039.41	11.8259
2042.34	11.6854
2045.27	12.5078
2048.2	13.7928
2051.12	14.1781
2054.05	14.6829
2056.98	15.5647
2059.9	16.0568
2062.82	17.2421
2065.75	18.9755
2068.67	20.4045
2071.59	22.1418
2074.51	23.3254
2077.43	24.2105
2080.34	25.207
2083.26	25.1693
2086.17	26.0042
2089.09	27.0152
2092	29.1239
2094.91	30.6273
2097.82	33.4328
2100.73	34.3559
2103.64	36.6346
2106.55	37.7453
2109.46	39.8916
2112.36	40.8459
2115.27	42.7531
2118.17	45.2157
2121.07	48.0049
2123.97	49.2341
2126.87	51.7044
2129.77	53.6467
2132.67	56.2632
2135.57	59.1171
2138.46	62.9016
2141.36	66.0227
2144.25	68.4364
2147.14	70.517
2150.03	73.0922
2152.92	74.9624
2155.81	76.7707
2158.7	78.1777
2161.59	80.7112
2164.48	82.0277
2167.36	83.1011
2170.25	82.7781
2173.13	82.7624
2176.01	81.1373
2178.89	80.8346
2181.77	79.8419
2184.65	78.5402
2187.53	76.6651
2190.41	75.8742
2193.28	73.976
2196.16	72.6095
2199.03	70.8193
2201.9	68.3981
2204.78	67.4621
2207.65	64.4459
2210.51	61.3922
2213.38	58.2895
2216.25	54.5519
2219.12	51.8868
2221.98	49.14
2224.85	45.6409
2227.71	43.4255
2230.57	40.7485
2233.43	39.1984
2236.29	36.2737
2239.15	33.7881
2242.01	32.0977
2244.87	30.1805
2247.73	28.6854
2250.58	27.6995
2253.43	26.5771
2256.29	26.3312
2259.14	25.2502
2261.99	24.5588
2264.84	25.1905
2267.69	24.9696
2270.54	24.1992
2273.38	22.9746
2276.23	20.9279
2279.07	21.0301
2281.92	19.4163
2284.76	18.0098
2287.6	17.0922
2290.44	16.0362
2293.28	14.6865
2296.12	13.3737
2298.96	13.5697
2301.79	13.4936
2304.63	13.9919
2307.46	14.1634
2310.3	13.9578
2313.13	13.4401
2315.96	13.724
2318.79	13.6565
2321.62	13.7777
2324.45	13.0921
2327.27	13.136
2330.1	12.5834
2332.93	12.3126
2335.75	11.8741
2338.57	10.465
2341.4	9.07387
2344.22	7.88492
2347.04	7.75062
2349.86	6.77746
2352.67	5.95431
2355.49	5.48659
2358.31	4.86274
2361.12	4.64257
2363.94	6.19793
2366.75	5.33798
2369.56	6.01596
2372.37	6.35947
2375.18	5.95539
2377.99	5.57779
2380.8	4.76726
2383.61	4.55637
2386.41	5.79466
2389.22	5.05842
2392.02	4.52739
2394.82	4.01403
2397.63	3.65983
2400.43	3.63357
2403.23	3.7373
2406.02	4.1983
2408.82	4.27756
2411.62	4.36135
2414.41	4.91299
2417.21	5.52588
2420	6.74399
2422.79	7.49428
2425.59	7.79121
2428.38	8.42085
2431.17	8.67653
2433.96	9.4244
2436.74	10.3478
2439.53	10.4657
2442.32	10.2139
2445.1	8.87812
2447.88	8.7555
2450.67	8.92498
2453.45	9.37836
2456.23	8.32784
2459.01	6.67278
2461.79	4.95112
2464.57	4.19063
2467.34	4.38408
2470.12	3.41307
2472.89	2.71558
2475.67	1.78002
2478.44	1.72444
2481.21	1.55727
2483.98	1.51104
2486.75	1.57254
2489.52	2.53903
2492.29	2.21341
2495.06	2.92141
2497.82	2.96376
2500.59	3.43963
2503.35	5.75736
2506.11	5.48322
2508.88	5.30024
2511.63	5.37027
2514.39	6.43736
2517.15	6.9942
2519.91	6.34534
2522.67	5.94251
2525.42	5.34763
2528.18	5.63741
2530.93	5.7559
2533.69	6.34951
2536.44	6.77309
2539.19	6.33095
2541.94	6.90487
2544.69	6.85187
2547.44	7.52415
2550.18	7.90355
2552.93	7.86506
2555.68	9.37834
2558.42	9.27749
2561.16	9.05923
2563.9	9.86215
2566.64	9.20553
2569.38	9.81257
2572.12	10.0172
2574.86	9.5374
2577.6	9.00763
2580.34	8.38626
2583.07	7.63558
2585.81	7.25112
2588.54	5.95882
2591.27	5.27637
2594	4.64426
2596.73	4.1406
2599.46	3.08754
2602.19	2.40092
2604.92	1.52503
2607.64	2.02787
2610.37	2.35989
2613.09	2.94962
2615.82	3.37442
2618.54	4.50603
2621.26	5.50379
2623.98	6.52016
2626.7	7.59468
2629.42	8.32301
2632.14	9.08991
2634.86	9.36609
2637.57	10.3543
2640.29	10.8161
2643	11.0723
2645.72	10.9856
2648.43	9.95375
2651.14	10.5098
2653.85	10.6991
2656.56	9.26
2659.27	8.89618
2661.97	8.37944
2664.68	8.19812
2667.38	7.42957
2670.09	6.36458
2672.79	6.36294
2675.49	6.42346
2678.2	6.06994
2680.89	6.26663
2683.59	6.61288
2686.29	5.99911
2688.99	5.67956
2691.69	5.66886
2694.38	5.75625
2697.08	6.03034
2699.77	6.46027
2702.46	8.25732
2705.16	9.06279
2707.85	9.91119
2710.54	9.84799
2713.23	9.47854
2715.92	10.0869
2718.6	10.8129
2721.29	11.1125
2723.97	11.0394
2726.66	11.0032
2729.34	10.9546
2732.02	9.54486
2734.7	8.97532
2737.39	8.68336
2740.06	8.34734
2742.74	7.30335
2745.42	6.9919
2748.1	6.66337
2750.77	5.14654
2753.45	4.16643
2756.12	3.87312
2758.79	3.57078
2761.47	3.21865
2764.14	3.08597
2766.81	3.47178
2769.48	4.20679
2772.14	3.55898
2774.81	2.90125
2777.48	3.02752
2780.14	2.38822
2782.81	2.50642
2785.47	2.82268
2788.13	1.76548
2790.79	1.20793
2793.46	0.612127
2796.11	0.608088
2798.77	0.67038
2801.43	-0.228175
2804.09	-0.163643
2806.74	-0.758477
2809.4	-0.943632
2812.05	-0.933023
2814.71	-0.15434
2817.36	0.486247
2820.01	1.73715
2822.66	3.86868
2825.31	7.60328
2827.96	11.425
2830.61	15.6718
2833.25	20.4305
2835.9	24.6117
2838.54	29.8378
2841.18	35.5002
2843.83	40.1622
2846.47	44.9665
2849.11	50.7814
2851.75	55.66
2854.39	61.6289
2857.03	66.9881
2859.67	71.4451
2862.3	74.9839
2864.94	78.7838
2867.57	82.17
2870.21	85.8041
2872.84	87.9114
2875.47	89.8162
2878.1	92.4379
2880.73	94.3941
2883.36	94.9288
2885.99	97.415
2888.61	100.097
2891.24	103.68
2893.87	105.832
2896.49	109.37
2899.11	114.619
2901.74	119.013
2904.36	124.265
2906.98	130.744
2909.6	137.612
2912.22	145.098
2914.83	151.486
2917.45	157.71
2920.07	163.338
2922.68	167.199
2925.3	171.505
2927.91	174.504
2930.52	176.289
2933.13	176.202
2935.74	175.182
2938.35	173.208
2940.96	169.65
2943.57	165.076
2946.18	158.301
2948.78	152.436
2951.39	146.368
2953.99	139.379
2956.6	132.016
2959.2	125.473
2961.8	120.209
2964.4	114.065
2967	107.373
2969.6	101.855
2972.2	95.9063
2974.79	90.0371
2977.39	83.8626
2979.98	77.6964
2982.58	71.1337
2985.17	65.1177
2987.76	58.6564
2990.36	52.4234
2992.95	46.9964
2995.54	40.9377
2998.12	36.6836
3000.71	32.7026
3003.3	28.4771
3005.88	23.3601
3008.47	19.9585
3011.05	16.7288
3013.64	14.1565
3016.22	11.9251
3018.8	9.60812
3021.38	8.44092
3023.96	7.32002
3026.54	5.49585
3029.12	3.64398
3031.69	2.74329
3034.27	1.89298
3036.85	0.846546
3039.42	0.908015
3041.99	0.794528
3044.57	0.0059101
3047.14	-0.860761
3049.71	-1.02422
3052.28	-1.09488
3054.85	-0.884914
3057.42	0.0121662
3059.98	0.244392
3062.55	0.383416
3065.11	0.936204
3067.68	0.654173
3070.24	0.912674
3072.8	1.46652
3075.37	1.74743
3077.93	2.59058
3080.49	2.43132
3083.05	2.0136
3085.61	2.79947
3088.16	2.94672
3090.72	2.08195
3093.27	2.05804
3095.83	1.84536
3098.38	1.21797
3100.94	1.03449
3103.49	1.55861
3106.04	1.08514
3108.59	0.949879
3111.14	1.21791
3113.69	1.76023
3116.23	2.19554
3118.78	2.97954
3121.33	3.56202
3123.87	3.55226
3126.42	3.97608
3128.96	4.61046
3131.5	5.71768
3134.04	7.08343
3136.58	8.28829
3139.12	9.63065
3141.66	10.3695
3144.2	11.1602
3146.74	11.0773
3149.27	8.73246