File: data/Raman/poly_smoothed/Mb_50_18_33_1x_45s_532 nm_x100_100%_600 gr_mm_01.txt
#Acq. time (s)=	45
#Accumulations=	2
#Range (cm-¹)=	200...3150
#Windows=	2
#Auto scanning=	Off
#Autofocus=	Off
#Macrospot=	Off
#AutoExposure=	Off
#Spike filter=	Multiple accum.
#Delay time (s)=	0
#Binning=	1
#Readout mode=	Signal
#DeNoise=	Off
#ICS correction=	On
#Dark correction=	Off
#Inst. Process=	Off
#Detector Gain=	Best Dynamic Range
#Detector ADC=	20 kHz
#Detector temperature (°C)=	-69.85
#Instrument=	LabRAM HR Evol
#Detector=	Synapse
#Objective=	x100
#Grating=	600 gr/mm
#ND Filter=	100%
#Laser (nm)=	532
#Hole=	100.021
#Range=	Auto
#Laser Pol.=	No
#Raman. Pol.=	No
#Laser Pol. (°)=	-0.0007625
#Raman Pol. (°)=	89.9995
#Collection=	Microscope
#StageXY=	Marzhauser
#StageZ=	Marzhauser
#X (µm)=	28287.9
#Y (µm)=	-3238.1
#Z (µm)=	1041.05
#Full time(mm:ss)=	3:19
#Project=
#Sample=
#Site=
#Title=	Mb_50_18_33_2x_45s_532 nm_x100_100%_600 gr_mm
#Remark=
#Date=	12.07.2022 13:23
#Acquired=	12.07.2022 13:23:53
#Base:Fit=	10.08.2022 10:49:18
#Base:Sub=	10.08.2022 10:49:30
#Filter:Polynom=	16.08.2022 10:14:59
#AxisType[0]=Intens
#AxisUnit[0]=Cnt
#AxisType[1]=Spectr
#AxisUnit[1]=1/cm
200.388	26.7321
204.019	24.5216
207.646	20.95
211.274	17.6694
214.899	15.8583
218.524	13.0959
222.146	12.8261
225.766	11.955
229.388	9.90769
233.005	9.0273
236.621	8.83069
240.236	8.30378
243.852	8.80145
247.464	9.34686
251.074	9.52844
254.683	9.62646
258.291	12.2737
261.897	15.3875
265.504	16.125
269.108	16.5361
272.71	16.6537
276.311	16.0396
279.91	16.0326
283.508	14.5472
287.105	13.4973
290.698	11.0974
294.291	11.5174
297.884	12.6999
301.475	13.4694
305.064	13.7309
308.652	13.198
312.237	13.4334
315.822	13.4852
319.406	16.4251
322.987	18.7448
326.568	19.8109
330.148	22.0804
333.724	25.4576
337.301	26.1629
340.875	28.7301
344.449	29.4437
348.02	31.5461
351.592	33.2591
355.16	34.7861
358.728	36.1707
362.294	38.3267
365.858	40.2786
369.422	41.417
372.983	41.63
376.543	40.356
380.102	41.8508
383.661	42.75
387.216	43.0005
390.771	40.108
394.324	38.7434
397.875	37.1691
401.425	35.1131
404.974	33.712
408.524	31.58
412.07	28.8183
415.614	25.5333
419.156	24.4724
422.698	20.804
426.238	16.7905
429.777	15.0823
433.315	12.7486
436.852	12.2113
440.387	10.9144
443.919	10.2591
447.451	9.13624
450.982	8.87765
454.512	9.35222
458.038	8.09062
461.565	7.99846
465.091	9.50575
468.613	9.4558
472.136	10.0374
475.655	11.163
479.176	12.6558
482.692	13.9609
486.21	16.533
489.724	21.1135
493.237	24.7444
496.75	28.1671
500.26	32.3779
503.771	35.2154
507.279	38.5229
510.785	40.1272
514.289	39.1528
517.793	38.4936
521.297	37.4096
524.797	34.6815
528.297	32.4958
531.795	29.739
535.291	27.2709
538.787	24.7302
542.281	20.1095
545.773	16.6638
549.264	14.1756
552.754	9.15331
556.243	7.13212
559.73	4.99127
563.216	1.5121
566.701	0.544523
570.182	0.755585
573.664	0.284091
577.145	1.59445
580.624	1.41614
584.1	2.00203
587.577	2.96316
591.052	3.41917
594.524	4.29998
597.997	4.26074
601.466	4.72799
604.936	5.30751
608.403	5.05713
611.87	4.68709
615.334	5.15177
618.799	5.60027
622.26	6.49673
625.72	5.96004
629.181	6.10683
632.638	6.06817
636.095	6.01534
639.551	6.05253
643.005	5.79404
646.457	6.24106
649.908	7.35087
653.357	8.63263
656.806	7.91005
660.253	9.65058
663.7	10.6707
667.145	13.5898
670.588	14.5737
674.027	16.306
677.468	17.6908
680.907	20.4359
684.345	21.9418
687.781	21.222
691.216	22.0576
694.65	22.2455
698.081	23.8483
701.512	25.4926
704.942	26.0284
708.371	27.4984
711.796	27.0739
715.222	28.7503
718.645	28.8715
722.068	29.3433
725.49	29.6439
728.909	28.6403
732.329	29.8806
735.745	31.9902
739.16	35.5215
742.576	40.3719
745.988	47.2625
749.401	52.3637
752.811	59.0214
756.22	64.6203
759.627	69.9508
763.035	74.8295
766.44	78.4756
769.843	81.1456
773.245	83.2318
776.646	85.9574
780.046	87.7689
783.444	89.6967
786.841	89.2677
790.237	91.0513
793.631	88.8885
797.024	86.0022
800.416	83.1853
803.807	78.1011
807.196	74.4553
810.584	70.4347
813.971	68.7039
817.354	65.783
820.739	64.7441
824.122	63.1184
827.503	63.5268
830.882	61.3628
834.261	60.4143
837.637	59.1017
841.013	57.3888
844.389	54.5879
847.761	52.6761
851.131	49.8154
854.503	46.7341
857.871	45.1413
861.24	44.7739
864.606	43.4212
867.97	41.7515
871.336	40.7755
874.698	40.0972
878.058	39.9834
881.418	38.2966
884.778	37.8781
888.135	38.5831
891.49	39.4794
894.845	38.2992
898.198	37.8348
901.55	37.6938
904.901	38.1242
908.25	39.7537
911.598	40.89
914.945	41.2238
918.291	41.2989
921.635	41.0344
924.978	41.4296
928.318	39.6377
931.659	38.3429
934.998	36.8279
938.336	35.8867
941.671	35.3343
945.007	33.4528
948.339	31.3858
951.672	29.8086
955.004	29.6486
958.333	29.1065
961.662	27.1404
964.989	24.3327
968.315	21.6106
971.639	20.468
974.962	17.0999
978.285	16.1833
981.605	15.888
984.924	14.0811
988.243	13.4596
991.56	13.6344
994.875	14.841
998.188	16.5163
1001.5	19.5259
1004.81	22.8187
1008.12	26.7272
1011.43	30.5586
1014.74	33.4625
1018.05	38.9732
1021.35	42.4502
1024.65	45.0039
1027.96	48.0221
1031.26	49.5564
1034.56	50.7298
1037.86	51.2788
1041.16	48.6147
1044.45	45.4091
1047.75	42.8635
1051.04	41.5892
1054.33	38.7789
1057.62	36.1336
1060.91	34.1007
1064.2	31.1798
1067.49	29.3868
1070.77	28.6108
1074.06	28.1023
1077.34	28.9619
1080.62	29.6016
1083.91	29.4653
1087.18	28.6406
1090.46	31.1676
1093.74	32.0388
1097.02	32.9932
1100.29	34.096
1103.56	32.5286
1106.84	32.1779
1110.11	29.5717
1113.38	28.2218
1116.64	25.4192
1119.91	23.0984
1123.18	20.3583
1126.44	18.0219
1129.7	16.6374
1132.97	13.6944
1136.23	11.9951
1139.49	9.61333
1142.74	9.24599
1146	7.71407
1149.26	5.20934
1152.51	4.55896
1155.76	2.74362
1159.01	2.4072
1162.27	2.12918
1165.51	1.43937
1168.76	3.91379
1172.01	5.87081
1175.25	6.69289
1178.5	6.62093
1181.74	6.4621
1184.98	5.96327
1188.22	6.47287
1191.46	5.97405
1194.7	6.51264
1197.94	7.18097
1201.17	7.12568
1204.41	7.27154
1207.64	8.00717
1210.87	8.10698
1214.1	10.4345
1217.33	12.5462
1220.56	14.1131
1223.79	14.6806
1227.01	17.22
1230.23	18.9707
1233.46	23.0753
1236.68	25.6758
1239.9	28.5405
1243.12	30.8922
1246.34	35.3267
1249.55	37.1155
1252.77	38.531
1255.98	38.8983
1259.2	41.0882
1262.41	41.6136
1265.62	43.4376
1268.83	46.5112
1272.03	48.4481
1275.24	49.9727
1278.45	52.1972
1281.65	53.1733
1284.85	53.6998
1288.06	54.6453
1291.26	54.5807
1294.46	53.5191
1297.66	51.8213
1300.85	51.8646
1304.05	51.9229
1307.24	52.4343
1310.43	53.6025
1313.63	53.2316
1316.82	51.4159
1320.01	50.5094
1323.2	49.9012
1326.38	48.1269
1329.57	46.4877
1332.76	46.0844
1335.94	45.8823
1339.12	46.4781
1342.3	45.8289
1345.48	46.251
1348.66	46.0321
1351.84	45.2898
1355.01	45.7487
1358.19	44.4112
1361.36	41.9853
1364.53	41.8408
1367.71	40.6484
1370.88	38.7042
1374.04	37.3865
1377.21	35.4192
1380.38	34.3976
1383.54	33.7059
1386.71	32.7907
1389.87	31.6494
1393.03	28.6436
1396.19	27.8992
1399.35	28.3973
1402.51	27.962
1405.67	28.9168
1408.82	30.5898
1411.98	32.5115
1415.13	36.548
1418.28	39.5287
1421.43	44.1426
1424.58	48.9658
1427.73	52.747
1430.88	57.05
1434.02	60.8686
1437.17	64.3582
1440.31	68.6771
1443.45	69.6827
1446.6	70.8959
1449.74	71.6641
1452.87	70.4344
1456.01	69.7319
1459.15	69.9365
1462.28	69.5573
1465.42	68.3046
1468.55	65.9442
1471.68	64.0693
1474.81	62.6043
1477.94	58.1805
1481.07	56.2362
1484.2	53.9513
1487.32	52.3152
1490.45	51.049
1493.57	48.4352
1496.69	46.1933
1499.81	44.1608
1502.93	42.0065
1506.05	39.4027
1509.17	37.6923
1512.28	35.1294
1515.4	33.3094
1518.51	32.121
1521.63	30.3642
1524.74	30.4208
1527.85	29.5609
1530.96	29.3704
1534.06	30.3148
1537.17	32.026
1540.28	32.6317
1543.38	34.0258
1546.48	35.7825
1549.59	36.631
1552.69	37.6523
1555.79	37.8506
1558.88	40.7198
1561.98	41.7828
1565.08	43.1957
1568.17	43.7976
1571.27	44.1829
1574.36	45.9828
1577.45	47.2194
1580.54	48.7317
1583.63	49.4282
1586.72	49.6498
1589.8	50.3803
1592.89	51.6812
1595.97	50.3651
1599.06	50.0941
1602.14	49.013
1605.22	48.2525
1608.3	47.7988
1611.38	49.6589
1614.46	49.3517
1617.53	50.519
1620.61	51.4779
1623.68	51.8969
1626.75	52.0675
1629.82	53.7402
1632.9	54.1438
1635.96	55.8104
1639.03	56.262
1642.1	58.0726
1645.16	58.2201
1648.23	59.5051
1651.29	60.5993
1654.36	61.8234
1657.42	62.1393
1660.48	60.4023
1663.53	59.7961
1666.59	57.6319
1669.65	54.8498
1672.7	51.8415
1675.76	49.1003
1678.81	45.932
1681.86	43.3529
1684.91	39.9818
1687.96	35.807
1691.01	31.7498
1694.06	29.9292
1697.11	27.0926
1700.15	24.7774
1703.2	22.8445
1706.24	20.8947
1709.28	18.6278
1712.32	18.4097
1715.36	18.8076
1718.4	18.2358
1721.43	19.0544
1724.47	19.4868
1727.5	20.3769
1730.54	20.4214
1733.57	21.0474
1736.6	21.5643
1739.63	21.5679
1742.66	21.0458
1745.69	21.2618
1748.72	20.9035
1751.74	20.5866
1754.77	19.9798
1757.79	19.4743
1760.81	18.8076
1763.83	18.5895
1766.85	18.8227
1769.87	17.8668
1772.89	16.8286
1775.91	15.9792
1778.92	15.495
1781.94	15.0464
1784.95	15.4069
1787.96	14.9934
1790.97	13.779
1793.98	14.2089
1796.99	14.1614
1800	14.0652
1803	13.605
1806.01	13.705
1809.01	13.3588
1812.02	12.5083
1815.02	12.1562
1818.02	11.6163
1821.02	11.0186
1824.02	11.1923
1827.01	11.2892
1830.01	11.5081
1833	11.1215
1836	11.9213
1838.99	11.7506
1841.98	11.5664
1844.97	11.1813
1847.96	11.0446
1850.95	10.9253
1853.94	11.7733
1856.92	12.0276
1859.91	12.5225
1862.89	12.8437
1865.88	13.6198
1868.86	14.9585
1871.84	14.8531
1874.82	15.5235
1877.8	15.3127
1880.77	15.2891
1882.51	15.0596
1885.5	14.3173
1888.48	11.9622
1891.47	10.3292
1894.46	8.86992
1897.44	8.34509
1900.42	7.1715
1903.41	6.28194
1906.39	5.87743
1909.37	5.88071
1912.35	5.8597
1915.32	5.1621
1918.3	4.29668
1921.28	3.65479
1924.25	3.6171
1927.22	4.74684
1930.2	4.53228
1933.17	3.85871
1936.14	4.88562
1939.11	4.75998
1942.08	4.59303
1945.04	4.55671
1948.01	5.00878
1950.97	4.88547
1953.94	4.33019
1956.9	3.79711
1959.86	1.83338
1962.82	1.56982
1965.78	1.6509
1968.74	1.75217
1971.69	1.97616
1974.65	2.68178
1977.61	2.81333
1980.56	3.04062
1983.51	4.06768
1986.46	3.8775
1989.41	4.7157
1992.36	4.28095
1995.31	4.74271
1998.26	5.67597
2001.2	5.37779
2004.15	4.86007
2007.09	4.80805
2010.04	4.647
2012.98	3.48708
2015.92	4.86851
2018.86	3.69324
2021.8	3.96037
2024.74	2.92837
2027.67	3.34498
2030.61	2.59974
2033.54	2.69608
2036.47	4.3742
2039.41	4.27746
2042.34	4.63194
2045.27	5.41014
2048.2	5.81633
2051.12	7.40147
2054.05	8.83915
2056.98	10.1993
2059.9	11.9594
2062.82	13.339
2065.75	14.5648
2068.67	16.906
2071.59	18.1024
2074.51	18.2979
2077.43	18.8157
2080.34	18.8508
2083.26	19.7948
2086.17	21.1041
2089.09	23.3707
2092	24.1428
2094.91	26.2083
2097.82	27.4324
2100.73	28.8273
2103.64	29.878
2106.55	32.2121
2109.46	34.1701
2112.36	35.7881
2115.27	37.9788
2118.17	40.6126
2121.07	42.7423
2123.97	45.8985
2126.87	48.4233
2129.77	50.9719
2132.67	53.6886
2135.57	57.3303
2138.46	60.913
2141.36	63.564
2144.25	65.8751
2147.14	68.3564
2150.03	72.3969
2152.92	75.7045
2155.81	78.6867
2158.7	80.1897
2161.59	81.9755
2164.48	83.292
2167.36	82.6967
2170.25	82.4994
2173.13	82.5232
2176.01	81.6712
2178.89	80.5295
2181.77	78.5514
2184.65	75.4723
2187.53	71.368
2190.41	69.2198
2193.28	65.9245
2196.16	63.1359
2199.03	60.2542
2201.9	57.6546
2204.78	55.1037
2207.65	53.2962
2210.51	50.28
2213.38	47.4995
2216.25	44.8708
2219.12	41.7663
2221.98	39.0057
2224.85	35.6144
2227.71	33.104
2230.57	30.3416
2233.43	27.823
2236.29	25.5456
2239.15	22.8019
2242.01	21.3899
2244.87	19.1491
2247.73	17.5771
2250.58	16.2516
2253.43	14.397
2256.29	12.2234
2259.14	12.2561
2261.99	11.651
2264.84	11.8998
2267.69	11.0016
2270.54	10.506
2273.38	9.52601
2276.23	8.96393
2279.07	8.12344
2281.92	6.76952
2284.76	5.12416
2287.6	4.06509
2290.44	3.98451
2293.28	2.24409
2296.12	1.8087
2298.96	2.01849
2301.79	2.31294
2304.63	1.59199
2307.46	2.11657
2310.3	2.39164
2313.13	2.35748
2315.96	2.52216
2318.79	3.33369
2321.62	3.28087
2324.45	3.85185
2327.27	4.41193
2330.1	3.9966
2332.93	4.92937
2335.75	5.25728
2338.57	4.49794
2341.4	4.39407
2344.22	3.81399
2347.04	4.99779
2349.86	3.05525
2352.67	1.92287
2355.49	2.28354
2358.31	2.16537
2361.12	1.39937
2363.94	2.24715
2366.75	3.48502
2369.56	3.099
2372.37	2.43461
2375.18	1.98166
2377.99	1.75855
2380.8	1.75525
2383.61	1.77846
2386.41	1.30231
2389.22	1.30171
2392.02	0.915737
2394.82	1.02116
2397.63	1.7797
2400.43	1.51078
2403.23	0.845556
2406.02	0.577147
2408.82	0.405572
2411.62	0.394164
2414.41	0.731941
2417.21	-0.0971453
2420	-0.472677
2422.79	-0.107648
2425.59	0.292471
2428.38	0.0116864
2431.17	1.15509
2433.96	1.59439
2436.74	1.76267
2439.53	1.47697
2442.32	1.56524
2445.1	2.07779
2447.88	2.22134
2450.67	2.77748
2453.45	2.56269
2456.23	2.0064
2459.01	2.08485
2461.79	2.38812
2464.57	2.952
2467.34	3.85636
2470.12	3.15073
2472.89	3.17042
2475.67	2.37059
2478.44	2.0116
2481.21	1.16497
2483.98	0.741852
2486.75	0.324567
2489.52	0.374887
2492.29	0.268886
2495.06	0.956353
2497.82	0.696491
2500.59	1.65842
2503.35	2.56198
2506.11	3.08499
2508.88	4.24954
2511.63	5.8044
2514.39	6.44012
2517.15	6.66721
2519.91	7.07845
2522.67	6.56758
2525.42	7.07098
2528.18	8.21033
2530.93	8.89703
2533.69	8.65765
2536.44	8.4583
2539.19	7.54895
2541.94	6.90801
2544.69	6.3286
2547.44	5.17611
2550.18	4.26757
2552.93	2.97036
2555.68	2.70269
2558.42	2.37521
2561.16	2.45139
2563.9	3.36546
2566.64	4.64775
2569.38	6.38723
2572.12	7.27168
2574.86	8.20135
2577.6	8.55739
2580.34	8.14752
2583.07	7.78031
2585.81	8.38468
2588.54	7.65
2591.27	8.01615
2594	8.16897
2596.73	7.45508
2599.46	7.16412
2602.19	6.81999
2604.92	6.72711
2607.64	6.96253
2610.37	6.72883
2613.09	5.72124
2615.82	4.46463
2618.54	4.28498
2621.26	5.75307
2623.98	7.30697
2626.7	9.30399
2629.42	11.357
2632.14	12.7066
2634.86	13.4646
2637.57	12.8225
2640.29	12.8182
2643	12.809
2645.72	12.1174
2648.43	12.7826
2651.14	12.0591
2653.85	11.1586
2656.56	10.8679
2659.27	10.0942
2661.97	9.55456
2664.68	8.54352
2667.38	9.22717
2670.09	9.49281
2672.79	8.54836
2675.49	8.31458
2678.2	6.95414
2680.89	6.54047
2683.59	7.37372
2686.29	8.05738
2688.99	9.79609
2691.69	10.7907
2694.38	11.3977
2697.08	11.6527
2699.77	12.0967
2702.46	11.7693
2705.16	12.5473
2707.85	12.6714
2710.54	12.4859
2713.23	12.4141
2715.92	12.5857
2718.6	12.0069
2721.29	12.1952
2723.97	11.6298
2726.66	11.2953
2729.34	11.477
2732.02	11.827
2734.7	11.1398
2737.39	10.2191
2740.06	9.72989
2742.74	9.12496
2745.42	8.40605
2748.1	8.73634
2750.77	8.75183
2753.45	8.8057
2756.12	9.72553
2758.79	8.53933
2761.47	7.40424
2764.14	6.95645
2766.81	5.89834
2769.48	4.39193
2772.14	4.2781
2774.81	3.36775
2777.48	2.79264
2780.14	1.32984
2782.81	0.850407
2785.47	0.789163
2788.13	0.149462
2790.79	0.193502
2793.46	-0.176058
2796.11	-0.65509
2798.77	-0.469699
2801.43	-0.0660441
2804.09	0.494454
2806.74	0.390145
2809.4	0.23642
2812.05	0.890138
2814.71	2.36434
2817.36	2.5598
2820.01	4.34066
2822.66	6.37738
2825.31	10.1885
2827.96	14.7381
2830.61	19.4484
2833.25	24.4379
2835.9	29.7053
2838.54	35.5157
2841.18	42.4634
2843.83	48.7626
2846.47	56.079
2849.11	62.7326
2851.75	69.5785
2854.39	74.9999
2857.03	81.3396
2859.67	86.9055
2862.3	92.2256
2864.94	97.4752
2867.57	101.884
2870.21	104.911
2872.84	106.528
2875.47	109.428
2878.1	111.423
2880.73	113.277
2883.36	114.777
2885.99	117.565
2888.61	121.029
2891.24	124.276
2893.87	127.447
2896.49	131.241
2899.11	136.189
2901.74	140.944
2904.36	147.438
2906.98	154.507
2909.6	162.464
2912.22	169.505
2914.83	176.462
2917.45	183.181
2920.07	189.813
2922.68	195.613
2925.3	199.619
2927.91	202.802
2930.52	203.646
2933.13	203.832
2935.74	202.213
2938.35	199.511
2940.96	195.407
2943.57	189.077
2946.18	182.518
2948.78	174.345
2951.39	167.447
2953.99	159.225
2956.6	150.028
2959.2	142.037
2961.8	133.003
2964.4	125.185
2967	116.775
2969.6	110.705
2972.2	104.074
2974.79	97.6457
2977.39	90.2294
2979.98	84.5743
2982.58	77.6637
2985.17	71.1727
2987.76	63.311
2990.36	56.8627
2992.95	50.9526
2995.54	44.8671
2998.12	39.8606
3000.71	34.3362
3003.3	29.0338
3005.88	23.3749
3008.47	19.2996
3011.05	15.1481
3013.64	11.7223
3016.22	7.96109
3018.8	5.44191
3021.38	3.28899
3023.96	2.67224
3026.54	1.85909
3029.12	1.22172
3031.69	1.27449
3034.27	1.87466
3036.85	2.40726
3039.42	3.30599
3041.99	3.92581
3044.57	4.4669
3047.14	4.56128
3049.71	5.42392
3052.28	5.84257
3054.85	7.32259
3057.42	7.35029
3059.98	8.00882
3062.55	7.99451
3065.11	7.78865
3067.68	7.67587
3070.24	7.39606
3072.8	5.86796
3075.37	4.82918
3077.93	3.75081
3080.49	2.91063
3083.05	2.82094
3085.61	2.07601
3088.16	2.97613
3090.72	2.74936
3093.27	3.73765
3095.83	5.10418
3098.38	6.55318
3100.94	7.48088
3103.49	9.1025
3106.04	11.1062
3108.59	13.1296
3111.14	15.8564
3113.69	18.2484
3116.23	20.2111
3118.78	22.2978
3121.33	24.4158
3123.87	27.0342
3126.42	29.0185
3128.96	30.2458
3131.5	31.2735
3134.04	32.1922
3136.58	32.5161
3139.12	32.9259
3141.66	33.6018
3144.2	34.8345
3146.74	36.5889
3149.27	38.2634