File: data/Raman/poly_smoothed/Mb_50_18_32_1x_45s_532 nm_x100_100%_600 gr_mm_01.txt
#Acq. time (s)=	45
#Accumulations=	2
#Range (cm-¹)=	200...3150
#Windows=	2
#Auto scanning=	Off
#Autofocus=	Off
#Macrospot=	Off
#AutoExposure=	Off
#Spike filter=	Multiple accum.
#Delay time (s)=	0
#Binning=	1
#Readout mode=	Signal
#DeNoise=	Off
#ICS correction=	On
#Dark correction=	Off
#Inst. Process=	Off
#Detector Gain=	Best Dynamic Range
#Detector ADC=	20 kHz
#Detector temperature (°C)=	-69.85
#Instrument=	LabRAM HR Evol
#Detector=	Synapse
#Objective=	x100
#Grating=	600 gr/mm
#ND Filter=	100%
#Laser (nm)=	532
#Hole=	100.021
#Range=	Auto
#Laser Pol.=	No
#Raman. Pol.=	No
#Laser Pol. (°)=	-0.0007625
#Raman Pol. (°)=	89.9995
#Collection=	Microscope
#StageXY=	Marzhauser
#StageZ=	Marzhauser
#X (µm)=	28337.3
#Y (µm)=	-3244.3
#Z (µm)=	1041.05
#Full time(mm:ss)=	3:19
#Project=
#Sample=
#Site=
#Title=	Mb_50_18_32_2x_45s_532 nm_x100_100%_600 gr_mm
#Remark=
#Date=	12.07.2022 13:19
#Acquired=	12.07.2022 13:19:31
#Base:Fit=	10.08.2022 10:49:18
#Base:Sub=	10.08.2022 10:49:30
#Filter:Polynom=	16.08.2022 10:14:59
#AxisType[0]=Intens
#AxisUnit[0]=Cnt
#AxisType[1]=Spectr
#AxisUnit[1]=1/cm
200.388	44.4678
204.019	37.0825
207.646	31.605
211.274	26.2629
214.899	23.1107
218.524	20.3102
222.146	19.4357
225.766	16.0637
229.388	14.4991
233.005	11.918
236.621	11.4604
240.236	10.4582
243.852	10.106
247.464	9.19932
251.074	9.45729
254.683	10.1384
258.291	10.1601
261.897	11.8776
265.504	11.0754
269.108	8.95105
272.71	7.98798
276.311	4.5106
279.91	4.32974
283.508	3.09611
287.105	2.79018
290.698	4.57527
294.291	4.7079
297.884	8.14071
301.475	13.4297
305.064	18.2706
308.652	23.5111
312.237	27.0719
315.822	29.6338
319.406	31.6175
322.987	33.6231
326.568	33.5732
330.148	33.7521
333.724	32.0713
337.301	29.0295
340.875	24.5255
344.449	22.0495
348.02	21.2951
351.592	23.9916
355.16	28.1792
358.728	35.416
362.294	43.9126
365.858	52.2975
369.422	62.908
372.983	71.2569
376.543	79.7345
380.102	88.1954
383.661	95.1436
387.216	101.521
390.771	104.121
394.324	106.27
397.875	102.113
401.425	96.4909
404.974	87.9057
408.524	78.5369
412.07	67.4789
415.614	54.6263
419.156	41.033
422.698	26.5278
426.238	13.2354
429.777	5.16651
433.315	-0.776209
436.852	-4.08628
440.387	-4.15101
443.919	-3.1037
447.451	-0.696885
450.982	0.592043
454.512	2.2736
458.038	3.08482
461.565	3.41586
465.091	4.12531
468.613	5.44417
472.136	6.02126
475.655	7.86801
479.176	11.8522
482.692	17.5972
486.21	25.6504
489.724	34.3289
493.237	45.2834
496.75	57.9438
500.26	69.8709
503.771	79.7107
507.279	88.3022
510.785	96.7646
514.289	102.177
517.793	106.389
521.297	107.694
524.797	108.745
528.297	106.016
531.795	101.911
535.291	95.7411
538.787	87.1413
542.281	78.0681
545.773	67.9892
549.264	56.4472
552.754	44.1104
556.243	33.1368
559.73	24.9214
563.216	18.1698
566.701	14.7248
570.182	11.9148
573.664	12.2373
577.145	12.4667
580.624	14.9138
584.1	17.8214
587.577	20.1683
591.052	20.2362
594.524	21.9677
597.997	23.2025
601.466	25.7837
604.936	26.1348
608.403	26.6314
611.87	25.4591
615.334	25.3232
618.799	24.4286
622.26	24.8066
625.72	23.246
629.181	22.4712
632.638	17.4884
636.095	15.6366
639.551	12.5814
643.005	10.9304
646.457	6.79698
649.908	5.52697
653.357	3.99615
656.806	3.67491
660.253	4.12453
663.7	4.46789
667.145	4.78724
670.588	5.19735
674.027	4.72586
677.468	5.78253
680.907	7.89687
684.345	12.0888
687.781	14.8839
691.216	16.4892
694.65	19.6869
698.081	22.6154
701.512	24.0192
704.942	26.5214
708.371	28.7564
711.796	30.1079
715.222	30.0227
718.645	27.3411
722.068	25.3501
725.49	22.5433
728.909	19.3914
732.329	19.8662
735.745	25.9167
739.16	35.995
742.576	51.3813
745.988	70.6943
749.401	91.0661
752.811	113.294
756.22	133.243
759.627	151.369
763.035	168.277
766.44	182.903
769.843	196.195
773.245	203.105
776.646	209.049
780.046	209.791
783.444	206.318
786.841	200.184
790.237	190.425
793.631	177.061
797.024	161.024
800.416	140.358
803.807	118.559
807.196	100.324
810.584	83.3861
813.971	68.0908
817.354	58.8036
820.739	55.0826
824.122	52.4954
827.503	52.4065
830.882	53.4342
834.261	54.4355
837.637	53.0098
841.013	51.5619
844.389	50.0581
847.761	48.2711
851.131	46.9043
854.503	45.8208
857.871	43.4309
861.24	40.6716
864.606	39.1573
867.97	37.6169
871.336	35.869
874.698	36.2303
878.058	36.1415
881.418	36.3429
884.778	34.5834
888.135	35.1863
891.49	34.2491
894.845	33.0085
898.198	31.973
901.55	32.9409
904.901	32.0554
908.25	33.0713
911.598	35.4557
914.945	35.8166
918.291	36.0388
921.635	35.9645
924.978	33.505
928.318	33.9394
931.659	32.6227
934.998	31.4474
938.336	31.0013
941.671	29.7786
945.007	27.5045
948.339	25.7286
951.672	25.2788
955.004	24.0903
958.333	22.01
961.662	20.1977
964.989	19.1266
968.315	18.8391
971.639	17.9723
974.962	17.1803
978.285	16.4203
981.605	14.569
984.924	14.5453
988.243	12.1563
991.56	13.5442
994.875	16.8412
998.188	22.1626
1001.5	28.7136
1004.81	38.1041
1008.12	50.0678
1011.43	63.8704
1014.74	75.147
1018.05	87.1657
1021.35	99.361
1024.65	107.043
1027.96	115.699
1031.26	122.345
1034.56	124.296
1037.86	124.565
1041.16	124.443
1044.45	122.943
1047.75	115.996
1051.04	109.058
1054.33	103.5
1057.62	100.517
1060.91	99.4306
1064.2	99.8226
1067.49	100.693
1070.77	101.833
1074.06	104.663
1077.34	107.965
1080.62	111.104
1083.91	113.419
1087.18	114.861
1090.46	117.59
1093.74	117.329
1097.02	114.85
1100.29	111.618
1103.56	104.791
1106.84	96.3113
1110.11	85.1454
1113.38	70.1829
1116.64	56.9937
1119.91	42.5572
1123.18	29.2069
1126.44	16.7839
1129.7	8.49364
1132.97	5.59343
1136.23	4.27548
1139.49	5.68056
1142.74	7.2101
1146	7.99188
1149.26	8.55865
1152.51	9.04271
1155.76	10.8522
1159.01	11.2972
1162.27	11.733
1165.51	14.635
1168.76	18.9189
1172.01	22.9076
1175.25	25.3161
1178.5	26.2517
1181.74	27.6427
1184.98	28.9639
1188.22	29.1274
1191.46	28.9283
1194.7	29.3001
1197.94	28.7783
1201.17	27.5677
1204.41	27.7699
1207.64	28.3352
1210.87	28.6721
1214.1	28.3408
1217.33	28.6049
1220.56	29.1033
1223.79	30.5659
1227.01	31.8803
1230.23	32.7377
1233.46	33.0095
1236.68	33.1251
1239.9	34.3826
1243.12	36.6934
1246.34	39.1119
1249.55	40.3745
1252.77	40.5378
1255.98	41.3291
1259.2	42.0216
1262.41	45.1947
1265.62	48.358
1268.83	51.3744
1272.03	54.0231
1275.24	56.7422
1278.45	58.6179
1281.65	61.0244
1284.85	61.6804
1288.06	61.9372
1291.26	62.7819
1294.46	61.2636
1297.66	62.0117
1300.85	60.8368
1304.05	61.1377
1307.24	59.3026
1310.43	57.8502
1313.63	55.5201
1316.82	54.2879
1320.01	52.476
1323.2	50.204
1326.38	46.9355
1329.57	45.5506
1332.76	45.4106
1335.94	44.3138
1339.12	44.6548
1342.3	44.2187
1345.48	41.2402
1348.66	39.7065
1351.84	37.4209
1355.01	35.6405
1358.19	33.0493
1361.36	30.2749
1364.53	27.4826
1367.71	25.8521
1370.88	23.9293
1374.04	23.2013
1377.21	21.9241
1380.38	19.8262
1383.54	19.4775
1386.71	17.4885
1389.87	17.2948
1393.03	17.7998
1396.19	17.3875
1399.35	19.2429
1402.51	23.5796
1405.67	30.0976
1408.82	38.8468
1411.98	48.7906
1415.13	57.7236
1418.28	65.2631
1421.43	73.5906
1424.58	82.9444
1427.73	92.7199
1430.88	102.113
1434.02	110.113
1437.17	115.182
1440.31	119.788
1443.45	124.23
1446.6	123.316
1449.74	121.76
1452.87	118.257
1456.01	114.038
1459.15	107.901
1462.28	101.106
1465.42	92.9467
1468.55	82.2747
1471.68	72.9309
1474.81	64.0901
1477.94	58.4494
1481.07	50.8047
1484.2	44.3509
1487.32	39.2747
1490.45	33.1092
1493.57	27.8757
1496.69	22.898
1499.81	20.4165
1502.93	18.2878
1506.05	16.7682
1509.17	14.0189
1512.28	9.89868
1515.4	6.20426
1518.51	5.40808
1521.63	4.84869
1524.74	4.18446
1527.85	5.34543
1530.96	5.80362
1534.06	6.52573
1537.17	8.52887
1540.28	10.4037
1543.38	11.2602
1546.48	11.4641
1549.59	14.2598
1552.69	14.7559
1555.79	15.1676
1558.88	16.8737
1561.98	18.4942
1565.08	22.079
1568.17	23.7402
1571.27	26.2849
1574.36	28.8541
1577.45	33.4089
1580.54	36.066
1583.63	37.7153
1586.72	39.916
1589.8	40.8344
1592.89	42.6126
1595.97	44.9357
1599.06	46.0802
1602.14	44.2276
1605.22	41.6044
1608.3	40.8095
1611.38	40.6678
1614.46	40.7589
1617.53	40.1089
1620.61	38.066
1623.68	39.0317
1626.75	39.0037
1629.82	38.9555
1632.9	40.5153
1635.96	42.1423
1639.03	44.4873
1642.1	46.8592
1645.16	49.8498
1648.23	52.2782
1651.29	55.7377
1654.36	59.0632
1657.42	60.0638
1660.48	59.5106
1663.53	59.893
1666.59	57.3664
1669.65	56.3823
1672.7	53.1826
1675.76	47.1871
1678.81	42.0482
1681.86	38.4011
1684.91	34.9301
1687.96	31.5308
1691.01	27.875
1694.06	24.1517
1697.11	20.9006
1700.15	18.723
1703.2	14.4241
1706.24	13.3421
1709.28	10.6941
1712.32	9.37945
1715.36	7.53292
1718.4	6.15377
1721.43	5.90472
1724.47	6.43259
1727.5	5.85917
1730.54	4.14111
1733.57	3.68104
1736.6	3.09446
1739.63	2.83488
1742.66	1.83395
1745.69	1.48407
1748.72	-0.435122
1751.74	-0.555083
1754.77	0.32644
1757.79	-0.725409
1760.81	-0.511148
1763.83	-0.356568
1766.85	0.408836
1769.87	1.54067
1772.89	0.412922
1775.91	0.700041
1778.92	0.57807
1781.94	0.0436147
1784.95	-0.174012
1787.96	0.877426
1790.97	0.513365
1793.98	1.07852
1796.99	1.03462
1800	1.75214
1803	1.83591
1806.01	1.52984
1809.01	1.83466
1812.02	2.86823
1815.02	3.15324
1818.02	2.21257
1821.02	1.97961
1824.02	2.73808
1827.01	2.74306
1830.01	2.09835
1833	2.45349
1836	2.6763
1838.99	3.08325
1841.98	3.24083
1844.97	3.90351
1847.96	4.06661
1850.95	3.34357
1853.94	3.14708
1856.92	4.00824
1859.91	3.29844
1862.89	3.04738
1865.88	4.205
1868.86	4.25625
1871.84	5.66182
1874.82	5.80029
1877.8	4.82367
1880.77	6.42727
1882.51	8.13247
1885.5	8.20922
1888.48	7.55555
1891.47	7.03301
1894.46	7.33398
1897.44	6.9415
1900.42	6.40309
1903.41	6.60753
1906.39	5.92081
1909.37	4.917
1912.35	4.9494
1915.32	4.51873
1918.3	2.89228
1921.28	1.31308
1924.25	2.02183
1927.22	3.1013
1930.2	3.1555
1933.17	2.41607
1936.14	2.98458
1939.11	3.70219
1942.08	4.50978
1945.04	5.0449
1948.01	5.08503
1950.97	6.72344
1953.94	7.61783
1956.9	7.87668
1959.86	6.50587
1962.82	6.3318
1965.78	6.18332
1968.74	7.8773
1971.69	8.5119
1974.65	9.0559
1977.61	9.45727
1980.56	9.67243
1983.51	9.01726
1986.46	8.15682
1989.41	8.38994
1992.36	9.25921
1995.31	10.8302
1998.26	11.3297
2001.2	10.6607
2004.15	10.1426
2007.09	10.0036
2010.04	10.4668
2012.98	11.268
2015.92	12.1271
2018.86	11.3429
2021.8	11.7939
2024.74	10.7276
2027.67	11.1945
2030.61	11.4965
2033.54	11.9307
2036.47	13.0499
2039.41	14.1731
2042.34	15.2815
2045.27	14.2286
2048.2	15.2958
2051.12	16.6892
2054.05	17.7639
2056.98	18.1793
2059.9	20.213
2062.82	21.9888
2065.75	22.7882
2068.67	23.9054
2071.59	23.1059
2074.51	24.2034
2077.43	26.2547
2080.34	28.172
2083.26	29.83
2086.17	31.7434
2089.09	34.4623
2092	36.9856
2094.91	37.9414
2097.82	40.771
2100.73	43.0456
2103.64	46.3038
2106.55	48.5429
2109.46	50.5557
2112.36	52.0747
2115.27	54.7365
2118.17	57.2564
2121.07	60.4
2123.97	63.7304
2126.87	67.7374
2129.77	70.9204
2132.67	74.0985
2135.57	75.437
2138.46	78.1091
2141.36	81.1602
2144.25	85.7178
2147.14	89.9
2150.03	93.335
2152.92	96.4094
2155.81	98.3931
2158.7	101.09
2161.59	103.98
2164.48	105.892
2167.36	106.957
2170.25	108.219
2173.13	108.45
2176.01	108.198
2178.89	107.214
2181.77	105.878
2184.65	103.225
2187.53	102.943
2190.41	99.9284
2193.28	97.4983
2196.16	96.6462
2199.03	94.0787
2201.9	91.4302
2204.78	87.6669
2207.65	85.0682
2210.51	83.9408
2213.38	81.5308
2216.25	78.755
2219.12	73.6568
2221.98	69.8866
2224.85	66.6556
2227.71	63.9247
2230.57	61.1325
2233.43	58.4983
2236.29	54.4926
2239.15	51.0316
2242.01	47.739
2244.87	44.4465
2247.73	41.8162
2250.58	38.8964
2253.43	36.0069
2256.29	33.5187
2259.14	31.6745
2261.99	29.7049
2264.84	27.6973
2267.69	26.9792
2270.54	25.8561
2273.38	24.7728
2276.23	23.9247
2279.07	22.3522
2281.92	22.0297
2284.76	21.4004
2287.6	20.5594
2290.44	20.2841
2293.28	19.9364
2296.12	19.2285
2298.96	20.5875
2301.79	20.9735
2304.63	19.8301
2307.46	19.5277
2310.3	20.4352
2313.13	19.5639
2315.96	19.7047
2318.79	18.5703
2321.62	17.7205
2324.45	17.6348
2327.27	16.2973
2330.1	15.8385
2332.93	14.9747
2335.75	13.9913
2338.57	13.0488
2341.4	10.8063
2344.22	8.3165
2347.04	6.08884
2349.86	5.95179
2352.67	5.84015
2355.49	5.60131
2358.31	3.76733
2361.12	3.34474
2363.94	2.12467
2366.75	3.39662
2369.56	3.40986
2372.37	3.62421
2375.18	3.07108
2377.99	3.05253
2380.8	2.73483
2383.61	2.64328
2386.41	3.31204
2389.22	4.45502
2392.02	5.49448
2394.82	6.314
2397.63	6.74888
2400.43	6.59306
2403.23	7.22534
2406.02	7.28889
2408.82	6.55894
2411.62	6.13875
2414.41	5.95364
2417.21	7.29445
2420	6.87513
2422.79	6.30085
2425.59	5.17858
2428.38	3.96067
2431.17	2.94382
2433.96	2.4686
2436.74	3.37202
2439.53	2.09705
2442.32	0.867741
2445.1	0.538955
2447.88	0.561612
2450.67	1.15858
2453.45	2.02786
2456.23	2.96252
2459.01	3.28005
2461.79	3.56149
2464.57	4.20233
2467.34	3.59854
2470.12	4.71799
2472.89	4.2509
2475.67	3.64013
2478.44	4.75168
2481.21	5.34857
2483.98	5.19134
2486.75	4.63913
2489.52	3.34816
2492.29	2.53206
2495.06	2.7596
2497.82	2.52963
2500.59	3.07614
2503.35	2.94227
2506.11	2.81481
2508.88	3.56335
2511.63	3.84416
2514.39	3.38016
2517.15	3.60051
2519.91	4.34783
2522.67	4.52763
2525.42	5.09556
2528.18	3.98406
2530.93	4.03037
2533.69	3.95531
2536.44	4.51013
2539.19	4.12861
2541.94	4.09332
2544.69	5.42552
2547.44	6.03748
2550.18	5.94244
2552.93	6.20209
2555.68	5.67773
2558.42	5.91994
2561.16	7.59662
2563.9	6.88509
2566.64	7.4223
2569.38	7.76134
2572.12	8.02534
2574.86	7.80711
2577.6	8.32111
2580.34	7.31897
2583.07	7.5106
2585.81	7.11754
2588.54	7.40189
2591.27	6.90078
2594	5.49445
2596.73	4.44927
2599.46	4.05642
2602.19	3.85769
2604.92	3.93901
2607.64	2.60182
2610.37	2.01116
2613.09	0.985456
2615.82	0.536631
2618.54	0.82547
2621.26	0.267391
2623.98	-0.559354
2626.7	0.376879
2629.42	1.5069
2632.14	1.59141
2634.86	3.75139
2637.57	5.12135
2640.29	5.83653
2643	6.62209
2645.72	8.65936
2648.43	8.75628
2651.14	9.69077
2653.85	10.4853
2656.56	10.684
2659.27	9.90686
2661.97	9.94372
2664.68	8.77087
2667.38	7.73987
2670.09	7.54702
2672.79	6.98656
2675.49	5.78303
2678.2	5.61015
2680.89	5.29276
2683.59	5.71625
2686.29	5.13864
2688.99	4.3794
2691.69	4.46272
2694.38	5.95242
2697.08	7.0968
2699.77	8.63913
2702.46	9.72907
2705.16	9.94818
2707.85	10.7392
2710.54	10.4265
2713.23	10.1643
2715.92	10.8853
2718.6	9.86618
2721.29	9.52926
2723.97	7.64278
2726.66	6.49512
2729.34	5.3111
2732.02	4.89186
2734.7	4.96339
2737.39	4.87208
2740.06	4.63809
2742.74	3.84093
2745.42	4.38981
2748.1	3.14629
2750.77	2.70538
2753.45	1.72572
2756.12	1.84888
2758.79	2.18284
2761.47	2.94783
2764.14	3.2488
2766.81	2.34828
2769.48	2.20734
2772.14	1.82072
2774.81	1.54763
2777.48	1.39501
2780.14	0.553919
2782.81	0.471637
2785.47	-0.197291
2788.13	-0.604276
2790.79	-0.943759
2793.46	-1.32321
2796.11	-1.6743
2798.77	-0.44568
2801.43	0.384444
2804.09	-0.644839
2806.74	-2.11845
2809.4	-2.18333
2812.05	-2.34037
2814.71	-1.52106
2817.36	3.04666
2820.01	7.66256
2822.66	16.0253
2825.31	25.4524
2827.96	35.4759
2830.61	45.5744
2833.25	55.9998
2835.9	66.7176
2838.54	78.914
2841.18	88.9069
2843.83	98.6722
2846.47	108.42
2849.11	118.636
2851.75	129.346
2854.39	142.29
2857.03	153.516
2859.67	163.927
2862.3	173.015
2864.94	179.604
2867.57	184.319
2870.21	188.616
2872.84	192.503
2875.47	195.413
2878.1	197.443
2880.73	201.165
2883.36	203.865
2885.99	206.406
2888.61	210.738
2891.24	212.633
2893.87	214.452
2896.49	216.758
2899.11	219.977
2901.74	223.257
2904.36	228.06
2906.98	234.463
2909.6	241.995
2912.22	255.697
2914.83	268.225
2917.45	281.935
2920.07	295.583
2922.68	304.752
2925.3	313.905
2927.91	320.339
2930.52	325.457
2933.13	327.735
2935.74	326.359
2938.35	323.077
2940.96	316.496
2943.57	308.559
2946.18	297.338
2948.78	285.401
2951.39	273.137
2953.99	259.358
2956.6	244.691
2959.2	230.771
2961.8	216.812
2964.4	203.011
2967	190.981
2969.6	179.998
2972.2	170.5
2974.79	161.525
2977.39	152.479
2979.98	143.057
2982.58	134.143
2985.17	123.957
2987.76	115.43
2990.36	106.604
2992.95	97.8881
2995.54	88.4347
2998.12	79.8661
3000.71	71.9609
3003.3	63.5974
3005.88	55.3992
3008.47	48.942
3011.05	42.7368
3013.64	37.5293
3016.22	32.8358
3018.8	27.8262
3021.38	24.2409
3023.96	20.1025
3026.54	17.3755
3029.12	14.9424
3031.69	13.1925
3034.27	11.0087
3036.85	10.8422
3039.42	10.5629
3041.99	10.1659
3044.57	9.72397
3047.14	9.56912
3049.71	9.37266
3052.28	10.0652
3054.85	9.03308
3057.42	8.77163
3059.98	8.06612
3062.55	7.86399
3065.11	7.59058
3067.68	7.59949
3070.24	8.09008
3072.8	7.72394
3075.37	7.09915
3077.93	6.17943
3080.49	5.34742
3083.05	3.92489
3085.61	2.45643
3088.16	1.97095
3090.72	0.464676
3093.27	-0.0116535
3095.83	0.00864224
3098.38	1.19303
3100.94	2.65118
3103.49	2.91784
3106.04	2.74772
3108.59	3.20448
3111.14	3.79932
3113.69	4.45915
3116.23	4.72379
3118.78	5.46288
3121.33	7.40546
3123.87	8.85968
3126.42	11.4035
3128.96	13.7232
3131.5	15.4944
3134.04	16.5093
3136.58	18.6735
3139.12	20.7403
3141.66	22.617
3144.2	24.8387
3146.74	27.9131
3149.27	32.316