File: data/Raman/poly_smoothed/Mb_50_18_39_1x_45s_532 nm_x100_100%_600 gr_mm_01.txt
#Acq. time (s)=	45
#Accumulations=	2
#Range (cm-¹)=	200...3150
#Windows=	2
#Auto scanning=	Off
#Autofocus=	Off
#Macrospot=	Off
#AutoExposure=	Off
#Spike filter=	Multiple accum.
#Delay time (s)=	0
#Binning=	1
#Readout mode=	Signal
#DeNoise=	Off
#ICS correction=	On
#Dark correction=	Off
#Inst. Process=	Off
#Detector Gain=	Best Dynamic Range
#Detector ADC=	20 kHz
#Detector temperature (°C)=	-69.85
#Instrument=	LabRAM HR Evol
#Detector=	Synapse
#Objective=	x100
#Grating=	600 gr/mm
#ND Filter=	100%
#Laser (nm)=	532
#Hole=	100.021
#Range=	Auto
#Laser Pol.=	No
#Raman. Pol.=	No
#Laser Pol. (°)=	-0.0007625
#Raman Pol. (°)=	89.9995
#Collection=	Microscope
#StageXY=	Marzhauser
#StageZ=	Marzhauser
#X (µm)=	28249.8
#Y (µm)=	-3209.3
#Z (µm)=	1041.05
#Full time(mm:ss)=	3:18
#Project=
#Sample=
#Site=
#Title=	Mb_50_18_39_2x_45s_532 nm_x100_100%_600 gr_mm
#Remark=
#Date=	12.07.2022 13:59
#Acquired=	12.07.2022 13:59:34
#Base:Fit=	10.08.2022 10:49:18
#Base:Sub=	10.08.2022 10:49:30
#Filter:Polynom=	16.08.2022 10:14:59
#AxisType[0]=Intens
#AxisUnit[0]=Cnt
#AxisType[1]=Spectr
#AxisUnit[1]=1/cm
200.388	20.5325
204.019	18.0825
207.646	15.9485
211.274	13.5242
214.899	12.5821
218.524	12.7499
222.146	11.0778
225.766	8.55974
229.388	8.82498
233.005	9.68076
236.621	10.7975
240.236	11.8333
243.852	12.8076
247.464	14.1812
251.074	16.7889
254.683	16.8662
258.291	18.4332
261.897	18.641
265.504	18.5435
269.108	20.4649
272.71	21.7951
276.311	22.4039
279.91	21.2487
283.508	22.4744
287.105	21.8829
290.698	23.8919
294.291	27.1146
297.884	29.351
301.475	30.9186
305.064	32.5435
308.652	33.3209
312.237	33.9832
315.822	35.8814
319.406	38.104
322.987	37.5519
326.568	38.0125
330.148	37.0517
333.724	36.1624
337.301	34.6524
340.875	33.6272
344.449	33.3851
348.02	35.4818
351.592	36.9864
355.16	42.0991
358.728	47.2437
362.294	53.8394
365.858	59.2771
369.422	64.5365
372.983	70.6401
376.543	76.305
380.102	80.1276
383.661	81.1001
387.216	83.2406
390.771	83.9542
394.324	82.6298
397.875	80.3906
401.425	77.2569
404.974	72.6544
408.524	67.5936
412.07	60.7107
415.614	52.5081
419.156	42.8456
422.698	34.8534
426.238	28.2586
429.777	22.9857
433.315	19.8744
436.852	16.9549
440.387	13.789
443.919	13.7325
447.451	14.2687
450.982	14.4689
454.512	12.8126
458.038	14.2064
461.565	15.3306
465.091	14.6076
468.613	14.4665
472.136	14.9891
475.655	17.988
479.176	20.7597
482.692	25.5834
486.21	32.1269
489.724	38.827
493.237	46.4232
496.75	53.7004
500.26	59.5605
503.771	63.9422
507.279	69.9764
510.785	74.0264
514.289	74.8925
517.793	76.1874
521.297	76.369
524.797	75.285
528.297	73.9204
531.795	72.8394
535.291	67.9866
538.787	63.3004
542.281	58.8572
545.773	51.443
549.264	43.1135
552.754	35.4762
556.243	30.4318
559.73	25.3567
563.216	24.7183
566.701	20.6257
570.182	20.0889
573.664	19.563
577.145	20.4901
580.624	20.8878
584.1	21.6046
587.577	21.7499
591.052	21.2284
594.524	20.8179
597.997	19.1987
601.466	19.5846
604.936	20.7832
608.403	18.8897
611.87	18.7564
615.334	15.5342
618.799	13.5684
622.26	12.0666
625.72	10.334
629.181	8.77045
632.638	6.81665
636.095	6.14437
639.551	5.02397
643.005	3.28375
646.457	4.48539
649.908	2.40743
653.357	1.62592
656.806	3.29093
660.253	3.24987
663.7	5.07054
667.145	6.08583
670.588	8.06318
674.027	7.93326
677.468	8.81219
680.907	9.65891
684.345	10.9219
687.781	12.6427
691.216	13.2898
694.65	14.7251
698.081	14.606
701.512	15.037
704.942	17.5932
708.371	18.4824
711.796	20.5475
715.222	22.0608
718.645	21.506
722.068	21.6709
725.49	21.791
728.909	21.7746
732.329	24.6046
735.745	29.0148
739.16	38.1562
742.576	48.7307
745.988	61.7789
749.401	75.3285
752.811	87.5064
756.22	98.983
759.627	109.686
763.035	118.747
766.44	125.187
769.843	129.053
773.245	134.353
776.646	135.978
780.046	134.96
783.444	131.388
786.841	129.162
790.237	124.004
793.631	116.681
797.024	109.02
800.416	100.149
803.807	89.0708
807.196	80.1136
810.584	70.9124
813.971	64.2249
817.354	62.4203
820.739	58.1057
824.122	59.1643
827.503	59.6394
830.882	60.1425
834.261	58.6902
837.637	57.6381
841.013	56.624
844.389	55.2779
847.761	51.1672
851.131	48.7814
854.503	49.0798
857.871	46.703
861.24	43.9271
864.606	41.5901
867.97	39.467
871.336	38.8015
874.698	35.4122
878.058	34.5277
881.418	33.6652
884.778	32.1698
888.135	33.3354
891.49	34.293
894.845	33.4868
898.198	34.4124
901.55	32.057
904.901	32.1063
908.25	33.659
911.598	32.1465
914.945	32.0767
918.291	29.2517
921.635	29.3365
924.978	28.8897
928.318	27.0112
931.659	24.3806
934.998	21.9958
938.336	21.5567
941.671	18.315
945.007	16.0583
948.339	13.1766
951.672	12.5409
955.004	9.75988
958.333	7.11297
961.662	6.32577
964.989	4.78036
968.315	6.00979
971.639	5.98081
974.962	5.8794
978.285	4.48168
981.605	2.68316
984.924	2.02133
988.243	2.73768
991.56	4.63036
994.875	8.11908
998.188	13.7164
1001.5	22.9582
1004.81	33.8306
1008.12	43.1739
1011.43	53.8752
1014.74	64.0162
1018.05	73.2791
1021.35	81.1717
1024.65	86.0947
1027.96	92.7274
1031.26	95.7281
1034.56	93.9451
1037.86	90.7109
1041.16	88.0542
1044.45	84.2257
1047.75	79.4439
1051.04	73.2457
1054.33	67.3219
1057.62	64.2415
1060.91	59.567
1064.2	57.5577
1067.49	57.4798
1070.77	58.2686
1074.06	61.1401
1077.34	64.9753
1080.62	66.8325
1083.91	69.76
1087.18	69.0393
1090.46	69.9973
1093.74	70.0382
1097.02	68.6683
1100.29	65.4503
1103.56	62.0053
1106.84	57.7221
1110.11	52.4532
1113.38	44.7203
1116.64	37.7339
1119.91	32.2496
1123.18	27.6689
1126.44	21.2369
1129.7	17.538
1132.97	15.6141
1136.23	13.4307
1139.49	13.9107
1142.74	13.2013
1146	13.6245
1149.26	13.9499
1152.51	14.1594
1155.76	13.7073
1159.01	11.3542
1162.27	9.72485
1165.51	10.362
1168.76	10.2496
1172.01	11.5508
1175.25	15.0733
1178.5	16.9865
1181.74	18.5143
1184.98	19.925
1188.22	21.8115
1191.46	23.1503
1194.7	23.2656
1197.94	24.212
1201.17	24.3242
1204.41	24.1237
1207.64	21.7563
1210.87	23.8864
1214.1	25.6491
1217.33	28.5577
1220.56	30.8209
1223.79	32.3791
1227.01	36.4529
1230.23	39.0193
1233.46	40.2491
1236.68	39.6965
1239.9	39.019
1243.12	42.2942
1246.34	43.2442
1249.55	44.7478
1252.77	47.1252
1255.98	48.551
1259.2	48.5412
1262.41	49.575
1265.62	53.6505
1268.83	54.1837
1272.03	56.6549
1275.24	58.2
1278.45	60.2535
1281.65	62.1577
1284.85	64.7589
1288.06	69.2414
1291.26	74.6442
1294.46	76.1061
1297.66	77.6405
1300.85	78.2278
1304.05	79.7016
1307.24	79.9329
1310.43	79.3237
1313.63	78.6635
1316.82	78.012
1320.01	76.7107
1323.2	76.3455
1326.38	74.6976
1329.57	72.1822
1332.76	69.0739
1335.94	68.4832
1339.12	68.3883
1342.3	67.454
1345.48	67.4018
1348.66	65.2976
1351.84	65.8434
1355.01	62.7504
1358.19	60.4248
1361.36	58.2155
1364.53	56.91
1367.71	56.3048
1370.88	54.6236
1374.04	50.2533
1377.21	49.4712
1380.38	47.1647
1383.54	44.6222
1386.71	40.3175
1389.87	36.8365
1393.03	33.7316
1396.19	30.754
1399.35	28.9905
1402.51	30.4929
1405.67	30.7357
1408.82	33.1721
1411.98	37.9234
1415.13	43.5939
1418.28	50.2328
1421.43	57.2182
1424.58	64.8884
1427.73	74.0371
1430.88	81.8344
1434.02	88.1469
1437.17	94.9146
1440.31	101.888
1443.45	106.183
1446.6	110.757
1449.74	113.334
1452.87	115.512
1456.01	115.756
1459.15	115.582
1462.28	114.994
1465.42	113.676
1468.55	112.684
1471.68	111.156
1474.81	110.253
1477.94	105.833
1481.07	103.435
1484.2	98.4599
1487.32	92.2638
1490.45	87.5995
1493.57	81.4233
1496.69	76.5079
1499.81	69.6364
1502.93	63.7762
1506.05	56.579
1509.17	49.0338
1512.28	42.7272
1515.4	37.7847
1518.51	32.2919
1521.63	27.8335
1524.74	24.0128
1527.85	21.8024
1530.96	21.515
1534.06	22.5115
1537.17	25.8857
1540.28	28.4109
1543.38	30.2222
1546.48	32.072
1549.59	34.3321
1552.69	37.0358
1555.79	37.396
1558.88	38.6998
1561.98	39.5247
1565.08	42.1596
1568.17	44.5311
1571.27	44.8773
1574.36	46.2776
1577.45	48.0775
1580.54	50.3914
1583.63	52.5984
1586.72	54.2002
1589.8	55.5828
1592.89	56.4463
1595.97	54.5369
1599.06	52.2968
1602.14	52.4729
1605.22	52.7408
1608.3	51.7612
1611.38	52.235
1614.46	51.3667
1617.53	51.3382
1620.61	52.1295
1623.68	52.2347
1626.75	53.3926
1629.82	54.6325
1632.9	55.3911
1635.96	58.3342
1639.03	62.9179
1642.1	65.4053
1645.16	68.5577
1648.23	71.5387
1651.29	74.8403
1654.36	77.044
1657.42	76.927
1660.48	75.7347
1663.53	74.5194
1666.59	73.4594
1669.65	70.134
1672.7	66.7425
1675.76	62.2799
1678.81	57.9776
1681.86	50.4636
1684.91	45.1064
1687.96	39.5203
1691.01	34.3421
1694.06	30.5856
1697.11	25.8085
1700.15	21.2205
1703.2	19.2019
1706.24	17.0223
1709.28	15.9614
1712.32	15.56
1715.36	14.0936
1718.4	12.9519
1721.43	12.2608
1724.47	10.7256
1727.5	9.50653
1730.54	9.5728
1733.57	8.58025
1736.6	8.40065
1739.63	8.95874
1742.66	9.21737
1745.69	8.12672
1748.72	6.60876
1751.74	4.72073
1754.77	2.73531
1757.79	1.69606
1760.81	1.22527
1763.83	1.44565
1766.85	1.64222
1769.87	1.87004
1772.89	1.78336
1775.91	1.73717
1778.92	2.38079
1781.94	2.02119
1784.95	1.90851
1787.96	1.27675
1790.97	-0.207111
1793.98	-0.246506
1796.99	0.19313
1800	-0.329606
1803	-1.06068
1806.01	-0.815227
1809.01	-0.818573
1812.02	0.139899
1815.02	1.11931
1818.02	0.382489
1821.02	0.62378
1824.02	0.177279
1827.01	0.487993
1830.01	0.792979
1833	1.24564
1836	3.16475
1838.99	3.16092
1841.98	3.4554
1844.97	3.14159
1847.96	3.01384
1850.95	3.75074
1853.94	3.83401
1856.92	4.10039
1859.91	4.8976
1862.89	5.49671
1865.88	6.81074
1868.86	7.2105
1871.84	7.73728
1874.82	7.74408
1877.8	8.6552
1880.77	9.31363
1882.51	9.66125
1885.5	9.90412
1888.48	8.43798
1891.47	7.95883
1894.46	7.41529
1897.44	6.25483
1900.42	5.32711
1903.41	5.088
1906.39	4.95533
1909.37	3.32052
1912.35	2.65375
1915.32	2.8094
1918.3	2.71827
1921.28	4.05317
1924.25	4.33712
1927.22	4.74777
1930.2	5.48297
1933.17	5.45013
1936.14	5.59391
1939.11	5.64501
1942.08	6.0502
1945.04	7.18112
1948.01	7.6009
1950.97	8.33673
1953.94	8.26141
1956.9	8.03808
1959.86	7.54108
1962.82	7.10638
1965.78	6.93728
1968.74	7.02356
1971.69	6.48116
1974.65	6.43892
1977.61	7.01809
1980.56	6.87918
1983.51	5.87767
1986.46	6.67079
1989.41	7.75743
1992.36	7.64108
1995.31	7.46997
1998.26	6.34974
2001.2	5.6117
2004.15	5.38927
2007.09	4.93373
2010.04	5.74883
2012.98	5.12765
2015.92	5.31098
2018.86	5.25097
2021.8	6.77377
2024.74	6.05259
2027.67	5.95788
2030.61	6.80503
2033.54	7.52479
2036.47	8.85163
2039.41	8.80958
2042.34	9.24935
2045.27	10.8051
2048.2	12.419
2051.12	12.6134
2054.05	14.3758
2056.98	15.3507
2059.9	17.0935
2062.82	16.931
2065.75	17.8268
2068.67	18.8573
2071.59	19.8181
2074.51	22.9563
2077.43	25.233
2080.34	27.0741
2083.26	28.9576
2086.17	31.6912
2089.09	33.2405
2092	35.9697
2094.91	38.189
2097.82	39.8879
2100.73	42.9419
2103.64	45.0742
2106.55	48.5131
2109.46	51.9367
2112.36	54.1455
2115.27	58.5138
2118.17	62.9676
2121.07	67.3228
2123.97	69.8779
2126.87	74.4659
2129.77	77.9001
2132.67	83.2081
2135.57	87.8359
2138.46	93.8754
2141.36	97.2719
2144.25	102.639
2147.14	107.433
2150.03	111.397
2152.92	114.119
2155.81	117.982
2158.7	119.688
2161.59	121.391
2164.48	122.182
2167.36	121.89
2170.25	121.511
2173.13	120.16
2176.01	119.416
2178.89	117.462
2181.77	114.385
2184.65	110.989
2187.53	107.044
2190.41	104.128
2193.28	100.469
2196.16	96.5048
2199.03	93.0699
2201.9	90.7991
2204.78	86.7057
2207.65	81.6075
2210.51	78.073
2213.38	74.4037
2216.25	70.8874
2219.12	65.8348
2221.98	62.1849
2224.85	59.1826
2227.71	55.2489
2230.57	50.7633
2233.43	47.1472
2236.29	44.1422
2239.15	41.5182
2242.01	38.2675
2244.87	36.8242
2247.73	32.7062
2250.58	28.7486
2253.43	26.1825
2256.29	24.1277
2259.14	23.6381
2261.99	22.0419
2264.84	20.9087
2267.69	20.3308
2270.54	19.6559
2273.38	19.4234
2276.23	18.3808
2279.07	18.6164
2281.92	18.8992
2284.76	17.9673
2287.6	16.1837
2290.44	15.3142
2293.28	15.1107
2296.12	14.8162
2298.96	15.2603
2301.79	16.5123
2304.63	16.8307
2307.46	16.9267
2310.3	17.3903
2313.13	16.4378
2315.96	15.0632
2318.79	13.3948
2321.62	12.7013
2324.45	11.9658
2327.27	10.9822
2330.1	9.01535
2332.93	8.16977
2335.75	7.66451
2338.57	7.09857
2341.4	6.66563
2344.22	5.84202
2347.04	6.08279
2349.86	4.14159
2352.67	2.43711
2355.49	0.785975
2358.31	0.801587
2361.12	0.129746
2363.94	0.958442
2366.75	1.10098
2369.56	2.82944
2372.37	2.77749
2375.18	2.51197
2377.99	1.65496
2380.8	1.00387
2383.61	0.942605
2386.41	0.782378
2389.22	-0.0219557
2392.02	-0.287823
2394.82	-0.595105
2397.63	-0.285559
2400.43	0.518258
2403.23	1.80972
2406.02	2.97143
2408.82	4.19929
2411.62	4.72623
2414.41	4.834
2417.21	5.39632
2420	4.60821
2422.79	5.7037
2425.59	6.75826
2428.38	7.37483
2431.17	7.47821
2433.96	7.24221
2436.74	7.20361
2439.53	7.05958
2442.32	5.2787
2445.1	4.26514
2447.88	3.1434
2450.67	2.96623
2453.45	2.85364
2456.23	3.07406
2459.01	2.80493
2461.79	2.58572
2464.57	3.86664
2467.34	4.1602
2470.12	4.33892
2472.89	4.57085
2475.67	4.77958
2478.44	4.46756
2481.21	4.06024
2483.98	3.75718
2486.75	2.91547
2489.52	3.72255
2492.29	5.04561
2495.06	4.64864
2497.82	4.27615
2500.59	3.40784
2503.35	2.96953
2506.11	2.88726
2508.88	2.44236
2511.63	1.83511
2514.39	2.31818
2517.15	0.922048
2519.91	1.36498
2522.67	2.69644
2525.42	2.85374
2528.18	2.78678
2530.93	3.6755
2533.69	3.93762
2536.44	3.7878
2539.19	4.01388
2541.94	3.87734
2544.69	4.8323
2547.44	4.91534
2550.18	5.18885
2552.93	5.53966
2555.68	6.15631
2558.42	6.97106
2561.16	7.29121
2563.9	7.00207
2566.64	6.81057
2569.38	6.26229
2572.12	6.52807
2574.86	7.53779
2577.6	7.23991
2580.34	6.60526
2583.07	6.2685
2585.81	6.18402
2588.54	6.456
2591.27	6.04571
2594	5.42105
2596.73	6.78506
2599.46	7.61005
2602.19	8.06331
2604.92	9.24196
2607.64	8.87611
2610.37	9.3076
2613.09	9.12399
2615.82	8.66295
2618.54	9.29721
2621.26	10.0429
2623.98	11.1518
2626.7	11.584
2629.42	11.108
2632.14	11.1397
2634.86	11.0572
2637.57	10.5711
2640.29	11.2146
2643	11.219
2645.72	10.0237
2648.43	8.97098
2651.14	8.97784
2653.85	8.1534
2656.56	7.37025
2659.27	8.06916
2661.97	8.3386
2664.68	8.57951
2667.38	9.22365
2670.09	9.18402
2672.79	8.40932
2675.49	7.35061
2678.2	7.85754
2680.89	9.08237
2683.59	9.32866
2686.29	11.1596
2688.99	11.8172
2691.69	12.5946
2694.38	12.0787
2697.08	13.0791
2699.77	12.9665
2702.46	12.8592
2705.16	13.6097
2707.85	14.0696
2710.54	13.2647
2713.23	12.9095
2715.92	13.1366
2718.6	13.1553
2721.29	12.7888
2723.97	13.5436
2726.66	12.791
2729.34	11.7298
2732.02	10.889
2734.7	10.6331
2737.39	9.80638
2740.06	9.0592
2742.74	10.1083
2745.42	9.8962
2748.1	9.77339
2750.77	8.99746
2753.45	8.51429
2756.12	6.9535
2758.79	5.79374
2761.47	4.57602
2764.14	3.73321
2766.81	4.27697
2769.48	3.82586
2772.14	3.54946
2774.81	2.97654
2777.48	2.46634
2780.14	2.37888
2782.81	2.04854
2785.47	1.04721
2788.13	1.34435
2790.79	0.925034
2793.46	0.300028
2796.11	-0.134817
2798.77	0.318493
2801.43	0.773939
2804.09	1.66774
2806.74	2.43232
2809.4	2.16252
2812.05	2.15521
2814.71	2.7856
2817.36	4.5157
2820.01	6.51088
2822.66	10.2326
2825.31	15.6901
2827.96	20.523
2830.61	27.672
2833.25	34.5484
2835.9	41.8755
2838.54	49.3431
2841.18	57.4641
2843.83	66.0446
2846.47	74.3528
2849.11	83.8555
2851.75	91.3568
2854.39	98.8721
2857.03	105.953
2859.67	113.155
2862.3	118.294
2864.94	124.967
2867.57	130.869
2870.21	135.144
2872.84	138.521
2875.47	141.904
2878.1	145.942
2880.73	150.977
2883.36	155.637
2885.99	160.427
2888.61	166.872
2891.24	172.088
2893.87	177.851
2896.49	185.84
2899.11	194.573
2901.74	205.615
2904.36	217.09
2906.98	229.33
2909.6	242.997
2912.22	256.381
2914.83	269.833
2917.45	282.913
2920.07	295.993
2922.68	306.483
2925.3	313.731
2927.91	319.757
2930.52	322.835
2933.13	324.314
2935.74	321.38
2938.35	316.845
2940.96	311.117
2943.57	303.315
2946.18	292.324
2948.78	280.301
2951.39	267.839
2953.99	253.741
2956.6	240.235
2959.2	227.532
2961.8	214.895
2964.4	203.112
2967	190.936
2969.6	179.471
2972.2	169.173
2974.79	159.457
2977.39	148.746
2979.98	139.252
2982.58	128.74
2985.17	118.235
2987.76	107.958
2990.36	96.7251
2992.95	85.948
2995.54	76.0372
2998.12	66.0533
3000.71	56.0403
3003.3	47.7724
3005.88	40.4522
3008.47	33.3193
3011.05	25.4516
3013.64	21.5754
3016.22	17.5088
3018.8	13.6186
3021.38	10.7109
3023.96	7.24245
3026.54	5.34551
3029.12	3.67656
3031.69	1.95484
3034.27	2.09182
3036.85	2.47775
3039.42	2.60298
3041.99	2.79444
3044.57	3.97907
3047.14	4.71423
3049.71	5.32551
3052.28	5.24758
3054.85	5.33249
3057.42	6.19815
3059.98	5.86863
3062.55	5.15396
3065.11	4.75214
3067.68	4.52003
3070.24	4.35833
3072.8	2.73452
3075.37	1.71502
3077.93	1.20781
3080.49	0.266772
3083.05	-0.325883
3085.61	0.185629
3088.16	0.342268
3090.72	0.932315
3093.27	1.47651
3095.83	2.81453
3098.38	3.92366
3100.94	5.30191
3103.49	6.74011
3106.04	8.63968
3108.59	10.4739
3111.14	12.6046
3113.69	13.6857
3116.23	15.2394
3118.78	17.7125
3121.33	19.225
3123.87	21.1255
3126.42	22.6304
3128.96	24.3987
3131.5	26.494
3134.04	28.3025
3136.58	29.536
3139.12	32.3528
3141.66	34.9412
3144.2	37.4283
3146.74	39.4486
3149.27	39.6547