File: data/Raman/poly_smoothed/Mb_50_18_30_1x_45s_532 nm_x100_100%_600 gr_mm_01.txt
#Acq. time (s)=	45
#Accumulations=	2
#Range (cm-¹)=	200...3150
#Windows=	2
#Auto scanning=	Off
#Autofocus=	Off
#Macrospot=	Off
#AutoExposure=	Off
#Spike filter=	Multiple accum.
#Delay time (s)=	0
#Binning=	1
#Readout mode=	Signal
#DeNoise=	Off
#ICS correction=	On
#Dark correction=	Off
#Inst. Process=	Off
#Detector Gain=	Best Dynamic Range
#Detector ADC=	20 kHz
#Detector temperature (°C)=	-69.85
#Instrument=	LabRAM HR Evol
#Detector=	Synapse
#Objective=	x100
#Grating=	600 gr/mm
#ND Filter=	100%
#Laser (nm)=	532
#Hole=	100.021
#Range=	Auto
#Laser Pol.=	No
#Raman. Pol.=	No
#Laser Pol. (°)=	-0.0007625
#Raman Pol. (°)=	89.9995
#Collection=	Microscope
#StageXY=	Marzhauser
#StageZ=	Marzhauser
#X (µm)=	28304.5
#Y (µm)=	-3269
#Z (µm)=	1041.35
#Full time(mm:ss)=	3:18
#Project=
#Sample=
#Site=
#Title=	Mb_50_18_30_2x_45s_532 nm_x100_100%_600 gr_mm
#Remark=
#Date=	12.07.2022 13:03
#Acquired=	12.07.2022 13:03:25
#Base:Fit=	10.08.2022 10:49:18
#Base:Sub=	10.08.2022 10:49:30
#Filter:Polynom=	16.08.2022 10:14:59
#AxisType[0]=Intens
#AxisUnit[0]=Cnt
#AxisType[1]=Spectr
#AxisUnit[1]=1/cm
200.388	42.777
204.019	34.5022
207.646	25.5406
211.274	18.3875
214.899	12.9915
218.524	8.12834
222.146	6.67034
225.766	5.66017
229.388	3.19567
233.005	1.82992
236.621	1.60232
240.236	2.35086
243.852	1.88275
247.464	3.62124
251.074	6.0579
254.683	7.94823
258.291	8.21129
261.897	7.13371
265.504	8.13049
269.108	10.0379
272.71	9.57204
276.311	9.46293
279.91	8.24619
283.508	6.67039
287.105	6.28057
290.698	6.46058
294.291	8.23933
297.884	8.625
301.475	9.00271
305.064	5.23227
308.652	5.35669
312.237	11.0255
315.822	15.3183
319.406	19.0112
322.987	24.3982
326.568	28.9309
330.148	30.504
333.724	31.7284
337.301	31.5155
340.875	30.2439
344.449	31.198
348.02	32.2804
351.592	36.6189
355.16	39.5274
358.728	43.9713
362.294	46.3001
365.858	51.184
369.422	55.1599
372.983	58.0597
376.543	60.4193
380.102	62.3137
383.661	61.265
387.216	59.365
390.771	55.6696
394.324	55.006
397.875	58.3396
401.425	55.6337
404.974	52.1779
408.524	46.4161
412.07	41.7251
415.614	32.0266
419.156	24.4115
422.698	16.1985
426.238	8.48402
429.777	4.03394
433.315	3.29453
436.852	1.95306
440.387	0.155205
443.919	0.583382
447.451	3.17861
450.982	3.82167
454.512	5.52963
458.038	5.61257
461.565	7.14164
465.091	7.49669
468.613	7.61527
472.136	9.72033
475.655	10.6102
479.176	13.9124
482.692	17.9296
486.21	23.7567
489.724	29.9361
493.237	36.6773
496.75	44.131
500.26	49.0669
503.771	53.1304
507.279	58.0215
510.785	60.6785
514.289	63.6356
517.793	66.2362
521.297	67.1896
524.797	65.5475
528.297	64.2322
531.795	63.1818
535.291	57.6098
538.787	50.6735
542.281	46.3134
545.773	40.1381
549.264	33.2141
552.754	24.7539
556.243	17.11
559.73	12.3665
563.216	6.714
566.701	6.66575
570.182	6.13237
573.664	6.91276
577.145	8.77199
580.624	9.64177
584.1	10.8399
587.577	11.5432
591.052	12.9263
594.524	13.3157
597.997	14.2088
601.466	15.435
604.936	15.5121
608.403	15.0161
611.87	15.0037
615.334	14.8285
618.799	14.4278
622.26	12.796
625.72	12.5574
629.181	10.884
632.638	10.701
636.095	8.16729
639.551	7.17571
643.005	6.33492
646.457	5.43466
649.908	5.23798
653.357	7.48146
656.806	8.82687
660.253	10.6869
663.7	9.10615
667.145	10.6751
670.588	11.3958
674.027	9.12577
677.468	7.99496
680.907	8.56576
684.345	7.97866
687.781	7.83414
691.216	8.41162
694.65	9.27523
698.081	9.82079
701.512	11.1217
704.942	13.1832
708.371	13.8919
711.796	15.8138
715.222	18.3279
718.645	19.3563
722.068	17.9693
725.49	17.3257
728.909	16.8545
732.329	18.7443
735.745	24.4401
739.16	32.5444
742.576	42.965
745.988	55.2164
749.401	69.8201
752.811	82.312
756.22	94.5741
759.627	105.104
763.035	113.653
766.44	120.184
769.843	125.899
773.245	130.688
776.646	131.55
780.046	132.387
783.444	129.658
786.841	126.555
790.237	120.516
793.631	112.765
797.024	103.874
800.416	93.0574
803.807	79.7606
807.196	66.9556
810.584	59.874
813.971	52.1093
817.354	48.2444
820.739	47.8767
824.122	49.2509
827.503	50.2392
830.882	51.4209
834.261	51.8646
837.637	50.8695
841.013	47.412
844.389	44.9868
847.761	41.3915
851.131	39.8706
854.503	38.0962
857.871	34.6198
861.24	31.3774
864.606	30.5249
867.97	28.9905
871.336	27.6912
874.698	25.3007
878.058	23.8122
881.418	24.3681
884.778	23.4036
888.135	21.8754
891.49	22.0376
894.845	24.8312
898.198	25.9318
901.55	27.587
904.901	29.9583
908.25	29.6239
911.598	29.9525
914.945	28.6438
918.291	26.8756
921.635	24.6979
924.978	23.3555
928.318	22.8572
931.659	21.8873
934.998	20.0877
938.336	16.8687
941.671	14.2377
945.007	13.3107
948.339	13.6818
951.672	10.7821
955.004	7.60591
958.333	4.37286
961.662	2.46111
964.989	1.56356
968.315	0.211725
971.639	1.58932
974.962	4.43956
978.285	9.40251
981.605	13.2459
984.924	15.9376
988.243	19.0438
991.56	22.3182
994.875	28.3203
998.188	34.5198
1001.5	42.6032
1004.81	51.4284
1008.12	61.1903
1011.43	70.6825
1014.74	78.2209
1018.05	85.6798
1021.35	91.7978
1024.65	98.9919
1027.96	101.345
1031.26	100.526
1034.56	96.3324
1037.86	92.5673
1041.16	86.0086
1044.45	79.5719
1047.75	74.1554
1051.04	70.0069
1054.33	65.5794
1057.62	62.3609
1060.91	60.434
1064.2	58.1886
1067.49	56.0202
1070.77	56.169
1074.06	58.7076
1077.34	60.2079
1080.62	61.8
1083.91	62.2549
1087.18	62.2851
1090.46	63.9849
1093.74	63.8415
1097.02	63.4289
1100.29	62.0377
1103.56	58.4855
1106.84	53.4518
1110.11	46.6501
1113.38	39.3851
1116.64	32.9439
1119.91	24.3905
1123.18	18.186
1126.44	11.4316
1129.7	9.00791
1132.97	5.69718
1136.23	4.09643
1139.49	3.86154
1142.74	6.11482
1146	6.20541
1149.26	5.87342
1152.51	5.53741
1155.76	4.16458
1159.01	2.89639
1162.27	2.93638
1165.51	3.18577
1168.76	5.61948
1172.01	7.50384
1175.25	10.1056
1178.5	10.3966
1181.74	10.3927
1184.98	11.3571
1188.22	12.7776
1191.46	13.6754
1194.7	13.5791
1197.94	12.9738
1201.17	14.5483
1204.41	14.8538
1207.64	14.5216
1210.87	15.0999
1214.1	16.7532
1217.33	18.8464
1220.56	19.8758
1223.79	22.051
1227.01	22.3298
1230.23	20.4912
1233.46	21.6881
1236.68	23.3432
1239.9	23.7355
1243.12	26.1062
1246.34	27.7617
1249.55	29.3455
1252.77	29.5377
1255.98	30.3739
1259.2	30.6598
1262.41	31.4086
1265.62	32.8435
1268.83	32.5296
1272.03	34.515
1275.24	36.65
1278.45	39.2312
1281.65	42.0509
1284.85	42.1201
1288.06	45.1125
1291.26	47.2589
1294.46	49.6867
1297.66	51.1473
1300.85	50.1861
1304.05	49.9718
1307.24	50.1184
1310.43	50.8582
1313.63	52.0651
1316.82	51.1321
1320.01	50.2003
1323.2	49.6956
1326.38	48.4879
1329.57	47.3077
1332.76	46.8206
1335.94	45.0976
1339.12	42.1956
1342.3	40.1778
1345.48	37.7005
1348.66	35.6237
1351.84	32.9098
1355.01	30.6796
1358.19	27.7903
1361.36	24.8768
1364.53	23.4168
1367.71	22.9612
1370.88	21.1609
1374.04	20.5257
1377.21	18.9148
1380.38	18.3031
1383.54	17.4041
1386.71	16.9425
1389.87	18.328
1393.03	15.6416
1396.19	15.2843
1399.35	17.5041
1402.51	22.0335
1405.67	26.8384
1408.82	30.6707
1411.98	35.7382
1415.13	40.5483
1418.28	44.4838
1421.43	49.8075
1424.58	55.4097
1427.73	61.1309
1430.88	67.423
1434.02	73.0436
1437.17	77.0491
1440.31	80.7802
1443.45	82.1223
1446.6	83.6641
1449.74	81.99
1452.87	79.7385
1456.01	76.3351
1459.15	72.0633
1462.28	67.1459
1465.42	62.1572
1468.55	55.3978
1471.68	48.7779
1474.81	44.971
1477.94	39.9028
1481.07	36.4885
1484.2	31.4977
1487.32	28.6115
1490.45	25.7741
1493.57	22.8336
1496.69	22.3368
1499.81	20.549
1502.93	18.0433
1506.05	17.5029
1509.17	15.9179
1512.28	14.0923
1515.4	11.2128
1518.51	8.88685
1521.63	8.02206
1524.74	7.89963
1527.85	6.59807
1530.96	7.62128
1534.06	8.66409
1537.17	9.5342
1540.28	11.5206
1543.38	15.1107
1546.48	16.8839
1549.59	18.0806
1552.69	20.3687
1555.79	22.9248
1558.88	25.0603
1561.98	27.9524
1565.08	32.0354
1568.17	35.5611
1571.27	38.5995
1574.36	40.6116
1577.45	42.4837
1580.54	45.0117
1583.63	45.6279
1586.72	46.4367
1589.8	46.8119
1592.89	47.2785
1595.97	48.4758
1599.06	47.6184
1602.14	47.6008
1605.22	47.7691
1608.3	47.773
1611.38	48.5562
1614.46	48.2708
1617.53	48.4152
1620.61	48.6874
1623.68	47.6191
1626.75	47.0241
1629.82	47.9065
1632.9	49.4588
1635.96	51.3875
1639.03	54.3895
1642.1	55.8049
1645.16	57.3671
1648.23	57.5288
1651.29	58.1645
1654.36	56.2988
1657.42	55.5898
1660.48	53.3203
1663.53	52.3684
1666.59	50.0366
1669.65	47.7795
1672.7	45.4912
1675.76	42.118
1678.81	39.1173
1681.86	34.7614
1684.91	30.7779
1687.96	25.1011
1691.01	20.8786
1694.06	17.7224
1697.11	14.7731
1700.15	12.2332
1703.2	10.0941
1706.24	8.41191
1709.28	5.8163
1712.32	5.24289
1715.36	5.12244
1718.4	4.4807
1721.43	4.38119
1724.47	3.65775
1727.5	3.2125
1730.54	3.16242
1733.57	3.99167
1736.6	4.60644
1739.63	5.4095
1742.66	5.87075
1745.69	6.37912
1748.72	5.46015
1751.74	4.52618
1754.77	4.41198
1757.79	4.16588
1760.81	2.29652
1763.83	2.26047
1766.85	1.94772
1769.87	2.36155
1772.89	1.11977
1775.91	0.822801
1778.92	-0.00432143
1781.94	0.408611
1784.95	1.37236
1787.96	2.44743
1790.97	2.15727
1793.98	2.36123
1796.99	1.99199
1800	2.16434
1803	2.394
1806.01	2.12545
1809.01	1.9881
1812.02	2.04638
1815.02	2.20901
1818.02	1.89995
1821.02	0.837532
1824.02	1.10134
1827.01	1.34215
1830.01	1.96535
1833	2.51448
1836	3.54583
1838.99	3.97365
1841.98	5.24185
1844.97	6.28952
1847.96	7.14861
1850.95	8.38194
1853.94	8.23812
1856.92	8.91152
1859.91	9.76665
1862.89	9.44896
1865.88	9.20144
1868.86	9.40192
1871.84	9.15221
1874.82	8.85556
1877.8	8.19149
1880.77	8.68612
1882.51	8.49082
1885.5	8.89387
1888.48	8.92714
1891.47	8.48742
1894.46	8.87951
1897.44	8.91436
1900.42	8.18162
1903.41	8.7196
1906.39	8.86449
1909.37	8.76506
1912.35	9.30392
1915.32	9.60685
1918.3	8.66174
1921.28	7.06923
1924.25	6.79332
1927.22	6.73759
1930.2	6.78002
1933.17	5.77825
1936.14	5.03744
1939.11	4.4108
1942.08	3.14099
1945.04	1.83453
1948.01	0.748288
1950.97	1.31295
1953.94	3.01709
1956.9	2.57789
1959.86	3.25603
1962.82	2.7966
1965.78	2.80648
1968.74	1.40298
1971.69	1.5993
1974.65	1.50601
1977.61	2.66642
1980.56	2.55885
1983.51	3.20664
1986.46	4.10637
1989.41	3.09773
1992.36	4.51935
1995.31	4.7478
1998.26	6.18941
2001.2	6.52311
2004.15	6.60405
2007.09	7.0637
2010.04	6.77088
2012.98	6.12871
2015.92	6.55909
2018.86	7.31973
2021.8	7.83023
2024.74	8.06454
2027.67	8.21875
2030.61	7.27949
2033.54	7.0719
2036.47	7.663
2039.41	7.76952
2042.34	7.97961
2045.27	9.0533
2048.2	11.0168
2051.12	11.2663
2054.05	12.4331
2056.98	14.0939
2059.9	14.4786
2062.82	16.1585
2065.75	17.1032
2068.67	17.2538
2071.59	17.144
2074.51	17.6399
2077.43	18.3824
2080.34	18.8011
2083.26	19.9037
2086.17	21.2288
2089.09	22.6229
2092	22.9013
2094.91	23.5078
2097.82	24.0128
2100.73	25.0977
2103.64	26.0473
2106.55	27.7807
2109.46	28.6032
2112.36	30.7314
2115.27	32.9324
2118.17	36.1554
2121.07	38.2115
2123.97	40.3086
2126.87	42.8535
2129.77	46.0747
2132.67	48.2191
2135.57	51.0121
2138.46	52.7816
2141.36	55.1451
2144.25	58.7769
2147.14	63.3023
2150.03	66.4275
2152.92	70.0105
2155.81	74.7004
2158.7	75.9425
2161.59	78.5709
2164.48	79.6237
2167.36	79.8627
2170.25	79.7178
2173.13	79.3397
2176.01	78.9744
2178.89	78.8718
2181.77	76.9629
2184.65	76.2589
2187.53	73.9213
2190.41	72.0729
2193.28	68.1621
2196.16	66.5296
2199.03	63.8754
2201.9	60.0267
2204.78	57.0192
2207.65	53.9117
2210.51	51.0514
2213.38	49.8894
2216.25	47.8025
2219.12	45.0994
2221.98	43.1437
2224.85	41.6259
2227.71	40.6057
2230.57	36.4796
2233.43	34.3538
2236.29	30.7445
2239.15	28.2235
2242.01	24.7723
2244.87	23.3596
2247.73	21.2851
2250.58	19.2055
2253.43	17.977
2256.29	16.0896
2259.14	15.2537
2261.99	13.697
2264.84	12.691
2267.69	12.0199
2270.54	10.9826
2273.38	9.99859
2276.23	9.04598
2279.07	8.86692
2281.92	8.1542
2284.76	8.0104
2287.6	9.09324
2290.44	9.24224
2293.28	8.96942
2296.12	8.52618
2298.96	9.55673
2301.79	9.76703
2304.63	10.1549
2307.46	11.1952
2310.3	10.3412
2313.13	9.96804
2315.96	10.7643
2318.79	10.0409
2321.62	11.1729
2324.45	11.906
2327.27	12.6622
2330.1	11.365
2332.93	10.5364
2335.75	9.54504
2338.57	8.361
2341.4	6.97512
2344.22	5.25679
2347.04	4.44748
2349.86	3.20938
2352.67	2.9827
2355.49	2.83517
2358.31	3.39855
2361.12	2.94839
2363.94	1.74417
2366.75	4.07169
2369.56	4.2885
2372.37	4.27247
2375.18	4.07613
2377.99	3.60394
2380.8	4.01824
2383.61	3.90611
2386.41	5.56909
2389.22	6.29725
2392.02	8.10394
2394.82	8.4056
2397.63	7.91652
2400.43	6.65627
2403.23	6.11976
2406.02	6.62307
2408.82	6.59804
2411.62	7.10775
2414.41	6.60114
2417.21	7.02151
2420	7.13573
2422.79	7.77256
2425.59	8.13096
2428.38	8.23954
2431.17	6.85252
2433.96	6.5729
2436.74	5.80901
2439.53	6.10873
2442.32	6.46831
2445.1	5.99344
2447.88	6.55068
2450.67	6.93844
2453.45	7.00162
2456.23	7.7323
2459.01	7.57504
2461.79	8.06058
2464.57	7.93781
2467.34	7.91097
2470.12	7.15116
2472.89	7.45263
2475.67	7.62959
2478.44	5.65461
2481.21	5.27449
2483.98	4.80283
2486.75	5.81595
2489.52	4.22368
2492.29	3.29601
2495.06	3.53349
2497.82	2.32517
2500.59	2.2335
2503.35	1.28169
2506.11	0.832127
2508.88	2.22673
2511.63	2.22199
2514.39	2.27568
2517.15	2.64955
2519.91	3.66852
2522.67	3.85102
2525.42	4.42848
2528.18	4.32862
2530.93	4.58227
2533.69	5.64536
2536.44	5.24896
2539.19	5.42027
2541.94	6.84663
2544.69	7.06903
2547.44	7.52942
2550.18	7.566
2552.93	8.8198
2555.68	8.7472
2558.42	7.78958
2561.16	8.98126
2563.9	9.47639
2566.64	8.69848
2569.38	8.47552
2572.12	9.17245
2574.86	10.6541
2577.6	9.55118
2580.34	9.36101
2583.07	8.78812
2585.81	8.82955
2588.54	7.73672
2591.27	6.03163
2594	5.4913
2596.73	4.69244
2599.46	3.03018
2602.19	3.55757
2604.92	4.05772
2607.64	4.8873
2610.37	4.26806
2613.09	4.32062
2615.82	4.68936
2618.54	5.6009
2621.26	6.42815
2623.98	6.90471
2626.7	7.52709
2629.42	8.7591
2632.14	9.23614
2634.86	10.8055
2637.57	11.5012
2640.29	12.2269
2643	12.6713
2645.72	12.2826
2648.43	13.1404
2651.14	12.6484
2653.85	11.9228
2656.56	12.106
2659.27	12.5079
2661.97	12.5515
2664.68	11.9315
2667.38	11.6556
2670.09	11.7059
2672.79	11.2788
2675.49	10.1171
2678.2	9.63725
2680.89	10.0259
2683.59	9.63157
2686.29	10.345
2688.99	10.3267
2691.69	9.99139
2694.38	10.6331
2697.08	10.1967
2699.77	10.0685
2702.46	9.89323
2705.16	9.33433
2707.85	9.45136
2710.54	9.884
2713.23	11.1351
2715.92	12.1579
2718.6	12.2482
2721.29	12.5543
2723.97	11.8986
2726.66	11.8025
2729.34	10.7478
2732.02	10.0868
2734.7	8.06314
2737.39	7.21526
2740.06	6.69854
2742.74	6.02876
2745.42	5.71558
2748.1	5.36248
2750.77	5.12302
2753.45	3.67288
2756.12	3.30716
2758.79	3.32072
2761.47	2.99283
2764.14	3.02383
2766.81	3.27278
2769.48	2.79264
2772.14	3.55732
2774.81	4.48256
2777.48	4.96921
2780.14	5.40469
2782.81	4.47287
2785.47	3.34747
2788.13	3.2735
2790.79	3.14766
2793.46	2.72328
2796.11	3.09319
2798.77	2.45861
2801.43	1.78865
2804.09	1.76743
2806.74	1.59034
2809.4	1.43021
2812.05	0.604695
2814.71	-0.223973
2817.36	-0.773519
2820.01	1.49528
2822.66	4.14067
2825.31	8.75124
2827.96	13.3033
2830.61	18.3486
2833.25	23.1323
2835.9	28.6123
2838.54	34.9994
2841.18	41.4298
2843.83	47.98
2846.47	55.2012
2849.11	61.9809
2851.75	69.5798
2854.39	75.6563
2857.03	81.6544
2859.67	87.6765
2862.3	93.6796
2864.94	98.815
2867.57	103.261
2870.21	106.248
2872.84	108.371
2875.47	110.05
2878.1	112.071
2880.73	113.272
2883.36	117.051
2885.99	120.193
2888.61	122.006
2891.24	125.244
2893.87	129.178
2896.49	133.255
2899.11	138.311
2901.74	144.405
2904.36	150.958
2906.98	158.489
2909.6	168.396
2912.22	178.004
2914.83	187.486
2917.45	197.093
2920.07	205.864
2922.68	215.425
2925.3	222.387
2927.91	228.296
2930.52	232.281
2933.13	234.746
2935.74	234.399
2938.35	231.902
2940.96	227.811
2943.57	221.94
2946.18	213.608
2948.78	203.554
2951.39	192.813
2953.99	181.574
2956.6	170.777
2959.2	158.928
2961.8	147.025
2964.4	136.5
2967	127.084
2969.6	118.364
2972.2	110.972
2974.79	103.785
2977.39	96.5941
2979.98	89.7019
2982.58	82.5438
2985.17	75.9823
2987.76	69.332
2990.36	62.9535
2992.95	57.0813
2995.54	52.3164
2998.12	47.1631
3000.71	40.7216
3003.3	34.4428
3005.88	28.7782
3008.47	23.9738
3011.05	19.2127
3013.64	14.6455
3016.22	10.3068
3018.8	6.79145
3021.38	5.04092
3023.96	3.23503
3026.54	1.62828
3029.12	1.66701
3031.69	0.65718
3034.27	0.989697
3036.85	1.24406
3039.42	2.64231
3041.99	2.95335
3044.57	3.71086
3047.14	4.49588
3049.71	5.81691
3052.28	7.25094
3054.85	7.63091
3057.42	7.68797
3059.98	8.10684
3062.55	7.67645
3065.11	6.38515
3067.68	5.85961
3070.24	5.68057
3072.8	4.91733
3075.37	4.08762
3077.93	4.63483
3080.49	5.35013
3083.05	5.74504
3085.61	6.15726
3088.16	5.91157
3090.72	6.76853
3093.27	8.83356
3095.83	10.6911
3098.38	11.7729
3100.94	13.5791
3103.49	16.4985
3106.04	18.6839
3108.59	20.8521
3111.14	24.0352
3113.69	27.1151
3116.23	28.3645
3118.78	30.6386
3121.33	33.3014
3123.87	35.5813
3126.42	37.3641
3128.96	39.8747
3131.5	42.9935
3134.04	46.3074
3136.58	49.0446
3139.12	52.1885
3141.66	54.8817
3144.2	57.7041
3146.74	61.0432
3149.27	64.3312