File: data/Raman/poly_smoothed/Mb_50_18_25_1x_45s_532 nm_x100_100%_600 gr_mm_01.txt
#Acq. time (s)=	45
#Accumulations=	2
#Range (cm-¹)=	200...3150
#Windows=	2
#Auto scanning=	Off
#Autofocus=	Off
#Macrospot=	Off
#AutoExposure=	Off
#Spike filter=	Multiple accum.
#Delay time (s)=	0
#Binning=	1
#Readout mode=	Signal
#DeNoise=	Off
#ICS correction=	On
#Dark correction=	Off
#Inst. Process=	Off
#Detector Gain=	Best Dynamic Range
#Detector ADC=	20 kHz
#Detector temperature (°C)=	-69.85
#Instrument=	LabRAM HR Evol
#Detector=	Synapse
#Objective=	x100
#Grating=	600 gr/mm
#ND Filter=	100%
#Laser (nm)=	532
#Hole=	100.021
#Range=	Auto
#Laser Pol.=	No
#Raman. Pol.=	No
#Laser Pol. (°)=	-0.0007625
#Raman Pol. (°)=	89.9995
#Collection=	Microscope
#StageXY=	Marzhauser
#StageZ=	Marzhauser
#X (µm)=	28334
#Y (µm)=	-3291.7
#Z (µm)=	1040.6
#Full time(mm:ss)=	3:18
#Project=
#Sample=
#Site=
#Title=	Mb_50_18_25_2x_45s_532 nm_x100_100%_600 gr_mm
#Remark=
#Date=	12.07.2022 12:43
#Acquired=	12.07.2022 12:43:41
#Base:Fit=	10.08.2022 10:49:18
#Base:Sub=	10.08.2022 10:49:30
#Filter:Polynom=	16.08.2022 10:14:59
#AxisType[0]=Intens
#AxisUnit[0]=Cnt
#AxisType[1]=Spectr
#AxisUnit[1]=1/cm
200.388	108.931
204.019	102.404
207.646	95.2421
211.274	87.905
214.899	80.4147
218.524	72.5667
222.146	66.424
225.766	59.7234
229.388	55.1114
233.005	50.3065
236.621	46.2797
240.236	42.4288
243.852	37.6244
247.464	36.0766
251.074	34.5679
254.683	31.4896
258.291	31.5663
261.897	28.8388
265.504	27.328
269.108	24.6742
272.71	22.7203
276.311	19.6958
279.91	19.6943
283.508	17.4375
287.105	14.7888
290.698	14.0945
294.291	14.3067
297.884	15.5922
301.475	17.3088
305.064	19.3394
308.652	21.041
312.237	23.373
315.822	26.828
319.406	27.9169
322.987	28.663
326.568	29.6045
330.148	28.2517
333.724	26.8835
337.301	26.1247
340.875	20.9425
344.449	18.6485
348.02	19.2322
351.592	23.002
355.16	30.0863
358.728	39.5369
362.294	50.1135
365.858	60.9153
369.422	71.4443
372.983	81.5809
376.543	92.1301
380.102	100.111
383.661	105.001
387.216	108.268
390.771	109.458
394.324	109.749
397.875	106.957
401.425	99.3541
404.974	91.489
408.524	82.1164
412.07	70.0488
415.614	55.7309
419.156	38.8769
422.698	24.6247
426.238	11.5697
429.777	-0.153587
433.315	-6.2187
436.852	-8.31789
440.387	-8.03485
443.919	-4.18185
447.451	-0.741057
450.982	2.27758
454.512	5.93203
458.038	10.0813
461.565	12.7592
465.091	15.4885
468.613	15.6689
472.136	17.9563
475.655	22.065
479.176	28.5541
482.692	35.6564
486.21	43.2914
489.724	53.2211
493.237	68.393
496.75	79.8124
500.26	91.1793
503.771	100.224
507.279	108.417
510.785	114.975
514.289	120.434
517.793	123.198
521.297	126.021
524.797	126.721
528.297	127.027
531.795	124.107
535.291	117.295
538.787	109.492
542.281	100.003
545.773	88.8011
549.264	77.1467
552.754	64.4178
556.243	52.9854
559.73	44.0014
563.216	37.4568
566.701	34.1998
570.182	33.4756
573.664	35.2508
577.145	39.9367
580.624	42.7528
584.1	44.8732
587.577	45.9261
591.052	47.9861
594.524	51.3964
597.997	54.2291
601.466	56.5924
604.936	58.4041
608.403	60.1526
611.87	60.1173
615.334	59.2921
618.799	56.9511
622.26	54.0155
625.72	50.2548
629.181	48.7177
632.638	45.1319
636.095	41.9859
639.551	39.6993
643.005	36.9882
646.457	35.8601
649.908	35.9987
653.357	38.7785
656.806	39.2647
660.253	41.2509
663.7	42.9139
667.145	42.6024
670.588	43.8253
674.027	46.2778
677.468	46.3259
680.907	48.9324
684.345	51.4897
687.781	54.4007
691.216	55.575
694.65	57.8375
698.081	59.5244
701.512	61.4046
704.942	63.2048
708.371	64.2005
711.796	65.6148
715.222	65.773
718.645	65.3118
722.068	62.7408
725.49	59.882
728.909	59.3165
732.329	60.4822
735.745	66.0622
739.16	75.2811
742.576	88.9552
745.988	106.566
749.401	126.802
752.811	146.563
756.22	165.488
759.627	181.66
763.035	196.616
766.44	208.657
769.843	217.378
773.245	221.006
776.646	223.895
780.046	223.412
783.444	218.693
786.841	210.739
790.237	199.227
793.631	185.855
797.024	171.622
800.416	152.433
803.807	134.237
807.196	116.12
810.584	99.4687
813.971	86.9366
817.354	79.0446
820.739	76.0713
824.122	73.9356
827.503	76.3274
830.882	77.5623
834.261	77.7564
837.637	77.3101
841.013	77.0761
844.389	73.5692
847.761	71.2445
851.131	68.4417
854.503	64.7067
857.871	61.7459
861.24	60.6887
864.606	57.468
867.97	55.338
871.336	53.109
874.698	53.2485
878.058	52.1654
881.418	51.857
884.778	50.3242
888.135	47.5131
891.49	45.1199
894.845	44.3604
898.198	43.0542
901.55	44.4365
904.901	45.9741
908.25	45.3214
911.598	46.0436
914.945	44.9356
918.291	45.4902
921.635	44.3231
924.978	43.3453
928.318	40.807
931.659	38.1627
934.998	37.5636
938.336	36.3759
941.671	34.3261
945.007	32.3882
948.339	28.8563
951.672	26.3761
955.004	23.4784
958.333	17.0974
961.662	12.9375
964.989	10.4655
968.315	7.31509
971.639	5.27386
974.962	5.41623
978.285	4.10148
981.605	3.49573
984.924	1.07408
988.243	-0.629717
991.56	-3.10691
994.875	0.586051
998.188	6.40503
1001.5	13.3752
1004.81	23.6764
1008.12	35.6183
1011.43	49.3064
1014.74	63.4743
1018.05	78.9044
1021.35	91.4528
1024.65	102.142
1027.96	112.273
1031.26	120.118
1034.56	122.721
1037.86	122.254
1041.16	119.139
1044.45	117.78
1047.75	113.407
1051.04	107.865
1054.33	100.915
1057.62	96.2923
1060.91	92.0498
1064.2	91.2552
1067.49	89.7859
1070.77	91.0281
1074.06	93.0717
1077.34	96.2653
1080.62	96.8025
1083.91	99.3662
1087.18	101.771
1090.46	101.271
1093.74	101.551
1097.02	100.121
1100.29	95.0015
1103.56	89.0345
1106.84	80.9847
1110.11	70.239
1113.38	57.865
1116.64	43.9851
1119.91	31.5127
1123.18	19.1882
1126.44	11.8826
1129.7	5.41763
1132.97	3.0813
1136.23	3.84507
1139.49	7.08366
1142.74	10.2769
1146	12.8801
1149.26	14.5566
1152.51	13.6381
1155.76	13.6159
1159.01	12.3586
1162.27	13.3507
1165.51	13.1332
1168.76	13.5385
1172.01	14.4671
1175.25	15.4437
1178.5	16.5835
1181.74	18.2165
1184.98	17.2782
1188.22	15.5706
1191.46	16.3713
1194.7	15.4752
1197.94	15.336
1201.17	15.6828
1204.41	15.4589
1207.64	17.8281
1210.87	18.6941
1214.1	20.5622
1217.33	21.5489
1220.56	22.5855
1223.79	24.6139
1227.01	23.814
1230.23	24.522
1233.46	25.7463
1236.68	27.7918
1239.9	27.6476
1243.12	28.843
1246.34	28.523
1249.55	28.3277
1252.77	27.5485
1255.98	27.2672
1259.2	25.4531
1262.41	26.9545
1265.62	27.2846
1268.83	29.1823
1272.03	32.0645
1275.24	31.8082
1278.45	34.5599
1281.65	35.9371
1284.85	38.3124
1288.06	39.4742
1291.26	40.8965
1294.46	43.9482
1297.66	45.5103
1300.85	46.7518
1304.05	47.7015
1307.24	48.7735
1310.43	52.5816
1313.63	51.96
1316.82	51.5447
1320.01	49.0896
1323.2	47.1761
1326.38	44.9669
1329.57	40.573
1332.76	37.858
1335.94	37.3687
1339.12	34.7815
1342.3	34.0763
1345.48	31.9863
1348.66	30.1814
1351.84	28.7242
1355.01	28.3365
1358.19	27.9133
1361.36	26.2941
1364.53	25.6695
1367.71	25.1314
1370.88	24.0819
1374.04	22.9767
1377.21	23.3674
1380.38	21.9665
1383.54	20.8947
1386.71	21.274
1389.87	20.1667
1393.03	17.4838
1396.19	16.2429
1399.35	18.0094
1402.51	19.8684
1405.67	23.1566
1408.82	28.3248
1411.98	36.2201
1415.13	44.1527
1418.28	51.6596
1421.43	59.7044
1424.58	69.9874
1427.73	80.7925
1430.88	91.4848
1434.02	101.043
1437.17	109.005
1440.31	113.274
1443.45	118.848
1446.6	119.581
1449.74	120.278
1452.87	120.066
1456.01	120.243
1459.15	120.291
1462.28	117.139
1465.42	112.331
1468.55	108.043
1471.68	104.096
1474.81	100.733
1477.94	97.5361
1481.07	92.8108
1484.2	88.5273
1487.32	85.9674
1490.45	81.5097
1493.57	75.858
1496.69	71.1474
1499.81	63.0536
1502.93	58.9465
1506.05	51.4235
1509.17	44.4699
1512.28	38.7963
1515.4	30.4456
1518.51	24.3939
1521.63	20.3443
1524.74	15.9863
1527.85	14.0673
1530.96	15.8886
1534.06	17.5414
1537.17	17.7588
1540.28	17.8301
1543.38	18.8475
1546.48	20.7209
1549.59	21.5057
1552.69	23.5327
1555.79	25.4782
1558.88	26.7985
1561.98	27.7565
1565.08	29.3055
1568.17	32.5341
1571.27	36.6115
1574.36	39.3281
1577.45	42.7522
1580.54	46.1872
1583.63	48.9668
1586.72	53.9225
1589.8	57.3798
1592.89	62.6156
1595.97	63.8726
1599.06	65.616
1602.14	65.8237
1605.22	65.8477
1608.3	67.1669
1611.38	65.7287
1614.46	65.4904
1617.53	65.318
1620.61	65.5712
1623.68	65.2614
1626.75	63.2808
1629.82	63.2568
1632.9	63.8884
1635.96	64.8204
1639.03	66.5861
1642.1	69.8183
1645.16	71.9502
1648.23	71.7802
1651.29	73.1361
1654.36	73.6992
1657.42	74.7161
1660.48	73.4795
1663.53	71.3818
1666.59	68.5395
1669.65	62.3334
1672.7	54.9059
1675.76	47.9525
1678.81	41.6474
1681.86	36.943
1684.91	32.4032
1687.96	26.8207
1691.01	21.5061
1694.06	17.7402
1697.11	12.9316
1700.15	10.9376
1703.2	8.92057
1706.24	7.86028
1709.28	7.30462
1712.32	5.09926
1715.36	4.50347
1718.4	3.27461
1721.43	3.81524
1724.47	4.46406
1727.5	4.96559
1730.54	4.84878
1733.57	5.46786
1736.6	4.4406
1739.63	4.8591
1742.66	4.05993
1745.69	3.48429
1748.72	3.25534
1751.74	3.29145
1754.77	2.95742
1757.79	2.32342
1760.81	1.75815
1763.83	0.0722986
1766.85	-0.627946
1769.87	-0.944969
1772.89	-0.849071
1775.91	0.940706
1778.92	1.81972
1781.94	1.1108
1784.95	1.44545
1787.96	1.14854
1790.97	1.72115
1793.98	2.49429
1796.99	3.10898
1800	3.61749
1803	2.24683
1806.01	3.30811
1809.01	3.08701
1812.02	3.14015
1815.02	3.58694
1818.02	4.80665
1821.02	4.82884
1824.02	3.42509
1827.01	2.42964
1830.01	2.42252
1833	2.84651
1836	1.82004
1838.99	2.08341
1841.98	2.15179
1844.97	2.72234
1847.96	3.9334
1850.95	3.8941
1853.94	3.81726
1856.92	3.56622
1859.91	4.41593
1862.89	4.75461
1865.88	6.1466
1868.86	5.66987
1871.84	5.1092
1874.82	5.27334
1877.8	5.41911
1880.77	7.01249
1882.51	8.19757
1885.5	8.70216
1888.48	9.7016
1891.47	10.2193
1894.46	8.83087
1897.44	8.87732
1900.42	7.48062
1903.41	7.9781
1906.39	6.93469
1909.37	6.56882
1912.35	5.10827
1915.32	4.45483
1918.3	4.77485
1921.28	6.55158
1924.25	6.57074
1927.22	7.06598
1930.2	7.06596
1933.17	7.12524
1936.14	8.12681
1939.11	7.98058
1942.08	7.94752
1945.04	9.41865
1948.01	10.9748
1950.97	12.1455
1953.94	13.9884
1956.9	12.9491
1959.86	12.5607
1962.82	12.1581
1965.78	11.3064
1968.74	10.3645
1971.69	8.09728
1974.65	7.2523
1977.61	7.01793
1980.56	5.47154
1983.51	4.64559
1986.46	5.00443
1989.41	5.42381
1992.36	6.57986
1995.31	6.36657
1998.26	5.98393
2001.2	5.25443
2004.15	5.31914
2007.09	6.30207
2010.04	7.80427
2012.98	8.16418
2015.92	8.00985
2018.86	8.63747
2021.8	8.38796
2024.74	7.97911
2027.67	7.67143
2030.61	7.03219
2033.54	6.60017
2036.47	7.56996
2039.41	8.35308
2042.34	7.79615
2045.27	6.99138
2048.2	9.04615
2051.12	10.617
2054.05	12.1594
2056.98	14.2599
2059.9	17.8314
2062.82	20.3946
2065.75	21.4986
2068.67	23.8293
2071.59	27.8149
2074.51	29.9125
2077.43	32.2451
2080.34	35.0351
2083.26	37.9119
2086.17	39.6232
2089.09	40.6733
2092	44.0212
2094.91	46.2511
2097.82	48.2786
2100.73	49.8265
2103.64	51.3132
2106.55	53.0355
2109.46	56.97
2112.36	59.4841
2115.27	62.5262
2118.17	66.313
2121.07	69.7274
2123.97	74.282
2126.87	79.2921
2129.77	83.683
2132.67	88.0004
2135.57	92.8997
2138.46	98.0092
2141.36	104.462
2144.25	108.613
2147.14	112.668
2150.03	118.666
2152.92	122.514
2155.81	125.374
2158.7	128.328
2161.59	131.808
2164.48	133.229
2167.36	134.433
2170.25	134.605
2173.13	135.107
2176.01	134.291
2178.89	133.456
2181.77	132.926
2184.65	128.928
2187.53	126.76
2190.41	123.002
2193.28	120.141
2196.16	116.335
2199.03	114.101
2201.9	109.651
2204.78	105.801
2207.65	102.504
2210.51	98.7473
2213.38	93.9653
2216.25	89.9618
2219.12	85.0249
2221.98	80.4289
2224.85	75.22
2227.71	71.6874
2230.57	68.4404
2233.43	64.4731
2236.29	61.1415
2239.15	57.699
2242.01	55.8978
2244.87	52.6609
2247.73	49.5477
2250.58	47.5625
2253.43	44.8479
2256.29	41.1761
2259.14	38.5422
2261.99	37.4617
2264.84	36.6064
2267.69	35.4764
2270.54	33.5922
2273.38	30.4832
2276.23	27.8995
2279.07	27.1747
2281.92	23.4202
2284.76	20.5907
2287.6	16.7863
2290.44	14.008
2293.28	10.4066
2296.12	9.17327
2298.96	8.77645
2301.79	5.7917
2304.63	5.44326
2307.46	3.68873
2310.3	4.19021
2313.13	4.67821
2315.96	3.13818
2318.79	2.82459
2321.62	1.92043
2324.45	1.84854
2327.27	3.19192
2330.1	5.04672
2332.93	7.5239
2335.75	8.01235
2338.57	8.01944
2341.4	8.21731
2344.22	8.95444
2347.04	8.5919
2349.86	7.61642
2352.67	5.22711
2355.49	4.80839
2358.31	3.96399
2361.12	4.62455
2363.94	5.35274
2366.75	4.47291
2369.56	3.35665
2372.37	3.34447
2375.18	3.37443
2377.99	3.4043
2380.8	3.09289
2383.61	2.52529
2386.41	2.90862
2389.22	3.33546
2392.02	5.29804
2394.82	6.98202
2397.63	7.22197
2400.43	8.64711
2403.23	10.1611
2406.02	10.5217
2408.82	12.6578
2411.62	12.6718
2414.41	12.7134
2417.21	12.4025
2420	13.0174
2422.79	14.3849
2425.59	15.0065
2428.38	14.1283
2431.17	12.7233
2433.96	11.5421
2436.74	10.6358
2439.53	9.13316
2442.32	9.16259
2445.1	7.08976
2447.88	6.53508
2450.67	5.09455
2453.45	4.99367
2456.23	6.10293
2459.01	5.60927
2461.79	5.24564
2464.57	4.14216
2467.34	4.07946
2470.12	3.75384
2472.89	4.51257
2475.67	4.95765
2478.44	5.50548
2481.21	5.63563
2483.98	6.3619
2486.75	6.90757
2489.52	7.71614
2492.29	7.64715
2495.06	7.33815
2497.82	6.48278
2500.59	6.37158
2503.35	6.10011
2506.11	5.65532
2508.88	5.77101
2511.63	5.92583
2514.39	6.45844
2517.15	6.99703
2519.91	6.25324
2522.67	7.12273
2525.42	6.00949
2528.18	5.24839
2530.93	5.84064
2533.69	4.97565
2536.44	4.24415
2539.19	4.54308
2541.94	5.09977
2544.69	4.08905
2547.44	4.41965
2550.18	4.9636
2552.93	4.22707
2555.68	4.09663
2558.42	4.06831
2561.16	4.32355
2563.9	4.69934
2566.64	4.94326
2569.38	4.3655
2572.12	4.55354
2574.86	3.81278
2577.6	4.59907
2580.34	2.78772
2583.07	3.33412
2585.81	3.22523
2588.54	3.40379
2591.27	4.4965
2594	4.54268
2596.73	6.4559
2599.46	6.80921
2602.19	6.11349
2604.92	6.29716
2607.64	7.48578
2610.37	7.19728
2613.09	8.41551
2615.82	9.52234
2618.54	8.75108
2621.26	9.58083
2623.98	10.4224
2626.7	13.0703
2629.42	13.5253
2632.14	13.9209
2634.86	12.4391
2637.57	11.4714
2640.29	10.8124
2643	9.8797
2645.72	10.0412
2648.43	10.2144
2651.14	11.3928
2653.85	11.5776
2656.56	12.9871
2659.27	11.8558
2661.97	13.839
2664.68	14.572
2667.38	15.2145
2670.09	14.154
2672.79	15.0915
2675.49	16.0838
2678.2	15.8698
2680.89	16.2337
2683.59	16.6829
2686.29	17.5321
2688.99	19.0202
2691.69	21.369
2694.38	20.9732
2697.08	19.4862
2699.77	17.0282
2702.46	16.0082
2705.16	16.5366
2707.85	17.435
2710.54	18.4589
2713.23	19.3781
2715.92	19.1642
2718.6	18.6851
2721.29	19.0992
2723.97	18.9749
2726.66	18.5367
2729.34	18.6612
2732.02	16.7328
2734.7	13.599
2737.39	11.2712
2740.06	10.2401
2742.74	7.38133
2745.42	6.65494
2748.1	6.30038
2750.77	5.9087
2753.45	6.47638
2756.12	5.13357
2758.79	3.82602
2761.47	2.34298
2764.14	1.68994
2766.81	1.34276
2769.48	3.115
2772.14	3.81634
2774.81	4.6548
2777.48	4.49043
2780.14	4.35177
2782.81	3.5257
2785.47	5.8122
2788.13	7.35624
2790.79	7.17155
2793.46	7.02555
2796.11	6.61957
2798.77	4.35276
2801.43	3.6988
2804.09	3.87482
2806.74	4.25549
2809.4	3.99918
2812.05	4.82185
2814.71	6.19326
2817.36	8.37879
2820.01	12.5149
2822.66	17.7432
2825.31	26.4262
2827.96	34.9912
2830.61	43.7051
2833.25	54.574
2835.9	65.9888
2838.54	76.3417
2841.18	87.8431
2843.83	99.0794
2846.47	111.274
2849.11	123.609
2851.75	135.94
2854.39	147.363
2857.03	157.654
2859.67	167.637
2862.3	176.589
2864.94	184.186
2867.57	190.66
2870.21	195.386
2872.84	200.313
2875.47	203.894
2878.1	207.483
2880.73	211.156
2883.36	214.921
2885.99	221.992
2888.61	229.93
2891.24	237.3
2893.87	243.732
2896.49	252.786
2899.11	261.555
2901.74	273.237
2904.36	285.075
2906.98	299.147
2909.6	317.242
2912.22	335.713
2914.83	353.994
2917.45	374.614
2920.07	391.727
2922.68	408.125
2925.3	423.345
2927.91	433.312
2930.52	440.335
2933.13	445.951
2935.74	447.218
2938.35	443.073
2940.96	434.866
2943.57	424.142
2946.18	411.149
2948.78	396.946
2951.39	380.453
2953.99	360.668
2956.6	339.781
2959.2	320.083
2961.8	300.527
2964.4	281.223
2967	264.52
2969.6	249.331
2972.2	235.445
2974.79	222.357
2977.39	209.897
2979.98	197.921
2982.58	184.973
2985.17	172.738
2987.76	160.835
2990.36	148.094
2992.95	136.307
2995.54	124.762
2998.12	113.073
3000.71	100.123
3003.3	88.2811
3005.88	76.8876
3008.47	65.9992
3011.05	56.2436
3013.64	47.2821
3016.22	39.8873
3018.8	32.1959
3021.38	25.2193
3023.96	19.8699
3026.54	15.3387
3029.12	12.028
3031.69	10.4985
3034.27	7.80303
3036.85	6.32112
3039.42	4.96974
3041.99	5.46249
3044.57	6.14543
3047.14	6.59578
3049.71	7.0997
3052.28	8.03267
3054.85	8.25506
3057.42	8.21335
3059.98	8.73959
3062.55	8.66496
3065.11	8.77864
3067.68	8.19828
3070.24	7.9006
3072.8	6.76735
3075.37	6.90298
3077.93	5.51838
3080.49	3.73774
3083.05	2.29642
3085.61	1.40713
3088.16	0.792285
3090.72	0.235792
3093.27	0.505953
3095.83	1.59417
3098.38	1.57072
3100.94	2.65755
3103.49	5.5466
3106.04	7.79619
3108.59	10.1642
3111.14	12.0138
3113.69	13.7167
3116.23	16.0089
3118.78	17.75
3121.33	21.0644
3123.87	23.5174
3126.42	25.9873
3128.96	29.4362
3131.5	32.3508
3134.04	34.4167
3136.58	35.9304
3139.12	38.5259
3141.66	41.9415
3144.2	45.5638
3146.74	49.3688
3149.27	54.7181