File: data/Raman/poly_smoothed/Mb_50_18_19_1x_45s_532 nm_x100_100%_600 gr_mm_01.txt
#Acq. time (s)=	45
#Accumulations=	2
#Range (cm-¹)=	200...3150
#Windows=	2
#Auto scanning=	Off
#Autofocus=	Off
#Macrospot=	Off
#AutoExposure=	Off
#Spike filter=	Multiple accum.
#Delay time (s)=	0
#Binning=	1
#Readout mode=	Signal
#DeNoise=	Off
#ICS correction=	On
#Dark correction=	Off
#Inst. Process=	Off
#Detector Gain=	Best Dynamic Range
#Detector ADC=	20 kHz
#Detector temperature (°C)=	-69.85
#Instrument=	LabRAM HR Evol
#Detector=	Synapse
#Objective=	x100
#Grating=	600 gr/mm
#ND Filter=	100%
#Laser (nm)=	532
#Hole=	100.021
#Range=	Auto
#Laser Pol.=	No
#Raman. Pol.=	No
#Laser Pol. (°)=	-0.0007625
#Raman Pol. (°)=	89.9995
#Collection=	Microscope
#StageXY=	Marzhauser
#StageZ=	Marzhauser
#X (µm)=	19306.5
#Y (µm)=	3028
#Z (µm)=	1047.7
#Full time(mm:ss)=	3:18
#Project=
#Sample=
#Site=
#Title=	Mb_50_18_19_2x_45s_532 nm_x100_100%_600 gr_mm
#Remark=
#Date=	12.07.2022 11:40
#Acquired=	12.07.2022 11:40:10
#Base:Fit=	10.08.2022 10:49:18
#Base:Sub=	10.08.2022 10:49:30
#Filter:Polynom=	16.08.2022 10:14:59
#AxisType[0]=Intens
#AxisUnit[0]=Cnt
#AxisType[1]=Spectr
#AxisUnit[1]=1/cm
200.388	19.6768
204.019	22.9596
207.646	23.618
211.274	21.4474
214.899	18.3757
218.524	15.7806
222.146	14.3903
225.766	13.05
229.388	13.543
233.005	11.0969
236.621	9.89759
240.236	11.1609
243.852	10.7425
247.464	11.444
251.074	11.1542
254.683	10.9908
258.291	12.0564
261.897	12.695
265.504	12.1854
269.108	12.4488
272.71	14.4924
276.311	15.003
279.91	13.7613
283.508	13.9799
287.105	12.659
290.698	14.4316
294.291	15.4748
297.884	15.213
301.475	15.4112
305.064	17.72
308.652	17.8455
312.237	20.2704
315.822	21.0108
319.406	21.341
322.987	21.4294
326.568	22.0696
330.148	21.5864
333.724	20.3027
337.301	19.4068
340.875	15.5596
344.449	13.4852
348.02	11.7975
351.592	11.3687
355.16	10.7913
358.728	12.384
362.294	13.7395
365.858	14.9532
369.422	16.5951
372.983	18.9416
376.543	22.6217
380.102	26.4374
383.661	26.7553
387.216	28.5492
390.771	30.5244
394.324	30.9843
397.875	31.8523
401.425	33.1942
404.974	31.7817
408.524	29.0606
412.07	26.7115
415.614	23.0767
419.156	19.5949
422.698	14.8337
426.238	11.2157
429.777	8.52338
433.315	8.27244
436.852	6.86398
440.387	6.25593
443.919	5.90184
447.451	7.1291
450.982	8.12449
454.512	9.56023
458.038	9.88334
461.565	10.4296
465.091	10.8779
468.613	11.8905
472.136	13.5251
475.655	15.7529
479.176	16.7059
482.692	20.0004
486.21	23.2775
489.724	27.4904
493.237	32.0577
496.75	35.9221
500.26	38.6568
503.771	39.3182
507.279	40.9029
510.785	42.646
514.289	44.2476
517.793	43.8114
521.297	41.6713
524.797	42.1462
528.297	40.4392
531.795	37.4127
535.291	33.0038
538.787	30.3116
542.281	25.1495
545.773	20.3764
549.264	16.401
552.754	11.7131
556.243	7.67603
559.73	5.46064
563.216	1.8629
566.701	-0.164243
570.182	-0.608065
573.664	0.374362
577.145	2.14093
580.624	3.23503
584.1	2.52719
587.577	1.6154
591.052	2.86709
594.524	3.98491
597.997	4.9489
601.466	4.7877
604.936	5.8444
608.403	7.16419
611.87	7.27454
615.334	8.13589
618.799	8.56864
622.26	9.83485
625.72	9.1402
629.181	9.3107
632.638	10.8076
636.095	10.9897
639.551	10.1191
643.005	10.8624
646.457	9.77549
649.908	7.38567
653.357	8.51644
656.806	7.10622
660.253	6.60375
663.7	5.89734
667.145	4.55091
670.588	4.66668
674.027	4.19212
677.468	5.47144
680.907	6.14523
684.345	7.94437
687.781	7.97508
691.216	10.2774
694.65	11.1877
698.081	10.6993
701.512	14.2902
704.942	16.8177
708.371	18.4635
711.796	20.6736
715.222	24.1943
718.645	25.6102
722.068	26.5736
725.49	27.6039
728.909	27.7452
732.329	29.2743
735.745	31.9604
739.16	35.5084
742.576	38.9387
745.988	45.3066
749.401	51.2557
752.811	57.9529
756.22	63.0991
759.627	69.357
763.035	73.7009
766.44	77.497
769.843	80.6334
773.245	82.1841
776.646	83.3409
780.046	84.1043
783.444	85.0174
786.841	86.1056
790.237	84.5055
793.631	82.8797
797.024	81.037
800.416	77.7945
803.807	75.2342
807.196	71.2591
810.584	68.79
813.971	67.35
817.354	65.339
820.739	65.7856
824.122	66.1221
827.503	66.0508
830.882	66.1966
834.261	65.7768
837.637	66.4456
841.013	66.3569
844.389	63.474
847.761	61.2895
851.131	60.712
854.503	57.8698
857.871	54.7037
861.24	53.3631
864.606	50.9905
867.97	49.292
871.336	46.0162
874.698	44.6104
878.058	43.5373
881.418	41.3158
884.778	41.5854
888.135	39.3495
891.49	37.3801
894.845	35.286
898.198	34.2559
901.55	32.5847
904.901	32.0205
908.25	32.7134
911.598	32.453
914.945	33.7484
918.291	33.9658
921.635	33.9925
924.978	33.6998
928.318	31.3724
931.659	32.6447
934.998	29.6407
938.336	29.5584
941.671	28.1921
945.007	27.1317
948.339	25.6024
951.672	26.3243
955.004	26.3879
958.333	25.1127
961.662	24.6011
964.989	25.0812
968.315	25.0196
971.639	25.1505
974.962	24.7491
978.285	24.1327
981.605	22.5897
984.924	21.7101
988.243	22.4406
991.56	22.0337
994.875	24.8881
998.188	27.3472
1001.5	30.8658
1004.81	36.7593
1008.12	40.8823
1011.43	44.1788
1014.74	49.5782
1018.05	52.9972
1021.35	55.6225
1024.65	59.7203
1027.96	63.1673
1031.26	67.2449
1034.56	67.2716
1037.86	67.8162
1041.16	67.8289
1044.45	68.0431
1047.75	67.2043
1051.04	64.4909
1054.33	60.7264
1057.62	55.4757
1060.91	50.8544
1064.2	45.351
1067.49	42.3044
1070.77	39.5223
1074.06	36.6775
1077.34	35.654
1080.62	35.456
1083.91	35.1726
1087.18	35.5272
1090.46	34.125
1093.74	34.2673
1097.02	36.8514
1100.29	38.4619
1103.56	39.299
1106.84	39.9283
1110.11	38.3798
1113.38	37.5526
1116.64	37.7571
1119.91	36.9886
1123.18	36.5795
1126.44	34.2588
1129.7	31.9878
1132.97	28.9427
1136.23	25.7147
1139.49	23.8223
1142.74	20.7167
1146	16.1788
1149.26	13.2769
1152.51	9.51071
1155.76	6.09654
1159.01	3.39891
1162.27	1.43712
1165.51	1.84636
1168.76	3.96043
1172.01	3.66324
1175.25	7.299
1178.5	5.92781
1181.74	6.44858
1184.98	6.29782
1188.22	6.63506
1191.46	7.33002
1194.7	8.56438
1197.94	8.93971
1201.17	10.3623
1204.41	11.2595
1207.64	12.4064
1210.87	13.6707
1214.1	16.0348
1217.33	17.7706
1220.56	21.4344
1223.79	23.7258
1227.01	25.458
1230.23	29.057
1233.46	32.36
1236.68	34.803
1239.9	36.6481
1243.12	41.6312
1246.34	45.743
1249.55	49.4486
1252.77	51.7012
1255.98	53.001
1259.2	55.554
1262.41	59.8667
1265.62	62.6118
1268.83	66.7208
1272.03	68.946
1275.24	73.4887
1278.45	75.9828
1281.65	77.7177
1284.85	79.4935
1288.06	81.3542
1291.26	82.4096
1294.46	85.2614
1297.66	86.7822
1300.85	88.5049
1304.05	88.7265
1307.24	88.4345
1310.43	87.5407
1313.63	84.3958
1316.82	81.2772
1320.01	79.5677
1323.2	76.5796
1326.38	73.7516
1329.57	71.2902
1332.76	66.9336
1335.94	62.7308
1339.12	61.3684
1342.3	59.6979
1345.48	55.9771
1348.66	52.4037
1351.84	48.9494
1355.01	45.4929
1358.19	41.6104
1361.36	39.8805
1364.53	36.4177
1367.71	34.2961
1370.88	33.0425
1374.04	32.7759
1377.21	31.1581
1380.38	30.0791
1383.54	28.7291
1386.71	27.0263
1389.87	24.9507
1393.03	23.1077
1396.19	22.9757
1399.35	20.8414
1402.51	22.2118
1405.67	25.3748
1408.82	28.5977
1411.98	32.3623
1415.13	38.5762
1418.28	47.0957
1421.43	53.8885
1424.58	61.9719
1427.73	71.382
1430.88	81.3513
1434.02	89.7683
1437.17	98.4824
1440.31	105.248
1443.45	109.065
1446.6	112.374
1449.74	115.306
1452.87	113.61
1456.01	112.475
1459.15	110.085
1462.28	105.813
1465.42	101.82
1468.55	96.8216
1471.68	88.1571
1474.81	81.4083
1477.94	74.0273
1481.07	68.1779
1484.2	62.5471
1487.32	58.0273
1490.45	52.3256
1493.57	49.9286
1496.69	46.9447
1499.81	45.0882
1502.93	41.9932
1506.05	39.3471
1509.17	35.5234
1512.28	31.3195
1515.4	26.5427
1518.51	21.8882
1521.63	18.8469
1524.74	17.0383
1527.85	13.6452
1530.96	12.8467
1534.06	13.7435
1537.17	14.2719
1540.28	15.4851
1543.38	16.9496
1546.48	16.4181
1549.59	16.9134
1552.69	18.5357
1555.79	18.5273
1558.88	21.7911
1561.98	25.2518
1565.08	28.7058
1568.17	32.0511
1571.27	38.094
1574.36	44.0071
1577.45	47.3066
1580.54	50.0299
1583.63	54.6271
1586.72	57.9349
1589.8	59.0765
1592.89	62.3079
1595.97	65.1102
1599.06	67.2386
1602.14	66.7137
1605.22	66.5516
1608.3	68.1005
1611.38	68.7496
1614.46	67.6488
1617.53	67.5824
1620.61	66.7666
1623.68	66.5567
1626.75	67.2343
1629.82	68.9027
1632.9	71.1893
1635.96	74.3814
1639.03	77.2957
1642.1	82.3721
1645.16	85.4084
1648.23	88.1496
1651.29	91.908
1654.36	93.4024
1657.42	95.1572
1660.48	94.4635
1663.53	92.413
1666.59	89.5899
1669.65	85.7636
1672.7	81.915
1675.76	75.6049
1678.81	68.927
1681.86	62.3865
1684.91	56.5429
1687.96	49.6524
1691.01	42.6134
1694.06	36.2986
1697.11	31.0898
1700.15	26.9651
1703.2	22.838
1706.24	21.1076
1709.28	17.5535
1712.32	15.0409
1715.36	13.5587
1718.4	12.7826
1721.43	10.325
1724.47	9.72488
1727.5	8.39328
1730.54	7.83914
1733.57	6.48022
1736.6	5.63152
1739.63	5.65822
1742.66	5.22072
1745.69	5.51714
1748.72	5.50055
1751.74	5.8111
1754.77	4.61267
1757.79	4.89537
1760.81	4.70938
1763.83	4.72361
1766.85	4.29724
1769.87	3.77467
1772.89	3.53284
1775.91	3.9114
1778.92	4.50584
1781.94	5.05088
1784.95	5.60449
1787.96	4.73415
1790.97	4.26461
1793.98	3.12064
1796.99	2.55158
1800	1.32592
1803	1.48449
1806.01	2.04647
1809.01	1.95937
1812.02	1.75169
1815.02	1.98899
1818.02	1.2095
1821.02	1.83818
1824.02	1.79147
1827.01	1.4691
1830.01	1.66803
1833	1.14933
1836	0.362536
1838.99	1.2533
1841.98	0.649725
1844.97	1.02118
1847.96	0.499754
1850.95	1.1846
1853.94	2.37602
1856.92	2.44175
1859.91	2.90213
1862.89	2.82543
1865.88	2.56028
1868.86	3.22826
1871.84	2.824
1874.82	4.35715
1877.8	5.6465
1880.77	6.32111
1882.51	6.92573
1885.5	7.76705
1888.48	8.59036
1891.47	8.56492
1894.46	9.26507
1897.44	10.1144
1900.42	10.81
1903.41	11.3897
1906.39	11.0835
1909.37	10.7882
1912.35	10.7624
1915.32	11.0093
1918.3	10.2526
1921.28	9.32462
1924.25	9.27426
1927.22	7.73526
1930.2	6.57523
1933.17	5.37296
1936.14	3.43002
1939.11	2.32253
1942.08	1.13566
1945.04	0.0365181
1948.01	0.407616
1950.97	0.945673
1953.94	-0.0147085
1956.9	0.226014
1959.86	0.0897062
1962.82	0.76866
1965.78	1.77436
1968.74	3.04757
1971.69	4.77912
1974.65	5.71042
1977.61	5.09545
1980.56	5.65115
1983.51	6.7361
1986.46	6.58429
1989.41	7.07796
1992.36	6.67864
1995.31	6.59939
1998.26	6.85086
2001.2	5.50148
2004.15	4.38135
2007.09	5.30349
2010.04	5.26668
2012.98	4.91081
2015.92	4.34763
2018.86	4.87023
2021.8	4.13082
2024.74	4.62203
2027.67	5.63674
2030.61	6.77619
2033.54	7.33753
2036.47	10.0912
2039.41	11.2318
2042.34	13.5742
2045.27	15.2702
2048.2	16.1509
2051.12	17.1285
2054.05	19.3424
2056.98	19.8741
2059.9	20.9952
2062.82	22.16
2065.75	22.348
2068.67	23.2221
2071.59	24.3433
2074.51	25.4337
2077.43	26.9275
2080.34	27.9804
2083.26	28.89
2086.17	30.725
2089.09	32.2551
2092	34.5796
2094.91	36.8111
2097.82	40.5161
2100.73	43.1233
2103.64	46.6082
2106.55	50.4788
2109.46	53.868
2112.36	57.0408
2115.27	60.5306
2118.17	63.5507
2121.07	66.6306
2123.97	72.1033
2126.87	77.0389
2129.77	81.7343
2132.67	85.2507
2135.57	91.0461
2138.46	95.871
2141.36	101.638
2144.25	106.478
2147.14	110.706
2150.03	114.75
2152.92	118.632
2155.81	122.744
2158.7	125.137
2161.59	127.392
2164.48	129.338
2167.36	130.009
2170.25	129.513
2173.13	128.924
2176.01	126.728
2178.89	123.641
2181.77	120.259
2184.65	117.536
2187.53	112.962
2190.41	109.357
2193.28	106.045
2196.16	102.788
2199.03	98.4491
2201.9	93.3162
2204.78	89.4968
2207.65	86.3681
2210.51	82.1652
2213.38	78.6378
2216.25	75.3714
2219.12	71.348
2221.98	67.4637
2224.85	63.2346
2227.71	59.6009
2230.57	55.3316
2233.43	51.9992
2236.29	48.5724
2239.15	45.7522
2242.01	44.2237
2244.87	40.8436
2247.73	38.167
2250.58	35.8657
2253.43	34.1893
2256.29	30.83
2259.14	29.0117
2261.99	27.476
2264.84	26.654
2267.69	27.2236
2270.54	25.8059
2273.38	24.8668
2276.23	25.2152
2279.07	24.3929
2281.92	22.6451
2284.76	22.3034
2287.6	21.3074
2290.44	18.1046
2293.28	15.0169
2296.12	14.9042
2298.96	14.4308
2301.79	14.7243
2304.63	14.5295
2307.46	13.6177
2310.3	14.215
2313.13	13.1951
2315.96	12.3341
2318.79	11.5467
2321.62	10.4408
2324.45	9.68749
2327.27	8.69217
2330.1	8.07482
2332.93	7.68915
2335.75	7.91201
2338.57	6.88519
2341.4	6.26735
2344.22	6.03919
2347.04	5.51208
2349.86	4.21319
2352.67	3.22041
2355.49	2.94778
2358.31	1.73463
2361.12	1.24042
2363.94	2.61105
2366.75	3.78055
2369.56	4.20492
2372.37	5.35186
2375.18	6.0143
2377.99	7.06687
2380.8	7.21342
2383.61	8.34871
2386.41	8.92542
2389.22	8.84641
2392.02	9.1383
2394.82	8.12991
2397.63	7.63295
2400.43	6.101
2403.23	6.49282
2406.02	6.86602
2408.82	6.90974
2411.62	6.61829
2414.41	6.04363
2417.21	5.65168
2420	4.60475
2422.79	5.26181
2425.59	5.21137
2428.38	4.91767
2431.17	4.74149
2433.96	3.89219
2436.74	4.5345
2439.53	5.08006
2442.32	5.85755
2445.1	6.28106
2447.88	7.64526
2450.67	7.70347
2453.45	9.10282
2456.23	9.07886
2459.01	8.78808
2461.79	7.29167
2464.57	7.08821
2467.34	7.59075
2470.12	7.30018
2472.89	6.95321
2475.67	6.27313
2478.44	6.20313
2481.21	4.4968
2483.98	3.30584
2486.75	3.03512
2489.52	2.3778
2492.29	2.05513
2495.06	-0.174363
2497.82	-1.27375
2500.59	-1.19492
2503.35	-1.3717
2506.11	-0.707525
2508.88	0.409054
2511.63	-0.414283
2514.39	0.973969
2517.15	1.8222
2519.91	2.29451
2522.67	3.2262
2525.42	3.7058
2528.18	4.83757
2530.93	5.46168
2533.69	6.65472
2536.44	6.97009
2539.19	6.43623
2541.94	7.50226
2544.69	8.38543
2547.44	7.74691
2550.18	6.85273
2552.93	6.88303
2555.68	6.463
2558.42	6.65569
2561.16	5.67263
2563.9	4.96441
2566.64	4.88611
2569.38	4.92004
2572.12	5.58715
2574.86	5.4606
2577.6	3.63723
2580.34	2.78179
2583.07	2.7033
2585.81	2.84525
2588.54	1.98248
2591.27	2.51879
2594	2.38281
2596.73	2.08685
2599.46	1.21256
2602.19	1.14703
2604.92	0.343477
2607.64	1.07756
2610.37	1.57696
2613.09	1.64809
2615.82	1.67583
2618.54	2.446
2621.26	3.67843
2623.98	5.14858
2626.7	5.61424
2629.42	6.00382
2632.14	6.51898
2634.86	7.22241
2637.57	8.95302
2640.29	9.03536
2643	9.01389
2645.72	8.70664
2648.43	9.34282
2651.14	9.17678
2653.85	9.08536
2656.56	8.3148
2659.27	7.87712
2661.97	7.32388
2664.68	6.74226
2667.38	5.45194
2670.09	5.06645
2672.79	5.08248
2675.49	5.61937
2678.2	5.62095
2680.89	5.57621
2683.59	7.18824
2686.29	7.06501
2688.99	7.84094
2691.69	8.9455
2694.38	10.3931
2697.08	11.1263
2699.77	12.7537
2702.46	14.3638
2705.16	15.1245
2707.85	15.0488
2710.54	15.9017
2713.23	16.7745
2715.92	17.6906
2718.6	17.9367
2721.29	18.1067
2723.97	19.0351
2726.66	18.2126
2729.34	17.983
2732.02	16.6597
2734.7	14.662
2737.39	13.9794
2740.06	13.9685
2742.74	13.0594
2745.42	11.299
2748.1	10.5344
2750.77	9.69952
2753.45	8.81824
2756.12	7.65888
2758.79	6.30535
2761.47	4.32274
2764.14	4.4378
2766.81	3.44302
2769.48	1.84922
2772.14	0.548183
2774.81	1.1875
2777.48	2.36703
2780.14	3.54367
2782.81	2.68664
2785.47	2.40622
2788.13	3.4784
2790.79	3.14979
2793.46	3.47393
2796.11	3.12278
2798.77	2.82469
2801.43	3.29287
2804.09	4.66558
2806.74	4.66936
2809.4	4.83321
2812.05	4.20536
2814.71	4.7866
2817.36	6.22609
2820.01	8.74637
2822.66	12.9689
2825.31	18.6237
2827.96	25.8272
2830.61	33.8335
2833.25	40.9909
2835.9	49.8313
2838.54	58.7057
2841.18	67.1723
2843.83	76.384
2846.47	85.1823
2849.11	94.1363
2851.75	106.06
2854.39	115.363
2857.03	123.511
2859.67	132.431
2862.3	140.086
2864.94	146.344
2867.57	152.031
2870.21	157.665
2872.84	161.057
2875.47	164.101
2878.1	168.137
2880.73	171.698
2883.36	176.294
2885.99	181.574
2888.61	186.297
2891.24	191.832
2893.87	197.183
2896.49	201.794
2899.11	207.628
2901.74	213.304
2904.36	221.427
2906.98	228.037
2909.6	236.642
2912.22	246.695
2914.83	256.663
2917.45	265.593
2920.07	272.51
2922.68	278.232
2925.3	281.771
2927.91	284.705
2930.52	285
2933.13	284.218
2935.74	282.067
2938.35	276.939
2940.96	270.873
2943.57	263.492
2946.18	254.989
2948.78	246.457
2951.39	237.372
2953.99	226.367
2956.6	214.473
2959.2	201.622
2961.8	190.812
2964.4	179.62
2967	168.469
2969.6	158.029
2972.2	149.4
2974.79	140.51
2977.39	130.223
2979.98	120.211
2982.58	109.841
2985.17	99.9876
2987.76	90.017
2990.36	79.7076
2992.95	71.217
2995.54	63.2366
2998.12	55.1888
3000.71	48.3262
3003.3	40.5778
3005.88	34.8389
3008.47	29.0384
3011.05	24.3715
3013.64	20.5805
3016.22	16.9514
3018.8	12.8991
3021.38	9.70686
3023.96	7.53051
3026.54	7.11461
3029.12	5.84272
3031.69	6.32151
3034.27	6.99237
3036.85	8.51134
3039.42	9.35348
3041.99	9.98004
3044.57	11.3363
3047.14	12.3795
3049.71	12.462
3052.28	12.6847
3054.85	12.4105
3057.42	12.5701
3059.98	11.8884
3062.55	10.5583
3065.11	9.06441
3067.68	7.04886
3070.24	6.60697
3072.8	6.18519
3075.37	4.51746
3077.93	2.91459
3080.49	1.74139
3083.05	-0.0457121
3085.61	-0.262751
3088.16	0.710489
3090.72	0.65379
3093.27	0.331662
3095.83	0.932006
3098.38	2.56153
3100.94	2.3812
3103.49	2.14975
3106.04	2.90067
3108.59	3.5246
3111.14	2.79059
3113.69	2.2246
3116.23	2.03814
3118.78	1.64091
3121.33	2.5608
3123.87	2.55433
3126.42	3.7402
3128.96	4.77441
3131.5	5.81681
3134.04	7.85437
3136.58	8.88658
3139.12	11.1037
3141.66	14.1964
3144.2	18.4798
3146.74	23.1256
3149.27	26.0186