File: data/Raman/poly_smoothed/Mb_50_18_13_1x_45s_532 nm_x100_100%_600 gr_mm_01.txt
#Acq. time (s)=	45
#Accumulations=	2
#Range (cm-¹)=	200...3150
#Windows=	2
#Auto scanning=	Off
#Autofocus=	Off
#Macrospot=	Off
#AutoExposure=	Off
#Spike filter=	Multiple accum.
#Delay time (s)=	0
#Binning=	1
#Readout mode=	Signal
#DeNoise=	Off
#ICS correction=	On
#Dark correction=	Off
#Inst. Process=	Off
#Detector Gain=	Best Dynamic Range
#Detector ADC=	20 kHz
#Detector temperature (°C)=	-69.85
#Instrument=	LabRAM HR Evol
#Detector=	Synapse
#Objective=	x100
#Grating=	600 gr/mm
#ND Filter=	100%
#Laser (nm)=	532
#Hole=	100.021
#Range=	Auto
#Laser Pol.=	No
#Raman. Pol.=	No
#Laser Pol. (°)=	-0.0007625
#Raman Pol. (°)=	89.9995
#Collection=	Microscope
#StageXY=	Marzhauser
#StageZ=	Marzhauser
#X (µm)=	19300.1
#Y (µm)=	3092.2
#Z (µm)=	1046.85
#Full time(mm:ss)=	3:18
#Project=
#Sample=
#Site=
#Title=	Mb_50_18_13_2x_45s_532 nm_x100_100%_600 gr_mm
#Remark=
#Date=	12.07.2022 11:13
#Acquired=	12.07.2022 11:13:15
#Base:Fit=	10.08.2022 10:49:18
#Base:Sub=	10.08.2022 10:49:30
#Filter:Polynom=	16.08.2022 10:14:59
#AxisType[0]=Intens
#AxisUnit[0]=Cnt
#AxisType[1]=Spectr
#AxisUnit[1]=1/cm
200.388	7.14518
204.019	5.40286
207.646	4.41854
211.274	3.75508
214.899	3.95602
218.524	4.55374
222.146	5.92924
225.766	6.2978
229.388	6.5286
233.005	5.52395
236.621	5.85722
240.236	6.25412
243.852	6.40088
247.464	5.67535
251.074	6.02432
254.683	5.86079
258.291	5.21723
261.897	4.77032
265.504	4.45764
269.108	2.60622
272.71	2.22266
276.311	4.40981
279.91	4.135
283.508	3.75979
287.105	4.27898
290.698	4.36321
294.291	4.99536
297.884	6.00458
301.475	8.46532
305.064	10.6751
308.652	10.8013
312.237	11.138
315.822	10.1227
319.406	10.9912
322.987	12.9606
326.568	14.8488
330.148	12.7665
333.724	10.8201
337.301	11.1854
340.875	11.2561
344.449	9.85449
348.02	8.12489
351.592	9.81595
355.16	11.2844
358.728	14.784
362.294	17.348
365.858	18.9609
369.422	19.2451
372.983	22.8052
376.543	25.3157
380.102	26.8006
383.661	29.1558
387.216	29.6393
390.771	29.6421
394.324	27.1789
397.875	26.1501
401.425	25.6818
404.974	24.1419
408.524	22.4702
412.07	17.5212
415.614	13.0206
419.156	9.4698
422.698	7.71125
426.238	5.51703
429.777	2.87696
433.315	2.06492
436.852	2.34458
440.387	1.80718
443.919	2.33966
447.451	2.48247
450.982	4.59559
454.512	5.32483
458.038	7.04483
461.565	9.56623
465.091	10.5215
468.613	11.5423
472.136	12.8991
475.655	14.0067
479.176	15.6772
482.692	18.1836
486.21	21.3227
489.724	23.3135
493.237	25.3827
496.75	26.6862
500.26	28.4347
503.771	31.4498
507.279	31.2009
510.785	32.8407
514.289	32.3776
517.793	34.9733
521.297	34.7986
524.797	32.2051
528.297	30.1284
531.795	29.69
535.291	26.8996
538.787	24.6998
542.281	20.7532
545.773	16.3634
549.264	13.4651
552.754	11.1098
556.243	8.01207
559.73	5.64977
563.216	5.25873
566.701	5.00828
570.182	5.16288
573.664	6.11626
577.145	7.44481
580.624	7.07476
584.1	6.33595
587.577	7.80026
591.052	7.71119
594.524	8.40424
597.997	10.5613
601.466	12.9905
604.936	13.2557
608.403	11.7234
611.87	12.2646
615.334	13.1364
618.799	13.5679
622.26	12.6566
625.72	11.7847
629.181	12.2818
632.638	13.0202
636.095	14.5181
639.551	13.4098
643.005	13.9821
646.457	16.1217
649.908	16.227
653.357	18.0993
656.806	20.6472
660.253	20.7036
663.7	21.8801
667.145	22.1944
670.588	22.112
674.027	24.0009
677.468	24.2075
680.907	26.5271
684.345	27.8105
687.781	27.6959
691.216	27.95
694.65	28.5771
698.081	31.1992
701.512	31.1961
704.942	33.2924
708.371	33.7205
711.796	34.4324
715.222	36.7568
718.645	36.8533
722.068	37.6208
725.49	37.3125
728.909	40.0447
732.329	39.9929
735.745	43.1985
739.16	46.0881
742.576	49.6485
745.988	54.3375
749.401	58.8878
752.811	61.5167
756.22	67.1283
759.627	71.0482
763.035	75.3681
766.44	79.451
769.843	81.3305
773.245	83.8305
776.646	85.9619
780.046	86.5411
783.444	88.5921
786.841	90.5157
790.237	88.7496
793.631	86.8436
797.024	85.9943
800.416	84.8832
803.807	83.2775
807.196	79.6736
810.584	78.8888
813.971	76.8756
817.354	75.9103
820.739	76.7868
824.122	76.3165
827.503	76.2231
830.882	73.8191
834.261	71.6742
837.637	72.0565
841.013	70.4995
844.389	68.1241
847.761	65.0316
851.131	62.4855
854.503	59.9166
857.871	56.8633
861.24	55.2012
864.606	53.2318
867.97	52.8538
871.336	50.1203
874.698	47.9894
878.058	46.7248
881.418	45.7541
884.778	43.6509
888.135	42.0578
891.49	41.7711
894.845	41.6451
898.198	40.7248
901.55	40.4811
904.901	39.8756
908.25	39.0896
911.598	37.9604
914.945	37.861
918.291	39.8857
921.635	39.2617
924.978	38.1889
928.318	35.3306
931.659	33.7328
934.998	33.3602
938.336	32.8702
941.671	32.4604
945.007	33.1105
948.339	32.2666
951.672	33.0537
955.004	32.6802
958.333	30.3154
961.662	28.1326
964.989	28.2814
968.315	27.3204
971.639	28.0576
974.962	26.5819
978.285	24.2416
981.605	23.1232
984.924	22.6516
988.243	20.8252
991.56	19.5836
994.875	20.2181
998.188	21.7836
1001.5	22.932
1004.81	24.6856
1008.12	25.5826
1011.43	26.273
1014.74	30.0962
1018.05	32.7719
1021.35	35.3134
1024.65	37.9498
1027.96	40.9061
1031.26	40.3981
1034.56	40.3904
1037.86	38.1188
1041.16	36.9571
1044.45	36.4718
1047.75	36.5669
1051.04	37.6266
1054.33	35.0479
1057.62	32.8032
1060.91	31.4186
1064.2	30.5797
1067.49	30.4708
1070.77	28.6246
1074.06	30.51
1077.34	31.5783
1080.62	33.4334
1083.91	33.2076
1087.18	33.0587
1090.46	33.8369
1093.74	35.1727
1097.02	36.0804
1100.29	36.0588
1103.56	34.8238
1106.84	31.011
1110.11	28.6507
1113.38	26.3876
1116.64	23.5452
1119.91	20.098
1123.18	18.8883
1126.44	17.97
1129.7	16.0293
1132.97	13.1196
1136.23	9.66118
1139.49	9.02807
1142.74	8.18201
1146	5.8871
1149.26	4.44932
1152.51	2.34241
1155.76	2.2294
1159.01	0.211143
1162.27	-0.39466
1165.51	-0.186954
1168.76	0.334326
1172.01	0.624837
1175.25	1.63277
1178.5	1.81797
1181.74	3.47612
1184.98	3.50853
1188.22	6.17545
1191.46	7.32318
1194.7	7.85164
1197.94	7.70457
1201.17	8.22557
1204.41	8.38455
1207.64	7.00915
1210.87	8.44315
1214.1	8.5508
1217.33	12.0084
1220.56	13.2806
1223.79	15.149
1227.01	16.6657
1230.23	17.416
1233.46	18.2796
1236.68	20.3118
1239.9	21.3241
1243.12	22.397
1246.34	25.6091
1249.55	26.0998
1252.77	28.6065
1255.98	31.3266
1259.2	33.0781
1262.41	36.3324
1265.62	37.281
1268.83	39.8995
1272.03	42.7456
1275.24	44.772
1278.45	45.8755
1281.65	47.3734
1284.85	48.5441
1288.06	51.2269
1291.26	53.8444
1294.46	55.6106
1297.66	56.9831
1300.85	56.3452
1304.05	58.0563
1307.24	57.4174
1310.43	55.0039
1313.63	53.6423
1316.82	53.1665
1320.01	51.6958
1323.2	49.1897
1326.38	48.4489
1329.57	45.4077
1332.76	43.99
1335.94	43.3732
1339.12	43.2734
1342.3	42.1924
1345.48	41.2064
1348.66	41.5981
1351.84	39.8063
1355.01	37.5909
1358.19	35.4009
1361.36	34.183
1364.53	32.7251
1367.71	32.1815
1370.88	29.8887
1374.04	26.41
1377.21	25.2321
1380.38	24.833
1383.54	22.931
1386.71	19.8063
1389.87	19.7494
1393.03	18.3983
1396.19	17.0122
1399.35	16.5894
1402.51	19.3144
1405.67	21.0705
1408.82	24.4305
1411.98	27.8414
1415.13	32.2055
1418.28	35.9882
1421.43	42.0462
1424.58	48.2574
1427.73	54.2293
1430.88	59.5193
1434.02	64.1902
1437.17	69.2503
1440.31	72.3399
1443.45	73.4674
1446.6	74.1993
1449.74	72.4354
1452.87	73.062
1456.01	71.4975
1459.15	70.5632
1462.28	69.54
1465.42	66.2364
1468.55	62.8818
1471.68	58.1011
1474.81	56.1832
1477.94	51.8425
1481.07	47.2926
1484.2	42.9393
1487.32	39.7921
1490.45	37.5273
1493.57	36.1935
1496.69	31.8758
1499.81	30.0438
1502.93	27.7494
1506.05	25.2224
1509.17	23.4284
1512.28	20.2723
1515.4	16.3476
1518.51	13.2789
1521.63	12.4868
1524.74	12.7674
1527.85	11.2762
1530.96	11.8928
1534.06	13.0556
1537.17	12.9883
1540.28	14.2155
1543.38	14.0283
1546.48	15.2197
1549.59	16.1866
1552.69	16.9701
1555.79	17.0911
1558.88	18.4921
1561.98	19.8264
1565.08	24.1657
1568.17	28.2747
1571.27	29.9534
1574.36	30.9957
1577.45	33.305
1580.54	37.1236
1583.63	37.9957
1586.72	39.2405
1589.8	40.7397
1592.89	43.6574
1595.97	45.1989
1599.06	45.0938
1602.14	43.2053
1605.22	41.439
1608.3	40.9609
1611.38	39.7181
1614.46	40.4989
1617.53	40.1126
1620.61	39.9469
1623.68	41.6311
1626.75	43.2438
1629.82	44.5392
1632.9	46.3099
1635.96	48.0134
1639.03	51.1351
1642.1	54.9774
1645.16	54.186
1648.23	54.6566
1651.29	57.1478
1654.36	58.0616
1657.42	59.8521
1660.48	57.4602
1663.53	56.7237
1666.59	54.8186
1669.65	52.2302
1672.7	49.5398
1675.76	45.9122
1678.81	42.9332
1681.86	39.2759
1684.91	36.6985
1687.96	34.286
1691.01	30.9576
1694.06	28.4218
1697.11	25.5542
1700.15	23.4778
1703.2	22.3787
1706.24	20.6199
1709.28	18.9598
1712.32	17.1937
1715.36	15.899
1718.4	14.2871
1721.43	13.184
1724.47	12.1036
1727.5	10.2615
1730.54	8.7281
1733.57	7.34545
1736.6	6.71499
1739.63	6.86247
1742.66	6.37029
1745.69	6.29607
1748.72	6.44136
1751.74	5.87912
1754.77	5.02836
1757.79	4.36178
1760.81	4.04933
1763.83	3.98463
1766.85	4.21684
1769.87	3.54993
1772.89	3.95522
1775.91	4.47741
1778.92	5.03257
1781.94	5.11442
1784.95	5.66294
1787.96	4.76169
1790.97	4.26453
1793.98	3.52031
1796.99	3.31301
1800	3.56837
1803	4.06539
1806.01	4.33223
1809.01	5.0726
1812.02	3.48574
1815.02	4.19315
1818.02	4.41542
1821.02	4.22058
1824.02	4.34758
1827.01	2.61061
1830.01	3.00909
1833	3.58393
1836	4.19935
1838.99	4.51632
1841.98	4.39113
1844.97	4.77565
1847.96	4.99944
1850.95	4.46457
1853.94	5.18669
1856.92	5.98692
1859.91	6.25999
1862.89	7.2296
1865.88	8.08757
1868.86	9.3575
1871.84	11.2001
1874.82	11.0805
1877.8	11.2422
1880.77	11.5214
1882.51	11.1462
1885.5	10.8209
1888.48	10.8263
1891.47	10.6664
1894.46	9.58805
1897.44	9.34495
1900.42	8.96109
1903.41	10.5003
1906.39	9.64881
1909.37	10.5326
1912.35	9.55937
1915.32	8.62412
1918.3	7.32237
1921.28	6.56055
1924.25	5.70498
1927.22	4.32675
1930.2	3.06248
1933.17	4.0104
1936.14	4.04556
1939.11	2.64524
1942.08	2.34126
1945.04	2.60295
1948.01	1.95901
1950.97	2.29511
1953.94	1.8679
1956.9	2.15376
1959.86	3.26698
1962.82	3.83148
1965.78	4.89587
1968.74	5.31556
1971.69	7.23376
1974.65	8.9112
1977.61	10.1027
1980.56	10.1187
1983.51	9.90461
1986.46	10.056
1989.41	9.92491
1992.36	10.4054
1995.31	10.1619
1998.26	8.72942
2001.2	8.29774
2004.15	8.68402
2007.09	8.99522
2010.04	8.05981
2012.98	7.3217
2015.92	8.26328
2018.86	8.79265
2021.8	8.01391
2024.74	8.45395
2027.67	9.33654
2030.61	8.72407
2033.54	10.0218
2036.47	9.23164
2039.41	9.9959
2042.34	9.36918
2045.27	9.49127
2048.2	9.19538
2051.12	10.3453
2054.05	10.7382
2056.98	13.0636
2059.9	14.5274
2062.82	15.7687
2065.75	16.3164
2068.67	15.7966
2071.59	16.8017
2074.51	19.1233
2077.43	20.413
2080.34	21.4646
2083.26	22.5856
2086.17	23.2629
2089.09	25.2949
2092	25.8617
2094.91	26.4634
2097.82	27.7072
2100.73	29.5212
2103.64	29.9493
2106.55	31.3783
2109.46	32.2216
2112.36	35.1277
2115.27	38.167
2118.17	40.4569
2121.07	43.726
2123.97	47.1098
2126.87	50.0369
2129.77	53.5268
2132.67	56.3457
2135.57	59.8999
2138.46	62.6851
2141.36	65.7215
2144.25	68.2348
2147.14	71.735
2150.03	73.0424
2152.92	75.6623
2155.81	77.7221
2158.7	79.3028
2161.59	80.7522
2164.48	80.9235
2167.36	82.3742
2170.25	81.6737
2173.13	81.5833
2176.01	81.8295
2178.89	81.0768
2181.77	80.7065
2184.65	79.6845
2187.53	79.3426
2190.41	76.6314
2193.28	74.5301
2196.16	72.5973
2199.03	71.0414
2201.9	68.4108
2204.78	65.7777
2207.65	63.1185
2210.51	59.0403
2213.38	56.2064
2216.25	54.1381
2219.12	52.3391
2221.98	48.7691
2224.85	46.3738
2227.71	44.7207
2230.57	42.6062
2233.43	38.6175
2236.29	37.2411
2239.15	34.9407
2242.01	32.2238
2244.87	30.0354
2247.73	28.5473
2250.58	27.0635
2253.43	26.4712
2256.29	27.0147
2259.14	25.5595
2261.99	24.2191
2264.84	23.5372
2267.69	22.2342
2270.54	20.7103
2273.38	19.5933
2276.23	18.0387
2279.07	16.9656
2281.92	15.6287
2284.76	15.5536
2287.6	12.4645
2290.44	11.1733
2293.28	9.16865
2296.12	8.7116
2298.96	9.65988
2301.79	8.2441
2304.63	8.2239
2307.46	7.26569
2310.3	5.98054
2313.13	6.62483
2315.96	8.15805
2318.79	8.09981
2321.62	8.31176
2324.45	9.30628
2327.27	10.241
2330.1	10.435
2332.93	9.849
2335.75	9.69751
2338.57	9.95291
2341.4	10.1486
2344.22	8.81549
2347.04	8.73619
2349.86	7.33026
2352.67	5.78231
2355.49	4.69207
2358.31	3.19501
2361.12	3.20503
2363.94	3.96961
2366.75	4.14753
2369.56	3.77999
2372.37	2.55913
2375.18	2.16559
2377.99	1.08798
2380.8	1.17449
2383.61	2.37863
2386.41	1.99602
2389.22	2.80618
2392.02	4.56549
2394.82	6.21339
2397.63	6.80611
2400.43	7.4494
2403.23	8.25464
2406.02	8.82485
2408.82	9.6683
2411.62	9.00377
2414.41	10.0345
2417.21	9.6667
2420	8.30927
2422.79	6.53804
2425.59	6.86179
2428.38	5.58077
2431.17	5.27441
2433.96	4.38692
2436.74	2.77581
2439.53	1.58378
2442.32	0.198924
2445.1	0.0839368
2447.88	-1.05127
2450.67	-0.872329
2453.45	0.822402
2456.23	-0.0146444
2459.01	0.921701
2461.79	0.673759
2464.57	0.698762
2467.34	0.770358
2470.12	-0.0389022
2472.89	0.722179
2475.67	1.9167
2478.44	1.47973
2481.21	2.53883
2483.98	2.72505
2486.75	1.43799
2489.52	2.40006
2492.29	2.98978
2495.06	3.06973
2497.82	2.85389
2500.59	3.67655
2503.35	2.40364
2506.11	2.32866
2508.88	3.0049
2511.63	3.68327
2514.39	2.0388
2517.15	1.85348
2519.91	1.50456
2522.67	1.60882
2525.42	1.40793
2528.18	1.66153
2530.93	1.90124
2533.69	2.9167
2536.44	3.10594
2539.19	4.73509
2541.94	6.72604
2544.69	6.01182
2547.44	6.40797
2550.18	7.15119
2552.93	7.72324
2555.68	8.25147
2558.42	8.07233
2561.16	8.16688
2563.9	7.39357
2566.64	6.06385
2569.38	6.29702
2572.12	5.97788
2574.86	5.57972
2577.6	4.72314
2580.34	2.35149
2583.07	1.7447
2585.81	2.44752
2588.54	3.00027
2591.27	2.83162
2594	3.03722
2596.73	2.765
2599.46	3.83471
2602.19	4.80232
2604.92	3.89629
2607.64	4.59841
2610.37	3.56216
2613.09	3.90625
2615.82	4.91812
2618.54	4.77804
2621.26	5.82363
2623.98	5.22208
2626.7	6.05381
2629.42	6.32996
2632.14	7.46952
2634.86	8.0116
2637.57	9.02176
2640.29	9.38403
2643	9.97677
2645.72	10.1615
2648.43	11.0623
2651.14	10.4778
2653.85	11.3115
2656.56	10.8724
2659.27	10.2071
2661.97	10.1758
2664.68	10.7316
2667.38	10.6107
2670.09	10.9399
2672.79	10.4406
2675.49	11.3657
2678.2	10.4838
2680.89	10.8503
2683.59	11.1028
2686.29	11.5587
2688.99	13.069
2691.69	13.3405
2694.38	14.1646
2697.08	15.4098
2699.77	15.6435
2702.46	16.3341
2705.16	16.3096
2707.85	16.2748
2710.54	16.3579
2713.23	16.9814
2715.92	16.8925
2718.6	17.5082
2721.29	18.6004
2723.97	18.79
2726.66	19.1932
2729.34	19.6446
2732.02	19.5792
2734.7	19.058
2737.39	19.3058
2740.06	18.6732
2742.74	18.5856
2745.42	17.2978
2748.1	15.3643
2750.77	14.2199
2753.45	13.373
2756.12	12.5649
2758.79	11.1736
2761.47	10.2123
2764.14	9.92626
2766.81	9.18267
2769.48	9.22627
2772.14	7.88856
2774.81	7.8215
2777.48	6.97622
2780.14	7.40234
2782.81	6.46043
2785.47	6.62775
2788.13	5.86422
2790.79	5.03847
2793.46	4.23311
2796.11	3.70134
2798.77	3.96127
2801.43	4.16818
2804.09	4.22129
2806.74	3.5163
2809.4	2.45042
2812.05	1.81549
2814.71	2.53627
2817.36	4.22126
2820.01	7.67703
2822.66	12.0256
2825.31	17.1471
2827.96	23.6434
2830.61	31.0926
2833.25	37.5662
2835.9	43.4921
2838.54	49.8906
2841.18	55.7097
2843.83	61.8685
2846.47	68.2074
2849.11	73.8432
2851.75	80.6565
2854.39	86.7132
2857.03	93.7831
2859.67	99.8826
2862.3	105.27
2864.94	109.599
2867.57	113.148
2870.21	115.693
2872.84	117.423
2875.47	120.405
2878.1	121.98
2880.73	125.032
2883.36	129.46
2885.99	133.41
2888.61	135.996
2891.24	140.473
2893.87	144.19
2896.49	146.742
2899.11	149.123
2901.74	154.124
2904.36	158.923
2906.98	163.416
2909.6	171.026
2912.22	177.939
2914.83	184.524
2917.45	192.667
2920.07	198.912
2922.68	203.59
2925.3	206.946
2927.91	208.317
2930.52	209.876
2933.13	209.807
2935.74	207.697
2938.35	205.913
2940.96	201.522
2943.57	196.102
2946.18	190.261
2948.78	183.756
2951.39	174.981
2953.99	165.63
2956.6	156.775
2959.2	146.977
2961.8	137.656
2964.4	128.758
2967	120.712
2969.6	112.204
2972.2	104.429
2974.79	97.2119
2977.39	89.9629
2979.98	84.1105
2982.58	76.9039
2985.17	70.0519
2987.76	62.387
2990.36	55.8093
2992.95	48.9201
2995.54	43.4282
2998.12	37.7817
3000.71	32.0725
3003.3	27.1633
3005.88	23.1862
3008.47	20.7046
3011.05	18.3443
3013.64	16.0534
3016.22	13.3139
3018.8	10.3699
3021.38	7.67683
3023.96	6.9618
3026.54	5.49503
3029.12	4.79871
3031.69	5.07755
3034.27	4.85553
3036.85	5.91766
3039.42	7.16215
3041.99	8.66923
3044.57	9.90666
3047.14	10.3631
3049.71	10.7529
3052.28	10.3871
3054.85	9.88485
3057.42	9.62863
3059.98	9.34854
3062.55	9.17356
3065.11	8.56203
3067.68	8.31024
3070.24	8.58466
3072.8	7.93795
3075.37	6.81192
3077.93	5.10015
3080.49	3.26199
3083.05	1.07724
3085.61	0.862475
3088.16	0.34379
3090.72	-0.144285
3093.27	0.242222
3095.83	-0.298253
3098.38	-0.492926
3100.94	0.499886
3103.49	1.58397
3106.04	2.73601
3108.59	2.09415
3111.14	2.37777
3113.69	2.63971
3116.23	3.75264
3118.78	4.19352
3121.33	5.17802
3123.87	5.80547
3126.42	6.33086
3128.96	7.26792
3131.5	8.70493
3134.04	8.61595
3136.58	9.95114
3139.12	10.6738
3141.66	11.3766
3144.2	12.5672
3146.74	14.607
3149.27	16.1319