File: data/Raman/poly_smoothed/Mb_50_18_28_1x_45s_532 nm_x100_100%_600 gr_mm_01.txt
#Acq. time (s)=	45
#Accumulations=	2
#Range (cm-¹)=	200...3150
#Windows=	2
#Auto scanning=	Off
#Autofocus=	Off
#Macrospot=	Off
#AutoExposure=	Off
#Spike filter=	Multiple accum.
#Delay time (s)=	0
#Binning=	1
#Readout mode=	Signal
#DeNoise=	Off
#ICS correction=	On
#Dark correction=	Off
#Inst. Process=	Off
#Detector Gain=	Best Dynamic Range
#Detector ADC=	20 kHz
#Detector temperature (°C)=	-69.85
#Instrument=	LabRAM HR Evol
#Detector=	Synapse
#Objective=	x100
#Grating=	600 gr/mm
#ND Filter=	100%
#Laser (nm)=	532
#Hole=	100.021
#Range=	Auto
#Laser Pol.=	No
#Raman. Pol.=	No
#Laser Pol. (°)=	-0.0007625
#Raman Pol. (°)=	89.9995
#Collection=	Microscope
#StageXY=	Marzhauser
#StageZ=	Marzhauser
#X (µm)=	28332.4
#Y (µm)=	-3279.5
#Z (µm)=	1041.35
#Full time(mm:ss)=	3:19
#Project=
#Sample=
#Site=
#Title=	Mb_50_18_28_2x_45s_532 nm_x100_100%_600 gr_mm
#Remark=
#Date=	12.07.2022 12:55
#Acquired=	12.07.2022 12:55:29
#Base:Fit=	10.08.2022 10:49:18
#Base:Sub=	10.08.2022 10:49:30
#Filter:Polynom=	16.08.2022 10:14:59
#AxisType[0]=Intens
#AxisUnit[0]=Cnt
#AxisType[1]=Spectr
#AxisUnit[1]=1/cm
200.388	17.7116
204.019	18.7431
207.646	18.6492
211.274	16.4585
214.899	15.1999
218.524	14.5622
222.146	10.7268
225.766	9.59925
229.388	6.85582
233.005	4.05179
236.621	4.15198
240.236	6.03388
243.852	5.7367
247.464	5.83697
251.074	4.15801
254.683	6.45458
258.291	9.63844
261.897	9.79951
265.504	11.0504
269.108	11.5729
272.71	11.8137
276.311	10.3358
279.91	8.75273
283.508	8.99552
287.105	10.0854
290.698	11.0739
294.291	12.9654
297.884	15.6629
301.475	18.503
305.064	21.9796
308.652	23.4142
312.237	25.8728
315.822	29.6419
319.406	33.187
322.987	36.9493
326.568	37.9593
330.148	35.5864
333.724	32.7944
337.301	28.622
340.875	25.8032
344.449	26.5364
348.02	27.1978
351.592	31.2744
355.16	38.165
358.728	48.9133
362.294	61.4905
365.858	75.4452
369.422	88.263
372.983	101.486
376.543	113.965
380.102	123.631
383.661	132.269
387.216	137.397
390.771	140.201
394.324	141.108
397.875	138.685
401.425	135.046
404.974	127.289
408.524	114.605
412.07	98.4887
415.614	78.9163
419.156	61.0888
422.698	42.9802
426.238	27.916
429.777	15.7532
433.315	7.38235
436.852	1.68447
440.387	1.45042
443.919	1.97021
447.451	3.00831
450.982	2.59628
454.512	2.29965
458.038	2.82415
461.565	3.23005
465.091	4.24732
468.613	5.0613
472.136	5.20954
475.655	7.72274
479.176	13.0557
482.692	20.9031
486.21	30.5576
489.724	41.4067
493.237	54.4635
496.75	67.8295
500.26	81.0819
503.771	92.3179
507.279	102.914
510.785	110.534
514.289	117.064
517.793	121.55
521.297	122.321
524.797	122.295
528.297	120.548
531.795	114.867
535.291	107.428
538.787	98.4489
542.281	88.9715
545.773	76.5071
549.264	63.276
552.754	50.0927
556.243	37.5507
559.73	28.9752
563.216	23.9106
566.701	19.0658
570.182	17.7276
573.664	18.9287
577.145	23.4608
580.624	28.1888
584.1	31.8209
587.577	32.3768
591.052	34.2709
594.524	35.0377
597.997	35.5267
601.466	35.5071
604.936	34.9547
608.403	36.3517
611.87	33.7659
615.334	31.0522
618.799	29.0062
622.26	24.9736
625.72	21.4878
629.181	18.8533
632.638	15.5627
636.095	11.2583
639.551	7.58201
643.005	6.65226
646.457	7.50636
649.908	7.29502
653.357	6.08199
656.806	6.82306
660.253	7.51902
663.7	9.1697
667.145	7.76371
670.588	7.21635
674.027	5.69788
677.468	6.75129
680.907	7.31557
684.345	8.10546
687.781	8.90259
691.216	10.4171
694.65	9.99511
698.081	11.3073
701.512	12.3356
704.942	15.3125
708.371	15.3033
711.796	17.3538
715.222	18.0848
718.645	17.5735
722.068	16.6014
725.49	17.5094
728.909	18.8306
732.329	21.5409
735.745	25.8752
739.16	36.4754
742.576	54.9024
745.988	78.1018
749.401	103.384
752.811	128.332
756.22	152.077
759.627	172.152
763.035	189.454
766.44	203.659
769.843	213.425
773.245	220.375
776.646	224.403
780.046	223.386
783.444	219.725
786.841	211.109
790.237	199.176
793.631	184.864
797.024	168.211
800.416	146.207
803.807	123.834
807.196	103.183
810.584	83.4803
813.971	66.0554
817.354	55.5781
820.739	51.8836
824.122	51.2517
827.503	52.5873
830.882	52.9156
834.261	51.0793
837.637	49.9498
841.013	46.6893
844.389	42.8376
847.761	39.7122
851.131	35.0295
854.503	32.1649
857.871	29.4597
861.24	25.0929
864.606	22.55
867.97	23.1671
871.336	22.0183
874.698	22.6992
878.058	22.6968
881.418	19.4592
884.778	18.6984
888.135	16.8024
891.49	16.5626
894.845	17.2852
898.198	17.0708
901.55	20.6948
904.901	21.236
908.25	23.0224
911.598	23.8338
914.945	26.4636
918.291	27.2253
921.635	28.1417
924.978	27.3712
928.318	26.5437
931.659	23.938
934.998	23.7211
938.336	21.7246
941.671	19.9941
945.007	18.5278
948.339	16.9988
951.672	16.2185
955.004	12.6282
958.333	10.225
961.662	6.07867
964.989	2.48661
968.315	-0.585833
971.639	-1.8557
974.962	-3.67025
978.285	-2.84538
981.605	-6.49482
984.924	-6.49777
988.243	-7.92111
991.56	-9.10534
994.875	-5.1206
998.188	1.31229
1001.5	11.7975
1004.81	24.6765
1008.12	39.4098
1011.43	56.3494
1014.74	74.9382
1018.05	92.3045
1021.35	108.282
1024.65	121.823
1027.96	134.031
1031.26	143.992
1034.56	149.876
1037.86	151.244
1041.16	149.32
1044.45	145.32
1047.75	138.596
1051.04	131.797
1054.33	125.87
1057.62	122.031
1060.91	117.895
1064.2	115.922
1067.49	116.645
1070.77	117.232
1074.06	121.087
1077.34	126.87
1080.62	133.581
1083.91	138.7
1087.18	140.653
1090.46	143.051
1093.74	144.186
1097.02	141.017
1100.29	135.906
1103.56	128.249
1106.84	119.072
1110.11	105.465
1113.38	88.4218
1116.64	72.643
1119.91	55.8276
1123.18	39.3474
1126.44	25.0043
1129.7	12.6439
1132.97	5.72039
1136.23	4.11382
1139.49	4.82704
1142.74	7.17877
1146	7.59302
1149.26	10.0583
1152.51	11.1689
1155.76	12.7384
1159.01	15.0478
1162.27	14.985
1165.51	16.5108
1168.76	18.5979
1172.01	24.1899
1175.25	24.7725
1178.5	27.0849
1181.74	29.1478
1184.98	30.132
1188.22	30.7428
1191.46	29.0254
1194.7	29.6158
1197.94	30.5768
1201.17	30.628
1204.41	30.3874
1207.64	28.95
1210.87	28.4201
1214.1	29.9613
1217.33	30.8787
1220.56	31.5227
1223.79	31.9051
1227.01	33.0274
1230.23	34.1049
1233.46	33.9744
1236.68	33.9527
1239.9	35.2491
1243.12	36.0898
1246.34	37.6915
1249.55	38.0192
1252.77	38.3994
1255.98	37.5431
1259.2	37.424
1262.41	38.0628
1265.62	39.1994
1268.83	40.0469
1272.03	44.4371
1275.24	47.992
1278.45	53.0718
1281.65	53.5938
1284.85	54.688
1288.06	56.0182
1291.26	56.4818
1294.46	56.6266
1297.66	57.9025
1300.85	58.3357
1304.05	59.0545
1307.24	59.3881
1310.43	57.7315
1313.63	56.9222
1316.82	56.5862
1320.01	53.8784
1323.2	50.7517
1326.38	48.5053
1329.57	43.3079
1332.76	39.2625
1335.94	38.0195
1339.12	35.8105
1342.3	33.8209
1345.48	33.8884
1348.66	33.8027
1351.84	31.4889
1355.01	29.4593
1358.19	27.7155
1361.36	25.1369
1364.53	23.4859
1367.71	23.19
1370.88	22.815
1374.04	23.1281
1377.21	21.8623
1380.38	21.7769
1383.54	20.4857
1386.71	21.6826
1389.87	21.903
1393.03	22.4457
1396.19	20.7098
1399.35	21.9109
1402.51	25.7928
1405.67	29.4245
1408.82	35.703
1411.98	42.1196
1415.13	49.2901
1418.28	57.6374
1421.43	64.8935
1424.58	72.2022
1427.73	79.5317
1430.88	85.9524
1434.02	93.5865
1437.17	97.8275
1440.31	100.673
1443.45	102.605
1446.6	103.113
1449.74	101.38
1452.87	98.0612
1456.01	94.1074
1459.15	90.4377
1462.28	85.4944
1465.42	79.998
1468.55	74.2613
1471.68	66.046
1474.81	59.6155
1477.94	55.7386
1481.07	49.7433
1484.2	46.0145
1487.32	41.9722
1490.45	36.7012
1493.57	33.6024
1496.69	29.2925
1499.81	25.4841
1502.93	23.9551
1506.05	21.0481
1509.17	17.3685
1512.28	13.3544
1515.4	8.58777
1518.51	6.54279
1521.63	4.33771
1524.74	3.5458
1527.85	3.02164
1530.96	3.56658
1534.06	4.75364
1537.17	5.35225
1540.28	7.69052
1543.38	8.42503
1546.48	8.67153
1549.59	10.3045
1552.69	12.962
1555.79	14.9069
1558.88	16.2691
1561.98	19.8078
1565.08	22.5483
1568.17	25.834
1571.27	30.0458
1574.36	32.292
1577.45	35.8571
1580.54	39.0256
1583.63	40.7854
1586.72	43.1426
1589.8	45.0227
1592.89	44.5792
1595.97	45.9844
1599.06	47.1484
1602.14	46.8633
1605.22	47.8382
1608.3	48.2557
1611.38	47.9057
1614.46	47.8844
1617.53	49.4494
1620.61	49.7641
1623.68	53.1127
1626.75	55.2852
1629.82	55.6883
1632.9	58.6359
1635.96	62.7626
1639.03	67.2915
1642.1	71.0504
1645.16	74.132
1648.23	75.336
1651.29	76.9259
1654.36	77.7383
1657.42	77.6537
1660.48	76.6084
1663.53	71.7993
1666.59	67.0929
1669.65	62.3006
1672.7	56.6083
1675.76	51.8313
1678.81	44.8617
1681.86	39.5012
1684.91	32.15
1687.96	26.074
1691.01	22.8187
1694.06	18.0918
1697.11	13.4369
1700.15	9.44527
1703.2	4.89621
1706.24	2.30084
1709.28	0.95482
1712.32	0.529627
1715.36	0.269237
1718.4	0.0754764
1721.43	0.231629
1724.47	0.00791004
1727.5	2.01178
1730.54	2.01874
1733.57	1.8382
1736.6	2.79641
1739.63	3.70286
1742.66	3.77046
1745.69	3.90086
1748.72	4.7772
1751.74	4.81202
1754.77	5.23206
1757.79	6.33245
1760.81	7.95818
1763.83	8.81884
1766.85	8.5016
1769.87	9.26365
1772.89	10.545
1775.91	10.5092
1778.92	11.5995
1781.94	13.5626
1784.95	14.3518
1787.96	15.5901
1790.97	16.3639
1793.98	17.6299
1796.99	18.7065
1800	19.1656
1803	18.9615
1806.01	17.7949
1809.01	18.2033
1812.02	17.9853
1815.02	18.7792
1818.02	17.475
1821.02	18.2833
1824.02	17.4551
1827.01	16.6155
1830.01	16.8027
1833	16.9402
1836	16.4931
1838.99	15.7199
1841.98	16.6239
1844.97	16.8381
1847.96	16.6456
1850.95	16.1942
1853.94	16.1539
1856.92	15.1264
1859.91	14.6354
1862.89	14.5554
1865.88	15.3373
1868.86	15.1565
1871.84	14.0585
1874.82	13.4595
1877.8	13.5328
1880.77	13.9736
1882.51	14.8424
1885.5	15.8469
1888.48	16.7013
1891.47	16.8115
1894.46	18.1417
1897.44	18.4481
1900.42	19.3765
1903.41	18.6543
1906.39	17.9475
1909.37	18.1647
1912.35	18.5301
1915.32	17.2787
1918.3	15.8935
1921.28	15.5669
1924.25	13.7737
1927.22	12.514
1930.2	11.0567
1933.17	9.4558
1936.14	8.05819
1939.11	5.35345
1942.08	4.07369
1945.04	2.34925
1948.01	2.86839
1950.97	2.48272
1953.94	2.00623
1956.9	1.12802
1959.86	3.09112
1962.82	3.78222
1965.78	5.13629
1968.74	7.40538
1971.69	7.28362
1974.65	7.51581
1977.61	7.14082
1980.56	7.55711
1983.51	7.81231
1986.46	8.46675
1989.41	8.0567
1992.36	8.35611
1995.31	8.82245
1998.26	8.28472
2001.2	7.8143
2004.15	8.3317
2007.09	7.3273
2010.04	5.08835
2012.98	4.07266
2015.92	4.94245
2018.86	6.00173
2021.8	5.80566
2024.74	5.05001
2027.67	4.50475
2030.61	6.05629
2033.54	6.87862
2036.47	7.37859
2039.41	8.25206
2042.34	8.23485
2045.27	8.55213
2048.2	9.28832
2051.12	9.68833
2054.05	9.95858
2056.98	11.4204
2059.9	12.204
2062.82	12.4606
2065.75	16.1291
2068.67	17.5233
2071.59	19.0091
2074.51	20.8697
2077.43	21.5589
2080.34	22.3653
2083.26	24.8726
2086.17	28.7199
2089.09	32.0495
2092	32.8364
2094.91	35.5208
2097.82	37.0907
2100.73	39.9228
2103.64	41.4125
2106.55	44.9759
2109.46	48.7254
2112.36	52.6353
2115.27	54.3057
2118.17	57.4343
2121.07	61.1308
2123.97	64.2067
2126.87	67.6816
2129.77	70.6557
2132.67	73.9761
2135.57	78.1964
2138.46	83.581
2141.36	88.3188
2144.25	91.1668
2147.14	95.0388
2150.03	97.3375
2152.92	100.804
2155.81	103.176
2158.7	106.705
2161.59	108.172
2164.48	109.008
2167.36	109.841
2170.25	109.209
2173.13	109.293
2176.01	109.502
2178.89	107.965
2181.77	105.462
2184.65	102.729
2187.53	100.347
2190.41	97.9184
2193.28	94.0015
2196.16	91.0885
2199.03	87.3563
2201.9	83.0763
2204.78	80.0881
2207.65	76.5892
2210.51	73.0644
2213.38	68.3343
2216.25	64.8265
2219.12	61.9453
2221.98	58.3881
2224.85	55.371
2227.71	54.499
2230.57	52.48
2233.43	50.0575
2236.29	47.0136
2239.15	43.5001
2242.01	40.6554
2244.87	38.0088
2247.73	34.991
2250.58	33.1139
2253.43	31.0231
2256.29	29.5854
2259.14	27.0729
2261.99	25.6895
2264.84	25.1651
2267.69	23.7296
2270.54	22.0937
2273.38	21.0424
2276.23	19.9483
2279.07	18.2103
2281.92	17.4997
2284.76	17.8558
2287.6	17.1503
2290.44	16.8766
2293.28	16.3548
2296.12	16.4214
2298.96	16.4007
2301.79	15.5354
2304.63	14.7629
2307.46	13.7788
2310.3	12.6202
2313.13	11.9748
2315.96	11.5553
2318.79	10.6153
2321.62	9.65542
2324.45	8.48531
2327.27	7.65779
2330.1	6.7702
2332.93	7.26006
2335.75	5.8784
2338.57	4.98854
2341.4	4.8802
2344.22	4.19252
2347.04	4.14002
2349.86	3.38945
2352.67	3.59295
2355.49	2.60896
2358.31	1.60032
2361.12	1.18222
2363.94	0.811152
2366.75	1.39377
2369.56	-0.439523
2372.37	0.754182
2375.18	0.896271
2377.99	1.0636
2380.8	-0.144092
2383.61	-0.818245
2386.41	-0.354927
2389.22	-0.806693
2392.02	-0.619545
2394.82	-1.50871
2397.63	-0.81976
2400.43	-0.0676977
2403.23	-0.370708
2406.02	0.259391
2408.82	1.792
2411.62	3.12076
2414.41	6.12573
2417.21	7.37497
2420	8.23367
2422.79	8.09196
2425.59	9.04565
2428.38	10.6836
2431.17	10.7382
2433.96	10.7552
2436.74	10.2699
2439.53	10.7209
2442.32	11.5883
2445.1	11.2431
2447.88	10.6556
2450.67	9.88383
2453.45	10.084
2456.23	9.80352
2459.01	8.04594
2461.79	7.31087
2464.57	7.56198
2467.34	5.79221
2470.12	4.31803
2472.89	4.07214
2475.67	4.37249
2478.44	4.31511
2481.21	3.64853
2483.98	4.20634
2486.75	3.84074
2489.52	3.53552
2492.29	4.06502
2495.06	4.71273
2497.82	4.51238
2500.59	4.38724
2503.35	4.8278
2506.11	5.39838
2508.88	7.15845
2511.63	7.37143
2514.39	7.73363
2517.15	7.91135
2519.91	7.61129
2522.67	7.15988
2525.42	7.45728
2528.18	7.68863
2530.93	7.9215
2533.69	6.94493
2536.44	6.74757
2539.19	7.85983
2541.94	7.06718
2544.69	6.39938
2547.44	5.73375
2550.18	5.46666
2552.93	5.51621
2555.68	4.54953
2558.42	4.25114
2561.16	4.19632
2563.9	2.86525
2566.64	2.0556
2569.38	2.09911
2572.12	2.9281
2574.86	3.2581
2577.6	3.26606
2580.34	1.26869
2583.07	1.4242
2585.81	0.836501
2588.54	1.19375
2591.27	0.586661
2594	0.759166
2596.73	1.138
2599.46	2.40994
2602.19	3.42215
2604.92	5.17662
2607.64	5.59044
2610.37	7.13044
2613.09	7.25045
2615.82	6.91797
2618.54	7.72207
2621.26	8.81331
2623.98	9.76311
2626.7	10.0348
2629.42	10.6651
2632.14	10.8886
2634.86	11.5513
2637.57	12.6802
2640.29	12.685
2643	12.5122
2645.72	12.1331
2648.43	12.395
2651.14	11.4957
2653.85	10.1146
2656.56	8.55812
2659.27	8.01343
2661.97	8.95775
2664.68	8.97501
2667.38	9.48754
2670.09	8.8529
2672.79	8.91437
2675.49	8.98882
2678.2	8.48899
2680.89	8.56198
2683.59	9.5844
2686.29	10.7927
2688.99	10.6428
2691.69	10.7749
2694.38	11.2167
2697.08	11.7105
2699.77	10.902
2702.46	11.2886
2705.16	12.0583
2707.85	13.1937
2710.54	13.9283
2713.23	13.4025
2715.92	13.527
2718.6	13.3854
2721.29	14.3702
2723.97	14.8557
2726.66	15.5068
2729.34	14.4237
2732.02	13.5148
2734.7	12.6003
2737.39	11.5916
2740.06	11.1273
2742.74	10.3542
2745.42	8.17206
2748.1	7.45538
2750.77	5.79275
2753.45	5.73467
2756.12	5.34854
2758.79	4.27188
2761.47	2.21041
2764.14	1.47474
2766.81	2.10402
2769.48	2.13459
2772.14	2.8496
2774.81	2.59809
2777.48	2.78714
2780.14	4.16168
2782.81	5.03732
2785.47	4.86146
2788.13	4.18137
2790.79	3.66168
2793.46	3.85822
2796.11	3.24948
2798.77	2.50046
2801.43	2.67839
2804.09	2.56168
2806.74	2.18689
2809.4	1.42995
2812.05	1.20573
2814.71	1.84437
2817.36	4.65943
2820.01	8.36587
2822.66	12.0363
2825.31	17.4294
2827.96	24.3876
2830.61	33.6061
2833.25	41.4072
2835.9	51.2287
2838.54	60.4968
2841.18	69.8549
2843.83	78.913
2846.47	86.8233
2849.11	94.8742
2851.75	105.155
2854.39	116.126
2857.03	125.869
2859.67	134.45
2862.3	141.934
2864.94	149.41
2867.57	154.212
2870.21	159.28
2872.84	161.439
2875.47	163.941
2878.1	166.593
2880.73	168.929
2883.36	173.377
2885.99	176.996
2888.61	180.483
2891.24	184.761
2893.87	189.56
2896.49	194.603
2899.11	201.908
2901.74	208.942
2904.36	218.627
2906.98	228.215
2909.6	240.146
2912.22	254.696
2914.83	270.3
2917.45	287.485
2920.07	303.188
2922.68	316.352
2925.3	327.145
2927.91	336.128
2930.52	342.588
2933.13	346.045
2935.74	345.82
2938.35	342.905
2940.96	338.374
2943.57	327.856
2946.18	316.55
2948.78	302.484
2951.39	287.491
2953.99	271.562
2956.6	254.509
2959.2	238.65
2961.8	223.164
2964.4	208.446
2967	193.407
2969.6	181.397
2972.2	170.304
2974.79	161.999
2977.39	153.23
2979.98	144.071
2982.58	135.483
2985.17	126.393
2987.76	117.83
2990.36	108.833
2992.95	100.218
2995.54	90.9011
2998.12	82.5779
3000.71	74.4413
3003.3	65.4879
3005.88	56.6489
3008.47	48.4594
3011.05	40.7493
3013.64	33.0883
3016.22	27.8257
3018.8	22.1295
3021.38	17.6606
3023.96	13.3478
3026.54	10.3664
3029.12	6.95707
3031.69	5.30223
3034.27	4.7021
3036.85	5.07677
3039.42	4.06109
3041.99	4.46304
3044.57	3.72185
3047.14	3.99355
3049.71	3.02392
3052.28	2.77414
3054.85	2.95859
3057.42	2.11086
3059.98	2.61848
3062.55	3.88949
3065.11	2.95859
3067.68	3.10812
3070.24	2.94991
3072.8	2.04904
3075.37	1.19504
3077.93	1.21554
3080.49	1.68856
3083.05	1.38939
3085.61	1.07541
3088.16	0.890288
3090.72	1.18614
3093.27	2.29029
3095.83	4.36272
3098.38	5.75164
3100.94	7.06713
3103.49	8.96353
3106.04	10.0528
3108.59	11.7243
3111.14	12.4592
3113.69	14.9353
3116.23	17.7975
3118.78	19.9041
3121.33	22.4943
3123.87	25.4686
3126.42	27.9488
3128.96	30.277
3131.5	32.675
3134.04	35.2484
3136.58	37.9237
3139.12	40.9961
3141.66	43.9512
3144.2	45.5275
3146.74	47.1724
3149.27	50.1949