File: data/Raman/poly_smoothed/Mb_50_18_44_1x_45s_532 nm_x100_100%_600 gr_mm_01.txt
#Acq. time (s)=	45
#Accumulations=	2
#Range (cm-¹)=	200...3150
#Windows=	2
#Auto scanning=	Off
#Autofocus=	Off
#Macrospot=	Off
#AutoExposure=	Off
#Spike filter=	Multiple accum.
#Delay time (s)=	0
#Binning=	1
#Readout mode=	Signal
#DeNoise=	Off
#ICS correction=	On
#Dark correction=	Off
#Inst. Process=	Off
#Detector Gain=	Best Dynamic Range
#Detector ADC=	20 kHz
#Detector temperature (°C)=	-69.85
#Instrument=	LabRAM HR Evol
#Detector=	Synapse
#Objective=	x100
#Grating=	600 gr/mm
#ND Filter=	100%
#Laser (nm)=	532
#Hole=	100.021
#Range=	Auto
#Laser Pol.=	No
#Raman. Pol.=	No
#Laser Pol. (°)=	-0.0007625
#Raman Pol. (°)=	89.9995
#Collection=	Microscope
#StageXY=	Marzhauser
#StageZ=	Marzhauser
#X (µm)=	28464.6
#Y (µm)=	-3006.6
#Z (µm)=	1043.05
#Full time(mm:ss)=	3:19
#Project=
#Sample=
#Site=
#Title=	Mb_50_18_44_2x_45s_532 nm_x100_100%_600 gr_mm
#Remark=
#Date=	12.07.2022 14:29
#Acquired=	12.07.2022 14:29:04
#Base:Fit=	10.08.2022 10:49:18
#Base:Sub=	10.08.2022 10:49:30
#Filter:Polynom=	16.08.2022 10:14:59
#AxisType[0]=Intens
#AxisUnit[0]=Cnt
#AxisType[1]=Spectr
#AxisUnit[1]=1/cm
200.388	3.81526
204.019	3.71897
207.646	3.31264
211.274	3.32428
214.899	3.89632
218.524	2.32999
222.146	2.61084
225.766	3.32248
229.388	2.8808
233.005	3.67025
236.621	3.12337
240.236	3.60552
243.852	6.00106
247.464	6.85579
251.074	6.91124
254.683	8.76082
258.291	9.78588
261.897	10.671
265.504	11.9162
269.108	10.5223
272.71	9.25987
276.311	9.04975
279.91	8.81379
283.508	9.00415
287.105	8.34194
290.698	8.19092
294.291	8.63617
297.884	7.93364
301.475	8.12705
305.064	7.50651
308.652	7.44129
312.237	8.95569
315.822	8.21315
319.406	10.2604
322.987	10.3912
326.568	11.4163
330.148	14.9851
333.724	15.9739
337.301	17.1812
340.875	18.32
344.449	20.4037
348.02	20.5289
351.592	21.7007
355.16	20.0878
358.728	19.0721
362.294	19.3777
365.858	21.2232
369.422	21.8692
372.983	20.5709
376.543	20.9307
380.102	20.4513
383.661	21.3627
387.216	20.2511
390.771	20.2871
394.324	18.1694
397.875	16.6844
401.425	16.8485
404.974	15.654
408.524	13.7686
412.07	12.5443
415.614	11.9258
419.156	10.2461
422.698	10.3222
426.238	8.70087
429.777	7.3652
433.315	5.51293
436.852	5.81421
440.387	5.41348
443.919	4.25562
447.451	5.77881
450.982	7.31539
454.512	7.89527
458.038	8.02629
461.565	9.4087
465.091	11.582
468.613	11.9158
472.136	11.9378
475.655	10.5191
479.176	11.8871
482.692	14.2051
486.21	15.5438
489.724	17.1706
493.237	18.3218
496.75	20.3942
500.26	20.9823
503.771	21.9943
507.279	22.1737
510.785	21.9893
514.289	20.5052
517.793	22.577
521.297	22.2039
524.797	23.1255
528.297	23.468
531.795	22.6757
535.291	21.6702
538.787	20.6026
542.281	20.0623
545.773	17.378
549.264	13.8933
552.754	11.3417
556.243	9.39826
559.73	7.36342
563.216	6.79227
566.701	6.28751
570.182	4.97864
573.664	4.55221
577.145	3.95115
580.624	2.51122
584.1	1.44147
587.577	1.75264
591.052	1.12872
594.524	0.635364
597.997	0.857192
601.466	2.5212
604.936	3.1207
608.403	3.58849
611.87	4.68073
615.334	5.61069
618.799	5.12645
622.26	4.81929
625.72	4.91499
629.181	5.25108
632.638	4.5823
636.095	6.09664
639.551	6.83101
643.005	6.50125
646.457	7.19292
649.908	7.2395
653.357	7.66073
656.806	8.96673
660.253	8.19216
663.7	6.92192
667.145	8.17314
670.588	10.1482
674.027	12.6638
677.468	12.7153
680.907	16.0721
684.345	17.7981
687.781	19.1559
691.216	22.2334
694.65	23.064
698.081	23.0784
701.512	24.4063
704.942	25.3152
708.371	26.5312
711.796	28.0891
715.222	30.8222
718.645	31.1385
722.068	31.0371
725.49	32.2996
728.909	33.6031
732.329	35.9202
735.745	36.4325
739.16	37.9486
742.576	40.9096
745.988	44.4838
749.401	49.1933
752.811	54.1355
756.22	58.6564
759.627	62.9224
763.035	67.9505
766.44	72.9435
769.843	76.6404
773.245	78.1835
776.646	79.372
780.046	79.9645
783.444	82.5291
786.841	83.4238
790.237	84.2839
793.631	83.363
797.024	82.3218
800.416	81.1864
803.807	78.5941
807.196	78.4724
810.584	76.6665
813.971	75.7975
817.354	75.0247
820.739	73.8886
824.122	74.6843
827.503	75.5381
830.882	74.6577
834.261	74.1601
837.637	74.3185
841.013	73.4163
844.389	71.8398
847.761	69.1555
851.131	67.0242
854.503	64.9003
857.871	61.3907
861.24	60.2368
864.606	59.1809
867.97	56.1958
871.336	53.7341
874.698	51.6644
878.058	49.7395
881.418	48.1187
884.778	47.0498
888.135	45.2636
891.49	45.0525
894.845	45.8094
898.198	45.5044
901.55	45.0583
904.901	44.753
908.25	43.4476
911.598	44.1732
914.945	43.2376
918.291	42.2297
921.635	41.031
924.978	38.8768
928.318	36.4083
931.659	34.7588
934.998	33.5544
938.336	33.0456
941.671	31.2037
945.007	29.4036
948.339	29.2357
951.672	29.312
955.004	30.4923
958.333	30.1214
961.662	28.9892
964.989	30.2687
968.315	31.2309
971.639	32.475
974.962	31.8147
978.285	31.8146
981.605	31.864
984.924	31.834
988.243	31.3177
991.56	31.7087
994.875	34.299
998.188	35.3889
1001.5	36.9415
1004.81	37.4111
1008.12	38.5986
1011.43	40.0362
1014.74	41.9981
1018.05	43.0957
1021.35	43.4647
1024.65	44.0775
1027.96	45.343
1031.26	46.2665
1034.56	48.0744
1037.86	47.5
1041.16	47.0108
1044.45	47.1245
1047.75	47.3689
1051.04	46.0677
1054.33	44.6732
1057.62	41.9523
1060.91	41.6472
1064.2	40.3154
1067.49	38.8505
1070.77	37.3399
1074.06	37.3835
1077.34	35.6878
1080.62	35.0066
1083.91	34.0796
1087.18	34.1999
1090.46	33.8595
1093.74	34.481
1097.02	33.1933
1100.29	31.9156
1103.56	30.7374
1106.84	30.4617
1110.11	29.1256
1113.38	28.2237
1116.64	27.3665
1119.91	25.0571
1123.18	24.9664
1126.44	25.0289
1129.7	22.9846
1132.97	20.8742
1136.23	20.3379
1139.49	18.6406
1142.74	16.7948
1146	14.3572
1149.26	12.1712
1152.51	10.3752
1155.76	8.77762
1159.01	6.89105
1162.27	6.33929
1165.51	4.55335
1168.76	5.26028
1172.01	5.0819
1175.25	2.65781
1178.5	1.16472
1181.74	1.04054
1184.98	0.357917
1188.22	-0.0252087
1191.46	-0.741601
1194.7	-0.517301
1197.94	2.484
1201.17	5.49972
1204.41	7.87266
1207.64	9.49575
1210.87	12.5989
1214.1	14.9035
1217.33	16.8742
1220.56	19.6994
1223.79	20.9194
1227.01	23.2965
1230.23	25.9785
1233.46	28.2581
1236.68	29.2299
1239.9	32.0955
1243.12	34.1572
1246.34	34.9381
1249.55	36.1478
1252.77	38.3733
1255.98	40.5483
1259.2	42.9938
1262.41	45.2013
1265.62	47.2794
1268.83	51.7037
1272.03	54.7722
1275.24	58.9626
1278.45	62.9676
1281.65	66.9487
1284.85	68.8616
1288.06	70.5837
1291.26	71.8175
1294.46	71.4252
1297.66	70.1678
1300.85	69.1816
1304.05	69.103
1307.24	68.6465
1310.43	66.6434
1313.63	65.9159
1316.82	65.4938
1320.01	65.349
1323.2	62.0326
1326.38	58.6483
1329.57	58.5759
1332.76	58.4213
1335.94	57.7918
1339.12	57.1388
1342.3	56.7074
1345.48	55.9811
1348.66	54.2711
1351.84	52.3077
1355.01	51.6078
1358.19	48.9388
1361.36	46.8908
1364.53	42.92
1367.71	40.0238
1370.88	37.865
1374.04	34.1033
1377.21	31.5495
1380.38	29.1719
1383.54	26.7199
1386.71	22.701
1389.87	21.8353
1393.03	21.9202
1396.19	21.8418
1399.35	20.4387
1402.51	19.7365
1405.67	22.0407
1408.82	25.2149
1411.98	28.1302
1415.13	34.6402
1418.28	38.515
1421.43	43.3376
1424.58	47.6059
1427.73	52.634
1430.88	57.4735
1434.02	61.9648
1437.17	65.1798
1440.31	67.1402
1443.45	69.2989
1446.6	71.4409
1449.74	71.492
1452.87	71.0472
1456.01	70.8152
1459.15	67.2833
1462.28	64.0196
1465.42	61.7081
1468.55	59.5845
1471.68	56.7861
1474.81	53.2833
1477.94	49.4569
1481.07	46.5063
1484.2	44.3106
1487.32	39.9484
1490.45	38.0426
1493.57	34.1976
1496.69	30.8977
1499.81	27.6174
1502.93	23.9798
1506.05	20.8662
1509.17	18.7087
1512.28	14.9526
1515.4	13.4406
1518.51	11.7529
1521.63	10.8418
1524.74	10.5934
1527.85	9.06801
1530.96	9.8866
1534.06	9.33804
1537.17	10.9711
1540.28	14.4148
1543.38	16.6725
1546.48	19.4516
1549.59	22.4841
1552.69	24.5097
1555.79	27.0619
1558.88	28.5888
1561.98	30.8143
1565.08	33.6894
1568.17	35.8447
1571.27	39.1353
1574.36	41.9542
1577.45	43.9106
1580.54	45.9873
1583.63	48.1358
1586.72	50.1807
1589.8	51.5162
1592.89	51.7397
1595.97	52.06
1599.06	50.9655
1602.14	50.5763
1605.22	50.742
1608.3	50.8437
1611.38	50.4232
1614.46	49.8124
1617.53	50.7242
1620.61	50.1767
1623.68	51.9163
1626.75	52.6368
1629.82	53.9461
1632.9	54.7524
1635.96	57.1659
1639.03	59.4341
1642.1	62.3852
1645.16	65.0163
1648.23	66.6345
1651.29	67.3873
1654.36	67.7276
1657.42	66.3249
1660.48	64.594
1663.53	61.5192
1666.59	58.811
1669.65	56.6886
1672.7	51.8844
1675.76	47.7026
1678.81	43.9709
1681.86	40.0104
1684.91	35.2864
1687.96	31.3395
1691.01	27.4135
1694.06	24.5092
1697.11	23.6984
1700.15	21.5959
1703.2	18.73
1706.24	17.93
1709.28	16.5264
1712.32	15.9883
1715.36	15.1789
1718.4	14.6908
1721.43	13.0824
1724.47	12.1134
1727.5	11.4004
1730.54	9.25477
1733.57	8.12805
1736.6	8.3952
1739.63	7.63603
1742.66	6.46945
1745.69	4.60575
1748.72	3.39823
1751.74	4.76596
1754.77	3.56919
1757.79	3.90785
1760.81	3.97911
1763.83	3.74275
1766.85	4.47144
1769.87	5.3406
1772.89	5.30699
1775.91	4.58591
1778.92	4.41935
1781.94	4.47108
1784.95	4.04879
1787.96	4.39318
1790.97	3.41608
1793.98	4.22203
1796.99	5.61171
1800	6.60218
1803	6.72899
1806.01	6.43401
1809.01	6.68663
1812.02	5.76426
1815.02	4.87767
1818.02	4.44436
1821.02	4.60207
1824.02	4.79842
1827.01	4.62643
1830.01	5.02926
1833	5.17791
1836	4.34045
1838.99	4.11388
1841.98	4.01732
1844.97	3.75807
1847.96	3.01678
1850.95	2.5473
1853.94	1.99584
1856.92	1.81047
1859.91	2.52652
1862.89	2.89987
1865.88	3.5828
1868.86	4.44798
1871.84	4.06982
1874.82	3.74595
1877.8	2.92004
1880.77	2.26683
1882.51	2.65033
1885.5	0.933975
1888.48	1.78773
1891.47	2.02335
1894.46	2.12683
1897.44	1.42368
1900.42	1.81067
1903.41	2.00781
1906.39	0.341387
1909.37	0.678467
1912.35	0.317187
1915.32	0.764639
1918.3	0.584889
1921.28	0.467436
1924.25	1.20067
1927.22	1.47641
1930.2	1.79182
1933.17	2.56995
1936.14	3.91822
1939.11	3.99098
1942.08	4.09187
1945.04	4.08841
1948.01	3.61316
1950.97	4.10748
1953.94	3.52166
1956.9	2.92204
1959.86	2.99696
1962.82	4.07852
1965.78	3.36418
1968.74	3.15434
1971.69	3.48083
1974.65	3.09972
1977.61	1.57401
1980.56	1.80899
1983.51	2.12957
1986.46	2.365
1989.41	3.17672
1992.36	3.07877
1995.31	4.31145
1998.26	4.7777
2001.2	4.63695
2004.15	5.76089
2007.09	7.29221
2010.04	7.83699
2012.98	8.41637
2015.92	9.36761
2018.86	9.88094
2021.8	11.0408
2024.74	10.979
2027.67	11.7189
2030.61	12.9472
2033.54	13.6688
2036.47	15.6756
2039.41	16.6891
2042.34	17.3906
2045.27	18.3793
2048.2	19.6831
2051.12	20.2789
2054.05	21.4684
2056.98	23.363
2059.9	24.8877
2062.82	25.7783
2065.75	26.0848
2068.67	26.1904
2071.59	27.1462
2074.51	28.4398
2077.43	29.6363
2080.34	31.708
2083.26	34.275
2086.17	36.4109
2089.09	37.5366
2092	39.5608
2094.91	41.3599
2097.82	43.6768
2100.73	45.7835
2103.64	48.981
2106.55	51.9313
2109.46	54.0552
2112.36	57.5267
2115.27	60.8323
2118.17	65.8278
2121.07	68.9648
2123.97	71.922
2126.87	75.8958
2129.77	79.5362
2132.67	80.2259
2135.57	82.6491
2138.46	86.5472
2141.36	89.0741
2144.25	93.1261
2147.14	97.1033
2150.03	99.8664
2152.92	103.388
2155.81	106.716
2158.7	109.134
2161.59	111.232
2164.48	113.445
2167.36	113.955
2170.25	114.01
2173.13	113.563
2176.01	111.554
2178.89	109.677
2181.77	107.441
2184.65	104.665
2187.53	103.263
2190.41	100.574
2193.28	96.3836
2196.16	92.7457
2199.03	87.7687
2201.9	85.1323
2204.78	81.5993
2207.65	78.9777
2210.51	75.4492
2213.38	72.6291
2216.25	71.0629
2219.12	67.3597
2221.98	64.2998
2224.85	62.3764
2227.71	59.5445
2230.57	56.5413
2233.43	52.8407
2236.29	48.5543
2239.15	44.7342
2242.01	40.4215
2244.87	36.2677
2247.73	33.5935
2250.58	31.5579
2253.43	28.7874
2256.29	26.89
2259.14	26.1188
2261.99	24.1737
2264.84	22.8185
2267.69	22.4866
2270.54	22.0927
2273.38	21.5467
2276.23	21.0612
2279.07	20.4646
2281.92	20.3744
2284.76	20.6846
2287.6	18.9478
2290.44	18.1159
2293.28	17.3588
2296.12	17.5099
2298.96	17.8222
2301.79	17.0552
2304.63	17.6526
2307.46	17.5876
2310.3	18.3665
2313.13	17.4346
2315.96	16.9864
2318.79	16.6603
2321.62	15.6763
2324.45	14.8058
2327.27	14.6781
2330.1	14.8673
2332.93	12.8629
2335.75	12.4196
2338.57	10.364
2341.4	9.39989
2344.22	8.49566
2347.04	6.75089
2349.86	5.69748
2352.67	5.51146
2355.49	4.27804
2358.31	3.22946
2361.12	2.2257
2363.94	2.76134
2366.75	3.23062
2369.56	3.49163
2372.37	4.76105
2375.18	5.7932
2377.99	5.43621
2380.8	5.35299
2383.61	4.28995
2386.41	4.67491
2389.22	4.23012
2392.02	5.38377
2394.82	6.15745
2397.63	7.56338
2400.43	7.04752
2403.23	6.46722
2406.02	7.73695
2408.82	7.81508
2411.62	7.43753
2414.41	7.98955
2417.21	7.7996
2420	7.1214
2422.79	7.53632
2425.59	7.14944
2428.38	6.57626
2431.17	6.35838
2433.96	6.57304
2436.74	7.19493
2439.53	7.31234
2442.32	7.56528
2445.1	5.95853
2447.88	5.01402
2450.67	3.95867
2453.45	4.10613
2456.23	2.74902
2459.01	3.53027
2461.79	4.33826
2464.57	3.50148
2467.34	3.4643
2470.12	4.2564
2472.89	4.24165
2475.67	4.0308
2478.44	3.03902
2481.21	3.45134
2483.98	2.51865
2486.75	1.57157
2489.52	2.12164
2492.29	2.71964
2495.06	2.38292
2497.82	2.26809
2500.59	1.77057
2503.35	0.852822
2506.11	2.15448
2508.88	1.79601
2511.63	0.69816
2514.39	0.96397
2517.15	0.731696
2519.91	0.452004
2522.67	1.1378
2525.42	1.92034
2528.18	2.93652
2530.93	3.19602
2533.69	3.39897
2536.44	3.61919
2539.19	5.14256
2541.94	4.78748
2544.69	5.41612
2547.44	5.35976
2550.18	5.53533
2552.93	5.27896
2555.68	6.03656
2558.42	6.31598
2561.16	6.22219
2563.9	6.03973
2566.64	7.03534
2569.38	7.0471
2572.12	7.72541
2574.86	8.56676
2577.6	7.77605
2580.34	7.4905
2583.07	7.29637
2585.81	5.95493
2588.54	6.39064
2591.27	5.3847
2594	4.92002
2596.73	4.0906
2599.46	3.20013
2602.19	2.90243
2604.92	2.29155
2607.64	2.19373
2610.37	1.79727
2613.09	0.707274
2615.82	-0.0168146
2618.54	-0.391767
2621.26	-0.191786
2623.98	0.232483
2626.7	0.50194
2629.42	1.446
2632.14	2.1851
2634.86	2.94353
2637.57	3.99761
2640.29	4.91036
2643	5.0192
2645.72	4.84787
2648.43	5.38857
2651.14	6.31215
2653.85	7.30428
2656.56	7.79082
2659.27	7.58248
2661.97	7.73241
2664.68	7.24258
2667.38	8.35342
2670.09	7.79531
2672.79	8.21292
2675.49	7.33994
2678.2	7.32324
2680.89	8.32043
2683.59	8.38038
2686.29	8.49958
2688.99	8.47919
2691.69	9.32959
2694.38	9.66561
2697.08	10.2568
2699.77	11.3477
2702.46	12.0841
2705.16	11.5361
2707.85	11.5563
2710.54	11.9688
2713.23	12.3365
2715.92	13.2759
2718.6	13.3122
2721.29	12.5001
2723.97	13.0115
2726.66	12.3236
2729.34	12.3665
2732.02	12.1734
2734.7	11.3526
2737.39	10.0818
2740.06	9.45736
2742.74	9.075
2745.42	8.52928
2748.1	7.55552
2750.77	5.92014
2753.45	4.83599
2756.12	4.12254
2758.79	3.53012
2761.47	3.2508
2764.14	2.90171
2766.81	2.54771
2769.48	1.03898
2772.14	-0.0270321
2774.81	-0.138973
2777.48	-0.150665
2780.14	0.0804975
2782.81	-0.35534
2785.47	0.118031
2788.13	0.872851
2790.79	0.275712
2793.46	0.45161
2796.11	0.31591
2798.77	-0.511723
2801.43	0.303341
2804.09	0.452245
2806.74	1.06566
2809.4	0.157846
2812.05	0.727106
2814.71	2.05388
2817.36	3.62179
2820.01	6.20895
2822.66	9.21019
2825.31	14.113
2827.96	20.0654
2830.61	25.3782
2833.25	31.2281
2835.9	37.6659
2838.54	45.8438
2841.18	52.8528
2843.83	60.0743
2846.47	68.5221
2849.11	77.0117
2851.75	84.296
2854.39	91.5639
2857.03	99.2468
2859.67	105.769
2862.3	111.402
2864.94	117.054
2867.57	122.639
2870.21	127.206
2872.84	130.649
2875.47	135.023
2878.1	137.877
2880.73	142.26
2883.36	147.076
2885.99	151.07
2888.61	155.864
2891.24	160.467
2893.87	164.998
2896.49	169.842
2899.11	175.593
2901.74	182.483
2904.36	190.479
2906.98	198.735
2909.6	206.092
2912.22	214.962
2914.83	224.593
2917.45	233.599
2920.07	240.795
2922.68	246.843
2925.3	250.977
2927.91	254.262
2930.52	256.77
2933.13	255.762
2935.74	253.759
2938.35	251.503
2940.96	246.392
2943.57	241.067
2946.18	234.934
2948.78	226.605
2951.39	218.14
2953.99	208.231
2956.6	198.098
2959.2	187.886
2961.8	177.858
2964.4	168.259
2967	159.214
2969.6	148.839
2972.2	139.401
2974.79	130.725
2977.39	122.537
2979.98	113.775
2982.58	103.72
2985.17	95.174
2987.76	86.193
2990.36	77.235
2992.95	69.2972
2995.54	61.9207
2998.12	54.0731
3000.71	48.981
3003.3	43.2438
3005.88	38.2121
3008.47	34.9425
3011.05	31.5563
3013.64	28.3849
3016.22	25.3075
3018.8	23.405
3021.38	20.4772
3023.96	18.5776
3026.54	16.9306
3029.12	15.2702
3031.69	14.8972
3034.27	14.514
3036.85	14.3482
3039.42	13.0499
3041.99	13.6507
3044.57	14.2944
3047.14	14.7541
3049.71	15.1093
3052.28	14.809
3054.85	15.413
3057.42	15.3369
3059.98	15.4279
3062.55	15.3735
3065.11	15.1867
3067.68	14.1336
3070.24	13.6257
3072.8	12.4064
3075.37	11.3399
3077.93	10.0714
3080.49	7.82407
3083.05	5.48477
3085.61	4.0934
3088.16	3.69173
3090.72	2.4958
3093.27	2.14185
3095.83	1.23168
3098.38	0.630742
3100.94	0.128996
3103.49	0.874869
3106.04	1.25706
3108.59	1.86581
3111.14	2.17786
3113.69	2.69844
3116.23	2.61924
3118.78	3.31404
3121.33	3.7905
3123.87	4.11064
3126.42	5.01131
3128.96	5.09057
3131.5	5.37626
3134.04	5.55536
3136.58	5.83055
3139.12	6.24135
3141.66	5.72847
3144.2	6.39757
3146.74	7.28071
3149.27	6.82751