File: data/Raman/poly_smoothed/Mb_50_18_38_1x_45s_532 nm_x100_100%_600 gr_mm_01.txt
#Acq. time (s)=	45
#Accumulations=	2
#Range (cm-¹)=	200...3150
#Windows=	2
#Auto scanning=	Off
#Autofocus=	Off
#Macrospot=	Off
#AutoExposure=	Off
#Spike filter=	Multiple accum.
#Delay time (s)=	0
#Binning=	1
#Readout mode=	Signal
#DeNoise=	Off
#ICS correction=	On
#Dark correction=	Off
#Inst. Process=	Off
#Detector Gain=	Best Dynamic Range
#Detector ADC=	20 kHz
#Detector temperature (°C)=	-69.85
#Instrument=	LabRAM HR Evol
#Detector=	Synapse
#Objective=	x100
#Grating=	600 gr/mm
#ND Filter=	100%
#Laser (nm)=	532
#Hole=	100.021
#Range=	Auto
#Laser Pol.=	No
#Raman. Pol.=	No
#Laser Pol. (°)=	-0.0007625
#Raman Pol. (°)=	89.9995
#Collection=	Microscope
#StageXY=	Marzhauser
#StageZ=	Marzhauser
#X (µm)=	28246.7
#Y (µm)=	-3221.3
#Z (µm)=	1041.05
#Full time(mm:ss)=	3:19
#Project=
#Sample=
#Site=
#Title=	Mb_50_18_38_2x_45s_532 nm_x100_100%_600 gr_mm
#Remark=
#Date=	12.07.2022 13:54
#Acquired=	12.07.2022 13:54:23
#Base:Fit=	10.08.2022 10:49:18
#Base:Sub=	10.08.2022 10:49:30
#Filter:Polynom=	16.08.2022 10:14:59
#AxisType[0]=Intens
#AxisUnit[0]=Cnt
#AxisType[1]=Spectr
#AxisUnit[1]=1/cm
200.388	99.8525
204.019	96.4014
207.646	91.5923
211.274	85.55
214.899	78.0499
218.524	69.4994
222.146	62.7049
225.766	55.8021
229.388	48.2607
233.005	42.1
236.621	37.4689
240.236	34.0199
243.852	30.2944
247.464	24.9759
251.074	18.95
254.683	15.6036
258.291	12.4736
261.897	11.5681
265.504	10.3188
269.108	8.39398
272.71	7.59172
276.311	6.70292
279.91	4.75415
283.508	4.34294
287.105	3.30333
290.698	6.03308
294.291	6.52155
297.884	8.96738
301.475	11.4251
305.064	12.0463
308.652	14.0177
312.237	14.1091
315.822	15.1977
319.406	18.5971
322.987	19.1446
326.568	18.6904
330.148	15.827
333.724	11.9313
337.301	6.07107
340.875	4.58302
344.449	5.24031
348.02	8.7747
351.592	12.3255
355.16	17.9923
358.728	26.6113
362.294	36.4727
365.858	47.2852
369.422	58.5735
372.983	67.5015
376.543	73.9945
380.102	81.2573
383.661	86.8975
387.216	89.7799
390.771	89.6335
394.324	88.0492
397.875	84.5794
401.425	78.9034
404.974	71.5682
408.524	62.1512
412.07	50.034
415.614	38.6624
419.156	25.3956
422.698	12.6627
426.238	3.83385
429.777	-0.934228
433.315	-5.28139
436.852	-6.58721
440.387	-5.3886
443.919	-2.3378
447.451	1.22447
450.982	3.29742
454.512	4.20158
458.038	1.91661
461.565	0.722994
465.091	0.690915
468.613	-0.546815
472.136	1.42877
475.655	3.05449
479.176	7.50797
482.692	14.7599
486.21	24.5857
489.724	34.3658
493.237	44.9884
496.75	57.9426
500.26	70.1951
503.771	80.5086
507.279	88.2291
510.785	94.1687
514.289	101.255
517.793	104.991
521.297	107.135
524.797	107.627
528.297	104.837
531.795	99.6553
535.291	92.8388
538.787	84.3769
542.281	71.5309
545.773	59.0552
549.264	46.6305
552.754	33.6866
556.243	23.324
559.73	16.2058
563.216	11.5373
566.701	9.78577
570.182	9.60256
573.664	9.31771
577.145	10.1831
580.624	12.2407
584.1	12.9166
587.577	14.6539
591.052	15.1005
594.524	15.5261
597.997	19.6045
601.466	19.1212
604.936	18.9697
608.403	18.614
611.87	18.6845
615.334	18.5008
618.799	17.8001
622.26	15.6362
625.72	13.0032
629.181	9.57177
632.638	9.12735
636.095	7.23089
639.551	4.35645
643.005	3.52885
646.457	3.07527
649.908	3.82951
653.357	1.7701
656.806	1.25033
660.253	0.817329
663.7	-0.0919513
667.145	-0.592339
670.588	0.0700781
674.027	0.774065
677.468	2.80714
680.907	6.2721
684.345	9.18519
687.781	9.70363
691.216	9.88932
694.65	11.9544
698.081	13.0728
701.512	15.1019
704.942	15.8664
708.371	16.7551
711.796	18.5066
715.222	19.2201
718.645	19.9932
722.068	17.1305
725.49	15.5748
728.909	14.6726
732.329	17.0289
735.745	23.0959
739.16	34.5952
742.576	51.8657
745.988	71.7639
749.401	91.5409
752.811	113.185
756.22	131.801
759.627	149.485
763.035	165.256
766.44	177.015
769.843	184.419
773.245	188.743
776.646	191.798
780.046	190.937
783.444	185.883
786.841	178.439
790.237	168.109
793.631	154.286
797.024	138.74
800.416	121.638
803.807	102.433
807.196	84.0492
810.584	69.1216
813.971	59.6528
817.354	55.2292
820.739	54.7607
824.122	56.0777
827.503	58.3237
830.882	60.8458
834.261	61.5279
837.637	63.1404
841.013	62.3085
844.389	61.7196
847.761	59.3524
851.131	58.6839
854.503	56.9021
857.871	55.5293
861.24	52.4378
864.606	49.7491
867.97	47.9765
871.336	47.5631
874.698	43.608
878.058	41.4559
881.418	37.988
884.778	35.3065
888.135	30.6241
891.49	30.2079
894.845	29.4654
898.198	29.148
901.55	28.9845
904.901	28.4588
908.25	30.5555
911.598	31.2726
914.945	31.7589
918.291	30.0147
921.635	30.6461
924.978	29.9668
928.318	29.8691
931.659	27.8461
934.998	25.5238
938.336	25.1669
941.671	22.411
945.007	20.486
948.339	20.5207
951.672	18.5407
955.004	16.3572
958.333	13.3141
961.662	10.3906
964.989	9.27478
968.315	10.7048
971.639	15.4408
974.962	24.7919
978.285	32.6474
981.605	39.3294
984.924	44.3885
988.243	48.6868
991.56	56.6021
994.875	66.2838
998.188	78.7142
1001.5	95.0859
1004.81	110.215
1008.12	125.014
1011.43	137.83
1014.74	149.419
1018.05	160.018
1021.35	166.478
1024.65	170.012
1027.96	171.924
1031.26	170.314
1034.56	165.289
1037.86	158.666
1041.16	149.61
1044.45	142.802
1047.75	135.981
1051.04	131.677
1054.33	129.103
1057.62	123.625
1060.91	116.782
1064.2	112.094
1067.49	108.533
1070.77	110.167
1074.06	114.696
1077.34	120.179
1080.62	123.983
1083.91	125.674
1087.18	128.523
1090.46	130.021
1093.74	129.098
1097.02	125.725
1100.29	120.435
1103.56	115.012
1106.84	106.972
1110.11	98.3209
1113.38	89.5903
1116.64	77.5493
1119.91	67.0689
1123.18	55.3021
1126.44	47.6442
1129.7	42.7029
1132.97	39.0765
1136.23	35.9611
1139.49	34.8477
1142.74	32.7496
1146	31.6862
1149.26	29.1117
1152.51	27.6523
1155.76	23.7827
1159.01	20.7471
1162.27	17.2725
1165.51	18.2773
1168.76	18.0671
1172.01	19.4528
1175.25	19.3591
1178.5	19.1585
1181.74	20.2839
1184.98	20.8077
1188.22	20.8417
1191.46	21.8032
1194.7	21.9522
1197.94	22.4046
1201.17	23.7814
1204.41	25.8978
1207.64	28.9279
1210.87	34.6709
1214.1	38.3492
1217.33	43.2328
1220.56	45.7217
1223.79	49.7579
1227.01	52.6231
1230.23	55.2831
1233.46	58.3208
1236.68	60.737
1239.9	63.2495
1243.12	66.8355
1246.34	69.6525
1249.55	71.0201
1252.77	74.6037
1255.98	75.2107
1259.2	76.8663
1262.41	80.6546
1265.62	84.1099
1268.83	88.8255
1272.03	96.5198
1275.24	103.328
1278.45	110.039
1281.65	115.027
1284.85	122.701
1288.06	126.948
1291.26	132.898
1294.46	135.155
1297.66	137.168
1300.85	138.704
1304.05	138.527
1307.24	138.074
1310.43	134.531
1313.63	131.006
1316.82	127.307
1320.01	120.165
1323.2	114.057
1326.38	107.045
1329.57	99.8273
1332.76	91.653
1335.94	85.5314
1339.12	80.3893
1342.3	75.921
1345.48	71.523
1348.66	70.1575
1351.84	67.8732
1355.01	64.5211
1358.19	60.1675
1361.36	56.4129
1364.53	54.3016
1367.71	52.4467
1370.88	47.0658
1374.04	43.5693
1377.21	42.0005
1380.38	41.3689
1383.54	37.4942
1386.71	35.6309
1389.87	33.2553
1393.03	29.68
1396.19	28.6611
1399.35	29.6094
1402.51	35.8515
1405.67	44.6569
1408.82	55.2626
1411.98	69.4741
1415.13	84.5662
1418.28	98.9538
1421.43	115.597
1424.58	134.775
1427.73	152.893
1430.88	170.056
1434.02	184.468
1437.17	195.905
1440.31	205.389
1443.45	209.988
1446.6	208.728
1449.74	207.319
1452.87	202.733
1456.01	195.243
1459.15	182.303
1462.28	166.467
1465.42	147.44
1468.55	128.502
1471.68	111.269
1474.81	94.6013
1477.94	79.6338
1481.07	66.6288
1484.2	53.3383
1487.32	41.2713
1490.45	30.147
1493.57	23.1664
1496.69	15.8353
1499.81	12.8561
1502.93	8.85799
1506.05	6.15041
1509.17	2.89776
1512.28	0.891187
1515.4	-1.36632
1518.51	-4.35723
1521.63	-4.3444
1524.74	-2.35157
1527.85	-0.111151
1530.96	3.83603
1534.06	7.76481
1537.17	10.1144
1540.28	12.8966
1543.38	17.0606
1546.48	22.137
1549.59	26.7532
1552.69	29.7336
1555.79	32.2738
1558.88	33.6721
1561.98	37.0362
1565.08	41.8837
1568.17	48.9213
1571.27	56.2632
1574.36	62.4139
1577.45	68.2934
1580.54	74.5219
1583.63	79.644
1586.72	83.3337
1589.8	85.5951
1592.89	88.5559
1595.97	91.2274
1599.06	92.4928
1602.14	92.0693
1605.22	92.4046
1608.3	91.2628
1611.38	89.79
1614.46	84.9557
1617.53	83.2782
1620.61	84.18
1623.68	83.0201
1626.75	81.2092
1629.82	80.8665
1632.9	81.7013
1635.96	86.0524
1639.03	92.7259
1642.1	96.8013
1645.16	101.011
1648.23	105.519
1651.29	108.694
1654.36	112.451
1657.42	112.439
1660.48	112.458
1663.53	111.492
1666.59	108.037
1669.65	104.763
1672.7	96.3281
1675.76	90.7852
1678.81	82.3667
1681.86	74.834
1684.91	67.1881
1687.96	58.7801
1691.01	50.7514
1694.06	44.9931
1697.11	39.1941
1700.15	35.0104
1703.2	32.3446
1706.24	30.8798
1709.28	27.8715
1712.32	26.7789
1715.36	24.3223
1718.4	23.1518
1721.43	22.1941
1724.47	23.0238
1727.5	22.6713
1730.54	21.9691
1733.57	21.8936
1736.6	22.0201
1739.63	20.7398
1742.66	19.0212
1745.69	17.3001
1748.72	16.1077
1751.74	15.7194
1754.77	14.3073
1757.79	12.6243
1760.81	12.2978
1763.83	8.96445
1766.85	8.0818
1769.87	6.38833
1772.89	5.02913
1775.91	6.03353
1778.92	6.40327
1781.94	4.67348
1784.95	3.86726
1787.96	2.69694
1790.97	2.27496
1793.98	1.8758
1796.99	1.40105
1800	1.9849
1803	1.95354
1806.01	2.51548
1809.01	3.61553
1812.02	3.24855
1815.02	2.42983
1818.02	2.18878
1821.02	2.80475
1824.02	2.98195
1827.01	3.20888
1830.01	3.39737
1833	4.27061
1836	3.99585
1838.99	3.8972
1841.98	3.51158
1844.97	1.99671
1847.96	2.20624
1850.95	2.27127
1853.94	1.97476
1856.92	1.91751
1859.91	1.71622
1862.89	1.31334
1865.88	1.85718
1868.86	2.06413
1871.84	2.36364
1874.82	2.95896
1877.8	5.12587
1880.77	5.0139
1882.51	4.58752
1885.5	4.96584
1888.48	5.79598
1891.47	7.66824
1894.46	8.15481
1897.44	9.12536
1900.42	9.91491
1903.41	9.25334
1906.39	8.92171
1909.37	8.29146
1912.35	8.73884
1915.32	8.92996
1918.3	8.23744
1921.28	8.02485
1924.25	6.97617
1927.22	6.54157
1930.2	4.67677
1933.17	3.96302
1936.14	3.53883
1939.11	2.25178
1942.08	2.43676
1945.04	1.4136
1948.01	0.77843
1950.97	-0.402854
1953.94	-0.0799866
1956.9	-0.446533
1959.86	0.167061
1962.82	1.20593
1965.78	1.2454
1968.74	1.2308
1971.69	1.51042
1974.65	1.70095
1977.61	0.823217
1980.56	1.92241
1983.51	2.62907
1986.46	3.41758
1989.41	3.7479
1992.36	2.785
1995.31	2.57957
1998.26	1.67518
2001.2	1.87279
2004.15	3.34598
2007.09	3.13609
2010.04	2.44969
2012.98	2.9202
2015.92	1.97614
2018.86	2.29385
2021.8	0.235046
2024.74	2.29464
2027.67	2.24755
2030.61	3.34748
2033.54	5.0385
2036.47	6.63669
2039.41	8.68427
2042.34	9.37669
2045.27	11.5336
2048.2	13.9231
2051.12	15.5432
2054.05	16.6851
2056.98	17.6339
2059.9	20.0197
2062.82	21.4364
2065.75	23.1915
2068.67	25.2881
2071.59	28.0718
2074.51	32.6202
2077.43	33.9575
2080.34	35.8913
2083.26	38.2115
2086.17	39.506
2089.09	42.3109
2092	43.2426
2094.91	45.4315
2097.82	49.7214
2100.73	54.3539
2103.64	58.87
2106.55	62.339
2109.46	67.9808
2112.36	71.5902
2115.27	77.0277
2118.17	82.3317
2121.07	85.4302
2123.97	91.7847
2126.87	96.3779
2129.77	102.833
2132.67	109.901
2135.57	116.243
2138.46	122.828
2141.36	132.018
2144.25	139.571
2147.14	146.37
2150.03	151.114
2152.92	154.797
2155.81	158.46
2158.7	162.785
2161.59	166.008
2164.48	168.89
2167.36	171.233
2170.25	172.068
2173.13	170.788
2176.01	168.179
2178.89	166.912
2181.77	163.742
2184.65	159.875
2187.53	155.315
2190.41	151.073
2193.28	146.812
2196.16	140.83
2199.03	135.388
2201.9	130.912
2204.78	126.033
2207.65	122.253
2210.51	118.15
2213.38	113.86
2216.25	107.582
2219.12	101.76
2221.98	96.547
2224.85	92.7251
2227.71	86.0609
2230.57	81.3644
2233.43	74.9261
2236.29	69.7936
2239.15	64.117
2242.01	58.4178
2244.87	53.2279
2247.73	48.1987
2250.58	44.1926
2253.43	39.3397
2256.29	37.1819
2259.14	34.9733
2261.99	33.1745
2264.84	30.2637
2267.69	30.8187
2270.54	29.8434
2273.38	27.5388
2276.23	25.4741
2279.07	23.7219
2281.92	22.1868
2284.76	20.6944
2287.6	18.8859
2290.44	16.9181
2293.28	14.2933
2296.12	11.6524
2298.96	8.54472
2301.79	7.71653
2304.63	5.92526
2307.46	5.25531
2310.3	5.53333
2313.13	5.14702
2315.96	5.91124
2318.79	4.59627
2321.62	4.42177
2324.45	5.16236
2327.27	5.36361
2330.1	6.74431
2332.93	7.10726
2335.75	8.01438
2338.57	8.02552
2341.4	7.0352
2344.22	5.76114
2347.04	5.45174
2349.86	3.85914
2352.67	2.9112
2355.49	2.04958
2358.31	2.10505
2361.12	2.06789
2363.94	2.71585
2366.75	2.43738
2369.56	3.60364
2372.37	3.8904
2375.18	3.51857
2377.99	4.70481
2380.8	4.24508
2383.61	4.36807
2386.41	4.05476
2389.22	3.18749
2392.02	3.41244
2394.82	4.29369
2397.63	5.73728
2400.43	5.35995
2403.23	6.55963
2406.02	7.49258
2408.82	7.41556
2411.62	7.85693
2414.41	6.48154
2417.21	6.92815
2420	7.52112
2422.79	8.25137
2425.59	8.695
2428.38	8.64199
2431.17	9.0895
2433.96	9.31669
2436.74	7.93444
2439.53	7.98726
2442.32	7.53918
2445.1	8.45667
2447.88	8.67969
2450.67	9.79396
2453.45	9.53381
2456.23	10.0346
2459.01	8.95347
2461.79	9.0502
2464.57	9.75026
2467.34	10.8507
2470.12	11.7092
2472.89	11.8693
2475.67	12.2236
2478.44	11.7071
2481.21	10.6477
2483.98	10.1826
2486.75	9.91965
2489.52	8.01529
2492.29	6.21039
2495.06	6.1645
2497.82	5.28887
2500.59	4.87353
2503.35	2.38162
2506.11	1.37886
2508.88	2.46694
2511.63	2.84573
2514.39	2.5347
2517.15	2.60707
2519.91	2.41062
2522.67	2.32024
2525.42	2.92677
2528.18	3.49822
2530.93	7.39151
2533.69	9.92892
2536.44	12.2504
2539.19	14.5807
2541.94	14.2743
2544.69	14.7128
2547.44	15.1902
2550.18	15.9279
2552.93	15.7526
2555.68	16.3523
2558.42	16.8168
2561.16	16.7757
2563.9	16.3728
2566.64	15.2651
2569.38	14.7872
2572.12	14.2201
2574.86	14.2161
2577.6	14.1742
2580.34	13.9338
2583.07	13.5008
2585.81	13.8327
2588.54	13.5443
2591.27	13.6384
2594	13.9669
2596.73	16.1862
2599.46	16.0936
2602.19	14.8195
2604.92	14.7914
2607.64	14.5982
2610.37	14.8927
2613.09	16.2047
2615.82	15.928
2618.54	16.7509
2621.26	15.8567
2623.98	15.4519
2626.7	15.7789
2629.42	15.9488
2632.14	15.6717
2634.86	17.1623
2637.57	18.0056
2640.29	19.5994
2643	20.0008
2645.72	20.1323
2648.43	20.2347
2651.14	21.4831
2653.85	21.3557
2656.56	20.969
2659.27	21.9877
2661.97	22.4303
2664.68	22.8361
2667.38	23.225
2670.09	23.5102
2672.79	23.687
2675.49	23.7692
2678.2	23.7811
2680.89	23.4873
2683.59	23.2064
2686.29	23.4534
2688.99	22.0423
2691.69	21.0576
2694.38	20.9564
2697.08	22.093
2699.77	22.5873
2702.46	23.2082
2705.16	23.7479
2707.85	24.9567
2710.54	25.0927
2713.23	26.1619
2715.92	27.4347
2718.6	28.8545
2721.29	29.6559
2723.97	30.7044
2726.66	31.9212
2729.34	31.1582
2732.02	30.9945
2734.7	30.635
2737.39	29.2341
2740.06	27.9577
2742.74	25.6166
2745.42	24.2312
2748.1	21.6361
2750.77	19.2913
2753.45	15.721
2756.12	12.9166
2758.79	10.6729
2761.47	9.30499
2764.14	5.95731
2766.81	3.38427
2769.48	2.57277
2772.14	1.86044
2774.81	1.17978
2777.48	0.87799
2780.14	0.121333
2782.81	0.424357
2785.47	0.57489
2788.13	0.455862
2790.79	1.5095
2793.46	1.6646
2796.11	1.64144
2798.77	1.54907
2801.43	1.36459
2804.09	0.432031
2806.74	-1.05638
2809.4	-2.2306
2812.05	-2.99932
2814.71	-2.28801
2817.36	1.80301
2820.01	10.1764
2822.66	23.2415
2825.31	40.6998
2827.96	60.5729
2830.61	82.9903
2833.25	107.219
2835.9	135.39
2838.54	163.015
2841.18	190.269
2843.83	218.569
2846.47	247.179
2849.11	273.374
2851.75	300.599
2854.39	326.201
2857.03	350.393
2859.67	372.488
2862.3	389.981
2864.94	404.358
2867.57	416.337
2870.21	425
2872.84	430.98
2875.47	436.336
2878.1	442.968
2880.73	449.931
2883.36	458.229
2885.99	467.086
2888.61	477.529
2891.24	486.656
2893.87	496.898
2896.49	508.392
2899.11	521.473
2901.74	535.28
2904.36	550.367
2906.98	569.039
2909.6	589.977
2912.22	609.25
2914.83	630.504
2917.45	650.37
2920.07	666.832
2922.68	677.945
2925.3	684.931
2927.91	688.77
2930.52	687.345
2933.13	682.878
2935.74	672.964
2938.35	659.461
2940.96	641.7
2943.57	619.063
2946.18	593.982
2948.78	565.782
2951.39	537.073
2953.99	507.69
2956.6	479.124
2959.2	449.666
2961.8	422.495
2964.4	396.586
2967	372.01
2969.6	350.244
2972.2	329.341
2974.79	308.088
2977.39	286.776
2979.98	265.153
2982.58	241.465
2985.17	219.959
2987.76	197.701
2990.36	177.013
2992.95	156.415
2995.54	136.702
2998.12	119.722
3000.71	102.55
3003.3	86.7322
3005.88	71.0391
3008.47	57.8183
3011.05	46.3032
3013.64	35.6203
3016.22	27.0827
3018.8	20.8829
3021.38	14.8674
3023.96	10.2492
3026.54	7.77496
3029.12	4.67917
3031.69	2.56115
3034.27	2.48521
3036.85	3.47279
3039.42	4.85983
3041.99	6.08651
3044.57	8.05964
3047.14	10.2431
3049.71	11.9646
3052.28	13.2204
3054.85	15.6845
3057.42	16.2526
3059.98	17.1942
3062.55	16.8769
3065.11	15.8509
3067.68	15.2409
3070.24	13.1712
3072.8	11.7101
3075.37	9.37094
3077.93	6.94781
3080.49	5.76179
3083.05	3.55495
3085.61	2.33808
3088.16	1.93246
3090.72	2.17159
3093.27	3.10668
3095.83	5.42208
3098.38	9.30014
3100.94	11.6179
3103.49	14.0556
3106.04	16.1925
3108.59	20.3366
3111.14	22.5614
3113.69	25.9817
3116.23	30.8658
3118.78	33.1055
3121.33	37.3933
3123.87	41.0269
3126.42	44.8726
3128.96	49.8768
3131.5	53.7647
3134.04	57.4885
3136.58	62.2734
3139.12	67.2542
3141.66	73.5948
3144.2	81.3157
3146.74	90.6081
3149.27	101.379