File: data/Raman/poly_smoothed/Mb_50_18_14_1x_45s_532 nm_x100_100%_600 gr_mm_01.txt
#Acq. time (s)=	45
#Accumulations=	2
#Range (cm-¹)=	200...3150
#Windows=	2
#Auto scanning=	Off
#Autofocus=	Off
#Macrospot=	Off
#AutoExposure=	Off
#Spike filter=	Multiple accum.
#Delay time (s)=	0
#Binning=	1
#Readout mode=	Signal
#DeNoise=	Off
#ICS correction=	On
#Dark correction=	Off
#Inst. Process=	Off
#Detector Gain=	Best Dynamic Range
#Detector ADC=	20 kHz
#Detector temperature (°C)=	-69.85
#Instrument=	LabRAM HR Evol
#Detector=	Synapse
#Objective=	x100
#Grating=	600 gr/mm
#ND Filter=	100%
#Laser (nm)=	532
#Hole=	100.021
#Range=	Auto
#Laser Pol.=	No
#Raman. Pol.=	No
#Laser Pol. (°)=	-0.0007625
#Raman Pol. (°)=	89.9995
#Collection=	Microscope
#StageXY=	Marzhauser
#StageZ=	Marzhauser
#X (µm)=	19304
#Y (µm)=	3091.4
#Z (µm)=	1046.85
#Full time(mm:ss)=	3:18
#Project=
#Sample=
#Site=
#Title=	Mb_50_18_14_2x_45s_532 nm_x100_100%_600 gr_mm
#Remark=
#Date=	12.07.2022 11:17
#Acquired=	12.07.2022 11:17:02
#Base:Fit=	10.08.2022 10:49:18
#Base:Sub=	10.08.2022 10:49:30
#Filter:Polynom=	16.08.2022 10:14:59
#AxisType[0]=Intens
#AxisUnit[0]=Cnt
#AxisType[1]=Spectr
#AxisUnit[1]=1/cm
200.388	2.68525
204.019	1.70302
207.646	3.08113
211.274	3.86317
214.899	4.19
218.524	4.99871
222.146	4.69015
225.766	5.62413
229.388	5.15996
233.005	5.63294
236.621	7.80146
240.236	8.00981
243.852	8.19479
247.464	8.8994
251.074	9.90984
254.683	10.1046
258.291	11.2528
261.897	14.2054
265.504	14.3056
269.108	15.3259
272.71	15.8414
276.311	15.1013
279.91	13.4642
283.508	13.868
287.105	13.8059
290.698	13.7744
294.291	13.9891
297.884	13.1675
301.475	15.1334
305.064	15.801
308.652	16.5062
312.237	17.5281
315.822	17.1984
319.406	16.6471
322.987	18.3349
326.568	18.8907
330.148	19.2824
333.724	19.5077
337.301	19.9068
340.875	20.8883
344.449	21.2509
348.02	22.2735
351.592	22.0661
355.16	22.3543
358.728	22.2013
362.294	20.925
365.858	21.4536
369.422	22.2254
372.983	24.0448
376.543	26.9759
380.102	27.7266
383.661	28.7733
387.216	32.024
390.771	32.6871
394.324	32.4678
397.875	31.7043
401.425	29.8307
404.974	28.3819
408.524	28.5506
412.07	26.4295
415.614	23.5727
419.156	19.344
422.698	15.7897
426.238	12.1457
429.777	8.99561
433.315	6.87907
436.852	4.5351
440.387	3.55014
443.919	1.85512
447.451	2.49916
450.982	1.20083
454.512	2.49154
458.038	4.47725
461.565	7.76484
465.091	11.212
468.613	13.441
472.136	17.175
475.655	20.0053
479.176	23.114
482.692	25.5052
486.21	28.573
489.724	31.7542
493.237	34.6137
496.75	34.8551
500.26	36.6936
503.771	36.3433
507.279	35.0695
510.785	36.3657
514.289	34.8622
517.793	36.2808
521.297	34.337
524.797	32.2002
528.297	29.5124
531.795	29.3854
535.291	26.059
538.787	23.3503
542.281	20.9881
545.773	19.2497
549.264	18.556
552.754	15.284
556.243	11.9974
559.73	8.08841
563.216	6.5399
566.701	5.13074
570.182	5.31272
573.664	5.14046
577.145	5.23122
580.624	4.57469
584.1	4.54734
587.577	5.52145
591.052	4.29144
594.524	5.76992
597.997	5.26401
601.466	6.02448
604.936	7.2307
608.403	7.21826
611.87	7.23744
615.334	6.82648
618.799	7.0433
622.26	7.27954
625.72	8.4043
629.181	9.28418
632.638	11.0804
636.095	10.9516
639.551	10.7376
643.005	10.287
646.457	9.63215
649.908	12.0695
653.357	13.7038
656.806	14.3812
660.253	13.7486
663.7	13.9073
667.145	14.2013
670.588	15.1612
674.027	13.9377
677.468	14.148
680.907	15.4672
684.345	16.3892
687.781	17.7364
691.216	17.4818
694.65	17.7121
698.081	20.8295
701.512	23.5307
704.942	26.8476
708.371	29.255
711.796	31.5708
715.222	33.5777
718.645	35.8219
722.068	36.8195
725.49	37.2883
728.909	39.4629
732.329	41.3044
735.745	43.9844
739.16	45.3198
742.576	48.9242
745.988	53.6869
749.401	57.855
752.811	60.5178
756.22	65.5651
759.627	67.3952
763.035	69.6006
766.44	72.5389
769.843	73.6814
773.245	75.2552
776.646	77.1295
780.046	80.3991
783.444	81.9217
786.841	82.8649
790.237	81.6503
793.631	82.281
797.024	82.0928
800.416	80.9741
803.807	80.0857
807.196	78.7556
810.584	77.9033
813.971	77.8589
817.354	76.7793
820.739	77.2902
824.122	78.0248
827.503	77.6316
830.882	77.234
834.261	74.9153
837.637	72.6056
841.013	68.1962
844.389	65.9946
847.761	63.9836
851.131	61.6698
854.503	60.0596
857.871	58.7015
861.24	58.6703
864.606	58.0126
867.97	56.0477
871.336	54.154
874.698	53.9333
878.058	53.0948
881.418	53.5063
884.778	53.8243
888.135	53.7975
891.49	53.2998
894.845	53.6493
898.198	54.2016
901.55	53.8936
904.901	53.3619
908.25	54.478
911.598	53.763
914.945	52.959
918.291	49.9609
921.635	48.923
924.978	48.0878
928.318	48.3967
931.659	46.3965
934.998	46.3725
938.336	44.7603
941.671	42.6961
945.007	40.3289
948.339	38.1717
951.672	37.5821
955.004	35.9746
958.333	34.9269
961.662	33.8509
964.989	32.7256
968.315	31.7774
971.639	30.8922
974.962	30.745
978.285	30.0179
981.605	30.5719
984.924	28.8359
988.243	28.5927
991.56	26.4742
994.875	25.721
998.188	26.8585
1001.5	26.7369
1004.81	28.5385
1008.12	31.3874
1011.43	33.4712
1014.74	36.5072
1018.05	35.7943
1021.35	36.9722
1024.65	38.4023
1027.96	39.0029
1031.26	40.5194
1034.56	42.2408
1037.86	41.8872
1041.16	41.2597
1044.45	39.8388
1047.75	40.4423
1051.04	39.7004
1054.33	38.93
1057.62	36.6232
1060.91	35.672
1064.2	33.1562
1067.49	31.0641
1070.77	29.9405
1074.06	30.5974
1077.34	32.3318
1080.62	31.5624
1083.91	31.7297
1087.18	32.876
1090.46	32.9671
1093.74	32.0204
1097.02	31.5306
1100.29	31.0203
1103.56	30.7329
1106.84	30.2827
1110.11	29.349
1113.38	29.0028
1116.64	27.9516
1119.91	25.7091
1123.18	23.2568
1126.44	21.404
1129.7	19.7835
1132.97	17.4528
1136.23	15.1354
1139.49	13.4149
1142.74	11.3386
1146	8.33816
1149.26	7.97585
1152.51	7.7171
1155.76	5.99314
1159.01	5.05865
1162.27	5.15865
1165.51	5.05846
1168.76	5.80459
1172.01	7.23752
1175.25	8.13081
1178.5	11.6331
1181.74	13.152
1184.98	15.022
1188.22	17.1348
1191.46	18.0249
1194.7	18.2111
1197.94	20.3037
1201.17	20.2387
1204.41	20.2324
1207.64	21.5937
1210.87	21.1176
1214.1	21.252
1217.33	20.9973
1220.56	21.056
1223.79	22.0118
1227.01	24.0719
1230.23	25.0346
1233.46	26.6674
1236.68	27.8485
1239.9	30.6878
1243.12	32.2049
1246.34	35.1305
1249.55	39.3645
1252.77	42.5114
1255.98	45.6832
1259.2	49.6088
1262.41	51.7687
1265.62	54.7049
1268.83	56.0517
1272.03	57.4973
1275.24	58.2231
1278.45	59.949
1281.65	60.7057
1284.85	60.2182
1288.06	60.3887
1291.26	58.9054
1294.46	58.4366
1297.66	57.4148
1300.85	57.0783
1304.05	56.7495
1307.24	54.6675
1310.43	53.8349
1313.63	54.4499
1316.82	53.4978
1320.01	52.3263
1323.2	51.6618
1326.38	52.396
1329.57	52.6088
1332.76	53.1683
1335.94	52.8292
1339.12	51.1423
1342.3	49.8924
1345.48	49.443
1348.66	48.1249
1351.84	46.5267
1355.01	44.2952
1358.19	42.86
1361.36	40.6854
1364.53	38.3763
1367.71	38.0382
1370.88	35.8513
1374.04	34.8171
1377.21	34.2984
1380.38	32.8872
1383.54	31.7331
1386.71	31.8767
1389.87	32.5331
1393.03	32.2592
1396.19	31.1644
1399.35	31.4636
1402.51	33.3292
1405.67	34.5629
1408.82	35.2749
1411.98	36.9115
1415.13	39.2382
1418.28	42.0364
1421.43	45.3225
1424.58	50.3404
1427.73	52.0414
1430.88	56.3126
1434.02	59.7042
1437.17	62.2838
1440.31	66.0287
1443.45	69.1269
1446.6	69.31
1449.74	69.8742
1452.87	69.294
1456.01	68.6601
1459.15	66.6791
1462.28	64.541
1465.42	61.5254
1468.55	58.1161
1471.68	55.4623
1474.81	53.0923
1477.94	50.0194
1481.07	45.5605
1484.2	43.5349
1487.32	41.4059
1490.45	38.7687
1493.57	37.0192
1496.69	34.591
1499.81	33.5774
1502.93	31.9625
1506.05	30.526
1509.17	29.4041
1512.28	27.0852
1515.4	26.6191
1518.51	26.082
1521.63	23.4906
1524.74	22.4502
1527.85	21.4913
1530.96	23.104
1534.06	22.2253
1537.17	22.8961
1540.28	23.8897
1543.38	25.4669
1546.48	26.277
1549.59	27.9484
1552.69	28.4038
1555.79	29.3241
1558.88	30.4938
1561.98	32.527
1565.08	33.4819
1568.17	34.9814
1571.27	36.9558
1574.36	39.8052
1577.45	41.5756
1580.54	42.7895
1583.63	43.4619
1586.72	43.5189
1589.8	44.3942
1592.89	45.2922
1595.97	45.264
1599.06	46.3566
1602.14	46.4242
1605.22	48.4122
1608.3	47.7823
1611.38	47.3498
1614.46	46.9116
1617.53	46.6932
1620.61	45.8773
1623.68	45.4944
1626.75	45.4907
1629.82	45.7859
1632.9	47.4603
1635.96	47.8391
1639.03	49.8137
1642.1	52.15
1645.16	53.8091
1648.23	56.0777
1651.29	56.8532
1654.36	57.1528
1657.42	56.7747
1660.48	56.5134
1663.53	55.2649
1666.59	55.0817
1669.65	52.5247
1672.7	50.895
1675.76	50.0108
1678.81	47.7509
1681.86	44.4935
1684.91	40.9667
1687.96	38.4585
1691.01	34.6379
1694.06	31.772
1697.11	28.2736
1700.15	26.4009
1703.2	24.4617
1706.24	23.1684
1709.28	21.1861
1712.32	18.5795
1715.36	18.463
1718.4	15.798
1721.43	14.6466
1724.47	13.9948
1727.5	12.1359
1730.54	11.8921
1733.57	11.354
1736.6	10.2716
1739.63	9.50315
1742.66	8.5802
1745.69	8.27197
1748.72	8.60429
1751.74	8.31244
1754.77	7.67471
1757.79	6.72875
1760.81	7.25981
1763.83	6.83101
1766.85	5.23446
1769.87	4.56228
1772.89	4.3526
1775.91	4.62024
1778.92	5.24253
1781.94	4.02388
1784.95	4.13913
1787.96	4.07137
1790.97	2.77939
1793.98	3.69256
1796.99	3.55397
1800	3.98104
1803	3.35574
1806.01	3.66995
1809.01	2.914
1812.02	3.08428
1815.02	4.10146
1818.02	4.85587
1821.02	5.80179
1824.02	6.22257
1827.01	7.76867
1830.01	7.32926
1833	7.26769
1836	6.94022
1838.99	7.0671
1841.98	8.48802
1844.97	8.48042
1847.96	8.58341
1850.95	9.06587
1853.94	8.5499
1856.92	7.41651
1859.91	7.53694
1862.89	7.51973
1865.88	6.70139
1868.86	5.63344
1871.84	3.84218
1874.82	3.26904
1877.8	3.27021
1880.77	2.98652
1882.51	2.93497
1885.5	3.05741
1888.48	3.06302
1891.47	3.6548
1894.46	4.40152
1897.44	5.24306
1900.42	5.17994
1903.41	4.30127
1906.39	4.73397
1909.37	4.7373
1912.35	6.13706
1915.32	6.46355
1918.3	5.09233
1921.28	5.92403
1924.25	5.03076
1927.22	4.32879
1930.2	4.80404
1933.17	5.01861
1936.14	3.61466
1939.11	2.16381
1942.08	2.34379
1945.04	2.41902
1948.01	2.56004
1950.97	2.25188
1953.94	1.96947
1956.9	2.003
1959.86	2.28216
1962.82	2.79512
1965.78	3.48534
1968.74	2.33921
1971.69	1.51314
1974.65	1.0365
1977.61	1.00467
1980.56	1.95966
1983.51	2.78256
1986.46	2.38637
1989.41	3.14323
1992.36	2.20815
1995.31	1.98625
1998.26	0.700523
2001.2	0.856513
2004.15	1.11015
2007.09	0.00235934
2010.04	-0.458946
2012.98	0.670715
2015.92	0.62382
2018.86	0.882577
2021.8	0.345023
2024.74	-0.350463
2027.67	-0.337916
2030.61	0.164925
2033.54	1.32703
2036.47	1.31197
2039.41	1.83217
2042.34	3.1588
2045.27	4.11101
2048.2	5.39077
2051.12	7.76177
2054.05	9.82277
2056.98	10.5145
2059.9	11.1134
2062.82	13.0454
2065.75	13.0651
2068.67	14.2812
2071.59	15.8776
2074.51	16.6909
2077.43	17.3644
2080.34	18.7965
2083.26	19.9788
2086.17	22.0892
2089.09	23.7236
2092	25.0998
2094.91	27.2244
2097.82	29.2551
2100.73	31.6478
2103.64	34.8522
2106.55	36.1284
2109.46	38.5529
2112.36	41.4588
2115.27	44.7111
2118.17	46.2006
2121.07	48.5001
2123.97	50.3139
2126.87	52.0978
2129.77	54.4912
2132.67	56.7089
2135.57	59.6579
2138.46	61.5671
2141.36	64.0601
2144.25	66.0933
2147.14	68.3496
2150.03	71.8585
2152.92	73.7337
2155.81	75.1646
2158.7	77.8763
2161.59	78.1461
2164.48	79.2052
2167.36	79.0204
2170.25	79.0808
2173.13	79.429
2176.01	78.0528
2178.89	77.0521
2181.77	76.2782
2184.65	75.5698
2187.53	72.6996
2190.41	70.0215
2193.28	67.8831
2196.16	66.5889
2199.03	65.4511
2201.9	63.9884
2204.78	61.9859
2207.65	60.2415
2210.51	58.1753
2213.38	56.2572
2216.25	54.0693
2219.12	51.4023
2221.98	48.2374
2224.85	44.8049
2227.71	41.3803
2230.57	38.3202
2233.43	34.707
2236.29	32.8242
2239.15	31.0318
2242.01	28.3386
2244.87	25.2303
2247.73	23.4854
2250.58	21.2712
2253.43	19.5127
2256.29	18.7094
2259.14	17.7805
2261.99	16.5569
2264.84	15.5148
2267.69	15.6245
2270.54	15.3686
2273.38	15.0811
2276.23	14.7059
2279.07	13.806
2281.92	13.675
2284.76	12.5971
2287.6	10.7807
2290.44	8.91276
2293.28	8.00444
2296.12	6.52959
2298.96	6.6102
2301.79	6.87889
2304.63	6.87365
2307.46	7.39627
2310.3	7.0273
2313.13	6.51441
2315.96	6.69574
2318.79	6.57531
2321.62	6.38958
2324.45	6.88692
2327.27	6.64535
2330.1	5.95636
2332.93	6.76978
2335.75	6.91804
2338.57	6.99542
2341.4	5.60418
2344.22	5.75878
2347.04	5.42947
2349.86	4.51906
2352.67	2.57338
2355.49	1.56994
2358.31	0.608091
2361.12	1.00487
2363.94	1.38208
2366.75	0.794207
2369.56	1.72282
2372.37	1.84529
2375.18	2.04
2377.99	1.5901
2380.8	2.70584
2383.61	3.48472
2386.41	2.98068
2389.22	3.72981
2392.02	4.94289
2394.82	6.47484
2397.63	7.00664
2400.43	7.65896
2403.23	7.59212
2406.02	7.35256
2408.82	6.87526
2411.62	6.70983
2414.41	7.40652
2417.21	6.43613
2420	5.39271
2422.79	5.25832
2425.59	5.20466
2428.38	4.39404
2431.17	3.48616
2433.96	2.55912
2436.74	1.87662
2439.53	1.84344
2442.32	1.65067
2445.1	1.05821
2447.88	0.881237
2450.67	0.987285
2453.45	0.776465
2456.23	0.904255
2459.01	1.06434
2461.79	2.03382
2464.57	3.41448
2467.34	3.00182
2470.12	2.8733
2472.89	3.94383
2475.67	3.19647
2478.44	2.29677
2481.21	2.14223
2483.98	2.0276
2486.75	2.15161
2489.52	2.30936
2492.29	1.7724
2495.06	0.8782
2497.82	0.604627
2500.59	0.847826
2503.35	0.689802
2506.11	1.5583
2508.88	1.4584
2511.63	1.65696
2514.39	1.89671
2517.15	2.19962
2519.91	2.23825
2522.67	2.49628
2525.42	2.95312
2528.18	4.27427
2530.93	4.6308
2533.69	4.91947
2536.44	4.40376
2539.19	6.24014
2541.94	6.57299
2544.69	6.50402
2547.44	7.38196
2550.18	8.214
2552.93	8.99583
2555.68	9.5761
2558.42	8.6728
2561.16	8.57384
2563.9	9.21675
2566.64	9.7575
2569.38	10.1351
2572.12	10.0285
2574.86	9.53707
2577.6	8.43022
2580.34	7.86296
2583.07	7.21231
2585.81	6.46814
2588.54	5.58447
2591.27	5.08017
2594	4.9241
2596.73	4.3249
2599.46	3.57219
2602.19	3.54063
2604.92	3.7849
2607.64	5.13001
2610.37	5.6991
2613.09	5.69956
2615.82	5.79046
2618.54	5.50994
2621.26	5.51925
2623.98	5.54745
2626.7	5.52636
2629.42	7.62097
2632.14	7.32689
2634.86	6.63899
2637.57	6.7298
2640.29	5.95824
2643	6.09512
2645.72	5.89835
2648.43	6.6608
2651.14	6.39091
2653.85	7.31955
2656.56	6.95429
2659.27	7.67418
2661.97	7.67039
2664.68	8.28097
2667.38	8.57079
2670.09	8.77842
2672.79	9.7538
2675.49	9.96143
2678.2	10.2134
2680.89	10.0393
2683.59	10.7971
2686.29	10.7332
2688.99	11.5171
2691.69	11.7986
2694.38	11.6302
2697.08	10.9973
2699.77	9.79487
2702.46	10.2535
2705.16	9.9362
2707.85	8.8264
2710.54	9.50088
2713.23	9.32037
2715.92	8.75966
2718.6	9.49676
2721.29	9.22693
2723.97	9.16392
2726.66	9.87861
2729.34	9.4037
2732.02	9.85266
2734.7	8.93005
2737.39	8.99204
2740.06	9.13451
2742.74	9.14115
2745.42	9.34286
2748.1	8.90778
2750.77	8.24228
2753.45	7.976
2756.12	6.84595
2758.79	5.29136
2761.47	3.2471
2764.14	2.21704
2766.81	1.1964
2769.48	0.613834
2772.14	-0.661751
2774.81	-0.85692
2777.48	-0.302129
2780.14	-0.873173
2782.81	-1.31528
2785.47	-0.858228
2788.13	-1.01669
2790.79	-0.0243419
2793.46	0.65545
2796.11	0.875593
2798.77	1.72566
2801.43	1.41183
2804.09	2.14444
2806.74	2.31151
2809.4	2.44328
2812.05	1.9743
2814.71	1.4783
2817.36	2.18966
2820.01	3.28338
2822.66	4.5428
2825.31	7.24678
2827.96	11.5527
2830.61	16.4511
2833.25	21.6698
2835.9	27.0316
2838.54	32.9639
2841.18	38.618
2843.83	44.6914
2846.47	50.4322
2849.11	56.4993
2851.75	63.7955
2854.39	70.3311
2857.03	75.5598
2859.67	81.5389
2862.3	85.4128
2864.94	89.3135
2867.57	92.9139
2870.21	95.4982
2872.84	97.0523
2875.47	99.2184
2878.1	101.305
2880.73	103.746
2883.36	105.945
2885.99	108.198
2888.61	111.482
2891.24	115.818
2893.87	118.912
2896.49	122.937
2899.11	127.075
2901.74	131.428
2904.36	137.231
2906.98	142.071
2909.6	147.551
2912.22	154.083
2914.83	160.971
2917.45	166.763
2920.07	171.34
2922.68	174.966
2925.3	178.167
2927.91	181.043
2930.52	182.331
2933.13	182.386
2935.74	180.378
2938.35	177.766
2940.96	174.605
2943.57	170.342
2946.18	165.217
2948.78	157.693
2951.39	150.606
2953.99	143.425
2956.6	135.612
2959.2	128.463
2961.8	121.242
2964.4	114.54
2967	108.722
2969.6	101.486
2972.2	95.194
2974.79	88.8993
2977.39	83.1356
2979.98	76.0393
2982.58	68.689
2985.17	62.2907
2987.76	56.5692
2990.36	50.988
2992.95	44.4346
2995.54	39.0911
2998.12	33.6357
3000.71	28.9765
3003.3	25.1082
3005.88	20.8596
3008.47	16.2515
3011.05	12.5054
3013.64	9.67347
3016.22	8.53637
3018.8	7.01046
3021.38	5.58581
3023.96	4.31155
3026.54	4.17608
3029.12	4.47915
3031.69	3.68459
3034.27	3.18648
3036.85	2.60261
3039.42	3.0109
3041.99	2.83244
3044.57	2.82197
3047.14	3.46574
3049.71	3.83257
3052.28	4.1726
3054.85	4.70498
3057.42	5.16173
3059.98	5.66659
3062.55	5.04984
3065.11	5.22384
3067.68	5.13815
3070.24	3.94793
3072.8	3.6444
3075.37	3.59279
3077.93	3.08297
3080.49	1.50068
3083.05	0.486941
3085.61	0.471498
3088.16	0.903766
3090.72	1.33677
3093.27	1.01072
3095.83	1.12802
3098.38	1.86301
3100.94	3.02492
3103.49	3.91818
3106.04	4.46483
3108.59	5.45639
3111.14	7.47
3113.69	8.45
3116.23	9.71224
3118.78	10.8396
3121.33	12.2765
3123.87	13.0926
3126.42	13.6097
3128.96	15.1836
3131.5	15.3237
3134.04	15.285
3136.58	15.4246
3139.12	15.7627
3141.66	15.6103
3144.2	16.7589
3146.74	17.8423
3149.27	17.6464