File: data/Raman/poly_smoothed/Mb_50_18_31_1x_45s_532 nm_x100_100%_600 gr_mm_02.txt
#Acq. time (s)=	45
#Accumulations=	2
#Range (cm-¹)=	200...3150
#Windows=	2
#Auto scanning=	Off
#Autofocus=	Off
#Macrospot=	Off
#AutoExposure=	Off
#Spike filter=	Multiple accum.
#Delay time (s)=	0
#Binning=	1
#Readout mode=	Signal
#DeNoise=	Off
#ICS correction=	On
#Dark correction=	Off
#Inst. Process=	Off
#Detector Gain=	Best Dynamic Range
#Detector ADC=	20 kHz
#Detector temperature (°C)=	-69.85
#Instrument=	LabRAM HR Evol
#Detector=	Synapse
#Objective=	x100
#Grating=	600 gr/mm
#ND Filter=	100%
#Laser (nm)=	532
#Hole=	100.021
#Range=	Auto
#Laser Pol.=	No
#Raman. Pol.=	No
#Laser Pol. (°)=	-0.0007625
#Raman Pol. (°)=	89.9995
#Collection=	Microscope
#StageXY=	Marzhauser
#StageZ=	Marzhauser
#X (µm)=	28299.8
#Y (µm)=	-3252.8
#Z (µm)=	1041.05
#Full time(mm:ss)=	3:18
#Project=
#Sample=
#Site=
#Title=	Mb_50_18_31_2x_45s_532 nm_x100_100%_600 gr_mm
#Remark=
#Date=	12.07.2022 13:12
#Acquired=	12.07.2022 13:12:43
#Base:Fit=	10.08.2022 10:49:18
#Base:Sub=	10.08.2022 10:49:30
#Filter:Polynom=	16.08.2022 10:14:59
#AxisType[0]=Intens
#AxisUnit[0]=Cnt
#AxisType[1]=Spectr
#AxisUnit[1]=1/cm
200.388	15.8959
204.019	14.1249
207.646	13.9976
211.274	13.2017
214.899	12.1177
218.524	11.8858
222.146	13.2437
225.766	15.1224
229.388	16.3642
233.005	16.0198
236.621	14.6075
240.236	13.3085
243.852	12.1167
247.464	11.8187
251.074	11.0641
254.683	11.2095
258.291	9.98336
261.897	11.4137
265.504	13.0023
269.108	13.5604
272.71	14.1116
276.311	14.3981
279.91	14.1123
283.508	12.8298
287.105	14.4669
290.698	15.4798
294.291	16.8511
297.884	17.9433
301.475	19.9234
305.064	21.5501
308.652	23.8012
312.237	26.5172
315.822	28.8047
319.406	29.9909
322.987	29.8809
326.568	29.4558
330.148	28.3387
333.724	27.2811
337.301	27.1685
340.875	24.7442
344.449	24.6819
348.02	27.2877
351.592	29.1518
355.16	30.2745
358.728	33.5466
362.294	36.2789
365.858	38.1023
369.422	40.6094
372.983	42.0938
376.543	44.138
380.102	46.0159
383.661	46.9128
387.216	48.9858
390.771	49.0251
394.324	48.6857
397.875	48.7702
401.425	47.576
404.974	46.6381
408.524	44.549
412.07	40.6085
415.614	35.4717
419.156	30.5276
422.698	27.5005
426.238	23.9169
429.777	20.3287
433.315	17.3818
436.852	16.3568
440.387	14.9374
443.919	14.9944
447.451	14.8967
450.982	13.9301
454.512	12.8724
458.038	12.9978
461.565	13.4937
465.091	14.293
468.613	15.5374
472.136	16.0227
475.655	17.239
479.176	19.013
482.692	21.9809
486.21	26.8478
489.724	32.369
493.237	36.3459
496.75	39.2861
500.26	42.6684
503.771	44.7484
507.279	47.974
510.785	48.9354
514.289	49.2581
517.793	49.8051
521.297	50.281
524.797	50.8165
528.297	49.0002
531.795	48.5914
535.291	46.4841
538.787	41.4796
542.281	38.4256
545.773	33.9356
549.264	30.6475
552.754	26.5736
556.243	22.2947
559.73	18.7092
563.216	17.8597
566.701	16.5671
570.182	16.1891
573.664	15.1515
577.145	13.9433
580.624	12.9015
584.1	10.922
587.577	9.07885
591.052	8.24993
594.524	7.90778
597.997	7.80126
601.466	9.32642
604.936	9.95474
608.403	10.8274
611.87	11.711
615.334	11.8258
618.799	12.1787
622.26	10.3758
625.72	9.39293
629.181	9.79443
632.638	9.96721
636.095	10.5638
639.551	9.39739
643.005	10.0408
646.457	10.529
649.908	9.82906
653.357	10.8936
656.806	10.5424
660.253	9.91548
663.7	10.5468
667.145	11.5639
670.588	12.5193
674.027	14.5515
677.468	15.8574
680.907	18.6214
684.345	22.6707
687.781	24.7504
691.216	25.3932
694.65	28.1576
698.081	29.2746
701.512	31.0074
704.942	31.697
708.371	32.7773
711.796	32.4402
715.222	34.5251
718.645	35.7698
722.068	35.5655
725.49	34.8841
728.909	34.3723
732.329	35.0629
735.745	37.6861
739.16	41.404
742.576	45.7984
745.988	51.0828
749.401	58.6738
752.811	64.9998
756.22	71.6674
759.627	75.8118
763.035	80.3742
766.44	86.3423
769.843	89.9968
773.245	91.3915
776.646	94.03
780.046	94.0052
783.444	93.9238
786.841	92.1732
790.237	89.0968
793.631	86.1261
797.024	83.8408
800.416	80.1031
803.807	74.5329
807.196	69.6413
810.584	65.9083
813.971	62.9911
817.354	61.4923
820.739	60.7847
824.122	59.7485
827.503	57.739
830.882	58.0165
834.261	55.9292
837.637	54.5445
841.013	52.168
844.389	50.8185
847.761	49.7687
851.131	47.4348
854.503	44.1043
857.871	42.8921
861.24	39.8847
864.606	38.3843
867.97	36.6787
871.336	36.3869
874.698	36.4818
878.058	36.4252
881.418	36.4992
884.778	36.2019
888.135	35.4612
891.49	35.5243
894.845	35.2252
898.198	35.1922
901.55	34.2501
904.901	33.7211
908.25	34.05
911.598	33.5943
914.945	32.224
918.291	29.9115
921.635	28.0617
924.978	26.4987
928.318	23.9459
931.659	20.3876
934.998	18.7327
938.336	16.8111
941.671	15.0979
945.007	14.2714
948.339	13.5895
951.672	13.8184
955.004	13.0239
958.333	11.9314
961.662	11.0948
964.989	9.69222
968.315	8.87235
971.639	8.08425
974.962	9.5213
978.285	10.3731
981.605	10.7759
984.924	11.0696
988.243	12.4047
991.56	12.3282
994.875	12.8565
998.188	14.0906
1001.5	17.1418
1004.81	21.8878
1008.12	25.7548
1011.43	30.1381
1014.74	35.6247
1018.05	40.5211
1021.35	42.7289
1024.65	45.7607
1027.96	47.9075
1031.26	49.5683
1034.56	49.3017
1037.86	46.6707
1041.16	42.7819
1044.45	40.0336
1047.75	36.463
1051.04	34.4768
1054.33	32.5342
1057.62	29.9164
1060.91	27.5647
1064.2	24.9517
1067.49	24.6328
1070.77	24.3759
1074.06	23.644
1077.34	24.4492
1080.62	26.6751
1083.91	28.8992
1087.18	29.8006
1090.46	31.1418
1093.74	32.5534
1097.02	34.0279
1100.29	32.3091
1103.56	31.9899
1106.84	31.5628
1110.11	30.0014
1113.38	27.5895
1116.64	22.9564
1119.91	18.2551
1123.18	15.7468
1126.44	15.6879
1129.7	14.1917
1132.97	12.1517
1136.23	10.8087
1139.49	11.044
1142.74	8.19215
1146	8.33685
1149.26	7.30307
1152.51	6.28988
1155.76	3.75506
1159.01	1.70134
1162.27	1.2452
1165.51	1.16893
1168.76	1.43891
1172.01	2.18496
1175.25	3.33693
1178.5	4.21993
1181.74	5.54956
1184.98	7.79236
1188.22	7.8975
1191.46	7.75682
1194.7	8.47239
1197.94	9.51208
1201.17	9.89936
1204.41	12.5321
1207.64	12.8851
1210.87	12.624
1214.1	13.8366
1217.33	15.899
1220.56	15.7157
1223.79	17.0379
1227.01	19.783
1230.23	21.1654
1233.46	22.0299
1236.68	20.5744
1239.9	23.5908
1243.12	25.0852
1246.34	26.4324
1249.55	26.2924
1252.77	29.2587
1255.98	30.1418
1259.2	33.1418
1262.41	34.6804
1265.62	34.8024
1268.83	35.1977
1272.03	37.2231
1275.24	38.2191
1278.45	39.8338
1281.65	41.0323
1284.85	41.7847
1288.06	42.1326
1291.26	43.7099
1294.46	44.9639
1297.66	45.3514
1300.85	45.8273
1304.05	46.7241
1307.24	46.6838
1310.43	45.9491
1313.63	44.6339
1316.82	44.524
1320.01	45.4807
1323.2	45.6656
1326.38	45.9058
1329.57	45.6753
1332.76	46.2916
1335.94	46.054
1339.12	46.22
1342.3	44.8516
1345.48	44.379
1348.66	44.549
1351.84	44.8204
1355.01	44.9483
1358.19	43.9397
1361.36	43.4266
1364.53	42.4001
1367.71	42.5222
1370.88	41.9779
1374.04	41.0816
1377.21	41.4031
1380.38	38.6642
1383.54	36.4226
1386.71	33.2462
1389.87	32.2799
1393.03	29.7672
1396.19	29.7725
1399.35	29.7924
1402.51	29.6227
1405.67	28.9587
1408.82	29.3637
1411.98	30.374
1415.13	31.2595
1418.28	33.3745
1421.43	36.6102
1424.58	40.8103
1427.73	44.4449
1430.88	49.3525
1434.02	52.4962
1437.17	55.4613
1440.31	57.6379
1443.45	59.4918
1446.6	61.2496
1449.74	61.8041
1452.87	63.7435
1456.01	65.1306
1459.15	65.7981
1462.28	69.9701
1465.42	71.9014
1468.55	72.5027
1471.68	74.1086
1474.81	75.8918
1477.94	76.612
1481.07	75.8334
1484.2	75.0968
1487.32	73.1491
1490.45	71.2565
1493.57	69.8139
1496.69	67.2409
1499.81	64.1146
1502.93	59.45
1506.05	54.4909
1509.17	48.1241
1512.28	40.5155
1515.4	34.3866
1518.51	28.9314
1521.63	24.3821
1524.74	22.1804
1527.85	19.1144
1530.96	18.4459
1534.06	18.6209
1537.17	19.6239
1540.28	21.0679
1543.38	22.3239
1546.48	24.1811
1549.59	26.7779
1552.69	27.5078
1555.79	29.4167
1558.88	28.9074
1561.98	30.0402
1565.08	31.8043
1568.17	34.4194
1571.27	36.5816
1574.36	38.951
1577.45	40.6402
1580.54	41.3508
1583.63	43.2122
1586.72	44.2596
1589.8	44.541
1592.89	46.2883
1595.97	47.4946
1599.06	46.1917
1602.14	44.5269
1605.22	43.7715
1608.3	44.0641
1611.38	43.7556
1614.46	43.8573
1617.53	44.3655
1620.61	45.6481
1623.68	45.6518
1626.75	45.4044
1629.82	47.7855
1632.9	47.4853
1635.96	48.9104
1639.03	52.1359
1642.1	54.6192
1645.16	56.5351
1648.23	58.4655
1651.29	60.7801
1654.36	62.3818
1657.42	62.3237
1660.48	62.6425
1663.53	61.2671
1666.59	60.3005
1669.65	58.3291
1672.7	55.4398
1675.76	52.1446
1678.81	49.1972
1681.86	45.0692
1684.91	41.5981
1687.96	37.7678
1691.01	34.7419
1694.06	31.3498
1697.11	28.436
1700.15	25.6055
1703.2	22.4634
1706.24	19.6715
1709.28	16.6136
1712.32	15.3638
1715.36	12.5911
1718.4	9.11223
1721.43	8.00268
1724.47	8.01826
1727.5	6.70499
1730.54	6.37387
1733.57	7.32661
1736.6	6.07075
1739.63	5.66577
1742.66	5.46549
1745.69	5.23868
1748.72	4.69435
1751.74	4.16581
1754.77	4.0265
1757.79	4.58291
1760.81	5.50036
1763.83	4.84993
1766.85	5.04659
1769.87	4.82642
1772.89	5.46915
1775.91	5.92545
1778.92	5.66278
1781.94	6.13459
1784.95	5.48614
1787.96	4.73444
1790.97	3.75575
1793.98	3.0226
1796.99	3.5813
1800	4.18378
1803	4.18792
1806.01	4.14436
1809.01	4.34749
1812.02	3.60369
1815.02	4.19429
1818.02	5.10226
1821.02	5.3164
1824.02	6.78234
1827.01	7.03436
1830.01	7.73709
1833	8.26322
1836	7.94423
1838.99	7.43075
1841.98	7.5473
1844.97	8.38353
1847.96	8.90459
1850.95	9.06353
1853.94	8.23227
1856.92	7.01851
1859.91	6.14821
1862.89	5.8118
1865.88	4.00064
1868.86	3.57509
1871.84	2.78816
1874.82	3.00961
1877.8	3.80346
1880.77	3.36138
1882.51	3.40438
1885.5	3.38852
1888.48	4.76381
1891.47	5.27429
1894.46	5.70424
1897.44	5.58082
1900.42	5.06771
1903.41	4.15937
1906.39	3.42503
1909.37	3.41247
1912.35	3.49183
1915.32	4.37335
1918.3	5.43559
1921.28	4.96488
1924.25	4.74546
1927.22	5.40054
1930.2	6.11055
1933.17	6.72409
1936.14	6.73182
1939.11	7.42717
1942.08	7.75463
1945.04	8.19707
1948.01	8.12178
1950.97	7.87354
1953.94	8.35392
1956.9	8.01719
1959.86	8.03188
1962.82	9.2881
1965.78	8.79102
1968.74	6.84206
1971.69	6.47088
1974.65	6.61834
1977.61	6.84022
1980.56	6.55526
1983.51	7.23438
1986.46	7.31335
1989.41	7.76095
1992.36	7.45482
1995.31	6.65655
1998.26	7.39824
2001.2	7.67889
2004.15	7.60794
2007.09	7.58801
2010.04	7.76107
2012.98	7.41503
2015.92	7.40808
2018.86	6.33129
2021.8	6.61923
2024.74	8.09499
2027.67	8.1673
2030.61	7.9931
2033.54	10.1078
2036.47	11.2647
2039.41	11.217
2042.34	12.3457
2045.27	15.1757
2048.2	17.2179
2051.12	17.5384
2054.05	18.2147
2056.98	18.3992
2059.9	18.9356
2062.82	19.6897
2065.75	19.9151
2068.67	20.1674
2071.59	20.989
2074.51	22.3921
2077.43	22.5246
2080.34	23.1567
2083.26	24.3332
2086.17	25.2013
2089.09	26.086
2092	26.4815
2094.91	26.5284
2097.82	29.2322
2100.73	31.2829
2103.64	33.954
2106.55	35.455
2109.46	36.3784
2112.36	38.2588
2115.27	41.48
2118.17	44.64
2121.07	46.6708
2123.97	50.0592
2126.87	52.131
2129.77	55.2593
2132.67	59.3035
2135.57	62.7064
2138.46	64.4685
2141.36	68.2659
2144.25	71.7002
2147.14	73.5015
2150.03	74.7538
2152.92	77.5438
2155.81	80.0551
2158.7	80.38
2161.59	82.461
2164.48	83.7214
2167.36	85.1312
2170.25	86.3795
2173.13	85.7573
2176.01	83.4978
2178.89	80.8648
2181.77	80.4171
2184.65	79.2482
2187.53	77.6759
2190.41	76.3373
2193.28	73.4938
2196.16	71.2406
2199.03	68.0141
2201.9	66.2827
2204.78	63.9371
2207.65	61.0659
2210.51	57.9063
2213.38	54.8462
2216.25	52.1726
2219.12	50.6518
2221.98	48.7058
2224.85	46.5387
2227.71	43.7304
2230.57	42.2241
2233.43	40.4742
2236.29	37.4858
2239.15	35.2299
2242.01	33.239
2244.87	30.5853
2247.73	28.0195
2250.58	26.5642
2253.43	25.719
2256.29	24.4038
2259.14	22.6941
2261.99	21.5343
2264.84	20.6264
2267.69	20.5126
2270.54	19.7513
2273.38	18.9701
2276.23	18.8291
2279.07	17.5211
2281.92	16.5921
2284.76	16.8016
2287.6	16.4688
2290.44	14.9371
2293.28	13.2986
2296.12	12.4545
2298.96	12.9114
2301.79	12.8246
2304.63	13.4062
2307.46	13.5416
2310.3	13.3232
2313.13	12.3618
2315.96	12.6856
2318.79	12.2052
2321.62	12.6261
2324.45	12.1127
2327.27	11.5744
2330.1	11.2439
2332.93	10.8998
2335.75	10.2805
2338.57	9.19817
2341.4	8.62316
2344.22	7.17953
2347.04	6.38356
2349.86	4.88093
2352.67	3.17711
2355.49	1.82709
2358.31	-0.049191
2361.12	-1.36133
2363.94	-0.627532
2366.75	0.216212
2369.56	-0.231792
2372.37	0.441251
2375.18	1.26498
2377.99	1.80184
2380.8	1.5278
2383.61	2.08666
2386.41	3.41619
2389.22	2.85157
2392.02	4.04117
2394.82	3.54461
2397.63	4.22269
2400.43	2.9212
2403.23	3.68272
2406.02	4.32805
2408.82	5.17442
2411.62	5.82347
2414.41	4.81196
2417.21	5.33071
2420	5.41807
2422.79	4.52614
2425.59	5.03304
2428.38	4.19016
2431.17	3.86987
2433.96	3.54475
2436.74	3.43921
2439.53	3.53576
2442.32	3.74979
2445.1	4.52407
2447.88	5.1514
2450.67	5.11015
2453.45	5.36384
2456.23	5.34652
2459.01	6.26674
2461.79	6.91624
2464.57	6.90238
2467.34	6.62543
2470.12	6.51833
2472.89	7.32125
2475.67	6.52503
2478.44	6.37096
2481.21	5.71567
2483.98	4.9628
2486.75	4.9497
2489.52	3.71487
2492.29	3.57955
2495.06	3.06772
2497.82	1.42
2500.59	1.40921
2503.35	0.798069
2506.11	1.03234
2508.88	0.324962
2511.63	0.631819
2514.39	1.35555
2517.15	1.09128
2519.91	1.66135
2522.67	1.84636
2525.42	2.199
2528.18	3.07368
2530.93	2.88345
2533.69	1.54399
2536.44	1.02809
2539.19	0.877707
2541.94	1.17151
2544.69	2.05007
2547.44	2.0082
2550.18	2.4166
2552.93	2.89293
2555.68	4.10585
2558.42	5.70968
2561.16	6.2512
2563.9	7.31208
2566.64	7.51946
2569.38	8.58192
2572.12	8.78047
2574.86	9.06017
2577.6	8.83448
2580.34	9.47916
2583.07	9.22596
2585.81	8.62152
2588.54	7.31238
2591.27	6.11669
2594	5.20834
2596.73	4.75409
2599.46	3.98977
2602.19	3.20042
2604.92	2.01226
2607.64	2.22954
2610.37	3.22443
2613.09	3.05035
2615.82	3.73427
2618.54	4.93168
2621.26	6.0419
2623.98	5.95018
2626.7	6.61481
2629.42	7.09218
2632.14	6.87662
2634.86	6.377
2637.57	6.14093
2640.29	6.43087
2643	6.05955
2645.72	6.21727
2648.43	4.80363
2651.14	3.91024
2653.85	2.47718
2656.56	2.20263
2659.27	1.78995
2661.97	1.3235
2664.68	0.824303
2667.38	0.661626
2670.09	1.79494
2672.79	2.52951
2675.49	3.59791
2678.2	4.0912
2680.89	5.05022
2683.59	5.12828
2686.29	4.95688
2688.99	5.7719
2691.69	4.91606
2694.38	6.62899
2697.08	6.88048
2699.77	7.47972
2702.46	7.82038
2705.16	8.89694
2707.85	9.26897
2710.54	9.55224
2713.23	8.80848
2715.92	8.0567
2718.6	8.39755
2721.29	8.14099
2723.97	8.32984
2726.66	8.07287
2729.34	8.07424
2732.02	8.04851
2734.7	7.8765
2737.39	7.45384
2740.06	6.38181
2742.74	5.87236
2745.42	4.80635
2748.1	4.14506
2750.77	2.977
2753.45	2.62903
2756.12	2.84972
2758.79	2.56457
2761.47	2.65442
2764.14	1.72382
2766.81	1.66373
2769.48	0.865963
2772.14	1.62564
2774.81	1.49995
2777.48	0.96689
2780.14	0.517442
2782.81	0.742653
2785.47	2.17254
2788.13	1.5004
2790.79	0.405634
2793.46	0.149687
2796.11	0.19521
2798.77	0.122417
2801.43	0.512368
2804.09	0.974326
2806.74	0.876178
2809.4	0.781689
2812.05	0.992748
2814.71	2.37296
2817.36	4.23525
2820.01	7.11068
2822.66	9.44704
2825.31	12.3216
2827.96	15.9136
2830.61	21.218
2833.25	26.5362
2835.9	32.3428
2838.54	38.627
2841.18	42.5676
2843.83	47.4483
2846.47	52.8991
2849.11	59.8558
2851.75	65.084
2854.39	69.5941
2857.03	75.0158
2859.67	80.3336
2862.3	84.6015
2864.94	87.9186
2867.57	90.2876
2870.21	91.1969
2872.84	92.8456
2875.47	94.9606
2878.1	97.3691
2880.73	99.5005
2883.36	102.452
2885.99	105.402
2888.61	107.859
2891.24	111.53
2893.87	115.682
2896.49	119.709
2899.11	125.413
2901.74	130.24
2904.36	136.393
2906.98	142.354
2909.6	151.173
2912.22	159.886
2914.83	168.061
2917.45	175.675
2920.07	182.687
2922.68	187.645
2925.3	192.366
2927.91	194.389
2930.52	196.026
2933.13	195.748
2935.74	194.576
2938.35	192.388
2940.96	189.077
2943.57	183.377
2946.18	178.139
2948.78	171.038
2951.39	163.174
2953.99	154.85
2956.6	146.711
2959.2	138.302
2961.8	130.743
2964.4	122.915
2967	115.14
2969.6	108.111
2972.2	102.483
2974.79	95.563
2977.39	88.7777
2979.98	82.7525
2982.58	76.2314
2985.17	70.1894
2987.76	63.1868
2990.36	57.6139
2992.95	52.1167
2995.54	46.8569
2998.12	42.4193
3000.71	37.9582
3003.3	32.7387
3005.88	26.996
3008.47	23.7465
3011.05	19.8611
3013.64	16.1307
3016.22	13.7484
3018.8	11.7411
3021.38	10.2932
3023.96	8.35077
3026.54	7.18561
3029.12	6.83562
3031.69	5.8745
3034.27	5.68851
3036.85	4.61698
3039.42	2.8993
3041.99	4.15882
3044.57	5.02463
3047.14	5.51634
3049.71	5.73948
3052.28	5.59353
3054.85	5.30776
3057.42	6.02093
3059.98	5.70129
3062.55	5.52114
3065.11	5.3244
3067.68	4.75903
3070.24	4.85493
3072.8	4.92959
3075.37	4.32891
3077.93	4.20776
3080.49	4.22824
3083.05	4.0297
3085.61	3.93647
3088.16	3.07555
3090.72	2.46613
3093.27	3.57434
3095.83	3.43604
3098.38	2.71166
3100.94	1.56155
3103.49	1.57152
3106.04	2.93841
3108.59	3.31512
3111.14	2.49221
3113.69	1.80723
3116.23	2.17258
3118.78	3.22876
3121.33	4.28042
3123.87	4.57319
3126.42	6.30821
3128.96	7.54985
3131.5	8.45883
3134.04	9.88167
3136.58	11.129
3139.12	11.862
3141.66	13.2016
3144.2	14.2659
3146.74	15.6945
3149.27	15.399