File: data/Raman/poly_smoothed/Mb_50_18_20_1x_45s_532 nm_x100_100%_600 gr_mm_01.txt
#Acq. time (s)=	45
#Accumulations=	2
#Range (cm-¹)=	200...3150
#Windows=	2
#Auto scanning=	Off
#Autofocus=	Off
#Macrospot=	Off
#AutoExposure=	Off
#Spike filter=	Multiple accum.
#Delay time (s)=	0
#Binning=	1
#Readout mode=	Signal
#DeNoise=	Off
#ICS correction=	On
#Dark correction=	Off
#Inst. Process=	Off
#Detector Gain=	Best Dynamic Range
#Detector ADC=	20 kHz
#Detector temperature (°C)=	-69.85
#Instrument=	LabRAM HR Evol
#Detector=	Synapse
#Objective=	x100
#Grating=	600 gr/mm
#ND Filter=	100%
#Laser (nm)=	532
#Hole=	100.021
#Range=	Auto
#Laser Pol.=	No
#Raman. Pol.=	No
#Laser Pol. (°)=	-0.0007625
#Raman Pol. (°)=	89.9995
#Collection=	Microscope
#StageXY=	Marzhauser
#StageZ=	Marzhauser
#X (µm)=	28275.7
#Y (µm)=	-3325.3
#Z (µm)=	1040.6
#Full time(mm:ss)=	3:19
#Project=
#Sample=
#Site=
#Title=	Mb_50_18_20_2x_45s_532 nm_x100_100%_600 gr_mm
#Remark=
#Date=	12.07.2022 12:19
#Acquired=	12.07.2022 12:19:26
#Base:Fit=	10.08.2022 10:49:18
#Base:Sub=	10.08.2022 10:49:30
#Filter:Polynom=	16.08.2022 10:14:59
#AxisType[0]=Intens
#AxisUnit[0]=Cnt
#AxisType[1]=Spectr
#AxisUnit[1]=1/cm
200.388	23.6688
204.019	19.9217
207.646	17.5004
211.274	15.2896
214.899	13.927
218.524	12.8295
222.146	10.1082
225.766	9.50894
229.388	9.67481
233.005	8.95485
236.621	9.60667
240.236	8.35124
243.852	7.62605
247.464	7.14585
251.074	6.3891
254.683	4.45832
258.291	5.82578
261.897	5.61223
265.504	5.50412
269.108	5.38451
272.71	5.59365
276.311	4.44863
279.91	4.41716
283.508	4.21569
287.105	5.16222
290.698	6.34527
294.291	6.26541
297.884	7.85289
301.475	10.9797
305.064	13.2748
308.652	16.102
312.237	16.9431
315.822	19.7435
319.406	20.2413
322.987	21.7463
326.568	20.7545
330.148	20.1224
333.724	18.8908
337.301	17.4906
340.875	16.2953
344.449	15.4336
348.02	15.0998
351.592	14.8892
355.16	15.8115
358.728	18.7921
362.294	22.2912
365.858	23.2995
369.422	26.2143
372.983	28.9156
376.543	31.3225
380.102	32.1851
383.661	33.895
387.216	35.3897
390.771	38.0524
394.324	38.1509
397.875	36.8738
401.425	34.3946
404.974	31.7886
408.524	28.2435
412.07	24.0256
415.614	21.2638
419.156	16.2077
422.698	11.6868
426.238	8.19257
429.777	5.70482
433.315	3.39406
436.852	2.62143
440.387	1.96782
443.919	1.89216
447.451	1.88284
450.982	1.90102
454.512	0.372801
458.038	0.804317
461.565	2.08404
465.091	1.99724
468.613	1.79048
472.136	3.52854
475.655	5.38894
479.176	8.77504
482.692	11.5283
486.21	15.4733
489.724	19.2473
493.237	25.3775
496.75	30.1573
500.26	32.9015
503.771	36.3723
507.279	38.1385
510.785	41.2186
514.289	42.0683
517.793	42.4922
521.297	41.5415
524.797	41.178
528.297	39.2207
531.795	37.0128
535.291	33.8341
538.787	29.8754
542.281	26.2799
545.773	23.1618
549.264	18.4528
552.754	13.6322
556.243	13.1227
559.73	9.8842
563.216	8.08007
566.701	7.77627
570.182	9.20222
573.664	10.6173
577.145	11.5183
580.624	11.6449
584.1	10.1182
587.577	10.0822
591.052	11.0671
594.524	11.0124
597.997	11.1059
601.466	10.7662
604.936	9.93567
608.403	9.43429
611.87	8.31276
615.334	7.01677
618.799	5.81188
622.26	5.3644
625.72	3.71456
629.181	3.21091
632.638	3.5292
636.095	3.1666
639.551	3.70098
643.005	2.11423
646.457	3.23748
649.908	3.92656
653.357	2.98592
656.806	7.32782
660.253	11.08
663.7	14.3394
667.145	18.3947
670.588	21.7374
674.027	26.491
677.468	30.0911
680.907	32.6976
684.345	37.2074
687.781	39.2603
691.216	40.361
694.65	40.807
698.081	40.7121
701.512	39.9297
704.942	39.2379
708.371	39.133
711.796	38.6245
715.222	37.8441
718.645	36.9332
722.068	35.3842
725.49	32.4392
728.909	30.6983
732.329	31.1946
735.745	31.3377
739.16	41.0908
742.576	51.2051
745.988	57.8812
749.401	66.7416
752.811	74.2076
756.22	84.3217
759.627	92.4907
763.035	98.2344
766.44	104.545
769.843	109.937
773.245	111.829
776.646	112.146
780.046	113.34
783.444	112.453
786.841	111.946
790.237	110.043
793.631	105.84
797.024	100.895
800.416	95.0494
803.807	89.2122
807.196	84.0557
810.584	78.0307
813.971	74.529
817.354	73.8698
820.739	72.1425
824.122	70.1494
827.503	69.4406
830.882	70.0333
834.261	68.8048
837.637	68.5998
841.013	67.7863
844.389	65.9074
847.761	62.8046
851.131	61.9695
854.503	59.3897
857.871	57.3336
861.24	55.8779
864.606	53.9832
867.97	52.585
871.336	50.103
874.698	47.5077
878.058	45.3349
881.418	44.5058
884.778	45.2774
888.135	44.2094
891.49	43.65
894.845	42.9065
898.198	43.2049
901.55	43.7518
904.901	43.033
908.25	43.238
911.598	44.2194
914.945	45.4828
918.291	45.2621
921.635	45.2739
924.978	44.6145
928.318	44.184
931.659	42.1562
934.998	41.3585
938.336	38.3069
941.671	37.0434
945.007	33.8386
948.339	33.1563
951.672	30.2122
955.004	29.4022
958.333	28.2421
961.662	26.9401
964.989	25.4156
968.315	24.5846
971.639	23.9723
974.962	24.14
978.285	24.8241
981.605	25.3389
984.924	24.0581
988.243	24.3184
991.56	24.6341
994.875	27.675
998.188	30.0285
1001.5	32.472
1004.81	39.8385
1008.12	44.8989
1011.43	48.8776
1014.74	52.7272
1018.05	56.2176
1021.35	58.4146
1024.65	60.0149
1027.96	61.2826
1031.26	62.2482
1034.56	61.0747
1037.86	60.1263
1041.16	57.4121
1044.45	54.0547
1047.75	51.9756
1051.04	49.2958
1054.33	45.1439
1057.62	43.9092
1060.91	41.2535
1064.2	38.6572
1067.49	37.5845
1070.77	36.7486
1074.06	38.2967
1077.34	39.5078
1080.62	40.664
1083.91	42.2873
1087.18	44.0042
1090.46	44.2773
1093.74	44.86
1097.02	44.1816
1100.29	42.3275
1103.56	39.9629
1106.84	38.9594
1110.11	36.1306
1113.38	32.3116
1116.64	29.569
1119.91	26.0076
1123.18	23.8595
1126.44	19.2044
1129.7	17.5266
1132.97	16.1406
1136.23	17.0971
1139.49	17.5933
1142.74	16.667
1146	16.3115
1149.26	14.6349
1152.51	12.4984
1155.76	10.9644
1159.01	10.7559
1162.27	10.4479
1165.51	10.3419
1168.76	10.1609
1172.01	11.7411
1175.25	12.1441
1178.5	12.0408
1181.74	10.5486
1184.98	10.4577
1188.22	9.48101
1191.46	8.32656
1194.7	8.39628
1197.94	8.30509
1201.17	7.57069
1204.41	7.61368
1207.64	9.21995
1210.87	10.0847
1214.1	10.5267
1217.33	12.369
1220.56	13.8947
1223.79	14.9569
1227.01	18.3332
1230.23	18.2086
1233.46	21.3471
1236.68	23.8772
1239.9	26.4813
1243.12	29.3493
1246.34	31.1178
1249.55	33.9802
1252.77	34.4303
1255.98	34.5094
1259.2	34.4724
1262.41	34.4689
1265.62	36.403
1268.83	36.7449
1272.03	36.5953
1275.24	35.2681
1278.45	36.0795
1281.65	36.7689
1284.85	37.4909
1288.06	38.6588
1291.26	39.6713
1294.46	43.0021
1297.66	43.0156
1300.85	42.8187
1304.05	43.0958
1307.24	43.4302
1310.43	44.8375
1313.63	45.0153
1316.82	45.0531
1320.01	44.8677
1323.2	45.18
1326.38	44.5967
1329.57	43.8985
1332.76	42.6056
1335.94	42.6496
1339.12	41.6625
1342.3	40.0991
1345.48	37.7588
1348.66	36.091
1351.84	35.069
1355.01	32.626
1358.19	31.366
1361.36	29.3498
1364.53	26.4918
1367.71	25.2389
1370.88	22.7822
1374.04	20.721
1377.21	18.3439
1380.38	16.8912
1383.54	15.9069
1386.71	16.7078
1389.87	16.7749
1393.03	16.7014
1396.19	17.7952
1399.35	18.635
1402.51	19.0557
1405.67	20.34
1408.82	23.5587
1411.98	25.8809
1415.13	28.3113
1418.28	31.5386
1421.43	36.0746
1424.58	41.7439
1427.73	47.2066
1430.88	50.9707
1434.02	54.3573
1437.17	57.1089
1440.31	60.0219
1443.45	61.7559
1446.6	62.782
1449.74	64.8408
1452.87	63.0566
1456.01	62.6305
1459.15	61.8817
1462.28	60.5126
1465.42	58.6799
1468.55	57.601
1471.68	55.5139
1474.81	52.4687
1477.94	48.9954
1481.07	45.018
1484.2	42.6756
1487.32	39.1987
1490.45	37.3407
1493.57	34.5019
1496.69	32.4844
1499.81	31.6096
1502.93	29.7556
1506.05	27.2841
1509.17	24.589
1512.28	22.9344
1515.4	20.091
1518.51	18.0009
1521.63	15.4669
1524.74	14.167
1527.85	13.6313
1530.96	12.557
1534.06	12.6014
1537.17	14.0044
1540.28	14.8675
1543.38	16.5096
1546.48	17.231
1549.59	16.9517
1552.69	18.0333
1555.79	19.0699
1558.88	19.7173
1561.98	21.137
1565.08	22.3199
1568.17	22.6647
1571.27	24.314
1574.36	27.0291
1577.45	29.6867
1580.54	31.1706
1583.63	32.686
1586.72	35.1214
1589.8	36.5299
1592.89	37.7261
1595.97	38.8098
1599.06	39.6607
1602.14	40.1114
1605.22	40.9312
1608.3	40.4908
1611.38	40.496
1614.46	40.7488
1617.53	40.6522
1620.61	40.758
1623.68	40.7939
1626.75	42.8391
1629.82	43.71
1632.9	44.7867
1635.96	47.0404
1639.03	47.8957
1642.1	48.8764
1645.16	50.2182
1648.23	52.231
1651.29	53.4504
1654.36	54.7995
1657.42	53.8597
1660.48	52.9074
1663.53	52.0071
1666.59	48.9805
1669.65	46.3424
1672.7	43.2794
1675.76	39.8066
1678.81	35.6658
1681.86	31.2305
1684.91	27.3538
1687.96	24.7308
1691.01	22.4735
1694.06	19.866
1697.11	18.5606
1700.15	17.5554
1703.2	15.805
1706.24	13.1308
1709.28	11.562
1712.32	10.4573
1715.36	8.90772
1718.4	8.82563
1721.43	8.59692
1724.47	6.78866
1727.5	7.03984
1730.54	7.18848
1733.57	6.12938
1736.6	5.91647
1739.63	5.70447
1742.66	4.59127
1745.69	4.32883
1748.72	3.52978
1751.74	2.25697
1754.77	1.98061
1757.79	1.94892
1760.81	2.32018
1763.83	2.68548
1766.85	2.9854
1769.87	3.41292
1772.89	3.57695
1775.91	2.99385
1778.92	3.52828
1781.94	4.30905
1784.95	5.38639
1787.96	4.94464
1790.97	4.27059
1793.98	4.79102
1796.99	4.97143
1800	5.84592
1803	6.74871
1806.01	6.89909
1809.01	5.96012
1812.02	5.06158
1815.02	5.04154
1818.02	4.18263
1821.02	3.32039
1824.02	3.36627
1827.01	3.31001
1830.01	2.99036
1833	2.39837
1836	2.55332
1838.99	2.96705
1841.98	3.4042
1844.97	2.96029
1847.96	3.02778
1850.95	3.17793
1853.94	2.90108
1856.92	2.37817
1859.91	1.85281
1862.89	1.90412
1865.88	2.09197
1868.86	1.82351
1871.84	2.99597
1874.82	2.81908
1877.8	2.81897
1880.77	2.92394
1882.51	2.73351
1885.5	2.55293
1888.48	2.08967
1891.47	2.20075
1894.46	2.24641
1897.44	2.71697
1900.42	2.07496
1903.41	1.93387
1906.39	2.37318
1909.37	3.86059
1912.35	4.58212
1915.32	3.3771
1918.3	2.67367
1921.28	2.40939
1924.25	1.91537
1927.22	2.06797
1930.2	2.80235
1933.17	3.07678
1936.14	2.79042
1939.11	1.92943
1942.08	2.7698
1945.04	3.31513
1948.01	4.25555
1950.97	4.74727
1953.94	4.53777
1956.9	4.08033
1959.86	3.45474
1962.82	4.42966
1965.78	3.7298
1968.74	4.10512
1971.69	3.96215
1974.65	3.839
1977.61	4.08132
1980.56	5.41194
1983.51	4.67219
1986.46	4.55976
1989.41	4.16852
1992.36	4.96835
1995.31	5.90738
1998.26	6.17383
2001.2	7.2195
2004.15	8.01804
2007.09	8.18939
2010.04	8.24145
2012.98	8.02149
2015.92	7.85811
2018.86	9.58037
2021.8	10.1368
2024.74	9.68939
2027.67	9.98217
2030.61	10.6102
2033.54	9.90841
2036.47	10.3764
2039.41	10.2581
2042.34	10.6286
2045.27	10.3952
2048.2	11.0834
2051.12	11.4953
2054.05	11.7524
2056.98	13.1854
2059.9	14.5868
2062.82	16.5592
2065.75	17.5998
2068.67	18.1188
2071.59	18.7685
2074.51	19.1866
2077.43	19.8897
2080.34	18.549
2083.26	18.3806
2086.17	19.5289
2089.09	21.6354
2092	23.0903
2094.91	24.6844
2097.82	26.4135
2100.73	27.1774
2103.64	28.9904
2106.55	30.8594
2109.46	32.7525
2112.36	34.7778
2115.27	37.2235
2118.17	39.6177
2121.07	42.6371
2123.97	46.4293
2126.87	49.6225
2129.77	53.096
2132.67	56.3399
2135.57	60.4414
2138.46	62.4956
2141.36	64.9056
2144.25	68.201
2147.14	71.7418
2150.03	74.4387
2152.92	76.5726
2155.81	79.4868
2158.7	81.1704
2161.59	82.4651
2164.48	84.0643
2167.36	84.2908
2170.25	84.1849
2173.13	82.769
2176.01	82.5665
2178.89	80.829
2181.77	79.2434
2184.65	77.4543
2187.53	75.4823
2190.41	73.9086
2193.28	70.4838
2196.16	68.44
2199.03	65.3349
2201.9	62.025
2204.78	60.0004
2207.65	57.4472
2210.51	54.2891
2213.38	52.2901
2216.25	50.194
2219.12	47.3244
2221.98	46.2582
2224.85	43.1158
2227.71	40.917
2230.57	38.5363
2233.43	37.1676
2236.29	34.5494
2239.15	31.3622
2242.01	29.1612
2244.87	27.5602
2247.73	25.9243
2250.58	24.5147
2253.43	23.1331
2256.29	22.653
2259.14	21.0048
2261.99	19.3197
2264.84	17.5276
2267.69	17.0946
2270.54	16.1102
2273.38	16.2431
2276.23	15.6748
2279.07	14.3576
2281.92	13.8032
2284.76	13.6632
2287.6	13.4079
2290.44	12.7621
2293.28	11.5986
2296.12	10.6166
2298.96	10.7971
2301.79	11.2989
2304.63	11.3874
2307.46	11.2471
2310.3	11.2495
2313.13	11.5348
2315.96	11.3997
2318.79	11.6876
2321.62	11.1209
2324.45	10.8576
2327.27	9.60975
2330.1	8.54129
2332.93	8.59203
2335.75	7.52291
2338.57	6.79198
2341.4	6.37805
2344.22	5.73305
2347.04	3.89925
2349.86	3.1218
2352.67	1.61767
2355.49	0.883798
2358.31	0.29743
2361.12	-0.357056
2363.94	0.319071
2366.75	1.03949
2369.56	1.35826
2372.37	2.23035
2375.18	2.11124
2377.99	2.27256
2380.8	2.68795
2383.61	1.57697
2386.41	2.02745
2389.22	2.47213
2392.02	1.92418
2394.82	2.14865
2397.63	2.92269
2400.43	2.79259
2403.23	2.52002
2406.02	2.02464
2408.82	3.06624
2411.62	4.02649
2414.41	5.1079
2417.21	5.53319
2420	5.3706
2422.79	6.572
2425.59	7.3347
2428.38	8.0639
2431.17	8.25834
2433.96	8.0451
2436.74	7.15637
2439.53	6.60534
2442.32	5.24673
2445.1	4.34683
2447.88	3.84447
2450.67	3.49923
2453.45	3.28392
2456.23	3.00614
2459.01	2.9123
2461.79	1.89563
2464.57	2.31982
2467.34	2.09094
2470.12	2.63065
2472.89	2.22463
2475.67	2.81237
2478.44	3.57973
2481.21	3.80786
2483.98	4.41179
2486.75	4.02479
2489.52	4.21314
2492.29	3.71672
2495.06	4.31216
2497.82	4.02383
2500.59	3.53517
2503.35	3.70265
2506.11	2.82061
2508.88	2.13895
2511.63	2.17421
2514.39	2.56819
2517.15	2.91438
2519.91	2.66928
2522.67	2.40483
2525.42	2.82957
2528.18	2.40186
2530.93	2.53998
2533.69	2.14835
2536.44	2.08309
2539.19	1.53871
2541.94	1.79809
2544.69	1.99302
2547.44	1.88648
2550.18	1.97958
2552.93	2.45072
2555.68	2.75234
2558.42	2.90732
2561.16	3.72611
2563.9	3.47038
2566.64	4.06175
2569.38	4.93156
2572.12	5.76978
2574.86	5.88585
2577.6	4.91021
2580.34	5.34387
2583.07	5.66652
2585.81	4.57153
2588.54	5.11206
2591.27	5.50942
2594	5.08729
2596.73	3.63752
2599.46	4.1485
2602.19	4.36668
2604.92	4.22793
2607.64	4.60046
2610.37	4.39512
2613.09	4.08776
2615.82	5.02128
2618.54	5.74282
2621.26	5.26501
2623.98	5.37346
2626.7	5.868
2629.42	6.34923
2632.14	6.45917
2634.86	6.32162
2637.57	6.09615
2640.29	5.13843
2643	3.35121
2645.72	3.59734
2648.43	3.78866
2651.14	3.33938
2653.85	3.14324
2656.56	3.37826
2659.27	2.73519
2661.97	2.48854
2664.68	3.43281
2667.38	3.82956
2670.09	3.37338
2672.79	3.82824
2675.49	3.92307
2678.2	4.55751
2680.89	5.57675
2683.59	5.94625
2686.29	6.73367
2688.99	6.69237
2691.69	8.05062
2694.38	9.05113
2697.08	8.29261
2699.77	8.94516
2702.46	8.95216
2705.16	9.26834
2707.85	9.95406
2710.54	10.7014
2713.23	11.5567
2715.92	11.4211
2718.6	10.3091
2721.29	10.0971
2723.97	10.0203
2726.66	10.0542
2729.34	10.2495
2732.02	9.16733
2734.7	8.39342
2737.39	8.58591
2740.06	8.13576
2742.74	8.7436
2745.42	8.03768
2748.1	7.62195
2750.77	7.52872
2753.45	7.29904
2756.12	8.14161
2758.79	7.26063
2761.47	5.932
2764.14	5.6725
2766.81	4.69854
2769.48	5.08813
2772.14	5.1909
2774.81	4.55138
2777.48	4.10358
2780.14	3.72479
2782.81	2.03258
2785.47	1.81271
2788.13	2.17319
2790.79	1.49325
2793.46	1.32651
2796.11	1.05068
2798.77	1.5388
2801.43	2.43213
2804.09	2.59725
2806.74	3.01701
2809.4	3.20681
2812.05	3.7474
2814.71	3.61633
2817.36	4.62558
2820.01	6.31889
2822.66	8.1469
2825.31	10.7492
2827.96	14.8632
2830.61	19.8625
2833.25	25.3695
2835.9	29.7818
2838.54	35.2651
2841.18	40.9806
2843.83	47.3769
2846.47	53.1122
2849.11	58.9925
2851.75	65.3573
2854.39	70.585
2857.03	76.8929
2859.67	82.8008
2862.3	87.6542
2864.94	92.3995
2867.57	95.6053
2870.21	98.8633
2872.84	101.537
2875.47	101.82
2878.1	102.54
2880.73	104.964
2883.36	107.534
2885.99	110.214
2888.61	112.19
2891.24	115.915
2893.87	118.9
2896.49	122.216
2899.11	126.101
2901.74	130.981
2904.36	136.163
2906.98	143.162
2909.6	149.504
2912.22	158.252
2914.83	165.735
2917.45	172.928
2920.07	179.772
2922.68	186.068
2925.3	190.969
2927.91	193.975
2930.52	195.173
2933.13	196.035
2935.74	195.482
2938.35	192.845
2940.96	189.435
2943.57	185.796
2946.18	180.7
2948.78	174.038
2951.39	166.697
2953.99	159.429
2956.6	152.943
2959.2	145.519
2961.8	139.191
2964.4	132.451
2967	125.815
2969.6	118.846
2972.2	113.101
2974.79	108.483
2977.39	102.105
2979.98	95.6824
2982.58	88.9166
2985.17	80.726
2987.76	73.5307
2990.36	65.261
2992.95	58.72
2995.54	52.6812
2998.12	46.9991
3000.71	42.4286
3003.3	36.685
3005.88	31.561
3008.47	25.9939
3011.05	21.172
3013.64	17.9892
3016.22	15.171
3018.8	13.5481
3021.38	11.9679
3023.96	9.55156
3026.54	7.81166
3029.12	6.39635
3031.69	4.99721
3034.27	4.85741
3036.85	5.99194
3039.42	5.81982
3041.99	5.49358
3044.57	5.16224
3047.14	4.72944
3049.71	4.03128
3052.28	4.30128
3054.85	6.05366
3057.42	6.03256
3059.98	5.96874
3062.55	5.42212
3065.11	5.85655
3067.68	3.88657
3070.24	3.61732
3072.8	3.07441
3075.37	2.98395
3077.93	1.97379
3080.49	1.54645
3083.05	0.629114
3085.61	-0.373759
3088.16	-0.490692
3090.72	-1.10999
3093.27	-1.17572
3095.83	-0.603724
3098.38	-0.383757
3100.94	0.460884
3103.49	1.02973
3106.04	1.77176
3108.59	2.59876
3111.14	2.85455
3113.69	3.2219
3116.23	4.28354
3118.78	4.56321
3121.33	4.65912
3123.87	5.57895
3126.42	6.38583
3128.96	7.1463
3131.5	7.06907
3134.04	8.22653
3136.58	8.76661
3139.12	9.47099
3141.66	10.3172
3144.2	11.1486
3146.74	12.3499
3149.27	13.8881