File: data/Raman/poly_smoothed/Mb_50_18_08_1x_45s_532 nm_x100_100%_600 gr_mm_01.txt
#Acq. time (s)=	45
#Accumulations=	2
#Range (cm-¹)=	200...3150
#Windows=	2
#Auto scanning=	Off
#Autofocus=	Off
#Macrospot=	Off
#AutoExposure=	Off
#Spike filter=	Multiple accum.
#Delay time (s)=	0
#Binning=	1
#Readout mode=	Signal
#DeNoise=	Off
#ICS correction=	On
#Dark correction=	Off
#Inst. Process=	Off
#Detector Gain=	Best Dynamic Range
#Detector ADC=	20 kHz
#Detector temperature (°C)=	-69.85
#Instrument=	LabRAM HR Evol
#Detector=	Synapse
#Objective=	x100
#Grating=	600 gr/mm
#ND Filter=	100%
#Laser (nm)=	532
#Hole=	100.021
#Range=	Auto
#Laser Pol.=	No
#Raman. Pol.=	No
#Laser Pol. (°)=	-0.0007625
#Raman Pol. (°)=	89.9995
#Collection=	Microscope
#StageXY=	Marzhauser
#StageZ=	Marzhauser
#X (µm)=	19372.1
#Y (µm)=	3086.5
#Z (µm)=	1047
#Full time(mm:ss)=	3:18
#Project=
#Sample=
#Site=
#Title=	Mb_50_18_08_2x_45s_532 nm_x100_100%_600 gr_mm
#Remark=
#Date=	12.07.2022 10:52
#Acquired=	12.07.2022 10:52:38
#Base:Fit=	10.08.2022 10:49:18
#Base:Sub=	10.08.2022 10:49:30
#Filter:Polynom=	16.08.2022 10:14:59
#AxisType[0]=Intens
#AxisUnit[0]=Cnt
#AxisType[1]=Spectr
#AxisUnit[1]=1/cm
200.388	75.2162
204.019	66.6606
207.646	58.2952
211.274	51.4577
214.899	45.9982
218.524	41.3143
222.146	35.4197
225.766	28.7369
229.388	25.1525
233.005	21.0937
236.621	20.1153
240.236	18.0284
243.852	15.6002
247.464	15.0557
251.074	16.0089
254.683	15.6564
258.291	15.5102
261.897	14.5443
265.504	14.9323
269.108	14.4489
272.71	14.0027
276.311	13.0628
279.91	12.0158
283.508	11.9903
287.105	11.0053
290.698	11.7255
294.291	12.4412
297.884	14.7794
301.475	15.5542
305.064	16.3991
308.652	16.299
312.237	15.3739
315.822	16.5362
319.406	16.8857
322.987	17.2196
326.568	17.2885
330.148	16.286
333.724	16.1204
337.301	16.1231
340.875	15.2051
344.449	12.6998
348.02	12.2265
351.592	13.0069
355.16	14.5533
358.728	15.2628
362.294	17.2858
365.858	19.687
369.422	21.815
372.983	23.825
376.543	27.1222
380.102	29.4987
383.661	31.6852
387.216	32.037
390.771	32.8741
394.324	32.3553
397.875	31.872
401.425	29.0335
404.974	26.4239
408.524	23.3575
412.07	20.188
415.614	16.1365
419.156	11.3153
422.698	7.88258
426.238	4.91326
429.777	3.96845
433.315	2.09979
436.852	0.93609
440.387	0.82992
443.919	-1.47798
447.451	-1.18866
450.982	0.390622
454.512	-0.795988
458.038	0.586228
461.565	0.989793
465.091	3.00472
468.613	2.78308
472.136	1.25181
475.655	5.22851
479.176	6.0842
482.692	9.93835
486.21	10.9055
489.724	14.3981
493.237	16.8064
496.75	20.0456
500.26	23.6654
503.771	26.1199
507.279	29.2822
510.785	30.8357
514.289	33.3619
517.793	33.6093
521.297	34.2628
524.797	34.8556
528.297	36.445
531.795	35.5052
535.291	35.5141
538.787	33.0801
542.281	29.3163
545.773	27.2862
549.264	24.6755
552.754	21.6312
556.243	17.0921
559.73	15.2621
563.216	13.203
566.701	10.9598
570.182	8.20947
573.664	5.82939
577.145	4.78673
580.624	4.98937
584.1	4.13471
587.577	1.64858
591.052	0.560419
594.524	-0.696036
597.997	-0.147289
601.466	1.03436
604.936	2.23489
608.403	2.92148
611.87	4.27799
615.334	4.26747
618.799	3.55731
622.26	2.82751
625.72	2.99796
629.181	2.82699
632.638	3.72002
636.095	5.25115
639.551	4.93415
643.005	6.38462
646.457	5.62697
649.908	5.54792
653.357	4.91561
656.806	6.13929
660.253	6.47369
663.7	8.5397
667.145	9.41515
670.588	9.91959
674.027	11.6006
677.468	14.6482
680.907	16.452
684.345	18.6534
687.781	19.4014
691.216	20.7443
694.65	21.0274
698.081	22.3368
701.512	23.3745
704.942	26.1497
708.371	28.4578
711.796	30.3715
715.222	31.8775
718.645	32.7678
722.068	33.7757
725.49	34.4188
728.909	35.2323
732.329	36.9146
735.745	41.4006
739.16	45.5878
742.576	52.8842
745.988	59.5438
749.401	67.4543
752.811	76.1442
756.22	81.8243
759.627	86.3047
763.035	90.1733
766.44	93.2984
769.843	96.5836
773.245	99.2548
776.646	100.865
780.046	100.438
783.444	100.468
786.841	99.7133
790.237	96.4118
793.631	92.923
797.024	89.2645
800.416	85.7548
803.807	80.8291
807.196	78.3967
810.584	74.4015
813.971	71.925
817.354	70.5116
820.739	69.425
824.122	69.1404
827.503	68.5191
830.882	66.676
834.261	65.1305
837.637	62.4603
841.013	57.978
844.389	54.1785
847.761	51.5998
851.131	51.0195
854.503	49.5381
857.871	45.357
861.24	42.614
864.606	39.6986
867.97	37.9768
871.336	35.9502
874.698	34.411
878.058	34.8688
881.418	34.538
884.778	33.5564
888.135	32.4423
891.49	34.5122
894.845	34.8922
898.198	36.1971
901.55	37.2929
904.901	36.6488
908.25	37.3005
911.598	38.7907
914.945	37.9245
918.291	36.8481
921.635	35.4489
924.978	33.9845
928.318	33.3518
931.659	34.1869
934.998	32.227
938.336	29.9831
941.671	27.9722
945.007	26.0392
948.339	24.9208
951.672	23.7406
955.004	23.0638
958.333	21.6786
961.662	20.7038
964.989	18.5933
968.315	18.4867
971.639	19.2675
974.962	20.8599
978.285	21.7225
981.605	22.603
984.924	23.203
988.243	23.5079
991.56	24.5895
994.875	26.919
998.188	28.2219
1001.5	30.7527
1004.81	34.616
1008.12	39.2428
1011.43	43.3907
1014.74	47.0125
1018.05	50.3022
1021.35	52.2876
1024.65	54.1075
1027.96	56.0999
1031.26	57.0226
1034.56	56.3131
1037.86	56.0928
1041.16	54.8838
1044.45	53.9172
1047.75	52.6317
1051.04	50.5361
1054.33	48.3514
1057.62	46.4109
1060.91	43.218
1064.2	41.0787
1067.49	38.7117
1070.77	37.1465
1074.06	37.2653
1077.34	37.7565
1080.62	37.323
1083.91	37.307
1087.18	39.4552
1090.46	38.9041
1093.74	39.4849
1097.02	39.6137
1100.29	38.7542
1103.56	37.6322
1106.84	37.2181
1110.11	36.6512
1113.38	35.4812
1116.64	34.0746
1119.91	32.2291
1123.18	28.3326
1126.44	25.5753
1129.7	23.948
1132.97	22.172
1136.23	18.9493
1139.49	19.1456
1142.74	15.7883
1146	13.2769
1149.26	10.3826
1152.51	8.00465
1155.76	7.08653
1159.01	5.88761
1162.27	5.48757
1165.51	5.41149
1168.76	6.65543
1172.01	7.52299
1175.25	9.49334
1178.5	9.85661
1181.74	11.1971
1184.98	11.4231
1188.22	11.12
1191.46	11.7494
1194.7	11.1479
1197.94	10.9693
1201.17	10.8205
1204.41	12.8113
1207.64	14.3131
1210.87	13.6626
1214.1	13.5986
1217.33	15.0919
1220.56	15.8389
1223.79	15.5611
1227.01	15.7879
1230.23	16.5919
1233.46	18.8075
1236.68	20.1472
1239.9	22.3331
1243.12	24.0847
1246.34	26.2735
1249.55	27.6776
1252.77	29.9687
1255.98	32.4439
1259.2	34.4008
1262.41	35.295
1265.62	37.901
1268.83	40.9994
1272.03	43.9519
1275.24	47.3784
1278.45	49.8058
1281.65	52.165
1284.85	55.3861
1288.06	57.0348
1291.26	58.5763
1294.46	60.6239
1297.66	61.118
1300.85	61.2183
1304.05	60.6053
1307.24	59.6434
1310.43	58.4183
1313.63	57.101
1316.82	55.4377
1320.01	54.9403
1323.2	52.7583
1326.38	51.0981
1329.57	49.8915
1332.76	48.4463
1335.94	47.42
1339.12	44.8835
1342.3	42.1588
1345.48	41.5439
1348.66	39.7656
1351.84	37.6359
1355.01	35.9243
1358.19	33.5995
1361.36	32.6166
1364.53	31.7602
1367.71	30.1631
1370.88	28.2451
1374.04	26.088
1377.21	23.0903
1380.38	22.0336
1383.54	19.2572
1386.71	17.4761
1389.87	16.0279
1393.03	14.3976
1396.19	13.8344
1399.35	13.3402
1402.51	14.7645
1405.67	16.5298
1408.82	19.6277
1411.98	22.9863
1415.13	26.3726
1418.28	31.3377
1421.43	37.3835
1424.58	42.6876
1427.73	48.2096
1430.88	55.475
1434.02	61.3729
1437.17	66.6541
1440.31	70.9653
1443.45	72.1931
1446.6	74.069
1449.74	75.3961
1452.87	75.4146
1456.01	76.0644
1459.15	75.472
1462.28	73.3122
1465.42	70.1569
1468.55	67.134
1471.68	63.2522
1474.81	60.6522
1477.94	58.4426
1481.07	56.9788
1484.2	54.3044
1487.32	49.6599
1490.45	46.9404
1493.57	44.0712
1496.69	41.0044
1499.81	37.5412
1502.93	35.5317
1506.05	33.4898
1509.17	30.6376
1512.28	26.9066
1515.4	23.3294
1518.51	20.6718
1521.63	17.6705
1524.74	17.0597
1527.85	16.21
1530.96	16.8566
1534.06	17.4826
1537.17	17.84
1540.28	18.561
1543.38	20.6962
1546.48	23.546
1549.59	25.9357
1552.69	26.203
1555.79	26.0854
1558.88	25.405
1561.98	26.0605
1565.08	27.7889
1568.17	28.3333
1571.27	31.2294
1574.36	33.1216
1577.45	36.5081
1580.54	39.6576
1583.63	41.8959
1586.72	43.608
1589.8	44.6739
1592.89	46.3163
1595.97	48.1877
1599.06	49.2958
1602.14	50.1534
1605.22	50.105
1608.3	50.1293
1611.38	51.9493
1614.46	52.4198
1617.53	54.8099
1620.61	56.3891
1623.68	55.6915
1626.75	55.764
1629.82	56.0089
1632.9	56.2527
1635.96	58.8152
1639.03	61.4186
1642.1	63.0464
1645.16	66.0401
1648.23	69.1487
1651.29	71.3871
1654.36	71.9415
1657.42	72.1279
1660.48	70.9502
1663.53	68.683
1666.59	67.1319
1669.65	63.965
1672.7	60.3795
1675.76	56.4296
1678.81	51.8693
1681.86	47.198
1684.91	43.9127
1687.96	39.9233
1691.01	36.1459
1694.06	32.3402
1697.11	28.5715
1700.15	25.8709
1703.2	24.1866
1706.24	21.3848
1709.28	19.3025
1712.32	17.8776
1715.36	16.9242
1718.4	16.7529
1721.43	16.3842
1724.47	15.9396
1727.5	15.5969
1730.54	14.8911
1733.57	14.0314
1736.6	13.7363
1739.63	13.6624
1742.66	12.8079
1745.69	11.1715
1748.72	10.202
1751.74	8.4488
1754.77	6.85319
1757.79	5.97622
1760.81	4.6235
1763.83	4.25717
1766.85	4.62171
1769.87	4.64749
1772.89	4.32304
1775.91	4.36617
1778.92	4.62051
1781.94	3.81078
1784.95	3.77234
1787.96	4.23533
1790.97	4.58051
1793.98	4.3242
1796.99	5.10569
1800	5.68605
1803	5.92616
1806.01	5.91471
1809.01	6.18747
1812.02	5.34313
1815.02	5.67206
1818.02	5.62368
1821.02	4.82067
1824.02	4.88729
1827.01	5.08502
1830.01	4.70028
1833	5.44841
1836	6.49863
1838.99	7.06708
1841.98	6.86466
1844.97	6.69761
1847.96	6.97522
1850.95	8.13533
1853.94	8.91946
1856.92	7.89942
1859.91	8.50188
1862.89	8.27617
1865.88	8.52608
1868.86	9.4432
1871.84	8.96051
1874.82	8.30078
1877.8	7.35449
1880.77	7.84211
1882.51	7.46526
1885.5	7.44087
1888.48	7.80739
1891.47	8.30398
1894.46	8.20803
1897.44	7.96123
1900.42	7.25946
1903.41	7.31903
1906.39	6.2916
1909.37	4.93024
1912.35	4.47988
1915.32	4.42544
1918.3	3.86685
1921.28	4.25458
1924.25	3.92266
1927.22	3.58106
1930.2	3.56668
1933.17	3.24323
1936.14	2.92756
1939.11	3.08307
1942.08	2.79728
1945.04	1.04645
1948.01	0.0146674
1950.97	0.556135
1953.94	1.08014
1956.9	1.20533
1959.86	1.59605
1962.82	1.98471
1965.78	1.98402
1968.74	1.25789
1971.69	2.32206
1974.65	2.89446
1977.61	3.42099
1980.56	4.02159
1983.51	4.55599
1986.46	5.08665
1989.41	4.66637
1992.36	5.13972
1995.31	6.61387
1998.26	7.07418
2001.2	6.09605
2004.15	4.97444
2007.09	4.80143
2010.04	5.50443
2012.98	6.03483
2015.92	5.17148
2018.86	4.75843
2021.8	4.76861
2024.74	5.0642
2027.67	3.98556
2030.61	3.64184
2033.54	2.78009
2036.47	2.84189
2039.41	4.13176
2042.34	5.85981
2045.27	7.77697
2048.2	9.91101
2051.12	11.5241
2054.05	13.5698
2056.98	14.7054
2059.9	16.536
2062.82	19.0389
2065.75	21.3861
2068.67	23.7232
2071.59	24.4279
2074.51	26.1684
2077.43	28.7837
2080.34	31.4141
2083.26	33.0506
2086.17	35.211
2089.09	37.7028
2092	39.9584
2094.91	41.985
2097.82	44.8325
2100.73	48.2708
2103.64	51.5364
2106.55	55.8002
2109.46	58.9882
2112.36	63.5308
2115.27	68.3225
2118.17	72.6034
2121.07	76.9581
2123.97	82.6028
2126.87	87.9597
2129.77	92.2466
2132.67	97.4794
2135.57	105.045
2138.46	110.683
2141.36	114.909
2144.25	119.823
2147.14	124.386
2150.03	126.682
2152.92	131.693
2155.81	135.061
2158.7	138.01
2161.59	140.6
2164.48	142.14
2167.36	143.505
2170.25	143.569
2173.13	142.875
2176.01	140.058
2178.89	138.082
2181.77	134.475
2184.65	130.659
2187.53	126.422
2190.41	121.491
2193.28	118.027
2196.16	114.691
2199.03	109.688
2201.9	105.488
2204.78	101.656
2207.65	97.7043
2210.51	92.1784
2213.38	87.5713
2216.25	83.7203
2219.12	79.3028
2221.98	77.0787
2224.85	74.3475
2227.71	71.9652
2230.57	69.3599
2233.43	66.3496
2236.29	63.1141
2239.15	59.7464
2242.01	56.0799
2244.87	53.671
2247.73	50.3393
2250.58	47.3451
2253.43	44.1615
2256.29	41.7175
2259.14	40.227
2261.99	38.9093
2264.84	36.8591
2267.69	34.2127
2270.54	32.6455
2273.38	30.1212
2276.23	27.8974
2279.07	25.7457
2281.92	24.4979
2284.76	23.5493
2287.6	22.6488
2290.44	20.9527
2293.28	19.0144
2296.12	17.324
2298.96	17.0863
2301.79	16.0088
2304.63	16.013
2307.46	15.7946
2310.3	14.8635
2313.13	14.9587
2315.96	14.9728
2318.79	14.596
2321.62	14.6392
2324.45	15.6831
2327.27	15.9057
2330.1	16.1462
2332.93	16.0264
2335.75	16.3819
2338.57	14.9804
2341.4	14.2209
2344.22	12.4074
2347.04	11.9921
2349.86	11.9946
2352.67	12.2473
2355.49	12.3793
2358.31	11.6655
2361.12	10.4078
2363.94	11.42
2366.75	12.2066
2369.56	12.9787
2372.37	12.6418
2375.18	12.607
2377.99	11.7456
2380.8	12.0219
2383.61	11.9826
2386.41	11.7689
2389.22	11.4202
2392.02	11.0717
2394.82	10.8011
2397.63	9.80113
2400.43	9.36365
2403.23	8.23737
2406.02	6.81161
2408.82	5.94782
2411.62	6.6838
2414.41	6.30702
2417.21	7.786
2420	8.16831
2422.79	8.32831
2425.59	9.47952
2428.38	9.68444
2431.17	9.04626
2433.96	9.04296
2436.74	7.9134
2439.53	8.38484
2442.32	7.42438
2445.1	7.17302
2447.88	7.90453
2450.67	7.18378
2453.45	7.25163
2456.23	7.2693
2459.01	5.93022
2461.79	5.96563
2464.57	4.95818
2467.34	4.67149
2470.12	4.66689
2472.89	4.545
2475.67	4.78486
2478.44	4.76828
2481.21	4.96622
2483.98	5.10484
2486.75	4.27266
2489.52	3.72268
2492.29	4.63581
2495.06	3.28742
2497.82	2.35029
2500.59	1.53223
2503.35	1.36169
2506.11	1.63367
2508.88	0.793264
2511.63	0.332582
2514.39	0.39897
2517.15	0.268627
2519.91	-0.700681
2522.67	-0.976797
2525.42	-1.25732
2528.18	-1.38525
2530.93	-0.858351
2533.69	-0.777558
2536.44	-1.25749
2539.19	-0.704502
2541.94	-0.0582253
2544.69	0.947307
2547.44	0.61026
2550.18	0.354723
2552.93	0.0526537
2555.68	0.154003
2558.42	1.38446
2561.16	1.11875
2563.9	1.37072
2566.64	2.96182
2569.38	2.85795
2572.12	3.41583
2574.86	3.42568
2577.6	3.38673
2580.34	3.8625
2583.07	3.33417
2585.81	2.75606
2588.54	2.80816
2591.27	3.68101
2594	3.40542
2596.73	3.02437
2599.46	3.56749
2602.19	3.36477
2604.92	2.88913
2607.64	3.74825
2610.37	3.69612
2613.09	3.07012
2615.82	3.33036
2618.54	3.85418
2621.26	4.04163
2623.98	4.67637
2626.7	6.00466
2629.42	5.44521
2632.14	6.31262
2634.86	5.85105
2637.57	5.9845
2640.29	6.61282
2643	6.26781
2645.72	7.27024
2648.43	8.25961
2651.14	8.46634
2653.85	8.54451
2656.56	8.33712
2659.27	8.23326
2661.97	7.83307
2664.68	8.30697
2667.38	8.44632
2670.09	7.77279
2672.79	7.69964
2675.49	7.10759
2678.2	5.90083
2680.89	5.4802
2683.59	4.60283
2686.29	4.42821
2688.99	4.51523
2691.69	5.04975
2694.38	5.90177
2697.08	6.48528
2699.77	7.59417
2702.46	7.91019
2705.16	7.88608
2707.85	9.23253
2710.54	9.69849
2713.23	10.4445
2715.92	11.1273
2718.6	9.70831
2721.29	10.6713
2723.97	10.7176
2726.66	11.2108
2729.34	10.8718
2732.02	10.7429
2734.7	10.3551
2737.39	10.2331
2740.06	9.21515
2742.74	8.18255
2745.42	6.9012
2748.1	6.86737
2750.77	7.06925
2753.45	7.59739
2756.12	7.50514
2758.79	7.66972
2761.47	6.19238
2764.14	4.57086
2766.81	3.58965
2769.48	2.6604
2772.14	2.50514
2774.81	1.71007
2777.48	0.989758
2780.14	-0.135647
2782.81	-0.626322
2785.47	0.161429
2788.13	0.708762
2790.79	0.900069
2793.46	1.2322
2796.11	1.69551
2798.77	2.25734
2801.43	3.13884
2804.09	2.88143
2806.74	2.6787
2809.4	1.8789
2812.05	2.06492
2814.71	2.31224
2817.36	3.05401
2820.01	5.93394
2822.66	8.54364
2825.31	12.8776
2827.96	18.092
2830.61	24.5193
2833.25	32.9893
2835.9	41.0201
2838.54	49.3692
2841.18	58.2761
2843.83	68.2699
2846.47	79.2882
2849.11	91.8304
2851.75	102.948
2854.39	114.446
2857.03	124.618
2859.67	133.172
2862.3	142.258
2864.94	149.816
2867.57	155.24
2870.21	159.603
2872.84	163.879
2875.47	167.324
2878.1	171.298
2880.73	175
2883.36	180.123
2885.99	185.332
2888.61	190.262
2891.24	194.122
2893.87	200.532
2896.49	207.141
2899.11	214.853
2901.74	224.155
2904.36	233.386
2906.98	244.515
2909.6	256.514
2912.22	269.433
2914.83	281.385
2917.45	292.936
2920.07	303.174
2922.68	310.58
2925.3	315.937
2927.91	318.998
2930.52	320.986
2933.13	320.039
2935.74	318.584
2938.35	313.704
2940.96	306.906
2943.57	297.76
2946.18	287.526
2948.78	275.87
2951.39	261.531
2953.99	248.063
2956.6	234.558
2959.2	221.026
2961.8	208.389
2964.4	196.18
2967	183.18
2969.6	170.466
2972.2	159.515
2974.79	148.291
2977.39	137.644
2979.98	126.511
2982.58	116.071
2985.17	104.077
2987.76	93.1737
2990.36	83.2638
2992.95	74.8418
2995.54	65.5945
2998.12	57.32
3000.71	48.055
3003.3	40.9153
3005.88	35.2744
3008.47	29.9082
3011.05	24.1689
3013.64	19.351
3016.22	15.3449
3018.8	13.4874
3021.38	11.03
3023.96	9.33949
3026.54	6.96604
3029.12	4.84373
3031.69	4.37398
3034.27	4.29384
3036.85	3.81859
3039.42	4.65931
3041.99	5.08141
3044.57	6.61119
3047.14	7.69144
3049.71	8.13112
3052.28	9.24614
3054.85	10.0133
3057.42	11.3156
3059.98	11.1007
3062.55	10.3515
3065.11	9.9373
3067.68	9.70804
3070.24	9.02616
3072.8	8.28935
3075.37	7.38554
3077.93	6.43609
3080.49	5.6628
3083.05	3.88292
3085.61	2.46179
3088.16	1.84015
3090.72	0.663945
3093.27	0.21412
3095.83	0.515789
3098.38	1.03915
3100.94	1.79792
3103.49	2.99489
3106.04	3.77094
3108.59	4.65409
3111.14	5.67131
3113.69	7.14162
3116.23	8.34846
3118.78	8.95794
3121.33	9.8382
3123.87	10.3652
3126.42	11.4817
3128.96	13.5423
3131.5	14.9236
3134.04	16.8671
3136.58	18.6233
3139.12	20.188
3141.66	22.1896
3144.2	24.4442
3146.74	27.2816
3149.27	29.661