File: data/Raman/poly_smoothed/Mb_50_18_46_1x_45s_532 nm_x100_100%_600 gr_mm_01.txt
#Acq. time (s)=	45
#Accumulations=	2
#Range (cm-¹)=	200...3150
#Windows=	2
#Auto scanning=	Off
#Autofocus=	Off
#Macrospot=	Off
#AutoExposure=	Off
#Spike filter=	Multiple accum.
#Delay time (s)=	0
#Binning=	1
#Readout mode=	Signal
#DeNoise=	Off
#ICS correction=	On
#Dark correction=	Off
#Inst. Process=	Off
#Detector Gain=	Best Dynamic Range
#Detector ADC=	20 kHz
#Detector temperature (°C)=	-69.85
#Instrument=	LabRAM HR Evol
#Detector=	Synapse
#Objective=	x100
#Grating=	600 gr/mm
#ND Filter=	100%
#Laser (nm)=	532
#Hole=	100.021
#Range=	Auto
#Laser Pol.=	No
#Raman. Pol.=	No
#Laser Pol. (°)=	-0.0007625
#Raman Pol. (°)=	89.9995
#Collection=	Microscope
#StageXY=	Marzhauser
#StageZ=	Marzhauser
#X (µm)=	28454.7
#Y (µm)=	-2968.7
#Z (µm)=	1043.55
#Full time(mm:ss)=	3:18
#Project=
#Sample=
#Site=
#Title=	Mb_50_18_46_2x_45s_532 nm_x100_100%_600 gr_mm
#Remark=
#Date=	12.07.2022 14:37
#Acquired=	12.07.2022 14:37:40
#Base:Fit=	10.08.2022 10:49:18
#Base:Sub=	10.08.2022 10:49:30
#Filter:Polynom=	16.08.2022 10:14:59
#AxisType[0]=Intens
#AxisUnit[0]=Cnt
#AxisType[1]=Spectr
#AxisUnit[1]=1/cm
200.388	48.398
204.019	44.221
207.646	41.3765
211.274	39.5248
214.899	35.3377
218.524	32.8213
222.146	30.8776
225.766	28.794
229.388	25.5927
233.005	22.3932
236.621	20.586
240.236	18.7315
243.852	16.6725
247.464	15.817
251.074	13.6088
254.683	12.9035
258.291	10.4558
261.897	9.14352
265.504	7.63496
269.108	6.62599
272.71	4.90372
276.311	3.12054
279.91	4.34655
283.508	2.72319
287.105	2.75528
290.698	2.84917
294.291	4.02209
297.884	5.75006
301.475	4.29526
305.064	4.91002
308.652	5.77956
312.237	5.053
315.822	4.84955
319.406	5.06463
322.987	4.5187
326.568	6.13852
330.148	5.56039
333.724	5.22078
337.301	5.89302
340.875	6.00534
344.449	5.87439
348.02	7.9181
351.592	9.9776
355.16	12.2954
358.728	15.2773
362.294	19.133
365.858	24.6305
369.422	28.6686
372.983	32.6001
376.543	36.1883
380.102	38.014
383.661	39.8683
387.216	40.3562
390.771	39.983
394.324	38.1715
397.875	35.9389
401.425	32.1632
404.974	28.9724
408.524	24.5609
412.07	20.8099
415.614	17.3163
419.156	13.5066
422.698	11.172
426.238	9.45411
429.777	5.38735
433.315	3.92916
436.852	5.13665
440.387	5.1346
443.919	4.84682
447.451	5.63035
450.982	7.13029
454.512	9.27249
458.038	9.58984
461.565	11.4982
465.091	10.8336
468.613	11.97
472.136	13.6287
475.655	16.3467
479.176	18.4342
482.692	21.0696
486.21	24.4828
489.724	29.692
493.237	35.2833
496.75	40.1615
500.26	45.6556
503.771	49.1143
507.279	52.0184
510.785	54.255
514.289	55.2544
517.793	55.9473
521.297	56.7547
524.797	55.6753
528.297	52.4097
531.795	50.3904
535.291	46.8011
538.787	42.5501
542.281	35.8788
545.773	30.4294
549.264	25.1297
552.754	19.4624
556.243	14.37
559.73	11.7641
563.216	11.1549
566.701	9.03917
570.182	7.971
573.664	7.09146
577.145	6.54412
580.624	4.88832
584.1	6.50308
587.577	7.99365
591.052	7.14803
594.524	8.04467
597.997	9.8133
601.466	10.6736
604.936	13.056
608.403	12.985
611.87	12.4154
615.334	12.6013
618.799	11.7131
622.26	10.0709
625.72	8.21816
629.181	8.00074
632.638	7.68182
636.095	8.10868
639.551	8.76321
643.005	8.68566
646.457	8.67802
649.908	7.61962
653.357	6.75937
656.806	4.43527
660.253	5.84742
663.7	7.5008
667.145	9.88734
670.588	10.9217
674.027	12.8062
677.468	12.3282
680.907	13.6843
684.345	14.758
687.781	15.6225
691.216	16.9198
694.65	16.4099
698.081	17.9741
701.512	18.262
704.942	19.113
708.371	21.0177
711.796	23.308
715.222	26.4316
718.645	26.2252
722.068	27.0207
725.49	26.969
728.909	27.1835
732.329	31.0944
735.745	35.2569
739.16	43.1052
742.576	52.9512
745.988	63.3176
749.401	72.1821
752.811	80.7062
756.22	89.2347
759.627	96.3147
763.035	103.112
766.44	107.035
769.843	110.889
773.245	114.318
776.646	114.606
780.046	116.641
783.444	115.801
786.841	114.192
790.237	110.487
793.631	105.922
797.024	99.1867
800.416	92.3193
803.807	86.4482
807.196	81.1914
810.584	76.5392
813.971	74.6872
817.354	73.8962
820.739	75.1268
824.122	75.5595
827.503	75.3091
830.882	74.893
834.261	73.2718
837.637	71.6768
841.013	70.3556
844.389	67.0086
847.761	62.8546
851.131	59.3579
854.503	56.7942
857.871	55.7835
861.24	55.1991
864.606	54.7156
867.97	53.5207
871.336	51.1411
874.698	49.6667
878.058	48.0504
881.418	48.2713
884.778	47.924
888.135	47.9445
891.49	47.9258
894.845	47.4963
898.198	46.6841
901.55	47.8527
904.901	47.4058
908.25	47.6742
911.598	46.7407
914.945	46.1417
918.291	42.0508
921.635	41.9034
924.978	40.5305
928.318	38.7125
931.659	36.8786
934.998	37.8952
938.336	38.579
941.671	39.8384
945.007	38.5612
948.339	38.543
951.672	37.2124
955.004	34.5008
958.333	30.5349
961.662	29.363
964.989	27.6695
968.315	27.2088
971.639	26.9693
974.962	26.6167
978.285	26.9405
981.605	28.1523
984.924	29.1345
988.243	29.0714
991.56	30.6308
994.875	33.7678
998.188	38.3135
1001.5	45.3877
1004.81	53.9528
1008.12	61.4513
1011.43	68.0939
1014.74	74.9903
1018.05	80.5456
1021.35	85.2662
1024.65	87.7589
1027.96	88.8465
1031.26	90.8703
1034.56	89.3115
1037.86	85.7779
1041.16	82.6521
1044.45	81.6825
1047.75	78.5635
1051.04	74.6107
1054.33	72.9409
1057.62	68.3321
1060.91	65.1107
1064.2	60.847
1067.49	57.6367
1070.77	55.5788
1074.06	54.6226
1077.34	55.844
1080.62	56.997
1083.91	57.6708
1087.18	56.1974
1090.46	55.7332
1093.74	54.2892
1097.02	53.859
1100.29	53.2782
1103.56	52.8427
1106.84	49.6753
1110.11	46.3043
1113.38	42.6816
1116.64	40.0172
1119.91	36.2572
1123.18	33.961
1126.44	33.2105
1129.7	31.5407
1132.97	31.2708
1136.23	30.1071
1139.49	27.3077
1142.74	25.136
1146	22.4947
1149.26	20.6751
1152.51	17.1728
1155.76	15.2456
1159.01	13.9832
1162.27	13.1463
1165.51	11.5148
1168.76	11.9107
1172.01	12.4179
1175.25	12.7707
1178.5	14.224
1181.74	14.9728
1184.98	15.8775
1188.22	16.3369
1191.46	18.8134
1194.7	18.3449
1197.94	19.6225
1201.17	22.4924
1204.41	23.7995
1207.64	27.5067
1210.87	30.3434
1214.1	32.7024
1217.33	33.8326
1220.56	34.9103
1223.79	37.1963
1227.01	39.3565
1230.23	41.8104
1233.46	45.1366
1236.68	48.5999
1239.9	50.3016
1243.12	52.6041
1246.34	55.3801
1249.55	56.7479
1252.77	59.1453
1255.98	60.6052
1259.2	63.5559
1262.41	68.0211
1265.62	70.0896
1268.83	73.0465
1272.03	75.3305
1275.24	77.6043
1278.45	80.4861
1281.65	83.2388
1284.85	85.5213
1288.06	89.5165
1291.26	90.7798
1294.46	90.727
1297.66	92.6885
1300.85	93.5622
1304.05	94.4853
1307.24	94.3736
1310.43	94.795
1313.63	95.735
1316.82	94.9441
1320.01	92.6489
1323.2	91.2849
1326.38	89.1833
1329.57	86.0709
1332.76	83.4984
1335.94	80.6718
1339.12	79.3337
1342.3	76.8175
1345.48	74.0116
1348.66	72.3765
1351.84	68.545
1355.01	66.4327
1358.19	63.315
1361.36	61.3404
1364.53	58.4283
1367.71	54.8764
1370.88	52.0209
1374.04	51.1217
1377.21	49.8561
1380.38	47.8286
1383.54	44.4667
1386.71	43.742
1389.87	42.4133
1393.03	40.4018
1396.19	40.1148
1399.35	38.3903
1402.51	39.5921
1405.67	41.2167
1408.82	42.3042
1411.98	46.4366
1415.13	51.8433
1418.28	57.6815
1421.43	65.8906
1424.58	71.5265
1427.73	78.6209
1430.88	86.7766
1434.02	93.474
1437.17	99.4463
1440.31	102.545
1443.45	104.239
1446.6	107.006
1449.74	108.896
1452.87	109.833
1456.01	109.708
1459.15	108.565
1462.28	107.074
1465.42	105.618
1468.55	102.775
1471.68	99.8141
1474.81	95.6193
1477.94	91.0394
1481.07	87.6152
1484.2	81.6438
1487.32	76.9372
1490.45	71.9359
1493.57	68.5331
1496.69	63.7887
1499.81	58.5245
1502.93	53.0508
1506.05	49.449
1509.17	42.3173
1512.28	35.8147
1515.4	29.6505
1518.51	25.9838
1521.63	22.9685
1524.74	23.2187
1527.85	22.4941
1530.96	23.2328
1534.06	25.4316
1537.17	26.6307
1540.28	27.4772
1543.38	30.1724
1546.48	33.077
1549.59	35.2632
1552.69	37.649
1555.79	40.5206
1558.88	41.3849
1561.98	43.5775
1565.08	45.6452
1568.17	48.0949
1571.27	50.5106
1574.36	53.1674
1577.45	55.0903
1580.54	57.2249
1583.63	60.8623
1586.72	61.3805
1589.8	62.9622
1592.89	63.8446
1595.97	65.5803
1599.06	66.6823
1602.14	67.1233
1605.22	65.8819
1608.3	66.5971
1611.38	65.8514
1614.46	65.5482
1617.53	65.9726
1620.61	68.5846
1623.68	69.9772
1626.75	71.9414
1629.82	74.2077
1632.9	76.4753
1635.96	80.1051
1639.03	83.8835
1642.1	87.597
1645.16	92.1413
1648.23	96.6589
1651.29	99.699
1654.36	100.914
1657.42	101.983
1660.48	98.8727
1663.53	94.7885
1666.59	91.0322
1669.65	86.6197
1672.7	81.2163
1675.76	75.5734
1678.81	68.4349
1681.86	62.4011
1684.91	57.3088
1687.96	50.0549
1691.01	43.6383
1694.06	38.3485
1697.11	33.9897
1700.15	30.4245
1703.2	27.296
1706.24	24.2945
1709.28	22.1023
1712.32	20.7964
1715.36	20.3727
1718.4	20.8889
1721.43	20.6078
1724.47	20.0354
1727.5	18.3689
1730.54	15.3278
1733.57	13.627
1736.6	12.432
1739.63	10.8136
1742.66	9.82167
1745.69	8.55774
1748.72	8.37463
1751.74	8.07135
1754.77	7.32591
1757.79	6.19086
1760.81	5.71006
1763.83	3.89908
1766.85	2.24859
1769.87	2.16382
1772.89	1.87622
1775.91	1.04984
1778.92	0.597543
1781.94	1.01076
1784.95	1.20487
1787.96	1.81666
1790.97	1.96691
1793.98	1.88307
1796.99	0.974506
1800	0.107516
1803	-0.164341
1806.01	-0.227845
1809.01	0.242067
1812.02	0.193766
1815.02	0.261734
1818.02	0.403093
1821.02	0.833431
1824.02	1.66786
1827.01	1.33454
1830.01	1.34843
1833	1.03144
1836	1.06336
1838.99	1.62102
1841.98	2.89456
1844.97	2.49549
1847.96	3.21904
1850.95	3.2862
1853.94	4.18252
1856.92	4.83965
1859.91	5.63227
1862.89	5.98932
1865.88	5.90525
1868.86	6.7864
1871.84	7.5407
1874.82	7.98033
1877.8	8.65694
1880.77	8.21387
1882.51	7.57538
1885.5	7.27911
1888.48	8.11759
1891.47	8.13559
1894.46	8.40986
1897.44	8.18132
1900.42	7.45854
1903.41	7.82142
1906.39	7.3792
1909.37	6.5216
1912.35	7.3197
1915.32	6.59857
1918.3	6.1728
1921.28	6.21728
1924.25	6.57661
1927.22	7.57404
1930.2	7.4259
1933.17	7.50476
1936.14	7.52489
1939.11	6.24593
1942.08	5.75387
1945.04	5.09409
1948.01	3.71392
1950.97	3.46935
1953.94	2.40014
1956.9	1.6182
1959.86	2.11026
1962.82	2.12852
1965.78	0.309829
1968.74	-0.258516
1971.69	-0.953389
1974.65	-1.46153
1977.61	-1.58278
1980.56	-0.387504
1983.51	0.0892046
1986.46	1.58817
1989.41	1.9878
1992.36	2.10076
1995.31	2.24796
1998.26	3.38169
2001.2	4.3747
2004.15	5.29481
2007.09	5.26099
2010.04	5.80718
2012.98	6.43296
2015.92	7.41776
2018.86	7.89365
2021.8	8.90539
2024.74	9.5858
2027.67	9.66671
2030.61	10.6289
2033.54	10.6764
2036.47	11.5923
2039.41	12.3428
2042.34	12.9797
2045.27	13.1261
2048.2	15.4839
2051.12	16.5306
2054.05	18.4404
2056.98	19.7394
2059.9	21.0439
2062.82	21.8204
2065.75	22.5325
2068.67	24.8863
2071.59	27.3104
2074.51	30.5445
2077.43	32.4066
2080.34	33.4934
2083.26	36.7926
2086.17	39.5798
2089.09	42.6071
2092	45.9512
2094.91	47.8953
2097.82	51.1907
2100.73	54.5575
2103.64	57.8554
2106.55	61.7154
2109.46	65.4006
2112.36	68.2698
2115.27	70.7961
2118.17	75.2342
2121.07	80.7968
2123.97	85.0638
2126.87	90.6387
2129.77	96.1964
2132.67	101.291
2135.57	106.022
2138.46	111.691
2141.36	116.379
2144.25	120.955
2147.14	125.167
2150.03	129.066
2152.92	133.122
2155.81	135.65
2158.7	138.705
2161.59	141.037
2164.48	141.51
2167.36	141.628
2170.25	141.068
2173.13	138.486
2176.01	136.065
2178.89	133.585
2181.77	129.471
2184.65	126.069
2187.53	121.757
2190.41	118.917
2193.28	115.207
2196.16	110.576
2199.03	107.009
2201.9	103.281
2204.78	97.7769
2207.65	93.532
2210.51	88.9098
2213.38	84.6518
2216.25	80.3647
2219.12	77.6599
2221.98	73.4267
2224.85	69.462
2227.71	66.578
2230.57	63.3354
2233.43	59.7193
2236.29	56.0202
2239.15	51.8932
2242.01	47.8988
2244.87	45.1008
2247.73	42.9338
2250.58	39.6757
2253.43	36.7227
2256.29	34.6373
2259.14	31.6691
2261.99	29.8695
2264.84	28.0039
2267.69	25.7967
2270.54	23.8366
2273.38	21.9576
2276.23	19.382
2279.07	17.9207
2281.92	17.0272
2284.76	16.2895
2287.6	15.3554
2290.44	14.2943
2293.28	12.714
2296.12	12.7462
2298.96	13.3014
2301.79	13.0102
2304.63	13.1445
2307.46	13.2907
2310.3	13.279
2313.13	13.6529
2315.96	13.1627
2318.79	12.6285
2321.62	11.3964
2324.45	10.7205
2327.27	10.3218
2330.1	9.10017
2332.93	8.32673
2335.75	7.31039
2338.57	6.95251
2341.4	5.74591
2344.22	5.34654
2347.04	3.40293
2349.86	1.99965
2352.67	2.16871
2355.49	0.366005
2358.31	0.556655
2361.12	-0.541678
2363.94	-0.482589
2366.75	0.445962
2369.56	0.511627
2372.37	1.06846
2375.18	1.05494
2377.99	1.37539
2380.8	2.05421
2383.61	2.91236
2386.41	3.13071
2389.22	3.42637
2392.02	4.03974
2394.82	3.73295
2397.63	4.65774
2400.43	4.86429
2403.23	5.84182
2406.02	6.88166
2408.82	7.0076
2411.62	7.06726
2414.41	7.12322
2417.21	8.31147
2420	8.75103
2422.79	9.36611
2425.59	9.73884
2428.38	8.49038
2431.17	8.28127
2433.96	8.61119
2436.74	9.5315
2439.53	9.51285
2442.32	8.90248
2445.1	8.66089
2447.88	9.1971
2450.67	8.81509
2453.45	9.56731
2456.23	8.29317
2459.01	8.19049
2461.79	7.52449
2464.57	6.94605
2467.34	6.58941
2470.12	4.86872
2472.89	4.35548
2475.67	2.35705
2478.44	2.49687
2481.21	1.83546
2483.98	1.35927
2486.75	1.40515
2489.52	-0.153065
2492.29	-0.435009
2495.06	-0.132618
2497.82	0.308858
2500.59	1.1268
2503.35	1.77307
2506.11	2.48307
2508.88	2.28591
2511.63	2.333
2514.39	3.44361
2517.15	4.1738
2519.91	5.47173
2522.67	6.22407
2525.42	5.76804
2528.18	5.7937
2530.93	6.1089
2533.69	6.03632
2536.44	5.38405
2539.19	5.51291
2541.94	5.91221
2544.69	6.24857
2547.44	6.15658
2550.18	5.88263
2552.93	6.08913
2555.68	6.42201
2558.42	7.27061
2561.16	7.96961
2563.9	8.41619
2566.64	8.31536
2569.38	8.71742
2572.12	8.98724
2574.86	8.63835
2577.6	8.97823
2580.34	9.42249
2583.07	9.53997
2585.81	9.29077
2588.54	8.86194
2591.27	7.56563
2594	7.50344
2596.73	7.89211
2599.46	6.88528
2602.19	6.48706
2604.92	7.05068
2607.64	6.32041
2610.37	6.60739
2613.09	5.65639
2615.82	5.6917
2618.54	5.95845
2621.26	5.60437
2623.98	6.70937
2626.7	6.3123
2629.42	5.89515
2632.14	5.4047
2634.86	4.5071
2637.57	4.10151
2640.29	3.89357
2643	4.37922
2645.72	5.14538
2648.43	5.11936
2651.14	5.32591
2653.85	5.86809
2656.56	5.37475
2659.27	5.05972
2661.97	5.18382
2664.68	5.52462
2667.38	5.29894
2670.09	6.00093
2672.79	6.22484
2675.49	7.27176
2678.2	7.81174
2680.89	7.93489
2683.59	8.8252
2686.29	8.80776
2688.99	9.26721
2691.69	9.36087
2694.38	9.09048
2697.08	9.80802
2699.77	8.90636
2702.46	9.25717
2705.16	10.0069
2707.85	10.7748
2710.54	11.7709
2713.23	12.2319
2715.92	12.387
2718.6	12.5995
2721.29	12.3125
2723.97	11.4939
2726.66	12.4341
2729.34	11.8384
2732.02	10.6493
2734.7	10.7445
2737.39	9.89283
2740.06	9.36813
2742.74	8.74219
2745.42	7.54091
2748.1	6.38141
2750.77	4.69259
2753.45	4.42953
2756.12	3.63467
2758.79	3.07359
2761.47	2.90905
2764.14	1.99553
2766.81	0.812308
2769.48	0.326452
2772.14	0.783145
2774.81	0.183796
2777.48	-0.636584
2780.14	-0.720502
2782.81	-0.820536
2785.47	-0.538947
2788.13	-1.06487
2790.79	-0.729336
2793.46	-0.042362
2796.11	-0.305828
2798.77	-0.688036
2801.43	-1.92663
2804.09	-1.9355
2806.74	-2.22236
2809.4	-2.10869
2812.05	-3.36557
2814.71	-2.05092
2817.36	0.394133
2820.01	4.20673
2822.66	8.68459
2825.31	14.822
2827.96	20.8355
2830.61	28.1624
2833.25	36.386
2835.9	45.0061
2838.54	54.6693
2841.18	63.0522
2843.83	73.701
2846.47	83.1115
2849.11	94.0844
2851.75	104.52
2854.39	114.592
2857.03	124.727
2859.67	134.038
2862.3	141.303
2864.94	148.413
2867.57	154.412
2870.21	159.835
2872.84	164.565
2875.47	169.252
2878.1	173.041
2880.73	178.694
2883.36	182.783
2885.99	186.3
2888.61	191.236
2891.24	195.597
2893.87	201.77
2896.49	208.584
2899.11	215.901
2901.74	223.785
2904.36	233.045
2906.98	245.025
2909.6	256.678
2912.22	270.427
2914.83	284.063
2917.45	296.105
2920.07	306.366
2922.68	316.299
2925.3	323.099
2927.91	329.047
2930.52	332.51
2933.13	332.364
2935.74	331.29
2938.35	328.292
2940.96	321.803
2943.57	313.334
2946.18	302.708
2948.78	290.995
2951.39	279.494
2953.99	266.599
2956.6	253.286
2959.2	239.523
2961.8	225.162
2964.4	211.688
2967	200.699
2969.6	189.591
2972.2	177.833
2974.79	167.658
2977.39	156.736
2979.98	144.361
2982.58	132.251
2985.17	120.083
2987.76	109.23
2990.36	97.9033
2992.95	85.5819
2995.54	75.4587
2998.12	65.5912
3000.71	56.5468
3003.3	47.5846
3005.88	39.2072
3008.47	32.2753
3011.05	26.0599
3013.64	20.9117
3016.22	16.4672
3018.8	11.5924
3021.38	8.21846
3023.96	5.7031
3026.54	4.70121
3029.12	3.71617
3031.69	3.30746
3034.27	2.97848
3036.85	3.78334
3039.42	5.10023
3041.99	5.31866
3044.57	5.83854
3047.14	5.60464
3049.71	5.71068
3052.28	6.52273
3054.85	5.78227
3057.42	4.87213
3059.98	4.94622
3062.55	4.4314
3065.11	4.77148
3067.68	4.45034
3070.24	4.59962
3072.8	4.23815
3075.37	3.10888
3077.93	2.01981
3080.49	1.74836
3083.05	1.09105
3085.61	1.46635
3088.16	1.69144
3090.72	1.96518
3093.27	3.16071
3095.83	4.45724
3098.38	5.98724
3100.94	6.88749
3103.49	7.59679
3106.04	8.28503
3108.59	9.52123
3111.14	11.6558
3113.69	12.9619
3116.23	14.7388
3118.78	15.7099
3121.33	18.0584
3123.87	20.9229
3126.42	23.7468
3128.96	26.5145
3131.5	28.6102
3134.04	31.1129
3136.58	32.8387
3139.12	35.3105
3141.66	39.3405
3144.2	43.1984
3146.74	46.9283
3149.27	51.8239