File: data/Raman/poly_smoothed/Mb_50_18_17_1x_45s_532 nm_x100_100%_600 gr_mm_01.txt
#Acq. time (s)=	45
#Accumulations=	2
#Range (cm-¹)=	200...3150
#Windows=	2
#Auto scanning=	Off
#Autofocus=	Off
#Macrospot=	Off
#AutoExposure=	Off
#Spike filter=	Multiple accum.
#Delay time (s)=	0
#Binning=	1
#Readout mode=	Signal
#DeNoise=	Off
#ICS correction=	On
#Dark correction=	Off
#Inst. Process=	Off
#Detector Gain=	Best Dynamic Range
#Detector ADC=	20 kHz
#Detector temperature (°C)=	-69.85
#Instrument=	LabRAM HR Evol
#Detector=	Synapse
#Objective=	x100
#Grating=	600 gr/mm
#ND Filter=	100%
#Laser (nm)=	532
#Hole=	100.021
#Range=	Auto
#Laser Pol.=	No
#Raman. Pol.=	No
#Laser Pol. (°)=	-0.0007625
#Raman Pol. (°)=	89.9995
#Collection=	Microscope
#StageXY=	Marzhauser
#StageZ=	Marzhauser
#X (µm)=	19279.6
#Y (µm)=	3038
#Z (µm)=	1047.7
#Full time(mm:ss)=	3:19
#Project=
#Sample=
#Site=
#Title=	Mb_50_18_17_2x_45s_532 nm_x100_100%_600 gr_mm
#Remark=
#Date=	12.07.2022 11:28
#Acquired=	12.07.2022 11:28:48
#Base:Fit=	10.08.2022 10:49:18
#Base:Sub=	10.08.2022 10:49:30
#Filter:Polynom=	16.08.2022 10:14:59
#AxisType[0]=Intens
#AxisUnit[0]=Cnt
#AxisType[1]=Spectr
#AxisUnit[1]=1/cm
200.388	19.8399
204.019	15.9555
207.646	12.3967
211.274	10.4386
214.899	9.25097
218.524	7.7388
222.146	6.14961
225.766	4.38783
229.388	3.38841
233.005	3.19263
236.621	3.86247
240.236	4.95997
243.852	6.52675
247.464	6.47544
251.074	6.31347
254.683	6.98782
258.291	9.16121
261.897	10.2996
265.504	9.04138
269.108	8.63699
272.71	7.6187
276.311	7.67224
279.91	7.47606
283.508	7.05211
287.105	8.71229
290.698	8.31933
294.291	10.3106
297.884	10.694
301.475	11.5355
305.064	12.1297
308.652	12.408
312.237	14.342
315.822	15.9362
319.406	18.609
322.987	21.0013
326.568	22.4299
330.148	21.2001
333.724	19.2434
337.301	16.8962
340.875	17.3224
344.449	16.9205
348.02	15.9914
351.592	15.3651
355.16	14.9876
358.728	14.6683
362.294	17.4697
365.858	19.7202
369.422	21.7672
372.983	24.1369
376.543	26.1845
380.102	28.7828
383.661	30.6026
387.216	31.416
390.771	33.4734
394.324	35.4482
397.875	36.4949
401.425	36.4261
404.974	34.2923
408.524	32.9834
412.07	29.2
415.614	25.8843
419.156	23.6671
422.698	18.8198
426.238	16.7627
429.777	13.7367
433.315	11.8267
436.852	9.29031
440.387	9.28669
443.919	8.21681
447.451	9.42237
450.982	10.4322
454.512	10.912
458.038	11.2534
461.565	12.1067
465.091	12.018
468.613	13.8077
472.136	15.9402
475.655	18.3422
479.176	20.8218
482.692	23.4578
486.21	25.6024
489.724	28.0063
493.237	30.9616
496.75	34.1832
500.26	37.9115
503.771	40.2664
507.279	40.6175
510.785	42.4974
514.289	43.2072
517.793	44.1631
521.297	42.7565
524.797	43.1056
528.297	41.864
531.795	39.975
535.291	36.1274
538.787	31.2275
542.281	26.7028
545.773	22.9566
549.264	19.7855
552.754	16.1455
556.243	14.1904
559.73	12.2485
563.216	10.8082
566.701	10.8977
570.182	9.84008
573.664	9.28374
577.145	9.62446
580.624	9.1326
584.1	7.63683
587.577	6.87261
591.052	7.76376
594.524	9.65868
597.997	11.0765
601.466	10.8909
604.936	11.0034
608.403	11.0278
611.87	11.8738
615.334	11.8513
618.799	10.045
622.26	8.31053
625.72	8.28389
629.181	6.75309
632.638	6.1102
636.095	5.47223
639.551	5.70995
643.005	6.25521
646.457	5.61107
649.908	5.56722
653.357	5.48381
656.806	5.6476
660.253	5.56384
663.7	5.40098
667.145	3.63529
670.588	5.95381
674.027	8.62563
677.468	10.2885
680.907	14.1025
684.345	16.1962
687.781	17.5296
691.216	19.9234
694.65	22.3248
698.081	24.1435
701.512	25.777
704.942	28.7036
708.371	29.5249
711.796	31.6161
715.222	31.5073
718.645	34.5073
722.068	34.4984
725.49	33.9766
728.909	34.4684
732.329	36.6286
735.745	41.041
739.16	45.5451
742.576	51.3583
745.988	57.0543
749.401	64.1018
752.811	71.5414
756.22	78.0728
759.627	84.7532
763.035	88.5916
766.44	93.5327
769.843	97.2221
773.245	100.222
776.646	102.81
780.046	104.157
783.444	103.752
786.841	104.554
790.237	103.913
793.631	100.105
797.024	97.5316
800.416	92.8555
803.807	88.4309
807.196	82.0849
810.584	78.0792
813.971	76.4534
817.354	75.2437
820.739	75.8871
824.122	74.5983
827.503	75.0083
830.882	73.8936
834.261	73.9152
837.637	70.823
841.013	70.2409
844.389	67.3217
847.761	66.7491
851.131	64.885
854.503	62.4395
857.871	58.7446
861.24	58.2833
864.606	55.75
867.97	55.1195
871.336	51.9419
874.698	50.1058
878.058	48.3084
881.418	47.1179
884.778	46.0065
888.135	45.9846
891.49	44.8938
894.845	44.8067
898.198	45.3838
901.55	45.645
904.901	44.7619
908.25	44.6723
911.598	45.7492
914.945	46.311
918.291	46.6605
921.635	47.2167
924.978	46.6779
928.318	45.155
931.659	43.6361
934.998	41.1725
938.336	40.5399
941.671	39.8272
945.007	39.7059
948.339	37.6569
951.672	38.4164
955.004	38.3463
958.333	38.7696
961.662	38.6167
964.989	38.1363
968.315	37.7654
971.639	36.7289
974.962	35.5903
978.285	34.4009
981.605	33.0756
984.924	31.0852
988.243	30.617
991.56	30.5213
994.875	33.3366
998.188	34.6192
1001.5	38.3057
1004.81	42.9762
1008.12	46.8362
1011.43	50.2151
1014.74	53.5541
1018.05	58.0588
1021.35	61.8223
1024.65	66.8008
1027.96	68.9137
1031.26	73.8698
1034.56	74.1831
1037.86	73.5628
1041.16	72.6992
1044.45	71.0308
1047.75	67.9534
1051.04	64.6143
1054.33	62.356
1057.62	60.393
1060.91	57.3211
1064.2	54.4232
1067.49	51.9518
1070.77	52.3926
1074.06	53.1061
1077.34	54.6767
1080.62	55.375
1083.91	55.1785
1087.18	56.7864
1090.46	55.7752
1093.74	54.8208
1097.02	56.6578
1100.29	56.356
1103.56	56.5825
1106.84	55.1055
1110.11	54.1826
1113.38	50.1018
1116.64	45.6722
1119.91	41.107
1123.18	37.1222
1126.44	33.8711
1129.7	30.0186
1132.97	28.1893
1136.23	25.6693
1139.49	23.6771
1142.74	20.5904
1146	19.1364
1149.26	17.0346
1152.51	13.2198
1155.76	10.2743
1159.01	8.16851
1162.27	5.02126
1165.51	6.01027
1168.76	5.24771
1172.01	4.68523
1175.25	5.88575
1178.5	7.47708
1181.74	7.27695
1184.98	8.09442
1188.22	7.58967
1191.46	7.06449
1194.7	6.34416
1197.94	6.26825
1201.17	8.09233
1204.41	10.176
1207.64	10.7491
1210.87	12.5941
1214.1	14.8703
1217.33	18.2597
1220.56	20.9448
1223.79	22.4817
1227.01	24.6807
1230.23	24.8887
1233.46	27.0201
1236.68	31.1939
1239.9	34.8223
1243.12	36.7262
1246.34	38.5281
1249.55	39.5121
1252.77	40.7197
1255.98	45.009
1259.2	45.9062
1262.41	47.4257
1265.62	49.4577
1268.83	52.6787
1272.03	56.451
1275.24	59.9429
1278.45	63.5725
1281.65	65.5738
1284.85	66.9669
1288.06	69.593
1291.26	72.14
1294.46	74.1145
1297.66	75.7536
1300.85	75.068
1304.05	74.532
1307.24	74.2884
1310.43	73.3017
1313.63	73.9797
1316.82	73.7147
1320.01	70.0573
1323.2	69.0599
1326.38	65.9018
1329.57	64.4936
1332.76	62.7604
1335.94	61.3177
1339.12	59.5554
1342.3	58.2366
1345.48	56.4741
1348.66	54.8543
1351.84	50.6176
1355.01	47.0551
1358.19	41.9205
1361.36	39.6479
1364.53	37.7101
1367.71	35.1484
1370.88	32.0162
1374.04	29.2202
1377.21	25.5556
1380.38	24.021
1383.54	22.1698
1386.71	20.9471
1389.87	18.5601
1393.03	14.0818
1396.19	14.6539
1399.35	16.5107
1402.51	18.8208
1405.67	22.2202
1408.82	27.5766
1411.98	32.5084
1415.13	39.3172
1418.28	44.5015
1421.43	50.3447
1424.58	57.4468
1427.73	63.1759
1430.88	69.5135
1434.02	76.3912
1437.17	80.7126
1440.31	84.6029
1443.45	85.0547
1446.6	85.3055
1449.74	83.5253
1452.87	82.5306
1456.01	80.447
1459.15	76.421
1462.28	71.0147
1465.42	64.8357
1468.55	57.8488
1471.68	52.8549
1474.81	49.8765
1477.94	44.4106
1481.07	40.0833
1484.2	35.8562
1487.32	31.9745
1490.45	28.4243
1493.57	25.4075
1496.69	21.6759
1499.81	19.6119
1502.93	18.0396
1506.05	15.7593
1509.17	14.0794
1512.28	11.6285
1515.4	9.15637
1518.51	6.81963
1521.63	6.46646
1524.74	6.18409
1527.85	6.52053
1530.96	7.20265
1534.06	8.51414
1537.17	8.46886
1540.28	10.4311
1543.38	12.734
1546.48	13.0061
1549.59	15.6564
1552.69	17.516
1555.79	19.5606
1558.88	20.4584
1561.98	20.7189
1565.08	23.7476
1568.17	25.6102
1571.27	29.1621
1574.36	31.6849
1577.45	33.995
1580.54	35.9575
1583.63	37.1917
1586.72	39.0939
1589.8	41.3921
1592.89	42.3852
1595.97	44.3381
1599.06	45.2876
1602.14	45.1284
1605.22	44.3557
1608.3	43.8594
1611.38	44.3598
1614.46	44.014
1617.53	45.209
1620.61	44.4934
1623.68	45.8006
1626.75	47.6405
1629.82	47.9292
1632.9	49.4712
1635.96	51.3535
1639.03	54.9868
1642.1	59.4162
1645.16	62.2985
1648.23	64.5681
1651.29	65.9784
1654.36	66.5095
1657.42	67.4406
1660.48	66.8904
1663.53	65.1251
1666.59	63.7615
1669.65	61.5095
1672.7	58.951
1675.76	53.6929
1678.81	48.1785
1681.86	43.1532
1684.91	39.4973
1687.96	34.8297
1691.01	29.9998
1694.06	26.6038
1697.11	23.7921
1700.15	21.233
1703.2	17.8215
1706.24	14.6352
1709.28	12.6431
1712.32	11.6789
1715.36	10.1463
1718.4	8.92631
1721.43	7.24108
1724.47	6.55651
1727.5	5.46728
1730.54	5.35831
1733.57	4.99961
1736.6	5.48746
1739.63	4.14398
1742.66	4.19808
1745.69	4.25747
1748.72	3.00131
1751.74	2.81684
1754.77	2.62736
1757.79	2.7838
1760.81	2.33714
1763.83	2.14768
1766.85	1.79218
1769.87	2.1187
1772.89	1.96195
1775.91	1.5484
1778.92	1.02234
1781.94	1.46603
1784.95	1.40219
1787.96	1.45371
1790.97	1.12729
1793.98	0.669159
1796.99	1.24057
1800	2.19805
1803	2.13535
1806.01	2.90193
1809.01	3.51075
1812.02	2.75482
1815.02	1.97943
1818.02	2.26168
1821.02	2.08608
1824.02	1.31771
1827.01	1.77239
1830.01	1.40845
1833	0.217356
1836	-0.00848692
1838.99	0.0135959
1841.98	-0.454261
1844.97	-0.0531779
1847.96	0.0711408
1850.95	0.0698755
1853.94	0.462995
1856.92	0.461219
1859.91	0.822277
1862.89	1.65695
1865.88	2.40364
1868.86	2.4392
1871.84	3.53304
1874.82	4.92918
1877.8	5.93611
1880.77	5.54301
1882.51	6.15875
1885.5	5.75507
1888.48	5.41721
1891.47	6.26914
1894.46	5.45235
1897.44	5.76998
1900.42	4.87145
1903.41	3.98103
1906.39	3.90208
1909.37	4.31624
1912.35	4.8748
1915.32	4.32864
1918.3	4.42443
1921.28	4.00828
1924.25	4.54709
1927.22	4.95216
1930.2	4.49419
1933.17	4.55941
1936.14	3.60654
1939.11	4.49201
1942.08	4.31663
1945.04	5.60467
1948.01	7.00954
1950.97	5.37817
1953.94	5.24439
1956.9	5.67988
1959.86	6.16909
1962.82	6.62355
1965.78	7.59335
1968.74	8.2131
1971.69	8.49376
1974.65	8.44681
1977.61	9.93009
1980.56	11.0468
1983.51	12.7958
1986.46	13.2082
1989.41	12.5253
1992.36	11.9723
1995.31	12.5922
1998.26	12.061
2001.2	11.2079
2004.15	10.0409
2007.09	9.19777
2010.04	9.17553
2012.98	8.31489
2015.92	7.14546
2018.86	7.31617
2021.8	7.16182
2024.74	6.61984
2027.67	7.41413
2030.61	7.19785
2033.54	7.42371
2036.47	8.47399
2039.41	10.0075
2042.34	10.7935
2045.27	11.9249
2048.2	13.8906
2051.12	16.4902
2054.05	19.2231
2056.98	20.9409
2059.9	22.8064
2062.82	24.4139
2065.75	26.6123
2068.67	28.8683
2071.59	30.7612
2074.51	32.322
2077.43	35.3115
2080.34	38.8072
2083.26	41.0343
2086.17	43.342
2089.09	45.753
2092	50.0812
2094.91	52.4356
2097.82	56.0047
2100.73	59.4648
2103.64	63.48
2106.55	68.5518
2109.46	73.4513
2112.36	78.6502
2115.27	83.65
2118.17	89.2475
2121.07	94.3325
2123.97	100.948
2126.87	106.73
2129.77	111.888
2132.67	116.329
2135.57	120.446
2138.46	126.606
2141.36	131.657
2144.25	136.867
2147.14	140.708
2150.03	144.839
2152.92	148.654
2155.81	150.28
2158.7	151.647
2161.59	153.211
2164.48	153.825
2167.36	154.025
2170.25	153.846
2173.13	153.195
2176.01	151.661
2178.89	149.206
2181.77	146.649
2184.65	144.057
2187.53	139.171
2190.41	135.298
2193.28	131.584
2196.16	126.867
2199.03	121.181
2201.9	116.165
2204.78	110.376
2207.65	105.554
2210.51	100.449
2213.38	94.8188
2216.25	88.7563
2219.12	84.6732
2221.98	80.5068
2224.85	75.355
2227.71	70.2374
2230.57	65.2804
2233.43	60.2442
2236.29	57.1402
2239.15	52.9753
2242.01	50.1112
2244.87	47.1017
2247.73	44.2877
2250.58	42.3844
2253.43	40.5634
2256.29	38.52
2259.14	37.1395
2261.99	36.5211
2264.84	34.7479
2267.69	33.47
2270.54	31.4583
2273.38	30.5356
2276.23	29.1383
2279.07	27.7567
2281.92	26.2975
2284.76	24.5636
2287.6	23.9817
2290.44	22.025
2293.28	18.7654
2296.12	17.3565
2298.96	17.1899
2301.79	15.642
2304.63	14.7754
2307.46	14.0679
2310.3	14.1464
2313.13	13.4655
2315.96	14.3915
2318.79	13.5686
2321.62	11.7958
2324.45	10.8915
2327.27	10.5398
2330.1	11.5024
2332.93	11.5779
2335.75	10.5852
2338.57	11.1059
2341.4	11.231
2344.22	10.2946
2347.04	8.86133
2349.86	7.71597
2352.67	6.61445
2355.49	6.21441
2358.31	4.823
2361.12	5.23928
2363.94	6.63795
2366.75	8.11587
2369.56	7.96154
2372.37	6.62142
2375.18	6.40997
2377.99	6.52775
2380.8	6.67034
2383.61	5.61818
2386.41	4.01519
2389.22	1.99999
2392.02	2.32923
2394.82	3.21364
2397.63	3.82383
2400.43	3.71473
2403.23	3.68421
2406.02	3.89886
2408.82	3.5585
2411.62	2.80856
2414.41	2.75036
2417.21	3.30893
2420	4.60537
2422.79	5.62558
2425.59	6.95667
2428.38	7.93867
2431.17	9.404
2433.96	9.84257
2436.74	8.63128
2439.53	9.37602
2442.32	9.22468
2445.1	8.79784
2447.88	8.88537
2450.67	7.87067
2453.45	6.73823
2456.23	5.65843
2459.01	5.62017
2461.79	5.07218
2464.57	3.8408
2467.34	3.62881
2470.12	2.00831
2472.89	1.52623
2475.67	1.2811
2478.44	0.712055
2481.21	-0.118913
2483.98	0.0854875
2486.75	-0.0837455
2489.52	0.109989
2492.29	0.357764
2495.06	-0.722432
2497.82	-0.877441
2500.59	-0.024641
2503.35	0.0945613
2506.11	1.60747
2508.88	1.92035
2511.63	2.30634
2514.39	3.45799
2517.15	3.90697
2519.91	4.92016
2522.67	4.87943
2525.42	6.04683
2528.18	6.50349
2530.93	6.82586
2533.69	6.13015
2536.44	6.66379
2539.19	7.64668
2541.94	7.02154
2544.69	5.88816
2547.44	5.12159
2550.18	4.70941
2552.93	4.50903
2555.68	3.20239
2558.42	3.21146
2561.16	3.11491
2563.9	3.63015
2566.64	3.7604
2569.38	3.70359
2572.12	3.57547
2574.86	4.32155
2577.6	3.91417
2580.34	4.53997
2583.07	4.93442
2585.81	5.76659
2588.54	5.04973
2591.27	5.37857
2594	5.6764
2596.73	5.00528
2599.46	4.85879
2602.19	4.14169
2604.92	4.48456
2607.64	3.14531
2610.37	2.19036
2613.09	1.7608
2615.82	2.42566
2618.54	2.63553
2621.26	1.86247
2623.98	2.61616
2626.7	2.97494
2629.42	3.53872
2632.14	2.35729
2634.86	2.11642
2637.57	1.84234
2640.29	2.35971
2643	2.15037
2645.72	2.7431
2648.43	2.59212
2651.14	1.47081
2653.85	1.66104
2656.56	1.20261
2659.27	1.27075
2661.97	0.234537
2664.68	1.76063
2667.38	2.17396
2670.09	1.69974
2672.79	2.11213
2675.49	3.11457
2678.2	2.87873
2680.89	3.06456
2683.59	4.26966
2686.29	4.76514
2688.99	5.16311
2691.69	5.74787
2694.38	4.68165
2697.08	4.73574
2699.77	5.0223
2702.46	4.83224
2705.16	6.28512
2707.85	6.83509
2710.54	7.54763
2713.23	8.80219
2715.92	9.17401
2718.6	10.4689
2721.29	11.679
2723.97	11.6028
2726.66	12.8427
2729.34	13.0703
2732.02	12.7213
2734.7	12.5622
2737.39	12.0008
2740.06	11.7879
2742.74	10.5856
2745.42	8.39737
2748.1	8.92095
2750.77	8.18815
2753.45	5.85977
2756.12	3.72563
2758.79	2.44661
2761.47	1.7627
2764.14	0.320621
2766.81	-0.142176
2769.48	-0.29497
2772.14	-0.762614
2774.81	-1.3007
2777.48	0.212476
2780.14	-0.644062
2782.81	-0.190538
2785.47	-0.310873
2788.13	-0.9201
2790.79	-0.437608
2793.46	0.143346
2796.11	-0.240619
2798.77	0.53685
2801.43	-0.273422
2804.09	-0.571848
2806.74	-0.711919
2809.4	-1.46059
2812.05	-1.94029
2814.71	-1.41667
2817.36	1.83629
2820.01	7.39199
2822.66	15.5273
2825.31	23.6381
2827.96	33.3271
2830.61	42.3935
2833.25	54.1778
2835.9	66.3808
2838.54	77.6558
2841.18	90.8428
2843.83	103.224
2846.47	115.643
2849.11	129.522
2851.75	142.393
2854.39	155.972
2857.03	168.685
2859.67	179.883
2862.3	190.421
2864.94	199.601
2867.57	206.551
2870.21	211.999
2872.84	216.718
2875.47	220.571
2878.1	224.317
2880.73	229.089
2883.36	235.292
2885.99	240.808
2888.61	244.779
2891.24	249.356
2893.87	254.986
2896.49	259.634
2899.11	266.362
2901.74	271.893
2904.36	278.316
2906.98	287.408
2909.6	294.772
2912.22	305.972
2914.83	316.488
2917.45	325.781
2920.07	334.614
2922.68	342.131
2925.3	347.794
2927.91	351.986
2930.52	353.113
2933.13	351.248
2935.74	348.567
2938.35	341.775
2940.96	333.089
2943.57	322.189
2946.18	310.916
2948.78	298.669
2951.39	284.996
2953.99	271.613
2956.6	257.38
2959.2	243.599
2961.8	228.633
2964.4	214.297
2967	201.754
2969.6	188.659
2972.2	175.259
2974.79	163.283
2977.39	152.411
2979.98	139.895
2982.58	126.868
2985.17	115.606
2987.76	103.34
2990.36	92.995
2992.95	82.833
2995.54	73.0948
2998.12	62.7325
3000.71	54.1268
3003.3	45.9965
3005.88	37.3597
3008.47	30.0982
3011.05	25.7012
3013.64	21.3759
3016.22	17.7034
3018.8	15.3827
3021.38	12.5298
3023.96	10.3334
3026.54	8.13577
3029.12	6.91604
3031.69	5.98942
3034.27	5.23021
3036.85	5.52263
3039.42	6.53311
3041.99	6.45421
3044.57	6.45596
3047.14	6.97376
3049.71	6.93825
3052.28	8.191
3054.85	8.59484
3057.42	9.7511
3059.98	10.1957
3062.55	10.6312
3065.11	10.1936
3067.68	8.9249
3070.24	8.29372
3072.8	7.88505
3075.37	7.50275
3077.93	6.99095
3080.49	5.50093
3083.05	3.27022
3085.61	1.61481
3088.16	0.682417
3090.72	0.105439
3093.27	0.729692
3095.83	1.16865
3098.38	1.30989
3100.94	2.06671
3103.49	3.16514
3106.04	3.49662
3108.59	4.38067
3111.14	6.05999
3113.69	7.28864
3116.23	9.03456
3118.78	11.5604
3121.33	13.3867
3123.87	15.2968
3126.42	16.7909
3128.96	18.1347
3131.5	20.2514
3134.04	21.2489
3136.58	22.8157
3139.12	24.0128
3141.66	25.3422
3144.2	26.255
3146.74	27.5947
3149.27	28.6175