File: data/Raman/poly_smoothed/Mb_50_18_21_1x_45s_532 nm_x100_100%_600 gr_mm_01.txt
#Acq. time (s)=	45
#Accumulations=	2
#Range (cm-¹)=	200...3150
#Windows=	2
#Auto scanning=	Off
#Autofocus=	Off
#Macrospot=	Off
#AutoExposure=	Off
#Spike filter=	Multiple accum.
#Delay time (s)=	0
#Binning=	1
#Readout mode=	Signal
#DeNoise=	Off
#ICS correction=	On
#Dark correction=	Off
#Inst. Process=	Off
#Detector Gain=	Best Dynamic Range
#Detector ADC=	20 kHz
#Detector temperature (°C)=	-70.08
#Instrument=	LabRAM HR Evol
#Detector=	Synapse
#Objective=	x100
#Grating=	600 gr/mm
#ND Filter=	100%
#Laser (nm)=	532
#Hole=	100.021
#Range=	Auto
#Laser Pol.=	No
#Raman. Pol.=	No
#Laser Pol. (°)=	-0.0007625
#Raman Pol. (°)=	89.9995
#Collection=	Microscope
#StageXY=	Marzhauser
#StageZ=	Marzhauser
#X (µm)=	28300.2
#Y (µm)=	-3322
#Z (µm)=	1040.6
#Full time(mm:ss)=	3:18
#Project=
#Sample=
#Site=
#Title=	Mb_50_18_21_2x_45s_532 nm_x100_100%_600 gr_mm
#Remark=
#Date=	12.07.2022 12:24
#Acquired=	12.07.2022 12:24:58
#Base:Fit=	10.08.2022 10:49:18
#Base:Sub=	10.08.2022 10:49:30
#Filter:Polynom=	16.08.2022 10:14:59
#AxisType[0]=Intens
#AxisUnit[0]=Cnt
#AxisType[1]=Spectr
#AxisUnit[1]=1/cm
200.388	121.757
204.019	110.628
207.646	101.54
211.274	93.0179
214.899	87.1967
218.524	78.2276
222.146	73.8198
225.766	70.9058
229.388	65.1301
233.005	56.814
236.621	49.0856
240.236	43.6969
243.852	39.0078
247.464	35.3314
251.074	30.584
254.683	25.9797
258.291	22.5009
261.897	22.1587
265.504	19.7552
269.108	17.6866
272.71	15.2931
276.311	12.5586
279.91	7.49965
283.508	4.46504
287.105	3.7948
290.698	6.50325
294.291	8.04984
297.884	11.9286
301.475	16.7288
305.064	20.9813
308.652	24.3779
312.237	30.9369
315.822	31.4704
319.406	32.3576
322.987	32.4528
326.568	34.067
330.148	34.3117
333.724	31.7715
337.301	27.0736
340.875	20.6567
344.449	19.7588
348.02	24.2822
351.592	28.8241
355.16	35.6079
358.728	48.5456
362.294	61.9409
365.858	75.5965
369.422	91.0199
372.983	106.185
376.543	117.747
380.102	128.479
383.661	136.975
387.216	144.474
390.771	146.57
394.324	146.694
397.875	140.529
401.425	132.977
404.974	121.985
408.524	108.717
412.07	94.1573
415.614	74.2539
419.156	53.3939
422.698	33.7416
426.238	16.6765
429.777	6.1732
433.315	-0.233245
436.852	-5.08686
440.387	-7.16141
443.919	-6.156
447.451	-3.90569
450.982	-3.6183
454.512	-2.69274
458.038	-1.15991
461.565	-0.830433
465.091	1.1971
468.613	2.05221
472.136	4.58652
475.655	9.24707
479.176	15.7131
482.692	24.5568
486.21	36.6676
489.724	52.716
493.237	68.3332
496.75	85.8098
500.26	102.169
503.771	117.332
507.279	130.301
510.785	142.23
514.289	149.787
517.793	154.991
521.297	155.734
524.797	156.637
528.297	154.412
531.795	146.803
535.291	135.522
538.787	123.946
542.281	111.694
545.773	94.3273
549.264	78.3265
552.754	61.1806
556.243	47.2091
559.73	36.0726
563.216	30.226
566.701	26.1232
570.182	23.8057
573.664	26.2169
577.145	29.8517
580.624	32.4658
584.1	34.2308
587.577	35.249
591.052	35.2598
594.524	36.8867
597.997	39.7502
601.466	41.7961
604.936	43.6649
608.403	44.0808
611.87	45.3706
615.334	43.8937
618.799	41.2237
622.26	38.9106
625.72	36.2948
629.181	32.7724
632.638	29.6977
636.095	26.1508
639.551	22.9535
643.005	21.2304
646.457	20.5933
649.908	20.6545
653.357	19.3989
656.806	21.3525
660.253	22.3714
663.7	23.0326
667.145	21.0321
670.588	21.1889
674.027	19.4504
677.468	20.7013
680.907	24.4943
684.345	26.8721
687.781	29.7661
691.216	31.2286
694.65	33.7396
698.081	34.1957
701.512	34.5509
704.942	35.7119
708.371	37.9459
711.796	38.2509
715.222	36.5608
718.645	34.6373
722.068	31.1771
725.49	28.6582
728.909	28.0352
732.329	30.6824
735.745	40.9819
739.16	58.9059
742.576	81.8744
745.988	108.073
749.401	134.523
752.811	160.649
756.22	184.817
759.627	208.416
763.035	228.688
766.44	244.435
769.843	253.848
773.245	260.029
776.646	259.673
780.046	255.101
783.444	248.989
786.841	238.641
790.237	222.33
793.631	201.425
797.024	179.18
800.416	153.213
803.807	126.919
807.196	100.909
810.584	81.0281
813.971	66.8739
817.354	57.4051
820.739	56.3379
824.122	57.8574
827.503	58.8319
830.882	59.3183
834.261	59.8015
837.637	59.1401
841.013	57.5074
844.389	57.242
847.761	54.0096
851.131	49.088
854.503	44.9309
857.871	42.1214
861.24	39.2022
864.606	38.5814
867.97	39.0029
871.336	36.5754
874.698	34.2944
878.058	31.9616
881.418	28.2783
884.778	26.0513
888.135	23.1378
891.49	23.2363
894.845	23.4368
898.198	24.9335
901.55	25.8039
904.901	24.5782
908.25	25.2697
911.598	25.2458
914.945	26.658
918.291	24.2028
921.635	22.635
924.978	22.382
928.318	23.518
931.659	21.7847
934.998	20.1891
938.336	19.4652
941.671	18.7955
945.007	17.7196
948.339	16.1197
951.672	12.9168
955.004	9.68376
958.333	7.07223
961.662	4.02464
964.989	1.11322
968.315	1.25893
971.639	-0.732754
974.962	0.347753
978.285	0.342498
981.605	-2.97386
984.924	-8.39274
988.243	-10.0323
991.56	-8.85102
994.875	-1.92625
998.188	8.41827
1001.5	24.2212
1004.81	45.5872
1008.12	68.0739
1011.43	90.1607
1014.74	111.067
1018.05	131.058
1021.35	151.218
1024.65	167.361
1027.96	179.348
1031.26	189.227
1034.56	193.616
1037.86	192.736
1041.16	188.004
1044.45	178.036
1047.75	165.887
1051.04	153.388
1054.33	142.617
1057.62	131.517
1060.91	120.669
1064.2	111.528
1067.49	107.341
1070.77	110.043
1074.06	113.55
1077.34	121.134
1080.62	127.983
1083.91	132.477
1087.18	137.179
1090.46	139.827
1093.74	141.499
1097.02	140.919
1100.29	137.497
1103.56	129.538
1106.84	118.197
1110.11	104.965
1113.38	89.3498
1116.64	73.7955
1119.91	54.6847
1123.18	38.9665
1126.44	23.2467
1129.7	15.9823
1132.97	10.1519
1136.23	8.93155
1139.49	8.97786
1142.74	10.9933
1146	11.8017
1149.26	12.3222
1152.51	11.1523
1155.76	11.7855
1159.01	10.6595
1162.27	11.1782
1165.51	10.1945
1168.76	10.2657
1172.01	10.5433
1175.25	10.5136
1178.5	10.5948
1181.74	6.89962
1184.98	7.06166
1188.22	5.31125
1191.46	5.40981
1194.7	7.72571
1197.94	7.94095
1201.17	8.64214
1204.41	8.94815
1207.64	11.5495
1210.87	15.5463
1214.1	18.1924
1217.33	21.3495
1220.56	25.6199
1223.79	28.4265
1227.01	31.9735
1230.23	36.1138
1233.46	41.5279
1236.68	43.401
1239.9	45.9108
1243.12	46.5758
1246.34	46.6864
1249.55	48.775
1252.77	51.347
1255.98	52.9663
1259.2	53.7049
1262.41	56.3865
1265.62	57.806
1268.83	60.7716
1272.03	67.5076
1275.24	70.671
1278.45	73.4818
1281.65	74.9052
1284.85	75.6869
1288.06	78.6113
1291.26	78.0906
1294.46	80.3553
1297.66	81.519
1300.85	82.0865
1304.05	83.0182
1307.24	81.8566
1310.43	81.4798
1313.63	79.0229
1316.82	76.9503
1320.01	74.5537
1323.2	71.3808
1326.38	68.6371
1329.57	67.3882
1332.76	65.0379
1335.94	63.241
1339.12	61.4895
1342.3	59.5607
1345.48	57.9056
1348.66	57.1038
1351.84	55.8776
1355.01	53.3345
1358.19	51.0691
1361.36	45.6206
1364.53	42.1346
1367.71	40.8375
1370.88	39.2929
1374.04	35.1457
1377.21	29.9022
1380.38	26.8125
1383.54	21.4293
1386.71	19.7189
1389.87	15.8087
1393.03	13.0922
1396.19	10.5471
1399.35	10.4553
1402.51	12.291
1405.67	17.6842
1408.82	25.1494
1411.98	33.0561
1415.13	43.0699
1418.28	54.7487
1421.43	67.8272
1424.58	81.6787
1427.73	97.5033
1430.88	111.065
1434.02	123.252
1437.17	132.625
1440.31	141.083
1443.45	147.154
1446.6	150.006
1449.74	148.98
1452.87	146.553
1456.01	144.808
1459.15	141.042
1462.28	136.443
1465.42	129.725
1468.55	123.956
1471.68	115.968
1474.81	107.469
1477.94	100.016
1481.07	94.3653
1484.2	88.1383
1487.32	80.5542
1490.45	72.1951
1493.57	67.3749
1496.69	61.952
1499.81	55.7063
1502.93	50.92
1506.05	42.1631
1509.17	36.284
1512.28	29.9756
1515.4	24.1877
1518.51	19.545
1521.63	14.7238
1524.74	12.0315
1527.85	9.92189
1530.96	10.559
1534.06	11.2602
1537.17	11.5015
1540.28	14.7902
1543.38	16.8427
1546.48	18.2066
1549.59	19.5869
1552.69	22.3375
1555.79	27.0658
1558.88	29.462
1561.98	32.1874
1565.08	36.2513
1568.17	40.3296
1571.27	44.8481
1574.36	49.0533
1577.45	54.6782
1580.54	58.7008
1583.63	62.185
1586.72	67.1869
1589.8	69.0954
1592.89	72.0966
1595.97	75.427
1599.06	78.0976
1602.14	79.6513
1605.22	79.8697
1608.3	80.4664
1611.38	79.8027
1614.46	81.1009
1617.53	83.4859
1620.61	82.9631
1623.68	84.2295
1626.75	87.0947
1629.82	91.5071
1632.9	95.2435
1635.96	97.9946
1639.03	103.524
1642.1	109.585
1645.16	112.949
1648.23	115.834
1651.29	118.657
1654.36	119.122
1657.42	118.052
1660.48	116.706
1663.53	111.665
1666.59	107.661
1669.65	104.165
1672.7	98.2635
1675.76	90.1115
1678.81	80.9091
1681.86	72.7756
1684.91	63.3046
1687.96	54.9937
1691.01	47.678
1694.06	40.3556
1697.11	35.5249
1700.15	30.5591
1703.2	26.3161
1706.24	23.532
1709.28	19.1159
1712.32	17.8725
1715.36	16.5865
1718.4	14.5943
1721.43	13.4378
1724.47	13.0939
1727.5	10.7386
1730.54	8.4375
1733.57	6.62466
1736.6	5.82887
1739.63	5.99679
1742.66	5.77409
1745.69	5.64738
1748.72	3.1005
1751.74	2.78479
1754.77	2.59802
1757.79	0.344578
1760.81	-0.39798
1763.83	-0.548188
1766.85	-0.0166392
1769.87	1.67085
1772.89	1.65457
1775.91	1.25581
1778.92	1.0398
1781.94	2.23653
1784.95	3.43992
1787.96	3.3851
1790.97	4.20197
1793.98	3.16181
1796.99	3.38362
1800	2.49579
1803	1.06985
1806.01	1.26862
1809.01	2.23321
1812.02	3.00735
1815.02	2.97394
1818.02	2.85413
1821.02	2.42411
1824.02	1.65366
1827.01	2.68806
1830.01	2.34455
1833	2.44345
1836	3.0839
1838.99	2.88639
1841.98	5.116
1844.97	6.10028
1847.96	6.825
1850.95	6.24592
1853.94	6.9947
1856.92	6.99253
1859.91	7.02085
1862.89	6.9005
1865.88	6.41941
1868.86	6.83095
1871.84	6.55874
1874.82	6.60397
1877.8	7.46941
1880.77	8.30483
1882.51	8.79604
1885.5	9.64536
1888.48	10.0613
1891.47	9.70292
1894.46	10.659
1897.44	12.3827
1900.42	15.2544
1903.41	15.4459
1906.39	16.4158
1909.37	17.0153
1912.35	18.2384
1915.32	19.3766
1918.3	19.5962
1921.28	20.621
1924.25	18.8875
1927.22	17.9398
1930.2	16.2776
1933.17	16.0736
1936.14	15.0572
1939.11	13.9193
1942.08	13.2485
1945.04	11.904
1948.01	11.4006
1950.97	10.1552
1953.94	9.94416
1956.9	8.52968
1959.86	8.28543
1962.82	7.05402
1965.78	7.73377
1968.74	7.93768
1971.69	9.27134
1974.65	10.9452
1977.61	11.3532
1980.56	13.7861
1983.51	15.4785
1986.46	15.5389
1989.41	18.2079
1992.36	20.6052
1995.31	21.1362
1998.26	21.5547
2001.2	22.4738
2004.15	23.3771
2007.09	24.1355
2010.04	25.1561
2012.98	25.0107
2015.92	25.1786
2018.86	24.6006
2021.8	23.0047
2024.74	22.541
2027.67	21.1812
2030.61	20.7385
2033.54	19.8712
2036.47	19.8803
2039.41	20.553
2042.34	21.8472
2045.27	23.5967
2048.2	25.5911
2051.12	28.7011
2054.05	28.9475
2056.98	31.1188
2059.9	32.868
2062.82	34.7299
2065.75	37.7642
2068.67	41.1248
2071.59	43.9587
2074.51	46.0869
2077.43	49.5019
2080.34	53.1414
2083.26	55.3961
2086.17	58.6025
2089.09	60.6162
2092	64.5531
2094.91	68.9823
2097.82	75.2147
2100.73	80.4638
2103.64	85.9624
2106.55	92.0576
2109.46	98.6901
2112.36	104.605
2115.27	110.992
2118.17	118.168
2121.07	124.834
2123.97	131.725
2126.87	139.305
2129.77	146.559
2132.67	154.716
2135.57	162.602
2138.46	170.276
2141.36	177.884
2144.25	185.632
2147.14	191.099
2150.03	198.004
2152.92	202.649
2155.81	208.744
2158.7	213.883
2161.59	217.319
2164.48	220.311
2167.36	220.797
2170.25	221.152
2173.13	220.479
2176.01	217.208
2178.89	214.079
2181.77	210.314
2184.65	205.034
2187.53	201.59
2190.41	196.777
2193.28	191.255
2196.16	185.817
2199.03	180.289
2201.9	173.592
2204.78	167.084
2207.65	160.794
2210.51	154.252
2213.38	148.232
2216.25	140.468
2219.12	135.154
2221.98	127.042
2224.85	120.45
2227.71	115.155
2230.57	106.98
2233.43	98.2025
2236.29	91.1324
2239.15	84.6568
2242.01	78.3267
2244.87	71.6115
2247.73	66.8232
2250.58	63.0925
2253.43	59.6211
2256.29	56.8315
2259.14	53.582
2261.99	50.3627
2264.84	47.0457
2267.69	44.7402
2270.54	40.912
2273.38	39.2629
2276.23	37.407
2279.07	34.2039
2281.92	31.8279
2284.76	30.2589
2287.6	28.0088
2290.44	24.2622
2293.28	22.4734
2296.12	21.5304
2298.96	20.099
2301.79	21.192
2304.63	18.4606
2307.46	17.8131
2310.3	16.1594
2313.13	15.8881
2315.96	14.4004
2318.79	14.774
2321.62	14.5597
2324.45	14.677
2327.27	13.1206
2330.1	12.5654
2332.93	11.0883
2335.75	9.81458
2338.57	9.09415
2341.4	6.88294
2344.22	5.76502
2347.04	5.79566
2349.86	5.12492
2352.67	4.49938
2355.49	3.15153
2358.31	1.73411
2361.12	1.93722
2363.94	3.02707
2366.75	3.63189
2369.56	4.2369
2372.37	3.03459
2375.18	2.03523
2377.99	0.500114
2380.8	0.763763
2383.61	0.919939
2386.41	2.43155
2389.22	3.51903
2392.02	4.1863
2394.82	5.69956
2397.63	7.57831
2400.43	9.16495
2403.23	8.78861
2406.02	11.0486
2408.82	12.8158
2411.62	15.0138
2414.41	15.2721
2417.21	16.1759
2420	15.8315
2422.79	15.8975
2425.59	14.9274
2428.38	15.2656
2431.17	13.7479
2433.96	12.7393
2436.74	12.0565
2439.53	9.49216
2442.32	7.85658
2445.1	6.22403
2447.88	5.46757
2450.67	4.12905
2453.45	2.98826
2456.23	1.65275
2459.01	1.29994
2461.79	0.883689
2464.57	0.386164
2467.34	-0.194127
2470.12	-1.5257
2472.89	-1.09222
2475.67	0.641064
2478.44	0.942761
2481.21	-0.596238
2483.98	-1.12062
2486.75	-0.410837
2489.52	-1.15903
2492.29	-0.822594
2495.06	-1.58363
2497.82	-1.91199
2500.59	-1.07743
2503.35	0.550894
2506.11	0.613759
2508.88	1.29209
2511.63	1.12784
2514.39	2.84482
2517.15	3.11338
2519.91	3.14604
2522.67	3.10255
2525.42	3.79371
2528.18	4.41799
2530.93	3.70239
2533.69	4.69262
2536.44	5.61936
2539.19	5.89713
2541.94	6.99921
2544.69	7.24528
2547.44	6.91997
2550.18	7.16543
2552.93	7.3196
2555.68	7.95414
2558.42	6.49683
2561.16	5.73698
2563.9	5.59208
2566.64	6.18912
2569.38	7.68896
2572.12	9.09163
2574.86	9.28792
2577.6	8.49849
2580.34	7.55657
2583.07	7.43136
2585.81	7.6399
2588.54	6.60214
2591.27	6.71302
2594	7.87461
2596.73	8.13507
2599.46	8.56208
2602.19	9.27526
2604.92	8.32421
2607.64	8.09057
2610.37	8.3526
2613.09	8.21013
2615.82	7.87121
2618.54	8.6771
2621.26	8.15372
2623.98	8.11532
2626.7	6.95601
2629.42	7.30585
2632.14	7.89837
2634.86	8.53414
2637.57	9.19709
2640.29	8.35066
2643	8.15854
2645.72	7.60465
2648.43	6.9088
2651.14	7.91061
2653.85	8.94882
2656.56	9.00366
2659.27	11.2202
2661.97	12.5934
2664.68	12.3736
2667.38	12.1911
2670.09	12.7104
2672.79	12.2432
2675.49	12.987
2678.2	12.1921
2680.89	12.8169
2683.59	12.9137
2686.29	12.5698
2688.99	11.9435
2691.69	12.4054
2694.38	12.5219
2697.08	14.9749
2699.77	14.3269
2702.46	14.7839
2705.16	14.9576
2707.85	14.5532
2710.54	16.2086
2713.23	15.996
2715.92	16.1297
2718.6	16.8493
2721.29	17.0399
2723.97	17.2401
2726.66	17.5725
2729.34	15.5506
2732.02	15.3899
2734.7	15.7179
2737.39	14.7697
2740.06	12.7359
2742.74	12.2927
2745.42	11.5312
2748.1	10.244
2750.77	10.0563
2753.45	9.24525
2756.12	8.94344
2758.79	9.05224
2761.47	8.62968
2764.14	7.65399
2766.81	5.49692
2769.48	4.14479
2772.14	4.10214
2774.81	4.61624
2777.48	4.74676
2780.14	4.82657
2782.81	4.50807
2785.47	2.85258
2788.13	3.21817
2790.79	2.26972
2793.46	1.92126
2796.11	1.8753
2798.77	3.06029
2801.43	2.07027
2804.09	-0.129284
2806.74	-0.117229
2809.4	0.430654
2812.05	-0.401515
2814.71	1.809
2817.36	5.33525
2820.01	9.21499
2822.66	15.858
2825.31	23.4783
2827.96	32.0292
2830.61	44.5494
2833.25	58.8465
2835.9	74.1702
2838.54	89.5265
2841.18	105.225
2843.83	119.981
2846.47	135.707
2849.11	150.915
2851.75	166.632
2854.39	182.816
2857.03	196.814
2859.67	211.016
2862.3	221.7
2864.94	232.041
2867.57	239.881
2870.21	247.849
2872.84	252.242
2875.47	257.802
2878.1	263.747
2880.73	269.279
2883.36	275.48
2885.99	285.192
2888.61	292.576
2891.24	303.175
2893.87	314.174
2896.49	327.815
2899.11	341.469
2901.74	358.288
2904.36	379.022
2906.98	401.1
2909.6	427.827
2912.22	455.078
2914.83	481.704
2917.45	509.125
2920.07	535.43
2922.68	556.306
2925.3	574.849
2927.91	588.521
2930.52	598.591
2933.13	601.5
2935.74	599.503
2938.35	595.987
2940.96	586.097
2943.57	571.515
2946.18	553.861
2948.78	533.549
2951.39	509.119
2953.99	482.223
2956.6	455.89
2959.2	429.163
2961.8	403.881
2964.4	380.565
2967	358.659
2969.6	338.596
2972.2	320.315
2974.79	303.042
2977.39	284.04
2979.98	267.121
2982.58	249.021
2985.17	231.074
2987.76	211.771
2990.36	192.623
2992.95	172.707
2995.54	154.841
2998.12	138.214
3000.71	122.018
3003.3	106.783
3005.88	91.2168
3008.47	78.0451
3011.05	65.804
3013.64	53.3817
3016.22	42.2357
3018.8	34.9439
3021.38	28.6744
3023.96	24.5256
3026.54	19.9689
3029.12	16.2717
3031.69	15.2224
3034.27	14.857
3036.85	13.7802
3039.42	13.5129
3041.99	14.9986
3044.57	15.6261
3047.14	15.6653
3049.71	17.128
3052.28	16.3082
3054.85	17.4878
3057.42	17.2555
3059.98	17.5009
3062.55	17.6575
3065.11	16.9212
3067.68	15.1936
3070.24	13.2894
3072.8	11.7245
3075.37	9.50446
3077.93	6.46642
3080.49	6.56374
3083.05	6.50615
3085.61	4.7248
3088.16	2.39047
3090.72	1.95681
3093.27	2.07126
3095.83	3.27787
3098.38	3.9088
3100.94	5.4764
3103.49	7.8454
3106.04	10.3139
3108.59	13.3371
3111.14	15.3082
3113.69	17.2409
3116.23	20.3443
3118.78	22.613
3121.33	25.3042
3123.87	29.023
3126.42	30.614
3128.96	33.5875
3131.5	36.2161
3134.04	39.2859
3136.58	42.657
3139.12	45.6022
3141.66	48.9801
3144.2	52.2981
3146.74	56.3756
3149.27	63.6405