File: data/Raman/poly_smoothed/Mb_50_18_22_1x_45s_532 nm_x100_100%_600 gr_mm_01.txt
#Acq. time (s)=	45
#Accumulations=	2
#Range (cm-¹)=	200...3150
#Windows=	2
#Auto scanning=	Off
#Autofocus=	Off
#Macrospot=	Off
#AutoExposure=	Off
#Spike filter=	Multiple accum.
#Delay time (s)=	0
#Binning=	1
#Readout mode=	Signal
#DeNoise=	Off
#ICS correction=	On
#Dark correction=	Off
#Inst. Process=	Off
#Detector Gain=	Best Dynamic Range
#Detector ADC=	20 kHz
#Detector temperature (°C)=	-69.62
#Instrument=	LabRAM HR Evol
#Detector=	Synapse
#Objective=	x100
#Grating=	600 gr/mm
#ND Filter=	100%
#Laser (nm)=	532
#Hole=	100.021
#Range=	Auto
#Laser Pol.=	No
#Raman. Pol.=	No
#Laser Pol. (°)=	-0.0007625
#Raman Pol. (°)=	89.9995
#Collection=	Microscope
#StageXY=	Marzhauser
#StageZ=	Marzhauser
#X (µm)=	28334.8
#Y (µm)=	-3322.2
#Z (µm)=	1040.6
#Full time(mm:ss)=	3:19
#Project=
#Sample=
#Site=
#Title=	Mb_50_18_22_2x_45s_532 nm_x100_100%_600 gr_mm
#Remark=
#Date=	12.07.2022 12:29
#Acquired=	12.07.2022 12:29:12
#Base:Fit=	10.08.2022 10:49:18
#Base:Sub=	10.08.2022 10:49:30
#Filter:Polynom=	16.08.2022 10:14:59
#AxisType[0]=Intens
#AxisUnit[0]=Cnt
#AxisType[1]=Spectr
#AxisUnit[1]=1/cm
200.388	17.4924
204.019	10.121
207.646	5.56277
211.274	3.0443
214.899	0.707319
218.524	0.337634
222.146	0.951977
225.766	2.01714
229.388	2.52824
233.005	2.21763
236.621	1.6899
240.236	2.67133
243.852	3.64511
247.464	4.76402
251.074	5.72935
254.683	6.68474
258.291	5.48325
261.897	7.28334
265.504	5.76579
269.108	4.26893
272.71	2.99673
276.311	0.830264
279.91	-0.798693
283.508	-0.453616
287.105	-1.48417
290.698	-0.431629
294.291	5.58068
297.884	10.1766
301.475	16.9469
305.064	24.1127
308.652	30.7313
312.237	36.271
315.822	39.9325
319.406	43.0027
322.987	47.8729
326.568	50.0792
330.148	51.099
333.724	49.7137
337.301	45.2234
340.875	40.1492
344.449	36.8779
348.02	36.4939
351.592	41.078
355.16	49.8693
358.728	62.7867
362.294	75.6646
365.858	89.7788
369.422	104.994
372.983	119.343
376.543	134.5
380.102	148.061
383.661	159.483
387.216	166.108
390.771	169.041
394.324	168.756
397.875	164.237
401.425	155.417
404.974	144.783
408.524	130.816
412.07	114.693
415.614	96.2051
419.156	74.8381
422.698	55.701
426.238	36.558
429.777	22.1163
433.315	12.3998
436.852	8.19475
440.387	7.17521
443.919	7.79242
447.451	7.72827
450.982	8.51316
454.512	9.44254
458.038	9.12943
461.565	10.1311
465.091	10.3895
468.613	10.9699
472.136	12.6241
475.655	15.262
479.176	22.2913
482.692	30.2292
486.21	41.4685
489.724	52.8764
493.237	69.8396
496.75	85.9713
500.26	104.942
503.771	119.828
507.279	130.764
510.785	140.617
514.289	146.571
517.793	152.313
521.297	155.405
524.797	154.363
528.297	150.985
531.795	146.042
535.291	135.599
538.787	124.262
542.281	110.802
545.773	95.8229
549.264	78.8451
552.754	63.9625
556.243	50.2228
559.73	37.4717
563.216	28.3526
566.701	24.5928
570.182	23.7206
573.664	23.4785
577.145	26.7961
580.624	31.5029
584.1	33.8237
587.577	36.3531
591.052	37.3089
594.524	37.7441
597.997	39.791
601.466	40.1543
604.936	41.7782
608.403	41.0331
611.87	38.7436
615.334	37.0295
618.799	32.9415
622.26	30.0124
625.72	26.4717
629.181	22.2296
632.638	15.4826
636.095	10.1271
639.551	6.80336
643.005	2.52554
646.457	1.78529
649.908	2.09958
653.357	2.30687
656.806	1.26717
660.253	-0.0246443
663.7	1.59615
667.145	1.50685
670.588	2.50326
674.027	3.77691
677.468	2.46466
680.907	3.0682
684.345	4.60785
687.781	6.12151
691.216	7.38462
694.65	8.85777
698.081	10.534
701.512	11.483
704.942	13.4239
708.371	14.9617
711.796	15.717
715.222	15.2895
718.645	15.0242
722.068	14
725.49	12.1806
728.909	8.59902
732.329	9.22177
735.745	15.0155
739.16	24.7843
742.576	44.1586
745.988	70.0285
749.401	99.5276
752.811	127.785
756.22	156.171
759.627	179.672
763.035	201.738
766.44	218.775
769.843	233.095
773.245	243.116
776.646	249.147
780.046	250.158
783.444	244.881
786.841	236.125
790.237	223.27
793.631	206.18
797.024	182.338
800.416	157.192
803.807	130.678
807.196	103.211
810.584	78.1305
813.971	58.0805
817.354	45.2359
820.739	37.66
824.122	34.6917
827.503	36.7957
830.882	39.3489
834.261	39.6527
837.637	39.179
841.013	38.1398
844.389	36.4194
847.761	34.0842
851.131	31.5249
854.503	29.3047
857.871	27.7644
861.24	26.6847
864.606	23.5675
867.97	21.4431
871.336	17.7509
874.698	16.0222
878.058	14.1549
881.418	11.3598
884.778	9.23324
888.135	7.48652
891.49	6.79946
894.845	5.10722
898.198	3.26883
901.55	3.97877
904.901	3.02709
908.25	5.77168
911.598	7.30664
914.945	9.23843
918.291	8.36882
921.635	11.9641
924.978	13.5771
928.318	13.5516
931.659	13.6883
934.998	13.7037
938.336	14.7969
941.671	13.8994
945.007	12.5009
948.339	11.6159
951.672	8.62221
955.004	8.98686
958.333	7.04131
961.662	4.11114
964.989	2.22645
968.315	1.58319
971.639	-0.60833
974.962	-1.12357
978.285	-1.96028
981.605	-2.4045
984.924	-5.04979
988.243	-9.46342
991.56	-10.0893
994.875	-8.19611
998.188	1.51243
1001.5	15.4552
1004.81	30.5533
1008.12	47.0901
1011.43	66.7839
1014.74	85.2505
1018.05	104.785
1021.35	123.553
1024.65	140.839
1027.96	154.416
1031.26	165.854
1034.56	170.649
1037.86	170.017
1041.16	165.156
1044.45	158.372
1047.75	150.213
1051.04	141.103
1054.33	133.288
1057.62	129.79
1060.91	127.935
1064.2	126.276
1067.49	126.483
1070.77	130.683
1074.06	137.324
1077.34	145.214
1080.62	154.598
1083.91	159.897
1087.18	162.1
1090.46	165.87
1093.74	167.314
1097.02	165.148
1100.29	159.161
1103.56	152.025
1106.84	139.696
1110.11	122.584
1113.38	103.145
1116.64	82.2012
1119.91	59.9968
1123.18	41.7327
1126.44	27.0757
1129.7	14.1933
1132.97	6.347
1136.23	5.95217
1139.49	6.01749
1142.74	8.91711
1146	10.9591
1149.26	12.8134
1152.51	12.9355
1155.76	13.2742
1159.01	15.3485
1162.27	17.2469
1165.51	17.5502
1168.76	19.5036
1172.01	22.3156
1175.25	24.2249
1178.5	27.8437
1181.74	30.7559
1184.98	33.8347
1188.22	36.7259
1191.46	38.8159
1194.7	40.3108
1197.94	39.8877
1201.17	42.0132
1204.41	43.4503
1207.64	45.1746
1210.87	43.6251
1214.1	47.1185
1217.33	47.9269
1220.56	49.492
1223.79	53.1662
1227.01	55.1291
1230.23	56.3471
1233.46	56.6152
1236.68	58.7099
1239.9	60.0105
1243.12	60.53
1246.34	60.9076
1249.55	60.8369
1252.77	61.2857
1255.98	61.517
1259.2	63.2437
1262.41	63.3686
1265.62	57.4363
1268.83	48
1272.03	52.0347
1275.24	64.9823
1278.45	79.2981
1281.65	89.7295
1284.85	99.3124
1288.06	107.206
1291.26	112.855
1294.46	116.55
1297.66	120.002
1300.85	123.101
1304.05	122.796
1307.24	122.086
1310.43	119.111
1313.63	116.491
1316.82	111.905
1320.01	107.116
1323.2	101.243
1326.38	94.0555
1329.57	85.4214
1332.76	76.4664
1335.94	67.6292
1339.12	58.0835
1342.3	45.3326
1345.48	31.2611
1348.66	37.4459
1351.84	48.8526
1355.01	48.204
1358.19	46.484
1361.36	42.0789
1364.53	39.7896
1367.71	37.3829
1370.88	35.0706
1374.04	34.7992
1377.21	30.8585
1380.38	28.4735
1383.54	27.3904
1386.71	25.3687
1389.87	24.493
1393.03	24.0775
1396.19	25.1167
1399.35	27.9481
1402.51	35.1868
1405.67	43.4086
1408.82	51.6137
1411.98	59.8367
1415.13	69.5782
1418.28	76.6368
1421.43	87.0918
1424.58	96.3777
1427.73	106.462
1430.88	116.519
1434.02	123.232
1437.17	129.391
1440.31	134.911
1443.45	137.867
1446.6	138.519
1449.74	136.071
1452.87	130.586
1456.01	122.895
1459.15	114.878
1462.28	105.805
1465.42	96.6624
1468.55	87.5251
1471.68	80.7183
1474.81	73.4085
1477.94	67.1739
1481.07	60.6332
1484.2	53.1895
1487.32	46.0959
1490.45	40.3991
1493.57	36.0147
1496.69	32.8764
1499.81	29.2881
1502.93	26.9251
1506.05	25.6881
1509.17	21.8701
1512.28	20.0105
1515.4	16.2346
1518.51	14.5123
1521.63	13.4915
1524.74	11.9793
1527.85	10.5723
1530.96	10.7005
1534.06	11.5123
1537.17	13.4589
1540.28	15.3191
1543.38	18.354
1546.48	20.7348
1549.59	23.2819
1552.69	24.3949
1555.79	27.9515
1558.88	29.2809
1561.98	32.0482
1565.08	36.1328
1568.17	40.6996
1571.27	44.248
1574.36	48.439
1577.45	53.191
1580.54	56.673
1583.63	60.0075
1586.72	60.8124
1589.8	63.3159
1592.89	63.3038
1595.97	64.3444
1599.06	63.6562
1602.14	61.5933
1605.22	60.8242
1608.3	58.7946
1611.38	56.2237
1614.46	55.7896
1617.53	55.2944
1620.61	55.4511
1623.68	56.6072
1626.75	59.2376
1629.82	60.4941
1632.9	63.561
1635.96	67.0293
1639.03	72.3361
1642.1	76.8884
1645.16	82.0015
1648.23	86.6449
1651.29	91.7941
1654.36	94.8139
1657.42	95.6541
1660.48	95.3253
1663.53	94.1672
1666.59	92.1725
1669.65	86.6005
1672.7	82.7373
1675.76	75.8461
1678.81	69.5142
1681.86	63.0745
1684.91	55.3315
1687.96	48.6677
1691.01	42.2341
1694.06	35.8038
1697.11	30.5628
1700.15	26.1172
1703.2	21.0299
1706.24	16.8291
1709.28	13.5265
1712.32	10.9417
1715.36	8.83376
1718.4	5.37021
1721.43	4.29445
1724.47	2.57273
1727.5	3.60152
1730.54	3.23152
1733.57	2.95111
1736.6	2.47255
1739.63	1.37657
1742.66	1.47711
1745.69	1.65222
1748.72	0.821243
1751.74	1.77978
1754.77	3.21475
1757.79	4.83912
1760.81	4.97622
1763.83	5.16401
1766.85	5.72787
1769.87	5.75062
1772.89	5.87351
1775.91	6.90922
1778.92	6.72799
1781.94	7.36265
1784.95	7.41922
1787.96	6.46558
1790.97	4.89179
1793.98	4.86444
1796.99	6.07093
1800	6.37606
1803	6.46744
1806.01	5.34419
1809.01	3.98256
1812.02	3.96583
1815.02	4.70657
1818.02	4.72785
1821.02	5.82861
1824.02	7.02897
1827.01	7.5453
1830.01	8.24284
1833	8.03084
1836	7.94611
1838.99	7.68607
1841.98	6.93921
1844.97	7.46314
1847.96	7.94729
1850.95	7.75841
1853.94	8.9793
1856.92	8.98613
1859.91	7.98916
1862.89	7.80496
1865.88	6.44663
1868.86	7.20942
1871.84	7.26478
1874.82	5.83793
1877.8	6.23257
1880.77	6.86362
1882.51	8.18599
1885.5	8.28285
1888.48	6.75708
1891.47	6.47131
1894.46	7.44247
1897.44	6.64729
1900.42	6.72074
1903.41	7.42575
1906.39	6.81929
1909.37	7.65428
1912.35	6.86729
1915.32	7.44875
1918.3	7.43394
1921.28	7.28479
1924.25	8.53979
1927.22	8.98734
1930.2	8.55652
1933.17	8.1518
1936.14	7.53041
1939.11	7.26401
1942.08	7.78917
1945.04	6.81382
1948.01	6.71726
1950.97	7.22931
1953.94	6.48047
1956.9	5.05478
1959.86	2.31545
1962.82	2.4394
1965.78	2.70613
1968.74	2.65311
1971.69	3.30457
1974.65	3.68203
1977.61	3.43517
1980.56	3.52711
1983.51	3.70471
1986.46	3.3034
1989.41	3.59917
1992.36	4.67684
1995.31	5.14348
1998.26	6.23288
2001.2	6.69266
2004.15	7.62484
2007.09	7.84166
2010.04	9.45447
2012.98	9.65621
2015.92	11.6127
2018.86	12.8838
2021.8	13.386
2024.74	13.7716
2027.67	15.3703
2030.61	15.3029
2033.54	16.4054
2036.47	16.9296
2039.41	16.3603
2042.34	18.509
2045.27	20.4397
2048.2	20.8529
2051.12	20.388
2054.05	20.4336
2056.98	21.3126
2059.9	22.3722
2062.82	24.7952
2065.75	25.4268
2068.67	27.3397
2071.59	28.7451
2074.51	30.1634
2077.43	30.7839
2080.34	33.5119
2083.26	34.5562
2086.17	37.8441
2089.09	39.3034
2092	41.7545
2094.91	45.0267
2097.82	47.6064
2100.73	50.8337
2103.64	53.1047
2106.55	55.5038
2109.46	59.2324
2112.36	62.3098
2115.27	65.8423
2118.17	69.8926
2121.07	75.0384
2123.97	80.4417
2126.87	85.902
2129.77	91.2299
2132.67	98.1635
2135.57	104.687
2138.46	111.099
2141.36	118.154
2144.25	125.191
2147.14	132.197
2150.03	138.085
2152.92	143.958
2155.81	149.524
2158.7	154.326
2161.59	157.4
2164.48	160.951
2167.36	161.496
2170.25	162.482
2173.13	161.767
2176.01	161.176
2178.89	158.671
2181.77	154.648
2184.65	149.475
2187.53	146.851
2190.41	142.317
2193.28	138.013
2196.16	131.231
2199.03	125.7
2201.9	119.88
2204.78	115.262
2207.65	109.788
2210.51	104.278
2213.38	100.142
2216.25	96.5561
2219.12	92.4679
2221.98	88.2807
2224.85	84.9751
2227.71	80.9805
2230.57	76.1488
2233.43	71.7011
2236.29	67.4646
2239.15	63.7213
2242.01	60.1387
2244.87	57.225
2247.73	54.0492
2250.58	50.2122
2253.43	46.6237
2256.29	45.1748
2259.14	44.2029
2261.99	40.1617
2264.84	39.0887
2267.69	35.7851
2270.54	33.7336
2273.38	31.4177
2276.23	30.2308
2279.07	28.7521
2281.92	28.0919
2284.76	28.1231
2287.6	27.0474
2290.44	25.536
2293.28	23.3666
2296.12	23.4953
2298.96	24.2336
2301.79	23.1564
2304.63	22.2374
2307.46	22.1046
2310.3	23.1254
2313.13	22.6106
2315.96	21.5425
2318.79	20.3143
2321.62	20.5848
2324.45	22.9464
2327.27	20.4666
2330.1	19.0747
2332.93	17.8891
2335.75	17.5591
2338.57	17.0315
2341.4	16.5131
2344.22	14.7328
2347.04	13.9497
2349.86	11.1645
2352.67	9.01696
2355.49	8.131
2358.31	5.6867
2361.12	4.76465
2363.94	6.85828
2366.75	7.59074
2369.56	6.22687
2372.37	4.69185
2375.18	5.14396
2377.99	4.39603
2380.8	3.47206
2383.61	3.05329
2386.41	2.04253
2389.22	1.70714
2392.02	2.21596
2394.82	1.8689
2397.63	2.42264
2400.43	2.51779
2403.23	3.70522
2406.02	3.61637
2408.82	4.45838
2411.62	4.31775
2414.41	4.65033
2417.21	4.8968
2420	6.94835
2422.79	9.12863
2425.59	10.609
2428.38	11.6634
2431.17	13.4367
2433.96	14.447
2436.74	13.9776
2439.53	12.7123
2442.32	12.0857
2445.1	12.0964
2447.88	11.3382
2450.67	10.0548
2453.45	9.96698
2456.23	9.80491
2459.01	9.02084
2461.79	9.19016
2464.57	6.69251
2467.34	7.92627
2470.12	6.9107
2472.89	6.14789
2475.67	6.32012
2478.44	6.89407
2481.21	7.83469
2483.98	7.81742
2486.75	7.66275
2489.52	7.89824
2492.29	7.04913
2495.06	6.66788
2497.82	5.44786
2500.59	5.1219
2503.35	3.11858
2506.11	2.30678
2508.88	0.703566
2511.63	1.28899
2514.39	1.67407
2517.15	1.11284
2519.91	0.791465
2522.67	2.49593
2525.42	2.66761
2528.18	3.59709
2530.93	3.41431
2533.69	4.29376
2536.44	5.74231
2539.19	6.38564
2541.94	8.91903
2544.69	9.50005
2547.44	10.1228
2550.18	10.1916
2552.93	9.76831
2555.68	9.77487
2558.42	10.8599
2561.16	10.0624
2563.9	10.1763
2566.64	10.7219
2569.38	10.0344
2572.12	9.85272
2574.86	11.2364
2577.6	12.1111
2580.34	12.5001
2583.07	11.4552
2585.81	11.9408
2588.54	12.8174
2591.27	13.0917
2594	13.3949
2596.73	12.4507
2599.46	11.8274
2602.19	11.6773
2604.92	11.5119
2607.64	10.6686
2610.37	9.71978
2613.09	8.27662
2615.82	6.65736
2618.54	5.30552
2621.26	4.68728
2623.98	3.56695
2626.7	2.7237
2629.42	4.09363
2632.14	5.06712
2634.86	5.85008
2637.57	7.06245
2640.29	9.82635
2643	10.3446
2645.72	10.9144
2648.43	12.595
2651.14	14.3975
2653.85	15.5038
2656.56	16.0789
2659.27	16.9491
2661.97	15.9872
2664.68	16.2702
2667.38	15.0144
2670.09	16.5256
2672.79	15.0749
2675.49	13.6586
2678.2	12.2367
2680.89	10.0018
2683.59	9.16089
2686.29	8.91277
2688.99	8.41683
2691.69	9.28002
2694.38	10.2512
2697.08	10.5238
2699.77	10.466
2702.46	11.6337
2705.16	12.5784
2707.85	14.2393
2710.54	14.6258
2713.23	16.5643
2715.92	15.6214
2718.6	16.9122
2721.29	17.4893
2723.97	17.5519
2726.66	17.2263
2729.34	15.0986
2732.02	15.0104
2734.7	15.6292
2737.39	14.3687
2740.06	11.5501
2742.74	10.2846
2745.42	8.68431
2748.1	7.87893
2750.77	7.11362
2753.45	7.26277
2756.12	7.37952
2758.79	6.16314
2761.47	4.02351
2764.14	2.65071
2766.81	1.39402
2769.48	1.928
2772.14	2.16378
2774.81	1.3604
2777.48	0.573592
2780.14	0.407133
2782.81	0.460432
2785.47	-0.541925
2788.13	-1.40357
2790.79	-2.07492
2793.46	-2.05914
2796.11	-1.46753
2798.77	-0.502197
2801.43	-1.52698
2804.09	-1.02145
2806.74	-1.38174
2809.4	-0.113807
2812.05	0.433947
2814.71	2.3893
2817.36	5.75416
2820.01	9.77114
2822.66	14.8153
2825.31	19.1656
2827.96	26.6352
2830.61	35.1302
2833.25	43.3821
2835.9	52.3438
2838.54	60.0297
2841.18	69.0074
2843.83	79.0984
2846.47	88.7332
2849.11	98.1168
2851.75	108.307
2854.39	117.566
2857.03	126.523
2859.67	136.023
2862.3	143.673
2864.94	149.69
2867.57	155.274
2870.21	161.205
2872.84	165.947
2875.47	171.04
2878.1	176.36
2880.73	182.171
2883.36	187.162
2885.99	191.539
2888.61	198.365
2891.24	205.422
2893.87	214.069
2896.49	223.833
2899.11	234.84
2901.74	248.411
2904.36	265.09
2906.98	284.338
2909.6	305.229
2912.22	328.872
2914.83	353.35
2917.45	379.661
2920.07	402.897
2922.68	425.946
2925.3	445.274
2927.91	460.011
2930.52	471.359
2933.13	479.662
2935.74	484.16
2938.35	483.988
2940.96	479.672
2943.57	469.401
2946.18	455.956
2948.78	440.079
2951.39	420.362
2953.99	400.377
2956.6	378.587
2959.2	359.704
2961.8	340.169
2964.4	320.759
2967	303.809
2969.6	286.251
2972.2	270.086
2974.79	257.489
2977.39	245.049
2979.98	232.748
2982.58	220.704
2985.17	207.689
2987.76	193.982
2990.36	179.787
2992.95	167.257
2995.54	152.764
2998.12	138.509
3000.71	123.899
3003.3	109.549
3005.88	96.2212
3008.47	82.1937
3011.05	71.0765
3013.64	59.2055
3016.22	49.4365
3018.8	41.5345
3021.38	33.7788
3023.96	28.5384
3026.54	22.3371
3029.12	17.6979
3031.69	13.3706
3034.27	10.7327
3036.85	8.82561
3039.42	9.06942
3041.99	8.86815
3044.57	9.50452
3047.14	10.1401
3049.71	12.1607
3052.28	12.217
3054.85	13.0316
3057.42	11.9464
3059.98	11.5506
3062.55	11.2486
3065.11	10.9166
3067.68	10.1444
3070.24	9.29088
3072.8	7.86925
3075.37	7.02278
3077.93	6.29608
3080.49	5.46354
3083.05	3.43456
3085.61	0.989687
3088.16	0.965083
3090.72	1.06638
3093.27	1.41902
3095.83	0.641808
3098.38	0.785657
3100.94	1.57368
3103.49	2.06059
3106.04	3.29566
3108.59	5.6004
3111.14	7.86236
3113.69	9.63906
3116.23	10.6869
3118.78	12.5833
3121.33	14.9757
3123.87	17.8748
3126.42	19.5616
3128.96	20.5351
3131.5	22.3263
3134.04	24.0185
3136.58	25.8775
3139.12	28.5512
3141.66	29.161
3144.2	29.7371
3146.74	30.8029
3149.27	29.0617