File: data/Raman/poly_smoothed/Mb_50_18_42_1x_45s_532 nm_x100_100%_600 gr_mm_01.txt
#Acq. time (s)=	45
#Accumulations=	2
#Range (cm-¹)=	200...3150
#Windows=	2
#Auto scanning=	Off
#Autofocus=	Off
#Macrospot=	Off
#AutoExposure=	Off
#Spike filter=	Multiple accum.
#Delay time (s)=	0
#Binning=	1
#Readout mode=	Signal
#DeNoise=	Off
#ICS correction=	On
#Dark correction=	Off
#Inst. Process=	Off
#Detector Gain=	Best Dynamic Range
#Detector ADC=	20 kHz
#Detector temperature (°C)=	-69.85
#Instrument=	LabRAM HR Evol
#Detector=	Synapse
#Objective=	x100
#Grating=	600 gr/mm
#ND Filter=	100%
#Laser (nm)=	532
#Hole=	100.021
#Range=	Auto
#Laser Pol.=	No
#Raman. Pol.=	No
#Laser Pol. (°)=	-0.0007625
#Raman Pol. (°)=	89.9995
#Collection=	Microscope
#StageXY=	Marzhauser
#StageZ=	Marzhauser
#X (µm)=	28228.3
#Y (µm)=	-3255.6
#Z (µm)=	1040.65
#Full time(mm:ss)=	3:18
#Project=
#Sample=
#Site=
#Title=	Mb_50_18_42_2x_45s_532 nm_x100_100%_600 gr_mm
#Remark=
#Date=	12.07.2022 14:14
#Acquired=	12.07.2022 14:14:36
#Base:Fit=	10.08.2022 10:49:18
#Base:Sub=	10.08.2022 10:49:30
#Filter:Polynom=	16.08.2022 10:14:59
#AxisType[0]=Intens
#AxisUnit[0]=Cnt
#AxisType[1]=Spectr
#AxisUnit[1]=1/cm
200.388	21.5552
204.019	19.4632
207.646	17.236
211.274	14.5638
214.899	12.5915
218.524	12.8455
222.146	11.5431
225.766	9.74562
229.388	7.45748
233.005	9.57774
236.621	13.5345
240.236	14.0086
243.852	15.6713
247.464	17.7469
251.074	18.772
254.683	18.8209
258.291	19.6692
261.897	20.4247
265.504	18.5516
269.108	18.043
272.71	18.0119
276.311	18.4742
279.91	16.8886
283.508	15.9618
287.105	14.1439
290.698	13.1024
294.291	12.6097
297.884	13.0728
301.475	12.3519
305.064	12.7762
308.652	12.2302
312.237	11.6026
315.822	11.692
319.406	16.302
322.987	17.1154
326.568	17.8166
330.148	16.8107
333.724	15.1537
337.301	14.0745
340.875	11.861
344.449	10.5137
348.02	11.3764
351.592	12.072
355.16	13.2207
358.728	17.3409
362.294	20.4679
365.858	22.5521
369.422	26.2679
372.983	30.0578
376.543	32.9528
380.102	36.2509
383.661	37.34
387.216	38.0727
390.771	37.9278
394.324	38.4439
397.875	37.2803
401.425	35.3791
404.974	32.238
408.524	28.9874
412.07	24.6582
415.614	18.1166
419.156	13.031
422.698	9.74096
426.238	4.76425
429.777	1.60572
433.315	0.933915
436.852	0.458477
440.387	0.00366716
443.919	-0.385241
447.451	-0.419981
450.982	-0.16111
454.512	1.41056
458.038	2.62208
461.565	3.57598
465.091	6.00027
468.613	6.74324
472.136	8.8121
475.655	11.2027
479.176	14.078
482.692	17.7566
486.21	22.8258
489.724	27.1062
493.237	30.1437
496.75	34.4392
500.26	38.3546
503.771	41.9
507.279	44.6672
510.785	46.1009
514.289	45.914
517.793	47.1736
521.297	45.2619
524.797	42.0412
528.297	39.9892
531.795	36.3425
535.291	32.6047
538.787	28.9384
542.281	23.6532
545.773	18.516
549.264	15.3979
552.754	11.6822
556.243	8.20821
559.73	5.35902
563.216	2.81821
566.701	1.76683
570.182	3.14258
573.664	2.62819
577.145	2.96334
580.624	3.74137
584.1	5.98225
587.577	7.29234
591.052	6.95433
594.524	6.82763
597.997	6.84714
601.466	7.66042
604.936	8.24565
608.403	7.27771
611.87	6.19329
615.334	5.51092
618.799	5.63147
622.26	4.98069
625.72	5.80075
629.181	3.93733
632.638	4.37669
636.095	3.35983
639.551	3.87928
643.005	2.99208
646.457	1.6638
649.908	1.10617
653.357	2.22548
656.806	3.70655
660.253	4.59985
663.7	5.14911
667.145	6.05155
670.588	7.1677
674.027	8.247
677.468	9.81553
680.907	11.3596
684.345	13.598
687.781	16.3047
691.216	18.3612
694.65	18.4156
698.081	19.6369
701.512	21.5159
704.942	21.8936
708.371	24.2904
711.796	26.2014
715.222	27.1956
718.645	27.0223
722.068	26.8974
725.49	27.9132
728.909	28.6376
732.329	31.8468
735.745	36.6345
739.16	42.3943
742.576	49.1454
745.988	55.8112
749.401	64.2341
752.811	71.4947
756.22	78.8478
759.627	84.7402
763.035	91.8026
766.44	97.1836
769.843	101.061
773.245	104.024
776.646	105.436
780.046	104.416
783.444	103.275
786.841	101.366
790.237	97.8592
793.631	94.0657
797.024	88.6272
800.416	80.9622
803.807	75.4579
807.196	70.8353
810.584	67.7452
813.971	65.5222
817.354	63.0444
820.739	62.1133
824.122	62.0323
827.503	62.9306
830.882	64.2742
834.261	62.551
837.637	59.9224
841.013	59.9446
844.389	58.085
847.761	56.3915
851.131	56.0816
854.503	54.6985
857.871	52.4805
861.24	51.5712
864.606	50.5046
867.97	48.0969
871.336	46.1744
874.698	43.1576
878.058	43.1673
881.418	41.9344
884.778	40.0722
888.135	39.8351
891.49	39.5908
894.845	39.9958
898.198	37.3642
901.55	37.8042
904.901	37.7887
908.25	37.8229
911.598	36.8074
914.945	35.9449
918.291	33.858
921.635	33.5746
924.978	33.327
928.318	29.8222
931.659	29.5453
934.998	28.0042
938.336	24.8219
941.671	23.0492
945.007	22.0606
948.339	18.8033
951.672	17.6676
955.004	15.7734
958.333	13.8424
961.662	12.9893
964.989	13.1126
968.315	13.0496
971.639	13.2352
974.962	13.0289
978.285	10.9645
981.605	9.92026
984.924	10.8976
988.243	11.5382
991.56	12.2408
994.875	16.6468
998.188	20.3121
1001.5	24.9707
1004.81	29.7663
1008.12	33.705
1011.43	39.0377
1014.74	44.3044
1018.05	49.1167
1021.35	53.203
1024.65	57.8743
1027.96	60.4923
1031.26	60.4067
1034.56	61.1684
1037.86	60.9006
1041.16	59.4559
1044.45	56.9035
1047.75	53.6899
1051.04	50.4655
1054.33	45.9576
1057.62	44.4366
1060.91	41.9465
1064.2	40.4306
1067.49	39.5012
1070.77	40.8508
1074.06	42.2776
1077.34	44.7454
1080.62	46.2069
1083.91	46.7347
1087.18	46.628
1090.46	47.7809
1093.74	49.0739
1097.02	49.4044
1100.29	48.1783
1103.56	48.0672
1106.84	47.2736
1110.11	43.7436
1113.38	39.1595
1116.64	34.3078
1119.91	29.1377
1123.18	23.872
1126.44	20.1214
1129.7	16.1176
1132.97	15.2446
1136.23	14.9143
1139.49	14.2806
1142.74	11.8773
1146	11.2416
1149.26	11.4168
1152.51	10.7202
1155.76	9.54973
1159.01	8.18093
1162.27	6.71938
1165.51	6.65917
1168.76	7.82332
1172.01	9.13674
1175.25	10.0722
1178.5	11.5683
1181.74	13.8719
1184.98	14.6389
1188.22	14.165
1191.46	15.7823
1194.7	16.0031
1197.94	15.4492
1201.17	15.1288
1204.41	15.5223
1207.64	17.7618
1210.87	17.9723
1214.1	20.2427
1217.33	22.7951
1220.56	23.5379
1223.79	27.8878
1227.01	30.9475
1230.23	33.124
1233.46	34.2941
1236.68	35.6975
1239.9	37.5621
1243.12	39.0753
1246.34	40.3957
1249.55	41.5563
1252.77	43.0099
1255.98	44.0634
1259.2	48.0097
1262.41	51.4607
1265.62	54.5041
1268.83	57.729
1272.03	61.2048
1275.24	63.965
1278.45	65.995
1281.65	70.9459
1284.85	73.0469
1288.06	75.3612
1291.26	76.6657
1294.46	78.1359
1297.66	78.0296
1300.85	78.5354
1304.05	80.6193
1307.24	78.7724
1310.43	77.0012
1313.63	76.251
1316.82	73.3964
1320.01	71.2103
1323.2	68.0897
1326.38	66.2056
1329.57	63.3742
1332.76	62.0984
1335.94	60.4099
1339.12	59.5747
1342.3	58.9202
1345.48	56.8759
1348.66	55.0742
1351.84	53.9002
1355.01	52.1791
1358.19	50.5871
1361.36	48.4912
1364.53	45.6513
1367.71	42.1565
1370.88	41.0325
1374.04	38.3703
1377.21	38.752
1380.38	38.5482
1383.54	36.6051
1386.71	35.7045
1389.87	33.5914
1393.03	32.6916
1396.19	30.5628
1399.35	30.4516
1402.51	30.1659
1405.67	33.1999
1408.82	35.8748
1411.98	40.2997
1415.13	44.6261
1418.28	51.248
1421.43	57.4635
1424.58	63.8187
1427.73	71.8707
1430.88	77.7236
1434.02	82.715
1437.17	86.2111
1440.31	89.3378
1443.45	91.9547
1446.6	94.6022
1449.74	95.5556
1452.87	95.9466
1456.01	95.0902
1459.15	93.1598
1462.28	90.2616
1465.42	86.7984
1468.55	82.2908
1471.68	78.523
1474.81	75.2393
1477.94	71.3393
1481.07	68.5254
1484.2	65.0768
1487.32	61.8331
1490.45	59.6932
1493.57	57.1157
1496.69	55.3033
1499.81	51.7958
1502.93	49.2107
1506.05	44.9218
1509.17	39.9386
1512.28	35.1587
1515.4	30.469
1518.51	28.2546
1521.63	24.3429
1524.74	21.7013
1527.85	21.0605
1530.96	19.3907
1534.06	19.9006
1537.17	21.2299
1540.28	21.9963
1543.38	22.8854
1546.48	23.3604
1549.59	24.3598
1552.69	24.4827
1555.79	27.0552
1558.88	27.3606
1561.98	29.4617
1565.08	34.003
1568.17	38.0431
1571.27	42.2245
1574.36	46.0579
1577.45	51.3107
1580.54	55.4976
1583.63	58.1094
1586.72	62.8854
1589.8	64.6851
1592.89	66.8345
1595.97	67.3398
1599.06	68.4753
1602.14	68.4348
1605.22	68.8347
1608.3	68.897
1611.38	69.8582
1614.46	68.3167
1617.53	68.4784
1620.61	68.9646
1623.68	69.3871
1626.75	69.5951
1629.82	70.0476
1632.9	71.3801
1635.96	73.8037
1639.03	77.0133
1642.1	80.3771
1645.16	81.7741
1648.23	83.5008
1651.29	85.1294
1654.36	85.7491
1657.42	84.0638
1660.48	83.2434
1663.53	81.0377
1666.59	77.4184
1669.65	73.6467
1672.7	68.3196
1675.76	62.8826
1678.81	58.2326
1681.86	52.8194
1684.91	47.8883
1687.96	43.8765
1691.01	39.2432
1694.06	35.1754
1697.11	30.5015
1700.15	27.0568
1703.2	22.8559
1706.24	19.8038
1709.28	17.4302
1712.32	16.1235
1715.36	13.0623
1718.4	12.1832
1721.43	10.3611
1724.47	8.96486
1727.5	8.37817
1730.54	7.98513
1733.57	7.25696
1736.6	6.96227
1739.63	7.19364
1742.66	6.73627
1745.69	4.92187
1748.72	3.52046
1751.74	3.73103
1754.77	3.16802
1757.79	2.61854
1760.81	3.02012
1763.83	2.97951
1766.85	1.46095
1769.87	1.42936
1772.89	0.779504
1775.91	0.915854
1778.92	-0.476691
1781.94	0.490996
1784.95	1.21359
1787.96	2.06625
1790.97	2.07189
1793.98	2.16607
1796.99	2.37883
1800	3.35143
1803	3.66224
1806.01	4.46375
1809.01	6.16084
1812.02	6.70168
1815.02	7.56432
1818.02	7.35117
1821.02	7.9796
1824.02	8.35215
1827.01	8.95833
1830.01	9.93389
1833	10.9155
1836	11.5728
1838.99	11.032
1841.98	10.7745
1844.97	10.0611
1847.96	9.90669
1850.95	8.79393
1853.94	8.03238
1856.92	7.86697
1859.91	8.12307
1862.89	8.25567
1865.88	7.51486
1868.86	6.99799
1871.84	7.36321
1874.82	6.74485
1877.8	7.61268
1880.77	6.53255
1882.51	6.7693
1885.5	6.36729
1888.48	5.7305
1891.47	5.07975
1894.46	4.85229
1897.44	4.06575
1900.42	4.49346
1903.41	4.47835
1906.39	5.35947
1909.37	4.80149
1912.35	4.84488
1915.32	4.61466
1918.3	5.43449
1921.28	6.20176
1924.25	6.44674
1927.22	6.47207
1930.2	7.06758
1933.17	7.73345
1936.14	7.16078
1939.11	6.98362
1942.08	7.11077
1945.04	8.35129
1948.01	8.39116
1950.97	9.79533
1953.94	9.29557
1956.9	9.35035
1959.86	9.2046
1962.82	9.44257
1965.78	9.11152
1968.74	9.50575
1971.69	8.44679
1974.65	10.085
1977.61	10.1086
1980.56	9.39186
1983.51	9.34034
1986.46	9.22373
1989.41	10.0972
1992.36	11.6314
1995.31	11.5874
1998.26	11.0397
2001.2	12.1019
2004.15	13.2852
2007.09	12.4823
2010.04	14.57
2012.98	16.3668
2015.92	17.5189
2018.86	18.3205
2021.8	18.7492
2024.74	18.6362
2027.67	18.2207
2030.61	18.2522
2033.54	19.3539
2036.47	18.7344
2039.41	18.5185
2042.34	18.0837
2045.27	18.9111
2048.2	18.9959
2051.12	17.8333
2054.05	19.528
2056.98	20.5399
2059.9	23.1495
2062.82	25.5881
2065.75	27.3424
2068.67	28.0277
2071.59	30.4951
2074.51	32.6332
2077.43	35.1751
2080.34	38.0205
2083.26	39.9333
2086.17	41.9221
2089.09	44.7318
2092	46.6638
2094.91	49.2474
2097.82	52.2614
2100.73	54.805
2103.64	57.8623
2106.55	62.1779
2109.46	64.1642
2112.36	68.4142
2115.27	72.2816
2118.17	77.1966
2121.07	82.4764
2123.97	89.0645
2126.87	94.6833
2129.77	100.263
2132.67	106.071
2135.57	111.158
2138.46	115.495
2141.36	121.223
2144.25	126.493
2147.14	131.58
2150.03	135.205
2152.92	139.346
2155.81	141.636
2158.7	144.241
2161.59	146.34
2164.48	147.118
2167.36	148.586
2170.25	147.972
2173.13	147.041
2176.01	144.435
2178.89	142.262
2181.77	138.732
2184.65	136.502
2187.53	132.34
2190.41	128.304
2193.28	124.647
2196.16	120.101
2199.03	115.091
2201.9	111.482
2204.78	107.133
2207.65	102.197
2210.51	97.1219
2213.38	91.7814
2216.25	86.2729
2219.12	82.4267
2221.98	77.495
2224.85	73.853
2227.71	70.7083
2230.57	66.4971
2233.43	62.0216
2236.29	58.4882
2239.15	54.791
2242.01	51.6401
2244.87	48.171
2247.73	46.2393
2250.58	43.3536
2253.43	39.5563
2256.29	37.2007
2259.14	36.1528
2261.99	34.3995
2264.84	32.5221
2267.69	32.681
2270.54	31.7877
2273.38	29.3056
2276.23	27.603
2279.07	25.1752
2281.92	23.3009
2284.76	22.0728
2287.6	21.7818
2290.44	20.8506
2293.28	19.6772
2296.12	19.0137
2298.96	18.8078
2301.79	18.017
2304.63	17.2015
2307.46	16.9467
2310.3	17.3234
2313.13	17.3148
2315.96	17.4046
2318.79	16.7686
2321.62	16.3924
2324.45	16.79
2327.27	17.3496
2330.1	16.6744
2332.93	16.0646
2335.75	15.9804
2338.57	14.8134
2341.4	12.5059
2344.22	10.8008
2347.04	9.16285
2349.86	7.90994
2352.67	6.25488
2355.49	4.94424
2358.31	4.19248
2361.12	2.88134
2363.94	2.33048
2366.75	2.90874
2369.56	3.44996
2372.37	1.95032
2375.18	2.06055
2377.99	2.40459
2380.8	3.7329
2383.61	4.49693
2386.41	4.71003
2389.22	5.75439
2392.02	6.64365
2394.82	7.78359
2397.63	8.46655
2400.43	9.51888
2403.23	10.2324
2406.02	10.3871
2408.82	9.95533
2411.62	9.13011
2414.41	9.60457
2417.21	8.3863
2420	7.91378
2422.79	8.62248
2425.59	9.15393
2428.38	9.39273
2431.17	9.41605
2433.96	11.0678
2436.74	10.6885
2439.53	9.49562
2442.32	9.88122
2445.1	10.4408
2447.88	9.73649
2450.67	9.75085
2453.45	8.79454
2456.23	8.55422
2459.01	8.05645
2461.79	7.77455
2464.57	7.18866
2467.34	6.20798
2470.12	6.1573
2472.89	4.9023
2475.67	3.02784
2478.44	1.68224
2481.21	0.795444
2483.98	0.600121
2486.75	0.123236
2489.52	0.546026
2492.29	0.284205
2495.06	0.321653
2497.82	0.223341
2500.59	0.359479
2503.35	-0.262369
2506.11	-0.278975
2508.88	1.34275
2511.63	1.9077
2514.39	2.32761
2517.15	2.98301
2519.91	3.62533
2522.67	2.76655
2525.42	1.72275
2528.18	2.44329
2530.93	3.22019
2533.69	4.10255
2536.44	3.05424
2539.19	4.17774
2541.94	4.0164
2544.69	4.08698
2547.44	4.00247
2550.18	3.52893
2552.93	4.3418
2555.68	4.88332
2558.42	5.49147
2561.16	5.59165
2563.9	5.37998
2566.64	5.2166
2569.38	5.11916
2572.12	5.36222
2574.86	5.91425
2577.6	5.62237
2580.34	5.39517
2583.07	5.46486
2585.81	4.57211
2588.54	3.42725
2591.27	2.54014
2594	2.82574
2596.73	3.90939
2599.46	2.35661
2602.19	1.37989
2604.92	1.52485
2607.64	1.51554
2610.37	1.0602
2613.09	1.08523
2615.82	1.34294
2618.54	2.38861
2621.26	2.82818
2623.98	3.48715
2626.7	3.05825
2629.42	3.24307
2632.14	4.09873
2634.86	5.07161
2637.57	5.82253
2640.29	6.36158
2643	6.82748
2645.72	6.94629
2648.43	7.242
2651.14	6.59658
2653.85	6.73901
2656.56	7.26985
2659.27	7.9102
2661.97	6.45817
2664.68	6.09313
2667.38	5.98529
2670.09	6.35172
2672.79	5.72383
2675.49	6.2251
2678.2	6.10051
2680.89	5.89185
2683.59	5.38568
2686.29	5.07097
2688.99	5.0856
2691.69	4.91972
2694.38	4.41135
2697.08	4.53667
2699.77	4.4966
2702.46	3.44434
2705.16	3.12773
2707.85	2.23883
2710.54	1.39234
2713.23	0.846958
2715.92	1.87185
2718.6	1.60982
2721.29	2.07091
2723.97	1.85055
2726.66	1.79722
2729.34	2.20925
2732.02	3.14257
2734.7	2.66448
2737.39	2.65393
2740.06	2.28285
2742.74	2.66182
2745.42	3.33225
2748.1	3.44853
2750.77	3.56067
2753.45	2.71469
2756.12	2.25727
2758.79	2.07332
2761.47	1.90305
2764.14	2.06772
2766.81	2.19587
2769.48	2.53255
2772.14	2.33801
2774.81	1.23107
2777.48	2.92133
2780.14	2.48848
2782.81	2.67866
2785.47	1.8805
2788.13	1.32855
2790.79	2.19102
2793.46	1.73806
2796.11	1.28717
2798.77	0.671934
2801.43	-0.000893867
2804.09	-0.92936
2806.74	-1.51664
2809.4	-2.16592
2812.05	-2.84144
2814.71	-2.52552
2817.36	-1.17752
2820.01	2.07483
2822.66	7.49807
2825.31	13.6283
2827.96	21.4773
2830.61	30.1721
2833.25	39.7591
2835.9	49.6293
2838.54	59.861
2841.18	71.1078
2843.83	82.4452
2846.47	93.0121
2849.11	105.344
2851.75	116.281
2854.39	127.217
2857.03	138.135
2859.67	147.054
2862.3	155.827
2864.94	162.968
2867.57	169.106
2870.21	175.413
2872.84	178.864
2875.47	182.88
2878.1	186.467
2880.73	190.458
2883.36	194.843
2885.99	200.23
2888.61	205.339
2891.24	211.19
2893.87	216.657
2896.49	223.531
2899.11	231.804
2901.74	242.275
2904.36	251.391
2906.98	263.294
2909.6	275.535
2912.22	288.142
2914.83	301.407
2917.45	312.156
2920.07	322.119
2922.68	330.265
2925.3	337.347
2927.91	341.093
2930.52	343.022
2933.13	341.809
2935.74	337.299
2938.35	329.889
2940.96	320.997
2943.57	310.875
2946.18	300.734
2948.78	288.22
2951.39	274.074
2953.99	259.182
2956.6	244.72
2959.2	230.467
2961.8	217.154
2964.4	204.026
2967	191.645
2969.6	179.582
2972.2	167.61
2974.79	157.035
2977.39	144.727
2979.98	133.087
2982.58	121.711
2985.17	109.476
2987.76	99.7591
2990.36	88.2297
2992.95	77.6016
2995.54	67.9127
2998.12	59.209
3000.71	51.1233
3003.3	43.3745
3005.88	37.2012
3008.47	31.3038
3011.05	25.863
3013.64	21.2713
3016.22	17.7691
3018.8	15.1366
3021.38	12.2227
3023.96	10.035
3026.54	8.26647
3029.12	6.95333
3031.69	5.47977
3034.27	5.49824
3036.85	4.84062
3039.42	4.5779
3041.99	5.18144
3044.57	5.68941
3047.14	6.11476
3049.71	6.88647
3052.28	7.69146
3054.85	7.58338
3057.42	7.60367
3059.98	7.96521
3062.55	8.07682
3065.11	6.93385
3067.68	5.62536
3070.24	5.62932
3072.8	4.25819
3075.37	3.65944
3077.93	3.72702
3080.49	3.03593
3083.05	1.70221
3085.61	0.314491
3088.16	-0.865836
3090.72	-1.71033
3093.27	-1.70907
3095.83	-0.6248
3098.38	-0.551867
3100.94	-0.04789
3103.49	0.794469
3106.04	1.02219
3108.59	1.49901
3111.14	2.64047
3113.69	3.08282
3116.23	3.72922
3118.78	4.80822
3121.33	5.7899
3123.87	7.49781
3126.42	8.81821
3128.96	9.92416
3131.5	12.218
3134.04	14.211
3136.58	16.1503
3139.12	17.9671
3141.66	20.2357
3144.2	22.0631
3146.74	24.6951
3149.27	27.909