File: data/Raman/poly_smoothed/Mb_50_18_41_1x_45s_532 nm_x100_100%_600 gr_mm_01.txt
#Acq. time (s)=	45
#Accumulations=	2
#Range (cm-¹)=	200...3150
#Windows=	2
#Auto scanning=	Off
#Autofocus=	Off
#Macrospot=	Off
#AutoExposure=	Off
#Spike filter=	Multiple accum.
#Delay time (s)=	0
#Binning=	1
#Readout mode=	Signal
#DeNoise=	Off
#ICS correction=	On
#Dark correction=	Off
#Inst. Process=	Off
#Detector Gain=	Best Dynamic Range
#Detector ADC=	20 kHz
#Detector temperature (°C)=	-69.85
#Instrument=	LabRAM HR Evol
#Detector=	Synapse
#Objective=	x100
#Grating=	600 gr/mm
#ND Filter=	100%
#Laser (nm)=	532
#Hole=	100.021
#Range=	Auto
#Laser Pol.=	No
#Raman. Pol.=	No
#Laser Pol. (°)=	-0.0007625
#Raman Pol. (°)=	89.9995
#Collection=	Microscope
#StageXY=	Marzhauser
#StageZ=	Marzhauser
#X (µm)=	28233.8
#Y (µm)=	-3245.5
#Z (µm)=	1040.6
#Full time(mm:ss)=	3:19
#Project=
#Sample=
#Site=
#Title=	Mb_50_18_41_2x_45s_532 nm_x100_100%_600 gr_mm
#Remark=
#Date=	12.07.2022 14:10
#Acquired=	12.07.2022 14:10:39
#Base:Fit=	10.08.2022 10:49:18
#Base:Sub=	10.08.2022 10:49:30
#Filter:Polynom=	16.08.2022 10:14:59
#AxisType[0]=Intens
#AxisUnit[0]=Cnt
#AxisType[1]=Spectr
#AxisUnit[1]=1/cm
200.388	0.761814
204.019	7.75688
207.646	9.16431
211.274	9.3761
214.899	8.12869
218.524	7.66375
222.146	7.78401
225.766	8.47864
229.388	8.84758
233.005	10.3314
236.621	10.1034
240.236	10.7056
243.852	9.78428
247.464	10.5596
251.074	9.77509
254.683	9.26347
258.291	9.92455
261.897	9.15013
265.504	8.66513
269.108	9.62953
272.71	9.87818
276.311	9.56498
279.91	8.63172
283.508	9.23695
287.105	9.55645
290.698	9.61843
294.291	9.30923
297.884	10.9471
301.475	12.4764
305.064	13.9928
308.652	15.9943
312.237	16.8832
315.822	19.0664
319.406	21.975
322.987	21.9993
326.568	21.6379
330.148	20.3336
333.724	18.5011
337.301	18.2502
340.875	17.9042
344.449	17.6483
348.02	19.42
351.592	20.9072
355.16	22.72
358.728	24.2832
362.294	26.1769
365.858	29.2847
369.422	32.8567
372.983	34.7366
376.543	38.36
380.102	42.1792
383.661	44.7291
387.216	47.4893
390.771	48.0846
394.324	48.2127
397.875	48.2043
401.425	45.7453
404.974	43.9349
408.524	38.6577
412.07	33.0937
415.614	26.725
419.156	21.1532
422.698	16.627
426.238	13.5675
429.777	9.52336
433.315	7.52544
436.852	5.79994
440.387	3.31099
443.919	2.78211
447.451	4.0331
450.982	4.98834
454.512	5.34076
458.038	6.54175
461.565	8.35174
465.091	9.91726
468.613	12.1373
472.136	14.0843
475.655	16.8721
479.176	19.2766
482.692	24.1458
486.21	28.0917
489.724	31.4274
493.237	35.125
496.75	37.6356
500.26	40.4208
503.771	41.9116
507.279	41.9748
510.785	43.1256
514.289	43.23
517.793	42.7918
521.297	42.6507
524.797	41.0287
528.297	39.7749
531.795	39.2123
535.291	37.2162
538.787	33.9498
542.281	29.5889
545.773	24.6554
549.264	20.0138
552.754	17.0839
556.243	15.4411
559.73	14.0146
563.216	12.5385
566.701	12.7479
570.182	14.1365
573.664	14.461
577.145	13.3712
580.624	13.7615
584.1	11.793
587.577	10.707
591.052	9.59808
594.524	7.9184
597.997	8.66119
601.466	8.39989
604.936	6.8117
608.403	5.72614
611.87	5.49541
615.334	4.76243
618.799	4.57891
622.26	2.97677
625.72	1.71491
629.181	2.15146
632.638	3.59244
636.095	3.30083
639.551	4.21707
643.005	4.91322
646.457	6.45105
649.908	7.18407
653.357	9.3394
656.806	9.52384
660.253	10.6488
663.7	9.92765
667.145	10.3253
670.588	10.8837
674.027	10.6843
677.468	12.8449
680.907	13.009
684.345	13.4263
687.781	14.455
691.216	15.9258
694.65	17.4531
698.081	18.366
701.512	19.1475
704.942	20.2993
708.371	20.6692
711.796	23.8964
715.222	24.4399
718.645	26.1099
722.068	26.3588
725.49	27.2742
728.909	28.8735
732.329	29.6679
735.745	31.888
739.16	36.5442
742.576	42.2335
745.988	48.4962
749.401	53.666
752.811	59.3345
756.22	65.2705
759.627	70.8458
763.035	77.1747
766.44	81.0019
769.843	85.6133
773.245	89.1828
776.646	89.8807
780.046	89.3451
783.444	87.9495
786.841	86.8346
790.237	85.7677
793.631	84.1982
797.024	80.4644
800.416	78.0595
803.807	74.4684
807.196	71.9779
810.584	68.6909
813.971	66.3101
817.354	64.2283
820.739	63.5141
824.122	61.7051
827.503	61.3486
830.882	59.1409
834.261	56.1136
837.637	53.3817
841.013	50.6403
844.389	47.6093
847.761	45.654
851.131	41.4476
854.503	38.4598
857.871	36.0115
861.24	33.4683
864.606	31.6289
867.97	30.188
871.336	29.0456
874.698	29.3061
878.058	28.4646
881.418	27.6216
884.778	28.5069
888.135	30.1016
891.49	29.2713
894.845	30.7025
898.198	28.8467
901.55	29.6078
904.901	30.0477
908.25	29.5588
911.598	28.9959
914.945	28.2373
918.291	26.0337
921.635	24.9781
924.978	23.8498
928.318	21.3703
931.659	20.8929
934.998	17.6031
938.336	16.8571
941.671	13.7705
945.007	11.7076
948.339	9.1547
951.672	7.25518
955.004	6.05919
958.333	4.46722
961.662	3.86937
964.989	3.45492
968.315	4.2718
971.639	4.6041
974.962	4.7644
978.285	3.90643
981.605	4.13804
984.924	3.1353
988.243	1.99683
991.56	3.6898
994.875	4.66927
998.188	6.39982
1001.5	9.9986
1004.81	13.8624
1008.12	16.8287
1011.43	19.8585
1014.74	21.79
1018.05	24.2218
1021.35	27.2451
1024.65	29.4456
1027.96	31.915
1031.26	32.4097
1034.56	32.1096
1037.86	32.3125
1041.16	30.8489
1044.45	29.3935
1047.75	28.3247
1051.04	26.675
1054.33	23.9756
1057.62	21.2335
1060.91	20.1471
1064.2	17.9112
1067.49	17.9341
1070.77	16.341
1074.06	16.727
1077.34	17.9579
1080.62	18.1598
1083.91	19.3555
1087.18	19.6114
1090.46	20.1753
1093.74	21.3126
1097.02	21.221
1100.29	21.6677
1103.56	20.7119
1106.84	19.5549
1110.11	18.7658
1113.38	16.752
1116.64	14.2238
1119.91	12.4141
1123.18	11.9673
1126.44	11.192
1129.7	10.5844
1132.97	9.77884
1136.23	8.61216
1139.49	9.17637
1142.74	8.46189
1146	7.28798
1149.26	4.8308
1152.51	3.54347
1155.76	3.72543
1159.01	1.26993
1162.27	0.360199
1165.51	1.2648
1168.76	1.70429
1172.01	2.65804
1175.25	1.19885
1178.5	-0.550367
1181.74	0.136591
1184.98	1.08672
1188.22	1.72141
1191.46	2.44395
1194.7	3.00205
1197.94	5.13119
1201.17	5.63591
1204.41	6.65893
1207.64	7.24089
1210.87	8.12608
1214.1	9.48685
1217.33	9.93776
1220.56	12.261
1223.79	14.0953
1227.01	15.8277
1230.23	16.1358
1233.46	17.2291
1236.68	18.5208
1239.9	20.1596
1243.12	21.9595
1246.34	23.0113
1249.55	22.9482
1252.77	22.6501
1255.98	21.0008
1259.2	21.2061
1262.41	21.2315
1265.62	23.6207
1268.83	25.3179
1272.03	28.1785
1275.24	28.9548
1278.45	29.4444
1281.65	31.0501
1284.85	32.4945
1288.06	34.8277
1291.26	37.2026
1294.46	38.7221
1297.66	40.1264
1300.85	42.1159
1304.05	42.8118
1307.24	44.3616
1310.43	44.3784
1313.63	44.9485
1316.82	46.3449
1320.01	44.9384
1323.2	45.1155
1326.38	45.0236
1329.57	42.8724
1332.76	40.6239
1335.94	38.2903
1339.12	38.2998
1342.3	37.9222
1345.48	38.4108
1348.66	36.2229
1351.84	36.2221
1355.01	36.5057
1358.19	37.213
1361.36	36.4701
1364.53	37.0092
1367.71	36.595
1370.88	36.0737
1374.04	34.4555
1377.21	33.4381
1380.38	32.9499
1383.54	31.6015
1386.71	30.3364
1389.87	28.4136
1393.03	27.5323
1396.19	24.834
1399.35	24.7975
1402.51	24.4181
1405.67	24.5967
1408.82	24.5537
1411.98	24.9099
1415.13	26.9213
1418.28	29.218
1421.43	34.0898
1424.58	37.9151
1427.73	42.2804
1430.88	47.3795
1434.02	51.4241
1437.17	55.4527
1440.31	58.3078
1443.45	61.0854
1446.6	62.9961
1449.74	63.7617
1452.87	63.7511
1456.01	64.766
1459.15	65.1059
1462.28	66.3061
1465.42	65.0603
1468.55	65.0404
1471.68	64.4185
1474.81	64.1258
1477.94	62.8446
1481.07	60.5639
1484.2	58.4304
1487.32	54.9969
1490.45	52.9709
1493.57	51.4987
1496.69	48.8398
1499.81	46.6609
1502.93	43.6882
1506.05	39.5323
1509.17	37.1554
1512.28	34.7736
1515.4	31.1093
1518.51	27.7491
1521.63	25.2792
1524.74	22.2858
1527.85	20.9358
1530.96	19.7641
1534.06	20.11
1537.17	21.0574
1540.28	21.2309
1543.38	21.8782
1546.48	22.8287
1549.59	22.2947
1552.69	21.2925
1555.79	21.1497
1558.88	22.256
1561.98	22.8695
1565.08	24.3757
1568.17	26.5328
1571.27	29.0408
1574.36	32.4366
1577.45	35.1987
1580.54	39.0373
1583.63	39.8049
1586.72	42.9599
1589.8	44.8156
1592.89	45.2672
1595.97	46.3169
1599.06	47.2758
1602.14	48.5973
1605.22	47.3515
1608.3	47.2138
1611.38	46.9575
1614.46	46.924
1617.53	46.9686
1620.61	46.0846
1623.68	45.339
1626.75	45.6047
1629.82	45.8445
1632.9	45.9731
1635.96	47.1036
1639.03	48.5529
1642.1	49.8591
1645.16	50.5363
1648.23	52.2908
1651.29	52.1962
1654.36	52.4813
1657.42	50.2692
1660.48	48.5653
1663.53	46.9095
1666.59	44.5468
1669.65	42.6389
1672.7	39.745
1675.76	38.2351
1678.81	34.163
1681.86	31.1281
1684.91	27.0333
1687.96	24.4016
1691.01	21.0236
1694.06	18.4806
1697.11	16.4763
1700.15	14.2118
1703.2	12.7279
1706.24	10.2261
1709.28	9.06932
1712.32	8.6124
1715.36	7.24911
1718.4	5.92468
1721.43	5.27275
1724.47	5.48091
1727.5	6.00597
1730.54	5.96099
1733.57	6.35364
1736.6	7.73898
1739.63	8.10651
1742.66	9.35575
1745.69	9.47646
1748.72	9.55992
1751.74	8.15638
1754.77	7.61049
1757.79	7.02841
1760.81	7.71516
1763.83	7.17085
1766.85	5.32561
1769.87	5.14864
1772.89	4.85068
1775.91	4.15771
1778.92	3.95919
1781.94	3.65091
1784.95	3.46862
1787.96	3.68744
1790.97	4.03406
1793.98	4.36594
1796.99	4.53778
1800	4.71942
1803	4.9275
1806.01	4.9646
1809.01	5.67666
1812.02	5.97603
1815.02	5.20203
1818.02	4.67446
1821.02	4.36609
1824.02	4.24891
1827.01	4.53194
1830.01	4.38235
1833	4.39823
1836	4.1869
1838.99	3.54416
1841.98	3.50597
1844.97	5.06358
1847.96	5.15419
1850.95	5.39736
1853.94	5.46233
1856.92	6.21023
1859.91	7.05573
1862.89	6.27558
1865.88	7.13283
1868.86	7.414
1871.84	7.87045
1874.82	8.27327
1877.8	8.13118
1880.77	8.29133
1882.51	7.29232
1885.5	5.73113
1888.48	5.57272
1891.47	6.21783
1894.46	6.00546
1897.44	5.873
1900.42	5.26351
1903.41	5.36486
1906.39	5.24986
1909.37	5.1691
1912.35	6.00151
1915.32	6.43392
1918.3	6.03561
1921.28	5.13423
1924.25	4.75505
1927.22	4.27378
1930.2	4.58335
1933.17	4.65799
1936.14	4.96746
1939.11	5.13357
1942.08	4.68148
1945.04	4.09049
1948.01	4.22303
1950.97	3.50364
1953.94	2.37782
1956.9	2.36437
1959.86	3.02527
1962.82	3.2891
1965.78	3.22604
1968.74	2.66769
1971.69	2.76672
1974.65	3.33977
1977.61	3.70668
1980.56	5.53726
1983.51	5.69812
1986.46	6.88225
1989.41	6.64639
1992.36	6.3415
1995.31	6.3624
1998.26	5.73327
2001.2	6.65666
2004.15	7.68523
2007.09	7.86355
2010.04	7.59303
2012.98	7.57792
2015.92	8.26708
2018.86	7.95328
2021.8	7.66935
2024.74	6.90337
2027.67	7.20066
2030.61	7.14415
2033.54	7.12837
2036.47	7.62278
2039.41	8.27814
2042.34	8.34399
2045.27	9.3806
2048.2	11.0723
2051.12	12.2462
2054.05	12.2796
2056.98	13.0322
2059.9	14.6638
2062.82	16.7751
2065.75	17.144
2068.67	18.234
2071.59	18.9067
2074.51	21.1908
2077.43	22.5573
2080.34	23.7915
2083.26	25.4405
2086.17	26.864
2089.09	27.3509
2092	28.7096
2094.91	30.3555
2097.82	31.5245
2100.73	32.9126
2103.64	35.5352
2106.55	37.3923
2109.46	38.8127
2112.36	40.2711
2115.27	42.124
2118.17	44.8879
2121.07	47.4125
2123.97	50.8409
2126.87	53.3231
2129.77	55.8525
2132.67	59.2109
2135.57	61.1863
2138.46	63.5486
2141.36	66.8651
2144.25	68.8747
2147.14	71.9554
2150.03	74.3989
2152.92	76.2309
2155.81	77.9431
2158.7	79.8045
2161.59	82.5251
2164.48	83.6948
2167.36	84.8089
2170.25	84.0016
2173.13	83.0636
2176.01	83.5144
2178.89	81.601
2181.77	80.6693
2184.65	79.9206
2187.53	78.2894
2190.41	76.5303
2193.28	74.615
2196.16	72.4097
2199.03	69.8363
2201.9	66.4762
2204.78	63.4539
2207.65	60.1458
2210.51	58.0829
2213.38	55.1576
2216.25	53.6785
2219.12	50.4267
2221.98	47.5238
2224.85	45.0748
2227.71	43.1843
2230.57	40.3134
2233.43	37.2021
2236.29	35.0591
2239.15	32.319
2242.01	30.1722
2244.87	28.4497
2247.73	27.3285
2250.58	25.4925
2253.43	24.8681
2256.29	23.4326
2259.14	21.9007
2261.99	20.9761
2264.84	20.8158
2267.69	20.0384
2270.54	19.0635
2273.38	18.135
2276.23	18.1724
2279.07	18.0893
2281.92	18.355
2284.76	17.8955
2287.6	16.7649
2290.44	14.9211
2293.28	13.734
2296.12	14.1443
2298.96	14.4083
2301.79	14.7764
2304.63	15.7776
2307.46	15.4902
2310.3	16.0222
2313.13	16.637
2315.96	16.8344
2318.79	16.4798
2321.62	16.3868
2324.45	15.6385
2327.27	15.8363
2330.1	14.6554
2332.93	14.0376
2335.75	14.0848
2338.57	13.0103
2341.4	12.1597
2344.22	10.9821
2347.04	9.84602
2349.86	8.38844
2352.67	5.86351
2355.49	4.30591
2358.31	2.67348
2361.12	1.64361
2363.94	2.49225
2366.75	3.07355
2369.56	2.91664
2372.37	3.7138
2375.18	3.33433
2377.99	3.86102
2380.8	4.39394
2383.61	2.86653
2386.41	2.63822
2389.22	2.08882
2392.02	2.80575
2394.82	3.32672
2397.63	4.79538
2400.43	4.46799
2403.23	4.42558
2406.02	4.4225
2408.82	3.81923
2411.62	5.07839
2414.41	4.02645
2417.21	3.54281
2420	3.7862
2422.79	3.45619
2425.59	4.23892
2428.38	4.23374
2431.17	4.28321
2433.96	4.75251
2436.74	5.64803
2439.53	6.13186
2442.32	6.28979
2445.1	6.16178
2447.88	5.5338
2450.67	4.70398
2453.45	4.18766
2456.23	4.61376
2459.01	5.01313
2461.79	5.56403
2464.57	5.39312
2467.34	5.27172
2470.12	4.63243
2472.89	5.20543
2475.67	4.92295
2478.44	5.44663
2481.21	5.65626
2483.98	5.80349
2486.75	5.92711
2489.52	5.71923
2492.29	6.23682
2495.06	6.98143
2497.82	6.53629
2500.59	5.98677
2503.35	6.78346
2506.11	6.29597
2508.88	5.98164
2511.63	5.29214
2514.39	4.5315
2517.15	4.74005
2519.91	4.72252
2522.67	5.76013
2525.42	5.97683
2528.18	5.13035
2530.93	4.17604
2533.69	3.53634
2536.44	3.19538
2539.19	2.75661
2541.94	2.95222
2544.69	2.20394
2547.44	2.41253
2550.18	3.71113
2552.93	2.83927
2555.68	3.16545
2558.42	3.73302
2561.16	3.80117
2563.9	3.14714
2566.64	2.85041
2569.38	3.47308
2572.12	2.89519
2574.86	2.95397
2577.6	3.59888
2580.34	3.52169
2583.07	4.30054
2585.81	4.41045
2588.54	4.45708
2591.27	4.73371
2594	3.6801
2596.73	3.33086
2599.46	3.13178
2602.19	3.14465
2604.92	2.48159
2607.64	3.61339
2610.37	4.14802
2613.09	4.55401
2615.82	5.21378
2618.54	5.9274
2621.26	5.88513
2623.98	6.25333
2626.7	6.30535
2629.42	6.59062
2632.14	6.66468
2634.86	6.81628
2637.57	6.72859
2640.29	6.3482
2643	6.67591
2645.72	6.56007
2648.43	5.70003
2651.14	5.00328
2653.85	4.75519
2656.56	4.82333
2659.27	4.815
2661.97	3.64607
2664.68	3.17303
2667.38	3.09696
2670.09	2.68128
2672.79	3.52336
2675.49	3.76276
2678.2	3.01661
2680.89	3.33446
2683.59	3.93518
2686.29	3.53935
2688.99	3.835
2691.69	4.10419
2694.38	3.89366
2697.08	4.04786
2699.77	4.92532
2702.46	6.4481
2705.16	7.7278
2707.85	8.31508
2710.54	9.55992
2713.23	10.4344
2715.92	10.7445
2718.6	11.107
2721.29	11.883
2723.97	12.0963
2726.66	10.8518
2729.34	10.7971
2732.02	10.7409
2734.7	11.1539
2737.39	9.98031
2740.06	9.0434
2742.74	8.34746
2745.42	7.18439
2748.1	6.06958
2750.77	5.50482
2753.45	4.68545
2756.12	3.69585
2758.79	2.62574
2761.47	1.4368
2764.14	1.1334
2766.81	0.707762
2769.48	0.979481
2772.14	0.464991
2774.81	0.0596924
2777.48	0.399565
2780.14	0.508413
2782.81	-0.129265
2785.47	-0.747759
2788.13	-0.37891
2790.79	-0.386255
2793.46	-0.194539
2796.11	-0.551454
2798.77	-0.487921
2801.43	-0.566765
2804.09	-1.05154
2806.74	-0.710509
2809.4	-1.59675
2812.05	-1.24025
2814.71	0.97919
2817.36	2.45425
2820.01	4.93061
2822.66	7.25613
2825.31	10.4872
2827.96	14.3855
2830.61	18.706
2833.25	23.5489
2835.9	28.9111
2838.54	33.8914
2841.18	39.8363
2843.83	45.7719
2846.47	51.2458
2849.11	57.551
2851.75	63.6845
2854.39	69.256
2857.03	73.7157
2859.67	77.771
2862.3	82.2455
2864.94	86.4385
2867.57	89.1228
2870.21	91.4309
2872.84	93.2934
2875.47	95.8338
2878.1	98.6327
2880.73	100.68
2883.36	103.796
2885.99	107.023
2888.61	109.307
2891.24	111.856
2893.87	115.223
2896.49	119.356
2899.11	123.903
2901.74	129.485
2904.36	135.387
2906.98	142.573
2909.6	150.007
2912.22	156.817
2914.83	164.735
2917.45	170.949
2920.07	177.781
2922.68	183.872
2925.3	188.998
2927.91	192.471
2930.52	193.294
2933.13	193.476
2935.74	192.194
2938.35	189.524
2940.96	185.357
2943.57	180.547
2946.18	176.017
2948.78	169.697
2951.39	162.648
2953.99	154.512
2956.6	146.373
2959.2	137.83
2961.8	130.213
2964.4	123.341
2967	116.939
2969.6	109.458
2972.2	102.995
2974.79	97.1515
2977.39	89.9038
2979.98	84.3462
2982.58	77.7216
2985.17	71.6232
2987.76	65.3923
2990.36	58.3724
2992.95	52.0939
2995.54	45.8303
2998.12	40.845
3000.71	34.6764
3003.3	29.9942
3005.88	25.5648
3008.47	21.9513
3011.05	18.955
3013.64	15.4823
3016.22	12.359
3018.8	9.26258
3021.38	6.76622
3023.96	5.85484
3026.54	5.44087
3029.12	4.36225
3031.69	3.39747
3034.27	3.26146
3036.85	3.44806
3039.42	3.06425
3041.99	2.8587
3044.57	2.98512
3047.14	2.52484
3049.71	2.93855
3052.28	3.56914
3054.85	3.46837
3057.42	4.30603
3059.98	4.61828
3062.55	4.34741
3065.11	4.34162
3067.68	4.50568
3070.24	4.43474
3072.8	5.07814
3075.37	4.11382
3077.93	3.47621
3080.49	2.53227
3083.05	2.34713
3085.61	2.21097
3088.16	1.93492
3090.72	1.52862
3093.27	0.680129
3095.83	0.413066
3098.38	0.113874
3100.94	-0.186195
3103.49	-0.296653
3106.04	-1.08746
3108.59	-0.922899
3111.14	-0.461817
3113.69	0.628445
3116.23	1.38683
3118.78	1.96784
3121.33	2.63461
3123.87	3.26726
3126.42	3.57702
3128.96	4.45824
3131.5	5.33954
3134.04	6.33882
3136.58	6.58312
3139.12	7.70695
3141.66	8.35312
3144.2	9.07467
3146.74	8.62652
3149.27	8.43915