File: data/Raman/poly_smoothed/Mbcal_20_25_49_1x_45s_532 nm_x100_100%_600 gr_mm_01.txt
#Acq. time (s)=	45
#Accumulations=	2
#Range (cm-¹)=	200...3150
#Windows=	2
#Auto scanning=	Off
#Autofocus=	Off
#Macrospot=	Off
#AutoExposure=	Off
#Spike filter=	Multiple accum.
#Delay time (s)=	0
#Binning=	1
#Readout mode=	Signal
#DeNoise=	Off
#ICS correction=	On
#Dark correction=	Off
#Inst. Process=	Off
#Detector Gain=	Best Dynamic Range
#Detector ADC=	20 kHz
#Detector temperature (°C)=	-69.85
#Instrument=	LabRAM HR Evol
#Detector=	Synapse
#Objective=	x100
#Grating=	600 gr/mm
#ND Filter=	100%
#Laser (nm)=	532
#Hole=	100.021
#Range=	Auto
#Laser Pol.=	No
#Raman. Pol.=	No
#Laser Pol. (°)=	-0.0007625
#Raman Pol. (°)=	89.9995
#Collection=	Microscope
#StageXY=	Marzhauser
#StageZ=	Marzhauser
#X (µm)=	-1134.9
#Y (µm)=	1234.8
#Z (µm)=	578.35
#Full time(mm:ss)=	3:18
#Project=
#Sample=
#Site=
#Title=	Mbcal_20_25_49_2x_45s_532 nm_x100_100%_600 gr_mm
#Remark=
#Date=	18.07.2022 13:58
#Acquired=	18.07.2022 13:58:59
#Base:Fit=	10.08.2022 10:55:08
#Base:Sub=	10.08.2022 10:55:14
#Filter:Polynom=	16.08.2022 10:07:28
#AxisType[0]=Intens
#AxisUnit[0]=Cnt
#AxisType[1]=Spectr
#AxisUnit[1]=1/cm
200.419	14.1235
204.048	15.4893
207.678	16.5199
211.304	15.9369
214.928	14.3948
218.554	12.6984
222.176	12.1729
225.798	10.2536
229.417	10.1032
233.035	8.84764
236.653	7.61013
240.268	6.22978
243.881	5.99479
247.493	4.83435
251.103	3.79679
254.715	1.97104
258.322	1.56479
261.929	3.00739
265.534	2.44364
269.137	4.20775
272.739	4.82423
276.34	5.0834
279.939	5.45227
283.537	6.33252
287.134	5.85376
290.729	6.19369
294.323	6.87238
297.913	6.43861
301.504	7.62375
305.093	8.05336
308.682	8.92013
312.268	8.85531
315.852	8.50051
319.436	8.8902
323.018	7.99884
326.597	8.38153
330.177	7.95192
333.753	7.87165
337.331	5.64652
340.906	5.21866
344.478	5.62439
348.051	6.4766
351.621	6.1361
355.189	5.50888
358.757	5.63458
362.323	4.63849
365.889	4.41792
369.451	2.0488
373.012	2.7427
376.574	2.79799
380.133	4.72993
383.69	4.78247
387.245	5.79438
390.8	6.2866
394.353	6.75664
397.906	7.63228
401.456	7.82562
405.005	7.99599
408.552	8.85653
412.099	9.67788
415.643	10.0661
419.187	9.90024
422.728	9.79175
426.269	9.88679
429.806	9.5536
433.344	7.79374
436.881	7.44512
440.416	6.57362
443.949	5.07166
447.48	4.76377
451.011	3.2436
454.541	1.43765
458.069	0.224839
461.594	1.05951
465.119	0.948521
468.642	1.42741
472.165	1.64017
475.684	3.39907
479.204	2.56462
482.721	4.09592
486.239	6.85901
489.753	9.64596
493.268	12.5881
496.779	14.7173
500.289	17.0633
503.8	19.6982
507.307	20.3638
510.813	23.6148
514.32	24.8366
517.823	24.5171
521.325	26.5041
524.826	27.2993
528.325	26.2003
531.823	25.2977
535.32	24.7661
538.815	24.0367
542.309	22.5588
545.802	22.0302
549.293	19.9769
552.783	17.1522
556.271	16.3329
559.759	13.9947
563.245	11.2141
566.729	8.23584
570.213	9.13288
573.693	7.43906
577.173	6.8002
580.652	5.11274
584.13	4.82757
587.605	6.41248
591.08	6.64151
594.552	7.56681
598.025	9.04701
601.496	8.04154
604.964	9.04703
608.433	9.62419
611.898	10.0923
615.364	10.314
618.827	11.3749
622.288	12.3029
625.75	14.6474
629.209	16.1514
632.667	15.6506
636.125	17.3054
639.58	18.5405
643.033	18.2369
646.485	18.9485
649.936	19.9133
653.388	20.1463
656.836	19.9324
660.283	23.2783
663.728	24.9815
667.173	26.4744
670.616	26.7956
674.057	27.2
677.498	27.0473
680.937	27.035
684.375	28.2306
687.809	27.1712
691.244	27.4639
694.678	27.2688
698.111	25.9746
701.54	26.8645
704.97	27.5937
708.398	29.6444
711.826	30.6493
715.25	30.5367
718.675	30.5312
722.096	30.9412
725.518	30.462
728.937	32.9538
732.357	33.671
735.773	34.3869
739.19	35.8019
742.604	37.7232
746.018	41.3194
749.429	43.1361
752.839	45.8151
756.248	47.7139
759.657	50.9707
763.063	53.6373
766.468	55.8225
769.871	57.2417
773.273	58.4394
776.676	61.4153
780.075	63.5764
783.474	66.7828
786.871	69.3346
790.266	69.7454
793.661	69.0315
797.054	69.2058
800.446	70.1291
803.834	70.822
807.224	71.7025
810.612	71.0797
813.998	70.8855
817.384	70.0086
820.766	69.4451
824.149	69.5412
827.531	70.9062
830.909	75.1187
834.288	77.9745
837.666	80.634
841.041	84.4609
844.416	86.28
847.788	87.4435
851.161	87.9819
854.53	88.0189
857.901	86.9784
861.268	86.0602
864.633	83.3359
868	80.9174
871.363	77.1003
874.725	71.7715
878.088	68.9312
881.447	65.5269
884.805	60.3774
888.162	56.0651
891.518	50.555
894.872	46.5652
898.225	40.996
901.577	37.2577
904.928	36.8686
908.277	38.1245
911.625	41.9547
914.972	43.407
918.318	43.6129
921.662	43.9253
925.005	45.284
928.347	44.2838
931.686	43.7837
935.025	43.0092
938.363	43.16
941.698	43.0428
945.034	42.7562
948.368	39.8774
951.699	40.4326
955.031	39.9922
958.36	38.9082
961.689	37.7057
965.016	36.0892
968.343	35.6236
971.666	35.7432
974.991	35.5722
978.312	34.6017
981.632	34.2114
984.953	34.036
988.27	32.5166
991.587	30.459
994.902	29.3232
998.216	26.0217
1001.53	24.0824
1004.84	23.5142
1008.15	23.8414
1011.46	25.4453
1014.77	26.8589
1018.07	27.6201
1021.38	28.6905
1024.68	29.7917
1027.99	29.9912
1031.29	32.2134
1034.59	33.2018
1037.89	32.1474
1041.18	32.2606
1044.48	32.9824
1047.77	33.4871
1051.07	33.9067
1054.36	33.2135
1057.65	31.6183
1060.94	30.9188
1064.23	28.11
1067.52	26.557
1070.8	25.7703
1074.09	22.8758
1077.37	22.3443
1080.65	20.593
1083.93	19.6447
1087.21	20.917
1090.49	21.6875
1093.77	22.598
1097.04	23.9436
1100.32	23.1592
1103.59	23.4007
1106.86	23.545
1110.13	23.6659
1113.4	21.5468
1116.67	20.3089
1119.94	17.9656
1123.2	16.7417
1126.47	16.0389
1129.73	15.6493
1132.99	12.8357
1136.25	11.3116
1139.51	9.53272
1142.77	8.55885
1146.03	7.04044
1149.28	6.53493
1152.54	4.48712
1155.79	3.43263
1159.04	2.28074
1162.29	1.63179
1165.54	3.34437
1168.79	4.72624
1172.04	3.62889
1175.28	3.87255
1178.53	4.59402
1181.77	4.99611
1185.01	4.18925
1188.25	4.51564
1191.49	4.24648
1194.73	4.09764
1197.96	4.25433
1201.2	4.34388
1204.43	3.77392
1207.66	4.159
1210.9	4.7783
1214.13	4.92181
1217.36	6.74478
1220.58	8.28395
1223.81	11.2357
1227.04	13.0584
1230.26	14.0821
1233.48	17.5357
1236.71	20.0188
1239.93	22.4045
1243.14	25.4149
1246.36	27.3525
1249.58	29.4941
1252.8	32.3631
1256.01	35.3731
1259.22	38.2888
1262.43	39.3944
1265.64	40.5882
1268.85	42.4973
1272.06	42.6378
1275.27	43.405
1278.48	44.2861
1281.68	44.401
1284.88	45.3046
1288.08	48.5892
1291.28	48.9692
1294.48	50.1327
1297.68	51.4246
1300.88	53.7865
1304.07	53.9418
1307.27	55.5107
1310.46	55.7212
1313.65	56.0312
1316.85	54.2362
1320.03	54.2705
1323.22	54.1325
1326.41	55.0584
1329.6	54.2389
1332.78	53.4171
1335.96	53.6153
1339.15	51.7445
1342.33	50.0718
1345.51	48.9367
1348.69	48.7153
1351.86	48.0535
1355.04	48.5823
1358.21	48.3231
1361.39	47.2781
1364.56	48.243
1367.73	48.0909
1370.9	47.8552
1374.07	49.4483
1377.24	49.6161
1380.41	48.7131
1383.57	48.266
1386.73	47.6741
1389.9	45.7811
1393.06	44.0511
1396.22	44.3007
1399.38	45.0206
1402.54	45.1816
1405.69	46.0775
1408.85	48.2921
1412	52.2157
1415.16	55.1989
1418.31	58.7705
1421.46	63.3182
1424.61	68.7387
1427.76	72.869
1430.9	77.9927
1434.05	83.1059
1437.2	86.9555
1440.34	91.1048
1443.48	93.7011
1446.62	95.1613
1449.76	96.3401
1452.9	94.9018
1456.04	93.727
1459.17	92.9438
1462.31	89.0227
1465.44	85.1688
1468.58	80.3772
1471.71	76.0027
1474.84	71.5099
1477.97	66.1929
1481.1	60.7275
1484.22	57.2638
1487.35	52.9692
1490.47	47.0108
1493.59	42.1134
1496.72	37.6671
1499.84	34.6831
1502.96	31.4046
1506.08	28.7865
1509.19	27.0815
1512.31	24.4678
1515.42	22.4008
1518.54	21.5477
1521.65	19.573
1524.76	18.7725
1527.87	18.8517
1530.98	19.2069
1534.09	20.5146
1537.2	20.4241
1540.3	21.6392
1543.41	22.5617
1546.51	23.4801
1549.61	25.1119
1552.71	27.5326
1555.81	27.3018
1558.91	28.9747
1562.01	29.5618
1565.1	30.3072
1568.2	30.575
1571.29	31.8907
1574.38	35.7224
1577.48	37.9684
1580.57	39.5687
1583.65	42.8819
1586.74	43.2158
1589.83	44.159
1592.92	45.978
1596	47.2183
1599.08	47.5342
1602.16	47.9917
1605.24	47.2788
1608.32	48.3941
1611.4	48.3466
1614.48	47.8154
1617.56	47.63
1620.63	48.8714
1623.71	48.6279
1626.78	48.9233
1629.85	49.9663
1632.92	51.0834
1635.99	53.0925
1639.06	55.3238
1642.12	57.2643
1645.19	58.136
1648.25	59.8184
1651.32	59.4193
1654.38	59.6645
1657.44	58.892
1660.5	56.6634
1663.56	55.1334
1666.62	52.7794
1669.67	50.2096
1672.73	44.6875
1675.79	40.0316
1678.84	36.2935
1681.89	31.3724
1684.94	27.5438
1687.99	23.9183
1691.04	20.9151
1694.08	17.1306
1697.13	15.6103
1700.18	13.5171
1703.22	13.3406
1706.26	13.3691
1709.3	12.5533
1712.35	11.8075
1715.39	11.3592
1718.42	8.71841
1721.46	7.21561
1724.5	6.41116
1727.53	6.06696
1730.56	5.88124
1733.6	5.40766
1736.63	4.94498
1739.66	4.63341
1742.69	3.83888
1745.71	3.01891
1748.74	1.94309
1751.77	2.82649
1754.79	2.79127
1757.81	2.5022
1760.84	2.47752
1763.86	2.88345
1766.88	2.51488
1769.9	3.74164
1772.91	4.30601
1775.93	4.59556
1778.95	5.33183
1781.96	5.53537
1784.97	4.92827
1787.99	4.41501
1791	3.80635
1794.01	3.7365
1797.01	5.48968
1800.02	5.26347
1803.03	5.47808
1806.03	6.50711
1809.04	7.30486
1812.04	6.91015
1815.04	7.20883
1818.04	7.41103
1821.04	7.13656
1824.04	8.15382
1827.04	8.02157
1830.03	6.5927
1833.03	6.1407
1836.02	5.96911
1839.02	5.34995
1842.01	5.41663
1845	5.83372
1847.99	6.29229
1850.98	5.05167
1853.96	5.7261
1856.95	4.94437
1859.94	5.56673
1862.92	5.76258
1865.9	5.70296
1868.88	6.06185
1871.86	7.51077
1874.84	8.0086
1877.82	8.70487
1880.8	8.52751
1882.58	7.82788
1885.57	7.75067
1888.56	6.7778
1891.54	6.70818
1894.53	6.52646
1897.51	5.43315
1900.5	4.81608
1903.48	4.69966
1906.46	4.65917
1909.44	4.39438
1912.42	5.59798
1915.4	5.9779
1918.37	5.24399
1921.35	4.5959
1924.32	5.20234
1927.3	6.16015
1930.27	5.55489
1933.24	6.15092
1936.21	5.20316
1939.18	5.19949
1942.15	6.30929
1945.11	6.40701
1948.08	6.08862
1951.04	5.68819
1954.01	6.28235
1956.97	6.73251
1959.93	6.74294
1962.89	7.64559
1965.85	8.29353
1968.81	8.03724
1971.77	8.4899
1974.72	7.72412
1977.68	6.66526
1980.63	7.35922
1983.58	9.08836
1986.53	9.32114
1989.48	9.94477
1992.43	11.1456
1995.38	11.4962
1998.33	12.8238
2001.27	12.0721
2004.22	11.1444
2007.16	11.0058
2010.11	11.0782
2013.05	11.9351
2015.99	11.7493
2018.93	12.1644
2021.87	13.1347
2024.8	13.5712
2027.74	14.4837
2030.68	13.8378
2033.61	13.9274
2036.54	15.1186
2039.48	13.8027
2042.41	11.9761
2045.34	10.9997
2048.27	11.6737
2051.19	12.181
2054.12	12.393
2057.05	13.1428
2059.97	13.1558
2062.9	14.0291
2065.82	13.3588
2068.74	14.6076
2071.66	13.5526
2074.58	13.6656
2077.5	14.3428
2080.41	14.2009
2083.33	13.6176
2086.24	14.2129
2089.16	14.7959
2092.07	14.7385
2094.98	14.7127
2097.89	16.6695
2100.8	16.7575
2103.71	16.6109
2106.62	16.8428
2109.53	17.107
2112.43	18.5796
2115.33	18.7824
2118.24	19.2974
2121.14	20.0669
2124.04	20.7588
2126.94	21.9981
2129.84	23.3924
2132.74	25.6789
2135.63	26.9141
2138.53	28.9016
2141.43	29.3799
2144.32	30.0947
2147.21	32.0671
2150.1	33.6129
2152.99	33.7701
2155.88	35.0252
2158.77	37.1897
2161.66	37.7655
2164.55	39.2772
2167.43	39.7722
2170.31	41.4176
2173.2	41.3427
2176.08	40.9142
2178.96	41.1915
2181.84	41.0018
2184.72	39.7987
2187.6	38.4524
2190.47	37.6965
2193.35	36.9346
2196.23	35.7245
2199.1	33.6844
2201.97	33.3605
2204.84	32.1718
2207.71	31.4618
2210.58	29.5369
2213.45	28.6377
2216.32	27.5998
2219.19	25.0813
2222.05	23.6106
2224.92	22.8633
2227.78	22.7173
2230.64	21.373
2233.5	20.4257
2236.36	19.2517
2239.22	19.1592
2242.08	19.1603
2244.94	17.46
2247.79	15.9158
2250.65	15.0717
2253.5	13.7482
2256.36	12.9486
2259.21	12.22
2262.06	11.4554
2264.91	10.8253
2267.76	8.42922
2270.6	6.87697
2273.45	6.798
2276.3	6.86549
2279.14	6.30378
2281.98	5.79313
2284.83	5.1737
2287.67	3.68506
2290.51	2.74553
2293.35	1.34976
2296.19	2.43272
2299.02	1.84512
2301.86	2.16454
2304.7	2.96609
2307.53	3.92734
2310.36	5.4853
2313.2	5.68249
2316.03	5.25735
2318.86	5.23617
2321.69	5.48417
2324.51	5.0835
2327.34	5.15226
2330.17	5.8272
2332.99	5.44998
2335.82	4.79207
2338.64	4.41678
2341.46	5.47981
2344.28	5.89823
2347.1	5.89166
2349.92	5.11023
2352.74	4.89314
2355.56	3.66319
2358.37	1.70745
2361.19	1.45185
2364	2.02398
2366.82	2.59843
2369.63	2.46267
2372.44	3.66304
2375.25	4.07399
2378.06	5.17928
2380.86	4.44755
2383.67	5.5197
2386.48	5.95547
2389.28	6.34472
2392.09	6.90918
2394.89	6.41583
2397.69	7.85946
2400.49	7.65258
2403.29	7.15972
2406.09	6.8285
2408.89	6.33545
2411.69	6.3511
2414.48	7.11183
2417.28	6.02943
2420.07	5.72231
2422.86	5.71195
2425.65	5.18064
2428.45	5.29243
2431.23	4.70183
2434.02	5.02604
2436.81	4.16772
2439.6	3.54417
2442.38	2.98655
2445.17	3.47101
2447.95	2.86013
2450.73	2.99554
2453.52	3.47044
2456.3	3.46088
2459.08	2.97961
2461.85	2.59974
2464.63	2.58008
2467.41	2.36994
2470.19	1.90279
2472.96	0.931888
2475.73	0.916057
2478.51	1.09492
2481.28	1.02776
2484.05	0.542202
2486.82	0.409518
2489.59	1.67474
2492.35	3.86795
2495.12	5.08804
2497.89	4.80007
2500.65	6.05044
2503.42	5.83156
2506.18	5.87464
2508.94	5.97111
2511.7	6.12824
2514.46	6.07121
2517.22	6.56721
2519.98	7.66863
2522.73	8.24103
2525.49	7.1922
2528.25	6.38594
2531	5.76715
2533.75	5.59972
2536.5	5.12351
2539.25	3.57316
2542.01	2.64474
2544.75	1.91812
2547.5	0.676269
2550.25	0.415748
2553	0.339444
2555.74	0.517964
2558.49	1.58615
2561.23	1.21993
2563.97	1.19125
2566.71	1.21375
2569.45	1.66996
2572.19	1.05125
2574.93	0.823219
2577.67	0.905059
2580.4	0.983584
2583.14	1.51495
2585.87	2.04174
2588.6	1.58852
2591.34	2.50147
2594.07	1.77209
2596.8	2.40684
2599.53	2.98925
2602.26	3.79377
2604.98	4.4431
2607.71	5.60035
2610.44	5.27976
2613.16	5.90585
2615.88	5.41568
2618.61	5.67799
2621.33	5.74228
2624.05	6.01135
2626.77	7.09377
2629.49	5.84214
2632.21	6.44117
2634.92	5.42432
2637.64	4.44963
2640.35	4.02972
2643.07	2.64611
2645.78	2.48695
2648.49	1.80681
2651.2	1.60936
2653.91	1.23441
2656.62	0.638881
2659.33	0.729555
2662.04	0.961003
2664.74	2.14313
2667.45	2.88875
2670.15	2.99937
2672.86	3.40995
2675.56	3.54967
2678.26	3.03927
2680.96	3.76156
2683.66	4.54532
2686.36	6.33603
2689.06	7.08728
2691.75	8.332
2694.45	8.38824
2697.14	8.84715
2699.84	9.52895
2702.53	10.3831
2705.22	10.7178
2707.91	10.6509
2710.6	11.105
2713.29	10.9113
2715.98	11.0303
2718.67	11.4896
2721.35	11.9625
2724.04	12.5262
2726.72	12.8516
2729.4	12.5518
2732.09	12.7384
2734.77	11.0762
2737.45	10.4551
2740.13	10.2413
2742.81	10.2928
2745.48	10.4822
2748.16	11.359
2750.84	11.4676
2753.51	11.1367
2756.19	10.8771
2758.86	10.3324
2761.53	9.58926
2764.2	8.85805
2766.87	7.8302
2769.54	6.08114
2772.21	4.77317
2774.88	4.84396
2777.54	4.63136
2780.21	3.94261
2782.87	3.94635
2785.53	4.16723
2788.2	4.30752
2790.86	4.00302
2793.52	3.91973
2796.18	4.22898
2798.84	4.39615
2801.49	4.95458
2804.15	5.21199
2806.81	6.17579
2809.46	6.56794
2812.12	7.80079
2814.77	9.78801
2817.42	12.3786
2820.07	14.5302
2822.72	18.3733
2825.37	22.3488
2828.02	26.4301
2830.67	30.8552
2833.31	36.6826
2835.96	43.3355
2838.61	49.9896
2841.25	57.1624
2843.89	65.1851
2846.53	72.9587
2849.17	81.7273
2851.81	90.1331
2854.45	99.1637
2857.09	108.605
2859.73	116.966
2862.36	124.772
2865	131.585
2867.64	138.366
2870.27	144.452
2872.9	149.546
2875.53	155.907
2878.16	162.128
2880.79	166.34
2883.42	170.459
2886.05	174.36
2888.68	177.814
2891.3	181.309
2893.93	184.752
2896.55	188.793
2899.18	194.345
2901.8	199.317
2904.42	205.766
2907.04	213.098
2909.66	222.196
2912.28	232.282
2914.9	241.189
2917.51	250.423
2920.13	258.956
2922.74	265.907
2925.36	270.925
2927.97	274.082
2930.59	275.302
2933.2	275.036
2935.81	272.779
2938.42	268.274
2941.02	260.4
2943.63	251.568
2946.24	240.23
2948.85	228.379
2951.45	216.746
2954.05	204.056
2956.66	191.552
2959.26	180.412
2961.86	169.973
2964.46	160.329
2967.06	152.246
2969.66	145.576
2972.26	138.699
2974.85	133.999
2977.45	128.688
2980.05	122.584
2982.64	117.407
2985.23	111.871
2987.83	106.277
2990.42	99.4163
2993.01	91.5577
2995.6	85.4609
2998.19	78.0644
3000.77	70.3413
3003.36	60.9901
3005.95	54.6928
3008.53	47.8666
3011.12	42.2493
3013.7	36.5839
3016.28	31.6993
3018.86	27.4377
3021.44	24.9373
3024.02	22.551
3026.6	20.2131
3029.18	18.4607
3031.76	17.6349
3034.33	16.5225
3036.91	15.8674
3039.48	16.5694
3042.05	16.6829
3044.63	17.0191
3047.2	17.0178
3049.77	18.4019
3052.34	19.3113
3054.91	19.0794
3057.48	18.8203
3060.04	19.7159
3062.61	19.219
3065.17	19.6973
3067.74	19.2578
3070.3	19.3178
3072.87	17.6404
3075.43	16.5618
3077.99	15.2684
3080.55	13.4068
3083.11	12.0469
3085.67	11.1739
3088.22	9.15946
3090.78	7.58739
3093.34	6.66821
3095.89	6.6765
3098.44	5.62047
3101	6.0995
3103.55	6.22836
3106.1	6.41201
3108.65	7.3364
3111.2	9.28234
3113.75	9.96876
3116.3	11.2377
3118.84	10.8579
3121.39	12.0535
3123.93	13.2661
3126.48	13.6748
3129.02	14.041
3131.56	12.7882
3134.1	11.9532
3136.64	11.17
3139.18	10.5878
3141.72	9.31136
3144.26	8.44864
3146.8	7.14626
3149.33	6.80168