File: data/Raman/poly_smoothed/Mbcal_20_25_50_1x_45s_532 nm_x100_100%_600 gr_mm_01.txt
#Acq. time (s)=	45
#Accumulations=	2
#Range (cm-¹)=	200...3150
#Windows=	2
#Auto scanning=	Off
#Autofocus=	Off
#Macrospot=	Off
#AutoExposure=	Off
#Spike filter=	Multiple accum.
#Delay time (s)=	0
#Binning=	1
#Readout mode=	Signal
#DeNoise=	Off
#ICS correction=	On
#Dark correction=	Off
#Inst. Process=	Off
#Detector Gain=	Best Dynamic Range
#Detector ADC=	20 kHz
#Detector temperature (°C)=	-69.85
#Instrument=	LabRAM HR Evol
#Detector=	Synapse
#Objective=	x100
#Grating=	600 gr/mm
#ND Filter=	100%
#Laser (nm)=	532
#Hole=	100.021
#Range=	Auto
#Laser Pol.=	No
#Raman. Pol.=	No
#Laser Pol. (°)=	-0.0007625
#Raman Pol. (°)=	89.9995
#Collection=	Microscope
#StageXY=	Marzhauser
#StageZ=	Marzhauser
#X (µm)=	-1136.5
#Y (µm)=	1234.1
#Z (µm)=	578.5
#Full time(mm:ss)=	3:18
#Project=
#Sample=
#Site=
#Title=	Mbcal_20_25_50_2x_45s_532 nm_x100_100%_600 gr_mm
#Remark=
#Date=	18.07.2022 14:05
#Acquired=	18.07.2022 14:05:03
#Base:Fit=	10.08.2022 10:55:08
#Base:Sub=	10.08.2022 10:55:14
#Filter:Polynom=	16.08.2022 10:07:28
#AxisType[0]=Intens
#AxisUnit[0]=Cnt
#AxisType[1]=Spectr
#AxisUnit[1]=1/cm
200.419	40.1142
204.048	33.9709
207.678	27.134
211.304	22.3139
214.928	18.6453
218.554	18.4276
222.176	17.1605
225.798	18.432
229.417	18.233
233.035	17.368
236.653	16.4379
240.268	14.1587
243.881	12.7397
247.493	11.9115
251.103	11.9712
254.715	12.6978
258.322	13.5217
261.929	14.5512
265.534	14.8649
269.137	14.2338
272.739	14.4558
276.34	13.8849
279.939	13.1854
283.537	9.1541
287.134	7.83602
290.729	7.00129
294.323	8.24111
297.913	8.86979
301.504	11.012
305.093	12.2738
308.682	14.205
312.268	14.4114
315.852	16.3739
319.436	16.3776
323.018	16.5578
326.597	16.0109
330.177	15.8195
333.753	17.4603
337.331	17.4665
340.906	18.3693
344.478	18.8505
348.051	18.2507
351.621	17.3056
355.189	14.8332
358.757	12.5396
362.323	10.5127
365.889	9.65264
369.451	7.97887
373.012	5.97492
376.574	5.58887
380.133	6.18124
383.69	5.4196
387.245	5.43527
390.8	5.34679
394.353	6.18173
397.906	6.18303
401.456	7.58919
405.005	8.49829
408.552	8.48585
412.099	9.41149
415.643	8.02864
419.187	9.5875
422.728	9.0586
426.269	7.84468
429.806	7.52143
433.344	7.31376
436.881	7.56342
440.416	6.74834
443.949	6.016
447.48	5.26171
451.011	4.20248
454.541	3.67252
458.069	3.59856
461.594	2.94748
465.119	2.97917
468.642	1.93309
472.165	2.04749
475.684	4.33039
479.204	5.61133
482.721	5.98073
486.239	6.49793
489.753	6.71727
493.268	7.41081
496.779	8.49145
500.289	9.95086
503.8	11.4724
507.307	14.8144
510.813	17.2616
514.32	19.3673
517.823	21.6654
521.325	23.7463
524.826	25.7617
528.325	26.6318
531.823	27.8193
535.32	28.5681
538.815	28.6792
542.309	29.3866
545.802	28.9489
549.293	27.2886
552.783	25.4738
556.271	24.3529
559.759	23.2205
563.245	19.8568
566.729	17.0089
570.213	12.8907
573.693	9.48544
577.173	6.90958
580.652	4.62406
584.13	2.29701
587.605	2.37206
591.08	1.48672
594.552	1.14392
598.025	0.665548
601.496	1.19511
604.964	1.77917
608.433	2.88361
611.898	4.97617
615.364	6.40648
618.827	6.92313
622.288	10.8463
625.75	12.1745
629.209	13.7236
632.667	15.0839
636.125	16.0095
639.58	17.1275
643.033	17.0723
646.485	17.4049
649.936	18.4062
653.388	18.0151
656.836	19.3958
660.283	18.9728
663.728	19.2297
667.173	18.8927
670.616	20.2889
674.057	21.0053
677.498	21.4045
680.937	22.2076
684.375	23.9141
687.809	23.8216
691.244	24.2376
694.678	25.3294
698.111	26.609
701.54	28.6687
704.97	29.9538
708.398	29.7237
711.826	30.538
715.25	32.3303
718.675	30.9783
722.096	31.1427
725.518	31.0088
728.937	30.3703
732.357	30.9182
735.773	32.9212
739.19	35.4772
742.604	36.1929
746.018	38.8332
749.429	41.1814
752.839	44.9771
756.248	47.8722
759.657	53.1078
763.063	55.8478
766.468	58.6721
769.871	61.7521
773.273	63.8057
776.676	65.8017
780.075	69.4515
783.474	69.9462
786.871	72.6986
790.266	73.5162
793.661	74.6837
797.054	74.0268
800.446	74.4179
803.834	72.9884
807.224	71.8759
810.612	71.2598
813.998	70.7815
817.384	69.3574
820.766	69.1293
824.149	67.6549
827.531	69.631
830.909	73.5995
834.288	75.2604
837.666	77.9235
841.041	80.8889
844.416	81.713
847.788	81.3712
851.161	82.2861
854.53	82.7773
857.901	82.7414
861.268	81.9601
864.633	79.5167
868	78.6823
871.363	76.6143
874.725	74.0079
878.088	70.6405
881.447	66.1977
884.805	63.328
888.162	59.1613
891.518	55.9408
894.872	53.5666
898.225	51.5392
901.577	49.9207
904.928	50.1525
908.277	50.8555
911.625	52.4394
914.972	52.6214
918.318	52.5184
921.662	52.7093
925.005	51.3495
928.347	50.7176
931.686	51.142
935.025	50.0631
938.363	49.4431
941.698	46.5194
945.034	44.3795
948.368	41.4442
951.699	39.0463
955.031	36.0097
958.36	32.5905
961.689	30.0019
965.016	27.8537
968.343	28.0024
971.666	27.847
974.991	28.2022
978.312	28.7919
981.632	28.9488
984.953	30.6012
988.27	29.4383
991.587	30.0631
994.902	31.1091
998.216	31.3221
1001.53	31.6271
1004.84	32.488
1008.15	33.3214
1011.46	35.0679
1014.77	36.9867
1018.07	40.3805
1021.38	41.5064
1024.68	42.6483
1027.99	42.623
1031.29	42.3455
1034.59	42.6379
1037.89	42.3376
1041.18	41.4927
1044.48	41.3594
1047.77	40.8813
1051.07	39.7909
1054.36	37.904
1057.65	36.3471
1060.94	33.8501
1064.23	31.6153
1067.52	29.8768
1070.8	26.9526
1074.09	26.6334
1077.37	25.0627
1080.65	22.5025
1083.93	19.7259
1087.21	19.9471
1090.49	20.1824
1093.77	19.8281
1097.04	20.8664
1100.32	22.001
1103.59	23.8916
1106.86	24.5244
1110.13	25.1449
1113.4	25.9539
1116.67	26.1455
1119.94	25.8935
1123.2	26.2366
1126.47	26.4508
1129.73	26.3362
1132.99	25.9915
1136.25	24.7473
1139.51	23.127
1142.77	22.3862
1146.03	21.0007
1149.28	18.5416
1152.54	16.4067
1155.79	14.3064
1159.04	12.2961
1162.29	10.1448
1165.54	8.62174
1168.79	8.49059
1172.04	7.04557
1175.28	6.77064
1178.53	6.69222
1181.77	8.11262
1185.01	8.33354
1188.25	7.47899
1191.49	8.04112
1194.73	8.59842
1197.96	10.213
1201.2	11.3212
1204.43	11.3423
1207.66	13.4628
1210.9	16.6996
1214.13	19.3037
1217.36	21.8909
1220.58	24.1619
1223.81	25.2336
1227.04	26.773
1230.26	28.126
1233.48	32.5167
1236.71	36.446
1239.93	38.387
1243.14	40.7414
1246.36	44.3376
1249.58	47.8065
1252.8	49.2327
1256.01	51.5358
1259.22	53.2613
1262.43	54.6264
1265.64	53.8895
1268.85	55.1529
1272.06	55.2999
1275.27	55.6864
1278.48	55.2318
1281.68	54.4519
1284.88	56.0883
1288.08	58.2366
1291.28	59.3336
1294.48	60.802
1297.68	61.0921
1300.88	61.8055
1304.07	60.4988
1307.27	60.5617
1310.46	62.4686
1313.65	64.1331
1316.85	63.8539
1320.03	63.8941
1323.22	66.1425
1326.41	66.6003
1329.6	66.7447
1332.78	67.3848
1335.96	66.9767
1339.15	65.767
1342.33	65.5709
1345.51	63.6355
1348.69	62.0013
1351.86	60.0991
1355.04	60.0112
1358.21	57.6744
1361.39	56.8949
1364.56	56.0232
1367.73	53.9714
1370.9	52.805
1374.07	52.6634
1377.24	51.4784
1380.41	49.7262
1383.57	47.6105
1386.73	46.925
1389.9	46.5472
1393.06	45.7043
1396.22	45.4484
1399.38	46.0354
1402.54	48.6629
1405.69	50.9797
1408.85	55.1478
1412	57.9791
1415.16	60.6344
1418.31	65.0467
1421.46	69.4662
1424.61	73.9787
1427.76	81.4246
1430.9	86.0622
1434.05	91.5392
1437.2	95.4001
1440.34	99.1841
1443.48	100.873
1446.62	102.75
1449.76	101.639
1452.9	102.144
1456.04	101.498
1459.17	98.0217
1462.31	95.3533
1465.44	92.4904
1468.58	88.6043
1471.71	84.5214
1474.84	80.143
1477.97	74.7273
1481.1	71.4002
1484.22	66.3328
1487.35	60.9083
1490.47	56.6685
1493.59	52.3883
1496.72	50.5191
1499.84	47.9457
1502.96	45.1968
1506.08	42.786
1509.19	38.7611
1512.31	36.8532
1515.42	34.0286
1518.54	31.5386
1521.65	29.2609
1524.76	27.9512
1527.87	26.9359
1530.98	26.3371
1534.09	25.814
1537.2	25.3268
1540.3	26.7427
1543.41	28.19
1546.51	29.3476
1549.61	29.4598
1552.71	30.3048
1555.81	31.0157
1558.91	33.2971
1562.01	35.2342
1565.1	36.5895
1568.2	39.0942
1571.29	40.4774
1574.38	41.5104
1577.48	43.0139
1580.57	45.3378
1583.65	46.7848
1586.74	48.7446
1589.83	50.5022
1592.92	51.1463
1596	52.9667
1599.08	54.0646
1602.16	53.2284
1605.24	52.5482
1608.32	52.3388
1611.4	53.1404
1614.48	53.5548
1617.56	54.0355
1620.63	54.9289
1623.71	54.718
1626.78	55.2421
1629.85	56.0363
1632.92	57.497
1635.99	59.4146
1639.06	61.2623
1642.12	62.3024
1645.19	61.7765
1648.25	63.5421
1651.32	65.0823
1654.38	66.5593
1657.44	66.8575
1660.5	66.539
1663.56	66.4705
1666.62	64.8608
1669.67	61.7018
1672.73	58.7617
1675.79	55.2593
1678.84	50.8515
1681.89	47.1746
1684.94	42.6413
1687.99	38.586
1691.04	33.7231
1694.08	29.9436
1697.13	26.6685
1700.18	23.2194
1703.22	19.6543
1706.26	17.483
1709.3	15.478
1712.35	14.2438
1715.39	12.3393
1718.42	9.90977
1721.46	9.98505
1724.5	10.337
1727.53	9.69938
1730.56	9.95928
1733.6	9.15159
1736.63	7.88808
1739.66	6.87469
1742.69	5.65917
1745.71	4.54903
1748.74	3.88663
1751.77	3.95613
1754.79	2.91155
1757.81	2.34682
1760.84	2.65329
1763.86	2.72805
1766.88	2.26319
1769.9	2.41392
1772.91	2.58364
1775.93	3.21728
1778.95	3.95288
1781.96	5.52167
1784.97	7.00644
1787.99	7.66757
1791	8.27057
1794.01	8.99625
1797.01	9.73703
1800.02	9.73071
1803.03	9.82193
1806.03	9.22282
1809.04	9.13987
1812.04	8.92101
1815.04	8.73644
1818.04	8.01451
1821.04	8.48046
1824.04	9.46094
1827.04	9.23725
1830.03	8.79522
1833.03	8.27278
1836.02	8.26119
1839.02	8.35861
1842.01	8.53708
1845	8.53941
1847.99	7.86449
1850.98	7.58785
1853.96	7.93603
1856.95	7.51739
1859.94	6.85461
1862.92	6.81087
1865.9	6.99718
1868.88	6.51156
1871.86	6.85039
1874.84	7.18835
1877.82	6.53638
1880.8	6.50514
1882.58	6.56159
1885.57	6.76915
1888.56	6.94337
1891.54	7.51229
1894.53	8.82772
1897.51	8.96719
1900.5	9.34209
1903.48	10.0027
1906.46	9.9328
1909.44	11.4602
1912.42	11.0265
1915.4	10.8661
1918.37	9.81042
1921.35	9.74565
1924.32	9.66692
1927.3	9.84868
1930.27	9.25021
1933.24	8.36993
1936.21	8.46142
1939.18	7.00532
1942.15	5.69698
1945.11	4.87295
1948.08	3.04172
1951.04	2.14827
1954.01	1.54541
1956.97	1.78416
1959.93	1.42063
1962.89	2.00215
1965.85	2.70331
1968.81	3.58504
1971.77	3.37305
1974.72	4.15748
1977.68	4.25842
1980.63	5.94142
1983.58	6.77335
1986.53	7.5643
1989.48	8.53123
1992.43	8.41197
1995.38	8.69666
1998.33	8.81528
2001.27	8.77245
2004.22	9.1741
2007.16	9.8186
2010.11	10.3905
2013.05	9.72163
2015.99	9.24666
2018.93	8.89984
2021.87	9.36028
2024.8	9.14587
2027.74	9.423
2030.68	9.42914
2033.61	10.1975
2036.54	10.0462
2039.48	10.5085
2042.41	9.94815
2045.34	9.00239
2048.27	9.41218
2051.19	9.79381
2054.12	8.51579
2057.05	8.79608
2059.97	8.88731
2062.9	8.3615
2065.82	8.45957
2068.74	9.03746
2071.66	9.41942
2074.58	9.92071
2077.5	10.6091
2080.41	9.91919
2083.33	10.0092
2086.24	10.1931
2089.16	10.1885
2092.07	10.765
2094.98	10.8489
2097.89	10.9405
2100.8	12.9386
2103.71	13.7079
2106.62	14.8417
2109.53	14.5939
2112.43	14.8736
2115.33	15.5507
2118.24	16.6708
2121.14	17.9446
2124.04	19.1476
2126.94	20.3739
2129.84	22.0191
2132.74	23.504
2135.63	24.874
2138.53	26.8401
2141.43	29.0551
2144.32	30.4469
2147.21	31.9865
2150.1	32.9571
2152.99	34.1382
2155.88	36.8184
2158.77	37.6543
2161.66	39.6969
2164.55	41.1701
2167.43	42.4565
2170.31	43.8323
2173.2	44.3308
2176.08	44.2407
2178.96	43.5874
2181.84	44.2999
2184.72	44.4273
2187.6	43.4475
2190.47	43.0348
2193.35	41.4683
2196.23	40.029
2199.1	38.2553
2201.97	36.8801
2204.84	35.6693
2207.71	34.3886
2210.58	32.7184
2213.45	29.9612
2216.32	27.7656
2219.19	26.0227
2222.05	24.2294
2224.92	22.8842
2227.78	21.2167
2230.64	18.6839
2233.5	17.0503
2236.36	15.4104
2239.22	13.8139
2242.08	12.4969
2244.94	11.2212
2247.79	10.8957
2250.65	11.1278
2253.5	11.1142
2256.36	10.3207
2259.21	9.79281
2262.06	10.0818
2264.91	9.68515
2267.76	9.43121
2270.6	9.16454
2273.45	9.00111
2276.3	8.28683
2279.14	7.99462
2281.98	7.414
2284.83	7.83837
2287.67	7.48704
2290.51	7.11223
2293.35	5.47878
2296.19	5.67386
2299.02	6.44508
2301.86	7.22059
2304.7	8.67884
2307.53	9.6395
2310.36	10.7076
2313.2	10.8559
2316.03	11.2547
2318.86	11.5988
2321.69	11.5517
2324.51	10.5573
2327.34	10.2321
2330.17	8.63165
2332.99	8.42611
2335.82	7.31141
2338.64	5.76629
2341.46	4.85233
2344.28	3.95964
2347.1	3.80162
2349.92	2.78575
2352.74	2.14048
2355.56	1.99931
2358.37	0.477753
2361.19	0.358473
2364	0.922562
2366.82	2.77142
2369.63	2.36405
2372.44	2.58788
2375.25	2.77487
2378.06	2.98823
2380.86	2.55554
2383.67	2.39303
2386.48	2.81547
2389.28	3.05236
2392.09	1.46251
2394.89	1.28367
2397.69	1.96972
2400.49	1.26827
2403.29	1.54087
2406.09	1.05751
2408.89	1.64771
2411.69	1.54358
2414.48	2.00773
2417.28	1.84491
2420.07	1.81724
2422.86	2.25652
2425.65	1.60353
2428.45	1.07594
2431.23	1.74975
2434.02	2.66885
2436.81	2.83435
2439.6	3.0517
2442.38	4.06323
2445.17	4.44921
2447.95	4.82791
2450.73	3.76913
2453.52	4.43779
2456.3	4.27766
2459.08	3.93551
2461.85	3.51662
2464.63	3.91742
2467.41	3.13947
2470.19	3.13193
2472.96	2.82066
2475.73	2.98531
2478.51	2.95982
2481.28	2.77932
2484.05	2.2258
2486.82	1.83463
2489.59	1.5918
2492.35	0.591763
2495.12	0.98119
2497.89	1.83836
2500.65	2.81579
2503.42	2.96802
2506.18	2.58044
2508.94	2.34667
2511.7	2.21095
2514.46	1.76912
2517.22	1.43595
2519.98	1.50729
2522.73	1.91861
2525.49	2.0509
2528.25	2.47028
2531	2.35429
2533.75	2.07397
2536.5	2.63099
2539.25	2.8763
2542.01	2.92039
2544.75	2.97379
2547.5	3.28464
2550.25	3.59784
2553	3.63368
2555.74	4.08375
2558.49	3.9777
2561.23	4.44169
2563.97	5.89092
2566.71	6.46935
2569.45	7.00842
2572.19	6.38105
2574.93	5.94341
2577.67	6.31301
2580.4	6.08366
2583.14	6.55464
2585.87	6.53561
2588.6	6.01839
2591.34	5.91184
2594.07	6.38735
2596.8	6.30566
2599.53	5.79886
2602.26	5.59158
2604.98	5.92878
2607.71	6.40905
2610.44	5.25746
2613.16	5.68875
2615.88	5.95255
2618.61	5.35956
2621.33	5.25423
2624.05	4.62686
2626.77	3.90867
2629.49	4.67671
2632.21	4.03916
2634.92	3.55781
2637.64	2.29369
2640.35	1.4042
2643.07	2.04786
2645.78	1.64611
2648.49	0.814583
2651.2	1.29466
2653.91	1.78256
2656.62	2.22387
2659.33	3.34166
2662.04	4.31236
2664.74	4.71224
2667.45	5.3832
2670.15	6.56897
2672.86	7.96844
2675.56	7.76392
2678.26	8.18035
2680.96	8.93648
2683.66	9.3357
2686.36	9.4944
2689.06	8.88507
2691.75	7.80196
2694.45	7.8507
2697.14	7.24713
2699.84	7.8656
2702.53	7.93284
2705.22	7.54055
2707.91	6.66137
2710.6	6.91346
2713.29	6.54093
2715.98	6.86187
2718.67	7.16349
2721.35	7.363
2724.04	7.87719
2726.72	7.90535
2729.4	7.56483
2732.09	7.02156
2734.77	6.92232
2737.45	6.33185
2740.13	5.88018
2742.81	5.93235
2745.48	5.65985
2748.16	4.86324
2750.84	4.09756
2753.51	3.94667
2756.19	2.74602
2758.86	2.59106
2761.53	2.92481
2764.2	2.73341
2766.87	3.17571
2769.54	2.32524
2772.21	2.07018
2774.88	1.52365
2777.54	2.14038
2780.21	2.91406
2782.87	2.85067
2785.53	2.99178
2788.2	3.06452
2790.86	2.36777
2793.52	1.4109
2796.18	1.13559
2798.84	1.51148
2801.49	0.617888
2804.15	-0.443801
2806.81	-0.31465
2809.46	-0.607037
2812.12	-0.825155
2814.77	-0.920314
2817.42	0.795373
2820.07	1.9659
2822.72	3.67475
2825.37	7.86489
2828.02	11.6232
2830.67	15.5983
2833.31	19.7056
2835.96	23.8687
2838.61	29.1656
2841.25	34.9238
2843.89	41.5386
2846.53	48.3278
2849.17	55.3706
2851.81	62.9415
2854.45	70.5019
2857.09	78.9238
2859.73	86.8262
2862.36	94.1205
2865	101.519
2867.64	107.751
2870.27	113.645
2872.9	119.464
2875.53	125.332
2878.16	131.621
2880.79	136.885
2883.42	141.862
2886.05	145.395
2888.68	150.731
2891.3	156.803
2893.93	161.647
2896.55	167.287
2899.18	172.273
2901.8	178.705
2904.42	186.541
2907.04	194.995
2909.66	203.837
2912.28	214.054
2914.9	223.656
2917.51	233.118
2920.13	241.939
2922.74	248.88
2925.36	254.01
2927.97	256.453
2930.59	257.656
2933.2	256.903
2935.81	253.711
2938.42	248.558
2941.02	241.835
2943.63	231.835
2946.24	220.68
2948.85	208.693
2951.45	198.292
2954.05	187.377
2956.66	177.317
2959.26	167.93
2961.86	158.431
2964.46	149.085
2967.06	142.045
2969.66	137.115
2972.26	132.015
2974.85	128.26
2977.45	124.014
2980.05	118.932
2982.64	113.869
2985.23	108.054
2987.83	101.9
2990.42	95.9578
2993.01	89.6932
2995.6	82.4998
2998.19	75.045
3000.77	67.0663
3003.36	58.6711
3005.95	50.4706
3008.53	43.5239
3011.12	37.0563
3013.7	31.5973
3016.28	25.7098
3018.86	20.361
3021.44	16.351
3024.02	12.3362
3026.6	8.80387
3029.18	6.86622
3031.76	5.97369
3034.33	5.03194
3036.91	4.26465
3039.48	3.95684
3042.05	3.94529
3044.63	4.71435
3047.2	5.27042
3049.77	6.84967
3052.34	7.23027
3054.91	7.76518
3057.48	8.11359
3060.04	7.54508
3062.61	7.55688
3065.17	7.39424
3067.74	6.89269
3070.3	6.94094
3072.87	6.78077
3075.43	5.91341
3077.99	4.84493
3080.55	3.91362
3083.11	3.37372
3085.67	2.14863
3088.22	1.75865
3090.78	0.971284
3093.34	0.706929
3095.89	0.923163
3098.44	0.969393
3101	2.15657
3103.55	3.15336
3106.1	4.12972
3108.65	5.42002
3111.2	5.19988
3113.75	5.46789
3116.3	6.17076
3118.84	7.21534
3121.39	7.92291
3123.93	9.13977
3126.48	10.2601
3129.02	11.5087
3131.56	13.0972
3134.1	14.967
3136.64	16.9048
3139.18	18.6091
3141.72	19.7302
3144.26	21.2247
3146.8	23.3119
3149.33	26.3101