File: data/Raman/poly_smoothed/Mbcal_20_25_30_1x_45s_532 nm_x100_100%_600 gr_mm_02.txt
#Acq. time (s)=	45
#Accumulations=	2
#Range (cm-¹)=	200...3150
#Windows=	2
#Auto scanning=	Off
#Autofocus=	Off
#Macrospot=	Off
#AutoExposure=	Off
#Spike filter=	Multiple accum.
#Delay time (s)=	0
#Binning=	1
#Readout mode=	Signal
#DeNoise=	Off
#ICS correction=	On
#Dark correction=	Off
#Inst. Process=	Off
#Detector Gain=	Best Dynamic Range
#Detector ADC=	20 kHz
#Detector temperature (°C)=	-69.85
#Instrument=	LabRAM HR Evol
#Detector=	Synapse
#Objective=	x100
#Grating=	600 gr/mm
#ND Filter=	100%
#Laser (nm)=	532
#Hole=	100.021
#Range=	Auto
#Laser Pol.=	No
#Raman. Pol.=	No
#Laser Pol. (°)=	-0.0007625
#Raman Pol. (°)=	89.9995
#Collection=	Microscope
#StageXY=	Marzhauser
#StageZ=	Marzhauser
#X (µm)=	-1141.3
#Y (µm)=	1296.8
#Z (µm)=	578
#Full time(mm:ss)=	3:18
#Project=
#Sample=
#Site=
#Title=	Mbcal_20_25_30_2x_45s_532 nm_x100_100%_600 gr_mm
#Remark=
#Date=	18.07.2022 11:59
#Acquired=	18.07.2022 11:59:01
#Base:Fit=	10.08.2022 10:55:08
#Base:Sub=	10.08.2022 10:55:14
#Filter:Polynom=	16.08.2022 10:07:28
#AxisType[0]=Intens
#AxisUnit[0]=Cnt
#AxisType[1]=Spectr
#AxisUnit[1]=1/cm
200.419	-2.54694
204.048	-0.711314
207.678	0.778817
211.304	1.40215
214.928	2.71025
218.554	4.82264
222.176	6.26827
225.798	8.1032
229.417	10.5078
233.035	11.0249
236.653	12.7484
240.268	13.4114
243.881	12.7437
247.493	13.6815
251.103	14.7162
254.715	15.2596
258.322	16.1616
261.929	17.2102
265.534	17.1706
269.137	17.9805
272.739	17.013
276.34	15.7794
279.939	15.777
283.537	13.825
287.134	12.7725
290.729	12.6421
294.323	11.9991
297.913	11.9061
301.504	12.9605
305.093	14.1615
308.682	15.0913
312.268	16.7152
315.852	17.4244
319.436	16.9691
323.018	16.5591
326.597	17.3041
330.177	15.7803
333.753	16.4376
337.331	17.8774
340.906	18.5929
344.478	18.9304
348.051	19.8205
351.621	20.7595
355.189	19.6586
358.757	18.8329
362.323	15.2696
365.889	14.509
369.451	12.9297
373.012	11.3665
376.574	11.6385
380.133	10.0342
383.69	10.4828
387.245	9.0161
390.8	8.09913
394.353	7.06404
397.906	7.73775
401.456	5.80712
405.005	4.53343
408.552	3.44364
412.099	3.51734
415.643	4.58208
419.187	4.66445
422.728	5.3542
426.269	5.29002
429.806	5.6666
433.344	7.29354
436.881	8.01974
440.416	8.10993
443.949	6.67865
447.48	6.09464
451.011	6.86217
454.541	7.93605
458.069	7.43999
461.594	7.1711
465.119	8.98496
468.642	10.1839
472.165	10.1127
475.684	10.3975
479.204	11.3062
482.721	11.0125
486.239	11.852
489.753	11.7907
493.268	11.8939
496.779	12.6995
500.289	12.9757
503.8	13.5774
507.307	13.2248
510.813	12.9168
514.32	15.4181
517.823	17.2992
521.325	16.7072
524.826	15.9346
528.325	16.2548
531.823	16.5723
535.32	16.6833
538.815	17.8253
542.309	18.0973
545.802	16.9058
549.293	16.816
552.783	16.9196
556.271	15.4247
559.759	12.8821
563.245	11.409
566.729	9.87356
570.213	7.40687
573.693	6.77299
577.173	5.20111
580.652	4.37424
584.13	3.72841
587.605	2.59815
591.08	2.31495
594.552	2.53553
598.025	3.83689
601.496	3.79687
604.964	4.5139
608.433	5.33617
611.898	6.39504
615.364	7.9393
618.827	7.99517
622.288	9.07238
625.75	10.3592
629.209	8.64357
632.667	10.0925
636.125	10.56
639.58	10.7355
643.033	10.568
646.485	11.0051
649.936	12.3612
653.388	12.3422
656.836	14.8715
660.283	16.0664
663.728	17.0772
667.173	17.2787
670.616	17.7826
674.057	18.9673
677.498	19.1477
680.937	20.4711
684.375	21.2409
687.809	22.1258
691.244	22.7174
694.678	23.5204
698.111	24.8408
701.54	23.5531
704.97	23.6919
708.398	24.9051
711.826	24.549
715.25	24.5969
718.675	25.934
722.096	26.887
725.518	27.8072
728.937	30.2042
732.357	32.3955
735.773	35.0224
739.19	37.1474
742.604	39.3957
746.018	41.9404
749.429	44.5416
752.839	46.5303
756.248	49.7592
759.657	53.2829
763.063	55.815
766.468	58.1021
769.871	60.6411
773.273	63.585
776.676	65.9591
780.075	66.8128
783.474	68.1231
786.871	68.2298
790.266	69.2195
793.661	70.4752
797.054	70.0193
800.446	70.5928
803.834	71.373
807.224	72.731
810.612	73.9634
813.998	74.679
817.384	74.3987
820.766	72.8852
824.149	73.1541
827.531	73.1792
830.909	74.3133
834.288	75.991
837.666	77.2061
841.041	78.5117
844.416	77.7003
847.788	77.7606
851.161	76.8683
854.53	75.5768
857.901	73.2056
861.268	71.4959
864.633	69.5583
868	67.7721
871.363	66.1707
874.725	63.9952
878.088	62.1519
881.447	59.4336
884.805	57.9036
888.162	56.6895
891.518	55.1129
894.872	52.9675
898.225	50.8005
901.577	49.1272
904.928	49.1184
908.277	49.5163
911.625	51.3352
914.972	52.4899
918.318	52.6706
921.662	53.6752
925.005	53.4629
928.347	52.7401
931.686	52.0068
935.025	50.5844
938.363	49.7737
941.698	49.1388
945.034	48.0154
948.368	47.4787
951.699	45.7315
955.031	45.5584
958.36	43.2971
961.689	41.2683
965.016	40.8979
968.343	39.8297
971.666	40.0373
974.991	39.8129
978.312	40.1494
981.632	38.8256
984.953	38.2362
988.27	38.0489
991.587	38.2311
994.902	38.2772
998.216	36.5371
1001.53	35.8223
1004.84	34.417
1008.15	33.6364
1011.46	33.0699
1014.77	32.6485
1018.07	32.2138
1021.38	31.4861
1024.68	30.5495
1027.99	30.3568
1031.29	31.0181
1034.59	31.2823
1037.89	31.6133
1041.18	31.3608
1044.48	32.6104
1047.77	33.1342
1051.07	32.2125
1054.36	32.1989
1057.65	32.6738
1060.94	31.0148
1064.23	29.3738
1067.52	29.5101
1070.8	29.615
1074.09	29.5096
1077.37	28.7964
1080.65	27.4471
1083.93	25.8597
1087.21	25.5147
1090.49	25.2914
1093.77	26.3538
1097.04	26.2253
1100.32	26.8371
1103.59	25.6131
1106.86	26.9867
1110.13	27.5369
1113.4	27.2095
1116.67	26.384
1119.94	25.0368
1123.2	23.3761
1126.47	20.7917
1129.73	19.546
1132.99	18.9834
1136.25	18.9587
1139.51	19.5923
1142.77	18.0267
1146.03	17.5652
1149.28	17.0235
1152.54	16.635
1155.79	13.7104
1159.04	10.6455
1162.29	8.90131
1165.54	7.96207
1168.79	8.19255
1172.04	9.23077
1175.28	9.75781
1178.53	9.81366
1181.77	9.96525
1185.01	9.48707
1188.25	8.73772
1191.49	7.75516
1194.73	8.74077
1197.96	8.99145
1201.2	11.5857
1204.43	13.3879
1207.66	16.8616
1210.9	19.5874
1214.13	21.543
1217.36	24.5445
1220.58	26.795
1223.81	28.0415
1227.04	30.3958
1230.26	32.6128
1233.48	34.1165
1236.71	35.0025
1239.93	37.6981
1243.14	40.2021
1246.36	42.1788
1249.58	44.5689
1252.8	46.0491
1256.01	47.5728
1259.22	49.6976
1262.43	50.85
1265.64	52.5784
1268.85	54.1768
1272.06	55.2348
1275.27	56.9408
1278.48	57.9938
1281.68	60.5909
1284.88	61.7167
1288.08	62.4389
1291.28	64.0447
1294.48	65.4834
1297.68	66.86
1300.88	68.3373
1304.07	70.7569
1307.27	72.4501
1310.46	73.8591
1313.65	75.0152
1316.85	75.7792
1320.03	76.9483
1323.22	76.391
1326.41	75.709
1329.6	75.1957
1332.78	75.6049
1335.96	74.1658
1339.15	74.0307
1342.33	70.8694
1345.51	69.0109
1348.69	66.3591
1351.86	63.4813
1355.04	60.7307
1358.21	57.411
1361.39	55.4273
1364.56	54.3872
1367.73	52.6155
1370.9	50.95
1374.07	49.5297
1377.24	47.6657
1380.41	49.0558
1383.57	49.087
1386.73	48.17
1389.9	48.2304
1393.06	47.4723
1396.22	47.38
1399.38	47.2268
1402.54	47.6104
1405.69	49.6155
1408.85	50.2535
1412	51.6383
1415.16	54.0618
1418.31	55.26
1421.46	58.4452
1424.61	63.6067
1427.76	66.9071
1430.9	71.2006
1434.05	74.1912
1437.2	77.6654
1440.34	80.7912
1443.48	82.5572
1446.62	82.9274
1449.76	83.1792
1452.9	82.9539
1456.04	82.402
1459.17	81.8046
1462.31	79.653
1465.44	78.2216
1468.58	73.6093
1471.71	70.7896
1474.84	68.5869
1477.97	64.7449
1481.1	60.3186
1484.22	56.5306
1487.35	51.589
1490.47	48.6544
1493.59	45.6351
1496.72	42.4746
1499.84	40.7099
1502.96	38.3719
1506.08	34.7979
1509.19	32.3079
1512.31	28.1529
1515.42	25.5531
1518.54	23.4922
1521.65	21.0024
1524.76	19.5816
1527.87	19.933
1530.98	19.2032
1534.09	19.3951
1537.2	20.9469
1540.3	22.3217
1543.41	24.3176
1546.51	27.8511
1549.61	31.6955
1552.71	34.2268
1555.81	35.431
1558.91	38.3289
1562.01	41.7002
1565.1	44.2583
1568.2	46.7366
1571.29	48.0883
1574.38	50.513
1577.48	52.1491
1580.57	54.8556
1583.65	55.7317
1586.74	55.9563
1589.83	55.4758
1592.92	56.5646
1596	56.0155
1599.08	54.8385
1602.16	54.9869
1605.24	53.0855
1608.32	52.1168
1611.4	51.5011
1614.48	51.225
1617.56	50.7038
1620.63	50.9563
1623.71	50.5243
1626.78	51.0057
1629.85	52.5369
1632.92	53.1828
1635.99	54.9081
1639.06	56.9856
1642.12	58.2501
1645.19	60.737
1648.25	62.4717
1651.32	64.3021
1654.38	64.9459
1657.44	65.144
1660.5	63.9714
1663.56	63.087
1666.62	62.1189
1669.67	59.6314
1672.73	55.7099
1675.79	52.211
1678.84	47.7303
1681.89	43.8294
1684.94	39.38
1687.99	34.2392
1691.04	28.9858
1694.08	24.5286
1697.13	20.1037
1700.18	16.8958
1703.22	14.3714
1706.26	11.6649
1709.3	8.6156
1712.35	6.12085
1715.39	5.1618
1718.42	4.87064
1721.46	3.33225
1724.5	3.00226
1727.53	2.71817
1730.56	3.25145
1733.6	2.69175
1736.63	2.86848
1739.66	3.55081
1742.69	3.0031
1745.71	3.30359
1748.74	2.83418
1751.77	3.84143
1754.79	3.34122
1757.81	3.36395
1760.84	3.23807
1763.86	2.76366
1766.88	2.53047
1769.9	2.963
1772.91	2.42906
1775.93	2.47953
1778.95	2.09472
1781.96	2.15224
1784.97	2.5277
1787.99	3.19456
1791	3.09598
1794.01	2.92785
1797.01	3.72583
1800.02	4.26204
1803.03	3.46085
1806.03	3.74954
1809.04	4.32686
1812.04	4.55364
1815.04	4.07221
1818.04	3.44944
1821.04	3.12663
1824.04	2.89106
1827.04	2.89734
1830.03	1.69277
1833.03	1.24914
1836.02	1.97013
1839.02	1.49294
1842.01	2.26741
1845	2.15022
1847.99	2.15524
1850.98	2.76483
1853.96	2.35467
1856.95	3.10299
1859.94	3.54118
1862.92	3.51929
1865.9	2.84012
1868.88	3.42375
1871.86	3.08773
1874.84	3.15336
1877.82	3.42585
1880.8	3.50286
1882.58	3.42372
1885.57	3.41441
1888.56	2.73595
1891.54	2.08362
1894.53	2.15049
1897.51	2.09602
1900.5	1.91091
1903.48	1.95209
1906.46	3.16751
1909.44	3.50223
1912.42	3.97192
1915.4	4.33115
1918.37	3.73623
1921.35	3.4297
1924.32	3.19557
1927.3	4.00979
1930.27	4.2703
1933.24	3.67263
1936.21	3.87272
1939.18	3.49689
1942.15	3.90886
1945.11	3.81616
1948.08	3.50403
1951.04	3.71273
1954.01	3.55537
1956.97	3.52293
1959.93	4.19137
1962.89	4.4754
1965.85	4.49077
1968.81	4.45242
1971.77	3.95779
1974.72	4.80986
1977.68	4.87716
1980.63	5.7344
1983.58	5.21123
1986.53	5.1802
1989.48	5.74036
1992.43	5.5017
1995.38	5.1875
1998.33	5.5403
2001.27	5.5647
2004.22	5.25463
2007.16	4.36698
2010.11	4.10855
2013.05	4.27225
2015.99	3.1888
2018.93	3.75722
2021.87	3.77771
2024.8	3.89437
2027.74	3.59397
2030.68	3.03949
2033.61	3.06833
2036.54	2.90229
2039.48	2.87983
2042.41	2.69213
2045.34	3.75371
2048.27	4.13553
2051.19	4.95528
2054.12	5.15561
2057.05	5.52498
2059.97	6.20047
2062.9	6.78401
2065.82	6.78495
2068.74	6.76231
2071.66	7.42403
2074.58	7.38677
2077.5	7.26768
2080.41	7.05245
2083.33	8.16484
2086.24	8.5553
2089.16	8.27234
2092.07	8.86223
2094.98	8.93099
2097.89	9.99449
2100.8	10.2976
2103.71	10.9732
2106.62	12.0642
2109.53	12.428
2112.43	13.2867
2115.33	14.0473
2118.24	15.0149
2121.14	16.7324
2124.04	18.0318
2126.94	20.1862
2129.84	21.9034
2132.74	24.9405
2135.63	28.0684
2138.53	30.0378
2141.43	32.3085
2144.32	34.4959
2147.21	36.2522
2150.1	38.8837
2152.99	41.2836
2155.88	42.4758
2158.77	43.799
2161.66	45.9813
2164.55	47.6361
2167.43	49.7367
2170.31	50.3178
2173.2	50.1608
2176.08	49.7235
2178.96	49.715
2181.84	49.3626
2184.72	47.5783
2187.6	46.1353
2190.47	44.5786
2193.35	42.4913
2196.23	39.9076
2199.1	38.6711
2201.97	37.0876
2204.84	35.0848
2207.71	32.2509
2210.58	29.776
2213.45	27.9263
2216.32	26.0199
2219.19	24.084
2222.05	21.8235
2224.92	19.8203
2227.78	17.993
2230.64	16.6007
2233.5	16.6171
2236.36	15.6092
2239.22	14.7361
2242.08	14.3597
2244.94	13.9046
2247.79	13.5408
2250.65	13.8951
2253.5	11.5191
2256.36	10.6143
2259.21	9.39796
2262.06	8.83391
2264.91	7.86152
2267.76	7.88251
2270.6	7.64964
2273.45	7.45922
2276.3	7.14512
2279.14	6.81215
2281.98	7.14497
2284.83	7.09701
2287.67	6.54126
2290.51	5.76999
2293.35	4.68818
2296.19	5.19673
2299.02	6.40479
2301.86	7.76616
2304.7	9.24494
2307.53	9.19016
2310.36	10.434
2313.2	11.1016
2316.03	11.3954
2318.86	10.6979
2321.69	10.3393
2324.51	9.8781
2327.34	9.75583
2330.17	9.30343
2332.99	9.49281
2335.82	7.88763
2338.64	7.55332
2341.46	6.90509
2344.28	5.92605
2347.1	4.53187
2349.92	3.60623
2352.74	3.33101
2355.56	2.25823
2358.37	1.97844
2361.19	1.78964
2364	2.26106
2366.82	3.03167
2369.63	2.62653
2372.44	2.48534
2375.25	2.8916
2378.06	2.74761
2380.86	2.78643
2383.67	2.28065
2386.48	1.80374
2389.28	1.96266
2392.09	2.39055
2394.89	2.62281
2397.69	2.80798
2400.49	2.15238
2403.29	1.94318
2406.09	1.05193
2408.89	0.812127
2411.69	1.36095
2414.48	1.09735
2417.28	1.60313
2420.07	2.26408
2422.86	2.45545
2425.65	2.70749
2428.45	2.69615
2431.23	2.88972
2434.02	3.48556
2436.81	3.18993
2439.6	2.95807
2442.38	3.21511
2445.17	2.64527
2447.95	2.1834
2450.73	2.28702
2453.52	2.71867
2456.3	2.38689
2459.08	2.5179
2461.85	1.98553
2464.63	1.74289
2467.41	1.26019
2470.19	0.456584
2472.96	0.773867
2475.73	0.282568
2478.51	0.287953
2481.28	0.496401
2484.05	0.0185313
2486.82	-0.0345886
2489.59	0.256026
2492.35	0.412231
2495.12	0.944984
2497.89	1.00431
2500.65	1.5455
2503.42	1.78183
2506.18	1.98644
2508.94	2.63405
2511.7	2.59914
2514.46	2.90876
2517.22	3.88188
2519.98	3.52946
2522.73	3.04268
2525.49	2.61514
2528.25	2.99051
2531	2.94413
2533.75	2.97654
2536.5	3.99774
2539.25	3.48828
2542.01	3.19909
2544.75	3.09104
2547.5	2.09203
2550.25	3.25381
2553	3.5704
2555.74	3.79902
2558.49	4.36198
2561.23	4.09242
2563.97	4.04512
2566.71	3.66711
2569.45	3.62848
2572.19	3.59038
2574.93	3.36365
2577.67	3.73879
2580.4	2.97374
2583.14	2.9675
2585.87	2.22793
2588.6	1.97671
2591.34	2.42261
2594.07	2.53211
2596.8	2.5163
2599.53	2.46764
2602.26	2.33593
2604.98	2.57574
2607.71	2.40013
2610.44	2.36062
2613.16	2.15662
2615.88	2.09678
2618.61	2.9095
2621.33	2.71252
2624.05	3.14061
2626.77	2.70466
2629.49	2.00369
2632.21	2.10414
2634.92	1.70539
2637.64	2.00528
2640.35	2.989
2643.07	3.23864
2645.78	2.72381
2648.49	3.4478
2651.2	4.10641
2653.91	3.963
2656.62	4.43259
2659.33	4.93759
2662.04	5.64401
2664.74	6.78049
2667.45	7.18888
2670.15	7.74414
2672.86	8.39908
2675.56	8.78284
2678.26	9.44724
2680.96	9.27337
2683.66	9.15681
2686.36	9.58476
2689.06	10.1863
2691.75	9.76003
2694.45	9.19871
2697.14	9.50672
2699.84	10.0154
2702.53	10.8577
2705.22	11.1906
2707.91	11.1224
2710.6	10.8673
2713.29	10.6685
2715.98	10.7392
2718.67	10.6277
2721.35	10.919
2724.04	10.7798
2726.72	11.5165
2729.4	10.5594
2732.09	9.61872
2734.77	8.90973
2737.45	8.57817
2740.13	7.49677
2742.81	6.74907
2745.48	5.01761
2748.16	4.18739
2750.84	2.89513
2753.51	2.2238
2756.19	1.79064
2758.86	0.697965
2761.53	-0.0488332
2764.2	0.341458
2766.87	-0.238093
2769.54	0.170632
2772.21	0.234539
2774.88	0.744914
2777.54	0.568497
2780.21	0.916849
2782.87	1.51259
2785.53	1.77077
2788.2	2.14508
2790.86	1.91774
2793.52	1.5291
2796.18	1.15398
2798.84	0.812055
2801.49	1.24972
2804.15	0.470533
2806.81	0.917588
2809.46	-0.00902967
2812.12	-0.470418
2814.77	0.100869
2817.42	0.991938
2820.07	3.10075
2822.72	4.38152
2825.37	7.60998
2828.02	11.8274
2830.67	16.2377
2833.31	21.1989
2835.96	26.0119
2838.61	31.8323
2841.25	38.0899
2843.89	45.5266
2846.53	53.0866
2849.17	60.1574
2851.81	69.0653
2854.45	77.7686
2857.09	86.4343
2859.73	95.3599
2862.36	104.812
2865	112.318
2867.64	118.799
2870.27	124.799
2872.9	131.475
2875.53	136.036
2878.16	140.103
2880.79	144.502
2883.42	148.863
2886.05	153.253
2888.68	157.602
2891.3	163.105
2893.93	167.774
2896.55	174.195
2899.18	179.945
2901.8	186.91
2904.42	194.63
2907.04	202.5
2909.66	212.277
2912.28	223.536
2914.9	234.79
2917.51	245.701
2920.13	255.363
2922.74	263.045
2925.36	269.517
2927.97	273.974
2930.59	274.68
2933.2	274.193
2935.81	271.756
2938.42	266.097
2941.02	258.064
2943.63	248.51
2946.24	238.856
2948.85	227.971
2951.45	216.609
2954.05	204.269
2956.66	191.881
2959.26	180.214
2961.86	169.413
2964.46	157.527
2967.06	147.213
2969.66	138.99
2972.26	132.827
2974.85	126.135
2977.45	120.04
2980.05	112.355
2982.64	105.68
2985.23	98.5694
2987.83	91.462
2990.42	84.4423
2993.01	77.5004
2995.6	69.2313
2998.19	62.4503
3000.77	54.7002
3003.36	47.3796
3005.95	40.124
3008.53	34.0029
3011.12	28.5126
3013.7	23.5808
3016.28	18.5414
3018.86	14.6935
3021.44	11.8823
3024.02	9.2868
3026.6	7.55604
3029.18	5.94999
3031.76	6.25558
3034.33	6.3862
3036.91	6.51545
3039.48	6.88482
3042.05	7.67487
3044.63	8.42596
3047.2	8.82894
3049.77	8.53363
3052.34	8.77309
3054.91	9.75841
3057.48	9.85701
3060.04	9.48579
3062.61	9.19489
3065.17	8.38386
3067.74	7.01753
3070.3	6.53445
3072.87	5.86168
3075.43	5.01407
3077.99	4.73872
3080.55	3.595
3083.11	1.86152
3085.67	0.677942
3088.22	0.38878
3090.78	0.422753
3093.34	0.192408
3095.89	0.274169
3098.44	1.30171
3101	2.33495
3103.55	3.34301
3106.1	4.30906
3108.65	4.76908
3111.2	5.31795
3113.75	6.01156
3116.3	7.26247
3118.84	8.74825
3121.39	9.38313
3123.93	10.4106
3126.48	11.1671
3129.02	12.2589
3131.56	12.9433
3134.1	13.7751
3136.64	14.5093
3139.18	15.2049
3141.72	15.6356
3144.26	16.8249
3146.8	18.7664
3149.33	21.7278