File: data/Raman/poly_smoothed/Mbcal_20_25_40_1x_45s_532 nm_x100_100%_600 gr_mm_01.txt
#Acq. time (s)=	45
#Accumulations=	2
#Range (cm-¹)=	200...3150
#Windows=	2
#Auto scanning=	Off
#Autofocus=	Off
#Macrospot=	Off
#AutoExposure=	Off
#Spike filter=	Multiple accum.
#Delay time (s)=	0
#Binning=	1
#Readout mode=	Signal
#DeNoise=	Off
#ICS correction=	On
#Dark correction=	Off
#Inst. Process=	Off
#Detector Gain=	Best Dynamic Range
#Detector ADC=	20 kHz
#Detector temperature (°C)=	-69.85
#Instrument=	LabRAM HR Evol
#Detector=	Synapse
#Objective=	x100
#Grating=	600 gr/mm
#ND Filter=	100%
#Laser (nm)=	532
#Hole=	100.021
#Range=	Auto
#Laser Pol.=	No
#Raman. Pol.=	No
#Laser Pol. (°)=	-0.0007625
#Raman Pol. (°)=	89.9995
#Collection=	Microscope
#StageXY=	Marzhauser
#StageZ=	Marzhauser
#X (µm)=	-1125.5
#Y (µm)=	1267.7
#Z (µm)=	578.25
#Full time(mm:ss)=	3:18
#Project=
#Sample=
#Site=
#Title=	Mbcal_20_25_40_2x_45s_532 nm_x100_100%_600 gr_mm
#Remark=
#Date=	18.07.2022 13:14
#Acquired=	18.07.2022 13:14:40
#Base:Fit=	10.08.2022 10:55:08
#Base:Sub=	10.08.2022 10:55:14
#Filter:Polynom=	16.08.2022 10:07:28
#AxisType[0]=Intens
#AxisUnit[0]=Cnt
#AxisType[1]=Spectr
#AxisUnit[1]=1/cm
200.419	4.99629
204.048	5.91235
207.678	5.89563
211.304	5.89083
214.928	8.09537
218.554	7.85732
222.176	6.00766
225.798	6.40025
229.417	5.96504
233.035	5.66478
236.653	5.61483
240.268	5.96102
243.881	6.24256
247.493	6.57816
251.103	6.97398
254.715	7.25147
258.322	8.80762
261.929	9.39752
265.534	11.1985
269.137	11.2346
272.739	11.4584
276.34	11.9491
279.939	12.8196
283.537	12.2591
287.134	12.6391
290.729	12.1917
294.323	13.8242
297.913	14.509
301.504	16.1758
305.093	15.7166
308.682	14.8045
312.268	16.3643
315.852	16.7214
319.436	15.2926
323.018	15.8984
326.597	15.4973
330.177	14.234
333.753	14.1293
337.331	13.8458
340.906	13.4627
344.478	11.9355
348.051	11.4712
351.621	10.7579
355.189	9.01563
358.757	9.39204
362.323	7.10849
365.889	7.44788
369.451	8.04955
373.012	7.02743
376.574	7.69552
380.133	8.10521
383.69	10.4418
387.245	11.5589
390.8	11.2911
394.353	11.5492
397.906	11.4873
401.456	11.8729
405.005	11.0953
408.552	10.8061
412.099	10.8265
415.643	10.6952
419.187	10.7638
422.728	11.4075
426.269	9.80317
429.806	9.15887
433.344	7.19995
436.881	8.77195
440.416	6.04103
443.949	4.76453
447.48	4.11473
451.011	3.51351
454.541	4.59996
458.069	5.39804
461.594	5.13499
465.119	7.35561
468.642	7.67273
472.165	8.36245
475.684	7.07941
479.204	7.68693
482.721	9.84991
486.239	11.3404
489.753	13.0764
493.268	15.3754
496.779	17.1311
500.289	19.5779
503.8	21.5417
507.307	21.9843
510.813	22.8712
514.32	23.0796
517.823	26.6638
521.325	26.6627
524.826	26.7446
528.325	26.3999
531.823	26.7062
535.32	27.2349
538.815	28.5327
542.309	30.1976
545.802	30.0828
549.293	29.1701
552.783	27.0671
556.271	25.1558
559.759	24.2979
563.245	21.5491
566.729	19.6801
570.213	18.4455
573.693	16.2415
577.173	14.697
580.652	12.3188
584.13	11.0426
587.605	8.34759
591.08	6.54366
594.552	5.39923
598.025	4.39809
601.496	3.56617
604.964	2.58579
608.433	2.4598
611.898	3.92352
615.364	4.45778
618.827	4.58959
622.288	6.15679
625.75	8.05235
629.209	9.02974
632.667	9.30986
636.125	11.0001
639.58	12.7563
643.033	14.4627
646.485	15.4316
649.936	18.4231
653.388	20.0856
656.836	22.2508
660.283	23.6042
663.728	25.8603
667.173	27.0802
670.616	27.8581
674.057	27.941
677.498	30.2857
680.937	32.1354
684.375	31.5406
687.809	33.7845
691.244	35.4591
694.678	37.3359
698.111	37.9494
701.54	38.0286
704.97	38.8293
708.398	41.2382
711.826	42.1925
715.25	42.5932
718.675	43.054
722.096	44.3779
725.518	42.869
728.937	43.9163
732.357	43.1463
735.773	44.4715
739.19	45.3165
742.604	44.9413
746.018	48.3257
749.429	51.3894
752.839	55.3982
756.248	59.304
759.657	63.6908
763.063	67.0168
766.468	68.6701
769.871	73.3399
773.273	78.0746
776.676	81.0106
780.075	83.8182
783.474	88.2396
786.871	88.8926
790.266	90.1072
793.661	92.1714
797.054	92.8911
800.446	90.3263
803.834	89.9291
807.224	89.7691
810.612	86.9924
813.998	83.6834
817.384	82.9367
820.766	81.507
824.149	80.239
827.531	81.5354
830.909	83.3667
834.288	84.29
837.666	85.6553
841.041	87.1161
844.416	87.9488
847.788	89.7322
851.161	90.5032
854.53	91.8535
857.901	90.99
861.268	90.3743
864.633	89.7929
868	88.7957
871.363	88.0024
874.725	87.0661
878.088	84.6835
881.447	82.0899
884.805	79.6974
888.162	77.0545
891.518	73.322
894.872	69.8597
898.225	66.9334
901.577	65.1079
904.928	63.4027
908.277	62.1386
911.625	61.1731
914.972	61.5469
918.318	60.4387
921.662	61.4077
925.005	60.57
928.347	60.2525
931.686	58.3965
935.025	57.4107
938.363	58.1397
941.698	56.6586
945.034	55.5208
948.368	55.4526
951.699	54.7921
955.031	52.8389
958.36	52.7182
961.689	50.9623
965.016	49.8077
968.343	49.4589
971.666	48.4893
974.991	48.1092
978.312	46.9394
981.632	47.1131
984.953	47.814
988.27	45.8771
991.587	45.5446
994.902	45.2663
998.216	42.7975
1001.53	42.0011
1004.84	39.0906
1008.15	37.4683
1011.46	35.911
1014.77	36.202
1018.07	37.7085
1021.38	37.3809
1024.68	36.4333
1027.99	37.1571
1031.29	37.5849
1034.59	39.1861
1037.89	38.8651
1041.18	38.6793
1044.48	37.5613
1047.77	39.6313
1051.07	39.6859
1054.36	38.152
1057.65	37.6294
1060.94	38.0018
1064.23	37.6704
1067.52	37.1285
1070.8	37.5884
1074.09	36.6949
1077.37	34.723
1080.65	34.0394
1083.93	33.0751
1087.21	31.7595
1090.49	32.507
1093.77	34.0189
1097.04	36.0243
1100.32	37.8794
1103.59	39.0762
1106.86	39.7659
1110.13	40.2444
1113.4	40.1305
1116.67	39.4528
1119.94	37.5295
1123.2	35.9387
1126.47	35.8712
1129.73	32.8891
1132.99	30.2494
1136.25	30.1927
1139.51	26.9477
1142.77	24.0576
1146.03	21.2447
1149.28	17.5828
1152.54	14.9027
1155.79	10.7981
1159.04	9.02757
1162.29	7.68312
1165.54	5.58751
1168.79	5.93395
1172.04	5.55884
1175.28	6.76513
1178.53	8.28708
1181.77	8.15485
1185.01	9.38445
1188.25	10.8179
1191.49	11.639
1194.73	14.1433
1197.96	16.626
1201.2	18.2624
1204.43	21.7595
1207.66	23.5027
1210.9	24.321
1214.13	28.1374
1217.36	29.4108
1220.58	31.456
1223.81	33.3214
1227.04	35.1027
1230.26	36.4765
1233.48	39.0474
1236.71	41.87
1239.93	45.2639
1243.14	47.746
1246.36	49.3553
1249.58	51.0907
1252.8	53.9639
1256.01	55.6414
1259.22	56.2893
1262.43	57.9633
1265.64	59.5555
1268.85	61.1953
1272.06	61.7103
1275.27	63.3187
1278.48	65.5847
1281.68	67.7979
1284.88	69.7305
1288.08	72.1469
1291.28	72.8131
1294.48	74.1203
1297.68	75.792
1300.88	75.4089
1304.07	75.402
1307.27	75.8252
1310.46	76.6489
1313.65	78.3579
1316.85	79.753
1320.03	79.9292
1323.22	79.839
1326.41	79.2674
1329.6	79.5736
1332.78	78.4563
1335.96	76.3988
1339.15	74.8673
1342.33	74.8077
1345.51	72.6405
1348.69	71.8972
1351.86	70.1548
1355.04	69.4956
1358.21	68.5456
1361.39	66.2518
1364.56	63.9204
1367.73	59.9216
1370.9	57.395
1374.07	54.5467
1377.24	53.1608
1380.41	51.5277
1383.57	50.6156
1386.73	49.7158
1389.9	48.5343
1393.06	49.0035
1396.22	47.5458
1399.38	47.284
1402.54	49.6843
1405.69	52.1515
1408.85	53.8703
1412	56.4936
1415.16	60.6649
1418.31	64.5491
1421.46	69.6986
1424.61	74.6454
1427.76	80.5709
1430.9	85.7511
1434.05	89.4252
1437.2	91.7584
1440.34	93.634
1443.48	94.8015
1446.62	95.6477
1449.76	94.8052
1452.9	94.5702
1456.04	92.6033
1459.17	89.3297
1462.31	85.8403
1465.44	81.89
1468.58	76.7835
1471.71	70.5149
1474.84	65.4742
1477.97	61.8734
1481.1	57.2491
1484.22	51.681
1487.35	46.2425
1490.47	42.6176
1493.59	39.1265
1496.72	35.8376
1499.84	32.72
1502.96	31.2903
1506.08	27.1702
1509.19	22.6848
1512.31	18.7024
1515.42	15.591
1518.54	14.6064
1521.65	13.4235
1524.76	11.5144
1527.87	11.551
1530.98	11.2033
1534.09	10.4747
1537.2	11.1655
1540.3	11.9948
1543.41	13.0072
1546.51	15.3967
1549.61	18.8406
1552.71	23.0096
1555.81	25.8387
1558.91	27.3292
1562.01	29.8272
1565.1	30.9538
1568.2	33.3266
1571.29	34.9735
1574.38	37.3277
1577.48	38.9116
1580.57	39.4551
1583.65	39.4851
1586.74	41.4726
1589.83	43.6763
1592.92	45.0666
1596	45.4567
1599.08	45.0145
1602.16	45.0131
1605.24	45.3829
1608.32	44.2488
1611.4	42.8531
1614.48	43.5426
1617.56	44.7277
1620.63	45.8165
1623.71	48.6435
1626.78	49.5024
1629.85	50.4313
1632.92	51.2782
1635.99	51.9641
1639.06	52.8244
1642.12	54.7831
1645.19	55.802
1648.25	57.332
1651.32	59.3207
1654.38	59.3606
1657.44	60.4479
1660.5	60.5891
1663.56	60.4722
1666.62	59.4105
1669.67	57.4202
1672.73	54.1643
1675.79	50.1078
1678.84	46.7634
1681.89	42.5817
1684.94	38.0353
1687.99	32.9822
1691.04	28.5964
1694.08	25.3861
1697.13	21.4518
1700.18	16.9171
1703.22	13.8025
1706.26	11.6671
1709.3	9.10645
1712.35	8.19337
1715.39	7.5623
1718.42	6.11594
1721.46	4.69317
1724.5	4.88062
1727.53	4.4825
1730.56	5.0738
1733.6	4.65983
1736.63	5.35776
1739.66	5.82797
1742.69	5.63083
1745.71	4.88803
1748.74	4.23591
1751.77	5.3037
1754.79	4.99659
1757.81	3.87581
1760.84	3.41481
1763.86	2.91699
1766.88	2.59829
1769.9	2.04819
1772.91	1.04368
1775.93	1.1858
1778.95	1.75401
1781.96	1.70183
1784.97	1.88512
1787.99	1.69729
1791	0.675899
1794.01	0.589305
1797.01	0.668319
1800.02	1.37855
1803.03	1.14277
1806.03	0.505083
1809.04	1.16849
1812.04	1.21639
1815.04	1.82134
1818.04	2.10197
1821.04	2.6279
1824.04	2.62864
1827.04	2.72922
1830.03	3.02475
1833.03	3.52471
1836.02	3.39473
1839.02	3.45251
1842.01	3.59831
1845	3.06557
1847.99	2.88987
1850.98	3.33225
1853.96	3.58296
1856.95	4.09308
1859.94	4.65569
1862.92	4.34706
1865.9	4.30489
1868.88	4.01335
1871.86	3.12924
1874.84	2.64352
1877.82	2.71721
1880.8	2.66262
1882.58	2.39818
1885.57	1.84392
1888.56	2.40493
1891.54	2.31801
1894.53	1.86008
1897.51	2.23921
1900.5	1.6445
1903.48	1.75634
1906.46	1.77481
1909.44	2.08532
1912.42	1.97084
1915.4	2.78327
1918.37	3.79962
1921.35	4.16878
1924.32	5.13863
1927.3	5.09289
1930.27	4.91106
1933.24	4.75015
1936.21	3.87866
1939.18	3.1051
1942.15	1.97768
1945.11	1.70843
1948.08	3.00246
1951.04	3.33656
1954.01	2.89074
1956.97	4.31633
1959.93	4.17312
1962.89	4.31646
1965.85	3.28403
1968.81	2.93971
1971.77	3.6554
1974.72	3.81814
1977.68	3.41589
1980.63	3.39496
1983.58	3.98503
1986.53	3.95109
1989.48	4.81424
1992.43	4.96484
1995.38	4.25926
1998.33	4.1296
2001.27	4.10056
2004.22	4.03482
2007.16	3.46093
2010.11	3.3815
2013.05	3.92184
2015.99	4.13094
2018.93	5.18963
2021.87	5.9766
2024.8	6.94078
2027.74	6.93207
2030.68	6.54076
2033.61	6.34856
2036.54	6.59738
2039.48	7.09653
2042.41	7.38613
2045.34	8.2097
2048.27	8.03556
2051.19	7.87329
2054.12	8.06383
2057.05	8.73983
2059.97	8.49725
2062.9	9.22391
2065.82	9.05887
2068.74	9.74448
2071.66	10.4992
2074.58	10.3236
2077.5	11.6471
2080.41	12.0494
2083.33	12.2432
2086.24	13.3211
2089.16	13.5407
2092.07	13.8613
2094.98	15.7512
2097.89	15.8587
2100.8	16.3833
2103.71	17.735
2106.62	19.7364
2109.53	21.7106
2112.43	22.6645
2115.33	23.5928
2118.24	23.9493
2121.14	25.8341
2124.04	26.4787
2126.94	28.2299
2129.84	30.4543
2132.74	32.2308
2135.63	33.5481
2138.53	35.4543
2141.43	38.2914
2144.32	39.7993
2147.21	42.7498
2150.1	44.8023
2152.99	47.6121
2155.88	50.0191
2158.77	52.3606
2161.66	54.4074
2164.55	56.1974
2167.43	57.422
2170.31	58.814
2173.2	59.4813
2176.08	59.5503
2178.96	58.7783
2181.84	58.1207
2184.72	56.6319
2187.6	54.1507
2190.47	52.5758
2193.35	50.8578
2196.23	49.196
2199.1	46.6791
2201.97	44.2748
2204.84	40.8495
2207.71	37.6164
2210.58	35.7058
2213.45	33.6563
2216.32	31.1477
2219.19	29.3774
2222.05	27.8001
2224.92	26.4195
2227.78	24.6276
2230.64	23.5778
2233.5	22.0264
2236.36	21.0897
2239.22	19.5796
2242.08	18.6046
2244.94	17.2852
2247.79	17.1606
2250.65	16.3421
2253.5	16.7049
2256.36	16.4909
2259.21	17.0137
2262.06	18.0534
2264.91	18.2771
2267.76	18.1611
2270.6	16.2171
2273.45	15.8702
2276.3	16.0066
2279.14	15.8431
2281.98	15.4808
2284.83	15.0463
2287.67	13.7713
2290.51	12.4282
2293.35	10.9635
2296.19	10.3086
2299.02	9.58453
2301.86	9.47574
2304.7	9.02979
2307.53	9.18201
2310.36	9.69714
2313.2	10.555
2316.03	10.6177
2318.86	11.922
2321.69	12.2487
2324.51	12.8177
2327.34	12.9747
2330.17	13.1928
2332.99	11.8809
2335.82	10.9451
2338.64	10.0655
2341.46	9.49017
2344.28	8.46622
2347.1	7.6423
2349.92	6.97394
2352.74	6.15882
2355.56	5.18659
2358.37	3.52799
2361.19	1.87306
2364	1.70768
2366.82	2.02594
2369.63	1.70697
2372.44	1.87201
2375.25	2.38745
2378.06	3.21056
2380.86	3.6861
2383.67	3.77519
2386.48	4.72427
2389.28	4.9267
2392.09	4.58338
2394.89	3.97545
2397.69	4.59325
2400.49	4.16853
2403.29	4.38853
2406.09	4.16236
2408.89	4.15313
2411.69	4.41618
2414.48	4.27612
2417.28	4.58222
2420.07	5.15645
2422.86	5.70934
2425.65	5.44562
2428.45	6.00386
2431.23	5.75284
2434.02	5.36291
2436.81	5.19397
2439.6	5.60167
2442.38	5.49206
2445.17	4.45163
2447.95	4.56083
2450.73	4.66789
2453.52	4.51342
2456.3	3.85974
2459.08	2.59526
2461.85	2.9909
2464.63	2.87207
2467.41	2.53701
2470.19	2.22898
2472.96	2.32319
2475.73	2.93906
2478.51	3.42535
2481.28	4.20986
2484.05	3.74625
2486.82	3.31562
2489.59	3.37464
2492.35	3.37674
2495.12	3.30908
2497.89	3.55023
2500.65	2.87041
2503.42	3.79229
2506.18	3.12624
2508.94	3.32569
2511.7	2.95233
2514.46	3.01388
2517.22	2.41198
2519.98	2.78212
2522.73	2.60219
2525.49	1.94517
2528.25	2.30316
2531	2.66204
2533.75	2.39278
2536.5	2.22986
2539.25	3.17428
2542.01	3.61153
2544.75	3.18539
2547.5	2.47609
2550.25	1.32814
2553	0.409245
2555.74	-0.480352
2558.49	-0.145256
2561.23	0.310577
2563.97	0.960426
2566.71	1.56886
2569.45	1.7303
2572.19	2.71025
2574.93	2.99605
2577.67	2.93783
2580.4	3.01925
2583.14	2.64065
2585.87	3.49765
2588.6	3.81115
2591.34	3.39623
2594.07	3.17338
2596.8	4.03912
2599.53	4.65357
2602.26	4.41432
2604.98	4.22887
2607.71	4.87407
2610.44	3.04817
2613.16	2.44611
2615.88	1.97919
2618.61	1.87777
2621.33	1.83231
2624.05	2.48058
2626.77	2.8356
2629.49	3.55573
2632.21	3.42738
2634.92	3.44863
2637.64	4.14499
2640.35	4.33752
2643.07	3.92855
2645.78	3.86911
2648.49	3.3368
2651.2	3.02171
2653.91	2.67255
2656.62	2.40225
2659.33	2.65615
2662.04	3.57254
2664.74	3.61242
2667.45	3.59161
2670.15	3.00765
2672.86	2.99329
2675.56	2.35292
2678.26	2.01555
2680.96	3.09575
2683.66	3.90416
2686.36	4.24609
2689.06	4.581
2691.75	4.63037
2694.45	4.99488
2697.14	4.93991
2699.84	5.31707
2702.53	5.74613
2705.22	6.34299
2707.91	6.74629
2710.6	7.21338
2713.29	6.69664
2715.98	6.82977
2718.67	7.20394
2721.35	7.94162
2724.04	8.98995
2726.72	8.51468
2729.4	8.13077
2732.09	7.97607
2734.77	7.40384
2737.45	6.94061
2740.13	5.86303
2742.81	6.39411
2745.48	6.52138
2748.16	6.79763
2750.84	5.93396
2753.51	4.90691
2756.19	4.24769
2758.86	3.60038
2761.53	3.33812
2764.2	2.31097
2766.87	3.19298
2769.54	2.69764
2772.21	2.77772
2774.88	2.37933
2777.54	1.52151
2780.21	1.54363
2782.87	1.8693
2785.53	2.30533
2788.2	2.19313
2790.86	0.548577
2793.52	-0.0823047
2796.18	-0.228033
2798.84	-0.122145
2801.49	-0.944222
2804.15	-0.460224
2806.81	-1.05102
2809.46	-1.10933
2812.12	-0.666576
2814.77	0.0518189
2817.42	1.93329
2820.07	3.89744
2822.72	6.95722
2825.37	11.3098
2828.02	16.5442
2830.67	21.672
2833.31	26.8537
2835.96	32.303
2838.61	38.7573
2841.25	46.3076
2843.89	53.9743
2846.53	62.1288
2849.17	71.5711
2851.81	80.6855
2854.45	89.6043
2857.09	98.9021
2859.73	108.24
2862.36	115.821
2865	123.978
2867.64	130.796
2870.27	137.394
2872.9	143.825
2875.53	149.553
2878.16	154.443
2880.79	159.305
2883.42	163.914
2886.05	168.17
2888.68	171.362
2891.3	175.216
2893.93	178.534
2896.55	181.296
2899.18	185.492
2901.8	191.593
2904.42	199.18
2907.04	207.921
2909.66	217.151
2912.28	225.728
2914.9	235.97
2917.51	244.289
2920.13	252.563
2922.74	259.35
2925.36	264.019
2927.97	268.051
2930.59	269.404
2933.2	270.032
2935.81	267.63
2938.42	264.306
2941.02	257.77
2943.63	249.465
2946.24	240.844
2948.85	231.248
2951.45	220.416
2954.05	208.742
2956.66	197.396
2959.26	185.817
2961.86	175.138
2964.46	165.985
2967.06	158.163
2969.66	150.03
2972.26	141.727
2974.85	133.461
2977.45	125.778
2980.05	118.692
2982.64	111.793
2985.23	103.357
2987.83	95.5006
2990.42	87.9288
2993.01	80.0314
2995.6	72.9156
2998.19	65.3693
3000.77	57.6201
3003.36	50.2565
3005.95	43.858
3008.53	37.7672
3011.12	31.8535
3013.7	26.6214
3016.28	21.741
3018.86	17.9076
3021.44	14.9511
3024.02	11.6266
3026.6	10.4811
3029.18	8.59225
3031.76	7.59965
3034.33	6.75855
3036.91	6.65199
3039.48	7.00277
3042.05	8.2438
3044.63	8.73584
3047.2	9.43942
3049.77	10.4607
3052.34	11.1244
3054.91	11.5708
3057.48	11.8346
3060.04	11.0414
3062.61	9.96941
3065.17	9.4472
3067.74	9.67965
3070.3	8.86315
3072.87	8.41333
3075.43	7.46233
3077.99	6.95327
3080.55	6.2483
3083.11	5.70217
3085.67	4.42897
3088.22	3.19968
3090.78	1.97011
3093.34	1.11143
3095.89	1.31777
3098.44	1.45687
3101	1.93019
3103.55	1.1224
3106.1	1.73395
3108.65	2.71716
3111.2	3.5192
3113.75	3.97994
3116.3	4.75595
3118.84	4.91104
3121.39	5.46977
3123.93	6.23836
3126.48	7.91515
3129.02	9.23147
3131.56	10.972
3134.1	12.5317
3136.64	13.7679
3139.18	14.9293
3141.72	15.6186
3144.26	15.9494
3146.8	16.2468
3149.33	17.5903