File: data/Raman/poly_smoothed/Mbcal_20_25_05_1x_45s_532 nm_x100_100%_600 gr_mm_01.txt
#Acq. time (s)=	45
#Accumulations=	2
#Range (cm-¹)=	200...3150
#Windows=	2
#Auto scanning=	Off
#Autofocus=	Off
#Macrospot=	Off
#AutoExposure=	Off
#Spike filter=	Multiple accum.
#Delay time (s)=	0
#Binning=	1
#Readout mode=	Signal
#DeNoise=	Off
#ICS correction=	On
#Dark correction=	Off
#Inst. Process=	Off
#Detector Gain=	Best Dynamic Range
#Detector ADC=	20 kHz
#Detector temperature (°C)=	-69.85
#Instrument=	LabRAM HR Evol
#Detector=	Synapse
#Objective=	x100
#Grating=	600 gr/mm
#ND Filter=	100%
#Laser (nm)=	532
#Hole=	100.021
#Range=	Auto
#Laser Pol.=	No
#Raman. Pol.=	No
#Laser Pol. (°)=	-0.0007625
#Raman Pol. (°)=	89.9995
#Collection=	Microscope
#StageXY=	Marzhauser
#StageZ=	Marzhauser
#X (µm)=	-1202.3
#Y (µm)=	1255.6
#Z (µm)=	577.85
#Full time(mm:ss)=	3:18
#Project=
#Sample=
#Site=
#Title=	Mbcal_20_25_05_2x_45s_532 nm_x100_100%_600 gr_mm
#Remark=
#Date=	18.07.2022 09:45
#Acquired=	18.07.2022 09:45:21
#Base:Fit=	10.08.2022 10:55:08
#Base:Sub=	10.08.2022 10:55:14
#Filter:Polynom=	16.08.2022 10:07:27
#AxisType[0]=Intens
#AxisUnit[0]=Cnt
#AxisType[1]=Spectr
#AxisUnit[1]=1/cm
200.419	4.15146
204.048	3.22361
207.678	2.67485
211.304	1.88163
214.928	1.63822
218.554	2.48353
222.176	0.569907
225.798	1.58593
229.417	3.2142
233.035	4.46692
236.653	4.619
240.268	5.2239
243.881	6.57816
247.493	7.18245
251.103	8.38465
254.715	10.6215
258.322	11.3766
261.929	11.419
265.534	13.188
269.137	12.3972
272.739	13.074
276.34	12.8765
279.939	11.9009
283.537	11.2163
287.134	10.4059
290.729	10.9086
294.323	9.24231
297.913	9.04907
301.504	12.1577
305.093	12.0439
308.682	11.9569
312.268	13.3833
315.852	15.8759
319.436	16.975
323.018	17.7949
326.597	18.419
330.177	19.4111
333.753	20.0414
337.331	20.4351
340.906	21.2864
344.478	20.4117
348.051	18.8107
351.621	16.3312
355.189	14.5283
358.757	13.2284
362.323	11.5403
365.889	9.34394
369.451	7.38795
373.012	6.0986
376.574	6.31993
380.133	6.14335
383.69	5.68542
387.245	6.39201
390.8	5.59975
394.353	4.25595
397.906	4.4312
401.456	5.50118
405.005	7.00287
408.552	7.60876
412.099	7.66868
415.643	7.33154
419.187	6.98118
422.728	7.19849
426.269	7.08202
429.806	6.68292
433.344	6.48838
436.881	6.99591
440.416	7.03982
443.949	7.18241
447.48	8.98081
451.011	9.34894
454.541	9.16956
458.069	10.5131
461.594	11.3748
465.119	11.6729
468.642	11.4544
472.165	12.2459
475.684	11.9816
479.204	10.5969
482.721	12.1109
486.239	13.355
489.753	14.2411
493.268	12.3673
496.779	12.1415
500.289	11.9604
503.8	13.3381
507.307	12.9943
510.813	14.4772
514.32	16.6627
517.823	17.715
521.325	18.8215
524.826	19.411
528.325	19.3642
531.823	18.2582
535.32	18.0547
538.815	18.8038
542.309	19.498
545.802	19.4351
549.293	19.1722
552.783	18.4121
556.271	18.5657
559.759	16.6352
563.245	14.6141
566.729	14.056
570.213	13.3278
573.693	10.9759
577.173	7.8213
580.652	6.364
584.13	5.4446
587.605	5.04135
591.08	4.35216
594.552	3.66462
598.025	4.82341
601.496	5.12748
604.964	5.80219
608.433	6.71166
611.898	7.7572
615.364	8.33284
618.827	8.15615
622.288	9.19985
625.75	10.1589
629.209	11.1815
632.667	12.4353
636.125	14.7705
639.58	14.91
643.033	15.8654
646.485	16.4797
649.936	17.1754
653.388	18.9185
656.836	19.7743
660.283	20.5362
663.728	20.0599
667.173	19.9279
670.616	21.6341
674.057	21.8787
677.498	21.2717
680.937	23.1932
684.375	23.5097
687.809	23.1653
691.244	24.7814
694.678	24.9832
698.111	24.5262
701.54	24.2465
704.97	24.2966
708.398	23.4465
711.826	24.7357
715.25	24.9076
718.675	26.8823
722.096	28.8106
725.518	28.8524
728.937	29.4138
732.357	31.1439
735.773	32.9241
739.19	34.4954
742.604	36.0035
746.018	36.8272
749.429	38.2741
752.839	40.7244
756.248	41.7266
759.657	43.9257
763.063	45.7586
766.468	47.2885
769.871	49.7091
773.273	51.7837
776.676	54.6297
780.075	56.1628
783.474	60.3557
786.871	62.4559
790.266	63.9258
793.661	67.2868
797.054	71.1499
800.446	74.1858
803.834	76.4074
807.224	76.539
810.612	76.406
813.998	76.7102
817.384	76.046
820.766	75.4093
824.149	75.1984
827.531	75.8948
830.909	74.94
834.288	74.5376
837.666	73.2107
841.041	70.6989
844.416	68.3535
847.788	64.9454
851.161	61.2791
854.53	59.1448
857.901	56.9142
861.268	54.3605
864.633	53.3891
868	51.9061
871.363	51.3006
874.725	49.9251
878.088	49.7016
881.447	47.8993
884.805	45.3925
888.162	44.1639
891.518	43.8526
894.872	41.6721
898.225	41.3358
901.577	42.8398
904.928	44.9418
908.277	46.144
911.625	46.7315
914.972	48.0695
918.318	46.1545
921.662	45.3665
925.005	42.9596
928.347	42.4796
931.686	40.7605
935.025	39.4494
938.363	37.6392
941.698	35.8159
945.034	35.689
948.368	33.794
951.699	32.2447
955.031	31.3818
958.36	28.7023
961.689	26.0614
965.016	25.9843
968.343	25.7831
971.666	25.7461
974.991	25.737
978.312	25.0664
981.632	24.0638
984.953	24.1465
988.27	23.0841
991.587	21.0896
994.902	19.8887
998.216	17.3313
1001.53	15.356
1004.84	14.3231
1008.15	12.0559
1011.46	11.7006
1014.77	9.53228
1018.07	9.81915
1021.38	9.30428
1024.68	8.77236
1027.99	9.90684
1031.29	10.399
1034.59	10.4159
1037.89	10.1966
1041.18	10.4883
1044.48	11.5155
1047.77	10.6383
1051.07	10.5383
1054.36	10.1411
1057.65	9.64581
1060.94	9.37481
1064.23	8.13923
1067.52	6.89553
1070.8	6.7267
1074.09	6.34169
1077.37	5.59245
1080.65	4.87866
1083.93	3.73399
1087.21	2.97264
1090.49	3.23029
1093.77	3.96693
1097.04	6.1422
1100.32	7.30094
1103.59	5.70602
1106.86	6.65473
1110.13	6.98036
1113.4	6.73078
1116.67	7.60014
1119.94	6.3465
1123.2	6.52396
1126.47	5.13135
1129.73	3.94879
1132.99	4.02097
1136.25	4.81005
1139.51	4.03991
1142.77	4.51686
1146.03	5.20472
1149.28	4.06085
1152.54	6.05267
1155.79	4.63586
1159.04	3.50898
1162.29	4.82518
1165.54	4.67518
1168.79	5.57198
1172.04	7.30208
1175.28	8.42544
1178.53	6.86791
1181.77	5.76971
1185.01	5.42502
1188.25	6.83571
1191.49	6.0187
1194.73	6.46433
1197.96	5.10907
1201.2	6.25347
1204.43	6.62254
1207.66	6.22358
1210.9	6.84887
1214.13	8.82743
1217.36	9.04603
1220.58	9.10653
1223.81	12.4705
1227.04	13.9845
1230.26	15.7173
1233.48	19.2861
1236.71	21.7196
1239.93	24.727
1243.14	26.1058
1246.36	26.6563
1249.58	28.4661
1252.8	28.6784
1256.01	28.4626
1259.22	27.9924
1262.43	28.9884
1265.64	30.5762
1268.85	29.2971
1272.06	30.454
1275.27	30.9446
1278.48	32.5288
1281.68	33.9677
1284.88	35.6448
1288.08	37.5142
1291.28	39.6215
1294.48	40.5727
1297.68	41.4601
1300.88	44.1689
1304.07	47.4122
1307.27	48.8966
1310.46	50.6878
1313.65	52.8041
1316.85	52.2095
1320.03	52.7289
1323.22	52.4981
1326.41	52.023
1329.6	52.0145
1332.78	51.4399
1335.96	51.8283
1339.15	50.5684
1342.33	49.4655
1345.51	48.6289
1348.69	48.873
1351.86	48.7772
1355.04	47.8547
1358.21	47.394
1361.39	47.2594
1364.56	46.8847
1367.73	45.3905
1370.9	44.2379
1374.07	43.5328
1377.24	42.1418
1380.41	41.6702
1383.57	40.3069
1386.73	39.1758
1389.9	38.1095
1393.06	37.1606
1396.22	36.7711
1399.38	37.5255
1402.54	37.7513
1405.69	39.1319
1408.85	40.6289
1412	40.5005
1415.16	42.7236
1418.31	45.726
1421.46	48.8501
1424.61	53.0889
1427.76	56.1885
1430.9	59.9423
1434.05	63.2503
1437.2	67.7431
1440.34	70.5418
1443.48	71.902
1446.62	72.7088
1449.76	72.9987
1452.9	71.6427
1456.04	71.6479
1459.17	72.2649
1462.31	70.9458
1465.44	69.4406
1468.58	67.9737
1471.71	63.8891
1474.84	60.4556
1477.97	57.6472
1481.1	54.9931
1484.22	50.7775
1487.35	47.2781
1490.47	43.755
1493.59	41.4682
1496.72	39.4612
1499.84	37.3623
1502.96	36.4534
1506.08	34.0118
1509.19	33.8303
1512.31	32.4956
1515.42	29.874
1518.54	28.464
1521.65	26.1458
1524.76	26.6349
1527.87	25.9972
1530.98	26.7606
1534.09	27.1671
1537.2	27.7714
1540.3	27.0329
1543.41	27.8678
1546.51	26.9208
1549.61	27.1098
1552.71	27.7818
1555.81	28.7212
1558.91	29.7218
1562.01	29.5964
1565.1	29.8413
1568.2	31.1499
1571.29	32.8804
1574.38	33.8582
1577.48	35.0713
1580.57	36.8314
1583.65	39.0586
1586.74	41.3444
1589.83	42.509
1592.92	44.6744
1596	47.9899
1599.08	49.0927
1602.16	49.726
1605.24	49.4937
1608.32	48.7827
1611.4	50.2423
1614.48	51.2544
1617.56	50.9503
1620.63	51.0033
1623.71	51.4706
1626.78	51.2566
1629.85	51.2861
1632.92	50.2683
1635.99	48.9269
1639.06	46.6352
1642.12	45.3064
1645.19	45.3993
1648.25	45.5583
1651.32	44.8261
1654.38	44.8135
1657.44	45.7507
1660.5	43.6671
1663.56	41.4135
1666.62	38.8345
1669.67	37.6557
1672.73	33.9595
1675.79	30.6655
1678.84	28.0157
1681.89	26.5741
1684.94	25.2331
1687.99	22.8461
1691.04	20.2492
1694.08	16.7835
1697.13	16.4684
1700.18	14.4537
1703.22	12.2173
1706.26	10.454
1709.3	9.04096
1712.35	6.98396
1715.39	6.90656
1718.42	6.19545
1721.46	6.63671
1724.5	6.28941
1727.53	5.91141
1730.56	6.37901
1733.6	5.78208
1736.63	5.34621
1739.66	5.99387
1742.69	6.72707
1745.71	6.44348
1748.74	5.05232
1751.77	5.35875
1754.79	6.00848
1757.81	5.98175
1760.84	5.01039
1763.86	5.12744
1766.88	5.48756
1769.9	6.19392
1772.91	5.72228
1775.93	4.0258
1778.95	4.30638
1781.96	3.74062
1784.97	1.95067
1787.99	1.50645
1791	1.04398
1794.01	0.39119
1797.01	-0.241272
1800.02	0.136449
1803.03	1.03894
1806.03	0.511044
1809.04	0.378465
1812.04	-0.0336452
1815.04	-0.905272
1818.04	-0.969039
1821.04	-0.472871
1824.04	-0.355302
1827.04	1.17378
1830.03	1.308
1833.03	2.44854
1836.02	2.84659
1839.02	4.03756
1842.01	5.22078
1845	5.94852
1847.99	6.42241
1850.98	7.77845
1853.96	7.66166
1856.95	7.68639
1859.94	8.57103
1862.92	8.69745
1865.9	7.37761
1868.88	6.46196
1871.86	6.2191
1874.84	6.09655
1877.82	5.1747
1880.8	4.95122
1882.58	4.43045
1885.57	3.84388
1888.56	3.78309
1891.54	3.65196
1894.53	3.05348
1897.51	3.33549
1900.5	3.00187
1903.48	3.47708
1906.46	2.58868
1909.44	2.64706
1912.42	3.06241
1915.4	3.44817
1918.37	3.23676
1921.35	3.4703
1924.32	2.97013
1927.3	3.71604
1930.27	4.9447
1933.24	3.73049
1936.21	3.59253
1939.18	3.93088
1942.15	4.28145
1945.11	4.10342
1948.08	3.74891
1951.04	3.81158
1954.01	5.34346
1956.97	5.90589
1959.93	6.31222
1962.89	5.66766
1965.85	5.31704
1968.81	5.56337
1971.77	5.47302
1974.72	5.20403
1977.68	4.8509
1980.63	4.09379
1983.58	4.80227
1986.53	4.62344
1989.48	5.29418
1992.43	6.44148
1995.38	7.53449
1998.33	8.47196
2001.27	7.78904
2004.22	6.43113
2007.16	5.98035
2010.11	6.4639
2013.05	5.96311
2015.99	5.77383
2018.93	6.5046
2021.87	7.87604
2024.8	8.17054
2027.74	8.7147
2030.68	8.15659
2033.61	8.72436
2036.54	7.59351
2039.48	6.71243
2042.41	6.51982
2045.34	5.37091
2048.27	5.21507
2051.19	4.84345
2054.12	5.24456
2057.05	6.36013
2059.97	6.09815
2062.9	6.14807
2065.82	6.48314
2068.74	7.08367
2071.66	5.91509
2074.58	5.25752
2077.5	5.26846
2080.41	6.21726
2083.33	5.93439
2086.24	6.42025
2089.16	8.45841
2092.07	8.38654
2094.98	8.56964
2097.89	9.8621
2100.8	10.685
2103.71	11.1004
2106.62	11.6668
2109.53	11.114
2112.43	11.0265
2115.33	11.0887
2118.24	12.4188
2121.14	13.6567
2124.04	15.1202
2126.94	16.185
2129.84	16.4935
2132.74	17.3572
2135.63	19.5973
2138.53	20.4661
2141.43	21.8324
2144.32	22.7474
2147.21	24.9744
2150.1	27.0675
2152.99	28.9368
2155.88	31.143
2158.77	33.6811
2161.66	34.8657
2164.55	36.1813
2167.43	38.6752
2170.31	39.5698
2173.2	39.8915
2176.08	39.5302
2178.96	39.1891
2181.84	39.1351
2184.72	38.5503
2187.6	38.063
2190.47	37.2023
2193.35	36.0363
2196.23	34.5372
2199.1	33.1823
2201.97	31.5863
2204.84	30.4378
2207.71	28.9365
2210.58	28.0362
2213.45	28.1331
2216.32	27.9069
2219.19	26.8716
2222.05	25.5305
2224.92	24.956
2227.78	24.5281
2230.64	22.8595
2233.5	22.8518
2236.36	22.2278
2239.22	21.395
2242.08	19.301
2244.94	18.5931
2247.79	16.509
2250.65	16.0173
2253.5	16.2866
2256.36	15.3499
2259.21	14.0861
2262.06	12.9953
2264.91	11.3293
2267.76	11.1956
2270.6	10.6572
2273.45	8.6951
2276.3	8.16142
2279.14	8.10401
2281.98	7.73584
2284.83	6.53141
2287.67	5.15848
2290.51	3.34941
2293.35	2.10258
2296.19	2.48081
2299.02	3.66974
2301.86	4.76548
2304.7	6.36634
2307.53	7.33951
2310.36	7.8336
2313.2	8.9831
2316.03	9.48543
2318.86	10.4673
2321.69	12.9255
2324.51	13.676
2327.34	12.4244
2330.17	11.8638
2332.99	11.8621
2335.82	11.1699
2338.64	10.6696
2341.46	8.66623
2344.28	7.82801
2347.1	6.76778
2349.92	5.91915
2352.74	3.81444
2355.56	2.53969
2358.37	1.67892
2361.19	0.666513
2364	0.917832
2366.82	1.40694
2369.63	2.04334
2372.44	2.60151
2375.25	2.74432
2378.06	2.37726
2380.86	2.68616
2383.67	3.38137
2386.48	3.80692
2389.28	4.70422
2392.09	5.19302
2394.89	5.30739
2397.69	5.3169
2400.49	5.65774
2403.29	5.6012
2406.09	6.22934
2408.89	6.96337
2411.69	7.56552
2414.48	8.79417
2417.28	8.91382
2420.07	9.07918
2422.86	10.1104
2425.65	10.0734
2428.45	9.98316
2431.23	9.29869
2434.02	9.2729
2436.81	9.22815
2439.6	9.22194
2442.38	8.85572
2445.17	7.67795
2447.95	6.57112
2450.73	5.89454
2453.52	5.42531
2456.3	5.0886
2459.08	3.99707
2461.85	3.71129
2464.63	2.25874
2467.41	1.40423
2470.19	0.641425
2472.96	0.56137
2475.73	0.357462
2478.51	-0.351066
2481.28	0.0265606
2484.05	0.796139
2486.82	0.800382
2489.59	1.56065
2492.35	1.38162
2495.12	1.32809
2497.89	1.8623
2500.65	2.14836
2503.42	2.20147
2506.18	2.26555
2508.94	2.38086
2511.7	1.59547
2514.46	2.19226
2517.22	2.86956
2519.98	3.86343
2522.73	4.63614
2525.49	5.04707
2528.25	4.64691
2531	4.64274
2533.75	4.17206
2536.5	4.61718
2539.25	5.1859
2542.01	4.82102
2544.75	4.71569
2547.5	4.56611
2550.25	4.47365
2553	4.03328
2555.74	3.63793
2558.49	3.41156
2561.23	3.4013
2563.97	3.40353
2566.71	4.09116
2569.45	4.61755
2572.19	4.05469
2574.93	3.80798
2577.67	4.24177
2580.4	4.91971
2583.14	5.7843
2585.87	5.31346
2588.6	5.88973
2591.34	6.03698
2594.07	6.37735
2596.8	6.49612
2599.53	7.12226
2602.26	7.02217
2604.98	7.09413
2607.71	6.78064
2610.44	6.01338
2613.16	5.44203
2615.88	5.41837
2618.61	4.26865
2621.33	4.26189
2624.05	4.31986
2626.77	3.52999
2629.49	3.44148
2632.21	2.89106
2634.92	3.68852
2637.64	3.46746
2640.35	3.45166
2643.07	3.72053
2645.78	3.55012
2648.49	3.65942
2651.2	3.5523
2653.91	3.94248
2656.62	4.6861
2659.33	5.87116
2662.04	6.74129
2664.74	6.84714
2667.45	7.00561
2670.15	6.1618
2672.86	7.23419
2675.56	7.57374
2678.26	7.25076
2680.96	6.9243
2683.66	5.92402
2686.36	5.35904
2689.06	4.62595
2691.75	4.86794
2694.45	4.51701
2697.14	5.02031
2699.84	6.14628
2702.53	7.04528
2705.22	8.32121
2707.91	8.9186
2710.6	9.48542
2713.29	10.0656
2715.98	10.2624
2718.67	11.1516
2721.35	10.7678
2724.04	11.0204
2726.72	11.1165
2729.4	10.1817
2732.09	9.65906
2734.77	8.90268
2737.45	8.66427
2740.13	7.84561
2742.81	6.28838
2745.48	5.73273
2748.16	4.35468
2750.84	3.38888
2753.51	3.14005
2756.19	2.34927
2758.86	2.75463
2761.53	1.84849
2764.2	1.92015
2766.87	1.59142
2769.54	1.50637
2772.21	1.59518
2774.88	1.00504
2777.54	1.35616
2780.21	0.156031
2782.87	0.745981
2785.53	0.0564828
2788.2	-0.45915
2790.86	0.805025
2793.52	1.63986
2796.18	1.0736
2798.84	1.38301
2801.49	0.881048
2804.15	1.07354
2806.81	0.62102
2809.46	0.4858
2812.12	-0.0219237
2814.77	-0.252599
2817.42	0.782905
2820.07	1.65108
2822.72	4.59215
2825.37	7.04116
2828.02	9.37424
2830.67	13.0021
2833.31	16.7536
2835.96	21.6192
2838.61	25.9755
2841.25	30.9672
2843.89	36.9691
2846.53	42.6224
2849.17	49.2635
2851.81	55.9774
2854.45	63.312
2857.09	70.5591
2859.73	76.6797
2862.36	82.1545
2865	87.8485
2867.64	92.7834
2870.27	96.5974
2872.9	101.146
2875.53	104.311
2878.16	108.039
2880.79	112.076
2883.42	116.375
2886.05	121.147
2888.68	125.274
2891.3	129.736
2893.93	133.88
2896.55	138.096
2899.18	142.758
2901.8	149.351
2904.42	154.766
2907.04	161.011
2909.66	167.383
2912.28	175.338
2914.9	184.249
2917.51	190.503
2920.13	197.808
2922.74	202.772
2925.36	207.354
2927.97	209.119
2930.59	209.397
2933.2	207.883
2935.81	205.295
2938.42	201.249
2941.02	195.707
2943.63	189.465
2946.24	182.057
2948.85	174.498
2951.45	165.065
2954.05	156.75
2956.66	148.193
2959.26	140.21
2961.86	133.902
2964.46	126.844
2967.06	119.931
2969.66	113.702
2972.26	109.432
2974.85	106.11
2977.45	102.076
2980.05	97.485
2982.64	92.6333
2985.23	87.3335
2987.83	81.2037
2990.42	76.0783
2993.01	69.6416
2995.6	63.0409
2998.19	56.876
3000.77	50.2864
3003.36	43.9061
3005.95	36.973
3008.53	31.5743
3011.12	25.6893
3013.7	20.7138
3016.28	16.8927
3018.86	14.485
3021.44	11.7148
3024.02	9.1461
3026.6	6.91971
3029.18	4.30638
3031.76	2.88174
3034.33	2.82097
3036.91	3.29499
3039.48	2.22623
3042.05	2.18521
3044.63	2.1066
3047.2	2.17498
3049.77	2.86758
3052.34	3.69009
3054.91	4.74238
3057.48	4.41351
3060.04	4.28569
3062.61	3.73859
3065.17	3.7332
3067.74	3.36902
3070.3	4.00501
3072.87	4.16344
3075.43	3.4632
3077.99	3.9903
3080.55	4.43881
3083.11	4.33502
3085.67	3.71034
3088.22	4.22765
3090.78	3.95485
3093.34	4.26344
3095.89	4.60459
3098.44	5.51837
3101	5.65285
3103.55	5.38162
3106.1	6.28341
3108.65	7.55347
3111.2	10.2005
3113.75	11.9656
3116.3	13.4876
3118.84	14.5885
3121.39	15.4506
3123.93	17.5408
3126.48	18.7902
3129.02	20.4001
3131.56	22.7286
3134.1	24.815
3136.64	26.7108
3139.18	28.8009
3141.72	30.981
3144.26	32.3161
3146.8	34.08
3149.33	33.9494