File: data/Raman/poly_smoothed/Mbcal_20_25_27_1x_45s_532 nm_x100_100%_600 gr_mm_01.txt
#Acq. time (s)=	45
#Accumulations=	2
#Range (cm-¹)=	200...3150
#Windows=	2
#Auto scanning=	Off
#Autofocus=	Off
#Macrospot=	Off
#AutoExposure=	Off
#Spike filter=	Multiple accum.
#Delay time (s)=	0
#Binning=	1
#Readout mode=	Signal
#DeNoise=	Off
#ICS correction=	On
#Dark correction=	Off
#Inst. Process=	Off
#Detector Gain=	Best Dynamic Range
#Detector ADC=	20 kHz
#Detector temperature (°C)=	-69.85
#Instrument=	LabRAM HR Evol
#Detector=	Synapse
#Objective=	x100
#Grating=	600 gr/mm
#ND Filter=	100%
#Laser (nm)=	532
#Hole=	100.021
#Range=	Auto
#Laser Pol.=	No
#Raman. Pol.=	No
#Laser Pol. (°)=	-0.0007625
#Raman Pol. (°)=	89.9995
#Collection=	Microscope
#StageXY=	Marzhauser
#StageZ=	Marzhauser
#X (µm)=	-1166.6
#Y (µm)=	1293.4
#Z (µm)=	578.45
#Full time(mm:ss)=	3:18
#Project=
#Sample=
#Site=
#Title=	Mbcal_20_25_27_2x_45s_532 nm_x100_100%_600 gr_mm
#Remark=
#Date=	18.07.2022 11:41
#Acquired=	18.07.2022 11:41:35
#Base:Fit=	10.08.2022 10:55:08
#Base:Sub=	10.08.2022 10:55:14
#Filter:Polynom=	16.08.2022 10:07:28
#AxisType[0]=Intens
#AxisUnit[0]=Cnt
#AxisType[1]=Spectr
#AxisUnit[1]=1/cm
200.419	19.5496
204.048	21.7562
207.678	18.6265
211.304	16.6233
214.928	15.6461
218.554	16.3044
222.176	14.9328
225.798	16.1702
229.417	13.5723
233.035	16.5012
236.653	17.3079
240.268	17.7401
243.881	18.8368
247.493	17.574
251.103	17.1866
254.715	18.4162
258.322	18.6768
261.929	20.009
265.534	20.9596
269.137	19.8463
272.739	17.655
276.34	17.2167
279.939	16.0868
283.537	11.9207
287.134	8.14927
290.729	8.15001
294.323	8.91767
297.913	9.67566
301.504	11.6352
305.093	13.7955
308.682	14.1172
312.268	16.8017
315.852	19.2816
319.436	21.8972
323.018	23.9597
326.597	25.1115
330.177	26.6365
333.753	28.8902
337.331	29.1863
340.906	30.3997
344.478	26.6569
348.051	25.5466
351.621	23.8011
355.189	20.6908
358.757	19.5442
362.323	17.6875
365.889	15.4413
369.451	14.3086
373.012	10.954
376.574	12.9377
380.133	13.0525
383.69	12.5043
387.245	12.1366
390.8	15.67
394.353	16.4527
397.906	15.9543
401.456	16.6553
405.005	16.9606
408.552	16.4165
412.099	14.9082
415.643	15.3364
419.187	15.109
422.728	12.2541
426.269	11.9668
429.806	11.2543
433.344	10.4825
436.881	10.1875
440.416	9.00246
443.949	8.68913
447.48	9.50356
451.011	9.31459
454.541	11.508
458.069	15.0125
461.594	14.8895
465.119	15.9014
468.642	16.7704
472.165	18.633
475.684	22.1619
479.204	25.3525
482.721	25.7713
486.239	29.2497
489.753	29.7982
493.268	29.9722
496.779	30.2011
500.289	31.2921
503.8	32.2035
507.307	32.2264
510.813	32.43
514.32	32.7312
517.823	31.8841
521.325	31.445
524.826	30.6226
528.325	30.7326
531.823	30.4018
535.32	30.6809
538.815	30.3365
542.309	30.4475
545.802	27.9644
549.293	26.8879
552.783	25.9774
556.271	25.5059
559.759	23.2309
563.245	23.587
566.729	21.5562
570.213	17.6585
573.693	16.707
577.173	13.1368
580.652	10.6115
584.13	9.10636
587.605	7.01949
591.08	4.90022
594.552	3.85873
598.025	2.30024
601.496	1.8545
604.964	1.59893
608.433	1.22027
611.898	1.91746
615.364	2.79151
618.827	2.4834
622.288	2.28771
625.75	2.33117
629.209	3.05853
632.667	3.7333
636.125	5.30032
639.58	6.86622
643.033	8.2153
646.485	8.23309
649.936	10.6362
653.388	8.34336
656.836	9.96112
660.283	9.79191
663.728	8.75553
667.173	9.07392
670.616	8.88209
674.057	11.1381
677.498	13.956
680.937	16.5917
684.375	18.6748
687.809	20.1831
691.244	20.3893
694.678	20.6692
698.111	19.9568
701.54	20.2251
704.97	20.9271
708.398	22.5728
711.826	22.3804
715.25	23.6996
718.675	23.3833
722.096	23.9781
725.518	23.4438
728.937	23.7108
732.357	22.1671
735.773	23.16
739.19	22.4103
742.604	24.5449
746.018	27.2055
749.429	30.2033
752.839	33.4727
756.248	38.2009
759.657	43.1934
763.063	44.2495
766.468	47.1431
769.871	47.9071
773.273	50.7962
776.676	53.646
780.075	55.0113
783.474	57.3765
786.871	60.5562
790.266	62.6796
793.661	65.1341
797.054	65.5872
800.446	68.5706
803.834	69.6367
807.224	71.4459
810.612	73.4021
813.998	74.5964
817.384	75.727
820.766	77.4432
824.149	79.2932
827.531	80.9633
830.909	81.1795
834.288	81.2188
837.666	80.8206
841.041	78.0271
844.416	73.594
847.788	69.3673
851.161	67.933
854.53	65.4714
857.901	64.3502
861.268	60.1293
864.633	55.6385
868	53.7623
871.363	52.0012
874.725	49.9076
878.088	47.7237
881.447	45.7383
884.805	44.9797
888.162	41.977
891.518	39.9409
894.872	40.6498
898.225	40.2826
901.577	41.2083
904.928	39.9913
908.277	41.0707
911.625	40.9495
914.972	41.0026
918.318	42.9752
921.662	42.3256
925.005	43.7432
928.347	44.2597
931.686	45.2881
935.025	45.7757
938.363	44.8577
941.698	44.6165
945.034	42.9508
948.368	43.4392
951.699	45.6634
955.031	44.328
958.36	42.4592
961.689	38.943
965.016	36.6706
968.343	37.3718
971.666	38.4405
974.991	40.1175
978.312	42.0702
981.632	41.6406
984.953	42.3031
988.27	39.8894
991.587	39.4802
994.902	39.9507
998.216	41.7758
1001.53	43.4054
1004.84	40.7446
1008.15	38.5407
1011.46	37.3563
1014.77	36.2975
1018.07	36.8695
1021.38	35.8226
1024.68	37.2598
1027.99	37.0188
1031.29	40.691
1034.59	39.2025
1037.89	37.5128
1041.18	36.6398
1044.48	38.9192
1047.77	42.2879
1051.07	44.7851
1054.36	44.0771
1057.65	44.0351
1060.94	44.2672
1064.23	44.3945
1067.52	43.8505
1070.8	43.3793
1074.09	43.3751
1077.37	42.7152
1080.65	43.0281
1083.93	39.4893
1087.21	37.1599
1090.49	36.9794
1093.77	36.1448
1097.04	38.8935
1100.32	38.7977
1103.59	39.2364
1106.86	41.4609
1110.13	40.9944
1113.4	42.6277
1116.67	42.0632
1119.94	40.6888
1123.2	39.2583
1126.47	37.0061
1129.73	33.7528
1132.99	31.8545
1136.25	30.2408
1139.51	27.6742
1142.77	25.0762
1146.03	22.2019
1149.28	18.3237
1152.54	15.7022
1155.79	11.7076
1159.04	7.63968
1162.29	3.63837
1165.54	0.953202
1168.79	0.337616
1172.04	0.381056
1175.28	2.00167
1178.53	3.61897
1181.77	4.4971
1185.01	4.59272
1188.25	6.28529
1191.49	8.8485
1194.73	11.3078
1197.96	12.7223
1201.2	15.8467
1204.43	21.2554
1207.66	26.3029
1210.9	30.8305
1214.13	36.4694
1217.36	42.7023
1220.58	46.1688
1223.81	50.6441
1227.04	56.2294
1230.26	59.9956
1233.48	64.0874
1236.71	67.2879
1239.93	70.3994
1243.14	75.9146
1246.36	78.4252
1249.58	81.6753
1252.8	84.1027
1256.01	86.7776
1259.22	88.4415
1262.43	90.841
1265.64	94.0039
1268.85	98.0504
1272.06	101.66
1275.27	106.566
1278.48	109.94
1281.68	113.874
1284.88	117.835
1288.08	119.501
1291.28	122.705
1294.48	125.268
1297.68	126.619
1300.88	128.854
1304.07	131.771
1307.27	133.263
1310.46	136.37
1313.65	139.05
1316.85	138.379
1320.03	140.2
1323.22	139.956
1326.41	137.61
1329.6	138.281
1332.78	137.302
1335.96	136.005
1339.15	135.524
1342.33	132.204
1345.51	128.417
1348.69	124.968
1351.86	119.102
1355.04	115.372
1358.21	109.567
1361.39	104.513
1364.56	99.8472
1367.73	95.2559
1370.9	91.2857
1374.07	87.3916
1377.24	85.9196
1380.41	81.8755
1383.57	80.2648
1386.73	77.4535
1389.9	75.9425
1393.06	73.899
1396.22	72.7836
1399.38	73.0758
1402.54	76.0303
1405.69	76.9883
1408.85	80.8374
1412	87.2183
1415.16	92.8076
1418.31	98.1524
1421.46	107.214
1424.61	114.768
1427.76	128.011
1430.9	136.48
1434.05	146.995
1437.2	154.286
1440.34	161.814
1443.48	168.439
1446.62	173.885
1449.76	176.033
1452.9	175.211
1456.04	172.176
1459.17	168.412
1462.31	162.303
1465.44	156.315
1468.58	149.181
1471.71	140.552
1474.84	131.358
1477.97	122.131
1481.1	112.877
1484.22	102.062
1487.35	94.6663
1490.47	88.1259
1493.59	80.7634
1496.72	75.0632
1499.84	69.9612
1502.96	65.4859
1506.08	59.6247
1509.19	53.278
1512.31	49.3599
1515.42	46.2859
1518.54	42.1712
1521.65	37.4647
1524.76	35.726
1527.87	31.3082
1530.98	28.9564
1534.09	29.0286
1537.2	30.4515
1540.3	31.3075
1543.41	33.6258
1546.51	36.5576
1549.61	38.9964
1552.71	41.1659
1555.81	43.3438
1558.91	49.2032
1562.01	53.6515
1565.1	57.1804
1568.2	61.3634
1571.29	64.8755
1574.38	68.5389
1577.48	72.6173
1580.57	77.2321
1583.65	80.8523
1586.74	83.8244
1589.83	85.7334
1592.92	88.8412
1596	87.3721
1599.08	88.5402
1602.16	88.5901
1605.24	87.6824
1608.32	87.8438
1611.4	87.6712
1614.48	87.4395
1617.56	86.2678
1620.63	88.5141
1623.71	90.5662
1626.78	91.9908
1629.85	95.2919
1632.92	99.8119
1635.99	104.491
1639.06	107.302
1642.12	109.623
1645.19	114.978
1648.25	117.358
1651.32	120.236
1654.38	123.688
1657.44	126.158
1660.5	124.471
1663.56	123.207
1666.62	120.25
1669.67	115.191
1672.73	107.286
1675.79	99.8008
1678.84	91.2241
1681.89	83.2469
1684.94	74.2664
1687.99	64.861
1691.04	56.0914
1694.08	49.0592
1697.13	43.2467
1700.18	38.2914
1703.22	32.664
1706.26	27.3953
1709.3	21.0211
1712.35	17.216
1715.39	13.2278
1718.42	10.4112
1721.46	8.32558
1724.5	6.51896
1727.53	6.18721
1730.56	6.09699
1733.6	5.75315
1736.63	4.87393
1739.66	5.02116
1742.69	4.61819
1745.71	3.36573
1748.74	3.38647
1751.77	4.62248
1754.79	4.34726
1757.81	4.90659
1760.84	6.27073
1763.86	6.05309
1766.88	6.29946
1769.9	6.26428
1772.91	6.53177
1775.93	5.1676
1778.95	4.14971
1781.96	3.22442
1784.97	3.82184
1787.99	4.51519
1791	4.17328
1794.01	3.95242
1797.01	3.86916
1800.02	3.83663
1803.03	4.50088
1806.03	5.36828
1809.04	5.26246
1812.04	4.84072
1815.04	4.06258
1818.04	3.95758
1821.04	3.82716
1824.04	3.87789
1827.04	4.24229
1830.03	5.3339
1833.03	5.39095
1836.02	5.25714
1839.02	4.08854
1842.01	3.46458
1845	3.80487
1847.99	3.9529
1850.98	2.62316
1853.96	3.33338
1856.95	3.52951
1859.94	3.85757
1862.92	3.72634
1865.9	3.4921
1868.88	3.87212
1871.86	3.9955
1874.84	4.84145
1877.82	5.33195
1880.8	4.3753
1882.58	4.5123
1885.57	5.57346
1888.56	7.28535
1891.54	8.8028
1894.53	9.56543
1897.51	10.8311
1900.5	10.5035
1903.48	10.5798
1906.46	9.59953
1909.44	9.295
1912.42	9.22465
1915.4	9.89138
1918.37	10.0393
1921.35	9.78472
1924.32	9.57828
1927.3	9.04371
1930.27	7.18486
1933.24	6.02411
1936.21	4.76449
1939.18	6.47489
1942.15	6.27427
1945.11	5.05151
1948.08	6.196
1951.04	5.39883
1954.01	5.26364
1956.97	6.244
1959.93	6.92499
1962.89	7.14724
1965.85	6.73657
1968.81	5.81071
1971.77	5.13426
1974.72	3.96615
1977.68	4.3426
1980.63	5.37805
1983.58	5.5919
1986.53	5.23091
1989.48	6.4962
1992.43	6.49988
1995.38	5.73946
1998.33	4.58889
2001.27	5.25248
2004.22	6.49092
2007.16	6.31266
2010.11	6.94459
2013.05	5.89076
2015.99	5.67978
2018.93	6.62063
2021.87	6.3336
2024.8	6.10664
2027.74	7.8449
2030.68	9.08887
2033.61	9.19572
2036.54	9.21974
2039.48	8.86565
2042.41	8.30513
2045.34	8.76285
2048.27	7.09499
2051.19	7.56133
2054.12	6.85169
2057.05	7.15262
2059.97	6.33008
2062.9	7.19672
2065.82	8.67145
2068.74	8.05814
2071.66	9.65977
2074.58	9.12002
2077.5	10.0542
2080.41	10.355
2083.33	10.4559
2086.24	11.6075
2089.16	12.7984
2092.07	14.2983
2094.98	16.2404
2097.89	18.1914
2100.8	19.7208
2103.71	21.3903
2106.62	22.8662
2109.53	24.1625
2112.43	25.4415
2115.33	27.4354
2118.24	30.4998
2121.14	32.4572
2124.04	34.5539
2126.94	39.6758
2129.84	42.8115
2132.74	47.0174
2135.63	52.2522
2138.53	57.0145
2141.43	60.8745
2144.32	67.1387
2147.21	72.1699
2150.1	77.6098
2152.99	80.5369
2155.88	86.0727
2158.77	92.1633
2161.66	96.8416
2164.55	100.825
2167.43	103.009
2170.31	103.134
2173.2	105.001
2176.08	104.467
2178.96	103.892
2181.84	102.763
2184.72	101.025
2187.6	97.1722
2190.47	92.7623
2193.35	88.297
2196.23	85.1966
2199.1	79.9275
2201.97	74.6107
2204.84	68.6469
2207.71	63.8051
2210.58	58.3574
2213.45	53.1675
2216.32	48.3532
2219.19	45.2204
2222.05	40.9056
2224.92	36.3852
2227.78	36.0519
2230.64	32.2251
2233.5	30.1792
2236.36	28.0941
2239.22	26.4465
2242.08	24.3574
2244.94	24.3056
2247.79	23.4745
2250.65	23.7869
2253.5	22.6308
2256.36	22.3571
2259.21	22.786
2262.06	22.9535
2264.91	23.7788
2267.76	21.8952
2270.6	22.4972
2273.45	21.905
2276.3	21.452
2279.14	19.8293
2281.98	18.6929
2284.83	17.4142
2287.67	15.5026
2290.51	13.37
2293.35	10.4004
2296.19	8.9068
2299.02	7.88627
2301.86	7.23138
2304.7	7.49467
2307.53	6.81968
2310.36	6.09908
2313.2	5.85229
2316.03	5.51543
2318.86	6.1664
2321.69	4.7741
2324.51	5.46974
2327.34	5.29588
2330.17	5.06235
2332.99	5.31585
2335.82	5.73125
2338.64	4.66925
2341.46	5.65904
2344.28	4.9297
2347.1	4.10719
2349.92	3.1626
2352.74	1.20959
2355.56	-0.599503
2358.37	-0.808087
2361.19	-1.67489
2364	-0.809554
2366.82	0.0596825
2369.63	1.47847
2372.44	0.818197
2375.25	0.609489
2378.06	1.11717
2380.86	1.08844
2383.67	0.663141
2386.48	0.538301
2389.28	1.22283
2392.09	1.39946
2394.89	2.3375
2397.69	2.28939
2400.49	2.18766
2403.29	2.62041
2406.09	3.50084
2408.89	4.12159
2411.69	4.55331
2414.48	3.9542
2417.28	3.82942
2420.07	4.15107
2422.86	4.86183
2425.65	6.30265
2428.45	7.2913
2431.23	8.91826
2434.02	7.77383
2436.81	8.13892
2439.6	7.19485
2442.38	7.55785
2445.17	8.37101
2447.95	8.38983
2450.73	8.60621
2453.52	9.67492
2456.3	9.29542
2459.08	8.65684
2461.85	8.91887
2464.63	7.58296
2467.41	7.25722
2470.19	6.51859
2472.96	6.73792
2475.73	6.38682
2478.51	4.58134
2481.28	2.96992
2484.05	3.09947
2486.82	3.18729
2489.59	2.04798
2492.35	2.50876
2495.12	2.21613
2497.89	1.85845
2500.65	1.66889
2503.42	1.95371
2506.18	2.98139
2508.94	3.42092
2511.7	5.28865
2514.46	6.80641
2517.22	7.65263
2519.98	9.30873
2522.73	9.38467
2525.49	10.5207
2528.25	11.5607
2531	12.0639
2533.75	11.6942
2536.5	12.5381
2539.25	13.5952
2542.01	13.7942
2544.75	14.0025
2547.5	15.3093
2550.25	14.844
2553	15.3433
2555.74	16.4065
2558.49	16.4135
2561.23	16.7591
2563.97	16.2903
2566.71	16.6595
2569.45	16.8754
2572.19	17.1692
2574.93	17.3573
2577.67	17.7879
2580.4	18.5394
2583.14	17.534
2585.87	16.386
2588.6	16.63
2591.34	15.6465
2594.07	14.8432
2596.8	14.2883
2599.53	13.8929
2602.26	12.8469
2604.98	13.0451
2607.71	13.0097
2610.44	12.3273
2613.16	11.9551
2615.88	11.6525
2618.61	9.94709
2621.33	11.2038
2624.05	10.073
2626.77	10.6844
2629.49	9.15008
2632.21	10.3612
2634.92	11.5085
2637.64	12.0664
2640.35	13.3768
2643.07	13.3754
2645.78	13.577
2648.49	13.046
2651.2	13.5128
2653.91	13.1574
2656.62	13.7104
2659.33	15.236
2662.04	15.4146
2664.74	14.8035
2667.45	14.7041
2670.15	14.4675
2672.86	15.1575
2675.56	14.7397
2678.26	15.1639
2680.96	15.8146
2683.66	15.9326
2686.36	17.6852
2689.06	17.7038
2691.75	18.5754
2694.45	18.6601
2697.14	19.5587
2699.84	20.8455
2702.53	21.4354
2705.22	22.6177
2707.91	22.5057
2710.6	23.36
2713.29	23.5554
2715.98	23.3714
2718.67	23.8428
2721.35	24.4622
2724.04	24.4099
2726.72	23.797
2729.4	23.4613
2732.09	22.6252
2734.77	22.3326
2737.45	19.8933
2740.13	18.9481
2742.81	17.5037
2745.48	18.1433
2748.16	17.5684
2750.84	16.5751
2753.51	15.6745
2756.19	13.4695
2758.86	12.1698
2761.53	11.0484
2764.2	9.38043
2766.87	7.69616
2769.54	7.27876
2772.21	6.18421
2774.88	5.42609
2777.54	4.19786
2780.21	2.60525
2782.87	1.77969
2785.53	1.59562
2788.2	1.46053
2790.86	1.42995
2793.52	2.81584
2796.18	3.80675
2798.84	4.01339
2801.49	4.48902
2804.15	3.85344
2806.81	4.25132
2809.46	5.07432
2812.12	6.74274
2814.77	7.552
2817.42	9.74263
2820.07	15.6557
2822.72	21.5783
2825.37	28.915
2828.02	36.4699
2830.67	45.1177
2833.31	56.1083
2835.96	68.3998
2838.61	79.4885
2841.25	92.8117
2843.89	107.513
2846.53	122.344
2849.17	140.021
2851.81	158.221
2854.45	176.857
2857.09	195.139
2859.73	212.486
2862.36	228.873
2865	241.588
2867.64	254.23
2870.27	265.03
2872.9	273.646
2875.53	282.935
2878.16	291.215
2880.79	298.625
2883.42	305.551
2886.05	312.199
2888.68	318.161
2891.3	326.053
2893.93	332.118
2896.55	340.218
2899.18	349.298
2901.8	359.743
2904.42	372.655
2907.04	386.582
2909.66	401.539
2912.28	418.193
2914.9	435.02
2917.51	451.458
2920.13	464.729
2922.74	477.897
2925.36	486.423
2927.97	491.326
2930.59	493.493
2933.2	491.432
2935.81	486.835
2938.42	478.781
2941.02	469.323
2943.63	455.834
2946.24	439.406
2948.85	423.115
2951.45	406.042
2954.05	387.414
2956.66	367.678
2959.26	348.348
2961.86	331.225
2964.46	312.847
2967.06	294.576
2969.66	277.622
2972.26	262
2974.85	244.473
2977.45	229.864
2980.05	213.477
2982.64	196.798
2985.23	180.979
2987.83	164.276
2990.42	146.083
2993.01	130.38
2995.6	114.528
2998.19	100.117
3000.77	85.6732
3003.36	72.759
3005.95	60.6621
3008.53	48.6961
3011.12	39.4408
3013.7	30.757
3016.28	23.4253
3018.86	17.5164
3021.44	12.1575
3024.02	8.72839
3026.6	6.19473
3029.18	4.02252
3031.76	2.87839
3034.33	4.02747
3036.91	4.67115
3039.48	6.0023
3042.05	7.67257
3044.63	9.63201
3047.2	12.2318
3049.77	13.3311
3052.34	15.063
3054.91	16.592
3057.48	17.6485
3060.04	16.3709
3062.61	16.2334
3065.17	15.205
3067.74	14.1662
3070.3	12.5656
3072.87	11.0008
3075.43	8.95944
3077.99	6.45002
3080.55	4.97772
3083.11	3.44148
3085.67	0.810064
3088.22	0.0585081
3090.78	-0.0938021
3093.34	-0.903987
3095.89	-0.528188
3098.44	0.470731
3101	1.0137
3103.55	1.75796
3106.1	3.56419
3108.65	5.08127
3111.2	6.32239
3113.75	9.26262
3116.3	11.8622
3118.84	14.0529
3121.39	15.9744
3123.93	17.9931
3126.48	21.1252
3129.02	23.7479
3131.56	27.1213
3134.1	28.8723
3136.64	31.1268
3139.18	31.8762
3141.72	33.7518
3144.26	35.6616
3146.8	37.4935
3149.33	38.492