File: data/Raman/poly_smoothed/Mbcal_20_25_44_1x_45s_532 nm_x100_100%_600 gr_mm_01.txt
#Acq. time (s)=	45
#Accumulations=	2
#Range (cm-¹)=	200...3150
#Windows=	2
#Auto scanning=	Off
#Autofocus=	Off
#Macrospot=	Off
#AutoExposure=	Off
#Spike filter=	Multiple accum.
#Delay time (s)=	0
#Binning=	1
#Readout mode=	Signal
#DeNoise=	Off
#ICS correction=	On
#Dark correction=	Off
#Inst. Process=	Off
#Detector Gain=	Best Dynamic Range
#Detector ADC=	20 kHz
#Detector temperature (°C)=	-69.85
#Instrument=	LabRAM HR Evol
#Detector=	Synapse
#Objective=	x100
#Grating=	600 gr/mm
#ND Filter=	100%
#Laser (nm)=	532
#Hole=	100.021
#Range=	Auto
#Laser Pol.=	No
#Raman. Pol.=	No
#Laser Pol. (°)=	-0.0007625
#Raman Pol. (°)=	89.9995
#Collection=	Microscope
#StageXY=	Marzhauser
#StageZ=	Marzhauser
#X (µm)=	-1107.8
#Y (µm)=	1263.3
#Z (µm)=	578.25
#Full time(mm:ss)=	3:18
#Project=
#Sample=
#Site=
#Title=	Mbcal_20_25_44_2x_45s_532 nm_x100_100%_600 gr_mm
#Remark=
#Date=	18.07.2022 13:31
#Acquired=	18.07.2022 13:31:00
#Base:Fit=	10.08.2022 10:55:08
#Base:Sub=	10.08.2022 10:55:14
#Filter:Polynom=	16.08.2022 10:07:28
#AxisType[0]=Intens
#AxisUnit[0]=Cnt
#AxisType[1]=Spectr
#AxisUnit[1]=1/cm
200.419	8.53287
204.048	9.13315
207.678	9.86391
211.304	9.81907
214.928	7.5616
218.554	6.33826
222.176	4.86424
225.798	4.1432
229.417	5.16129
233.035	4.7242
236.653	5.52581
240.268	5.98446
243.881	5.83038
247.493	6.28146
251.103	6.0188
254.715	5.19974
258.322	6.29919
261.929	6.43822
265.534	9.68218
269.137	11.9843
272.739	12.3371
276.34	13.442
279.939	14.1463
283.537	15.0021
287.134	14.7314
290.729	15.4075
294.323	16.4954
297.913	15.9008
301.504	15.6487
305.093	15.3938
308.682	17.6567
312.268	18.2028
315.852	20.239
319.436	19.8648
323.018	19.3621
326.597	18.4817
330.177	18.459
333.753	18.7123
337.331	18.6982
340.906	19.5402
344.478	20.1091
348.051	19.9076
351.621	19.0318
355.189	19.0146
358.757	16.2061
362.323	13.2723
365.889	11.9482
369.451	10.8866
373.012	11.4325
376.574	11.4267
380.133	11.2272
383.69	11.4476
387.245	11.5878
390.8	12.3053
394.353	12.8761
397.906	13.1005
401.456	12.9812
405.005	13.4992
408.552	12.4778
412.099	11.4218
415.643	12.6732
419.187	11.5737
422.728	11.2168
426.269	10.5094
429.806	11.3275
433.344	9.52138
436.881	8.33991
440.416	6.81621
443.949	6.80266
447.48	5.88813
451.011	5.83337
454.541	6.37351
458.069	8.49108
461.594	8.48808
465.119	8.01973
468.642	9.45823
472.165	11.3927
475.684	13.3801
479.204	14.3113
482.721	15.9812
486.239	16.6728
489.753	18.0886
493.268	18.7681
496.779	17.7128
500.289	18.1966
503.8	17.8072
507.307	18.3057
510.813	19.3465
514.32	20.4383
517.823	20.7466
521.325	20.115
524.826	19.9239
528.325	20.5563
531.823	20.2177
535.32	20.882
538.815	19.4783
542.309	17.2756
545.802	15.9405
549.293	15.4194
552.783	15.4598
556.271	15.9464
559.759	15.7777
563.245	15.4058
566.729	15.0378
570.213	12.3612
573.693	10.1081
577.173	9.22537
580.652	8.76615
584.13	7.76617
587.605	7.02995
591.08	8.06763
594.552	6.42761
598.025	5.96912
601.496	5.71697
604.964	4.9804
608.433	5.74111
611.898	7.2543
615.364	8.36654
618.827	8.17739
622.288	6.75499
625.75	6.29359
629.209	6.89136
632.667	9.0517
636.125	9.49816
639.58	11.0336
643.033	12.2445
646.485	12.8499
649.936	13.7408
653.388	12.9441
656.836	13.4333
660.283	15.3824
663.728	16.5483
667.173	16.6064
670.616	15.8641
674.057	17.7685
677.498	18.9609
680.937	18.1908
684.375	21.1031
687.809	23.0855
691.244	24.0341
694.678	25.8781
698.111	25.6633
701.54	25.287
704.97	25.805
708.398	26.0227
711.826	26.0902
715.25	28.0917
718.675	27.4101
722.096	27.6099
725.518	29.254
728.937	31.0148
732.357	31.0399
735.773	31.6514
739.19	33.5504
742.604	34.2887
746.018	35.9005
749.429	36.958
752.839	38.9606
756.248	41.1893
759.657	43.7294
763.063	46.2464
766.468	48.741
769.871	51.6104
773.273	52.8282
776.676	54.4184
780.075	57.5939
783.474	57.8832
786.871	60.1651
790.266	63.6224
793.661	66.0492
797.054	66.1053
800.446	67.7272
803.834	68.4221
807.224	71.2419
810.612	72.4493
813.998	72.3287
817.384	72.6093
820.766	73.871
824.149	74.4859
827.531	75.3629
830.909	76.118
834.288	77.0967
837.666	76.6904
841.041	75.5539
844.416	72.6975
847.788	72.6436
851.161	69.337
854.53	65.1054
857.901	62.422
861.268	60.6728
864.633	58.9917
868	55.703
871.363	54.604
874.725	52.1121
878.088	47.861
881.447	44.9057
884.805	42.3676
888.162	38.8856
891.518	36.834
894.872	35.3734
898.225	35.2657
901.577	34.7949
904.928	35.8201
908.277	37.2958
911.625	40.6327
914.972	41.2444
918.318	40.6375
921.662	39.9856
925.005	40.2544
928.347	40.0766
931.686	39.9626
935.025	40.1174
938.363	40.79
941.698	41.1588
945.034	41.6034
948.368	42.0463
951.699	41.1592
955.031	41.8164
958.36	39.2545
961.689	36.411
965.016	35.7094
968.343	34.165
971.666	33.2837
974.991	34.1234
978.312	34.1417
981.632	33.9678
984.953	33.3766
988.27	33.1681
991.587	34.2429
994.902	33.0992
998.216	29.771
1001.53	28.0053
1004.84	26.8319
1008.15	26.7057
1011.46	25.5575
1014.77	26.0858
1018.07	26.4306
1021.38	26.6583
1024.68	27.5976
1027.99	28.4941
1031.29	28.7389
1034.59	29.5257
1037.89	28.6008
1041.18	28.9559
1044.48	30.5197
1047.77	31.3426
1051.07	31.0522
1054.36	31.5347
1057.65	32.6469
1060.94	31.9501
1064.23	30.951
1067.52	28.1728
1070.8	26.8126
1074.09	25.3412
1077.37	22.3375
1080.65	20.0773
1083.93	18.2493
1087.21	18.0058
1090.49	16.9441
1093.77	17.2556
1097.04	18.4514
1100.32	20.3232
1103.59	21.2402
1106.86	21.6413
1110.13	20.7975
1113.4	20.6563
1116.67	20.446
1119.94	20.2479
1123.2	21.138
1126.47	20.1578
1129.73	18.8284
1132.99	18.73
1136.25	17.4243
1139.51	14.7267
1142.77	11.9598
1146.03	10.1934
1149.28	8.76015
1152.54	9.10127
1155.79	6.00883
1159.04	4.56482
1162.29	3.47724
1165.54	2.96119
1168.79	3.0625
1172.04	2.07647
1175.28	2.1584
1178.53	1.71436
1181.77	2.60321
1185.01	1.77032
1188.25	2.74649
1191.49	3.02626
1194.73	4.396
1197.96	3.50197
1201.2	5.14997
1204.43	7.63273
1207.66	8.5031
1210.9	10.9093
1214.13	13.1484
1217.36	13.8844
1220.58	15.9415
1223.81	18.9758
1227.04	21.4663
1230.26	22.9948
1233.48	25.8314
1236.71	27.6601
1239.93	30.0509
1243.14	31.0585
1246.36	31.4981
1249.58	32.8985
1252.8	35.0264
1256.01	36.4575
1259.22	38.5506
1262.43	39.6744
1265.64	41.457
1268.85	42.0052
1272.06	44.3829
1275.27	45.6014
1278.48	46.7298
1281.68	49.2083
1284.88	50.0142
1288.08	50.5755
1291.28	53.3142
1294.48	54.5724
1297.68	56.0789
1300.88	57.6874
1304.07	59.7175
1307.27	60.3295
1310.46	61.841
1313.65	61.94
1316.85	62.0142
1320.03	61.213
1323.22	59.5156
1326.41	56.8883
1329.6	55.7547
1332.78	54.605
1335.96	53.1656
1339.15	51.2616
1342.33	49.6107
1345.51	48.1595
1348.69	46.368
1351.86	44.7127
1355.04	41.6402
1358.21	40.2978
1361.39	38.2967
1364.56	36.1293
1367.73	35.5023
1370.9	35.2936
1374.07	33.7338
1377.24	34.3294
1380.41	33.6086
1383.57	33.796
1386.73	34.8744
1389.9	33.8306
1393.06	33.2802
1396.22	32.8603
1399.38	33.5649
1402.54	34.6071
1405.69	38.3036
1408.85	41.7532
1412	45.0049
1415.16	48.5777
1418.31	52.0448
1421.46	55.1842
1424.61	60.678
1427.76	65.7016
1430.9	69.8343
1434.05	73.4107
1437.2	77.624
1440.34	80.2865
1443.48	82.6696
1446.62	83.9673
1449.76	84.6312
1452.9	82.7078
1456.04	79.4713
1459.17	77.5873
1462.31	74.2228
1465.44	67.7066
1468.58	61.2474
1471.71	54.8668
1474.84	49.5617
1477.97	45.207
1481.1	40.1217
1484.22	34.522
1487.35	28.7251
1490.47	23.829
1493.59	19.1663
1496.72	16.5098
1499.84	13.5848
1502.96	13.3558
1506.08	11.2451
1509.19	10.3295
1512.31	9.9075
1515.42	10.7356
1518.54	9.49734
1521.65	10.4551
1524.76	10.295
1527.87	11.1914
1530.98	11.2243
1534.09	11.9196
1537.2	12.5886
1540.3	12.8992
1543.41	14.8847
1546.51	16.6209
1549.61	18.7908
1552.71	20.3443
1555.81	21.5379
1558.91	21.6187
1562.01	22.5955
1565.1	23.4382
1568.2	24.7369
1571.29	25.6772
1574.38	27.314
1577.48	28.0956
1580.57	29.7113
1583.65	30.8919
1586.74	32.0273
1589.83	32.8682
1592.92	33.9381
1596	35.8205
1599.08	35.9711
1602.16	35.4311
1605.24	36.2158
1608.32	35.966
1611.4	36.4717
1614.48	37.0332
1617.56	37.7987
1620.63	37.9865
1623.71	37.1279
1626.78	36.9223
1629.85	37.8114
1632.92	39.8669
1635.99	41.1969
1639.06	44.0735
1642.12	46.0175
1645.19	48.2844
1648.25	50.1902
1651.32	53.5678
1654.38	54.1505
1657.44	56.4774
1660.5	56.5792
1663.56	56.803
1666.62	57.343
1669.67	55.5983
1672.73	51.9152
1675.79	49.6662
1678.84	48.0736
1681.89	43.737
1684.94	39.6882
1687.99	34.8608
1691.04	30.3744
1694.08	25.124
1697.13	19.5218
1700.18	15.2735
1703.22	14.4738
1706.26	11.8101
1709.3	9.57418
1712.35	7.39398
1715.39	6.71037
1718.42	5.33785
1721.46	5.196
1724.5	4.48063
1727.53	4.69401
1730.56	5.06086
1733.6	4.81974
1736.63	5.78778
1739.66	6.31487
1742.69	6.02387
1745.71	5.91838
1748.74	7.44755
1751.77	8.13794
1754.79	8.34671
1757.81	7.03197
1760.84	6.54346
1763.86	5.50703
1766.88	4.90772
1769.9	4.66334
1772.91	3.80685
1775.93	3.71832
1778.95	2.84576
1781.96	2.15689
1784.97	0.936343
1787.99	0.470163
1791	0.407679
1794.01	-0.558052
1797.01	-0.248392
1800.02	0.115191
1803.03	0.176734
1806.03	0.355948
1809.04	0.123497
1812.04	0.127356
1815.04	-0.110895
1818.04	0.633864
1821.04	1.26266
1824.04	1.62435
1827.04	1.99014
1830.03	2.30427
1833.03	2.28717
1836.02	1.66875
1839.02	2.4573
1842.01	3.53745
1845	2.94507
1847.99	2.4416
1850.98	2.46063
1853.96	2.74743
1856.95	3.18569
1859.94	3.76794
1862.92	4.44487
1865.9	4.07442
1868.88	4.00236
1871.86	4.33856
1874.84	4.58225
1877.82	4.62701
1880.8	4.57663
1882.58	4.81581
1885.57	4.4174
1888.56	5.49408
1891.54	5.79286
1894.53	6.19917
1897.51	6.12738
1900.5	6.22997
1903.48	6.33805
1906.46	5.25835
1909.44	5.02422
1912.42	5.02293
1915.4	4.24487
1918.37	4.64386
1921.35	4.49467
1924.32	4.68825
1927.3	4.3305
1930.27	4.2309
1933.24	3.50531
1936.21	3.03092
1939.18	3.23149
1942.15	3.60962
1945.11	3.49822
1948.08	2.68478
1951.04	2.00069
1954.01	1.69624
1956.97	1.92819
1959.93	1.9484
1962.89	2.77749
1965.85	3.64833
1968.81	4.03998
1971.77	5.06209
1974.72	4.92625
1977.68	5.41391
1980.63	5.44005
1983.58	5.92091
1986.53	6.59972
1989.48	6.86611
1992.43	7.51421
1995.38	7.28504
1998.33	8.13804
2001.27	8.2007
2004.22	8.25867
2007.16	8.90985
2010.11	9.55694
2013.05	8.98071
2015.99	8.02116
2018.93	6.92037
2021.87	6.75431
2024.8	6.20485
2027.74	6.85389
2030.68	7.89202
2033.61	8.93725
2036.54	9.47002
2039.48	10.2404
2042.41	10.4646
2045.34	10.4137
2048.27	10.1226
2051.19	9.86026
2054.12	9.63872
2057.05	9.02515
2059.97	8.62923
2062.9	8.28838
2065.82	9.02843
2068.74	8.46759
2071.66	7.98169
2074.58	7.26542
2077.5	7.3674
2080.41	7.20625
2083.33	6.37735
2086.24	5.63202
2089.16	5.86145
2092.07	5.37726
2094.98	5.17529
2097.89	5.83935
2100.8	6.71974
2103.71	7.25497
2106.62	8.23301
2109.53	8.53532
2112.43	9.13875
2115.33	10.5138
2118.24	11.2218
2121.14	11.6472
2124.04	11.7464
2126.94	12.8981
2129.84	14.3418
2132.74	16.1449
2135.63	18.2685
2138.53	19.5705
2141.43	20.8232
2144.32	22.9712
2147.21	25.61
2150.1	28.0822
2152.99	30.4501
2155.88	31.9825
2158.77	33.0547
2161.66	35.4954
2164.55	37.5534
2167.43	40.317
2170.31	41.2415
2173.2	41.2143
2176.08	41.6053
2178.96	42.0071
2181.84	41.5235
2184.72	41.234
2187.6	40.5587
2190.47	38.285
2193.35	36.3314
2196.23	34.9949
2199.1	33.8364
2201.97	31.274
2204.84	28.989
2207.71	27.2954
2210.58	25.4787
2213.45	24.5982
2216.32	22.4528
2219.19	21.161
2222.05	19.5059
2224.92	18.3556
2227.78	17.4239
2230.64	16.1604
2233.5	15.234
2236.36	13.8287
2239.22	11.1556
2242.08	9.24393
2244.94	7.62241
2247.79	6.8743
2250.65	6.44965
2253.5	5.83092
2256.36	5.50707
2259.21	5.3623
2262.06	4.67804
2264.91	5.18733
2267.76	4.50592
2270.6	4.34678
2273.45	4.01226
2276.3	5.02299
2279.14	5.14408
2281.98	5.06737
2284.83	5.32357
2287.67	4.66406
2290.51	5.13178
2293.35	4.6555
2296.19	4.39588
2299.02	4.45041
2301.86	4.47601
2304.7	4.24568
2307.53	5.39416
2310.36	5.68193
2313.2	6.75251
2316.03	6.95386
2318.86	7.38152
2321.69	6.71774
2324.51	7.07275
2327.34	7.18849
2330.17	5.94053
2332.99	5.9874
2335.82	5.59692
2338.64	5.20798
2341.46	5.27344
2344.28	4.79006
2347.1	4.15591
2349.92	2.94289
2352.74	1.95589
2355.56	1.58091
2358.37	0.165895
2361.19	0.226148
2364	0.196433
2366.82	0.589217
2369.63	1.76858
2372.44	1.53149
2375.25	2.92237
2378.06	3.44177
2380.86	2.34003
2383.67	2.17935
2386.48	2.2044
2389.28	2.86096
2392.09	2.80901
2394.89	3.53482
2397.69	4.1558
2400.49	4.19568
2403.29	4.15159
2406.09	5.31175
2408.89	5.59594
2411.69	5.96871
2414.48	5.36813
2417.28	5.01341
2420.07	5.78189
2422.86	5.41074
2425.65	4.70977
2428.45	3.96851
2431.23	3.97484
2434.02	2.81547
2436.81	2.73981
2439.6	1.82403
2442.38	1.17079
2445.17	0.27879
2447.95	-0.47249
2450.73	0.155397
2453.52	0.38657
2456.3	0.825588
2459.08	0.89129
2461.85	1.39974
2464.63	0.773735
2467.41	1.93523
2470.19	1.78942
2472.96	2.19583
2475.73	2.35632
2478.51	2.12121
2481.28	2.45502
2484.05	3.06561
2486.82	3.10026
2489.59	3.55597
2492.35	1.86714
2495.12	1.81343
2497.89	2.51832
2500.65	1.79887
2503.42	2.54824
2506.18	1.88375
2508.94	1.96441
2511.7	1.74932
2514.46	2.32594
2517.22	3.74808
2519.98	4.55892
2522.73	5.24272
2525.49	5.27392
2528.25	4.8573
2531	5.26238
2533.75	5.3123
2536.5	5.91118
2539.25	7.224
2542.01	7.07366
2544.75	8.18497
2547.5	8.51675
2550.25	9.06459
2553	8.59318
2555.74	8.59117
2558.49	7.92189
2561.23	7.62151
2563.97	8.53542
2566.71	8.65448
2569.45	8.26238
2572.19	8.17819
2574.93	7.02373
2577.67	6.42815
2580.4	6.75833
2583.14	7.27644
2585.87	7.28026
2588.6	6.58401
2591.34	5.67199
2594.07	5.35632
2596.8	5.73576
2599.53	6.43048
2602.26	6.15522
2604.98	6.82488
2607.71	5.92292
2610.44	5.55763
2613.16	5.45309
2615.88	4.76231
2618.61	4.34225
2621.33	4.88459
2624.05	5.2936
2626.77	4.70848
2629.49	4.0503
2632.21	4.06127
2634.92	3.49564
2637.64	2.28477
2640.35	2.7834
2643.07	3.09555
2645.78	2.9244
2648.49	3.65993
2651.2	3.96485
2653.91	3.62672
2656.62	4.03194
2659.33	5.02493
2662.04	5.78932
2664.74	5.70291
2667.45	6.34696
2670.15	6.78493
2672.86	7.11455
2675.56	7.13262
2678.26	7.18606
2680.96	7.5319
2683.66	8.48362
2686.36	9.1417
2689.06	8.81754
2691.75	8.90881
2694.45	8.56061
2697.14	8.93505
2699.84	9.26037
2702.53	9.50345
2705.22	10.3674
2707.91	10.1784
2710.6	10.6204
2713.29	10.6902
2715.98	11.3858
2718.67	10.9576
2721.35	11.5731
2724.04	11.7838
2726.72	12.086
2729.4	11.6032
2732.09	12.0624
2734.77	11.2629
2737.45	10.5407
2740.13	10.3192
2742.81	9.6427
2745.48	9.66855
2748.16	9.67395
2750.84	10.2175
2753.51	9.71165
2756.19	9.76247
2758.86	9.12293
2761.53	8.92361
2764.2	8.71873
2766.87	8.73531
2769.54	7.36695
2772.21	7.17075
2774.88	6.6548
2777.54	6.21264
2780.21	5.37145
2782.87	4.58067
2785.53	3.51659
2788.2	2.52783
2790.86	1.92023
2793.52	0.576214
2796.18	-0.45466
2798.84	-0.554653
2801.49	-0.932736
2804.15	-0.869542
2806.81	0.176117
2809.46	0.00125582
2812.12	0.516227
2814.77	0.346159
2817.42	1.38943
2820.07	1.99499
2822.72	4.18412
2825.37	6.21994
2828.02	9.3905
2830.67	13.3846
2833.31	17.2302
2835.96	21.3267
2838.61	25.8676
2841.25	30.176
2843.89	35.3061
2846.53	40.5147
2849.17	46.2643
2851.81	52.6587
2854.45	59.7238
2857.09	66.6167
2859.73	73.0836
2862.36	79.8591
2865	86.3924
2867.64	92.7005
2870.27	97.6278
2872.9	101.749
2875.53	105.91
2878.16	109.539
2880.79	113.939
2883.42	117.484
2886.05	121.383
2888.68	125.788
2891.3	128.661
2893.93	133.092
2896.55	136.692
2899.18	140.795
2901.8	144.48
2904.42	148.628
2907.04	154.818
2909.66	161.831
2912.28	168.89
2914.9	176.184
2917.51	182.071
2920.13	187.665
2922.74	192.413
2925.36	196.055
2927.97	197.391
2930.59	198.048
2933.2	197.92
2935.81	195.495
2938.42	192.49
2941.02	187.669
2943.63	181.82
2946.24	175.487
2948.85	168.288
2951.45	160.792
2954.05	152.713
2956.66	145.392
2959.26	138.119
2961.86	131.496
2964.46	125.258
2967.06	119.293
2969.66	114.66
2972.26	110.132
2974.85	106.264
2977.45	100.404
2980.05	94.9631
2982.64	88.3659
2985.23	82.5081
2987.83	75.3668
2990.42	68.0257
2993.01	61.7153
2995.6	54.8984
2998.19	48.8668
3000.77	41.0423
3003.36	34.9902
3005.95	29.262
3008.53	23.7611
3011.12	18.5708
3013.7	14.2343
3016.28	10.79
3018.86	8.42519
3021.44	5.66619
3024.02	3.44973
3026.6	2.45556
3029.18	1.41689
3031.76	1.22306
3034.33	1.00577
3036.91	-0.0634256
3039.48	0.930473
3042.05	1.56347
3044.63	1.5123
3047.2	1.40565
3049.77	1.577
3052.34	2.01649
3054.91	2.4844
3057.48	2.93483
3060.04	2.81822
3062.61	2.55486
3065.17	3.24156
3067.74	3.67472
3070.3	3.59012
3072.87	2.4931
3075.43	2.72127
3077.99	2.59477
3080.55	2.60862
3083.11	1.56915
3085.67	1.40883
3088.22	0.746055
3090.78	0.809325
3093.34	1.74781
3095.89	1.42765
3098.44	1.85573
3101	3.05319
3103.55	3.9722
3106.1	4.31821
3108.65	5.28431
3111.2	6.36082
3113.75	7.77155
3116.3	9.74109
3118.84	11.0058
3121.39	12.2273
3123.93	13.2167
3126.48	14.6004
3129.02	16.234
3131.56	16.7037
3134.1	17.0802
3136.64	19.1561
3139.18	20.0521
3141.72	20.2518
3144.26	20.2917
3146.8	20.1124
3149.33	18.5468