File: data/Raman/poly_smoothed/Mbcal_20_25_15_1x_45s_532 nm_x100_100%_600 gr_mm_01.txt
#Acq. time (s)=	45
#Accumulations=	2
#Range (cm-¹)=	200...3150
#Windows=	2
#Auto scanning=	Off
#Autofocus=	Off
#Macrospot=	Off
#AutoExposure=	Off
#Spike filter=	Multiple accum.
#Delay time (s)=	0
#Binning=	1
#Readout mode=	Signal
#DeNoise=	Off
#ICS correction=	On
#Dark correction=	Off
#Inst. Process=	Off
#Detector Gain=	Best Dynamic Range
#Detector ADC=	20 kHz
#Detector temperature (°C)=	-69.85
#Instrument=	LabRAM HR Evol
#Detector=	Synapse
#Objective=	x100
#Grating=	600 gr/mm
#ND Filter=	100%
#Laser (nm)=	532
#Hole=	100.021
#Range=	Auto
#Laser Pol.=	No
#Raman. Pol.=	No
#Laser Pol. (°)=	-0.0007625
#Raman Pol. (°)=	89.9995
#Collection=	Microscope
#StageXY=	Marzhauser
#StageZ=	Marzhauser
#X (µm)=	-1180.5
#Y (µm)=	1254.7
#Z (µm)=	577.95
#Full time(mm:ss)=	3:18
#Project=
#Sample=
#Site=
#Title=	Mbcal_20_25_15_2x_45s_532 nm_x100_100%_600 gr_mm
#Remark=
#Date=	18.07.2022 10:29
#Acquired=	18.07.2022 10:29:59
#Base:Fit=	10.08.2022 10:55:08
#Base:Sub=	10.08.2022 10:55:14
#Filter:Polynom=	16.08.2022 10:07:28
#AxisType[0]=Intens
#AxisUnit[0]=Cnt
#AxisType[1]=Spectr
#AxisUnit[1]=1/cm
200.419	4.99028
204.048	8.59382
207.678	10.7879
211.304	11.0513
214.928	10.4819
218.554	8.38096
222.176	9.04645
225.798	7.95785
229.417	8.22325
233.035	9.49414
236.653	10.0436
240.268	10.0622
243.881	9.22545
247.493	8.86395
251.103	7.92487
254.715	7.84952
258.322	10.2664
261.929	11
265.534	11.1711
269.137	13.3861
272.739	15.9712
276.34	17.8704
279.939	19.0003
283.537	17.1869
287.134	16.2117
290.729	16.1634
294.323	16.4248
297.913	15.4283
301.504	14.7809
305.093	13.6535
308.682	15.2414
312.268	16.5408
315.852	15.8484
319.436	17.5719
323.018	16.7124
326.597	14.5796
330.177	14.231
333.753	15.0703
337.331	14.7261
340.906	13.472
344.478	14.0647
348.051	12.6156
351.621	11.8843
355.189	10.7587
358.757	11.3859
362.323	11.8313
365.889	9.80309
369.451	7.34149
373.012	6.77998
376.574	6.88592
380.133	7.07689
383.69	6.42408
387.245	6.60799
390.8	8.10802
394.353	10.4762
397.906	11.9992
401.456	12.2188
405.005	11.929
408.552	11.4268
412.099	12.6667
415.643	15.0863
419.187	16.9087
422.728	14.9362
426.269	13.2495
429.806	11.5014
433.344	10.8015
436.881	10.9365
440.416	10.891
443.949	11.5167
447.48	12.9979
451.011	12.7378
454.541	14.02
458.069	13.9879
461.594	13.8318
465.119	13.6274
468.642	14.3279
472.165	15.8978
475.684	16.0287
479.204	18.7599
482.721	20.9778
486.239	21.3314
489.753	23.1557
493.268	23.6722
496.779	25.6414
500.289	27.7004
503.8	27.2681
507.307	25.9613
510.813	25.8631
514.32	27.4585
517.823	27.5947
521.325	29.9092
524.826	32.185
528.325	32.6683
531.823	33.2906
535.32	32.5943
538.815	30.6941
542.309	30.1171
545.802	28.6969
549.293	27.4341
552.783	27.1842
556.271	25.8185
559.759	22.5377
563.245	22.0242
566.729	21.5875
570.213	19.2812
573.693	15.9046
577.173	14.1083
580.652	13.3557
584.13	11.9422
587.605	10.6084
591.08	9.57417
594.552	10.4849
598.025	11.1772
601.496	11.1008
604.964	11.6761
608.433	12.3801
611.898	12.6212
615.364	12.3518
618.827	12.3379
622.288	11.4636
625.75	13.9672
629.209	17.0488
632.667	17.7216
636.125	18.4758
639.58	19.7022
643.033	18.6246
646.485	19.0084
649.936	19.43
653.388	18.8645
656.836	18.6229
660.283	19.1032
663.728	20.1485
667.173	21.2768
670.616	22.9527
674.057	25.0973
677.498	25.2189
680.937	26.1808
684.375	25.4243
687.809	26.9194
691.244	27.9079
694.678	28.0491
698.111	28.879
701.54	31.9402
704.97	32.162
708.398	34.9122
711.826	37.3655
715.25	38.2677
718.675	38.9555
722.096	39.5035
725.518	39.3844
728.937	40.5096
732.357	40.3518
735.773	41.1746
739.19	42.8578
742.604	43.2931
746.018	45.5615
749.429	47.9399
752.839	50.1628
756.248	50.7199
759.657	53.3833
763.063	56.4752
766.468	58.8184
769.871	61.2193
773.273	64.1718
776.676	66.8775
780.075	69.5057
783.474	71.5964
786.871	73.5075
790.266	74.8416
793.661	76.9298
797.054	76.5502
800.446	75.6415
803.834	76.6197
807.224	79.1875
810.612	77.635
813.998	77.1005
817.384	77.8906
820.766	76.9592
824.149	77.221
827.531	78.3802
830.909	82.0075
834.288	83.9156
837.666	84.0234
841.041	85.2771
844.416	85.5786
847.788	83.413
851.161	81.3418
854.53	78.3934
857.901	75.7368
861.268	73.9304
864.633	70.1964
868	67.018
871.363	63.7913
874.725	60.1977
878.088	56.2772
881.447	52.1213
884.805	48.632
888.162	47.6296
891.518	43.9825
894.872	42.7237
898.225	43.2327
901.577	44.6952
904.928	45.0475
908.277	49.614
911.625	52.681
914.972	54.931
918.318	55.6568
921.662	56.1203
925.005	57.2687
928.347	56.4561
931.686	54.5521
935.025	54.4844
938.363	53.0747
941.698	52.8926
945.034	50.2423
948.368	46.8849
951.699	45.9584
955.031	42.0438
958.36	40.8951
961.689	36.574
965.016	35.6989
968.343	34.1015
971.666	33.6929
974.991	31.6016
978.312	31.2017
981.632	30.0251
984.953	30.0062
988.27	29.4017
991.587	28.7813
994.902	27.5969
998.216	26.0881
1001.53	25.1492
1004.84	24.935
1008.15	25.2127
1011.46	25.1033
1014.77	26.3927
1018.07	27.5306
1021.38	27.3625
1024.68	27.5042
1027.99	28.4086
1031.29	29.0087
1034.59	28.9006
1037.89	28.3303
1041.18	27.4425
1044.48	27.192
1047.77	27.7182
1051.07	26.3869
1054.36	24.8588
1057.65	23.2512
1060.94	22.288
1064.23	20.8136
1067.52	21.1437
1070.8	20.8697
1074.09	20.9346
1077.37	20.3307
1080.65	19.3075
1083.93	18.4736
1087.21	22.0564
1090.49	23.7447
1093.77	24.8383
1097.04	25.8391
1100.32	25.7945
1103.59	25.6167
1106.86	26.0806
1110.13	25.5163
1113.4	24.73
1116.67	23.2146
1119.94	23.1769
1123.2	20.0512
1126.47	18.9548
1129.73	18.2046
1132.99	15.7506
1136.25	14.4449
1139.51	13.1835
1142.77	11.1349
1146.03	10.0535
1149.28	9.42455
1152.54	6.5545
1155.79	5.37467
1159.04	3.76377
1162.29	1.13814
1165.54	1.66741
1168.79	2.22295
1172.04	2.34912
1175.28	2.50739
1178.53	3.34066
1181.77	4.17594
1185.01	6.60667
1188.25	8.53238
1191.49	9.26934
1194.73	8.39337
1197.96	10.0209
1201.2	12.3123
1204.43	14.2591
1207.66	16.9663
1210.9	18.8125
1214.13	21.5424
1217.36	23.0358
1220.58	25.6603
1223.81	26.9918
1227.04	29.8154
1230.26	31.8978
1233.48	33.5401
1236.71	35.5043
1239.93	35.2884
1243.14	36.3105
1246.36	38.5661
1249.58	39.7534
1252.8	41.3996
1256.01	42.6977
1259.22	44.3599
1262.43	46.7961
1265.64	47.25
1268.85	46.8348
1272.06	47.4239
1275.27	49.2924
1278.48	52.5004
1281.68	54.8818
1284.88	56.427
1288.08	60.2008
1291.28	63.6733
1294.48	65.9939
1297.68	67.0242
1300.88	69.5257
1304.07	72.6033
1307.27	76.0865
1310.46	76.8731
1313.65	77.934
1316.85	78.9148
1320.03	77.8593
1323.22	78.0308
1326.41	78.8284
1329.6	78.8446
1332.78	78.6269
1335.96	77.0535
1339.15	75.7949
1342.33	73.1167
1345.51	69.2941
1348.69	67.1636
1351.86	65.4351
1355.04	63.0659
1358.21	59.7474
1361.39	58.1989
1364.56	57.478
1367.73	55.5184
1370.9	54.1411
1374.07	52.9961
1377.24	51.7396
1380.41	51.7669
1383.57	49.8881
1386.73	49.1948
1389.9	48.124
1393.06	47.5713
1396.22	47.2629
1399.38	47.4713
1402.54	49.1676
1405.69	49.3536
1408.85	51.943
1412	52.9801
1415.16	56.8429
1418.31	59.0653
1421.46	64.0746
1424.61	68.9675
1427.76	75.3823
1430.9	79.7072
1434.05	84.4516
1437.2	89.778
1440.34	93.9104
1443.48	98.5513
1446.62	99.877
1449.76	100.726
1452.9	101.697
1456.04	101.809
1459.17	100.642
1462.31	99.4793
1465.44	97.0851
1468.58	92.8549
1471.71	89.2053
1474.84	83.8964
1477.97	79.1123
1481.1	75.1713
1484.22	71.058
1487.35	64.4164
1490.47	59.0243
1493.59	54.798
1496.72	49.909
1499.84	46.5992
1502.96	44.1162
1506.08	39.9536
1509.19	35.0986
1512.31	31.9673
1515.42	29.3159
1518.54	26.5826
1521.65	24.6023
1524.76	23.2926
1527.87	23.8334
1530.98	23.8905
1534.09	24.3374
1537.2	24.4366
1540.3	25.6009
1543.41	27.2364
1546.51	28.1969
1549.61	30.1485
1552.71	31.4778
1555.81	35.8605
1558.91	39.5489
1562.01	39.655
1565.1	40.9268
1568.2	43.5442
1571.29	46.1736
1574.38	49.3746
1577.48	51.5128
1580.57	53.5605
1583.65	55.4125
1586.74	57.4159
1589.83	59.6663
1592.92	61.2639
1596	61.0914
1599.08	61.3802
1602.16	61.3463
1605.24	59.9964
1608.32	60.3467
1611.4	58.7737
1614.48	57.174
1617.56	56.9666
1620.63	56.1806
1623.71	56.122
1626.78	56.2756
1629.85	56.6809
1632.92	58.1931
1635.99	57.1412
1639.06	57.1881
1642.12	60.1273
1645.19	63.7165
1648.25	65.7911
1651.32	67.4172
1654.38	69.776
1657.44	69.5875
1660.5	69.9803
1663.56	69.0299
1666.62	66.8819
1669.67	63.7481
1672.73	59.95
1675.79	56.7492
1678.84	52.5828
1681.89	47.8032
1684.94	44.1927
1687.99	39.5361
1691.04	35.4297
1694.08	30.4219
1697.13	26.6791
1700.18	22.6051
1703.22	19.2863
1706.26	15.5696
1709.3	12.8287
1712.35	10.7804
1715.39	9.54681
1718.42	9.86881
1721.46	9.27402
1724.5	8.3977
1727.53	6.7359
1730.56	5.96156
1733.6	4.99055
1736.63	4.16032
1739.66	3.26664
1742.69	0.849714
1745.71	0.691325
1748.74	0.355133
1751.77	0.831214
1754.79	1.32058
1757.81	1.08483
1760.84	0.616107
1763.86	0.875851
1766.88	-0.0663615
1769.9	-0.0691381
1772.91	1.66544
1775.93	1.60964
1778.95	2.01684
1781.96	0.933054
1784.97	1.53329
1787.99	2.25222
1791	2.54447
1794.01	2.15972
1797.01	2.58166
1800.02	2.54096
1803.03	2.68812
1806.03	3.03656
1809.04	2.99281
1812.04	2.67101
1815.04	3.00217
1818.04	3.4857
1821.04	4.56002
1824.04	4.58288
1827.04	4.24822
1830.03	4.31127
1833.03	5.17693
1836.02	5.03593
1839.02	5.3282
1842.01	5.87123
1845	6.59599
1847.99	6.50084
1850.98	6.68621
1853.96	5.31664
1856.95	5.20063
1859.94	4.82691
1862.92	4.58741
1865.9	3.26329
1868.88	2.36536
1871.86	1.46906
1874.84	1.29231
1877.82	1.40015
1880.8	1.42958
1882.58	0.968386
1885.57	0.78316
1888.56	0.91025
1891.54	1.54539
1894.53	1.48301
1897.51	2.04193
1900.5	0.97226
1903.48	1.50653
1906.46	0.819843
1909.44	0.75349
1912.42	0.970264
1915.4	0.737574
1918.37	0.735122
1921.35	1.22228
1924.32	0.849744
1927.3	1.86257
1930.27	2.66427
1933.24	2.0917
1936.21	2.19031
1939.18	1.88097
1942.15	1.47231
1945.11	2.15047
1948.08	3.54946
1951.04	5.34691
1954.01	4.55656
1956.97	3.60603
1959.93	4.0063
1962.89	4.83927
1965.85	5.55345
1968.81	5.18969
1971.77	3.83068
1974.72	3.62457
1977.68	3.90202
1980.63	4.11907
1983.58	3.85575
1986.53	3.04426
1989.48	3.45081
1992.43	3.61464
1995.38	3.95043
1998.33	3.3426
2001.27	3.23889
2004.22	3.77648
2007.16	3.36216
2010.11	4.09617
2013.05	4.28887
2015.99	4.16634
2018.93	5.09278
2021.87	5.65089
2024.8	4.55799
2027.74	4.10995
2030.68	4.34469
2033.61	4.69725
2036.54	5.67295
2039.48	4.81594
2042.41	5.13542
2045.34	6.73991
2048.27	6.76709
2051.19	7.79211
2054.12	6.21887
2057.05	5.64608
2059.97	6.88697
2062.9	7.47663
2065.82	7.882
2068.74	9.03518
2071.66	9.92972
2074.58	11.5276
2077.5	11.5339
2080.41	12.3067
2083.33	12.244
2086.24	12.9822
2089.16	14.3961
2092.07	15.6111
2094.98	15.2371
2097.89	16.2044
2100.8	17.3602
2103.71	17.5355
2106.62	19.7341
2109.53	20.7108
2112.43	22.0406
2115.33	22.7669
2118.24	23.4332
2121.14	24.2316
2124.04	25.7026
2126.94	27.5831
2129.84	29.4588
2132.74	32.4271
2135.63	34.0469
2138.53	36.041
2141.43	37.669
2144.32	40.0297
2147.21	41.3467
2150.1	42.9544
2152.99	44.6209
2155.88	46.3204
2158.77	47.2489
2161.66	49.4876
2164.55	49.0813
2167.43	50.2114
2170.31	51.1874
2173.2	51.4755
2176.08	52.1055
2178.96	51.1446
2181.84	50.5186
2184.72	48.8395
2187.6	47.9038
2190.47	47.0352
2193.35	45.7805
2196.23	44.7141
2199.1	43.7738
2201.97	40.8527
2204.84	38.3627
2207.71	35.9344
2210.58	33.3571
2213.45	33.2105
2216.32	29.1507
2219.19	26.4883
2222.05	25.1739
2224.92	22.918
2227.78	22.0543
2230.64	20.7416
2233.5	18.6469
2236.36	18.9802
2239.22	18.4747
2242.08	18.1354
2244.94	16.7864
2247.79	15.9088
2250.65	15.8028
2253.5	15.8582
2256.36	15.3778
2259.21	14.0974
2262.06	13.9468
2264.91	14.0514
2267.76	13.1659
2270.6	11.345
2273.45	10.0061
2276.3	10.9809
2279.14	9.33447
2281.98	9.42002
2284.83	9.61065
2287.67	9.65026
2290.51	9.39477
2293.35	9.6468
2296.19	10.0534
2299.02	10.4041
2301.86	11.0477
2304.7	12.3165
2307.53	13.8951
2310.36	15.238
2313.2	15.7545
2316.03	15.4126
2318.86	15.9955
2321.69	15.4191
2324.51	14.8942
2327.34	13.6419
2330.17	11.5001
2332.99	10.5213
2335.82	10.1463
2338.64	8.57199
2341.46	7.72555
2344.28	7.47671
2347.1	6.88899
2349.92	5.53806
2352.74	4.8766
2355.56	4.38253
2358.37	3.18803
2361.19	3.28969
2364	4.20428
2366.82	5.06881
2369.63	5.09475
2372.44	5.14289
2375.25	5.20952
2378.06	5.55857
2380.86	5.11681
2383.67	4.53944
2386.48	4.36841
2389.28	4.62939
2392.09	3.70653
2394.89	4.01233
2397.69	3.65585
2400.49	4.01594
2403.29	5.27122
2406.09	5.63365
2408.89	4.74738
2411.69	4.75922
2414.48	6.19345
2417.28	6.97354
2420.07	7.68693
2422.86	8.48173
2425.65	9.3906
2428.45	10.6675
2431.23	10.6363
2434.02	9.65357
2436.81	8.71185
2439.6	7.20491
2442.38	7.31749
2445.17	5.95623
2447.95	5.46007
2450.73	5.64325
2453.52	5.36196
2456.3	5.52298
2459.08	5.42567
2461.85	5.71586
2464.63	5.37222
2467.41	4.89328
2470.19	3.89207
2472.96	2.45628
2475.73	2.78411
2478.51	3.5703
2481.28	4.9552
2484.05	5.40028
2486.82	5.03565
2489.59	5.30414
2492.35	4.76492
2495.12	4.77885
2497.89	3.6198
2500.65	2.79026
2503.42	1.82414
2506.18	1.73235
2508.94	1.05746
2511.7	-0.0181481
2514.46	0.384078
2517.22	1.51814
2519.98	2.51539
2522.73	2.63427
2525.49	2.9984
2528.25	2.94649
2531	3.30479
2533.75	2.95628
2536.5	3.21364
2539.25	3.95128
2542.01	6.13403
2544.75	7.81636
2547.5	8.05139
2550.25	8.4748
2553	9.27977
2555.74	10.1801
2558.49	11.1923
2561.23	12.0113
2563.97	12.4546
2566.71	12.6616
2569.45	12.1438
2572.19	11.8149
2574.93	11.4258
2577.67	10.3356
2580.4	10.533
2583.14	10.8731
2585.87	10.9234
2588.6	10.3912
2591.34	9.87283
2594.07	8.92424
2596.8	8.2751
2599.53	7.28961
2602.26	6.6126
2604.98	6.82227
2607.71	7.28758
2610.44	6.72235
2613.16	7.29903
2615.88	7.09358
2618.61	7.43183
2621.33	7.31463
2624.05	7.57835
2626.77	7.18939
2629.49	6.53755
2632.21	7.29328
2634.92	7.71865
2637.64	8.54271
2640.35	9.18713
2643.07	8.7356
2645.78	9.59306
2648.49	10.2333
2651.2	9.9651
2653.91	9.78484
2656.62	9.13394
2659.33	8.22316
2662.04	7.74107
2664.74	7.51852
2667.45	7.09079
2670.15	7.66405
2672.86	8.68805
2675.56	8.08281
2678.26	7.17637
2680.96	7.72177
2683.66	8.03534
2686.36	8.23094
2689.06	8.15598
2691.75	8.72709
2694.45	10.0398
2697.14	11.6406
2699.84	12.0127
2702.53	13.1046
2705.22	15.2673
2707.91	16.1238
2710.6	16.3411
2713.29	16.8841
2715.98	16.4489
2718.67	17.1121
2721.35	17.1198
2724.04	16.6169
2726.72	17.5001
2729.4	17.2068
2732.09	16.7908
2734.77	15.9771
2737.45	15.7818
2740.13	15.1384
2742.81	14.0662
2745.48	12.8287
2748.16	12.2789
2750.84	11.7829
2753.51	10.2802
2756.19	9.05662
2758.86	8.41068
2761.53	8.51238
2764.2	7.49865
2766.87	7.20194
2769.54	7.44775
2772.21	7.03119
2774.88	6.33144
2777.54	5.74796
2780.21	5.06565
2782.87	4.19978
2785.53	5.10225
2788.2	4.72424
2790.86	4.047
2793.52	3.33094
2796.18	2.60696
2798.84	1.50612
2801.49	1.51067
2804.15	1.04446
2806.81	-0.649652
2809.46	-2.3353
2812.12	-1.83368
2814.77	-0.523167
2817.42	0.439525
2820.07	3.7953
2822.72	7.0616
2825.37	12.2339
2828.02	16.3955
2830.67	21.053
2833.31	26.705
2835.96	32.8728
2838.61	38.7886
2841.25	45.7657
2843.89	54.1988
2846.53	62.6512
2849.17	71.706
2851.81	80.8041
2854.45	90.3982
2857.09	99.5623
2859.73	107.916
2862.36	116.315
2865	123.514
2867.64	130.788
2870.27	134.934
2872.9	140.753
2875.53	146.614
2878.16	152.724
2880.79	157.956
2883.42	163.976
2886.05	169.542
2888.68	174.361
2891.3	178.748
2893.93	184.218
2896.55	189.719
2899.18	196.724
2901.8	204.004
2904.42	213.532
2907.04	223.851
2909.66	234.887
2912.28	246.755
2914.9	259.591
2917.51	271.753
2920.13	281.492
2922.74	290.186
2925.36	295.72
2927.97	299.873
2930.59	300.665
2933.2	298.661
2935.81	296.733
2938.42	291.516
2941.02	284.572
2943.63	274.904
2946.24	264.451
2948.85	253.14
2951.45	241.444
2954.05	227.724
2956.66	215.274
2959.26	203.802
2961.86	192.116
2964.46	181.011
2967.06	171.782
2969.66	163.201
2972.26	155.228
2974.85	146.894
2977.45	140.94
2980.05	133.759
2982.64	125.782
2985.23	118.066
2987.83	109.02
2990.42	98.8331
2993.01	88.4786
2995.6	79.1171
2998.19	70.7164
3000.77	62.7971
3003.36	53.0241
3005.95	45.4136
3008.53	38.0312
3011.12	31.5125
3013.7	25.1346
3016.28	19.3662
3018.86	14.4937
3021.44	10.5453
3024.02	7.22715
3026.6	5.13824
3029.18	3.9218
3031.76	2.31541
3034.33	1.94354
3036.91	2.55196
3039.48	4.29334
3042.05	4.92931
3044.63	5.30694
3047.2	5.64137
3049.77	5.43692
3052.34	5.23123
3054.91	6.08318
3057.48	7.4751
3060.04	8.41994
3062.61	8.77571
3065.17	8.7599
3067.74	8.52356
3070.3	7.84188
3072.87	7.04418
3075.43	5.20482
3077.99	4.13595
3080.55	3.6077
3083.11	3.42392
3085.67	2.51378
3088.22	1.90818
3090.78	1.48188
3093.34	1.60095
3095.89	2.32124
3098.44	4.03641
3101	4.29652
3103.55	4.26474
3106.1	5.06237
3108.65	6.91825
3111.2	8.09258
3113.75	9.42046
3116.3	11.0515
3118.84	12.1312
3121.39	12.8974
3123.93	14.2251
3126.48	15.2741
3129.02	16.2491
3131.56	17.028
3134.1	17.6849
3136.64	19.0205
3139.18	19.9062
3141.72	20.5958
3144.26	20.9129
3146.8	20.8963
3149.33	23.1088