File: data/Raman/poly_smoothed/Mbcal_20_25_19_1x_45s_532 nm_x100_100%_600 gr_mm_01.txt
#Acq. time (s)=	45
#Accumulations=	2
#Range (cm-¹)=	200...3150
#Windows=	2
#Auto scanning=	Off
#Autofocus=	Off
#Macrospot=	Off
#AutoExposure=	Off
#Spike filter=	Multiple accum.
#Delay time (s)=	0
#Binning=	1
#Readout mode=	Signal
#DeNoise=	Off
#ICS correction=	On
#Dark correction=	Off
#Inst. Process=	Off
#Detector Gain=	Best Dynamic Range
#Detector ADC=	20 kHz
#Detector temperature (°C)=	-69.85
#Instrument=	LabRAM HR Evol
#Detector=	Synapse
#Objective=	x100
#Grating=	600 gr/mm
#ND Filter=	100%
#Laser (nm)=	532
#Hole=	100.021
#Range=	Auto
#Laser Pol.=	No
#Raman. Pol.=	No
#Laser Pol. (°)=	-0.0007625
#Raman Pol. (°)=	89.9995
#Collection=	Microscope
#StageXY=	Marzhauser
#StageZ=	Marzhauser
#X (µm)=	-1170.7
#Y (µm)=	1261.6
#Z (µm)=	578.2
#Full time(mm:ss)=	3:18
#Project=
#Sample=
#Site=
#Title=	Mbcal_20_25_19_2x_45s_532 nm_x100_100%_600 gr_mm
#Remark=
#Date=	18.07.2022 10:49
#Acquired=	18.07.2022 10:49:06
#Base:Fit=	10.08.2022 10:55:08
#Base:Sub=	10.08.2022 10:55:14
#Filter:Polynom=	16.08.2022 10:07:28
#AxisType[0]=Intens
#AxisUnit[0]=Cnt
#AxisType[1]=Spectr
#AxisUnit[1]=1/cm
200.419	13.8636
204.048	11.3945
207.678	7.69401
211.304	5.51143
214.928	3.65297
218.554	3.69554
222.176	3.50573
225.798	3.36487
229.417	3.87195
233.035	3.49447
236.653	5.31862
240.268	7.0797
243.881	7.10605
247.493	7.81437
251.103	7.78107
254.715	9.00064
258.322	10.7811
261.929	10.1649
265.534	11.4442
269.137	12.0179
272.739	9.85574
276.34	8.24566
279.939	8.54143
283.537	7.26508
287.134	5.37682
290.729	5.9742
294.323	5.70827
297.913	6.52341
301.504	6.64928
305.093	8.39917
308.682	10.0592
312.268	11.0715
315.852	11.2438
319.436	12.3635
323.018	13.5542
326.597	15.6085
330.177	15.1056
333.753	13.9092
337.331	13.5311
340.906	15.0618
344.478	15.2372
348.051	15.117
351.621	14.0751
355.189	13.9199
358.757	12.2202
362.323	11.591
365.889	11.4921
369.451	12.3327
373.012	12.266
376.574	12.4731
380.133	13.3981
383.69	14.8522
387.245	16.4606
390.8	16.902
394.353	17.2058
397.906	19.2742
401.456	17.9903
405.005	18.7771
408.552	18.4625
412.099	19.9011
415.643	19.236
419.187	17.7551
422.728	18.2801
426.269	17.9625
429.806	18.7401
433.344	18.1131
436.881	17.3941
440.416	16.9221
443.949	15.8069
447.48	17.4903
451.011	18.5282
454.541	18.9533
458.069	21.6336
461.594	22.2051
465.119	22.4943
468.642	23.9465
472.165	24.6642
475.684	24.1971
479.204	24.402
482.721	25.6701
486.239	26.038
489.753	24.1678
493.268	26.2999
496.779	25.5951
500.289	25.2517
503.8	25.7341
507.307	26.2906
510.813	25.0656
514.32	26.0657
517.823	26.3452
521.325	24.7371
524.826	24.2763
528.325	23.434
531.823	25.1976
535.32	25.5015
538.815	25.3915
542.309	23.4637
545.802	21.5068
549.293	19.296
552.783	16.8767
556.271	15.6773
559.759	15.1667
563.245	14.0565
566.729	13.5439
570.213	12.5739
573.693	11.935
577.173	12.7789
580.652	11.6991
584.13	10.7791
587.605	10.023
591.08	10.7853
594.552	11.2629
598.025	13.1105
601.496	13.9507
604.964	14.0269
608.433	13.7351
611.898	15.3879
615.364	15.5236
618.827	15.8232
622.288	13.8022
625.75	14.0914
629.209	13.5437
632.667	14.2243
636.125	15.4245
639.58	16.7552
643.033	17.8023
646.485	18.5907
649.936	18.4795
653.388	17.8092
656.836	18.9207
660.283	19.0635
663.728	18.4037
667.173	16.9853
670.616	17.7486
674.057	19.2521
677.498	22.4974
680.937	23.9819
684.375	25.2319
687.809	27.1275
691.244	27.9377
694.678	28.8995
698.111	29.9852
701.54	31.0486
704.97	33.2922
708.398	35.7874
711.826	38.2903
715.25	39.4442
718.675	40.4979
722.096	42.9295
725.518	44.7484
728.937	45.9234
732.357	45.5375
735.773	47.1229
739.19	48.0918
742.604	48.5712
746.018	50.602
749.429	52.8731
752.839	54.8247
756.248	59.2241
759.657	60.5728
763.063	62.9787
766.468	65.2469
769.871	68.4413
773.273	69.9643
776.676	71.2988
780.075	72.9682
783.474	75.2171
786.871	76.5008
790.266	78.7036
793.661	79.8345
797.054	81.5737
800.446	83.2781
803.834	83.6934
807.224	84.5981
810.612	85.1017
813.998	84.6463
817.384	83.2907
820.766	81.6557
824.149	81.1764
827.531	81.2809
830.909	82.1722
834.288	82.5126
837.666	82.3504
841.041	83.0014
844.416	81.838
847.788	81.8479
851.161	80.9499
854.53	78.3473
857.901	75.4522
861.268	73.7268
864.633	72.714
868	71.4774
871.363	69.0588
874.725	66.4865
878.088	65.2775
881.447	62.9826
884.805	59.6916
888.162	56.41
891.518	55.033
894.872	53.7548
898.225	52.5091
901.577	51.364
904.928	52.9431
908.277	53.1097
911.625	53.4476
914.972	53.3332
918.318	54.9427
921.662	54.2077
925.005	53.7496
928.347	53.7973
931.686	52.9022
935.025	50.9964
938.363	50.0197
941.698	47.7765
945.034	47.5518
948.368	45.4392
951.699	42.8374
955.031	39.5022
958.36	36.7001
961.689	33.1948
965.016	31.3312
968.343	29.1926
971.666	29.0115
974.991	30.6198
978.312	31.0969
981.632	31.5002
984.953	31.3353
988.27	30.5425
991.587	29.0432
994.902	29.1976
998.216	31.3052
1001.53	30.7088
1004.84	31.8783
1008.15	32.6707
1011.46	33.3036
1014.77	34.5706
1018.07	36.3933
1021.38	36.6725
1024.68	37.1474
1027.99	37.5276
1031.29	37.6983
1034.59	35.8109
1037.89	34.5457
1041.18	31.0731
1044.48	31.597
1047.77	31.3825
1051.07	30.7648
1054.36	30.2113
1057.65	28.5519
1060.94	27.8035
1064.23	25.6625
1067.52	25.5354
1070.8	26.3236
1074.09	26.8916
1077.37	29.2425
1080.65	30.1526
1083.93	30.7224
1087.21	32.2424
1090.49	34.6756
1093.77	35.5799
1097.04	37.9762
1100.32	37.8626
1103.59	37.5624
1106.86	37.9322
1110.13	38.1518
1113.4	36.05
1116.67	33.2517
1119.94	29.8182
1123.2	26.8696
1126.47	22.2687
1129.73	20.4898
1132.99	17.2482
1136.25	15.214
1139.51	12.7798
1142.77	11.208
1146.03	9.96532
1149.28	9.6067
1152.54	7.58703
1155.79	6.29394
1159.04	6.1257
1162.29	5.68083
1165.54	4.03671
1168.79	5.05786
1172.04	5.46936
1175.28	6.06327
1178.53	7.21565
1181.77	7.33869
1185.01	9.70358
1188.25	11.385
1191.49	11.8883
1194.73	11.2897
1197.96	11.206
1201.2	13.3441
1204.43	15.0534
1207.66	17.9188
1210.9	21.8517
1214.13	23.7753
1217.36	24.9428
1220.58	27.4816
1223.81	30.4509
1227.04	32.7173
1230.26	34.5361
1233.48	36.236
1236.71	39.0158
1239.93	41.4306
1243.14	42.3507
1246.36	46.4763
1249.58	48.4327
1252.8	50.4838
1256.01	52.7446
1259.22	55.2017
1262.43	56.2674
1265.64	56.489
1268.85	56.7669
1272.06	58.2158
1275.27	58.1053
1278.48	61.071
1281.68	64.0151
1284.88	65.7048
1288.08	67.2661
1291.28	69.141
1294.48	69.9953
1297.68	71.951
1300.88	73.8464
1304.07	75.1551
1307.27	74.6596
1310.46	75.5277
1313.65	77.5657
1316.85	78.4599
1320.03	79.6176
1323.22	82.7722
1326.41	83.311
1329.6	82.7933
1332.78	82.2722
1335.96	80.8555
1339.15	79.1504
1342.33	77.982
1345.51	76.0582
1348.69	74.7817
1351.86	72.1341
1355.04	69.99
1358.21	68.411
1361.39	65.6959
1364.56	63.2659
1367.73	60.2457
1370.9	56.2704
1374.07	55.0157
1377.24	53.2264
1380.41	50.4842
1383.57	49.0975
1386.73	49.8944
1389.9	50.4483
1393.06	51.5816
1396.22	51.234
1399.38	51.8985
1402.54	50.9923
1405.69	50.948
1408.85	52.5031
1412	55.4554
1415.16	58.9551
1418.31	62.1308
1421.46	66.5981
1424.61	71.0104
1427.76	76.8216
1430.9	81.5503
1434.05	85.8902
1437.2	89.3
1440.34	92.3521
1443.48	95.5206
1446.62	97.296
1449.76	98.4641
1452.9	99.0377
1456.04	99.7947
1459.17	100.005
1462.31	99.6019
1465.44	98.3594
1468.58	93.6493
1471.71	87.498
1474.84	81.1538
1477.97	76.0406
1481.1	70.2414
1484.22	66.1553
1487.35	62.4799
1490.47	58.6684
1493.59	53.4512
1496.72	49.9556
1499.84	46.2048
1502.96	43.516
1506.08	41.6727
1509.19	38.2692
1512.31	35.3571
1515.42	34.6899
1518.54	32.6308
1521.65	31.1067
1524.76	29.9194
1527.87	29.4228
1530.98	30.1416
1534.09	31.2184
1537.2	32.6753
1540.3	33.254
1543.41	34.1094
1546.51	33.7458
1549.61	35.5773
1552.71	37.0468
1555.81	39.1882
1558.91	40.6103
1562.01	41.4131
1565.1	42.0028
1568.2	40.8992
1571.29	41.8576
1574.38	42.9852
1577.48	44.0396
1580.57	45.9585
1583.65	45.6683
1586.74	46.2678
1589.83	47.2273
1592.92	48.3669
1596	47.0392
1599.08	47.3524
1602.16	46.9238
1605.24	48.2201
1608.32	48.1944
1611.4	48.6305
1614.48	48.8997
1617.56	49.3202
1620.63	49.5799
1623.71	51.0213
1626.78	52.836
1629.85	54.6299
1632.92	57.9725
1635.99	58.8228
1639.06	62.1379
1642.12	64.7342
1645.19	66.9912
1648.25	69.7177
1651.32	72.2552
1654.38	73.2367
1657.44	73.7713
1660.5	72.0146
1663.56	70.7869
1666.62	67.6665
1669.67	65.1572
1672.73	61.7718
1675.79	58.2569
1678.84	54.3237
1681.89	48.914
1684.94	43.1908
1687.99	37.6354
1691.04	32.5953
1694.08	28.1547
1697.13	24.2746
1700.18	21.9458
1703.22	19.6557
1706.26	17.4629
1709.3	15.3303
1712.35	13.1461
1715.39	11.2532
1718.42	9.0027
1721.46	8.3821
1724.5	8.67016
1727.53	6.72924
1730.56	4.24955
1733.6	2.87025
1736.63	2.20761
1739.66	1.32289
1742.69	1.2112
1745.71	1.84186
1748.74	1.19076
1751.77	0.616529
1754.79	1.25609
1757.81	1.73344
1760.84	1.62255
1763.86	2.09069
1766.88	2.79627
1769.9	3.24932
1772.91	3.94838
1775.93	4.18326
1778.95	5.02979
1781.96	5.04315
1784.97	4.99792
1787.99	4.73442
1791	4.98315
1794.01	4.26201
1797.01	4.27464
1800.02	4.09109
1803.03	3.83488
1806.03	3.63869
1809.04	4.18869
1812.04	3.88701
1815.04	2.28228
1818.04	2.19083
1821.04	2.75958
1824.04	2.96705
1827.04	3.4199
1830.03	3.68646
1833.03	3.74399
1836.02	3.2933
1839.02	3.77691
1842.01	3.66885
1845	4.28674
1847.99	4.45882
1850.98	5.0643
1853.96	4.98091
1856.95	4.87749
1859.94	5.67885
1862.92	6.11181
1865.9	5.98699
1868.88	6.22795
1871.86	7.44399
1874.84	7.45828
1877.82	6.89533
1880.8	6.21401
1882.58	5.10416
1885.57	5.06825
1888.56	4.91282
1891.54	5.24851
1894.53	4.97939
1897.51	5.60584
1900.5	5.68172
1903.48	5.585
1906.46	4.09908
1909.44	3.93336
1912.42	3.77551
1915.4	3.45297
1918.37	3.52127
1921.35	3.87096
1924.32	3.60683
1927.3	3.85949
1930.27	3.53443
1933.24	2.85555
1936.21	2.60165
1939.18	1.81926
1942.15	1.579
1945.11	1.89794
1948.08	0.922774
1951.04	1.31653
1954.01	2.07795
1956.97	3.04042
1959.93	3.43899
1962.89	3.29155
1965.85	4.1643
1968.81	5.41544
1971.77	5.89914
1974.72	5.69806
1977.68	4.94954
1980.63	4.69086
1983.58	4.13547
1986.53	4.4795
1989.48	4.46815
1992.43	5.06318
1995.38	5.47519
1998.33	5.5889
2001.27	5.72695
2004.22	4.65541
2007.16	5.18404
2010.11	5.16097
2013.05	5.49257
2015.99	5.35605
2018.93	5.94487
2021.87	7.21772
2024.8	8.26389
2027.74	8.35724
2030.68	8.37878
2033.61	8.69185
2036.54	9.72504
2039.48	9.72218
2042.41	10.6111
2045.34	10.5061
2048.27	10.3055
2051.19	10.3019
2054.12	9.24439
2057.05	9.71392
2059.97	9.48459
2062.9	10.2617
2065.82	9.82142
2068.74	10.1793
2071.66	9.91936
2074.58	9.81189
2077.5	9.0393
2080.41	9.33586
2083.33	8.27905
2086.24	7.53022
2089.16	7.71263
2092.07	8.55462
2094.98	8.25764
2097.89	8.83622
2100.8	10.0326
2103.71	11.2153
2106.62	13.1699
2109.53	14.3321
2112.43	15.344
2115.33	17.2715
2118.24	19.1047
2121.14	20.3245
2124.04	22.244
2126.94	24.2118
2129.84	26.5783
2132.74	27.7462
2135.63	30.1502
2138.53	32.3391
2141.43	34.7723
2144.32	36.9142
2147.21	38.8413
2150.1	40.6846
2152.99	43.4005
2155.88	45.5307
2158.77	47.9934
2161.66	49.2696
2164.55	51.3893
2167.43	53.3301
2170.31	55.1183
2173.2	56.3208
2176.08	55.528
2178.96	55.7156
2181.84	55.3726
2184.72	54.6648
2187.6	54.0213
2190.47	52.7153
2193.35	50.5765
2196.23	48.1723
2199.1	45.6693
2201.97	43.2269
2204.84	39.8947
2207.71	37.2815
2210.58	34.4351
2213.45	32.1772
2216.32	29.4954
2219.19	27.6805
2222.05	25.9751
2224.92	24.5354
2227.78	22.9254
2230.64	20.7217
2233.5	19.5665
2236.36	17.8698
2239.22	17.2756
2242.08	15.8573
2244.94	15.2697
2247.79	14.8573
2250.65	13.8205
2253.5	13.5264
2256.36	13.4454
2259.21	13.57
2262.06	13.2028
2264.91	13.1433
2267.76	13.4369
2270.6	12.2318
2273.45	11.6275
2276.3	11.4391
2279.14	10.9193
2281.98	10.342
2284.83	9.87531
2287.67	9.46666
2290.51	8.7478
2293.35	7.36273
2296.19	6.44393
2299.02	6.83108
2301.86	7.3811
2304.7	7.43315
2307.53	8.03108
2310.36	9.17732
2313.2	8.16584
2316.03	7.7364
2318.86	7.93153
2321.69	8.51721
2324.51	8.93992
2327.34	9.88441
2330.17	9.3007
2332.99	8.45174
2335.82	7.06444
2338.64	6.16309
2341.46	5.90108
2344.28	5.24356
2347.1	4.67592
2349.92	3.65886
2352.74	2.50123
2355.56	1.38879
2358.37	0.87825
2361.19	-0.274288
2364	-0.022751
2366.82	0.810334
2369.63	1.63771
2372.44	0.961723
2375.25	0.161618
2378.06	0.594411
2380.86	-0.978537
2383.67	-1.21639
2386.48	-0.444209
2389.28	-0.231712
2392.09	1.16317
2394.89	1.00007
2397.69	1.21865
2400.49	0.750313
2403.29	0.595099
2406.09	2.34174
2408.89	3.07962
2411.69	3.27624
2414.48	3.89235
2417.28	4.42945
2420.07	5.744
2422.86	5.85203
2425.65	6.23666
2428.45	6.47555
2431.23	6.8285
2434.02	7.01688
2436.81	7.4288
2439.6	7.50587
2442.38	6.67811
2445.17	6.9205
2447.95	5.97823
2450.73	5.53821
2453.52	5.76084
2456.3	6.6548
2459.08	6.56601
2461.85	6.4715
2464.63	6.47157
2467.41	6.20814
2470.19	5.28755
2472.96	5.10073
2475.73	4.87975
2478.51	3.72261
2481.28	3.15494
2484.05	3.07025
2486.82	3.08778
2489.59	1.79359
2492.35	1.43419
2495.12	1.78882
2497.89	1.5096
2500.65	1.39853
2503.42	1.23968
2506.18	1.2798
2508.94	0.351495
2511.7	0.463868
2514.46	1.46107
2517.22	0.743152
2519.98	1.35664
2522.73	2.61767
2525.49	2.93106
2528.25	2.93104
2531	3.15266
2533.75	3.44827
2536.5	4.19205
2539.25	4.22905
2542.01	4.42407
2544.75	4.53143
2547.5	4.83472
2550.25	5.35793
2553	5.94983
2555.74	5.68354
2558.49	6.43065
2561.23	6.76376
2563.97	7.30034
2566.71	6.49669
2569.45	6.48797
2572.19	5.82046
2574.93	5.32561
2577.67	5.13478
2580.4	5.61451
2583.14	5.05607
2585.87	4.77055
2588.6	3.9073
2591.34	3.16911
2594.07	2.78026
2596.8	2.70463
2599.53	3.43911
2602.26	3.50161
2604.98	4.38419
2607.71	4.7349
2610.44	4.47784
2613.16	5.65146
2615.88	5.80239
2618.61	6.00833
2621.33	5.46424
2624.05	5.55794
2626.77	5.6346
2629.49	6.11611
2632.21	5.15958
2634.92	4.23349
2637.64	3.61904
2640.35	3.53542
2643.07	3.06296
2645.78	3.45654
2648.49	2.74036
2651.2	2.27104
2653.91	1.53284
2656.62	0.996108
2659.33	1.90599
2662.04	1.52649
2664.74	2.57517
2667.45	3.5594
2670.15	4.46671
2672.86	4.53306
2675.56	3.99423
2678.26	3.63592
2680.96	3.03102
2683.66	3.14766
2686.36	4.20888
2689.06	4.1378
2691.75	4.00971
2694.45	4.47798
2697.14	4.70054
2699.84	4.83381
2702.53	4.57734
2705.22	4.84763
2707.91	4.89227
2710.6	6.22686
2713.29	6.61603
2715.98	6.99998
2718.67	6.66538
2721.35	6.69477
2724.04	6.82151
2726.72	6.4487
2729.4	5.95017
2732.09	6.26369
2734.77	5.48893
2737.45	5.73361
2740.13	4.91087
2742.81	4.762
2745.48	4.79891
2748.16	4.99795
2750.84	5.25815
2753.51	4.74729
2756.19	4.38995
2758.86	3.95219
2761.53	3.65493
2764.2	2.95654
2766.87	2.62761
2769.54	1.88573
2772.21	1.48499
2774.88	1.4796
2777.54	1.78665
2780.21	0.621636
2782.87	0.232942
2785.53	-0.0635644
2788.2	-0.840657
2790.86	-1.46447
2793.52	-1.49861
2796.18	-1.43431
2798.84	-0.768667
2801.49	-0.78713
2804.15	-0.915436
2806.81	-1.20374
2809.46	-1.66651
2812.12	-2.40146
2814.77	-1.47465
2817.42	-1.1687
2820.07	1.64594
2822.72	4.75841
2825.37	7.03578
2828.02	10.135
2830.67	13.881
2833.31	17.9233
2835.96	22.6825
2838.61	28.2436
2841.25	35.7671
2843.89	41.8404
2846.53	50.3071
2849.17	59.5763
2851.81	69.4983
2854.45	80.0853
2857.09	90.0266
2859.73	100.345
2862.36	109.351
2865	117.684
2867.64	126.309
2870.27	134.097
2872.9	140.972
2875.53	148.252
2878.16	154.232
2880.79	160.204
2883.42	165.071
2886.05	169.401
2888.68	172.859
2891.3	177.215
2893.93	182.053
2896.55	187.21
2899.18	192.458
2901.8	199.548
2904.42	207.69
2907.04	216.499
2909.66	227.075
2912.28	237.789
2914.9	248.845
2917.51	258.204
2920.13	267.782
2922.74	275.364
2925.36	280.466
2927.97	284.298
2930.59	287.475
2933.2	287.333
2935.81	285.593
2938.42	281.389
2941.02	274.226
2943.63	264.903
2946.24	254.759
2948.85	243.651
2951.45	232.871
2954.05	221.094
2956.66	209.45
2959.26	197.99
2961.86	186.331
2964.46	176.923
2967.06	167.756
2969.66	158.916
2972.26	150.387
2974.85	142.967
2977.45	135.443
2980.05	126.729
2982.64	118.157
2985.23	110.02
2987.83	101.017
2990.42	91.8678
2993.01	84.1832
2995.6	75.3135
2998.19	66.7623
3000.77	58.1447
3003.36	50.5478
3005.95	43.0044
3008.53	36.1807
3011.12	30.2274
3013.7	24.7227
3016.28	19.8513
3018.86	15.6696
3021.44	12.3894
3024.02	9.73714
3026.6	7.0318
3029.18	5.35756
3031.76	4.0619
3034.33	3.98287
3036.91	4.07249
3039.48	4.25116
3042.05	4.31763
3044.63	4.69952
3047.2	5.73147
3049.77	6.65427
3052.34	6.78213
3054.91	7.78083
3057.48	7.57758
3060.04	7.36423
3062.61	7.59482
3065.17	8.35573
3067.74	7.47313
3070.3	7.46061
3072.87	6.72708
3075.43	6.24873
3077.99	5.39628
3080.55	3.99279
3083.11	2.81351
3085.67	1.49582
3088.22	0.647745
3090.78	0.495962
3093.34	0.843991
3095.89	0.677316
3098.44	1.44725
3101	2.14727
3103.55	3.23348
3106.1	4.61088
3108.65	6.23724
3111.2	8.70004
3113.75	9.07055
3116.3	10.1432
3118.84	11.459
3121.39	13.1622
3123.93	15.2255
3126.48	16.914
3129.02	18.2472
3131.56	19.4952
3134.1	21.5798
3136.64	23.3711
3139.18	24.9857
3141.72	27.0367
3144.26	29.5149
3146.8	32.5136
3149.33	36.7595