File: data/Raman/poly_smoothed/Mbcal_20_25_26_1x_45s_532 nm_x100_100%_600 gr_mm_02.txt
#Acq. time (s)=	45
#Accumulations=	2
#Range (cm-¹)=	200...3150
#Windows=	2
#Auto scanning=	Off
#Autofocus=	Off
#Macrospot=	Off
#AutoExposure=	Off
#Spike filter=	Multiple accum.
#Delay time (s)=	0
#Binning=	1
#Readout mode=	Signal
#DeNoise=	Off
#ICS correction=	On
#Dark correction=	Off
#Inst. Process=	Off
#Detector Gain=	Best Dynamic Range
#Detector ADC=	20 kHz
#Detector temperature (°C)=	-69.85
#Instrument=	LabRAM HR Evol
#Detector=	Synapse
#Objective=	x100
#Grating=	600 gr/mm
#ND Filter=	100%
#Laser (nm)=	532
#Hole=	100.021
#Range=	Auto
#Laser Pol.=	No
#Raman. Pol.=	No
#Laser Pol. (°)=	-0.0007625
#Raman Pol. (°)=	89.9995
#Collection=	Microscope
#StageXY=	Marzhauser
#StageZ=	Marzhauser
#X (µm)=	-1165.5
#Y (µm)=	1301.4
#Z (µm)=	578.35
#Full time(mm:ss)=	3:18
#Project=
#Sample=
#Site=
#Title=	Mbcal_20_25_26_2x_45s_532 nm_x100_100%_600 gr_mm
#Remark=
#Date=	18.07.2022 11:36
#Acquired=	18.07.2022 11:36:57
#Base:Fit=	10.08.2022 10:55:08
#Base:Sub=	10.08.2022 10:55:14
#Filter:Polynom=	16.08.2022 10:07:28
#AxisType[0]=Intens
#AxisUnit[0]=Cnt
#AxisType[1]=Spectr
#AxisUnit[1]=1/cm
200.419	2.41789
204.048	7.05751
207.678	9.88673
211.304	10.3601
214.928	11.1882
218.554	11.7129
222.176	12.3906
225.798	12.7231
229.417	12.6168
233.035	13.4671
236.653	14.5672
240.268	15.711
243.881	16.2678
247.493	15.1129
251.103	14.7046
254.715	15.7403
258.322	15.7784
261.929	16.2966
265.534	16.6172
269.137	16.5891
272.739	14.9881
276.34	15.6605
279.939	15.7642
283.537	15.1942
287.134	14.6321
290.729	13.0362
294.323	12.1522
297.913	10.792
301.504	10.1235
305.093	10.1403
308.682	9.37874
312.268	9.58712
315.852	9.56676
319.436	10.6178
323.018	11.6316
326.597	12.1945
330.177	11.5038
333.753	11.5808
337.331	11.7988
340.906	12.1528
344.478	10.7777
348.051	10.9541
351.621	10.7674
355.189	10.9772
358.757	10.2744
362.323	11.5017
365.889	10.8553
369.451	7.87844
373.012	8.10634
376.574	7.13104
380.133	5.92051
383.69	5.81436
387.245	3.94456
390.8	3.23937
394.353	4.21448
397.906	4.24292
401.456	4.46505
405.005	6.50618
408.552	7.34309
412.099	7.23303
415.643	8.56416
419.187	8.65109
422.728	9.81472
426.269	9.14173
429.806	8.24519
433.344	8.78672
436.881	9.99132
440.416	10.5799
443.949	10.3685
447.48	10.1743
451.011	9.47434
454.541	8.91155
458.069	9.88295
461.594	11.1302
465.119	10.7515
468.642	10.0939
472.165	9.70132
475.684	10.7306
479.204	12.4416
482.721	13.9987
486.239	13.4653
489.753	14.5332
493.268	16.1072
496.779	17.5607
500.289	18.5162
503.8	20.7632
507.307	21.2066
510.813	20.9538
514.32	20.3684
517.823	21.1827
521.325	21.7288
524.826	21.8281
528.325	22.7712
531.823	22.0154
535.32	23.2376
538.815	23.9327
542.309	23.659
545.802	22.5809
549.293	21.9931
552.783	21.2698
556.271	20.4634
559.759	20.6805
563.245	18.3657
566.729	16.3982
570.213	13.6753
573.693	13.2182
577.173	12.5741
580.652	11.9625
584.13	10.8151
587.605	10.8732
591.08	10.8653
594.552	10.3487
598.025	8.68528
601.496	9.78051
604.964	12.3938
608.433	12.9478
611.898	13.929
615.364	15.0302
618.827	15.9189
622.288	17.2338
625.75	17.9555
629.209	19.7552
632.667	20.9955
636.125	22.6798
639.58	23.2704
643.033	23.683
646.485	24.3427
649.936	25.2871
653.388	25.4503
656.836	27.4136
660.283	28.1513
663.728	27.315
667.173	29.1397
670.616	30.6346
674.057	32.0312
677.498	31.7599
680.937	32.0127
684.375	32.4212
687.809	35.1914
691.244	35.6744
694.678	36.8284
698.111	37.2136
701.54	35.8634
704.97	36.2135
708.398	37.9668
711.826	38.6805
715.25	38.4476
718.675	39.0433
722.096	40.1529
725.518	42.1195
728.937	42.3398
732.357	43.0191
735.773	45.2011
739.19	47.7551
742.604	49.0281
746.018	51.0374
749.429	52.3709
752.839	54.3975
756.248	56.6954
759.657	58.5228
763.063	61.8184
766.468	64.5229
769.871	66.3162
773.273	69.4632
776.676	72.3193
780.075	74.6115
783.474	75.7648
786.871	77.4188
790.266	79.5727
793.661	80.8451
797.054	81.2061
800.446	82.4962
803.834	83.857
807.224	82.7775
810.612	81.9764
813.998	81.7972
817.384	82.032
820.766	82.5731
824.149	82.0143
827.531	82.8575
830.909	82.8169
834.288	81.985
837.666	82.0243
841.041	82.3294
844.416	81.0351
847.788	79.0279
851.161	77.474
854.53	76.9881
857.901	76.4785
861.268	74.7738
864.633	72.5884
868	70.112
871.363	67.9389
874.725	65.9465
878.088	62.6364
881.447	60.073
884.805	58.9312
888.162	55.5116
891.518	53.9072
894.872	53.0559
898.225	53.2986
901.577	52.5406
904.928	52.8592
908.277	52.8396
911.625	53.108
914.972	54.0376
918.318	53.1743
921.662	53.5902
925.005	52.3362
928.347	50.7929
931.686	49.5891
935.025	48.9815
938.363	48.4726
941.698	47.6933
945.034	46.3908
948.368	45.866
951.699	44.0521
955.031	44.2091
958.36	41.9474
961.689	40.008
965.016	39.4381
968.343	38.4162
971.666	38.867
974.991	38.9616
978.312	38.0719
981.632	38.6485
984.953	38.382
988.27	38.183
991.587	37.7414
994.902	37.8195
998.216	35.9353
1001.53	32.8922
1004.84	31.5769
1008.15	30.5067
1011.46	29.4203
1014.77	28.7214
1018.07	28.8419
1021.38	27.4231
1024.68	25.8399
1027.99	25.483
1031.29	24.4082
1034.59	24.6311
1037.89	24.0291
1041.18	24.1704
1044.48	24.3956
1047.77	25.9646
1051.07	26.275
1054.36	25.9754
1057.65	26.116
1060.94	26.2243
1064.23	27.3529
1067.52	27.5359
1070.8	27.2937
1074.09	25.9176
1077.37	24.344
1080.65	21.4202
1083.93	20.6201
1087.21	20.6753
1090.49	19.798
1093.77	19.3946
1097.04	20.1706
1100.32	19.9922
1103.59	19.8241
1106.86	19.9449
1110.13	20.4461
1113.4	19.3602
1116.67	20.8312
1119.94	19.863
1123.2	19.2068
1126.47	18.8101
1129.73	18.6877
1132.99	18.8424
1136.25	17.6386
1139.51	17.7886
1142.77	17.6588
1146.03	15.9739
1149.28	13.6848
1152.54	10.9141
1155.79	7.62685
1159.04	5.53695
1162.29	4.1893
1165.54	3.16841
1168.79	2.22341
1172.04	1.57027
1175.28	1.4831
1178.53	0.728409
1181.77	0.507077
1185.01	0.13135
1188.25	-0.187199
1191.49	0.513627
1194.73	0.745669
1197.96	1.79497
1201.2	3.46539
1204.43	4.6135
1207.66	6.86568
1210.9	8.54891
1214.13	10.7931
1217.36	13.2846
1220.58	16.1646
1223.81	18.6916
1227.04	20.3762
1230.26	23.0536
1233.48	25.3455
1236.71	27.5506
1239.93	29.2406
1243.14	29.9626
1246.36	30.0671
1249.58	30.7527
1252.8	31.1296
1256.01	31.1073
1259.22	33.5224
1262.43	33.9315
1265.64	33.8193
1268.85	35.5389
1272.06	35.0255
1275.27	34.8726
1278.48	36.2137
1281.68	37.0668
1284.88	38.2415
1288.08	39.6218
1291.28	40.2847
1294.48	42.1763
1297.68	44.3542
1300.88	46.8281
1304.07	48.6053
1307.27	49.425
1310.46	49.5679
1313.65	49.7296
1316.85	49.3674
1320.03	48.3928
1323.22	48.3524
1326.41	45.5569
1329.6	43.9439
1332.78	42.8082
1335.96	41.9347
1339.15	41.0833
1342.33	37.712
1345.51	35.9074
1348.69	33.5306
1351.86	30.2802
1355.04	28.0609
1358.21	25.4092
1361.39	24.5186
1364.56	22.7707
1367.73	22.41
1370.9	22.133
1374.07	22.0863
1377.24	24.024
1380.41	24.5019
1383.57	24.5286
1386.73	24.2556
1389.9	25.7996
1393.06	25.3284
1396.22	25.5716
1399.38	25.3921
1402.54	26.4725
1405.69	28.8197
1408.85	30.191
1412	32.6961
1415.16	35.0443
1418.31	37.7697
1421.46	41.1521
1424.61	45.5526
1427.76	50.6782
1430.9	54.4007
1434.05	56.1544
1437.2	58.7641
1440.34	60.8267
1443.48	62.2308
1446.62	63.5006
1449.76	62.3186
1452.9	61.2819
1456.04	59.804
1459.17	56.4965
1462.31	52.6791
1465.44	48.0763
1468.58	44.0039
1471.71	39.6366
1474.84	35.4486
1477.97	32.597
1481.1	29.2251
1484.22	25.6007
1487.35	22.7928
1490.47	20.6992
1493.59	19.3203
1496.72	17.8883
1499.84	17.4019
1502.96	15.809
1506.08	14.2661
1509.19	11.7355
1512.31	10.0045
1515.42	8.23054
1518.54	7.71788
1521.65	7.60296
1524.76	6.67547
1527.87	5.36769
1530.98	5.81915
1534.09	5.50072
1537.2	6.42708
1540.3	7.83328
1543.41	8.38207
1546.51	10.1647
1549.61	12.276
1552.71	14.0116
1555.81	15.479
1558.91	15.373
1562.01	15.3797
1565.1	16.1052
1568.2	17.352
1571.29	18.415
1574.38	21.2199
1577.48	22.045
1580.57	23.4666
1583.65	24.7508
1586.74	24.4891
1589.83	25.6557
1592.92	25.9509
1596	26.9758
1599.08	26.5131
1602.16	26.3823
1605.24	26.2835
1608.32	25.0352
1611.4	24.8471
1614.48	25.093
1617.56	23.0521
1620.63	23.5876
1623.71	23.8453
1626.78	23.3033
1629.85	23.376
1632.92	23.0994
1635.99	23.9242
1639.06	26.0264
1642.12	29.0899
1645.19	32.7765
1648.25	35.6891
1651.32	37.6726
1654.38	39.0326
1657.44	39.9847
1660.5	40.7677
1663.56	41.3675
1666.62	41.6348
1669.67	40.5801
1672.73	39.2237
1675.79	37.5285
1678.84	35.3652
1681.89	32.2719
1684.94	29.0258
1687.99	24.9559
1691.04	22.1663
1694.08	18.4025
1697.13	15.3901
1700.18	11.6791
1703.22	8.94737
1706.26	6.94718
1709.3	4.92479
1712.35	4.49671
1715.39	2.16386
1718.42	1.67377
1721.46	0.889523
1724.5	0.737664
1727.53	0.35722
1730.56	1.23004
1733.6	3.12231
1736.63	3.59883
1739.66	4.77511
1742.69	4.71502
1745.71	5.48459
1748.74	6.36034
1751.77	7.30173
1754.79	7.34922
1757.81	7.0014
1760.84	7.44839
1763.86	7.3054
1766.88	7.78549
1769.9	7.36488
1772.91	6.74336
1775.93	6.81379
1778.95	6.36236
1781.96	5.96194
1784.97	5.63957
1787.99	5.10027
1791	5.31819
1794.01	5.80498
1797.01	5.81358
1800.02	6.13226
1803.03	6.49775
1806.03	8.00305
1809.04	7.79826
1812.04	7.4705
1815.04	8.00627
1818.04	7.52261
1821.04	7.62764
1824.04	7.04242
1827.04	6.59716
1830.03	7.26894
1833.03	7.53215
1836.02	8.14817
1839.02	7.94595
1842.01	7.25916
1845	6.66947
1847.99	6.18294
1850.98	5.48698
1853.96	5.28564
1856.95	4.80894
1859.94	5.16742
1862.92	5.65116
1865.9	5.71589
1868.88	5.46336
1871.86	5.53157
1874.84	6.30436
1877.82	5.85113
1880.8	7.05055
1882.58	6.87834
1885.57	7.75259
1888.56	8.5271
1891.54	8.65442
1894.53	8.66307
1897.51	8.74616
1900.5	10.2922
1903.48	11.3128
1906.46	10.9578
1909.44	10.919
1912.42	9.8374
1915.4	9.01872
1918.37	8.99059
1921.35	8.5533
1924.32	8.37626
1927.3	8.37494
1930.27	7.55336
1933.24	7.07608
1936.21	6.56769
1939.18	6.31777
1942.15	5.8611
1945.11	5.46976
1948.08	6.08221
1951.04	6.69772
1954.01	6.77132
1956.97	7.3733
1959.93	8.16784
1962.89	7.05059
1965.85	5.78321
1968.81	5.68357
1971.77	6.05826
1974.72	6.16462
1977.68	5.91013
1980.63	4.75861
1983.58	3.72443
1986.53	2.94262
1989.48	2.1917
1992.43	1.26338
1995.38	0.50282
1998.33	-0.360135
2001.27	-0.136198
2004.22	-0.50368
2007.16	-0.0927585
2010.11	-0.122938
2013.05	-0.267932
2015.99	-0.0340302
2018.93	1.63303
2021.87	3.63519
2024.8	3.42587
2027.74	3.53569
2030.68	4.22364
2033.61	4.01904
2036.54	3.92047
2039.48	4.25526
2042.41	5.61097
2045.34	6.38116
2048.27	7.2995
2051.19	6.99456
2054.12	7.26583
2057.05	7.39442
2059.97	7.8358
2062.9	7.73694
2065.82	8.43537
2068.74	9.98292
2071.66	10.3153
2074.58	11.8583
2077.5	11.6647
2080.41	13.4474
2083.33	13.7068
2086.24	14.7209
2089.16	15.3199
2092.07	15.7601
2094.98	15.5214
2097.89	16.1188
2100.8	15.96
2103.71	16.3888
2106.62	16.731
2109.53	16.5598
2112.43	17.0597
2115.33	18.1751
2118.24	19.2142
2121.14	18.6661
2124.04	20.4142
2126.94	20.4124
2129.84	20.4568
2132.74	21.0791
2135.63	23.872
2138.53	24.8192
2141.43	26.1216
2144.32	28.0234
2147.21	30.0132
2150.1	31.3469
2152.99	32.9719
2155.88	34.666
2158.77	36.5891
2161.66	38.0018
2164.55	38.2924
2167.43	38.4807
2170.31	39.8782
2173.2	39.1024
2176.08	39.127
2178.96	38.0203
2181.84	38.2974
2184.72	37.1667
2187.6	36.1088
2190.47	35.0163
2193.35	34.6478
2196.23	33.8156
2199.1	32.2271
2201.97	31.2921
2204.84	30.6329
2207.71	29.2412
2210.58	28.412
2213.45	26.5824
2216.32	26.2267
2219.19	25.3107
2222.05	24.4626
2224.92	23.2666
2227.78	23.1288
2230.64	22.3096
2233.5	20.5455
2236.36	18.0882
2239.22	17.8097
2242.08	16.8204
2244.94	15.9074
2247.79	15.105
2250.65	14.1654
2253.5	15.0915
2256.36	14.05
2259.21	14.0562
2262.06	14.2101
2264.91	13.0695
2267.76	11.8873
2270.6	10.7761
2273.45	10.4398
2276.3	9.92759
2279.14	10.0779
2281.98	9.06238
2284.83	8.97617
2287.67	9.24901
2290.51	8.28539
2293.35	6.31807
2296.19	5.59739
2299.02	5.91631
2301.86	7.4177
2304.7	7.29844
2307.53	7.8351
2310.36	9.60997
2313.2	10.5412
2316.03	10.8959
2318.86	10.8559
2321.69	11.9741
2324.51	11.4146
2327.34	11.085
2330.17	10.656
2332.99	10.0823
2335.82	9.13828
2338.64	8.4454
2341.46	7.87631
2344.28	7.99318
2347.1	6.60692
2349.92	6.3161
2352.74	5.28767
2355.56	4.22514
2358.37	2.77165
2361.19	1.50856
2364	1.20007
2366.82	2.94773
2369.63	4.60343
2372.44	5.34964
2375.25	5.89142
2378.06	6.76377
2380.86	8.02794
2383.67	7.83965
2386.48	7.7633
2389.28	7.31359
2392.09	7.53813
2394.89	8.05195
2397.69	7.66451
2400.49	6.37834
2403.29	6.42942
2406.09	6.22569
2408.89	5.85465
2411.69	6.03503
2414.48	5.50424
2417.28	5.46926
2420.07	4.22157
2422.86	3.96953
2425.65	3.68693
2428.45	4.50415
2431.23	4.48409
2434.02	4.68023
2436.81	5.07905
2439.6	5.163
2442.38	5.15323
2445.17	4.37874
2447.95	4.37043
2450.73	3.87069
2453.52	3.65095
2456.3	3.19805
2459.08	3.22284
2461.85	2.07164
2464.63	1.32228
2467.41	0.488858
2470.19	0.862671
2472.96	1.04212
2475.73	0.460793
2478.51	-0.480668
2481.28	-0.123916
2484.05	-1.03509
2486.82	-1.46098
2489.59	-1.25775
2492.35	-1.09857
2495.12	-0.930777
2497.89	-0.69554
2500.65	-0.635897
2503.42	-0.0566451
2506.18	0.236859
2508.94	0.792023
2511.7	0.897215
2514.46	1.63907
2517.22	2.33395
2519.98	2.61364
2522.73	3.44833
2525.49	4.19852
2528.25	3.46286
2531	3.73796
2533.75	4.37238
2536.5	4.19668
2539.25	4.26445
2542.01	3.91377
2544.75	3.97775
2547.5	4.01164
2550.25	3.8506
2553	4.0237
2555.74	3.99193
2558.49	3.97581
2561.23	3.23427
2563.97	3.9715
2566.71	3.44101
2569.45	3.4496
2572.19	3.96785
2574.93	3.91908
2577.67	3.49988
2580.4	3.36482
2583.14	3.50096
2585.87	3.43884
2588.6	3.29374
2591.34	3.01099
2594.07	2.53057
2596.8	2.21831
2599.53	1.91351
2602.26	1.79059
2604.98	1.82613
2607.71	2.35712
2610.44	1.97602
2613.16	2.89933
2615.88	3.30397
2618.61	3.52991
2621.33	4.27013
2624.05	4.08447
2626.77	4.5517
2629.49	4.80067
2632.21	5.97623
2634.92	5.81944
2637.64	6.20572
2640.35	5.2286
2643.07	4.59676
2645.78	4.39854
2648.49	4.24504
2651.2	3.48805
2653.91	2.60823
2656.62	1.81796
2659.33	1.37839
2662.04	1.67717
2664.74	1.71152
2667.45	1.07958
2670.15	1.16209
2672.86	2.01816
2675.56	2.49003
2678.26	3.23814
2680.96	4.11944
2683.66	5.04639
2686.36	5.58772
2689.06	6.46046
2691.75	7.77019
2694.45	9.10312
2697.14	9.40341
2699.84	8.86226
2702.53	9.06241
2705.22	9.41708
2707.91	9.98089
2710.6	10.2987
2713.29	9.95286
2715.98	9.60857
2718.67	9.40936
2721.35	9.81911
2724.04	9.76169
2726.72	10.2026
2729.4	9.9709
2732.09	9.82722
2734.77	8.78065
2737.45	8.83475
2740.13	9.28592
2742.81	9.31726
2745.48	9.30386
2748.16	9.0873
2750.84	8.96877
2753.51	8.69173
2756.19	8.1375
2758.86	7.73411
2761.53	7.18034
2764.2	7.03234
2766.87	6.07914
2769.54	6.14555
2772.21	5.01876
2774.88	4.49131
2777.54	5.66773
2780.21	5.35125
2782.87	4.12551
2785.53	3.55597
2788.2	3.27348
2790.86	2.71915
2793.52	1.92842
2796.18	1.40747
2798.84	1.22348
2801.49	1.64551
2804.15	2.06544
2806.81	2.71409
2809.46	2.87004
2812.12	3.35719
2814.77	4.1415
2817.42	4.40772
2820.07	5.49318
2822.72	8.28537
2825.37	11.8351
2828.02	15.1752
2830.67	18.903
2833.31	22.4839
2835.96	26.7929
2838.61	31.2924
2841.25	35.6826
2843.89	40.5979
2846.53	45.265
2849.17	50.9644
2851.81	56.8846
2854.45	63.2137
2857.09	68.7754
2859.73	74.7664
2862.36	80.3685
2865	85.294
2867.64	89.1178
2870.27	92.0851
2872.9	95.5001
2875.53	98.9429
2878.16	101.575
2880.79	104.003
2883.42	106.01
2886.05	108.971
2888.68	112.561
2891.3	114.585
2893.93	117.926
2896.55	120.592
2899.18	123.156
2901.8	127.056
2904.42	130.59
2907.04	136.407
2909.66	142.135
2912.28	147.78
2914.9	152.76
2917.51	158.534
2920.13	163.003
2922.74	165.154
2925.36	166.735
2927.97	166.576
2930.59	165.994
2933.2	164.88
2935.81	162.531
2938.42	158.978
2941.02	154.704
2943.63	149.052
2946.24	143.447
2948.85	137.2
2951.45	131.53
2954.05	125.6
2956.66	119.806
2959.26	114.776
2961.86	109.106
2964.46	103.856
2967.06	98.8391
2969.66	94.8434
2972.26	91.509
2974.85	86.4878
2977.45	82.3337
2980.05	77.1768
2982.64	72.3658
2985.23	67.2034
2987.83	61.3077
2990.42	56.2735
2993.01	51.0841
2995.6	45.9816
2998.19	41.2224
3000.77	36.5071
3003.36	32.1
3005.95	27.9081
3008.53	23.7416
3011.12	20.521
3013.7	16.9875
3016.28	14.1989
3018.86	11.3098
3021.44	9.71395
3024.02	7.77288
3026.6	6.88063
3029.18	5.71948
3031.76	5.28075
3034.33	4.81418
3036.91	4.94074
3039.48	4.97552
3042.05	5.43582
3044.63	6.26638
3047.2	6.83021
3049.77	7.64035
3052.34	7.77356
3054.91	8.12049
3057.48	8.18867
3060.04	8.5109
3062.61	8.92014
3065.17	9.03784
3067.74	9.04811
3070.3	7.60576
3072.87	6.94582
3075.43	6.62368
3077.99	5.13579
3080.55	4.1439
3083.11	3.22114
3085.67	2.09514
3088.22	2.12373
3090.78	0.645754
3093.34	-0.409242
3095.89	0.0521586
3098.44	-0.279688
3101	-0.708212
3103.55	-0.415753
3106.1	0.172826
3108.65	0.13
3111.2	0.869913
3113.75	1.15645
3116.3	0.904537
3118.84	1.73454
3121.39	2.43365
3123.93	3.82828
3126.48	4.34705
3129.02	5.70167
3131.56	6.73826
3134.1	7.10445
3136.64	8.384
3139.18	9.8599
3141.72	10.0771
3144.26	11.4987
3146.8	12.5026
3149.33	12.8296