File: data/Raman/poly_smoothed/Mbcal_20_25_17_1x_45s_532 nm_x100_100%_600 gr_mm_01.txt
#Acq. time (s)=	45
#Accumulations=	2
#Range (cm-¹)=	200...3150
#Windows=	2
#Auto scanning=	Off
#Autofocus=	Off
#Macrospot=	Off
#AutoExposure=	Off
#Spike filter=	Multiple accum.
#Delay time (s)=	0
#Binning=	1
#Readout mode=	Signal
#DeNoise=	Off
#ICS correction=	On
#Dark correction=	Off
#Inst. Process=	Off
#Detector Gain=	Best Dynamic Range
#Detector ADC=	20 kHz
#Detector temperature (°C)=	-69.85
#Instrument=	LabRAM HR Evol
#Detector=	Synapse
#Objective=	x100
#Grating=	600 gr/mm
#ND Filter=	100%
#Laser (nm)=	532
#Hole=	100.021
#Range=	Auto
#Laser Pol.=	No
#Raman. Pol.=	No
#Laser Pol. (°)=	-0.0007625
#Raman Pol. (°)=	89.9995
#Collection=	Microscope
#StageXY=	Marzhauser
#StageZ=	Marzhauser
#X (µm)=	-1173.1
#Y (µm)=	1255.1
#Z (µm)=	578.65
#Full time(mm:ss)=	3:19
#Project=
#Sample=
#Site=
#Title=	Mbcal_20_25_17_2x_45s_532 nm_x100_100%_600 gr_mm
#Remark=
#Date=	18.07.2022 10:38
#Acquired=	18.07.2022 10:38:27
#Base:Fit=	10.08.2022 10:55:08
#Base:Sub=	10.08.2022 10:55:14
#Filter:Polynom=	16.08.2022 10:07:28
#AxisType[0]=Intens
#AxisUnit[0]=Cnt
#AxisType[1]=Spectr
#AxisUnit[1]=1/cm
200.419	5.44112
204.048	10.3724
207.678	9.05392
211.304	7.86922
214.928	8.99291
218.554	9.55642
222.176	12.3914
225.798	14.4256
229.417	14.2934
233.035	16.3134
236.653	15.7546
240.268	18.3513
243.881	20.9714
247.493	22.2849
251.103	22.8829
254.715	24.5816
258.322	28.167
261.929	28.1912
265.534	28.9584
269.137	27.0965
272.739	24.0852
276.34	25.0634
279.939	26.9921
283.537	28.6012
287.134	25.4889
290.729	23.304
294.323	25.1075
297.913	24.5342
301.504	24.1271
305.093	25.447
308.682	24.32
312.268	25.8935
315.852	23.5369
319.436	24.0063
323.018	23.9685
326.597	26.0786
330.177	25.6182
333.753	26.8414
337.331	26.374
340.906	25.9494
344.478	23.5004
348.051	21.6335
351.621	17.8416
355.189	16.5691
358.757	14.6295
362.323	16.6348
365.889	15.6751
369.451	15.6501
373.012	12.6152
376.574	10.9049
380.133	10.4029
383.69	9.70063
387.245	7.31004
390.8	6.26515
394.353	4.11724
397.906	4.34656
401.456	5.04187
405.005	5.34188
408.552	3.76598
412.099	5.66985
415.643	6.98552
419.187	6.95253
422.728	7.07222
426.269	7.13157
429.806	6.53303
433.344	6.16711
436.881	5.70967
440.416	5.00496
443.949	7.849
447.48	8.0282
451.011	6.13008
454.541	6.10611
458.069	7.80851
461.594	10.5655
465.119	10.1907
468.642	9.69808
472.165	11.9733
475.684	13.415
479.204	11.7501
482.721	14.8843
486.239	17.2707
489.753	18.4451
493.268	17.8012
496.779	19.8183
500.289	22.0575
503.8	21.1781
507.307	21.0579
510.813	22.71
514.32	21.4492
517.823	19.4743
521.325	15.9919
524.826	13.8157
528.325	15.0343
531.823	14.1354
535.32	15.2209
538.815	17.7028
542.309	21.7299
545.802	20.9622
549.293	19.6132
552.783	18.8639
556.271	19.8229
559.759	19.3006
563.245	15.9133
566.729	16.4419
570.213	17.4325
573.693	15.0994
577.173	13.1391
580.652	14.4276
584.13	15.7612
587.605	14.0461
591.08	11.1179
594.552	9.54152
598.025	8.69751
601.496	6.78979
604.964	5.12688
608.433	4.63219
611.898	7.10698
615.364	9.79197
618.827	9.39514
622.288	11.0184
625.75	10.468
629.209	10.6283
632.667	8.417
636.125	10.661
639.58	10.3657
643.033	8.91504
646.485	6.53113
649.936	7.71224
653.388	7.07555
656.836	7.90259
660.283	8.04279
663.728	11.176
667.173	13.1303
670.616	11.8029
674.057	12.7981
677.498	14.5875
680.937	18.3558
684.375	21.6358
687.809	24.9353
691.244	23.2864
694.678	23.9503
698.111	26.4622
701.54	26.3082
704.97	25.6027
708.398	28.5935
711.826	30.0318
715.25	30.944
718.675	30.8856
722.096	32.4007
725.518	34.4102
728.937	33.2561
732.357	36.4999
735.773	40.2838
739.19	43.4222
742.604	45.6484
746.018	48.08
749.429	54.5495
752.839	60.2308
756.248	64.9921
759.657	70.04
763.063	76.1653
766.468	80.9067
769.871	83.4877
773.273	86.3931
776.676	90.0254
780.075	95.024
783.474	100.266
786.871	105.136
790.266	107.522
793.661	112.581
797.054	114.287
800.446	115.343
803.834	117.051
807.224	120.207
810.612	120.041
813.998	119.861
817.384	123.624
820.766	122.073
824.149	125.425
827.531	129.331
830.909	131.272
834.288	136.022
837.666	140.489
841.041	145.646
844.416	146.333
847.788	147.381
851.161	149.419
854.53	150.018
857.901	149.979
861.268	149.064
864.633	146.716
868	144.901
871.363	142.106
874.725	136.912
878.088	130.332
881.447	125.403
884.805	119.131
888.162	112.288
891.518	105.244
894.872	100.604
898.225	97.5509
901.577	93.7131
904.928	92.9684
908.277	93.3129
911.625	93.2228
914.972	94.1494
918.318	96.956
921.662	92.0474
925.005	91.0276
928.347	89.569
931.686	87.9298
935.025	85.6528
938.363	82.8044
941.698	80.7067
945.034	80.1805
948.368	77.1855
951.699	78.3829
955.031	70.5494
958.36	66.0611
961.689	63.0215
965.016	59.0067
968.343	55.4554
971.666	51.8648
974.991	51.0486
978.312	48.5138
981.632	46.6436
984.953	43.2272
988.27	39.315
991.587	35.4274
994.902	32.5529
998.216	31.0658
1001.53	28.1862
1004.84	23.2194
1008.15	21.9303
1011.46	22.3478
1014.77	22.0199
1018.07	22.6999
1021.38	24.8905
1024.68	27.2026
1027.99	31.8727
1031.29	33.4355
1034.59	34.2408
1037.89	34.0865
1041.18	38.2256
1044.48	40.1153
1047.77	44.5939
1051.07	48.7518
1054.36	51.844
1057.65	52.8856
1060.94	51.8994
1064.23	53.7513
1067.52	51.6866
1070.8	52.4035
1074.09	52.4675
1077.37	53.8242
1080.65	51.8812
1083.93	48.3985
1087.21	45.8206
1090.49	44.2
1093.77	45.1948
1097.04	44.8646
1100.32	43.9099
1103.59	44.4463
1106.86	47.4093
1110.13	45.991
1113.4	42.9961
1116.67	43.4846
1119.94	42.0962
1123.2	42.4524
1126.47	40.7002
1129.73	40.4802
1132.99	36.6637
1136.25	34.1301
1139.51	30.5182
1142.77	31.0971
1146.03	27.5524
1149.28	24.267
1152.54	21.3607
1155.79	16.511
1159.04	14.1042
1162.29	10.6422
1165.54	6.94663
1168.79	5.85336
1172.04	5.61922
1175.28	7.04197
1178.53	6.32057
1181.77	6.61293
1185.01	9.35074
1188.25	9.2719
1191.49	10.1043
1194.73	15.2437
1197.96	16.969
1201.2	16.463
1204.43	17.6178
1207.66	19.3202
1210.9	22.0608
1214.13	26.0243
1217.36	28.9449
1220.58	32.5325
1223.81	34.4698
1227.04	35.8095
1230.26	40.1613
1233.48	42.4144
1236.71	47.0017
1239.93	50.7334
1243.14	54.3693
1246.36	58.5574
1249.58	62.347
1252.8	65.9654
1256.01	67.4508
1259.22	69.4859
1262.43	72.5794
1265.64	74.6288
1268.85	79.1659
1272.06	82.8895
1275.27	86.2177
1278.48	86.1133
1281.68	89.3818
1284.88	95.9802
1288.08	100.142
1291.28	104.803
1294.48	106.91
1297.68	109.998
1300.88	109.808
1304.07	113.44
1307.27	116.452
1310.46	117.324
1313.65	121.355
1316.85	122.249
1320.03	126.377
1323.22	124.509
1326.41	127.995
1329.6	126.658
1332.78	125.633
1335.96	125.55
1339.15	125.14
1342.33	123.543
1345.51	122.569
1348.69	121.521
1351.86	119.947
1355.04	115.978
1358.21	113.342
1361.39	113.047
1364.56	108.725
1367.73	105.915
1370.9	103.168
1374.07	100.786
1377.24	96.573
1380.41	90.4616
1383.57	88.5538
1386.73	86.6956
1389.9	85.4195
1393.06	83.0727
1396.22	81.1293
1399.38	81.8707
1402.54	82.8195
1405.69	86.6705
1408.85	88.4924
1412	95.8906
1415.16	102.356
1418.31	108.271
1421.46	115.869
1424.61	126.212
1427.76	135.266
1430.9	142.086
1434.05	148.597
1437.2	156.874
1440.34	164.423
1443.48	170.472
1446.62	174.076
1449.76	176.305
1452.9	176.577
1456.04	176.185
1459.17	172.047
1462.31	170.499
1465.44	166.134
1468.58	158.585
1471.71	151.744
1474.84	144.986
1477.97	138.686
1481.1	129.186
1484.22	119.899
1487.35	111.795
1490.47	104.341
1493.59	95.7062
1496.72	88.9035
1499.84	80.7817
1502.96	74.7831
1506.08	67.1991
1509.19	59.3747
1512.31	53.594
1515.42	50.03
1518.54	44.4732
1521.65	42.9655
1524.76	42.6145
1527.87	42.1894
1530.98	42.0884
1534.09	41.8878
1537.2	43.4418
1540.3	44.3995
1543.41	45.6319
1546.51	48.2839
1549.61	49.1039
1552.71	49.931
1555.81	52.6031
1558.91	53.6259
1562.01	57.1012
1565.1	61.2219
1568.2	62.7052
1571.29	65.6575
1574.38	68.9409
1577.48	71.4816
1580.57	76.3107
1583.65	79.4465
1586.74	83.0115
1589.83	87.7807
1592.92	91.0008
1596	91.9286
1599.08	94.2257
1602.16	95.8841
1605.24	94.3636
1608.32	91.8214
1611.4	88.4707
1614.48	83.3193
1617.56	80.8196
1620.63	77.8704
1623.71	75.1505
1626.78	73.0126
1629.85	72.3464
1632.92	71.3961
1635.99	72.9008
1639.06	73.2146
1642.12	74.3466
1645.19	74.1392
1648.25	75.6291
1651.32	76.907
1654.38	79.32
1657.44	81.6978
1660.5	81.1546
1663.56	80.5503
1666.62	78.4045
1669.67	73.768
1672.73	70.4887
1675.79	65.7462
1678.84	60.6572
1681.89	53.7879
1684.94	44.3006
1687.99	37.6006
1691.04	31.7679
1694.08	26.5206
1697.13	22.9127
1700.18	17.5414
1703.22	16.2945
1706.26	13.4779
1709.3	11.3892
1712.35	8.45084
1715.39	5.57791
1718.42	6.14335
1721.46	2.20678
1724.5	3.26139
1727.53	3.59043
1730.56	4.53421
1733.6	3.41846
1736.63	2.76628
1739.66	1.55007
1742.69	0.617403
1745.71	2.31933
1748.74	2.72494
1751.77	2.23704
1754.79	2.08487
1757.81	0.897773
1760.84	2.10389
1763.86	4.24755
1766.88	2.98918
1769.9	4.93225
1772.91	4.45438
1775.93	4.88413
1778.95	5.96398
1781.96	4.73201
1784.97	4.85385
1787.99	4.46984
1791	4.39069
1794.01	4.17376
1797.01	2.1312
1800.02	4.46979
1803.03	6.84511
1806.03	6.68481
1809.04	7.67937
1812.04	8.34415
1815.04	12.4864
1818.04	12.8895
1821.04	12.876
1824.04	11.9872
1827.04	12.3597
1830.03	12.9137
1833.03	13.5454
1836.02	14.2676
1839.02	16.3314
1842.01	16.7719
1845	17.0018
1847.99	17.7053
1850.98	17.125
1853.96	15.3831
1856.95	14.5086
1859.94	15.3043
1862.92	15.797
1865.9	15.925
1868.88	14.3233
1871.86	13.7239
1874.84	15.0289
1877.82	14.4488
1880.8	13.6533
1882.58	12.988
1885.57	12.4698
1888.56	11.6244
1891.54	10.7333
1894.53	8.33579
1897.51	7.95732
1900.5	8.97896
1903.48	9.30203
1906.46	9.51093
1909.44	9.85064
1912.42	10.2813
1915.4	8.98164
1918.37	9.76239
1921.35	7.53714
1924.32	7.74171
1927.3	7.74235
1930.27	10.3272
1933.24	9.02009
1936.21	5.85965
1939.18	4.83278
1942.15	2.93016
1945.11	2.42301
1948.08	3.06535
1951.04	3.14671
1954.01	3.08421
1956.97	2.34564
1959.93	3.11053
1962.89	2.03107
1965.85	1.76288
1968.81	1.7734
1971.77	2.60222
1974.72	2.71995
1977.68	2.08528
1980.63	4.53216
1983.58	5.92894
1986.53	7.63766
1989.48	8.31836
1992.43	8.55776
1995.38	8.92087
1998.33	10.1316
2001.27	9.67233
2004.22	9.3636
2007.16	9.2193
2010.11	9.60237
2013.05	10.6168
2015.99	13.2247
2018.93	14.171
2021.87	15.7901
2024.8	15.1306
2027.74	15.1233
2030.68	15.3753
2033.61	15.647
2036.54	15.4324
2039.48	15.1152
2042.41	13.0292
2045.34	12.3032
2048.27	13.8965
2051.19	16.2884
2054.12	17.6656
2057.05	18.918
2059.97	18.7728
2062.9	18.0494
2065.82	19.5243
2068.74	19.1435
2071.66	20.0084
2074.58	19.8673
2077.5	20.9691
2080.41	21.137
2083.33	21.5975
2086.24	21.4207
2089.16	20.7973
2092.07	20.5257
2094.98	22.5882
2097.89	22.8975
2100.8	24.4158
2103.71	27.421
2106.62	29.0699
2109.53	29.0831
2112.43	29.9828
2115.33	32.1843
2118.24	33.8796
2121.14	35.7429
2124.04	37.315
2126.94	39.9029
2129.84	42.1589
2132.74	42.8933
2135.63	44.8519
2138.53	47.3478
2141.43	47.5267
2144.32	48.2309
2147.21	46.8489
2150.1	47.8742
2152.99	49.6916
2155.88	50.285
2158.77	53.555
2161.66	56.8634
2164.55	60.3843
2167.43	64.1124
2170.31	67.5411
2173.2	69.6937
2176.08	71.7015
2178.96	73.2308
2181.84	73.0164
2184.72	74.5353
2187.6	75.3455
2190.47	73.9067
2193.35	73.4625
2196.23	72.1622
2199.1	70.7723
2201.97	67.9788
2204.84	63.5021
2207.71	61.4047
2210.58	56.4877
2213.45	50.4907
2216.32	47.5229
2219.19	43.5629
2222.05	42.4987
2224.92	41.3343
2227.78	39.5092
2230.64	37.2292
2233.5	34.1127
2236.36	32.8305
2239.22	32.3575
2242.08	29.7723
2244.94	27.2678
2247.79	26.8501
2250.65	27.8287
2253.5	26.0671
2256.36	27.4921
2259.21	26.2056
2262.06	25.3054
2264.91	25.0162
2267.76	25.7783
2270.6	25.0659
2273.45	24.5834
2276.3	24.06
2279.14	21.7287
2281.98	21.0521
2284.83	24.1155
2287.67	23.6492
2290.51	23.2634
2293.35	24.3929
2296.19	24.3829
2299.02	23.9408
2301.86	24.888
2304.7	22.9561
2307.53	22.2547
2310.36	22.9343
2313.2	21.3774
2316.03	22.2442
2318.86	22.6867
2321.69	22.1294
2324.51	21.7398
2327.34	19.8265
2330.17	18.471
2332.99	17.5514
2335.82	15.7683
2338.64	13.7391
2341.46	10.4352
2344.28	7.84682
2347.1	6.04616
2349.92	5.04813
2352.74	4.75529
2355.56	3.86753
2358.37	4.14801
2361.19	3.69823
2364	6.53275
2366.82	6.64945
2369.63	7.5553
2372.44	7.04554
2375.25	8.30868
2378.06	9.66024
2380.86	12.0955
2383.67	15.2209
2386.48	17.2052
2389.28	16.7872
2392.09	17.1943
2394.89	17.8167
2397.69	17.5353
2400.49	18.9014
2403.29	17.8656
2406.09	16.6269
2408.89	15.7291
2411.69	15.2978
2414.48	13.6005
2417.28	12.7136
2420.07	14.0117
2422.86	14.5912
2425.65	14.6331
2428.45	14.8081
2431.23	15.1213
2434.02	14.7447
2436.81	14.0832
2439.6	13.8106
2442.38	14.4849
2445.17	15.3619
2447.95	14.2331
2450.73	12.8512
2453.52	12.7696
2456.3	11.5198
2459.08	11.8395
2461.85	12.1337
2464.63	11.6581
2467.41	10.7841
2470.19	10.2788
2472.96	9.14001
2475.73	9.23663
2478.51	9.54242
2481.28	8.5115
2484.05	8.1383
2486.82	9.16374
2489.59	10.0574
2492.35	7.60157
2495.12	7.86885
2497.89	8.66399
2500.65	7.37572
2503.42	6.53762
2506.18	6.71761
2508.94	6.43817
2511.7	7.09542
2514.46	6.49557
2517.22	6.09898
2519.98	5.61233
2522.73	6.43668
2525.49	7.5822
2528.25	7.73194
2531	9.25116
2533.75	8.53239
2536.5	9.16826
2539.25	10.4107
2542.01	10.6755
2544.75	10.1509
2547.5	8.75908
2550.25	8.30598
2553	8.37986
2555.74	8.10355
2558.49	6.88392
2561.23	7.64658
2563.97	8.46824
2566.71	9.56127
2569.45	9.92995
2572.19	10.3306
2574.93	11.6172
2577.67	15.0798
2580.4	16.0777
2583.14	17.0024
2585.87	16.8172
2588.6	18.1347
2591.34	18.8709
2594.07	19.5089
2596.8	18.1252
2599.53	19.2709
2602.26	16.8703
2604.98	15.4525
2607.71	12.9597
2610.44	10.9037
2613.16	9.44109
2615.88	8.06732
2618.61	6.24146
2621.33	5.67883
2624.05	4.81891
2626.77	4.35965
2629.49	3.76318
2632.21	5.20903
2634.92	5.95161
2637.64	5.76141
2640.35	6.76049
2643.07	8.65202
2645.78	10.403
2648.49	11.2618
2651.2	12.7876
2653.91	14.4856
2656.62	15.6827
2659.33	16.1814
2662.04	19.1608
2664.74	19.9298
2667.45	19.6614
2670.15	18.5562
2672.86	18.2952
2675.56	18.7832
2678.26	20.3565
2680.96	20.0958
2683.66	19.4346
2686.36	19.6784
2689.06	20.1504
2691.75	19.9434
2694.45	18.7631
2697.14	19.4783
2699.84	20.2835
2702.53	19.9118
2705.22	21.4953
2707.91	22.8343
2710.6	23.9098
2713.29	25.4116
2715.98	25.2034
2718.67	24.7432
2721.35	25.9742
2724.04	26.1789
2726.72	26.3009
2729.4	26.2562
2732.09	24.0658
2734.77	22.5097
2737.45	23.1083
2740.13	23.1954
2742.81	23.4846
2745.48	22.3109
2748.16	20.3234
2750.84	18.778
2753.51	17.5096
2756.19	15.7406
2758.86	14.3505
2761.53	13.5967
2764.2	11.2788
2766.87	10.32
2769.54	9.03822
2772.21	6.68417
2774.88	7.24963
2777.54	5.88095
2780.21	5.40701
2782.87	3.09629
2785.53	2.32222
2788.2	1.25156
2790.86	0.473087
2793.52	-0.0612022
2796.18	-0.466108
2798.84	-1.35758
2801.49	-1.35533
2804.15	-1.36596
2806.81	-2.63371
2809.46	-5.37651
2812.12	-6.22039
2814.77	-4.49209
2817.42	-1.84429
2820.07	5.32836
2822.72	14.4977
2825.37	23.7231
2828.02	33.29
2830.67	44.9558
2833.31	57.6657
2835.96	70.5777
2838.61	84.666
2841.25	98.6589
2843.89	112.736
2846.53	127.921
2849.17	143.603
2851.81	158.772
2854.45	173.772
2857.09	188.453
2859.73	201.078
2862.36	213.466
2865	222.036
2867.64	227.266
2870.27	232.607
2872.9	235.302
2875.53	240.558
2878.16	243.65
2880.79	250.722
2883.42	255.3
2886.05	260.953
2888.68	265.803
2891.3	270.841
2893.93	274.373
2896.55	277.86
2899.18	283.356
2901.8	288.044
2904.42	294.129
2907.04	304.516
2909.66	313.835
2912.28	327.3
2914.9	341.103
2917.51	351.83
2920.13	361.399
2922.74	367.627
2925.36	373.216
2927.97	373.788
2930.59	370.962
2933.2	365.874
2935.81	361.023
2938.42	351.564
2941.02	339.783
2943.63	328.129
2946.24	314.022
2948.85	299.893
2951.45	284.835
2954.05	267.949
2956.66	251.817
2959.26	235.694
2961.86	220.593
2964.46	206.873
2967.06	194.467
2969.66	183.625
2972.26	175.266
2974.85	168.624
2977.45	160.896
2980.05	150.95
2982.64	140.117
2985.23	129.266
2987.83	119.264
2990.42	106.933
2993.01	94.7237
2995.6	83.3104
2998.19	72.875
3000.77	62.0629
3003.36	51.7666
3005.95	41.4183
3008.53	33.0666
3011.12	26.3255
3013.7	19.8934
3016.28	12.5053
3018.86	7.42613
3021.44	3.23426
3024.02	1.24269
3026.6	-0.028195
3029.18	-1.36161
3031.76	-2.18296
3034.33	-1.82402
3036.91	-0.262269
3039.48	1.82006
3042.05	2.91009
3044.63	3.76286
3047.2	4.05386
3049.77	4.08608
3052.34	4.98172
3054.91	3.61131
3057.48	4.68046
3060.04	5.13532
3062.61	4.29035
3065.17	3.51536
3067.74	3.17545
3070.3	3.08932
3072.87	2.27341
3075.43	1.67252
3077.99	0.721169
3080.55	-0.140113
3083.11	-0.565452
3085.67	0.743005
3088.22	0.418138
3090.78	-0.135799
3093.34	-0.127086
3095.89	0.437159
3098.44	1.45403
3101	3.23961
3103.55	3.34006
3106.1	4.15705
3108.65	5.7075
3111.2	6.11176
3113.75	7.94593
3116.3	9.08927
3118.84	9.4866
3121.39	11.0616
3123.93	12.437
3126.48	14.2066
3129.02	16.0278
3131.56	17.9195
3134.1	18.8485
3136.64	19.9984
3139.18	22.9991
3141.72	25.4239
3144.26	28.1054
3146.8	30.6317
3149.33	31.2308