File: data/Raman/poly_smoothed/Mbcal_20_25_13_1x_45s_532 nm_x100_100%_600 gr_mm_01.txt
#Acq. time (s)=	45
#Accumulations=	2
#Range (cm-¹)=	200...3150
#Windows=	2
#Auto scanning=	Off
#Autofocus=	Off
#Macrospot=	Off
#AutoExposure=	Off
#Spike filter=	Multiple accum.
#Delay time (s)=	0
#Binning=	1
#Readout mode=	Signal
#DeNoise=	Off
#ICS correction=	On
#Dark correction=	Off
#Inst. Process=	Off
#Detector Gain=	Best Dynamic Range
#Detector ADC=	20 kHz
#Detector temperature (°C)=	-69.85
#Instrument=	LabRAM HR Evol
#Detector=	Synapse
#Objective=	x100
#Grating=	600 gr/mm
#ND Filter=	100%
#Laser (nm)=	532
#Hole=	100.021
#Range=	Auto
#Laser Pol.=	No
#Raman. Pol.=	No
#Laser Pol. (°)=	-0.0007625
#Raman Pol. (°)=	89.9995
#Collection=	Microscope
#StageXY=	Marzhauser
#StageZ=	Marzhauser
#X (µm)=	-1186.3
#Y (µm)=	1245.3
#Z (µm)=	578
#Full time(mm:ss)=	3:18
#Project=
#Sample=
#Site=
#Title=	Mbcal_20_25_13_2x_45s_532 nm_x100_100%_600 gr_mm
#Remark=
#Date=	18.07.2022 10:21
#Acquired=	18.07.2022 10:21:18
#Base:Fit=	10.08.2022 10:55:08
#Base:Sub=	10.08.2022 10:55:14
#Filter:Polynom=	16.08.2022 10:07:28
#AxisType[0]=Intens
#AxisUnit[0]=Cnt
#AxisType[1]=Spectr
#AxisUnit[1]=1/cm
200.419	-3.02005
204.048	2.53599
207.678	5.04417
211.304	6.66516
214.928	7.50821
218.554	7.51932
222.176	6.89757
225.798	9.0899
229.417	10.236
233.035	11.5884
236.653	11.1387
240.268	10.1759
243.881	11.0956
247.493	11.6603
251.103	11.3975
254.715	13.1078
258.322	14.1553
261.929	15.7497
265.534	17.6511
269.137	21.7039
272.739	22.136
276.34	22.9914
279.939	23.8812
283.537	24.3607
287.134	25.1448
290.729	23.7347
294.323	22.8796
297.913	22.5993
301.504	22.0515
305.093	21.5565
308.682	22.1485
312.268	23.3559
315.852	23.532
319.436	21.1681
323.018	20.5903
326.597	17.736
330.177	18.8113
333.753	19.6822
337.331	19.7254
340.906	20.7478
344.478	22.8037
348.051	24.1593
351.621	25.1841
355.189	25.5513
358.757	24.7577
362.323	23.5301
365.889	22.34
369.451	22.9129
373.012	21.9187
376.574	21.0017
380.133	21.276
383.69	22.6439
387.245	23.2496
390.8	23.786
394.353	24.7307
397.906	24.437
401.456	20.6452
405.005	20.0309
408.552	18.0892
412.099	17.9522
415.643	17.9804
419.187	17.5818
422.728	14.9964
426.269	15.3507
429.806	13.6654
433.344	11.3776
436.881	9.82068
440.416	6.53307
443.949	4.92555
447.48	3.10224
451.011	3.52608
454.541	3.97499
458.069	3.7531
461.594	5.03224
465.119	6.29752
468.642	7.25985
472.165	9.73146
475.684	10.9753
479.204	13.3337
482.721	13.3007
486.239	14.7385
489.753	15.3525
493.268	16.5631
496.779	19.7381
500.289	22.1028
503.8	21.9703
507.307	22.9858
510.813	25.8062
514.32	25.5112
517.823	25.3701
521.325	25.9676
524.826	24.5133
528.325	23.6942
531.823	24.6246
535.32	24.514
538.815	25.126
542.309	24.8834
545.802	24.1685
549.293	23.2876
552.783	21.5987
556.271	21.3932
559.759	21.0059
563.245	20.1332
566.729	17.5555
570.213	15.9694
573.693	13.4844
577.173	12.6563
580.652	12.4757
584.13	11.2228
587.605	9.85483
591.08	9.06269
594.552	8.0392
598.025	6.11958
601.496	4.98667
604.964	4.12036
608.433	2.5862
611.898	2.23786
615.364	1.72043
618.827	2.83919
622.288	3.07251
625.75	3.38537
629.209	4.9485
632.667	4.11816
636.125	4.91598
639.58	5.91942
643.033	8.52295
646.485	10.2752
649.936	11.3114
653.388	10.4285
656.836	11.679
660.283	14.0359
663.728	14.4144
667.173	16.0737
670.616	17.3603
674.057	17.5323
677.498	18.0783
680.937	19.7851
684.375	20.8346
687.809	21.9212
691.244	21.2715
694.678	22.797
698.111	23.8676
701.54	25.5992
704.97	26.4001
708.398	27.1772
711.826	28.9776
715.25	31.1407
718.675	31.0402
722.096	31.5372
725.518	32.6547
728.937	31.3491
732.357	32.4415
735.773	31.9551
739.19	31.9361
742.604	31.4737
746.018	30.3539
749.429	31.3
752.839	33.2126
756.248	33.2625
759.657	34.0192
763.063	35.8699
766.468	37.8589
769.871	38.4877
773.273	41.3532
776.676	44.0978
780.075	46.3263
783.474	50.1367
786.871	52.3993
790.266	55.4272
793.661	57.0798
797.054	59.0799
800.446	58.138
803.834	58.4025
807.224	60.2193
810.612	62.6427
813.998	63.467
817.384	64.2371
820.766	64.3888
824.149	62.1786
827.531	62.901
830.909	66.4521
834.288	66.821
837.666	68.0681
841.041	67.111
844.416	65.9294
847.788	66.704
851.161	65.5183
854.53	65.0709
857.901	64.1708
861.268	62.1487
864.633	60.0456
868	57.8239
871.363	56.0209
874.725	51.9825
878.088	48.9059
881.447	46.1598
884.805	43.8582
888.162	41.8051
891.518	39.2898
894.872	36.9514
898.225	33.8499
901.577	33.6666
904.928	32.7115
908.277	32.6899
911.625	33.5315
914.972	33.6237
918.318	33.6841
921.662	32.8389
925.005	32.415
928.347	33.8948
931.686	33.5334
935.025	32.1043
938.363	33.3036
941.698	31.9609
945.034	30.3926
948.368	30.6203
951.699	28.0338
955.031	26.3014
958.36	24.5076
961.689	23.9923
965.016	22.1619
968.343	21.8983
971.666	20.0319
974.991	18.4203
978.312	16.7884
981.632	16.3768
984.953	16.0522
988.27	15.3855
991.587	14.2735
994.902	13.3905
998.216	13.1771
1001.53	13.5962
1004.84	14.3159
1008.15	14.5999
1011.46	14.0945
1014.77	15.0787
1018.07	15.563
1021.38	15.2261
1024.68	17.1875
1027.99	17.8956
1031.29	19.2214
1034.59	18.4182
1037.89	19.6382
1041.18	19.262
1044.48	21.2158
1047.77	20.6401
1051.07	18.8285
1054.36	18.0515
1057.65	15.9752
1060.94	14.5398
1064.23	13.6519
1067.52	12.9918
1070.8	10.5831
1074.09	10.7165
1077.37	10.6212
1080.65	9.06484
1083.93	9.25416
1087.21	8.73522
1090.49	7.64507
1093.77	9.09009
1097.04	9.46649
1100.32	9.74634
1103.59	12.9685
1106.86	14.3008
1110.13	15.8886
1113.4	16.7801
1116.67	18.0698
1119.94	17.1198
1123.2	17.4455
1126.47	17.7283
1129.73	14.686
1132.99	14.7377
1136.25	15.403
1139.51	13.3191
1142.77	12.1889
1146.03	11.3771
1149.28	10.9204
1152.54	10.3677
1155.79	9.92551
1159.04	8.14085
1162.29	6.77625
1165.54	6.18707
1168.79	5.8237
1172.04	5.49907
1175.28	4.3248
1178.53	2.90449
1181.77	4.25197
1185.01	5.36608
1188.25	5.11259
1191.49	4.12778
1194.73	3.61399
1197.96	2.72394
1201.2	3.51975
1204.43	5.13227
1207.66	7.43294
1210.9	9.16986
1214.13	11.6054
1217.36	12.2841
1220.58	14.1686
1223.81	15.7066
1227.04	16.6588
1230.26	20.5567
1233.48	22.6195
1236.71	23.8769
1239.93	23.7512
1243.14	25.7339
1246.36	26.068
1249.58	27.2699
1252.8	26.8772
1256.01	27.6009
1259.22	27.8335
1262.43	29.4429
1265.64	30.9558
1268.85	31.0765
1272.06	32.2703
1275.27	34.2399
1278.48	37.2136
1281.68	38.8044
1284.88	41.7725
1288.08	44.3738
1291.28	45.852
1294.48	47.7707
1297.68	48.1188
1300.88	50.0824
1304.07	51.6707
1307.27	53.1774
1310.46	53.4446
1313.65	52.7999
1316.85	51.0147
1320.03	51.1248
1323.22	52.2273
1326.41	52.2728
1329.6	52.3481
1332.78	49.734
1335.96	49.9844
1339.15	48.9955
1342.33	49.2251
1345.51	48.5665
1348.69	46.5901
1351.86	45.7022
1355.04	44.0588
1358.21	43.0321
1361.39	40.7739
1364.56	39.5061
1367.73	38.5163
1370.9	37.2162
1374.07	34.6172
1377.24	33.6301
1380.41	31.9518
1383.57	30.4959
1386.73	28.3799
1389.9	25.7869
1393.06	25.2682
1396.22	26.5263
1399.38	27.0457
1402.54	28.9315
1405.69	29.7088
1408.85	30.4607
1412	33.1047
1415.16	36.5187
1418.31	40.1303
1421.46	42.5752
1424.61	45.9052
1427.76	47.7591
1430.9	51.3192
1434.05	54.5669
1437.2	57.7541
1440.34	59.2789
1443.48	60.9857
1446.62	61.1947
1449.76	62.6271
1452.9	62.0977
1456.04	62.9241
1459.17	62.9481
1462.31	63.7964
1465.44	64.6349
1468.58	66.3313
1471.71	66.6882
1474.84	67.2361
1477.97	68.2241
1481.1	67.1234
1484.22	66.3882
1487.35	64.4208
1490.47	61.3172
1493.59	57.7968
1496.72	54.5387
1499.84	51.5231
1502.96	47.5748
1506.08	43.9656
1509.19	40.9081
1512.31	37.413
1515.42	32.1267
1518.54	26.5456
1521.65	23.2729
1524.76	21.186
1527.87	19.8842
1530.98	19.0152
1534.09	17.7643
1537.2	19.0838
1540.3	19.9177
1543.41	22.0893
1546.51	23.3564
1549.61	24.1476
1552.71	27.9719
1555.81	30.0595
1558.91	29.4207
1562.01	29.1124
1565.1	28.4709
1568.2	29.3679
1571.29	30.8034
1574.38	33.1073
1577.48	34.1601
1580.57	34.2438
1583.65	36.1145
1586.74	37.748
1589.83	36.832
1592.92	37.1259
1596	37.7345
1599.08	39.0424
1602.16	40.2673
1605.24	38.4626
1608.32	36.7109
1611.4	36.4841
1614.48	36.8584
1617.56	35.7633
1620.63	34.7625
1623.71	34.6596
1626.78	34.5594
1629.85	33.0528
1632.92	30.9167
1635.99	30.757
1639.06	29.9466
1642.12	30.2836
1645.19	30.3473
1648.25	29.4365
1651.32	30.7069
1654.38	30.6355
1657.44	31.1245
1660.5	30.3238
1663.56	29.0797
1666.62	27.1878
1669.67	27.8876
1672.73	26.4717
1675.79	25.7653
1678.84	22.9648
1681.89	20.282
1684.94	18.7202
1687.99	17.4579
1691.04	14.4295
1694.08	13.5386
1697.13	12.3662
1700.18	10.874
1703.22	9.06381
1706.26	6.39584
1709.3	6.86241
1712.35	6.13863
1715.39	4.75634
1718.42	4.3395
1721.46	3.55615
1724.5	3.8229
1727.53	4.1012
1730.56	2.6304
1733.6	3.1248
1736.63	3.49855
1739.66	2.40646
1742.69	2.14347
1745.71	2.79242
1748.74	2.55839
1751.77	2.32099
1754.79	1.29378
1757.81	1.09171
1760.84	0.928042
1763.86	1.13858
1766.88	1.17432
1769.9	2.52658
1772.91	1.86293
1775.93	2.11985
1778.95	1.1525
1781.96	3.71823
1784.97	4.14392
1787.99	4.75289
1791	4.67661
1794.01	5.50008
1797.01	5.84539
1800.02	5.92268
1803.03	6.1913
1806.03	6.02132
1809.04	6.38607
1812.04	5.90511
1815.04	4.65736
1818.04	4.07258
1821.04	4.85076
1824.04	4.75152
1827.04	3.50572
1830.03	3.65835
1833.03	4.04046
1836.02	3.80381
1839.02	2.36697
1842.01	2.55893
1845	3.22753
1847.99	3.5487
1850.98	2.94263
1853.96	2.93758
1856.95	2.68254
1859.94	1.59462
1862.92	0.502232
1865.9	0.40512
1868.88	0.633721
1871.86	0.642198
1874.84	1.38862
1877.82	1.08111
1880.8	1.61292
1882.58	1.08767
1885.57	1.92348
1888.56	1.68453
1891.54	2.69174
1894.53	3.28195
1897.51	2.32305
1900.5	2.63474
1903.48	3.20039
1906.46	4.94494
1909.44	4.30015
1912.42	4.71167
1915.4	4.92179
1918.37	5.43736
1921.35	5.65743
1924.32	5.33033
1927.3	6.39278
1930.27	6.43034
1933.24	7.87836
1936.21	7.84426
1939.18	7.98471
1942.15	7.99939
1945.11	8.43784
1948.08	7.3997
1951.04	8.22751
1954.01	7.05576
1956.97	7.44429
1959.93	7.40357
1962.89	7.25734
1965.85	6.86379
1968.81	6.82868
1971.77	6.13868
1974.72	6.33478
1977.68	6.48791
1980.63	5.10733
1983.58	4.99351
1986.53	4.83421
1989.48	5.33411
1992.43	6.7819
1995.38	6.78895
1998.33	7.80211
2001.27	8.67476
2004.22	8.85151
2007.16	8.74151
2010.11	8.61102
2013.05	8.0892
2015.99	9.53547
2018.93	9.0845
2021.87	9.7588
2024.8	10.8708
2027.74	11.1803
2030.68	13.2075
2033.61	14.1081
2036.54	15.1044
2039.48	14.8263
2042.41	15.9876
2045.34	16.6416
2048.27	16.5534
2051.19	16.5273
2054.12	16.4944
2057.05	17.2557
2059.97	18.7836
2062.9	18.7868
2065.82	19.8436
2068.74	19.2272
2071.66	18.9044
2074.58	17.4554
2077.5	17.1246
2080.41	16.3241
2083.33	15.343
2086.24	15.8299
2089.16	15.5315
2092.07	15.8977
2094.98	15.4831
2097.89	16.844
2100.8	16.7621
2103.71	18.4179
2106.62	19.9316
2109.53	20.0749
2112.43	22.4931
2115.33	22.8155
2118.24	23.6087
2121.14	25.6642
2124.04	26.4273
2126.94	29.1227
2129.84	31.3891
2132.74	34.3371
2135.63	34.8402
2138.53	36.3197
2141.43	36.794
2144.32	37.2416
2147.21	37.9493
2150.1	37.8832
2152.99	38.8912
2155.88	40.4921
2158.77	40.6747
2161.66	40.0978
2164.55	39.8334
2167.43	37.347
2170.31	36.3722
2173.2	36.5017
2176.08	35.9774
2178.96	35.8822
2181.84	34.5667
2184.72	33.9246
2187.6	32.9926
2190.47	32.9948
2193.35	32.7518
2196.23	32.2681
2199.1	32.4506
2201.97	31.4005
2204.84	31.1446
2207.71	30.2706
2210.58	29.9207
2213.45	28.6363
2216.32	27.4896
2219.19	27.6237
2222.05	27.8442
2224.92	26.5516
2227.78	26.3194
2230.64	23.9985
2233.5	23.521
2236.36	23.0132
2239.22	22.2057
2242.08	23.4487
2244.94	23.0404
2247.79	22.292
2250.65	21.7534
2253.5	20.4812
2256.36	20.0907
2259.21	18.654
2262.06	17.971
2264.91	17.9066
2267.76	17.4296
2270.6	16.1568
2273.45	14.7866
2276.3	13.8173
2279.14	12.3307
2281.98	11.6411
2284.83	10.634
2287.67	10.4228
2290.51	9.85436
2293.35	8.66652
2296.19	9.85218
2299.02	11.4468
2301.86	13.307
2304.7	15.0754
2307.53	16.0579
2310.36	15.8841
2313.2	17.2648
2316.03	17.7792
2318.86	18.4275
2321.69	19.203
2324.51	19.326
2327.34	19.4608
2330.17	19.4659
2332.99	18.7833
2335.82	17.8391
2338.64	18.0468
2341.46	17.9193
2344.28	15.8967
2347.1	16.0679
2349.92	15.9252
2352.74	13.653
2355.56	12.4742
2358.37	12.5819
2361.19	12.5678
2364	13.7851
2366.82	14.9577
2369.63	13.5145
2372.44	14.0422
2375.25	12.4619
2378.06	11.2348
2380.86	11.2607
2383.67	10.3419
2386.48	8.43778
2389.28	7.00673
2392.09	5.13048
2394.89	3.92599
2397.69	3.39875
2400.49	1.23582
2403.29	0.880194
2406.09	1.13887
2408.89	1.70788
2411.69	2.30008
2414.48	3.56243
2417.28	4.47649
2420.07	3.87922
2422.86	5.02867
2425.65	6.33822
2428.45	7.57216
2431.23	7.64311
2434.02	6.72516
2436.81	6.76063
2439.6	6.62909
2442.38	7.08944
2445.17	5.74173
2447.95	4.76627
2450.73	4.45645
2453.52	4.25706
2456.3	3.86311
2459.08	4.4357
2461.85	4.50678
2464.63	4.47783
2467.41	3.92382
2470.19	4.39586
2472.96	5.95973
2475.73	6.84585
2478.51	7.23209
2481.28	7.91155
2484.05	7.64048
2486.82	7.63405
2489.59	7.58062
2492.35	6.47927
2495.12	6.22681
2497.89	4.13026
2500.65	3.14742
2503.42	1.98104
2506.18	1.29744
2508.94	1.40134
2511.7	0.570001
2514.46	0.914723
2517.22	0.460018
2519.98	1.81852
2522.73	2.64489
2525.49	3.80413
2528.25	4.8323
2531	6.15428
2533.75	6.81111
2536.5	8.41929
2539.25	9.37083
2542.01	10.2603
2544.75	10.8893
2547.5	11.3279
2550.25	11.0235
2553	10.7583
2555.74	11.367
2558.49	9.83012
2561.23	9.60555
2563.97	9.07576
2566.71	7.33747
2569.45	6.11231
2572.19	6.51869
2574.93	5.42636
2577.67	4.82086
2580.4	4.88037
2583.14	3.88595
2585.87	3.24895
2588.6	3.08208
2591.34	2.23178
2594.07	2.48461
2596.8	2.8911
2599.53	3.31983
2602.26	2.96455
2604.98	3.6607
2607.71	4.12965
2610.44	4.2836
2613.16	3.4081
2615.88	3.18231
2618.61	3.19882
2621.33	4.70854
2624.05	4.18246
2626.77	3.8438
2629.49	3.69212
2632.21	3.5256
2634.92	4.39296
2637.64	4.47976
2640.35	4.56303
2643.07	4.04444
2645.78	4.36853
2648.49	4.60382
2651.2	3.63445
2653.91	4.61999
2656.62	5.80534
2659.33	5.31828
2662.04	6.4975
2664.74	5.90893
2667.45	6.58825
2670.15	6.56775
2672.86	6.99557
2675.56	7.00134
2678.26	6.3424
2680.96	6.62004
2683.66	6.86262
2686.36	6.80141
2689.06	6.77057
2691.75	6.37104
2694.45	5.92462
2697.14	7.07245
2699.84	7.28932
2702.53	7.33899
2705.22	8.09098
2707.91	8.88333
2710.6	10.2773
2713.29	12.4936
2715.98	13.7202
2718.67	13.6982
2721.35	15.004
2724.04	15.3499
2726.72	15.2521
2729.4	15.9149
2732.09	15.928
2734.77	15.7576
2737.45	15.5379
2740.13	14.7396
2742.81	13.5335
2745.48	13.5348
2748.16	13.3943
2750.84	12.4842
2753.51	11.2042
2756.19	10.9451
2758.86	9.61035
2761.53	7.8964
2764.2	6.47257
2766.87	6.82334
2769.54	7.52629
2772.21	7.71038
2774.88	7.90401
2777.54	7.52633
2780.21	6.57784
2782.87	5.47495
2785.53	4.26258
2788.2	5.42597
2790.86	5.5897
2793.52	4.12162
2796.18	3.29293
2798.84	2.26447
2801.49	1.44813
2804.15	1.0868
2806.81	-0.157707
2809.46	-0.583587
2812.12	-0.460251
2814.77	-1.15823
2817.42	-0.533634
2820.07	0.771463
2822.72	2.56254
2825.37	4.72295
2828.02	7.60981
2830.67	12.675
2833.31	16.7823
2835.96	21.0272
2838.61	25.0197
2841.25	30.3121
2843.89	34.2437
2846.53	40.0813
2849.17	44.7386
2851.81	52.3149
2854.45	59.003
2857.09	64.7177
2859.73	69.7287
2862.36	74.6256
2865	79.9095
2867.64	83.6875
2870.27	87.2469
2872.9	90.4308
2875.53	94.4014
2878.16	97.2797
2880.79	100.895
2883.42	103.699
2886.05	107.59
2888.68	111.665
2891.3	114.953
2893.93	117.595
2896.55	120.484
2899.18	124.831
2901.8	128.252
2904.42	131.309
2907.04	135.197
2909.66	139.769
2912.28	145.531
2914.9	150.853
2917.51	156.959
2920.13	160.273
2922.74	163.855
2925.36	166.021
2927.97	167.767
2930.59	166.864
2933.2	166.686
2935.81	165.547
2938.42	161.75
2941.02	157.578
2943.63	152.167
2946.24	145.771
2948.85	139.536
2951.45	132.621
2954.05	125.653
2956.66	117.738
2959.26	111.366
2961.86	105.794
2964.46	99.9045
2967.06	94.8337
2969.66	90.0829
2972.26	86.6379
2974.85	83.2618
2977.45	79.2146
2980.05	75.4555
2982.64	71.3079
2985.23	67.2812
2987.83	63.2219
2990.42	58.6804
2993.01	54.0193
2995.6	49.5288
2998.19	44.2707
3000.77	38.3237
3003.36	33.9922
3005.95	29.063
3008.53	24.2097
3011.12	18.9242
3013.7	15.4064
3016.28	13.1495
3018.86	10.7991
3021.44	8.83949
3024.02	7.66685
3026.6	7.40451
3029.18	6.54362
3031.76	6.33741
3034.33	6.30609
3036.91	5.8406
3039.48	5.27842
3042.05	5.21089
3044.63	5.39546
3047.2	6.60004
3049.77	5.95027
3052.34	6.71657
3054.91	5.20717
3057.48	5.5775
3060.04	4.48814
3062.61	3.2443
3065.17	3.10941
3067.74	2.00571
3070.3	1.72259
3072.87	1.23
3075.43	1.32052
3077.99	1.32211
3080.55	1.6561
3083.11	1.5638
3085.67	0.791976
3088.22	1.28828
3090.78	1.23213
3093.34	1.46826
3095.89	1.57289
3098.44	1.16839
3101	0.873235
3103.55	0.864889
3106.1	1.57079
3108.65	1.96176
3111.2	2.38711
3113.75	2.68521
3116.3	2.9436
3118.84	3.61248
3121.39	3.87062
3123.93	3.06746
3126.48	3.22002
3129.02	3.16465
3131.56	3.87907
3134.1	4.14028
3136.64	4.38003
3139.18	4.55507
3141.72	4.19521
3144.26	3.56675
3146.8	3.01625
3149.33	0.157041