File: data/Raman/poly_smoothed/Mbcal_20_25_37_1x_45s_532 nm_x100_100%_600 gr_mm_03.txt
#Acq. time (s)=	45
#Accumulations=	2
#Range (cm-¹)=	200...3150
#Windows=	2
#Auto scanning=	Off
#Autofocus=	Off
#Macrospot=	Off
#AutoExposure=	Off
#Spike filter=	Multiple accum.
#Delay time (s)=	0
#Binning=	1
#Readout mode=	Signal
#DeNoise=	Off
#ICS correction=	On
#Dark correction=	Off
#Inst. Process=	Off
#Detector Gain=	Best Dynamic Range
#Detector ADC=	20 kHz
#Detector temperature (°C)=	-69.85
#Instrument=	LabRAM HR Evol
#Detector=	Synapse
#Objective=	x100
#Grating=	600 gr/mm
#ND Filter=	100%
#Laser (nm)=	532
#Hole=	100.021
#Range=	Auto
#Laser Pol.=	No
#Raman. Pol.=	No
#Laser Pol. (°)=	-0.0007625
#Raman Pol. (°)=	89.9995
#Collection=	Microscope
#StageXY=	Marzhauser
#StageZ=	Marzhauser
#X (µm)=	-1125.8
#Y (µm)=	1303.8
#Z (µm)=	578.4
#Full time(mm:ss)=	3:18
#Project=
#Sample=
#Site=
#Title=	Mbcal_20_25_37_2x_45s_532 nm_x100_100%_600 gr_mm
#Remark=
#Date=	18.07.2022 13:00
#Acquired=	18.07.2022 13:00:16
#Base:Fit=	10.08.2022 10:55:08
#Base:Sub=	10.08.2022 10:55:14
#Filter:Polynom=	16.08.2022 10:07:28
#AxisType[0]=Intens
#AxisUnit[0]=Cnt
#AxisType[1]=Spectr
#AxisUnit[1]=1/cm
200.419	11.49
204.048	5.85147
207.678	4.40308
211.304	4.29428
214.928	5.05225
218.554	7.60588
222.176	9.96088
225.798	12.548
229.417	13.5893
233.035	15.851
236.653	15.9326
240.268	14.3261
243.881	12.2004
247.493	10.1689
251.103	2.05375
254.715	-1.73915
258.322	5.71917
261.929	27.263
265.534	49.6493
269.137	69.6261
272.739	88.9029
276.34	106.225
279.939	119.815
283.537	131
287.134	140.076
290.729	147.519
294.323	153.171
297.913	156.676
301.504	158.339
305.093	157.074
308.682	152.785
312.268	144.827
315.852	134.655
319.436	121.901
323.018	106.451
326.597	88.5604
330.177	70.1303
333.753	50.606
337.331	34.3728
340.906	23.249
344.478	28.9883
348.051	38.1342
351.621	43.6513
355.189	42.0915
358.757	40.7204
362.323	40.4123
365.889	37.9654
369.451	35.6128
373.012	34.9743
376.574	33.994
380.133	33.0925
383.69	32.8167
387.245	32.4879
390.8	32.2415
394.353	32.5442
397.906	31.4226
401.456	32.8354
405.005	33.0816
408.552	32.6294
412.099	29.9112
415.643	28.6687
419.187	25.7241
422.728	23.1211
426.269	21.0511
429.806	20.4827
433.344	18.456
436.881	15.4995
440.416	12.5867
443.949	10.7433
447.48	9.21054
451.011	9.7088
454.541	10.6335
458.069	11.2111
461.594	10.0635
465.119	10.6181
468.642	11.156
472.165	14.017
475.684	14.7503
479.204	15.9697
482.721	17.9449
486.239	19.9583
489.753	20.0619
493.268	20.2596
496.779	21.0318
500.289	21.0371
503.8	23.5531
507.307	25.385
510.813	27.2275
514.32	29.4299
517.823	30.8019
521.325	31.5952
524.826	30.3813
528.325	30.821
531.823	31.4134
535.32	29.9871
538.815	30.1133
542.309	28.6898
545.802	26.6543
549.293	24.2797
552.783	23.7128
556.271	21.3846
559.759	17.7173
563.245	14.0646
566.729	12.587
570.213	10.4181
573.693	6.89529
577.173	4.65932
580.652	3.9933
584.13	2.12089
587.605	0.987158
591.08	1.58345
594.552	1.58478
598.025	1.29476
601.496	1.82093
604.964	2.36657
608.433	1.06624
611.898	2.36425
615.364	4.49034
618.827	4.85363
622.288	6.48552
625.75	7.23598
629.209	8.34009
632.667	8.97118
636.125	9.00692
639.58	9.22293
643.033	9.32235
646.485	10.6914
649.936	9.70535
653.388	10.8397
656.836	10.5549
660.283	10.0741
663.728	9.62379
667.173	10.2162
670.616	9.53648
674.057	10.1912
677.498	9.70389
680.937	9.90876
684.375	12.3429
687.809	16.936
691.244	22.1961
694.678	28.2292
698.111	34.0667
701.54	37.1304
704.97	40.173
708.398	42.5874
711.826	43.7753
715.25	45.3384
718.675	45.9348
722.096	46.7688
725.518	46.2413
728.937	45.3967
732.357	44.4566
735.773	43.0678
739.19	41.5211
742.604	39.5383
746.018	37.1324
749.429	35.3727
752.839	33.6542
756.248	31.1279
759.657	30.7175
763.063	31.5976
766.468	33.6779
769.871	37.7695
773.273	41.5397
776.676	44.8832
780.075	46.9273
783.474	47.2273
786.871	48.9719
790.266	51.6403
793.661	53.647
797.054	56.247
800.446	57.1013
803.834	58.9708
807.224	59.5838
810.612	60.4577
813.998	59.5838
817.384	59.5057
820.766	59.1858
824.149	60.3498
827.531	62.5458
830.909	64.511
834.288	66.8463
837.666	68.2593
841.041	67.6261
844.416	67.7539
847.788	67.5607
851.161	67.6706
854.53	66.994
857.901	67.0144
861.268	65.928
864.633	65.1942
868	63.4424
871.363	61.9668
874.725	60.4965
878.088	58.5604
881.447	55.6978
884.805	52.7254
888.162	49.8276
891.518	45.2621
894.872	42.4358
898.225	39.7197
901.577	37.436
904.928	36.1538
908.277	37.4601
911.625	37.8448
914.972	37.7291
918.318	38.6061
921.662	37.9708
925.005	35.8504
928.347	35.1289
931.686	36.3877
935.025	35.5578
938.363	34.8843
941.698	34.0386
945.034	29.8992
948.368	27.9289
951.699	27.335
955.031	25.7458
958.36	23.691
961.689	21.1247
965.016	19.8274
968.343	17.4154
971.666	16.1518
974.991	15.5925
978.312	13.6525
981.632	12.6605
984.953	10.955
988.27	11.1196
991.587	11.2219
994.902	10.9263
998.216	11.2295
1001.53	11.6936
1004.84	10.2408
1008.15	10.8305
1011.46	14.3929
1014.77	15.1545
1018.07	18.3153
1021.38	20.6768
1024.68	21.1931
1027.99	24.4715
1031.29	27.2869
1034.59	28.5587
1037.89	29.7024
1041.18	30.5395
1044.48	31.6996
1047.77	30.8522
1051.07	22.3697
1054.36	-2.68598
1057.65	-16.6506
1060.94	11.3065
1064.23	53.6407
1067.52	94.3334
1070.8	131.741
1074.09	164.745
1077.37	192.928
1080.65	218.371
1083.93	237.291
1087.21	252.785
1090.49	264.203
1093.77	267.934
1097.04	267.186
1100.32	264.546
1103.59	258.205
1106.86	245.465
1110.13	227.204
1113.4	203.02
1116.67	175.36
1119.94	144.021
1123.2	107.893
1126.47	68.6692
1129.73	28.3839
1132.99	-7.2673
1136.25	-21.5118
1139.51	4.87
1142.77	25.404
1146.03	28.382
1149.28	25.7442
1152.54	22.7305
1155.79	18.4109
1159.04	16.4259
1162.29	12.4728
1165.54	9.52303
1168.79	9.48197
1172.04	6.89468
1175.28	4.2951
1178.53	6.62945
1181.77	8.56984
1185.01	9.7382
1188.25	9.29101
1191.49	10.3605
1194.73	13.1094
1197.96	18.4019
1201.2	21.1298
1204.43	23.0837
1207.66	26.3711
1210.9	28.9347
1214.13	32.7416
1217.36	35.0279
1220.58	36.3737
1223.81	37.7023
1227.04	39.5162
1230.26	41.8645
1233.48	43.3165
1236.71	44.824
1239.93	47.6049
1243.14	48.2626
1246.36	49.9769
1249.58	49.8831
1252.8	49.3353
1256.01	50.9469
1259.22	52.5197
1262.43	55.3363
1265.64	57.4036
1268.85	59.967
1272.06	62.9052
1275.27	66.837
1278.48	69.1578
1281.68	71.348
1284.88	74.0357
1288.08	77.5876
1291.28	80.3583
1294.48	82.1886
1297.68	84.898
1300.88	86.7989
1304.07	87.2479
1307.27	88.5669
1310.46	88.8716
1313.65	90.4771
1316.85	92.7461
1320.03	93.2562
1323.22	93.8741
1326.41	94.6199
1329.6	95.3993
1332.78	96.0203
1335.96	98.5541
1339.15	99.8352
1342.33	99.9872
1345.51	99.8424
1348.69	99.9397
1351.86	98.6123
1355.04	97.8379
1358.21	96.7443
1361.39	94.5372
1364.56	92.9351
1367.73	90.607
1370.9	87.3941
1374.07	84.8203
1377.24	81.0709
1380.41	78.9502
1383.57	77.1243
1386.73	76.1216
1389.9	74.8041
1393.06	74.2247
1396.22	73.0545
1399.38	73.7208
1402.54	73.3824
1405.69	75.3074
1408.85	78.7215
1412	84.2427
1415.16	90.5437
1418.31	98.7561
1421.46	105.873
1424.61	112.021
1427.76	120.046
1430.9	127.356
1434.05	134.181
1437.2	140.126
1440.34	145.621
1443.48	149.461
1446.62	150.656
1449.76	151.104
1452.9	150.598
1456.04	149.985
1459.17	148.905
1462.31	146.251
1465.44	141.906
1468.58	137.374
1471.71	131.693
1474.84	126.138
1477.97	120.779
1481.1	113.462
1484.22	109.026
1487.35	101.96
1490.47	97.7571
1493.59	93.5128
1496.72	89.0539
1499.84	81.9218
1502.96	78.985
1506.08	73.6346
1509.19	67.9088
1512.31	61.6044
1515.42	56.4637
1518.54	52.5233
1521.65	47.5152
1524.76	43.674
1527.87	40.9183
1530.98	39.2721
1534.09	38.8938
1537.2	38.468
1540.3	38.3694
1543.41	40.5084
1546.51	43.22
1549.61	45.2206
1552.71	47.1206
1555.81	49.118
1558.91	48.8155
1562.01	51.2808
1565.1	54.2108
1568.2	57.9257
1571.29	60.3566
1574.38	62.3781
1577.48	65.9272
1580.57	68.7874
1583.65	70.8978
1586.74	72.3122
1589.83	73.2507
1592.92	74.15
1596	76.0423
1599.08	76.597
1602.16	73.9086
1605.24	73.2931
1608.32	70.468
1611.4	67.3407
1614.48	65.2625
1617.56	64.3334
1620.63	62.9546
1623.71	60.3479
1626.78	60.8273
1629.85	61.5683
1632.92	60.3969
1635.99	61.9017
1639.06	61.5254
1642.12	63.2168
1645.19	63.5711
1648.25	64.1057
1651.32	66.9248
1654.38	67.8881
1657.44	69.2956
1660.5	68.8462
1663.56	69.3877
1666.62	66.6822
1669.67	65.8156
1672.73	63.0292
1675.79	58.5858
1678.84	53.8847
1681.89	48.8129
1684.94	44.4916
1687.99	41.0991
1691.04	36.958
1694.08	34.9035
1697.13	32.5278
1700.18	30.0533
1703.22	28.4952
1706.26	25.5921
1709.3	22.167
1712.35	20.0852
1715.39	17.5735
1718.42	15.8335
1721.46	14.5623
1724.5	14.5236
1727.53	14.1656
1730.56	14.2026
1733.6	13.969
1736.63	14.3139
1739.66	13.8908
1742.69	12.7775
1745.71	12.866
1748.74	12.85
1751.77	12.2679
1754.79	12.4721
1757.81	12.1562
1760.84	12.2111
1763.86	11.7409
1766.88	11.1083
1769.9	9.39145
1772.91	7.78444
1775.93	6.83189
1778.95	6.66224
1781.96	4.2137
1784.97	3.30086
1787.99	2.1405
1791	1.30452
1794.01	1.11878
1797.01	1.26691
1800.02	2.15946
1803.03	2.29184
1806.03	2.86687
1809.04	3.91899
1812.04	4.38021
1815.04	4.92155
1818.04	5.64858
1821.04	5.69169
1824.04	5.67257
1827.04	6.37059
1830.03	6.21428
1833.03	7.23602
1836.02	5.47892
1839.02	4.46992
1842.01	3.79298
1845	4.08871
1847.99	3.57342
1850.98	3.50229
1853.96	2.49444
1856.95	2.11685
1859.94	2.12102
1862.92	2.40136
1865.9	3.35407
1868.88	3.66867
1871.86	4.40779
1874.84	4.15918
1877.82	4.93418
1880.8	5.43254
1882.58	6.45363
1885.57	5.63929
1888.56	5.49216
1891.54	5.05774
1894.53	5.6588
1897.51	4.70467
1900.5	4.47725
1903.48	4.57619
1906.46	4.45635
1909.44	3.95309
1912.42	5.53498
1915.4	6.99081
1918.37	6.77834
1921.35	7.02807
1924.32	6.52199
1927.3	7.35629
1930.27	8.66216
1933.24	9.16299
1936.21	9.94548
1939.18	9.70498
1942.15	8.12432
1945.11	6.90903
1948.08	6.65091
1951.04	6.09233
1954.01	5.28119
1956.97	4.26226
1959.93	2.89026
1962.89	2.07643
1965.85	0.422822
1968.81	-0.555956
1971.77	-1.5315
1974.72	-1.05438
1977.68	0.116935
1980.63	0.102293
1983.58	0.14539
1986.53	0.633949
1989.48	0.940969
1992.43	1.48381
1995.38	2.21576
1998.33	3.00011
2001.27	3.69414
2004.22	5.18573
2007.16	4.65339
2010.11	4.57456
2013.05	4.11319
2015.99	4.04392
2018.93	4.79617
2021.87	5.59403
2024.8	5.71519
2027.74	4.80795
2030.68	4.39394
2033.61	3.02635
2036.54	1.87837
2039.48	1.72502
2042.41	3.13644
2045.34	2.82772
2048.27	3.57217
2051.19	4.25226
2054.12	4.66214
2057.05	5.29616
2059.97	5.04129
2062.9	5.94341
2065.82	5.58858
2068.74	5.81247
2071.66	5.89173
2074.58	6.24051
2077.5	6.48574
2080.41	5.85304
2083.33	6.45764
2086.24	6.30853
2089.16	6.74211
2092.07	7.10658
2094.98	7.58179
2097.89	9.32022
2100.8	9.60963
2103.71	10.0804
2106.62	10.5224
2109.53	12.3092
2112.43	14.5288
2115.33	15.4472
2118.24	16.0982
2121.14	17.6692
2124.04	18.6419
2126.94	20.0281
2129.84	20.1513
2132.74	22.3691
2135.63	23.2584
2138.53	24.2083
2141.43	26.4078
2144.32	28.7183
2147.21	29.5932
2150.1	31.2606
2152.99	31.8946
2155.88	35.0888
2158.77	37.939
2161.66	40.2344
2164.55	41.8585
2167.43	43.6492
2170.31	43.9469
2173.2	44.4682
2176.08	44.9883
2178.96	45.4576
2181.84	45.3543
2184.72	44.3958
2187.6	43.5225
2190.47	42.8128
2193.35	41.0215
2196.23	39.9676
2199.1	39.2465
2201.97	37.7474
2204.84	35.9244
2207.71	34.2194
2210.58	33.3436
2213.45	31.4655
2216.32	30.0399
2219.19	27.8241
2222.05	27.5311
2224.92	26.5193
2227.78	25.8695
2230.64	25.1769
2233.5	23.8275
2236.36	21.9524
2239.22	20.4809
2242.08	20.231
2244.94	20.0609
2247.79	18.8548
2250.65	17.9825
2253.5	18.0264
2256.36	16.6469
2259.21	15.6502
2262.06	15.3105
2264.91	15.8902
2267.76	16.0044
2270.6	15.8867
2273.45	15.4317
2276.3	14.7536
2279.14	14.0695
2281.98	13.5413
2284.83	12.2357
2287.67	11.4533
2290.51	10.4954
2293.35	9.8069
2296.19	8.48437
2299.02	9.75803
2301.86	10.7418
2304.7	10.7098
2307.53	10.2976
2310.36	10.968
2313.2	11.2654
2316.03	10.4452
2318.86	11.4915
2321.69	12.285
2324.51	11.4117
2327.34	11.3522
2330.17	12.1411
2332.99	13.0102
2335.82	12.4217
2338.64	12.9307
2341.46	10.9488
2344.28	9.76248
2347.1	8.3635
2349.92	7.21211
2352.74	7.00164
2355.56	6.14835
2358.37	5.67651
2361.19	5.73281
2364	5.82441
2366.82	7.03265
2369.63	7.33351
2372.44	6.90314
2375.25	7.24102
2378.06	6.22969
2380.86	4.81496
2383.67	5.98034
2386.48	6.28277
2389.28	5.84207
2392.09	5.17461
2394.89	4.4566
2397.69	3.90751
2400.49	3.2096
2403.29	3.14115
2406.09	3.80339
2408.89	2.61865
2411.69	1.32787
2414.48	1.4802
2417.28	2.86365
2420.07	3.46036
2422.86	3.7063
2425.65	3.35262
2428.45	3.81347
2431.23	3.96511
2434.02	3.7513
2436.81	4.18306
2439.6	4.26412
2442.38	5.53771
2445.17	5.54354
2447.95	5.32387
2450.73	6.36999
2453.52	6.50663
2456.3	6.21143
2459.08	6.7379
2461.85	6.74204
2464.63	7.5646
2467.41	7.98665
2470.19	8.17712
2472.96	8.46795
2475.73	7.00115
2478.51	5.62606
2481.28	4.66205
2484.05	4.68408
2486.82	3.06751
2489.59	2.32798
2492.35	1.19212
2495.12	-0.113124
2497.89	-0.320446
2500.65	-1.16541
2503.42	-1.91797
2506.18	-1.19521
2508.94	-0.606921
2511.7	0.505272
2514.46	-0.0461493
2517.22	-0.186463
2519.98	0.846074
2522.73	1.95758
2525.49	4.16665
2528.25	5.46343
2531	6.14408
2533.75	7.62901
2536.5	8.02034
2539.25	8.48921
2542.01	9.11796
2544.75	9.1195
2547.5	9.71175
2550.25	10.0868
2553	10.0164
2555.74	10.357
2558.49	10.7357
2561.23	11.1896
2563.97	10.2071
2566.71	10.2583
2569.45	9.63504
2572.19	9.14332
2574.93	8.40517
2577.67	7.60644
2580.4	6.53972
2583.14	5.87023
2585.87	6.03371
2588.6	6.12479
2591.34	6.6282
2594.07	6.41571
2596.8	6.9318
2599.53	6.02839
2602.26	5.46443
2604.98	5.1562
2607.71	5.20402
2610.44	5.37526
2613.16	5.70556
2615.88	6.12306
2618.61	5.68665
2621.33	7.06865
2624.05	7.88874
2626.77	8.77916
2629.49	8.86318
2632.21	9.63497
2634.92	10.3754
2637.64	11.0547
2640.35	11.5034
2643.07	11.7565
2645.78	12.1492
2648.49	12.0941
2651.2	12.3702
2653.91	13.0742
2656.62	12.7572
2659.33	12.2417
2662.04	12.0188
2664.74	11.5424
2667.45	11.0227
2670.15	10.7721
2672.86	10.2404
2675.56	10.5865
2678.26	10.518
2680.96	10.2362
2683.66	9.82663
2686.36	9.79144
2689.06	9.87192
2691.75	9.94553
2694.45	10.5217
2697.14	10.4727
2699.84	11.9472
2702.53	12.6727
2705.22	13.9108
2707.91	13.9965
2710.6	14.6241
2713.29	14.4051
2715.98	15.4275
2718.67	16.3688
2721.35	17.149
2724.04	16.8806
2726.72	16.7166
2729.4	15.9195
2732.09	15.4505
2734.77	15.3919
2737.45	13.4054
2740.13	12.6042
2742.81	11.6441
2745.48	11.0276
2748.16	8.84235
2750.84	6.3201
2753.51	5.58378
2756.19	5.1995
2758.86	3.3351
2761.53	2.42649
2764.2	2.57319
2766.87	1.5358
2769.54	1.61245
2772.21	1.5471
2774.88	1.84456
2777.54	1.2626
2780.21	2.04843
2782.87	2.35936
2785.53	1.32287
2788.2	1.29921
2790.86	0.390509
2793.52	-0.125708
2796.18	0.29025
2798.84	1.08301
2801.49	0.202221
2804.15	-0.716446
2806.81	-1.04678
2809.46	-2.2018
2812.12	-2.56312
2814.77	-2.6484
2817.42	-0.60774
2820.07	3.5304
2822.72	7.82916
2825.37	13.0085
2828.02	20.5233
2830.67	28.6217
2833.31	36.9994
2835.96	46.8333
2838.61	55.1346
2841.25	64.2574
2843.89	73.8719
2846.53	83.4481
2849.17	93.4958
2851.81	104.632
2854.45	115.645
2857.09	125.496
2859.73	135.781
2862.36	144.752
2865	152.682
2867.64	157.956
2870.27	164.352
2872.9	169.858
2875.53	173.657
2878.16	177.397
2880.79	183.103
2883.42	188.925
2886.05	193.966
2888.68	199.315
2891.3	204.574
2893.93	210.899
2896.55	215.557
2899.18	219.566
2901.8	225.564
2904.42	232.083
2907.04	240.693
2909.66	248.995
2912.28	257.637
2914.9	267.603
2917.51	276.968
2920.13	284.967
2922.74	291.787
2925.36	297.061
2927.97	298.997
2930.59	299.648
2933.2	297.542
2935.81	294.509
2938.42	287.052
2941.02	279.528
2943.63	271.309
2946.24	260.886
2948.85	248.647
2951.45	235.791
2954.05	223.365
2956.66	210.902
2959.26	198.51
2961.86	186.816
2964.46	175.624
2967.06	166.116
2969.66	157.63
2972.26	148.87
2974.85	141.711
2977.45	134.547
2980.05	127.218
2982.64	120.46
2985.23	112.255
2987.83	104.809
2990.42	95.9308
2993.01	86.6673
2995.6	77.969
2998.19	69.1436
3000.77	60.4664
3003.36	52.0626
3005.95	44.1945
3008.53	36.3139
3011.12	29.6519
3013.7	22.859
3016.28	17.7026
3018.86	13.4818
3021.44	9.85362
3024.02	6.80731
3026.6	4.08442
3029.18	2.14663
3031.76	1.03478
3034.33	-1.01089
3036.91	0.0571018
3039.48	0.994879
3042.05	1.64803
3044.63	2.78799
3047.2	3.74326
3049.77	4.34302
3052.34	4.02649
3054.91	4.48166
3057.48	5.56917
3060.04	5.29558
3062.61	5.95598
3065.17	5.85784
3067.74	5.67015
3070.3	5.6914
3072.87	6.44122
3075.43	5.59845
3077.99	4.25413
3080.55	3.87874
3083.11	2.84004
3085.67	1.79396
3088.22	1.67864
3090.78	0.927072
3093.34	0.249975
3095.89	-0.574395
3098.44	0.381668
3101	2.33077
3103.55	2.31211
3106.1	4.02529
3108.65	4.97383
3111.2	5.4391
3113.75	7.02819
3116.3	8.4863
3118.84	9.71685
3121.39	11.0951
3123.93	12.3006
3126.48	15.2038
3129.02	17.3823
3131.56	19.8357
3134.1	22.4326
3136.64	24.2417
3139.18	26.7045
3141.72	29.1654
3144.26	32.1821
3146.8	35.3973
3149.33	38.4819