File: data/Raman/poly_smoothed/Mbcal_20_25_06_1x_45s_532 nm_x100_100%_600 gr_mm_01.txt
#Acq. time (s)=	45
#Accumulations=	2
#Range (cm-¹)=	200...3150
#Windows=	2
#Auto scanning=	Off
#Autofocus=	Off
#Macrospot=	Off
#AutoExposure=	Off
#Spike filter=	Multiple accum.
#Delay time (s)=	0
#Binning=	1
#Readout mode=	Signal
#DeNoise=	Off
#ICS correction=	On
#Dark correction=	Off
#Inst. Process=	Off
#Detector Gain=	Best Dynamic Range
#Detector ADC=	20 kHz
#Detector temperature (°C)=	-69.85
#Instrument=	LabRAM HR Evol
#Detector=	Synapse
#Objective=	x100
#Grating=	600 gr/mm
#ND Filter=	100%
#Laser (nm)=	532
#Hole=	100.021
#Range=	Auto
#Laser Pol.=	No
#Raman. Pol.=	No
#Laser Pol. (°)=	-0.0007625
#Raman Pol. (°)=	89.9995
#Collection=	Microscope
#StageXY=	Marzhauser
#StageZ=	Marzhauser
#X (µm)=	-1198.6
#Y (µm)=	1255.5
#Z (µm)=	577.9
#Full time(mm:ss)=	3:18
#Project=
#Sample=
#Site=
#Title=	Mbcal_20_25_06_2x_45s_532 nm_x100_100%_600 gr_mm
#Remark=
#Date=	18.07.2022 09:51
#Acquired=	18.07.2022 09:51:44
#Base:Fit=	10.08.2022 10:55:08
#Base:Sub=	10.08.2022 10:55:14
#Filter:Polynom=	16.08.2022 10:07:27
#AxisType[0]=Intens
#AxisUnit[0]=Cnt
#AxisType[1]=Spectr
#AxisUnit[1]=1/cm
200.419	34.7626
204.048	27.3596
207.678	19.7631
211.304	16.6751
214.928	15.729
218.554	15.0949
222.176	16.3601
225.798	18.2258
229.417	20.7363
233.035	22.9694
236.653	25.1716
240.268	26.5949
243.881	26.4662
247.493	26.8779
251.103	27.326
254.715	27.0106
258.322	27.9157
261.929	27.713
265.534	29.3519
269.137	30.3207
272.739	30.3431
276.34	27.4591
279.939	24.5537
283.537	23.6356
287.134	22.4976
290.729	22.0689
294.323	23.7894
297.913	25.6432
301.504	25.6176
305.093	27.7867
308.682	30.1096
312.268	33.5724
315.852	37.238
319.436	39.4194
323.018	40.1977
326.597	42.0469
330.177	41.8665
333.753	42.0624
337.331	42.7003
340.906	42.5975
344.478	42.9148
348.051	41.7822
351.621	40.9214
355.189	38.6584
358.757	36.6666
362.323	33.0173
365.889	29.7341
369.451	28.0397
373.012	25.8485
376.574	23.8326
380.133	24.0206
383.69	24.044
387.245	24.1593
390.8	23.1625
394.353	25.1237
397.906	24.7247
401.456	25.1866
405.005	23.4332
408.552	22.4429
412.099	22.9679
415.643	23.5732
419.187	23.5992
422.728	21.5319
426.269	20.0302
429.806	17.8214
433.344	16.3193
436.881	13.9502
440.416	11.6975
443.949	8.9161
447.48	7.95734
451.011	7.78786
454.541	6.93744
458.069	5.8461
461.594	6.38066
465.119	8.43882
468.642	4.46336
472.165	5.21945
475.684	11.401
479.204	16.0586
482.721	19.8997
486.239	23.302
489.753	27.8853
493.268	32.1957
496.779	37.0772
500.289	41.0288
503.8	44.5648
507.307	47.0412
510.813	50.4296
514.32	53.8282
517.823	56.2091
521.325	56.7791
524.826	56.2498
528.325	56.0444
531.823	54.9432
535.32	50.9575
538.815	47.6275
542.309	42.4168
545.802	37.5767
549.293	32.8768
552.783	25.3777
556.271	19.7477
559.759	23.0666
563.245	20.689
566.729	15.7334
570.213	12.0778
573.693	8.55269
577.173	6.32285
580.652	3.984
584.13	1.81989
587.605	1.59632
591.08	-0.0508737
594.552	0.389098
598.025	1.53336
601.496	1.46713
604.964	4.45017
608.433	5.77614
611.898	7.74231
615.364	10.2031
618.827	10.181
622.288	11.5668
625.75	12.9762
629.209	13.7741
632.667	14.4645
636.125	13.4253
639.58	14.8685
643.033	16.1141
646.485	15.9542
649.936	15.9409
653.388	16.6289
656.836	16.2629
660.283	15.4333
663.728	15.8824
667.173	15.7207
670.616	14.641
674.057	15.6194
677.498	13.8469
680.937	14.8828
684.375	17.5098
687.809	18.3682
691.244	19.7108
694.678	19.5835
698.111	20.2069
701.54	19.7796
704.97	19.3462
708.398	18.7902
711.826	18.5193
715.25	20.3764
718.675	20.5171
722.096	20.3901
725.518	19.8002
728.937	18.095
732.357	18.0361
735.773	19.4823
739.19	21.7507
742.604	22.2738
746.018	24.5994
749.429	27.0153
752.839	28.9585
756.248	32.3048
759.657	32.4071
763.063	35.0248
766.468	37.8255
769.871	38.7205
773.273	39.9509
776.676	41.4639
780.075	42.4763
783.474	46.3858
786.871	48.0368
790.266	49.9975
793.661	53.0506
797.054	55.4812
800.446	57.09
803.834	57.4448
807.224	56.0648
810.612	54.8573
813.998	54.8517
817.384	54.8144
820.766	56.8303
824.149	59.2143
827.531	59.8883
830.909	64.6488
834.288	67.0713
837.666	70.3402
841.041	72.4395
844.416	74.5199
847.788	74.9713
851.161	74.6728
854.53	74.821
857.901	73.7671
861.268	73.1948
864.633	71.4862
868	71.2199
871.363	68.8455
874.725	67.1225
878.088	63.9121
881.447	59.8968
884.805	56.1201
888.162	50.1967
891.518	45.9884
894.872	39.6496
898.225	36.9487
901.577	36.2793
904.928	36.5049
908.277	36.6263
911.625	38.6984
914.972	41.3747
918.318	39.5025
921.662	40.5128
925.005	38.6186
928.347	37.8719
931.686	36.9162
935.025	37.2354
938.363	35.3348
941.698	34.0862
945.034	32.8035
948.368	31.7521
951.699	31.8941
955.031	30.7959
958.36	30.3245
961.689	27.8498
965.016	27.2264
968.343	24.2081
971.666	23.0733
974.991	21.642
978.312	21.8754
981.632	22.5869
984.953	22.0664
988.27	22.2738
991.587	21.8941
994.902	23.9027
998.216	22.0302
1001.53	22.3564
1004.84	22.096
1008.15	22.2575
1011.46	25.8166
1014.77	28.3507
1018.07	31.6805
1021.38	34.4981
1024.68	36.1797
1027.99	37.1088
1031.29	39.2273
1034.59	41.7732
1037.89	42.0793
1041.18	40.2382
1044.48	42.2733
1047.77	42.3058
1051.07	41.3602
1054.36	40.0492
1057.65	39.3977
1060.94	38.1616
1064.23	37.4107
1067.52	36.9867
1070.8	35.5961
1074.09	34.3492
1077.37	34.287
1080.65	32.4399
1083.93	31.737
1087.21	32.5885
1090.49	36.0154
1093.77	38.0972
1097.04	39.9041
1100.32	39.0829
1103.59	38.2926
1106.86	36.8802
1110.13	37.5445
1113.4	37.9116
1116.67	37.4301
1119.94	36.5042
1123.2	35.3959
1126.47	31.1902
1129.73	28.2523
1132.99	25.999
1136.25	23.8734
1139.51	22.0004
1142.77	19.1482
1146.03	16.6707
1149.28	13.5869
1152.54	11.0711
1155.79	9.11704
1159.04	7.35426
1162.29	5.42999
1165.54	6.26162
1168.79	7.3943
1172.04	6.41231
1175.28	6.25913
1178.53	7.78908
1181.77	7.35255
1185.01	7.50286
1188.25	8.29271
1191.49	10.4061
1194.73	11.9103
1197.96	14.1188
1201.2	16.4024
1204.43	18.0444
1207.66	22.2732
1210.9	26.9745
1214.13	31.1089
1217.36	34.9084
1220.58	37.8306
1223.81	41.2255
1227.04	45.8211
1230.26	49.8399
1233.48	53.0872
1236.71	59.1691
1239.93	61.8513
1243.14	63.3805
1246.36	67.7022
1249.58	70.0666
1252.8	72.278
1256.01	73.0204
1259.22	73.9801
1262.43	74.3234
1265.64	75.4601
1268.85	76.8691
1272.06	78.476
1275.27	79.4268
1278.48	82.1936
1281.68	84.962
1284.88	87.0231
1288.08	89.7505
1291.28	91.0437
1294.48	93.2922
1297.68	94.4332
1300.88	96.5596
1304.07	98.0381
1307.27	100.701
1310.46	102.299
1313.65	104.947
1316.85	106.136
1320.03	106.76
1323.22	107.278
1326.41	107.041
1329.6	104.648
1332.78	103.103
1335.96	101.544
1339.15	99.1653
1342.33	96.7772
1345.51	94.0228
1348.69	91.5242
1351.86	88.9872
1355.04	86.5437
1358.21	83.8575
1361.39	81.2765
1364.56	77.0035
1367.73	75.304
1370.9	72.9003
1374.07	70.8485
1377.24	70.5889
1380.41	70.7212
1383.57	69.45
1386.73	70.9284
1389.9	69.4266
1393.06	70.4607
1396.22	70.4527
1399.38	71.378
1402.54	73.6085
1405.69	76.3148
1408.85	79.6582
1412	85.3948
1415.16	89.7807
1418.31	96.7941
1421.46	105.365
1424.61	113.321
1427.76	122.016
1430.9	128.94
1434.05	134.5
1437.2	140.286
1440.34	145.293
1443.48	149.613
1446.62	150.716
1449.76	151.317
1452.9	148.901
1456.04	145.62
1459.17	140.945
1462.31	137.063
1465.44	131.195
1468.58	124.297
1471.71	119.842
1474.84	111.827
1477.97	105.236
1481.1	98.7111
1484.22	91.0839
1487.35	84.2485
1490.47	78.8675
1493.59	71.9566
1496.72	66.4486
1499.84	61.6643
1502.96	57.0259
1506.08	51.923
1509.19	47.5651
1512.31	43.0907
1515.42	40.0672
1518.54	37.6971
1521.65	33.9286
1524.76	31.6986
1527.87	30.8672
1530.98	31.2224
1534.09	32.4918
1537.2	35.8792
1540.3	39.2407
1543.41	40.7859
1546.51	43.7528
1549.61	46.5798
1552.71	48.3193
1555.81	51.0604
1558.91	51.7554
1562.01	52.6407
1565.1	54.2015
1568.2	55.8362
1571.29	57.084
1574.38	58.4777
1577.48	61.4537
1580.57	64.1035
1583.65	65.4714
1586.74	65.966
1589.83	69.0338
1592.92	71.6587
1596	72.2408
1599.08	71.7815
1602.16	73.1543
1605.24	73.6259
1608.32	74.9554
1611.4	75.1102
1614.48	77.1025
1617.56	77.9488
1620.63	77.3203
1623.71	78.19
1626.78	78.5754
1629.85	79.6158
1632.92	80.9639
1635.99	83.9323
1639.06	86.8369
1642.12	89.7716
1645.19	92.9604
1648.25	96.6071
1651.32	99.674
1654.38	101.167
1657.44	102.661
1660.5	100.922
1663.56	99.4183
1666.62	98.2022
1669.67	95.1062
1672.73	91.0173
1675.79	85.9758
1678.84	80.8541
1681.89	75.5537
1684.94	70.1947
1687.99	62.7855
1691.04	56.5352
1694.08	50.6316
1697.13	45.9688
1700.18	40.978
1703.22	36.0727
1706.26	33.4417
1709.3	30.1303
1712.35	27.1917
1715.39	25.1311
1718.42	22.2886
1721.46	22.2112
1724.5	19.5282
1727.53	16.4374
1730.56	14.9502
1733.6	12.7817
1736.63	10.7555
1739.66	9.90227
1742.69	7.73699
1745.71	7.04324
1748.74	3.71698
1751.77	2.83701
1754.79	1.55588
1757.81	1.5209
1760.84	0.676566
1763.86	0.807279
1766.88	2.0728
1769.9	2.3481
1772.91	1.64904
1775.93	3.76138
1778.95	4.05263
1781.96	5.55757
1784.97	6.32051
1787.99	6.63717
1791	7.75736
1794.01	8.76512
1797.01	8.45707
1800.02	8.80244
1803.03	8.96754
1806.03	9.49626
1809.04	9.70392
1812.04	9.56191
1815.04	8.38593
1818.04	7.71553
1821.04	6.76578
1824.04	7.4061
1827.04	7.53844
1830.03	8.15141
1833.03	7.48096
1836.02	8.25407
1839.02	7.96103
1842.01	7.2317
1845	8.43397
1847.99	8.87568
1850.98	7.94549
1853.96	6.67117
1856.95	6.10421
1859.94	6.1256
1862.92	6.27578
1865.9	6.38384
1868.88	5.52564
1871.86	5.23273
1874.84	4.09342
1877.82	3.905
1880.8	4.10334
1882.58	3.69684
1885.57	3.08506
1888.56	2.82213
1891.54	3.41499
1894.53	4.59129
1897.51	5.0497
1900.5	5.20457
1903.48	6.70628
1906.46	7.75079
1909.44	7.60723
1912.42	8.27059
1915.4	7.8734
1918.37	7.65847
1921.35	6.64724
1924.32	6.08551
1927.3	6.16469
1930.27	6.09138
1933.24	6.18551
1936.21	6.26443
1939.18	5.31908
1942.15	4.96164
1945.11	5.54229
1948.08	4.67103
1951.04	5.88411
1954.01	5.82341
1956.97	5.88219
1959.93	6.11717
1962.89	5.79596
1965.85	6.42188
1968.81	5.93816
1971.77	5.01178
1974.72	5.65346
1977.68	6.81383
1980.63	6.91562
1983.58	7.63353
1986.53	7.81339
1989.48	8.1549
1992.43	9.34143
1995.38	8.99202
1998.33	8.1641
2001.27	7.57627
2004.22	7.89703
2007.16	7.68323
2010.11	6.80303
2013.05	7.74437
2015.99	7.50876
2018.93	7.58829
2021.87	7.82194
2024.8	8.93792
2027.74	9.40285
2030.68	8.93213
2033.61	9.57981
2036.54	8.83674
2039.48	8.44234
2042.41	8.95474
2045.34	9.6675
2048.27	10.8835
2051.19	10.8608
2054.12	11.9757
2057.05	11.6671
2059.97	11.7967
2062.9	11.8087
2065.82	11.2987
2068.74	9.40496
2071.66	8.67519
2074.58	7.60433
2077.5	8.03672
2080.41	8.82313
2083.33	9.07206
2086.24	10.0681
2089.16	10.5336
2092.07	11.1397
2094.98	12.7916
2097.89	14.6243
2100.8	16.1986
2103.71	17.8556
2106.62	20.0821
2109.53	21.6597
2112.43	24.073
2115.33	24.8285
2118.24	27.548
2121.14	29.6708
2124.04	32.836
2126.94	33.8216
2129.84	35.8719
2132.74	38.585
2135.63	41.0366
2138.53	41.953
2141.43	43.9823
2144.32	46.6433
2147.21	47.8541
2150.1	51.1456
2152.99	53.7901
2155.88	56.0782
2158.77	57.945
2161.66	60.3115
2164.55	61.3255
2167.43	63.8912
2170.31	65.4832
2173.2	66.699
2176.08	66.6498
2178.96	65.6835
2181.84	64.4766
2184.72	63.6347
2187.6	64.1432
2190.47	63.4487
2193.35	60.7499
2196.23	57.9584
2199.1	54.1174
2201.97	51.6871
2204.84	47.7187
2207.71	44.7573
2210.58	41.6449
2213.45	40.3297
2216.32	36.4604
2219.19	35.2976
2222.05	32.8813
2224.92	31.4957
2227.78	28.2924
2230.64	26.5203
2233.5	23.7489
2236.36	21.5591
2239.22	19.4808
2242.08	18.6544
2244.94	16.9293
2247.79	15.9104
2250.65	14.2312
2253.5	13.7013
2256.36	13.1534
2259.21	11.9521
2262.06	9.83275
2264.91	9.65472
2267.76	8.72014
2270.6	8.13953
2273.45	8.31136
2276.3	8.4574
2279.14	8.81868
2281.98	9.00504
2284.83	8.9491
2287.67	8.51388
2290.51	7.7977
2293.35	6.24202
2296.19	4.61507
2299.02	3.60656
2301.86	4.49799
2304.7	5.26817
2307.53	5.56335
2310.36	5.26524
2313.2	6.25875
2316.03	6.11111
2318.86	4.61453
2321.69	3.93131
2324.51	4.26743
2327.34	4.40055
2330.17	3.95584
2332.99	3.99262
2335.82	3.61008
2338.64	3.09879
2341.46	3.4348
2344.28	3.36798
2347.1	2.69787
2349.92	3.13001
2352.74	1.76737
2355.56	0.721192
2358.37	0.574613
2361.19	-0.718399
2364	-0.606739
2366.82	0.21558
2369.63	1.16754
2372.44	1.7245
2375.25	1.20602
2378.06	1.30669
2380.86	1.59752
2383.67	2.77023
2386.48	2.05714
2389.28	1.00891
2392.09	0.975497
2394.89	0.69127
2397.69	0.37492
2400.49	-0.474873
2403.29	-0.216978
2406.09	-0.583352
2408.89	-0.0771821
2411.69	0.4231
2414.48	0.192838
2417.28	1.13806
2420.07	1.38249
2422.86	2.1493
2425.65	2.48131
2428.45	3.43619
2431.23	4.16111
2434.02	4.98352
2436.81	5.04517
2439.6	5.1513
2442.38	4.37876
2445.17	4.23526
2447.95	4.9008
2450.73	5.12313
2453.52	5.75296
2456.3	4.89524
2459.08	3.85598
2461.85	3.14908
2464.63	3.23231
2467.41	2.31977
2470.19	2.46388
2472.96	2.49233
2475.73	2.85462
2478.51	2.8789
2481.28	3.55499
2484.05	3.88567
2486.82	4.89596
2489.59	5.25434
2492.35	5.70176
2495.12	6.51313
2497.89	7.40002
2500.65	7.07955
2503.42	6.47461
2506.18	5.36287
2508.94	4.66942
2511.7	4.92664
2514.46	5.15264
2517.22	5.96259
2519.98	6.11735
2522.73	4.99946
2525.49	3.68916
2528.25	3.52958
2531	3.57116
2533.75	3.8656
2536.5	3.22866
2539.25	4.43468
2542.01	3.73348
2544.75	3.1704
2547.5	3.5257
2550.25	3.14309
2553	3.54313
2555.74	3.99407
2558.49	4.87864
2561.23	3.89392
2563.97	4.17758
2566.71	4.83173
2569.45	4.56438
2572.19	4.95625
2574.93	5.36083
2577.67	6.87692
2580.4	7.4983
2583.14	9.23112
2585.87	9.18159
2588.6	9.38111
2591.34	9.03773
2594.07	9.40496
2596.8	10.6884
2599.53	9.60165
2602.26	8.35591
2604.98	8.6653
2607.71	7.83572
2610.44	6.99752
2613.16	6.64059
2615.88	6.52541
2618.61	6.92367
2621.33	7.27997
2624.05	7.6296
2626.77	7.0276
2629.49	8.22766
2632.21	8.31546
2634.92	9.38645
2637.64	10.6374
2640.35	11.9942
2643.07	13.0533
2645.78	14.1594
2648.49	13.8836
2651.2	13.5686
2653.91	12.8657
2656.62	11.8979
2659.33	10.6209
2662.04	10.7329
2664.74	8.96785
2667.45	7.71911
2670.15	7.47841
2672.86	6.59593
2675.56	5.44209
2678.26	5.21689
2680.96	5.33875
2683.66	5.50675
2686.36	5.69177
2689.06	6.14279
2691.75	5.78221
2694.45	7.03232
2697.14	7.86943
2699.84	9.33209
2702.53	11.7141
2705.22	13.655
2707.91	14.7628
2710.6	17.2721
2713.29	17.6731
2715.98	17.168
2718.67	17.8639
2721.35	18.5445
2724.04	20.0461
2726.72	20.5
2729.4	19.0821
2732.09	18.4985
2734.77	17.6511
2737.45	16.1399
2740.13	14.3123
2742.81	13.3607
2745.48	11.9849
2748.16	10.6001
2750.84	8.8392
2753.51	7.10547
2756.19	6.70851
2758.86	5.68142
2761.53	4.95829
2764.2	4.56588
2766.87	3.77945
2769.54	4.30199
2772.21	4.19987
2774.88	3.19149
2777.54	2.44706
2780.21	1.82499
2782.87	2.79791
2785.53	2.33897
2788.2	1.51793
2790.86	0.719259
2793.52	0.0416701
2796.18	-0.465371
2798.84	-0.41382
2801.49	0.010908
2804.15	-0.866602
2806.81	-1.01578
2809.46	-0.253726
2812.12	-0.295385
2814.77	0.691448
2817.42	2.88292
2820.07	6.0874
2822.72	10.2247
2825.37	15.7825
2828.02	21.7244
2830.67	28.9588
2833.31	37.0012
2835.96	45.124
2838.61	53.6535
2841.25	62.4196
2843.89	73.0616
2846.53	84.3251
2849.17	96.9004
2851.81	108.895
2854.45	123.559
2857.09	136.961
2859.73	149.596
2862.36	162.418
2865	174.819
2867.64	185.411
2870.27	193.729
2872.9	202.238
2875.53	210.452
2878.16	216.824
2880.79	225.327
2883.42	232.009
2886.05	239.592
2888.68	245.715
2891.3	253.777
2893.93	261.814
2896.55	269.603
2899.18	277.964
2901.8	289.314
2904.42	301.617
2907.04	315.353
2909.66	331.433
2912.28	349.006
2914.9	364.557
2917.51	381.101
2920.13	395.813
2922.74	406.444
2925.36	415.538
2927.97	422.166
2930.59	425.127
2933.2	424.248
2935.81	418.607
2938.42	411.039
2941.02	399.904
2943.63	386.353
2946.24	370.103
2948.85	352.593
2951.45	334.538
2954.05	316.313
2956.66	299.318
2959.26	281.429
2961.86	265.026
2964.46	250.413
2967.06	236.669
2969.66	223.676
2972.26	212.825
2974.85	202.939
2977.45	192.632
2980.05	182.331
2982.64	172.153
2985.23	160.862
2987.83	148.514
2990.42	136.736
2993.01	124.453
2995.6	111.713
2998.19	99.3997
3000.77	86.5936
3003.36	74.3455
3005.95	63.1732
3008.53	52.0322
3011.12	42.9083
3013.7	34.8066
3016.28	28.5032
3018.86	22.7665
3021.44	16.9114
3024.02	13.4813
3026.6	9.92957
3029.18	7.44537
3031.76	5.72964
3034.33	5.29577
3036.91	5.0961
3039.48	7.09626
3042.05	7.01873
3044.63	6.6328
3047.2	6.54372
3049.77	6.27021
3052.34	6.65674
3054.91	5.96036
3057.48	6.21899
3060.04	5.90338
3062.61	5.59001
3065.17	5.90108
3067.74	5.904
3070.3	5.96349
3072.87	5.44505
3075.43	4.05767
3077.99	3.4407
3080.55	2.77794
3083.11	1.58379
3085.67	1.01973
3088.22	0.261238
3090.78	0.572348
3093.34	1.01687
3095.89	1.19719
3098.44	2.63973
3101	3.37285
3103.55	3.5204
3106.1	3.64055
3108.65	4.23083
3111.2	5.10862
3113.75	6.57016
3116.3	7.01644
3118.84	7.92303
3121.39	9.30819
3123.93	11.0542
3126.48	13.4056
3129.02	16.1585
3131.56	18.4993
3134.1	20.2249
3136.64	22.2935
3139.18	25.9609
3141.72	29.5491
3144.26	32.9283
3146.8	36.8704
3149.33	42.1247