File: data/Raman/poly_smoothed/Mbcal_20_25_41_1x_45s_532 nm_x100_100%_600 gr_mm_01.txt
#Acq. time (s)=	45
#Accumulations=	2
#Range (cm-¹)=	200...3150
#Windows=	2
#Auto scanning=	Off
#Autofocus=	Off
#Macrospot=	Off
#AutoExposure=	Off
#Spike filter=	Multiple accum.
#Delay time (s)=	0
#Binning=	1
#Readout mode=	Signal
#DeNoise=	Off
#ICS correction=	On
#Dark correction=	Off
#Inst. Process=	Off
#Detector Gain=	Best Dynamic Range
#Detector ADC=	20 kHz
#Detector temperature (°C)=	-69.85
#Instrument=	LabRAM HR Evol
#Detector=	Synapse
#Objective=	x100
#Grating=	600 gr/mm
#ND Filter=	100%
#Laser (nm)=	532
#Hole=	100.021
#Range=	Auto
#Laser Pol.=	No
#Raman. Pol.=	No
#Laser Pol. (°)=	-0.0007625
#Raman Pol. (°)=	89.9995
#Collection=	Microscope
#StageXY=	Marzhauser
#StageZ=	Marzhauser
#X (µm)=	-1131.9
#Y (µm)=	1268.1
#Z (µm)=	577.8
#Full time(mm:ss)=	3:18
#Project=
#Sample=
#Site=
#Title=	Mbcal_20_25_41_2x_45s_532 nm_x100_100%_600 gr_mm
#Remark=
#Date=	18.07.2022 13:18
#Acquired=	18.07.2022 13:18:44
#Base:Fit=	10.08.2022 10:55:08
#Base:Sub=	10.08.2022 10:55:14
#Filter:Polynom=	16.08.2022 10:07:28
#AxisType[0]=Intens
#AxisUnit[0]=Cnt
#AxisType[1]=Spectr
#AxisUnit[1]=1/cm
200.419	4.42125
204.048	6.31384
207.678	6.4512
211.304	4.66699
214.928	4.91873
218.554	4.95089
222.176	4.99287
225.798	5.20427
229.417	4.91132
233.035	4.70697
236.653	5.14898
240.268	7.63167
243.881	9.19286
247.493	9.62522
251.103	10.3463
254.715	12.7748
258.322	13.6403
261.929	14.0648
265.534	15.4356
269.137	15.9509
272.739	15.1931
276.34	17.5077
279.939	18.63
283.537	18.2702
287.134	18.3661
290.729	17.9113
294.323	18.1506
297.913	18.3919
301.504	19.6936
305.093	20.2748
308.682	20.9469
312.268	21.7668
315.852	21.4896
319.436	21.5506
323.018	24.2724
326.597	26.7899
330.177	28.1076
333.753	28.1607
337.331	27.9778
340.906	28.7808
344.478	27.2868
348.051	24.5621
351.621	25.6676
355.189	25.7218
358.757	23.4047
362.323	21.6016
365.889	19.946
369.451	17.8048
373.012	16.866
376.574	17.1801
380.133	16.8404
383.69	16.6854
387.245	17.0906
390.8	17.8722
394.353	19.899
397.906	19.2139
401.456	19.097
405.005	18.0738
408.552	19.9616
412.099	18.6294
415.643	17.6621
419.187	15.9768
422.728	14.2294
426.269	12.4935
429.806	11.8709
433.344	9.06673
436.881	8.62245
440.416	8.40307
443.949	6.89431
447.48	5.30267
451.011	5.41949
454.541	5.65699
458.069	7.45287
461.594	9.83209
465.119	12.2247
468.642	13.3842
472.165	15.3322
475.684	18.3963
479.204	21.3166
482.721	22.4816
486.239	24.4337
489.753	26.0619
493.268	26.9953
496.779	27.931
500.289	26.7898
503.8	24.9122
507.307	25.8003
510.813	25.3508
514.32	24.7501
517.823	25.3953
521.325	25.1591
524.826	25.1036
528.325	25.3785
531.823	24.9072
535.32	23.9364
538.815	23.7134
542.309	23.5119
545.802	24.0476
549.293	22.18
552.783	20.7789
556.271	19.9215
559.759	19.8845
563.245	18.6467
566.729	18.4725
570.213	15.9864
573.693	14.4615
577.173	12.0955
580.652	9.67806
584.13	7.21381
587.605	4.23885
591.08	3.81321
594.552	3.27454
598.025	2.73472
601.496	5.04437
604.964	5.5477
608.433	5.97216
611.898	8.09452
615.364	10.7771
618.827	12.305
622.288	14.2344
625.75	14.5511
629.209	16.475
632.667	17.4229
636.125	18.1747
639.58	19.8466
643.033	20.1837
646.485	20.0073
649.936	19.9545
653.388	19.0593
656.836	18.1743
660.283	18.7311
663.728	17.4097
667.173	18.2602
670.616	18.3912
674.057	19.8544
677.498	19.9246
680.937	21.2685
684.375	23.4538
687.809	25.1497
691.244	26.6719
694.678	27.7678
698.111	29.8993
701.54	31.1241
704.97	31.3861
708.398	31.9701
711.826	32.0849
715.25	33.9866
718.675	34.9248
722.096	33.5098
725.518	32.8859
728.937	32.2024
732.357	32.059
735.773	32.7862
739.19	33.389
742.604	33.6146
746.018	35.469
749.429	38.1528
752.839	41.0764
756.248	45.2276
759.657	49.1344
763.063	53.0312
766.468	57.6176
769.871	60.8659
773.273	63.0632
776.676	64.6344
780.075	67.0312
783.474	68.0224
786.871	69.6084
790.266	69.7285
793.661	72.7555
797.054	74.5188
800.446	75.1879
803.834	74.3985
807.224	72.9399
810.612	73.0471
813.998	73.5356
817.384	74.7069
820.766	73.9908
824.149	75.3843
827.531	76.4988
830.909	78.6995
834.288	78.8951
837.666	81.1792
841.041	82.1244
844.416	81.6766
847.788	80.8247
851.161	77.9308
854.53	75.0662
857.901	71.7766
861.268	69.1708
864.633	67.1248
868	65.8767
871.363	64.2155
874.725	62.4688
878.088	60.0996
881.447	58.1238
884.805	54.0898
888.162	51.9737
891.518	51.3538
894.872	50.5205
898.225	50.1167
901.577	49.5774
904.928	48.2168
908.277	48.9976
911.625	49.416
914.972	49.9655
918.318	49.0918
921.662	49.3484
925.005	48.2033
928.347	46.2843
931.686	46.351
935.025	47.4558
938.363	46.8125
941.698	45.6516
945.034	44.6333
948.368	43.8034
951.699	42.8161
955.031	40.7048
958.36	39.2347
961.689	35.6135
965.016	34.841
968.343	35.0607
971.666	35.7027
974.991	36.655
978.312	35.9588
981.632	37.0805
984.953	35.9457
988.27	36.2871
991.587	35.9311
994.902	36.4465
998.216	37.2765
1001.53	36.5072
1004.84	36.7963
1008.15	35.6433
1011.46	35.9727
1014.77	35.8681
1018.07	35.7958
1021.38	34.2916
1024.68	33.8091
1027.99	32.9583
1031.29	31.4448
1034.59	30.4956
1037.89	29.2461
1041.18	28.3441
1044.48	28.6704
1047.77	29.0311
1051.07	28.7547
1054.36	29.2629
1057.65	27.8954
1060.94	26.6546
1064.23	25.4257
1067.52	25.5387
1070.8	25.3278
1074.09	26.8731
1077.37	26.2258
1080.65	25.0784
1083.93	23.7731
1087.21	23.3532
1090.49	23.6676
1093.77	24.627
1097.04	23.996
1100.32	25.0672
1103.59	25.9204
1106.86	25.9199
1110.13	25.0897
1113.4	24.9991
1116.67	24.6458
1119.94	26.2214
1123.2	25.2792
1126.47	23.6159
1129.73	22.726
1132.99	22.3481
1136.25	21.7732
1139.51	20.601
1142.77	20.3247
1146.03	18.7213
1149.28	18.0417
1152.54	16.2826
1155.79	13.8619
1159.04	10.692
1162.29	9.10795
1165.54	7.97347
1168.79	6.15348
1172.04	5.18807
1175.28	4.94964
1178.53	4.36538
1181.77	5.15033
1185.01	6.5046
1188.25	7.79781
1191.49	8.29391
1194.73	9.13559
1197.96	10.072
1201.2	11.8743
1204.43	12.9067
1207.66	15.2905
1210.9	18.4602
1214.13	21.1922
1217.36	24.6625
1220.58	26.5423
1223.81	28.7944
1227.04	31.1822
1230.26	34.1421
1233.48	35.0968
1236.71	36.5432
1239.93	38.6115
1243.14	38.724
1246.36	39.8353
1249.58	42.6813
1252.8	42.9803
1256.01	45.5029
1259.22	47.5957
1262.43	48.9935
1265.64	49.2215
1268.85	49.3245
1272.06	50.3492
1275.27	51.83
1278.48	53.2837
1281.68	55.3143
1284.88	56.9688
1288.08	57.6604
1291.28	58.2778
1294.48	58.715
1297.68	58.8204
1300.88	59.388
1304.07	61.3587
1307.27	61.5431
1310.46	62.8358
1313.65	63.9623
1316.85	64.2098
1320.03	63.9286
1323.22	64.1699
1326.41	65.844
1329.6	65.943
1332.78	64.8104
1335.96	63.9765
1339.15	61.9838
1342.33	60.9834
1345.51	59.9923
1348.69	59.3043
1351.86	58.8707
1355.04	57.6547
1358.21	54.6812
1361.39	52.4128
1364.56	50.3094
1367.73	46.8827
1370.9	44.0881
1374.07	42.7158
1377.24	41.7524
1380.41	43.2878
1383.57	42.308
1386.73	41.8735
1389.9	41.6393
1393.06	41.7702
1396.22	41.1453
1399.38	42.883
1402.54	42.998
1405.69	44.38
1408.85	45.7263
1412	47.3231
1415.16	48.6877
1418.31	52.7006
1421.46	57.4079
1424.61	62.0112
1427.76	65.933
1430.9	71.2678
1434.05	74.4204
1437.2	77.8832
1440.34	82.1421
1443.48	85.6427
1446.62	86.8791
1449.76	87.9243
1452.9	88.6773
1456.04	88.5367
1459.17	85.9735
1462.31	84.1634
1465.44	81.7603
1468.58	78.0086
1471.71	74.251
1474.84	69.8131
1477.97	64.5223
1481.1	60.4439
1484.22	55.2709
1487.35	50.8121
1490.47	44.4317
1493.59	41.4064
1496.72	39.4577
1499.84	35.6134
1502.96	31.7359
1506.08	29.9604
1509.19	26.4185
1512.31	23.3728
1515.42	21.8396
1518.54	21.0923
1521.65	19.483
1524.76	17.688
1527.87	16.3151
1530.98	15.4133
1534.09	15.0791
1537.2	17.636
1540.3	19.6437
1543.41	20.3736
1546.51	21.9704
1549.61	23.205
1552.71	25.1415
1555.81	27.6845
1558.91	27.7467
1562.01	28.1545
1565.1	28.9058
1568.2	30.4445
1571.29	31.8712
1574.38	30.6829
1577.48	31.4658
1580.57	32.6139
1583.65	33.3257
1586.74	34.5514
1589.83	36.9976
1592.92	38.7231
1596	39.3751
1599.08	39.6132
1602.16	38.7576
1605.24	38.7114
1608.32	39.5402
1611.4	39.6627
1614.48	41.1424
1617.56	41.888
1620.63	42.0615
1623.71	44.027
1626.78	44.4978
1629.85	45.2193
1632.92	46.2485
1635.99	46.2247
1639.06	49.2564
1642.12	50.3679
1645.19	52.2315
1648.25	54.5776
1651.32	56.8653
1654.38	58.7634
1657.44	59.6505
1660.5	59.9987
1663.56	60.3722
1666.62	59.6917
1669.67	57.2939
1672.73	54.0093
1675.79	51.0153
1678.84	46.353
1681.89	42.6784
1684.94	38.1861
1687.99	32.9563
1691.04	28.3523
1694.08	23.277
1697.13	20.4879
1700.18	16.4013
1703.22	11.7366
1706.26	8.55301
1709.3	6.34699
1712.35	4.71063
1715.39	3.69415
1718.42	3.49074
1721.46	3.44739
1724.5	3.20666
1727.53	1.92527
1730.56	2.04541
1733.6	1.87461
1736.63	1.39851
1739.66	2.74291
1742.69	3.15069
1745.71	2.03176
1748.74	1.47352
1751.77	1.77541
1754.79	1.44603
1757.81	0.261238
1760.84	0.455689
1763.86	0.0453413
1766.88	-0.0358953
1769.9	1.03117
1772.91	0.689621
1775.93	-0.470239
1778.95	-0.158341
1781.96	0.360682
1784.97	0.362218
1787.99	0.287532
1791	0.0805714
1794.01	0.209708
1797.01	0.269466
1800.02	0.694515
1803.03	1.25093
1806.03	1.99544
1809.04	2.28063
1812.04	2.82176
1815.04	2.51685
1818.04	2.60659
1821.04	1.61219
1824.04	2.00489
1827.04	1.78817
1830.03	1.71537
1833.03	1.8206
1836.02	2.14637
1839.02	2.35781
1842.01	2.57453
1845	2.53179
1847.99	2.0599
1850.98	1.84809
1853.96	1.63563
1856.95	1.86716
1859.94	1.61084
1862.92	1.31187
1865.9	1.2695
1868.88	1.92755
1871.86	1.83973
1874.84	2.71799
1877.82	3.3585
1880.8	4.32125
1882.58	4.45225
1885.57	5.07497
1888.56	5.06049
1891.54	5.37428
1894.53	5.36019
1897.51	4.68294
1900.5	4.17196
1903.48	4.2849
1906.46	3.56158
1909.44	3.04927
1912.42	3.30554
1915.4	3.22914
1918.37	2.97674
1921.35	2.90476
1924.32	3.97276
1927.3	3.97606
1930.27	3.40231
1933.24	3.01975
1936.21	4.3442
1939.18	4.69644
1942.15	4.70195
1945.11	5.43823
1948.08	6.21779
1951.04	6.02704
1954.01	7.60017
1956.97	7.10834
1959.93	7.04608
1962.89	6.17411
1965.85	5.19527
1968.81	4.12249
1971.77	3.75243
1974.72	3.01182
1977.68	2.35301
1980.63	1.74564
1983.58	2.3254
1986.53	2.12896
1989.48	0.798918
1992.43	1.20088
1995.38	1.96578
1998.33	2.39938
2001.27	1.5951
2004.22	1.78012
2007.16	2.4158
2010.11	1.58784
2013.05	1.74439
2015.99	1.80255
2018.93	1.71104
2021.87	2.38271
2024.8	3.32767
2027.74	4.65806
2030.68	4.67715
2033.61	5.5121
2036.54	5.69561
2039.48	6.61783
2042.41	7.30066
2045.34	7.90076
2048.27	8.27406
2051.19	8.32161
2054.12	8.70834
2057.05	8.86517
2059.97	9.70212
2062.9	10.8416
2065.82	10.297
2068.74	11.1361
2071.66	9.80291
2074.58	9.51058
2077.5	8.92321
2080.41	8.25132
2083.33	8.38475
2086.24	9.35324
2089.16	10.2834
2092.07	11.3265
2094.98	12.9987
2097.89	13.7235
2100.8	15.701
2103.71	17.2427
2106.62	18.0898
2109.53	19.8593
2112.43	20.2593
2115.33	22.083
2118.24	24.2863
2121.14	25.2263
2124.04	26.2248
2126.94	28.2075
2129.84	30.4343
2132.74	32.4447
2135.63	33.5564
2138.53	34.9236
2141.43	37.6734
2144.32	40.3086
2147.21	42.6193
2150.1	44.5352
2152.99	47.7028
2155.88	51.3134
2158.77	53.0506
2161.66	56.0102
2164.55	57.51
2167.43	60.0431
2170.31	62.3718
2173.2	63.8491
2176.08	63.5887
2178.96	63.9787
2181.84	63.2766
2184.72	62.198
2187.6	61.4095
2190.47	59.4749
2193.35	56.4189
2196.23	53.7663
2199.1	50.6736
2201.97	47.5698
2204.84	45.1162
2207.71	42.5369
2210.58	40.0306
2213.45	37.719
2216.32	35.2291
2219.19	32.8785
2222.05	30.8825
2224.92	29.5936
2227.78	27.6409
2230.64	26.2607
2233.5	25.2089
2236.36	24.0367
2239.22	22.6048
2242.08	21.4186
2244.94	18.7065
2247.79	18.1551
2250.65	17.5152
2253.5	17.212
2256.36	16.2385
2259.21	15.2381
2262.06	14.2483
2264.91	13.2258
2267.76	12.7104
2270.6	12.6619
2273.45	12.8663
2276.3	12.0778
2279.14	11.8207
2281.98	11.3001
2284.83	11.1076
2287.67	11.1421
2290.51	9.94594
2293.35	8.5599
2296.19	8.5914
2299.02	9.6928
2301.86	10.7352
2304.7	11.3656
2307.53	11.1984
2310.36	11.306
2313.2	11.6948
2316.03	12.2033
2318.86	13.1979
2321.69	13.6551
2324.51	14.7175
2327.34	14.1811
2330.17	13.4973
2332.99	13.4511
2335.82	13.4909
2338.64	12.7161
2341.46	10.3922
2344.28	9.10029
2347.1	7.73154
2349.92	6.6204
2352.74	5.44317
2355.56	4.18741
2358.37	2.95225
2361.19	2.08291
2364	2.69246
2366.82	5.01573
2369.63	6.0227
2372.44	5.79992
2375.25	6.43451
2378.06	7.50247
2380.86	7.1799
2383.67	7.83077
2386.48	7.78988
2389.28	8.26833
2392.09	7.87158
2394.89	8.15526
2397.69	7.24504
2400.49	7.33332
2403.29	6.59769
2406.09	6.05565
2408.89	5.79088
2411.69	6.44853
2414.48	6.8718
2417.28	5.88295
2420.07	6.54942
2422.86	5.91232
2425.65	5.90627
2428.45	4.90068
2431.23	4.51407
2434.02	4.86903
2436.81	5.02111
2439.6	4.65653
2442.38	4.60335
2445.17	4.37425
2447.95	3.89327
2450.73	3.28067
2453.52	3.25544
2456.3	2.60389
2459.08	2.85677
2461.85	1.9693
2464.63	3.08763
2467.41	4.33073
2470.19	5.2365
2472.96	6.32462
2475.73	7.17171
2478.51	8.10338
2481.28	8.12942
2484.05	8.36914
2486.82	8.99163
2489.59	8.93122
2492.35	7.93873
2495.12	6.81825
2497.89	6.41531
2500.65	6.49442
2503.42	5.82237
2506.18	5.24798
2508.94	4.97249
2511.7	4.3821
2514.46	4.51334
2517.22	4.01059
2519.98	3.04874
2522.73	3.10435
2525.49	3.02028
2528.25	3.21003
2531	3.73772
2533.75	4.38329
2536.5	4.84284
2539.25	5.33998
2542.01	5.86997
2544.75	6.62363
2547.5	7.05241
2550.25	8.09172
2553	8.49115
2555.74	8.35179
2558.49	7.3098
2561.23	6.93684
2563.97	6.38397
2566.71	7.10427
2569.45	5.91946
2572.19	5.52472
2574.93	5.33758
2577.67	5.83184
2580.4	5.36803
2583.14	4.96489
2585.87	3.90913
2588.6	3.57808
2591.34	2.48197
2594.07	2.41998
2596.8	2.80672
2599.53	1.94747
2602.26	2.56399
2604.98	2.80616
2607.71	3.05746
2610.44	3.18082
2613.16	3.38005
2615.88	3.59252
2618.61	3.96173
2621.33	4.36197
2624.05	4.18695
2626.77	4.32607
2629.49	4.56306
2632.21	5.4089
2634.92	5.67149
2637.64	5.81577
2640.35	6.90433
2643.07	7.69649
2645.78	7.30219
2648.49	7.89753
2651.2	7.44336
2653.91	7.66893
2656.62	7.7531
2659.33	8.22868
2662.04	8.07987
2664.74	8.27341
2667.45	8.09339
2670.15	8.05045
2672.86	8.30422
2675.56	7.59809
2678.26	7.78838
2680.96	8.39794
2683.66	8.77004
2686.36	8.8778
2689.06	9.03055
2691.75	9.5819
2694.45	9.96341
2697.14	10.2557
2699.84	12.2346
2702.53	13.3937
2705.22	14.6797
2707.91	14.6647
2710.6	15.4637
2713.29	16.0973
2715.98	17.3955
2718.67	17.3139
2721.35	17.8447
2724.04	16.9639
2726.72	16.6823
2729.4	15.8138
2732.09	14.9615
2734.77	13.3762
2737.45	12.4405
2740.13	10.5493
2742.81	8.79179
2745.48	7.78986
2748.16	6.13745
2750.84	5.9088
2753.51	4.32851
2756.19	3.83166
2758.86	2.43123
2761.53	2.10421
2764.2	2.26987
2766.87	1.46463
2769.54	0.889419
2772.21	-0.308392
2774.88	-0.248814
2777.54	0.277982
2780.21	0.104189
2782.87	0.557271
2785.53	-0.126806
2788.2	-0.489514
2790.86	0.380869
2793.52	1.10534
2796.18	1.54058
2798.84	1.17701
2801.49	0.374715
2804.15	0.726448
2806.81	0.0533388
2809.46	-0.816422
2812.12	-0.855553
2814.77	-0.471397
2817.42	0.956307
2820.07	3.08755
2822.72	6.50118
2825.37	10.6285
2828.02	14.8454
2830.67	19.7918
2833.31	24.3872
2835.96	30.0081
2838.61	36.4794
2841.25	43.9737
2843.89	52.1637
2846.53	60.699
2849.17	69.9429
2851.81	79.201
2854.45	89.1356
2857.09	99.0302
2859.73	107.449
2862.36	115.316
2865	122.358
2867.64	128.885
2870.27	134.86
2872.9	139.38
2875.53	144.927
2878.16	149.942
2880.79	155.296
2883.42	160.249
2886.05	164.696
2888.68	169.691
2891.3	174.349
2893.93	179.64
2896.55	184.845
2899.18	191.174
2901.8	198.167
2904.42	207.49
2907.04	217.171
2909.66	227.312
2912.28	236.978
2914.9	247.881
2917.51	257.662
2920.13	266.362
2922.74	274.721
2925.36	279.895
2927.97	283.539
2930.59	285.104
2933.2	285.13
2935.81	282.973
2938.42	278.188
2941.02	272.898
2943.63	264.613
2946.24	256.327
2948.85	246.439
2951.45	235.646
2954.05	226.277
2956.66	215.161
2959.26	204.985
2961.86	194.615
2964.46	185.223
2967.06	176.54
2969.66	167.483
2972.26	158.648
2974.85	151.241
2977.45	142.54
2980.05	134.014
2982.64	125.447
2985.23	117.124
2987.83	108.474
2990.42	98.9279
2993.01	90.4211
2995.6	81.1172
2998.19	73.0164
3000.77	64.5008
3003.36	57.3197
3005.95	49.2071
3008.53	42.4118
3011.12	35.8365
3013.7	30.0125
3016.28	25.0792
3018.86	20.951
3021.44	17.4517
3024.02	15.1066
3026.6	12.6031
3029.18	10.8408
3031.76	9.43663
3034.33	8.63076
3036.91	8.72716
3039.48	9.28326
3042.05	9.61304
3044.63	10.02
3047.2	12.1957
3049.77	12.606
3052.34	13.7313
3054.91	14.1135
3057.48	14.7705
3060.04	14.1802
3062.61	13.6779
3065.17	13.3949
3067.74	12.8522
3070.3	11.2608
3072.87	9.9466
3075.43	8.5153
3077.99	7.66058
3080.55	5.87336
3083.11	4.4259
3085.67	3.71207
3088.22	2.70318
3090.78	1.44399
3093.34	1.12733
3095.89	0.976426
3098.44	1.40663
3101	1.32511
3103.55	1.24224
3106.1	1.47276
3108.65	1.42015
3111.2	2.1415
3113.75	1.5496
3116.3	2.19692
3118.84	1.95847
3121.39	1.80305
3123.93	1.36863
3126.48	2.28798
3129.02	2.36389
3131.56	2.85707
3134.1	3.41778
3136.64	3.27734
3139.18	3.70112
3141.72	4.40766
3144.26	5.6299
3146.8	6.92715
3149.33	8.15776