File: data/Raman/poly_smoothed/Mbcal_20_25_03_1x_45s_532 nm_x100_100%_600 gr_mm_01.txt
#Acq. time (s)=	45
#Accumulations=	2
#Range (cm-¹)=	200...3150
#Windows=	2
#Auto scanning=	Off
#Autofocus=	Off
#Macrospot=	Off
#AutoExposure=	Off
#Spike filter=	Multiple accum.
#Delay time (s)=	0
#Binning=	1
#Readout mode=	Signal
#DeNoise=	Off
#ICS correction=	On
#Dark correction=	Off
#Inst. Process=	Off
#Detector Gain=	Best Dynamic Range
#Detector ADC=	20 kHz
#Detector temperature (°C)=	-69.85
#Instrument=	LabRAM HR Evol
#Detector=	Synapse
#Objective=	x100
#Grating=	600 gr/mm
#ND Filter=	100%
#Laser (nm)=	532
#Hole=	100.021
#Range=	Auto
#Laser Pol.=	No
#Raman. Pol.=	No
#Laser Pol. (°)=	-0.0007625
#Raman Pol. (°)=	89.9995
#Collection=	Microscope
#StageXY=	Marzhauser
#StageZ=	Marzhauser
#X (µm)=	-1206.2
#Y (µm)=	1269.1
#Z (µm)=	577.95
#Full time(mm:ss)=	3:19
#Project=
#Sample=
#Site=
#Title=	Mbcal_20_25_03_2x_45s_532 nm_x100_100%_600 gr_mm
#Remark=
#Date=	18.07.2022 09:37
#Acquired=	18.07.2022 09:37:16
#Base:Fit=	10.08.2022 10:55:08
#Base:Sub=	10.08.2022 10:55:14
#Filter:Polynom=	16.08.2022 09:24:11
#Filter:Polynom=	16.08.2022 10:07:27
#AxisType[0]=Intens
#AxisUnit[0]=Cnt
#AxisType[1]=Spectr
#AxisUnit[1]=1/cm
200.419	8.02328
204.048	9.11461
207.678	11.4284
211.304	14.0248
214.928	16.6846
218.554	16.111
222.176	18.641
225.798	22.2169
229.417	25.0418
233.035	30.9964
236.653	36.6635
240.268	39.7555
243.881	43.2058
247.493	46.2419
251.103	49.8279
254.715	52.6166
258.322	55.4137
261.929	55.615
265.534	55.5953
269.137	55.427
272.739	56.242
276.34	56.8966
279.939	55.9712
283.537	53.8289
287.134	50.4556
290.729	47.4738
294.323	46.1697
297.913	40.9655
301.504	38.2816
305.093	36.498
308.682	34.3401
312.268	34.2577
315.852	34.4107
319.436	36.5096
323.018	35.5215
326.597	32.9181
330.177	33.2405
333.753	34.2004
337.331	33.7537
340.906	32.7057
344.478	30.0007
348.051	24.2418
351.621	23.5742
355.189	22.3074
358.757	22.1571
362.323	20.5301
365.889	19.4986
369.451	16.2354
373.012	16.242
376.574	15.0682
380.133	11.7043
383.69	14.8222
387.245	13.6726
390.8	16.2865
394.353	17.7659
397.906	19.742
401.456	19.3827
405.005	21.9564
408.552	22.7192
412.099	22.4395
415.643	23.5181
419.187	24.037
422.728	22.8398
426.269	20.34
429.806	16.3978
433.344	14.3287
436.881	11.4668
440.416	12.5068
443.949	11.8002
447.48	11.3881
451.011	8.63602
454.541	10.4616
458.069	7.85452
461.594	8.88297
465.119	8.85232
468.642	11.6948
472.165	12.5169
475.684	13.0527
479.204	17.6529
482.721	18.7527
486.239	20.897
489.753	24.147
493.268	26.2271
496.779	27.7467
500.289	28.5085
503.8	28.3786
507.307	29.2643
510.813	30.006
514.32	29.538
517.823	27.6029
521.325	28.5608
524.826	28.0068
528.325	30.1355
531.823	29.8681
535.32	28.8717
538.815	28.2597
542.309	28.437
545.802	28.6006
549.293	28.1559
552.783	26.5582
556.271	28.8277
559.759	28.8385
563.245	29.6455
566.729	28.9297
570.213	29.8034
573.693	31.7455
577.173	32.0741
580.652	29.8728
584.13	31.3577
587.605	29.4577
591.08	26.6677
594.552	26.5626
598.025	21.7757
601.496	18.6001
604.964	17.1408
608.433	17.0247
611.898	14.5162
615.364	13.3787
618.827	12.4216
622.288	11.9923
625.75	10.901
629.209	12.2852
632.667	9.65425
636.125	9.85647
639.58	13.3832
643.033	15.0621
646.485	17.6512
649.936	19.4188
653.388	21.0028
656.836	23.9757
660.283	28.4839
663.728	31.5532
667.173	34.1653
670.616	35.656
674.057	36.1456
677.498	38.1391
680.937	39.5944
684.375	40.7929
687.809	40.4998
691.244	42.2989
694.678	40.7801
698.111	40.0814
701.54	41.7277
704.97	41.7126
708.398	38.9609
711.826	39.0049
715.25	41.5714
718.675	37.0342
722.096	38.9606
725.518	39.8094
728.937	39.5827
732.357	40.7936
735.773	41.9416
739.19	44.6272
742.604	51.1907
746.018	56.2239
749.429	61.9855
752.839	66.6878
756.248	73.0903
759.657	78.5339
763.063	81.7287
766.468	85.8032
769.871	89.1976
773.273	94.6744
776.676	100.873
780.075	102.889
783.474	106.214
786.871	110.769
790.266	113.364
793.661	116.052
797.054	117.737
800.446	118.508
803.834	117.245
807.224	119.17
810.612	118.689
813.998	118.012
817.384	117.632
820.766	119.909
824.149	123.528
827.531	126.346
830.909	129.106
834.288	132.18
837.666	134.777
841.041	137.261
844.416	137.445
847.788	139.404
851.161	139.038
854.53	139.806
857.901	139.719
861.268	140.871
864.633	137.34
868	137.006
871.363	133.813
874.725	127.524
878.088	124.131
881.447	118.967
884.805	114.13
888.162	109.639
891.518	105.542
894.872	96.9307
898.225	93.2577
901.577	90.9504
904.928	88.4148
908.277	92.0451
911.625	93.3897
914.972	92.8617
918.318	95.521
921.662	95.5452
925.005	93.3327
928.347	94.7311
931.686	96.3252
935.025	96.1442
938.363	95.0576
941.698	93.6676
945.034	91.4052
948.368	88.2463
951.699	86.3762
955.031	81.8472
958.36	78.3278
961.689	75.8028
965.016	69.6628
968.343	65.857
971.666	60.4908
974.991	56.4985
978.312	53.1165
981.632	48.7896
984.953	44.4059
988.27	44.069
991.587	39.5202
994.902	37.8922
998.216	38.0951
1001.53	34.4805
1004.84	36.5446
1008.15	36.1963
1011.46	39.6601
1014.77	41.144
1018.07	39.5754
1021.38	41.1866
1024.68	46.22
1027.99	48.9288
1031.29	52.6418
1034.59	53.0983
1037.89	53.9471
1041.18	53.6089
1044.48	54.6459
1047.77	53.2842
1051.07	54.8323
1054.36	54.0927
1057.65	53.7148
1060.94	52.7821
1064.23	50.5457
1067.52	48.4862
1070.8	48.9408
1074.09	47.9236
1077.37	47.7367
1080.65	45.9104
1083.93	43.0489
1087.21	42.744
1090.49	40.7622
1093.77	43.5507
1097.04	40.4056
1100.32	38.4821
1103.59	41.3225
1106.86	43.4277
1110.13	41.8853
1113.4	39.9151
1116.67	37.7643
1119.94	37.3587
1123.2	38.3904
1126.47	36.5876
1129.73	34.9721
1132.99	33.3409
1136.25	32.0671
1139.51	33.1473
1142.77	33.7158
1146.03	29.1208
1149.28	30.1626
1152.54	29.3977
1155.79	27.2518
1159.04	29.1299
1162.29	27.8923
1165.54	27.5123
1168.79	26.3592
1172.04	22.2445
1175.28	20.5367
1178.53	19.535
1181.77	21.546
1185.01	22.8304
1188.25	21.7762
1191.49	21.7488
1194.73	23.2083
1197.96	22.6763
1201.2	23.8062
1204.43	25.1613
1207.66	24.606
1210.9	23.3452
1214.13	27.1464
1217.36	28.7995
1220.58	31.3965
1223.81	32.9019
1227.04	35.2366
1230.26	39.6613
1233.48	41.3001
1236.71	44.7109
1239.93	49.2076
1243.14	53.1603
1246.36	56.1022
1249.58	58.7027
1252.8	60.3197
1256.01	65.6271
1259.22	65.5486
1262.43	67.5467
1265.64	71.2102
1268.85	70.8551
1272.06	74.1499
1275.27	76.186
1278.48	77.7851
1281.68	76.9851
1284.88	77.1025
1288.08	78.1757
1291.28	81.3929
1294.48	79.4047
1297.68	79.8151
1300.88	79.4887
1304.07	78.9309
1307.27	81.775
1310.46	82.6134
1313.65	85.0882
1316.85	90.1412
1320.03	92.4315
1323.22	94.8167
1326.41	95.705
1329.6	95.4981
1332.78	96.2129
1335.96	96.9731
1339.15	99.4559
1342.33	100.521
1345.51	102.17
1348.69	102.669
1351.86	104.588
1355.04	102.203
1358.21	102.196
1361.39	101.786
1364.56	101.059
1367.73	100.746
1370.9	96.8827
1374.07	93.5615
1377.24	93.9368
1380.41	93.4229
1383.57	93.2006
1386.73	90.9388
1389.9	86.1906
1393.06	84.3225
1396.22	82.2372
1399.38	83.4494
1402.54	85.5838
1405.69	85.5524
1408.85	88.1238
1412	88.0765
1415.16	91.5305
1418.31	95.8931
1421.46	100.001
1424.61	104.875
1427.76	110.835
1430.9	117.344
1434.05	122.619
1437.2	127.328
1440.34	129.919
1443.48	131.663
1446.62	134.239
1449.76	133.507
1452.9	133.724
1456.04	133.946
1459.17	132.947
1462.31	129.917
1465.44	123.758
1468.58	118.4
1471.71	117.656
1474.84	114.621
1477.97	112.533
1481.1	105.352
1484.22	97.9027
1487.35	90.5113
1490.47	86.0546
1493.59	81.8484
1496.72	76.9924
1499.84	72.7176
1502.96	68.7769
1506.08	64.3955
1509.19	61.4399
1512.31	55.0252
1515.42	50.8906
1518.54	48.9469
1521.65	48.7339
1524.76	48.6421
1527.87	46.5444
1530.98	47.7201
1534.09	47.2841
1537.2	47.1291
1540.3	46.7154
1543.41	48.5735
1546.51	51.0953
1549.61	55.6671
1552.71	55.8283
1555.81	58.3682
1558.91	57.9858
1562.01	58.5282
1565.1	61.8888
1568.2	64.0665
1571.29	64.3179
1574.38	65.477
1577.48	67.7337
1580.57	68.4776
1583.65	69.6899
1586.74	70.8642
1589.83	72.2885
1592.92	76.4746
1596	78.2874
1599.08	79.8398
1602.16	79.2969
1605.24	79.1952
1608.32	78.2769
1611.4	75.5175
1614.48	71.6116
1617.56	68.8382
1620.63	66.5721
1623.71	62.8905
1626.78	63.1049
1629.85	62.9308
1632.92	63.0924
1635.99	62.866
1639.06	64.1774
1642.12	64.732
1645.19	66.0638
1648.25	69.3613
1651.32	69.5258
1654.38	70.404
1657.44	71.0103
1660.5	71.7307
1663.56	72.6942
1666.62	72.6782
1669.67	72.5108
1672.73	69.9551
1675.79	68.0141
1678.84	62.8473
1681.89	57.8215
1684.94	49.3219
1687.99	39.9087
1691.04	33.7614
1694.08	28.7453
1697.13	24.8753
1700.18	20.6152
1703.22	17.8366
1706.26	13.6777
1709.3	9.10084
1712.35	5.78225
1715.39	4.45276
1718.42	4.39143
1721.46	3.74415
1724.5	6.27094
1727.53	6.19679
1730.56	6.23732
1733.6	6.27443
1736.63	7.69931
1739.66	8.36151
1742.69	9.98135
1745.71	9.81098
1748.74	8.02331
1751.77	8.27948
1754.79	8.23581
1757.81	8.91777
1760.84	8.83842
1763.86	8.09446
1766.88	7.79617
1769.9	7.06848
1772.91	4.18928
1775.93	4.22165
1778.95	3.5902
1781.96	3.1759
1784.97	3.77787
1787.99	4.6968
1791	3.36692
1794.01	3.95363
1797.01	4.97557
1800.02	4.74694
1803.03	3.16491
1806.03	2.38785
1809.04	1.05319
1812.04	0.304112
1815.04	-0.531433
1818.04	-1.31036
1821.04	-1.12075
1824.04	-0.590003
1827.04	0.299619
1830.03	2.35909
1833.03	0.940778
1836.02	0.842476
1839.02	2.06408
1842.01	2.17068
1845	3.1235
1847.99	5.85511
1850.98	6.79751
1853.96	7.51635
1856.95	9.13767
1859.94	9.33052
1862.92	9.60635
1865.9	8.44839
1868.88	9.7295
1871.86	9.35369
1874.84	9.63345
1877.82	8.86
1880.8	6.71835
1882.58	6.23724
1885.57	4.86537
1888.56	4.85723
1891.54	3.959
1894.53	5.10118
1897.51	3.62446
1900.5	3.23839
1903.48	0.470763
1906.46	0.350177
1909.44	1.71382
1912.42	0.770329
1915.4	2.24267
1918.37	4.94911
1921.35	6.94233
1924.32	7.15062
1927.3	7.95648
1930.27	10.684
1933.24	10.8503
1936.21	12.7478
1939.18	13.3828
1942.15	14.7585
1945.11	16.7125
1948.08	18.8905
1951.04	17.3072
1954.01	17.0046
1956.97	15.3531
1959.93	15.8744
1962.89	15.427
1965.85	15.0516
1968.81	16.077
1971.77	14.3774
1974.72	13.2999
1977.68	13.4905
1980.63	12.9932
1983.58	12.9513
1986.53	12.7081
1989.48	12.3838
1992.43	13.2606
1995.38	11.5989
1998.33	12.5433
2001.27	13.3722
2004.22	11.6063
2007.16	12.8446
2010.11	12.0306
2013.05	13.0487
2015.99	14.9102
2018.93	14.6144
2021.87	12.0549
2024.8	14.7506
2027.74	15.852
2030.68	15.7924
2033.61	17.0697
2036.54	18.259
2039.48	19.4814
2042.41	18.7756
2045.34	19.4159
2048.27	18.8746
2051.19	17.4865
2054.12	16.0579
2057.05	15.7371
2059.97	15.0198
2062.9	15.9072
2065.82	16.5759
2068.74	17.4912
2071.66	17.801
2074.58	15.5033
2077.5	13.4548
2080.41	13.7418
2083.33	13.8
2086.24	15.1318
2089.16	15.1272
2092.07	14.4671
2094.98	14.5527
2097.89	14.6553
2100.8	14.3428
2103.71	14.6281
2106.62	16.791
2109.53	16.0524
2112.43	17.6677
2115.33	19.5938
2118.24	22.6448
2121.14	23.0379
2124.04	24.6337
2126.94	28.7126
2129.84	31.3313
2132.74	34.3868
2135.63	37.452
2138.53	39.7869
2141.43	41.3255
2144.32	41.9599
2147.21	43.676
2150.1	45.3581
2152.99	49.1062
2155.88	50.833
2158.77	51.0533
2161.66	50.9404
2164.55	50.5676
2167.43	50.8747
2170.31	53.4606
2173.2	53.8011
2176.08	55.0415
2178.96	55.5566
2181.84	56.3728
2184.72	56.0645
2187.6	55.0518
2190.47	54.317
2193.35	52.7691
2196.23	49.8307
2199.1	46.7877
2201.97	45.0592
2204.84	42.8468
2207.71	42.3033
2210.58	40.4272
2213.45	38.5861
2216.32	37.2202
2219.19	35.7958
2222.05	33.2032
2224.92	32.8835
2227.78	29.2675
2230.64	27.6334
2233.5	27.848
2236.36	28.1175
2239.22	28.7681
2242.08	28.4819
2244.94	28.9421
2247.79	28.9907
2250.65	30.4947
2253.5	31.6868
2256.36	33.0163
2259.21	32.7491
2262.06	34.1313
2264.91	33.5905
2267.76	32.8277
2270.6	33.8673
2273.45	33.0671
2276.3	30.0083
2279.14	29.471
2281.98	26.7556
2284.83	25.2937
2287.67	22.6936
2290.51	19.9865
2293.35	17.431
2296.19	15.2889
2299.02	14.5937
2301.86	14.1218
2304.7	14.8162
2307.53	14.5679
2310.36	15.1435
2313.2	15.3557
2316.03	15.8253
2318.86	17.5461
2321.69	19.0032
2324.51	20.0745
2327.34	20.8679
2330.17	20.4114
2332.99	20.4215
2335.82	19.0794
2338.64	16.5019
2341.46	14.2589
2344.28	13.5333
2347.1	12.8229
2349.92	11.5449
2352.74	11.9444
2355.56	11.2365
2358.37	8.8203
2361.19	8.48318
2364	8.26561
2366.82	8.20039
2369.63	9.61392
2372.44	10.6604
2375.25	10.0545
2378.06	11.0963
2380.86	11.3522
2383.67	11.21
2386.48	12.8734
2389.28	13.9647
2392.09	14.5077
2394.89	14.5567
2397.69	13.9838
2400.49	12.8144
2403.29	12.1352
2406.09	9.85734
2408.89	12.0121
2411.69	14.541
2414.48	16.4105
2417.28	16.7348
2420.07	16.9754
2422.86	18.1706
2425.65	17.0009
2428.45	15.8486
2431.23	14.5167
2434.02	13.8352
2436.81	13.8869
2439.6	13.5404
2442.38	14.0458
2445.17	14.8615
2447.95	15.2885
2450.73	15.7222
2453.52	15.0398
2456.3	14.593
2459.08	15.2385
2461.85	15.8714
2464.63	13.9963
2467.41	12.4164
2470.19	11.214
2472.96	10.7096
2475.73	11.7058
2478.51	11.4983
2481.28	8.56365
2484.05	6.82345
2486.82	4.53406
2489.59	5.04153
2492.35	5.19287
2495.12	3.90231
2497.89	2.83322
2500.65	3.33655
2503.42	4.26807
2506.18	5.02532
2508.94	5.77074
2511.7	7.28116
2514.46	5.04581
2517.22	5.38392
2519.98	3.8535
2522.73	3.53031
2525.49	4.91831
2528.25	5.90432
2531	7.32242
2533.75	6.73685
2536.5	6.1749
2539.25	7.58409
2542.01	6.78348
2544.75	7.79309
2547.5	8.24627
2550.25	8.56274
2553	11.4934
2555.74	14.1375
2558.49	15.8556
2561.23	16.5494
2563.97	16.0259
2566.71	17.26
2569.45	17.9399
2572.19	16.5058
2574.93	14.6647
2577.67	13.7035
2580.4	12.2777
2583.14	10.964
2585.87	9.42202
2588.6	9.07367
2591.34	8.49339
2594.07	9.14636
2596.8	7.65879
2599.53	5.03072
2602.26	4.62268
2604.98	3.51291
2607.71	3.92511
2610.44	5.01341
2613.16	4.72155
2615.88	4.10285
2618.61	6.00709
2621.33	4.9318
2624.05	4.42041
2626.77	3.11994
2629.49	2.05492
2632.21	2.5345
2634.92	1.73064
2637.64	2.35837
2640.35	1.65627
2643.07	4.18063
2645.78	4.55314
2648.49	4.82779
2651.2	3.77922
2653.91	4.83409
2656.62	3.12684
2659.33	3.0012
2662.04	4.79627
2664.74	4.35656
2667.45	5.61949
2670.15	8.05119
2672.86	8.6016
2675.56	9.49675
2678.26	11.8528
2680.96	10.8537
2683.66	11.0272
2686.36	10.5683
2689.06	10.496
2691.75	11.5723
2694.45	11.6704
2697.14	13.9283
2699.84	14.8179
2702.53	16.183
2705.22	17.6785
2707.91	19.0149
2710.6	19.6988
2713.29	19.0971
2715.98	18.8423
2718.67	19.1766
2721.35	18.8128
2724.04	18.8135
2726.72	18.832
2729.4	18.5365
2732.09	15.7556
2734.77	14.7697
2737.45	13.155
2740.13	12.8272
2742.81	12.1061
2745.48	9.30658
2748.16	7.30575
2750.84	5.69462
2753.51	5.6334
2756.19	6.76502
2758.86	6.1062
2761.53	5.51702
2764.2	5.45099
2766.87	5.14162
2769.54	5.6083
2772.21	5.00349
2774.88	4.86824
2777.54	5.11916
2780.21	4.92841
2782.87	4.99514
2785.53	5.16742
2788.2	5.81563
2790.86	6.0158
2793.52	4.1273
2796.18	4.18165
2798.84	4.10813
2801.49	3.52969
2804.15	2.91097
2806.81	3.26151
2809.46	3.19709
2812.12	2.77636
2814.77	5.2231
2817.42	8.56655
2820.07	9.81342
2822.72	13.917
2825.37	16.9035
2828.02	20.4694
2830.67	25.3502
2833.31	29.0047
2835.96	34.1686
2838.61	39.6445
2841.25	46.1046
2843.89	52.6615
2846.53	60.5472
2849.17	68.0288
2851.81	75.1308
2854.45	83.7536
2857.09	91.2988
2859.73	99.2146
2862.36	104.408
2865	110.471
2867.64	115.705
2870.27	121.655
2872.9	127.178
2875.53	133.322
2878.16	139.659
2880.79	145.357
2883.42	149.326
2886.05	153.655
2888.68	157.525
2891.3	160.884
2893.93	164.561
2896.55	168.874
2899.18	172.816
2901.8	177.486
2904.42	185.864
2907.04	193.222
2909.66	200.353
2912.28	208.851
2914.9	216.75
2917.51	223.938
2920.13	231.4
2922.74	235.843
2925.36	238.551
2927.97	242.61
2930.59	244.523
2933.2	243.321
2935.81	241.085
2938.42	237.347
2941.02	230.117
2943.63	222.218
2946.24	212.698
2948.85	201.949
2951.45	190.114
2954.05	180.109
2956.66	168.062
2959.26	159.009
2961.86	149.341
2964.46	141.218
2967.06	134.856
2969.66	129.51
2972.26	124.473
2974.85	119.685
2977.45	115.561
2980.05	110.238
2982.64	104.875
2985.23	100.538
2987.83	94.8256
2990.42	88.847
2993.01	82.713
2995.6	75.3603
2998.19	68.2558
3000.77	60.8719
3003.36	52.5601
3005.95	46.49
3008.53	38.0115
3011.12	31.9436
3013.7	25.2725
3016.28	19.4258
3018.86	15.0301
3021.44	10.5212
3024.02	6.23564
3026.6	4.23466
3029.18	1.87911
3031.76	0.517618
3034.33	1.97583
3036.91	0.259711
3039.48	-0.597481
3042.05	-0.910589
3044.63	-0.757746
3047.2	0.312715
3049.77	-0.484309
3052.34	0.281734
3054.91	0.251547
3057.48	2.53096
3060.04	3.07226
3062.61	3.64942
3065.17	3.55361
3067.74	3.74727
3070.3	4.20897
3072.87	4.76434
3075.43	5.95153
3077.99	6.16869
3080.55	5.8783
3083.11	6.326
3085.67	4.91986
3088.22	5.18671
3090.78	6.33499
3093.34	6.1497
3095.89	6.243
3098.44	4.84134
3101	4.03032
3103.55	4.57266
3106.1	5.36979
3108.65	4.93949
3111.2	5.54838
3113.75	6.1045
3116.3	6.60223
3118.84	7.0586
3121.39	8.24155
3123.93	7.86793
3126.48	7.13103
3129.02	7.10676
3131.56	7.34086
3134.1	6.78512
3136.64	7.64261
3139.18	8.12005
3141.72	7.45054
3144.26	7.02197
3146.8	5.726
3149.33	3.79058