File: data/Raman/poly_smoothed/Mbcal_20_25_24_1x_45s_532 nm_x100_100%_600 gr_mm_01.txt
#Acq. time (s)=	45
#Accumulations=	2
#Range (cm-¹)=	200...3150
#Windows=	2
#Auto scanning=	Off
#Autofocus=	Off
#Macrospot=	Off
#AutoExposure=	Off
#Spike filter=	Multiple accum.
#Delay time (s)=	0
#Binning=	1
#Readout mode=	Signal
#DeNoise=	Off
#ICS correction=	On
#Dark correction=	Off
#Inst. Process=	Off
#Detector Gain=	Best Dynamic Range
#Detector ADC=	20 kHz
#Detector temperature (°C)=	-69.85
#Instrument=	LabRAM HR Evol
#Detector=	Synapse
#Objective=	x100
#Grating=	600 gr/mm
#ND Filter=	100%
#Laser (nm)=	532
#Hole=	100.021
#Range=	Auto
#Laser Pol.=	No
#Raman. Pol.=	No
#Laser Pol. (°)=	-0.0007625
#Raman Pol. (°)=	89.9995
#Collection=	Microscope
#StageXY=	Marzhauser
#StageZ=	Marzhauser
#X (µm)=	-1173.3
#Y (µm)=	1305.7
#Z (µm)=	578
#Full time(mm:ss)=	3:18
#Project=
#Sample=
#Site=
#Title=	Mbcal_20_25_24_2x_45s_532 nm_x100_100%_600 gr_mm
#Remark=
#Date=	18.07.2022 11:24
#Acquired=	18.07.2022 11:24:15
#Base:Fit=	10.08.2022 10:55:08
#Base:Sub=	10.08.2022 10:55:14
#Filter:Polynom=	16.08.2022 10:07:28
#AxisType[0]=Intens
#AxisUnit[0]=Cnt
#AxisType[1]=Spectr
#AxisUnit[1]=1/cm
200.419	40.1926
204.048	33.6384
207.678	27.53
211.304	22.4693
214.928	17.0247
218.554	15.3772
222.176	12.12
225.798	13.5699
229.417	11.8415
233.035	12.8043
236.653	13.6578
240.268	15.0751
243.881	16.0438
247.493	16.6601
251.103	17.3166
254.715	18.6239
258.322	20.0201
261.929	20.9253
265.534	21.2105
269.137	19.8929
272.739	19.4283
276.34	16.6347
279.939	12.5889
283.537	10.7242
287.134	6.21496
290.729	4.0646
294.323	3.56303
297.913	4.66438
301.504	4.66881
305.093	6.87538
308.682	10.0847
312.268	15.2648
315.852	17.7908
319.436	21.4756
323.018	24.0482
326.597	27.3394
330.177	30.0999
333.753	31.8746
337.331	32.4826
340.906	33.5547
344.478	33.5175
348.051	32.2752
351.621	31.0867
355.189	29.1991
358.757	27.1247
362.323	23.8818
365.889	21.3557
369.451	20.3698
373.012	18.3429
376.574	17.0521
380.133	19.7268
383.69	21.5336
387.245	22.6151
390.8	23.5795
394.353	23.1333
397.906	25.1814
401.456	24.7908
405.005	25.7523
408.552	26.765
412.099	25.7505
415.643	26.7163
419.187	26.0113
422.728	24.9249
426.269	23.5066
429.806	23.1225
433.344	21.6021
436.881	18.8015
440.416	17.0658
443.949	16.6253
447.48	16.086
451.011	15.4496
454.541	17.0454
458.069	16.3331
461.594	15.4702
465.119	16.3863
468.642	18.8782
472.165	19.2135
475.684	20.6652
479.204	21.627
482.721	23.754
486.239	26.5474
489.753	30.3283
493.268	34.6795
496.779	35.8733
500.289	38.6325
503.8	41.254
507.307	44.1212
510.813	46.7766
514.32	49.6088
517.823	53.7651
521.325	54.7147
524.826	57.4205
528.325	59.595
531.823	61.8044
535.32	63.466
538.815	64.0607
542.309	63.6851
545.802	62.9904
549.293	60.2172
552.783	58.4148
556.271	54.5536
559.759	51.0606
563.245	48.0871
566.729	44.4393
570.213	39.2059
573.693	33.0756
577.173	26.1039
580.652	19.496
584.13	17.313
587.605	16.1319
591.08	14.1833
594.552	12.4174
598.025	11.8947
601.496	12.8516
604.964	15.4683
608.433	15.6502
611.898	18.3027
615.364	19.5496
618.827	22.8135
622.288	24.6689
625.75	27.1449
629.209	28.5299
632.667	30.9429
636.125	32.5176
639.58	35.0743
643.033	35.5099
646.485	34.1549
649.936	34.226
653.388	33.6196
656.836	29.2439
660.283	26.3916
663.728	24.3093
667.173	23.373
670.616	23.075
674.057	23.6467
677.498	22.3244
680.937	23.8869
684.375	25.9689
687.809	28.2626
691.244	29.0103
694.678	30.6108
698.111	31.1418
701.54	29.6089
704.97	30.441
708.398	31.2207
711.826	30.8768
715.25	30.8956
718.675	30.2278
722.096	29.6097
725.518	30.4339
728.937	32.5165
732.357	33.403
735.773	35.104
739.19	33.9649
742.604	34.7818
746.018	34.7524
749.429	37.9413
752.839	40.0988
756.248	43.866
759.657	49.3771
763.063	53.7218
766.468	59.038
769.871	64.6678
773.273	67.8476
776.676	70.9433
780.075	71.7076
783.474	71.9713
786.871	72.8055
790.266	73.1936
793.661	73.2794
797.054	73.2156
800.446	73.7634
803.834	74.1067
807.224	76.369
810.612	75.8171
813.998	75.4869
817.384	72.8997
820.766	72.4092
824.149	73.3977
827.531	78.4379
830.909	85.1886
834.288	92.6668
837.666	99.672
841.041	106.905
844.416	112.912
847.788	118.97
851.161	121.709
854.53	123.54
857.901	123.926
861.268	123.012
864.633	122.733
868	120.479
871.363	114.88
874.725	108.988
878.088	102.466
881.447	94.7101
884.805	85.6854
888.162	76.4787
891.518	68.5471
894.872	59.823
898.225	53.8872
901.577	51.4298
904.928	49.894
908.277	51.852
911.625	55.5993
914.972	57.8619
918.318	61.0624
921.662	62.0234
925.005	64.5083
928.347	65.669
931.686	65.3964
935.025	62.6284
938.363	62.3897
941.698	62.7743
945.034	59.2699
948.368	56.7514
951.699	53.1039
955.031	52.6421
958.36	47.9689
961.689	43.9618
965.016	42.6805
968.343	44.4828
971.666	47.0977
974.991	49.8367
978.312	52.3878
981.632	55.7248
984.953	56.6594
988.27	59.1891
991.587	59.4696
994.902	62.074
998.216	63.4218
1001.53	64.2241
1004.84	63.626
1008.15	64.74
1011.46	66.6271
1014.77	66.9881
1018.07	70.4545
1021.38	72.3062
1024.68	72.6422
1027.99	72.9468
1031.29	73.9267
1034.59	72.7401
1037.89	70.9345
1041.18	65.5022
1044.48	67.2224
1047.77	68.8637
1051.07	68.421
1054.36	61.1183
1057.65	59.4236
1060.94	62.5834
1064.23	63.9831
1067.52	63.3586
1070.8	66.1075
1074.09	65.2308
1077.37	65.7156
1080.65	67.5147
1083.93	68.321
1087.21	71.6558
1090.49	76.417
1093.77	81.1939
1097.04	85.2509
1100.32	87.0738
1103.59	89.2467
1106.86	88.7089
1110.13	85.7656
1113.4	83.0901
1116.67	79.4707
1119.94	74.6936
1123.2	68.9259
1126.47	64.6916
1129.73	57.3567
1132.99	49.4014
1136.25	42.6786
1139.51	46.5083
1142.77	44.7106
1146.03	39.1795
1149.28	34.6768
1152.54	29.2957
1155.79	23.2081
1159.04	18.8221
1162.29	13.0648
1165.54	9.12456
1168.79	7.09463
1172.04	5.59937
1175.28	7.35917
1178.53	8.1502
1181.77	8.59028
1185.01	11.528
1188.25	12.8547
1191.49	17.8432
1194.73	22.3464
1197.96	27.2168
1201.2	31.7822
1204.43	38.451
1207.66	45.523
1210.9	53.3108
1214.13	62.8966
1217.36	71.017
1220.58	77.2153
1223.81	84.427
1227.04	90.8916
1230.26	96.3777
1233.48	101.742
1236.71	106.573
1239.93	113.052
1243.14	119.643
1246.36	126.156
1249.58	131.982
1252.8	135.557
1256.01	140.257
1259.22	144.747
1262.43	149.787
1265.64	152.664
1268.85	155.741
1272.06	159.141
1275.27	161.415
1278.48	163.965
1281.68	165.336
1284.88	169.715
1288.08	174.211
1291.28	177.493
1294.48	179.227
1297.68	179.777
1300.88	179.858
1304.07	183.316
1307.27	186.005
1310.46	186.287
1313.65	189.796
1316.85	192.31
1320.03	194.425
1323.22	193.443
1326.41	191.887
1329.6	191.681
1332.78	190.37
1335.96	188.806
1339.15	183.596
1342.33	181.394
1345.51	176.654
1348.69	171.851
1351.86	167.269
1355.04	161.967
1358.21	155.711
1361.39	150.621
1364.56	146.765
1367.73	143.074
1370.9	135.809
1374.07	128.374
1377.24	123.868
1380.41	119.803
1383.57	117.663
1386.73	116.379
1389.9	113.778
1393.06	112.644
1396.22	112.354
1399.38	113.733
1402.54	117.31
1405.69	123.349
1408.85	130.762
1412	138.72
1415.16	150.041
1418.31	162.744
1421.46	177.655
1424.61	194.158
1427.76	210.442
1430.9	226.042
1434.05	239.846
1437.2	252.828
1440.34	262.094
1443.48	269.774
1446.62	271.838
1449.76	270.816
1452.9	269.039
1456.04	263.398
1459.17	254.861
1462.31	245.546
1465.44	233.032
1468.58	218.199
1471.71	203.605
1474.84	188.869
1477.97	174.857
1481.1	159.078
1484.22	143.088
1487.35	128.644
1490.47	118.017
1493.59	107.95
1496.72	99.6686
1499.84	91.0627
1502.96	85.3942
1506.08	78.7746
1509.19	72.3359
1512.31	66.9974
1515.42	61.0759
1518.54	54.7959
1521.65	50.1782
1524.76	45.4479
1527.87	44.1221
1530.98	42.1493
1534.09	41.3462
1537.2	43.7259
1540.3	46.3452
1543.41	47.5188
1546.51	51.8772
1549.61	56.655
1552.71	60.9641
1555.81	63.8697
1558.91	66.9323
1562.01	70.4076
1565.1	75.3865
1568.2	81.0613
1571.29	86.31
1574.38	91.4869
1577.48	97.3431
1580.57	102.446
1583.65	106.492
1586.74	111.962
1589.83	114.568
1592.92	117.365
1596	119.131
1599.08	119.252
1602.16	120.256
1605.24	119.495
1608.32	118.162
1611.4	117.383
1614.48	117.118
1617.56	117.948
1620.63	119.167
1623.71	121.518
1626.78	124.692
1629.85	128.681
1632.92	135.265
1635.99	140.386
1639.06	148.735
1642.12	158.22
1645.19	164.805
1648.25	171.452
1651.32	177.815
1654.38	182.341
1657.44	185.574
1660.5	187.028
1663.56	184.707
1666.62	180.736
1669.67	172.643
1672.73	162.835
1675.79	152.529
1678.84	139.699
1681.89	125.535
1684.94	111.211
1687.99	97.8265
1691.04	84.9774
1694.08	72.8012
1697.13	60.7186
1700.18	52.527
1703.22	43.1593
1706.26	37.0403
1709.3	30.0856
1712.35	23.5943
1715.39	19.9628
1718.42	16.247
1721.46	12.1642
1724.5	10.6841
1727.53	9.01432
1730.56	7.21411
1733.6	6.44883
1736.63	5.43783
1739.66	3.07798
1742.69	2.66262
1745.71	2.24209
1748.74	2.15348
1751.77	2.55219
1754.79	3.09823
1757.81	3.24886
1760.84	3.56436
1763.86	3.20122
1766.88	3.29951
1769.9	2.71089
1772.91	3.16972
1775.93	2.23154
1778.95	1.53556
1781.96	1.21138
1784.97	0.937671
1787.99	1.53161
1791	2.36145
1794.01	1.77294
1797.01	1.46704
1800.02	1.33493
1803.03	1.24183
1806.03	1.28673
1809.04	1.28311
1812.04	2.20468
1815.04	2.84625
1818.04	4.27782
1821.04	5.22747
1824.04	5.19694
1827.04	6.26202
1830.03	6.27489
1833.03	6.26536
1836.02	6.31468
1839.02	6.01397
1842.01	5.92501
1845	6.27986
1847.99	6.53786
1850.98	6.5479
1853.96	5.72849
1856.95	5.05799
1859.94	3.75534
1862.92	2.8633
1865.9	2.25475
1868.88	2.60947
1871.86	2.56785
1874.84	2.75957
1877.82	2.62653
1880.8	3.30764
1882.58	3.83079
1885.57	4.07327
1888.56	3.19119
1891.54	3.16975
1894.53	3.13083
1897.51	4.22326
1900.5	5.4356
1903.48	6.54684
1906.46	7.1843
1909.44	7.7709
1912.42	8.52183
1915.4	8.98056
1918.37	10.495
1921.35	10.4089
1924.32	10.2306
1927.3	10.592
1930.27	10.0725
1933.24	10.8247
1936.21	11.829
1939.18	10.8259
1942.15	10.3613
1945.11	10.1449
1948.08	9.63677
1951.04	8.7365
1954.01	7.53842
1956.97	5.95094
1959.93	4.95491
1962.89	5.60235
1965.85	5.44943
1968.81	4.47587
1971.77	3.65764
1974.72	3.58009
1977.68	3.82741
1980.63	3.47331
1983.58	2.13602
1986.53	3.05063
1989.48	4.86924
1992.43	5.47113
1995.38	5.99147
1998.33	7.45388
2001.27	8.71413
2004.22	9.20972
2007.16	9.47981
2010.11	8.71163
2013.05	8.12981
2015.99	8.86765
2018.93	8.81399
2021.87	9.30788
2024.8	10.2126
2027.74	10.9504
2030.68	12.8453
2033.61	13.1355
2036.54	13.5791
2039.48	12.3034
2042.41	10.7848
2045.34	10.964
2048.27	10.8879
2051.19	11.4749
2054.12	10.6894
2057.05	10.6467
2059.97	12.4807
2062.9	12.485
2065.82	13.0783
2068.74	13.8739
2071.66	15.0692
2074.58	14.6479
2077.5	16.1285
2080.41	15.8028
2083.33	15.9403
2086.24	15.6543
2089.16	17.3121
2092.07	18.4726
2094.98	20.7881
2097.89	22.024
2100.8	23.8415
2103.71	25.0464
2106.62	25.5728
2109.53	26.3747
2112.43	28.4063
2115.33	30.7975
2118.24	33.4878
2121.14	36.7331
2124.04	39.0601
2126.94	43.1783
2129.84	48.929
2132.74	54.4809
2135.63	60.163
2138.53	65.6797
2141.43	73.6848
2144.32	79.575
2147.21	86.5214
2150.1	93.48
2152.99	99.0897
2155.88	104.899
2158.77	110.201
2161.66	116.123
2164.55	122.19
2167.43	126.601
2170.31	129.998
2173.2	131.558
2176.08	132.385
2178.96	132.185
2181.84	131.865
2184.72	129.454
2187.6	125.614
2190.47	123.222
2193.35	118.631
2196.23	112.928
2199.1	106.916
2201.97	100.921
2204.84	94.95
2207.71	88.7024
2210.58	82.9473
2213.45	78.6889
2216.32	73.3438
2219.19	68.1936
2222.05	63.4465
2224.92	58.4263
2227.78	53.5334
2230.64	49.2471
2233.5	46.3656
2236.36	43.2231
2239.22	39.3176
2242.08	36.9079
2244.94	33.8784
2247.79	31.7346
2250.65	29.014
2253.5	26.1264
2256.36	23.719
2259.21	20.9432
2262.06	19.6729
2264.91	17.5288
2267.76	16.2179
2270.6	15.6206
2273.45	15.128
2276.3	14.8049
2279.14	14.0157
2281.98	13.4969
2284.83	12.5348
2287.67	10.8059
2290.51	9.96373
2293.35	7.96401
2296.19	7.56837
2299.02	6.9926
2301.86	7.19775
2304.7	7.84611
2307.53	7.90829
2310.36	8.43594
2313.2	7.63693
2316.03	7.53135
2318.86	6.48648
2321.69	5.4929
2324.51	5.06657
2327.34	4.24671
2330.17	4.62969
2332.99	5.26212
2335.82	5.54823
2338.64	4.75564
2341.46	4.73391
2344.28	4.51567
2347.1	3.41246
2349.92	1.81523
2352.74	1.39869
2355.56	0.144704
2358.37	-0.228826
2361.19	-0.522078
2364	-0.884429
2366.82	0.08296
2369.63	0.708578
2372.44	1.04154
2375.25	1.81102
2378.06	1.79329
2380.86	1.73146
2383.67	1.87297
2386.48	1.56387
2389.28	2.18676
2392.09	2.54782
2394.89	2.39762
2397.69	2.24159
2400.49	2.81397
2403.29	2.77235
2406.09	2.29351
2408.89	1.5969
2411.69	1.21067
2414.48	1.16912
2417.28	0.819904
2420.07	1.00891
2422.86	1.20269
2425.65	0.636145
2428.45	1.96553
2431.23	1.20078
2434.02	0.115756
2436.81	-0.0881272
2439.6	0.098008
2442.38	1.15459
2445.17	2.37224
2447.95	2.69478
2450.73	3.38675
2453.52	3.78544
2456.3	4.61508
2459.08	5.29672
2461.85	5.68576
2464.63	6.92406
2467.41	7.04699
2470.19	7.97256
2472.96	6.3515
2475.73	6.01724
2478.51	5.55316
2481.28	6.33024
2484.05	6.8412
2486.82	6.7321
2489.59	6.03231
2492.35	5.36085
2495.12	4.99371
2497.89	4.60385
2500.65	2.25808
2503.42	1.0459
2506.18	0.826849
2508.94	1.3713
2511.7	0.729785
2514.46	0.645186
2517.22	0.88028
2519.98	0.51915
2522.73	1.54574
2525.49	3.4214
2528.25	4.53693
2531	5.57743
2533.75	6.04042
2536.5	5.73617
2539.25	6.00079
2542.01	6.2736
2544.75	6.56379
2547.5	7.00221
2550.25	6.13707
2553	5.77287
2555.74	5.58811
2558.49	5.67297
2561.23	5.83125
2563.97	6.34972
2566.71	5.53644
2569.45	4.6797
2572.19	5.34586
2574.93	4.90306
2577.67	4.6294
2580.4	4.28911
2583.14	5.38324
2585.87	6.4825
2588.6	7.63028
2591.34	8.39118
2594.07	9.84607
2596.8	10.8194
2599.53	11.4127
2602.26	12.6853
2604.98	13.5351
2607.71	11.928
2610.44	12.0829
2613.16	10.9792
2615.88	9.8642
2618.61	8.90496
2621.33	9.33303
2624.05	8.76314
2626.77	8.65289
2629.49	8.35311
2632.21	7.33441
2634.92	5.864
2637.64	5.14138
2640.35	4.29394
2643.07	4.03049
2645.78	3.93797
2648.49	5.15082
2651.2	5.01447
2653.91	4.56101
2656.62	5.19484
2659.33	5.00202
2662.04	5.59789
2664.74	5.90538
2667.45	6.23604
2670.15	5.94966
2672.86	5.8367
2675.56	6.23394
2678.26	6.67798
2680.96	6.38265
2683.66	7.73274
2686.36	8.58223
2689.06	9.33171
2691.75	9.93531
2694.45	11.8501
2697.14	11.8743
2699.84	12.9017
2702.53	13.6685
2705.22	16.0834
2707.91	18.1596
2710.6	19.0625
2713.29	20.5347
2715.98	21.7778
2718.67	22.3986
2721.35	23.1273
2724.04	22.6737
2726.72	21.7494
2729.4	21.9057
2732.09	21.7547
2734.77	21.6316
2737.45	21.2838
2740.13	20.5263
2742.81	18.9853
2745.48	17.9163
2748.16	17.8883
2750.84	16.5599
2753.51	14.1919
2756.19	12.6444
2758.86	12.0623
2761.53	10.758
2764.2	9.32984
2766.87	7.9593
2769.54	6.69104
2772.21	5.41579
2774.88	3.99128
2777.54	2.9432
2780.21	1.98268
2782.87	2.0695
2785.53	1.70531
2788.2	1.52396
2790.86	1.44395
2793.52	2.045
2796.18	2.47154
2798.84	1.811
2801.49	1.81225
2804.15	1.88676
2806.81	1.36207
2809.46	1.82345
2812.12	3.12357
2814.77	5.05901
2817.42	7.20588
2820.07	11.9378
2822.72	19.4509
2825.37	26.0437
2828.02	35.4652
2830.67	44.1437
2833.31	53.0215
2835.96	64.2164
2838.61	76.5052
2841.25	88.0485
2843.89	103.165
2846.53	120.171
2849.17	137.893
2851.81	157.926
2854.45	178.549
2857.09	198.934
2859.73	219.888
2862.36	238.816
2865	258.453
2867.64	274.995
2870.27	289.748
2872.9	304.323
2875.53	318.501
2878.16	332.324
2880.79	345.139
2883.42	358.697
2886.05	371.767
2888.68	385.101
2891.3	398.852
2893.93	411.15
2896.55	425.655
2899.18	441.445
2901.8	458.511
2904.42	478.675
2907.04	502.336
2909.66	530.069
2912.28	558.297
2914.9	587.424
2917.51	615.743
2920.13	641.531
2922.74	662.34
2925.36	678.293
2927.97	689.396
2930.59	693.865
2933.2	693.482
2935.81	689.06
2938.42	678.833
2941.02	662.705
2943.63	641.465
2946.24	618.083
2948.85	590.181
2951.45	563.603
2954.05	535.014
2956.66	505.773
2959.26	476.241
2961.86	449.22
2964.46	423.26
2967.06	400.922
2969.66	381.696
2972.26	363.096
2974.85	346.451
2977.45	329.78
2980.05	314.276
2982.64	298.087
2985.23	279.117
2987.83	261.189
2990.42	243.162
2993.01	222.673
2995.6	202.568
2998.19	182.663
3000.77	162.276
3003.36	141.33
3005.95	121.696
3008.53	104.553
3011.12	88.1268
3013.7	74.3331
3016.28	61.4156
3018.86	49.2411
3021.44	39.2632
3024.02	30.9781
3026.6	25.4318
3029.18	21.4962
3031.76	18.7477
3034.33	15.8048
3036.91	15.3706
3039.48	15.7124
3042.05	17.8401
3044.63	19.8017
3047.2	20.669
3049.77	22.4173
3052.34	23.0004
3054.91	22.2502
3057.48	22.7262
3060.04	22.7311
3062.61	22.8213
3065.17	21.6219
3067.74	20.5522
3070.3	19.7691
3072.87	19.0354
3075.43	15.8253
3077.99	13.0302
3080.55	10.889
3083.11	8.11648
3085.67	6.68373
3088.22	4.26775
3090.78	3.47722
3093.34	2.16533
3095.89	2.15619
3098.44	1.99882
3101	2.61067
3103.55	4.20465
3106.1	5.89038
3108.65	6.05017
3111.2	7.96196
3113.75	9.66136
3116.3	11.322
3118.84	13.067
3121.39	15.3169
3123.93	17.3526
3126.48	19.2162
3129.02	20.5383
3131.56	23.3909
3134.1	25.2763
3136.64	26.6173
3139.18	28.3212
3141.72	31.1092
3144.26	33.8472
3146.8	37.5013
3149.33	41.1