File: data/Raman/poly_smoothed/Mbcal_20_25_09_1x_45s_532 nm_x100_100%_600 gr_mm_01.txt
#Acq. time (s)=	45
#Accumulations=	2
#Range (cm-¹)=	200...3150
#Windows=	2
#Auto scanning=	Off
#Autofocus=	Off
#Macrospot=	Off
#AutoExposure=	Off
#Spike filter=	Multiple accum.
#Delay time (s)=	0
#Binning=	1
#Readout mode=	Signal
#DeNoise=	Off
#ICS correction=	On
#Dark correction=	Off
#Inst. Process=	Off
#Detector Gain=	Best Dynamic Range
#Detector ADC=	20 kHz
#Detector temperature (°C)=	-69.85
#Instrument=	LabRAM HR Evol
#Detector=	Synapse
#Objective=	x100
#Grating=	600 gr/mm
#ND Filter=	100%
#Laser (nm)=	532
#Hole=	100.021
#Range=	Auto
#Laser Pol.=	No
#Raman. Pol.=	No
#Laser Pol. (°)=	-0.0007625
#Raman Pol. (°)=	89.9995
#Collection=	Microscope
#StageXY=	Marzhauser
#StageZ=	Marzhauser
#X (µm)=	-1205.8
#Y (µm)=	1248.4
#Z (µm)=	578.3
#Full time(mm:ss)=	3:18
#Project=
#Sample=
#Site=
#Title=	Mbcal_20_25_09_2x_45s_532 nm_x100_100%_600 gr_mm
#Remark=
#Date=	18.07.2022 10:05
#Acquired=	18.07.2022 10:05:01
#Edit:Spike=	18.07.2022 10:07:34
#Base:Fit=	10.08.2022 10:55:08
#Base:Sub=	10.08.2022 10:55:14
#Filter:Polynom=	16.08.2022 10:07:28
#AxisType[0]=Intens
#AxisUnit[0]=Cnt
#AxisType[1]=Spectr
#AxisUnit[1]=1/cm
200.419	22.4675
204.048	23.8599
207.678	21.3104
211.304	17.5572
214.928	14.9119
218.554	13.5324
222.176	14.0644
225.798	12.0257
229.417	10.2309
233.035	8.94724
236.653	8.24832
240.268	6.88247
243.881	7.71409
247.493	8.14645
251.103	5.92262
254.715	6.85752
258.322	7.1677
261.929	7.60517
265.534	7.90738
269.137	7.93424
272.739	10.8314
276.34	9.85631
279.939	9.35839
283.537	8.71325
287.134	10.2366
290.729	8.023
294.323	10.5572
297.913	11.2738
301.504	12.011
305.093	14.8712
308.682	14.5819
312.268	15.2414
315.852	14.0543
319.436	15.4487
323.018	13.7212
326.597	14.101
330.177	15.5299
333.753	14.92
337.331	12.3423
340.906	12.3609
344.478	11.0856
348.051	10.4392
351.621	9.33914
355.189	6.09323
358.757	6.78115
362.323	4.77814
365.889	4.80515
369.451	5.3693
373.012	5.14965
376.574	8.88566
380.133	10.4287
383.69	12.8067
387.245	11.6532
390.8	14.0968
394.353	16.7948
397.906	15.927
401.456	18.6473
405.005	19.7143
408.552	17.6553
412.099	17.0421
415.643	17.0248
419.187	15.353
422.728	13.2293
426.269	13.1318
429.806	12.6634
433.344	11.4094
436.881	9.95076
440.416	7.69501
443.949	7.64463
447.48	6.97469
451.011	6.23789
454.541	6.26823
458.069	6.1821
461.594	6.59176
465.119	7.47605
468.642	7.32684
472.165	8.03805
475.684	10.7657
479.204	11.8337
482.721	10.5626
486.239	13.3466
489.753	13.303
493.268	13.2339
496.779	12.8734
500.289	14.9987
503.8	16.5687
507.307	15.8111
510.813	18.8721
514.32	21.4482
517.823	23.0189
521.325	23.4977
524.826	24.5631
528.325	24.5809
531.823	26.5366
535.32	27.5122
538.815	28.8267
542.309	27.7491
545.802	27.4091
549.293	26.972
552.783	27.4615
556.271	26.9943
559.759	25.7063
563.245	24.105
566.729	21.7172
570.213	21.8494
573.693	22.0443
577.173	20.6938
580.652	20.7859
584.13	20.7818
587.605	18.1161
591.08	17.2857
594.552	15.8801
598.025	17.229
601.496	18.2706
604.964	16.2539
608.433	16.9225
611.898	15.9504
615.364	15.0946
618.827	13.4971
622.288	13.068
625.75	10.9101
629.209	8.77983
632.667	8.52985
636.125	8.22838
639.58	4.73995
643.033	3.91953
646.485	4.88853
649.936	3.26161
653.388	6.57249
656.836	7.33598
660.283	8.09591
663.728	8.78852
667.173	10.9071
670.616	10.8091
674.057	13.9302
677.498	15.3924
680.937	19.0317
684.375	22.6378
687.809	23.3999
691.244	25.3984
694.678	27.0758
698.111	30.1009
701.54	32.3062
704.97	32.2699
708.398	34.0285
711.826	34.9103
715.25	34.2577
718.675	33.7587
722.096	32.0075
725.518	32.2556
728.937	33.8643
732.357	34.5205
735.773	34.4009
739.19	35.5156
742.604	36.4049
746.018	36.7374
749.429	37.5531
752.839	40.1627
756.248	41.3728
759.657	44.3617
763.063	48.7199
766.468	52.4173
769.871	55.6414
773.273	59.8945
776.676	65.5417
780.075	68.3101
783.474	70.4676
786.871	73.2696
790.266	74.4661
793.661	78.7806
797.054	80.2635
800.446	81.3106
803.834	82.2153
807.224	84.7561
810.612	86.1077
813.998	86.7344
817.384	87.2161
820.766	87.8224
824.149	88.8791
827.531	88.8963
830.909	90.0726
834.288	91.3649
837.666	95.7845
841.041	97.4111
844.416	98.1971
847.788	98.4514
851.161	99.4898
854.53	100.85
857.901	98.7236
861.268	96.331
864.633	92.2289
868	90.6
871.363	88.2511
874.725	85.7838
878.088	83.2683
881.447	78.8654
884.805	74.173
888.162	69.7403
891.518	64.8212
894.872	59.9323
898.225	55.3239
901.577	51.9051
904.928	52.4461
908.277	50.0225
911.625	49.8748
914.972	48.3365
918.318	48.0291
921.662	46.8121
925.005	45.9332
928.347	45.9979
931.686	45.4188
935.025	44.4748
938.363	42.3671
941.698	41.6304
945.034	38.5585
948.368	35.7492
951.699	31.7658
955.031	30.2296
958.36	26.981
961.689	22.3001
965.016	22.0753
968.343	22.8617
971.666	19.0675
974.991	18.1933
978.312	17.1074
981.632	19.0861
984.953	18.4522
988.27	16.3073
991.587	14.2045
994.902	15.3401
998.216	14.6922
1001.53	15.8479
1004.84	17.0924
1008.15	19.2328
1011.46	19.6936
1014.77	21.0124
1018.07	21.8375
1021.38	21.3409
1024.68	23.2283
1027.99	22.9712
1031.29	23.8432
1034.59	24.7478
1037.89	25.8446
1041.18	26.1469
1044.48	28.9641
1047.77	28.4543
1051.07	28.3026
1054.36	25.832
1057.65	27.1813
1060.94	26.2601
1064.23	24.2799
1067.52	22.952
1070.8	21.4711
1074.09	20.9713
1077.37	18.3704
1080.65	17.0088
1083.93	15.5492
1087.21	15.6936
1090.49	13.8899
1093.77	14.5571
1097.04	13.1285
1100.32	12.9951
1103.59	13.4274
1106.86	16.1806
1110.13	17.1568
1113.4	17.3828
1116.67	15.9419
1119.94	15.3381
1123.2	15.8986
1126.47	16.1665
1129.73	15.8946
1132.99	15.4635
1136.25	15.6581
1139.51	16.6939
1142.77	14.6578
1146.03	15.4587
1149.28	16.0201
1152.54	12.3609
1155.79	8.96421
1159.04	6.27079
1162.29	5.9786
1165.54	5.87064
1168.79	5.89062
1172.04	6.53871
1175.28	5.35916
1178.53	7.32014
1181.77	8.57679
1185.01	10.705
1188.25	12.6555
1191.49	13.618
1194.73	13.602
1197.96	15.6361
1201.2	18.8918
1204.43	21.1481
1207.66	23.2034
1210.9	25.3256
1214.13	27.303
1217.36	31.5391
1220.58	34.7597
1223.81	35.6253
1227.04	36.0556
1230.26	36.8917
1233.48	37.3293
1236.71	37.5376
1239.93	40.7613
1243.14	42.0137
1246.36	45.0007
1249.58	46.982
1252.8	48.3312
1256.01	49.5761
1259.22	52.0567
1262.43	52.4831
1265.64	51.5476
1268.85	52.5043
1272.06	53.3066
1275.27	55.891
1278.48	59.4161
1281.68	61.6201
1284.88	65.8838
1288.08	68.8323
1291.28	70.1882
1294.48	73.3963
1297.68	77.2642
1300.88	78.7896
1304.07	81.4599
1307.27	81.7501
1310.46	84.3209
1313.65	86.1131
1316.85	86.4188
1320.03	87.7169
1323.22	89.295
1326.41	92.6785
1329.6	92.4606
1332.78	91.2993
1335.96	90.1448
1339.15	89.228
1342.33	87.3788
1345.51	86.3797
1348.69	87.2854
1351.86	88.0067
1355.04	88.287
1358.21	86.263
1361.39	84.8989
1364.56	83.9897
1367.73	81.3157
1370.9	81.1143
1374.07	80.6763
1377.24	79.7359
1380.41	77.2812
1383.57	75.7536
1386.73	73.6863
1389.9	71.7437
1393.06	70.3599
1396.22	68.0127
1399.38	69.5431
1402.54	69.1104
1405.69	69.9641
1408.85	70.8693
1412	74.1209
1415.16	78.7944
1418.31	83.3022
1421.46	88.7613
1424.61	96.5635
1427.76	104.505
1430.9	110.715
1434.05	116.854
1437.2	121.497
1440.34	126.82
1443.48	131.72
1446.62	136.609
1449.76	137.411
1452.9	137.218
1456.04	136.022
1459.17	136.657
1462.31	136.262
1465.44	135.641
1468.58	135.795
1471.71	133.89
1474.84	131.143
1477.97	127.488
1481.1	123.773
1484.22	118.437
1487.35	114.142
1490.47	109.115
1493.59	102.253
1496.72	97.6502
1499.84	93.3786
1502.96	89.1759
1506.08	82.2332
1509.19	75.9354
1512.31	69.7243
1515.42	63.7814
1518.54	57.3365
1521.65	49.2997
1524.76	43.595
1527.87	35.5057
1530.98	33.4236
1534.09	33.3566
1537.2	34.5201
1540.3	36.5102
1543.41	39.3776
1546.51	39.2443
1549.61	41.7397
1552.71	45.1314
1555.81	44.938
1558.91	45.5251
1562.01	47.4197
1565.1	50.5607
1568.2	53.1479
1571.29	57.845
1574.38	62.3718
1577.48	63.6275
1580.57	67.3061
1583.65	68.6907
1586.74	68.9005
1589.83	70.9392
1592.92	71.8869
1596	70.0468
1599.08	71.6639
1602.16	71.8522
1605.24	72.0428
1608.32	70.6192
1611.4	71.1029
1614.48	70.6703
1617.56	70.8236
1620.63	70.8884
1623.71	69.6717
1626.78	70.1763
1629.85	70.2911
1632.92	71.5747
1635.99	72.8658
1639.06	73.7187
1642.12	75.1638
1645.19	76.6193
1648.25	76.9832
1651.32	77.0117
1654.38	77.8475
1657.44	78.7955
1660.5	76.2336
1663.56	75.4165
1666.62	74.7433
1669.67	71.3096
1672.73	69.0063
1675.79	65.578
1678.84	59.4081
1681.89	52.7372
1684.94	46.7667
1687.99	42.127
1691.04	37.6377
1694.08	32.7309
1697.13	28.4671
1700.18	26.4686
1703.22	23.424
1706.26	19.9
1709.3	17.7803
1712.35	16.5423
1715.39	14.4245
1718.42	15.681
1721.46	15.5251
1724.5	14.6871
1727.53	14.1773
1730.56	15.5476
1733.6	13.7764
1736.63	14.3658
1739.66	14.3704
1742.69	13.7909
1745.71	12.3182
1748.74	11.1002
1751.77	10.5703
1754.79	9.38785
1757.81	8.82995
1760.84	7.91354
1763.86	7.44707
1766.88	6.92608
1769.9	7.14909
1772.91	6.98911
1775.93	6.20773
1778.95	6.63931
1781.96	6.85399
1784.97	7.26842
1787.99	9.58776
1791	8.78926
1794.01	9.75134
1797.01	7.39495
1800.02	6.59871
1803.03	6.82415
1806.03	6.30198
1809.04	7.09522
1812.04	7.67752
1815.04	7.76674
1818.04	9.0751
1821.04	9.16347
1824.04	9.83178
1827.04	10.7581
1830.03	10.6784
1833.03	10.0352
1836.02	10.9383
1839.02	11.5835
1842.01	12.1827
1845	13.2924
1847.99	12.583
1850.98	12.8176
1853.96	12.4488
1856.95	10.7377
1859.94	10.968
1862.92	9.83744
1865.9	8.07149
1868.88	7.74156
1871.86	7.09448
1874.84	6.29235
1877.82	6.92606
1880.8	7.39213
1882.58	8.35204
1885.57	10.6666
1888.56	11.0824
1891.54	11.3042
1894.53	11.0803
1897.51	11.6985
1900.5	12.0516
1903.48	11.2085
1906.46	12.084
1909.44	11.8685
1912.42	11.7139
1915.4	10.668
1918.37	9.65139
1921.35	7.57808
1924.32	5.68057
1927.3	4.22219
1930.27	1.73852
1933.24	1.96062
1936.21	0.322408
1939.18	0.682523
1942.15	0.659528
1945.11	-0.630722
1948.08	-0.0121218
1951.04	1.53295
1954.01	3.14763
1956.97	3.95433
1959.93	4.54471
1962.89	4.32337
1965.85	6.06815
1968.81	7.71303
1971.77	7.77141
1974.72	8.23704
1977.68	8.76083
1980.63	8.12304
1983.58	8.18506
1986.53	8.07978
1989.48	8.88612
1992.43	8.71741
1995.38	7.59118
1998.33	8.03934
2001.27	7.88919
2004.22	8.07619
2007.16	7.51807
2010.11	6.24746
2013.05	5.57614
2015.99	5.14514
2018.93	6.02813
2021.87	5.33464
2024.8	4.02884
2027.74	2.8601
2030.68	3.47768
2033.61	4.19465
2036.54	5.42885
2039.48	4.99526
2042.41	5.57581
2045.34	5.63048
2048.27	4.82865
2051.19	5.78908
2054.12	8.10649
2057.05	8.45775
2059.97	10.1514
2062.9	9.28601
2065.82	10.1721
2068.74	9.99317
2071.66	12.3302
2074.58	13.5865
2077.5	13.455
2080.41	13.7165
2083.33	13.6868
2086.24	13.8673
2089.16	13.4827
2092.07	14.7382
2094.98	15.103
2097.89	14.932
2100.8	16.2438
2103.71	17.8549
2106.62	17.9685
2109.53	18.003
2112.43	18.9771
2115.33	19.5834
2118.24	20.2089
2121.14	21.9904
2124.04	25.4465
2126.94	23.872
2129.84	25.8126
2132.74	26.8941
2135.63	28.6761
2138.53	30.3815
2141.43	33.4894
2144.32	36.6694
2147.21	38.9716
2150.1	40.5972
2152.99	43.4316
2155.88	44.299
2158.77	47.4253
2161.66	49.1408
2164.55	50.3497
2167.43	49.7776
2170.31	49.4706
2173.2	48.8305
2176.08	46.4341
2178.96	45.4398
2181.84	45.6202
2184.72	44.2172
2187.6	42.3056
2190.47	40.6597
2193.35	38.0005
2196.23	36.1262
2199.1	32.9092
2201.97	31.5648
2204.84	30.4419
2207.71	28.1605
2210.58	26.464
2213.45	26.9707
2216.32	25.8969
2219.19	24.7055
2222.05	24.4377
2224.92	22.6223
2227.78	21.3932
2230.64	19.8343
2233.5	18.3661
2236.36	17.5796
2239.22	17.0542
2242.08	16.4903
2244.94	14.9042
2247.79	11.7908
2250.65	12.1067
2253.5	11.1869
2256.36	9.81145
2259.21	10.8317
2262.06	10.2857
2264.91	10.9043
2267.76	11.2554
2270.6	11.6195
2273.45	12.6388
2276.3	12.9084
2279.14	14.4743
2281.98	14.4837
2284.83	15.7658
2287.67	14.9318
2290.51	14.9821
2293.35	13.3763
2296.19	12.9853
2299.02	13.2116
2301.86	12.6145
2304.7	14.3909
2307.53	13.5554
2310.36	13.3849
2313.2	12.7173
2316.03	9.83566
2318.86	9.97232
2321.69	11.0474
2324.51	10.6156
2327.34	9.66472
2330.17	9.62226
2332.99	9.08879
2335.82	9.70963
2338.64	9.91433
2341.46	9.84046
2344.28	8.86623
2347.1	8.87505
2349.92	7.09672
2352.74	6.21983
2355.56	5.72882
2358.37	4.50574
2361.19	3.63201
2364	3.40837
2366.82	3.59345
2369.63	3.40966
2372.44	4.00849
2375.25	3.15208
2378.06	2.93925
2380.86	3.42543
2383.67	1.818
2386.48	1.8422
2389.28	1.89772
2392.09	1.59725
2394.89	1.19013
2397.69	2.22535
2400.49	3.25873
2403.29	4.30709
2406.09	4.64042
2408.89	4.61967
2411.69	5.51492
2414.48	6.19351
2417.28	7.08049
2420.07	7.00348
2422.86	8.63451
2425.65	8.15613
2428.45	8.90484
2431.23	8.4989
2434.02	9.57945
2436.81	8.5458
2439.6	7.04467
2442.38	6.78906
2445.17	7.05531
2447.95	7.30675
2450.73	8.16994
2453.52	7.57983
2456.3	7.89393
2459.08	7.95515
2461.85	7.31675
2464.63	6.3478
2467.41	6.96975
2470.19	6.33156
2472.96	7.11905
2475.73	8.5343
2478.51	8.03521
2481.28	9.00079
2484.05	8.59313
2486.82	7.94656
2489.59	6.74787
2492.35	6.52293
2495.12	4.4643
2497.89	4.93313
2500.65	3.74114
2503.42	3.18953
2506.18	0.778452
2508.94	1.45907
2511.7	2.00847
2514.46	2.00548
2517.22	2.91395
2519.98	2.69297
2522.73	3.41537
2525.49	3.65329
2528.25	4.266
2531	5.16299
2533.75	4.64646
2536.5	6.1453
2539.25	7.66064
2542.01	8.77546
2544.75	10.1113
2547.5	10.0074
2550.25	9.87533
2553	10.4422
2555.74	9.88333
2558.49	9.12385
2561.23	8.70927
2563.97	8.95848
2566.71	7.27017
2569.45	5.94254
2572.19	5.52404
2574.93	4.10348
2577.67	3.28274
2580.4	2.18285
2583.14	1.83927
2585.87	2.95567
2588.6	3.13939
2591.34	3.446
2594.07	2.78038
2596.8	2.12901
2599.53	2.02995
2602.26	1.99945
2604.98	4.02094
2607.71	3.70898
2610.44	4.20085
2613.16	5.06164
2615.88	4.84716
2618.61	5.71661
2621.33	5.98382
2624.05	6.67495
2626.77	5.13439
2629.49	5.68251
2632.21	5.68795
2634.92	5.94225
2637.64	5.60964
2640.35	5.29093
2643.07	4.97467
2645.78	4.31358
2648.49	4.17559
2651.2	4.92184
2653.91	6.60535
2656.62	6.51032
2659.33	6.97653
2662.04	7.87309
2664.74	8.99258
2667.45	9.58891
2670.15	9.13492
2672.86	9.79995
2675.56	9.00836
2678.26	9.28597
2680.96	8.49023
2683.66	8.36974
2686.36	7.79987
2689.06	8.08247
2691.75	7.84402
2694.45	8.65469
2697.14	9.76369
2699.84	9.66276
2702.53	9.67983
2705.22	10.0511
2707.91	9.16239
2710.6	9.80975
2713.29	11.3305
2715.98	12.5504
2718.67	15.5748
2721.35	17.3613
2724.04	18.6372
2726.72	19.7709
2729.4	19.6297
2732.09	19.3679
2734.77	19.084
2737.45	16.927
2740.13	16.4919
2742.81	15.3951
2745.48	13.5829
2748.16	12.1396
2750.84	10.8617
2753.51	9.29706
2756.19	9.30175
2758.86	7.65565
2761.53	5.65279
2764.2	3.8924
2766.87	2.79344
2769.54	0.959696
2772.21	0.960329
2774.88	-0.614623
2777.54	-0.813838
2780.21	0.0428813
2782.87	0.588231
2785.53	-0.640855
2788.2	-0.715947
2790.86	-0.727599
2793.52	-1.27778
2796.18	-1.01366
2798.84	-1.18993
2801.49	-1.04404
2804.15	-0.968442
2806.81	-0.369624
2809.46	0.275798
2812.12	-0.0913512
2814.77	0.533647
2817.42	2.19833
2820.07	4.53567
2822.72	9.36918
2825.37	14.1439
2828.02	21.6499
2830.67	28.3462
2833.31	35.5909
2835.96	43.4623
2838.61	51.5094
2841.25	60.8775
2843.89	71.4204
2846.53	82.7932
2849.17	93.351
2851.81	103.752
2854.45	114.752
2857.09	126.485
2859.73	136.218
2862.36	146.582
2865	154.528
2867.64	160.892
2870.27	166.781
2872.9	171.717
2875.53	175.371
2878.16	179.791
2880.79	183.977
2883.42	187.219
2886.05	191.678
2888.68	196.986
2891.3	202.65
2893.93	208.087
2896.55	212.328
2899.18	218.326
2901.8	226.781
2904.42	235.29
2907.04	247.68
2909.66	258.859
2912.28	272.018
2914.9	283.219
2917.51	294.633
2920.13	305.415
2922.74	312.651
2925.36	317.809
2927.97	320.748
2930.59	319.857
2933.2	317.369
2935.81	312.871
2938.42	305.491
2941.02	294.826
2943.63	283.357
2946.24	268.817
2948.85	255.136
2951.45	241.036
2954.05	227.001
2956.66	213.398
2959.26	200.404
2961.86	189.66
2964.46	179.456
2967.06	169.952
2969.66	163.049
2972.26	157.744
2974.85	151.835
2977.45	146.036
2980.05	139.933
2982.64	132.405
2985.23	123.802
2987.83	114.534
2990.42	105.589
2993.01	97.1732
2995.6	87.7747
2998.19	77.9142
3000.77	68.3084
3003.36	58.7009
3005.95	48.4691
3008.53	39.8909
3011.12	32.4441
3013.7	25.9524
3016.28	19.9147
3018.86	15.2126
3021.44	12.1319
3024.02	9.58495
3026.6	6.08937
3029.18	4.66161
3031.76	3.8917
3034.33	3.49304
3036.91	2.30462
3039.48	2.27096
3042.05	2.98242
3044.63	1.68303
3047.2	0.291768
3049.77	0.240063
3052.34	0.614527
3054.91	1.05954
3057.48	1.37065
3060.04	1.63339
3062.61	1.93252
3065.17	3.75156
3067.74	4.32704
3070.3	3.70887
3072.87	3.85597
3075.43	3.96178
3077.99	3.29537
3080.55	3.37559
3083.11	2.82234
3085.67	3.00393
3088.22	2.60012
3090.78	2.35314
3093.34	2.63776
3095.89	2.88526
3098.44	3.22638
3101	1.95754
3103.55	2.58014
3106.1	2.08835
3108.65	2.12453
3111.2	3.07465
3113.75	4.78308
3116.3	6.06365
3118.84	6.46976
3121.39	8.88114
3123.93	10.3047
3126.48	12.0115
3129.02	13.5117
3131.56	14.8001
3134.1	16.3938
3136.64	17.9663
3139.18	19.4172
3141.72	21.0565
3144.26	23.3983
3146.8	25.6874
3149.33	28.1759