File: data/Raman/poly_smoothed/Mbcal_20_25_47_1x_45s_532 nm_x100_100%_600 gr_mm_01.txt
#Acq. time (s)=	45
#Accumulations=	2
#Range (cm-¹)=	200...3150
#Windows=	2
#Auto scanning=	Off
#Autofocus=	Off
#Macrospot=	Off
#AutoExposure=	Off
#Spike filter=	Multiple accum.
#Delay time (s)=	0
#Binning=	1
#Readout mode=	Signal
#DeNoise=	Off
#ICS correction=	On
#Dark correction=	Off
#Inst. Process=	Off
#Detector Gain=	Best Dynamic Range
#Detector ADC=	20 kHz
#Detector temperature (°C)=	-69.85
#Instrument=	LabRAM HR Evol
#Detector=	Synapse
#Objective=	x100
#Grating=	600 gr/mm
#ND Filter=	100%
#Laser (nm)=	532
#Hole=	100.021
#Range=	Auto
#Laser Pol.=	No
#Raman. Pol.=	No
#Laser Pol. (°)=	-0.0007625
#Raman Pol. (°)=	89.9995
#Collection=	Microscope
#StageXY=	Marzhauser
#StageZ=	Marzhauser
#X (µm)=	-1138.8
#Y (µm)=	1238.5
#Z (µm)=	578.3
#Full time(mm:ss)=	3:18
#Project=
#Sample=
#Site=
#Title=	Mbcal_20_25_47_2x_45s_532 nm_x100_100%_600 gr_mm
#Remark=
#Date=	18.07.2022 13:47
#Acquired=	18.07.2022 13:47:18
#Base:Fit=	10.08.2022 10:55:08
#Base:Sub=	10.08.2022 10:55:14
#Filter:Polynom=	16.08.2022 10:07:28
#AxisType[0]=Intens
#AxisUnit[0]=Cnt
#AxisType[1]=Spectr
#AxisUnit[1]=1/cm
200.419	16.6583
204.048	11.6871
207.678	8.68957
211.304	6.8137
214.928	4.97466
218.554	2.97296
222.176	2.37306
225.798	0.843597
229.417	0.54967
233.035	3.32851
236.653	5.77154
240.268	7.70145
243.881	10.4786
247.493	12.4748
251.103	15.2769
254.715	17.568
258.322	18.5137
261.929	20.2901
265.534	21.7189
269.137	22.5431
272.739	22.3601
276.34	20.585
279.939	21.251
283.537	22.0044
287.134	20.9543
290.729	19.5219
294.323	17.4169
297.913	18.0827
301.504	17.3598
305.093	15.4951
308.682	16.7997
312.268	15.8595
315.852	16.1558
319.436	17.4492
323.018	18.1295
326.597	19.9736
330.177	21.3079
333.753	19.6693
337.331	18.6157
340.906	19.4328
344.478	19.4511
348.051	18.2669
351.621	17.0365
355.189	15.0531
358.757	13.2539
362.323	12.0602
365.889	11.584
369.451	9.55173
373.012	8.03822
376.574	6.02877
380.133	3.85201
383.69	4.63104
387.245	5.18431
390.8	6.41779
394.353	7.51759
397.906	7.21019
401.456	5.15194
405.005	5.43009
408.552	4.95822
412.099	5.60828
415.643	5.70689
419.187	4.17984
422.728	4.0424
426.269	5.75927
429.806	7.49738
433.344	8.8595
436.881	8.62532
440.416	7.24917
443.949	7.57743
447.48	7.19265
451.011	6.65039
454.541	5.46871
458.069	4.70299
461.594	4.97222
465.119	5.37202
468.642	7.55345
472.165	10.3908
475.684	9.93169
479.204	11.751
482.721	11.716
486.239	11.0173
489.753	11.8687
493.268	13.242
496.779	13.8633
500.289	15.9719
503.8	17.0032
507.307	19.2226
510.813	20.6433
514.32	22.0991
517.823	23.7742
521.325	23.3525
524.826	21.9184
528.325	20.4685
531.823	20.5096
535.32	19.3398
538.815	18.7492
542.309	18.0279
545.802	17.673
549.293	16.8509
552.783	16.0281
556.271	15.6216
559.759	13.1585
563.245	13.3305
566.729	12.3232
570.213	9.83616
573.693	10.9953
577.173	8.11344
580.652	8.0718
584.13	7.60231
587.605	7.06731
591.08	6.62956
594.552	5.621
598.025	4.28082
601.496	4.07998
604.964	5.50628
608.433	4.63798
611.898	5.55154
615.364	6.88925
618.827	9.59601
622.288	7.63651
625.75	8.74189
629.209	9.11123
632.667	10.4072
636.125	12.3697
639.58	13.765
643.033	14.6294
646.485	16.2247
649.936	18.5334
653.388	18.6028
656.836	19.854
660.283	21.834
663.728	22.158
667.173	25.1567
670.616	25.8033
674.057	26.694
677.498	26.6839
680.937	28.5764
684.375	30.6086
687.809	33.1095
691.244	34.7363
694.678	35.2822
698.111	34.6689
701.54	33.8195
704.97	34.5023
708.398	34.557
711.826	36.6756
715.25	37.0261
718.675	38.3688
722.096	39.0476
725.518	38.9314
728.937	41.8346
732.357	44.449
735.773	46.5299
739.19	47.6589
742.604	49.9472
746.018	55.2841
749.429	59.2977
752.839	64.0646
756.248	65.9819
759.657	68.8651
763.063	72.5768
766.468	75.5596
769.871	77.739
773.273	79.5902
776.676	80.1285
780.075	82.1359
783.474	84.475
786.871	88.8663
790.266	91.0161
793.661	94.2206
797.054	94.844
800.446	96.2764
803.834	97.5999
807.224	96.3287
810.612	96.6673
813.998	93.6071
817.384	93.2009
820.766	93.187
824.149	93.7121
827.531	96.5173
830.909	98.427
834.288	99.9939
837.666	102.672
841.041	102.982
844.416	102.967
847.788	103.765
851.161	102.587
854.53	103.117
857.901	102.965
861.268	102.017
864.633	102.322
868	101.306
871.363	99.4799
874.725	97.4128
878.088	93.744
881.447	89.4384
884.805	84.6766
888.162	80.4659
891.518	77.3288
894.872	73.363
898.225	69.5875
901.577	67.3756
904.928	67.9543
908.277	68.9389
911.625	69.4108
914.972	70.6804
918.318	70.5311
921.662	68.8502
925.005	68.3912
928.347	66.6956
931.686	65.3679
935.025	62.8755
938.363	59.6984
941.698	57.6516
945.034	54.4553
948.368	51.6289
951.699	48.6372
955.031	46.9726
958.36	43.3316
961.689	40.3887
965.016	38.4264
968.343	37.5401
971.666	37.1777
974.991	34.9242
978.312	31.7972
981.632	30.8981
984.953	31.0296
988.27	30.0726
991.587	27.973
994.902	26.5021
998.216	24.4381
1001.53	22.6379
1004.84	22.1706
1008.15	21.1193
1011.46	20.9382
1014.77	20.293
1018.07	20.8184
1021.38	22.9918
1024.68	23.5076
1027.99	26.3418
1031.29	27.2787
1034.59	29.408
1037.89	28.3128
1041.18	28.9082
1044.48	28.8861
1047.77	31.4835
1051.07	31.8834
1054.36	30.3481
1057.65	31.369
1060.94	29.8646
1064.23	27.5321
1067.52	24.5863
1070.8	23.5142
1074.09	21.7359
1077.37	20.7049
1080.65	19.4371
1083.93	19.4493
1087.21	20.5225
1090.49	20.7823
1093.77	21.3567
1097.04	21.9556
1100.32	21.9179
1103.59	22.9098
1106.86	21.7489
1110.13	22.9528
1113.4	20.5544
1116.67	19.76
1119.94	16.8404
1123.2	16.7157
1126.47	14.9858
1129.73	14.3258
1132.99	12.4584
1136.25	9.96499
1139.51	7.71583
1142.77	6.81151
1146.03	5.67795
1149.28	6.86758
1152.54	6.65146
1155.79	6.5177
1159.04	5.14838
1162.29	5.83032
1165.54	8.1618
1168.79	9.6496
1172.04	10.8539
1175.28	12.1656
1178.53	11.4838
1181.77	12.0582
1185.01	15.3065
1188.25	15.6926
1191.49	16.0043
1194.73	15.214
1197.96	15.92
1201.2	14.7656
1204.43	15.1697
1207.66	15.7407
1210.9	15.301
1214.13	16.6811
1217.36	17.4254
1220.58	19.5711
1223.81	22.8979
1227.04	24.4717
1230.26	26.0449
1233.48	27.701
1236.71	28.0503
1239.93	29.2506
1243.14	31.8023
1246.36	34.1752
1249.58	34.6533
1252.8	35.0337
1256.01	34.6715
1259.22	34.9405
1262.43	36.5602
1265.64	37.164
1268.85	35.8721
1272.06	34.9617
1275.27	35.2523
1278.48	35.6631
1281.68	37.6603
1284.88	40.5156
1288.08	41.97
1291.28	43.7233
1294.48	48.1864
1297.68	51.5578
1300.88	54.3686
1304.07	56.2713
1307.27	56.8199
1310.46	56.6726
1313.65	58.2582
1316.85	58.3952
1320.03	57.2351
1323.22	57.5642
1326.41	55.9389
1329.6	55.3531
1332.78	53.1955
1335.96	51.2544
1339.15	50.4833
1342.33	49.2054
1345.51	44.4491
1348.69	42.5726
1351.86	40.8606
1355.04	41.1505
1358.21	42.8806
1361.39	43.6303
1364.56	43.7555
1367.73	44.9402
1370.9	46.8654
1374.07	47.8579
1377.24	46.3965
1380.41	46.1792
1383.57	45.9964
1386.73	45.377
1389.9	46.1532
1393.06	45.1805
1396.22	44.5879
1399.38	45.0302
1402.54	45.9688
1405.69	47.379
1408.85	50.3678
1412	53.2048
1415.16	56.3725
1418.31	59.4865
1421.46	64.1069
1424.61	68.6222
1427.76	74.5256
1430.9	79.2421
1434.05	82.054
1437.2	85.615
1440.34	88.3479
1443.48	90.777
1446.62	91.7274
1449.76	92.2097
1452.9	90.973
1456.04	89.0334
1459.17	87.077
1462.31	84.154
1465.44	79.6537
1468.58	74.7989
1471.71	70.5832
1474.84	66.5611
1477.97	61.0739
1481.1	57.2223
1484.22	53.2931
1487.35	49.4559
1490.47	45.7997
1493.59	43.0277
1496.72	40.3277
1499.84	37.5377
1502.96	35.516
1506.08	34.1739
1509.19	29.974
1512.31	28.1069
1515.42	25.436
1518.54	23.5982
1521.65	22.9155
1524.76	20.8451
1527.87	21.125
1530.98	20.6466
1534.09	22.0467
1537.2	22.4791
1540.3	22.5171
1543.41	23.1409
1546.51	22.9514
1549.61	24.2666
1552.71	24.754
1555.81	24.6682
1558.91	25.6684
1562.01	25.6307
1565.1	26.4962
1568.2	28.2321
1571.29	29.9453
1574.38	32.3791
1577.48	34.1118
1580.57	35.9076
1583.65	35.617
1586.74	36.1557
1589.83	37.4275
1592.92	37.6683
1596	39.7269
1599.08	41.0385
1602.16	42.0562
1605.24	42.9868
1608.32	43.8431
1611.4	43.8862
1614.48	43.622
1617.56	42.2719
1620.63	43.7784
1623.71	43.8403
1626.78	45.594
1629.85	45.5638
1632.92	45.2669
1635.99	46.087
1639.06	46.192
1642.12	49.3778
1645.19	50.7882
1648.25	52.4596
1651.32	51.9234
1654.38	51.7286
1657.44	51.0114
1660.5	51.0271
1663.56	51.0999
1666.62	49.4738
1669.67	46.6571
1672.73	44.0713
1675.79	39.6687
1678.84	35.0519
1681.89	30.9601
1684.94	27.7845
1687.99	24.8391
1691.04	21.759
1694.08	18.8389
1697.13	16.9571
1700.18	16.3498
1703.22	15.3298
1706.26	12.4325
1709.3	10.6986
1712.35	10.5246
1715.39	9.60754
1718.42	10.5948
1721.46	9.17511
1724.5	9.47554
1727.53	6.89021
1730.56	8.28294
1733.6	8.004
1736.63	8.07405
1739.66	6.99227
1742.69	6.09112
1745.71	5.29236
1748.74	4.77462
1751.77	3.45273
1754.79	4.1367
1757.81	4.53632
1760.84	4.23897
1763.86	4.30303
1766.88	5.61879
1769.9	5.83466
1772.91	6.70884
1775.93	6.34882
1778.95	5.35391
1781.96	4.48358
1784.97	4.12041
1787.99	4.23061
1791	3.50094
1794.01	3.85304
1797.01	3.33571
1800.02	2.3085
1803.03	2.62796
1806.03	3.1277
1809.04	2.15736
1812.04	2.87106
1815.04	4.27618
1818.04	3.81796
1821.04	3.38807
1824.04	3.38461
1827.04	3.49263
1830.03	3.77787
1833.03	4.87686
1836.02	5.19403
1839.02	6.67443
1842.01	7.95532
1845	8.04097
1847.99	7.54896
1850.98	8.98457
1853.96	9.55474
1856.95	10.8311
1859.94	10.768
1862.92	10.3075
1865.9	11.2666
1868.88	9.99511
1871.86	9.182
1874.84	9.02582
1877.82	8.245
1880.8	8.46294
1882.58	8.42291
1885.57	6.41816
1888.56	4.79926
1891.54	3.32235
1894.53	3.31675
1897.51	2.43818
1900.5	2.27581
1903.48	2.46109
1906.46	2.29871
1909.44	2.17057
1912.42	3.42648
1915.4	3.80521
1918.37	3.40829
1921.35	4.5986
1924.32	6.35625
1927.3	6.4826
1930.27	6.86471
1933.24	5.02377
1936.21	6.44806
1939.18	6.64065
1942.15	6.02963
1945.11	7.31027
1948.08	7.29404
1951.04	6.88552
1954.01	6.36478
1956.97	7.91092
1959.93	7.3915
1962.89	8.0168
1965.85	8.42176
1968.81	9.2122
1971.77	10.5035
1974.72	10.9944
1977.68	9.78782
1980.63	8.61422
1983.58	9.41145
1986.53	9.92718
1989.48	9.62167
1992.43	8.82191
1995.38	10.0867
1998.33	8.89085
2001.27	8.69942
2004.22	6.85395
2007.16	7.16134
2010.11	7.50943
2013.05	6.59784
2015.99	6.68025
2018.93	6.62025
2021.87	7.14795
2024.8	8.49512
2027.74	9.24162
2030.68	9.27233
2033.61	9.58285
2036.54	10.4539
2039.48	12.2568
2042.41	13.4961
2045.34	13.9083
2048.27	13.6906
2051.19	13.6338
2054.12	15.9437
2057.05	16.4874
2059.97	16.2261
2062.9	16.5985
2065.82	17.6043
2068.74	18.2063
2071.66	18.1664
2074.58	17.9512
2077.5	18.0498
2080.41	17.9424
2083.33	17.6868
2086.24	17.6981
2089.16	17.4565
2092.07	17.3834
2094.98	16.7866
2097.89	17.0166
2100.8	16.3892
2103.71	17.1049
2106.62	16.6047
2109.53	17.4819
2112.43	18.2383
2115.33	17.0713
2118.24	17.7393
2121.14	17.6228
2124.04	19.9476
2126.94	20.16
2129.84	21.3785
2132.74	23.4538
2135.63	26.2967
2138.53	27.4752
2141.43	28.5976
2144.32	29.4074
2147.21	31.1964
2150.1	33.2444
2152.99	35.4429
2155.88	37.064
2158.77	40.1195
2161.66	42.6206
2164.55	43.2702
2167.43	45.1458
2170.31	46.0908
2173.2	45.3048
2176.08	45.4131
2178.96	44.2119
2181.84	43.9528
2184.72	41.1432
2187.6	39.9154
2190.47	38.66
2193.35	36.9227
2196.23	35.6286
2199.1	33.435
2201.97	31.3074
2204.84	29.5545
2207.71	27.5917
2210.58	26.9191
2213.45	25.0668
2216.32	23.1763
2219.19	22.102
2222.05	21.7378
2224.92	20.3653
2227.78	20.0467
2230.64	20.4719
2233.5	19.1764
2236.36	18.9597
2239.22	19.776
2242.08	18.3666
2244.94	17.7198
2247.79	16.1297
2250.65	15.6663
2253.5	15.9592
2256.36	16.2909
2259.21	15.6685
2262.06	16.2677
2264.91	15.9402
2267.76	15.2868
2270.6	15.8182
2273.45	16.008
2276.3	16.3398
2279.14	16.7265
2281.98	16.4605
2284.83	16.0075
2287.67	15.5195
2290.51	15.4858
2293.35	14.7236
2296.19	14.2046
2299.02	15.6843
2301.86	16.6647
2304.7	17.3278
2307.53	19.2747
2310.36	19.0853
2313.2	17.8735
2316.03	17.5604
2318.86	17.1154
2321.69	17.0072
2324.51	15.895
2327.34	14.1253
2330.17	13.6584
2332.99	13.4709
2335.82	11.1113
2338.64	10.4767
2341.46	9.7019
2344.28	7.87364
2347.1	6.66299
2349.92	5.71218
2352.74	5.43424
2355.56	5.29914
2358.37	5.23975
2361.19	4.9074
2364	5.74444
2366.82	7.29036
2369.63	8.04936
2372.44	10.0296
2375.25	11.014
2378.06	11.5031
2380.86	11.1254
2383.67	8.77478
2386.48	9.10774
2389.28	8.5865
2392.09	8.88882
2394.89	9.74075
2397.69	8.88589
2400.49	8.12624
2403.29	8.21027
2406.09	7.03593
2408.89	6.4271
2411.69	6.07931
2414.48	5.29531
2417.28	3.99466
2420.07	4.27721
2422.86	4.88676
2425.65	5.89214
2428.45	5.56737
2431.23	5.52564
2434.02	4.99531
2436.81	4.35527
2439.6	4.16464
2442.38	4.58608
2445.17	5.41115
2447.95	4.84368
2450.73	5.33493
2453.52	6.0886
2456.3	5.93597
2459.08	5.61871
2461.85	5.17345
2464.63	5.18654
2467.41	4.5052
2470.19	4.47149
2472.96	3.46095
2475.73	2.78265
2478.51	2.67458
2481.28	2.95285
2484.05	3.04634
2486.82	3.08859
2489.59	3.70181
2492.35	4.56912
2495.12	4.34696
2497.89	4.49195
2500.65	4.07315
2503.42	3.56318
2506.18	3.81351
2508.94	4.48971
2511.7	6.01224
2514.46	6.98262
2517.22	7.4285
2519.98	7.17917
2522.73	6.87854
2525.49	5.74923
2528.25	6.78075
2531	6.99815
2533.75	7.34627
2536.5	6.96232
2539.25	7.32099
2542.01	8.37366
2544.75	8.98971
2547.5	8.64887
2550.25	8.61455
2553	7.37716
2555.74	6.88478
2558.49	7.40589
2561.23	6.39767
2563.97	5.25645
2566.71	5.06934
2569.45	3.47851
2572.19	3.13719
2574.93	3.39202
2577.67	2.552
2580.4	2.73178
2583.14	1.89126
2585.87	-0.0610348
2588.6	-0.251143
2591.34	0.319
2594.07	0.565497
2596.8	0.238997
2599.53	1.39179
2602.26	1.1555
2604.98	0.902919
2607.71	1.87591
2610.44	2.08059
2613.16	0.657271
2615.88	1.17134
2618.61	1.54991
2621.33	2.1868
2624.05	2.71046
2626.77	3.29846
2629.49	3.28632
2632.21	3.67867
2634.92	4.46706
2637.64	4.71608
2640.35	5.49008
2643.07	5.99415
2645.78	5.83363
2648.49	6.6747
2651.2	5.94357
2653.91	5.91662
2656.62	6.19664
2659.33	5.36921
2662.04	4.59766
2664.74	4.08382
2667.45	3.82481
2670.15	3.3347
2672.86	3.13742
2675.56	3.27675
2678.26	3.04068
2680.96	3.26839
2683.66	4.28426
2686.36	3.17846
2689.06	2.8325
2691.75	3.80487
2694.45	4.67361
2697.14	4.52682
2699.84	5.21958
2702.53	6.09651
2705.22	6.40418
2707.91	7.8876
2710.6	8.38153
2713.29	9.71573
2715.98	10.7934
2718.67	10.1044
2721.35	11.5172
2724.04	11.4138
2726.72	10.6951
2729.4	10.5835
2732.09	10.1957
2734.77	10.6688
2737.45	10.2937
2740.13	10.3013
2742.81	9.8151
2745.48	9.41567
2748.16	8.12111
2750.84	6.66126
2753.51	5.82594
2756.19	5.79974
2758.86	4.97282
2761.53	3.58824
2764.2	2.65015
2766.87	1.77708
2769.54	2.82209
2772.21	2.74199
2774.88	2.68752
2777.54	2.55261
2780.21	3.6863
2782.87	3.3988
2785.53	2.80949
2788.2	2.09271
2790.86	0.975743
2793.52	1.56979
2796.18	0.868294
2798.84	1.33992
2801.49	2.16274
2804.15	1.56338
2806.81	0.938213
2809.46	0.368457
2812.12	0.510974
2814.77	0.837076
2817.42	2.10478
2820.07	4.53525
2822.72	6.85467
2825.37	8.40566
2828.02	12.0353
2830.67	15.9725
2833.31	21.264
2835.96	25.9524
2838.61	31.1132
2841.25	37.468
2843.89	44.0167
2846.53	50.9673
2849.17	57.5069
2851.81	65.4314
2854.45	72.4155
2857.09	80.7215
2859.73	87.9476
2862.36	94.9775
2865	101.228
2867.64	107.027
2870.27	112.058
2872.9	116.791
2875.53	121.351
2878.16	125.26
2880.79	129.157
2883.42	133.995
2886.05	139.003
2888.68	142.585
2891.3	147.295
2893.93	152.826
2896.55	157.693
2899.18	163.155
2901.8	170.511
2904.42	177.645
2907.04	185.188
2909.66	194.972
2912.28	203.34
2914.9	211.665
2917.51	220.047
2920.13	226.413
2922.74	231.668
2925.36	234.924
2927.97	236.477
2930.59	235.418
2933.2	233.175
2935.81	228.415
2938.42	222.564
2941.02	214.744
2943.63	206.226
2946.24	197.194
2948.85	189.322
2951.45	179.111
2954.05	168.86
2956.66	159.342
2959.26	150.459
2961.86	141.396
2964.46	134.517
2967.06	128.178
2969.66	122.672
2972.26	118.112
2974.85	113.637
2977.45	108.838
2980.05	103.406
2982.64	98.3345
2985.23	92.5043
2987.83	86.825
2990.42	80.1774
2993.01	73.1527
2995.6	66.1623
2998.19	58.7088
3000.77	51.6215
3003.36	45.5367
3005.95	38.9394
3008.53	32.4864
3011.12	27.1441
3013.7	21.8714
3016.28	16.3285
3018.86	12.7211
3021.44	9.69014
3024.02	7.28818
3026.6	6.30663
3029.18	5.79541
3031.76	4.66302
3034.33	4.73326
3036.91	4.94896
3039.48	4.64944
3042.05	4.14023
3044.63	4.70958
3047.2	6.30367
3049.77	7.50902
3052.34	8.3933
3054.91	9.79611
3057.48	9.35416
3060.04	10.5979
3062.61	11.1079
3065.17	10.6469
3067.74	9.00607
3070.3	7.62303
3072.87	6.76398
3075.43	6.20756
3077.99	6.57049
3080.55	5.87767
3083.11	5.86143
3085.67	5.60557
3088.22	4.89524
3090.78	4.62472
3093.34	4.68928
3095.89	4.56404
3098.44	5.02563
3101	5.77894
3103.55	5.67772
3106.1	7.68019
3108.65	9.31153
3111.2	10.1397
3113.75	11.1198
3116.3	12.3002
3118.84	12.5635
3121.39	13.343
3123.93	14.2124
3126.48	14.1266
3129.02	13.5377
3131.56	13.3683
3134.1	14.1744
3136.64	14.089
3139.18	14.9247
3141.72	14.2481
3144.26	13.5339
3146.8	13.1264
3149.33	14.1851