File: data/Raman/poly_smoothed/Mbcal_20_25_42_1x_45s_532 nm_x100_100%_600 gr_mm_01.txt
#Acq. time (s)=	45
#Accumulations=	2
#Range (cm-¹)=	200...3150
#Windows=	2
#Auto scanning=	Off
#Autofocus=	Off
#Macrospot=	Off
#AutoExposure=	Off
#Spike filter=	Multiple accum.
#Delay time (s)=	0
#Binning=	1
#Readout mode=	Signal
#DeNoise=	Off
#ICS correction=	On
#Dark correction=	Off
#Inst. Process=	Off
#Detector Gain=	Best Dynamic Range
#Detector ADC=	20 kHz
#Detector temperature (°C)=	-69.85
#Instrument=	LabRAM HR Evol
#Detector=	Synapse
#Objective=	x100
#Grating=	600 gr/mm
#ND Filter=	100%
#Laser (nm)=	532
#Hole=	100.021
#Range=	Auto
#Laser Pol.=	No
#Raman. Pol.=	No
#Laser Pol. (°)=	-0.0007625
#Raman Pol. (°)=	89.9995
#Collection=	Microscope
#StageXY=	Marzhauser
#StageZ=	Marzhauser
#X (µm)=	-1134.3
#Y (µm)=	1258.5
#Z (µm)=	578.4
#Full time(mm:ss)=	3:18
#Project=
#Sample=
#Site=
#Title=	Mbcal_20_25_42_2x_45s_532 nm_x100_100%_600 gr_mm
#Remark=
#Date=	18.07.2022 13:22
#Acquired=	18.07.2022 13:22:35
#Base:Fit=	10.08.2022 10:55:08
#Base:Sub=	10.08.2022 10:55:14
#Filter:Polynom=	16.08.2022 10:07:28
#AxisType[0]=Intens
#AxisUnit[0]=Cnt
#AxisType[1]=Spectr
#AxisUnit[1]=1/cm
200.419	-1.79454
204.048	2.11988
207.678	5.85134
211.304	7.52525
214.928	8.5257
218.554	9.7272
222.176	8.48991
225.798	7.09116
229.417	6.69162
233.035	7.57766
236.653	7.17988
240.268	8.69601
243.881	9.65296
247.493	8.75042
251.103	8.51753
254.715	8.32109
258.322	8.6809
261.929	9.30605
265.534	9.94296
269.137	8.94984
272.739	8.44595
276.34	10.4288
279.939	10.3779
283.537	10.6723
287.134	9.79743
290.729	8.92683
294.323	8.3865
297.913	7.30488
301.504	7.82773
305.093	8.2653
308.682	7.00597
312.268	7.50064
315.852	8.67312
319.436	9.54467
323.018	11.9125
326.597	11.3251
330.177	11.1614
333.753	11.3769
337.331	11.7241
340.906	13.0743
344.478	12.5181
348.051	12.9494
351.621	12.6185
355.189	11.6219
358.757	12.6531
362.323	13.6941
365.889	13.308
369.451	11.0203
373.012	10.6304
376.574	11.1966
380.133	11.0372
383.69	11.9571
387.245	12.6427
390.8	12.9038
394.353	13.5206
397.906	13.5284
401.456	14.525
405.005	15.9421
408.552	16.5
412.099	15.4553
415.643	15.6762
419.187	15.2045
422.728	15.0238
426.269	13.743
429.806	12.0592
433.344	11.5446
436.881	11.0781
440.416	11.0264
443.949	10.0638
447.48	10.437
451.011	9.71376
454.541	10.1654
458.069	10.955
461.594	11.2371
465.119	11.4084
468.642	12.9287
472.165	12.3695
475.684	12.5606
479.204	14.39
482.721	14.7744
486.239	16.713
489.753	19.9434
493.268	21.4098
496.779	21.234
500.289	22.4516
503.8	21.9959
507.307	20.7582
510.813	21.9952
514.32	21.7401
517.823	22.1556
521.325	21.8016
524.826	21.8395
528.325	22.6293
531.823	22.7455
535.32	22.6594
538.815	23.1725
542.309	22.1789
545.802	20.303
549.293	18.8238
552.783	17.186
556.271	14.4432
559.759	14.2776
563.245	12.3893
566.729	11.467
570.213	10.2741
573.693	8.99894
577.173	7.81571
580.652	6.89531
584.13	4.75731
587.605	3.20452
591.08	3.23568
594.552	2.4073
598.025	1.19027
601.496	1.01564
604.964	-0.767043
608.433	0.572952
611.898	1.70661
615.364	2.61881
618.827	3.98659
622.288	4.64037
625.75	5.72964
629.209	5.01427
632.667	6.25965
636.125	8.80244
639.58	10.7274
643.033	12.5157
646.485	15.7773
649.936	17.0064
653.388	18.0297
656.836	18.7661
660.283	19.724
663.728	20.4664
667.173	20.4585
670.616	20.9291
674.057	21.964
677.498	23.2127
680.937	22.4887
684.375	23.8153
687.809	27.3764
691.244	28.7588
694.678	31.6548
698.111	31.3432
701.54	31.8596
704.97	33.0172
708.398	33.8043
711.826	35.2003
715.25	37.7362
718.675	40.5427
722.096	41.7484
725.518	43.0787
728.937	44.9151
732.357	45.2281
735.773	44.2324
739.19	43.5823
742.604	44.6995
746.018	45.1351
749.429	46.4012
752.839	48.5388
756.248	51.1123
759.657	52.2538
763.063	55.0772
766.468	58.1878
769.871	61.6717
773.273	64.3119
776.676	64.4399
780.075	65.0275
783.474	65.5701
786.871	66.7476
790.266	70.2441
793.661	71.8234
797.054	72.3348
800.446	73.5677
803.834	72.7044
807.224	71.2083
810.612	70.7908
813.998	70.1472
817.384	67.7883
820.766	66.2075
824.149	66.1024
827.531	66.1184
830.909	66.0754
834.288	66.3255
837.666	68.1602
841.041	68.8573
844.416	71.1219
847.788	71.2338
851.161	71.0637
854.53	70.795
857.901	69.6993
861.268	67.8799
864.633	66.0394
868	64.7239
871.363	61.6569
874.725	59.7651
878.088	57.1239
881.447	54.4955
884.805	51.0864
888.162	48.4123
891.518	46.5466
894.872	44.6361
898.225	40.9505
901.577	39.8092
904.928	39.6346
908.277	39.3146
911.625	38.2292
914.972	38.5609
918.318	40.4536
921.662	40.9247
925.005	40.2892
928.347	39.2952
931.686	39.0461
935.025	38.0059
938.363	36.6588
941.698	34.8929
945.034	30.3454
948.368	28.6144
951.699	26.7844
955.031	24.5828
958.36	23.3258
961.689	21.2236
965.016	18.3027
968.343	18.0157
971.666	17.9687
974.991	16.8468
978.312	16.629
981.632	17.198
984.953	16.8694
988.27	16.5247
991.587	16.4588
994.902	16.6074
998.216	15.7997
1001.53	15.6806
1004.84	15.1935
1008.15	14.1249
1011.46	14.391
1014.77	14.7829
1018.07	12.9659
1021.38	12.7223
1024.68	11.3596
1027.99	13.5362
1031.29	13.4505
1034.59	13.3719
1037.89	14.4667
1041.18	13.5109
1044.48	14.3036
1047.77	14.6938
1051.07	14.9495
1054.36	15.5372
1057.65	14.6437
1060.94	15.0512
1064.23	16.4445
1067.52	15.224
1070.8	15.3532
1074.09	15.1199
1077.37	13.9219
1080.65	12.8798
1083.93	12.9487
1087.21	12.8989
1090.49	13.0682
1093.77	13.12
1097.04	12.3026
1100.32	13.3845
1103.59	13.291
1106.86	14.9759
1110.13	15.8271
1113.4	15.8507
1116.67	16.317
1119.94	16.3222
1123.2	14.5506
1126.47	13.679
1129.73	11.4943
1132.99	10.9705
1136.25	10.2706
1139.51	8.88965
1142.77	8.18447
1146.03	7.57638
1149.28	6.25275
1152.54	5.55456
1155.79	4.25324
1159.04	2.50057
1162.29	2.25573
1165.54	1.85014
1168.79	2.46714
1172.04	1.73142
1175.28	2.10719
1178.53	4.29273
1181.77	7.94456
1185.01	10.3603
1188.25	12.924
1191.49	14.1052
1194.73	14.4745
1197.96	15.4677
1201.2	16.771
1204.43	17.3458
1207.66	18.4634
1210.9	20.8375
1214.13	22.4692
1217.36	24.1302
1220.58	25.0778
1223.81	28.224
1227.04	29.3276
1230.26	30.4969
1233.48	29.9402
1236.71	29.7997
1239.93	30.4023
1243.14	30.9559
1246.36	32.9826
1249.58	34.2843
1252.8	35.5119
1256.01	39.3038
1259.22	41.6649
1262.43	42.7174
1265.64	42.9715
1268.85	44.6513
1272.06	46.4169
1275.27	49.2383
1278.48	51.9472
1281.68	54.9705
1284.88	57.3662
1288.08	59.6698
1291.28	62.6537
1294.48	63.8524
1297.68	65.3709
1300.88	65.9537
1304.07	68.3176
1307.27	69.1814
1310.46	69.845
1313.65	69.976
1316.85	72.0121
1320.03	72.8219
1323.22	74.2948
1326.41	74.2732
1329.6	74.5356
1332.78	73.6903
1335.96	73.9283
1339.15	71.9021
1342.33	72.4339
1345.51	73.1873
1348.69	72.4761
1351.86	72.586
1355.04	70.9671
1358.21	69.7596
1361.39	69.0185
1364.56	67.549
1367.73	66.8927
1370.9	65.9392
1374.07	65.8151
1377.24	64.2884
1380.41	63.3341
1383.57	63.2275
1386.73	62.3003
1389.9	60.5324
1393.06	59.7687
1396.22	57.2959
1399.38	54.2449
1402.54	53.0134
1405.69	52.8793
1408.85	52.5033
1412	52.7358
1415.16	53.275
1418.31	56.4971
1421.46	60.1906
1424.61	63.9649
1427.76	68.4653
1430.9	71.0758
1434.05	76.7994
1437.2	80.8681
1440.34	84.2883
1443.48	86.4769
1446.62	89.4913
1449.76	92.9548
1452.9	94.7813
1456.04	99.2941
1459.17	100.187
1462.31	102.656
1465.44	103.762
1468.58	105.536
1471.71	106.105
1474.84	106.532
1477.97	106.682
1481.1	107.456
1484.22	106.207
1487.35	104.083
1490.47	101.28
1493.59	100.26
1496.72	96.0543
1499.84	91.7903
1502.96	86.7823
1506.08	80.2457
1509.19	75.0224
1512.31	67.5295
1515.42	57.8608
1518.54	51.5943
1521.65	47.4116
1524.76	42.7681
1527.87	39.3614
1530.98	37.827
1534.09	37.0332
1537.2	36.25
1540.3	36.7369
1543.41	36.5341
1546.51	38.5786
1549.61	40.2291
1552.71	41.6272
1555.81	43.2812
1558.91	44.2062
1562.01	45.5672
1565.1	46.1166
1568.2	47.2283
1571.29	48.1509
1574.38	49.8114
1577.48	51.7969
1580.57	52.7614
1583.65	52.6989
1586.74	53.5854
1589.83	52.9559
1592.92	54.5059
1596	55.4838
1599.08	55.4092
1602.16	54.6537
1605.24	55.4287
1608.32	55.9801
1611.4	55.5514
1614.48	56.3246
1617.56	56.817
1620.63	56.5156
1623.71	57.1376
1626.78	58.7032
1629.85	59.6629
1632.92	61.6716
1635.99	63.5861
1639.06	67.0103
1642.12	68.3071
1645.19	70.9945
1648.25	74.5484
1651.32	75.6824
1654.38	76.0943
1657.44	75.5827
1660.5	74.6738
1663.56	73.7937
1666.62	71.2941
1669.67	70.4635
1672.73	66.4707
1675.79	63.1244
1678.84	60.0208
1681.89	55.5474
1684.94	50.8497
1687.99	46.7649
1691.04	41.2256
1694.08	36.4854
1697.13	31.0134
1700.18	28.1106
1703.22	25.1529
1706.26	22.5879
1709.3	19.445
1712.35	17.2507
1715.39	15.6717
1718.42	14.3348
1721.46	13.6884
1724.5	14.018
1727.53	12.9428
1730.56	12.147
1733.6	11.0075
1736.63	9.85539
1739.66	9.47932
1742.69	9.11045
1745.71	8.15782
1748.74	8.59851
1751.77	7.99077
1754.79	7.18708
1757.81	6.82527
1760.84	6.71529
1763.86	5.58527
1766.88	5.66944
1769.9	5.48333
1772.91	5.66122
1775.93	5.49335
1778.95	3.99525
1781.96	4.35038
1784.97	4.82789
1787.99	5.56119
1791	7.22757
1794.01	8.25053
1797.01	8.77699
1800.02	8.74831
1803.03	8.74682
1806.03	8.44184
1809.04	8.43167
1812.04	8.63562
1815.04	8.31344
1818.04	8.45864
1821.04	8.19373
1824.04	7.68192
1827.04	6.88128
1830.03	6.24209
1833.03	6.14795
1836.02	5.95668
1839.02	6.36981
1842.01	6.24208
1845	6.11172
1847.99	5.80151
1850.98	5.24103
1853.96	4.86445
1856.95	4.07585
1859.94	4.52331
1862.92	4.65963
1865.9	4.53251
1868.88	4.34883
1871.86	4.49453
1874.84	4.43151
1877.82	5.61582
1880.8	5.50434
1882.58	6.27019
1885.57	6.55568
1888.56	5.85822
1891.54	6.78146
1894.53	6.98622
1897.51	6.9254
1900.5	7.32219
1903.48	7.91398
1906.46	8.08563
1909.44	9.13827
1912.42	9.65014
1915.4	8.77304
1918.37	8.44757
1921.35	7.10583
1924.32	5.629
1927.3	4.50965
1930.27	4.22067
1933.24	3.35311
1936.21	2.65658
1939.18	2.02886
1942.15	1.92609
1945.11	0.811786
1948.08	0.84404
1951.04	0.39336
1954.01	0.479005
1956.97	0.529479
1959.93	0.400736
1962.89	1.56291
1965.85	1.91247
1968.81	2.80046
1971.77	4.36594
1974.72	5.10548
1977.68	5.48089
1980.63	6.37517
1983.58	7.03792
1986.53	6.94307
1989.48	6.35474
1992.43	5.39764
1995.38	4.71254
1998.33	4.3711
2001.27	3.67254
2004.22	3.46376
2007.16	3.64026
2010.11	2.9648
2013.05	3.03612
2015.99	2.39221
2018.93	2.84539
2021.87	2.57367
2024.8	2.95144
2027.74	3.38773
2030.68	3.17477
2033.61	3.9876
2036.54	4.59685
2039.48	5.32551
2042.41	6.58198
2045.34	6.45488
2048.27	7.99163
2051.19	8.44933
2054.12	8.39181
2057.05	9.24883
2059.97	8.84135
2062.9	7.58889
2065.82	7.11613
2068.74	6.89776
2071.66	5.77947
2074.58	6.39853
2077.5	6.34804
2080.41	6.06692
2083.33	4.84298
2086.24	5.02747
2089.16	6.22573
2092.07	4.92146
2094.98	5.49982
2097.89	6.91871
2100.8	6.73491
2103.71	6.93001
2106.62	7.64635
2109.53	8.71517
2112.43	10.088
2115.33	12.0389
2118.24	13.9219
2121.14	14.9936
2124.04	16.2009
2126.94	17.3125
2129.84	17.841
2132.74	19.4684
2135.63	20.8333
2138.53	23.2995
2141.43	25.4178
2144.32	26.6524
2147.21	28.8928
2150.1	30.469
2152.99	30.405
2155.88	32.1952
2158.77	34.5486
2161.66	36.3421
2164.55	39.291
2167.43	41.7942
2170.31	42.2129
2173.2	42.9178
2176.08	43.6873
2178.96	44.3618
2181.84	44.6142
2184.72	45.2602
2187.6	45.7547
2190.47	44.3031
2193.35	42.7212
2196.23	41.0555
2199.1	39.495
2201.97	38.7065
2204.84	37.519
2207.71	36.3158
2210.58	34.145
2213.45	32.0611
2216.32	30.5362
2219.19	28.4081
2222.05	27.9087
2224.92	25.7025
2227.78	24.718
2230.64	22.9649
2233.5	21.7583
2236.36	20.657
2239.22	18.8312
2242.08	17.0729
2244.94	15.5306
2247.79	14.1376
2250.65	12.7228
2253.5	12.2388
2256.36	11.5711
2259.21	9.70481
2262.06	7.1872
2264.91	4.93015
2267.76	3.25315
2270.6	1.84831
2273.45	1.47892
2276.3	0.736819
2279.14	0.895273
2281.98	0.590895
2284.83	1.35934
2287.67	0.551386
2290.51	0.580174
2293.35	1.50195
2296.19	1.29121
2299.02	3.04558
2301.86	3.32472
2304.7	5.87631
2307.53	7.14386
2310.36	8.94451
2313.2	10.4496
2316.03	10.3073
2318.86	12.0755
2321.69	12.1111
2324.51	11.5059
2327.34	11.8868
2330.17	10.818
2332.99	11.1263
2335.82	9.84008
2338.64	9.79034
2341.46	8.70467
2344.28	7.94171
2347.1	8.36178
2349.92	6.76735
2352.74	6.07501
2355.56	5.03258
2358.37	4.43942
2361.19	3.70585
2364	3.9024
2366.82	3.57469
2369.63	3.55041
2372.44	3.59405
2375.25	4.30997
2378.06	3.78112
2380.86	3.72514
2383.67	2.62955
2386.48	1.77419
2389.28	2.05463
2392.09	1.49271
2394.89	1.47726
2397.69	1.86747
2400.49	1.99821
2403.29	3.38834
2406.09	3.22374
2408.89	3.80965
2411.69	4.32003
2414.48	4.06572
2417.28	5.94803
2420.07	6.09823
2422.86	6.40221
2425.65	6.6225
2428.45	6.69469
2431.23	5.72036
2434.02	5.52921
2436.81	5.11297
2439.6	4.71633
2442.38	4.49797
2445.17	4.19392
2447.95	3.40985
2450.73	3.86701
2453.52	2.52767
2456.3	2.66477
2459.08	2.26065
2461.85	1.43348
2464.63	1.05716
2467.41	0.566126
2470.19	0.564132
2472.96	0.408458
2475.73	0.565381
2478.51	0.633712
2481.28	0.298837
2484.05	1.63303
2486.82	1.45868
2489.59	0.562143
2492.35	1.21295
2495.12	1.55929
2497.89	2.66222
2500.65	2.38752
2503.42	3.08246
2506.18	3.45163
2508.94	4.81358
2511.7	5.51736
2514.46	6.91951
2517.22	7.96072
2519.98	8.24929
2522.73	8.48831
2525.49	8.92314
2528.25	9.63615
2531	9.82434
2533.75	9.55183
2536.5	9.02369
2539.25	9.11213
2542.01	8.64786
2544.75	9.10563
2547.5	8.68088
2550.25	8.85327
2553	8.1368
2555.74	8.02031
2558.49	8.54837
2561.23	9.56997
2563.97	9.5504
2566.71	9.49025
2569.45	9.94654
2572.19	10.2872
2574.93	10.0834
2577.67	10.825
2580.4	10.4113
2583.14	10.4034
2585.87	10.1296
2588.6	10.449
2591.34	10.2783
2594.07	11.8079
2596.8	11.3816
2599.53	11.1704
2602.26	10.5907
2604.98	10.8646
2607.71	10.2046
2610.44	10.2192
2613.16	11.0304
2615.88	10.978
2618.61	10.8419
2621.33	10.8877
2624.05	11.4135
2626.77	10.6935
2629.49	11.1883
2632.21	11.2855
2634.92	10.7565
2637.64	10.556
2640.35	10.0792
2643.07	10.9237
2645.78	9.65035
2648.49	9.29033
2651.2	9.77309
2653.91	10.1138
2656.62	10.454
2659.33	10.5976
2662.04	11.0939
2664.74	11.1764
2667.45	11.0851
2670.15	11.0392
2672.86	10.7121
2675.56	10.7046
2678.26	11.833
2680.96	11.8729
2683.66	11.7644
2686.36	11.8015
2689.06	11.3775
2691.75	10.4719
2694.45	10.6419
2697.14	10.3763
2699.84	10.4881
2702.53	10.7573
2705.22	12.3289
2707.91	12.4687
2710.6	11.939
2713.29	12.1433
2715.98	13.6665
2718.67	14.1577
2721.35	14.2767
2724.04	15.0023
2726.72	14.7117
2729.4	14.7398
2732.09	14.3837
2734.77	13.5406
2737.45	13.1671
2740.13	11.8386
2742.81	11.5478
2745.48	10.3368
2748.16	9.10508
2750.84	7.83985
2753.51	7.25318
2756.19	6.86703
2758.86	5.65762
2761.53	5.73818
2764.2	5.11082
2766.87	4.82866
2769.54	5.2009
2772.21	5.23612
2774.88	4.57064
2777.54	4.13126
2780.21	3.97535
2782.87	3.16044
2785.53	2.65457
2788.2	2.39454
2790.86	1.59323
2793.52	1.9934
2796.18	1.28764
2798.84	0.00776492
2801.49	-0.548339
2804.15	-1.59684
2806.81	-1.63088
2809.46	-0.383894
2812.12	-1.06138
2814.77	-0.508753
2817.42	0.8094
2820.07	3.34039
2822.72	4.44971
2825.37	6.99298
2828.02	11.026
2830.67	13.7835
2833.31	17.8055
2835.96	21.9994
2838.61	26.0757
2841.25	30.4196
2843.89	36.2411
2846.53	42.3416
2849.17	49.5275
2851.81	56.9826
2854.45	64.8639
2857.09	73.0349
2859.73	80.6677
2862.36	87.5437
2865	94.4226
2867.64	100.493
2870.27	106.505
2872.9	111.549
2875.53	116.935
2878.16	121.588
2880.79	125.826
2883.42	129.088
2886.05	133.18
2888.68	136.781
2891.3	141.183
2893.93	145.441
2896.55	150.147
2899.18	155.782
2901.8	160.699
2904.42	167.874
2907.04	176.631
2909.66	186.546
2912.28	195.208
2914.9	206.258
2917.51	216.009
2920.13	225.16
2922.74	232.559
2925.36	237.86
2927.97	241.506
2930.59	243.482
2933.2	243.757
2935.81	241.385
2938.42	237.61
2941.02	232.322
2943.63	224.296
2946.24	214.719
2948.85	204.5
2951.45	194.951
2954.05	184.301
2956.66	173.557
2959.26	162.489
2961.86	151.578
2964.46	142.651
2967.06	134.46
2969.66	128.14
2972.26	121.551
2974.85	115.299
2977.45	109.095
2980.05	103.124
2982.64	96.5864
2985.23	90.1635
2987.83	83.4464
2990.42	76.0961
2993.01	69.6736
2995.6	62.4392
2998.19	54.8985
3000.77	48.8085
3003.36	41.6711
3005.95	35.42
3008.53	28.5803
3011.12	22.6262
3013.7	17.7752
3016.28	13.4559
3018.86	9.42908
3021.44	5.91865
3024.02	2.88602
3026.6	1.48057
3029.18	0.602125
3031.76	0.681955
3034.33	-0.212587
3036.91	-0.4647
3039.48	-0.200337
3042.05	-0.422846
3044.63	0.708081
3047.2	2.03542
3049.77	1.87609
3052.34	2.0265
3054.91	1.6858
3057.48	1.84498
3060.04	1.95034
3062.61	3.04977
3065.17	3.35206
3067.74	3.25929
3070.3	3.5855
3072.87	3.15359
3075.43	2.23953
3077.99	1.95628
3080.55	2.05523
3083.11	1.53979
3085.67	1.47651
3088.22	0.850559
3090.78	1.05565
3093.34	0.979449
3095.89	1.82846
3098.44	2.30341
3101	3.09598
3103.55	4.32882
3106.1	4.91883
3108.65	6.5242
3111.2	7.39781
3113.75	8.85152
3116.3	10.5089
3118.84	12.6727
3121.39	14.7411
3123.93	16.6125
3126.48	18.7455
3129.02	20.499
3131.56	23.1043
3134.1	23.8533
3136.64	24.8638
3139.18	27.0284
3141.72	28.8159
3144.26	29.5719
3146.8	29.9105
3149.33	29.8179