File: data/Raman/poly_smoothed/Mbcal_20_25_12_1x_45s_532 nm_x100_100%_600 gr_mm_01.txt
#Acq. time (s)=	45
#Accumulations=	2
#Range (cm-¹)=	200...3150
#Windows=	2
#Auto scanning=	Off
#Autofocus=	Off
#Macrospot=	Off
#AutoExposure=	Off
#Spike filter=	Multiple accum.
#Delay time (s)=	0
#Binning=	1
#Readout mode=	Signal
#DeNoise=	Off
#ICS correction=	On
#Dark correction=	Off
#Inst. Process=	Off
#Detector Gain=	Best Dynamic Range
#Detector ADC=	20 kHz
#Detector temperature (°C)=	-69.85
#Instrument=	LabRAM HR Evol
#Detector=	Synapse
#Objective=	x100
#Grating=	600 gr/mm
#ND Filter=	100%
#Laser (nm)=	532
#Hole=	100.021
#Range=	Auto
#Laser Pol.=	No
#Raman. Pol.=	No
#Laser Pol. (°)=	-0.0007625
#Raman Pol. (°)=	89.9995
#Collection=	Microscope
#StageXY=	Marzhauser
#StageZ=	Marzhauser
#X (µm)=	-1198.9
#Y (µm)=	1242.3
#Z (µm)=	577.9
#Full time(mm:ss)=	3:18
#Project=
#Sample=
#Site=
#Title=	Mbcal_20_25_12_2x_45s_532 nm_x100_100%_600 gr_mm
#Remark=
#Date=	18.07.2022 10:17
#Acquired=	18.07.2022 10:17:30
#Base:Fit=	10.08.2022 10:55:08
#Base:Sub=	10.08.2022 10:55:14
#Filter:Polynom=	16.08.2022 10:07:28
#AxisType[0]=Intens
#AxisUnit[0]=Cnt
#AxisType[1]=Spectr
#AxisUnit[1]=1/cm
200.419	28.6039
204.048	19.8218
207.678	15.1557
211.304	12.1352
214.928	9.5822
218.554	7.49468
222.176	5.84567
225.798	4.74924
229.417	3.79305
233.035	2.42867
236.653	2.17912
240.268	1.34204
243.881	0.283711
247.493	1.37613
251.103	2.53441
254.715	1.38838
258.322	2.28902
261.929	3.50088
265.534	2.5305
269.137	4.17771
272.739	5.11843
276.34	4.24923
279.939	4.05851
283.537	4.79047
287.134	3.53047
290.729	3.84396
294.323	3.5649
297.913	4.68855
301.504	4.12356
305.093	4.56118
308.682	2.56227
312.268	3.38835
315.852	2.76516
319.436	4.70114
323.018	4.3684
326.597	4.18297
330.177	4.08794
333.753	3.38732
337.331	6.59999
340.906	4.62576
344.478	5.30846
348.051	7.1591
351.621	7.94005
355.189	7.07426
358.757	8.15512
362.323	7.65391
365.889	6.17138
369.451	6.26175
373.012	4.16182
376.574	4.90405
380.133	4.4382
383.69	4.69415
387.245	3.98102
390.8	6.13305
394.353	5.05876
397.906	5.12285
401.456	6.62152
405.005	6.35681
408.552	7.2985
412.099	8.11092
415.643	6.43323
419.187	7.48497
422.728	8.98282
426.269	8.38485
429.806	7.3647
433.344	7.98858
436.881	7.28656
440.416	6.16974
443.949	5.18183
447.48	3.93421
451.011	3.58111
454.541	3.21195
458.069	3.15272
461.594	3.41477
465.119	4.50574
468.642	4.93477
472.165	5.38927
475.684	7.055
479.204	8.26087
482.721	8.6025
486.239	10.3674
489.753	11.2904
493.268	12.4835
496.779	15.6962
500.289	15.1281
503.8	16.3495
507.307	17.6894
510.813	20.0234
514.32	20.387
517.823	22.3975
521.325	24.5904
524.826	23.858
528.325	26.2104
531.823	26.7657
535.32	26.3294
538.815	25.1128
542.309	24.9284
545.802	24.7188
549.293	22.9419
552.783	20.7753
556.271	19.5356
559.759	18.6957
563.245	17.1402
566.729	16.2209
570.213	14.6018
573.693	11.6569
577.173	8.96766
580.652	7.22966
584.13	6.1697
587.605	4.57148
591.08	5.2798
594.552	5.25692
598.025	6.28296
601.496	6.88421
604.964	7.59659
608.433	7.90431
611.898	9.07015
615.364	10.9781
618.827	10.0106
622.288	11.1419
625.75	11.2049
629.209	12.8876
632.667	14.6034
636.125	13.9213
639.58	15.8237
643.033	15.4055
646.485	14.8398
649.936	14.2478
653.388	12.6181
656.836	11.5865
660.283	10.2094
663.728	9.47842
667.173	8.79705
670.616	7.31328
674.057	7.92089
677.498	8.58857
680.937	7.81661
684.375	9.01145
687.809	11.3737
691.244	12.6004
694.678	15.5464
698.111	20.1713
701.54	20.3392
704.97	24.1657
708.398	26.3363
711.826	29.2372
715.25	32.662
718.675	34.9133
722.096	36.4158
725.518	37.9778
728.937	38.5807
732.357	39.3418
735.773	40.648
739.19	41.2046
742.604	42.4153
746.018	42.3742
749.429	42.6305
752.839	43.1195
756.248	44.4598
759.657	46.6464
763.063	49.8119
766.468	52.1058
769.871	54.5485
773.273	57.3649
776.676	57.6641
780.075	58.7802
783.474	60.8208
786.871	59.982
790.266	61.479
793.661	62.797
797.054	63.6881
800.446	65.0157
803.834	66.1351
807.224	67.9064
810.612	67.7735
813.998	64.5583
817.384	63.1458
820.766	63.1836
824.149	64.235
827.531	64.971
830.909	66.3108
834.288	69.3133
837.666	73.3023
841.041	75.6965
844.416	75.0571
847.788	74.2986
851.161	73.232
854.53	72.4825
857.901	71.0616
861.268	68.3088
864.633	66.2147
868	62.2357
871.363	59.1469
874.725	57.042
878.088	52.4613
881.447	47.4946
884.805	43.8609
888.162	39.1879
891.518	33.5046
894.872	29.0334
898.225	26.5265
901.577	25.836
904.928	25.6308
908.277	26.4197
911.625	27.8912
914.972	29.2692
918.318	31.1128
921.662	31.7338
925.005	31.4598
928.347	30.6946
931.686	30.9325
935.025	30.8832
938.363	29.7354
941.698	29.5973
945.034	27.1571
948.368	23.8293
951.699	22.4211
955.031	19.3561
958.36	17.0289
961.689	16.4856
965.016	15.3644
968.343	13.8447
971.666	12.4472
974.991	12.9249
978.312	12.8032
981.632	10.9769
984.953	10.7947
988.27	9.56475
991.587	10.9072
994.902	11.5636
998.216	12.0293
1001.53	11.2589
1004.84	11.3958
1008.15	10.168
1011.46	11.122
1014.77	10.9265
1018.07	11.4745
1021.38	11.7528
1024.68	14.1261
1027.99	14.4746
1031.29	13.7474
1034.59	14.8133
1037.89	13.4641
1041.18	16.3818
1044.48	15.4
1047.77	14.8556
1051.07	14.5487
1054.36	14.8085
1057.65	13.5394
1060.94	9.92296
1064.23	9.13018
1067.52	7.18176
1070.8	6.96873
1074.09	5.8443
1077.37	5.23594
1080.65	3.25876
1083.93	3.78847
1087.21	4.01545
1090.49	5.35138
1093.77	7.56752
1097.04	7.79014
1100.32	8.75041
1103.59	10.1769
1106.86	10.6113
1110.13	9.41465
1113.4	8.86121
1116.67	8.83885
1119.94	8.74942
1123.2	9.24427
1126.47	8.83894
1129.73	10.6848
1132.99	9.78817
1136.25	10.0769
1139.51	9.61246
1142.77	10.7682
1146.03	10.8318
1149.28	10.9217
1152.54	10.5136
1155.79	7.90719
1159.04	8.25227
1162.29	7.88992
1165.54	8.54515
1168.79	9.1275
1172.04	8.46322
1175.28	6.29171
1178.53	5.14754
1181.77	5.37775
1185.01	5.41116
1188.25	4.06415
1191.49	4.19195
1194.73	5.39336
1197.96	7.49653
1201.2	10.6459
1204.43	13.6971
1207.66	17.5634
1210.9	19.5495
1214.13	21.8279
1217.36	25.4857
1220.58	28.5064
1223.81	29.9785
1227.04	32.3596
1230.26	34.3185
1233.48	34.6425
1236.71	34.7779
1239.93	36.9948
1243.14	36.8
1246.36	37.1469
1249.58	36.365
1252.8	35.6401
1256.01	36.6577
1259.22	35.3307
1262.43	37.5546
1265.64	37.9516
1268.85	38.8157
1272.06	39.8594
1275.27	41.4772
1278.48	44.306
1281.68	46.7989
1284.88	47.5201
1288.08	49.8031
1291.28	52.0908
1294.48	56.7677
1297.68	58.2236
1300.88	59.9157
1304.07	63.5203
1307.27	64.98
1310.46	65.0575
1313.65	66.2566
1316.85	69.1369
1320.03	71.1777
1323.22	72.2973
1326.41	72.6259
1329.6	74.5284
1332.78	74.4733
1335.96	76.1913
1339.15	77.0423
1342.33	78.8706
1345.51	78.879
1348.69	79.2125
1351.86	78.9494
1355.04	78.1249
1358.21	76.8709
1361.39	73.2011
1364.56	72.185
1367.73	69.6848
1370.9	66.4302
1374.07	62.8827
1377.24	57.6722
1380.41	54.1055
1383.57	51.1649
1386.73	49.2218
1389.9	47.4368
1393.06	46.0499
1396.22	44.2435
1399.38	45.2681
1402.54	45.9172
1405.69	46.792
1408.85	49.2647
1412	54.6559
1415.16	58.4709
1418.31	64.4723
1421.46	70.6647
1424.61	76.4417
1427.76	83.5332
1430.9	89.0579
1434.05	94.8269
1437.2	97.7189
1440.34	101.119
1443.48	104.928
1446.62	104.986
1449.76	106.653
1452.9	107.642
1456.04	108.817
1459.17	110.772
1462.31	114.562
1465.44	117.633
1468.58	119.634
1471.71	122.782
1474.84	124.73
1477.97	125.401
1481.1	123.752
1484.22	121.144
1487.35	117.946
1490.47	113.574
1493.59	110.135
1496.72	106.807
1499.84	100.329
1502.96	95.0517
1506.08	86.6631
1509.19	79.9596
1512.31	72.0326
1515.42	62.3498
1518.54	56.226
1521.65	50.5506
1524.76	43.7991
1527.87	40.145
1530.98	37.5986
1534.09	36.7617
1537.2	37.9251
1540.3	40.1794
1543.41	40.3647
1546.51	41.7225
1549.61	43.2416
1552.71	43.7678
1555.81	43.871
1558.91	44.8489
1562.01	45.1294
1565.1	46.9708
1568.2	47.8734
1571.29	49.4672
1574.38	51.4926
1577.48	54.3378
1580.57	56.4682
1583.65	58.2736
1586.74	60.9077
1589.83	61.7277
1592.92	63.9532
1596	65.7126
1599.08	65.1874
1602.16	65.1737
1605.24	64.2889
1608.32	62.0402
1611.4	59.4767
1614.48	57.1838
1617.56	55.4089
1620.63	53.5688
1623.71	52.576
1626.78	52.5187
1629.85	51.9325
1632.92	51.686
1635.99	52.5146
1639.06	53.3683
1642.12	55.4941
1645.19	57.6537
1648.25	59.2592
1651.32	61.7428
1654.38	63.6679
1657.44	62.7257
1660.5	63.4369
1663.56	61.2821
1666.62	59.3904
1669.67	55.6807
1672.73	52.975
1675.79	49.2384
1678.84	46.4382
1681.89	40.5913
1684.94	36.5631
1687.99	32.1665
1691.04	27.8224
1694.08	23.848
1697.13	18.8446
1700.18	16.3189
1703.22	13.5619
1706.26	11.831
1709.3	9.62221
1712.35	7.9199
1715.39	7.50805
1718.42	7.1275
1721.46	7.32139
1724.5	6.89775
1727.53	6.52695
1730.56	4.78745
1733.6	5.08151
1736.63	3.7334
1739.66	2.8557
1742.69	2.612
1745.71	3.29549
1748.74	3.66856
1751.77	3.76148
1754.79	3.60407
1757.81	3.48982
1760.84	3.56261
1763.86	3.26696
1766.88	2.40048
1769.9	3.07803
1772.91	3.95561
1775.93	3.70734
1778.95	3.23143
1781.96	3.66478
1784.97	3.90796
1787.99	4.26704
1791	4.98885
1794.01	5.32607
1797.01	5.34118
1800.02	4.99827
1803.03	4.4058
1806.03	5.40371
1809.04	5.0508
1812.04	4.61658
1815.04	5.06054
1818.04	5.23684
1821.04	5.85444
1824.04	5.59462
1827.04	5.42339
1830.03	5.81222
1833.03	6.43047
1836.02	6.84626
1839.02	5.35499
1842.01	5.52412
1845	5.43384
1847.99	5.30465
1850.98	4.90923
1853.96	4.77737
1856.95	5.35374
1859.94	6.25256
1862.92	5.56302
1865.9	5.60619
1868.88	5.24649
1871.86	5.46881
1874.84	4.45651
1877.82	4.62607
1880.8	4.30111
1882.58	4.45946
1885.57	5.42918
1888.56	6.68882
1891.54	6.78631
1894.53	6.46789
1897.51	6.29015
1900.5	5.70909
1903.48	6.19895
1906.46	7.31379
1909.44	6.43228
1912.42	7.25661
1915.4	7.60403
1918.37	7.32802
1921.35	7.06559
1924.32	6.83611
1927.3	6.87408
1930.27	7.49759
1933.24	5.5175
1936.21	4.02737
1939.18	3.94505
1942.15	4.29328
1945.11	4.29186
1948.08	4.33259
1951.04	4.59103
1954.01	4.17738
1956.97	5.43662
1959.93	5.30358
1962.89	5.35358
1965.85	3.90516
1968.81	4.00167
1971.77	3.87738
1974.72	4.34722
1977.68	4.51923
1980.63	4.10245
1983.58	3.63245
1986.53	3.6167
1989.48	3.28667
1992.43	4.02234
1995.38	3.00908
1998.33	2.47051
2001.27	1.44323
2004.22	0.619198
2007.16	1.16545
2010.11	2.18413
2013.05	3.50463
2015.99	3.51926
2018.93	3.72956
2021.87	3.51803
2024.8	4.13135
2027.74	4.29873
2030.68	5.31211
2033.61	5.06961
2036.54	4.97392
2039.48	5.54333
2042.41	5.77677
2045.34	4.87743
2048.27	5.65052
2051.19	6.16534
2054.12	6.68621
2057.05	7.75927
2059.97	7.95681
2062.9	6.51107
2065.82	6.8304
2068.74	5.9868
2071.66	5.48884
2074.58	5.56361
2077.5	5.99376
2080.41	5.83059
2083.33	6.13462
2086.24	5.64286
2089.16	5.78664
2092.07	6.12665
2094.98	7.23533
2097.89	8.46385
2100.8	9.45742
2103.71	10.8093
2106.62	11.3156
2109.53	13.5504
2112.43	15.2163
2115.33	17.0684
2118.24	19.0057
2121.14	20.8711
2124.04	22.3817
2126.94	24.0863
2129.84	24.5798
2132.74	26.6106
2135.63	28.1672
2138.53	30.3792
2141.43	32.2673
2144.32	34.5286
2147.21	36.0229
2150.1	37.3894
2152.99	39.3885
2155.88	41.9769
2158.77	43.4044
2161.66	45.2383
2164.55	46.6411
2167.43	47.0817
2170.31	48.0205
2173.2	48.4183
2176.08	49.404
2178.96	50.7497
2181.84	49.9159
2184.72	49.0604
2187.6	48.3449
2190.47	46.403
2193.35	45.0253
2196.23	44.074
2199.1	40.6577
2201.97	38.7938
2204.84	37.3453
2207.71	35.0173
2210.58	32.2223
2213.45	30.7015
2216.32	29.273
2219.19	26.4656
2222.05	24.4305
2224.92	22.5338
2227.78	19.6976
2230.64	19.073
2233.5	17.0079
2236.36	15.712
2239.22	14.5382
2242.08	14.0249
2244.94	13.2281
2247.79	13.1736
2250.65	12.1614
2253.5	11.8768
2256.36	12.1622
2259.21	11.4836
2262.06	11.9384
2264.91	12.2598
2267.76	11.735
2270.6	10.6811
2273.45	10.1656
2276.3	10.08
2279.14	9.02942
2281.98	8.57858
2284.83	7.58579
2287.67	7.39555
2290.51	5.22142
2293.35	3.56647
2296.19	2.93752
2299.02	4.84291
2301.86	4.97682
2304.7	5.58102
2307.53	5.93017
2310.36	7.40554
2313.2	8.19264
2316.03	8.8613
2318.86	8.69691
2321.69	9.3275
2324.51	10.7194
2327.34	10.5265
2330.17	10.4347
2332.99	10.6201
2335.82	9.58741
2338.64	8.35917
2341.46	7.59554
2344.28	7.04513
2347.1	6.44531
2349.92	5.4518
2352.74	4.23519
2355.56	4.37826
2358.37	3.87586
2361.19	3.47784
2364	3.59212
2366.82	4.22417
2369.63	4.03579
2372.44	4.02101
2375.25	3.02514
2378.06	3.39292
2380.86	2.69631
2383.67	1.98866
2386.48	1.7226
2389.28	2.74541
2392.09	1.89797
2394.89	2.10122
2397.69	2.83962
2400.49	2.93049
2403.29	3.41076
2406.09	3.37477
2408.89	5.22509
2411.69	5.99647
2414.48	6.61182
2417.28	6.85568
2420.07	7.39872
2422.86	8.05996
2425.65	8.38363
2428.45	8.89446
2431.23	8.64079
2434.02	7.20763
2436.81	6.72504
2439.6	6.25976
2442.38	5.82124
2445.17	4.73176
2447.95	3.6404
2450.73	2.65449
2453.52	2.52389
2456.3	3.71164
2459.08	3.26258
2461.85	3.06713
2464.63	4.66121
2467.41	4.71806
2470.19	5.01149
2472.96	4.53308
2475.73	5.69871
2478.51	6.00808
2481.28	4.06363
2484.05	3.92835
2486.82	4.73103
2489.59	4.62658
2492.35	5.16975
2495.12	5.22341
2497.89	5.76089
2500.65	5.79372
2503.42	4.7238
2506.18	4.94642
2508.94	3.71371
2511.7	3.88857
2514.46	3.89294
2517.22	3.12729
2519.98	3.73803
2522.73	5.05125
2525.49	5.99033
2528.25	6.38815
2531	6.90221
2533.75	6.50721
2536.5	5.73103
2539.25	5.94571
2542.01	5.98106
2544.75	6.44527
2547.5	5.70593
2550.25	6.40081
2553	7.36762
2555.74	8.02388
2558.49	8.41863
2561.23	9.36509
2563.97	9.69797
2566.71	9.32014
2569.45	8.89635
2572.19	9.16562
2574.93	8.53748
2577.67	8.76209
2580.4	10.0003
2583.14	10.3761
2585.87	10.5909
2588.6	11.3213
2591.34	11.236
2594.07	10.7498
2596.8	10.8272
2599.53	9.72396
2602.26	9.7505
2604.98	10.0085
2607.71	10.2163
2610.44	10.206
2613.16	10.2717
2615.88	10.6022
2618.61	11.2816
2621.33	10.6278
2624.05	10.8834
2626.77	11.6349
2629.49	11.556
2632.21	11.9036
2634.92	13.1633
2637.64	13.6349
2640.35	13.6924
2643.07	13.723
2645.78	14.3894
2648.49	14.4825
2651.2	14.1187
2653.91	13.6694
2656.62	13.7233
2659.33	13.9715
2662.04	15.0479
2664.74	14.3679
2667.45	14.5068
2670.15	15.2505
2672.86	15.7877
2675.56	16.224
2678.26	15.7615
2680.96	15.7136
2683.66	15.5472
2686.36	15.6964
2689.06	16.1182
2691.75	17.2553
2694.45	18.1133
2697.14	19.031
2699.84	20.5254
2702.53	20.4798
2705.22	20.1539
2707.91	20.4205
2710.6	20.3784
2713.29	19.5181
2715.98	19.2059
2718.67	19.4163
2721.35	19.6422
2724.04	20.6934
2726.72	20.3429
2729.4	19.7073
2732.09	18.5039
2734.77	18.1624
2737.45	17.978
2740.13	17.0376
2742.81	15.6736
2745.48	14.9252
2748.16	13.8547
2750.84	13.3749
2753.51	12.6555
2756.19	12.0387
2758.86	11.8741
2761.53	11.8093
2764.2	11.8712
2766.87	11.4227
2769.54	10.2566
2772.21	10.0184
2774.88	8.41266
2777.54	6.83113
2780.21	6.06997
2782.87	5.99654
2785.53	6.15704
2788.2	5.65212
2790.86	4.12076
2793.52	3.45302
2796.18	2.71246
2798.84	3.7774
2801.49	3.61779
2804.15	2.92026
2806.81	2.06513
2809.46	2.03202
2812.12	1.77911
2814.77	2.65532
2817.42	3.87492
2820.07	5.55513
2822.72	8.9517
2825.37	13.2092
2828.02	17.3998
2830.67	21.3739
2833.31	25.6995
2835.96	30.5907
2838.61	35.6419
2841.25	40.9316
2843.89	47.7948
2846.53	55.6313
2849.17	63.8498
2851.81	71.7672
2854.45	80.5024
2857.09	89.2303
2859.73	99.6578
2862.36	108.586
2865	117.612
2867.64	123.861
2870.27	130.455
2872.9	136.313
2875.53	141.763
2878.16	147.895
2880.79	152.667
2883.42	156.509
2886.05	161.555
2888.68	166.737
2891.3	171.501
2893.93	177.437
2896.55	182.774
2899.18	189.801
2901.8	197.705
2904.42	205.214
2907.04	214.747
2909.66	224.898
2912.28	236.625
2914.9	249.622
2917.51	261.039
2920.13	271.053
2922.74	279.977
2925.36	286.857
2927.97	291.247
2930.59	293.42
2933.2	292.666
2935.81	289.03
2938.42	283.221
2941.02	275.672
2943.63	265.846
2946.24	255.309
2948.85	243.969
2951.45	233.055
2954.05	220.625
2956.66	209.155
2959.26	198.482
2961.86	186.777
2964.46	176.726
2967.06	167.396
2969.66	157.654
2972.26	150.892
2974.85	145.257
2977.45	138.577
2980.05	132.042
2982.64	124.034
2985.23	115.961
2987.83	108.159
2990.42	100.093
2993.01	90.1688
2995.6	81.129
2998.19	71.8079
3000.77	61.6381
3003.36	52.591
3005.95	43.8324
3008.53	36.3032
3011.12	29.52
3013.7	22.7067
3016.28	16.8654
3018.86	11.9775
3021.44	8.98033
3024.02	4.69993
3026.6	2.27175
3029.18	1.03905
3031.76	-0.149009
3034.33	-0.456147
3036.91	0.0421381
3039.48	-0.47804
3042.05	0.0535351
3044.63	1.4625
3047.2	2.46545
3049.77	3.92424
3052.34	5.6435
3054.91	5.32979
3057.48	5.95621
3060.04	6.1273
3062.61	5.84099
3065.17	5.72904
3067.74	5.42668
3070.3	5.1781
3072.87	5.51025
3075.43	4.49972
3077.99	3.23334
3080.55	2.83915
3083.11	2.47014
3085.67	1.56456
3088.22	0.44856
3090.78	1.2161
3093.34	1.32881
3095.89	1.46666
3098.44	0.786456
3101	0.668341
3103.55	1.94574
3106.1	4.15245
3108.65	6.35887
3111.2	7.52922
3113.75	9.77674
3116.3	10.2763
3118.84	11.9912
3121.39	13.7097
3123.93	14.1516
3126.48	16.5226
3129.02	17.6962
3131.56	20.1304
3134.1	20.9725
3136.64	22.2298
3139.18	23.2619
3141.72	24.4588
3144.26	25.1449
3146.8	25.2995
3149.33	27.0694