File: data/Raman/poly_smoothed/Mbcal_20_25_02_1x_45s_532 nm_x100_100%_600 gr_mm_01.txt
#Acq. time (s)=	45
#Accumulations=	2
#Range (cm-¹)=	200...3150
#Windows=	2
#Auto scanning=	Off
#Autofocus=	Off
#Macrospot=	Off
#AutoExposure=	Off
#Spike filter=	Multiple accum.
#Delay time (s)=	0
#Binning=	1
#Readout mode=	Signal
#DeNoise=	Off
#ICS correction=	On
#Dark correction=	Off
#Inst. Process=	Off
#Detector Gain=	Best Dynamic Range
#Detector ADC=	20 kHz
#Detector temperature (°C)=	-69.85
#Instrument=	LabRAM HR Evol
#Detector=	Synapse
#Objective=	x100
#Grating=	600 gr/mm
#ND Filter=	100%
#Laser (nm)=	532
#Hole=	100.021
#Range=	Auto
#Laser Pol.=	No
#Raman. Pol.=	No
#Laser Pol. (°)=	-0.0007625
#Raman Pol. (°)=	89.9995
#Collection=	Microscope
#StageXY=	Marzhauser
#StageZ=	Marzhauser
#X (µm)=	-1207.3
#Y (µm)=	1272.8
#Z (µm)=	577.8
#Full time(mm:ss)=	3:18
#Project=
#Sample=
#Site=
#Title=	Mbcal_20_25_02_2x_45s_532 nm_x100_100%_600 gr_mm
#Remark=
#Date=	18.07.2022 09:33
#Acquired=	18.07.2022 09:33:25
#Base:Fit=	10.08.2022 10:55:08
#Base:Sub=	10.08.2022 10:55:14
#Filter:Polynom=	16.08.2022 09:24:11
#Filter:Polynom=	16.08.2022 10:07:27
#AxisType[0]=Intens
#AxisUnit[0]=Cnt
#AxisType[1]=Spectr
#AxisUnit[1]=1/cm
200.419	14.9351
204.048	15.1428
207.678	14.1028
211.304	12.6892
214.928	10.9258
218.554	14.746
222.176	15.3201
225.798	16.9413
229.417	19.9404
233.035	19.1917
236.653	16.8786
240.268	17.8888
243.881	17.4627
247.493	16.0638
251.103	15.1177
254.715	15.2674
258.322	15.2248
261.929	12.3995
265.534	10.2262
269.137	10.3398
272.739	9.85042
276.34	8.35413
279.939	8.88804
283.537	9.34824
287.134	5.94928
290.729	5.07359
294.323	4.66137
297.913	5.69236
301.504	8.67217
305.093	14.1656
308.682	17.4581
312.268	21.1678
315.852	26.2441
319.436	28.8278
323.018	30.4322
326.597	30.9605
330.177	34.0785
333.753	34.6924
337.331	34.9979
340.906	35.9517
344.478	35.2757
348.051	32.5813
351.621	32.6078
355.189	31.6765
358.757	29.0809
362.323	25.2972
365.889	21.9705
369.451	19.1737
373.012	17.5179
376.574	15.9342
380.133	18.7453
383.69	18.891
387.245	22.6911
390.8	25.9677
394.353	29.4931
397.906	33.0247
401.456	35.5797
405.005	38.1477
408.552	39.5932
412.099	40.6581
415.643	41.7209
419.187	46.6326
422.728	46.7825
426.269	46.806
429.806	45.7065
433.344	43.5902
436.881	44.0637
440.416	42.1294
443.949	38.7591
447.48	37.8439
451.011	37.7508
454.541	36.5586
458.069	37.1497
461.594	39.7074
465.119	38.9665
468.642	39.7271
472.165	41.1627
475.684	45.1306
479.204	47.5412
482.721	48.3363
486.239	50.7468
489.753	52.3235
493.268	55.0004
496.779	57.3601
500.289	59.8226
503.8	61.9767
507.307	67.7068
510.813	72.1368
514.32	74.2627
517.823	78.8631
521.325	81.3563
524.826	83.8564
528.325	84.436
531.823	85.4315
535.32	86.365
538.815	86.6588
542.309	85.2975
545.802	84.2453
549.293	83.517
552.783	80.3381
556.271	78.2163
559.759	75.8213
563.245	69.9685
566.729	62.9525
570.213	54.7964
573.693	48.1019
577.173	41.0476
580.652	34.0883
584.13	29.3672
587.605	23.5918
591.08	19.7399
594.552	15.9545
598.025	12.2279
601.496	9.7038
604.964	8.85744
608.433	7.30873
611.898	6.39706
615.364	7.66865
618.827	7.85352
622.288	10.926
625.75	14.4397
629.209	16.6291
632.667	22.2549
636.125	24.6126
639.58	24.537
643.033	26.5044
646.485	28.0285
649.936	26.7754
653.388	27.4718
656.836	26.3046
660.283	25.7163
663.728	24.1106
667.173	23.1674
670.616	21.5006
674.057	19.841
677.498	18.4748
680.937	17.523
684.375	17.5172
687.809	17.187
691.244	19.5357
694.678	20.2031
698.111	19.8632
701.54	21.2343
704.97	21.6807
708.398	20.795
711.826	20.3234
715.25	20.7106
718.675	20.3256
722.096	19.3666
725.518	19.5982
728.937	19.6451
732.357	17.528
735.773	15.7693
739.19	14.5669
742.604	13.7687
746.018	16.159
749.429	17.6946
752.839	19.0942
756.248	20.6686
759.657	21.8688
763.063	23.8475
766.468	24.8994
769.871	27.3569
773.273	31.0966
776.676	34.0677
780.075	37.1795
783.474	37.3211
786.871	38.0587
790.266	40.3329
793.661	41.9853
797.054	43.9941
800.446	44.6001
803.834	47.8967
807.224	50.315
810.612	49.6598
813.998	47.0383
817.384	48.6245
820.766	49.8283
824.149	54.008
827.531	59.1823
830.909	65.3032
834.288	72.8661
837.666	81.6703
841.041	88.3021
844.416	94.8022
847.788	99.3594
851.161	104.615
854.53	108.423
857.901	109.329
861.268	109.518
864.633	106.155
868	103.964
871.363	101.494
874.725	98.6359
878.088	89.003
881.447	80.1784
884.805	70.369
888.162	61.0783
891.518	50.0758
894.872	40.1373
898.225	30.7399
901.577	25.9052
904.928	23.4987
908.277	26.4441
911.625	27.8656
914.972	32.1556
918.318	35.2527
921.662	37.915
925.005	40.6272
928.347	42.5864
931.686	45.2259
935.025	46.999
938.363	45.2332
941.698	44.7501
945.034	45.1678
948.368	45.2054
951.699	43.2819
955.031	38.7747
958.36	34.8726
961.689	29.8605
965.016	28.8742
968.343	28.6659
971.666	29.6558
974.991	30.7025
978.312	30.6134
981.632	33.5254
984.953	35.6031
988.27	35.3363
991.587	35.8169
994.902	36.1285
998.216	38.0374
1001.53	38.2788
1004.84	39.4926
1008.15	39.6815
1011.46	43.4053
1014.77	46.7876
1018.07	49.6172
1021.38	53.645
1024.68	57.8378
1027.99	59.8716
1031.29	60.5953
1034.59	62.4181
1037.89	62.4238
1041.18	62.7156
1044.48	65.9687
1047.77	65.6214
1051.07	67.3467
1054.36	65.4767
1057.65	63.6227
1060.94	64.0986
1064.23	61.8148
1067.52	58.6503
1070.8	57.6696
1074.09	55.8755
1077.37	54.9015
1080.65	53.4942
1083.93	51.676
1087.21	50.5842
1090.49	53.1074
1093.77	57.7914
1097.04	62.0546
1100.32	66.4505
1103.59	68.788
1106.86	69.4427
1110.13	66.7259
1113.4	65.915
1116.67	63.8807
1119.94	58.4942
1123.2	56.6611
1126.47	53.5057
1129.73	50.0854
1132.99	48.137
1136.25	43.8447
1139.51	40.7337
1142.77	36.6424
1146.03	32.61
1149.28	28.9419
1152.54	23.6079
1155.79	18.0561
1159.04	11.2316
1162.29	6.47825
1165.54	2.82304
1168.79	3.82474
1172.04	6.18419
1175.28	10.3814
1178.53	12.8442
1181.77	13.0713
1185.01	13.6476
1188.25	13.9272
1191.49	16.2411
1194.73	18.8405
1197.96	22.5261
1201.2	27.4973
1204.43	37.0543
1207.66	41.8189
1210.9	48.6353
1214.13	57.6524
1217.36	63.651
1220.58	70.7826
1223.81	75.6516
1227.04	82.1499
1230.26	86.0368
1233.48	92.7934
1236.71	100.254
1239.93	103.784
1243.14	112.062
1246.36	119.963
1249.58	128.702
1252.8	134.368
1256.01	140.109
1259.22	143.707
1262.43	147.591
1265.64	151.806
1268.85	156.682
1272.06	163.536
1275.27	165.48
1278.48	173.312
1281.68	178.407
1284.88	182.869
1288.08	188.066
1291.28	192.218
1294.48	197.567
1297.68	199.584
1300.88	201.963
1304.07	203.481
1307.27	204.713
1310.46	207.876
1313.65	209.34
1316.85	207.643
1320.03	207.866
1323.22	211.06
1326.41	211.991
1329.6	212.743
1332.78	211.628
1335.96	209.509
1339.15	208.24
1342.33	206.148
1345.51	201.92
1348.69	197.764
1351.86	196.928
1355.04	191.934
1358.21	189.176
1361.39	184.22
1364.56	181.128
1367.73	174.15
1370.9	169.362
1374.07	165.709
1377.24	160.176
1380.41	155.531
1383.57	152.086
1386.73	150.478
1389.9	147.336
1393.06	144.469
1396.22	143.683
1399.38	145.267
1402.54	148.41
1405.69	151.985
1408.85	156.697
1412	167.438
1415.16	179.301
1418.31	194.447
1421.46	210.769
1424.61	226.942
1427.76	245.612
1430.9	261.352
1434.05	275.757
1437.2	290.474
1440.34	301.783
1443.48	308.871
1446.62	314.68
1449.76	315.463
1452.9	315.71
1456.04	309.686
1459.17	301.827
1462.31	292.163
1465.44	279.326
1468.58	263.504
1471.71	246.848
1474.84	228.565
1477.97	211.886
1481.1	194.385
1484.22	179.446
1487.35	166.268
1490.47	155.492
1493.59	145.606
1496.72	134.533
1499.84	125.919
1502.96	116.981
1506.08	110.4
1509.19	104.287
1512.31	101.609
1515.42	94.8289
1518.54	90.5814
1521.65	87.3456
1524.76	85.062
1527.87	83.9524
1530.98	81.6788
1534.09	81.3935
1537.2	81.2833
1540.3	83.6115
1543.41	82.9547
1546.51	87.0653
1549.61	90.6655
1552.71	94.2529
1555.81	99.1252
1558.91	101.409
1562.01	104.372
1565.1	108.295
1568.2	111.32
1571.29	114.728
1574.38	118.416
1577.48	123.575
1580.57	129.734
1583.65	135.462
1586.74	140.846
1589.83	147.216
1592.92	151.104
1596	154.447
1599.08	156.336
1602.16	157.634
1605.24	156.036
1608.32	154.514
1611.4	157.135
1614.48	158.428
1617.56	160.59
1620.63	161.83
1623.71	165.397
1626.78	168.168
1629.85	171.423
1632.92	175.685
1635.99	179.193
1639.06	183.974
1642.12	189.682
1645.19	194.503
1648.25	200.093
1651.32	204.648
1654.38	207.864
1657.44	208.8
1660.5	207.071
1663.56	205.323
1666.62	198.393
1669.67	189.105
1672.73	178.024
1675.79	165.601
1678.84	151.389
1681.89	136.886
1684.94	121.685
1687.99	106.514
1691.04	93.5926
1694.08	80.2291
1697.13	66.7739
1700.18	56.6205
1703.22	50.3016
1706.26	41.5539
1709.3	33.9338
1712.35	27.9366
1715.39	22.214
1718.42	19.9893
1721.46	16.206
1724.5	14.9396
1727.53	13.5127
1730.56	11.6752
1733.6	11.3092
1736.63	10.8417
1739.66	9.67341
1742.69	9.80158
1745.71	9.53243
1748.74	7.94103
1751.77	7.02946
1754.79	7.23794
1757.81	5.32864
1760.84	4.82615
1763.86	5.2294
1766.88	5.35961
1769.9	4.18976
1772.91	2.92066
1775.93	2.54129
1778.95	3.49375
1781.96	2.40474
1784.97	3.62209
1787.99	3.19396
1791	3.95369
1794.01	3.68722
1797.01	4.8138
1800.02	4.12279
1803.03	4.35257
1806.03	4.5968
1809.04	4.63139
1812.04	5.08579
1815.04	5.91259
1818.04	5.37292
1821.04	4.81353
1824.04	3.32182
1827.04	3.86856
1830.03	4.08764
1833.03	2.64595
1836.02	2.03587
1839.02	1.17811
1842.01	1.40433
1845	0.826596
1847.99	1.21346
1850.98	2.50252
1853.96	2.65526
1856.95	2.39252
1859.94	2.59765
1862.92	1.18637
1865.9	0.774668
1868.88	1.24632
1871.86	1.27427
1874.84	2.51864
1877.82	3.36654
1880.8	2.86753
1882.58	3.868
1885.57	3.53327
1888.56	4.76582
1891.54	4.00641
1894.53	4.65963
1897.51	5.04949
1900.5	6.02868
1903.48	6.17634
1906.46	4.9147
1909.44	5.51322
1912.42	5.50807
1915.4	6.06769
1918.37	5.73138
1921.35	7.43606
1924.32	5.63546
1927.3	4.64659
1930.27	4.88335
1933.24	3.94893
1936.21	3.16925
1939.18	5.20731
1942.15	4.92895
1945.11	4.8908
1948.08	3.90839
1951.04	4.02066
1954.01	2.92513
1956.97	2.62859
1959.93	3.26167
1962.89	2.94955
1965.85	1.9692
1968.81	2.72215
1971.77	0.515411
1974.72	0.947064
1977.68	0.612744
1980.63	-0.107073
1983.58	1.37674
1986.53	1.9777
1989.48	1.60226
1992.43	2.48378
1995.38	2.44571
1998.33	2.62597
2001.27	3.84724
2004.22	6.31234
2007.16	6.09615
2010.11	6.85137
2013.05	6.86259
2015.99	7.68132
2018.93	8.38241
2021.87	8.58501
2024.8	8.14123
2027.74	7.59173
2030.68	8.42786
2033.61	8.43812
2036.54	4.62967
2039.48	3.03334
2042.41	4.20751
2045.34	4.3649
2048.27	5.46332
2051.19	6.34555
2054.12	7.24622
2057.05	5.11338
2059.97	5.78191
2062.9	7.66723
2065.82	8.99886
2068.74	11.2417
2071.66	12.762
2074.58	14.9744
2077.5	16.7937
2080.41	17.9266
2083.33	20.3707
2086.24	22.1376
2089.16	23.8753
2092.07	25.4383
2094.98	28.1678
2097.89	29.8914
2100.8	31.9853
2103.71	32.7383
2106.62	34.9909
2109.53	35.674
2112.43	38.0406
2115.33	39.1994
2118.24	40.728
2121.14	45.0432
2124.04	49.2613
2126.94	51.3524
2129.84	55.8657
2132.74	60.9574
2135.63	65.2277
2138.53	71.4152
2141.43	78.3324
2144.32	82.6224
2147.21	89.1984
2150.1	96.6023
2152.99	101.972
2155.88	108.866
2158.77	114.495
2161.66	119.608
2164.55	125.102
2167.43	130.028
2170.31	132.009
2173.2	135.203
2176.08	135.634
2178.96	135.193
2181.84	133.336
2184.72	131.192
2187.6	129.356
2190.47	127.885
2193.35	122.936
2196.23	118.514
2199.1	111.598
2201.97	106.456
2204.84	101.688
2207.71	97.0493
2210.58	90.5339
2213.45	85.021
2216.32	77.0076
2219.19	71.4278
2222.05	64.3351
2224.92	59.6106
2227.78	54.9598
2230.64	49.9724
2233.5	46.131
2236.36	44.3043
2239.22	40.4102
2242.08	38.2486
2244.94	35.1732
2247.79	33.4143
2250.65	31.5127
2253.5	30.2555
2256.36	28.3414
2259.21	27.2491
2262.06	25.9459
2264.91	25.1912
2267.76	25.6931
2270.6	23.62
2273.45	22.2864
2276.3	19.6006
2279.14	18.5631
2281.98	16.3948
2284.83	14.4134
2287.67	11.6324
2290.51	9.19162
2293.35	6.85451
2296.19	7.22907
2299.02	5.86835
2301.86	6.74089
2304.7	6.73324
2307.53	6.46058
2310.36	5.76775
2313.2	6.40566
2316.03	5.72236
2318.86	6.46322
2321.69	4.36914
2324.51	5.42865
2327.34	6.61317
2330.17	6.83903
2332.99	6.09719
2335.82	6.76004
2338.64	5.62486
2341.46	5.28386
2344.28	6.41181
2347.1	6.33574
2349.92	5.2552
2352.74	3.54434
2355.56	2.61852
2358.37	1.86843
2361.19	2.24217
2364	2.68054
2366.82	4.87906
2369.63	4.47793
2372.44	5.35161
2375.25	4.28966
2378.06	5.34357
2380.86	5.08965
2383.67	4.7661
2386.48	3.97454
2389.28	2.70603
2392.09	3.31489
2394.89	3.96813
2397.69	3.60125
2400.49	2.95495
2403.29	3.19364
2406.09	2.07697
2408.89	2.16249
2411.69	3.32228
2414.48	2.2616
2417.28	1.55611
2420.07	0.44452
2422.86	2.24666
2425.65	2.40176
2428.45	2.03034
2431.23	2.61632
2434.02	2.4607
2436.81	3.64334
2439.6	4.07794
2442.38	4.45847
2445.17	5.22862
2447.95	6.16265
2450.73	6.70938
2453.52	6.9821
2456.3	6.45448
2459.08	6.75061
2461.85	6.7834
2464.63	5.64295
2467.41	4.43268
2470.19	3.61388
2472.96	2.6224
2475.73	1.79637
2478.51	2.43988
2481.28	1.91292
2484.05	0.828528
2486.82	0.386876
2489.59	1.73168
2492.35	3.6051
2495.12	3.62399
2497.89	4.42957
2500.65	5.75902
2503.42	6.37839
2506.18	7.3437
2508.94	7.34349
2511.7	8.6624
2514.46	8.66706
2517.22	7.90522
2519.98	7.65277
2522.73	8.04944
2525.49	7.54664
2528.25	7.61723
2531	6.11653
2533.75	6.60508
2536.5	5.58015
2539.25	5.79911
2542.01	4.63446
2544.75	5.08088
2547.5	4.78535
2550.25	3.42356
2553	2.93988
2555.74	4.7698
2558.49	5.12979
2561.23	5.48681
2563.97	5.00736
2566.71	5.18253
2569.45	5.35907
2572.19	5.45276
2574.93	6.01983
2577.67	6.99957
2580.4	7.11721
2583.14	6.41264
2585.87	4.90483
2588.6	5.80405
2591.34	5.15676
2594.07	5.49004
2596.8	6.54618
2599.53	6.78946
2602.26	7.41723
2604.98	7.05576
2607.71	6.69225
2610.44	6.15284
2613.16	6.91455
2615.88	6.46802
2618.61	7.23313
2621.33	9.46871
2624.05	9.51011
2626.77	11.5625
2629.49	11.7325
2632.21	13.4998
2634.92	13.9886
2637.64	15.6853
2640.35	17.4596
2643.07	17.6706
2645.78	17.732
2648.49	17.1719
2651.2	16.753
2653.91	16.1962
2656.62	15.9764
2659.33	15.3323
2662.04	14.8289
2664.74	14.5972
2667.45	14.3518
2670.15	12.9627
2672.86	11.1936
2675.56	10.0462
2678.26	9.9678
2680.96	10.1845
2683.66	11.1655
2686.36	13.0751
2689.06	12.8405
2691.75	14.2618
2694.45	14.5571
2697.14	14.3708
2699.84	17.1816
2702.53	19.8417
2705.22	23.7395
2707.91	25.6816
2710.6	26.9914
2713.29	28.2145
2715.98	28.6007
2718.67	28.2553
2721.35	27.8941
2724.04	29.3687
2726.72	29.7611
2729.4	30.3232
2732.09	29.7338
2734.77	25.7441
2737.45	24.517
2740.13	23.2972
2742.81	22.9662
2745.48	21.5499
2748.16	21.2755
2750.84	20.9516
2753.51	19.865
2756.19	17.3199
2758.86	15.6263
2761.53	15.8518
2764.2	16.2331
2766.87	16.8781
2769.54	14.9802
2772.21	12.3607
2774.88	10.7076
2777.54	9.24191
2780.21	7.20022
2782.87	6.64579
2785.53	6.25587
2788.2	5.75872
2790.86	5.43135
2793.52	3.84935
2796.18	2.12082
2798.84	-0.434675
2801.49	-0.395476
2804.15	0.279455
2806.81	-0.336547
2809.46	-0.0875692
2812.12	-0.650158
2814.77	0.177762
2817.42	1.56403
2820.07	7.41696
2822.72	14.061
2825.37	23.0125
2828.02	33.4411
2830.67	43.4777
2833.31	54.5632
2835.96	67.3426
2838.61	82.3838
2841.25	97.847
2843.89	116.749
2846.53	137.639
2849.17	158.287
2851.81	180.754
2854.45	204.323
2857.09	228.116
2859.73	251.533
2862.36	275.068
2865	297.382
2867.64	316.861
2870.27	334.692
2872.9	350.261
2875.53	366.99
2878.16	382.307
2880.79	396.35
2883.42	410.407
2886.05	426.122
2888.68	440.922
2891.3	455.518
2893.93	469.65
2896.55	487.216
2899.18	504.306
2901.8	522.44
2904.42	544.399
2907.04	568.892
2909.66	598.327
2912.28	627.911
2914.9	657.57
2917.51	687.801
2920.13	714.333
2922.74	735.107
2925.36	753.495
2927.97	764.179
2930.59	768.921
2933.2	767.787
2935.81	759.681
2938.42	747.107
2941.02	728.539
2943.63	706.009
2946.24	679.833
2948.85	652.779
2951.45	624.283
2954.05	592.797
2956.66	561.295
2959.26	530.542
2961.86	502.776
2964.46	474.138
2967.06	449.68
2969.66	427.984
2972.26	410.511
2974.85	392.769
2977.45	374.799
2980.05	357.415
2982.64	337.572
2985.23	316.68
2987.83	294.46
2990.42	271.381
2993.01	247.184
2995.6	223.494
2998.19	198.569
3000.77	175.524
3003.36	151.987
3005.95	130.56
3008.53	110.659
3011.12	90.1376
3013.7	73.5581
3016.28	57.6403
3018.86	45.3921
3021.44	34.1872
3024.02	25.6905
3026.6	19.9973
3029.18	14.8301
3031.76	12.5417
3034.33	11.3967
3036.91	10.772
3039.48	11.8615
3042.05	11.9828
3044.63	13.7243
3047.2	14.6772
3049.77	14.791
3052.34	15.3072
3054.91	16.3284
3057.48	16.0657
3060.04	15.6994
3062.61	16.7895
3065.17	16.5242
3067.74	14.6142
3070.3	12.1775
3072.87	10.2043
3075.43	7.88368
3077.99	7.8375
3080.55	6.83042
3083.11	5.15941
3085.67	2.8136
3088.22	1.14011
3090.78	1.16747
3093.34	-0.0367371
3095.89	1.11489
3098.44	1.17916
3101	2.79376
3103.55	5.42291
3106.1	7.83346
3108.65	9.42111
3111.2	11.4035
3113.75	15.1033
3116.3	17.4819
3118.84	21.1938
3121.39	24.2815
3123.93	29.0696
3126.48	33.2038
3129.02	35.4754
3131.56	38.5521
3134.1	42.8117
3136.64	47.1954
3139.18	49.6997
3141.72	52.3513
3144.26	53.1618
3146.8	54.4581
3149.33	55.9069