File: data/Raman/poly_smoothed/Mbcal_20_25_33_1x_45s_532 nm_x100_100%_600 gr_mm_01.txt
#Acq. time (s)=	45
#Accumulations=	2
#Range (cm-¹)=	200...3150
#Windows=	2
#Auto scanning=	Off
#Autofocus=	Off
#Macrospot=	Off
#AutoExposure=	Off
#Spike filter=	Multiple accum.
#Delay time (s)=	0
#Binning=	1
#Readout mode=	Signal
#DeNoise=	Off
#ICS correction=	On
#Dark correction=	Off
#Inst. Process=	Off
#Detector Gain=	Best Dynamic Range
#Detector ADC=	20 kHz
#Detector temperature (°C)=	-69.85
#Instrument=	LabRAM HR Evol
#Detector=	Synapse
#Objective=	x100
#Grating=	600 gr/mm
#ND Filter=	100%
#Laser (nm)=	532
#Hole=	100.021
#Range=	Auto
#Laser Pol.=	No
#Raman. Pol.=	No
#Laser Pol. (°)=	-0.0007625
#Raman Pol. (°)=	89.9995
#Collection=	Microscope
#StageXY=	Marzhauser
#StageZ=	Marzhauser
#X (µm)=	-1130.3
#Y (µm)=	1290.4
#Z (µm)=	578.1
#Full time(mm:ss)=	3:18
#Project=
#Sample=
#Site=
#Title=	Mbcal_20_25_33_2x_45s_532 nm_x100_100%_600 gr_mm
#Remark=
#Date=	18.07.2022 12:31
#Acquired=	18.07.2022 12:31:33
#Base:Fit=	10.08.2022 10:55:08
#Base:Sub=	10.08.2022 10:55:14
#Filter:Polynom=	16.08.2022 10:07:28
#AxisType[0]=Intens
#AxisUnit[0]=Cnt
#AxisType[1]=Spectr
#AxisUnit[1]=1/cm
200.419	19.6416
204.048	15.9691
207.678	14.1634
211.304	13.841
214.928	13.8549
218.554	13.2053
222.176	12.6626
225.798	13.16
229.417	14.1832
233.035	13.7324
236.653	13.0549
240.268	12.7555
243.881	13.2438
247.493	13.0166
251.103	12.2929
254.715	10.816
258.322	11.6971
261.929	12.0491
265.534	12.8207
269.137	10.8437
272.739	10.7931
276.34	8.55669
279.939	8.54734
283.537	6.22898
287.134	3.15272
290.729	3.04485
294.323	6.52545
297.913	7.51264
301.504	10.1423
305.093	11.5113
308.682	14.5416
312.268	15.8893
315.852	17.7471
319.436	18.2744
323.018	17.2735
326.597	16.8606
330.177	16.1398
333.753	16.2641
337.331	18.355
340.906	15.5986
344.478	16.0403
348.051	15.8299
351.621	13.1391
355.189	13.1957
358.757	11.2534
362.323	8.34161
365.889	4.90051
369.451	3.2118
373.012	0.824087
376.574	0.69417
380.133	2.67877
383.69	6.13356
387.245	9.10929
390.8	11.92
394.353	13.702
397.906	15.1554
401.456	16.4444
405.005	17.5743
408.552	19.6618
412.099	20.1953
415.643	23.0404
419.187	25.8873
422.728	26.8281
426.269	26.2862
429.806	26.0073
433.344	26.8125
436.881	23.6012
440.416	23.6239
443.949	23.1675
447.48	22.365
451.011	20.3101
454.541	18.8561
458.069	18.1958
461.594	19.4701
465.119	21.994
468.642	24.0635
472.165	25.8221
475.684	25.564
479.204	26.9823
482.721	28.0814
486.239	28.3584
489.753	30.9875
493.268	34.4181
496.779	37.6149
500.289	38.2198
503.8	39.8942
507.307	42.4143
510.813	44.1702
514.32	46.8816
517.823	51.4366
521.325	56.0946
524.826	59.2071
528.325	62.0658
531.823	64.645
535.32	65.9044
538.815	66.5947
542.309	66.6917
545.802	66.5608
549.293	66.2261
552.783	63.1978
556.271	60.2961
559.759	55.326
563.245	52.5471
566.729	49.0788
570.213	44.1262
573.693	37.9497
577.173	31.9361
580.652	24.9891
584.13	20.5384
587.605	16.4376
591.08	12.4391
594.552	10.9179
598.025	10.8995
601.496	11.3437
604.964	10.8328
608.433	9.7015
611.898	10.1543
615.364	10.708
618.827	11.43
622.288	14.6896
625.75	16.7807
629.209	20.3589
632.667	21.0935
636.125	22.042
639.58	22.9481
643.033	25.8761
646.485	25.9474
649.936	24.1795
653.388	22.9084
656.836	21.6946
660.283	20.6918
663.728	18.2056
667.173	15.8741
670.616	15.3413
674.057	14.7316
677.498	14.8925
680.937	16.1731
684.375	15.5157
687.809	14.2547
691.244	13.0851
694.678	14.2021
698.111	14.6491
701.54	16.9227
704.97	18.2164
708.398	19.2507
711.826	19.7184
715.25	19.8621
718.675	19.7869
722.096	19.2991
725.518	20.4916
728.937	19.1101
732.357	17.8173
735.773	19.6119
739.19	20.8223
742.604	23.6986
746.018	24.9368
749.429	28.8157
752.839	32.2211
756.248	34.7309
759.657	36.6234
763.063	39.1778
766.468	39.5439
769.871	40.7634
773.273	40.7691
776.676	44.0817
780.075	45.5117
783.474	46.0133
786.871	45.7764
790.266	44.734
793.661	45.6968
797.054	46.6667
800.446	47.6428
803.834	47.3501
807.224	48.422
810.612	49.0976
813.998	49.2581
817.384	51.139
820.766	51.7347
824.149	57.3354
827.531	63.3522
830.909	69.5736
834.288	76.9618
837.666	84.6253
841.041	90.878
844.416	97.6622
847.788	101.259
851.161	100.843
854.53	102.751
857.901	103.676
861.268	103.574
864.633	99.3806
868	95.349
871.363	90.5033
874.725	85.775
878.088	78.7174
881.447	70.7349
884.805	60.3166
888.162	49.0179
891.518	41.4443
894.872	31.2625
898.225	25.1242
901.577	21.4253
904.928	21.3348
908.277	23.7752
911.625	25.918
914.972	28.856
918.318	33.6335
921.662	36.5247
925.005	39.0721
928.347	41.0947
931.686	41.6701
935.025	43.1942
938.363	43.3021
941.698	43.982
945.034	42.1442
948.368	38.8169
951.699	40.1647
955.031	37.7073
958.36	35.402
961.689	28.4379
965.016	26.0035
968.343	24.8825
971.666	25.6748
974.991	26.5865
978.312	27.7673
981.632	29.4904
984.953	31.9927
988.27	31.1842
991.587	33.3318
994.902	33.0832
998.216	35.2515
1001.53	36.8942
1004.84	36.587
1008.15	38.1333
1011.46	39.4589
1014.77	41.5829
1018.07	44.8438
1021.38	46.0283
1024.68	49.6722
1027.99	54.3003
1031.29	58.3782
1034.59	59.4699
1037.89	58.7986
1041.18	59.0794
1044.48	59.9259
1047.77	62.1573
1051.07	59.677
1054.36	57.357
1057.65	53.6438
1060.94	52.0019
1064.23	49.9051
1067.52	45.3965
1070.8	41.5234
1074.09	39.5818
1077.37	38.8763
1080.65	36.415
1083.93	34.4181
1087.21	34.6597
1090.49	36.9165
1093.77	40.411
1097.04	44.2262
1100.32	46.5004
1103.59	49.945
1106.86	52.6099
1110.13	51.9704
1113.4	51.0138
1116.67	49.6004
1119.94	47.9175
1123.2	43.9246
1126.47	39.9055
1129.73	36.8951
1132.99	33.8391
1136.25	29.3355
1139.51	27.7118
1142.77	25.2104
1146.03	19.409
1149.28	12.8825
1152.54	11.3945
1155.79	9.66714
1159.04	6.83833
1162.29	2.85639
1165.54	3.2938
1168.79	3.01844
1172.04	5.62821
1175.28	7.54615
1178.53	9.05254
1181.77	11.4473
1185.01	13.9175
1188.25	12.2932
1191.49	14.7841
1194.73	17.2025
1197.96	22.3416
1201.2	25.7158
1204.43	29.7245
1207.66	34.6897
1210.9	39.1171
1214.13	45.8585
1217.36	50.5549
1220.58	56.1568
1223.81	61.4869
1227.04	64.0475
1230.26	70.9934
1233.48	77.2748
1236.71	83.4642
1239.93	90.4027
1243.14	95.6045
1246.36	101.432
1249.58	105.692
1252.8	109.123
1256.01	112.662
1259.22	116.114
1262.43	120.886
1265.64	125.098
1268.85	127.333
1272.06	133.474
1275.27	137.824
1278.48	142.617
1281.68	146.791
1284.88	150.635
1288.08	154.972
1291.28	158.623
1294.48	162.223
1297.68	164.207
1300.88	166.972
1304.07	168.532
1307.27	171.354
1310.46	174.042
1313.65	178.377
1316.85	179.669
1320.03	178.613
1323.22	177.252
1326.41	175.344
1329.6	172.294
1332.78	169.661
1335.96	169.418
1339.15	167.129
1342.33	164.054
1345.51	158.413
1348.69	153.713
1351.86	149.801
1355.04	148.134
1358.21	145.382
1361.39	140.042
1364.56	135.335
1367.73	130.719
1370.9	128.254
1374.07	124.821
1377.24	121.705
1380.41	118.87
1383.57	118.14
1386.73	116.603
1389.9	115.823
1393.06	117.036
1396.22	116.21
1399.38	118.799
1402.54	121.873
1405.69	129.23
1408.85	137.232
1412	145.553
1415.16	156.032
1418.31	168.443
1421.46	183.259
1424.61	196.741
1427.76	214.673
1430.9	230.677
1434.05	245.683
1437.2	257.303
1440.34	267.239
1443.48	275.757
1446.62	280.076
1449.76	280.331
1452.9	278.805
1456.04	274.678
1459.17	268.532
1462.31	261.567
1465.44	252.381
1468.58	242.286
1471.71	229.927
1474.84	215.986
1477.97	202.904
1481.1	188.173
1484.22	173.545
1487.35	156.629
1490.47	142.943
1493.59	131.046
1496.72	119.082
1499.84	106.819
1502.96	97.3067
1506.08	88.397
1509.19	79.1612
1512.31	72.1815
1515.42	63.7781
1518.54	56.1228
1521.65	51.9886
1524.76	48.7081
1527.87	45.3938
1530.98	45.4812
1534.09	44.6456
1537.2	48.282
1540.3	54.3447
1543.41	56.9723
1546.51	59.2802
1549.61	61.6983
1552.71	64.4372
1555.81	69.07
1558.91	71.5489
1562.01	74.2661
1565.1	77.9897
1568.2	83.1908
1571.29	85.4753
1574.38	89.181
1577.48	94.9695
1580.57	102.049
1583.65	106.657
1586.74	111.114
1589.83	115.799
1592.92	119.959
1596	124.239
1599.08	127.471
1602.16	127.496
1605.24	128.237
1608.32	127.324
1611.4	126.936
1614.48	128.689
1617.56	128.091
1620.63	129.823
1623.71	131.265
1626.78	134.272
1629.85	137.854
1632.92	141.205
1635.99	145.112
1639.06	151.313
1642.12	155.782
1645.19	160.874
1648.25	165.983
1651.32	170.842
1654.38	173.749
1657.44	175.361
1660.5	174.051
1663.56	173.01
1666.62	166.902
1669.67	160.856
1672.73	152.194
1675.79	142.036
1678.84	130.097
1681.89	117.619
1684.94	106.614
1687.99	93.8238
1691.04	83.0002
1694.08	72.28
1697.13	62.4623
1700.18	52.3632
1703.22	45.4995
1706.26	37.677
1709.3	31.0575
1712.35	25.6081
1715.39	21.3307
1718.42	18.9217
1721.46	17.5371
1724.5	15.0846
1727.53	12.7597
1730.56	10.7844
1733.6	9.39776
1736.63	6.09999
1739.66	4.96859
1742.69	4.52832
1745.71	5.86816
1748.74	4.54027
1751.77	4.0331
1754.79	3.86954
1757.81	4.85528
1760.84	5.27303
1763.86	6.02568
1766.88	5.49179
1769.9	5.33003
1772.91	5.63631
1775.93	3.8802
1778.95	3.9854
1781.96	3.77724
1784.97	4.13854
1787.99	5.32329
1791	5.68402
1794.01	4.83363
1797.01	4.69334
1800.02	3.40587
1803.03	2.89614
1806.03	2.66731
1809.04	2.41273
1812.04	2.16771
1815.04	2.7365
1818.04	3.07037
1821.04	2.78454
1824.04	2.83648
1827.04	2.81702
1830.03	2.81073
1833.03	3.51654
1836.02	3.63808
1839.02	1.9886
1842.01	0.476047
1845	1.12246
1847.99	0.815006
1850.98	0.902286
1853.96	0.914247
1856.95	2.17673
1859.94	2.93303
1862.92	3.0436
1865.9	2.48378
1868.88	2.45738
1871.86	2.84237
1874.84	3.49588
1877.82	3.84802
1880.8	4.31021
1882.58	3.98069
1885.57	5.18237
1888.56	5.40219
1891.54	5.81291
1894.53	6.79485
1897.51	7.25462
1900.5	6.94382
1903.48	6.72183
1906.46	6.79813
1909.44	6.42001
1912.42	5.35854
1915.4	6.51726
1918.37	5.54756
1921.35	4.97304
1924.32	2.98955
1927.3	3.51872
1930.27	4.77955
1933.24	3.85185
1936.21	3.54734
1939.18	3.13623
1942.15	3.0211
1945.11	2.18116
1948.08	2.66026
1951.04	2.19761
1954.01	3.08192
1956.97	3.09227
1959.93	3.0763
1962.89	2.63092
1965.85	2.59976
1968.81	2.72895
1971.77	2.61085
1974.72	2.0852
1977.68	2.61457
1980.63	2.40478
1983.58	2.20238
1986.53	3.48778
1989.48	3.90254
1992.43	3.28223
1995.38	4.04236
1998.33	4.04044
2001.27	5.07701
2004.22	5.38124
2007.16	5.82686
2010.11	6.34608
2013.05	5.30327
2015.99	4.38277
2018.93	4.94097
2021.87	5.4359
2024.8	4.68431
2027.74	3.3564
2030.68	3.92971
2033.61	3.95465
2036.54	2.61431
2039.48	2.84213
2042.41	2.56368
2045.34	3.20615
2048.27	3.87528
2051.19	3.89098
2054.12	4.40435
2057.05	5.25806
2059.97	5.22929
2062.9	6.33218
2065.82	6.42216
2068.74	6.8856
2071.66	7.92123
2074.58	8.79553
2077.5	9.43893
2080.41	9.98564
2083.33	11.6924
2086.24	10.6578
2089.16	12.5445
2092.07	14.1854
2094.98	13.965
2097.89	14.8555
2100.8	16.6701
2103.71	18.9838
2106.62	20.4184
2109.53	22.728
2112.43	25.4253
2115.33	28.4331
2118.24	30.2592
2121.14	34.0531
2124.04	37.1
2126.94	40.2228
2129.84	44.9144
2132.74	50.1162
2135.63	55.0892
2138.53	59.7784
2141.43	64.8482
2144.32	69.5922
2147.21	74.5582
2150.1	81.3456
2152.99	87.2175
2155.88	90.3818
2158.77	95.4313
2161.66	99.874
2164.55	104.88
2167.43	107.875
2170.31	110.615
2173.2	112.919
2176.08	113.338
2178.96	112.574
2181.84	111.849
2184.72	108.721
2187.6	107.051
2190.47	103.655
2193.35	98.9182
2196.23	94.0712
2199.1	89.5107
2201.97	84.2577
2204.84	77.8886
2207.71	71.4589
2210.58	65.7432
2213.45	59.269
2216.32	54.8114
2219.19	51.8628
2222.05	47.0962
2224.92	42.1149
2227.78	37.3111
2230.64	34.8007
2233.5	31.5842
2236.36	28.3577
2239.22	25.6591
2242.08	23.6443
2244.94	23.5947
2247.79	22.5829
2250.65	21.2503
2253.5	19.9604
2256.36	20.2208
2259.21	19.441
2262.06	18.5972
2264.91	16.4645
2267.76	16.1598
2270.6	15.1666
2273.45	14.5846
2276.3	13.6162
2279.14	12.0047
2281.98	11.7863
2284.83	11.1287
2287.67	10.3216
2290.51	8.46544
2293.35	6.43434
2296.19	5.30939
2299.02	6.10624
2301.86	6.24993
2304.7	6.41753
2307.53	7.02318
2310.36	7.53773
2313.2	7.33873
2316.03	8.2624
2318.86	6.41632
2321.69	5.94763
2324.51	6.72473
2327.34	6.52151
2330.17	4.91134
2332.99	4.04287
2335.82	3.39471
2338.64	3.39102
2341.46	2.77906
2344.28	3.34918
2347.1	2.17655
2349.92	1.0903
2352.74	0.807064
2355.56	0.0236137
2358.37	0.187428
2361.19	-0.138682
2364	1.25916
2366.82	2.80198
2369.63	2.236
2372.44	0.457108
2375.25	1.36489
2378.06	1.22224
2380.86	1.49511
2383.67	0.897628
2386.48	0.600027
2389.28	0.559451
2392.09	1.19128
2394.89	0.593013
2397.69	0.949496
2400.49	2.2818
2403.29	1.90925
2406.09	3.47758
2408.89	4.07238
2411.69	4.41234
2414.48	5.04771
2417.28	5.40446
2420.07	5.42292
2422.86	4.94671
2425.65	5.11782
2428.45	4.81758
2431.23	5.56175
2434.02	4.92263
2436.81	2.75302
2439.6	3.37956
2442.38	4.40492
2445.17	4.79482
2447.95	4.77445
2450.73	3.80635
2453.52	2.9899
2456.3	4.40532
2459.08	4.83355
2461.85	5.76756
2464.63	6.06371
2467.41	6.91424
2470.19	7.31243
2472.96	7.69992
2475.73	8.63063
2478.51	8.43704
2481.28	8.86865
2484.05	8.77516
2486.82	8.28383
2489.59	6.72565
2492.35	6.84969
2495.12	5.87623
2497.89	6.11502
2500.65	5.29706
2503.42	5.11055
2506.18	4.21951
2508.94	4.05917
2511.7	3.36478
2514.46	3.96281
2517.22	4.98804
2519.98	5.86034
2522.73	6.88679
2525.49	7.81812
2528.25	7.98446
2531	8.28399
2533.75	8.91298
2536.5	9.98456
2539.25	11.2976
2542.01	11.7066
2544.75	12.2147
2547.5	12.7398
2550.25	12.9028
2553	13.2432
2555.74	13.3472
2558.49	13.4495
2561.23	14.0279
2563.97	13.1631
2566.71	12.6919
2569.45	12.5046
2572.19	13.362
2574.93	12.9348
2577.67	13.7165
2580.4	14.6943
2583.14	16.378
2585.87	16.7622
2588.6	17.1847
2591.34	17.518
2594.07	17.4559
2596.8	17.3046
2599.53	17.4728
2602.26	17.9772
2604.98	18.4919
2607.71	18.6447
2610.44	18.2096
2613.16	18.612
2615.88	18.5217
2618.61	17.6745
2621.33	17.529
2624.05	16.7153
2626.77	16.1972
2629.49	15.5994
2632.21	15.446
2634.92	16.3249
2637.64	16.6828
2640.35	15.818
2643.07	16.8268
2645.78	16.2349
2648.49	17.9848
2651.2	18.7079
2653.91	18.4175
2656.62	18.748
2659.33	18.3872
2662.04	19.4584
2664.74	21.2521
2667.45	21.9537
2670.15	22.5054
2672.86	22.3604
2675.56	23.813
2678.26	24.065
2680.96	23.581
2683.66	23.6429
2686.36	23.8897
2689.06	24.342
2691.75	25.4446
2694.45	26.5128
2697.14	28.8043
2699.84	29.128
2702.53	30.5981
2705.22	32.2115
2707.91	32.5741
2710.6	33.7301
2713.29	35.1422
2715.98	36.9146
2718.67	37.1206
2721.35	37.0662
2724.04	36.5807
2726.72	36.2638
2729.4	35.5611
2732.09	34.4479
2734.77	32.845
2737.45	30.4711
2740.13	29.6407
2742.81	27.3992
2745.48	24.9779
2748.16	23.1781
2750.84	21.3168
2753.51	19.043
2756.19	16.8934
2758.86	14.7254
2761.53	12.5886
2764.2	11.2182
2766.87	9.94852
2769.54	9.32975
2772.21	8.00276
2774.88	6.57027
2777.54	5.40948
2780.21	5.13824
2782.87	3.86129
2785.53	2.08913
2788.2	1.26841
2790.86	0.284108
2793.52	1.28233
2796.18	1.88831
2798.84	1.5865
2801.49	1.02639
2804.15	0.279318
2806.81	-0.849514
2809.46	-3.16032
2812.12	-2.94866
2814.77	-1.52888
2817.42	3.31009
2820.07	11.1177
2822.72	21.807
2825.37	36.5785
2828.02	52.6632
2830.67	69.7465
2833.31	86.8526
2835.96	106.683
2838.61	125.221
2841.25	145.384
2843.89	166.793
2846.53	188.696
2849.17	211.448
2851.81	237.772
2854.45	266.154
2857.09	294.621
2859.73	321.545
2862.36	344.521
2865	366.291
2867.64	382.715
2870.27	397.343
2872.9	410.905
2875.53	423.439
2878.16	435.649
2880.79	446.637
2883.42	457.907
2886.05	467.935
2888.68	476.228
2891.3	484.846
2893.93	492.31
2896.55	500.072
2899.18	510.444
2901.8	520.769
2904.42	533.801
2907.04	548.873
2909.66	568.504
2912.28	591.799
2914.9	618.968
2917.51	645.714
2920.13	667.697
2922.74	686.144
2925.36	698.937
2927.97	705.794
2930.59	707.711
2933.2	703.267
2935.81	693.394
2938.42	679.69
2941.02	660.249
2943.63	634.904
2946.24	606.02
2948.85	575.518
2951.45	541.488
2954.05	508.953
2956.66	476.959
2959.26	446.421
2961.86	415.894
2964.46	390.183
2967.06	365.152
2969.66	345.136
2972.26	327.421
2974.85	311.856
2977.45	297.295
2980.05	281.581
2982.64	264.964
2985.23	247.758
2987.83	230.39
2990.42	212.31
2993.01	193.283
2995.6	174.461
2998.19	156.208
3000.77	137.141
3003.36	118.632
3005.95	100.321
3008.53	82.6255
3011.12	66.9035
3013.7	52.8081
3016.28	39.5274
3018.86	29.0347
3021.44	19.0388
3024.02	11.8403
3026.6	5.19619
3029.18	1.40386
3031.76	-0.905549
3034.33	-1.00059
3036.91	-0.178067
3039.48	1.30876
3042.05	3.31473
3044.63	6.17575
3047.2	9.11745
3049.77	11.7826
3052.34	12.3191
3054.91	13.6566
3057.48	13.9611
3060.04	14.9557
3062.61	15.8499
3065.17	15.474
3067.74	14.66
3070.3	13.3959
3072.87	11.4731
3075.43	10.2222
3077.99	8.16805
3080.55	5.6474
3083.11	3.96739
3085.67	2.7257
3088.22	1.34522
3090.78	0.89626
3093.34	1.81294
3095.89	3.07478
3098.44	4.7522
3101	6.14705
3103.55	9.23595
3106.1	11.9862
3108.65	14.7147
3111.2	17.7403
3113.75	20.2984
3116.3	23.8313
3118.84	27.6653
3121.39	31.4864
3123.93	36.3393
3126.48	40.2054
3129.02	43.7141
3131.56	48.3514
3134.1	53.0054
3136.64	59.1087
3139.18	63.7188
3141.72	68.5963
3144.26	73.3062
3146.8	78.5909
3149.33	82.1264