File: data/Raman/poly_smoothed/Mbcal_20_25_45_1x_45s_532 nm_x100_100%_600 gr_mm_01.txt
#Acq. time (s)=	45
#Accumulations=	2
#Range (cm-¹)=	200...3150
#Windows=	2
#Auto scanning=	Off
#Autofocus=	Off
#Macrospot=	Off
#AutoExposure=	Off
#Spike filter=	Multiple accum.
#Delay time (s)=	0
#Binning=	1
#Readout mode=	Signal
#DeNoise=	Off
#ICS correction=	On
#Dark correction=	Off
#Inst. Process=	Off
#Detector Gain=	Best Dynamic Range
#Detector ADC=	20 kHz
#Detector temperature (°C)=	-69.85
#Instrument=	LabRAM HR Evol
#Detector=	Synapse
#Objective=	x100
#Grating=	600 gr/mm
#ND Filter=	100%
#Laser (nm)=	532
#Hole=	100.021
#Range=	Auto
#Laser Pol.=	No
#Raman. Pol.=	No
#Laser Pol. (°)=	-0.0007625
#Raman Pol. (°)=	89.9995
#Collection=	Microscope
#StageXY=	Marzhauser
#StageZ=	Marzhauser
#X (µm)=	-1124.2
#Y (µm)=	1239.6
#Z (µm)=	578.4
#Full time(mm:ss)=	3:18
#Project=
#Sample=
#Site=
#Title=	Mbcal_20_25_45_2x_45s_532 nm_x100_100%_600 gr_mm
#Remark=
#Date=	18.07.2022 13:35
#Acquired=	18.07.2022 13:35:58
#Base:Fit=	10.08.2022 10:55:08
#Base:Sub=	10.08.2022 10:55:14
#Filter:Polynom=	16.08.2022 10:07:28
#AxisType[0]=Intens
#AxisUnit[0]=Cnt
#AxisType[1]=Spectr
#AxisUnit[1]=1/cm
200.419	18.8942
204.048	13.6883
207.678	9.26297
211.304	5.85652
214.928	3.57463
218.554	2.17006
222.176	1.93997
225.798	2.01971
229.417	0.848427
233.035	1.28286
236.653	1.16503
240.268	0.0389229
243.881	0.555953
247.493	0.529211
251.103	3.1155
254.715	4.98142
258.322	4.06685
261.929	4.57541
265.534	5.45206
269.137	8.03613
272.739	7.73678
276.34	8.34422
279.939	8.6149
283.537	9.76199
287.134	9.51567
290.729	8.96081
294.323	9.88308
297.913	10.1343
301.504	11.1145
305.093	13.5697
308.682	14.2517
312.268	16.4102
315.852	16.2656
319.436	16.6983
323.018	16.6757
326.597	15.7056
330.177	16.3967
333.753	16.1432
337.331	16.1657
340.906	16.6622
344.478	16.1354
348.051	14.4954
351.621	13.2815
355.189	12.6696
358.757	11.0516
362.323	9.65942
365.889	7.97776
369.451	5.79837
373.012	6.17905
376.574	5.86821
380.133	8.22657
383.69	7.08534
387.245	7.18667
390.8	8.83353
394.353	8.95475
397.906	10.077
401.456	9.48055
405.005	10.1159
408.552	9.8698
412.099	11.23
415.643	11.1727
419.187	10.0713
422.728	10.333
426.269	10.3512
429.806	10.8058
433.344	8.29925
436.881	7.60864
440.416	5.17066
443.949	2.66159
447.48	1.15995
451.011	1.40488
454.541	2.29191
458.069	2.79064
461.594	4.18424
465.119	3.79871
468.642	3.56824
472.165	2.13327
475.684	3.79477
479.204	4.01575
482.721	4.64934
486.239	6.44939
489.753	8.77503
493.268	11.3406
496.779	13.4365
500.289	15.7261
503.8	18.0259
507.307	20.0537
510.813	23.2391
514.32	27.3432
517.823	28.6815
521.325	31.2473
524.826	33.3945
528.325	34.7164
531.823	35.8315
535.32	40.0121
538.815	40.5507
542.309	40.2116
545.802	39.2268
549.293	37.9546
552.783	36.2312
556.271	34.0277
559.759	30.5329
563.245	28.7724
566.729	25.3212
570.213	23.5567
573.693	21.8283
577.173	19.6143
580.652	15.9602
584.13	13.9092
587.605	12.2632
591.08	10.097
594.552	9.41108
598.025	7.86473
601.496	6.63756
604.964	5.90651
608.433	6.76212
611.898	5.90749
615.364	6.14579
618.827	5.40774
622.288	5.73242
625.75	6.42116
629.209	6.29505
632.667	5.42807
636.125	5.68118
639.58	5.43978
643.033	6.30974
646.485	7.83776
649.936	7.71836
653.388	8.50613
656.836	9.9069
660.283	11.1776
663.728	10.6405
667.173	10.9586
670.616	11.6304
674.057	11.9799
677.498	11.434
680.937	13.4769
684.375	15.0243
687.809	15.4053
691.244	15.6958
694.678	15.6784
698.111	16.3543
701.54	15.7327
704.97	16.2752
708.398	16.7253
711.826	16.5036
715.25	17.2821
718.675	17.8868
722.096	18.5641
725.518	19.9122
728.937	21.3873
732.357	21.2601
735.773	22.0754
739.19	23.1097
742.604	24.371
746.018	25.4415
749.429	26.2821
752.839	30.2726
756.248	32.4256
759.657	32.9305
763.063	37.4293
766.468	39.6348
769.871	42.2168
773.273	43.3729
776.676	45.5694
780.075	47.436
783.474	48.4022
786.871	50.4833
790.266	52.3546
793.661	52.7711
797.054	57.5648
800.446	57.4468
803.834	57.8552
807.224	58.0147
810.612	56.6851
813.998	54.1971
817.384	52.1516
820.766	50.8656
824.149	51.8454
827.531	54.4651
830.909	57.294
834.288	63.2772
837.666	67.1591
841.041	71.2885
844.416	77.284
847.788	81.3822
851.161	82.9183
854.53	84.4494
857.901	85.7645
861.268	85.6367
864.633	84.8653
868	83.1862
871.363	79.4451
874.725	75.3866
878.088	70.8753
881.447	65.6848
884.805	58.1672
888.162	50.9187
891.518	41.9255
894.872	35.1566
898.225	28.4391
901.577	24.9379
904.928	23.0039
908.277	24.5551
911.625	27.1704
914.972	29.5004
918.318	30.7867
921.662	31.3335
925.005	32.943
928.347	34.0952
931.686	33.217
935.025	33.7078
938.363	34.3469
941.698	32.8653
945.034	29.9525
948.368	25.9929
951.699	23.4323
955.031	21.1898
958.36	19.5951
961.689	15.5371
965.016	14.1648
968.343	12.5821
971.666	10.7118
974.991	9.26701
978.312	9.48332
981.632	8.7149
984.953	9.34041
988.27	9.21865
991.587	9.79588
994.902	10.2767
998.216	10.2826
1001.53	8.59415
1004.84	9.3198
1008.15	11.1687
1011.46	11.6397
1014.77	14.4025
1018.07	16.4667
1021.38	18.0795
1024.68	18.7057
1027.99	19.7151
1031.29	20.5799
1034.59	23.2299
1037.89	23.4673
1041.18	23.9805
1044.48	24.5011
1047.77	25.7403
1051.07	24.2582
1054.36	22.7342
1057.65	21.4886
1060.94	20.486
1064.23	18.6551
1067.52	17.4596
1070.8	15.5633
1074.09	15.7346
1077.37	15.91
1080.65	14.7074
1083.93	15.8051
1087.21	17.1329
1090.49	18.265
1093.77	20.4039
1097.04	22.4806
1100.32	22.2607
1103.59	21.8084
1106.86	20.7469
1110.13	21.588
1113.4	21.8527
1116.67	21.2264
1119.94	21.1775
1123.2	20.3309
1126.47	17.9818
1129.73	15.2854
1132.99	13.8438
1136.25	13.4008
1139.51	12.3068
1142.77	10.6061
1146.03	9.37989
1149.28	8.3186
1152.54	7.36575
1155.79	8.59191
1159.04	8.00741
1162.29	3.81616
1165.54	4.83546
1168.79	6.4112
1172.04	7.00371
1175.28	7.34233
1178.53	8.50012
1181.77	6.73792
1185.01	7.19005
1188.25	8.18503
1191.49	8.83392
1194.73	8.62186
1197.96	10.2067
1201.2	9.76278
1204.43	10.6191
1207.66	11.7978
1210.9	13.103
1214.13	12.9822
1217.36	14.8015
1220.58	15.9214
1223.81	17.3722
1227.04	19.9326
1230.26	23.6026
1233.48	26.6
1236.71	29.35
1239.93	33.2648
1243.14	35.2684
1246.36	43.567
1249.58	46.8766
1252.8	49.608
1256.01	52.7254
1259.22	53.8969
1262.43	54.3247
1265.64	56.7111
1268.85	59.3262
1272.06	60.2428
1275.27	64.2005
1278.48	64.9603
1281.68	66.8952
1284.88	69.9769
1288.08	73.3864
1291.28	75.2284
1294.48	77.2738
1297.68	81.1716
1300.88	82.337
1304.07	85.1237
1307.27	86.3663
1310.46	86.3168
1313.65	87.6523
1316.85	87.7199
1320.03	88.21
1323.22	87.338
1326.41	86.8846
1329.6	85.0205
1332.78	83.2402
1335.96	80.8541
1339.15	79.1281
1342.33	76.2973
1345.51	75.1019
1348.69	72.1779
1351.86	70.0005
1355.04	68.6402
1358.21	66.1404
1361.39	67.2413
1364.56	67.7827
1367.73	66.6831
1370.9	66.1857
1374.07	65.6288
1377.24	65.0529
1380.41	64.3099
1383.57	64.1104
1386.73	63.5172
1389.9	63.9467
1393.06	63.6011
1396.22	63.1017
1399.38	66.2024
1402.54	67.3452
1405.69	71.6595
1408.85	74.3408
1412	79.7234
1415.16	85.9468
1418.31	93.2234
1421.46	98.9745
1424.61	104.193
1427.76	111.568
1430.9	119.822
1434.05	126.745
1437.2	134.088
1440.34	139.059
1443.48	143.227
1446.62	145.577
1449.76	145.378
1452.9	144.54
1456.04	140.99
1459.17	137.005
1462.31	133.195
1465.44	127.267
1468.58	122.587
1471.71	116.972
1474.84	111.691
1477.97	105.529
1481.1	100.344
1484.22	93.8353
1487.35	88.3092
1490.47	84.6361
1493.59	80.0717
1496.72	72.6581
1499.84	68.3317
1502.96	64.6666
1506.08	61.6159
1509.19	57.891
1512.31	53.1383
1515.42	49.8434
1518.54	47.3962
1521.65	43.6582
1524.76	40.7211
1527.87	38.9718
1530.98	36.7786
1534.09	36.723
1537.2	36.3914
1540.3	38.0268
1543.41	39.7951
1546.51	41.3475
1549.61	42.813
1552.71	42.9724
1555.81	45.3533
1558.91	47.3605
1562.01	48.9741
1565.1	51.2087
1568.2	52.755
1571.29	53.0178
1574.38	54.6175
1577.48	58.7039
1580.57	60.4958
1583.65	63.6938
1586.74	67.1317
1589.83	70.7789
1592.92	73.6398
1596	75.6939
1599.08	76.3513
1602.16	78.0954
1605.24	79.0032
1608.32	79.5831
1611.4	80.008
1614.48	80.9433
1617.56	82.6795
1620.63	83.3276
1623.71	84.2385
1626.78	84.7961
1629.85	85.2104
1632.92	86.1502
1635.99	86.0793
1639.06	85.7618
1642.12	86.6407
1645.19	86.2531
1648.25	87.6912
1651.32	88.0172
1654.38	87.8141
1657.44	87.2144
1660.5	85.804
1663.56	81.6567
1666.62	79.0442
1669.67	74.0972
1672.73	68.4012
1675.79	64.6099
1678.84	60.1654
1681.89	55.2781
1684.94	49.3475
1687.99	44.3386
1691.04	40.1696
1694.08	34.2866
1697.13	31.1324
1700.18	25.6856
1703.22	22.2963
1706.26	18.4315
1709.3	15.475
1712.35	12.4021
1715.39	12.6212
1718.42	11.154
1721.46	12.2592
1724.5	12.0891
1727.53	10.8964
1730.56	11.6099
1733.6	9.40281
1736.63	9.84994
1739.66	8.61906
1742.69	8.48622
1745.71	7.58346
1748.74	7.91909
1751.77	7.26866
1754.79	5.95588
1757.81	4.8214
1760.84	4.48917
1763.86	4.56135
1766.88	4.42694
1769.9	3.58238
1772.91	3.45423
1775.93	3.91896
1778.95	4.79224
1781.96	4.18693
1784.97	6.00616
1787.99	6.95648
1791	7.33147
1794.01	7.94288
1797.01	8.31047
1800.02	8.35477
1803.03	8.06387
1806.03	7.24144
1809.04	5.63354
1812.04	5.16882
1815.04	4.34186
1818.04	3.05768
1821.04	2.50361
1824.04	1.67118
1827.04	1.21109
1830.03	0.857488
1833.03	1.06036
1836.02	1.85343
1839.02	1.4658
1842.01	0.161563
1845	0.34052
1847.99	0.79746
1850.98	2.14336
1853.96	2.95691
1856.95	3.55049
1859.94	4.48791
1862.92	5.43436
1865.9	6.47287
1868.88	7.10545
1871.86	8.09352
1874.84	7.91144
1877.82	6.00662
1880.8	6.74463
1882.58	6.82979
1885.57	7.05256
1888.56	6.74739
1891.54	6.6759
1894.53	6.82389
1897.51	6.80683
1900.5	6.57726
1903.48	5.74836
1906.46	4.4456
1909.44	3.1383
1912.42	2.36413
1915.4	1.50919
1918.37	2.89
1921.35	4.19058
1924.32	4.76538
1927.3	4.47162
1930.27	4.33829
1933.24	5.46699
1936.21	5.68334
1939.18	5.84699
1942.15	5.46398
1945.11	5.68054
1948.08	5.55799
1951.04	7.42437
1954.01	7.42139
1956.97	7.72803
1959.93	7.60794
1962.89	6.89216
1965.85	7.315
1968.81	6.77626
1971.77	5.60133
1974.72	5.04414
1977.68	4.20816
1980.63	3.67089
1983.58	3.29164
1986.53	3.50648
1989.48	3.6336
1992.43	4.87918
1995.38	4.88126
1998.33	3.81034
2001.27	3.28211
2004.22	2.7957
2007.16	2.05253
2010.11	2.74737
2013.05	2.84994
2015.99	2.64169
2018.93	3.45604
2021.87	3.46761
2024.8	3.16539
2027.74	2.89541
2030.68	3.93766
2033.61	2.79969
2036.54	3.07798
2039.48	2.51788
2042.41	3.15774
2045.34	2.62443
2048.27	2.49568
2051.19	2.129
2054.12	2.48072
2057.05	2.5263
2059.97	3.37312
2062.9	4.92108
2065.82	4.33406
2068.74	3.53945
2071.66	3.53078
2074.58	4.19659
2077.5	6.43151
2080.41	9.19086
2083.33	12.6752
2086.24	13.6576
2089.16	15.8494
2092.07	17.9874
2094.98	17.9205
2097.89	19.9927
2100.8	23.0037
2103.71	24.466
2106.62	25.7558
2109.53	27.8281
2112.43	29.0859
2115.33	31.723
2118.24	31.9127
2121.14	32.3754
2124.04	32.735
2126.94	34.2739
2129.84	35.4004
2132.74	35.9381
2135.63	36.2492
2138.53	36.3424
2141.43	39.1533
2144.32	41.0564
2147.21	44.6322
2150.1	47.2789
2152.99	49.6625
2155.88	51.677
2158.77	53.4417
2161.66	54.7359
2164.55	55.6619
2167.43	57.1408
2170.31	59.9464
2173.2	60.365
2176.08	60.5603
2178.96	59.1639
2181.84	57.0792
2184.72	55.7409
2187.6	54.1835
2190.47	50.8458
2193.35	47.9475
2196.23	46.0019
2199.1	42.9724
2201.97	40.4479
2204.84	38.1387
2207.71	35.9764
2210.58	33.9357
2213.45	32.307
2216.32	30.7253
2219.19	29.3852
2222.05	28.713
2224.92	27.4843
2227.78	24.8422
2230.64	23.129
2233.5	22.1483
2236.36	20.4883
2239.22	19.7279
2242.08	17.8438
2244.94	15.5295
2247.79	13.8687
2250.65	12.9209
2253.5	11.6853
2256.36	10.8504
2259.21	9.59302
2262.06	8.56931
2264.91	7.59448
2267.76	6.95689
2270.6	6.86097
2273.45	6.39691
2276.3	6.16612
2279.14	5.83998
2281.98	5.76748
2284.83	5.59389
2287.67	3.71669
2290.51	3.15385
2293.35	0.615327
2296.19	-0.957369
2299.02	-0.332636
2301.86	2.02124
2304.7	2.36829
2307.53	2.70548
2310.36	3.37204
2313.2	4.67107
2316.03	4.89682
2318.86	5.21701
2321.69	4.9069
2324.51	6.30395
2327.34	6.83247
2330.17	6.39776
2332.99	6.17772
2335.82	5.97725
2338.64	6.77555
2341.46	7.04803
2344.28	6.72854
2347.1	6.71934
2349.92	6.26317
2352.74	5.39902
2355.56	3.03688
2358.37	2.6073
2361.19	1.57082
2364	1.72258
2366.82	3.39976
2369.63	5.24282
2372.44	5.42623
2375.25	4.83173
2378.06	3.85553
2380.86	3.42194
2383.67	3.36469
2386.48	2.91774
2389.28	2.93671
2392.09	2.47564
2394.89	2.489
2397.69	2.39198
2400.49	2.87912
2403.29	3.22956
2406.09	4.33762
2408.89	5.01542
2411.69	4.30199
2414.48	4.24841
2417.28	3.94125
2420.07	4.30751
2422.86	3.61357
2425.65	3.39007
2428.45	4.30965
2431.23	4.23262
2434.02	5.07676
2436.81	6.27349
2439.6	5.71431
2442.38	6.5706
2445.17	5.48606
2447.95	4.79795
2450.73	4.55724
2453.52	4.93886
2456.3	4.7902
2459.08	4.16706
2461.85	2.96883
2464.63	3.1887
2467.41	3.22807
2470.19	3.89025
2472.96	3.73558
2475.73	3.48202
2478.51	2.81897
2481.28	3.44061
2484.05	3.78914
2486.82	4.37193
2489.59	4.44496
2492.35	5.39835
2495.12	6.56321
2497.89	5.86896
2500.65	6.60843
2503.42	7.52273
2506.18	7.1875
2508.94	6.80353
2511.7	6.81286
2514.46	5.88648
2517.22	6.28948
2519.98	6.43395
2522.73	6.56637
2525.49	5.67126
2528.25	5.42099
2531	5.00977
2533.75	5.498
2536.5	5.87888
2539.25	5.37361
2542.01	5.8623
2544.75	5.51528
2547.5	7.15026
2550.25	8.18319
2553	8.61823
2555.74	8.53575
2558.49	9.09685
2561.23	8.43437
2563.97	7.30551
2566.71	7.73128
2569.45	7.4419
2572.19	7.50011
2574.93	7.49377
2577.67	7.33166
2580.4	8.06069
2583.14	7.48735
2585.87	8.18259
2588.6	7.21682
2591.34	7.27484
2594.07	5.96969
2596.8	5.18719
2599.53	4.74517
2602.26	4.78461
2604.98	4.62258
2607.71	5.84079
2610.44	5.55058
2613.16	7.05602
2615.88	7.42713
2618.61	7.92478
2621.33	7.68177
2624.05	8.49439
2626.77	8.40255
2629.49	9.51266
2632.21	10.2909
2634.92	12.103
2637.64	12.617
2640.35	13.8211
2643.07	14.759
2645.78	14.2938
2648.49	15.032
2651.2	14.3769
2653.91	13.984
2656.62	13.5117
2659.33	12.5938
2662.04	11.7992
2664.74	11.8393
2667.45	11.4598
2670.15	10.4144
2672.86	9.48221
2675.56	8.7538
2678.26	8.31646
2680.96	7.89086
2683.66	8.39553
2686.36	7.77271
2689.06	8.06528
2691.75	8.38752
2694.45	9.24061
2697.14	10.6301
2699.84	11.27
2702.53	12.744
2705.22	13.3622
2707.91	15.3583
2710.6	17.1966
2713.29	18.2243
2715.98	18.3042
2718.67	19.1722
2721.35	20.3935
2724.04	20.3744
2726.72	20.6342
2729.4	20.979
2732.09	20.4201
2734.77	19.6286
2737.45	18.2696
2740.13	16.6832
2742.81	15.6754
2745.48	14.3513
2748.16	13.3178
2750.84	12.0778
2753.51	11.1344
2756.19	11.0018
2758.86	9.51155
2761.53	8.52181
2764.2	8.03206
2766.87	7.00362
2769.54	5.87597
2772.21	5.07125
2774.88	4.77785
2777.54	4.0812
2780.21	3.24274
2782.87	2.69124
2785.53	2.4767
2788.2	1.90847
2790.86	1.56168
2793.52	1.59731
2796.18	1.09259
2798.84	0.50905
2801.49	-0.259187
2804.15	-0.422154
2806.81	-1.59297
2809.46	-0.712041
2812.12	0.175517
2814.77	2.06524
2817.42	3.6484
2820.07	7.12178
2822.72	11.0768
2825.37	16.531
2828.02	22.6284
2830.67	29.0339
2833.31	35.5356
2835.96	43.479
2838.61	52.4324
2841.25	62.3407
2843.89	72.9807
2846.53	84.778
2849.17	95.9354
2851.81	108.47
2854.45	121.64
2857.09	136.066
2859.73	148.718
2862.36	160.808
2865	173.04
2867.64	185.012
2870.27	195.519
2872.9	204.082
2875.53	213.632
2878.16	221.396
2880.79	229.145
2883.42	236.406
2886.05	243.678
2888.68	251.16
2891.3	257.382
2893.93	263.992
2896.55	271.197
2899.18	279.233
2901.8	288.711
2904.42	299.545
2907.04	312.54
2909.66	326.05
2912.28	341.118
2914.9	356.174
2917.51	370.879
2920.13	384.931
2922.74	396.208
2925.36	402.796
2927.97	408.094
2930.59	410.41
2933.2	407.75
2935.81	401.641
2938.42	391.98
2941.02	379.895
2943.63	364.854
2946.24	347.011
2948.85	328.941
2951.45	309.526
2954.05	290.041
2956.66	271.392
2959.26	253.701
2961.86	237.136
2964.46	222.358
2967.06	208.076
2969.66	196.839
2972.26	186.625
2974.85	178.393
2977.45	169.911
2980.05	161.864
2982.64	153.581
2985.23	144.368
2987.83	133.76
2990.42	123.935
2993.01	112.365
2995.6	101.28
2998.19	90.0318
3000.77	78.5931
3003.36	66.7615
3005.95	55.2232
3008.53	45.282
3011.12	35.8912
3013.7	28.9254
3016.28	20.7154
3018.86	14.5535
3021.44	10.7343
3024.02	6.05269
3026.6	2.70764
3029.18	-0.0639407
3031.76	-1.70475
3034.33	-2.5513
3036.91	-1.6866
3039.48	-1.01239
3042.05	0.400603
3044.63	2.21156
3047.2	3.03836
3049.77	4.20878
3052.34	5.47632
3054.91	6.34674
3057.48	5.8492
3060.04	6.54305
3062.61	6.85152
3065.17	5.98287
3067.74	4.74465
3070.3	4.84671
3072.87	4.87349
3075.43	4.57956
3077.99	3.81006
3080.55	3.65689
3083.11	2.80737
3085.67	1.77255
3088.22	1.9952
3090.78	2.33114
3093.34	2.63634
3095.89	3.92741
3098.44	5.89276
3101	7.13937
3103.55	8.71653
3106.1	10.3186
3108.65	12.219
3111.2	14.4607
3113.75	16.4918
3116.3	17.9799
3118.84	19.4314
3121.39	21.877
3123.93	24.4693
3126.48	26.2751
3129.02	28.1558
3131.56	31.8752
3134.1	34.9683
3136.64	38.648
3139.18	41.6337
3141.72	45.3703
3144.26	49.4261
3146.8	54.4489
3149.33	58.7076