File: data/Raman/poly_smoothed/Mbcal_20_25_35_1x_45s_532 nm_x100_100%_600 gr_mm_01.txt
#Acq. time (s)=	45
#Accumulations=	2
#Range (cm-¹)=	200...3150
#Windows=	2
#Auto scanning=	Off
#Autofocus=	Off
#Macrospot=	Off
#AutoExposure=	Off
#Spike filter=	Multiple accum.
#Delay time (s)=	0
#Binning=	1
#Readout mode=	Signal
#DeNoise=	Off
#ICS correction=	On
#Dark correction=	Off
#Inst. Process=	Off
#Detector Gain=	Best Dynamic Range
#Detector ADC=	20 kHz
#Detector temperature (°C)=	-69.85
#Instrument=	LabRAM HR Evol
#Detector=	Synapse
#Objective=	x100
#Grating=	600 gr/mm
#ND Filter=	100%
#Laser (nm)=	532
#Hole=	100.021
#Range=	Auto
#Laser Pol.=	No
#Raman. Pol.=	No
#Laser Pol. (°)=	-0.0007625
#Raman Pol. (°)=	89.9995
#Collection=	Microscope
#StageXY=	Marzhauser
#StageZ=	Marzhauser
#X (µm)=	-1125.7
#Y (µm)=	1288.2
#Z (µm)=	578.4
#Full time(mm:ss)=	3:19
#Project=
#Sample=
#Site=
#Title=	Mbcal_20_25_35_2x_45s_532 nm_x100_100%_600 gr_mm
#Remark=
#Date=	18.07.2022 12:41
#Acquired=	18.07.2022 12:41:29
#Base:Fit=	10.08.2022 10:55:08
#Base:Sub=	10.08.2022 10:55:14
#Filter:Polynom=	16.08.2022 10:07:28
#AxisType[0]=Intens
#AxisUnit[0]=Cnt
#AxisType[1]=Spectr
#AxisUnit[1]=1/cm
200.419	21.2171
204.048	14.8562
207.678	10.2593
211.304	7.44037
214.928	4.02752
218.554	4.31202
222.176	3.86082
225.798	1.64986
229.417	2.53263
233.035	2.73225
236.653	3.02392
240.268	2.6437
243.881	2.81302
247.493	3.99445
251.103	5.60375
254.715	4.84578
258.322	5.56381
261.929	4.5227
265.534	4.86616
269.137	5.52954
272.739	4.22144
276.34	2.49863
279.939	3.0796
283.537	2.6756
287.134	1.60141
290.729	1.77169
294.323	1.18228
297.913	3.1351
301.504	4.05978
305.093	5.97633
308.682	6.91557
312.268	7.54978
315.852	9.06146
319.436	11.556
323.018	12.8241
326.597	13.4761
330.177	13.8724
333.753	15.936
337.331	16.3968
340.906	16.8793
344.478	16.186
348.051	15.1133
351.621	12.6361
355.189	11.8238
358.757	8.48486
362.323	6.8338
365.889	5.21518
369.451	4.51317
373.012	3.42422
376.574	5.33412
380.133	7.73041
383.69	10.18
387.245	11.3102
390.8	12.029
394.353	14.2898
397.906	16.5167
401.456	18.9507
405.005	22.2934
408.552	25.7643
412.099	27.1566
415.643	28.201
419.187	28.3357
422.728	28.4395
426.269	26.1161
429.806	26.386
433.344	24.3638
436.881	21.9826
440.416	19.98
443.949	18.1313
447.48	15.0395
451.011	13.7025
454.541	13.7467
458.069	13.2711
461.594	14.575
465.119	16.373
468.642	17.7415
472.165	17.3787
475.684	18.0485
479.204	18.6911
482.721	21.4774
486.239	24.2612
489.753	25.1349
493.268	26.4412
496.779	28.8397
500.289	29.2638
503.8	26.4415
507.307	27.7365
510.813	27.8523
514.32	30.1112
517.823	30.6532
521.325	29.6577
524.826	30.4159
528.325	29.9091
531.823	28.7604
535.32	30.2518
538.815	30.0409
542.309	30.9136
545.802	30.4516
549.293	30.1971
552.783	30.6101
556.271	29.0339
559.759	27.0977
563.245	27.1074
566.729	23.3959
570.213	21.4177
573.693	17.1205
577.173	15.6738
580.652	13.6426
584.13	11.4669
587.605	9.68098
591.08	9.59989
594.552	8.85278
598.025	7.00686
601.496	5.88134
604.964	5.45496
608.433	5.71148
611.898	6.48947
615.364	6.26115
618.827	8.06791
622.288	8.12712
625.75	8.37989
629.209	10.2091
632.667	9.89632
636.125	10.8649
639.58	12.7053
643.033	9.82379
646.485	10.1417
649.936	7.49724
653.388	6.87318
656.836	5.91461
660.283	6.48144
663.728	5.86029
667.173	5.66771
670.616	4.95622
674.057	7.03343
677.498	6.04622
680.937	6.41077
684.375	7.3083
687.809	10.2995
691.244	12.3187
694.678	14.4423
698.111	17.7134
701.54	20.623
704.97	23.7889
708.398	25.1885
711.826	28.6978
715.25	30.3373
718.675	32.2459
722.096	33.1261
725.518	35.5264
728.937	36.6821
732.357	36.4552
735.773	37.1652
739.19	35.3468
742.604	35.6565
746.018	37.6522
749.429	38.4683
752.839	41.7346
756.248	43.9807
759.657	45.7388
763.063	47.0171
766.468	51.0313
769.871	54.4462
773.273	56.1447
776.676	58.4778
780.075	60.5789
783.474	62.3885
786.871	62.6091
790.266	63.1366
793.661	63.6335
797.054	64.3356
800.446	61.8941
803.834	58.2588
807.224	57.0959
810.612	55.7511
813.998	51.2717
817.384	48.2911
820.766	48.2704
824.149	47.4892
827.531	50.5708
830.909	53.1243
834.288	56.1596
837.666	58.3828
841.041	60.7582
844.416	63.4898
847.788	66.5456
851.161	68.859
854.53	68.3315
857.901	66.9197
861.268	65.8974
864.633	66.0558
868	65.4424
871.363	62.4972
874.725	60.0263
878.088	57.5388
881.447	51.4687
884.805	48.4769
888.162	43.8794
891.518	40.0765
894.872	35.762
898.225	33.4287
901.577	30.7726
904.928	29.4443
908.277	28.2796
911.625	30.9774
914.972	31.4987
918.318	33.1539
921.662	33.8888
925.005	35.0177
928.347	35.3076
931.686	34.9713
935.025	33.5904
938.363	31.0757
941.698	29.9613
945.034	30.1855
948.368	29.9317
951.699	28.4181
955.031	27.7429
958.36	24.3578
961.689	21.9689
965.016	20.6434
968.343	22.1357
971.666	20.2803
974.991	20.0504
978.312	18.4414
981.632	16.6304
984.953	15.8756
988.27	16.442
991.587	18.3592
994.902	18.663
998.216	19.2389
1001.53	17.9709
1004.84	18.3569
1008.15	18.7074
1011.46	18.7119
1014.77	20.0483
1018.07	20.7938
1021.38	20.9422
1024.68	22.9878
1027.99	24.5856
1031.29	24.4719
1034.59	24.0178
1037.89	22.473
1041.18	22.5661
1044.48	23.2616
1047.77	26.5608
1051.07	25.1881
1054.36	23.4837
1057.65	21.2236
1060.94	20.9716
1064.23	23.1404
1067.52	21.6936
1070.8	22.5634
1074.09	23.1538
1077.37	22.2799
1080.65	22.7705
1083.93	23.2659
1087.21	25.053
1090.49	27.3839
1093.77	29.5349
1097.04	30.2997
1100.32	30.636
1103.59	31.2216
1106.86	33.7085
1110.13	35.4284
1113.4	33.6709
1116.67	34.7573
1119.94	34.7579
1123.2	34.2317
1126.47	32.7058
1129.73	32.213
1132.99	31.1838
1136.25	30.6313
1139.51	29.6482
1142.77	27.1449
1146.03	20.5768
1149.28	21.351
1152.54	22.424
1155.79	22.5229
1159.04	20.0359
1162.29	19.92
1165.54	19.6817
1168.79	20.4673
1172.04	21.6646
1175.28	23.053
1178.53	22.3341
1181.77	23.9461
1185.01	26.1675
1188.25	28.2171
1191.49	29.9699
1194.73	31.159
1197.96	32.6783
1201.2	35.4134
1204.43	38.1451
1207.66	40.7146
1210.9	43.3045
1214.13	44.8928
1217.36	46.508
1220.58	47.0453
1223.81	46.8619
1227.04	55.8573
1230.26	59.2727
1233.48	62.9492
1236.71	66.2494
1239.93	68.8853
1243.14	72.6011
1246.36	75.2253
1249.58	76.9716
1252.8	78.9039
1256.01	80.309
1259.22	80.5836
1262.43	82.3421
1265.64	82.7393
1268.85	84.0111
1272.06	86.2913
1275.27	87.5966
1278.48	91.5179
1281.68	94.3574
1284.88	98.18
1288.08	101.83
1291.28	105.058
1294.48	108.931
1297.68	111.584
1300.88	115.122
1304.07	120.205
1307.27	123.886
1310.46	130.216
1313.65	134.858
1316.85	138.243
1320.03	138.781
1323.22	141.695
1326.41	143.086
1329.6	142.534
1332.78	141.766
1335.96	139.903
1339.15	137.524
1342.33	135.985
1345.51	133.684
1348.69	131.501
1351.86	126.846
1355.04	124.247
1358.21	120.479
1361.39	117.489
1364.56	113.739
1367.73	108.487
1370.9	105.119
1374.07	100.641
1377.24	95.6337
1380.41	94.0927
1383.57	91.6236
1386.73	91.3723
1389.9	90.2247
1393.06	86.8975
1396.22	84.7252
1399.38	84.5304
1402.54	85.3393
1405.69	87.3678
1408.85	87.7389
1412	91.2102
1415.16	97.9433
1418.31	104.896
1421.46	113.915
1424.61	124.23
1427.76	134.124
1430.9	144.894
1434.05	155.921
1437.2	166.02
1440.34	173.963
1443.48	179.951
1446.62	184.536
1449.76	189.21
1452.9	191.002
1456.04	193.091
1459.17	196.406
1462.31	201.372
1465.44	205.006
1468.58	207.808
1471.71	206.784
1474.84	207.54
1477.97	204.005
1481.1	200.199
1484.22	194.803
1487.35	188.059
1490.47	180.302
1493.59	171.38
1496.72	161.7
1499.84	153.919
1502.96	141.768
1506.08	130.179
1509.19	118.911
1512.31	105.102
1515.42	93.3978
1518.54	80.7233
1521.65	68.3635
1524.76	60.4629
1527.87	53.8503
1530.98	48.1564
1534.09	47.6172
1537.2	50.592
1540.3	53.4628
1543.41	57.631
1546.51	61.1311
1549.61	63.5104
1552.71	66.3851
1555.81	69.0124
1558.91	71.805
1562.01	75.2643
1565.1	76.9421
1568.2	79.7191
1571.29	84.2876
1574.38	87.9672
1577.48	91.9549
1580.57	94.6838
1583.65	97.4644
1586.74	99.7166
1589.83	101.824
1592.92	103.167
1596	104.621
1599.08	104.291
1602.16	103.272
1605.24	101.873
1608.32	99.2397
1611.4	97.8749
1614.48	95.7194
1617.56	93.374
1620.63	94.1655
1623.71	94.5364
1626.78	94.5911
1629.85	97.4191
1632.92	99.8306
1635.99	104.606
1639.06	107.614
1642.12	112.126
1645.19	115.499
1648.25	119.906
1651.32	122.506
1654.38	124.505
1657.44	126.515
1660.5	127.58
1663.56	124.953
1666.62	121.553
1669.67	115.164
1672.73	108.574
1675.79	101.261
1678.84	90.4857
1681.89	81.8906
1684.94	72.6494
1687.99	63.2091
1691.04	54.845
1694.08	47.7578
1697.13	40.7172
1700.18	32.8019
1703.22	27.9349
1706.26	22.1762
1709.3	17.7004
1712.35	13.3977
1715.39	9.61164
1718.42	7.23685
1721.46	6.00886
1724.5	5.16005
1727.53	4.85882
1730.56	4.68954
1733.6	5.55047
1736.63	3.9894
1739.66	3.45093
1742.69	2.01287
1745.71	1.97332
1748.74	2.4349
1751.77	2.28945
1754.79	3.36037
1757.81	3.51264
1760.84	4.15806
1763.86	3.38286
1766.88	3.72017
1769.9	2.69718
1772.91	2.64299
1775.93	3.15755
1778.95	2.92925
1781.96	2.51035
1784.97	3.35278
1787.99	3.45818
1791	3.49357
1794.01	3.92399
1797.01	4.53407
1800.02	5.19274
1803.03	5.16801
1806.03	6.10054
1809.04	6.3868
1812.04	6.43577
1815.04	6.42104
1818.04	5.81808
1821.04	4.55368
1824.04	4.50607
1827.04	3.07333
1830.03	2.48955
1833.03	2.36296
1836.02	2.93257
1839.02	2.94016
1842.01	3.68797
1845	2.52298
1847.99	3.17944
1850.98	4.3392
1853.96	5.68335
1856.95	5.97454
1859.94	5.70088
1862.92	6.02346
1865.9	5.39428
1868.88	5.59829
1871.86	6.25587
1874.84	6.79202
1877.82	7.76762
1880.8	8.91048
1882.58	9.38683
1885.57	8.85652
1888.56	8.91864
1891.54	7.71199
1894.53	8.65239
1897.51	8.67811
1900.5	8.83474
1903.48	10.7418
1906.46	11.1048
1909.44	11.411
1912.42	10.3065
1915.4	8.85918
1918.37	9.10342
1921.35	9.86934
1924.32	8.91034
1927.3	8.46871
1930.27	6.2554
1933.24	5.87967
1936.21	6.24634
1939.18	4.62882
1942.15	4.50377
1945.11	5.29201
1948.08	5.37503
1951.04	6.53214
1954.01	7.0852
1956.97	7.12606
1959.93	6.52803
1962.89	7.21085
1965.85	8.80098
1968.81	8.85825
1971.77	9.38669
1974.72	10.8367
1977.68	10.8342
1980.63	8.07879
1983.58	6.91826
1986.53	5.2475
1989.48	5.52711
1992.43	6.91309
1995.38	6.72825
1998.33	6.7214
2001.27	5.93629
2004.22	5.66554
2007.16	5.60571
2010.11	5.68273
2013.05	6.38289
2015.99	6.3252
2018.93	6.26613
2021.87	7.27869
2024.8	7.62206
2027.74	7.73497
2030.68	7.75874
2033.61	9.81658
2036.54	9.87768
2039.48	11.5141
2042.41	11.5347
2045.34	12.2131
2048.27	12.0958
2051.19	10.1284
2054.12	10.9674
2057.05	10.7676
2059.97	12.396
2062.9	12.977
2065.82	14.4297
2068.74	14.7551
2071.66	15.1717
2074.58	14.5015
2077.5	15.4073
2080.41	15.2016
2083.33	15.7603
2086.24	15.9849
2089.16	16.2842
2092.07	18.5693
2094.98	19.1008
2097.89	20.6851
2100.8	22.4102
2103.71	22.7301
2106.62	25.8715
2109.53	27.2229
2112.43	28.8725
2115.33	30.271
2118.24	32.9883
2121.14	34.7445
2124.04	37.0721
2126.94	40.2519
2129.84	43.1411
2132.74	46.5379
2135.63	49.4982
2138.53	53.4175
2141.43	56.2019
2144.32	60.2521
2147.21	62.8494
2150.1	66.9928
2152.99	70.09
2155.88	74.2591
2158.77	76.7387
2161.66	80.1564
2164.55	81.0154
2167.43	82.9336
2170.31	83.9981
2173.2	84.8378
2176.08	86.001
2178.96	86.8866
2181.84	86.6647
2184.72	85.0926
2187.6	83.7962
2190.47	81.982
2193.35	78.9707
2196.23	76.5469
2199.1	72.6318
2201.97	69.361
2204.84	64.9872
2207.71	60.7547
2210.58	56.1172
2213.45	53.0432
2216.32	48.1993
2219.19	44.5577
2222.05	41.4515
2224.92	38.6821
2227.78	36.3031
2230.64	34.5697
2233.5	32.9509
2236.36	31.5817
2239.22	30.5748
2242.08	28.2788
2244.94	27.1817
2247.79	26.6258
2250.65	26.2045
2253.5	25.4948
2256.36	23.6506
2259.21	22.7146
2262.06	22.6361
2264.91	22.3388
2267.76	21.8308
2270.6	20.0677
2273.45	17.6551
2276.3	16.2163
2279.14	14.9459
2281.98	14.3516
2284.83	13.4785
2287.67	12.4298
2290.51	13.4237
2293.35	12.3728
2296.19	13.7257
2299.02	14.3593
2301.86	15.1294
2304.7	15.2742
2307.53	16.0624
2310.36	15.1475
2313.2	14.9919
2316.03	15.5041
2318.86	13.9141
2321.69	13.2266
2324.51	12.8366
2327.34	10.7951
2330.17	9.47596
2332.99	9.75282
2335.82	8.65227
2338.64	6.48424
2341.46	4.30289
2344.28	3.56832
2347.1	3.05565
2349.92	1.88877
2352.74	0.595652
2355.56	-0.616127
2358.37	-1.58921
2361.19	-2.41558
2364	-1.18909
2366.82	0.739282
2369.63	0.916304
2372.44	1.26133
2375.25	1.62422
2378.06	2.19449
2380.86	2.01611
2383.67	2.32415
2386.48	3.03523
2389.28	3.58632
2392.09	4.40983
2394.89	5.34132
2397.69	4.20378
2400.49	5.47414
2403.29	6.51004
2406.09	7.57956
2408.89	8.11815
2411.69	9.04629
2414.48	10.3927
2417.28	10.8823
2420.07	11.8991
2422.86	11.8256
2425.65	12.4458
2428.45	11.9161
2431.23	12.6025
2434.02	12.2411
2436.81	11.2897
2439.6	9.21908
2442.38	7.78149
2445.17	6.82342
2447.95	6.02992
2450.73	3.61935
2453.52	3.76046
2456.3	2.27713
2459.08	1.0248
2461.85	0.0779982
2464.63	-0.930343
2467.41	-1.48176
2470.19	-0.992863
2472.96	-1.21718
2475.73	-0.476606
2478.51	0.380305
2481.28	0.713326
2484.05	1.53211
2486.82	1.94114
2489.59	3.14071
2492.35	4.20723
2495.12	3.75038
2497.89	5.25423
2500.65	5.77603
2503.42	5.92676
2506.18	5.60972
2508.94	5.71683
2511.7	5.51633
2514.46	5.86051
2517.22	4.76625
2519.98	5.28573
2522.73	5.9353
2525.49	5.90323
2528.25	5.74963
2531	5.78551
2533.75	6.27413
2536.5	6.11813
2539.25	5.89707
2542.01	7.17507
2544.75	7.1674
2547.5	7.95739
2550.25	8.84943
2553	7.8613
2555.74	7.89601
2558.49	7.82562
2561.23	8.82351
2563.97	10.2964
2566.71	10.3393
2569.45	10.414
2572.19	10.8368
2574.93	11.6904
2577.67	11.6395
2580.4	12.6327
2583.14	12.8732
2585.87	12.4122
2588.6	12.4865
2591.34	11.5149
2594.07	11.5612
2596.8	10.7782
2599.53	10.3999
2602.26	10.2094
2604.98	9.84239
2607.71	9.88259
2610.44	9.50519
2613.16	9.56767
2615.88	8.55831
2618.61	8.01827
2621.33	6.86876
2624.05	7.2438
2626.77	8.02966
2629.49	8.70485
2632.21	9.66613
2634.92	10.4405
2637.64	12.1086
2640.35	14.0007
2643.07	14.7296
2645.78	15.3513
2648.49	15.765
2651.2	15.6746
2653.91	15.8687
2656.62	16.8959
2659.33	16.1532
2662.04	16.3253
2664.74	17.2205
2667.45	16.0909
2670.15	15.6274
2672.86	15.7893
2675.56	14.4762
2678.26	13.94
2680.96	11.5979
2683.66	9.642
2686.36	9.26569
2689.06	8.61028
2691.75	8.12189
2694.45	8.13649
2697.14	10.3471
2699.84	10.4935
2702.53	12.0395
2705.22	13.4494
2707.91	15.4358
2710.6	15.6912
2713.29	17.7066
2715.98	18.9689
2718.67	20.4289
2721.35	22.4485
2724.04	23.5993
2726.72	24.0071
2729.4	24.7249
2732.09	24.7777
2734.77	23.828
2737.45	23.2702
2740.13	22.5248
2742.81	20.6993
2745.48	18.9721
2748.16	16.0397
2750.84	14.0164
2753.51	12.46
2756.19	12.1086
2758.86	12.1827
2761.53	11.157
2764.2	9.73183
2766.87	8.02145
2769.54	6.91875
2772.21	5.51063
2774.88	4.91741
2777.54	3.44936
2780.21	3.89758
2782.87	3.59482
2785.53	3.35911
2788.2	3.38813
2790.86	2.9713
2793.52	2.44317
2796.18	2.09911
2798.84	2.51993
2801.49	2.74369
2804.15	3.71067
2806.81	2.78035
2809.46	2.05112
2812.12	2.11594
2814.77	2.29165
2817.42	5.2301
2820.07	8.48871
2822.72	13.7648
2825.37	18.1337
2828.02	24.4915
2830.67	31.3246
2833.31	38.828
2835.96	47.41
2838.61	57.9374
2841.25	70.0338
2843.89	83.6729
2846.53	97.0421
2849.17	112.168
2851.81	128.952
2854.45	144.981
2857.09	161.051
2859.73	176.802
2862.36	191.36
2865	206.999
2867.64	220.519
2870.27	232.426
2872.9	242.445
2875.53	252.196
2878.16	261.833
2880.79	271.625
2883.42	279.397
2886.05	288.617
2888.68	296.697
2891.3	305.172
2893.93	314.143
2896.55	323.382
2899.18	334.857
2901.8	347.977
2904.42	363.091
2907.04	380.762
2909.66	397.233
2912.28	415.701
2914.9	436.03
2917.51	455.025
2920.13	470.776
2922.74	484.517
2925.36	494.505
2927.97	501.499
2930.59	504.852
2933.2	503.538
2935.81	498.442
2938.42	491.542
2941.02	479.052
2943.63	465.616
2946.24	448.198
2948.85	430.235
2951.45	410.321
2954.05	387.955
2956.66	368.318
2959.26	348.701
2961.86	328.485
2964.46	309.338
2967.06	291.822
2969.66	277.651
2972.26	262.763
2974.85	248.434
2977.45	235.318
2980.05	222.872
2982.64	208.428
2985.23	193.633
2987.83	178.174
2990.42	162.574
2993.01	148.123
2995.6	133.256
2998.19	117.73
3000.77	104.283
3003.36	90.5926
3005.95	77.8074
3008.53	65.2068
3011.12	54.7583
3013.7	44.9185
3016.28	34.1894
3018.86	26.9713
3021.44	20.4401
3024.02	13.5358
3026.6	9.45213
3029.18	7.68844
3031.76	4.87897
3034.33	4.53671
3036.91	3.82285
3039.48	3.37439
3042.05	4.38604
3044.63	6.79115
3047.2	8.29337
3049.77	9.58311
3052.34	10.5864
3054.91	11.6352
3057.48	12.815
3060.04	13.8305
3062.61	14.0608
3065.17	13.8178
3067.74	13.1182
3070.3	12.3169
3072.87	10.8319
3075.43	9.06563
3077.99	7.02371
3080.55	5.17737
3083.11	4.23229
3085.67	3.50151
3088.22	2.05447
3090.78	-0.0174722
3093.34	-1.45364
3095.89	-1.37813
3098.44	-1.35361
3101	-1.18422
3103.55	-0.0411572
3106.1	1.37219
3108.65	2.10192
3111.2	3.44916
3113.75	4.30453
3116.3	5.17293
3118.84	6.29288
3121.39	7.8071
3123.93	8.63951
3126.48	10.1086
3129.02	11.6123
3131.56	13.2798
3134.1	13.9717
3136.64	15.2385
3139.18	17.6863
3141.72	19.0257
3144.26	19.7383
3146.8	19.2992
3149.33	20.2622