File: data/Raman/poly_smoothed/Mbcal_20_25_01_1x_45s_532 nm_x100_100%_600 gr_mm_01.txt
#Acq. time (s)=	45
#Accumulations=	2
#Range (cm-¹)=	200...3150
#Windows=	2
#Auto scanning=	Off
#Autofocus=	Off
#Macrospot=	Off
#AutoExposure=	Off
#Spike filter=	Multiple accum.
#Delay time (s)=	0
#Binning=	1
#Readout mode=	Signal
#DeNoise=	Off
#ICS correction=	On
#Dark correction=	Off
#Inst. Process=	Off
#Detector Gain=	Best Dynamic Range
#Detector ADC=	20 kHz
#Detector temperature (°C)=	-69.85
#Instrument=	LabRAM HR Evol
#Detector=	Synapse
#Objective=	x100
#Grating=	600 gr/mm
#ND Filter=	100%
#Laser (nm)=	532
#Hole=	100.021
#Range=	Auto
#Laser Pol.=	No
#Raman. Pol.=	No
#Laser Pol. (°)=	-0.0007625
#Raman Pol. (°)=	89.9995
#Collection=	Microscope
#StageXY=	Marzhauser
#StageZ=	Marzhauser
#X (µm)=	-1211.4
#Y (µm)=	1297
#Z (µm)=	578.1
#Full time(mm:ss)=	3:10
#Project=
#Sample=
#Site=
#Title=	Mbcal_20_25_01_2x_45s_532 nm_x100_100%_600 gr_mm
#Remark=
#Date=	18.07.2022 09:28
#Acquired=	18.07.2022 09:28:55
#Edit:Spike=	18.07.2022 09:30:48
#Edit:Spike=	18.07.2022 09:30:49
#Edit:Spike=	18.07.2022 09:30:49
#Edit:Spike=	18.07.2022 09:30:50
#Edit:Spike=	18.07.2022 09:30:51
#Edit:Spike=	18.07.2022 09:30:52
#Edit:Spike=	18.07.2022 09:30:53
#Edit:Spike=	18.07.2022 09:30:54
#Edit:Spike=	18.07.2022 09:30:54
#Edit:Spike=	18.07.2022 09:30:55
#Edit:Spike=	18.07.2022 09:30:56
#Edit:Spike=	18.07.2022 09:30:56
#Edit:Spike=	18.07.2022 09:30:57
#Edit:Spike=	18.07.2022 09:30:58
#Edit:Spike=	18.07.2022 09:30:59
#Edit:Spike=	18.07.2022 09:31:00
#Edit:Spike=	18.07.2022 09:31:01
#Edit:Spike=	18.07.2022 09:31:02
#Edit:Spike=	18.07.2022 09:31:02
#Edit:Spike=	18.07.2022 09:31:04
#Base:Fit=	10.08.2022 10:55:08
#Base:Sub=	10.08.2022 10:55:14
#Filter:Polynom=	16.08.2022 09:24:11
#Filter:Polynom=	16.08.2022 10:07:27
#AxisType[0]=Intens
#AxisUnit[0]=Cnt
#AxisType[1]=Spectr
#AxisUnit[1]=1/cm
200.419	20.2989
204.048	17.5724
207.678	14.8485
211.304	12.6136
214.928	9.52487
218.554	9.79034
222.176	10.0952
225.798	12.8482
229.417	15.9579
233.035	18.1481
236.653	18.3279
240.268	19.0524
243.881	19.9965
247.493	22.349
251.103	25.0298
254.715	27.8001
258.322	30.7752
261.929	36.3184
265.534	46.7989
269.137	53.5515
272.739	60.5695
276.34	66.7346
279.939	72.0166
283.537	77.7461
287.134	83.7213
290.729	89.7515
294.323	96.8767
297.913	104.836
301.504	109.63
305.093	114.949
308.682	119.876
312.268	123.034
315.852	122.861
319.436	119.499
323.018	115.441
326.597	111.585
330.177	106.717
333.753	102.675
337.331	96.561
340.906	91.04
344.478	85.8564
348.051	81.2737
351.621	78.28
355.189	72.4578
358.757	66.9576
362.323	61.9184
365.889	59.2743
369.451	56.9795
373.012	53.5864
376.574	50.9112
380.133	52.6652
383.69	51.5867
387.245	48.9808
390.8	46.0587
394.353	43.4789
397.906	40.2808
401.456	36.9646
405.005	32.9264
408.552	28.2398
412.099	25.4989
415.643	24.0827
419.187	20.8952
422.728	17.7107
426.269	15.3231
429.806	12.9891
433.344	11.4452
436.881	9.75037
440.416	7.46548
443.949	6.84378
447.48	8.09815
451.011	9.21765
454.541	9.96035
458.069	8.36268
461.594	7.78213
465.119	8.01695
468.642	8.47162
472.165	8.17766
475.684	7.77111
479.204	9.12729
482.721	8.27512
486.239	8.02499
489.753	7.33587
493.268	9.5219
496.779	12.2684
500.289	13.7107
503.8	13.7383
507.307	15.0558
510.813	15.1839
514.32	17.811
517.823	16.8796
521.325	16.9483
524.826	17.404
528.325	18.2099
531.823	19.8346
535.32	19.1985
538.815	18.2203
542.309	17.4545
545.802	15.9244
549.293	15.6123
552.783	15.0005
556.271	13.1832
559.759	11.5864
563.245	12.2362
566.729	12.799
570.213	12.7552
573.693	12.3971
577.173	13.0837
580.652	11.4613
584.13	10.6745
587.605	8.71587
591.08	8.05089
594.552	8.50607
598.025	10.7364
601.496	11.978
604.964	10.5234
608.433	11.6442
611.898	13.4804
615.364	14.2591
618.827	16.577
622.288	15.1024
625.75	17.6195
629.209	18.6808
632.667	21.4976
636.125	20.9311
639.58	23.6259
643.033	22.972
646.485	24.7582
649.936	27.5889
653.388	29.3533
656.836	30.4039
660.283	32.1895
663.728	35.8417
667.173	36.7757
670.616	39.7352
674.057	41.1745
677.498	44.2024
680.937	48.7149
684.375	54.4584
687.809	59.2594
691.244	62.444
694.678	68.1626
698.111	72.2725
701.54	73.8249
704.97	75.4747
708.398	77.8304
711.826	76.6249
715.25	74.4632
718.675	73.1743
722.096	71.2749
725.518	68.8536
728.937	65.388
732.357	62.1676
735.773	60.5858
739.19	58.5824
742.604	56.6864
746.018	53.2398
749.429	50.0398
752.839	47.6513
756.248	46.5578
759.657	47.8739
763.063	49.104
766.468	53.1882
769.871	58.0779
773.273	61.2367
776.676	65.2894
780.075	69.136
783.474	72.826
786.871	75.6607
790.266	78.9851
793.661	79.7599
797.054	82.3273
800.446	84.8431
803.834	88.3649
807.224	88.6887
810.612	87.1131
813.998	86.0682
817.384	85.0311
820.766	85.9573
824.149	85.1897
827.531	84.6496
830.909	83.8094
834.288	81.9553
837.666	80.9967
841.041	78.6481
844.416	76.4638
847.788	72.8586
851.161	72.867
854.53	70.1724
857.901	67.9217
861.268	68.1113
864.633	67.0966
868	66.0479
871.363	62.646
874.725	61.0054
878.088	58.2601
881.447	56.8673
884.805	55.5812
888.162	54.1936
891.518	51.0099
894.872	49.6163
898.225	50.5145
901.577	51.0736
904.928	51.7526
908.277	51.5918
911.625	51.0019
914.972	51.477
918.318	50.3276
921.662	51.1073
925.005	50.4436
928.347	46.7632
931.686	46.812
935.025	45.0524
938.363	44.7962
941.698	44.4487
945.034	43.7059
948.368	40.3077
951.699	36.9596
955.031	34.1714
958.36	31.6441
961.689	28.8266
965.016	26.8191
968.343	26.2075
971.666	23.8383
974.991	23.1423
978.312	21.7673
981.632	20.6857
984.953	19.5955
988.27	19.1316
991.587	17.5996
994.902	16.9316
998.216	15.6895
1001.53	14.9412
1004.84	13.668
1008.15	14.1165
1011.46	14.841
1014.77	15.3015
1018.07	14.2184
1021.38	15.5581
1024.68	17.4
1027.99	15.306
1031.29	12.9288
1034.59	14.332
1037.89	13.6222
1041.18	13.3916
1044.48	13.6928
1047.77	13.8223
1051.07	13.665
1054.36	13.2997
1057.65	13.529
1060.94	15.0399
1064.23	18.0405
1067.52	20.3195
1070.8	22.913
1074.09	25.2713
1077.37	27.0919
1080.65	28.8559
1083.93	29.5823
1087.21	31.5188
1090.49	34.2973
1093.77	34.8591
1097.04	35.8444
1100.32	37.1651
1103.59	35.9681
1106.86	34.2956
1110.13	32.8278
1113.4	32.1731
1116.67	30.1991
1119.94	27.0349
1123.2	24.6779
1126.47	23.4297
1129.73	20.4613
1132.99	19.2124
1136.25	18.2567
1139.51	17.3586
1142.77	17.9755
1146.03	17.3584
1149.28	17.4443
1152.54	15.814
1155.79	12.998
1159.04	10.2159
1162.29	8.55879
1165.54	6.57729
1168.79	6.67751
1172.04	4.67021
1175.28	4.88714
1178.53	4.25977
1181.77	3.10097
1185.01	4.70371
1188.25	5.28174
1191.49	6.07342
1194.73	5.193
1197.96	6.65643
1201.2	6.57692
1204.43	9.38864
1207.66	10.182
1210.9	11.0482
1214.13	12.3911
1217.36	12.2085
1220.58	14.0314
1223.81	15.0736
1227.04	16.315
1230.26	17.491
1233.48	16.8427
1236.71	16.4121
1239.93	16.3235
1243.14	18.2412
1246.36	19.2748
1249.58	20.5905
1252.8	20.8601
1256.01	21.7811
1259.22	24.1422
1262.43	24.0076
1265.64	26.2081
1268.85	26.9183
1272.06	28.4838
1275.27	30.6968
1278.48	33.2853
1281.68	34.514
1284.88	37.1912
1288.08	39.1095
1291.28	41.3818
1294.48	42.4119
1297.68	43.6516
1300.88	47.4086
1304.07	49.3496
1307.27	49.3589
1310.46	50.7637
1313.65	51.6335
1316.85	51.3403
1320.03	51.7561
1323.22	53.0351
1326.41	53.4568
1329.6	53.1324
1332.78	51.5726
1335.96	51.4803
1339.15	49.6685
1342.33	49.4741
1345.51	50.5615
1348.69	50.6495
1351.86	49.3862
1355.04	47.6153
1358.21	45.4304
1361.39	45.3624
1364.56	44.7797
1367.73	43.2643
1370.9	40.9415
1374.07	40.0012
1377.24	41.4081
1380.41	39.4641
1383.57	40.6618
1386.73	40.0776
1389.9	39.764
1393.06	40.2772
1396.22	39.6913
1399.38	39.7871
1402.54	39.132
1405.69	39.164
1408.85	40.8772
1412	42.2635
1415.16	44.184
1418.31	46.9665
1421.46	48.8136
1424.61	53.5886
1427.76	57.373
1430.9	60.649
1434.05	63.7867
1437.2	68.032
1440.34	70.4619
1443.48	71.9488
1446.62	73.0967
1449.76	74.0915
1452.9	77.7717
1456.04	80.1322
1459.17	82.2594
1462.31	83.9887
1465.44	83.7456
1468.58	85.8727
1471.71	86.0658
1474.84	86.6278
1477.97	86.4045
1481.1	85.4899
1484.22	86.5641
1487.35	85.0816
1490.47	81.6973
1493.59	79.2071
1496.72	75.4679
1499.84	72.3112
1502.96	70.2724
1506.08	66.3362
1509.19	59.0206
1512.31	55.8645
1515.42	50.0333
1518.54	45.3653
1521.65	41.4816
1524.76	37.8405
1527.87	36.328
1530.98	36.7418
1534.09	34.9667
1537.2	33.6911
1540.3	34.5369
1543.41	36.2256
1546.51	36.3613
1549.61	35.487
1552.71	35.8942
1555.81	35.391
1558.91	37.1595
1562.01	37.7109
1565.1	36.245
1568.2	37.3623
1571.29	39.9285
1574.38	42.0782
1577.48	43.8882
1580.57	46.3148
1583.65	49.4438
1586.74	50.7389
1589.83	53.3228
1592.92	53.6504
1596	55.5427
1599.08	57.332
1602.16	55.8819
1605.24	56.8476
1608.32	54.5293
1611.4	52.6694
1614.48	50.2596
1617.56	49.349
1620.63	47.807
1623.71	44.7664
1626.78	42.5527
1629.85	39.0619
1632.92	39.0437
1635.99	40.2028
1639.06	38.79
1642.12	38.5812
1645.19	36.7794
1648.25	38.0475
1651.32	36.8819
1654.38	36.7469
1657.44	35.6859
1660.5	34.638
1663.56	34.4888
1666.62	33.649
1669.67	31.7168
1672.73	29.1705
1675.79	27.531
1678.84	25.1123
1681.89	23.6317
1684.94	22.3732
1687.99	21.0673
1691.04	19.224
1694.08	18.9876
1697.13	18.3032
1700.18	15.6449
1703.22	13.254
1706.26	13.0357
1709.3	12.295
1712.35	11.1871
1715.39	9.39675
1718.42	7.41562
1721.46	5.40006
1724.5	4.67152
1727.53	4.32347
1730.56	2.84165
1733.6	4.23417
1736.63	4.42428
1739.66	4.85085
1742.69	4.29482
1745.71	4.61111
1748.74	5.95947
1751.77	5.85916
1754.79	6.22861
1757.81	6.38054
1760.84	6.2009
1763.86	5.63139
1766.88	6.03373
1769.9	4.92878
1772.91	5.08026
1775.93	3.49716
1778.95	2.91978
1781.96	2.28079
1784.97	2.584
1787.99	1.52061
1791	1.83622
1794.01	1.09465
1797.01	-0.986638
1800.02	0.198709
1803.03	0.0713349
1806.03	-0.150614
1809.04	-0.435869
1812.04	0.124581
1815.04	2.91146
1818.04	3.64564
1821.04	3.06741
1824.04	3.74505
1827.04	3.26114
1830.03	2.57745
1833.03	3.26556
1836.02	4.25072
1839.02	4.12524
1842.01	4.51852
1845	5.30476
1847.99	5.91492
1850.98	5.81329
1853.96	5.39479
1856.95	5.04772
1859.94	5.10835
1862.92	4.61105
1865.9	5.122
1868.88	5.75961
1871.86	4.94276
1874.84	6.17783
1877.82	6.143
1880.8	7.53964
1882.58	8.16642
1885.57	9.06559
1888.56	9.34069
1891.54	8.44169
1894.53	9.16341
1897.51	9.74467
1900.5	9.79211
1903.48	9.69062
1906.46	10.0803
1909.44	9.9252
1912.42	9.66602
1915.4	10.8157
1918.37	11.7479
1921.35	11.8711
1924.32	12.202
1927.3	11.1271
1930.27	10.0803
1933.24	10.0423
1936.21	9.0849
1939.18	9.75403
1942.15	7.37476
1945.11	6.41689
1948.08	7.77481
1951.04	6.4382
1954.01	5.11404
1956.97	2.99058
1959.93	3.66524
1962.89	2.86517
1965.85	3.57865
1968.81	4.73746
1971.77	5.70805
1974.72	4.64345
1977.68	5.14096
1980.63	6.04375
1983.58	6.39489
1986.53	6.27709
1989.48	8.42879
1992.43	8.30695
1995.38	7.80632
1998.33	8.09701
2001.27	8.05278
2004.22	6.50269
2007.16	5.56154
2010.11	5.4066
2013.05	6.2284
2015.99	6.39372
2018.93	6.82374
2021.87	3.75286
2024.8	3.27974
2027.74	2.51085
2030.68	4.35325
2033.61	6.16085
2036.54	6.62439
2039.48	8.08537
2042.41	8.41307
2045.34	8.27921
2048.27	9.79262
2051.19	10.4506
2054.12	10.9019
2057.05	12.0476
2059.97	11.3648
2062.9	11.3873
2065.82	10.3555
2068.74	10.4617
2071.66	10.8508
2074.58	10.2172
2077.5	10.262
2080.41	11.4611
2083.33	12.2482
2086.24	11.647
2089.16	11.6709
2092.07	10.3414
2094.98	9.82317
2097.89	10.5638
2100.8	10.0064
2103.71	9.93119
2106.62	9.66141
2109.53	9.11801
2112.43	9.53016
2115.33	11.0359
2118.24	12.2235
2121.14	12.599
2124.04	13.259
2126.94	14.1284
2129.84	13.5038
2132.74	13.0657
2135.63	14.8772
2138.53	14.9621
2141.43	17.3102
2144.32	18.0899
2147.21	17.6404
2150.1	19.8119
2152.99	20.167
2155.88	21.8244
2158.77	23.5485
2161.66	24.429
2164.55	23.9577
2167.43	24.7925
2170.31	25.091
2173.2	25.3575
2176.08	25.9214
2178.96	26.9545
2181.84	27.3187
2184.72	27.4228
2187.6	27.2873
2190.47	27.5114
2193.35	27.4608
2196.23	26.2354
2199.1	24.2689
2201.97	22.7829
2204.84	22.2157
2207.71	22.5809
2210.58	20.4961
2213.45	19.07
2216.32	17.7176
2219.19	17.9178
2222.05	16.9092
2224.92	16.9257
2227.78	16.1494
2230.64	14.9917
2233.5	14.8695
2236.36	14.6388
2239.22	14.2817
2242.08	14.6701
2244.94	13.8216
2247.79	13.2162
2250.65	13.1497
2253.5	13.0464
2256.36	12.7243
2259.21	13.1732
2262.06	13.7525
2264.91	11.6109
2267.76	10.866
2270.6	9.91704
2273.45	9.23063
2276.3	9.53106
2279.14	9.63169
2281.98	9.68369
2284.83	10.1001
2287.67	9.78646
2290.51	9.8545
2293.35	9.73016
2296.19	9.74115
2299.02	10.6185
2301.86	11.2688
2304.7	10.8171
2307.53	11.0999
2310.36	11.4994
2313.2	11.013
2316.03	11.8981
2318.86	13.4296
2321.69	13.7384
2324.51	14.9215
2327.34	14.076
2330.17	13.8436
2332.99	13.3812
2335.82	12.2113
2338.64	11.0645
2341.46	9.59131
2344.28	8.96314
2347.1	8.40638
2349.92	7.53863
2352.74	5.10553
2355.56	3.73079
2358.37	1.91124
2361.19	1.4603
2364	1.83198
2366.82	1.9387
2369.63	1.43064
2372.44	1.7563
2375.25	3.11961
2378.06	3.49962
2380.86	4.26081
2383.67	5.71266
2386.48	5.79268
2389.28	6.30164
2392.09	6.76998
2394.89	7.40092
2397.69	8.6609
2400.49	9.50369
2403.29	10.4093
2406.09	9.65841
2408.89	9.66415
2411.69	7.69842
2414.48	8.00762
2417.28	6.26523
2420.07	3.5081
2422.86	2.62569
2425.65	1.78099
2428.45	1.15692
2431.23	1.17964
2434.02	1.68873
2436.81	1.2431
2439.6	2.08805
2442.38	2.67543
2445.17	3.03559
2447.95	2.19703
2450.73	2.73495
2453.52	3.48389
2456.3	4.49948
2459.08	4.97303
2461.85	5.7327
2464.63	5.46225
2467.41	6.35656
2470.19	5.60849
2472.96	6.66604
2475.73	5.14177
2478.51	5.85547
2481.28	5.75407
2484.05	5.25226
2486.82	2.99327
2489.59	2.98212
2492.35	3.7964
2495.12	3.3084
2497.89	3.60311
2500.65	3.62244
2503.42	2.63676
2506.18	2.45459
2508.94	2.20111
2511.7	3.59136
2514.46	4.10014
2517.22	4.9295
2519.98	4.35919
2522.73	4.22593
2525.49	3.52031
2528.25	3.86708
2531	5.29767
2533.75	6.09451
2536.5	5.91699
2539.25	6.86874
2542.01	6.17514
2544.75	7.01981
2547.5	7.6712
2550.25	6.29237
2553	4.86828
2555.74	5.19831
2558.49	6.66059
2561.23	6.28442
2563.97	5.76283
2566.71	5.13886
2569.45	3.92583
2572.19	4.52806
2574.93	4.73386
2577.67	6.00805
2580.4	6.87573
2583.14	5.56925
2585.87	5.80824
2588.6	6.01818
2591.34	6.77984
2594.07	6.24528
2596.8	7.2407
2599.53	7.4395
2602.26	6.88516
2604.98	6.34853
2607.71	6.75272
2610.44	5.89323
2613.16	5.89332
2615.88	6.21232
2618.61	5.74285
2621.33	6.2495
2624.05	6.71211
2626.77	6.25328
2629.49	5.58749
2632.21	4.64082
2634.92	4.65645
2637.64	5.62083
2640.35	5.28305
2643.07	5.02462
2645.78	6.09101
2648.49	6.03297
2651.2	6.19446
2653.91	6.31849
2656.62	6.9691
2659.33	6.97002
2662.04	6.65677
2664.74	7.73673
2667.45	8.16613
2670.15	9.23528
2672.86	11.4421
2675.56	12.5776
2678.26	13.5926
2680.96	14.1754
2683.66	14.9426
2686.36	13.8963
2689.06	13.9596
2691.75	13.5082
2694.45	13.5287
2697.14	12.9886
2699.84	12.5592
2702.53	12.4693
2705.22	12.1372
2707.91	12.1718
2710.6	12.3004
2713.29	11.2042
2715.98	11.0653
2718.67	8.95606
2721.35	8.79575
2724.04	8.24995
2726.72	8.87697
2729.4	9.19246
2732.09	9.39001
2734.77	10.7154
2737.45	10.3835
2740.13	9.60905
2742.81	9.65472
2745.48	9.71974
2748.16	9.28066
2750.84	7.99979
2753.51	8.49285
2756.19	8.6338
2758.86	6.86884
2761.53	6.65487
2764.2	7.01728
2766.87	6.05657
2769.54	6.22368
2772.21	6.08534
2774.88	5.82979
2777.54	5.18599
2780.21	5.29274
2782.87	6.54238
2785.53	7.45407
2788.2	8.42643
2790.86	7.70136
2793.52	7.76908
2796.18	6.3912
2798.84	6.19897
2801.49	6.53018
2804.15	5.11946
2806.81	6.3153
2809.46	6.03404
2812.12	5.1401
2814.77	5.21917
2817.42	7.12066
2820.07	8.13853
2822.72	10.5105
2825.37	12.6942
2828.02	14.8585
2830.67	17.6154
2833.31	21.5868
2835.96	26.0788
2838.61	31.4481
2841.25	35.7408
2843.89	40.1154
2846.53	45.1151
2849.17	49.3324
2851.81	50.8651
2854.45	55.4936
2857.09	58.5483
2859.73	61.5114
2862.36	64.6151
2865	68.4732
2867.64	70.721
2870.27	73.1169
2872.9	74.1548
2875.53	74.9612
2878.16	77.1836
2880.79	79.3691
2883.42	81.0005
2886.05	82.6945
2888.68	84.5757
2891.3	86.5852
2893.93	89.0841
2896.55	92.5741
2899.18	94.671
2901.8	97.7021
2904.42	100.115
2907.04	103.755
2909.66	107.09
2912.28	111.07
2914.9	115.003
2917.51	118.778
2920.13	121.886
2922.74	123.761
2925.36	125.539
2927.97	125.645
2930.59	125.767
2933.2	125.873
2935.81	124.14
2938.42	120.371
2941.02	115.006
2943.63	110.932
2946.24	106.783
2948.85	102.47
2951.45	96.9438
2954.05	92.4905
2956.66	86.7522
2959.26	80.8602
2961.86	75.4094
2964.46	71.5594
2967.06	66.2837
2969.66	62.6106
2972.26	59.4697
2974.85	56.3183
2977.45	52.3699
2980.05	49.3531
2982.64	45.0085
2985.23	41.7229
2987.83	38.3729
2990.42	34.5992
2993.01	31.1083
2995.6	28.956
2998.19	25.5728
3000.77	21.6606
3003.36	17.9544
3005.95	15.1974
3008.53	14.1947
3011.12	12.8124
3013.7	9.59383
3016.28	6.54552
3018.86	5.50876
3021.44	3.84976
3024.02	3.26504
3026.6	3.03518
3029.18	1.88749
3031.76	2.2094
3034.33	2.80874
3036.91	4.3323
3039.48	3.62459
3042.05	4.46004
3044.63	5.27872
3047.2	5.21903
3049.77	5.91549
3052.34	5.53304
3054.91	5.73828
3057.48	5.84973
3060.04	5.70044
3062.61	5.91734
3065.17	4.69064
3067.74	4.88613
3070.3	3.99127
3072.87	3.57078
3075.43	1.98301
3077.99	1.13604
3080.55	0.983256
3083.11	0.588965
3085.67	-0.420635
3088.22	-0.00316361
3090.78	0.27994
3093.34	0.155276
3095.89	0.0997776
3098.44	-0.303148
3101	0.217264
3103.55	0.418045
3106.1	-0.195729
3108.65	0.985294
3111.2	1.65504
3113.75	1.84065
3116.3	1.20314
3118.84	0.72762
3121.39	1.27669
3123.93	0.94583
3126.48	1.29553
3129.02	1.52466
3131.56	1.83728
3134.1	1.76454
3136.64	3.0884
3139.18	3.16534
3141.72	3.45934
3144.26	3.80386
3146.8	4.22431
3149.33	6.48318