File: data/Raman/poly_smoothed/Mbcal_20_25_29_1x_45s_532 nm_x100_100%_600 gr_mm_01.txt
#Acq. time (s)=	45
#Accumulations=	2
#Range (cm-¹)=	200...3150
#Windows=	2
#Auto scanning=	Off
#Autofocus=	Off
#Macrospot=	Off
#AutoExposure=	Off
#Spike filter=	Multiple accum.
#Delay time (s)=	0
#Binning=	1
#Readout mode=	Signal
#DeNoise=	Off
#ICS correction=	On
#Dark correction=	Off
#Inst. Process=	Off
#Detector Gain=	Best Dynamic Range
#Detector ADC=	20 kHz
#Detector temperature (°C)=	-69.85
#Instrument=	LabRAM HR Evol
#Detector=	Synapse
#Objective=	x100
#Grating=	600 gr/mm
#ND Filter=	100%
#Laser (nm)=	532
#Hole=	100.021
#Range=	Auto
#Laser Pol.=	No
#Raman. Pol.=	No
#Laser Pol. (°)=	-0.0007625
#Raman Pol. (°)=	89.9995
#Collection=	Microscope
#StageXY=	Marzhauser
#StageZ=	Marzhauser
#X (µm)=	-1149.3
#Y (µm)=	1306.7
#Z (µm)=	578
#Full time(mm:ss)=	3:18
#Project=
#Sample=
#Site=
#Title=	Mbcal_20_25_29_2x_45s_532 nm_x100_100%_600 gr_mm
#Remark=
#Date=	18.07.2022 11:49
#Acquired=	18.07.2022 11:49:56
#Base:Fit=	10.08.2022 10:55:08
#Base:Sub=	10.08.2022 10:55:14
#Filter:Polynom=	16.08.2022 10:07:28
#AxisType[0]=Intens
#AxisUnit[0]=Cnt
#AxisType[1]=Spectr
#AxisUnit[1]=1/cm
200.419	40.9094
204.048	31.5266
207.678	24.78
211.304	20.2864
214.928	18.5705
218.554	16.0827
222.176	13.0952
225.798	11.2515
229.417	9.77063
233.035	8.93278
236.653	7.04481
240.268	8.48061
243.881	9.36026
247.493	8.8458
251.103	8.89526
254.715	9.19894
258.322	10.2881
261.929	11.8924
265.534	11.9987
269.137	11.7991
272.739	12.1763
276.34	10.4527
279.939	8.85937
283.537	7.46961
287.134	7.27289
290.729	7.00099
294.323	7.41908
297.913	8.74529
301.504	8.65429
305.093	9.13634
308.682	8.47366
312.268	8.64476
315.852	9.08227
319.436	10.0992
323.018	11.7633
326.597	13.4539
330.177	15.1867
333.753	12.9954
337.331	12.8407
340.906	11.9198
344.478	12.027
348.051	11.0814
351.621	10.0867
355.189	9.62404
358.757	9.98822
362.323	7.85492
365.889	4.75041
369.451	3.81156
373.012	4.0443
376.574	3.08185
380.133	2.62727
383.69	3.89464
387.245	3.39792
390.8	4.13803
394.353	4.85382
397.906	5.01505
401.456	5.58207
405.005	5.80419
408.552	7.92039
412.099	9.16702
415.643	7.44945
419.187	7.20852
422.728	7.67747
426.269	6.88598
429.806	5.60884
433.344	5.56385
436.881	5.33873
440.416	5.27499
443.949	5.64861
447.48	4.32534
451.011	2.87938
454.541	3.98749
458.069	4.64215
461.594	4.93353
465.119	5.01145
468.642	6.15799
472.165	7.1933
475.684	7.95512
479.204	10.2178
482.721	11.7707
486.239	12.6968
489.753	13.6553
493.268	15.086
496.779	17.0644
500.289	17.821
503.8	19.6509
507.307	20.9775
510.813	22.6502
514.32	22.0107
517.823	24.0864
521.325	23.895
524.826	24.0088
528.325	23.937
531.823	25.6693
535.32	25.002
538.815	25.3728
542.309	24.9496
545.802	25.4427
549.293	24.6189
552.783	24.1419
556.271	22.7602
559.759	21.5855
563.245	21.2364
566.729	19.1475
570.213	14.8569
573.693	12.5597
577.173	10.2186
580.652	8.80643
584.13	7.25741
587.605	6.64867
591.08	6.91781
594.552	6.08586
598.025	4.85839
601.496	5.56132
604.964	5.83942
608.433	5.64572
611.898	7.06464
615.364	8.65783
618.827	9.38115
622.288	10.8617
625.75	12.3458
629.209	14.6233
632.667	16.5844
636.125	18.0934
639.58	18.9551
643.033	19.3632
646.485	20.6914
649.936	20.6095
653.388	19.836
656.836	20.3839
660.283	21.171
663.728	23.3136
667.173	24.3538
670.616	25.5818
674.057	27.9506
677.498	29.2748
680.937	31.5084
684.375	31.9238
687.809	34.4994
691.244	36.2044
694.678	37.5296
698.111	39.7961
701.54	42.0671
704.97	42.8249
708.398	43.9483
711.826	45.476
715.25	47.1303
718.675	49.1811
722.096	49.8683
725.518	49.4855
728.937	49.0237
732.357	50.4853
735.773	50.5942
739.19	50.7816
742.604	51.8611
746.018	52.3414
749.429	55.2263
752.839	57.603
756.248	59.7785
759.657	61.8374
763.063	64.2554
766.468	66.8376
769.871	68.2827
773.273	69.6243
776.676	72.3877
780.075	75.7338
783.474	77.6315
786.871	78.9646
790.266	82.0149
793.661	84.7239
797.054	86.5054
800.446	90.1581
803.834	90.3881
807.224	90.6282
810.612	90.1993
813.998	90.9899
817.384	91.2303
820.766	89.1128
824.149	88.3293
827.531	88.4922
830.909	88.9242
834.288	88.8462
837.666	87.7812
841.041	84.9398
844.416	84.0904
847.788	82.0403
851.161	79.3431
854.53	75.7551
857.901	75.9047
861.268	74.7513
864.633	74.2549
868	72.304
871.363	71.4497
874.725	70.6727
878.088	69.1233
881.447	68.2379
884.805	68.0052
888.162	65.8224
891.518	65.1402
894.872	63.8914
898.225	63.7025
901.577	62.6581
904.928	62.3552
908.277	61.5403
911.625	63.2473
914.972	62.4255
918.318	62.1205
921.662	63.041
925.005	62.908
928.347	62.9603
931.686	61.8036
935.025	59.733
938.363	59.0675
941.698	58.8093
945.034	57.7718
948.368	58.1402
951.699	55.5717
955.031	55.3609
958.36	52.6736
961.689	50.7331
965.016	51.3951
968.343	52.57
971.666	53.1343
974.991	54.5527
978.312	54.5539
981.632	54.7267
984.953	54.072
988.27	52.6425
991.587	53.7656
994.902	53.0698
998.216	52.3549
1001.53	51.4706
1004.84	52.6339
1008.15	52.2214
1011.46	50.6432
1014.77	50.8719
1018.07	51.1873
1021.38	50.6328
1024.68	50.2058
1027.99	48.405
1031.29	46.6609
1034.59	45.3086
1037.89	45.3221
1041.18	43.5989
1044.48	43.5324
1047.77	43.303
1051.07	41.7687
1054.36	41.2771
1057.65	40.0427
1060.94	39.7134
1064.23	38.4149
1067.52	37.7747
1070.8	37.3382
1074.09	36.5781
1077.37	36.7369
1080.65	37.5382
1083.93	38.903
1087.21	40.9684
1090.49	42.0691
1093.77	42.732
1097.04	43.2727
1100.32	42.2405
1103.59	41.0763
1106.86	41.2117
1110.13	40.4723
1113.4	40.3208
1116.67	38.1461
1119.94	35.1319
1123.2	32.5517
1126.47	32.0932
1129.73	29.5859
1132.99	27.6695
1136.25	27.7315
1139.51	27.4797
1142.77	25.3551
1146.03	23.6173
1149.28	22.2434
1152.54	19.2442
1155.79	17.0589
1159.04	15.4011
1162.29	13.4563
1165.54	11.7912
1168.79	11.017
1172.04	10.0696
1175.28	9.97321
1178.53	9.93598
1181.77	9.82792
1185.01	10.1355
1188.25	10.6927
1191.49	10.7046
1194.73	12.0471
1197.96	13.6867
1201.2	17.187
1204.43	20.0678
1207.66	22.571
1210.9	26.3364
1214.13	31.0109
1217.36	36.4526
1220.58	40.2151
1223.81	43.4781
1227.04	45.9411
1230.26	48.0358
1233.48	49.0167
1236.71	53.094
1239.93	55.0217
1243.14	56.8254
1246.36	60.313
1249.58	61.9756
1252.8	63.9058
1256.01	66.1643
1259.22	67.6675
1262.43	68.9044
1265.64	69.6817
1268.85	71.3287
1272.06	72.0169
1275.27	73.3978
1278.48	75.0528
1281.68	77.0529
1284.88	78.194
1288.08	80.4559
1291.28	83.2201
1294.48	86.1922
1297.68	87.0686
1300.88	89.3166
1304.07	88.9473
1307.27	90.5269
1310.46	90.5206
1313.65	92.2704
1316.85	92.4749
1320.03	91.3533
1323.22	91.7554
1326.41	89.2326
1329.6	86.562
1332.78	84.7125
1335.96	82.2034
1339.15	77.5213
1342.33	74.5443
1345.51	71.0424
1348.69	66.0456
1351.86	62.7514
1355.04	59.8719
1358.21	57.787
1361.39	56.7878
1364.56	54.7481
1367.73	55.4129
1370.9	54.0186
1374.07	54.0946
1377.24	54.0059
1380.41	52.8977
1383.57	52.005
1386.73	53.8537
1389.9	54.1814
1393.06	54.2586
1396.22	52.9566
1399.38	53.3614
1402.54	53.1668
1405.69	53.3537
1408.85	54.6621
1412	57.8786
1415.16	60.8853
1418.31	64.7794
1421.46	69.8277
1424.61	74.5956
1427.76	80.9946
1430.9	88.1636
1434.05	96.0075
1437.2	101.237
1440.34	106.431
1443.48	109.17
1446.62	111.879
1449.76	111.761
1452.9	110.337
1456.04	107.228
1459.17	102.716
1462.31	98.2787
1465.44	92.0073
1468.58	84.3181
1471.71	76.65
1474.84	70.3095
1477.97	62.2469
1481.1	54.4034
1484.22	48.3722
1487.35	43.6916
1490.47	38.9279
1493.59	36.472
1496.72	34.1587
1499.84	31.3837
1502.96	29.3916
1506.08	27.8128
1509.19	26.7981
1512.31	25.8047
1515.42	22.4155
1518.54	23.4696
1521.65	23.5434
1524.76	23.1681
1527.87	22.8487
1530.98	22.3221
1534.09	22.1386
1537.2	22.2317
1540.3	22.4888
1543.41	24.404
1546.51	25.8176
1549.61	27.6883
1552.71	29.1392
1555.81	29.3805
1558.91	30.0287
1562.01	30.0291
1565.1	31.4503
1568.2	33.8802
1571.29	36.7029
1574.38	37.2645
1577.48	38.6261
1580.57	40.7313
1583.65	42.921
1586.74	45.3975
1589.83	46.0744
1592.92	47.9233
1596	50.7764
1599.08	51.3128
1602.16	50.3301
1605.24	50.5669
1608.32	50.561
1611.4	50.1861
1614.48	50.5665
1617.56	50.9625
1620.63	51.9411
1623.71	53.3224
1626.78	53.4839
1629.85	56.2598
1632.92	57.2804
1635.99	59.0506
1639.06	63.1481
1642.12	69.3868
1645.19	73.8936
1648.25	78.4155
1651.32	82.0366
1654.38	84.6432
1657.44	87.3035
1660.5	88.8994
1663.56	89.5038
1666.62	88.3047
1669.67	85.3638
1672.73	80.5415
1675.79	74.0693
1678.84	69.2682
1681.89	62.1907
1684.94	53.7138
1687.99	47.7908
1691.04	39.8204
1694.08	33.1223
1697.13	28.2775
1700.18	22.8045
1703.22	18.538
1706.26	13.7291
1709.3	9.42244
1712.35	7.79439
1715.39	6.38351
1718.42	5.30993
1721.46	3.81039
1724.5	3.15619
1727.53	2.01673
1730.56	2.98618
1733.6	2.55712
1736.63	1.74486
1739.66	2.02361
1742.69	1.60606
1745.71	0.601902
1748.74	0.676138
1751.77	1.20464
1754.79	0.697478
1757.81	0.304424
1760.84	0.497269
1763.86	0.454091
1766.88	0.25911
1769.9	-0.247449
1772.91	0.669281
1775.93	1.07429
1778.95	0.932405
1781.96	1.47595
1784.97	2.23162
1787.99	2.97114
1791	2.51928
1794.01	3.07304
1797.01	2.80736
1800.02	2.78552
1803.03	2.4437
1806.03	2.74349
1809.04	2.39058
1812.04	1.48301
1815.04	2.59005
1818.04	3.05735
1821.04	3.08466
1824.04	3.74246
1827.04	3.80871
1830.03	4.3122
1833.03	3.86942
1836.02	3.70291
1839.02	3.7638
1842.01	4.49471
1845	4.96946
1847.99	4.32478
1850.98	3.75111
1853.96	3.6225
1856.95	3.17361
1859.94	3.00435
1862.92	2.4606
1865.9	1.98711
1868.88	1.94348
1871.86	0.847846
1874.84	0.467343
1877.82	0.487841
1880.8	0.486158
1882.58	0.0348316
1885.57	0.184062
1888.56	1.32633
1891.54	0.940846
1894.53	1.1404
1897.51	1.56488
1900.5	1.88171
1903.48	1.35916
1906.46	1.62123
1909.44	2.24043
1912.42	3.14136
1915.4	3.54025
1918.37	2.99268
1921.35	3.8137
1924.32	4.32428
1927.3	4.69838
1930.27	3.91171
1933.24	4.00603
1936.21	4.56108
1939.18	4.19427
1942.15	4.86024
1945.11	4.60372
1948.08	4.87105
1951.04	5.17601
1954.01	4.57876
1956.97	3.90983
1959.93	2.91134
1962.89	1.89394
1965.85	1.46507
1968.81	1.73107
1971.77	0.850299
1974.72	0.205001
1977.68	-0.0923631
1980.63	0.337254
1983.58	1.0017
1986.53	2.45445
1989.48	3.05955
1992.43	4.04657
1995.38	4.29401
1998.33	3.6998
2001.27	3.98395
2004.22	3.90595
2007.16	4.43873
2010.11	4.90917
2013.05	5.93608
2015.99	6.09861
2018.93	5.56854
2021.87	5.07592
2024.8	4.47333
2027.74	4.53613
2030.68	4.34695
2033.61	3.1984
2036.54	2.94356
2039.48	3.07423
2042.41	3.5898
2045.34	2.92256
2048.27	2.46667
2051.19	2.90466
2054.12	4.92736
2057.05	5.83015
2059.97	7.59902
2062.9	6.59308
2065.82	6.9637
2068.74	6.09396
2071.66	6.6079
2074.58	6.56556
2077.5	6.89873
2080.41	7.84466
2083.33	8.19766
2086.24	8.60726
2089.16	8.19759
2092.07	9.15018
2094.98	10.1089
2097.89	10.6139
2100.8	12.1307
2103.71	12.5955
2106.62	12.8854
2109.53	14.8619
2112.43	16.4435
2115.33	17.6347
2118.24	18.341
2121.14	20.0298
2124.04	22.3353
2126.94	25.4143
2129.84	27.8446
2132.74	29.8617
2135.63	31.172
2138.53	33.7967
2141.43	35.3689
2144.32	37.2586
2147.21	40.2154
2150.1	42.2707
2152.99	45.4263
2155.88	49.037
2158.77	51.0754
2161.66	53.7767
2164.55	55.8404
2167.43	58.2486
2170.31	59.9369
2173.2	62.9731
2176.08	63.6061
2178.96	64.0982
2181.84	64.3896
2184.72	63.2421
2187.6	61.8091
2190.47	60.7771
2193.35	58.9129
2196.23	56.6764
2199.1	53.6443
2201.97	49.88
2204.84	45.6706
2207.71	41.7645
2210.58	36.8427
2213.45	33.3742
2216.32	30.281
2219.19	27.1542
2222.05	24.1547
2224.92	21.9508
2227.78	20.2641
2230.64	17.4131
2233.5	16.4913
2236.36	15.3467
2239.22	14.1467
2242.08	14.7603
2244.94	14.3917
2247.79	14.8009
2250.65	13.7656
2253.5	13.5581
2256.36	13.5972
2259.21	13.4124
2262.06	13.4732
2264.91	13.5339
2267.76	12.8315
2270.6	12.6255
2273.45	12.5513
2276.3	11.8323
2279.14	10.311
2281.98	9.53733
2284.83	9.41836
2287.67	8.94965
2290.51	8.10892
2293.35	6.49253
2296.19	6.73688
2299.02	7.13527
2301.86	5.83279
2304.7	5.31473
2307.53	5.10978
2310.36	6.05164
2313.2	6.47126
2316.03	5.79771
2318.86	5.72553
2321.69	5.1082
2324.51	4.89814
2327.34	5.16409
2330.17	5.86002
2332.99	6.43972
2335.82	6.13583
2338.64	6.36905
2341.46	5.76692
2344.28	4.43734
2347.1	3.05316
2349.92	2.48727
2352.74	2.59403
2355.56	1.22209
2358.37	0.680794
2361.19	-0.337747
2364	0.0779011
2366.82	1.32231
2369.63	1.17908
2372.44	0.954397
2375.25	1.91824
2378.06	2.24413
2380.86	3.25332
2383.67	3.75689
2386.48	3.24516
2389.28	3.81846
2392.09	4.30685
2394.89	5.75207
2397.69	6.3019
2400.49	7.16918
2403.29	6.82557
2406.09	6.71909
2408.89	6.25067
2411.69	5.63336
2414.48	4.96745
2417.28	5.34474
2420.07	4.95652
2422.86	4.88675
2425.65	5.04712
2428.45	4.95324
2431.23	5.02038
2434.02	5.26174
2436.81	4.64782
2439.6	3.3029
2442.38	3.0826
2445.17	2.7565
2447.95	2.56394
2450.73	2.05228
2453.52	2.22472
2456.3	2.04273
2459.08	3.15955
2461.85	3.02504
2464.63	3.68226
2467.41	3.63019
2470.19	3.08948
2472.96	3.30765
2475.73	3.27267
2478.51	4.4144
2481.28	5.57564
2484.05	6.32367
2486.82	6.41986
2489.59	7.38845
2492.35	8.68576
2495.12	7.57759
2497.89	7.54669
2500.65	7.05035
2503.42	5.9022
2506.18	5.33094
2508.94	5.37363
2511.7	5.96489
2514.46	5.98361
2517.22	5.45834
2519.98	6.30037
2522.73	6.46077
2525.49	6.82867
2528.25	6.50979
2531	6.91316
2533.75	8.01855
2536.5	7.07906
2539.25	7.19437
2542.01	7.64805
2544.75	8.47184
2547.5	8.61571
2550.25	9.13982
2553	9.36235
2555.74	8.97058
2558.49	9.33553
2561.23	8.34838
2563.97	7.85276
2566.71	8.06517
2569.45	8.63762
2572.19	8.94306
2574.93	9.12507
2577.67	9.33217
2580.4	8.50877
2583.14	7.11958
2585.87	7.7597
2588.6	8.08125
2591.34	7.23794
2594.07	6.6921
2596.8	6.4583
2599.53	5.85131
2602.26	5.80651
2604.98	5.5072
2607.71	6.47155
2610.44	6.34712
2613.16	6.34388
2615.88	6.19072
2618.61	6.23289
2621.33	7.05486
2624.05	7.27095
2626.77	7.19983
2629.49	7.58152
2632.21	8.37265
2634.92	9.37761
2637.64	9.63676
2640.35	8.8527
2643.07	8.53351
2645.78	8.22603
2648.49	7.4934
2651.2	6.68594
2653.91	6.46443
2656.62	6.09542
2659.33	5.19749
2662.04	4.08015
2664.74	4.35785
2667.45	4.48723
2670.15	5.14567
2672.86	4.74622
2675.56	5.09116
2678.26	4.49601
2680.96	4.33267
2683.66	5.61208
2686.36	6.6016
2689.06	6.77985
2691.75	7.49138
2694.45	8.9192
2697.14	9.67101
2699.84	10.6559
2702.53	10.9654
2705.22	11.5911
2707.91	12.5752
2710.6	13.265
2713.29	13.6555
2715.98	13.5029
2718.67	14.1814
2721.35	14.8317
2724.04	15.0207
2726.72	13.4501
2729.4	12.3505
2732.09	12.5858
2734.77	12.5905
2737.45	11.4367
2740.13	10.9782
2742.81	10.4891
2745.48	9.41342
2748.16	8.94872
2750.84	7.82578
2753.51	6.4846
2756.19	4.96204
2758.86	3.71044
2761.53	2.92439
2764.2	2.15821
2766.87	1.87887
2769.54	1.56787
2772.21	1.9639
2774.88	1.94933
2777.54	2.00911
2780.21	1.46537
2782.87	1.12909
2785.53	1.01339
2788.2	0.670103
2790.86	0.497554
2793.52	0.260564
2796.18	1.77597
2798.84	1.98279
2801.49	1.95748
2804.15	2.22024
2806.81	1.57596
2809.46	0.926313
2812.12	-0.688271
2814.77	-1.14188
2817.42	-0.162209
2820.07	1.63102
2822.72	3.71902
2825.37	6.68926
2828.02	10.6884
2830.67	14.9733
2833.31	19.0446
2835.96	24.1015
2838.61	30.5471
2841.25	35.9996
2843.89	43.3856
2846.53	51.1622
2849.17	60.5267
2851.81	69.8517
2854.45	80.3434
2857.09	90.7298
2859.73	101.233
2862.36	111.369
2865	120.056
2867.64	127.847
2870.27	134.977
2872.9	140.785
2875.53	146.846
2878.16	152.805
2880.79	158.667
2883.42	163.494
2886.05	168.659
2888.68	174.184
2891.3	178.975
2893.93	184.211
2896.55	189.355
2899.18	195.21
2901.8	203.568
2904.42	212.428
2907.04	222.691
2909.66	233.549
2912.28	245.094
2914.9	257.085
2917.51	269.724
2920.13	280.478
2922.74	289.004
2925.36	296.124
2927.97	299.992
2930.59	302.128
2933.2	301.636
2935.81	299.487
2938.42	295.414
2941.02	287.945
2943.63	278.727
2946.24	269.259
2948.85	259.197
2951.45	248.45
2954.05	236.26
2956.66	223.735
2959.26	211.823
2961.86	200.722
2964.46	190.336
2967.06	180.594
2969.66	170.673
2972.26	161.204
2974.85	152.04
2977.45	144.21
2980.05	135.634
2982.64	126.807
2985.23	116.762
2987.83	107.113
2990.42	97.0551
2993.01	87.4486
2995.6	78.1911
2998.19	68.2206
3000.77	58.2353
3003.36	49.436
3005.95	41.0861
3008.53	34.938
3011.12	29.5268
3013.7	23.8855
3016.28	19.06
3018.86	14.4088
3021.44	11.4192
3024.02	8.83117
3026.6	5.80749
3029.18	4.96054
3031.76	3.00798
3034.33	3.21846
3036.91	3.94253
3039.48	4.53154
3042.05	5.38332
3044.63	6.95108
3047.2	9.01419
3049.77	9.91077
3052.34	10.4451
3054.91	11.7194
3057.48	11.2917
3060.04	10.9684
3062.61	10.8841
3065.17	11.1341
3067.74	10.8254
3070.3	10.3658
3072.87	9.27993
3075.43	8.50272
3077.99	6.4949
3080.55	4.70963
3083.11	3.13328
3085.67	1.68882
3088.22	0.268991
3090.78	-0.728404
3093.34	-1.05197
3095.89	-1.65725
3098.44	-0.215513
3101	0.91022
3103.55	1.40947
3106.1	2.1158
3108.65	4.28777
3111.2	5.98211
3113.75	6.96365
3116.3	8.58444
3118.84	10.4984
3121.39	11.6308
3123.93	14.1966
3126.48	16.4377
3129.02	17.2876
3131.56	18.4128
3134.1	19.5679
3136.64	20.601
3139.18	21.8236
3141.72	22.1273
3144.26	22.2163
3146.8	22.5077
3149.33	22.6098