File: data/Raman/poly_smoothed/Mbcal_20_25_21_1x_45s_532 nm_x100_100%_600 gr_mm_02.txt
#Acq. time (s)=	45
#Accumulations=	2
#Range (cm-¹)=	200...3150
#Windows=	2
#Auto scanning=	Off
#Autofocus=	Off
#Macrospot=	Off
#AutoExposure=	Off
#Spike filter=	Multiple accum.
#Delay time (s)=	0
#Binning=	1
#Readout mode=	Signal
#DeNoise=	Off
#ICS correction=	On
#Dark correction=	Off
#Inst. Process=	Off
#Detector Gain=	Best Dynamic Range
#Detector ADC=	20 kHz
#Detector temperature (°C)=	-69.85
#Instrument=	LabRAM HR Evol
#Detector=	Synapse
#Objective=	x100
#Grating=	600 gr/mm
#ND Filter=	100%
#Laser (nm)=	532
#Hole=	100.021
#Range=	Auto
#Laser Pol.=	No
#Raman. Pol.=	No
#Laser Pol. (°)=	-0.0007625
#Raman Pol. (°)=	89.9995
#Collection=	Microscope
#StageXY=	Marzhauser
#StageZ=	Marzhauser
#X (µm)=	-1186.8
#Y (µm)=	1277.3
#Z (µm)=	577.8
#Full time(mm:ss)=	3:18
#Project=
#Sample=
#Site=
#Title=	Mbcal_20_25_21_2x_45s_532 nm_x100_100%_600 gr_mm
#Remark=
#Date=	18.07.2022 11:02
#Acquired=	18.07.2022 11:02:05
#Base:Fit=	10.08.2022 10:55:08
#Base:Sub=	10.08.2022 10:55:14
#Filter:Polynom=	16.08.2022 10:07:28
#AxisType[0]=Intens
#AxisUnit[0]=Cnt
#AxisType[1]=Spectr
#AxisUnit[1]=1/cm
200.419	25.3371
204.048	16.1794
207.678	9.70853
211.304	6.39454
214.928	5.28682
218.554	4.38522
222.176	3.03267
225.798	3.11028
229.417	4.97154
233.035	3.44602
236.653	2.84868
240.268	3.08101
243.881	3.38664
247.493	2.88524
251.103	4.84063
254.715	6.30066
258.322	6.21935
261.929	5.62571
265.534	6.12762
269.137	7.36346
272.739	5.93176
276.34	4.46478
279.939	3.98091
283.537	2.03981
287.134	0.366092
290.729	1.71483
294.323	2.76111
297.913	6.26748
301.504	8.7782
305.093	11.4838
308.682	12.7462
312.268	14.3786
315.852	15.8003
319.436	17.987
323.018	18.7929
326.597	20.0562
330.177	20.4319
333.753	20.7516
337.331	21.6123
340.906	21.3115
344.478	21.0513
348.051	19.8377
351.621	19.5904
355.189	17.6688
358.757	17.247
362.323	12.8852
365.889	10.7371
369.451	8.65945
373.012	7.15426
376.574	5.07255
380.133	5.51653
383.69	6.598
387.245	6.71573
390.8	7.74886
394.353	5.28951
397.906	4.01277
401.456	5.46517
405.005	4.84743
408.552	4.03898
412.099	4.98691
415.643	5.52366
419.187	6.55849
422.728	6.56113
426.269	5.34395
429.806	5.03082
433.344	5.97691
436.881	6.38771
440.416	7.333
443.949	8.26384
447.48	7.20266
451.011	7.02558
454.541	8.2469
458.069	8.20716
461.594	7.80717
465.119	10.4139
468.642	12.5195
472.165	13.1853
475.684	13.6655
479.204	16.4996
482.721	17.6127
486.239	20.9811
489.753	22.5338
493.268	23.0751
496.779	24.9394
500.289	26.5032
503.8	26.8628
507.307	27.9237
510.813	29.1565
514.32	28.404
517.823	29.7787
521.325	32.3056
524.826	34.7047
528.325	34.6246
531.823	36.3643
535.32	36.9989
538.815	36.9667
542.309	37.1022
545.802	34.8342
549.293	34.689
552.783	33.6772
556.271	31.0538
559.759	29.6571
563.245	30.2452
566.729	28.3392
570.213	25.4219
573.693	22.1587
577.173	18.6091
580.652	16.8981
584.13	15.53
587.605	13.4648
591.08	13.297
594.552	12.8361
598.025	12.5882
601.496	13.9771
604.964	16.6712
608.433	18.9005
611.898	19.0699
615.364	21.0968
618.827	22.9168
622.288	24.6309
625.75	26.5875
629.209	29.1773
632.667	30.1432
636.125	32.5127
639.58	33.0015
643.033	34.5406
646.485	37.7774
649.936	38.5014
653.388	37.5458
656.836	37.985
660.283	38.4414
663.728	40.028
667.173	40.2569
670.616	39.0452
674.057	37.017
677.498	37.7634
680.937	38.6445
684.375	38.4682
687.809	40.0112
691.244	40.9064
694.678	41.0236
698.111	40.1154
701.54	40.0073
704.97	42.1566
708.398	43.2462
711.826	45.2167
715.25	46.7246
718.675	48.8431
722.096	48.9812
725.518	50.1541
728.937	52.1506
732.357	53.8595
735.773	54.6821
739.19	57.6358
742.604	61.6521
746.018	63.562
749.429	64.4815
752.839	67.6009
756.248	69.8153
759.657	74.029
763.063	77.6498
766.468	80.5432
769.871	83.583
773.273	87.2846
776.676	90.6421
780.075	92.9573
783.474	94.1861
786.871	97.2346
790.266	100.31
793.661	101.995
797.054	104.793
800.446	105.866
803.834	107.372
807.224	107.548
810.612	107.106
813.998	105.727
817.384	105.643
820.766	105.458
824.149	105.359
827.531	104.998
830.909	105.382
834.288	106.544
837.666	106.175
841.041	104.811
844.416	105.462
847.788	102.964
851.161	101.801
854.53	101.036
857.901	100.409
861.268	98.3137
864.633	97.1977
868	95.8458
871.363	93.9024
874.725	92.8642
878.088	90.159
881.447	87.1511
884.805	83.7928
888.162	79.8298
891.518	76.8706
894.872	74.1646
898.225	71.3806
901.577	71.6879
904.928	70.6954
908.277	70.7124
911.625	72.3281
914.972	72.7945
918.318	70.8539
921.662	72.9909
925.005	73.4489
928.347	72.1076
931.686	70.8299
935.025	71.5827
938.363	71.8385
941.698	72.7257
945.034	71.0234
948.368	69.0832
951.699	67.3841
955.031	64.757
958.36	63.8181
961.689	58.2629
965.016	56.6163
968.343	55.3038
971.666	57.5155
974.991	56.8149
978.312	55.8699
981.632	55.6323
984.953	55.8984
988.27	56.4476
991.587	56.5143
994.902	57.041
998.216	56.5958
1001.53	57.6192
1004.84	56.4488
1008.15	56.3703
1011.46	54.4547
1014.77	56.9125
1018.07	56.8595
1021.38	55.6211
1024.68	55.2392
1027.99	54.25
1031.29	55.5975
1034.59	56.5847
1037.89	54.4118
1041.18	52.4273
1044.48	52.3443
1047.77	53.3847
1051.07	54.7208
1054.36	53.9892
1057.65	51.7721
1060.94	51.2926
1064.23	51.4251
1067.52	50.3355
1070.8	48.1412
1074.09	47.2936
1077.37	45.2586
1080.65	45.2339
1083.93	44.6223
1087.21	44.2362
1090.49	44.3346
1093.77	45.6267
1097.04	45.8293
1100.32	45.8367
1103.59	47.0229
1106.86	48.1505
1110.13	48.9086
1113.4	48.3971
1116.67	46.6152
1119.94	45.3968
1123.2	44.1728
1126.47	43.5093
1129.73	42.051
1132.99	39.034
1136.25	35.4011
1139.51	33.0979
1142.77	30.1023
1146.03	27.6959
1149.28	23.1842
1152.54	20.0206
1155.79	16.3876
1159.04	12.268
1162.29	9.12905
1165.54	6.15072
1168.79	5.63376
1172.04	4.11519
1175.28	4.17598
1178.53	4.23924
1181.77	4.76819
1185.01	6.43372
1188.25	6.84974
1191.49	9.07443
1194.73	9.53404
1197.96	10.4864
1201.2	14.3443
1204.43	17.0168
1207.66	20.259
1210.9	21.695
1214.13	25.6265
1217.36	30.024
1220.58	32.9133
1223.81	36.2789
1227.04	39.2393
1230.26	43.2217
1233.48	46.5433
1236.71	47.6089
1239.93	49.9005
1243.14	54.1968
1246.36	56.4064
1249.58	57.798
1252.8	60.1805
1256.01	62.6062
1259.22	64.8087
1262.43	65.6673
1265.64	65.8283
1268.85	67.2505
1272.06	67.3563
1275.27	68.3221
1278.48	69.797
1281.68	73.2587
1284.88	74.1606
1288.08	75.2251
1291.28	78.3321
1294.48	81.6618
1297.68	83.7732
1300.88	85.0031
1304.07	86.8489
1307.27	88.8585
1310.46	90.6426
1313.65	90.5508
1316.85	91.4777
1320.03	90.6743
1323.22	89.6634
1326.41	87.8992
1329.6	85.2517
1332.78	83.4096
1335.96	81.4858
1339.15	77.8813
1342.33	73.7792
1345.51	72.194
1348.69	69.4239
1351.86	67.2047
1355.04	65.7724
1358.21	63.6618
1361.39	61.5324
1364.56	59.8593
1367.73	58.9443
1370.9	57.0303
1374.07	54.8427
1377.24	52.8959
1380.41	52.6037
1383.57	53.1135
1386.73	52.2904
1389.9	52.4772
1393.06	52.8994
1396.22	52.6013
1399.38	51.4916
1402.54	53.1887
1405.69	54.7373
1408.85	57.8382
1412	61.8134
1415.16	66.7489
1418.31	71.0927
1421.46	77.728
1424.61	84.3552
1427.76	89.8149
1430.9	96.4921
1434.05	101.083
1437.2	106.699
1440.34	111.524
1443.48	114.07
1446.62	114.104
1449.76	113.488
1452.9	113.246
1456.04	111.747
1459.17	107.772
1462.31	104.975
1465.44	99.2233
1468.58	94.4495
1471.71	87.5032
1474.84	81.0357
1477.97	74.0348
1481.1	67.8198
1484.22	61.3002
1487.35	54.5098
1490.47	48.6615
1493.59	42.4269
1496.72	36.6668
1499.84	31.5325
1502.96	27.6236
1506.08	23.6356
1509.19	20.4804
1512.31	15.7042
1515.42	12.7536
1518.54	10.2354
1521.65	8.74017
1524.76	8.03531
1527.87	8.68832
1530.98	9.26255
1534.09	9.20257
1537.2	10.0459
1540.3	11.223
1543.41	13.3389
1546.51	15.5414
1549.61	17.325
1552.71	20.8857
1555.81	21.7031
1558.91	23.27
1562.01	24.4292
1565.1	27.151
1568.2	29.2307
1571.29	30.3871
1574.38	31.7595
1577.48	35.0108
1580.57	37.3102
1583.65	40.0267
1586.74	43.0664
1589.83	44.6537
1592.92	47.4826
1596	48.2785
1599.08	50.2212
1602.16	49.451
1605.24	48.7397
1608.32	48.9731
1611.4	49.1396
1614.48	47.871
1617.56	47.0765
1620.63	48.7836
1623.71	50.0344
1626.78	52.525
1629.85	55.2977
1632.92	58.109
1635.99	61.9119
1639.06	64.3354
1642.12	68.9129
1645.19	71.5278
1648.25	74.2714
1651.32	77.1963
1654.38	80.0226
1657.44	81.9439
1660.5	82.7945
1663.56	81.8751
1666.62	79.8139
1669.67	75.6877
1672.73	71.3488
1675.79	65.0635
1678.84	59.3635
1681.89	53.6688
1684.94	46.3002
1687.99	38.5378
1691.04	32.4537
1694.08	27.7485
1697.13	23.4694
1700.18	20.2952
1703.22	15.2867
1706.26	12.217
1709.3	8.84211
1712.35	7.35084
1715.39	5.09521
1718.42	3.8474
1721.46	3.66476
1724.5	4.5479
1727.53	4.37038
1730.56	4.37019
1733.6	4.9609
1736.63	5.16629
1739.66	5.5979
1742.69	5.52262
1745.71	4.83258
1748.74	5.0513
1751.77	5.78664
1754.79	5.2942
1757.81	4.57768
1760.84	4.62432
1763.86	3.94642
1766.88	4.71478
1769.9	4.13241
1772.91	3.74859
1775.93	2.58581
1778.95	2.99915
1781.96	4.64438
1784.97	4.80342
1787.99	4.88272
1791	5.31841
1794.01	6.8529
1797.01	5.99018
1800.02	5.10112
1803.03	5.23948
1806.03	5.01584
1809.04	5.55708
1812.04	4.54727
1815.04	4.3182
1818.04	4.14839
1821.04	4.17364
1824.04	3.6873
1827.04	4.91381
1830.03	4.58371
1833.03	4.28992
1836.02	3.96504
1839.02	5.2877
1842.01	5.28376
1845	5.58162
1847.99	4.86007
1850.98	5.51709
1853.96	8.41898
1856.95	8.77742
1859.94	9.69599
1862.92	9.5385
1865.9	8.7325
1868.88	8.40395
1871.86	7.22643
1874.84	6.68925
1877.82	6.27046
1880.8	4.08705
1882.58	2.49572
1885.57	1.75788
1888.56	1.02912
1891.54	1.06151
1894.53	1.81258
1897.51	1.39836
1900.5	2.5343
1903.48	1.82402
1906.46	2.49969
1909.44	3.59544
1912.42	4.50486
1915.4	3.81943
1918.37	3.5887
1921.35	4.03648
1924.32	6.41346
1927.3	7.79435
1930.27	6.52709
1933.24	6.75583
1936.21	7.63631
1939.18	5.65108
1942.15	5.92159
1945.11	4.32364
1948.08	3.96598
1951.04	3.64016
1954.01	2.77668
1956.97	2.4414
1959.93	2.44934
1962.89	2.40004
1965.85	1.68158
1968.81	1.6021
1971.77	3.36015
1974.72	3.36993
1977.68	3.03357
1980.63	4.17351
1983.58	5.21249
1986.53	5.6992
1989.48	5.00755
1992.43	4.77261
1995.38	5.15171
1998.33	6.74969
2001.27	5.88745
2004.22	7.60972
2007.16	7.25772
2010.11	7.46978
2013.05	7.13547
2015.99	8.29875
2018.93	8.21373
2021.87	9.039
2024.8	10.0254
2027.74	10.7009
2030.68	11.3473
2033.61	11.5785
2036.54	11.0658
2039.48	11.8324
2042.41	13.4711
2045.34	15.0566
2048.27	15.7507
2051.19	16.6442
2054.12	18.9672
2057.05	19.0065
2059.97	17.7344
2062.9	14.9118
2065.82	15.5312
2068.74	16.0115
2071.66	15.4951
2074.58	15.725
2077.5	15.5983
2080.41	15.4141
2083.33	15.3939
2086.24	16.0943
2089.16	16.1894
2092.07	17.4602
2094.98	17.7454
2097.89	19.0055
2100.8	16.6275
2103.71	18.3608
2106.62	18.1003
2109.53	18.9036
2112.43	19.8891
2115.33	21.8392
2118.24	24.7733
2121.14	26.397
2124.04	28.526
2126.94	30.3768
2129.84	31.9365
2132.74	34.2074
2135.63	38.1328
2138.53	43.3663
2141.43	45.7436
2144.32	51.2006
2147.21	55.5893
2150.1	59.1821
2152.99	61.6033
2155.88	66.5985
2158.77	69.67
2161.66	73.6016
2164.55	76.7849
2167.43	79.3018
2170.31	80.9862
2173.2	81.1406
2176.08	83.0348
2178.96	82.798
2181.84	82.1836
2184.72	82.7103
2187.6	80.5331
2190.47	78.0115
2193.35	75.1112
2196.23	71.8224
2199.1	68.2363
2201.97	64.59
2204.84	61.4328
2207.71	57.2938
2210.58	52.6463
2213.45	48.6699
2216.32	44.5147
2219.19	40.5441
2222.05	37.4764
2224.92	35.724
2227.78	34.3429
2230.64	34.1057
2233.5	33.185
2236.36	31.6497
2239.22	31.1019
2242.08	30.0499
2244.94	28.3072
2247.79	27.8606
2250.65	27.4723
2253.5	27.9322
2256.36	27.5497
2259.21	26.5287
2262.06	27.8278
2264.91	28.8676
2267.76	28.3855
2270.6	27.9182
2273.45	25.5488
2276.3	22.7961
2279.14	22.6635
2281.98	21.6966
2284.83	21.7114
2287.67	20.4044
2290.51	20.4338
2293.35	18.5626
2296.19	16.9595
2299.02	16.0722
2301.86	15.9937
2304.7	15.3584
2307.53	15.0372
2310.36	14.4764
2313.2	13.8277
2316.03	14.574
2318.86	14.1729
2321.69	12.7249
2324.51	13.1453
2327.34	12.1257
2330.17	12.3406
2332.99	14.1101
2335.82	12.4465
2338.64	10.5653
2341.46	9.68799
2344.28	8.83885
2347.1	10.2321
2349.92	11.234
2352.74	10.4704
2355.56	9.51258
2358.37	9.88517
2361.19	9.30736
2364	10.7677
2366.82	11.1454
2369.63	13.4536
2372.44	14.9255
2375.25	15.4858
2378.06	14.3051
2380.86	14.2146
2383.67	14.2488
2386.48	13.7367
2389.28	12.5822
2392.09	12.5978
2394.89	13.8643
2397.69	13.0516
2400.49	14.1617
2403.29	13.6291
2406.09	13.7427
2408.89	14.6991
2411.69	15.2835
2414.48	14.7884
2417.28	15.5065
2420.07	14.2385
2422.86	12.2704
2425.65	11.571
2428.45	10.8941
2431.23	10.1048
2434.02	9.03114
2436.81	7.34043
2439.6	7.53763
2442.38	6.78702
2445.17	6.12443
2447.95	5.60277
2450.73	5.59324
2453.52	5.73395
2456.3	5.06016
2459.08	5.28251
2461.85	7.06836
2464.63	7.75379
2467.41	7.66257
2470.19	7.86157
2472.96	8.76655
2475.73	9.87139
2478.51	10.3608
2481.28	9.27642
2484.05	8.38271
2486.82	7.58653
2489.59	7.04795
2492.35	6.05038
2495.12	8.17377
2497.89	7.02015
2500.65	8.06878
2503.42	7.2934
2506.18	7.26979
2508.94	8.3544
2511.7	7.04885
2514.46	6.74052
2517.22	5.24524
2519.98	6.49939
2522.73	5.87334
2525.49	6.04095
2528.25	7.48434
2531	6.4782
2533.75	5.941
2536.5	6.02527
2539.25	7.87452
2542.01	7.88934
2544.75	8.73143
2547.5	9.56933
2550.25	9.49904
2553	10.1586
2555.74	11.3824
2558.49	12.2529
2561.23	13.8238
2563.97	12.9809
2566.71	13.1193
2569.45	13.3347
2572.19	13.5891
2574.93	13.2029
2577.67	11.7977
2580.4	12.0786
2583.14	11.664
2585.87	11.265
2588.6	10.8032
2591.34	11.4454
2594.07	11.5089
2596.8	12.7895
2599.53	12.809
2602.26	11.1125
2604.98	10.7257
2607.71	9.55392
2610.44	9.78886
2613.16	10.1743
2615.88	10.2371
2618.61	8.63946
2621.33	9.06087
2624.05	8.84142
2626.77	10.4249
2629.49	11.1616
2632.21	11.5007
2634.92	13.13
2637.64	12.5782
2640.35	12.5369
2643.07	13.0558
2645.78	12.5685
2648.49	11.2287
2651.2	11.4461
2653.91	11.3674
2656.62	11.9174
2659.33	12.8642
2662.04	11.4729
2664.74	9.08518
2667.45	7.66829
2670.15	5.11702
2672.86	4.2895
2675.56	4.8292
2678.26	4.26081
2680.96	4.13614
2683.66	4.40454
2686.36	5.1781
2689.06	5.34002
2691.75	8.31718
2694.45	11.0896
2697.14	13.7936
2699.84	15.4208
2702.53	16.0954
2705.22	16.446
2707.91	17.549
2710.6	18.2156
2713.29	17.9408
2715.98	20.144
2718.67	21.9814
2721.35	22.1921
2724.04	22.1663
2726.72	21.5186
2729.4	20.2756
2732.09	21.1609
2734.77	20.5844
2737.45	19.4501
2740.13	18.2822
2742.81	17.6725
2745.48	16.3131
2748.16	15.8584
2750.84	13.9394
2753.51	11.2699
2756.19	11.3606
2758.86	10.9444
2761.53	10.2916
2764.2	8.34257
2766.87	5.63721
2769.54	4.79891
2772.21	3.22874
2774.88	3.31825
2777.54	2.4269
2780.21	3.45078
2782.87	3.71611
2785.53	3.72562
2788.2	3.146
2790.86	2.98766
2793.52	2.83316
2796.18	3.60598
2798.84	3.39041
2801.49	1.95741
2804.15	2.83062
2806.81	3.43674
2809.46	2.88058
2812.12	2.0987
2814.77	0.669021
2817.42	3.04337
2820.07	6.18143
2822.72	11.3684
2825.37	16.2352
2828.02	21.5529
2830.67	29.7087
2833.31	37.17
2835.96	46.1602
2838.61	55.9661
2841.25	66.1972
2843.89	78.1649
2846.53	91.0157
2849.17	103.922
2851.81	118.455
2854.45	132.106
2857.09	145.9
2859.73	158.96
2862.36	171.848
2865	181.982
2867.64	192.374
2870.27	200.471
2872.9	208.042
2875.53	216.13
2878.16	223.891
2880.79	230.985
2883.42	237.864
2886.05	244.883
2888.68	250.926
2891.3	255.473
2893.93	260.609
2896.55	267.01
2899.18	274.699
2901.8	285.074
2904.42	295.491
2907.04	309.211
2909.66	323.815
2912.28	339.928
2914.9	355.588
2917.51	371.158
2920.13	382.595
2922.74	392.996
2925.36	401.843
2927.97	405.706
2930.59	406.704
2933.2	405.756
2935.81	402.586
2938.42	396.638
2941.02	388.591
2943.63	375.891
2946.24	362.882
2948.85	346.065
2951.45	330.133
2954.05	312.664
2956.66	295.963
2959.26	278.414
2961.86	264.006
2964.46	248.098
2967.06	234.943
2969.66	221.287
2972.26	210.004
2974.85	199.09
2977.45	188.553
2980.05	177.871
2982.64	165.402
2985.23	153.504
2987.83	141.693
2990.42	128.646
2993.01	114.073
2995.6	101.783
2998.19	89.9652
3000.77	76.7524
3003.36	67.0216
3005.95	56.277
3008.53	46.7739
3011.12	37.5883
3013.7	28.5858
3016.28	22.675
3018.86	16.6621
3021.44	11.4574
3024.02	7.72664
3026.6	3.80762
3029.18	1.54993
3031.76	-0.302035
3034.33	0.597465
3036.91	1.25582
3039.48	2.80054
3042.05	4.18993
3044.63	3.69653
3047.2	5.02009
3049.77	5.41973
3052.34	6.09594
3054.91	7.19177
3057.48	8.4991
3060.04	8.0348
3062.61	8.23337
3065.17	9.45977
3067.74	9.03479
3070.3	8.28596
3072.87	7.51872
3075.43	6.72398
3077.99	6.22876
3080.55	5.68132
3083.11	4.34369
3085.67	2.50534
3088.22	1.3969
3090.78	0.912521
3093.34	0.923993
3095.89	1.01078
3098.44	2.09824
3101	2.88391
3103.55	2.60143
3106.1	2.57802
3108.65	2.96585
3111.2	4.60971
3113.75	5.96683
3116.3	9.22953
3118.84	11.2284
3121.39	11.5829
3123.93	14.2587
3126.48	15.8146
3129.02	18.431
3131.56	21.0739
3134.1	22.4972
3136.64	25.0391
3139.18	27.3927
3141.72	28.5474
3144.26	29.9355
3146.8	32.5813
3149.33	37.7313