File: data/Raman/poly_smoothed/Mbcal_20_25_22_1x_45s_532 nm_x100_100%_600 gr_mm_01.txt
#Acq. time (s)=	45
#Accumulations=	2
#Range (cm-¹)=	200...3150
#Windows=	2
#Auto scanning=	Off
#Autofocus=	Off
#Macrospot=	Off
#AutoExposure=	Off
#Spike filter=	Multiple accum.
#Delay time (s)=	0
#Binning=	1
#Readout mode=	Signal
#DeNoise=	Off
#ICS correction=	On
#Dark correction=	Off
#Inst. Process=	Off
#Detector Gain=	Best Dynamic Range
#Detector ADC=	20 kHz
#Detector temperature (°C)=	-69.85
#Instrument=	LabRAM HR Evol
#Detector=	Synapse
#Objective=	x100
#Grating=	600 gr/mm
#ND Filter=	100%
#Laser (nm)=	532
#Hole=	100.021
#Range=	Auto
#Laser Pol.=	No
#Raman. Pol.=	No
#Laser Pol. (°)=	-0.0007625
#Raman Pol. (°)=	89.9995
#Collection=	Microscope
#StageXY=	Marzhauser
#StageZ=	Marzhauser
#X (µm)=	-1184
#Y (µm)=	1298.9
#Z (µm)=	578.1
#Full time(mm:ss)=	3:18
#Project=
#Sample=
#Site=
#Title=	Mbcal_20_25_22_2x_45s_532 nm_x100_100%_600 gr_mm
#Remark=
#Date=	18.07.2022 11:06
#Acquired=	18.07.2022 11:06:08
#Base:Fit=	10.08.2022 10:55:08
#Base:Sub=	10.08.2022 10:55:14
#Filter:Polynom=	16.08.2022 10:07:28
#AxisType[0]=Intens
#AxisUnit[0]=Cnt
#AxisType[1]=Spectr
#AxisUnit[1]=1/cm
200.419	21.6587
204.048	18.6764
207.678	15.8754
211.304	13.2653
214.928	10.5044
218.554	8.56988
222.176	6.87039
225.798	5.02241
229.417	3.40573
233.035	1.04658
236.653	0.942182
240.268	0.756639
243.881	0.474977
247.493	0.724203
251.103	0.880965
254.715	0.953953
258.322	4.13621
261.929	7.79137
265.534	14.3365
269.137	19.7501
272.739	25.2543
276.34	28.7139
279.939	33.0696
283.537	35.3329
287.134	37.591
290.729	39.9652
294.323	40.8072
297.913	40.7029
301.504	41.4413
305.093	42.4334
308.682	42.951
312.268	41.8313
315.852	40.965
319.436	39.4181
323.018	37.4431
326.597	35.611
330.177	32.8997
333.753	29.5054
337.331	26.3604
340.906	25.1531
344.478	27.2854
348.051	28.5315
351.621	29.1636
355.189	27.6132
358.757	26.2399
362.323	24.164
365.889	21.2406
369.451	21.078
373.012	21.6885
376.574	21.2538
380.133	20.6928
383.69	19.4455
387.245	21.7762
390.8	23.628
394.353	23.5569
397.906	23.8711
401.456	22.5803
405.005	21.8241
408.552	19.3331
412.099	19.1551
415.643	15.6684
419.187	15.4088
422.728	15.0076
426.269	15.3878
429.806	14.318
433.344	12.2106
436.881	12.9636
440.416	11.4567
443.949	10.6799
447.48	10.9366
451.011	10.9417
454.541	12.8745
458.069	16.1986
461.594	18.3881
465.119	21.0274
468.642	22.9141
472.165	25.1553
475.684	26.9572
479.204	27.2572
482.721	27.5705
486.239	27.1701
489.753	27.5646
493.268	27.9367
496.779	27.0179
500.289	28.979
503.8	29.6778
507.307	31.8078
510.813	32.3455
514.32	31.4608
517.823	32.9068
521.325	34.4666
524.826	35.8236
528.325	36.403
531.823	35.5313
535.32	35.4044
538.815	37.1012
542.309	39.0791
545.802	39.9429
549.293	39.9917
552.783	39.2346
556.271	36.2431
559.759	34.7548
563.245	31.8609
566.729	30.0671
570.213	27.93
573.693	25.1843
577.173	23.4587
580.652	20.0519
584.13	18.2242
587.605	17.3162
591.08	14.7916
594.552	11.5346
598.025	9.15416
601.496	6.8051
604.964	6.85789
608.433	6.45677
611.898	7.36414
615.364	7.66812
618.827	9.404
622.288	10.8182
625.75	13.1782
629.209	15.6489
632.667	17.3456
636.125	17.8072
639.58	19.3882
643.033	21.1451
646.485	23.0932
649.936	24.5326
653.388	26.2342
656.836	29.0891
660.283	30.2344
663.728	29.8215
667.173	29.1834
670.616	26.8614
674.057	26.4069
677.498	24.3158
680.937	23.6511
684.375	24.2111
687.809	25.7116
691.244	28.4057
694.678	30.9365
698.111	33.6489
701.54	35.0844
704.97	36.4354
708.398	36.7356
711.826	37.6119
715.25	37.7238
718.675	37.7212
722.096	38.5512
725.518	39.2555
728.937	38.9416
732.357	40.2239
735.773	39.9215
739.19	40.1965
742.604	39.5804
746.018	39.0227
749.429	39.8405
752.839	39.8584
756.248	41.9857
759.657	44.696
763.063	49.2925
766.468	52.3455
769.871	55.8186
773.273	59.8957
776.676	64.0607
780.075	67.5419
783.474	68.9362
786.871	71.9412
790.266	73.8267
793.661	76.0019
797.054	77.1159
800.446	80.2765
803.834	80.1091
807.224	79.9467
810.612	78.7127
813.998	78.8358
817.384	75.7598
820.766	75.0156
824.149	73.918
827.531	73.4213
830.909	73.4815
834.288	75.1476
837.666	77.1831
841.041	78.1925
844.416	79.7936
847.788	80.8693
851.161	78.4828
854.53	77.9797
857.901	76.8211
861.268	74.6819
864.633	72.7481
868	72.0998
871.363	70.173
874.725	68.2926
878.088	65.6653
881.447	64.4858
884.805	61.5533
888.162	57.2149
891.518	53.8685
894.872	52.2296
898.225	50.6317
901.577	50.6714
904.928	51.9593
908.277	53.6723
911.625	55.1069
914.972	57.1816
918.318	59.6273
921.662	60.6456
925.005	60.4777
928.347	58.3968
931.686	56.1174
935.025	55.7521
938.363	54.2374
941.698	52.7957
945.034	48.7895
948.368	47.2059
951.699	45.8058
955.031	43.0307
958.36	39.8902
961.689	35.2882
965.016	34.5776
968.343	33.7284
971.666	32.4589
974.991	32.2506
978.312	33.4429
981.632	33.4716
984.953	35.4797
988.27	36.5239
991.587	34.8661
994.902	35.9676
998.216	35.9267
1001.53	34.7055
1004.84	34.8439
1008.15	34.3099
1011.46	34.9939
1014.77	36.7501
1018.07	38.6362
1021.38	38.4889
1024.68	38.1968
1027.99	38.1696
1031.29	41.8767
1034.59	42.3528
1037.89	41.1251
1041.18	40.6188
1044.48	44.2422
1047.77	45.8877
1051.07	43.211
1054.36	38.8959
1057.65	36.933
1060.94	39.7308
1064.23	45.2397
1067.52	51.2468
1070.8	56.8943
1074.09	59.8856
1077.37	64.2921
1080.65	66.6805
1083.93	68.5905
1087.21	68.9587
1090.49	69.9521
1093.77	72.3144
1097.04	72.8608
1100.32	72.5803
1103.59	70.8714
1106.86	69.9239
1110.13	67.3102
1113.4	64.0894
1116.67	55.7418
1119.94	50.878
1123.2	43.4241
1126.47	36.0919
1129.73	28.8076
1132.99	20.8313
1136.25	18.6623
1139.51	22.4367
1142.77	25.4362
1146.03	26.4708
1149.28	25.7658
1152.54	24.2514
1155.79	20.7209
1159.04	19.3485
1162.29	16.4285
1165.54	15.3368
1168.79	13.7178
1172.04	12.9977
1175.28	12.6547
1178.53	12.7779
1181.77	13.8821
1185.01	12.762
1188.25	12.7595
1191.49	13.3421
1194.73	13.9823
1197.96	14.7781
1201.2	15.3883
1204.43	16.8588
1207.66	19.3561
1210.9	23.4711
1214.13	25.7721
1217.36	28.6537
1220.58	32.2495
1223.81	33.7598
1227.04	36.0693
1230.26	37.3768
1233.48	39.1228
1236.71	43.0915
1239.93	44.3749
1243.14	46.413
1246.36	48.2533
1249.58	49.5246
1252.8	52.9101
1256.01	55.4902
1259.22	60.214
1262.43	61.8943
1265.64	61.9579
1268.85	64.2511
1272.06	64.9367
1275.27	66.7428
1278.48	69.0754
1281.68	72.3524
1284.88	74.3933
1288.08	76.3246
1291.28	78.3998
1294.48	79.6946
1297.68	81.4976
1300.88	80.8741
1304.07	80.6866
1307.27	80.3927
1310.46	80.8683
1313.65	82.515
1316.85	81.4287
1320.03	80.5555
1323.22	79.8149
1326.41	79.0237
1329.6	77.5609
1332.78	76.5562
1335.96	75.7734
1339.15	73.6035
1342.33	69.0104
1345.51	67.1852
1348.69	66.2652
1351.86	66.9483
1355.04	66.5012
1358.21	66.0369
1361.39	65.1609
1364.56	63.7117
1367.73	61.3187
1370.9	60.2665
1374.07	57.4858
1377.24	54.2058
1380.41	52.3524
1383.57	52.2079
1386.73	52.759
1389.9	52.2786
1393.06	51.7952
1396.22	50.4923
1399.38	51.7233
1402.54	51.0918
1405.69	52.5968
1408.85	55.5935
1412	59.8527
1415.16	63.2032
1418.31	67.7904
1421.46	74.8125
1424.61	83.417
1427.76	90.7182
1430.9	97.2635
1434.05	102.71
1437.2	108.302
1440.34	111.007
1443.48	113.974
1446.62	114.91
1449.76	115.31
1452.9	114.11
1456.04	111.529
1459.17	109.869
1462.31	104.933
1465.44	98.7234
1468.58	91.2227
1471.71	84.1008
1474.84	78.8479
1477.97	70.5123
1481.1	64.0815
1484.22	59.514
1487.35	53.1845
1490.47	48.048
1493.59	43.4433
1496.72	40.3421
1499.84	36.3908
1502.96	31.7812
1506.08	29.4504
1509.19	25.6911
1512.31	21.8973
1515.42	19.4302
1518.54	17.1967
1521.65	17.3334
1524.76	16.4352
1527.87	15.9577
1530.98	14.7422
1534.09	15.52
1537.2	15.673
1540.3	18.0197
1543.41	19.2333
1546.51	20.7929
1549.61	22.3018
1552.71	24.3579
1555.81	26.4975
1558.91	29.777
1562.01	29.8926
1565.1	31.0131
1568.2	31.4595
1571.29	32.4709
1574.38	32.3623
1577.48	33.8342
1580.57	34.2178
1583.65	36.5358
1586.74	36.6404
1589.83	36.933
1592.92	37.8958
1596	38.0812
1599.08	38.5389
1602.16	38.4494
1605.24	38.4552
1608.32	40.0696
1611.4	42.9847
1614.48	44.3692
1617.56	46.3131
1620.63	49.0234
1623.71	50.3336
1626.78	54.1316
1629.85	55.5964
1632.92	58.7968
1635.99	60.4813
1639.06	63.3529
1642.12	66.3249
1645.19	68.0927
1648.25	70.512
1651.32	72.6593
1654.38	73.971
1657.44	72.7951
1660.5	70.7962
1663.56	67.9115
1666.62	64.8065
1669.67	60.0216
1672.73	54.9409
1675.79	49.8281
1678.84	46.4047
1681.89	41.964
1684.94	37.97
1687.99	32.9206
1691.04	28.3512
1694.08	25.0889
1697.13	20.7028
1700.18	17.2136
1703.22	13.1959
1706.26	11.1923
1709.3	9.75888
1712.35	7.68891
1715.39	5.85562
1718.42	4.78036
1721.46	4.10014
1724.5	3.71664
1727.53	2.35885
1730.56	1.79708
1733.6	0.671399
1736.63	1.64214
1739.66	0.825511
1742.69	0.236496
1745.71	-0.0508407
1748.74	0.67614
1751.77	1.35864
1754.79	2.85969
1757.81	2.46657
1760.84	3.5285
1763.86	2.66315
1766.88	3.72221
1769.9	3.44159
1772.91	4.41485
1775.93	3.99992
1778.95	4.36972
1781.96	4.82412
1784.97	3.11046
1787.99	2.40647
1791	2.88801
1794.01	3.38788
1797.01	3.2046
1800.02	2.73259
1803.03	2.6861
1806.03	2.93211
1809.04	3.00503
1812.04	2.6966
1815.04	2.13874
1818.04	1.66412
1821.04	1.73967
1824.04	1.66806
1827.04	3.72886
1830.03	3.55843
1833.03	3.94119
1836.02	4.41268
1839.02	5.21307
1842.01	5.75979
1845	6.95577
1847.99	6.24468
1850.98	6.32328
1853.96	6.1241
1856.95	5.90736
1859.94	6.89604
1862.92	8.21144
1865.9	9.51446
1868.88	9.51277
1871.86	9.16029
1874.84	9.12503
1877.82	9.59789
1880.8	9.60063
1882.58	8.85306
1885.57	8.42798
1888.56	7.36516
1891.54	7.4355
1894.53	8.17643
1897.51	8.92535
1900.5	8.31982
1903.48	8.66536
1906.46	9.43707
1909.44	10.0895
1912.42	9.85825
1915.4	10.7966
1918.37	10.0884
1921.35	8.98042
1924.32	9.17904
1927.3	9.60809
1930.27	10.1916
1933.24	10.617
1936.21	10.1019
1939.18	9.71485
1942.15	9.34738
1945.11	8.75297
1948.08	8.13931
1951.04	8.99636
1954.01	8.45525
1956.97	7.88904
1959.93	6.76145
1962.89	6.04557
1965.85	4.69222
1968.81	4.57251
1971.77	4.1817
1974.72	4.10096
1977.68	2.84203
1980.63	2.40323
1983.58	1.38126
1986.53	2.02041
1989.48	2.09579
1992.43	1.11689
1995.38	1.32322
1998.33	0.453645
2001.27	-0.225229
2004.22	0.422014
2007.16	0.925864
2010.11	0.862828
2013.05	0.688093
2015.99	2.22062
2018.93	1.73382
2021.87	3.92769
2024.8	4.65232
2027.74	5.6104
2030.68	5.97216
2033.61	6.60824
2036.54	7.50297
2039.48	8.56138
2042.41	10.3348
2045.34	11.0504
2048.27	11.1706
2051.19	12.5266
2054.12	14.2768
2057.05	14.8977
2059.97	15.2071
2062.9	15.7628
2065.82	15.4644
2068.74	15.2313
2071.66	14.9191
2074.58	15.397
2077.5	15.5137
2080.41	14.4497
2083.33	13.146
2086.24	14.1629
2089.16	14.7485
2092.07	13.5379
2094.98	13.8446
2097.89	13.4677
2100.8	13.1321
2103.71	14.6515
2106.62	15.1263
2109.53	16.4814
2112.43	20.1864
2115.33	21.8142
2118.24	22.5221
2121.14	24.7011
2124.04	27.4868
2126.94	28.7899
2129.84	31.1503
2132.74	34.2336
2135.63	37.1997
2138.53	39.2234
2141.43	41.298
2144.32	44.5317
2147.21	46.2101
2150.1	49.1382
2152.99	51.3163
2155.88	54.6168
2158.77	56.6353
2161.66	57.1542
2164.55	59.1522
2167.43	60.0131
2170.31	61.0215
2173.2	62.1054
2176.08	62.7027
2178.96	63.0479
2181.84	63.0064
2184.72	61.5834
2187.6	61.2677
2190.47	60.4179
2193.35	59.1195
2196.23	57.7733
2199.1	54.602
2201.97	51.1801
2204.84	47.721
2207.71	45.4931
2210.58	42.2954
2213.45	39.2697
2216.32	36.156
2219.19	33.8675
2222.05	31.5756
2224.92	30.2135
2227.78	28.2927
2230.64	25.4427
2233.5	23.6714
2236.36	21.7945
2239.22	20.9625
2242.08	19.1716
2244.94	18.2569
2247.79	18.1999
2250.65	16.6319
2253.5	15.4784
2256.36	16.9594
2259.21	18.8091
2262.06	18.5725
2264.91	17.6388
2267.76	16.5196
2270.6	14.1189
2273.45	13.9988
2276.3	12.6597
2279.14	12.7063
2281.98	10.6649
2284.83	10.6596
2287.67	10.9491
2290.51	10.4889
2293.35	9.31783
2296.19	9.21281
2299.02	9.19966
2301.86	10.7373
2304.7	12.3938
2307.53	12.6371
2310.36	13.7399
2313.2	14.8389
2316.03	14.5877
2318.86	15.1215
2321.69	16.6843
2324.51	18.1069
2327.34	17.7665
2330.17	16.6506
2332.99	15.41
2335.82	15.886
2338.64	14.3183
2341.46	13.2297
2344.28	13.1621
2347.1	12.5045
2349.92	11.1842
2352.74	10.6136
2355.56	10.7753
2358.37	8.98523
2361.19	8.2962
2364	8.62112
2366.82	10.0331
2369.63	11.0386
2372.44	10.4457
2375.25	9.77884
2378.06	9.50352
2380.86	9.73819
2383.67	7.82427
2386.48	8.20074
2389.28	7.42783
2392.09	7.90455
2394.89	6.75008
2397.69	5.85785
2400.49	7.44988
2403.29	8.71068
2406.09	8.18482
2408.89	8.07266
2411.69	7.40009
2414.48	9.1258
2417.28	9.67044
2420.07	10.5096
2422.86	10.7328
2425.65	10.3425
2428.45	10.5822
2431.23	11.0649
2434.02	11.1481
2436.81	11.4433
2439.6	10.7741
2442.38	10.585
2445.17	9.73803
2447.95	9.34651
2450.73	7.37682
2453.52	7.05457
2456.3	7.66946
2459.08	6.73659
2461.85	5.94073
2464.63	5.15562
2467.41	5.23757
2470.19	4.23927
2472.96	2.09029
2475.73	1.62867
2478.51	1.19076
2481.28	1.51414
2484.05	2.22713
2486.82	1.67782
2489.59	0.681954
2492.35	1.10487
2495.12	1.69968
2497.89	0.988267
2500.65	1.90147
2503.42	1.61668
2506.18	2.80891
2508.94	2.11741
2511.7	1.69422
2514.46	1.15007
2517.22	0.658036
2519.98	0.74766
2522.73	1.55465
2525.49	1.73418
2528.25	1.70926
2531	3.34027
2533.75	3.78427
2536.5	4.87076
2539.25	4.8568
2542.01	5.85383
2544.75	6.20889
2547.5	6.01382
2550.25	7.66117
2553	7.68826
2555.74	8.06331
2558.49	8.43542
2561.23	8.61755
2563.97	8.05137
2566.71	7.65394
2569.45	6.52755
2572.19	5.99693
2574.93	5.27871
2577.67	5.42281
2580.4	3.7026
2583.14	3.05485
2585.87	3.52711
2588.6	2.22672
2591.34	2.1616
2594.07	2.09574
2596.8	0.990263
2599.53	1.74377
2602.26	1.09596
2604.98	1.43902
2607.71	-0.494629
2610.44	-0.867384
2613.16	-0.740866
2615.88	0.0210965
2618.61	0.127095
2621.33	0.92654
2624.05	0.964212
2626.77	0.541468
2629.49	-0.147424
2632.21	-0.635246
2634.92	0.326878
2637.64	2.74415
2640.35	4.60707
2643.07	5.41729
2645.78	5.24392
2648.49	5.62538
2651.2	5.83225
2653.91	5.38498
2656.62	6.72099
2659.33	5.51452
2662.04	4.98985
2664.74	6.27431
2667.45	5.63118
2670.15	5.51727
2672.86	4.17596
2675.56	3.56187
2678.26	3.52306
2680.96	3.96973
2683.66	3.89344
2686.36	4.00157
2689.06	3.65347
2691.75	2.86093
2694.45	3.54199
2697.14	4.3552
2699.84	6.07117
2702.53	8.14435
2705.22	7.55316
2707.91	9.14753
2710.6	9.50853
2713.29	9.60528
2715.98	10.3771
2718.67	11.2262
2721.35	12.5812
2724.04	12.5767
2726.72	12.1695
2729.4	11.8386
2732.09	11.9712
2734.77	11.4919
2737.45	10.0622
2740.13	8.96259
2742.81	8.20196
2745.48	7.62578
2748.16	7.27535
2750.84	5.45853
2753.51	4.63063
2756.19	3.26086
2758.86	2.02451
2761.53	2.02127
2764.2	1.89296
2766.87	1.78581
2769.54	1.64628
2772.21	0.776678
2774.88	1.07073
2777.54	1.32878
2780.21	0.920642
2782.87	1.13909
2785.53	1.61873
2788.2	0.913079
2790.86	0.729499
2793.52	0.0348033
2796.18	0.0057976
2798.84	0.514891
2801.49	-0.0297105
2804.15	0.332261
2806.81	0.328485
2809.46	0.797988
2812.12	1.52446
2814.77	2.59286
2817.42	4.54317
2820.07	6.04459
2822.72	8.97546
2825.37	13.0761
2828.02	18.5795
2830.67	23.2695
2833.31	28.8765
2835.96	34.6709
2838.61	41.3205
2841.25	49.0459
2843.89	56.6506
2846.53	63.9987
2849.17	73.6484
2851.81	83.2578
2854.45	91.3088
2857.09	101.812
2859.73	110.424
2862.36	119.627
2865	128.853
2867.64	136.662
2870.27	144.495
2872.9	152.197
2875.53	158.401
2878.16	164.982
2880.79	172.029
2883.42	176.7
2886.05	182.88
2888.68	188.126
2891.3	195.199
2893.93	201.532
2896.55	209.379
2899.18	217.079
2901.8	225.74
2904.42	234.74
2907.04	245.429
2909.66	256.853
2912.28	269.273
2914.9	283.074
2917.51	294.844
2920.13	303.825
2922.74	311.9
2925.36	318.625
2927.97	323.347
2930.59	324.918
2933.2	323.227
2935.81	319.577
2938.42	313.13
2941.02	305.29
2943.63	296.749
2946.24	284.967
2948.85	272.538
2951.45	260.282
2954.05	248.345
2956.66	235.489
2959.26	223.892
2961.86	213.978
2964.46	202.559
2967.06	193.302
2969.66	184.89
2972.26	178.632
2974.85	171.034
2977.45	164.437
2980.05	157.491
2982.64	148.516
2985.23	139.669
2987.83	131.695
2990.42	121.713
2993.01	112.154
2995.6	101.404
2998.19	91.4101
3000.77	81.5708
3003.36	72.0023
3005.95	62.4572
3008.53	53.7855
3011.12	45.5843
3013.7	38.7092
3016.28	32.0197
3018.86	26.426
3021.44	22.7392
3024.02	18.3799
3026.6	15.3371
3029.18	12.6653
3031.76	11.8321
3034.33	11.3335
3036.91	11.6587
3039.48	11.7975
3042.05	12.8022
3044.63	14.5281
3047.2	16.2526
3049.77	17.0319
3052.34	17.7014
3054.91	18.1952
3057.48	20.0649
3060.04	19.9909
3062.61	19.5886
3065.17	18.7826
3067.74	18.3559
3070.3	17.6022
3072.87	14.3475
3075.43	12.8544
3077.99	10.496
3080.55	9.96999
3083.11	8.27683
3085.67	6.19339
3088.22	3.64764
3090.78	3.57305
3093.34	2.60578
3095.89	3.04415
3098.44	3.16839
3101	4.01698
3103.55	4.93886
3106.1	6.35539
3108.65	6.7506
3111.2	7.79069
3113.75	9.20057
3116.3	10.2738
3118.84	11.258
3121.39	11.0571
3123.93	11.5221
3126.48	12.1243
3129.02	13.1747
3131.56	13.8665
3134.1	13.0221
3136.64	12.6722
3139.18	14.0927
3141.72	15.0185
3144.26	14.8792
3146.8	15.8408
3149.33	17.9069