File: data/Raman/poly_smoothed/Mbcal_20_25_32_1x_45s_532 nm_x100_100%_600 gr_mm_01.txt
#Acq. time (s)=	45
#Accumulations=	2
#Range (cm-¹)=	200...3150
#Windows=	2
#Auto scanning=	Off
#Autofocus=	Off
#Macrospot=	Off
#AutoExposure=	Off
#Spike filter=	Multiple accum.
#Delay time (s)=	0
#Binning=	1
#Readout mode=	Signal
#DeNoise=	Off
#ICS correction=	On
#Dark correction=	Off
#Inst. Process=	Off
#Detector Gain=	Best Dynamic Range
#Detector ADC=	20 kHz
#Detector temperature (°C)=	-69.85
#Instrument=	LabRAM HR Evol
#Detector=	Synapse
#Objective=	x100
#Grating=	600 gr/mm
#ND Filter=	100%
#Laser (nm)=	532
#Hole=	100.021
#Range=	Auto
#Laser Pol.=	No
#Raman. Pol.=	No
#Laser Pol. (°)=	-0.0007625
#Raman Pol. (°)=	89.9995
#Collection=	Microscope
#StageXY=	Marzhauser
#StageZ=	Marzhauser
#X (µm)=	-1133.4
#Y (µm)=	1294.5
#Z (µm)=	578.05
#Full time(mm:ss)=	3:18
#Project=
#Sample=
#Site=
#Title=	Mbcal_20_25_32_2x_45s_532 nm_x100_100%_600 gr_mm
#Remark=
#Date=	18.07.2022 12:27
#Acquired=	18.07.2022 12:27:31
#Base:Fit=	10.08.2022 10:55:08
#Base:Sub=	10.08.2022 10:55:14
#Filter:Polynom=	16.08.2022 10:07:28
#AxisType[0]=Intens
#AxisUnit[0]=Cnt
#AxisType[1]=Spectr
#AxisUnit[1]=1/cm
200.419	45.8714
204.048	37.5869
207.678	28.183
211.304	21.8641
214.928	18.3284
218.554	16.0424
222.176	13.9938
225.798	11.8838
229.417	10.0383
233.035	8.42355
236.653	8.57922
240.268	7.35456
243.881	6.03769
247.493	5.7361
251.103	8.30581
254.715	7.35804
258.322	6.94866
261.929	7.87482
265.534	7.71096
269.137	8.16526
272.739	8.70063
276.34	7.45976
279.939	4.48105
283.537	2.04021
287.134	-0.00207499
290.729	-0.438161
294.323	0.500848
297.913	3.93019
301.504	5.55107
305.093	8.85555
308.682	11.2078
312.268	14.0555
315.852	17.4931
319.436	22.1359
323.018	24.9827
326.597	26.7989
330.177	30.5354
333.753	33.6724
337.331	35.8306
340.906	37.8008
344.478	35.033
348.051	36.2431
351.621	35.1819
355.189	31.7566
358.757	30.0072
362.323	26.5724
365.889	24.4197
369.451	21.377
373.012	19.5359
376.574	18.2762
380.133	19.8125
383.69	19.2981
387.245	18.2641
390.8	17.8887
394.353	18.8911
397.906	20.1251
401.456	23.202
405.005	24.8298
408.552	23.4144
412.099	23.8046
415.643	24.5915
419.187	24.0427
422.728	23.7631
426.269	22.5681
429.806	22.1043
433.344	20.6265
436.881	19.3428
440.416	16.2397
443.949	15.1768
447.48	16.2019
451.011	17.1695
454.541	18.2357
458.069	18.3946
461.594	19.3615
465.119	20.8278
468.642	21.1828
472.165	21.1835
475.684	22.9843
479.204	23.9548
482.721	26.7006
486.239	29.9118
489.753	31.859
493.268	31.6275
496.779	32.9214
500.289	34.5598
503.8	35.9393
507.307	37.423
510.813	38.8904
514.32	40.8567
517.823	42.823
521.325	42.6464
524.826	42.554
528.325	44.9039
531.823	46.7045
535.32	47.2944
538.815	49.4232
542.309	48.7958
545.802	47.4004
549.293	45.3
552.783	43.8064
556.271	41.1266
559.759	37.4378
563.245	36.3232
566.729	31.9827
570.213	28.9203
573.693	23.7917
577.173	18.4395
580.652	13.9634
584.13	11.1289
587.605	11.08
591.08	7.29573
594.552	4.48861
598.025	3.5423
601.496	2.33766
604.964	2.91876
608.433	4.6224
611.898	6.28451
615.364	7.4031
618.827	8.64194
622.288	9.75245
625.75	10.7156
629.209	11.6039
632.667	11.9912
636.125	13.2418
639.58	13.7904
643.033	12.0395
646.485	11.4083
649.936	10.2713
653.388	9.2865
656.836	9.22847
660.283	7.0299
663.728	7.62679
667.173	4.54441
670.616	4.92191
674.057	2.78166
677.498	1.02011
680.937	3.57176
684.375	5.16153
687.809	7.51384
691.244	10.9202
694.678	12.7813
698.111	14.5773
701.54	17.5059
704.97	19.994
708.398	22.3546
711.826	26.0763
715.25	29.3917
718.675	31.0738
722.096	32.1846
725.518	33.1813
728.937	31.8292
732.357	32.8755
735.773	32.993
739.19	33.6788
742.604	34.1422
746.018	34.5975
749.429	32.9798
752.839	34.0309
756.248	36.2893
759.657	39.7235
763.063	42.6221
766.468	47.0373
769.871	47.6809
773.273	50.3074
776.676	51.7835
780.075	54.8536
783.474	57.6747
786.871	59.9993
790.266	59.9523
793.661	62.2813
797.054	61.903
800.446	62.6519
803.834	62.7744
807.224	63.0643
810.612	62.5044
813.998	63.0146
817.384	63.089
820.766	63.1756
824.149	64.2822
827.531	67.1929
830.909	69.9143
834.288	71.1021
837.666	76.1978
841.041	80.4359
844.416	83.3277
847.788	82.5651
851.161	81.5453
854.53	80.0429
857.901	82.2431
861.268	81.2381
864.633	80.1441
868	74.8643
871.363	70.9147
874.725	68.0221
878.088	63.3644
881.447	59.5106
884.805	55.897
888.162	52.1831
891.518	48.5134
894.872	44.6286
898.225	42.4887
901.577	41.4223
904.928	41.2247
908.277	43.0228
911.625	43.7642
914.972	46.1189
918.318	48.2482
921.662	48.7758
925.005	48.3847
928.347	49.8482
931.686	49.7831
935.025	49.0083
938.363	49.0681
941.698	51.0474
945.034	47.6444
948.368	45.9284
951.699	44.4292
955.031	43.4661
958.36	37.0569
961.689	32.1909
965.016	31.7957
968.343	31.2177
971.666	30.1265
974.991	30.8262
978.312	29.5057
981.632	28.9114
984.953	30.0685
988.27	27.614
991.587	28.23
994.902	28.4364
998.216	28.6391
1001.53	28.5368
1004.84	28.2981
1008.15	31.7724
1011.46	33.665
1014.77	35.4777
1018.07	37.6562
1021.38	41.7109
1024.68	44.1242
1027.99	46.7517
1031.29	47.146
1034.59	46.1428
1037.89	43.5196
1041.18	43.6656
1044.48	43.6261
1047.77	43.2273
1051.07	40.931
1054.36	38.4304
1057.65	35.2351
1060.94	33.286
1064.23	32.6826
1067.52	31.155
1070.8	29.5079
1074.09	31.1809
1077.37	30.4086
1080.65	28.4252
1083.93	29.0956
1087.21	30.2919
1090.49	31.9883
1093.77	33.3147
1097.04	35.7243
1100.32	36.8088
1103.59	38.774
1106.86	40.8717
1110.13	41.1876
1113.4	39.9254
1116.67	39.6181
1119.94	38.3709
1123.2	37.0689
1126.47	36.6243
1129.73	36.0138
1132.99	34.701
1136.25	36.2123
1139.51	35.6467
1142.77	36.9193
1146.03	34.4777
1149.28	31.756
1152.54	27.6705
1155.79	24.7162
1159.04	21.0209
1162.29	18.1925
1165.54	14.6842
1168.79	13.362
1172.04	12.0862
1175.28	13.0382
1178.53	13.3141
1181.77	13.675
1185.01	13.8213
1188.25	15.2926
1191.49	18.8428
1194.73	21.5409
1197.96	25.1024
1201.2	29.3325
1204.43	34.0265
1207.66	38.4817
1210.9	41.777
1214.13	47.8648
1217.36	52.8085
1220.58	56.4892
1223.81	58.3281
1227.04	60.8322
1230.26	64.6967
1233.48	66.6011
1236.71	70.4905
1239.93	74.8345
1243.14	78.6297
1246.36	81.1641
1249.58	86.2935
1252.8	89.125
1256.01	93.1251
1259.22	96.068
1262.43	98.2935
1265.64	103.564
1268.85	107.156
1272.06	112.484
1275.27	116.393
1278.48	120.542
1281.68	123.787
1284.88	127.698
1288.08	134.15
1291.28	137.076
1294.48	142.307
1297.68	145.857
1300.88	147.745
1304.07	152.986
1307.27	157.176
1310.46	159.317
1313.65	162.584
1316.85	166.27
1320.03	168.703
1323.22	167.526
1326.41	167.152
1329.6	167.383
1332.78	165.672
1335.96	162.612
1339.15	161.447
1342.33	158.481
1345.51	156.232
1348.69	153.852
1351.86	151.066
1355.04	147.824
1358.21	143.367
1361.39	138.974
1364.56	135.299
1367.73	130.913
1370.9	127.312
1374.07	120.54
1377.24	117.358
1380.41	112.909
1383.57	109.934
1386.73	107.51
1389.9	104.312
1393.06	103.276
1396.22	100.78
1399.38	99.7434
1402.54	100.477
1405.69	102.299
1408.85	105.632
1412	111.955
1415.16	119.508
1418.31	127.871
1421.46	137.479
1424.61	150.282
1427.76	162.146
1430.9	173.514
1434.05	186.587
1437.2	195.892
1440.34	205.294
1443.48	212.209
1446.62	216.852
1449.76	218.763
1452.9	218.293
1456.04	219.569
1459.17	221.082
1462.31	221.462
1465.44	220.429
1468.58	218.619
1471.71	213.844
1474.84	209.026
1477.97	202.51
1481.1	196.442
1484.22	186.758
1487.35	177.668
1490.47	167.462
1493.59	157.663
1496.72	147.998
1499.84	139.548
1502.96	132.378
1506.08	122.731
1509.19	113.907
1512.31	104.52
1515.42	94.8917
1518.54	86.5447
1521.65	77.9607
1524.76	69.7366
1527.87	64.3389
1530.98	62.6119
1534.09	63.9775
1537.2	64.2315
1540.3	65.9768
1543.41	67.8213
1546.51	70.1108
1549.61	72.1978
1552.71	72.8713
1555.81	74.5287
1558.91	74.698
1562.01	75.8678
1565.1	77.6304
1568.2	80.6531
1571.29	84.9732
1574.38	87.8273
1577.48	92.4985
1580.57	97.0982
1583.65	100.652
1586.74	104.892
1589.83	110.048
1592.92	113.385
1596	115.381
1599.08	116.576
1602.16	118.745
1605.24	118.442
1608.32	119.816
1611.4	120.445
1614.48	117.18
1617.56	117.408
1620.63	118.631
1623.71	119.936
1626.78	121.636
1629.85	120.994
1632.92	123.854
1635.99	126.956
1639.06	129.432
1642.12	133.557
1645.19	136.109
1648.25	137.8
1651.32	139.026
1654.38	141.985
1657.44	142.113
1660.5	141.091
1663.56	139.541
1666.62	136.531
1669.67	131.527
1672.73	125.51
1675.79	116.847
1678.84	108.555
1681.89	98.2103
1684.94	87.0973
1687.99	75.7655
1691.04	65.1477
1694.08	56.7321
1697.13	49.4654
1700.18	39.914
1703.22	33.2103
1706.26	26.9954
1709.3	21.7425
1712.35	18.4673
1715.39	14.7643
1718.42	10.4032
1721.46	7.55598
1724.5	5.57403
1727.53	5.80525
1730.56	6.34609
1733.6	4.70529
1736.63	5.24644
1739.66	5.91445
1742.69	7.09176
1745.71	6.50308
1748.74	6.41419
1751.77	6.545
1754.79	6.54145
1757.81	6.98045
1760.84	6.95092
1763.86	5.6388
1766.88	5.26949
1769.9	5.35613
1772.91	6.49629
1775.93	6.9331
1778.95	7.15193
1781.96	7.3342
1784.97	7.26713
1787.99	7.47992
1791	6.18705
1794.01	4.9907
1797.01	5.23456
1800.02	4.94756
1803.03	5.49841
1806.03	4.63615
1809.04	3.66897
1812.04	4.05433
1815.04	2.40515
1818.04	1.38775
1821.04	0.685683
1824.04	0.115732
1827.04	-0.891382
1830.03	-1.39074
1833.03	-1.90582
1836.02	-3.625
1839.02	-2.30471
1842.01	-1.0914
1845	-0.0170259
1847.99	1.41462
1850.98	1.74841
1853.96	3.30456
1856.95	5.41298
1859.94	6.71229
1862.92	8.25246
1865.9	9.20346
1868.88	12.1493
1871.86	14.1992
1874.84	14.1273
1877.82	15.9982
1880.8	15.8993
1882.58	14.6021
1885.57	14.434
1888.56	14.6073
1891.54	12.7213
1894.53	10.9114
1897.51	9.67509
1900.5	8.87797
1903.48	6.29707
1906.46	5.30838
1909.44	5.10872
1912.42	5.08648
1915.4	5.04815
1918.37	4.94778
1921.35	4.61137
1924.32	5.12732
1927.3	5.25392
1930.27	6.48778
1933.24	7.54698
1936.21	7.93429
1939.18	9.17112
1942.15	9.58929
1945.11	8.45114
1948.08	9.72629
1951.04	8.50785
1954.01	7.77003
1956.97	6.18948
1959.93	6.90052
1962.89	6.93266
1965.85	6.89052
1968.81	6.49828
1971.77	6.75875
1974.72	6.45514
1977.68	6.71416
1980.63	6.81793
1983.58	7.69931
1986.53	8.10139
1989.48	8.56918
1992.43	8.1132
1995.38	7.03175
1998.33	6.92713
2001.27	7.79589
2004.22	9.97226
2007.16	8.91117
2010.11	8.84826
2013.05	7.88578
2015.99	8.12289
2018.93	7.43106
2021.87	6.16556
2024.8	4.48638
2027.74	2.73298
2030.68	4.13234
2033.61	4.5858
2036.54	5.79205
2039.48	5.81166
2042.41	6.6876
2045.34	8.24224
2048.27	8.40639
2051.19	9.56217
2054.12	11.3129
2057.05	11.3058
2059.97	14.0493
2062.9	14.4946
2065.82	13.7694
2068.74	14.831
2071.66	15.8185
2074.58	16.9952
2077.5	16.6645
2080.41	17.6329
2083.33	20.3608
2086.24	20.5606
2089.16	21.3005
2092.07	21.7353
2094.98	22.5853
2097.89	23.1845
2100.8	26.0191
2103.71	26.5547
2106.62	27.1689
2109.53	30.0713
2112.43	31.4889
2115.33	34.2549
2118.24	37.1556
2121.14	39.66
2124.04	43.4505
2126.94	46.2796
2129.84	51.235
2132.74	54.0522
2135.63	57.4353
2138.53	59.8842
2141.43	64.5492
2144.32	67.5428
2147.21	70.8355
2150.1	76.1435
2152.99	79.8795
2155.88	85.0448
2158.77	88.8413
2161.66	92.8197
2164.55	96.2433
2167.43	97.8328
2170.31	99.968
2173.2	100.443
2176.08	101.706
2178.96	102.567
2181.84	101.625
2184.72	100.335
2187.6	96.5832
2190.47	93.7348
2193.35	90.4204
2196.23	86.3294
2199.1	82.7179
2201.97	78.4605
2204.84	73.7895
2207.71	68.4637
2210.58	62.4241
2213.45	56.9217
2216.32	53.5789
2219.19	50.1642
2222.05	47.7226
2224.92	46.6164
2227.78	44.4199
2230.64	40.4194
2233.5	37.7341
2236.36	34.6522
2239.22	31.7872
2242.08	30.6169
2244.94	29.0494
2247.79	28.4605
2250.65	26.7434
2253.5	24.5228
2256.36	23.5046
2259.21	22.2893
2262.06	20.9
2264.91	19.0517
2267.76	18.3163
2270.6	18.4856
2273.45	17.4706
2276.3	16.8558
2279.14	15.8379
2281.98	15.1857
2284.83	14.6596
2287.67	15.957
2290.51	14.6513
2293.35	13.6842
2296.19	11.4517
2299.02	10.2655
2301.86	9.32624
2304.7	9.74774
2307.53	8.89775
2310.36	8.79008
2313.2	9.06178
2316.03	9.64601
2318.86	10.8163
2321.69	10.2064
2324.51	10.3056
2327.34	10.2903
2330.17	9.14419
2332.99	8.61367
2335.82	7.20124
2338.64	6.25089
2341.46	6.18538
2344.28	5.63206
2347.1	4.84828
2349.92	3.59392
2352.74	2.45349
2355.56	2.40872
2358.37	1.78614
2361.19	0.538505
2364	-0.212856
2366.82	0.0950739
2369.63	0.408197
2372.44	-0.562434
2375.25	-0.439868
2378.06	-0.514084
2380.86	-0.0829047
2383.67	-0.523186
2386.48	1.13898
2389.28	0.775036
2392.09	0.919508
2394.89	2.02108
2397.69	1.21856
2400.49	0.97834
2403.29	0.472364
2406.09	1.06181
2408.89	1.23761
2411.69	1.35229
2414.48	0.996108
2417.28	1.59147
2420.07	1.54703
2422.86	2.1608
2425.65	1.49914
2428.45	0.144924
2431.23	0.152804
2434.02	0.168424
2436.81	0.598653
2439.6	0.621648
2442.38	1.5102
2445.17	1.68258
2447.95	2.39359
2450.73	1.7747
2453.52	2.70247
2456.3	2.64608
2459.08	1.38056
2461.85	2.20424
2464.63	1.22966
2467.41	2.1819
2470.19	2.75078
2472.96	1.83496
2475.73	1.16651
2478.51	0.73892
2481.28	0.943791
2484.05	2.11803
2486.82	2.01518
2489.59	2.24132
2492.35	1.56091
2495.12	1.15699
2497.89	1.98462
2500.65	2.36343
2503.42	2.03296
2506.18	2.84475
2508.94	3.63189
2511.7	2.99265
2514.46	3.45208
2517.22	2.53426
2519.98	3.07136
2522.73	2.74453
2525.49	2.99782
2528.25	2.93882
2531	2.63105
2533.75	3.26607
2536.5	3.21223
2539.25	3.3051
2542.01	2.97695
2544.75	4.68995
2547.5	5.54129
2550.25	5.85386
2553	5.6133
2555.74	5.53917
2558.49	3.98105
2561.23	3.92297
2563.97	3.86673
2566.71	4.21125
2569.45	3.914
2572.19	3.13167
2574.93	4.294
2577.67	3.67946
2580.4	2.84439
2583.14	2.78447
2585.87	3.75028
2588.6	3.75029
2591.34	3.70075
2594.07	3.99242
2596.8	2.42449
2599.53	3.50718
2602.26	4.05422
2604.98	3.80577
2607.71	4.84711
2610.44	4.46626
2613.16	3.97865
2615.88	3.49386
2618.61	3.96906
2621.33	3.4265
2624.05	3.0077
2626.77	4.89854
2629.49	5.75627
2632.21	6.18309
2634.92	7.17718
2637.64	8.57702
2640.35	9.51958
2643.07	9.57539
2645.78	10.5613
2648.49	11.4
2651.2	12.9422
2653.91	12.1856
2656.62	11.6711
2659.33	12.5943
2662.04	11.9489
2664.74	11.9372
2667.45	11.8956
2670.15	10.6779
2672.86	9.13292
2675.56	8.18698
2678.26	7.27106
2680.96	7.30419
2683.66	6.35276
2686.36	5.99742
2689.06	5.99016
2691.75	7.59566
2694.45	8.57891
2697.14	9.22704
2699.84	9.62485
2702.53	11.9175
2705.22	12.9688
2707.91	15.069
2710.6	16.8911
2713.29	18.5291
2715.98	19.3239
2718.67	19.6774
2721.35	19.593
2724.04	20.5535
2726.72	19.9773
2729.4	18.9744
2732.09	19.2394
2734.77	18.9822
2737.45	18.1711
2740.13	16.2317
2742.81	15.361
2745.48	13.6309
2748.16	11.465
2750.84	10.1798
2753.51	8.76064
2756.19	7.90271
2758.86	7.12654
2761.53	6.10107
2764.2	4.89529
2766.87	5.55515
2769.54	5.89105
2772.21	6.48171
2774.88	5.68881
2777.54	4.18307
2780.21	2.1782
2782.87	3.00876
2785.53	1.58075
2788.2	0.954359
2790.86	0.614578
2793.52	-0.76363
2796.18	0.0702887
2798.84	0.34833
2801.49	-0.388317
2804.15	-1.37856
2806.81	-2.38861
2809.46	-3.63209
2812.12	-4.53418
2814.77	-4.66974
2817.42	-3.0224
2820.07	1.0494
2822.72	6.96435
2825.37	13.505
2828.02	20.5962
2830.67	29.1638
2833.31	38.6286
2835.96	48.0988
2838.61	57.1958
2841.25	70.1436
2843.89	84.91
2846.53	101.124
2849.17	118.412
2851.81	136.518
2854.45	154.723
2857.09	172.757
2859.73	190.778
2862.36	207.083
2865	221.708
2867.64	236.595
2870.27	249.63
2872.9	261.081
2875.53	271.516
2878.16	281.571
2880.79	292.268
2883.42	303.604
2886.05	315.069
2888.68	324.747
2891.3	333.537
2893.93	342.608
2896.55	353.297
2899.18	365.092
2901.8	378.042
2904.42	395.522
2907.04	414.475
2909.66	433.269
2912.28	455.492
2914.9	475.43
2917.51	493.819
2920.13	512.026
2922.74	525.714
2925.36	536.361
2927.97	542.199
2930.59	544.719
2933.2	544.231
2935.81	538.503
2938.42	529.5
2941.02	515.806
2943.63	500.235
2946.24	482.769
2948.85	462.38
2951.45	439.795
2954.05	417.495
2956.66	395.675
2959.26	373.336
2961.86	355.263
2964.46	337.376
2967.06	322.024
2969.66	306.991
2972.26	292.113
2974.85	279.779
2977.45	266.556
2980.05	252.999
2982.64	237.916
2985.23	221.587
2987.83	205.206
2990.42	188.378
2993.01	171.626
2995.6	154.773
2998.19	138.347
3000.77	120.446
3003.36	103.022
3005.95	86.8533
3008.53	71.4167
3011.12	58.3607
3013.7	46.6074
3016.28	35.7176
3018.86	27.3116
3021.44	19.9089
3024.02	15.2554
3026.6	12.7328
3029.18	9.43897
3031.76	8.32289
3034.33	5.97764
3036.91	7.08608
3039.48	7.81047
3042.05	8.80001
3044.63	8.90139
3047.2	10.4797
3049.77	12.3242
3052.34	14.1142
3054.91	15.5929
3057.48	16.639
3060.04	17.1777
3062.61	17.7731
3065.17	17.5575
3067.74	17.1771
3070.3	16.7991
3072.87	15.7665
3075.43	13.8924
3077.99	12.2631
3080.55	10.2181
3083.11	7.84511
3085.67	6.41846
3088.22	5.64367
3090.78	3.51092
3093.34	2.18725
3095.89	0.0290172
3098.44	0.737704
3101	1.4069
3103.55	1.88164
3106.1	3.12827
3108.65	4.52805
3111.2	5.85311
3113.75	8.69427
3116.3	11.3726
3118.84	13.0881
3121.39	15.8901
3123.93	19.039
3126.48	22.3853
3129.02	25.6183
3131.56	28.1261
3134.1	31.3607
3136.64	34.3048
3139.18	38.2873
3141.72	41.636
3144.26	44.6692
3146.8	48.0539
3149.33	51.0468