File: data/Raman/poly_smoothed/Mbcal_20_25_39_1x_45s_532 nm_x100_100%_600 gr_mm_01.txt
#Acq. time (s)=	45
#Accumulations=	2
#Range (cm-¹)=	200...3150
#Windows=	2
#Auto scanning=	Off
#Autofocus=	Off
#Macrospot=	Off
#AutoExposure=	Off
#Spike filter=	Multiple accum.
#Delay time (s)=	0
#Binning=	1
#Readout mode=	Signal
#DeNoise=	Off
#ICS correction=	On
#Dark correction=	Off
#Inst. Process=	Off
#Detector Gain=	Best Dynamic Range
#Detector ADC=	20 kHz
#Detector temperature (°C)=	-69.85
#Instrument=	LabRAM HR Evol
#Detector=	Synapse
#Objective=	x100
#Grating=	600 gr/mm
#ND Filter=	100%
#Laser (nm)=	532
#Hole=	100.021
#Range=	Auto
#Laser Pol.=	No
#Raman. Pol.=	No
#Laser Pol. (°)=	-0.0007625
#Raman Pol. (°)=	89.9995
#Collection=	Microscope
#StageXY=	Marzhauser
#StageZ=	Marzhauser
#X (µm)=	-1116.2
#Y (µm)=	1274.4
#Z (µm)=	578.55
#Full time(mm:ss)=	3:18
#Project=
#Sample=
#Site=
#Title=	Mbcal_20_25_39_2x_45s_532 nm_x100_100%_600 gr_mm
#Remark=
#Date=	18.07.2022 13:10
#Acquired=	18.07.2022 13:10:36
#Base:Fit=	10.08.2022 10:55:08
#Base:Sub=	10.08.2022 10:55:14
#Filter:Polynom=	16.08.2022 10:07:28
#AxisType[0]=Intens
#AxisUnit[0]=Cnt
#AxisType[1]=Spectr
#AxisUnit[1]=1/cm
200.419	10.4474
204.048	9.83112
207.678	7.73702
211.304	5.31207
214.928	4.2344
218.554	2.8946
222.176	3.64903
225.798	3.94595
229.417	6.35085
233.035	7.96282
236.653	10.1142
240.268	11.5311
243.881	13.9806
247.493	14.8296
251.103	16.0374
254.715	17.2423
258.322	19.0841
261.929	21.7594
265.534	21.785
269.137	23.1584
272.739	22.662
276.34	22.8381
279.939	20.65
283.537	18.1948
287.134	18.5637
290.729	17.0979
294.323	16.6073
297.913	17.3249
301.504	18.9977
305.093	18.6697
308.682	20.7981
312.268	21.0804
315.852	24.622
319.436	26.2317
323.018	28.5575
326.597	30.7736
330.177	30.1972
333.753	30.6248
337.331	28.5673
340.906	27.0193
344.478	24.609
348.051	23.1344
351.621	21.9282
355.189	19.5593
358.757	19.5864
362.323	17.8218
365.889	17.1755
369.451	15.6764
373.012	15.947
376.574	15.0963
380.133	14.7148
383.69	16.008
387.245	17.5438
390.8	17.8952
394.353	18.446
397.906	20.463
401.456	21.5533
405.005	23.6736
408.552	23.5084
412.099	26.053
415.643	24.497
419.187	23.6545
422.728	23.0945
426.269	22.205
429.806	20.0626
433.344	19.2828
436.881	18.3518
440.416	17.9334
443.949	17.9644
447.48	17.6672
451.011	16.1554
454.541	16.1625
458.069	16.3261
461.594	17.9325
465.119	19.0958
468.642	20.4904
472.165	22.915
475.684	23.4928
479.204	25.1375
482.721	26.7933
486.239	28.6615
489.753	30.1109
493.268	31.368
496.779	33.2262
500.289	33.4436
503.8	32.7302
507.307	32.5385
510.813	33.5705
514.32	35.2877
517.823	34.897
521.325	36.1572
524.826	36.6813
528.325	36.8939
531.823	35.984
535.32	36.2645
538.815	37.4043
542.309	38.3821
545.802	37.5379
549.293	36.6813
552.783	35.0839
556.271	34.1326
559.759	31.1414
563.245	29.3948
566.729	26.1919
570.213	22.5419
573.693	18.528
577.173	15.3489
580.652	12.1085
584.13	8.19122
587.605	5.60313
591.08	3.77416
594.552	3.41656
598.025	3.17795
601.496	2.64867
604.964	1.88429
608.433	2.35015
611.898	1.88966
615.364	3.45497
618.827	4.2639
622.288	6.30683
625.75	7.38735
629.209	7.64122
632.667	9.54798
636.125	13.0144
639.58	13.3994
643.033	15.0952
646.485	16.6417
649.936	17.5444
653.388	18.1079
656.836	18.7128
660.283	20.4738
663.728	22.0214
667.173	20.5194
670.616	20.8332
674.057	20.1071
677.498	20.4751
680.937	20.8285
684.375	21.506
687.809	22.715
691.244	22.5475
694.678	22.0205
698.111	25.1775
701.54	25.8504
704.97	26.4696
708.398	26.1336
711.826	26.8423
715.25	28.2925
718.675	29.7342
722.096	30.5179
725.518	31.1227
728.937	32.3711
732.357	33.3545
735.773	33.9073
739.19	36.1963
742.604	38.3954
746.018	40.9367
749.429	42.3147
752.839	45.1577
756.248	47.3194
759.657	49.7702
763.063	53.0678
766.468	55.5879
769.871	58.1599
773.273	60.8921
776.676	63.0233
780.075	64.6872
783.474	68.229
786.871	69.2841
790.266	69.8311
793.661	71.3742
797.054	72.6416
800.446	72.5235
803.834	72.6949
807.224	73.7612
810.612	73.2446
813.998	72.2385
817.384	70.2793
820.766	70.9222
824.149	70.8689
827.531	71.6423
830.909	74.5038
834.288	77.294
837.666	81.2627
841.041	84.633
844.416	87.9871
847.788	88.6057
851.161	88.6967
854.53	89.141
857.901	89.948
861.268	90.2559
864.633	89.544
868	89.2221
871.363	86.5621
874.725	84.0481
878.088	79.9082
881.447	76.1546
884.805	71.4932
888.162	67.5133
891.518	62.1278
894.872	57.0577
898.225	51.977
901.577	48.3881
904.928	45.7778
908.277	46.798
911.625	45.7193
914.972	46.4404
918.318	45.7108
921.662	46.2596
925.005	45.8452
928.347	45.6747
931.686	44.9037
935.025	45.2123
938.363	45.5282
941.698	46.2513
945.034	44.6703
948.368	43.3921
951.699	42.1029
955.031	39.17
958.36	36.6972
961.689	34.3415
965.016	32.9804
968.343	32.3527
971.666	31.7892
974.991	33.1956
978.312	32.4871
981.632	31.0487
984.953	31.3274
988.27	32.7261
991.587	32.2509
994.902	30.4923
998.216	30.544
1001.53	29.5737
1004.84	30.5785
1008.15	32.0026
1011.46	34.4146
1014.77	35.9506
1018.07	37.2023
1021.38	38.1626
1024.68	39.3555
1027.99	38.7351
1031.29	38.103
1034.59	37.9992
1037.89	36.2612
1041.18	34.0636
1044.48	33.8158
1047.77	34.7868
1051.07	35.2372
1054.36	34.3774
1057.65	33.4074
1060.94	32.0812
1064.23	31.3295
1067.52	30.7849
1070.8	29.5871
1074.09	27.8838
1077.37	26.7804
1080.65	25.9936
1083.93	26.5222
1087.21	27.2262
1090.49	28.1691
1093.77	28.7003
1097.04	30.3009
1100.32	30.4049
1103.59	30.0454
1106.86	29.4671
1110.13	29.0609
1113.4	26.9951
1116.67	25.6688
1119.94	23.8101
1123.2	22.4852
1126.47	22.4467
1129.73	22.1173
1132.99	20.0026
1136.25	19.576
1139.51	18.4509
1142.77	15.7848
1146.03	14.4189
1149.28	13.0518
1152.54	11.29
1155.79	10.4478
1159.04	9.13981
1162.29	6.77888
1165.54	5.02151
1168.79	3.89023
1172.04	3.36765
1175.28	3.54102
1178.53	2.88425
1181.77	1.58937
1185.01	1.35075
1188.25	2.87247
1191.49	2.56733
1194.73	3.0034
1197.96	6.90737
1201.2	9.21053
1204.43	12.22
1207.66	16.4489
1210.9	19.4126
1214.13	24.4057
1217.36	29.2358
1220.58	33.8516
1223.81	39.9852
1227.04	44.8659
1230.26	48.9016
1233.48	52.5048
1236.71	57.0953
1239.93	59.037
1243.14	61.6255
1246.36	65.0612
1249.58	67.9899
1252.8	70.7059
1256.01	70.276
1259.22	70.4989
1262.43	70.3751
1265.64	69.5777
1268.85	69.9489
1272.06	70.4035
1275.27	71.3714
1278.48	73.0821
1281.68	73.6047
1284.88	75.2724
1288.08	76.6342
1291.28	79.3135
1294.48	81.2233
1297.68	83.1915
1300.88	84.992
1304.07	86.8219
1307.27	88.279
1310.46	91.2041
1313.65	92.8316
1316.85	93.4233
1320.03	95.2178
1323.22	95.7514
1326.41	97.114
1329.6	95.2697
1332.78	93.1571
1335.96	90.7579
1339.15	89.5787
1342.33	86.4724
1345.51	84.7539
1348.69	83.3244
1351.86	80.9059
1355.04	80.6214
1358.21	79.4061
1361.39	77.3024
1364.56	75.1695
1367.73	71.837
1370.9	70.6748
1374.07	70.3388
1377.24	69.2536
1380.41	66.9105
1383.57	65.3503
1386.73	63.1888
1389.9	62.1876
1393.06	61.8186
1396.22	62.3473
1399.38	63.4679
1402.54	63.8189
1405.69	65.3739
1408.85	66.7029
1412	69.1516
1415.16	73.8288
1418.31	79.0214
1421.46	85.6574
1424.61	94.6395
1427.76	103.64
1430.9	110.41
1434.05	117.779
1437.2	123.565
1440.34	127.911
1443.48	130.767
1446.62	132.147
1449.76	133.972
1452.9	131.74
1456.04	128.255
1459.17	124.814
1462.31	120.43
1465.44	115.18
1468.58	108.999
1471.71	103.041
1474.84	96.7142
1477.97	87.5021
1481.1	79.1484
1484.22	71.4189
1487.35	64.4823
1490.47	59.3666
1493.59	54.2403
1496.72	49.2821
1499.84	45.4406
1502.96	40.7351
1506.08	36.2322
1509.19	32.5349
1512.31	29.4718
1515.42	26.7406
1518.54	23.6632
1521.65	21.47
1524.76	21.099
1527.87	21.2489
1530.98	21.452
1534.09	21.8732
1537.2	20.9057
1540.3	22.5534
1543.41	25.8521
1546.51	27.7199
1549.61	29.446
1552.71	32.1681
1555.81	33.7206
1558.91	36.3474
1562.01	38.96
1565.1	40.1709
1568.2	42.223
1571.29	44.1515
1574.38	47.1015
1577.48	49.6323
1580.57	53.1407
1583.65	56.6442
1586.74	58.6913
1589.83	62.1928
1592.92	64.521
1596	64.5002
1599.08	66.157
1602.16	67.238
1605.24	66.7479
1608.32	65.3399
1611.4	64.1466
1614.48	64.4856
1617.56	66.2608
1620.63	65.5184
1623.71	65.9447
1626.78	66.4818
1629.85	67.0422
1632.92	67.2848
1635.99	68.7095
1639.06	70.2493
1642.12	73.7286
1645.19	76.0092
1648.25	79.6251
1651.32	82.794
1654.38	86.1438
1657.44	86.8133
1660.5	87.1271
1663.56	87.4087
1666.62	85.6145
1669.67	82.9575
1672.73	74.4588
1675.79	68.9466
1678.84	67.7935
1681.89	64.2531
1684.94	61.9995
1687.99	59.8378
1691.04	56.8429
1694.08	53.3206
1697.13	50.8095
1700.18	47.8374
1703.22	44.6744
1706.26	41.8528
1709.3	39.4629
1712.35	37.6901
1715.39	34.9941
1718.42	31.8288
1721.46	29.0603
1724.5	25.7991
1727.53	22.812
1730.56	20.0849
1733.6	16.2819
1736.63	13.5442
1739.66	10.0781
1742.69	5.76201
1745.71	1.35246
1748.74	0.96072
1751.77	4.63105
1754.79	4.76062
1757.81	5.04204
1760.84	5.32659
1763.86	5.71002
1766.88	5.51133
1769.9	5.48911
1772.91	4.33598
1775.93	4.55529
1778.95	5.11773
1781.96	4.61085
1784.97	3.82442
1787.99	3.53786
1791	2.93279
1794.01	2.44227
1797.01	1.62752
1800.02	1.60516
1803.03	1.83375
1806.03	2.38426
1809.04	2.61967
1812.04	2.64102
1815.04	2.43395
1818.04	3.02658
1821.04	3.00704
1824.04	2.72857
1827.04	3.06208
1830.03	3.29213
1833.03	3.9947
1836.02	3.82662
1839.02	3.09602
1842.01	3.71696
1845	3.83983
1847.99	3.38004
1850.98	3.98637
1853.96	3.65199
1856.95	3.97112
1859.94	4.28948
1862.92	5.02467
1865.9	4.30493
1868.88	3.28182
1871.86	3.81623
1874.84	4.18467
1877.82	2.58319
1880.8	2.82404
1882.58	2.33478
1885.57	2.5558
1888.56	2.42608
1891.54	1.90948
1894.53	2.26922
1897.51	3.19419
1900.5	3.38353
1903.48	3.7095
1906.46	3.45413
1909.44	3.23065
1912.42	2.54517
1915.4	2.82248
1918.37	1.45869
1921.35	0.405133
1924.32	0.194315
1927.3	0.530601
1930.27	0.455678
1933.24	0.220864
1936.21	-0.555947
1939.18	-0.81439
1942.15	-0.46777
1945.11	0.350596
1948.08	0.28695
1951.04	-0.59876
1954.01	0.485375
1956.97	0.988842
1959.93	2.29219
1962.89	3.14013
1965.85	4.4732
1968.81	5.79814
1971.77	6.2439
1974.72	5.58569
1977.68	6.03968
1980.63	6.27572
1983.58	6.06977
1986.53	5.65577
1989.48	6.17985
1992.43	5.25703
1995.38	4.75253
1998.33	4.74003
2001.27	5.62874
2004.22	5.84677
2007.16	5.62951
2010.11	5.60699
2013.05	4.27946
2015.99	3.28033
2018.93	2.48784
2021.87	2.98327
2024.8	3.00508
2027.74	4.01896
2030.68	3.57896
2033.61	3.45233
2036.54	3.26816
2039.48	2.71612
2042.41	1.88777
2045.34	3.02762
2048.27	2.05973
2051.19	2.41385
2054.12	2.56264
2057.05	3.06036
2059.97	3.94643
2062.9	4.25323
2065.82	3.93466
2068.74	4.87034
2071.66	6.04352
2074.58	6.2939
2077.5	7.1703
2080.41	5.4419
2083.33	5.00509
2086.24	5.22962
2089.16	6.44412
2092.07	7.26273
2094.98	8.90574
2097.89	9.77644
2100.8	9.18372
2103.71	10.3832
2106.62	9.43454
2109.53	10.2516
2112.43	11.5396
2115.33	12.631
2118.24	12.7345
2121.14	13.3742
2124.04	15.7989
2126.94	17.3798
2129.84	19.5025
2132.74	21.4039
2135.63	23.2043
2138.53	26.0652
2141.43	28.9032
2144.32	30.8757
2147.21	32.9894
2150.1	36.0929
2152.99	38.1841
2155.88	41.807
2158.77	45.1772
2161.66	46.8244
2164.55	49.2153
2167.43	51.8203
2170.31	52.6546
2173.2	53.4652
2176.08	52.6284
2178.96	53.8636
2181.84	53.7929
2184.72	52.1878
2187.6	49.0674
2190.47	46.978
2193.35	45.2202
2196.23	43.4689
2199.1	40.9158
2201.97	38.4022
2204.84	35.7807
2207.71	33.7605
2210.58	31.6486
2213.45	29.1467
2216.32	28.2058
2219.19	27.1712
2222.05	26.0505
2224.92	24.5265
2227.78	23.7308
2230.64	22.032
2233.5	21.4419
2236.36	23.0119
2239.22	21.8145
2242.08	20.3525
2244.94	19.0028
2247.79	18.4284
2250.65	17.4122
2253.5	15.6277
2256.36	14.0211
2259.21	12.4602
2262.06	12.0658
2264.91	11.8299
2267.76	10.4775
2270.6	8.23208
2273.45	6.77535
2276.3	5.93056
2279.14	5.31694
2281.98	5.42518
2284.83	5.72669
2287.67	4.75802
2290.51	3.86831
2293.35	3.0636
2296.19	3.33115
2299.02	4.68212
2301.86	5.74465
2304.7	6.54401
2307.53	6.56284
2310.36	6.00027
2313.2	6.6384
2316.03	8.58342
2318.86	9.04282
2321.69	9.06143
2324.51	9.5883
2327.34	9.22569
2330.17	8.79089
2332.99	8.79886
2335.82	7.90233
2338.64	6.71814
2341.46	5.93247
2344.28	5.54877
2347.1	6.27574
2349.92	5.62566
2352.74	5.05618
2355.56	5.70879
2358.37	4.47257
2361.19	5.12391
2364	6.72004
2366.82	8.81851
2369.63	7.83465
2372.44	7.59298
2375.25	8.0256
2378.06	9.76872
2380.86	10.7031
2383.67	11.757
2386.48	11.1549
2389.28	11.8113
2392.09	12.5409
2394.89	11.6019
2397.69	10.5019
2400.49	10.4303
2403.29	10.662
2406.09	10.6528
2408.89	10.137
2411.69	10.9112
2414.48	10.6753
2417.28	11.6858
2420.07	11.4976
2422.86	11.6413
2425.65	11.552
2428.45	11.3211
2431.23	11.7222
2434.02	10.8759
2436.81	10.4832
2439.6	10.6636
2442.38	11.4283
2445.17	11.0803
2447.95	11.9072
2450.73	11.5069
2453.52	12.2526
2456.3	12.7694
2459.08	13.3411
2461.85	13.1513
2464.63	13.7692
2467.41	12.8525
2470.19	12.6683
2472.96	12.2964
2475.73	12.9761
2478.51	11.4996
2481.28	11.7197
2484.05	11.4904
2486.82	11.5153
2489.59	10.9846
2492.35	10.0367
2495.12	8.99532
2497.89	9.10273
2500.65	9.87451
2503.42	8.8024
2506.18	8.69555
2508.94	8.37569
2511.7	8.49306
2514.46	8.47204
2517.22	8.36352
2519.98	7.88888
2522.73	8.45278
2525.49	7.75398
2528.25	8.00239
2531	7.79493
2533.75	5.94656
2536.5	4.77726
2539.25	5.05983
2542.01	4.86919
2544.75	4.21956
2547.5	3.87751
2550.25	4.39569
2553	5.05342
2555.74	5.75963
2558.49	6.41671
2561.23	6.99369
2563.97	6.23567
2566.71	5.86825
2569.45	5.57589
2572.19	6.18387
2574.93	5.41311
2577.67	6.42168
2580.4	6.1579
2583.14	4.87921
2585.87	4.45919
2588.6	4.61637
2591.34	3.66295
2594.07	3.15847
2596.8	3.5792
2599.53	2.21334
2602.26	2.61895
2604.98	2.62303
2607.71	2.43468
2610.44	2.29004
2613.16	2.74288
2615.88	2.66493
2618.61	3.43371
2621.33	4.64894
2624.05	4.81863
2626.77	3.48898
2629.49	2.68185
2632.21	2.88945
2634.92	3.15471
2637.64	4.64452
2640.35	4.87686
2643.07	4.04841
2645.78	3.35067
2648.49	1.49568
2651.2	1.7754
2653.91	1.51861
2656.62	0.992317
2659.33	0.799324
2662.04	1.31107
2664.74	0.708862
2667.45	0.303041
2670.15	0.720322
2672.86	0.13984
2675.56	-0.514562
2678.26	-0.327658
2680.96	-1.31606
2683.66	-0.105512
2686.36	0.0625448
2689.06	0.371298
2691.75	1.0949
2694.45	0.920657
2697.14	2.21639
2699.84	3.80702
2702.53	4.43429
2705.22	5.95081
2707.91	6.35395
2710.6	6.86648
2713.29	7.37163
2715.98	8.7941
2718.67	9.61324
2721.35	10.9481
2724.04	11.0039
2726.72	11.912
2729.4	11.3889
2732.09	11.1754
2734.77	10.8872
2737.45	10.0715
2740.13	9.14855
2742.81	8.67545
2745.48	7.8646
2748.16	6.51684
2750.84	5.0199
2753.51	4.30174
2756.19	4.73438
2758.86	4.20544
2761.53	2.82859
2764.2	1.96055
2766.87	2.00594
2769.54	3.04457
2772.21	1.50398
2774.88	2.22654
2777.54	2.18614
2780.21	1.6478
2782.87	2.77524
2785.53	3.99919
2788.2	3.84221
2790.86	4.01402
2793.52	3.77937
2796.18	4.05972
2798.84	3.81528
2801.49	3.90663
2804.15	3.96058
2806.81	3.98796
2809.46	3.36868
2812.12	3.19478
2814.77	3.60081
2817.42	5.92222
2820.07	7.9398
2822.72	9.09216
2825.37	11.3685
2828.02	16.3935
2830.67	21.1633
2833.31	25.2834
2835.96	30.8443
2838.61	38.4533
2841.25	47.0282
2843.89	55.5816
2846.53	65.0181
2849.17	75.1228
2851.81	85.1433
2854.45	96.0365
2857.09	106.69
2859.73	117.282
2862.36	128.053
2865	137.874
2867.64	148.18
2870.27	156.514
2872.9	165.545
2875.53	172.074
2878.16	178.106
2880.79	185.19
2883.42	191.318
2886.05	196.691
2888.68	202.609
2891.3	208.793
2893.93	215.929
2896.55	222.686
2899.18	231.497
2901.8	241.022
2904.42	250.34
2907.04	260.391
2909.66	272.799
2912.28	285.11
2914.9	296.794
2917.51	308.623
2920.13	320.338
2922.74	329.577
2925.36	337.233
2927.97	342.016
2930.59	343.819
2933.2	344.532
2935.81	341.599
2938.42	335.855
2941.02	329.144
2943.63	320.273
2946.24	308.084
2948.85	294.953
2951.45	281.976
2954.05	268.63
2956.66	255.048
2959.26	242.183
2961.86	229.664
2964.46	217.024
2967.06	207.096
2969.66	196.705
2972.26	188.497
2974.85	179.678
2977.45	171.533
2980.05	163.682
2982.64	156.86
2985.23	149.1
2987.83	140.457
2990.42	130.819
2993.01	121.128
2995.6	112.122
2998.19	103.348
3000.77	93.7605
3003.36	84.2258
3005.95	75.6327
3008.53	65.6935
3011.12	56.586
3013.7	49.6375
3016.28	42.1661
3018.86	35.6236
3021.44	30.7769
3024.02	26.2591
3026.6	22.8664
3029.18	19.9864
3031.76	17.7542
3034.33	16.8351
3036.91	16.1343
3039.48	16.447
3042.05	16.7877
3044.63	17.6079
3047.2	17.9312
3049.77	19.1663
3052.34	19.2064
3054.91	19.8193
3057.48	20.535
3060.04	20.6523
3062.61	20.4875
3065.17	19.431
3067.74	18.2539
3070.3	17.8665
3072.87	16.1309
3075.43	14.5506
3077.99	12.0496
3080.55	9.99035
3083.11	7.47488
3085.67	5.61671
3088.22	4.27539
3090.78	2.88533
3093.34	1.50721
3095.89	-0.11971
3098.44	0.57402
3101	0.526893
3103.55	-0.435696
3106.1	-0.360383
3108.65	0.265791
3111.2	0.155669
3113.75	0.752528
3116.3	0.426142
3118.84	0.00208574
3121.39	0.345585
3123.93	0.378491
3126.48	-0.223382
3129.02	0.00178748
3131.56	0.651721
3134.1	-0.0288941
3136.64	-0.290669
3139.18	-0.720532
3141.72	-1.35074
3144.26	-0.816947
3146.8	0.047628
3149.33	1.75474