File: data/Raman/poly_smoothed/Mbcal_20_25_14_1x_45s_532 nm_x100_100%_600 gr_mm_01.txt
#Acq. time (s)=	45
#Accumulations=	2
#Range (cm-¹)=	200...3150
#Windows=	2
#Auto scanning=	Off
#Autofocus=	Off
#Macrospot=	Off
#AutoExposure=	Off
#Spike filter=	Multiple accum.
#Delay time (s)=	0
#Binning=	1
#Readout mode=	Signal
#DeNoise=	Off
#ICS correction=	On
#Dark correction=	Off
#Inst. Process=	Off
#Detector Gain=	Best Dynamic Range
#Detector ADC=	20 kHz
#Detector temperature (°C)=	-69.85
#Instrument=	LabRAM HR Evol
#Detector=	Synapse
#Objective=	x100
#Grating=	600 gr/mm
#ND Filter=	100%
#Laser (nm)=	532
#Hole=	100.021
#Range=	Auto
#Laser Pol.=	No
#Raman. Pol.=	No
#Laser Pol. (°)=	-0.0007625
#Raman Pol. (°)=	89.9995
#Collection=	Microscope
#StageXY=	Marzhauser
#StageZ=	Marzhauser
#X (µm)=	-1181.5
#Y (µm)=	1252
#Z (µm)=	578.2
#Full time(mm:ss)=	3:18
#Project=
#Sample=
#Site=
#Title=	Mbcal_20_25_14_2x_45s_532 nm_x100_100%_600 gr_mm
#Remark=
#Date=	18.07.2022 10:26
#Acquired=	18.07.2022 10:26:07
#Base:Fit=	10.08.2022 10:55:08
#Base:Sub=	10.08.2022 10:55:14
#Filter:Polynom=	16.08.2022 10:07:28
#AxisType[0]=Intens
#AxisUnit[0]=Cnt
#AxisType[1]=Spectr
#AxisUnit[1]=1/cm
200.419	35.5696
204.048	32.2246
207.678	28.9251
211.304	28.1205
214.928	25.249
218.554	23.411
222.176	19.1387
225.798	17.1581
229.417	16.7023
233.035	15.8942
236.653	17.0664
240.268	16.5542
243.881	17.4057
247.493	14.6286
251.103	13.6353
254.715	13.9622
258.322	14.1413
261.929	13.3051
265.534	13.0927
269.137	13.0016
272.739	11.7692
276.34	11.5797
279.939	10.6099
283.537	7.97387
287.134	6.93351
290.729	7.46096
294.323	8.20574
297.913	10.7496
301.504	9.90624
305.093	11.7603
308.682	14.1551
312.268	13.8324
315.852	18.2114
319.436	23.1677
323.018	26.5454
326.597	29.4588
330.177	31.2518
333.753	31.1261
337.331	32.7546
340.906	35.3505
344.478	35.2584
348.051	33.8091
351.621	32.0847
355.189	29.5428
358.757	26.9118
362.323	23.7711
365.889	21.131
369.451	18.3216
373.012	15.8171
376.574	15.5594
380.133	15.143
383.69	15.4736
387.245	15.0724
390.8	15.95
394.353	13.8125
397.906	12.1816
401.456	12.8719
405.005	15.3936
408.552	15.6645
412.099	14.2355
415.643	15.0495
419.187	14.8219
422.728	13.9041
426.269	13.7112
429.806	11.5878
433.344	10.3409
436.881	8.87639
440.416	8.07716
443.949	7.98417
447.48	8.43101
451.011	8.02568
454.541	8.37473
458.069	10.6625
461.594	11.1662
465.119	13.2535
468.642	15.0027
472.165	17.0239
475.684	17.5634
479.204	19.3687
482.721	18.47
486.239	19.278
489.753	19.674
493.268	22.3989
496.779	24.6813
500.289	27.2171
503.8	29.9091
507.307	32.7087
510.813	34.7164
514.32	37.1125
517.823	37.7807
521.325	37.1818
524.826	39.5552
528.325	41.7829
531.823	41.974
535.32	39.8864
538.815	37.5658
542.309	38.3356
545.802	36.2518
549.293	33.884
552.783	31.106
556.271	26.1147
559.759	23.1251
563.245	19.4236
566.729	16.2611
570.213	11.8764
573.693	8.93555
577.173	7.68827
580.652	7.37802
584.13	7.13662
587.605	7.11643
591.08	5.05496
594.552	5.33659
598.025	2.85229
601.496	3.74612
604.964	4.7915
608.433	6.15126
611.898	8.1347
615.364	5.98654
618.827	5.61244
622.288	3.97041
625.75	4.94609
629.209	4.36759
632.667	3.34771
636.125	6.18615
639.58	6.34861
643.033	6.31436
646.485	7.51284
649.936	7.12409
653.388	7.93801
656.836	9.95712
660.283	10.7126
663.728	10.6464
667.173	11.2007
670.616	11.5738
674.057	11.5561
677.498	12.1153
680.937	13.5001
684.375	14.9974
687.809	17.0056
691.244	18.7002
694.678	20.6761
698.111	21.0014
701.54	21.1674
704.97	24.2321
708.398	26.1085
711.826	29.6566
715.25	30.7226
718.675	33.4196
722.096	33.3481
725.518	33.1961
728.937	32.9205
732.357	31.6915
735.773	31.7633
739.19	32.497
742.604	32.6677
746.018	32.7481
749.429	33.6655
752.839	34.9925
756.248	36.3852
759.657	38.4492
763.063	41.9126
766.468	43.7694
769.871	46.6319
773.273	50.3925
776.676	52.5934
780.075	57.6912
783.474	60.9475
786.871	65.136
790.266	67.7041
793.661	67.5707
797.054	67.8652
800.446	66.3393
803.834	64.2736
807.224	61.8405
810.612	61.9563
813.998	59.9941
817.384	59.2275
820.766	57.5706
824.149	59.4491
827.531	61.8877
830.909	64.2563
834.288	69.033
837.666	71.5818
841.041	76.2026
844.416	81.8673
847.788	84.6888
851.161	86.1544
854.53	89.1703
857.901	89.7974
861.268	89.6846
864.633	90.5521
868	86.7783
871.363	82.7229
874.725	79.1248
878.088	74.5508
881.447	70.2281
884.805	62.691
888.162	56.69
891.518	52.5029
894.872	49.2154
898.225	45.4065
901.577	42.0515
904.928	40.6503
908.277	40.7967
911.625	40.8652
914.972	43.0964
918.318	45.9411
921.662	47.5544
925.005	50.2109
928.347	52.4762
931.686	51.2991
935.025	52.1239
938.363	50.415
941.698	49.6993
945.034	47.0763
948.368	46.794
951.699	46.1071
955.031	45.9591
958.36	45.1067
961.689	41.8781
965.016	39.0556
968.343	37.6164
971.666	36.5801
974.991	35.922
978.312	36.1461
981.632	33.824
984.953	33.7508
988.27	32.9983
991.587	33.6237
994.902	33.7397
998.216	34.7096
1001.53	33.1248
1004.84	32.7281
1008.15	34.734
1011.46	36.996
1014.77	39.4613
1018.07	42.9552
1021.38	46.2604
1024.68	48.9962
1027.99	51.8209
1031.29	54.7705
1034.59	55.5044
1037.89	54.5559
1041.18	52.4239
1044.48	50.3353
1047.77	51.6158
1051.07	48.9371
1054.36	47.0833
1057.65	47.3111
1060.94	45.0007
1064.23	44.0083
1067.52	44.4047
1070.8	43.1576
1074.09	40.9441
1077.37	39.3254
1080.65	37.5961
1083.93	37.9358
1087.21	37.9384
1090.49	42.0252
1093.77	43.3656
1097.04	45.6857
1100.32	47.9814
1103.59	47.6126
1106.86	47.783
1110.13	46.8695
1113.4	44.6597
1116.67	43.0886
1119.94	39.9685
1123.2	39.4213
1126.47	39.7366
1129.73	37.7436
1132.99	35.4974
1136.25	34.017
1139.51	32.3883
1142.77	29.6479
1146.03	29.7302
1149.28	25.8417
1152.54	23.1193
1155.79	19.2544
1159.04	15.6754
1162.29	12.0287
1165.54	8.33621
1168.79	7.00155
1172.04	5.95409
1175.28	5.16216
1178.53	3.82263
1181.77	3.75558
1185.01	4.18027
1188.25	4.86524
1191.49	5.53004
1194.73	7.31449
1197.96	10.0327
1201.2	14.222
1204.43	19.1049
1207.66	22.267
1210.9	26.5038
1214.13	31.3029
1217.36	36.655
1220.58	40.6794
1223.81	45.189
1227.04	49.1739
1230.26	53.0086
1233.48	56.6627
1236.71	60.7718
1239.93	64.9271
1243.14	67.7598
1246.36	71.4462
1249.58	75.2978
1252.8	78.0476
1256.01	80.8643
1259.22	80.6022
1262.43	83.216
1265.64	85.4801
1268.85	87.8369
1272.06	90.0953
1275.27	92.0416
1278.48	93.8925
1281.68	97.2594
1284.88	99.9005
1288.08	102.484
1291.28	105.354
1294.48	109.993
1297.68	113.2
1300.88	115.245
1304.07	117.115
1307.27	120.018
1310.46	121.354
1313.65	124.273
1316.85	123.904
1320.03	124.996
1323.22	126.636
1326.41	125.758
1329.6	125.481
1332.78	124.174
1335.96	120.255
1339.15	117.74
1342.33	115.847
1345.51	112.438
1348.69	109.733
1351.86	107.035
1355.04	104.575
1358.21	102.058
1361.39	99.1921
1364.56	95.22
1367.73	92.8605
1370.9	90.686
1374.07	88.8618
1377.24	85.4378
1380.41	83.3845
1383.57	80.349
1386.73	78.9054
1389.9	78.712
1393.06	78.9028
1396.22	77.958
1399.38	79.8542
1402.54	81.1103
1405.69	84.7395
1408.85	88.581
1412	91.6336
1415.16	96.1282
1418.31	102.651
1421.46	111.663
1424.61	120.998
1427.76	132.006
1430.9	141.76
1434.05	150.801
1437.2	159.128
1440.34	164.351
1443.48	171.075
1446.62	173.939
1449.76	176.026
1452.9	175.507
1456.04	173.754
1459.17	170.745
1462.31	166.033
1465.44	160.889
1468.58	155.117
1471.71	145.721
1474.84	136.808
1477.97	129.167
1481.1	120.182
1484.22	110.411
1487.35	99.7459
1490.47	91.5912
1493.59	84.7479
1496.72	78.724
1499.84	71.9524
1502.96	66.4635
1506.08	62.1643
1509.19	58.1625
1512.31	53.7335
1515.42	50.9364
1518.54	47.2329
1521.65	43.6187
1524.76	41.6063
1527.87	39.104
1530.98	38.074
1534.09	36.4433
1537.2	36.8109
1540.3	36.9479
1543.41	37.8762
1546.51	38.0401
1549.61	40.2379
1552.71	42.8762
1555.81	43.5168
1558.91	45.6932
1562.01	47.3988
1565.1	49.5161
1568.2	52.7274
1571.29	55.3127
1574.38	58.0345
1577.48	60.7968
1580.57	64.0269
1583.65	67.6008
1586.74	70.3972
1589.83	73.3435
1592.92	75.6024
1596	76.836
1599.08	76.9557
1602.16	77.7893
1605.24	79.6432
1608.32	81.2561
1611.4	82.0134
1614.48	82.8115
1617.56	84.0959
1620.63	85.506
1623.71	87.3736
1626.78	88.9439
1629.85	91.2028
1632.92	93.269
1635.99	96.8377
1639.06	99.3109
1642.12	102.007
1645.19	103.754
1648.25	105.228
1651.32	107.661
1654.38	109.513
1657.44	108.459
1660.5	108.098
1663.56	106.111
1666.62	102.539
1669.67	97.998
1672.73	91.8778
1675.79	86.3603
1678.84	79.0663
1681.89	72.0546
1684.94	63.8139
1687.99	55.5943
1691.04	46.9035
1694.08	39.8534
1697.13	32.6055
1700.18	26.2445
1703.22	21.0554
1706.26	16.954
1709.3	12.4724
1712.35	10.1836
1715.39	6.1681
1718.42	3.83289
1721.46	3.22634
1724.5	2.81687
1727.53	3.47263
1730.56	2.0097
1733.6	2.28939
1736.63	1.99788
1739.66	1.89561
1742.69	1.17629
1745.71	1.39055
1748.74	1.3341
1751.77	1.08842
1754.79	1.43152
1757.81	1.03728
1760.84	0.821016
1763.86	0.134721
1766.88	-0.475522
1769.9	0.658683
1772.91	0.806147
1775.93	0.270602
1778.95	0.665564
1781.96	0.181616
1784.97	1.33235
1787.99	0.390829
1791	1.13452
1794.01	1.41354
1797.01	2.01296
1800.02	1.17045
1803.03	1.04333
1806.03	1.03648
1809.04	1.72848
1812.04	1.48045
1815.04	1.95341
1818.04	1.67052
1821.04	1.65701
1824.04	1.01819
1827.04	1.36729
1830.03	0.604313
1833.03	1.06533
1836.02	1.34323
1839.02	1.75888
1842.01	1.84228
1845	2.21633
1847.99	1.84914
1850.98	1.84292
1853.96	1.65023
1856.95	2.2673
1859.94	3.03339
1862.92	2.93653
1865.9	2.38901
1868.88	2.91685
1871.86	3.73201
1874.84	3.47384
1877.82	3.67252
1880.8	3.93841
1882.58	3.70462
1885.57	3.14164
1888.56	2.82517
1891.54	1.85903
1894.53	2.04209
1897.51	1.5928
1900.5	1.20451
1903.48	2.38143
1906.46	2.51505
1909.44	1.86435
1912.42	1.72531
1915.4	2.36223
1918.37	2.71814
1921.35	2.53994
1924.32	3.30703
1927.3	3.57025
1930.27	4.06643
1933.24	4.81843
1936.21	2.45146
1939.18	2.74952
1942.15	3.63632
1945.11	3.87361
1948.08	3.98058
1951.04	3.69717
1954.01	3.37678
1956.97	3.68943
1959.93	4.14468
1962.89	4.48497
1965.85	5.76277
1968.81	5.45814
1971.77	5.92806
1974.72	7.15563
1977.68	7.1008
1980.63	7.79614
1983.58	8.97897
1986.53	9.98662
1989.48	11.1097
1992.43	10.9924
1995.38	11.57
1998.33	12.1395
2001.27	11.2853
2004.22	10.337
2007.16	9.39047
2010.11	9.75601
2013.05	9.72701
2015.99	10.6147
2018.93	10.5204
2021.87	10.8223
2024.8	11.1898
2027.74	13.5272
2030.68	14.5461
2033.61	16.0362
2036.54	15.9043
2039.48	17.2896
2042.41	17.6334
2045.34	17.1192
2048.27	17.873
2051.19	18.2531
2054.12	17.8211
2057.05	18.1425
2059.97	17.892
2062.9	18.8078
2065.82	18.0463
2068.74	18.1604
2071.66	17.408
2074.58	17.4213
2077.5	18.1116
2080.41	18.603
2083.33	20.1441
2086.24	20.4977
2089.16	22.1924
2092.07	24.4967
2094.98	26.4929
2097.89	29.2301
2100.8	30.1448
2103.71	30.3891
2106.62	32.5646
2109.53	33.8401
2112.43	36.0407
2115.33	37.6073
2118.24	39.6804
2121.14	41.3001
2124.04	44.0185
2126.94	45.9056
2129.84	48.5649
2132.74	51.0681
2135.63	52.6652
2138.53	54.953
2141.43	58.5928
2144.32	61.02
2147.21	65.0535
2150.1	68.4049
2152.99	71.6384
2155.88	75.8256
2158.77	79.8743
2161.66	83.3789
2164.55	85.8053
2167.43	88.4365
2170.31	90.1133
2173.2	91.0189
2176.08	91.5861
2178.96	91.8888
2181.84	90.3275
2184.72	88.5865
2187.6	86.5358
2190.47	84.594
2193.35	81.8505
2196.23	78.5388
2199.1	73.8052
2201.97	70.45
2204.84	66.3835
2207.71	62.4765
2210.58	59.182
2213.45	54.8984
2216.32	52.2779
2219.19	49.8595
2222.05	46.8953
2224.92	45.1486
2227.78	42.9091
2230.64	40.7872
2233.5	37.1945
2236.36	36.2347
2239.22	34.0017
2242.08	31.5965
2244.94	29.0937
2247.79	26.8932
2250.65	24.816
2253.5	23.4257
2256.36	23.4848
2259.21	23.5649
2262.06	22.7484
2264.91	21.8895
2267.76	21.1646
2270.6	21.1276
2273.45	20.456
2276.3	19.5135
2279.14	18.0837
2281.98	17.7691
2284.83	17.1919
2287.67	16.9341
2290.51	15.8618
2293.35	14.8638
2296.19	14.6276
2299.02	15.269
2301.86	15.1334
2304.7	15.0892
2307.53	14.2053
2310.36	15.0134
2313.2	15.7932
2316.03	16.4503
2318.86	16.1168
2321.69	16.9898
2324.51	17.3651
2327.34	17.8004
2330.17	17.6205
2332.99	16.6559
2335.82	17.0457
2338.64	16.082
2341.46	14.9784
2344.28	13.0792
2347.1	11.763
2349.92	10.3026
2352.74	9.32334
2355.56	8.86981
2358.37	6.84772
2361.19	5.87666
2364	5.58304
2366.82	5.40681
2369.63	3.43255
2372.44	2.88313
2375.25	2.64572
2378.06	2.95525
2380.86	3.15066
2383.67	3.40051
2386.48	3.80445
2389.28	4.18282
2392.09	5.2996
2394.89	6.15344
2397.69	7.99524
2400.49	8.81985
2403.29	8.99057
2406.09	10.0936
2408.89	8.51285
2411.69	9.1317
2414.48	8.70006
2417.28	9.40082
2420.07	9.4963
2422.86	10.6433
2425.65	10.1523
2428.45	9.88441
2431.23	8.15245
2434.02	7.78391
2436.81	6.96447
2439.6	5.85005
2442.38	5.36062
2445.17	4.55611
2447.95	3.73327
2450.73	4.70397
2453.52	5.21578
2456.3	5.85913
2459.08	5.41507
2461.85	4.48758
2464.63	4.56004
2467.41	5.2773
2470.19	5.261
2472.96	4.86575
2475.73	5.25897
2478.51	5.34666
2481.28	5.78064
2484.05	6.52087
2486.82	8.03658
2489.59	8.62455
2492.35	8.21333
2495.12	7.97866
2497.89	7.08076
2500.65	6.2688
2503.42	5.70611
2506.18	4.80892
2508.94	3.48872
2511.7	3.33874
2514.46	4.57288
2517.22	4.87622
2519.98	3.57239
2522.73	3.39144
2525.49	2.17147
2528.25	1.40019
2531	1.56908
2533.75	1.99732
2536.5	2.4629
2539.25	2.34985
2542.01	1.52932
2544.75	2.0951
2547.5	1.75606
2550.25	2.07014
2553	1.72498
2555.74	1.47612
2558.49	1.47193
2561.23	1.36074
2563.97	2.31144
2566.71	2.12987
2569.45	1.8148
2572.19	1.25702
2574.93	2.01983
2577.67	2.69519
2580.4	3.67615
2583.14	3.29575
2585.87	2.88265
2588.6	3.90668
2591.34	4.68575
2594.07	5.52101
2596.8	5.53302
2599.53	5.35234
2602.26	4.07484
2604.98	3.89033
2607.71	3.85114
2610.44	3.76759
2613.16	3.79022
2615.88	3.63008
2618.61	2.19308
2621.33	1.8468
2624.05	2.66219
2626.77	2.86215
2629.49	3.23483
2632.21	3.38746
2634.92	4.31294
2637.64	4.41455
2640.35	5.21588
2643.07	5.1681
2645.78	5.87863
2648.49	6.10225
2651.2	6.95087
2653.91	6.91452
2656.62	6.52187
2659.33	7.22467
2662.04	6.49968
2664.74	6.85445
2667.45	5.6429
2670.15	5.18563
2672.86	5.95522
2675.56	5.71832
2678.26	5.53079
2680.96	4.99793
2683.66	3.49642
2686.36	3.76941
2689.06	4.34369
2691.75	5.25593
2694.45	5.94132
2697.14	7.6208
2699.84	8.26047
2702.53	8.68617
2705.22	9.57471
2707.91	9.09987
2710.6	9.3143
2713.29	9.88496
2715.98	9.08422
2718.67	8.35912
2721.35	7.91231
2724.04	7.16138
2726.72	7.11329
2729.4	7.91169
2732.09	8.50661
2734.77	8.60206
2737.45	10.02
2740.13	9.92404
2742.81	10.2915
2745.48	9.81186
2748.16	8.86401
2750.84	9.76555
2753.51	9.31676
2756.19	9.23237
2758.86	9.01394
2761.53	9.09505
2764.2	8.22126
2766.87	7.95889
2769.54	7.11118
2772.21	5.54438
2774.88	3.52381
2777.54	2.92935
2780.21	1.95455
2782.87	-0.392703
2785.53	-0.965459
2788.2	-1.70445
2790.86	-1.62689
2793.52	-1.01424
2796.18	-1.54111
2798.84	-2.32518
2801.49	-2.90409
2804.15	-1.96726
2806.81	-2.45089
2809.46	-2.52192
2812.12	-2.02337
2814.77	-1.8807
2817.42	0.323303
2820.07	3.16015
2822.72	8.1659
2825.37	12.9916
2828.02	18.458
2830.67	25.0088
2833.31	31.8988
2835.96	39.045
2838.61	47.954
2841.25	57.4405
2843.89	68.7955
2846.53	80.9447
2849.17	93.5766
2851.81	106.557
2854.45	119.818
2857.09	133.516
2859.73	147.154
2862.36	160.328
2865	173.679
2867.64	186.126
2870.27	197.621
2872.9	207.377
2875.53	216.775
2878.16	226.387
2880.79	235.949
2883.42	245.394
2886.05	255.421
2888.68	264.688
2891.3	272.977
2893.93	283.519
2896.55	293.593
2899.18	303.499
2901.8	314.933
2904.42	328.183
2907.04	343.884
2909.66	361.322
2912.28	377.782
2914.9	394.849
2917.51	412.054
2920.13	428.069
2922.74	440.577
2925.36	451.439
2927.97	458.824
2930.59	462.119
2933.2	460.742
2935.81	456.215
2938.42	447.517
2941.02	436.379
2943.63	423.324
2946.24	407.554
2948.85	390.639
2951.45	371.546
2954.05	352.495
2956.66	333.27
2959.26	314.624
2961.86	295.65
2964.46	278.631
2967.06	263.805
2969.66	250.622
2972.26	239.125
2974.85	227.323
2977.45	215.43
2980.05	205.173
2982.64	195.043
2985.23	183.622
2987.83	172.142
2990.42	160.19
2993.01	146.374
2995.6	132.426
2998.19	119.213
3000.77	105.702
3003.36	93.1321
3005.95	81.8299
3008.53	70.3124
3011.12	60.8044
3013.7	49.4651
3016.28	41.3057
3018.86	34.5642
3021.44	27.9979
3024.02	22.9203
3026.6	18.58
3029.18	15.2842
3031.76	12.4466
3034.33	10.4455
3036.91	9.75305
3039.48	9.72514
3042.05	10.3907
3044.63	11.1644
3047.2	12.3697
3049.77	11.6585
3052.34	11.9236
3054.91	12.184
3057.48	12.4862
3060.04	12.1275
3062.61	11.183
3065.17	10.4121
3067.74	9.81918
3070.3	8.86814
3072.87	7.08501
3075.43	6.77347
3077.99	5.41885
3080.55	5.04045
3083.11	3.8076
3085.67	2.3084
3088.22	2.12138
3090.78	2.03981
3093.34	2.53544
3095.89	2.60108
3098.44	3.27304
3101	3.1075
3103.55	3.0366
3106.1	4.62285
3108.65	5.48313
3111.2	6.10589
3113.75	6.91189
3116.3	8.375
3118.84	8.95208
3121.39	9.29981
3123.93	9.56746
3126.48	9.40576
3129.02	10.1812
3131.56	11.9927
3134.1	12.3177
3136.64	13.9671
3139.18	15.1829
3141.72	15.117
3144.26	15.6779
3146.8	14.8078
3149.33	13.2315