File: data/Raman/poly_smoothed/Mbcal_20_25_31_1x_45s_532 nm_x100_100%_600 gr_mm_01.txt
#Acq. time (s)=	45
#Accumulations=	2
#Range (cm-¹)=	200...3150
#Windows=	2
#Auto scanning=	Off
#Autofocus=	Off
#Macrospot=	Off
#AutoExposure=	Off
#Spike filter=	Multiple accum.
#Delay time (s)=	0
#Binning=	1
#Readout mode=	Signal
#DeNoise=	Off
#ICS correction=	On
#Dark correction=	Off
#Inst. Process=	Off
#Detector Gain=	Best Dynamic Range
#Detector ADC=	20 kHz
#Detector temperature (°C)=	-69.85
#Instrument=	LabRAM HR Evol
#Detector=	Synapse
#Objective=	x100
#Grating=	600 gr/mm
#ND Filter=	100%
#Laser (nm)=	532
#Hole=	100.021
#Range=	Auto
#Laser Pol.=	No
#Raman. Pol.=	No
#Laser Pol. (°)=	-0.0007625
#Raman Pol. (°)=	89.9995
#Collection=	Microscope
#StageXY=	Marzhauser
#StageZ=	Marzhauser
#X (µm)=	-1135.1
#Y (µm)=	1288.2
#Z (µm)=	578.45
#Full time(mm:ss)=	3:18
#Project=
#Sample=
#Site=
#Title=	Mbcal_20_25_31_2x_45s_532 nm_x100_100%_600 gr_mm
#Remark=
#Date=	18.07.2022 12:03
#Acquired=	18.07.2022 12:03:15
#Base:Fit=	10.08.2022 10:55:08
#Base:Sub=	10.08.2022 10:55:14
#Filter:Polynom=	16.08.2022 10:07:28
#AxisType[0]=Intens
#AxisUnit[0]=Cnt
#AxisType[1]=Spectr
#AxisUnit[1]=1/cm
200.419	5.66549
204.048	9.59025
207.678	12.4499
211.304	14.1731
214.928	13.532
218.554	12.526
222.176	12.0136
225.798	10.5884
229.417	10.0026
233.035	8.25186
236.653	7.21627
240.268	6.96008
243.881	6.91521
247.493	7.19219
251.103	7.0747
254.715	6.0342
258.322	5.75155
261.929	5.3847
265.534	5.98125
269.137	5.65318
272.739	7.81651
276.34	9.1854
279.939	11.2698
283.537	11.2495
287.134	10.3231
290.729	11.5852
294.323	12.9952
297.913	12.5646
301.504	12.4255
305.093	12.6787
308.682	11.8308
312.268	10.2653
315.852	10.231
319.436	8.90777
323.018	8.19723
326.597	8.30616
330.177	8.32035
333.753	9.53123
337.331	8.65602
340.906	6.96823
344.478	6.68841
348.051	5.79143
351.621	5.07602
355.189	3.5694
358.757	3.08147
362.323	2.35971
365.889	3.85718
369.451	5.93958
373.012	5.27662
376.574	5.50357
380.133	6.74017
383.69	6.46424
387.245	6.92863
390.8	9.40022
394.353	8.39007
397.906	9.15202
401.456	9.76834
405.005	10.7984
408.552	12.2119
412.099	12.8129
415.643	13.9013
419.187	14.6039
422.728	14.0851
426.269	13.5355
429.806	14.2852
433.344	14.0617
436.881	13.1284
440.416	11.5289
443.949	10.5583
447.48	10.8382
451.011	9.96016
454.541	9.57745
458.069	6.93045
461.594	5.11553
465.119	5.75268
468.642	5.75856
472.165	6.34018
475.684	8.68551
479.204	10.0835
482.721	11.8322
486.239	12.0437
489.753	14.7628
493.268	15.2024
496.779	16.5322
500.289	16.8998
503.8	18.3886
507.307	19.8335
510.813	22.135
514.32	22.9734
517.823	22.7351
521.325	24.475
524.826	25.8271
528.325	25.1589
531.823	25.6547
535.32	24.5367
538.815	25.1748
542.309	25.5966
545.802	25.509
549.293	25.1725
552.783	25.0174
556.271	24.726
559.759	24.4353
563.245	23.7043
566.729	22.5822
570.213	19.9297
573.693	18.5032
577.173	17.4416
580.652	14.4969
584.13	13.3358
587.605	11.015
591.08	8.81528
594.552	7.6696
598.025	6.21739
601.496	4.679
604.964	5.0349
608.433	2.94079
611.898	3.33932
615.364	2.24987
618.827	3.16403
622.288	3.61236
625.75	4.69813
629.209	5.0766
632.667	5.81622
636.125	7.94387
639.58	11.477
643.033	12.8219
646.485	14.097
649.936	17.0371
653.388	17.877
656.836	19.3828
660.283	21.7285
663.728	23.9796
667.173	24.4255
670.616	24.1047
674.057	25.5886
677.498	27.2308
680.937	28.6509
684.375	29.5652
687.809	29.45
691.244	30.1655
694.678	31.113
698.111	33.0825
701.54	35.0106
704.97	36.3481
708.398	38.2973
711.826	40.7565
715.25	42.9951
718.675	45.3309
722.096	48.2912
725.518	49.1031
728.937	48.2996
732.357	50.3942
735.773	52.132
739.19	52.8919
742.604	54.3398
746.018	56.8364
749.429	57.4509
752.839	58.5137
756.248	63.1991
759.657	66.3335
763.063	68.326
766.468	69.626
769.871	71.0203
773.273	72.9918
776.676	73.2049
780.075	75.7476
783.474	75.9998
786.871	77.5558
790.266	79.6023
793.661	81.8019
797.054	82.3842
800.446	83.2328
803.834	83.8141
807.224	84.7701
810.612	83.5026
813.998	83.3528
817.384	84.3975
820.766	83.3695
824.149	81.8279
827.531	83.2219
830.909	83.5849
834.288	83.683
837.666	84.5851
841.041	85.3044
844.416	84.4267
847.788	84.8697
851.161	84.4371
854.53	82.5831
857.901	80.0578
861.268	76.6763
864.633	74.7533
868	73.9206
871.363	72.9896
874.725	71.8332
878.088	68.9598
881.447	66.4823
884.805	65.2441
888.162	62.3421
891.518	58.1931
894.872	56.3871
898.225	54.0156
901.577	52.1044
904.928	51.731
908.277	50.9359
911.625	51.1597
914.972	52.5912
918.318	53.8325
921.662	53.0921
925.005	53.8379
928.347	55.5689
931.686	54.4856
935.025	52.3367
938.363	49.6731
941.698	48.9788
945.034	47.0647
948.368	45.8798
951.699	45.3426
955.031	43.6924
958.36	41.5423
961.689	39.9126
965.016	37.0923
968.343	33.8926
971.666	32.6614
974.991	32.1551
978.312	31.8796
981.632	30.0986
984.953	29.0677
988.27	27.7941
991.587	27.3781
994.902	27.1348
998.216	26.0005
1001.53	23.7938
1004.84	22.8887
1008.15	24.126
1011.46	24.5267
1014.77	23.2669
1018.07	24.3637
1021.38	26.0873
1024.68	26.0703
1027.99	27.8938
1031.29	29.5403
1034.59	30.2356
1037.89	31.8484
1041.18	32.2956
1044.48	32.9795
1047.77	33.0551
1051.07	32.699
1054.36	35.322
1057.65	34.7946
1060.94	34.2107
1064.23	32.5735
1067.52	31.3271
1070.8	30.0072
1074.09	28.6673
1077.37	26.7494
1080.65	25.2522
1083.93	24.5537
1087.21	24.8163
1090.49	24.7601
1093.77	23.7327
1097.04	23.2554
1100.32	22.6847
1103.59	22.1121
1106.86	22.1411
1110.13	22.84
1113.4	23.9557
1116.67	23.4933
1119.94	22.8713
1123.2	21.9347
1126.47	20.049
1129.73	19.3667
1132.99	17.6571
1136.25	17.3423
1139.51	15.8488
1142.77	15.2544
1146.03	13.5882
1149.28	12.5243
1152.54	10.6918
1155.79	8.75792
1159.04	8.04181
1162.29	8.23867
1165.54	8.38369
1168.79	7.90941
1172.04	7.52162
1175.28	5.85305
1178.53	6.83048
1181.77	6.95832
1185.01	7.38555
1188.25	7.82631
1191.49	8.4031
1194.73	9.84027
1197.96	10.2147
1201.2	11.7853
1204.43	13.0002
1207.66	13.2621
1210.9	14.2336
1214.13	15.6217
1217.36	17.9702
1220.58	19.9969
1223.81	21.3093
1227.04	23.4438
1230.26	25.3335
1233.48	27.1145
1236.71	30.3746
1239.93	33.5218
1243.14	34.1416
1246.36	35.8319
1249.58	35.8013
1252.8	34.679
1256.01	35.501
1259.22	35.3048
1262.43	37.6311
1265.64	37.7692
1268.85	40.3736
1272.06	42.9692
1275.27	44.6187
1278.48	46.3072
1281.68	48.6325
1284.88	50.2362
1288.08	50.9519
1291.28	53.9688
1294.48	55.5539
1297.68	56.9458
1300.88	58.5114
1304.07	60.9921
1307.27	63.6431
1310.46	64.4712
1313.65	65.9192
1316.85	67.466
1320.03	67.7289
1323.22	67.8269
1326.41	67.7943
1329.6	65.9905
1332.78	64.0925
1335.96	63.7891
1339.15	63.7725
1342.33	62.7094
1345.51	60.7521
1348.69	61.5821
1351.86	60.1555
1355.04	59.6605
1358.21	59.4171
1361.39	59.4021
1364.56	57.9673
1367.73	55.4241
1370.9	54.5121
1374.07	53.027
1377.24	50.9404
1380.41	48.4806
1383.57	47.4022
1386.73	46.8539
1389.9	45.4501
1393.06	45.1913
1396.22	44.9936
1399.38	44.5319
1402.54	44.1991
1405.69	43.4312
1408.85	44.4096
1412	46.9452
1415.16	48.6286
1418.31	50.9006
1421.46	55.0751
1424.61	59.4079
1427.76	64.4384
1430.9	69.0411
1434.05	73.1904
1437.2	75.1233
1440.34	77.4258
1443.48	80.0827
1446.62	81.0262
1449.76	79.965
1452.9	79.7694
1456.04	79.2753
1459.17	77.8738
1462.31	77.0359
1465.44	74.8843
1468.58	72.0521
1471.71	70.4263
1474.84	67.3344
1477.97	62.0781
1481.1	57.6451
1484.22	54.1879
1487.35	52.0263
1490.47	47.6774
1493.59	44.3663
1496.72	41.6535
1499.84	40.2659
1502.96	38.6445
1506.08	36.78
1509.19	34.3842
1512.31	30.5202
1515.42	27.2224
1518.54	25.2598
1521.65	23.1728
1524.76	20.0755
1527.87	19.5937
1530.98	18.9114
1534.09	17.6922
1537.2	16.8352
1540.3	16.4709
1543.41	17.53
1546.51	18.6903
1549.61	19.5774
1552.71	20.8341
1555.81	22.0784
1558.91	23.8293
1562.01	25.7607
1565.1	28.4556
1568.2	29.9375
1571.29	31.393
1574.38	34.843
1577.48	37.0481
1580.57	39.3655
1583.65	40.0918
1586.74	40.9473
1589.83	40.9719
1592.92	41.4422
1596	43.5123
1599.08	43.6003
1602.16	43.6211
1605.24	43.4313
1608.32	43.667
1611.4	43.6688
1614.48	43.7202
1617.56	44.743
1620.63	45.7496
1623.71	46.2039
1626.78	47.399
1629.85	48.2878
1632.92	49.8006
1635.99	50.4777
1639.06	51.7289
1642.12	53.3995
1645.19	53.6598
1648.25	55.4522
1651.32	57.7808
1654.38	58.347
1657.44	59.1095
1660.5	59.4897
1663.56	59.7689
1666.62	58.6972
1669.67	56.8354
1672.73	54.7615
1675.79	51.7922
1678.84	48.0701
1681.89	43.0481
1684.94	39.107
1687.99	32.6204
1691.04	26.863
1694.08	22.8677
1697.13	19.7585
1700.18	14.9767
1703.22	10.6474
1706.26	9.91516
1709.3	7.3819
1712.35	4.7247
1715.39	2.84025
1718.42	2.63455
1721.46	1.36493
1724.5	1.40807
1727.53	2.35108
1730.56	1.69438
1733.6	2.50021
1736.63	4.46036
1739.66	4.74346
1742.69	5.42518
1745.71	4.83191
1748.74	6.0407
1751.77	7.18437
1754.79	6.04838
1757.81	6.48451
1760.84	5.51121
1763.86	5.75311
1766.88	6.55412
1769.9	6.69821
1772.91	6.48043
1775.93	5.6378
1778.95	6.57517
1781.96	7.34228
1784.97	6.03035
1787.99	5.55105
1791	5.74836
1794.01	6.05927
1797.01	5.38134
1800.02	4.40078
1803.03	4.24846
1806.03	3.88231
1809.04	4.54413
1812.04	5.26236
1815.04	4.80033
1818.04	4.95172
1821.04	5.28156
1824.04	5.22165
1827.04	5.1344
1830.03	4.31612
1833.03	4.42614
1836.02	3.58976
1839.02	3.67078
1842.01	3.33794
1845	2.84204
1847.99	2.41442
1850.98	1.67384
1853.96	2.2513
1856.95	1.985
1859.94	1.92956
1862.92	3.36309
1865.9	3.56961
1868.88	3.14426
1871.86	2.82061
1874.84	4.00413
1877.82	3.86165
1880.8	4.66289
1882.58	5.3856
1885.57	5.83976
1888.56	6.11584
1891.54	7.02421
1894.53	7.08441
1897.51	7.21093
1900.5	7.40098
1903.48	6.94985
1906.46	6.22095
1909.44	5.64617
1912.42	5.79534
1915.4	4.28666
1918.37	4.28595
1921.35	4.70574
1924.32	5.17336
1927.3	5.09563
1930.27	4.47648
1933.24	4.09085
1936.21	4.10997
1939.18	3.40172
1942.15	2.71254
1945.11	3.11239
1948.08	2.37485
1951.04	1.0379
1954.01	1.48793
1956.97	1.98335
1959.93	2.96526
1962.89	2.57733
1965.85	2.63476
1968.81	2.14092
1971.77	1.48153
1974.72	1.09744
1977.68	0.298292
1980.63	0.558622
1983.58	0.991071
1986.53	1.58902
1989.48	1.86449
1992.43	3.03023
1995.38	3.27566
1998.33	2.79594
2001.27	1.99518
2004.22	2.09644
2007.16	2.63623
2010.11	3.58224
2013.05	2.58242
2015.99	2.36573
2018.93	2.33538
2021.87	2.28535
2024.8	3.19038
2027.74	3.39843
2030.68	3.44589
2033.61	3.99566
2036.54	4.14266
2039.48	4.35032
2042.41	5.01588
2045.34	5.43021
2048.27	5.40378
2051.19	5.26034
2054.12	5.33958
2057.05	6.34156
2059.97	5.9475
2062.9	5.78051
2065.82	5.58159
2068.74	5.1968
2071.66	4.71895
2074.58	4.88698
2077.5	4.992
2080.41	5.31895
2083.33	4.19953
2086.24	5.29152
2089.16	5.84372
2092.07	6.95683
2094.98	7.32949
2097.89	7.5123
2100.8	7.38844
2103.71	8.59572
2106.62	9.30428
2109.53	11.3221
2112.43	11.3784
2115.33	11.8221
2118.24	12.735
2121.14	13.2526
2124.04	15.2397
2126.94	16.3017
2129.84	17.3568
2132.74	19.2379
2135.63	21.1854
2138.53	22.7006
2141.43	23.5215
2144.32	25.2046
2147.21	27.7144
2150.1	30.3714
2152.99	31.4641
2155.88	34.3987
2158.77	36.2417
2161.66	36.8768
2164.55	38.9279
2167.43	39.6778
2170.31	39.9662
2173.2	40.548
2176.08	41.4028
2178.96	41.4251
2181.84	40.6239
2184.72	39.6661
2187.6	38.4607
2190.47	36.3291
2193.35	35.0851
2196.23	33.4249
2199.1	31.7463
2201.97	30.0777
2204.84	27.5291
2207.71	25.394
2210.58	23.2461
2213.45	22.5296
2216.32	20.5106
2219.19	19.2224
2222.05	18.0256
2224.92	17.1543
2227.78	16.2572
2230.64	15.1272
2233.5	14.9286
2236.36	14.1195
2239.22	12.5338
2242.08	11.8754
2244.94	11.3894
2247.79	10.9677
2250.65	9.71426
2253.5	9.15186
2256.36	7.53355
2259.21	6.18838
2262.06	5.86295
2264.91	5.67975
2267.76	4.52729
2270.6	4.179
2273.45	3.31565
2276.3	2.97925
2279.14	2.90039
2281.98	2.65133
2284.83	2.38487
2287.67	2.54344
2290.51	1.8787
2293.35	0.70516
2296.19	0.964619
2299.02	1.42815
2301.86	3.03187
2304.7	2.78908
2307.53	3.24402
2310.36	4.45024
2313.2	4.98513
2316.03	4.47896
2318.86	5.36138
2321.69	5.66049
2324.51	5.41952
2327.34	5.35351
2330.17	6.37904
2332.99	5.99269
2335.82	6.03217
2338.64	5.85188
2341.46	6.35423
2344.28	6.36889
2347.1	5.68122
2349.92	5.17717
2352.74	4.32198
2355.56	2.94436
2358.37	3.10306
2361.19	1.98998
2364	3.23553
2366.82	4.29169
2369.63	5.3734
2372.44	4.65862
2375.25	4.89585
2378.06	4.14082
2380.86	4.11047
2383.67	4.15716
2386.48	4.17146
2389.28	5.06276
2392.09	4.76929
2394.89	4.7432
2397.69	5.02195
2400.49	5.11262
2403.29	5.53877
2406.09	5.86008
2408.89	6.57101
2411.69	6.39793
2414.48	5.01303
2417.28	3.71874
2420.07	2.90853
2422.86	2.48915
2425.65	2.50376
2428.45	2.31065
2431.23	2.20793
2434.02	1.4998
2436.81	1.19298
2439.6	0.485338
2442.38	0.809457
2445.17	0.800945
2447.95	0.315324
2450.73	0.494217
2453.52	0.747671
2456.3	1.02103
2459.08	1.2654
2461.85	2.15829
2464.63	1.96921
2467.41	1.89285
2470.19	3.37004
2472.96	3.79739
2475.73	4.83443
2478.51	4.67978
2481.28	4.37601
2484.05	4.14762
2486.82	4.42865
2489.59	5.12771
2492.35	5.08435
2495.12	5.10377
2497.89	4.67816
2500.65	4.62642
2503.42	3.77785
2506.18	3.78892
2508.94	3.42786
2511.7	3.94114
2514.46	2.74386
2517.22	2.27088
2519.98	1.79832
2522.73	1.62353
2525.49	1.98433
2528.25	2.07418
2531	2.16722
2533.75	2.6842
2536.5	3.45317
2539.25	4.39799
2542.01	5.1498
2544.75	5.95361
2547.5	6.84344
2550.25	7.52578
2553	8.3291
2555.74	9.39654
2558.49	10.239
2561.23	10.1103
2563.97	9.60795
2566.71	10.3723
2569.45	11.0468
2572.19	11.8904
2574.93	12.1251
2577.67	12.352
2580.4	11.2577
2583.14	11.4759
2585.87	10.947
2588.6	10.418
2591.34	10.149
2594.07	9.28269
2596.8	8.14086
2599.53	7.91684
2602.26	7.4312
2604.98	6.66734
2607.71	5.7216
2610.44	5.10342
2613.16	5.18822
2615.88	5.31029
2618.61	4.74252
2621.33	5.53075
2624.05	5.99169
2626.77	6.05278
2629.49	6.35634
2632.21	7.2655
2634.92	8.30822
2637.64	9.46987
2640.35	9.0517
2643.07	7.65528
2645.78	8.43404
2648.49	8.31834
2651.2	8.22176
2653.91	7.90293
2656.62	7.66453
2659.33	7.18525
2662.04	6.77825
2664.74	7.14108
2667.45	7.76562
2670.15	6.78602
2672.86	6.71526
2675.56	6.8823
2678.26	7.02007
2680.96	6.9855
2683.66	6.33101
2686.36	6.61091
2689.06	6.70251
2691.75	6.67363
2694.45	6.60156
2697.14	6.49905
2699.84	6.57883
2702.53	6.55842
2705.22	7.13743
2707.91	7.39883
2710.6	7.7162
2713.29	7.63593
2715.98	7.79617
2718.67	7.2321
2721.35	8.2959
2724.04	7.97151
2726.72	7.95773
2729.4	8.66821
2732.09	9.59908
2734.77	9.50318
2737.45	9.35677
2740.13	9.08197
2742.81	7.73005
2745.48	7.74701
2748.16	7.32518
2750.84	6.70232
2753.51	6.24123
2756.19	5.55084
2758.86	5.30245
2761.53	4.94893
2764.2	4.11001
2766.87	4.29045
2769.54	4.88387
2772.21	4.4148
2774.88	3.01332
2777.54	2.41209
2780.21	2.0869
2782.87	1.61404
2785.53	1.65127
2788.2	1.0975
2790.86	0.624747
2793.52	1.05671
2796.18	1.5963
2798.84	0.976686
2801.49	0.978107
2804.15	0.325432
2806.81	0.393859
2809.46	0.218365
2812.12	0.0597126
2814.77	0.734152
2817.42	1.74272
2820.07	3.15491
2822.72	5.06192
2825.37	8.14089
2828.02	11.165
2830.67	15.1395
2833.31	18.9258
2835.96	23.601
2838.61	28.4111
2841.25	33.2295
2843.89	40.0542
2846.53	46.239
2849.17	53.2364
2851.81	61.3733
2854.45	69.7072
2857.09	77.6987
2859.73	86.3366
2862.36	93.6111
2865	98.8253
2867.64	104.42
2870.27	109.451
2872.9	113.535
2875.53	117.596
2878.16	121.255
2880.79	124.859
2883.42	128.875
2886.05	132.452
2888.68	135.932
2891.3	140.509
2893.93	144.249
2896.55	148.252
2899.18	153.344
2901.8	159.051
2904.42	165.092
2907.04	172.693
2909.66	181.132
2912.28	190.317
2914.9	199.262
2917.51	207.306
2920.13	214.13
2922.74	219.73
2925.36	223.703
2927.97	225.403
2930.59	226.464
2933.2	226.118
2935.81	223.777
2938.42	219.715
2941.02	214.348
2943.63	208.144
2946.24	200.76
2948.85	192.832
2951.45	183.999
2954.05	175.157
2956.66	165.998
2959.26	156.247
2961.86	148.271
2964.46	140.737
2967.06	132.28
2969.66	125.966
2972.26	119.491
2974.85	111.934
2977.45	105.632
2980.05	97.9063
2982.64	91.4213
2985.23	84.4285
2987.83	77.3852
2990.42	70.5917
2993.01	62.8779
2995.6	56.2487
2998.19	49.8696
3000.77	42.9405
3003.36	37.0612
3005.95	30.9232
3008.53	25.1185
3011.12	20.907
3013.7	16.8654
3016.28	12.4037
3018.86	9.43186
3021.44	6.88147
3024.02	5.10392
3026.6	3.13181
3029.18	1.80973
3031.76	0.801749
3034.33	-0.555653
3036.91	-1.58886
3039.48	-1.80894
3042.05	-1.94144
3044.63	-1.7577
3047.2	-1.04627
3049.77	-0.0987575
3052.34	0.74397
3054.91	0.799672
3057.48	1.59643
3060.04	2.63969
3062.61	2.64093
3065.17	3.3038
3067.74	3.6109
3070.3	4.23504
3072.87	4.38482
3075.43	4.29493
3077.99	4.28605
3080.55	4.73926
3083.11	5.5509
3085.67	5.21113
3088.22	4.57752
3090.78	5.04879
3093.34	4.86666
3095.89	4.56772
3098.44	4.85973
3101	5.24955
3103.55	5.77593
3106.1	7.38032
3108.65	8.63657
3111.2	10.5738
3113.75	11.3133
3116.3	13.1916
3118.84	15.1644
3121.39	16.7036
3123.93	17.8048
3126.48	19.6694
3129.02	21.5542
3131.56	23.6617
3134.1	25.6754
3136.64	27.0012
3139.18	29.911
3141.72	32.0531
3144.26	33.7958
3146.8	35.0378
3149.33	35.9461