File: data/Raman/poly_smoothed/Mbcal_20_25_16_1x_45s_532 nm_x100_100%_600 gr_mm_01.txt
#Acq. time (s)=	45
#Accumulations=	2
#Range (cm-¹)=	200...3150
#Windows=	2
#Auto scanning=	Off
#Autofocus=	Off
#Macrospot=	Off
#AutoExposure=	Off
#Spike filter=	Multiple accum.
#Delay time (s)=	0
#Binning=	1
#Readout mode=	Signal
#DeNoise=	Off
#ICS correction=	On
#Dark correction=	Off
#Inst. Process=	Off
#Detector Gain=	Best Dynamic Range
#Detector ADC=	20 kHz
#Detector temperature (°C)=	-69.85
#Instrument=	LabRAM HR Evol
#Detector=	Synapse
#Objective=	x100
#Grating=	600 gr/mm
#ND Filter=	100%
#Laser (nm)=	532
#Hole=	100.021
#Range=	Auto
#Laser Pol.=	No
#Raman. Pol.=	No
#Laser Pol. (°)=	-0.0007625
#Raman Pol. (°)=	89.9995
#Collection=	Microscope
#StageXY=	Marzhauser
#StageZ=	Marzhauser
#X (µm)=	-1169.3
#Y (µm)=	1253
#Z (µm)=	578.15
#Full time(mm:ss)=	3:18
#Project=
#Sample=
#Site=
#Title=	Mbcal_20_25_16_2x_45s_532 nm_x100_100%_600 gr_mm
#Remark=
#Date=	18.07.2022 10:34
#Acquired=	18.07.2022 10:34:29
#Base:Fit=	10.08.2022 10:55:08
#Base:Sub=	10.08.2022 10:55:14
#Filter:Polynom=	16.08.2022 10:07:28
#AxisType[0]=Intens
#AxisUnit[0]=Cnt
#AxisType[1]=Spectr
#AxisUnit[1]=1/cm
200.419	-0.0704666
204.048	1.59728
207.678	0.913095
211.304	0.640861
214.928	1.88318
218.554	2.7666
222.176	2.97442
225.798	3.08353
229.417	3.38213
233.035	4.99164
236.653	4.751
240.268	5.92112
243.881	7.97075
247.493	8.72395
251.103	9.55407
254.715	10.809
258.322	11.8188
261.929	11.1193
265.534	10.1564
269.137	10.7738
272.739	9.7624
276.34	9.8684
279.939	9.26643
283.537	7.31439
287.134	7.10967
290.729	4.79047
294.323	5.66545
297.913	5.665
301.504	6.62846
305.093	7.39237
308.682	6.91684
312.268	8.52671
315.852	8.16683
319.436	8.88057
323.018	10.6048
326.597	10.5443
330.177	15.4763
333.753	17.9672
337.331	17.7425
340.906	17.0145
344.478	17.4344
348.051	16.1557
351.621	16.4394
355.189	17.1295
358.757	17.8037
362.323	14.9796
365.889	13.1511
369.451	12.7559
373.012	12.6632
376.574	14.3923
380.133	15.6955
383.69	17.5882
387.245	17.7463
390.8	19.0858
394.353	18.528
397.906	18.924
401.456	19.0868
405.005	18.9489
408.552	17.9605
412.099	20.2154
415.643	20.8076
419.187	21.0608
422.728	18.6114
426.269	16.8451
429.806	17.2851
433.344	17.1065
436.881	17.8733
440.416	17.6738
443.949	17.1294
447.48	15.7107
451.011	15.5972
454.541	15.2531
458.069	16.1781
461.594	17.9853
465.119	20.1979
468.642	21.5221
472.165	22.1013
475.684	22.1647
479.204	23.1189
482.721	23.8048
486.239	26.6126
489.753	27.0144
493.268	28.8473
496.779	31.905
500.289	34.3002
503.8	34.7383
507.307	35.9068
510.813	39.5908
514.32	44.0147
517.823	47.3803
521.325	49.605
524.826	50.3646
528.325	52.4699
531.823	53.3313
535.32	53.2632
538.815	52.1532
542.309	51.8813
545.802	53.1881
549.293	54.1374
552.783	51.5691
556.271	49.1096
559.759	46.7994
563.245	42.5755
566.729	39.7671
570.213	36.2106
573.693	30.0997
577.173	27.2828
580.652	22.2727
584.13	18.7925
587.605	14.6217
591.08	13.1616
594.552	10.1841
598.025	8.0062
601.496	6.95394
604.964	5.67958
608.433	6.99261
611.898	7.48659
615.364	8.51772
618.827	8.16329
622.288	10.3667
625.75	13.3673
629.209	14.6141
632.667	15.4762
636.125	16.1095
639.58	16.2554
643.033	16.7504
646.485	16.0486
649.936	15.5048
653.388	16.8843
656.836	14.8199
660.283	12.9889
663.728	11.8388
667.173	11.4088
670.616	11.2199
674.057	10.6958
677.498	7.72083
680.937	8.38457
684.375	10.4438
687.809	11.6006
691.244	14.0623
694.678	15.8984
698.111	17.1532
701.54	18.2093
704.97	18.978
708.398	21.3193
711.826	21.528
715.25	23.457
718.675	23.9406
722.096	24.5005
725.518	25.9449
728.937	23.8738
732.357	26.0343
735.773	26.8679
739.19	26.2519
742.604	24.5541
746.018	25.4875
749.429	28.744
752.839	32.1944
756.248	34.7592
759.657	36.8352
763.063	41.1526
766.468	45.3584
769.871	46.8944
773.273	49.4895
776.676	50.6329
780.075	50.412
783.474	51.7297
786.871	52.9175
790.266	55.1863
793.661	58.0093
797.054	58.7476
800.446	58.6573
803.834	57.2869
807.224	55.4319
810.612	54.6983
813.998	53.0454
817.384	53.8835
820.766	51.5801
824.149	53.7417
827.531	59.1956
830.909	66.9907
834.288	74.1546
837.666	80.7911
841.041	85.8429
844.416	92.2597
847.788	94.8854
851.161	96.4832
854.53	97.1464
857.901	96.7077
861.268	94.3078
864.633	92.3863
868	88.6441
871.363	86.1611
874.725	83.2032
878.088	75.1189
881.447	67.572
884.805	59.0523
888.162	52.8658
891.518	45.0391
894.872	38.784
898.225	33.6057
901.577	30.9574
904.928	29.8506
908.277	31.8247
911.625	35.8712
914.972	36.2479
918.318	37.911
921.662	40.291
925.005	42.7037
928.347	43.7922
931.686	44.5564
935.025	42.5648
938.363	40.4848
941.698	37.3277
945.034	34.9271
948.368	32.0782
951.699	31.6859
955.031	29.4528
958.36	25.288
961.689	20.9607
965.016	22.4756
968.343	22.3993
971.666	25.6653
974.991	26.6688
978.312	28.1644
981.632	28.7476
984.953	30.6308
988.27	29.4307
991.587	29.9682
994.902	30.0532
998.216	29.2931
1001.53	30.5545
1004.84	30.8109
1008.15	29.9497
1011.46	31.497
1014.77	33.0292
1018.07	35.7457
1021.38	39.2557
1024.68	42.3413
1027.99	46.6154
1031.29	49.1651
1034.59	49.3299
1037.89	50.9764
1041.18	51.476
1044.48	54.8532
1047.77	55.9757
1051.07	54.6255
1054.36	54.1348
1057.65	51.0087
1060.94	50.3474
1064.23	48.3039
1067.52	47.3191
1070.8	45.3721
1074.09	43.7585
1077.37	40.9665
1080.65	39.8748
1083.93	38.7589
1087.21	40.1353
1090.49	42.6654
1093.77	46.3073
1097.04	49.7819
1100.32	52.4726
1103.59	52.9928
1106.86	53.0547
1110.13	53.8066
1113.4	51.7949
1116.67	48.5118
1119.94	46.8751
1123.2	44.9433
1126.47	41.6252
1129.73	38.9236
1132.99	35.6623
1136.25	33.8666
1139.51	29.6759
1142.77	27.1278
1146.03	26.6314
1149.28	23.9926
1152.54	20.3853
1155.79	15.3119
1159.04	10.7386
1162.29	6.96089
1165.54	4.30493
1168.79	3.62707
1172.04	4.35341
1175.28	4.27377
1178.53	5.24322
1181.77	6.53406
1185.01	8.30017
1188.25	11.363
1191.49	13.0997
1194.73	17.2189
1197.96	20.7799
1201.2	26.306
1204.43	31.2644
1207.66	37.1149
1210.9	44.9425
1214.13	51.4352
1217.36	58.1456
1220.58	66.5284
1223.81	76.2574
1227.04	84.0836
1230.26	89.7394
1233.48	96.1958
1236.71	103.7
1239.93	110.776
1243.14	116.773
1246.36	123.44
1249.58	129.316
1252.8	135.148
1256.01	141.404
1259.22	147.325
1262.43	153.196
1265.64	159.685
1268.85	161.542
1272.06	165.708
1275.27	169.706
1278.48	172.872
1281.68	178.274
1284.88	182.908
1288.08	186.905
1291.28	190.657
1294.48	195.063
1297.68	197.412
1300.88	202.795
1304.07	206.12
1307.27	208.099
1310.46	210.626
1313.65	215.078
1316.85	215.463
1320.03	215.178
1323.22	214.729
1326.41	214.083
1329.6	214.179
1332.78	214.647
1335.96	212.286
1339.15	211.117
1342.33	207.429
1345.51	203.214
1348.69	197.977
1351.86	195.48
1355.04	192.984
1358.21	189.095
1361.39	185.495
1364.56	179.783
1367.73	174.914
1370.9	171.349
1374.07	166.508
1377.24	162.881
1380.41	160.676
1383.57	158.916
1386.73	159.364
1389.9	158.921
1393.06	157.433
1396.22	156.59
1399.38	157.833
1402.54	162.422
1405.69	167.589
1408.85	171.669
1412	177.855
1415.16	183.484
1418.31	195.707
1421.46	208.944
1424.61	221.62
1427.76	235.979
1430.9	249.228
1434.05	262.281
1437.2	272.33
1440.34	277.957
1443.48	281.44
1446.62	282.841
1449.76	280.749
1452.9	277.713
1456.04	272.362
1459.17	265.465
1462.31	256.305
1465.44	243.261
1468.58	227.82
1471.71	212.743
1474.84	197.292
1477.97	180.524
1481.1	163.02
1484.22	145.377
1487.35	131.354
1490.47	120.679
1493.59	109.674
1496.72	102.406
1499.84	95.2278
1502.96	89.0417
1506.08	83.8734
1509.19	79.9268
1512.31	75.8331
1515.42	72.6189
1518.54	70.9121
1521.65	72.0978
1524.76	71.7979
1527.87	73.5466
1530.98	75.9322
1534.09	78.5943
1537.2	82.6655
1540.3	83.8188
1543.41	86.4769
1546.51	90.74
1549.61	95.0208
1552.71	98.8724
1555.81	104.003
1558.91	107.146
1562.01	111.799
1565.1	116.343
1568.2	119.83
1571.29	124.834
1574.38	130.053
1577.48	136.417
1580.57	140.369
1583.65	145.613
1586.74	150.021
1589.83	155.08
1592.92	158.819
1596	162.034
1599.08	165.447
1602.16	165.231
1605.24	162.867
1608.32	162.183
1611.4	159.319
1614.48	158.308
1617.56	157.366
1620.63	158.267
1623.71	159.159
1626.78	159.874
1629.85	160.086
1632.92	161.079
1635.99	162.501
1639.06	164.998
1642.12	168.656
1645.19	169.876
1648.25	171.746
1651.32	172.655
1654.38	172.232
1657.44	169.969
1660.5	167.719
1663.56	162.829
1666.62	156.004
1669.67	148.032
1672.73	138.322
1675.79	126.168
1678.84	113.499
1681.89	99.7114
1684.94	88.2364
1687.99	77.7196
1691.04	65.8379
1694.08	57.211
1697.13	47.9471
1700.18	38.8283
1703.22	33.2064
1706.26	27.1121
1709.3	22.7892
1712.35	19.0748
1715.39	16.984
1718.42	14.5951
1721.46	12.7551
1724.5	11.3639
1727.53	12.2836
1730.56	10.5062
1733.6	10.1935
1736.63	9.47064
1739.66	8.57685
1742.69	8.42024
1745.71	7.65368
1748.74	5.95733
1751.77	4.39425
1754.79	4.29197
1757.81	3.65804
1760.84	3.54882
1763.86	2.34828
1766.88	1.58344
1769.9	0.309855
1772.91	0.0370812
1775.93	0.553346
1778.95	0.442911
1781.96	1.35199
1784.97	2.41572
1787.99	2.98687
1791	4.43199
1794.01	4.57124
1797.01	5.50513
1800.02	5.52935
1803.03	5.55688
1806.03	5.03924
1809.04	5.1634
1812.04	5.30039
1815.04	4.92222
1818.04	5.62185
1821.04	6.18686
1824.04	4.96337
1827.04	5.37042
1830.03	4.83634
1833.03	4.66662
1836.02	4.69731
1839.02	5.28804
1842.01	3.94865
1845	4.66038
1847.99	5.25843
1850.98	5.70358
1853.96	5.07636
1856.95	5.51896
1859.94	5.48451
1862.92	6.25701
1865.9	5.66214
1868.88	6.21763
1871.86	6.05934
1874.84	6.63698
1877.82	6.25619
1880.8	7.30478
1882.58	7.97044
1885.57	9.4914
1888.56	10.0186
1891.54	10.0619
1894.53	9.79852
1897.51	10.0918
1900.5	9.92405
1903.48	9.74129
1906.46	10.209
1909.44	9.04856
1912.42	6.72678
1915.4	6.01504
1918.37	5.99532
1921.35	4.06198
1924.32	3.87369
1927.3	4.30035
1930.27	4.16883
1933.24	3.30454
1936.21	1.73333
1939.18	0.738116
1942.15	0.182433
1945.11	0.807827
1948.08	1.22144
1951.04	1.97608
1954.01	2.81004
1956.97	3.60426
1959.93	4.02732
1962.89	3.993
1965.85	5.38873
1968.81	5.20538
1971.77	4.4921
1974.72	5.17253
1977.68	4.72765
1980.63	5.37462
1983.58	5.73536
1986.53	5.97483
1989.48	6.63232
1992.43	8.26684
1995.38	9.57829
1998.33	10.776
2001.27	8.76709
2004.22	8.3271
2007.16	7.03572
2010.11	6.86827
2013.05	6.33893
2015.99	6.24499
2018.93	6.43342
2021.87	6.47338
2024.8	7.24841
2027.74	8.43938
2030.68	8.35614
2033.61	7.86096
2036.54	6.78426
2039.48	6.34705
2042.41	5.79359
2045.34	6.40255
2048.27	8.17393
2051.19	8.80807
2054.12	10.2435
2057.05	12.7915
2059.97	14.8256
2062.9	16.3124
2065.82	16.9437
2068.74	18.3433
2071.66	19.4055
2074.58	19.0558
2077.5	19.7602
2080.41	20.8853
2083.33	21.4323
2086.24	21.6972
2089.16	22.0034
2092.07	23.154
2094.98	24.4382
2097.89	25.5737
2100.8	26.461
2103.71	27.3884
2106.62	27.8679
2109.53	30.1948
2112.43	32.299
2115.33	34.6818
2118.24	38.0855
2121.14	41.657
2124.04	45.7009
2126.94	49.7606
2129.84	54.3283
2132.74	57.8013
2135.63	63.6296
2138.53	69.4517
2141.43	74.3769
2144.32	79.0359
2147.21	83.6746
2150.1	88.1584
2152.99	92.5581
2155.88	97.0072
2158.77	101.785
2161.66	106.492
2164.55	110.897
2167.43	113.812
2170.31	116.801
2173.2	117.793
2176.08	119.008
2178.96	118.708
2181.84	116.758
2184.72	115.428
2187.6	113.172
2190.47	109.103
2193.35	104.932
2196.23	99.9403
2199.1	95.3583
2201.97	89.7925
2204.84	84.6639
2207.71	77.3236
2210.58	71.5062
2213.45	65.8712
2216.32	60.6175
2219.19	57.2391
2222.05	52.7034
2224.92	49.8453
2227.78	47.4355
2230.64	44.352
2233.5	41.8108
2236.36	39.5611
2239.22	37.7133
2242.08	35.536
2244.94	33.7156
2247.79	33.4898
2250.65	32.097
2253.5	30.186
2256.36	29.3517
2259.21	27.3645
2262.06	26.4112
2264.91	25.4989
2267.76	24.1357
2270.6	22.9878
2273.45	21.3635
2276.3	19.6099
2279.14	19.2707
2281.98	18.4935
2284.83	16.8982
2287.67	16.5507
2290.51	15.3445
2293.35	12.8325
2296.19	12.1744
2299.02	12.5078
2301.86	11.3332
2304.7	10.5182
2307.53	10.3617
2310.36	10.324
2313.2	12.0887
2316.03	13.1187
2318.86	13.1593
2321.69	11.8745
2324.51	11.1005
2327.34	11.1466
2330.17	10.5668
2332.99	10.7781
2335.82	10.308
2338.64	10.5992
2341.46	9.46377
2344.28	8.81148
2347.1	7.71585
2349.92	6.56537
2352.74	5.2225
2355.56	3.90832
2358.37	3.3032
2361.19	3.0668
2364	3.57833
2366.82	4.34184
2369.63	4.77569
2372.44	3.92178
2375.25	3.76919
2378.06	4.39393
2380.86	5.23767
2383.67	5.21394
2386.48	4.66739
2389.28	3.55313
2392.09	2.72614
2394.89	2.03771
2397.69	2.69038
2400.49	3.03343
2403.29	4.13626
2406.09	4.89068
2408.89	4.59198
2411.69	4.53339
2414.48	4.18748
2417.28	4.00822
2420.07	4.22905
2422.86	4.24345
2425.65	5.80838
2428.45	5.36406
2431.23	6.63074
2434.02	4.84064
2436.81	5.4807
2439.6	6.50644
2442.38	4.56587
2445.17	3.55678
2447.95	2.9832
2450.73	2.64576
2453.52	0.569246
2456.3	0.91494
2459.08	0.0670966
2461.85	0.21303
2464.63	0.408882
2467.41	1.30114
2470.19	1.92826
2472.96	2.57756
2475.73	3.17042
2478.51	2.47508
2481.28	3.36422
2484.05	3.63931
2486.82	4.21358
2489.59	3.75766
2492.35	4.10406
2495.12	3.34417
2497.89	3.01497
2500.65	3.98633
2503.42	3.85069
2506.18	4.2753
2508.94	2.69413
2511.7	1.5776
2514.46	1.82149
2517.22	1.64278
2519.98	2.33645
2522.73	3.03322
2525.49	3.30925
2528.25	4.28719
2531	5.5928
2533.75	7.05993
2536.5	8.49877
2539.25	9.00166
2542.01	9.25385
2544.75	9.51627
2547.5	9.55926
2550.25	8.59433
2553	7.3333
2555.74	6.53491
2558.49	7.32367
2561.23	7.85411
2563.97	7.42847
2566.71	8.12498
2569.45	9.33396
2572.19	7.97402
2574.93	7.4424
2577.67	8.17887
2580.4	8.0885
2583.14	8.08531
2585.87	8.93418
2588.6	9.44345
2591.34	9.98586
2594.07	10.6383
2596.8	12.1051
2599.53	12.9971
2602.26	13.6421
2604.98	12.3057
2607.71	11.6726
2610.44	11.5763
2613.16	11.0112
2615.88	9.62817
2618.61	9.50249
2621.33	9.7029
2624.05	10.3936
2626.77	9.4869
2629.49	9.65178
2632.21	9.26418
2634.92	10.0918
2637.64	9.82897
2640.35	10.5761
2643.07	10.7315
2645.78	11.3618
2648.49	10.5652
2651.2	10.5032
2653.91	10.985
2656.62	11.9152
2659.33	13.4401
2662.04	14.4891
2664.74	15.2345
2667.45	15.4096
2670.15	14.4641
2672.86	14.2685
2675.56	13.014
2678.26	13.9109
2680.96	13.71
2683.66	13.3251
2686.36	13.5437
2689.06	14.3771
2691.75	14.4689
2694.45	15.3966
2697.14	16.1275
2699.84	17.7337
2702.53	19.0923
2705.22	20.4547
2707.91	21.3087
2710.6	23.3493
2713.29	23.3924
2715.98	23.883
2718.67	25.5601
2721.35	25.795
2724.04	25.7791
2726.72	24.3181
2729.4	23.8393
2732.09	22.0143
2734.77	20.0541
2737.45	17.7748
2740.13	16.6498
2742.81	14.9488
2745.48	13.0942
2748.16	11.1609
2750.84	9.6453
2753.51	8.07684
2756.19	6.15609
2758.86	5.14895
2761.53	4.48481
2764.2	2.71994
2766.87	2.18075
2769.54	1.53305
2772.21	2.1229
2774.88	1.81461
2777.54	2.11119
2780.21	2.38821
2782.87	2.80618
2785.53	2.2559
2788.2	1.85126
2790.86	-0.0949133
2793.52	-0.260427
2796.18	0.906974
2798.84	0.982881
2801.49	0.496791
2804.15	0.0553974
2806.81	-0.103442
2809.46	-0.0511492
2812.12	-1.20212
2814.77	0.200339
2817.42	3.21716
2820.07	8.39884
2822.72	15.4574
2825.37	24.6075
2828.02	34.2283
2830.67	46.1324
2833.31	58.3878
2835.96	71.8094
2838.61	86.1202
2841.25	100.369
2843.89	116.641
2846.53	134.435
2849.17	152.841
2851.81	173.01
2854.45	193.55
2857.09	214.442
2859.73	236.873
2862.36	257.289
2865	274.762
2867.64	291.123
2870.27	306.96
2872.9	321.382
2875.53	334.652
2878.16	348.98
2880.79	364.001
2883.42	377.629
2886.05	389.945
2888.68	402.591
2891.3	416.311
2893.93	429.19
2896.55	441.708
2899.18	457.307
2901.8	473.597
2904.42	491.648
2907.04	513.061
2909.66	538.338
2912.28	563.811
2914.9	589.422
2917.51	615.667
2920.13	638.18
2922.74	659.044
2925.36	673.468
2927.97	679.495
2930.59	681.82
2933.2	679.908
2935.81	672.567
2938.42	658.35
2941.02	642.241
2943.63	619.229
2946.24	594.995
2948.85	566.907
2951.45	538.473
2954.05	510.608
2956.66	481.76
2959.26	453.169
2961.86	427.22
2964.46	401.282
2967.06	379.175
2969.66	360.615
2972.26	344.297
2974.85	328.143
2977.45	312.211
2980.05	296.902
2982.64	281.247
2985.23	264.163
2987.83	246.288
2990.42	225.068
2993.01	205.641
2995.6	185.223
2998.19	165.517
3000.77	145.277
3003.36	126.326
3005.95	107.134
3008.53	89.8584
3011.12	73.3041
3013.7	58.777
3016.28	45.9524
3018.86	34.418
3021.44	24.2562
3024.02	17.2815
3026.6	10.4968
3029.18	6.69431
3031.76	4.78151
3034.33	2.94455
3036.91	2.41062
3039.48	3.57287
3042.05	5.23616
3044.63	7.39913
3047.2	8.65275
3049.77	11.0648
3052.34	12.4698
3054.91	14.1391
3057.48	13.5328
3060.04	14.0271
3062.61	14.7146
3065.17	13.6411
3067.74	13.2252
3070.3	11.2785
3072.87	8.95328
3075.43	7.19784
3077.99	4.99114
3080.55	2.81989
3083.11	0.630944
3085.67	-0.346308
3088.22	-1.20072
3090.78	-0.71301
3093.34	-0.209406
3095.89	1.05558
3098.44	2.12886
3101	2.83392
3103.55	3.69037
3106.1	4.79354
3108.65	5.61984
3111.2	6.20466
3113.75	8.50425
3116.3	10.7766
3118.84	12.2586
3121.39	14.7321
3123.93	17.5118
3126.48	19.7947
3129.02	22.9732
3131.56	25.6591
3134.1	28.5206
3136.64	31.7929
3139.18	35.5192
3141.72	40.4163
3144.26	45.6893
3146.8	51.972
3149.33	57.4476