File: data/Raman/poly_smoothed/Mbcal_20_25_34_1x_45s_532 nm_x100_100%_600 gr_mm_01.txt
#Acq. time (s)=	45
#Accumulations=	2
#Range (cm-¹)=	200...3150
#Windows=	2
#Auto scanning=	Off
#Autofocus=	Off
#Macrospot=	Off
#AutoExposure=	Off
#Spike filter=	Multiple accum.
#Delay time (s)=	0
#Binning=	1
#Readout mode=	Signal
#DeNoise=	Off
#ICS correction=	On
#Dark correction=	Off
#Inst. Process=	Off
#Detector Gain=	Best Dynamic Range
#Detector ADC=	20 kHz
#Detector temperature (°C)=	-70.08
#Instrument=	LabRAM HR Evol
#Detector=	Synapse
#Objective=	x100
#Grating=	600 gr/mm
#ND Filter=	100%
#Laser (nm)=	532
#Hole=	100.021
#Range=	Auto
#Laser Pol.=	No
#Raman. Pol.=	No
#Laser Pol. (°)=	-0.0007625
#Raman Pol. (°)=	89.9995
#Collection=	Microscope
#StageXY=	Marzhauser
#StageZ=	Marzhauser
#X (µm)=	-1124.5
#Y (µm)=	1292.6
#Z (µm)=	578.4
#Full time(mm:ss)=	3:09
#Project=
#Sample=
#Site=
#Title=	Mbcal_20_25_34_2x_45s_532 nm_x100_100%_600 gr_mm
#Remark=
#Date=	18.07.2022 12:37
#Acquired=	18.07.2022 12:37:05
#Base:Fit=	10.08.2022 10:55:08
#Base:Sub=	10.08.2022 10:55:14
#Filter:Polynom=	16.08.2022 10:07:28
#AxisType[0]=Intens
#AxisUnit[0]=Cnt
#AxisType[1]=Spectr
#AxisUnit[1]=1/cm
200.419	52.6596
204.048	36.3175
207.678	26.2642
211.304	20.0991
214.928	16.5779
218.554	13.7218
222.176	11.0916
225.798	9.13576
229.417	8.11047
233.035	6.29751
236.653	5.14121
240.268	5.67402
243.881	5.15927
247.493	4.77663
251.103	5.34137
254.715	4.17159
258.322	6.66747
261.929	8.52555
265.534	8.2936
269.137	7.51444
272.739	5.44361
276.34	5.95274
279.939	2.98858
283.537	2.87978
287.134	-0.115459
290.729	0.992035
294.323	1.46474
297.913	4.15326
301.504	5.89536
305.093	8.45989
308.682	10.1175
312.268	12.038
315.852	14.4267
319.436	15.6001
323.018	17.4761
326.597	21.3033
330.177	24.2366
333.753	23.6895
337.331	24.8442
340.906	25.9555
344.478	27.6592
348.051	28.7415
351.621	29.1828
355.189	27.1162
358.757	23.965
362.323	23.4593
365.889	21.9104
369.451	19.7817
373.012	16.7544
376.574	14.9206
380.133	15.1751
383.69	14.8065
387.245	15.1082
390.8	15.584
394.353	15.7786
397.906	15.0778
401.456	16.4147
405.005	16.5673
408.552	18.4307
412.099	19.4708
415.643	19.5503
419.187	18.4505
422.728	17.1907
426.269	16.0837
429.806	14.6816
433.344	14.9656
436.881	13.9034
440.416	12.1604
443.949	10.1546
447.48	10.1541
451.011	9.08362
454.541	9.84084
458.069	10.0054
461.594	9.82162
465.119	10.4806
468.642	11.1233
472.165	12.5975
475.684	14.3829
479.204	17.7732
482.721	20.7325
486.239	24.1552
489.753	26.4286
493.268	29.1012
496.779	30.4261
500.289	31.5583
503.8	32.665
507.307	32.6819
510.813	33.148
514.32	34.7982
517.823	35.3473
521.325	35.2101
524.826	36.5059
528.325	36.4476
531.823	37.0406
535.32	36.5341
538.815	37.2477
542.309	37.7353
545.802	36.7555
549.293	32.2784
552.783	31.2839
556.271	28.5667
559.759	27.4826
563.245	26.9151
566.729	26.1663
570.213	23.5668
573.693	20.9553
577.173	17.1282
580.652	15.8425
584.13	12.8579
587.605	10.4813
591.08	6.5191
594.552	6.26504
598.025	5.05311
601.496	5.55838
604.964	6.43545
608.433	7.19846
611.898	7.58922
615.364	8.23383
618.827	8.68245
622.288	9.37049
625.75	9.62627
629.209	11.4286
632.667	13.7067
636.125	13.0908
639.58	14.2253
643.033	14.5302
646.485	15.9938
649.936	17.0712
653.388	16.4516
656.836	17.0803
660.283	17.6198
663.728	18.3012
667.173	16.9248
670.616	16.1347
674.057	18.0521
677.498	18.9511
680.937	20.6007
684.375	21.7799
687.809	23.3238
691.244	23.9879
694.678	23.294
698.111	23.8065
701.54	24.3079
704.97	24.9201
708.398	25.542
711.826	28.2583
715.25	29.751
718.675	28.9013
722.096	28.6452
725.518	28.6767
728.937	29.6675
732.357	30.4372
735.773	31.4275
739.19	33.5093
742.604	34.7955
746.018	34.2721
749.429	36.7925
752.839	40.9991
756.248	45.5224
759.657	47.4851
763.063	48.3565
766.468	50.8673
769.871	53.4416
773.273	55.5745
776.676	57.8711
780.075	60.7276
783.474	62.4111
786.871	62.7759
790.266	64.5094
793.661	65.8521
797.054	67.7249
800.446	66.2074
803.834	67.0632
807.224	66.8519
810.612	64.2385
813.998	63.3022
817.384	63.7692
820.766	62.8701
824.149	62.8946
827.531	64.4645
830.909	65.7277
834.288	68.242
837.666	69.3328
841.041	70.9547
844.416	69.8724
847.788	70.7723
851.161	72.629
854.53	73.0578
857.901	71.2127
861.268	69.3982
864.633	68.111
868	64.9273
871.363	61.1704
874.725	59.1284
878.088	55.0549
881.447	50.4484
884.805	46.9853
888.162	41.4628
891.518	38.0353
894.872	35.343
898.225	32.7395
901.577	31.0131
904.928	30.0041
908.277	30.6947
911.625	31.1005
914.972	32.0102
918.318	32.2609
921.662	31.5318
925.005	33.8005
928.347	34.9809
931.686	36.8038
935.025	35.9095
938.363	35.1151
941.698	33.5618
945.034	31.7541
948.368	28.9495
951.699	26.6906
955.031	25.5622
958.36	22.7039
961.689	19.1981
965.016	17.6363
968.343	16.7379
971.666	15.1626
974.991	16.1292
978.312	13.7982
981.632	12.9133
984.953	13.0378
988.27	12.4652
991.587	13.4657
994.902	13.6724
998.216	14.9741
1001.53	16.0293
1004.84	16.8695
1008.15	17.8593
1011.46	17.6758
1014.77	19.0349
1018.07	19.7517
1021.38	23.9312
1024.68	25.9626
1027.99	27.3259
1031.29	28.8608
1034.59	28.9964
1037.89	27.7593
1041.18	24.9161
1044.48	25.1845
1047.77	25.5156
1051.07	23.4568
1054.36	22.9547
1057.65	21.3827
1060.94	19.4958
1064.23	19.2516
1067.52	17.968
1070.8	17.3548
1074.09	18.5778
1077.37	18.6588
1080.65	18.7765
1083.93	17.7705
1087.21	19.1425
1090.49	21.7235
1093.77	26.5067
1097.04	30.8676
1100.32	35.0107
1103.59	37.9065
1106.86	39.2503
1110.13	39.9911
1113.4	39.8124
1116.67	38.222
1119.94	38.0736
1123.2	37.3903
1126.47	36.0968
1129.73	35.0719
1132.99	32.9517
1136.25	31.5131
1139.51	31.0814
1142.77	29.4824
1146.03	27.4442
1149.28	23.6859
1152.54	21.549
1155.79	18.4505
1159.04	15.1956
1162.29	12.1194
1165.54	9.22991
1168.79	9.30247
1172.04	9.43097
1175.28	7.41814
1178.53	6.60687
1181.77	7.5043
1185.01	6.64341
1188.25	7.51989
1191.49	9.54557
1194.73	10.0011
1197.96	12.0258
1201.2	15.4351
1204.43	16.6074
1207.66	18.5841
1210.9	21.5523
1214.13	26.4617
1217.36	33.027
1220.58	37.5238
1223.81	42.4564
1227.04	46.0984
1230.26	49.1383
1233.48	54.4775
1236.71	56.7715
1239.93	59.7104
1243.14	62.1114
1246.36	65.834
1249.58	68.6531
1252.8	69.573
1256.01	71.1034
1259.22	72.8673
1262.43	74.0122
1265.64	76.8638
1268.85	78.3982
1272.06	79.0784
1275.27	79.3971
1278.48	80.6758
1281.68	81.169
1284.88	82.146
1288.08	83.8028
1291.28	87.6797
1294.48	90.0857
1297.68	91.7918
1300.88	95.5177
1304.07	97.859
1307.27	98.4553
1310.46	100.313
1313.65	103.733
1316.85	105.36
1320.03	105.66
1323.22	107.406
1326.41	107.276
1329.6	107.431
1332.78	106.961
1335.96	108.441
1339.15	109.807
1342.33	110.203
1345.51	111.057
1348.69	110.994
1351.86	109.14
1355.04	106.882
1358.21	104.102
1361.39	101.025
1364.56	99.0234
1367.73	96.9172
1370.9	93.9364
1374.07	90.2924
1377.24	86.0073
1380.41	84.0113
1383.57	79.4184
1386.73	76.0725
1389.9	73.5143
1393.06	69.8559
1396.22	67.789
1399.38	66.1373
1402.54	67.3733
1405.69	66.9947
1408.85	69.3807
1412	73.8426
1415.16	80.4523
1418.31	86.5816
1421.46	94.8652
1424.61	102.264
1427.76	110.879
1430.9	119.774
1434.05	127.051
1437.2	135.683
1440.34	143.091
1443.48	148.159
1446.62	150.152
1449.76	153.148
1452.9	152.686
1456.04	153.417
1459.17	154.682
1462.31	155.801
1465.44	155.557
1468.58	153.825
1471.71	154.212
1474.84	153.398
1477.97	149.908
1481.1	145.236
1484.22	140.159
1487.35	136.836
1490.47	131.168
1493.59	125.05
1496.72	118.033
1499.84	110.611
1502.96	104.058
1506.08	96.4771
1509.19	89.8355
1512.31	80.3227
1515.42	72.1104
1518.54	63.2085
1521.65	53.3743
1524.76	47.4529
1527.87	43.0901
1530.98	39.5037
1534.09	38.659
1537.2	38.7905
1540.3	40.151
1543.41	43.4927
1546.51	46.3554
1549.61	49.4492
1552.71	52.0056
1555.81	55.1161
1558.91	57.8963
1562.01	60.6715
1565.1	64.1944
1568.2	64.6333
1571.29	66.8732
1574.38	70.4403
1577.48	74.5221
1580.57	78.9985
1583.65	82.8143
1586.74	85.2008
1589.83	87.0508
1592.92	88.3226
1596	89.9971
1599.08	89.513
1602.16	89.3163
1605.24	87.8179
1608.32	85.4165
1611.4	84.3592
1614.48	83.6795
1617.56	85.6407
1620.63	84.4044
1623.71	86.3794
1626.78	87.5179
1629.85	88.1613
1632.92	89.8841
1635.99	92.5319
1639.06	95.3241
1642.12	97.6849
1645.19	100.031
1648.25	102.578
1651.32	104.446
1654.38	103.76
1657.44	103.062
1660.5	99.9208
1663.56	97.6884
1666.62	94.7627
1669.67	90.2888
1672.73	83.6359
1675.79	76.4576
1678.84	68.3798
1681.89	58.242
1684.94	52.3502
1687.99	45.647
1691.04	39.3827
1694.08	33.5973
1697.13	28.1208
1700.18	23.7415
1703.22	19.8836
1706.26	17.6911
1709.3	16.1972
1712.35	14.0529
1715.39	12.6674
1718.42	9.47178
1721.46	8.04264
1724.5	6.53578
1727.53	5.6867
1730.56	3.78372
1733.6	3.15886
1736.63	3.71574
1739.66	4.3667
1742.69	4.05273
1745.71	1.87938
1748.74	1.17301
1751.77	0.205516
1754.79	-1.0352
1757.81	-0.657345
1760.84	-0.253431
1763.86	-2.11311
1766.88	-2.02369
1769.9	-1.67993
1772.91	-0.386909
1775.93	-0.204946
1778.95	0.522859
1781.96	-0.069216
1784.97	0.828116
1787.99	1.07685
1791	1.79597
1794.01	1.69783
1797.01	1.40551
1800.02	2.34753
1803.03	2.93264
1806.03	3.18323
1809.04	4.35211
1812.04	4.46979
1815.04	5.54991
1818.04	4.92138
1821.04	3.83077
1824.04	4.69234
1827.04	4.71619
1830.03	5.23061
1833.03	4.87099
1836.02	4.42666
1839.02	3.90637
1842.01	2.55479
1845	3.21394
1847.99	3.80738
1850.98	3.51992
1853.96	2.06696
1856.95	1.76753
1859.94	1.95215
1862.92	2.03812
1865.9	2.04955
1868.88	3.02233
1871.86	2.86932
1874.84	4.4093
1877.82	4.50609
1880.8	5.34187
1882.58	5.71858
1885.57	7.88034
1888.56	9.15073
1891.54	8.76705
1894.53	9.26957
1897.51	10.6447
1900.5	10.9959
1903.48	12.5759
1906.46	12.0876
1909.44	12.2837
1912.42	13.3107
1915.4	14.017
1918.37	15.6579
1921.35	14.6133
1924.32	13.2097
1927.3	12.5007
1930.27	12.3549
1933.24	11.4642
1936.21	11.2136
1939.18	11.1667
1942.15	11.1287
1945.11	11.289
1948.08	12.5706
1951.04	12.0886
1954.01	10.9734
1956.97	10.7453
1959.93	9.34811
1962.89	8.87208
1965.85	7.45877
1968.81	7.40146
1971.77	6.8586
1974.72	6.89633
1977.68	5.87223
1980.63	5.97978
1983.58	6.18899
1986.53	5.95533
1989.48	6.70461
1992.43	7.29504
1995.38	7.00708
1998.33	7.68484
2001.27	8.49411
2004.22	9.71464
2007.16	11.1511
2010.11	11.9167
2013.05	13.7037
2015.99	13.6842
2018.93	14.9338
2021.87	14.1514
2024.8	13.4572
2027.74	12.382
2030.68	12.5821
2033.61	13.132
2036.54	13.5719
2039.48	13.467
2042.41	13.1198
2045.34	12.3895
2048.27	12.8127
2051.19	14.2351
2054.12	15.1714
2057.05	15.6818
2059.97	16.7857
2062.9	17.4499
2065.82	18.37
2068.74	17.9424
2071.66	17.3643
2074.58	17.1386
2077.5	17.2894
2080.41	17.3077
2083.33	17.2677
2086.24	18.1436
2089.16	18.1154
2092.07	18.5317
2094.98	18.7431
2097.89	20.0211
2100.8	21.6863
2103.71	23.5379
2106.62	24.7408
2109.53	26.7557
2112.43	28.0617
2115.33	29.8724
2118.24	32.4107
2121.14	35.5856
2124.04	38.0568
2126.94	40.9332
2129.84	43.0767
2132.74	45.7824
2135.63	48.9781
2138.53	51.4795
2141.43	53.1484
2144.32	55.2902
2147.21	59.2192
2150.1	61.6117
2152.99	64.5085
2155.88	67.0977
2158.77	70.1488
2161.66	72.2704
2164.55	73.5148
2167.43	74.638
2170.31	76.0094
2173.2	77.0095
2176.08	76.4905
2178.96	76.4172
2181.84	76.6457
2184.72	76.0545
2187.6	74.4796
2190.47	73.277
2193.35	71.5447
2196.23	70.2537
2199.1	67.2429
2201.97	64.6285
2204.84	62.0138
2207.71	58.9699
2210.58	55.565
2213.45	52.6478
2216.32	48.6768
2219.19	46.0215
2222.05	42.8805
2224.92	41.0482
2227.78	39.5299
2230.64	35.677
2233.5	32.0855
2236.36	30.0683
2239.22	28.7267
2242.08	28.1852
2244.94	27.3175
2247.79	26.0497
2250.65	25.4337
2253.5	25.0804
2256.36	24.4558
2259.21	22.775
2262.06	21.6581
2264.91	20.3578
2267.76	20.1525
2270.6	18.5325
2273.45	17.5468
2276.3	15.3371
2279.14	15.5148
2281.98	13.9088
2284.83	12.5675
2287.67	12.0362
2290.51	12.1658
2293.35	9.45548
2296.19	9.00972
2299.02	8.40208
2301.86	7.26891
2304.7	8.00666
2307.53	9.23725
2310.36	9.96363
2313.2	11.2051
2316.03	11.4062
2318.86	10.542
2321.69	10.5947
2324.51	9.52768
2327.34	8.63937
2330.17	7.74437
2332.99	7.18325
2335.82	6.58362
2338.64	6.19354
2341.46	5.66201
2344.28	5.50042
2347.1	6.08623
2349.92	7.08329
2352.74	5.58466
2355.56	4.5133
2358.37	3.98866
2361.19	3.12825
2364	3.32239
2366.82	3.8322
2369.63	3.78314
2372.44	4.38494
2375.25	4.8255
2378.06	6.64823
2380.86	7.21421
2383.67	6.31591
2386.48	5.09842
2389.28	4.53021
2392.09	4.0754
2394.89	4.49713
2397.69	4.73292
2400.49	4.63181
2403.29	4.82974
2406.09	4.65824
2408.89	5.2903
2411.69	7.1274
2414.48	6.46139
2417.28	7.1509
2420.07	6.85308
2422.86	5.36583
2425.65	4.39728
2428.45	4.45348
2431.23	3.75853
2434.02	4.59528
2436.81	4.52035
2439.6	3.72566
2442.38	3.76623
2445.17	3.66177
2447.95	3.21469
2450.73	2.15122
2453.52	3.64458
2456.3	3.43929
2459.08	2.72764
2461.85	1.63743
2464.63	1.11455
2467.41	1.7852
2470.19	1.12226
2472.96	1.05219
2475.73	2.43646
2478.51	2.68649
2481.28	2.72728
2484.05	2.41876
2486.82	3.88876
2489.59	3.51655
2492.35	1.98085
2495.12	2.60221
2497.89	3.95142
2500.65	4.9322
2503.42	5.56389
2506.18	4.69519
2508.94	4.60373
2511.7	4.02603
2514.46	4.16732
2517.22	5.10771
2519.98	6.36491
2522.73	6.85129
2525.49	5.89022
2528.25	5.84208
2531	6.33886
2533.75	7.27173
2536.5	7.5127
2539.25	8.00783
2542.01	9.50386
2544.75	10.2551
2547.5	10.0907
2550.25	10.3667
2553	10.8384
2555.74	10.1851
2558.49	9.47016
2561.23	9.29686
2563.97	10.3071
2566.71	9.56659
2569.45	8.74564
2572.19	7.45554
2574.93	6.83269
2577.67	6.31056
2580.4	5.98427
2583.14	5.78333
2585.87	6.62908
2588.6	5.83995
2591.34	6.26794
2594.07	5.56792
2596.8	5.40184
2599.53	4.67267
2602.26	4.39884
2604.98	5.05138
2607.71	5.15524
2610.44	5.97908
2613.16	5.07546
2615.88	4.79351
2618.61	4.7753
2621.33	4.85176
2624.05	4.67063
2626.77	5.10704
2629.49	6.45257
2632.21	6.37018
2634.92	6.32299
2637.64	6.99572
2640.35	7.51777
2643.07	8.27254
2645.78	8.45141
2648.49	9.05468
2651.2	9.75967
2653.91	9.52052
2656.62	10.413
2659.33	10.7423
2662.04	10.2699
2664.74	9.82629
2667.45	10.055
2670.15	10.77
2672.86	11.8235
2675.56	11.3141
2678.26	10.864
2680.96	11.1512
2683.66	11.6701
2686.36	13.1847
2689.06	13.7209
2691.75	13.9103
2694.45	14.3885
2697.14	14.8106
2699.84	14.2994
2702.53	14.9004
2705.22	15.3593
2707.91	15.0149
2710.6	15.1954
2713.29	17.0176
2715.98	17.4436
2718.67	16.7952
2721.35	17.8638
2724.04	19.1075
2726.72	18.2067
2729.4	19.0729
2732.09	18.4497
2734.77	18.7315
2737.45	18.4995
2740.13	17.5377
2742.81	16.8491
2745.48	17.5948
2748.16	17.304
2750.84	17.3806
2753.51	15.9043
2756.19	13.3342
2758.86	11.0628
2761.53	9.08429
2764.2	8.20736
2766.87	6.67819
2769.54	5.73583
2772.21	4.05424
2774.88	3.74317
2777.54	3.3298
2780.21	2.95435
2782.87	1.57916
2785.53	1.00614
2788.2	0.651008
2790.86	0.0999094
2793.52	-0.010107
2796.18	1.7644
2798.84	1.36761
2801.49	2.58384
2804.15	3.66585
2806.81	4.30016
2809.46	4.79815
2812.12	5.13791
2814.77	5.45393
2817.42	6.581
2820.07	9.61583
2822.72	13.7132
2825.37	18.8408
2828.02	24.3875
2830.67	31.3095
2833.31	38.535
2835.96	46.2604
2838.61	55.0573
2841.25	63.7148
2843.89	74.4174
2846.53	84.8513
2849.17	98.2148
2851.81	111.879
2854.45	127.198
2857.09	141.444
2859.73	154.941
2862.36	168.129
2865	180.536
2867.64	190.467
2870.27	200.381
2872.9	209.454
2875.53	217.002
2878.16	223.573
2880.79	230.784
2883.42	238.798
2886.05	245.456
2888.68	251.695
2891.3	258.807
2893.93	265.361
2896.55	271.877
2899.18	281.516
2901.8	292.005
2904.42	303.117
2907.04	315.261
2909.66	328.965
2912.28	344.446
2914.9	360.441
2917.51	375.48
2920.13	388.312
2922.74	397.985
2925.36	406.999
2927.97	412.249
2930.59	413.05
2933.2	411.644
2935.81	408.772
2938.42	401.474
2941.02	391.163
2943.63	379.871
2946.24	364.942
2948.85	349.769
2951.45	333.822
2954.05	316.558
2956.66	299.64
2959.26	282.616
2961.86	267.874
2964.46	254.012
2967.06	239.781
2969.66	226.844
2972.26	214.565
2974.85	203.577
2977.45	192.859
2980.05	181.753
2982.64	170.592
2985.23	158.747
2987.83	147.415
2990.42	135.492
2993.01	122.758
2995.6	111.303
2998.19	99.6304
3000.77	87.6188
3003.36	76.0793
3005.95	64.3299
3008.53	53.4072
3011.12	43.2827
3013.7	34.3817
3016.28	28.0332
3018.86	21.8233
3021.44	17.3289
3024.02	14.2779
3026.6	11.4676
3029.18	9.1645
3031.76	8.62541
3034.33	8.62299
3036.91	9.26424
3039.48	9.30867
3042.05	10.0804
3044.63	10.9388
3047.2	11.6109
3049.77	11.8691
3052.34	11.9495
3054.91	12.5514
3057.48	12.8231
3060.04	11.9168
3062.61	10.3668
3065.17	8.97754
3067.74	6.87389
3070.3	6.02294
3072.87	5.0295
3075.43	4.03893
3077.99	3.91728
3080.55	3.25153
3083.11	0.921977
3085.67	0.98564
3088.22	-0.262717
3090.78	-0.815322
3093.34	-0.282515
3095.89	0.556313
3098.44	0.959748
3101	1.24717
3103.55	1.36451
3106.1	2.30095
3108.65	3.69556
3111.2	5.43937
3113.75	7.23102
3116.3	8.78258
3118.84	10.6072
3121.39	11.3488
3123.93	12.9425
3126.48	14.4739
3129.02	16.152
3131.56	18.7585
3134.1	20.5113
3136.64	22.8686
3139.18	23.6608
3141.72	24.1049
3144.26	24.2945
3146.8	24.7827
3149.33	25.446