File: data/Raman/poly_smoothed/Mbcal_20_25_18_1x_45s_532 nm_x100_100%_600 gr_mm_01.txt
#Acq. time (s)=	45
#Accumulations=	2
#Range (cm-¹)=	200...3150
#Windows=	2
#Auto scanning=	Off
#Autofocus=	Off
#Macrospot=	Off
#AutoExposure=	Off
#Spike filter=	Multiple accum.
#Delay time (s)=	0
#Binning=	1
#Readout mode=	Signal
#DeNoise=	Off
#ICS correction=	On
#Dark correction=	Off
#Inst. Process=	Off
#Detector Gain=	Best Dynamic Range
#Detector ADC=	20 kHz
#Detector temperature (°C)=	-69.85
#Instrument=	LabRAM HR Evol
#Detector=	Synapse
#Objective=	x100
#Grating=	600 gr/mm
#ND Filter=	100%
#Laser (nm)=	532
#Hole=	100.021
#Range=	Auto
#Laser Pol.=	No
#Raman. Pol.=	No
#Laser Pol. (°)=	-0.0007625
#Raman Pol. (°)=	89.9995
#Collection=	Microscope
#StageXY=	Marzhauser
#StageZ=	Marzhauser
#X (µm)=	-1157.4
#Y (µm)=	1258.2
#Z (µm)=	578
#Full time(mm:ss)=	3:18
#Project=
#Sample=
#Site=
#Title=	Mbcal_20_25_18_2x_45s_532 nm_x100_100%_600 gr_mm
#Remark=
#Date=	18.07.2022 10:42
#Acquired=	18.07.2022 10:42:50
#Base:Fit=	10.08.2022 10:55:08
#Base:Sub=	10.08.2022 10:55:14
#Filter:Polynom=	16.08.2022 10:07:28
#AxisType[0]=Intens
#AxisUnit[0]=Cnt
#AxisType[1]=Spectr
#AxisUnit[1]=1/cm
200.419	2.464
204.048	3.51985
207.678	2.90812
211.304	2.78907
214.928	3.70056
218.554	4.59035
222.176	4.20154
225.798	4.87738
229.417	5.05107
233.035	4.44739
236.653	6.01811
240.268	6.49499
243.881	7.36565
247.493	7.47329
251.103	7.757
254.715	8.65895
258.322	10.139
261.929	9.07494
265.534	10.1789
269.137	10.5364
272.739	11.3192
276.34	11.6658
279.939	11.2656
283.537	9.86408
287.134	9.24706
290.729	9.38706
294.323	8.41914
297.913	9.66192
301.504	9.64336
305.093	10.1729
308.682	10.3211
312.268	11.9585
315.852	13.2759
319.436	12.9624
323.018	15.7453
326.597	17.1006
330.177	18.2577
333.753	18.3198
337.331	17.8826
340.906	17.4396
344.478	18.6989
348.051	18.2441
351.621	16.9039
355.189	15.9535
358.757	16.034
362.323	14.8253
365.889	13.9695
369.451	13.0449
373.012	11.3177
376.574	9.782
380.133	8.60168
383.69	8.10274
387.245	7.064
390.8	6.8342
394.353	6.49749
397.906	5.87893
401.456	5.26907
405.005	5.46187
408.552	4.42458
412.099	4.17421
415.643	3.56233
419.187	2.30132
422.728	1.72484
426.269	1.83395
429.806	3.0155
433.344	2.21525
436.881	1.78003
440.416	0.810294
443.949	1.87607
447.48	3.15347
451.011	3.52731
454.541	3.68731
458.069	5.29131
461.594	4.11744
465.119	6.51498
468.642	8.83221
472.165	9.28601
475.684	12.0109
479.204	13.2893
482.721	14.8295
486.239	15.9823
489.753	17.5606
493.268	18.3402
496.779	19.5648
500.289	21.12
503.8	22.5093
507.307	23.8842
510.813	24.4974
514.32	26.1957
517.823	25.4596
521.325	25.1883
524.826	25.0648
528.325	24.1352
531.823	24.7156
535.32	22.9901
538.815	21.1383
542.309	20.0003
545.802	18.8932
549.293	17.2709
552.783	17.1065
556.271	14.8072
559.759	11.3874
563.245	10.5656
566.729	9.14443
570.213	7.15859
573.693	5.4733
577.173	4.21611
580.652	4.4867
584.13	5.06612
587.605	2.22733
591.08	3.27988
594.552	3.07169
598.025	3.43054
601.496	3.26945
604.964	3.8319
608.433	4.89456
611.898	4.39293
615.364	5.91524
618.827	4.98077
622.288	4.75025
625.75	4.94177
629.209	6.76452
632.667	8.29252
636.125	8.79753
639.58	8.48176
643.033	7.97835
646.485	9.11866
649.936	11.1251
653.388	10.743
656.836	10.3897
660.283	10.4629
663.728	10.5738
667.173	9.92432
670.616	10.0555
674.057	9.38137
677.498	10.6658
680.937	10.1357
684.375	9.3062
687.809	9.32627
691.244	10.6233
694.678	11.4072
698.111	12.4938
701.54	11.798
704.97	13.0433
708.398	15.7002
711.826	17.0807
715.25	18.3269
718.675	17.8012
722.096	19.2453
725.518	19.8913
728.937	21.5111
732.357	23.7502
735.773	24.7803
739.19	26.5584
742.604	28.4361
746.018	32.157
749.429	33.5303
752.839	35.4591
756.248	37.1549
759.657	37.721
763.063	39.2981
766.468	40.9052
769.871	42.3448
773.273	45.8165
776.676	48.8552
780.075	50.1195
783.474	50.2601
786.871	53.1098
790.266	55.738
793.661	56.8897
797.054	58.0446
800.446	59.0662
803.834	59.8351
807.224	60.802
810.612	60.4652
813.998	60.6139
817.384	61.5209
820.766	61.8462
824.149	62.1452
827.531	63.7931
830.909	66.0554
834.288	67.9709
837.666	71.7484
841.041	73.719
844.416	77.1096
847.788	78.1694
851.161	77.9363
854.53	79.1228
857.901	78.6315
861.268	78.1359
864.633	75.9385
868	73.8461
871.363	72.7955
874.725	68.888
878.088	65.35
881.447	62.0429
884.805	56.5907
888.162	51.2526
891.518	47.9019
894.872	44.9165
898.225	41.7448
901.577	39.3258
904.928	38.3295
908.277	40.6434
911.625	43.0027
914.972	44.9137
918.318	46.398
921.662	48.0065
925.005	47.2598
928.347	47.0876
931.686	44.5692
935.025	42.6644
938.363	41.3034
941.698	41.5527
945.034	41.4707
948.368	38.8046
951.699	38.2269
955.031	36.4633
958.36	34.5726
961.689	34.3882
965.016	33.2981
968.343	32.8266
971.666	33.1097
974.991	33.4692
978.312	33.2639
981.632	32.7799
984.953	32.5974
988.27	33.3084
991.587	33.2714
994.902	31.9691
998.216	30.571
1001.53	28.6436
1004.84	27.6252
1008.15	26.0026
1011.46	24.6189
1014.77	24.7623
1018.07	28.5717
1021.38	29.5346
1024.68	31.1148
1027.99	31.6389
1031.29	32.0234
1034.59	32.3327
1037.89	30.5553
1041.18	32.4606
1044.48	33.2833
1047.77	35.2621
1051.07	36.8199
1054.36	37.0776
1057.65	36.7002
1060.94	35.2948
1064.23	33.589
1067.52	33.1123
1070.8	32.8395
1074.09	31.2827
1077.37	27.6516
1080.65	25.0813
1083.93	23.5552
1087.21	23.2132
1090.49	22.8283
1093.77	24.6535
1097.04	24.0984
1100.32	24.1737
1103.59	24.5612
1106.86	23.6826
1110.13	22.7794
1113.4	21.9886
1116.67	21.6292
1119.94	21.457
1123.2	21.7694
1126.47	21.9097
1129.73	20.6988
1132.99	18.2453
1136.25	17.171
1139.51	16.4457
1142.77	14.553
1146.03	15.2913
1149.28	12.7313
1152.54	10.3118
1155.79	7.08596
1159.04	5.02977
1162.29	2.82663
1165.54	1.23441
1168.79	0.772754
1172.04	0.0689067
1175.28	0.0994249
1178.53	1.55465
1181.77	1.87865
1185.01	2.13448
1188.25	2.41748
1191.49	5.54874
1194.73	7.97644
1197.96	10.2561
1201.2	13.3144
1204.43	14.9102
1207.66	16.4698
1210.9	18.2805
1214.13	21.814
1217.36	25.8323
1220.58	29.1892
1223.81	32.8763
1227.04	35.8949
1230.26	39.0592
1233.48	41.9608
1236.71	44.3479
1239.93	46.8493
1243.14	49.6845
1246.36	53.6076
1249.58	55.2696
1252.8	55.1982
1256.01	57.0969
1259.22	55.998
1262.43	55.1991
1265.64	57.0861
1268.85	58.1508
1272.06	60.0253
1275.27	60.5826
1278.48	61.1423
1281.68	61.0854
1284.88	61.1498
1288.08	62.1006
1291.28	63.0794
1294.48	64.2801
1297.68	65.5135
1300.88	67.76
1304.07	68.7673
1307.27	69.2221
1310.46	71.2377
1313.65	71.9545
1316.85	72.9597
1320.03	74.6563
1323.22	74.1771
1326.41	72.8709
1329.6	70.159
1332.78	69.0042
1335.96	66.6933
1339.15	64.5701
1342.33	63.6601
1345.51	63.0694
1348.69	61.5218
1351.86	61.3626
1355.04	59.197
1358.21	58.4006
1361.39	56.5327
1364.56	56.3471
1367.73	55.4611
1370.9	54.8153
1374.07	55.9256
1377.24	54.851
1380.41	55.1058
1383.57	55.0448
1386.73	55.4736
1389.9	56.0922
1393.06	56.9713
1396.22	57.2755
1399.38	57.4526
1402.54	59.1299
1405.69	60.5103
1408.85	62.8567
1412	64.7119
1415.16	68.3454
1418.31	72.8271
1421.46	76.6212
1424.61	82.0203
1427.76	88.3105
1430.9	93.7995
1434.05	99.1556
1437.2	103.673
1440.34	108.239
1443.48	111.097
1446.62	113.63
1449.76	114.807
1452.9	115.068
1456.04	113.614
1459.17	110.775
1462.31	106.594
1465.44	102.052
1468.58	97.3059
1471.71	90.2844
1474.84	83.0742
1477.97	76.5642
1481.1	69.5766
1484.22	63.7048
1487.35	57.4387
1490.47	52.0179
1493.59	46.6248
1496.72	41.7142
1499.84	37.9739
1502.96	36.1216
1506.08	32.4906
1509.19	30.0134
1512.31	27.4533
1515.42	25.2948
1518.54	23.2064
1521.65	22.1032
1524.76	21.3149
1527.87	21.3097
1530.98	21.4441
1534.09	20.1358
1537.2	21.1605
1540.3	23.2637
1543.41	25.2785
1546.51	27.4277
1549.61	27.8423
1552.71	30.1107
1555.81	32.5978
1558.91	35.4585
1562.01	37.0312
1565.1	38.6082
1568.2	40.6516
1571.29	41.7502
1574.38	44.2186
1577.48	46.2037
1580.57	49.872
1583.65	51.4965
1586.74	52.6594
1589.83	55.6157
1592.92	55.447
1596	56.7917
1599.08	56.2141
1602.16	56.6338
1605.24	56.9039
1608.32	56.0197
1611.4	57.5243
1614.48	57.0113
1617.56	56.9078
1620.63	56.0229
1623.71	56.866
1626.78	58.4529
1629.85	58.0385
1632.92	60.2718
1635.99	62.5033
1639.06	62.515
1642.12	64.4685
1645.19	64.5155
1648.25	66.4046
1651.32	69.4125
1654.38	70.5913
1657.44	72.4004
1660.5	71.9144
1663.56	70.6841
1666.62	69.4141
1669.67	66.9343
1672.73	62.4506
1675.79	58.4482
1678.84	54.1729
1681.89	49.2149
1684.94	45.6109
1687.99	39.7612
1691.04	35.2337
1694.08	30.433
1697.13	26.99
1700.18	23.8818
1703.22	19.8473
1706.26	16.9493
1709.3	14.7193
1712.35	11.3379
1715.39	9.34299
1718.42	7.01838
1721.46	5.62007
1724.5	6.41197
1727.53	6.30307
1730.56	5.64037
1733.6	5.23465
1736.63	4.47355
1739.66	4.64487
1742.69	3.73551
1745.71	2.53138
1748.74	1.99663
1751.77	2.42494
1754.79	3.09425
1757.81	3.14904
1760.84	2.86175
1763.86	1.92437
1766.88	2.04373
1769.9	2.97987
1772.91	2.75536
1775.93	3.29336
1778.95	3.95965
1781.96	4.18857
1784.97	4.95177
1787.99	5.77124
1791	5.72486
1794.01	6.81524
1797.01	6.17486
1800.02	7.41129
1803.03	7.09725
1806.03	7.2417
1809.04	6.01883
1812.04	5.91044
1815.04	5.03403
1818.04	4.30962
1821.04	3.80153
1824.04	3.3125
1827.04	3.30751
1830.03	3.18101
1833.03	2.7787
1836.02	2.35013
1839.02	1.5715
1842.01	1.70705
1845	1.3601
1847.99	1.26017
1850.98	1.4587
1853.96	2.66034
1856.95	3.55754
1859.94	4.1593
1862.92	3.7229
1865.9	3.35679
1868.88	4.05696
1871.86	3.4618
1874.84	4.10144
1877.82	3.19647
1880.8	3.62426
1882.58	3.18739
1885.57	3.86469
1888.56	3.71546
1891.54	4.5546
1894.53	4.42329
1897.51	4.71864
1900.5	5.01712
1903.48	5.2763
1906.46	6.16246
1909.44	5.17008
1912.42	5.11038
1915.4	4.918
1918.37	6.33106
1921.35	6.90552
1924.32	6.58469
1927.3	5.06694
1930.27	4.28495
1933.24	2.91396
1936.21	2.71446
1939.18	2.6776
1942.15	2.38573
1945.11	0.960556
1948.08	1.23388
1951.04	1.02248
1954.01	0.632355
1956.97	0.385339
1959.93	1.08281
1962.89	0.881732
1965.85	1.4831
1968.81	1.47091
1971.77	2.55615
1974.72	3.26733
1977.68	3.93066
1980.63	4.72228
1983.58	5.16528
1986.53	5.84102
1989.48	6.69119
1992.43	6.06344
1995.38	5.94531
1998.33	5.14596
2001.27	6.58314
2004.22	7.62542
2007.16	8.71012
2010.11	9.76099
2013.05	9.46154
2015.99	8.74438
2018.93	8.04623
2021.87	8.65632
2024.8	8.57272
2027.74	8.43348
2030.68	8.87169
2033.61	9.56387
2036.54	10.1322
2039.48	10.5898
2042.41	10.6141
2045.34	10.2509
2048.27	9.5412
2051.19	9.572
2054.12	8.05649
2057.05	8.28174
2059.97	8.33181
2062.9	8.57799
2065.82	8.76383
2068.74	8.99664
2071.66	9.67366
2074.58	10.3666
2077.5	11.0667
2080.41	10.9992
2083.33	11.3482
2086.24	11.397
2089.16	11.7599
2092.07	13.1347
2094.98	13.8689
2097.89	14.3516
2100.8	15.3556
2103.71	17.9774
2106.62	19.095
2109.53	20.9075
2112.43	21.9945
2115.33	22.4637
2118.24	23.6484
2121.14	24.2665
2124.04	25.0476
2126.94	27.1954
2129.84	29.3025
2132.74	31.5433
2135.63	33.5275
2138.53	35.6096
2141.43	37.701
2144.32	39.9741
2147.21	41.8441
2150.1	44.173
2152.99	46.7293
2155.88	49.3833
2158.77	51.989
2161.66	54.6188
2164.55	56.721
2167.43	58.5018
2170.31	60.5529
2173.2	61.1911
2176.08	63.1915
2178.96	62.702
2181.84	62.5497
2184.72	60.6987
2187.6	58.9194
2190.47	56.133
2193.35	53.8993
2196.23	52.654
2199.1	50.3427
2201.97	47.2007
2204.84	45.0606
2207.71	42.639
2210.58	39.535
2213.45	36.7326
2216.32	34.1174
2219.19	31.2727
2222.05	29.9053
2224.92	28.7147
2227.78	26.6692
2230.64	25.0577
2233.5	23.7454
2236.36	22.4382
2239.22	20.7013
2242.08	19.185
2244.94	18.2654
2247.79	16.7716
2250.65	14.2276
2253.5	12.4844
2256.36	11.2581
2259.21	9.76301
2262.06	8.98738
2264.91	9.19248
2267.76	8.84828
2270.6	7.24558
2273.45	8.47965
2276.3	9.43216
2279.14	9.5504
2281.98	8.32667
2284.83	8.40183
2287.67	9.46106
2290.51	8.88834
2293.35	7.85888
2296.19	7.63461
2299.02	9.02777
2301.86	10.2517
2304.7	11.7491
2307.53	12.5521
2310.36	13.3153
2313.2	12.7492
2316.03	13.2569
2318.86	12.3393
2321.69	12.3433
2324.51	12.2873
2327.34	11.6453
2330.17	11.7321
2332.99	10.1314
2335.82	9.04055
2338.64	8.49262
2341.46	6.86882
2344.28	7.01514
2347.1	6.21052
2349.92	4.82906
2352.74	4.76435
2355.56	4.2292
2358.37	3.5863
2361.19	1.92063
2364	3.43384
2366.82	4.29358
2369.63	4.37016
2372.44	4.53553
2375.25	4.48577
2378.06	5.38956
2380.86	5.23285
2383.67	4.12612
2386.48	3.85572
2389.28	4.49104
2392.09	4.895
2394.89	5.16308
2397.69	4.03706
2400.49	3.60362
2403.29	3.39529
2406.09	4.2388
2408.89	4.46032
2411.69	4.51748
2414.48	5.65915
2417.28	5.29517
2420.07	5.99207
2422.86	6.16412
2425.65	6.11563
2428.45	5.58593
2431.23	5.46727
2434.02	4.63725
2436.81	4.05783
2439.6	4.68683
2442.38	4.83796
2445.17	4.59907
2447.95	4.63192
2450.73	4.95094
2453.52	5.02206
2456.3	5.56502
2459.08	6.16853
2461.85	6.75844
2464.63	7.68364
2467.41	7.7391
2470.19	9.43914
2472.96	9.46782
2475.73	9.19701
2478.51	8.92741
2481.28	8.89398
2484.05	8.064
2486.82	7.7394
2489.59	6.92891
2492.35	6.96882
2495.12	6.11507
2497.89	5.66858
2500.65	5.39041
2503.42	4.83573
2506.18	3.84809
2508.94	2.92694
2511.7	1.86939
2514.46	1.0222
2517.22	0.898365
2519.98	0.483933
2522.73	1.27185
2525.49	1.61048
2528.25	2.58542
2531	2.98824
2533.75	4.0623
2536.5	3.90841
2539.25	4.01509
2542.01	3.8653
2544.75	4.43579
2547.5	4.6964
2550.25	5.49983
2553	5.25363
2555.74	6.74884
2558.49	7.23386
2561.23	7.70632
2563.97	7.4745
2566.71	7.85002
2569.45	7.68193
2572.19	6.2666
2574.93	5.17893
2577.67	4.39228
2580.4	3.13155
2583.14	3.132
2585.87	3.42487
2588.6	3.59714
2591.34	3.53128
2594.07	2.35906
2596.8	2.03657
2599.53	1.81951
2602.26	1.72685
2604.98	1.61749
2607.71	2.25468
2610.44	2.70472
2613.16	3.41532
2615.88	3.78793
2618.61	4.79573
2621.33	5.29843
2624.05	6.29841
2626.77	6.54822
2629.49	7.37787
2632.21	7.78499
2634.92	8.13177
2637.64	7.7667
2640.35	7.76632
2643.07	7.81505
2645.78	8.08653
2648.49	8.37791
2651.2	8.54743
2653.91	8.82762
2656.62	7.80949
2659.33	6.61847
2662.04	6.87029
2664.74	6.71314
2667.45	6.48361
2670.15	5.81256
2672.86	6.32294
2675.56	6.22409
2678.26	5.57085
2680.96	4.6457
2683.66	4.48923
2686.36	4.69603
2689.06	4.45356
2691.75	3.9168
2694.45	3.49404
2697.14	3.31573
2699.84	4.3721
2702.53	5.23345
2705.22	5.54421
2707.91	5.98293
2710.6	6.16104
2713.29	6.82907
2715.98	7.64245
2718.67	8.03695
2721.35	8.72326
2724.04	8.70663
2726.72	9.83545
2729.4	10.3324
2732.09	10.2389
2734.77	10.1414
2737.45	10.1581
2740.13	9.39032
2742.81	8.6057
2745.48	7.29592
2748.16	6.11398
2750.84	5.24928
2753.51	5.0527
2756.19	3.76239
2758.86	2.37008
2761.53	2.03631
2764.2	1.48079
2766.87	1.33719
2769.54	0.38239
2772.21	-0.468789
2774.88	-0.65438
2777.54	-0.203435
2780.21	-0.101747
2782.87	-0.434512
2785.53	0.0345367
2788.2	-0.294271
2790.86	0.122945
2793.52	0.403082
2796.18	0.141508
2798.84	0.823028
2801.49	-0.565811
2804.15	-0.933509
2806.81	-1.34511
2809.46	-2.62598
2812.12	-2.97281
2814.77	-2.3594
2817.42	-0.480425
2820.07	1.91276
2822.72	5.85376
2825.37	10.3717
2828.02	15.3874
2830.67	21.7482
2833.31	27.896
2835.96	33.7732
2838.61	41.3527
2841.25	49.7671
2843.89	59.3032
2846.53	68.8252
2849.17	79.8294
2851.81	90.6896
2854.45	102.067
2857.09	114.2
2859.73	124.754
2862.36	135.669
2865	145.813
2867.64	154.32
2870.27	162.697
2872.9	170.691
2875.53	178.327
2878.16	184.226
2880.79	191.212
2883.42	197.309
2886.05	203.51
2888.68	208.97
2891.3	213.856
2893.93	218.863
2896.55	225.413
2899.18	231.486
2901.8	240.36
2904.42	251.085
2907.04	262.479
2909.66	275.615
2912.28	288.496
2914.9	303.248
2917.51	317.092
2920.13	330.193
2922.74	340.754
2925.36	349.11
2927.97	354.435
2930.59	356.197
2933.2	354.668
2935.81	351.124
2938.42	344.336
2941.02	333.866
2943.63	320.674
2946.24	306.649
2948.85	290.855
2951.45	274.426
2954.05	257.071
2956.66	241.041
2959.26	225.65
2961.86	211.768
2964.46	198.809
2967.06	188.094
2969.66	177.791
2972.26	169.081
2974.85	161.309
2977.45	154.187
2980.05	147.268
2982.64	139.525
2985.23	130.903
2987.83	121.406
2990.42	110.907
2993.01	101.025
2995.6	90.2897
2998.19	80.3708
3000.77	70.1332
3003.36	59.4242
3005.95	49.2641
3008.53	40.3606
3011.12	32.0599
3013.7	25.004
3016.28	18.9058
3018.86	14.0152
3021.44	9.7822
3024.02	6.51844
3026.6	4.98217
3029.18	3.73312
3031.76	3.02035
3034.33	2.61603
3036.91	3.60848
3039.48	4.92751
3042.05	6.34118
3044.63	6.78624
3047.2	7.66132
3049.77	7.60898
3052.34	8.13191
3054.91	8.73584
3057.48	8.68437
3060.04	8.4666
3062.61	8.04429
3065.17	7.06955
3067.74	5.46448
3070.3	4.81925
3072.87	3.83866
3075.43	2.23094
3077.99	1.80094
3080.55	0.891016
3083.11	0.597466
3085.67	0.139921
3088.22	-0.135322
3090.78	0.355338
3093.34	-0.258328
3095.89	0.408598
3098.44	0.747657
3101	1.02291
3103.55	1.50973
3106.1	2.1649
3108.65	2.85927
3111.2	3.21735
3113.75	3.71285
3116.3	4.64675
3118.84	4.20119
3121.39	5.01943
3123.93	5.63625
3126.48	6.1283
3129.02	6.99391
3131.56	8.02979
3134.1	9.89991
3136.64	10.9219
3139.18	13.1631
3141.72	15.7377
3144.26	18.5269
3146.8	21.3888
3149.33	23.8251