File: data/Raman/poly_smoothed/Mbcal_20_25_23_1x_45s_532 nm_x100_100%_600 gr_mm_02.txt
#Acq. time (s)=	45
#Accumulations=	2
#Range (cm-¹)=	200...3150
#Windows=	2
#Auto scanning=	Off
#Autofocus=	Off
#Macrospot=	Off
#AutoExposure=	Off
#Spike filter=	Multiple accum.
#Delay time (s)=	0
#Binning=	1
#Readout mode=	Signal
#DeNoise=	Off
#ICS correction=	On
#Dark correction=	Off
#Inst. Process=	Off
#Detector Gain=	Best Dynamic Range
#Detector ADC=	20 kHz
#Detector temperature (°C)=	-69.85
#Instrument=	LabRAM HR Evol
#Detector=	Synapse
#Objective=	x100
#Grating=	600 gr/mm
#ND Filter=	100%
#Laser (nm)=	532
#Hole=	100.021
#Range=	Auto
#Laser Pol.=	No
#Raman. Pol.=	No
#Laser Pol. (°)=	-0.0007625
#Raman Pol. (°)=	89.9995
#Collection=	Microscope
#StageXY=	Marzhauser
#StageZ=	Marzhauser
#X (µm)=	-1177.1
#Y (µm)=	1309.2
#Z (µm)=	578.3
#Full time(mm:ss)=	3:09
#Project=
#Sample=
#Site=
#Title=	Mbcal_20_25_23_2x_45s_532 nm_x100_100%_600 gr_mm
#Remark=
#Date=	18.07.2022 11:20
#Acquired=	18.07.2022 11:20:19
#Base:Fit=	10.08.2022 10:55:08
#Base:Sub=	10.08.2022 10:55:14
#Filter:Polynom=	16.08.2022 10:07:28
#AxisType[0]=Intens
#AxisUnit[0]=Cnt
#AxisType[1]=Spectr
#AxisUnit[1]=1/cm
200.419	8.96306
204.048	10.4267
207.678	8.60235
211.304	7.04386
214.928	5.68512
218.554	4.44185
222.176	4.61049
225.798	2.79924
229.417	2.67653
233.035	2.87524
236.653	1.39015
240.268	1.60813
243.881	3.96237
247.493	3.62853
251.103	3.56157
254.715	4.46201
258.322	6.60244
261.929	8.14516
265.534	9.58338
269.137	10.5288
272.739	9.99797
276.34	10.6092
279.939	12.0678
283.537	11.4263
287.134	12.0894
290.729	12.5671
294.323	13.6963
297.913	14.7759
301.504	16.7362
305.093	17.9044
308.682	18.6067
312.268	18.4109
315.852	18.8571
319.436	18.4886
323.018	18.2034
326.597	19.2099
330.177	20.663
333.753	20.969
337.331	20.5719
340.906	21.0596
344.478	22.6767
348.051	22.2793
351.621	20.8152
355.189	18.8932
358.757	19.0304
362.323	17.9491
365.889	16.5453
369.451	16.2265
373.012	15.61
376.574	16.2491
380.133	16.8837
383.69	15.4468
387.245	15.5425
390.8	15.3323
394.353	13.9053
397.906	13.4518
401.456	12.7518
405.005	12.7756
408.552	11.9372
412.099	10.3114
415.643	10.2979
419.187	10.8137
422.728	10.4185
426.269	9.57631
429.806	8.46602
433.344	7.61735
436.881	5.78336
440.416	5.1141
443.949	4.97586
447.48	5.42847
451.011	5.96999
454.541	5.98728
458.069	6.27379
461.594	5.91173
465.119	6.22074
468.642	5.05645
472.165	5.92273
475.684	7.6666
479.204	9.10398
482.721	10.6356
486.239	11.5329
489.753	12.728
493.268	12.4345
496.779	12.2972
500.289	13.5065
503.8	14.9059
507.307	14.1976
510.813	14.4229
514.32	14.7336
517.823	15.4464
521.325	15.3231
524.826	16.4551
528.325	16.3299
531.823	16.7272
535.32	16.198
538.815	16.2898
542.309	14.9273
545.802	13.4915
549.293	11.6509
552.783	10.6604
556.271	10.1182
559.759	10.3764
563.245	10.0345
566.729	9.20049
570.213	7.43867
573.693	6.0048
577.173	4.93975
580.652	4.37298
584.13	3.20798
587.605	3.28425
591.08	2.47608
594.552	2.75309
598.025	1.7443
601.496	1.74996
604.964	1.18254
608.433	1.6553
611.898	0.834269
615.364	1.92851
618.827	0.911335
622.288	1.03171
625.75	1.95659
629.209	2.16348
632.667	2.34393
636.125	2.71521
639.58	4.11405
643.033	5.0112
646.485	5.94897
649.936	6.6518
653.388	6.43058
656.836	6.40337
660.283	6.91222
663.728	8.88355
667.173	10.5233
670.616	10.7876
674.057	10.698
677.498	11.1389
680.937	12.8855
684.375	13.5676
687.809	14.9052
691.244	15.406
694.678	16.2198
698.111	17.9763
701.54	19.8455
704.97	21.2858
708.398	23.3388
711.826	26.0486
715.25	27.0251
718.675	28.2703
722.096	29.4325
725.518	30.2723
728.937	31.2551
732.357	31.6689
735.773	33.6233
739.19	34.2294
742.604	35.4668
746.018	38.695
749.429	41.4314
752.839	43.3426
756.248	44.7642
759.657	45.9238
763.063	48.437
766.468	50.8507
769.871	52.7962
773.273	55.0268
776.676	56.9869
780.075	60.0971
783.474	61.8785
786.871	63.6031
790.266	65.101
793.661	67.1441
797.054	67.6572
800.446	67.9469
803.834	68.3114
807.224	68.6946
810.612	68.3872
813.998	68.8965
817.384	67.3812
820.766	66.749
824.149	65.7
827.531	66.6394
830.909	66.5504
834.288	68.1441
837.666	66.1265
841.041	66.8442
844.416	68.3297
847.788	68.8972
851.161	67.4888
854.53	66.6096
857.901	64.2334
861.268	63.0808
864.633	62.6175
868	60.1038
871.363	58.1008
874.725	56.9437
878.088	53.1305
881.447	51.0648
884.805	47.6419
888.162	44.2012
891.518	42.4467
894.872	40.3073
898.225	39.5855
901.577	37.5293
904.928	37.8432
908.277	39.0583
911.625	40.4259
914.972	41.2807
918.318	41.7459
921.662	42.1066
925.005	43.0357
928.347	41.6356
931.686	39.6412
935.025	39.0104
938.363	37.8228
941.698	36.5356
945.034	35.5424
948.368	34.0364
951.699	32.0762
955.031	30.5956
958.36	28.1724
961.689	25.845
965.016	23.6073
968.343	21.7776
971.666	21.5014
974.991	21.4266
978.312	21.172
981.632	21.4108
984.953	21.4627
988.27	21.5958
991.587	21.5116
994.902	20.278
998.216	19.6063
1001.53	17.4788
1004.84	16.5303
1008.15	15.1704
1011.46	13.8837
1014.77	14.0952
1018.07	13.5208
1021.38	13.7165
1024.68	14.2149
1027.99	14.591
1031.29	15.4042
1034.59	14.9658
1037.89	16.4498
1041.18	17.4692
1044.48	19.1667
1047.77	19.0613
1051.07	18.3637
1054.36	18.9053
1057.65	19.7969
1060.94	20.7375
1064.23	20.7129
1067.52	20.8723
1070.8	20.8289
1074.09	20.0282
1077.37	19.0918
1080.65	17.8483
1083.93	16.2905
1087.21	16.0527
1090.49	16.2083
1093.77	17.5494
1097.04	15.7157
1100.32	16.1815
1103.59	17.8018
1106.86	16.5134
1110.13	16.7469
1113.4	17.9937
1116.67	18.5103
1119.94	18.8418
1123.2	17.502
1126.47	15.8298
1129.73	14.2676
1132.99	13.5631
1136.25	14.1615
1139.51	12.0699
1142.77	11.09
1146.03	11.1568
1149.28	10.4431
1152.54	7.5707
1155.79	6.07756
1159.04	5.66272
1162.29	4.4816
1165.54	3.20577
1168.79	2.36065
1172.04	1.59383
1175.28	1.21845
1178.53	1.66823
1181.77	1.91848
1185.01	2.12504
1188.25	2.65237
1191.49	4.72372
1194.73	4.95458
1197.96	7.05668
1201.2	9.06887
1204.43	10.8475
1207.66	14.3063
1210.9	16.1164
1214.13	17.287
1217.36	19.3869
1220.58	19.3125
1223.81	20.3562
1227.04	20.6463
1230.26	20.5295
1233.48	21.0284
1236.71	22.1398
1239.93	22.0289
1243.14	22.0571
1246.36	22.4217
1249.58	22.4525
1252.8	23.4585
1256.01	23.3887
1259.22	23.712
1262.43	24.7437
1265.64	25.7888
1268.85	27.5304
1272.06	28.5452
1275.27	29.7681
1278.48	33.2382
1281.68	33.6813
1284.88	35.5108
1288.08	36.5519
1291.28	37.6188
1294.48	38.7831
1297.68	40.261
1300.88	41.5865
1304.07	42.1257
1307.27	43.686
1310.46	44.6534
1313.65	46.6354
1316.85	47.0073
1320.03	49.1807
1323.22	48.7711
1326.41	49.4342
1329.6	49.4651
1332.78	48.9902
1335.96	50.1178
1339.15	49.7156
1342.33	48.7771
1345.51	47.3456
1348.69	46.5094
1351.86	46.0135
1355.04	45.1301
1358.21	44.4398
1361.39	42.4985
1364.56	42.0937
1367.73	41.5692
1370.9	41.7414
1374.07	40.5374
1377.24	40.4533
1380.41	39.33
1383.57	38.5079
1386.73	38.466
1389.9	38.6092
1393.06	38.6417
1396.22	38.16
1399.38	37.9027
1402.54	38.3186
1405.69	38.2951
1408.85	38.9154
1412	40.7946
1415.16	42.2704
1418.31	44.7325
1421.46	46.4192
1424.61	48.9795
1427.76	51.6615
1430.9	55.1807
1434.05	57.2461
1437.2	59.1176
1440.34	61.4206
1443.48	63.5743
1446.62	64.8578
1449.76	66.2796
1452.9	66.7219
1456.04	65.2561
1459.17	63.2776
1462.31	61.7133
1465.44	61.2819
1468.58	59.5257
1471.71	56.8743
1474.84	53.4073
1477.97	51.1686
1481.1	48.5613
1484.22	44.5314
1487.35	42.1026
1490.47	40.0942
1493.59	38.3168
1496.72	35.5341
1499.84	33.155
1502.96	31.3114
1506.08	30.0753
1509.19	29.047
1512.31	26.7282
1515.42	25.1313
1518.54	24.7541
1521.65	24.0777
1524.76	24.2804
1527.87	24.4356
1530.98	23.2766
1534.09	21.7003
1537.2	20.9642
1540.3	22.3295
1543.41	22.3614
1546.51	21.9202
1549.61	21.8628
1552.71	23.3412
1555.81	24.3269
1558.91	24.1089
1562.01	24.6068
1565.1	25.2581
1568.2	25.6467
1571.29	26.5236
1574.38	26.5421
1577.48	29.1533
1580.57	31.3909
1583.65	32.5845
1586.74	34.8295
1589.83	37.2431
1592.92	38.8238
1596	39.7522
1599.08	40.7145
1602.16	40.4668
1605.24	39.9255
1608.32	37.7621
1611.4	36.6632
1614.48	35.2318
1617.56	33.7819
1620.63	32.1335
1623.71	32.071
1626.78	31.1186
1629.85	30.5277
1632.92	29.5734
1635.99	28.3332
1639.06	29.0858
1642.12	29.1735
1645.19	29.4541
1648.25	31.3385
1651.32	32.7291
1654.38	33.8424
1657.44	33.4561
1660.5	33.9467
1663.56	34.1665
1666.62	34.382
1669.67	32.9584
1672.73	30.9568
1675.79	28.9933
1678.84	27.0145
1681.89	24.2791
1684.94	21.0554
1687.99	18.3392
1691.04	15.9494
1694.08	13.0621
1697.13	10.9411
1700.18	9.68728
1703.22	8.5784
1706.26	7.3505
1709.3	5.68263
1712.35	5.22532
1715.39	4.9439
1718.42	4.63018
1721.46	4.94674
1724.5	4.81307
1727.53	4.92349
1730.56	4.07736
1733.6	2.9512
1736.63	3.00264
1739.66	3.77507
1742.69	2.91086
1745.71	2.41538
1748.74	2.24371
1751.77	2.8063
1754.79	3.67424
1757.81	3.88619
1760.84	3.48479
1763.86	3.65853
1766.88	3.63581
1769.9	2.92793
1772.91	3.86622
1775.93	4.33175
1778.95	4.6389
1781.96	4.21614
1784.97	4.63884
1787.99	5.45144
1791	6.07089
1794.01	6.09729
1797.01	5.56751
1800.02	5.14857
1803.03	4.44045
1806.03	4.06222
1809.04	4.33454
1812.04	5.31624
1815.04	5.53588
1818.04	5.41978
1821.04	4.98135
1824.04	5.78531
1827.04	5.71017
1830.03	4.9545
1833.03	4.74239
1836.02	4.34431
1839.02	4.39776
1842.01	4.0622
1845	3.76866
1847.99	3.63719
1850.98	3.3138
1853.96	3.70694
1856.95	4.21387
1859.94	3.77076
1862.92	3.48845
1865.9	4.09972
1868.88	3.80101
1871.86	3.44791
1874.84	3.63082
1877.82	3.49946
1880.8	3.54623
1882.58	3.37876
1885.57	2.51173
1888.56	1.74076
1891.54	1.16818
1894.53	1.3049
1897.51	1.69414
1900.5	1.31235
1903.48	1.904
1906.46	2.15341
1909.44	2.25893
1912.42	2.4631
1915.4	3.36231
1918.37	3.59883
1921.35	4.23228
1924.32	5.10327
1927.3	5.21898
1930.27	4.84546
1933.24	4.81582
1936.21	4.91407
1939.18	4.50128
1942.15	3.59106
1945.11	3.70419
1948.08	2.86069
1951.04	2.02696
1954.01	1.77167
1956.97	2.0117
1959.93	2.27316
1962.89	2.57845
1965.85	3.08314
1968.81	3.25151
1971.77	3.90418
1974.72	4.75887
1977.68	5.21928
1980.63	4.79312
1983.58	5.27052
1986.53	6.31062
1989.48	5.25016
1992.43	5.41315
1995.38	5.6828
1998.33	5.42458
2001.27	5.23446
2004.22	5.51384
2007.16	5.20824
2010.11	4.85129
2013.05	5.81862
2015.99	5.18101
2018.93	4.92397
2021.87	4.45605
2024.8	5.75526
2027.74	6.81816
2030.68	7.16689
2033.61	7.23445
2036.54	7.54516
2039.48	8.43282
2042.41	8.16979
2045.34	9.77162
2048.27	9.88696
2051.19	9.96805
2054.12	9.96214
2057.05	11.1114
2059.97	10.9443
2062.9	10.1897
2065.82	11.1893
2068.74	11.7298
2071.66	11.8446
2074.58	11.4704
2077.5	10.6674
2080.41	10.9817
2083.33	10.9163
2086.24	9.67513
2089.16	9.61346
2092.07	8.99704
2094.98	9.51046
2097.89	9.47384
2100.8	9.71026
2103.71	9.58432
2106.62	11.3339
2109.53	11.7609
2112.43	12.4011
2115.33	13.1756
2118.24	13.6161
2121.14	14.4363
2124.04	15.8685
2126.94	16.6428
2129.84	17.8552
2132.74	18.7585
2135.63	20.0686
2138.53	21.4745
2141.43	22.0016
2144.32	22.5142
2147.21	23.4203
2150.1	24.1166
2152.99	25.7299
2155.88	26.1827
2158.77	27.4852
2161.66	28.5211
2164.55	28.0401
2167.43	28.5063
2170.31	29.0512
2173.2	29.5233
2176.08	29.1144
2178.96	29.6684
2181.84	29.1533
2184.72	28.5279
2187.6	27.4698
2190.47	26.8512
2193.35	27.355
2196.23	26.9583
2199.1	26.8401
2201.97	25.3861
2204.84	25.5099
2207.71	24.5939
2210.58	23.3765
2213.45	22.1811
2216.32	21.3059
2219.19	20.7692
2222.05	19.3899
2224.92	18.3839
2227.78	17.4744
2230.64	15.9595
2233.5	15.061
2236.36	13.7088
2239.22	13.408
2242.08	11.9382
2244.94	11.9879
2247.79	11.6483
2250.65	10.6819
2253.5	9.77314
2256.36	9.20928
2259.21	9.66752
2262.06	9.87815
2264.91	9.93823
2267.76	8.84886
2270.6	9.45774
2273.45	9.80979
2276.3	9.95823
2279.14	9.66252
2281.98	9.37969
2284.83	9.49916
2287.67	8.47988
2290.51	8.23192
2293.35	7.19159
2296.19	6.8461
2299.02	8.00402
2301.86	9.37063
2304.7	8.90679
2307.53	9.4059
2310.36	10.1228
2313.2	9.76724
2316.03	10.3377
2318.86	9.49735
2321.69	9.31432
2324.51	9.06143
2327.34	9.63504
2330.17	8.78681
2332.99	7.07119
2335.82	6.31603
2338.64	5.82832
2341.46	5.5374
2344.28	4.12866
2347.1	2.83303
2349.92	3.09191
2352.74	2.3734
2355.56	0.822269
2358.37	0.194974
2361.19	0.0304128
2364	-0.104391
2366.82	0.937672
2369.63	1.78833
2372.44	3.05669
2375.25	2.83193
2378.06	3.43758
2380.86	4.072
2383.67	4.29078
2386.48	4.76093
2389.28	5.30769
2392.09	5.01827
2394.89	5.2217
2397.69	4.11549
2400.49	4.33128
2403.29	4.93944
2406.09	5.25064
2408.89	5.61834
2411.69	6.26724
2414.48	6.79574
2417.28	7.82118
2420.07	7.41762
2422.86	8.15706
2425.65	8.39996
2428.45	8.53282
2431.23	8.65738
2434.02	8.81228
2436.81	8.92154
2439.6	9.31894
2442.38	9.54184
2445.17	8.65844
2447.95	7.85256
2450.73	6.63
2453.52	6.26248
2456.3	5.24006
2459.08	4.01161
2461.85	3.61808
2464.63	3.58204
2467.41	3.13216
2470.19	3.83382
2472.96	2.56558
2475.73	2.15997
2478.51	1.53048
2481.28	1.48419
2484.05	2.48325
2486.82	3.01656
2489.59	2.65044
2492.35	3.07818
2495.12	3.41082
2497.89	3.4416
2500.65	5.19851
2503.42	5.33418
2506.18	5.84322
2508.94	5.50621
2511.7	5.24798
2514.46	4.16377
2517.22	3.66616
2519.98	3.38867
2522.73	3.78328
2525.49	3.09945
2528.25	3.88148
2531	3.70754
2533.75	3.73017
2536.5	3.67635
2539.25	3.81175
2542.01	3.51602
2544.75	3.89716
2547.5	4.75913
2550.25	5.77077
2553	6.67059
2555.74	7.19355
2558.49	7.08182
2561.23	7.78287
2563.97	8.56567
2566.71	7.98194
2569.45	7.59332
2572.19	6.22342
2574.93	5.44494
2577.67	5.06918
2580.4	5.32485
2583.14	4.04721
2585.87	3.97923
2588.6	3.28974
2591.34	3.31782
2594.07	2.39607
2596.8	1.61045
2599.53	2.41818
2602.26	2.43136
2604.98	1.81511
2607.71	3.44917
2610.44	4.00893
2613.16	4.29869
2615.88	4.62035
2618.61	5.05748
2621.33	5.46221
2624.05	6.24426
2626.77	6.40129
2629.49	5.93624
2632.21	6.22072
2634.92	6.2733
2637.64	7.02379
2640.35	7.5913
2643.07	8.51198
2645.78	7.82534
2648.49	7.31965
2651.2	6.37053
2653.91	6.12627
2656.62	5.72908
2659.33	5.27529
2662.04	4.94648
2664.74	5.32053
2667.45	5.25634
2670.15	4.79865
2672.86	5.65417
2675.56	6.21106
2678.26	5.98008
2680.96	6.23857
2683.66	5.81796
2686.36	5.86315
2689.06	5.88081
2691.75	6.3447
2694.45	5.97826
2697.14	7.0646
2699.84	7.70784
2702.53	8.16716
2705.22	8.37385
2707.91	8.47038
2710.6	9.23238
2713.29	8.73305
2715.98	8.05231
2718.67	8.5515
2721.35	8.60295
2724.04	8.16364
2726.72	8.1109
2729.4	8.29644
2732.09	7.96822
2734.77	7.75208
2737.45	8.76592
2740.13	8.70794
2742.81	8.40748
2745.48	7.6694
2748.16	7.30641
2750.84	6.96676
2753.51	7.50239
2756.19	7.67643
2758.86	7.183
2761.53	6.97139
2764.2	6.91255
2766.87	6.39532
2769.54	6.53246
2772.21	6.57434
2774.88	7.03316
2777.54	5.98858
2780.21	4.45486
2782.87	3.61459
2785.53	3.03688
2788.2	2.2399
2790.86	1.58969
2793.52	1.49605
2796.18	1.35374
2798.84	1.2132
2801.49	1.62851
2804.15	1.45306
2806.81	1.32739
2809.46	0.970387
2812.12	1.44234
2814.77	1.36176
2817.42	3.28366
2820.07	4.38583
2822.72	5.83422
2825.37	7.75933
2828.02	10.5922
2830.67	13.4685
2833.31	15.6449
2835.96	18.796
2838.61	22.3547
2841.25	25.2849
2843.89	29.0203
2846.53	33.0126
2849.17	37.5102
2851.81	41.7896
2854.45	47.013
2857.09	51.9466
2859.73	57.7645
2862.36	62.4228
2865	66.4804
2867.64	70.6065
2870.27	74.0033
2872.9	76.4664
2875.53	80.0973
2878.16	83.1028
2880.79	85.9816
2883.42	89.1588
2886.05	92.1736
2888.68	94.6831
2891.3	97.4468
2893.93	100.753
2896.55	103.153
2899.18	105.71
2901.8	109.399
2904.42	112.784
2907.04	116.481
2909.66	120.658
2912.28	125.284
2914.9	130.638
2917.51	134.772
2920.13	138.47
2922.74	141.652
2925.36	143.7
2927.97	144.554
2930.59	145.14
2933.2	144.469
2935.81	142.039
2938.42	139.922
2941.02	136.228
2943.63	132.582
2946.24	128.519
2948.85	123.533
2951.45	119.178
2954.05	114.401
2956.66	109.139
2959.26	104.462
2961.86	97.7715
2964.46	93.2118
2967.06	89.6372
2969.66	86.2833
2972.26	82.8012
2974.85	79.2667
2977.45	76.0361
2980.05	71.1245
2982.64	67.3852
2985.23	63.0134
2987.83	58.2214
2990.42	54.2984
2993.01	49.8064
2995.6	44.8395
2998.19	40.1796
3000.77	36.0337
3003.36	31.3614
3005.95	27.0558
3008.53	23.8439
3011.12	20.1771
3013.7	17.1232
3016.28	14.6018
3018.86	11.1641
3021.44	8.38784
3024.02	6.06979
3026.6	4.40128
3029.18	3.84827
3031.76	3.11664
3034.33	2.33649
3036.91	0.938367
3039.48	1.10336
3042.05	1.20307
3044.63	0.571065
3047.2	0.111455
3049.77	-0.0324113
3052.34	0.406409
3054.91	0.618619
3057.48	0.524207
3060.04	0.963346
3062.61	1.99618
3065.17	2.18541
3067.74	1.99118
3070.3	1.73408
3072.87	2.4683
3075.43	2.53898
3077.99	1.89684
3080.55	1.43998
3083.11	1.05932
3085.67	0.974003
3088.22	0.794699
3090.78	1.13041
3093.34	1.06353
3095.89	1.00045
3098.44	0.839904
3101	1.38973
3103.55	1.92531
3106.1	1.5608
3108.65	1.11849
3111.2	1.36643
3113.75	1.84056
3116.3	2.10923
3118.84	2.42564
3121.39	2.88905
3123.93	3.57319
3126.48	3.87806
3129.02	3.83172
3131.56	4.01296
3134.1	4.12872
3136.64	4.56118
3139.18	4.42975
3141.72	4.60347
3144.26	4.93468
3146.8	5.8212
3149.33	5.20028