File: data/Raman/poly_smoothed/Mbcal_20_25_48_1x_45s_532 nm_x100_100%_600 gr_mm_01.txt
#Acq. time (s)=	45
#Accumulations=	2
#Range (cm-¹)=	200...3150
#Windows=	2
#Auto scanning=	Off
#Autofocus=	Off
#Macrospot=	Off
#AutoExposure=	Off
#Spike filter=	Multiple accum.
#Delay time (s)=	0
#Binning=	1
#Readout mode=	Signal
#DeNoise=	Off
#ICS correction=	On
#Dark correction=	Off
#Inst. Process=	Off
#Detector Gain=	Best Dynamic Range
#Detector ADC=	20 kHz
#Detector temperature (°C)=	-69.85
#Instrument=	LabRAM HR Evol
#Detector=	Synapse
#Objective=	x100
#Grating=	600 gr/mm
#ND Filter=	100%
#Laser (nm)=	532
#Hole=	100.021
#Range=	Auto
#Laser Pol.=	No
#Raman. Pol.=	No
#Laser Pol. (°)=	-0.0007625
#Raman Pol. (°)=	89.9995
#Collection=	Microscope
#StageXY=	Marzhauser
#StageZ=	Marzhauser
#X (µm)=	-1139.8
#Y (µm)=	1240.8
#Z (µm)=	578.4
#Full time(mm:ss)=	3:18
#Project=
#Sample=
#Site=
#Title=	Mbcal_20_25_48_2x_45s_532 nm_x100_100%_600 gr_mm
#Remark=
#Date=	18.07.2022 13:52
#Acquired=	18.07.2022 13:52:09
#Base:Fit=	10.08.2022 10:55:08
#Base:Sub=	10.08.2022 10:55:14
#Filter:Polynom=	16.08.2022 10:07:28
#AxisType[0]=Intens
#AxisUnit[0]=Cnt
#AxisType[1]=Spectr
#AxisUnit[1]=1/cm
200.419	6.00831
204.048	12.2719
207.678	16.4944
211.304	18.9057
214.928	20.8631
218.554	22.8003
222.176	25.2703
225.798	25.7272
229.417	27.2163
233.035	28.0699
236.653	29.5964
240.268	30.9436
243.881	32.2998
247.493	34.7905
251.103	36.7336
254.715	36.1949
258.322	35.752
261.929	36.8051
265.534	36.8593
269.137	38.4162
272.739	38.1047
276.34	38.6132
279.939	34.975
283.537	35.0897
287.134	34.7743
290.729	34.9129
294.323	33.6837
297.913	32.9954
301.504	32.9464
305.093	32.939
308.682	31.7913
312.268	31.5957
315.852	31.9245
319.436	30.2903
323.018	29.7035
326.597	29.5415
330.177	31.1858
333.753	32.028
337.331	31.2002
340.906	29.8697
344.478	27.2981
348.051	24.3427
351.621	23.7984
355.189	20.2732
358.757	18.0632
362.323	15.3391
365.889	11.6452
369.451	12.4982
373.012	12.1504
376.574	9.10161
380.133	8.98739
383.69	8.63149
387.245	8.44148
390.8	8.38362
394.353	8.83201
397.906	10.3021
401.456	10.0897
405.005	9.88692
408.552	10.6528
412.099	12.4627
415.643	13.2374
419.187	12.8257
422.728	11.0664
426.269	9.64363
429.806	9.42715
433.344	9.02595
436.881	6.73733
440.416	7.0423
443.949	7.46625
447.48	6.96173
451.011	8.49369
454.541	8.80498
458.069	9.35414
461.594	6.65009
465.119	6.6567
468.642	7.81004
472.165	9.03623
475.684	10.0673
479.204	9.08715
482.721	11.6694
486.239	13.2504
489.753	12.4966
493.268	15.601
496.779	15.3005
500.289	14.6531
503.8	13.513
507.307	12.6804
510.813	12.7034
514.32	14.6828
517.823	15.7934
521.325	17.7642
524.826	21.3412
528.325	25.2055
531.823	28.3563
535.32	28.4651
538.815	30.5018
542.309	31.8621
545.802	33.6046
549.293	31.7875
552.783	32.0324
556.271	32.7306
559.759	31.637
563.245	30.1952
566.729	30.8565
570.213	27.2052
573.693	26.0003
577.173	24.6893
580.652	24.3242
584.13	21.8285
587.605	18.5488
591.08	13.602
594.552	13.0129
598.025	11.1704
601.496	10.1407
604.964	11.2004
608.433	10.1783
611.898	11.5339
615.364	14.1361
618.827	14.9784
622.288	16.1599
625.75	20.0943
629.209	22.0596
632.667	23.0144
636.125	26.071
639.58	27.9812
643.033	30.1915
646.485	34.1052
649.936	36.2591
653.388	38.2595
656.836	40.1301
660.283	43.9172
663.728	45.0945
667.173	44.8568
670.616	41.898
674.057	38.7844
677.498	40.418
680.937	39.5955
684.375	39.0263
687.809	36.5128
691.244	36.2428
694.678	35.826
698.111	36.4642
701.54	37.042
704.97	35.5962
708.398	36.7775
711.826	34.5819
715.25	34.8363
718.675	34.5729
722.096	34.1526
725.518	36.2405
728.937	37.3772
732.357	39.5756
735.773	41.5114
739.19	44.493
742.604	47.0049
746.018	49.4759
749.429	52.3875
752.839	55.8774
756.248	60.5042
759.657	63.9279
763.063	69.4952
766.468	72.9364
769.871	75.1872
773.273	78.6807
776.676	83.7963
780.075	87.7435
783.474	91.1076
786.871	95.0189
790.266	97.3593
793.661	96.5924
797.054	98.2688
800.446	99.7628
803.834	101.223
807.224	101.033
810.612	101.344
813.998	102.127
817.384	102.903
820.766	102.821
824.149	101.021
827.531	102.727
830.909	106.589
834.288	109.337
837.666	111.839
841.041	112.305
844.416	115.949
847.788	116.682
851.161	118.277
854.53	118.191
857.901	118.59
861.268	116.744
864.633	116.601
868	114.176
871.363	112.192
874.725	107.879
878.088	104.712
881.447	101.42
884.805	95.425
888.162	88.7339
891.518	84.6878
894.872	80.3978
898.225	78.8584
901.577	73.1807
904.928	72.6217
908.277	73.5179
911.625	73.3906
914.972	74.6254
918.318	72.992
921.662	72.526
925.005	71.2047
928.347	71.3528
931.686	68.4866
935.025	65.3768
938.363	61.5181
941.698	57.3437
945.034	51.7222
948.368	49.6176
951.699	47.3643
955.031	44.2669
958.36	41.498
961.689	38.0677
965.016	34.7248
968.343	33.3955
971.666	31.8391
974.991	30.74
978.312	28.8142
981.632	28.2464
984.953	28.1158
988.27	27.0891
991.587	26.5095
994.902	25.5334
998.216	25.376
1001.53	22.9907
1004.84	21.7616
1008.15	23.9569
1011.46	24.0776
1014.77	24.6175
1018.07	24.3641
1021.38	25.9088
1024.68	28.5138
1027.99	29.6695
1031.29	32.0912
1034.59	34.3363
1037.89	35.534
1041.18	34.7425
1044.48	35.7894
1047.77	35.9601
1051.07	34.9956
1054.36	33.2949
1057.65	31.4513
1060.94	29.4815
1064.23	30.8003
1067.52	28.0243
1070.8	26.7591
1074.09	24.9512
1077.37	22.6914
1080.65	19.6001
1083.93	20.2652
1087.21	22.0764
1090.49	22.5403
1093.77	23.1332
1097.04	24.425
1100.32	25.131
1103.59	25.9083
1106.86	25.3503
1110.13	25.5845
1113.4	26.8711
1116.67	26.1829
1119.94	25.1341
1123.2	21.2098
1126.47	19.9795
1129.73	19.5881
1132.99	17.7703
1136.25	16.0384
1139.51	15.0632
1142.77	16.7912
1146.03	17.8849
1149.28	14.953
1152.54	13.2434
1155.79	11.6389
1159.04	9.73261
1162.29	8.72102
1165.54	8.46676
1168.79	7.57905
1172.04	7.63606
1175.28	7.27708
1178.53	8.35598
1181.77	8.53277
1185.01	9.08827
1188.25	12.7779
1191.49	12.6957
1194.73	13.5097
1197.96	12.6641
1201.2	12.7112
1204.43	13.9207
1207.66	15.4922
1210.9	15.2148
1214.13	15.9516
1217.36	18.0962
1220.58	20.8529
1223.81	21.3069
1227.04	21.0981
1230.26	19.7039
1233.48	21.5747
1236.71	22.584
1239.93	23.7496
1243.14	25.0494
1246.36	27.5024
1249.58	30.7368
1252.8	34.8049
1256.01	35.9295
1259.22	39.8584
1262.43	41.3033
1265.64	44.2786
1268.85	44.4175
1272.06	44.7882
1275.27	46.8244
1278.48	48.934
1281.68	50.7304
1284.88	50.794
1288.08	51.5724
1291.28	54.2463
1294.48	56.5989
1297.68	59.3783
1300.88	60.5826
1304.07	60.3464
1307.27	62.9146
1310.46	64.8292
1313.65	66.1622
1316.85	67.3979
1320.03	66.9551
1323.22	67.2399
1326.41	66.2695
1329.6	67.9622
1332.78	66.2601
1335.96	65.884
1339.15	62.9085
1342.33	61.1878
1345.51	58.028
1348.69	55.3459
1351.86	54.1589
1355.04	51.907
1358.21	49.7011
1361.39	49.1974
1364.56	47.2464
1367.73	45.5211
1370.9	45.0245
1374.07	43.4478
1377.24	43.1326
1380.41	41.788
1383.57	41.2416
1386.73	42.3252
1389.9	42.6634
1393.06	43.3199
1396.22	44.3616
1399.38	47.0635
1402.54	50.7843
1405.69	55.0795
1408.85	60.0195
1412	63.5747
1415.16	66.936
1418.31	69.2161
1421.46	73.0595
1424.61	76.2389
1427.76	83.6305
1430.9	87.9787
1434.05	90.9405
1437.2	94.4799
1440.34	96.4767
1443.48	97.7123
1446.62	96.2708
1449.76	96.5241
1452.9	96.6639
1456.04	94.7415
1459.17	94.6414
1462.31	93.8836
1465.44	93.1823
1468.58	90.5068
1471.71	89.1404
1474.84	86.8024
1477.97	84.8131
1481.1	81.1336
1484.22	76.313
1487.35	71.5858
1490.47	65.6356
1493.59	60.0641
1496.72	56.1713
1499.84	51.7136
1502.96	49.1
1506.08	45.249
1509.19	39.4979
1512.31	34.4411
1515.42	29.516
1518.54	25.759
1521.65	17.6282
1524.76	16.0131
1527.87	16.7236
1530.98	17.4653
1534.09	18.6918
1537.2	20.4458
1540.3	21.5765
1543.41	23.7954
1546.51	27.6102
1549.61	28.7389
1552.71	30.1023
1555.81	32.7861
1558.91	35.4147
1562.01	35.7335
1565.1	37.8067
1568.2	40.1788
1571.29	42.5702
1574.38	46.1335
1577.48	48.2991
1580.57	49.1025
1583.65	49.4909
1586.74	49.8273
1589.83	50.3241
1592.92	49.7567
1596	48.2251
1599.08	49.2645
1602.16	51.107
1605.24	50.3632
1608.32	49.4377
1611.4	49.9662
1614.48	48.3754
1617.56	48.2631
1620.63	47.9286
1623.71	45.7074
1626.78	45.4389
1629.85	44.729
1632.92	45.4606
1635.99	45.5139
1639.06	44.9232
1642.12	46.5053
1645.19	48.5119
1648.25	50.7229
1651.32	52.0178
1654.38	51.1496
1657.44	50.1326
1660.5	49.5699
1663.56	48.0568
1666.62	46.1817
1669.67	43.4936
1672.73	39.3579
1675.79	37.1546
1678.84	32.6772
1681.89	30.0324
1684.94	27.9303
1687.99	25.9835
1691.04	22.7063
1694.08	17.8982
1697.13	16.9123
1700.18	16.3493
1703.22	15.5205
1706.26	13.5373
1709.3	14.2118
1712.35	14.0574
1715.39	13.0701
1718.42	14.2847
1721.46	14.7322
1724.5	13.8643
1727.53	13.6352
1730.56	14.3542
1733.6	13.3618
1736.63	12.5083
1739.66	11.7729
1742.69	10.8142
1745.71	10.5283
1748.74	10.9536
1751.77	11.4333
1754.79	10.1438
1757.81	9.6059
1760.84	10.4028
1763.86	8.41886
1766.88	7.26234
1769.9	8.11578
1772.91	8.80223
1775.93	8.18327
1778.95	7.22307
1781.96	7.36139
1784.97	8.45487
1787.99	9.09345
1791	10.011
1794.01	9.39867
1797.01	9.18949
1800.02	8.1398
1803.03	7.75228
1806.03	6.24599
1809.04	6.26059
1812.04	6.27344
1815.04	6.43026
1818.04	6.73902
1821.04	7.10289
1824.04	6.96882
1827.04	6.99749
1830.03	7.70218
1833.03	8.33915
1836.02	9.74449
1839.02	10.3589
1842.01	11.4779
1845	12.3391
1847.99	11.881
1850.98	12.8922
1853.96	13.8627
1856.95	14.1049
1859.94	13.8483
1862.92	13.2427
1865.9	12.0686
1868.88	10.6077
1871.86	10.5954
1874.84	9.85459
1877.82	9.64526
1880.8	8.38812
1882.58	8.08989
1885.57	9.54837
1888.56	9.50331
1891.54	9.7766
1894.53	10.0325
1897.51	10.267
1900.5	10.0944
1903.48	10.1352
1906.46	11.0351
1909.44	10.9626
1912.42	10.31
1915.4	8.53433
1918.37	7.45947
1921.35	8.13055
1924.32	6.92342
1927.3	6.26907
1930.27	6.14089
1933.24	5.2053
1936.21	4.35913
1939.18	3.95368
1942.15	2.81909
1945.11	2.03402
1948.08	2.72827
1951.04	0.553796
1954.01	1.09888
1956.97	1.21608
1959.93	1.96221
1962.89	0.711357
1965.85	0.653848
1968.81	0.514595
1971.77	-0.650831
1974.72	-1.42473
1977.68	-1.05893
1980.63	-1.43203
1983.58	-1.37109
1986.53	-1.20422
1989.48	-0.974576
1992.43	0.142169
1995.38	0.182668
1998.33	1.05606
2001.27	2.01284
2004.22	2.5862
2007.16	2.985
2010.11	3.28352
2013.05	3.7652
2015.99	2.75951
2018.93	2.60319
2021.87	1.44264
2024.8	2.39113
2027.74	4.16618
2030.68	5.02996
2033.61	5.37437
2036.54	5.42113
2039.48	4.86233
2042.41	4.31228
2045.34	4.55172
2048.27	5.08311
2051.19	6.30085
2054.12	6.25344
2057.05	6.10561
2059.97	6.41309
2062.9	6.59191
2065.82	7.04155
2068.74	6.81753
2071.66	5.96511
2074.58	5.13157
2077.5	6.12842
2080.41	5.06003
2083.33	3.66455
2086.24	4.40868
2089.16	3.73247
2092.07	5.76356
2094.98	6.8507
2097.89	8.26363
2100.8	9.38735
2103.71	9.42145
2106.62	10.0629
2109.53	11.4666
2112.43	12.2962
2115.33	13.6836
2118.24	14.4287
2121.14	16.5341
2124.04	17.6785
2126.94	19.3558
2129.84	20.2782
2132.74	21.6252
2135.63	22.3307
2138.53	23.2741
2141.43	22.1586
2144.32	22.9902
2147.21	23.6149
2150.1	24.2302
2152.99	23.5157
2155.88	24.9586
2158.77	26.2842
2161.66	26.6008
2164.55	26.7219
2167.43	27.4342
2170.31	28.6253
2173.2	29.5864
2176.08	30.1326
2178.96	29.9003
2181.84	29.668
2184.72	29.8049
2187.6	28.6397
2190.47	28.5663
2193.35	28.4221
2196.23	27.4728
2199.1	27.7837
2201.97	27.9408
2204.84	27.3708
2207.71	25.826
2210.58	23.8436
2213.45	21.8228
2216.32	20.2192
2219.19	19.8099
2222.05	19.3651
2224.92	17.4807
2227.78	16.5652
2230.64	15.402
2233.5	14.9972
2236.36	15.1689
2239.22	16.0333
2242.08	15.9848
2244.94	16.4211
2247.79	15.2876
2250.65	14.466
2253.5	14.3391
2256.36	13.2707
2259.21	12.9024
2262.06	13.3168
2264.91	12.8464
2267.76	12.878
2270.6	13.0012
2273.45	11.6005
2276.3	9.84394
2279.14	8.13078
2281.98	6.48776
2284.83	5.94221
2287.67	5.44775
2290.51	4.34617
2293.35	2.38021
2296.19	2.38062
2299.02	2.4539
2301.86	2.19405
2304.7	3.99206
2307.53	6.01283
2310.36	6.411
2313.2	8.05068
2316.03	7.80909
2318.86	7.42628
2321.69	7.91247
2324.51	8.46854
2327.34	10.1275
2330.17	9.97596
2332.99	9.29139
2335.82	9.33362
2338.64	8.20963
2341.46	7.8317
2344.28	7.23714
2347.1	6.61814
2349.92	6.1286
2352.74	4.63082
2355.56	3.55417
2358.37	2.46507
2361.19	2.94763
2364	3.59949
2366.82	4.66698
2369.63	3.55415
2372.44	4.3557
2375.25	5.16582
2378.06	5.81325
2380.86	5.7853
2383.67	5.98002
2386.48	5.95938
2389.28	6.80662
2392.09	7.55518
2394.89	6.51791
2397.69	6.45545
2400.49	6.59285
2403.29	6.47551
2406.09	6.34685
2408.89	6.62601
2411.69	7.02042
2414.48	5.51757
2417.28	4.29395
2420.07	3.98639
2422.86	5.28231
2425.65	5.26893
2428.45	4.44296
2431.23	4.56359
2434.02	3.90551
2436.81	3.35179
2439.6	3.2096
2442.38	2.69932
2445.17	1.09689
2447.95	0.489004
2450.73	-0.774632
2453.52	-1.24357
2456.3	-1.62301
2459.08	-1.89642
2461.85	-2.50402
2464.63	-3.08833
2467.41	-2.82758
2470.19	-2.15179
2472.96	-1.79702
2475.73	-0.755961
2478.51	0.249021
2481.28	0.833415
2484.05	1.68358
2486.82	3.04306
2489.59	5.00192
2492.35	5.26776
2495.12	5.27692
2497.89	5.54801
2500.65	7.79697
2503.42	6.73146
2506.18	6.55725
2508.94	7.12608
2511.7	6.49545
2514.46	6.82361
2517.22	7.69783
2519.98	8.10729
2522.73	8.03677
2525.49	7.25306
2528.25	7.37184
2531	7.10297
2533.75	7.99002
2536.5	7.35237
2539.25	7.3389
2542.01	7.86414
2544.75	7.36056
2547.5	7.68902
2550.25	7.01016
2553	6.86347
2555.74	6.69226
2558.49	6.60242
2561.23	6.08279
2563.97	6.12794
2566.71	5.82004
2569.45	4.5742
2572.19	3.65395
2574.93	2.88332
2577.67	3.51301
2580.4	3.31747
2583.14	2.78437
2585.87	2.42977
2588.6	2.60287
2591.34	2.63223
2594.07	2.69008
2596.8	1.62276
2599.53	3.15579
2602.26	3.81716
2604.98	4.18716
2607.71	3.43166
2610.44	3.57377
2613.16	5.39155
2615.88	5.25283
2618.61	5.11685
2621.33	6.51286
2624.05	6.30464
2626.77	6.4052
2629.49	5.91384
2632.21	5.58194
2634.92	4.28387
2637.64	3.16837
2640.35	3.27652
2643.07	3.04968
2645.78	2.06127
2648.49	1.06504
2651.2	0.810839
2653.91	2.3968
2656.62	2.80258
2659.33	2.8348
2662.04	2.70756
2664.74	4.52017
2667.45	4.2187
2670.15	5.36922
2672.86	4.79579
2675.56	4.84342
2678.26	5.28965
2680.96	5.53647
2683.66	5.59544
2686.36	6.05832
2689.06	5.57178
2691.75	6.16026
2694.45	6.75609
2697.14	6.68549
2699.84	6.53267
2702.53	6.19493
2705.22	6.19015
2707.91	5.82777
2710.6	5.6654
2713.29	5.98166
2715.98	6.92643
2718.67	8.15848
2721.35	9.2391
2724.04	9.11058
2726.72	9.69911
2729.4	9.51629
2732.09	9.16382
2734.77	9.07369
2737.45	9.05641
2740.13	8.12692
2742.81	7.81203
2745.48	7.84049
2748.16	8.25393
2750.84	7.66934
2753.51	7.4714
2756.19	5.75575
2758.86	5.41225
2761.53	3.55208
2764.2	2.48393
2766.87	0.969724
2769.54	1.30989
2772.21	1.02208
2774.88	-0.355179
2777.54	-0.339744
2780.21	1.05791
2782.87	1.56409
2785.53	1.28132
2788.2	0.812672
2790.86	1.79324
2793.52	1.90898
2796.18	1.4823
2798.84	2.45315
2801.49	2.77881
2804.15	2.74975
2806.81	2.85615
2809.46	2.82659
2812.12	3.20541
2814.77	2.88948
2817.42	3.37228
2820.07	4.81049
2822.72	7.17791
2825.37	10.103
2828.02	14.4744
2830.67	18.9125
2833.31	24.019
2835.96	30.6413
2838.61	36.4422
2841.25	42.7553
2843.89	50.1441
2846.53	57.6631
2849.17	64.4496
2851.81	72.3358
2854.45	82.0583
2857.09	90.0227
2859.73	98.0777
2862.36	105.363
2865	112.648
2867.64	119.57
2870.27	125.119
2872.9	129.582
2875.53	134.562
2878.16	140.345
2880.79	145.743
2883.42	150.876
2886.05	155.123
2888.68	159.995
2891.3	163.456
2893.93	167.322
2896.55	171.021
2899.18	175.971
2901.8	180.765
2904.42	185.296
2907.04	191.365
2909.66	198.406
2912.28	205.752
2914.9	213.081
2917.51	220.521
2920.13	225.903
2922.74	229.645
2925.36	232.038
2927.97	232.016
2930.59	231.278
2933.2	228.622
2935.81	224.399
2938.42	220.343
2941.02	213.799
2943.63	204.378
2946.24	195.646
2948.85	185.792
2951.45	175.11
2954.05	163.022
2956.66	151.352
2959.26	141.366
2961.86	133.276
2964.46	126.325
2967.06	119.347
2969.66	115.717
2972.26	110.311
2974.85	106.273
2977.45	101.737
2980.05	98.6827
2982.64	93.6691
2985.23	89.816
2987.83	85.1141
2990.42	79.0351
2993.01	73.7853
2995.6	68.2064
2998.19	63.2933
3000.77	57.6733
3003.36	52.2868
3005.95	45.1313
3008.53	38.6997
3011.12	32.9087
3013.7	26.6818
3016.28	21.2384
3018.86	16.6808
3021.44	13.765
3024.02	9.6069
3026.6	7.68538
3029.18	5.56424
3031.76	3.70841
3034.33	2.48741
3036.91	0.749946
3039.48	1.16366
3042.05	2.04779
3044.63	2.46076
3047.2	3.41975
3049.77	3.26831
3052.34	1.95027
3054.91	2.00081
3057.48	2.5956
3060.04	1.96541
3062.61	2.68349
3065.17	3.791
3067.74	2.85659
3070.3	2.9683
3072.87	3.69599
3075.43	3.44668
3077.99	3.07329
3080.55	3.16002
3083.11	2.38744
3085.67	2.03559
3088.22	2.55174
3090.78	2.53864
3093.34	3.06927
3095.89	2.90882
3098.44	3.34383
3101	5.47908
3103.55	6.6484
3106.1	7.38363
3108.65	7.83766
3111.2	8.74761
3113.75	9.3844
3116.3	10.1477
3118.84	11.6134
3121.39	12.5575
3123.93	14.6256
3126.48	16.9845
3129.02	18.2596
3131.56	20.4341
3134.1	21.5254
3136.64	22.9322
3139.18	23.5285
3141.72	24.8668
3144.26	26.2351
3146.8	27.7177
3149.33	28.8347