File: data/Raman/poly_smoothed/Mbcal_20_25_36_1x_45s_532 nm_x100_100%_600 gr_mm_01.txt
#Acq. time (s)=	45
#Accumulations=	2
#Range (cm-¹)=	200...3150
#Windows=	2
#Auto scanning=	Off
#Autofocus=	Off
#Macrospot=	Off
#AutoExposure=	Off
#Spike filter=	Multiple accum.
#Delay time (s)=	0
#Binning=	1
#Readout mode=	Signal
#DeNoise=	Off
#ICS correction=	On
#Dark correction=	Off
#Inst. Process=	Off
#Detector Gain=	Best Dynamic Range
#Detector ADC=	20 kHz
#Detector temperature (°C)=	-69.85
#Instrument=	LabRAM HR Evol
#Detector=	Synapse
#Objective=	x100
#Grating=	600 gr/mm
#ND Filter=	100%
#Laser (nm)=	532
#Hole=	100.021
#Range=	Auto
#Laser Pol.=	No
#Raman. Pol.=	No
#Laser Pol. (°)=	-0.0007625
#Raman Pol. (°)=	89.9995
#Collection=	Microscope
#StageXY=	Marzhauser
#StageZ=	Marzhauser
#X (µm)=	-1126.8
#Y (µm)=	1284.6
#Z (µm)=	578.7
#Full time(mm:ss)=	3:18
#Project=
#Sample=
#Site=
#Title=	Mbcal_20_25_36_2x_45s_532 nm_x100_100%_600 gr_mm
#Remark=
#Date=	18.07.2022 12:45
#Acquired=	18.07.2022 12:45:33
#Edit:Spike=	18.07.2022 12:46:44
#Edit:Spike=	18.07.2022 12:46:45
#Edit:Spike=	18.07.2022 12:46:46
#Base:Fit=	10.08.2022 10:55:08
#Base:Sub=	10.08.2022 10:55:14
#Filter:Polynom=	16.08.2022 10:07:28
#AxisType[0]=Intens
#AxisUnit[0]=Cnt
#AxisType[1]=Spectr
#AxisUnit[1]=1/cm
200.419	41.9242
204.048	40.3686
207.678	34.176
211.304	29.9048
214.928	24.9449
218.554	22.6802
222.176	19.8335
225.798	16.9921
229.417	13.7583
233.035	12.9372
236.653	11.0934
240.268	12.0047
243.881	14.6732
247.493	16.1559
251.103	18.0794
254.715	19.4907
258.322	21.364
261.929	21.5278
265.534	21.4054
269.137	22.9715
272.739	25.2406
276.34	25.4673
279.939	22.2337
283.537	20.0072
287.134	17.5575
290.729	17.7296
294.323	16.3275
297.913	18.4295
301.504	18.8873
305.093	18.3174
308.682	17.8728
312.268	18.0497
315.852	15.1584
319.436	15.4432
323.018	16.2162
326.597	19.3795
330.177	24.8073
333.753	26.9839
337.331	26.1227
340.906	27.0397
344.478	24.8338
348.051	25.4047
351.621	22.4171
355.189	21.1025
358.757	18.9947
362.323	18.035
365.889	15.1558
369.451	11.9591
373.012	11.5372
376.574	10.9865
380.133	10.7807
383.69	11.4847
387.245	13.3944
390.8	12.5205
394.353	12.623
397.906	11.2747
401.456	9.80879
405.005	10.2899
408.552	11.7389
412.099	13.8643
415.643	15.2043
419.187	15.8416
422.728	14.9461
426.269	13.9751
429.806	13.6691
433.344	14.1822
436.881	15.0094
440.416	13.8752
443.949	13.3511
447.48	10.6875
451.011	11.0789
454.541	8.66516
458.069	9.13046
461.594	7.925
465.119	6.63795
468.642	7.12522
472.165	7.18573
475.684	7.05819
479.204	7.05766
482.721	8.21889
486.239	9.16866
489.753	10.3261
493.268	12.1325
496.779	13.8157
500.289	15.0999
503.8	16.8679
507.307	20.4315
510.813	22.0846
514.32	24.4744
517.823	26.8431
521.325	27.7257
524.826	29.5947
528.325	31.1336
531.823	31.3517
535.32	29.8691
538.815	31.142
542.309	32.1063
545.802	30.3773
549.293	29.1961
552.783	29.4028
556.271	29.3287
559.759	28.2779
563.245	27.2911
566.729	26.7235
570.213	24.4048
573.693	22.8739
577.173	21.1753
580.652	19.4722
584.13	16.7666
587.605	14.1497
591.08	13.9297
594.552	11.6919
598.025	10.308
601.496	10.2736
604.964	7.79966
608.433	6.6417
611.898	5.1793
615.364	4.62363
618.827	2.53387
622.288	0.851069
625.75	1.61662
629.209	0.405281
632.667	2.82292
636.125	2.90335
639.58	3.53895
643.033	3.88693
646.485	3.43639
649.936	3.55079
653.388	4.73526
656.836	5.06387
660.283	5.66174
663.728	5.02355
667.173	5.24353
670.616	5.56882
674.057	7.54423
677.498	8.92921
680.937	10.7675
684.375	11.4958
687.809	12.0696
691.244	13.0851
694.678	13.7749
698.111	14.5689
701.54	15.6262
704.97	15.3575
708.398	16.7575
711.826	18.6575
715.25	20.4855
718.675	21.862
722.096	23.2061
725.518	25.3958
728.937	26.0688
732.357	26.3263
735.773	26.7023
739.19	27.161
742.604	28.5429
746.018	32.7061
749.429	32.7283
752.839	35.1349
756.248	38.9564
759.657	40.7337
763.063	41.2958
766.468	42.3559
769.871	43.6223
773.273	46.2287
776.676	45.8596
780.075	48.5167
783.474	50.868
786.871	52.464
790.266	54.2432
793.661	58.4084
797.054	59.7657
800.446	60.4966
803.834	60.874
807.224	63.5137
810.612	61.8712
813.998	61.0272
817.384	60.6725
820.766	59.96
824.149	61.0981
827.531	64.7021
830.909	63.004
834.288	66.4816
837.666	67.6834
841.041	68.7845
844.416	67.6063
847.788	67.4905
851.161	65.8562
854.53	65.0422
857.901	63.6385
861.268	62.7352
864.633	62.2944
868	57.729
871.363	57.1757
874.725	53.1005
878.088	49.5571
881.447	44.4622
884.805	41.0251
888.162	37.7264
891.518	34.4261
894.872	28.8967
898.225	27.7384
901.577	25.319
904.928	24.4393
908.277	26.0685
911.625	25.9131
914.972	26.0056
918.318	27.1319
921.662	26.6817
925.005	25.7041
928.347	24.7046
931.686	25.0736
935.025	24.246
938.363	24.4971
941.698	22.5427
945.034	21.7993
948.368	18.9061
951.699	16.9735
955.031	16.6357
958.36	12.9665
961.689	10.4771
965.016	8.56367
968.343	8.32284
971.666	7.77924
974.991	6.56276
978.312	8.61336
981.632	8.97843
984.953	6.44439
988.27	7.60854
991.587	8.11742
994.902	6.42675
998.216	6.4117
1001.53	8.29042
1004.84	7.60647
1008.15	8.48068
1011.46	9.88352
1014.77	13.6933
1018.07	14.0093
1021.38	15.4264
1024.68	18.7781
1027.99	20.3534
1031.29	20.2276
1034.59	19.4426
1037.89	19.6692
1041.18	17.5647
1044.48	17.2535
1047.77	17.7812
1051.07	18.0204
1054.36	16.4745
1057.65	16.1584
1060.94	15.2344
1064.23	12.9237
1067.52	11.5452
1070.8	12.3055
1074.09	10.3002
1077.37	10.4907
1080.65	8.89269
1083.93	7.94953
1087.21	6.12773
1090.49	8.12833
1093.77	10.6553
1097.04	11.9791
1100.32	12.7097
1103.59	14.8468
1106.86	16.3405
1110.13	17.0184
1113.4	15.2476
1116.67	15.66
1119.94	14.7489
1123.2	14.5833
1126.47	13.5503
1129.73	13.439
1132.99	14.3049
1136.25	14.7656
1139.51	14.5446
1142.77	15.8129
1146.03	14.4702
1149.28	13.1628
1152.54	12.3858
1155.79	9.92
1159.04	7.43561
1162.29	5.66346
1165.54	4.48058
1168.79	5.54462
1172.04	6.31056
1175.28	7.71523
1178.53	8.55672
1181.77	8.7031
1185.01	9.41039
1188.25	11.4323
1191.49	11.8703
1194.73	11.3461
1197.96	12.5102
1201.2	13.9355
1204.43	15.9763
1207.66	18.7197
1210.9	22.165
1214.13	23.8035
1217.36	26.0437
1220.58	28.9005
1223.81	32.7779
1227.04	35.8529
1230.26	37.6601
1233.48	38.6821
1236.71	39.913
1239.93	42.149
1243.14	45.9065
1246.36	48.358
1249.58	50.6542
1252.8	51.4668
1256.01	49.3354
1259.22	48.9758
1262.43	49.7033
1265.64	50.4247
1268.85	51.3677
1272.06	50.4341
1275.27	50.9224
1278.48	53.2226
1281.68	54.6092
1284.88	56.2641
1288.08	60.3071
1291.28	65.054
1294.48	67.1714
1297.68	70.232
1300.88	74.6087
1304.07	79.6713
1307.27	82.5408
1310.46	84.9404
1313.65	89.3674
1316.85	91.4891
1320.03	94.5402
1323.22	97.5214
1326.41	98.3229
1329.6	96.5405
1332.78	93.6544
1335.96	94.2537
1339.15	92.5257
1342.33	91.3132
1345.51	90.4044
1348.69	88.8077
1351.86	89.1327
1355.04	87.3099
1358.21	87.3485
1361.39	86.3052
1364.56	85.0004
1367.73	84.6502
1370.9	80.9584
1374.07	79.9077
1377.24	79.7478
1380.41	79.4687
1383.57	78.5669
1386.73	79.3507
1389.9	81.0879
1393.06	81.436
1396.22	80.5363
1399.38	82.1539
1402.54	82.9456
1405.69	82.3612
1408.85	84.1071
1412	87.5779
1415.16	92.3331
1418.31	96.0695
1421.46	103.013
1424.61	110.736
1427.76	119.534
1430.9	126.394
1434.05	131.296
1437.2	137.141
1440.34	140.455
1443.48	144.924
1446.62	146.606
1449.76	149.062
1452.9	150.16
1456.04	150.425
1459.17	151.207
1462.31	151.505
1465.44	152.433
1468.58	151.507
1471.71	148.51
1474.84	145.923
1477.97	141.104
1481.1	135.647
1484.22	131.181
1487.35	126.484
1490.47	121.13
1493.59	114.681
1496.72	108.708
1499.84	103.597
1502.96	97.4752
1506.08	89.0672
1509.19	81.9467
1512.31	72.8855
1515.42	67.0056
1518.54	59.2877
1521.65	53.8207
1524.76	50.2622
1527.87	46.0284
1530.98	43.5817
1534.09	43.1195
1537.2	43.505
1540.3	44.3799
1543.41	44.3861
1546.51	45.644
1549.61	47.3129
1552.71	48.8851
1555.81	50.2045
1558.91	53.5171
1562.01	55.2224
1565.1	58.1243
1568.2	61.9578
1571.29	64.5505
1574.38	68.5687
1577.48	73.4652
1580.57	76.7772
1583.65	80.7392
1586.74	83.1683
1589.83	86.1964
1592.92	87.9121
1596	88.8974
1599.08	89.5901
1602.16	91.7775
1605.24	90.4052
1608.32	87.4705
1611.4	85.8838
1614.48	84.1142
1617.56	81.6448
1620.63	80.4448
1623.71	77.8155
1626.78	77.5469
1629.85	76.0145
1632.92	77.4723
1635.99	74.9786
1639.06	75.9782
1642.12	74.6192
1645.19	76.2337
1648.25	76.7195
1651.32	78.2409
1654.38	77.3315
1657.44	76.6534
1660.5	75.5012
1663.56	73.9543
1666.62	72.3004
1669.67	68.3958
1672.73	64.9317
1675.79	60.5239
1678.84	55.4645
1681.89	49.723
1684.94	46.9825
1687.99	43.9459
1691.04	38.9904
1694.08	37.0837
1697.13	33.0547
1700.18	31.2436
1703.22	29.3177
1706.26	25.2547
1709.3	22.8404
1712.35	19.6715
1715.39	17.2493
1718.42	13.6648
1721.46	12.7281
1724.5	10.6169
1727.53	8.84152
1730.56	9.50251
1733.6	8.80364
1736.63	7.34186
1739.66	6.31387
1742.69	4.88692
1745.71	3.64109
1748.74	2.18119
1751.77	2.50609
1754.79	3.68417
1757.81	4.15982
1760.84	6.13011
1763.86	5.34431
1766.88	4.95695
1769.9	5.55101
1772.91	6.61681
1775.93	5.9347
1778.95	5.20815
1781.96	4.52847
1784.97	3.6309
1787.99	4.04605
1791	5.40259
1794.01	5.6844
1797.01	6.50029
1800.02	7.06547
1803.03	7.19508
1806.03	8.42727
1809.04	7.60879
1812.04	8.84163
1815.04	8.29345
1818.04	8.62605
1821.04	9.26764
1824.04	9.57364
1827.04	9.5274
1830.03	9.62632
1833.03	9.60422
1836.02	8.79831
1839.02	9.00378
1842.01	9.67599
1845	9.44791
1847.99	10.1541
1850.98	10.2299
1853.96	9.30136
1856.95	9.0935
1859.94	9.21765
1862.92	9.60222
1865.9	7.84727
1868.88	7.55147
1871.86	6.96272
1874.84	8.11752
1877.82	8.26688
1880.8	8.47563
1882.58	7.78908
1885.57	7.56266
1888.56	8.70785
1891.54	9.93335
1894.53	10.2656
1897.51	9.05845
1900.5	8.45477
1903.48	8.842
1906.46	9.10738
1909.44	10.6818
1912.42	10.2697
1915.4	10.6506
1918.37	9.76739
1921.35	9.26772
1924.32	7.52855
1927.3	7.1419
1930.27	8.52481
1933.24	7.47618
1936.21	6.62068
1939.18	6.56555
1942.15	6.92067
1945.11	6.12517
1948.08	5.55176
1951.04	5.32682
1954.01	5.87964
1956.97	6.66253
1959.93	7.38441
1962.89	8.16846
1965.85	7.59951
1968.81	6.08964
1971.77	6.07776
1974.72	4.83489
1977.68	5.52713
1980.63	5.45008
1983.58	4.3061
1986.53	4.69463
1989.48	3.71824
1992.43	3.51472
1995.38	3.24911
1998.33	3.50637
2001.27	3.32345
2004.22	2.66802
2007.16	3.20006
2010.11	3.08828
2013.05	3.96212
2015.99	4.21631
2018.93	4.19955
2021.87	5.12948
2024.8	6.83856
2027.74	8.22423
2030.68	9.45765
2033.61	10.9567
2036.54	10.6665
2039.48	11.5542
2042.41	12.3215
2045.34	12.8196
2048.27	13.8126
2051.19	15.6071
2054.12	15.7195
2057.05	15.9863
2059.97	15.6883
2062.9	15.4826
2065.82	14.8524
2068.74	14.631
2071.66	15.3761
2074.58	16.1284
2077.5	17.9054
2080.41	18.5561
2083.33	18.0331
2086.24	17.2981
2089.16	17.8902
2092.07	16.8115
2094.98	17.0443
2097.89	16.3289
2100.8	16.97
2103.71	17.916
2106.62	17.8565
2109.53	18.055
2112.43	19.3315
2115.33	20.4068
2118.24	20.8851
2121.14	22.3025
2124.04	22.6289
2126.94	24.4698
2129.84	25.2456
2132.74	26.723
2135.63	28.5832
2138.53	31.0449
2141.43	33.6018
2144.32	36.5351
2147.21	39.844
2150.1	41.9303
2152.99	43.379
2155.88	44.8563
2158.77	46.7765
2161.66	47.6606
2164.55	48.6292
2167.43	49.7889
2170.31	50.8838
2173.2	52.585
2176.08	52.5999
2178.96	52.8741
2181.84	51.8005
2184.72	51.0985
2187.6	49.7196
2190.47	48.4769
2193.35	46.9188
2196.23	44.7129
2199.1	41.4696
2201.97	38.8217
2204.84	38.2612
2207.71	36.6984
2210.58	34.1898
2213.45	32.8951
2216.32	30.6517
2219.19	28.6091
2222.05	26.1057
2224.92	23.7206
2227.78	20.7762
2230.64	18.9261
2233.5	17.1889
2236.36	17.0594
2239.22	16.7583
2242.08	16.1339
2244.94	16.487
2247.79	16.4229
2250.65	14.9943
2253.5	15.6987
2256.36	16.1006
2259.21	16.6818
2262.06	15.6184
2264.91	16.3367
2267.76	16.0929
2270.6	16.829
2273.45	17.3038
2276.3	18.2024
2279.14	17.3157
2281.98	16.0854
2284.83	14.8663
2287.67	13.1834
2290.51	11.8966
2293.35	8.25523
2296.19	6.0845
2299.02	5.00867
2301.86	6.174
2304.7	6.33372
2307.53	6.51294
2310.36	7.04558
2313.2	7.52073
2316.03	6.96534
2318.86	6.34497
2321.69	5.40593
2324.51	6.11655
2327.34	5.9352
2330.17	6.3435
2332.99	7.77505
2335.82	7.09822
2338.64	8.08749
2341.46	7.60933
2344.28	6.99145
2347.1	6.76736
2349.92	6.2446
2352.74	6.35138
2355.56	5.43888
2358.37	4.79047
2361.19	4.5764
2364	4.05109
2366.82	5.14975
2369.63	4.43046
2372.44	4.33346
2375.25	4.77841
2378.06	4.03767
2380.86	4.00065
2383.67	3.24187
2386.48	2.0722
2389.28	1.54009
2392.09	1.91842
2394.89	1.3853
2397.69	1.36715
2400.49	2.17267
2403.29	3.4201
2406.09	3.167
2408.89	3.4477
2411.69	3.38993
2414.48	4.32074
2417.28	5.15415
2420.07	6.62319
2422.86	7.35316
2425.65	8.0944
2428.45	8.00014
2431.23	8.49436
2434.02	8.43443
2436.81	8.78966
2439.6	9.57587
2442.38	11.2681
2445.17	11.0692
2447.95	10.9526
2450.73	12.113
2453.52	11.5689
2456.3	11.4409
2459.08	9.73288
2461.85	9.77738
2464.63	8.44251
2467.41	8.56036
2470.19	7.12993
2472.96	6.12366
2475.73	4.63369
2478.51	3.23311
2481.28	1.23368
2484.05	-0.0848751
2486.82	-0.561897
2489.59	-1.42534
2492.35	-2.48241
2495.12	-1.82702
2497.89	-1.06659
2500.65	-0.818338
2503.42	-0.617363
2506.18	1.20455
2508.94	2.34997
2511.7	3.13618
2514.46	3.8414
2517.22	5.6274
2519.98	6.75582
2522.73	8.61479
2525.49	9.48642
2528.25	9.93638
2531	10.9279
2533.75	10.487
2536.5	11.2671
2539.25	11.115
2542.01	10.2775
2544.75	9.2658
2547.5	9.00717
2550.25	9.73765
2553	9.00893
2555.74	9.57298
2558.49	8.81607
2561.23	8.91325
2563.97	9.26363
2566.71	8.29459
2569.45	8.24784
2572.19	8.62672
2574.93	8.86602
2577.67	8.32927
2580.4	8.80079
2583.14	9.12513
2585.87	8.31512
2588.6	8.87442
2591.34	7.28687
2594.07	6.08727
2596.8	6.61922
2599.53	6.14313
2602.26	5.13328
2604.98	4.34864
2607.71	2.78906
2610.44	2.86549
2613.16	2.59641
2615.88	3.20032
2618.61	3.36655
2621.33	2.80705
2624.05	3.28811
2626.77	4.55718
2629.49	5.58011
2632.21	6.98951
2634.92	8.1822
2637.64	8.80984
2640.35	8.88059
2643.07	10.0559
2645.78	10.1576
2648.49	10.5711
2651.2	9.52176
2653.91	8.65465
2656.62	8.5768
2659.33	8.71981
2662.04	9.50789
2664.74	9.31186
2667.45	8.87255
2670.15	8.99216
2672.86	9.18881
2675.56	8.6952
2678.26	9.13219
2680.96	10.1143
2683.66	10.539
2686.36	10.893
2689.06	12.7083
2691.75	14.0675
2694.45	15.4083
2697.14	15.2465
2699.84	15.1982
2702.53	16.5812
2705.22	17.6002
2707.91	18.7591
2710.6	18.9606
2713.29	17.9316
2715.98	16.8218
2718.67	16.7094
2721.35	17.1825
2724.04	17.6401
2726.72	17.4817
2729.4	17.1966
2732.09	17.0896
2734.77	16.3814
2737.45	16.4819
2740.13	15.414
2742.81	13.9427
2745.48	12.8883
2748.16	11.2892
2750.84	9.67259
2753.51	8.11324
2756.19	7.0208
2758.86	5.63307
2761.53	4.31145
2764.2	3.14006
2766.87	3.59993
2769.54	3.30321
2772.21	2.33965
2774.88	1.61929
2777.54	1.5438
2780.21	1.53747
2782.87	1.50103
2785.53	2.42452
2788.2	2.63834
2790.86	2.84756
2793.52	3.00045
2796.18	4.13082
2798.84	4.38124
2801.49	4.83248
2804.15	4.60595
2806.81	4.01603
2809.46	3.34496
2812.12	2.56749
2814.77	1.88339
2817.42	4.16244
2820.07	7.50126
2822.72	11.2673
2825.37	16.0082
2828.02	21.637
2830.67	28.5034
2833.31	34.5856
2835.96	41.9585
2838.61	48.8586
2841.25	57.0916
2843.89	66.0487
2846.53	74.108
2849.17	83.9138
2851.81	95.1907
2854.45	107.474
2857.09	119.238
2859.73	130.292
2862.36	141.922
2865	151.259
2867.64	160.333
2870.27	167.871
2872.9	173.996
2875.53	180.358
2878.16	186.323
2880.79	193.686
2883.42	200.423
2886.05	205.875
2888.68	209.829
2891.3	216.043
2893.93	219.893
2896.55	225.166
2899.18	229.064
2901.8	234.085
2904.42	240.27
2907.04	247.937
2909.66	257.24
2912.28	266.728
2914.9	277.724
2917.51	286.191
2920.13	295.111
2922.74	302.526
2925.36	308.115
2927.97	311.358
2930.59	311.48
2933.2	308.234
2935.81	303.722
2938.42	297.687
2941.02	289.764
2943.63	279.415
2946.24	269.039
2948.85	256.357
2951.45	243.783
2954.05	231.71
2956.66	219.007
2959.26	206.126
2961.86	195.676
2964.46	184.596
2967.06	174.52
2969.66	166.994
2972.26	158.946
2974.85	150.609
2977.45	142.643
2980.05	134.49
2982.64	126.53
2985.23	118.285
2987.83	111.601
2990.42	101.681
2993.01	91.4279
2995.6	83.5784
2998.19	75.1589
3000.77	65.7108
3003.36	56.0418
3005.95	48.7683
3008.53	41.4743
3011.12	33.8502
3013.7	28.6604
3016.28	23.3797
3018.86	19.5209
3021.44	14.9351
3024.02	10.7544
3026.6	6.71586
3029.18	5.13617
3031.76	2.78183
3034.33	1.11985
3036.91	-0.203884
3039.48	-1.92359
3042.05	-1.8663
3044.63	-1.2903
3047.2	0.192892
3049.77	0.926448
3052.34	2.15799
3054.91	3.33356
3057.48	4.25167
3060.04	5.65861
3062.61	5.13998
3065.17	5.22263
3067.74	6.5932
3070.3	6.92082
3072.87	7.17746
3075.43	8.4621
3077.99	8.85004
3080.55	7.47271
3083.11	7.60563
3085.67	5.59513
3088.22	4.58372
3090.78	4.38163
3093.34	4.6512
3095.89	4.18546
3098.44	4.02807
3101	5.12362
3103.55	6.57987
3106.1	8.34191
3108.65	10.2762
3111.2	11.8477
3113.75	13.6487
3116.3	15.6241
3118.84	16.72
3121.39	18.4251
3123.93	20.2974
3126.48	22.9048
3129.02	24.482
3131.56	26.9725
3134.1	30.2727
3136.64	31.5568
3139.18	32.3214
3141.72	33.212
3144.26	34.2402
3146.8	35.0033
3149.33	36.1333