File: data/Raman/poly_smoothed/Mbcal_20_25_25_1x_45s_532 nm_x100_100%_600 gr_mm_01.txt
#Acq. time (s)=	45
#Accumulations=	2
#Range (cm-¹)=	200...3150
#Windows=	2
#Auto scanning=	Off
#Autofocus=	Off
#Macrospot=	Off
#AutoExposure=	Off
#Spike filter=	Multiple accum.
#Delay time (s)=	0
#Binning=	1
#Readout mode=	Signal
#DeNoise=	Off
#ICS correction=	On
#Dark correction=	Off
#Inst. Process=	Off
#Detector Gain=	Best Dynamic Range
#Detector ADC=	20 kHz
#Detector temperature (°C)=	-69.85
#Instrument=	LabRAM HR Evol
#Detector=	Synapse
#Objective=	x100
#Grating=	600 gr/mm
#ND Filter=	100%
#Laser (nm)=	532
#Hole=	100.021
#Range=	Auto
#Laser Pol.=	No
#Raman. Pol.=	No
#Laser Pol. (°)=	-0.0007625
#Raman Pol. (°)=	89.9995
#Collection=	Microscope
#StageXY=	Marzhauser
#StageZ=	Marzhauser
#X (µm)=	-1175.2
#Y (µm)=	1298.7
#Z (µm)=	577.85
#Full time(mm:ss)=	3:18
#Project=
#Sample=
#Site=
#Title=	Mbcal_20_25_25_2x_45s_532 nm_x100_100%_600 gr_mm
#Remark=
#Date=	18.07.2022 11:28
#Acquired=	18.07.2022 11:28:15
#Base:Fit=	10.08.2022 10:55:08
#Base:Sub=	10.08.2022 10:55:14
#Filter:Polynom=	16.08.2022 10:07:28
#AxisType[0]=Intens
#AxisUnit[0]=Cnt
#AxisType[1]=Spectr
#AxisUnit[1]=1/cm
200.419	6.18832
204.048	6.46159
207.678	8.06067
211.304	9.65293
214.928	11.204
218.554	11.9209
222.176	15.7853
225.798	18.3937
229.417	22.4369
233.035	24.6985
236.653	26.9356
240.268	28.4757
243.881	30.8144
247.493	33.9589
251.103	35.9328
254.715	37.8233
258.322	38.6004
261.929	39.3842
265.534	41.0256
269.137	41.6154
272.739	44.7156
276.34	47.1386
279.939	45.8176
283.537	42.8062
287.134	43.2278
290.729	45.4676
294.323	46.1822
297.913	47.2724
301.504	50.1868
305.093	54.1504
308.682	57.431
312.268	60.2637
315.852	61.6946
319.436	62.5446
323.018	63.9274
326.597	65.0062
330.177	64.7378
333.753	68.222
337.331	68.2145
340.906	66.2584
344.478	65.9044
348.051	62.4401
351.621	61.6082
355.189	60.7548
358.757	57.6708
362.323	56.0616
365.889	50.139
369.451	45.613
373.012	43.4253
376.574	42.1637
380.133	39.4423
383.69	37.4203
387.245	37.3307
390.8	34.9392
394.353	33.7388
397.906	29.9119
401.456	28.7471
405.005	26.7533
408.552	27.0139
412.099	25.6179
415.643	22.8007
419.187	23.8861
422.728	22.4542
426.269	20.6922
429.806	19.6512
433.344	19.0165
436.881	17.6992
440.416	15.5755
443.949	14.4537
447.48	13.0293
451.011	14.1233
454.541	14.9668
458.069	15.4069
461.594	15.7561
465.119	17.5355
468.642	18.5965
472.165	19.5515
475.684	20.9859
479.204	22.0323
482.721	24.8322
486.239	26.3908
489.753	29.6377
493.268	30.7657
496.779	32.5945
500.289	33.1422
503.8	33.7085
507.307	33.7557
510.813	33.3925
514.32	31.7921
517.823	31.2594
521.325	30.9775
524.826	31.6907
528.325	32.8877
531.823	32.6949
535.32	33.0954
538.815	31.6774
542.309	29.4594
545.802	28.4387
549.293	28.4035
552.783	27.2836
556.271	22.9372
559.759	20.2037
563.245	19.3393
566.729	17.7439
570.213	14.9983
573.693	12.6232
577.173	11.1688
580.652	8.53126
584.13	6.17111
587.605	3.92372
591.08	1.85966
594.552	0.842954
598.025	0.191436
601.496	1.44276
604.964	2.24657
608.433	2.96811
611.898	4.89595
615.364	4.81322
618.827	4.26046
622.288	3.83724
625.75	5.51943
629.209	7.58567
632.667	10.4205
636.125	9.69639
639.58	9.79911
643.033	9.14142
646.485	9.22753
649.936	8.39856
653.388	9.60207
656.836	9.35333
660.283	8.86253
663.728	7.43925
667.173	5.93652
670.616	5.40657
674.057	5.94103
677.498	4.3511
680.937	5.16377
684.375	4.79562
687.809	6.81961
691.244	6.68663
694.678	8.29586
698.111	9.34142
701.54	9.7444
704.97	10.5078
708.398	12.4538
711.826	14.1342
715.25	15.8363
718.675	17.4829
722.096	17.2629
725.518	18.7492
728.937	17.8852
732.357	19.7964
735.773	18.9287
739.19	19.2133
742.604	19.2178
746.018	18.1291
749.429	18.7468
752.839	21.3705
756.248	23.0115
759.657	26.1265
763.063	26.3587
766.468	28.2881
769.871	31.1379
773.273	33.5537
776.676	35.6883
780.075	36.6209
783.474	39.2381
786.871	41.2782
790.266	43.6985
793.661	45.9674
797.054	50.124
800.446	52.2335
803.834	51.3674
807.224	52.7493
810.612	52.423
813.998	50.3407
817.384	51.1054
820.766	49.5259
824.149	49.7121
827.531	51.3796
830.909	52.6197
834.288	55.5447
837.666	55.8231
841.041	56.527
844.416	55.5661
847.788	54.9201
851.161	52.7443
854.53	52.847
857.901	52.8783
861.268	52.7689
864.633	52.613
868	50.9105
871.363	50.1244
874.725	49.6025
878.088	46.5488
881.447	44.7696
884.805	41.1276
888.162	36.6903
891.518	32.5021
894.872	29.6758
898.225	27.5914
901.577	25.6732
904.928	23.6898
908.277	21.8403
911.625	21.4775
914.972	21.0468
918.318	20.1775
921.662	19.4041
925.005	17.3374
928.347	17.903
931.686	17.7442
935.025	19.3001
938.363	18.4596
941.698	19.3859
945.034	19.2069
948.368	20.1434
951.699	20.1683
955.031	22.01
958.36	18.0507
961.689	17.124
965.016	20.2997
968.343	20.6827
971.666	22.4378
974.991	23.0643
978.312	22.3926
981.632	24.6344
984.953	23.9299
988.27	23.1426
991.587	24.0159
994.902	24.0661
998.216	24.3557
1001.53	23.6913
1004.84	22.574
1008.15	22.5827
1011.46	23.297
1014.77	21.8477
1018.07	20.8432
1021.38	17.7514
1024.68	20.3134
1027.99	22.8627
1031.29	25.4109
1034.59	25.2403
1037.89	26.009
1041.18	24.8788
1044.48	29.1641
1047.77	32.5274
1051.07	35.0101
1054.36	34.9595
1057.65	32.7515
1060.94	32.8014
1064.23	33.8551
1067.52	33.9855
1070.8	35.7232
1074.09	36.7752
1077.37	37.0005
1080.65	36.8442
1083.93	37.7693
1087.21	35.1509
1090.49	34.7604
1093.77	32.9451
1097.04	33.6305
1100.32	33.0195
1103.59	35.0108
1106.86	34.9763
1110.13	35.2224
1113.4	34.0514
1116.67	31.8311
1119.94	29.2539
1123.2	28.2114
1126.47	27.6361
1129.73	25.3938
1132.99	21.2247
1136.25	17.8115
1139.51	16.6222
1142.77	16.475
1146.03	14.2924
1149.28	12.6321
1152.54	12.1178
1155.79	9.33
1159.04	7.90354
1162.29	5.24459
1165.54	2.12941
1168.79	-0.948711
1172.04	-0.792701
1175.28	-0.746235
1178.53	-0.29212
1181.77	-0.35365
1185.01	-0.485866
1188.25	1.85082
1191.49	5.16379
1194.73	6.23455
1197.96	7.64921
1201.2	12.2568
1204.43	16.6401
1207.66	20.8783
1210.9	25.029
1214.13	30.7765
1217.36	35.6749
1220.58	41.6482
1223.81	48.8422
1227.04	53.9477
1230.26	56.3276
1233.48	59.5921
1236.71	63.8468
1239.93	68.5668
1243.14	72.3121
1246.36	74.6452
1249.58	79.6478
1252.8	83.465
1256.01	84.6368
1259.22	87.9897
1262.43	90.8263
1265.64	96.9609
1268.85	101.438
1272.06	105.238
1275.27	110.438
1278.48	116.036
1281.68	120.159
1284.88	124.483
1288.08	129.427
1291.28	133.164
1294.48	136.013
1297.68	139.969
1300.88	140.895
1304.07	142.003
1307.27	142.267
1310.46	143.187
1313.65	143.109
1316.85	144.768
1320.03	143.552
1323.22	140.083
1326.41	135.428
1329.6	132.432
1332.78	126.525
1335.96	123.165
1339.15	122.258
1342.33	120.322
1345.51	117.736
1348.69	113.667
1351.86	112.757
1355.04	110.75
1358.21	106.414
1361.39	102.276
1364.56	100.365
1367.73	97.6354
1370.9	95.4551
1374.07	94.0261
1377.24	91.0579
1380.41	91.4682
1383.57	91.4667
1386.73	91.155
1389.9	89.9212
1393.06	90.5596
1396.22	90.2072
1399.38	91.055
1402.54	94.2215
1405.69	99.7179
1408.85	105.782
1412	114.224
1415.16	126.171
1418.31	137.955
1421.46	148.565
1424.61	160.999
1427.76	175.475
1430.9	186.772
1434.05	200.724
1437.2	208.885
1440.34	217.665
1443.48	223.15
1446.62	228.057
1449.76	229.471
1452.9	225.328
1456.04	222.816
1459.17	216.041
1462.31	208.28
1465.44	198.791
1468.58	186.493
1471.71	173.681
1474.84	159.667
1477.97	146.542
1481.1	134.397
1484.22	123.326
1487.35	110.994
1490.47	100.565
1493.59	89.8847
1496.72	80.929
1499.84	73.0608
1502.96	68.2027
1506.08	64.2711
1509.19	60.3382
1512.31	54.6513
1515.42	51.035
1518.54	48.9498
1521.65	46.8642
1524.76	45.6914
1527.87	44.0485
1530.98	43.299
1534.09	44.9547
1537.2	46.3063
1540.3	50.9362
1543.41	52.8167
1546.51	54.8861
1549.61	58.3499
1552.71	60.0125
1555.81	64.2066
1558.91	67.2308
1562.01	69.7986
1565.1	73.8969
1568.2	77.2513
1571.29	81.552
1574.38	85.2268
1577.48	90.3695
1580.57	95.2453
1583.65	99.6649
1586.74	101.679
1589.83	104.396
1592.92	107.954
1596	109.706
1599.08	111.119
1602.16	111.101
1605.24	109.639
1608.32	106.645
1611.4	106.491
1614.48	104.43
1617.56	101.606
1620.63	98.8911
1623.71	97.3827
1626.78	98.1362
1629.85	98.213
1632.92	100.552
1635.99	102.801
1639.06	105.865
1642.12	107.988
1645.19	110.42
1648.25	114.583
1651.32	117.489
1654.38	118.106
1657.44	118.471
1660.5	118.286
1663.56	116.31
1666.62	113.987
1669.67	111.473
1672.73	105.424
1675.79	98.806
1678.84	89.49
1681.89	80.6688
1684.94	70.7307
1687.99	61.375
1691.04	51.4268
1694.08	44.2396
1697.13	38.2148
1700.18	33.0693
1703.22	28.8324
1706.26	24.4023
1709.3	21.3023
1712.35	19.5581
1715.39	16.6481
1718.42	15.4473
1721.46	15.5658
1724.5	15.9523
1727.53	15.5496
1730.56	14.8967
1733.6	16.0098
1736.63	14.9977
1739.66	15.7518
1742.69	14.5008
1745.71	13.058
1748.74	12.5383
1751.77	11.2442
1754.79	10.9435
1757.81	9.21983
1760.84	7.48278
1763.86	7.18929
1766.88	5.39431
1769.9	4.88958
1772.91	3.89787
1775.93	3.93607
1778.95	3.27157
1781.96	2.94498
1784.97	3.02756
1787.99	2.51713
1791	1.85757
1794.01	4.39392
1797.01	6.05756
1800.02	6.53455
1803.03	6.9552
1806.03	7.58433
1809.04	7.75196
1812.04	7.19053
1815.04	7.27019
1818.04	5.38839
1821.04	5.9748
1824.04	6.06957
1827.04	5.85099
1830.03	4.82658
1833.03	3.93809
1836.02	4.24572
1839.02	4.95257
1842.01	5.56874
1845	5.6974
1847.99	5.67185
1850.98	4.72693
1853.96	4.46381
1856.95	3.95831
1859.94	3.46528
1862.92	4.50052
1865.9	5.84644
1868.88	6.30158
1871.86	6.15241
1874.84	7.12756
1877.82	7.3498
1880.8	7.41805
1882.58	6.29019
1885.57	5.19255
1888.56	5.10583
1891.54	3.6754
1894.53	3.06157
1897.51	2.23146
1900.5	0.540456
1903.48	0.776606
1906.46	1.83515
1909.44	3.02852
1912.42	3.55957
1915.4	3.46434
1918.37	3.27366
1921.35	4.47473
1924.32	4.09202
1927.3	4.4098
1930.27	4.9368
1933.24	5.26031
1936.21	7.40429
1939.18	6.00662
1942.15	6.05608
1945.11	5.34274
1948.08	5.27429
1951.04	4.64365
1954.01	4.76897
1956.97	4.95913
1959.93	3.99003
1962.89	2.91241
1965.85	1.71805
1968.81	1.07836
1971.77	0.404811
1974.72	0.547859
1977.68	1.06141
1980.63	1.45796
1983.58	2.23679
1986.53	1.37779
1989.48	2.69251
1992.43	3.19415
1995.38	3.06947
1998.33	5.0571
2001.27	4.52394
2004.22	4.92074
2007.16	4.14371
2010.11	5.23612
2013.05	4.69517
2015.99	5.10043
2018.93	5.19307
2021.87	6.8639
2024.8	7.3504
2027.74	7.22588
2030.68	7.78338
2033.61	6.44894
2036.54	7.15552
2039.48	7.05508
2042.41	6.76217
2045.34	6.20386
2048.27	7.79919
2051.19	8.5113
2054.12	8.07459
2057.05	7.78909
2059.97	7.59171
2062.9	7.7532
2065.82	7.7838
2068.74	8.72195
2071.66	6.80919
2074.58	5.99637
2077.5	8.12493
2080.41	7.90639
2083.33	8.48068
2086.24	9.44089
2089.16	11.0145
2092.07	11.592
2094.98	13.299
2097.89	15.3586
2100.8	17.3304
2103.71	18.9218
2106.62	20.622
2109.53	22.1703
2112.43	22.2277
2115.33	24.5189
2118.24	26.0978
2121.14	26.9957
2124.04	29.1529
2126.94	31.5341
2129.84	33.766
2132.74	36.1246
2135.63	39.3956
2138.53	41.8571
2141.43	45.5163
2144.32	50.4948
2147.21	55.2028
2150.1	58.8427
2152.99	62.6542
2155.88	66.393
2158.77	69.7743
2161.66	72.2032
2164.55	74.9175
2167.43	77.7952
2170.31	79.2555
2173.2	79.5466
2176.08	79.5738
2178.96	78.0849
2181.84	76.8419
2184.72	76.0523
2187.6	73.1038
2190.47	70.0258
2193.35	67.3323
2196.23	64.3586
2199.1	61.3925
2201.97	58.3701
2204.84	55.6211
2207.71	52.9861
2210.58	50.3506
2213.45	48.6358
2216.32	45.5575
2219.19	42.2391
2222.05	39.3516
2224.92	36.8468
2227.78	32.2777
2230.64	29.7274
2233.5	27.4446
2236.36	25.0021
2239.22	22.9118
2242.08	20.8955
2244.94	20.5308
2247.79	18.715
2250.65	17.5093
2253.5	15.6261
2256.36	14.349
2259.21	12.3782
2262.06	11.4016
2264.91	10.7875
2267.76	9.67612
2270.6	8.70649
2273.45	8.42949
2276.3	7.50909
2279.14	7.17766
2281.98	6.15441
2284.83	6.28031
2287.67	5.40442
2290.51	5.67274
2293.35	3.89983
2296.19	3.19093
2299.02	4.27885
2301.86	4.70426
2304.7	5.1574
2307.53	6.0205
2310.36	6.05954
2313.2	7.30777
2316.03	7.04672
2318.86	7.6124
2321.69	8.2338
2324.51	8.50726
2327.34	9.02854
2330.17	7.02336
2332.99	6.2248
2335.82	4.52442
2338.64	4.19843
2341.46	4.3143
2344.28	3.93709
2347.1	2.42585
2349.92	2.31957
2352.74	0.54339
2355.56	0.332667
2358.37	-0.0299678
2361.19	0.200201
2364	-0.831435
2366.82	-1.18207
2369.63	-2.10755
2372.44	-1.90746
2375.25	-0.258905
2378.06	-0.132193
2380.86	-0.0820038
2383.67	1.67125
2386.48	1.58875
2389.28	2.44781
2392.09	3.36085
2394.89	3.51583
2397.69	2.84252
2400.49	3.05534
2403.29	2.67693
2406.09	3.0209
2408.89	4.01893
2411.69	4.67628
2414.48	4.03883
2417.28	4.82688
2420.07	6.48368
2422.86	7.29313
2425.65	8.1787
2428.45	6.4271
2431.23	6.29312
2434.02	5.19433
2436.81	5.85098
2439.6	7.05839
2442.38	8.75288
2445.17	8.49805
2447.95	8.9467
2450.73	9.11488
2453.52	8.78343
2456.3	8.46501
2459.08	8.85217
2461.85	7.75137
2464.63	6.70272
2467.41	5.66252
2470.19	3.89583
2472.96	2.88539
2475.73	2.77368
2478.51	2.78224
2481.28	3.76868
2484.05	3.53356
2486.82	3.20089
2489.59	2.92815
2492.35	2.54695
2495.12	2.04744
2497.89	1.50209
2500.65	1.83335
2503.42	2.18493
2506.18	2.94584
2508.94	3.69222
2511.7	3.36312
2514.46	4.49394
2517.22	3.94184
2519.98	4.63243
2522.73	4.14564
2525.49	4.6615
2528.25	5.2312
2531	5.8158
2533.75	5.9339
2536.5	6.75267
2539.25	7.03589
2542.01	8.90958
2544.75	10.359
2547.5	11.3871
2550.25	13.2971
2553	13.343
2555.74	14.2005
2558.49	14.7752
2561.23	15.0007
2563.97	14.9082
2566.71	14.5489
2569.45	13.9705
2572.19	12.666
2574.93	11.4627
2577.67	11.6963
2580.4	11.1994
2583.14	11.1451
2585.87	10.6908
2588.6	9.64347
2591.34	8.90297
2594.07	9.20928
2596.8	8.23327
2599.53	7.8591
2602.26	6.86073
2604.98	7.64027
2607.71	7.06832
2610.44	6.29557
2613.16	7.42494
2615.88	8.88328
2618.61	8.98726
2621.33	8.03928
2624.05	8.0329
2626.77	8.89263
2629.49	9.02452
2632.21	9.29925
2634.92	9.0901
2637.64	8.09444
2640.35	8.4188
2643.07	10.0999
2645.78	10.5836
2648.49	11.4253
2651.2	12.6581
2653.91	12.7557
2656.62	13.5701
2659.33	14.3531
2662.04	14.6547
2664.74	14.7599
2667.45	16.724
2670.15	17.5643
2672.86	17.4574
2675.56	17.0111
2678.26	17.8458
2680.96	17.9704
2683.66	17.5371
2686.36	17.4868
2689.06	17.0033
2691.75	17.8034
2694.45	18.5643
2697.14	18.8541
2699.84	19.0942
2702.53	20.6049
2705.22	22.6639
2707.91	24.3004
2710.6	26.8371
2713.29	27.9903
2715.98	29.6008
2718.67	30.6737
2721.35	31.6624
2724.04	32.1544
2726.72	32.4947
2729.4	33.3243
2732.09	33.1389
2734.77	32.0999
2737.45	29.637
2740.13	27.4588
2742.81	24.4908
2745.48	22.5845
2748.16	19.6052
2750.84	17.2864
2753.51	14.3372
2756.19	12.1368
2758.86	10.4797
2761.53	7.86311
2764.2	6.01236
2766.87	4.35264
2769.54	3.14561
2772.21	1.60647
2774.88	0.864294
2777.54	0.638909
2780.21	-1.03612
2782.87	-0.925579
2785.53	-1.36596
2788.2	-1.2532
2790.86	-1.10898
2793.52	-0.425787
2796.18	-0.348016
2798.84	-0.894931
2801.49	-0.647392
2804.15	-2.08002
2806.81	-2.1958
2809.46	-2.15009
2812.12	-3.11236
2814.77	-1.52498
2817.42	3.19749
2820.07	10.8024
2822.72	23.5395
2825.37	37.7507
2828.02	52.925
2830.67	70.525
2833.31	89.4723
2835.96	109.535
2838.61	129.704
2841.25	150.259
2843.89	170.691
2846.53	192.827
2849.17	215.907
2851.81	240.825
2854.45	265.837
2857.09	291.18
2859.73	312.685
2862.36	333.82
2865	352.461
2867.64	366.44
2870.27	378.065
2872.9	388.933
2875.53	397.855
2878.16	407.424
2880.79	418.193
2883.42	427.789
2886.05	437.075
2888.68	446.131
2891.3	452.779
2893.93	458.988
2896.55	464.95
2899.18	470.24
2901.8	477.506
2904.42	486.197
2907.04	497.343
2909.66	511.245
2912.28	527.686
2914.9	545.537
2917.51	561.079
2920.13	574.921
2922.74	585.79
2925.36	589.832
2927.97	593.525
2930.59	590.066
2933.2	583.892
2935.81	574.642
2938.42	563.169
2941.02	547.725
2943.63	529.476
2946.24	509.123
2948.85	486.461
2951.45	462.426
2954.05	437.577
2956.66	411.612
2959.26	387.906
2961.86	365.222
2964.46	343.664
2967.06	323.926
2969.66	305.706
2972.26	288.703
2974.85	271.565
2977.45	254.855
2980.05	237.306
2982.64	218.853
2985.23	201.352
2987.83	181.564
2990.42	162.224
2993.01	144.83
2995.6	126.679
2998.19	109.918
3000.77	94.4538
3003.36	80.5858
3005.95	66.5015
3008.53	54.2792
3011.12	42.6787
3013.7	32.0327
3016.28	24.0745
3018.86	16.5106
3021.44	10.2894
3024.02	5.19621
3026.6	2.3545
3029.18	0.0744198
3031.76	-1.26777
3034.33	-1.01581
3036.91	-0.512016
3039.48	1.0274
3042.05	2.2868
3044.63	4.31974
3047.2	6.04168
3049.77	7.78562
3052.34	9.37043
3054.91	12.1377
3057.48	12.7315
3060.04	12.6109
3062.61	13.775
3065.17	13.709
3067.74	13.0195
3070.3	11.4335
3072.87	10.5941
3075.43	9.66381
3077.99	8.52971
3080.55	6.59389
3083.11	4.93164
3085.67	4.12693
3088.22	3.22693
3090.78	3.43055
3093.34	3.77751
3095.89	3.68498
3098.44	4.31307
3101	5.07031
3103.55	6.54777
3106.1	8.248
3108.65	10.204
3111.2	13.1685
3113.75	15.2518
3116.3	16.4667
3118.84	18.5077
3121.39	20.5578
3123.93	23.0643
3126.48	25.7852
3129.02	28.0899
3131.56	31.4033
3134.1	33.8713
3136.64	38.257
3139.18	41.114
3141.72	44.7964
3144.26	48.9538
3146.8	53.6512
3149.33	57.8119