File: data/Raman/poly_smoothed/Mbcal_20_25_38_1x_45s_532 nm_x100_100%_600 gr_mm_01.txt
#Acq. time (s)=	45
#Accumulations=	2
#Range (cm-¹)=	200...3150
#Windows=	2
#Auto scanning=	Off
#Autofocus=	Off
#Macrospot=	Off
#AutoExposure=	Off
#Spike filter=	Multiple accum.
#Delay time (s)=	0
#Binning=	1
#Readout mode=	Signal
#DeNoise=	Off
#ICS correction=	On
#Dark correction=	Off
#Inst. Process=	Off
#Detector Gain=	Best Dynamic Range
#Detector ADC=	20 kHz
#Detector temperature (°C)=	-69.85
#Instrument=	LabRAM HR Evol
#Detector=	Synapse
#Objective=	x100
#Grating=	600 gr/mm
#ND Filter=	100%
#Laser (nm)=	532
#Hole=	100.021
#Range=	Auto
#Laser Pol.=	No
#Raman. Pol.=	No
#Laser Pol. (°)=	-0.0007625
#Raman Pol. (°)=	89.9995
#Collection=	Microscope
#StageXY=	Marzhauser
#StageZ=	Marzhauser
#X (µm)=	-1107.4
#Y (µm)=	1296.8
#Z (µm)=	578.55
#Full time(mm:ss)=	3:18
#Project=
#Sample=
#Site=
#Title=	Mbcal_20_25_38_2x_45s_532 nm_x100_100%_600 gr_mm
#Remark=
#Date=	18.07.2022 13:05
#Acquired=	18.07.2022 13:05:44
#Base:Fit=	10.08.2022 10:55:08
#Base:Sub=	10.08.2022 10:55:14
#Filter:Polynom=	16.08.2022 10:07:28
#AxisType[0]=Intens
#AxisUnit[0]=Cnt
#AxisType[1]=Spectr
#AxisUnit[1]=1/cm
200.419	10.1811
204.048	7.59537
207.678	6.00722
211.304	4.77002
214.928	3.80205
218.554	4.50134
222.176	5.41048
225.798	2.81296
229.417	5.29519
233.035	4.94214
236.653	5.6568
240.268	6.54991
243.881	7.86276
247.493	9.21364
251.103	10.0784
254.715	9.80021
258.322	10.2308
261.929	10.3733
265.534	10.8566
269.137	8.77989
272.739	6.89667
276.34	6.99166
279.939	5.75471
283.537	3.54655
287.134	2.24065
290.729	0.404897
294.323	1.21541
297.913	2.47378
301.504	5.743
305.093	8.7907
308.682	12.6244
312.268	14.0348
315.852	18.4061
319.436	23.7134
323.018	26.9198
326.597	30.5708
330.177	36.2018
333.753	38.7904
337.331	40.1101
340.906	41.6827
344.478	41.297
348.051	42.5907
351.621	41.9124
355.189	37.1087
358.757	36.2191
362.323	32.8014
365.889	30.6543
369.451	28.0647
373.012	25.7756
376.574	26.2626
380.133	26.9124
383.69	26.4268
387.245	29.83
390.8	30.1861
394.353	30.6071
397.906	30.5516
401.456	32.3603
405.005	31.2805
408.552	30.9372
412.099	32.9833
415.643	33.6189
419.187	32.1778
422.728	30.5263
426.269	28.3387
429.806	24.6653
433.344	23.9956
436.881	21.1577
440.416	17.33
443.949	15.8746
447.48	17.4711
451.011	17.197
454.541	18.081
458.069	18.0096
461.594	17.8156
465.119	19.6613
468.642	23.3153
472.165	27.2051
475.684	29.6937
479.204	30.7873
482.721	33.9465
486.239	36.8503
489.753	36.3957
493.268	39.2344
496.779	42.5219
500.289	43.2167
503.8	44.6597
507.307	44.2121
510.813	46.334
514.32	47.0616
517.823	48.5826
521.325	48.3828
524.826	45.8349
528.325	46.3962
531.823	47.3742
535.32	46.1499
538.815	43.7046
542.309	42.9317
545.802	41.3256
549.293	40.4965
552.783	38.7834
556.271	37.7676
559.759	33.8382
563.245	32.2893
566.729	32.4947
570.213	28.7888
573.693	27.3048
577.173	24.6417
580.652	21.6387
584.13	18.4237
587.605	17.1671
591.08	15.5785
594.552	13.4082
598.025	13.2487
601.496	11.2155
604.964	11.057
608.433	10.074
611.898	9.29644
615.364	10.4138
618.827	8.63156
622.288	7.97493
625.75	7.93802
629.209	7.94486
632.667	7.65123
636.125	6.87592
639.58	6.83994
643.033	8.29716
646.485	10.3882
649.936	11.3982
653.388	10.6102
656.836	10.2247
660.283	11.0785
663.728	9.777
667.173	8.62887
670.616	9.98686
674.057	10.3083
677.498	10.6004
680.937	13.0134
684.375	14.7805
687.809	17.227
691.244	17.7519
694.678	19.9565
698.111	21.9709
701.54	22.5873
704.97	22.2796
708.398	23.1758
711.826	22.6503
715.25	23.6867
718.675	24.2272
722.096	24.6213
725.518	25.0293
728.937	25.6866
732.357	27.1839
735.773	27.0547
739.19	28.3575
742.604	28.1179
746.018	30.0254
749.429	30.698
752.839	31.8063
756.248	34.594
759.657	38.0869
763.063	41.0157
766.468	43.392
769.871	47.6144
773.273	51.0323
776.676	53.136
780.075	56.081
783.474	57.1545
786.871	58.6368
790.266	59.9728
793.661	60.3482
797.054	59.9319
800.446	65.4149
803.834	65.2828
807.224	65.0481
810.612	65.2707
813.998	64.856
817.384	65.9139
820.766	66.4463
824.149	66.2951
827.531	65.5074
830.909	70.8179
834.288	71.7955
837.666	73.7027
841.041	76.3134
844.416	77.5737
847.788	79.2928
851.161	78.0971
854.53	79.7465
857.901	77.7227
861.268	75.9731
864.633	72.962
868	70.1831
871.363	65.4595
874.725	62.4375
878.088	58.6592
881.447	54.8661
884.805	49.415
888.162	43.1812
891.518	37.7809
894.872	35.7035
898.225	32.5156
901.577	29.8426
904.928	30.4031
908.277	29.3456
911.625	28.487
914.972	29.9027
918.318	29.4354
921.662	29.2622
925.005	29.4623
928.347	28.008
931.686	27.7057
935.025	27.9658
938.363	28.107
941.698	24.5516
945.034	22.0012
948.368	18.8013
951.699	17.2477
955.031	16.9116
958.36	14.6567
961.689	12.0851
965.016	11.4436
968.343	13.9668
971.666	13.9659
974.991	13.4713
978.312	14.2602
981.632	13.4832
984.953	15.3572
988.27	15.1057
991.587	13.513
994.902	12.8493
998.216	12.7094
1001.53	13.5655
1004.84	12.7772
1008.15	13.5585
1011.46	16.0134
1014.77	17.6016
1018.07	19.6486
1021.38	19.1668
1024.68	21.3447
1027.99	21.7689
1031.29	24.0653
1034.59	24.8831
1037.89	24.4019
1041.18	24.773
1044.48	25.3413
1047.77	24.4058
1051.07	23.3213
1054.36	19.5619
1057.65	18.5236
1060.94	16.0325
1064.23	14.6312
1067.52	13.5978
1070.8	10.9016
1074.09	7.60455
1077.37	6.94603
1080.65	6.64551
1083.93	5.54327
1087.21	7.11675
1090.49	8.72391
1093.77	12.2053
1097.04	14.891
1100.32	16.0422
1103.59	18.0065
1106.86	20.9207
1110.13	21.7745
1113.4	23.6718
1116.67	24.0758
1119.94	24.2404
1123.2	24.1335
1126.47	25.6046
1129.73	24.0865
1132.99	25.1184
1136.25	27.3298
1139.51	27.9893
1142.77	26.2434
1146.03	24.1935
1149.28	22.3654
1152.54	19.9966
1155.79	18.2886
1159.04	17.2319
1162.29	16.3844
1165.54	14.8185
1168.79	14.9011
1172.04	15.447
1175.28	15.2432
1178.53	15.0174
1181.77	15.7225
1185.01	18.631
1188.25	20.2039
1191.49	20.2598
1194.73	21.2438
1197.96	21.8226
1201.2	26.1083
1204.43	29.7326
1207.66	32.4909
1210.9	36.3009
1214.13	43.3149
1217.36	45.6059
1220.58	48.114
1223.81	52.1341
1227.04	56.7497
1230.26	59.5845
1233.48	64.0716
1236.71	67.9152
1239.93	71.4214
1243.14	74.665
1246.36	77.6005
1249.58	81.4397
1252.8	84.0954
1256.01	86.2505
1259.22	88.9407
1262.43	92.1444
1265.64	95.1394
1268.85	97.3066
1272.06	100.546
1275.27	103.658
1278.48	106.997
1281.68	110.688
1284.88	114.344
1288.08	117.191
1291.28	122.273
1294.48	126.333
1297.68	129.429
1300.88	132.079
1304.07	136.814
1307.27	141.719
1310.46	146.327
1313.65	154.635
1316.85	160.986
1320.03	167.689
1323.22	174.721
1326.41	181.46
1329.6	187.886
1332.78	193.979
1335.96	198.285
1339.15	201.99
1342.33	204.827
1345.51	205.045
1348.69	201.615
1351.86	198.537
1355.04	193.34
1358.21	186.38
1361.39	179.235
1364.56	169.865
1367.73	160.354
1370.9	147.882
1374.07	138.195
1377.24	125.307
1380.41	115.526
1383.57	106.625
1386.73	102.053
1389.9	97.3836
1393.06	94.0789
1396.22	91.3041
1399.38	89.8598
1402.54	91.4776
1405.69	91.2618
1408.85	96.8095
1412	101.513
1415.16	109.389
1418.31	117.719
1421.46	127.433
1424.61	137.037
1427.76	148.999
1430.9	161.039
1434.05	171.694
1437.2	182.251
1440.34	191.514
1443.48	201.348
1446.62	206.148
1449.76	208.294
1452.9	210
1456.04	211.841
1459.17	213.381
1462.31	216.62
1465.44	216.673
1468.58	217.535
1471.71	216.2
1474.84	212.845
1477.97	208.09
1481.1	201.28
1484.22	194.866
1487.35	188.281
1490.47	179.351
1493.59	170.491
1496.72	161.086
1499.84	151.751
1502.96	142.079
1506.08	132.934
1509.19	121.534
1512.31	111.663
1515.42	100.436
1518.54	92.7266
1521.65	83.2099
1524.76	74.2841
1527.87	68.1669
1530.98	65.7376
1534.09	63.7878
1537.2	63.397
1540.3	66.6975
1543.41	74.1407
1546.51	83.2484
1549.61	96.3839
1552.71	111.155
1555.81	126.715
1558.91	141.367
1562.01	155.502
1565.1	162.562
1568.2	174.922
1571.29	185.975
1574.38	199.091
1577.48	208.611
1580.57	212.273
1583.65	215.627
1586.74	217.24
1589.83	216.009
1592.92	211.917
1596	205.608
1599.08	197.12
1602.16	186.115
1605.24	172.05
1608.32	157.221
1611.4	144.526
1614.48	132.173
1617.56	125.628
1620.63	123.5
1623.71	121.279
1626.78	121.88
1629.85	120.98
1632.92	121.757
1635.99	119.161
1639.06	120.794
1642.12	121.191
1645.19	131.05
1648.25	134.172
1651.32	136.885
1654.38	136.749
1657.44	135.97
1660.5	136.267
1663.56	133.113
1666.62	130.198
1669.67	125.653
1672.73	118.838
1675.79	109.908
1678.84	100.586
1681.89	89.2647
1684.94	78.5002
1687.99	69.6484
1691.04	59.1697
1694.08	51.1265
1697.13	43.8167
1700.18	37.4103
1703.22	31.2915
1706.26	26.3493
1709.3	21.566
1712.35	16.769
1715.39	15.1915
1718.42	12.0815
1721.46	10.2584
1724.5	8.19588
1727.53	7.01765
1730.56	4.82019
1733.6	5.30898
1736.63	4.36747
1739.66	2.71132
1742.69	2.50089
1745.71	1.43978
1748.74	0.541232
1751.77	0.0715112
1754.79	-0.318413
1757.81	0.153788
1760.84	0.360128
1763.86	0.729285
1766.88	-0.41593
1769.9	0.720196
1772.91	0.704109
1775.93	2.00773
1778.95	2.93416
1781.96	3.39773
1784.97	4.24709
1787.99	4.7253
1791	5.37708
1794.01	6.2861
1797.01	5.60826
1800.02	5.33127
1803.03	4.49334
1806.03	5.43159
1809.04	5.42048
1812.04	3.98944
1815.04	4.97014
1818.04	4.30202
1821.04	4.05921
1824.04	4.34309
1827.04	3.56556
1830.03	2.61281
1833.03	1.79951
1836.02	1.97812
1839.02	1.80989
1842.01	2.38756
1845	2.69588
1847.99	2.77998
1850.98	3.18673
1853.96	3.32194
1856.95	3.45535
1859.94	3.90696
1862.92	4.53225
1865.9	4.30031
1868.88	4.99447
1871.86	4.00918
1874.84	4.93843
1877.82	6.23408
1880.8	6.47591
1882.58	5.91269
1885.57	6.82138
1888.56	6.30102
1891.54	5.65253
1894.53	5.12412
1897.51	5.66154
1900.5	6.01222
1903.48	5.30622
1906.46	6.84956
1909.44	7.50877
1912.42	7.37419
1915.4	6.44307
1918.37	6.21895
1921.35	5.08664
1924.32	4.59121
1927.3	4.84222
1930.27	3.52232
1933.24	4.71739
1936.21	3.7326
1939.18	4.06076
1942.15	3.22996
1945.11	2.56643
1948.08	1.98131
1951.04	1.88866
1954.01	0.622883
1956.97	1.21911
1959.93	2.1455
1962.89	2.41543
1965.85	2.33072
1968.81	2.16518
1971.77	3.20665
1974.72	4.12127
1977.68	4.06378
1980.63	4.8122
1983.58	4.84194
1986.53	3.45223
1989.48	4.58448
1992.43	2.82244
1995.38	2.58288
1998.33	3.21135
2001.27	3.1974
2004.22	3.58797
2007.16	4.13745
2010.11	3.31688
2013.05	2.31763
2015.99	1.66043
2018.93	1.42311
2021.87	2.15324
2024.8	3.78038
2027.74	4.82684
2030.68	5.81788
2033.61	4.84129
2036.54	5.96126
2039.48	6.77739
2042.41	7.87103
2045.34	9.3524
2048.27	9.60896
2051.19	9.85809
2054.12	10.8327
2057.05	11.1555
2059.97	12.3465
2062.9	13.136
2065.82	13.2442
2068.74	14.1142
2071.66	13.7346
2074.58	14.9419
2077.5	16.7616
2080.41	17.6934
2083.33	17.7522
2086.24	17.6018
2089.16	19.172
2092.07	20.3215
2094.98	20.921
2097.89	21.9383
2100.8	21.3691
2103.71	24.2146
2106.62	26.1504
2109.53	29.3844
2112.43	30.9824
2115.33	33.3339
2118.24	35.6305
2121.14	37.0309
2124.04	39.434
2126.94	40.5275
2129.84	44.2231
2132.74	46.7132
2135.63	49.7568
2138.53	52.6715
2141.43	56.121
2144.32	60.4291
2147.21	65.2996
2150.1	68.6253
2152.99	72.0306
2155.88	74.6711
2158.77	77.6771
2161.66	82.73
2164.55	84.8964
2167.43	87.6968
2170.31	92.7501
2173.2	95.0353
2176.08	96.9745
2178.96	97.9076
2181.84	97.292
2184.72	96.3546
2187.6	92.6104
2190.47	89.1406
2193.35	85.4209
2196.23	81.8202
2199.1	77.0121
2201.97	72.0389
2204.84	66.7201
2207.71	61.9696
2210.58	58.235
2213.45	53.6664
2216.32	48.2093
2219.19	42.9075
2222.05	37.7091
2224.92	34.1397
2227.78	30.8866
2230.64	28.4097
2233.5	27.3352
2236.36	25.9082
2239.22	25.6223
2242.08	24.8657
2244.94	25.0165
2247.79	24.5965
2250.65	23.2226
2253.5	22.6605
2256.36	21.578
2259.21	21.0103
2262.06	22.3113
2264.91	22.5326
2267.76	21.801
2270.6	20.1492
2273.45	20.0748
2276.3	19.2555
2279.14	17.773
2281.98	16.0565
2284.83	14.5213
2287.67	12.393
2290.51	11.0959
2293.35	8.49981
2296.19	7.17338
2299.02	6.84356
2301.86	6.48178
2304.7	6.70696
2307.53	7.28352
2310.36	7.15535
2313.2	7.78608
2316.03	8.6441
2318.86	8.20324
2321.69	8.72189
2324.51	9.84
2327.34	9.16528
2330.17	9.53837
2332.99	9.85846
2335.82	9.2749
2338.64	7.99957
2341.46	8.11598
2344.28	7.16726
2347.1	6.16494
2349.92	4.8689
2352.74	3.02747
2355.56	2.49599
2358.37	0.289801
2361.19	-0.0710823
2364	-0.192045
2366.82	-0.633501
2369.63	-0.665336
2372.44	-1.71263
2375.25	-1.78447
2378.06	-0.810708
2380.86	0.0110286
2383.67	1.44512
2386.48	0.188263
2389.28	1.86854
2392.09	2.56323
2394.89	2.87327
2397.69	3.53531
2400.49	3.52082
2403.29	5.12314
2406.09	5.20006
2408.89	6.05386
2411.69	7.95891
2414.48	7.95102
2417.28	9.93506
2420.07	8.16454
2422.86	9.50943
2425.65	9.34579
2428.45	8.54008
2431.23	7.59137
2434.02	8.23185
2436.81	7.80463
2439.6	7.23523
2442.38	6.81053
2445.17	6.97797
2447.95	6.87305
2450.73	6.13007
2453.52	4.43141
2456.3	4.3685
2459.08	3.62237
2461.85	3.39079
2464.63	2.34227
2467.41	1.78666
2470.19	2.09462
2472.96	2.82346
2475.73	2.51493
2478.51	3.61124
2481.28	4.50613
2484.05	4.363
2486.82	3.96301
2489.59	3.82699
2492.35	2.98889
2495.12	3.09088
2497.89	3.11908
2500.65	3.63637
2503.42	2.53259
2506.18	1.15507
2508.94	2.00869
2511.7	1.76329
2514.46	1.92512
2517.22	2.1685
2519.98	2.09317
2522.73	3.02729
2525.49	3.71314
2528.25	5.45001
2531	6.77758
2533.75	6.91314
2536.5	7.97856
2539.25	8.69965
2542.01	10.4713
2544.75	10.875
2547.5	11.1744
2550.25	11.321
2553	10.4157
2555.74	11.0794
2558.49	10.2905
2561.23	8.70864
2563.97	8.50097
2566.71	7.94704
2569.45	6.24754
2572.19	5.94068
2574.93	5.62593
2577.67	4.46484
2580.4	3.83071
2583.14	4.72463
2585.87	5.27893
2588.6	5.27955
2591.34	5.35354
2594.07	6.28542
2596.8	7.94029
2599.53	7.94438
2602.26	9.87354
2604.98	11.8149
2607.71	11.5752
2610.44	12.2228
2613.16	13.118
2615.88	12.2253
2618.61	12.5114
2621.33	12.6247
2624.05	13.7619
2626.77	14.5273
2629.49	15.406
2632.21	17.5535
2634.92	19.2346
2637.64	19.8959
2640.35	21.7199
2643.07	23.3907
2645.78	25.4418
2648.49	27.6017
2651.2	28.1338
2653.91	29.0794
2656.62	32.4261
2659.33	35.4592
2662.04	39.2595
2664.74	41.5406
2667.45	45.5432
2670.15	49.2889
2672.86	51.1047
2675.56	54.1154
2678.26	57.6177
2680.96	60.5243
2683.66	62.0528
2686.36	64.4172
2689.06	67.4933
2691.75	68.7152
2694.45	69.4732
2697.14	70.9702
2699.84	72.7881
2702.53	74.5446
2705.22	75.8269
2707.91	76.1591
2710.6	74.6511
2713.29	72.8572
2715.98	70.8041
2718.67	68.6856
2721.35	67.4113
2724.04	63.7135
2726.72	59.9437
2729.4	56.9822
2732.09	53.2346
2734.77	51.0908
2737.45	47.4706
2740.13	43.4454
2742.81	39.5913
2745.48	35.4224
2748.16	32.102
2750.84	27.3721
2753.51	23.4927
2756.19	19.6853
2758.86	15.5441
2761.53	13.4209
2764.2	11.504
2766.87	8.96805
2769.54	6.86903
2772.21	6.39449
2774.88	4.13753
2777.54	3.6364
2780.21	3.474
2782.87	2.66799
2785.53	2.01
2788.2	1.57163
2790.86	0.820777
2793.52	1.57044
2796.18	1.07096
2798.84	1.38931
2801.49	2.01768
2804.15	1.22186
2806.81	0.0898368
2809.46	-0.469414
2812.12	-0.192485
2814.77	0.228521
2817.42	1.23641
2820.07	3.90638
2822.72	8.96882
2825.37	13.0354
2828.02	20.3786
2830.67	27.9603
2833.31	37.1639
2835.96	46.2661
2838.61	55.4225
2841.25	66.0453
2843.89	77.8189
2846.53	90.8769
2849.17	106.148
2851.81	122.666
2854.45	139.832
2857.09	156.78
2859.73	173.803
2862.36	188.707
2865	203.605
2867.64	215.769
2870.27	226.356
2872.9	236.17
2875.53	246.306
2878.16	256.683
2880.79	266.037
2883.42	275.403
2886.05	285.062
2888.68	293.652
2891.3	303.424
2893.93	314.94
2896.55	323.718
2899.18	333.979
2901.8	344.475
2904.42	359.369
2907.04	376.178
2909.66	396.528
2912.28	418.392
2914.9	441.021
2917.51	462.758
2920.13	482.325
2922.74	499.794
2925.36	512.44
2927.97	521.167
2930.59	525.504
2933.2	525.742
2935.81	521.855
2938.42	514.154
2941.02	502.826
2943.63	487.938
2946.24	468.969
2948.85	449.054
2951.45	428.127
2954.05	406.171
2956.66	384.222
2959.26	361.099
2961.86	338.861
2964.46	319.072
2967.06	301.507
2969.66	284.158
2972.26	269.155
2974.85	255.93
2977.45	241.755
2980.05	228.392
2982.64	213.994
2985.23	200.085
2987.83	185.792
2990.42	169.147
2993.01	152.585
2995.6	136.467
2998.19	119.354
3000.77	103.158
3003.36	88.2488
3005.95	73.562
3008.53	59.2376
3011.12	47.4372
3013.7	36.7286
3016.28	28.8076
3018.86	21.4799
3021.44	14.4652
3024.02	10.311
3026.6	7.1249
3029.18	4.87817
3031.76	3.52528
3034.33	3.18459
3036.91	3.8262
3039.48	5.77474
3042.05	9.09628
3044.63	11.0102
3047.2	14.5002
3049.77	16.7385
3052.34	17.5455
3054.91	16.8878
3057.48	17.9015
3060.04	17.6462
3062.61	18.386
3065.17	17.9242
3067.74	17.5163
3070.3	15.8341
3072.87	13.6635
3075.43	12.442
3077.99	10.101
3080.55	8.34837
3083.11	5.86391
3085.67	4.51652
3088.22	2.81365
3090.78	1.76413
3093.34	2.09335
3095.89	2.90331
3098.44	3.51204
3101	5.60078
3103.55	7.30406
3106.1	9.66789
3108.65	12.1856
3111.2	14.9511
3113.75	15.3095
3116.3	16.7159
3118.84	18.795
3121.39	22.1113
3123.93	24.5744
3126.48	26.5091
3129.02	28.3552
3131.56	29.6989
3134.1	31.0481
3136.64	33.2114
3139.18	34.6651
3141.72	35.5417
3144.26	37.0231
3146.8	38.3189
3149.33	41.9391