File: data/Raman/poly_smoothed/Mbcal_20_25_20_1x_45s_532 nm_x100_100%_600 gr_mm_01.txt
#Acq. time (s)=	45
#Accumulations=	2
#Range (cm-¹)=	200...3150
#Windows=	2
#Auto scanning=	Off
#Autofocus=	Off
#Macrospot=	Off
#AutoExposure=	Off
#Spike filter=	Multiple accum.
#Delay time (s)=	0
#Binning=	1
#Readout mode=	Signal
#DeNoise=	Off
#ICS correction=	On
#Dark correction=	Off
#Inst. Process=	Off
#Detector Gain=	Best Dynamic Range
#Detector ADC=	20 kHz
#Detector temperature (°C)=	-69.85
#Instrument=	LabRAM HR Evol
#Detector=	Synapse
#Objective=	x100
#Grating=	600 gr/mm
#ND Filter=	100%
#Laser (nm)=	532
#Hole=	100.021
#Range=	Auto
#Laser Pol.=	No
#Raman. Pol.=	No
#Laser Pol. (°)=	-0.0007625
#Raman Pol. (°)=	89.9995
#Collection=	Microscope
#StageXY=	Marzhauser
#StageZ=	Marzhauser
#X (µm)=	-1166
#Y (µm)=	1264.4
#Z (µm)=	578.2
#Full time(mm:ss)=	3:18
#Project=
#Sample=
#Site=
#Title=	Mbcal_20_25_20_2x_45s_532 nm_x100_100%_600 gr_mm
#Remark=
#Date=	18.07.2022 10:53
#Acquired=	18.07.2022 10:53:30
#Base:Fit=	10.08.2022 10:55:08
#Base:Sub=	10.08.2022 10:55:14
#Filter:Polynom=	16.08.2022 10:07:28
#AxisType[0]=Intens
#AxisUnit[0]=Cnt
#AxisType[1]=Spectr
#AxisUnit[1]=1/cm
200.419	24.7341
204.048	18.7207
207.678	12.8683
211.304	10.1585
214.928	7.7966
218.554	6.86957
222.176	6.57366
225.798	6.93274
229.417	4.77719
233.035	4.88089
236.653	5.61551
240.268	4.88207
243.881	5.20214
247.493	6.56965
251.103	8.22444
254.715	9.01865
258.322	9.22875
261.929	9.25924
265.534	9.68119
269.137	10.0427
272.739	10.0726
276.34	10.1971
279.939	10.9318
283.537	11.5915
287.134	11.1984
290.729	11.9522
294.323	14.8442
297.913	15.9383
301.504	18.1543
305.093	18.5718
308.682	19.8243
312.268	19.7683
315.852	19.2362
319.436	19.1909
323.018	20.1257
326.597	19.5219
330.177	19.6613
333.753	19.2548
337.331	19.392
340.906	18.4478
344.478	17.9966
348.051	17.6431
351.621	18.0056
355.189	18.5788
358.757	18.0223
362.323	17.1876
365.889	16.5443
369.451	17.7571
373.012	17.4176
376.574	16.2194
380.133	18.0472
383.69	18.8051
387.245	18.9477
390.8	18.9525
394.353	18.5094
397.906	16.1226
401.456	15.4803
405.005	14.709
408.552	12.9928
412.099	12.2712
415.643	10.3426
419.187	10.2832
422.728	9.74929
426.269	9.70732
429.806	8.95967
433.344	9.35468
436.881	9.41801
440.416	9.18301
443.949	8.22808
447.48	6.1045
451.011	6.72547
454.541	6.83502
458.069	6.62109
461.594	8.49821
465.119	10.1284
468.642	12.3007
472.165	13.2639
475.684	13.0564
479.204	13.783
482.721	13.585
486.239	15.0691
489.753	17.3173
493.268	18.2397
496.779	18.7317
500.289	20.7555
503.8	22.7449
507.307	23.6938
510.813	24.5097
514.32	25.0512
517.823	24.8287
521.325	24.4269
524.826	23.4158
528.325	23.5524
531.823	22.7554
535.32	23.2955
538.815	22.6039
542.309	21.1282
545.802	19.8673
549.293	18.4873
552.783	16.1783
556.271	13.7774
559.759	10.5222
563.245	9.01532
566.729	8.70993
570.213	6.75613
573.693	6.01237
577.173	4.74661
580.652	4.57384
584.13	4.90144
587.605	5.3019
591.08	4.42201
594.552	5.37606
598.025	4.75937
601.496	3.96636
604.964	3.24596
608.433	4.15779
611.898	5.73101
615.364	6.16336
618.827	6.48418
622.288	6.72701
625.75	7.92589
629.209	9.70837
632.667	10.4393
636.125	10.4249
639.58	11.2385
643.033	11.9887
646.485	13.8182
649.936	14.4396
653.388	15.5459
656.836	16.5211
660.283	18.9836
663.728	20.9369
667.173	21.9114
670.616	22.7163
674.057	22.7729
677.498	23.8772
680.937	24.1761
684.375	24.6743
687.809	25.1397
691.244	26.9653
694.678	29.5095
698.111	29.5847
701.54	30.5228
704.97	31.7427
708.398	34.5525
711.826	37.3699
715.25	37.1765
718.675	36.6794
722.096	38.1943
725.518	39.6094
728.937	40.4367
732.357	41.1614
735.773	41.0742
739.19	43.8594
742.604	43.5437
746.018	44.3655
749.429	45.2423
752.839	47.2593
756.248	49.8429
759.657	50.7153
763.063	52.8839
766.468	55.7623
769.871	58.1042
773.273	61.3934
776.676	64.8418
780.075	66.5035
783.474	70.1505
786.871	72.9822
790.266	75.1171
793.661	78.5617
797.054	79.4992
800.446	80.1278
803.834	82.8864
807.224	84.2824
810.612	84.9441
813.998	84.6527
817.384	83.649
820.766	82.1467
824.149	80.7696
827.531	79.0843
830.909	78.6475
834.288	77.3277
837.666	76.0231
841.041	72.838
844.416	71.6113
847.788	71.0382
851.161	70.9917
854.53	69.2957
857.901	67.5707
861.268	65.0155
864.633	62.6839
868	60.1296
871.363	56.8114
874.725	55.082
878.088	54.3286
881.447	52.3994
884.805	50.724
888.162	49.8681
891.518	47.3959
894.872	45.3036
898.225	45.4734
901.577	43.8095
904.928	43.2974
908.277	44.1354
911.625	45.459
914.972	46.156
918.318	45.8892
921.662	46.8484
925.005	48.0149
928.347	50.5409
931.686	50.8156
935.025	50.4082
938.363	50.0249
941.698	49.8099
945.034	47.1778
948.368	45.6177
951.699	44.7948
955.031	43.3422
958.36	41.4494
961.689	39.6298
965.016	37.7952
968.343	35.0431
971.666	33.4003
974.991	31.4648
978.312	31.3448
981.632	30.0381
984.953	28.6481
988.27	27.214
991.587	27.4197
994.902	26.8806
998.216	25.1413
1001.53	24.2253
1004.84	24.751
1008.15	23.5583
1011.46	22.9311
1014.77	22.1851
1018.07	22.0686
1021.38	20.9267
1024.68	20.1446
1027.99	20.4836
1031.29	20.6537
1034.59	19.8339
1037.89	18.9016
1041.18	19.0832
1044.48	20.2271
1047.77	18.9795
1051.07	17.2186
1054.36	17.2387
1057.65	17.59
1060.94	18.4897
1064.23	18.6622
1067.52	17.9092
1070.8	17.9251
1074.09	17.8511
1077.37	16.9593
1080.65	15.7045
1083.93	15.2382
1087.21	14.2087
1090.49	13.798
1093.77	13.6018
1097.04	13.4708
1100.32	13.6398
1103.59	14.0445
1106.86	14.8178
1110.13	13.6327
1113.4	13.0215
1116.67	11.6199
1119.94	11.6239
1123.2	11.9266
1126.47	10.7419
1129.73	10.3575
1132.99	10.3656
1136.25	10.7292
1139.51	11.8841
1142.77	10.5834
1146.03	8.35957
1149.28	8.02401
1152.54	7.36601
1155.79	6.44079
1159.04	5.26309
1162.29	4.27346
1165.54	3.38907
1168.79	3.44339
1172.04	3.6369
1175.28	2.83942
1178.53	2.04562
1181.77	0.71887
1185.01	0.347807
1188.25	-0.84005
1191.49	-0.389015
1194.73	-0.513244
1197.96	0.55832
1201.2	0.973278
1204.43	1.72197
1207.66	3.60553
1210.9	5.73993
1214.13	7.941
1217.36	8.56585
1220.58	11.0504
1223.81	12.1104
1227.04	15.2801
1230.26	18.1369
1233.48	19.2621
1236.71	22.3691
1239.93	23.141
1243.14	23.7863
1246.36	25.1932
1249.58	27.4151
1252.8	27.9809
1256.01	28.377
1259.22	29.6574
1262.43	30.832
1265.64	30.6987
1268.85	31.525
1272.06	33.6882
1275.27	34.137
1278.48	35.6571
1281.68	35.6125
1284.88	37.3722
1288.08	37.7853
1291.28	38.0293
1294.48	37.7333
1297.68	38.2043
1300.88	37.6919
1304.07	39.4071
1307.27	39.9568
1310.46	40.6955
1313.65	40.978
1316.85	39.9109
1320.03	37.9381
1323.22	38.2272
1326.41	37.3271
1329.6	37.544
1332.78	36.8491
1335.96	36.3513
1339.15	34.929
1342.33	34.1824
1345.51	33.912
1348.69	34.4565
1351.86	34.6804
1355.04	34.2652
1358.21	32.8267
1361.39	32.0883
1364.56	30.1822
1367.73	28.6105
1370.9	28.1266
1374.07	27.4087
1377.24	26.5265
1380.41	25.6406
1383.57	26.4419
1386.73	25.7857
1389.9	26.9075
1393.06	25.7702
1396.22	25.3238
1399.38	24.3142
1402.54	24.4792
1405.69	24.4402
1408.85	25.607
1412	26.0251
1415.16	27.8455
1418.31	31.0863
1421.46	34.4151
1424.61	38.2053
1427.76	42.6501
1430.9	45.7526
1434.05	49.2767
1437.2	52.1284
1440.34	54.4995
1443.48	56.9591
1446.62	58.5452
1449.76	59.8885
1452.9	60.0745
1456.04	60.1144
1459.17	59.2055
1462.31	58.5947
1465.44	56.7106
1468.58	53.1843
1471.71	49.3237
1474.84	44.3875
1477.97	40.4425
1481.1	37.5864
1484.22	34.527
1487.35	30.8688
1490.47	27.8262
1493.59	26.0139
1496.72	23.3769
1499.84	20.3554
1502.96	18.7042
1506.08	17.7691
1509.19	16.0125
1512.31	15.1157
1515.42	13.0228
1518.54	11.7965
1521.65	11.6089
1524.76	12.3325
1527.87	13.2396
1530.98	13.402
1534.09	12.9477
1537.2	12.9107
1540.3	13.9201
1543.41	14.9674
1546.51	16.0471
1549.61	16.775
1552.71	17.6394
1555.81	19.18
1558.91	19.0707
1562.01	20.2888
1565.1	20.4701
1568.2	21.1048
1571.29	21.7866
1574.38	22.5939
1577.48	23.4246
1580.57	25.3971
1583.65	25.5027
1586.74	26.5761
1589.83	26.7214
1592.92	29.0464
1596	29.4777
1599.08	30.2302
1602.16	32.424
1605.24	31.9153
1608.32	30.7512
1611.4	29.8604
1614.48	30.041
1617.56	31.0233
1620.63	30.0995
1623.71	30.0388
1626.78	29.8452
1629.85	30.898
1632.92	30.876
1635.99	31.8589
1639.06	34.306
1642.12	34.5145
1645.19	37.3645
1648.25	39.4416
1651.32	41.1751
1654.38	42.2289
1657.44	42.0099
1660.5	42.4901
1663.56	42.9542
1666.62	41.8362
1669.67	39.9916
1672.73	38.1403
1675.79	36.6683
1678.84	34.0272
1681.89	30.677
1684.94	27.6702
1687.99	25.9032
1691.04	22.5972
1694.08	19.701
1697.13	17.1564
1700.18	15.5264
1703.22	13.8255
1706.26	12.8226
1709.3	12.4202
1712.35	12.5171
1715.39	13.048
1718.42	14.3565
1721.46	14.6961
1724.5	14.6557
1727.53	13.3181
1730.56	13.4161
1733.6	13.0778
1736.63	12.4626
1739.66	11.1434
1742.69	9.72894
1745.71	9.38136
1748.74	8.45414
1751.77	7.48013
1754.79	6.29128
1757.81	5.56767
1760.84	4.63923
1763.86	3.20913
1766.88	1.94941
1769.9	1.30034
1772.91	1.69347
1775.93	1.87921
1778.95	1.56128
1781.96	1.69682
1784.97	3.32334
1787.99	4.54248
1791	6.0637
1794.01	6.09392
1797.01	6.20067
1800.02	6.91318
1803.03	7.51248
1806.03	8.06752
1809.04	7.421
1812.04	7.02036
1815.04	6.0527
1818.04	6.39229
1821.04	6.07137
1824.04	5.61597
1827.04	5.56539
1830.03	5.50581
1833.03	5.05049
1836.02	4.18188
1839.02	4.36898
1842.01	4.87043
1845	5.30874
1847.99	5.35891
1850.98	5.68616
1853.96	6.14333
1856.95	7.74452
1859.94	8.35532
1862.92	8.60411
1865.9	8.74867
1868.88	9.76979
1871.86	10.6919
1874.84	11.4544
1877.82	10.8145
1880.8	10.9956
1882.58	10.8319
1885.57	10.7797
1888.56	10.0647
1891.54	9.90823
1894.53	9.50402
1897.51	9.45796
1900.5	8.22803
1903.48	7.5393
1906.46	6.61291
1909.44	6.39576
1912.42	6.08992
1915.4	5.29648
1918.37	4.51964
1921.35	4.06582
1924.32	3.1884
1927.3	2.00685
1930.27	1.12874
1933.24	0.570158
1936.21	0.210853
1939.18	0.386579
1942.15	0.0320366
1945.11	-0.308071
1948.08	-0.838471
1951.04	-0.235932
1954.01	0.298624
1956.97	0.33809
1959.93	1.09576
1962.89	1.13809
1965.85	1.90271
1968.81	2.81336
1971.77	3.67596
1974.72	3.52034
1977.68	3.404
1980.63	3.36725
1983.58	2.69732
1986.53	3.24652
1989.48	3.39641
1992.43	4.2071
1995.38	3.86898
1998.33	4.46189
2001.27	4.5773
2004.22	4.19631
2007.16	4.40143
2010.11	4.92239
2013.05	4.54861
2015.99	4.54822
2018.93	5.15017
2021.87	6.46302
2024.8	7.03592
2027.74	6.77739
2030.68	6.41541
2033.61	6.66998
2036.54	6.85997
2039.48	7.13719
2042.41	6.5295
2045.34	6.11826
2048.27	6.12577
2051.19	5.00542
2054.12	4.99259
2057.05	4.96998
2059.97	5.36119
2062.9	5.27141
2065.82	5.43087
2068.74	5.64533
2071.66	5.25393
2074.58	5.08295
2077.5	5.13758
2080.41	5.71468
2083.33	5.81324
2086.24	6.82243
2089.16	7.47943
2092.07	8.87506
2094.98	9.15606
2097.89	9.87039
2100.8	9.91949
2103.71	10.6669
2106.62	11.9967
2109.53	13.2046
2112.43	13.8152
2115.33	15.0124
2118.24	15.8246
2121.14	16.867
2124.04	18.2914
2126.94	19.1307
2129.84	19.9237
2132.74	20.4978
2135.63	20.9155
2138.53	22.1817
2141.43	22.0955
2144.32	23.2359
2147.21	24.162
2150.1	26.3496
2152.99	27.0702
2155.88	28.5985
2158.77	29.8783
2161.66	31.0646
2164.55	31.8774
2167.43	32.4418
2170.31	32.4567
2173.2	32.7964
2176.08	31.3378
2178.96	31.6141
2181.84	31.2143
2184.72	30.6166
2187.6	30.1978
2190.47	29.8565
2193.35	29.5941
2196.23	27.9116
2199.1	26.3314
2201.97	24.7215
2204.84	23.0664
2207.71	21.1713
2210.58	19.3275
2213.45	17.8265
2216.32	17.4875
2219.19	15.8909
2222.05	14.1697
2224.92	12.9276
2227.78	12.5845
2230.64	11.5494
2233.5	11.5572
2236.36	10.4325
2239.22	9.35303
2242.08	7.9961
2244.94	7.24625
2247.79	7.38805
2250.65	7.34329
2253.5	7.63268
2256.36	7.31595
2259.21	7.62324
2262.06	7.8842
2264.91	7.8833
2267.76	7.53171
2270.6	7.08232
2273.45	6.50181
2276.3	6.10055
2279.14	5.89962
2281.98	6.32509
2284.83	6.54983
2287.67	6.22208
2290.51	4.93444
2293.35	4.12934
2296.19	4.81373
2299.02	6.11933
2301.86	6.93783
2304.7	7.41791
2307.53	7.37635
2310.36	7.72895
2313.2	8.16773
2316.03	8.08633
2318.86	7.21916
2321.69	7.47302
2324.51	7.77334
2327.34	7.54027
2330.17	7.94622
2332.99	7.41178
2335.82	6.708
2338.64	5.60041
2341.46	5.37694
2344.28	4.50982
2347.1	3.93991
2349.92	3.36357
2352.74	2.95896
2355.56	3.17444
2358.37	2.10356
2361.19	1.63881
2364	2.04033
2366.82	4.08891
2369.63	4.33939
2372.44	4.10575
2375.25	4.61316
2378.06	4.88272
2380.86	4.55519
2383.67	3.72367
2386.48	2.10506
2389.28	2.50354
2392.09	2.26213
2394.89	1.69595
2397.69	1.125
2400.49	1.1872
2403.29	-0.133069
2406.09	-0.88059
2408.89	-0.640288
2411.69	-0.804239
2414.48	-1.27003
2417.28	-1.10701
2420.07	-0.779551
2422.86	0.197091
2425.65	0.10744
2428.45	0.995603
2431.23	1.84769
2434.02	2.502
2436.81	2.83304
2439.6	3.16562
2442.38	4.19418
2445.17	3.97441
2447.95	4.33478
2450.73	3.87948
2453.52	3.455
2456.3	3.64497
2459.08	3.56307
2461.85	3.61046
2464.63	3.62734
2467.41	3.35276
2470.19	2.84149
2472.96	2.70416
2475.73	2.36917
2478.51	2.2483
2481.28	2.23035
2484.05	2.2789
2486.82	2.76317
2489.59	2.64081
2492.35	3.39023
2495.12	3.61608
2497.89	3.37169
2500.65	2.88358
2503.42	1.90694
2506.18	3.24785
2508.94	3.25094
2511.7	3.82454
2514.46	3.54585
2517.22	3.17311
2519.98	3.56916
2522.73	3.81625
2525.49	3.77416
2528.25	4.07709
2531	4.27141
2533.75	3.8989
2536.5	3.30831
2539.25	3.61065
2542.01	3.675
2544.75	3.55408
2547.5	4.15805
2550.25	4.61724
2553	4.75223
2555.74	4.4872
2558.49	4.79767
2561.23	4.50702
2563.97	4.24443
2566.71	3.75829
2569.45	3.45494
2572.19	3.19185
2574.93	3.14007
2577.67	2.28445
2580.4	1.5709
2583.14	1.49058
2585.87	2.17534
2588.6	2.21874
2591.34	2.45296
2594.07	2.35504
2596.8	2.47324
2599.53	1.30572
2602.26	1.44302
2604.98	0.850493
2607.71	1.34295
2610.44	1.51057
2613.16	1.73417
2615.88	1.99368
2618.61	2.2142
2621.33	2.64298
2624.05	3.34362
2626.77	3.19253
2629.49	2.56825
2632.21	2.59733
2634.92	2.68303
2637.64	3.6125
2640.35	2.58303
2643.07	3.18693
2645.78	3.6547
2648.49	3.79917
2651.2	3.94144
2653.91	3.94897
2656.62	2.6466
2659.33	2.81995
2662.04	2.22596
2664.74	1.49249
2667.45	2.03941
2670.15	1.35604
2672.86	0.414075
2675.56	0.524505
2678.26	0.109062
2680.96	0.161092
2683.66	0.621802
2686.36	1.21885
2689.06	0.864455
2691.75	1.09324
2694.45	1.49419
2697.14	2.03907
2699.84	3.43278
2702.53	5.40551
2705.22	6.08814
2707.91	7.55718
2710.6	8.64103
2713.29	8.94761
2715.98	9.13342
2718.67	9.93968
2721.35	11.232
2724.04	11.886
2726.72	12.6911
2729.4	12.6276
2732.09	12.2552
2734.77	12.0044
2737.45	10.8168
2740.13	10.8671
2742.81	10.1743
2745.48	9.2055
2748.16	8.46139
2750.84	7.64916
2753.51	6.74679
2756.19	6.65973
2758.86	5.63994
2761.53	4.73194
2764.2	3.93323
2766.87	4.42922
2769.54	4.07813
2772.21	3.97111
2774.88	3.40263
2777.54	2.99599
2780.21	2.52947
2782.87	3.12272
2785.53	2.81709
2788.2	2.93723
2790.86	2.21557
2793.52	2.04539
2796.18	0.93401
2798.84	0.649084
2801.49	0.416352
2804.15	-0.103223
2806.81	-0.544488
2809.46	-0.662591
2812.12	-0.211189
2814.77	-0.140409
2817.42	1.14628
2820.07	3.00869
2822.72	5.5033
2825.37	8.06382
2828.02	11.3557
2830.67	15.3107
2833.31	20.0443
2835.96	23.8946
2838.61	27.7047
2841.25	31.7393
2843.89	37.819
2846.53	43.7519
2849.17	49.5101
2851.81	56.063
2854.45	62.2791
2857.09	68.1334
2859.73	73.6711
2862.36	78.629
2865	83.8805
2867.64	88.5642
2870.27	93.4344
2872.9	96.3281
2875.53	99.7631
2878.16	102.228
2880.79	105.868
2883.42	108.597
2886.05	112.379
2888.68	114.716
2891.3	116.556
2893.93	118.73
2896.55	120.469
2899.18	123.303
2901.8	126.106
2904.42	130.073
2907.04	135.523
2909.66	140.562
2912.28	146.273
2914.9	152.767
2917.51	157.565
2920.13	162.014
2922.74	166.061
2925.36	169.217
2927.97	171.719
2930.59	171.6
2933.2	170.905
2935.81	169.023
2938.42	165.501
2941.02	161.661
2943.63	157.012
2946.24	151.736
2948.85	145.835
2951.45	138.5
2954.05	131.248
2956.66	123.872
2959.26	116.697
2961.86	109.802
2964.46	103.59
2967.06	97.5477
2969.66	91.928
2972.26	86.5321
2974.85	81.557
2977.45	77.576
2980.05	71.6663
2982.64	66.971
2985.23	61.9109
2987.83	56.468
2990.42	51.049
2993.01	45.3375
2995.6	40.7801
2998.19	35.8381
3000.77	31.2213
3003.36	26.5563
3005.95	22.3565
3008.53	18.7486
3011.12	15.2993
3013.7	12.146
3016.28	9.80473
3018.86	8.21081
3021.44	6.61526
3024.02	5.18742
3026.6	4.05633
3029.18	3.69099
3031.76	3.22432
3034.33	2.91701
3036.91	3.69647
3039.48	4.09165
3042.05	4.13243
3044.63	5.21695
3047.2	6.47952
3049.77	6.41808
3052.34	6.86334
3054.91	6.87685
3057.48	7.14501
3060.04	6.69669
3062.61	6.15362
3065.17	5.19712
3067.74	4.53114
3070.3	4.38318
3072.87	3.79466
3075.43	2.85199
3077.99	2.78519
3080.55	2.0185
3083.11	1.86964
3085.67	1.30885
3088.22	1.33776
3090.78	1.14762
3093.34	1.51429
3095.89	2.57179
3098.44	3.08308
3101	3.86255
3103.55	4.78402
3106.1	5.94779
3108.65	7.44321
3111.2	8.54199
3113.75	9.03389
3116.3	9.92633
3118.84	10.768
3121.39	12.0328
3123.93	12.8347
3126.48	13.7895
3129.02	14.2228
3131.56	15.3996
3134.1	16.2847
3136.64	16.6993
3139.18	17.7375
3141.72	19.0468
3144.26	20.5505
3146.8	21.2531
3149.33	22.3925