File: data/Raman/poly_smoothed/Mbcal_20_25_43_1x_45s_532 nm_x100_100%_600 gr_mm_01.txt
#Acq. time (s)=	45
#Accumulations=	2
#Range (cm-¹)=	200...3150
#Windows=	2
#Auto scanning=	Off
#Autofocus=	Off
#Macrospot=	Off
#AutoExposure=	Off
#Spike filter=	Multiple accum.
#Delay time (s)=	0
#Binning=	1
#Readout mode=	Signal
#DeNoise=	Off
#ICS correction=	On
#Dark correction=	Off
#Inst. Process=	Off
#Detector Gain=	Best Dynamic Range
#Detector ADC=	20 kHz
#Detector temperature (°C)=	-69.85
#Instrument=	LabRAM HR Evol
#Detector=	Synapse
#Objective=	x100
#Grating=	600 gr/mm
#ND Filter=	100%
#Laser (nm)=	532
#Hole=	100.021
#Range=	Auto
#Laser Pol.=	No
#Raman. Pol.=	No
#Laser Pol. (°)=	-0.0007625
#Raman Pol. (°)=	89.9995
#Collection=	Microscope
#StageXY=	Marzhauser
#StageZ=	Marzhauser
#X (µm)=	-1141.3
#Y (µm)=	1255.2
#Z (µm)=	578.5
#Full time(mm:ss)=	3:18
#Project=
#Sample=
#Site=
#Title=	Mbcal_20_25_43_2x_45s_532 nm_x100_100%_600 gr_mm
#Remark=
#Date=	18.07.2022 13:26
#Acquired=	18.07.2022 13:26:46
#Base:Fit=	10.08.2022 10:55:08
#Base:Sub=	10.08.2022 10:55:14
#Filter:Polynom=	16.08.2022 10:07:28
#AxisType[0]=Intens
#AxisUnit[0]=Cnt
#AxisType[1]=Spectr
#AxisUnit[1]=1/cm
200.419	24.8954
204.048	21.1383
207.678	17.3645
211.304	13.8958
214.928	10.7773
218.554	9.36563
222.176	7.9873
225.798	6.67778
229.417	7.16517
233.035	6.88419
236.653	6.8926
240.268	5.82151
243.881	6.32249
247.493	6.78696
251.103	6.73169
254.715	7.8298
258.322	8.83798
261.929	10.7283
265.534	11.0106
269.137	11.7543
272.739	11.0644
276.34	9.10624
279.939	8.60306
283.537	6.42778
287.134	4.63276
290.729	4.34102
294.323	3.65499
297.913	4.71533
301.504	6.10152
305.093	6.99326
308.682	8.49085
312.268	9.16224
315.852	10.5824
319.436	10.8299
323.018	11.7709
326.597	11.7739
330.177	15.5679
333.753	16.1991
337.331	15.8096
340.906	16.9025
344.478	15.1144
348.051	15.5113
351.621	15.7576
355.189	12.819
358.757	11.816
362.323	10.314
365.889	8.87555
369.451	7.71848
373.012	7.55161
376.574	5.60815
380.133	6.98745
383.69	7.58597
387.245	9.14226
390.8	8.83646
394.353	8.13837
397.906	9.69105
401.456	9.93433
405.005	9.25478
408.552	9.48813
412.099	9.29701
415.643	9.97956
419.187	9.67174
422.728	7.43967
426.269	6.57194
429.806	6.71383
433.344	4.05777
436.881	3.21437
440.416	3.52926
443.949	2.15979
447.48	2.63351
451.011	2.43479
454.541	3.87017
458.069	4.36233
461.594	4.45686
465.119	6.22475
468.642	8.04155
472.165	8.78981
475.684	10.1402
479.204	10.7451
482.721	12.2648
486.239	13.2571
489.753	14.6701
493.268	15.4193
496.779	15.7729
500.289	17.921
503.8	17.3534
507.307	17.5351
510.813	18.2298
514.32	18.2296
517.823	17.8091
521.325	17.2877
524.826	17.8739
528.325	17.9767
531.823	17.9531
535.32	17.9787
538.815	18.5788
542.309	18.2253
545.802	16.1334
549.293	15.5303
552.783	16.0263
556.271	12.9663
559.759	11.9305
563.245	9.87218
566.729	9.63413
570.213	7.63096
573.693	7.30687
577.173	7.02921
580.652	5.5676
584.13	5.73428
587.605	4.27793
591.08	3.44996
594.552	3.7781
598.025	4.56472
601.496	3.39252
604.964	2.16116
608.433	2.18624
611.898	1.94939
615.364	1.8787
618.827	0.911919
622.288	1.06513
625.75	2.47554
629.209	2.92848
632.667	3.63583
636.125	4.1322
639.58	2.55898
643.033	2.60281
646.485	2.10554
649.936	2.03124
653.388	4.40494
656.836	6.71399
660.283	8.65063
663.728	10.2868
667.173	11.0217
670.616	12.9538
674.057	13.4592
677.498	17.0065
680.937	17.9381
684.375	18.1419
687.809	16.6592
691.244	19.0197
694.678	19.3466
698.111	20.2276
701.54	20.8181
704.97	21.1352
708.398	21.9257
711.826	21.4104
715.25	21.856
718.675	21.0923
722.096	21.2877
725.518	20.1491
728.937	20.2732
732.357	21.2344
735.773	24.3362
739.19	26.4191
742.604	25.8894
746.018	28.0108
749.429	30.6106
752.839	31.5926
756.248	35.2028
759.657	37.7055
763.063	40.6445
766.468	42.375
769.871	46.4641
773.273	49.2421
776.676	51.1244
780.075	53.5668
783.474	55.7921
786.871	57.3937
790.266	60.2439
793.661	61.339
797.054	62.6098
800.446	63.9926
803.834	64.1422
807.224	64.032
810.612	63.3638
813.998	64.7503
817.384	64.6487
820.766	64.3829
824.149	62.0066
827.531	61.4013
830.909	63.8163
834.288	63.7972
837.666	64.4462
841.041	65.7679
844.416	64.9239
847.788	64.8517
851.161	65.224
854.53	63.4342
857.901	60.4401
861.268	58.655
864.633	58.1264
868	56.6042
871.363	55.0285
874.725	52.1015
878.088	49.0307
881.447	47.315
884.805	43.1356
888.162	41.2157
891.518	39.8896
894.872	37.6218
898.225	35.5636
901.577	34.0595
904.928	35.2603
908.277	35.0862
911.625	34.6794
914.972	33.9929
918.318	33.4853
921.662	31.4478
925.005	30.275
928.347	28.4925
931.686	26.494
935.025	25.3613
938.363	24.1831
941.698	24.7529
945.034	23.7272
948.368	22.2471
951.699	21.8607
955.031	21.2592
958.36	19.7686
961.689	19.5113
965.016	19.093
968.343	19.2719
971.666	20.3911
974.991	19.7814
978.312	18.801
981.632	19.6925
984.953	18.862
988.27	17.0558
991.587	13.6498
994.902	11.2397
998.216	9.03874
1001.53	6.07784
1004.84	4.88335
1008.15	4.22752
1011.46	4.81353
1014.77	6.71677
1018.07	9.19549
1021.38	11.025
1024.68	12.2883
1027.99	13.1586
1031.29	15.5861
1034.59	16.1144
1037.89	17.4058
1041.18	18.4093
1044.48	19.0935
1047.77	20.84
1051.07	21.4879
1054.36	20.8688
1057.65	20.3736
1060.94	17.9303
1064.23	17.9723
1067.52	15.9295
1070.8	15.3519
1074.09	12.5829
1077.37	12.0303
1080.65	10.6797
1083.93	9.56427
1087.21	12.1436
1090.49	13.8275
1093.77	13.8675
1097.04	13.4307
1100.32	14.845
1103.59	14.986
1106.86	14.3541
1110.13	13.4883
1113.4	13.8689
1116.67	12.6954
1119.94	11.1338
1123.2	10.8794
1126.47	9.99522
1129.73	9.03301
1132.99	8.37477
1136.25	7.94089
1139.51	8.10724
1142.77	8.19357
1146.03	8.72226
1149.28	8.53746
1152.54	9.47763
1155.79	7.98446
1159.04	8.84896
1162.29	9.29856
1165.54	8.42942
1168.79	10.429
1172.04	9.50057
1175.28	9.35029
1178.53	10.1782
1181.77	9.57511
1185.01	8.40345
1188.25	7.50747
1191.49	7.59033
1194.73	6.08911
1197.96	5.9143
1201.2	6.03493
1204.43	7.43407
1207.66	10.3405
1210.9	10.9802
1214.13	12.3753
1217.36	14.8806
1220.58	17.0352
1223.81	17.8219
1227.04	19.1513
1230.26	20.6604
1233.48	22.0801
1236.71	23.9576
1239.93	25.7733
1243.14	26.3662
1246.36	27.8989
1249.58	31.179
1252.8	30.4508
1256.01	30.2796
1259.22	30.5918
1262.43	30.7155
1265.64	33.1
1268.85	35.3732
1272.06	37.9482
1275.27	38.5673
1278.48	39.8958
1281.68	40.7126
1284.88	44.2892
1288.08	44.8911
1291.28	46.5186
1294.48	47.9607
1297.68	49.3076
1300.88	50.0608
1304.07	50.6343
1307.27	50.846
1310.46	51.1528
1313.65	51.6035
1316.85	54.2456
1320.03	54.474
1323.22	57.0199
1326.41	57.4887
1329.6	58.3077
1332.78	59.1136
1335.96	60.4083
1339.15	61.4718
1342.33	61.5007
1345.51	61.2387
1348.69	59.8382
1351.86	59.1321
1355.04	57.3511
1358.21	57.0118
1361.39	56.3765
1364.56	55.7949
1367.73	55.6662
1370.9	56.9887
1374.07	54.3729
1377.24	53.1987
1380.41	52.5638
1383.57	50.6643
1386.73	49.8855
1389.9	49.4596
1393.06	49.6918
1396.22	48.6245
1399.38	47.2239
1402.54	47.4632
1405.69	48.8175
1408.85	50.936
1412	53.2088
1415.16	55.4624
1418.31	58.2289
1421.46	62.5558
1424.61	66.2473
1427.76	70.1214
1430.9	74.8082
1434.05	80.3623
1437.2	83.5725
1440.34	87.4105
1443.48	90.5128
1446.62	92.854
1449.76	94.8554
1452.9	94.5635
1456.04	96.4621
1459.17	96.5176
1462.31	95.9289
1465.44	95.6746
1468.58	95.1094
1471.71	94.2419
1474.84	91.4969
1477.97	90.6418
1481.1	89.3064
1484.22	87.7345
1487.35	87.1952
1490.47	84.9264
1493.59	83.0179
1496.72	80.8795
1499.84	77.8263
1502.96	76.0707
1506.08	73.8682
1509.19	71.218
1512.31	65.1072
1515.42	60.5341
1518.54	57.6162
1521.65	53.056
1524.76	48.9984
1527.87	46.6948
1530.98	44.1102
1534.09	41.7472
1537.2	40.1482
1540.3	39.9285
1543.41	40.4325
1546.51	40.7898
1549.61	41.0718
1552.71	41.9863
1555.81	42.3188
1558.91	42.5081
1562.01	43.7091
1565.1	43.7018
1568.2	45.2117
1571.29	47.1483
1574.38	49.6176
1577.48	55.3694
1580.57	57.3979
1583.65	58.7138
1586.74	60.6702
1589.83	62.4867
1592.92	65.1528
1596	65.2537
1599.08	65.2488
1602.16	64.3066
1605.24	63.446
1608.32	62.7272
1611.4	62.3276
1614.48	61.3064
1617.56	60.8877
1620.63	59.7077
1623.71	58.4332
1626.78	58.6109
1629.85	58.0606
1632.92	56.524
1635.99	58.1159
1639.06	58.413
1642.12	59.9804
1645.19	62.2014
1648.25	64.4269
1651.32	65.9351
1654.38	65.6178
1657.44	65.4303
1660.5	65.35
1663.56	64.3628
1666.62	60.6179
1669.67	56.7682
1672.73	52.5031
1675.79	46.8479
1678.84	41.9759
1681.89	36.8327
1684.94	32.7838
1687.99	27.5685
1691.04	22.7887
1694.08	18.1543
1697.13	14.3405
1700.18	11.5677
1703.22	10.1603
1706.26	7.92319
1709.3	5.29583
1712.35	4.16843
1715.39	3.97191
1718.42	3.91233
1721.46	3.74578
1724.5	3.59541
1727.53	3.73475
1730.56	3.11746
1733.6	2.68527
1736.63	2.00071
1739.66	1.14717
1742.69	1.13003
1745.71	1.58253
1748.74	2.41981
1751.77	3.463
1754.79	4.22283
1757.81	4.25158
1760.84	5.54704
1763.86	5.14738
1766.88	4.63737
1769.9	4.70591
1772.91	4.83475
1775.93	3.77775
1778.95	4.08605
1781.96	4.06348
1784.97	4.97795
1787.99	6.05895
1791	6.17651
1794.01	5.95207
1797.01	6.14781
1800.02	5.89476
1803.03	5.64128
1806.03	5.62288
1809.04	6.60403
1812.04	6.67212
1815.04	7.69985
1818.04	8.30767
1821.04	9.0767
1824.04	9.89113
1827.04	8.83347
1830.03	10.1328
1833.03	10.3292
1836.02	9.4669
1839.02	9.38555
1842.01	9.14429
1845	9.47445
1847.99	8.91707
1850.98	9.38977
1853.96	9.92476
1856.95	10.5356
1859.94	10.4667
1862.92	9.76359
1865.9	8.98384
1868.88	9.45367
1871.86	9.41405
1874.84	9.05537
1877.82	8.77732
1880.8	9.23358
1882.58	8.82465
1885.57	8.0932
1888.56	8.4708
1891.54	7.96945
1894.53	8.34307
1897.51	8.70811
1900.5	9.89517
1903.48	8.95825
1906.46	8.12535
1909.44	9.2505
1912.42	8.50842
1915.4	8.06056
1918.37	8.2214
1921.35	8.3582
1924.32	8.79251
1927.3	7.73698
1930.27	8.20828
1933.24	7.42682
1936.21	6.8979
1939.18	6.79977
1942.15	6.6763
1945.11	6.10662
1948.08	5.92831
1951.04	5.88528
1954.01	5.94785
1956.97	5.41027
1959.93	5.69984
1962.89	6.2995
1965.85	6.55662
1968.81	7.00149
1971.77	7.8744
1974.72	8.47551
1977.68	7.52683
1980.63	9.04333
1983.58	9.08099
1986.53	8.8431
1989.48	9.50013
1992.43	9.34906
1995.38	9.76318
1998.33	9.27039
2001.27	9.92813
2004.22	10.7
2007.16	10.2087
2010.11	10.8682
2013.05	10.8523
2015.99	11.2408
2018.93	11.2041
2021.87	11.267
2024.8	12.3736
2027.74	12.9347
2030.68	13.4382
2033.61	13.2614
2036.54	13.5357
2039.48	13.5728
2042.41	13.3638
2045.34	12.7204
2048.27	12.4023
2051.19	12.7297
2054.12	12.394
2057.05	12.2314
2059.97	12.22
2062.9	11.9843
2065.82	11.3061
2068.74	11.367
2071.66	10.7719
2074.58	11.4724
2077.5	12.2742
2080.41	13.0958
2083.33	12.8966
2086.24	13.167
2089.16	13.537
2092.07	13.2916
2094.98	14.3719
2097.89	13.757
2100.8	13.0357
2103.71	13.2848
2106.62	12.9908
2109.53	13.9118
2112.43	14.2083
2115.33	13.8445
2118.24	13.4284
2121.14	13.6685
2124.04	14.4067
2126.94	15.1579
2129.84	16.7679
2132.74	17.5582
2135.63	18.0718
2138.53	20.0435
2141.43	22.5388
2144.32	24.7434
2147.21	27.7791
2150.1	29.1539
2152.99	31.7332
2155.88	33.9239
2158.77	35.7736
2161.66	37.7344
2164.55	38.3728
2167.43	39.3216
2170.31	39.9564
2173.2	41.3785
2176.08	41.6768
2178.96	42.1876
2181.84	41.2437
2184.72	40.1426
2187.6	38.9093
2190.47	37.6908
2193.35	36.4213
2196.23	35.5972
2199.1	34.3506
2201.97	32.6349
2204.84	29.7467
2207.71	27.8766
2210.58	26.4087
2213.45	24.2292
2216.32	22.3615
2219.19	21.3119
2222.05	19.2349
2224.92	16.6081
2227.78	15.1417
2230.64	13.7044
2233.5	11.7976
2236.36	10.8447
2239.22	8.66533
2242.08	6.77095
2244.94	6.48703
2247.79	5.95408
2250.65	5.79158
2253.5	5.71985
2256.36	6.43887
2259.21	6.4943
2262.06	7.06697
2264.91	6.92559
2267.76	7.21244
2270.6	7.22876
2273.45	7.4259
2276.3	7.44068
2279.14	9.2444
2281.98	8.98763
2284.83	8.38461
2287.67	7.77757
2290.51	7.14803
2293.35	5.8933
2296.19	5.67823
2299.02	6.65331
2301.86	6.59182
2304.7	6.68199
2307.53	7.69538
2310.36	7.30511
2313.2	6.94843
2316.03	7.31783
2318.86	7.34563
2321.69	6.69319
2324.51	6.9821
2327.34	6.57602
2330.17	6.20446
2332.99	6.77903
2335.82	6.55851
2338.64	6.02212
2341.46	5.31399
2344.28	4.50942
2347.1	3.93431
2349.92	2.27637
2352.74	1.41331
2355.56	0.287109
2358.37	-0.531592
2361.19	-1.81888
2364	-1.32928
2366.82	0.12452
2369.63	0.0949185
2372.44	-0.693598
2375.25	-0.231978
2378.06	-0.368165
2380.86	-0.498812
2383.67	0.126519
2386.48	-0.0234182
2389.28	0.252757
2392.09	1.08624
2394.89	0.749125
2397.69	1.13866
2400.49	2.21377
2403.29	2.1965
2406.09	2.4026
2408.89	2.6674
2411.69	3.23218
2414.48	2.96176
2417.28	3.08606
2420.07	3.99632
2422.86	4.85528
2425.65	4.53684
2428.45	5.29944
2431.23	6.97889
2434.02	7.02276
2436.81	6.41627
2439.6	6.02094
2442.38	5.88648
2445.17	6.43478
2447.95	6.38889
2450.73	7.30991
2453.52	6.60988
2456.3	6.13676
2459.08	6.16852
2461.85	5.21109
2464.63	3.91515
2467.41	3.80284
2470.19	4.15728
2472.96	4.6089
2475.73	4.00635
2478.51	2.91478
2481.28	3.25775
2484.05	2.56475
2486.82	3.30618
2489.59	2.39122
2492.35	2.4571
2495.12	2.40284
2497.89	2.12127
2500.65	1.91463
2503.42	1.54135
2506.18	1.28
2508.94	2.11821
2511.7	2.65674
2514.46	3.1785
2517.22	3.86845
2519.98	4.5278
2522.73	4.70998
2525.49	4.2198
2528.25	5.45716
2531	5.31159
2533.75	5.00028
2536.5	6.27551
2539.25	7.02929
2542.01	6.89698
2544.75	6.94156
2547.5	7.15318
2550.25	7.20287
2553	5.65289
2555.74	6.15847
2558.49	6.09543
2561.23	5.39702
2563.97	6.05144
2566.71	6.69144
2569.45	6.42682
2572.19	6.2984
2574.93	5.97705
2577.67	6.86415
2580.4	6.70461
2583.14	6.19783
2585.87	6.84089
2588.6	6.56763
2591.34	6.22088
2594.07	6.43413
2596.8	6.43035
2599.53	6.94565
2602.26	7.76129
2604.98	8.85311
2607.71	8.50948
2610.44	9.25565
2613.16	9.42447
2615.88	9.12253
2618.61	8.43487
2621.33	9.10336
2624.05	8.96087
2626.77	8.58156
2629.49	8.93665
2632.21	8.25995
2634.92	8.07678
2637.64	7.56555
2640.35	7.43541
2643.07	6.89472
2645.78	6.83876
2648.49	6.83762
2651.2	6.87352
2653.91	6.72924
2656.62	7.11599
2659.33	6.72963
2662.04	8.42152
2664.74	8.45726
2667.45	10.1858
2670.15	9.55004
2672.86	8.47857
2675.56	8.9351
2678.26	8.85277
2680.96	8.59084
2683.66	9.32426
2686.36	9.14106
2689.06	9.27577
2691.75	9.59372
2694.45	9.46596
2697.14	9.57788
2699.84	10.0789
2702.53	10.2811
2705.22	11.0046
2707.91	10.9882
2710.6	11.648
2713.29	12.4719
2715.98	12.2943
2718.67	11.4913
2721.35	12.3589
2724.04	12.7998
2726.72	12.5185
2729.4	11.6994
2732.09	10.1155
2734.77	8.66192
2737.45	7.71368
2740.13	7.26713
2742.81	6.08757
2745.48	5.71474
2748.16	5.77163
2750.84	4.64419
2753.51	3.83634
2756.19	3.69627
2758.86	3.20137
2761.53	2.44844
2764.2	2.52027
2766.87	2.74195
2769.54	2.12255
2772.21	2.04782
2774.88	2.11749
2777.54	2.21074
2780.21	1.49325
2782.87	0.742092
2785.53	1.64221
2788.2	0.666137
2790.86	0.935012
2793.52	-0.264715
2796.18	-0.318716
2798.84	-0.597574
2801.49	0.000218088
2804.15	0.490585
2806.81	0.265414
2809.46	0.678601
2812.12	1.66798
2814.77	2.50817
2817.42	4.57423
2820.07	6.8918
2822.72	10.0052
2825.37	12.6118
2828.02	15.4742
2830.67	19.012
2833.31	22.4462
2835.96	25.1873
2838.61	29.7829
2841.25	33.3559
2843.89	37.5381
2846.53	43.1937
2849.17	47.9794
2851.81	53.0424
2854.45	58.511
2857.09	65.3272
2859.73	70.3481
2862.36	76.341
2865	81.3016
2867.64	86.8544
2870.27	92.4579
2872.9	97.3431
2875.53	101.483
2878.16	105.48
2880.79	110.235
2883.42	114.254
2886.05	117.696
2888.68	121.942
2891.3	124.645
2893.93	128.583
2896.55	132.477
2899.18	137.125
2901.8	142.016
2904.42	148.63
2907.04	155.023
2909.66	162.453
2912.28	171.872
2914.9	179.533
2917.51	186.981
2920.13	193.742
2922.74	198.975
2925.36	203.109
2927.97	206.941
2930.59	208.373
2933.2	208.289
2935.81	205.876
2938.42	201.355
2941.02	196.3
2943.63	189.605
2946.24	181.911
2948.85	174.013
2951.45	164.68
2954.05	156.23
2956.66	146.69
2959.26	138.538
2961.86	130.142
2964.46	123.796
2967.06	117.676
2969.66	112.332
2972.26	107.768
2974.85	103.67
2977.45	100.231
2980.05	94.2864
2982.64	88.5309
2985.23	83.7754
2987.83	77.9061
2990.42	72.5631
2993.01	66.947
2995.6	60.3072
2998.19	54.6101
3000.77	48.5442
3003.36	42.4252
3005.95	36.5323
3008.53	30.3526
3011.12	24.5658
3013.7	19.3691
3016.28	15.4237
3018.86	11.428
3021.44	8.58265
3024.02	6.07729
3026.6	3.66294
3029.18	3.14612
3031.76	1.89642
3034.33	1.45706
3036.91	1.68323
3039.48	2.40665
3042.05	2.39719
3044.63	3.2127
3047.2	3.43845
3049.77	3.62684
3052.34	4.43562
3054.91	4.68037
3057.48	5.36659
3060.04	5.04238
3062.61	4.81646
3065.17	4.94153
3067.74	4.65383
3070.3	3.12202
3072.87	2.78193
3075.43	1.84041
3077.99	1.10622
3080.55	0.637827
3083.11	0.442772
3085.67	-0.297765
3088.22	-0.202533
3090.78	-0.109544
3093.34	-0.525542
3095.89	-0.278884
3098.44	1.36683
3101	1.85165
3103.55	2.02061
3106.1	2.90045
3108.65	2.76648
3111.2	3.56248
3113.75	3.93025
3116.3	4.93307
3118.84	6.43442
3121.39	7.18159
3123.93	8.1927
3126.48	9.89182
3129.02	10.5801
3131.56	12.0686
3134.1	13.2112
3136.64	14.6241
3139.18	15.7871
3141.72	18.2525
3144.26	19.9175
3146.8	21.5378
3149.33	24.1444