File: data/Raman/poly_smoothed/Mbcal_20_25_28_1x_45s_532 nm_x100_100%_600 gr_mm_01.txt
#Acq. time (s)=	45
#Accumulations=	2
#Range (cm-¹)=	200...3150
#Windows=	2
#Auto scanning=	Off
#Autofocus=	Off
#Macrospot=	Off
#AutoExposure=	Off
#Spike filter=	Multiple accum.
#Delay time (s)=	0
#Binning=	1
#Readout mode=	Signal
#DeNoise=	Off
#ICS correction=	On
#Dark correction=	Off
#Inst. Process=	Off
#Detector Gain=	Best Dynamic Range
#Detector ADC=	20 kHz
#Detector temperature (°C)=	-69.85
#Instrument=	LabRAM HR Evol
#Detector=	Synapse
#Objective=	x100
#Grating=	600 gr/mm
#ND Filter=	100%
#Laser (nm)=	532
#Hole=	100.021
#Range=	Auto
#Laser Pol.=	No
#Raman. Pol.=	No
#Laser Pol. (°)=	-0.0007625
#Raman Pol. (°)=	89.9995
#Collection=	Microscope
#StageXY=	Marzhauser
#StageZ=	Marzhauser
#X (µm)=	-1159.1
#Y (µm)=	1301.1
#Z (µm)=	578
#Full time(mm:ss)=	3:18
#Project=
#Sample=
#Site=
#Title=	Mbcal_20_25_28_2x_45s_532 nm_x100_100%_600 gr_mm
#Remark=
#Date=	18.07.2022 11:45
#Acquired=	18.07.2022 11:45:44
#Edit:Spike=	18.07.2022 11:48:09
#Base:Fit=	10.08.2022 10:55:08
#Base:Sub=	10.08.2022 10:55:14
#Filter:Polynom=	16.08.2022 10:07:28
#AxisType[0]=Intens
#AxisUnit[0]=Cnt
#AxisType[1]=Spectr
#AxisUnit[1]=1/cm
200.419	7.45725
204.048	10.8371
207.678	11.1177
211.304	11.1006
214.928	10.9971
218.554	11.0687
222.176	12.842
225.798	12.9191
229.417	12.5809
233.035	11.5526
236.653	11.0199
240.268	10.1755
243.881	10.673
247.493	9.67465
251.103	7.6105
254.715	6.5559
258.322	6.65604
261.929	7.30277
265.534	5.71917
269.137	6.35973
272.739	5.99344
276.34	6.16605
279.939	5.90305
283.537	3.1479
287.134	3.90085
290.729	2.67392
294.323	2.26366
297.913	2.57479
301.504	3.21153
305.093	4.20297
308.682	6.60923
312.268	8.92148
315.852	9.63481
319.436	9.43848
323.018	10.2907
326.597	9.71943
330.177	11.149
333.753	11.9804
337.331	10.8003
340.906	11.3206
344.478	12.1031
348.051	11.782
351.621	11.0682
355.189	10.0209
358.757	11.7243
362.323	11.4824
365.889	10.8306
369.451	8.7915
373.012	7.42491
376.574	6.97596
380.133	5.67509
383.69	5.69553
387.245	5.97742
390.8	7.05481
394.353	7.87584
397.906	7.60696
401.456	7.77535
405.005	6.16955
408.552	6.87372
412.099	5.68725
415.643	5.98126
419.187	6.02616
422.728	6.77473
426.269	7.49633
429.806	7.09494
433.344	7.19354
436.881	7.02977
440.416	8.16526
443.949	9.02496
447.48	8.10069
451.011	6.12225
454.541	5.50687
458.069	4.193
461.594	5.24497
465.119	6.07068
468.642	7.70434
472.165	7.59455
475.684	8.12689
479.204	9.0141
482.721	8.77677
486.239	9.70967
489.753	11.1233
493.268	11.6983
496.779	12.3463
500.289	12.097
503.8	14.064
507.307	14.4786
510.813	14.8393
514.32	15.1454
517.823	15.5793
521.325	15.4718
524.826	14.7834
528.325	14.4196
531.823	14.2512
535.32	13.6638
538.815	12.5679
542.309	13.6055
545.802	13.4948
549.293	12.9034
552.783	11.8723
556.271	9.35972
559.759	7.99935
563.245	8.33668
566.729	9.26625
570.213	7.31315
573.693	6.56021
577.173	6.15367
580.652	4.29225
584.13	4.20567
587.605	4.16269
591.08	4.42497
594.552	4.14968
598.025	4.90048
601.496	4.78453
604.964	6.61221
608.433	7.62004
611.898	8.68888
615.364	9.10132
618.827	10.0689
622.288	9.74439
625.75	11.7902
629.209	11.9307
632.667	12.7338
636.125	11.7407
639.58	11.1994
643.033	11.483
646.485	13.7957
649.936	14.2398
653.388	13.7179
656.836	11.8779
660.283	11.4038
663.728	12.8372
667.173	13.7562
670.616	15.6751
674.057	17.6452
677.498	18.6552
680.937	19.9413
684.375	21.7691
687.809	23.8459
691.244	24.5652
694.678	26.1052
698.111	25.8051
701.54	28.0166
704.97	31.0346
708.398	32.7687
711.826	35.6927
715.25	36.3047
718.675	38.8483
722.096	39.261
725.518	41.433
728.937	43.3193
732.357	46.2431
735.773	44.6058
739.19	45.5162
742.604	46.6145
746.018	49.3787
749.429	52.2069
752.839	55.071
756.248	58.1591
759.657	61.0582
763.063	65.2565
766.468	68.8706
769.871	70.8779
773.273	74.3404
776.676	76.4029
780.075	78.3175
783.474	79.5643
786.871	82.623
790.266	84.0392
793.661	85.5364
797.054	86.6845
800.446	89.3682
803.834	91.341
807.224	90.4417
810.612	90.4058
813.998	89.3546
817.384	86.0387
820.766	84.7884
824.149	83.5827
827.531	81.2342
830.909	80.4746
834.288	78.042
837.666	77.6732
841.041	75.7591
844.416	73.2666
847.788	69.9078
851.161	67.0799
854.53	64.4804
857.901	61.3412
861.268	59.529
864.633	56.2836
868	54.391
871.363	53.6721
874.725	51.171
878.088	50.6371
881.447	50.9427
884.805	51.4465
888.162	52.4161
891.518	51.7911
894.872	53.9688
898.225	54.3977
901.577	54.8279
904.928	55.959
908.277	54.3437
911.625	54.4101
914.972	54.9746
918.318	56.0444
921.662	55.8719
925.005	54.2476
928.347	52.9705
931.686	51.5031
935.025	50.1296
938.363	49.1736
941.698	45.9364
945.034	44.2531
948.368	39.8873
951.699	36.5089
955.031	32.9312
958.36	31.4652
961.689	30.6668
965.016	30.2112
968.343	32.4172
971.666	34.5598
974.991	34.8268
978.312	36.3739
981.632	35.691
984.953	34.1762
988.27	34.1876
991.587	37.0915
994.902	39.6882
998.216	42.2432
1001.53	42.5039
1004.84	42.6081
1008.15	40.2424
1011.46	39.2736
1014.77	38.905
1018.07	39.4355
1021.38	37.6835
1024.68	36.2933
1027.99	33.8049
1031.29	32.7951
1034.59	31.0729
1037.89	30.156
1041.18	29.5481
1044.48	30.0085
1047.77	32.4169
1051.07	31.7845
1054.36	31.1855
1057.65	29.8094
1060.94	28.5561
1064.23	27.9113
1067.52	27.4063
1070.8	30.0434
1074.09	29.6219
1077.37	29.465
1080.65	27.3694
1083.93	25.5229
1087.21	23.2629
1090.49	22.7989
1093.77	22.7467
1097.04	23.1715
1100.32	22.606
1103.59	22.5697
1106.86	20.9027
1110.13	21.221
1113.4	20.047
1116.67	19.0691
1119.94	19.1257
1123.2	19.4667
1126.47	17.4817
1129.73	16.3709
1132.99	14.6295
1136.25	13.3574
1139.51	10.211
1142.77	10.306
1146.03	9.094
1149.28	9.83425
1152.54	8.67241
1155.79	8.0678
1159.04	7.4515
1162.29	6.73618
1165.54	5.47744
1168.79	6.26837
1172.04	7.21806
1175.28	5.93178
1178.53	9.13819
1181.77	9.45137
1185.01	12.2502
1188.25	12.9328
1191.49	14.9451
1194.73	14.9315
1197.96	16.6924
1201.2	18.9505
1204.43	20.0872
1207.66	21.0586
1210.9	23.4065
1214.13	26.9856
1217.36	28.6473
1220.58	32.569
1223.81	36.0269
1227.04	39.8312
1230.26	43.9151
1233.48	46.067
1236.71	48.5173
1239.93	51.4919
1243.14	53.3856
1246.36	56.4754
1249.58	58.0663
1252.8	59.3474
1256.01	60.7764
1259.22	61.9172
1262.43	63.3148
1265.64	64.1115
1268.85	62.6608
1272.06	61.7811
1275.27	61.7016
1278.48	61.3139
1281.68	61.8094
1284.88	62.3851
1288.08	63.0027
1291.28	64.8218
1294.48	63.7396
1297.68	65.1311
1300.88	66.4487
1304.07	69.0365
1307.27	72.8919
1310.46	75.1674
1313.65	78.851
1316.85	81.6737
1320.03	83.3992
1323.22	84.4674
1326.41	84.4071
1329.6	83.2514
1332.78	84.016
1335.96	84.6154
1339.15	83.4798
1342.33	84.0674
1345.51	80.971
1348.69	78.2317
1351.86	76.577
1355.04	72.7699
1358.21	70.9464
1361.39	68.1059
1364.56	63.2162
1367.73	60.9636
1370.9	58.3822
1374.07	56.2624
1377.24	54.2644
1380.41	52.8685
1383.57	52.5787
1386.73	52.6893
1389.9	51.9794
1393.06	52.0477
1396.22	50.394
1399.38	49.12
1402.54	48.7388
1405.69	47.9931
1408.85	48.7601
1412	50.8507
1415.16	52.7636
1418.31	56.5773
1421.46	59.6297
1424.61	61.9514
1427.76	65.0414
1430.9	68.25
1434.05	72.8966
1437.2	76.5661
1440.34	77.8833
1443.48	79.0599
1446.62	79.5018
1449.76	80.1712
1452.9	81.7168
1456.04	81.4374
1459.17	82.1755
1462.31	82.6489
1465.44	81.5038
1468.58	80.7831
1471.71	77.6857
1474.84	75.0339
1477.97	71.3247
1481.1	67.915
1484.22	63.2751
1487.35	59.6037
1490.47	56.9264
1493.59	54.2855
1496.72	49.7281
1499.84	44.846
1502.96	42.5281
1506.08	39.8021
1509.19	38.3681
1512.31	34.7983
1515.42	31.2375
1518.54	27.1932
1521.65	26.1074
1524.76	24.0291
1527.87	24.8252
1530.98	24.5068
1534.09	24.4102
1537.2	25.9671
1540.3	29.222
1543.41	30.5735
1546.51	32.7478
1549.61	33.6227
1552.71	36.747
1555.81	39.1341
1558.91	41.9165
1562.01	43.8804
1565.1	46.603
1568.2	48.6803
1571.29	51.2356
1574.38	52.8142
1577.48	55.5377
1580.57	57.2986
1583.65	58.0619
1586.74	59.5374
1589.83	60.6021
1592.92	61.5802
1596	61.8073
1599.08	63.1455
1602.16	62.3787
1605.24	60.2121
1608.32	59.1878
1611.4	58.6589
1614.48	57.3107
1617.56	56.9041
1620.63	56.0663
1623.71	57.3008
1626.78	57.8791
1629.85	60.0343
1632.92	61.1687
1635.99	64.5306
1639.06	68.2059
1642.12	71.7036
1645.19	74.4931
1648.25	78.2415
1651.32	80.5173
1654.38	82.5669
1657.44	84.2983
1660.5	84.4092
1663.56	83.0827
1666.62	82.4152
1669.67	79.6668
1672.73	76.9686
1675.79	72.4312
1678.84	67.3651
1681.89	60.6166
1684.94	55.9693
1687.99	50.2207
1691.04	43.9294
1694.08	38.6721
1697.13	34.6241
1700.18	29.7778
1703.22	25.4561
1706.26	22.7198
1709.3	20.3023
1712.35	18.9185
1715.39	17.2631
1718.42	15.7672
1721.46	13.7413
1724.5	12.5371
1727.53	11.1903
1730.56	9.75908
1733.6	7.79984
1736.63	6.46162
1739.66	6.83423
1742.69	6.53455
1745.71	6.26988
1748.74	6.90094
1751.77	5.89917
1754.79	6.13872
1757.81	5.00234
1760.84	4.75446
1763.86	4.56582
1766.88	3.31217
1769.9	3.91435
1772.91	3.6332
1775.93	3.47846
1778.95	3.8796
1781.96	4.64528
1784.97	3.80222
1787.99	3.88553
1791	2.80698
1794.01	3.02172
1797.01	3.11446
1800.02	3.50458
1803.03	4.152
1806.03	5.37229
1809.04	5.0025
1812.04	5.57357
1815.04	5.93485
1818.04	5.8507
1821.04	5.68792
1824.04	6.51685
1827.04	7.33031
1830.03	7.6994
1833.03	7.66584
1836.02	7.40384
1839.02	7.80208
1842.01	8.30632
1845	9.7739
1847.99	9.55563
1850.98	9.16644
1853.96	8.81694
1856.95	7.40481
1859.94	4.35127
1862.92	4.53587
1865.9	3.97674
1868.88	4.25245
1871.86	3.60388
1874.84	3.03799
1877.82	2.82807
1880.8	1.52794
1882.58	0.819513
1885.57	0.813997
1888.56	0.848684
1891.54	1.12066
1894.53	2.06081
1897.51	2.94182
1900.5	3.34412
1903.48	3.66119
1906.46	4.09896
1909.44	5.75776
1912.42	6.47618
1915.4	6.27001
1918.37	6.26563
1921.35	5.91009
1924.32	6.36254
1927.3	5.77855
1930.27	5.13797
1933.24	5.00791
1936.21	5.10142
1939.18	5.34473
1942.15	4.71162
1945.11	3.99221
1948.08	4.16458
1951.04	3.89177
1954.01	3.44652
1956.97	3.43942
1959.93	4.4158
1962.89	3.91767
1965.85	4.18728
1968.81	4.91987
1971.77	4.6495
1974.72	4.59538
1977.68	4.4943
1980.63	5.09977
1983.58	4.97378
1986.53	6.06412
1989.48	7.42154
1992.43	8.03916
1995.38	9.20002
1998.33	8.66803
2001.27	8.39002
2004.22	8.7749
2007.16	8.20551
2010.11	7.80174
2013.05	7.98139
2015.99	7.58486
2018.93	7.27187
2021.87	8.02497
2024.8	7.98617
2027.74	8.37525
2030.68	8.05808
2033.61	7.60015
2036.54	6.58643
2039.48	5.62802
2042.41	4.78394
2045.34	4.6079
2048.27	3.85346
2051.19	4.25804
2054.12	4.76325
2057.05	5.14415
2059.97	5.32502
2062.9	5.34126
2065.82	5.56263
2068.74	6.2701
2071.66	6.22937
2074.58	7.68615
2077.5	8.99026
2080.41	9.57971
2083.33	11.2777
2086.24	12.1902
2089.16	13.3375
2092.07	14.1421
2094.98	15.7662
2097.89	14.724
2100.8	16.0468
2103.71	16.9678
2106.62	17.3699
2109.53	16.8645
2112.43	17.3656
2115.33	17.5714
2118.24	18.3197
2121.14	19.6948
2124.04	20.2813
2126.94	21.6249
2129.84	23.993
2132.74	25.7402
2135.63	28.474
2138.53	30.9109
2141.43	33.6185
2144.32	36.3879
2147.21	39.6791
2150.1	42.8448
2152.99	45.9511
2155.88	48.3831
2158.77	51.3074
2161.66	53.3386
2164.55	56.3946
2167.43	57.8596
2170.31	60.2848
2173.2	62.3731
2176.08	62.8609
2178.96	62.2314
2181.84	61.2412
2184.72	60.9475
2187.6	59.1823
2190.47	58.1433
2193.35	55.9728
2196.23	53.9759
2199.1	51.7834
2201.97	48.6694
2204.84	46.3963
2207.71	44.2716
2210.58	41.2725
2213.45	37.9916
2216.32	35.5914
2219.19	33.6878
2222.05	31.1449
2224.92	30.1229
2227.78	28.5444
2230.64	26.3173
2233.5	25.6827
2236.36	24.9046
2239.22	23.9364
2242.08	23.0909
2244.94	21.4047
2247.79	20.2428
2250.65	19.7957
2253.5	18.5743
2256.36	17.325
2259.21	16.6019
2262.06	15.1884
2264.91	14.241
2267.76	13.0798
2270.6	12.496
2273.45	12.4975
2276.3	12.3836
2279.14	10.8706
2281.98	9.0458
2284.83	9.30897
2287.67	9.02111
2290.51	9.19052
2293.35	7.54485
2296.19	8.1705
2299.02	7.63074
2301.86	9.32197
2304.7	10.5003
2307.53	11.2627
2310.36	10.5288
2313.2	10.7785
2316.03	10.3842
2318.86	10.6907
2321.69	10.9135
2324.51	8.86681
2327.34	8.14542
2330.17	6.88416
2332.99	6.00122
2335.82	5.84076
2338.64	5.40372
2341.46	4.99512
2344.28	4.06334
2347.1	3.2577
2349.92	2.11175
2352.74	1.99506
2355.56	2.16772
2358.37	1.28664
2361.19	1.19064
2364	1.82342
2366.82	2.92861
2369.63	2.94742
2372.44	3.73138
2375.25	2.92525
2378.06	2.36725
2380.86	3.2146
2383.67	3.10279
2386.48	3.85459
2389.28	4.17086
2392.09	3.95543
2394.89	3.78472
2397.69	3.80177
2400.49	4.68749
2403.29	4.85574
2406.09	5.06438
2408.89	6.07139
2411.69	6.43945
2414.48	7.0018
2417.28	7.89287
2420.07	8.9215
2422.86	9.06089
2425.65	9.55293
2428.45	10.0209
2431.23	10.9489
2434.02	11.7334
2436.81	11.3195
2439.6	11.6659
2442.38	11.6594
2445.17	10.5524
2447.95	11.1214
2450.73	10.6476
2453.52	9.55922
2456.3	7.96432
2459.08	6.57716
2461.85	5.79498
2464.63	4.69552
2467.41	4.03675
2470.19	4.33227
2472.96	3.31777
2475.73	2.60566
2478.51	1.707
2481.28	0.488526
2484.05	1.34257
2486.82	1.15625
2489.59	1.66205
2492.35	1.60273
2495.12	2.48588
2497.89	2.57891
2500.65	2.56675
2503.42	2.52852
2506.18	2.49664
2508.94	4.11537
2511.7	3.25756
2514.46	3.41069
2517.22	3.93999
2519.98	3.25921
2522.73	3.34187
2525.49	3.62101
2528.25	4.11256
2531	4.70155
2533.75	5.2017
2536.5	6.00217
2539.25	6.26967
2542.01	6.15142
2544.75	6.17211
2547.5	5.95569
2550.25	5.61739
2553	5.82094
2555.74	5.79488
2558.49	4.81843
2561.23	4.81342
2563.97	4.14067
2566.71	4.76363
2569.45	5.11299
2572.19	5.37345
2574.93	6.79004
2577.67	6.85102
2580.4	6.7278
2583.14	7.28686
2585.87	7.33311
2588.6	7.50903
2591.34	7.17213
2594.07	7.70543
2596.8	8.42303
2599.53	8.12855
2602.26	8.5267
2604.98	7.75217
2607.71	7.1445
2610.44	6.57707
2613.16	6.33299
2615.88	5.60985
2618.61	5.2149
2621.33	4.96516
2624.05	4.41975
2626.77	4.562
2629.49	5.16684
2632.21	5.58237
2634.92	5.60218
2637.64	6.50774
2640.35	7.22465
2643.07	7.96752
2645.78	7.60434
2648.49	7.34447
2651.2	7.65313
2653.91	7.23462
2656.62	7.39938
2659.33	7.38503
2662.04	8.1774
2664.74	7.90942
2667.45	7.94187
2670.15	7.34332
2672.86	6.88282
2675.56	7.38862
2678.26	8.98707
2680.96	9.44068
2683.66	9.09228
2686.36	8.89071
2689.06	8.93286
2691.75	8.91808
2694.45	9.83647
2697.14	9.21149
2699.84	10.9548
2702.53	11.5354
2705.22	11.3458
2707.91	12.0471
2710.6	11.7034
2713.29	11.7883
2715.98	12.0508
2718.67	12.0717
2721.35	12.4057
2724.04	12.7051
2726.72	13.3551
2729.4	13.0204
2732.09	13.6255
2734.77	13.0798
2737.45	12.2427
2740.13	11.8604
2742.81	11.2909
2745.48	10.6391
2748.16	9.85908
2750.84	8.26402
2753.51	8.08553
2756.19	7.21957
2758.86	6.89021
2761.53	7.29632
2764.2	6.45141
2766.87	5.71532
2769.54	5.15493
2772.21	4.48731
2774.88	3.40777
2777.54	2.82699
2780.21	2.26802
2782.87	2.19121
2785.53	1.77438
2788.2	1.24887
2790.86	1.67549
2793.52	0.756053
2796.18	0.571806
2798.84	0.0823999
2801.49	-0.629738
2804.15	-1.11759
2806.81	-1.05754
2809.46	-0.393115
2812.12	0.192755
2814.77	1.06716
2817.42	2.85351
2820.07	5.30045
2822.72	8.21096
2825.37	11.4446
2828.02	15.134
2830.67	19.0829
2833.31	23.5217
2835.96	28.639
2838.61	34.7262
2841.25	40.5728
2843.89	47.5727
2846.53	55.6821
2849.17	63.2032
2851.81	73.0669
2854.45	83.1711
2857.09	93.5849
2859.73	102.224
2862.36	111.006
2865	120.274
2867.64	127.637
2870.27	135.212
2872.9	141.588
2875.53	148.025
2878.16	152.61
2880.79	157.317
2883.42	162.682
2886.05	166.362
2888.68	170.359
2891.3	174.31
2893.93	178.489
2896.55	183.058
2899.18	188.357
2901.8	195.069
2904.42	204.037
2907.04	214.387
2909.66	225.065
2912.28	237.015
2914.9	250.704
2917.51	262.682
2920.13	273.889
2922.74	282.496
2925.36	289.359
2927.97	295.28
2930.59	298.84
2933.2	299.048
2935.81	297.548
2938.42	293.573
2941.02	287.057
2943.63	276.944
2946.24	266.902
2948.85	256.165
2951.45	244.018
2954.05	231.989
2956.66	218.783
2959.26	205.777
2961.86	193.545
2964.46	181.649
2967.06	171.4
2969.66	160.427
2972.26	149.865
2974.85	141.192
2977.45	132.668
2980.05	123.985
2982.64	113.946
2985.23	105.254
2987.83	96.0872
2990.42	87.4564
2993.01	78.1548
2995.6	68.5204
2998.19	59.7392
3000.77	50.0156
3003.36	42.0218
3005.95	34.8451
3008.53	28.7804
3011.12	22.8343
3013.7	18.3049
3016.28	13.6038
3018.86	9.92857
3021.44	7.07776
3024.02	4.29988
3026.6	2.71993
3029.18	0.776276
3031.76	-0.54351
3034.33	-1.06306
3036.91	-0.177247
3039.48	0.687479
3042.05	1.32919
3044.63	2.50905
3047.2	2.95792
3049.77	4.49159
3052.34	5.13225
3054.91	5.30857
3057.48	5.77891
3060.04	5.49437
3062.61	5.23006
3065.17	5.55058
3067.74	4.62131
3070.3	4.54051
3072.87	3.26208
3075.43	2.88931
3077.99	2.2396
3080.55	1.88443
3083.11	1.11179
3085.67	0.456104
3088.22	-0.151076
3090.78	0.00940323
3093.34	-0.453388
3095.89	0.488583
3098.44	0.721695
3101	1.65937
3103.55	2.14241
3106.1	2.99663
3108.65	4.11825
3111.2	5.50232
3113.75	7.31124
3116.3	8.13519
3118.84	9.04971
3121.39	10.6854
3123.93	12.4862
3126.48	13.157
3129.02	14.3101
3131.56	15.1877
3134.1	16.3625
3136.64	17.5215
3139.18	18.5021
3141.72	19.4678
3144.26	20.4401
3146.8	22.564
3149.33	23.139