File: data/Raman/poly_smoothed/Mbcal_20_25_07_1x_45s_532 nm_x100_100%_600 gr_mm_01.txt
#Acq. time (s)=	45
#Accumulations=	2
#Range (cm-¹)=	200...3150
#Windows=	2
#Auto scanning=	Off
#Autofocus=	Off
#Macrospot=	Off
#AutoExposure=	Off
#Spike filter=	Multiple accum.
#Delay time (s)=	0
#Binning=	1
#Readout mode=	Signal
#DeNoise=	Off
#ICS correction=	On
#Dark correction=	Off
#Inst. Process=	Off
#Detector Gain=	Best Dynamic Range
#Detector ADC=	20 kHz
#Detector temperature (°C)=	-69.85
#Instrument=	LabRAM HR Evol
#Detector=	Synapse
#Objective=	x100
#Grating=	600 gr/mm
#ND Filter=	100%
#Laser (nm)=	532
#Hole=	100.021
#Range=	Auto
#Laser Pol.=	No
#Raman. Pol.=	No
#Laser Pol. (°)=	-0.0007625
#Raman Pol. (°)=	89.9995
#Collection=	Microscope
#StageXY=	Marzhauser
#StageZ=	Marzhauser
#X (µm)=	-1197.9
#Y (µm)=	1252.7
#Z (µm)=	578.3
#Full time(mm:ss)=	3:18
#Project=
#Sample=
#Site=
#Title=	Mbcal_20_25_07_2x_45s_532 nm_x100_100%_600 gr_mm
#Remark=
#Date=	18.07.2022 09:55
#Acquired=	18.07.2022 09:55:47
#Base:Fit=	10.08.2022 10:55:08
#Base:Sub=	10.08.2022 10:55:14
#Filter:Polynom=	16.08.2022 10:07:28
#AxisType[0]=Intens
#AxisUnit[0]=Cnt
#AxisType[1]=Spectr
#AxisUnit[1]=1/cm
200.419	12.2802
204.048	8.85893
207.678	7.61482
211.304	6.43373
214.928	5.5985
218.554	6.3454
222.176	6.92784
225.798	7.16268
229.417	7.20615
233.035	7.20361
236.653	6.09049
240.268	7.62582
243.881	7.84617
247.493	7.5984
251.103	7.58593
254.715	7.30259
258.322	8.74022
261.929	9.71053
265.534	10.6779
269.137	11.3145
272.739	11.4027
276.34	11.3999
279.939	10.929
283.537	11.5053
287.134	10.9474
290.729	10.1975
294.323	10.9163
297.913	11.9508
301.504	12.0234
305.093	13.6836
308.682	12.6827
312.268	12.4977
315.852	13.8899
319.436	15.3721
323.018	16.4142
326.597	18.5174
330.177	18.4101
333.753	17.5927
337.331	18.3174
340.906	18.2154
344.478	17.821
348.051	17.3328
351.621	16.668
355.189	14.5527
358.757	13.2055
362.323	12.2619
365.889	10.3711
369.451	9.52867
373.012	8.30811
376.574	6.90756
380.133	5.33787
383.69	5.64149
387.245	5.01606
390.8	3.62406
394.353	3.14924
397.906	4.50808
401.456	6.49598
405.005	8.30226
408.552	8.22682
412.099	9.70247
415.643	10.485
419.187	10.2565
422.728	12.0283
426.269	12.7197
429.806	11.7389
433.344	10.9007
436.881	9.88861
440.416	9.85242
443.949	8.04224
447.48	8.22463
451.011	7.14714
454.541	6.02214
458.069	6.02855
461.594	5.60709
465.119	5.53777
468.642	5.83937
472.165	6.05763
475.684	6.51832
479.204	7.18626
482.721	8.27013
486.239	9.54454
489.753	9.10543
493.268	9.86736
496.779	10.8777
500.289	11.9442
503.8	11.4484
507.307	12.6518
510.813	13.7468
514.32	13.4954
517.823	15.1891
521.325	15.7247
524.826	16.4268
528.325	15.7333
531.823	15.175
535.32	13.566
538.815	14.3259
542.309	15.1802
545.802	14.4441
549.293	12.8713
552.783	12.484
556.271	12.7169
559.759	10.3959
563.245	10.0914
566.729	10.2665
570.213	7.63203
573.693	5.10537
577.173	4.43441
580.652	3.7892
584.13	3.66356
587.605	2.57227
591.08	1.9387
594.552	1.83623
598.025	1.97161
601.496	2.87568
604.964	2.40935
608.433	2.12546
611.898	1.65376
615.364	2.04141
618.827	3.81249
622.288	4.90179
625.75	6.37935
629.209	6.05237
632.667	6.43334
636.125	7.75269
639.58	9.85634
643.033	10.1498
646.485	11.7682
649.936	13.499
653.388	13.5047
656.836	15.1456
660.283	16.9002
663.728	18.281
667.173	18.8496
670.616	18.8521
674.057	18.5149
677.498	18.5672
680.937	17.5799
684.375	19.7403
687.809	20.076
691.244	20.1778
694.678	22.0109
698.111	22.8272
701.54	25.02
704.97	27.4801
708.398	29.4246
711.826	30.4996
715.25	32.5215
718.675	33.5657
722.096	34.5353
725.518	37.3833
728.937	40.3335
732.357	41.2055
735.773	42.8058
739.19	45.7429
742.604	49.0269
746.018	52.0764
749.429	54.4595
752.839	55.0735
756.248	56.5336
759.657	57.2441
763.063	57.1827
766.468	58.9244
769.871	60.9913
773.273	62.5115
776.676	64.7336
780.075	68.0322
783.474	69.9325
786.871	72.1828
790.266	72.2637
793.661	72.5718
797.054	72.6079
800.446	72.8735
803.834	73.819
807.224	74.164
810.612	74.7518
813.998	73.1488
817.384	71.969
820.766	72.2519
824.149	73.2752
827.531	73.2284
830.909	71.5918
834.288	69.7205
837.666	68.5596
841.041	66.0671
844.416	66.7625
847.788	65.137
851.161	65.241
854.53	64.7632
857.901	64.1673
861.268	62.1896
864.633	60.6404
868	58.2085
871.363	56.3719
874.725	54.6397
878.088	54.618
881.447	55.5596
884.805	54.2525
888.162	53.3127
891.518	51.4451
894.872	49.2118
898.225	48.3386
901.577	47.0749
904.928	47.1828
908.277	47.5294
911.625	47.4297
914.972	46.6053
918.318	46.9101
921.662	46.2614
925.005	46.7798
928.347	45.9783
931.686	43.3937
935.025	42.3574
938.363	40.2254
941.698	36.8522
945.034	35.7253
948.368	35.5906
951.699	35.223
955.031	34.6434
958.36	33.0249
961.689	32.4297
965.016	31.079
968.343	28.8247
971.666	28.2192
974.991	26.3342
978.312	26.0607
981.632	25.7442
984.953	25.1902
988.27	24.3102
991.587	23.3031
994.902	22.0689
998.216	20.5823
1001.53	18.8678
1004.84	17.1044
1008.15	16.8568
1011.46	16.7021
1014.77	15.5823
1018.07	15.0087
1021.38	14.7338
1024.68	16.2638
1027.99	18.2825
1031.29	19.8963
1034.59	19.3674
1037.89	19.3015
1041.18	19.2315
1044.48	19.6989
1047.77	19.2875
1051.07	19.8166
1054.36	20.3451
1057.65	19.9868
1060.94	20.0605
1064.23	18.404
1067.52	17.3941
1070.8	18.5739
1074.09	17.6123
1077.37	15.8605
1080.65	14.981
1083.93	14.4478
1087.21	12.784
1090.49	11.2565
1093.77	11.2743
1097.04	11.3714
1100.32	11.8016
1103.59	12.0758
1106.86	11.889
1110.13	11.5971
1113.4	11.4016
1116.67	10.7684
1119.94	9.87701
1123.2	8.11065
1126.47	8.15293
1129.73	7.8927
1132.99	8.22292
1136.25	8.93935
1139.51	10.5118
1142.77	11.1908
1146.03	10.7431
1149.28	12.8303
1152.54	13.2956
1155.79	10.6913
1159.04	10.2641
1162.29	8.95189
1165.54	8.17693
1168.79	8.23663
1172.04	9.06643
1175.28	8.69095
1178.53	10.0907
1181.77	10.0628
1185.01	9.23612
1188.25	9.27187
1191.49	9.71087
1194.73	11.0888
1197.96	11.8791
1201.2	11.9246
1204.43	12.9043
1207.66	14.0056
1210.9	15.5361
1214.13	16.4596
1217.36	17.397
1220.58	18.3889
1223.81	19.6477
1227.04	19.7119
1230.26	19.9649
1233.48	20.1409
1236.71	21.1745
1239.93	21.6092
1243.14	20.4161
1246.36	22.0059
1249.58	23.7542
1252.8	24.7944
1256.01	25.0083
1259.22	25.6427
1262.43	24.8807
1265.64	26.3486
1268.85	28.1598
1272.06	29.951
1275.27	30.5582
1278.48	31.1025
1281.68	30.7957
1284.88	29.9633
1288.08	29.7091
1291.28	30.0261
1294.48	30.6319
1297.68	31.0338
1300.88	30.5945
1304.07	30.5343
1307.27	30.8657
1310.46	31.2236
1313.65	32.7783
1316.85	33.5816
1320.03	33.937
1323.22	35.1288
1326.41	37.7806
1329.6	39.3952
1332.78	39.9159
1335.96	41.6081
1339.15	42.1194
1342.33	44.9046
1345.51	47.1647
1348.69	47.6117
1351.86	48.8875
1355.04	47.6192
1358.21	46.3641
1361.39	46.3351
1364.56	45.6766
1367.73	45.1988
1370.9	44.603
1374.07	43.0627
1377.24	40.672
1380.41	38.4672
1383.57	37.3813
1386.73	35.235
1389.9	35.7816
1393.06	34.3694
1396.22	32.4131
1399.38	31.0252
1402.54	29.6856
1405.69	31.378
1408.85	31.2961
1412	32.2119
1415.16	33.0842
1418.31	33.4693
1421.46	36.7527
1424.61	40.0373
1427.76	42.7723
1430.9	44.6479
1434.05	48.377
1437.2	52.2553
1440.34	54.1855
1443.48	55.519
1446.62	56.2179
1449.76	56.5737
1452.9	57.198
1456.04	56.6113
1459.17	56.4061
1462.31	56.9767
1465.44	57.6144
1468.58	55.954
1471.71	54.0438
1474.84	53.3822
1477.97	51.8042
1481.1	50.3867
1484.22	48.5
1487.35	46.3297
1490.47	44.5992
1493.59	42.8967
1496.72	40.4589
1499.84	39.0389
1502.96	36.5272
1506.08	33.7068
1509.19	32.523
1512.31	31.1491
1515.42	27.5747
1518.54	24.0949
1521.65	23.3038
1524.76	22.9309
1527.87	21.0712
1530.98	20.8569
1534.09	21.0128
1537.2	22.1204
1540.3	22.705
1543.41	23.3825
1546.51	24.4919
1549.61	25.8233
1552.71	26.4031
1555.81	27.427
1558.91	28.411
1562.01	29.3471
1565.1	30.1072
1568.2	29.6082
1571.29	29.4877
1574.38	29.6976
1577.48	31.2424
1580.57	32.6923
1583.65	35.4683
1586.74	37.4429
1589.83	38.6317
1592.92	39.0846
1596	40.3151
1599.08	40.6355
1602.16	39.7081
1605.24	38.2548
1608.32	37.3226
1611.4	37.6416
1614.48	35.9356
1617.56	34.7774
1620.63	33.0452
1623.71	33.4225
1626.78	32.0989
1629.85	31.8155
1632.92	31.9666
1635.99	31.5239
1639.06	31.0479
1642.12	29.8189
1645.19	30.4652
1648.25	32.6858
1651.32	33.9839
1654.38	34.601
1657.44	34.6476
1660.5	35.2527
1663.56	34.6488
1666.62	33.9707
1669.67	32.7026
1672.73	31.7769
1675.79	28.1266
1678.84	26.584
1681.89	24.9053
1684.94	22.6669
1687.99	20.6358
1691.04	18.7606
1694.08	17.5468
1697.13	17.3099
1700.18	15.4706
1703.22	14.6847
1706.26	13.9302
1709.3	14.0373
1712.35	13.5854
1715.39	12.9339
1718.42	12.9657
1721.46	13.2083
1724.5	12.2929
1727.53	10.468
1730.56	9.83438
1733.6	9.39668
1736.63	8.29103
1739.66	7.50313
1742.69	6.31365
1745.71	5.90102
1748.74	5.56545
1751.77	4.10399
1754.79	4.43901
1757.81	3.25207
1760.84	2.88279
1763.86	3.28521
1766.88	3.08847
1769.9	3.13152
1772.91	3.75631
1775.93	4.26006
1778.95	4.35105
1781.96	5.17213
1784.97	5.63557
1787.99	6.1988
1791	6.14169
1794.01	6.49098
1797.01	6.46591
1800.02	5.81782
1803.03	6.41631
1806.03	7.02576
1809.04	6.61971
1812.04	6.7006
1815.04	7.0735
1818.04	7.99628
1821.04	8.35698
1824.04	9.10009
1827.04	9.2732
1830.03	8.95352
1833.03	8.00921
1836.02	8.25199
1839.02	8.44066
1842.01	8.31669
1845	8.6869
1847.99	8.00349
1850.98	6.71106
1853.96	5.33413
1856.95	5.69079
1859.94	4.49848
1862.92	4.08957
1865.9	3.37945
1868.88	2.63099
1871.86	2.32278
1874.84	2.75929
1877.82	3.50117
1880.8	2.71555
1882.58	2.48907
1885.57	2.55004
1888.56	3.72813
1891.54	5.89163
1894.53	6.58519
1897.51	6.99599
1900.5	7.67885
1903.48	7.41931
1906.46	8.30083
1909.44	9.57391
1912.42	10.4926
1915.4	10.4276
1918.37	11.3498
1921.35	10.7675
1924.32	11.1043
1927.3	11.5771
1930.27	11.4836
1933.24	10.7514
1936.21	10.1237
1939.18	10.3925
1942.15	11.3185
1945.11	10.9699
1948.08	10.6595
1951.04	9.67669
1954.01	9.53917
1956.97	9.72074
1959.93	9.84549
1962.89	11.004
1965.85	9.79424
1968.81	9.8104
1971.77	9.82096
1974.72	9.82109
1977.68	9.52684
1980.63	10.9223
1983.58	9.99528
1986.53	8.82753
1989.48	8.88846
1992.43	8.21494
1995.38	6.91534
1998.33	5.94328
2001.27	5.80797
2004.22	5.54447
2007.16	5.45681
2010.11	5.42654
2013.05	6.32597
2015.99	5.64439
2018.93	4.99719
2021.87	5.84515
2024.8	6.96526
2027.74	6.30203
2030.68	6.0758
2033.61	6.75888
2036.54	7.47768
2039.48	7.78599
2042.41	8.83522
2045.34	8.51429
2048.27	8.19869
2051.19	8.86462
2054.12	7.6774
2057.05	7.28881
2059.97	7.3269
2062.9	6.66174
2065.82	6.3044
2068.74	7.19708
2071.66	8.43358
2074.58	8.70091
2077.5	8.62159
2080.41	8.65455
2083.33	9.96188
2086.24	9.63105
2089.16	9.99777
2092.07	9.98252
2094.98	11.321
2097.89	10.7788
2100.8	11.6246
2103.71	11.7448
2106.62	12.473
2109.53	11.5939
2112.43	10.3429
2115.33	9.20577
2118.24	8.83414
2121.14	8.76276
2124.04	8.20031
2126.94	8.49905
2129.84	9.37867
2132.74	10.407
2135.63	10.9088
2138.53	11.9465
2141.43	13.4481
2144.32	13.5098
2147.21	13.9797
2150.1	15.7251
2152.99	17.0262
2155.88	18.6243
2158.77	18.4973
2161.66	19.6856
2164.55	20.6217
2167.43	21.0437
2170.31	21.0518
2173.2	21.002
2176.08	20.6009
2178.96	20.2007
2181.84	19.5162
2184.72	19.4193
2187.6	20.4307
2190.47	19.4855
2193.35	18.7727
2196.23	18.657
2199.1	18.9975
2201.97	18.4839
2204.84	18.6704
2207.71	18.0837
2210.58	17.1213
2213.45	15.9996
2216.32	15.0531
2219.19	14.5037
2222.05	14.6158
2224.92	13.9177
2227.78	13.0394
2230.64	11.5899
2233.5	10.8449
2236.36	9.18248
2239.22	8.18025
2242.08	8.08292
2244.94	7.90159
2247.79	6.93961
2250.65	5.93701
2253.5	5.79664
2256.36	5.04682
2259.21	4.7481
2262.06	3.28659
2264.91	2.99467
2267.76	3.33301
2270.6	3.93467
2273.45	3.78633
2276.3	3.1158
2279.14	2.95072
2281.98	2.99027
2284.83	2.90274
2287.67	2.87524
2290.51	3.05592
2293.35	2.23756
2296.19	2.083
2299.02	3.74804
2301.86	4.72085
2304.7	5.32194
2307.53	5.72436
2310.36	6.90182
2313.2	7.17239
2316.03	6.25744
2318.86	7.00005
2321.69	7.63357
2324.51	8.14158
2327.34	8.63806
2330.17	7.97199
2332.99	6.98857
2335.82	7.87767
2338.64	7.69428
2341.46	6.55668
2344.28	5.31061
2347.1	4.70778
2349.92	4.67876
2352.74	3.19847
2355.56	1.56476
2358.37	1.04929
2361.19	0.489745
2364	1.08955
2366.82	2.10755
2369.63	2.7366
2372.44	2.26584
2375.25	2.10858
2378.06	2.16715
2380.86	2.36043
2383.67	1.93932
2386.48	2.93943
2389.28	3.50946
2392.09	3.97501
2394.89	3.99287
2397.69	3.18845
2400.49	2.09552
2403.29	2.46131
2406.09	2.57126
2408.89	2.16872
2411.69	2.37241
2414.48	2.90029
2417.28	3.66903
2420.07	3.33292
2422.86	2.72942
2425.65	1.6287
2428.45	1.57547
2431.23	1.8909
2434.02	2.04311
2436.81	1.11128
2439.6	1.21829
2442.38	1.27073
2445.17	1.56065
2447.95	1.23483
2450.73	0.375473
2453.52	0.647795
2456.3	0.609301
2459.08	1.2508
2461.85	2.41742
2464.63	2.00203
2467.41	2.33337
2470.19	3.28512
2472.96	4.09882
2475.73	4.64614
2478.51	5.56318
2481.28	5.67524
2484.05	5.48691
2486.82	4.85127
2489.59	4.26814
2492.35	3.41121
2495.12	3.16469
2497.89	3.5578
2500.65	3.02061
2503.42	1.82667
2506.18	2.02765
2508.94	1.34028
2511.7	1.41528
2514.46	1.28724
2517.22	0.800322
2519.98	-0.28434
2522.73	0.655583
2525.49	1.59489
2528.25	3.02635
2531	2.42886
2533.75	2.70886
2536.5	3.9164
2539.25	4.23179
2542.01	4.73196
2544.75	5.75486
2547.5	5.33956
2550.25	6.3973
2553	6.01129
2555.74	7.04064
2558.49	7.45747
2561.23	8.01445
2563.97	8.04433
2566.71	7.59175
2569.45	6.81616
2572.19	7.28577
2574.93	7.09774
2577.67	6.41145
2580.4	5.82964
2583.14	4.82379
2585.87	5.33741
2588.6	5.3239
2591.34	5.39177
2594.07	5.37393
2596.8	4.30383
2599.53	4.23581
2602.26	4.76455
2604.98	4.81748
2607.71	5.29511
2610.44	5.38772
2613.16	5.78967
2615.88	5.64536
2618.61	7.11031
2621.33	7.79587
2624.05	8.3187
2626.77	7.77292
2629.49	8.57909
2632.21	7.58775
2634.92	7.66037
2637.64	8.25169
2640.35	8.63488
2643.07	8.17626
2645.78	7.79986
2648.49	7.56031
2651.2	7.0633
2653.91	5.75961
2656.62	5.90557
2659.33	5.59798
2662.04	5.60991
2664.74	4.65361
2667.45	4.91704
2670.15	3.88338
2672.86	4.03348
2675.56	3.15987
2678.26	3.28931
2680.96	3.42095
2683.66	3.5619
2686.36	4.11389
2689.06	4.61235
2691.75	4.80573
2694.45	5.80883
2697.14	5.88942
2699.84	6.44593
2702.53	7.90449
2705.22	8.73567
2707.91	8.72711
2710.6	8.46771
2713.29	8.81771
2715.98	9.14138
2718.67	9.0087
2721.35	9.67148
2724.04	10.0521
2726.72	10.5836
2729.4	10.0175
2732.09	8.70187
2734.77	7.61019
2737.45	7.26409
2740.13	6.80412
2742.81	6.62077
2745.48	6.08172
2748.16	5.9428
2750.84	5.60188
2753.51	5.48948
2756.19	4.84601
2758.86	4.11377
2761.53	3.98969
2764.2	3.97277
2766.87	3.95753
2769.54	3.53199
2772.21	2.8668
2774.88	3.15597
2777.54	3.20714
2780.21	3.09162
2782.87	2.08423
2785.53	1.29713
2788.2	1.56535
2790.86	1.52866
2793.52	1.51149
2796.18	0.225195
2798.84	-0.00878069
2801.49	1.20819
2804.15	1.2751
2806.81	1.21145
2809.46	1.19529
2812.12	0.971732
2814.77	1.68748
2817.42	2.45125
2820.07	3.5926
2822.72	5.14817
2825.37	6.67362
2828.02	9.44196
2830.67	11.832
2833.31	13.3697
2835.96	16.4254
2838.61	18.5646
2841.25	21.4638
2843.89	24.2317
2846.53	26.4782
2849.17	27.8154
2851.81	30.6869
2854.45	34.3167
2857.09	37.1988
2859.73	39.8017
2862.36	42.4984
2865	45.2923
2867.64	47.2153
2870.27	48.0165
2872.9	49.6997
2875.53	51.5422
2878.16	53.3669
2880.79	56.3076
2883.42	58.1137
2886.05	59.8169
2888.68	61.8334
2891.3	63.5829
2893.93	65.2891
2896.55	66.2214
2899.18	68.4249
2901.8	70.1984
2904.42	71.3304
2907.04	74.0048
2909.66	76.3091
2912.28	78.9592
2914.9	81.2887
2917.51	83.5418
2920.13	85.7008
2922.74	88.0448
2925.36	88.9783
2927.97	89.171
2930.59	89.8299
2933.2	89.0831
2935.81	86.9076
2938.42	85.3686
2941.02	82.9489
2943.63	80.234
2946.24	77.6121
2948.85	73.958
2951.45	70.0676
2954.05	65.8089
2956.66	61.2817
2959.26	57.6178
2961.86	54.4246
2964.46	50.513
2967.06	46.5761
2969.66	44.4485
2972.26	41.725
2974.85	38.8279
2977.45	35.8659
2980.05	34.1086
2982.64	32.375
2985.23	30.4251
2987.83	28.3191
2990.42	25.1611
2993.01	23.5219
2995.6	19.9911
2998.19	17.5789
3000.77	15.1275
3003.36	13.2144
3005.95	12.1649
3008.53	10.6033
3011.12	8.4391
3013.7	6.142
3016.28	4.72896
3018.86	4.05261
3021.44	2.78447
3024.02	2.16977
3026.6	1.1283
3029.18	0.19913
3031.76	0.0724756
3034.33	-0.213781
3036.91	-0.972821
3039.48	-1.18087
3042.05	-0.0757917
3044.63	-0.108838
3047.2	0.297661
3049.77	0.730945
3052.34	0.862753
3054.91	0.825822
3057.48	1.39864
3060.04	1.88629
3062.61	2.36789
3065.17	2.01831
3067.74	2.20153
3070.3	2.89724
3072.87	2.93931
3075.43	2.95503
3077.99	3.74979
3080.55	3.02753
3083.11	2.28621
3085.67	2.36615
3088.22	1.79051
3090.78	1.94039
3093.34	1.62948
3095.89	0.990464
3098.44	1.0598
3101	0.984868
3103.55	1.44035
3106.1	2.93355
3108.65	3.02681
3111.2	3.74719
3113.75	4.061
3116.3	4.03075
3118.84	4.40091
3121.39	5.68571
3123.93	5.61951
3126.48	6.21562
3129.02	7.12488
3131.56	8.59983
3134.1	9.88052
3136.64	11.2209
3139.18	12.0472
3141.72	12.5645
3144.26	14.1053
3146.8	15.73
3149.33	17.7514