File: data/Raman/poly_smoothed/Mbcal_20_25_10_1x_45s_532 nm_x100_100%_600 gr_mm_01.txt
#Acq. time (s)=	45
#Accumulations=	2
#Range (cm-¹)=	200...3150
#Windows=	2
#Auto scanning=	Off
#Autofocus=	Off
#Macrospot=	Off
#AutoExposure=	Off
#Spike filter=	Multiple accum.
#Delay time (s)=	0
#Binning=	1
#Readout mode=	Signal
#DeNoise=	Off
#ICS correction=	On
#Dark correction=	Off
#Inst. Process=	Off
#Detector Gain=	Best Dynamic Range
#Detector ADC=	20 kHz
#Detector temperature (°C)=	-69.85
#Instrument=	LabRAM HR Evol
#Detector=	Synapse
#Objective=	x100
#Grating=	600 gr/mm
#ND Filter=	100%
#Laser (nm)=	532
#Hole=	100.021
#Range=	Auto
#Laser Pol.=	No
#Raman. Pol.=	No
#Laser Pol. (°)=	-0.0007625
#Raman Pol. (°)=	89.9995
#Collection=	Microscope
#StageXY=	Marzhauser
#StageZ=	Marzhauser
#X (µm)=	-1203.3
#Y (µm)=	1246.6
#Z (µm)=	577.6
#Full time(mm:ss)=	3:18
#Project=
#Sample=
#Site=
#Title=	Mbcal_20_25_10_2x_45s_532 nm_x100_100%_600 gr_mm
#Remark=
#Date=	18.07.2022 10:09
#Acquired=	18.07.2022 10:09:03
#Base:Fit=	10.08.2022 10:55:08
#Base:Sub=	10.08.2022 10:55:14
#Filter:Polynom=	16.08.2022 10:07:28
#AxisType[0]=Intens
#AxisUnit[0]=Cnt
#AxisType[1]=Spectr
#AxisUnit[1]=1/cm
200.419	3.33382
204.048	3.63271
207.678	5.18777
211.304	5.86154
214.928	6.1109
218.554	6.03521
222.176	6.16668
225.798	4.14014
229.417	4.53791
233.035	4.44409
236.653	4.71577
240.268	5.53995
243.881	5.63318
247.493	5.66739
251.103	5.34932
254.715	3.6181
258.322	3.86178
261.929	4.68378
265.534	5.55945
269.137	4.87501
272.739	4.06706
276.34	3.53606
279.939	4.3163
283.537	3.44485
287.134	3.23325
290.729	3.33961
294.323	3.1588
297.913	3.42199
301.504	5.73597
305.093	6.71194
308.682	7.51848
312.268	7.74476
315.852	8.55831
319.436	11.1768
323.018	11.3317
326.597	13.4603
330.177	15.1245
333.753	15.9897
337.331	16.7711
340.906	15.4318
344.478	17.1005
348.051	19.8442
351.621	21.7125
355.189	21.5083
358.757	21.1602
362.323	21.0261
365.889	21.4023
369.451	21.3587
373.012	21.3661
376.574	20.391
380.133	21.3533
383.69	22.8438
387.245	23.5886
390.8	24.3386
394.353	23.7951
397.906	23.8727
401.456	24.6593
405.005	23.7789
408.552	22.8255
412.099	22.6668
415.643	22.3966
419.187	21.4721
422.728	20.1545
426.269	19.4105
429.806	19.0253
433.344	19.3851
436.881	19.2254
440.416	16.1636
443.949	14.7768
447.48	15.747
451.011	14.386
454.541	13.6695
458.069	13.4928
461.594	13.5445
465.119	13.5924
468.642	14.5682
472.165	15.3685
475.684	17.845
479.204	19.4043
482.721	20.5591
486.239	23.2332
489.753	23.5097
493.268	23.0159
496.779	25.0092
500.289	24.5586
503.8	26.8547
507.307	28.2504
510.813	29.8067
514.32	30.644
517.823	31.2905
521.325	31.9493
524.826	32.8684
528.325	32.8752
531.823	33.4303
535.32	33.3707
538.815	31.165
542.309	29.5816
545.802	28.7429
549.293	28.5603
552.783	26.4378
556.271	26.7014
559.759	25.7731
563.245	25.2274
566.729	23.2264
570.213	20.5881
573.693	19.0953
577.173	16.5847
580.652	14.2026
584.13	11.8845
587.605	11.0045
591.08	10.9441
594.552	10.6049
598.025	10.3953
601.496	9.31144
604.964	9.69927
608.433	12.5641
611.898	14.9927
615.364	15.0198
618.827	15.2053
622.288	16.5095
625.75	16.8327
629.209	19.5803
632.667	22.8479
636.125	24.1509
639.58	27.4154
643.033	29.8798
646.485	30.6291
649.936	30.5304
653.388	30.4995
656.836	29.8211
660.283	30.0926
663.728	28.0163
667.173	28.2651
670.616	29.1742
674.057	29.6859
677.498	30.2377
680.937	30.4494
684.375	29.7724
687.809	31.5515
691.244	34.0461
694.678	35.9033
698.111	35.4315
701.54	37.1592
704.97	36.6788
708.398	37.8547
711.826	40.9721
715.25	41.8178
718.675	43.2295
722.096	44.3328
725.518	46.3469
728.937	44.6183
732.357	44.0229
735.773	45.792
739.19	45.492
742.604	43.4863
746.018	42.8401
749.429	45.4478
752.839	47.3183
756.248	50.304
759.657	52.4109
763.063	55.9396
766.468	56.7653
769.871	59.0812
773.273	63.2539
776.676	66.0375
780.075	67.6357
783.474	70.7391
786.871	73.992
790.266	75.2186
793.661	78.415
797.054	78.6526
800.446	79.2624
803.834	80.8748
807.224	79.5519
810.612	78.2362
813.998	75.3147
817.384	74.7958
820.766	73.774
824.149	71.808
827.531	71.5575
830.909	72.6175
834.288	74.6203
837.666	77.4467
841.041	79.7398
844.416	80.4425
847.788	80.2969
851.161	79.4058
854.53	79.0153
857.901	79.6587
861.268	80.2128
864.633	78.4244
868	76.5443
871.363	73.4882
874.725	70.3061
878.088	67.9625
881.447	63.8549
884.805	60.8182
888.162	56.7209
891.518	52.3769
894.872	48.0887
898.225	45.958
901.577	44.1893
904.928	42.3812
908.277	41.6525
911.625	41.3409
914.972	42.5166
918.318	44.2449
921.662	44.1608
925.005	44.0092
928.347	43.6728
931.686	44.1329
935.025	43.9324
938.363	44.3113
941.698	44.7959
945.034	41.5583
948.368	38.5704
951.699	36.8841
955.031	33.6581
958.36	31.277
961.689	28.2402
965.016	26.9905
968.343	26.7511
971.666	25.6383
974.991	24.3185
978.312	22.7825
981.632	21.6731
984.953	18.0979
988.27	17.8971
991.587	15.8568
994.902	14.4237
998.216	14.3547
1001.53	13.1978
1004.84	12.2642
1008.15	12.4287
1011.46	12.2918
1014.77	14.9634
1018.07	16.2288
1021.38	17.9143
1024.68	16.8207
1027.99	17.7302
1031.29	20.0166
1034.59	20.1243
1037.89	19.8345
1041.18	20.649
1044.48	22.2503
1047.77	24.6093
1051.07	26.5358
1054.36	24.7333
1057.65	22.9969
1060.94	23.2667
1064.23	21.5523
1067.52	22.2539
1070.8	22.6184
1074.09	20.874
1077.37	19.9902
1080.65	19.5938
1083.93	19.1641
1087.21	18.7632
1090.49	20.7552
1093.77	22.376
1097.04	24.4966
1100.32	25.7382
1103.59	26.7599
1106.86	26.0621
1110.13	24.5709
1113.4	22.461
1116.67	21.0449
1119.94	18.2944
1123.2	17.8118
1126.47	17.1821
1129.73	16.2902
1132.99	13.4954
1136.25	11.1126
1139.51	10.951
1142.77	11.6161
1146.03	10.2693
1149.28	9.4949
1152.54	8.44672
1155.79	6.11993
1159.04	5.37041
1162.29	4.05147
1165.54	3.15862
1168.79	3.38883
1172.04	3.86535
1175.28	3.68314
1178.53	3.28409
1181.77	4.76917
1185.01	3.55368
1188.25	2.98289
1191.49	3.28699
1194.73	3.89207
1197.96	7.0213
1201.2	8.81334
1204.43	9.33545
1207.66	10.7918
1210.9	12.3785
1214.13	14.4503
1217.36	16.6914
1220.58	19.2842
1223.81	20.9455
1227.04	23.4398
1230.26	25.7721
1233.48	27.0793
1236.71	29.0993
1239.93	32.7833
1243.14	34.255
1246.36	36.369
1249.58	38.4659
1252.8	39.1469
1256.01	40.5503
1259.22	43.5762
1262.43	45.4899
1265.64	46.8358
1268.85	48.0957
1272.06	48.7654
1275.27	51.0629
1278.48	51.5202
1281.68	52.0546
1284.88	52.7696
1288.08	55.9441
1291.28	58.817
1294.48	59.6098
1297.68	59.8641
1300.88	60.5434
1304.07	61.8681
1307.27	62.1558
1310.46	62.4312
1313.65	62.2124
1316.85	63.6406
1320.03	64.7932
1323.22	64.8913
1326.41	63.6377
1329.6	63.7838
1332.78	63.4493
1335.96	63.3718
1339.15	64.4302
1342.33	63.8554
1345.51	61.7639
1348.69	59.7011
1351.86	61.0091
1355.04	59.6546
1358.21	59.1184
1361.39	59.4034
1364.56	59.7511
1367.73	58.6935
1370.9	58.0038
1374.07	56.3124
1377.24	55.3423
1380.41	52.6849
1383.57	51.4343
1386.73	49.0915
1389.9	48.0764
1393.06	47.3844
1396.22	47.1642
1399.38	47.1287
1402.54	47.1558
1405.69	48.3927
1408.85	50.743
1412	53.371
1415.16	58.3158
1418.31	61.2714
1421.46	66.4337
1424.61	72.1152
1427.76	77.6047
1430.9	84.1661
1434.05	90.5663
1437.2	97.0174
1440.34	100.817
1443.48	103.762
1446.62	106.096
1449.76	107.746
1452.9	107.859
1456.04	105.743
1459.17	105.002
1462.31	103.553
1465.44	102.38
1468.58	99.4736
1471.71	96.3744
1474.84	92.5047
1477.97	88.402
1481.1	85.3734
1484.22	81.1253
1487.35	77.175
1490.47	72.4113
1493.59	67.7902
1496.72	64.2653
1499.84	62.7605
1502.96	59.2075
1506.08	55.4068
1509.19	51.2385
1512.31	46.9081
1515.42	41.8314
1518.54	37.9512
1521.65	33.7547
1524.76	33.242
1527.87	30.9857
1530.98	30.4459
1534.09	29.6835
1537.2	30.9867
1540.3	33.1133
1543.41	34.1764
1546.51	33.865
1549.61	35.4237
1552.71	36.8547
1555.81	38.1699
1558.91	39.2958
1562.01	39.3565
1565.1	39.3968
1568.2	40.6503
1571.29	42.0162
1574.38	44.7074
1577.48	47.5188
1580.57	49.0078
1583.65	49.578
1586.74	52.7766
1589.83	54.0145
1592.92	57.2054
1596	58.0553
1599.08	57.884
1602.16	57.7117
1605.24	59.3133
1608.32	59.6931
1611.4	60.3695
1614.48	60.3331
1617.56	59.4876
1620.63	59.9521
1623.71	59.5694
1626.78	60.1516
1629.85	59.6816
1632.92	59.438
1635.99	59.6756
1639.06	59.683
1642.12	59.9876
1645.19	58.9702
1648.25	60.096
1651.32	60.2895
1654.38	57.9323
1657.44	56.1948
1660.5	53.6648
1663.56	51.8171
1666.62	49.4661
1669.67	45.1818
1672.73	40.864
1675.79	37.5502
1678.84	34.0503
1681.89	30.4278
1684.94	26.1864
1687.99	22.7346
1691.04	19.2202
1694.08	18.0626
1697.13	16.7414
1700.18	14.1427
1703.22	13.0928
1706.26	11.6024
1709.3	10.9958
1712.35	8.92878
1715.39	7.66826
1718.42	6.57144
1721.46	5.77214
1724.5	4.97241
1727.53	2.9617
1730.56	2.33576
1733.6	1.51886
1736.63	1.16448
1739.66	0.933835
1742.69	0.812236
1745.71	0.262914
1748.74	0.237338
1751.77	0.324376
1754.79	-1.16086
1757.81	-0.711364
1760.84	-0.929685
1763.86	-0.95115
1766.88	0.326112
1769.9	0.243426
1772.91	0.670684
1775.93	0.976051
1778.95	1.538
1781.96	2.61124
1784.97	4.16136
1787.99	5.0016
1791	4.71502
1794.01	4.9758
1797.01	5.41984
1800.02	6.69398
1803.03	6.38644
1806.03	5.78517
1809.04	4.84912
1812.04	5.84266
1815.04	6.06292
1818.04	6.48268
1821.04	6.29929
1824.04	7.12202
1827.04	6.81161
1830.03	5.96671
1833.03	6.20852
1836.02	6.87323
1839.02	7.28653
1842.01	7.32066
1845	8.07194
1847.99	8.01317
1850.98	8.65862
1853.96	9.08031
1856.95	9.82298
1859.94	9.63712
1862.92	8.18841
1865.9	8.03179
1868.88	7.41126
1871.86	8.10383
1874.84	7.54723
1877.82	6.55636
1880.8	5.19836
1882.58	5.57775
1885.57	6.14092
1888.56	6.5459
1891.54	6.91159
1894.53	7.63736
1897.51	7.65334
1900.5	6.73355
1903.48	6.54202
1906.46	7.02041
1909.44	6.70805
1912.42	6.53506
1915.4	6.29889
1918.37	6.47461
1921.35	6.35846
1924.32	5.25803
1927.3	4.52958
1930.27	4.18653
1933.24	3.19909
1936.21	2.17221
1939.18	2.19462
1942.15	2.52747
1945.11	3.03483
1948.08	3.00916
1951.04	3.33
1954.01	3.88637
1956.97	5.34037
1959.93	5.41001
1962.89	6.31761
1965.85	7.2591
1968.81	7.23636
1971.77	6.857
1974.72	6.86145
1977.68	7.22489
1980.63	7.41759
1983.58	8.18661
1986.53	7.03768
1989.48	6.48736
1992.43	6.8527
1995.38	5.93142
1998.33	5.63137
2001.27	5.96389
2004.22	5.68858
2007.16	6.02403
2010.11	6.40424
2013.05	6.41783
2015.99	6.8954
2018.93	7.20972
2021.87	7.2274
2024.8	7.1902
2027.74	8.48966
2030.68	8.87281
2033.61	8.04716
2036.54	8.33672
2039.48	9.53271
2042.41	9.83438
2045.34	9.85609
2048.27	10.4583
2051.19	10.7922
2054.12	11.9141
2057.05	12.0735
2059.97	12.1923
2062.9	12.8258
2065.82	13.1322
2068.74	13.5234
2071.66	13.032
2074.58	12.5864
2077.5	13.2872
2080.41	14.219
2083.33	12.6697
2086.24	12.7159
2089.16	13.6144
2092.07	14.0454
2094.98	13.6451
2097.89	14.347
2100.8	14.7763
2103.71	14.5238
2106.62	15.0296
2109.53	16.4974
2112.43	18.3397
2115.33	19.493
2118.24	21.4737
2121.14	23.769
2124.04	26.1669
2126.94	28.5623
2129.84	29.9998
2132.74	30.9213
2135.63	31.8956
2138.53	33.2815
2141.43	34.8986
2144.32	36.6339
2147.21	38.0542
2150.1	40.7956
2152.99	43.1998
2155.88	45.995
2158.77	47.5676
2161.66	49.248
2164.55	49.8681
2167.43	51.3239
2170.31	51.9749
2173.2	51.6423
2176.08	52.9586
2178.96	52.7471
2181.84	52.036
2184.72	51.1315
2187.6	50.6316
2190.47	48.4862
2193.35	46.1154
2196.23	44.5159
2199.1	42.7081
2201.97	39.7955
2204.84	36.2829
2207.71	34.7717
2210.58	32.5334
2213.45	30.6555
2216.32	28.0377
2219.19	27.1589
2222.05	27.202
2224.92	26.5152
2227.78	25.363
2230.64	24.1901
2233.5	23.3116
2236.36	23.415
2239.22	23.6962
2242.08	23.3827
2244.94	23.1828
2247.79	22.7097
2250.65	22.3778
2253.5	22.6146
2256.36	21.168
2259.21	20.0276
2262.06	19.6656
2264.91	20.2642
2267.76	20.3782
2270.6	19.2092
2273.45	17.3859
2276.3	17.1114
2279.14	16.7679
2281.98	15.7756
2284.83	14.7999
2287.67	15.0866
2290.51	14.8881
2293.35	13.1946
2296.19	12.3
2299.02	13.2203
2301.86	12.1923
2304.7	13.1482
2307.53	13.8983
2310.36	14.4971
2313.2	13.7567
2316.03	14.8702
2318.86	14.7269
2321.69	14.7505
2324.51	14.0322
2327.34	13.9519
2330.17	14.3278
2332.99	14.6817
2335.82	13.322
2338.64	12.7579
2341.46	10.9545
2344.28	10.111
2347.1	8.31912
2349.92	7.27074
2352.74	5.76513
2355.56	5.4799
2358.37	4.66416
2361.19	3.99073
2364	4.15169
2366.82	4.69514
2369.63	3.8293
2372.44	3.31306
2375.25	2.99083
2378.06	3.30576
2380.86	3.31479
2383.67	4.04158
2386.48	4.19567
2389.28	4.63983
2392.09	4.74267
2394.89	4.866
2397.69	4.95202
2400.49	5.95846
2403.29	6.83489
2406.09	6.21191
2408.89	5.66775
2411.69	5.57644
2414.48	6.45515
2417.28	7.23766
2420.07	8.53828
2422.86	9.14949
2425.65	9.98901
2428.45	10.1995
2431.23	10.1843
2434.02	9.48181
2436.81	8.44555
2439.6	8.9013
2442.38	8.72812
2445.17	8.8337
2447.95	8.68852
2450.73	8.6766
2453.52	9.34391
2456.3	8.66173
2459.08	8.69606
2461.85	8.09137
2464.63	8.64699
2467.41	9.18456
2470.19	8.53783
2472.96	8.07754
2475.73	7.33368
2478.51	6.21414
2481.28	6.1333
2484.05	5.9935
2486.82	5.95687
2489.59	5.5404
2492.35	4.68559
2495.12	4.94811
2497.89	4.12362
2500.65	3.5725
2503.42	2.77301
2506.18	2.93446
2508.94	2.79496
2511.7	2.19813
2514.46	2.99309
2517.22	2.47509
2519.98	2.69313
2522.73	3.50014
2525.49	3.6016
2528.25	3.88497
2531	4.69645
2533.75	5.04365
2536.5	5.27624
2539.25	5.4992
2542.01	5.02273
2544.75	5.62495
2547.5	6.01126
2550.25	7.30028
2553	7.26497
2555.74	7.88856
2558.49	8.206
2561.23	8.78994
2563.97	7.60311
2566.71	6.77095
2569.45	7.15279
2572.19	8.23974
2574.93	7.85018
2577.67	7.92151
2580.4	7.40344
2583.14	6.16485
2585.87	6.13018
2588.6	6.05872
2591.34	5.68046
2594.07	5.47182
2596.8	5.35006
2599.53	5.54859
2602.26	5.87974
2604.98	6.17669
2607.71	4.94305
2610.44	4.187
2613.16	4.63229
2615.88	4.92041
2618.61	4.85464
2621.33	4.47182
2624.05	5.03956
2626.77	4.29061
2629.49	3.66766
2632.21	3.11838
2634.92	3.95652
2637.64	5.31528
2640.35	4.51561
2643.07	4.38291
2645.78	4.3988
2648.49	3.8548
2651.2	3.32527
2653.91	3.65632
2656.62	2.54036
2659.33	3.93812
2662.04	4.20076
2664.74	3.66291
2667.45	5.06576
2670.15	5.60954
2672.86	5.96382
2675.56	5.53269
2678.26	5.80794
2680.96	6.08884
2683.66	5.75419
2686.36	5.81743
2689.06	6.42783
2691.75	6.19658
2694.45	5.50323
2697.14	5.37262
2699.84	5.55879
2702.53	5.84188
2705.22	6.36211
2707.91	6.59423
2710.6	8.11938
2713.29	8.25737
2715.98	8.28878
2718.67	8.53112
2721.35	9.03946
2724.04	8.58076
2726.72	8.27619
2729.4	7.98154
2732.09	8.58832
2734.77	9.71277
2737.45	8.70662
2740.13	7.9567
2742.81	6.80133
2745.48	6.38151
2748.16	4.74803
2750.84	3.12118
2753.51	2.39234
2756.19	1.86627
2758.86	1.05652
2761.53	0.285008
2764.2	0.115275
2766.87	0.334321
2769.54	0.889368
2772.21	0.675011
2774.88	1.43917
2777.54	1.46512
2780.21	0.253166
2782.87	1.08858
2785.53	0.560488
2788.2	0.153845
2790.86	0.174821
2793.52	0.754239
2796.18	0.597094
2798.84	0.796365
2801.49	0.91863
2804.15	0.52274
2806.81	0.234841
2809.46	-0.498155
2812.12	-2.20864
2814.77	-2.20714
2817.42	-1.6383
2820.07	1.28119
2822.72	4.60765
2825.37	7.64374
2828.02	11.5731
2830.67	16.7553
2833.31	22.0028
2835.96	28.6017
2838.61	35.2897
2841.25	41.8
2843.89	50.2196
2846.53	60.1269
2849.17	68.9074
2851.81	78.2804
2854.45	88.6668
2857.09	98.8864
2859.73	108.056
2862.36	116.745
2865	126.656
2867.64	135.747
2870.27	142.512
2872.9	149.243
2875.53	153.939
2878.16	159.636
2880.79	164.518
2883.42	169.464
2886.05	174.735
2888.68	178.731
2891.3	183.12
2893.93	187.979
2896.55	193.714
2899.18	199.734
2901.8	206.845
2904.42	215.174
2907.04	224.361
2909.66	233.923
2912.28	244.24
2914.9	254.766
2917.51	264.854
2920.13	273.257
2922.74	280.386
2925.36	285.513
2927.97	289.334
2930.59	291.623
2933.2	290.157
2935.81	286.917
2938.42	281.978
2941.02	273.738
2943.63	263.517
2946.24	253.301
2948.85	241.517
2951.45	229.64
2954.05	217.042
2956.66	205.355
2959.26	194.498
2961.86	183.528
2964.46	173.964
2967.06	165.27
2969.66	156.094
2972.26	148.506
2974.85	141.982
2977.45	135.42
2980.05	128.702
2982.64	120.275
2985.23	113.416
2987.83	106.211
2990.42	97.3215
2993.01	89.391
2995.6	81.0505
2998.19	73.4745
3000.77	64.3873
3003.36	55.5903
3005.95	47.2431
3008.53	40.3272
3011.12	33.6986
3013.7	27.669
3016.28	22.8392
3018.86	18.5301
3021.44	14.3503
3024.02	11.5301
3026.6	8.99121
3029.18	8.30447
3031.76	6.70191
3034.33	6.44103
3036.91	5.93218
3039.48	6.22254
3042.05	5.6656
3044.63	7.12394
3047.2	7.19299
3049.77	8.0048
3052.34	7.56873
3054.91	8.02933
3057.48	7.92686
3060.04	7.07353
3062.61	6.4614
3065.17	5.29849
3067.74	4.68471
3070.3	4.72124
3072.87	3.79758
3075.43	4.12458
3077.99	3.8098
3080.55	3.05697
3083.11	1.77315
3085.67	1.09897
3088.22	1.15039
3090.78	1.03343
3093.34	0.711295
3095.89	0.284921
3098.44	0.955098
3101	0.812671
3103.55	1.0991
3106.1	0.815393
3108.65	1.31645
3111.2	1.37813
3113.75	1.52151
3116.3	2.36245
3118.84	3.15167
3121.39	3.66204
3123.93	3.68416
3126.48	4.22758
3129.02	4.4341
3131.56	5.83031
3134.1	6.68291
3136.64	7.39673
3139.18	8.60263
3141.72	8.46936
3144.26	8.45137
3146.8	9.20679
3149.33	7.85562