File: data/Raman/poly_smoothed/Mbcal_20_25_08_1x_45s_532 nm_x100_100%_600 gr_mm_01.txt
#Acq. time (s)=	45
#Accumulations=	2
#Range (cm-¹)=	200...3150
#Windows=	2
#Auto scanning=	Off
#Autofocus=	Off
#Macrospot=	Off
#AutoExposure=	Off
#Spike filter=	Multiple accum.
#Delay time (s)=	0
#Binning=	1
#Readout mode=	Signal
#DeNoise=	Off
#ICS correction=	On
#Dark correction=	Off
#Inst. Process=	Off
#Detector Gain=	Best Dynamic Range
#Detector ADC=	20 kHz
#Detector temperature (°C)=	-69.85
#Instrument=	LabRAM HR Evol
#Detector=	Synapse
#Objective=	x100
#Grating=	600 gr/mm
#ND Filter=	100%
#Laser (nm)=	532
#Hole=	100.021
#Range=	Auto
#Laser Pol.=	No
#Raman. Pol.=	No
#Laser Pol. (°)=	-0.0007625
#Raman Pol. (°)=	89.9995
#Collection=	Microscope
#StageXY=	Marzhauser
#StageZ=	Marzhauser
#X (µm)=	-1207.1
#Y (µm)=	1250.2
#Z (µm)=	578.3
#Full time(mm:ss)=	3:19
#Project=
#Sample=
#Site=
#Title=	Mbcal_20_25_08_2x_45s_532 nm_x100_100%_600 gr_mm
#Remark=
#Date=	18.07.2022 10:01
#Acquired=	18.07.2022 10:01:07
#Edit:Spike=	18.07.2022 10:04:06
#Edit:Spike=	18.07.2022 10:04:08
#Base:Fit=	10.08.2022 10:55:08
#Base:Sub=	10.08.2022 10:55:14
#Filter:Polynom=	16.08.2022 10:07:28
#AxisType[0]=Intens
#AxisUnit[0]=Cnt
#AxisType[1]=Spectr
#AxisUnit[1]=1/cm
200.419	37.1922
204.048	29.8697
207.678	21.8535
211.304	16.8911
214.928	15.3883
218.554	13.3385
222.176	13.0051
225.798	13.3869
229.417	14.7419
233.035	14.1064
236.653	13.9102
240.268	12.7818
243.881	12.5955
247.493	13.5477
251.103	14.7938
254.715	17.1387
258.322	17.39
261.929	16.8464
265.534	17.6373
269.137	18.1416
272.739	19.5569
276.34	17.6901
279.939	14.7794
283.537	12.3235
287.134	10.8343
290.729	9.19122
294.323	8.5544
297.913	10.1477
301.504	10.6485
305.093	10.7723
308.682	11.9672
312.268	12.0283
315.852	13.4852
319.436	13.4616
323.018	14.7016
326.597	14.5704
330.177	14.4585
333.753	16.1091
337.331	15.4882
340.906	16.5224
344.478	16.712
348.051	16.9656
351.621	15.8787
355.189	15.0252
358.757	13.2151
362.323	10.567
365.889	8.79838
369.451	6.72747
373.012	3.49119
376.574	4.96601
380.133	5.93196
383.69	5.88823
387.245	7.87333
390.8	8.89535
394.353	10.8827
397.906	12.1352
401.456	12.3916
405.005	14.3463
408.552	16.7515
412.099	16.8155
415.643	17.6034
419.187	18.9191
422.728	17.4636
426.269	17.2665
429.806	18.0357
433.344	16.4282
436.881	13.1265
440.416	12.8263
443.949	10.996
447.48	8.97811
451.011	8.51104
454.541	6.60851
458.069	4.70312
461.594	3.85464
465.119	4.35795
468.642	5.56984
472.165	6.2285
475.684	6.79701
479.204	6.66129
482.721	9.31574
486.239	9.07077
489.753	10.8552
493.268	12.4147
496.779	14.2609
500.289	16.4005
503.8	19.2663
507.307	20.5533
510.813	22.672
514.32	25.5175
517.823	27.0739
521.325	28.0922
524.826	31.6545
528.325	32.1885
531.823	33.5379
535.32	31.5677
538.815	30.6023
542.309	28.1795
545.802	27.1056
549.293	26.2174
552.783	25.0179
556.271	22.5615
559.759	21.3687
563.245	18.2254
566.729	16.8987
570.213	16.2215
573.693	13.0097
577.173	10.098
580.652	9.26426
584.13	7.7534
587.605	7.27414
591.08	6.32532
594.552	5.61155
598.025	4.98156
601.496	4.77695
604.964	4.49526
608.433	5.0636
611.898	4.35515
615.364	2.48398
618.827	0.336774
622.288	-0.638984
625.75	0.252664
629.209	1.14423
632.667	2.01909
636.125	2.69106
639.58	4.17997
643.033	5.45229
646.485	6.25761
649.936	7.57146
653.388	7.94685
656.836	7.97748
660.283	9.92341
663.728	10.8139
667.173	10.4519
670.616	12.5007
674.057	14.6038
677.498	14.4833
680.937	16.4284
684.375	16.9668
687.809	18.1392
691.244	17.5426
694.678	17.5116
698.111	14.4164
701.54	14.9226
704.97	17.0383
708.398	18.8646
711.826	19.9116
715.25	19.2074
718.675	18.8646
722.096	20.4411
725.518	20.5328
728.937	20.4126
732.357	19.771
735.773	19.4466
739.19	21.4294
742.604	23.3232
746.018	24.1551
749.429	27.7965
752.839	31.5564
756.248	35.6079
759.657	37.9055
763.063	40.6809
766.468	43.9391
769.871	45.2617
773.273	47.888
776.676	51.5286
780.075	50.3719
783.474	52.4
786.871	54.7717
790.266	54.5976
793.661	56.135
797.054	56.711
800.446	56.9328
803.834	57.0298
807.224	56.3587
810.612	53.6035
813.998	52.5584
817.384	48.6207
820.766	47.7648
824.149	50.4804
827.531	53.6535
830.909	59.0599
834.288	62.2052
837.666	66.52
841.041	70.0659
844.416	72.5743
847.788	75.9113
851.161	78.466
854.53	80.1975
857.901	79.236
861.268	75.7654
864.633	71.0193
868	69.018
871.363	65.2183
874.725	62.4994
878.088	56.6222
881.447	50.8022
884.805	43.1946
888.162	36.8453
891.518	31.1939
894.872	25.3116
898.225	20.9132
901.577	19.2455
904.928	20.1473
908.277	20.3625
911.625	22.4525
914.972	25.2144
918.318	27.4097
921.662	29.3566
925.005	28.7377
928.347	29.234
931.686	30.4737
935.025	28.437
938.363	26.1907
941.698	26.0361
945.034	24.7798
948.368	26.1885
951.699	25.5429
955.031	23.9106
958.36	22.7365
961.689	19.348
965.016	19.2975
968.343	19.7914
971.666	22.5604
974.991	24.4567
978.312	24.2133
981.632	23.1613
984.953	22.599
988.27	22.0853
991.587	22.408
994.902	23.8376
998.216	24.0809
1001.53	21.8611
1004.84	18.3032
1008.15	16.1818
1011.46	16.457
1014.77	18.2657
1018.07	18.9512
1021.38	21.4367
1024.68	24.3918
1027.99	24.6311
1031.29	26.4741
1034.59	27.0518
1037.89	27.2475
1041.18	26.6875
1044.48	29.7602
1047.77	31.7031
1051.07	33.6644
1054.36	34.9897
1057.65	32.7909
1060.94	31.2876
1064.23	29.8763
1067.52	28.3876
1070.8	29.1123
1074.09	28.3978
1077.37	26.1462
1080.65	23.7275
1083.93	21.3476
1087.21	19.7066
1090.49	21.3721
1093.77	21.5045
1097.04	21.7991
1100.32	20.866
1103.59	22.8061
1106.86	22.0363
1110.13	19.9763
1113.4	21.4571
1116.67	20.3186
1119.94	19.8244
1123.2	18.6927
1126.47	19.1969
1129.73	18.3064
1132.99	16.7763
1136.25	14.4402
1139.51	13.2242
1142.77	11.4828
1146.03	11.0752
1149.28	9.23418
1152.54	7.98164
1155.79	6.69478
1159.04	5.90085
1162.29	2.73707
1165.54	1.731
1168.79	1.25644
1172.04	1.46527
1175.28	1.51675
1178.53	2.46492
1181.77	5.39866
1185.01	7.47446
1188.25	6.9734
1191.49	7.1611
1194.73	8.52911
1197.96	10.8514
1201.2	10.4426
1204.43	14.5617
1207.66	17.648
1210.9	18.1742
1214.13	21.5126
1217.36	26.2702
1220.58	29.1407
1223.81	31.2085
1227.04	33.7129
1230.26	36.0285
1233.48	40.061
1236.71	44.1989
1239.93	49.2655
1243.14	53.015
1246.36	57.1164
1249.58	60.8935
1252.8	64.6934
1256.01	67.9041
1259.22	70.5332
1262.43	74.424
1265.64	74.4952
1268.85	73.9417
1272.06	75.642
1275.27	77.4655
1278.48	80.6967
1281.68	82.3027
1284.88	84.5858
1288.08	86.9534
1291.28	90.7188
1294.48	92.0409
1297.68	92.881
1300.88	94.8752
1304.07	97.7253
1307.27	101.903
1310.46	105.335
1313.65	109.225
1316.85	113.168
1320.03	116.268
1323.22	117.658
1326.41	119.061
1329.6	119.124
1332.78	119.505
1335.96	117.274
1339.15	116.59
1342.33	114.931
1345.51	111.445
1348.69	109.805
1351.86	107.013
1355.04	104.614
1358.21	102.879
1361.39	100.852
1364.56	97.3325
1367.73	93.5054
1370.9	90.4304
1374.07	87.1244
1377.24	83.1212
1380.41	82.6466
1383.57	79.7113
1386.73	77.8817
1389.9	73.902
1393.06	74.2277
1396.22	73.5642
1399.38	73.2805
1402.54	74.8739
1405.69	78.5853
1408.85	81.2784
1412	87.3239
1415.16	92.5193
1418.31	99.2998
1421.46	106.502
1424.61	112.807
1427.76	123.028
1430.9	132.477
1434.05	140.385
1437.2	148.499
1440.34	153.799
1443.48	157.133
1446.62	159.594
1449.76	161.925
1452.9	160.603
1456.04	159.127
1459.17	156.846
1462.31	152.469
1465.44	148.975
1468.58	143.92
1471.71	141.313
1474.84	134.373
1477.97	128.862
1481.1	123.197
1484.22	118.006
1487.35	110.964
1490.47	103.037
1493.59	94.529
1496.72	88.4554
1499.84	81.4576
1502.96	75.9338
1506.08	70.0987
1509.19	64.2846
1512.31	58.36
1515.42	49.9899
1518.54	44.9329
1521.65	41.9904
1524.76	41.2295
1527.87	42.0305
1530.98	41.9146
1534.09	43.3139
1537.2	46.4273
1540.3	47.5217
1543.41	52.3192
1546.51	57.5074
1549.61	60.7731
1552.71	63.8992
1555.81	67.1672
1558.91	68.426
1562.01	70.6238
1565.1	69.9727
1568.2	71.4486
1571.29	73.9224
1574.38	75.2274
1577.48	77.9689
1580.57	79.1406
1583.65	79.6544
1586.74	80.7735
1589.83	80.0208
1592.92	79.8434
1596	82.9298
1599.08	83.1789
1602.16	82.6295
1605.24	82.6842
1608.32	80.6264
1611.4	81.0769
1614.48	80.5
1617.56	79.3489
1620.63	81.1957
1623.71	81.4344
1626.78	81.3641
1629.85	81.5623
1632.92	82.9934
1635.99	82.2069
1639.06	82.8837
1642.12	84.5072
1645.19	87.1877
1648.25	87.6049
1651.32	89.3918
1654.38	90.5347
1657.44	90.4875
1660.5	89.2931
1663.56	87.4595
1666.62	83.2917
1669.67	77.6267
1672.73	72.0455
1675.79	67.6144
1678.84	61.4034
1681.89	56.5768
1684.94	50.9783
1687.99	44.89
1691.04	39.6372
1694.08	34.2741
1697.13	30.825
1700.18	25.5226
1703.22	20.5132
1706.26	17.1819
1709.3	13.648
1712.35	9.66856
1715.39	8.59305
1718.42	6.61672
1721.46	5.4054
1724.5	3.99804
1727.53	4.0467
1730.56	4.04099
1733.6	4.00103
1736.63	3.12293
1739.66	3.46034
1742.69	1.93961
1745.71	1.92028
1748.74	2.89412
1751.77	1.66081
1754.79	1.78539
1757.81	2.22427
1760.84	1.83728
1763.86	2.43789
1766.88	2.25793
1769.9	1.86639
1772.91	1.279
1775.93	0.34853
1778.95	1.52618
1781.96	2.57959
1784.97	2.21962
1787.99	0.851889
1791	1.32941
1794.01	1.39061
1797.01	1.71501
1800.02	2.59062
1803.03	2.53124
1806.03	3.52661
1809.04	3.52449
1812.04	3.95391
1815.04	4.55312
1818.04	4.30226
1821.04	4.27626
1824.04	4.52527
1827.04	3.99867
1830.03	4.40214
1833.03	4.40346
1836.02	4.55138
1839.02	5.19334
1842.01	5.67763
1845	6.91969
1847.99	7.42507
1850.98	7.81023
1853.96	7.92577
1856.95	6.0726
1859.94	5.41027
1862.92	3.50408
1865.9	4.95338
1868.88	4.86019
1871.86	5.27754
1874.84	4.21725
1877.82	3.52067
1880.8	4.84189
1882.58	4.64315
1885.57	5.12748
1888.56	6.13261
1891.54	6.0605
1894.53	5.62929
1897.51	6.15322
1900.5	5.88282
1903.48	6.1316
1906.46	5.01108
1909.44	6.00545
1912.42	7.35585
1915.4	7.81889
1918.37	8.16198
1921.35	7.18689
1924.32	7.27788
1927.3	5.39113
1930.27	4.9956
1933.24	4.83099
1936.21	3.79588
1939.18	5.00255
1942.15	4.27184
1945.11	3.95529
1948.08	4.21065
1951.04	5.613
1954.01	6.30831
1956.97	6.16547
1959.93	6.09666
1962.89	6.80688
1965.85	6.30494
1968.81	7.04934
1971.77	7.66143
1974.72	6.93472
1977.68	7.75296
1980.63	7.86698
1983.58	8.85924
1986.53	8.07029
1989.48	7.6446
1992.43	6.12822
1995.38	7.11989
1998.33	6.59091
2001.27	5.53734
2004.22	4.83589
2007.16	3.93786
2010.11	3.54139
2013.05	2.89595
2015.99	3.48383
2018.93	3.26275
2021.87	4.11377
2024.8	3.79042
2027.74	4.51843
2030.68	5.16255
2033.61	6.75262
2036.54	9.08139
2039.48	10.7411
2042.41	11.8384
2045.34	12.3467
2048.27	12.8644
2051.19	13.942
2054.12	14.5011
2057.05	14.0728
2059.97	13.0245
2062.9	14.3865
2065.82	16.1994
2068.74	16.6945
2071.66	15.4726
2074.58	16.1818
2077.5	15.5188
2080.41	15.7973
2083.33	15.6681
2086.24	16.7051
2089.16	17.4836
2092.07	17.8568
2094.98	19.2607
2097.89	20.6426
2100.8	22.1028
2103.71	24.4081
2106.62	26.2117
2109.53	27.025
2112.43	27.1889
2115.33	28.3506
2118.24	29.2581
2121.14	30.963
2124.04	32.6721
2126.94	34.8064
2129.84	37.3594
2132.74	40.507
2135.63	43.684
2138.53	45.1223
2141.43	47.8392
2144.32	50.4646
2147.21	54.0399
2150.1	55.4052
2152.99	58.603
2155.88	60.2617
2158.77	62.5706
2161.66	64.8995
2164.55	65.8529
2167.43	67.9265
2170.31	68.7592
2173.2	68.7191
2176.08	69.0825
2178.96	67.9797
2181.84	66.9281
2184.72	63.1933
2187.6	62.0961
2190.47	60.8448
2193.35	59.1015
2196.23	56.9328
2199.1	54.8317
2201.97	52.4133
2204.84	49.5321
2207.71	48.3094
2210.58	46.8631
2213.45	45.744
2216.32	44.3994
2219.19	42.6668
2222.05	40.0825
2224.92	39.8423
2227.78	38.147
2230.64	37.7418
2233.5	34.8236
2236.36	33.6446
2239.22	32.1725
2242.08	29.7617
2244.94	28.3978
2247.79	26.3359
2250.65	24.2728
2253.5	21.7244
2256.36	19.2283
2259.21	18.666
2262.06	18.1036
2264.91	15.8728
2267.76	16.0687
2270.6	15.4653
2273.45	13.9951
2276.3	14.217
2279.14	13.3666
2281.98	13.334
2284.83	12.523
2287.67	12.6164
2290.51	10.9599
2293.35	10.3274
2296.19	10.7662
2299.02	9.2994
2301.86	9.49905
2304.7	9.26039
2307.53	9.93966
2310.36	10.298
2313.2	10.5495
2316.03	10.5318
2318.86	9.93296
2321.69	10.2394
2324.51	10.1453
2327.34	10.8791
2330.17	10.5051
2332.99	9.78261
2335.82	9.58518
2338.64	8.97342
2341.46	7.42568
2344.28	6.71032
2347.1	3.97633
2349.92	2.28888
2352.74	1.18795
2355.56	0.67704
2358.37	-1.28229
2361.19	-2.13234
2364	-1.7874
2366.82	-0.443044
2369.63	-0.670637
2372.44	-0.132986
2375.25	1.74802
2378.06	2.85662
2380.86	3.16331
2383.67	3.75361
2386.48	4.5795
2389.28	4.99554
2392.09	5.98629
2394.89	6.05795
2397.69	6.54031
2400.49	6.64735
2403.29	8.21652
2406.09	7.97922
2408.89	7.57698
2411.69	6.67923
2414.48	5.87763
2417.28	4.78405
2420.07	4.01882
2422.86	4.48414
2425.65	4.63255
2428.45	4.10566
2431.23	3.71391
2434.02	4.28429
2436.81	3.8183
2439.6	5.67962
2442.38	6.41019
2445.17	8.16045
2447.95	7.86191
2450.73	7.90648
2453.52	9.05939
2456.3	8.27795
2459.08	9.0252
2461.85	10.0875
2464.63	9.82518
2467.41	9.28652
2470.19	9.46168
2472.96	8.42515
2475.73	7.12865
2478.51	6.55954
2481.28	5.55131
2484.05	4.43042
2486.82	3.52625
2489.59	2.27794
2492.35	2.56468
2495.12	1.55392
2497.89	0.224445
2500.65	0.163396
2503.42	1.23528
2506.18	2.3682
2508.94	2.53322
2511.7	2.95311
2514.46	2.45246
2517.22	2.41697
2519.98	2.06041
2522.73	1.22301
2525.49	3.37112
2528.25	4.13835
2531	4.46289
2533.75	5.32398
2536.5	5.78485
2539.25	7.02696
2542.01	7.41669
2544.75	8.25951
2547.5	8.70599
2550.25	8.08896
2553	7.66552
2555.74	8.6573
2558.49	9.07634
2561.23	8.46626
2563.97	7.91299
2566.71	8.428
2569.45	8.66421
2572.19	9.22455
2574.93	8.39135
2577.67	7.2529
2580.4	7.18241
2583.14	7.63592
2585.87	7.16174
2588.6	7.59599
2591.34	8.23635
2594.07	9.21601
2596.8	9.53291
2599.53	8.74764
2602.26	8.59662
2604.98	9.14017
2607.71	9.40345
2610.44	9.46216
2613.16	8.6796
2615.88	7.25562
2618.61	6.47933
2621.33	7.40192
2624.05	8.08649
2626.77	6.78841
2629.49	6.61675
2632.21	7.57752
2634.92	6.9399
2637.64	6.59757
2640.35	8.13302
2643.07	8.46806
2645.78	9.44629
2648.49	10.0701
2651.2	11.4822
2653.91	10.1256
2656.62	10.8066
2659.33	11.04
2662.04	10.9009
2664.74	9.84651
2667.45	10.1396
2670.15	10.6467
2672.86	10.0097
2675.56	9.37349
2678.26	8.37424
2680.96	8.11843
2683.66	7.79591
2686.36	7.80738
2689.06	7.34644
2691.75	6.66912
2694.45	7.04258
2697.14	7.93283
2699.84	9.25602
2702.53	10.1373
2705.22	11.6178
2707.91	12.3554
2710.6	14.1616
2713.29	16.2439
2715.98	17.0111
2718.67	17.4622
2721.35	18.3218
2724.04	19.2715
2726.72	19.943
2729.4	19.8106
2732.09	19.2294
2734.77	18.0721
2737.45	16.9897
2740.13	14.9498
2742.81	13.5647
2745.48	12.1367
2748.16	10.8191
2750.84	9.25621
2753.51	7.91911
2756.19	6.8419
2758.86	5.43725
2761.53	3.97924
2764.2	3.63026
2766.87	3.86653
2769.54	2.75214
2772.21	3.84154
2774.88	5.2249
2777.54	5.54972
2780.21	6.33305
2782.87	5.4512
2785.53	5.61532
2788.2	6.25326
2790.86	5.41618
2793.52	4.38684
2796.18	3.90194
2798.84	2.44731
2801.49	1.60013
2804.15	0.537791
2806.81	0.336939
2809.46	-0.0370013
2812.12	-0.765675
2814.77	-1.0135
2817.42	-0.641671
2820.07	2.16049
2822.72	7.29463
2825.37	11.1816
2828.02	16.9913
2830.67	23.6595
2833.31	30.4116
2835.96	37.5345
2838.61	46.5024
2841.25	55.5639
2843.89	66.1037
2846.53	75.5674
2849.17	85.996
2851.81	97.6133
2854.45	108.931
2857.09	119.678
2859.73	130.44
2862.36	139.77
2865	148.701
2867.64	157.672
2870.27	165.941
2872.9	172.69
2875.53	180.686
2878.16	187.243
2880.79	193.267
2883.42	201.157
2886.05	208.549
2888.68	214.934
2891.3	222.214
2893.93	230.576
2896.55	238.423
2899.18	249.943
2901.8	260.944
2904.42	273.439
2907.04	286.827
2909.66	300.843
2912.28	314.716
2914.9	329.121
2917.51	342.208
2920.13	353.565
2922.74	361.435
2925.36	367.226
2927.97	370.878
2930.59	371.435
2933.2	369.403
2935.81	363.141
2938.42	354.037
2941.02	343.57
2943.63	328.831
2946.24	315.063
2948.85	300.746
2951.45	285.59
2954.05	271.21
2956.66	256.937
2959.26	243.662
2961.86	229.915
2964.46	218.057
2967.06	207.585
2969.66	197.981
2972.26	190.239
2974.85	184.062
2977.45	176.278
2980.05	169.975
2982.64	161.209
2985.23	152.203
2987.83	140.824
2990.42	131.847
2993.01	121.48
2995.6	109.546
2998.19	99.0148
3000.77	87.6842
3003.36	76.3588
3005.95	67.1096
3008.53	56.6911
3011.12	49.6262
3013.7	42.0788
3016.28	35.3627
3018.86	28.9399
3021.44	22.4679
3024.02	17.7849
3026.6	13.16
3029.18	10.6212
3031.76	9.36181
3034.33	7.40982
3036.91	7.27403
3039.48	5.77449
3042.05	5.63227
3044.63	5.0086
3047.2	4.1824
3049.77	3.96648
3052.34	3.50508
3054.91	4.25819
3057.48	3.46929
3060.04	3.54482
3062.61	4.2106
3065.17	3.82475
3067.74	3.97863
3070.3	3.80335
3072.87	4.7099
3075.43	5.58625
3077.99	5.37604
3080.55	4.68979
3083.11	3.51352
3085.67	2.92294
3088.22	1.92369
3090.78	1.35102
3093.34	2.4145
3095.89	2.30905
3098.44	1.79972
3101	1.07189
3103.55	1.26954
3106.1	1.46692
3108.65	2.50656
3111.2	3.08765
3113.75	3.01985
3116.3	3.21983
3118.84	3.47472
3121.39	4.76207
3123.93	6.34943
3126.48	7.845
3129.02	8.95788
3131.56	10.5984
3134.1	13.2258
3136.64	14.3261
3139.18	16.1389
3141.72	17.2015
3144.26	19.2779
3146.8	21.9283
3149.33	25.1423