File: data/Raman/poly_smoothed/Mbcal_20_25_04_1x_45s_532 nm_x100_100%_600 gr_mm_01.txt
#Acq. time (s)=	45
#Accumulations=	2
#Range (cm-¹)=	200...3150
#Windows=	2
#Auto scanning=	Off
#Autofocus=	Off
#Macrospot=	Off
#AutoExposure=	Off
#Spike filter=	Multiple accum.
#Delay time (s)=	0
#Binning=	1
#Readout mode=	Signal
#DeNoise=	Off
#ICS correction=	On
#Dark correction=	Off
#Inst. Process=	Off
#Detector Gain=	Best Dynamic Range
#Detector ADC=	20 kHz
#Detector temperature (°C)=	-69.85
#Instrument=	LabRAM HR Evol
#Detector=	Synapse
#Objective=	x100
#Grating=	600 gr/mm
#ND Filter=	100%
#Laser (nm)=	532
#Hole=	100.021
#Range=	Auto
#Laser Pol.=	No
#Raman. Pol.=	No
#Laser Pol. (°)=	-0.0007625
#Raman Pol. (°)=	89.9995
#Collection=	Microscope
#StageXY=	Marzhauser
#StageZ=	Marzhauser
#X (µm)=	-1203.5
#Y (µm)=	1269.6
#Z (µm)=	577.75
#Full time(mm:ss)=	3:18
#Project=
#Sample=
#Site=
#Title=	Mbcal_20_25_04_2x_45s_532 nm_x100_100%_600 gr_mm
#Remark=
#Date=	18.07.2022 09:41
#Acquired=	18.07.2022 09:41:30
#Base:Fit=	10.08.2022 10:55:08
#Base:Sub=	10.08.2022 10:55:14
#Filter:Polynom=	16.08.2022 09:24:11
#Filter:Polynom=	16.08.2022 10:07:27
#AxisType[0]=Intens
#AxisUnit[0]=Cnt
#AxisType[1]=Spectr
#AxisUnit[1]=1/cm
200.419	-0.983504
204.048	4.28719
207.678	7.75173
211.304	8.89012
214.928	11.133
218.554	12.7214
222.176	11.0419
225.798	10.4126
229.417	8.58256
233.035	8.41173
236.653	8.3232
240.268	10.0952
243.881	11.0859
247.493	13.1979
251.103	14.6179
254.715	15.507
258.322	16.298
261.929	17.7943
265.534	17.1119
269.137	19.4216
272.739	18.4268
276.34	19.2156
279.939	19.1934
283.537	17.1886
287.134	14.5046
290.729	14.3901
294.323	14.901
297.913	14.0458
301.504	13.8337
305.093	12.65
308.682	10.1156
312.268	10.7978
315.852	9.8713
319.436	9.22123
323.018	9.27772
326.597	9.96536
330.177	10.7995
333.753	12.559
337.331	13.1329
340.906	13.8349
344.478	13.1128
348.051	13.4879
351.621	11.7718
355.189	11.4035
358.757	10.7288
362.323	6.5317
365.889	5.55386
369.451	3.63602
373.012	3.14345
376.574	3.67949
380.133	4.7374
383.69	4.79605
387.245	5.30598
390.8	6.39243
394.353	6.43627
397.906	7.4606
401.456	8.50513
405.005	7.33247
408.552	6.32312
412.099	6.49122
415.643	6.71246
419.187	8.412
422.728	7.73901
426.269	7.93207
429.806	6.54565
433.344	6.86396
436.881	6.73326
440.416	5.92775
443.949	4.79613
447.48	1.7576
451.011	0.519584
454.541	-0.0563723
458.069	2.87788
461.594	4.59693
465.119	3.89241
468.642	4.26506
472.165	5.57338
475.684	6.04591
479.204	7.3538
482.721	8.323
486.239	8.71686
489.753	11.3991
493.268	11.2465
496.779	12.7248
500.289	13.8207
503.8	14.0224
507.307	15.1712
510.813	16.7131
514.32	17.9798
517.823	18.3795
521.325	21.3067
524.826	21.7641
528.325	23.0084
531.823	22.822
535.32	22.3052
538.815	22.6512
542.309	24.163
545.802	23.4831
549.293	20.8305
552.783	19.6308
556.271	17.611
559.759	16.4472
563.245	14.5785
566.729	13.5471
570.213	14.0119
573.693	10.7173
577.173	9.68238
580.652	9.17576
584.13	6.78754
587.605	5.71531
591.08	5.38338
594.552	6.16446
598.025	6.63472
601.496	6.60498
604.964	6.89132
608.433	6.39788
611.898	4.72237
615.364	4.58418
618.827	3.52812
622.288	3.80964
625.75	4.89998
629.209	3.79625
632.667	2.66021
636.125	3.1099
639.58	3.58174
643.033	3.0901
646.485	3.39839
649.936	6.15098
653.388	8.46677
656.836	10.7776
660.283	11.4264
663.728	13.8961
667.173	14.1509
670.616	14.4203
674.057	16.9397
677.498	19.9709
680.937	23.2734
684.375	25.2703
687.809	26.1689
691.244	27.3284
694.678	27.2738
698.111	28.8224
701.54	29.4593
704.97	30.4852
708.398	29.2764
711.826	28.574
715.25	27.3222
718.675	28.2459
722.096	27.9373
725.518	30.4605
728.937	29.9497
732.357	31.6588
735.773	34.0702
739.19	35.3214
742.604	37.9246
746.018	38.495
749.429	40.3926
752.839	43.834
756.248	48.8028
759.657	52.5497
763.063	58.0654
766.468	61.779
769.871	63.7412
773.273	66.8902
776.676	69.7027
780.075	73.6195
783.474	75.7222
786.871	78.3795
790.266	80.4818
793.661	83.0386
797.054	86.1078
800.446	89.2765
803.834	90.5224
807.224	93.186
810.612	95.9025
813.998	96.6945
817.384	98.6604
820.766	96.6948
824.149	96.136
827.531	96.8485
830.909	97.6024
834.288	99.687
837.666	101.807
841.041	103.568
844.416	105.506
847.788	104.662
851.161	103.714
854.53	103.222
857.901	101.893
861.268	98.7659
864.633	96.6887
868	93.4404
871.363	90.8391
874.725	88.0733
878.088	86.4247
881.447	81.8306
884.805	77.3226
888.162	73.9717
891.518	69.904
894.872	66.131
898.225	59.7452
901.577	55.8181
904.928	54.3292
908.277	54.3654
911.625	55.8035
914.972	55.8863
918.318	56.8326
921.662	56.7727
925.005	59.2883
928.347	59.3781
931.686	58.2244
935.025	57.8634
938.363	57.4493
941.698	56.8607
945.034	56.094
948.368	53.6487
951.699	52.1104
955.031	49.6672
958.36	46.852
961.689	42.9552
965.016	39.089
968.343	36.2443
971.666	35.4059
974.991	33.0652
978.312	31.923
981.632	30.2828
984.953	28.4337
988.27	27.6383
991.587	25.7408
994.902	24.5571
998.216	23.7512
1001.53	22.2984
1004.84	22.5287
1008.15	23.0242
1011.46	23.8939
1014.77	24.6651
1018.07	26.2492
1021.38	27.7461
1024.68	29.2971
1027.99	30.0113
1031.29	30.4974
1034.59	31.5175
1037.89	32.8838
1041.18	32.4618
1044.48	32.511
1047.77	32.797
1051.07	32.3777
1054.36	31.5716
1057.65	31.7605
1060.94	31.6091
1064.23	29.8258
1067.52	26.9917
1070.8	25.0977
1074.09	24.3355
1077.37	23.0655
1080.65	22.0113
1083.93	20.0018
1087.21	18.9395
1090.49	17.6395
1093.77	16.243
1097.04	14.7722
1100.32	15.7826
1103.59	15.9813
1106.86	16.2745
1110.13	14.6379
1113.4	13.136
1116.67	12.9893
1119.94	13.635
1123.2	12.444
1126.47	9.56585
1129.73	9.26742
1132.99	8.83496
1136.25	9.24586
1139.51	8.25928
1142.77	7.39166
1146.03	6.7893
1149.28	4.77221
1152.54	8.00168
1155.79	7.1763
1159.04	4.977
1162.29	3.20703
1165.54	2.96187
1168.79	0.719303
1172.04	0.793678
1175.28	3.88474
1178.53	2.88412
1181.77	2.30624
1185.01	4.50267
1188.25	5.35024
1191.49	4.86237
1194.73	6.43142
1197.96	8.58356
1201.2	10.1305
1204.43	11.1123
1207.66	10.9186
1210.9	10.4551
1214.13	12.7999
1217.36	14.2809
1220.58	16
1223.81	18.9601
1227.04	18.6787
1230.26	19.2447
1233.48	22.2174
1236.71	21.4111
1239.93	23.5845
1243.14	25.3703
1246.36	26.2767
1249.58	26.4058
1252.8	27.5539
1256.01	27.6374
1259.22	28.3794
1262.43	30.7812
1265.64	31.6068
1268.85	34.1126
1272.06	37.5417
1275.27	40.2396
1278.48	41.8384
1281.68	43.4576
1284.88	45.4741
1288.08	46.5664
1291.28	48.9077
1294.48	52.7254
1297.68	53.8124
1300.88	56.3324
1304.07	56.9342
1307.27	57.4059
1310.46	57.4834
1313.65	57.6974
1316.85	55.4138
1320.03	53.5521
1323.22	51.8474
1326.41	52.0117
1329.6	51.7721
1332.78	51.8591
1335.96	51.4302
1339.15	51.4737
1342.33	49.3856
1345.51	49.8197
1348.69	49.005
1351.86	47.4258
1355.04	46.1053
1358.21	45.0838
1361.39	43.6615
1364.56	42.1675
1367.73	40.5315
1370.9	39.4849
1374.07	39.1174
1377.24	38.1549
1380.41	36.8061
1383.57	34.9629
1386.73	33.3998
1389.9	33.9092
1393.06	33.331
1396.22	33.3648
1399.38	35.9657
1402.54	41.7878
1405.69	44.6703
1408.85	49.0434
1412	52.276
1415.16	57.3109
1418.31	62.7321
1421.46	67.4062
1424.61	73.0578
1427.76	79.3817
1430.9	85.9957
1434.05	90.6839
1437.2	93.7232
1440.34	95.5709
1443.48	97.2877
1446.62	97.5608
1449.76	96.2582
1452.9	94.3499
1456.04	90.5881
1459.17	87.4436
1462.31	85.1701
1465.44	82.461
1468.58	77.1718
1471.71	70.7426
1474.84	64.2473
1477.97	59.6893
1481.1	55.0197
1484.22	50.699
1487.35	45.3069
1490.47	39.9944
1493.59	37.0988
1496.72	33.7322
1499.84	28.2004
1502.96	25.953
1506.08	23.7013
1509.19	19.5175
1512.31	15.3727
1515.42	12.8762
1518.54	9.94878
1521.65	8.23636
1524.76	6.99474
1527.87	5.06547
1530.98	5.66099
1534.09	8.10649
1537.2	10.2362
1540.3	11.0594
1543.41	11.8954
1546.51	13.6347
1549.61	16.733
1552.71	17.5764
1555.81	19.6051
1558.91	22.3273
1562.01	22.1382
1565.1	23.3218
1568.2	24.2803
1571.29	26.027
1574.38	26.898
1577.48	27.5117
1580.57	28.1842
1583.65	29.105
1586.74	28.4821
1589.83	29.507
1592.92	32.2475
1596	34.2871
1599.08	37.672
1602.16	39.3318
1605.24	39.9239
1608.32	40.8399
1611.4	41.6253
1614.48	41.326
1617.56	41.2379
1620.63	43.8313
1623.71	45.5231
1626.78	46.3921
1629.85	46.0254
1632.92	48.197
1635.99	49.9841
1639.06	51.3542
1642.12	50.8018
1645.19	52.1527
1648.25	53.2767
1651.32	53.0354
1654.38	53.6812
1657.44	53.5729
1660.5	53.1764
1663.56	52.9695
1666.62	52.4882
1669.67	51.9331
1672.73	48.2818
1675.79	44.1329
1678.84	40.7555
1681.89	35.8271
1684.94	31.5703
1687.99	28.6382
1691.04	24.1295
1694.08	21.1404
1697.13	16.4333
1700.18	13.7368
1703.22	12.3349
1706.26	11.4142
1709.3	9.62365
1712.35	7.06672
1715.39	6.3765
1718.42	5.46032
1721.46	5.914
1724.5	5.74395
1727.53	6.24062
1730.56	6.29765
1733.6	6.44222
1736.63	6.40539
1739.66	6.641
1742.69	5.84747
1745.71	5.41309
1748.74	5.55775
1751.77	6.5477
1754.79	7.4588
1757.81	6.40222
1760.84	6.66908
1763.86	6.06476
1766.88	7.14207
1769.9	5.75385
1772.91	7.18533
1775.93	9.5184
1778.95	9.65762
1781.96	8.88948
1784.97	9.32151
1787.99	8.99943
1791	9.3651
1794.01	9.94272
1797.01	10.6385
1800.02	11.1528
1803.03	11.3951
1806.03	11.0299
1809.04	11.4725
1812.04	12.4997
1815.04	14.0245
1818.04	14.797
1821.04	15.5856
1824.04	16.6782
1827.04	17.0402
1830.03	17.4628
1833.03	17.2005
1836.02	16.7589
1839.02	16.9997
1842.01	17.015
1845	15.926
1847.99	15.8211
1850.98	15.2277
1853.96	12.8934
1856.95	11.6539
1859.94	11.6357
1862.92	10.826
1865.9	10.9526
1868.88	9.89779
1871.86	9.24786
1874.84	8.86702
1877.82	8.17463
1880.8	8.90123
1882.58	8.74732
1885.57	10.0916
1888.56	10.986
1891.54	9.51591
1894.53	10.8331
1897.51	10.9397
1900.5	13.2655
1903.48	12.7167
1906.46	12.6565
1909.44	12.5587
1912.42	12.8955
1915.4	13.1421
1918.37	12.797
1921.35	12.7432
1924.32	14.2998
1927.3	16.1981
1930.27	17.5224
1933.24	17.6986
1936.21	16.83
1939.18	15.9138
1942.15	13.8696
1945.11	13.7782
1948.08	12.6513
1951.04	11.982
1954.01	13.169
1956.97	11.1385
1959.93	9.97402
1962.89	8.32736
1965.85	6.62619
1968.81	7.17913
1971.77	4.96304
1974.72	4.20621
1977.68	2.76984
1980.63	2.3061
1983.58	1.79877
1986.53	2.90261
1989.48	4.35696
1992.43	6.09186
1995.38	9.1427
1998.33	11.1353
2001.27	11.335
2004.22	9.60603
2007.16	10.3517
2010.11	11.4201
2013.05	11.0983
2015.99	12.0505
2018.93	11.9272
2021.87	13.5825
2024.8	14.4801
2027.74	13.6788
2030.68	13.5969
2033.61	13.3473
2036.54	12.8441
2039.48	13.7773
2042.41	14.2764
2045.34	13.8775
2048.27	14.389
2051.19	13.1025
2054.12	13.018
2057.05	13.8534
2059.97	15.8892
2062.9	15.5674
2065.82	15.5404
2068.74	14.7203
2071.66	12.0891
2074.58	12.3598
2077.5	13.0408
2080.41	13.2453
2083.33	11.6815
2086.24	11.6372
2089.16	11.4147
2092.07	11.6902
2094.98	11.6105
2097.89	12.3045
2100.8	14.7339
2103.71	15.6933
2106.62	15.6152
2109.53	16.8154
2112.43	17.545
2115.33	17.9178
2118.24	19.475
2121.14	20.6518
2124.04	22.2388
2126.94	24.4682
2129.84	27.5563
2132.74	28.5134
2135.63	29.1735
2138.53	30.2466
2141.43	31.957
2144.32	34.7242
2147.21	36.9942
2150.1	39.055
2152.99	39.8247
2155.88	43.5262
2158.77	45.0326
2161.66	47.8693
2164.55	49.1752
2167.43	50.1878
2170.31	53.8737
2173.2	54.6208
2176.08	54.0912
2178.96	53.0369
2181.84	51.7801
2184.72	50.4038
2187.6	50.2121
2190.47	47.6224
2193.35	45.9465
2196.23	43.0335
2199.1	40.7191
2201.97	37.5741
2204.84	33.14
2207.71	29.9344
2210.58	26.4584
2213.45	25.4278
2216.32	24.7283
2219.19	23.1799
2222.05	21.4467
2224.92	21.4364
2227.78	21.3344
2230.64	21.2647
2233.5	21.4732
2236.36	20.9727
2239.22	22.3616
2242.08	22.1091
2244.94	20.2648
2247.79	21.3486
2250.65	21.1237
2253.5	22.7056
2256.36	24.314
2259.21	23.316
2262.06	22.9125
2264.91	23.3944
2267.76	21.0448
2270.6	19.9112
2273.45	20.8606
2276.3	20.6445
2279.14	20.2398
2281.98	19.2131
2284.83	18.9504
2287.67	16.7789
2290.51	15.2745
2293.35	13.0331
2296.19	13.6995
2299.02	13.816
2301.86	12.516
2304.7	13.4044
2307.53	14.0148
2310.36	14.3454
2313.2	13.879
2316.03	14.906
2318.86	17.0126
2321.69	17.9493
2324.51	18.2605
2327.34	17.3063
2330.17	16.7775
2332.99	18.2965
2335.82	17.915
2338.64	17.8682
2341.46	17.1014
2344.28	18.7079
2347.1	16.7638
2349.92	16.4365
2352.74	13.3689
2355.56	12.3733
2358.37	12.0792
2361.19	9.73821
2364	9.41729
2366.82	9.62382
2369.63	8.2345
2372.44	9.45094
2375.25	10.3222
2378.06	10.0274
2380.86	9.43234
2383.67	10.6635
2386.48	10.1511
2389.28	10.5466
2392.09	11.1417
2394.89	10.3122
2397.69	10.7973
2400.49	10.6601
2403.29	10.6313
2406.09	10.1248
2408.89	9.85439
2411.69	10.1257
2414.48	9.89279
2417.28	8.17632
2420.07	7.79722
2422.86	7.41987
2425.65	8.63614
2428.45	8.34234
2431.23	7.36767
2434.02	7.78262
2436.81	7.39321
2439.6	6.79611
2442.38	6.63938
2445.17	6.46809
2447.95	6.83675
2450.73	6.50251
2453.52	7.88998
2456.3	8.04111
2459.08	8.8304
2461.85	8.09653
2464.63	6.16509
2467.41	7.45205
2470.19	8.43356
2472.96	8.28258
2475.73	8.00572
2478.51	6.80786
2481.28	6.29807
2484.05	7.0577
2486.82	6.86063
2489.59	6.91875
2492.35	7.12245
2495.12	7.59339
2497.89	7.49731
2500.65	5.79069
2503.42	4.78782
2506.18	2.77434
2508.94	2.00768
2511.7	2.40656
2514.46	2.77349
2517.22	2.85087
2519.98	3.2312
2522.73	4.29217
2525.49	3.58286
2528.25	3.45238
2531	3.71608
2533.75	6.02095
2536.5	8.72939
2539.25	7.91463
2542.01	7.8092
2544.75	8.11317
2547.5	8.37877
2550.25	8.55414
2553	8.72176
2555.74	8.28712
2558.49	9.15644
2561.23	10.27
2563.97	10.1126
2566.71	10.3831
2569.45	8.3674
2572.19	7.63623
2574.93	5.71727
2577.67	5.90899
2580.4	5.72931
2583.14	5.01907
2585.87	5.53708
2588.6	6.31833
2591.34	5.01443
2594.07	4.45148
2596.8	4.94534
2599.53	4.83407
2602.26	4.21656
2604.98	3.14656
2607.71	2.78349
2610.44	2.51163
2613.16	2.69306
2615.88	2.54505
2618.61	2.60081
2621.33	3.62394
2624.05	4.71197
2626.77	4.6567
2629.49	4.08357
2632.21	3.74738
2634.92	2.62888
2637.64	2.26375
2640.35	2.36652
2643.07	2.40918
2645.78	4.62635
2648.49	6.02314
2651.2	7.39745
2653.91	8.0736
2656.62	8.95466
2659.33	9.99639
2662.04	11.73
2664.74	12.4308
2667.45	10.9518
2670.15	11.07
2672.86	13.1838
2675.56	12.9905
2678.26	13.6302
2680.96	14.7156
2683.66	15.3745
2686.36	15.4618
2689.06	16.6491
2691.75	15.7452
2694.45	15.0335
2697.14	15.5732
2699.84	15.3956
2702.53	15.3378
2705.22	15.0861
2707.91	15.2919
2710.6	16.4638
2713.29	16.5558
2715.98	18.1028
2718.67	17.068
2721.35	16.3209
2724.04	16.0671
2726.72	14.7052
2729.4	14.61
2732.09	13.4933
2734.77	11.8176
2737.45	11.9778
2740.13	13.4715
2742.81	12.7245
2745.48	13.6798
2748.16	13.3789
2750.84	13.1914
2753.51	12.8047
2756.19	11.4129
2758.86	9.6417
2761.53	9.02581
2764.2	8.14234
2766.87	6.3851
2769.54	5.37541
2772.21	4.61648
2774.88	4.70669
2777.54	3.94108
2780.21	2.52561
2782.87	2.0988
2785.53	2.27343
2788.2	0.391055
2790.86	0.171017
2793.52	0.648942
2796.18	0.8664
2798.84	1.10889
2801.49	1.18992
2804.15	1.41338
2806.81	1.74827
2809.46	2.22023
2812.12	3.23779
2814.77	3.76102
2817.42	6.77678
2820.07	8.7615
2822.72	12.5565
2825.37	16.9969
2828.02	21.9649
2830.67	27.7111
2833.31	34.5812
2835.96	42.1789
2838.61	49.4797
2841.25	58.0883
2843.89	66.9734
2846.53	76.6371
2849.17	85.389
2851.81	94.8089
2854.45	104.549
2857.09	114.948
2859.73	123.832
2862.36	131.584
2865	139.977
2867.64	145.259
2870.27	152.646
2872.9	158.236
2875.53	163.452
2878.16	167.062
2880.79	172.668
2883.42	175.856
2886.05	180.384
2888.68	185.72
2891.3	190.213
2893.93	195.594
2896.55	200.74
2899.18	207.029
2901.8	213.349
2904.42	220.514
2907.04	229.266
2909.66	237.954
2912.28	249.14
2914.9	257.885
2917.51	269.774
2920.13	279.348
2922.74	285.477
2925.36	290.205
2927.97	293.237
2930.59	292.942
2933.2	292.048
2935.81	288.146
2938.42	280.768
2941.02	272.504
2943.63	262.896
2946.24	252.114
2948.85	239.85
2951.45	226.774
2954.05	213.848
2956.66	200.976
2959.26	189.697
2961.86	178.198
2964.46	165.375
2967.06	155.161
2969.66	147.32
2972.26	140.102
2974.85	133.865
2977.45	128.158
2980.05	122.013
2982.64	115.451
2985.23	107.068
2987.83	99.6574
2990.42	93.8559
2993.01	85.6255
2995.6	78.4125
2998.19	70.5314
3000.77	61.4193
3003.36	53.1361
3005.95	45.7122
3008.53	38.0081
3011.12	31.68
3013.7	25.8424
3016.28	20.9383
3018.86	15.8833
3021.44	11.6843
3024.02	8.84829
3026.6	6.42498
3029.18	4.78831
3031.76	4.39925
3034.33	5.44115
3036.91	6.15995
3039.48	6.37162
3042.05	8.04892
3044.63	8.54863
3047.2	9.58447
3049.77	11.1797
3052.34	12.1974
3054.91	12.5803
3057.48	13.1025
3060.04	13.262
3062.61	14.1031
3065.17	14.421
3067.74	14.3106
3070.3	13.1838
3072.87	12.6625
3075.43	11.4782
3077.99	9.64514
3080.55	8.71404
3083.11	7.2981
3085.67	7.15307
3088.22	6.3802
3090.78	5.89266
3093.34	5.61536
3095.89	6.41186
3098.44	7.88543
3101	9.1016
3103.55	9.77312
3106.1	10.2648
3108.65	11.5106
3111.2	12.2739
3113.75	13.278
3116.3	15.3329
3118.84	17.4662
3121.39	19.6982
3123.93	21.5932
3126.48	22.6762
3129.02	23.2346
3131.56	23.1705
3134.1	23.8022
3136.64	24.3287
3139.18	24.7208
3141.72	25.8197
3144.26	26.9523
3146.8	28.2379
3149.33	29.8984