File: data/Raman/poly_smoothed/Mbcal_20_25_11_1x_45s_532 nm_x100_100%_600 gr_mm_01.txt
#Acq. time (s)=	45
#Accumulations=	2
#Range (cm-¹)=	200...3150
#Windows=	2
#Auto scanning=	Off
#Autofocus=	Off
#Macrospot=	Off
#AutoExposure=	Off
#Spike filter=	Multiple accum.
#Delay time (s)=	0
#Binning=	1
#Readout mode=	Signal
#DeNoise=	Off
#ICS correction=	On
#Dark correction=	Off
#Inst. Process=	Off
#Detector Gain=	Best Dynamic Range
#Detector ADC=	20 kHz
#Detector temperature (°C)=	-69.85
#Instrument=	LabRAM HR Evol
#Detector=	Synapse
#Objective=	x100
#Grating=	600 gr/mm
#ND Filter=	100%
#Laser (nm)=	532
#Hole=	100.021
#Range=	Auto
#Laser Pol.=	No
#Raman. Pol.=	No
#Laser Pol. (°)=	-0.0007625
#Raman Pol. (°)=	89.9995
#Collection=	Microscope
#StageXY=	Marzhauser
#StageZ=	Marzhauser
#X (µm)=	-1203.6
#Y (µm)=	1243.5
#Z (µm)=	578.2
#Full time(mm:ss)=	3:18
#Project=
#Sample=
#Site=
#Title=	Mbcal_20_25_11_2x_45s_532 nm_x100_100%_600 gr_mm
#Remark=
#Date=	18.07.2022 10:13
#Acquired=	18.07.2022 10:13:12
#Base:Fit=	10.08.2022 10:55:08
#Base:Sub=	10.08.2022 10:55:14
#Filter:Polynom=	16.08.2022 10:07:28
#AxisType[0]=Intens
#AxisUnit[0]=Cnt
#AxisType[1]=Spectr
#AxisUnit[1]=1/cm
200.419	24.2569
204.048	18.6451
207.678	13.8684
211.304	10.9072
214.928	10.2912
218.554	7.68301
222.176	6.48828
225.798	4.78749
229.417	3.5983
233.035	3.79371
236.653	2.98084
240.268	2.60285
243.881	3.48261
247.493	4.4972
251.103	4.86367
254.715	6.22363
258.322	8.56842
261.929	10.4201
265.534	12.6511
269.137	13.8071
272.739	15.0828
276.34	15.6265
279.939	15.5551
283.537	13.9647
287.134	13.5469
290.729	13.6512
294.323	14.5987
297.913	15.8838
301.504	17.1564
305.093	17.2583
308.682	15.2053
312.268	15.7391
315.852	15.7656
319.436	15.6686
323.018	14.8686
326.597	14.6085
330.177	15.3542
333.753	16.7517
337.331	15.9785
340.906	15.2399
344.478	15.9787
348.051	14.623
351.621	15.0557
355.189	14.1504
358.757	11.4318
362.323	10.1722
365.889	8.67392
369.451	7.44174
373.012	7.72794
376.574	7.49283
380.133	7.90664
383.69	9.25284
387.245	8.87375
390.8	9.57536
394.353	8.00271
397.906	7.88131
401.456	7.6646
405.005	6.60733
408.552	5.47344
412.099	5.78959
415.643	7.40028
419.187	8.40432
422.728	8.55973
426.269	7.89066
429.806	7.13431
433.344	7.47833
436.881	7.41368
440.416	7.8654
443.949	6.88333
447.48	7.20306
451.011	7.5176
454.541	7.11008
458.069	8.22793
461.594	8.28905
465.119	8.05577
468.642	7.20342
472.165	6.65153
475.684	6.39477
479.204	5.17855
482.721	5.74077
486.239	5.80674
489.753	6.30007
493.268	6.62222
496.779	9.24061
500.289	10.706
503.8	13.4899
507.307	14.8468
510.813	16.7463
514.32	17.9804
517.823	19.9053
521.325	20.4936
524.826	21.3606
528.325	19.5425
531.823	19.9461
535.32	19.0823
538.815	18.171
542.309	17.8737
545.802	16.5028
549.293	15.5415
552.783	14.7467
556.271	13.8892
559.759	12.4348
563.245	12.5786
566.729	11.5031
570.213	10.6802
573.693	10.4688
577.173	8.16182
580.652	7.07445
584.13	5.76643
587.605	6.88931
591.08	5.91649
594.552	6.01095
598.025	5.39531
601.496	5.93521
604.964	5.84038
608.433	6.51825
611.898	5.17212
615.364	5.67385
618.827	6.83184
622.288	6.03078
625.75	7.493
629.209	8.22077
632.667	10.8547
636.125	12.8156
639.58	14.3441
643.033	15.5524
646.485	18.491
649.936	19.6089
653.388	20.317
656.836	21.7767
660.283	22.557
663.728	22.178
667.173	21.706
670.616	22.531
674.057	22.4062
677.498	21.5928
680.937	21.9988
684.375	22.7517
687.809	24.0117
691.244	24.2172
694.678	24.59
698.111	25.6122
701.54	26.4455
704.97	28.0355
708.398	28.4983
711.826	29.8996
715.25	30.9004
718.675	34.0853
722.096	33.9166
725.518	35.8719
728.937	37.2228
732.357	38.7672
735.773	40.498
739.19	43.3444
742.604	45.2914
746.018	45.3844
749.429	47.8555
752.839	50.7541
756.248	51.4153
759.657	53.4832
763.063	53.7476
766.468	56.5149
769.871	59.4054
773.273	61.6919
776.676	62.577
780.075	64.8683
783.474	67.2843
786.871	69.6201
790.266	71.3482
793.661	72.2363
797.054	72.3388
800.446	73.6517
803.834	73.2914
807.224	74.1749
810.612	75.7431
813.998	75.758
817.384	75.3868
820.766	73.9117
824.149	75.5185
827.531	76.1211
830.909	76.3955
834.288	78.1574
837.666	78.9441
841.041	80.2537
844.416	82.2873
847.788	83.6907
851.161	84.6715
854.53	86.1977
857.901	84.802
861.268	83.789
864.633	83.6058
868	82.7114
871.363	80.6365
874.725	76.6577
878.088	74.2076
881.447	70.0924
884.805	68.2177
888.162	66.9434
891.518	61.9865
894.872	57.693
898.225	55.127
901.577	51.8845
904.928	50.9608
908.277	48.8473
911.625	48.7742
914.972	50.0521
918.318	49.7107
921.662	50.0488
925.005	50.3559
928.347	49.7387
931.686	48.8956
935.025	48.6115
938.363	47.2537
941.698	45.9351
945.034	45.8871
948.368	44.2703
951.699	43.2933
955.031	41.9809
958.36	40.9223
961.689	40.5185
965.016	39.5094
968.343	39.7386
971.666	39.8911
974.991	39.6608
978.312	39.5331
981.632	39.1651
984.953	38.2701
988.27	37.8985
991.587	37.9318
994.902	37.5949
998.216	36.8472
1001.53	34.5946
1004.84	34.1723
1008.15	33.4765
1011.46	34.2071
1014.77	35.8498
1018.07	36.0786
1021.38	37.4221
1024.68	38.8282
1027.99	40.3447
1031.29	40.6559
1034.59	40.0204
1037.89	40.4639
1041.18	40.024
1044.48	39.1116
1047.77	39.5298
1051.07	39.2947
1054.36	38.1244
1057.65	37.027
1060.94	35.5691
1064.23	34.9009
1067.52	32.8843
1070.8	31.8736
1074.09	31.6645
1077.37	30.3481
1080.65	29.165
1083.93	29.123
1087.21	30.5202
1090.49	31.2577
1093.77	32.193
1097.04	33.7476
1100.32	32.9125
1103.59	33.8002
1106.86	33.1255
1110.13	33.5493
1113.4	32.2576
1116.67	30.5625
1119.94	30.2366
1123.2	29.559
1126.47	29.143
1129.73	27.4592
1132.99	25.9085
1136.25	25.0988
1139.51	23.4573
1142.77	22.9369
1146.03	21.4046
1149.28	19.8062
1152.54	18.2463
1155.79	16.012
1159.04	14.1519
1162.29	13.5396
1165.54	12.7272
1168.79	10.3519
1172.04	10.6227
1175.28	10.1802
1178.53	9.51229
1181.77	8.84781
1185.01	9.63276
1188.25	10.7308
1191.49	11.1604
1194.73	12.2684
1197.96	14.6287
1201.2	17.4247
1204.43	19.7194
1207.66	22.443
1210.9	24.3175
1214.13	27.6989
1217.36	30.5411
1220.58	33.7019
1223.81	37.3349
1227.04	39.387
1230.26	41.1999
1233.48	43.4837
1236.71	45.6281
1239.93	49.5202
1243.14	51.5041
1246.36	53.1543
1249.58	56.6399
1252.8	58.291
1256.01	59.9026
1259.22	61.3203
1262.43	62.5433
1265.64	65.2551
1268.85	66.4291
1272.06	67.0145
1275.27	68.5053
1278.48	69.0105
1281.68	71.4306
1284.88	71.4511
1288.08	72.8194
1291.28	73.9215
1294.48	76.2416
1297.68	79.7926
1300.88	82.1008
1304.07	84.5078
1307.27	85.2498
1310.46	87.0783
1313.65	88.9421
1316.85	90.1575
1320.03	93.2271
1323.22	93.5977
1326.41	95.5788
1329.6	98.4855
1332.78	97.3399
1335.96	98.3123
1339.15	99.3839
1342.33	99.2726
1345.51	97.9474
1348.69	95.6899
1351.86	92.6817
1355.04	90.1578
1358.21	84.3252
1361.39	84.3476
1364.56	82.3706
1367.73	83.1992
1370.9	82.6407
1374.07	81.9518
1377.24	79.4703
1380.41	77.4842
1383.57	75.3504
1386.73	74.2024
1389.9	73.2374
1393.06	72.1711
1396.22	71.8249
1399.38	71.329
1402.54	73.3497
1405.69	75.1393
1408.85	76.8601
1412	78.397
1415.16	82.4534
1418.31	86.8297
1421.46	90.2935
1424.61	93.2161
1427.76	95.9313
1430.9	98.5337
1434.05	101.191
1437.2	105.942
1440.34	110.443
1443.48	112.599
1446.62	112.113
1449.76	112.413
1452.9	111.015
1456.04	108.035
1459.17	106.021
1462.31	102.651
1465.44	97.7987
1468.58	93.0178
1471.71	88.0975
1474.84	82.5861
1477.97	76.7404
1481.1	72.6494
1484.22	67.8912
1487.35	61.2553
1490.47	56.1893
1493.59	52.753
1496.72	47.9895
1499.84	42.8209
1502.96	39.9335
1506.08	36.7903
1509.19	34.2889
1512.31	31.7211
1515.42	30.6956
1518.54	30.1902
1521.65	29.5861
1524.76	30.0123
1527.87	31.1189
1530.98	32.2782
1534.09	33.6655
1537.2	35.782
1540.3	36.5674
1543.41	39.3958
1546.51	43.6719
1549.61	46.0944
1552.71	47.9016
1555.81	50.7909
1558.91	52.3718
1562.01	53.9417
1565.1	56.3258
1568.2	56.9971
1571.29	59.834
1574.38	60.8665
1577.48	64.2239
1580.57	65.1922
1583.65	66.9036
1586.74	69.652
1589.83	71.3617
1592.92	73.0638
1596	74.3077
1599.08	75.1784
1602.16	74.8081
1605.24	73.5523
1608.32	71.8965
1611.4	70.4879
1614.48	68.3213
1617.56	68.3006
1620.63	69.2037
1623.71	67.903
1626.78	66.405
1629.85	66.6191
1632.92	65.6699
1635.99	65.4672
1639.06	66.0814
1642.12	67.1025
1645.19	67.2039
1648.25	67.5822
1651.32	66.0548
1654.38	65.1386
1657.44	64.5867
1660.5	63.8233
1663.56	61.4768
1666.62	59.3556
1669.67	56.9075
1672.73	53.7049
1675.79	49.8954
1678.84	44.726
1681.89	39.7734
1684.94	35.3371
1687.99	31.3101
1691.04	27.217
1694.08	24.1132
1697.13	20.2773
1700.18	18.2843
1703.22	16.695
1706.26	14.2067
1709.3	13.4862
1712.35	12.7086
1715.39	12.6617
1718.42	11.5601
1721.46	10.9821
1724.5	9.95948
1727.53	8.98682
1730.56	8.71277
1733.6	8.12702
1736.63	6.26631
1739.66	5.61581
1742.69	5.01821
1745.71	4.92012
1748.74	4.79343
1751.77	4.27197
1754.79	4.28386
1757.81	4.00227
1760.84	3.39141
1763.86	2.99847
1766.88	3.49015
1769.9	4.09455
1772.91	5.20959
1775.93	5.99308
1778.95	6.39051
1781.96	6.5353
1784.97	7.09741
1787.99	6.83489
1791	6.74896
1794.01	6.25904
1797.01	6.09672
1800.02	5.25032
1803.03	4.88171
1806.03	3.51075
1809.04	3.23018
1812.04	3.67136
1815.04	3.9019
1818.04	4.07711
1821.04	3.49493
1824.04	4.30151
1827.04	3.85334
1830.03	3.45601
1833.03	2.95346
1836.02	3.54001
1839.02	3.61538
1842.01	3.69383
1845	4.36315
1847.99	4.65327
1850.98	6.09624
1853.96	5.62955
1856.95	4.63
1859.94	4.81794
1862.92	3.64685
1865.9	3.15345
1868.88	2.88344
1871.86	3.61197
1874.84	3.35177
1877.82	3.07395
1880.8	3.31948
1882.58	3.78767
1885.57	3.19995
1888.56	3.39971
1891.54	3.32402
1894.53	4.60804
1897.51	4.82409
1900.5	4.22794
1903.48	5.00178
1906.46	5.29628
1909.44	5.83491
1912.42	5.48146
1915.4	5.41481
1918.37	5.8817
1921.35	6.13234
1924.32	5.62263
1927.3	4.8065
1930.27	4.23428
1933.24	4.09703
1936.21	2.83113
1939.18	2.09132
1942.15	2.51606
1945.11	2.07308
1948.08	1.86316
1951.04	2.10095
1954.01	1.70437
1956.97	0.951759
1959.93	1.30755
1962.89	3.52551
1965.85	3.89489
1968.81	4.16508
1971.77	3.77822
1974.72	3.4829
1977.68	3.85974
1980.63	4.45763
1983.58	4.97311
1986.53	4.71469
1989.48	4.96647
1992.43	5.60869
1995.38	5.24112
1998.33	5.20676
2001.27	5.17394
2004.22	4.42981
2007.16	4.13819
2010.11	4.05155
2013.05	4.43867
2015.99	5.47347
2018.93	4.93523
2021.87	5.33808
2024.8	4.4396
2027.74	3.09178
2030.68	3.27178
2033.61	4.14205
2036.54	4.07963
2039.48	3.18824
2042.41	1.89951
2045.34	1.45647
2048.27	2.46269
2051.19	2.26307
2054.12	1.29621
2057.05	0.780598
2059.97	1.00566
2062.9	0.418334
2065.82	-0.753576
2068.74	-0.848072
2071.66	-0.506974
2074.58	-0.298038
2077.5	-0.0590509
2080.41	1.54653
2083.33	2.1308
2086.24	2.71953
2089.16	3.84661
2092.07	3.64545
2094.98	4.77812
2097.89	4.6157
2100.8	5.50409
2103.71	6.10743
2106.62	6.94487
2109.53	7.78559
2112.43	9.06124
2115.33	9.45799
2118.24	11.9429
2121.14	11.9771
2124.04	12.2872
2126.94	14.0878
2129.84	15.778
2132.74	17.0929
2135.63	20.1941
2138.53	21.3616
2141.43	24.0057
2144.32	25.8065
2147.21	29.2127
2150.1	30.7812
2152.99	32.9642
2155.88	34.7994
2158.77	37.2267
2161.66	39.1636
2164.55	39.6761
2167.43	40.4254
2170.31	41.0808
2173.2	40.6624
2176.08	40.8682
2178.96	41.3653
2181.84	40.9868
2184.72	39.1991
2187.6	37.6349
2190.47	36.0149
2193.35	34.5153
2196.23	33.1996
2199.1	32.3586
2201.97	30.227
2204.84	28.5351
2207.71	26.3292
2210.58	23.9319
2213.45	22.0643
2216.32	20.7163
2219.19	18.9742
2222.05	17.9248
2224.92	16.8789
2227.78	16.0588
2230.64	15.1621
2233.5	14.7908
2236.36	14.6298
2239.22	13.8514
2242.08	12.6461
2244.94	12.3483
2247.79	11.749
2250.65	11.233
2253.5	10.302
2256.36	9.88792
2259.21	9.90182
2262.06	9.27946
2264.91	8.69461
2267.76	8.44816
2270.6	8.34653
2273.45	7.36515
2276.3	6.27085
2279.14	5.81
2281.98	5.25432
2284.83	5.56225
2287.67	5.59779
2290.51	4.49093
2293.35	3.48579
2296.19	3.37106
2299.02	4.54931
2301.86	5.78052
2304.7	7.18315
2307.53	7.94353
2310.36	6.58296
2313.2	7.81249
2316.03	8.2186
2318.86	8.24076
2321.69	8.40062
2324.51	8.05818
2327.34	7.78372
2330.17	7.87678
2332.99	7.58276
2335.82	8.42133
2338.64	8.31701
2341.46	8.1378
2344.28	6.1035
2347.1	6.01127
2349.92	5.84944
2352.74	6.05327
2355.56	4.17418
2358.37	3.55678
2361.19	2.54708
2364	2.75758
2366.82	3.35608
2369.63	3.96756
2372.44	4.17674
2375.25	4.4023
2378.06	3.46705
2380.86	3.58529
2383.67	4.17825
2386.48	3.58546
2389.28	3.59214
2392.09	4.3477
2394.89	5.35972
2397.69	5.81714
2400.49	5.88516
2403.29	7.23163
2406.09	7.90912
2408.89	8.07633
2411.69	7.68015
2414.48	8.31662
2417.28	8.84685
2420.07	8.49752
2422.86	7.82971
2425.65	7.1713
2428.45	6.49392
2431.23	5.982
2434.02	5.77736
2436.81	4.56053
2439.6	3.94544
2442.38	4.52847
2445.17	4.01435
2447.95	3.53862
2450.73	3.43829
2453.52	3.38677
2456.3	3.38013
2459.08	4.16059
2461.85	4.5769
2464.63	4.6336
2467.41	4.07965
2470.19	4.424
2472.96	4.19406
2475.73	3.20966
2478.51	3.14304
2481.28	2.76972
2484.05	1.74768
2486.82	0.100827
2489.59	-1.00045
2492.35	-0.566481
2495.12	-1.60462
2497.89	-1.25908
2500.65	-1.82207
2503.42	-1.86528
2506.18	-0.528707
2508.94	0.239389
2511.7	1.96718
2514.46	2.51852
2517.22	3.72493
2519.98	5.04592
2522.73	5.48902
2525.49	6.18509
2528.25	7.29398
2531	7.79476
2533.75	8.23707
2536.5	8.20846
2539.25	8.7587
2542.01	8.80464
2544.75	8.3706
2547.5	8.4848
2550.25	8.24755
2553	7.80417
2555.74	6.81383
2558.49	6.86155
2561.23	5.76884
2563.97	5.40098
2566.71	5.71299
2569.45	5.78455
2572.19	6.40447
2574.93	6.92246
2577.67	6.49149
2580.4	6.52295
2583.14	6.9797
2585.87	7.23636
2588.6	7.34348
2591.34	7.22068
2594.07	8.01394
2596.8	8.36214
2599.53	7.56545
2602.26	7.42022
2604.98	7.93216
2607.71	7.73184
2610.44	7.14169
2613.16	7.04607
2615.88	7.16527
2618.61	6.61665
2621.33	6.21863
2624.05	6.05608
2626.77	5.37787
2629.49	5.20548
2632.21	5.62878
2634.92	5.88059
2637.64	6.26262
2640.35	6.78199
2643.07	7.45499
2645.78	7.64555
2648.49	8.72574
2651.2	9.44692
2653.91	9.337
2656.62	8.85458
2659.33	9.03731
2662.04	8.74014
2664.74	8.88652
2667.45	8.17626
2670.15	8.17028
2672.86	6.89347
2675.56	5.82521
2678.26	5.40853
2680.96	5.60105
2683.66	5.3984
2686.36	4.9948
2689.06	4.94593
2691.75	4.94492
2694.45	4.56933
2697.14	5.0885
2699.84	5.89693
2702.53	6.66484
2705.22	8.57977
2707.91	9.30825
2710.6	9.96134
2713.29	11.2899
2715.98	11.7129
2718.67	12.2785
2721.35	12.4943
2724.04	12.6652
2726.72	13.5345
2729.4	12.7466
2732.09	12.0998
2734.77	11.1791
2737.45	10.0186
2740.13	8.81274
2742.81	8.16604
2745.48	7.20807
2748.16	6.89896
2750.84	6.58405
2753.51	5.83736
2756.19	5.07363
2758.86	3.89066
2761.53	3.71373
2764.2	3.03958
2766.87	2.60427
2769.54	3.03881
2772.21	2.12252
2774.88	1.88413
2777.54	1.68223
2780.21	1.76871
2782.87	1.22358
2785.53	1.20734
2788.2	1.09886
2790.86	0.4985
2793.52	0.586506
2796.18	0.262008
2798.84	0.299315
2801.49	-0.935727
2804.15	-0.6785
2806.81	-1.03416
2809.46	-0.813547
2812.12	-0.576825
2814.77	0.16585
2817.42	1.66079
2820.07	3.36572
2822.72	5.63733
2825.37	8.4553
2828.02	12.0072
2830.67	15.8962
2833.31	19.6331
2835.96	24.6638
2838.61	30.3859
2841.25	36.5974
2843.89	43.04
2846.53	50.6442
2849.17	57.3394
2851.81	65.054
2854.45	72.7838
2857.09	81.5113
2859.73	89.8825
2862.36	95.6873
2865	102.149
2867.64	108.293
2870.27	113.688
2872.9	117.764
2875.53	122.559
2878.16	127.251
2880.79	131.906
2883.42	135.823
2886.05	139.134
2888.68	142.681
2891.3	145.65
2893.93	149.929
2896.55	155.206
2899.18	160.168
2901.8	166.477
2904.42	173.742
2907.04	180.45
2909.66	188.296
2912.28	197.252
2914.9	205.803
2917.51	214.196
2920.13	221.913
2922.74	228.368
2925.36	232.006
2927.97	233.387
2930.59	235.09
2933.2	233.573
2935.81	231.462
2938.42	227.22
2941.02	221.078
2943.63	213.848
2946.24	204.564
2948.85	195.276
2951.45	184.897
2954.05	175.348
2956.66	165.546
2959.26	156.573
2961.86	146.667
2964.46	137.528
2967.06	130.281
2969.66	122.313
2972.26	115.097
2974.85	109.058
2977.45	104.609
2980.05	99.1839
2982.64	93.1775
2985.23	87.1115
2987.83	79.6862
2990.42	72.6852
2993.01	67.2701
2995.6	60.5062
2998.19	54.3915
3000.77	47.8167
3003.36	40.6667
3005.95	34.2597
3008.53	28.3451
3011.12	22.866
3013.7	17.0365
3016.28	12.9889
3018.86	9.41452
3021.44	6.42489
3024.02	3.16455
3026.6	1.2686
3029.18	-0.0322559
3031.76	-0.970067
3034.33	-1.01552
3036.91	-0.372558
3039.48	0.367309
3042.05	0.996632
3044.63	1.70664
3047.2	2.49607
3049.77	2.43183
3052.34	3.20273
3054.91	4.32611
3057.48	4.61265
3060.04	4.70849
3062.61	4.7341
3065.17	4.01144
3067.74	3.13034
3070.3	3.13506
3072.87	2.78909
3075.43	2.09836
3077.99	1.27217
3080.55	0.636797
3083.11	0.697851
3085.67	0.417886
3088.22	0.262574
3090.78	0.419988
3093.34	1.20647
3095.89	1.67768
3098.44	2.35751
3101	2.54183
3103.55	3.27655
3106.1	4.97971
3108.65	5.66783
3111.2	7.04843
3113.75	8.63777
3116.3	10.765
3118.84	12.8052
3121.39	14.2865
3123.93	16.0098
3126.48	16.9039
3129.02	18.0448
3131.56	20.7592
3134.1	22.2717
3136.64	23.3376
3139.18	24.62
3141.72	26.3097
3144.26	27.8345
3146.8	28.8713
3149.33	30.5296