File: data/Raman/poly_smoothed/Mbcal_20_25_46_1x_45s_532 nm_x100_100%_600 gr_mm_01.txt
#Acq. time (s)=	45
#Accumulations=	2
#Range (cm-¹)=	200...3150
#Windows=	2
#Auto scanning=	Off
#Autofocus=	Off
#Macrospot=	Off
#AutoExposure=	Off
#Spike filter=	Multiple accum.
#Delay time (s)=	0
#Binning=	1
#Readout mode=	Signal
#DeNoise=	Off
#ICS correction=	On
#Dark correction=	Off
#Inst. Process=	Off
#Detector Gain=	Best Dynamic Range
#Detector ADC=	20 kHz
#Detector temperature (°C)=	-69.85
#Instrument=	LabRAM HR Evol
#Detector=	Synapse
#Objective=	x100
#Grating=	600 gr/mm
#ND Filter=	100%
#Laser (nm)=	532
#Hole=	100.021
#Range=	Auto
#Laser Pol.=	No
#Raman. Pol.=	No
#Laser Pol. (°)=	-0.0007625
#Raman Pol. (°)=	89.9995
#Collection=	Microscope
#StageXY=	Marzhauser
#StageZ=	Marzhauser
#X (µm)=	-1137.4
#Y (µm)=	1238.1
#Z (µm)=	578.3
#Full time(mm:ss)=	3:18
#Project=
#Sample=
#Site=
#Title=	Mbcal_20_25_46_2x_45s_532 nm_x100_100%_600 gr_mm
#Remark=
#Date=	18.07.2022 13:42
#Acquired=	18.07.2022 13:42:54
#Base:Fit=	10.08.2022 10:55:08
#Base:Sub=	10.08.2022 10:55:14
#Filter:Polynom=	16.08.2022 10:07:28
#AxisType[0]=Intens
#AxisUnit[0]=Cnt
#AxisType[1]=Spectr
#AxisUnit[1]=1/cm
200.419	-3.41914
204.048	1.90265
207.678	4.84571
211.304	6.58801
214.928	8.04171
218.554	8.17336
222.176	9.99471
225.798	9.38714
229.417	9.23812
233.035	9.70931
236.653	9.63564
240.268	9.70159
243.881	10.0818
247.493	9.7677
251.103	9.47804
254.715	11.5844
258.322	11.2954
261.929	10.3314
265.534	12.4909
269.137	12.5724
272.739	14.7884
276.34	15.2365
279.939	14.7596
283.537	15.9634
287.134	16.4188
290.729	16.7871
294.323	17.2484
297.913	17.2962
301.504	16.9024
305.093	16.8497
308.682	16.9967
312.268	17.1782
315.852	15.2473
319.436	15.5727
323.018	14.8488
326.597	13.3333
330.177	12.6185
333.753	10.7454
337.331	10.0985
340.906	8.84922
344.478	7.91263
348.051	6.51175
351.621	6.65898
355.189	4.78182
358.757	5.81656
362.323	5.91859
365.889	7.16535
369.451	7.34907
373.012	8.94514
376.574	8.51248
380.133	9.54321
383.69	10.7531
387.245	10.8146
390.8	10.6263
394.353	10.0727
397.906	11.2999
401.456	12.0885
405.005	10.7321
408.552	10.328
412.099	9.55118
415.643	8.7276
419.187	8.10704
422.728	6.00918
426.269	5.65135
429.806	5.3218
433.344	3.64511
436.881	3.72589
440.416	5.83276
443.949	6.70526
447.48	8.04722
451.011	8.75622
454.541	9.4432
458.069	10.7382
461.594	10.8373
465.119	11.7436
468.642	13.6938
472.165	13.5533
475.684	15.0789
479.204	16.3187
482.721	18.5443
486.239	18.6571
489.753	17.2056
493.268	18.9012
496.779	19.0939
500.289	19.2498
503.8	20.0055
507.307	19.2058
510.813	20.0073
514.32	21.7858
517.823	23.4322
521.325	23.9024
524.826	27.6312
528.325	29.051
531.823	29.416
535.32	29.8949
538.815	31.3196
542.309	32.2573
545.802	31.0763
549.293	31.908
552.783	31.7066
556.271	31.9338
559.759	31.093
563.245	29.0521
566.729	26.5052
570.213	22.2644
573.693	19.0962
577.173	16.2743
580.652	14.0475
584.13	11.5896
587.605	10.6735
591.08	8.76628
594.552	8.57382
598.025	8.49423
601.496	8.39956
604.964	6.49918
608.433	6.93823
611.898	7.55035
615.364	9.54221
618.827	11.1956
622.288	11.2044
625.75	13.2926
629.209	14.9795
632.667	17.6598
636.125	20.4125
639.58	21.5309
643.033	23.4729
646.485	24.0899
649.936	24.4672
653.388	24.4088
656.836	25.0953
660.283	26.6355
663.728	27.9178
667.173	29.7398
670.616	30.5089
674.057	29.442
677.498	28.4945
680.937	30.35
684.375	28.8139
687.809	29.0409
691.244	26.2699
694.678	26.3686
698.111	24.1653
701.54	23.8176
704.97	22.2216
708.398	22.5183
711.826	24.118
715.25	24.4357
718.675	25.0763
722.096	23.0144
725.518	23.2619
728.937	24.5413
732.357	25.5279
735.773	27.0464
739.19	27.9483
742.604	31.3513
746.018	35.3301
749.429	38.306
752.839	39.5384
756.248	43.7291
759.657	47.4159
763.063	51.0585
766.468	55.1588
769.871	58.1176
773.273	63.0928
776.676	66.0934
780.075	69.0859
783.474	74.0543
786.871	77.0112
790.266	80.4672
793.661	80.6923
797.054	83.645
800.446	84.0808
803.834	83.9684
807.224	84.7661
810.612	83.3277
813.998	83.2311
817.384	79.9379
820.766	78.2025
824.149	80.5033
827.531	81.4924
830.909	81.6078
834.288	83.4706
837.666	85.1782
841.041	87.9747
844.416	87.1294
847.788	87.6905
851.161	86.9771
854.53	86.7015
857.901	85.0336
861.268	83.6505
864.633	82.787
868	79.0756
871.363	76.7598
874.725	72.0593
878.088	68.1584
881.447	64.8154
884.805	58.863
888.162	54.3439
891.518	49.5847
894.872	44.1532
898.225	43.2012
901.577	41.1976
904.928	42.3016
908.277	43.1199
911.625	44.5462
914.972	46.1308
918.318	47.3893
921.662	48.1606
925.005	47.3063
928.347	45.3565
931.686	44.2592
935.025	43.844
938.363	44.2127
941.698	43.7771
945.034	41.717
948.368	38.5217
951.699	38.9084
955.031	36.7549
958.36	33.3318
961.689	30.8615
965.016	27.8144
968.343	25.3425
971.666	24.6547
974.991	24.1951
978.312	23.334
981.632	23.0045
984.953	22.6009
988.27	21.1179
991.587	20.817
994.902	20.8997
998.216	19.9482
1001.53	19.4016
1004.84	17.679
1008.15	17.6718
1011.46	18.9974
1014.77	22.652
1018.07	25.7493
1021.38	27.6417
1024.68	28.6903
1027.99	31.4985
1031.29	34.2317
1034.59	33.3778
1037.89	31.9597
1041.18	31.3703
1044.48	30.2162
1047.77	29.6734
1051.07	28.6386
1054.36	29.0242
1057.65	27.0732
1060.94	24.4869
1064.23	22.6048
1067.52	23.6848
1070.8	23.4506
1074.09	23.5311
1077.37	22.3212
1080.65	22.7182
1083.93	22.2464
1087.21	23.8543
1090.49	25.1933
1093.77	27.5103
1097.04	29.8965
1100.32	29.7891
1103.59	30.5568
1106.86	29.4615
1110.13	30.2986
1113.4	28.5196
1116.67	25.5696
1119.94	23.4753
1123.2	21.434
1126.47	19.9123
1129.73	17.1818
1132.99	14.9679
1136.25	13.0662
1139.51	11.0199
1142.77	11.0784
1146.03	11.7724
1149.28	10.6341
1152.54	10.8126
1155.79	8.30481
1159.04	6.98391
1162.29	6.71124
1165.54	5.41406
1168.79	5.96963
1172.04	5.35692
1175.28	6.03301
1178.53	6.02246
1181.77	4.94749
1185.01	6.48488
1188.25	5.68638
1191.49	7.35428
1194.73	7.9446
1197.96	8.52907
1201.2	8.19613
1204.43	9.52486
1207.66	10.9314
1210.9	11.5758
1214.13	13.0145
1217.36	13.6385
1220.58	16.9981
1223.81	19.5828
1227.04	19.5549
1230.26	21.6941
1233.48	25.2032
1236.71	28.5102
1239.93	31.3754
1243.14	33.7451
1246.36	37.4135
1249.58	42.6569
1252.8	44.8308
1256.01	48.5918
1259.22	50.5576
1262.43	54.059
1265.64	56.377
1268.85	57.9821
1272.06	61.8641
1275.27	63.5793
1278.48	63.9519
1281.68	65.2984
1284.88	65.9743
1288.08	66.1528
1291.28	66.5723
1294.48	66.0178
1297.68	66.7646
1300.88	68.1347
1304.07	69.3216
1307.27	69.2178
1310.46	69.6587
1313.65	70.4752
1316.85	72.0847
1320.03	72.4849
1323.22	75.6628
1326.41	77.283
1329.6	79.6769
1332.78	79.4302
1335.96	79.5924
1339.15	80.0141
1342.33	78.8844
1345.51	77.714
1348.69	77.9027
1351.86	75.6281
1355.04	73.0274
1358.21	70.8949
1361.39	68.8709
1364.56	65.5318
1367.73	63.204
1370.9	62.6173
1374.07	61.0975
1377.24	59.0599
1380.41	56.5057
1383.57	55.5501
1386.73	54.3445
1389.9	52.9053
1393.06	52.3878
1396.22	50.7851
1399.38	52.2394
1402.54	55.6515
1405.69	57.7894
1408.85	60.6876
1412	62.4085
1415.16	65.76
1418.31	69.2591
1421.46	74.1894
1424.61	80.9646
1427.76	86.8331
1430.9	93.0073
1434.05	99.0249
1437.2	103.875
1440.34	108.04
1443.48	110.721
1446.62	113.971
1449.76	115.417
1452.9	112.89
1456.04	111.611
1459.17	109.529
1462.31	106.754
1465.44	101.015
1468.58	95.5327
1471.71	90.2797
1474.84	85.3858
1477.97	79.6386
1481.1	73.1001
1484.22	67.6062
1487.35	61.8308
1490.47	55.392
1493.59	52.021
1496.72	48.9751
1499.84	47.6925
1502.96	44.3596
1506.08	41.3298
1509.19	37.792
1512.31	35.2145
1515.42	32.2487
1518.54	29.1631
1521.65	27.6273
1524.76	27.3767
1527.87	25.1222
1530.98	25.3775
1534.09	24.7967
1537.2	26.4433
1540.3	27.3015
1543.41	27.9103
1546.51	29.9583
1549.61	31.5843
1552.71	33.4735
1555.81	36.6837
1558.91	39.3599
1562.01	43.5699
1565.1	44.6022
1568.2	47.5705
1571.29	51.1086
1574.38	55.2621
1577.48	57.8483
1580.57	60.376
1583.65	60.9744
1586.74	60.4765
1589.83	60.3818
1592.92	62.1461
1596	63.7078
1599.08	65.6322
1602.16	65.616
1605.24	62.3777
1608.32	61.7837
1611.4	61.7968
1614.48	60.6037
1617.56	60.523
1620.63	59.8668
1623.71	60.3527
1626.78	60.8102
1629.85	59.8896
1632.92	60.6303
1635.99	60.9994
1639.06	62.9881
1642.12	63.5193
1645.19	65.3118
1648.25	66.1203
1651.32	65.1288
1654.38	63.9668
1657.44	60.9795
1660.5	58.4515
1663.56	56.8475
1666.62	55.5334
1669.67	54.4098
1672.73	51.4628
1675.79	48.9021
1678.84	44.8573
1681.89	42.2261
1684.94	38.9196
1687.99	35.9418
1691.04	33.1347
1694.08	29.3103
1697.13	25.8234
1700.18	21.4882
1703.22	18.0192
1706.26	15.2254
1709.3	13.9689
1712.35	11.8261
1715.39	10.5203
1718.42	9.43089
1721.46	7.91855
1724.5	5.71293
1727.53	4.48937
1730.56	4.71328
1733.6	3.77093
1736.63	3.39896
1739.66	4.93566
1742.69	6.09077
1745.71	6.88627
1748.74	8.82261
1751.77	10.9464
1754.79	11.9735
1757.81	12.4251
1760.84	11.4433
1763.86	11.221
1766.88	10.0819
1769.9	9.91904
1772.91	7.79675
1775.93	7.31168
1778.95	8.96175
1781.96	9.38307
1784.97	8.93607
1787.99	9.80688
1791	10.6
1794.01	11.175
1797.01	10.9213
1800.02	10.9282
1803.03	10.6948
1806.03	11.1899
1809.04	11.4256
1812.04	12.622
1815.04	14.187
1818.04	14.1534
1821.04	14.9924
1824.04	14.9325
1827.04	14.6569
1830.03	13.6137
1833.03	13.0126
1836.02	12.3781
1839.02	11.6056
1842.01	12.6028
1845	12.9081
1847.99	11.8166
1850.98	12.629
1853.96	12.442
1856.95	12.6446
1859.94	12.205
1862.92	12.8312
1865.9	12.2969
1868.88	13.2623
1871.86	13.2857
1874.84	13.5705
1877.82	13.9062
1880.8	13.872
1882.58	13.6099
1885.57	14.7262
1888.56	13.7958
1891.54	13.8073
1894.53	13.3894
1897.51	12.1086
1900.5	11.1693
1903.48	10.429
1906.46	11.2124
1909.44	10.7557
1912.42	10.2343
1915.4	10.0552
1918.37	8.74639
1921.35	8.32094
1924.32	7.92519
1927.3	9.19012
1930.27	8.88771
1933.24	8.53897
1936.21	8.43795
1939.18	8.64195
1942.15	8.08666
1945.11	7.86953
1948.08	9.04634
1951.04	8.29311
1954.01	8.98427
1956.97	8.65508
1959.93	7.61295
1962.89	6.9082
1965.85	5.61449
1968.81	4.09726
1971.77	4.21494
1974.72	5.06367
1977.68	4.2224
1980.63	4.65038
1983.58	3.70385
1986.53	3.81879
1989.48	4.44245
1992.43	3.91172
1995.38	3.88903
1998.33	4.06395
2001.27	4.06698
2004.22	3.02348
2007.16	3.14321
2010.11	3.43659
2013.05	4.55633
2015.99	6.35965
2018.93	8.28486
2021.87	9.69182
2024.8	10.1577
2027.74	11.0175
2030.68	11.169
2033.61	10.4273
2036.54	10.3713
2039.48	11.5106
2042.41	11.4907
2045.34	13.4243
2048.27	13.6355
2051.19	14.0396
2054.12	13.0011
2057.05	13.7463
2059.97	13.1223
2062.9	12.5036
2065.82	12.4454
2068.74	11.7857
2071.66	12.1394
2074.58	11.8043
2077.5	11.6878
2080.41	12.9596
2083.33	12.8406
2086.24	13.5608
2089.16	14.5842
2092.07	15.817
2094.98	16.3995
2097.89	15.6699
2100.8	16.8705
2103.71	17.9141
2106.62	19.151
2109.53	21.0984
2112.43	21.9977
2115.33	22.6285
2118.24	24.2947
2121.14	24.3267
2124.04	25.1691
2126.94	25.7532
2129.84	27.6395
2132.74	28.2771
2135.63	30.207
2138.53	30.6588
2141.43	31.4766
2144.32	33.2688
2147.21	33.5089
2150.1	36.2815
2152.99	37.8782
2155.88	38.8034
2158.77	39.8069
2161.66	40.9755
2164.55	42.1893
2167.43	44.625
2170.31	46.6633
2173.2	47.6467
2176.08	47.9855
2178.96	49.6808
2181.84	49.3811
2184.72	47.3516
2187.6	46.1534
2190.47	43.9246
2193.35	42.5313
2196.23	41.0236
2199.1	38.2047
2201.97	36.1937
2204.84	34.8726
2207.71	32.2501
2210.58	29.2669
2213.45	28.21
2216.32	25.2032
2219.19	22.9903
2222.05	21.4718
2224.92	18.7816
2227.78	16.8818
2230.64	14.8675
2233.5	14.6823
2236.36	14.0789
2239.22	14.7383
2242.08	15.4925
2244.94	15.6739
2247.79	15.1577
2250.65	14.4463
2253.5	14.1057
2256.36	12.7751
2259.21	12.9432
2262.06	13.2514
2264.91	14.0781
2267.76	13.1603
2270.6	13.259
2273.45	12.2754
2276.3	12.7545
2279.14	10.8639
2281.98	11.1288
2284.83	10.4489
2287.67	8.29704
2290.51	7.81821
2293.35	5.37579
2296.19	4.14727
2299.02	4.72554
2301.86	5.14421
2304.7	6.58388
2307.53	8.18361
2310.36	8.28073
2313.2	7.70562
2316.03	8.93818
2318.86	9.04604
2321.69	8.32853
2324.51	7.97533
2327.34	7.43926
2330.17	8.25249
2332.99	8.41719
2335.82	8.61988
2338.64	6.58884
2341.46	7.05456
2344.28	6.50154
2347.1	5.76298
2349.92	5.12121
2352.74	5.3646
2355.56	4.50089
2358.37	3.25566
2361.19	2.45668
2364	2.40587
2366.82	3.8503
2369.63	4.40601
2372.44	4.51473
2375.25	4.68465
2378.06	3.76998
2380.86	2.7779
2383.67	3.85986
2386.48	3.75834
2389.28	3.5892
2392.09	4.22361
2394.89	5.03607
2397.69	6.22834
2400.49	6.56398
2403.29	7.21681
2406.09	7.18894
2408.89	6.25856
2411.69	5.83843
2414.48	5.15363
2417.28	4.81018
2420.07	5.69727
2422.86	5.37317
2425.65	4.55044
2428.45	3.02005
2431.23	2.61917
2434.02	1.53832
2436.81	0.729006
2439.6	0.0686411
2442.38	-1.12754
2445.17	-1.36698
2447.95	-1.69132
2450.73	-1.24119
2453.52	-0.845884
2456.3	-0.63526
2459.08	-0.317915
2461.85	0.751166
2464.63	2.02608
2467.41	1.81686
2470.19	1.38275
2472.96	1.52862
2475.73	0.832939
2478.51	1.06931
2481.28	1.69295
2484.05	2.18026
2486.82	2.42557
2489.59	2.79068
2492.35	2.30288
2495.12	2.15407
2497.89	2.33482
2500.65	2.19404
2503.42	1.30477
2506.18	2.05323
2508.94	1.83259
2511.7	2.20003
2514.46	2.37187
2517.22	2.0819
2519.98	1.89075
2522.73	1.28127
2525.49	1.40209
2528.25	1.21422
2531	1.1625
2533.75	1.80019
2536.5	1.55863
2539.25	0.851681
2542.01	0.798753
2544.75	1.17278
2547.5	2.73073
2550.25	3.15221
2553	3.28413
2555.74	2.57775
2558.49	2.26775
2561.23	3.03565
2563.97	3.43245
2566.71	2.97066
2569.45	4.4142
2572.19	4.43282
2574.93	5.28503
2577.67	5.50878
2580.4	6.22093
2583.14	5.51184
2585.87	5.42232
2588.6	5.34653
2591.34	4.70241
2594.07	5.59371
2596.8	6.1258
2599.53	6.53359
2602.26	6.2861
2604.98	5.08946
2607.71	4.74199
2610.44	5.18735
2613.16	5.36752
2615.88	5.98941
2618.61	5.32862
2621.33	5.24524
2624.05	5.23238
2626.77	4.97134
2629.49	4.63202
2632.21	4.86296
2634.92	5.7766
2637.64	6.04324
2640.35	7.4469
2643.07	7.08204
2645.78	6.26541
2648.49	6.31267
2651.2	5.8718
2653.91	6.67716
2656.62	7.09073
2659.33	7.54353
2662.04	7.86515
2664.74	8.22343
2667.45	8.66727
2670.15	8.41791
2672.86	9.46264
2675.56	9.26673
2678.26	9.94855
2680.96	11.1357
2683.66	11.1986
2686.36	11.9634
2689.06	12.0492
2691.75	12.2398
2694.45	12.8778
2697.14	12.5501
2699.84	14.0019
2702.53	13.9307
2705.22	14.8243
2707.91	14.2499
2710.6	14.2582
2713.29	14.8359
2715.98	14.7011
2718.67	14.8747
2721.35	15.9364
2724.04	16.087
2726.72	15.8268
2729.4	14.9384
2732.09	14.5627
2734.77	14.7447
2737.45	13.7126
2740.13	13.1504
2742.81	11.4239
2745.48	10.4646
2748.16	10.4038
2750.84	9.50243
2753.51	8.32895
2756.19	7.28692
2758.86	6.89562
2761.53	5.49251
2764.2	5.1335
2766.87	4.93257
2769.54	3.4471
2772.21	2.95451
2774.88	2.80454
2777.54	3.42866
2780.21	4.20659
2782.87	4.8562
2785.53	4.81044
2788.2	4.91716
2790.86	5.29329
2793.52	3.77266
2796.18	3.91111
2798.84	3.5196
2801.49	2.83681
2804.15	2.64463
2806.81	2.74792
2809.46	1.85128
2812.12	2.21896
2814.77	2.31426
2817.42	2.86042
2820.07	4.17806
2822.72	7.59509
2825.37	11.416
2828.02	16.6154
2830.67	21.7007
2833.31	26.5813
2835.96	32.5833
2838.61	39.6655
2841.25	47.4238
2843.89	55.7142
2846.53	62.4266
2849.17	70.8664
2851.81	80.1864
2854.45	90.0118
2857.09	100.107
2859.73	108.968
2862.36	117.497
2865	125.686
2867.64	132.473
2870.27	139.202
2872.9	144.684
2875.53	149.796
2878.16	155.002
2880.79	159.565
2883.42	164.94
2886.05	170.066
2888.68	174.762
2891.3	178.494
2893.93	181.909
2896.55	186.077
2899.18	190.191
2901.8	195.762
2904.42	200.925
2907.04	207.071
2909.66	215.316
2912.28	224.38
2914.9	233.991
2917.51	241.646
2920.13	249.902
2922.74	256.963
2925.36	261.793
2927.97	264.215
2930.59	264.723
2933.2	264.204
2935.81	261.778
2938.42	256.194
2941.02	248.797
2943.63	240.098
2946.24	229.998
2948.85	218.994
2951.45	206.732
2954.05	194.226
2956.66	183.43
2959.26	173.446
2961.86	162.55
2964.46	152.89
2967.06	144.53
2969.66	136.802
2972.26	130.992
2974.85	125.484
2977.45	119.026
2980.05	114.795
2982.64	109.294
2985.23	103.738
2987.83	96.9072
2990.42	91.3441
2993.01	83.6188
2995.6	77.1996
2998.19	70.2126
3000.77	61.7021
3003.36	52.786
3005.95	45.4436
3008.53	38.2114
3011.12	31.5351
3013.7	25.0348
3016.28	19.7207
3018.86	14.508
3021.44	11.2415
3024.02	7.23112
3026.6	4.38885
3029.18	1.55033
3031.76	-0.0759878
3034.33	-1.72953
3036.91	-2.4183
3039.48	-1.79375
3042.05	-1.23648
3044.63	-0.93091
3047.2	-0.835365
3049.77	-0.501538
3052.34	0.649979
3054.91	1.0502
3057.48	-0.0411434
3060.04	0.307583
3062.61	0.810713
3065.17	1.69469
3067.74	1.90203
3070.3	1.77688
3072.87	1.97209
3075.43	2.86746
3077.99	2.82658
3080.55	2.19067
3083.11	1.95913
3085.67	1.65221
3088.22	1.06606
3090.78	1.03122
3093.34	0.386187
3095.89	0.448718
3098.44	1.64416
3101	2.66962
3103.55	4.36775
3106.1	4.96286
3108.65	5.43541
3111.2	7.34482
3113.75	8.83082
3116.3	10.8264
3118.84	11.495
3121.39	12.4986
3123.93	14.1486
3126.48	17.0617
3129.02	18.3969
3131.56	18.8158
3134.1	20.7962
3136.64	22.6238
3139.18	23.3955
3141.72	22.7575
3144.26	22.7801
3146.8	21.8805
3149.33	23.2212