File: data/Raman/poly_smoothed/Thy_00_07_35_1x_45s_532 nm_x100_100%_600 gr_mm_01.txt
#Acq. time (s)=	45
#Accumulations=	2
#Range (cm-¹)=	200...3150
#Windows=	2
#Auto scanning=	Off
#Autofocus=	Off
#Macrospot=	Off
#AutoExposure=	Off
#Spike filter=	Multiple accum.
#Delay time (s)=	0
#Binning=	1
#Readout mode=	Signal
#DeNoise=	Off
#ICS correction=	On
#Dark correction=	Off
#Inst. Process=	Off
#Detector Gain=	Best Dynamic Range
#Detector ADC=	20 kHz
#Detector temperature (°C)=	-69.85
#Instrument=	LabRAM HR Evol
#Detector=	Synapse
#Objective=	x100
#Grating=	600 gr/mm
#ND Filter=	100%
#Laser (nm)=	532
#Hole=	100.021
#Range=	Auto
#Laser Pol.=	No
#Raman. Pol.=	No
#Laser Pol. (°)=	-0.0007625
#Raman Pol. (°)=	89.9995
#Collection=	Microscope
#StageXY=	Marzhauser
#StageZ=	Marzhauser
#X (µm)=	8967.2
#Y (µm)=	-3068.2
#Z (µm)=	-54.85
#Full time(mm:ss)=	3:19
#Project=
#Sample=
#Site=
#Title=	Thy_00_07_35_2x_45s_532 nm_x100_100%_600 gr_mm
#Remark=
#Date=	28.06.2022 12:41
#Acquired=	28.06.2022 12:41:49
#Base:Fit=	10.08.2022 10:07:56
#Base:Sub=	10.08.2022 10:08:40
#Filter:Polynom=	16.08.2022 10:26:06
#AxisType[0]=Intens
#AxisUnit[0]=Cnt
#AxisType[1]=Spectr
#AxisUnit[1]=1/cm
200.407	28.7429
204.035	30.6846
207.665	27.6668
211.291	23.577
214.916	21.0015
218.541	18.1826
222.163	16.8299
225.785	13.7114
229.404	12.8903
233.022	11.2731
236.638	8.70965
240.255	7.28756
243.868	7.13398
247.48	5.70517
251.091	5.91252
254.702	6.60247
258.31	5.44035
261.916	4.70452
265.521	4.33321
269.125	4.17394
272.727	3.94567
276.328	4.52104
279.927	5.18212
283.525	5.63059
287.121	5.89769
290.716	5.44425
294.31	3.7302
297.9	4.96886
301.491	4.87136
305.081	6.21975
308.669	6.73305
312.256	6.97993
315.839	7.60065
319.423	7.78232
323.006	7.24745
326.585	7.34058
330.165	8.35188
333.741	7.09852
337.318	7.97133
340.894	7.02642
344.466	6.48696
348.039	5.93356
351.608	4.78162
355.176	4.32369
358.745	4.47687
362.31	3.65448
365.876	2.1716
369.439	1.73068
373	1.57991
376.56	1.5892
380.12	1.90222
383.677	1.93696
387.233	1.9365
390.787	1.29305
394.34	2.33334
397.894	3.61266
401.444	3.01911
404.993	3.432
408.54	3.54873
412.086	3.0558
415.631	2.64709
419.174	2.75691
422.716	3.34471
426.257	4.04149
429.794	3.66428
433.332	3.7922
436.868	2.91004
440.403	2.70883
443.937	2.72279
447.468	2.66282
450.999	3.51816
454.528	4.06736
458.057	4.76191
461.582	5.23664
465.107	6.74432
468.629	8.88809
472.152	9.85966
475.672	11.1169
479.192	12.5504
482.709	14.0994
486.226	14.9004
489.74	14.4285
493.255	15.4357
496.767	15.988
500.277	17.0268
503.788	16.9456
507.295	18.3205
510.801	17.5495
514.308	17.2774
517.811	15.2611
521.313	15.7262
524.814	15.3659
528.313	15.1109
531.811	14.5125
535.308	14.1288
538.803	12.7367
542.297	10.8739
545.789	9.7567
549.281	10.7391
552.771	12.0432
556.259	11.6897
559.747	11.4241
563.233	10.9689
566.717	9.7592
570.2	10.1304
573.68	8.98458
577.161	8.1519
580.64	7.75144
584.118	6.3537
587.593	5.99167
591.068	5.09902
594.54	4.71615
598.013	3.47809
601.484	3.5606
604.952	3.10006
608.421	3.84354
611.886	4.00964
615.35	5.54633
618.815	5.34219
622.276	6.95722
625.738	8.15287
629.197	10.4411
632.655	13.273
636.113	15.9863
639.568	17.8951
643.021	20.3804
646.473	22.0044
649.924	24.4497
653.376	25.5587
656.824	27.4928
660.271	29.0124
663.716	30.0113
667.161	28.9846
670.604	29.9707
674.045	31.8744
677.486	33.0413
680.925	30.9293
684.361	29.9041
687.797	31.179
691.232	30.4838
694.666	31.6833
698.099	31.8928
701.528	31.6519
704.958	31.6461
708.387	32.7152
711.814	33.634
715.238	34.7516
718.663	36.0965
722.084	38.2969
725.506	40.639
728.925	43.0597
732.345	45.9512
735.761	48.6224
739.178	50.6728
742.592	52.7765
746.006	54.6323
749.417	58.1269
752.827	59.59
756.236	62.9011
759.645	65.84
763.051	67.3199
766.456	68.2103
769.859	70.667
773.261	72.2763
776.664	72.6252
780.064	73.3803
783.462	74.2128
786.859	74.8175
790.255	77.3834
793.649	79.3352
797.042	80.4247
800.434	80.7194
803.823	82.4776
807.212	84.6973
810.6	85.8721
813.987	86.3481
817.372	87.0459
820.754	86.584
824.137	86.8973
827.519	87.365
830.897	87.0974
834.276	85.2663
837.654	83.8284
841.029	83.3149
844.404	81.3128
847.776	78.8017
851.149	76.933
854.519	73.9193
857.889	71.0539
861.256	67.7644
864.622	64.9953
867.988	61.8119
871.351	60.8667
874.713	58.7079
878.074	56.3062
881.435	52.3794
884.794	49.6541
888.15	50.1289
891.506	48.9377
894.861	48.9311
898.214	48.8985
901.566	48.8872
904.916	47.8979
908.266	49.4168
911.614	49.6584
914.961	48.6226
918.306	47.689
921.651	47.5121
924.994	48.125
928.336	47.9855
931.674	46.1171
935.014	46.9646
938.352	47.0901
941.687	47.1305
945.022	48.7339
948.357	49.4687
951.688	52.0867
955.02	50.0878
958.348	47.8607
961.678	45.3071
965.004	44.6412
968.331	47.0121
971.655	51.3664
974.979	54.3671
978.3	56.8081
981.62	59.2894
984.941	60.0988
988.259	58.7123
991.575	57.8714
994.89	56.3348
998.204	54.8577
1001.52	53.4618
1004.83	54.0947
1008.14	52.3657
1011.45	50.5887
1014.76	48.7404
1018.06	47.5155
1021.37	45.0022
1024.67	43.8519
1027.97	42.0635
1031.27	39.4256
1034.57	35.6061
1037.87	31.7553
1041.17	29.427
1044.47	28.7389
1047.76	29.5043
1051.06	30.1622
1054.35	28.9257
1057.64	27.4348
1060.93	26.7093
1064.22	25.2284
1067.5	22.4973
1070.79	22.2227
1074.08	22.899
1077.36	23.6531
1080.64	22.809
1083.92	21.1475
1087.2	19.8995
1090.48	19.8695
1093.76	21.2064
1097.03	22.5902
1100.31	24.3526
1103.58	25.4581
1106.85	26.7233
1110.12	27.1635
1113.39	26.4139
1116.66	24.393
1119.93	23.4986
1123.19	20.9278
1126.46	18.3681
1129.72	16.3934
1132.98	14.6684
1136.24	13.9739
1139.5	14.0681
1142.76	12.8326
1146.01	13.1742
1149.27	13.8304
1152.53	13.6935
1155.78	12.1293
1159.03	11.091
1162.28	8.98701
1165.53	9.93231
1168.78	11.9479
1172.02	14.481
1175.27	16.4616
1178.51	18.7585
1181.76	19.3339
1185	19.5271
1188.24	21.0317
1191.48	21.8049
1194.71	23.4096
1197.95	25.3344
1201.19	27.5247
1204.42	30.2029
1207.65	34.7418
1210.88	38.1109
1214.12	41.6324
1217.35	44.0045
1220.57	47.4818
1223.8	50.6609
1227.03	53.6259
1230.25	56.2306
1233.47	58.0599
1236.69	59.7762
1239.92	59.8079
1243.13	61.0621
1246.35	62.5986
1249.57	62.6891
1252.78	62.1277
1256	61.7016
1259.21	59.943
1262.42	59.7823
1265.63	59.7813
1268.84	59.1811
1272.05	59.5469
1275.26	60.0429
1278.46	62.0488
1281.67	63.9753
1284.87	66.2131
1288.07	69.6147
1291.27	71.0169
1294.47	73.1682
1297.67	75.4509
1300.87	77.1251
1304.06	79.6152
1307.26	84.3082
1310.45	88.3307
1313.64	90.5479
1316.83	91.3162
1320.02	93.6411
1323.21	95.3345
1326.4	95.2104
1329.59	92.8495
1332.77	92.1134
1335.95	89.7727
1339.14	88.0395
1342.32	85.783
1345.5	82.3512
1348.67	79.8704
1351.85	79.0964
1355.03	77.2967
1358.2	76.5032
1361.38	75.113
1364.55	74.1936
1367.72	71.6905
1370.89	68.4347
1374.06	66.5578
1377.23	65.7616
1380.39	64.1129
1383.56	63.9711
1386.72	62.8916
1389.89	61.9406
1393.05	60.895
1396.21	58.0892
1399.37	55.4404
1402.52	51.556
1405.68	48.8634
1408.84	49.4665
1411.99	50.981
1415.15	53.3361
1418.3	57.0718
1421.45	60.0015
1424.6	65.6667
1427.75	70.7761
1430.89	76.9403
1434.04	82.237
1437.18	88.3009
1440.33	91.3456
1443.47	95.8605
1446.61	98.4831
1449.75	99.8664
1452.89	100.698
1456.03	99.2467
1459.16	97.1755
1462.3	94.4856
1465.43	89.246
1468.56	81.9657
1471.7	76.1435
1474.83	68.0013
1477.96	61.1014
1481.08	54.9811
1484.21	51.7177
1487.34	46.4196
1490.46	41.3244
1493.58	38.5303
1496.71	35.3185
1499.83	32.6762
1502.95	32.3104
1506.07	29.879
1509.18	29.216
1512.3	27.7347
1515.41	28.0875
1518.53	29.0811
1521.64	30.4861
1524.75	30.9057
1527.86	30.94
1530.97	32.7616
1534.08	34.9901
1537.19	37.7301
1540.29	39.1867
1543.4	40.9117
1546.5	44.8716
1549.6	49.2974
1552.7	52.6544
1555.8	54.8392
1558.9	56.4187
1562	59.9561
1565.09	62.0305
1568.19	65.8344
1571.28	69.0053
1574.37	70.8643
1577.47	73.8608
1580.56	75.4688
1583.64	77.698
1586.73	80.7219
1589.82	83.7512
1592.9	86.2765
1595.99	87.4147
1599.07	86.3833
1602.15	85.0165
1605.23	84.9495
1608.31	85.7721
1611.39	85.5343
1614.47	84.5425
1617.55	83.5159
1620.62	82.6338
1623.7	82.4988
1626.77	81.415
1629.84	81.1141
1632.91	82.2585
1635.98	82.5657
1639.05	84.3797
1642.11	85.5091
1645.18	88.0184
1648.24	88.737
1651.31	89.872
1654.37	92.9072
1657.43	94.7688
1660.49	96.353
1663.55	96.5494
1666.61	93.7333
1669.66	90.1568
1672.72	86.8646
1675.77	83.4345
1678.83	79.3936
1681.88	76.3303
1684.93	71.6826
1687.98	66.9915
1691.03	59.5667
1694.07	52.9422
1697.12	48.886
1700.17	44.7902
1703.21	40.2905
1706.25	36.3247
1709.29	31.5384
1712.33	27.6163
1715.37	23.9541
1718.41	21.5954
1721.45	19.6374
1724.49	18.1362
1727.52	16.8508
1730.55	16.4518
1733.59	15.3135
1736.62	13.4917
1739.65	11.6009
1742.68	11.5971
1745.7	10.393
1748.73	10.8623
1751.76	11.1853
1754.78	10.9778
1757.8	10.872
1760.83	10.7
1763.85	9.46324
1766.87	9.39978
1769.89	9.45735
1772.9	10.1255
1775.92	9.29438
1778.94	8.58497
1781.95	7.29791
1784.96	6.50998
1787.97	6.28001
1790.99	6.17792
1794	6.13697
1797	5.92558
1800.01	5.48855
1803.02	4.14484
1806.02	4.21577
1809.03	3.59397
1812.03	3.53501
1815.03	3.59385
1818.03	2.79919
1821.03	2.28652
1824.03	2.79611
1827.03	2.16752
1830.02	2.34577
1833.02	2.29427
1836.01	2.31818
1839.01	2.0887
1842	2.17364
1844.99	3.27087
1847.98	4.4113
1850.97	4.28818
1853.95	4.50329
1856.94	4.98765
1859.93	5.77884
1862.91	5.29441
1865.89	4.95092
1868.87	5.42938
1871.85	6.2621
1874.83	7.07187
1877.81	7.28966
1880.79	9.66115
1882.52	9.29279
1885.51	9.55617
1888.5	8.40043
1891.49	7.84031
1894.47	7.32065
1897.46	6.87086
1900.44	5.50106
1903.42	5.38825
1906.4	5.23458
1909.38	5.78987
1912.36	6.14533
1915.34	6.75044
1918.32	8.03365
1921.29	7.11144
1924.27	6.53173
1927.24	6.676
1930.21	7.57403
1933.18	6.67863
1936.15	5.62135
1939.12	4.70998
1942.09	5.07097
1945.06	5.90712
1948.02	5.73088
1950.99	5.37659
1953.95	5.5801
1956.91	4.67039
1959.88	3.79012
1962.84	2.91796
1965.8	2.34617
1968.75	1.3847
1971.71	0.180433
1974.67	0.402168
1977.62	1.11419
1980.58	1.19222
1983.53	0.890608
1986.48	1.60233
1989.43	2.0634
1992.38	2.07517
1995.33	1.31418
1998.27	2.30025
2001.22	3.7661
2004.16	3.65481
2007.11	3.2369
2010.05	3.16622
2012.99	3.89513
2015.93	4.81303
2018.87	5.71393
2021.81	5.6664
2024.75	6.69572
2027.69	6.23453
2030.62	6.85687
2033.56	6.68402
2036.49	6.39836
2039.42	6.70241
2042.35	7.57302
2045.28	7.85103
2048.21	7.85769
2051.14	7.59587
2054.07	6.9025
2056.99	7.11032
2059.92	6.44092
2062.84	6.97975
2065.76	5.94863
2068.68	6.14032
2071.6	6.13343
2074.52	6.21038
2077.44	4.17409
2080.36	3.78167
2083.27	3.49407
2086.19	3.207
2089.1	1.94309
2092.02	1.35229
2094.93	1.78109
2097.84	1.02742
2100.75	1.14888
2103.66	1.07353
2106.56	1.90565
2109.47	3.02879
2112.38	2.9685
2115.28	3.61947
2118.18	3.25394
2121.09	3.46501
2123.99	3.71614
2126.89	3.00026
2129.79	3.73493
2132.68	4.06784
2135.58	4.45821
2138.48	4.77116
2141.37	5.11833
2144.27	5.12106
2147.16	5.48168
2150.05	5.54568
2152.94	6.4778
2155.83	6.42213
2158.72	6.15522
2161.6	6.77379
2164.49	7.83082
2167.38	7.6469
2170.26	8.07768
2173.14	8.61765
2176.03	8.52902
2178.91	9.28753
2181.79	8.18625
2184.67	8.03858
2187.54	8.20101
2190.42	8.5428
2193.3	9.45225
2196.17	8.82481
2199.05	8.84423
2201.92	9.56716
2204.79	10.1024
2207.66	9.69893
2210.53	9.15895
2213.4	8.57695
2216.27	8.10793
2219.13	8.16675
2222	8.17546
2224.86	8.01737
2227.72	7.77889
2230.59	7.82983
2233.45	8.16172
2236.31	7.75616
2239.17	7.86562
2242.03	6.94484
2244.88	6.97238
2247.74	6.48627
2250.59	5.16655
2253.45	5.72481
2256.3	5.57878
2259.15	6.25835
2262	6.14192
2264.85	5.16946
2267.7	5.51838
2270.55	6.06219
2273.4	6.49145
2276.24	6.51924
2279.09	5.03927
2281.93	4.75548
2284.77	4.82948
2287.62	4.99684
2290.46	5.88564
2293.3	5.59751
2296.13	6.71915
2298.97	7.82629
2301.81	8.85061
2304.64	9.741
2307.48	9.85325
2310.31	10.6424
2313.14	11.074
2315.98	10.7288
2318.81	10.207
2321.64	10.1174
2324.46	10.422
2327.29	10.0792
2330.12	10.0129
2332.94	9.3994
2335.77	8.66847
2338.59	8.25596
2341.41	7.43247
2344.23	6.79987
2347.05	5.0286
2349.87	2.97428
2352.69	1.63909
2355.51	1.35776
2358.32	1.08452
2361.14	0.62472
2363.95	0.915866
2366.76	1.91838
2369.58	2.57073
2372.39	3.16688
2375.2	3.68242
2378	4.01626
2380.81	3.76385
2383.62	3.02053
2386.43	3.08925
2389.23	3.77419
2392.03	4.52999
2394.84	4.23398
2397.64	4.44327
2400.44	4.37607
2403.24	4.92126
2406.04	4.98598
2408.84	5.79201
2411.63	7.07271
2414.43	6.29328
2417.22	6.62708
2420.02	7.64098
2422.81	8.22221
2425.6	9.47191
2428.39	9.27847
2431.18	9.84953
2433.97	9.44751
2436.76	9.48474
2439.54	9.13122
2442.33	8.72188
2445.12	7.69623
2447.9	6.2959
2450.68	5.54318
2453.46	4.86717
2456.24	3.99535
2459.02	2.59318
2461.8	1.11052
2464.58	0.848204
2467.36	1.22563
2470.13	1.80084
2472.91	1.47644
2475.68	1.59024
2478.45	2.29426
2481.23	2.48962
2484	2.53209
2486.77	4.28901
2489.54	4.73239
2492.3	4.03777
2495.07	4.53749
2497.84	4.41273
2500.6	5.16052
2503.36	4.0874
2506.13	3.77369
2508.89	3.59277
2511.65	3.32133
2514.41	4.47417
2517.17	4.2917
2519.93	3.93136
2522.68	4.62111
2525.44	4.04603
2528.19	4.46875
2530.95	5.45168
2533.7	5.9856
2536.45	6.01288
2539.2	5.89406
2541.95	5.43697
2544.7	6.14947
2547.45	5.79054
2550.2	5.50446
2552.94	6.64385
2555.69	6.78105
2558.43	6.3531
2561.18	6.38595
2563.92	5.86869
2566.66	5.34984
2569.4	5.34977
2572.14	5.01618
2574.88	4.07605
2577.61	3.01189
2580.35	3.22731
2583.09	3.95798
2585.82	3.59908
2588.55	3.74192
2591.29	2.74343
2594.02	1.32689
2596.75	1.57312
2599.48	1.33739
2602.21	0.316507
2604.93	-0.454328
2607.66	-0.333608
2610.39	-0.0639471
2613.11	0.0166075
2615.83	0.243023
2618.56	0.701144
2621.28	0.942804
2624	1.64086
2626.72	1.94569
2629.44	1.70078
2632.15	1.25423
2634.87	1.9344
2637.59	1.4912
2640.3	1.15948
2643.02	1.55667
2645.73	3.1857
2648.44	4.36033
2651.15	4.61757
2653.86	5.20849
2656.57	4.7851
2659.28	5.6364
2661.99	5.64271
2664.69	5.70137
2667.4	5.61326
2670.1	5.65148
2672.81	5.37794
2675.51	5.17775
2678.21	4.59079
2680.91	4.62318
2683.61	3.96039
2686.31	3.73183
2689	3.36039
2691.7	2.42137
2694.4	1.60607
2697.09	1.63296
2699.79	2.04346
2702.48	2.65236
2705.17	3.8304
2707.86	5.90479
2710.55	7.94116
2713.24	9.25053
2715.93	9.5799
2718.62	11.1565
2721.3	12.3669
2723.99	12.9271
2726.67	12.2308
2729.35	12.1667
2732.04	11.7987
2734.72	11.0745
2737.4	10.363
2740.08	9.77526
2742.76	9.29099
2745.43	8.23067
2748.11	7.64695
2750.79	6.72246
2753.46	5.64224
2756.14	4.65453
2758.81	4.08965
2761.48	3.98753
2764.15	3.09446
2766.82	3.1402
2769.49	2.96128
2772.16	3.05701
2774.82	3.15835
2777.49	2.70038
2780.16	1.85215
2782.82	1.63018
2785.48	1.61152
2788.15	1.34103
2790.81	0.310634
2793.47	-0.243271
2796.13	-0.662296
2798.79	-0.462275
2801.44	-0.436138
2804.1	-0.447254
2806.76	-0.350505
2809.41	0.462147
2812.07	0.752809
2814.72	1.26284
2817.37	2.37433
2820.02	3.71769
2822.67	5.07362
2825.32	7.03114
2827.97	8.98846
2830.62	12.2924
2833.26	15.0967
2835.91	18.6715
2838.56	22.7165
2841.2	28.2619
2843.84	34.6591
2846.48	42.906
2849.12	52.4077
2851.77	62.6148
2854.4	72.3292
2857.04	83.0027
2859.68	93.0987
2862.32	103.544
2864.95	112.899
2867.59	122.701
2870.22	131.615
2872.85	139.722
2875.48	145.885
2878.11	151.619
2880.74	156.319
2883.37	160.641
2886	164.727
2888.63	167.632
2891.25	171.49
2893.88	175.109
2896.5	178.906
2899.13	184.958
2901.75	191.657
2904.37	200.784
2906.99	210.351
2909.61	221.281
2912.23	233.75
2914.85	246.755
2917.46	258.408
2920.08	269.779
2922.7	279.024
2925.31	285.514
2927.92	290.604
2930.54	293.184
2933.15	294.446
2935.76	291.826
2938.37	287.19
2940.98	281.882
2943.58	273.799
2946.19	264.878
2948.8	255.297
2951.4	244.873
2954.01	234.199
2956.61	223.077
2959.21	212.232
2961.81	201.586
2964.41	191.606
2967.01	182.21
2969.61	173.218
2972.21	164.496
2974.81	156.266
2977.4	148.364
2980	139.709
2982.59	129.833
2985.18	119.264
2987.78	108.706
2990.37	99.2548
2992.96	88.893
2995.55	79.4495
2998.14	69.9522
3000.73	60.7773
3003.31	53.3704
3005.9	46.5228
3008.48	39.8564
3011.07	34.4951
3013.65	30.1435
3016.23	25.3745
3018.81	21.6281
3021.4	18.2384
3023.97	16.5721
3026.55	15.1276
3029.13	13.4881
3031.71	12.2066
3034.28	11.0642
3036.86	11.0636
3039.43	11.7648
3042.01	12.1214
3044.58	13.1688
3047.15	13.8612
3049.72	16.1611
3052.29	17.6896
3054.86	19.5809
3057.43	19.9493
3060	20.5486
3062.56	20.3607
3065.13	21.5113
3067.69	21.1782
3070.26	19.5522
3072.82	18.1366
3075.38	16.9169
3077.94	14.2487
3080.5	11.8258
3083.06	10.1482
3085.62	8.31572
3088.18	5.96876
3090.73	3.29294
3093.29	1.22798
3095.84	0.616972
3098.4	0.451739
3100.95	-0.389629
3103.5	-0.0170042
3106.05	0.853406
3108.6	2.73724
3111.15	4.13589
3113.7	5.68229
3116.25	7.0823
3118.79	8.60538
3121.34	9.85641
3123.88	11.5967
3126.43	13.1264
3128.97	14.83
3131.51	15.906
3134.06	17.3744
3136.6	19.4086
3139.14	20.4501
3141.67	21.5849
3144.21	22.9389
3146.75	23.9048
3149.29	25.5719