File: data/Raman/poly_smoothed/Thy_00_07_13_1x_45s_532 nm_x100_100%_600 gr_mm_01.txt
#Acq. time (s)=	45
#Accumulations=	2
#Range (cm-¹)=	200...3150
#Windows=	2
#Auto scanning=	Off
#Autofocus=	Off
#Macrospot=	Off
#AutoExposure=	Off
#Spike filter=	Multiple accum.
#Delay time (s)=	0
#Binning=	1
#Readout mode=	Signal
#DeNoise=	Off
#ICS correction=	On
#Dark correction=	Off
#Inst. Process=	Off
#Detector Gain=	Best Dynamic Range
#Detector ADC=	20 kHz
#Detector temperature (°C)=	-69.85
#Instrument=	LabRAM HR Evol
#Detector=	Synapse
#Objective=	x100
#Grating=	600 gr/mm
#ND Filter=	100%
#Laser (nm)=	532
#Hole=	100.021
#Range=	Auto
#Laser Pol.=	No
#Raman. Pol.=	No
#Laser Pol. (°)=	-0.0007625
#Raman Pol. (°)=	89.9995
#Collection=	Microscope
#StageXY=	Marzhauser
#StageZ=	Marzhauser
#X (µm)=	9026
#Y (µm)=	-3091.3
#Z (µm)=	-55.25
#Full time(mm:ss)=	3:18
#Project=
#Sample=
#Site=
#Title=	Thy_00_07_13_2x_45s_532 nm_x100_100%_600 gr_mm
#Remark=
#Date=	28.06.2022 11:01
#Acquired=	28.06.2022 11:01:05
#Base:Fit=	10.08.2022 10:06:44
#Base:Fit=	10.08.2022 10:07:16
#Base:Fit=	10.08.2022 10:07:25
#Base:Fit=	10.08.2022 10:07:44
#Base:Fit=	10.08.2022 10:07:56
#Base:Sub=	10.08.2022 10:08:40
#Filter:Polynom=	16.08.2022 10:26:06
#AxisType[0]=Intens
#AxisUnit[0]=Cnt
#AxisType[1]=Spectr
#AxisUnit[1]=1/cm
200.407	4.30302
204.035	6.12723
207.665	7.5182
211.291	8.62781
214.916	10.5069
218.541	11.4772
222.163	11.7945
225.785	11.8737
229.404	10.4012
233.022	11.8155
236.638	10.7022
240.255	10.8279
243.868	10.0753
247.48	10.4768
251.091	10.4951
254.702	11.597
258.31	12.0506
261.916	10.8872
265.521	10.7824
269.125	11.4437
272.727	11.5044
276.328	10.3096
279.927	9.30182
283.525	8.36882
287.121	8.09381
290.716	9.83652
294.31	9.79928
297.9	9.89347
301.491	10.2148
305.081	10.1506
308.669	8.86656
312.256	10.6036
315.839	11.0966
319.423	11.8388
323.006	12.2718
326.585	12.0733
330.165	13.5429
333.741	14.0306
337.318	15.1452
340.894	14.7467
344.466	13.1462
348.039	14.1879
351.608	14.3585
355.176	15.1015
358.745	14.3445
362.31	13.4151
365.876	12.7126
369.439	12.6743
373	12.7945
376.56	11.9793
380.12	10.7221
383.677	8.70864
387.233	6.20162
390.787	6.70549
394.34	6.66747
397.894	7.26296
401.444	7.77567
404.993	6.77649
408.54	6.20682
412.086	4.83305
415.631	6.86535
419.174	5.92961
422.716	3.72312
426.257	2.9488
429.794	4.4354
433.332	4.90294
436.868	6.29074
440.403	7.95857
443.937	9.25011
447.468	10.6473
450.999	12.5042
454.528	14.8192
458.057	15.916
461.582	17.1375
465.107	18.0737
468.629	18.6912
472.152	20.2155
475.672	22.1272
479.192	23.8385
482.709	26.2402
486.226	26.7187
489.74	28.5889
493.255	30.2379
496.767	31.5187
500.277	32.3665
503.788	31.9218
507.295	29.6452
510.801	28.1549
514.308	28.3587
517.811	29.0091
521.313	28.5191
524.814	28.9295
528.313	28.4751
531.811	28.7935
535.308	28.6201
538.803	29.6431
542.297	28.2112
545.789	26.2848
549.281	25.9683
552.771	24.3178
556.259	22.3359
559.747	19.7916
563.233	21.3623
566.717	20.3975
570.2	19.8259
573.68	19.6217
577.161	18.0178
580.64	16.2343
584.118	15.4915
587.593	12.5107
591.068	11.0793
594.54	11.1066
598.013	10.6732
601.484	10.9198
604.952	11.3857
608.421	11.3476
611.886	12.8631
615.35	13.0609
618.815	15.0322
622.276	14.9729
625.738	14.8082
629.197	13.8785
632.655	12.4467
636.113	12.2662
639.568	12.2183
643.021	11.2694
646.473	12.2867
649.924	13.0127
653.376	12.8912
656.824	13.267
660.271	12.5801
663.716	13.7166
667.161	13.4803
670.604	14.2308
674.045	15.7553
677.486	16.1602
680.925	17.7203
684.361	20.9598
687.797	24.1569
691.232	26.0794
694.666	28.4177
698.099	29.901
701.528	33.0549
704.958	33.3985
708.387	31.562
711.814	33.1277
715.238	33.3586
718.663	34.4437
722.084	35.7722
725.506	36.5636
728.925	37.3207
732.345	39.0496
735.761	42.1859
739.178	43.4936
742.592	45.04
746.006	49.6087
749.417	52.6451
752.827	56.3298
756.236	62.2923
759.645	64.4392
763.051	66.8894
766.456	70.5698
769.859	73.3983
773.261	75.2673
776.664	75.9297
780.064	77.7132
783.462	77.551
786.859	76.8458
790.255	75.5822
793.649	73.3259
797.042	72.7892
800.434	70.9763
803.823	69.1465
807.212	67.1566
810.6	66.2416
813.987	66.2031
817.372	66.2211
820.754	67.0723
824.137	66.9632
827.519	67.6929
830.897	70.3183
834.276	70.3521
837.654	69.3836
841.029	67.6355
844.404	64.8352
847.776	62.1786
851.149	61.5751
854.519	59.7251
857.889	57.4524
861.256	54.2829
864.622	53.0348
867.988	50.5069
871.351	48.5012
874.713	46.3758
878.074	42.7813
881.435	41.3101
884.794	41.3415
888.15	39.1819
891.506	37.8504
894.861	37.7484
898.214	38.099
901.566	38.2371
904.916	38.783
908.266	37.9732
911.614	37.662
914.961	38.8703
918.306	37.6063
921.651	36.7852
924.994	37.1579
928.336	36.7458
931.674	37.408
935.014	37.4297
938.352	36.7308
941.687	34.8846
945.022	32.6068
948.357	33.0132
951.688	31.7971
955.02	31.5281
958.348	27.5803
961.678	25.0655
965.004	25.4225
968.331	26.3405
971.655	27.7079
974.979	28.9489
978.3	31.6071
981.62	32.1903
984.941	33.356
988.259	33.0089
991.575	33.6682
994.89	35.9449
998.204	38.9032
1001.52	41.6381
1004.83	45.1407
1008.14	47.5302
1011.45	48.435
1014.76	48.7133
1018.06	48.1005
1021.37	46.9823
1024.67	45.9468
1027.97	44.8178
1031.27	42.5994
1034.57	38.3645
1037.87	34.1263
1041.17	31.9261
1044.47	31.4321
1047.76	29.977
1051.06	27.1916
1054.35	25.3476
1057.64	22.872
1060.93	20.7716
1064.22	18.2129
1067.5	17.101
1070.79	16.3871
1074.08	17.5737
1077.36	18.5713
1080.64	18.1788
1083.92	19.5948
1087.2	18.9731
1090.48	20.2818
1093.76	21.092
1097.03	24.1363
1100.31	28.091
1103.58	30.2412
1106.85	30.7372
1110.12	30.0927
1113.39	28.6133
1116.66	27.6887
1119.93	28.1336
1123.19	26.5651
1126.46	25.2191
1129.72	23.3599
1132.98	23.3799
1136.24	23.7276
1139.5	23.4117
1142.76	24.0256
1146.01	23.7734
1149.27	22.4997
1152.53	22.3456
1155.78	19.656
1159.03	18.3235
1162.28	15.3566
1165.53	15.1072
1168.78	16.1305
1172.02	19.6968
1175.27	21.6113
1178.51	25.0274
1181.76	25.1959
1185	25.3477
1188.24	24.1374
1191.48	25.4065
1194.71	26.6852
1197.95	27.622
1201.19	30.6284
1204.42	33.1047
1207.65	35.647
1210.88	37.8622
1214.12	41.2085
1217.35	45.4487
1220.57	47.6846
1223.8	49.4933
1227.03	51.5366
1230.25	53.4296
1233.47	54.0638
1236.69	54.1247
1239.92	54.6302
1243.13	55.5517
1246.35	57.7479
1249.57	58.0093
1252.78	58.0786
1256	56.6402
1259.21	57.1817
1262.42	56.2987
1265.63	55.6652
1268.84	58.1719
1272.05	57.8501
1275.26	57.8999
1278.46	62.1089
1281.67	65.2698
1284.87	68.7331
1288.07	71.4393
1291.27	75.0274
1294.47	79.5992
1297.67	85.7407
1300.87	91.7619
1304.06	95.7132
1307.26	100.47
1310.45	105.662
1313.64	110.42
1316.83	112.825
1320.02	114.737
1323.21	114.859
1326.4	112.826
1329.59	111.701
1332.77	110.995
1335.95	109.773
1339.14	108.027
1342.32	105.334
1345.5	102.767
1348.67	100.438
1351.85	96.2165
1355.03	93.4831
1358.2	93.008
1361.38	89.7105
1364.55	86.7875
1367.72	85.5314
1370.89	85.9394
1374.06	85.0582
1377.23	84.9638
1380.39	84.9057
1383.56	83.0111
1386.72	82.5807
1389.89	81.3018
1393.05	79.1182
1396.21	75.3537
1399.37	72.308
1402.52	72.4067
1405.68	72.5918
1408.84	75.8647
1411.99	78.7313
1415.15	80.594
1418.3	84.232
1421.45	88.4299
1424.6	93.4575
1427.75	99.5366
1430.89	104.313
1434.04	109.674
1437.18	116.308
1440.33	119.163
1443.47	122.323
1446.61	124.821
1449.75	125.269
1452.89	123.973
1456.03	122.703
1459.16	116.821
1462.3	110.634
1465.43	103.428
1468.56	94.4861
1471.7	85.3989
1474.83	77.9346
1477.96	70.3209
1481.08	64.0977
1484.21	57.7136
1487.34	51.6609
1490.46	44.7805
1493.58	39.119
1496.71	35.6583
1499.83	32.7962
1502.95	31.8287
1506.07	32.3493
1509.18	33.368
1512.3	33.5979
1515.41	33.359
1518.53	34.6231
1521.64	35.686
1524.75	36.0227
1527.86	38.9333
1530.97	40.3746
1534.08	43.7279
1537.19	45.4253
1540.29	48.6096
1543.4	51.6578
1546.5	54.1508
1549.6	58.8441
1552.7	63.9286
1555.8	69.4919
1558.9	74.3288
1562	78.6375
1565.09	83.3995
1568.19	87.2021
1571.28	91.9803
1574.37	97.2466
1577.47	100.194
1580.56	103.963
1583.64	106.848
1586.73	108.382
1589.82	108.838
1592.9	109.197
1595.99	108.2
1599.07	105.205
1602.15	104.503
1605.23	103.022
1608.31	100.821
1611.39	98.6024
1614.47	96.8541
1617.55	95.3983
1620.62	94.7652
1623.7	93.6565
1626.77	94.4304
1629.84	95.0126
1632.91	96.1374
1635.98	96.9598
1639.05	98.533
1642.11	100.205
1645.18	100.611
1648.24	102.109
1651.31	101.639
1654.37	102.314
1657.43	101.885
1660.49	100.771
1663.55	97.4048
1666.61	94.4349
1669.66	90.1975
1672.72	84.6078
1675.77	79.8496
1678.83	75.9695
1681.88	68.4531
1684.93	62.3049
1687.98	55.6202
1691.03	48.955
1694.07	42.0405
1697.12	34.9472
1700.17	29.2813
1703.21	24.0699
1706.25	19.6938
1709.29	16.0718
1712.33	13.6378
1715.37	10.5432
1718.41	8.52981
1721.45	7.58675
1724.49	7.38449
1727.52	6.58711
1730.55	8.06164
1733.59	8.21867
1736.62	8.29405
1739.65	8.88183
1742.68	9.26944
1745.7	10.8744
1748.73	11.3051
1751.76	11.9755
1754.78	11.7651
1757.8	10.114
1760.83	10.575
1763.85	9.11863
1766.87	9.07754
1769.89	8.65415
1772.9	7.14311
1775.92	7.42074
1778.94	7.33846
1781.95	7.24111
1784.96	6.60677
1787.97	6.67167
1790.99	6.50723
1794	7.1283
1797	6.67617
1800.01	7.9381
1803.02	7.0899
1806.02	6.85922
1809.03	7.2425
1812.03	7.15908
1815.03	6.91715
1818.03	6.49502
1821.03	6.70961
1824.03	6.50082
1827.03	5.19329
1830.02	5.15688
1833.02	5.06766
1836.01	4.13287
1839.01	3.87748
1842	3.73411
1844.99	2.60461
1847.98	2.31262
1850.97	3.55811
1853.95	3.65363
1856.94	3.405
1859.93	4.92059
1862.91	6.35127
1865.89	6.85772
1868.87	7.16904
1871.85	6.9831
1874.83	6.08107
1877.81	5.39017
1880.79	5.81684
1882.52	5.31568
1885.51	5.18619
1888.5	5.12805
1891.49	4.79348
1894.47	4.19682
1897.46	4.4098
1900.44	4.00083
1903.42	4.43882
1906.4	3.08698
1909.38	3.1532
1912.36	2.89747
1915.34	2.2736
1918.32	1.18402
1921.29	1.98629
1924.27	1.76211
1927.24	1.45329
1930.21	2.70051
1933.18	2.87614
1936.15	1.85231
1939.12	1.65708
1942.09	1.81841
1945.06	1.50128
1948.02	2.07522
1950.99	2.31631
1953.95	2.57034
1956.91	2.79169
1959.88	2.90113
1962.84	3.2216
1965.8	2.61837
1968.75	3.27881
1971.71	3.43066
1974.67	4.53286
1977.62	3.65617
1980.58	4.22147
1983.53	3.91306
1986.48	4.89602
1989.43	4.61555
1992.38	5.55428
1995.33	5.84719
1998.27	6.36626
2001.22	6.80741
2004.16	7.08695
2007.11	6.20585
2010.05	5.57609
2012.99	6.23206
2015.93	6.76461
2018.87	7.08925
2021.81	6.66082
2024.75	5.8851
2027.69	5.98883
2030.62	4.99373
2033.56	4.73649
2036.49	4.69493
2039.42	4.62439
2042.35	4.53545
2045.28	4.88075
2048.21	5.22578
2051.14	5.85801
2054.07	5.69872
2056.99	6.98481
2059.92	7.53946
2062.84	6.99188
2065.76	6.86174
2068.68	7.24125
2071.6	5.85362
2074.52	4.50723
2077.44	3.34467
2080.36	2.91998
2083.27	3.76371
2086.19	3.87487
2089.1	3.82497
2092.02	3.68256
2094.93	2.8776
2097.84	3.9248
2100.75	3.30495
2103.66	3.76607
2106.56	5.52938
2109.47	6.38444
2112.38	6.42789
2115.28	7.16689
2118.18	7.19135
2121.09	7.60296
2123.99	8.24677
2126.89	8.76046
2129.79	8.50858
2132.68	9.15998
2135.58	9.12084
2138.48	8.97166
2141.37	9.08053
2144.27	8.89285
2147.16	8.83274
2150.05	8.2157
2152.94	8.65388
2155.83	8.37158
2158.72	8.34807
2161.6	8.62855
2164.49	8.64086
2167.38	9.53436
2170.26	10.3774
2173.14	10.9635
2176.03	11.5093
2178.91	11.4744
2181.79	11.4269
2184.67	11.1022
2187.54	10.7261
2190.42	11.3137
2193.3	11.9179
2196.17	12.871
2199.05	12.8655
2201.92	13.1684
2204.79	12.798
2207.66	12.2734
2210.53	11.7517
2213.4	12.5507
2216.27	11.8954
2219.13	11.6745
2222	11.7439
2224.86	12.2808
2227.72	12.1607
2230.59	11.7358
2233.45	11.2438
2236.31	10.6516
2239.17	11.3379
2242.03	11.2668
2244.88	10.9754
2247.74	10.7386
2250.59	9.66317
2253.45	9.98212
2256.3	10.6886
2259.15	10.8502
2262	10.3546
2264.85	10.3916
2267.7	10.8012
2270.55	9.70129
2273.4	8.56864
2276.24	8.06056
2279.09	7.28867
2281.93	7.48854
2284.77	7.74857
2287.62	7.31072
2290.46	7.06514
2293.3	5.69952
2296.13	6.76552
2298.97	6.47608
2301.81	7.29955
2304.64	8.03035
2307.48	7.5611
2310.31	8.1969
2313.14	7.56859
2315.98	7.07198
2318.81	7.57467
2321.64	7.84132
2324.46	7.18233
2327.29	6.62622
2330.12	6.73091
2332.94	7.15434
2335.77	7.46139
2338.59	6.50193
2341.41	5.54489
2344.23	5.08521
2347.05	4.18357
2349.87	4.7103
2352.69	4.89148
2355.51	4.36617
2358.32	3.61666
2361.14	4.17798
2363.95	5.65287
2366.76	5.51891
2369.58	5.38273
2372.39	4.14433
2375.2	3.88411
2378	3.94316
2380.81	3.68015
2383.62	2.64223
2386.43	1.90793
2389.23	1.48159
2392.03	1.44492
2394.84	1.14988
2397.64	1.98378
2400.44	1.53529
2403.24	1.93516
2406.04	2.23127
2408.84	2.96471
2411.63	3.40488
2414.43	4.80288
2417.22	6.08952
2420.02	6.33033
2422.81	7.52037
2425.6	8.92747
2428.39	9.40066
2431.18	9.59006
2433.97	9.06253
2436.76	8.4836
2439.54	8.87718
2442.33	7.33915
2445.12	8.12374
2447.9	6.75051
2450.68	4.93289
2453.46	3.83264
2456.24	3.22916
2459.02	2.57516
2461.8	2.74221
2464.58	2.74083
2467.36	1.88281
2470.13	1.77777
2472.91	1.91552
2475.68	2.18801
2478.45	1.19508
2481.23	0.912547
2484	1.65121
2486.77	2.68098
2489.54	3.40046
2492.3	4.92114
2495.07	5.44009
2497.84	4.69501
2500.6	4.5823
2503.36	4.24181
2506.13	3.9508
2508.89	3.89775
2511.65	4.1844
2514.41	4.51927
2517.17	3.16352
2519.93	3.46454
2522.68	3.285
2525.44	3.00278
2528.19	4.418
2530.95	3.72732
2533.7	4.0599
2536.45	3.32427
2539.2	1.69796
2541.95	2.24708
2544.7	2.82283
2547.45	3.64903
2550.2	4.51061
2552.94	4.58906
2555.69	5.19895
2558.43	5.45053
2561.18	4.30656
2563.92	4.9343
2566.66	5.29754
2569.4	5.11423
2572.14	5.38887
2574.88	4.73486
2577.61	4.72338
2580.35	4.52876
2583.09	5.14324
2585.82	5.07668
2588.55	4.56395
2591.29	3.07537
2594.02	2.922
2596.75	3.07073
2599.48	2.46641
2602.21	3.38582
2604.93	1.84159
2607.66	2.67768
2610.39	3.39974
2613.11	3.31015
2615.83	3.38177
2618.56	3.47027
2621.28	3.06015
2624	2.94193
2626.72	3.25183
2629.44	4.10995
2632.15	4.21378
2634.87	3.94096
2637.59	4.1474
2640.3	2.84628
2643.02	3.90565
2645.73	3.73091
2648.44	4.55737
2651.15	3.9353
2653.86	3.01773
2656.57	2.46579
2659.28	1.93481
2661.99	2.19598
2664.69	2.08791
2667.4	2.44432
2670.1	2.83373
2672.81	2.60104
2675.51	3.14047
2678.21	4.286
2680.91	4.66686
2683.61	5.96972
2686.31	6.67249
2689	7.30621
2691.7	8.27301
2694.4	8.07538
2697.09	8.65439
2699.79	9.17151
2702.48	10.5205
2705.17	10.8598
2707.86	11.6957
2710.55	12.389
2713.24	12.8806
2715.93	13.2427
2718.62	13.3932
2721.3	11.8565
2723.99	10.7723
2726.67	10.165
2729.35	9.34405
2732.04	9.0894
2734.72	7.90471
2737.4	7.38322
2740.08	7.32866
2742.76	7.06429
2745.43	6.71062
2748.11	6.3269
2750.79	6.55164
2753.46	6.8614
2756.14	5.51399
2758.81	4.3434
2761.48	4.26355
2764.15	4.25669
2766.82	4.12524
2769.49	4.20419
2772.16	4.11991
2774.82	3.77343
2777.49	2.75569
2780.16	2.61088
2782.82	2.90945
2785.48	2.23332
2788.15	2.03383
2790.81	2.16889
2793.47	2.02821
2796.13	1.00958
2798.79	0.752444
2801.44	0.235286
2804.1	0.673243
2806.76	-0.1281
2809.41	-0.795308
2812.07	0.220772
2814.72	0.970339
2817.37	1.48764
2820.02	3.50457
2822.67	6.5663
2825.32	10.5469
2827.97	15.1598
2830.62	19.7659
2833.26	24.015
2835.91	29.4834
2838.56	35.8599
2841.2	43.4895
2843.84	53.2593
2846.48	62.9573
2849.12	75.9015
2851.77	87.9591
2854.4	99.5584
2857.04	110.787
2859.68	121.494
2862.32	132.86
2864.95	142.74
2867.59	152.443
2870.22	160.598
2872.85	168.773
2875.48	177.073
2878.11	184.283
2880.74	190.323
2883.37	197.48
2886	204.335
2888.63	209.488
2891.25	215.714
2893.88	221.084
2896.5	227.361
2899.13	234.868
2901.75	242.46
2904.37	251.496
2906.99	262.997
2909.61	273.796
2912.23	286.317
2914.85	298.974
2917.46	308.681
2920.08	317.613
2922.7	324.956
2925.31	330.209
2927.92	333.497
2930.54	333.49
2933.15	332.776
2935.76	328.221
2938.37	322.284
2940.98	314.641
2943.58	305.53
2946.19	294.821
2948.8	283.982
2951.4	271.893
2954.01	259.171
2956.61	249.001
2959.21	237.466
2961.81	226.252
2964.41	214.339
2967.01	203.81
2969.61	193.538
2972.21	184.481
2974.81	174.787
2977.4	164.875
2980	155.066
2982.59	144.678
2985.18	133.779
2987.78	121.935
2990.37	111.268
2992.96	100.191
2995.55	89.5404
2998.14	78.8489
3000.73	67.7595
3003.31	57.9136
3005.9	48.7689
3008.48	40.3018
3011.07	33.4699
3013.65	25.9854
3016.23	21.1661
3018.81	17.2606
3021.4	13.7968
3023.97	10.9234
3026.55	7.62133
3029.13	6.98529
3031.71	5.94745
3034.28	5.32669
3036.86	6.71441
3039.43	7.72682
3042.01	8.98537
3044.58	10.3546
3047.15	12.8365
3049.72	15.0064
3052.29	16.7143
3054.86	18.1965
3057.43	19.0419
3060	18.4944
3062.56	18.2978
3065.13	16.9985
3067.69	15.8568
3070.26	14.7565
3072.82	12.7587
3075.38	11.3316
3077.94	9.53697
3080.5	7.60512
3083.06	6.15725
3085.62	4.02886
3088.18	2.39271
3090.73	1.54927
3093.29	0.37402
3095.84	-1.27097
3098.4	-1.75972
3100.95	-0.752351
3103.5	-0.952677
3106.05	-0.566795
3108.6	0.182983
3111.15	0.745167
3113.7	1.22444
3116.25	2.82277
3118.79	4.0387
3121.34	5.50861
3123.88	7.44713
3126.43	9.94936
3128.97	11.4414
3131.51	13.4223
3134.06	16.5073
3136.6	19.3437
3139.14	22.517
3141.67	26.1235
3144.21	29.1492
3146.75	32.0735
3149.29	35.3053