File: data/Raman/poly_smoothed/Thy_10_08_33_1x_45s_532 nm_x100_100%_600 gr_mm_01.txt
#Acq. time (s)=	45
#Accumulations=	2
#Range (cm-¹)=	200...3150
#Windows=	2
#Auto scanning=	Off
#Autofocus=	Off
#Macrospot=	Off
#AutoExposure=	Off
#Spike filter=	Multiple accum.
#Delay time (s)=	0
#Binning=	1
#Readout mode=	Signal
#DeNoise=	Off
#ICS correction=	On
#Dark correction=	Off
#Inst. Process=	Off
#Detector Gain=	Best Dynamic Range
#Detector ADC=	20 kHz
#Detector temperature (°C)=	-69.85
#Instrument=	LabRAM HR Evol
#Detector=	Synapse
#Objective=	x100
#Grating=	600 gr/mm
#ND Filter=	100%
#Laser (nm)=	532
#Hole=	100.021
#Range=	Auto
#Laser Pol.=	No
#Raman. Pol.=	No
#Laser Pol. (°)=	-0.0007625
#Raman Pol. (°)=	89.9995
#Collection=	Microscope
#StageXY=	Marzhauser
#StageZ=	Marzhauser
#X (µm)=	2183.2
#Y (µm)=	1230.6
#Z (µm)=	442.2
#Full time(mm:ss)=	3:18
#Project=
#Sample=
#Site=
#Title=	Thy_10_08_33_2x_45s_532 nm_x100_100%_600 gr_mm
#Remark=
#Date=	05.07.2022 16:37
#Acquired=	05.07.2022 16:37:18
#Base:Fit=	10.08.2022 09:46:25
#Base:Sub=	10.08.2022 09:46:49
#Filter:Polynom=	16.08.2022 10:24:56
#AxisType[0]=Intens
#AxisUnit[0]=Cnt
#AxisType[1]=Spectr
#AxisUnit[1]=1/cm
200.43	5.34133
204.059	12.3479
207.688	15.4583
211.314	16.8971
214.941	18.1011
218.564	18.9785
222.186	20.3966
225.809	20.7298
229.428	21.7383
233.045	21.9602
236.663	24.0725
240.278	24.5696
243.891	25.4955
247.503	25.7323
251.116	24.4192
254.725	24.6815
258.333	25.7895
261.939	28.3144
265.544	30.1994
269.148	30.5972
272.75	31.0113
276.351	32.6268
279.95	32.5962
283.548	33.2469
287.144	33.8161
290.739	33.4252
294.333	33.5076
297.925	33.5493
301.514	33.2333
305.104	34.2263
308.692	33.3419
312.279	33.4406
315.862	31.8007
319.446	31.7112
323.029	32.0003
326.608	31.3864
330.188	30.7354
333.766	30.7722
337.341	29.9852
340.917	29.11
344.489	27.3613
348.062	27.5299
351.631	26.2791
355.201	25.1627
358.768	23.4156
362.333	23.3281
365.899	22.9383
369.462	23.2356
373.023	22.7801
376.585	22.9055
380.143	22.9585
383.7	23.0327
387.256	23.4626
390.812	23.3646
394.365	23.1735
397.916	23.369
401.467	24.5137
405.015	23.5559
408.563	23.3911
412.109	22.9373
415.654	22.0292
419.197	21.8991
422.739	19.9859
426.279	19.0343
429.819	17.1936
433.356	16.9915
436.891	15.6086
440.426	14.4803
443.96	12.8782
447.492	12.1838
451.021	11.6646
454.551	12.0034
458.079	13.2429
461.604	12.968
465.13	14.4334
468.654	15.2915
472.175	16.8349
475.696	18.3602
479.215	19.7041
482.733	21.5876
486.249	22.561
489.765	23.146
493.278	24.3484
496.789	24.9177
500.301	25.7387
503.81	25.9837
507.317	25.7015
510.825	25.6692
514.33	25.6676
517.833	24.904
521.335	24.4074
524.836	24.6603
528.335	22.6424
531.835	21.0604
535.332	21.1824
538.827	21.255
542.321	20.9411
545.814	19.5508
549.305	18.8628
552.795	18.5514
556.282	18.4442
559.769	19.3238
563.255	19.1175
566.739	17.5842
570.223	15.9815
573.705	14.9466
577.183	13.7947
580.663	11.4087
584.141	10.9861
587.615	10.8624
591.09	10.1132
594.564	9.53275
598.035	8.72203
601.506	8.04794
604.974	7.98056
608.443	8.245
611.908	9.01005
615.374	9.13732
618.837	10.7676
622.3	11.3062
625.761	12.3786
629.219	13.4832
632.677	14.7281
636.135	16.3167
639.59	16.9534
643.043	17.8784
646.495	19.2483
649.948	19.4019
653.398	19.1283
656.846	18.6048
660.293	19.9982
663.738	21.2695
667.183	22.4906
670.626	25.4834
674.067	25.4724
677.508	25.4054
680.947	26.838
684.385	27.7484
687.821	29.447
691.254	31.0547
694.688	32.9628
698.121	33.9231
701.552	33.5523
704.98	34.5283
708.409	36.1057
711.836	38.7686
715.26	40.5136
718.685	42.5208
722.108	43.1631
725.528	45.0159
728.949	46.3722
732.367	48.8037
735.785	50.2617
739.2	51.1014
742.614	53.5261
746.028	56.4737
749.439	59.4652
752.849	61.6416
756.26	63.3597
759.667	63.8938
763.073	65.4127
766.477	66.9656
769.883	67.9532
773.285	70.2803
776.686	71.3788
780.085	71.4773
783.484	73.0805
786.881	74.3891
790.276	77.1047
793.671	79.3036
797.064	81.4511
800.456	82.0554
803.846	82.4946
807.234	82.7761
810.622	83.5046
814.008	83.1729
817.394	85.7557
820.778	85.3094
824.159	85.264
827.541	85.3826
830.921	85.5478
834.298	84.4449
837.676	83.0827
841.051	79.8205
844.426	77.122
847.798	74.1276
851.171	72.2547
854.54	70.4276
857.911	67.5087
861.278	65.9121
864.645	63.4818
868.01	62.7164
871.373	60.8021
874.735	59.9221
878.097	58.9532
881.457	57.0837
884.815	56.2445
888.172	54.2967
891.528	54.7539
894.882	54.5472
898.237	53.8809
901.589	52.5996
904.94	51.7302
908.289	50.6401
911.635	49.2763
914.982	48.8813
918.328	49.1372
921.672	47.7298
925.015	46.6402
928.357	45.6509
931.698	45.2511
935.035	43.7311
938.373	42.5057
941.71	41.735
945.044	38.6181
948.378	37.9678
951.709	37.4007
955.041	35.4094
958.372	35.0391
961.699	33.3783
965.027	33.5221
968.352	33.9578
971.676	33.7392
975	34.8275
978.322	35.3116
981.642	35.0065
984.962	36.4713
988.28	35.1644
991.596	34.3359
994.911	34.7555
998.227	35.9158
1001.54	36.4776
1004.85	35.6856
1008.16	34.6217
1011.47	32.9649
1014.78	30.9538
1018.08	31.1212
1021.39	28.8226
1024.69	25.9179
1028	24.4232
1031.3	23.5029
1034.6	20.8086
1037.9	18.1966
1041.19	16.201
1044.49	18.0705
1047.78	19.3597
1051.08	18.7413
1054.37	18.6208
1057.66	20.4086
1060.95	18.8328
1064.24	19.2263
1067.53	19.1579
1070.81	18.5647
1074.1	19.7374
1077.38	21.0513
1080.66	21.4783
1083.94	21.8001
1087.22	20.9449
1090.5	20.9705
1093.78	21.8202
1097.05	23.1805
1100.33	23.7108
1103.6	23.34
1106.87	22.1722
1110.14	21.5777
1113.41	20.0898
1116.68	18.2381
1119.95	16.1116
1123.21	16.3842
1126.48	16.2831
1129.74	16.0543
1133	15.5966
1136.26	14.6793
1139.52	13.3525
1142.78	13.3202
1146.04	12.6045
1149.29	12.4741
1152.55	12.346
1155.8	11.7411
1159.05	10.7535
1162.3	10.2293
1165.55	10.42
1168.8	10.5213
1172.05	10.9083
1175.29	13.46
1178.54	14.6892
1181.78	14.2768
1185.02	14.3061
1188.26	14.6232
1191.5	14.4697
1194.74	15.9693
1197.97	17.5187
1201.21	19.9631
1204.44	22.4263
1207.68	24.3896
1210.91	26.3563
1214.14	27.5653
1217.37	29.58
1220.59	31.1031
1223.82	32.7873
1227.05	34.9489
1230.27	36.3174
1233.49	38.1192
1236.72	39.5612
1239.94	41.0086
1243.16	41.3729
1246.37	43.1781
1249.59	44.5186
1252.8	46.4684
1256.02	46.8926
1259.23	46.916
1262.44	47.2814
1265.66	47.478
1268.86	49.4681
1272.07	49.8816
1275.28	50.3814
1278.48	51.3821
1281.69	52.2007
1284.89	53.523
1288.09	54.8555
1291.29	55.5757
1294.49	56.7976
1297.69	57.6274
1300.89	57.9287
1304.08	59.3802
1307.28	61.389
1310.47	62.9871
1313.66	65.9675
1316.85	66.3601
1320.04	66.8861
1323.23	66.6881
1326.42	67.0822
1329.61	66.4976
1332.79	65.2135
1335.97	63.2808
1339.16	62.6501
1342.34	61.61
1345.52	59.7845
1348.7	57.2486
1351.87	54.6247
1355.05	51.5721
1358.22	49.2645
1361.4	47.6533
1364.57	45.6867
1367.74	43.1157
1370.91	40.4448
1374.08	38.8499
1377.25	37.75
1380.41	36.4099
1383.58	37.0704
1386.74	36.4698
1389.91	36.8405
1393.07	35.3507
1396.23	33.9149
1399.39	32.8727
1402.55	32.0354
1405.7	33.1973
1408.86	34.5759
1412.01	35.4869
1415.17	37.3971
1418.32	41.5603
1421.47	44.9567
1424.62	49.1383
1427.77	52.1641
1430.91	56.7532
1434.06	60.6003
1437.2	64.4282
1440.35	68.2317
1443.49	69.3842
1446.63	72.8457
1449.77	73.5013
1452.91	73.4064
1456.05	71.6179
1459.18	69.6664
1462.32	67.1883
1465.45	63.1572
1468.59	58.3999
1471.72	52.9657
1474.85	46.2908
1477.98	41.2072
1481.1	36.4102
1484.23	32.1412
1487.36	27.2837
1490.48	22.6408
1493.61	21.359
1496.73	19.7335
1499.85	18.3529
1502.97	18.1151
1506.09	17.1967
1509.2	17.0015
1512.32	16.2144
1515.43	16.6118
1518.55	16.6336
1521.66	17.7683
1524.77	19.4206
1527.88	20.5406
1530.99	21.6493
1534.1	22.7772
1537.21	24.0392
1540.31	26.4472
1543.42	26.899
1546.52	28.4574
1549.62	30.5309
1552.72	32.4402
1555.82	34.9134
1558.92	36.6296
1562.02	37.0586
1565.11	38.1325
1568.21	42.0199
1571.3	43.6772
1574.39	46.024
1577.49	47.3048
1580.57	49.1425
1583.66	50.802
1586.75	50.9636
1589.84	52.1395
1592.92	52.7294
1596.01	52.181
1599.09	51.9232
1602.17	51.0646
1605.25	50.5307
1608.33	49.7455
1611.41	49.6657
1614.49	49.4813
1617.57	49.33
1620.64	49.689
1623.72	50.4102
1626.79	50.0643
1629.86	50.8067
1632.93	50.9863
1636	51.7408
1639.07	53.9638
1642.13	56.9367
1645.2	56.7746
1648.26	57.6698
1651.33	59.1641
1654.39	59.4134
1657.45	60.169
1660.51	58.767
1663.57	57.9626
1666.63	56.5037
1669.68	53.2967
1672.74	49.9234
1675.79	47.4603
1678.85	44.2126
1681.9	41.8986
1684.95	38.5643
1688	34.0041
1691.05	28.9468
1694.09	26.1935
1697.14	22.4049
1700.18	18.6629
1703.23	15.9663
1706.27	13.1996
1709.31	11.508
1712.35	11.4533
1715.39	10.3946
1718.43	8.08735
1721.47	6.66968
1724.5	6.3006
1727.54	5.70782
1730.57	5.08988
1733.61	4.33719
1736.64	3.66538
1739.67	3.57057
1742.7	2.87315
1745.72	2.10033
1748.75	2.38248
1751.77	1.98934
1754.8	1.29663
1757.82	0.920572
1760.84	-0.0206299
1763.87	-0.663328
1766.89	-0.670941
1769.91	-1.1336
1772.92	-0.638006
1775.94	-0.659764
1778.95	-0.623193
1781.97	0.0826178
1784.98	0.971789
1787.99	1.55019
1791.01	1.63919
1794.01	1.14733
1797.02	1.52934
1800.03	0.98253
1803.04	1.47207
1806.04	1.01285
1809.05	1.58078
1812.05	1.47157
1815.05	1.93553
1818.05	2.69931
1821.05	3.25712
1824.05	3.61991
1827.05	3.26087
1830.04	4.0026
1833.04	4.84203
1836.03	5.25272
1839.03	5.9583
1842.02	7.67253
1845.01	8.26743
1848	9.2687
1850.99	9.59151
1853.97	9.97281
1856.96	10.4228
1859.94	11.0297
1862.93	11.2469
1865.91	11.1498
1868.89	11.2938
1871.87	11.4171
1874.85	11.4224
1877.83	11.823
1880.81	11.7478
1882.57	11.5689
1885.56	12.0977
1888.55	12.8031
1891.54	12.69
1894.52	11.7225
1897.51	11.6575
1900.49	11.0887
1903.47	11.3927
1906.45	11.5839
1909.43	11.8
1912.41	11.998
1915.39	12.0095
1918.37	11.9798
1921.34	11.2131
1924.32	11.0824
1927.29	10.7582
1930.26	10.7553
1933.23	10.0062
1936.2	10.1533
1939.17	10.7218
1942.14	10.3316
1945.11	11.174
1948.07	11.5368
1951.04	12.2548
1954	11.612
1956.96	12.5172
1959.93	12.1993
1962.89	11.6449
1965.85	10.8626
1968.8	11.1644
1971.76	10.8837
1974.72	11.2867
1977.67	12.0841
1980.63	13.3088
1983.58	12.8909
1986.53	12.7431
1989.48	13.0775
1992.43	11.6548
1995.38	11.5843
1998.32	11.7528
2001.27	12.078
2004.22	11.5333
2007.16	11.4038
2010.1	10.3371
2013.04	10.2429
2015.98	10.2063
2018.92	9.22208
2021.86	8.84982
2024.8	9.2216
2027.74	8.25387
2030.67	7.98865
2033.61	6.94864
2036.54	6.86625
2039.47	7.92235
2042.4	7.81875
2045.33	9.08193
2048.26	10.2471
2051.19	10.6445
2054.12	10.8901
2057.04	10.7703
2059.97	10.8682
2062.89	11.3707
2065.81	11.7022
2068.73	11.5373
2071.65	11.4878
2074.57	11.5467
2077.49	11.2836
2080.41	10.539
2083.32	10.1779
2086.24	10.8886
2089.15	10.6504
2092.07	11.1123
2094.98	12.0871
2097.89	12.1025
2100.8	12.7871
2103.71	12.798
2106.61	12.9865
2109.52	12.9526
2112.43	13.4747
2115.33	13.8804
2118.23	14.857
2121.13	14.759
2124.04	15.2037
2126.94	16.6237
2129.83	18.0135
2132.73	19.266
2135.63	20.2594
2138.53	21.2637
2141.42	22.4406
2144.31	23.3653
2147.21	24.0577
2150.1	25.2992
2152.99	26.729
2155.88	27.6054
2158.77	28.1109
2161.65	29.2232
2164.54	29.8535
2167.43	28.9855
2170.31	29.4831
2173.19	29.598
2176.07	29.7166
2178.96	28.9501
2181.84	27.9248
2184.72	27.209
2187.59	27.4354
2190.47	26.6707
2193.35	25.9882
2196.22	25.0276
2199.09	25.0893
2201.97	23.1716
2204.84	22.8708
2207.71	22.8411
2210.58	22.0439
2213.45	21.1416
2216.31	20.8076
2219.18	20.904
2222.05	20.8045
2224.91	19.7819
2227.78	19.1624
2230.64	19.2125
2233.5	18.0833
2236.36	16.5283
2239.22	16.0286
2242.08	15.9179
2244.93	15.523
2247.79	15.4244
2250.64	13.7337
2253.5	12.6552
2256.35	12.4046
2259.2	10.5581
2262.05	10.3302
2264.9	9.03831
2267.75	7.91188
2270.6	6.82713
2273.45	6.63048
2276.29	6.41481
2279.14	5.58918
2281.98	5.65364
2284.82	6.12049
2287.66	6.11624
2290.5	4.8233
2293.34	4.7413
2296.18	4.55376
2299.02	5.51157
2301.86	5.74874
2304.69	6.47638
2307.53	8.1287
2310.36	8.78289
2313.19	9.96533
2316.02	10.6263
2318.85	10.7246
2321.68	9.93476
2324.51	9.89065
2327.34	9.47887
2330.16	8.91387
2332.99	8.126
2335.81	6.89443
2338.64	6.48789
2341.46	5.70827
2344.28	4.87656
2347.1	4.4501
2349.92	3.46528
2352.74	2.37069
2355.55	1.63984
2358.37	0.481469
2361.19	0.73696
2364	1.21355
2366.81	1.99129
2369.62	2.33314
2372.44	3.07506
2375.24	3.58196
2378.05	3.28564
2380.86	3.85686
2383.67	3.4762
2386.47	2.73659
2389.28	2.2587
2392.08	2.48948
2394.89	2.09223
2397.69	2.63883
2400.49	2.37601
2403.29	2.6876
2406.09	2.60254
2408.88	2.81593
2411.68	3.28626
2414.48	2.64185
2417.27	2.32799
2420.06	2.30931
2422.86	2.29197
2425.65	2.20439
2428.44	1.95722
2431.23	1.60985
2434.02	0.872337
2436.81	1.24583
2439.59	1.24622
2442.38	1.21982
2445.16	0.666368
2447.95	-1.1963
2450.73	-0.936965
2453.51	-1.35181
2456.29	-1.03364
2459.07	-0.799273
2461.85	-1.33138
2464.63	-1.80789
2467.4	-0.324124
2470.18	-0.623289
2472.95	0.0324276
2475.73	-0.270476
2478.5	-0.112533
2481.27	-0.532725
2484.04	-0.456216
2486.81	-0.506106
2489.58	-0.0803805
2492.35	0.639909
2495.12	0.537072
2497.88	0.753633
2500.65	0.738123
2503.41	1.33742
2506.17	1.56819
2508.94	1.54045
2511.7	1.07071
2514.46	0.178788
2517.22	0.155907
2519.97	1.01575
2522.73	0.725275
2525.49	0.958194
2528.24	1.27196
2530.99	1.4348
2533.75	2.26483
2536.5	2.74216
2539.25	2.71995
2542	2.65907
2544.75	3.0018
2547.5	3.78301
2550.24	4.30524
2552.99	4.51234
2555.74	5.31342
2558.48	6.08578
2561.22	5.98014
2563.96	5.72703
2566.71	5.53845
2569.45	4.42211
2572.18	4.71079
2574.92	4.89245
2577.66	4.62584
2580.4	3.99882
2583.13	4.37032
2585.87	4.31642
2588.6	4.71733
2591.33	4.24425
2594.06	3.41908
2596.79	2.45301
2599.52	3.02188
2602.25	2.35002
2604.98	2.08146
2607.71	1.26957
2610.43	1.20711
2613.16	1.08051
2615.88	1.01632
2618.6	0.242042
2621.32	0.0166147
2624.04	-0.896047
2626.76	-1.33379
2629.48	-1.97464
2632.2	-1.75041
2634.92	-1.20489
2637.63	-0.73105
2640.35	0.384215
2643.06	0.804695
2645.77	1.85128
2648.49	1.80265
2651.2	2.69979
2653.91	3.00466
2656.62	3.17268
2659.33	2.88755
2662.03	2.67547
2664.74	3.35791
2667.44	2.82838
2670.15	1.99995
2672.85	1.84215
2675.55	1.70009
2678.26	1.47752
2680.96	1.42782
2683.66	1.31501
2686.35	1.82699
2689.05	1.86637
2691.75	2.07623
2694.44	2.75629
2697.14	3.94114
2699.83	5.27479
2702.52	5.99768
2705.22	6.59344
2707.91	7.51605
2710.6	8.98405
2713.29	10.0742
2715.97	10.8952
2718.66	11.9925
2721.35	11.5573
2724.03	12.1214
2726.72	13.2194
2729.4	13.6119
2732.08	12.8229
2734.76	12.3695
2737.44	12.8873
2740.12	13.4674
2742.8	13.603
2745.48	14.1739
2748.16	13.846
2750.83	12.7424
2753.51	12.3882
2756.18	10.935
2758.85	10.4367
2761.53	10.2355
2764.2	9.83558
2766.87	8.24472
2769.54	6.82151
2772.2	5.89792
2774.87	5.63769
2777.54	4.84903
2780.2	4.19866
2782.87	4.06953
2785.53	4.43434
2788.19	5.005
2790.85	6.27577
2793.51	6.98681
2796.17	6.45844
2798.83	6.34998
2801.49	7.84669
2804.15	8.59166
2806.8	8.14098
2809.46	8.27572
2812.11	8.10136
2814.76	8.93873
2817.42	9.7705
2820.07	11.2197
2822.72	12.1684
2825.37	15.0885
2828.02	17.72
2830.66	21.3372
2833.31	25.4654
2835.96	30.1338
2838.6	34.7352
2841.24	40.5181
2843.89	47.4902
2846.53	54.8032
2849.17	61.8467
2851.81	69.4008
2854.45	77.1897
2857.09	85.1511
2859.72	91.3786
2862.36	98.0467
2865	103.628
2867.63	109.656
2870.26	114.681
2872.9	118.612
2875.53	123.273
2878.16	126.834
2880.79	130.765
2883.42	133.892
2886.05	137.087
2888.67	141.234
2891.3	146.214
2893.92	150.902
2896.55	155.432
2899.17	158.597
2901.79	164.765
2904.42	171.991
2907.04	180.272
2909.66	188.643
2912.27	197.057
2914.89	205.654
2917.51	214.472
2920.13	221.264
2922.74	227.657
2925.35	231.287
2927.97	233.903
2930.58	235.409
2933.19	236.185
2935.8	234.867
2938.41	232.258
2941.02	228.763
2943.63	224.025
2946.24	218.729
2948.84	212.25
2951.45	206.188
2954.05	199.622
2956.65	192.983
2959.26	185.626
2961.86	177.699
2964.46	171.038
2967.06	166.21
2969.66	159.672
2972.25	152.892
2974.85	146.461
2977.45	139.299
2980.04	132.136
2982.64	124.248
2985.23	115.623
2987.82	107.923
2990.41	99.1705
2993	91.2638
2995.59	83.4065
2998.18	76.0722
3000.77	69.504
3003.36	62.7728
3005.94	56.4912
3008.53	50.7987
3011.11	46.6233
3013.69	42.0995
3016.28	38.8879
3018.86	36.8737
3021.44	34.5832
3024.02	32.5
3026.6	31.1941
3029.18	30.1253
3031.75	30.1144
3034.33	29.0978
3036.9	29.5029
3039.48	29.9326
3042.05	30.1719
3044.62	32.1333
3047.19	32.851
3049.77	34.0328
3052.34	34.5385
3054.9	34.7208
3057.47	34.5545
3060.04	34.749
3062.61	34.4153
3065.17	31.8838
3067.74	29.9004
3070.3	27.8672
3072.86	25.8286
3075.42	22.9535
3077.99	21.488
3080.54	20.6194
3083.1	18.5706
3085.66	16.5867
3088.22	14.5606
3090.78	12.7948
3093.33	11.4846
3095.89	10.1388
3098.44	9.19267
3100.99	9.17222
3103.54	8.64557
3106.1	8.6086
3108.65	8.73853
3111.2	8.34481
3113.74	7.90139
3116.29	7.19609
3118.84	6.83826
3121.38	6.79902
3123.93	5.67458
3126.47	4.16792
3129.01	3.36024
3131.56	2.22036
3134.1	1.666
3136.64	0.804356
3139.18	0.470582
3141.72	0.473564
3144.26	-0.388522
3146.79	-1.07172
3149.33	-0.747525