File: data/Raman/poly_smoothed/Thy_20_09_23_1x_45s_532 nm_x100_100%_600 gr_mm_01.txt
#Acq. time (s)=	45
#Accumulations=	2
#Range (cm-¹)=	200...3150
#Windows=	2
#Auto scanning=	Off
#Autofocus=	Off
#Macrospot=	Off
#AutoExposure=	Off
#Spike filter=	Multiple accum.
#Delay time (s)=	0
#Binning=	1
#Readout mode=	Signal
#DeNoise=	Off
#ICS correction=	On
#Dark correction=	Off
#Inst. Process=	Off
#Detector Gain=	Best Dynamic Range
#Detector ADC=	20 kHz
#Detector temperature (°C)=	-69.85
#Instrument=	LabRAM HR Evol
#Detector=	Synapse
#Objective=	x100
#Grating=	600 gr/mm
#ND Filter=	100%
#Laser (nm)=	532
#Hole=	100.021
#Range=	Auto
#Laser Pol.=	No
#Raman. Pol.=	No
#Laser Pol. (°)=	-0.0007625
#Raman Pol. (°)=	89.9995
#Collection=	Microscope
#StageXY=	Marzhauser
#StageZ=	Marzhauser
#X (µm)=	-5913.2
#Y (µm)=	2879.2
#Z (µm)=	-223.8
#Full time(mm:ss)=	3:18
#Project=
#Sample=
#Site=
#Title=	Thy_20_09_23_2x_45s_532 nm_x100_100%_600 gr_mm
#Remark=
#Date=	29.06.2022 12:16
#Acquired=	29.06.2022 12:16:56
#Base:Fit=	10.08.2022 09:52:02
#Base:Fit=	10.08.2022 09:52:12
#Base:Sub=	10.08.2022 09:54:21
#Filter:Polynom=	16.08.2022 10:24:04
#AxisType[0]=Intens
#AxisUnit[0]=Cnt
#AxisType[1]=Spectr
#AxisUnit[1]=1/cm
200.523	6.10683
204.154	7.89099
207.781	11.2916
211.409	13.4586
215.034	15.3967
218.659	15.7042
222.281	17.0831
225.903	17.2448
229.522	17.4954
233.14	17.0627
236.756	15.712
240.373	15.1366
243.986	14.2605
247.598	13.9519
251.208	13.5101
254.818	12.4702
258.427	12.761
262.034	12.592
265.638	13.0524
269.242	12.3877
272.844	13.9183
276.445	14.1309
280.044	15.5038
283.642	15.133
287.238	17.9393
290.833	20.9367
294.425	21.954
298.017	24.0582
301.608	25.2886
305.198	25.3466
308.786	25.8918
312.371	24.7091
315.956	25.1048
319.54	25.5031
323.122	25.1362
326.701	23.4482
330.281	24.3117
333.857	25.1865
337.434	24.8504
341.008	24.3557
344.582	21.3355
348.153	20.6941
351.724	18.3911
355.292	17.3472
358.861	15.33
362.426	15.4009
365.99	13.6418
369.555	12.1769
373.116	10.0838
376.676	9.79677
380.236	9.99565
383.793	8.77865
387.349	7.25684
390.903	4.16963
394.456	3.02902
398.007	0.714378
401.56	1.23189
405.108	1.20639
408.656	1.46096
412.202	1.82631
415.746	1.9338
419.29	4.50347
422.831	4.52822
426.37	4.31852
429.909	4.2024
433.447	4.65986
436.983	6.64564
440.519	6.62029
444.052	6.01802
447.583	5.38047
451.114	6.22873
454.643	6.19207
458.169	6.73485
461.696	7.34462
465.222	9.32096
468.744	9.75233
472.267	10.9352
475.787	11.4465
479.307	12.3804
482.823	13.1262
486.341	14.0595
489.855	15.0077
493.37	15.3223
496.881	15.7394
500.391	14.8306
503.902	14.5318
507.409	15.0745
510.915	14.2668
514.42	13.7646
517.925	13.517
521.427	13.341
524.928	12.047
528.427	10.1975
531.925	7.59095
535.422	6.28515
538.917	7.1228
542.411	5.41568
545.903	4.83843
549.395	5.21015
552.884	5.30532
556.373	4.98771
559.86	5.43285
563.346	5.33725
566.831	4.14704
570.314	5.06476
573.794	3.83851
577.274	2.73534
580.754	3.29969
584.23	2.01087
587.706	1.84839
591.181	1.39519
594.653	1.5765
598.126	1.49116
601.595	2.99783
605.065	4.27615
608.532	3.92802
611.999	4.19138
615.463	3.63238
618.928	3.58792
622.389	5.4415
625.851	5.57065
629.31	6.09191
632.767	6.60424
636.223	6.9356
639.68	7.24118
643.134	7.58445
646.586	6.33278
650.037	7.63398
653.486	8.08009
656.936	9.39303
660.383	10.5912
663.829	13.2587
667.273	14.5873
670.716	14.3986
674.158	16.3271
677.598	17.7707
681.035	19.6685
684.473	20.538
687.909	20.7195
691.344	21.0444
694.778	21.9131
698.211	20.6052
701.64	21.5544
705.07	22.131
708.498	22.8073
711.924	23.9344
715.35	24.1469
718.774	24.8623
722.196	26.0954
725.618	27.779
729.037	29.214
732.456	30.4997
735.873	33.8701
739.289	36.9621
742.703	40.1622
746.116	43.3338
749.529	46.5905
752.938	47.9623
756.347	51.5571
759.756	54.608
763.162	55.9932
766.567	55.6516
769.97	56.6699
773.372	57.1787
776.773	58.7752
780.174	59.2792
783.573	59.8098
786.97	61.4386
790.365	61.5823
793.76	64.0359
797.153	64.7558
800.543	64.3078
803.933	64.9878
807.322	65.5992
810.71	64.8939
814.097	65.6005
817.483	65.6782
820.865	66.4033
824.248	66.1936
827.629	67.1243
831.008	66.5587
834.387	66.8288
837.765	66.2243
841.139	65.7309
844.514	63.9435
847.886	61.5694
851.259	58.6121
854.629	57.5701
857.997	55.7306
861.366	53.7513
864.732	50.8127
868.098	50.1092
871.461	50.6121
874.823	48.0141
878.184	46.7441
881.545	44.5597
884.903	43.26
888.26	42.2504
891.616	40.0071
894.97	39.6778
898.323	40.0643
901.675	40.4336
905.026	41.019
908.375	40.2173
911.723	38.6278
915.07	38.7586
918.415	37.3477
921.76	36.3025
925.103	36.0261
928.443	35.3085
931.783	34.5031
935.123	34.1687
938.461	33.5675
941.796	33.1653
945.131	31.9989
948.465	31.1166
951.797	33.0322
955.128	30.585
958.457	29.1109
961.786	27.1358
965.113	28.9184
968.44	28.7495
971.763	30.6527
975.086	30.3647
978.409	31.3942
981.729	32.8738
985.048	33.7006
988.367	33.3918
991.683	32.043
994.998	31.4263
998.312	31.9505
1001.62	33.0065
1004.94	32.8783
1008.25	33.1055
1011.56	32.4844
1014.86	33.1733
1018.17	31.3141
1021.48	29.2416
1024.78	27.4348
1028.08	24.3249
1031.38	24.1439
1034.68	22.3303
1037.98	20.0844
1041.28	18.3325
1044.57	17.9693
1047.87	17.4846
1051.16	17.6391
1054.45	17.1872
1057.75	17.1468
1061.04	15.9002
1064.32	17.3678
1067.61	17.9434
1070.9	17.2403
1074.18	17.2902
1077.47	20.3101
1080.75	20.2122
1084.03	20.2306
1087.31	20.432
1090.59	21.8442
1093.86	23.1903
1097.14	23.3479
1100.41	22.4149
1103.69	23.0152
1106.96	23.4797
1110.23	22.441
1113.5	22.5
1116.77	22.8974
1120.03	21.148
1123.3	20.1124
1126.56	19.6465
1129.83	17.467
1133.09	16.76
1136.35	15.8877
1139.61	14.0655
1142.86	12.8668
1146.12	12.7985
1149.38	10.2718
1152.63	8.58087
1155.88	7.48234
1159.14	5.04407
1162.39	3.3286
1165.63	2.50007
1168.88	2.74391
1172.13	3.61978
1175.38	4.76098
1178.62	5.95612
1181.86	6.68884
1185.1	7.11786
1188.34	9.93492
1191.58	13.5358
1194.82	16.2883
1198.06	20.3097
1201.29	20.9801
1204.53	23.4113
1207.76	27.0565
1210.99	29.9362
1214.22	34.1975
1217.45	38.4368
1220.68	42.8821
1223.91	46.9142
1227.13	49.5037
1230.36	50.9592
1233.58	52.6566
1236.8	54.2525
1240.02	55.8637
1243.24	57.1621
1246.46	57.9702
1249.67	60.3011
1252.89	61.9033
1256.1	63.5331
1259.32	64.7043
1262.53	64.9221
1265.74	67.0953
1268.95	70.3652
1272.15	70.2595
1275.36	71.0846
1278.57	72.555
1281.77	72.0292
1284.97	74.984
1288.18	76.8133
1291.38	78.4175
1294.58	81.9461
1297.78	83.2432
1300.97	84.3632
1304.17	83.6425
1307.36	85.2189
1310.55	85.975
1313.75	87.2579
1316.94	87.1579
1320.13	88.5018
1323.32	89.0354
1326.5	89.3386
1329.69	91.1196
1332.87	89.4725
1336.06	88.054
1339.24	87.199
1342.42	84.8103
1345.6	83.7446
1348.78	80.6977
1351.96	78.2597
1355.13	76.7357
1358.31	73.4529
1361.48	71.3444
1364.65	68.4871
1367.82	67.1928
1370.99	64.45
1374.16	59.895
1377.33	56.578
1380.5	54.0573
1383.66	53.7827
1386.83	52.2858
1389.99	50.8674
1393.15	49.3066
1396.31	49.3686
1399.47	48.4441
1402.63	48.1263
1405.78	47.7557
1408.94	46.8306
1412.1	47.1737
1415.25	50.9631
1418.4	54.7832
1421.55	58.7751
1424.7	63.8805
1427.85	70.0919
1431	75.9769
1434.14	81.325
1437.29	87.5352
1440.43	91.7018
1443.57	94.5582
1446.71	96.7713
1449.85	96.7737
1452.99	96.0394
1456.13	95.8218
1459.26	94.6269
1462.4	91.5745
1465.54	86.3182
1468.67	80.0322
1471.8	72.9082
1474.93	66.2808
1478.06	58.137
1481.19	51.715
1484.31	44.0309
1487.44	36.8996
1490.56	34.5776
1493.69	30.2784
1496.81	27.1205
1499.93	25.9516
1503.05	25.36
1506.17	25.0151
1509.28	24.5385
1512.4	24.3559
1515.52	23.0265
1518.63	24.6255
1521.74	25.7389
1524.85	27.4963
1527.96	29.0304
1531.07	29.7913
1534.18	32.1182
1537.29	33.0688
1540.39	33.4021
1543.5	35.3135
1546.6	36.8723
1549.7	41.1456
1552.8	43.931
1555.9	46.8675
1559	49.9197
1562.1	52.9619
1565.19	57.2293
1568.29	61.8816
1571.38	65.7106
1574.47	69.7493
1577.56	73.43
1580.66	78.5412
1583.74	81.6548
1586.83	84.5186
1589.92	85.6129
1593.01	87.7652
1596.09	88.7395
1599.17	88.226
1602.25	87.0807
1605.34	85.1551
1608.41	81.9042
1611.49	79.1739
1614.57	75.6825
1617.65	72.5046
1620.72	71.3525
1623.79	70.416
1626.87	69.9
1629.94	68.8886
1633.01	69.68
1636.08	69.203
1639.15	68.8991
1642.21	70.5428
1645.28	72.6395
1648.34	73.556
1651.41	75.944
1654.47	77.5536
1657.53	78.5496
1660.59	77.9181
1663.65	77.223
1666.71	75.3079
1669.76	73.8958
1672.82	72.0826
1675.87	67.978
1678.93	64.2978
1681.98	58.7105
1685.03	53.4061
1688.08	48.6094
1691.13	43.6869
1694.17	39.6334
1697.22	36.4344
1700.27	32.3643
1703.31	28.3282
1706.35	24.0562
1709.39	20.6916
1712.43	17.4384
1715.47	14.4575
1718.51	13.0603
1721.55	9.71865
1724.58	6.87549
1727.62	5.70804
1730.65	4.22274
1733.68	3.19194
1736.72	2.16812
1739.74	2.51094
1742.77	2.02914
1745.8	1.23545
1748.83	0.507647
1751.85	0.332523
1754.88	1.10556
1757.9	0.779971
1760.92	1.00409
1763.95	1.68179
1766.96	2.79261
1769.98	2.03859
1773	2.0072
1776.02	2.90054
1779.03	2.91905
1782.05	3.06469
1785.06	3.12571
1788.07	3.04376
1791.08	2.97419
1794.09	2.86589
1797.1	2.69307
1800.11	3.55406
1803.12	4.03762
1806.12	3.46509
1809.12	3.25305
1812.13	3.84852
1815.13	2.9975
1818.13	2.57215
1821.13	2.0185
1824.13	2.03327
1827.13	2.66144
1830.12	2.8129
1833.12	3.30804
1836.11	4.23645
1839.1	3.21913
1842.09	2.2081
1845.09	2.58979
1848.08	3.25201
1851.06	3.34543
1854.05	2.4921
1857.04	2.66582
1860.02	3.71886
1863.01	2.98942
1865.99	2.67351
1868.97	2.35886
1871.95	2.50642
1874.93	2.10574
1877.91	1.20947
1880.89	1.15556
1882.46	0.611589
1885.45	0.619686
1888.43	0.611528
1891.42	1.20675
1894.41	2.20487
1897.39	3.33902
1900.37	4.34134
1903.36	5.18838
1906.34	5.48337
1909.32	5.9476
1912.29	5.74112
1915.27	6.17655
1918.25	6.37646
1921.23	5.0611
1924.2	5.09236
1927.17	5.82609
1930.15	7.00648
1933.12	6.01181
1936.09	5.54738
1939.06	4.87552
1942.02	4.45776
1944.99	3.83266
1947.96	2.90862
1950.92	2.59602
1953.88	2.19432
1956.85	1.67235
1959.81	2.33052
1962.77	3.24478
1965.73	3.10987
1968.69	3.29099
1971.64	3.66289
1974.6	3.28614
1977.55	3.05895
1980.51	3.59965
1983.46	3.58295
1986.41	3.80164
1989.36	4.61784
1992.31	4.93085
1995.26	5.67112
1998.21	7.55601
2001.15	7.9807
2004.1	7.71907
2007.04	6.84436
2009.99	7.00476
2012.93	5.97399
2015.87	6.29792
2018.81	6.73447
2021.75	6.76426
2024.68	5.57672
2027.62	5.07902
2030.56	5.25107
2033.49	5.93553
2036.42	5.91989
2039.36	5.76013
2042.29	5.84987
2045.22	6.94395
2048.14	7.52357
2051.07	8.50848
2054	9.41715
2056.93	11.7288
2059.85	12.2402
2062.77	11.9663
2065.7	13.051
2068.62	13.6831
2071.54	14.4233
2074.46	14.5672
2077.38	14.2035
2080.29	15.7215
2083.21	16.7582
2086.12	17.0504
2089.04	16.7648
2091.95	16.0352
2094.86	16.205
2097.77	16.1866
2100.68	16.329
2103.59	16.8958
2106.5	16.7003
2109.41	17.9291
2112.31	18.9364
2115.21	20.0429
2118.12	21.3821
2121.02	22.0194
2123.92	24.3269
2126.82	25.7349
2129.72	28.2704
2132.62	29.2786
2135.51	32.2984
2138.41	35.4465
2141.31	38.2227
2144.2	41.2575
2147.09	43.8226
2149.98	46.1935
2152.87	47.582
2155.76	48.3596
2158.65	49.4998
2161.54	51.8381
2164.43	54.4848
2167.31	55.1249
2170.2	55.1549
2173.08	55.8527
2175.96	55.3868
2178.84	55.5137
2181.72	53.9632
2184.6	52.0414
2187.48	48.7008
2190.36	47.0293
2193.23	44.9084
2196.11	41.9035
2198.98	39.0058
2201.85	36.12
2204.72	33.8876
2207.59	31.7813
2210.46	30.2524
2213.33	28.2273
2216.2	26.0287
2219.07	24.0184
2221.93	22.6752
2224.8	22.6262
2227.66	23.5269
2230.52	24.0399
2233.39	24.1911
2236.25	24.0394
2239.1	23.6817
2241.96	22.7042
2244.82	22.518
2247.68	22.1079
2250.53	21.6416
2253.38	20.2214
2256.24	20.258
2259.09	19.6189
2261.94	18.5556
2264.79	16.9605
2267.64	15.662
2270.49	14.5259
2273.33	13.9327
2276.18	13.2588
2279.02	13.9944
2281.87	13.3446
2284.71	13.7916
2287.55	13.4848
2290.39	12.7079
2293.23	12.8723
2296.07	13.5156
2298.91	14.1881
2301.74	13.9253
2304.58	13.8652
2307.41	13.1722
2310.25	14.0548
2313.08	13.4565
2315.91	13.4026
2318.74	12.7996
2321.57	12.4184
2324.4	12.2118
2327.23	11.6117
2330.05	10.5309
2332.88	8.99782
2335.7	7.6608
2338.52	7.49885
2341.35	6.80756
2344.17	5.98256
2346.99	5.14931
2349.81	4.19977
2352.62	3.40157
2355.44	2.12788
2358.26	0.480452
2361.07	-0.0201522
2363.89	0.570301
2366.7	1.36198
2369.51	1.4445
2372.32	1.74821
2375.13	1.94816
2377.94	1.94435
2380.75	2.57656
2383.56	2.50323
2386.36	3.0256
2389.17	3.00062
2391.97	4.15654
2394.77	4.23321
2397.58	5.17616
2400.38	4.30484
2403.18	5.70709
2405.97	6.14744
2408.77	6.05971
2411.57	4.81317
2414.37	3.97223
2417.16	4.33731
2419.95	4.4863
2422.75	4.22588
2425.54	3.83804
2428.33	4.57299
2431.12	4.03567
2433.91	3.6116
2436.7	3.76888
2439.48	4.39652
2442.27	4.41874
2445.05	3.60385
2447.84	3.58343
2450.62	4.68821
2453.4	4.41885
2456.18	3.56013
2458.96	3.15841
2461.74	4.03623
2464.52	2.99822
2467.29	2.73641
2470.07	3.22419
2472.85	3.08595
2475.62	1.83004
2478.39	1.15177
2481.16	0.517805
2483.93	1.32249
2486.7	1.25876
2489.47	0.0192825
2492.24	-0.289063
2495.01	0.501894
2497.77	-0.619009
2500.54	0.0441848
2503.3	0.912445
2506.06	1.43561
2508.83	2.17168
2511.59	3.45485
2514.35	4.08625
2517.11	4.80585
2519.86	4.95185
2522.62	4.73829
2525.38	4.56992
2528.13	5.04623
2530.89	4.85218
2533.64	5.13141
2536.39	5.736
2539.14	5.36776
2541.89	5.2077
2544.64	5.24452
2547.39	5.3104
2550.14	5.37255
2552.88	4.78899
2555.63	3.90241
2558.37	3.80714
2561.11	4.39113
2563.86	4.21067
2566.6	3.47828
2569.34	4.35625
2572.08	3.95533
2574.82	3.68761
2577.55	3.57351
2580.29	3.37343
2583.02	2.72279
2585.76	2.56355
2588.49	2.07548
2591.22	1.16885
2593.96	1.06542
2596.69	1.61536
2599.42	1.90374
2602.14	2.47402
2604.87	2.71131
2607.6	3.09236
2610.32	2.71712
2613.05	3.74212
2615.77	3.70853
2618.49	4.51923
2621.22	4.53795
2623.94	6.13923
2626.66	5.39297
2629.37	4.04243
2632.09	3.19283
2634.81	3.68315
2637.53	3.35657
2640.24	2.99861
2642.96	2.88751
2645.67	3.30559
2648.38	3.81775
2651.09	3.22719
2653.8	4.11127
2656.51	3.53921
2659.22	3.74013
2661.93	4.05033
2664.63	4.68276
2667.34	4.37024
2670.04	4.60326
2672.75	3.73079
2675.45	3.81011
2678.15	4.33905
2680.85	5.11247
2683.55	5.34342
2686.25	4.98006
2688.94	4.93167
2691.64	3.95035
2694.34	3.66547
2697.03	3.86374
2699.73	4.43459
2702.42	4.64154
2705.11	5.39596
2707.8	5.83173
2710.49	5.97825
2713.18	7.08105
2715.87	7.42534
2718.55	7.66474
2721.24	8.29525
2723.93	8.12444
2726.61	8.31204
2729.29	8.61031
2731.98	7.9373
2734.66	7.73311
2737.34	7.65377
2740.02	7.70036
2742.7	7.2125
2745.37	6.55375
2748.05	6.13693
2750.72	5.45227
2753.4	4.80768
2756.07	4.66675
2758.75	4.03913
2761.42	3.52855
2764.09	2.92838
2766.76	2.25201
2769.43	1.69081
2772.1	1.54635
2774.76	0.51573
2777.43	1.62606
2780.1	1.3803
2782.76	1.075
2785.42	-0.116786
2788.09	0.116274
2790.75	-0.970428
2793.41	-0.161907
2796.07	0.00990232
2798.73	0.368896
2801.39	0.915931
2804.04	1.28817
2806.7	2.58788
2809.35	2.4602
2812.01	2.56952
2814.66	3.30523
2817.31	4.29959
2819.96	5.78031
2822.61	7.21363
2825.26	9.22388
2827.91	12.135
2830.56	15.0582
2833.21	18.9098
2835.85	23.573
2838.5	27.7917
2841.14	33.9072
2843.78	40.7203
2846.42	47.417
2849.06	54.289
2851.71	62.1719
2854.34	70.593
2856.98	79.7284
2859.62	89.152
2862.26	98.2106
2864.89	106.83
2867.53	114.772
2870.16	122.285
2872.79	127.578
2875.42	132.127
2878.05	136.592
2880.68	141.457
2883.31	145.81
2885.94	150.033
2888.57	154.991
2891.19	159.233
2893.82	165.335
2896.44	171.442
2899.07	176.391
2901.69	183.036
2904.31	190.646
2906.93	199.507
2909.55	208.627
2912.17	218.183
2914.79	228.431
2917.41	237.781
2920.02	246.34
2922.64	252.055
2925.25	258.222
2927.86	261.527
2930.48	262.496
2933.09	260.529
2935.7	257.91
2938.31	253.693
2940.92	248.99
2943.53	242.386
2946.13	234.865
2948.74	226.94
2951.34	219.203
2953.95	210.641
2956.55	201.258
2959.15	193.057
2961.75	184.486
2964.35	174.466
2966.95	166.273
2969.55	158.147
2972.15	149.823
2974.75	142.59
2977.34	134.357
2979.94	125.443
2982.53	115.629
2985.13	105.754
2987.72	96.8559
2990.31	88.2632
2992.9	79.2366
2995.49	69.5365
2998.08	61.4535
3000.67	52.9526
3003.25	46.032
3005.84	39.2245
3008.42	32.3958
3011.01	26.9908
3013.59	23.2613
3016.17	19.877
3018.76	16.6442
3021.34	14.3741
3023.92	13.65
3026.49	11.7013
3029.07	9.29115
3031.65	8.60479
3034.23	9.09718
3036.8	10.6954
3039.38	11.2821
3041.95	12.0478
3044.52	13.3419
3047.09	14.3406
3049.66	15.0684
3052.23	15.2631
3054.8	15.863
3057.37	14.9699
3059.94	14.208
3062.5	12.4095
3065.07	11.5056
3067.63	10.7489
3070.2	8.81659
3072.76	7.72783
3075.32	6.45143
3077.88	4.75474
3080.44	3.25158
3083	1.97102
3085.56	1.03475
3088.12	-0.329378
3090.67	-1.45473
3093.23	-1.78869
3095.78	-1.34596
3098.34	-1.01279
3100.89	-1.1038
3103.44	-0.612316
3105.99	-0.085669
3108.54	0.787019
3111.09	1.06596
3113.64	2.0366
3116.19	2.78828
3118.74	2.8311
3121.28	3.34329
3123.83	3.92883
3126.37	4.84115
3128.91	5.37761
3131.46	5.77888
3134	6.44172
3136.54	6.95906
3139.08	7.4209
3141.62	7.75679
3144.16	7.84931
3146.69	7.28174
3149.23	7.73214