File: data/Raman/poly_smoothed/Thy_00_07_33_1x_45s_532 nm_x100_100%_600 gr_mm_01.txt
#Acq. time (s)=	45
#Accumulations=	2
#Range (cm-¹)=	200...3150
#Windows=	2
#Auto scanning=	Off
#Autofocus=	Off
#Macrospot=	Off
#AutoExposure=	Off
#Spike filter=	Multiple accum.
#Delay time (s)=	0
#Binning=	1
#Readout mode=	Signal
#DeNoise=	Off
#ICS correction=	On
#Dark correction=	Off
#Inst. Process=	Off
#Detector Gain=	Best Dynamic Range
#Detector ADC=	20 kHz
#Detector temperature (°C)=	-69.85
#Instrument=	LabRAM HR Evol
#Detector=	Synapse
#Objective=	x100
#Grating=	600 gr/mm
#ND Filter=	100%
#Laser (nm)=	532
#Hole=	100.021
#Range=	Auto
#Laser Pol.=	No
#Raman. Pol.=	No
#Laser Pol. (°)=	-0.0007625
#Raman Pol. (°)=	89.9995
#Collection=	Microscope
#StageXY=	Marzhauser
#StageZ=	Marzhauser
#X (µm)=	8966
#Y (µm)=	-3072.6
#Z (µm)=	-54.85
#Full time(mm:ss)=	3:19
#Project=
#Sample=
#Site=
#Title=	Thy_00_07_33_2x_45s_532 nm_x100_100%_600 gr_mm
#Remark=
#Date=	28.06.2022 12:33
#Acquired=	28.06.2022 12:33:44
#Base:Fit=	10.08.2022 10:07:56
#Base:Sub=	10.08.2022 10:08:40
#Filter:Polynom=	16.08.2022 10:26:06
#AxisType[0]=Intens
#AxisUnit[0]=Cnt
#AxisType[1]=Spectr
#AxisUnit[1]=1/cm
200.407	5.82397
204.035	2.23815
207.665	0.881682
211.291	0.549802
214.916	0.341453
218.541	2.15584
222.163	2.41542
225.785	3.59519
229.404	3.03177
233.022	1.61935
236.638	2.31879
240.255	3.30368
243.868	3.03852
247.48	3.81002
251.091	3.38838
254.702	5.01011
258.31	5.46741
261.916	6.58172
265.521	8.44181
269.125	8.76005
272.727	9.09488
276.328	9.21905
279.927	10.127
283.525	9.82897
287.121	10.3917
290.716	11.6489
294.31	12.585
297.9	14.4449
301.491	14.8197
305.081	16.7282
308.669	19.2876
312.256	20.6765
315.839	20.2129
319.423	21.3191
323.006	22.5584
326.585	24.9855
330.165	24.7427
333.741	25.0696
337.318	23.5968
340.894	23.9542
344.466	23.8006
348.039	23.2848
351.608	23.1715
355.176	21.0159
358.745	20.8032
362.31	21.1624
365.876	19.4942
369.439	19.3513
373	19.3247
376.56	20.3759
380.12	20.7554
383.677	21.1847
387.233	22.2669
390.787	23.3466
394.34	25.4228
397.894	26.4318
401.444	25.8855
404.993	26.1435
408.54	25.5011
412.086	24.2874
415.631	23.4642
419.174	22.1194
422.716	21.5398
426.257	19.8937
429.794	18.0651
433.332	15.4937
436.868	12.6879
440.403	11.451
443.937	10.9956
447.468	11.4553
450.999	11.7541
454.528	11.3659
458.057	13.1645
461.582	13.6298
465.107	16.4527
468.629	19.2971
472.152	20.3678
475.672	23.2212
479.192	26.2576
482.709	29.1041
486.226	28.6003
489.74	29.175
493.255	31.0489
496.767	30.8493
500.277	32.4522
503.788	34.9445
507.295	35.0653
510.801	34.3538
514.308	32.2276
517.811	29.9703
521.313	28.9064
524.814	29.407
528.313	29.5806
531.811	30.6754
535.308	29.2792
538.803	28.3119
542.297	28.0002
545.789	27.3296
549.281	27.8845
552.771	27.9774
556.259	29.1132
559.747	29.7321
563.233	30.3569
566.717	29.4707
570.2	27.604
573.68	26.3993
577.161	25.5647
580.64	26.5236
584.118	25.6727
587.593	25.6813
591.068	23.3466
594.54	19.7408
598.013	16.4654
601.484	14.9654
604.952	14.2101
608.421	13.6631
611.886	14.2055
615.35	12.5942
618.815	11.9884
622.276	11.0974
625.738	11.8852
629.197	13.8584
632.655	15.3021
636.113	18.0479
639.568	20.0975
643.021	21.7939
646.473	23.0346
649.924	23.6667
653.376	23.3482
656.824	26.4023
660.271	28.9122
663.716	29.8868
667.161	31.3266
670.604	29.4631
674.045	28.5072
677.486	27.8583
680.925	25.617
684.361	25.2852
687.797	25.6096
691.232	26.2437
694.666	26.9224
698.099	28.0011
701.528	27.6806
704.958	30.7345
708.387	31.7044
711.814	33.7243
715.238	36.6788
718.663	39.7651
722.084	41.8979
725.506	44.6772
728.925	47.6455
732.345	49.4556
735.761	52.0579
739.178	53.3997
742.592	56.44
746.006	57.8969
749.417	59.1222
752.827	60.4092
756.236	62.4777
759.645	63.3992
763.051	63.3311
766.456	65.8189
769.859	67.2346
773.261	70.1517
776.664	72.3837
780.064	73.4301
783.462	73.1124
786.859	71.6154
790.255	72.9904
793.649	72.5048
797.042	74.7564
800.434	76.1588
803.823	75.1081
807.212	75.0152
810.6	74.0516
813.987	71.9077
817.372	70.486
820.754	68.3853
824.137	67.8064
827.519	67.8327
830.897	67.8941
834.276	67.4974
837.654	67.1018
841.029	66.0826
844.404	65.2631
847.776	64.1728
851.149	62.052
854.519	60.7881
857.889	57.883
861.256	58.1838
864.622	57.7048
867.988	54.4833
871.351	53.7254
874.713	52.7853
878.074	51.8647
881.435	51.3754
884.794	48.334
888.15	47.7643
891.506	46.3927
894.861	45.8629
898.214	44.7727
901.566	44.293
904.916	43.2302
908.266	43.109
911.614	43.7118
914.961	44.366
918.306	45.5153
921.651	44.3394
924.994	43.3982
928.336	41.3823
931.674	41.1145
935.014	41.9564
938.352	42.1747
941.687	41.5433
945.022	42.3575
948.357	40.118
951.688	38.9743
955.02	38.0474
958.348	37.1425
961.678	34.2891
965.004	34.6825
968.331	35.5357
971.655	36.4975
974.979	35.9438
978.3	34.347
981.62	34.7186
984.941	34.8335
988.259	33.6408
991.575	33.7457
994.89	35.476
998.204	36.2172
1001.52	35.6954
1004.83	35.2576
1008.14	34.2394
1011.45	34.6992
1014.76	35.7462
1018.06	33.6207
1021.37	31.3223
1024.67	29.789
1027.97	30.6006
1031.27	29.0027
1034.57	27.3841
1037.87	25.3105
1041.17	23.3094
1044.47	23.1863
1047.76	24.9814
1051.06	23.1915
1054.35	23.0506
1057.64	21.3783
1060.93	20.8873
1064.22	21.8335
1067.5	21.1991
1070.79	21.0737
1074.08	21.1036
1077.36	19.8921
1080.64	18.6038
1083.92	17.6106
1087.2	16.8236
1090.48	16.2495
1093.76	17.1554
1097.03	18.1646
1100.31	20.2358
1103.58	22.0528
1106.85	22.8085
1110.12	24.7169
1113.39	24.6943
1116.66	25.8757
1119.93	27.5428
1123.19	29.5201
1126.46	32.1661
1129.72	31.9539
1132.98	32.4697
1136.24	32.7768
1139.5	34.5748
1142.76	35.308
1146.01	35.1192
1149.27	34.9923
1152.53	31.4546
1155.78	27.3383
1159.03	23.3074
1162.28	18.4984
1165.53	16.3284
1168.78	14.0244
1172.02	13.1884
1175.27	14.4897
1178.51	13.904
1181.76	12.0962
1185	11.6345
1188.24	11.4159
1191.48	12.2033
1194.71	13.4996
1197.95	15.1269
1201.19	18.0756
1204.42	20.9291
1207.65	21.1991
1210.88	23.2477
1214.12	27.3009
1217.35	32.1796
1220.57	35.9338
1223.8	40.359
1227.03	43.0101
1230.25	45.8119
1233.47	47.8827
1236.69	49.4519
1239.92	51.358
1243.13	52.7722
1246.35	54.2682
1249.57	56.1778
1252.78	57.9401
1256	59.2724
1259.21	58.5361
1262.42	59.6568
1265.63	60.4015
1268.84	60.3157
1272.05	60.5154
1275.26	60.7375
1278.46	61.7322
1281.67	62.4091
1284.87	63.702
1288.07	64.6097
1291.27	66.5554
1294.47	71.6343
1297.67	73.535
1300.87	77.9288
1304.06	81.81
1307.26	84.2698
1310.45	87.5784
1313.64	90.0831
1316.83	91.3478
1320.02	95.6669
1323.21	97.604
1326.4	99.8846
1329.59	101.825
1332.77	102.074
1335.95	101.817
1339.14	102.713
1342.32	101.089
1345.5	99.7406
1348.67	98.3652
1351.85	96.5424
1355.03	95.8953
1358.2	93.6482
1361.38	91.1747
1364.55	89.1088
1367.72	86.3709
1370.89	84.8389
1374.06	80.5728
1377.23	79.4405
1380.39	77.601
1383.56	75.6262
1386.72	75.0249
1389.89	72.9702
1393.05	71.9317
1396.21	71.1797
1399.37	70.5746
1402.52	69.2231
1405.68	68.4434
1408.84	67.5823
1411.99	67.6098
1415.15	70.0029
1418.3	71.6953
1421.45	75.2434
1424.6	78.0179
1427.75	83.9328
1430.89	89.0494
1434.04	93.3468
1437.18	99.1291
1440.33	103.752
1443.47	105.818
1446.61	106.847
1449.75	106.959
1452.89	108.762
1456.03	107.705
1459.16	106.154
1462.3	104.486
1465.43	101.366
1468.56	96.0281
1471.7	89.7556
1474.83	82.8856
1477.96	76.2367
1481.08	69.4733
1484.21	61.8659
1487.34	56.4161
1490.46	51.8611
1493.58	47.198
1496.71	42.4585
1499.83	40.7104
1502.95	39.1605
1506.07	39.5659
1509.18	39.1546
1512.3	38.8028
1515.41	37.3434
1518.53	36.1261
1521.64	35.3578
1524.75	38.0447
1527.86	40.1989
1530.97	42.9908
1534.08	46.9462
1537.19	51.0725
1540.29	53.5857
1543.4	56.1821
1546.5	59.4554
1549.6	63.4529
1552.7	68.0645
1555.8	72.6616
1558.9	76.4865
1562	79.9885
1565.09	83.0232
1568.19	86.3727
1571.28	90.7279
1574.37	92.6568
1577.47	95.4777
1580.56	98.0118
1583.64	100.915
1586.73	101.921
1589.82	100.789
1592.9	101.235
1595.99	100.914
1599.07	99.0895
1602.15	98.246
1605.23	97.2424
1608.31	95.1902
1611.39	92.91
1614.47	89.9965
1617.55	87.9736
1620.62	86.6459
1623.7	85.2529
1626.77	84.235
1629.84	82.8515
1632.91	82.8587
1635.98	81.6936
1639.05	81.0791
1642.11	80.7578
1645.18	81.0903
1648.24	81.2694
1651.31	81.9019
1654.37	82.6638
1657.43	82.3709
1660.49	81.0039
1663.55	79.0844
1666.61	78.0347
1669.66	75.8501
1672.72	72.4874
1675.77	69.4697
1678.83	65.7408
1681.88	62.1666
1684.93	58.1254
1687.98	54.1446
1691.03	50.8544
1694.07	46.6457
1697.12	42.7801
1700.17	39.4088
1703.21	36.3024
1706.25	33.2245
1709.29	30.2213
1712.33	26.9566
1715.37	25.1588
1718.41	22.6511
1721.45	20.7058
1724.49	19.7668
1727.52	17.8736
1730.55	16.6694
1733.59	15.6036
1736.62	15.7503
1739.65	15.1332
1742.68	13.6132
1745.7	12.9804
1748.73	12.1039
1751.76	11.6332
1754.78	10.6383
1757.8	10.9013
1760.83	10.3888
1763.85	9.07936
1766.87	8.56477
1769.89	8.55759
1772.9	7.71908
1775.92	6.8523
1778.94	6.13986
1781.95	5.75894
1784.96	5.52813
1787.97	5.43625
1790.99	5.42862
1794	6.10799
1797	7.8381
1800.01	8.54135
1803.02	8.98765
1806.02	9.38205
1809.03	10.2228
1812.03	10.0888
1815.03	10.4123
1818.03	11.1787
1821.03	11.8906
1824.03	12.3485
1827.03	11.9008
1830.02	10.826
1833.02	11.5078
1836.01	10.9615
1839.01	10.9765
1842	11.327
1844.99	10.7439
1847.98	10.5462
1850.97	10.7072
1853.95	11.2373
1856.94	11.6174
1859.93	12.5314
1862.91	13.6297
1865.89	14.2111
1868.87	14.8173
1871.85	15.5935
1874.83	15.3011
1877.81	13.9451
1880.79	12.968
1882.52	11.926
1885.51	10.2006
1888.5	9.80298
1891.49	8.86709
1894.47	7.86564
1897.46	6.37095
1900.44	6.4205
1903.42	6.09899
1906.4	6.41239
1909.38	6.12295
1912.36	6.58427
1915.34	6.86265
1918.32	6.84532
1921.29	8.47225
1924.27	9.902
1927.24	10.4858
1930.21	10.8808
1933.18	12.0415
1936.15	12.1566
1939.12	12.3889
1942.09	12.8489
1945.06	12.4696
1948.02	12.6151
1950.99	10.8849
1953.95	10.8898
1956.91	9.80559
1959.88	8.49772
1962.84	7.77227
1965.8	7.21271
1968.75	6.19031
1971.71	7.27853
1974.67	5.75978
1977.62	4.38646
1980.58	4.5528
1983.53	4.18317
1986.48	4.77833
1989.43	4.64018
1992.38	5.95896
1995.33	6.66152
1998.27	6.11521
2001.22	6.11293
2004.16	5.36756
2007.11	6.42166
2010.05	6.6525
2012.99	6.95619
2015.93	6.62181
2018.87	7.99697
2021.81	8.97134
2024.75	8.44851
2027.69	8.28064
2030.62	7.76424
2033.56	6.75478
2036.49	7.28133
2039.42	7.37249
2042.35	7.98226
2045.28	7.68059
2048.21	7.93979
2051.14	8.23717
2054.07	7.97066
2056.99	7.60611
2059.92	8.07061
2062.84	8.31305
2065.76	9.00965
2068.68	8.91388
2071.6	9.1951
2074.52	9.46902
2077.44	9.78015
2080.36	10.145
2083.27	9.84739
2086.19	9.2375
2089.1	8.54945
2092.02	9.80122
2094.93	10.0086
2097.84	8.80304
2100.75	8.75186
2103.66	7.99366
2106.56	7.09322
2109.47	7.0734
2112.38	5.91235
2115.28	4.3333
2118.18	3.66525
2121.09	3.73879
2123.99	2.5484
2126.89	1.95628
2129.79	2.188
2132.68	1.25017
2135.58	0.873327
2138.48	1.11676
2141.37	1.5955
2144.27	2.87248
2147.16	3.3174
2150.05	4.85232
2152.94	5.1338
2155.83	5.08985
2158.72	5.33372
2161.6	6.50035
2164.49	7.66008
2167.38	8.62426
2170.26	7.98872
2173.14	7.75751
2176.03	8.14895
2178.91	7.80137
2181.79	7.14303
2184.67	7.07958
2187.54	7.36131
2190.42	7.40634
2193.3	6.68801
2196.17	5.89521
2199.05	4.89814
2201.92	3.35398
2204.79	3.19723
2207.66	2.80459
2210.53	2.6939
2213.4	3.41196
2216.27	2.44933
2219.13	3.15683
2222	3.51273
2224.86	3.05918
2227.72	3.47891
2230.59	4.51297
2233.45	5.20727
2236.31	5.7333
2239.17	6.72938
2242.03	8.12416
2244.88	8.71311
2247.74	8.66653
2250.59	8.90984
2253.45	9.26172
2256.3	9.06108
2259.15	8.31993
2262	6.98714
2264.85	6.67683
2267.7	6.64111
2270.55	5.65614
2273.4	4.37939
2276.24	2.63856
2279.09	2.1867
2281.93	2.20466
2284.77	1.78979
2287.62	0.776303
2290.46	1.36481
2293.3	1.30171
2296.13	1.38432
2298.97	2.8128
2301.81	3.57926
2304.64	5.57664
2307.48	7.87087
2310.31	8.7838
2313.14	10.3881
2315.98	11.4733
2318.81	12.137
2321.64	12.7445
2324.46	13.0203
2327.29	13.2687
2330.12	12.9466
2332.94	13.3806
2335.77	12.8621
2338.59	10.7273
2341.41	9.02688
2344.23	8.01245
2347.05	7.10201
2349.87	5.36052
2352.69	3.97605
2355.51	2.02137
2358.32	1.51811
2361.14	0.716351
2363.95	1.02805
2366.76	1.75541
2369.58	1.60459
2372.39	1.97819
2375.2	2.57541
2378	1.73906
2380.81	2.14072
2383.62	2.90408
2386.43	2.64788
2389.23	2.39241
2392.03	2.56893
2394.84	3.92667
2397.64	3.23836
2400.44	3.34911
2403.24	3.76563
2406.04	3.57841
2408.84	4.80557
2411.63	4.72027
2414.43	5.50963
2417.22	6.01776
2420.02	7.49917
2422.81	8.90007
2425.6	9.59594
2428.39	10.4031
2431.18	9.63071
2433.97	10.3236
2436.76	10.4643
2439.54	10.4174
2442.33	9.93663
2445.12	9.98606
2447.9	10.3892
2450.68	10.0458
2453.46	9.62993
2456.24	8.75988
2459.02	7.54228
2461.8	6.46558
2464.58	5.29337
2467.36	4.78277
2470.13	3.97586
2472.91	4.16018
2475.68	2.91217
2478.45	1.90318
2481.23	1.80745
2484	1.93186
2486.77	1.7016
2489.54	0.909275
2492.3	1.46803
2495.07	0.832545
2497.84	1.09655
2500.6	0.957404
2503.36	2.4056
2506.13	2.4783
2508.89	3.17415
2511.65	3.80685
2514.41	4.8132
2517.17	4.99638
2519.93	5.37064
2522.68	5.61797
2525.44	5.25911
2528.19	5.25589
2530.95	5.76217
2533.7	6.53145
2536.45	6.22336
2539.2	6.09771
2541.95	5.69778
2544.7	5.6271
2547.45	5.76096
2550.2	6.15588
2552.94	6.78049
2555.69	6.86861
2558.43	8.00783
2561.18	8.52199
2563.92	8.18397
2566.66	7.9734
2569.4	8.31062
2572.14	8.23852
2574.88	8.29076
2577.61	8.75876
2580.35	9.57392
2583.09	10.02
2585.82	10.1601
2588.55	11.0933
2591.29	11.481
2594.02	10.5421
2596.75	10.223
2599.48	9.53858
2602.21	8.61135
2604.93	7.50783
2607.66	5.89393
2610.39	4.85612
2613.11	4.87811
2615.83	4.43475
2618.56	4.82931
2621.28	4.13388
2624	3.99909
2626.72	2.58622
2629.44	1.97619
2632.15	2.05118
2634.87	2.46008
2637.59	3.25167
2640.3	4.58054
2643.02	4.62781
2645.73	4.93555
2648.44	6.15435
2651.15	6.32554
2653.86	6.8922
2656.57	7.63546
2659.28	6.71323
2661.99	6.49545
2664.69	6.61423
2667.4	5.87827
2670.1	4.53046
2672.81	5.24124
2675.51	6.09939
2678.21	6.74408
2680.91	6.60871
2683.61	7.55317
2686.31	6.94372
2689	6.6462
2691.7	8.39544
2694.4	9.62257
2697.09	10.8202
2699.79	12.4206
2702.48	13.8696
2705.17	15.8003
2707.86	16.0533
2710.55	15.8808
2713.24	17.2904
2715.93	18.0664
2718.62	18.1169
2721.3	18.1537
2723.99	18.306
2726.67	17.5625
2729.35	17.3906
2732.04	16.309
2734.72	14.6695
2737.4	14.5226
2740.08	13.912
2742.76	12.5901
2745.43	10.514
2748.11	8.35362
2750.79	7.34846
2753.46	5.02793
2756.14	4.05649
2758.81	3.5336
2761.48	2.45353
2764.15	1.68609
2766.82	1.00571
2769.49	1.79595
2772.16	1.42589
2774.82	-0.00238303
2777.49	0.328004
2780.16	-0.0265722
2782.82	0.50383
2785.48	0.767896
2788.15	0.873892
2790.81	0.582355
2793.47	1.17482
2796.13	1.45233
2798.79	1.97503
2801.44	2.9655
2804.1	3.77445
2806.76	3.32953
2809.41	2.37253
2812.07	1.39483
2814.72	2.71941
2817.37	2.85059
2820.02	3.5015
2822.67	5.85846
2825.32	8.63724
2827.97	11.306
2830.62	14.4069
2833.26	18.4836
2835.91	23.2172
2838.56	27.4025
2841.2	33.0508
2843.84	39.3232
2846.48	45.1569
2849.12	53.2713
2851.77	60.9423
2854.4	68.8776
2857.04	77.5897
2859.68	86.3803
2862.32	94.4664
2864.95	102.255
2867.59	109.143
2870.22	115.609
2872.85	120.139
2875.48	125.597
2878.11	130.339
2880.74	134.759
2883.37	138.606
2886	141.84
2888.63	145.812
2891.25	148.316
2893.88	151.54
2896.5	154.89
2899.13	159.518
2901.75	163.714
2904.37	169.674
2906.99	176.272
2909.61	183.725
2912.23	191.657
2914.85	200.463
2917.46	208.07
2920.08	215.62
2922.7	222.271
2925.31	226.769
2927.92	229.939
2930.54	231.04
2933.15	231.094
2935.76	229.236
2938.37	226.524
2940.98	221.179
2943.58	215.061
2946.19	208.301
2948.8	201.202
2951.4	193.61
2954.01	185.522
2956.61	177.805
2959.21	169.153
2961.81	161.652
2964.41	154.442
2967.01	146.726
2969.61	141.166
2972.21	134.67
2974.81	128.095
2977.4	120.794
2980	114.845
2982.59	106.707
2985.18	99.2107
2987.78	90.4926
2990.37	81.2298
2992.96	73.1162
2995.55	64.9016
2998.14	56.3009
3000.73	49.0508
3003.31	40.8151
3005.9	33.5239
3008.48	27.8419
3011.07	23.9854
3013.65	19.1371
3016.23	15.45
3018.81	11.9724
3021.4	9.18447
3023.97	7.61976
3026.55	4.77065
3029.13	3.49682
3031.71	1.90829
3034.28	1.66522
3036.86	1.98526
3039.43	2.62197
3042.01	4.17216
3044.58	5.35269
3047.15	5.64324
3049.72	6.37511
3052.29	6.26243
3054.86	7.48621
3057.43	8.66006
3060	9.06297
3062.56	8.78617
3065.13	8.72216
3067.69	7.76829
3070.26	7.43721
3072.82	7.22367
3075.38	6.00396
3077.94	4.59596
3080.5	3.77103
3083.06	2.46985
3085.62	1.14657
3088.18	0.17069
3090.73	-1.19302
3093.29	-1.2219
3095.84	-0.830538
3098.4	-0.173277
3100.95	0.400193
3103.5	0.953364
3106.05	2.27403
3108.6	2.20072
3111.15	3.06591
3113.7	4.55303
3116.25	5.37401
3118.79	7.68559
3121.34	9.24493
3123.88	10.7847
3126.43	12.3985
3128.97	13.4501
3131.51	15.7499
3134.06	17.6445
3136.6	20.112
3139.14	22.7997
3141.67	25.4009
3144.21	28.3603
3146.75	31.849
3149.29	36.4228