File: data/Raman/poly_smoothed/Thy_00_07_20_1x_45s_532 nm_x100_100%_600 gr_mm_01.txt
#Acq. time (s)=	45
#Accumulations=	2
#Range (cm-¹)=	200...3150
#Windows=	2
#Auto scanning=	Off
#Autofocus=	Off
#Macrospot=	Off
#AutoExposure=	Off
#Spike filter=	Multiple accum.
#Delay time (s)=	0
#Binning=	1
#Readout mode=	Signal
#DeNoise=	Off
#ICS correction=	On
#Dark correction=	Off
#Inst. Process=	Off
#Detector Gain=	Best Dynamic Range
#Detector ADC=	20 kHz
#Detector temperature (°C)=	-69.85
#Instrument=	LabRAM HR Evol
#Detector=	Synapse
#Objective=	x100
#Grating=	600 gr/mm
#ND Filter=	100%
#Laser (nm)=	532
#Hole=	100.021
#Range=	Auto
#Laser Pol.=	No
#Raman. Pol.=	No
#Laser Pol. (°)=	-0.0007625
#Raman Pol. (°)=	89.9995
#Collection=	Microscope
#StageXY=	Marzhauser
#StageZ=	Marzhauser
#X (µm)=	9022.5
#Y (µm)=	-3077
#Z (µm)=	-55
#Full time(mm:ss)=	3:18
#Project=
#Sample=
#Site=
#Title=	Thy_00_07_20_2x_45s_532 nm_x100_100%_600 gr_mm
#Remark=
#Date=	28.06.2022 11:35
#Acquired=	28.06.2022 11:35:42
#Base:Fit=	10.08.2022 10:07:56
#Base:Sub=	10.08.2022 10:08:40
#Filter:Polynom=	16.08.2022 10:26:06
#AxisType[0]=Intens
#AxisUnit[0]=Cnt
#AxisType[1]=Spectr
#AxisUnit[1]=1/cm
200.407	44.0286
204.035	44.8332
207.665	44.6
211.291	43.3291
214.916	41.6501
218.541	40.7394
222.163	37.5191
225.785	34.7286
229.404	31.4205
233.022	29.6107
236.638	27.9134
240.255	25.2708
243.868	24.2372
247.48	22.9727
251.091	19.8114
254.702	16.9296
258.31	14.0256
261.916	13.7426
265.521	12.5207
269.125	11.1655
272.727	10.9875
276.328	9.51949
279.927	7.11873
283.525	5.55838
287.121	9.36728
290.716	7.96536
294.31	8.71483
297.9	12.9881
301.491	14.9519
305.081	15.1206
308.669	17.2736
312.256	17.9158
315.839	19.3942
319.423	20.6485
323.006	20.7028
326.585	20.9882
330.165	20.3047
333.741	21.0564
337.318	18.8857
340.894	15.8983
344.466	12.8775
348.039	11.13
351.608	8.92337
355.176	7.06002
358.745	5.04292
362.31	2.80781
365.876	2.40645
369.439	-0.00774704
373	0.353408
376.56	1.68301
380.12	1.60324
383.677	3.47309
387.233	5.42862
390.787	5.19268
394.34	7.05428
397.894	8.43254
401.444	8.46584
404.993	8.60071
408.54	9.32672
412.086	9.73271
415.631	9.65752
419.174	9.67276
422.716	8.16452
426.257	7.44485
429.794	7.24482
433.332	7.37776
436.868	7.565
440.403	6.0063
443.937	4.8893
447.468	4.35843
450.999	4.64763
454.528	4.30451
458.057	4.02548
461.582	3.23158
465.107	4.15309
468.629	3.94883
472.152	4.01757
475.672	4.05261
479.192	4.26107
482.709	5.21779
486.226	5.65345
489.74	7.43003
493.255	10.3061
496.767	13.1706
500.277	15.1297
503.788	14.8978
507.295	15.6315
510.801	16.7743
514.308	19.1625
517.811	20.1823
521.313	21.0805
524.814	19.9975
528.313	20.627
531.811	21.2819
535.308	22.1539
538.803	22.5987
542.297	19.8112
545.789	18.0119
549.281	16.0661
552.771	15.8121
556.259	13.9163
559.747	12.0386
563.233	10.9158
566.717	10.9733
570.2	10.742
573.68	9.15649
577.161	9.27209
580.64	9.09141
584.118	8.15145
587.593	5.78112
591.068	3.71781
594.54	1.88396
598.013	2.2316
601.484	1.75555
604.952	1.68178
608.421	2.07414
611.886	2.43429
615.35	2.04531
618.815	1.38486
622.276	4.28434
625.738	3.83443
629.197	4.05101
632.655	6.68027
636.113	9.04708
639.568	9.61557
643.021	9.78872
646.473	10.3842
649.924	12.3084
653.376	13.5877
656.824	12.8214
660.271	13.6155
663.716	13.6375
667.161	14.0395
670.604	14.1638
674.045	15.4071
677.486	16.5444
680.925	17.7846
684.361	18.3117
687.797	18.9439
691.232	20.2129
694.666	20.5601
698.099	20.178
701.528	22.3635
704.958	24.6466
708.387	26.9909
711.814	27.7692
715.238	30.7835
718.663	32.2378
722.084	32.7268
725.506	33.9432
728.925	37.4795
732.345	39.6593
735.761	40.7023
739.178	43.3123
742.592	44.8245
746.006	48.0506
749.417	53.1172
752.827	56.8872
756.236	63.4017
759.645	66.5672
763.051	69.5187
766.456	70.4891
769.859	71.1384
773.261	71.2471
776.664	70.4222
780.064	68.1772
783.462	69.2099
786.859	70.5192
790.255	71.3577
793.649	70.0448
797.042	72.2946
800.434	72.4721
803.823	73.8447
807.212	74.8965
810.6	74.7463
813.987	75.1632
817.372	74.0946
820.754	74.8642
824.137	75.6455
827.519	76.779
830.897	78.3944
834.276	77.9765
837.654	78.133
841.029	78.4943
844.404	76.0588
847.776	73.5023
851.149	69.7384
854.519	64.3494
857.889	60.5318
861.256	56.4846
864.622	53.0398
867.988	51.5861
871.351	49.4562
874.713	47.6666
878.074	46.668
881.435	45.8285
884.794	45.3917
888.15	43.8162
891.506	42.7623
894.861	42.8618
898.214	41.9937
901.566	41.8216
904.916	42.3153
908.266	43.0415
911.614	43.7074
914.961	44.5899
918.306	44.6427
921.651	46.5517
924.994	46.072
928.336	45.5643
931.674	45.6083
935.014	44.7075
938.352	44.3464
941.687	44.8822
945.022	43.8631
948.357	42.9383
951.688	42.443
955.02	41.2851
958.348	39.9703
961.678	36.5585
965.004	35.9591
968.331	38.8848
971.655	41.2127
974.979	43.7749
978.3	47.2958
981.62	48.1476
984.941	49.1021
988.259	48.5931
991.575	47.8594
994.89	48.9072
998.204	48.8554
1001.52	48.2349
1004.83	50.6153
1008.14	51.6934
1011.45	52.2398
1014.76	51.6852
1018.06	51.7973
1021.37	50.7748
1024.67	49.0266
1027.97	47.4033
1031.27	45.2013
1034.57	42.5256
1037.87	40.2074
1041.17	35.3351
1044.47	35.0262
1047.76	36.7129
1051.06	36.6874
1054.35	35.3
1057.64	34.1765
1060.93	31.76
1064.22	30.204
1067.5	27.8398
1070.79	26.3406
1074.08	25.5569
1077.36	24.0935
1080.64	21.7447
1083.92	21.053
1087.2	19.3821
1090.48	18.225
1093.76	18.437
1097.03	17.5446
1100.31	16.6165
1103.58	16.5877
1106.85	16.5615
1110.12	14.696
1113.39	12.2319
1116.66	10.3536
1119.93	9.61807
1123.19	8.87233
1126.46	7.87351
1129.72	7.59997
1132.98	7.75034
1136.24	8.61894
1139.5	7.87469
1142.76	9.22162
1146.01	8.41162
1149.27	6.64918
1152.53	5.65914
1155.78	3.17526
1159.03	2.67697
1162.28	2.26441
1165.53	0.145688
1168.78	2.41505
1172.02	4.7322
1175.27	5.46656
1178.51	7.26807
1181.76	9.4205
1185	10.7241
1188.24	13.3578
1191.48	15.0766
1194.71	16.9189
1197.95	21.0973
1201.19	23.7288
1204.42	25.3128
1207.65	28.989
1210.88	33.787
1214.12	39.4045
1217.35	42.7818
1220.57	44.9494
1223.8	46.5149
1227.03	49.5119
1230.25	53.2508
1233.47	55.6558
1236.69	57.5796
1239.92	58.6896
1243.13	59.984
1246.35	60.1361
1249.57	62.4867
1252.78	62.8933
1256	61.9123
1259.21	61.8776
1262.42	60.4481
1265.63	60.3205
1268.84	60.1403
1272.05	58.5605
1275.26	56.357
1278.46	56.7211
1281.67	57.2073
1284.87	58.9539
1288.07	60.525
1291.27	62.5898
1294.47	65.7856
1297.67	69.2245
1300.87	71.8882
1304.06	76.5081
1307.26	81.4682
1310.45	84.5387
1313.64	86.1423
1316.83	87.8718
1320.02	88.5909
1323.21	87.3695
1326.4	86.3445
1329.59	85.3764
1332.77	83.8682
1335.95	82.21
1339.14	82.0212
1342.32	78.8872
1345.5	75.7578
1348.67	71.8374
1351.85	68.2611
1355.03	64.3678
1358.2	61.288
1361.38	57.8289
1364.55	53.9494
1367.72	51.5717
1370.89	50.7833
1374.06	48.2142
1377.23	47.7742
1380.39	45.7987
1383.56	45.847
1386.72	46.5327
1389.89	45.162
1393.05	43.1347
1396.21	42.4196
1399.37	41.3319
1402.52	42.1939
1405.68	45.5514
1408.84	48.1608
1411.99	51.3241
1415.15	56.3927
1418.3	62.622
1421.45	67.9461
1424.6	75.788
1427.75	82.607
1430.89	88.589
1434.04	94.3495
1437.18	100.626
1440.33	106.25
1443.47	112.094
1446.61	115.467
1449.75	116.799
1452.89	118.141
1456.03	114.844
1459.16	109.868
1462.3	105.644
1465.43	97.851
1468.56	88.865
1471.7	79.019
1474.83	68.7785
1477.96	59.2087
1481.08	50.9955
1484.21	41.9976
1487.34	33.8489
1490.46	27.4991
1493.58	21.5111
1496.71	17.5112
1499.83	12.7292
1502.95	9.98129
1506.07	7.31407
1509.18	7.12097
1512.3	8.45664
1515.41	8.22243
1518.53	10.0081
1521.64	11.473
1524.75	12.9931
1527.86	15.0274
1530.97	17.338
1534.08	18.6878
1537.19	21.3132
1540.29	22.3624
1543.4	25.2922
1546.5	27.1518
1549.6	29.6107
1552.7	31.9972
1555.8	35.9697
1558.9	38.5472
1562	40.1007
1565.09	42.2708
1568.19	43.5843
1571.28	45.6147
1574.37	47.7812
1577.47	50.924
1580.56	53.1246
1583.64	56.7554
1586.73	59.5791
1589.82	61.4619
1592.9	63.3019
1595.99	66.6052
1599.07	68.1849
1602.15	69.1932
1605.23	71.0071
1608.31	70.537
1611.39	70.3336
1614.47	70.071
1617.55	69.9262
1620.62	70.5339
1623.7	69.7626
1626.77	71.7456
1629.84	71.7044
1632.91	73.1112
1635.98	74.9174
1639.05	77.4349
1642.11	81.0642
1645.18	84.7574
1648.24	89.1259
1651.31	92.9356
1654.37	95.5546
1657.43	97.7493
1660.49	99.007
1663.55	99.6762
1666.61	98.2523
1669.66	95.9182
1672.72	92.0173
1675.77	86.9225
1678.83	82.1783
1681.88	74.5983
1684.93	66.9293
1687.98	59.1067
1691.03	52.9083
1694.07	46.179
1697.12	39.0637
1700.17	32.0816
1703.21	26.6103
1706.25	22.9565
1709.29	19.6688
1712.33	18.2529
1715.37	15.8543
1718.41	15.0246
1721.45	14.1054
1724.49	14.1887
1727.52	13.2125
1730.55	12.8608
1733.59	14.2048
1736.62	13.6047
1739.65	12.6871
1742.68	12.4756
1745.7	12.7059
1748.73	12.1949
1751.76	11.8676
1754.78	11.5703
1757.8	9.71977
1760.83	9.12308
1763.85	8.1309
1766.87	7.04988
1769.89	5.56789
1772.9	3.86802
1775.92	3.39226
1778.94	3.25168
1781.95	2.78527
1784.96	2.38887
1787.97	1.7465
1790.99	1.61582
1794	2.32837
1797	2.49265
1800.01	1.99947
1803.02	1.37026
1806.02	1.19571
1809.03	1.32239
1812.03	1.54576
1815.03	2.62824
1818.03	3.00276
1821.03	3.58407
1824.03	3.37648
1827.03	3.46829
1830.02	2.67223
1833.02	2.39935
1836.01	2.96788
1839.01	3.44974
1842	4.50342
1844.99	4.57585
1847.98	4.87841
1850.97	5.61885
1853.95	6.72573
1856.94	6.46662
1859.93	6.38114
1862.91	4.95664
1865.89	4.65195
1868.87	4.53316
1871.85	3.95636
1874.83	3.91903
1877.81	3.80377
1880.79	3.9684
1882.52	3.40919
1885.51	3.69477
1888.5	2.93142
1891.49	2.50205
1894.47	3.40221
1897.46	2.89662
1900.44	2.80045
1903.42	4.03835
1906.4	4.84356
1909.38	6.08807
1912.36	6.42808
1915.34	6.5275
1918.32	6.78351
1921.29	6.92498
1924.27	6.63967
1927.24	6.32636
1930.21	5.73843
1933.18	5.09357
1936.15	4.41138
1939.12	3.9963
1942.09	4.40794
1945.06	4.63464
1948.02	4.1466
1950.99	4.55914
1953.95	4.04535
1956.91	3.5634
1959.88	3.93064
1962.84	4.92463
1965.8	5.24466
1968.75	5.06929
1971.71	5.41279
1974.67	4.87549
1977.62	5.14413
1980.58	4.87069
1983.53	5.33407
1986.48	5.68575
1989.43	5.38691
1992.38	5.46481
1995.33	4.41974
1998.27	4.51079
2001.22	4.10133
2004.16	4.13941
2007.11	4.06526
2010.05	3.45108
2012.99	3.83662
2015.93	2.56115
2018.87	2.48773
2021.81	3.00898
2024.75	2.49209
2027.69	1.65609
2030.62	1.60399
2033.56	1.64599
2036.49	0.722508
2039.42	1.24098
2042.35	1.10845
2045.28	1.40771
2048.21	2.0106
2051.14	3.25654
2054.07	3.93692
2056.99	4.18389
2059.92	5.59777
2062.84	6.28608
2065.76	5.78658
2068.68	6.05555
2071.6	6.74901
2074.52	6.88654
2077.44	7.32195
2080.36	7.76287
2083.27	7.41176
2086.19	7.20831
2089.1	6.87672
2092.02	6.6618
2094.93	6.25586
2097.84	5.80876
2100.75	5.49234
2103.66	5.99262
2106.56	6.0544
2109.47	6.57766
2112.38	6.98915
2115.28	7.05819
2118.18	6.86226
2121.09	6.58846
2123.99	7.33297
2126.89	8.03884
2129.79	8.54981
2132.68	8.02312
2135.58	8.02889
2138.48	6.76563
2141.37	6.9748
2144.27	7.26651
2147.16	6.93573
2150.05	6.74812
2152.94	5.37032
2155.83	5.29663
2158.72	5.6359
2161.6	4.58448
2164.49	3.77916
2167.38	4.43504
2170.26	5.30211
2173.14	5.24772
2176.03	5.63869
2178.91	6.00579
2181.79	6.82621
2184.67	6.82856
2187.54	7.73918
2190.42	8.64875
2193.3	9.08569
2196.17	10.0984
2199.05	9.7208
2201.92	8.76763
2204.79	8.89186
2207.66	8.66385
2210.53	7.6807
2213.4	8.03389
2216.27	7.96363
2219.13	7.26855
2222	7.01288
2224.86	6.43307
2227.72	7.25239
2230.59	6.5369
2233.45	6.18965
2236.31	6.63104
2239.17	6.73027
2242.03	6.51716
2244.88	6.7076
2247.74	7.77184
2250.59	7.32868
2253.45	7.96478
2256.3	7.39612
2259.15	7.0313
2262	6.96667
2264.85	6.81368
2267.7	7.16151
2270.55	7.24415
2273.4	7.3883
2276.24	6.85589
2279.09	6.32112
2281.93	6.87247
2284.77	7.37292
2287.62	6.90549
2290.46	5.52242
2293.3	4.23023
2296.13	4.30239
2298.97	4.9863
2301.81	4.52071
2304.64	3.83247
2307.48	2.76847
2310.31	3.3777
2313.14	3.53107
2315.98	4.36244
2318.81	5.01095
2321.64	5.46362
2324.46	5.32467
2327.29	6.05427
2330.12	7.21529
2332.94	8.59764
2335.77	9.70367
2338.59	9.72162
2341.41	9.82892
2344.23	9.48599
2347.05	8.41288
2349.87	7.39792
2352.69	6.2048
2355.51	4.47011
2358.32	2.97067
2361.14	1.83687
2363.95	1.62415
2366.76	1.93151
2369.58	1.30647
2372.39	0.245457
2375.2	0.345001
2378	0.423568
2380.81	1.4643
2383.62	1.10639
2386.43	1.65548
2389.23	2.77814
2392.03	3.71752
2394.84	4.5615
2397.64	5.49623
2400.44	6.55101
2403.24	7.80258
2406.04	8.05352
2408.84	7.58634
2411.63	7.7655
2414.43	8.44318
2417.22	8.21896
2420.02	9.56757
2422.81	9.58346
2425.6	9.60791
2428.39	10.0835
2431.18	9.48287
2433.97	9.30332
2436.76	8.84996
2439.54	8.39128
2442.33	7.41455
2445.12	6.13184
2447.9	5.88684
2450.68	5.44733
2453.46	4.90692
2456.24	4.73912
2459.02	5.00888
2461.8	4.59794
2464.58	3.90128
2467.36	4.40902
2470.13	5.76918
2472.91	5.43208
2475.68	4.86011
2478.45	4.9841
2481.23	5.95069
2484	5.66764
2486.77	6.56577
2489.54	5.87481
2492.3	5.89936
2495.07	5.73118
2497.84	4.51567
2500.6	3.73592
2503.36	3.86735
2506.13	2.99236
2508.89	1.85451
2511.65	1.86763
2514.41	2.5281
2517.17	2.56386
2519.93	3.16581
2522.68	3.7427
2525.44	4.60687
2528.19	4.15802
2530.95	4.03713
2533.7	5.00295
2536.45	5.24334
2539.2	4.82467
2541.95	4.25723
2544.7	4.31198
2547.45	4.16321
2550.2	4.01434
2552.94	3.98678
2555.69	3.48608
2558.43	3.00918
2561.18	2.92913
2563.92	3.00264
2566.66	2.63913
2569.4	3.76307
2572.14	3.39229
2574.88	2.06394
2577.61	2.94671
2580.35	2.73051
2583.09	2.63748
2585.82	3.17941
2588.55	3.2334
2591.29	3.35989
2594.02	2.77596
2596.75	2.5644
2599.48	3.13003
2602.21	3.09814
2604.93	2.9242
2607.66	3.21763
2610.39	3.65684
2613.11	4.42036
2615.83	5.39523
2618.56	5.31918
2621.28	6.16549
2624	7.46311
2626.72	6.96755
2629.44	7.73821
2632.15	8.41351
2634.87	8.22786
2637.59	7.94086
2640.3	7.67285
2643.02	7.47771
2645.73	7.75651
2648.44	7.29732
2651.15	6.53234
2653.86	5.27172
2656.57	4.99238
2659.28	3.89352
2661.99	3.13247
2664.69	2.66381
2667.4	1.32464
2670.1	0.797043
2672.81	0.182856
2675.51	0.937948
2678.21	0.433861
2680.91	0.902231
2683.61	1.96152
2686.31	2.67433
2689	4.13441
2691.7	5.28313
2694.4	7.0036
2697.09	8.1092
2699.79	9.4958
2702.48	10.717
2705.17	12.5283
2707.86	13.682
2710.55	15.4233
2713.24	16.8441
2715.93	17.5791
2718.62	17.7455
2721.3	17.7282
2723.99	17.0164
2726.67	15.7857
2729.35	14.1654
2732.04	12.713
2734.72	11.7646
2737.4	9.89765
2740.08	8.96766
2742.76	7.98047
2745.43	7.69385
2748.11	6.60104
2750.79	5.79875
2753.46	5.23245
2756.14	4.32452
2758.81	3.45148
2761.48	2.91388
2764.15	2.07428
2766.82	1.66408
2769.49	2.10563
2772.16	2.47921
2774.82	3.0592
2777.49	4.13399
2780.16	4.97965
2782.82	4.84028
2785.48	4.47218
2788.15	3.88306
2790.81	3.31993
2793.47	2.74089
2796.13	2.29726
2798.79	2.53837
2801.44	2.44895
2804.1	1.42374
2806.76	2.00707
2809.41	1.63103
2812.07	1.04122
2814.72	1.48202
2817.37	3.01902
2820.02	4.64955
2822.67	7.19907
2825.32	10.9887
2827.97	15.2911
2830.62	20.1368
2833.26	26.8828
2835.91	33.1325
2838.56	39.9786
2841.2	49.009
2843.84	57.511
2846.48	67.3059
2849.12	77.1498
2851.77	87.9323
2854.4	100.129
2857.04	111.937
2859.68	123.394
2862.32	133.699
2864.95	144.149
2867.59	152.524
2870.22	161.244
2872.85	168.895
2875.48	175.919
2878.11	181.767
2880.74	187.333
2883.37	191.349
2886	196.494
2888.63	200.449
2891.25	203.663
2893.88	208.646
2896.5	214.2
2899.13	219.281
2901.75	226.106
2904.37	233.655
2906.99	241.973
2909.61	252.595
2912.23	265.217
2914.85	276.423
2917.46	288.401
2920.08	298.457
2922.7	306.374
2925.31	312.022
2927.92	314.758
2930.54	315.777
2933.15	315.502
2935.76	313.242
2938.37	308.628
2940.98	301.222
2943.58	294.098
2946.19	285.153
2948.8	275.273
2951.4	265.703
2954.01	254.591
2956.61	244.52
2959.21	235.647
2961.81	227.341
2964.41	218.066
2967.01	208.971
2969.61	199.23
2972.21	192.345
2974.81	184.61
2977.4	177.678
2980	167.9
2982.59	157.346
2985.18	146.521
2987.78	135.071
2990.37	122.888
2992.96	110.816
2995.55	99.4235
2998.14	89.1863
3000.73	79.1599
3003.31	68.7197
3005.9	58.8805
3008.48	51.1287
3011.07	44.1158
3013.65	37.4937
3016.23	31.7721
3018.81	27.0961
3021.4	23.3555
3023.97	19.8795
3026.55	16.9264
3029.13	14.1861
3031.71	12.9668
3034.28	12.1204
3036.86	12.6969
3039.43	13.7338
3042.01	15.1691
3044.58	15.6159
3047.15	17.2287
3049.72	18.6359
3052.29	19.3118
3054.86	19.9541
3057.43	20.7381
3060	21.4403
3062.56	22.2868
3065.13	22.3467
3067.69	22.6488
3070.26	21.6945
3072.82	20.5329
3075.38	18.6746
3077.94	15.8676
3080.5	13.5641
3083.06	11.3613
3085.62	10.2922
3088.18	8.2861
3090.73	7.18135
3093.29	5.43574
3095.84	5.07399
3098.4	4.62851
3100.95	5.31902
3103.5	5.54744
3106.05	6.50352
3108.6	7.54643
3111.15	8.42117
3113.7	9.42595
3116.25	10.1055
3118.79	11.4053
3121.34	12.786
3123.88	14.1765
3126.43	15.7881
3128.97	17.2261
3131.51	16.893
3134.06	17.2324
3136.6	17.4429
3139.14	17.5145
3141.67	18.012
3144.21	18.0856
3146.75	17.589
3149.29	17.8882