File: data/Raman/poly_smoothed/Thy_30_10_35_1x_45s_532 nm_x100_100%_600 gr_mm_01.txt
#Acq. time (s)=	45
#Accumulations=	2
#Range (cm-¹)=	200...3150
#Windows=	2
#Auto scanning=	Off
#Autofocus=	Off
#Macrospot=	Off
#AutoExposure=	Off
#Spike filter=	Multiple accum.
#Delay time (s)=	0
#Binning=	1
#Readout mode=	Signal
#DeNoise=	Off
#ICS correction=	On
#Dark correction=	Off
#Inst. Process=	Off
#Detector Gain=	Best Dynamic Range
#Detector ADC=	20 kHz
#Detector temperature (°C)=	-69.85
#Instrument=	LabRAM HR Evol
#Detector=	Synapse
#Objective=	x100
#Grating=	600 gr/mm
#ND Filter=	100%
#Laser (nm)=	532
#Hole=	100.021
#Range=	Auto
#Laser Pol.=	No
#Raman. Pol.=	No
#Laser Pol. (°)=	-0.0007625
#Raman Pol. (°)=	89.9995
#Collection=	Microscope
#StageXY=	Marzhauser
#StageZ=	Marzhauser
#X (µm)=	4741
#Y (µm)=	-7720.3
#Z (µm)=	584.9
#Full time(mm:ss)=	3:18
#Project=
#Sample=
#Site=
#Title=	Thy_30_10_35_2x_45s_532 nm_x100_100%_600 gr_mm
#Remark=
#Date=	30.06.2022 13:58
#Acquired=	30.06.2022 13:58:16
#Base:Fit=	10.08.2022 09:58:11
#Base:Sub=	10.08.2022 09:58:44
#Filter:Polynom=	16.08.2022 10:22:53
#AxisType[0]=Intens
#AxisUnit[0]=Cnt
#AxisType[1]=Spectr
#AxisUnit[1]=1/cm
200.533	25.4542
204.162	19.7063
207.792	13.9265
211.418	9.47872
215.044	7.14855
218.667	3.84256
222.289	2.42996
225.912	2.31805
229.531	3.05677
233.148	1.46574
236.766	1.04613
240.381	2.1517
243.994	4.1678
247.606	5.71971
251.217	8.11763
254.828	10.6811
258.436	11.3282
262.042	12.8981
265.647	13.3795
269.25	14.0281
272.852	15.2495
276.453	14.6005
280.052	13.7833
283.65	14.4298
287.247	15.2411
290.842	13.858
294.436	12.3573
298.028	11.6549
301.617	11.1282
305.206	10.3568
308.794	8.69787
312.381	7.74397
315.964	6.13631
319.548	4.72768
323.131	3.22766
326.71	2.64617
330.29	2.1603
333.868	2.2761
337.443	1.76712
341.018	2.45373
344.591	1.35011
348.163	1.41314
351.733	3.09543
355.303	0.967769
358.869	1.57572
362.435	1.3637
366.001	0.80928
369.563	1.26572
373.124	1.62914
376.686	1.01702
380.244	1.54952
383.801	1.8006
387.357	1.70482
390.911	3.05131
394.466	1.90258
398.018	1.1999
401.568	1.2365
405.117	2.51977
408.664	1.79101
412.21	2.73345
415.755	3.37675
419.298	6.81998
422.84	8.08926
426.38	8.21713
429.919	7.36182
433.455	8.09349
436.992	7.83933
440.527	6.887
444.06	7.5498
447.593	7.6363
451.122	6.55485
454.651	6.8456
458.18	6.44343
461.705	5.87276
465.23	6.26695
468.752	7.32597
472.275	5.98843
475.797	6.76919
479.315	7.9863
482.834	9.4617
486.349	11.7709
489.863	13.9531
493.378	16.3515
496.889	16.4236
500.401	17.3029
503.91	19.6625
507.417	20.5603
510.923	21.5091
514.43	21.5486
517.933	21.5222
521.435	22.5424
524.936	20.7927
528.435	21.6595
531.933	22.4093
535.43	21.5949
538.927	21.4723
542.421	21.907
545.913	20.7776
549.403	21.0571
552.893	21.2688
556.381	21.0947
559.868	22.2475
563.354	22.6192
566.839	24.8752
570.322	24.2145
573.802	24.6508
577.283	23.5622
580.762	22.6884
584.24	23.3352
587.714	26.1994
591.19	26.4661
594.663	25.2172
598.134	25.7255
601.605	23.7033
605.073	22.5701
608.542	21.8552
612.007	22.5912
615.473	25.2472
618.936	26.2008
622.397	25.8498
625.859	26.3533
629.318	26.9198
632.775	26.9204
636.233	25.4827
639.688	25.9271
643.142	26.0248
646.594	27.3009
650.045	28.0921
653.496	28.3158
656.944	29.4231
660.391	30.1919
663.837	30.651
667.281	32.7496
670.724	34.9677
674.166	35.861
677.606	35.3737
681.045	37.8745
684.483	39.6535
687.917	42.0247
691.352	43.8003
694.786	46.5881
698.219	49.6661
701.65	51.0885
705.078	51.5523
708.506	51.8628
711.934	52.8024
715.358	51.4897
718.782	52.5782
722.204	53.3712
725.626	55.4506
729.045	56.5183
732.464	58.6497
735.881	59.6934
739.297	63.1744
742.711	65.8475
746.125	69.3087
749.537	72.613
752.946	76.5651
756.357	82.1228
759.764	87.412
763.17	91.8635
766.575	99.3614
769.978	103.193
773.382	105.852
776.783	108.89
780.182	113.629
783.581	114.938
786.978	118.805
790.373	122.915
793.768	125.903
797.161	128.262
800.552	129.275
803.941	131.003
807.33	130.569
810.718	132.728
814.105	133.811
817.49	134.543
820.873	134.07
824.256	134.702
827.637	134.465
831.016	133.239
834.395	133.454
837.772	133.304
841.147	129.891
844.522	128.369
847.894	127.551
851.267	125.9
854.637	123.191
858.007	118.754
861.374	116.71
864.739	114.418
868.106	112.746
871.469	112.554
874.831	110.657
878.193	108.126
881.553	104.548
884.911	101.279
888.268	100.066
891.623	98.0667
894.978	93.7183
898.331	91.5129
901.683	90.7125
905.033	88.9739
908.383	86.7515
911.731	85.4361
915.078	83.9351
918.423	82.3743
921.768	78.5409
925.111	78.1845
928.452	76.7191
931.791	73.5902
935.13	71.4907
938.468	69.403
941.803	67.5166
945.139	65.0594
948.473	62.4943
951.804	60.763
955.136	60.7581
958.465	58.4769
961.794	54.0836
965.12	50.9052
968.447	50.7872
971.771	50.3473
975.095	47.7321
978.417	46.5537
981.737	46.2383
985.057	44.9189
988.375	41.0458
991.691	40.0472
995.006	40.8451
998.32	40.6254
1001.63	42.0039
1004.95	42.327
1008.26	40.8081
1011.56	41.3487
1014.87	41.126
1018.18	41.4422
1021.48	40.4759
1024.79	38.729
1028.09	36.9469
1031.39	36.6349
1034.69	36.6649
1037.99	34.0289
1041.29	32.0913
1044.58	31.2398
1047.88	30.8863
1051.17	30.5015
1054.46	28.1372
1057.75	25.4965
1061.04	23.9504
1064.33	18.7231
1067.62	17.8993
1070.9	18.1839
1074.19	19.1858
1077.47	20.9277
1080.76	20.2552
1084.04	21.016
1087.32	22.1228
1090.59	23.1486
1093.87	23.6442
1097.15	21.958
1100.42	22.1568
1103.69	21.2485
1106.97	20.1576
1110.24	19.3692
1113.51	18.8821
1116.77	20.9207
1120.04	18.1422
1123.31	18.1947
1126.57	16.6593
1129.83	17.8217
1133.1	15.5986
1136.36	13.4146
1139.62	12.6972
1142.87	10.1735
1146.13	7.73288
1149.38	7.64172
1152.64	6.96383
1155.89	5.79127
1159.14	5.34328
1162.39	3.75459
1165.64	5.32529
1168.89	4.27162
1172.14	4.22772
1175.38	4.60928
1178.63	4.682
1181.87	4.78223
1185.11	4.86661
1188.35	4.61428
1191.59	6.01124
1194.83	7.52167
1198.07	9.77067
1201.3	11.6034
1204.53	15.8094
1207.77	20.2554
1211	23.8059
1214.23	24.3604
1217.46	28.8147
1220.69	30.5964
1223.91	33.4857
1227.14	36.201
1230.36	37.941
1233.59	41.3025
1236.81	42.6605
1240.03	43.6965
1243.25	46.0061
1246.46	49.0147
1249.68	50.9129
1252.9	54.0752
1256.11	53.697
1259.32	53.3037
1262.54	52.9567
1265.75	52.4883
1268.96	54.3775
1272.16	55.1963
1275.37	57.4749
1278.57	59.5738
1281.78	61.235
1284.98	61.7324
1288.18	62.2937
1291.38	62.2882
1294.58	63.4752
1297.78	64.094
1300.98	65.2008
1304.17	66.4021
1307.37	66.1979
1310.56	67.9629
1313.76	67.8579
1316.95	66.3477
1320.14	67.2262
1323.32	66.4984
1326.51	66.9286
1329.7	65.9168
1332.88	66.3614
1336.07	62.5826
1339.25	63.1441
1342.43	61.0969
1345.61	58.851
1348.79	57.3298
1351.96	55.0915
1355.14	52.7002
1358.31	51.6998
1361.49	49.1339
1364.66	45.8272
1367.83	43.4642
1371	40.8334
1374.17	38.5505
1377.34	37.0893
1380.5	35.9587
1383.67	36.2824
1386.83	35.249
1390	32.9038
1393.16	31.9298
1396.32	30.1727
1399.48	30.429
1402.64	30.8179
1405.79	30.8164
1408.95	30.4699
1412.1	32.1122
1415.26	35.5343
1418.41	39.4099
1421.56	40.5969
1424.71	45.492
1427.86	50.7456
1431	55.8581
1434.15	59.5254
1437.29	62.713
1440.44	64.4105
1443.58	67.5373
1446.72	68.4322
1449.86	67.2889
1453	67.9502
1456.14	66.9573
1459.27	64.5573
1462.41	62.7168
1465.54	59.336
1468.67	52.1292
1471.81	44.9606
1474.94	37.5207
1478.07	30.5213
1481.19	24.0621
1484.32	18.6633
1487.45	14.3622
1490.57	11.8545
1493.69	8.2226
1496.82	5.03432
1499.94	3.0339
1503.06	2.20052
1506.17	1.87134
1509.29	2.45791
1512.41	2.40169
1515.52	2.97636
1518.64	5.04493
1521.75	5.55961
1524.86	6.39768
1527.97	8.56246
1531.08	10.645
1534.19	13.1719
1537.29	14.0477
1540.4	18.3638
1543.5	19.9864
1546.61	20.3433
1549.71	23.1519
1552.81	25.8874
1555.91	30.2967
1559.01	32.4222
1562.11	36.7139
1565.2	40.3248
1568.29	41.1893
1571.39	44.2755
1574.48	46.446
1577.57	49.5935
1580.66	50.4889
1583.75	51.4315
1586.84	54.2796
1589.93	53.8845
1593.01	53.5763
1596.1	52.7932
1599.18	51.0031
1602.26	49.6164
1605.34	48.3149
1608.42	47.361
1611.5	46.4697
1614.58	45.3974
1617.65	47.2021
1620.73	46.7436
1623.8	49.0284
1626.87	50.8249
1629.95	53.4389
1633.02	57.6567
1636.09	61.6722
1639.15	64.2443
1642.22	66.2622
1645.29	67.9928
1648.35	71.0559
1651.42	73.6839
1654.48	75.2836
1657.54	76.7197
1660.6	76.6945
1663.66	75.0385
1666.72	70.7481
1669.77	67.41
1672.83	64.6629
1675.88	59.7415
1678.93	56.5411
1681.99	51.2494
1685.04	45.2654
1688.09	40.9311
1691.13	35.6848
1694.18	30.1936
1697.23	25.8845
1700.27	22.5497
1703.32	19.5196
1706.36	15.298
1709.4	13.5015
1712.44	10.2874
1715.48	5.57044
1718.52	3.40992
1721.56	2.94386
1724.59	3.53245
1727.63	3.15394
1730.66	3.42838
1733.69	1.86955
1736.72	1.4188
1739.75	0.368265
1742.78	1.51313
1745.81	3.34491
1748.84	4.43153
1751.86	4.57043
1754.89	5.78855
1757.91	5.61268
1760.93	5.16218
1763.95	5.10665
1766.97	4.41092
1769.99	5.35267
1773.01	6.85764
1776.03	8.77228
1779.04	7.10407
1782.06	6.68986
1785.07	7.87733
1788.08	7.05237
1791.09	7.59976
1794.1	7.85555
1797.11	8.47433
1800.12	10.2263
1803.12	9.47558
1806.13	10.8312
1809.13	11.9787
1812.14	14.2597
1815.14	15.5138
1818.14	17.8567
1821.14	19.9453
1824.14	22.1791
1827.13	24.4493
1830.13	25.5021
1833.12	26.8645
1836.12	27.4139
1839.11	27.3631
1842.1	27.7854
1845.09	28.7014
1848.08	29.6204
1851.07	29.3362
1854.06	30.0708
1857.04	31.6368
1860.03	32.6154
1863.01	33.815
1866	33.784
1868.98	34.7428
1871.96	34.729
1874.94	35.2224
1877.92	35.6552
1880.89	36.7513
1882.48	38.196
1885.47	38.5232
1888.46	39.7468
1891.44	40.6332
1894.43	39.9479
1897.41	39.5259
1900.4	37.6362
1903.38	36.0075
1906.36	33.7997
1909.34	32.1162
1912.32	31.0534
1915.29	31.4034
1918.27	30.51
1921.25	29.9432
1924.22	30.2527
1927.2	29.8156
1930.17	29.3036
1933.14	29.9747
1936.11	29.5644
1939.08	28.4618
1942.05	27.5884
1945.01	25.9859
1947.98	25.8752
1950.94	24.8595
1953.91	24.6605
1956.87	25.2933
1959.83	25.2682
1962.79	23.7273
1965.75	22.3021
1968.71	23.4585
1971.67	23.323
1974.62	24.4344
1977.58	24.6885
1980.53	24.8467
1983.48	26.4439
1986.43	26.9757
1989.38	26.3352
1992.33	25.4561
1995.28	27.6856
1998.23	27.3608
2001.18	28.2378
2004.12	28.6311
2007.06	28.762
2010.01	27.781
2012.95	25.133
2015.89	25.5324
2018.83	24.0366
2021.77	23.9433
2024.71	22.9028
2027.64	24.0495
2030.58	24.2845
2033.51	22.725
2036.45	23.2999
2039.38	24.2473
2042.31	24.3184
2045.24	26.544
2048.17	27.8882
2051.1	27.844
2054.02	28.9648
2056.95	30.3552
2059.87	30.776
2062.8	32.3641
2065.72	32.7864
2068.64	33.2551
2071.56	34.0446
2074.48	33.9967
2077.4	33.7437
2080.31	33.6936
2083.23	33.4203
2086.14	34.6904
2089.06	35.4198
2091.97	35.427
2094.88	37.7575
2097.79	37.3368
2100.7	38.5317
2103.61	38.9816
2106.52	40.9503
2109.43	42.1066
2112.33	45.0381
2115.24	47.6684
2118.14	50.8307
2121.04	52.8867
2123.94	56.1216
2126.84	59.0104
2129.74	61.6033
2132.64	65.1047
2135.54	67.0737
2138.43	70.5519
2141.33	72.3117
2144.22	73.4709
2147.11	76.3298
2150.01	79.3321
2152.9	80.8192
2155.79	82.1794
2158.67	84.3643
2161.56	85.4717
2164.45	86.6278
2167.33	87.2913
2170.22	87.0139
2173.1	88.0561
2175.98	88.4363
2178.86	88.6715
2181.74	87.7567
2184.62	87.0218
2187.5	85.543
2190.38	85.449
2193.25	83.3641
2196.13	82.0372
2199	78.5866
2201.88	76.3612
2204.75	73.2272
2207.62	69.9323
2210.49	66.6436
2213.36	63.3857
2216.22	60.0208
2219.09	58.0948
2221.96	54.0348
2224.82	51.2644
2227.68	49.0311
2230.55	47.2444
2233.41	45.0289
2236.27	43.0263
2239.12	42.4133
2241.98	41.0405
2244.84	39.9203
2247.7	38.623
2250.55	37.8798
2253.41	37.0945
2256.26	36.0961
2259.11	36.8943
2261.96	36.4417
2264.81	36.5175
2267.66	34.642
2270.51	34.3281
2273.35	33.3377
2276.2	32.741
2279.04	32.0916
2281.89	30.9774
2284.73	30.7394
2287.57	29.676
2290.41	28.2411
2293.25	26.9018
2296.09	27.2745
2298.93	27.3995
2301.76	27.7731
2304.6	27.2895
2307.44	27.6966
2310.27	26.2663
2313.1	25.0463
2315.93	22.7212
2318.76	22.8848
2321.59	21.7928
2324.42	20.9401
2327.25	20.6399
2330.07	19.9486
2332.9	18.2545
2335.72	17.149
2338.55	15.9709
2341.37	15.1614
2344.19	13.2003
2347.01	12.7004
2349.83	10.2898
2352.65	10.1225
2355.46	9.79107
2358.28	9.97399
2361.09	10.8365
2363.91	11.9864
2366.72	13.1207
2369.53	13.3343
2372.34	13.5758
2375.15	13.0705
2377.96	12.4651
2380.77	11.8209
2383.58	10.3341
2386.38	11.1603
2389.19	10.5562
2391.99	10.9133
2394.8	10.0596
2397.6	10.0855
2400.4	10.3121
2403.2	9.88112
2406	8.96523
2408.79	8.80072
2411.59	8.75845
2414.39	9.09244
2417.18	8.80922
2419.98	9.60963
2422.77	11.3421
2425.56	10.6881
2428.35	10.7167
2431.14	10.1429
2433.93	9.225
2436.72	9.03696
2439.5	7.46679
2442.29	5.81526
2445.07	5.42735
2447.86	2.65462
2450.64	1.77061
2453.42	1.27233
2456.2	0.755231
2458.98	0.899237
2461.76	1.62038
2464.54	1.24687
2467.32	2.40441
2470.09	2.65976
2472.87	2.05657
2475.64	2.05663
2478.41	2.50979
2481.18	3.20554
2483.95	3.51846
2486.72	3.40126
2489.49	4.01322
2492.26	4.54433
2495.03	4.39961
2497.79	4.42763
2500.56	5.29566
2503.32	3.68128
2506.09	3.555
2508.85	3.53395
2511.61	3.54539
2514.37	1.82121
2517.13	2.04797
2519.89	1.97494
2522.64	3.01011
2525.4	2.53499
2528.15	4.00783
2530.91	4.77058
2533.66	5.80057
2536.41	6.17423
2539.16	6.01132
2541.91	5.88151
2544.66	6.59873
2547.41	7.36119
2550.16	8.48314
2552.9	8.82339
2555.65	10.2795
2558.39	10.98
2561.13	10.5321
2563.88	9.41058
2566.62	8.82168
2569.36	7.88196
2572.1	6.97157
2574.84	5.33948
2577.57	4.35437
2580.31	2.59311
2583.05	2.01934
2585.78	1.24705
2588.51	-0.308567
2591.24	-0.432647
2593.98	-0.476112
2596.71	-0.16624
2599.44	1.04312
2602.16	0.966362
2604.89	2.1235
2607.62	2.92283
2610.34	4.77723
2613.07	6.04296
2615.79	7.07842
2618.52	7.23642
2621.24	6.80388
2623.96	7.67304
2626.68	5.86651
2629.4	5.14045
2632.11	6.15911
2634.83	7.54239
2637.55	7.03258
2640.26	6.61464
2642.98	5.84091
2645.69	6.07896
2648.4	4.9527
2651.11	4.4874
2653.82	3.0114
2656.53	3.36823
2659.24	3.16218
2661.95	3.16114
2664.65	4.19467
2667.36	4.26401
2670.06	5.37609
2672.76	6.21154
2675.47	6.06404
2678.17	6.97769
2680.87	7.39818
2683.57	5.97695
2686.27	7.31443
2688.97	6.55285
2691.66	7.04891
2694.36	8.22974
2697.05	9.96444
2699.75	11.7689
2702.44	10.9371
2705.13	11.0013
2707.82	12.3622
2710.51	12.5816
2713.2	13.3936
2715.89	13.9015
2718.57	15.1261
2721.26	15.7223
2723.95	17.0808
2726.63	18.6992
2729.31	18.7212
2732	19.1319
2734.68	19.7476
2737.36	19.5259
2740.04	19.0723
2742.72	18.6448
2745.39	18.5815
2748.07	17.445
2750.75	16.8498
2753.42	15.8917
2756.09	14.7791
2758.77	15.0837
2761.44	15.6582
2764.11	15.5589
2766.78	15.7612
2769.45	15.0348
2772.12	15.0201
2774.78	15.0583
2777.45	15.877
2780.12	16.4192
2782.78	16.387
2785.44	15.6452
2788.11	16.6445
2790.77	16.6538
2793.43	17.0828
2796.09	18.1594
2798.75	18.5548
2801.4	18.5337
2804.06	18.9058
2806.72	18.8837
2809.37	18.9957
2812.03	18.7736
2814.68	18.8799
2817.33	18.7188
2819.98	21.4748
2822.63	23.8598
2825.28	26.5538
2827.93	31.6085
2830.58	37.2373
2833.23	41.3741
2835.87	46.4601
2838.52	53.0305
2841.16	59.7037
2843.8	67.0913
2846.44	75.3713
2849.08	85.8726
2851.73	97.246
2854.36	108.047
2857	118.343
2859.64	128.05
2862.28	138.66
2864.91	146.117
2867.55	154.538
2870.18	161.891
2872.81	166.511
2875.44	171.4
2878.07	174.43
2880.7	179.699
2883.33	184.506
2885.96	188.39
2888.59	192.123
2891.21	197.497
2893.84	202.759
2896.46	206.028
2899.09	212.28
2901.71	219.23
2904.33	226.434
2906.95	236.002
2909.57	247.899
2912.19	260.267
2914.81	271.854
2917.43	282.143
2920.04	292.25
2922.66	300.001
2925.27	305.826
2927.88	309.931
2930.5	310.24
2933.11	310.024
2935.72	305.936
2938.33	302.375
2940.94	296.298
2943.54	288.157
2946.15	280.406
2948.76	270.069
2951.36	258.483
2953.97	248.235
2956.57	237.253
2959.17	225.55
2961.77	214.023
2964.37	204.574
2966.97	194.828
2969.57	187.587
2972.17	180.247
2974.77	172.704
2977.36	164.053
2979.96	156.273
2982.55	147.868
2985.15	138.672
2987.74	127.95
2990.33	118.186
2992.92	108.769
2995.51	100.442
2998.1	92.6816
3000.69	84.5052
3003.27	77.0411
3005.86	70.7358
3008.44	64.1048
3011.03	59.2257
3013.61	54.5285
3016.19	50.447
3018.78	46.7533
3021.36	44.7527
3023.94	43.3003
3026.51	42.3005
3029.09	41.9646
3031.67	40.8817
3034.24	41.6819
3036.82	40.9101
3039.39	41.7965
3041.97	43.5389
3044.54	44.8479
3047.11	45.1473
3049.68	44.3538
3052.25	44.8296
3054.82	43.4749
3057.39	42.3797
3059.96	41.6932
3062.52	39.0207
3065.09	36.8871
3067.65	35.4171
3070.22	33.2932
3072.78	31.6178
3075.34	30.1875
3077.9	28.3801
3080.46	25.493
3083.02	24.0952
3085.58	22.328
3088.14	19.3354
3090.69	17.4741
3093.25	16.7075
3095.8	16.518
3098.36	15.8936
3100.91	16.4114
3103.46	15.4388
3106.01	14.5188
3108.56	12.5228
3111.11	12.2334
3113.66	11.1852
3116.21	10.0167
3118.76	8.43374
3121.3	7.53519
3123.85	6.61698
3126.39	5.86116
3128.93	5.27559
3131.48	5.30066
3134.02	4.18869
3136.56	3.66644
3139.1	2.77777
3141.64	1.93264
3144.17	1.7612
3146.71	1.57038
3149.25	2.87599