File: data/Raman/poly_smoothed/Thy_00_07_36_1x_45s_532 nm_x100_100%_600 gr_mm_01.txt
#Acq. time (s)=	45
#Accumulations=	2
#Range (cm-¹)=	200...3150
#Windows=	2
#Auto scanning=	Off
#Autofocus=	Off
#Macrospot=	Off
#AutoExposure=	Off
#Spike filter=	Multiple accum.
#Delay time (s)=	0
#Binning=	1
#Readout mode=	Signal
#DeNoise=	Off
#ICS correction=	On
#Dark correction=	Off
#Inst. Process=	Off
#Detector Gain=	Best Dynamic Range
#Detector ADC=	20 kHz
#Detector temperature (°C)=	-69.85
#Instrument=	LabRAM HR Evol
#Detector=	Synapse
#Objective=	x100
#Grating=	600 gr/mm
#ND Filter=	100%
#Laser (nm)=	532
#Hole=	100.021
#Range=	Auto
#Laser Pol.=	No
#Raman. Pol.=	No
#Laser Pol. (°)=	-0.0007625
#Raman Pol. (°)=	89.9995
#Collection=	Microscope
#StageXY=	Marzhauser
#StageZ=	Marzhauser
#X (µm)=	8962.9
#Y (µm)=	-3069.7
#Z (µm)=	-54.85
#Full time(mm:ss)=	3:18
#Project=
#Sample=
#Site=
#Title=	Thy_00_07_36_2x_45s_532 nm_x100_100%_600 gr_mm
#Remark=
#Date=	28.06.2022 12:46
#Acquired=	28.06.2022 12:46:02
#Base:Fit=	10.08.2022 10:07:56
#Base:Sub=	10.08.2022 10:08:40
#Filter:Polynom=	16.08.2022 10:26:06
#AxisType[0]=Intens
#AxisUnit[0]=Cnt
#AxisType[1]=Spectr
#AxisUnit[1]=1/cm
200.407	30.4668
204.035	28.2237
207.665	26.627
211.291	25.3777
214.916	22.2596
218.541	20.7313
222.163	20.1071
225.785	18.6006
229.404	17.4808
233.022	15.6906
236.638	14.2836
240.255	12.8135
243.868	11.2519
247.48	8.70679
251.091	6.7345
254.702	6.43601
258.31	5.81055
261.916	4.97561
265.521	4.75837
269.125	5.48658
272.727	5.84588
276.328	5.24882
279.927	7.18114
283.525	6.93222
287.121	8.09158
290.716	9.5954
294.31	10.6817
297.9	11.9282
301.491	11.8688
305.081	11.1746
308.669	13.2809
312.256	13.1168
315.839	13.0396
319.423	13.7534
323.006	12.736
326.585	11.7959
330.165	10.2106
333.741	9.87796
337.318	8.95133
340.894	8.84936
344.466	7.70016
348.039	7.60474
351.608	5.988
355.176	6.89119
358.745	6.65807
362.31	7.15531
365.876	9.07672
369.439	10.5047
373	10.7126
376.56	11.5489
380.12	10.8373
383.677	11.3244
387.233	11.1884
390.787	9.77338
394.34	10.8965
397.894	10.4245
401.444	9.608
404.993	9.41792
408.54	9.76606
412.086	9.60159
415.631	9.8411
419.174	10.173
422.716	8.3416
426.257	9.05887
429.794	6.45395
433.332	3.86185
436.868	1.92025
440.403	2.77577
443.937	3.78282
447.468	5.35883
450.999	8.23361
454.528	13.7466
458.057	16.8028
461.582	17.4653
465.107	22.1485
468.629	25.0392
472.152	28.341
475.672	31.5973
479.192	35.537
482.709	37.9651
486.226	39.7798
489.74	42.3093
493.255	45.8389
496.767	47.1547
500.277	47.4784
503.788	46.5548
507.295	44.6517
510.801	42.4747
514.308	38.2312
517.811	33.742
521.313	30.7897
524.814	28.7957
528.313	26.9918
531.811	23.5113
535.308	22.7388
538.803	22.1953
542.297	19.5737
545.789	17.0031
549.281	15.8216
552.771	15.4833
556.259	13.6119
559.747	13.1336
563.233	14.1347
566.717	13.413
570.2	12.245
573.68	12.8656
577.161	11.1782
580.64	11.5962
584.118	10.9571
587.593	12.1506
591.068	10.3771
594.54	9.13906
598.013	7.6644
601.484	6.90396
604.952	5.57493
608.421	5.20675
611.886	2.76518
615.35	3.36242
618.815	3.93216
622.276	4.4941
625.738	5.66073
629.197	5.65767
632.655	7.37946
636.113	7.58928
639.568	7.4407
643.021	9.83698
646.473	11.1491
649.924	12.2131
653.376	11.9211
656.824	13.0469
660.271	15.5377
663.716	16.6604
667.161	18.1553
670.604	19.8351
674.045	20.759
677.486	21.4121
680.925	23.6453
684.361	26.4007
687.797	28.6762
691.232	30.4247
694.666	32.4407
698.099	33.4751
701.528	36.5689
704.958	37.8493
708.387	39.0437
711.814	41.4942
715.238	41.8274
718.663	43.5362
722.084	43.3834
725.506	46.2264
728.925	49.2819
732.345	49.5731
735.761	53.577
739.178	55.6878
742.592	59.2673
746.006	62.8878
749.417	65.2783
752.827	68.5891
756.236	71.6684
759.645	75.2854
763.051	75.2682
766.456	78.3257
769.859	79.6173
773.261	80.32
776.664	81.0399
780.064	79.7647
783.462	79.7493
786.859	77.7066
790.255	77.3437
793.649	77.6479
797.042	77.7973
800.434	77.6179
803.823	76.677
807.212	75.4185
810.6	77.4712
813.987	77.4972
817.372	78.6907
820.754	79.6027
824.137	81.892
827.519	83.8898
830.897	87.6302
834.276	91.0542
837.654	93.8995
841.029	94.3667
844.404	93.4417
847.776	92.5656
851.149	92.3768
854.519	90.3978
857.889	87.6892
861.256	83.9751
864.622	80.1387
867.988	76.3023
871.351	72.3196
874.713	69.934
878.074	65.3892
881.435	63.0329
884.794	59.4415
888.15	55.4057
891.506	52.6143
894.861	49.7638
898.214	48.8673
901.566	48.7742
904.916	50.5084
908.266	54.3346
911.614	58.3758
914.961	63.0314
918.306	64.8842
921.651	66.0459
924.994	67.743
928.336	68.4511
931.674	68.3547
935.014	67.4982
938.352	66.9025
941.687	65.508
945.022	62.6894
948.357	61.1176
951.688	60.204
955.02	57.6464
958.348	55.5142
961.678	51.3566
965.004	49.1553
968.331	48.3378
971.655	46.5636
974.979	44.8499
978.3	44.7931
981.62	44.6042
984.941	43.5261
988.259	44.9518
991.575	44.0783
994.89	43.5888
998.204	43.5553
1001.52	44.1688
1004.83	45.4907
1008.14	45.8789
1011.45	45.6954
1014.76	46.3388
1018.06	47.0255
1021.37	48.0818
1024.67	47.6215
1027.97	47.1271
1031.27	47.4253
1034.57	45.4344
1037.87	45.0256
1041.17	45.3597
1044.47	46.445
1047.76	48.9057
1051.06	49.8872
1054.35	49.2091
1057.64	49.2797
1060.93	50.1032
1064.22	49.7324
1067.5	50.0604
1070.79	49.2878
1074.08	51.1792
1077.36	51.9662
1080.64	53.0085
1083.92	53.6164
1087.2	52.5606
1090.48	52.9883
1093.76	54.5436
1097.03	56.7959
1100.31	57.5266
1103.58	58.0393
1106.85	57.8729
1110.12	55.6349
1113.39	53.7369
1116.66	52.5149
1119.93	52.2538
1123.19	50.3267
1126.46	48.7249
1129.72	47.6834
1132.98	45.801
1136.24	45.6055
1139.5	44.1159
1142.76	42.625
1146.01	39.6462
1149.27	37.0413
1152.53	34.251
1155.78	30.2209
1159.03	25.4709
1162.28	21.9539
1165.53	18.1341
1168.78	15.343
1172.02	14.6414
1175.27	13.8456
1178.51	12.8283
1181.76	11.2042
1185	9.72449
1188.24	7.92224
1191.48	6.71856
1194.71	7.78686
1197.95	8.3308
1201.19	11.0553
1204.42	13.4114
1207.65	15.3478
1210.88	18.7052
1214.12	22.8192
1217.35	28.4517
1220.57	32.1623
1223.8	34.9339
1227.03	38.5927
1230.25	41.4366
1233.47	44.3171
1236.69	46.2025
1239.92	47.1051
1243.13	50.2391
1246.35	52.4269
1249.57	53.1078
1252.78	52.9023
1256	52.1453
1259.21	51.7891
1262.42	50.1099
1265.63	48.5585
1268.84	48.2374
1272.05	49.79
1275.26	49.2536
1278.46	48.9702
1281.67	50.3105
1284.87	50.6384
1288.07	52.3763
1291.27	54.3001
1294.47	56.4058
1297.67	59.1737
1300.87	63.073
1304.06	67.7223
1307.26	74.1162
1310.45	80.526
1313.64	85.6669
1316.83	89.3158
1320.02	94.4501
1323.21	98.2544
1326.4	98.347
1329.59	98.1495
1332.77	98.7662
1335.95	99.4245
1339.14	98.299
1342.32	97.2318
1345.5	96.6473
1348.67	95.1322
1351.85	92.6883
1355.03	89.1494
1358.2	85.8754
1361.38	82.8527
1364.55	77.9157
1367.72	74.3299
1370.89	70.7911
1374.06	69.8492
1377.23	68.5877
1380.39	68.3045
1383.56	66.8146
1386.72	65.1018
1389.89	64.6967
1393.05	61.8901
1396.21	59.4956
1399.37	58.9723
1402.52	56.184
1405.68	53.81
1408.84	52.9427
1411.99	52.2371
1415.15	52.6317
1418.3	53.8718
1421.45	57.6286
1424.6	60.6489
1427.75	65.3106
1430.89	71.3392
1434.04	76.405
1437.18	80.742
1440.33	84.5853
1443.47	87.933
1446.61	89.5892
1449.75	92.5156
1452.89	92.2011
1456.03	90.4748
1459.16	86.9128
1462.3	82.7106
1465.43	78.366
1468.56	72.5178
1471.7	65.0231
1474.83	58.1141
1477.96	51.0787
1481.08	43.8742
1484.21	36.1853
1487.34	30.4787
1490.46	26.0524
1493.58	22.1044
1496.71	20.0211
1499.83	18.5697
1502.95	17.9014
1506.07	18.2755
1509.18	18.7148
1512.3	20.8079
1515.41	20.8505
1518.53	21.6726
1521.64	22.1378
1524.75	23.0286
1527.86	24.5793
1530.97	25.0947
1534.08	24.5933
1537.19	25.3576
1540.29	25.672
1543.4	27.6678
1546.5	30.0741
1549.6	32.5359
1552.7	35.6484
1555.8	37.28
1558.9	39.254
1562	41.4577
1565.09	44.1348
1568.19	45.9272
1571.28	48.8975
1574.37	52.9105
1577.47	57.4803
1580.56	60.2897
1583.64	63.3041
1586.73	68.2581
1589.82	69.384
1592.9	70.3622
1595.99	71.1161
1599.07	70.4486
1602.15	70.2864
1605.23	68.8298
1608.31	68.3098
1611.39	66.5039
1614.47	64.9793
1617.55	64.4182
1620.62	63.7275
1623.7	62.269
1626.77	62.1058
1629.84	62.0057
1632.91	61.1805
1635.98	61.5302
1639.05	62.1894
1642.11	64.2229
1645.18	65.5905
1648.24	67.779
1651.31	68.5166
1654.37	66.8191
1657.43	67.639
1660.49	65.8489
1663.55	64.956
1666.61	61.5938
1669.66	58.515
1672.72	55.5449
1675.77	52.1146
1678.83	48.9345
1681.88	44.6988
1684.93	41.3244
1687.98	36.4588
1691.03	32.45
1694.07	29.5911
1697.12	25.61
1700.17	22.9264
1703.21	19.9511
1706.25	17.1031
1709.29	16.4942
1712.33	16.1486
1715.37	14.9262
1718.41	13.213
1721.45	12.2045
1724.49	11.4067
1727.52	9.87533
1730.55	9.42102
1733.59	8.81086
1736.62	7.68909
1739.65	7.3672
1742.68	6.85301
1745.7	6.36054
1748.73	5.7947
1751.76	4.85652
1754.78	4.73284
1757.8	3.90387
1760.83	3.3212
1763.85	3.07383
1766.87	2.18953
1769.89	2.24276
1772.9	1.74418
1775.92	1.68855
1778.94	0.849684
1781.95	2.29594
1784.96	2.38705
1787.97	1.89938
1790.99	2.3111
1794	2.34986
1797	2.06891
1800.01	1.5202
1803.02	1.76233
1806.02	2.07523
1809.03	1.95321
1812.03	1.80415
1815.03	1.66488
1818.03	1.67032
1821.03	1.67217
1824.03	2.61729
1827.03	3.00572
1830.02	2.37289
1833.02	2.36918
1836.01	2.55148
1839.01	2.6373
1842	3.60671
1844.99	3.93194
1847.98	4.55696
1850.97	5.83745
1853.95	6.46134
1856.94	7.17565
1859.93	8.10654
1862.91	7.44464
1865.89	6.83307
1868.87	5.7279
1871.85	5.54773
1874.83	4.4499
1877.81	4.17395
1880.79	4.20454
1882.52	4.31159
1885.51	4.00089
1888.5	3.38287
1891.49	3.29697
1894.47	4.12473
1897.46	3.97552
1900.44	4.24583
1903.42	4.57592
1906.4	5.74401
1909.38	7.02433
1912.36	8.83229
1915.34	9.22547
1918.32	9.81108
1921.29	10.5636
1924.27	11.1351
1927.24	10.4312
1930.21	10.9159
1933.18	9.65812
1936.15	7.70541
1939.12	6.39673
1942.09	4.91676
1945.06	4.34339
1948.02	3.67852
1950.99	2.24552
1953.95	1.88813
1956.91	0.97689
1959.88	0.6255
1962.84	2.47817
1965.8	1.92416
1968.75	1.98453
1971.71	2.6575
1974.67	3.77899
1977.62	4.97098
1980.58	5.44065
1983.53	6.38833
1986.48	6.82392
1989.43	7.0753
1992.38	7.35029
1995.33	6.47792
1998.27	6.14787
2001.22	6.66497
2004.16	5.97735
2007.11	3.87476
2010.05	2.64228
2012.99	2.34185
2015.93	2.26354
2018.87	2.09064
2021.81	0.951071
2024.75	1.52158
2027.69	2.94528
2030.62	3.36661
2033.56	4.08516
2036.49	3.91121
2039.42	3.14657
2042.35	3.7815
2045.28	4.16743
2048.21	6.03553
2051.14	6.00579
2054.07	6.69575
2056.99	7.45509
2059.92	7.54917
2062.84	8.2649
2065.76	7.75077
2068.68	8.45756
2071.6	9.69868
2074.52	10.5073
2077.44	10.0926
2080.36	9.75328
2083.27	9.3741
2086.19	10.5072
2089.1	10.4654
2092.02	10.1932
2094.93	10.3349
2097.84	10.6539
2100.75	10.4464
2103.66	9.8651
2106.56	9.72853
2109.47	9.05272
2112.38	9.43711
2115.28	8.79619
2118.18	9.04314
2121.09	8.2484
2123.99	8.64384
2126.89	9.53778
2129.79	9.56518
2132.68	9.52011
2135.58	9.33327
2138.48	9.57672
2141.37	9.3246
2144.27	9.66873
2147.16	10.1583
2150.05	9.6238
2152.94	9.15633
2155.83	9.01029
2158.72	9.41521
2161.6	8.36918
2164.49	8.17305
2167.38	8.02086
2170.26	7.90974
2173.14	8.17404
2176.03	7.26807
2178.91	8.12083
2181.79	8.22486
2184.67	8.18073
2187.54	8.31611
2190.42	7.46839
2193.3	7.99569
2196.17	8.88415
2199.05	8.07746
2201.92	6.92116
2204.79	6.9263
2207.66	6.59796
2210.53	6.99155
2213.4	7.22963
2216.27	6.7118
2219.13	7.69782
2222	7.57014
2224.86	6.88531
2227.72	7.96359
2230.59	8.57334
2233.45	8.44673
2236.31	8.03212
2239.17	8.25696
2242.03	8.45761
2244.88	8.97398
2247.74	9.21229
2250.59	9.47242
2253.45	7.80291
2256.3	7.86062
2259.15	6.92712
2262	7.23299
2264.85	8.6942
2267.7	8.53848
2270.55	8.19514
2273.4	8.23834
2276.24	8.96911
2279.09	8.42571
2281.93	7.56606
2284.77	7.47702
2287.62	8.52135
2290.46	7.83869
2293.3	6.91438
2296.13	6.7139
2298.97	7.97918
2301.81	8.27589
2304.64	9.6076
2307.48	10.0845
2310.31	10.4541
2313.14	10.2487
2315.98	9.47542
2318.81	10.4703
2321.64	10.3781
2324.46	11.2501
2327.29	12.2892
2330.12	12.7786
2332.94	14.3884
2335.77	14.8703
2338.59	14.7711
2341.41	14.147
2344.23	13.2749
2347.05	12.8648
2349.87	11.2073
2352.69	10.0656
2355.51	8.33448
2358.32	6.81832
2361.14	5.82936
2363.95	5.85653
2366.76	6.82107
2369.58	5.89313
2372.39	5.45342
2375.2	5.28754
2378	4.62361
2380.81	3.43448
2383.62	3.34185
2386.43	3.28975
2389.23	3.85817
2392.03	3.85473
2394.84	3.52313
2397.64	3.54053
2400.44	5.25526
2403.24	5.12984
2406.04	6.34146
2408.84	6.87535
2411.63	7.5675
2414.43	8.19749
2417.22	9.4573
2420.02	10.1124
2422.81	9.72549
2425.6	11.3008
2428.39	12.3774
2431.18	12.9882
2433.97	12.7001
2436.76	11.5579
2439.54	11.3856
2442.33	11.8334
2445.12	11.2883
2447.9	10.5589
2450.68	9.0378
2453.46	8.61021
2456.24	7.31485
2459.02	6.78373
2461.8	6.91673
2464.58	7.19619
2467.36	7.14269
2470.13	6.52748
2472.91	7.21678
2475.68	8.03095
2478.45	8.43795
2481.23	7.39201
2484	7.31587
2486.77	5.88772
2489.54	5.2398
2492.3	5.07503
2495.07	4.50762
2497.84	3.64394
2500.6	2.49398
2503.36	2.65695
2506.13	2.03214
2508.89	2.40728
2511.65	2.64534
2514.41	2.21703
2517.17	1.98414
2519.93	1.98131
2522.68	1.27228
2525.44	1.30662
2528.19	2.32195
2530.95	3.11959
2533.7	3.72997
2536.45	3.99274
2539.2	5.15804
2541.95	6.78688
2544.7	6.70582
2547.45	6.54252
2550.2	5.96713
2552.94	6.26121
2555.69	6.71933
2558.43	6.07687
2561.18	5.43488
2563.92	5.80411
2566.66	6.07097
2569.4	5.70944
2572.14	5.42463
2574.88	4.78968
2577.61	3.63144
2580.35	2.9455
2583.09	1.94531
2585.82	0.954971
2588.55	0.507282
2591.29	-0.342743
2594.02	0.654699
2596.75	1.63704
2599.48	1.86074
2602.21	2.04722
2604.93	3.4438
2607.66	3.94704
2610.39	3.96874
2613.11	4.26551
2615.83	4.44146
2618.56	4.4259
2621.28	4.74682
2624	4.32047
2626.72	3.81046
2629.44	4.55111
2632.15	4.42197
2634.87	4.58511
2637.59	4.24723
2640.3	4.55079
2643.02	3.73709
2645.73	4.02513
2648.44	4.74185
2651.15	3.97002
2653.86	4.20631
2656.57	3.98044
2659.28	4.36127
2661.99	4.48525
2664.69	3.97838
2667.4	4.19394
2670.1	3.86013
2672.81	3.08646
2675.51	2.93882
2678.21	2.69485
2680.91	2.57659
2683.61	1.60614
2686.31	1.36577
2689	1.27811
2691.7	1.43768
2694.4	1.92127
2697.09	3.25183
2699.79	3.52867
2702.48	4.17383
2705.17	5.92114
2707.86	5.8892
2710.55	6.37735
2713.24	7.58202
2715.93	8.0543
2718.62	7.79237
2721.3	7.92657
2723.99	8.84435
2726.67	8.26679
2729.35	7.75697
2732.04	8.37343
2734.72	7.89966
2737.4	7.45707
2740.08	6.75197
2742.76	5.72307
2745.43	4.81554
2748.11	3.65936
2750.79	3.26099
2753.46	2.81832
2756.14	2.1112
2758.81	1.67982
2761.48	1.20517
2764.15	0.401083
2766.82	0.697158
2769.49	0.800254
2772.16	0.0469335
2774.82	-0.723486
2777.49	-1.01383
2780.16	-0.679187
2782.82	-0.816479
2785.48	-0.669889
2788.15	-0.315545
2790.81	-0.92347
2793.47	-0.42328
2796.13	-0.0105369
2798.79	0.79124
2801.44	0.0813322
2804.1	-0.6263
2806.76	-0.331341
2809.41	-0.437902
2812.07	-1.3435
2814.72	-0.879605
2817.37	-0.0647589
2820.02	1.01786
2822.67	3.04622
2825.32	5.68085
2827.97	8.42163
2830.62	12.1946
2833.26	15.6909
2835.91	18.7445
2838.56	23.201
2841.2	28.6015
2843.84	34.092
2846.48	41.4409
2849.12	49.2468
2851.77	59.0213
2854.4	69.1257
2857.04	79.3778
2859.68	90.5504
2862.32	102.632
2864.95	114.022
2867.59	124.25
2870.22	135.739
2872.85	147.162
2875.48	156.836
2878.11	167.442
2880.74	177.504
2883.37	186.878
2886	196.667
2888.63	206.697
2891.25	215.527
2893.88	223.825
2896.5	231.926
2899.13	238.856
2901.75	246.722
2904.37	254.133
2906.99	262.164
2909.61	271.417
2912.23	281.456
2914.85	290.262
2917.46	297.801
2920.08	304.384
2922.7	309.543
2925.31	313.358
2927.92	314.271
2930.54	312.654
2933.15	310.56
2935.76	306.534
2938.37	301.299
2940.98	293.314
2943.58	284.127
2946.19	274.523
2948.8	264.334
2951.4	253.627
2954.01	241.785
2956.61	229.566
2959.21	219.207
2961.81	207.355
2964.41	197.182
2967.01	188.024
2969.61	178.494
2972.21	169.736
2974.81	160.709
2977.4	150.904
2980	141.204
2982.59	130.932
2985.18	120.461
2987.78	108.962
2990.37	97.1394
2992.96	86.4826
2995.55	76.3126
2998.14	66.1559
3000.73	55.4027
3003.31	45.7296
3005.9	37.1006
3008.48	29.2895
3011.07	22.2725
3013.65	16.5447
3016.23	11.4321
3018.81	7.2461
3021.4	4.58251
3023.97	2.84513
3026.55	1.41263
3029.13	0.579351
3031.71	0.0343906
3034.28	-0.720696
3036.86	-0.879681
3039.43	1.34032
3042.01	2.85377
3044.58	4.46002
3047.15	5.29674
3049.72	5.62437
3052.29	5.61557
3054.86	6.35001
3057.43	7.36024
3060	6.03082
3062.56	6.16989
3065.13	6.77084
3067.69	6.05163
3070.26	5.55471
3072.82	4.40709
3075.38	3.54464
3077.94	2.78194
3080.5	1.8688
3083.06	1.12612
3085.62	0.911107
3088.18	0.838161
3090.73	1.13956
3093.29	2.38553
3095.84	3.41339
3098.4	4.833
3100.95	6.72043
3103.5	9.5367
3106.05	11.2427
3108.6	13.5911
3111.15	14.9299
3113.7	17.4508
3116.25	19.9423
3118.79	22.072
3121.34	24.752
3123.88	26.6563
3126.43	29.5926
3128.97	30.7975
3131.51	32.7383
3134.06	35.1005
3136.6	36.8649
3139.14	38.853
3141.67	41.1639
3144.21	43.7821
3146.75	46.8242
3149.29	48.2435