File: data/Raman/poly_smoothed/Thy_40_11_46_1x_45s_532 nm_x100_100%_600 gr_mm_01.txt
#Acq. time (s)=	45
#Accumulations=	2
#Range (cm-¹)=	200...3150
#Windows=	2
#Auto scanning=	Off
#Autofocus=	Off
#Macrospot=	Off
#AutoExposure=	Off
#Spike filter=	Multiple accum.
#Delay time (s)=	0
#Binning=	1
#Readout mode=	Signal
#DeNoise=	Off
#ICS correction=	On
#Dark correction=	Off
#Inst. Process=	Off
#Detector Gain=	Best Dynamic Range
#Detector ADC=	20 kHz
#Detector temperature (°C)=	-69.85
#Instrument=	LabRAM HR Evol
#Detector=	Synapse
#Objective=	x100
#Grating=	600 gr/mm
#ND Filter=	100%
#Laser (nm)=	532
#Hole=	100.021
#Range=	Auto
#Laser Pol.=	No
#Raman. Pol.=	No
#Laser Pol. (°)=	-0.0007625
#Raman Pol. (°)=	89.9995
#Collection=	Microscope
#StageXY=	Marzhauser
#StageZ=	Marzhauser
#X (µm)=	265.6
#Y (µm)=	1684.6
#Z (µm)=	426.9
#Full time(mm:ss)=	3:18
#Project=
#Sample=
#Site=
#Title=	Thy_40_11_46_2x_45s_532 nm_x100_100%_600 gr_mm
#Remark=
#Date=	05.07.2022 13:16
#Acquired=	05.07.2022 13:16:46
#Base:Fit=	10.08.2022 10:01:35
#Base:Sub=	10.08.2022 10:01:52
#Filter:Polynom=	16.08.2022 10:21:53
#AxisType[0]=Intens
#AxisUnit[0]=Cnt
#AxisType[1]=Spectr
#AxisUnit[1]=1/cm
200.43	21.1751
204.059	16.9553
207.688	13.7332
211.314	12.581
214.941	10.9981
218.564	9.66185
222.186	8.04531
225.809	7.92889
229.428	6.38562
233.045	5.05069
236.663	3.93839
240.278	3.66694
243.891	3.27118
247.503	2.77705
251.116	3.42148
254.725	3.53313
258.333	3.23876
261.939	2.93958
265.544	1.28223
269.148	1.30204
272.75	3.06872
276.351	4.55047
279.95	5.74525
283.548	6.33976
287.144	7.50252
290.739	7.90497
294.333	10.5423
297.925	12.4958
301.514	13.1752
305.104	14.8514
308.692	15.086
312.279	16.4853
315.862	16.8629
319.446	17.8762
323.029	19.8532
326.608	20.6827
330.188	20.6881
333.766	20.0413
337.341	18.8642
340.917	18.4575
344.489	16.6896
348.062	15.6302
351.631	14.8486
355.201	14.2367
358.768	14.0777
362.333	12.2148
365.899	10.6504
369.462	10.1205
373.023	8.99718
376.585	8.94346
380.143	8.03989
383.7	7.75159
387.256	7.35774
390.812	7.19416
394.365	7.94181
397.916	8.04268
401.467	9.6223
405.015	11.4173
408.563	12.073
412.109	12.9943
415.654	13.3557
419.197	13.0932
422.739	12.1691
426.279	13.8071
429.819	15.4638
433.356	15.078
436.891	15.9853
440.426	16.2371
443.96	14.2672
447.492	13.6791
451.021	14.8176
454.551	14.8174
458.079	16.0692
461.604	17.4061
465.13	18.8527
468.654	19.1218
472.175	20.1103
475.696	20.7543
479.215	20.753
482.733	22.435
486.249	23.3988
489.765	25.0445
493.278	25.5107
496.789	26.0501
500.301	26.5524
503.81	27.6651
507.317	27.6932
510.825	28.6352
514.33	29.0651
517.833	27.6706
521.335	26.9773
524.836	26.6268
528.335	24.5378
531.835	22.7027
535.332	22.3651
538.827	20.7297
542.321	20.6143
545.814	20.3847
549.305	20.4203
552.795	18.3254
556.282	17.3645
559.769	17.8969
563.255	16.4917
566.739	15.4834
570.223	14.9573
573.705	14.158
577.183	12.5001
580.663	10.3254
584.141	10.4612
587.615	9.31837
591.09	8.9496
594.564	7.22274
598.035	5.57863
601.506	4.67275
604.974	5.4656
608.443	5.89167
611.908	5.77562
615.374	6.21654
618.837	6.31614
622.3	7.4634
625.761	7.72217
629.219	9.78566
632.677	11.1268
636.135	13.3457
639.59	13.7068
643.043	16.0826
646.495	16.9931
649.948	15.8464
653.398	16.9985
656.846	15.532
660.293	15.9305
663.738	16.2171
667.183	16.7493
670.626	16.9329
674.067	16.8662
677.508	16.3819
680.947	17.4686
684.385	19.8105
687.821	23.4044
691.254	24.6105
694.688	26.8617
698.121	28.4344
701.552	29.929
704.98	30.2728
708.409	33.8347
711.836	37.5537
715.26	40.1431
718.685	42.5715
722.108	45.7837
725.528	48.3581
728.949	50.9314
732.367	51.73
735.785	53.6509
739.2	55.1547
742.614	55.7315
746.028	58.5078
749.439	61.1268
752.849	62.0794
756.26	63.1368
759.667	63.8426
763.073	64.9541
766.477	68.1338
769.883	68.0564
773.285	69.3564
776.686	70.3598
780.085	72.2595
783.484	74.6303
786.881	77.6716
790.276	78.7362
793.671	82.1648
797.064	84.7305
800.456	86.8293
803.846	88.7839
807.234	89.927
810.622	89.8582
814.008	90.4979
817.394	90.3925
820.778	90.5127
824.159	89.8748
827.541	88.8199
830.921	89.23
834.298	87.5056
837.676	85.1553
841.051	84.1066
844.426	81.1989
847.798	78.9262
851.171	77.6226
854.54	75.5835
857.911	73.3908
861.278	71.4294
864.645	70.5388
868.01	69.3081
871.373	67.2695
874.735	65.9789
878.097	65.4867
881.457	64.0868
884.815	62.8876
888.172	61.5447
891.528	60.4443
894.882	59.5618
898.237	58.8907
901.589	57.6963
904.94	57.6281
908.289	55.5044
911.635	54.8258
914.982	55.2572
918.328	53.4294
921.672	53.0171
925.015	52.9412
928.357	50.4474
931.698	48.2957
935.035	47.2772
938.373	46.7117
941.71	45.1145
945.044	43.6701
948.378	43.7094
951.709	43.21
955.041	42.8541
958.372	43.2172
961.699	41.6054
965.027	40.8065
968.352	40.8444
971.676	41.5397
975	42.971
978.322	44.2838
981.642	45.4396
984.962	47.1626
988.28	46.6958
991.596	46.7242
994.911	47.8533
998.227	46.873
1001.54	47.9857
1004.85	49.1977
1008.16	48.9097
1011.47	48.6466
1014.78	47.9848
1018.08	48.7307
1021.39	48.1959
1024.69	48.5982
1028	48.1024
1031.3	49.1625
1034.6	47.4545
1037.9	46.7988
1041.19	44.6129
1044.49	43.7558
1047.78	43.6284
1051.08	42.0176
1054.37	40.6728
1057.66	41.3406
1060.95	39.7303
1064.24	36.8636
1067.53	34.6339
1070.81	32.2829
1074.1	30.5026
1077.38	30.6616
1080.66	31.1504
1083.94	29.8328
1087.22	27.9491
1090.5	28.2066
1093.78	26.7982
1097.05	25.8102
1100.33	25.4305
1103.6	26.6426
1106.87	25.089
1110.14	24.4887
1113.41	24.1886
1116.68	23.0549
1119.95	22.2545
1123.21	20.0837
1126.48	18.7099
1129.74	17.6927
1133	17.1849
1136.26	17.1783
1139.52	15.3583
1142.78	12.4844
1146.04	11.5016
1149.29	10.0562
1152.55	9.86868
1155.8	9.30887
1159.05	8.48786
1162.3	8.92014
1165.55	7.74688
1168.8	9.68216
1172.05	11.7122
1175.29	12.0752
1178.54	12.7764
1181.78	15.0914
1185.02	16.2863
1188.26	16.5344
1191.5	16.884
1194.74	18.9144
1197.97	20.1094
1201.21	22.9144
1204.44	25.2841
1207.68	28.8691
1210.91	31.8563
1214.14	33.8192
1217.37	35.3982
1220.59	37.942
1223.82	39.8355
1227.05	43.8828
1230.27	48.0744
1233.49	52.92
1236.72	55.0099
1239.94	58.7247
1243.16	62.6508
1246.37	64.6909
1249.59	68.1499
1252.8	71.2416
1256.02	74.048
1259.23	76.651
1262.44	78.1892
1265.66	79.5648
1268.86	79.8138
1272.07	78.8703
1275.28	80.7217
1278.48	80.7778
1281.69	82.7714
1284.89	82.7995
1288.09	83.6054
1291.29	83.0839
1294.49	83.8986
1297.69	85.1351
1300.89	85.2354
1304.08	85.5322
1307.28	86.1724
1310.47	86.2064
1313.66	85.9891
1316.85	85.5687
1320.04	86.6379
1323.23	86.4022
1326.42	85.4043
1329.61	84.2404
1332.79	82.6143
1335.97	80.8947
1339.16	77.7543
1342.34	75.3794
1345.52	71.5126
1348.7	66.7512
1351.87	64.5119
1355.05	61.7745
1358.22	58.2304
1361.4	55.9039
1364.57	52.3792
1367.74	49.5018
1370.91	47.1276
1374.08	46.1406
1377.25	44.4192
1380.41	43.7791
1383.58	44.3852
1386.74	44.4428
1389.91	44.3556
1393.07	44.0995
1396.23	43.4532
1399.39	44.886
1402.55	46.0574
1405.7	45.0482
1408.86	45.133
1412.01	47.2864
1415.17	49.7244
1418.32	52.4664
1421.47	54.2341
1424.62	56.7996
1427.77	62.3088
1430.91	67.3759
1434.06	70.9586
1437.2	74.9636
1440.35	78.9546
1443.49	81.2258
1446.63	82.2755
1449.77	82.8878
1452.91	82.8592
1456.05	81.1234
1459.18	78.2741
1462.32	74.6165
1465.45	69.3538
1468.59	63.1971
1471.72	56.7306
1474.85	51.4622
1477.98	44.8425
1481.1	37.5844
1484.23	31.5097
1487.36	29.0208
1490.48	24.8357
1493.61	20.7229
1496.73	19.6745
1499.85	17.5341
1502.97	17.2065
1506.09	17.414
1509.2	17.3667
1512.32	17.733
1515.43	17.866
1518.55	18.1422
1521.66	19.0488
1524.77	19.7972
1527.88	20.3417
1530.99	21.6004
1534.1	22.367
1537.21	24.6436
1540.31	27.7624
1543.42	31.0743
1546.52	34.7293
1549.62	38.2675
1552.72	42.6395
1555.82	47.6635
1558.92	52.5948
1562.02	58.0544
1565.11	62.3571
1568.21	63.1357
1571.3	65.8142
1574.39	67.7957
1577.49	70.5599
1580.57	72.0902
1583.66	74.0234
1586.75	73.9739
1589.84	74.5571
1592.92	74.9092
1596.01	75.7391
1599.09	75.0759
1602.17	72.8956
1605.25	72.2136
1608.33	71.672
1611.41	71.9715
1614.49	71.6109
1617.57	72.3441
1620.64	72.8293
1623.72	74.8272
1626.79	76.5796
1629.86	79.7217
1632.93	83.3672
1636	86.4038
1639.07	88.489
1642.13	91.5245
1645.2	93.8541
1648.26	96.4884
1651.33	99.2967
1654.39	100.887
1657.45	101.174
1660.51	101.706
1663.57	100.054
1666.63	98.7487
1669.68	95.5599
1672.74	90.6812
1675.79	85.5559
1678.85	78.1902
1681.9	71.8229
1684.95	64.729
1688	57.4252
1691.05	49.5401
1694.09	43.2044
1697.14	37.0548
1700.18	30.3862
1703.23	25.5005
1706.27	21.4125
1709.31	17.1155
1712.35	13.6913
1715.39	12.2754
1718.43	11.3633
1721.47	9.04502
1724.5	8.54422
1727.54	8.91867
1730.57	9.43684
1733.61	9.84966
1736.64	9.59826
1739.67	10.2043
1742.7	10.7898
1745.72	10.3922
1748.75	10.0507
1751.77	9.79454
1754.8	8.35285
1757.82	8.15495
1760.84	6.65531
1763.87	6.48224
1766.89	5.4327
1769.91	5.0878
1772.92	3.59943
1775.94	3.275
1778.95	2.91877
1781.97	1.52085
1784.98	0.525163
1787.99	0.83114
1791.01	1.75577
1794.01	0.611928
1797.02	1.10876
1800.03	0.635013
1803.04	0.631235
1806.04	1.19093
1809.05	2.31396
1812.05	2.7923
1815.05	2.33761
1818.05	2.5177
1821.05	2.13813
1824.05	2.29843
1827.05	2.59578
1830.04	2.01089
1833.04	1.91847
1836.03	1.97595
1839.03	1.67172
1842.02	1.64879
1845.01	2.05355
1848	1.35346
1850.99	2.1327
1853.97	1.2968
1856.96	1.05947
1859.94	1.78371
1862.93	2.00805
1865.91	1.91253
1868.89	2.00942
1871.87	1.8101
1874.85	3.00165
1877.83	4.56171
1880.81	4.93963
1882.57	5.13314
1885.56	5.0715
1888.55	4.82789
1891.54	5.06615
1894.52	4.85196
1897.51	4.92231
1900.49	4.63732
1903.47	3.3987
1906.45	3.81839
1909.43	3.53741
1912.41	2.62362
1915.39	2.87492
1918.37	2.76443
1921.34	2.1188
1924.32	2.04311
1927.29	1.38422
1930.26	2.61545
1933.23	2.86704
1936.2	1.45675
1939.17	1.70656
1942.14	2.75981
1945.11	2.32823
1948.07	2.77764
1951.04	1.89613
1954	2.29588
1956.96	2.00865
1959.93	1.24084
1962.89	0.621413
1965.85	0.363432
1968.8	0.648235
1971.76	2.47291
1974.72	2.00721
1977.67	2.62425
1980.63	2.96579
1983.58	1.79245
1986.53	2.69735
1989.48	3.79751
1992.43	5.13745
1995.38	5.09275
1998.32	6.36881
2001.27	6.9962
2004.22	7.91672
2007.16	7.03384
2010.1	7.16051
2013.04	8.07975
2015.98	7.19872
2018.92	7.69724
2021.86	6.48746
2024.8	6.06716
2027.74	5.91976
2030.67	5.21086
2033.61	5.98629
2036.54	7.56003
2039.47	8.42265
2042.4	9.71014
2045.33	9.87924
2048.26	10.5124
2051.19	11.166
2054.12	11.6916
2057.04	12.092
2059.97	13.487
2062.89	14.4034
2065.81	14.4291
2068.73	15.1277
2071.65	17.0257
2074.57	17.9968
2077.49	19.7777
2080.41	20.3082
2083.32	21.3118
2086.24	23.037
2089.15	23.5949
2092.07	24.2218
2094.98	24.9413
2097.89	26.4107
2100.8	28.7882
2103.71	31.4923
2106.61	34.7814
2109.52	36.1323
2112.43	38.5602
2115.33	40.9662
2118.23	44.4626
2121.13	47.1223
2124.04	50.5303
2126.94	54.9201
2129.83	59.2652
2132.73	63.3743
2135.63	68.2138
2138.53	72.5714
2141.42	77.8381
2144.31	82.2113
2147.21	85.7147
2150.1	89.5885
2152.99	92.141
2155.88	95.366
2158.77	98.3891
2161.65	100.275
2164.54	100.87
2167.43	102.52
2170.31	103.619
2173.19	103.904
2176.07	103.676
2178.96	102.239
2181.84	100.764
2184.72	99.1292
2187.59	97.6682
2190.47	96.6967
2193.35	93.4821
2196.22	91.3172
2199.09	88.8647
2201.97	84.9344
2204.84	80.9926
2207.71	78.1297
2210.58	74.4459
2213.45	69.9205
2216.31	66.9394
2219.18	63.7631
2222.05	60.0077
2224.91	56.3336
2227.78	53.247
2230.64	49.8195
2233.5	47.1372
2236.36	44.7242
2239.22	42.5655
2242.08	39.2444
2244.93	36.1781
2247.79	33.8095
2250.64	31.9442
2253.5	30.9426
2256.35	29.5551
2259.2	28.4516
2262.05	26.8078
2264.9	24.6811
2267.75	23.231
2270.6	21.0174
2273.45	19.8261
2276.29	19.5383
2279.14	18.2209
2281.98	17.6034
2284.82	15.9132
2287.66	14.7204
2290.5	12.6435
2293.34	10.662
2296.18	9.87681
2299.02	10.1305
2301.86	9.91798
2304.69	10.3294
2307.53	10.2371
2310.36	10.0179
2313.19	9.85732
2316.02	10.5205
2318.85	10.5552
2321.68	10.764
2324.51	10.1604
2327.34	9.37443
2330.16	8.9432
2332.99	8.47162
2335.81	7.21326
2338.64	6.51718
2341.46	6.5779
2344.28	6.16961
2347.1	5.42406
2349.92	4.33806
2352.74	3.30932
2355.55	2.29868
2358.37	2.30129
2361.19	1.33107
2364	1.68825
2366.81	2.72207
2369.62	3.00461
2372.44	2.06422
2375.24	2.59105
2378.05	2.63302
2380.86	2.66282
2383.67	1.69077
2386.47	1.07235
2389.28	1.14732
2392.08	1.54383
2394.89	2.07268
2397.69	3.55366
2400.49	3.96037
2403.29	3.50913
2406.09	4.28259
2408.88	5.07089
2411.68	5.50871
2414.48	6.43995
2417.27	6.284
2420.06	7.49281
2422.86	8.00937
2425.65	8.07146
2428.44	8.3987
2431.23	8.47537
2434.02	8.70151
2436.81	7.66502
2439.59	7.08034
2442.38	7.55106
2445.16	7.2089
2447.95	6.85734
2450.73	6.12395
2453.51	5.61171
2456.29	5.20261
2459.07	5.06512
2461.85	5.56787
2464.63	4.69788
2467.4	4.52853
2470.18	3.87247
2472.95	5.33098
2475.73	5.29583
2478.5	5.32887
2481.27	5.05226
2484.04	4.44936
2486.81	4.60712
2489.58	5.37908
2492.35	5.36479
2495.12	5.64754
2497.88	5.5052
2500.65	5.15427
2503.41	5.05709
2506.17	4.55587
2508.94	4.66382
2511.7	4.20355
2514.46	3.06529
2517.22	2.69091
2519.97	1.54404
2522.73	1.16704
2525.49	2.10278
2528.24	2.44408
2530.99	2.88919
2533.75	2.36775
2536.5	2.3414
2539.25	1.5105
2542	2.19309
2544.75	1.99281
2547.5	1.07753
2550.24	1.95037
2552.99	2.53864
2555.74	3.39338
2558.48	3.72433
2561.22	4.2831
2563.96	5.24693
2566.71	5.88464
2569.45	6.12602
2572.18	6.00636
2574.92	5.80245
2577.66	5.05447
2580.4	4.78402
2583.13	4.62483
2585.87	5.18171
2588.6	5.38513
2591.33	5.673
2594.06	6.08457
2596.79	6.19732
2599.52	4.81855
2602.25	4.42501
2604.98	3.47607
2607.71	4.01521
2610.43	4.57855
2613.16	3.6381
2615.88	3.51531
2618.6	3.01765
2621.32	3.58588
2624.04	3.83457
2626.76	4.73911
2629.48	4.00674
2632.2	4.33022
2634.92	3.86509
2637.63	3.11056
2640.35	2.62634
2643.06	2.75562
2645.77	2.59198
2648.49	2.72581
2651.2	2.67348
2653.91	3.09971
2656.62	2.65287
2659.33	2.40776
2662.03	2.08738
2664.74	1.97503
2667.44	1.34362
2670.15	2.19778
2672.85	2.06085
2675.55	1.56589
2678.26	0.346632
2680.96	0.288022
2683.66	0.0507732
2686.35	1.09478
2689.05	2.48988
2691.75	3.5594
2694.44	4.14127
2697.14	3.64654
2699.83	4.11518
2702.52	4.60002
2705.22	5.34308
2707.91	6.40126
2710.6	7.04948
2713.29	8.01409
2715.97	8.83413
2718.66	8.596
2721.35	8.67391
2724.03	8.4403
2726.72	8.52999
2729.4	8.69872
2732.08	8.53536
2734.76	8.94464
2737.44	8.49451
2740.12	7.39168
2742.8	6.15554
2745.48	6.17609
2748.16	5.76675
2750.83	5.8203
2753.51	5.33396
2756.18	5.48213
2758.85	4.59126
2761.53	3.64185
2764.2	2.34444
2766.87	1.82762
2769.54	1.60803
2772.2	1.22337
2774.87	1.09282
2777.54	1.19052
2780.2	1.43801
2782.87	0.853869
2785.53	0.531247
2788.19	1.22838
2790.85	1.53592
2793.51	1.89553
2796.17	1.5321
2798.83	0.703157
2801.49	0.872094
2804.15	0.416218
2806.8	0.414793
2809.46	-0.0944456
2812.11	-0.658869
2814.76	-0.412935
2817.42	0.105671
2820.07	1.09978
2822.72	2.78023
2825.37	4.61986
2828.02	7.47476
2830.66	11.6502
2833.31	16.6291
2835.96	21.1944
2838.6	25.7689
2841.24	31.7268
2843.89	37.7242
2846.53	44.7711
2849.17	52.7443
2851.81	60.8872
2854.45	70.0703
2857.09	78.5422
2859.72	86.4781
2862.36	94.5377
2865	102.696
2867.63	109.795
2870.26	116.108
2872.9	121.845
2875.53	126.396
2878.16	131.976
2880.79	135.64
2883.42	140.908
2886.05	145.414
2888.67	148.289
2891.3	152.799
2893.92	157.697
2896.55	162.939
2899.17	168.723
2901.79	175.31
2904.42	182.888
2907.04	192.916
2909.66	204.36
2912.27	216.438
2914.89	229.913
2917.51	242.004
2920.13	252.775
2922.74	262.125
2925.35	269.812
2927.97	275.819
2930.58	279.498
2933.19	281.498
2935.8	282.213
2938.41	280.526
2941.02	276.867
2943.63	269.317
2946.24	263.329
2948.84	253.307
2951.45	242.353
2954.05	231.589
2956.65	220.457
2959.26	210.121
2961.86	200.207
2964.46	189.47
2967.06	178.877
2969.66	170.185
2972.25	161.889
2974.85	153.477
2977.45	145.132
2980.04	136.095
2982.64	126.393
2985.23	117.348
2987.82	106.971
2990.41	98.4259
2993	88.555
2995.59	80.1414
2998.18	72.4698
3000.77	64.8896
3003.36	56.5162
3005.94	49.1383
3008.53	42.3589
3011.11	36.2179
3013.69	29.1534
3016.28	24.3087
3018.86	20.0281
3021.44	16.6045
3024.02	14.0471
3026.6	12.5645
3029.18	10.9826
3031.75	10.604
3034.33	10.1073
3036.9	10.8982
3039.48	11.239
3042.05	11.6071
3044.62	13.3241
3047.19	15.1843
3049.77	16.2833
3052.34	18.3695
3054.9	19.0825
3057.47	20.7382
3060.04	21.702
3062.61	22.1105
3065.17	22.3182
3067.74	21.2175
3070.3	20.8011
3072.86	18.6706
3075.42	16.7326
3077.99	14.394
3080.54	12.7962
3083.1	10.3257
3085.66	9.18959
3088.22	8.16311
3090.78	7.07486
3093.33	5.67836
3095.89	4.64488
3098.44	2.57075
3100.99	1.98167
3103.54	0.932929
3106.1	1.15574
3108.65	1.74092
3111.2	2.51822
3113.74	3.04326
3116.29	4.02145
3118.84	4.43194
3121.38	5.75094
3123.93	6.76303
3126.47	7.76927
3129.01	8.60717
3131.56	9.0224
3134.1	9.47951
3136.64	9.60619
3139.18	10.2861
3141.72	11.0649
3144.26	11.9649
3146.79	12.4647
3149.33	11.9454