File: data/Raman/poly_smoothed/Thy_10_08_38_1x_45s_532 nm_x100_100%_600 gr_mm_01.txt
#Acq. time (s)=	45
#Accumulations=	2
#Range (cm-¹)=	200...3150
#Windows=	2
#Auto scanning=	Off
#Autofocus=	Off
#Macrospot=	Off
#AutoExposure=	Off
#Spike filter=	Multiple accum.
#Delay time (s)=	0
#Binning=	1
#Readout mode=	Signal
#DeNoise=	Off
#ICS correction=	On
#Dark correction=	Off
#Inst. Process=	Off
#Detector Gain=	Best Dynamic Range
#Detector ADC=	20 kHz
#Detector temperature (°C)=	-69.85
#Instrument=	LabRAM HR Evol
#Detector=	Synapse
#Objective=	x100
#Grating=	600 gr/mm
#ND Filter=	100%
#Laser (nm)=	532
#Hole=	100.021
#Range=	Auto
#Laser Pol.=	No
#Raman. Pol.=	No
#Laser Pol. (°)=	-0.0007625
#Raman Pol. (°)=	89.9995
#Collection=	Microscope
#StageXY=	Marzhauser
#StageZ=	Marzhauser
#X (µm)=	-2369.8
#Y (µm)=	230.7
#Z (µm)=	521
#Full time(mm:ss)=	3:18
#Project=
#Sample=
#Site=
#Title=	Thy_10_08_38_2x_45s_532 nm_x100_100%_600 gr_mm
#Remark=
#Date=	06.07.2022 14:29
#Acquired=	06.07.2022 14:29:20
#Base:Fit=	10.08.2022 09:46:25
#Base:Sub=	10.08.2022 09:46:49
#Filter:Polynom=	16.08.2022 10:24:56
#AxisType[0]=Intens
#AxisUnit[0]=Cnt
#AxisType[1]=Spectr
#AxisUnit[1]=1/cm
200.398	0.335536
204.027	4.43754
207.657	5.10935
211.283	6.47386
214.909	7.79233
218.533	8.57055
222.157	10.5092
225.777	10.7386
229.396	12.5004
233.016	13.4409
236.632	15.3516
240.247	15.4842
243.86	16.1791
247.474	15.3592
251.085	14.9699
254.694	16.2184
258.301	16.1529
261.908	16.6874
265.513	17.311
269.116	17.7608
272.718	19.0532
276.319	19.0583
279.918	19.6007
283.516	18.0624
287.113	18.5088
290.708	18.1517
294.302	17.9268
297.894	18.4808
301.485	19.0357
305.073	18.8634
308.661	19.9058
312.247	21.1577
315.833	21.0113
319.415	20.7516
322.997	21.5917
326.579	20.6667
330.156	19.2525
333.735	19.0885
337.31	19.3286
340.885	19.2485
344.458	17.8137
348.03	17.1645
351.6	16.4612
355.17	16.3858
358.737	15.1537
362.304	14.6271
365.868	13.1871
369.431	11.6147
372.994	11.0769
376.554	9.02421
380.112	8.5651
383.669	6.93648
387.225	6.90475
390.781	7.54366
394.334	6.74839
397.885	6.2559
401.436	6.10765
404.984	4.73328
408.532	5.75524
412.078	6.1785
415.623	6.58678
419.166	7.61643
422.708	7.96541
426.248	7.45321
429.788	6.23744
433.326	4.97564
436.86	4.75284
440.395	5.43731
443.929	6.55823
447.461	6.72231
450.99	6.5453
454.52	7.38077
458.048	7.65434
461.573	7.40228
465.099	7.45923
468.623	8.89009
472.144	9.69032
475.666	10.5715
479.184	11.2603
482.703	12.7044
486.218	14.963
489.734	16.4161
493.247	18.0161
496.759	20.0712
500.271	22.0997
503.779	21.1353
507.287	21.0166
510.795	19.4495
514.299	17.8622
517.803	15.873
521.305	17.1591
524.805	18.1993
528.307	17.4453
531.805	17.2166
535.301	15.7134
538.797	13.681
542.291	12.8419
545.783	11.6202
549.275	10.9427
552.765	9.154
556.253	8.29881
559.738	7.1318
563.224	5.52895
566.709	6.23717
570.192	5.82238
573.674	4.05833
577.153	2.97406
580.632	3.10281
584.11	2.33055
587.587	1.82142
591.06	1.84705
594.534	-0.481668
598.005	-1.05808
601.476	0.121169
604.944	2.29443
608.413	3.41592
611.878	3.95343
615.344	4.78651
618.807	4.59447
622.27	6.81789
625.73	8.89134
629.189	10.6334
632.648	12.5926
636.105	13.9997
639.559	15.673
643.013	16.7486
646.467	18.3367
649.918	18.8971
653.368	19.6293
656.816	19.136
660.263	19.2043
663.708	20.2901
667.153	20.7692
670.596	21.4129
674.037	21.2885
677.478	20.9928
680.917	22.101
684.355	23.0735
687.791	23.772
691.224	23.2602
694.658	23.6773
698.091	24.1757
701.522	24.8925
704.95	26.3961
708.379	29.267
711.806	31.2905
715.23	32.6731
718.655	35.1461
722.078	39.5548
725.498	42.7088
728.919	45.0431
732.337	47.8589
735.755	50.1259
739.17	52.5464
742.584	55.3072
745.998	56.8987
749.409	59.6913
752.819	62.6281
756.23	64.5194
759.637	67.3557
763.043	68.3136
766.448	69.1587
769.853	68.2359
773.255	69.9647
776.656	69.9442
780.056	71.2614
783.454	71.8629
786.851	72.9662
790.247	74.6791
793.641	75.8843
797.034	76.0845
800.426	78.4045
803.817	80.7685
807.206	81.3252
810.592	80.4675
813.979	81.2593
817.364	81.2006
820.748	82.1704
824.129	82.9464
827.511	82.6835
830.891	81.5073
834.269	81.3385
837.646	80.3574
841.023	79.0707
844.396	76.99
847.77	73.9187
851.141	71.7661
854.513	69.5923
857.881	70.3835
861.248	67.9698
864.616	66.8032
867.98	64.2795
871.343	63.4478
874.707	62.6926
878.068	61.4646
881.428	59.693
884.786	58.6186
888.143	57.6567
891.498	55.7538
894.855	54.8109
898.208	55.5511
901.56	54.8892
904.91	53.9076
908.26	53.6724
911.608	53.4339
914.955	53.2164
918.298	52.2215
921.643	52.4388
924.986	52.0954
928.328	50.9465
931.668	50.2745
935.006	49.7824
938.344	47.9161
941.681	46.0901
945.014	44.6057
948.349	43.707
951.682	44.643
955.012	44.4857
958.343	40.9945
961.67	39.1611
964.998	40.8786
968.323	41.5289
971.649	42.6584
974.971	44.5554
978.293	45.1011
981.615	44.8406
984.933	44.4009
988.251	44.6366
991.567	44.2792
994.884	43.3572
998.198	42.8039
1001.51	42.8757
1004.82	42.1762
1008.13	40.0897
1011.44	38.9028
1014.75	37.1737
1018.06	35.5374
1021.36	34.6577
1024.66	32.9409
1027.97	32.1782
1031.27	30.3818
1034.57	28.6913
1037.87	26.7775
1041.16	25.0974
1044.46	26.9639
1047.76	27.2462
1051.05	27.3555
1054.34	27.5736
1057.63	25.6424
1060.92	23.8055
1064.21	21.0617
1067.5	19.2502
1070.78	17.7543
1074.07	18.4981
1077.35	17.8335
1080.63	18.7094
1083.91	18.095
1087.19	18.4276
1090.47	18.8875
1093.75	18.3642
1097.03	19.4958
1100.3	19.4965
1103.57	18.4203
1106.84	17.4237
1110.11	17.4226
1113.38	17.6213
1116.65	16.201
1119.92	12.5884
1123.19	11.5387
1126.45	11.071
1129.71	10.5374
1132.97	10.713
1136.23	8.55189
1139.49	9.36645
1142.75	8.2897
1146.01	7.35184
1149.26	7.96309
1152.52	7.96943
1155.77	7.36951
1159.02	7.08578
1162.27	6.24133
1165.52	5.2629
1168.77	5.39233
1172.02	5.60641
1175.26	6.71418
1178.51	6.70373
1181.75	7.63007
1184.99	8.10775
1188.23	8.42487
1191.47	9.19092
1194.71	9.42389
1197.94	10.1685
1201.18	11.5749
1204.41	14.9257
1207.65	19.191
1210.88	23.3731
1214.11	26.7281
1217.34	29.5976
1220.57	33.56
1223.79	36.7501
1227.02	39.7732
1230.24	41.6494
1233.47	42.9876
1236.69	43.7664
1239.91	44.9244
1243.13	47.045
1246.34	48.4787
1249.56	50.8837
1252.78	51.2891
1255.99	50.8101
1259.2	51.2009
1262.42	51.5279
1265.63	51.2813
1268.84	51.5067
1272.04	52.6323
1275.25	53.1731
1278.46	55.2996
1281.66	55.7383
1284.86	57.8414
1288.07	59.1221
1291.27	60.2714
1294.47	61.2348
1297.66	63.2844
1300.86	64.9006
1304.06	66.3642
1307.25	68.1477
1310.44	67.8554
1313.64	69.1777
1316.83	68.3591
1320.02	69.2045
1323.2	68.9831
1326.39	68.9948
1329.58	67.4473
1332.76	65.8241
1335.95	65.4362
1339.13	64.628
1342.31	62.4723
1345.49	60.3725
1348.67	57.9804
1351.85	55.5676
1355.02	54.6738
1358.2	51.6938
1361.37	49.1399
1364.54	46.5554
1367.71	45.3548
1370.88	43.3278
1374.05	40.5623
1377.22	38.9442
1380.39	37.9854
1383.55	36.6601
1386.72	34.8132
1389.88	32.7641
1393.04	31.8854
1396.2	29.6171
1399.36	28.4824
1402.52	29.5267
1405.68	31.3265
1408.83	33.5036
1411.98	36.0558
1415.14	39.6256
1418.29	44.0818
1421.44	49.3085
1424.59	56.4031
1427.74	63.0717
1430.89	69.608
1434.03	75.1912
1437.18	80.3081
1440.32	83.1584
1443.46	86.596
1446.6	88.4612
1449.74	87.5309
1452.88	85.0065
1456.02	83.0896
1459.16	77.6094
1462.29	69.9678
1465.43	63.9738
1468.56	56.5424
1471.69	46.8296
1474.82	38.0887
1477.95	30.4333
1481.08	24.5744
1484.2	18.9362
1487.33	13.3684
1490.46	9.44312
1493.58	6.18199
1496.7	4.0011
1499.82	3.52646
1502.94	2.21611
1506.06	1.42097
1509.18	1.17269
1512.29	1.32704
1515.41	1.33158
1518.52	3.50305
1521.63	4.86707
1524.75	6.03585
1527.85	7.36485
1530.96	9.97063
1534.07	12.2114
1537.18	13.878
1540.28	16.4855
1543.39	18.6081
1546.49	20.8386
1549.59	23.8435
1552.69	27.2216
1555.79	29.5445
1558.89	31.6968
1561.99	33.826
1565.08	36.2383
1568.18	39.43
1571.27	41.8924
1574.37	44.4348
1577.46	46.2912
1580.55	48.6231
1583.64	50.6725
1586.73	51.9973
1589.81	52.7044
1592.9	53.9005
1595.98	54.5228
1599.06	54.0441
1602.15	54.0248
1605.23	54.2443
1608.31	53.795
1611.39	53.4673
1614.46	54.2609
1617.54	54.4385
1620.61	55.2013
1623.69	56.9868
1626.76	59.3367
1629.83	60.9472
1632.9	62.9191
1635.97	66.0623
1639.04	69.1514
1642.11	73.1323
1645.17	76.7611
1648.24	80.1667
1651.3	82.0265
1654.36	84.0173
1657.42	84.3972
1660.48	83.9561
1663.54	82.0072
1666.6	79.2967
1669.66	76.317
1672.71	70.9715
1675.77	65.9739
1678.82	60.1415
1681.87	54.0637
1684.92	48.6352
1687.97	43.4853
1691.02	37.9352
1694.07	33.8376
1697.11	29.286
1700.16	25.4327
1703.2	22.1136
1706.25	18.2329
1709.29	16.0722
1712.33	13.6116
1715.37	12.6265
1718.41	12.8246
1721.44	11.8877
1724.48	11.3695
1727.51	11.2183
1730.55	11.3063
1733.58	10.533
1736.61	10.2214
1739.64	9.92441
1742.67	8.55198
1745.7	7.77066
1748.72	7.67616
1751.75	6.77865
1754.77	6.24023
1757.8	5.25186
1760.82	4.43826
1763.84	3.14185
1766.86	2.54525
1769.88	1.53341
1772.9	-0.198973
1775.91	0.405397
1778.93	0.0619252
1781.94	-0.647787
1784.96	-0.472916
1787.97	-0.402226
1790.98	-0.353746
1793.99	0.35409
1797	0.618747
1800.01	0.856414
1803.01	0.258147
1806.02	-0.438637
1809.02	-0.744998
1812.02	-0.702248
1815.02	-0.473971
1818.03	0.554372
1821.02	1.92689
1824.02	2.57618
1827.02	3.19631
1830.02	3.51215
1833.01	3.53933
1836.01	3.23072
1839	3.20621
1841.99	3.84041
1844.98	3.9351
1847.97	4.94307
1850.96	5.00589
1853.95	4.74488
1856.93	5.17686
1859.92	5.78299
1862.9	5.70962
1865.88	5.34366
1868.87	5.33157
1871.85	4.4655
1874.83	3.18306
1877.81	2.23659
1880.78	1.72203
1882.53	2.00737
1885.52	2.7528
1888.51	3.36469
1891.5	3.99825
1894.48	4.2802
1897.47	4.4861
1900.45	4.69348
1903.43	4.99159
1906.41	5.74357
1909.39	5.59481
1912.37	6.1894
1915.35	5.9667
1918.33	5.95514
1921.3	6.10084
1924.28	7.02169
1927.25	6.8874
1930.22	7.0332
1933.19	7.86259
1936.16	8.14917
1939.13	7.32606
1942.1	7.85868
1945.07	8.42875
1948.03	8.71736
1951	9.46199
1953.96	9.46988
1956.92	9.48061
1959.88	9.80834
1962.84	9.88159
1965.8	9.43751
1968.76	9.26731
1971.72	9.99376
1974.67	9.53678
1977.63	10.0833
1980.58	9.30625
1983.54	9.16507
1986.49	10.4604
1989.44	11.1398
1992.39	11.1825
1995.33	11.7511
1998.28	11.5667
2001.23	12.1791
2004.17	12.9324
2007.12	13.4366
2010.06	13.0712
2013	14.2378
2015.94	14.6335
2018.88	15.5368
2021.82	14.5373
2024.76	13.9355
2027.69	13.3229
2030.63	12.8385
2033.56	13.0781
2036.5	12.8809
2039.43	13.7248
2042.36	13.4925
2045.29	13.6167
2048.22	14.403
2051.15	15.2446
2054.07	15.4237
2057	15.9355
2059.92	15.9395
2062.85	16.0227
2065.77	16.8282
2068.69	16.2077
2071.61	16.3182
2074.53	16.7413
2077.45	16.2929
2080.37	16.9794
2083.28	18.419
2086.2	18.5399
2089.11	19.9914
2092.02	19.382
2094.94	19.916
2097.85	19.9699
2100.76	21.3681
2103.66	22.9538
2106.57	24.4405
2109.48	26.2539
2112.38	26.9002
2115.29	27.1136
2118.19	30.001
2121.09	31.0668
2123.99	30.1672
2126.89	30.6841
2129.79	32.9834
2132.69	33.7979
2135.59	34.4916
2138.48	34.0425
2141.38	34.046
2144.27	35.6435
2147.17	36.3935
2150.06	38.2335
2152.95	40.9182
2155.84	42.6639
2158.73	43.6334
2161.61	44.8743
2164.5	45.663
2167.38	46.43
2170.27	46.843
2173.15	46.6689
2176.03	46.8237
2178.91	47.6273
2181.8	46.6184
2184.67	45.556
2187.55	44.6839
2190.43	44.409
2193.3	42.8088
2196.18	41.7411
2199.05	40.4759
2201.93	38.7207
2204.8	36.6574
2207.67	34.9737
2210.54	33.0406
2213.41	32.3751
2216.27	31.3193
2219.14	30.6055
2222.01	31.4016
2224.87	29.5477
2227.73	28.5885
2230.6	27.2756
2233.46	26.2888
2236.32	25.7437
2239.18	25.2039
2242.03	23.9331
2244.89	23.6557
2247.75	23.3694
2250.6	23.3219
2253.46	21.8111
2256.31	22.5412
2259.16	22.3897
2262.01	23.5647
2264.86	23.293
2267.71	22.2507
2270.56	21.5825
2273.4	21.4919
2276.25	21.194
2279.09	21.8673
2281.94	21.022
2284.78	20.2878
2287.62	19.7595
2290.46	18.952
2293.3	17.8252
2296.14	18.4629
2298.98	19.3387
2301.82	19.989
2304.65	21.0484
2307.49	21.6146
2310.32	21.616
2313.15	20.4367
2315.98	20.4503
2318.81	20.6572
2321.64	19.0795
2324.47	18.9682
2327.3	18.9336
2330.12	18.87
2332.95	18.0601
2335.77	16.2909
2338.6	15.134
2341.42	14.129
2344.24	13.2565
2347.06	12.0783
2349.88	10.1775
2352.7	8.82933
2355.51	7.36029
2358.33	6.7946
2361.14	6.08374
2363.96	6.72833
2366.77	7.92865
2369.58	7.73725
2372.39	7.99876
2375.2	7.94316
2378.01	7.83596
2380.82	7.25312
2383.63	6.94493
2386.43	7.09032
2389.24	6.68791
2392.04	7.40163
2394.84	7.96957
2397.65	8.02816
2400.45	8.63506
2403.25	8.90853
2406.05	9.22137
2408.84	9.22067
2411.64	9.3311
2414.44	9.63515
2417.23	9.80245
2420.02	9.83543
2422.82	10.5071
2425.61	10.5109
2428.4	11.5427
2431.19	11.9458
2433.98	12.5002
2436.77	12.4261
2439.55	11.1683
2442.34	11.3377
2445.12	10.3302
2447.91	9.75445
2450.69	9.60996
2453.47	9.27963
2456.25	9.08888
2459.03	8.74343
2461.81	7.64284
2464.59	7.21139
2467.36	7.00496
2470.14	6.5231
2472.92	5.62514
2475.69	5.3688
2478.46	5.05141
2481.23	5.02844
2484	5.24553
2486.77	4.86844
2489.54	4.21919
2492.31	4.05052
2495.08	4.12138
2497.84	3.64774
2500.61	2.91332
2503.37	2.06442
2506.13	3.15497
2508.9	3.26442
2511.66	3.53997
2514.42	3.42409
2517.18	3.77487
2519.93	3.75604
2522.69	2.77056
2525.45	2.52396
2528.2	2.13223
2530.95	1.60725
2533.71	1.84256
2536.46	2.0701
2539.21	2.03908
2541.96	2.10473
2544.71	2.38838
2547.46	1.64286
2550.2	1.61519
2552.95	1.79268
2555.7	1.53631
2558.44	0.413808
2561.18	1.20632
2563.93	1.10292
2566.67	1.82306
2569.41	2.87358
2572.15	3.86862
2574.88	3.42852
2577.62	2.96803
2580.36	3.27023
2583.09	3.51217
2585.83	2.86824
2588.56	1.68448
2591.29	1.4707
2594.02	1.65621
2596.75	1.92561
2599.48	1.43132
2602.21	1.00672
2604.94	1.31257
2607.67	2.0469
2610.39	2.0216
2613.12	1.33959
2615.84	1.22532
2618.56	1.32081
2621.28	0.569811
2624.01	-0.239195
2626.72	0.299331
2629.44	0.132226
2632.16	-0.0577905
2634.88	0.450306
2637.59	0.187995
2640.31	0.738766
2643.02	0.908941
2645.74	2.07981
2648.45	1.91141
2651.16	2.81285
2653.87	2.38151
2656.58	2.02293
2659.29	2.97708
2661.99	3.65381
2664.7	3.7397
2667.41	4.29478
2670.11	4.74084
2672.81	5.15146
2675.51	4.87693
2678.22	4.06622
2680.92	3.68415
2683.62	2.5132
2686.31	2.26615
2689.01	2.10455
2691.71	2.17769
2694.4	2.5465
2697.1	2.7778
2699.79	3.55897
2702.49	2.58188
2705.18	3.88488
2707.87	4.69316
2710.56	5.52227
2713.25	6.41492
2715.94	7.5623
2718.62	7.99934
2721.31	8.65744
2723.99	9.99399
2726.68	11.1731
2729.36	11.4049
2732.04	12.5057
2734.73	12.8114
2737.41	12.4706
2740.08	12.8017
2742.76	12.6741
2745.44	12.2048
2748.12	11.9399
2750.79	11.0932
2753.47	11.2445
2756.14	9.67491
2758.81	8.90507
2761.49	8.31856
2764.16	7.55371
2766.83	6.62545
2769.5	6.32934
2772.16	6.7491
2774.83	6.09304
2777.5	5.60667
2780.16	4.316
2782.83	4.14453
2785.49	4.07426
2788.15	4.12109
2790.82	3.20033
2793.48	2.48858
2796.14	3.89362
2798.79	3.41549
2801.45	2.27461
2804.11	1.69349
2806.76	1.39062
2809.42	1.4101
2812.07	0.750578
2814.73	1.12765
2817.38	1.93301
2820.03	4.48939
2822.68	7.98498
2825.33	12.2273
2827.98	17.7542
2830.63	24.6755
2833.27	31.833
2835.92	39.1886
2838.56	48.1253
2841.21	58.4249
2843.85	69.8449
2846.49	83.076
2849.13	97.2778
2851.77	111.165
2854.41	125.225
2857.05	139.77
2859.69	153.218
2862.32	165.765
2864.96	176.734
2867.59	186.966
2870.23	195.93
2872.86	203.842
2875.49	210.24
2878.12	215.908
2880.75	221.69
2883.38	226.855
2886.01	232.128
2888.63	236.408
2891.26	241.545
2893.89	247.975
2896.51	254.944
2899.13	261.903
2901.76	271.339
2904.38	282.835
2907	296.841
2909.62	312.644
2912.24	328.41
2914.85	343.458
2917.47	357.735
2920.09	371.209
2922.7	381.115
2925.32	387.704
2927.93	391.844
2930.54	394.103
2933.15	392.203
2935.76	387.984
2938.37	381.938
2940.98	372.359
2943.59	360.908
2946.2	347.836
2948.8	333.619
2951.41	318.372
2954.01	303.407
2956.62	288.383
2959.22	273.55
2961.82	260.224
2964.42	246.225
2967.02	233.617
2969.62	223.616
2972.22	213.372
2974.81	203.913
2977.41	194.808
2980	183.657
2982.6	172.77
2985.19	160.336
2987.78	147.558
2990.38	135.907
2992.97	122.398
2995.56	111.508
2998.14	99.9483
3000.73	90.0369
3003.32	79.7627
3005.91	69.88
3008.49	61.6252
3011.07	54.4642
3013.66	47.9221
3016.24	42.4008
3018.82	37.7318
3021.4	34.1083
3023.98	31.3097
3026.56	29.705
3029.14	27.5654
3031.71	27.9697
3034.29	28.9986
3036.87	30.164
3039.44	33.0279
3042.01	34.0111
3044.59	35.5888
3047.16	37.2548
3049.73	38.1238
3052.3	38.565
3054.87	38.8037
3057.43	38.7004
3060	38.3578
3062.57	36.6416
3065.13	34.2463
3067.7	31.5143
3070.26	29.5305
3072.82	26.6168
3075.39	23.8421
3077.95	20.5284
3080.51	15.9806
3083.07	11.529
3085.63	8.32659
3088.18	5.84088
3090.74	3.91227
3093.29	2.42602
3095.85	1.9586
3098.4	1.47648
3100.95	1.53073
3103.51	1.48768
3106.06	1.35268
3108.61	1.03656
3111.16	1.21521
3113.71	1.73721
3116.25	1.68965
3118.8	2.33046
3121.35	2.73688
3123.89	2.53775
3126.44	2.78175
3128.98	2.7583
3131.52	3.61681
3134.06	3.72018
3136.6	3.84889
3139.14	3.43897
3141.68	3.03198
3144.22	3.51609
3146.76	5.16722
3149.29	6.06891