File: data/Raman/poly_smoothed/Thy_00_07_2_1x_45s_532 nm_x100_100%_600 gr_mm_01.txt
#Acq. time (s)=	45
#Accumulations=	2
#Range (cm-¹)=	200...3150
#Windows=	2
#Auto scanning=	Off
#Autofocus=	Off
#Macrospot=	Off
#AutoExposure=	Off
#Spike filter=	Multiple accum.
#Delay time (s)=	0
#Binning=	1
#Readout mode=	Signal
#DeNoise=	Off
#ICS correction=	On
#Dark correction=	Off
#Inst. Process=	Off
#Detector Gain=	Best Dynamic Range
#Detector ADC=	20 kHz
#Detector temperature (°C)=	-69.85
#Instrument=	LabRAM HR Evol
#Detector=	Synapse
#Objective=	x100
#Grating=	600 gr/mm
#ND Filter=	100%
#Laser (nm)=	532
#Hole=	100.021
#Range=	Auto
#Laser Pol.=	No
#Raman. Pol.=	No
#Laser Pol. (°)=	-0.0007625
#Raman Pol. (°)=	89.9995
#Collection=	Microscope
#StageXY=	Marzhauser
#StageZ=	Marzhauser
#X (µm)=	8998.5
#Y (µm)=	-3084.5
#Z (µm)=	-54.85
#Full time(mm:ss)=	3:14
#Project=
#Sample=
#Site=
#Title=	Thy_00_07_2_2x_45s_532 nm_x100_100%_600 gr_mm
#Remark=
#Date=	28.06.2022 10:02
#Acquired=	28.06.2022 10:02:35
#Base:Fit=	10.08.2022 10:07:56
#Base:Sub=	10.08.2022 10:08:40
#Filter:Polynom=	16.08.2022 10:26:06
#AxisType[0]=Intens
#AxisUnit[0]=Cnt
#AxisType[1]=Spectr
#AxisUnit[1]=1/cm
200.407	15.9616
204.035	11.4913
207.665	9.67064
211.291	7.71648
214.916	6.10335
218.541	4.50933
222.163	3.80334
225.785	1.93324
229.404	1.37672
233.022	0.439902
236.638	0.166743
240.255	0.175751
243.868	0.352965
247.48	0.879947
251.091	2.66706
254.702	2.93284
258.31	2.20012
261.916	1.9999
265.521	3.26026
269.125	2.40991
272.727	1.70729
276.328	2.11618
279.927	2.56665
283.525	2.52041
287.121	3.8807
290.716	4.88933
294.31	4.07988
297.9	4.22187
301.491	5.18287
305.081	5.49655
308.669	5.34956
312.256	5.19633
315.839	7.18142
319.423	8.2452
323.006	9.2982
326.585	9.72651
330.165	10.8706
333.741	12.2459
337.318	11.9507
340.894	12.2011
344.466	10.5241
348.039	10.5665
351.608	9.59073
355.176	9.35705
358.745	8.6952
362.31	7.65278
365.876	6.91083
369.439	5.84918
373	5.17738
376.56	3.47888
380.12	1.84623
383.677	0.925744
387.233	1.02165
390.787	1.75559
394.34	0.858885
397.894	1.85551
401.444	2.1999
404.993	2.49002
408.54	3.31503
412.086	3.52027
415.631	4.31448
419.174	5.35037
422.716	5.00645
426.257	4.47181
429.794	5.14993
433.332	3.79117
436.868	4.21823
440.403	4.50685
443.937	4.8343
447.468	5.33904
450.999	5.07706
454.528	5.53613
458.057	6.17091
461.582	7.28827
465.107	8.88301
468.629	10.0737
472.152	11.4397
475.672	13.8005
479.192	15.9623
482.709	17.307
486.226	17.4188
489.74	19.1886
493.255	21.0697
496.767	22.781
500.277	24.2739
503.788	24.9974
507.295	24.646
510.801	25.0469
514.308	24.967
517.811	23.0228
521.313	22.3358
524.814	22.2924
528.313	21.2106
531.811	19.1661
535.308	18.3533
538.803	16.3438
542.297	15.5494
545.789	15.3401
549.281	15.1015
552.771	14.1274
556.259	13.5796
559.747	13.0917
563.233	12.6655
566.717	11.4809
570.2	9.7459
573.68	8.50251
577.161	7.18045
580.64	7.99011
584.118	7.0921
587.593	7.05785
591.068	6.52145
594.54	5.47693
598.013	4.79999
601.484	2.92977
604.952	2.01363
608.421	2.19495
611.886	2.17477
615.35	2.58704
618.815	1.55354
622.276	1.65108
625.738	1.78587
629.197	3.36011
632.655	3.66979
636.113	4.32128
639.568	6.23298
643.021	6.04421
646.473	8.03242
649.924	8.40389
653.376	9.72674
656.824	9.97253
660.271	12.0803
663.716	12.5939
667.161	12.6654
670.604	12.8455
674.045	12.8707
677.486	12.2207
680.925	12.0235
684.361	13.1051
687.797	14.2807
691.232	16.9148
694.666	19.6838
698.099	21.431
701.528	21.9051
704.958	22.7007
708.387	24.865
711.814	25.816
715.238	26.4092
718.663	28.5179
722.084	32.3033
725.506	34.6052
728.925	36.2846
732.345	37.378
735.761	39.3178
739.178	40.5585
742.592	42.7708
746.006	44.5697
749.417	46.2213
752.827	47.3485
756.236	49.246
759.645	51.8962
763.051	55.1366
766.456	58.2308
769.859	60.2606
773.261	63.9252
776.664	65.7972
780.064	65.9617
783.462	66.8078
786.859	67.6306
790.255	67.8043
793.649	68.1295
797.042	68.5255
800.434	69.7655
803.823	70.6808
807.212	69.7198
810.6	69.4065
813.987	68.3359
817.372	68.4681
820.754	69.0298
824.137	70.1434
827.519	71.9219
830.897	71.6269
834.276	72.8871
837.654	72.6624
841.029	72.6041
844.404	72.2075
847.776	70.8026
851.149	68.144
854.519	67.476
857.889	65.6221
861.256	62.2855
864.622	59.9896
867.988	58.1454
871.351	55.6482
874.713	53.4301
878.074	50.0077
881.435	47.8574
884.794	45.5183
888.15	44.6691
891.506	42.5333
894.861	41.8684
898.214	41.3962
901.566	41.1704
904.916	41.2024
908.266	41.4179
911.614	41.8416
914.961	40.9995
918.306	42.0187
921.651	42.0391
924.994	43.2675
928.336	44.274
931.674	44.2905
935.014	44.8976
938.352	46.135
941.687	45.0137
945.022	45.2932
948.357	45.299
951.688	46.0306
955.02	46.0918
958.348	44.1663
961.678	41.7025
965.004	41.614
968.331	42.632
971.655	43.6367
974.979	45.2067
978.3	44.3809
981.62	45.0831
984.941	43.9079
988.259	42.1503
991.575	40.3203
994.89	39.311
998.204	39.1077
1001.52	38.4551
1004.83	38.8733
1008.14	37.8026
1011.45	36.996
1014.76	36.1635
1018.06	35.9725
1021.37	34.16
1024.67	33.0025
1027.97	32.4017
1031.27	31.9707
1034.57	30.0055
1037.87	26.9011
1041.17	24.7983
1044.47	25.0723
1047.76	27.6378
1051.06	28.1513
1054.35	26.5732
1057.64	25.9663
1060.93	24.1674
1064.22	23.5052
1067.5	21.2903
1070.79	20.3579
1074.08	20.4654
1077.36	20.7481
1080.64	19.4008
1083.92	19.1278
1087.2	19.5994
1090.48	19.459
1093.76	19.8348
1097.03	21.0477
1100.31	20.9956
1103.58	20.6909
1106.85	20.2844
1110.12	20.3752
1113.39	18.7211
1116.66	17.0128
1119.93	15.8809
1123.19	15.031
1126.46	13.2045
1129.72	10.4462
1132.98	8.64059
1136.24	7.87776
1139.5	6.69688
1142.76	7.5669
1146.01	6.35712
1149.27	4.7311
1152.53	4.77537
1155.78	4.26007
1159.03	2.84682
1162.28	1.98766
1165.53	2.86338
1168.78	3.2947
1172.02	4.24864
1175.27	6.76101
1178.51	8.03779
1181.76	9.96762
1185	11.1919
1188.24	12.6208
1191.48	13.7547
1194.71	15.6429
1197.95	15.6119
1201.19	16.9625
1204.42	19.0163
1207.65	20.3742
1210.88	25.4806
1214.12	29.1802
1217.35	32.8744
1220.57	38.1157
1223.8	41.242
1227.03	43.8532
1230.25	46.7838
1233.47	49.957
1236.69	51.8801
1239.92	53.5756
1243.13	54.5035
1246.35	56.1336
1249.57	58.1333
1252.78	58.8445
1256	58.3685
1259.21	58.342
1262.42	56.8964
1265.63	56.4576
1268.84	54.7787
1272.05	52.4482
1275.26	50.736
1278.46	50.517
1281.67	51.2548
1284.87	52.7676
1288.07	54.1543
1291.27	55.4603
1294.47	55.8684
1297.67	58.4731
1300.87	60.1541
1304.06	63.5634
1307.26	66.9692
1310.45	70.4531
1313.64	73.8331
1316.83	78.011
1320.02	81.242
1323.21	83.118
1326.4	83.4715
1329.59	83.6145
1332.77	83.1157
1335.95	82.1733
1339.14	80.3477
1342.32	78.1095
1345.5	75.7442
1348.67	72.8908
1351.85	69.5627
1355.03	66.7571
1358.2	64.547
1361.38	60.3786
1364.55	56.0609
1367.72	52.0745
1370.89	48.8472
1374.06	46.0084
1377.23	45.077
1380.39	44.687
1383.56	44.6468
1386.72	44.1804
1389.89	43.2254
1393.05	43.455
1396.21	44.0556
1399.37	43.3998
1402.52	41.6638
1405.68	41.394
1408.84	42.8843
1411.99	44.4505
1415.15	45.8889
1418.3	49.7159
1421.45	54.7221
1424.6	60.2969
1427.75	66.4942
1430.89	72.6515
1434.04	79.0893
1437.18	83.551
1440.33	89.3746
1443.47	93.2404
1446.61	95.2892
1449.75	95.9895
1452.89	96.0345
1456.03	95.719
1459.16	93.47
1462.3	88.2162
1465.43	82.2035
1468.56	75.6269
1471.7	68.3957
1474.83	60.1289
1477.96	52.0772
1481.08	44.6556
1484.21	39.0231
1487.34	31.921
1490.46	26.2057
1493.58	21.8098
1496.71	18.1188
1499.83	15.9998
1502.95	13.6208
1506.07	13.356
1509.18	14.2048
1512.3	14.8591
1515.41	14.7523
1518.53	15.1655
1521.64	16.1426
1524.75	16.5197
1527.86	18.0981
1530.97	19.9821
1534.08	21.6723
1537.19	22.7346
1540.29	24.4248
1543.4	27.3138
1546.5	30.0161
1549.6	33.6805
1552.7	36.8145
1555.8	38.7544
1558.9	40.6809
1562	40.4605
1565.09	42.1338
1568.19	43.3631
1571.28	45.2476
1574.37	46.3261
1577.47	48.0736
1580.56	50.0998
1583.64	53.2464
1586.73	55.7629
1589.82	56.9202
1592.9	57.8438
1595.99	59.1668
1599.07	58.9728
1602.15	60.1284
1605.23	59.8036
1608.31	59.7752
1611.39	60.0431
1614.47	59.5438
1617.55	60.3813
1620.62	61.4671
1623.7	63.8879
1626.77	65.1598
1629.84	65.7954
1632.91	65.8133
1635.98	66.9548
1639.05	70.2814
1642.11	75.1813
1645.18	78.0291
1648.24	82.4245
1651.31	86.613
1654.37	88.6897
1657.43	90.2066
1660.49	92.4075
1663.55	91.2155
1666.61	90.3432
1669.66	88.5238
1672.72	85.4139
1675.77	82.1049
1678.83	79.0921
1681.88	74.8654
1684.93	68.8104
1687.98	62.3892
1691.03	57.5521
1694.07	54.0275
1697.12	48.3918
1700.17	44.3244
1703.21	39.6918
1706.25	35.0964
1709.29	30.6702
1712.33	28.662
1715.37	27.0346
1718.41	25.3023
1721.45	23.765
1724.49	21.4776
1727.52	20.126
1730.55	18.6053
1733.59	18.2282
1736.62	16.7428
1739.65	15.5162
1742.68	14.7133
1745.7	13.7973
1748.73	13.9998
1751.76	13.5061
1754.78	13.3366
1757.8	11.545
1760.83	10.239
1763.85	10.0725
1766.87	8.89488
1769.89	7.87084
1772.9	7.0773
1775.92	6.22837
1778.94	5.80484
1781.95	5.94465
1784.96	4.78873
1787.97	4.53343
1790.99	4.40626
1794	3.92853
1797	3.33939
1800.01	3.46335
1803.02	3.47571
1806.02	2.78024
1809.03	2.45353
1812.03	2.1342
1815.03	1.86853
1818.03	2.05996
1821.03	2.44365
1824.03	2.41638
1827.03	2.83242
1830.02	2.72789
1833.02	2.72558
1836.01	2.51848
1839.01	2.94412
1842	3.30398
1844.99	4.17484
1847.98	5.03923
1850.97	5.40375
1853.95	5.06632
1856.94	4.94685
1859.93	3.50871
1862.91	3.93211
1865.89	3.57574
1868.87	4.11373
1871.85	3.49864
1874.83	4.17384
1877.81	4.55444
1880.79	4.83212
1882.52	5.79711
1885.51	5.73719
1888.5	5.83176
1891.49	6.11128
1894.47	6.20149
1897.46	5.98756
1900.44	5.05961
1903.42	3.85124
1906.4	4.20909
1909.38	4.90031
1912.36	5.48453
1915.34	4.71793
1918.32	4.62269
1921.29	4.11897
1924.27	3.31443
1927.24	3.95747
1930.21	3.15237
1933.18	3.93527
1936.15	3.78196
1939.12	4.10672
1942.09	4.55215
1945.06	5.95835
1948.02	6.55096
1950.99	8.15783
1953.95	7.91461
1956.91	8.27814
1959.88	8.54707
1962.84	8.97103
1965.8	9.0121
1968.75	7.13988
1971.71	7.10049
1974.67	6.72619
1977.62	6.97259
1980.58	7.64097
1983.53	7.53857
1986.48	7.89183
1989.43	7.96321
1992.38	9.80163
1995.33	9.76362
1998.27	8.90593
2001.22	9.31061
2004.16	9.16241
2007.11	8.55741
2010.05	8.55585
2012.99	8.86227
2015.93	8.5675
2018.87	8.43027
2021.81	8.08791
2024.75	6.80203
2027.69	6.28911
2030.62	7.39481
2033.56	6.87378
2036.49	5.95149
2039.42	5.87044
2042.35	5.43685
2045.28	5.88486
2048.21	5.58887
2051.14	5.09825
2054.07	5.96147
2056.99	6.10255
2059.92	6.26692
2062.84	7.21143
2065.76	6.53989
2068.68	7.90467
2071.6	7.93381
2074.52	9.26608
2077.44	9.54433
2080.36	9.44689
2083.27	9.19615
2086.19	10.0754
2089.1	10.7204
2092.02	9.82619
2094.93	10.3924
2097.84	11.2702
2100.75	12.4455
2103.66	12.9626
2106.56	12.3753
2109.47	11.8359
2112.38	11.3604
2115.28	9.97226
2118.18	9.49722
2121.09	8.1044
2123.99	8.24006
2126.89	7.79815
2129.79	6.63152
2132.68	5.83189
2135.58	5.92438
2138.48	6.32264
2141.37	7.36901
2144.27	7.13841
2147.16	6.92363
2150.05	7.23403
2152.94	6.84844
2155.83	7.31281
2158.72	8.3921
2161.6	9.12837
2164.49	9.98733
2167.38	11.4442
2170.26	11.4572
2173.14	12.5986
2176.03	11.9691
2178.91	11.8548
2181.79	11.1979
2184.67	10.9326
2187.54	9.92173
2190.42	9.36364
2193.3	8.28852
2196.17	7.31914
2199.05	5.4824
2201.92	5.02735
2204.79	5.29067
2207.66	5.10976
2210.53	4.5457
2213.4	4.81371
2216.27	3.10007
2219.13	2.63097
2222	2.73652
2224.86	4.05933
2227.72	5.16717
2230.59	5.79051
2233.45	6.56778
2236.31	8.46262
2239.17	10.0612
2242.03	10.5693
2244.88	12.2165
2247.74	12.7044
2250.59	12.8205
2253.45	13.1852
2256.3	13.7822
2259.15	14.0751
2262	14.5355
2264.85	14.7076
2267.7	14.1988
2270.55	15.0443
2273.4	14.5486
2276.24	15.2669
2279.09	14.2152
2281.93	13.9375
2284.77	13.8695
2287.62	14.2312
2290.46	13.3605
2293.3	13.1496
2296.13	13.7092
2298.97	13.0438
2301.81	12.8612
2304.64	14.0567
2307.48	13.2787
2310.31	13.4621
2313.14	12.8666
2315.98	13.2762
2318.81	12.7717
2321.64	12.4841
2324.46	11.9762
2327.29	12.3702
2330.12	12.0308
2332.94	11.2713
2335.77	9.89777
2338.59	9.08689
2341.41	8.25362
2344.23	7.33897
2347.05	7.60111
2349.87	7.44015
2352.69	5.51931
2355.51	5.21863
2358.32	3.65551
2361.14	3.51542
2363.95	3.30152
2366.76	2.85142
2369.58	2.46063
2372.39	1.64649
2375.2	1.38111
2378	1.56124
2380.81	2.21968
2383.62	1.89592
2386.43	2.25507
2389.23	2.06427
2392.03	2.57082
2394.84	3.2024
2397.64	4.069
2400.44	4.53579
2403.24	4.65606
2406.04	5.51414
2408.84	7.58836
2411.63	9.29304
2414.43	10.5381
2417.22	12.4791
2420.02	11.6031
2422.81	11.8185
2425.6	12.2131
2428.39	12.0458
2431.18	12.2285
2433.97	11.6106
2436.76	11.0465
2439.54	10.6657
2442.33	10.7503
2445.12	10.6912
2447.9	10.055
2450.68	8.84989
2453.46	7.52574
2456.24	7.15
2459.02	6.92911
2461.8	6.58102
2464.58	5.69269
2467.36	4.47486
2470.13	3.96553
2472.91	4.34738
2475.68	3.9805
2478.45	4.18005
2481.23	4.51365
2484	3.64861
2486.77	1.77058
2489.54	1.23956
2492.3	1.59726
2495.07	1.69279
2497.84	2.17545
2500.6	2.39663
2503.36	2.42088
2506.13	3.5723
2508.89	4.39499
2511.65	4.77602
2514.41	3.92668
2517.17	2.96516
2519.93	3.74297
2522.68	4.6201
2525.44	4.60708
2528.19	4.73202
2530.95	4.51072
2533.7	3.50722
2536.45	3.69216
2539.2	5.00755
2541.95	5.34522
2544.7	4.35846
2547.45	4.68883
2550.2	4.47169
2552.94	5.10667
2555.69	5.59173
2558.43	6.00586
2561.18	6.32602
2563.92	6.21432
2566.66	6.63282
2569.4	7.72629
2572.14	8.20179
2574.88	8.00326
2577.61	7.26176
2580.35	7.11304
2583.09	7.4957
2585.82	8.33721
2588.55	8.26806
2591.29	8.62714
2594.02	8.45719
2596.75	8.7218
2599.48	8.01992
2602.21	8.16223
2604.93	9.02405
2607.66	9.54193
2610.39	8.8641
2613.11	8.62214
2615.83	9.79514
2618.56	9.61765
2621.28	9.69242
2624	8.52072
2626.72	8.62773
2629.44	9.05393
2632.15	9.42408
2634.87	9.70327
2637.59	9.78563
2640.3	9.75605
2643.02	9.49236
2645.73	9.87956
2648.44	9.34567
2651.15	9.35395
2653.86	8.77745
2656.57	8.11678
2659.28	7.75543
2661.99	7.42276
2664.69	6.95593
2667.4	6.99188
2670.1	7.57965
2672.81	7.34072
2675.51	7.06222
2678.21	7.15594
2680.91	7.67326
2683.61	7.97672
2686.31	8.27603
2689	8.91257
2691.7	10.3716
2694.4	11.8431
2697.09	13.4493
2699.79	14.7012
2702.48	14.9948
2705.17	15.3358
2707.86	16.0046
2710.55	15.3369
2713.24	14.8737
2715.93	14.5901
2718.62	14.6459
2721.3	14.3664
2723.99	13.9848
2726.67	13.8737
2729.35	13.8565
2732.04	14.0468
2734.72	13.5253
2737.4	13.4483
2740.08	12.9277
2742.76	13.3096
2745.43	14.0027
2748.11	13.8673
2750.79	14.1361
2753.46	14.1933
2756.14	14.9564
2758.81	14.9301
2761.48	13.565
2764.15	12.029
2766.82	10.7906
2769.49	10.4024
2772.16	9.00542
2774.82	7.0198
2777.49	5.46583
2780.16	4.27541
2782.82	3.46827
2785.48	2.73306
2788.15	2.31898
2790.81	1.24183
2793.47	0.477498
2796.13	-0.0186623
2798.79	-0.31504
2801.44	-0.844292
2804.1	-0.39448
2806.76	0.0244337
2809.41	0.658273
2812.07	1.70357
2814.72	1.92037
2817.37	2.65524
2820.02	4.6429
2822.67	7.29819
2825.32	10.4278
2827.97	14.9069
2830.62	20.1892
2833.26	26.4632
2835.91	32.8196
2838.56	39.429
2841.2	47.6799
2843.84	57.3312
2846.48	67.9847
2849.12	79.9934
2851.77	92.9793
2854.4	105.975
2857.04	119.939
2859.68	132.325
2862.32	143.899
2864.95	155.986
2867.59	166.491
2870.22	177.108
2872.85	185.792
2875.48	194.91
2878.11	201.345
2880.74	207.287
2883.37	212.966
2886	218.86
2888.63	222.774
2891.25	227.942
2893.88	232.352
2896.5	238.139
2899.13	244.352
2901.75	251.258
2904.37	259.654
2906.99	270.292
2909.61	282.86
2912.23	296.347
2914.85	309.565
2917.46	322.692
2920.08	333.472
2922.7	340.773
2925.31	347.037
2927.92	351.798
2930.54	353.964
2933.15	353.649
2935.76	350.524
2938.37	345.708
2940.98	339.477
2943.58	329.77
2946.19	318.716
2948.8	308.291
2951.4	295.759
2954.01	283.155
2956.61	271.023
2959.21	258.116
2961.81	246.437
2964.41	234.732
2967.01	224.345
2969.61	214.96
2972.21	206.498
2974.81	196.822
2977.4	187.603
2980	177.807
2982.59	167.732
2985.18	156.572
2987.78	145.144
2990.37	133.933
2992.96	121.931
2995.55	111.368
2998.14	101.483
3000.73	90.9197
3003.31	80.2167
3005.9	70.9889
3008.48	61.875
3011.07	53.8654
3013.65	46.7472
3016.23	39.8164
3018.81	34.8461
3021.4	30.3582
3023.97	25.7688
3026.55	22.0709
3029.13	19.5924
3031.71	18.4414
3034.28	17.8432
3036.86	18.5355
3039.43	18.9151
3042.01	20.7625
3044.58	22.4794
3047.15	23.578
3049.72	25.1574
3052.29	26.2452
3054.86	27.4186
3057.43	28.3223
3060	28.6205
3062.56	27.7131
3065.13	26.8448
3067.69	25.9243
3070.26	24.5842
3072.82	22.4679
3075.38	21.7925
3077.94	19.4859
3080.5	17.5137
3083.06	14.3313
3085.62	11.1439
3088.18	8.55683
3090.73	7.16613
3093.29	5.81425
3095.84	5.34425
3098.4	4.89432
3100.95	4.17572
3103.5	3.93005
3106.05	4.40056
3108.6	5.01608
3111.15	4.6245
3113.7	5.09357
3116.25	6.02096
3118.79	6.67099
3121.34	7.61918
3123.88	7.94591
3126.43	9.21052
3128.97	9.95232
3131.51	10.5947
3134.06	11.424
3136.6	12.3466
3139.14	13.4504
3141.67	12.5752
3144.21	12.3705
3146.75	12.6757
3149.29	12.2614