File: data/Raman/poly_smoothed/Thy_00_07_46_1x_45s_532 nm_x100_100%_600 gr_mm_01_0.txt
#Acq. time (s)=	45
#Accumulations=	2
#Range (cm-¹)=	200...3150
#Windows=	2
#Auto scanning=	Off
#Autofocus=	Off
#Macrospot=	Off
#AutoExposure=	Off
#Spike filter=	Multiple accum.
#Delay time (s)=	0
#Binning=	1
#Readout mode=	Signal
#DeNoise=	Off
#ICS correction=	On
#Dark correction=	Off
#Inst. Process=	Off
#Detector Gain=	Best Dynamic Range
#Detector ADC=	20 kHz
#Detector temperature (°C)=	-69.85
#Instrument=	LabRAM HR Evol
#Detector=	Synapse
#Objective=	x100
#Grating=	600 gr/mm
#ND Filter=	100%
#Laser (nm)=	532
#Hole=	100.021
#Range=	Auto
#Laser Pol.=	No
#Raman. Pol.=	No
#Laser Pol. (°)=	-0.0007625
#Raman Pol. (°)=	89.9995
#Collection=	Microscope
#StageXY=	Marzhauser
#StageZ=	Marzhauser
#X (µm)=	-1428.5
#Y (µm)=	-621.2
#Z (µm)=	-227.9
#Full time(mm:ss)=	3:18
#Project=
#Sample=
#Site=
#Title=	Thy_00_07_46_2x_45s_532 nm_x100_100%_600 gr_mm
#Remark=
#Date=	29.06.2022 09:45
#Acquired=	29.06.2022 09:45:15
#Base:Fit=	10.08.2022 10:07:56
#Base:Sub=	10.08.2022 10:08:40
#Filter:Polynom=	16.08.2022 10:26:06
#AxisType[0]=Intens
#AxisUnit[0]=Cnt
#AxisType[1]=Spectr
#AxisUnit[1]=1/cm
200.523	46.4732
204.154	43.9558
207.781	40.0921
211.409	35.1666
215.034	32.6573
218.659	30.6228
222.281	28.9434
225.903	25.9172
229.522	22.392
233.14	19.5039
236.756	17.8254
240.373	15.6024
243.986	14.5478
247.598	12.1264
251.208	10.6088
254.818	10.4648
258.427	9.13939
262.034	8.89696
265.638	7.78471
269.242	7.15968
272.844	7.96678
276.445	6.9088
280.044	6.64159
283.642	4.52994
287.238	4.9531
290.833	5.34438
294.425	5.23664
298.017	7.5514
301.608	8.8793
305.198	10.4288
308.786	11.2504
312.371	13.6737
315.956	14.8781
319.54	14.7543
323.122	15.0106
326.701	15.9592
330.281	15.0914
333.857	15.9703
337.434	16.4681
341.008	15.6809
344.582	16.9402
348.153	15.6475
351.724	15.5069
355.292	14.8261
358.861	16.1645
362.426	14.2129
365.99	12.4334
369.555	10.8264
373.116	10.0509
376.676	9.12406
380.236	8.3208
383.793	7.70931
387.349	7.0003
390.903	7.79117
394.456	8.26691
398.007	10.3999
401.56	10.5947
405.108	8.95965
408.656	9.29015
412.202	10.2757
415.746	9.59313
419.29	8.76386
422.831	9.32755
426.37	9.21415
429.909	9.51791
433.447	10.637
436.983	10.8032
440.519	12.6268
444.052	13.4627
447.583	13.1357
451.114	13.9364
454.643	13.8522
458.169	14.9953
461.696	15.9731
465.222	16.5604
468.744	19.2723
472.267	20.3836
475.787	21.3208
479.307	22.0933
482.823	22.8865
486.341	24.6354
489.855	26.357
493.37	28.7457
496.881	28.8717
500.391	28.5492
503.902	27.6058
507.409	27.2379
510.915	26.3278
514.42	25.9043
517.925	26.4053
521.427	25.1098
524.928	24.7781
528.427	23.7736
531.925	24.4671
535.422	23.8178
538.917	22.7414
542.411	20.8508
545.903	18.3179
549.395	16.0946
552.884	15.9448
556.373	15.1476
559.86	13.6877
563.346	12.1271
566.831	12.1937
570.314	13.232
573.794	12.8446
577.274	12.3255
580.754	10.5265
584.23	8.53637
587.706	6.61088
591.181	6.48971
594.653	5.12901
598.126	3.79046
601.595	3.37568
605.065	3.09042
608.532	2.37033
611.999	3.88822
615.463	4.27452
618.928	5.1948
622.389	5.21245
625.851	4.03769
629.31	3.69494
632.767	5.07476
636.223	7.78389
639.68	9.10268
643.134	10.9175
646.586	12.6308
650.037	15.068
653.486	16.1001
656.936	17.4698
660.383	18.934
663.829	19.3113
667.273	20.1474
670.716	20.8111
674.158	21.2982
677.598	20.105
681.035	19.5852
684.473	21.7588
687.909	23.8828
691.344	25.1491
694.778	26.3437
698.211	28.237
701.64	29.7325
705.07	30.7861
708.498	31.6522
711.924	34.9184
715.35	37.7005
718.774	40.4865
722.196	41.8422
725.618	45.7883
729.037	46.7207
732.456	48.3267
735.873	50.5676
739.289	53.0305
742.703	55.2054
746.116	58.3182
749.529	59.973
752.938	64.8695
756.347	67.1878
759.756	69.7463
763.162	70.9973
766.567	74.2599
769.97	77.4544
773.372	77.6057
776.773	79.2546
780.174	78.993
783.573	79.7399
786.97	80.017
790.365	81.0086
793.76	83.0884
797.153	83.7024
800.543	84.3843
803.933	81.8193
807.322	80.0057
810.71	77.3087
814.097	76.9192
817.483	78.0518
820.865	79.9645
824.248	80.4729
827.629	80.2692
831.008	80.6511
834.387	80.7203
837.765	79.4518
841.139	78.1923
844.514	76.0965
847.886	73.4052
851.259	72.236
854.629	68.5957
857.997	64.7663
861.366	59.6954
864.732	55.6508
868.098	52.1802
871.461	49.0505
874.823	48.3297
878.184	46.3617
881.545	43.9689
884.903	40.9778
888.26	39.4329
891.616	38.9944
894.97	40.3834
898.323	42.7017
901.675	44.7195
905.026	46.1833
908.375	47.3979
911.723	48.3991
915.07	48.624
918.415	48.5617
921.76	49.7777
925.103	49.9572
928.443	50.0114
931.783	48.092
935.123	46.5757
938.461	45.4048
941.796	43.0524
945.131	41.8851
948.465	41.8405
951.797	40.3134
955.128	38.9761
958.457	35.5277
961.786	32.7423
965.113	32.6153
968.44	33.9171
971.763	36.177
975.086	37.3863
978.409	38.7961
981.729	40.6101
985.048	40.7843
988.367	39.6513
991.683	38.7409
994.998	37.6335
998.312	38.6524
1001.62	39.1165
1004.94	40.2112
1008.25	40.5831
1011.56	41.2594
1014.86	40.4033
1018.17	39.2277
1021.48	38.4238
1024.78	37.5876
1028.08	35.7953
1031.38	33.2934
1034.68	29.5726
1037.98	27.6553
1041.28	25.8749
1044.57	27.2261
1047.87	28.0751
1051.16	27.7599
1054.45	27.4463
1057.75	25.2759
1061.04	23.8471
1064.32	20.9113
1067.61	19.3311
1070.9	19.3474
1074.18	21.1956
1077.47	22.4564
1080.75	22.8194
1084.03	23.4111
1087.31	23.2596
1090.59	23.6357
1093.86	23.0939
1097.14	23.3861
1100.41	23.3403
1103.69	25.4343
1106.96	25.0958
1110.23	25.1352
1113.5	26.5622
1116.77	26.0424
1120.03	26.4969
1123.3	26.1742
1126.56	24.7479
1129.83	22.9824
1133.09	21.4019
1136.35	19.8921
1139.61	18.9473
1142.86	17.3986
1146.12	17.0105
1149.38	16.1578
1152.63	14.5239
1155.88	12.2701
1159.14	10.5317
1162.39	6.74849
1165.63	3.90395
1168.88	3.32874
1172.13	3.98894
1175.38	4.89598
1178.62	5.1423
1181.86	5.65819
1185.1	5.79396
1188.34	6.80045
1191.58	8.44699
1194.82	9.57292
1198.06	10.6694
1201.29	12.3463
1204.53	15.3384
1207.76	18.9662
1210.99	22.4485
1214.22	28.8144
1217.45	32.2483
1220.68	36.979
1223.91	41.6366
1227.13	46.1268
1230.36	48.0692
1233.58	50.5317
1236.8	53.6294
1240.02	54.4731
1243.24	53.4296
1246.46	53.9874
1249.67	55.5072
1252.89	55.9371
1256.1	53.7397
1259.32	52.6708
1262.53	50.9011
1265.74	48.9656
1268.95	47.3531
1272.15	46.6401
1275.36	44.4156
1278.57	44.7109
1281.77	46.8445
1284.97	49.4102
1288.18	51.7812
1291.38	55.3835
1294.58	59.8181
1297.78	62.8321
1300.97	68.2266
1304.17	73.5259
1307.36	77.9607
1310.55	83.2533
1313.75	87.427
1316.94	90.9018
1320.13	92.9837
1323.32	93.2994
1326.5	95.2631
1329.69	95.9743
1332.87	96.4397
1336.06	95.1291
1339.24	93.5226
1342.42	91.4638
1345.6	87.4916
1348.78	82.8073
1351.96	78.7987
1355.13	74.6612
1358.31	72.3319
1361.48	69.784
1364.65	65.9444
1367.82	64.0495
1370.99	61.7986
1374.16	59.9707
1377.33	58.8828
1380.5	58.633
1383.66	56.4792
1386.83	54.6036
1389.99	52.9222
1393.15	50.3736
1396.31	49.0808
1399.47	47.5761
1402.63	45.8476
1405.78	46.9541
1408.94	47.3415
1412.1	50.37
1415.25	52.7919
1418.4	55.2254
1421.55	57.9843
1424.7	60.8897
1427.85	65.8272
1431	70.6879
1434.14	75.4259
1437.29	79.963
1440.43	83.4391
1443.57	88.5506
1446.71	91.1721
1449.85	91.6774
1452.99	92.651
1456.13	92.3809
1459.26	89.8261
1462.4	87.1092
1465.54	82.0202
1468.67	76.7704
1471.8	70.9021
1474.93	65.0437
1478.06	59.5964
1481.19	52.8373
1484.31	46.0231
1487.44	40.5316
1490.56	35.6965
1493.69	29.8308
1496.81	25.9339
1499.93	23.0791
1503.05	20.3362
1506.17	18.6505
1509.28	16.283
1512.4	13.9905
1515.52	12.7808
1518.63	12.501
1521.74	14.2149
1524.85	14.7622
1527.96	16.9786
1531.07	19.5151
1534.18	23.1468
1537.29	25.5048
1540.39	27.8878
1543.5	31.7653
1546.6	36.3001
1549.7	41.3769
1552.8	45.1561
1555.9	50.1104
1559	53.3801
1562.1	58.0367
1565.19	60.5945
1568.29	62.6238
1571.38	65.3087
1574.47	68.5622
1577.56	68.5437
1580.66	67.5324
1583.74	68.3243
1586.83	68.2135
1589.92	67.403
1593.01	66.5855
1596.09	64.7233
1599.17	62.8862
1602.25	60.7308
1605.34	58.1453
1608.41	56.1517
1611.49	54.1184
1614.57	52.1151
1617.65	52.5423
1620.72	52.8501
1623.79	53.4349
1626.87	55.0945
1629.94	57.0614
1633.01	59.5664
1636.08	62.5695
1639.15	64.3472
1642.21	67.1049
1645.28	69.4651
1648.34	71.7234
1651.41	74.4563
1654.47	76.8542
1657.53	79.6971
1660.59	81.7501
1663.65	82.1097
1666.71	80.7157
1669.76	78.6972
1672.82	75.7273
1675.87	73.0458
1678.93	69.4663
1681.98	64.3521
1685.03	60.0973
1688.08	55.2646
1691.13	50.7342
1694.17	44.9366
1697.22	40.4203
1700.27	35.2801
1703.31	31.0756
1706.35	26.8756
1709.39	23.1415
1712.43	18.5483
1715.47	15.2387
1718.51	12.9045
1721.55	10.9896
1724.58	9.12271
1727.62	9.12192
1730.65	9.81069
1733.68	9.98251
1736.72	9.95155
1739.74	8.18852
1742.77	7.87773
1745.8	7.50074
1748.83	6.72467
1751.85	6.32911
1754.88	6.3098
1757.9	6.24808
1760.92	5.80418
1763.95	4.97935
1766.96	4.45287
1769.98	4.07462
1773	4.02669
1776.02	2.74168
1779.03	2.16312
1782.05	2.36076
1785.06	0.341257
1788.07	0.111265
1791.08	0.822668
1794.09	1.05687
1797.1	1.04199
1800.11	1.99745
1803.12	3.01522
1806.12	3.68347
1809.12	3.72949
1812.13	3.323
1815.13	2.70122
1818.13	1.91331
1821.13	2.19769
1824.13	2.87364
1827.13	2.63283
1830.12	2.1898
1833.12	2.3946
1836.11	2.44783
1839.1	2.66901
1842.09	1.98915
1845.09	1.86237
1848.08	1.50282
1851.06	1.56518
1854.05	1.62582
1857.04	2.05769
1860.02	2.60723
1863.01	2.80811
1865.99	3.48389
1868.97	3.63242
1871.95	3.18834
1874.93	3.10708
1877.91	3.61059
1880.89	3.98025
1882.46	4.73966
1885.45	4.57937
1888.43	5.808
1891.42	5.90151
1894.41	6.38504
1897.39	6.51211
1900.37	6.92574
1903.36	7.26406
1906.34	8.63186
1909.32	9.12593
1912.29	7.65303
1915.27	7.18639
1918.25	6.62446
1921.23	6.67058
1924.2	6.90634
1927.17	6.55979
1930.15	6.28456
1933.12	5.47009
1936.09	4.49629
1939.06	3.31892
1942.02	3.46016
1944.99	2.70181
1947.96	2.75897
1950.92	3.46232
1953.88	3.65501
1956.85	4.62387
1959.81	4.69376
1962.77	5.36304
1965.73	5.54941
1968.69	6.45746
1971.64	6.58415
1974.6	7.11238
1977.55	6.89089
1980.51	6.72667
1983.46	6.02148
1986.41	4.93026
1989.36	4.5117
1992.31	4.80016
1995.26	4.55287
1998.21	4.24593
2001.15	4.26185
2004.1	4.50556
2007.04	3.53236
2009.99	3.90949
2012.93	3.73549
2015.87	2.83254
2018.81	3.85587
2021.75	3.21927
2024.68	3.87373
2027.62	4.14464
2030.56	5.01884
2033.49	4.96701
2036.42	4.58753
2039.36	4.71202
2042.29	5.1785
2045.22	7.0037
2048.14	7.65788
2051.07	7.45532
2054	7.47421
2056.93	7.20466
2059.85	7.39546
2062.77	6.9995
2065.7	6.7737
2068.62	6.49315
2071.54	6.08996
2074.46	5.6908
2077.38	5.48632
2080.29	4.91366
2083.21	4.882
2086.12	3.93694
2089.04	3.61486
2091.95	2.73328
2094.86	2.41757
2097.77	2.65092
2100.68	2.828
2103.59	2.35564
2106.5	3.04977
2109.41	3.76923
2112.31	4.41396
2115.21	5.77269
2118.12	6.67895
2121.02	6.039
2123.92	6.60293
2126.82	6.90138
2129.72	7.39434
2132.62	6.81798
2135.51	6.4251
2138.41	6.16989
2141.31	6.57752
2144.2	6.35243
2147.09	6.60335
2149.98	5.81498
2152.87	5.70203
2155.76	5.38472
2158.65	5.16205
2161.54	4.56615
2164.43	4.2017
2167.31	4.74528
2170.2	5.13181
2173.08	4.5632
2175.96	4.23483
2178.84	4.59657
2181.72	4.59966
2184.6	4.72862
2187.48	4.83556
2190.36	5.9318
2193.23	4.81296
2196.11	4.0442
2198.98	4.16571
2201.85	3.85967
2204.72	4.05281
2207.59	4.40427
2210.46	4.18348
2213.33	3.7965
2216.2	4.39917
2219.07	4.08706
2221.93	3.69085
2224.8	3.92948
2227.66	3.55307
2230.52	2.86845
2233.39	3.03034
2236.25	3.65368
2239.1	4.27408
2241.96	4.70695
2244.82	5.36457
2247.68	5.93716
2250.53	6.61902
2253.38	7.37977
2256.24	7.50669
2259.09	7.7932
2261.94	6.49875
2264.79	5.45085
2267.64	6.05966
2270.49	5.51923
2273.33	5.46909
2276.18	4.7758
2279.02	4.6929
2281.87	3.28857
2284.71	2.53529
2287.55	2.38244
2290.39	1.63486
2293.23	0.937207
2296.07	1.04394
2298.91	1.51201
2301.74	2.62151
2304.58	3.2649
2307.41	4.47311
2310.25	5.91009
2313.08	6.14849
2315.91	6.70934
2318.74	7.50722
2321.57	8.13821
2324.4	8.01713
2327.23	7.59059
2330.05	6.58017
2332.88	5.9193
2335.7	5.27534
2338.52	3.96897
2341.35	2.52606
2344.17	1.9565
2346.99	1.35454
2349.81	0.63129
2352.62	-0.400131
2355.44	-1.29703
2358.26	-1.71302
2361.07	-1.69798
2363.89	-0.869572
2366.7	0.441824
2369.51	1.1867
2372.32	1.61502
2375.13	1.96023
2377.94	1.6807
2380.75	2.45923
2383.56	3.08275
2386.36	3.54618
2389.17	4.27994
2391.97	3.70818
2394.77	3.9038
2397.58	2.89777
2400.38	2.22746
2403.18	2.08831
2405.97	2.09967
2408.77	2.77326
2411.57	3.73323
2414.37	4.17108
2417.16	4.51868
2419.95	4.68055
2422.75	5.05217
2425.54	4.95391
2428.33	6.51048
2431.12	6.95427
2433.91	7.45585
2436.7	7.20271
2439.48	7.13836
2442.27	7.52897
2445.05	6.98031
2447.84	7.18897
2450.62	6.93912
2453.4	8.08792
2456.18	7.35704
2458.96	6.23498
2461.74	6.007
2464.52	5.35109
2467.29	4.79828
2470.07	4.4238
2472.85	4.97842
2475.62	5.06447
2478.39	4.57273
2481.16	3.95932
2483.93	4.10389
2486.7	3.7368
2489.47	2.98382
2492.24	2.18052
2495.01	1.41049
2497.77	2.12136
2500.54	1.5354
2503.3	0.409845
2506.06	0.0573337
2508.83	-0.317896
2511.59	-0.897855
2514.35	-1.10528
2517.11	-0.353175
2519.86	1.49494
2522.62	1.78096
2525.38	2.05979
2528.13	2.48391
2530.89	2.57903
2533.64	2.87783
2536.39	4.02633
2539.14	4.71523
2541.89	5.01099
2544.64	5.68241
2547.39	7.00838
2550.14	7.53728
2552.88	7.5052
2555.63	7.93003
2558.37	8.73595
2561.11	8.26751
2563.86	8.72607
2566.6	8.75817
2569.34	8.09775
2572.08	7.15023
2574.82	6.51364
2577.55	6.63795
2580.29	6.64653
2583.02	6.91346
2585.76	7.97907
2588.49	7.47281
2591.22	6.87478
2593.96	5.84923
2596.69	3.99704
2599.42	3.81872
2602.14	4.32144
2604.87	4.25655
2607.6	4.64648
2610.32	5.73842
2613.05	5.78017
2615.77	5.37116
2618.49	5.30518
2621.22	5.32725
2623.94	6.02573
2626.66	5.3023
2629.37	6.05602
2632.09	6.60454
2634.81	6.15327
2637.53	6.10863
2640.24	6.47834
2642.96	6.26902
2645.67	7.13553
2648.38	7.76121
2651.09	8.11039
2653.8	7.81434
2656.51	7.61245
2659.22	7.41948
2661.93	7.22914
2664.63	8.77737
2667.34	9.94125
2670.04	10.4965
2672.75	11.8842
2675.45	12.2398
2678.15	11.3311
2680.85	10.6121
2683.55	10.1654
2686.25	10.2609
2688.94	10.0707
2691.64	10.4819
2694.34	10.7468
2697.03	11.418
2699.73	11.4065
2702.42	11.9941
2705.11	12.4895
2707.8	12.8813
2710.49	13.1945
2713.18	13.5997
2715.87	13.129
2718.55	13.8244
2721.24	13.7522
2723.93	14.2993
2726.61	14.7335
2729.29	14.9339
2731.98	15.1355
2734.66	14.9683
2737.34	14.2296
2740.02	13.5985
2742.7	12.1257
2745.37	12.4729
2748.05	11.9734
2750.72	10.521
2753.4	10.0292
2756.07	10.3242
2758.75	9.78294
2761.42	9.04567
2764.09	8.18713
2766.76	6.98845
2769.43	6.55215
2772.1	6.17698
2774.76	5.40146
2777.43	4.57797
2780.1	3.59058
2782.76	3.0416
2785.42	1.35304
2788.09	0.542946
2790.75	1.11424
2793.41	1.26166
2796.07	1.18277
2798.73	0.913921
2801.39	0.874125
2804.04	0.89481
2806.7	1.09161
2809.35	1.18701
2812.01	1.03821
2814.66	1.68857
2817.31	2.49755
2819.96	4.45111
2822.61	5.67387
2825.26	7.7274
2827.91	10.969
2830.56	14.8959
2833.21	19.7348
2835.85	25.1839
2838.5	30.4765
2841.14	37.6268
2843.78	45.1785
2846.42	54.2424
2849.06	65.127
2851.71	76.0029
2854.34	88.8319
2856.98	100.623
2859.62	111.594
2862.26	123.335
2864.89	134.883
2867.53	145.709
2870.16	155.014
2872.79	163.824
2875.42	171.648
2878.05	180.224
2880.68	186.706
2883.31	192.325
2885.94	198.173
2888.57	204.073
2891.19	209.657
2893.82	215.789
2896.44	221.785
2899.07	228.839
2901.69	236.862
2904.31	246.422
2906.93	256.262
2909.55	268.776
2912.17	279.611
2914.79	290.812
2917.41	302.211
2920.02	312.437
2922.64	320.97
2925.25	326.907
2927.86	330.702
2930.48	331.945
2933.09	329.997
2935.7	325.921
2938.31	320.789
2940.92	314.089
2943.53	305.512
2946.13	295.609
2948.74	285.024
2951.34	273.313
2953.95	261.894
2956.55	249.281
2959.15	237.812
2961.75	226.139
2964.35	214.53
2966.95	203.047
2969.55	192.909
2972.15	182.509
2974.75	172.821
2977.34	162.458
2979.94	151.886
2982.53	141.373
2985.13	130.564
2987.72	118.364
2990.31	106.268
2992.9	94.8341
2995.49	83.0544
2998.08	72.7293
3000.67	62.0999
3003.25	52.4289
3005.84	43.6831
3008.42	35.5603
3011.01	28.9191
3013.59	23.1268
3016.17	17.6474
3018.76	13.5683
3021.34	9.29373
3023.92	6.80997
3026.49	2.79465
3029.07	1.3278
3031.65	0.615567
3034.23	1.66343
3036.8	1.30055
3039.38	1.48656
3041.95	2.36529
3044.52	3.64469
3047.09	6.25848
3049.66	8.60518
3052.23	10.8019
3054.8	12.5712
3057.37	13.2954
3059.94	13.1997
3062.5	12.7147
3065.07	12.5458
3067.63	12.5967
3070.2	12.2598
3072.76	11.6621
3075.32	11.3554
3077.88	10.1445
3080.44	8.9929
3083	7.65897
3085.56	6.22303
3088.12	5.26218
3090.67	4.21227
3093.23	4.02911
3095.78	5.17773
3098.34	5.4818
3100.89	5.84306
3103.44	7.06613
3105.99	8.70709
3108.54	10.3482
3111.09	11.969
3113.64	13.3665
3116.19	14.5193
3118.74	15.9641
3121.28	16.8743
3123.83	18.1759
3126.37	19.6533
3128.91	21.2656
3131.46	22.3886
3134	24.1742
3136.54	25.5747
3139.08	27.4584
3141.62	28.2442
3144.16	29.7583
3146.69	31.1895
3149.23	33.8729