File: data/Raman/poly_smoothed/Thy_50_12_10_1x_45s_532 nm_x100_100%_600 gr_mm_01.txt
#Acq. time (s)=	45
#Accumulations=	2
#Range (cm-¹)=	200...3150
#Windows=	2
#Auto scanning=	Off
#Autofocus=	Off
#Macrospot=	Off
#AutoExposure=	Off
#Spike filter=	Multiple accum.
#Delay time (s)=	0
#Binning=	1
#Readout mode=	Signal
#DeNoise=	Off
#ICS correction=	On
#Dark correction=	Off
#Inst. Process=	Off
#Detector Gain=	Best Dynamic Range
#Detector ADC=	20 kHz
#Detector temperature (°C)=	-69.85
#Instrument=	LabRAM HR Evol
#Detector=	Synapse
#Objective=	x100
#Grating=	600 gr/mm
#ND Filter=	100%
#Laser (nm)=	532
#Hole=	100.021
#Range=	Auto
#Laser Pol.=	No
#Raman. Pol.=	No
#Laser Pol. (°)=	-0.0007625
#Raman Pol. (°)=	89.9995
#Collection=	Microscope
#StageXY=	Marzhauser
#StageZ=	Marzhauser
#X (µm)=	-5106.8
#Y (µm)=	1508.8
#Z (µm)=	63.1
#Full time(mm:ss)=	3:19
#Project=
#Sample=
#Site=
#Title=	Thy_50_12_10_2x_45s_532 nm_x100_100%_600 gr_mm
#Remark=
#Date=	07.07.2022 09:56
#Acquired=	07.07.2022 09:56:57
#Base:Fit=	10.08.2022 10:03:08
#Base:Fit=	10.08.2022 10:03:15
#Base:Fit=	10.08.2022 10:03:19
#Base:Fit=	10.08.2022 10:04:29
#Base:Sub=	10.08.2022 10:04:45
#Filter:Polynom=	16.08.2022 10:20:24
#AxisType[0]=Intens
#AxisUnit[0]=Cnt
#AxisType[1]=Spectr
#AxisUnit[1]=1/cm
200.43	8.8805
204.061	7.43778
207.688	6.05218
211.316	4.94925
214.941	4.6336
218.566	4.28565
222.188	2.40051
225.809	1.76382
229.43	1.48206
233.047	0.807801
236.663	1.4981
240.278	1.47587
243.894	2.86272
247.506	2.43604
251.116	3.27109
254.725	3.37483
258.333	3.5915
261.939	3.8699
265.546	5.71309
269.15	8.48972
272.752	9.0694
276.353	10.3945
279.952	12.0023
283.55	12.4316
287.146	13.468
290.739	16.0496
294.333	16.7271
297.925	17.8819
301.516	18.1133
305.106	16.2834
308.694	17.1822
312.279	16.1738
315.864	15.1053
319.448	15.0082
323.029	14.9362
326.61	14.5156
330.19	14.178
333.766	11.5163
337.343	10.1727
340.917	10.589
344.491	10.1783
348.062	9.84633
351.633	10.2094
355.201	9.10572
358.77	8.34913
362.335	7.91274
365.899	6.60782
369.464	7.1638
373.025	6.36575
376.585	6.17719
380.143	6.71301
383.702	6.71213
387.258	6.71062
390.812	4.70304
394.365	5.81653
397.916	5.76794
401.467	5.33766
405.015	5.24914
408.565	6.13717
412.111	5.3473
415.656	4.89007
419.197	4.3175
422.739	4.58513
426.279	5.02209
429.819	4.99654
433.356	3.9795
436.893	3.58096
440.428	3.74067
443.96	5.26021
447.492	5.80402
451.023	6.96848
454.553	8.49662
458.079	8.24817
461.606	8.88836
465.132	11.5227
468.654	12.8974
472.177	12.3457
475.696	14.191
479.217	15.4914
482.733	15.5514
486.251	15.7287
489.765	15.5954
493.278	15.2958
496.791	15.4604
500.301	15.384
503.81	17.1664
507.319	17.7325
510.825	17.5451
514.33	18.6503
517.833	19.5745
521.337	19.1467
524.838	17.9678
528.337	19.4273
531.835	19.9782
535.332	18.3053
538.827	16.4333
542.321	15.0333
545.814	14.5229
549.305	14.9838
552.795	14.2172
556.284	12.8221
559.771	10.3508
563.257	10.0318
566.742	7.93967
570.223	6.1409
573.705	5.5024
577.185	5.61318
580.665	4.87352
584.141	5.85358
587.617	5.38434
591.092	4.83509
594.564	4.54334
598.037	4.11028
601.506	5.53384
604.976	5.64813
608.443	5.56711
611.91	6.77405
615.374	7.87152
618.839	6.12521
622.3	5.51012
625.761	7.53882
629.221	8.80793
632.679	10.423
636.135	10.9861
639.592	11.3524
643.045	12.1647
646.497	12.9149
649.948	13.8765
653.398	15.6913
656.846	16.6519
660.293	18.4124
663.738	18.7554
667.185	18.4825
670.628	18.4122
674.067	17.7526
677.508	18.0945
680.947	19.8696
684.385	21.4728
687.821	21.265
691.256	20.7451
694.69	20.9084
698.121	20.1012
701.552	18.678
704.982	16.6953
708.41	18.3176
711.836	19.6377
715.262	21.9179
718.685	23.6699
722.108	25.0802
725.53	27.8939
728.949	27.4318
732.369	30.1927
735.785	32.3421
739.2	35.0896
742.616	37.6853
746.028	39.7439
749.441	42.178
752.851	45.1472
756.26	47.8427
759.667	51.4492
763.075	54.8486
766.479	57.324
769.883	61.3326
773.285	62.5357
776.686	65.0982
780.085	66.9963
783.484	67.9331
786.881	68.7059
790.276	70.3875
793.671	73.8501
797.064	75.6029
800.456	77.3388
803.846	75.4692
807.236	74.396
810.624	73.0151
814.01	72.3278
817.394	72.0423
820.778	71.2448
824.161	72.1824
827.543	71.0034
830.921	70.0984
834.3	69.5415
837.676	68.0258
841.053	67.3699
844.426	66.0362
847.8	62.619
851.171	61.3173
854.542	59.7929
857.911	56.8778
861.279	55.645
864.645	53.6481
868.01	55.1029
871.375	53.7486
874.737	53.0434
878.097	51.5881
881.457	49.8277
884.817	47.5753
888.174	46.8919
891.53	45.5798
894.884	44.1572
898.237	44.3329
901.589	42.9037
904.94	43.0087
908.289	42.18
911.637	39.4503
914.984	39.4667
918.33	37.4475
921.674	37.2537
925.015	36.1403
928.357	34.7767
931.698	33.8368
935.037	33.1011
938.373	33.3585
941.71	34.3162
945.046	36.2424
948.378	37.8986
951.711	38.6074
955.043	39.4819
958.372	38.9293
961.701	39.2727
965.027	38.8449
968.354	39.3285
971.678	38.8007
975	37.5284
978.324	36.8636
981.644	35.57
984.962	34.501
988.282	34.6257
991.598	33.5314
994.913	32.5493
998.227	32.3517
1001.54	30.9136
1004.85	28.34
1008.16	26.8507
1011.47	27.7338
1014.78	27.5096
1018.08	28.8799
1021.39	28.4918
1024.69	30.2845
1028	31.2177
1031.3	33.6107
1034.6	34.5541
1037.9	34.1415
1041.19	35.0809
1044.49	35.2351
1047.79	35.8748
1051.08	35.3733
1054.37	35.3898
1057.66	33.5873
1060.95	32.2163
1064.24	31.5632
1067.53	31.5239
1070.81	29.4792
1074.1	27.1929
1077.38	24.9573
1080.66	23.0691
1083.94	21.091
1087.22	20.0963
1090.5	20.3508
1093.78	20.0434
1097.05	19.5648
1100.33	18.7432
1103.6	19.6171
1106.87	20.0494
1110.15	20.5023
1113.41	21.959
1116.68	21.6043
1119.95	21.4311
1123.21	22.2458
1126.48	20.967
1129.74	20.9663
1133	21.4413
1136.26	21.8168
1139.52	21.1559
1142.78	21.5476
1146.04	19.4389
1149.29	17.8422
1152.55	16.0039
1155.8	15.0608
1159.05	13.0724
1162.3	12.439
1165.55	11.9861
1168.8	10.4718
1172.05	9.05494
1175.29	8.15061
1178.54	8.84619
1181.78	8.27387
1185.02	8.71036
1188.26	9.94799
1191.5	11.3459
1194.74	11.7008
1197.97	12.9739
1201.21	14.6591
1204.44	18.1214
1207.68	20.6293
1210.91	24.2817
1214.14	26.0815
1217.37	29.8188
1220.6	31.451
1223.82	34.8042
1227.05	35.9555
1230.27	36.7337
1233.49	39.5589
1236.72	40.8624
1239.94	42.6421
1243.16	43.6334
1246.37	43.9833
1249.59	45.4762
1252.8	46.0746
1256.02	48.6535
1259.23	51.6163
1262.44	54.9538
1265.66	57.8927
1268.87	60.3775
1272.07	64.1035
1275.28	65.7338
1278.48	69.2647
1281.69	71.2881
1284.89	73.1498
1288.09	73.1003
1291.3	74.5555
1294.49	76.7994
1297.69	77.1294
1300.89	76.7805
1304.09	76.4763
1307.28	74.9333
1310.47	74.1361
1313.66	72.2093
1316.86	71.435
1320.05	70.9177
1323.23	69.5239
1326.42	66.477
1329.61	63.5101
1332.79	62.2911
1335.98	60.6356
1339.16	59.9904
1342.34	56.7496
1345.52	54.1826
1348.7	52.8438
1351.87	51.5819
1355.05	49.7813
1358.23	49.0737
1361.4	46.7155
1364.57	45.9348
1367.74	44.8401
1370.91	45.0887
1374.08	44.7428
1377.25	45.251
1380.42	47.1448
1383.58	47.274
1386.75	47.2548
1389.91	48.3912
1393.07	49.5225
1396.23	48.6385
1399.39	46.8467
1402.55	44.2921
1405.7	43.0802
1408.86	43.2891
1412.01	43.512
1415.17	43.8261
1418.32	45.2677
1421.47	45.9181
1424.62	49.319
1427.77	53.9997
1430.92	58.1959
1434.06	62.9887
1437.2	67.5725
1440.35	71.0353
1443.49	73.9786
1446.63	76.5099
1449.77	78.488
1452.91	78.1711
1456.05	78.1437
1459.18	77.6578
1462.32	76.1865
1465.45	72.9324
1468.59	68.8387
1471.72	63.1598
1474.85	58.1081
1477.98	52.9613
1481.11	47.8999
1484.23	43.2413
1487.36	38.1792
1490.48	34.4259
1493.61	31.732
1496.73	29.1285
1499.85	27.9541
1502.97	28.4135
1506.09	27.7618
1509.2	27.5974
1512.32	27.6855
1515.44	28.0589
1518.55	28.0733
1521.66	28.1275
1524.77	29.0714
1527.88	30.291
1530.99	32.7671
1534.1	35.6587
1537.21	38.3946
1540.31	40.6954
1543.42	43.3837
1546.52	47.5156
1549.62	52.2199
1552.72	55.0415
1555.82	58.2007
1558.92	60.9095
1562.02	63.6805
1565.11	65.9578
1568.21	67.7792
1571.3	70.369
1574.39	72.3404
1577.49	73.0259
1580.58	74.1073
1583.67	74.0751
1586.75	73.7423
1589.84	74.0893
1592.93	73.1484
1596.01	72.9555
1599.09	71.4221
1602.18	69.9562
1605.26	70.1015
1608.34	67.9437
1611.41	66.7076
1614.49	65.8614
1617.57	64.8949
1620.64	64.4446
1623.72	65.9341
1626.79	65.1158
1629.86	63.361
1632.93	62.5292
1636	61.6471
1639.07	62.4869
1642.14	62.4643
1645.2	63.5114
1648.27	64.2786
1651.33	65.0446
1654.39	64.8399
1657.45	64.3018
1660.51	64.2502
1663.57	62.9588
1666.63	61.1247
1669.69	59.5995
1672.74	57.7927
1675.79	54.834
1678.85	50.5664
1681.9	47.034
1684.95	43.1374
1688	40.249
1691.05	35.3548
1694.1	31.9824
1697.14	29.3572
1700.19	25.6543
1703.23	22.1726
1706.27	19.8235
1709.32	17.6405
1712.35	15.2857
1715.39	14.062
1718.43	14.8179
1721.47	14.802
1724.5	13.8621
1727.54	14.3784
1730.57	13.0654
1733.61	12.5962
1736.64	11.9317
1739.67	11.4493
1742.7	11.8831
1745.72	10.1938
1748.75	9.05212
1751.78	7.4695
1754.8	7.36902
1757.82	7.30484
1760.85	6.48108
1763.87	4.81294
1766.89	2.59697
1769.91	2.2876
1772.92	0.93444
1775.94	0.0972608
1778.96	-0.851497
1781.97	-1.3713
1784.98	-0.699107
1788	-0.169974
1791.01	0.504384
1794.01	1.3088
1797.02	0.786762
1800.03	1.25674
1803.04	1.45784
1806.04	1.22965
1809.05	2.03735
1812.05	2.77468
1815.05	3.31157
1818.05	3.60269
1821.05	4.44635
1824.05	3.68088
1827.05	3.83952
1830.04	4.12385
1833.04	3.841
1836.03	3.44534
1839.03	3.44927
1842.02	2.8511
1845.01	2.98768
1848	2.67188
1850.99	2.55625
1853.97	2.59243
1856.96	3.67962
1859.94	3.70372
1862.93	3.35711
1865.91	4.7826
1868.89	4.22588
1871.87	4.12811
1874.85	4.33213
1877.83	5.31434
1880.81	6.17538
1882.56	6.93376
1885.55	7.38013
1888.54	7.32129
1891.52	7.47985
1894.51	7.69859
1897.49	7.67047
1900.48	8.48865
1903.46	8.43019
1906.44	8.15117
1909.42	8.17898
1912.4	7.8086
1915.38	6.8934
1918.35	6.1071
1921.33	6.41075
1924.3	5.24775
1927.28	4.49597
1930.25	5.19912
1933.22	4.93453
1936.19	4.1327
1939.16	3.98173
1942.13	4.01842
1945.09	3.7646
1948.06	4.92356
1951.03	6.09311
1953.99	6.56033
1956.95	6.23113
1959.91	6.83406
1962.87	6.72427
1965.83	6.48841
1968.79	6.74024
1971.75	6.55521
1974.7	5.32277
1977.66	4.9493
1980.61	4.18036
1983.56	3.83707
1986.52	3.32301
1989.47	2.65524
1992.41	2.72642
1995.36	2.7672
1998.31	2.49139
2001.26	3.12571
2004.2	3.83663
2007.15	3.77361
2010.09	4.66206
2013.03	5.27426
2015.97	6.09473
2018.91	6.4301
2021.85	8.11891
2024.79	8.13436
2027.72	8.32908
2030.66	8.72102
2033.59	8.29091
2036.53	9.1259
2039.46	9.36545
2042.39	10.493
2045.32	10.7649
2048.25	9.50284
2051.18	9.81446
2054.1	9.5946
2057.03	9.30782
2059.95	10.8246
2062.88	11.5092
2065.8	13.2932
2068.72	14.3069
2071.64	16.327
2074.56	18.4554
2077.48	20.9025
2080.39	21.812
2083.31	23.6547
2086.22	25.1872
2089.14	26.7266
2092.05	29.0655
2094.96	31.2445
2097.87	32.695
2100.78	34.1469
2103.69	35.2815
2106.6	38.3564
2109.51	39.8224
2112.41	41.3023
2115.32	41.8188
2118.22	43.2258
2121.12	44.6792
2124.02	46.7371
2126.92	48.9621
2129.82	50.9624
2132.72	53.0494
2135.62	55.5948
2138.51	57.6092
2141.41	60.4319
2144.3	64.0693
2147.19	66.4259
2150.09	68.1514
2152.97	70.0201
2155.86	71.8316
2158.75	72.5365
2161.64	75.3222
2164.53	76.2236
2167.41	76.2454
2170.3	76.8267
2173.18	77.2647
2176.06	77.8087
2178.94	78.2417
2181.82	76.837
2184.7	76.4279
2187.58	75.6515
2190.46	75.0855
2193.33	73.472
2196.21	70.6322
2199.08	68.3172
2201.95	66.0772
2204.83	64.5568
2207.7	61.9152
2210.57	61.0453
2213.43	60.2395
2216.3	57.5673
2219.17	55.476
2222.03	52.9479
2224.9	50.979
2227.76	48.8101
2230.62	46.7119
2233.49	45.0779
2236.34	43.4636
2239.2	41.741
2242.06	39.5621
2244.92	38.185
2247.78	36.1408
2250.63	33.6561
2253.48	33.1516
2256.34	31.484
2259.19	30.2634
2262.04	29.5018
2264.89	27.1831
2267.74	25.2672
2270.59	24.0908
2273.43	23.5818
2276.28	22.8782
2279.12	21.3406
2281.97	20.5925
2284.81	19.234
2287.65	18.3502
2290.49	17.8011
2293.33	15.4346
2296.17	15.0917
2299.01	15.3475
2301.84	16.0277
2304.68	17.1257
2307.51	16.6657
2310.35	16.638
2313.18	17.0785
2316.01	18.4302
2318.84	17.7717
2321.67	18.078
2324.5	18.0424
2327.33	17.2153
2330.15	16.7499
2332.98	16.519
2335.8	15.5516
2338.62	14.6739
2341.45	13.8246
2344.27	13.3721
2347.09	11.0055
2349.91	9.06323
2352.72	7.86758
2355.54	5.8518
2358.36	5.37866
2361.17	4.50939
2363.98	4.10155
2366.8	4.6755
2369.61	4.81744
2372.42	3.80855
2375.23	3.1445
2378.04	2.15823
2380.85	3.35342
2383.66	3.73006
2386.46	3.87298
2389.26	4.00645
2392.07	4.20071
2394.87	4.7464
2397.67	5.42534
2400.47	6.57084
2403.27	6.76601
2406.07	8.05116
2408.87	7.53775
2411.67	7.3476
2414.46	6.92466
2417.26	6.59084
2420.05	6.38745
2422.84	6.36743
2425.64	5.52448
2428.43	4.96677
2431.22	3.89508
2434.01	2.20947
2436.79	1.70666
2439.58	0.599023
2442.37	0.435194
2445.15	0.574163
2447.93	1.20164
2450.72	1.72198
2453.5	1.72899
2456.28	3.17687
2459.06	4.51367
2461.84	3.84547
2464.62	3.95799
2467.39	3.7907
2470.17	4.37229
2472.94	5.16652
2475.72	4.49283
2478.49	4.53853
2481.26	4.89872
2484.03	4.97903
2486.8	5.53605
2489.57	4.91515
2492.34	3.47435
2495.1	2.46485
2497.87	3.14777
2500.63	3.15952
2503.4	2.66162
2506.16	2.86092
2508.92	3.49101
2511.68	3.66068
2514.44	3.26846
2517.2	3.17754
2519.96	3.60657
2522.72	3.53424
2525.47	3.60557
2528.23	3.89209
2530.98	2.20588
2533.74	2.0448
2536.49	2.5871
2539.24	3.86283
2541.99	4.01515
2544.74	4.05978
2547.49	5.28056
2550.23	4.88376
2552.98	4.97093
2555.72	4.94901
2558.47	4.73691
2561.21	5.12305
2563.95	5.61517
2566.69	4.55885
2569.43	4.94282
2572.17	5.09651
2574.91	5.37679
2577.65	5.50885
2580.39	4.2919
2583.12	3.92422
2585.85	4.11534
2588.59	3.62452
2591.32	3.83927
2594.05	3.2602
2596.78	2.00967
2599.51	0.785778
2602.24	1.91582
2604.97	2.16796
2607.69	2.51978
2610.42	2.13892
2613.14	0.787761
2615.87	-0.556705
2618.59	0.160954
2621.31	0.734645
2624.03	0.708854
2626.75	0.936128
2629.47	1.33865
2632.19	1.64904
2634.91	1.52893
2637.62	1.97058
2640.34	2.6337
2643.05	2.20869
2645.76	2.07925
2648.48	2.24332
2651.19	2.49939
2653.9	2.52285
2656.6	2.24567
2659.31	2.20075
2662.02	2.06999
2664.73	2.57601
2667.43	3.60364
2670.14	2.95691
2672.84	2.59739
2675.54	2.49832
2678.24	1.71489
2680.94	3.27833
2683.64	4.15583
2686.34	4.66675
2689.04	6.02877
2691.74	6.26867
2694.43	6.60048
2697.13	6.82906
2699.82	7.59736
2702.51	8.11476
2705.21	7.95788
2707.9	8.59779
2710.58	8.94785
2713.27	9.8953
2715.96	10.0666
2718.65	9.54042
2721.33	9.59047
2724.02	9.86048
2726.71	10.3591
2729.39	10.8822
2732.07	10.622
2734.75	9.70275
2737.43	8.6112
2740.11	8.4957
2742.79	7.58845
2745.47	6.72494
2748.14	6.33476
2750.82	4.83119
2753.49	4.3329
2756.17	3.50176
2758.84	2.49575
2761.51	1.23554
2764.18	1.07191
2766.85	0.0385426
2769.52	0.609259
2772.19	0.771337
2774.86	0.547092
2777.52	0.507277
2780.19	0.412275
2782.85	-0.421906
2785.52	0.199867
2788.18	1.1652
2790.84	1.78075
2793.5	1.91283
2796.16	2.06952
2798.82	1.69419
2801.48	1.35333
2804.13	2.24372
2806.79	1.8964
2809.45	2.13878
2812.1	3.27676
2814.75	4.14879
2817.41	4.83353
2820.06	6.2405
2822.71	8.22471
2825.36	10.4034
2828	13.5803
2830.65	17.8206
2833.3	21.2939
2835.94	24.4388
2838.59	28.4144
2841.23	31.8275
2843.87	36.0794
2846.52	41.5362
2849.16	46.2741
2851.8	51.5587
2854.44	57.3791
2857.08	62.9847
2859.71	67.8408
2862.35	72.6709
2864.98	77.3959
2867.62	82.3441
2870.25	85.6995
2872.88	90.1571
2875.52	93.7986
2878.15	97.4033
2880.78	99.7943
2883.41	103.511
2886.03	107.189
2888.66	109.884
2891.29	113.075
2893.91	116.903
2896.54	120.496
2899.16	123.083
2901.78	127.173
2904.4	131.715
2907.02	137.075
2909.64	143.337
2912.26	151.505
2914.88	158.084
2917.5	163.984
2920.11	168.98
2922.73	173.947
2925.34	176.58
2927.96	179.415
2930.57	181.207
2933.18	180.982
2935.79	181.653
2938.4	180.105
2941.01	177.26
2943.62	172.65
2946.22	168.904
2948.83	163.368
2951.43	157.574
2954.04	151.51
2956.64	144.955
2959.24	138.45
2961.84	130.988
2964.45	124.231
2967.05	117.282
2969.64	111.18
2972.24	105.598
2974.84	99.9923
2977.43	94.4998
2980.03	87.6491
2982.62	80.6344
2985.22	74.8862
2987.81	68.8247
2990.4	61.2473
2992.99	54.9
2995.58	48.1931
2998.17	42.8531
3000.76	37.8327
3003.34	31.5693
3005.93	26.0614
3008.52	22.762
3011.1	19.2799
3013.68	15.5054
3016.27	11.8636
3018.85	8.79166
3021.43	6.47118
3024.01	4.55262
3026.59	2.61737
3029.16	1.72286
3031.74	1.14281
3034.32	2.1719
3036.89	3.10706
3039.47	3.87376
3042.04	4.5182
3044.61	5.19241
3047.18	5.87742
3049.75	6.25719
3052.32	6.22867
3054.89	7.04839
3057.46	7.76916
3060.03	8.62216
3062.59	8.81243
3065.16	8.50262
3067.72	8.43113
3070.29	7.94271
3072.85	6.67906
3075.41	5.73314
3077.97	4.45841
3080.53	3.88431
3083.09	3.38936
3085.65	2.9404
3088.21	1.51303
3090.76	1.49857
3093.32	0.957315
3095.87	1.33942
3098.43	0.796981
3100.98	-0.0118424
3103.53	-0.37565
3106.08	0.540125
3108.63	0.867183
3111.18	1.35047
3113.73	2.07818
3116.28	2.53608
3118.83	2.48145
3121.37	2.85504
3123.92	2.94776
3126.46	3.55329
3129	4.15581
3131.55	4.20238
3134.09	3.94496
3136.63	4.98281
3139.17	6.29672
3141.71	6.46295
3144.24	7.14958
3146.78	7.2028
3149.32	9.16645