File: data/Raman/poly_smoothed/Thy_50_12_13_1x_45s_532 nm_x100_100%_600 gr_mm_01.txt
#Acq. time (s)=	45
#Accumulations=	2
#Range (cm-¹)=	200...3150
#Windows=	2
#Auto scanning=	Off
#Autofocus=	Off
#Macrospot=	Off
#AutoExposure=	Off
#Spike filter=	Multiple accum.
#Delay time (s)=	0
#Binning=	1
#Readout mode=	Signal
#DeNoise=	Off
#ICS correction=	On
#Dark correction=	Off
#Inst. Process=	Off
#Detector Gain=	Best Dynamic Range
#Detector ADC=	20 kHz
#Detector temperature (°C)=	-69.85
#Instrument=	LabRAM HR Evol
#Detector=	Synapse
#Objective=	x100
#Grating=	600 gr/mm
#ND Filter=	100%
#Laser (nm)=	532
#Hole=	100.021
#Range=	Auto
#Laser Pol.=	No
#Raman. Pol.=	No
#Laser Pol. (°)=	-0.0007625
#Raman Pol. (°)=	89.9995
#Collection=	Microscope
#StageXY=	Marzhauser
#StageZ=	Marzhauser
#X (µm)=	-5110.8
#Y (µm)=	1481.1
#Z (µm)=	62.85
#Full time(mm:ss)=	3:13
#Project=
#Sample=
#Site=
#Title=	Thy_50_12_13_2x_45s_532 nm_x100_100%_600 gr_mm
#Remark=
#Date=	07.07.2022 10:10
#Acquired=	07.07.2022 10:10:58
#Base:Fit=	10.08.2022 10:04:29
#Base:Sub=	10.08.2022 10:04:45
#Filter:Polynom=	16.08.2022 10:20:24
#AxisType[0]=Intens
#AxisUnit[0]=Cnt
#AxisType[1]=Spectr
#AxisUnit[1]=1/cm
200.43	29.6251
204.061	27.1933
207.688	22.6713
211.316	18.1909
214.941	14.0883
218.566	11.6321
222.188	10.5905
225.809	9.58313
229.43	9.35415
233.047	6.99691
236.663	7.67722
240.278	6.51321
243.894	4.46929
247.506	3.7173
251.116	3.09074
254.725	2.6807
258.333	3.92807
261.939	3.17432
265.546	3.4465
269.15	4.41066
272.752	4.51594
276.353	5.56911
279.952	5.28441
283.55	4.30024
287.146	6.95401
290.739	8.09453
294.333	8.78352
297.925	11.5518
301.516	12.1611
305.106	13.6698
308.694	14.7129
312.279	15.8453
315.864	16.1661
319.448	14.9454
323.029	15.5025
326.61	14.4822
330.19	13.6612
333.766	13.7042
337.343	13.7806
340.917	13.4729
344.491	13.7665
348.062	13.694
351.633	12.4749
355.201	12.005
358.77	11.2828
362.335	10.0982
365.899	8.28732
369.464	8.46859
373.025	8.80022
376.585	9.73695
380.143	8.50323
383.702	7.84312
387.258	7.83346
390.812	5.8547
394.365	5.64098
397.916	5.03204
401.467	5.52065
405.015	3.81219
408.565	3.36541
412.111	3.57627
415.656	4.87274
419.197	5.6201
422.739	7.3721
426.279	7.49243
429.819	7.18809
433.356	6.8494
436.893	6.72141
440.428	6.64799
443.96	7.25738
447.492	7.05729
451.023	8.87604
454.553	9.82385
458.079	11.5633
461.606	12.4095
465.132	13.6592
468.654	14.9424
472.177	17.8258
475.696	19.5359
479.217	21.1543
482.733	21.3722
486.251	22.0338
489.765	23.4529
493.278	25.2463
496.791	27.4284
500.301	28.241
503.81	27.6441
507.319	26.2577
510.825	22.5896
514.33	21.3713
517.833	21.9065
521.337	23.1309
524.838	23.0517
528.337	22.5476
531.835	20.9964
535.332	18.569
538.827	17.6736
542.321	17.6431
545.814	17.3208
549.305	17.1382
552.795	16.5459
556.284	16.2716
559.771	17.1748
563.257	17.1723
566.742	16.8003
570.223	16.2922
573.705	16.9191
577.185	15.9865
580.665	14.2152
584.141	12.282
587.617	10.1531
591.092	7.65201
594.564	7.02036
598.037	7.23134
601.506	8.64767
604.976	8.53964
608.443	8.65258
611.91	7.24004
615.374	5.59968
618.839	4.81369
622.3	3.86653
625.761	5.58174
629.221	6.90392
632.679	7.12186
636.135	7.82658
639.592	10.4675
643.045	13.2771
646.497	15.1378
649.948	15.7579
653.398	15.8025
656.846	16.1976
660.293	16.7473
663.738	16.0084
667.185	16.5708
670.628	16.7699
674.067	16.4007
677.508	17.3986
680.947	19.0334
684.385	20.0978
687.821	19.7013
691.256	20.8323
694.69	22.103
698.121	20.5761
701.552	21.3407
704.982	21.995
708.41	23.7747
711.836	26.7215
715.262	29.6824
718.685	31.7687
722.108	36.7909
725.53	38.9052
728.949	40.4048
732.369	41.7444
735.785	43.4366
739.2	45.5982
742.616	46.9641
746.028	49.3652
749.441	52.3203
752.851	55.4788
756.26	58.2748
759.667	61.0392
763.075	63.7372
766.479	65.2839
769.883	68.1393
773.285	70.8246
776.686	73.3041
780.085	73.2553
783.484	75.7209
786.881	77.6499
790.276	78.8987
793.671	79.4844
797.064	82.4042
800.456	81.2109
803.846	81.7631
807.236	80.3668
810.624	77.3899
814.01	75.881
817.394	74.8084
820.778	73.9526
824.161	72.841
827.543	69.0355
830.921	67.3542
834.3	65.5174
837.676	65.0952
841.053	63.9839
844.426	61.9507
847.8	60.534
851.171	61.1641
854.542	60.2485
857.911	59.0297
861.279	58.2721
864.645	58.6923
868.01	58.2867
871.375	56.0665
874.737	55.7081
878.097	53.6865
881.457	53.252
884.817	51.5017
888.174	48.2636
891.53	48.5014
894.884	47.1023
898.237	46.3126
901.589	45.4391
904.94	43.4103
908.289	42.9993
911.637	41.8021
914.984	41.875
918.33	41.2228
921.674	41.2319
925.015	40.9752
928.357	40.4125
931.698	39.269
935.037	38.5122
938.373	36.4925
941.71	36.9895
945.046	36.2589
948.378	36.7428
951.711	35.8655
955.043	36.26
958.372	36.7632
961.701	36.5782
965.027	37.7091
968.354	38.3127
971.678	38.426
975	38.6765
978.324	39.333
981.644	39.775
984.962	40.1973
988.282	39.9011
991.598	38.9212
994.913	38.1836
998.227	36.9097
1001.54	36.828
1004.85	36.4351
1008.16	36.1847
1011.47	34.3339
1014.78	33.9286
1018.08	33.8961
1021.39	34.5896
1024.69	35.5098
1028	37.2188
1031.3	38.9986
1034.6	39.7641
1037.9	38.4915
1041.19	38.9496
1044.49	40.6925
1047.79	41.4035
1051.08	40.0073
1054.37	38.4286
1057.66	37.8146
1060.95	37.1362
1064.24	34.7791
1067.53	33.3815
1070.81	32.4419
1074.1	34.1475
1077.38	32.8502
1080.66	31.2203
1083.94	30.4249
1087.22	29.6454
1090.5	29.9229
1093.78	28.8621
1097.05	29.7201
1100.33	28.6636
1103.6	29.2155
1106.87	30.3356
1110.15	29.6698
1113.41	29.0141
1116.68	28.8757
1119.95	28.5334
1123.21	27.5179
1126.48	25.5197
1129.74	22.8762
1133	20.1766
1136.26	19.4122
1139.52	16.5757
1142.78	15.8685
1146.04	14.7004
1149.29	14.6582
1152.55	13.5139
1155.8	11.8123
1159.05	10.7401
1162.3	10.0083
1165.55	9.8627
1168.8	10.659
1172.05	11.551
1175.29	13.1073
1178.54	14.0519
1181.78	15.1636
1185.02	16.3829
1188.26	17.4205
1191.5	18.9755
1194.74	20.0761
1197.97	20.6173
1201.21	21.2171
1204.44	23.0143
1207.68	25.8042
1210.91	28.7149
1214.14	31.8105
1217.37	34.8553
1220.6	39.1004
1223.82	42.8291
1227.05	45.8267
1230.27	48.7515
1233.49	52.2712
1236.72	53.9371
1239.94	55.8894
1243.16	59.7834
1246.37	62.6017
1249.59	66.0136
1252.8	67.7376
1256.02	69.0246
1259.23	70.448
1262.44	70.9201
1265.66	71.0157
1268.87	73.3916
1272.07	74.644
1275.28	76.491
1278.48	78.9145
1281.69	81.39
1284.89	82.9438
1288.09	85.0475
1291.3	87.0589
1294.49	89.1549
1297.69	90.8451
1300.89	92.455
1304.09	95.1005
1307.28	95.7697
1310.47	95.3657
1313.66	94.491
1316.86	94.1684
1320.05	95.1439
1323.23	95.5754
1326.42	93.0626
1329.61	90.2629
1332.79	88.4739
1335.98	86.8962
1339.16	84.496
1342.34	81.5796
1345.52	78.9682
1348.7	77.3472
1351.87	75.3364
1355.05	74.5853
1358.23	71.8409
1361.4	68.0431
1364.57	66.4548
1367.74	64.0084
1370.91	62.1155
1374.08	61.0747
1377.25	59.9622
1380.42	58.8844
1383.58	57.4811
1386.75	54.9319
1389.91	54.193
1393.07	53.0169
1396.23	52.6652
1399.39	52.0263
1402.55	50.7891
1405.7	51.8167
1408.86	54.7526
1412.01	59.2099
1415.17	62.2248
1418.32	67.813
1421.47	72.6285
1424.62	79.4055
1427.77	86.0094
1430.92	92.2939
1434.06	95.8308
1437.2	99.3414
1440.35	104.222
1443.49	107.829
1446.63	109.897
1449.77	111.211
1452.91	111.315
1456.05	108.946
1459.18	106.88
1462.32	103.291
1465.45	97.7841
1468.59	90.8885
1471.72	83.6155
1474.85	76.8469
1477.98	69.6444
1481.11	63.3783
1484.23	56.4454
1487.36	52.1199
1490.48	47.5389
1493.61	44.2654
1496.73	40.5516
1499.85	37.8874
1502.97	37.2803
1506.09	35.2141
1509.2	33.8106
1512.32	34.876
1515.44	37.0017
1518.55	39.4725
1521.66	40.5005
1524.77	42.2908
1527.88	44.467
1530.99	45.8468
1534.1	46.6037
1537.21	48.665
1540.31	52.1724
1543.42	53.0627
1546.52	56.7035
1549.62	60.6639
1552.72	64.9731
1555.82	68.3883
1558.92	71.4159
1562.02	73.7419
1565.11	77.5595
1568.21	79.7103
1571.3	81.77
1574.39	82.8563
1577.49	86.1572
1580.58	87.4503
1583.67	89.1529
1586.75	90.8512
1589.84	91.001
1592.93	90.4817
1596.01	88.7155
1599.09	86.6616
1602.18	84.0276
1605.26	81.0355
1608.34	79.797
1611.41	78.7744
1614.49	79.9001
1617.57	79.2837
1620.64	79.7737
1623.72	81.8806
1626.79	83.0344
1629.86	84.621
1632.93	87.0261
1636	87.7707
1639.07	88.7739
1642.14	89.7013
1645.2	92.6024
1648.27	93.9257
1651.33	95.2193
1654.39	96.5243
1657.45	96.7662
1660.51	97.246
1663.57	93.6092
1666.63	90.6427
1669.69	86.0104
1672.74	82.9871
1675.79	77.6807
1678.85	73.5919
1681.9	68.9849
1684.95	64.2795
1688	57.9932
1691.05	51.687
1694.1	46.8537
1697.14	41.4055
1700.19	37.8465
1703.23	33.3101
1706.27	29.7927
1709.32	25.8105
1712.35	21.8315
1715.39	18.4361
1718.43	17.0935
1721.47	15.3222
1724.5	14.2924
1727.54	14.0566
1730.57	14.7031
1733.61	14.4116
1736.64	13.3762
1739.67	13.0443
1742.7	13.0611
1745.72	12.9656
1748.75	14.8284
1751.78	13.5776
1754.8	13.9522
1757.82	14.2206
1760.85	12.9129
1763.87	12.3808
1766.89	11.5566
1769.91	11.3271
1772.92	10.4879
1775.94	9.71539
1778.96	7.34942
1781.97	6.48223
1784.98	5.32211
1788	4.16137
1791.01	3.86917
1794.01	3.88108
1797.02	3.85457
1800.03	4.09189
1803.04	4.09391
1806.04	3.79096
1809.05	3.29591
1812.05	3.12875
1815.05	4.05608
1818.05	4.7989
1821.05	4.36632
1824.05	4.46181
1827.05	4.96962
1830.04	5.0515
1833.04	5.00521
1836.03	4.69291
1839.03	4.86261
1842.02	5.316
1845.01	5.95584
1848	5.3779
1850.99	5.80599
1853.97	5.59081
1856.96	5.31114
1859.94	4.36488
1862.93	5.26145
1865.91	4.41579
1868.89	4.57305
1871.87	3.80155
1874.85	3.05583
1877.83	1.98221
1880.81	1.91971
1882.56	1.4365
1885.55	1.29724
1888.54	1.50036
1891.52	0.522822
1894.51	0.65882
1897.49	1.30572
1900.48	1.0377
1903.46	0.93323
1906.44	1.70582
1909.42	2.92463
1912.4	4.35662
1915.38	4.58709
1918.35	4.98098
1921.33	5.13981
1924.3	5.60135
1927.28	4.26704
1930.25	4.87465
1933.22	4.34779
1936.19	4.72597
1939.16	2.30543
1942.13	1.4681
1945.09	1.11753
1948.06	-0.241595
1951.03	-1.64996
1953.99	-2.82398
1956.95	-2.44619
1959.91	-2.00412
1962.87	-1.27626
1965.83	-0.732458
1968.79	-0.0485491
1971.75	0.896162
1974.7	2.41455
1977.66	3.03182
1980.61	3.7153
1983.56	5.89966
1986.52	5.01672
1989.47	6.47077
1992.41	7.7826
1995.36	7.94522
1998.31	8.27271
2001.26	7.58938
2004.2	7.7292
2007.15	5.76689
2010.09	5.53687
2013.03	5.4854
2015.97	6.13489
2018.91	5.59989
2021.85	4.66824
2024.79	5.54456
2027.72	5.68594
2030.66	7.56965
2033.59	8.21633
2036.53	8.63054
2039.46	9.30534
2042.39	10.0171
2045.32	11.2938
2048.25	12.2027
2051.18	14.1652
2054.1	14.7334
2057.03	15.27
2059.95	16.9515
2062.88	20.0704
2065.8	21.3499
2068.72	22.3063
2071.64	23.4825
2074.56	25.0907
2077.48	25.7172
2080.39	27.7383
2083.31	29.7202
2086.22	30.7395
2089.14	31.0759
2092.05	32.0745
2094.96	34.1115
2097.87	35.5198
2100.78	37.6021
2103.69	39.4385
2106.6	40.8324
2109.51	43.2096
2112.41	45.3275
2115.32	48.4581
2118.22	50.3109
2121.12	54.3991
2124.02	57.2049
2126.92	61.7141
2129.82	67.1667
2132.72	72.1625
2135.62	76.1845
2138.51	81.1638
2141.41	84.2621
2144.3	89.3575
2147.19	93.2086
2150.09	96.4367
2152.97	99.8631
2155.86	102.573
2158.75	105.715
2161.64	108.966
2164.53	110.725
2167.41	113.921
2170.3	114.929
2173.18	115.131
2176.06	114.402
2178.94	112.3
2181.82	110.748
2184.7	109.285
2187.58	106.065
2190.46	104.342
2193.33	102.165
2196.21	99.3322
2199.08	97.7815
2201.95	93.2407
2204.83	90.7831
2207.7	88.0086
2210.57	84.4397
2213.43	81.6278
2216.3	78.8911
2219.17	75.3266
2222.03	73.0673
2224.9	71.2537
2227.76	69.5403
2230.62	68.1201
2233.49	66.4306
2236.34	63.9499
2239.2	62.2018
2242.06	61.2276
2244.92	59.991
2247.78	58.3918
2250.63	57.1804
2253.48	56.0044
2256.34	54.5613
2259.19	53.3392
2262.04	52.8644
2264.89	51.4411
2267.74	50.4064
2270.59	49.6214
2273.43	48.9633
2276.28	47.2037
2279.12	46.3877
2281.97	45.1504
2284.81	43.5126
2287.65	41.1676
2290.49	39.15
2293.33	36.9572
2296.17	35.059
2299.01	34.4685
2301.84	33.9829
2304.68	33.6487
2307.51	32.9576
2310.35	32.9911
2313.18	33.0909
2316.01	32.0554
2318.84	31.5326
2321.67	30.0289
2324.5	30.0947
2327.33	30.0635
2330.15	29.9422
2332.98	29.8436
2335.8	29.1248
2338.62	28.4482
2341.45	27.1007
2344.27	27.1547
2347.09	26.1371
2349.91	25.092
2352.72	23.9147
2355.54	23.0439
2358.36	22.1162
2361.17	20.9696
2363.98	21.3421
2366.8	21.7522
2369.61	21.2875
2372.42	19.5102
2375.23	18.6108
2378.04	19.0026
2380.85	18.0422
2383.66	18.3714
2386.46	16.6916
2389.26	15.7015
2392.07	14.845
2394.87	15.0377
2397.67	14.8548
2400.47	14.6191
2403.27	13.5569
2406.07	10.9993
2408.87	10.4527
2411.67	11.0396
2414.46	11.9562
2417.26	12.5753
2420.05	12.4391
2422.84	12.0657
2425.64	11.5917
2428.43	11.7868
2431.22	11.864
2434.01	11.9162
2436.79	12.2706
2439.58	12.6382
2442.37	12.5667
2445.15	12.7581
2447.93	11.652
2450.72	10.8855
2453.5	9.87624
2456.28	8.33774
2459.06	8.20827
2461.84	8.63569
2464.62	8.88736
2467.39	7.85391
2470.17	7.30215
2472.94	6.78731
2475.72	7.47393
2478.49	9.38163
2481.26	9.998
2484.03	9.31895
2486.8	7.88763
2489.57	7.32715
2492.34	6.50559
2495.1	6.27703
2497.87	6.541
2500.63	6.9861
2503.4	7.05433
2506.16	5.98997
2508.92	4.96738
2511.68	4.52058
2514.44	4.63969
2517.2	3.46776
2519.96	2.92658
2522.72	3.00613
2525.47	2.66133
2528.23	2.77588
2530.98	2.79606
2533.74	2.19447
2536.49	2.02917
2539.24	3.52111
2541.99	3.96913
2544.74	4.21701
2547.49	4.43894
2550.23	4.42236
2552.98	4.30558
2555.72	4.49733
2558.47	3.68506
2561.21	3.41095
2563.95	4.56481
2566.69	6.09177
2569.43	6.37185
2572.17	5.61363
2574.91	4.5265
2577.65	3.96047
2580.39	3.73737
2583.12	2.39159
2585.85	2.66147
2588.59	1.75089
2591.32	1.79137
2594.05	0.360748
2596.78	0.0648658
2599.51	-0.206486
2602.24	-0.1868
2604.97	-0.112566
2607.69	-0.514788
2610.42	-0.45253
2613.14	-0.866739
2615.87	-0.359337
2618.59	-0.0690038
2621.31	-0.344471
2624.03	-0.590308
2626.75	0.228061
2629.47	1.76639
2632.19	3.1043
2634.91	2.91957
2637.62	2.58244
2640.34	2.4977
2643.05	3.15543
2645.76	3.25578
2648.48	4.14264
2651.19	4.40151
2653.9	5.54247
2656.6	6.52461
2659.31	7.78786
2662.02	8.2162
2664.73	8.51146
2667.43	8.38208
2670.14	7.85208
2672.84	8.02385
2675.54	8.40173
2678.24	7.06481
2680.94	7.20925
2683.64	6.93431
2686.34	7.04143
2689.04	7.14463
2691.74	8.0375
2694.43	8.72017
2697.13	9.11947
2699.82	9.27621
2702.51	10.1318
2705.21	11.6418
2707.9	11.4878
2710.58	11.7267
2713.27	11.0227
2715.96	10.9894
2718.65	11.9891
2721.33	12.4647
2724.02	13.0168
2726.71	12.4285
2729.39	11.7759
2732.07	10.732
2734.75	10.2714
2737.43	9.51162
2740.11	9.20726
2742.79	9.00158
2745.47	9.02675
2748.14	8.41692
2750.82	7.92061
2753.49	7.49691
2756.17	7.08764
2758.84	6.89035
2761.51	7.02362
2764.18	5.66909
2766.85	5.78866
2769.52	6.06128
2772.19	4.60727
2774.86	3.62594
2777.52	3.21948
2780.19	2.68649
2782.85	3.05511
2785.52	2.76098
2788.18	1.60238
2790.84	1.07575
2793.5	0.211438
2796.16	-0.290577
2798.82	-0.338945
2801.48	-0.334906
2804.13	-0.488974
2806.79	-0.139757
2809.45	-0.523408
2812.1	-0.974022
2814.75	-1.25795
2817.41	-0.066408
2820.06	1.23181
2822.71	3.00168
2825.36	7.19855
2828	11.3026
2830.65	14.2326
2833.3	19.0708
2835.94	23.7053
2838.59	28.8801
2841.23	34.9609
2843.87	41.4072
2846.52	48.4506
2849.16	56.2946
2851.8	64.4098
2854.44	72.486
2857.08	81.306
2859.71	90.0162
2862.35	96.3078
2864.98	102.005
2867.62	108.065
2870.25	113.798
2872.88	118.632
2875.52	122.743
2878.15	126.835
2880.78	130.636
2883.41	134.764
2886.03	138.209
2888.66	142.279
2891.29	146.372
2893.91	150.213
2896.54	154.455
2899.16	159.649
2901.78	165.417
2904.4	171.289
2907.02	178.681
2909.64	187.296
2912.26	196.231
2914.88	205.745
2917.5	214.754
2920.11	222.563
2922.73	228.353
2925.34	232.947
2927.96	235.015
2930.57	237.57
2933.18	239.344
2935.79	238.862
2938.4	236.031
2941.01	233.172
2943.62	228.368
2946.22	221.189
2948.83	214.883
2951.43	206.647
2954.04	199.106
2956.64	190.296
2959.24	180.851
2961.84	173.354
2964.45	164.477
2967.05	155.479
2969.64	147.384
2972.24	139.294
2974.84	130.643
2977.43	122.342
2980.03	114.264
2982.62	105.811
2985.22	96.6668
2987.81	87.7969
2990.4	78.9264
2992.99	71.2448
2995.58	63.8792
2998.17	55.9317
3000.76	47.9394
3003.34	40.394
3005.93	34.1709
3008.52	28.7958
3011.1	23.4619
3013.68	18.951
3016.27	15.9355
3018.85	13.8835
3021.43	10.6942
3024.01	9.66827
3026.59	8.80337
3029.16	7.86343
3031.74	7.75523
3034.32	7.71427
3036.89	7.67108
3039.47	8.72263
3042.04	10.0386
3044.61	10.7309
3047.18	12.2855
3049.75	13.0048
3052.32	14.9982
3054.89	15.5806
3057.46	15.5326
3060.03	15.3427
3062.59	13.6282
3065.16	12.1976
3067.72	11.1329
3070.29	10.4401
3072.85	9.96065
3075.41	8.62769
3077.97	7.52692
3080.53	6.23527
3083.09	5.23807
3085.65	4.20631
3088.21	3.63016
3090.76	2.87668
3093.32	3.08984
3095.87	4.77327
3098.43	5.20828
3100.98	5.6972
3103.53	6.95969
3106.08	7.56565
3108.63	9.45769
3111.18	10.7948
3113.73	12.6744
3116.28	14.8093
3118.83	16.435
3121.37	17.6709
3123.92	19.2605
3126.46	20.3069
3129	21.1063
3131.55	23.2078
3134.09	25.9817
3136.63	27.6084
3139.17	28.6964
3141.71	30.0836
3144.24	32.2787
3146.78	34.1673
3149.32	36.8848