File: data/Raman/poly_smoothed/Thy_50_12_29_1x_45s_532 nm_x100_100%_600 gr_mm_01.txt
#Acq. time (s)=	45
#Accumulations=	2
#Range (cm-¹)=	200...3150
#Windows=	2
#Auto scanning=	Off
#Autofocus=	Off
#Macrospot=	Off
#AutoExposure=	Off
#Spike filter=	Multiple accum.
#Delay time (s)=	0
#Binning=	1
#Readout mode=	Signal
#DeNoise=	Off
#ICS correction=	On
#Dark correction=	Off
#Inst. Process=	Off
#Detector Gain=	Best Dynamic Range
#Detector ADC=	20 kHz
#Detector temperature (°C)=	-69.85
#Instrument=	LabRAM HR Evol
#Detector=	Synapse
#Objective=	x100
#Grating=	600 gr/mm
#ND Filter=	100%
#Laser (nm)=	532
#Hole=	100.021
#Range=	Auto
#Laser Pol.=	No
#Raman. Pol.=	No
#Laser Pol. (°)=	-0.0007625
#Raman Pol. (°)=	89.9995
#Collection=	Microscope
#StageXY=	Marzhauser
#StageZ=	Marzhauser
#X (µm)=	-5137.9
#Y (µm)=	1504.7
#Z (µm)=	63.25
#Full time(mm:ss)=	3:19
#Project=
#Sample=
#Site=
#Title=	Thy_50_12_29_2x_45s_532 nm_x100_100%_600 gr_mm
#Remark=
#Date=	07.07.2022 11:22
#Acquired=	07.07.2022 11:22:04
#Base:Fit=	10.08.2022 10:04:29
#Base:Sub=	10.08.2022 10:04:45
#Filter:Polynom=	16.08.2022 10:20:25
#AxisType[0]=Intens
#AxisUnit[0]=Cnt
#AxisType[1]=Spectr
#AxisUnit[1]=1/cm
200.43	6.08852
204.061	6.37849
207.688	5.27443
211.316	5.03232
214.941	4.97248
218.566	6.3136
222.188	6.31715
225.809	5.89944
229.43	7.99332
233.047	9.11784
236.663	9.33681
240.278	9.69824
243.894	9.70238
247.506	10.4195
251.116	10.4031
254.725	8.94849
258.333	10.5579
261.939	10.8369
265.546	11.218
269.15	11.9611
272.752	13.4236
276.353	14.5735
279.952	14.1326
283.55	15.4142
287.146	15.2301
290.739	14.6471
294.333	15.5273
297.925	16.3336
301.516	15.78
305.106	14.92
308.694	14.5276
312.279	11.772
315.864	12.4221
319.448	12.8805
323.029	11.8568
326.61	11.6237
330.19	11.3842
333.766	11.6163
337.343	9.61946
340.917	9.2037
344.491	8.05002
348.062	8.02017
351.633	7.65805
355.201	8.66391
358.77	8.80127
362.335	9.94276
365.899	10.5156
369.464	10.6565
373.025	12.4486
376.585	10.791
380.143	12.0955
383.702	10.6637
387.258	8.41513
390.812	6.95977
394.365	6.07652
397.916	4.31959
401.467	3.38105
405.015	4.76272
408.565	5.19561
412.111	5.44353
415.656	5.68779
419.197	6.17189
422.739	5.99511
426.279	5.99442
429.819	6.45187
433.356	7.89189
436.893	8.33013
440.428	7.68977
443.96	8.51257
447.492	9.24596
451.023	9.7279
454.553	10.0285
458.079	10.8615
461.606	10.5664
465.132	11.193
468.654	10.9597
472.177	12.0377
475.696	12.637
479.217	13.6862
482.733	14.6448
486.251	13.758
489.765	15.3546
493.278	16.429
496.791	17.4004
500.301	18.2777
503.81	19.669
507.319	20.2626
510.825	19.7688
514.33	19.3224
517.833	19.3005
521.337	18.8086
524.838	16.1661
528.337	13.6373
531.835	12.3531
535.332	9.92411
538.827	9.30237
542.321	9.14105
545.814	7.99904
549.305	5.59701
552.795	5.71336
556.284	5.01817
559.771	4.37133
563.257	3.63758
566.742	-0.0510321
570.223	-3.25911
573.705	-3.15187
577.185	1.94642
580.665	6.56119
584.141	12.2171
587.617	16.4385
591.092	19.8089
594.564	20.5449
598.037	23.4366
601.506	25.7222
604.976	27.1344
608.443	27.9828
611.91	29.1202
615.374	29.0961
618.839	28.1744
622.3	28.8549
625.761	27.2614
629.221	24.7761
632.679	21.2984
636.135	18.1728
639.592	14.8138
643.045	12.0183
646.497	7.41274
649.948	3.21143
653.398	1.05863
656.846	3.95111
660.293	9.00924
663.738	12.1671
667.185	14.2152
670.628	15.884
674.067	16.7987
677.508	18.5074
680.947	18.8755
684.385	21.8063
687.821	25.2233
691.256	27.165
694.69	30.0088
698.121	31.5562
701.552	31.6187
704.982	32.1942
708.41	33.2129
711.836	33.2923
715.262	33.5691
718.685	33.5562
722.108	34.0026
725.53	35.1007
728.949	36.1308
732.369	37.097
735.785	38.8259
739.2	39.7709
742.616	40.4621
746.028	42.3173
749.441	45.3898
752.851	48.1344
756.26	52.0685
759.667	55.725
763.075	56.4197
766.479	58.8439
769.883	61.7195
773.285	63.9969
776.686	65.2492
780.085	66.3058
783.484	66.8052
786.881	66.0176
790.276	68.5521
793.671	70.1801
797.064	70.6973
800.456	70.1148
803.846	71.9799
807.236	73.6206
810.624	72.0749
814.01	71.6194
817.394	69.6736
820.778	68.6647
824.161	68.3809
827.543	71.0062
830.921	70.8428
834.3	69.351
837.676	68.1793
841.053	65.8496
844.426	62.5304
847.8	58.9453
851.171	58.5403
854.542	55.4725
857.911	53.7455
861.279	52.0013
864.645	51.0273
868.01	49.7604
871.375	49.0611
874.737	49.4644
878.097	48.2924
881.457	48.2903
884.817	47.1625
888.174	46.8751
891.53	44.7475
894.884	43.8473
898.237	43.4416
901.589	43.4647
904.94	43.7683
908.289	43.9317
911.637	42.5285
914.984	39.6997
918.33	35.9815
921.674	33.7056
925.015	31.3315
928.357	28.0564
931.698	25.1544
935.037	23.2883
938.373	22.1292
941.71	20.2228
945.046	16.8036
948.378	17.4539
951.711	16.7588
955.043	16.488
958.372	15.8551
961.701	15.7933
965.027	16.7986
968.354	17.6175
971.678	19.8934
975	21.898
978.324	23.0688
981.644	24.9386
984.962	26.1822
988.282	27.2476
991.598	27.8229
994.913	27.3747
998.227	26.3781
1001.54	25.7209
1004.85	26.1735
1008.16	25.6099
1011.47	24.8001
1014.78	25.1372
1018.08	25.0929
1021.39	24.6843
1024.69	24.8616
1028	26.114
1031.3	27.0347
1034.6	26.2159
1037.9	27.0462
1041.19	26.6675
1044.49	27.781
1047.79	27.1526
1051.08	25.5693
1054.37	26.1621
1057.66	23.3976
1060.95	22.135
1064.24	20.6146
1067.53	19.3343
1070.81	18.1191
1074.1	17.6817
1077.38	16.4735
1080.66	15.9817
1083.94	14.8578
1087.22	14.1617
1090.5	14.8302
1093.78	13.5708
1097.05	15.1533
1100.33	15.0417
1103.6	15.5399
1106.87	16.6616
1110.15	17.3118
1113.41	17.4585
1116.68	16.9796
1119.95	16.5836
1123.21	14.4189
1126.48	12.3226
1129.74	10.9519
1133	10.0845
1136.26	8.22672
1139.52	5.84488
1142.78	5.86603
1146.04	4.82771
1149.29	5.82875
1152.55	5.62278
1155.8	3.73307
1159.05	1.95125
1162.3	1.89953
1165.55	1.99766
1168.8	2.96957
1172.05	3.93467
1175.29	4.33343
1178.54	4.69558
1181.78	4.71691
1185.02	5.63553
1188.26	6.2554
1191.5	5.12981
1194.74	5.18363
1197.97	6.199
1201.21	6.06539
1204.44	5.34665
1207.68	7.28921
1210.91	9.93502
1214.14	13.0744
1217.37	15.12
1220.6	19.9179
1223.82	22.334
1227.05	26.0555
1230.27	28.6423
1233.49	30.9494
1236.72	33.5455
1239.94	37.449
1243.16	39.7976
1246.37	43.7347
1249.59	46.2603
1252.8	46.3334
1256.02	47.0815
1259.23	49.0442
1262.44	50.8924
1265.66	52.6984
1268.87	52.8744
1272.07	54.1087
1275.28	55.8759
1278.48	56.7938
1281.69	58.5682
1284.89	60.7797
1288.09	64.3887
1291.3	67.2142
1294.49	69.7318
1297.69	71.7365
1300.89	72.7176
1304.09	72.8793
1307.28	73.1588
1310.47	72.2785
1313.66	71.8468
1316.86	70.4678
1320.05	70.5175
1323.23	70.5868
1326.42	69.853
1329.61	67.5104
1332.79	66.7714
1335.98	66.7969
1339.16	67.7685
1342.34	65.3037
1345.52	64.1062
1348.7	61.008
1351.87	60.4601
1355.05	57.7233
1358.23	56.9247
1361.4	55.9684
1364.57	54.6601
1367.74	54.8311
1370.91	53.1235
1374.08	51.0972
1377.25	50.0621
1380.42	48.9522
1383.58	47.5962
1386.75	46.9814
1389.91	46.309
1393.07	46.2186
1396.23	46.0571
1399.39	45.0893
1402.55	43.7249
1405.7	43.3444
1408.86	45.3355
1412.01	47.5268
1415.17	47.8993
1418.32	51.1398
1421.47	54.5912
1424.62	58.8895
1427.77	62.1437
1430.92	66.304
1434.06	69.3143
1437.2	74.6428
1440.35	78.2512
1443.49	79.2726
1446.63	81.5378
1449.77	82.3495
1452.91	82.2653
1456.05	80.3471
1459.18	78.059
1462.32	75.6049
1465.45	71.5977
1468.59	64.6811
1471.72	58.0236
1474.85	52.5879
1477.98	45.8965
1481.11	41.3333
1484.23	37.8367
1487.36	34.1072
1490.48	30.6624
1493.61	29.5379
1496.73	27.8622
1499.85	26.8709
1502.97	26.2019
1506.09	26.7022
1509.2	27.1562
1512.32	27.9121
1515.44	27.8913
1518.55	29.2535
1521.66	31.1655
1524.77	33.8191
1527.88	35.087
1530.99	38.3604
1534.1	39.4324
1537.21	42.8583
1540.31	46.9587
1543.42	50.6074
1546.52	54.7182
1549.62	60.4985
1552.72	65.3137
1555.82	70.1872
1558.92	73.8897
1562.02	76.7116
1565.11	80.0266
1568.21	82.5549
1571.3	83.8327
1574.39	85.4134
1577.49	86.0711
1580.58	86.5695
1583.67	87.5218
1586.75	85.4732
1589.84	83.9565
1592.93	83.2256
1596.01	81.0592
1599.09	80.402
1602.18	78.7141
1605.26	77.0217
1608.34	76.5267
1611.41	77.6027
1614.49	79.2086
1617.57	80.3981
1620.64	81.9379
1623.72	82.7374
1626.79	86.4627
1629.86	86.8552
1632.93	87.9136
1636	88.4185
1639.07	89.2499
1642.14	89.1985
1645.2	90.6912
1648.27	90.345
1651.33	88.9628
1654.39	87.9629
1657.45	87.7551
1660.51	85.1135
1663.57	81.9296
1666.63	79.4111
1669.69	75.8818
1672.74	72.3584
1675.79	68.176
1678.85	63.2938
1681.9	57.6844
1684.95	52.5425
1688	47.0946
1691.05	41.5867
1694.1	37.4242
1697.14	32.6687
1700.19	28.0188
1703.23	24.6288
1706.27	19.4154
1709.32	17.0652
1712.35	15.3505
1715.39	13.6117
1718.43	13.0569
1721.47	11.7425
1724.5	10.0058
1727.54	9.29443
1730.57	10.0311
1733.61	10.328
1736.64	10.3955
1739.67	11.6134
1742.7	11.1601
1745.72	10.7948
1748.75	9.42365
1751.78	8.67231
1754.8	8.01486
1757.82	6.83474
1760.85	6.05924
1763.87	6.26786
1766.89	4.88028
1769.91	4.09628
1772.92	3.07213
1775.94	2.88465
1778.96	2.86418
1781.97	2.99241
1784.98	2.29568
1788	2.36579
1791.01	1.39167
1794.01	0.772104
1797.02	-0.0113185
1800.03	-0.257232
1803.04	0.206294
1806.04	1.75703
1809.05	1.81335
1812.05	2.03468
1815.05	2.25009
1818.05	2.56175
1821.05	2.5036
1824.05	3.50189
1827.05	3.06745
1830.04	3.51175
1833.04	4.10812
1836.03	4.41235
1839.03	5.25402
1842.02	5.08408
1845.01	4.84778
1848	5.42415
1850.99	4.98511
1853.97	4.09556
1856.96	2.63183
1859.94	3.21802
1862.93	2.25861
1865.91	2.34151
1868.89	1.96184
1871.87	1.86749
1874.85	2.99393
1877.83	2.81337
1880.81	2.5857
1882.56	2.26419
1885.55	1.35375
1888.54	0.975696
1891.52	0.642717
1894.51	1.93432
1897.49	0.804832
1900.48	1.38794
1903.46	1.30041
1906.44	1.39115
1909.42	0.905115
1912.4	0.640071
1915.38	1.13328
1918.35	1.26562
1921.33	0.215771
1924.3	0.681359
1927.28	0.860927
1930.25	1.50495
1933.22	1.50484
1936.19	1.9071
1939.16	2.17801
1942.13	2.57331
1945.09	3.63299
1948.06	4.13492
1951.03	2.56502
1953.99	3.18435
1956.95	3.21126
1959.91	3.32097
1962.87	3.66377
1965.83	4.22241
1968.79	4.91942
1971.75	4.41922
1974.7	4.58634
1977.66	3.96872
1980.61	4.08175
1983.56	4.44082
1986.52	5.35153
1989.47	5.38954
1992.41	5.35161
1995.36	6.12054
1998.31	6.61203
2001.26	7.60499
2004.2	6.70563
2007.15	7.88749
2010.09	7.61748
2013.03	8.19376
2015.97	7.91899
2018.91	7.53121
2021.85	6.1795
2024.79	5.84974
2027.72	7.00578
2030.66	6.37338
2033.59	6.6526
2036.53	7.52214
2039.46	7.79708
2042.39	7.75757
2045.32	7.60046
2048.25	7.80155
2051.18	8.00586
2054.1	9.09431
2057.03	9.8058
2059.95	11.4046
2062.88	12.6773
2065.8	14.1612
2068.72	15.8718
2071.64	17.6321
2074.56	19.2783
2077.48	21.155
2080.39	22.8224
2083.31	23.4939
2086.22	27.0346
2089.14	28.9013
2092.05	31.1864
2094.96	32.7026
2097.87	35.137
2100.78	38.5897
2103.69	40.6408
2106.6	43.9729
2109.51	46.5924
2112.41	49.6693
2115.32	52.3082
2118.22	56.2964
2121.12	59.1416
2124.02	62.2975
2126.92	65.9749
2129.82	69.0618
2132.72	73.1996
2135.62	77.541
2138.51	79.9279
2141.41	83.8825
2144.3	88.617
2147.19	92.3972
2150.09	94.4511
2152.97	97.2089
2155.86	100.721
2158.75	103.144
2161.64	104.059
2164.53	105.145
2167.41	105.5
2170.3	105.108
2173.18	104.312
2176.06	102.534
2178.94	101.481
2181.82	99.1076
2184.7	97.6401
2187.58	94.8538
2190.46	91.3177
2193.33	87.8467
2196.21	85.1528
2199.08	81.5078
2201.95	77.7772
2204.83	74.9746
2207.7	71.9484
2210.57	69.0156
2213.43	66.3134
2216.3	62.7918
2219.17	59.028
2222.03	56.6506
2224.9	55.0544
2227.76	52.6278
2230.62	49.3236
2233.49	47.0636
2236.34	44.2206
2239.2	41.2361
2242.06	38.8405
2244.92	36.8034
2247.78	34.7273
2250.63	33.2176
2253.48	30.9364
2256.34	29.32
2259.19	27.6131
2262.04	25.4841
2264.89	24.4431
2267.74	22.3128
2270.59	21.1753
2273.43	20.8884
2276.28	19.9894
2279.12	19.738
2281.97	18.1163
2284.81	16.6442
2287.65	16.2116
2290.49	15.6409
2293.33	15.2448
2296.17	15.0371
2299.01	14.4086
2301.84	14.242
2304.68	15.4701
2307.51	15.2199
2310.35	15.2648
2313.18	15.0258
2316.01	14.1762
2318.84	13.7687
2321.67	12.4878
2324.5	11.84
2327.33	10.6989
2330.15	9.44772
2332.98	8.49881
2335.8	7.23149
2338.62	6.07017
2341.45	5.79751
2344.27	4.4601
2347.09	3.06547
2349.91	1.38418
2352.72	0.411648
2355.54	-0.538494
2358.36	-1.11454
2361.17	-1.40986
2363.98	-0.85843
2366.8	1.1965
2369.61	0.971267
2372.42	2.65471
2375.23	2.92118
2378.04	3.42267
2380.85	5.02192
2383.66	6.04668
2386.46	5.86065
2389.26	7.14263
2392.07	8.19699
2394.87	8.22299
2397.67	8.03968
2400.47	8.54822
2403.27	8.37043
2406.07	8.00462
2408.87	7.41253
2411.67	8.11314
2414.46	8.43465
2417.26	9.11151
2420.05	9.08988
2422.84	10.0126
2425.64	10.0181
2428.43	8.89125
2431.22	8.41561
2434.01	8.31138
2436.79	8.8446
2439.58	7.44454
2442.37	8.60765
2445.15	8.61498
2447.93	8.54533
2450.72	8.40633
2453.5	7.07337
2456.28	6.6295
2459.06	6.06068
2461.84	4.07068
2464.62	3.69057
2467.39	3.24973
2470.17	3.43313
2472.94	2.82604
2475.72	3.38408
2478.49	3.55465
2481.26	3.94114
2484.03	3.73256
2486.8	3.83829
2489.57	2.28533
2492.34	2.29591
2495.1	1.96702
2497.87	2.25331
2500.63	2.97247
2503.4	3.53803
2506.16	4.81242
2508.92	5.2543
2511.68	6.526
2514.44	5.69475
2517.2	5.76068
2519.96	5.77898
2522.72	5.78997
2525.47	5.96882
2528.23	5.41986
2530.98	5.47596
2533.74	6.2129
2536.49	5.77445
2539.24	5.55258
2541.99	4.83158
2544.74	4.56376
2547.49	3.82661
2550.23	3.43958
2552.98	2.81725
2555.72	3.64998
2558.47	3.31811
2561.21	4.33452
2563.95	4.77022
2566.69	4.60238
2569.43	4.225
2572.17	4.31978
2574.91	4.53154
2577.65	4.53142
2580.39	3.86619
2583.12	3.55572
2585.85	3.50052
2588.59	3.48414
2591.32	3.62141
2594.05	3.30577
2596.78	2.48314
2599.51	1.92471
2602.24	1.57619
2604.97	1.41668
2607.69	1.02666
2610.42	0.663546
2613.14	0.775548
2615.87	0.85339
2618.59	1.67411
2621.31	2.96581
2624.03	3.0077
2626.75	2.91104
2629.47	2.64147
2632.19	2.4825
2634.91	2.33696
2637.62	2.54499
2640.34	2.19513
2643.05	2.88863
2645.76	2.30125
2648.48	2.22242
2651.19	3.21548
2653.9	3.18221
2656.6	3.88383
2659.31	4.73697
2662.02	4.83318
2664.73	5.44864
2667.43	6.67405
2670.14	7.22102
2672.84	7.03767
2675.54	7.14596
2678.24	7.82943
2680.94	7.55648
2683.64	9.11066
2686.34	9.53436
2689.04	9.30604
2691.74	9.63293
2694.43	8.80618
2697.13	9.06952
2699.82	9.79873
2702.51	10.0975
2705.21	10.1666
2707.9	11.2851
2710.58	12.0281
2713.27	11.1053
2715.96	11.1151
2718.65	10.3725
2721.33	10.0804
2724.02	11.0364
2726.71	11.3248
2729.39	10.8185
2732.07	10.354
2734.75	9.91109
2737.43	9.10178
2740.11	7.91445
2742.79	6.9578
2745.47	6.62476
2748.14	6.40275
2750.82	5.77358
2753.49	4.53615
2756.17	3.49604
2758.84	3.16844
2761.51	1.87411
2764.18	2.61723
2766.85	2.50392
2769.52	2.73645
2772.19	3.40372
2774.86	4.00239
2777.52	3.02952
2780.19	2.51226
2782.85	2.74177
2785.52	2.2113
2788.18	2.70958
2790.84	2.89674
2793.5	2.60914
2796.16	2.80895
2798.82	3.89091
2801.48	4.11358
2804.13	3.77163
2806.79	3.40002
2809.45	2.53889
2812.1	1.12108
2814.75	0.903836
2817.41	1.14698
2820.06	3.15504
2822.71	6.60475
2825.36	12.0585
2828	17.5657
2830.65	22.8637
2833.3	29.696
2835.94	37.1099
2838.59	44.3479
2841.23	51.7757
2843.87	58.3363
2846.52	66.3749
2849.16	74.9853
2851.8	83.961
2854.44	93.934
2857.08	102.68
2859.71	112.15
2862.35	120.841
2864.98	126.952
2867.62	131.94
2870.25	136.966
2872.88	139.919
2875.52	142.551
2878.15	146.174
2880.78	150.814
2883.41	154.135
2886.03	158.257
2888.66	163.097
2891.29	166.265
2893.91	169.593
2896.54	174.862
2899.16	181.202
2901.78	188.162
2904.4	195.409
2907.02	204.455
2909.64	213.757
2912.26	223.71
2914.88	234.765
2917.5	244.565
2920.11	253.44
2922.73	260.457
2925.34	265.882
2927.96	268.492
2930.57	269.655
2933.18	268.493
2935.79	266.899
2938.4	261.777
2941.01	256.412
2943.62	249.033
2946.22	240.129
2948.83	230.28
2951.43	219.993
2954.04	210.255
2956.64	199.83
2959.24	190.524
2961.84	181.629
2964.45	171.47
2967.05	162.236
2969.64	152.908
2972.24	144.419
2974.84	135.831
2977.43	127.876
2980.03	119.869
2982.62	110.327
2985.22	101.184
2987.81	91.0046
2990.4	82.089
2992.99	72.7824
2995.58	63.5485
2998.17	55.6217
3000.76	47.7688
3003.34	40.7523
3005.93	33.8351
3008.52	28.5489
3011.1	23.7674
3013.68	18.8948
3016.27	15.4851
3018.85	13.4735
3021.43	10.5907
3024.01	9.02502
3026.59	8.08516
3029.16	7.79998
3031.74	9.24656
3034.32	9.92765
3036.89	11.2172
3039.47	13.0574
3042.04	14.3286
3044.61	15.064
3047.18	15.5397
3049.75	15.1223
3052.32	15.4477
3054.89	15.0287
3057.46	14.2957
3060.03	13.3477
3062.59	11.6264
3065.16	9.52788
3067.72	8.57183
3070.29	7.04363
3072.85	5.82095
3075.41	4.12482
3077.97	2.0813
3080.53	0.924285
3083.09	0.503658
3085.65	-0.558134
3088.21	-0.822708
3090.76	-0.225156
3093.32	-0.136648
3095.87	-0.00706494
3098.43	0.138305
3100.98	1.06842
3103.53	1.22467
3106.08	0.534739
3108.63	1.46021
3111.18	1.71074
3113.73	2.07188
3116.28	2.60463
3118.83	3.04626
3121.37	2.91322
3123.92	2.92378
3126.46	2.94754
3129	3.98471
3131.55	4.51421
3134.09	5.13156
3136.63	5.1792
3139.17	5.39337
3141.71	5.90504
3144.24	6.52027
3146.78	6.84174
3149.32	7.91956