File: data/Raman/poly_smoothed/Thy_10_08_08_1x_45s_532 nm_x100_100%_600 gr_mm_01.txt
#Acq. time (s)=	45
#Accumulations=	2
#Range (cm-¹)=	200...3150
#Windows=	2
#Auto scanning=	Off
#Autofocus=	Off
#Macrospot=	Off
#AutoExposure=	Off
#Spike filter=	Multiple accum.
#Delay time (s)=	0
#Binning=	1
#Readout mode=	Signal
#DeNoise=	Off
#ICS correction=	On
#Dark correction=	Off
#Inst. Process=	Off
#Detector Gain=	Best Dynamic Range
#Detector ADC=	20 kHz
#Detector temperature (°C)=	-69.85
#Instrument=	LabRAM HR Evol
#Detector=	Synapse
#Objective=	x100
#Grating=	600 gr/mm
#ND Filter=	100%
#Laser (nm)=	532
#Hole=	100.021
#Range=	Auto
#Laser Pol.=	No
#Raman. Pol.=	No
#Laser Pol. (°)=	-0.0007625
#Raman Pol. (°)=	89.9995
#Collection=	Microscope
#StageXY=	Marzhauser
#StageZ=	Marzhauser
#X (µm)=	2154
#Y (µm)=	1264.6
#Z (µm)=	442.55
#Full time(mm:ss)=	3:18
#Project=
#Sample=
#Site=
#Title=	Thy_10_08_08_2x_45s_532 nm_x100_100%_600 gr_mm
#Remark=
#Date=	05.07.2022 14:45
#Acquired=	05.07.2022 14:45:56
#Base:Fit=	10.08.2022 09:45:33
#Base:Fit=	10.08.2022 09:46:03
#Base:Fit=	10.08.2022 09:46:25
#Base:Sub=	10.08.2022 09:46:49
#Filter:Polynom=	16.08.2022 10:24:56
#AxisType[0]=Intens
#AxisUnit[0]=Cnt
#AxisType[1]=Spectr
#AxisUnit[1]=1/cm
200.43	4.15602
204.059	3.76503
207.688	2.12132
211.314	1.99164
214.941	1.68345
218.564	3.38623
222.186	3.25817
225.809	2.49838
229.428	3.44632
233.045	2.95682
236.663	3.75827
240.278	1.86876
243.891	1.91814
247.503	1.83617
251.116	2.01056
254.725	1.62513
258.333	1.76453
261.939	1.48507
265.544	2.07098
269.148	1.8205
272.75	2.63765
276.351	1.89953
279.95	2.4515
283.548	3.21982
287.144	4.98515
290.739	6.39456
294.333	6.67957
297.925	8.73325
301.514	9.75568
305.104	12.15
308.692	12.4578
312.279	12.6619
315.862	12.2318
319.446	13.5715
323.029	13.4332
326.608	12.5427
330.188	10.6972
333.766	10.0227
337.341	9.02528
340.917	8.67576
344.489	7.99127
348.062	6.62463
351.631	6.62064
355.201	6.12006
358.768	4.65377
362.333	4.27392
365.899	3.30677
369.462	5.88883
373.023	5.50132
376.585	6.87908
380.143	5.62019
383.7	6.6187
387.256	7.48209
390.812	7.08192
394.365	5.8258
397.916	4.9541
401.467	5.81219
405.015	7.863
408.563	6.86885
412.109	7.82887
415.654	7.08446
419.197	7.38233
422.739	8.13517
426.279	7.46824
429.819	6.41106
433.356	6.28723
436.891	5.82874
440.426	5.87128
443.96	4.82001
447.492	5.25316
451.021	6.25677
454.551	7.08642
458.079	8.47579
461.604	8.5428
465.13	8.45008
468.654	9.69652
472.175	11.7503
475.696	13.0798
479.215	13.4151
482.733	16.0726
486.249	19.0616
489.765	22.5359
493.278	26.2002
496.789	26.5583
500.301	26.7185
503.81	26.1965
507.317	26.2812
510.825	25.489
514.33	24.6083
517.833	23.8212
521.335	23.3854
524.836	22.6763
528.335	22.8554
531.835	22.2918
535.332	22.278
538.827	19.5805
542.321	19.055
545.814	16.4224
549.305	14.7802
552.795	14.6995
556.282	15.2649
559.769	14.3675
563.255	13.8145
566.739	12.6637
570.223	12.5669
573.705	13.5972
577.183	12.6276
580.663	11.129
584.141	9.29228
587.615	8.04037
591.09	7.82097
594.564	7.21455
598.035	7.28035
601.506	7.46414
604.974	8.91645
608.443	10.3708
611.908	12.2734
615.374	13.3044
618.837	13.6416
622.3	13.3319
625.761	13.8804
629.219	16.0416
632.677	17.5038
636.135	18.9164
639.59	21.6332
643.043	22.8392
646.495	25.0756
649.948	25.3771
653.398	26.9213
656.846	27.2453
660.293	29.0665
663.738	30.2257
667.183	31.5172
670.626	31.3066
674.067	32.7819
677.508	32.9788
680.947	33.969
684.385	35.0872
687.821	36.0344
691.254	36.9862
694.688	37.9233
698.121	39.8489
701.552	39.3343
704.98	40.6351
708.409	41.2312
711.836	41.8074
715.26	41.8368
718.685	42.4728
722.108	43.7619
725.528	44.5144
728.949	46.0192
732.367	46.8265
735.785	48.1392
739.2	51.2325
742.614	52.095
746.028	51.7977
749.439	57.4525
752.849	61.9021
756.26	66.3335
759.667	71.8486
763.073	75.6095
766.477	81.2673
769.883	84.1951
773.285	88.9165
776.686	93.8948
780.085	97.5595
783.484	98.6045
786.881	100.277
790.276	102.033
793.671	103.567
797.064	103.779
800.456	104.595
803.846	104.925
807.234	105.323
810.622	105.035
814.008	103.433
817.394	102.165
820.778	101.589
824.159	99.5133
827.541	96.4881
830.921	99.0558
834.298	100.033
837.676	97.6631
841.051	95.7967
844.426	93.1151
847.798	90.2995
851.171	87.0247
854.54	81.6851
857.911	80.3557
861.278	78.2415
864.645	74.662
868.01	71.6897
871.373	70.3863
874.735	68.4402
878.097	66.3426
881.457	65.9868
884.815	65.188
888.172	64.2781
891.528	64.7886
894.882	63.2281
898.237	63.1986
901.589	63.5471
904.94	64.3002
908.289	63.0753
911.635	61.8316
914.982	61.0259
918.328	59.5458
921.672	58.2831
925.015	57.2495
928.357	56.7757
931.698	56.739
935.035	55.0282
938.373	55.8847
941.71	56.1869
945.044	54.6296
948.378	52.914
951.709	52.5298
955.041	51.8238
958.372	48.9647
961.699	48.3393
965.027	49.9453
968.352	51.8643
971.676	53.5533
975	56.2793
978.322	58.3551
981.642	58.8627
984.962	59.8009
988.28	58.7464
991.596	58.6377
994.911	57.6168
998.227	57.6704
1001.54	56.5644
1004.85	56.2549
1008.16	55.6864
1011.47	54.9038
1014.78	51.7145
1018.08	50.1416
1021.39	48.4332
1024.69	46.0373
1028	42.2148
1031.3	40.4263
1034.6	37.304
1037.9	33.6238
1041.19	33.6289
1044.49	33.7259
1047.78	34.5969
1051.08	34.0318
1054.37	33.6863
1057.66	33.083
1060.95	30.9602
1064.24	30.2736
1067.53	29.3224
1070.81	27.1417
1074.1	25.6355
1077.38	24.8255
1080.66	25.6792
1083.94	25.0706
1087.22	25.3885
1090.5	24.8494
1093.78	23.8207
1097.05	25.9443
1100.33	25.868
1103.6	25.7155
1106.87	25.3426
1110.14	25.6507
1113.41	25.0931
1116.68	24.5308
1119.95	22.9072
1123.21	21.3635
1126.48	18.3581
1129.74	17.1226
1133	16.5746
1136.26	15.9507
1139.52	14.764
1142.78	14.5823
1146.04	14.0484
1149.29	12.4606
1152.55	11.7765
1155.8	10.3326
1159.05	7.95004
1162.3	6.70437
1165.55	4.67655
1168.8	3.90141
1172.05	6.34765
1175.29	7.88254
1178.54	9.55515
1181.78	10.4466
1185.02	10.9344
1188.26	12.7091
1191.5	15.3331
1194.74	18.8855
1197.97	21.8811
1201.21	25.0668
1204.44	29.8165
1207.68	32.689
1210.91	37.4839
1214.14	42.2948
1217.37	46.7214
1220.59	51.9267
1223.82	55.3136
1227.05	59.1928
1230.27	59.813
1233.49	60.1271
1236.72	61.5703
1239.94	62.821
1243.16	64.6647
1246.37	65.4554
1249.59	67.6158
1252.8	68.3421
1256.02	67.6144
1259.23	67.0148
1262.44	65.6312
1265.66	65.6668
1268.86	67.2206
1272.07	68.5176
1275.28	68.6194
1278.48	69.145
1281.69	70.5639
1284.89	70.8323
1288.09	73.181
1291.29	74.3962
1294.49	76.584
1297.69	78.2218
1300.89	79.5503
1304.08	81.3238
1307.28	83.0206
1310.47	85.2144
1313.66	87.9318
1316.85	89.9055
1320.04	90.4765
1323.23	90.9567
1326.42	89.7451
1329.61	89.1928
1332.79	86.883
1335.97	84.5748
1339.16	80.7636
1342.34	78.4084
1345.52	76.1011
1348.7	72.6374
1351.87	69.5481
1355.05	66.1025
1358.22	62.8338
1361.4	59.3281
1364.57	55.6206
1367.74	51.7239
1370.91	49.4105
1374.08	46.3844
1377.25	44.3804
1380.41	42.4597
1383.58	41.1835
1386.74	40.7759
1389.91	40.8874
1393.07	39.0895
1396.23	38.9914
1399.39	39.0104
1402.55	39.946
1405.7	41.4708
1408.86	42.8532
1412.01	45.228
1415.17	48.6014
1418.32	53.6231
1421.47	58.1019
1424.62	63.4469
1427.77	70.6179
1430.91	76.571
1434.06	80.8488
1437.2	85.4026
1440.35	89.4131
1443.49	93.1033
1446.63	94.3524
1449.77	94.0774
1452.91	93.8566
1456.05	91.9531
1459.18	88.5605
1462.32	84.4067
1465.45	78.2857
1468.59	71.1964
1471.72	63.0549
1474.85	56.1214
1477.98	48.9135
1481.1	42.4872
1484.23	34.4587
1487.36	30.1914
1490.48	25.6233
1493.61	20.9946
1496.73	17.3133
1499.85	14.024
1502.97	11.5379
1506.09	10.7624
1509.2	8.29145
1512.32	7.93643
1515.43	7.33041
1518.55	8.47536
1521.66	9.70491
1524.77	11.863
1527.88	15.8718
1530.99	18.1521
1534.1	21.1639
1537.21	23.1311
1540.31	25.2581
1543.42	27.6659
1546.52	32.2489
1549.62	35.2802
1552.72	38.6431
1555.82	41.6074
1558.92	44.5926
1562.02	47.229
1565.11	49.5511
1568.21	50.9547
1571.3	52.6307
1574.39	54.9712
1577.49	56.7565
1580.57	58.9842
1583.66	61.4422
1586.75	63.2885
1589.84	65.7259
1592.92	69.9907
1596.01	72.5259
1599.09	73.8878
1602.17	74.8742
1605.25	73.9392
1608.33	74.3029
1611.41	73.582
1614.49	73.132
1617.57	72.154
1620.64	72.5658
1623.72	72.8968
1626.79	73.6247
1629.86	74.7444
1632.93	75.6113
1636	76.2399
1639.07	77.663
1642.13	81.3732
1645.2	83.8965
1648.26	86.1537
1651.33	88.8721
1654.39	90.7054
1657.45	93.9328
1660.51	95.396
1663.57	95.8966
1666.63	95.8251
1669.68	93.9911
1672.74	89.955
1675.79	84.6208
1678.85	80.279
1681.9	75.9627
1684.95	71.0252
1688	64.1303
1691.05	57.1906
1694.09	52.7985
1697.14	48.0633
1700.18	42.1786
1703.23	36.1779
1706.27	30.7716
1709.31	27.1198
1712.35	24.5531
1715.39	21.2438
1718.43	18.3137
1721.47	14.941
1724.5	13.2519
1727.54	11.708
1730.57	11.6918
1733.61	11.1417
1736.64	8.88086
1739.67	8.21764
1742.7	7.25572
1745.72	7.45713
1748.75	6.15699
1751.77	5.66976
1754.8	6.9381
1757.82	5.58605
1760.84	3.72664
1763.87	3.70648
1766.89	3.09179
1769.91	3.72631
1772.92	3.28323
1775.94	2.68029
1778.95	3.30812
1781.97	3.80922
1784.98	2.76122
1787.99	1.7521
1791.01	1.76549
1794.01	2.06851
1797.02	2.10612
1800.03	2.1823
1803.04	1.9729
1806.04	2.5088
1809.05	1.54337
1812.05	1.73667
1815.05	0.84713
1818.05	0.632425
1821.05	0.35051
1824.05	0.0843207
1827.05	-0.474913
1830.04	-0.324901
1833.04	-0.240725
1836.03	-0.227779
1839.03	0.350531
1842.02	1.03361
1845.01	0.947532
1848	1.56752
1850.99	0.191033
1853.97	0.828677
1856.96	1.30829
1859.94	0.909244
1862.93	0.73249
1865.91	-0.167398
1868.89	1.03376
1871.87	1.80072
1874.85	1.40572
1877.83	1.19531
1880.81	1.29252
1882.57	0.813284
1885.56	0.550672
1888.55	0.745363
1891.54	1.70227
1894.52	1.67379
1897.51	2.04391
1900.49	3.94586
1903.47	3.73858
1906.45	4.34163
1909.43	4.52692
1912.41	4.88952
1915.39	4.89694
1918.37	5.12831
1921.34	5.20969
1924.32	5.23171
1927.29	6.21794
1930.26	6.11493
1933.23	6.11161
1936.2	5.6172
1939.17	6.66666
1942.14	7.06342
1945.11	5.57928
1948.07	5.65918
1951.04	5.18945
1954	5.55288
1956.96	4.93306
1959.93	4.88123
1962.89	4.88767
1965.85	4.3242
1968.8	4.57621
1971.76	4.5195
1974.72	5.12546
1977.67	5.61509
1980.63	5.78903
1983.58	6.49953
1986.53	7.05898
1989.48	8.01124
1992.43	8.68693
1995.38	9.99472
1998.32	11.2744
2001.27	11.9561
2004.22	12.8641
2007.16	12.7985
2010.1	12.3442
2013.04	13.1292
2015.98	13.8536
2018.92	13.5591
2021.86	12.7732
2024.8	12.4962
2027.74	11.5335
2030.67	10.2623
2033.61	10.0733
2036.54	9.80007
2039.47	10.188
2042.4	10.3562
2045.33	10.7273
2048.26	10.799
2051.19	11.3067
2054.12	11.5696
2057.04	12.2177
2059.97	12.3277
2062.89	12.6542
2065.81	12.5307
2068.73	12.8215
2071.65	13.4857
2074.57	13.7037
2077.49	14.6207
2080.41	15.4013
2083.32	16.0533
2086.24	17.8593
2089.15	18.1979
2092.07	18.6505
2094.98	19.5636
2097.89	19.7867
2100.8	19.3107
2103.71	19.5499
2106.61	20.2519
2109.52	20.4718
2112.43	21.3098
2115.33	21.3608
2118.23	22.8263
2121.13	23.2469
2124.04	23.757
2126.94	24.1966
2129.83	25.6544
2132.73	26.3314
2135.63	26.1292
2138.53	26.895
2141.42	28.3197
2144.31	29.033
2147.21	30.7144
2150.1	33.7533
2152.99	36.4762
2155.88	38.2196
2158.77	40.1413
2161.65	42.1752
2164.54	43.498
2167.43	44.0164
2170.31	44.318
2173.19	45.5868
2176.07	46.0049
2178.96	46.6111
2181.84	45.797
2184.72	44.9342
2187.59	43.7947
2190.47	42.6511
2193.35	41.0213
2196.22	40.0503
2199.09	37.7584
2201.97	35.3761
2204.84	33.6916
2207.71	30.7809
2210.58	29.3
2213.45	27.7461
2216.31	25.6114
2219.18	25.1851
2222.05	24.0752
2224.91	22.5612
2227.78	22.1471
2230.64	21.1435
2233.5	21.172
2236.36	21.0409
2239.22	20.8436
2242.08	21.2527
2244.93	21.1656
2247.79	20.8201
2250.64	20.0251
2253.5	18.5814
2256.35	17.9498
2259.2	17.4975
2262.05	18.2607
2264.9	17.1774
2267.75	16.2318
2270.6	16.1215
2273.45	17.464
2276.29	17.9019
2279.14	17.7397
2281.98	17.3107
2284.82	16.8485
2287.66	16.5273
2290.5	16.9933
2293.34	16.1815
2296.18	15.7764
2299.02	15.8021
2301.86	16.3218
2304.69	16.6781
2307.53	17.1979
2310.36	17.3702
2313.19	17.374
2316.02	16.0903
2318.85	15.5283
2321.68	14.2082
2324.51	12.9844
2327.34	12.9785
2330.16	11.9865
2332.99	12.6845
2335.81	10.2245
2338.64	9.90156
2341.46	10.3782
2344.28	10.6085
2347.1	8.70438
2349.92	8.26225
2352.74	8.34565
2355.55	7.96067
2358.37	7.06257
2361.19	6.87812
2364	6.0228
2366.81	6.23867
2369.62	6.47501
2372.44	6.93205
2375.24	6.99607
2378.05	6.67705
2380.86	6.66313
2383.67	6.5962
2386.47	6.21061
2389.28	5.82954
2392.08	5.58343
2394.89	6.0235
2397.69	6.3121
2400.49	6.23981
2403.29	5.98107
2406.09	4.71559
2408.88	5.18693
2411.68	5.46574
2414.48	5.6765
2417.27	6.07843
2420.06	5.64346
2422.86	5.68698
2425.65	5.27508
2428.44	4.66099
2431.23	4.40738
2434.02	4.00435
2436.81	4.27228
2439.59	4.45676
2442.38	4.35042
2445.16	3.28579
2447.95	3.05089
2450.73	1.7582
2453.51	2.34065
2456.29	1.87602
2459.07	2.40328
2461.85	3.08503
2464.63	2.91516
2467.4	3.12825
2470.18	2.76024
2472.95	2.93457
2475.73	2.24574
2478.5	3.19554
2481.27	2.67311
2484.04	2.68567
2486.81	1.3919
2489.58	0.967399
2492.35	0.408299
2495.12	1.19613
2497.88	0.538128
2500.65	1.82362
2503.41	1.26637
2506.17	1.21643
2508.94	0.776903
2511.7	0.541466
2514.46	0.414487
2517.22	0.142343
2519.97	0.535268
2522.73	1.40494
2525.49	1.28061
2528.24	2.62552
2530.99	3.0416
2533.75	3.95507
2536.5	4.36404
2539.25	4.68738
2542	5.33148
2544.75	4.71775
2547.5	4.02771
2550.24	3.88304
2552.99	4.04231
2555.74	3.55286
2558.48	3.90589
2561.22	5.02723
2563.96	4.20203
2566.71	4.43165
2569.45	4.30973
2572.18	4.217
2574.92	4.94746
2577.66	5.09092
2580.4	4.1504
2583.13	4.24172
2585.87	3.77709
2588.6	3.69728
2591.33	4.33162
2594.06	4.84722
2596.79	4.93079
2599.52	4.785
2602.25	3.80638
2604.98	3.80084
2607.71	3.54637
2610.43	3.12617
2613.16	2.75967
2615.88	2.46823
2618.6	1.96866
2621.32	1.3863
2624.04	1.37231
2626.76	1.59364
2629.48	2.17481
2632.2	2.88362
2634.92	4.88785
2637.63	5.28904
2640.35	5.58013
2643.06	5.48535
2645.77	5.9016
2648.49	5.42442
2651.2	5.96245
2653.91	5.96697
2656.62	5.95905
2659.33	6.92872
2662.03	5.41665
2664.74	5.04874
2667.44	5.85391
2670.15	6.28004
2672.85	7.01856
2675.55	7.18989
2678.26	7.06448
2680.96	6.38142
2683.66	6.2689
2686.35	7.03608
2689.05	8.59568
2691.75	10.353
2694.44	11.2999
2697.14	12.4519
2699.83	13.6297
2702.52	14.3887
2705.22	14.6955
2707.91	15.952
2710.6	17.201
2713.29	17.7425
2715.97	18.9818
2718.66	18.7744
2721.35	19.2033
2724.03	19.2728
2726.72	19.5548
2729.4	19.2524
2732.08	19.9264
2734.76	19.8463
2737.44	18.7846
2740.12	18.4203
2742.8	17.7452
2745.48	16.9016
2748.16	16.6241
2750.83	16.7155
2753.51	16.3109
2756.18	15.3618
2758.85	14.9885
2761.53	13.8479
2764.2	13.2967
2766.87	14.032
2769.54	12.754
2772.2	11.9927
2774.87	12.1578
2777.54	11.5702
2780.2	10.6169
2782.87	10.8991
2785.53	9.94795
2788.19	9.69055
2790.85	9.93201
2793.51	9.77511
2796.17	9.53062
2798.83	9.40195
2801.49	8.99124
2804.15	10.1496
2806.8	10.9121
2809.46	10.5692
2812.11	11.1726
2814.76	12.4588
2817.42	13.0154
2820.07	14.2276
2822.72	16.3374
2825.37	19.4245
2828.02	21.827
2830.66	25.7326
2833.31	29.4817
2835.96	33.4732
2838.6	38.2744
2841.24	45.1889
2843.89	52.5872
2846.53	63.0587
2849.17	72.0151
2851.81	83.961
2854.45	95.7695
2857.09	107.606
2859.72	118.583
2862.36	129.076
2865	140.096
2867.63	150.145
2870.26	159.342
2872.9	166.643
2875.53	172.736
2878.16	178.843
2880.79	184.107
2883.42	188.164
2886.05	193.008
2888.67	197.337
2891.3	202.135
2893.92	206.166
2896.55	212.19
2899.17	217
2901.79	225.676
2904.42	235.371
2907.04	247.776
2909.66	261.482
2912.27	273.736
2914.89	288.376
2917.51	302.093
2920.13	314.154
2922.74	324.369
2925.35	332.349
2927.97	337.53
2930.58	341.923
2933.19	339.821
2935.8	338.478
2938.41	334.529
2941.02	328.271
2943.63	319.817
2946.24	309.895
2948.84	298.978
2951.45	287.498
2954.05	275.644
2956.65	264.524
2959.26	251.713
2961.86	240.254
2964.46	228.229
2967.06	218.255
2969.66	208.856
2972.25	200.552
2974.85	191.371
2977.45	182.749
2980.04	174.265
2982.64	163.947
2985.23	153.618
2987.82	143.34
2990.41	132.93
2993	122.283
2995.59	112.308
2998.18	101.902
3000.77	92.9174
3003.36	83.6567
3005.94	74.9156
3008.53	67.2154
3011.11	60.0422
3013.69	53.8833
3016.28	49.3731
3018.86	45.3822
3021.44	41.7597
3024.02	37.7579
3026.6	36.294
3029.18	34.735
3031.75	34.3672
3034.33	34.9897
3036.9	35.1656
3039.48	36.3006
3042.05	36.9072
3044.62	37.8563
3047.19	40.1582
3049.77	41.5409
3052.34	43.1511
3054.9	44.0151
3057.47	43.0059
3060.04	41.8164
3062.61	40.5303
3065.17	39.1499
3067.74	36.8573
3070.3	34.9861
3072.86	33.5681
3075.42	30.3607
3077.99	27.4684
3080.54	25.4604
3083.1	23.2678
3085.66	20.0432
3088.22	17.5426
3090.78	15.1321
3093.33	12.8833
3095.89	11.4307
3098.44	11.0825
3100.99	9.44012
3103.54	8.01513
3106.1	7.52618
3108.65	6.57968
3111.2	5.74956
3113.74	5.19639
3116.29	3.8823
3118.84	3.06208
3121.38	2.10472
3123.93	1.4958
3126.47	1.16146
3129.01	0.026683
3131.56	-0.0267226
3134.1	0.794469
3136.64	0.630111
3139.18	0.858268
3141.72	2.12883
3144.26	2.75212
3146.79	3.47994
3149.33	6.04639