File: data/Raman/poly_smoothed/Thy_50_12_08_1x_45s_532 nm_x100_100%_600 gr_mm_01.txt
#Acq. time (s)=	45
#Accumulations=	2
#Range (cm-¹)=	200...3150
#Windows=	2
#Auto scanning=	Off
#Autofocus=	Off
#Macrospot=	Off
#AutoExposure=	Off
#Spike filter=	Multiple accum.
#Delay time (s)=	0
#Binning=	1
#Readout mode=	Signal
#DeNoise=	Off
#ICS correction=	On
#Dark correction=	Off
#Inst. Process=	Off
#Detector Gain=	Best Dynamic Range
#Detector ADC=	20 kHz
#Detector temperature (°C)=	-69.85
#Instrument=	LabRAM HR Evol
#Detector=	Synapse
#Objective=	x100
#Grating=	600 gr/mm
#ND Filter=	100%
#Laser (nm)=	532
#Hole=	100.021
#Range=	Auto
#Laser Pol.=	No
#Raman. Pol.=	No
#Laser Pol. (°)=	-0.0007625
#Raman Pol. (°)=	89.9995
#Collection=	Microscope
#StageXY=	Marzhauser
#StageZ=	Marzhauser
#X (µm)=	-5101.8
#Y (µm)=	1499.1
#Z (µm)=	63.1
#Full time(mm:ss)=	3:19
#Project=
#Sample=
#Site=
#Title=	Thy_50_12_08_2x_45s_532 nm_x100_100%_600 gr_mm
#Remark=
#Date=	07.07.2022 09:49
#Acquired=	07.07.2022 09:49:12
#Base:Fit=	10.08.2022 10:03:08
#Base:Fit=	10.08.2022 10:03:15
#Base:Fit=	10.08.2022 10:03:19
#Base:Fit=	10.08.2022 10:04:29
#Base:Sub=	10.08.2022 10:04:45
#Filter:Polynom=	16.08.2022 10:20:24
#AxisType[0]=Intens
#AxisUnit[0]=Cnt
#AxisType[1]=Spectr
#AxisUnit[1]=1/cm
200.43	23.8332
204.061	25.997
207.688	24.1076
211.316	21.7175
214.941	19.8919
218.566	16.9234
222.188	15.0865
225.809	13.9107
229.43	10.9275
233.047	9.66116
236.663	8.46693
240.278	7.56193
243.894	6.27478
247.506	5.50769
251.116	3.47793
254.725	2.32176
258.333	1.92667
261.939	1.49362
265.546	0.734142
269.15	2.32841
272.752	1.15866
276.353	2.3341
279.952	3.625
283.55	5.53665
287.146	5.94768
290.739	6.33412
294.333	7.87471
297.925	9.45894
301.516	10.4574
305.106	9.80263
308.694	10.9804
312.279	12.0942
315.864	11.5539
319.448	9.67214
323.029	10.471
326.61	10.249
330.19	8.75049
333.766	8.24085
337.343	7.21477
340.917	4.80537
344.491	3.58437
348.062	1.96453
351.633	1.62089
355.201	2.20865
358.77	2.65238
362.335	3.16523
365.899	4.57699
369.464	6.49148
373.025	7.021
376.585	7.78471
380.143	8.16488
383.702	7.99298
387.258	8.3193
390.812	6.81259
394.365	6.89066
397.916	7.40579
401.467	6.76536
405.015	5.42355
408.565	5.14407
412.111	4.01171
415.656	3.5242
419.197	2.46936
422.739	2.46048
426.279	2.71541
429.819	2.08071
433.356	2.63822
436.893	2.65011
440.428	3.70333
443.96	4.5619
447.492	4.85209
451.023	5.67855
454.553	5.60384
458.079	7.03701
461.606	7.45274
465.132	7.76452
468.654	9.25613
472.177	10.2585
475.696	11.39
479.217	10.5643
482.733	11.9567
486.251	13.4676
489.765	13.8157
493.278	14.11
496.791	14.6666
500.301	15.114
503.81	17.0219
507.319	18.4159
510.825	19.4976
514.33	19.4444
517.833	18.8868
521.337	19.3441
524.838	18.7389
528.337	19.6007
531.835	20.0451
535.332	19.1406
538.827	19.4683
542.321	17.9975
545.814	17.6288
549.305	16.5268
552.795	15.7422
556.284	15.1749
559.771	12.4983
563.257	10.6569
566.742	9.47612
570.223	7.689
573.705	6.78278
577.185	6.52043
580.665	5.73218
584.141	5.22803
587.617	4.83078
591.092	3.67456
594.564	1.18704
598.037	0.13702
601.506	0.365846
604.976	0.453119
608.443	1.06388
611.91	2.3072
615.374	3.23934
618.839	4.74547
622.3	4.27716
625.761	4.45642
629.221	5.17749
632.679	5.65929
636.135	7.09256
639.592	7.92762
643.045	8.84742
646.497	10.1893
649.948	12.1753
653.398	12.3427
656.846	13.7554
660.293	15.5962
663.738	16.8536
667.185	18.0884
670.628	18.2179
674.067	19.5667
677.508	22.348
680.947	22.9916
684.385	25.791
687.821	27.4113
691.256	28.927
694.69	32.9105
698.121	36.075
701.552	36.8787
704.982	36.6068
708.41	37.6345
711.836	40.7143
715.262	40.9462
718.685	41.4787
722.108	42.6589
725.53	43.7275
728.949	44.3122
732.369	44.9332
735.785	44.3486
739.2	46.0366
742.616	47.7825
746.028	49.0152
749.441	49.0136
752.851	51.1842
756.26	52.905
759.667	55.5608
763.075	57.3519
766.479	60.6263
769.883	62.8972
773.285	67.1298
776.686	71.0695
780.085	74.029
783.484	75.626
786.881	76.4626
790.276	78.0642
793.671	79.3971
797.064	80.2744
800.456	80.8843
803.846	81.7096
807.236	82.032
810.624	82.659
814.01	83.8451
817.394	82.9976
820.778	84.2764
824.161	83.7576
827.543	81.3434
830.921	79.86
834.3	78.0739
837.676	76.8051
841.053	75.8076
844.426	74.9743
847.8	74.7328
851.171	72.7281
854.542	72.1045
857.911	70.0034
861.279	67.4108
864.645	65.0634
868.01	60.8837
871.375	58.2227
874.737	56.1402
878.097	54.0766
881.457	54.5422
884.817	53.301
888.174	51.7972
891.53	52.6601
894.884	51.5698
898.237	51.0361
901.589	50.0288
904.94	49.9651
908.289	48.2999
911.637	48.5768
914.984	47.1508
918.33	45.5149
921.674	43.1826
925.015	41.8494
928.357	40.9468
931.698	39.1599
935.037	36.6439
938.373	35.5597
941.71	33.7485
945.046	31.6613
948.378	30.506
951.711	30.0299
955.043	29.5615
958.372	30.9035
961.701	29.8054
965.027	31.6931
968.354	32.8765
971.678	34.3299
975	33.5164
978.324	34.2065
981.644	36.2949
984.962	36.7423
988.282	38.3656
991.598	38.2008
994.913	37.4366
998.227	36.2261
1001.54	34.3965
1004.85	33.2685
1008.16	32.4289
1011.47	31.0946
1014.78	31.104
1018.08	29.5278
1021.39	28.7478
1024.69	29.1482
1028	28.9331
1031.3	29.2416
1034.6	28.7717
1037.9	27.3731
1041.19	26.2319
1044.49	25.5402
1047.79	23.904
1051.08	22.0128
1054.37	21.9757
1057.66	20.8695
1060.95	20.6371
1064.24	19.3224
1067.53	17.6403
1070.81	16.6272
1074.1	15.6832
1077.38	15.9624
1080.66	15.8567
1083.94	14.5951
1087.22	14.3794
1090.5	14.8513
1093.78	15.6955
1097.05	17.2764
1100.33	18.725
1103.6	19.1919
1106.87	20.8914
1110.15	21.9633
1113.41	21.1912
1116.68	21.6138
1119.95	20.9785
1123.21	19.465
1126.48	18.9265
1129.74	17.298
1133	17.6942
1136.26	16.648
1139.52	14.295
1142.78	13.7413
1146.04	12.5155
1149.29	12.4882
1152.55	12.8604
1155.8	11.2123
1159.05	8.52454
1162.3	6.30411
1165.55	5.36486
1168.8	5.39853
1172.05	5.61743
1175.29	6.26057
1178.54	6.3364
1181.78	5.61337
1185.02	5.19168
1188.26	5.65816
1191.5	5.52148
1194.74	4.75507
1197.97	4.17207
1201.21	4.15672
1204.44	4.30979
1207.68	5.40941
1210.91	7.07424
1214.14	10.5144
1217.37	11.9454
1220.6	14.8554
1223.82	17.7913
1227.05	19.7372
1230.27	20.9773
1233.49	23.1788
1236.72	25.5833
1239.94	27.9951
1243.16	30.9498
1246.37	34.8302
1249.59	38.167
1252.8	41.3329
1256.02	42.0886
1259.23	43.3284
1262.44	46.1326
1265.66	50.3617
1268.87	50.3704
1272.07	52.4052
1275.28	54.3127
1278.48	55.8383
1281.69	58.6029
1284.89	60.8307
1288.09	61.9811
1291.3	64.4036
1294.49	65.5785
1297.69	66.8577
1300.89	67.7104
1304.09	67.2619
1307.28	67.4146
1310.47	69.1124
1313.66	70.3064
1316.86	69.8962
1320.05	69.9079
1323.23	69.6917
1326.42	67.9739
1329.61	66.5116
1332.79	64.2468
1335.98	61.2909
1339.16	58.6915
1342.34	56.3757
1345.52	53.0184
1348.7	50.5926
1351.87	49.9436
1355.05	47.0107
1358.23	43.6879
1361.4	41.6738
1364.57	40.2325
1367.74	38.2262
1370.91	36.5408
1374.08	33.7309
1377.25	32.1277
1380.42	30.8672
1383.58	31.024
1386.75	30.8975
1389.91	29.3074
1393.07	28.6649
1396.23	27.871
1399.39	27.4023
1402.55	27.66
1405.7	28.0667
1408.86	29.6889
1412.01	29.503
1415.17	31.5074
1418.32	35.9696
1421.47	40.6333
1424.62	45.7998
1427.77	51.1083
1430.92	55.8179
1434.06	60.0117
1437.2	65.177
1440.35	67.785
1443.49	71.3967
1446.63	71.3371
1449.77	71.8941
1452.91	72.3919
1456.05	71.8967
1459.18	68.1805
1462.32	65.4232
1465.45	61.242
1468.59	56.5371
1471.72	51.9355
1474.85	47.3888
1477.98	43.1907
1481.11	37.0809
1484.23	32.0257
1487.36	26.1868
1490.48	21.5358
1493.61	18.3879
1496.73	17.8449
1499.85	16.6609
1502.97	14.1622
1506.09	13.7173
1509.2	14.0847
1512.32	13.7774
1515.44	12.6955
1518.55	12.445
1521.66	13.0452
1524.77	14.8119
1527.88	16.6848
1530.99	18.6535
1534.1	20.3776
1537.21	23.5555
1540.31	27.0499
1543.42	31.1121
1546.52	34.7442
1549.62	39.1505
1552.72	41.8831
1555.82	44.3451
1558.92	46.0635
1562.02	48.631
1565.11	50.181
1568.21	53.3989
1571.3	56.1174
1574.39	59.499
1577.49	61.0323
1580.58	62.9307
1583.67	65.3632
1586.75	64.3633
1589.84	64.4793
1592.93	63.2166
1596.01	61.0589
1599.09	60.2108
1602.18	59.1827
1605.26	58.3154
1608.34	56.7318
1611.41	55.7499
1614.49	54.3559
1617.57	53.2038
1620.64	53.3633
1623.72	54.0385
1626.79	53.4201
1629.86	53.7031
1632.93	54.3875
1636	56.0543
1639.07	58.2719
1642.14	61.2021
1645.2	66.1861
1648.27	70.1895
1651.33	71.1896
1654.39	72.9089
1657.45	75.1041
1660.51	75.3441
1663.57	73.3191
1666.63	71.4808
1669.69	69.623
1672.74	66.1349
1675.79	63.6614
1678.85	59.2479
1681.9	54.9591
1684.95	49.602
1688	45.9177
1691.05	41.4325
1694.1	37.106
1697.14	32.3172
1700.19	28.9594
1703.23	25.5632
1706.27	21.2202
1709.32	18.2574
1712.35	16.0819
1715.39	15.0755
1718.43	13.5615
1721.47	12.6565
1724.5	9.71339
1727.54	8.53156
1730.57	8.56711
1733.61	7.78726
1736.64	6.0837
1739.67	5.58091
1742.7	5.07849
1745.72	4.86202
1748.75	3.99858
1751.78	4.20411
1754.8	4.47071
1757.82	5.61487
1760.85	4.26179
1763.87	5.15982
1766.89	5.63368
1769.91	4.36652
1772.92	3.74492
1775.94	3.618
1778.96	3.13433
1781.97	3.15629
1784.98	3.10619
1788	3.35444
1791.01	2.48214
1794.01	3.02783
1797.02	1.96882
1800.03	2.1944
1803.04	2.29855
1806.04	2.51456
1809.05	3.14165
1812.05	3.12853
1815.05	3.34442
1818.05	4.05775
1821.05	3.36322
1824.05	3.38572
1827.05	4.00401
1830.04	4.45441
1833.04	2.96696
1836.03	2.38846
1839.03	3.52223
1842.02	2.53155
1845.01	2.75627
1848	2.74148
1850.99	3.73531
1853.97	3.6154
1856.96	3.28683
1859.94	3.11604
1862.93	2.24409
1865.91	2.19786
1868.89	1.99598
1871.87	1.92223
1874.85	2.002
1877.83	1.15068
1880.81	0.510938
1882.56	1.29273
1885.55	0.775821
1888.54	0.773523
1891.52	0.61308
1894.51	0.364608
1897.49	0.624066
1900.48	1.23199
1903.46	1.59275
1906.44	2.58172
1909.42	2.81588
1912.4	2.73147
1915.38	3.75858
1918.35	4.39325
1921.33	4.02593
1924.3	4.06938
1927.28	3.71724
1930.25	3.81998
1933.22	3.56055
1936.19	3.31434
1939.16	2.64306
1942.13	2.751
1945.09	1.86251
1948.06	1.84792
1951.03	0.964182
1953.99	2.11313
1956.95	2.00979
1959.91	2.61015
1962.87	3.75361
1965.83	3.69416
1968.79	3.59298
1971.75	4.10715
1974.7	5.96025
1977.66	4.865
1980.61	4.95513
1983.56	4.33632
1986.52	4.77216
1989.47	4.45125
1992.41	4.62467
1995.36	3.23194
1998.31	2.82331
2001.26	2.57255
2004.2	2.85831
2007.15	2.13571
2010.09	1.51555
2013.03	1.18831
2015.97	0.897551
2018.91	1.52078
2021.85	1.81688
2024.79	1.95999
2027.72	3.69596
2030.66	4.16962
2033.59	4.83332
2036.53	4.38998
2039.46	5.52405
2042.39	6.33487
2045.32	8.30914
2048.25	8.57469
2051.18	9.03419
2054.1	10.9881
2057.03	12.4547
2059.95	13.0498
2062.88	13.1398
2065.8	14.6603
2068.72	14.7462
2071.64	16.5477
2074.56	18.2358
2077.48	19.2984
2080.39	19.037
2083.31	20.2164
2086.22	21.5301
2089.14	22.6347
2092.05	24.2647
2094.96	26.7307
2097.87	29.5395
2100.78	30.9535
2103.69	33.5267
2106.6	35.4133
2109.51	37.5405
2112.41	40.8054
2115.32	43.2983
2118.22	46.4608
2121.12	49.4334
2124.02	53.1277
2126.92	56.0311
2129.82	58.8498
2132.72	62.3237
2135.62	66.2489
2138.51	68.5511
2141.41	72.3304
2144.3	75.7293
2147.19	79.0387
2150.09	81.9109
2152.97	85.3752
2155.86	88.5562
2158.75	90.5629
2161.64	92.313
2164.53	94.9127
2167.41	97.2629
2170.3	97.7236
2173.18	97.4023
2176.06	96.6036
2178.94	95.5615
2181.82	93.6724
2184.7	91.8028
2187.58	89.1421
2190.46	86.8409
2193.33	83.4112
2196.21	80.6222
2199.08	78.17
2201.95	75.21
2204.83	71.8935
2207.7	68.3613
2210.57	66.3469
2213.43	63.6107
2216.3	61.6273
2219.17	59.4668
2222.03	57.6799
2224.9	55.3683
2227.76	52.9884
2230.62	50.0817
2233.49	47.6148
2236.34	45.198
2239.2	42.3699
2242.06	39.8869
2244.92	38.7632
2247.78	36.0534
2250.63	33.6645
2253.48	30.2492
2256.34	28.0716
2259.19	26.0857
2262.04	24.205
2264.89	23.1389
2267.74	21.673
2270.59	20.6304
2273.43	18.7126
2276.28	18.3988
2279.12	17.3146
2281.97	16.1272
2284.81	15.075
2287.65	14.9609
2290.49	13.2877
2293.33	10.9512
2296.17	10.3694
2299.01	10.3242
2301.84	9.848
2304.68	8.79404
2307.51	8.8445
2310.35	9.06937
2313.18	9.23808
2316.01	8.8884
2318.84	8.16431
2321.67	6.88031
2324.5	6.07845
2327.33	5.22367
2330.15	5.1561
2332.98	6.30475
2335.8	5.18104
2338.62	5.16662
2341.45	4.34762
2344.27	4.79754
2347.09	4.69257
2349.91	3.24739
2352.72	2.63937
2355.54	1.51284
2358.36	1.30869
2361.17	1.82886
2363.98	2.51849
2366.8	3.88304
2369.61	3.82806
2372.42	4.51467
2375.23	5.15517
2378.04	6.3377
2380.85	6.2842
2383.66	6.9318
2386.46	6.46521
2389.26	5.78541
2392.07	5.43722
2394.87	6.096
2397.67	5.94506
2400.47	7.1871
2403.27	5.78458
2406.07	5.82786
2408.87	6.14209
2411.67	6.32458
2414.46	6.17816
2417.26	5.79551
2420.05	5.37994
2422.84	5.38132
2425.64	5.18231
2428.43	5.77363
2431.22	6.05619
2434.01	6.04457
2436.79	6.3324
2439.58	6.74298
2442.37	6.10644
2445.15	5.93052
2447.93	5.39212
2450.72	5.86796
2453.5	5.82618
2456.28	5.24035
2459.06	5.34529
2461.84	6.15727
2464.62	5.97874
2467.39	6.06523
2470.17	7.1755
2472.94	7.41438
2475.72	7.83767
2478.49	7.34322
2481.26	7.76583
2484.03	7.46844
2486.8	8.04395
2489.57	7.12299
2492.34	7.62809
2495.1	6.39316
2497.87	6.46168
2500.63	6.20064
2503.4	5.15365
2506.16	5.18412
2508.92	4.64645
2511.68	5.08382
2514.44	4.70821
2517.2	4.50344
2519.96	4.00481
2522.72	2.82287
2525.47	1.87363
2528.23	1.89919
2530.98	1.95956
2533.74	1.69939
2536.49	3.19712
2539.24	2.47342
2541.99	1.79377
2544.74	2.21659
2547.49	2.88861
2550.23	3.70573
2552.98	4.5532
2555.72	4.50925
2558.47	4.30486
2561.21	4.60648
2563.95	5.17862
2566.69	5.92739
2569.43	6.48881
2572.17	6.03768
2574.91	5.53965
2577.65	4.99024
2580.39	4.8229
2583.12	5.23669
2585.85	4.02623
2588.59	3.63204
2591.32	2.99672
2594.05	2.29943
2596.78	1.48264
2599.51	1.75097
2602.24	1.54955
2604.97	1.32789
2607.69	1.07709
2610.42	2.04679
2613.14	3.8723
2615.87	4.50639
2618.59	4.68932
2621.31	4.60646
2624.03	4.62252
2626.75	5.09823
2629.47	5.00442
2632.19	4.66301
2634.91	4.17207
2637.62	4.06114
2640.34	3.45339
2643.05	3.24429
2645.76	3.36383
2648.48	4.10415
2651.19	3.93656
2653.9	3.90757
2656.6	3.94991
2659.31	2.81614
2662.02	2.78351
2664.73	3.26064
2667.43	3.79284
2670.14	4.28046
2672.84	5.21066
2675.54	6.29786
2678.24	5.78525
2680.94	6.0583
2683.64	6.5364
2686.34	7.15138
2689.04	8.42077
2691.74	8.72172
2694.43	9.25083
2697.13	9.28732
2699.82	10.2682
2702.51	11.4907
2705.21	12.4303
2707.9	12.7844
2710.58	13.5756
2713.27	14.6357
2715.96	15.8646
2718.65	15.9616
2721.33	16.0305
2724.02	16.4416
2726.71	15.5498
2729.39	16.0831
2732.07	16.5876
2734.75	15.7739
2737.43	15.1534
2740.11	13.476
2742.79	11.8003
2745.47	10.9129
2748.14	9.85786
2750.82	9.35646
2753.49	8.37304
2756.17	6.90006
2758.84	7.02075
2761.51	6.48265
2764.18	5.79362
2766.85	5.65511
2769.52	5.07285
2772.19	4.74738
2774.86	4.10904
2777.52	4.32216
2780.19	3.96571
2782.85	3.33415
2785.52	3.19466
2788.18	3.87071
2790.84	3.96425
2793.5	4.40967
2796.16	4.69906
2798.82	4.26918
2801.48	3.8712
2804.13	3.49279
2806.79	3.23112
2809.45	3.52923
2812.1	2.31078
2814.75	2.46525
2817.41	3.86607
2820.06	5.98187
2822.71	9.06443
2825.36	12.8407
2828	17.0337
2830.65	22.644
2833.3	26.634
2835.94	31.8514
2838.59	37.5347
2841.23	43.8145
2843.87	49.0989
2846.52	55.5352
2849.16	62.6299
2851.8	70.6783
2854.44	78.9421
2857.08	85.7735
2859.71	93.0064
2862.35	99.852
2864.98	107.345
2867.62	114.091
2870.25	118.959
2872.88	123.074
2875.52	126.918
2878.15	130.198
2880.78	134.789
2883.41	139.18
2886.03	143.089
2888.66	147.456
2891.29	151.047
2893.91	154.735
2896.54	158.371
2899.16	162.187
2901.78	166.941
2904.4	173.43
2907.02	178.857
2909.64	185.236
2912.26	193.103
2914.88	200.752
2917.5	208.509
2920.11	214.186
2922.73	219.953
2925.34	225.094
2927.96	229.143
2930.57	232.105
2933.18	231.782
2935.79	229.887
2938.4	226.369
2941.01	222.172
2943.62	216.024
2946.22	209.434
2948.83	201.871
2951.43	193.563
2954.04	184.398
2956.64	176.202
2959.24	167.449
2961.84	158.542
2964.45	150.839
2967.05	142.897
2969.64	134.452
2972.24	126.963
2974.84	118.281
2977.43	111.118
2980.03	103.296
2982.62	94.1158
2985.22	85.5159
2987.81	77.5886
2990.4	70.7333
2992.99	63.4542
2995.58	55.9028
2998.17	48.3541
3000.76	41.7921
3003.34	35.0201
3005.93	29.8148
3008.52	25.7239
3011.1	22.4044
3013.68	19.463
3016.27	16.5059
3018.85	14.6102
3021.43	13.192
3024.01	12
3026.59	11.1395
3029.16	10.0951
3031.74	10.3226
3034.32	10.7356
3036.89	10.9607
3039.47	11.2992
3042.04	11.3264
3044.61	10.8107
3047.18	10.6768
3049.75	11.3319
3052.32	11.6795
3054.89	11.5721
3057.46	10.9261
3060.03	10.3041
3062.59	9.17514
3065.16	7.74833
3067.72	7.38152
3070.29	6.78843
3072.85	5.48299
3075.41	4.03743
3077.97	2.84522
3080.53	1.89903
3083.09	1.02124
3085.65	0.864689
3088.21	1.71063
3090.76	1.79077
3093.32	2.7889
3095.87	3.20688
3098.43	3.42137
3100.98	3.94126
3103.53	3.61602
3106.08	4.04413
3108.63	4.38363
3111.18	4.9244
3113.73	5.73611
3116.28	5.99948
3118.83	6.92122
3121.37	7.65357
3123.92	7.69467
3126.46	7.70839
3129	8.16399
3131.55	8.95747
3134.09	9.11814
3136.63	9.38414
3139.17	11.4519
3141.71	13.3209
3144.24	15.0203
3146.78	16.5137
3149.32	15.3753