File: data/Raman/poly_smoothed/Thy_30_10_40_1x_45s_532 nm_x100_100%_600 gr_mm_01.txt
#Acq. time (s)=	45
#Accumulations=	2
#Range (cm-¹)=	200...3150
#Windows=	2
#Auto scanning=	Off
#Autofocus=	Off
#Macrospot=	Off
#AutoExposure=	Off
#Spike filter=	Multiple accum.
#Delay time (s)=	0
#Binning=	1
#Readout mode=	Signal
#DeNoise=	Off
#ICS correction=	On
#Dark correction=	Off
#Inst. Process=	Off
#Detector Gain=	Best Dynamic Range
#Detector ADC=	20 kHz
#Detector temperature (°C)=	-69.85
#Instrument=	LabRAM HR Evol
#Detector=	Synapse
#Objective=	x100
#Grating=	600 gr/mm
#ND Filter=	100%
#Laser (nm)=	532
#Hole=	100.021
#Range=	Auto
#Laser Pol.=	No
#Raman. Pol.=	No
#Laser Pol. (°)=	-0.0007625
#Raman Pol. (°)=	89.9995
#Collection=	Microscope
#StageXY=	Marzhauser
#StageZ=	Marzhauser
#X (µm)=	4727.6
#Y (µm)=	-7713
#Z (µm)=	584.45
#Full time(mm:ss)=	3:19
#Project=
#Sample=
#Site=
#Title=	Thy_30_10_40_2x_45s_532 nm_x100_100%_600 gr_mm
#Remark=
#Date=	30.06.2022 14:18
#Acquired=	30.06.2022 14:18:20
#Base:Fit=	10.08.2022 09:58:11
#Base:Sub=	10.08.2022 09:58:44
#Filter:Polynom=	16.08.2022 10:22:53
#AxisType[0]=Intens
#AxisUnit[0]=Cnt
#AxisType[1]=Spectr
#AxisUnit[1]=1/cm
200.533	-1.44542
204.162	3.58133
207.792	6.97429
211.418	8.56709
215.044	9.96247
218.667	9.52853
222.289	9.24338
225.912	8.43104
229.531	7.86785
233.148	7.07089
236.766	6.91322
240.381	6.70653
243.994	7.47441
247.606	7.09142
251.217	5.68198
254.828	4.10283
258.436	3.89119
262.042	3.64752
265.647	3.93846
269.25	3.29407
272.852	3.88378
276.453	4.93711
280.052	4.8201
283.65	5.92066
287.247	8.15115
290.842	9.1222
294.436	9.06152
298.028	9.30731
301.617	9.71646
305.206	10.0708
308.794	10.8186
312.381	11.2915
315.964	11.314
319.548	11.8177
323.131	10.8993
326.71	11.7849
330.29	11.3241
333.868	10.224
337.443	8.90651
341.018	8.60868
344.591	8.44319
348.163	9.30099
351.733	8.93207
355.303	9.42771
358.869	10.2633
362.435	10.4763
366.001	10.1052
369.563	10.3351
373.124	10.8289
376.686	11.7198
380.244	12.7437
383.801	13.8569
387.357	13.6552
390.911	13.6757
394.466	13.4864
398.018	13.1262
401.568	12.5853
405.117	11.2202
408.664	9.26229
412.21	8.26559
415.755	8.08623
419.298	6.28606
422.84	6.44973
426.38	6.87939
429.919	8.71817
433.455	8.24129
436.992	7.72114
440.527	8.11379
444.06	8.16237
447.593	8.36609
451.122	7.96159
454.651	8.80887
458.18	12.1303
461.705	13.406
465.23	16.1003
468.752	16.5856
472.275	16.4578
475.797	17.1104
479.315	18.2637
482.834	17.9813
486.349	18.182
489.863	17.9426
493.378	18.4857
496.889	20.1341
500.401	21.8597
503.91	20.996
507.417	21.3562
510.923	23.1208
514.43	24.7425
517.933	24.84
521.435	23.7857
524.936	24.8669
528.435	25.2158
531.933	25.0911
535.43	25.0212
538.927	24.0239
542.421	22.5101
545.913	20.5209
549.403	17.3824
552.893	16.0839
556.381	12.8436
559.868	11.3371
563.354	10.3681
566.839	8.60594
570.322	7.14826
573.802	5.46199
577.283	4.63355
580.762	4.38711
584.24	4.87115
587.714	4.39721
591.19	4.2477
594.663	3.36305
598.134	4.91129
601.605	7.55755
605.073	8.30158
608.542	10.6602
612.007	11.7971
615.473	13.1835
618.936	13.5446
622.397	14.5018
625.859	16.6566
629.318	17.9178
632.775	18.6426
636.233	20.4366
639.688	22.0781
643.142	21.7101
646.594	22.0678
650.045	22.2919
653.496	21.8048
656.944	21.9252
660.391	21.6906
663.837	23.1298
667.281	23.4977
670.724	23.1613
674.166	22.985
677.606	23.6351
681.045	24.2631
684.483	25.6726
687.917	27.9493
691.352	29.0268
694.786	32.6114
698.219	34.5073
701.65	36.6892
705.078	38.9558
708.506	43.3252
711.934	45.6297
715.358	47.5656
718.782	47.7552
722.204	50.2489
725.626	51.3493
729.045	51.195
732.464	52.6735
735.881	54.5143
739.297	56.2343
742.711	55.7109
746.125	58.3468
749.537	60.8914
752.946	62.8302
756.357	64.5388
759.764	66.1195
763.17	67.389
766.575	68.3255
769.978	69.457
773.382	71.7214
776.783	73.6926
780.182	73.8087
783.581	74.0858
786.978	76.1744
790.373	76.5798
793.768	77.0552
797.161	78.089
800.552	78.5656
803.941	80.5812
807.33	80.7531
810.718	80.5156
814.105	80.2196
817.49	81.4009
820.873	82.4715
824.256	82.0192
827.637	83.1508
831.016	84.7139
834.395	83.1394
837.772	81.1972
841.147	79.5205
844.522	77.8627
847.894	75.8132
851.267	73.621
854.637	73.323
858.007	70.9974
861.374	69.1891
864.739	67.2602
868.106	65.5391
871.469	63.6574
874.831	59.9171
878.193	59.2341
881.553	57.8239
884.911	57.2847
888.268	56.4308
891.623	54.6635
894.978	54.5053
898.331	54.9338
901.683	54.6938
905.033	54.3188
908.383	54.8222
911.731	54.888
915.078	52.6287
918.423	51.5539
921.768	51.4708
925.111	51.701
928.452	51.2714
931.791	50.7279
935.13	51.1962
938.468	49.3647
941.803	49.1897
945.139	47.2665
948.473	45.1205
951.804	44.385
955.136	44.528
958.465	43.6348
961.794	43.1928
965.12	44.8672
968.447	47.6255
971.771	49.537
975.095	51.4353
978.417	53.2947
981.737	55.2194
985.057	57.163
988.375	57.0497
991.691	57.4532
995.006	57.1202
998.32	56.0033
1001.63	55.4132
1004.95	55.345
1008.26	52.8565
1011.56	50.8641
1014.87	49.4509
1018.18	46.6116
1021.48	45.4699
1024.79	42.4517
1028.09	41.3852
1031.39	41.5834
1034.69	39.5791
1037.99	39.4022
1041.29	38.0086
1044.58	38.4508
1047.88	38.1886
1051.17	36.7921
1054.46	34.6614
1057.75	34.0314
1061.04	33.4657
1064.33	31.9335
1067.62	30.4962
1070.9	28.7758
1074.19	27.6172
1077.47	26.6041
1080.76	25.9999
1084.04	24.6921
1087.32	25.8262
1090.59	26.4053
1093.87	26.3576
1097.15	26.5664
1100.42	27.8061
1103.69	28.9047
1106.97	29.8158
1110.24	29.9942
1113.51	29.1957
1116.77	28.3494
1120.04	26.4179
1123.31	24.5014
1126.57	21.8068
1129.83	18.6044
1133.1	16.682
1136.36	14.1119
1139.62	13.1038
1142.87	12.3142
1146.13	12.7537
1149.38	10.4084
1152.64	8.2205
1155.89	7.88051
1159.14	7.21858
1162.39	8.13706
1165.64	8.72556
1168.89	9.38844
1172.14	9.56797
1175.38	10.7701
1178.63	12.5832
1181.87	13.7132
1185.11	15.7826
1188.35	17.3794
1191.59	18.3785
1194.83	19.2259
1198.07	21.1212
1201.3	23.532
1204.53	25.9611
1207.77	27.5113
1211	30.7459
1214.23	33.8525
1217.46	37.7901
1220.69	40.9828
1223.91	42.4689
1227.14	44.0257
1230.36	46.6381
1233.59	49.2391
1236.81	49.8996
1240.03	52.0643
1243.25	54.3724
1246.46	56.3791
1249.68	58.557
1252.9	59.7767
1256.11	61.3377
1259.32	62.0929
1262.54	62.8516
1265.75	63.8822
1268.96	64.292
1272.16	65.1658
1275.37	65.9983
1278.57	68.8355
1281.78	72.111
1284.98	73.7837
1288.18	74.1138
1291.38	75.4303
1294.58	75.6184
1297.78	74.6207
1300.98	74.4486
1304.17	75.5895
1307.37	77.0784
1310.56	77.4513
1313.76	77.5739
1316.95	77.4529
1320.14	76.5983
1323.32	76.8424
1326.51	76.415
1329.7	73.2379
1332.88	70.0586
1336.07	66.904
1339.25	64.0651
1342.43	60.6685
1345.61	58.846
1348.79	57.0783
1351.96	54.3101
1355.14	52.9546
1358.31	50.4409
1361.49	47.1444
1364.66	44.8128
1367.83	41.5051
1371	39.7043
1374.17	38.8296
1377.34	38.2282
1380.5	37.1584
1383.67	37.2678
1386.83	37.0807
1390	35.2669
1393.16	33.9751
1396.32	33.3678
1399.48	33.9535
1402.64	33.3991
1405.79	33.3333
1408.95	32.7159
1412.1	33.0167
1415.26	35.85
1418.41	38.783
1421.56	41.6324
1424.71	45.8207
1427.86	49.534
1431	54.9124
1434.15	60.8329
1437.29	64.9069
1440.44	68.9199
1443.58	70.1618
1446.72	72.2432
1449.86	72.7031
1453	72.1712
1456.14	69.408
1459.27	66.472
1462.41	61.5649
1465.54	54.6738
1468.67	46.9208
1471.81	41.0259
1474.94	35.069
1478.07	29.0732
1481.19	23.8826
1484.32	18.1443
1487.45	13.6314
1490.57	9.95839
1493.69	8.13255
1496.82	6.16515
1499.94	4.91927
1503.06	5.62521
1506.17	6.34349
1509.29	7.6617
1512.41	9.02379
1515.52	9.28749
1518.64	9.942
1521.75	11.3773
1524.86	13.637
1527.97	15.3149
1531.08	15.4116
1534.19	16.4136
1537.29	16.9515
1540.4	17.5477
1543.5	19.867
1546.61	23.9785
1549.71	27.4874
1552.81	30.165
1555.91	33.3928
1559.01	35.5301
1562.11	37.6053
1565.2	39.876
1568.29	42.3617
1571.39	45.8144
1574.48	46.7362
1577.57	49.1197
1580.66	51.5059
1583.75	53.03
1586.84	55.6633
1589.93	56.8873
1593.01	57.419
1596.1	59.2096
1599.18	59.2075
1602.26	59.6123
1605.34	59.2353
1608.42	58.6913
1611.5	60.2833
1614.58	61.078
1617.65	63.2383
1620.73	65.6536
1623.8	68.0661
1626.87	69.0639
1629.95	72.273
1633.02	74.6514
1636.09	77.9138
1639.15	81.2857
1642.22	84.6082
1645.29	88.4957
1648.35	91.8594
1651.42	94.2781
1654.48	96.06
1657.54	96.0072
1660.6	95.0696
1663.66	94.1148
1666.72	90.4104
1669.77	86.1897
1672.83	81.6448
1675.88	76.0845
1678.93	69.4744
1681.99	63.089
1685.04	57.1289
1688.09	49.4691
1691.13	43.3752
1694.18	37.5077
1697.23	31.0189
1700.27	25.7698
1703.32	19.8914
1706.36	16.2074
1709.4	12.6866
1712.44	9.75081
1715.48	6.97754
1718.52	5.82888
1721.56	6.13482
1724.59	6.98211
1727.63	5.75859
1730.66	4.60887
1733.69	3.75451
1736.72	3.92905
1739.75	3.96791
1742.78	4.23598
1745.81	5.27504
1748.84	4.58793
1751.86	3.15206
1754.89	2.8403
1757.91	2.323
1760.93	2.23181
1763.95	2.32125
1766.97	2.6602
1769.99	1.65063
1773.01	0.227776
1776.03	0.451101
1779.04	-0.249236
1782.06	-0.454715
1785.07	-0.557649
1788.08	-0.314914
1791.09	0.0443366
1794.1	1.29119
1797.11	2.2481
1800.12	1.91766
1803.12	1.069
1806.13	1.57955
1809.13	1.84856
1812.14	2.87009
1815.14	2.6476
1818.14	3.14492
1821.14	3.17951
1824.14	2.63342
1827.13	2.09866
1830.13	2.35331
1833.12	1.96005
1836.12	2.25019
1839.11	2.67333
1842.1	2.07476
1845.09	1.59525
1848.08	1.49254
1851.07	2.25489
1854.06	2.36701
1857.04	2.92502
1860.03	3.66308
1863.01	5.14059
1866	6.03051
1868.98	6.48571
1871.96	5.60949
1874.94	5.33228
1877.92	5.64839
1880.89	6.62425
1882.48	7.12694
1885.47	7.96286
1888.46	8.24825
1891.44	8.87885
1894.43	8.95556
1897.41	8.35608
1900.4	7.81926
1903.38	7.24295
1906.36	7.6182
1909.34	7.55802
1912.32	7.34055
1915.29	7.06281
1918.27	6.52654
1921.25	6.84543
1924.22	7.39901
1927.2	7.29262
1930.17	7.82936
1933.14	7.27086
1936.11	7.49913
1939.08	7.59753
1942.05	6.5409
1945.01	6.55708
1947.98	6.48874
1950.94	6.78017
1953.91	6.11229
1956.87	6.43941
1959.83	6.14486
1962.79	5.41463
1965.75	5.56745
1968.71	5.28766
1971.67	5.03592
1974.62	5.06056
1977.58	5.46562
1980.53	6.0555
1983.48	6.17936
1986.43	5.85794
1989.38	6.10011
1992.33	7.12561
1995.28	8.57867
1998.23	8.25509
2001.18	8.86992
2004.12	10.3316
2007.06	11.5024
2010.01	12.7145
2012.95	13.5706
2015.89	14.736
2018.83	15.1233
2021.77	15.5913
2024.71	15.8688
2027.64	16.221
2030.58	15.9916
2033.51	16.1518
2036.45	16.771
2039.38	16.412
2042.31	16.9277
2045.24	17.6829
2048.17	18.1219
2051.1	17.9444
2054.02	18.5225
2056.95	19.1471
2059.87	18.773
2062.8	19.3435
2065.72	20.3176
2068.64	20.4427
2071.56	20.3827
2074.48	22.0122
2077.4	22.507
2080.31	22.9664
2083.23	24.201
2086.14	25.7871
2089.06	26.7717
2091.97	27.6936
2094.88	28.823
2097.79	31.0162
2100.7	32.6631
2103.61	35.0097
2106.52	35.9357
2109.43	37.81
2112.33	39.7444
2115.24	42.3266
2118.14	44.6287
2121.04	47.9072
2123.94	50.2879
2126.84	52.9502
2129.74	55.2353
2132.64	59.3574
2135.54	63.5914
2138.43	67.0071
2141.33	69.732
2144.22	73.178
2147.11	76.8381
2150.01	79.6297
2152.9	83.7704
2155.79	87.5245
2158.67	91.2354
2161.56	93.3135
2164.45	95.0305
2167.33	98.2756
2170.22	99.9114
2173.1	100.047
2175.98	98.7602
2178.86	97.672
2181.74	95.9152
2184.62	93.1382
2187.5	92.3419
2190.38	89.8202
2193.25	86.4219
2196.13	82.9777
2199	79.3099
2201.88	75.2586
2204.75	72.2351
2207.62	67.7646
2210.49	64.497
2213.36	60.342
2216.22	57.5296
2219.09	54.8514
2221.96	51.7213
2224.82	49.1967
2227.68	46.0508
2230.55	42.9313
2233.41	39.9268
2236.27	37.0466
2239.12	35.3534
2241.98	32.9207
2244.84	31.1779
2247.7	30.0424
2250.55	29.0514
2253.41	27.9282
2256.26	26.967
2259.11	27.1664
2261.96	25.9942
2264.81	25.1176
2267.66	23.9665
2270.51	23.7397
2273.35	24.2653
2276.2	24.5002
2279.04	23.7756
2281.89	22.5399
2284.73	21.8189
2287.57	21.7042
2290.41	20.3567
2293.25	18.8402
2296.09	17.9428
2298.93	17.1858
2301.76	16.8641
2304.6	16.4815
2307.44	16.9755
2310.27	17.2297
2313.1	18.1361
2315.93	17.9492
2318.76	17.4352
2321.59	16.8463
2324.42	15.6814
2327.25	16.0759
2330.07	15.4022
2332.9	14.911
2335.72	13.8642
2338.55	12.8169
2341.37	12.7363
2344.19	11.4635
2347.01	9.26173
2349.83	7.13885
2352.65	6.43761
2355.46	5.96177
2358.28	5.48514
2361.09	4.53233
2363.91	4.57729
2366.72	4.89088
2369.53	5.16416
2372.34	5.43414
2375.15	6.45956
2377.96	7.79285
2380.77	7.86945
2383.58	7.51355
2386.38	6.53601
2389.19	6.82845
2391.99	6.83224
2394.8	7.43064
2397.6	7.9927
2400.4	7.92342
2403.2	8.70423
2406	8.92915
2408.79	9.14862
2411.59	9.56433
2414.39	8.68116
2417.18	8.53682
2419.98	9.38125
2422.77	9.41438
2425.56	8.38572
2428.35	7.63592
2431.14	7.10149
2433.93	6.35559
2436.72	6.41185
2439.5	6.31401
2442.29	6.39984
2445.07	6.32454
2447.86	5.70262
2450.64	5.41345
2453.42	4.93276
2456.2	4.53432
2458.98	3.88106
2461.76	3.79622
2464.54	3.79737
2467.32	4.28307
2470.09	4.23315
2472.87	4.64917
2475.64	4.33011
2478.41	3.67146
2481.18	3.01489
2483.95	2.48573
2486.72	3.21224
2489.49	2.86116
2492.26	1.74474
2495.03	1.0002
2497.79	0.780583
2500.56	0.63041
2503.32	1.33353
2506.09	1.67459
2508.85	1.66228
2511.61	1.99749
2514.37	1.42423
2517.13	1.47064
2519.89	0.775073
2522.64	0.468049
2525.4	-0.291562
2528.15	0.0610266
2530.91	-0.164468
2533.66	0.422284
2536.41	0.0387832
2539.16	0.168239
2541.91	0.205484
2544.66	0.588336
2547.41	1.12306
2550.16	1.18105
2552.9	2.68818
2555.65	3.3419
2558.39	3.53597
2561.13	3.68378
2563.88	3.71728
2566.62	3.21023
2569.36	3.10175
2572.1	3.07509
2574.84	2.90907
2577.57	2.23792
2580.31	0.969952
2583.05	0.763852
2585.78	0.929986
2588.51	-0.158435
2591.24	-0.911199
2593.98	-0.887308
2596.71	-1.27925
2599.44	-1.57493
2602.16	-1.73391
2604.89	-1.77176
2607.62	-1.48319
2610.34	-0.688832
2613.07	-0.371954
2615.79	-0.261642
2618.52	0.338501
2621.24	1.70323
2623.96	1.94236
2626.68	1.52268
2629.4	1.76962
2632.11	1.6032
2634.83	2.15122
2637.55	3.25311
2640.26	2.57661
2642.98	2.77059
2645.69	3.12291
2648.4	3.68315
2651.11	4.02777
2653.82	3.59378
2656.53	3.58278
2659.24	3.24704
2661.95	3.08316
2664.65	2.41386
2667.36	2.94741
2670.06	3.14274
2672.76	2.38217
2675.47	1.75424
2678.17	1.53676
2680.87	2.32649
2683.57	2.60802
2686.27	2.52929
2688.97	2.91553
2691.66	2.8894
2694.36	2.79505
2697.05	4.44355
2699.75	5.28232
2702.44	6.45
2705.13	7.69241
2707.82	8.62368
2710.51	10.1792
2713.2	11.1285
2715.89	11.7849
2718.57	11.7925
2721.26	12.0652
2723.95	12.6263
2726.63	11.7574
2729.31	11.7775
2732	12.277
2734.68	11.7117
2737.36	10.792
2740.04	10.6569
2742.72	10.404
2745.39	9.97905
2748.07	9.75559
2750.75	8.89439
2753.42	8.50682
2756.09	8.86842
2758.77	8.94321
2761.44	8.51375
2764.11	8.32015
2766.78	7.68436
2769.45	7.9469
2772.12	6.82543
2774.78	5.81758
2777.45	4.94338
2780.12	5.41579
2782.78	4.75364
2785.44	4.5975
2788.11	4.41339
2790.77	4.75122
2793.43	4.90854
2796.09	5.45354
2798.75	4.95102
2801.4	5.23629
2804.06	6.41673
2806.72	6.07769
2809.37	6.41653
2812.03	6.71477
2814.68	7.13686
2817.33	8.51735
2819.98	10.761
2822.63	13.0871
2825.28	16.3295
2827.93	19.8873
2830.58	25.2797
2833.23	30.3154
2835.87	35.9496
2838.52	41.7744
2841.16	49.0621
2843.8	57.6011
2846.44	66.4213
2849.08	75.7991
2851.73	86.8836
2854.36	96.8941
2857	106.475
2859.64	116.33
2862.28	125.024
2864.91	133.062
2867.55	140.382
2870.18	146.166
2872.81	152.096
2875.44	156.496
2878.07	161.001
2880.7	165.03
2883.33	169.703
2885.96	173.818
2888.59	178.98
2891.21	184.373
2893.84	189.393
2896.46	194.905
2899.09	202.041
2901.71	209.372
2904.33	218.014
2906.95	229.854
2909.57	242.208
2912.19	256.851
2914.81	271.235
2917.43	283.776
2920.04	295.335
2922.66	304.383
2925.27	312.744
2927.88	318.391
2930.5	321.321
2933.11	322.232
2935.72	320.417
2938.33	315.655
2940.94	308.757
2943.54	301.856
2946.15	292.605
2948.76	281.068
2951.36	270.161
2953.97	257.818
2956.57	243.68
2959.17	230.953
2961.77	219.293
2964.37	207.803
2966.97	196.703
2969.57	187.229
2972.17	179.041
2974.77	170.394
2977.36	161.826
2979.96	152.081
2982.55	142.913
2985.15	133.293
2987.74	123.19
2990.33	113.332
2992.92	103.976
2995.51	94.9524
2998.1	85.9314
3000.69	77.2809
3003.27	69.2318
3005.86	62.1729
3008.44	56.056
3011.03	50.0319
3013.61	44.6081
3016.19	39.8917
3018.78	35.8251
3021.36	33.7327
3023.94	32.3784
3026.51	31.5144
3029.09	30.744
3031.67	31.5535
3034.24	31.982
3036.82	33.2791
3039.39	34.1056
3041.97	35.1852
3044.54	37.2158
3047.11	38.0797
3049.68	39.3176
3052.25	39.51
3054.82	39.2145
3057.39	38.6431
3059.96	37.8693
3062.52	37.0394
3065.09	35.1211
3067.65	33.1869
3070.22	31.3976
3072.78	28.995
3075.34	26.6279
3077.9	23.979
3080.46	20.8085
3083.02	18.5781
3085.58	16.5106
3088.14	13.7891
3090.69	12.5814
3093.25	10.7923
3095.8	9.26061
3098.36	7.31362
3100.91	6.44286
3103.46	5.54414
3106.01	4.01459
3108.56	2.48645
3111.11	1.97188
3113.66	1.1051
3116.21	0.0574382
3118.76	-0.387271
3121.3	-0.328519
3123.85	-0.435185
3126.39	-0.141608
3128.93	-0.090356
3131.48	0.270212
3134.02	0.536688
3136.56	1.47008
3139.1	2.26681
3141.64	2.97621
3144.17	3.88852
3146.71	4.18545
3149.25	4.46242