File: data/Raman/poly_smoothed/Thy_40_11_20_1x_45s_532 nm_x100_100%_600 gr_mm_01.txt
#Acq. time (s)=	45
#Accumulations=	2
#Range (cm-¹)=	200...3150
#Windows=	2
#Auto scanning=	Off
#Autofocus=	Off
#Macrospot=	Off
#AutoExposure=	Off
#Spike filter=	Multiple accum.
#Delay time (s)=	0
#Binning=	1
#Readout mode=	Signal
#DeNoise=	Off
#ICS correction=	On
#Dark correction=	Off
#Inst. Process=	Off
#Detector Gain=	Best Dynamic Range
#Detector ADC=	20 kHz
#Detector temperature (°C)=	-69.85
#Instrument=	LabRAM HR Evol
#Detector=	Synapse
#Objective=	x100
#Grating=	600 gr/mm
#ND Filter=	100%
#Laser (nm)=	532
#Hole=	100.021
#Range=	Auto
#Laser Pol.=	No
#Raman. Pol.=	No
#Laser Pol. (°)=	-0.0007625
#Raman Pol. (°)=	89.9995
#Collection=	Microscope
#StageXY=	Marzhauser
#StageZ=	Marzhauser
#X (µm)=	1979.8
#Y (µm)=	-43.5
#Z (µm)=	425.1
#Full time(mm:ss)=	3:18
#Project=
#Sample=
#Site=
#Title=	Thy_40_11_20_2x_45s_532 nm_x100_100%_600 gr_mm
#Remark=
#Date=	05.07.2022 11:17
#Acquired=	05.07.2022 11:17:20
#Base:Fit=	10.08.2022 10:01:35
#Base:Sub=	10.08.2022 10:01:52
#Filter:Polynom=	16.08.2022 10:21:53
#AxisType[0]=Intens
#AxisUnit[0]=Cnt
#AxisType[1]=Spectr
#AxisUnit[1]=1/cm
200.43	2.68798
204.059	8.6452
207.688	11.6879
211.314	13.09
214.941	13.2419
218.564	12.9527
222.186	12.4548
225.809	13.178
229.428	13.1532
233.045	12.1964
236.663	11.7927
240.278	11.8546
243.891	12.4075
247.503	11.934
251.116	10.491
254.725	9.16282
258.333	10.605
261.939	11.0589
265.544	11.0812
269.148	11.6368
272.75	12.4325
276.351	13.034
279.95	13.5331
283.548	14.3742
287.144	15.6408
290.739	15.8541
294.333	14.6873
297.925	13.8814
301.514	14.2208
305.104	14.1142
308.692	15.9994
312.279	16.6039
315.862	17.2592
319.446	16.109
323.029	16.0848
326.608	16.1276
330.188	16.1519
333.766	16.6678
337.341	15.5238
340.917	14.2001
344.489	13.2156
348.062	14.2471
351.631	13.9969
355.201	14.3611
358.768	14.7972
362.333	14.9259
365.899	15.9437
369.462	16.699
373.023	15.9927
376.585	15.2763
380.143	13.6535
383.7	13.2627
387.256	11.9259
390.812	13.367
394.365	12.7691
397.916	13.3437
401.467	10.9102
405.015	9.38469
408.563	7.51095
412.109	6.47804
415.654	6.31671
419.197	6.00268
422.739	4.7529
426.279	3.75137
429.819	3.71985
433.356	4.70025
436.891	3.5783
440.426	4.44964
443.96	5.96199
447.492	6.32351
451.021	7.23916
454.551	8.18464
458.079	8.30884
461.604	9.95514
465.13	10.7208
468.654	10.8813
472.175	12.1809
475.696	14.5115
479.215	16.3681
482.733	16.9761
486.249	16.507
489.765	15.6168
493.278	17.1348
496.789	18.1379
500.301	19.9603
503.81	19.4291
507.317	19.8938
510.825	19.1803
514.33	18.2985
517.833	18.5312
521.335	18.1992
524.836	18.9253
528.335	19.488
531.835	18.537
535.332	18.142
538.827	17.5677
542.321	17.8609
545.814	17.8829
549.305	17.2418
552.795	17.0939
556.282	17.632
559.769	17.8818
563.255	17.3123
566.739	17.219
570.223	13.7281
573.705	14.4264
577.183	14.1887
580.663	15.0517
584.141	13.8345
587.615	13.2483
591.09	11.6512
594.564	11.0544
598.035	8.76481
601.506	9.45622
604.974	8.87559
608.443	8.89643
611.908	8.96825
615.374	8.07456
618.837	8.95342
622.3	8.30847
625.761	8.57732
629.219	8.59478
632.677	9.25049
636.135	9.99139
639.59	10.4312
643.043	10.3526
646.495	10.1817
649.948	11.4051
653.398	11.1307
656.846	13.5949
660.293	14.7219
663.738	16.937
667.183	17.003
670.626	18.5894
674.067	18.8995
677.508	19.8731
680.947	19.965
684.385	21.3503
687.821	23.5847
691.254	25.671
694.688	28.3016
698.121	30.8385
701.552	32.1488
704.98	31.5848
708.409	33.0787
711.836	36.572
715.26	37.821
718.685	39.2293
722.108	41.3622
725.528	42.3514
728.949	45.6558
732.367	48.0951
735.785	49.6369
739.2	51.226
742.614	52.7755
746.028	53.7568
749.439	54.551
752.849	57.0332
756.26	58.9933
759.667	60.6071
763.073	62.9566
766.477	65.7578
769.883	68.6999
773.285	71.4028
776.686	72.5982
780.085	74.3689
783.484	74.7158
786.881	75.3916
790.276	77.8196
793.671	80.2272
797.064	81.3263
800.456	81.9169
803.846	83.5379
807.234	84.9746
810.622	85.1237
814.008	85.0341
817.394	83.9225
820.778	82.6527
824.159	81.798
827.541	80.6279
830.921	81.0657
834.298	78.9979
837.676	77.1469
841.051	77.2516
844.426	75.4886
847.798	74.2304
851.171	70.3828
854.54	67.5431
857.911	65.0538
861.278	62.6085
864.645	60.703
868.01	60.3742
871.373	58.9165
874.735	58.1795
878.097	55.3172
881.457	53.6218
884.815	53.0133
888.172	53.9144
891.528	54.4246
894.882	53.2564
898.237	51.9508
901.589	52.0367
904.94	52.2438
908.289	52.852
911.635	54.1206
914.982	54.8918
918.328	54.3246
921.672	53.9354
925.015	53.776
928.357	51.7148
931.698	49.9723
935.035	48.8542
938.373	48.9939
941.71	47.7148
945.044	46.4099
948.378	45.4047
951.709	45.1922
955.041	42.4114
958.372	41.0938
961.699	39.4831
965.027	38.7465
968.352	38.4697
971.676	37.8177
975	36.8001
978.322	34.354
981.642	34.5386
984.962	36.4251
988.28	36.3742
991.596	38.4163
994.911	37.2323
998.227	36.0754
1001.54	32.9757
1004.85	32.4219
1008.16	32.3341
1011.47	30.7338
1014.78	29.1709
1018.08	29.2774
1021.39	28.9568
1024.69	29.2274
1028	27.6993
1031.3	29.0348
1034.6	28.0068
1037.9	27.1254
1041.19	27.007
1044.49	26.6518
1047.78	26.7795
1051.08	27.508
1054.37	28.1569
1057.66	27.6605
1060.95	28.5397
1064.24	28.5715
1067.53	27.5824
1070.81	26.6485
1074.1	25.011
1077.38	23.2136
1080.66	21.5943
1083.94	20.146
1087.22	18.2339
1090.5	15.922
1093.78	15.9845
1097.05	14.5366
1100.33	14.4308
1103.6	13.9672
1106.87	13.9653
1110.14	13.4226
1113.41	13.5849
1116.68	11.7388
1119.95	11.6854
1123.21	12.5148
1126.48	13.5327
1129.74	13.1431
1133	12.3218
1136.26	12.3971
1139.52	11.5831
1142.78	11.4786
1146.04	10.2935
1149.29	9.3774
1152.55	8.95134
1155.8	8.47342
1159.05	6.70425
1162.3	6.45082
1165.55	5.02552
1168.8	4.90313
1172.05	5.37345
1175.29	5.28214
1178.54	6.06376
1181.78	6.51226
1185.02	7.59886
1188.26	7.79003
1191.5	8.01521
1194.74	9.19712
1197.97	8.93591
1201.21	12.9013
1204.44	14.5605
1207.68	15.6105
1210.91	16.3157
1214.14	18.1122
1217.37	21.069
1220.59	23.231
1223.82	25.3027
1227.05	27.6337
1230.27	30.5244
1233.49	31.9653
1236.72	34.2967
1239.94	36.5694
1243.16	38.5502
1246.37	40.3667
1249.59	40.8925
1252.8	41.1614
1256.02	42.4942
1259.23	45.0501
1262.44	44.4502
1265.66	45.0845
1268.86	46.4366
1272.07	49.1613
1275.28	48.9382
1278.48	50.6328
1281.69	52.2843
1284.89	54.3319
1288.09	54.7255
1291.29	55.135
1294.49	55.2864
1297.69	57.4148
1300.89	57.9476
1304.08	58.3713
1307.28	60.394
1310.47	60.2161
1313.66	63.402
1316.85	63.8638
1320.04	64.9351
1323.23	64.3418
1326.42	64.4218
1329.61	62.2181
1332.79	61.5776
1335.97	60.8222
1339.16	58.5831
1342.34	56.1743
1345.52	55.4029
1348.7	54.535
1351.87	51.7707
1355.05	49.274
1358.22	46.818
1361.4	44.686
1364.57	40.4446
1367.74	36.3623
1370.91	35.0736
1374.08	33.8237
1377.25	30.8981
1380.41	29.0212
1383.58	28.9666
1386.74	28.4624
1389.91	28.8329
1393.07	28.5214
1396.23	27.6873
1399.39	26.3332
1402.55	25.3408
1405.7	24.0557
1408.86	24.9811
1412.01	25.2311
1415.17	27.477
1418.32	30.9249
1421.47	33.3804
1424.62	36.1852
1427.77	39.7639
1430.91	43.6083
1434.06	47.0054
1437.2	51.2222
1440.35	53.5494
1443.49	56.803
1446.63	58.1753
1449.77	58.1562
1452.91	58.304
1456.05	57.5469
1459.18	56.1742
1462.32	53.151
1465.45	48.3792
1468.59	44.0709
1471.72	39.8245
1474.85	34.8708
1477.98	29.1814
1481.1	24.7783
1484.23	20.9001
1487.36	17.0273
1490.48	13.8098
1493.61	13.4233
1496.73	9.99585
1499.85	9.41647
1502.97	8.87406
1506.09	8.80151
1509.2	7.80558
1512.32	8.27203
1515.43	9.18637
1518.55	9.23608
1521.66	9.08727
1524.77	10.3611
1527.88	11.6961
1530.99	13.521
1534.1	14.1195
1537.21	15.3603
1540.31	15.9905
1543.42	18.3063
1546.52	21.9097
1549.62	23.387
1552.72	24.6028
1555.82	25.8785
1558.92	29.3129
1562.02	31.0333
1565.11	33.7266
1568.21	36.7837
1571.3	38.3432
1574.39	41.151
1577.49	43.8231
1580.57	44.6749
1583.66	46.2444
1586.75	47.1577
1589.84	49.1493
1592.92	49.5152
1596.01	50.1795
1599.09	49.9301
1602.17	49.7467
1605.25	48.1212
1608.33	48.4395
1611.41	47.6652
1614.49	46.315
1617.57	46.8169
1620.64	46.9058
1623.72	45.6259
1626.79	45.6641
1629.86	46.1803
1632.93	47.5762
1636	49.1447
1639.07	49.088
1642.13	51.1906
1645.2	51.9834
1648.26	54.0508
1651.33	55.953
1654.39	56.6348
1657.45	56.8889
1660.51	57.1819
1663.57	58.0212
1666.63	57.2928
1669.68	55.5508
1672.74	52.8912
1675.79	50.7192
1678.85	45.4429
1681.9	42.4243
1684.95	38.1181
1688	33.2411
1691.05	29.0205
1694.09	25.9397
1697.14	22.8523
1700.18	18.91
1703.23	15.5513
1706.27	12.9527
1709.31	10.1781
1712.35	7.89677
1715.39	6.88422
1718.43	5.25573
1721.47	4.11032
1724.5	5.60091
1727.54	4.82682
1730.57	5.48185
1733.61	6.37169
1736.64	7.08955
1739.67	7.46528
1742.7	7.33392
1745.72	6.71276
1748.75	7.13379
1751.77	7.05004
1754.8	6.50567
1757.82	6.37049
1760.84	6.49342
1763.87	6.58227
1766.89	6.04227
1769.91	5.66815
1772.92	4.65386
1775.94	3.50865
1778.95	2.80067
1781.97	1.70079
1784.98	1.72662
1787.99	1.71342
1791.01	1.34601
1794.01	0.670921
1797.02	0.854272
1800.03	0.195382
1803.04	0.0036548
1806.04	0.294525
1809.05	-0.761609
1812.05	-1.1658
1815.05	-0.681972
1818.05	-0.193092
1821.05	1.15261
1824.05	0.993052
1827.05	0.977839
1830.04	1.7368
1833.04	1.81822
1836.03	1.7741
1839.03	2.05942
1842.02	1.17992
1845.01	0.861709
1848	1.50949
1850.99	0.796679
1853.97	0.963379
1856.96	1.35641
1859.94	1.71473
1862.93	1.47572
1865.91	0.657867
1868.89	1.24091
1871.87	1.57847
1874.85	1.07047
1877.83	1.16268
1880.81	0.856983
1882.57	1.15217
1885.56	2.39309
1888.55	3.67474
1891.54	3.71966
1894.52	3.33967
1897.51	4.30117
1900.49	4.51828
1903.47	4.76535
1906.45	5.33054
1909.43	5.80116
1912.41	6.10016
1915.39	6.08011
1918.37	6.0594
1921.34	5.5494
1924.32	5.47978
1927.29	4.55288
1930.26	4.87292
1933.23	4.96551
1936.2	4.68397
1939.17	6.00385
1942.14	6.08964
1945.11	5.20836
1948.07	5.20679
1951.04	3.91574
1954	4.3249
1956.96	4.83477
1959.93	5.19631
1962.89	4.78632
1965.85	4.26852
1968.8	3.96491
1971.76	3.9228
1974.72	4.30718
1977.67	4.51983
1980.63	4.88955
1983.58	4.19953
1986.53	3.61538
1989.48	3.31539
1992.43	3.45776
1995.38	3.53465
1998.32	3.40965
2001.27	3.89981
2004.22	5.36903
2007.16	5.68599
2010.1	5.65844
2013.04	6.2927
2015.98	5.31613
2018.92	4.85146
2021.86	4.10316
2024.8	3.8638
2027.74	3.71803
2030.67	3.80036
2033.61	3.83878
2036.54	3.13978
2039.47	4.29422
2042.4	4.45296
2045.33	5.05774
2048.26	5.54329
2051.19	5.62028
2054.12	5.55966
2057.04	5.94156
2059.97	7.19998
2062.89	8.12488
2065.81	8.7025
2068.73	9.73515
2071.65	10.8804
2074.57	11.6922
2077.49	13.1256
2080.41	13.7532
2083.32	15.0688
2086.24	15.1401
2089.15	15.6117
2092.07	16.7093
2094.98	18.1763
2097.89	19.4194
2100.8	21.082
2103.71	23.1461
2106.61	24.7099
2109.52	27.1506
2112.43	28.736
2115.33	31.5623
2118.23	32.7275
2121.13	35.0763
2124.04	38.258
2126.94	41.6019
2129.83	44.5717
2132.73	47.5565
2135.63	49.6217
2138.53	52.0784
2141.42	54.336
2144.31	57.1431
2147.21	60.2951
2150.1	62.7446
2152.99	64.5059
2155.88	66.8713
2158.77	68.482
2161.65	70.9006
2164.54	72.4339
2167.43	73.1938
2170.31	73.9109
2173.19	74.1272
2176.07	74.3332
2178.96	74.8183
2181.84	73.2635
2184.72	72.1898
2187.59	69.9982
2190.47	68.8856
2193.35	67.187
2196.22	65.9553
2199.09	63.5229
2201.97	60.2123
2204.84	56.2941
2207.71	51.719
2210.58	48.1475
2213.45	44.6558
2216.31	41.462
2219.18	39.0314
2222.05	37.4755
2224.91	36.8825
2227.78	35.1493
2230.64	33.1335
2233.5	31.4299
2236.36	30.2275
2239.22	28.8713
2242.08	27.9772
2244.93	26.8163
2247.79	26.2263
2250.64	25.1087
2253.5	24.0894
2256.35	23.3261
2259.2	22.3344
2262.05	22.0304
2264.9	20.6977
2267.75	20.3137
2270.6	18.3515
2273.45	16.5749
2276.29	14.0268
2279.14	13.2133
2281.98	11.7948
2284.82	11.2476
2287.66	11.1437
2290.5	11.1773
2293.34	10.2508
2296.18	9.1116
2299.02	7.99628
2301.86	7.91784
2304.69	7.76798
2307.53	7.90068
2310.36	8.82583
2313.19	9.40707
2316.02	9.18839
2318.85	9.23657
2321.68	8.76733
2324.51	8.75969
2327.34	8.52836
2330.16	9.34697
2332.99	9.56144
2335.81	9.50161
2338.64	9.20565
2341.46	9.38987
2344.28	8.75224
2347.1	8.07038
2349.92	7.24624
2352.74	6.73419
2355.55	6.3417
2358.37	5.10727
2361.19	3.7117
2364	2.91764
2366.81	2.58589
2369.62	2.03048
2372.44	1.64642
2375.24	1.44806
2378.05	1.55977
2380.86	0.951368
2383.67	-1.08714
2386.47	-1.41045
2389.28	-1.89228
2392.08	-1.35288
2394.89	-0.782185
2397.69	-0.226649
2400.49	0.936815
2403.29	1.8958
2406.09	2.79417
2408.88	3.88298
2411.68	4.99984
2414.48	5.75979
2417.27	6.50448
2420.06	6.83675
2422.86	8.27178
2425.65	8.61665
2428.44	8.16769
2431.23	7.81352
2434.02	7.54619
2436.81	7.54329
2439.59	7.47786
2442.38	7.23382
2445.16	6.55384
2447.95	6.30155
2450.73	5.15512
2453.51	5.5025
2456.29	5.50935
2459.07	5.5569
2461.85	6.18899
2464.63	6.94265
2467.4	6.83141
2470.18	6.00043
2472.95	6.02076
2475.73	5.51676
2478.5	5.94873
2481.27	6.08515
2484.04	5.90643
2486.81	5.53627
2489.58	5.50709
2492.35	5.09624
2495.12	5.16228
2497.88	4.68818
2500.65	4.46638
2503.41	4.35585
2506.17	3.73965
2508.94	4.09375
2511.7	4.68128
2514.46	4.99584
2517.22	5.37674
2519.97	4.77183
2522.73	5.60241
2525.49	6.39319
2528.24	6.57189
2530.99	6.57429
2533.75	5.69359
2536.5	4.48526
2539.25	4.15888
2542	5.00329
2544.75	5.66984
2547.5	6.47189
2550.24	5.7838
2552.99	6.0451
2555.74	6.24354
2558.48	6.30435
2561.22	7.30242
2563.96	7.50125
2566.71	8.10097
2569.45	8.27197
2572.18	8.0693
2574.92	7.52752
2577.66	7.11936
2580.4	6.71642
2583.13	6.27702
2585.87	5.38494
2588.6	5.39886
2591.33	5.46281
2594.06	4.49538
2596.79	3.54073
2599.52	3.33217
2602.25	2.72066
2604.98	2.61147
2607.71	2.44282
2610.43	3.71272
2613.16	3.13171
2615.88	3.11782
2618.6	3.50735
2621.32	3.80731
2624.04	3.79746
2626.76	4.06683
2629.48	4.20371
2632.2	3.77021
2634.92	3.62528
2637.63	3.67328
2640.35	3.62705
2643.06	2.28482
2645.77	2.30313
2648.49	2.56321
2651.2	1.56163
2653.91	1.70173
2656.62	1.60851
2659.33	2.06756
2662.03	2.37036
2664.74	2.16124
2667.44	3.09168
2670.15	2.04259
2672.85	1.94634
2675.55	2.42466
2678.26	2.39953
2680.96	2.51089
2683.66	3.13632
2686.35	3.13908
2689.05	3.31687
2691.75	3.77011
2694.44	4.11711
2697.14	4.24008
2699.83	4.69995
2702.52	5.52083
2705.22	5.82897
2707.91	5.9074
2710.6	6.50931
2713.29	7.26823
2715.97	6.75835
2718.66	6.8361
2721.35	6.77399
2724.03	7.22544
2726.72	6.82855
2729.4	6.54511
2732.08	6.142
2734.76	4.76839
2737.44	3.71786
2740.12	3.19899
2742.8	2.69062
2745.48	2.75555
2748.16	3.33276
2750.83	3.06279
2753.51	2.1533
2756.18	1.60785
2758.85	1.42901
2761.53	1.0181
2764.2	1.14784
2766.87	1.0219
2769.54	1.70573
2772.2	2.15285
2774.87	2.2993
2777.54	1.88691
2780.2	2.01356
2782.87	2.24257
2785.53	2.35856
2788.19	2.84701
2790.85	2.22666
2793.51	1.54372
2796.17	1.55177
2798.83	0.533203
2801.49	-0.30483
2804.15	-0.150779
2806.8	0.342037
2809.46	0.721762
2812.11	0.607961
2814.76	-0.442553
2817.42	-1.21651
2820.07	-1.6021
2822.72	0.0374435
2825.37	1.038
2828.02	2.46483
2830.66	4.09774
2833.31	6.25077
2835.96	9.53424
2838.6	11.3191
2841.24	14.0075
2843.89	17.5861
2846.53	22.0285
2849.17	27.1442
2851.81	31.8314
2854.45	36.8009
2857.09	41.5144
2859.72	46.1184
2862.36	51.444
2865	56.8043
2867.63	61.5739
2870.26	66.338
2872.9	70.2034
2875.53	73.6446
2878.16	76.6091
2880.79	79.9864
2883.42	82.9633
2886.05	86.5662
2888.67	89.6198
2891.3	92.8178
2893.92	97.7082
2896.55	101.615
2899.17	104.689
2901.79	109.501
2904.42	114.978
2907.04	122.145
2909.66	129.584
2912.27	137.539
2914.89	144.056
2917.51	150.628
2920.13	157.402
2922.74	162.96
2925.35	167.793
2927.97	171.887
2930.58	174.036
2933.19	174.557
2935.8	175.409
2938.41	173.268
2941.02	170.811
2943.63	167.286
2946.24	162.211
2948.84	157.194
2951.45	151.751
2954.05	146.06
2956.65	140.399
2959.26	134.138
2961.86	126.458
2964.46	119.766
2967.06	114.929
2969.66	109.737
2972.25	103.494
2974.85	97.4146
2977.45	91.6561
2980.04	85.529
2982.64	79.3044
2985.23	73.5371
2987.82	67.6788
2990.41	61.0544
2993	54.4175
2995.59	47.3533
2998.18	41.806
3000.77	36.1331
3003.36	30.8823
3005.94	26.2671
3008.53	21.6249
3011.11	18.3217
3013.69	14.5738
3016.28	11.9994
3018.86	9.47726
3021.44	7.7331
3024.02	5.94825
3026.6	4.94591
3029.18	3.8916
3031.75	4.34366
3034.33	4.58566
3036.9	4.8442
3039.48	5.75554
3042.05	6.37262
3044.62	6.8217
3047.19	8.13778
3049.77	9.38592
3052.34	9.2305
3054.9	10.2814
3057.47	10.5436
3060.04	11.0154
3062.61	11.6729
3065.17	11.1613
3067.74	11.1055
3070.3	10.2674
3072.86	9.77931
3075.42	7.95941
3077.99	6.92372
3080.54	5.86785
3083.1	4.51553
3085.66	3.68994
3088.22	2.51637
3090.78	0.687109
3093.33	1.31813
3095.89	1.49021
3098.44	1.00674
3100.99	0.686101
3103.54	1.3092
3106.1	1.9649
3108.65	2.71706
3111.2	3.77488
3113.74	5.51663
3116.29	7.59792
3118.84	9.31918
3121.38	10.9434
3123.93	12.4235
3126.47	14.5097
3129.01	16.6943
3131.56	18.833
3134.1	20.0781
3136.64	21.2497
3139.18	22.6231
3141.72	24.314
3144.26	25.3644
3146.79	25.9491
3149.33	26.6062