File: data/Raman/poly_smoothed/Thy_20_09_09_1x_45s_532 nm_x100_100%_600 gr_mm_01.txt
#Acq. time (s)=	45
#Accumulations=	2
#Range (cm-¹)=	200...3150
#Windows=	2
#Auto scanning=	Off
#Autofocus=	Off
#Macrospot=	Off
#AutoExposure=	Off
#Spike filter=	Multiple accum.
#Delay time (s)=	0
#Binning=	1
#Readout mode=	Signal
#DeNoise=	Off
#ICS correction=	On
#Dark correction=	Off
#Inst. Process=	Off
#Detector Gain=	Best Dynamic Range
#Detector ADC=	20 kHz
#Detector temperature (°C)=	-69.85
#Instrument=	LabRAM HR Evol
#Detector=	Synapse
#Objective=	x100
#Grating=	600 gr/mm
#ND Filter=	100%
#Laser (nm)=	532
#Hole=	100.021
#Range=	Auto
#Laser Pol.=	No
#Raman. Pol.=	No
#Laser Pol. (°)=	-0.0007625
#Raman Pol. (°)=	89.9995
#Collection=	Microscope
#StageXY=	Marzhauser
#StageZ=	Marzhauser
#X (µm)=	-5898.3
#Y (µm)=	2841
#Z (µm)=	-223.25
#Full time(mm:ss)=	3:18
#Project=
#Sample=
#Site=
#Title=	Thy_20_09_09_2x_45s_532 nm_x100_100%_600 gr_mm
#Remark=
#Date=	29.06.2022 11:22
#Acquired=	29.06.2022 11:22:10
#Base:Fit=	10.08.2022 09:49:32
#Base:Fit=	10.08.2022 09:49:42
#Base:Fit=	10.08.2022 09:49:53
#Base:Fit=	10.08.2022 09:50:12
#Base:Fit=	10.08.2022 09:50:26
#Base:Fit=	10.08.2022 09:50:30
#Base:Fit=	10.08.2022 09:50:43
#Base:Fit=	10.08.2022 09:52:02
#Base:Fit=	10.08.2022 09:52:12
#Base:Sub=	10.08.2022 09:54:21
#Filter:Polynom=	16.08.2022 10:24:04
#AxisType[0]=Intens
#AxisUnit[0]=Cnt
#AxisType[1]=Spectr
#AxisUnit[1]=1/cm
200.523	4.25569
204.154	4.77092
207.781	4.28943
211.409	4.39005
215.034	4.56238
218.659	4.93032
222.281	4.65972
225.903	5.97727
229.522	5.6318
233.14	4.96872
236.756	6.36317
240.373	6.2276
243.986	5.91601
247.598	6.00907
251.208	6.60629
254.818	4.24988
258.427	2.7218
262.034	3.66732
265.638	3.10191
269.242	3.78354
272.844	4.37258
276.445	3.77095
280.044	3.96592
283.642	3.04227
287.238	4.23638
290.833	4.74089
294.425	6.26721
298.017	8.70665
301.608	9.0472
305.198	9.92739
308.786	10.9648
312.371	13.4271
315.956	13.2789
319.54	13.6762
323.122	14.1437
326.701	14.8551
330.281	15.186
333.857	16.1472
337.434	15.6804
341.008	14.4619
344.582	13.9143
348.153	14.2427
351.724	12.9577
355.292	13.6211
358.861	11.8669
362.426	9.00111
365.99	7.70361
369.555	5.63254
373.116	5.71753
376.676	5.10593
380.236	6.18471
383.793	4.59646
387.349	5.31429
390.903	3.47653
394.456	3.08028
398.007	3.2846
401.56	2.72358
405.108	2.76573
408.656	3.0482
412.202	4.41264
415.746	5.87805
419.29	7.35694
422.831	7.45504
426.37	7.19276
429.909	7.66865
433.447	9.34573
436.983	10.3165
440.519	9.84767
444.052	10.5528
447.583	10.7776
451.114	10.653
454.643	10.086
458.169	11.8895
461.696	13.3195
465.222	12.9108
468.744	13.1356
472.267	14.3185
475.787	13.4491
479.307	13.8278
482.823	14.402
486.341	13.4842
489.855	14.4148
493.37	14.141
496.881	13.4795
500.391	12.2645
503.902	12.9265
507.409	13.0096
510.915	12.6985
514.42	13.7743
517.925	14.7679
521.427	14.3308
524.928	13.863
528.427	13.708
531.925	13.9983
535.422	13.4126
538.917	11.3844
542.411	11.8288
545.903	10.9266
549.395	10.0854
552.884	8.80039
556.373	8.03986
559.86	8.42758
563.346	7.2466
566.831	5.57613
570.314	4.78902
573.794	2.89594
577.274	4.50957
580.754	3.6715
584.23	4.55402
587.706	5.2485
591.181	5.7429
594.653	6.97542
598.126	7.20683
601.595	8.74046
605.065	8.82017
608.532	8.15783
611.999	7.59936
615.463	8.34827
618.928	8.63599
622.389	7.61013
625.851	7.2256
629.31	6.65509
632.767	5.92243
636.223	6.56103
639.68	7.68293
643.134	9.53703
646.586	10.4911
650.037	10.693
653.486	12.0904
656.936	14.2844
660.383	16.5686
663.829	18.8094
667.273	21.1418
670.716	21.8462
674.158	23.9779
677.598	25.3352
681.035	25.262
684.473	26.9242
687.909	26.8898
691.344	26.9366
694.778	27.3716
698.211	28.6046
701.64	28.0458
705.07	28.0024
708.498	28.9964
711.924	29.9659
715.35	31.9097
718.774	33.6564
722.196	34.9028
725.618	37.4601
729.037	38.4848
732.456	39.3255
735.873	41.2909
739.289	43.9425
742.703	45.745
746.116	47.1501
749.529	47.3584
752.938	49.7699
756.347	51.8911
759.756	53.8087
763.162	54.6931
766.567	55.0253
769.97	56.1861
773.372	57.2855
776.773	59.9669
780.174	61.1643
783.573	61.2856
786.97	62.2812
790.365	65.8956
793.76	67.5936
797.153	69.8301
800.543	71.0914
803.933	72.4437
807.322	73.3794
810.71	74.3321
814.097	76.2744
817.483	77.8913
820.865	78.9303
824.248	77.6866
827.629	75.689
831.008	74.4541
834.387	74.6769
837.765	75.0924
841.139	72.7602
844.514	69.9924
847.886	68.2341
851.259	67.3923
854.629	66.141
857.997	64.9495
861.366	63.4739
864.732	60.2575
868.098	59.3529
871.461	58.6983
874.823	57.1078
878.184	55.2646
881.545	54.6475
884.903	53.9749
888.26	53.4739
891.616	53.4063
894.97	55.0209
898.323	55.8914
901.675	54.8373
905.026	53.4565
908.375	51.9139
911.723	51.8328
915.07	52.397
918.415	50.8896
921.76	48.8732
925.103	46.8073
928.443	47.5995
931.783	46.8794
935.123	46.9143
938.461	45.6756
941.796	43.484
945.131	39.9683
948.465	36.7938
951.797	34.9071
955.128	30.6139
958.457	27.2535
961.786	24.4494
965.113	24.9594
968.44	26.1211
971.763	28.1263
975.086	29.9786
978.409	30.926
981.729	30.0754
985.048	30.4387
988.367	30.9244
991.683	30.563
994.998	31.2667
998.312	30.6056
1001.62	30.1396
1004.94	29.9105
1008.25	31.9875
1011.56	33.0402
1014.86	32.7093
1018.17	31.8512
1021.48	29.2624
1024.78	25.7543
1028.08	25.3573
1031.38	23.4089
1034.68	22.4897
1037.98	21.5966
1041.28	20.8006
1044.57	21.0624
1047.87	22.5678
1051.16	22.5099
1054.45	22.8922
1057.75	21.9316
1061.04	21.059
1064.32	19.9289
1067.61	19.3867
1070.9	19.4862
1074.18	18.994
1077.47	16.9716
1080.75	16.0475
1084.03	17.405
1087.31	18.0055
1090.59	18.2752
1093.86	17.9423
1097.14	18.7355
1100.41	18.4167
1103.69	18.8284
1106.96	18.7021
1110.23	18.0139
1113.5	18.1534
1116.77	16.722
1120.03	15.0173
1123.3	13.379
1126.56	11.8333
1129.83	11.3405
1133.09	10.8069
1136.35	10.5167
1139.61	8.11592
1142.86	5.90556
1146.12	4.12794
1149.38	2.96528
1152.63	1.32534
1155.88	-0.649231
1159.14	-1.57322
1162.39	-0.245955
1165.63	0.645428
1168.88	0.747714
1172.13	2.87447
1175.38	4.26215
1178.62	6.64947
1181.86	7.49766
1185.1	9.48659
1188.34	11.8883
1191.58	14.3567
1194.82	16.4386
1198.06	18.2949
1201.29	20.5364
1204.53	23.8655
1207.76	25.6718
1210.99	27.6442
1214.22	30.405
1217.45	32.1564
1220.68	33.1356
1223.91	36.4292
1227.13	38.3299
1230.36	40.407
1233.58	41.8259
1236.8	43.5021
1240.02	46.2012
1243.24	47.5044
1246.46	48.9277
1249.67	50.1341
1252.89	51.4444
1256.1	52.4148
1259.32	53.7149
1262.53	53.7688
1265.74	54.8875
1268.95	55.613
1272.15	56.2888
1275.36	57.0966
1278.57	59.2365
1281.77	60.1303
1284.97	61.2841
1288.18	63.6178
1291.38	66.2827
1294.58	67.6223
1297.78	68.2851
1300.97	69.1546
1304.17	71.5001
1307.36	73.1779
1310.55	74.1276
1313.75	76.315
1316.94	79.2018
1320.13	80.232
1323.32	79.535
1326.5	78.8327
1329.69	78.2964
1332.87	77.0386
1336.06	74.9399
1339.24	73.4713
1342.42	69.1807
1345.6	67.1203
1348.78	64.8209
1351.96	60.7992
1355.13	57.6017
1358.31	55.2667
1361.48	52.3182
1364.65	48.7339
1367.82	46.7431
1370.99	44.2844
1374.16	40.9382
1377.33	37.9238
1380.5	37.1326
1383.66	37.7257
1386.83	36.0533
1389.99	35.8128
1393.15	33.886
1396.31	34.0015
1399.47	31.6658
1402.63	31.7761
1405.78	33.2678
1408.94	35.2937
1412.1	36.2175
1415.25	38.9248
1418.4	41.1663
1421.55	44.3715
1424.7	49.9222
1427.85	55.6722
1431	61.5858
1434.14	67.9024
1437.29	72.5774
1440.43	77.5834
1443.57	81.7488
1446.71	84.6314
1449.85	85.446
1452.99	83.8223
1456.13	82.5554
1459.26	79.271
1462.4	75.2485
1465.54	67.0238
1468.67	61.4317
1471.8	55.0079
1474.93	48.4555
1478.06	40.9034
1481.19	34.9711
1484.31	28.9806
1487.44	24.2263
1490.56	18.887
1493.69	15.5333
1496.81	13.0378
1499.93	11.1324
1503.05	12.1435
1506.17	11.376
1509.28	12.7759
1512.4	12.0762
1515.52	12.7921
1518.63	14.9885
1521.74	16.6395
1524.85	17.7367
1527.96	19.679
1531.07	20.7014
1534.18	21.9209
1537.29	24.1854
1540.39	25.8516
1543.5	28.5858
1546.6	31.1488
1549.7	34.183
1552.8	36.2321
1555.9	39.1798
1559	42.4416
1562.1	44.8656
1565.19	46.2111
1568.29	48.0166
1571.38	51.634
1574.47	52.772
1577.56	55.4162
1580.66	58.0171
1583.74	59.5273
1586.83	62.1311
1589.92	62.3189
1593.01	63.4741
1596.09	65.1983
1599.17	65.2369
1602.25	63.6279
1605.34	62.7749
1608.41	62.7302
1611.49	62.5839
1614.57	61.7206
1617.65	61.8589
1620.72	60.7148
1623.79	61.6706
1626.87	63.5801
1629.94	64.5384
1633.01	67.4081
1636.08	67.5674
1639.15	69.8774
1642.21	72.2668
1645.28	73.574
1648.34	75.4804
1651.41	77.5505
1654.47	78.9619
1657.53	79.6777
1660.59	78.3638
1663.65	76.1288
1666.71	73.7579
1669.76	72.2676
1672.82	66.9233
1675.87	61.7989
1678.93	56.7384
1681.98	52.2236
1685.03	46.7177
1688.08	40.3236
1691.13	34.7122
1694.17	28.4343
1697.22	23.1482
1700.27	19.1676
1703.31	14.9649
1706.35	12.1995
1709.39	9.73469
1712.43	7.1456
1715.47	6.14582
1718.51	4.83116
1721.55	3.53793
1724.58	4.46669
1727.62	3.37963
1730.65	3.06376
1733.68	2.40067
1736.72	2.85615
1739.74	2.21458
1742.77	3.66595
1745.8	3.07362
1748.83	3.48788
1751.85	4.05609
1754.88	4.00961
1757.9	4.18657
1760.92	4.03472
1763.95	4.2089
1766.96	3.59883
1769.98	3.15477
1773	3.47851
1776.02	4.15893
1779.03	4.19597
1782.05	4.58502
1785.06	5.04737
1788.07	4.78038
1791.08	5.08326
1794.09	4.6336
1797.1	5.01454
1800.11	4.90106
1803.12	3.74316
1806.12	2.83228
1809.12	2.86557
1812.13	1.68111
1815.13	1.33256
1818.13	1.53731
1821.13	2.61626
1824.13	3.03609
1827.13	2.69848
1830.12	2.6349
1833.12	2.88787
1836.11	3.2317
1839.1	3.75642
1842.09	4.60643
1845.09	4.86336
1848.08	5.37004
1851.06	5.19017
1854.05	4.74866
1857.04	4.97783
1860.02	5.36048
1863.01	5.72186
1865.99	5.95419
1868.97	6.38019
1871.95	6.50144
1874.93	6.3645
1877.91	4.72534
1880.89	4.23821
1882.46	4.87525
1885.45	4.86091
1888.43	4.39333
1891.42	4.76952
1894.41	3.97961
1897.39	2.90129
1900.37	3.10394
1903.36	2.73842
1906.34	2.36764
1909.32	3.32177
1912.29	3.00879
1915.27	2.585
1918.25	3.1207
1921.23	3.31189
1924.2	2.18446
1927.17	1.87815
1930.15	1.86756
1933.12	1.96687
1936.09	2.58634
1939.06	3.12551
1942.02	3.29368
1944.99	2.70731
1947.96	2.7843
1950.92	3.86914
1953.88	5.26052
1956.85	5.0427
1959.81	5.10914
1962.77	3.62628
1965.73	3.34193
1968.69	2.97289
1971.64	3.41807
1974.6	3.20925
1977.55	2.53344
1980.51	3.6157
1983.46	3.723
1986.41	4.18513
1989.36	4.77341
1992.31	4.85794
1995.26	4.98934
1998.21	4.65808
2001.15	5.24015
2004.1	6.45629
2007.04	7.65408
2009.99	7.86883
2012.93	7.75434
2015.87	7.43395
2018.81	7.86941
2021.75	9.15875
2024.68	9.52344
2027.62	7.99632
2030.56	7.55841
2033.49	6.94162
2036.42	6.78355
2039.36	7.87104
2042.29	8.36522
2045.22	7.75841
2048.14	7.79908
2051.07	8.39779
2054	9.06371
2056.93	10.2443
2059.85	11.4963
2062.77	12.0196
2065.7	12.7523
2068.62	13.4035
2071.54	14.5422
2074.46	15.1699
2077.38	14.8213
2080.29	14.4652
2083.21	13.8731
2086.12	13.8173
2089.04	14.2776
2091.95	14.7552
2094.86	14.9623
2097.77	14.5931
2100.68	15.3763
2103.59	16.0112
2106.5	16.2124
2109.41	16.9548
2112.31	18.1905
2115.21	19.0221
2118.12	20.298
2121.02	22.8804
2123.92	24.3773
2126.82	26.715
2129.72	29.1457
2132.62	31.3523
2135.51	32.8635
2138.41	36.0295
2141.31	37.7447
2144.2	39.0227
2147.09	41.3304
2149.98	42.4663
2152.87	44.6125
2155.76	47.3407
2158.65	49.2056
2161.54	51.4846
2164.43	52.4799
2167.31	53.0019
2170.2	54.3929
2173.08	54.1228
2175.96	54.9427
2178.84	54.1058
2181.72	54.0002
2184.6	54.1259
2187.48	54.0461
2190.36	52.9679
2193.23	50.7634
2196.11	49.3927
2198.98	48.5165
2201.85	45.6359
2204.72	43.2598
2207.59	40.6618
2210.46	38.2358
2213.33	35.5513
2216.2	33.4099
2219.07	31.0904
2221.93	28.8619
2224.8	27.8809
2227.66	26.6334
2230.52	24.7024
2233.39	23.7591
2236.25	21.8705
2239.1	21.5212
2241.96	20.0108
2244.82	19.6628
2247.68	17.9563
2250.53	17.6196
2253.38	18.5831
2256.24	17.858
2259.09	17.7189
2261.94	16.1923
2264.79	15.4146
2267.64	15.3206
2270.49	13.5729
2273.33	12.4855
2276.18	12.3536
2279.02	12.3205
2281.87	11.1524
2284.71	11.3472
2287.55	11.2328
2290.39	10.7305
2293.23	10.0955
2296.07	10.9466
2298.91	12.0975
2301.74	13.1787
2304.58	13.9356
2307.41	14.9632
2310.25	15.829
2313.08	16.0004
2315.91	15.2363
2318.74	15.6284
2321.57	16.0539
2324.4	15.0567
2327.23	13.3647
2330.05	12.5094
2332.88	11.501
2335.7	10.4847
2338.52	9.01797
2341.35	7.34101
2344.17	6.66871
2346.99	5.748
2349.81	3.71005
2352.62	3.71707
2355.44	3.8655
2358.26	2.37563
2361.07	2.14798
2363.89	2.5775
2366.7	3.38628
2369.51	3.27438
2372.32	3.97097
2375.13	3.12833
2377.94	4.26474
2380.75	3.97233
2383.56	4.53858
2386.36	4.98466
2389.17	4.70557
2391.97	4.77079
2394.77	5.16543
2397.58	6.02927
2400.38	6.6805
2403.18	8.23941
2405.97	7.87926
2408.77	7.36125
2411.57	7.69073
2414.37	8.88845
2417.16	8.58884
2419.95	8.84624
2422.75	8.47713
2425.54	7.83215
2428.33	6.6096
2431.12	6.02745
2433.91	5.30366
2436.7	4.82231
2439.48	4.53867
2442.27	4.40002
2445.05	3.94273
2447.84	4.29906
2450.62	3.88515
2453.4	2.80205
2456.18	3.1067
2458.96	3.52706
2461.74	4.36725
2464.52	4.57114
2467.29	6.04914
2470.07	5.84991
2472.85	6.13932
2475.62	5.80786
2478.39	6.33172
2481.16	6.8653
2483.93	6.0821
2486.7	5.0911
2489.47	4.22117
2492.24	3.28021
2495.01	3.16462
2497.77	2.11759
2500.54	2.40921
2503.3	1.56914
2506.06	1.5927
2508.83	1.99617
2511.59	1.74711
2514.35	1.65383
2517.11	1.12166
2519.86	1.01257
2522.62	1.36407
2525.38	2.07602
2528.13	2.35224
2530.89	3.65729
2533.64	3.84426
2536.39	3.76857
2539.14	3.9781
2541.89	4.17273
2544.64	4.65791
2547.39	4.60068
2550.14	4.4265
2552.88	4.889
2555.63	4.5601
2558.37	4.66878
2561.11	5.18162
2563.86	4.55213
2566.6	5.41098
2569.34	5.42472
2572.08	5.86525
2574.82	5.88438
2577.55	5.31048
2580.29	4.42714
2583.02	3.87836
2585.76	4.16627
2588.49	3.08976
2591.22	2.44225
2593.96	2.56635
2596.69	2.52459
2599.42	1.7106
2602.14	0.634775
2604.87	0.193771
2607.6	-0.605926
2610.32	-0.883901
2613.05	-0.704915
2615.77	-0.749071
2618.49	-0.596481
2621.22	-0.172336
2623.94	0.0190022
2626.66	-0.411574
2629.37	0.0881064
2632.09	0.590228
2634.81	1.44536
2637.53	1.9188
2640.24	1.14495
2642.96	0.938049
2645.67	1.00331
2648.38	2.28751
2651.09	2.14023
2653.8	2.22446
2656.51	2.01304
2659.22	3.38864
2661.93	3.9725
2664.63	4.53829
2667.34	4.50941
2670.04	4.65109
2672.75	4.94112
2675.45	5.80388
2678.15	5.6966
2680.85	5.65723
2683.55	6.58268
2686.25	7.06166
2688.94	7.91406
2691.64	7.73409
2694.34	7.8646
2697.03	8.91891
2699.73	8.90904
2702.42	8.82442
2705.11	8.96436
2707.8	9.28601
2710.49	9.53559
2713.18	9.9738
2715.87	10.0558
2718.55	9.52331
2721.24	10.0876
2723.93	11.5058
2726.61	11.8203
2729.29	11.3603
2731.98	11.5682
2734.66	10.6571
2737.34	10.3239
2740.02	9.90555
2742.7	9.87557
2745.37	9.59249
2748.05	9.77547
2750.72	8.7313
2753.4	8.53855
2756.07	8.16135
2758.75	7.65587
2761.42	7.38755
2764.09	7.94519
2766.76	7.04711
2769.43	6.748
2772.1	6.96096
2774.76	5.93006
2777.43	5.77477
2780.1	5.2281
2782.76	4.57795
2785.42	4.21694
2788.09	4.93194
2790.75	4.04836
2793.41	2.78508
2796.07	2.30835
2798.73	0.30212
2801.39	0.254309
2804.04	-0.164306
2806.7	-0.784765
2809.35	-1.46067
2812.01	-1.87439
2814.66	-2.34384
2817.31	-0.477261
2819.96	2.69358
2822.61	5.94447
2825.26	10.1083
2827.91	15.6831
2830.56	20.4958
2833.21	25.9665
2835.85	32.2622
2838.5	38.6742
2841.14	44.8752
2843.78	52.9052
2846.42	59.7259
2849.06	67.5358
2851.71	75.5323
2854.34	83.6453
2856.98	91.2949
2859.62	99.213
2862.26	106.178
2864.89	112.443
2867.53	118.616
2870.16	123.21
2872.79	126.907
2875.42	131.613
2878.05	135.554
2880.68	138.782
2883.31	142.905
2885.94	146.451
2888.57	149.663
2891.19	152.677
2893.82	156.443
2896.44	160.5
2899.07	165.211
2901.69	170.991
2904.31	176.763
2906.93	184.723
2909.55	193.517
2912.17	203.689
2914.79	212.386
2917.41	221.227
2920.02	229.159
2922.64	234.445
2925.25	238.981
2927.86	241.87
2930.48	242.884
2933.09	241.878
2935.7	238.162
2938.31	233.801
2940.92	228.052
2943.53	219.753
2946.13	211.799
2948.74	203.024
2951.34	193.381
2953.95	184.261
2956.55	174.741
2959.15	165.392
2961.75	155.918
2964.35	148.146
2966.95	140.855
2969.55	134.027
2972.15	128.979
2974.75	123.072
2977.34	116.021
2979.94	109.327
2982.53	102.607
2985.13	95.0043
2987.72	88.3288
2990.31	80.288
2992.9	72.6868
2995.49	65.1197
2998.08	56.8418
3000.67	50.5166
3003.25	44.4729
3005.84	39.162
3008.42	35.2852
3011.01	31.4429
3013.59	27.2433
3016.17	23.3202
3018.76	19.8405
3021.34	17.4501
3023.92	16.0389
3026.49	15.6972
3029.07	15.0561
3031.65	14.2118
3034.23	15.0538
3036.8	14.9379
3039.38	16.0244
3041.95	17.0944
3044.52	18.0593
3047.09	18.4076
3049.66	19.6009
3052.23	19.4133
3054.8	18.5386
3057.37	18.4368
3059.94	17.9118
3062.5	17.4174
3065.07	17.5917
3067.63	17.1952
3070.2	17.0386
3072.76	16.0841
3075.32	13.3906
3077.88	12.325
3080.44	10.6452
3083	9.20605
3085.56	7.65939
3088.12	6.41593
3090.67	5.28572
3093.23	3.31914
3095.78	3.14484
3098.34	3.27696
3100.89	3.66068
3103.44	3.64727
3105.99	4.25905
3108.54	4.1055
3111.09	4.71025
3113.64	4.73377
3116.19	4.0695
3118.74	4.37761
3121.28	5.38871
3123.83	5.95958
3126.37	7.85197
3128.91	8.77913
3131.46	9.30568
3134	9.56961
3136.54	10.8162
3139.08	11.1108
3141.62	12.007
3144.16	12.9886
3146.69	15.0137
3149.23	18.4772