File: data/Raman/poly_smoothed/Thy_50_12_14_1x_45s_532 nm_x100_100%_600 gr_mm_01.txt
#Acq. time (s)=	45
#Accumulations=	2
#Range (cm-¹)=	200...3150
#Windows=	2
#Auto scanning=	Off
#Autofocus=	Off
#Macrospot=	Off
#AutoExposure=	Off
#Spike filter=	Multiple accum.
#Delay time (s)=	0
#Binning=	1
#Readout mode=	Signal
#DeNoise=	Off
#ICS correction=	On
#Dark correction=	Off
#Inst. Process=	Off
#Detector Gain=	Best Dynamic Range
#Detector ADC=	20 kHz
#Detector temperature (°C)=	-69.85
#Instrument=	LabRAM HR Evol
#Detector=	Synapse
#Objective=	x100
#Grating=	600 gr/mm
#ND Filter=	100%
#Laser (nm)=	532
#Hole=	100.021
#Range=	Auto
#Laser Pol.=	No
#Raman. Pol.=	No
#Laser Pol. (°)=	-0.0007625
#Raman Pol. (°)=	89.9995
#Collection=	Microscope
#StageXY=	Marzhauser
#StageZ=	Marzhauser
#X (µm)=	-5111.9
#Y (µm)=	1476.6
#Z (µm)=	62.85
#Full time(mm:ss)=	3:20
#Project=
#Sample=
#Site=
#Title=	Thy_50_12_14_2x_45s_532 nm_x100_100%_600 gr_mm
#Remark=
#Date=	07.07.2022 10:16
#Acquired=	07.07.2022 10:16:20
#Base:Fit=	10.08.2022 10:04:29
#Base:Sub=	10.08.2022 10:04:45
#Filter:Polynom=	16.08.2022 10:20:24
#AxisType[0]=Intens
#AxisUnit[0]=Cnt
#AxisType[1]=Spectr
#AxisUnit[1]=1/cm
200.43	34.7576
204.061	27.444
207.688	20.7011
211.316	15.2047
214.941	11.7106
218.566	8.91311
222.188	6.0569
225.809	4.24753
229.43	4.44896
233.047	3.60087
236.663	2.86729
240.278	3.09403
243.894	2.72922
247.506	2.23981
251.116	3.72814
254.725	3.2122
258.333	3.40702
261.939	4.90158
265.546	5.0595
269.15	5.08455
272.752	5.95929
276.353	5.67098
279.952	6.26587
283.55	6.15829
287.146	6.61339
290.739	6.58753
294.333	6.41932
297.925	6.64801
301.516	7.29139
305.106	7.10043
308.694	7.36966
312.279	6.20009
315.864	8.72828
319.448	7.10857
323.029	7.64914
326.61	8.84238
330.19	7.9678
333.766	7.81847
337.343	9.49788
340.917	8.74111
344.491	7.13058
348.062	8.00471
351.633	7.94199
355.201	7.6621
358.77	7.17885
362.335	6.69746
365.899	5.0936
369.464	5.62796
373.025	4.78377
376.585	5.02056
380.143	4.92098
383.702	4.274
387.258	5.59983
390.812	4.64953
394.365	3.97668
397.916	4.13009
401.467	4.88509
405.015	5.14536
408.565	5.94525
412.111	7.25494
415.656	6.8437
419.197	6.86419
422.739	9.68767
426.279	10.0576
429.819	9.27378
433.356	9.85234
436.893	9.04315
440.428	7.99921
443.96	8.35639
447.492	7.2548
451.023	6.91198
454.553	5.7482
458.079	5.97312
461.606	6.73574
465.132	8.40527
468.654	7.94936
472.177	9.36552
475.696	10.5666
479.217	10.8176
482.733	13.8963
486.251	14.8625
489.765	16.698
493.278	18.9286
496.791	21.0888
500.301	22.0009
503.81	22.8402
507.319	23.4962
510.825	24.7081
514.33	25.331
517.833	25.2483
521.337	24.5966
524.838	23.9396
528.337	23.2568
531.835	22.1958
535.332	20.975
538.827	19.1755
542.321	18.0882
545.814	17.9325
549.305	16.7381
552.795	14.3431
556.284	12.7756
559.771	12.414
563.257	11.7864
566.742	10.7747
570.223	10.3419
573.705	9.70852
577.185	9.10478
580.665	7.95588
584.141	6.5192
587.617	5.51838
591.092	3.51315
594.564	2.841
598.037	3.35428
601.506	2.4511
604.976	2.88689
608.443	3.83552
611.91	4.8828
615.374	5.35157
618.839	5.67626
622.3	7.70735
625.761	9.11035
629.221	9.05166
632.679	10.8158
636.135	11.7308
639.592	13.7683
643.045	14.8762
646.497	17.8039
649.948	18.5126
653.398	19.0701
656.846	19.4452
660.293	20.1845
663.738	19.572
667.185	19.398
670.628	20.8631
674.067	21.6179
677.508	22.4398
680.947	25.5921
684.385	27.6917
687.821	29.7205
691.256	32.2891
694.69	34.66
698.121	36.053
701.552	39.3435
704.982	41.4609
708.41	43.7415
711.836	43.9298
715.262	45.7068
718.685	45.9333
722.108	46.0544
725.53	46.4896
728.949	46.6471
732.369	47.4161
735.785	49.1915
739.2	49.0461
742.616	51.2555
746.028	51.8195
749.441	54.5419
752.851	57.6562
756.26	60.4495
759.667	64.4465
763.075	67.4069
766.479	69.5793
769.883	72.4419
773.285	75.2552
776.686	78.675
780.085	82.4417
783.484	84.3938
786.881	85.7288
790.276	86.8256
793.671	88.1531
797.064	88.2386
800.456	87.773
803.846	88.6782
807.236	88.0034
810.624	88.6771
814.01	88.7593
817.394	90.6467
820.778	89.6543
824.161	88.1104
827.543	87.1118
830.921	84.9554
834.3	82.5744
837.676	79.6059
841.053	76.6324
844.426	72.8153
847.8	69.9283
851.171	68.4112
854.542	65.4237
857.911	61.5541
861.279	58.9041
864.645	55.8676
868.01	53.6437
871.375	52.783
874.737	50.3906
878.097	48.632
881.457	47.0078
884.817	47.4243
888.174	47.2179
891.53	47.6801
894.884	48.1795
898.237	47.9192
901.589	48.4462
904.94	45.8319
908.289	45.4341
911.637	45.4046
914.984	43.8082
918.33	44.1176
921.674	42.805
925.015	41.2931
928.357	41.3883
931.698	39.8437
935.037	38.2692
938.373	37.3811
941.71	37.4424
945.046	35.9738
948.378	35.8015
951.711	35.5409
955.043	35.4187
958.372	34.7236
961.701	34.733
965.027	36.5453
968.354	36.5313
971.678	36.4365
975	35.6097
978.324	34.1932
981.644	33.354
984.962	33.0492
988.282	33.0595
991.598	32.636
994.913	31.0226
998.227	30.2227
1001.54	29.8377
1004.85	28.9994
1008.16	28.74
1011.47	29.0349
1014.78	28.5
1018.08	29.375
1021.39	29.2211
1024.69	28.3569
1028	29.0854
1031.3	29.858
1034.6	29.6428
1037.9	29.3829
1041.19	28.6182
1044.49	28.6029
1047.79	27.1517
1051.08	24.9614
1054.37	23.6504
1057.66	21.4837
1060.95	21.3494
1064.24	19.9214
1067.53	17.9446
1070.81	15.4733
1074.1	14.2757
1077.38	14.8145
1080.66	14.5254
1083.94	14.0541
1087.22	15.1398
1090.5	15.9698
1093.78	16.0076
1097.05	16.1759
1100.33	15.8851
1103.6	14.9714
1106.87	15.0939
1110.15	14.5749
1113.41	13.9166
1116.68	13.1737
1119.95	11.7501
1123.21	10.9542
1126.48	10.2782
1129.74	9.12723
1133	6.46227
1136.26	5.11833
1139.52	3.69115
1142.78	2.74111
1146.04	0.709174
1149.29	0.32181
1152.55	0.154905
1155.8	-0.413068
1159.05	-0.376829
1162.3	-0.40157
1165.55	0.503769
1168.8	1.06613
1172.05	0.871658
1175.29	0.129029
1178.54	0.788629
1181.78	1.01821
1185.02	1.04751
1188.26	0.558793
1191.5	1.21331
1194.74	1.46223
1197.97	1.84096
1201.21	2.58947
1204.44	3.32078
1207.68	4.42478
1210.91	4.73819
1214.14	5.7901
1217.37	8.13975
1220.6	12.1195
1223.82	15.1641
1227.05	18.0229
1230.27	22.9671
1233.49	26.2048
1236.72	28.4997
1239.94	31.4919
1243.16	33.6476
1246.37	35.8817
1249.59	38.2905
1252.8	40.4076
1256.02	44.1829
1259.23	47.4471
1262.44	49.8947
1265.66	52.1455
1268.87	55.1083
1272.07	55.9851
1275.28	57.9768
1278.48	58.0117
1281.69	58.5705
1284.89	59.464
1288.09	58.3975
1291.3	59.6158
1294.49	59.675
1297.69	59.8956
1300.89	60.7016
1304.09	60.8255
1307.28	61.394
1310.47	61.8928
1313.66	60.0126
1316.86	59.2558
1320.05	58.3055
1323.23	57.6486
1326.42	56.7555
1329.61	56.1905
1332.79	56.0263
1335.98	54.029
1339.16	53.498
1342.34	51.5793
1345.52	51.0593
1348.7	48.327
1351.87	46.0578
1355.05	44.1597
1358.23	42.0386
1361.4	39.5443
1364.57	37.3463
1367.74	35.2346
1370.91	33.4874
1374.08	32.3753
1377.25	31.8563
1380.42	32.8488
1383.58	34.214
1386.75	32.9655
1389.91	31.8223
1393.07	30.2421
1396.23	28.9188
1399.39	28.4355
1402.55	28.1625
1405.7	28.4249
1408.86	30.1814
1412.01	29.9443
1415.17	31.3568
1418.32	33.4673
1421.47	36.7172
1424.62	39.2087
1427.77	44.614
1430.92	49.2521
1434.06	52.9087
1437.2	57.0737
1440.35	61.31
1443.49	64.8246
1446.63	68.1857
1449.77	69.9795
1452.91	71.2402
1456.05	70.4707
1459.18	67.4031
1462.32	63.1713
1465.45	58.4145
1468.59	54.453
1471.72	50.524
1474.85	44.9068
1477.98	40.5054
1481.11	33.7259
1484.23	28.3485
1487.36	23.0104
1490.48	18.4997
1493.61	15.6982
1496.73	12.216
1499.85	11.0406
1502.97	10.5895
1506.09	11.0149
1509.2	11.1537
1512.32	10.9727
1515.44	13.5623
1518.55	16.4203
1521.66	17.7728
1524.77	19.374
1527.88	19.7429
1530.99	20.874
1534.1	22.9992
1537.21	24.9833
1540.31	29.0115
1543.42	31.4081
1546.52	34.4772
1549.62	38.6135
1552.72	41.2051
1555.82	43.1112
1558.92	46.8615
1562.02	49.9572
1565.11	53.9253
1568.21	57.0577
1571.3	58.8186
1574.39	60.4424
1577.49	63.6337
1580.58	65.1809
1583.67	67.3437
1586.75	68.5733
1589.84	68.9538
1592.93	68.8164
1596.01	67.6364
1599.09	65.629
1602.18	63.059
1605.26	62.3423
1608.34	61.3901
1611.41	60.0984
1614.49	60.221
1617.57	60.5261
1620.64	60.2918
1623.72	61.1975
1626.79	62.569
1629.86	63.2386
1632.93	65.41
1636	67.0335
1639.07	68.5731
1642.14	70.1248
1645.2	71.184
1648.27	71.6262
1651.33	72.9789
1654.39	73.909
1657.45	73.9799
1660.51	74.4829
1663.57	73.2395
1666.63	70.5069
1669.69	69.5775
1672.74	65.5798
1675.79	61.6855
1678.85	57.4877
1681.9	52.3877
1684.95	48.1221
1688	44.8479
1691.05	41.1135
1694.1	35.5005
1697.14	30.3639
1700.19	26.736
1703.23	23.3851
1706.27	19.6715
1709.32	16.6817
1712.35	14.1973
1715.39	12.2265
1718.43	10.2905
1721.47	7.93192
1724.5	8.13282
1727.54	7.06968
1730.57	7.35913
1733.61	7.80083
1736.64	7.28945
1739.67	7.76932
1742.7	7.61991
1745.72	7.04454
1748.75	6.42432
1751.78	6.0378
1754.8	5.63731
1757.82	6.05508
1760.85	5.8257
1763.87	5.48011
1766.89	4.38589
1769.91	3.19598
1772.92	3.11865
1775.94	2.95354
1778.96	2.46416
1781.97	1.76902
1784.98	1.76692
1788	1.53858
1791.01	0.226962
1794.01	-0.136585
1797.02	0.357874
1800.03	0.308481
1803.04	-0.990824
1806.04	-0.161674
1809.05	0.0667325
1812.05	-0.413497
1815.05	0.508748
1818.05	0.812709
1821.05	0.809732
1824.05	1.00341
1827.05	0.990179
1830.04	0.683912
1833.04	0.679017
1836.03	1.28174
1839.03	1.29829
1842.02	1.79901
1845.01	1.60217
1848	1.56759
1850.99	1.61163
1853.97	1.27913
1856.96	1.32806
1859.94	1.32963
1862.93	0.264422
1865.91	0.328614
1868.89	1.30669
1871.87	1.10081
1874.85	1.99798
1877.83	2.20644
1880.81	2.8915
1882.56	2.97573
1885.55	3.96133
1888.54	4.30003
1891.52	4.73589
1894.51	5.58572
1897.49	4.5472
1900.48	4.49
1903.46	5.36515
1906.44	5.7038
1909.42	5.42708
1912.4	5.2279
1915.38	5.16156
1918.35	4.88488
1921.33	3.6086
1924.3	3.3023
1927.28	2.84966
1930.25	3.26021
1933.22	1.49093
1936.19	0.289079
1939.16	0.878209
1942.13	0.579239
1945.09	1.10791
1948.06	1.63129
1951.03	0.803139
1953.99	1.56516
1956.95	2.26346
1959.91	2.95454
1962.87	3.21663
1965.83	2.65786
1968.79	2.15154
1971.75	2.05805
1974.7	3.89323
1977.66	3.57598
1980.61	4.37094
1983.56	4.51329
1986.52	5.67089
1989.47	5.4656
1992.41	4.65248
1995.36	4.7361
1998.31	4.44914
2001.26	3.83617
2004.2	3.44249
2007.15	3.01846
2010.09	3.12136
2013.03	3.91822
2015.97	4.17937
2018.91	4.47443
2021.85	4.53743
2024.79	4.34595
2027.72	5.91839
2030.66	6.34785
2033.59	6.55679
2036.53	6.23807
2039.46	7.25841
2042.39	9.02956
2045.32	9.91557
2048.25	11.6096
2051.18	11.7358
2054.1	12.1859
2057.03	12.7043
2059.95	13.4312
2062.88	12.8645
2065.8	12.9694
2068.72	14.1989
2071.64	14.1878
2074.56	14.7796
2077.48	15.6911
2080.39	16.2487
2083.31	16.5279
2086.22	17.7423
2089.14	18.9333
2092.05	20.3407
2094.96	22.6551
2097.87	25.1044
2100.78	28.1345
2103.69	30.2745
2106.6	33.3711
2109.51	37.4715
2112.41	40.4129
2115.32	44.037
2118.22	47.6632
2121.12	51.791
2124.02	54.9849
2126.92	59.1009
2129.82	62.127
2132.72	64.4633
2135.62	68.5706
2138.51	71.5871
2141.41	73.9322
2144.3	76.6581
2147.19	78.4256
2150.09	79.9053
2152.97	81.6046
2155.86	83.5714
2158.75	85.6683
2161.64	86.9494
2164.53	88.3921
2167.41	89.3231
2170.3	90.1781
2173.18	90.9921
2176.06	90.5043
2178.94	90.0994
2181.82	88.5683
2184.7	87.5359
2187.58	86.8483
2190.46	84.4549
2193.33	83.2525
2196.21	80.5201
2199.08	78.228
2201.95	75.4344
2204.83	72.6008
2207.7	70.4555
2210.57	66.8356
2213.43	64.0685
2216.3	61.0838
2219.17	57.9168
2222.03	55.3105
2224.9	52.6635
2227.76	49.7041
2230.62	47.4783
2233.49	44.5717
2236.34	42.0468
2239.2	39.6946
2242.06	36.2244
2244.92	33.5739
2247.78	31.122
2250.63	29.4616
2253.48	27.7239
2256.34	26.4817
2259.19	24.0141
2262.04	22.3839
2264.89	21.1204
2267.74	19.966
2270.59	18.3657
2273.43	17.393
2276.28	16.9834
2279.12	16.298
2281.97	16.0665
2284.81	14.989
2287.65	14.4887
2290.49	13.8726
2293.33	11.6361
2296.17	11.8485
2299.01	11.9421
2301.84	12.1599
2304.68	11.6835
2307.51	11.6456
2310.35	10.4079
2313.18	10.5432
2316.01	11.8725
2318.84	11.8247
2321.67	10.6812
2324.5	9.92872
2327.33	9.38311
2330.15	8.83683
2332.98	8.25586
2335.8	7.47115
2338.62	6.52243
2341.45	5.99131
2344.27	5.40789
2347.09	4.51441
2349.91	3.25032
2352.72	2.01611
2355.54	0.792443
2358.36	0.491808
2361.17	-0.346415
2363.98	-0.403985
2366.8	0.488481
2369.61	0.861831
2372.42	1.03117
2375.23	1.62243
2378.04	1.67752
2380.85	3.25866
2383.66	4.22873
2386.46	4.82305
2389.26	3.8266
2392.07	4.4788
2394.87	5.92619
2397.67	6.57539
2400.47	7.07422
2403.27	7.66772
2406.07	8.06899
2408.87	8.90274
2411.67	9.27526
2414.46	9.10822
2417.26	8.84978
2420.05	9.28545
2422.84	9.16115
2425.64	8.9374
2428.43	8.67072
2431.22	8.17644
2434.01	7.99586
2436.79	8.20514
2439.58	9.70843
2442.37	10.2146
2445.15	9.82472
2447.93	9.90078
2450.72	9.72069
2453.5	9.51871
2456.28	9.00803
2459.06	8.8163
2461.84	9.2792
2464.62	9.34105
2467.39	9.80534
2470.17	9.38396
2472.94	9.56677
2475.72	9.99256
2478.49	8.69254
2481.26	7.68752
2484.03	7.50806
2486.8	7.6503
2489.57	7.44379
2492.34	5.96641
2495.1	6.04038
2497.87	5.64318
2500.63	5.40051
2503.4	5.19934
2506.16	5.48267
2508.92	5.1621
2511.68	5.24652
2514.44	5.44021
2517.2	5.93265
2519.96	6.25856
2522.72	6.33205
2525.47	6.48851
2528.23	7.60074
2530.98	6.96252
2533.74	6.99562
2536.49	6.27832
2539.24	5.93383
2541.99	5.18644
2544.74	5.09668
2547.49	3.86482
2550.23	4.88837
2552.98	4.47933
2555.72	4.67019
2558.47	4.38601
2561.21	4.16034
2563.95	4.05252
2566.69	4.06642
2569.43	3.65693
2572.17	3.69556
2574.91	3.65813
2577.65	4.1167
2580.39	4.0727
2583.12	3.29252
2585.85	4.08235
2588.59	4.21162
2591.32	4.41541
2594.05	4.51384
2596.78	4.1339
2599.51	3.77325
2602.24	3.36244
2604.97	2.06538
2607.69	1.8875
2610.42	1.43458
2613.14	1.02989
2615.87	1.17928
2618.59	1.56102
2621.31	2.77997
2624.03	2.98319
2626.75	2.98467
2629.47	4.14598
2632.19	4.58822
2634.91	4.67308
2637.62	4.88642
2640.34	5.60033
2643.05	6.46874
2645.76	7.51101
2648.48	6.39346
2651.19	7.98273
2653.9	8.58545
2656.6	9.11842
2659.31	9.00587
2662.02	8.96476
2664.73	9.44778
2667.43	9.89575
2670.14	9.65304
2672.84	8.70422
2675.54	7.64039
2678.24	7.45801
2680.94	6.63756
2683.64	6.08872
2686.34	5.63153
2689.04	4.70628
2691.74	3.93546
2694.43	3.97889
2697.13	4.87743
2699.82	5.07402
2702.51	4.98518
2705.21	5.68876
2707.9	6.42678
2710.58	6.74388
2713.27	6.56615
2715.96	6.93781
2718.65	7.9447
2721.33	8.09932
2724.02	7.97704
2726.71	8.5441
2729.39	9.44632
2732.07	9.75942
2734.75	9.26969
2737.43	9.26332
2740.11	8.68752
2742.79	9.32957
2745.47	8.96472
2748.14	8.59579
2750.82	8.44655
2753.49	8.74544
2756.17	9.53741
2758.84	10.2815
2761.51	10.4113
2764.18	10.5794
2766.85	9.8315
2769.52	9.32046
2772.19	9.00385
2774.86	7.9565
2777.52	7.46889
2780.19	6.90195
2782.85	6.28136
2785.52	5.61307
2788.18	4.53484
2790.84	3.50458
2793.5	2.77442
2796.16	1.93614
2798.82	1.58399
2801.48	0.901407
2804.13	1.6446
2806.79	1.67754
2809.45	1.08283
2812.1	0.865526
2814.75	0.235288
2817.41	2.06794
2820.06	4.20196
2822.71	6.06251
2825.36	10.1654
2828	13.5691
2830.65	17.7301
2833.3	21.1899
2835.94	26.014
2838.59	31.6725
2841.23	36.8366
2843.87	42.7126
2846.52	48.5516
2849.16	54.2059
2851.8	61.1224
2854.44	68.9202
2857.08	75.8612
2859.71	82.2784
2862.35	88.037
2864.98	93.1385
2867.62	98.28
2870.25	102.368
2872.88	105.296
2875.52	107.278
2878.15	109.78
2880.78	113.55
2883.41	116.001
2886.03	119.649
2888.66	123.113
2891.29	127.258
2893.91	129.786
2896.54	133.283
2899.16	137.212
2901.78	143.115
2904.4	149.757
2907.02	156.853
2909.64	166.506
2912.26	176.087
2914.88	186.007
2917.5	194.317
2920.11	203.231
2922.73	209.307
2925.34	214.443
2927.96	217.408
2930.57	220.317
2933.18	220.603
2935.79	220.682
2938.4	217.53
2941.01	212.607
2943.62	207.987
2946.22	201.181
2948.83	193.774
2951.43	185.541
2954.04	177.005
2956.64	167.903
2959.24	158.595
2961.84	149.797
2964.45	141.662
2967.05	134.193
2969.64	127.316
2972.24	120.137
2974.84	112.778
2977.43	104.626
2980.03	96.1708
2982.62	88.9464
2985.22	80.9634
2987.81	73.4196
2990.4	65.3239
2992.99	59.1661
2995.58	52.1247
2998.17	45.4613
3000.76	39.2958
3003.34	33.5267
3005.93	27.7581
3008.52	24.0101
3011.1	19.7131
3013.68	16.469
3016.27	13.2963
3018.85	10.303
3021.43	9.08187
3024.01	7.60197
3026.59	6.62985
3029.16	5.29398
3031.74	5.43103
3034.32	5.56784
3036.89	5.74609
3039.47	6.86585
3042.04	6.87997
3044.61	8.271
3047.18	9.65948
3049.75	11.0182
3052.32	11.3706
3054.89	11.796
3057.46	11.9002
3060.03	11.5379
3062.59	10.9882
3065.16	10.8218
3067.72	9.35899
3070.29	8.47132
3072.85	8.04666
3075.41	6.56601
3077.97	5.63637
3080.53	3.96282
3083.09	3.11184
3085.65	2.70809
3088.21	1.96146
3090.76	1.07262
3093.32	0.343648
3095.87	0.327328
3098.43	-0.322877
3100.98	-0.692621
3103.53	-1.2294
3106.08	-0.334983
3108.63	1.72433
3111.18	2.18613
3113.73	2.63622
3116.28	3.42407
3118.83	5.06103
3121.37	5.73733
3123.92	6.7766
3126.46	7.98535
3129	9.05942
3131.55	10.9117
3134.09	12.6018
3136.63	14.2773
3139.17	16.1664
3141.71	17.722
3144.24	18.4223
3146.78	17.843
3149.32	15.9527