File: data/Raman/poly_smoothed/Thy_00_07_11_1x_45s_532 nm_x100_100%_600 gr_mm_01.txt
#Acq. time (s)=	45
#Accumulations=	2
#Range (cm-¹)=	200...3150
#Windows=	2
#Auto scanning=	Off
#Autofocus=	Off
#Macrospot=	Off
#AutoExposure=	Off
#Spike filter=	Multiple accum.
#Delay time (s)=	0
#Binning=	1
#Readout mode=	Signal
#DeNoise=	Off
#ICS correction=	On
#Dark correction=	Off
#Inst. Process=	Off
#Detector Gain=	Best Dynamic Range
#Detector ADC=	20 kHz
#Detector temperature (°C)=	-69.85
#Instrument=	LabRAM HR Evol
#Detector=	Synapse
#Objective=	x100
#Grating=	600 gr/mm
#ND Filter=	100%
#Laser (nm)=	532
#Hole=	100.021
#Range=	Auto
#Laser Pol.=	No
#Raman. Pol.=	No
#Laser Pol. (°)=	-0.0007625
#Raman Pol. (°)=	89.9995
#Collection=	Microscope
#StageXY=	Marzhauser
#StageZ=	Marzhauser
#X (µm)=	8993.3
#Y (µm)=	-3087.6
#Z (µm)=	-54.75
#Full time(mm:ss)=	3:18
#Project=
#Sample=
#Site=
#Title=	Thy_00_07_11_2x_45s_532 nm_x100_100%_600 gr_mm
#Remark=
#Date=	28.06.2022 10:49
#Acquired=	28.06.2022 10:49:43
#Base:Fit=	10.08.2022 10:06:44
#Base:Fit=	10.08.2022 10:07:16
#Base:Fit=	10.08.2022 10:07:25
#Base:Fit=	10.08.2022 10:07:44
#Base:Fit=	10.08.2022 10:07:56
#Base:Sub=	10.08.2022 10:08:39
#Filter:Polynom=	16.08.2022 10:26:06
#AxisType[0]=Intens
#AxisUnit[0]=Cnt
#AxisType[1]=Spectr
#AxisUnit[1]=1/cm
200.407	3.81785
204.035	10.0043
207.665	14.6035
211.291	17.7853
214.916	18.5081
218.541	19.0758
222.163	19.8753
225.785	19.7704
229.404	20.0575
233.022	20.9532
236.638	20.9971
240.255	22.5427
243.868	23.4356
247.48	24.7738
251.091	22.8411
254.702	21.4421
258.31	22.0671
261.916	20.2299
265.521	22.2743
269.125	22.6714
272.727	21.2769
276.328	21.9531
279.927	21.907
283.525	21.9397
287.121	20.7664
290.716	22.0522
294.31	24.4232
297.9	24.6606
301.491	25.8526
305.081	29.8342
308.669	31.5521
312.256	35.2601
315.839	37.3017
319.423	39.6215
323.006	42.1191
326.585	44.2945
330.165	44.9353
333.741	46.1314
337.318	43.9524
340.894	42.036
344.466	41.2725
348.039	42.0071
351.608	43.8377
355.176	44.8524
358.745	45.9314
362.31	47.5545
365.876	49.5232
369.439	52.5606
373	53.9509
376.56	55.7395
380.12	58.0523
383.677	58.1073
387.233	58.2851
390.787	58.0189
394.34	55.5403
397.894	52.826
401.444	50.4776
404.993	48.3532
408.54	45.8084
412.086	42.1856
415.631	37.709
419.174	32.3303
422.716	26.95
426.257	20.2771
429.794	17.8195
433.332	15.0211
436.868	13.1286
440.403	14.0438
443.937	16.0811
447.468	16.9924
450.999	17.4641
454.528	19.1953
458.057	20.4113
461.582	22.0544
465.107	22.8942
468.629	22.8334
472.152	21.4505
475.672	22.7045
479.192	25.5257
482.709	28.9601
486.226	34.3188
489.74	39.4955
493.255	44.7839
496.767	49.3438
500.277	52.6989
503.788	55.2796
507.295	56.7496
510.801	56.4374
514.308	56.9806
517.811	57.1458
521.313	56.0596
524.814	57.0964
528.313	56.9634
531.811	52.4211
535.308	49.6851
538.803	47.0151
542.297	43.0856
545.789	37.0348
549.281	33.936
552.771	28.899
556.259	24.5635
559.747	21.6096
563.233	19.3559
566.717	19.3748
570.2	19.1577
573.68	19.9987
577.161	19.589
580.64	21.3608
584.118	22.7115
587.593	23.8431
591.068	22.7152
594.54	20.9919
598.013	20.4972
601.484	19.406
604.952	17.8843
608.421	16.4427
611.886	14.5849
615.35	13.7322
618.815	13.8321
622.276	13.6211
625.738	12.4391
629.197	10.3041
632.655	13.3727
636.113	13.1763
639.568	11.6767
643.021	11.0531
646.473	10.7651
649.924	10.6772
653.376	11.2253
656.824	11.2513
660.271	12.5139
663.716	14.0945
667.161	16.0667
670.604	15.0785
674.045	16.3297
677.486	15.505
680.925	16.5288
684.361	18.7669
687.797	20.2486
691.232	21.3268
694.666	22.7356
698.099	23.6994
701.528	25.8151
704.958	26.2111
708.387	25.4996
711.814	27.4899
715.238	27.6259
718.663	29.366
722.084	27.5695
725.506	27.0824
728.925	28.1694
732.345	29.0493
735.761	31.5859
739.178	37.2854
742.592	43.6669
746.006	54.3484
749.417	64.1807
752.827	73.52
756.236	83.8634
759.645	94.1884
763.051	103.167
766.456	110.577
769.859	115.396
773.261	120.245
776.664	120.485
780.064	121.789
783.462	119.749
786.859	114.827
790.255	110.554
793.649	105.503
797.042	99.147
800.434	91.4509
803.823	83.4019
807.212	73.1974
810.6	66.4648
813.987	61.6644
817.372	57.5918
820.754	55.305
824.137	55.0473
827.519	56.1779
830.897	56.5853
834.276	56.471
837.654	58.1637
841.029	59.164
844.404	59.0048
847.776	58.2248
851.149	57.0354
854.519	55.6483
857.889	53.1052
861.256	49.9226
864.622	47.6066
867.988	44.9661
871.351	42.7292
874.713	41.4502
878.074	37.4547
881.435	33.7688
884.794	33.092
888.15	31.3154
891.506	30.4924
894.861	29.3372
898.214	28.5331
901.566	28.9653
904.916	29.457
908.266	29.1238
911.614	29.6941
914.961	30.3556
918.306	31.4683
921.651	31.3189
924.994	30.9797
928.336	31.6355
931.674	31.9672
935.014	30.1758
938.352	29.144
941.687	27.8001
945.022	26.4791
948.357	25.2992
951.688	25.3917
955.02	23.6704
958.348	21.9783
961.678	19.9033
965.004	21.276
968.331	23.4668
971.655	23.8686
974.979	23.7201
978.3	24.2035
981.62	26.163
984.941	25.2314
988.259	23.9685
991.575	24.472
994.89	27.3264
998.204	30.1677
1001.52	36.1842
1004.83	43.7251
1008.14	51.3863
1011.45	57.1236
1014.76	61.3415
1018.06	64.7776
1021.37	67.7137
1024.67	68.8675
1027.97	68.7857
1031.27	68.3942
1034.57	66.4981
1037.87	62.2645
1041.17	57.6085
1044.47	53.0676
1047.76	51.1618
1051.06	45.3512
1054.35	39.287
1057.64	33.539
1060.93	30.5911
1064.22	27.3732
1067.5	26.4693
1070.79	28.2053
1074.08	30.8163
1077.36	35.4744
1080.64	39.8364
1083.92	42.6565
1087.2	44.9736
1090.48	47.6416
1093.76	49.7232
1097.03	50.8785
1100.31	51.0942
1103.58	50.1657
1106.85	48.7694
1110.12	45.4206
1113.39	40.7149
1116.66	34.6667
1119.93	28.1423
1123.19	24.2919
1126.46	20.3428
1129.72	16.4922
1132.98	13.4502
1136.24	13.1392
1139.5	13.076
1142.76	14.2301
1146.01	14.2633
1149.27	15.0688
1152.53	14.3593
1155.78	14.2954
1159.03	13.3161
1162.28	12.2131
1165.53	10.7917
1168.78	11.7549
1172.02	11.8601
1175.27	10.5296
1178.51	10.3179
1181.76	10.5853
1185	10.9989
1188.24	9.3413
1191.48	8.7565
1194.71	10.8795
1197.95	13.0334
1201.19	15.8071
1204.42	20.5308
1207.65	24.0769
1210.88	28.0678
1214.12	32.662
1217.35	37.0224
1220.57	43.7264
1223.8	48.8416
1227.03	53.7849
1230.25	58.3374
1233.47	63.0378
1236.69	65.0723
1239.92	65.0309
1243.13	65.1861
1246.35	65.0899
1249.57	63.5767
1252.78	62.7144
1256	62.0065
1259.21	58.6884
1262.42	57.3962
1265.63	55.5243
1268.84	55.9814
1272.05	56.6905
1275.26	57.4134
1278.46	57.2254
1281.67	59.7853
1284.87	61.6767
1288.07	64.8144
1291.27	67.5492
1294.47	72.5598
1297.67	77.4875
1300.87	83.5293
1304.06	88.5105
1307.26	93.2085
1310.45	99.1947
1313.64	102.139
1316.83	104.558
1320.02	106.193
1323.21	107.312
1326.4	107.643
1329.59	105.999
1332.77	106.046
1335.95	103.705
1339.14	101.595
1342.32	97.4401
1345.5	96.199
1348.67	92.9133
1351.85	87.973
1355.03	84.016
1358.2	80.2096
1361.38	76.4988
1364.55	71.8162
1367.72	67.6987
1370.89	64.0915
1374.06	61.9437
1377.23	60.623
1380.39	58.9092
1383.56	58.3676
1386.72	56.5938
1389.89	55.1917
1393.05	52.576
1396.21	52.3383
1399.37	50.4959
1402.52	51.9613
1405.68	53.763
1408.84	55.4413
1411.99	58.7124
1415.15	63.079
1418.3	68.6462
1421.45	74.0271
1424.6	80.4405
1427.75	88.0466
1430.89	95.4164
1434.04	101.488
1437.18	107.786
1440.33	111.173
1443.47	115.345
1446.61	117.9
1449.75	118.787
1452.89	119.099
1456.03	117.1
1459.16	113.666
1462.3	108.973
1465.43	101.16
1468.56	91.2097
1471.7	82.8191
1474.83	73.6441
1477.96	64.9042
1481.08	56.5853
1484.21	48.0385
1487.34	40.8272
1490.46	35.209
1493.58	30.435
1496.71	26.1377
1499.83	22.3844
1502.95	21.8165
1506.07	20.9123
1509.18	20.78
1512.3	20.1855
1515.41	21.0027
1518.53	23.4323
1521.64	23.9116
1524.75	24.5528
1527.86	26.9279
1530.97	30.4047
1534.08	32.0232
1537.19	35.4031
1540.29	39.1397
1543.4	42.1266
1546.5	45.7935
1549.6	50.0505
1552.7	54.7652
1555.8	59.3
1558.9	63.8088
1562	67.6165
1565.09	71.3176
1568.19	72.5498
1571.28	74.0094
1574.37	74.0101
1577.47	77.1823
1580.56	80.1127
1583.64	82.1251
1586.73	82.1307
1589.82	82.1247
1592.9	82.1718
1595.99	80.0423
1599.07	78.3237
1602.15	76.6257
1605.23	75.2414
1608.31	73.6852
1611.39	73.0665
1614.47	73.2783
1617.55	73.9888
1620.62	73.0831
1623.7	73.0002
1626.77	73.9964
1629.84	76.1553
1632.91	78.0292
1635.98	78.2371
1639.05	79.4855
1642.11	80.8822
1645.18	82.8199
1648.24	85.0001
1651.31	87.5194
1654.37	88.9985
1657.43	89.9903
1660.49	88.7124
1663.55	85.9598
1666.61	83.8769
1669.66	80.8002
1672.72	76.374
1675.77	73.1023
1678.83	67.3205
1681.88	62.1707
1684.93	56.4845
1687.98	50.6629
1691.03	43.7036
1694.07	38.6844
1697.12	32.5126
1700.17	26.8383
1703.21	23.9156
1706.25	20.0162
1709.29	16.0336
1712.33	14.6436
1715.37	12.0042
1718.41	10.2543
1721.45	9.28889
1724.49	8.93679
1727.52	8.59497
1730.55	7.68213
1733.59	7.23395
1736.62	7.45862
1739.65	7.98404
1742.68	7.71036
1745.7	7.18314
1748.73	6.91823
1751.76	6.70319
1754.78	5.27697
1757.8	5.49178
1760.83	4.20737
1763.85	3.94094
1766.87	3.46841
1769.89	3.13403
1772.9	1.92327
1775.92	2.17774
1778.94	2.11521
1781.95	2.9468
1784.96	3.11013
1787.97	4.25111
1790.99	3.83294
1794	3.64825
1797	3.79673
1800.01	3.02469
1803.02	2.03676
1806.02	2.08002
1809.03	2.53361
1812.03	2.66349
1815.03	1.86009
1818.03	1.61479
1821.03	2.60172
1824.03	2.46377
1827.03	2.67124
1830.02	2.95012
1833.02	3.48525
1836.01	4.11698
1839.01	3.66134
1842	3.78131
1844.99	4.3304
1847.98	5.66927
1850.97	6.53146
1853.95	8.23213
1856.94	9.22303
1859.93	9.98121
1862.91	9.22285
1865.89	8.2941
1868.87	7.93237
1871.85	7.51961
1874.83	7.47121
1877.81	7.72375
1880.79	8.07682
1882.52	7.76582
1885.51	8.51483
1888.5	7.37762
1891.49	6.98423
1894.47	6.67991
1897.46	5.84335
1900.44	6.27615
1903.42	6.00775
1906.4	5.97976
1909.38	6.16644
1912.36	6.10748
1915.34	6.0107
1918.32	6.02179
1921.29	6.36845
1924.27	6.31405
1927.24	6.79468
1930.21	6.96596
1933.18	7.21157
1936.15	6.51509
1939.12	7.11665
1942.09	7.2995
1945.06	7.84934
1948.02	8.54677
1950.99	7.39494
1953.95	6.42249
1956.91	6.14254
1959.88	5.68137
1962.84	4.46908
1965.8	3.68523
1968.75	2.60256
1971.71	2.03569
1974.67	2.33611
1977.62	1.85737
1980.58	1.34165
1983.53	1.42637
1986.48	2.38946
1989.43	2.54596
1992.38	3.14216
1995.33	3.87961
1998.27	4.45153
2001.22	4.9152
2004.16	5.95787
2007.11	6.14283
2010.05	5.50937
2012.99	6.15635
2015.93	7.21316
2018.87	5.73818
2021.81	5.73498
2024.75	5.316
2027.69	4.95191
2030.62	4.08315
2033.56	4.04977
2036.49	2.73742
2039.42	4.07644
2042.35	4.55694
2045.28	3.89523
2048.21	5.43944
2051.14	6.18453
2054.07	8.34559
2056.99	8.08203
2059.92	8.89165
2062.84	8.72122
2065.76	9.59071
2068.68	9.76366
2071.6	9.61487
2074.52	9.62029
2077.44	10.3002
2080.36	9.62937
2083.27	9.18683
2086.19	9.68304
2089.1	8.67246
2092.02	7.33723
2094.93	9.05978
2097.84	8.58735
2100.75	7.74347
2103.66	8.0267
2106.56	6.70674
2109.47	6.8128
2112.38	6.64765
2115.28	6.07337
2118.18	6.13864
2121.09	6.62601
2123.99	7.14548
2126.89	6.47496
2129.79	5.03993
2132.68	5.00964
2135.58	5.43814
2138.48	5.49519
2141.37	6.00658
2144.27	5.77192
2147.16	6.08995
2150.05	5.62927
2152.94	6.08084
2155.83	6.92321
2158.72	7.17644
2161.6	8.21047
2164.49	9.05529
2167.38	8.52644
2170.26	6.85048
2173.14	7.83361
2176.03	7.04968
2178.91	7.27075
2181.79	8.96582
2184.67	9.31596
2187.54	9.64554
2190.42	11.196
2193.3	10.4778
2196.17	10.801
2199.05	9.69258
2201.92	8.15101
2204.79	8.09077
2207.66	9.68593
2210.53	9.53411
2213.4	9.5766
2216.27	9.63302
2219.13	9.77884
2222	10.6452
2224.86	10.5045
2227.72	10.7688
2230.59	9.6799
2233.45	9.667
2236.31	9.32636
2239.17	9.25589
2242.03	9.78739
2244.88	9.85021
2247.74	9.18232
2250.59	10.28
2253.45	9.18143
2256.3	8.20935
2259.15	7.62862
2262	6.80069
2264.85	6.08953
2267.7	5.43763
2270.55	5.09677
2273.4	5.25484
2276.24	6.19314
2279.09	4.28512
2281.93	3.76559
2284.77	3.65043
2287.62	3.33165
2290.46	4.19352
2293.3	3.46993
2296.13	3.89375
2298.97	4.44155
2301.81	6.91692
2304.64	8.07405
2307.48	9.20619
2310.31	10.7412
2313.14	11.2012
2315.98	10.7619
2318.81	10.8708
2321.64	10.5046
2324.46	10.6763
2327.29	10.5882
2330.12	11.5524
2332.94	11.1475
2335.77	10.5214
2338.59	8.86043
2341.41	7.6286
2344.23	6.87802
2347.05	5.97529
2349.87	3.86686
2352.69	3.61954
2355.51	2.3007
2358.32	2.30569
2361.14	0.940897
2363.95	1.48719
2366.76	0.888578
2369.58	1.67622
2372.39	1.5671
2375.2	1.70462
2378	1.89466
2380.81	0.302455
2383.62	0.0687946
2386.43	0.222904
2389.23	0.0951825
2392.03	-0.524274
2394.84	0.59727
2397.64	0.691083
2400.44	1.01454
2403.24	1.74835
2406.04	2.68286
2408.84	4.12108
2411.63	5.67726
2414.43	7.00654
2417.22	7.88111
2420.02	8.55876
2422.81	8.9592
2425.6	9.16527
2428.39	9.27037
2431.18	9.69423
2433.97	9.76583
2436.76	9.477
2439.54	9.74602
2442.33	9.4863
2445.12	9.02555
2447.9	8.2217
2450.68	7.4564
2453.46	7.9656
2456.24	7.43393
2459.02	7.70488
2461.8	6.75327
2464.58	7.03316
2467.36	7.33036
2470.13	8.11939
2472.91	7.73556
2475.68	6.8084
2478.45	6.58443
2481.23	6.64696
2484	5.86727
2486.77	5.53149
2489.54	4.50554
2492.3	4.76434
2495.07	4.33857
2497.84	5.35447
2500.6	6.52262
2503.36	6.37036
2506.13	6.10348
2508.89	5.60533
2511.65	4.88717
2514.41	5.39104
2517.17	5.24705
2519.93	5.91979
2522.68	6.37538
2525.44	7.12052
2528.19	7.93371
2530.95	7.29525
2533.7	7.35661
2536.45	7.18255
2539.2	6.9807
2541.95	6.85719
2544.7	7.479
2547.45	7.65317
2550.2	8.38546
2552.94	8.78463
2555.69	8.60165
2558.43	8.47959
2561.18	8.49134
2563.92	8.86449
2566.66	8.62331
2569.4	7.84315
2572.14	6.35668
2574.88	5.83235
2577.61	6.27171
2580.35	6.11421
2583.09	6.00612
2585.82	6.89135
2588.55	6.87911
2591.29	6.96668
2594.02	6.58565
2596.75	5.26733
2599.48	4.67279
2602.21	5.04036
2604.93	4.1869
2607.66	4.23829
2610.39	4.47519
2613.11	5.53266
2615.83	5.6137
2618.56	5.60578
2621.28	5.10096
2624	4.59804
2626.72	5.1659
2629.44	5.29201
2632.15	5.43843
2634.87	6.03049
2637.59	6.19935
2640.3	6.75331
2643.02	6.93163
2645.73	7.64253
2648.44	7.44718
2651.15	8.25226
2653.86	7.63028
2656.57	6.34117
2659.28	6.37713
2661.99	7.67001
2664.69	6.78591
2667.4	5.87745
2670.1	4.7741
2672.81	4.38164
2675.51	4.60708
2678.21	4.78874
2680.91	4.18979
2683.61	4.51115
2686.31	5.09027
2689	4.9655
2691.7	5.97562
2694.4	5.83735
2697.09	5.47326
2699.79	6.95831
2702.48	8.34022
2705.17	8.15287
2707.86	9.02695
2710.55	9.04783
2713.24	9.70852
2715.93	10.8731
2718.62	11.0469
2721.3	12.0534
2723.99	13.2558
2726.67	12.8185
2729.35	12.2341
2732.04	11.4858
2734.72	11.666
2737.4	10.5643
2740.08	9.71906
2742.76	9.49181
2745.43	8.20452
2748.11	7.65987
2750.79	6.64864
2753.46	5.89773
2756.14	6.02026
2758.81	5.09452
2761.48	5.0639
2764.15	4.82355
2766.82	4.46965
2769.49	3.24471
2772.16	2.68935
2774.82	2.30517
2777.49	2.14264
2780.16	1.71333
2782.82	1.41932
2785.48	1.32012
2788.15	0.905049
2790.81	0.573152
2793.47	1.14547
2796.13	1.33887
2798.79	1.3515
2801.44	0.888855
2804.1	-0.744849
2806.76	-1.09122
2809.41	-1.23866
2812.07	-1.22942
2814.72	-0.689066
2817.37	1.15074
2820.02	3.28683
2822.67	5.8787
2825.32	8.30297
2827.97	11.8073
2830.62	14.5862
2833.26	18.6901
2835.91	23.1965
2838.56	28.2864
2841.2	34.1708
2843.84	40.3133
2846.48	46.93
2849.12	55.2958
2851.77	63.8722
2854.4	72.4902
2857.04	80.7945
2859.68	89.5333
2862.32	96.9059
2864.95	103.907
2867.59	110.318
2870.22	115.139
2872.85	121.544
2875.48	127.748
2878.11	133.113
2880.74	137.654
2883.37	141.884
2886	146.091
2888.63	149.857
2891.25	155.14
2893.88	160.284
2896.5	166.048
2899.13	171.995
2901.75	178.319
2904.37	186.508
2906.99	194.8
2909.61	204.29
2912.23	215.515
2914.85	226.144
2917.46	235.122
2920.08	244.248
2922.7	252.925
2925.31	258.636
2927.92	261.064
2930.54	261.273
2933.15	260.695
2935.76	258.763
2938.37	254.844
2940.98	250.898
2943.58	243.692
2946.19	236.102
2948.8	227.973
2951.4	219.873
2954.01	210.969
2956.61	202.86
2959.21	193.917
2961.81	185.591
2964.41	176.483
2967.01	169.076
2969.61	161.134
2972.21	153.717
2974.81	147.498
2977.4	141.207
2980	133.095
2982.59	125.521
2985.18	116.463
2987.78	107.38
2990.37	97.2256
2992.96	88.0623
2995.55	78.0139
2998.14	68.9608
3000.73	59.585
3003.31	51.3512
3005.9	44.9194
3008.48	36.7412
3011.07	29.2315
3013.65	23.448
3016.23	17.6696
3018.81	14.3575
3021.4	10.4468
3023.97	7.42835
3026.55	4.58896
3029.13	2.13654
3031.71	0.923628
3034.28	0.117559
3036.86	0.0311215
3039.43	0.751275
3042.01	0.764283
3044.58	0.656561
3047.15	2.5711
3049.72	3.82126
3052.29	4.75631
3054.86	5.87914
3057.43	5.34508
3060	5.25355
3062.56	5.41624
3065.13	4.78743
3067.69	4.51151
3070.26	3.9048
3072.82	2.60092
3075.38	2.58293
3077.94	1.70413
3080.5	2.02267
3083.06	1.50468
3085.62	0.688007
3088.18	-0.198
3090.73	0.701248
3093.29	-0.00458267
3095.84	0.236192
3098.4	-0.666848
3100.95	0.085965
3103.5	0.505675
3106.05	1.77923
3108.6	2.52666
3111.15	3.31841
3113.7	3.40908
3116.25	4.72403
3118.79	6.18778
3121.34	7.74024
3123.88	9.48216
3126.43	10.8904
3128.97	12.673
3131.51	14.2074
3134.06	16.9486
3136.6	19.376
3139.14	22.1674
3141.67	25.5945
3144.21	28.4853
3146.75	31.8057
3149.29	34.2093