File: data/Raman/poly_smoothed/Thy_10_08_36_1x_45s_532 nm_x100_100%_600 gr_mm_01.txt
#Acq. time (s)=	45
#Accumulations=	2
#Range (cm-¹)=	200...3150
#Windows=	2
#Auto scanning=	Off
#Autofocus=	Off
#Macrospot=	Off
#AutoExposure=	Off
#Spike filter=	Multiple accum.
#Delay time (s)=	0
#Binning=	1
#Readout mode=	Signal
#DeNoise=	Off
#ICS correction=	On
#Dark correction=	Off
#Inst. Process=	Off
#Detector Gain=	Best Dynamic Range
#Detector ADC=	20 kHz
#Detector temperature (°C)=	-69.85
#Instrument=	LabRAM HR Evol
#Detector=	Synapse
#Objective=	x100
#Grating=	600 gr/mm
#ND Filter=	100%
#Laser (nm)=	532
#Hole=	100.021
#Range=	Auto
#Laser Pol.=	No
#Raman. Pol.=	No
#Laser Pol. (°)=	-0.0007625
#Raman Pol. (°)=	89.9995
#Collection=	Microscope
#StageXY=	Marzhauser
#StageZ=	Marzhauser
#X (µm)=	-2373.6
#Y (µm)=	224.7
#Z (µm)=	521.55
#Full time(mm:ss)=	3:18
#Project=
#Sample=
#Site=
#Title=	Thy_10_08_36_2x_45s_532 nm_x100_100%_600 gr_mm
#Remark=
#Date=	06.07.2022 14:21
#Acquired=	06.07.2022 14:21:06
#Base:Fit=	10.08.2022 09:46:25
#Base:Sub=	10.08.2022 09:46:49
#Filter:Polynom=	16.08.2022 10:24:56
#AxisType[0]=Intens
#AxisUnit[0]=Cnt
#AxisType[1]=Spectr
#AxisUnit[1]=1/cm
200.398	-4.01697
204.027	-0.142428
207.657	1.59987
211.283	3.314
214.909	4.30925
218.533	4.38805
222.157	5.34607
225.777	5.78809
229.396	7.05358
233.016	6.44439
236.632	7.0944
240.247	6.94933
243.86	6.72944
247.474	6.40421
251.085	7.00431
254.694	7.34396
258.301	7.14451
261.908	8.55475
265.513	8.76725
269.116	8.80582
272.718	10.1436
276.319	11.1236
279.918	12.2482
283.516	12.7514
287.113	12.7254
290.708	12.3095
294.302	13.5351
297.894	13.2061
301.485	13.1279
305.073	13.1536
308.661	14.3591
312.247	13.7209
315.833	13.156
319.415	11.6129
322.997	10.1771
326.579	9.49439
330.156	8.57408
333.735	7.06342
337.31	6.35796
340.885	6.16462
344.458	6.36181
348.03	5.46123
351.6	4.45138
355.17	2.81762
358.737	2.41115
362.304	2.69222
365.868	2.84776
369.431	2.66496
372.994	2.17256
376.554	2.3337
380.112	4.25274
383.669	4.77777
387.225	4.984
390.781	5.61552
394.334	6.40923
397.885	6.84917
401.436	6.56709
404.984	5.9096
408.532	5.98176
412.078	6.86356
415.623	7.75793
419.166	7.60725
422.708	7.57016
426.248	6.90839
429.788	7.26165
433.326	5.1233
436.86	4.47683
440.395	4.88134
443.929	4.90359
447.461	5.47015
450.99	5.76006
454.52	5.88499
458.048	5.50857
461.573	6.99623
465.099	8.84038
468.623	9.50964
472.144	9.70164
475.666	10.6757
479.184	11.5458
482.703	12.1921
486.218	12.6115
489.734	12.1488
493.247	13.1314
496.759	14.0011
500.271	13.9381
503.779	12.9039
507.287	11.7891
510.795	10.4768
514.299	10.8364
517.803	10.0403
521.305	10.6794
524.805	10.6781
528.307	10.5808
531.805	8.47856
535.301	8.61113
538.797	8.83044
542.291	7.92906
545.783	7.85554
549.275	8.06586
552.765	6.88052
556.253	6.73892
559.738	6.68383
563.224	5.63048
566.709	7.04462
570.192	6.8591
573.674	6.75541
577.153	4.40237
580.632	4.48719
584.11	4.10225
587.587	2.20389
591.06	2.09895
594.534	2.12096
598.005	3.54006
601.476	4.42193
604.944	4.76228
608.413	5.63514
611.878	5.55963
615.344	5.90078
618.807	5.81973
622.27	8.15378
625.73	9.29139
629.189	9.17389
632.648	9.79941
636.105	10.405
639.559	11.1182
643.013	11.8121
646.467	13.0449
649.918	14.6098
653.368	15.1621
656.816	15.5651
660.263	16.3861
663.708	18.0822
667.153	18.9657
670.596	20.3505
674.037	20.1041
677.478	21.2916
680.917	21.8716
684.355	23.2678
687.791	25.4547
691.224	26.9548
694.658	28.7203
698.091	30.3854
701.522	30.891
704.95	32.7262
708.379	35.1133
711.806	35.2988
715.23	36.6586
718.655	37.0432
722.078	37.5529
725.498	39.5153
728.919	42.2643
732.337	43.2731
735.755	45.1117
739.17	47.6135
742.584	50.0409
745.998	52.1769
749.409	54.0698
752.819	55.2535
756.23	57.5291
759.637	59.7215
763.043	61.3061
766.448	64.9614
769.853	67.5862
773.255	69.4468
776.656	71.3169
780.056	71.9391
783.454	72.9417
786.851	73.762
790.247	74.7368
793.641	78.4558
797.034	78.5838
800.426	79.0827
803.817	79.0197
807.206	80.495
810.592	82.9393
813.979	83.3534
817.364	83.6576
820.748	84.0281
824.129	84.8851
827.511	84.3077
830.891	81.8813
834.269	80.9436
837.646	79.6814
841.023	77.7452
844.396	75.4697
847.77	72.8871
851.141	71.0747
854.513	67.94
857.881	65.3696
861.248	62.8276
864.616	59.776
867.98	58.9502
871.343	57.9612
874.707	57.8026
878.068	58.0865
881.428	56.3815
884.786	57.488
888.143	56.8903
891.498	57.3759
894.855	57.2284
898.208	56.9683
901.56	55.892
904.91	55.5481
908.26	54.9544
911.608	52.7096
914.955	51.6192
918.298	51.051
921.643	49.4334
924.986	48.5281
928.328	47.5471
931.668	47.5587
935.006	48.5595
938.344	47.9617
941.681	48.0184
945.014	48.5471
948.349	48.962
951.682	50.0163
955.012	50.8433
958.343	48.593
961.67	48.6233
964.998	48.8345
968.323	49.1517
971.649	49.5551
974.971	49.4266
978.293	49.5477
981.615	49.2613
984.933	48.0263
988.251	47.9124
991.567	45.5089
994.884	44.7425
998.198	43.9999
1001.51	42.2667
1004.82	41.3327
1008.13	40.5578
1011.44	39.751
1014.75	38.2165
1018.06	36.8704
1021.36	34.9285
1024.66	34.1591
1027.97	32.9173
1031.27	30.6652
1034.57	28.2791
1037.87	27.4998
1041.16	25.7008
1044.46	26.1597
1047.76	26.0748
1051.05	25.2151
1054.34	24.6795
1057.63	24.8658
1060.92	23.9562
1064.21	22.7059
1067.5	22.4359
1070.78	22.295
1074.07	22.7511
1077.35	22.1631
1080.63	20.844
1083.91	20.5422
1087.19	21.2744
1090.47	21.3404
1093.75	19.9691
1097.03	21.2923
1100.3	22.3767
1103.57	22.4901
1106.84	22.3724
1110.11	20.7404
1113.38	19.6736
1116.65	18.6436
1119.92	16.9517
1123.19	15.5692
1126.45	14.5431
1129.71	12.2389
1132.97	11.5063
1136.23	11.8957
1139.49	10.1802
1142.75	9.3097
1146.01	8.75718
1149.26	7.82166
1152.52	8.54895
1155.77	8.27538
1159.02	7.32229
1162.27	8.07523
1165.52	9.58322
1168.77	10.2827
1172.02	10.8781
1175.26	13.1037
1178.51	15.0016
1181.75	16.4192
1184.99	15.8018
1188.23	16.8614
1191.47	17.3693
1194.71	19.3904
1197.94	21.0746
1201.18	22.1188
1204.41	23.1176
1207.65	26.4599
1210.88	28.2746
1214.11	30.5399
1217.34	32.7229
1220.57	34.9202
1223.79	36.7306
1227.02	39.5644
1230.24	42.056
1233.47	44.5488
1236.69	45.7923
1239.91	46.6043
1243.13	48.1053
1246.34	48.8967
1249.56	49.8947
1252.78	50.4271
1255.99	49.0037
1259.2	49.1298
1262.42	50.3063
1265.63	51.2587
1268.84	53.5574
1272.04	53.5305
1275.25	54.2217
1278.46	53.9309
1281.66	54.0664
1284.86	55.0232
1288.07	55.1457
1291.27	54.0634
1294.47	53.5194
1297.66	53.0071
1300.86	54.3247
1304.06	55.5532
1307.25	55.8903
1310.44	57.0517
1313.64	56.981
1316.83	57.1149
1320.02	56.5839
1323.2	57.4782
1326.39	57.2621
1329.58	56.1749
1332.76	56.4364
1335.95	56.4009
1339.13	56.2295
1342.31	56.1752
1345.49	54.5553
1348.67	51.903
1351.85	49.5287
1355.02	47.958
1358.2	46.7692
1361.37	44.7508
1364.54	42.9582
1367.71	41.0818
1370.88	39.6112
1374.05	37.3167
1377.22	36.9514
1380.39	36.8758
1383.55	35.5344
1386.72	35.7849
1389.88	36.0846
1393.04	34.5427
1396.2	33.8988
1399.36	34.1761
1402.52	35.2114
1405.68	34.3945
1408.83	34.9852
1411.98	37.1856
1415.14	38.1055
1418.29	39.024
1421.44	41.7217
1424.59	44.8334
1427.74	47.9549
1430.89	52.8509
1434.03	56.8956
1437.18	60.5239
1440.32	64.077
1443.46	65.9603
1446.6	67.4472
1449.74	68.0331
1452.88	68.0309
1456.02	66.4656
1459.16	65.0584
1462.29	61.8988
1465.43	59.7009
1468.56	54.2688
1471.69	48.7858
1474.82	44.0282
1477.95	38.9112
1481.08	33.8871
1484.2	29.1671
1487.33	25.7536
1490.46	23.23
1493.58	19.3202
1496.7	15.9487
1499.82	14.3106
1502.94	13.4188
1506.06	12.4519
1509.18	12.1067
1512.29	12.1338
1515.41	11.8953
1518.52	12.2325
1521.63	13.247
1524.75	14.1418
1527.85	14.8581
1530.96	15.7352
1534.07	18.641
1537.18	20.2679
1540.28	21.567
1543.39	23.247
1546.49	23.9569
1549.59	26.4095
1552.69	27.3001
1555.79	28.5817
1558.89	29.9722
1561.99	31.5563
1565.08	32.2501
1568.18	33.2306
1571.27	34.3801
1574.37	36.1933
1577.46	38.4276
1580.55	39.933
1583.64	41.5996
1586.73	42.8651
1589.81	44.3553
1592.9	45.2888
1595.98	46.6191
1599.06	46.0341
1602.15	47.2835
1605.23	49.228
1608.31	50.8219
1611.39	50.0277
1614.46	49.4107
1617.54	49.1746
1620.61	48.3881
1623.69	48.2226
1626.76	48.6374
1629.83	48.766
1632.9	49.5499
1635.97	50.5527
1639.04	52.7914
1642.11	56.3102
1645.17	58.5707
1648.24	60.6842
1651.3	63.2583
1654.36	65.6411
1657.42	66.1454
1660.48	68.1889
1663.54	68.0182
1666.6	67.5798
1669.66	66.3987
1672.71	65.385
1675.77	62.7152
1678.82	61.5781
1681.87	57.8498
1684.92	53.9489
1687.97	50.6316
1691.02	46.5195
1694.07	42.685
1697.11	38.165
1700.16	35.654
1703.2	31.7816
1706.25	29.4896
1709.29	26.6026
1712.33	25.039
1715.37	23.1486
1718.41	21.7717
1721.44	19.6199
1724.48	18.0945
1727.51	16.7134
1730.55	13.9816
1733.58	12.8889
1736.61	12.5807
1739.64	10.9876
1742.67	10.6094
1745.7	10.5754
1748.72	9.018
1751.75	9.43104
1754.77	9.68315
1757.8	8.87669
1760.82	8.61678
1763.84	7.27538
1766.86	7.03392
1769.88	6.37866
1772.9	5.95215
1775.91	5.84817
1778.93	5.01224
1781.94	4.38298
1784.96	3.70138
1787.97	3.32572
1790.98	2.48996
1793.99	2.00948
1797	0.29224
1800.01	-0.414588
1803.01	-0.72408
1806.02	-0.264435
1809.02	0.00563378
1812.02	0.16638
1815.02	0.370567
1818.03	0.684156
1821.02	0.155584
1824.02	0.444486
1827.02	0.344279
1830.02	0.297425
1833.01	-0.54252
1836.01	-0.533536
1839	0.305493
1841.99	0.526436
1844.98	1.06699
1847.97	0.837788
1850.96	1.49792
1853.95	1.52169
1856.93	1.48217
1859.92	3.10976
1862.9	3.43995
1865.88	3.56238
1868.87	3.77144
1871.85	4.08674
1874.83	5.6093
1877.81	6.87979
1880.78	6.79715
1882.53	7.31029
1885.52	7.23771
1888.51	7.50834
1891.5	8.06129
1894.48	8.06316
1897.47	8.20344
1900.45	7.67232
1903.43	6.80806
1906.41	6.03554
1909.39	6.22303
1912.37	6.66429
1915.35	6.63567
1918.33	6.70464
1921.3	6.50893
1924.28	6.07767
1927.25	5.52231
1930.22	4.8963
1933.19	4.88742
1936.16	4.60972
1939.13	4.58503
1942.1	4.52648
1945.07	5.32075
1948.03	5.88845
1951	5.39501
1953.96	5.36888
1956.92	5.77334
1959.88	6.56369
1962.84	6.2891
1965.8	6.50261
1968.76	6.21234
1971.72	5.46221
1974.67	4.68065
1977.63	4.50543
1980.58	4.72447
1983.54	4.75485
1986.49	5.35692
1989.44	5.05851
1992.39	4.28857
1995.33	3.73021
1998.28	2.97425
2001.23	2.89218
2004.17	2.43522
2007.12	2.23747
2010.06	2.77379
2013	2.96081
2015.94	3.12547
2018.88	4.64732
2021.82	4.88295
2024.76	4.51051
2027.69	5.38326
2030.63	6.05291
2033.56	6.31926
2036.5	6.93486
2039.43	6.69351
2042.36	7.83325
2045.29	8.00881
2048.22	8.13074
2051.15	8.82094
2054.07	9.57723
2057	10.383
2059.92	11.0149
2062.85	10.8334
2065.77	10.5214
2068.69	10.9718
2071.61	11.1883
2074.53	10.5164
2077.45	10.3827
2080.37	11.2656
2083.28	11.1265
2086.2	11.6962
2089.11	11.1224
2092.02	10.4065
2094.94	9.52145
2097.85	9.42785
2100.76	9.39694
2103.66	10.5941
2106.57	11.4283
2109.48	11.4658
2112.38	11.3576
2115.29	11.5894
2118.19	11.7297
2121.09	12.5685
2123.99	12.3942
2126.89	13.3092
2129.79	14.1815
2132.69	13.9418
2135.59	14.7742
2138.48	16.4702
2141.38	17.4557
2144.27	18.1376
2147.17	19.0854
2150.06	20.1074
2152.95	20.8144
2155.84	21.4936
2158.73	21.4211
2161.61	21.4583
2164.5	21.7363
2167.38	22.7285
2170.27	23.5378
2173.15	23.925
2176.03	24.4821
2178.91	23.7406
2181.8	23.3224
2184.67	22.9916
2187.55	22.8836
2190.43	22.2318
2193.3	21.5586
2196.18	20.3924
2199.05	20.174
2201.93	19.7375
2204.8	18.7638
2207.67	18.7152
2210.54	19.1194
2213.41	19.1234
2216.27	17.1052
2219.14	16.1667
2222.01	15.369
2224.87	14.974
2227.73	13.349
2230.6	13.1186
2233.46	13.1613
2236.32	12.9781
2239.18	12.7411
2242.03	12.3583
2244.89	12.3255
2247.75	12.6191
2250.6	11.851
2253.46	11.1681
2256.31	11.647
2259.16	10.8937
2262.01	10.5327
2264.86	10.7614
2267.71	11.1722
2270.56	11.986
2273.4	11.7448
2276.25	11.8224
2279.09	11.8551
2281.94	10.9708
2284.78	9.41468
2287.62	8.58103
2290.46	8.43075
2293.3	8.09484
2296.14	7.52044
2298.98	7.98309
2301.82	9.11929
2304.65	9.76715
2307.49	10.0706
2310.32	10.6827
2313.15	11.3507
2315.98	11.3962
2318.81	10.6486
2321.64	10.284
2324.47	10.578
2327.3	10.8269
2330.12	11.1154
2332.95	11.7304
2335.77	12.4534
2338.6	12.5946
2341.42	11.1501
2344.24	10.576
2347.06	9.51441
2349.88	8.57862
2352.7	6.95198
2355.51	6.48652
2358.33	4.59436
2361.14	3.87585
2363.96	3.67867
2366.77	3.96955
2369.58	4.9711
2372.39	5.90388
2375.2	4.81139
2378.01	5.19477
2380.82	5.315
2383.63	4.9173
2386.43	3.94756
2389.24	4.18944
2392.04	3.81293
2394.84	3.57063
2397.65	4.34912
2400.45	4.67368
2403.25	4.89083
2406.05	4.70525
2408.84	4.75675
2411.64	4.4145
2414.44	5.19005
2417.23	5.21148
2420.02	5.24259
2422.82	6.43482
2425.61	6.27352
2428.4	6.85202
2431.19	8.03932
2433.98	8.28155
2436.77	8.70239
2439.55	8.58889
2442.34	8.69725
2445.12	8.90098
2447.91	8.51263
2450.69	8.05306
2453.47	6.78544
2456.25	6.65858
2459.03	4.90524
2461.81	4.25531
2464.59	3.34628
2467.36	2.3634
2470.14	1.29855
2472.92	1.21246
2475.69	1.26995
2478.46	0.42456
2481.23	0.301027
2484	-0.241803
2486.77	0.4712
2489.54	0.671302
2492.31	0.873451
2495.08	1.35796
2497.84	1.79201
2500.61	2.24658
2503.37	2.66523
2506.13	2.94863
2508.9	2.55607
2511.66	3.38678
2514.42	3.83387
2517.18	3.70421
2519.93	4.14087
2522.69	4.58687
2525.45	3.95325
2528.2	3.51162
2530.95	3.22355
2533.71	2.55538
2536.46	2.02306
2539.21	2.60116
2541.96	2.94658
2544.71	2.06455
2547.46	1.8053
2550.2	1.93189
2552.95	2.62495
2555.7	3.14914
2558.44	2.9546
2561.18	3.38627
2563.93	3.3274
2566.67	3.21788
2569.41	3.17491
2572.15	2.52429
2574.88	2.11492
2577.62	1.62809
2580.36	1.25785
2583.09	1.18486
2585.83	1.56721
2588.56	1.98768
2591.29	1.43944
2594.02	0.511366
2596.75	-0.114805
2599.48	0.206844
2602.21	-0.033637
2604.94	-0.0441085
2607.67	1.2197
2610.39	0.780197
2613.12	0.352953
2615.84	0.615752
2618.56	0.806993
2621.28	1.13339
2624.01	0.612684
2626.72	1.16915
2629.44	0.856666
2632.16	0.798232
2634.88	0.858518
2637.59	0.711927
2640.31	0.675206
2643.02	0.386829
2645.74	0.0378763
2648.45	1.10203
2651.16	1.90135
2653.87	2.41849
2656.58	2.17202
2659.29	1.40075
2661.99	1.84579
2664.7	2.38999
2667.41	2.43143
2670.11	2.77874
2672.81	3.14949
2675.51	3.2566
2678.22	3.57199
2680.92	2.88579
2683.62	3.54571
2686.31	3.99311
2689.01	4.7333
2691.71	4.90725
2694.4	5.21823
2697.1	5.52506
2699.79	6.66067
2702.49	6.9242
2705.18	7.39737
2707.87	8.05092
2710.56	8.13727
2713.25	8.57457
2715.94	8.63685
2718.62	8.92366
2721.31	8.61235
2723.99	8.10268
2726.68	8.34405
2729.36	8.33838
2732.04	7.87245
2734.73	7.93256
2737.41	8.24965
2740.08	8.29827
2742.76	8.34391
2745.44	8.15675
2748.12	8.22588
2750.79	8.39274
2753.47	8.45596
2756.14	8.39188
2758.81	8.86223
2761.49	8.86122
2764.16	8.76624
2766.83	7.9613
2769.5	7.47907
2772.16	6.49751
2774.83	5.93779
2777.5	5.24238
2780.16	4.74367
2782.83	4.50543
2785.49	4.05084
2788.15	3.50934
2790.82	3.54554
2793.48	3.66953
2796.14	3.59652
2798.79	3.94755
2801.45	3.72774
2804.11	4.04656
2806.76	4.26312
2809.42	3.83111
2812.07	3.81912
2814.73	4.63943
2817.38	5.65963
2820.03	6.84237
2822.68	8.55544
2825.33	10.701
2827.98	13.4037
2830.63	15.6714
2833.27	19.1158
2835.92	22.1707
2838.56	25.4373
2841.21	30.1015
2843.85	34.9543
2846.49	39.8743
2849.13	45.9983
2851.77	52.2883
2854.41	59.3149
2857.05	64.976
2859.69	70.6568
2862.32	76.0067
2864.96	82.3937
2867.59	87.3334
2870.23	91.1468
2872.86	95.3565
2875.49	99.3869
2878.12	103.776
2880.75	107.401
2883.38	110.509
2886.01	113.541
2888.63	117.973
2891.26	122.172
2893.89	125.882
2896.51	130.03
2899.13	135.039
2901.76	139.598
2904.38	145.965
2907	153.941
2909.62	161.201
2912.24	169.503
2914.85	178.035
2917.47	185.867
2920.09	192.214
2922.7	197.671
2925.32	201.477
2927.93	204.415
2930.54	205.71
2933.15	204.974
2935.76	204.168
2938.37	202.041
2940.98	197.973
2943.59	193.094
2946.2	186.993
2948.8	180.939
2951.41	174.547
2954.01	168.126
2956.62	160.654
2959.22	153.391
2961.82	146.563
2964.42	138.979
2967.02	132.334
2969.62	126.338
2972.22	121.099
2974.81	114.998
2977.41	110.357
2980	105.326
2982.6	98.5725
2985.19	91.0585
2987.78	83.7153
2990.38	76.8251
2992.97	70.0399
2995.56	63.5798
2998.14	57.3428
3000.73	51.2977
3003.32	45.7856
3005.91	40.5839
3008.49	36.4683
3011.07	32.2726
3013.66	27.9145
3016.24	26.1424
3018.82	23.5887
3021.4	21.0168
3023.98	18.9917
3026.56	17.6838
3029.14	17.1351
3031.71	16.8434
3034.29	18.0378
3036.87	18.7452
3039.44	19.247
3042.01	20.4802
3044.59	21.0493
3047.16	20.4357
3049.73	20.5457
3052.3	22.0527
3054.87	22.2265
3057.43	21.6667
3060	20.7193
3062.57	20.0174
3065.13	19.9796
3067.7	19.1123
3070.26	18.0933
3072.82	16.5063
3075.39	14.8847
3077.95	13.5164
3080.51	12.594
3083.07	10.4782
3085.63	8.66201
3088.18	7.22756
3090.74	6.90348
3093.29	5.66125
3095.85	5.0719
3098.4	4.55776
3100.95	3.69751
3103.51	3.83425
3106.06	4.11417
3108.61	3.04856
3111.16	2.61442
3113.71	2.69664
3116.25	2.83426
3118.8	2.5852
3121.35	2.41735
3123.89	2.90963
3126.44	3.02635
3128.98	2.96473
3131.52	1.80637
3134.06	1.34976
3136.6	0.799748
3139.14	0.0163347
3141.68	-0.804807
3144.22	-1.74741
3146.76	-2.5254
3149.29	-2.8628