File: data/Raman/poly_smoothed/Thy_00_07_43_1x_45s_532 nm_x100_100%_600 gr_mm_01.txt
#Acq. time (s)=	45
#Accumulations=	2
#Range (cm-¹)=	200...3150
#Windows=	2
#Auto scanning=	Off
#Autofocus=	Off
#Macrospot=	Off
#AutoExposure=	Off
#Spike filter=	Multiple accum.
#Delay time (s)=	0
#Binning=	1
#Readout mode=	Signal
#DeNoise=	Off
#ICS correction=	On
#Dark correction=	Off
#Inst. Process=	Off
#Detector Gain=	Best Dynamic Range
#Detector ADC=	20 kHz
#Detector temperature (°C)=	-69.85
#Instrument=	LabRAM HR Evol
#Detector=	Synapse
#Objective=	x100
#Grating=	600 gr/mm
#ND Filter=	100%
#Laser (nm)=	532
#Hole=	100.021
#Range=	Auto
#Laser Pol.=	No
#Raman. Pol.=	No
#Laser Pol. (°)=	-0.0007625
#Raman Pol. (°)=	89.9995
#Collection=	Microscope
#StageXY=	Marzhauser
#StageZ=	Marzhauser
#X (µm)=	-1465.2
#Y (µm)=	-615.7
#Z (µm)=	-228.2
#Full time(mm:ss)=	3:18
#Project=
#Sample=
#Site=
#Title=	Thy_00_07_43_2x_45s_532 nm_x100_100%_600 gr_mm
#Remark=
#Date=	29.06.2022 09:32
#Acquired=	29.06.2022 09:32:18
#Base:Fit=	10.08.2022 10:07:56
#Base:Sub=	10.08.2022 10:08:40
#Filter:Polynom=	16.08.2022 10:26:06
#AxisType[0]=Intens
#AxisUnit[0]=Cnt
#AxisType[1]=Spectr
#AxisUnit[1]=1/cm
200.523	30.3332
204.154	23.7725
207.781	18.7276
211.409	15.0243
215.034	12.6835
218.659	10.8583
222.281	8.60382
225.903	6.4728
229.522	4.8081
233.14	5.5145
236.756	4.44461
240.373	3.99472
243.986	3.84942
247.598	3.61033
251.208	3.21257
254.818	3.58105
258.427	3.52453
262.034	5.69961
265.638	5.61183
269.242	5.63676
272.844	3.3548
276.445	4.0404
280.044	4.82933
283.642	4.75746
287.238	6.986
290.833	10.3837
294.425	10.5136
298.017	12.5235
301.608	14.0083
305.198	13.3926
308.786	11.2803
312.371	11.4349
315.956	13.3245
319.54	16.666
323.122	18.0444
326.701	17.3929
330.281	18.0465
333.857	17.2633
337.434	17.2041
341.008	17.1332
344.582	17.3658
348.153	15.8
351.724	16.0513
355.292	13.9485
358.861	11.1244
362.426	10.4634
365.99	12.7956
369.555	12.348
373.116	12.0434
376.676	12.8895
380.236	12.9148
383.793	11.6934
387.349	10.6646
390.903	8.40835
394.456	7.41638
398.007	8.05762
401.56	11.2235
405.108	11.5273
408.656	12.6528
412.202	13.3072
415.746	12.9002
419.29	14.3206
422.831	13.796
426.37	12.7684
429.909	12.8568
433.447	11.1569
436.983	10.8622
440.519	9.04917
444.052	8.32221
447.583	9.78543
451.114	9.92919
454.643	11.9395
458.169	11.6764
461.696	12.7885
465.222	12.8549
468.744	14.0083
472.267	15.8176
475.787	16.7776
479.307	17.1307
482.823	18.4183
486.341	19.718
489.855	22.3071
493.37	23.459
496.881	25.6543
500.391	26.7128
503.902	27.4884
507.409	29.322
510.915	27.3552
514.42	27.5185
517.925	28.2447
521.427	27.6093
524.928	27.7775
528.427	27.9044
531.925	28.0218
535.422	27.3417
538.917	28.2252
542.411	25.4951
545.903	25.3888
549.395	24.1603
552.884	23.6048
556.373	22.7901
559.86	22.1969
563.346	19.6011
566.831	20.7217
570.314	18.7809
573.794	18.5453
577.274	17.5378
580.754	17.1094
584.23	17.9697
587.706	18.0254
591.181	17.886
594.653	17.9382
598.126	16.4527
601.595	17.7915
605.065	17.6806
608.532	18.0516
611.999	19.698
615.463	19.6963
618.928	19.6837
622.389	21.0971
625.851	21.3428
629.31	22.4745
632.767	23.2547
636.223	22.7221
639.68	24.064
643.134	25.315
646.586	26.7613
650.037	27.8088
653.486	28.9517
656.936	30.9486
660.383	32.764
663.829	34.6737
667.273	36.7172
670.716	39.1355
674.158	39.624
677.598	40.7968
681.035	43.3685
684.473	42.0255
687.909	43.5746
691.344	44.6276
694.778	46.0315
698.211	45.7887
701.64	44.9664
705.07	45.7598
708.498	46.0002
711.924	48.0041
715.35	47.7455
718.774	48.8953
722.196	50.8257
725.618	52.6828
729.037	54.4595
732.456	57.8898
735.873	60.0841
739.289	61.5688
742.703	64.6642
746.116	68.4524
749.529	72.147
752.938	75.8576
756.347	79.3452
759.756	81.9256
763.162	84.2181
766.567	87.4506
769.97	88.8344
773.372	91.9079
776.773	93.2283
780.174	92.7862
783.573	92.9213
786.97	94.7901
790.365	97.8813
793.76	97.9621
797.153	98.3498
800.543	97.985
803.933	95.1493
807.322	94.0939
810.71	91.1474
814.097	88.4731
817.483	86.5013
820.865	84.5797
824.248	82.2529
827.629	82.3897
831.008	81.8743
834.387	81.2124
837.765	80.0127
841.139	78.6905
844.514	76.946
847.886	76.8655
851.259	75.7132
854.629	75.8816
857.997	75.2081
861.366	74.1506
864.732	73.8596
868.098	73.3567
871.461	73.8063
874.823	72.3583
878.184	70.4837
881.545	68.3581
884.903	65.7391
888.26	62.5242
891.616	62.1715
894.97	61.3068
898.323	61.1187
901.675	60.2003
905.026	59.5961
908.375	58.7717
911.723	59.3638
915.07	57.4891
918.415	56.889
921.76	55.4707
925.103	55.2234
928.443	54.1964
931.783	54.7205
935.123	55.1447
938.461	54.1383
941.796	52.6914
945.131	52.2238
948.465	51.3574
951.797	50.6893
955.128	48.2996
958.457	46.1872
961.786	43.1292
965.113	43.6784
968.44	42.6553
971.763	43.269
975.086	44.7103
978.409	44.2539
981.729	43.8967
985.048	42.8233
988.367	41.9411
991.683	40.5241
994.998	40.1945
998.312	38.2853
1001.62	37.6977
1004.94	35.8471
1008.25	35.2785
1011.56	34.7037
1014.86	34.3439
1018.17	32.325
1021.48	31.5847
1024.78	30.4137
1028.08	28.378
1031.38	26.1046
1034.68	23.4171
1037.98	21.9524
1041.28	21.0614
1044.57	22.311
1047.87	23.1588
1051.16	22.2036
1054.45	23.269
1057.75	22.5961
1061.04	21.2918
1064.32	21.0141
1067.61	21.8856
1070.9	21.9018
1074.18	22.0292
1077.47	21.7078
1080.75	20.661
1084.03	20.3698
1087.31	18.8089
1090.59	18.114
1093.86	19.4271
1097.14	20.0083
1100.41	19.7849
1103.69	20.403
1106.96	21.2141
1110.23	20.4597
1113.5	19.0456
1116.77	17.8158
1120.03	17.7534
1123.3	17.0439
1126.56	15.9535
1129.83	14.9994
1133.09	15.9019
1136.35	15.8944
1139.61	14.0663
1142.86	14.0587
1146.12	15.1645
1149.38	14.0753
1152.63	13.1289
1155.88	11.4845
1159.14	10.5266
1162.39	8.41911
1165.63	6.38111
1168.88	5.59502
1172.13	7.5338
1175.38	9.85479
1178.62	11.0063
1181.86	12.2488
1185.1	11.9742
1188.34	11.2654
1191.58	9.99784
1194.82	10.5244
1198.06	13.5311
1201.29	14.6527
1204.53	18.3672
1207.76	22.065
1210.99	25.596
1214.22	29.4538
1217.45	33.3752
1220.68	34.9921
1223.91	38.8544
1227.13	41.5212
1230.36	44.0812
1233.58	45.5703
1236.8	45.8793
1240.02	45.7858
1243.24	47.7439
1246.46	48.2787
1249.67	49.739
1252.89	49.2499
1256.1	47.4393
1259.32	45.7314
1262.53	44.3787
1265.74	43.2755
1268.95	42.1854
1272.15	42.6748
1275.36	45.1629
1278.57	46.6236
1281.77	47.8339
1284.97	49.9927
1288.18	51.4402
1291.38	52.7932
1294.58	55.2606
1297.78	57.0465
1300.97	58.2897
1304.17	61.4148
1307.36	63.7453
1310.55	64.032
1313.75	66.0014
1316.94	68.9493
1320.13	70.5186
1323.32	70.0745
1326.5	69.9693
1329.69	69.8813
1332.87	67.5526
1336.06	67.017
1339.24	68.1596
1342.42	65.7865
1345.6	63.9897
1348.78	63.1242
1351.96	60.7217
1355.13	59.6135
1358.31	56.726
1361.48	54.3511
1364.65	52.4004
1367.82	49.6458
1370.99	47.3656
1374.16	44.0162
1377.33	42.5956
1380.5	40.3088
1383.66	39.4222
1386.83	37.84
1389.99	37.8094
1393.15	37.2405
1396.31	35.1516
1399.47	35.2815
1402.63	35.6196
1405.78	35.8926
1408.94	38.1369
1412.1	40.0553
1415.25	44.496
1418.4	47.1915
1421.55	50.038
1424.7	54.7448
1427.85	59.7062
1431	64.8118
1434.14	70.4809
1437.29	73.9191
1440.43	76.8612
1443.57	78.9044
1446.71	80.3344
1449.85	81.1877
1452.99	80.615
1456.13	80.3429
1459.26	77.5255
1462.4	74.2559
1465.54	69.3525
1468.67	63.3966
1471.8	57.9084
1474.93	53.6044
1478.06	48.2266
1481.19	42.8134
1484.31	38.4839
1487.44	34.5272
1490.56	31.624
1493.69	28.4437
1496.81	25.3485
1499.93	24.022
1503.05	22.5706
1506.17	22.2148
1509.28	21.0961
1512.4	19.5131
1515.52	17.8911
1518.63	18.2799
1521.74	19.2986
1524.85	20.7694
1527.96	22.5076
1531.07	24.7247
1534.18	25.0206
1537.29	24.9917
1540.39	26.7196
1543.5	28.1827
1546.6	31.6623
1549.7	33.6351
1552.8	37.2802
1555.9	39.6118
1559	43.3225
1562.1	46.1389
1565.19	48.1265
1568.29	51.6387
1571.38	53.1833
1574.47	54.4512
1577.56	56.1901
1580.66	57.7269
1583.74	58.503
1586.83	59.0823
1589.92	60.2574
1593.01	60.053
1596.09	61.0588
1599.17	61.3741
1602.25	61.4059
1605.34	60.126
1608.41	58.7646
1611.49	57.1675
1614.57	55.4081
1617.65	56.2708
1620.72	56.6676
1623.79	56.1423
1626.87	56.8348
1629.94	58.4899
1633.01	59.8694
1636.08	62.0792
1639.15	64.0861
1642.21	65.2693
1645.28	66.3832
1648.34	68.7647
1651.41	70.1864
1654.47	71.6729
1657.53	72.3114
1660.59	72.9548
1663.65	71.8347
1666.71	70.6519
1669.76	68.914
1672.82	65.12
1675.87	62.2069
1678.93	57.1135
1681.98	53.5991
1685.03	50.9728
1688.08	46.557
1691.13	43.0881
1694.17	39.9812
1697.22	34.8247
1700.27	30.8871
1703.31	28.5566
1706.35	25.6653
1709.39	23.1669
1712.43	20.6399
1715.47	17.4987
1718.51	15.1478
1721.55	14.9235
1724.58	13.9077
1727.62	12.1441
1730.65	11.9523
1733.68	11.1156
1736.72	9.37609
1739.74	8.74812
1742.77	7.30183
1745.8	6.54138
1748.83	6.10686
1751.85	6.38878
1754.88	6.51167
1757.9	7.15909
1760.92	6.7864
1763.95	5.18582
1766.96	4.95209
1769.98	3.43947
1773	2.36652
1776.02	3.39541
1779.03	3.37407
1782.05	2.72618
1785.06	3.13986
1788.07	2.30056
1791.08	2.18958
1794.09	2.70538
1797.1	3.13849
1800.11	3.22062
1803.12	3.55258
1806.12	2.65718
1809.12	3.23374
1812.13	3.38595
1815.13	3.47395
1818.13	4.41271
1821.13	4.30736
1824.13	4.50134
1827.13	4.46147
1830.12	3.67276
1833.12	1.90933
1836.11	1.6961
1839.1	1.68135
1842.09	1.43492
1845.09	1.63154
1848.08	1.84004
1851.06	2.34154
1854.05	1.74163
1857.04	1.44676
1860.02	1.04692
1863.01	1.18249
1865.99	1.13473
1868.97	2.43735
1871.95	2.77425
1874.93	3.34184
1877.91	3.98618
1880.89	4.43562
1882.46	4.44104
1885.45	3.9197
1888.43	4.77551
1891.42	4.91657
1894.41	5.28501
1897.39	5.00563
1900.37	5.07481
1903.36	4.99341
1906.34	4.7824
1909.32	5.50302
1912.29	5.84588
1915.27	6.40449
1918.25	7.20996
1921.23	6.26583
1924.2	5.85952
1927.17	5.9547
1930.15	5.23119
1933.12	5.45991
1936.09	5.37727
1939.06	5.26608
1942.02	5.65647
1944.99	4.55683
1947.96	4.31786
1950.92	2.90145
1953.88	1.74117
1956.85	2.2951
1959.81	2.69195
1962.77	2.73041
1965.73	2.55253
1968.69	3.22455
1971.64	4.24983
1974.6	4.23669
1977.55	4.67573
1980.51	5.06832
1983.46	5.1579
1986.41	5.52002
1989.36	5.60343
1992.31	5.32912
1995.26	5.00969
1998.21	4.48471
2001.15	4.7054
2004.1	4.16817
2007.04	3.36739
2009.99	3.33695
2012.93	3.62412
2015.87	3.78976
2018.81	2.72381
2021.75	3.02956
2024.68	2.95963
2027.62	3.93126
2030.56	4.65044
2033.49	4.8641
2036.42	5.66529
2039.36	6.3209
2042.29	7.92704
2045.22	9.41135
2048.14	9.35387
2051.07	10.5535
2054	10.3062
2056.93	9.75653
2059.85	9.80674
2062.77	10.4154
2065.7	9.97958
2068.62	9.48552
2071.54	8.91431
2074.46	9.53198
2077.38	9.09846
2080.29	10.6756
2083.21	10.9814
2086.12	10.7766
2089.04	10.6569
2091.95	9.36125
2094.86	9.30817
2097.77	9.94551
2100.68	10.571
2103.59	9.81132
2106.5	8.82542
2109.41	8.35537
2112.31	8.91765
2115.21	7.58772
2118.12	6.62348
2121.02	5.34359
2123.92	4.26126
2126.82	3.7137
2129.72	2.7485
2132.62	1.68524
2135.51	1.03549
2138.41	0.298124
2141.31	0.513738
2144.2	0.715573
2147.09	2.23984
2149.98	3.64807
2152.87	4.73972
2155.76	5.12313
2158.65	5.09361
2161.54	6.10464
2164.43	7.16704
2167.31	7.74758
2170.2	8.53074
2173.08	8.23521
2175.96	7.80419
2178.84	7.94547
2181.72	7.88666
2184.6	8.27387
2187.48	8.26752
2190.36	8.55946
2193.23	7.71565
2196.11	7.08916
2198.98	6.13504
2201.85	5.30072
2204.72	5.22433
2207.59	4.68197
2210.46	5.41905
2213.33	7.23035
2216.2	7.13625
2219.07	6.39323
2221.93	6.2235
2224.8	5.81543
2227.66	5.02266
2230.52	4.80676
2233.39	4.19073
2236.25	4.12788
2239.1	3.56219
2241.96	3.63017
2244.82	3.26354
2247.68	3.76003
2250.53	4.41103
2253.38	4.44452
2256.24	4.84091
2259.09	6.07496
2261.94	5.31994
2264.79	4.4819
2267.64	3.89066
2270.49	5.16074
2273.33	5.7806
2276.18	5.90245
2279.02	6.61612
2281.87	7.19893
2284.71	6.6385
2287.55	5.25922
2290.39	4.99774
2293.23	4.80871
2296.07	5.42197
2298.91	5.67784
2301.74	5.98727
2304.58	6.3977
2307.41	6.20562
2310.25	6.82142
2313.08	6.43216
2315.91	6.35353
2318.74	5.91981
2321.57	6.2255
2324.4	6.72731
2327.23	7.31727
2330.05	7.65286
2332.88	6.97215
2335.7	6.18873
2338.52	6.04688
2341.35	5.82261
2344.17	5.19708
2346.99	5.97392
2349.81	5.535
2352.62	4.82793
2355.44	4.46086
2358.26	4.99879
2361.07	4.67797
2363.89	5.69733
2366.7	5.48021
2369.51	5.88024
2372.32	6.25822
2375.13	5.69615
2377.94	5.40984
2380.75	4.91796
2383.56	3.8185
2386.36	4.0263
2389.17	3.75815
2391.97	3.9198
2394.77	3.54571
2397.58	3.50958
2400.38	3.46844
2403.18	3.57208
2405.97	2.61258
2408.77	3.10213
2411.57	3.29522
2414.37	4.75103
2417.16	4.49785
2419.95	5.13783
2422.75	4.66843
2425.54	4.66368
2428.33	5.10207
2431.12	5.58358
2433.91	5.75339
2436.7	5.73228
2439.48	6.19993
2442.27	5.3245
2445.05	6.36835
2447.84	5.75482
2450.62	5.55072
2453.4	5.25237
2456.18	5.21399
2458.96	4.36397
2461.74	4.75318
2464.52	4.11731
2467.29	3.79952
2470.07	3.8288
2472.85	4.14535
2475.62	3.88639
2478.39	4.05197
2481.16	2.98877
2483.93	2.6623
2486.7	1.64549
2489.47	0.990595
2492.24	0.506514
2495.01	1.25343
2497.77	1.06547
2500.54	0.700736
2503.3	0.133573
2506.06	-0.405731
2508.83	-0.0663022
2511.59	0.0435153
2514.35	-0.0748859
2517.11	-0.580158
2519.86	-1.63275
2522.62	-2.15082
2525.38	-1.76991
2528.13	-1.04998
2530.89	-0.276767
2533.64	0.265981
2536.39	0.806107
2539.14	1.61099
2541.89	1.94967
2544.64	3.8587
2547.39	4.14699
2550.14	4.95039
2552.88	6.33448
2555.63	7.95163
2558.37	8.91677
2561.11	9.69622
2563.86	9.60179
2566.6	9.60934
2569.34	9.94545
2572.08	9.75966
2574.82	9.585
2577.55	9.12445
2580.29	7.37988
2583.02	6.07213
2585.76	5.26155
2588.49	4.59097
2591.22	3.8794
2593.96	4.51941
2596.69	3.79135
2599.42	2.36536
2602.14	1.99788
2604.87	1.49003
2607.6	1.93187
2610.32	2.53271
2613.05	3.06346
2615.77	2.46094
2618.49	3.15119
2621.22	3.19057
2623.94	3.09805
2626.66	2.14915
2629.37	2.13863
2632.09	1.77173
2634.81	2.09371
2637.53	2.18975
2640.24	2.31039
2642.96	2.5584
2645.67	1.82866
2648.38	3.02522
2651.09	2.84777
2653.8	3.53773
2656.51	4.78535
2659.22	4.87735
2661.93	5.11018
2664.63	6.47794
2667.34	5.84184
2670.04	7.40328
2672.75	6.76867
2675.45	7.42152
2678.15	7.15832
2680.85	6.70974
2683.55	6.97072
2686.25	5.79269
2688.94	5.62669
2691.64	5.20755
2694.34	5.31179
2697.03	5.84515
2699.73	6.23505
2702.42	7.12724
2705.11	8.02976
2707.8	9.06821
2710.49	9.79314
2713.18	11.755
2715.87	13.4049
2718.55	13.3674
2721.24	14.136
2723.93	14.4054
2726.61	13.9248
2729.29	14.2784
2731.98	14.0641
2734.66	12.3297
2737.34	11.8286
2740.02	10.9396
2742.7	9.97339
2745.37	8.21785
2748.05	6.50154
2750.72	5.45041
2753.4	4.40056
2756.07	3.5357
2758.75	2.22052
2761.42	1.87163
2764.09	1.52329
2766.76	1.06015
2769.43	0.768617
2772.1	1.24156
2774.76	0.237635
2777.43	0.153209
2780.1	0.33824
2782.76	-0.538912
2785.42	-0.146882
2788.09	-0.531438
2790.75	-0.0254225
2793.41	0.760812
2796.07	0.798925
2798.73	1.15828
2801.39	0.808396
2804.04	1.65868
2806.7	0.313989
2809.35	-1.20577
2812.01	-1.46288
2814.66	-1.27558
2817.31	-0.605434
2819.96	0.780542
2822.61	2.82128
2825.26	4.78703
2827.91	7.8101
2830.56	11.2841
2833.21	14.9246
2835.85	19.0638
2838.5	24.8432
2841.14	30.5093
2843.78	38.1717
2846.42	44.948
2849.06	52.9621
2851.71	61.6236
2854.34	71.4166
2856.98	80.9007
2859.62	89.4699
2862.26	98.6752
2864.89	105.77
2867.53	112.497
2870.16	118.649
2872.79	123.613
2875.42	128.264
2878.05	132.675
2880.68	135.816
2883.31	139.852
2885.94	143.753
2888.57	146.712
2891.19	149.351
2893.82	152.605
2896.44	155.78
2899.07	159.91
2901.69	165.17
2904.31	170.305
2906.93	177.125
2909.55	185.017
2912.17	193.538
2914.79	202.915
2917.41	210.986
2920.02	217.838
2922.64	223.58
2925.25	227.844
2927.86	230.164
2930.48	230.224
2933.09	230.591
2935.7	228.435
2938.31	224.121
2940.92	218.67
2943.53	212.271
2946.13	204.524
2948.74	195.986
2951.34	187.481
2953.95	178.708
2956.55	170.222
2959.15	161.435
2961.75	153.266
2964.35	145.922
2966.95	139.367
2969.55	133.53
2972.15	128.089
2974.75	122.438
2977.34	117.002
2979.94	110.072
2982.53	103.708
2985.13	96.2422
2987.72	89.4398
2990.31	82.1883
2992.9	74.4003
2995.49	67.4217
2998.08	60.0892
3000.67	52.7812
3003.25	45.422
3005.84	38.6162
3008.42	33.1917
3011.01	27.8892
3013.59	23.0822
3016.17	18.7903
3018.76	15.8959
3021.34	13.1634
3023.92	10.9992
3026.49	8.86553
3029.07	7.69427
3031.65	7.15065
3034.23	7.66442
3036.8	8.56433
3039.38	9.28153
3041.95	10.4045
3044.52	11.2305
3047.09	11.9908
3049.66	12.0417
3052.23	13.0367
3054.8	12.9066
3057.37	12.7892
3059.94	13.1474
3062.5	13.1601
3065.07	13.4114
3067.63	12.712
3070.2	13.3048
3072.76	12.487
3075.32	11.5436
3077.88	9.78344
3080.44	8.24679
3083	6.75244
3085.56	5.36988
3088.12	4.07168
3090.67	3.38615
3093.23	3.84842
3095.78	3.84916
3098.34	3.98676
3100.89	3.78628
3103.44	3.66151
3105.99	3.82626
3108.54	4.5454
3111.09	4.96694
3113.64	4.79221
3116.19	5.03969
3118.74	5.68826
3121.28	6.9523
3123.83	8.20056
3126.37	9.66231
3128.91	10.5871
3131.46	10.9547
3134	12.0001
3136.54	12.6366
3139.08	13.3799
3141.62	13.9057
3144.16	15.3696
3146.69	17.553
3149.23	20.4681