File: data/Raman/poly_smoothed/Thy_10_08_03_1x_45s_532 nm_x100_100%_600 gr_mm_01.txt
#Acq. time (s)=	45
#Accumulations=	2
#Range (cm-¹)=	200...3150
#Windows=	2
#Auto scanning=	Off
#Autofocus=	Off
#Macrospot=	Off
#AutoExposure=	Off
#Spike filter=	Multiple accum.
#Delay time (s)=	0
#Binning=	1
#Readout mode=	Signal
#DeNoise=	Off
#ICS correction=	On
#Dark correction=	Off
#Inst. Process=	Off
#Detector Gain=	Best Dynamic Range
#Detector ADC=	20 kHz
#Detector temperature (°C)=	-69.85
#Instrument=	LabRAM HR Evol
#Detector=	Synapse
#Objective=	x100
#Grating=	600 gr/mm
#ND Filter=	100%
#Laser (nm)=	532
#Hole=	100.021
#Range=	Auto
#Laser Pol.=	No
#Raman. Pol.=	No
#Laser Pol. (°)=	-0.0007625
#Raman Pol. (°)=	89.9995
#Collection=	Microscope
#StageXY=	Marzhauser
#StageZ=	Marzhauser
#X (µm)=	2155.6
#Y (µm)=	1216.2
#Z (µm)=	442.65
#Full time(mm:ss)=	3:05
#Project=
#Sample=
#Site=
#Title=	Thy_10_08_03_2x_45s_532 nm_x100_100%_600 gr_mm
#Remark=
#Date=	05.07.2022 14:25
#Acquired=	05.07.2022 14:25:03
#Base:Fit=	10.08.2022 09:45:33
#Base:Fit=	10.08.2022 09:46:03
#Base:Fit=	10.08.2022 09:46:25
#Base:Sub=	10.08.2022 09:46:49
#Filter:Polynom=	16.08.2022 10:24:56
#AxisType[0]=Intens
#AxisUnit[0]=Cnt
#AxisType[1]=Spectr
#AxisUnit[1]=1/cm
200.43	4.49631
204.059	8.3945
207.688	9.77622
211.314	11.2805
214.941	12.3723
218.564	13.4781
222.186	13.712
225.809	14.4046
229.428	15.3634
233.045	15.8591
236.663	16.7296
240.278	17.3296
243.891	18.6318
247.503	20.0143
251.116	19.5152
254.725	19.0071
258.333	20.6356
261.939	21.5277
265.544	22.4937
269.148	21.6671
272.75	20.7306
276.351	19.9728
279.95	19.8793
283.548	18.3346
287.144	16.0064
290.739	14.6893
294.333	14.8068
297.925	13.6265
301.514	13.5905
305.104	13.823
308.692	12.9523
312.279	13.7612
315.862	13.1667
319.446	14.1875
323.029	15.1968
326.608	15.2074
330.188	15.6693
333.766	15.5092
337.341	15.9036
340.917	17.3338
344.489	17.6195
348.062	17.579
351.631	16.8042
355.201	15.9511
358.768	15.3216
362.333	14.7606
365.899	14.2056
369.462	12.8064
373.023	12.5154
376.585	12.0631
380.143	11.3001
383.7	12.8177
387.256	12.4706
390.812	13.0006
394.365	13.1061
397.916	14.1886
401.467	14.8164
405.015	14.3144
408.563	13.5221
412.109	12.3193
415.654	10.9699
419.197	11.6326
422.739	11.3021
426.279	11.1518
429.819	11.2502
433.356	9.68694
436.891	8.98544
440.426	8.33088
443.96	7.60778
447.492	8.55547
451.021	7.09275
454.551	7.33774
458.079	7.66803
461.604	7.10727
465.13	7.05151
468.654	7.40178
472.175	6.8473
475.696	7.04586
479.215	8.07305
482.733	9.07624
486.249	9.86519
489.765	10.5003
493.278	9.65562
496.789	10.0908
500.301	10.9363
503.81	11.8642
507.317	12.6856
510.825	13.5087
514.33	14.3964
517.833	13.3036
521.335	12.4909
524.836	12.172
528.335	12.6762
531.835	12.2229
535.332	11.6829
538.827	10.2696
542.321	10.3078
545.814	8.9327
549.305	7.18358
552.795	5.42094
556.282	3.18922
559.769	3.12677
563.255	2.55805
566.739	0.99973
570.223	0.697721
573.705	0.64413
577.183	-0.00381055
580.663	-0.433301
584.141	-0.617986
587.615	-1.30959
591.09	-1.30616
594.564	0.183587
598.035	0.102378
601.506	-0.130051
604.974	-0.0497429
608.443	0.900328
611.908	2.36975
615.374	2.62147
618.837	2.89318
622.3	3.50284
625.761	4.70062
629.219	5.53814
632.677	6.95351
636.135	7.64028
639.59	8.71972
643.043	9.67159
646.495	10.9376
649.948	11.9104
653.398	12.4624
656.846	13.5559
660.293	14.8882
663.738	14.7432
667.183	15.0119
670.626	14.4782
674.067	15.4417
677.508	17.0341
680.947	19.5596
684.385	19.9868
687.821	21.1321
691.254	22.5459
694.688	24.0567
698.121	25.6725
701.552	26.34
704.98	28.4192
708.409	29.9951
711.836	31.4075
715.26	33.2802
718.685	34.8574
722.108	37.1775
725.528	39.3545
728.949	41.0631
732.367	43.2843
735.785	44.733
739.2	46.9367
742.614	47.4926
746.028	49.4135
749.439	50.8639
752.849	52.8104
756.26	55.5559
759.667	58.8805
763.073	61.4208
766.477	63.8199
769.883	65.8744
773.285	67.5408
776.686	69.4387
780.085	69.5392
783.484	70.9573
786.881	71.7053
790.276	73.1165
793.671	73.7213
797.064	75.4731
800.456	76.9692
803.846	78.9837
807.234	81.0783
810.622	83.4936
814.008	83.892
817.394	84.0168
820.778	83.3668
824.159	84.3318
827.541	84.466
830.921	83.752
834.298	83.4991
837.676	82.1005
841.051	80.8553
844.426	78.3992
847.798	76.881
851.171	73.9682
854.54	71.5887
857.911	67.4769
861.278	64.4405
864.645	61.5694
868.01	59.6577
871.373	57.1281
874.735	55.9205
878.097	54.8256
881.457	53.079
884.815	53.1534
888.172	53.9683
891.528	53.5829
894.882	53.1875
898.237	53.4339
901.589	53.834
904.94	53.9391
908.289	55.2882
911.635	53.95
914.982	55.2118
918.328	53.8571
921.672	53.1983
925.015	52.5868
928.357	52.206
931.698	51.1683
935.035	49.9996
938.373	48.9076
941.71	47.8133
945.044	46.8826
948.378	44.798
951.709	42.2572
955.041	39.3513
958.372	37.1131
961.699	35.4162
965.027	34.2451
968.352	34.3403
971.676	34.9999
975	35.1491
978.322	36.0235
981.642	35.1646
984.962	34.5236
988.28	33.6469
991.596	32.4149
994.911	31.6595
998.227	30.5926
1001.54	28.6197
1004.85	27.3398
1008.16	27.2222
1011.47	26.8026
1014.78	25.8365
1018.08	25.3573
1021.39	23.9178
1024.69	22.6902
1028	21.9165
1031.3	19.9279
1034.6	18.3222
1037.9	17.1438
1041.19	16.6332
1044.49	17.49
1047.78	19.295
1051.08	20.165
1054.37	19.1927
1057.66	20.3056
1060.95	20.4527
1064.24	19.5669
1067.53	18.6137
1070.81	17.7391
1074.1	17.7163
1077.38	16.4369
1080.66	15.5867
1083.94	15.0078
1087.22	12.9864
1090.5	11.9354
1093.78	10.1262
1097.05	10.1186
1100.33	9.82374
1103.6	10.1504
1106.87	11.0108
1110.14	10.1158
1113.41	10.4805
1116.68	10.0377
1119.95	10.6844
1123.21	10.898
1126.48	11.205
1129.74	11.057
1133	9.66813
1136.26	10.4146
1139.52	11.1878
1142.78	9.8607
1146.04	10.365
1149.29	9.9809
1152.55	9.13135
1155.8	7.98139
1159.05	6.67114
1162.3	4.53981
1165.55	2.87792
1168.8	1.63296
1172.05	2.56693
1175.29	2.94915
1178.54	2.90371
1181.78	3.86302
1185.02	4.60261
1188.26	5.75345
1191.5	6.44408
1194.74	7.40688
1197.97	8.98272
1201.21	10.3008
1204.44	12.457
1207.68	14.2845
1210.91	17.1619
1214.14	20.9836
1217.37	23.9927
1220.59	27.2487
1223.82	28.8936
1227.05	31.7078
1230.27	33.0553
1233.49	32.8013
1236.72	34.4912
1239.94	34.9044
1243.16	35.8428
1246.37	36.9834
1249.59	37.5295
1252.8	38.3104
1256.02	37.7088
1259.23	38.4541
1262.44	38.8744
1265.66	38.5406
1268.86	39.8146
1272.07	40.9878
1275.28	42.2143
1278.48	43.454
1281.69	45.0205
1284.89	47.1741
1288.09	47.6533
1291.29	48.125
1294.49	49.0297
1297.69	49.6767
1300.89	50.6655
1304.08	51.8423
1307.28	52.7015
1310.47	54.278
1313.66	55.1744
1316.85	56.2788
1320.04	57.9346
1323.23	58.715
1326.42	58.141
1329.61	58.4211
1332.79	56.8433
1335.97	55.0243
1339.16	53.7985
1342.34	52.0866
1345.52	50.8344
1348.7	50.7812
1351.87	49.168
1355.05	46.349
1358.22	43.7135
1361.4	41.5123
1364.57	37.8142
1367.74	35.5166
1370.91	32.7619
1374.08	31.7935
1377.25	30.6068
1380.41	30.3468
1383.58	31.1477
1386.74	31.8219
1389.91	32.0416
1393.07	32.1422
1396.23	32.5967
1399.39	33.0397
1402.55	32.021
1405.7	32.0409
1408.86	32.1306
1412.01	34.0835
1415.17	37.4745
1418.32	40.1366
1421.47	43.7062
1424.62	47.3905
1427.77	51.0385
1430.91	54.4124
1434.06	58.0781
1437.2	61.6158
1440.35	63.9017
1443.49	64.5248
1446.63	65.1078
1449.77	64.5213
1452.91	64.3235
1456.05	62.8115
1459.18	59.9605
1462.32	57.0007
1465.45	52.3774
1468.59	48.2215
1471.72	42.936
1474.85	37.9471
1477.98	32.0481
1481.1	27.2542
1484.23	22.557
1487.36	20.8925
1490.48	18.5315
1493.61	16.291
1496.73	14.3448
1499.85	12.8712
1502.97	11.944
1506.09	11.2547
1509.2	12.6697
1512.32	13.356
1515.43	14.3351
1518.55	13.8997
1521.66	14.0809
1524.77	15.3397
1527.88	16.8605
1530.99	18.9639
1534.1	20.0951
1537.21	21.1662
1540.31	22.6052
1543.42	23.18
1546.52	24.5185
1549.62	25.069
1552.72	28.2029
1555.82	29.2675
1558.92	30.989
1562.02	32.42
1565.11	34.0489
1568.21	35.0885
1571.3	37.1232
1574.39	37.8708
1577.49	37.6652
1580.57	39.5434
1583.66	41.9616
1586.75	43.2866
1589.84	43.4541
1592.92	43.935
1596.01	45.0889
1599.09	44.6605
1602.17	44.6158
1605.25	43.9812
1608.33	43.8223
1611.41	42.7536
1614.49	41.24
1617.57	41.528
1620.64	41.1837
1623.72	41.8197
1626.79	41.9873
1629.86	41.6927
1632.93	43.5437
1636	44.8875
1639.07	46.5149
1642.13	49.0813
1645.2	50.2077
1648.26	51.7178
1651.33	53.3108
1654.39	54.23
1657.45	55.6136
1660.51	55.8375
1663.57	54.5689
1666.63	52.391
1669.68	50.3088
1672.74	48.2328
1675.79	45.686
1678.85	41.442
1681.9	38.7323
1684.95	36.0979
1688	30.9111
1691.05	26.7258
1694.09	22.2884
1697.14	18.5854
1700.18	14.6759
1703.23	11.5691
1706.27	11.0134
1709.31	8.55248
1712.35	6.3293
1715.39	5.05616
1718.43	3.65553
1721.47	2.72471
1724.5	2.44064
1727.54	1.50773
1730.57	0.361362
1733.61	0.421633
1736.64	-0.524035
1739.67	-0.979064
1742.7	-0.636656
1745.72	-0.0755618
1748.75	1.0794
1751.77	1.48914
1754.8	1.85809
1757.82	2.63728
1760.84	1.99682
1763.87	1.08016
1766.89	1.00861
1769.91	1.91098
1772.92	2.51691
1775.94	2.88533
1778.95	3.17732
1781.97	3.2515
1784.98	3.26895
1787.99	3.51312
1791.01	3.45948
1794.01	3.00816
1797.02	2.67765
1800.03	2.23344
1803.04	2.6631
1806.04	2.3094
1809.05	2.31039
1812.05	2.35768
1815.05	2.99109
1818.05	3.20182
1821.05	3.78948
1824.05	4.07632
1827.05	4.47309
1830.04	4.48918
1833.04	4.09572
1836.03	3.70099
1839.03	3.85349
1842.02	4.67906
1845.01	4.71619
1848	5.70793
1850.99	5.89219
1853.97	6.19999
1856.96	6.0546
1859.94	6.3299
1862.93	7.4741
1865.91	8.00155
1868.89	8.44702
1871.87	9.75924
1874.85	10.2788
1877.83	10.9924
1880.81	11.0936
1882.57	10.8111
1885.56	11.2598
1888.55	11.3607
1891.54	11.9757
1894.52	12.618
1897.51	12.9235
1900.49	12.6379
1903.47	12.1484
1906.45	11.2707
1909.43	10.4899
1912.41	11.0251
1915.39	10.545
1918.37	10.5179
1921.34	10.4876
1924.32	10.2878
1927.29	10.0746
1930.26	9.57588
1933.23	8.96691
1936.2	9.12826
1939.17	8.20171
1942.14	8.53109
1945.11	7.94931
1948.07	7.8471
1951.04	8.12899
1954	8.592
1956.96	9.76329
1959.93	10.7703
1962.89	11.0011
1965.85	10.9996
1968.8	12.2037
1971.76	12.5886
1974.72	12.5467
1977.67	12.2115
1980.63	11.9561
1983.58	12.1578
1986.53	13.3058
1989.48	13.2784
1992.43	13.9884
1995.38	14.2079
1998.32	14.0707
2001.27	14.0847
2004.22	13.7333
2007.16	13.2125
2010.1	13.7131
2013.04	12.002
2015.98	11.5674
2018.92	11.8282
2021.86	11.8771
2024.8	12.8719
2027.74	12.8858
2030.67	12.5632
2033.61	12.8096
2036.54	12.8579
2039.47	13.8525
2042.4	13.3338
2045.33	13.347
2048.26	13.0891
2051.19	12.5422
2054.12	12.2592
2057.04	11.976
2059.97	12.4795
2062.89	12.4383
2065.81	13.116
2068.73	14.5203
2071.65	15.4299
2074.57	15.6577
2077.49	14.7505
2080.41	14.4327
2083.32	14.6355
2086.24	14.6352
2089.15	15.8506
2092.07	16.3011
2094.98	16.7526
2097.89	17.6496
2100.8	17.936
2103.71	18.2941
2106.61	18.1613
2109.52	18.8681
2112.43	19.1256
2115.33	18.1048
2118.23	17.4665
2121.13	17.7221
2124.04	17.8892
2126.94	18.4572
2129.83	19.5756
2132.73	20.6179
2135.63	22.4756
2138.53	23.1522
2141.42	24.6825
2144.31	25.6642
2147.21	27.4825
2150.1	28.9438
2152.99	29.9975
2155.88	30.7509
2158.77	31.5689
2161.65	31.8186
2164.54	33.3095
2167.43	33.2721
2170.31	33.9773
2173.19	33.6808
2176.07	32.1974
2178.96	31.8517
2181.84	31.8423
2184.72	29.8544
2187.59	28.9616
2190.47	28.748
2193.35	28.4992
2196.22	27.6147
2199.09	26.6765
2201.97	24.6089
2204.84	22.6614
2207.71	21.5519
2210.58	20.3457
2213.45	19.4356
2216.31	18.9242
2219.18	17.6883
2222.05	16.6054
2224.91	15.0537
2227.78	15.6686
2230.64	14.4364
2233.5	13.4811
2236.36	12.6659
2239.22	11.554
2242.08	12.1846
2244.93	11.8522
2247.79	12.029
2250.64	12.2458
2253.5	11.966
2256.35	11.9812
2259.2	12.4109
2262.05	12.2345
2264.9	12.8885
2267.75	12.6036
2270.6	11.981
2273.45	11.6449
2276.29	12.2762
2279.14	12.1568
2281.98	11.3433
2284.82	11.4853
2287.66	11.6734
2290.5	11.5564
2293.34	10.8018
2296.18	10.5462
2299.02	11.0867
2301.86	10.974
2304.69	10.4813
2307.53	11.3008
2310.36	12.967
2313.19	13.651
2316.02	12.4466
2318.85	11.6366
2321.68	10.8809
2324.51	10.3737
2327.34	10.0801
2330.16	9.44146
2332.99	8.51541
2335.81	7.7211
2338.64	6.98648
2341.46	6.20573
2344.28	4.79829
2347.1	3.70003
2349.92	2.5841
2352.74	2.648
2355.55	2.38137
2358.37	2.64776
2361.19	2.59226
2364	3.6003
2366.81	4.72403
2369.62	4.90768
2372.44	5.25691
2375.24	5.9224
2378.05	7.17334
2380.86	6.95787
2383.67	7.20213
2386.47	6.54268
2389.28	5.92782
2392.08	5.28922
2394.89	4.31922
2397.69	3.48297
2400.49	3.88205
2403.29	3.29693
2406.09	3.28215
2408.88	3.56341
2411.68	3.44007
2414.48	3.72098
2417.27	3.96717
2420.06	5.04891
2422.86	5.23981
2425.65	5.17671
2428.44	6.0538
2431.23	6.31523
2434.02	5.62957
2436.81	5.19323
2439.59	4.55829
2442.38	4.80334
2445.16	4.28606
2447.95	4.73023
2450.73	3.64078
2453.51	3.7901
2456.29	3.14892
2459.07	2.3726
2461.85	2.6821
2464.63	2.99224
2467.4	3.17988
2470.18	3.97047
2472.95	3.41056
2475.73	3.82347
2478.5	4.39847
2481.27	4.29561
2484.04	3.94331
2486.81	3.60622
2489.58	2.9474
2492.35	2.54286
2495.12	1.76484
2497.88	1.51572
2500.65	1.19762
2503.41	0.638365
2506.17	0.98203
2508.94	0.480075
2511.7	1.17392
2514.46	1.56384
2517.22	1.77459
2519.97	1.56129
2522.73	2.6308
2525.49	3.32269
2528.24	3.79462
2530.99	4.30402
2533.75	4.74876
2536.5	4.60634
2539.25	5.01554
2542	4.60109
2544.75	4.29796
2547.5	3.74441
2550.24	2.73167
2552.99	2.89657
2555.74	2.56619
2558.48	2.21795
2561.22	1.88939
2563.96	1.90904
2566.71	2.2037
2569.45	1.62848
2572.18	1.16651
2574.92	0.368619
2577.66	1.21059
2580.4	0.45777
2583.13	0.293044
2585.87	0.308021
2588.6	-0.567437
2591.33	0.112595
2594.06	0.861911
2596.79	0.208134
2599.52	0.97935
2602.25	1.12283
2604.98	0.746532
2607.71	1.13359
2610.43	1.91546
2613.16	2.24237
2615.88	3.5237
2618.6	3.68328
2621.32	4.07375
2624.04	3.97989
2626.76	5.40495
2629.48	5.35617
2632.2	4.98106
2634.92	4.58141
2637.63	4.71025
2640.35	4.7219
2643.06	5.64979
2645.77	6.18314
2648.49	5.87269
2651.2	6.91366
2653.91	7.70113
2656.62	8.2081
2659.33	8.54551
2662.03	8.32135
2664.74	8.0023
2667.44	7.17939
2670.15	6.39335
2672.85	6.4955
2675.55	7.12811
2678.26	6.89282
2680.96	5.81535
2683.66	4.77986
2686.35	3.94855
2689.05	4.23141
2691.75	4.93369
2694.44	5.25975
2697.14	4.75554
2699.83	4.89899
2702.52	5.39506
2705.22	6.14776
2707.91	7.76438
2710.6	9.39083
2713.29	11.0269
2715.97	12.561
2718.66	13.8718
2721.35	15.0145
2724.03	15.213
2726.72	15.2238
2729.4	15.5057
2732.08	15.0268
2734.76	14.9178
2737.44	14.2911
2740.12	14.4624
2742.8	13.5411
2745.48	12.8077
2748.16	11.8205
2750.83	11.4201
2753.51	10.5529
2756.18	10.2568
2758.85	9.40523
2761.53	7.50266
2764.2	6.59319
2766.87	6.1816
2769.54	5.92054
2772.2	6.74943
2774.87	6.27039
2777.54	7.11114
2780.2	7.46629
2782.87	7.42672
2785.53	8.04936
2788.19	7.47633
2790.85	7.92783
2793.51	9.03183
2796.17	9.65452
2798.83	9.17352
2801.49	9.79001
2804.15	9.7034
2806.8	9.79789
2809.46	10.4629
2812.11	10.2937
2814.76	10.8594
2817.42	11.5098
2820.07	12.2636
2822.72	14.4791
2825.37	17.9808
2828.02	22.0257
2830.66	26.1603
2833.31	31.5373
2835.96	36.5941
2838.6	41.9788
2841.24	47.6511
2843.89	53.7904
2846.53	60.8772
2849.17	68.9914
2851.81	77.7351
2854.45	87.2679
2857.09	96.2301
2859.72	103.799
2862.36	111.092
2865	117.885
2867.63	124.085
2870.26	128.888
2872.9	133.44
2875.53	138.149
2878.16	141.388
2880.79	144.65
2883.42	148.063
2886.05	152.081
2888.67	156.298
2891.3	161.24
2893.92	164.955
2896.55	169.84
2899.17	174.947
2901.79	180.305
2904.42	186.666
2907.04	194.581
2909.66	204.053
2912.27	214.96
2914.89	224.938
2917.51	234.733
2920.13	241.975
2922.74	247.794
2925.35	252.801
2927.97	256.325
2930.58	257.424
2933.19	256.819
2935.8	254.251
2938.41	250.146
2941.02	244.08
2943.63	238.543
2946.24	230.639
2948.84	222.849
2951.45	215.475
2954.05	207.236
2956.65	198.631
2959.26	189.765
2961.86	181.544
2964.46	173.627
2967.06	165.92
2969.66	158.414
2972.25	151.95
2974.85	144.84
2977.45	138.13
2980.04	130.708
2982.64	122.475
2985.23	113.758
2987.82	105.808
2990.41	98.6812
2993	90.9906
2995.59	81.9092
2998.18	74.4222
3000.77	65.9022
3003.36	59.3829
3005.94	54.4788
3008.53	48.6268
3011.11	44.0311
3013.69	40.9625
3016.28	38.4
3018.86	35.915
3021.44	33.6283
3024.02	31.6442
3026.6	29.8959
3029.18	28.2671
3031.75	27.236
3034.33	27.7487
3036.9	27.5374
3039.48	28.2169
3042.05	29.699
3044.62	29.8866
3047.19	30.0603
3049.77	30.76
3052.34	30.8717
3054.9	31.3003
3057.47	29.9615
3060.04	29.4537
3062.61	28.8446
3065.17	28.0303
3067.74	26.7184
3070.3	25.2198
3072.86	23.9237
3075.42	21.729
3077.99	19.21
3080.54	16.5406
3083.1	14.1701
3085.66	11.603
3088.22	9.56317
3090.78	8.50606
3093.33	7.24687
3095.89	6.74691
3098.44	6.07749
3100.99	4.86647
3103.54	4.41914
3106.1	4.04006
3108.65	3.56108
3111.2	3.47962
3113.74	3.85198
3116.29	3.90899
3118.84	4.2263
3121.38	4.55265
3123.93	5.07588
3126.47	5.00829
3129.01	4.53718
3131.56	4.44931
3134.1	4.14977
3136.64	2.60898
3139.18	1.72767
3141.72	1.2791
3144.26	0.36273
3146.79	-0.965271
3149.33	-3.92191