File: data/Raman/poly_smoothed/Thy_30_10_16_1x_45s_532 nm_x100_100%_600 gr_mm_01.txt
#Acq. time (s)=	45
#Accumulations=	2
#Range (cm-¹)=	200...3150
#Windows=	2
#Auto scanning=	Off
#Autofocus=	Off
#Macrospot=	Off
#AutoExposure=	Off
#Spike filter=	Multiple accum.
#Delay time (s)=	0
#Binning=	1
#Readout mode=	Signal
#DeNoise=	Off
#ICS correction=	On
#Dark correction=	Off
#Inst. Process=	Off
#Detector Gain=	Best Dynamic Range
#Detector ADC=	20 kHz
#Detector temperature (°C)=	-69.85
#Instrument=	LabRAM HR Evol
#Detector=	Synapse
#Objective=	x100
#Grating=	600 gr/mm
#ND Filter=	100%
#Laser (nm)=	532
#Hole=	100.021
#Range=	Auto
#Laser Pol.=	No
#Raman. Pol.=	No
#Laser Pol. (°)=	-0.0007625
#Raman Pol. (°)=	89.9995
#Collection=	Microscope
#StageXY=	Marzhauser
#StageZ=	Marzhauser
#X (µm)=	4745
#Y (µm)=	-7724.3
#Z (µm)=	584.15
#Full time(mm:ss)=	3:18
#Project=
#Sample=
#Site=
#Title=	Thy_30_10_16_2x_45s_532 nm_x100_100%_600 gr_mm
#Remark=
#Date=	30.06.2022 12:36
#Acquired=	30.06.2022 12:36:25
#Base:Fit=	10.08.2022 09:58:11
#Base:Sub=	10.08.2022 09:58:44
#Filter:Polynom=	16.08.2022 10:22:53
#AxisType[0]=Intens
#AxisUnit[0]=Cnt
#AxisType[1]=Spectr
#AxisUnit[1]=1/cm
200.533	23.7838
204.162	22.6445
207.792	18.7121
211.418	16.0694
215.044	13.4426
218.667	12.2432
222.289	10.9324
225.912	9.93432
229.531	8.46041
233.148	6.80142
236.766	5.59076
240.381	4.18946
243.994	5.04149
247.606	4.03319
251.217	4.02196
254.828	4.9276
258.436	5.72991
262.042	6.14637
265.647	7.27212
269.25	8.70666
272.852	9.85816
276.453	8.77536
280.052	7.11383
283.65	6.58162
287.247	7.84846
290.842	8.24058
294.436	8.43779
298.028	10.1592
301.617	10.7202
305.206	10.8693
308.794	11.1115
312.381	11.2578
315.964	10.7082
319.548	11.084
323.131	12.2003
326.71	12.5953
330.29	13.0063
333.868	14.1419
337.443	13.7742
341.018	15.4594
344.591	15.607
348.163	14.8176
351.733	14.894
355.303	15.4359
358.869	15.8257
362.435	13.7829
366.001	13.5019
369.563	13.9955
373.124	13.4857
376.686	13.5295
380.244	12.1945
383.801	13.1836
387.357	12.3244
390.911	12.5361
394.466	12.9093
398.018	12.6619
401.568	12.4643
405.117	13.7496
408.664	13.342
412.21	12.9763
415.755	13.8946
419.298	13.0944
422.84	12.8981
426.38	12.2377
429.919	11.7182
433.455	10.2082
436.992	10.3892
440.527	10.6549
444.06	9.58114
447.593	9.23596
451.122	8.09357
454.651	8.80505
458.18	8.2896
461.705	9.20181
465.23	9.42872
468.752	10.8207
472.275	11.644
475.797	13.3528
479.315	16.3117
482.834	18.133
486.349	21.1047
489.863	23.5735
493.378	25.8963
496.889	27.9245
500.401	29.3397
503.91	30.2042
507.417	30.1216
510.923	30.1986
514.43	30.9512
517.933	31.3353
521.435	30.9184
524.936	30.2322
528.435	28.6186
531.933	25.6202
535.43	25.0308
538.927	23.1702
542.421	21.0951
545.913	20.0454
549.403	18.0848
552.893	16.5218
556.381	15.7879
559.868	15.8329
563.354	14.34
566.839	13.6985
570.322	12.4728
573.802	10.2838
577.283	9.60552
580.762	8.89982
584.24	8.11347
587.714	7.26051
591.19	5.21994
594.663	4.2272
598.134	3.65998
601.605	3.58893
605.073	3.86498
608.542	3.1978
612.007	4.83416
615.473	4.27865
618.936	5.50458
622.397	7.50798
625.859	8.15195
629.318	10.0313
632.775	11.3106
636.233	13.2086
639.688	14.0864
643.142	15.2244
646.594	15.671
650.045	16.141
653.496	16.8254
656.944	16.2788
660.391	17.8092
663.837	18.5434
667.281	19.0133
670.724	19.8888
674.166	19.2223
677.606	20.3279
681.045	21.1058
684.483	21.4625
687.917	24.8281
691.352	26.1651
694.786	28.9841
698.219	29.924
701.65	30.7122
705.078	32.5058
708.506	35.1982
711.934	35.4526
715.358	38.1441
718.782	40.878
722.204	41.6752
725.626	43.2358
729.045	45.5537
732.464	47.9149
735.881	48.3571
739.297	50.0412
742.711	51.2223
746.125	52.9106
749.537	54.9262
752.946	56.4495
756.357	58.9409
759.764	61.4669
763.17	61.0824
766.575	62.8593
769.978	63.2746
773.382	63.3
776.783	66.6365
780.182	65.6064
783.581	65.9453
786.978	66.1471
790.373	67.9071
793.768	70.6935
797.161	71.7599
800.552	73.2921
803.941	74.608
807.33	75.836
810.718	77.139
814.105	79.5077
817.49	80.1483
820.873	80.5786
824.256	80.8736
827.637	80.3442
831.016	79.883
834.395	80.1632
837.772	80.4059
841.147	79.6895
844.522	77.4876
847.894	74.4271
851.267	72.6732
854.637	69.4699
858.007	68.264
861.374	65.0817
864.739	61.4814
868.106	59.9373
871.469	59.1022
874.831	57.2263
878.193	56.9848
881.553	54.3004
884.911	53.2994
888.268	52.8449
891.623	51.598
894.978	51.1103
898.331	50.2542
901.683	48.8077
905.033	48.317
908.383	49.3356
911.731	49.7713
915.078	50.7702
918.423	50.9873
921.768	48.8614
925.111	48.516
928.452	46.6088
931.791	45.8844
935.13	45.1576
938.468	44.9252
941.803	42.9774
945.139	42.1961
948.473	42.0975
951.804	41.9477
955.136	40.3671
958.465	39.0633
961.794	36.7806
965.12	36.5819
968.447	37.8251
971.771	39.1638
975.095	40.2522
978.417	41.9651
981.737	43.3744
985.057	44.4777
988.375	47.0785
991.691	47.5477
995.006	47.7034
998.32	47.6134
1001.63	46.6588
1004.95	46.1241
1008.26	46.2495
1011.56	46.3682
1014.87	45.9795
1018.18	47.595
1021.48	46.4561
1024.79	45.654
1028.09	45.313
1031.39	42.9735
1034.69	38.8814
1037.99	35.958
1041.29	34.5125
1044.58	32.5345
1047.88	31.4318
1051.17	31.0787
1054.46	29.5213
1057.75	28.2581
1061.04	27.6714
1064.33	27.146
1067.62	25.2186
1070.9	24.3833
1074.19	24.119
1077.47	23.3688
1080.76	22.717
1084.04	22.2811
1087.32	23.3059
1090.59	24.225
1093.87	25.6693
1097.15	26.2976
1100.42	28.028
1103.69	28.1317
1106.97	27.219
1110.24	24.3741
1113.51	22.3931
1116.77	22.0228
1120.04	20.0325
1123.31	19.3182
1126.57	17.1961
1129.83	16.6195
1133.1	15.3634
1136.36	13.2386
1139.62	12.1684
1142.87	11.0423
1146.13	9.61047
1149.38	6.42778
1152.64	6.52245
1155.89	5.15881
1159.14	3.59395
1162.39	3.32191
1165.64	2.08441
1168.89	3.43171
1172.14	3.9479
1175.38	3.79768
1178.63	4.11693
1181.87	5.09904
1185.11	5.37154
1188.35	6.35879
1191.59	9.91071
1194.83	12.5321
1198.07	14.2993
1201.3	16.7874
1204.53	19.4928
1207.77	21.3897
1211	24.768
1214.23	26.933
1217.46	29.9616
1220.69	32.8551
1223.91	37.4333
1227.14	41.8966
1230.36	45.2026
1233.59	49.5337
1236.81	51.529
1240.03	53.611
1243.25	54.6397
1246.46	56.9273
1249.68	59.5563
1252.9	61.5776
1256.11	63.9607
1259.32	66.1977
1262.54	67.948
1265.75	69.6377
1268.96	71.4081
1272.16	72.7342
1275.37	72.1143
1278.57	71.7975
1281.78	71.4826
1284.98	71.9174
1288.18	73.3658
1291.38	74.664
1294.58	76.1471
1297.78	77.7434
1300.98	78.6373
1304.17	80.3004
1307.37	79.9225
1310.56	81.1651
1313.76	80.5967
1316.95	81.1408
1320.14	80.7497
1323.32	81.4646
1326.51	81.4731
1329.7	81.0248
1332.88	79.6974
1336.07	78.0237
1339.25	75.5187
1342.43	73.453
1345.61	69.6089
1348.79	65.116
1351.96	62.1208
1355.14	57.6911
1358.31	54.2576
1361.49	50.4711
1364.66	48.7672
1367.83	46.373
1371	42.9331
1374.17	40.3186
1377.34	37.8047
1380.5	36.5245
1383.67	35.5658
1386.83	35.1092
1390	33.9777
1393.16	33.1434
1396.32	32.325
1399.48	31.2736
1402.64	30.3392
1405.79	30.4521
1408.95	32.3011
1412.1	34.4305
1415.26	37.518
1418.41	41.0188
1421.56	44.8644
1424.71	49.7891
1427.86	55.0867
1431	62.2389
1434.15	68.5983
1437.29	74.6118
1440.44	79.1558
1443.58	83.0812
1446.72	85.3175
1449.86	86.8949
1453	87.9037
1456.14	86.2248
1459.27	82.7512
1462.41	77.2031
1465.54	71.3636
1468.67	64.4178
1471.81	56.7448
1474.94	49.2244
1478.07	41.1361
1481.19	33.968
1484.32	28.1777
1487.45	22.1972
1490.57	18.0902
1493.69	13.9677
1496.82	10.6598
1499.94	7.58057
1503.06	6.05378
1506.17	6.85031
1509.29	7.06044
1512.41	8.69633
1515.52	10.078
1518.64	10.5259
1521.75	12.2415
1524.86	13.5255
1527.97	13.975
1531.08	14.7192
1534.19	15.7052
1537.29	16.6864
1540.4	19.6948
1543.5	23.1703
1546.61	26.9115
1549.71	30.3405
1552.81	34.2208
1555.91	37.9985
1559.01	41.0807
1562.11	44.5773
1565.2	48.4513
1568.29	50.8023
1571.39	53.2105
1574.48	55.163
1577.57	57.1599
1580.66	61.2662
1583.75	64.8983
1586.84	66.3111
1589.93	68.7621
1593.01	68.6665
1596.1	69.8221
1599.18	70.1119
1602.26	69.2434
1605.34	68.8609
1608.42	69.8182
1611.5	70.9137
1614.58	71.9196
1617.65	73.9918
1620.73	76.8239
1623.8	80.5617
1626.87	83.8748
1629.95	87.1122
1633.02	91.3439
1636.09	95.8456
1639.15	100.988
1642.22	105.978
1645.29	110.12
1648.35	113.985
1651.42	117.557
1654.48	121.139
1657.54	123.163
1660.6	122.797
1663.66	121.428
1666.72	119.098
1669.77	114.47
1672.83	109.326
1675.88	101.668
1678.93	94.4442
1681.99	85.8023
1685.04	77.1858
1688.09	68.3344
1691.13	59.4064
1694.18	50.0027
1697.23	42.1859
1700.27	34.6685
1703.32	27.9738
1706.36	22.6488
1709.4	18.0408
1712.44	13.8729
1715.48	9.91554
1718.52	8.04225
1721.56	5.49123
1724.59	5.04374
1727.63	4.49079
1730.66	4.51106
1733.69	4.32304
1736.72	4.06189
1739.75	4.14485
1742.78	2.90615
1745.81	3.32148
1748.84	2.56742
1751.86	2.17527
1754.89	1.84562
1757.91	1.524
1760.93	0.385192
1763.95	-0.0779127
1766.97	-1.35071
1769.99	-1.37355
1773.01	-1.6993
1776.03	-1.87676
1779.04	-1.52982
1782.06	-2.19546
1785.07	-2.10144
1788.08	-0.86261
1791.09	-0.568569
1794.1	0.173603
1797.11	0.314688
1800.12	0.0629073
1803.12	0.58867
1806.13	1.57128
1809.13	1.89116
1812.14	2.87944
1815.14	2.82266
1818.14	2.89668
1821.14	4.11175
1824.14	4.76056
1827.13	4.59992
1830.13	4.69817
1833.12	4.78447
1836.12	4.79829
1839.11	5.83559
1842.1	6.47818
1845.09	6.41713
1848.08	6.65227
1851.07	6.94118
1854.06	6.99275
1857.04	7.19468
1860.03	8.08162
1863.01	8.2036
1866	7.98233
1868.98	8.82309
1871.96	10.3882
1874.94	12.0436
1877.92	13.4852
1880.89	14.8519
1882.48	14.7602
1885.47	14.9562
1888.46	15.451
1891.44	16.0528
1894.43	16.3622
1897.41	15.9451
1900.4	15.6447
1903.38	15.5754
1906.36	16.2171
1909.34	16.2129
1912.32	15.5773
1915.29	14.6506
1918.27	12.9438
1921.25	12.858
1924.22	12.7944
1927.2	11.7801
1930.17	12.1694
1933.14	12.2859
1936.11	13.7774
1939.08	13.8423
1942.05	14.7704
1945.01	15.621
1947.98	16.9814
1950.94	16.8403
1953.91	15.9943
1956.87	16.4852
1959.83	17.6128
1962.79	17.0196
1965.75	17.0477
1968.71	17.8967
1971.67	17.1421
1974.62	18.2361
1977.58	18.1417
1980.53	17.4112
1983.48	16.6712
1986.43	16.1807
1989.38	16.5855
1992.33	17.9075
1995.28	18.5902
1998.23	19.3174
2001.18	21.2228
2004.12	21.9038
2007.06	21.6039
2010.01	22.3947
2012.95	23.2453
2015.89	24.1565
2018.83	25.4078
2021.77	25.3138
2024.71	25.8531
2027.64	27.282
2030.58	28.2444
2033.51	28.4894
2036.45	28.8449
2039.38	29.5326
2042.31	28.5429
2045.24	28.4983
2048.17	28.2147
2051.1	27.7241
2054.02	28.1625
2056.95	28.5018
2059.87	30.82
2062.8	31.372
2065.72	32.43
2068.64	33.033
2071.56	34.013
2074.48	34.6743
2077.4	36.3254
2080.31	37.6675
2083.23	39.9075
2086.14	40.8116
2089.06	42.3085
2091.97	43.586
2094.88	44.6751
2097.79	46.3742
2100.7	46.9812
2103.61	48.7498
2106.52	49.8449
2109.43	51.5314
2112.33	53.3041
2115.24	54.7952
2118.14	57.66
2121.04	60.412
2123.94	63.3239
2126.84	67.9965
2129.74	71.7475
2132.64	75.7347
2135.54	79.9327
2138.43	85.0525
2141.33	89.1101
2144.22	93.861
2147.11	98.7955
2150.01	103.8
2152.9	108.209
2155.79	111.589
2158.67	114.6
2161.56	118.179
2164.45	119.229
2167.33	120.025
2170.22	121.045
2173.1	120.925
2175.98	120.606
2178.86	119.693
2181.74	118.203
2184.62	116.45
2187.5	114.452
2190.38	111.406
2193.25	108.454
2196.13	106.167
2199	102.577
2201.88	98.3455
2204.75	94.5808
2207.62	91.5747
2210.49	87.7189
2213.36	83.0992
2216.22	79.7419
2219.09	76.5203
2221.96	73.2542
2224.82	70.1067
2227.68	66.7076
2230.55	63.2574
2233.41	59.6322
2236.27	56.9232
2239.12	54.1933
2241.98	52.1507
2244.84	50.0245
2247.7	48.2491
2250.55	48.6445
2253.41	47.7581
2256.26	46.5039
2259.11	45.5377
2261.96	44.8115
2264.81	44.6113
2267.66	42.8536
2270.51	40.7561
2273.35	40.4974
2276.2	39.8468
2279.04	38.9995
2281.89	37.9957
2284.73	36.6233
2287.57	35.1764
2290.41	32.9969
2293.25	30.5271
2296.09	28.5042
2298.93	27.6112
2301.76	26.5813
2304.6	25.237
2307.44	24.8236
2310.27	24.4788
2313.1	24.2442
2315.93	23.5104
2318.76	22.944
2321.59	21.9473
2324.42	20.3624
2327.25	19.7928
2330.07	19.8215
2332.9	19.9501
2335.72	18.9097
2338.55	18.2679
2341.37	17.8395
2344.19	17.8677
2347.01	18.1306
2349.83	18.2742
2352.65	17.34
2355.46	16.1662
2358.28	16.2009
2361.09	15.445
2363.91	15.6293
2366.72	16.421
2369.53	16.6792
2372.34	16.8556
2375.15	16.0573
2377.96	15.5554
2380.77	16.2022
2383.58	16.1054
2386.38	14.8928
2389.19	14.2652
2391.99	13.7757
2394.8	12.9804
2397.6	12.6199
2400.4	11.9779
2403.2	12.0542
2406	11.4639
2408.79	10.4724
2411.59	10.1206
2414.39	10.3023
2417.18	9.97929
2419.98	8.73999
2422.77	9.05812
2425.56	8.55648
2428.35	8.07605
2431.14	8.79109
2433.93	9.92346
2436.72	10.0435
2439.5	9.66144
2442.29	10.0804
2445.07	9.98468
2447.86	10.4717
2450.64	10.4361
2453.42	8.92278
2456.2	8.54941
2458.98	8.47948
2461.76	7.68556
2464.54	7.37071
2467.32	7.06816
2470.09	7.10748
2472.87	7.02177
2475.64	7.10045
2478.41	7.29453
2481.18	7.36245
2483.95	7.4428
2486.72	7.18707
2489.49	7.9322
2492.26	8.62522
2495.03	9.16054
2497.79	9.89802
2500.56	10.6759
2503.32	9.96223
2506.09	9.31561
2508.85	8.88391
2511.61	7.94756
2514.37	7.45456
2517.13	6.30099
2519.89	5.10203
2522.64	4.92896
2525.4	4.86048
2528.15	4.05261
2530.91	4.1082
2533.66	4.8955
2536.41	4.39952
2539.16	4.43267
2541.91	5.40954
2544.66	5.43557
2547.41	5.62971
2550.16	5.61094
2552.9	5.50397
2555.65	4.81991
2558.39	5.09518
2561.13	5.95907
2563.88	5.5423
2566.62	5.61654
2569.36	5.42528
2572.1	4.3846
2574.84	4.51747
2577.57	4.62565
2580.31	4.53808
2583.05	5.20559
2585.78	5.04862
2588.51	5.47183
2591.24	5.24632
2593.98	5.42602
2596.71	4.22719
2599.44	3.59944
2602.16	2.74238
2604.89	2.11119
2607.62	1.48863
2610.34	1.06273
2613.07	0.60458
2615.79	0.396977
2618.52	-0.223548
2621.24	-0.752242
2623.96	-1.11382
2626.68	-0.475136
2629.4	-0.705551
2632.11	-0.79375
2634.83	-1.49941
2637.55	-2.13428
2640.26	-1.10444
2642.98	-0.229344
2645.69	1.3351
2648.4	1.64445
2651.11	1.66066
2653.82	1.02201
2656.53	1.14529
2659.24	0.585877
2661.95	0.2019
2664.65	-0.674502
2667.36	-1.03783
2670.06	-1.17555
2672.76	-0.46981
2675.47	-0.528618
2678.17	-0.35524
2680.87	-0.91532
2683.57	-1.17811
2686.27	-0.713811
2688.97	-0.752375
2691.66	0.0286502
2694.36	-0.0770061
2697.05	-0.0362189
2699.75	-0.329664
2702.44	-0.223192
2705.13	0.617806
2707.82	1.84223
2710.51	2.73128
2713.2	3.05985
2715.89	3.41954
2718.57	4.03416
2721.26	4.75607
2723.95	4.79758
2726.63	4.88656
2729.31	4.66975
2732	4.6672
2734.68	4.55917
2737.36	5.34297
2740.04	4.88399
2742.72	4.59106
2745.39	4.43038
2748.07	4.96332
2750.75	4.59472
2753.42	4.28584
2756.09	3.43044
2758.77	2.95859
2761.44	2.66112
2764.11	2.40016
2766.78	1.69908
2769.45	1.96978
2772.12	2.37464
2774.78	2.01169
2777.45	2.28949
2780.12	1.78007
2782.78	2.04085
2785.44	1.84647
2788.11	1.34161
2790.77	1.41724
2793.43	2.42859
2796.09	1.15945
2798.75	1.34695
2801.4	1.93138
2804.06	1.73587
2806.72	1.77054
2809.37	1.22002
2812.03	0.973742
2814.68	0.569294
2817.33	1.27546
2819.98	3.02888
2822.63	5.8842
2825.28	9.95856
2827.93	15.2877
2830.58	21.2264
2833.23	27.3347
2835.87	33.6599
2838.52	41.7297
2841.16	50.9296
2843.8	60.022
2846.44	69.5135
2849.08	80.5383
2851.73	92.7458
2854.36	104.812
2857	117.888
2859.64	128.439
2862.28	139.588
2864.91	150.002
2867.55	158.391
2870.18	165.793
2872.81	171.775
2875.44	177.335
2878.07	183.413
2880.7	187.807
2883.33	193.226
2885.96	197.998
2888.59	203.369
2891.21	208.596
2893.84	214.57
2896.46	220.491
2899.09	227.83
2901.71	236.57
2904.33	248.035
2906.95	260.025
2909.57	273.876
2912.19	289.86
2914.81	306.1
2917.43	323.306
2920.04	336.505
2922.66	348.241
2925.27	357.772
2927.88	364.434
2930.5	367.113
2933.11	368.673
2935.72	366.019
2938.33	361.667
2940.94	355.434
2943.54	345.625
2946.15	334.175
2948.76	319.978
2951.36	306.062
2953.97	291.463
2956.57	277.367
2959.17	262.327
2961.77	248.305
2964.37	234.724
2966.97	220.88
2969.57	209.723
2972.17	199.576
2974.77	188.938
2977.36	179.24
2979.96	169.132
2982.55	157.712
2985.15	146.476
2987.74	134.957
2990.33	123.567
2992.92	112.31
2995.51	102.624
2998.1	92.8551
3000.69	83.2189
3003.27	74.0236
3005.86	65.3403
3008.44	58.2181
3011.03	51.6601
3013.61	46.3037
3016.19	41.8206
3018.78	37.5383
3021.36	34.5168
3023.94	31.1965
3026.51	29.4161
3029.09	28.0506
3031.67	27.0752
3034.24	27.9504
3036.82	28.2515
3039.39	29.3018
3041.97	30.3921
3044.54	31.5688
3047.11	32.3896
3049.68	33.0501
3052.25	32.9275
3054.82	33.2918
3057.39	33.0103
3059.96	32.8937
3062.52	31.6541
3065.09	30.2424
3067.65	28.4126
3070.22	26.3689
3072.78	24.0659
3075.34	21.2398
3077.9	19.3362
3080.46	16.6386
3083.02	13.8921
3085.58	12.0777
3088.14	9.87217
3090.69	8.24069
3093.25	6.83378
3095.8	4.96281
3098.36	3.93039
3100.91	3.41367
3103.46	3.38829
3106.01	2.98622
3108.56	3.20514
3111.11	2.84334
3113.66	1.64067
3116.21	1.58193
3118.76	1.67679
3121.3	1.97741
3123.85	1.35114
3126.39	1.64748
3128.93	1.08511
3131.48	0.963397
3134.02	0.853529
3136.56	1.21595
3139.1	1.65185
3141.64	1.58435
3144.17	0.578047
3146.71	-1.16323
3149.25	-2.52087