File: data/Raman/poly_smoothed/Thy_10_08_13_1x_45s_532 nm_x100_100%_600 gr_mm_01.txt
#Acq. time (s)=	45
#Accumulations=	2
#Range (cm-¹)=	200...3150
#Windows=	2
#Auto scanning=	Off
#Autofocus=	Off
#Macrospot=	Off
#AutoExposure=	Off
#Spike filter=	Multiple accum.
#Delay time (s)=	0
#Binning=	1
#Readout mode=	Signal
#DeNoise=	Off
#ICS correction=	On
#Dark correction=	Off
#Inst. Process=	Off
#Detector Gain=	Best Dynamic Range
#Detector ADC=	20 kHz
#Detector temperature (°C)=	-69.85
#Instrument=	LabRAM HR Evol
#Detector=	Synapse
#Objective=	x100
#Grating=	600 gr/mm
#ND Filter=	100%
#Laser (nm)=	532
#Hole=	100.021
#Range=	Auto
#Laser Pol.=	No
#Raman. Pol.=	No
#Laser Pol. (°)=	-0.0007625
#Raman Pol. (°)=	89.9995
#Collection=	Microscope
#StageXY=	Marzhauser
#StageZ=	Marzhauser
#X (µm)=	2170.6
#Y (µm)=	1267.2
#Z (µm)=	442.8
#Full time(mm:ss)=	3:18
#Project=
#Sample=
#Site=
#Title=	Thy_10_08_13_2x_45s_532 nm_x100_100%_600 gr_mm
#Remark=
#Date=	05.07.2022 15:07
#Acquired=	05.07.2022 15:07:26
#Base:Fit=	10.08.2022 09:46:25
#Base:Sub=	10.08.2022 09:46:49
#Filter:Polynom=	16.08.2022 10:24:56
#AxisType[0]=Intens
#AxisUnit[0]=Cnt
#AxisType[1]=Spectr
#AxisUnit[1]=1/cm
200.43	9.33091
204.059	10.2879
207.688	10.1881
211.314	9.8745
214.941	9.75942
218.564	9.6527
222.186	9.70555
225.809	9.65114
229.428	8.66679
233.045	9.30159
236.663	8.47346
240.278	6.17026
243.891	5.58026
247.503	4.10001
251.116	3.39287
254.725	2.63689
258.333	2.3078
261.939	2.14794
265.544	3.22802
269.148	2.71737
272.75	3.16947
276.351	2.60679
279.95	3.19538
283.548	2.48214
287.144	2.30634
290.739	1.8495
294.333	4.87597
297.925	5.71551
301.514	7.05678
305.104	7.37366
308.692	8.06355
312.279	8.47808
315.862	9.31837
319.446	9.41276
323.029	9.79135
326.608	8.33417
330.188	9.49255
333.766	9.99064
337.341	10.3062
340.917	10.7655
344.489	11.5662
348.062	11.7073
351.631	10.7325
355.201	10.8953
358.768	9.98902
362.333	10.6741
365.899	10.2337
369.462	11.2097
373.023	11.9161
376.585	11.96
380.143	11.6057
383.7	12.4803
387.256	10.5379
390.812	9.82596
394.365	9.79823
397.916	10.5785
401.467	8.69837
405.015	9.1526
408.563	8.48338
412.109	7.40859
415.654	8.3034
419.197	7.98168
422.739	7.60748
426.279	7.18149
429.819	7.21853
433.356	6.34336
436.891	6.32645
440.426	6.25172
443.96	6.26672
447.492	6.04664
451.021	4.89626
454.551	6.23292
458.079	6.49318
461.604	7.00802
465.13	6.90239
468.654	7.5809
472.175	8.32681
475.696	8.87627
479.215	11.9815
482.733	14.2995
486.249	14.7242
489.765	16.215
493.278	16.1078
496.789	16.323
500.301	18.5721
503.81	19.6485
507.317	19.9444
510.825	19.2993
514.33	18.735
517.833	18.4139
521.335	18.3729
524.836	18.3933
528.335	18.4192
531.835	17.4813
535.332	16.8954
538.827	17.4349
542.321	18.6824
545.814	17.8042
549.305	16.3854
552.795	16.1608
556.282	15.2943
559.769	13.9752
563.255	12.9231
566.739	12.9925
570.223	10.9061
573.705	8.42224
577.183	5.98563
580.663	5.38702
584.141	4.84188
587.615	3.1874
591.09	3.50548
594.564	0.390128
598.035	0.00150299
601.506	0.252284
604.974	0.439951
608.443	-0.0548138
611.908	0.81849
615.374	3.29579
618.837	4.4578
622.3	5.94109
625.761	6.01306
629.219	7.0622
632.677	7.06527
636.135	9.32692
639.59	10.5308
643.043	11.5482
646.495	13.3147
649.948	14.1499
653.398	16.7163
656.846	17.5183
660.293	20.6776
663.738	21.7803
667.183	23.2601
670.626	24.0278
674.067	25.2867
677.508	26.6498
680.947	26.6645
684.385	28.5328
687.821	30.13
691.254	32.2915
694.688	33.4114
698.121	35.0401
701.552	35.1705
704.98	35.6775
708.409	37.2302
711.836	38.7966
715.26	41.3212
718.685	42.7695
722.108	45.6368
725.528	46.9873
728.949	48.331
732.367	48.9406
735.785	49.6955
739.2	51.5107
742.614	52.0069
746.028	51.9352
749.439	51.9076
752.849	54.1046
756.26	55.912
759.667	58.4842
763.073	59.8771
766.477	61.6953
769.883	64.7815
773.285	66.3303
776.686	67.8978
780.085	69.833
783.484	72.1237
786.881	75.7437
790.276	79.8763
793.671	83.9097
797.064	87.6878
800.456	89.0558
803.846	91.3874
807.234	94.3969
810.622	94.9158
814.008	94.3061
817.394	94.8673
820.778	94.7351
824.159	93.9724
827.541	91.8539
830.921	91.8626
834.298	90.6504
837.676	88.6213
841.051	84.6342
844.426	82.0064
847.798	79.0775
851.171	75.2696
854.54	72.5978
857.911	69.1987
861.278	67.3247
864.645	65.8098
868.01	65.0032
871.373	65.4487
874.735	63.2921
878.097	62.0645
881.457	60.0389
884.815	58.5756
888.172	58.882
891.528	57.9206
894.882	58.372
898.237	58.738
901.589	59.5913
904.94	58.7708
908.289	59.2607
911.635	58.0845
914.982	57.9125
918.328	58.2279
921.672	57.5023
925.015	57.6869
928.357	57.5197
931.698	57.2246
935.035	56.1317
938.373	55.1847
941.71	53.4225
945.044	53.6037
948.378	51.619
951.709	51.999
955.041	49.1282
958.372	45.0826
961.699	41.9942
965.027	42.809
968.352	45.4132
971.676	46.7733
975	49.246
978.322	52.0218
981.642	52.4502
984.962	53.6439
988.28	54.0928
991.596	53.7855
994.911	54.3204
998.227	54.9203
1001.54	54.1875
1004.85	53.286
1008.16	53.309
1011.47	50.7112
1014.78	50.6219
1018.08	49.0317
1021.39	45.9488
1024.69	44.7061
1028	42.2566
1031.3	38.368
1034.6	36.2457
1037.9	33.2018
1041.19	31.1989
1044.49	33.252
1047.78	35.5584
1051.08	35.0555
1054.37	35.6118
1057.66	34.538
1060.95	33.5551
1064.24	31.1138
1067.53	32.4476
1070.81	31.3159
1074.1	29.9614
1077.38	30.4983
1080.66	29.5571
1083.94	29.7806
1087.22	29.3775
1090.5	30.861
1093.78	31.9331
1097.05	33.4412
1100.33	33.7846
1103.6	32.8998
1106.87	30.8133
1110.14	29.1681
1113.41	28.3416
1116.68	27.6844
1119.95	26.4259
1123.21	24.4627
1126.48	24.1987
1129.74	20.5197
1133	18.1854
1136.26	16.5753
1139.52	15.4354
1142.78	14.6754
1146.04	15.0053
1149.29	14.3737
1152.55	11.1676
1155.8	10.7083
1159.05	10.736
1162.3	9.67485
1165.55	11.6137
1168.8	14.5493
1172.05	17.6745
1175.29	20.2041
1178.54	22.6127
1181.78	21.3928
1185.02	21.9054
1188.26	22.6602
1191.5	24.7351
1194.74	26.7993
1197.97	29.0429
1201.21	30.9147
1204.44	33.1557
1207.68	37.4837
1210.91	40.4436
1214.14	46.3848
1217.37	50.4543
1220.59	55.1389
1223.82	58.8811
1227.05	62.1188
1230.27	64.2958
1233.49	67.3874
1236.72	72.0496
1239.94	75.4877
1243.16	78.1943
1246.37	79.3244
1249.59	80.8607
1252.8	81.701
1256.02	82.4574
1259.23	80.5714
1262.44	78.4078
1265.66	77.3226
1268.86	76.9765
1272.07	77.5004
1275.28	77.1937
1278.48	78.5926
1281.69	81.3211
1284.89	83.6421
1288.09	85.628
1291.29	87.2597
1294.49	91.207
1297.69	91.4967
1300.89	92.3953
1304.08	94.6854
1307.28	96.7857
1310.47	99.7178
1313.66	103.134
1316.85	106.598
1320.04	105.095
1323.23	106.056
1326.42	107.283
1329.61	107.153
1332.79	105.172
1335.97	103.169
1339.16	98.4015
1342.34	96.0055
1345.52	92.4206
1348.7	88.9311
1351.87	84.2795
1355.05	81.334
1358.22	78.7494
1361.4	74.666
1364.57	68.7988
1367.74	64.4003
1370.91	60.5424
1374.08	56.7185
1377.25	53.6537
1380.41	52.9212
1383.58	52.5591
1386.74	52.4388
1389.91	52.8086
1393.07	52.0914
1396.23	49.3224
1399.39	47.4887
1402.55	47.0155
1405.7	46.1886
1408.86	48.0364
1412.01	50.8505
1415.17	54.508
1418.32	61.2587
1421.47	66.5689
1424.62	71.8076
1427.77	80.3562
1430.91	88.2449
1434.06	95.9479
1437.2	102.899
1440.35	105.561
1443.49	109.965
1446.63	112.37
1449.77	110.022
1452.91	111.751
1456.05	111.499
1459.18	109.286
1462.32	105.958
1465.45	100.56
1468.59	92.6611
1471.72	82.1714
1474.85	71.8632
1477.98	63.8408
1481.1	55.8532
1484.23	51.0018
1487.36	46.3355
1490.48	41.7249
1493.61	37.7124
1496.73	34.0139
1499.85	30.2633
1502.97	28.343
1506.09	27.8355
1509.2	26.6156
1512.32	23.9907
1515.43	21.5772
1518.55	20.4423
1521.66	19.3949
1524.77	19.9102
1527.88	22.1693
1530.99	27.6193
1534.1	30.5116
1537.21	34.1245
1540.31	35.5885
1543.42	38.0859
1546.52	40.0702
1549.62	42.9662
1552.72	47.7646
1555.82	53.1048
1558.92	58.1359
1562.02	63.912
1565.11	67.9079
1568.21	72.3117
1571.3	74.6865
1574.39	78.8001
1577.49	82.2615
1580.57	83.8552
1583.66	86.3914
1586.75	88.3281
1589.84	89.775
1592.92	90.3266
1596.01	90.2641
1599.09	90.473
1602.17	90.0307
1605.25	89.2803
1608.33	86.7333
1611.41	85.6863
1614.49	83.025
1617.57	81.4917
1620.64	82.2907
1623.72	83.2003
1626.79	84.0089
1629.86	86.4767
1632.93	88.8729
1636	91.9232
1639.07	95.5357
1642.13	98.8874
1645.2	101.298
1648.26	103.116
1651.33	106.957
1654.39	108.664
1657.45	109.504
1660.51	109.727
1663.57	107.444
1666.63	103.576
1669.68	101.175
1672.74	97.5972
1675.79	93.6744
1678.85	88.9476
1681.9	83.975
1684.95	77.4061
1688	71.5995
1691.05	65.7584
1694.09	58.1427
1697.14	50.728
1700.18	43.9962
1703.23	38.5213
1706.27	33.8187
1709.31	29.1474
1712.35	25.7257
1715.39	21.8393
1718.43	18.931
1721.47	16.2527
1724.5	11.9307
1727.54	10.8559
1730.57	9.2116
1733.61	7.27694
1736.64	4.79116
1739.67	4.43007
1742.7	4.32145
1745.72	4.83857
1748.75	4.77353
1751.77	5.51837
1754.8	4.91
1757.82	4.42141
1760.84	4.54107
1763.87	4.4044
1766.89	3.57265
1769.91	2.18885
1772.92	3.30644
1775.94	4.02938
1778.95	3.93479
1781.97	3.54233
1784.98	3.45228
1787.99	2.73718
1791.01	2.05371
1794.01	2.65562
1797.02	3.04135
1800.03	3.14837
1803.04	3.541
1806.04	2.45883
1809.05	1.78847
1812.05	1.80199
1815.05	1.45893
1818.05	0.933895
1821.05	0.797114
1824.05	0.198909
1827.05	-0.40713
1830.04	-0.730841
1833.04	-0.535435
1836.03	-0.939042
1839.03	-0.581092
1842.02	-0.642407
1845.01	0.594067
1848	1.67676
1850.99	2.13456
1853.97	2.37074
1856.96	2.24993
1859.94	2.71541
1862.93	3.3376
1865.91	4.17186
1868.89	4.09507
1871.87	3.6002
1874.85	3.70258
1877.83	3.39372
1880.81	2.86284
1882.57	3.17137
1885.56	3.43117
1888.55	3.82974
1891.54	3.80491
1894.52	3.39137
1897.51	3.69249
1900.49	2.88772
1903.47	2.26041
1906.45	2.4081
1909.43	2.21487
1912.41	2.45843
1915.39	3.11792
1918.37	3.46547
1921.34	3.69393
1924.32	4.22955
1927.29	3.53216
1930.26	3.54206
1933.23	3.67468
1936.2	3.33295
1939.17	3.15348
1942.14	3.12006
1945.11	4.5587
1948.07	5.34223
1951.04	5.4837
1954	5.86662
1956.96	7.42335
1959.93	7.42515
1962.89	7.23455
1965.85	7.7332
1968.8	7.81352
1971.76	8.46466
1974.72	7.99828
1977.67	7.75737
1980.63	7.77932
1983.58	7.32527
1986.53	7.70528
1989.48	8.69238
1992.43	9.76059
1995.38	9.91096
1998.32	9.54552
2001.27	9.66498
2004.22	9.83986
2007.16	11.5744
2010.1	11.9062
2013.04	13.3716
2015.98	14.7483
2018.92	15.6204
2021.86	16.0039
2024.8	17.3031
2027.74	19.4088
2030.67	19.3389
2033.61	19.4291
2036.54	19.7456
2039.47	19.2896
2042.4	18.5132
2045.33	18.2735
2048.26	17.1677
2051.19	15.9393
2054.12	15.2517
2057.04	15.2688
2059.97	16.4568
2062.89	16.1155
2065.81	17.0958
2068.73	16.3684
2071.65	16.9096
2074.57	16.8512
2077.49	16.3718
2080.41	16.3014
2083.32	15.8771
2086.24	16.2448
2089.15	16.5182
2092.07	17.2809
2094.98	17.845
2097.89	18.9447
2100.8	19.0417
2103.71	19.6192
2106.61	18.9742
2109.52	20.2938
2112.43	20.0317
2115.33	20.1555
2118.23	20.8972
2121.13	20.7365
2124.04	23.2387
2126.94	25.8621
2129.83	27.9135
2132.73	30.3319
2135.63	32.4693
2138.53	34.0553
2141.42	35.7348
2144.31	36.5081
2147.21	37.2623
2150.1	38.5355
2152.99	39.94
2155.88	40.3058
2158.77	40.465
2161.65	41.149
2164.54	42.6236
2167.43	42.3791
2170.31	42.2272
2173.19	43.8035
2176.07	43.1847
2178.96	43.5674
2181.84	43.8059
2184.72	43.0503
2187.59	43.1109
2190.47	42.1826
2193.35	42.0675
2196.22	42.8505
2199.09	42.216
2201.97	43.2513
2204.84	42.4598
2207.71	41.2325
2210.58	40.6543
2213.45	39.6977
2216.31	38.9609
2219.18	37.4607
2222.05	36.0623
2224.91	33.3399
2227.78	31.9043
2230.64	30.3053
2233.5	30.004
2236.36	28.9621
2239.22	29.1757
2242.08	29.243
2244.93	29.6294
2247.79	29.7738
2250.64	30.4749
2253.5	29.8757
2256.35	30.3236
2259.2	29.8941
2262.05	29.3798
2264.9	29.503
2267.75	29.2535
2270.6	29.0092
2273.45	28.7763
2276.29	27.1133
2279.14	25.5954
2281.98	24.4729
2284.82	23.1036
2287.66	22.0115
2290.5	19.9969
2293.34	17.476
2296.18	16.1635
2299.02	16.093
2301.86	16.9177
2304.69	17.8478
2307.53	18.0378
2310.36	18.1019
2313.19	18.6019
2316.02	19.4023
2318.85	18.5106
2321.68	19.0252
2324.51	18.0472
2327.34	17.1721
2330.16	16.3086
2332.99	15.6927
2335.81	15.3628
2338.64	15.3991
2341.46	15.7956
2344.28	14.2703
2347.1	12.4677
2349.92	12.0622
2352.74	11.6906
2355.55	12.9077
2358.37	11.9789
2361.19	11.4818
2364	11.0689
2366.81	12.4668
2369.62	12.794
2372.44	12.3352
2375.24	11.3429
2378.05	11.6091
2380.86	12.208
2383.67	12.1894
2386.47	12.1139
2389.28	11.9354
2392.08	12.9137
2394.89	13.0908
2397.69	13.3117
2400.49	12.7022
2403.29	13.6387
2406.09	13.9535
2408.88	13.9133
2411.68	13.7707
2414.48	13.247
2417.27	13.822
2420.06	15.2944
2422.86	16.2041
2425.65	14.9558
2428.44	13.8417
2431.23	14.2466
2434.02	13.9032
2436.81	13.3127
2439.59	13.1977
2442.38	12.8285
2445.16	12.6191
2447.95	12.5444
2450.73	12.3399
2453.51	12.2532
2456.29	11.0739
2459.07	10.2935
2461.85	9.76412
2464.63	9.02548
2467.4	8.14935
2470.18	8.39103
2472.95	8.15829
2475.73	8.11799
2478.5	5.79359
2481.27	5.14406
2484.04	5.36564
2486.81	4.88741
2489.58	4.07246
2492.35	3.85454
2495.12	4.03098
2497.88	4.56878
2500.65	5.3252
2503.41	4.93243
2506.17	4.71301
2508.94	4.17838
2511.7	3.71833
2514.46	2.75601
2517.22	2.66158
2519.97	2.43128
2522.73	1.92271
2525.49	1.91533
2528.24	2.60953
2530.99	2.98472
2533.75	2.88767
2536.5	2.98051
2539.25	3.20232
2542	2.77382
2544.75	2.40499
2547.5	2.18931
2550.24	3.45371
2552.99	3.49089
2555.74	4.46154
2558.48	4.86042
2561.22	5.52453
2563.96	5.20259
2566.71	5.41028
2569.45	4.92817
2572.18	3.53665
2574.92	3.13727
2577.66	2.17456
2580.4	2.42854
2583.13	2.0053
2585.87	2.80034
2588.6	1.84781
2591.33	1.59455
2594.06	1.43922
2596.79	2.15723
2599.52	1.60796
2602.25	1.60096
2604.98	1.7377
2607.71	1.6564
2610.43	1.41177
2613.16	1.65253
2615.88	2.13092
2618.6	3.21641
2621.32	2.46628
2624.04	2.62629
2626.76	2.97199
2629.48	2.73536
2632.2	2.69302
2634.92	4.32178
2637.63	4.66102
2640.35	5.73576
2643.06	5.26984
2645.77	6.07195
2648.49	7.6974
2651.2	8.42393
2653.91	7.73613
2656.62	8.04232
2659.33	8.03708
2662.03	8.61849
2664.74	8.01681
2667.44	7.17472
2670.15	6.45669
2672.85	4.61149
2675.55	4.27579
2678.26	3.28477
2680.96	2.18022
2683.66	1.3953
2686.35	0.464736
2689.05	-0.564186
2691.75	-0.374543
2694.44	-0.424138
2697.14	-0.626794
2699.83	1.17764
2702.52	2.1962
2705.22	3.3483
2707.91	3.47443
2710.6	4.52977
2713.29	6.44584
2715.97	8.02786
2718.66	7.81905
2721.35	8.97561
2724.03	10.0614
2726.72	11.1689
2729.4	10.9305
2732.08	11.4539
2734.76	11.2128
2737.44	11.2362
2740.12	11.5104
2742.8	11.7896
2745.48	11.5195
2748.16	11.9451
2750.83	11.1497
2753.51	10.3928
2756.18	10.0282
2758.85	9.23218
2761.53	9.0123
2764.2	8.86489
2766.87	8.42419
2769.54	7.44
2772.2	6.42876
2774.87	5.78289
2777.54	5.13915
2780.2	4.20926
2782.87	3.43295
2785.53	3.02648
2788.19	3.32418
2790.85	1.94296
2793.51	1.02668
2796.17	-0.163771
2798.83	-0.368207
2801.49	0.354642
2804.15	0.312685
2806.8	-0.025019
2809.46	0.444157
2812.11	1.18185
2814.76	1.44451
2817.42	2.24113
2820.07	4.38661
2822.72	8.53156
2825.37	13.771
2828.02	20.4317
2830.66	25.4021
2833.31	31.1967
2835.96	37.9976
2838.6	45.5407
2841.24	54.2927
2843.89	63.2393
2846.53	73.7252
2849.17	85.0559
2851.81	97.1214
2854.45	109.38
2857.09	121.911
2859.72	133.388
2862.36	144.691
2865	155.898
2867.63	164.943
2870.26	171.967
2872.9	179.382
2875.53	185.536
2878.16	190.629
2880.79	195.868
2883.42	201.154
2886.05	206.174
2888.67	211.664
2891.3	217.289
2893.92	221.754
2896.55	226.865
2899.17	232.471
2901.79	240.841
2904.42	251.073
2907.04	262.311
2909.66	276.155
2912.27	291.738
2914.89	308.086
2917.51	321.354
2920.13	334.574
2922.74	344.578
2925.35	353.337
2927.97	357.121
2930.58	359.718
2933.19	358.829
2935.8	354.779
2938.41	347.55
2941.02	339.71
2943.63	330.136
2946.24	319.007
2948.84	306.938
2951.45	293.693
2954.05	280.141
2956.65	266.368
2959.26	252.699
2961.86	239.373
2964.46	227.821
2967.06	218.005
2969.66	208.517
2972.25	200.053
2974.85	191.585
2977.45	181.543
2980.04	172.046
2982.64	161.368
2985.23	151.557
2987.82	139.308
2990.41	128.795
2993	117.026
2995.59	105.926
2998.18	94.9025
3000.77	85.9275
3003.36	76.8168
3005.94	68.851
3008.53	61.9068
3011.11	54.9104
3013.69	48.4425
3016.28	43.4895
3018.86	39.1741
3021.44	36.2912
3024.02	33.3643
3026.6	30.924
3029.18	29.2088
3031.75	27.6439
3034.33	26.6726
3036.9	26.6764
3039.48	26.5658
3042.05	28.1039
3044.62	29.9731
3047.19	30.8996
3049.77	31.8808
3052.34	33.4477
3054.9	33.5387
3057.47	33.7052
3060.04	32.6443
3062.61	32.1692
3065.17	31.4491
3067.74	29.7288
3070.3	27.247
3072.86	24.5306
3075.42	22.3126
3077.99	19.8942
3080.54	16.8686
3083.1	14.2057
3085.66	11.94
3088.22	9.28731
3090.78	7.56339
3093.33	6.39449
3095.89	4.84291
3098.44	4.72022
3100.99	4.36633
3103.54	4.8062
3106.1	5.36125
3108.65	4.93777
3111.2	4.36841
3113.74	4.05309
3116.29	3.62864
3118.84	3.49441
3121.38	3.38928
3123.93	2.23737
3126.47	2.35583
3129.01	1.88391
3131.56	0.891847
3134.1	0.21048
3136.64	-0.180614
3139.18	0.388855
3141.72	0.569557
3144.26	1.90438
3146.79	3.22117
3149.33	3.68711