File: data/Raman/poly_smoothed/Thy_20_09_05_1x_45s_532 nm_x100_100%_600 gr_mm_01.txt
#Acq. time (s)=	45
#Accumulations=	2
#Range (cm-¹)=	200...3150
#Windows=	2
#Auto scanning=	Off
#Autofocus=	Off
#Macrospot=	Off
#AutoExposure=	Off
#Spike filter=	Multiple accum.
#Delay time (s)=	0
#Binning=	1
#Readout mode=	Signal
#DeNoise=	Off
#ICS correction=	On
#Dark correction=	Off
#Inst. Process=	Off
#Detector Gain=	Best Dynamic Range
#Detector ADC=	20 kHz
#Detector temperature (°C)=	-69.85
#Instrument=	LabRAM HR Evol
#Detector=	Synapse
#Objective=	x100
#Grating=	600 gr/mm
#ND Filter=	100%
#Laser (nm)=	532
#Hole=	100.021
#Range=	Auto
#Laser Pol.=	No
#Raman. Pol.=	No
#Laser Pol. (°)=	-0.0007625
#Raman Pol. (°)=	89.9995
#Collection=	Microscope
#StageXY=	Marzhauser
#StageZ=	Marzhauser
#X (µm)=	-5919.9
#Y (µm)=	2831.4
#Z (µm)=	-223.3
#Full time(mm:ss)=	3:18
#Project=
#Sample=
#Site=
#Title=	Thy_20_09_05_2x_45s_532 nm_x100_100%_600 gr_mm
#Remark=
#Date=	29.06.2022 11:04
#Acquired=	29.06.2022 11:04:58
#Base:Fit=	10.08.2022 09:49:32
#Base:Fit=	10.08.2022 09:49:42
#Base:Fit=	10.08.2022 09:49:53
#Base:Fit=	10.08.2022 09:50:12
#Base:Fit=	10.08.2022 09:50:26
#Base:Fit=	10.08.2022 09:50:30
#Base:Fit=	10.08.2022 09:50:43
#Base:Fit=	10.08.2022 09:52:02
#Base:Fit=	10.08.2022 09:52:12
#Base:Sub=	10.08.2022 09:54:21
#Filter:Polynom=	16.08.2022 10:24:04
#AxisType[0]=Intens
#AxisUnit[0]=Cnt
#AxisType[1]=Spectr
#AxisUnit[1]=1/cm
200.523	-0.554942
204.154	3.98592
207.781	8.49539
211.409	9.34468
215.034	9.69687
218.659	10.9611
222.281	10.8026
225.903	7.25965
229.522	7.21358
233.14	7.05407
236.756	7.62205
240.373	7.1046
243.986	7.36959
247.598	6.07523
251.208	3.48696
254.818	4.37554
258.427	3.69833
262.034	4.27918
265.638	5.04697
269.242	3.97684
272.844	6.06538
276.445	6.7517
280.044	7.39497
283.642	7.19544
287.238	6.65686
290.833	8.19456
294.425	7.8164
298.017	7.55307
301.608	10.4836
305.198	9.46827
308.786	10.6476
312.371	11.2675
315.956	11.278
319.54	11.1212
323.122	10.837
326.701	10.8526
330.281	11.6007
333.857	11.0616
337.434	11.2855
341.008	12.6965
344.582	12.6844
348.153	10.4271
351.724	8.60556
355.292	8.49195
358.861	10.5552
362.426	9.81524
365.99	9.02828
369.555	7.76497
373.116	8.46856
376.676	8.12349
380.236	9.92156
383.793	9.87522
387.349	11.7196
390.903	11.8906
394.456	12.7306
398.007	13.8979
401.56	14.2632
405.108	13.2917
408.656	15.0787
412.202	15.1466
415.746	15.0698
419.29	15.2048
422.831	14.908
426.37	12.5491
429.909	11.6913
433.447	7.96141
436.983	6.5429
440.519	6.60647
444.052	5.13506
447.583	4.6173
451.114	3.86687
454.643	4.16523
458.169	5.43608
461.696	5.03664
465.222	5.57555
468.744	7.33264
472.267	8.83077
475.787	11.1942
479.307	13.3563
482.823	16.4118
486.341	19.0192
489.855	21.4147
493.37	21.6161
496.881	23.5891
500.391	24.9398
503.902	27.5246
507.409	28.8809
510.915	29.2602
514.42	31.8781
517.925	32.1917
521.427	33.2009
524.928	35.0273
528.427	33.6641
531.925	32.3541
535.422	33.3621
538.917	32.401
542.411	30.4037
545.903	27.3038
549.395	25.8414
552.884	23.4535
556.373	22.3194
559.86	20.4847
563.346	18.9683
566.831	17.71
570.314	16.1902
573.794	12.532
577.274	10.7395
580.754	10.1311
584.23	9.61126
587.706	9.1915
591.181	9.44631
594.653	8.58252
598.126	7.97766
601.595	9.60275
605.065	8.50741
608.532	9.00721
611.999	7.77928
615.463	8.11373
618.928	9.7018
622.389	12.197
625.851	12.6592
629.31	12.2655
632.767	14.0269
636.223	14.9907
639.68	17.3183
643.134	18.5444
646.586	20.9374
650.037	24.2497
653.486	25.2883
656.936	24.6762
660.383	26.3064
663.829	28.6401
667.273	29.9601
670.716	31.5409
674.158	32.7326
677.598	33.5826
681.035	34.3827
684.473	35.1489
687.909	36.2395
691.344	36.7455
694.778	36.5501
698.211	37.3165
701.64	37.3822
705.07	36.8006
708.498	37.4277
711.924	36.7437
715.35	36.6521
718.774	39.7376
722.196	40.8991
725.618	42.0059
729.037	44.8064
732.456	46.3342
735.873	47.3094
739.289	46.351
742.703	49.1872
746.116	53.3899
749.529	55.0803
752.938	57.9534
756.347	60.1302
759.756	61.7057
763.162	61.9783
766.567	61.5205
769.97	62.07
773.372	61.6796
776.773	62.4921
780.174	60.7063
783.573	60.9912
786.97	60.7832
790.365	63.3487
793.76	63.7628
797.153	65.6584
800.543	64.7645
803.933	66.4798
807.322	68.3603
810.71	68.7325
814.097	68.6332
817.483	69.1984
820.865	70.7262
824.248	71.6318
827.629	72.9436
831.008	73.3813
834.387	72.7659
837.765	72.4179
841.139	71.2266
844.514	68.6059
847.886	64.6767
851.259	64.1077
854.629	62.0422
857.997	57.0901
861.366	56.581
864.732	52.7309
868.098	50.953
871.461	49.7317
874.823	46.709
878.184	42.978
881.545	42.1899
884.903	40.224
888.26	39.7122
891.616	38.6217
894.97	36.9218
898.323	36.866
901.675	36.1337
905.026	38.4596
908.375	38.4287
911.723	38.0552
915.07	38.623
918.415	39.0556
921.76	39.9474
925.103	39.5302
928.443	39.277
931.783	38.7064
935.123	35.8321
938.461	35.2955
941.796	34.1323
945.131	29.7011
948.465	26.9959
951.797	28.6583
955.128	28.0609
958.457	24.6201
961.786	23.3818
965.113	24.6422
968.44	25.8749
971.763	27.0348
975.086	26.118
978.409	26.7213
981.729	26.1935
985.048	27.6451
988.367	26.7786
991.683	26.9724
994.998	26.273
998.312	25.8763
1001.62	24.4448
1004.94	23.8956
1008.25	22.9673
1011.56	21.2221
1014.86	19.502
1018.17	18.1788
1021.48	15.8783
1024.78	12.58
1028.08	10.7266
1031.38	10.1634
1034.68	8.50113
1037.98	6.48408
1041.28	5.0289
1044.57	7.46269
1047.87	8.8337
1051.16	8.12903
1054.45	7.20132
1057.75	6.82378
1061.04	6.53999
1064.32	6.36808
1067.61	7.55499
1070.9	7.77314
1074.18	7.10265
1077.47	7.56698
1080.75	7.99789
1084.03	9.24961
1087.31	10.7015
1090.59	11.4973
1093.86	10.6806
1097.14	13.6993
1100.41	15.8201
1103.69	16.4532
1106.96	17.4016
1110.23	17.8242
1113.5	18.7777
1116.77	18.8448
1120.03	18.3397
1123.3	19.0953
1126.56	19.8327
1129.83	18.709
1133.09	19.3513
1136.35	18.4756
1139.61	18.3958
1142.86	18.6552
1146.12	17.7514
1149.38	16.2742
1152.63	15.2816
1155.88	14.8042
1159.14	14.0481
1162.39	12.5172
1165.63	11.0599
1168.88	11.4329
1172.13	12.5694
1175.38	14.5464
1178.62	17.1551
1181.86	15.1003
1185.1	15.2259
1188.34	14.5356
1191.58	13.6952
1194.82	13.8476
1198.06	15.1053
1201.29	17.1276
1204.53	21.5666
1207.76	25.3018
1210.99	31.9325
1214.22	36.9958
1217.45	41.9845
1220.68	47.8551
1223.91	53.6303
1227.13	59.6596
1230.36	65.3622
1233.58	70.4664
1236.8	75.4668
1240.02	79.0239
1243.24	82.8905
1246.46	88.0073
1249.67	90.9979
1252.89	93.3247
1256.1	93.0334
1259.32	96.2768
1262.53	95.3391
1265.74	97.5597
1268.95	99.0771
1272.15	102.105
1275.36	105.126
1278.57	110.093
1281.77	116.131
1284.97	121.352
1288.18	127.551
1291.38	130.608
1294.58	135.51
1297.78	139.53
1300.97	145.678
1304.17	149.895
1307.36	154.098
1310.55	159.917
1313.75	162.541
1316.94	165.515
1320.13	168.722
1323.32	168.668
1326.5	169.288
1329.69	168.983
1332.87	168.945
1336.06	168.546
1339.24	167.923
1342.42	167.068
1345.6	166.283
1348.78	162.889
1351.96	159.207
1355.13	155.601
1358.31	152.688
1361.48	149.152
1364.65	142.174
1367.82	137.927
1370.99	135.529
1374.16	132.22
1377.33	129.119
1380.5	125.573
1383.66	122.583
1386.83	118.769
1389.99	115.067
1393.15	112.051
1396.31	108.717
1399.47	106.15
1402.63	103.561
1405.78	105.2
1408.94	105.742
1412.1	107.993
1415.25	110.139
1418.4	114.865
1421.55	117.483
1424.7	122.781
1427.85	127.194
1431	133.694
1434.14	140.129
1437.29	142.222
1440.43	146.741
1443.57	151.538
1446.71	154.952
1449.85	154.048
1452.99	153.688
1456.13	149.483
1459.26	144.418
1462.4	139.874
1465.54	133.951
1468.67	128.032
1471.8	120.229
1474.93	113.654
1478.06	108.661
1481.19	101.842
1484.31	96.3047
1487.44	91.7022
1490.56	88.0531
1493.69	85.6667
1496.81	82.2275
1499.93	81.9463
1503.05	79.9386
1506.17	80.2144
1509.28	81.7808
1512.4	80.2842
1515.52	83.4036
1518.63	85.7897
1521.74	87.3235
1524.85	89.9419
1527.96	90.9729
1531.07	94.6233
1534.18	96.8015
1537.29	100.814
1540.39	106.262
1543.5	111.225
1546.6	115.519
1549.7	121.61
1552.8	128.978
1555.9	137.02
1559	144.608
1562.1	152.606
1565.19	159.585
1568.29	166.322
1571.38	171.991
1574.47	179.953
1577.56	184.542
1580.66	189.661
1583.74	193.411
1586.83	196.797
1589.92	198.109
1593.01	197.359
1596.09	195.307
1599.17	193.28
1602.25	190.866
1605.34	185.343
1608.41	180.551
1611.49	176.718
1614.57	170.985
1617.65	166.501
1620.72	160.592
1623.79	155.935
1626.87	152.085
1629.94	151.017
1633.01	149.135
1636.08	147.521
1639.15	147.112
1642.21	146.123
1645.28	143.651
1648.34	142.877
1651.41	139.741
1654.47	135.094
1657.53	133.125
1660.59	128.858
1663.65	123.328
1666.71	117.198
1669.76	111.454
1672.82	106.971
1675.87	101.485
1678.93	95.6046
1681.98	88.8581
1685.03	82.6492
1688.08	74.4729
1691.13	66.8939
1694.17	59.9876
1697.22	54.8425
1700.27	49.1627
1703.31	46.0404
1706.35	42.4108
1709.39	39.3506
1712.43	36.5838
1715.47	32.9661
1718.51	29.0572
1721.55	26.4464
1724.58	24.0397
1727.62	21.7121
1730.65	19.4709
1733.68	19.41
1736.72	17.2083
1739.74	17.0612
1742.77	16.526
1745.8	16.2534
1748.83	16.7148
1751.85	16.0287
1754.88	16.1022
1757.9	14.7401
1760.92	13.3709
1763.95	11.7112
1766.96	11.3717
1769.98	10.0915
1773	10.7802
1776.02	8.98418
1779.03	8.22107
1782.05	9.11821
1785.06	8.615
1788.07	8.22834
1791.08	7.29759
1794.09	6.29335
1797.1	6.26907
1800.11	5.19345
1803.12	6.11025
1806.12	6.35312
1809.12	7.32987
1812.13	8.363
1815.13	8.96676
1818.13	10.0646
1821.13	11.4336
1824.13	11.4705
1827.13	11.806
1830.12	13.1775
1833.12	13.6564
1836.11	13.4898
1839.1	14.2576
1842.09	13.6601
1845.09	13.2731
1848.08	11.2061
1851.06	9.5222
1854.05	9.39186
1857.04	9.05023
1860.02	5.81007
1863.01	3.98942
1865.99	2.88289
1868.97	2.63322
1871.95	3.06597
1874.93	3.41681
1877.91	4.11264
1880.89	3.87156
1882.46	4.02579
1885.45	3.72891
1888.43	4.42522
1891.42	4.86898
1894.41	5.66881
1897.39	7.11835
1900.37	7.46446
1903.36	8.68916
1906.34	9.31075
1909.32	10.9014
1912.29	11.4783
1915.27	11.161
1918.25	10.4491
1921.23	11.1389
1924.2	11.6623
1927.17	11.4871
1930.15	11.0678
1933.12	10.9205
1936.09	13.4028
1939.06	14.5579
1942.02	16.2588
1944.99	16.8687
1947.96	16.8345
1950.92	16.4851
1953.88	16.41
1956.85	15.2005
1959.81	15.2697
1962.77	16.2512
1965.73	16.3127
1968.69	16.1361
1971.64	14.4166
1974.6	13.9137
1977.55	14.6198
1980.51	14.6577
1983.46	13.7575
1986.41	12.1745
1989.36	10.3215
1992.31	9.22684
1995.26	8.22991
1998.21	7.55258
2001.15	5.83885
2004.1	6.12352
2007.04	6.94681
2009.99	7.68696
2012.93	7.8708
2015.87	7.12788
2018.81	7.39183
2021.75	6.30316
2024.68	7.75333
2027.62	8.99525
2030.56	11.3005
2033.49	12.1419
2036.42	13.4136
2039.36	13.6318
2042.29	12.9947
2045.22	13.9044
2048.14	14.9429
2051.07	16.1587
2054	16.463
2056.93	17.164
2059.85	17.5264
2062.77	17.4463
2065.7	17.8354
2068.62	17.9159
2071.54	19.2029
2074.46	19.7301
2077.38	17.9786
2080.29	18.3668
2083.21	17.7191
2086.12	19.1781
2089.04	19.4984
2091.95	19.6663
2094.86	19.8944
2097.77	21.3885
2100.68	20.9803
2103.59	21.5153
2106.5	21.1942
2109.41	21.165
2112.31	20.9097
2115.21	22.7064
2118.12	23.9816
2121.02	26.4503
2123.92	28.4427
2126.82	30.0369
2129.72	32.056
2132.62	36.2032
2135.51	38.0356
2138.41	40.6561
2141.31	43.6568
2144.2	46.6236
2147.09	50.0941
2149.98	53.613
2152.87	58.1711
2155.76	61.2817
2158.65	64.2111
2161.54	66.2887
2164.43	67.2952
2167.31	69.0708
2170.2	71.0678
2173.08	70.0537
2175.96	71.1885
2178.84	70.7423
2181.72	69.9034
2184.6	69.7751
2187.48	68.4695
2190.36	66.3313
2193.23	63.6498
2196.11	60.3292
2198.98	56.8558
2201.85	53.8596
2204.72	50.707
2207.59	47.2339
2210.46	43.4761
2213.33	40.255
2216.2	37.6237
2219.07	33.746
2221.93	32.1238
2224.8	29.82
2227.66	27.4652
2230.52	26.3652
2233.39	23.7289
2236.25	21.885
2239.1	20.9205
2241.96	19.6848
2244.82	19.3557
2247.68	20.4978
2250.53	19.8104
2253.38	19.7964
2256.24	19.1147
2259.09	18.9955
2261.94	18.4798
2264.79	18.2064
2267.64	17.5071
2270.49	16.7725
2273.33	16.073
2276.18	14.5834
2279.02	12.4967
2281.87	10.8208
2284.71	10.3736
2287.55	8.583
2290.39	7.52096
2293.23	6.60155
2296.07	4.58346
2298.91	5.08577
2301.74	5.26597
2304.58	5.30873
2307.41	5.78845
2310.25	7.21116
2313.08	8.28927
2315.91	8.51241
2318.74	7.96085
2321.57	8.22545
2324.4	9.14107
2327.23	9.97034
2330.05	10.6713
2332.88	10.1424
2335.7	11.3974
2338.52	10.148
2341.35	8.77734
2344.17	7.737
2346.99	6.00554
2349.81	4.20524
2352.62	3.44552
2355.44	1.98173
2358.26	0.741172
2361.07	0.702021
2363.89	0.926744
2366.7	2.28806
2369.51	2.88028
2372.32	3.5728
2375.13	4.12753
2377.94	5.86544
2380.75	5.4385
2383.56	5.81658
2386.36	5.90805
2389.17	7.65081
2391.97	7.13265
2394.77	8.04447
2397.58	7.83717
2400.38	7.58263
2403.18	7.38433
2405.97	6.15288
2408.77	5.36117
2411.57	4.67856
2414.37	4.17781
2417.16	4.32379
2419.95	4.25906
2422.75	4.2906
2425.54	4.36047
2428.33	3.60601
2431.12	3.96519
2433.91	2.97927
2436.7	2.32041
2439.48	2.25736
2442.27	2.22919
2445.05	3.48609
2447.84	2.68225
2450.62	1.82712
2453.4	2.29475
2456.18	2.90233
2458.96	3.52998
2461.74	1.96986
2464.52	2.9086
2467.29	2.63269
2470.07	2.13155
2472.85	1.1971
2475.62	2.74447
2478.39	2.89565
2481.16	2.19078
2483.93	2.348
2486.7	2.66877
2489.47	3.53896
2492.24	2.77306
2495.01	1.89077
2497.77	2.74629
2500.54	3.33623
2503.3	3.52001
2506.06	3.63236
2508.83	3.49457
2511.59	3.98161
2514.35	3.50385
2517.11	2.49221
2519.86	2.9564
2522.62	3.71065
2525.38	3.72846
2528.13	2.99705
2530.89	3.27004
2533.64	2.73817
2536.39	0.855217
2539.14	0.959248
2541.89	1.55702
2544.64	0.811666
2547.39	0.521598
2550.14	0.304681
2552.88	1.44135
2555.63	1.43429
2558.37	1.54732
2561.11	0.816067
2563.86	2.85096
2566.6	5.20202
2569.34	6.10337
2572.08	6.84429
2574.82	7.57413
2577.55	9.09906
2580.29	9.99112
2583.02	9.58926
2585.76	9.62607
2588.49	10.4426
2591.22	10.2171
2593.96	9.64708
2596.69	8.88677
2599.42	7.696
2602.14	6.24852
2604.87	4.60127
2607.6	4.83635
2610.32	4.13512
2613.05	3.95229
2615.77	3.35143
2618.49	1.39592
2621.22	0.440766
2623.94	-0.958775
2626.66	-1.59322
2629.37	-0.490726
2632.09	1.1072
2634.81	2.51765
2637.53	3.9219
2640.24	3.89228
2642.96	5.45813
2645.67	5.87114
2648.38	5.24648
2651.09	6.00728
2653.8	6.64016
2656.51	7.07115
2659.22	6.743
2661.93	6.14338
2664.63	5.33136
2667.34	5.93266
2670.04	6.55259
2672.75	5.91642
2675.45	5.92729
2678.15	4.75705
2680.85	3.17301
2683.55	2.80117
2686.25	3.4451
2688.94	3.63274
2691.64	3.71068
2694.34	4.93279
2697.03	6.56883
2699.73	8.11528
2702.42	10.563
2705.11	11.4051
2707.8	11.2277
2710.49	12.432
2713.18	13.2237
2715.87	14.3315
2718.55	15.0991
2721.24	16.4817
2723.93	16.7259
2726.61	15.6725
2729.29	15.8313
2731.98	15.0186
2734.66	15.0278
2737.34	13.4389
2740.02	12.1914
2742.7	10.4808
2745.37	8.61941
2748.05	9.35513
2750.72	8.51527
2753.4	7.2027
2756.07	5.43588
2758.75	5.09721
2761.42	4.97684
2764.09	4.45487
2766.76	4.35457
2769.43	3.82982
2772.1	3.59148
2774.76	3.62752
2777.43	2.82068
2780.1	3.02909
2782.76	2.49236
2785.42	2.0139
2788.09	2.12032
2790.75	2.18776
2793.41	1.03671
2796.07	0.456323
2798.73	-0.161464
2801.39	0.324245
2804.04	0.537043
2806.7	-0.172471
2809.35	-1.02377
2812.01	-0.731321
2814.66	-1.45657
2817.31	-0.952297
2819.96	0.405827
2822.61	1.61179
2825.26	6.37122
2827.91	10.3533
2830.56	14.6603
2833.21	20.6013
2835.85	26.2882
2838.5	33.2802
2841.14	39.3395
2843.78	48.6853
2846.42	59.082
2849.06	69.8178
2851.71	82.6794
2854.34	93.7016
2856.98	104.85
2859.62	115.998
2862.26	127.939
2864.89	137.644
2867.53	147.455
2870.16	154.056
2872.79	161.015
2875.42	166.597
2878.05	171.97
2880.68	177.182
2883.31	182.292
2885.94	185.764
2888.57	191.709
2891.19	196.524
2893.82	200.992
2896.44	208.894
2899.07	215.612
2901.69	223.921
2904.31	233.194
2906.93	244.595
2909.55	258.212
2912.17	271.274
2914.79	284.397
2917.41	295.2
2920.02	305.074
2922.64	313.219
2925.25	320.062
2927.86	322.844
2930.48	321.885
2933.09	320.483
2935.7	316.458
2938.31	309.907
2940.92	302.016
2943.53	293.225
2946.13	282.842
2948.74	271.392
2951.34	260.845
2953.95	248.669
2956.55	236.739
2959.15	226.493
2961.75	216.052
2964.35	204.354
2966.95	193.684
2969.55	184.256
2972.15	175.041
2974.75	166.637
2977.34	157.981
2979.94	148.219
2982.53	137.369
2985.13	125.544
2987.72	113.756
2990.31	101.889
2992.9	89.7576
2995.49	79.5089
2998.08	68.8291
3000.67	58.4282
3003.25	48.6277
3005.84	39.5542
3008.42	30.9297
3011.01	24.1495
3013.59	17.5075
3016.17	12.2165
3018.76	8.85769
3021.34	6.90186
3023.92	5.06167
3026.49	3.32635
3029.07	3.83792
3031.65	4.26865
3034.23	6.14153
3036.8	8.23415
3039.38	10.8186
3041.95	12.054
3044.52	14.567
3047.09	16.9012
3049.66	17.6664
3052.23	19.4253
3054.8	21.718
3057.37	22.1516
3059.94	22.1389
3062.5	21.3819
3065.07	20.0343
3067.63	18.4527
3070.2	16.3018
3072.76	13.6193
3075.32	11.0109
3077.88	8.43642
3080.44	7.36437
3083	5.7996
3085.56	3.71472
3088.12	2.22632
3090.67	1.74324
3093.23	0.933264
3095.78	0.837852
3098.34	3.01365
3100.89	3.18668
3103.44	4.82441
3105.99	6.32181
3108.54	8.82786
3111.09	10.237
3113.64	12.4565
3116.19	14.6055
3118.74	16.5979
3121.28	18.4749
3123.83	20.4005
3126.37	23.2156
3128.91	24.7887
3131.46	26.3937
3134	27.3355
3136.54	28.9671
3139.08	30.0496
3141.62	31.5135
3144.16	33.0644
3146.69	35.1071
3149.23	36.8825