File: data/Raman/poly_smoothed/Thy_50_12_34_1x_45s_532 nm_x100_100%_600 gr_mm_01.txt
#Acq. time (s)=	45
#Accumulations=	2
#Range (cm-¹)=	200...3150
#Windows=	2
#Auto scanning=	Off
#Autofocus=	Off
#Macrospot=	Off
#AutoExposure=	Off
#Spike filter=	Multiple accum.
#Delay time (s)=	0
#Binning=	1
#Readout mode=	Signal
#DeNoise=	Off
#ICS correction=	On
#Dark correction=	Off
#Inst. Process=	Off
#Detector Gain=	Best Dynamic Range
#Detector ADC=	20 kHz
#Detector temperature (°C)=	-69.85
#Instrument=	LabRAM HR Evol
#Detector=	Synapse
#Objective=	x100
#Grating=	600 gr/mm
#ND Filter=	100%
#Laser (nm)=	532
#Hole=	100.021
#Range=	Auto
#Laser Pol.=	No
#Raman. Pol.=	No
#Laser Pol. (°)=	-0.0007625
#Raman Pol. (°)=	89.9995
#Collection=	Microscope
#StageXY=	Marzhauser
#StageZ=	Marzhauser
#X (µm)=	-5136.3
#Y (µm)=	1516.5
#Z (µm)=	63.7
#Full time(mm:ss)=	3:18
#Project=
#Sample=
#Site=
#Title=	Thy_50_12_34_2x_45s_532 nm_x100_100%_600 gr_mm
#Remark=
#Date=	07.07.2022 11:43
#Acquired=	07.07.2022 11:43:54
#Base:Fit=	10.08.2022 10:04:30
#Base:Sub=	10.08.2022 10:04:45
#Filter:Polynom=	16.08.2022 10:20:25
#AxisType[0]=Intens
#AxisUnit[0]=Cnt
#AxisType[1]=Spectr
#AxisUnit[1]=1/cm
200.43	25.1671
204.061	25.5678
207.688	25.1608
211.316	23.4328
214.941	20.7458
218.566	18.0734
222.188	15.8095
225.809	14.1336
229.43	13.0793
233.047	12.4831
236.663	12.3491
240.278	12.4333
243.894	12.2088
247.506	10.6545
251.116	10.144
254.725	9.25887
258.333	8.64817
261.939	11.4343
265.546	11.9542
269.15	11.9886
272.752	13.0241
276.353	15.4214
279.952	15.1726
283.55	15.7709
287.146	15.9837
290.739	15.675
294.333	14.8062
297.925	15.523
301.516	14.9132
305.106	14.6222
308.694	14.5142
312.279	14.7031
315.864	14.4599
319.448	15.48
323.029	14.8153
326.61	15.0461
330.19	15.5891
333.766	15.6348
337.343	13.3244
340.917	14.049
344.491	12.9437
348.062	11.1591
351.633	9.90927
355.201	9.6243
358.77	8.73811
362.335	9.66132
365.899	9.90581
369.464	9.06373
373.025	8.48979
376.585	6.7969
380.143	5.8972
383.702	6.36447
387.258	6.34056
390.812	4.30442
394.365	5.40735
397.916	3.94395
401.467	3.9919
405.015	4.76897
408.565	6.04168
412.111	6.92497
415.656	9.29725
419.197	9.33353
422.739	8.55351
426.279	10.4105
429.819	11.2251
433.356	11.2117
436.893	11.7446
440.428	13.4798
443.96	12.9965
447.492	14.0819
451.023	15.458
454.553	15.4401
458.079	15.9919
461.606	14.961
465.132	15.5023
468.654	16.3553
472.177	17.2319
475.696	18.3765
479.217	17.9431
482.733	17.348
486.251	17.0801
489.765	19.7342
493.278	20.7277
496.791	21.5946
500.301	23.0821
503.81	24.1742
507.319	24.9082
510.825	26.0797
514.33	26.1242
517.833	25.0906
521.337	23.6527
524.838	24.2379
528.337	24.579
531.835	25.0535
535.332	26.2965
538.827	26.1403
542.321	26.4271
545.814	25.1733
549.305	25.7681
552.795	25.5076
556.284	25.7616
559.771	24.856
563.257	23.2712
566.742	22.9968
570.223	22.0509
573.705	23.1602
577.185	23.2061
580.665	21.6562
584.141	20.2892
587.617	19.4013
591.092	16.5996
594.564	14.4059
598.037	13.0049
601.506	11.8045
604.976	11.8179
608.443	11.8889
611.91	13.3203
615.374	13.4428
618.839	14.0499
622.3	14.2114
625.761	14.8338
629.221	15.2169
632.679	17.1303
636.135	18.1558
639.592	19.5678
643.045	22.0144
646.497	23.7666
649.948	24.9254
653.398	27.8305
656.846	30.028
660.293	30.5596
663.738	30.1341
667.185	29.6138
670.628	31.8228
674.067	31.9153
677.508	31.7143
680.947	35.4037
684.385	36.2183
687.821	37.8442
691.256	38.252
694.69	40.6711
698.121	41.7869
701.552	40.952
704.982	41.8953
708.41	43.6014
711.836	46.0027
715.262	47.916
718.685	51.4624
722.108	53.7598
725.53	56.8055
728.949	58.0115
732.369	58.58
735.785	59.5614
739.2	61.1683
742.616	61.6986
746.028	63.8351
749.441	65.0303
752.851	68.7085
756.26	71.0458
759.667	73.2539
763.075	76.537
766.479	78.3898
769.883	79.2462
773.285	80.0479
776.686	81.0371
780.085	81.8069
783.484	81.8289
786.881	83.4127
790.276	85.3973
793.671	88.2646
797.064	89.0099
800.456	91.2516
803.846	92.3227
807.236	93.8976
810.624	92.9174
814.01	91.1622
817.394	91.4802
820.778	92.3858
824.161	91.8446
827.543	91.6359
830.921	92.5619
834.3	92.7144
837.676	90.3673
841.053	87.9661
844.426	86.9365
847.8	84.453
851.171	81.912
854.542	79.0742
857.911	77.0146
861.279	74.3767
864.645	72.8761
868.01	70.5568
871.375	69.3771
874.737	67.5329
878.097	66.9229
881.457	64.2907
884.817	63.8791
888.174	63.5839
891.53	61.107
894.884	60.6907
898.237	61.2472
901.589	62.0328
904.94	61.4119
908.289	60.916
911.637	60.3805
914.984	58.741
918.33	57.5681
921.674	56.0303
925.015	55.3858
928.357	52.8323
931.698	49.4851
935.037	47.4342
938.373	46.7384
941.71	44.3802
945.046	43.6681
948.378	42.2197
951.711	42.6547
955.043	41.6931
958.372	41.1166
961.701	39.7475
965.027	40.9189
968.354	44.3182
971.678	44.0001
975	45.2413
978.324	46.1196
981.644	47.0924
984.962	47.1763
988.282	48.3301
991.598	48.0458
994.913	47.5474
998.227	47.4766
1001.54	46.5402
1004.85	45.6319
1008.16	45.4183
1011.47	45.3175
1014.78	47.9679
1018.08	50.9487
1021.39	52.0079
1024.69	51.1854
1028	51.7842
1031.3	52.3522
1034.6	51.2642
1037.9	48.9061
1041.19	50.2484
1044.49	50.2759
1047.79	50.3588
1051.08	48.8288
1054.37	45.6906
1057.66	43.4309
1060.95	40.5442
1064.24	37.351
1067.53	35.0626
1070.81	30.8366
1074.1	26.7307
1077.38	25.3067
1080.66	25.2503
1083.94	22.8545
1087.22	24.5523
1090.5	23.6088
1093.78	24.855
1097.05	25.1981
1100.33	27.471
1103.6	26.4968
1106.87	27.5096
1110.15	28.486
1113.41	27.2287
1116.68	25.8107
1119.95	25.9512
1123.21	25.6074
1126.48	24.4996
1129.74	24.2425
1133	21.655
1136.26	17.9906
1139.52	16.9594
1142.78	14.7534
1146.04	11.9235
1149.29	10.3067
1152.55	7.94264
1155.8	6.18052
1159.05	5.73064
1162.3	5.32113
1165.55	4.91774
1168.8	4.0693
1172.05	5.19524
1175.29	8.08554
1178.54	10.6231
1181.78	11.5242
1185.02	12.5061
1188.26	13.8018
1191.5	14.4233
1194.74	14.9623
1197.97	15.5252
1201.21	16.5103
1204.44	19.0508
1207.68	20.7229
1210.91	21.6154
1214.14	23.3529
1217.37	26.0287
1220.6	27.7304
1223.82	28.2702
1227.05	31.0471
1230.27	32.9407
1233.49	35.8873
1236.72	38.5205
1239.94	42.4181
1243.16	46.0631
1246.37	49.3504
1249.59	52.4496
1252.8	55.9264
1256.02	59.4677
1259.23	62.9546
1262.44	65.2173
1265.66	69.1058
1268.87	71.3483
1272.07	73.1323
1275.28	74.5666
1278.48	76.8543
1281.69	77.7867
1284.89	80.0819
1288.09	81.4378
1291.3	82.194
1294.49	81.3987
1297.69	80.1693
1300.89	78.7075
1304.09	78.654
1307.28	79.3415
1310.47	78.996
1313.66	78.9347
1316.86	77.3758
1320.05	75.9116
1323.23	73.6188
1326.42	71.2999
1329.61	68.0258
1332.79	65.764
1335.98	63.7601
1339.16	60.3933
1342.34	58.1642
1345.52	55.3053
1348.7	51.3114
1351.87	48.5749
1355.05	46.3756
1358.23	44.3238
1361.4	43.7326
1364.57	43.1836
1367.74	41.889
1370.91	39.6866
1374.08	39.0178
1377.25	38.634
1380.42	39.2068
1383.58	39.261
1386.75	38.5018
1389.91	36.8662
1393.07	36.334
1396.23	35.6431
1399.39	34.4702
1402.55	34.9663
1405.7	36.1103
1408.86	37.3838
1412.01	39.6477
1415.17	40.7865
1418.32	43.6022
1421.47	47.2479
1424.62	50.7366
1427.77	56.5038
1430.92	59.6785
1434.06	66.6306
1437.2	72.5492
1440.35	77.1483
1443.49	80.4458
1446.63	82.6612
1449.77	83.3299
1452.91	82.8428
1456.05	81.2232
1459.18	78.1353
1462.32	73.2213
1465.45	68.9161
1468.59	62.492
1471.72	57.5662
1474.85	51.7987
1477.98	44.9105
1481.11	39.3083
1484.23	34.4784
1487.36	28.5024
1490.48	23.1953
1493.61	20.0995
1496.73	18.6903
1499.85	16.7297
1502.97	16.6469
1506.09	17.9018
1509.2	18.7489
1512.32	19.9246
1515.44	20.6658
1518.55	21.5706
1521.66	22.9807
1524.77	23.8659
1527.88	24.5872
1530.99	26.8948
1534.1	29.0926
1537.21	30.4392
1540.31	32.3429
1543.42	36.6406
1546.52	39.836
1549.62	42.6393
1552.72	46.4953
1555.82	49.9001
1558.92	52.226
1562.02	55.2517
1565.11	57.2015
1568.21	61.5518
1571.3	64.3096
1574.39	66.6876
1577.49	69.0285
1580.58	71.13
1583.67	71.6645
1586.75	72.6786
1589.84	73.5212
1592.93	75.0384
1596.01	75.1629
1599.09	73.6366
1602.18	72.4285
1605.26	71.0657
1608.34	70.8297
1611.41	69.5299
1614.49	69.3687
1617.57	70.5824
1620.64	72.5452
1623.72	72.9947
1626.79	75.2545
1629.86	79.0372
1632.93	82.7272
1636	80.7105
1639.07	82.6396
1642.14	89.1606
1645.2	94.0747
1648.27	99.1202
1651.33	103.183
1654.39	106.649
1657.45	108.919
1660.51	109.704
1663.57	109.336
1666.63	107.249
1669.69	103.774
1672.74	98.9052
1675.79	92.8152
1678.85	84.866
1681.9	76.9066
1684.95	69.3422
1688	60.8008
1691.05	52.2266
1694.1	44.897
1697.14	37.4137
1700.19	30.3193
1703.23	25.3196
1706.27	18.6325
1709.32	11.9999
1712.35	8.55069
1715.39	10.2367
1718.43	10.9971
1721.47	10.8637
1724.5	10.8524
1727.54	9.61756
1730.57	9.63728
1733.61	9.17869
1736.64	9.26504
1739.67	10.4632
1742.7	10.5255
1745.72	11.4305
1748.75	10.497
1751.78	9.22693
1754.8	9.47992
1757.82	9.05804
1760.85	8.51142
1763.87	6.87783
1766.89	5.5942
1769.91	4.5363
1772.92	3.08108
1775.94	3.4926
1778.96	2.17638
1781.97	1.27337
1784.98	1.08922
1788	0.904293
1791.01	1.08233
1794.01	1.16982
1797.02	0.561728
1800.03	1.11508
1803.04	0.0165473
1806.04	0.443729
1809.05	1.42266
1812.05	1.77616
1815.05	2.20402
1818.05	2.33494
1821.05	2.25154
1824.05	2.31908
1827.05	2.73381
1830.04	2.78345
1833.04	3.0228
1836.03	2.88564
1839.03	1.98433
1842.02	1.91028
1845.01	1.75357
1848	1.86204
1850.99	1.85759
1853.97	1.82345
1856.96	3.42842
1859.94	4.04031
1862.93	4.36003
1865.91	4.29392
1868.89	4.74569
1871.87	5.72939
1874.85	6.07338
1877.83	6.20732
1880.81	6.19477
1882.56	5.83204
1885.55	5.68623
1888.54	5.75815
1891.52	6.01915
1894.51	4.79091
1897.49	5.33894
1900.48	4.75753
1903.46	3.97134
1906.44	2.21012
1909.42	1.37157
1912.4	1.39709
1915.38	1.93294
1918.35	2.6612
1921.33	2.5865
1924.3	2.4127
1927.28	3.58208
1930.25	3.72568
1933.22	3.38856
1936.19	4.32207
1939.16	3.61847
1942.13	3.90404
1945.09	3.34293
1948.06	2.49607
1951.03	1.77999
1953.99	1.38934
1956.95	0.681234
1959.91	0.595282
1962.87	0.725173
1965.83	1.16604
1968.79	-0.0298008
1971.75	0.329706
1974.7	-0.259129
1977.66	-0.58649
1980.61	-0.0133815
1983.56	1.02813
1986.52	2.15355
1989.47	3.00085
1992.41	3.93016
1995.36	4.39556
1998.31	5.5491
2001.26	6.41085
2004.2	6.56684
2007.15	6.84782
2010.09	7.66283
2013.03	8.22628
2015.97	8.93253
2018.91	8.91069
2021.85	8.48975
2024.79	8.31033
2027.72	9.23842
2030.66	10.0532
2033.59	10.553
2036.53	10.5875
2039.46	10.9585
2042.39	10.8164
2045.32	11.6115
2048.25	11.836
2051.18	11.4856
2054.1	11.0238
2057.03	11.784
2059.95	12.3408
2062.88	13.692
2065.8	14.4956
2068.72	15.0639
2071.64	16.5444
2074.56	18.7899
2077.48	20.3008
2080.39	22.9207
2083.31	26.0725
2086.22	28.5696
2089.14	30.8052
2092.05	33.2677
2094.96	36.7244
2097.87	39.3134
2100.78	43.2195
2103.69	47.3173
2106.6	51.2614
2109.51	55.981
2112.41	59.5566
2115.32	63.7658
2118.22	67.4506
2121.12	71.4722
2124.02	74.5674
2126.92	78.3955
2129.82	82.4623
2132.72	86.7193
2135.62	90.3717
2138.51	93.7397
2141.41	98.554
2144.3	102.88
2147.19	106.328
2150.09	110.472
2152.97	114.848
2155.86	117.463
2158.75	119.49
2161.64	121.109
2164.53	122.662
2167.41	124.39
2170.3	125.63
2173.18	126.377
2176.06	124.455
2178.94	122.398
2181.82	120.811
2184.7	118.064
2187.58	114.502
2190.46	111.729
2193.33	108.099
2196.21	103.933
2199.08	101.092
2201.95	96.2145
2204.83	92.1265
2207.7	87.9336
2210.57	83.9747
2213.43	78.8464
2216.3	75.3741
2219.17	72.2314
2222.03	68.8747
2224.9	65.6547
2227.76	62.2117
2230.62	59.4024
2233.49	56.3276
2236.34	54.4151
2239.2	51.0737
2242.06	48.6151
2244.92	44.9008
2247.78	41.097
2250.63	38.6219
2253.48	36.3105
2256.34	35.9215
2259.19	34.7352
2262.04	32.8993
2264.89	30.8203
2267.74	29.3582
2270.59	27.4401
2273.43	26.1943
2276.28	24.5044
2279.12	23.8168
2281.97	22.7745
2284.81	21.9035
2287.65	21.8439
2290.49	20.1711
2293.33	19.6145
2296.17	19.2695
2299.01	20.1764
2301.84	20.0811
2304.68	20.3214
2307.51	19.6737
2310.35	19.6182
2313.18	18.6032
2316.01	18.2651
2318.84	17.5657
2321.67	17.0339
2324.5	16.877
2327.33	16.3673
2330.15	14.5222
2332.98	13.1128
2335.8	11.745
2338.62	10.6268
2341.45	8.45496
2344.27	7.00876
2347.09	6.37902
2349.91	4.93587
2352.72	4.29512
2355.54	4.45931
2358.36	3.82778
2361.17	2.31262
2363.98	4.22728
2366.8	5.3938
2369.61	6.14927
2372.42	7.57992
2375.23	6.88867
2378.04	7.81978
2380.85	9.36049
2383.66	10.2707
2386.46	11.3686
2389.26	11.4517
2392.07	11.232
2394.87	11.2919
2397.67	11.0716
2400.47	11.3982
2403.27	11.8923
2406.07	11.592
2408.87	11.1077
2411.67	11.8653
2414.46	11.3676
2417.26	11.6978
2420.05	11.5953
2422.84	12.8341
2425.64	12.9798
2428.43	13.1845
2431.22	13.8818
2434.01	14.1199
2436.79	14.0811
2439.58	13.7129
2442.37	13.0047
2445.15	12.3455
2447.93	12.693
2450.72	12.0094
2453.5	11.0294
2456.28	10.3961
2459.06	9.65768
2461.84	8.41666
2464.62	8.7644
2467.39	7.88854
2470.17	8.11512
2472.94	7.20943
2475.72	6.26884
2478.49	6.99674
2481.26	7.43551
2484.03	7.17601
2486.8	6.92021
2489.57	8.00667
2492.34	7.32801
2495.1	7.04719
2497.87	6.60741
2500.63	5.95848
2503.4	5.1907
2506.16	4.05575
2508.92	2.59774
2511.68	2.00381
2514.44	1.32666
2517.2	1.03908
2519.96	0.94583
2522.72	0.544011
2525.47	1.76979
2528.23	2.02011
2530.98	2.71743
2533.74	3.32268
2536.49	3.69439
2539.24	4.89087
2541.99	6.06345
2544.74	6.5106
2547.49	6.60842
2550.23	7.59461
2552.98	8.60954
2555.72	9.11301
2558.47	10.0419
2561.21	9.7275
2563.95	9.93946
2566.69	8.83303
2569.43	7.80907
2572.17	7.1642
2574.91	5.67136
2577.65	5.21442
2580.39	5.46533
2583.12	4.26271
2585.85	3.53072
2588.59	3.17126
2591.32	2.76385
2594.05	3.30075
2596.78	2.68916
2599.51	1.88087
2602.24	1.75592
2604.97	2.12221
2607.69	1.47973
2610.42	1.50869
2613.14	1.49158
2615.87	1.40547
2618.59	1.70749
2621.31	2.45463
2624.03	3.16259
2626.75	2.9147
2629.47	1.82321
2632.19	1.16359
2634.91	0.883387
2637.62	1.07362
2640.34	0.566962
2643.05	1.93112
2645.76	1.45035
2648.48	1.77005
2651.19	1.94105
2653.9	1.53025
2656.6	1.68501
2659.31	2.31185
2662.02	2.88972
2664.73	2.61304
2667.43	4.18349
2670.14	5.13267
2672.84	4.75993
2675.54	4.64595
2678.24	4.36271
2680.94	4.08303
2683.64	4.08616
2686.34	3.94873
2689.04	4.78029
2691.74	4.5602
2694.43	3.80519
2697.13	3.75544
2699.82	4.02
2702.51	4.70225
2705.21	5.22161
2707.9	7.09542
2710.58	7.75774
2713.27	8.02874
2715.96	9.32104
2718.65	10.1377
2721.33	11.0422
2724.02	12.2307
2726.71	12.5921
2729.39	14.0128
2732.07	14.9826
2734.75	13.581
2737.43	12.4247
2740.11	11.4311
2742.79	9.99464
2745.47	9.25896
2748.14	8.84414
2750.82	8.22384
2753.49	7.58534
2756.17	6.36162
2758.84	5.7334
2761.51	5.52563
2764.18	4.61955
2766.85	3.87381
2769.52	4.06944
2772.19	3.56777
2774.86	3.4089
2777.52	2.20837
2780.19	2.60212
2782.85	2.32197
2785.52	2.78807
2788.18	3.61796
2790.84	3.69269
2793.5	3.78605
2796.16	3.14849
2798.82	2.24328
2801.48	1.30844
2804.13	1.12137
2806.79	0.760181
2809.45	1.76866
2812.1	1.57398
2814.75	2.20697
2817.41	3.49755
2820.06	6.52743
2822.71	11.9157
2825.36	17.1655
2828	23.0829
2830.65	30.4107
2833.3	37.7477
2835.94	44.436
2838.59	51.9321
2841.23	59.05
2843.87	68.4082
2846.52	78.8646
2849.16	90.2758
2851.8	102.806
2854.44	114.737
2857.08	126.108
2859.71	135.973
2862.35	146.574
2864.98	156.065
2867.62	163.501
2870.25	169.411
2872.88	174.718
2875.52	179.638
2878.15	184.981
2880.78	189.307
2883.41	194.458
2886.03	199.707
2888.66	205.003
2891.29	208.542
2893.91	213.32
2896.54	216.844
2899.16	221.584
2901.78	227.512
2904.4	235.367
2907.02	245.613
2909.64	257.588
2912.26	271.196
2914.88	283.713
2917.5	295.81
2920.11	306.765
2922.73	313.478
2925.34	319.58
2927.96	324.771
2930.57	325.549
2933.18	324.651
2935.79	321.909
2938.4	317.486
2941.01	311.502
2943.62	301.827
2946.22	291.355
2948.83	279.4
2951.43	267.96
2954.04	255.166
2956.64	242.096
2959.24	230.417
2961.84	218.071
2964.45	205.546
2967.05	194.898
2969.64	183.231
2972.24	173.704
2974.84	163.949
2977.43	153.764
2980.03	143.404
2982.62	132.338
2985.22	121.422
2987.81	110.392
2990.4	100.845
2992.99	91.3795
2995.58	80.968
2998.17	72.1883
3000.76	62.9688
3003.34	55.0692
3005.93	48.4179
3008.52	41.4486
3011.1	36.0008
3013.68	31.5987
3016.27	29.3243
3018.85	26.2674
3021.43	23.2551
3024.01	20.8589
3026.59	18.8404
3029.16	17.7209
3031.74	17.8037
3034.32	18.7788
3036.89	19.5902
3039.47	20.6511
3042.04	21.2346
3044.61	21.4045
3047.18	22.071
3049.75	22.3779
3052.32	23.0006
3054.89	22.7069
3057.46	21.2622
3060.03	20.2429
3062.59	18.7641
3065.16	17.3949
3067.72	16.2175
3070.29	13.6811
3072.85	11.0232
3075.41	9.06658
3077.97	6.68676
3080.53	4.66251
3083.09	2.16937
3085.65	1.29786
3088.21	-0.113362
3090.76	0.171831
3093.32	-0.265986
3095.87	-0.00592333
3098.43	-0.876157
3100.98	-0.941957
3103.53	-1.9766
3106.08	-1.64698
3108.63	-0.541404
3111.18	0.104978
3113.73	0.639149
3116.28	1.85964
3118.83	2.3049
3121.37	2.32203
3123.92	3.5028
3126.46	4.6459
3129	5.13145
3131.55	5.68709
3134.09	6.19972
3136.63	7.35007
3139.17	8.41113
3141.71	9.40875
3144.24	10.3523
3146.78	11.0226
3149.32	11.8519