File: data/Raman/poly_smoothed/Thy_00_07_26_1x_45s_532 nm_x100_100%_600 gr_mm_01.txt
#Acq. time (s)=	45
#Accumulations=	2
#Range (cm-¹)=	200...3150
#Windows=	2
#Auto scanning=	Off
#Autofocus=	Off
#Macrospot=	Off
#AutoExposure=	Off
#Spike filter=	Multiple accum.
#Delay time (s)=	0
#Binning=	1
#Readout mode=	Signal
#DeNoise=	Off
#ICS correction=	On
#Dark correction=	Off
#Inst. Process=	Off
#Detector Gain=	Best Dynamic Range
#Detector ADC=	20 kHz
#Detector temperature (°C)=	-69.85
#Instrument=	LabRAM HR Evol
#Detector=	Synapse
#Objective=	x100
#Grating=	600 gr/mm
#ND Filter=	100%
#Laser (nm)=	532
#Hole=	100.021
#Range=	Auto
#Laser Pol.=	No
#Raman. Pol.=	No
#Laser Pol. (°)=	-0.0007625
#Raman Pol. (°)=	89.9995
#Collection=	Microscope
#StageXY=	Marzhauser
#StageZ=	Marzhauser
#X (µm)=	8998.3
#Y (µm)=	-3057.5
#Z (µm)=	-55.15
#Full time(mm:ss)=	3:18
#Project=
#Sample=
#Site=
#Title=	Thy_00_07_26_2x_45s_532 nm_x100_100%_600 gr_mm
#Remark=
#Date=	28.06.2022 12:02
#Acquired=	28.06.2022 12:02:00
#Base:Fit=	10.08.2022 10:07:56
#Base:Sub=	10.08.2022 10:08:40
#Filter:Polynom=	16.08.2022 10:26:06
#AxisType[0]=Intens
#AxisUnit[0]=Cnt
#AxisType[1]=Spectr
#AxisUnit[1]=1/cm
200.407	58.4658
204.035	53.1831
207.665	48.9021
211.291	45.5495
214.916	40.1662
218.541	34.6583
222.163	31.5018
225.785	25.7039
229.404	21.5808
233.022	18.1157
236.638	17.7305
240.255	14.9913
243.868	13.3588
247.48	11.7123
251.091	9.92756
254.702	9.086
258.31	8.81862
261.916	8.03271
265.521	8.95541
269.125	7.40617
272.727	7.73398
276.328	7.34614
279.927	7.188
283.525	5.42641
287.121	6.47668
290.716	6.97714
294.31	8.3683
297.9	8.81259
301.491	7.21971
305.081	6.69272
308.669	7.54827
312.256	8.06467
315.839	8.49807
319.423	9.51469
323.006	12.2829
326.585	14.2848
330.165	16.1109
333.741	18.0758
337.318	19.4414
340.894	20.5109
344.466	21.6227
348.039	21.5191
351.608	20.2694
355.176	18.433
358.745	16.4918
362.31	17.5576
365.876	15.4747
369.439	14.4779
373	13.6396
376.56	14.6631
380.12	13.316
383.677	13.6966
387.233	11.0652
390.787	8.64764
394.34	7.61773
397.894	5.58697
401.444	5.13771
404.993	7.00886
408.54	8.98584
412.086	10.8738
415.631	11.9149
419.174	12.5597
422.716	13.7933
426.257	14.0038
429.794	12.7836
433.332	9.5656
436.868	7.27603
440.403	7.53324
443.937	10.8135
447.468	18.8138
450.999	24.7599
454.528	30.1378
458.057	36.8019
461.582	42.4598
465.107	47.422
468.629	50.8069
472.152	52.9151
475.672	54.9494
479.192	57.2925
482.709	61.5982
486.226	62.7024
489.74	65.1071
493.255	65.3697
496.767	63.1616
500.277	61.1606
503.788	56.4657
507.295	51.0222
510.801	45.588
514.308	38.7537
517.811	32.0528
521.313	26.3121
524.814	25.7465
528.313	24.8715
531.811	23.6357
535.308	22.395
538.803	21.1655
542.297	19.3348
545.789	18.4435
549.281	18.1936
552.771	17.7153
556.259	18.6123
559.747	20.0451
563.233	21.2939
566.717	24.1118
570.2	24.1936
573.68	24.7126
577.161	24.2761
580.64	23.8265
584.118	22.0889
587.593	20.1555
591.068	20.3803
594.54	18.5678
598.013	17.7403
601.484	14.8098
604.952	12.6604
608.421	11.8855
611.886	9.78479
615.35	6.29719
618.815	4.61472
622.276	4.3247
625.738	3.29301
629.197	3.57829
632.655	5.83073
636.113	5.68602
639.568	5.38586
643.021	6.89187
646.473	8.65631
649.924	8.65678
653.376	7.95601
656.824	8.3714
660.271	7.47961
663.716	6.72356
667.161	6.9485
670.604	7.53003
674.045	9.27021
677.486	10.5912
680.925	10.7524
684.361	11.7524
687.797	14.2019
691.232	17.0333
694.666	17.5859
698.099	16.7514
701.528	17.7134
704.958	18.6267
708.387	19.5267
711.814	23.1233
715.238	25.0653
718.663	28.1184
722.084	29.9669
725.506	33.3502
728.925	34.2736
732.345	36.7005
735.761	38.3868
739.178	42.1884
742.592	45.1029
746.006	47.7552
749.417	52.2944
752.827	56.7829
756.236	60.7606
759.645	65.1374
763.051	68.4495
766.456	71.426
769.859	73.361
773.261	74.997
776.664	72.3254
780.064	70.3485
783.462	69.1763
786.859	68.6396
790.255	68.7106
793.649	69.5624
797.042	70.1094
800.434	68.8765
803.823	68.7007
807.212	67.4333
810.6	68.0659
813.987	70.1483
817.372	73.0597
820.754	76.3579
824.137	82.352
827.519	87.0214
830.897	90.1958
834.276	94.2413
837.654	97.3718
841.029	100.263
844.404	103.244
847.776	103.165
851.149	100.768
854.519	98.1739
857.889	93.9768
861.256	89.401
864.622	85.8492
867.988	80.7951
871.351	74.9006
874.713	70.9293
878.074	65.1255
881.435	59.9677
884.794	56.4517
888.15	54.5871
891.506	51.7834
894.861	52.7214
898.214	51.9654
901.566	54.4831
904.916	59.648
908.266	65.3926
911.614	70.3667
914.961	75.3038
918.306	79.6326
921.651	82.5933
924.994	83.7296
928.336	83.7656
931.674	82.0834
935.014	79.9835
938.352	76.594
941.687	72.5352
945.022	69.0777
948.357	64.0539
951.688	59.8903
955.02	55.4882
958.348	48.5306
961.678	42.8911
965.004	38.893
968.331	39.6034
971.655	37.4396
974.979	37.8159
978.3	38.7282
981.62	40.6772
984.941	44.6728
988.259	46.9281
991.575	48.7387
994.89	50.4176
998.204	50.7388
1001.52	53.1042
1004.83	53.1936
1008.14	56.7777
1011.45	60.7633
1014.76	62.9647
1018.06	60.4455
1021.37	59.939
1024.67	59.7672
1027.97	61.077
1031.27	62.791
1034.57	66.5451
1037.87	67.2362
1041.17	69.9917
1044.47	73.7273
1047.76	77.7086
1051.06	81.3633
1054.35	83.4613
1057.64	83.3346
1060.93	84.5085
1064.22	84.2714
1067.5	83.3773
1070.79	82.9119
1074.08	84.1788
1077.36	83.8841
1080.64	83.6338
1083.92	84.3695
1087.2	83.4088
1090.48	83.8034
1093.76	82.2093
1097.03	79.1056
1100.31	77.4666
1103.58	81.1121
1106.85	82.8822
1110.12	85.595
1113.39	84.8295
1116.66	85.2053
1119.93	83.7799
1123.19	82.9368
1126.46	82.5645
1129.72	80.9386
1132.98	79.2243
1136.24	76.3969
1139.5	71.8327
1142.76	67.2383
1146.01	61.1816
1149.27	55.6606
1152.53	48.8958
1155.78	41.9421
1159.03	34.585
1162.28	28.5139
1165.53	22.0412
1168.78	17.0284
1172.02	13.9624
1175.27	13.0344
1178.51	11.9123
1181.76	10.6985
1185	10.7205
1188.24	9.85845
1191.48	11.3383
1194.71	12.0474
1197.95	15.8999
1201.19	20.0487
1204.42	23.9462
1207.65	30.341
1210.88	36.3724
1214.12	42.5816
1217.35	46.4514
1220.57	49.9105
1223.8	54.5146
1227.03	58.0326
1230.25	61.0652
1233.47	64.2562
1236.69	66.4744
1239.92	68.9442
1243.13	70.2803
1246.35	70.3358
1249.57	72.1677
1252.78	70.2496
1256	68.796
1259.21	67.2555
1262.42	66.3582
1265.63	63.7366
1268.84	62.7947
1272.05	63.2554
1275.26	61.8776
1278.46	62.6021
1281.67	62.7951
1284.87	65.654
1288.07	68.4587
1291.27	71.1996
1294.47	74.5777
1297.67	77.5829
1300.87	82.3878
1304.06	87.8054
1307.26	94.6933
1310.45	102.574
1313.64	109.088
1316.83	115.192
1320.02	118.204
1323.21	120.369
1326.4	124.532
1329.59	125.219
1332.77	126.063
1335.95	126.958
1339.14	126.842
1342.32	126.064
1345.5	125.537
1348.67	125.13
1351.85	122.263
1355.03	117.285
1358.2	114.839
1361.38	110.913
1364.55	107.188
1367.72	104.004
1370.89	101.324
1374.06	98.2993
1377.23	95.0719
1380.39	94.8465
1383.56	94.4727
1386.72	94.299
1389.89	92.6025
1393.05	90.0711
1396.21	86.9975
1399.37	83.6063
1402.52	81.8568
1405.68	81.2792
1408.84	78.968
1411.99	77.9713
1415.15	77.8864
1418.3	78.5306
1421.45	81.9398
1424.6	85.0915
1427.75	88.8887
1430.89	94.9457
1434.04	100.186
1437.18	104.896
1440.33	108.82
1443.47	111.772
1446.61	114.463
1449.75	115.419
1452.89	114.542
1456.03	114.978
1459.16	111.667
1462.3	106.895
1465.43	99.2907
1468.56	91.437
1471.7	81.8692
1474.83	71.3877
1477.96	60.9479
1481.08	52.5621
1484.21	42.2072
1487.34	32.1634
1490.46	24.5621
1493.58	18.1539
1496.71	14.9713
1499.83	13.7424
1502.95	11.9215
1506.07	11.8738
1509.18	12.2606
1512.3	13.1732
1515.41	13.3272
1518.53	15.3105
1521.64	17.4225
1524.75	21.249
1527.86	22.4652
1530.97	25.5348
1534.08	28.2876
1537.19	29.0257
1540.29	30.9452
1543.4	32.0401
1546.5	33.208
1549.6	34.1172
1552.7	36.5538
1555.8	39.3433
1558.9	42.9014
1562	44.8691
1565.09	48.3035
1568.19	51.2629
1571.28	55.4814
1574.37	59.3139
1577.47	62.598
1580.56	66.7781
1583.64	70.1589
1586.73	72.7
1589.82	74.1879
1592.9	75.4678
1595.99	76.72
1599.07	77.5203
1602.15	77.0222
1605.23	76.2624
1608.31	75.3678
1611.39	73.0571
1614.47	70.9969
1617.55	68.2991
1620.62	66.5717
1623.7	67.6071
1626.77	68.5741
1629.84	70.4285
1632.91	72.3938
1635.98	75.1356
1639.05	78.237
1642.11	79.986
1645.18	83.2069
1648.24	85.7877
1651.31	88.009
1654.37	88.7528
1657.43	89.4385
1660.49	86.8099
1663.55	84.595
1666.61	81.8608
1669.66	78.5913
1672.72	75.1356
1675.77	70.8745
1678.83	65.1478
1681.88	58.3866
1684.93	52.409
1687.98	47.0075
1691.03	42.6278
1694.07	36.6311
1697.12	32.9563
1700.17	30.3547
1703.21	27.8574
1706.25	24.8949
1709.29	20.5761
1712.33	18.9279
1715.37	16.3167
1718.41	14.969
1721.45	12.3588
1724.49	10.6843
1727.52	8.79583
1730.55	7.59977
1733.59	6.81766
1736.62	6.99242
1739.65	7.31597
1742.68	7.06805
1745.7	5.8201
1748.73	5.60262
1751.76	4.37273
1754.78	4.73845
1757.8	4.87792
1760.83	4.92116
1763.85	5.10589
1766.87	4.08888
1769.89	4.51787
1772.9	5.09015
1775.92	4.9403
1778.94	4.65481
1781.95	3.64153
1784.96	3.05442
1787.97	3.17154
1790.99	2.77833
1794	1.78086
1797	0.670428
1800.01	0.931402
1803.02	1.535
1806.02	2.26704
1809.03	3.61379
1812.03	3.68553
1815.03	3.43151
1818.03	3.49871
1821.03	3.6094
1824.03	4.09133
1827.03	4.39055
1830.02	5.36935
1833.02	5.3999
1836.01	5.73944
1839.01	6.28852
1842	6.84263
1844.99	7.25906
1847.98	8.05581
1850.97	7.82207
1853.95	7.12986
1856.94	6.01126
1859.93	5.03422
1862.91	4.26809
1865.89	2.65411
1868.87	2.16465
1871.85	3.1055
1874.83	2.95835
1877.81	2.22715
1880.79	2.38623
1882.52	2.31782
1885.51	2.91655
1888.5	3.03586
1891.49	2.10136
1894.47	3.52432
1897.46	2.8296
1900.44	4.19365
1903.42	4.55119
1906.4	4.64758
1909.38	4.29994
1912.36	4.14165
1915.34	3.8116
1918.32	4.53348
1921.29	4.39316
1924.27	4.46642
1927.24	4.00253
1930.21	3.78961
1933.18	4.65821
1936.15	3.7264
1939.12	4.12814
1942.09	3.85795
1945.06	3.64002
1948.02	2.91997
1950.99	2.78425
1953.95	3.38019
1956.91	3.58999
1959.88	2.89546
1962.84	2.9945
1965.8	2.69438
1968.75	1.93848
1971.71	1.78266
1974.67	2.70712
1977.62	2.07767
1980.58	2.38205
1983.53	2.02567
1986.48	2.22967
1989.43	3.82928
1992.38	4.02666
1995.33	4.48606
1998.27	4.70294
2001.22	4.98974
2004.16	5.23386
2007.11	5.60784
2010.05	5.92092
2012.99	6.88674
2015.93	6.40865
2018.87	6.82282
2021.81	6.6828
2024.75	6.90169
2027.69	6.59396
2030.62	6.22312
2033.56	6.253
2036.49	5.98361
2039.42	6.69843
2042.35	7.08752
2045.28	8.65056
2048.21	8.07653
2051.14	7.50499
2054.07	8.05894
2056.99	8.44965
2059.92	8.06758
2062.84	7.44309
2065.76	7.95588
2068.68	8.03949
2071.6	8.19203
2074.52	8.56687
2077.44	8.46292
2080.36	8.5776
2083.27	7.93318
2086.19	8.38888
2089.1	8.03947
2092.02	8.13724
2094.93	7.75377
2097.84	6.67653
2100.75	5.31399
2103.66	6.15903
2106.56	4.85732
2109.47	4.1914
2112.38	3.7244
2115.28	4.28257
2118.18	3.40255
2121.09	2.57717
2123.99	3.08697
2126.89	2.41762
2129.79	1.06154
2132.68	1.50529
2135.58	1.99413
2138.48	2.51086
2141.37	2.51586
2144.27	2.62036
2147.16	3.67896
2150.05	4.16909
2152.94	4.69019
2155.83	4.64651
2158.72	4.51191
2161.6	4.45777
2164.49	4.42194
2167.38	4.5282
2170.26	4.19822
2173.14	3.80449
2176.03	3.17782
2178.91	2.25927
2181.79	3.03935
2184.67	3.66334
2187.54	4.0333
2190.42	4.35269
2193.3	3.88611
2196.17	3.16404
2199.05	3.3248
2201.92	3.20531
2204.79	3.65827
2207.66	4.19717
2210.53	4.68456
2213.4	4.94012
2216.27	5.09264
2219.13	4.94232
2222	4.87345
2224.86	5.25118
2227.72	4.67209
2230.59	4.98894
2233.45	4.37381
2236.31	4.39748
2239.17	4.75292
2242.03	4.38256
2244.88	3.53398
2247.74	2.79595
2250.59	2.79379
2253.45	3.12146
2256.3	3.67585
2259.15	3.82525
2262	3.1996
2264.85	3.3792
2267.7	4.11308
2270.55	3.44268
2273.4	5.14047
2276.24	5.5697
2279.09	5.46626
2281.93	4.8369
2284.77	5.08295
2287.62	5.25066
2290.46	4.41984
2293.3	5.10216
2296.13	4.65871
2298.97	5.10337
2301.81	5.74735
2304.64	6.212
2307.48	5.87078
2310.31	5.76393
2313.14	4.55453
2315.98	3.97437
2318.81	4.33851
2321.64	4.79951
2324.46	6.44532
2327.29	6.28223
2330.12	6.00503
2332.94	6.50009
2335.77	6.45394
2338.59	6.09295
2341.41	6.14361
2344.23	4.94123
2347.05	4.29065
2349.87	4.27602
2352.69	3.63544
2355.51	3.48813
2358.32	3.44243
2361.14	2.46093
2363.95	3.2783
2366.76	4.03434
2369.58	3.74098
2372.39	3.08163
2375.2	1.85132
2378	1.23468
2380.81	0.989634
2383.62	1.12841
2386.43	1.21761
2389.23	0.711693
2392.03	0.502982
2394.84	0.222304
2397.64	0.509704
2400.44	1.02382
2403.24	1.75548
2406.04	1.7936
2408.84	2.60146
2411.63	4.05352
2414.43	5.03273
2417.22	6.60821
2420.02	7.99084
2422.81	8.11557
2425.6	10.0522
2428.39	10.6801
2431.18	11.6512
2433.97	11.9885
2436.76	12.0376
2439.54	12.173
2442.33	11.1417
2445.12	10.1255
2447.9	9.18659
2450.68	7.80878
2453.46	6.50581
2456.24	4.68563
2459.02	4.12688
2461.8	3.74411
2464.58	4.12289
2467.36	3.79723
2470.13	3.97225
2472.91	4.27741
2475.68	3.6624
2478.45	4.70653
2481.23	5.37067
2484	5.81691
2486.77	5.67652
2489.54	4.82132
2492.3	5.25079
2495.07	4.62277
2497.84	4.36521
2500.6	4.05263
2503.36	4.23871
2506.13	3.61436
2508.89	3.67648
2511.65	2.66028
2514.41	2.68354
2517.17	2.59959
2519.93	2.63903
2522.68	3.31346
2525.44	2.80298
2528.19	3.25956
2530.95	2.96314
2533.7	3.53539
2536.45	4.48163
2539.2	5.50358
2541.95	5.27515
2544.7	5.62931
2547.45	5.72794
2550.2	5.56436
2552.94	4.96491
2555.69	4.31493
2558.43	3.21776
2561.18	2.81805
2563.92	2.91967
2566.66	3.16267
2569.4	3.41798
2572.14	3.89254
2574.88	4.03021
2577.61	3.79715
2580.35	3.52797
2583.09	3.53034
2585.82	3.21616
2588.55	2.86269
2591.29	2.18159
2594.02	1.78773
2596.75	2.35616
2599.48	2.02493
2602.21	2.92172
2604.93	3.08679
2607.66	3.03313
2610.39	2.57966
2613.11	3.20962
2615.83	2.6914
2618.56	1.8285
2621.28	1.25386
2624	0.734827
2626.72	1.08067
2629.44	0.935953
2632.15	1.19894
2634.87	1.57539
2637.59	2.26002
2640.3	2.5625
2643.02	2.26052
2645.73	2.58708
2648.44	2.52877
2651.15	2.64779
2653.86	2.10708
2656.57	3.07264
2659.28	2.95804
2661.99	4.57455
2664.69	4.43654
2667.4	5.16749
2670.1	6.32844
2672.81	6.55134
2675.51	6.89626
2678.21	6.60626
2680.91	6.71177
2683.61	6.18733
2686.31	5.71349
2689	5.13322
2691.7	5.65163
2694.4	5.53551
2697.09	5.81605
2699.79	5.90251
2702.48	6.20675
2705.17	7.61947
2707.86	7.71178
2710.55	7.70014
2713.24	8.28087
2715.93	9.01368
2718.62	9.6087
2721.3	10.1335
2723.99	11.4292
2726.67	12.141
2729.35	12.4159
2732.04	13.0333
2734.72	13.952
2737.4	12.8052
2740.08	12.0841
2742.76	12.4028
2745.43	10.9042
2748.11	9.28325
2750.79	7.89108
2753.46	6.56641
2756.14	5.6814
2758.81	4.58887
2761.48	3.13822
2764.15	3.12752
2766.82	1.71616
2769.49	1.05896
2772.16	0.618517
2774.82	0.454656
2777.49	0.523973
2780.16	-0.152219
2782.82	-0.277001
2785.48	-0.406268
2788.15	-0.94565
2790.81	-0.798535
2793.47	-0.594837
2796.13	-0.313708
2798.79	0.651853
2801.44	1.74839
2804.1	1.82845
2806.76	3.06071
2809.41	3.40579
2812.07	3.40141
2814.72	4.69858
2817.37	6.43429
2820.02	8.26251
2822.67	10.2222
2825.32	13.003
2827.97	16.8897
2830.62	20.7665
2833.26	24.8227
2835.91	29.6618
2838.56	35.7404
2841.2	43.3767
2843.84	51.5657
2846.48	61.3633
2849.12	71.8637
2851.77	84.0746
2854.4	96.8088
2857.04	112.352
2859.68	128.898
2862.32	145.905
2864.95	163.022
2867.59	180.511
2870.22	198.043
2872.85	215.532
2875.48	233.093
2878.11	251.048
2880.74	268.78
2883.37	285.85
2886	302.01
2888.63	318.612
2891.25	333.523
2893.88	346.842
2896.5	359.803
2899.13	372.865
2901.75	384.179
2904.37	397.195
2906.99	408.937
2909.61	418.344
2912.23	427.443
2914.85	436.841
2917.46	443.769
2920.08	450.114
2922.7	455.792
2925.31	457.86
2927.92	456.863
2930.54	453.06
2933.15	446.963
2935.76	440.168
2938.37	431.66
2940.98	420.76
2943.58	410.217
2946.19	398.085
2948.8	383.792
2951.4	369.059
2954.01	354.905
2956.61	339.474
2959.21	324.264
2961.81	310.832
2964.41	295.265
2967.01	280.563
2969.61	266.706
2972.21	251.619
2974.81	236.78
2977.4	222.459
2980	208.443
2982.59	192.352
2985.18	177.164
2987.78	162.077
2990.37	145.263
2992.96	128.617
2995.55	113.04
2998.14	99.3204
3000.73	85.5566
3003.31	72.6757
3005.9	60.7014
3008.48	50.3245
3011.07	39.1057
3013.65	30.089
3016.23	24.0516
3018.81	18.3362
3021.4	13.4941
3023.97	9.48013
3026.55	6.46757
3029.13	5.15184
3031.71	4.3151
3034.28	4.14907
3036.86	4.61656
3039.43	6.44398
3042.01	9.44481
3044.58	12.2202
3047.15	15.7565
3049.72	18.5768
3052.29	22.0005
3054.86	23.7425
3057.43	26.0854
3060	28.3624
3062.56	29.5541
3065.13	30.7566
3067.69	30.9002
3070.26	30.7514
3072.82	31.0441
3075.38	30.4602
3077.94	30.2757
3080.5	30.4127
3083.06	28.8195
3085.62	28.1978
3088.18	28.7269
3090.73	29.6144
3093.29	31.4905
3095.84	32.6004
3098.4	34.4847
3100.95	37.1229
3103.5	40.3587
3106.05	43.3283
3108.6	47.3024
3111.15	50.4334
3113.7	54.3769
3116.25	57.9841
3118.79	62.0694
3121.34	66.4731
3123.88	71.2157
3126.43	75.1436
3128.97	80.0401
3131.51	84.1395
3134.06	88.5139
3136.6	92.7496
3139.14	96.9167
3141.67	102.026
3144.21	106.834
3146.75	112.151
3149.29	116.526