File: data/Raman/poly_smoothed/Thy_20_09_13_1x_45s_532 nm_x100_100%_600 gr_mm_01.txt
#Acq. time (s)=	45
#Accumulations=	2
#Range (cm-¹)=	200...3150
#Windows=	2
#Auto scanning=	Off
#Autofocus=	Off
#Macrospot=	Off
#AutoExposure=	Off
#Spike filter=	Multiple accum.
#Delay time (s)=	0
#Binning=	1
#Readout mode=	Signal
#DeNoise=	Off
#ICS correction=	On
#Dark correction=	Off
#Inst. Process=	Off
#Detector Gain=	Best Dynamic Range
#Detector ADC=	20 kHz
#Detector temperature (°C)=	-69.85
#Instrument=	LabRAM HR Evol
#Detector=	Synapse
#Objective=	x100
#Grating=	600 gr/mm
#ND Filter=	100%
#Laser (nm)=	532
#Hole=	100.021
#Range=	Auto
#Laser Pol.=	No
#Raman. Pol.=	No
#Laser Pol. (°)=	-0.0007625
#Raman Pol. (°)=	89.9995
#Collection=	Microscope
#StageXY=	Marzhauser
#StageZ=	Marzhauser
#X (µm)=	-5896.9
#Y (µm)=	2848.3
#Z (µm)=	-223.7
#Full time(mm:ss)=	3:18
#Project=
#Sample=
#Site=
#Title=	Thy_20_09_13_2x_45s_532 nm_x100_100%_600 gr_mm
#Remark=
#Date=	29.06.2022 11:37
#Acquired=	29.06.2022 11:37:12
#Base:Fit=	10.08.2022 09:52:02
#Base:Fit=	10.08.2022 09:52:12
#Base:Sub=	10.08.2022 09:54:21
#Filter:Polynom=	16.08.2022 10:24:04
#AxisType[0]=Intens
#AxisUnit[0]=Cnt
#AxisType[1]=Spectr
#AxisUnit[1]=1/cm
200.523	19.4719
204.154	16.4496
207.781	16.0797
211.409	14.894
215.034	13.7417
218.659	11.5131
222.281	11.0234
225.903	10.0676
229.522	8.30989
233.14	5.038
236.756	4.04632
240.373	4.59232
243.986	4.05082
247.598	4.0165
251.208	2.45476
254.818	3.54968
258.427	3.33096
262.034	5.23785
265.638	5.8848
269.242	6.87416
272.844	6.3131
276.445	5.75651
280.044	6.66593
283.642	5.7163
287.238	5.65432
290.833	7.49111
294.425	8.10522
298.017	8.14896
301.608	8.12175
305.198	6.93238
308.786	6.38578
312.371	6.42009
315.956	5.36239
319.54	5.00422
323.122	6.64482
326.701	6.71419
330.281	7.17637
333.857	6.73859
337.434	5.84809
341.008	6.75511
344.582	6.16875
348.153	7.51032
351.724	6.67409
355.292	6.85564
358.861	6.58259
362.426	7.12386
365.99	6.56805
369.555	7.44843
373.116	6.92948
376.676	5.47813
380.236	7.46513
383.793	6.88843
387.349	6.17034
390.903	6.34339
394.456	6.04912
398.007	7.55016
401.56	6.90429
405.108	7.87037
408.656	8.45022
412.202	9.62744
415.746	9.8051
419.29	11.3423
422.831	12.4977
426.37	13.4633
429.909	13.5316
433.447	13.1904
436.983	12.6669
440.519	11.2051
444.052	11.9506
447.583	10.0657
451.114	10.7853
454.643	10.3892
458.169	9.02181
461.696	6.8295
465.222	6.98466
468.744	6.50176
472.267	7.55572
475.787	9.12699
479.307	10.5159
482.823	11.077
486.341	12.9124
489.855	14.1054
493.37	16.1651
496.881	17.7489
500.391	20.0552
503.902	20.9483
507.409	20.1094
510.915	19.6941
514.42	20.8683
517.925	20.9909
521.427	20.079
524.928	19.1917
528.427	19.1175
531.925	18.5694
535.422	17.7832
538.917	18.6425
542.411	16.5762
545.903	14.918
549.395	14.1072
552.884	13.5304
556.373	14.3745
559.86	14.3655
563.346	13.5382
566.831	11.5203
570.314	10.7882
573.794	10.1818
577.274	8.50074
580.754	6.59169
584.23	6.27899
587.706	5.47711
591.181	2.77605
594.653	2.42679
598.126	1.9343
601.595	2.34528
605.065	2.20866
608.532	1.49291
611.999	3.10363
615.463	2.47696
618.928	4.9571
622.389	6.72884
625.851	5.96416
629.31	7.66257
632.767	11.186
636.223	13.3902
639.68	15.2592
643.134	16.4786
646.586	17.3269
650.037	19.0212
653.486	21.1639
656.936	24.125
660.383	25.5816
663.829	26.8498
667.273	27.646
670.716	27.8499
674.158	27.4733
677.598	27.6642
681.035	27.7709
684.473	27.3351
687.909	26.2344
691.344	27.007
694.778	26.5087
698.211	27.6232
701.64	29.0047
705.07	30.675
708.498	30.0209
711.924	31.9244
715.35	35.9167
718.774	37.3049
722.196	37.2401
725.618	38.8625
729.037	40.714
732.456	43.5113
735.873	45.3448
739.289	47.4373
742.703	48.1021
746.116	49.0679
749.529	50.7442
752.938	51.7563
756.347	53.3365
759.756	52.0426
763.162	51.9156
766.567	51.0448
769.97	51.0147
773.372	51.726
776.773	53.9063
780.174	53.6834
783.573	55.4086
786.97	55.7424
790.365	57.0894
793.76	58.4564
797.153	62.1365
800.543	64.3069
803.933	64.6412
807.322	66.4674
810.71	69.4153
814.097	70.8709
817.483	72.4045
820.865	72.483
824.248	72.148
827.629	73.5821
831.008	72.2399
834.387	71.3109
837.765	70.0238
841.139	66.7705
844.514	64.408
847.886	61.462
851.259	59.3885
854.629	57.1314
857.997	55.9337
861.366	53.9018
864.732	51.1371
868.098	50.8226
871.461	51.0613
874.823	50.8872
878.184	50.3524
881.545	47.9803
884.903	46.2729
888.26	45.1324
891.616	45.0918
894.97	45.0361
898.323	45.1217
901.675	43.7258
905.026	42.3494
908.375	41.403
911.723	41.0165
915.07	38.3215
918.415	37.4703
921.76	35.7017
925.103	34.988
928.443	33.2925
931.783	31.3525
935.123	29.8412
938.461	28.8478
941.796	26.88
945.131	25.9542
948.465	24.9475
951.797	25.9973
955.128	24.6383
958.457	21.9781
961.786	19.9801
965.113	21.4954
968.44	23.1824
971.763	25.6474
975.086	28.4883
978.409	29.8677
981.729	30.2415
985.048	29.7887
988.367	30.4605
991.683	30.8228
994.998	30.6823
998.312	30.8797
1001.62	31.3019
1004.94	29.7329
1008.25	29.3218
1011.56	28.73
1014.86	26.6171
1018.17	24.3593
1021.48	21.242
1024.78	20.767
1028.08	18.3013
1031.38	16.7515
1034.68	14.1762
1037.98	11.0391
1041.28	9.55604
1044.57	10.0268
1047.87	11.8394
1051.16	9.87905
1054.45	10.4583
1057.75	8.73058
1061.04	6.68304
1064.32	3.71174
1067.61	4.08447
1070.9	3.77236
1074.18	4.37975
1077.47	4.6621
1080.75	4.11866
1084.03	3.78421
1087.31	5.26458
1090.59	6.64811
1093.86	8.47758
1097.14	9.14648
1100.41	11.1967
1103.69	10.7322
1106.96	10.5737
1110.23	10.0537
1113.5	10.9291
1116.77	12.0683
1120.03	13.1725
1123.3	13.2153
1126.56	12.1648
1129.83	11.4241
1133.09	10.6068
1136.35	9.04653
1139.61	9.30495
1142.86	9.28145
1146.12	7.76563
1149.38	7.81773
1152.63	6.49007
1155.88	4.45123
1159.14	5.57016
1162.39	4.6244
1165.63	4.47607
1168.88	4.32847
1172.13	5.12559
1175.38	5.8219
1178.62	6.73485
1181.86	6.15037
1185.1	6.23759
1188.34	7.80327
1191.58	9.42855
1194.82	11.6121
1198.06	12.9783
1201.29	14.7375
1204.53	17.4599
1207.76	20.4565
1210.99	24.5383
1214.22	29.3926
1217.45	35.2242
1220.68	40.2861
1223.91	43.9559
1227.13	47.4889
1230.36	51.4818
1233.58	54.4407
1236.8	58.1967
1240.02	60.901
1243.24	63.3506
1246.46	64.6274
1249.67	66.5204
1252.89	67.2685
1256.1	69.3202
1259.32	69.5002
1262.53	68.7906
1265.74	67.0005
1268.95	67.9019
1272.15	67.8388
1275.36	68.0904
1278.57	69.6472
1281.77	71.264
1284.97	73.6793
1288.18	75.997
1291.38	77.456
1294.58	79.2713
1297.78	80.7029
1300.97	82.4734
1304.17	85.0971
1307.36	87.9924
1310.55	90.6679
1313.75	93.239
1316.94	94.4125
1320.13	95.3636
1323.32	95.5538
1326.5	95.3535
1329.69	95.867
1332.87	94.0061
1336.06	90.8329
1339.24	87.132
1342.42	85.1875
1345.6	80.8306
1348.78	78.9611
1351.96	76.0571
1355.13	74.0467
1358.31	71.8942
1361.48	71.7537
1364.65	68.0585
1367.82	66.2945
1370.99	63.8129
1374.16	63.9914
1377.33	62.8156
1380.5	62.3841
1383.66	62.9532
1386.83	62.3693
1389.99	62.9524
1393.15	61.6412
1396.31	60.1702
1399.47	57.8085
1402.63	57.2266
1405.78	57.4055
1408.94	57.2472
1412.1	57.7475
1415.25	59.6186
1418.4	63.0799
1421.55	65.1812
1424.7	69.7858
1427.85	76.9999
1431	82.3293
1434.14	86.7771
1437.29	92.288
1440.43	95.5055
1443.57	98.7931
1446.71	101.925
1449.85	103.352
1452.99	104.415
1456.13	101.924
1459.26	98.3438
1462.4	94.1542
1465.54	90.1392
1468.67	83.7217
1471.8	76.8004
1474.93	69.1589
1478.06	61.7751
1481.19	55.4192
1484.31	48.7892
1487.44	43.4053
1490.56	38.8038
1493.69	36.4579
1496.81	33.3839
1499.93	30.3008
1503.05	30.3758
1506.17	29.2276
1509.28	28.7197
1512.4	28.9896
1515.52	30.1708
1518.63	32.6171
1521.74	36.9021
1524.85	40.9177
1527.96	43.39
1531.07	46.1945
1534.18	48.5684
1537.29	51.8891
1540.39	55.8909
1543.5	59.2363
1546.6	62.3122
1549.7	66.0178
1552.8	69.9799
1555.9	75.4567
1559	80.7542
1562.1	84.6762
1565.19	88.0925
1568.29	93.6916
1571.38	96.6403
1574.47	99.8252
1577.56	104.783
1580.66	107.197
1583.74	110.206
1586.83	113.29
1589.92	114.542
1593.01	115.287
1596.09	115.321
1599.17	115.127
1602.25	113.419
1605.34	110.496
1608.41	107.679
1611.49	103.391
1614.57	99.6698
1617.65	96.0407
1620.72	93.0417
1623.79	92.2693
1626.87	91.1971
1629.94	92.143
1633.01	91.6018
1636.08	89.4705
1639.15	89.4161
1642.21	90.7917
1645.28	91.6722
1648.34	93.1746
1651.41	94.7783
1654.47	94.9285
1657.53	94.8831
1660.59	93.1348
1663.65	90.8263
1666.71	86.5477
1669.76	83.9261
1672.82	80.8987
1675.87	76.0729
1678.93	71.7691
1681.98	66.2737
1685.03	59.5454
1688.08	53.4957
1691.13	47.4453
1694.17	40.7065
1697.22	36.3757
1700.27	31.8974
1703.31	28.3795
1706.35	24.0036
1709.39	20.9186
1712.43	18.6814
1715.47	16.6493
1718.51	15.1157
1721.55	14.1385
1724.58	13.3906
1727.62	11.9146
1730.65	10.6991
1733.68	9.48008
1736.72	7.65399
1739.74	7.39617
1742.77	6.62134
1745.8	6.97818
1748.83	5.86498
1751.85	5.10737
1754.88	4.31863
1757.9	2.45173
1760.92	1.76852
1763.95	1.38814
1766.96	0.291558
1769.98	0.838345
1773	1.3112
1776.02	1.74916
1779.03	1.98255
1782.05	1.65841
1785.06	2.45373
1788.07	2.43031
1791.08	2.74514
1794.09	3.04383
1797.1	2.90739
1800.11	4.17116
1803.12	3.68996
1806.12	4.14377
1809.12	4.14506
1812.13	4.38167
1815.13	4.82769
1818.13	4.55421
1821.13	5.06381
1824.13	4.46405
1827.13	5.01161
1830.12	5.14591
1833.12	5.19942
1836.11	5.63493
1839.1	6.14899
1842.09	6.85631
1845.09	7.05891
1848.08	6.2164
1851.06	5.15936
1854.05	3.94463
1857.04	3.90378
1860.02	3.23957
1863.01	1.6504
1865.99	1.79735
1868.97	2.64957
1871.95	2.22622
1874.93	2.33389
1877.91	1.98344
1880.89	2.40062
1882.46	1.75088
1885.45	1.83666
1888.43	2.02727
1891.42	2.27099
1894.41	2.84777
1897.39	2.70055
1900.37	3.22202
1903.36	4.20592
1906.34	4.85928
1909.32	4.9473
1912.29	4.42909
1915.27	5.36389
1918.25	4.1849
1921.23	4.61618
1924.2	5.32692
1927.17	5.84454
1930.15	6.60921
1933.12	5.79962
1936.09	6.29106
1939.06	7.76592
1942.02	8.97652
1944.99	8.89551
1947.96	9.27602
1950.92	9.71953
1953.88	9.38546
1956.85	9.91479
1959.81	9.56072
1962.77	9.48743
1965.73	8.82475
1968.69	9.48996
1971.64	8.93091
1974.6	9.28087
1977.55	8.67424
1980.51	7.65262
1983.46	7.29358
1986.41	7.10394
1989.36	6.84921
1992.31	6.3467
1995.26	6.0572
1998.21	4.53027
2001.15	4.2571
2004.1	3.13959
2007.04	3.91297
2009.99	3.19927
2012.93	3.21841
2015.87	3.58164
2018.81	4.00573
2021.75	4.02341
2024.68	4.46791
2027.62	3.74716
2030.56	4.42398
2033.49	4.36851
2036.42	3.48173
2039.36	4.91557
2042.29	5.5216
2045.22	5.28683
2048.14	5.7734
2051.07	6.59513
2054	7.75241
2056.93	7.72598
2059.85	7.9818
2062.77	7.8562
2065.7	8.70974
2068.62	9.55288
2071.54	10.141
2074.46	10.8559
2077.38	11.1583
2080.29	11.2346
2083.21	9.80802
2086.12	10.7915
2089.04	11.8467
2091.95	12.0582
2094.86	11.9745
2097.77	12.856
2100.68	11.6783
2103.59	10.9886
2106.5	10.7713
2109.41	11.2498
2112.31	11.8546
2115.21	12.8445
2118.12	13.9064
2121.02	15.4551
2123.92	17.538
2126.82	19.0088
2129.72	20.6331
2132.62	24.1129
2135.51	26.9728
2138.41	30.0999
2141.31	32.1944
2144.2	34.9103
2147.09	37.8585
2149.98	39.4206
2152.87	40.4143
2155.76	41.8301
2158.65	43.9341
2161.54	45.763
2164.43	46.5492
2167.31	46.8182
2170.2	47.0282
2173.08	46.4238
2175.96	47.6415
2178.84	47.7821
2181.72	46.8171
2184.6	45.4533
2187.48	44.1233
2190.36	42.5855
2193.23	42.17
2196.11	41.4441
2198.98	39.1675
2201.85	37.7854
2204.72	36.2263
2207.59	35.0892
2210.46	33.0124
2213.33	30.7989
2216.2	28.9503
2219.07	25.9407
2221.93	22.6831
2224.8	20.1764
2227.66	18.0046
2230.52	15.3997
2233.39	14.6307
2236.25	13.3868
2239.1	12.9161
2241.96	11.7792
2244.82	11.231
2247.68	10.4163
2250.53	9.18022
2253.38	7.71695
2256.24	7.21821
2259.09	7.40478
2261.94	6.7916
2264.79	7.60714
2267.64	6.42547
2270.49	5.9593
2273.33	5.12816
2276.18	4.24273
2279.02	4.5475
2281.87	4.15183
2284.71	4.50712
2287.55	4.33132
2290.39	3.97409
2293.23	4.08391
2296.07	4.88896
2298.91	6.18102
2301.74	7.85516
2304.58	9.5364
2307.41	10.0769
2310.25	10.8964
2313.08	11.1485
2315.91	11.7693
2318.74	12.1446
2321.57	11.1264
2324.4	10.9199
2327.23	10.6957
2330.05	9.34135
2332.88	8.46066
2335.7	6.65869
2338.52	5.00432
2341.35	3.41094
2344.17	1.66833
2346.99	1.38624
2349.81	1.45967
2352.62	0.839551
2355.44	0.657056
2358.26	-0.581294
2361.07	-0.493861
2363.89	-0.100867
2366.7	0.796847
2369.51	1.75693
2372.32	1.86273
2375.13	2.0099
2377.94	2.29975
2380.75	2.56745
2383.56	3.62136
2386.36	3.06758
2389.17	3.10712
2391.97	2.15508
2394.77	2.1261
2397.58	1.12724
2400.38	0.970686
2403.18	0.598633
2405.97	0.362428
2408.77	0.131766
2411.57	1.36316
2414.37	1.68083
2417.16	2.19225
2419.95	2.7982
2422.75	3.63744
2425.54	3.8063
2428.33	5.07134
2431.12	5.21902
2433.91	6.07864
2436.7	6.76543
2439.48	6.33091
2442.27	5.25785
2445.05	6.11932
2447.84	5.89464
2450.62	5.79041
2453.4	5.87969
2456.18	5.11744
2458.96	4.13394
2461.74	3.90759
2464.52	3.11339
2467.29	3.27272
2470.07	3.54465
2472.85	4.0298
2475.62	3.4944
2478.39	4.11883
2481.16	4.03041
2483.93	4.51795
2486.7	4.9324
2489.47	5.92731
2492.24	5.71793
2495.01	5.17124
2497.77	4.72339
2500.54	4.18728
2503.3	3.99041
2506.06	2.85072
2508.83	2.47881
2511.59	2.49478
2514.35	2.02951
2517.11	1.67099
2519.86	1.55781
2522.62	2.67507
2525.38	1.82604
2528.13	2.77854
2530.89	2.8224
2533.64	3.37342
2536.39	3.28315
2539.14	3.10559
2541.89	3.82925
2544.64	5.11651
2547.39	5.39426
2550.14	5.17055
2552.88	5.98123
2555.63	7.02354
2558.37	8.21561
2561.11	7.63154
2563.86	8.08745
2566.6	8.53403
2569.34	8.42924
2572.08	7.66546
2574.82	7.05063
2577.55	7.32995
2580.29	6.23701
2583.02	5.76297
2585.76	5.99387
2588.49	5.55868
2591.22	4.86923
2593.96	3.69918
2596.69	2.58986
2599.42	2.0254
2602.14	1.19991
2604.87	1.56708
2607.6	1.94472
2610.32	2.34899
2613.05	2.24974
2615.77	2.71953
2618.49	3.02361
2621.22	4.93365
2623.94	5.14736
2626.66	5.4977
2629.37	5.76321
2632.09	6.47646
2634.81	6.36813
2637.53	5.42024
2640.24	5.65398
2642.96	5.81512
2645.67	5.21664
2648.38	4.33738
2651.09	4.43736
2653.8	4.68394
2656.51	4.53276
2659.22	4.29871
2661.93	4.56732
2664.63	5.49764
2667.34	5.2872
2670.04	6.22947
2672.75	7.09332
2675.45	7.15604
2678.15	8.14535
2680.85	8.60198
2683.55	8.04812
2686.25	8.71947
2688.94	8.61994
2691.64	9.21231
2694.34	9.37429
2697.03	10.4874
2699.73	10.9774
2702.42	9.88684
2705.11	11.8368
2707.8	11.8372
2710.49	11.7733
2713.18	11.7077
2715.87	12.0895
2718.55	12.5909
2721.24	12.5535
2723.93	12.6315
2726.61	12.509
2729.29	12.4575
2731.98	11.4491
2734.66	10.4918
2737.34	10.6678
2740.02	9.83704
2742.7	9.21481
2745.37	9.80275
2748.05	8.49273
2750.72	8.5011
2753.4	8.58905
2756.07	8.57652
2758.75	10.137
2761.42	9.84737
2764.09	10.1112
2766.76	10.412
2769.43	10.0987
2772.1	9.12299
2774.76	7.78261
2777.43	6.58615
2780.1	7.09692
2782.76	6.75404
2785.42	5.76851
2788.09	4.12821
2790.75	2.06696
2793.41	1.86069
2796.07	1.3266
2798.73	1.25216
2801.39	1.06196
2804.04	1.09226
2806.7	1.09998
2809.35	0.831621
2812.01	0.92253
2814.66	0.94941
2817.31	2.1647
2819.96	3.15986
2822.61	4.94136
2825.26	8.19632
2827.91	10.1948
2830.56	13.567
2833.21	16.9874
2835.85	20.3338
2838.5	25.4997
2841.14	30.5849
2843.78	38.03
2846.42	47.1703
2849.06	55.5434
2851.71	63.895
2854.34	73.26
2856.98	82.5592
2859.62	92.1743
2862.26	100.708
2864.89	108.724
2867.53	115.413
2870.16	121.362
2872.79	126.791
2875.42	131.087
2878.05	135.695
2880.68	139.521
2883.31	143.795
2885.94	147.117
2888.57	151.469
2891.19	156.369
2893.82	160.683
2896.44	165.744
2899.07	172.442
2901.69	181.812
2904.31	192.277
2906.93	203.524
2909.55	216.225
2912.17	228.558
2914.79	240.845
2917.41	252.812
2920.02	261.764
2922.64	268.989
2925.25	274.634
2927.86	278.29
2930.48	279.634
2933.09	278.49
2935.7	276.234
2938.31	272.733
2940.92	266.043
2943.53	258.207
2946.13	248.88
2948.74	238.675
2951.34	228.842
2953.95	218.457
2956.55	207.735
2959.15	198.324
2961.75	188.994
2964.35	180.915
2966.95	173.085
2969.55	164.678
2972.15	157.151
2974.75	148.362
2977.34	140.591
2979.94	130.922
2982.53	120.813
2985.13	109.822
2987.72	99.0676
2990.31	88.8979
2992.9	79.2626
2995.49	70.1643
2998.08	61.3999
3000.67	53.7494
3003.25	44.5689
3005.84	36.5571
3008.42	29.7888
3011.01	24.4389
3013.59	19.804
3016.17	16.4831
3018.76	13.9658
3021.34	12.7732
3023.92	12.1763
3026.49	11.9315
3029.07	11.7253
3031.65	11.8163
3034.23	12.4481
3036.8	13.5008
3039.38	15.1858
3041.95	16.5454
3044.52	17.0799
3047.09	18.3426
3049.66	19.6092
3052.23	19.9172
3054.8	20.1601
3057.37	20.0367
3059.94	19.5938
3062.5	18.1395
3065.07	17.2418
3067.63	14.8924
3070.2	13.4937
3072.76	11.6394
3075.32	9.92226
3077.88	8.15564
3080.44	6.02621
3083	4.60606
3085.56	2.92038
3088.12	1.72907
3090.67	0.125539
3093.23	-1.26974
3095.78	-1.72456
3098.34	-0.947104
3100.89	-0.110386
3103.44	0.172379
3105.99	0.477775
3108.54	1.26539
3111.09	1.93429
3113.64	2.26395
3116.19	3.37054
3118.74	4.07276
3121.28	5.23309
3123.83	6.61835
3126.37	8.48213
3128.91	10.4917
3131.46	12.0284
3134	13.71
3136.54	16.1651
3139.08	18.7992
3141.62	22.1027
3144.16	25.1551
3146.69	28.1993
3149.23	32.2512