File: data/Raman/poly_smoothed/Thy_40_11_37_1x_45s_532 nm_x100_100%_600 gr_mm_01.txt
#Acq. time (s)=	45
#Accumulations=	2
#Range (cm-¹)=	200...3150
#Windows=	2
#Auto scanning=	Off
#Autofocus=	Off
#Macrospot=	Off
#AutoExposure=	Off
#Spike filter=	Multiple accum.
#Delay time (s)=	0
#Binning=	1
#Readout mode=	Signal
#DeNoise=	Off
#ICS correction=	On
#Dark correction=	Off
#Inst. Process=	Off
#Detector Gain=	Best Dynamic Range
#Detector ADC=	20 kHz
#Detector temperature (°C)=	-69.85
#Instrument=	LabRAM HR Evol
#Detector=	Synapse
#Objective=	x100
#Grating=	600 gr/mm
#ND Filter=	100%
#Laser (nm)=	532
#Hole=	100.021
#Range=	Auto
#Laser Pol.=	No
#Raman. Pol.=	No
#Laser Pol. (°)=	-0.0007625
#Raman Pol. (°)=	89.9995
#Collection=	Microscope
#StageXY=	Marzhauser
#StageZ=	Marzhauser
#X (µm)=	231.2
#Y (µm)=	1688.1
#Z (µm)=	427.55
#Full time(mm:ss)=	3:18
#Project=
#Sample=
#Site=
#Title=	Thy_40_11_37_2x_45s_532 nm_x100_100%_600 gr_mm
#Remark=
#Date=	05.07.2022 12:38
#Acquired=	05.07.2022 12:38:37
#Base:Fit=	10.08.2022 10:01:35
#Base:Sub=	10.08.2022 10:01:52
#Filter:Polynom=	16.08.2022 10:21:53
#AxisType[0]=Intens
#AxisUnit[0]=Cnt
#AxisType[1]=Spectr
#AxisUnit[1]=1/cm
200.43	23.6476
204.059	22.4542
207.688	20.7767
211.314	18.4056
214.941	15.5649
218.564	13.6366
222.186	10.6266
225.809	8.94753
229.428	6.96914
233.045	6.34696
236.663	5.94503
240.278	6.07195
243.891	6.17284
247.503	5.21106
251.116	5.0688
254.725	5.15071
258.333	5.1788
261.939	4.45867
265.544	5.10113
269.148	5.95892
272.75	4.88444
276.351	5.21917
279.95	5.54633
283.548	6.34862
287.144	6.01151
290.739	5.08062
294.333	5.34753
297.925	5.29855
301.514	5.18601
305.104	5.56057
308.692	5.0729
312.279	4.85742
315.862	4.98096
319.446	4.80345
323.029	5.96001
326.608	6.27822
330.188	7.56843
333.766	6.13306
337.341	6.67813
340.917	6.5572
344.489	5.88908
348.062	5.7271
351.631	5.07974
355.201	5.00662
358.768	3.5125
362.333	2.61925
365.899	2.46403
369.462	1.60669
373.023	2.38821
376.585	2.09299
380.143	3.34984
383.7	4.61074
387.256	4.75872
390.812	3.68623
394.365	3.68393
397.916	4.51538
401.467	4.82339
405.015	6.40683
408.563	6.58758
412.109	8.23479
415.654	9.98019
419.197	10.0376
422.739	9.72777
426.279	9.74534
429.819	9.73252
433.356	9.86082
436.891	9.69859
440.426	9.02603
443.96	8.06148
447.492	6.93455
451.021	7.46888
454.551	8.01742
458.079	9.37073
461.604	10.9008
465.13	12.7576
468.654	12.5449
472.175	12.8278
475.696	13.263
479.215	15.0069
482.733	16.7229
486.249	17.9661
489.765	18.2028
493.278	19.2314
496.789	20.3616
500.301	20.9623
503.81	19.6549
507.317	19.968
510.825	20.7956
514.33	21.2878
517.833	21.1022
521.335	21.0908
524.836	20.4997
528.335	19.2097
531.835	18.6725
535.332	18.4713
538.827	18.7778
542.321	18.9694
545.814	16.4483
549.305	16.5207
552.795	14.3162
556.282	11.8317
559.769	11.1663
563.255	10.4422
566.739	9.66783
570.223	7.4074
573.705	5.343
577.183	4.45273
580.663	3.23632
584.141	2.89061
587.615	3.19609
591.09	4.10313
594.564	5.70538
598.035	6.62862
601.506	8.30352
604.974	9.65465
608.443	10.8116
611.908	12.5527
615.374	14.073
618.837	14.5792
622.3	15.2718
625.761	15.3318
629.219	15.535
632.677	15.7984
636.135	15.6874
639.59	15.4773
643.043	16.2939
646.495	17.7173
649.948	18.1825
653.398	17.9762
656.846	19.0114
660.293	19.3401
663.738	19.7937
667.183	20.6201
670.626	22.714
674.067	23.5604
677.508	25.4987
680.947	27.347
684.385	29.217
687.821	32.0447
691.254	34.3791
694.688	34.6783
698.121	36.8352
701.552	38.1439
704.98	38.8384
708.409	40.0961
711.836	42.3624
715.26	44.9327
718.685	45.81
722.108	47.339
725.528	49.9384
728.949	49.7876
732.367	51.0638
735.785	54.6402
739.2	57.7905
742.614	59.8659
746.028	62.4877
749.439	65.06
752.849	69.0691
756.26	72.3534
759.667	76.3536
763.073	78.3757
766.477	81.6453
769.883	85.0727
773.285	87.304
776.686	88.6667
780.085	89.9002
783.484	91.8795
786.881	92.4963
790.276	93.3971
793.671	94.8367
797.064	93.8687
800.456	91.7252
803.846	89.1552
807.234	89.0685
810.622	87.1821
814.008	85.8333
817.394	86.4314
820.778	86.0586
824.159	86.1863
827.541	85.4942
830.921	85.521
834.298	85.3141
837.676	85.9486
841.051	85.6593
844.426	84.4235
847.798	81.8759
851.171	80.7677
854.54	78.705
857.911	76.4214
861.278	73.6875
864.645	71.1173
868.01	68.5695
871.373	67.5362
874.735	64.4907
878.097	61.8843
881.457	59.6188
884.815	57.9993
888.172	56.9022
891.528	56.2272
894.882	53.5504
898.237	52.4293
901.589	51.3831
904.94	50.3874
908.289	49.4795
911.635	49.4058
914.982	49.62
918.328	49.9426
921.672	49.7919
925.015	47.8285
928.357	46.5775
931.698	45.5328
935.035	44.0046
938.373	43.4018
941.71	42.6539
945.044	41.8884
948.378	41.177
951.709	41.8447
955.041	41.1909
958.372	40.727
961.699	40.0055
965.027	40.4683
968.352	40.9214
971.676	40.2365
975	41.5671
978.322	40.9101
981.642	39.5925
984.962	39.1337
988.28	39.973
991.596	41.2497
994.911	41.5637
998.227	41.1503
1001.54	40.4111
1004.85	38.4092
1008.16	38.2551
1011.47	36.952
1014.78	35.952
1018.08	36.6625
1021.39	34.4898
1024.69	32.7811
1028	31.0117
1031.3	31.8508
1034.6	32.11
1037.9	32.8598
1041.19	31.4803
1044.49	31.5292
1047.78	31.5807
1051.08	30.3287
1054.37	29.3524
1057.66	27.8449
1060.95	26.6831
1064.24	27.7466
1067.53	27.7063
1070.81	26.8185
1074.1	25.0081
1077.38	23.2134
1080.66	21.5909
1083.94	19.7584
1087.22	18.9614
1090.5	17.4243
1093.78	16.6128
1097.05	15.1923
1100.33	14.1474
1103.6	13.9109
1106.87	13.2743
1110.14	13.6657
1113.41	13.5478
1116.68	12.9505
1119.95	11.1146
1123.21	8.33859
1126.48	7.23847
1129.74	5.02984
1133	4.89134
1136.26	4.0174
1139.52	4.40555
1142.78	4.80622
1146.04	4.28582
1149.29	2.55345
1152.55	2.21352
1155.8	2.05985
1159.05	1.56909
1162.3	2.71726
1165.55	3.04571
1168.8	2.72719
1172.05	3.8073
1175.29	3.47158
1178.54	4.36157
1181.78	4.86235
1185.02	5.46685
1188.26	6.5028
1191.5	6.80665
1194.74	7.08871
1197.97	7.33329
1201.21	8.55872
1204.44	12.4751
1207.68	13.9706
1210.91	16.6763
1214.14	17.8814
1217.37	18.5034
1220.59	20.4538
1223.82	22.6773
1227.05	24.4262
1230.27	26.161
1233.49	28.882
1236.72	31.248
1239.94	33.8606
1243.16	35.387
1246.37	35.3871
1249.59	36.9927
1252.8	38.2191
1256.02	39.0323
1259.23	40.1292
1262.44	41.5312
1265.66	42.1056
1268.86	44.171
1272.07	45.2751
1275.28	47.2395
1278.48	49.3186
1281.69	52.8856
1284.89	53.5078
1288.09	53.0953
1291.29	53.5416
1294.49	54.8339
1297.69	55.3828
1300.89	56.6024
1304.08	57.5345
1307.28	58.2554
1310.47	59.4945
1313.66	60.169
1316.85	58.1729
1320.04	56.8667
1323.23	56.0077
1326.42	53.645
1329.61	51.9386
1332.79	49.4799
1335.97	48.1023
1339.16	46.3825
1342.34	44.6852
1345.52	42.1078
1348.7	40.4132
1351.87	38.2566
1355.05	36.0591
1358.22	35.3317
1361.4	32.8959
1364.57	30.322
1367.74	28.2856
1370.91	27.9425
1374.08	26.3779
1377.25	25.6112
1380.41	23.9292
1383.58	22.7135
1386.74	21.5689
1389.91	20.4664
1393.07	18.7627
1396.23	17.6905
1399.39	16.8011
1402.55	16.3554
1405.7	15.0443
1408.86	16.7033
1412.01	17.653
1415.17	18.0706
1418.32	21.8188
1421.47	24.5819
1424.62	27.4392
1427.77	31.0188
1430.91	34.618
1434.06	39.8224
1437.2	43.3243
1440.35	46.4806
1443.49	49.2781
1446.63	52.5648
1449.77	53.8706
1452.91	54.071
1456.05	53.6669
1459.18	51.7009
1462.32	49.9345
1465.45	47.4964
1468.59	43.1372
1471.72	38.0275
1474.85	32.8679
1477.98	27.3714
1481.1	21.9343
1484.23	17.5331
1487.36	14.1591
1490.48	10.094
1493.61	8.34826
1496.73	5.61452
1499.85	2.37379
1502.97	3.05153
1506.09	2.93468
1509.2	4.01016
1512.32	4.51245
1515.43	5.18216
1518.55	7.43995
1521.66	9.79217
1524.77	11.8846
1527.88	13.983
1530.99	14.0938
1534.1	15.2011
1537.21	15.019
1540.31	16.1075
1543.42	18.2755
1546.52	19.8122
1549.62	22.2387
1552.72	23.5021
1555.82	24.0352
1558.92	25.8034
1562.02	28.6608
1565.11	31.317
1568.21	32.7305
1571.3	34.7663
1574.39	35.403
1577.49	38.5409
1580.57	41.689
1583.66	44.1202
1586.75	45.5788
1589.84	47.8199
1592.92	49.6175
1596.01	50.442
1599.09	49.4906
1602.17	48.363
1605.25	46.6191
1608.33	45.0825
1611.41	44.0612
1614.49	45.0286
1617.57	46.2915
1620.64	47.2109
1623.72	47.4684
1626.79	48.6176
1629.86	49.8571
1632.93	51.1612
1636	52.7712
1639.07	53.5315
1642.13	56.3546
1645.2	57.8266
1648.26	59.8233
1651.33	62.0187
1654.39	64.4789
1657.45	65.679
1660.51	65.9282
1663.57	64.9132
1666.63	63.2685
1669.68	60.8183
1672.74	58.9836
1675.79	55.5073
1678.85	53.3529
1681.9	48.1539
1684.95	45.2814
1688	42.6387
1691.05	38.5126
1694.09	34.447
1697.14	32.3017
1700.18	30.0559
1703.23	26.6015
1706.27	23.8068
1709.31	20.2864
1712.35	18.8225
1715.39	17.6136
1718.43	16.6124
1721.47	15.6849
1724.5	15.3433
1727.54	13.976
1730.57	13.1058
1733.61	12.836
1736.64	10.6032
1739.67	10.6118
1742.7	10.1771
1745.72	8.63794
1748.75	8.3969
1751.77	7.89286
1754.8	6.65125
1757.82	5.45902
1760.84	6.12604
1763.87	3.67983
1766.89	2.52622
1769.91	2.83548
1772.92	2.51603
1775.94	1.81187
1778.95	1.5086
1781.97	1.61343
1784.98	1.12328
1787.99	1.88129
1791.01	2.62775
1794.01	2.14044
1797.02	2.10827
1800.03	2.27558
1803.04	2.18141
1806.04	2.76037
1809.05	2.44049
1812.05	1.91596
1815.05	1.94685
1818.05	1.84881
1821.05	2.29891
1824.05	3.28423
1827.05	2.97134
1830.04	2.24677
1833.04	2.62986
1836.03	2.74155
1839.03	1.86372
1842.02	1.12708
1845.01	1.24856
1848	1.13734
1850.99	0.475298
1853.97	0.211368
1856.96	-0.0678386
1859.94	-0.0164896
1862.93	0.176471
1865.91	0.705045
1868.89	0.36426
1871.87	1.18167
1874.85	1.23222
1877.83	2.15796
1880.81	1.79007
1882.57	1.47295
1885.56	1.24303
1888.55	2.03721
1891.54	3.51986
1894.52	3.96361
1897.51	5.00069
1900.49	4.59877
1903.47	4.77667
1906.45	4.93535
1909.43	4.93899
1912.41	4.48886
1915.39	4.32642
1918.37	4.452
1921.34	3.6431
1924.32	4.16897
1927.29	4.19837
1930.26	4.7196
1933.23	4.13082
1936.2	5.22209
1939.17	4.4461
1942.14	4.60255
1945.11	4.67273
1948.07	3.41928
1951.04	2.96282
1954	2.67337
1956.96	2.2319
1959.93	1.71415
1962.89	2.74838
1965.85	2.541
1968.8	1.75755
1971.76	2.20542
1974.72	2.40617
1977.67	1.11262
1980.63	1.9462
1983.58	1.82113
1986.53	0.913663
1989.48	2.21335
1992.43	2.41949
1995.38	2.70406
1998.32	3.88747
2001.27	4.06494
2004.22	5.0617
2007.16	6.3598
2010.1	6.80518
2013.04	6.67531
2015.98	7.20617
2018.92	6.29636
2021.86	6.40907
2024.8	7.23116
2027.74	7.49232
2030.67	7.64217
2033.61	8.58451
2036.54	8.19016
2039.47	7.76127
2042.4	7.71424
2045.33	7.84344
2048.26	7.27034
2051.19	5.97564
2054.12	6.64125
2057.04	7.45092
2059.97	6.76206
2062.89	7.20223
2065.81	7.08304
2068.73	7.52628
2071.65	9.48657
2074.57	10.1528
2077.49	11.6854
2080.41	11.4001
2083.32	11.9329
2086.24	12.7034
2089.15	13.9587
2092.07	14.2695
2094.98	16.2424
2097.89	17.881
2100.8	19.5115
2103.71	20.8055
2106.61	21.9062
2109.52	22.8541
2112.43	25.2065
2115.33	26.9163
2118.23	28.5178
2121.13	30.4339
2124.04	31.8393
2126.94	34.206
2129.83	35.7425
2132.73	38.0146
2135.63	40.4275
2138.53	43.7554
2141.42	46.5427
2144.31	49.3188
2147.21	51.3877
2150.1	53.4779
2152.99	56.1111
2155.88	59.0663
2158.77	60.5321
2161.65	62.6182
2164.54	63.8778
2167.43	65.4831
2170.31	66.1598
2173.19	66.6274
2176.07	67.0368
2178.96	66.7059
2181.84	66.0956
2184.72	65.6229
2187.59	62.45
2190.47	60.0274
2193.35	57.4544
2196.22	54.8514
2199.09	51.1913
2201.97	47.6778
2204.84	44.9873
2207.71	41.9101
2210.58	39.4002
2213.45	36.5647
2216.31	34.0682
2219.18	32.103
2222.05	31.1057
2224.91	30.1257
2227.78	27.8625
2230.64	25.4661
2233.5	24.324
2236.36	23.2748
2239.22	22.4346
2242.08	22.5277
2244.93	22.0092
2247.79	21.5835
2250.64	21.2542
2253.5	20.9079
2256.35	19.8468
2259.2	18.3849
2262.05	16.8711
2264.9	16.3558
2267.75	14.5936
2270.6	13.5802
2273.45	13.181
2276.29	12.392
2279.14	11.8785
2281.98	11.9109
2284.82	11.5896
2287.66	10.5543
2290.5	9.18997
2293.34	7.61567
2296.18	6.22274
2299.02	6.29068
2301.86	6.54084
2304.69	7.45855
2307.53	7.59946
2310.36	8.07316
2313.19	8.31179
2316.02	8.13168
2318.85	8.36005
2321.68	8.1495
2324.51	8.58951
2327.34	7.72594
2330.16	7.49925
2332.99	7.4451
2335.81	7.79309
2338.64	8.1936
2341.46	8.88184
2344.28	9.00155
2347.1	8.28065
2349.92	8.08095
2352.74	7.39602
2355.55	6.74351
2358.37	6.02865
2361.19	5.00062
2364	5.45462
2366.81	6.56196
2369.62	7.02622
2372.44	5.64595
2375.24	4.45505
2378.05	3.96123
2380.86	3.80193
2383.67	2.73721
2386.47	2.07147
2389.28	1.91426
2392.08	1.55375
2394.89	1.28149
2397.69	-0.221901
2400.49	-0.324941
2403.29	0.331015
2406.09	1.45374
2408.88	2.19556
2411.68	1.90056
2414.48	2.61773
2417.27	3.37694
2420.06	3.76478
2422.86	3.75207
2425.65	4.84859
2428.44	5.58876
2431.23	6.06994
2434.02	7.10446
2436.81	6.52709
2439.59	6.8327
2442.38	7.33047
2445.16	7.22183
2447.95	7.17558
2450.73	6.88383
2453.51	6.38335
2456.29	5.69029
2459.07	5.28946
2461.85	5.33109
2464.63	5.18152
2467.4	4.41996
2470.18	4.88249
2472.95	4.40247
2475.73	4.03478
2478.5	2.72225
2481.27	2.36862
2484.04	1.96866
2486.81	0.0401604
2489.58	0.0323643
2492.35	0.419309
2495.12	0.428107
2497.88	0.513237
2500.65	0.412947
2503.41	0.820789
2506.17	1.85088
2508.94	2.58564
2511.7	2.96829
2514.46	2.9235
2517.22	3.2565
2519.97	3.35367
2522.73	3.71534
2525.49	4.25184
2528.24	5.00255
2530.99	5.53964
2533.75	5.50103
2536.5	5.2973
2539.25	6.2469
2542	5.22843
2544.75	4.78163
2547.5	5.46978
2550.24	5.33339
2552.99	4.6453
2555.74	4.42006
2558.48	4.8003
2561.22	4.89219
2563.96	5.39714
2566.71	5.22641
2569.45	5.17094
2572.18	4.57582
2574.92	4.05999
2577.66	3.60861
2580.4	3.20087
2583.13	2.71896
2585.87	2.9451
2588.6	2.48036
2591.33	2.91868
2594.06	3.37397
2596.79	3.9956
2599.52	3.36521
2602.25	3.31524
2604.98	3.74529
2607.71	3.917
2610.43	3.73646
2613.16	4.27713
2615.88	4.62421
2618.6	4.77924
2621.32	5.08905
2624.04	4.59863
2626.76	4.82225
2629.48	4.83509
2632.2	4.18063
2634.92	4.15099
2637.63	4.78081
2640.35	4.50609
2643.06	4.27052
2645.77	4.44632
2648.49	4.35711
2651.2	4.80256
2653.91	5.18454
2656.62	4.98434
2659.33	4.7132
2662.03	4.42134
2664.74	3.94362
2667.44	3.62071
2670.15	4.03665
2672.85	4.1489
2675.55	4.69794
2678.26	4.07882
2680.96	4.55371
2683.66	4.42641
2686.35	4.69494
2689.05	4.77341
2691.75	5.36127
2694.44	6.42547
2697.14	6.97655
2699.83	7.409
2702.52	8.63612
2705.22	8.7363
2707.91	8.20163
2710.6	8.26235
2713.29	8.3749
2715.97	8.49529
2718.66	8.90519
2721.35	8.44423
2724.03	8.73956
2726.72	8.52992
2729.4	7.60327
2732.08	7.60237
2734.76	7.16207
2737.44	6.72799
2740.12	6.41188
2742.8	6.2827
2745.48	5.70242
2748.16	5.60856
2750.83	4.72667
2753.51	4.66443
2756.18	4.2122
2758.85	4.03815
2761.53	3.88196
2764.2	4.05697
2766.87	5.03666
2769.54	4.02299
2772.2	3.90369
2774.87	4.26855
2777.54	4.70763
2780.2	4.04991
2782.87	4.10237
2785.53	3.60078
2788.19	3.56527
2790.85	2.76827
2793.51	2.81973
2796.17	2.12662
2798.83	2.43986
2801.49	1.81866
2804.15	1.96644
2806.8	1.20692
2809.46	0.458143
2812.11	-0.000232081
2814.76	0.00426789
2817.42	-0.33255
2820.07	0.321378
2822.72	1.1346
2825.37	2.66189
2828.02	4.70939
2830.66	7.26157
2833.31	10.5519
2835.96	13.202
2838.6	15.8582
2841.24	19.1691
2843.89	22.7355
2846.53	27.5958
2849.17	32.0569
2851.81	36.8495
2854.45	41.9529
2857.09	46.7996
2859.72	52.2014
2862.36	57.8284
2865	61.9022
2867.63	66.1597
2870.26	69.7746
2872.9	72.2712
2875.53	74.7083
2878.16	77.0477
2880.79	78.5183
2883.42	80.796
2886.05	82.1855
2888.67	83.9804
2891.3	85.979
2893.92	89.6119
2896.55	92.1984
2899.17	95.5874
2901.79	98.9231
2904.42	102.785
2907.04	108.214
2909.66	114.732
2912.27	121.306
2914.89	127.635
2917.51	134.124
2920.13	140.187
2922.74	145.013
2925.35	150.096
2927.97	153.249
2930.58	155.18
2933.19	155.97
2935.8	155.445
2938.41	153.671
2941.02	151.279
2943.63	147.575
2946.24	143.128
2948.84	137.957
2951.45	131.862
2954.05	125.411
2956.65	119.789
2959.26	113.127
2961.86	106.763
2964.46	100.316
2967.06	94.6672
2969.66	88.7011
2972.25	83.8591
2974.85	79.2817
2977.45	74.4165
2980.04	69.8655
2982.64	65.7351
2985.23	60.1623
2987.82	54.2269
2990.41	49.6381
2993	44.7286
2995.59	40.1905
2998.18	36.0873
3000.77	32.4249
3003.36	27.3422
3005.94	23.4333
3008.53	19.883
3011.11	16.5311
3013.69	12.2341
3016.28	9.77322
3018.86	7.63062
3021.44	5.46366
3024.02	3.9443
3026.6	3.10188
3029.18	1.86219
3031.75	1.21664
3034.33	1.2115
3036.9	1.07256
3039.48	1.55933
3042.05	1.94012
3044.62	2.61658
3047.19	2.96047
3049.77	3.48308
3052.34	3.73103
3054.9	4.80978
3057.47	4.67825
3060.04	4.93693
3062.61	4.82052
3065.17	4.75285
3067.74	4.03553
3070.3	3.93121
3072.86	3.17929
3075.42	2.48157
3077.99	2.28665
3080.54	2.41657
3083.1	1.85395
3085.66	0.480169
3088.22	0.0731962
3090.78	0.476334
3093.33	-0.0697931
3095.89	-1.0728
3098.44	-0.614689
3100.99	-1.08747
3103.54	-1.19372
3106.1	-0.253629
3108.65	0.393603
3111.2	0.357881
3113.74	1.64858
3116.29	1.69279
3118.84	2.42609
3121.38	3.38409
3123.93	4.06161
3126.47	4.91554
3129.01	5.80676
3131.56	7.29181
3134.1	8.02247
3136.64	9.21693
3139.18	10.701
3141.72	11.9674
3144.26	12.6359
3146.79	13.6521
3149.33	14.497