File: data/Raman/poly_smoothed/Thy_50_12_23_1x_45s_532 nm_x100_100%_600 gr_mm_01.txt
#Acq. time (s)=	45
#Accumulations=	2
#Range (cm-¹)=	200...3150
#Windows=	2
#Auto scanning=	Off
#Autofocus=	Off
#Macrospot=	Off
#AutoExposure=	Off
#Spike filter=	Multiple accum.
#Delay time (s)=	0
#Binning=	1
#Readout mode=	Signal
#DeNoise=	Off
#ICS correction=	On
#Dark correction=	Off
#Inst. Process=	Off
#Detector Gain=	Best Dynamic Range
#Detector ADC=	20 kHz
#Detector temperature (°C)=	-69.85
#Instrument=	LabRAM HR Evol
#Detector=	Synapse
#Objective=	x100
#Grating=	600 gr/mm
#ND Filter=	100%
#Laser (nm)=	532
#Hole=	100.021
#Range=	Auto
#Laser Pol.=	No
#Raman. Pol.=	No
#Laser Pol. (°)=	-0.0007625
#Raman Pol. (°)=	89.9995
#Collection=	Microscope
#StageXY=	Marzhauser
#StageZ=	Marzhauser
#X (µm)=	-5101.5
#Y (µm)=	1486.2
#Z (µm)=	62.85
#Full time(mm:ss)=	3:18
#Project=
#Sample=
#Site=
#Title=	Thy_50_12_23_2x_45s_532 nm_x100_100%_600 gr_mm
#Remark=
#Date=	07.07.2022 10:54
#Acquired=	07.07.2022 10:54:41
#Base:Fit=	10.08.2022 10:04:29
#Base:Sub=	10.08.2022 10:04:45
#Filter:Polynom=	16.08.2022 10:20:24
#AxisType[0]=Intens
#AxisUnit[0]=Cnt
#AxisType[1]=Spectr
#AxisUnit[1]=1/cm
200.43	1.9558
204.061	6.45807
207.688	8.58562
211.316	10.1241
214.941	10.7479
218.566	10.818
222.188	12.5982
225.809	12.3558
229.43	11.0198
233.047	10.0943
236.663	9.10518
240.278	8.13079
243.894	7.04032
247.506	6.12245
251.116	4.12877
254.725	5.56977
258.333	4.82271
261.939	4.74925
265.546	5.65867
269.15	5.74207
272.752	4.78056
276.353	4.25605
279.952	4.51919
283.55	4.01182
287.146	3.99184
290.739	4.01792
294.333	4.94741
297.925	6.2514
301.516	7.78719
305.106	9.97719
308.694	11.9214
312.279	13.3683
315.864	13.8102
319.448	14.6633
323.029	14.4564
326.61	14.5912
330.19	14.6331
333.766	16.1961
337.343	16.5268
340.917	16.3489
344.491	16.1863
348.062	16.8829
351.633	16.6479
355.201	15.5332
358.77	14.3276
362.335	12.1621
365.899	12.3726
369.464	13.1195
373.025	12.5879
376.585	13.5211
380.143	12.3553
383.702	13.0174
387.258	13.2274
390.812	14.4571
394.365	15.0841
397.916	14.3029
401.467	14.387
405.015	14.4272
408.565	13.7296
412.111	14.2259
415.656	13.5757
419.197	14.2923
422.739	14.2215
426.279	13.9149
429.819	13.0076
433.356	13.3597
436.893	15.0887
440.428	14.5646
443.96	15.3435
447.492	16.1395
451.023	16.9524
454.553	17.6942
458.079	17.8531
461.606	18.6003
465.132	19.5151
468.654	20.5361
472.177	22.2331
475.696	23.3999
479.217	25.445
482.733	25.3411
486.251	28.1331
489.765	29.872
493.278	30.7155
496.791	30.5378
500.301	31.263
503.81	31.5892
507.319	30.4031
510.825	30.0333
514.33	28.4671
517.833	28.8441
521.337	29.3263
524.838	29.4627
528.337	28.6304
531.835	27.4347
535.332	25.308
538.827	23.0652
542.321	20.4326
545.814	20.0131
549.305	19.1273
552.795	18.4473
556.284	16.5204
559.771	15.1151
563.257	13.3721
566.742	11.1366
570.223	9.15461
573.705	7.44066
577.185	5.22807
580.665	3.54043
584.141	2.61227
587.617	1.89618
591.092	1.50776
594.564	1.19263
598.037	2.42915
601.506	2.69416
604.976	3.26925
608.443	4.45842
611.91	5.77719
615.374	6.40021
618.839	5.27231
622.3	5.43109
625.761	5.98132
629.221	7.97761
632.679	10.0141
636.135	11.1897
639.592	12.0566
643.045	12.3606
646.497	14.3649
649.948	13.9945
653.398	15.8395
656.846	17.1018
660.293	19.9567
663.738	19.1678
667.185	20.944
670.628	22.2198
674.067	24.2103
677.508	24.7945
680.947	24.2805
684.385	25.2877
687.821	26.2909
691.256	27.6761
694.69	27.8302
698.121	28.7319
701.552	28.6834
704.982	31.4591
708.41	33.0058
711.836	35.1226
715.262	37.0792
718.685	37.4475
722.108	37.4769
725.53	38.1722
728.949	40.1344
732.369	43.6499
735.785	44.0616
739.2	45.3728
742.616	47.6819
746.028	51.2039
749.441	53.6742
752.851	55.8694
756.26	57.8153
759.667	60.5058
763.075	62.1471
766.479	64.5043
769.883	66.7168
773.285	68.7652
776.686	69.4137
780.085	70.8986
783.484	73.0623
786.881	74.492
790.276	76.5042
793.671	75.3181
797.064	75.3175
800.456	74.9527
803.846	71.9669
807.236	71.9174
810.624	71.3037
814.01	70.5265
817.394	70.3385
820.778	70.1547
824.161	70.1951
827.543	70.5367
830.921	68.4238
834.3	65.1022
837.676	63.9375
841.053	62.5749
844.426	59.5527
847.8	58.5578
851.171	56.5054
854.542	53.6206
857.911	52.3897
861.279	52.975
864.645	53.3902
868.01	52.0397
871.375	50.448
874.737	49.496
878.097	49.6315
881.457	47.7981
884.817	46.5159
888.174	46.2107
891.53	45.8543
894.884	44.7347
898.237	45.1516
901.589	44.0601
904.94	43.072
908.289	39.6372
911.637	37.8459
914.984	35.9238
918.33	34.8579
921.674	34.2616
925.015	31.161
928.357	29.5819
931.698	28.2521
935.037	26.783
938.373	26.3017
941.71	25.3438
945.046	22.5957
948.378	21.4182
951.711	21.4063
955.043	22.0162
958.372	20.722
961.701	20.8623
965.027	22.3954
968.354	22.7923
971.678	22.4512
975	21.3071
978.324	21.2929
981.644	21.2168
984.962	22.4729
988.282	22.2162
991.598	21.4433
994.913	22.9463
998.227	23.8989
1001.54	23.5581
1004.85	23.7674
1008.16	23.8064
1011.47	25.7316
1014.78	25.7483
1018.08	27.5976
1021.39	27.409
1024.69	28.231
1028	30.3618
1031.3	32.4359
1034.6	34.1663
1037.9	31.9448
1041.19	32.0201
1044.49	32.0737
1047.79	31.8924
1051.08	29.5201
1054.37	28.0023
1057.66	24.9665
1060.95	23.8257
1064.24	22.0773
1067.53	20.6046
1070.81	18.815
1074.1	17.603
1077.38	14.388
1080.66	11.9197
1083.94	11.0654
1087.22	11.8437
1090.5	12.7922
1093.78	14.2082
1097.05	13.0205
1100.33	14.1616
1103.6	14.8587
1106.87	15.6396
1110.15	15.888
1113.41	14.1689
1116.68	13.1646
1119.95	12.8013
1123.21	11.8105
1126.48	11.5941
1129.74	10.093
1133	8.05918
1136.26	7.15524
1139.52	5.35425
1142.78	6.24786
1146.04	4.32599
1149.29	3.69043
1152.55	1.7764
1155.8	0.0809839
1159.05	-1.76661
1162.3	-0.316258
1165.55	0.604028
1168.8	1.40995
1172.05	2.33874
1175.29	3.38591
1178.54	3.04553
1181.78	2.91256
1185.02	3.01171
1188.26	2.95994
1191.5	3.44405
1194.74	2.37389
1197.97	3.67985
1201.21	4.70126
1204.44	5.38695
1207.68	7.23046
1210.91	9.42413
1214.14	12.5871
1217.37	15.6271
1220.6	18.8889
1223.82	21.0694
1227.05	24.2698
1230.27	28.4665
1233.49	31.5974
1236.72	35.1828
1239.94	38.1228
1243.16	42.1023
1246.37	45.3519
1249.59	48.2288
1252.8	51.7418
1256.02	53.7003
1259.23	56.7494
1262.44	60.9821
1265.66	64.0147
1268.87	68.5346
1272.07	72.6242
1275.28	74.9622
1278.48	78.1324
1281.69	80.0509
1284.89	81.9704
1288.09	84.5855
1291.3	86.1483
1294.49	86.9018
1297.69	88.1593
1300.89	89.2034
1304.09	91.6903
1307.28	91.4921
1310.47	90.8738
1313.66	90.4524
1316.86	89.5486
1320.05	86.7522
1323.23	84.6483
1326.42	83.2421
1329.61	81.5312
1332.79	80.0543
1335.98	78.7734
1339.16	78.7504
1342.34	77.4433
1345.52	75.4336
1348.7	72.8748
1351.87	69.3484
1355.05	66.8713
1358.23	63.4919
1361.4	61.2326
1364.57	58.3203
1367.74	56.6308
1370.91	54.87
1374.08	54.8409
1377.25	55.1291
1380.42	54.5837
1383.58	51.6198
1386.75	49.3978
1389.91	49.8721
1393.07	49.1368
1396.23	47.0438
1399.39	46.8114
1402.55	47.5295
1405.7	48.1258
1408.86	50.007
1412.01	52.2354
1415.17	54.3484
1418.32	58.9078
1421.47	63.0392
1424.62	68.1641
1427.77	73.4524
1430.92	79.2419
1434.06	84.5628
1437.2	88.6651
1440.35	94.2049
1443.49	99.0864
1446.63	102.433
1449.77	102.489
1452.91	102.735
1456.05	101.458
1459.18	97.2274
1462.32	93.1196
1465.45	89.4999
1468.59	84.9174
1471.72	77.5697
1474.85	70.5692
1477.98	64.5096
1481.11	57.1317
1484.23	50.9838
1487.36	44.9158
1490.48	38.6027
1493.61	34.9367
1496.73	32.712
1499.85	30.5407
1502.97	29.2382
1506.09	28.4941
1509.2	30.0007
1512.32	28.5752
1515.44	28.5897
1518.55	31.148
1521.66	32.0015
1524.77	32.8712
1527.88	34.8111
1530.99	39.3937
1534.1	43.5761
1537.21	46.518
1540.31	50.6981
1543.42	57.0215
1546.52	63.025
1549.62	68.4487
1552.72	74.6189
1555.82	80.1174
1558.92	83.7299
1562.02	87.0558
1565.11	90.8314
1568.21	94.7553
1571.3	98.7528
1574.39	101.569
1577.49	104.103
1580.58	105.436
1583.67	105.276
1586.75	105.172
1589.84	102.792
1592.93	102.145
1596.01	101.823
1599.09	101.293
1602.18	99.3215
1605.26	97.5754
1608.34	97.2355
1611.41	95.7197
1614.49	96.019
1617.57	98.9142
1620.64	100.403
1623.72	100.644
1626.79	101.211
1629.86	100.978
1632.93	102.11
1636	102.791
1639.07	105
1642.14	107.242
1645.2	107.826
1648.27	109.111
1651.33	108.592
1654.39	107.263
1657.45	106.313
1660.51	102.516
1663.57	99.5425
1666.63	95.6806
1669.69	91.6956
1672.74	87.2462
1675.79	81.6697
1678.85	74.7678
1681.9	69.1498
1684.95	62.2475
1688	57.2591
1691.05	51.0016
1694.1	42.8142
1697.14	36.7875
1700.19	31.7483
1703.23	27.413
1706.27	23.4863
1709.32	21.2511
1712.35	19.8735
1715.39	17.6574
1718.43	15.8722
1721.47	14.1162
1724.5	13.7074
1727.54	12.5966
1730.57	10.8587
1733.61	9.63265
1736.64	9.71318
1739.67	10.7521
1742.7	9.86327
1745.72	9.79904
1748.75	10.0194
1751.78	8.61337
1754.8	7.08135
1757.82	6.36882
1760.85	4.73528
1763.87	4.796
1766.89	2.9205
1769.91	1.60065
1772.92	2.83337
1775.94	2.56643
1778.96	3.33377
1781.97	3.72322
1784.98	4.29426
1788	4.78284
1791.01	4.34075
1794.01	4.16668
1797.02	4.11101
1800.03	4.01693
1803.04	3.76199
1806.04	4.6435
1809.05	5.40618
1812.05	5.41431
1815.05	4.89837
1818.05	5.19934
1821.05	4.80241
1824.05	3.85039
1827.05	2.6835
1830.04	2.93023
1833.04	2.15326
1836.03	1.34945
1839.03	1.18706
1842.02	0.64179
1845.01	0.119301
1848	0.182259
1850.99	-0.661028
1853.97	0.551153
1856.96	-0.0479694
1859.94	1.19335
1862.93	0.207817
1865.91	0.144794
1868.89	1.08915
1871.87	1.2502
1874.85	2.35485
1877.83	3.24262
1880.81	3.54137
1882.56	3.3882
1885.55	3.49461
1888.54	3.87132
1891.52	3.6809
1894.51	3.49091
1897.49	2.93831
1900.48	3.76776
1903.46	4.95172
1906.44	5.18724
1909.42	5.9624
1912.4	6.82693
1915.38	6.73053
1918.35	7.95273
1921.33	8.91633
1924.3	10.6066
1927.28	12.1241
1930.25	12.1415
1933.22	11.7038
1936.19	10.6372
1939.16	10.6776
1942.13	9.94436
1945.09	9.60886
1948.06	9.11589
1951.03	8.04847
1953.99	7.31994
1956.95	6.62018
1959.91	6.5308
1962.87	5.97021
1965.83	6.43842
1968.79	6.84745
1971.75	8.06623
1974.7	8.20999
1977.66	9.25432
1980.61	9.03182
1983.56	9.25316
1986.52	8.92414
1989.47	9.07356
1992.41	10.0101
1995.36	9.57803
1998.31	9.72228
2001.26	8.80857
2004.2	6.83127
2007.15	5.60096
2010.09	5.44457
2013.03	4.75553
2015.97	4.35217
2018.91	4.27488
2021.85	4.05539
2024.79	4.85937
2027.72	4.75459
2030.66	5.72249
2033.59	5.92692
2036.53	6.46488
2039.46	7.9719
2042.39	8.29165
2045.32	8.97709
2048.25	10.5868
2051.18	11.9936
2054.1	12.3329
2057.03	13.2262
2059.95	14.1223
2062.88	16.3168
2065.8	17.9441
2068.72	21.1003
2071.64	23.5747
2074.56	25.1379
2077.48	26.4258
2080.39	29.6914
2083.31	31.559
2086.22	34.4033
2089.14	36.9864
2092.05	39.5981
2094.96	41.9787
2097.87	44.8254
2100.78	47.4673
2103.69	50.9624
2106.6	54.7947
2109.51	58.4991
2112.41	62.0315
2115.32	65.6657
2118.22	69.4118
2121.12	72.7787
2124.02	76.3676
2126.92	80.2311
2129.82	85.2532
2132.72	90.4905
2135.62	96.2637
2138.51	101.104
2141.41	105.984
2144.3	109.299
2147.19	113.311
2150.09	116.713
2152.97	118.801
2155.86	121.675
2158.75	124.243
2161.64	126.096
2164.53	127.531
2167.41	128.358
2170.3	128.864
2173.18	128.379
2176.06	127.568
2178.94	125.427
2181.82	121.795
2184.7	118.776
2187.58	113.974
2190.46	110.703
2193.33	107.703
2196.21	104.59
2199.08	100.198
2201.95	95.7899
2204.83	91.9495
2207.7	88.1658
2210.57	82.8654
2213.43	78.1175
2216.3	73.9689
2219.17	70.0672
2222.03	66.8906
2224.9	63.1397
2227.76	59.6606
2230.62	55.1716
2233.49	52.1315
2236.34	47.3002
2239.2	43.9851
2242.06	40.7946
2244.92	38.4932
2247.78	36.2797
2250.63	35.0123
2253.48	33.4986
2256.34	32.0011
2259.19	30.4364
2262.04	29.3476
2264.89	27.5826
2267.74	26.8745
2270.59	25.2283
2273.43	23.9549
2276.28	23.3049
2279.12	22.6273
2281.97	22.1478
2284.81	22.0091
2287.65	21.6546
2290.49	20.3623
2293.33	17.6099
2296.17	16.9399
2299.01	16.9438
2301.84	15.5394
2304.68	14.6082
2307.51	13.033
2310.35	13.0076
2313.18	12.2203
2316.01	12.7362
2318.84	13.2632
2321.67	12.4624
2324.5	11.3257
2327.33	10.7851
2330.15	10.1161
2332.98	9.5111
2335.8	8.63041
2338.62	6.64445
2341.45	5.77247
2344.27	4.07682
2347.09	3.44103
2349.91	3.49003
2352.72	2.87087
2355.54	2.29857
2358.36	3.24472
2361.17	3.51595
2363.98	5.72969
2366.8	7.9115
2369.61	7.45599
2372.42	8.81605
2375.23	9.05817
2378.04	9.16033
2380.85	9.57084
2383.66	9.66445
2386.46	10.7559
2389.26	10.2758
2392.07	10.3927
2394.87	11.307
2397.67	11.3853
2400.47	10.3205
2403.27	10.3403
2406.07	8.55715
2408.87	8.50356
2411.67	8.2122
2414.46	8.13558
2417.26	7.51803
2420.05	7.37516
2422.84	7.49612
2425.64	8.6083
2428.43	9.14765
2431.22	9.04911
2434.01	9.18453
2436.79	8.95134
2439.58	8.25246
2442.37	7.04689
2445.15	6.11381
2447.93	6.23637
2450.72	6.41852
2453.5	6.23407
2456.28	5.85545
2459.06	5.20075
2461.84	5.05193
2464.62	5.13026
2467.39	5.38235
2470.17	5.71897
2472.94	6.4702
2475.72	5.29753
2478.49	5.18202
2481.26	5.00448
2484.03	4.53216
2486.8	4.0761
2489.57	4.62245
2492.34	4.47293
2495.1	4.00805
2497.87	3.07509
2500.63	1.9605
2503.4	1.63231
2506.16	1.04023
2508.92	-0.152409
2511.68	0.570883
2514.44	0.394506
2517.2	1.52822
2519.96	1.61789
2522.72	1.81392
2525.47	2.21178
2528.23	2.06958
2530.98	2.18577
2533.74	3.47346
2536.49	3.39279
2539.24	4.35029
2541.99	3.5775
2544.74	3.99981
2547.49	5.07293
2550.23	5.77456
2552.98	5.2675
2555.72	6.3548
2558.47	5.39654
2561.21	5.12186
2563.95	5.19052
2566.69	5.29284
2569.43	5.52776
2572.17	5.97991
2574.91	5.36424
2577.65	5.22716
2580.39	6.10554
2583.12	6.569
2585.85	6.5573
2588.59	5.94421
2591.32	6.00385
2594.05	4.72867
2596.78	4.17578
2599.51	4.58056
2602.24	3.62121
2604.97	3.03362
2607.69	2.41948
2610.42	1.42118
2613.14	0.491847
2615.87	0.618267
2618.59	-0.347121
2621.31	-0.795128
2624.03	-0.707874
2626.75	-0.95608
2629.47	0.71458
2632.19	1.54258
2634.91	2.99773
2637.62	4.38864
2640.34	4.84851
2643.05	5.94478
2645.76	7.07455
2648.48	7.91375
2651.19	8.23332
2653.9	8.95741
2656.6	7.86019
2659.31	8.21628
2662.02	7.95043
2664.73	7.90183
2667.43	7.05285
2670.14	5.94806
2672.84	5.1262
2675.54	5.32551
2678.24	4.66832
2680.94	4.38295
2683.64	4.36994
2686.34	4.55518
2689.04	4.94809
2691.74	5.5524
2694.43	6.49062
2697.13	7.49567
2699.82	7.34447
2702.51	8.20572
2705.21	8.17116
2707.9	8.71289
2710.58	10.254
2713.27	10.9364
2715.96	11.0059
2718.65	10.467
2721.33	11.269
2724.02	11.3966
2726.71	12.0043
2729.39	11.5875
2732.07	12.0539
2734.75	12.0662
2737.43	12.5519
2740.11	12.9019
2742.79	12.8888
2745.47	12.6955
2748.14	12.2649
2750.82	11.1973
2753.49	10.6305
2756.17	9.86545
2758.84	8.31606
2761.51	6.91249
2764.18	5.4004
2766.85	4.15857
2769.52	4.49242
2772.19	3.96562
2774.86	2.51871
2777.52	1.88092
2780.19	0.72605
2782.85	0.223689
2785.52	0.342663
2788.18	0.199715
2790.84	-0.880926
2793.5	-0.239207
2796.16	-0.429803
2798.82	0.0206188
2801.48	0.0961215
2804.13	0.426952
2806.79	0.748498
2809.45	0.644782
2812.1	0.787327
2814.75	1.14765
2817.41	2.96464
2820.06	4.35769
2822.71	8.5481
2825.36	12.599
2828	18.0689
2830.65	23.9781
2833.3	29.925
2835.94	36.4447
2838.59	43.4527
2841.23	51.4457
2843.87	59.5133
2846.52	68.8611
2849.16	78.6004
2851.8	88.453
2854.44	98.268
2857.08	108.79
2859.71	119.382
2862.35	129.051
2864.98	138.208
2867.62	145.72
2870.25	152.416
2872.88	159.218
2875.52	164.994
2878.15	170.034
2880.78	173.301
2883.41	178.6
2886.03	183.858
2888.66	188.986
2891.29	193.07
2893.91	198.945
2896.54	203.658
2899.16	209.627
2901.78	217.26
2904.4	224.898
2907.02	234.957
2909.64	246.204
2912.26	257.415
2914.88	269.811
2917.5	280.895
2920.11	291.044
2922.73	300.242
2925.34	306.775
2927.96	311.613
2930.57	312.987
2933.18	313.534
2935.79	313.207
2938.4	310.283
2941.01	304.549
2943.62	296.378
2946.22	288.092
2948.83	278.967
2951.43	267.64
2954.04	256.214
2956.64	243.997
2959.24	232.858
2961.84	220.589
2964.45	209.604
2967.05	198.787
2969.64	188.263
2972.24	179.16
2974.84	168.867
2977.43	158.595
2980.03	148.061
2982.62	137.069
2985.22	126.544
2987.81	114.436
2990.4	103.177
2992.99	91.952
2995.58	81.7514
2998.17	73.3144
3000.76	64.0871
3003.34	55.1591
3005.93	46.9337
3008.52	39.4235
3011.1	32.5975
3013.68	27.0556
3016.27	22.4687
3018.85	19.2021
3021.43	16.5138
3024.01	15.7427
3026.59	14.4535
3029.16	13.2222
3031.74	12.9827
3034.32	13.9741
3036.89	14.693
3039.47	16.1393
3042.04	17.2957
3044.61	19.7801
3047.18	20.7138
3049.75	20.9108
3052.32	21.2995
3054.89	20.3082
3057.46	19.9983
3060.03	19.0713
3062.59	18.0625
3065.16	16.6937
3067.72	15.5716
3070.29	13.9705
3072.85	11.9169
3075.41	9.43589
3077.97	7.97476
3080.53	6.38259
3083.09	4.45667
3085.65	4.15646
3088.21	2.63166
3090.76	2.34372
3093.32	1.49297
3095.87	2.58895
3098.43	3.27778
3100.98	4.33852
3103.53	5.25852
3106.08	6.76726
3108.63	7.42037
3111.18	7.22067
3113.73	8.44357
3116.28	8.52192
3118.83	9.51656
3121.37	10.6169
3123.92	12.2185
3126.46	13.6237
3129	14.5956
3131.55	16.135
3134.09	15.5705
3136.63	15.8072
3139.17	16.7295
3141.71	17.9252
3144.24	19.4793
3146.78	21.5548
3149.32	24.8361