File: data/Raman/poly_smoothed/Thy_40_11_10_1x_45s_532 nm_x100_100%_600 gr_mm_01.txt
#Acq. time (s)=	45
#Accumulations=	2
#Range (cm-¹)=	200...3150
#Windows=	2
#Auto scanning=	Off
#Autofocus=	Off
#Macrospot=	Off
#AutoExposure=	Off
#Spike filter=	Multiple accum.
#Delay time (s)=	0
#Binning=	1
#Readout mode=	Signal
#DeNoise=	Off
#ICS correction=	On
#Dark correction=	Off
#Inst. Process=	Off
#Detector Gain=	Best Dynamic Range
#Detector ADC=	20 kHz
#Detector temperature (°C)=	-69.85
#Instrument=	LabRAM HR Evol
#Detector=	Synapse
#Objective=	x100
#Grating=	600 gr/mm
#ND Filter=	100%
#Laser (nm)=	532
#Hole=	100.021
#Range=	Auto
#Laser Pol.=	No
#Raman. Pol.=	No
#Laser Pol. (°)=	-0.0007625
#Raman Pol. (°)=	89.9995
#Collection=	Microscope
#StageXY=	Marzhauser
#StageZ=	Marzhauser
#X (µm)=	1976.8
#Y (µm)=	-66.7
#Z (µm)=	425.7
#Full time(mm:ss)=	3:18
#Project=
#Sample=
#Site=
#Title=	Thy_40_11_10_2x_45s_532 nm_x100_100%_600 gr_mm
#Remark=
#Date=	05.07.2022 10:34
#Acquired=	05.07.2022 10:34:02
#Base:Fit=	10.08.2022 10:01:35
#Base:Sub=	10.08.2022 10:01:52
#Filter:Polynom=	16.08.2022 10:21:53
#AxisType[0]=Intens
#AxisUnit[0]=Cnt
#AxisType[1]=Spectr
#AxisUnit[1]=1/cm
200.43	5.58175
204.059	5.05615
207.688	5.44561
211.314	4.85253
214.941	3.25503
218.564	2.09923
222.186	1.48382
225.809	1.85405
229.428	2.84076
233.045	4.11677
236.663	3.99017
240.278	4.49009
243.891	5.08812
247.503	5.71277
251.116	6.94768
254.725	7.65761
258.333	9.21811
261.939	10.5579
265.544	12.4685
269.148	12.5255
272.75	13.3751
276.351	14.5417
279.95	15.2399
283.548	14.574
287.144	14.5808
290.739	14.5229
294.333	14.0968
297.925	13.6538
301.514	14.0451
305.104	14.0689
308.692	14.9686
312.279	15.3478
315.862	16.0244
319.446	16.2386
323.029	16.1969
326.608	17.277
330.188	17.4908
333.766	19.2637
337.341	20.5113
340.917	20.7611
344.489	21.1032
348.062	20.7649
351.631	20.2014
355.201	21.0843
358.768	19.3889
362.333	19.6338
365.899	18.1745
369.462	17.2577
373.023	16.9178
376.585	15.5227
380.143	13.985
383.7	12.5648
387.256	12.9176
390.812	12.3872
394.365	11.9347
397.916	10.4119
401.467	11.2691
405.015	10.4231
408.563	11.3258
412.109	11.6501
415.654	12.2404
419.197	12.1493
422.739	12.6204
426.279	10.5307
429.819	9.28632
433.356	8.15238
436.891	8.08207
440.426	7.5195
443.96	7.1711
447.492	6.97054
451.021	8.33044
454.551	7.8704
458.079	6.30535
461.604	6.82295
465.13	5.67951
468.654	7.11911
472.175	8.51149
475.696	8.77695
479.215	9.60097
482.733	10.4389
486.249	11.1326
489.765	13.2819
493.278	12.9745
496.789	13.0523
500.301	13.8823
503.81	14.4933
507.317	14.2265
510.825	14.0951
514.33	12.9521
517.833	14.0018
521.335	13.969
524.836	14.5249
528.335	14.6233
531.835	14.1906
535.332	14.1934
538.827	13.0185
542.321	12.1639
545.814	12.0975
549.305	12.287
552.795	12.3326
556.282	11.587
559.769	10.8922
563.255	10.7652
566.739	10.1236
570.223	8.22659
573.705	8.05355
577.183	7.24375
580.663	6.01268
584.141	5.65663
587.615	5.97875
591.09	5.18052
594.564	4.51524
598.035	3.67729
601.506	2.24594
604.974	1.98687
608.443	2.33442
611.908	1.63509
615.374	0.517639
618.837	0.891491
622.3	1.77244
625.761	2.69667
629.219	2.92721
632.677	2.90545
636.135	3.88707
639.59	5.11589
643.043	6.00567
646.495	7.45914
649.948	8.60822
653.398	9.59065
656.846	10.7695
660.293	12.5906
663.738	14.1916
667.183	15.7176
670.626	16.1361
674.067	16.3583
677.508	16.6886
680.947	16.8524
684.385	17.2793
687.821	17.7326
691.254	18.8887
694.688	19.6642
698.121	21.2444
701.552	22.328
704.98	25.6129
708.409	25.9319
711.836	26.3738
715.26	28.0922
718.685	29.4774
722.108	31.2931
725.528	31.64
728.949	34.2971
732.367	36.9924
735.785	39.0354
739.2	42.4271
742.614	43.6224
746.028	45.3102
749.439	46.4968
752.849	47.4719
756.26	49.5614
759.667	50.9959
763.073	53.0468
766.477	54.4711
769.883	57.4514
773.285	59.3216
776.686	60.6891
780.085	62.8966
783.484	64.573
786.881	66.2327
790.276	67.4789
793.671	67.7422
797.064	70.9965
800.456	71.3893
803.846	71.8963
807.234	73.8505
810.622	73.1698
814.008	73.3056
817.394	73.7404
820.778	72.513
824.159	71.2391
827.541	68.7423
830.921	67.3118
834.298	65.9358
837.676	64.8306
841.051	61.7626
844.426	59.7046
847.798	57.5395
851.171	55.5679
854.54	51.6815
857.911	49.1865
861.278	47.3164
864.645	44.4176
868.01	43.7767
871.373	43.9247
874.735	43.2378
878.097	43.7219
881.457	45.1652
884.815	43.6909
888.172	44.3177
891.528	44.9929
894.882	45.2354
898.237	44.7088
901.589	45.5865
904.94	44.93
908.289	45.3924
911.635	44.0274
914.982	45.3418
918.328	44.3262
921.672	43.3703
925.015	42.7806
928.357	40.7974
931.698	39.1662
935.035	36.2585
938.373	34.8337
941.71	32.883
945.044	31.934
948.378	31.6858
951.709	32.5882
955.041	31.5903
958.372	31.1702
961.699	30.6096
965.027	30.6641
968.352	30.6316
971.676	30.0725
975	30.4664
978.322	28.9137
981.642	29.2686
984.962	27.9078
988.28	27.7863
991.596	26.9023
994.911	26.7485
998.227	25.6953
1001.54	23.8599
1004.85	22.2848
1008.16	21.6523
1011.47	19.4408
1014.78	17.6242
1018.08	17.5193
1021.39	16.9728
1024.69	15.9325
1028	17.1903
1031.3	17.2174
1034.6	15.7759
1037.9	14.9929
1041.19	13.6278
1044.49	14.0499
1047.78	13.2839
1051.08	12.8719
1054.37	11.7568
1057.66	11.2488
1060.95	9.35703
1064.24	7.82964
1067.53	7.07029
1070.81	7.83193
1074.1	7.357
1077.38	7.34755
1080.66	6.71928
1083.94	5.81989
1087.22	5.09249
1090.5	5.25019
1093.78	5.84029
1097.05	6.45663
1100.33	7.77827
1103.6	7.76667
1106.87	7.85158
1110.14	9.79372
1113.41	9.01438
1116.68	9.79358
1119.95	9.50812
1123.21	10.1078
1126.48	9.5679
1129.74	11.6519
1133	11.0804
1136.26	9.66124
1139.52	7.98779
1142.78	7.63887
1146.04	7.28211
1149.29	8.59747
1152.55	7.84239
1155.8	6.73521
1159.05	7.40288
1162.3	6.57222
1165.55	6.59264
1168.8	7.67921
1172.05	7.52769
1175.29	7.38636
1178.54	7.10582
1181.78	7.29375
1185.02	7.03343
1188.26	8.71969
1191.5	7.83134
1194.74	8.28382
1197.97	8.94187
1201.21	9.7078
1204.44	10.0029
1207.68	10.6649
1210.91	11.7024
1214.14	11.8391
1217.37	11.5404
1220.59	13.493
1223.82	15.624
1227.05	17.4596
1230.27	19.512
1233.49	20.9278
1236.72	23.2042
1239.94	24.2483
1243.16	25.1993
1246.37	27.1483
1249.59	28.9615
1252.8	30.4333
1256.02	31.1866
1259.23	31.2591
1262.44	32.4422
1265.66	34.0887
1268.86	34.7876
1272.07	36.5418
1275.28	37.9058
1278.48	38.8939
1281.69	38.8085
1284.89	39.1406
1288.09	40.3223
1291.29	41.3825
1294.49	41.4012
1297.69	42.3164
1300.89	42.4679
1304.08	43.6175
1307.28	44.2251
1310.47	44.8933
1313.66	44.8796
1316.85	44.3382
1320.04	43.9486
1323.23	44.0316
1326.42	44.2231
1329.61	44.4899
1332.79	43.3937
1335.97	42.6688
1339.16	43.2223
1342.34	43.7719
1345.52	41.4196
1348.7	41.5893
1351.87	40.6973
1355.05	38.5421
1358.22	36.6665
1361.4	34.4367
1364.57	33.3474
1367.74	31.5618
1370.91	30.3534
1374.08	29.6936
1377.25	29.5865
1380.41	29.0499
1383.58	29.8018
1386.74	28.5009
1389.91	27.5908
1393.07	26.336
1396.23	26.4196
1399.39	25.9039
1402.55	26.3325
1405.7	27.2794
1408.86	28.8014
1412.01	29.9726
1415.17	31.9094
1418.32	33.0338
1421.47	33.3233
1424.62	35.235
1427.77	37.0434
1430.91	40.1215
1434.06	42.8631
1437.2	44.8194
1440.35	47.2735
1443.49	49.4725
1446.63	51.9319
1449.77	53.4601
1452.91	54.3057
1456.05	53.7751
1459.18	52.0599
1462.32	49.3541
1465.45	46.2214
1468.59	44.5957
1471.72	42.007
1474.85	38.2026
1477.98	35.0293
1481.1	32.4431
1484.23	30.5295
1487.36	26.4654
1490.48	23.3524
1493.61	20.3374
1496.73	17.4488
1499.85	16.5195
1502.97	15.8304
1506.09	16.186
1509.2	17.6492
1512.32	17.9716
1515.43	17.9223
1518.55	18.9749
1521.66	19.5744
1524.77	19.7363
1527.88	20.9403
1530.99	22.1697
1534.1	23.3299
1537.21	23.603
1540.31	25.5666
1543.42	27.7971
1546.52	30.7175
1549.62	31.9417
1552.72	33.9585
1555.82	36.2174
1558.92	37.75
1562.02	39.3146
1565.11	40.0894
1568.21	41.6609
1571.3	43.5417
1574.39	46.5913
1577.49	47.9857
1580.57	49.3573
1583.66	49.8435
1586.75	48.9474
1589.84	47.8383
1592.92	46.1445
1596.01	44.6628
1599.09	43.1391
1602.17	40.9411
1605.25	41.3632
1608.33	40.1439
1611.41	39.1034
1614.49	38.7353
1617.57	38.0187
1620.64	37.4434
1623.72	37.8832
1626.79	37.5673
1629.86	38.1586
1632.93	39.2112
1636	40.6545
1639.07	41.3248
1642.13	42.8535
1645.2	45.2334
1648.26	47.324
1651.33	46.2762
1654.39	46.3881
1657.45	45.4876
1660.51	44.2546
1663.57	42.2125
1666.63	39.911
1669.68	37.4001
1672.74	34.9651
1675.79	33.0194
1678.85	31.6545
1681.9	29.7317
1684.95	27.4443
1688	25.1151
1691.05	22.4447
1694.09	21.0173
1697.14	19.3432
1700.18	18.6491
1703.23	17.6615
1706.27	16.3942
1709.31	15.3105
1712.35	14.2164
1715.39	13.8137
1718.43	12.9652
1721.47	11.2921
1724.5	10.6111
1727.54	9.66997
1730.57	8.73503
1733.61	8.24304
1736.64	6.97287
1739.67	6.0932
1742.7	6.27048
1745.72	5.63802
1748.75	5.24503
1751.77	4.25615
1754.8	3.9793
1757.82	3.71626
1760.84	4.50356
1763.87	3.60993
1766.89	4.52279
1769.91	3.88689
1772.92	3.92872
1775.94	3.605
1778.95	2.70212
1781.97	2.53919
1784.98	2.32903
1787.99	2.07321
1791.01	1.39385
1794.01	0.981922
1797.02	1.73083
1800.03	2.68327
1803.04	3.32642
1806.04	3.32839
1809.05	3.0929
1812.05	3.79471
1815.05	3.60534
1818.05	4.42361
1821.05	4.16788
1824.05	4.61623
1827.05	4.75073
1830.04	6.03523
1833.04	6.02389
1836.03	6.90467
1839.03	6.87773
1842.02	7.92434
1845.01	7.75551
1848	8.07086
1850.99	7.79106
1853.97	9.0461
1856.96	8.62906
1859.94	8.06879
1862.93	8.3962
1865.91	8.69076
1868.89	9.20614
1871.87	9.41566
1874.85	9.74959
1877.83	10.1011
1880.81	9.36476
1882.57	10.2629
1885.56	10.4069
1888.55	9.7628
1891.54	9.194
1894.52	8.75227
1897.51	8.27949
1900.49	8.20549
1903.47	8.23632
1906.45	8.44488
1909.43	7.72572
1912.41	6.84514
1915.39	6.6761
1918.37	5.67102
1921.34	5.21719
1924.32	4.44044
1927.29	4.61284
1930.26	3.88608
1933.23	3.52788
1936.2	3.09249
1939.17	2.94501
1942.14	3.4915
1945.11	3.80342
1948.07	4.6328
1951.04	3.78786
1954	3.40224
1956.96	2.54688
1959.93	2.49373
1962.89	2.05639
1965.85	1.91534
1968.8	2.42446
1971.76	3.14378
1974.72	3.8182
1977.67	3.96781
1980.63	3.88964
1983.58	3.60069
1986.53	4.2327
1989.48	3.90188
1992.43	3.28982
1995.38	3.72899
1998.32	3.59527
2001.27	3.32014
2004.22	3.7702
2007.16	3.6476
2010.1	3.91753
2013.04	3.38812
2015.98	3.80227
2018.92	3.80761
2021.86	4.08243
2024.8	4.88802
2027.74	4.82961
2030.67	4.97524
2033.61	6.08094
2036.54	6.55136
2039.47	6.6192
2042.4	7.08962
2045.33	7.39385
2048.26	8.35194
2051.19	9.52023
2054.12	9.04508
2057.04	9.3674
2059.97	9.25855
2062.89	8.93764
2065.81	9.70957
2068.73	9.86876
2071.65	10.3434
2074.57	10.5295
2077.49	10.944
2080.41	10.635
2083.32	11.1158
2086.24	11.7639
2089.15	12.2293
2092.07	11.9031
2094.98	11.3289
2097.89	11.1304
2100.8	12.152
2103.71	12.5069
2106.61	13.02
2109.52	13.2687
2112.43	13.8778
2115.33	15.0532
2118.23	17.9776
2121.13	19.5082
2124.04	21.7189
2126.94	24.2351
2129.83	25.9584
2132.73	28.6264
2135.63	30.6577
2138.53	32.1551
2141.42	33.4178
2144.31	35.2955
2147.21	37.7306
2150.1	39.5746
2152.99	40.865
2155.88	41.7977
2158.77	42.4879
2161.65	42.197
2164.54	42.9137
2167.43	44.1203
2170.31	45.68
2173.19	46.3098
2176.07	46.1046
2178.96	45.4855
2181.84	43.9789
2184.72	44.6378
2187.59	44.3944
2190.47	43.7558
2193.35	42.9548
2196.22	41.8642
2199.09	39.267
2201.97	37.7183
2204.84	36.6197
2207.71	33.6124
2210.58	31.8162
2213.45	29.8677
2216.31	28.185
2219.18	25.0331
2222.05	22.927
2224.91	20.5835
2227.78	18.617
2230.64	18.2958
2233.5	16.7805
2236.36	17.1262
2239.22	16.4392
2242.08	16.5044
2244.93	16.1691
2247.79	15.3175
2250.64	14.2193
2253.5	14.1929
2256.35	14.4961
2259.2	13.8572
2262.05	14.5652
2264.9	13.4235
2267.75	13.6299
2270.6	13.3167
2273.45	12.9044
2276.29	11.8748
2279.14	10.8187
2281.98	9.61936
2284.82	9.70417
2287.66	8.82498
2290.5	7.9765
2293.34	6.22594
2296.18	6.17637
2299.02	6.51842
2301.86	6.78817
2304.69	8.19452
2307.53	8.05462
2310.36	8.66798
2313.19	8.23527
2316.02	7.61214
2318.85	7.95507
2321.68	8.47875
2324.51	7.95524
2327.34	8.56379
2330.16	8.11158
2332.99	7.09577
2335.81	6.03513
2338.64	5.43743
2341.46	4.43044
2344.28	3.5249
2347.1	3.02548
2349.92	2.47845
2352.74	1.94861
2355.55	2.01515
2358.37	1.19984
2361.19	0.103437
2364	0.0559481
2366.81	1.29975
2369.62	1.17149
2372.44	1.3865
2375.24	1.81817
2378.05	1.92941
2380.86	1.83822
2383.67	2.06768
2386.47	2.47852
2389.28	2.81735
2392.08	2.42765
2394.89	2.68452
2397.69	2.33106
2400.49	2.17338
2403.29	2.06478
2406.09	2.05103
2408.88	2.46677
2411.68	2.92005
2414.48	2.85785
2417.27	3.13942
2420.06	3.70576
2422.86	4.06195
2425.65	4.17032
2428.44	4.14225
2431.23	4.18364
2434.02	3.78469
2436.81	3.938
2439.59	3.36757
2442.38	3.24454
2445.16	3.30373
2447.95	3.16894
2450.73	2.51392
2453.51	1.69933
2456.29	1.67724
2459.07	1.46342
2461.85	0.788012
2464.63	1.22276
2467.4	0.574936
2470.18	0.665988
2472.95	0.662825
2475.73	0.0804442
2478.5	0.659002
2481.27	0.710993
2484.04	0.62435
2486.81	1.43147
2489.58	1.07842
2492.35	1.15815
2495.12	1.91188
2497.88	1.72817
2500.65	2.00494
2503.41	1.76694
2506.17	1.89463
2508.94	1.67509
2511.7	1.93558
2514.46	1.94424
2517.22	2.40948
2519.97	3.16885
2522.73	4.18773
2525.49	4.54012
2528.24	4.2869
2530.99	5.19802
2533.75	5.53298
2536.5	5.81588
2539.25	5.31261
2542	5.09661
2544.75	5.04839
2547.5	5.27243
2550.24	5.36488
2552.99	5.33939
2555.74	5.33021
2558.48	4.45711
2561.22	4.93014
2563.96	4.56162
2566.71	4.39822
2569.45	3.68863
2572.18	4.1706
2574.92	3.65064
2577.66	3.28158
2580.4	2.87057
2583.13	2.84515
2585.87	3.70344
2588.6	4.155
2591.33	4.93828
2594.06	4.5514
2596.79	4.94762
2599.52	5.09756
2602.25	4.43014
2604.98	3.69758
2607.71	2.74361
2610.43	3.28451
2613.16	3.00109
2615.88	2.96889
2618.6	3.00793
2621.32	2.97573
2624.04	3.37539
2626.76	3.44157
2629.48	3.68837
2632.2	2.91944
2634.92	3.60462
2637.63	3.92056
2640.35	4.26937
2643.06	4.06667
2645.77	3.9636
2648.49	3.77354
2651.2	3.91925
2653.91	3.93028
2656.62	4.20804
2659.33	3.80891
2662.03	3.64516
2664.74	2.87915
2667.44	2.68668
2670.15	2.55128
2672.85	1.90686
2675.55	1.15051
2678.26	1.46012
2680.96	0.727079
2683.66	0.448607
2686.35	0.905092
2689.05	1.67226
2691.75	1.29822
2694.44	1.57169
2697.14	2.02467
2699.83	2.56914
2702.52	3.3739
2705.22	3.12104
2707.91	3.30739
2710.6	3.34831
2713.29	2.88754
2715.97	2.72286
2718.66	3.56411
2721.35	4.09319
2724.03	5.08615
2726.72	5.41611
2729.4	5.11807
2732.08	4.48889
2734.76	4.62126
2737.44	3.9675
2740.12	3.91136
2742.8	3.76029
2745.48	3.19104
2748.16	2.5246
2750.83	2.48369
2753.51	2.47538
2756.18	2.89329
2758.85	2.85505
2761.53	2.42428
2764.2	1.88263
2766.87	0.754387
2769.54	1.11207
2772.2	1.26314
2774.87	1.34479
2777.54	1.4154
2780.2	2.24413
2782.87	2.28815
2785.53	2.72877
2788.19	2.65725
2790.85	3.28456
2793.51	2.55988
2796.17	2.03601
2798.83	2.25213
2801.49	2.08165
2804.15	1.92389
2806.8	1.9403
2809.46	0.642565
2812.11	0.152841
2814.76	-0.419596
2817.42	-0.328411
2820.07	0.40341
2822.72	0.833658
2825.37	1.10238
2828.02	2.70549
2830.66	4.28367
2833.31	6.52882
2835.96	9.01205
2838.6	11.0138
2841.24	12.9234
2843.89	15.8712
2846.53	18.0659
2849.17	20.6186
2851.81	23.8476
2854.45	26.9103
2857.09	30.6064
2859.72	33.2429
2862.36	35.6233
2865	37.9108
2867.63	40.6336
2870.26	42.3612
2872.9	44.2124
2875.53	45.07
2878.16	47.435
2880.79	48.9651
2883.42	51.2634
2886.05	53.6664
2888.67	55.2753
2891.3	58.1353
2893.92	60.2802
2896.55	63.013
2899.17	66.3824
2901.79	70.1178
2904.42	74.0498
2907.04	77.9364
2909.66	82.1306
2912.27	86.9405
2914.89	92.1133
2917.51	97.0459
2920.13	100.669
2922.74	104.846
2925.35	107.548
2927.97	109.129
2930.58	110.03
2933.19	110.727
2935.8	110.401
2938.41	109.31
2941.02	108.14
2943.63	106.381
2946.24	103.391
2948.84	100.042
2951.45	96.2626
2954.05	92.8235
2956.65	89.0104
2959.26	85.292
2961.86	81.9567
2964.46	78.1375
2967.06	74.7876
2969.66	71.6514
2972.25	68.2954
2974.85	64.917
2977.45	60.5409
2980.04	55.7824
2982.64	51.1267
2985.23	46.2651
2987.82	42.1842
2990.41	36.0136
2993	30.7134
2995.59	26.0904
2998.18	21.8324
3000.77	18.1647
3003.36	15.3398
3005.94	12.287
3008.53	9.21786
3011.11	7.13228
3013.69	5.40387
3016.28	4.10049
3018.86	2.6589
3021.44	1.58045
3024.02	1.09298
3026.6	1.28507
3029.18	2.58184
3031.75	3.65247
3034.33	3.88654
3036.9	4.20069
3039.48	5.03752
3042.05	5.61987
3044.62	5.57196
3047.19	6.67853
3049.77	7.31997
3052.34	7.83667
3054.9	7.73468
3057.47	7.60775
3060.04	6.73658
3062.61	7.05454
3065.17	6.76791
3067.74	6.49794
3070.3	5.69732
3072.86	5.48663
3075.42	4.62717
3077.99	3.78983
3080.54	2.51371
3083.1	1.37894
3085.66	0.861618
3088.22	-0.0973491
3090.78	0.638303
3093.33	0.802476
3095.89	0.773324
3098.44	1.12962
3100.99	2.0796
3103.54	2.59469
3106.1	3.51699
3108.65	4.66209
3111.2	5.37272
3113.74	6.04425
3116.29	6.79557
3118.84	6.83743
3121.38	6.92391
3123.93	7.71759
3126.47	8.49794
3129.01	8.75348
3131.56	9.48486
3134.1	10.1225
3136.64	9.57329
3139.18	9.87179
3141.72	9.30143
3144.26	8.88396
3146.79	8.49322
3149.33	10.1963