File: data/Raman/poly_smoothed/Thy_40_11_15_1x_45s_532 nm_x100_100%_600 gr_mm_01.txt
#Acq. time (s)=	45
#Accumulations=	2
#Range (cm-¹)=	200...3150
#Windows=	2
#Auto scanning=	Off
#Autofocus=	Off
#Macrospot=	Off
#AutoExposure=	Off
#Spike filter=	Multiple accum.
#Delay time (s)=	0
#Binning=	1
#Readout mode=	Signal
#DeNoise=	Off
#ICS correction=	On
#Dark correction=	Off
#Inst. Process=	Off
#Detector Gain=	Best Dynamic Range
#Detector ADC=	20 kHz
#Detector temperature (°C)=	-69.85
#Instrument=	LabRAM HR Evol
#Detector=	Synapse
#Objective=	x100
#Grating=	600 gr/mm
#ND Filter=	100%
#Laser (nm)=	532
#Hole=	100.021
#Range=	Auto
#Laser Pol.=	No
#Raman. Pol.=	No
#Laser Pol. (°)=	-0.0007625
#Raman Pol. (°)=	89.9995
#Collection=	Microscope
#StageXY=	Marzhauser
#StageZ=	Marzhauser
#X (µm)=	1965.5
#Y (µm)=	-54.3
#Z (µm)=	425.7
#Full time(mm:ss)=	3:19
#Project=
#Sample=
#Site=
#Title=	Thy_40_11_15_2x_45s_532 nm_x100_100%_600 gr_mm
#Remark=
#Date=	05.07.2022 10:57
#Acquired=	05.07.2022 10:57:42
#Base:Fit=	10.08.2022 10:01:35
#Base:Sub=	10.08.2022 10:01:52
#Filter:Polynom=	16.08.2022 10:21:53
#AxisType[0]=Intens
#AxisUnit[0]=Cnt
#AxisType[1]=Spectr
#AxisUnit[1]=1/cm
200.43	27.7917
204.059	24.248
207.688	19.4973
211.314	16.1894
214.941	13.985
218.564	10.9805
222.186	9.00843
225.809	7.63195
229.428	4.62719
233.045	2.9034
236.663	1.83711
240.278	1.39343
243.891	1.63296
247.503	2.55633
251.116	3.64065
254.725	4.32583
258.333	4.63339
261.939	4.41739
265.544	4.18298
269.148	4.4814
272.75	4.704
276.351	4.30894
279.95	3.9647
283.548	6.51438
287.144	6.21016
290.739	6.41195
294.333	6.35783
297.925	7.17321
301.514	6.87065
305.104	8.33423
308.692	7.54062
312.279	7.66821
315.862	6.88964
319.446	6.72606
323.029	7.45944
326.608	8.04275
330.188	8.82376
333.766	8.95582
337.341	9.18317
340.917	8.78276
344.489	8.18382
348.062	8.03873
351.631	7.59966
355.201	5.74808
358.768	6.58368
362.333	6.84159
365.899	5.50525
369.462	6.34459
373.023	6.51914
376.585	6.45008
380.143	6.08942
383.7	6.22594
387.256	7.10456
390.812	7.20348
394.365	6.7847
397.916	7.14183
401.467	8.2146
405.015	6.62398
408.563	6.60589
412.109	8.08745
415.654	8.57506
419.197	8.08029
422.739	6.7383
426.279	7.83758
429.819	8.3629
433.356	6.27162
436.891	5.4507
440.426	4.91259
443.96	4.27992
447.492	4.32584
451.021	3.52207
454.551	2.8851
458.079	2.93925
461.604	2.53646
465.13	2.57202
468.654	3.06083
472.175	2.90132
475.696	3.22331
479.215	3.46262
482.733	5.33629
486.249	7.32941
489.765	8.50505
493.278	10.9805
496.789	14.3588
500.301	15.0133
503.81	15.7182
507.317	17.5241
510.825	16.8928
514.33	17.856
517.833	17.0065
521.335	17.1165
524.836	16.9931
528.335	16.8735
531.835	15.8735
535.332	15.0631
538.827	12.0743
542.321	10.9969
545.814	9.44602
549.305	8.39737
552.795	7.53404
556.282	8.01766
559.769	6.41034
563.255	5.01762
566.739	5.12533
570.223	5.14739
573.705	5.45569
577.183	5.36251
580.663	5.47108
584.141	6.31914
587.615	6.54974
591.09	7.19492
594.564	7.50019
598.035	7.18684
601.506	7.84808
604.974	7.70561
608.443	8.77846
611.908	10.6136
615.374	11.9618
618.837	12.49
622.3	13.3109
625.761	13.4016
629.219	14.6306
632.677	15.3624
636.135	16.6803
639.59	18.4066
643.043	18.7193
646.495	18.3622
649.948	17.7492
653.398	19.6437
656.846	19.9547
660.293	21.3091
663.738	23.1081
667.183	24.7354
670.626	25.1218
674.067	24.5003
677.508	24.8054
680.947	26.7236
684.385	26.6632
687.821	27.5306
691.254	29.9266
694.688	31.8143
698.121	31.6294
701.552	33.2944
704.98	34.1585
708.409	34.8602
711.836	37.0159
715.26	38.212
718.685	38.4946
722.108	40.32
725.528	42.1591
728.949	42.9954
732.367	44.241
735.785	46.0305
739.2	47.1434
742.614	49.1859
746.028	52.6615
749.439	55.1359
752.849	55.5966
756.26	58.2436
759.667	60.8462
763.073	63.3988
766.477	64.7117
769.883	67.0517
773.285	67.9846
776.686	69.7366
780.085	70.9976
783.484	73.4087
786.881	76.7797
790.276	78.0691
793.671	81.4263
797.064	83.3678
800.456	83.1453
803.846	85.6975
807.234	86.3909
810.622	87.1467
814.008	85.3886
817.394	82.931
820.778	82.3596
824.159	83.0255
827.541	83.3492
830.921	83.5688
834.298	80.7937
837.676	80.2511
841.051	79.9621
844.426	75.9925
847.798	74.0804
851.171	72.32
854.54	69.1237
857.911	66.3909
861.278	63.0953
864.645	61.6926
868.01	60.3043
871.373	59.4909
874.735	57.2928
878.097	55.8395
881.457	54.0827
884.815	53.2459
888.172	53.1339
891.528	51.8373
894.882	49.8057
898.237	48.9826
901.589	49.2489
904.94	51.6187
908.289	50.6262
911.635	50.107
914.982	47.5876
918.328	47.4633
921.672	47.7491
925.015	46.7316
928.357	46.2149
931.698	44.3263
935.035	44.692
938.373	45.2997
941.71	43.2365
945.044	40.5523
948.378	39.7948
951.709	38.5192
955.041	36.2638
958.372	33.7009
961.699	33.1479
965.027	32.1761
968.352	31.3536
971.676	30.4371
975	30.3698
978.322	29.6727
981.642	29.9225
984.962	29.7051
988.28	27.7032
991.596	25.2377
994.911	24.1356
998.227	24.7398
1001.54	25.4053
1004.85	24.8622
1008.16	25.0003
1011.47	24.5043
1014.78	25.7458
1018.08	27.5488
1021.39	27.0616
1024.69	26.1778
1028	24.7313
1031.3	25.7847
1034.6	25.2073
1037.9	24.5727
1041.19	24.589
1044.49	24.1473
1047.78	24.2963
1051.08	23.9823
1054.37	24.1375
1057.66	22.4285
1060.95	21.8817
1064.24	20.5596
1067.53	18.2317
1070.81	16.1528
1074.1	15.86
1077.38	15.221
1080.66	14.3038
1083.94	12.2591
1087.22	12.3695
1090.5	12.4396
1093.78	13.3502
1097.05	15.2572
1100.33	16.6291
1103.6	18.1377
1106.87	18.2179
1110.14	18.9446
1113.41	20.3406
1116.68	20.5883
1119.95	19.9758
1123.21	20.2411
1126.48	19.6575
1129.74	16.9736
1133	15.5853
1136.26	13.5434
1139.52	11.3031
1142.78	10.2025
1146.04	7.28009
1149.29	6.39121
1152.55	5.70799
1155.8	3.84423
1159.05	1.8856
1162.3	1.21173
1165.55	-0.315291
1168.8	0.445255
1172.05	0.622558
1175.29	1.15843
1178.54	2.05758
1181.78	2.48566
1185.02	3.95179
1188.26	5.56378
1191.5	6.66401
1194.74	7.89356
1197.97	8.7374
1201.21	9.99775
1204.44	11.8677
1207.68	12.4089
1210.91	13.1892
1214.14	16.7902
1217.37	17.1124
1220.59	18.1878
1223.82	19.1414
1227.05	20.6353
1230.27	22.1879
1233.49	23.8681
1236.72	24.9142
1239.94	25.0601
1243.16	26.9985
1246.37	27.9637
1249.59	29.0389
1252.8	30.6793
1256.02	31.8225
1259.23	32.921
1262.44	33.9176
1265.66	36.2785
1268.86	36.5385
1272.07	36.5217
1275.28	37.5961
1278.48	38.4656
1281.69	39.329
1284.89	39.6811
1288.09	39.4032
1291.29	38.9767
1294.49	39.7326
1297.69	40.9853
1300.89	40.8869
1304.08	41.0218
1307.28	43.1207
1310.47	43.8585
1313.66	42.9138
1316.85	42.8364
1320.04	42.9192
1323.23	43.2329
1326.42	43.5605
1329.61	43.0652
1332.79	43.0405
1335.97	41.7354
1339.16	41.2369
1342.34	41.294
1345.52	41.0331
1348.7	38.7316
1351.87	38.0984
1355.05	37.5288
1358.22	36.5365
1361.4	35.9004
1364.57	34.8778
1367.74	34.2048
1370.91	33.6043
1374.08	32.1853
1377.25	31.0907
1380.41	30.0737
1383.58	30.1689
1386.74	29.6013
1389.91	28.5649
1393.07	28.1937
1396.23	27.4303
1399.39	26.9398
1402.55	26.9396
1405.7	26.6621
1408.86	26.417
1412.01	26.5076
1415.17	26.0335
1418.32	28.7738
1421.47	29.7666
1424.62	31.9782
1427.77	34.9339
1430.91	38.4199
1434.06	41.446
1437.2	44.2787
1440.35	46.9279
1443.49	48.6043
1446.63	49.1619
1449.77	48.8935
1452.91	47.8475
1456.05	47.7504
1459.18	47.0333
1462.32	45.4176
1465.45	43.0304
1468.59	39.863
1471.72	36.0839
1474.85	32.9732
1477.98	29.8319
1481.1	25.2577
1484.23	21.9863
1487.36	18.7304
1490.48	16.5237
1493.61	14.8363
1496.73	14.0688
1499.85	13.5327
1502.97	13.2191
1506.09	13.9653
1509.2	14.3669
1512.32	16.0167
1515.43	16.351
1518.55	16.4922
1521.66	17.6076
1524.77	17.3273
1527.88	17.1928
1530.99	18.3742
1534.1	20.4416
1537.21	22.1594
1540.31	24.2339
1543.42	24.4698
1546.52	25.9814
1549.62	27.4466
1552.72	29.736
1555.82	29.9278
1558.92	32.1468
1562.02	33.7538
1565.11	34.9657
1568.21	36.2753
1571.3	36.8856
1574.39	37.662
1577.49	38.8403
1580.57	39.9378
1583.66	40.1121
1586.75	41.1862
1589.84	41.5491
1592.92	40.3757
1596.01	38.5321
1599.09	36.6261
1602.17	36.8409
1605.25	36.6177
1608.33	36.4713
1611.41	36.0355
1614.49	37.202
1617.57	37.0597
1620.64	36.7772
1623.72	37.8785
1626.79	39.5515
1629.86	40.6022
1632.93	42.3374
1636	44.8996
1639.07	46.9087
1642.13	49.4397
1645.2	51.1705
1648.26	52.0011
1651.33	54.1996
1654.39	54.8525
1657.45	56.0852
1660.51	55.931
1663.57	55.7425
1666.63	53.5183
1669.68	51.3208
1672.74	48.9178
1675.79	46.8289
1678.85	44.7487
1681.9	41.2486
1684.95	38.7511
1688	35.5686
1691.05	31.9679
1694.09	28.5509
1697.14	25.842
1700.18	23.196
1703.23	21.3308
1706.27	18.6398
1709.31	16.8064
1712.35	14.8478
1715.39	14.0449
1718.43	13.3535
1721.47	12.2732
1724.5	12.8433
1727.54	11.8327
1730.57	11.1911
1733.61	11.3288
1736.64	11.0165
1739.67	10.9288
1742.7	10.7358
1745.72	11.1457
1748.75	10.5756
1751.77	10.7356
1754.8	10.5341
1757.82	10.0704
1760.84	10.2603
1763.87	9.04915
1766.89	8.26541
1769.91	9.21489
1772.92	7.85507
1775.94	6.70079
1778.95	6.47233
1781.97	6.97946
1784.98	6.63941
1787.99	7.12163
1791.01	7.31506
1794.01	7.14383
1797.02	6.21735
1800.03	5.17656
1803.04	4.39418
1806.04	4.3853
1809.05	4.63314
1812.05	5.01783
1815.05	5.2399
1818.05	5.23894
1821.05	4.61767
1824.05	5.02378
1827.05	5.01663
1830.04	4.72746
1833.04	4.62892
1836.03	4.36812
1839.03	4.76152
1842.02	4.57217
1845.01	5.2034
1848	5.43732
1850.99	6.13798
1853.97	7.22912
1856.96	6.62983
1859.94	6.17319
1862.93	5.87365
1865.91	5.62328
1868.89	4.97492
1871.87	4.67925
1874.85	4.99035
1877.83	4.7297
1880.81	4.19521
1882.57	4.09075
1885.56	3.48923
1888.55	3.11179
1891.54	2.83305
1894.52	1.38575
1897.51	1.57528
1900.49	1.08454
1903.47	0.300912
1906.45	0.597143
1909.43	0.681434
1912.41	1.20899
1915.39	2.10354
1918.37	2.14467
1921.34	1.37754
1924.32	1.5019
1927.29	1.81423
1930.26	1.42001
1933.23	2.13942
1936.2	3.425
1939.17	3.81819
1942.14	3.99226
1945.11	4.12198
1948.07	4.17214
1951.04	4.0762
1954	3.77659
1956.96	4.24295
1959.93	3.88741
1962.89	3.78591
1965.85	2.83894
1968.8	2.57527
1971.76	3.45979
1974.72	1.92125
1977.67	2.21204
1980.63	1.34884
1983.58	2.28291
1986.53	1.25846
1989.48	0.251861
1992.43	-0.51406
1995.38	0.248627
1998.32	0.784824
2001.27	0.658232
2004.22	1.0428
2007.16	1.87097
2010.1	2.36548
2013.04	2.70403
2015.98	2.93297
2018.92	2.94259
2021.86	3.96149
2024.8	5.60481
2027.74	5.1816
2030.67	4.79119
2033.61	4.77014
2036.54	5.44817
2039.47	7.09535
2042.4	7.30189
2045.33	7.03987
2048.26	7.04745
2051.19	6.65533
2054.12	7.32875
2057.04	7.20681
2059.97	7.53632
2062.89	7.88021
2065.81	8.38083
2068.73	9.19965
2071.65	9.27276
2074.57	9.8023
2077.49	9.89824
2080.41	9.86546
2083.32	9.86037
2086.24	9.9776
2089.15	10.0488
2092.07	10.8938
2094.98	12.122
2097.89	12.5313
2100.8	12.8888
2103.71	14.452
2106.61	15.8202
2109.52	18.2359
2112.43	18.9979
2115.33	19.8624
2118.23	22.8523
2121.13	24.5612
2124.04	26.8255
2126.94	29.6301
2129.83	31.485
2132.73	33.4192
2135.63	34.6589
2138.53	36.6628
2141.42	39.0082
2144.31	40.3048
2147.21	41.3206
2150.1	40.8396
2152.99	41.3213
2155.88	41.9886
2158.77	42.4911
2161.65	43.0071
2164.54	43.186
2167.43	43.4001
2170.31	43.4634
2173.19	44.8289
2176.07	44.4451
2178.96	44.6355
2181.84	43.8851
2184.72	43.1023
2187.59	43.3076
2190.47	42.2088
2193.35	40.8199
2196.22	39.4356
2199.09	38.1223
2201.97	35.9494
2204.84	33.6063
2207.71	32.5951
2210.58	31.4838
2213.45	28.766
2216.31	26.0759
2219.18	23.6044
2222.05	22.3315
2224.91	20.9887
2227.78	20.6957
2230.64	19.685
2233.5	18.3958
2236.36	17.0887
2239.22	16.4047
2242.08	16.7424
2244.93	15.3683
2247.79	14.1216
2250.64	12.692
2253.5	11.8188
2256.35	10.922
2259.2	9.25627
2262.05	8.08013
2264.9	7.24023
2267.75	6.34037
2270.6	5.8412
2273.45	4.79422
2276.29	4.72125
2279.14	4.31122
2281.98	4.0628
2284.82	2.80288
2287.66	2.94821
2290.5	3.42087
2293.34	4.3051
2296.18	3.63842
2299.02	4.79363
2301.86	4.40501
2304.69	4.93963
2307.53	5.06544
2310.36	6.39046
2313.19	7.57704
2316.02	8.02766
2318.85	8.08701
2321.68	7.34104
2324.51	7.5547
2327.34	7.94106
2330.16	8.23911
2332.99	8.81132
2335.81	9.3775
2338.64	8.82993
2341.46	7.94374
2344.28	6.7659
2347.1	6.62377
2349.92	5.42535
2352.74	3.83232
2355.55	2.81411
2358.37	1.97744
2361.19	1.9936
2364	1.48944
2366.81	1.62474
2369.62	1.26305
2372.44	1.57403
2375.24	1.882
2378.05	2.39142
2380.86	2.95439
2383.67	2.896
2386.47	4.15075
2389.28	3.48422
2392.08	3.38607
2394.89	4.70143
2397.69	4.88706
2400.49	5.01439
2403.29	5.09951
2406.09	4.2306
2408.88	3.18808
2411.68	3.14135
2414.48	3.37814
2417.27	3.43513
2420.06	3.24445
2422.86	4.21881
2425.65	4.53686
2428.44	4.95742
2431.23	4.97294
2434.02	4.44019
2436.81	4.90376
2439.59	6.01415
2442.38	6.5506
2445.16	6.91876
2447.95	7.25959
2450.73	7.71323
2453.51	8.76343
2456.29	9.01462
2459.07	9.46942
2461.85	9.50735
2464.63	8.12362
2467.4	7.36737
2470.18	6.86937
2472.95	6.6483
2475.73	5.01971
2478.5	5.57421
2481.27	5.88221
2484.04	5.77006
2486.81	5.75344
2489.58	5.90035
2492.35	4.42491
2495.12	3.79432
2497.88	3.1028
2500.65	2.96395
2503.41	3.99233
2506.17	4.71249
2508.94	4.77291
2511.7	4.21697
2514.46	4.00351
2517.22	3.86797
2519.97	3.87574
2522.73	4.3693
2525.49	5.17623
2528.24	5.46749
2530.99	4.80538
2533.75	4.22011
2536.5	3.3553
2539.25	4.14191
2542	3.53691
2544.75	4.36979
2547.5	5.43945
2550.24	5.27878
2552.99	5.90718
2555.74	5.86274
2558.48	5.19913
2561.22	5.15712
2563.96	4.74772
2566.71	4.39942
2569.45	4.23229
2572.18	4.26174
2574.92	3.56736
2577.66	2.93059
2580.4	2.10743
2583.13	1.00486
2585.87	1.65289
2588.6	1.38418
2591.33	1.88775
2594.06	1.55155
2596.79	1.88576
2599.52	1.5815
2602.25	1.57046
2604.98	2.2029
2607.71	2.98615
2610.43	4.28849
2613.16	4.59062
2615.88	4.90787
2618.6	4.44161
2621.32	4.00009
2624.04	3.54162
2626.76	4.13265
2629.48	3.96932
2632.2	4.31755
2634.92	5.54693
2637.63	6.18792
2640.35	6.36709
2643.06	6.98049
2645.77	7.64956
2648.49	7.33037
2651.2	6.99086
2653.91	6.82289
2656.62	7.04235
2659.33	7.30328
2662.03	8.01732
2664.74	8.28768
2667.44	7.72837
2670.15	7.6219
2672.85	7.31466
2675.55	6.47713
2678.26	5.06454
2680.96	4.6402
2683.66	4.05125
2686.35	3.53836
2689.05	3.81514
2691.75	4.2326
2694.44	4.45058
2697.14	5.05437
2699.83	5.14068
2702.52	6.11437
2705.22	6.83383
2707.91	7.39671
2710.6	7.68329
2713.29	7.53403
2715.97	6.69049
2718.66	7.51266
2721.35	7.77144
2724.03	7.55471
2726.72	7.55596
2729.4	6.77906
2732.08	6.23664
2734.76	5.59621
2737.44	5.06694
2740.12	4.93961
2742.8	3.83366
2745.48	4.06643
2748.16	4.44611
2750.83	3.78049
2753.51	3.89727
2756.18	2.79464
2758.85	1.98656
2761.53	1.35774
2764.2	2.05362
2766.87	1.64749
2769.54	2.12886
2772.2	2.39153
2774.87	1.81446
2777.54	1.60715
2780.2	1.37576
2782.87	1.32224
2785.53	1.38197
2788.19	0.629954
2790.85	0.820037
2793.51	0.499699
2796.17	0.654294
2798.83	0.0454491
2801.49	0.187061
2804.15	0.0833348
2806.8	-0.185194
2809.46	-0.153803
2812.11	-0.686325
2814.76	-0.611992
2817.42	0.0251676
2820.07	0.653539
2822.72	1.66684
2825.37	3.72285
2828.02	6.37559
2830.66	8.57624
2833.31	9.93607
2835.96	12.9996
2838.6	14.2577
2841.24	17.7591
2843.89	20.4341
2846.53	25.0016
2849.17	28.3037
2851.81	31.3928
2854.45	34.8648
2857.09	39.7509
2859.72	42.3068
2862.36	45.3001
2865	48.3886
2867.63	51.2902
2870.26	53.5399
2872.9	54.9538
2875.53	55.6993
2878.16	56.5062
2880.79	58.0132
2883.42	59.6464
2886.05	60.9566
2888.67	62.8468
2891.3	63.5954
2893.92	64.7008
2896.55	65.9347
2899.17	68.7731
2901.79	71.4507
2904.42	74.529
2907.04	79.1687
2909.66	84.4735
2912.27	88.3555
2914.89	93.2974
2917.51	97.9245
2920.13	102.395
2922.74	106.561
2925.35	108.04
2927.97	110.051
2930.58	110.416
2933.19	111.128
2935.8	108.986
2938.41	106.279
2941.02	102.557
2943.63	100.412
2946.24	97.4648
2948.84	93.6006
2951.45	89.4746
2954.05	84.8689
2956.65	78.7974
2959.26	74.9243
2961.86	71.015
2964.46	67.1767
2967.06	63.2797
2969.66	59.9143
2972.25	55.8339
2974.85	52.2331
2977.45	48.3984
2980.04	44.5913
2982.64	40.5856
2985.23	36.5236
2987.82	32.3281
2990.41	28.1364
2993	24.3251
2995.59	21.0652
2998.18	18.1236
3000.77	13.5488
3003.36	11.3532
3005.94	10.7107
3008.53	8.11668
3011.11	5.77103
3013.69	4.08828
3016.28	2.11478
3018.86	1.54617
3021.44	1.18415
3024.02	1.82925
3026.6	1.51437
3029.18	1.02195
3031.75	0.718473
3034.33	0.562459
3036.9	1.22578
3039.48	1.9085
3042.05	2.3826
3044.62	2.8979
3047.19	3.20246
3049.77	3.60374
3052.34	3.33361
3054.9	3.43096
3057.47	3.79404
3060.04	3.46786
3062.61	3.35714
3065.17	2.86285
3067.74	2.40175
3070.3	1.85339
3072.86	0.788844
3075.42	0.73948
3077.99	0.607267
3080.54	1.33359
3083.1	1.9551
3085.66	1.30064
3088.22	1.38013
3090.78	1.11729
3093.33	1.38441
3095.89	2.0771
3098.44	3.10346
3100.99	3.86925
3103.54	4.7679
3106.1	6.34796
3108.65	6.95284
3111.2	8.55117
3113.74	8.87012
3116.29	9.66159
3118.84	10.1905
3121.38	10.8218
3123.93	11.2241
3126.47	11.7369
3129.01	11.4951
3131.56	12.1948
3134.1	13.2693
3136.64	13.9862
3139.18	14.556
3141.72	14.7991
3144.26	14.4391
3146.79	14.5192
3149.33	16.2234