File: data/Raman/poly_smoothed/Thy_30_10_04_1x_45s_532 nm_x100_100%_600 gr_mm_01.txt
#Acq. time (s)=	45
#Accumulations=	2
#Range (cm-¹)=	200...3150
#Windows=	2
#Auto scanning=	Off
#Autofocus=	Off
#Macrospot=	Off
#AutoExposure=	Off
#Spike filter=	Multiple accum.
#Delay time (s)=	0
#Binning=	1
#Readout mode=	Signal
#DeNoise=	Off
#ICS correction=	On
#Dark correction=	Off
#Inst. Process=	Off
#Detector Gain=	Best Dynamic Range
#Detector ADC=	20 kHz
#Detector temperature (°C)=	-69.85
#Instrument=	LabRAM HR Evol
#Detector=	Synapse
#Objective=	x100
#Grating=	600 gr/mm
#ND Filter=	100%
#Laser (nm)=	532
#Hole=	100.021
#Range=	Auto
#Laser Pol.=	No
#Raman. Pol.=	No
#Laser Pol. (°)=	-0.0007625
#Raman Pol. (°)=	89.9995
#Collection=	Microscope
#StageXY=	Marzhauser
#StageZ=	Marzhauser
#X (µm)=	4766
#Y (µm)=	-7735.8
#Z (µm)=	584
#Full time(mm:ss)=	3:18
#Project=
#Sample=
#Site=
#Title=	Thy_30_10_04_2x_45s_532 nm_x100_100%_600 gr_mm
#Remark=
#Date=	30.06.2022 11:40
#Acquired=	30.06.2022 11:40:29
#Base:Fit=	10.08.2022 09:56:48
#Base:Fit=	10.08.2022 09:57:06
#Base:Fit=	10.08.2022 09:57:43
#Base:Fit=	10.08.2022 09:57:50
#Base:Fit=	10.08.2022 09:58:11
#Base:Sub=	10.08.2022 09:58:44
#Filter:Polynom=	16.08.2022 10:22:53
#AxisType[0]=Intens
#AxisUnit[0]=Cnt
#AxisType[1]=Spectr
#AxisUnit[1]=1/cm
200.533	13.4479
204.162	11.0292
207.792	9.82314
211.418	8.02557
215.044	6.84561
218.667	6.48272
222.289	6.22357
225.912	4.95984
229.531	4.72157
233.148	5.74536
236.766	5.40131
240.381	5.03221
243.994	4.4412
247.606	5.1044
251.217	4.83487
254.828	4.68256
258.436	4.39877
262.042	4.06248
265.647	5.43327
269.25	5.10583
272.852	5.94782
276.453	4.77973
280.052	3.81484
283.65	4.55984
287.247	3.48713
290.842	2.30214
294.436	3.69184
298.028	4.14119
301.617	5.16363
305.206	5.83717
308.794	6.93929
312.381	8.54024
315.964	8.35797
319.548	9.46824
323.131	9.86249
326.71	10.0668
330.29	10.3467
333.868	11.3529
337.443	12.5821
341.018	13.6848
344.591	13.1409
348.163	12.4003
351.733	12.4254
355.303	12.079
358.869	11.139
362.435	10.7982
366.001	8.68325
369.563	7.71962
373.124	6.01973
376.686	4.98191
380.244	5.45531
383.801	4.31139
387.357	4.18591
390.911	3.17424
394.466	3.39275
398.018	3.2173
401.568	2.16829
405.117	2.20491
408.664	1.75801
412.21	2.02454
415.755	1.49849
419.298	2.97439
422.84	2.8292
426.38	3.7077
429.919	3.36038
433.455	2.32628
436.992	2.76529
440.527	2.39017
444.06	2.97592
447.593	3.89776
451.122	4.67458
454.651	3.90276
458.18	4.82788
461.705	4.88285
465.23	5.42808
468.752	6.19108
472.275	7.54455
475.797	7.88214
479.315	9.35389
482.834	10.5648
486.349	11.8408
489.863	12.9798
493.378	13.2075
496.889	13.182
500.401	14.1565
503.91	13.7816
507.417	13.371
510.923	13.0432
514.43	12.7599
517.933	11.418
521.435	10.4894
524.936	9.84376
528.435	9.72239
531.933	9.83188
535.43	9.13265
538.927	7.8696
542.421	7.59388
545.913	6.10986
549.403	5.98723
552.893	6.34679
556.381	5.39164
559.868	4.76694
563.354	6.28561
566.839	6.91365
570.322	7.3945
573.802	7.86005
577.283	8.72021
580.762	9.16717
584.24	10.3638
587.714	10.0264
591.19	9.65196
594.663	9.78088
598.134	10.851
601.605	11.0931
605.073	11.4816
608.542	11.3629
612.007	12.6929
615.473	13.7494
618.936	13.8089
622.397	12.5369
625.859	11.0314
629.318	10.5229
632.775	10.7589
636.233	11.6515
639.688	10.6603
643.142	11.0472
646.594	12.3542
650.045	12.7682
653.496	13.7734
656.944	15.6766
660.391	17.788
663.837	18.6667
667.281	20.9912
670.724	24.006
674.166	25.7568
677.606	27.4805
681.045	30.1081
684.483	31.5525
687.917	32.3662
691.352	34.3429
694.786	35.2474
698.219	37.0542
701.65	37.8181
705.078	37.2242
708.506	37.8622
711.934	38.642
715.358	40.0863
718.782	41.4865
722.204	42.3428
725.626	43.1791
729.045	44.5921
732.464	45.7006
735.881	46.5888
739.297	47.9526
742.711	50.5531
746.125	52.6417
749.537	54.9902
752.946	59.4973
756.357	61.0794
759.764	61.9543
763.17	64.6688
766.575	65.067
769.978	67.6493
773.382	70.395
776.783	71.9108
780.182	73.503
783.581	76.4768
786.978	77.4332
790.373	79.4794
793.768	81.2816
797.161	83.026
800.552	85.5553
803.941	85.3042
807.33	86.0634
810.718	84.937
814.105	85.335
817.49	84.2635
820.873	83.7442
824.256	84.868
827.637	84.1387
831.016	83.1486
834.395	83.6441
837.772	82.3888
841.147	80.9328
844.522	78.703
847.894	76.7962
851.267	74.5441
854.637	73.027
858.007	72.3263
861.374	70.0119
864.739	68.823
868.106	68.0703
871.469	67.817
874.831	66.7583
878.193	64.0883
881.553	63.7263
884.911	62.572
888.268	60.4857
891.623	59.8529
894.978	58.6478
898.331	58.8426
901.683	58.1452
905.033	57.7747
908.383	57.3967
911.731	57.8121
915.078	58.9109
918.423	59.6778
921.768	60.1306
925.111	59.8867
928.452	58.9584
931.791	59.0921
935.13	59.9689
938.468	59.7077
941.803	59.7364
945.139	59.1145
948.473	58.5169
951.804	58.9458
955.136	58.3018
958.465	57.0005
961.794	57.5177
965.12	58.6174
968.447	58.1201
971.771	58.0414
975.095	59.5353
978.417	59.6448
981.737	60.378
985.057	60.9452
988.375	60.4877
991.691	59.749
995.006	60.0714
998.32	61.4236
1001.63	62.3905
1004.95	61.7525
1008.26	61.2122
1011.56	60.5307
1014.87	60.6715
1018.18	59.1521
1021.48	58.1011
1024.79	57.5626
1028.09	55.8858
1031.39	56.3679
1034.69	55.865
1037.99	54.877
1041.29	52.9235
1044.58	51.0122
1047.88	49.5074
1051.17	48.315
1054.46	45.2508
1057.75	43.5146
1061.04	40.9642
1064.33	38.7386
1067.62	37.2033
1070.9	35.03
1074.19	34.3733
1077.47	34.747
1080.76	34.9936
1084.04	34.6733
1087.32	35.8378
1090.59	35.0455
1093.87	35.9586
1097.15	36.348
1100.42	37.967
1103.69	38.9358
1106.97	40.5065
1110.24	41.6569
1113.51	42.7549
1116.77	42.3833
1120.04	42.2816
1123.31	41.2447
1126.57	40.131
1129.83	40.2073
1133.1	37.6474
1136.36	36.3967
1139.62	35.3759
1142.87	35.5873
1146.13	33.6712
1149.38	31.8562
1152.64	28.6682
1155.89	25.1988
1159.14	21.8913
1162.39	18.986
1165.64	17.2675
1168.89	14.8205
1172.14	13.6386
1175.38	12.8259
1178.63	11.9758
1181.87	12.2813
1185.11	13.6367
1188.35	14.4752
1191.59	16.0682
1194.83	18.2652
1198.07	19.8966
1201.3	22.98
1204.53	25.7743
1207.77	28.478
1211	31.7887
1214.23	35.5011
1217.46	40.296
1220.69	44.8207
1223.91	47.4431
1227.14	51.1242
1230.36	52.5649
1233.59	54.0239
1236.81	56.042
1240.03	57.4609
1243.25	58.8004
1246.46	60.23
1249.68	62.0558
1252.9	62.7025
1256.11	64.8451
1259.32	66.2426
1262.54	68.4079
1265.75	68.7331
1268.96	68.726
1272.16	69.6733
1275.37	70.0708
1278.57	70.2688
1281.78	70.9104
1284.98	71.4475
1288.18	72.4809
1291.38	72.0655
1294.58	72.8915
1297.78	73.1469
1300.98	73.9218
1304.17	75.2853
1307.37	74.2185
1310.56	74.2652
1313.76	75.3863
1316.95	75.9171
1320.14	75.153
1323.32	75.8865
1326.51	76.7358
1329.7	75.4148
1332.88	75.3509
1336.07	75.0674
1339.25	73.7803
1342.43	70.6617
1345.61	67.0072
1348.79	65.8614
1351.96	63.8751
1355.14	60.582
1358.31	57.7842
1361.49	55.3003
1364.66	52.3201
1367.83	49.2949
1371	46.4264
1374.17	45.3328
1377.34	43.4973
1380.5	43.3252
1383.67	42.5441
1386.83	41.4696
1390	40.7894
1393.16	41.9462
1396.32	40.7421
1399.48	40.3498
1402.64	39.7421
1405.79	38.8452
1408.95	39.0016
1412.1	40.105
1415.26	41.7114
1418.41	43.3304
1421.56	46.073
1424.71	50.1681
1427.86	54.1565
1431	57.7223
1434.15	60.7565
1437.29	66.189
1440.44	69.0951
1443.58	72.4987
1446.72	74.9069
1449.86	76.5513
1453	75.7513
1456.14	74.4077
1459.27	72.4888
1462.41	69.2024
1465.54	65.3739
1468.67	59.3642
1471.81	52.9873
1474.94	47.1118
1478.07	41.1017
1481.19	36.027
1484.32	30.9624
1487.45	25.4369
1490.57	20.3972
1493.69	16.8461
1496.82	14.6752
1499.94	14.0868
1503.06	13.5637
1506.17	13.1482
1509.29	14.83
1512.41	14.1041
1515.52	14.5829
1518.64	15.6324
1521.75	16.8831
1524.86	17.7409
1527.97	18.5863
1531.08	20.6344
1534.19	23.5569
1537.29	25.8916
1540.4	27.4395
1543.5	29.4034
1546.61	32.2694
1549.71	35.2696
1552.81	39.1399
1555.91	41.924
1559.01	44.5234
1562.11	45.6193
1565.2	47.8054
1568.29	50.5655
1571.39	53.1411
1574.48	55.8476
1577.57	57.3637
1580.66	57.8066
1583.75	58.4398
1586.84	60.0072
1589.93	59.9164
1593.01	60.4303
1596.1	59.7194
1599.18	60.0784
1602.26	59.9373
1605.34	59.1874
1608.42	59.62
1611.5	59.1972
1614.58	58.7368
1617.65	59.8687
1620.73	61.2377
1623.8	62.4455
1626.87	65.0271
1629.95	66.1206
1633.02	68.0824
1636.09	70.0297
1639.15	72.1704
1642.22	74.1583
1645.29	76.0542
1648.35	78.4789
1651.42	80.0277
1654.48	81.2265
1657.54	81.7293
1660.6	82.3608
1663.66	79.846
1666.72	76.5134
1669.77	73.8453
1672.83	69.5776
1675.88	66.6782
1678.93	61.1877
1681.99	55.3977
1685.04	48.7713
1688.09	43.606
1691.13	39.0613
1694.18	32.8439
1697.23	27.5931
1700.27	23.7502
1703.32	21.0681
1706.36	18.5052
1709.4	15.8935
1712.44	13.83
1715.48	12.0243
1718.52	11.8778
1721.56	11.397
1724.59	11.3955
1727.63	11.8977
1730.66	11.2384
1733.69	10.8062
1736.72	9.84313
1739.75	10.1866
1742.78	9.80438
1745.81	9.65368
1748.84	8.75045
1751.86	7.54491
1754.89	6.27276
1757.91	5.36648
1760.93	4.41133
1763.95	2.60933
1766.97	1.30777
1769.99	-0.0616489
1773.01	0.486369
1776.03	1.3053
1779.04	1.40033
1782.06	0.24226
1785.07	-0.0683737
1788.08	0.468544
1791.09	0.97116
1794.1	1.91437
1797.11	3.14777
1800.12	4.0027
1803.12	3.96465
1806.13	3.85979
1809.13	3.88009
1812.14	3.16696
1815.14	2.62139
1818.14	2.99649
1821.14	3.50478
1824.14	2.88418
1827.13	2.81312
1830.13	2.5056
1833.12	1.68702
1836.12	1.87042
1839.11	1.34275
1842.1	0.968661
1845.09	1.09576
1848.08	1.60573
1851.07	0.766829
1854.06	0.196558
1857.04	1.17752
1860.03	1.45821
1863.01	1.59291
1866	1.33514
1868.98	1.67302
1871.96	1.95957
1874.94	2.03869
1877.92	1.66646
1880.89	1.31233
1882.48	1.21712
1885.47	1.40593
1888.46	1.68115
1891.44	1.91664
1894.43	2.06903
1897.41	1.56925
1900.4	2.06308
1903.38	2.63681
1906.36	3.83928
1909.34	4.22675
1912.32	3.99266
1915.29	4.62156
1918.27	4.95727
1921.25	4.49378
1924.22	5.17768
1927.2	6.14518
1930.17	5.94701
1933.14	5.07019
1936.11	4.56924
1939.08	4.58439
1942.05	4.8789
1945.01	4.74794
1947.98	5.45556
1950.94	5.07444
1953.91	5.16069
1956.87	5.55938
1959.83	5.34322
1962.79	5.27363
1965.75	5.01899
1968.71	4.72211
1971.67	5.36118
1974.62	5.31163
1977.58	6.23323
1980.53	6.15095
1983.48	6.57815
1986.43	7.15238
1989.38	8.10768
1992.33	7.02726
1995.28	7.14348
1998.23	7.81116
2001.18	7.36829
2004.12	7.17824
2007.06	7.29146
2010.01	7.44029
2012.95	8.87555
2015.89	9.37878
2018.83	9.89306
2021.77	10.7724
2024.71	11.4343
2027.64	11.7281
2030.58	13.1242
2033.51	12.9265
2036.45	12.3196
2039.38	12.4473
2042.31	12.8274
2045.24	14.1935
2048.17	14.9543
2051.1	15.9492
2054.02	16.6278
2056.95	17.5602
2059.87	17.8448
2062.8	17.9818
2065.72	18.7042
2068.64	19.6009
2071.56	19.9086
2074.48	20.9413
2077.4	21.862
2080.31	22.041
2083.23	22.816
2086.14	24.5502
2089.06	24.7772
2091.97	26.0337
2094.88	26.5664
2097.79	26.1207
2100.7	27.4406
2103.61	29.0659
2106.52	30.3398
2109.43	32.2318
2112.33	34.1787
2115.24	36.9277
2118.14	40.3907
2121.04	43.1513
2123.94	46.1677
2126.84	48.4226
2129.74	51.4119
2132.64	54.6272
2135.54	57.4492
2138.43	59.896
2141.33	63.2812
2144.22	65.748
2147.11	69.3649
2150.01	72.2251
2152.9	74.5437
2155.79	77.1784
2158.67	79.9564
2161.56	81.3427
2164.45	82.4961
2167.33	83.0623
2170.22	83.6346
2173.1	84.8734
2175.98	85.0184
2178.86	83.9626
2181.74	83.0913
2184.62	81.3229
2187.5	79.7793
2190.38	78.0146
2193.25	75.41
2196.13	71.594
2199	68.0009
2201.88	64.4995
2204.75	61.0065
2207.62	58.4678
2210.49	55.553
2213.36	53.3219
2216.22	51.621
2219.09	49.2332
2221.96	46.4499
2224.82	43.2748
2227.68	41.0627
2230.55	38.9723
2233.41	36.8801
2236.27	35.5119
2239.12	33.6748
2241.98	31.6303
2244.84	31.033
2247.7	28.782
2250.55	28.0144
2253.41	27.1981
2256.26	26.0892
2259.11	25.2301
2261.96	24.9697
2264.81	23.6364
2267.66	22.6232
2270.51	22.7192
2273.35	21.7864
2276.2	21.688
2279.04	21.2912
2281.89	20.5869
2284.73	19.7488
2287.57	18.2561
2290.41	15.6094
2293.25	13.5863
2296.09	13.1562
2298.93	13.6594
2301.76	14.0623
2304.6	14.2348
2307.44	14.3551
2310.27	14.9492
2313.1	16.2312
2315.93	17.3892
2318.76	17.6335
2321.59	17.8957
2324.42	18.1618
2327.25	18.4002
2330.07	18.3664
2332.9	18.3059
2335.72	17.8252
2338.55	17.2004
2341.37	17.1102
2344.19	15.3436
2347.01	13.9342
2349.83	11.8328
2352.65	11.2546
2355.46	10.4081
2358.28	8.89791
2361.09	8.37901
2363.91	7.63858
2366.72	8.07926
2369.53	7.48092
2372.34	7.26364
2375.15	8.40781
2377.96	9.04923
2380.77	9.78792
2383.58	9.99619
2386.38	9.25513
2389.19	9.16306
2391.99	8.68041
2394.8	8.68949
2397.6	8.05255
2400.4	7.83747
2403.2	7.2441
2406	7.76982
2408.79	7.50443
2411.59	7.61913
2414.39	9.1669
2417.18	9.22642
2419.98	10.9923
2422.77	11.3956
2425.56	11.3732
2428.35	10.2211
2431.14	9.49356
2433.93	9.08175
2436.72	9.37885
2439.5	9.24367
2442.29	9.666
2445.07	10.0437
2447.86	9.04263
2450.64	8.9814
2453.42	8.09275
2456.2	7.52681
2458.98	6.6177
2461.76	6.16694
2464.54	5.30579
2467.32	5.11299
2470.09	4.78196
2472.87	4.84393
2475.64	5.15144
2478.41	4.81802
2481.18	4.89958
2483.95	4.99671
2486.72	3.87028
2489.49	4.33318
2492.26	3.70401
2495.03	3.95867
2497.79	3.80251
2500.56	3.85224
2503.32	3.55021
2506.09	3.33983
2508.85	2.7007
2511.61	3.04042
2514.37	2.449
2517.13	2.11392
2519.89	2.01949
2522.64	1.7054
2525.4	1.66867
2528.15	1.64049
2530.91	1.12603
2533.66	1.58742
2536.41	0.77272
2539.16	0.883214
2541.91	0.215382
2544.66	-0.0361647
2547.41	-0.621265
2550.16	-0.705664
2552.9	-0.107552
2555.65	0.247841
2558.39	0.902511
2561.13	1.35949
2563.88	1.61655
2566.62	1.55616
2569.36	2.07193
2572.1	1.83515
2574.84	2.39346
2577.57	2.84622
2580.31	2.90496
2583.05	2.54848
2585.78	2.38823
2588.51	2.85398
2591.24	2.68401
2593.98	2.09981
2596.71	1.5075
2599.44	2.17871
2602.16	1.61656
2604.89	1.74966
2607.62	1.4944
2610.34	1.00453
2613.07	1.09364
2615.79	0.644371
2618.52	0.588304
2621.24	1.00562
2623.96	0.61526
2626.68	0.829581
2629.4	0.693734
2632.11	1.69436
2634.83	2.21044
2637.55	1.92374
2640.26	2.06626
2642.98	2.46343
2645.69	2.54657
2648.4	2.61377
2651.11	2.10623
2653.82	1.73004
2656.53	1.37614
2659.24	0.327342
2661.95	0.292645
2664.65	1.03239
2667.36	0.906744
2670.06	1.6598
2672.76	1.46265
2675.47	1.22898
2678.17	0.738478
2680.87	1.262
2683.57	1.43235
2686.27	0.753093
2688.97	0.62498
2691.66	0.171806
2694.36	0.663432
2697.05	0.496287
2699.75	1.22001
2702.44	1.71217
2705.13	1.86966
2707.82	2.85216
2710.51	3.06154
2713.2	3.80328
2715.89	4.13141
2718.57	4.68462
2721.26	4.93223
2723.95	4.87329
2726.63	5.82494
2729.31	6.40541
2732	6.33877
2734.68	6.17995
2737.36	5.91692
2740.04	5.89459
2742.72	6.08756
2745.39	6.95108
2748.07	6.61635
2750.75	5.72608
2753.42	5.03924
2756.09	5.71117
2758.77	5.32359
2761.44	4.81877
2764.11	4.95102
2766.78	4.89616
2769.45	4.65803
2772.12	4.43975
2774.78	4.13285
2777.45	4.54393
2780.12	4.044
2782.78	3.76913
2785.44	3.27251
2788.11	3.08891
2790.77	2.5909
2793.43	2.06886
2796.09	1.10719
2798.75	1.03807
2801.4	1.55798
2804.06	1.77685
2806.72	2.56667
2809.37	2.48928
2812.03	2.11966
2814.68	2.17527
2817.33	3.41723
2819.98	4.43184
2822.63	7.10587
2825.28	10.9238
2827.93	15.2632
2830.58	19.539
2833.23	23.5566
2835.87	28.8685
2838.52	34.2465
2841.16	40.4286
2843.8	47.239
2846.44	53.9
2849.08	62.5544
2851.73	72.2988
2854.36	81.3827
2857	90.2593
2859.64	99.2612
2862.28	109.167
2864.91	116.937
2867.55	124.766
2870.18	131.8
2872.81	137.559
2875.44	142.022
2878.07	146.265
2880.7	151.092
2883.33	155.952
2885.96	160.74
2888.59	165.44
2891.21	170.552
2893.84	174.611
2896.46	179.785
2899.09	185.146
2901.71	192.642
2904.33	201.189
2906.95	212.29
2909.57	223.542
2912.19	235.463
2914.81	247.936
2917.43	258.464
2920.04	268.597
2922.66	275.089
2925.27	281.977
2927.88	287.096
2930.5	288.667
2933.11	288.646
2935.72	286.299
2938.33	281.479
2940.94	275.42
2943.54	267.532
2946.15	259.267
2948.76	249.587
2951.36	238.102
2953.97	227.751
2956.57	216.685
2959.17	206.038
2961.77	195.691
2964.37	186.625
2966.97	178.27
2969.57	169.695
2972.17	161.08
2974.77	152.715
2977.36	143.943
2979.96	135.159
2982.55	125.716
2985.15	116.51
2987.74	107.325
2990.33	98.7637
2992.92	89.8598
2995.51	80.983
2998.1	73.1223
3000.69	65.6926
3003.27	59.5853
3005.86	53.1143
3008.44	47.4144
3011.03	42.4235
3013.61	37.9075
3016.19	34.6147
3018.78	31.4848
3021.36	29.6331
3023.94	27.9698
3026.51	27.034
3029.09	25.7801
3031.67	25.3998
3034.24	24.783
3036.82	25.3562
3039.39	25.6697
3041.97	26.2518
3044.54	27.3372
3047.11	28.3427
3049.68	29.0724
3052.25	29.7511
3054.82	29.8657
3057.39	29.3616
3059.96	28.0043
3062.52	27.6926
3065.09	25.5004
3067.65	24.5745
3070.22	22.2518
3072.78	20.6085
3075.34	18.15
3077.9	15.7862
3080.46	14.7314
3083.02	12.6017
3085.58	10.9356
3088.14	9.37831
3090.69	8.16793
3093.25	7.89351
3095.8	6.74137
3098.36	6.79657
3100.91	6.01066
3103.46	5.64547
3106.01	5.87941
3108.56	5.65585
3111.11	5.10506
3113.66	4.14129
3116.21	4.09451
3118.76	3.58843
3121.3	3.14034
3123.85	3.22943
3126.39	3.06445
3128.93	3.14779
3131.48	3.69162
3134.02	3.28276
3136.56	3.02328
3139.1	3.14542
3141.64	4.30337
3144.17	5.6481
3146.71	7.34212
3149.25	9.52282