File: data/Raman/poly_smoothed/Thy_10_08_24_1x_45s_532 nm_x100_100%_600 gr_mm_01.txt
#Acq. time (s)=	45
#Accumulations=	2
#Range (cm-¹)=	200...3150
#Windows=	2
#Auto scanning=	Off
#Autofocus=	Off
#Macrospot=	Off
#AutoExposure=	Off
#Spike filter=	Multiple accum.
#Delay time (s)=	0
#Binning=	1
#Readout mode=	Signal
#DeNoise=	Off
#ICS correction=	On
#Dark correction=	Off
#Inst. Process=	Off
#Detector Gain=	Best Dynamic Range
#Detector ADC=	20 kHz
#Detector temperature (°C)=	-69.85
#Instrument=	LabRAM HR Evol
#Detector=	Synapse
#Objective=	x100
#Grating=	600 gr/mm
#ND Filter=	100%
#Laser (nm)=	532
#Hole=	100.021
#Range=	Auto
#Laser Pol.=	No
#Raman. Pol.=	No
#Laser Pol. (°)=	-0.0007625
#Raman Pol. (°)=	89.9995
#Collection=	Microscope
#StageXY=	Marzhauser
#StageZ=	Marzhauser
#X (µm)=	2207.5
#Y (µm)=	1221.7
#Z (µm)=	442.65
#Full time(mm:ss)=	3:18
#Project=
#Sample=
#Site=
#Title=	Thy_10_08_24_2x_45s_532 nm_x100_100%_600 gr_mm
#Remark=
#Date=	05.07.2022 15:55
#Acquired=	05.07.2022 15:55:01
#Base:Fit=	10.08.2022 09:46:25
#Base:Sub=	10.08.2022 09:46:49
#Filter:Polynom=	16.08.2022 10:24:56
#AxisType[0]=Intens
#AxisUnit[0]=Cnt
#AxisType[1]=Spectr
#AxisUnit[1]=1/cm
200.43	-0.150102
204.059	3.37104
207.688	9.00306
211.314	11.6833
214.941	13.1108
218.564	14.477
222.186	15.8161
225.809	15.9048
229.428	14.2479
233.045	13.2728
236.663	13.5345
240.278	13.2649
243.891	13.2646
247.503	12.8096
251.116	10.6818
254.725	9.02825
258.333	9.30059
261.939	9.71838
265.544	10.2996
269.148	11.3367
272.75	9.4485
276.351	10.6549
279.95	11.0447
283.548	11.1429
287.144	9.97177
290.739	10.6105
294.333	12.241
297.925	11.9827
301.514	14.2255
305.104	15.803
308.692	15.7579
312.279	17.4072
315.862	14.006
319.446	14.0075
323.029	14.6811
326.608	14.8795
330.188	16.4906
333.766	15.8012
337.341	14.4637
340.917	14.4439
344.489	15.039
348.062	14.8429
351.631	14.4708
355.201	13.5585
358.768	10.9367
362.333	8.53219
365.899	6.43572
369.462	5.5863
373.023	4.69315
376.585	5.14583
380.143	6.49022
383.7	7.11776
387.256	8.46393
390.812	7.79461
394.365	7.27805
397.916	6.60923
401.467	4.57449
405.015	4.96365
408.563	5.61533
412.109	4.93806
415.654	5.8324
419.197	6.72834
422.739	7.94754
426.279	7.71746
429.819	9.19006
433.356	7.1932
436.891	7.35572
440.426	7.84403
443.96	6.8242
447.492	6.32359
451.021	6.78779
454.551	7.08264
458.079	7.87222
461.604	9.76588
465.13	10.5924
468.654	11.4884
472.175	12.8474
475.696	11.8307
479.215	11.7926
482.733	11.0686
486.249	10.626
489.765	11.5763
493.278	12.4446
496.789	13.9164
500.301	14.8492
503.81	16.8675
507.317	18.2501
510.825	17.6668
514.33	17.7849
517.833	16.9375
521.335	15.6125
524.836	15.7675
528.335	14.4534
531.835	13.489
535.332	12.7925
538.827	10.1335
542.321	9.99358
545.814	9.20752
549.305	9.05621
552.795	7.94728
556.282	8.23524
559.769	6.60918
563.255	6.9544
566.739	6.98583
570.223	6.24042
573.705	6.7568
577.183	6.71168
580.663	6.6792
584.141	6.97788
587.615	7.33156
591.09	6.87857
594.564	6.39043
598.035	6.47523
601.506	7.0746
604.974	7.10323
608.443	7.49947
611.908	7.0681
615.374	8.43078
618.837	8.62187
622.3	9.77491
625.761	13.1449
629.219	15.3905
632.677	16.4679
636.135	18.6716
639.59	19.7475
643.043	21.2672
646.495	22.5518
649.948	23.8302
653.398	24.5299
656.846	24.6358
660.293	26.0164
663.738	25.021
667.183	24.2799
670.626	26.2316
674.067	25.6362
677.508	24.8196
680.947	25.6951
684.385	28.0087
687.821	28.273
691.254	29.6299
694.688	29.5126
698.121	32.1579
701.552	32.9182
704.98	34.5533
708.409	37.9822
711.836	40.2962
715.26	41.8168
718.685	43.1126
722.108	45.7702
725.528	46.8245
728.949	49.9407
732.367	51.8018
735.785	53.9123
739.2	55.8753
742.614	57.9422
746.028	61.3878
749.439	64.7435
752.849	67.4504
756.26	70.1329
759.667	71.9492
763.073	74.2819
766.477	77.5434
769.883	78.9514
773.285	80.7108
776.686	83.0534
780.085	84.5335
783.484	86.6888
786.881	88.6653
790.276	90.4868
793.671	91.6447
797.064	94.103
800.456	94.5497
803.846	95.9279
807.234	95.8593
810.622	95.392
814.008	95.5683
817.394	96.7453
820.778	97.0046
824.159	98.3361
827.541	99.7348
830.921	100.66
834.298	97.6496
837.676	95.6608
841.051	93.756
844.426	90.9575
847.798	90.6104
851.171	88.2547
854.54	87.0412
857.911	85.4077
861.278	84.0233
864.645	79.9561
868.01	78.0571
871.373	75.7619
874.735	75.7378
878.097	73.5234
881.457	70.6256
884.815	66.5933
888.172	66.5623
891.528	64.812
894.882	65.0401
898.237	66.0119
901.589	66.362
904.94	65.1751
908.289	64.1137
911.635	61.1674
914.982	59.5176
918.328	57.9976
921.672	59.0194
925.015	60.0774
928.357	60.151
931.698	58.8243
935.035	59.7568
938.373	59.3539
941.71	58.2959
945.044	58.0361
948.378	56.8292
951.709	57.9677
955.041	57.939
958.372	56.8215
961.699	52.9754
965.027	53.9243
968.352	57.0833
971.676	61.4429
975	64.6852
978.322	66.6366
981.642	68.129
984.962	69.4135
988.28	68.6161
991.596	67.497
994.911	67.6098
998.227	66.9604
1001.54	66.9536
1004.85	66.9686
1008.16	64.9857
1011.47	63.2153
1014.78	61.7692
1018.08	60.1189
1021.39	57.2984
1024.69	52.9366
1028	49.2655
1031.3	46.3996
1034.6	44.0071
1037.9	42.3825
1041.19	39.4227
1044.49	38.9335
1047.78	41.118
1051.08	42.151
1054.37	41.6199
1057.66	40.0185
1060.95	39.9903
1064.24	39.3167
1067.53	38.3083
1070.81	36.7771
1074.1	36.8141
1077.38	37.6748
1080.66	36.9665
1083.94	37.4819
1087.22	38.4069
1090.5	38.1655
1093.78	37.8202
1097.05	39.0363
1100.33	38.1265
1103.6	37.3205
1106.87	37.1552
1110.14	36.9362
1113.41	37.1477
1116.68	36.1202
1119.95	32.9258
1123.21	31.4316
1126.48	30.6106
1129.74	28.5386
1133	27.6423
1136.26	25.5153
1139.52	23.7127
1142.78	24.2213
1146.04	22.3408
1149.29	20.4948
1152.55	20.0058
1155.8	21.2546
1159.05	20.6125
1162.3	20.4271
1165.55	20.1878
1168.8	21.5223
1172.05	23.3575
1175.29	25.7427
1178.54	27.5672
1181.78	27.9117
1185.02	28.6733
1188.26	28.7335
1191.5	28.2668
1194.74	28.4315
1197.97	28.9896
1201.21	31.9359
1204.44	35.4959
1207.68	39.0084
1210.91	41.6277
1214.14	46.0007
1217.37	51.9377
1220.59	56.2423
1223.82	60.0445
1227.05	62.9242
1230.27	66.7078
1233.49	69.6095
1236.72	72.2026
1239.94	74.5904
1243.16	76.1151
1246.37	77.4566
1249.59	78.7994
1252.8	78.7834
1256.02	77.092
1259.23	76.744
1262.44	74.7644
1265.66	76.3052
1268.86	74.8379
1272.07	74.9263
1275.28	75.9588
1278.48	77.9878
1281.69	79.4124
1284.89	81.0712
1288.09	82.3415
1291.29	85.8355
1294.49	89.0926
1297.69	90.7107
1300.89	93.9788
1304.08	95.76
1307.28	96.2331
1310.47	98.2239
1313.66	101.938
1316.85	103.278
1320.04	103.971
1323.23	105.11
1326.42	105.218
1329.61	103.879
1332.79	101.966
1335.97	101.72
1339.16	100.049
1342.34	98.2632
1345.52	96.4139
1348.7	92.8357
1351.87	90.1597
1355.05	88.4171
1358.22	85.4552
1361.4	82.8688
1364.57	79.0308
1367.74	75.2885
1370.91	71.759
1374.08	68.7118
1377.25	66.0679
1380.41	63.4266
1383.58	60.3005
1386.74	57.672
1389.91	58.0255
1393.07	56.2261
1396.23	54.8
1399.39	52.6324
1402.55	51.9213
1405.7	50.6786
1408.86	50.7274
1412.01	52.5231
1415.17	54.908
1418.32	59.4096
1421.47	64.8406
1424.62	71.1987
1427.77	77.1596
1430.91	83.5992
1434.06	91.4709
1437.2	96.8727
1440.35	101.408
1443.49	104.403
1446.63	105.943
1449.77	107.608
1452.91	105.965
1456.05	103.264
1459.18	99.3167
1462.32	94.6249
1465.45	88.4677
1468.59	80.0678
1471.72	71.3881
1474.85	63.1465
1477.98	55.581
1481.1	48.7519
1484.23	42.0851
1487.36	35.9473
1490.48	31.2014
1493.61	29.083
1496.73	25.528
1499.85	22.7339
1502.97	21.7365
1506.09	20.3977
1509.2	20.4461
1512.32	20.6189
1515.43	20.4029
1518.55	21.5749
1521.66	23.7213
1524.77	25.1473
1527.88	25.9644
1530.99	26.2876
1534.1	28.5251
1537.21	30.4035
1540.31	32.4707
1543.42	33.9822
1546.52	36.4326
1549.62	41.0022
1552.72	44.718
1555.82	49.0403
1558.92	52.8665
1562.02	55.1503
1565.11	58.2121
1568.21	61.6615
1571.3	62.99
1574.39	64.7864
1577.49	67.8595
1580.57	69.5919
1583.66	71.0281
1586.75	73.1835
1589.84	76.23
1592.92	76.5281
1596.01	76.9039
1599.09	76.5152
1602.17	75.8629
1605.25	73.8548
1608.33	72.7777
1611.41	71.3928
1614.49	70.5748
1617.57	69.7498
1620.64	71.1469
1623.72	73.3419
1626.79	76.1157
1629.86	78.9499
1632.93	82.0105
1636	83.936
1639.07	87.0772
1642.13	91.4568
1645.2	94.9202
1648.26	98.9531
1651.33	101.653
1654.39	104.261
1657.45	105.734
1660.51	106.951
1663.57	105.051
1666.63	102.852
1669.68	98.4232
1672.74	95.0618
1675.79	89.3596
1678.85	81.8766
1681.9	75.817
1684.95	66.7842
1688	59.8903
1691.05	53.987
1694.09	48.0357
1697.14	41.4097
1700.18	35.8511
1703.23	31.0363
1706.27	26.4242
1709.31	21.4159
1712.35	18.8653
1715.39	16.2694
1718.43	13.1184
1721.47	11.5913
1724.5	9.48991
1727.54	7.74086
1730.57	7.17821
1733.61	5.5354
1736.64	5.86683
1739.67	4.02376
1742.7	3.75125
1745.72	2.69942
1748.75	1.92282
1751.77	1.0995
1754.8	0.253861
1757.82	-0.847576
1760.84	-1.78549
1763.87	-0.971457
1766.89	0.0748482
1769.91	-0.946742
1772.92	-1.29113
1775.94	-0.586149
1778.95	-0.417654
1781.97	-1.17608
1784.98	-1.07024
1787.99	-0.687902
1791.01	-0.445862
1794.01	0.896094
1797.02	1.27526
1800.03	1.31799
1803.04	1.34848
1806.04	2.02598
1809.05	2.39728
1812.05	3.49877
1815.05	3.61163
1818.05	3.79185
1821.05	2.22188
1824.05	2.26649
1827.05	1.88355
1830.04	2.03357
1833.04	3.02365
1836.03	2.90293
1839.03	3.63497
1842.02	3.88067
1845.01	3.50499
1848	3.3312
1850.99	4.09007
1853.97	4.53715
1856.96	4.51019
1859.94	5.50546
1862.93	5.87048
1865.91	6.35053
1868.89	7.17782
1871.87	7.30094
1874.85	6.79774
1877.83	7.55785
1880.81	8.3263
1882.57	8.69859
1885.56	8.6297
1888.55	8.63675
1891.54	8.5803
1894.52	8.95896
1897.51	9.06858
1900.49	10.342
1903.47	10.5039
1906.45	10.6945
1909.43	10.2199
1912.41	10.0608
1915.39	9.682
1918.37	9.55384
1921.34	10.4229
1924.32	11.0691
1927.29	10.089
1930.26	10.0983
1933.23	9.82307
1936.2	9.90814
1939.17	10.3497
1942.14	9.45564
1945.11	8.70513
1948.07	7.64242
1951.04	7.22094
1954	7.76328
1956.96	7.78368
1959.93	8.34128
1962.89	9.77657
1965.85	9.23625
1968.8	9.08417
1971.76	8.98734
1974.72	8.76216
1977.67	8.20696
1980.63	8.0332
1983.58	8.64092
1986.53	8.74304
1989.48	9.25999
1992.43	9.4174
1995.38	9.07012
1998.32	9.41271
2001.27	8.29257
2004.22	9.54354
2007.16	9.81666
2010.1	9.89836
2013.04	10.9368
2015.98	11.0376
2018.92	11.2548
2021.86	11.1543
2024.8	11.5284
2027.74	11.8274
2030.67	12.7637
2033.61	13.3619
2036.54	13.1528
2039.47	12.4075
2042.4	12.3334
2045.33	12.3126
2048.26	11.7817
2051.19	12.0742
2054.12	12.524
2057.04	13.1181
2059.97	12.7801
2062.89	12.5783
2065.81	12.7596
2068.73	13.2652
2071.65	13.8512
2074.57	14.5663
2077.49	15.2742
2080.41	16.5861
2083.32	17.7315
2086.24	18.6263
2089.15	18.1211
2092.07	18.0933
2094.98	18.5361
2097.89	19.8956
2100.8	20.2746
2103.71	21.4896
2106.61	21.3939
2109.52	22.1816
2112.43	23.2254
2115.33	23.3723
2118.23	23.5486
2121.13	24.1662
2124.04	25.1133
2126.94	25.9346
2129.83	26.9521
2132.73	28.3895
2135.63	29.9043
2138.53	30.8531
2141.42	32.3931
2144.31	34.2418
2147.21	36.618
2150.1	39.1773
2152.99	40.2576
2155.88	41.4311
2158.77	42.6793
2161.65	44.3705
2164.54	45.9727
2167.43	47.0889
2170.31	47.738
2173.19	48.4664
2176.07	48.4827
2178.96	48.831
2181.84	48.533
2184.72	46.8719
2187.59	46.005
2190.47	45.4178
2193.35	43.8762
2196.22	42.4249
2199.09	41.0254
2201.97	39.575
2204.84	37.4163
2207.71	35.8292
2210.58	34.1761
2213.45	33.4421
2216.31	32.3116
2219.18	31.3688
2222.05	29.8517
2224.91	28.827
2227.78	28.0331
2230.64	27.539
2233.5	26.5936
2236.36	25.6696
2239.22	25.2069
2242.08	24.4818
2244.93	24.343
2247.79	25.0168
2250.64	23.8883
2253.5	22.9285
2256.35	22.8447
2259.2	22.8529
2262.05	22.5197
2264.9	21.9019
2267.75	21.34
2270.6	21.4476
2273.45	19.5627
2276.29	18.9241
2279.14	18.3046
2281.98	17.5871
2284.82	18.3297
2287.66	17.9004
2290.5	17.2414
2293.34	16.5064
2296.18	16.2951
2299.02	16.3892
2301.86	16.5932
2304.69	15.7888
2307.53	15.6068
2310.36	15.3817
2313.19	15.8677
2316.02	14.9346
2318.85	13.1292
2321.68	12.3122
2324.51	11.6865
2327.34	10.8901
2330.16	9.73929
2332.99	9.37127
2335.81	8.61898
2338.64	7.65634
2341.46	6.98519
2344.28	6.00389
2347.1	6.40283
2349.92	5.74329
2352.74	5.47697
2355.55	5.28587
2358.37	5.12364
2361.19	4.19143
2364	3.72932
2366.81	4.51128
2369.62	4.86002
2372.44	3.52935
2375.24	3.53351
2378.05	3.04089
2380.86	3.2686
2383.67	3.14145
2386.47	2.01778
2389.28	1.97709
2392.08	2.3249
2394.89	1.53845
2397.69	2.19156
2400.49	3.53098
2403.29	5.25845
2406.09	5.93109
2408.88	7.84169
2411.68	8.7546
2414.48	8.85262
2417.27	9.52886
2420.06	9.27466
2422.86	10.7237
2425.65	10.8004
2428.44	11.2041
2431.23	9.58638
2434.02	9.11973
2436.81	9.04787
2439.59	7.57891
2442.38	6.6483
2445.16	5.6358
2447.95	4.53953
2450.73	3.29102
2453.51	3.33056
2456.29	2.14614
2459.07	1.82022
2461.85	0.895666
2464.63	0.113197
2467.4	0.831507
2470.18	0.623097
2472.95	1.33893
2475.73	1.17011
2478.5	0.709579
2481.27	0.411196
2484.04	0.252088
2486.81	1.90543
2489.58	2.02402
2492.35	2.40769
2495.12	1.5854
2497.88	1.36435
2500.65	0.374128
2503.41	0.49118
2506.17	-0.439088
2508.94	-0.423469
2511.7	0.29859
2514.46	0.196158
2517.22	0.638397
2519.97	0.849472
2522.73	2.07884
2525.49	1.84011
2528.24	1.58074
2530.99	0.959658
2533.75	1.52965
2536.5	2.41085
2539.25	2.07279
2542	1.43041
2544.75	2.10574
2547.5	2.56471
2550.24	2.51324
2552.99	3.44782
2555.74	3.92425
2558.48	3.348
2561.22	3.39326
2563.96	3.69195
2566.71	3.58843
2569.45	4.38159
2572.18	3.54454
2574.92	3.88854
2577.66	4.18966
2580.4	3.2641
2583.13	3.0435
2585.87	3.35607
2588.6	2.95947
2591.33	3.18704
2594.06	3.44471
2596.79	2.65992
2599.52	2.10967
2602.25	2.18086
2604.98	2.10829
2607.71	1.55776
2610.43	0.993454
2613.16	1.12054
2615.88	0.704671
2618.6	1.07868
2621.32	1.08566
2624.04	1.90572
2626.76	1.7254
2629.48	2.58975
2632.2	3.36276
2634.92	3.56941
2637.63	4.22853
2640.35	3.97733
2643.06	5.07926
2645.77	4.4098
2648.49	3.94365
2651.2	4.62188
2653.91	4.25826
2656.62	3.4003
2659.33	3.55273
2662.03	2.8241
2664.74	2.72612
2667.44	2.42467
2670.15	2.32961
2672.85	1.72235
2675.55	2.09974
2678.26	2.17434
2680.96	2.76012
2683.66	3.15181
2686.35	4.68294
2689.05	5.03142
2691.75	6.62153
2694.44	7.78587
2697.14	9.09444
2699.83	11.455
2702.52	13.2495
2705.22	15.4612
2707.91	16.9944
2710.6	18.2562
2713.29	19.4896
2715.97	20.7036
2718.66	21.711
2721.35	22.0974
2724.03	23.3414
2726.72	24.4285
2729.4	24.3041
2732.08	24.9089
2734.76	24.6796
2737.44	23.7617
2740.12	23.2236
2742.8	21.191
2745.48	20.7915
2748.16	20.1761
2750.83	19.0745
2753.51	18.1848
2756.18	16.4721
2758.85	15.4675
2761.53	13.8048
2764.2	13.5983
2766.87	13.7593
2769.54	13.756
2772.2	13.6123
2774.87	13.1159
2777.54	13.48
2780.2	13.0763
2782.87	12.4074
2785.53	12.11
2788.19	12.1301
2790.85	11.2354
2793.51	10.7961
2796.17	10.1571
2798.83	10.3414
2801.49	9.84952
2804.15	10.0149
2806.8	10.361
2809.46	11.0991
2812.11	12.0916
2814.76	11.1823
2817.42	11.8096
2820.07	12.6688
2822.72	14.5959
2825.37	18.7251
2828.02	24.1951
2830.66	30.2353
2833.31	36.6224
2835.96	44.1238
2838.6	50.1557
2841.24	59.6122
2843.89	69.3138
2846.53	80.7061
2849.17	93.4086
2851.81	106.884
2854.45	120.667
2857.09	134.998
2859.72	149.83
2862.36	164.297
2865	177.367
2867.63	188.635
2870.26	199.175
2872.9	208.652
2875.53	216.206
2878.16	221.129
2880.79	227.37
2883.42	232.948
2886.05	239.211
2888.67	245.507
2891.3	251.478
2893.92	258.219
2896.55	265.36
2899.17	274.287
2901.79	283.787
2904.42	296.263
2907.04	311.391
2909.66	328.32
2912.27	346.006
2914.89	363.167
2917.51	380.065
2920.13	396.307
2922.74	409.767
2925.35	419.218
2927.97	425.537
2930.58	429.162
2933.19	429.976
2935.8	427.165
2938.41	421.586
2941.02	413.157
2943.63	403.902
2946.24	392.296
2948.84	378.945
2951.45	364.45
2954.05	349.303
2956.65	333.071
2959.26	318.51
2961.86	303.335
2964.46	289.636
2967.06	275.984
2969.66	263.769
2972.25	251.976
2974.85	240.7
2977.45	228.408
2980.04	215.983
2982.64	204.143
2985.23	190.595
2987.82	176.697
2990.41	163.011
2993	149.956
2995.59	137.474
2998.18	125.814
3000.77	115.752
3003.36	105.008
3005.94	95.0175
3008.53	85.4586
3011.11	77.5616
3013.69	69.9322
3016.28	62.3748
3018.86	56.7645
3021.44	51.4073
3024.02	47.3791
3026.6	43.7679
3029.18	40.6134
3031.75	38.4817
3034.33	37.3454
3036.9	37.8279
3039.48	38.4036
3042.05	39.2143
3044.62	40.0502
3047.19	42.6274
3049.77	44.4804
3052.34	45.9945
3054.9	46.3754
3057.47	47.0551
3060.04	46.5486
3062.61	46.2929
3065.17	45.2573
3067.74	43.0881
3070.3	39.9702
3072.86	37.7773
3075.42	34.7456
3077.99	30.5247
3080.54	26.7024
3083.1	23.0445
3085.66	19.0311
3088.22	16.0302
3090.78	13.0575
3093.33	9.79231
3095.89	8.20792
3098.44	6.38902
3100.99	5.60429
3103.54	4.23987
3106.1	3.28481
3108.65	2.7304
3111.2	1.90375
3113.74	1.77366
3116.29	1.23636
3118.84	0.398719
3121.38	-0.104569
3123.93	-0.50613
3126.47	0.00122437
3129.01	-0.774583
3131.56	-1.19901
3134.1	-0.800216
3136.64	-0.21671
3139.18	0.32999
3141.72	0.621528
3144.26	1.48125
3146.79	2.25742
3149.33	3.31463