File: data/Raman/poly_smoothed/Thy_40_11_26_1x_45s_532 nm_x100_100%_600 gr_mm_01.txt
#Acq. time (s)=	45
#Accumulations=	2
#Range (cm-¹)=	200...3150
#Windows=	2
#Auto scanning=	Off
#Autofocus=	Off
#Macrospot=	Off
#AutoExposure=	Off
#Spike filter=	Multiple accum.
#Delay time (s)=	0
#Binning=	1
#Readout mode=	Signal
#DeNoise=	Off
#ICS correction=	On
#Dark correction=	Off
#Inst. Process=	Off
#Detector Gain=	Best Dynamic Range
#Detector ADC=	20 kHz
#Detector temperature (°C)=	-69.85
#Instrument=	LabRAM HR Evol
#Detector=	Synapse
#Objective=	x100
#Grating=	600 gr/mm
#ND Filter=	100%
#Laser (nm)=	532
#Hole=	100.021
#Range=	Auto
#Laser Pol.=	No
#Raman. Pol.=	No
#Laser Pol. (°)=	-0.0007625
#Raman Pol. (°)=	89.9995
#Collection=	Microscope
#StageXY=	Marzhauser
#StageZ=	Marzhauser
#X (µm)=	1940.1
#Y (µm)=	-57.1
#Z (µm)=	425.2
#Full time(mm:ss)=	3:19
#Project=
#Sample=
#Site=
#Title=	Thy_40_11_26_2x_45s_532 nm_x100_100%_600 gr_mm
#Remark=
#Date=	05.07.2022 11:42
#Acquired=	05.07.2022 11:42:25
#Base:Fit=	10.08.2022 10:01:35
#Base:Sub=	10.08.2022 10:01:52
#Filter:Polynom=	16.08.2022 10:21:53
#AxisType[0]=Intens
#AxisUnit[0]=Cnt
#AxisType[1]=Spectr
#AxisUnit[1]=1/cm
200.43	25.4619
204.059	21.6428
207.688	19.0208
211.314	15.8813
214.941	12.6196
218.564	11.0498
222.186	7.75314
225.809	5.83117
229.428	5.23987
233.045	4.37138
236.663	3.59105
240.278	3.53296
243.891	2.48263
247.503	2.3776
251.116	2.319
254.725	1.23703
258.333	0.964165
261.939	2.14607
265.544	3.39253
269.148	3.90793
272.75	3.36086
276.351	3.57781
279.95	4.51987
283.548	6.03466
287.144	6.74743
290.739	5.63816
294.333	6.76865
297.925	8.63924
301.514	7.99787
305.104	9.91496
308.692	10.6826
312.279	11.9528
315.862	11.9625
319.446	13.8675
323.029	12.6265
326.608	12.4013
330.188	12.1555
333.766	11.9535
337.341	11.2144
340.917	9.39206
344.489	9.36942
348.062	9.44978
351.631	8.36762
355.201	8.03062
358.768	6.42805
362.333	6.47095
365.899	5.99914
369.462	5.08358
373.023	5.14144
376.585	3.96964
380.143	5.11346
383.7	3.73046
387.256	3.78981
390.812	3.53817
394.365	3.23887
397.916	2.62298
401.467	2.49525
405.015	0.819889
408.563	1.09944
412.109	0.497196
415.654	0.10249
419.197	-0.807951
422.739	0.115728
426.279	0.307841
429.819	1.48424
433.356	1.9009
436.891	0.858315
440.426	0.246358
443.96	1.09716
447.492	0.214741
451.021	2.26324
454.551	3.02654
458.079	3.43034
461.604	5.09234
465.13	6.18674
468.654	6.5006
472.175	7.15957
475.696	9.04558
479.215	10.1622
482.733	11.6483
486.249	12.4993
489.765	15.0923
493.278	16.985
496.789	19.1364
500.301	19.796
503.81	20.8345
507.317	20.9128
510.825	21.0732
514.33	21.3504
517.833	20.6437
521.335	19.1471
524.836	18.2095
528.335	16.2268
531.835	14.2062
535.332	11.4495
538.827	11.8836
542.321	9.4874
545.814	8.0957
549.305	6.79209
552.795	6.11881
556.282	3.18689
559.769	3.58616
563.255	2.35919
566.739	3.12013
570.223	2.73935
573.705	3.19397
577.183	2.94643
580.663	3.30093
584.141	3.31972
587.615	4.51736
591.09	4.91257
594.564	5.82653
598.035	5.88778
601.506	6.91558
604.974	9.29019
608.443	9.94035
611.908	10.7959
615.374	10.7594
618.837	10.3587
622.3	10.9825
625.761	11.3614
629.219	12.0885
632.677	13.1617
636.135	13.3419
639.59	11.508
643.043	12.8172
646.495	11.9798
649.948	12.3025
653.398	11.4234
656.846	9.73258
660.293	8.54714
663.738	9.6996
667.183	11.202
670.626	11.1545
674.067	12.8049
677.508	13.5133
680.947	14.8578
684.385	14.7645
687.821	17.9396
691.254	19.8119
694.688	19.9864
698.121	19.4804
701.552	21.8829
704.98	24.1862
708.409	26.7616
711.836	28.4696
715.26	31.6499
718.685	32.3316
722.108	33.9825
725.528	35.1822
728.949	36.1098
732.367	37.4261
735.785	39.7664
739.2	41.5203
742.614	42.9786
746.028	45.7158
749.439	49.5521
752.849	51.4921
756.26	53.2456
759.667	54.4896
763.073	56.4046
766.477	58.4023
769.883	60.3844
773.285	63.0659
776.686	63.8348
780.085	65.3625
783.484	67.2927
786.881	68.1881
790.276	67.9912
793.671	67.4484
797.064	68.8388
800.456	69.4488
803.846	70.056
807.234	68.9546
810.622	69.3289
814.008	71.7462
817.394	72.1637
820.778	71.8064
824.159	71.1275
827.541	69.6649
830.921	69.5678
834.298	69.3314
837.676	66.2285
841.051	62.8278
844.426	61.8231
847.798	60.0752
851.171	59.8737
854.54	58.3047
857.911	56.5736
861.278	53.2499
864.645	51.3431
868.01	49.0994
871.373	48.9539
874.735	46.4044
878.097	46.5004
881.457	45.354
884.815	44.5895
888.172	45.3044
891.528	45.7941
894.882	44.9099
898.237	44.0772
901.589	42.8739
904.94	40.7473
908.289	41.2298
911.635	40.4543
914.982	40.6052
918.328	38.2372
921.672	37.7676
925.015	38.2489
928.357	38.7628
931.698	37.8908
935.035	38.6986
938.373	38.1417
941.71	37.0471
945.044	35.7666
948.378	35.1723
951.709	35.2727
955.041	35.7821
958.372	36.6928
961.699	36.5607
965.027	37.3768
968.352	39.336
971.676	40.8484
975	39.1474
978.322	42.1233
981.642	42.3859
984.962	41.9497
988.28	41.3924
991.596	42.1297
994.911	41.2033
998.227	40.2316
1001.54	40.4588
1004.85	40.4821
1008.16	38.3273
1011.47	37.7483
1014.78	35.6209
1018.08	34.7484
1021.39	32.8719
1024.69	33.1383
1028	34.0828
1031.3	34.0865
1034.6	33.7665
1037.9	33.2265
1041.19	32.2743
1044.49	31.8615
1047.78	32.2397
1051.08	34.5939
1054.37	34.2443
1057.66	35.6558
1060.95	35.5603
1064.24	34.2854
1067.53	32.7786
1070.81	32.8546
1074.1	31.8585
1077.38	31.8184
1080.66	32.5059
1083.94	32.3139
1087.22	31.3938
1090.5	31.116
1093.78	30.4588
1097.05	29.7213
1100.33	31.6317
1103.6	33.6723
1106.87	33.1646
1110.14	32.3113
1113.41	30.4657
1116.68	28.535
1119.95	27.2033
1123.21	25.4182
1126.48	23.6978
1129.74	23.9477
1133	23.0087
1136.26	22.3329
1139.52	21.5284
1142.78	20.7522
1146.04	18.5483
1149.29	16.9561
1152.55	14.1633
1155.8	12.1514
1159.05	10.4179
1162.3	8.39411
1165.55	8.01271
1168.8	8.48731
1172.05	8.45835
1175.29	7.46641
1178.54	9.46455
1181.78	11.4711
1185.02	11.574
1188.26	12.8129
1191.5	13.9708
1194.74	13.3575
1197.97	14.2248
1201.21	15.5839
1204.44	17.1152
1207.68	19.3298
1210.91	22.8856
1214.14	25.9913
1217.37	30.4485
1220.59	32.5708
1223.82	34.7005
1227.05	37.2731
1230.27	39.9212
1233.49	42.757
1236.72	45.6895
1239.94	50.6808
1243.16	53.4416
1246.37	58.7909
1249.59	62.1419
1252.8	65.7812
1256.02	68.5958
1259.23	73.0144
1262.44	76.4339
1265.66	78.659
1268.86	80.0515
1272.07	82.0112
1275.28	83.4245
1278.48	86.4701
1281.69	89.6363
1284.89	92.8183
1288.09	95.3869
1291.29	94.48
1294.49	96.1068
1297.69	96.8971
1300.89	98.449
1304.08	98.886
1307.28	99.0002
1310.47	98.515
1313.66	98.6095
1316.85	97.3061
1320.04	96.8014
1323.23	95.0274
1326.42	94.4699
1329.61	89.8924
1332.79	87.9016
1335.97	85.4846
1339.16	84.8961
1342.34	83.5393
1345.52	81.4496
1348.7	78.5854
1351.87	77.8892
1355.05	76.5322
1358.22	76.4402
1361.4	73.9883
1364.57	73.2273
1367.74	70.5232
1370.91	68.5377
1374.08	68.5262
1377.25	68.7553
1380.41	69.0342
1383.58	68.3743
1386.74	68.8801
1389.91	67.5094
1393.07	66.2867
1396.23	66.1832
1399.39	65.04
1402.55	66.4231
1405.7	64.8705
1408.86	63.8001
1412.01	66.9513
1415.17	70.9185
1418.32	74.8722
1421.47	77.5527
1424.62	80.4895
1427.77	83.6718
1430.91	88.5964
1434.06	93.8665
1437.2	97.7029
1440.35	100.385
1443.49	102.957
1446.63	104.493
1449.77	105.641
1452.91	106.224
1456.05	105.139
1459.18	104.236
1462.32	100.986
1465.45	95.9851
1468.59	89.4237
1471.72	82.6112
1474.85	73.8325
1477.98	66.98
1481.1	60.4131
1484.23	51.2371
1487.36	45.8849
1490.48	41.5948
1493.61	37.5272
1496.73	33.5626
1499.85	31.3969
1502.97	29.062
1506.09	28.7719
1509.2	30.1631
1512.32	30.9243
1515.43	32.0481
1518.55	34.3079
1521.66	37.8515
1524.77	41.9885
1527.88	45.3567
1530.99	48.4713
1534.1	53.0577
1537.21	55.8538
1540.31	59.8178
1543.42	63.2915
1546.52	67.383
1549.62	71.4895
1552.72	76.5884
1555.82	80.964
1558.92	85.5225
1562.02	88.9439
1565.11	92.8328
1568.21	95.0707
1571.3	99.1854
1574.39	102.078
1577.49	103.814
1580.57	105.115
1583.66	107.846
1586.75	106.955
1589.84	107.097
1592.92	106.865
1596.01	106.566
1599.09	105.312
1602.17	103.475
1605.25	101.412
1608.33	99.5131
1611.41	97.8344
1614.49	97.1498
1617.57	95.7463
1620.64	97.4581
1623.72	97.393
1626.79	97.3973
1629.86	97.9488
1632.93	101.147
1636	103.296
1639.07	104.475
1642.13	106.199
1645.2	109.017
1648.26	110.522
1651.33	110.691
1654.39	109.495
1657.45	109.812
1660.51	107.709
1663.57	105.81
1666.63	101.724
1669.68	97.4077
1672.74	92.7919
1675.79	86.9218
1678.85	81.1758
1681.9	74.1611
1684.95	67.7004
1688	62.1878
1691.05	55.4691
1694.09	48.9125
1697.14	43.8751
1700.18	39.7667
1703.23	35.6187
1706.27	32.4643
1709.31	29.7553
1712.35	26.0358
1715.39	23.6614
1718.43	22.8976
1721.47	23.05
1724.5	21.6749
1727.54	20.8081
1730.57	19.6211
1733.61	19.085
1736.64	18.8508
1739.67	18.5285
1742.7	17.3548
1745.72	19.0991
1748.75	18.1727
1751.77	17.8403
1754.8	17.6734
1757.82	18.1184
1760.84	18.4236
1763.87	17.5182
1766.89	16.9838
1769.91	16.0104
1772.92	16.3643
1775.94	15.8276
1778.95	14.8413
1781.97	13.2132
1784.98	12.1883
1787.99	12.0383
1791.01	12.114
1794.01	11.45
1797.02	10.6375
1800.03	9.40818
1803.04	8.31168
1806.04	7.23751
1809.05	6.87248
1812.05	6.12969
1815.05	5.58347
1818.05	5.62234
1821.05	5.89059
1824.05	4.93078
1827.05	5.00546
1830.04	3.93815
1833.04	4.38309
1836.03	3.65927
1839.03	4.16409
1842.02	4.07794
1845.01	4.11837
1848	4.41429
1850.99	4.37286
1853.97	4.24306
1856.96	4.08757
1859.94	4.35956
1862.93	4.70979
1865.91	4.52146
1868.89	4.8252
1871.87	5.09521
1874.85	4.37464
1877.83	5.18459
1880.81	4.33046
1882.57	3.23457
1885.56	3.94242
1888.55	3.20083
1891.54	2.9834
1894.52	1.33927
1897.51	0.634574
1900.49	1.40979
1903.47	1.21023
1906.45	1.15283
1909.43	2.37591
1912.41	3.20776
1915.39	3.81237
1918.37	3.4682
1921.34	3.96698
1924.32	3.46521
1927.29	4.76354
1930.26	5.10369
1933.23	4.61324
1936.2	4.19558
1939.17	4.15901
1942.14	4.64191
1945.11	4.94774
1948.07	6.33557
1951.04	5.50331
1954	4.70953
1956.96	5.68031
1959.93	4.73119
1962.89	3.48061
1965.85	3.16749
1968.8	2.95839
1971.76	2.9461
1974.72	2.55109
1977.67	2.2999
1980.63	2.14454
1983.58	2.57054
1986.53	1.61127
1989.48	0.219739
1992.43	1.02311
1995.38	1.50855
1998.32	2.52989
2001.27	2.40305
2004.22	2.10434
2007.16	2.67617
2010.1	4.13982
2013.04	5.09837
2015.98	6.11454
2018.92	7.80493
2021.86	9.42565
2024.8	10.5292
2027.74	11.7952
2030.67	12.9412
2033.61	13.2437
2036.54	14.843
2039.47	14.5504
2042.4	15.6901
2045.33	15.5355
2048.26	16.4587
2051.19	16.4333
2054.12	15.4637
2057.04	15.5006
2059.97	15.6163
2062.89	15.767
2065.81	15.8807
2068.73	15.4219
2071.65	15.1888
2074.57	15.5139
2077.49	16.7823
2080.41	17.4467
2083.32	17.8321
2086.24	18.7161
2089.15	21.4956
2092.07	23.8719
2094.98	26.6734
2097.89	28.5144
2100.8	30.9854
2103.71	34.8298
2106.61	36.5622
2109.52	39.8228
2112.43	42.5822
2115.33	46.2148
2118.23	48.4651
2121.13	52.0825
2124.04	54.5863
2126.94	58.4951
2129.83	63.3019
2132.73	66.9689
2135.63	70.255
2138.53	74.1502
2141.42	77.315
2144.31	80.5905
2147.21	85.3979
2150.1	89.316
2152.99	91.4973
2155.88	95.3831
2158.77	98.9004
2161.65	101.706
2164.54	103.16
2167.43	104.04
2170.31	103.751
2173.19	103.971
2176.07	102.83
2178.96	101.63
2181.84	99.9024
2184.72	96.5757
2187.59	92.7414
2190.47	90.832
2193.35	88.8445
2196.22	86.6118
2199.09	84.3309
2201.97	80.4184
2204.84	77.2245
2207.71	74.0787
2210.58	70.0614
2213.45	66.8971
2216.31	64.0338
2219.18	62.0416
2222.05	59.0337
2224.91	56.729
2227.78	54.6796
2230.64	51.4371
2233.5	47.5459
2236.36	44.2879
2239.22	41.3235
2242.08	39.1287
2244.93	37.4852
2247.79	34.7622
2250.64	32.5458
2253.5	29.7495
2256.35	28.8275
2259.2	28.0878
2262.05	27.0604
2264.9	26.2285
2267.75	25.4366
2270.6	24.8927
2273.45	23.6708
2276.29	23.2661
2279.14	22.9332
2281.98	22.9965
2284.82	21.8747
2287.66	21.0231
2290.5	20.6614
2293.34	19.262
2296.18	17.3353
2299.02	16.1201
2301.86	15.8983
2304.69	16.2198
2307.53	15.834
2310.36	15.615
2313.19	16.2249
2316.02	15.6128
2318.85	13.8295
2321.68	14.5407
2324.51	14.0348
2327.34	13.4901
2330.16	12.6114
2332.99	12.337
2335.81	12.4955
2338.64	12.5064
2341.46	11.3884
2344.28	11.231
2347.1	11.1391
2349.92	10.7081
2352.74	8.44778
2355.55	7.1389
2358.37	7.16108
2361.19	6.42173
2364	6.84218
2366.81	8.38015
2369.62	9.25479
2372.44	9.46347
2375.24	10.0502
2378.05	10.9584
2380.86	11.1733
2383.67	10.8727
2386.47	10.3933
2389.28	10.8176
2392.08	10.201
2394.89	8.78165
2397.69	10.0263
2400.49	8.70875
2403.29	8.37699
2406.09	7.85047
2408.88	7.42076
2411.68	6.54011
2414.48	6.32611
2417.27	4.76434
2420.06	4.83649
2422.86	5.35978
2425.65	5.66286
2428.44	5.87144
2431.23	6.08158
2434.02	6.64404
2436.81	6.66051
2439.59	5.96792
2442.38	6.18929
2445.16	6.59492
2447.95	6.62404
2450.73	5.66036
2453.51	4.93879
2456.29	5.43894
2459.07	5.66735
2461.85	5.84681
2464.63	5.68065
2467.4	5.37288
2470.18	4.27929
2472.95	4.97654
2475.73	4.58033
2478.5	4.02584
2481.27	3.56511
2484.04	3.12759
2486.81	3.83448
2489.58	3.88211
2492.35	2.85701
2495.12	2.23078
2497.88	1.91011
2500.65	2.62873
2503.41	2.06298
2506.17	1.91604
2508.94	1.87308
2511.7	1.76623
2514.46	0.98118
2517.22	1.93152
2519.97	2.20832
2522.73	3.34216
2525.49	3.38186
2528.24	3.42535
2530.99	4.23939
2533.75	4.06716
2536.5	4.3509
2539.25	5.25605
2542	5.62231
2544.75	5.27343
2547.5	5.36599
2550.24	5.6299
2552.99	6.723
2555.74	6.94751
2558.48	7.22813
2561.22	7.41682
2563.96	8.00613
2566.71	8.21114
2569.45	7.50443
2572.18	7.3607
2574.92	7.29057
2577.66	6.70928
2580.4	5.90503
2583.13	6.10287
2585.87	6.65258
2588.6	6.33966
2591.33	5.98786
2594.06	6.32122
2596.79	6.09606
2599.52	5.32106
2602.25	4.41275
2604.98	4.90666
2607.71	4.16667
2610.43	2.95154
2613.16	2.73546
2615.88	1.87847
2618.6	1.81101
2621.32	2.06746
2624.04	1.43019
2626.76	1.57394
2629.48	1.60268
2632.2	1.97864
2634.92	1.94239
2637.63	2.25107
2640.35	3.25495
2643.06	3.94384
2645.77	4.70512
2648.49	4.40517
2651.2	5.67726
2653.91	5.57442
2656.62	6.2916
2659.33	6.38948
2662.03	5.71746
2664.74	6.43112
2667.44	6.62002
2670.15	6.85954
2672.85	6.3123
2675.55	5.43199
2678.26	5.22138
2680.96	6.00893
2683.66	5.6072
2686.35	5.95157
2689.05	6.05674
2691.75	6.64652
2694.44	7.00288
2697.14	7.07171
2699.83	7.57478
2702.52	7.39062
2705.22	7.52649
2707.91	8.86005
2710.6	9.08177
2713.29	9.02563
2715.97	9.57504
2718.66	9.50092
2721.35	9.26818
2724.03	9.29831
2726.72	9.04573
2729.4	9.64803
2732.08	9.43692
2734.76	8.82093
2737.44	8.73344
2740.12	8.72684
2742.8	9.33978
2745.48	8.64073
2748.16	8.86361
2750.83	7.76845
2753.51	7.62804
2756.18	6.95803
2758.85	6.36762
2761.53	5.83348
2764.2	4.39534
2766.87	3.05807
2769.54	2.24633
2772.2	2.38293
2774.87	2.56578
2777.54	2.40063
2780.2	1.94415
2782.87	1.4164
2785.53	1.03342
2788.19	1.20344
2790.85	1.22296
2793.51	1.06685
2796.17	0.985524
2798.83	1.55379
2801.49	1.41569
2804.15	1.82399
2806.8	1.30568
2809.46	1.25959
2812.11	1.04437
2814.76	0.406652
2817.42	0.692417
2820.07	1.91628
2822.72	3.5798
2825.37	6.22817
2828.02	8.01383
2830.66	11.1543
2833.31	15.0088
2835.96	19.5525
2838.6	23.9305
2841.24	30.5317
2843.89	37.3258
2846.53	45.4449
2849.17	54.2048
2851.81	63.3308
2854.45	72.2136
2857.09	81.6361
2859.72	90.9142
2862.36	100.283
2865	109.311
2867.63	117.012
2870.26	125.063
2872.9	131.85
2875.53	137.009
2878.16	141.56
2880.79	146.281
2883.42	152.057
2886.05	156.841
2888.67	160.116
2891.3	162.887
2893.92	166.975
2896.55	171.383
2899.17	176.479
2901.79	183.063
2904.42	191.042
2907.04	200.855
2909.66	211.918
2912.27	222.797
2914.89	233.991
2917.51	243.385
2920.13	252.859
2922.74	260.453
2925.35	266.441
2927.97	271.669
2930.58	274.303
2933.19	274.463
2935.8	272.448
2938.41	267.41
2941.02	261.007
2943.63	253.962
2946.24	244.864
2948.84	235.27
2951.45	224.113
2954.05	211.954
2956.65	200.084
2959.26	188.363
2961.86	178.45
2964.46	168.683
2967.06	159.688
2969.66	151.647
2972.25	143.825
2974.85	135.643
2977.45	127.218
2980.04	118.305
2982.64	109.029
2985.23	99.7159
2987.82	90.7889
2990.41	82.1178
2993	73.8314
2995.59	65.3232
2998.18	57.2388
3000.77	48.4916
3003.36	42.358
3005.94	35.9099
3008.53	29.4393
3011.11	23.8372
3013.69	19.7342
3016.28	14.5795
3018.86	10.0097
3021.44	7.10343
3024.02	5.10561
3026.6	3.36387
3029.18	2.63298
3031.75	2.71251
3034.33	2.82952
3036.9	3.4513
3039.48	4.31478
3042.05	4.77992
3044.62	4.99568
3047.19	5.62809
3049.77	6.99781
3052.34	7.74734
3054.9	8.47214
3057.47	9.65259
3060.04	10.5445
3062.61	9.64038
3065.17	9.62884
3067.74	9.54006
3070.3	8.35006
3072.86	7.5948
3075.42	7.10782
3077.99	6.0415
3080.54	4.39803
3083.1	2.66193
3085.66	1.41169
3088.22	0.137866
3090.78	0.425019
3093.33	0.854798
3095.89	0.871371
3098.44	1.50972
3100.99	1.44524
3103.54	1.52123
3106.1	2.26622
3108.65	3.03533
3111.2	4.04132
3113.74	4.67274
3116.29	5.89209
3118.84	6.72176
3121.38	7.45073
3123.93	8.11035
3126.47	9.2805
3129.01	10.6743
3131.56	11.8514
3134.1	12.5764
3136.64	14.2663
3139.18	15.0781
3141.72	15.5068
3144.26	17.1882
3146.79	19.467
3149.33	21.8754