File: data/Raman/poly_smoothed/Thy_30_10_48_1x_45s_532 nm_x100_100%_600 gr_mm_01.txt
#Acq. time (s)=	45
#Accumulations=	2
#Range (cm-¹)=	200...3150
#Windows=	2
#Auto scanning=	Off
#Autofocus=	Off
#Macrospot=	Off
#AutoExposure=	Off
#Spike filter=	Multiple accum.
#Delay time (s)=	0
#Binning=	1
#Readout mode=	Signal
#DeNoise=	Off
#ICS correction=	On
#Dark correction=	Off
#Inst. Process=	Off
#Detector Gain=	Best Dynamic Range
#Detector ADC=	20 kHz
#Detector temperature (°C)=	-69.85
#Instrument=	LabRAM HR Evol
#Detector=	Synapse
#Objective=	x100
#Grating=	600 gr/mm
#ND Filter=	100%
#Laser (nm)=	532
#Hole=	100.021
#Range=	Auto
#Laser Pol.=	No
#Raman. Pol.=	No
#Laser Pol. (°)=	-0.0007625
#Raman Pol. (°)=	89.9995
#Collection=	Microscope
#StageXY=	Marzhauser
#StageZ=	Marzhauser
#X (µm)=	4727.8
#Y (µm)=	-7696
#Z (µm)=	584.4
#Full time(mm:ss)=	3:18
#Project=
#Sample=
#Site=
#Title=	Thy_30_10_48_2x_45s_532 nm_x100_100%_600 gr_mm
#Remark=
#Date=	30.06.2022 14:50
#Acquired=	30.06.2022 14:50:49
#Base:Fit=	10.08.2022 09:58:11
#Base:Sub=	10.08.2022 09:58:44
#Filter:Polynom=	16.08.2022 10:22:53
#AxisType[0]=Intens
#AxisUnit[0]=Cnt
#AxisType[1]=Spectr
#AxisUnit[1]=1/cm
200.533	-2.49714
204.162	-0.944035
207.792	-0.326991
211.418	-0.224577
215.044	-0.622421
218.667	-1.09583
222.289	-0.00108366
225.912	-0.143691
229.531	0.81704
233.148	1.21694
236.766	1.57338
240.381	2.19591
243.994	2.64827
247.606	3.44619
251.217	3.7037
254.828	5.55547
258.436	4.5255
262.042	4.25788
265.647	5.34201
269.25	6.0702
272.852	7.20513
276.453	7.09452
280.052	7.34902
283.65	6.5738
287.247	7.00298
290.842	7.14303
294.436	7.34067
298.028	7.64385
301.617	8.20192
305.206	7.93126
308.794	8.58032
312.381	9.84915
315.964	10.4332
319.548	11.1855
323.131	11.2304
326.71	11.6324
330.29	11.0945
333.868	11.967
337.443	11.9175
341.018	11.5676
344.591	10.9509
348.163	10.5993
351.733	11.0854
355.303	11.313
358.869	10.8286
362.435	9.61126
366.001	9.05027
369.563	8.76463
373.124	9.07925
376.686	8.43859
380.244	8.42126
383.801	7.48475
387.357	6.43301
390.911	6.23767
394.466	5.0749
398.018	5.99729
401.568	6.22947
405.117	5.51196
408.664	5.58877
412.21	5.89277
415.755	5.26606
419.298	4.98729
422.84	5.83858
426.38	5.51724
429.919	5.55196
433.455	5.15877
436.992	4.75052
440.527	5.13552
444.06	5.00693
447.593	5.33777
451.122	5.58914
454.651	6.68658
458.18	6.53809
461.705	5.94705
465.23	5.73543
468.752	4.70114
472.275	5.02952
475.797	6.45155
479.315	6.99365
482.834	8.73356
486.349	10.0019
489.863	11.5568
493.378	11.9617
496.889	12.59
500.401	13.5286
503.91	13.2303
507.417	13.1939
510.923	13.121
514.43	10.8458
517.933	9.46872
521.435	8.79908
524.936	9.2181
528.435	8.29632
531.933	7.84358
535.43	6.71056
538.927	6.12746
542.421	5.20212
545.913	4.19573
549.403	2.51424
552.893	1.91996
556.381	0.955729
559.868	0.756766
563.354	0.619328
566.839	1.34943
570.322	2.22759
573.802	1.84414
577.283	1.87232
580.762	1.74298
584.24	2.31916
587.714	2.34445
591.19	1.59716
594.663	0.836616
598.134	1.00057
601.605	1.24464
605.073	2.36794
608.542	2.91557
612.007	3.20546
615.473	3.98472
618.936	5.42881
622.397	5.98616
625.859	6.27316
629.318	7.05796
632.775	7.97293
636.233	9.04403
639.688	9.43017
643.142	10.1853
646.594	11.7258
650.045	12.5709
653.496	12.2705
656.944	12.4615
660.391	12.4086
663.837	13.3653
667.281	14.399
670.724	15.499
674.166	16.0531
677.606	17.0702
681.045	18.0226
684.483	18.8617
687.917	19.9846
691.352	22.0853
694.786	22.9613
698.219	25.7387
701.65	29.0089
705.078	31.6561
708.506	32.6261
711.934	34.1534
715.358	37.3546
718.782	38.0412
722.204	38.5062
725.626	39.6673
729.045	42.1164
732.464	41.6775
735.881	42.036
739.297	43.0348
742.711	44.1209
746.125	45.8769
749.537	47.2728
752.946	49.2088
756.357	50.5988
759.764	50.6751
763.17	52.2218
766.575	54.2785
769.978	55.1595
773.382	57.2559
776.783	58.3727
780.182	60.557
783.581	63.6282
786.978	64.93
790.373	65.9828
793.768	66.7582
797.161	67.7528
800.552	67.8826
803.941	68.0303
807.33	68.7317
810.718	68.9782
814.105	69.5395
817.49	69.1515
820.873	68.9029
824.256	69.847
827.637	67.7788
831.016	67.1237
834.395	66.9515
837.772	66.1449
841.147	64.4051
844.522	63.4358
847.894	61.8977
851.267	60.2331
854.637	58.9197
858.007	57.3934
861.374	55.7665
864.739	54.6389
868.106	53.2149
871.469	51.881
874.831	49.1302
878.193	46
881.553	44.9805
884.911	44.3617
888.268	43.438
891.623	43.0771
894.978	42.2306
898.331	41.4619
901.683	39.7205
905.033	38.9503
908.383	38.6603
911.731	38.14
915.078	38.3382
918.423	39.2872
921.768	38.0589
925.111	38.5793
928.452	37.5757
931.791	36.6659
935.13	36.5602
938.468	36.5864
941.803	36.4006
945.139	35.4947
948.473	35.5456
951.804	34.0208
955.136	32.05
958.465	31.2624
961.794	30.9573
965.12	30.2066
968.447	29.699
971.771	28.7505
975.095	28.3132
978.417	27.8363
981.737	26.4737
985.057	24.6822
988.375	23.8591
991.691	23.1249
995.006	21.9427
998.32	21.6578
1001.63	20.674
1004.95	19.9071
1008.26	19.8944
1011.56	20.3647
1014.87	19.7126
1018.18	18.8703
1021.48	19.3047
1024.79	18.3105
1028.09	17.8949
1031.39	17.1207
1034.69	16.6897
1037.99	15.9983
1041.29	14.8986
1044.58	15.9992
1047.88	16.7288
1051.17	16.1583
1054.46	16.0205
1057.75	17.5669
1061.04	16.2732
1064.33	14.7333
1067.62	13.654
1070.9	13.7682
1074.19	13.7331
1077.47	14.4899
1080.76	14.2599
1084.04	14.5179
1087.32	14.5346
1090.59	15.6248
1093.87	16.4904
1097.15	16.2782
1100.42	17.6174
1103.69	17.7626
1106.97	16.5029
1110.24	16.5345
1113.51	15.4519
1116.77	15.4186
1120.04	14.7537
1123.31	14.4124
1126.57	14.1407
1129.83	13.5749
1133.1	11.4199
1136.36	11.1191
1139.62	9.57314
1142.87	8.7911
1146.13	7.826
1149.38	7.47844
1152.64	7.49142
1155.89	7.3394
1159.14	7.33456
1162.39	7.27038
1165.64	7.8878
1168.89	9.06016
1172.14	11.6631
1175.38	10.9931
1178.63	11.4348
1181.87	11.1151
1185.11	10.4687
1188.35	9.2384
1191.59	9.95441
1194.83	9.89245
1198.07	10.1127
1201.3	10.6111
1204.53	11.2911
1207.77	12.1239
1211	12.8111
1214.23	13.5543
1217.46	15.6621
1220.69	17.9111
1223.91	18.9894
1227.14	19.815
1230.36	21.3789
1233.59	22.9379
1236.81	24.9447
1240.03	25.8466
1243.25	28.0281
1246.46	30.368
1249.68	31.6657
1252.9	33.0247
1256.11	33.9692
1259.32	34.7719
1262.54	34.8489
1265.75	35.7614
1268.96	35.5157
1272.16	35.189
1275.37	35.9529
1278.57	37.3581
1281.78	37.9729
1284.98	38.4354
1288.18	39.0207
1291.38	39.189
1294.58	38.3393
1297.78	39.3303
1300.98	39.7099
1304.17	38.962
1307.37	39.8704
1310.56	41.016
1313.76	42.0308
1316.95	42.6706
1320.14	42.9359
1323.32	44.3085
1326.51	44.2884
1329.7	45.0375
1332.88	42.9922
1336.07	42.5665
1339.25	41.6846
1342.43	40.838
1345.61	39.6081
1348.79	37.3533
1351.96	36.5594
1355.14	36.1149
1358.31	35.096
1361.49	33.9575
1364.66	32.1772
1367.83	31.2736
1371	30.7574
1374.17	29.6019
1377.34	29.0166
1380.5	27.8303
1383.67	26.6451
1386.83	26.8786
1390	26.0856
1393.16	26.0658
1396.32	25.4035
1399.48	25.6513
1402.64	24.9951
1405.79	25.119
1408.95	24.2506
1412.1	24.4174
1415.26	26.3903
1418.41	26.9214
1421.56	28.4013
1424.71	28.6102
1427.86	30.0857
1431	32.585
1434.15	34.395
1437.29	36.3455
1440.44	38.3408
1443.58	38.912
1446.72	40.8289
1449.86	40.8226
1453	40.1148
1456.14	38.2534
1459.27	36.5535
1462.41	35.3297
1465.54	32.6087
1468.67	30.2591
1471.81	28.2883
1474.94	25.2708
1478.07	22.448
1481.19	19.2462
1484.32	17.1189
1487.45	14.4861
1490.57	13.4832
1493.69	11.1301
1496.82	8.84472
1499.94	6.93372
1503.06	6.28673
1506.17	8.16799
1509.29	8.62784
1512.41	9.12224
1515.52	9.57977
1518.64	11.604
1521.75	14.115
1524.86	14.9668
1527.97	16.3241
1531.08	18.0032
1534.19	18.4854
1537.29	20.5926
1540.4	21.5022
1543.5	23.6419
1546.61	26.1716
1549.71	28.0701
1552.81	29.2162
1555.91	31.3464
1559.01	32.4673
1562.11	33.2687
1565.2	34.8054
1568.29	35.9654
1571.39	36.5333
1574.48	37.2814
1577.57	38.944
1580.66	40.4275
1583.75	40.7513
1586.84	41.8824
1589.93	41.3974
1593.01	42.3195
1596.1	42.0576
1599.18	41.2155
1602.26	40.6892
1605.34	40.0071
1608.42	39.1944
1611.5	37.643
1614.58	36.0395
1617.65	34.9948
1620.73	34.5421
1623.8	33.1414
1626.87	32.5799
1629.95	32.2895
1633.02	32.0536
1636.09	32.026
1639.15	32.9177
1642.22	33.244
1645.29	33.1826
1648.35	33.1778
1651.42	33.3104
1654.48	33.6726
1657.54	32.8918
1660.6	32.2743
1663.66	31.212
1666.72	29.2859
1669.77	27.8391
1672.83	27.1463
1675.88	25.0093
1678.93	23.1526
1681.99	20.7046
1685.04	18.3915
1688.09	15.5881
1691.13	13.6509
1694.18	11.8624
1697.23	9.64651
1700.27	8.34722
1703.32	7.84804
1706.36	6.48099
1709.4	5.47955
1712.44	3.76266
1715.48	3.2366
1718.52	3.15853
1721.56	2.68254
1724.59	2.70188
1727.63	2.56579
1730.66	1.92304
1733.69	1.5488
1736.72	1.45374
1739.75	1.90661
1742.78	1.80775
1745.81	2.4949
1748.84	2.16443
1751.86	1.63477
1754.89	1.74297
1757.91	2.25466
1760.93	2.45899
1763.95	2.85672
1766.97	2.70115
1769.99	2.96888
1773.01	2.74376
1776.03	2.9163
1779.04	3.2199
1782.06	2.43712
1785.07	2.63248
1788.08	2.46296
1791.09	3.02636
1794.1	3.51214
1797.11	2.92448
1800.12	3.33641
1803.12	3.01708
1806.13	2.89958
1809.13	3.23512
1812.14	3.57316
1815.14	3.71668
1818.14	4.01997
1821.14	4.00455
1824.14	4.49724
1827.13	5.00431
1830.13	5.9183
1833.12	6.48767
1836.12	5.88906
1839.11	6.22964
1842.1	5.14798
1845.09	4.70604
1848.08	3.61944
1851.07	3.76014
1854.06	3.96553
1857.04	4.0482
1860.03	3.63589
1863.01	3.0284
1866	3.52821
1868.98	3.10914
1871.96	3.01809
1874.94	4.2268
1877.92	4.14185
1880.89	4.79201
1882.48	5.22301
1885.47	6.90796
1888.46	7.27515
1891.44	7.24058
1894.43	8.15901
1897.41	9.59012
1900.4	10.1831
1903.38	10.3414
1906.36	10.1601
1909.34	10.1879
1912.32	9.97758
1915.29	10.4895
1918.27	10.8981
1921.25	11.9475
1924.22	12.6232
1927.2	12.2744
1930.17	12.2983
1933.14	11.1831
1936.11	10.5619
1939.08	10.5373
1942.05	10.5649
1945.01	10.2941
1947.98	10.3234
1950.94	9.97398
1953.91	10.9919
1956.87	11.1883
1959.83	10.8966
1962.79	9.9799
1965.75	9.42768
1968.71	10.1228
1971.67	9.75964
1974.62	8.58598
1977.58	8.98455
1980.53	9.17722
1983.48	9.72842
1986.43	9.79191
1989.38	10.3095
1992.33	10.6424
1995.28	11.2691
1998.23	10.5045
2001.18	10.6054
2004.12	9.76526
2007.06	9.45608
2010.01	10.0474
2012.95	11.1421
2015.89	11.3266
2018.83	11.8332
2021.77	12.1231
2024.71	12.2573
2027.64	12.5113
2030.58	12.4535
2033.51	12.4178
2036.45	12.8171
2039.38	13.6169
2042.31	13.8721
2045.24	14.1837
2048.17	14.0817
2051.1	14.1211
2054.02	14.2417
2056.95	14.5147
2059.87	14.1655
2062.8	14.3985
2065.72	14.6457
2068.64	14.6742
2071.56	14.2787
2074.48	14.4568
2077.4	14.3551
2080.31	14.9756
2083.23	15.6319
2086.14	15.5483
2089.06	15.6085
2091.97	15.9942
2094.88	15.592
2097.79	15.9324
2100.7	16.2601
2103.61	16.884
2106.52	17.6228
2109.43	18.6249
2112.33	19.3852
2115.24	19.8741
2118.14	20.7772
2121.04	20.3948
2123.94	22.4762
2126.84	22.9077
2129.74	24.1434
2132.64	25.1564
2135.54	26.8862
2138.43	27.8376
2141.33	28.7728
2144.22	29.58
2147.11	30.2715
2150.01	31.2012
2152.9	31.7796
2155.79	32.2476
2158.67	33.4767
2161.56	34.6945
2164.45	34.7248
2167.33	33.9009
2170.22	34.0603
2173.1	34.4864
2175.98	34.6162
2178.86	35.5227
2181.74	35.5331
2184.62	36.2268
2187.5	35.8965
2190.38	35.5449
2193.25	35.5279
2196.13	35.4686
2199	34.2425
2201.88	32.9023
2204.75	32.0662
2207.62	30.5392
2210.49	29.3564
2213.36	27.8701
2216.22	26.5887
2219.09	25.4086
2221.96	24.4052
2224.82	23.5751
2227.68	24.0081
2230.55	23.7952
2233.41	22.1352
2236.27	20.9062
2239.12	21.4739
2241.98	21.9042
2244.84	21.9261
2247.7	21.4947
2250.55	21.0859
2253.41	20.2592
2256.26	19.4643
2259.11	19.6897
2261.96	19.2152
2264.81	18.3516
2267.66	17.4543
2270.51	15.97
2273.35	15.4846
2276.2	14.3701
2279.04	13.9023
2281.89	13.553
2284.73	12.9082
2287.57	12.574
2290.41	11.5118
2293.25	10.4191
2296.09	10.0927
2298.93	10.3698
2301.76	10.4324
2304.6	10.8769
2307.44	12.5591
2310.27	13.6029
2313.1	13.4418
2315.93	13.4288
2318.76	12.5704
2321.59	12.317
2324.42	13.2507
2327.25	13.8124
2330.07	13.6557
2332.9	13.5289
2335.72	13.4419
2338.55	12.9187
2341.37	12.6323
2344.19	12.0063
2347.01	11.2893
2349.83	11.1649
2352.65	9.62314
2355.46	8.39454
2358.28	6.55037
2361.09	5.0997
2363.91	4.75635
2366.72	5.01469
2369.53	5.69353
2372.34	5.9716
2375.15	6.12528
2377.96	6.06373
2380.77	5.79065
2383.58	6.00138
2386.38	6.16043
2389.19	6.09333
2391.99	7.06547
2394.8	8.13896
2397.6	8.8716
2400.4	8.98995
2403.2	9.83931
2406	10.9943
2408.79	11.6281
2411.59	12.5992
2414.39	12.9608
2417.18	13.3994
2419.98	13.0051
2422.77	12.0452
2425.56	11.4316
2428.35	10.7634
2431.14	10.1037
2433.93	10.0653
2436.72	9.47765
2439.5	9.34465
2442.29	8.58887
2445.07	8.1057
2447.86	7.35688
2450.64	7.38885
2453.42	6.62356
2456.2	5.60239
2458.98	5.3706
2461.76	5.56084
2464.54	5.59824
2467.32	5.77938
2470.09	5.8472
2472.87	6.14904
2475.64	6.94991
2478.41	6.93377
2481.18	6.93918
2483.95	5.96159
2486.72	4.99443
2489.49	4.09087
2492.26	3.89768
2495.03	4.23784
2497.79	3.39105
2500.56	3.01895
2503.32	2.50384
2506.09	2.26477
2508.85	1.3758
2511.61	1.19259
2514.37	1.34056
2517.13	0.734221
2519.89	1.38084
2522.64	1.01922
2525.4	0.581296
2528.15	0.921518
2530.91	2.10203
2533.66	2.34645
2536.41	3.22514
2539.16	3.65807
2541.91	4.62481
2544.66	4.3997
2547.41	4.41936
2550.16	4.76417
2552.9	5.21473
2555.65	5.54449
2558.39	5.88268
2561.13	6.35224
2563.88	5.51769
2566.62	5.3781
2569.36	4.51419
2572.1	4.10304
2574.84	4.08805
2577.57	3.93695
2580.31	4.09645
2583.05	3.97292
2585.78	3.30263
2588.51	3.00105
2591.24	1.57989
2593.98	2.43989
2596.71	3.8471
2599.44	3.48679
2602.16	3.44162
2604.89	3.99156
2607.62	4.40924
2610.34	3.92096
2613.07	4.17431
2615.79	4.74608
2618.52	4.35603
2621.24	4.09239
2623.96	3.71188
2626.68	3.51643
2629.4	3.31652
2632.11	2.55377
2634.83	2.40185
2637.55	2.59959
2640.26	2.54723
2642.98	2.28815
2645.69	2.63262
2648.4	2.53054
2651.11	2.71038
2653.82	2.53081
2656.53	3.05421
2659.24	3.3541
2661.95	2.57687
2664.65	2.62485
2667.36	2.12734
2670.06	2.27584
2672.76	2.36366
2675.47	2.15638
2678.17	1.9504
2680.87	0.76687
2683.57	0.747848
2686.27	0.812164
2688.97	0.0144721
2691.66	-0.553382
2694.36	-0.588908
2697.05	-0.139972
2699.75	0.00587156
2702.44	-0.341695
2705.13	-0.348188
2707.82	-0.372622
2710.51	0.681718
2713.2	0.971502
2715.89	1.25278
2718.57	1.70486
2721.26	2.65394
2723.95	3.322
2726.63	3.22273
2729.31	3.92254
2732	4.39762
2734.68	4.7346
2737.36	5.43868
2740.04	6.34649
2742.72	5.782
2745.39	6.10516
2748.07	6.02803
2750.75	7.12752
2753.42	7.08279
2756.09	6.93614
2758.77	7.46774
2761.44	6.62146
2764.11	5.60577
2766.78	5.37083
2769.45	4.09362
2772.12	3.84938
2774.78	3.62368
2777.45	3.25966
2780.12	2.50558
2782.78	2.40592
2785.44	2.61083
2788.11	2.90625
2790.77	2.27455
2793.43	2.01567
2796.09	1.55632
2798.75	1.5589
2801.4	1.50143
2804.06	1.23847
2806.72	1.15162
2809.37	0.978248
2812.03	1.54915
2814.68	2.25813
2817.33	3.53339
2819.98	4.00755
2822.63	4.94209
2825.28	6.6064
2827.93	8.29654
2830.58	10.5818
2833.23	11.1527
2835.87	12.5511
2838.52	14.5043
2841.16	16.1434
2843.8	18.1155
2846.44	20.7192
2849.08	23.7427
2851.73	26.4348
2854.36	29.1203
2857	31.6619
2859.64	33.4645
2862.28	35.4368
2864.91	37.3119
2867.55	39.0891
2870.18	41.0125
2872.81	42.0183
2875.44	43.5156
2878.07	45.5999
2880.7	46.6923
2883.33	48.031
2885.96	48.8408
2888.59	50.8081
2891.21	52.9755
2893.84	54.874
2896.46	55.6404
2899.09	57.3236
2901.71	60.1587
2904.33	63.1759
2906.95	67.1251
2909.57	70.481
2912.19	75.4431
2914.81	79.1948
2917.43	82.6743
2920.04	86.489
2922.66	89.4675
2925.27	92.0072
2927.88	93.1804
2930.5	94.2878
2933.11	95.1974
2935.72	94.8291
2938.33	93.5479
2940.94	92.1654
2943.54	89.4254
2946.15	87.0526
2948.76	83.7182
2951.36	81.4917
2953.97	78.7367
2956.57	75.2939
2959.17	71.6393
2961.77	68.0307
2964.37	65.8785
2966.97	63.6914
2969.57	60.8056
2972.17	58.1715
2974.77	55.9592
2977.36	53.835
2979.96	50.4063
2982.55	48.2461
2985.15	45.6348
2987.74	43.0429
2990.33	39.6063
2992.92	36.7079
2995.51	34.5592
2998.1	32.5897
3000.69	29.8109
3003.27	27.4088
3005.86	24.4668
3008.44	21.9809
3011.03	19.2113
3013.61	17.2175
3016.19	15.2636
3018.78	12.5242
3021.36	10.9558
3023.94	10.3542
3026.51	9.16831
3029.09	9.05023
3031.67	8.63758
3034.24	7.8157
3036.82	8.59028
3039.39	8.83947
3041.97	9.02102
3044.54	9.63592
3047.11	10.105
3049.68	9.99578
3052.25	10.5051
3054.82	10.4679
3057.39	11.0568
3059.96	11.0908
3062.52	10.8153
3065.09	10.4742
3067.65	8.9809
3070.22	8.22693
3072.78	7.70313
3075.34	6.0434
3077.9	4.79567
3080.46	3.85793
3083.02	2.73668
3085.58	1.77303
3088.14	1.57187
3090.69	0.705567
3093.25	0.962454
3095.8	0.371393
3098.36	1.02028
3100.91	1.15491
3103.46	0.281903
3106.01	-0.106848
3108.56	0.0842214
3111.11	-0.0932236
3113.66	-0.322048
3116.21	0.212804
3118.76	0.322814
3121.3	0.738643
3123.85	0.861931
3126.39	1.19295
3128.93	1.31635
3131.48	1.12646
3134.02	2.03389
3136.56	1.55665
3139.1	1.55349
3141.64	1.68211
3144.17	1.79165
3146.71	2.21848
3149.25	1.52627