File: data/Raman/poly_smoothed/Thy_50_12_47_1x_45s_532 nm_x100_100%_600 gr_mm_01.txt
#Acq. time (s)=	45
#Accumulations=	2
#Range (cm-¹)=	200...3150
#Windows=	2
#Auto scanning=	Off
#Autofocus=	Off
#Macrospot=	Off
#AutoExposure=	Off
#Spike filter=	Multiple accum.
#Delay time (s)=	0
#Binning=	1
#Readout mode=	Signal
#DeNoise=	Off
#ICS correction=	On
#Dark correction=	Off
#Inst. Process=	Off
#Detector Gain=	Best Dynamic Range
#Detector ADC=	20 kHz
#Detector temperature (°C)=	-69.85
#Instrument=	LabRAM HR Evol
#Detector=	Synapse
#Objective=	x100
#Grating=	600 gr/mm
#ND Filter=	100%
#Laser (nm)=	532
#Hole=	100.021
#Range=	Auto
#Laser Pol.=	No
#Raman. Pol.=	No
#Laser Pol. (°)=	-0.0007625
#Raman Pol. (°)=	89.9995
#Collection=	Microscope
#StageXY=	Marzhauser
#StageZ=	Marzhauser
#X (µm)=	-5111.6
#Y (µm)=	1527.7
#Z (µm)=	63.6
#Full time(mm:ss)=	3:19
#Project=
#Sample=
#Site=
#Title=	Thy_50_12_47_2x_45s_532 nm_x100_100%_600 gr_mm
#Remark=
#Date=	07.07.2022 12:42
#Acquired=	07.07.2022 12:42:26
#Base:Fit=	10.08.2022 10:04:30
#Base:Sub=	10.08.2022 10:04:45
#Filter:Polynom=	16.08.2022 10:20:25
#AxisType[0]=Intens
#AxisUnit[0]=Cnt
#AxisType[1]=Spectr
#AxisUnit[1]=1/cm
200.43	16.9656
204.061	25.0088
207.688	27.6327
211.316	27.2838
214.941	25.8302
218.566	24.362
222.188	22.4791
225.809	22.7961
229.43	21.3127
233.047	18.4685
236.663	17.6132
240.278	17.6302
243.894	16.3834
247.506	15.9859
251.116	14.4352
254.725	14.6163
258.333	13.7453
261.939	14.0942
265.546	13.8017
269.15	14.9687
272.752	14.9236
276.353	17.1253
279.952	18.8591
283.55	16.8248
287.146	17.173
290.739	15.2841
294.333	14.5223
297.925	15.009
301.516	15.0436
305.106	16.3065
308.694	16.4889
312.279	18.0653
315.864	17.6019
319.448	16.8863
323.029	16.585
326.61	17.6479
330.19	17.415
333.766	17.5402
337.343	17.0907
340.917	17.44
344.491	18.2987
348.062	19.1592
351.633	19.296
355.201	18.6393
358.77	18.4278
362.335	17.112
365.899	15.4232
369.464	11.1384
373.025	9.84407
376.585	9.60987
380.143	9.55595
383.702	10.0795
387.258	9.17738
390.812	9.44694
394.365	8.7354
397.916	8.62555
401.467	8.73944
405.015	7.50238
408.565	8.05807
412.111	7.91994
415.656	9.50756
419.197	10.9348
422.739	13.0407
426.279	13.9018
429.819	15.5279
433.356	16.3448
436.893	15.5037
440.428	15.3974
443.96	14.3751
447.492	14.5541
451.023	12.5093
454.553	10.8344
458.079	10.4619
461.606	10.4296
465.132	10.37
468.654	10.2076
472.177	10.665
475.696	10.1173
479.217	8.74541
482.733	8.42076
486.251	9.14739
489.765	9.9637
493.278	10.8571
496.791	11.1157
500.301	11.1574
503.81	11.652
507.319	13.5224
510.825	14.644
514.33	13.6776
517.833	14.114
521.337	13.5643
524.838	14.2988
528.337	14.3855
531.835	15.7543
535.332	14.129
538.827	13.4203
542.321	14.6613
545.814	13.5415
549.305	13.2874
552.795	13.629
556.284	13.089
559.771	13.1365
563.257	12.6776
566.742	11.3625
570.223	8.8419
573.705	7.81791
577.185	8.06197
580.665	7.08594
584.141	5.92528
587.617	5.36804
591.092	6.46566
594.564	6.16753
598.037	3.64967
601.506	4.68884
604.976	4.41847
608.443	4.34733
611.91	3.84625
615.374	3.44214
618.839	4.37124
622.3	4.2234
625.761	4.19663
629.221	5.57302
632.679	6.11735
636.135	6.56571
639.592	8.18886
643.045	8.93836
646.497	9.6795
649.948	9.70028
653.398	9.21723
656.846	10.0058
660.293	11.7327
663.738	13.0702
667.185	13.5828
670.628	14.2776
674.067	14.4292
677.508	13.3369
680.947	12.5186
684.385	12.0391
687.821	13.2297
691.256	14.2425
694.69	14.774
698.121	16.112
701.552	17.7785
704.982	18.8983
708.41	20.7439
711.836	23.7799
715.262	26.1081
718.685	26.7686
722.108	28.5561
725.53	31.0468
728.949	32.6395
732.369	34.4933
735.785	36.0645
739.2	38.6538
742.616	40.8162
746.028	42.7957
749.441	43.8412
752.851	44.3705
756.26	44.4443
759.667	43.9467
763.075	45.2812
766.479	46.5168
769.883	50.0761
773.285	52.2574
776.686	56.3373
780.085	57.4877
783.484	61.0343
786.881	63.5611
790.276	65.4167
793.671	69.2069
797.064	71.3747
800.456	71.4762
803.846	70.7304
807.236	72.7244
810.624	72.5816
814.01	72.1983
817.394	71.3981
820.778	70.9253
824.161	68.2006
827.543	64.5233
830.921	60.3592
834.3	58.2644
837.676	56.0455
841.053	51.2603
844.426	49.1818
847.8	46.8941
851.171	44.1616
854.542	42.1019
857.911	40.5275
861.279	40.4562
864.645	38.7201
868.01	36.4373
871.375	35.782
874.737	37.6166
878.097	37.329
881.457	37.1422
884.817	37.544
888.174	37.0957
891.53	37.7938
894.884	36.7748
898.237	36.1154
901.589	35.8183
904.94	33.3913
908.289	31.5686
911.637	30.6678
914.984	32.0636
918.33	31.0176
921.674	28.1074
925.015	26.7734
928.357	24.0361
931.698	22.9669
935.037	21.167
938.373	19.6163
941.71	17.4748
945.046	15.216
948.378	12.791
951.711	13.5552
955.043	13.8443
958.372	11.6533
961.701	11.6073
965.027	12.829
968.354	13.3186
971.678	13.7295
975	13.1978
978.324	12.0544
981.644	12.7725
984.962	12.5027
988.282	13.3488
991.598	15.1261
994.913	15.2919
998.227	15.2109
1001.54	14.2009
1004.85	15.5097
1008.16	16.9701
1011.47	16.4604
1014.78	17.3947
1018.08	17.4938
1021.39	17.7638
1024.69	17.2389
1028	17.5062
1031.3	19.6436
1034.6	19.8019
1037.9	21.6114
1041.19	23.1173
1044.49	23.1864
1047.79	23.9943
1051.08	23.1557
1054.37	21.8626
1057.66	20.4312
1060.95	19.3571
1064.24	19.2112
1067.53	16.5805
1070.81	15.4195
1074.1	14.3758
1077.38	13.1466
1080.66	12.2407
1083.94	11.7519
1087.22	10.3412
1090.5	9.15048
1093.78	8.85157
1097.05	10.029
1100.33	9.73331
1103.6	11.5594
1106.87	11.6781
1110.15	11.7784
1113.41	11.8936
1116.68	11.5345
1119.95	12.1539
1123.21	11.7424
1126.48	11.0638
1129.74	10.9663
1133	10.2912
1136.26	10.0321
1139.52	7.74884
1142.78	6.97917
1146.04	6.35968
1149.29	4.96244
1152.55	3.78373
1155.8	3.3491
1159.05	3.43848
1162.3	3.06234
1165.55	1.59614
1168.8	1.16587
1172.05	2.38167
1175.29	1.673
1178.54	1.81505
1181.78	1.39038
1185.02	1.26011
1188.26	1.42209
1191.5	0.742336
1194.74	0.0353089
1197.97	3.12369
1201.21	4.63564
1204.44	6.5552
1207.68	6.08543
1210.91	7.81797
1214.14	9.09303
1217.37	10.3787
1220.6	13.0515
1223.82	17.2381
1227.05	18.6666
1230.27	20.8562
1233.49	22.5352
1236.72	24.8415
1239.94	28.5215
1243.16	31.466
1246.37	33.6767
1249.59	35.1982
1252.8	37.6097
1256.02	42.0707
1259.23	43.7694
1262.44	47.3524
1265.66	50.5444
1268.87	53.1339
1272.07	56.26
1275.28	60.0641
1278.48	62.2962
1281.69	64.2535
1284.89	66.5359
1288.09	66.9273
1291.3	68.0667
1294.49	68.5592
1297.69	69.0733
1300.89	70.0828
1304.09	69.5946
1307.28	67.848
1310.47	66.4791
1313.66	65.5828
1316.86	64.4624
1320.05	62.9065
1323.23	60.9285
1326.42	58.8309
1329.61	56.8425
1332.79	55.4458
1335.98	54.9566
1339.16	52.8634
1342.34	52.1982
1345.52	50.6488
1348.7	49.4146
1351.87	47.7944
1355.05	46.4835
1358.23	45.4124
1361.4	44.1099
1364.57	42.1882
1367.74	40.6104
1370.91	40.5083
1374.08	39.0901
1377.25	39.2161
1380.42	38.4117
1383.58	37.9464
1386.75	37.8579
1389.91	37.4023
1393.07	37.1686
1396.23	35.3594
1399.39	35.6343
1402.55	36.667
1405.7	36.3959
1408.86	37.4989
1412.01	40.0128
1415.17	42.9566
1418.32	46.7033
1421.47	50.1137
1424.62	54.5944
1427.77	59.0019
1430.92	64.6999
1434.06	71.2238
1437.2	75.5794
1440.35	79.0141
1443.49	81.1002
1446.63	81.7683
1449.77	81.9845
1452.91	81.071
1456.05	79.8342
1459.18	77.5718
1462.32	74.558
1465.45	70.4437
1468.59	65.7812
1471.72	58.7877
1474.85	53.258
1477.98	47.0883
1481.11	41.4003
1484.23	35.0775
1487.36	30.0898
1490.48	27.143
1493.61	24.4213
1496.73	21.828
1499.85	20.5771
1502.97	20.1686
1506.09	19.0598
1509.2	19.6595
1512.32	18.8914
1515.44	18.2302
1518.55	20.3336
1521.66	20.4725
1524.77	22.5625
1527.88	24.9601
1530.99	27.0043
1534.1	29.426
1537.21	32.0716
1540.31	34.5883
1543.42	36.4343
1546.52	39.0803
1549.62	44.0356
1552.72	47.2588
1555.82	49.6163
1558.92	52.201
1562.02	53.9175
1565.11	56.3886
1568.21	61.5998
1571.3	64.1001
1574.39	67.3768
1577.49	69.9471
1580.58	72.0191
1583.67	74.7023
1586.75	74.5937
1589.84	75.864
1592.93	76.2001
1596.01	76.0426
1599.09	74.2359
1602.18	73.3906
1605.26	71.2664
1608.34	69.9092
1611.41	67.0687
1614.49	65.8937
1617.57	63.4181
1620.64	63.0604
1623.72	63.619
1626.79	62.5054
1629.86	58.8546
1632.93	58.8492
1636	58.3188
1639.07	60.3091
1642.14	61.8129
1645.2	64.7882
1648.27	67.0954
1651.33	68.0847
1654.39	69.1108
1657.45	68.3505
1660.51	67.5661
1663.57	65.1711
1666.63	64.1037
1669.69	63.1101
1672.74	61.1595
1675.79	59.5056
1678.85	55.4846
1681.9	50.8445
1684.95	46.6706
1688	42.2656
1691.05	37.2605
1694.1	32.778
1697.14	28.8343
1700.19	23.8289
1703.23	20.6896
1706.27	18.1602
1709.32	16.2821
1712.35	15.1477
1715.39	13.6773
1718.43	12.5899
1721.47	12.0589
1724.5	11.6659
1727.54	10.7284
1730.57	9.53175
1733.61	8.79915
1736.64	9.71202
1739.67	10.5447
1742.7	10.8788
1745.72	11.5286
1748.75	11.107
1751.78	9.10149
1754.8	8.24635
1757.82	8.15357
1760.85	7.13367
1763.87	6.22096
1766.89	6.29559
1769.91	5.88295
1772.92	5.71996
1775.94	5.38564
1778.96	4.27735
1781.97	3.86634
1784.98	3.60396
1788	3.39387
1791.01	3.2601
1794.01	3.11704
1797.02	2.95091
1800.03	3.8775
1803.04	4.00523
1806.04	4.19597
1809.05	4.97344
1812.05	5.40091
1815.05	4.84636
1818.05	4.14042
1821.05	4.29269
1824.05	4.34748
1827.05	4.32168
1830.04	4.59323
1833.04	4.91118
1836.03	5.63166
1839.03	5.51994
1842.02	5.73219
1845.01	5.97861
1848	5.40168
1850.99	4.94106
1853.97	4.87233
1856.96	4.46037
1859.94	3.30931
1862.93	3.78413
1865.91	3.38183
1868.89	3.6989
1871.87	4.19588
1874.85	5.49167
1877.83	6.80328
1880.81	6.89779
1882.56	7.66777
1885.55	7.85823
1888.54	7.81762
1891.52	8.09727
1894.51	7.7339
1897.49	7.53636
1900.48	8.08561
1903.46	8.37466
1906.44	9.05582
1909.42	8.57014
1912.4	8.63684
1915.38	8.11968
1918.35	7.00309
1921.33	5.74977
1924.3	3.62352
1927.28	2.88637
1930.25	1.5046
1933.22	1.38077
1936.19	1.44676
1939.16	1.15131
1942.13	1.95244
1945.09	2.68222
1948.06	3.50774
1951.03	3.33825
1953.99	3.66008
1956.95	3.1384
1959.91	2.91394
1962.87	3.03629
1965.83	2.95311
1968.79	4.29969
1971.75	4.46143
1974.7	5.16983
1977.66	4.07134
1980.61	3.8604
1983.56	3.34708
1986.52	2.62907
1989.47	3.11994
1992.41	3.0474
1995.36	1.64736
1998.31	1.12623
2001.26	2.01112
2004.2	2.30484
2007.15	2.6531
2010.09	2.3392
2013.03	2.37097
2015.97	1.99516
2018.91	2.44921
2021.85	2.65076
2024.79	3.44682
2027.72	3.56297
2030.66	3.89996
2033.59	4.04739
2036.53	5.02273
2039.46	6.36125
2042.39	7.4318
2045.32	7.07729
2048.25	7.80174
2051.18	8.38761
2054.1	9.76457
2057.03	10.8604
2059.95	11.8302
2062.88	11.7569
2065.8	11.8257
2068.72	13.4589
2071.64	14.4521
2074.56	15.8727
2077.48	15.9225
2080.39	16.4706
2083.31	17.1852
2086.22	18.916
2089.14	21.8995
2092.05	23.4545
2094.96	24.7916
2097.87	26.7715
2100.78	29.0118
2103.69	31.3071
2106.6	33.2162
2109.51	36.5003
2112.41	38.18
2115.32	40.1203
2118.22	42.2331
2121.12	44.8866
2124.02	47.9608
2126.92	50.7557
2129.82	54.238
2132.72	56.0621
2135.62	58.5768
2138.51	61.9342
2141.41	65.1241
2144.3	68.0406
2147.19	70.2072
2150.09	72.9446
2152.97	75.8391
2155.86	77.916
2158.75	79.8149
2161.64	81.3114
2164.53	83.0735
2167.41	82.9608
2170.3	82.8102
2173.18	81.9172
2176.06	81.111
2178.94	80.2656
2181.82	78.9287
2184.7	76.6612
2187.58	74.6031
2190.46	71.9866
2193.33	70.7665
2196.21	69.7193
2199.08	66.9954
2201.95	64.5978
2204.83	62.5695
2207.7	60.0273
2210.57	58.6029
2213.43	57.0854
2216.3	54.4778
2219.17	51.2822
2222.03	48.7407
2224.9	45.4018
2227.76	42.8445
2230.62	40.0481
2233.49	37.228
2236.34	34.5195
2239.2	30.8853
2242.06	28.9676
2244.92	27.5571
2247.78	25.616
2250.63	23.3678
2253.48	20.7053
2256.34	19.5169
2259.19	19.0495
2262.04	18.5589
2264.89	18.2384
2267.74	16.6897
2270.59	15.9882
2273.43	16.7171
2276.28	16.1337
2279.12	15.8252
2281.97	14.9461
2284.81	13.8727
2287.65	11.7781
2290.49	10.824
2293.33	8.77881
2296.17	8.24571
2299.01	7.64863
2301.84	7.51076
2304.68	7.69008
2307.51	7.78453
2310.35	8.12455
2313.18	7.90144
2316.01	7.76062
2318.84	7.30358
2321.67	6.89078
2324.5	7.72588
2327.33	7.28088
2330.15	7.15355
2332.98	7.24028
2335.8	5.96638
2338.62	5.36988
2341.45	5.08409
2344.27	4.09323
2347.09	2.53122
2349.91	1.99664
2352.72	0.73457
2355.54	-0.00396369
2358.36	-0.965852
2361.17	-1.93863
2363.98	-0.859948
2366.8	-0.238005
2369.61	0.809951
2372.42	1.25061
2375.23	2.07942
2378.04	2.62958
2380.85	2.62612
2383.66	3.02334
2386.46	4.05257
2389.26	5.28739
2392.07	6.43856
2394.87	6.66392
2397.67	6.87797
2400.47	7.0626
2403.27	6.9042
2406.07	6.13244
2408.87	5.94209
2411.67	6.04791
2414.46	5.72397
2417.26	6.08333
2420.05	6.25877
2422.84	6.05494
2425.64	5.38856
2428.43	4.98315
2431.22	5.24723
2434.01	5.42671
2436.79	4.43867
2439.58	5.21269
2442.37	4.57942
2445.15	4.68322
2447.93	4.66315
2450.72	4.48253
2453.5	5.30505
2456.28	6.77917
2459.06	6.97464
2461.84	6.48499
2464.62	6.0992
2467.39	5.23926
2470.17	5.79335
2472.94	5.464
2475.72	5.77319
2478.49	5.26172
2481.26	4.65042
2484.03	4.12329
2486.8	4.0353
2489.57	3.43032
2492.34	2.12146
2495.1	2.02644
2497.87	1.46708
2500.63	1.84512
2503.4	0.93695
2506.16	0.962141
2508.92	0.72568
2511.68	0.46118
2514.44	0.261253
2517.2	0.562558
2519.96	1.04029
2522.72	1.94928
2525.47	1.81421
2528.23	2.44944
2530.98	1.86499
2533.74	1.93109
2536.49	2.91599
2539.24	3.37735
2541.99	2.79264
2544.74	3.73369
2547.49	4.53997
2550.23	5.32775
2552.98	6.06755
2555.72	5.68575
2558.47	5.8155
2561.21	5.99774
2563.95	6.73158
2566.69	6.64294
2569.43	7.27389
2572.17	6.56601
2574.91	6.93737
2577.65	7.53559
2580.39	6.97263
2583.12	6.48988
2585.85	6.74808
2588.59	5.99619
2591.32	6.22332
2594.05	5.91571
2596.78	5.75392
2599.51	4.31407
2602.24	5.16827
2604.97	4.83487
2607.69	4.88927
2610.42	4.48536
2613.14	4.13737
2615.87	3.10688
2618.59	2.92548
2621.31	3.0943
2624.03	3.00319
2626.75	3.34355
2629.47	2.7493
2632.19	1.71725
2634.91	1.8419
2637.62	1.4433
2640.34	1.46568
2643.05	1.20635
2645.76	1.83998
2648.48	1.49064
2651.19	1.40312
2653.9	2.18011
2656.6	3.64225
2659.31	3.97091
2662.02	4.99966
2664.73	5.6135
2667.43	6.37068
2670.14	6.52479
2672.84	5.70971
2675.54	5.52858
2678.24	4.48576
2680.94	4.11354
2683.64	4.17867
2686.34	4.0026
2689.04	3.78429
2691.74	3.79254
2694.43	3.85992
2697.13	3.93454
2699.82	4.47104
2702.51	4.4422
2705.21	4.19405
2707.9	4.67203
2710.58	5.46799
2713.27	6.94671
2715.96	7.71706
2718.65	9.5436
2721.33	11.3346
2724.02	12.0541
2726.71	12.4489
2729.39	12.9363
2732.07	13.1043
2734.75	12.7334
2737.43	12.1917
2740.11	11.6824
2742.79	9.74147
2745.47	9.0396
2748.14	7.56652
2750.82	6.88563
2753.49	6.88946
2756.17	6.91548
2758.84	5.45664
2761.51	4.84948
2764.18	4.10363
2766.85	2.64192
2769.52	1.80833
2772.19	1.81021
2774.86	0.96009
2777.52	1.74905
2780.19	1.73443
2782.85	1.87608
2785.52	1.04916
2788.18	0.767594
2790.84	0.833027
2793.5	0.78729
2796.16	0.0200189
2798.82	0.586664
2801.48	0.181858
2804.13	0.50165
2806.79	-0.357232
2809.45	-1.14903
2812.1	-0.704097
2814.75	-0.271592
2817.41	1.26346
2820.06	3.62133
2822.71	6.79753
2825.36	9.87465
2828	14.0867
2830.65	18.8277
2833.3	24.1644
2835.94	29.0969
2838.59	34.2443
2841.23	39.367
2843.87	44.413
2846.52	50.5076
2849.16	55.5227
2851.8	62.4865
2854.44	68.902
2857.08	75.1489
2859.71	81.3778
2862.35	86.3695
2864.98	90.903
2867.62	95.4824
2870.25	99.9567
2872.88	102.463
2875.52	105.81
2878.15	109.777
2880.78	112.413
2883.41	116.2
2886.03	120.105
2888.66	123.51
2891.29	127.245
2893.91	131.158
2896.54	134.91
2899.16	139.091
2901.78	144.1
2904.4	149.108
2907.02	154.849
2909.64	161.79
2912.26	169.524
2914.88	177.396
2917.5	184.556
2920.11	191.668
2922.73	197.601
2925.34	199.932
2927.96	201.785
2930.57	203.269
2933.18	203.302
2935.79	201.383
2938.4	198.132
2941.01	194.003
2943.62	189.024
2946.22	183.941
2948.83	177.451
2951.43	171.096
2954.04	163.853
2956.64	155.565
2959.24	148.106
2961.84	141.457
2964.45	133.764
2967.05	127.358
2969.64	120.993
2972.24	114.205
2974.84	107.742
2977.43	100.808
2980.03	93.9349
2982.62	86.0591
2985.22	78.7245
2987.81	70.1564
2990.4	61.944
2992.99	54.5415
2995.58	48.2197
2998.17	41.7425
3000.76	36.1925
3003.34	31.1245
3005.93	26.9703
3008.52	23.0267
3011.1	19.095
3013.68	15.5804
3016.27	13.2082
3018.85	10.8535
3021.43	9.52342
3024.01	8.60826
3026.59	7.69924
3029.16	7.73127
3031.74	8.11963
3034.32	7.52575
3036.89	7.10262
3039.47	7.73876
3042.04	8.71517
3044.61	9.33965
3047.18	10.1462
3049.75	9.69785
3052.32	9.63571
3054.89	10.2632
3057.46	10.1461
3060.03	9.43946
3062.59	9.41354
3065.16	8.40514
3067.72	8.05807
3070.29	6.55024
3072.85	5.06194
3075.41	3.87061
3077.97	3.21165
3080.53	2.54473
3083.09	2.66573
3085.65	2.12791
3088.21	1.76433
3090.76	2.47525
3093.32	3.4042
3095.87	3.75561
3098.43	4.03161
3100.98	5.23722
3103.53	6.51487
3106.08	7.84608
3108.63	8.86659
3111.18	9.99045
3113.73	10.6616
3116.28	12.2034
3118.83	12.4687
3121.37	12.6067
3123.92	13.3004
3126.46	13.6347
3129	14.8202
3131.55	14.7137
3134.09	14.9402
3136.63	16.2038
3139.17	17.0657
3141.71	18.4078
3144.24	19.6305
3146.78	20.6642
3149.32	22.3944