File: data/Raman/poly_smoothed/Thy_00_07_23_1x_45s_532 nm_x100_100%_600 gr_mm_01.txt
#Acq. time (s)=	45
#Accumulations=	2
#Range (cm-¹)=	200...3150
#Windows=	2
#Auto scanning=	Off
#Autofocus=	Off
#Macrospot=	Off
#AutoExposure=	Off
#Spike filter=	Multiple accum.
#Delay time (s)=	0
#Binning=	1
#Readout mode=	Signal
#DeNoise=	Off
#ICS correction=	On
#Dark correction=	Off
#Inst. Process=	Off
#Detector Gain=	Best Dynamic Range
#Detector ADC=	20 kHz
#Detector temperature (°C)=	-69.85
#Instrument=	LabRAM HR Evol
#Detector=	Synapse
#Objective=	x100
#Grating=	600 gr/mm
#ND Filter=	100%
#Laser (nm)=	532
#Hole=	100.021
#Range=	Auto
#Laser Pol.=	No
#Raman. Pol.=	No
#Laser Pol. (°)=	-0.0007625
#Raman Pol. (°)=	89.9995
#Collection=	Microscope
#StageXY=	Marzhauser
#StageZ=	Marzhauser
#X (µm)=	8998.5
#Y (µm)=	-3064.3
#Z (µm)=	-54.65
#Full time(mm:ss)=	3:19
#Project=
#Sample=
#Site=
#Title=	Thy_00_07_23_2x_45s_532 nm_x100_100%_600 gr_mm
#Remark=
#Date=	28.06.2022 11:49
#Acquired=	28.06.2022 11:49:37
#Base:Fit=	10.08.2022 10:07:56
#Base:Sub=	10.08.2022 10:08:40
#Filter:Polynom=	16.08.2022 10:26:06
#AxisType[0]=Intens
#AxisUnit[0]=Cnt
#AxisType[1]=Spectr
#AxisUnit[1]=1/cm
200.407	5.15973
204.035	13.0448
207.665	16.168
211.291	19.9042
214.916	21.9701
218.541	22.2645
222.163	23.0403
225.785	22.3103
229.404	21.1615
233.022	17.4137
236.638	15.5113
240.255	13.6601
243.868	12.2995
247.48	11.2797
251.091	10.6121
254.702	8.85185
258.31	7.04211
261.916	4.06625
265.521	4.70168
269.125	5.12879
272.727	4.54152
276.328	2.90119
279.927	5.00129
283.525	5.36702
287.121	6.85054
290.716	8.86269
294.31	13.3631
297.9	17.8315
301.491	20.1535
305.081	22.3171
308.669	24.0425
312.256	27.5317
315.839	29.2653
319.423	29.8648
323.006	30.7699
326.585	32.215
330.165	31.6684
333.741	32.4747
337.318	31.9771
340.894	30.5761
344.466	29.807
348.039	28.1727
351.608	28.3501
355.176	27.3583
358.745	22.7565
362.31	19.6888
365.876	19.69
369.439	21.4641
373	26.1051
376.56	33.2355
380.12	44.1954
383.677	52.5109
387.233	60.381
390.787	67.9354
394.34	75.0301
397.894	80.6887
401.444	84.6551
404.993	85.0945
408.54	85.9513
412.086	85.5185
415.631	82.4377
419.174	79.494
422.716	74.8457
426.257	70.652
429.794	62.5102
433.332	53.674
436.868	45.5342
440.403	39.1319
443.937	33.3446
447.468	26.4603
450.999	27.9005
454.528	28.0188
458.057	32.1732
461.582	38.2891
465.107	44.965
468.629	47.7532
472.152	50.083
475.672	55.1635
479.192	57.6058
482.709	61.7208
486.226	63.8467
489.74	66.2398
493.255	68.2978
496.767	69.7165
500.277	71.1188
503.788	69.2722
507.295	68.0149
510.801	64.2187
514.308	59.4627
517.811	56.0438
521.313	53.092
524.814	54.1459
528.313	50.0055
531.811	45.9872
535.308	41.7938
538.803	39.2959
542.297	36.4636
545.789	35.7139
549.281	32.906
552.771	29.0094
556.259	28.4548
559.747	29.1565
563.233	30.4251
566.717	31.8673
570.2	33.8965
573.68	32.2034
577.161	32.2769
580.64	30.9569
584.118	29.7891
587.593	29.1652
591.068	29.1762
594.54	28.1441
598.013	25.0781
601.484	22.4922
604.952	18.6512
608.421	15.605
611.886	12.6476
615.35	10.1514
618.815	7.48431
622.276	6.82571
625.738	6.16213
629.197	2.75432
632.655	1.90926
636.113	0.429892
639.568	0.154995
643.021	1.49948
646.473	3.34036
649.924	4.44042
653.376	4.94744
656.824	4.25573
660.271	3.84233
663.716	4.97792
667.161	5.05671
670.604	5.11888
674.045	5.33616
677.486	5.76111
680.925	4.62587
684.361	6.40213
687.797	7.97096
691.232	11.0386
694.666	11.2694
698.099	13.4108
701.528	14.0296
704.958	14.4952
708.387	15.6269
711.814	16.7417
715.238	18.7133
718.663	21.0939
722.084	24.6458
725.506	26.863
728.925	31.7523
732.345	36.2384
735.761	39.6839
739.178	42.6986
742.592	48.013
746.006	53.8788
749.417	55.6884
752.827	62.3771
756.236	66.7065
759.645	70.6296
763.051	72.8866
766.456	73.4177
769.859	74.3296
773.261	73.094
776.664	71.2367
780.064	67.7218
783.462	65.3777
786.859	60.1402
790.255	57.413
793.649	55.4481
797.042	50.6513
800.434	49.0873
803.823	45.4196
807.212	44.6367
810.6	41.2024
813.987	42.1531
817.372	42.7896
820.754	45.1837
824.137	50.1014
827.519	53.9335
830.897	58.3006
834.276	60.2119
837.654	62.3978
841.029	62.3543
844.404	62.9063
847.776	60.2358
851.149	59.368
854.519	55.6993
857.889	53.2256
861.256	50.0631
864.622	46.7493
867.988	43.8388
871.351	39.8562
874.713	36.0259
878.074	31.9592
881.435	28.1964
884.794	26.06
888.15	24.5903
891.506	21.7748
894.861	20.1325
898.214	21.7586
901.566	25.4858
904.916	28.8235
908.266	30.6594
911.614	32.1134
914.961	33.283
918.306	33.8314
921.651	35.5671
924.994	35.3581
928.336	34.0236
931.674	32.4088
935.014	29.772
938.352	30.3207
941.687	29.093
945.022	27.2575
948.357	25.3086
951.688	24.9649
955.02	22.9616
958.348	16.7902
961.678	11.839
965.004	13.7225
968.331	15.969
971.655	18.3589
974.979	21.5882
978.3	25.8022
981.62	29.0714
984.941	29.7777
988.259	27.47
991.575	28.4296
994.89	30.6795
998.204	33.2223
1001.52	36.7126
1004.83	38.2063
1008.14	38.6374
1011.45	40.1177
1014.76	42.2353
1018.06	41.7614
1021.37	44.0963
1024.67	42.1999
1027.97	43.4764
1031.27	40.9832
1034.57	37.1732
1037.87	31.3456
1041.17	28.9105
1044.47	31.2419
1047.76	32.3905
1051.06	33.0373
1054.35	32.22
1057.64	31.3413
1060.93	28.7194
1064.22	27.0043
1067.5	27.8164
1070.79	29.6479
1074.08	35.8831
1077.36	40.1521
1080.64	42.4785
1083.92	42.7072
1087.2	46.5592
1090.48	49.2812
1093.76	55.3418
1097.03	59.9304
1100.31	64.6273
1103.58	68.8971
1106.85	71.7115
1110.12	71.5978
1113.39	70.2573
1116.66	69.2023
1119.93	68.5711
1123.19	67.1033
1126.46	64.977
1129.72	62.2387
1132.98	61.6087
1136.24	57.5421
1139.5	54.3437
1142.76	51.5977
1146.01	49.4171
1149.27	47.713
1152.53	42.5931
1155.78	37.0555
1159.03	29.8257
1162.28	23.6278
1165.53	19.8464
1168.78	18.7054
1172.02	17.5232
1175.27	17.0944
1178.51	16.3926
1181.76	16.0611
1185	14.9253
1188.24	14.6122
1191.48	13.2296
1194.71	16.3532
1197.95	20.8982
1201.19	24.8591
1204.42	31.6152
1207.65	38.0256
1210.88	46.0027
1214.12	55.6215
1217.35	63.4307
1220.57	71.3525
1223.8	79.9664
1227.03	87.8871
1230.25	94.3211
1233.47	99.2513
1236.69	102.148
1239.92	105.702
1243.13	107.849
1246.35	111.491
1249.57	111.257
1252.78	109.26
1256	107.493
1259.21	104.466
1262.42	99.497
1265.63	96.4491
1268.84	94.1439
1272.05	91.6478
1275.26	94.5563
1278.46	96.2808
1281.67	99.2019
1284.87	104.021
1288.07	111.296
1291.27	117.155
1294.47	125.445
1297.67	132.213
1300.87	141.158
1304.06	150.788
1307.26	160.152
1310.45	170.005
1313.64	179.556
1316.83	187.036
1320.02	192.579
1323.21	194.933
1326.4	196.599
1329.59	198.455
1332.77	196.052
1335.95	195.451
1339.14	191.978
1342.32	188.631
1345.5	183.55
1348.67	177.599
1351.85	173.19
1355.03	168.615
1358.2	162.588
1361.38	156.904
1364.55	151.955
1367.72	147.822
1370.89	143.638
1374.06	141.153
1377.23	138.978
1380.39	136.701
1383.56	134.74
1386.72	133.068
1389.89	130.74
1393.05	126.645
1396.21	120.531
1399.37	115.864
1402.52	113.594
1405.68	113.853
1408.84	114.628
1411.99	116.532
1415.15	122.331
1418.3	127.732
1421.45	135.413
1424.6	145.361
1427.75	154.984
1430.89	166.332
1434.04	178.531
1437.18	188.649
1440.33	199.207
1443.47	208.634
1446.61	215.56
1449.75	217.282
1452.89	218.077
1456.03	213.716
1459.16	207.337
1462.3	198.18
1465.43	187.266
1468.56	171.69
1471.7	155.09
1474.83	140.339
1477.96	124.594
1481.08	109.826
1484.21	95.7263
1487.34	82.9919
1490.46	70.782
1493.58	63.0149
1496.71	55.8724
1499.83	52.5626
1502.95	48.1488
1506.07	46.5065
1509.18	44.8875
1512.3	45.2013
1515.41	46.5838
1518.53	47.9207
1521.64	50.1318
1524.75	52.1595
1527.86	54.5409
1530.97	59.5624
1534.08	62.8793
1537.19	67.4581
1540.29	71.7163
1543.4	76.769
1546.5	83.3452
1549.6	90.8142
1552.7	100.939
1555.8	108.363
1558.9	117.348
1562	125.119
1565.09	133.587
1568.19	142.562
1571.28	150.28
1574.37	157.007
1577.47	164.095
1580.56	169.473
1583.64	172.571
1586.73	176.714
1589.82	180.116
1592.9	179.508
1595.99	177.331
1599.07	175.916
1602.15	172.423
1605.23	167.713
1608.31	162.731
1611.39	158.527
1614.47	155.355
1617.55	154.023
1620.62	150.783
1623.7	148.762
1626.77	149.286
1629.84	148.99
1632.91	149.871
1635.98	151.078
1639.05	153.381
1642.11	156.924
1645.18	158.787
1648.24	161.132
1651.31	162.374
1654.37	162.546
1657.43	163.23
1660.49	163.151
1663.55	159.352
1666.61	155
1669.66	147.648
1672.72	140.458
1675.77	132.227
1678.83	124.519
1681.88	116.101
1684.93	108.62
1687.98	98.1923
1691.03	89.3291
1694.07	79.7196
1697.12	69.4964
1700.17	60.8775
1703.21	52.7138
1706.25	45.8128
1709.29	40.006
1712.33	35.4397
1715.37	31.616
1718.41	28.2642
1721.45	25.6815
1724.49	24.7666
1727.52	21.8192
1730.55	20.9706
1733.59	20.4907
1736.62	19.3249
1739.65	16.7348
1742.68	13.9129
1745.7	12.4244
1748.73	11.9716
1751.76	9.76306
1754.78	8.65876
1757.8	6.95869
1760.83	4.61973
1763.85	4.18465
1766.87	2.90373
1769.89	0.971631
1772.9	-0.152998
1775.92	-2.02066
1778.94	-2.82885
1781.95	-1.74442
1784.96	-1.55863
1787.97	0.168664
1790.99	0.737383
1794	2.45418
1797	3.33513
1800.01	3.46921
1803.02	3.83552
1806.02	5.03107
1809.03	5.19531
1812.03	5.27842
1815.03	5.76112
1818.03	7.40384
1821.03	8.54427
1824.03	6.9626
1827.03	7.55248
1830.02	7.56925
1833.02	7.26855
1836.01	6.96752
1839.01	6.87375
1842	6.52004
1844.99	6.48494
1847.98	6.5064
1850.97	7.50862
1853.95	7.69029
1856.94	8.10521
1859.93	7.74002
1862.91	7.81821
1865.89	8.83348
1868.87	9.16531
1871.85	7.99243
1874.83	7.74461
1877.81	7.6212
1880.79	7.63262
1882.52	7.29564
1885.51	6.96186
1888.5	6.12607
1891.49	5.09966
1894.47	4.17567
1897.46	3.44689
1900.44	2.58349
1903.42	1.29929
1906.4	0.849706
1909.38	0.534651
1912.36	1.89962
1915.34	1.69105
1918.32	3.41695
1921.29	3.83951
1924.27	4.29382
1927.24	4.1454
1930.21	4.32882
1933.18	5.65083
1936.15	6.9052
1939.12	7.44914
1942.09	6.85758
1945.06	7.47149
1948.02	7.31466
1950.99	8.18392
1953.95	7.60497
1956.91	6.91437
1959.88	7.96497
1962.84	7.28842
1965.8	5.88716
1968.75	4.9584
1971.71	2.76535
1974.67	2.23237
1977.62	2.19922
1980.58	2.78519
1983.53	3.23262
1986.48	2.17148
1989.43	3.32315
1992.38	2.59039
1995.33	3.53667
1998.27	3.28989
2001.22	5.02139
2004.16	4.2432
2007.11	4.9954
2010.05	6.19439
2012.99	7.05667
2015.93	5.90942
2018.87	6.88192
2021.81	7.17108
2024.75	6.72042
2027.69	6.50424
2030.62	7.08275
2033.56	7.53024
2036.49	6.16362
2039.42	6.38318
2042.35	5.71641
2045.28	6.53726
2048.21	5.22558
2051.14	6.10354
2054.07	6.72036
2056.99	7.36007
2059.92	8.65769
2062.84	9.2607
2065.76	9.5324
2068.68	10.5283
2071.6	11.0668
2074.52	11.3378
2077.44	11.5469
2080.36	12.328
2083.27	11.6007
2086.19	11.0104
2089.1	10.1936
2092.02	8.23475
2094.93	6.92801
2097.84	5.27006
2100.75	5.05677
2103.66	4.62774
2106.56	4.06147
2109.47	2.46068
2112.38	1.21265
2115.28	1.69374
2118.18	0.833823
2121.09	2.02407
2123.99	2.76778
2126.89	2.68643
2129.79	3.93117
2132.68	4.55693
2135.58	5.83301
2138.48	6.01484
2141.37	6.1471
2144.27	8.27712
2147.16	9.41871
2150.05	9.73208
2152.94	11.1709
2155.83	11.4689
2158.72	11.2884
2161.6	9.93157
2164.49	9.29827
2167.38	9.11297
2170.26	8.10987
2173.14	8.8069
2176.03	7.24525
2178.91	6.93491
2181.79	5.70896
2184.67	6.47479
2187.54	6.15582
2190.42	5.4012
2193.3	4.66799
2196.17	3.58455
2199.05	3.29747
2201.92	3.28621
2204.79	3.92867
2207.66	4.01591
2210.53	3.48232
2213.4	4.71159
2216.27	6.42124
2219.13	7.66435
2222	8.20251
2224.86	9.82244
2227.72	8.79751
2230.59	8.31502
2233.45	8.8505
2236.31	8.44967
2239.17	8.27482
2242.03	9.16641
2244.88	9.52094
2247.74	9.82537
2250.59	9.62572
2253.45	9.48162
2256.3	8.72403
2259.15	8.2368
2262	6.47157
2264.85	7.15128
2267.7	7.14748
2270.55	7.09716
2273.4	8.38322
2276.24	7.70042
2279.09	8.34111
2281.93	8.6107
2284.77	8.36877
2287.62	9.31594
2290.46	9.69576
2293.3	7.42556
2296.13	6.89852
2298.97	6.06569
2301.81	6.4838
2304.64	6.12858
2307.48	6.11813
2310.31	6.26428
2313.14	6.32927
2315.98	4.55485
2318.81	4.2072
2321.64	3.14309
2324.46	2.17687
2327.29	1.81506
2330.12	1.31213
2332.94	2.06239
2335.77	2.03164
2338.59	1.71274
2341.41	2.26378
2344.23	1.58427
2347.05	2.0499
2349.87	1.9152
2352.69	1.72016
2355.51	0.626024
2358.32	0.599834
2361.14	-1.09627
2363.95	-0.719293
2366.76	-0.0576274
2369.58	-0.303511
2372.39	-0.901161
2375.2	-0.573433
2378	-1.0096
2380.81	-0.000289567
2383.62	-1.512
2386.43	-1.30307
2389.23	-1.60134
2392.03	-0.630627
2394.84	-1.13303
2397.64	-1.47263
2400.44	-1.623
2403.24	0.643087
2406.04	1.58959
2408.84	4.25264
2411.63	5.0557
2414.43	6.6711
2417.22	6.90125
2420.02	7.37472
2422.81	7.04573
2425.6	7.24284
2428.39	7.92373
2431.18	8.02543
2433.97	8.08122
2436.76	8.48788
2439.54	8.72577
2442.33	8.61056
2445.12	8.6892
2447.9	8.75709
2450.68	6.903
2453.46	6.36656
2456.24	6.99233
2459.02	6.84183
2461.8	6.81526
2464.58	7.10202
2467.36	6.60046
2470.13	7.68403
2472.91	8.16647
2475.68	9.4685
2478.45	9.3431
2481.23	8.25266
2484	7.47719
2486.77	7.05578
2489.54	6.50185
2492.3	6.43471
2495.07	6.77164
2497.84	5.43627
2500.6	5.13439
2503.36	5.35898
2506.13	3.87553
2508.89	4.12334
2511.65	4.82881
2514.41	4.95688
2517.17	5.86771
2519.93	6.26484
2522.68	6.84606
2525.44	6.49093
2528.19	7.12796
2530.95	8.68839
2533.7	9.51039
2536.45	8.90729
2539.2	9.61423
2541.95	10.379
2544.7	10.1889
2547.45	11.3893
2550.2	12.0274
2552.94	10.814
2555.69	11.0777
2558.43	11.1327
2561.18	12.1363
2563.92	10.2379
2566.66	10.3421
2569.4	9.93608
2572.14	9.45039
2574.88	9.5422
2577.61	9.85313
2580.35	8.71484
2583.09	8.33539
2585.82	7.99443
2588.55	8.16151
2591.29	8.31965
2594.02	8.20717
2596.75	10.4199
2599.48	10.2407
2602.21	10.4131
2604.93	11.1622
2607.66	11.7562
2610.39	12.0355
2613.11	12.362
2615.83	12.1514
2618.56	11.7923
2621.28	11.6873
2624	12.0765
2626.72	12.0742
2629.44	10.2567
2632.15	8.69969
2634.87	8.46908
2637.59	7.6688
2640.3	7.55568
2643.02	6.55707
2645.73	5.29246
2648.44	5.2491
2651.15	5.29577
2653.86	5.54004
2656.57	5.42837
2659.28	5.37819
2661.99	7.627
2664.69	9.22185
2667.4	10.063
2670.1	12.1587
2672.81	12.4193
2675.51	13.635
2678.21	13.5211
2680.91	14.1076
2683.61	14.3635
2686.31	15.3141
2689	14.5258
2691.7	16.0394
2694.4	15.6365
2697.09	15.3719
2699.79	16.2406
2702.48	16.8598
2705.17	18.3107
2707.86	18.599
2710.55	19.1961
2713.24	20.3293
2715.93	20.7879
2718.62	21.1931
2721.3	21.3573
2723.99	21.7807
2726.67	23.9097
2729.35	23.8341
2732.04	25.0449
2734.72	24.0792
2737.4	24.0164
2740.08	23.0287
2742.76	20.1641
2745.43	19.3025
2748.11	17.8809
2750.79	17.3908
2753.46	15.8386
2756.14	14.5395
2758.81	13.6932
2761.48	10.1693
2764.15	8.58477
2766.82	7.30141
2769.49	6.81901
2772.16	5.39449
2774.82	4.76196
2777.49	4.13628
2780.16	3.81436
2782.82	3.27318
2785.48	2.58931
2788.15	3.51576
2790.81	4.33724
2793.47	3.75247
2796.13	4.03903
2798.79	4.80461
2801.44	4.42515
2804.1	5.49489
2806.76	4.76658
2809.41	3.74038
2812.07	5.84849
2814.72	7.69885
2817.37	9.07183
2820.02	11.415
2822.67	14.8372
2825.32	19.5562
2827.97	24.6387
2830.62	31.2399
2833.26	38.4651
2835.91	45.9673
2838.56	55.6424
2841.2	66.9797
2843.84	80.4482
2846.48	95.6333
2849.12	112.194
2851.77	129.896
2854.4	148.524
2857.04	167.121
2859.68	185.753
2862.32	204.402
2864.95	223.306
2867.59	241.025
2870.22	258.264
2872.85	271.955
2875.48	286.463
2878.11	301.137
2880.74	315.028
2883.37	328.238
2886	340.359
2888.63	352.254
2891.25	364.432
2893.88	375.335
2896.5	387.278
2899.13	398.767
2901.75	412.065
2904.37	426.027
2906.99	443.631
2909.61	459.75
2912.23	475.923
2914.85	492.681
2917.46	506.134
2920.08	517.58
2922.7	527.708
2925.31	533.495
2927.92	538.854
2930.54	539.726
2933.15	536.426
2935.76	529.325
2938.37	519.713
2940.98	508.683
2943.58	495.01
2946.19	481.037
2948.8	463.666
2951.4	446.425
2954.01	429.336
2956.61	411.594
2959.21	394.332
2961.81	377.299
2964.41	360.82
2967.01	344.802
2969.61	328.881
2972.21	313.55
2974.81	296.864
2977.4	279.722
2980	261.119
2982.59	243.731
2985.18	224.58
2987.78	205.135
2990.37	186.652
2992.96	168.807
2995.55	149.692
2998.14	129.792
3000.73	111.593
3003.31	95.3072
3005.9	78.6367
3008.48	64.746
3011.07	51.9835
3013.65	40.2416
3016.23	31.4353
3018.81	23.2297
3021.4	16.1352
3023.97	11.4108
3026.55	6.69635
3029.13	3.14981
3031.71	0.423444
3034.28	-0.360072
3036.86	0.69111
3039.43	2.45226
3042.01	5.24452
3044.58	8.63176
3047.15	10.7355
3049.72	13.2799
3052.29	16.7757
3054.86	18.8053
3057.43	20.1104
3060	21.0704
3062.56	20.3394
3065.13	20.0556
3067.69	18.9251
3070.26	17.8302
3072.82	16.6295
3075.38	14.5873
3077.94	12.0438
3080.5	8.65986
3083.06	5.12643
3085.62	2.37783
3088.18	1.29499
3090.73	-0.542095
3093.29	-0.843652
3095.84	-0.590671
3098.4	0.803756
3100.95	2.32293
3103.5	3.64082
3106.05	6.73798
3108.6	10.0924
3111.15	12.6952
3113.7	15.4938
3116.25	18.6832
3118.79	22.3021
3121.34	25.924
3123.88	29.7378
3126.43	32.3006
3128.97	35.9499
3131.51	40.13
3134.06	44.4788
3136.6	47.4296
3139.14	50.6082
3141.67	54.5221
3144.21	57.7862
3146.75	60.0842
3149.29	60.9685