File: data/Raman/poly_smoothed/Thy_40_11_03_1x_45s_532 nm_x100_100%_600 gr_mm_01.txt
#Acq. time (s)=	45
#Accumulations=	2
#Range (cm-¹)=	200...3150
#Windows=	2
#Auto scanning=	Off
#Autofocus=	Off
#Macrospot=	Off
#AutoExposure=	Off
#Spike filter=	Multiple accum.
#Delay time (s)=	0
#Binning=	1
#Readout mode=	Signal
#DeNoise=	Off
#ICS correction=	On
#Dark correction=	Off
#Inst. Process=	Off
#Detector Gain=	Best Dynamic Range
#Detector ADC=	20 kHz
#Detector temperature (°C)=	-69.85
#Instrument=	LabRAM HR Evol
#Detector=	Synapse
#Objective=	x100
#Grating=	600 gr/mm
#ND Filter=	100%
#Laser (nm)=	532
#Hole=	100.021
#Range=	Auto
#Laser Pol.=	No
#Raman. Pol.=	No
#Laser Pol. (°)=	-0.0007625
#Raman Pol. (°)=	89.9995
#Collection=	Microscope
#StageXY=	Marzhauser
#StageZ=	Marzhauser
#X (µm)=	1973.1
#Y (µm)=	-91.6
#Z (µm)=	425.4
#Full time(mm:ss)=	3:18
#Project=
#Sample=
#Site=
#Title=	Thy_40_11_03_2x_45s_532 nm_x100_100%_600 gr_mm
#Remark=
#Date=	05.07.2022 10:04
#Acquired=	05.07.2022 10:04:45
#Base:Fit=	10.08.2022 10:00:48
#Base:Fit=	10.08.2022 10:01:07
#Base:Fit=	10.08.2022 10:01:15
#Base:Fit=	10.08.2022 10:01:35
#Base:Sub=	10.08.2022 10:01:52
#Filter:Polynom=	16.08.2022 10:21:53
#AxisType[0]=Intens
#AxisUnit[0]=Cnt
#AxisType[1]=Spectr
#AxisUnit[1]=1/cm
200.43	15.7363
204.059	12.0202
207.688	10.8391
211.314	10.4664
214.941	10.1277
218.564	9.3536
222.186	8.8412
225.809	6.62763
229.428	5.15717
233.045	5.48684
236.663	5.99384
240.278	4.45236
243.891	4.38179
247.503	3.7917
251.116	3.84348
254.725	4.57743
258.333	4.61467
261.939	5.22427
265.544	3.93622
269.148	4.15293
272.75	3.45449
276.351	3.85058
279.95	4.88784
283.548	4.10888
287.144	3.72871
290.739	2.87152
294.333	5.68201
297.925	5.02012
301.514	6.09637
305.104	6.30604
308.692	5.54587
312.279	5.29953
315.862	6.27913
319.446	7.03314
323.029	8.69448
326.608	9.18467
330.188	9.48869
333.766	12.0206
337.341	12.207
340.917	13.3798
344.489	13.0004
348.062	12.664
351.631	12.6941
355.201	10.621
358.768	13.3074
362.333	11.2034
365.899	8.98335
369.462	6.30757
373.023	5.72216
376.585	5.07612
380.143	7.14417
383.7	7.07565
387.256	6.97842
390.812	6.86363
394.365	5.01197
397.916	5.2709
401.467	5.72876
405.015	7.06144
408.563	7.43262
412.109	10.4688
415.654	10.6519
419.197	12.0752
422.739	12.2339
426.279	12.483
429.819	13.0135
433.356	11.2223
436.891	10.4176
440.426	11.4456
443.96	10.0121
447.492	9.86437
451.021	9.29957
454.551	9.41697
458.079	9.78817
461.604	12.4365
465.13	13.2068
468.654	11.7904
472.175	13.6439
475.696	15.6326
479.215	17.3292
482.733	19.781
486.249	22.7575
489.765	24.129
493.278	25.6776
496.789	29.0646
500.301	31.5603
503.81	32.5594
507.317	33.492
510.825	34.1546
514.33	33.8128
517.833	32.4887
521.335	31.1968
524.836	29.5637
528.335	28.689
531.835	26.9861
535.332	26.7348
538.827	24.9004
542.321	23.7992
545.814	22.4774
549.305	18.5046
552.795	15.0093
556.282	15.8522
559.769	14.6541
563.255	12.1835
566.739	9.8322
570.223	8.52973
573.705	8.17026
577.183	7.63408
580.663	5.75317
584.141	6.46522
587.615	4.53017
591.09	2.68939
594.564	1.98669
598.035	0.501544
601.506	1.05644
604.974	1.15821
608.443	2.08351
611.908	4.44737
615.374	6.79109
618.837	8.37553
622.3	11.062
625.761	12.351
629.219	13.055
632.677	15.6451
636.135	17.4386
639.59	20.4917
643.043	22.5127
646.495	23.3042
649.948	24.8183
653.398	25.3727
656.846	25.434
660.293	27.2224
663.738	28.6486
667.183	29.095
670.626	30.5721
674.067	32.4668
677.508	33.2817
680.947	33.3138
684.385	33.9968
687.821	34.0964
691.254	37.3084
694.688	38.8491
698.121	40.5826
701.552	41.7453
704.98	45.0228
708.409	45.9381
711.836	46.4451
715.26	48.1721
718.685	48.3719
722.108	49.6897
725.528	50.7769
728.949	51.9172
732.367	50.8711
735.785	50.0954
739.2	51.6349
742.614	54.0489
746.028	57.3745
749.439	61.2952
752.849	63.838
756.26	67.3871
759.667	69.9516
763.073	70.4255
766.477	74.2199
769.883	77.3979
773.285	80.9665
776.686	82.617
780.085	84.7648
783.484	86.9092
786.881	90.6155
790.276	91.6494
793.671	90.6412
797.064	92.1224
800.456	92.7617
803.846	91.6252
807.234	92.0653
810.622	93.0757
814.008	93.2022
817.394	94.0046
820.778	95.2704
824.159	95.9474
827.541	94.9415
830.921	95.506
834.298	94.8352
837.676	95.309
841.051	93.8951
844.426	92.3659
847.798	91.7495
851.171	90.5154
854.54	89.1601
857.911	87.1177
861.278	86.7494
864.645	84.0497
868.01	83.0081
871.373	82.0726
874.735	80.1574
878.097	79.5766
881.457	77.8308
884.815	75.0683
888.172	74.6705
891.528	76.5578
894.882	77.3372
898.237	75.5938
901.589	72.8555
904.94	70.2507
908.289	67.6513
911.635	65.6671
914.982	64.9807
918.328	65.0201
921.672	64.7614
925.015	65.1987
928.357	62.5
931.698	62.1644
935.035	60.7822
938.373	59.7744
941.71	58.6065
945.044	57.33
948.378	55.2293
951.709	55.9505
955.041	55.9912
958.372	56.0005
961.699	54.9237
965.027	54.0747
968.352	56.8735
971.676	58.3376
975	56.7088
978.322	54.7601
981.642	49.5296
984.962	48.9793
988.28	48.2618
991.596	48.6947
994.911	51.1181
998.227	51.4439
1001.54	51.8887
1004.85	52.471
1008.16	50.9164
1011.47	50.7268
1014.78	50.3819
1018.08	51.4741
1021.39	51.3179
1024.69	49.9753
1028	51.1859
1031.3	52.819
1034.6	52.8625
1037.9	53.6931
1041.19	52.0951
1044.49	52.2939
1047.78	51.1907
1051.08	50.1556
1054.37	46.6586
1057.66	42.1864
1060.95	39.6164
1064.24	37.9675
1067.53	35.0637
1070.81	34.7767
1074.1	34.4899
1077.38	33.8377
1080.66	30.005
1083.94	28.1524
1087.22	27.9307
1090.5	27.6177
1093.78	27.1698
1097.05	27.4162
1100.33	27.2071
1103.6	26.5337
1106.87	26.542
1110.14	27.6507
1113.41	27.7933
1116.68	28.578
1119.95	27.4343
1123.21	26.0325
1126.48	23.3144
1129.74	20.5761
1133	19.2852
1136.26	17.0768
1139.52	16.2435
1142.78	16.8613
1146.04	15.7458
1149.29	16.4534
1152.55	14.7632
1155.8	13.8829
1159.05	10.8142
1162.3	9.79881
1165.55	12.829
1168.8	13.5403
1172.05	13.4629
1175.29	15.2651
1178.54	16.5742
1181.78	16.7838
1185.02	18.4306
1188.26	18.4245
1191.5	20.6859
1194.74	21.4728
1197.97	22.1484
1201.21	22.3749
1204.44	23.711
1207.68	26.1083
1210.91	27.8974
1214.14	32.1612
1217.37	36.0683
1220.59	39.2391
1223.82	42.412
1227.05	44.7544
1230.27	46.7021
1233.49	49.5692
1236.72	50.8781
1239.94	54.2157
1243.16	58.177
1246.37	61.5865
1249.59	64.6646
1252.8	66.5123
1256.02	68.3243
1259.23	68.9226
1262.44	72.7115
1265.66	75.6635
1268.86	78.096
1272.07	80.395
1275.28	84.4523
1278.48	85.973
1281.69	89.2005
1284.89	91.3933
1288.09	92.3551
1291.29	94.625
1294.49	96.3253
1297.69	98.5091
1300.89	98.7523
1304.08	100.883
1307.28	101.251
1310.47	103.363
1313.66	103.62
1316.85	105.602
1320.04	105.129
1323.23	103.197
1326.42	101.515
1329.61	100.955
1332.79	98.9778
1335.97	98.4242
1339.16	95.9421
1342.34	92.2638
1345.52	88.713
1348.7	83.097
1351.87	78.5498
1355.05	74.1041
1358.22	69.6378
1361.4	63.727
1364.57	60.6391
1367.74	56.1779
1370.91	54.6328
1374.08	53.2324
1377.25	50.4084
1380.41	48.7782
1383.58	47.3351
1386.74	47.0793
1389.91	46.7171
1393.07	44.7517
1396.23	43.8271
1399.39	42.6024
1402.55	42.7012
1405.7	43.0346
1408.86	44.4573
1412.01	45.2558
1415.17	46.7969
1418.32	47.086
1421.47	48.612
1424.62	51.5165
1427.77	54.0203
1430.91	56.8402
1434.06	63.6162
1437.2	69.4519
1440.35	74.3722
1443.49	78.1023
1446.63	81.6245
1449.77	82.6377
1452.91	82.345
1456.05	81.5613
1459.18	78.9982
1462.32	75.788
1465.45	70.6311
1468.59	65.3594
1471.72	60.5793
1474.85	54.4641
1477.98	48.6978
1481.1	42.1623
1484.23	33.3966
1487.36	27.8262
1490.48	23.3235
1493.61	18.7561
1496.73	14.8749
1499.85	12.8995
1502.97	12.2247
1506.09	12.0561
1509.2	14.261
1512.32	15.0154
1515.43	15.8869
1518.55	16.1862
1521.66	14.5289
1524.77	15.2062
1527.88	17.2148
1530.99	19.7858
1534.1	21.6687
1537.21	23.8917
1540.31	25.423
1543.42	27.0739
1546.52	30.3869
1549.62	33.356
1552.72	36.6964
1555.82	39.0073
1558.92	40.8945
1562.02	42.8304
1565.11	47.3062
1568.21	51.599
1571.3	55.3602
1574.39	58.7603
1577.49	62.2686
1580.57	64.1202
1583.66	67.367
1586.75	69.7447
1589.84	71.795
1592.92	72.0978
1596.01	73.2266
1599.09	74.7979
1602.17	76.8902
1605.25	76.5053
1608.33	76.8405
1611.41	77.6495
1614.49	78.1613
1617.57	78.283
1620.64	80.0513
1623.72	81.8008
1626.79	85.4592
1629.86	89.0399
1632.93	91.1352
1636	93.8541
1639.07	96.5187
1642.13	100.891
1645.2	104.5
1648.26	105.998
1651.33	107.97
1654.39	108.436
1657.45	108.34
1660.51	107.923
1663.57	105.742
1666.63	104.493
1669.68	100.028
1672.74	95.7991
1675.79	87.8121
1678.85	80.6906
1681.9	71.9661
1684.95	64.4696
1688	58.4987
1691.05	52.4064
1694.09	45.517
1697.14	37.8448
1700.18	33.0349
1703.23	27.5328
1706.27	23.5322
1709.31	19.7127
1712.35	17.703
1715.39	15.4574
1718.43	12.4852
1721.47	10.1263
1724.5	9.55448
1727.54	9.14874
1730.57	7.89932
1733.61	8.27013
1736.64	8.35392
1739.67	8.53742
1742.7	7.8168
1745.72	6.90558
1748.75	5.67385
1751.77	4.82768
1754.8	5.68456
1757.82	4.94401
1760.84	5.61626
1763.87	5.68773
1766.89	4.38671
1769.91	3.21193
1772.92	2.84067
1775.94	2.90565
1778.95	2.52269
1781.97	3.26325
1784.98	4.15747
1787.99	4.41074
1791.01	4.05463
1794.01	5.1168
1797.02	4.91987
1800.03	4.363
1803.04	3.80193
1806.04	3.27099
1809.05	3.8847
1812.05	2.16655
1815.05	2.38175
1818.05	2.57909
1821.05	3.02053
1824.05	2.28594
1827.05	2.032
1830.04	3.17408
1833.04	2.37035
1836.03	2.3252
1839.03	2.21338
1842.02	2.39641
1845.01	2.53476
1848	2.94883
1850.99	2.7272
1853.97	3.31806
1856.96	4.44526
1859.94	4.28806
1862.93	4.56811
1865.91	4.9434
1868.89	4.85292
1871.87	4.20436
1874.85	5.2443
1877.83	4.78627
1880.81	5.36333
1882.57	4.00001
1885.56	3.9755
1888.55	3.81203
1891.54	3.25357
1894.52	2.55954
1897.51	2.24088
1900.49	1.95504
1903.47	1.67356
1906.45	1.62591
1909.43	1.12236
1912.41	0.802657
1915.39	0.308068
1918.37	0.0578573
1921.34	-1.29223
1924.32	-1.37388
1927.29	-1.09207
1930.26	-0.654038
1933.23	-1.04501
1936.2	-0.355491
1939.17	-0.660952
1942.14	-0.249702
1945.11	-0.396658
1948.07	0.445683
1951.04	0.895657
1954	1.83048
1956.96	0.773058
1959.93	1.27392
1962.89	1.32113
1965.85	1.75081
1968.8	2.3158
1971.76	2.58896
1974.72	3.11912
1977.67	3.47564
1980.63	3.93188
1983.58	4.06044
1986.53	3.58551
1989.48	3.37741
1992.43	3.54297
1995.38	3.17401
1998.32	3.45081
2001.27	2.88802
2004.22	3.23029
2007.16	2.36722
2010.1	2.16223
2013.04	1.92946
2015.98	2.50605
2018.92	2.48415
2021.86	3.30359
2024.8	3.62175
2027.74	3.39717
2030.67	3.00646
2033.61	3.75524
2036.54	4.15677
2039.47	5.50207
2042.4	5.19135
2045.33	5.77832
2048.26	6.65583
2051.19	7.60551
2054.12	8.26211
2057.04	8.24407
2059.97	8.48155
2062.89	10.0657
2065.81	11.2026
2068.73	11.2302
2071.65	13.0973
2074.57	14.3597
2077.49	15.7313
2080.41	17.4138
2083.32	19.3075
2086.24	21.0798
2089.15	23.7253
2092.07	25.9715
2094.98	28.1439
2097.89	29.3836
2100.8	31.8938
2103.71	34.469
2106.61	37.7414
2109.52	41.9512
2112.43	44.58
2115.33	48.6488
2118.23	53.0226
2121.13	56.7998
2124.04	60.239
2126.94	64.0656
2129.83	67.912
2132.73	73.4219
2135.63	76.7747
2138.53	80.507
2141.42	84.8764
2144.31	89.1414
2147.21	94.9943
2150.1	99.5087
2152.99	103.097
2155.88	105.786
2158.77	109.429
2161.65	111.43
2164.54	114.82
2167.43	115.465
2170.31	115.546
2173.19	117.148
2176.07	117.881
2178.96	116.9
2181.84	116.679
2184.72	115.28
2187.59	113.345
2190.47	109.259
2193.35	104.815
2196.22	101.127
2199.09	96.2842
2201.97	91.9734
2204.84	87.6458
2207.71	82.2855
2210.58	79.0715
2213.45	75.82
2216.31	73.6579
2219.18	69.6482
2222.05	66.1204
2224.91	61.9043
2227.78	58.7363
2230.64	55.5098
2233.5	52.2048
2236.36	49.5838
2239.22	46.0846
2242.08	43.2154
2244.93	41.4121
2247.79	38.6775
2250.64	36.3366
2253.5	34.4445
2256.35	32.4278
2259.2	29.9058
2262.05	28.9026
2264.9	27.2389
2267.75	26.2102
2270.6	25.305
2273.45	24.9522
2276.29	25.5433
2279.14	25.3813
2281.98	24.1247
2284.82	24.4587
2287.66	23.1347
2290.5	21.8707
2293.34	19.7028
2296.18	18.8658
2299.02	18.9787
2301.86	18.8231
2304.69	19.0129
2307.53	18.909
2310.36	17.3728
2313.19	17.9062
2316.02	17.4873
2318.85	17.1925
2321.68	16.1899
2324.51	16.356
2327.34	16.2845
2330.16	16.3747
2332.99	14.1852
2335.81	13.3626
2338.64	12.9046
2341.46	11.3349
2344.28	9.04816
2347.1	7.91973
2349.92	5.77682
2352.74	3.75344
2355.55	3.00346
2358.37	0.627576
2361.19	-0.751256
2364	-1.67232
2366.81	-0.063513
2369.62	0.786713
2372.44	0.43856
2375.24	0.164261
2378.05	0.709554
2380.86	1.32995
2383.67	1.39804
2386.47	1.44481
2389.28	2.53255
2392.08	2.70728
2394.89	3.59136
2397.69	3.59166
2400.49	3.46353
2403.29	3.09458
2406.09	5.5813
2408.88	6.51036
2411.68	7.74475
2414.48	8.13652
2417.27	9.44843
2420.06	10.4075
2422.86	11.1177
2425.65	11.7148
2428.44	11.4964
2431.23	11.4556
2434.02	11.5162
2436.81	11.5364
2439.59	11.0678
2442.38	10.9069
2445.16	10.2668
2447.95	9.73559
2450.73	8.23323
2453.51	7.0596
2456.29	6.8087
2459.07	6.06631
2461.85	5.40719
2464.63	5.15684
2467.4	4.43239
2470.18	4.5637
2472.95	5.52228
2475.73	6.19739
2478.5	7.63919
2481.27	8.53183
2484.04	8.87216
2486.81	8.44633
2489.58	8.56389
2492.35	8.03694
2495.12	8.24761
2497.88	6.12402
2500.65	6.6562
2503.41	7.11775
2506.17	7.04257
2508.94	5.92201
2511.7	4.49311
2514.46	4.49663
2517.22	4.02026
2519.97	3.61068
2522.73	3.57436
2525.49	4.49789
2528.24	3.51625
2530.99	3.95109
2533.75	4.0881
2536.5	4.42527
2539.25	4.27661
2542	4.72841
2544.75	5.34325
2547.5	5.61857
2550.24	4.04243
2552.99	2.62125
2555.74	2.48635
2558.48	2.12342
2561.22	2.54231
2563.96	2.54322
2566.71	3.52371
2569.45	3.77051
2572.18	3.33587
2574.92	3.63946
2577.66	4.33143
2580.4	4.28919
2583.13	6.10052
2585.87	5.93917
2588.6	6.07183
2591.33	6.18972
2594.06	6.66045
2596.79	6.63944
2599.52	6.0322
2602.25	5.78094
2604.98	5.03394
2607.71	4.372
2610.43	4.71673
2613.16	3.68575
2615.88	2.84116
2618.6	2.49833
2621.32	3.42368
2624.04	3.55796
2626.76	4.70178
2629.48	5.40871
2632.2	4.70142
2634.92	4.37838
2637.63	3.99255
2640.35	4.77182
2643.06	5.34643
2645.77	6.15937
2648.49	5.08814
2651.2	4.65966
2653.91	3.89996
2656.62	3.6619
2659.33	2.65934
2662.03	2.7979
2664.74	2.0396
2667.44	2.86691
2670.15	3.03155
2672.85	2.69419
2675.55	3.07063
2678.26	3.97472
2680.96	5.80082
2683.66	6.70048
2686.35	6.29017
2689.05	6.75568
2691.75	6.32965
2694.44	6.94763
2697.14	6.53823
2699.83	6.26609
2702.52	6.23152
2705.22	6.80956
2707.91	7.44549
2710.6	8.08489
2713.29	8.07671
2715.97	7.20185
2718.66	7.30234
2721.35	6.96588
2724.03	6.42631
2726.72	6.63851
2729.4	7.01641
2732.08	6.20706
2734.76	5.84067
2737.44	6.20635
2740.12	5.77413
2742.8	6.09273
2745.48	6.66821
2748.16	5.80385
2750.83	4.53944
2753.51	4.41601
2756.18	4.90426
2758.85	5.216
2761.53	5.70579
2764.2	5.9606
2766.87	5.0635
2769.54	5.24301
2772.2	6.61744
2774.87	6.95348
2777.54	6.90397
2780.2	6.57415
2782.87	6.58404
2785.53	5.34728
2788.19	4.06126
2790.85	3.80706
2793.51	3.05899
2796.17	2.08634
2798.83	1.42867
2801.49	1.57598
2804.15	0.225009
2806.8	-0.6523
2809.46	-1.02322
2812.11	-1.44497
2814.76	-0.956013
2817.42	-0.583946
2820.07	0.536629
2822.72	3.01247
2825.37	5.82235
2828.02	9.62578
2830.66	12.7296
2833.31	16.9527
2835.96	22.2063
2838.6	27.332
2841.24	32.2524
2843.89	39.4946
2846.53	47.2271
2849.17	55.7488
2851.81	64.7165
2854.45	73.9818
2857.09	84.642
2859.72	94.3092
2862.36	103.652
2865	111.975
2867.63	119.301
2870.26	124.907
2872.9	131.037
2875.53	137.541
2878.16	142.526
2880.79	147.878
2883.42	154.481
2886.05	159.791
2888.67	165.079
2891.3	170.446
2893.92	177.483
2896.55	183.337
2899.17	190.163
2901.79	199.086
2904.42	208.536
2907.04	221.234
2909.66	234.371
2912.27	247.3
2914.89	262.462
2917.51	275.839
2920.13	288.968
2922.74	299.558
2925.35	308.419
2927.97	313.738
2930.58	318.401
2933.19	319.367
2935.8	317.499
2938.41	315.211
2941.02	309.55
2943.63	301.565
2946.24	291.367
2948.84	279.325
2951.45	267.07
2954.05	254.728
2956.65	242.107
2959.26	227.949
2961.86	215.094
2964.46	201.63
2967.06	190.162
2969.66	179.777
2972.25	168.301
2974.85	157.535
2977.45	148.506
2980.04	138.818
2982.64	128.691
2985.23	118.455
2987.82	107.742
2990.41	97.5556
2993	88.1783
2995.59	79.3595
2998.18	70.4226
3000.77	62.3874
3003.36	53.7254
3005.94	46.1605
3008.53	39.1039
3011.11	32.7385
3013.69	28.6659
3016.28	25.1096
3018.86	21.9111
3021.44	18.5115
3024.02	16.3905
3026.6	15.2531
3029.18	14.5785
3031.75	13.5376
3034.33	12.9503
3036.9	13.5402
3039.48	14.3162
3042.05	14.5034
3044.62	15.3442
3047.19	16.9991
3049.77	17.5193
3052.34	18.6153
3054.9	19.1978
3057.47	19.8119
3060.04	19.9982
3062.61	20.4039
3065.17	20.0643
3067.74	19.781
3070.3	18.1795
3072.86	16.5571
3075.42	15.3995
3077.99	14.4982
3080.54	12.4195
3083.1	10.3459
3085.66	9.53279
3088.22	7.15198
3090.78	6.15355
3093.33	4.8428
3095.89	4.19129
3098.44	3.84167
3100.99	3.88807
3103.54	3.34826
3106.1	4.44224
3108.65	5.57504
3111.2	5.98925
3113.74	6.27559
3116.29	7.73879
3118.84	8.80695
3121.38	9.90353
3123.93	11.5155
3126.47	12.7
3129.01	13.8583
3131.56	13.7832
3134.1	14.1804
3136.64	15.0289
3139.18	15.7915
3141.72	15.7663
3144.26	16.2314
3146.79	16.1351
3149.33	17.0054