File: data/Raman/poly_smoothed/Thy_30_10_34_1x_45s_532 nm_x100_100%_600 gr_mm_01.txt
#Acq. time (s)=	45
#Accumulations=	2
#Range (cm-¹)=	200...3150
#Windows=	2
#Auto scanning=	Off
#Autofocus=	Off
#Macrospot=	Off
#AutoExposure=	Off
#Spike filter=	Multiple accum.
#Delay time (s)=	0
#Binning=	1
#Readout mode=	Signal
#DeNoise=	Off
#ICS correction=	On
#Dark correction=	Off
#Inst. Process=	Off
#Detector Gain=	Best Dynamic Range
#Detector ADC=	20 kHz
#Detector temperature (°C)=	-69.85
#Instrument=	LabRAM HR Evol
#Detector=	Synapse
#Objective=	x100
#Grating=	600 gr/mm
#ND Filter=	100%
#Laser (nm)=	532
#Hole=	100.021
#Range=	Auto
#Laser Pol.=	No
#Raman. Pol.=	No
#Laser Pol. (°)=	-0.0007625
#Raman Pol. (°)=	89.9995
#Collection=	Microscope
#StageXY=	Marzhauser
#StageZ=	Marzhauser
#X (µm)=	4749.1
#Y (µm)=	-7717.1
#Z (µm)=	585
#Full time(mm:ss)=	3:19
#Project=
#Sample=
#Site=
#Title=	Thy_30_10_34_2x_45s_532 nm_x100_100%_600 gr_mm
#Remark=
#Date=	30.06.2022 13:54
#Acquired=	30.06.2022 13:54:14
#Base:Fit=	10.08.2022 09:58:11
#Base:Sub=	10.08.2022 09:58:44
#Filter:Polynom=	16.08.2022 10:22:53
#AxisType[0]=Intens
#AxisUnit[0]=Cnt
#AxisType[1]=Spectr
#AxisUnit[1]=1/cm
200.533	4.76495
204.162	1.45109
207.792	0.958835
211.418	1.12922
215.044	2.11315
218.667	3.54732
222.289	3.64242
225.912	4.4677
229.531	4.26876
233.148	4.88625
236.766	4.48339
240.381	3.65761
243.994	3.56936
247.606	3.53134
251.217	3.40041
254.828	5.18153
258.436	5.35484
262.042	5.48619
265.647	5.40658
269.25	5.07007
272.852	4.65786
276.453	5.16316
280.052	5.4813
283.65	7.32887
287.247	8.78771
290.842	10.8251
294.436	12.0038
298.028	13.5176
301.617	15.6108
305.206	16.409
308.794	17.1357
312.381	17.7963
315.964	18.8024
319.548	19.2648
323.131	18.8268
326.71	20.2445
330.29	20.6393
333.868	20.9586
337.443	18.6941
341.018	19.045
344.591	19.4641
348.163	16.8711
351.733	15.9564
355.303	14.9629
358.869	13.9965
362.435	14.4539
366.001	13.8494
369.563	14.1364
373.124	14.1242
376.686	13.2054
380.244	13.2473
383.801	13.8819
387.357	13.9374
390.911	13.5048
394.466	12.0628
398.018	12.4819
401.568	12.3247
405.117	13.1847
408.664	14.3794
412.21	14.4293
415.755	16.6508
419.298	16.17
422.84	14.7415
426.38	14.6323
429.919	14.6264
433.455	14.3298
436.992	15.3833
440.527	15.6736
444.06	15.9595
447.593	14.8243
451.122	16.5121
454.651	17.7196
458.18	17.4144
461.705	17.6795
465.23	18.983
468.752	20.0934
472.275	20.4727
475.797	20.8968
479.315	21.1325
482.834	22.1848
486.349	22.8756
489.863	23.262
493.378	24.5777
496.889	25.1503
500.401	26.0549
503.91	28.382
507.417	26.586
510.923	26.6443
514.43	25.6264
517.933	26.1605
521.435	25.9692
524.936	25.2548
528.435	23.7587
531.933	22.495
535.43	22.9563
538.927	22.6542
542.421	21.1324
545.913	19.8815
549.403	20.3462
552.893	19.781
556.381	19.3256
559.868	19.3524
563.354	18.3331
566.839	16.5026
570.322	13.6811
573.802	11.6132
577.283	11.2214
580.762	10.2912
584.24	10.0819
587.714	9.27279
591.19	8.32023
594.663	5.75442
598.134	5.69727
601.605	6.2768
605.073	7.14648
608.542	7.70574
612.007	8.14967
615.473	8.6749
618.936	9.57674
622.397	10.2605
625.859	10.6493
629.318	11.9459
632.775	15.5169
636.233	17.5799
639.688	17.6733
643.142	19.1145
646.594	18.6121
650.045	17.9012
653.496	17.721
656.944	17.3965
660.391	18.9113
663.837	20.2228
667.281	20.4954
670.724	21.8373
674.166	23.2952
677.606	23.9662
681.045	26.2128
684.483	28.2616
687.917	30.32
691.352	31.1623
694.786	32.1289
698.219	32.9563
701.65	34.703
705.078	35.9937
708.506	39.1199
711.934	41.2704
715.358	43.9624
718.782	46.126
722.204	48.0949
725.626	49.7299
729.045	51.3769
732.464	53.1536
735.881	53.7906
739.297	55.4868
742.711	58.0629
746.125	59.0914
749.537	61.7512
752.946	64.9616
756.357	66.5803
759.764	66.7619
763.17	68.9121
766.575	70.9786
769.978	72.908
773.382	73.077
776.783	73.5853
780.182	74.6439
783.581	74.7341
786.978	77.2229
790.373	78.3872
793.768	80.7968
797.161	81.2012
800.552	83.7799
803.941	86.8998
807.33	86.8222
810.718	87.5191
814.105	87.5543
817.49	87.0896
820.873	86.4224
824.256	85.9365
827.637	85.1257
831.016	83.399
834.395	83.7487
837.772	80.3293
841.147	77.6994
844.522	75.6905
847.894	73.8947
851.267	70.4158
854.637	67.53
858.007	65.3109
861.374	64.0097
864.739	61.7266
868.106	60.8831
871.469	61.1102
874.831	59.6284
878.193	60.4288
881.553	60.6188
884.911	60.2395
888.268	59.9957
891.623	57.8701
894.978	55.7178
898.331	56.1528
901.683	55.0144
905.033	53.8833
908.383	51.8591
911.731	49.1448
915.078	47.5308
918.423	46.7835
921.768	43.9189
925.111	43.1732
928.452	41.7465
931.791	39.8099
935.13	39.8933
938.468	38.643
941.803	39.4251
945.139	37.9251
948.473	37.8683
951.804	39.9868
955.136	40.2779
958.465	39.3351
961.794	39.9047
965.12	40.5741
968.447	42.074
971.771	44.001
975.095	46.8425
978.417	49.553
981.737	51.9624
985.057	52.4176
988.375	51.883
991.691	49.7689
995.006	49.5284
998.32	48.7001
1001.63	48.9152
1004.95	47.8234
1008.26	47.3447
1011.56	46.5377
1014.87	46.1041
1018.18	45.0731
1021.48	44.2742
1024.79	42.9496
1028.09	41.8376
1031.39	41.1114
1034.69	39.9609
1037.99	38.4635
1041.29	36.873
1044.58	36.6335
1047.88	37.3029
1051.17	36.916
1054.46	37.636
1057.75	36.9228
1061.04	34.5367
1064.33	33.9023
1067.62	30.5175
1070.9	28.8402
1074.19	27.0401
1077.47	25.6679
1080.76	24.84
1084.04	25.448
1087.32	26.6294
1090.59	26.2967
1093.87	25.5999
1097.15	25.5511
1100.42	26.4587
1103.69	26.6948
1106.97	25.9128
1110.24	24.597
1113.51	23.3576
1116.77	22.2416
1120.04	19.9766
1123.31	17.3972
1126.57	15.5034
1129.83	12.7136
1133.1	11.4868
1136.36	9.7191
1139.62	7.30647
1142.87	7.37988
1146.13	7.47785
1149.38	6.28286
1152.64	5.5939
1155.89	5.96619
1159.14	5.99113
1162.39	6.69608
1165.64	7.43104
1168.89	8.5343
1172.14	8.14152
1175.38	9.03745
1178.63	8.65507
1181.87	10.2475
1185.11	9.66669
1188.35	9.96267
1191.59	10.7467
1194.83	11.4425
1198.07	12.8385
1201.3	15.0051
1204.53	16.0901
1207.77	18.1904
1211	22.2587
1214.23	25.7816
1217.46	29.1977
1220.69	35.2899
1223.91	40.594
1227.14	45.62
1230.36	50.5912
1233.59	53.8892
1236.81	56.8101
1240.03	60.1593
1243.25	62.4941
1246.46	66.2524
1249.68	67.4305
1252.9	66.8532
1256.11	67.8476
1259.32	68.8349
1262.54	69.4981
1265.75	70.2619
1268.96	70.938
1272.16	72.2435
1275.37	74.1128
1278.57	74.0678
1281.78	74.8216
1284.98	74.1114
1288.18	76.5744
1291.38	77.3978
1294.58	78.2112
1297.78	79.7081
1300.98	81.1001
1304.17	82.4777
1307.37	81.9589
1310.56	82.1981
1313.76	81.6996
1316.95	81.2271
1320.14	80.5695
1323.32	80.0919
1326.51	78.8941
1329.7	77.4041
1332.88	74.3567
1336.07	72.8877
1339.25	71.7438
1342.43	69.8653
1345.61	66.6732
1348.79	63.9575
1351.96	60.2854
1355.14	55.9672
1358.31	52.865
1361.49	49.6002
1364.66	46.7639
1367.83	42.0685
1371	38.0034
1374.17	35.2095
1377.34	32.4666
1380.5	30.7099
1383.67	29.8172
1386.83	29.2181
1390	29.0992
1393.16	29.3618
1396.32	28.9203
1399.48	29.5454
1402.64	29.0654
1405.79	29.3134
1408.95	30.2412
1412.1	32.4182
1415.26	36.9247
1418.41	41.5948
1421.56	47.3216
1424.71	51.809
1427.86	57.7366
1431	63.4076
1434.15	70.0465
1437.29	74.5738
1440.44	78.6829
1443.58	81.4446
1446.72	82.2718
1449.86	81.8636
1453	82.2544
1456.14	81.2808
1459.27	79.1389
1462.41	75.5408
1465.54	70.6542
1468.67	64.6859
1471.81	58.1459
1474.94	49.4527
1478.07	42.8722
1481.19	35.437
1484.32	30.2821
1487.45	26.2213
1490.57	21.7447
1493.69	18.7291
1496.82	15.895
1499.94	12.9977
1503.06	11.9484
1506.17	10.8238
1509.29	11.4811
1512.41	11.9361
1515.52	11.5915
1518.64	13.0403
1521.75	13.9411
1524.86	15.2985
1527.97	16.9181
1531.08	17.9483
1534.19	18.1039
1537.29	21.2059
1540.4	23.2959
1543.5	25.6444
1546.61	29.3284
1549.71	33.0405
1552.81	35.9727
1555.91	39.6464
1559.01	43.7232
1562.11	46.7734
1565.2	48.6941
1568.29	51.5231
1571.39	55.4382
1574.48	57.8656
1577.57	60.6169
1580.66	64.289
1583.75	66.6224
1586.84	68.5023
1589.93	69.806
1593.01	70.9058
1596.1	71.5891
1599.18	71.029
1602.26	69.4403
1605.34	68.8314
1608.42	67.8858
1611.5	67.1173
1614.58	68.1832
1617.65	68.5086
1620.73	69.3325
1623.8	71.7487
1626.87	73.8587
1629.95	74.9864
1633.02	78.4898
1636.09	81.3428
1639.15	84.3186
1642.22	89.0838
1645.29	95.1566
1648.35	97.4107
1651.42	101.34
1654.48	103.946
1657.54	105.026
1660.6	103.5
1663.66	102.554
1666.72	100.239
1669.77	96.5864
1672.83	92.858
1675.88	87.2452
1678.93	81.7707
1681.99	75.036
1685.04	67.5098
1688.09	59.4745
1691.13	52.9268
1694.18	45.9206
1697.23	39.7502
1700.27	33.5795
1703.32	29.1548
1706.36	24.7734
1709.4	21.4135
1712.44	20.0877
1715.48	20.0049
1718.52	18.3617
1721.56	18.0527
1724.59	16.7536
1727.63	16.0151
1730.66	15.5115
1733.69	14.7495
1736.72	14.296
1739.75	15.1479
1742.78	15.3951
1745.81	14.9065
1748.84	14.2194
1751.86	12.9998
1754.89	11.9716
1757.91	9.84499
1760.93	8.74696
1763.95	8.40426
1766.97	7.21054
1769.99	7.42926
1773.01	7.09973
1776.03	6.31765
1779.04	5.41009
1782.06	4.92097
1785.07	6.05693
1788.08	5.22786
1791.09	4.01178
1794.1	3.15065
1797.11	2.77204
1800.12	2.02012
1803.12	1.01873
1806.13	0.252705
1809.13	0.321436
1812.14	0.176666
1815.14	0.350578
1818.14	-0.00953478
1821.14	0.0939811
1824.14	-0.0297327
1827.13	0.365426
1830.13	0.535136
1833.12	1.07364
1836.12	1.89485
1839.11	2.38435
1842.1	3.81397
1845.09	3.95844
1848.08	3.88115
1851.07	4.26047
1854.06	4.21063
1857.04	4.73415
1860.03	5.15753
1863.01	4.1616
1866	2.78402
1868.98	3.35231
1871.96	2.88746
1874.94	1.77877
1877.92	0.790431
1880.89	0.470199
1882.48	-0.00419804
1885.47	0.295931
1888.46	0.725515
1891.44	1.32623
1894.43	1.53556
1897.41	1.23119
1900.4	1.16079
1903.38	1.06452
1906.36	0.92279
1909.34	1.33507
1912.32	2.19942
1915.29	2.76258
1918.27	3.41458
1921.25	3.47991
1924.22	4.11649
1927.2	4.88417
1930.17	5.03583
1933.14	4.97406
1936.11	4.89416
1939.08	5.46555
1942.05	4.92135
1945.01	5.07192
1947.98	4.84398
1950.94	5.00097
1953.91	6.80398
1956.87	7.42413
1959.83	7.42945
1962.79	8.70618
1965.75	8.09389
1968.71	7.32516
1971.67	7.96415
1974.62	8.67376
1977.58	9.41732
1980.53	10.0159
1983.48	10.9249
1986.43	12.0306
1989.38	12.8384
1992.33	13.6077
1995.28	13.7156
1998.23	14.4296
2001.18	14.4386
2004.12	14.1929
2007.06	13.692
2010.01	14.2391
2012.95	12.746
2015.89	13.5624
2018.83	12.8797
2021.77	13.5177
2024.71	13.3331
2027.64	13.595
2030.58	12.8402
2033.51	13.9494
2036.45	15.4711
2039.38	16.4088
2042.31	16.5509
2045.24	18.6341
2048.17	19.1471
2051.1	19.5833
2054.02	20.0876
2056.95	21.7648
2059.87	22.7024
2062.8	23.5368
2065.72	24.2962
2068.64	24.2686
2071.56	24.4552
2074.48	23.9231
2077.4	24.6121
2080.31	25.6203
2083.23	25.551
2086.14	25.4313
2089.06	25.1577
2091.97	25.7715
2094.88	26.8393
2097.79	27.7578
2100.7	29.4516
2103.61	30.6722
2106.52	33.7459
2109.43	36.5262
2112.33	39.0721
2115.24	42.5751
2118.14	44.4328
2121.04	47.2414
2123.94	51.4687
2126.84	55.592
2129.74	58.4419
2132.64	62.7466
2135.54	67.1179
2138.43	70.1894
2141.33	73.7042
2144.22	77.0692
2147.11	80.4689
2150.01	83.289
2152.9	85.4353
2155.79	87.0376
2158.67	89.4933
2161.56	92.2053
2164.45	93.8841
2167.33	94.8713
2170.22	95.1332
2173.1	94.4722
2175.98	93.5383
2178.86	92.7241
2181.74	91.768
2184.62	89.7643
2187.5	88.4515
2190.38	85.848
2193.25	83.6311
2196.13	80.9599
2199	77.3144
2201.88	74.8082
2204.75	72.3159
2207.62	67.9366
2210.49	63.561
2213.36	59.3551
2216.22	55.7011
2219.09	52.1726
2221.96	49.2631
2224.82	46.2704
2227.68	43.2943
2230.55	41.6137
2233.41	39.165
2236.27	36.6731
2239.12	34.6385
2241.98	33.1113
2244.84	31.8384
2247.7	30.7141
2250.55	30.6842
2253.41	30.972
2256.26	30.4686
2259.11	29.799
2261.96	29.7661
2264.81	29.406
2267.66	28.9024
2270.51	29.2147
2273.35	29.1955
2276.2	27.7981
2279.04	26.8944
2281.89	26.0861
2284.73	25.852
2287.57	24.6471
2290.41	22.8893
2293.25	20.64
2296.09	20.1382
2298.93	20.1918
2301.76	21.2336
2304.6	20.2399
2307.44	19.9353
2310.27	19.5794
2313.1	19.5525
2315.93	19.0604
2318.76	17.4077
2321.59	17.3114
2324.42	17.0319
2327.25	16.1361
2330.07	15.3671
2332.9	15.6835
2335.72	15.178
2338.55	13.9945
2341.37	12.9859
2344.19	11.1631
2347.01	10.0061
2349.83	9.85083
2352.65	9.27203
2355.46	7.57726
2358.28	7.02449
2361.09	6.30803
2363.91	7.06277
2366.72	7.2006
2369.53	7.25229
2372.34	6.65371
2375.15	6.71786
2377.96	6.755
2380.77	6.48698
2383.58	6.93291
2386.38	6.71943
2389.19	5.80238
2391.99	5.35527
2394.8	5.1916
2397.6	5.79825
2400.4	5.21345
2403.2	5.0477
2406	4.16729
2408.79	3.58063
2411.59	3.71833
2414.39	4.30855
2417.18	4.94661
2419.98	5.52921
2422.77	4.86394
2425.56	4.85093
2428.35	5.62106
2431.14	5.39208
2433.93	5.75864
2436.72	6.47676
2439.5	7.14884
2442.29	7.51846
2445.07	8.39857
2447.86	7.54827
2450.64	6.46125
2453.42	5.68204
2456.2	4.81917
2458.98	4.52703
2461.76	4.35092
2464.54	4.73118
2467.32	4.53044
2470.09	4.16095
2472.87	3.83125
2475.64	2.9124
2478.41	2.97865
2481.18	3.50102
2483.95	3.54966
2486.72	3.13341
2489.49	2.72187
2492.26	2.38149
2495.03	2.80521
2497.79	3.58901
2500.56	3.26998
2503.32	3.59616
2506.09	2.8024
2508.85	3.39896
2511.61	3.21568
2514.37	2.65343
2517.13	1.8224
2519.89	2.03793
2522.64	2.06392
2525.4	1.82102
2528.15	1.96986
2530.91	1.98812
2533.66	1.37013
2536.41	0.210683
2539.16	0.434954
2541.91	0.611906
2544.66	0.293555
2547.41	0.645228
2550.16	0.491591
2552.9	0.619672
2555.65	0.698556
2558.39	0.611185
2561.13	0.998786
2563.88	-0.288233
2566.62	-0.813067
2569.36	-0.241982
2572.1	-0.485921
2574.84	0.115557
2577.57	0.553611
2580.31	0.837205
2583.05	1.34571
2585.78	1.8249
2588.51	2.28176
2591.24	1.99178
2593.98	2.31447
2596.71	2.37993
2599.44	1.55327
2602.16	2.06844
2604.89	3.0716
2607.62	3.3688
2610.34	3.8258
2613.07	4.03385
2615.79	4.42952
2618.52	5.19239
2621.24	4.78695
2623.96	4.96487
2626.68	4.23959
2629.4	3.30281
2632.11	2.15187
2634.83	2.36028
2637.55	2.36845
2640.26	3.68265
2642.98	4.26829
2645.69	4.67409
2648.4	4.28379
2651.11	3.44447
2653.82	2.37392
2656.53	1.83444
2659.24	1.2476
2661.95	1.22887
2664.65	0.591144
2667.36	0.531451
2670.06	0.889422
2672.76	0.539071
2675.47	-0.147869
2678.17	-0.524909
2680.87	0.261699
2683.57	0.323897
2686.27	0.905693
2688.97	1.62191
2691.66	2.46263
2694.36	2.39384
2697.05	3.44764
2699.75	4.61528
2702.44	6.82673
2705.13	8.84954
2707.82	10.4642
2710.51	11.2282
2713.2	11.1101
2715.89	12.6556
2718.57	13.1477
2721.26	13.8406
2723.95	14.9985
2726.63	15.4261
2729.31	15.6799
2732	15.3953
2734.68	14.5761
2737.36	13.8017
2740.04	13.6712
2742.72	13.3109
2745.39	12.5147
2748.07	12.231
2750.75	11.2058
2753.42	10.4449
2756.09	9.55723
2758.77	8.89856
2761.44	8.78229
2764.11	8.00365
2766.78	7.36282
2769.45	7.16515
2772.12	7.26973
2774.78	6.95776
2777.45	6.33334
2780.12	6.33464
2782.78	7.52081
2785.44	7.78426
2788.11	7.92176
2790.77	7.75027
2793.43	7.90245
2796.09	7.59366
2798.75	8.44045
2801.4	8.58338
2804.06	8.40315
2806.72	8.98247
2809.37	7.68919
2812.03	7.31578
2814.68	7.79215
2817.33	8.3312
2819.98	9.75917
2822.63	12.8135
2825.28	16.3065
2827.93	20.0005
2830.58	24.5408
2833.23	29.5279
2835.87	35.2675
2838.52	41.7581
2841.16	48.2515
2843.8	55.6179
2846.44	64.3455
2849.08	74.0526
2851.73	84.5272
2854.36	94.3569
2857	104.748
2859.64	114.191
2862.28	123.006
2864.91	131.932
2867.55	138.516
2870.18	145.866
2872.81	151.68
2875.44	155.989
2878.07	161.389
2880.7	166.34
2883.33	171.131
2885.96	175.284
2888.59	181.165
2891.21	186.339
2893.84	191.044
2896.46	196.076
2899.09	202.276
2901.71	210.882
2904.33	220.298
2906.95	230.794
2909.57	242.519
2912.19	256.781
2914.81	270.937
2917.43	283.155
2920.04	294.363
2922.66	303.406
2925.27	309.364
2927.88	313.821
2930.5	317.002
2933.11	316.922
2935.72	315.994
2938.33	311.263
2940.94	306.524
2943.54	298.833
2946.15	289.984
2948.76	279.513
2951.36	268.136
2953.97	255.985
2956.57	243.648
2959.17	231.607
2961.77	220.602
2964.37	210.129
2966.97	200.074
2969.57	190.949
2972.17	181.4
2974.77	171.975
2977.36	164.095
2979.96	154.472
2982.55	145.44
2985.15	135.423
2987.74	125.351
2990.33	115.759
2992.92	106.745
2995.51	98.2919
2998.1	90.4043
3000.69	83.3159
3003.27	75.6041
3005.86	68.7042
3008.44	62.2553
3011.03	56.0472
3013.61	51.0368
3016.19	46.5203
3018.78	43.0293
3021.36	40.3094
3023.94	37.2323
3026.51	35.1988
3029.09	33.3297
3031.67	31.6745
3034.24	30.561
3036.82	30.0686
3039.39	30.6326
3041.97	31.4504
3044.54	32.7463
3047.11	33.7911
3049.68	34.3957
3052.25	34.9674
3054.82	35.0721
3057.39	35.8557
3059.96	35.6988
3062.52	34.8223
3065.09	34.4619
3067.65	32.5626
3070.22	31.3716
3072.78	29.9721
3075.34	28.9973
3077.9	26.9326
3080.46	24.9739
3083.02	22.8159
3085.58	20.4909
3088.14	18.4911
3090.69	17.0416
3093.25	15.3388
3095.8	13.7105
3098.36	12.82
3100.91	11.9489
3103.46	11.2282
3106.01	9.65072
3108.56	8.98636
3111.11	8.18536
3113.66	6.76821
3116.21	5.72738
3118.76	4.60703
3121.3	3.9416
3123.85	2.74932
3126.39	2.2926
3128.93	1.23446
3131.48	0.428109
3134.02	0.543282
3136.56	0.364902
3139.1	-0.220329
3141.64	-0.197011
3144.17	-0.114615
3146.71	0.482465
3149.25	0.509285