File: data/Raman/poly_smoothed/Thy_00_07_9_1x_45s_532 nm_x100_100%_600 gr_mm_01.txt
#Acq. time (s)=	45
#Accumulations=	2
#Range (cm-¹)=	200...3150
#Windows=	2
#Auto scanning=	Off
#Autofocus=	Off
#Macrospot=	Off
#AutoExposure=	Off
#Spike filter=	Multiple accum.
#Delay time (s)=	0
#Binning=	1
#Readout mode=	Signal
#DeNoise=	Off
#ICS correction=	On
#Dark correction=	Off
#Inst. Process=	Off
#Detector Gain=	Best Dynamic Range
#Detector ADC=	20 kHz
#Detector temperature (°C)=	-69.85
#Instrument=	LabRAM HR Evol
#Detector=	Synapse
#Objective=	x100
#Grating=	600 gr/mm
#ND Filter=	100%
#Laser (nm)=	532
#Hole=	100.021
#Range=	Auto
#Laser Pol.=	No
#Raman. Pol.=	No
#Laser Pol. (°)=	-0.0007625
#Raman Pol. (°)=	89.9995
#Collection=	Microscope
#StageXY=	Marzhauser
#StageZ=	Marzhauser
#X (µm)=	8993.4
#Y (µm)=	-3090.6
#Z (µm)=	-54.55
#Full time(mm:ss)=	3:19
#Project=
#Sample=
#Site=
#Title=	Thy_00_07_9_2x_45s_532 nm_x100_100%_600 gr_mm
#Remark=
#Date=	28.06.2022 10:40
#Acquired=	28.06.2022 10:40:07
#Base:Fit=	10.08.2022 10:07:56
#Base:Sub=	10.08.2022 10:08:40
#Filter:Polynom=	16.08.2022 10:26:06
#AxisType[0]=Intens
#AxisUnit[0]=Cnt
#AxisType[1]=Spectr
#AxisUnit[1]=1/cm
200.407	41.5521
204.035	39.1637
207.665	32.8437
211.291	30.4144
214.916	26.7382
218.541	23.2239
222.163	20.0751
225.785	19.0653
229.404	16.8155
233.022	14.3771
236.638	13.4802
240.255	11.3599
243.868	8.79388
247.48	7.45775
251.091	7.96458
254.702	7.70072
258.31	7.27865
261.916	7.07902
265.521	5.54477
269.125	3.63259
272.727	2.83189
276.328	1.45347
279.927	0.659333
283.525	2.30727
287.121	3.13661
290.716	2.18337
294.31	5.2116
297.9	9.81592
301.491	10.8957
305.081	11.5584
308.669	13.867
312.256	15.9553
315.839	16.6133
319.423	16.0647
323.006	18.8435
326.585	19.6654
330.165	19.3793
333.741	18.9418
337.318	18.8328
340.894	18.9691
344.466	17.5497
348.039	16.4509
351.608	17.1575
355.176	17.1483
358.745	18.0474
362.31	18.906
365.876	20.4404
369.439	23.8314
373	25.7754
376.56	27.2148
380.12	29.4281
383.677	31.8735
387.233	32.7505
390.787	33.0938
394.34	30.987
397.894	30.3826
401.444	28.6683
404.993	26.3102
408.54	25.1414
412.086	21.9618
415.631	18.2179
419.174	13.7433
422.716	10.6792
426.257	7.30556
429.794	5.62394
433.332	3.32235
436.868	2.54056
440.403	1.78229
443.937	2.74608
447.468	4.70001
450.999	5.83092
454.528	6.82515
458.057	8.09198
461.582	9.50037
465.107	12.2805
468.629	15.6591
472.152	17.7998
475.672	18.3465
479.192	21.268
482.709	23.5296
486.226	28.7847
489.74	31.7412
493.255	34.73
496.767	39.125
500.277	40.5506
503.788	42.5595
507.295	44.1617
510.801	45.1304
514.308	42.9286
517.811	41.7505
521.313	39.4516
524.814	39.034
528.313	37.397
531.811	34.6843
535.308	30.7692
538.803	27.117
542.297	24.2636
545.789	21.1513
549.281	17.9121
552.771	13.9504
556.259	11.311
559.747	8.25174
563.233	7.28469
566.717	5.79909
570.2	5.37009
573.68	5.82883
577.161	4.17198
580.64	4.47299
584.118	5.62636
587.593	4.78385
591.068	4.64315
594.54	4.74105
598.013	3.73884
601.484	3.10043
604.952	4.17911
608.421	5.28014
611.886	3.21305
615.35	4.20181
618.815	4.16665
622.276	3.90814
625.738	3.00861
629.197	3.07193
632.655	3.29416
636.113	1.90972
639.568	2.02932
643.021	2.41408
646.473	0.663981
649.924	-0.0124174
653.376	1.26407
656.824	1.31017
660.271	2.23547
663.716	4.46207
667.161	4.91696
670.604	3.91802
674.045	6.12501
677.486	8.50137
680.925	9.50064
684.361	10.6886
687.797	10.4354
691.232	12.8035
694.666	12.8803
698.099	14.8212
701.528	16.6327
704.958	17.9821
708.387	18.1181
711.814	18.6887
715.238	20.9531
718.663	22.4988
722.084	26.5512
725.506	28.3092
728.925	29.631
732.345	33.2997
735.761	36.0386
739.178	41.2079
742.592	49.6855
746.006	58.7742
749.417	65.6633
752.827	72.1016
756.236	79.2227
759.645	85.2734
763.051	89.1236
766.456	89.6461
769.859	91.2272
773.261	91.5816
776.664	91.0042
780.064	89.6246
783.462	86.3684
786.859	83.0227
790.255	80.218
793.649	76.4911
797.042	72.6069
800.434	68.6658
803.823	64.5244
807.212	58.7325
810.6	53.0208
813.987	51.7484
817.372	49.4421
820.754	50.4896
824.137	53.9327
827.519	55.9888
830.897	57.4147
834.276	57.2848
837.654	58.6103
841.029	57.4022
844.404	53.6425
847.776	48.8102
851.149	49.08
854.519	48.6638
857.889	47.1337
861.256	45.6176
864.622	44.5692
867.988	42.9915
871.351	40.5599
874.713	39.3519
878.074	36.577
881.435	34.3046
884.794	32.2875
888.15	31.7139
891.506	28.8526
894.861	28.2389
898.214	29.6607
901.566	29.9589
904.916	32.6702
908.266	33.2288
911.614	33.5518
914.961	34.2589
918.306	32.9264
921.651	32.6372
924.994	30.0617
928.336	26.0342
931.674	30.384
935.014	29.7183
938.352	26.6728
941.687	25.3722
945.022	22.6692
948.357	19.7903
951.688	18.1432
955.02	15.5665
958.348	13.1119
961.678	10.1484
965.004	10.6715
968.331	11.0472
971.655	13.1964
974.979	15.2085
978.3	19.2738
981.62	23.2375
984.941	25.0364
988.259	25.1277
991.575	27.4421
994.89	30.7892
998.204	35.7727
1001.52	41.2312
1004.83	46.666
1008.14	50.9691
1011.45	55.4413
1014.76	57.7854
1018.06	59.3134
1021.37	61.1091
1024.67	60.3438
1027.97	60.0079
1031.27	57.8042
1034.57	52.863
1037.87	48.7411
1041.17	43.4765
1044.47	40.9312
1047.76	38.7188
1051.06	35.8447
1054.35	33.8675
1057.64	31.5536
1060.93	31.9821
1064.22	28.1555
1067.5	27.1185
1070.79	28.7725
1074.08	33.7091
1077.36	35.6689
1080.64	38.621
1083.92	41.731
1087.2	42.6356
1090.48	44.3611
1093.76	47.6249
1097.03	48.0526
1100.31	49.0131
1103.58	48.3963
1106.85	46.7612
1110.12	44.8743
1113.39	41.9998
1116.66	39.8603
1119.93	37.9646
1123.19	35.1364
1126.46	31.662
1129.72	31.097
1132.98	30.7745
1136.24	30.9882
1139.5	30.3692
1142.76	28.3888
1146.01	26.5514
1149.27	26.48
1152.53	24.6316
1155.78	19.8328
1159.03	15.6533
1162.28	13.0466
1165.53	10.2921
1168.78	9.0248
1172.02	8.47393
1175.27	7.25544
1178.51	6.31771
1181.76	6.36057
1185	5.73433
1188.24	7.68155
1191.48	9.19701
1194.71	10.039
1197.95	14.2652
1201.19	17.031
1204.42	20.8624
1207.65	26.055
1210.88	30.9357
1214.12	35.3041
1217.35	38.8126
1220.57	42.7168
1223.8	45.6635
1227.03	50.5014
1230.25	53.8536
1233.47	54.8947
1236.69	56.4882
1239.92	57.2981
1243.13	56.2179
1246.35	54.9316
1249.57	54.3996
1252.78	52.9351
1256	51.2269
1259.21	49.6615
1262.42	46.5341
1265.63	44.1785
1268.84	43.8583
1272.05	42.5239
1275.26	43.5665
1278.46	45.0009
1281.67	44.4178
1284.87	47.5849
1288.07	49.754
1291.27	52.189
1294.47	55.2907
1297.67	61.1165
1300.87	65.7235
1304.06	74.477
1307.26	81.7877
1310.45	87.8455
1313.64	94.1004
1316.83	97.7007
1320.02	100.778
1323.21	103.692
1326.4	107.766
1329.59	108.269
1332.77	109.104
1335.95	109.26
1339.14	106.87
1342.32	104.364
1345.5	102.122
1348.67	100.601
1351.85	98.2295
1355.03	95.538
1358.2	92.1807
1361.38	90.361
1364.55	86.9707
1367.72	84.2186
1370.89	81.9615
1374.06	82.2648
1377.23	81.782
1380.39	81.2928
1383.56	78.9798
1386.72	77.9856
1389.89	75.6324
1393.05	72.6077
1396.21	68.9219
1399.37	66.5969
1402.52	65.0121
1405.68	64.7186
1408.84	65.2627
1411.99	67.8114
1415.15	70.4122
1418.3	73.0487
1421.45	78.6479
1424.6	84.7519
1427.75	91.0608
1430.89	98.1546
1434.04	105.252
1437.18	111.02
1440.33	116.067
1443.47	119.998
1446.61	122.882
1449.75	125.109
1452.89	124.854
1456.03	121.9
1459.16	118.981
1462.3	114.337
1465.43	107.188
1468.56	97.4265
1471.7	86.5418
1474.83	77.2931
1477.96	67.4125
1481.08	57.6201
1484.21	48.0609
1487.34	40.6459
1490.46	34.0456
1493.58	29.2954
1496.71	26.1666
1499.83	23.0952
1502.95	20.8005
1506.07	20.4724
1509.18	21.1947
1512.3	21.9134
1515.41	23.0095
1518.53	25.0563
1521.64	28.113
1524.75	32.4271
1527.86	37.3119
1530.97	41.3537
1534.08	45.9915
1537.19	50.0253
1540.29	52.4654
1543.4	54.7163
1546.5	56.3688
1549.6	61.2477
1552.7	66.0434
1555.8	67.6198
1558.9	71.1304
1562	76.6748
1565.09	80.3661
1568.19	84.1309
1571.28	87.9771
1574.37	90.2116
1577.47	91.8102
1580.56	94.5391
1583.64	95.6277
1586.73	97.4471
1589.82	98.3441
1592.9	99.7302
1595.99	99.9656
1599.07	98.8938
1602.15	96.2059
1605.23	95.158
1608.31	91.7577
1611.39	91.7733
1614.47	91.6399
1617.55	87.9503
1620.62	86.6321
1623.7	85.2305
1626.77	84.7861
1629.84	83.8223
1632.91	81.7489
1635.98	81.7283
1639.05	81.6428
1642.11	81.2059
1645.18	82.9299
1648.24	84.259
1651.31	84.3759
1654.37	83.4839
1657.43	83.5379
1660.49	83.2988
1663.55	81.4727
1666.61	79.8789
1669.66	77.2657
1672.72	72.6135
1675.77	67.9532
1678.83	64.4474
1681.88	60.0166
1684.93	55.4772
1687.98	50.9646
1691.03	45.6286
1694.07	39.6674
1697.12	34.2144
1700.17	29.1485
1703.21	24.5032
1706.25	19.9745
1709.29	16.2108
1712.33	14.1017
1715.37	12.4849
1718.41	10.7902
1721.45	9.95626
1724.49	7.53238
1727.52	7.40227
1730.55	6.28352
1733.59	6.71976
1736.62	6.31752
1739.65	5.95545
1742.68	5.68975
1745.7	4.35905
1748.73	3.51939
1751.76	1.35161
1754.78	1.80624
1757.8	1.36427
1760.83	1.20138
1763.85	1.59573
1766.87	1.33523
1769.89	0.046057
1772.9	-1.07403
1775.92	0.0909804
1778.94	-1.25073
1781.95	-1.2491
1784.96	-1.59169
1787.97	-1.23214
1790.99	-0.0614221
1794	-0.56759
1797	-0.57278
1800.01	-0.46772
1803.02	0.691147
1806.02	1.03761
1809.03	1.56832
1812.03	1.72198
1815.03	2.29105
1818.03	2.21686
1821.03	3.84698
1824.03	3.5838
1827.03	3.89923
1830.02	4.9095
1833.02	4.11597
1836.01	3.93896
1839.01	4.1366
1842	3.99128
1844.99	3.62072
1847.98	3.37775
1850.97	3.21986
1853.95	2.73981
1856.94	2.96025
1859.93	3.12238
1862.91	3.95061
1865.89	3.10398
1868.87	3.04807
1871.85	2.67984
1874.83	3.2433
1877.81	3.68805
1880.79	4.32786
1882.52	4.93511
1885.51	6.1549
1888.5	7.17677
1891.49	7.99233
1894.47	8.59614
1897.46	8.42918
1900.44	7.59982
1903.42	6.98696
1906.4	6.87832
1909.38	7.17464
1912.36	6.94967
1915.34	7.82495
1918.32	7.31213
1921.29	6.83561
1924.27	7.32628
1927.24	7.2503
1930.21	8.133
1933.18	8.59379
1936.15	8.52609
1939.12	7.91699
1942.09	8.76027
1945.06	8.80425
1948.02	7.74454
1950.99	8.58042
1953.95	8.5835
1956.91	9.35561
1959.88	9.18313
1962.84	8.29092
1965.8	7.63073
1968.75	6.5368
1971.71	4.68539
1974.67	2.54828
1977.62	3.05501
1980.58	2.202
1983.53	1.44941
1986.48	1.08809
1989.43	1.20527
1992.38	1.40197
1995.33	1.06661
1998.27	1.40252
2001.22	1.26439
2004.16	1.13216
2007.11	1.15772
2010.05	2.04554
2012.99	3.6579
2015.93	4.23988
2018.87	4.71536
2021.81	5.95022
2024.75	8.1863
2027.69	9.46932
2030.62	9.71122
2033.56	10.0902
2036.49	10.8295
2039.42	11.6558
2042.35	11.7324
2045.28	11.1956
2048.21	11.3075
2051.14	11.35
2054.07	11.8844
2056.99	12.5074
2059.92	13.3164
2062.84	12.8756
2065.76	10.7779
2068.68	10.0823
2071.6	9.14886
2074.52	7.66076
2077.44	6.37074
2080.36	5.13914
2083.27	4.7959
2086.19	4.1069
2089.1	3.13558
2092.02	3.67624
2094.93	3.95599
2097.84	3.93839
2100.75	3.68848
2103.66	3.80082
2106.56	3.45457
2109.47	4.14065
2112.38	3.11139
2115.28	2.88594
2118.18	4.09081
2121.09	4.38373
2123.99	5.65578
2126.89	6.69769
2129.79	7.02449
2132.68	6.49156
2135.58	5.45238
2138.48	5.03139
2141.37	5.35738
2144.27	4.02992
2147.16	3.07346
2150.05	3.25333
2152.94	3.19819
2155.83	3.84332
2158.72	4.52139
2161.6	4.33181
2164.49	5.62879
2167.38	6.43968
2170.26	6.43722
2173.14	6.59792
2176.03	5.80388
2178.91	5.81839
2181.79	5.70743
2184.67	6.98671
2187.54	6.96919
2190.42	7.46529
2193.3	6.46903
2196.17	6.91279
2199.05	8.02294
2201.92	8.83986
2204.79	9.55279
2207.66	8.22817
2210.53	8.90952
2213.4	8.82164
2216.27	8.67072
2219.13	8.17856
2222	8.56931
2224.86	10.2472
2227.72	10.1174
2230.59	8.54341
2233.45	7.60231
2236.31	7.16962
2239.17	5.70228
2242.03	5.33576
2244.88	6.20081
2247.74	6.63175
2250.59	7.60815
2253.45	9.51289
2256.3	9.48484
2259.15	9.8833
2262	10.5086
2264.85	12.3237
2267.7	13.3882
2270.55	14.3525
2273.4	14.0462
2276.24	13.762
2279.09	14.045
2281.93	15.2537
2284.77	15.3806
2287.62	13.9197
2290.46	12.6517
2293.3	11.8827
2296.13	10.6039
2298.97	9.71235
2301.81	8.39986
2304.64	7.69097
2307.48	7.76734
2310.31	7.44955
2313.14	8.7288
2315.98	7.89428
2318.81	7.78222
2321.64	8.90798
2324.46	8.59191
2327.29	7.50798
2330.12	7.54604
2332.94	7.26014
2335.77	6.41507
2338.59	6.35599
2341.41	5.86722
2344.23	6.7281
2347.05	6.14952
2349.87	7.10277
2352.69	6.06679
2355.51	5.50301
2358.32	3.635
2361.14	2.25679
2363.95	2.36022
2366.76	3.91991
2369.58	3.63429
2372.39	3.57198
2375.2	3.88886
2378	2.22917
2380.81	2.01393
2383.62	1.83707
2386.43	1.18918
2389.23	1.29369
2392.03	0.889351
2394.84	1.18184
2397.64	2.37985
2400.44	2.11172
2403.24	2.88025
2406.04	5.6559
2408.84	6.03936
2411.63	8.5727
2414.43	10.878
2417.22	11.6282
2420.02	12.3955
2422.81	12.8383
2425.6	12.8944
2428.39	13.6329
2431.18	15.0893
2433.97	17.0356
2436.76	15.9336
2439.54	15.2184
2442.33	14.7325
2445.12	12.7007
2447.9	12.0373
2450.68	11.0101
2453.46	8.52874
2456.24	7.11171
2459.02	6.79913
2461.8	6.73532
2464.58	5.96371
2467.36	5.99944
2470.13	5.75641
2472.91	6.98162
2475.68	6.04226
2478.45	5.50286
2481.23	5.42978
2484	5.76101
2486.77	5.8304
2489.54	6.7561
2492.3	7.61931
2495.07	8.16717
2497.84	8.60042
2500.6	8.75644
2503.36	7.53992
2506.13	7.59791
2508.89	7.93616
2511.65	9.83207
2514.41	9.87191
2517.17	10.0154
2519.93	10.3754
2522.68	11.0864
2525.44	12.1549
2528.19	13.3831
2530.95	13.5289
2533.7	13.7408
2536.45	13.0079
2539.2	12.4984
2541.95	12.6453
2544.7	11.4227
2547.45	10.7749
2550.2	9.58614
2552.94	10.1653
2555.69	9.19688
2558.43	7.89085
2561.18	6.81989
2563.92	6.77052
2566.66	7.62681
2569.4	6.4878
2572.14	5.64029
2574.88	6.21891
2577.61	5.79224
2580.35	5.77886
2583.09	4.79684
2585.82	5.55985
2588.55	6.17039
2591.29	6.51481
2594.02	6.97105
2596.75	6.85284
2599.48	6.11662
2602.21	6.57487
2604.93	7.50839
2607.66	8.66339
2610.39	9.55154
2613.11	10.4808
2615.83	13.0793
2618.56	13.3878
2621.28	14.8222
2624	16.1565
2626.72	17.4127
2629.44	18.6888
2632.15	20.0682
2634.87	18.7899
2637.59	17.8736
2640.3	18.8198
2643.02	19.1181
2645.73	19.041
2648.44	19.1304
2651.15	19.0873
2653.86	19.2954
2656.57	16.7514
2659.28	16.2826
2661.99	15.1943
2664.69	12.9574
2667.4	12.8808
2670.1	13.0825
2672.81	12.3177
2675.51	12.815
2678.21	12.7213
2680.91	12.4716
2683.61	12.372
2686.31	12.7085
2689	13.9206
2691.7	14.1427
2694.4	13.896
2697.09	15.071
2699.79	16.3395
2702.48	17.6416
2705.17	19.0356
2707.86	19.9727
2710.55	20.4379
2713.24	21.0239
2715.93	21.4424
2718.62	20.0032
2721.3	19.3535
2723.99	18.5721
2726.67	18.4328
2729.35	17.5218
2732.04	16.2786
2734.72	15.8142
2737.4	15.4961
2740.08	14.8206
2742.76	14.3433
2745.43	12.9379
2748.11	12.8137
2750.79	12.4649
2753.46	12.5254
2756.14	11.8661
2758.81	12.1649
2761.48	11.7853
2764.15	11.2427
2766.82	10.3245
2769.49	8.9003
2772.16	8.61908
2774.82	8.48763
2777.49	7.16754
2780.16	6.35117
2782.82	5.14272
2785.48	3.73426
2788.15	3.02812
2790.81	2.18184
2793.47	1.11954
2796.13	0.145169
2798.79	0.0456776
2801.44	0.0452033
2804.1	0.496335
2806.76	0.0870127
2809.41	-1.07833
2812.07	-0.956678
2814.72	-0.72873
2817.37	1.15866
2820.02	4.2199
2822.67	6.84014
2825.32	11.1072
2827.97	15.4124
2830.62	20.4005
2833.26	25.4591
2835.91	30.7427
2838.56	37.4241
2841.2	43.5628
2843.84	51.9566
2846.48	60.6587
2849.12	69.5663
2851.77	79.6981
2854.4	90.441
2857.04	100.96
2859.68	112.062
2862.32	123.381
2864.95	133.636
2867.59	142.46
2870.22	151.454
2872.85	158.098
2875.48	165.103
2878.11	172.325
2880.74	179.531
2883.37	185.733
2886	192.203
2888.63	198.502
2891.25	205.224
2893.88	211.069
2896.5	217.866
2899.13	224.764
2901.75	234.125
2904.37	244.167
2906.99	255.135
2909.61	267.611
2912.23	280.186
2914.85	294.122
2917.46	306.027
2920.08	317.377
2922.7	326.571
2925.31	332.483
2927.92	336.675
2930.54	338.482
2933.15	336.909
2935.76	334.253
2938.37	328.283
2940.98	321.308
2943.58	311.42
2946.19	299.552
2948.8	288.851
2951.4	277.205
2954.01	265.279
2956.61	253.159
2959.21	241.006
2961.81	229.708
2964.41	219.573
2967.01	210.094
2969.61	200.492
2972.21	190.906
2974.81	182.548
2977.4	173.619
2980	162.723
2982.59	151.741
2985.18	141.412
2987.78	129.381
2990.37	117.447
2992.96	106.564
2995.55	93.8286
2998.14	83.1472
3000.73	72.9472
3003.31	61.8342
3005.9	50.8442
3008.48	41.8859
3011.07	33.7081
3013.65	27.3484
3016.23	21.129
3018.81	15.1404
3021.4	11.3435
3023.97	8.02114
3026.55	5.22727
3029.13	3.13378
3031.71	2.47966
3034.28	1.91529
3036.86	1.3257
3039.43	2.56865
3042.01	3.57337
3044.58	6.40557
3047.15	9.44436
3049.72	10.5116
3052.29	13.2518
3054.86	15.0997
3057.43	15.58
3060	17.275
3062.56	17.9189
3065.13	17.0872
3067.69	16.5289
3070.26	14.9808
3072.82	14.0511
3075.38	11.2072
3077.94	9.37266
3080.5	7.98287
3083.06	6.86081
3085.62	6.39555
3088.18	5.57173
3090.73	4.44214
3093.29	5.15168
3095.84	5.98039
3098.4	8.36728
3100.95	10.8186
3103.5	13.7736
3106.05	17.3995
3108.6	20.6827
3111.15	22.9286
3113.7	25.8259
3116.25	29.2927
3118.79	32.5882
3121.34	35.4682
3123.88	38.3172
3126.43	39.796
3128.97	42.76
3131.51	45.1056
3134.06	47.6977
3136.6	49.8837
3139.14	51.7714
3141.67	54.6531
3144.21	57.6227
3146.75	60.2576
3149.29	63.3596