File: data/Raman/poly_smoothed/Thy_50_12_49_1x_45s_532 nm_x100_100%_600 gr_mm_01.txt
#Acq. time (s)=	45
#Accumulations=	2
#Range (cm-¹)=	200...3150
#Windows=	2
#Auto scanning=	Off
#Autofocus=	Off
#Macrospot=	Off
#AutoExposure=	Off
#Spike filter=	Multiple accum.
#Delay time (s)=	0
#Binning=	1
#Readout mode=	Signal
#DeNoise=	Off
#ICS correction=	On
#Dark correction=	Off
#Inst. Process=	Off
#Detector Gain=	Best Dynamic Range
#Detector ADC=	20 kHz
#Detector temperature (°C)=	-69.85
#Instrument=	LabRAM HR Evol
#Detector=	Synapse
#Objective=	x100
#Grating=	600 gr/mm
#ND Filter=	100%
#Laser (nm)=	532
#Hole=	100.021
#Range=	Auto
#Laser Pol.=	No
#Raman. Pol.=	No
#Laser Pol. (°)=	-0.0007625
#Raman Pol. (°)=	89.9995
#Collection=	Microscope
#StageXY=	Marzhauser
#StageZ=	Marzhauser
#X (µm)=	-5093.2
#Y (µm)=	1482
#Z (µm)=	63.8
#Full time(mm:ss)=	3:20
#Project=
#Sample=
#Site=
#Title=	Thy_50_12_49_2x_45s_532 nm_x100_100%_600 gr_mm
#Remark=
#Date=	07.07.2022 12:53
#Acquired=	07.07.2022 12:53:09
#Base:Fit=	10.08.2022 10:04:30
#Base:Sub=	10.08.2022 10:04:45
#Filter:Polynom=	16.08.2022 10:20:25
#AxisType[0]=Intens
#AxisUnit[0]=Cnt
#AxisType[1]=Spectr
#AxisUnit[1]=1/cm
200.43	32.8497
204.061	26.4555
207.688	21.9264
211.316	19.2274
214.941	17.4907
218.566	16.3392
222.188	15.0367
225.809	12.3531
229.43	10.59
233.047	8.68031
236.663	8.35012
240.278	8.05967
243.894	8.86023
247.506	10.2786
251.116	10.3978
254.725	10.4939
258.333	10.3053
261.939	10.749
265.546	9.48475
269.15	7.31819
272.752	7.07459
276.353	5.96416
279.952	6.16106
283.55	5.75452
287.146	6.83584
290.739	6.77889
294.333	7.81636
297.925	10.5682
301.516	10.8258
305.106	12.4966
308.694	12.7738
312.279	13.7094
315.864	15.0599
319.448	16.2446
323.029	17.089
326.61	18.9069
330.19	19.6214
333.766	20.9608
337.343	19.9103
340.917	18.1833
344.491	17.1626
348.062	17.6165
351.633	16.6891
355.201	14.4354
358.77	13.8041
362.335	13.1926
365.899	13.7582
369.464	14.2968
373.025	13.2746
376.585	13.5976
380.143	14.1119
383.702	15.8531
387.258	15.6028
390.812	14.4466
394.365	13.6311
397.916	13.7971
401.467	12.2397
405.015	10.822
408.565	7.5009
412.111	7.96758
415.656	7.54299
419.197	6.73716
422.739	8.1719
426.279	7.83705
429.819	7.86641
433.356	8.36152
436.893	8.67198
440.428	8.70457
443.96	8.67181
447.492	10.7773
451.023	11.2672
454.553	13.5725
458.079	12.9539
461.606	16.6404
465.132	16.5234
468.654	17.2854
472.177	18.9951
475.696	16.4734
479.217	16.2898
482.733	16.8296
486.251	18.2969
489.765	18.1895
493.278	19.2758
496.791	20.1245
500.301	21.3517
503.81	21.2467
507.319	21.7491
510.825	21.0011
514.33	19.9152
517.833	20.558
521.337	20.4922
524.838	20.7597
528.337	20.3416
531.835	20.1194
535.332	19.309
538.827	18.2474
542.321	16.2558
545.814	16.194
549.305	16.3024
552.795	15.3551
556.284	16.4497
559.771	15.8286
563.257	15.1457
566.742	14.9242
570.223	15.5271
573.705	14.9933
577.185	14.0781
580.665	14.1746
584.141	13.3493
587.617	11.9184
591.092	10.3281
594.564	10.0786
598.037	9.63578
601.506	9.16333
604.976	9.23365
608.443	6.92012
611.91	5.53226
615.374	2.95694
618.839	3.03188
622.3	1.91259
625.761	1.98478
629.221	4.50969
632.679	4.75539
636.135	5.74846
639.592	7.58715
643.045	8.10567
646.497	9.2509
649.948	9.84304
653.398	12.3239
656.846	12.6633
660.293	15.6474
663.738	16.534
667.185	18.021
670.628	19.5159
674.067	22.4025
677.508	24.5184
680.947	26.2645
684.385	26.8069
687.821	28.1714
691.256	27.8436
694.69	29.3056
698.121	30.2921
701.552	32.536
704.982	32.3861
708.41	35.3078
711.836	37.2256
715.262	38.2766
718.685	38.6324
722.108	38.5957
725.53	39.389
728.949	39.6352
732.369	39.8603
735.785	40.0354
739.2	40.723
742.616	41.9595
746.028	42.8693
749.441	45.2112
752.851	47.86
756.26	46.9092
759.667	49.4243
763.075	53.3419
766.479	57.0118
769.883	59.4035
773.285	63.4581
776.686	67.0242
780.085	68.7714
783.484	70.4906
786.881	73.7553
790.276	75.2024
793.671	76.384
797.064	76.9401
800.456	77.3182
803.846	77.1247
807.236	75.5253
810.624	75.6919
814.01	74.5243
817.394	72.0065
820.778	71.2241
824.161	68.2436
827.543	66.6871
830.921	64.3465
834.3	60.6787
837.676	56.6895
841.053	55.0633
844.426	55.6252
847.8	54.0977
851.171	51.8069
854.542	49.2995
857.911	46.3839
861.279	43.3492
864.645	42.5836
868.01	41.6663
871.375	39.9848
874.737	38.0318
878.097	39.5394
881.457	40.5664
884.817	38.5955
888.174	38.7458
891.53	38.2058
894.884	38.4664
898.237	37.9638
901.589	38.976
904.94	38.9335
908.289	39.3075
911.637	38.8484
914.984	37.72
918.33	37.9791
921.674	37.0776
925.015	36.0839
928.357	34.1616
931.698	30.9708
935.037	29.6263
938.373	27.8904
941.71	26.0597
945.046	25.2041
948.378	24.9199
951.711	22.9926
955.043	22.3048
958.372	22.8516
961.701	20.4345
965.027	20.2451
968.354	20.3374
971.678	18.9664
975	19.2841
978.324	20.141
981.644	17.9074
984.962	17.0448
988.282	16.3227
991.598	14.3177
994.913	16.1681
998.227	15.7729
1001.54	16.2976
1004.85	16.4834
1008.16	15.9197
1011.47	14.8498
1014.78	15.511
1018.08	18.4943
1021.39	19.4893
1024.69	18.7991
1028	20.9013
1031.3	22.1379
1034.6	22.5017
1037.9	23.0592
1041.19	21.0635
1044.49	21.9055
1047.79	22.4476
1051.08	21.089
1054.37	18.3679
1057.66	15.126
1060.95	12.5345
1064.24	9.67238
1067.53	2.82947
1070.81	1.16571
1074.1	3.28916
1077.38	5.66518
1080.66	6.2635
1083.94	7.94419
1087.22	9.47552
1090.5	10.4113
1093.78	12.1528
1097.05	16.0716
1100.33	17.3759
1103.6	19.1408
1106.87	19.9514
1110.15	21.3322
1113.41	21.0301
1116.68	19.4387
1119.95	19.476
1123.21	18.911
1126.48	18.5103
1129.74	16.0119
1133	11.9445
1136.26	8.84251
1139.52	7.28692
1142.78	4.17383
1146.04	-0.0292584
1149.29	-2.08285
1152.55	3.38497
1155.8	3.00196
1159.05	3.30345
1162.3	3.44891
1165.55	3.21882
1168.8	3.46602
1172.05	3.10602
1175.29	5.95769
1178.54	5.90507
1181.78	6.23105
1185.02	5.95867
1188.26	5.90356
1191.5	6.40741
1194.74	4.45035
1197.97	4.3021
1201.21	3.58416
1204.44	3.29832
1207.68	4.32457
1210.91	6.20821
1214.14	9.19099
1217.37	11.3283
1220.6	13.0036
1223.82	14.7205
1227.05	17.2757
1230.27	21.2494
1233.49	25.0219
1236.72	27.6057
1239.94	30.8662
1243.16	34.659
1246.37	37.3214
1249.59	41.1637
1252.8	44.1852
1256.02	46.8258
1259.23	47.074
1262.44	48.1247
1265.66	48.9584
1268.87	49.3577
1272.07	49.702
1275.28	51.1829
1278.48	52.7398
1281.69	54.2471
1284.89	54.6974
1288.09	56.1696
1291.3	56.3851
1294.49	54.339
1297.69	55.421
1300.89	56.2128
1304.09	56.8738
1307.28	57.7082
1310.47	58.5531
1313.66	57.696
1316.86	56.5274
1320.05	58.0443
1323.23	58.5189
1326.42	57.751
1329.61	56.3049
1332.79	53.525
1335.98	52.498
1339.16	52.5859
1342.34	51.9053
1345.52	52.3208
1348.7	51.0876
1351.87	51.4554
1355.05	50.7645
1358.23	49.2289
1361.4	45.8612
1364.57	45.0452
1367.74	42.8618
1370.91	40.3483
1374.08	39.5853
1377.25	40.4082
1380.42	41.0586
1383.58	41.2131
1386.75	41.6153
1389.91	40.5642
1393.07	39.7562
1396.23	40.1767
1399.39	42.9447
1402.55	42.8208
1405.7	42.9307
1408.86	44.3414
1412.01	46.8271
1415.17	50.5695
1418.32	54.0071
1421.47	57.9513
1424.62	61.5943
1427.77	65.3282
1430.92	67.8081
1434.06	70.4518
1437.2	73.1584
1440.35	74.1564
1443.49	74.5709
1446.63	75.1954
1449.77	75.794
1452.91	75.9796
1456.05	75.5776
1459.18	73.7964
1462.32	69.1687
1465.45	63.3149
1468.59	58.1026
1471.72	52.7311
1474.85	48.1324
1477.98	43.7161
1481.11	37.9321
1484.23	34.6587
1487.36	32.0662
1490.48	29.9701
1493.61	26.4437
1496.73	26.402
1499.85	27.167
1502.97	26.5391
1506.09	26.3643
1509.2	25.987
1512.32	28.6354
1515.44	29.157
1518.55	31.4501
1521.66	33.0498
1524.77	35.2063
1527.88	35.894
1530.99	37.8738
1534.1	40.7445
1537.21	41.8708
1540.31	42.916
1543.42	44.71
1546.52	47.7405
1549.62	51.5058
1552.72	53.8704
1555.82	57.3749
1558.92	60.3979
1562.02	63.8845
1565.11	67.5166
1568.21	70.5341
1571.3	72.9783
1574.39	75.9739
1577.49	76.6667
1580.58	76.3835
1583.67	75.6255
1586.75	76.5545
1589.84	75.3979
1592.93	74.7931
1596.01	73.5257
1599.09	71.5035
1602.18	69.4886
1605.26	67.8248
1608.34	67.5394
1611.41	66.8207
1614.49	65.5382
1617.57	63.6426
1620.64	63.9796
1623.72	63.0794
1626.79	63.7465
1629.86	65.1863
1632.93	67.8702
1636	68.6746
1639.07	70.8566
1642.14	72.4206
1645.2	73.4513
1648.27	73.7044
1651.33	72.8444
1654.39	72.3653
1657.45	70.7067
1660.51	70.4751
1663.57	69.2547
1666.63	66.8814
1669.69	64.9368
1672.74	61.4718
1675.79	58.2009
1678.85	55.0435
1681.9	51.466
1684.95	47.1334
1688	41.7875
1691.05	37.3595
1694.1	32.4366
1697.14	30.0585
1700.19	28.1011
1703.23	26.1742
1706.27	23.7068
1709.32	21.5973
1712.35	19.5872
1715.39	18.1895
1718.43	16.8119
1721.47	15.216
1724.5	13.8881
1727.54	12.8701
1730.57	11.6223
1733.61	9.19806
1736.64	9.91209
1739.67	8.77496
1742.7	8.10795
1745.72	8.21199
1748.75	7.4217
1751.78	6.75802
1754.8	6.44133
1757.82	5.60167
1760.85	5.77105
1763.87	6.07353
1766.89	6.25769
1769.91	6.71718
1772.92	6.8454
1775.94	7.84373
1778.96	8.38195
1781.97	8.02015
1784.98	8.22499
1788	8.75753
1791.01	7.86654
1794.01	7.73041
1797.02	7.01221
1800.03	7.14217
1803.04	7.03856
1806.04	6.71741
1809.05	6.56086
1812.05	6.28415
1815.05	5.93366
1818.05	5.48564
1821.05	5.36488
1824.05	5.82029
1827.05	6.26377
1830.04	5.68512
1833.04	5.85117
1836.03	5.11793
1839.03	5.28753
1842.02	5.00788
1845.01	5.23004
1848	4.67843
1850.99	4.71594
1853.97	4.74124
1856.96	5.59496
1859.94	6.03199
1862.93	7.09839
1865.91	6.54945
1868.89	6.82104
1871.87	6.84875
1874.85	7.24635
1877.83	8.68265
1880.81	8.98932
1882.56	9.43664
1885.55	9.78617
1888.54	9.50147
1891.52	10.0356
1894.51	9.85847
1897.49	8.60714
1900.48	7.39045
1903.46	5.57597
1906.44	4.32477
1909.42	4.39932
1912.4	4.30252
1915.38	3.71502
1918.35	3.47749
1921.33	2.71729
1924.3	2.50992
1927.28	2.66853
1930.25	2.27269
1933.22	1.53194
1936.19	0.269545
1939.16	-0.69207
1942.13	-1.0465
1945.09	-1.2952
1948.06	-0.469566
1951.03	-0.236144
1953.99	-0.0838623
1956.95	0.550108
1959.91	0.387352
1962.87	0.292816
1965.83	0.322382
1968.79	0.139928
1971.75	0.374873
1974.7	2.32337
1977.66	2.18471
1980.61	3.66046
1983.56	5.48408
1986.52	5.7656
1989.47	6.61494
1992.41	7.0453
1995.36	6.99212
1998.31	6.57408
2001.26	7.44619
2004.2	7.84831
2007.15	7.58896
2010.09	8.54009
2013.03	9.1176
2015.97	9.30727
2018.91	9.80857
2021.85	9.62013
2024.79	11.191
2027.72	11.2156
2030.66	11.09
2033.59	11.2929
2036.53	11.1544
2039.46	10.2883
2042.39	10.7928
2045.32	11.22
2048.25	10.5273
2051.18	11.1056
2054.1	10.8382
2057.03	10.3738
2059.95	10.5139
2062.88	11.112
2065.8	11.6013
2068.72	11.7257
2071.64	12.8068
2074.56	15.0723
2077.48	16.4297
2080.39	18.434
2083.31	20.27
2086.22	21.6864
2089.14	23.5114
2092.05	26.1403
2094.96	29.6369
2097.87	30.962
2100.78	32.648
2103.69	35.716
2106.6	37.5844
2109.51	38.6253
2112.41	40.6622
2115.32	43.0868
2118.22	46.0676
2121.12	47.6694
2124.02	49.8531
2126.92	53.1678
2129.82	56.1471
2132.72	59.132
2135.62	61.055
2138.51	63.2517
2141.41	66.1235
2144.3	69.5808
2147.19	72.1805
2150.09	74.0729
2152.97	75.263
2155.86	76.9872
2158.75	78.2138
2161.64	79.5229
2164.53	81.1639
2167.41	81.078
2170.3	80.2202
2173.18	80.4276
2176.06	78.6148
2178.94	76.223
2181.82	75.7639
2184.7	74.0669
2187.58	73.5269
2190.46	72.3058
2193.33	70.2276
2196.21	69.2096
2199.08	67.607
2201.95	65.1843
2204.83	62.8209
2207.7	60.6339
2210.57	59.8915
2213.43	57.7187
2216.3	54.4403
2219.17	51.502
2222.03	47.4811
2224.9	44.4446
2227.76	41.6987
2230.62	38.0562
2233.49	35.2542
2236.34	31.7512
2239.2	27.9315
2242.06	25.7095
2244.92	23.3162
2247.78	21.7145
2250.63	20.5978
2253.48	20.1464
2256.34	18.8449
2259.19	19.0934
2262.04	19.3174
2264.89	19.9547
2267.74	20.2296
2270.59	20.1598
2273.43	21.0101
2276.28	20.218
2279.12	19.2331
2281.97	19.7534
2284.81	18.6255
2287.65	16.9435
2290.49	15.5981
2293.33	13.8394
2296.17	13.3973
2299.01	12.9566
2301.84	12.9493
2304.68	12.4401
2307.51	13.035
2310.35	13.2064
2313.18	13.0504
2316.01	12.5653
2318.84	12.2808
2321.67	13.3113
2324.5	13.2157
2327.33	13.4594
2330.15	14.0026
2332.98	14.6633
2335.8	14.7337
2338.62	12.8121
2341.45	12.3261
2344.27	11.2924
2347.09	9.96898
2349.91	8.97834
2352.72	9.21951
2355.54	6.60538
2358.36	5.40868
2361.17	4.17971
2363.98	4.64656
2366.8	4.6294
2369.61	4.03243
2372.42	3.5326
2375.23	3.30103
2378.04	3.39212
2380.85	3.2885
2383.66	3.4597
2386.46	3.76666
2389.26	3.82261
2392.07	4.16429
2394.87	4.89556
2397.67	5.65645
2400.47	6.24031
2403.27	6.66422
2406.07	6.43161
2408.87	6.49809
2411.67	6.63032
2414.46	8.09802
2417.26	9.03643
2420.05	10.1247
2422.84	9.7003
2425.64	9.26318
2428.43	9.53298
2431.22	9.32613
2434.01	9.24841
2436.79	9.5225
2439.58	9.61094
2442.37	8.52601
2445.15	8.10601
2447.93	8.16609
2450.72	7.39591
2453.5	7.66188
2456.28	6.02258
2459.06	5.25375
2461.84	5.26351
2464.62	4.33244
2467.39	3.50883
2470.17	1.49905
2472.94	1.7205
2475.72	2.26554
2478.49	2.26362
2481.26	3.49744
2484.03	3.99827
2486.8	4.48053
2489.57	4.39043
2492.34	3.7643
2495.1	4.50099
2497.87	3.9463
2500.63	3.58477
2503.4	4.2741
2506.16	3.48158
2508.92	3.81784
2511.68	3.42655
2514.44	3.05801
2517.2	2.60159
2519.96	1.83846
2522.72	2.53049
2525.47	1.36894
2528.23	2.38307
2530.98	1.90423
2533.74	2.34558
2536.49	3.21127
2539.24	3.21181
2541.99	4.78503
2544.74	5.04995
2547.49	5.79878
2550.23	5.31252
2552.98	4.84132
2555.72	2.5366
2558.47	2.15674
2561.21	2.15918
2563.95	2.38941
2566.69	1.43212
2569.43	2.09474
2572.17	0.757793
2574.91	0.85614
2577.65	-0.252578
2580.39	-0.161066
2583.12	-0.624902
2585.85	0.612266
2588.59	2.42382
2591.32	2.60414
2594.05	3.4906
2596.78	3.75975
2599.51	3.73374
2602.24	4.43139
2604.97	4.59668
2607.69	4.30137
2610.42	5.12197
2613.14	4.78702
2615.87	4.84705
2618.59	4.39104
2621.31	3.99637
2624.03	4.27925
2626.75	4.81588
2629.47	5.59827
2632.19	5.31734
2634.91	4.98375
2637.62	5.01263
2640.34	3.79777
2643.05	4.48559
2645.76	5.1595
2648.48	5.12964
2651.19	4.90196
2653.9	5.0484
2656.6	4.11824
2659.31	4.04538
2662.02	2.28841
2664.73	2.51436
2667.43	2.30523
2670.14	2.91219
2672.84	3.34265
2675.54	3.74638
2678.24	3.96127
2680.94	4.22435
2683.64	5.91042
2686.34	6.43012
2689.04	6.91279
2691.74	7.65916
2694.43	8.63038
2697.13	10.1967
2699.82	11.3198
2702.51	12.0298
2705.21	13.4401
2707.9	14.1421
2710.58	14.8508
2713.27	15.2284
2715.96	14.5459
2718.65	14.7068
2721.33	14.5138
2724.02	14.2122
2726.71	13.8917
2729.39	12.7455
2732.07	12.5354
2734.75	11.6327
2737.43	11.6668
2740.11	11.0238
2742.79	10.77
2745.47	8.59227
2748.14	8.33675
2750.82	7.32979
2753.49	5.94015
2756.17	4.84201
2758.84	4.85647
2761.51	5.81732
2764.18	6.28874
2766.85	6.26449
2769.52	5.80929
2772.19	5.18551
2774.86	4.05604
2777.52	4.34576
2780.19	3.57754
2782.85	3.08727
2785.52	3.73832
2788.18	2.99018
2790.84	1.95628
2793.5	1.44913
2796.16	0.917271
2798.82	1.05227
2801.48	1.42686
2804.13	0.910795
2806.79	0.123064
2809.45	-0.90312
2812.1	-1.26504
2814.75	-1.10297
2817.41	0.632375
2820.06	3.62895
2822.71	8.63569
2825.36	14.7608
2828	19.4516
2830.65	24.9451
2833.3	30.539
2835.94	36.0465
2838.59	41.8483
2841.23	50.0199
2843.87	57.9561
2846.52	66.3478
2849.16	74.0253
2851.8	82.4704
2854.44	89.8808
2857.08	97.7108
2859.71	106.083
2862.35	113.231
2864.98	118.897
2867.62	123.844
2870.25	127.174
2872.88	130.341
2875.52	131.475
2878.15	133.963
2880.78	137.081
2883.41	140.115
2886.03	143.072
2888.66	145.371
2891.29	147.42
2893.91	149.517
2896.54	152.332
2899.16	155.424
2901.78	160.697
2904.4	168.31
2907.02	176.162
2909.64	183.728
2912.26	191.482
2914.88	200.057
2917.5	207.929
2920.11	214.614
2922.73	221.176
2925.34	224.639
2927.96	227.077
2930.57	227.791
2933.18	227.407
2935.79	225.105
2938.4	221.796
2941.01	216.327
2943.62	210.164
2946.22	202.513
2948.83	193.777
2951.43	184.987
2954.04	175.264
2956.64	166.052
2959.24	157.54
2961.84	147.987
2964.45	140.861
2967.05	133.952
2969.64	126.929
2972.24	119.193
2974.84	111.312
2977.43	102.808
2980.03	95.8979
2982.62	88.4144
2985.22	81.3155
2987.81	74.1607
2990.4	66.8384
2992.99	60.7552
2995.58	53.8673
2998.17	47.6639
3000.76	41.6665
3003.34	36.5187
3005.93	30.0051
3008.52	24.604
3011.1	20.1947
3013.68	16.2518
3016.27	12.9301
3018.85	9.92517
3021.43	7.77992
3024.01	5.91907
3026.59	4.88169
3029.16	5.65617
3031.74	5.02818
3034.32	3.85786
3036.89	5.29433
3039.47	5.92369
3042.04	7.18005
3044.61	8.62208
3047.18	9.37333
3049.75	11.5822
3052.32	12.0846
3054.89	11.9474
3057.46	12.101
3060.03	12.9672
3062.59	12.2973
3065.16	12.4116
3067.72	10.5852
3070.29	9.36184
3072.85	8.94828
3075.41	7.11823
3077.97	5.36485
3080.53	3.38468
3083.09	1.43595
3085.65	0.923716
3088.21	0.66661
3090.76	0.776404
3093.32	0.00221469
3095.87	-0.178311
3098.43	0.400125
3100.98	0.958811
3103.53	2.00269
3106.08	2.83156
3108.63	4.78307
3111.18	6.96137
3113.73	9.08537
3116.28	9.98235
3118.83	11.8176
3121.37	13.5431
3123.92	15.5654
3126.46	16.7616
3129	18.4757
3131.55	19.8082
3134.09	21.5458
3136.63	22.718
3139.17	22.4565
3141.71	22.9226
3144.24	23.7201
3146.78	23.5094
3149.32	21.0406