File: data/Raman/poly_smoothed/Thy_50_12_46_1x_45s_532 nm_x100_100%_600 gr_mm_01.txt
#Acq. time (s)=	45
#Accumulations=	2
#Range (cm-¹)=	200...3150
#Windows=	2
#Auto scanning=	Off
#Autofocus=	Off
#Macrospot=	Off
#AutoExposure=	Off
#Spike filter=	Multiple accum.
#Delay time (s)=	0
#Binning=	1
#Readout mode=	Signal
#DeNoise=	Off
#ICS correction=	On
#Dark correction=	Off
#Inst. Process=	Off
#Detector Gain=	Best Dynamic Range
#Detector ADC=	20 kHz
#Detector temperature (°C)=	-69.85
#Instrument=	LabRAM HR Evol
#Detector=	Synapse
#Objective=	x100
#Grating=	600 gr/mm
#ND Filter=	100%
#Laser (nm)=	532
#Hole=	100.021
#Range=	Auto
#Laser Pol.=	No
#Raman. Pol.=	No
#Laser Pol. (°)=	-0.0007625
#Raman Pol. (°)=	89.9995
#Collection=	Microscope
#StageXY=	Marzhauser
#StageZ=	Marzhauser
#X (µm)=	-5114.8
#Y (µm)=	1528.5
#Z (µm)=	63.6
#Full time(mm:ss)=	3:18
#Project=
#Sample=
#Site=
#Title=	Thy_50_12_46_2x_45s_532 nm_x100_100%_600 gr_mm
#Remark=
#Date=	07.07.2022 12:37
#Acquired=	07.07.2022 12:37:54
#Base:Fit=	10.08.2022 10:04:30
#Base:Sub=	10.08.2022 10:04:45
#Filter:Polynom=	16.08.2022 10:20:25
#AxisType[0]=Intens
#AxisUnit[0]=Cnt
#AxisType[1]=Spectr
#AxisUnit[1]=1/cm
200.43	3.78499
204.061	4.76593
207.688	4.06477
211.316	3.34795
214.941	2.73326
218.566	2.80769
222.188	2.02228
225.809	3.72112
229.43	5.14453
233.047	8.43168
236.663	8.86878
240.278	9.19154
243.894	9.48949
247.506	10.4307
251.116	11.3568
254.725	11.8749
258.333	13.1598
261.939	14.1985
265.546	15.1245
269.15	13.3942
272.752	11.3642
276.353	10.4375
279.952	9.86771
283.55	9.65924
287.146	9.58153
290.739	9.84343
294.333	9.11845
297.925	10.4441
301.516	12.4812
305.106	12.9034
308.694	13.6017
312.279	15.1723
315.864	17.7178
319.448	18.6602
323.029	19.2806
326.61	19.8513
330.19	21.0648
333.766	23.075
337.343	25.9938
340.917	27.4313
344.491	26.5067
348.062	25.9865
351.633	24.5401
355.201	21.7449
358.77	20.0647
362.335	19.3609
365.899	18.7226
369.464	18.0604
373.025	16.6115
376.585	16.0558
380.143	14.2426
383.702	13.9783
387.258	13.0159
390.812	12.9363
394.365	13.007
397.916	14.0686
401.467	15.0859
405.015	15.5503
408.565	15.9597
412.111	17.4459
415.656	18.9253
419.197	20.9484
422.739	23.6165
426.279	22.7494
429.819	23.379
433.356	23.0471
436.893	24.239
440.428	23.2337
443.96	23.5722
447.492	24.4199
451.023	23.3625
454.553	22.1446
458.079	20.1145
461.606	20.5696
465.132	20.1365
468.654	21.2389
472.177	20.4481
475.696	21.1011
479.217	23.0648
482.733	23.8121
486.251	25.2536
489.765	25.9707
493.278	28.1629
496.791	29.4603
500.301	31.5701
503.81	33.062
507.319	33.8236
510.825	32.9125
514.33	32.8905
517.833	32.2063
521.337	31.0921
524.838	30.9643
528.337	32.2629
531.835	32.2592
535.332	31.2068
538.827	29.1062
542.321	28.0687
545.814	24.7218
549.305	22.7739
552.795	21.0201
556.284	17.2541
559.771	15.2472
563.257	13.9003
566.742	12.9142
570.223	11.8236
573.705	11.3108
577.185	10.8824
580.665	11.2416
584.141	10.1155
587.617	7.00415
591.092	5.89303
594.564	4.33723
598.037	4.63053
601.506	5.09186
604.976	5.2545
608.443	7.21367
611.91	8.5319
615.374	9.5725
618.839	9.26708
622.3	9.69619
625.761	9.75765
629.221	9.94927
632.679	8.82018
636.135	9.82113
639.592	10.4202
643.045	11.5871
646.497	14.5429
649.948	16.235
653.398	18.6666
656.846	20.2145
660.293	19.2557
663.738	19.6508
667.185	21.3217
670.628	20.1263
674.067	21.0722
677.508	21.7304
680.947	23.4898
684.385	25.1066
687.821	24.9666
691.256	26.5587
694.69	27.4982
698.121	28.2222
701.552	28.9469
704.982	29.5408
708.41	32.6474
711.836	33.9879
715.262	33.784
718.685	34.5623
722.108	35.1838
725.53	38.4818
728.949	39.5047
732.369	40.5753
735.785	40.6835
739.2	41.9162
742.616	42.928
746.028	43.2124
749.441	45.3153
752.851	47.1544
756.26	48.2675
759.667	49.5505
763.075	51.3545
766.479	54.4928
769.883	57.877
773.285	60.8181
776.686	63.8751
780.085	67.0613
783.484	68.7973
786.881	69.8878
790.276	71.1346
793.671	73.1546
797.064	73.7123
800.456	73.1853
803.846	73.1448
807.236	72.0041
810.624	72.407
814.01	71.5224
817.394	69.0631
820.778	68.6339
824.161	66.6647
827.543	65.1821
830.921	62.6037
834.3	60.4177
837.676	59.6866
841.053	57.4832
844.426	56.6436
847.8	55.9794
851.171	54.6557
854.542	54.1964
857.911	52.938
861.279	51.3308
864.645	50.3204
868.01	48.4063
871.375	47.4984
874.737	46.0509
878.097	45.354
881.457	42.7026
884.817	41.069
888.174	40.2401
891.53	39.5586
894.884	39.2661
898.237	38.4518
901.589	36.7917
904.94	36.5997
908.289	34.0976
911.637	34.0823
914.984	34.4056
918.33	32.7067
921.674	31.5281
925.015	30.6207
928.357	29.4337
931.698	26.3747
935.037	26.1462
938.373	24.3366
941.71	22.8589
945.046	21.4862
948.378	21.0036
951.711	19.5571
955.043	19.1942
958.372	16.6635
961.701	16.6488
965.027	17.0462
968.354	17.7935
971.678	18.8544
975	20.0524
978.324	21.0527
981.644	21.5797
984.962	21.6903
988.282	22.4136
991.598	22.2576
994.913	23.4813
998.227	23.6659
1001.54	21.9647
1004.85	21.229
1008.16	21.276
1011.47	19.2103
1014.78	18.5338
1018.08	18.8099
1021.39	18.3599
1024.69	19.4519
1028	20.5151
1031.3	22.9677
1034.6	22.4133
1037.9	21.8837
1041.19	20.5181
1044.49	20.705
1047.79	21.3132
1051.08	20.8515
1054.37	19.9085
1057.66	18.9343
1060.95	16.649
1064.24	13.68
1067.53	13.404
1070.81	10.2704
1074.1	8.71864
1077.38	10.4917
1080.66	7.75117
1083.94	7.2239
1087.22	7.4252
1090.5	8.13572
1093.78	9.87266
1097.05	12.8201
1100.33	13.7009
1103.6	15.5409
1106.87	17.9151
1110.15	18.1687
1113.41	18.4701
1116.68	18.6865
1119.95	16.5433
1123.21	17.4591
1126.48	16.7782
1129.74	16.657
1133	14.6264
1136.26	13.0229
1139.52	9.98632
1142.78	7.73543
1146.04	6.80311
1149.29	4.93777
1152.55	2.9301
1155.8	1.86886
1159.05	0.567026
1162.3	-0.453232
1165.55	0.164033
1168.8	0.606723
1172.05	2.6701
1175.29	3.69958
1178.54	2.72947
1181.78	2.18838
1185.02	3.43261
1188.26	4.93062
1191.5	4.41266
1194.74	6.97315
1197.97	8.18335
1201.21	8.71909
1204.44	10.188
1207.68	11.9539
1210.91	14.1757
1214.14	17.8582
1217.37	20.2337
1220.6	23.2549
1223.82	27.2258
1227.05	28.8708
1230.27	31.4783
1233.49	34.8811
1236.72	37.4258
1239.94	43.1508
1243.16	46.7387
1246.37	50.4102
1249.59	53.6051
1252.8	57.554
1256.02	58.649
1259.23	61.0878
1262.44	64.7032
1265.66	66.9591
1268.87	67.2885
1272.07	70.1224
1275.28	71.849
1278.48	71.4312
1281.69	70.8362
1284.89	72.8546
1288.09	74.9551
1291.3	76.0452
1294.49	77.6852
1297.69	77.7001
1300.89	78.5999
1304.09	78.8556
1307.28	78.633
1310.47	80.2565
1313.66	81.5702
1316.86	81.6018
1320.05	83.3254
1323.23	83.0124
1326.42	81.8158
1329.61	79.896
1332.79	79.9653
1335.98	76.9174
1339.16	72.8669
1342.34	72.2955
1345.52	68.0756
1348.7	66.2217
1351.87	64.0376
1355.05	59.6478
1358.23	55.738
1361.4	54.4499
1364.57	52.5656
1367.74	50.5915
1370.91	49.381
1374.08	48.6887
1377.25	48.6196
1380.42	46.3605
1383.58	45.9282
1386.75	46.1369
1389.91	46.6388
1393.07	46.5841
1396.23	46.3762
1399.39	47.2985
1402.55	46.8814
1405.7	48.2604
1408.86	48.8576
1412.01	50.6062
1415.17	51.8303
1418.32	55.8883
1421.47	60.2065
1424.62	64.258
1427.77	67.899
1430.92	72.1647
1434.06	77.2449
1437.2	83.236
1440.35	86.6116
1443.49	90.2452
1446.63	92.4374
1449.77	92.7504
1452.91	92.5023
1456.05	89.9258
1459.18	87.4352
1462.32	84.602
1465.45	79.5114
1468.59	73.6902
1471.72	66.6108
1474.85	62.5095
1477.98	56.9616
1481.11	50.6416
1484.23	44.334
1487.36	38.3896
1490.48	33.6135
1493.61	30.2336
1496.73	28.2674
1499.85	26.4164
1502.97	24.8964
1506.09	24.7927
1509.2	25.6018
1512.32	26.2711
1515.44	25.7743
1518.55	27.5382
1521.66	28.9268
1524.77	29.5531
1527.88	32.6967
1530.99	34.8099
1534.1	38.1018
1537.21	42.1315
1540.31	45.3979
1543.42	51.7556
1546.52	55.4201
1549.62	60.883
1552.72	65.1407
1555.82	68.8599
1558.92	73.1709
1562.02	76.1628
1565.11	79.6837
1568.21	84.05
1571.3	87.9356
1574.39	89.3726
1577.49	92.6331
1580.58	93.8568
1583.67	94.3982
1586.75	92.3672
1589.84	92.2354
1592.93	91.3414
1596.01	89.0852
1599.09	86.5321
1602.18	85.5703
1605.26	83.658
1608.34	81.0531
1611.41	80.4517
1614.49	79.9677
1617.57	77.8141
1620.64	77.7791
1623.72	77.1885
1626.79	77.0412
1629.86	77.7823
1632.93	78.8296
1636	77.8305
1639.07	79.5979
1642.14	80.7105
1645.2	82.1887
1648.27	82.2645
1651.33	83.3269
1654.39	82.7731
1657.45	82.1928
1660.51	80.6938
1663.57	77.8691
1666.63	75.9277
1669.69	73.4283
1672.74	69.9366
1675.79	66.0051
1678.85	62.5487
1681.9	56.6421
1684.95	50.9246
1688	46.4706
1691.05	41.3671
1694.1	36.8803
1697.14	33.5693
1700.19	29.7572
1703.23	25.6736
1706.27	22.6082
1709.32	19.8609
1712.35	17.0082
1715.39	14.9043
1718.43	13.7258
1721.47	12.9016
1724.5	12.7003
1727.54	12.0524
1730.57	10.8954
1733.61	10.3342
1736.64	10.2577
1739.67	10.8958
1742.7	11.4472
1745.72	10.6212
1748.75	10.1771
1751.78	9.60392
1754.8	8.37241
1757.82	7.29021
1760.85	6.27197
1763.87	6.19995
1766.89	6.14969
1769.91	6.67865
1772.92	6.5504
1775.94	6.28096
1778.96	5.57647
1781.97	5.31298
1784.98	3.81984
1788	3.6998
1791.01	2.87133
1794.01	2.91296
1797.02	3.85212
1800.03	3.22716
1803.04	2.43204
1806.04	3.26099
1809.05	2.74315
1812.05	2.97344
1815.05	2.81263
1818.05	2.83418
1821.05	3.32046
1824.05	2.66921
1827.05	2.11347
1830.04	1.78521
1833.04	2.66059
1836.03	3.48731
1839.03	4.32329
1842.02	5.06882
1845.01	6.01631
1848	7.13229
1850.99	6.56581
1853.97	5.50214
1856.96	4.31444
1859.94	3.31046
1862.93	2.98538
1865.91	3.06686
1868.89	3.05431
1871.87	3.58985
1874.85	4.0628
1877.83	5.7581
1880.81	6.11304
1882.56	7.00391
1885.55	8.00562
1888.54	7.60712
1891.52	7.7402
1894.51	7.29029
1897.49	6.70402
1900.48	6.99736
1903.46	7.1625
1906.44	7.9515
1909.42	7.0601
1912.4	6.82262
1915.38	7.2683
1918.35	7.36914
1921.33	5.99847
1924.3	4.24364
1927.28	3.59554
1930.25	1.30249
1933.22	1.46656
1936.19	1.61481
1939.16	2.23416
1942.13	2.94007
1945.09	4.36822
1948.06	4.52657
1951.03	5.15469
1953.99	5.59796
1956.95	5.0556
1959.91	5.2292
1962.87	4.84235
1965.83	4.25283
1968.79	4.97103
1971.75	5.5869
1974.7	5.85917
1977.66	5.58162
1980.61	5.88763
1983.56	6.92437
1986.52	8.35702
1989.47	8.50272
1992.41	8.13748
1995.36	7.63007
1998.31	6.32832
2001.26	6.67079
2004.2	6.39917
2007.15	6.8476
2010.09	8.00187
2013.03	8.05334
2015.97	8.53624
2018.91	8.54226
2021.85	8.54345
2024.79	7.9026
2027.72	7.95663
2030.66	8.49407
2033.59	8.13045
2036.53	9.05342
2039.46	11.1466
2042.39	11.2638
2045.32	11.0534
2048.25	10.0756
2051.18	9.51995
2054.1	9.63006
2057.03	8.67261
2059.95	8.56562
2062.88	8.91728
2065.8	9.3608
2068.72	10.041
2071.64	11.0183
2074.56	12.1831
2077.48	13.658
2080.39	15.3464
2083.31	15.6491
2086.22	18.1244
2089.14	19.3791
2092.05	20.9486
2094.96	22.2623
2097.87	24.4553
2100.78	28.1425
2103.69	30.249
2106.6	32.5665
2109.51	35.641
2112.41	36.1878
2115.32	37.5509
2118.22	40.0308
2121.12	41.5042
2124.02	45.2168
2126.92	48.3977
2129.82	51.6618
2132.72	54.0943
2135.62	57.3338
2138.51	60.6272
2141.41	63.4181
2144.3	66.1631
2147.19	68.6861
2150.09	71.023
2152.97	73.3922
2155.86	76.2657
2158.75	78.4504
2161.64	79.3431
2164.53	80.07
2167.41	80.4141
2170.3	81.348
2173.18	82.4223
2176.06	82.0458
2178.94	80.6579
2181.82	79.6493
2184.7	78.045
2187.58	76.4648
2190.46	74.7276
2193.33	72.5829
2196.21	69.7693
2199.08	65.9601
2201.95	62.9119
2204.83	59.4619
2207.7	56.9892
2210.57	53.6182
2213.43	51.1094
2216.3	47.0176
2219.17	43.636
2222.03	40.5365
2224.9	38.4801
2227.76	34.7742
2230.62	32.2867
2233.49	30.2961
2236.34	28.7291
2239.2	27.4076
2242.06	26.2015
2244.92	25.8809
2247.78	24.434
2250.63	24.4534
2253.48	24.0078
2256.34	23.1347
2259.19	22.8668
2262.04	22.5949
2264.89	22.0948
2267.74	20.7328
2270.59	20.1009
2273.43	19.0723
2276.28	17.6573
2279.12	16.508
2281.97	15.4739
2284.81	13.1544
2287.65	11.629
2290.49	10.195
2293.33	8.47491
2296.17	8.29904
2299.01	7.61285
2301.84	7.58006
2304.68	7.90298
2307.51	7.63794
2310.35	6.48035
2313.18	8.16258
2316.01	8.78742
2318.84	9.6462
2321.67	9.84408
2324.5	9.29332
2327.33	9.00511
2330.15	9.24011
2332.98	8.61955
2335.8	7.50722
2338.62	6.85418
2341.45	6.83552
2344.27	5.58083
2347.09	4.58791
2349.91	4.78658
2352.72	3.55457
2355.54	2.23315
2358.36	1.95041
2361.17	1.25692
2363.98	1.20677
2366.8	2.01313
2369.61	1.30469
2372.42	1.13624
2375.23	0.469042
2378.04	1.12384
2380.85	0.0332287
2383.66	1.45724
2386.46	2.99448
2389.26	3.29165
2392.07	4.10988
2394.87	4.52689
2397.67	5.11914
2400.47	6.27684
2403.27	7.66874
2406.07	8.33656
2408.87	8.02886
2411.67	8.23854
2414.46	7.95081
2417.26	7.60054
2420.05	7.00963
2422.84	5.22086
2425.64	5.20325
2428.43	4.62148
2431.22	4.31302
2434.01	3.40311
2436.79	3.94813
2439.58	3.24682
2442.37	3.56183
2445.15	3.23978
2447.93	3.5014
2450.72	4.13168
2453.5	5.59852
2456.28	5.49243
2459.06	4.74858
2461.84	4.73286
2464.62	4.59499
2467.39	5.23028
2470.17	4.77669
2472.94	4.31629
2475.72	3.58553
2478.49	3.06109
2481.26	1.70545
2484.03	1.05977
2486.8	-0.247158
2489.57	-0.968267
2492.34	-0.996108
2495.1	-0.419811
2497.87	0.522096
2500.63	1.75941
2503.4	1.75312
2506.16	3.02395
2508.92	3.37784
2511.68	4.6803
2514.44	5.46962
2517.2	5.91878
2519.96	7.03143
2522.72	8.31152
2525.47	8.49233
2528.23	10.2867
2530.98	10.2918
2533.74	10.0573
2536.49	10.1546
2539.24	10.5165
2541.99	10.6593
2544.74	10.7356
2547.49	10.7736
2550.23	10.8251
2552.98	10.3472
2555.72	10.6118
2558.47	11.6839
2561.21	11.7373
2563.95	11.979
2566.69	11.7922
2569.43	11.5814
2572.17	11.4696
2574.91	12.9944
2577.65	12.6342
2580.39	12.4332
2583.12	11.9982
2585.85	12.0608
2588.59	12.7033
2591.32	12.484
2594.05	12.476
2596.78	11.8418
2599.51	10.4244
2602.24	10.7961
2604.97	10.6637
2607.69	9.8639
2610.42	9.92502
2613.14	10.0085
2615.87	10.3318
2618.59	9.92694
2621.31	10.4803
2624.03	10.1312
2626.75	9.67171
2629.47	9.18861
2632.19	9.26849
2634.91	9.42482
2637.62	8.72003
2640.34	8.43371
2643.05	7.82349
2645.76	6.65391
2648.48	6.20584
2651.19	6.37508
2653.9	5.89889
2656.6	6.13502
2659.31	4.80212
2662.02	4.92328
2664.73	4.74566
2667.43	4.35063
2670.14	5.19953
2672.84	4.75753
2675.54	4.10741
2678.24	3.63488
2680.94	5.16534
2683.64	4.38415
2686.34	5.31004
2689.04	6.05282
2691.74	6.45349
2694.43	7.482
2697.13	7.94482
2699.82	9.1186
2702.51	9.50071
2705.21	9.58216
2707.9	10.9592
2710.58	10.6763
2713.27	11.8138
2715.96	12.2675
2718.65	12.9244
2721.33	13.2385
2724.02	12.6477
2726.71	12.7926
2729.39	12.2385
2732.07	11.6669
2734.75	10.6469
2737.43	9.01881
2740.11	7.4825
2742.79	6.54636
2745.47	5.39339
2748.14	4.46349
2750.82	3.81787
2753.49	3.50625
2756.17	2.18871
2758.84	1.20575
2761.51	1.25676
2764.18	0.875606
2766.85	0.495164
2769.52	-0.680259
2772.19	0.0679843
2774.86	0.882402
2777.52	2.06281
2780.19	1.83367
2782.85	3.2241
2785.52	4.15331
2788.18	4.20622
2790.84	3.78894
2793.5	4.48268
2796.16	3.59648
2798.82	4.71982
2801.48	4.09407
2804.13	2.86059
2806.79	1.92063
2809.45	-0.349745
2812.1	-2.12973
2814.75	-1.68146
2817.41	-1.69267
2820.06	-0.468582
2822.71	1.50735
2825.36	5.05405
2828	8.15283
2830.65	10.9687
2833.3	16.4904
2835.94	22.3231
2838.59	28.552
2841.23	35.5027
2843.87	40.4593
2846.52	46.9601
2849.16	54.0342
2851.8	60.0103
2854.44	66.1091
2857.08	72.3997
2859.71	79.1421
2862.35	85.7912
2864.98	91.9708
2867.62	95.2763
2870.25	98.0223
2872.88	100.433
2875.52	102.793
2878.15	105.974
2880.78	110.612
2883.41	113.383
2886.03	116.822
2888.66	120.272
2891.29	123.423
2893.91	126.993
2896.54	131.169
2899.16	136.549
2901.78	141.286
2904.4	146.295
2907.02	153.199
2909.64	160.901
2912.26	167.572
2914.88	174.475
2917.5	180.685
2920.11	186.306
2922.73	191.657
2925.34	196.011
2927.96	197.282
2930.57	197.224
2933.18	196.734
2935.79	194.883
2938.4	191.746
2941.01	188.034
2943.62	183.492
2946.22	177.212
2948.83	169.565
2951.43	162.574
2954.04	154.076
2956.64	146.526
2959.24	139.041
2961.84	132.293
2964.45	124.956
2967.05	118.525
2969.64	112.609
2972.24	106.515
2974.84	99.3206
2977.43	92.1223
2980.03	84.968
2982.62	77.0277
2985.22	68.8026
2987.81	60.9005
2990.4	52.3314
2992.99	45.0905
2995.58	38.5499
2998.17	32.9456
3000.76	27.5835
3003.34	22.6156
3005.93	17.6945
3008.52	13.3833
3011.1	10.0194
3013.68	6.52801
3016.27	3.49149
3018.85	1.96542
3021.43	0.0589454
3024.01	0.441849
3026.59	-0.53218
3029.16	-0.320806
3031.74	0.22817
3034.32	0.684254
3036.89	2.13031
3039.47	2.63464
3042.04	2.71833
3044.61	2.33538
3047.18	2.57041
3049.75	2.24191
3052.32	3.00144
3054.89	3.43258
3057.46	4.8498
3060.03	5.85798
3062.59	5.11454
3065.16	5.30043
3067.72	5.64947
3070.29	6.78878
3072.85	5.5047
3075.41	4.8784
3077.97	3.61457
3080.53	2.78414
3083.09	2.29824
3085.65	2.25224
3088.21	2.24414
3090.76	2.42265
3093.32	4.09591
3095.87	5.25611
3098.43	6.38563
3100.98	6.93041
3103.53	7.29921
3106.08	8.28972
3108.63	9.69689
3111.18	12.4243
3113.73	13.4985
3116.28	15.5337
3118.83	17.8805
3121.37	19.8839
3123.92	21.0579
3126.46	23.6193
3129	26.7754
3131.55	28.4626
3134.09	30.5289
3136.63	31.1255
3139.17	32.834
3141.71	35.5422
3144.24	39.1005
3146.78	43.4559
3149.32	47.3724