File: data/Raman/poly_smoothed/Thy_20_09_06_1x_45s_532 nm_x100_100%_600 gr_mm_01.txt
#Acq. time (s)=	45
#Accumulations=	2
#Range (cm-¹)=	200...3150
#Windows=	2
#Auto scanning=	Off
#Autofocus=	Off
#Macrospot=	Off
#AutoExposure=	Off
#Spike filter=	Multiple accum.
#Delay time (s)=	0
#Binning=	1
#Readout mode=	Signal
#DeNoise=	Off
#ICS correction=	On
#Dark correction=	Off
#Inst. Process=	Off
#Detector Gain=	Best Dynamic Range
#Detector ADC=	20 kHz
#Detector temperature (°C)=	-69.85
#Instrument=	LabRAM HR Evol
#Detector=	Synapse
#Objective=	x100
#Grating=	600 gr/mm
#ND Filter=	100%
#Laser (nm)=	532
#Hole=	100.021
#Range=	Auto
#Laser Pol.=	No
#Raman. Pol.=	No
#Laser Pol. (°)=	-0.0007625
#Raman Pol. (°)=	89.9995
#Collection=	Microscope
#StageXY=	Marzhauser
#StageZ=	Marzhauser
#X (µm)=	-5920.1
#Y (µm)=	2830.3
#Z (µm)=	-223.3
#Full time(mm:ss)=	3:18
#Project=
#Sample=
#Site=
#Title=	Thy_20_09_06_2x_45s_532 nm_x100_100%_600 gr_mm
#Remark=
#Date=	29.06.2022 11:09
#Acquired=	29.06.2022 11:09:57
#Base:Fit=	10.08.2022 09:49:32
#Base:Fit=	10.08.2022 09:49:42
#Base:Fit=	10.08.2022 09:49:53
#Base:Fit=	10.08.2022 09:50:12
#Base:Fit=	10.08.2022 09:50:26
#Base:Fit=	10.08.2022 09:50:30
#Base:Fit=	10.08.2022 09:50:43
#Base:Fit=	10.08.2022 09:52:02
#Base:Fit=	10.08.2022 09:52:12
#Base:Sub=	10.08.2022 09:54:21
#Filter:Polynom=	16.08.2022 10:24:04
#AxisType[0]=Intens
#AxisUnit[0]=Cnt
#AxisType[1]=Spectr
#AxisUnit[1]=1/cm
200.523	0.906038
204.154	5.25457
207.781	7.19452
211.409	8.89898
215.034	11.2115
218.659	11.1468
222.281	11.1276
225.903	10.1627
229.522	10.2122
233.14	10.446
236.756	11.4829
240.373	10.1711
243.986	9.59803
247.598	10.1305
251.208	9.58359
254.818	6.48662
258.427	6.68042
262.034	6.43353
265.638	5.90459
269.242	5.87256
272.844	6.34331
276.445	5.25218
280.044	5.49898
283.642	4.06358
287.238	5.01865
290.833	4.49262
294.425	5.44718
298.017	7.78363
301.608	9.09338
305.198	8.99187
308.786	8.93553
312.371	8.60295
315.956	9.62406
319.54	10.2697
323.122	10.348
326.701	11.2828
330.281	11.4207
333.857	11.6183
337.434	12.3606
341.008	10.8314
344.582	10.9853
348.153	10.4607
351.724	11.074
355.292	11.1154
358.861	10.9262
362.426	10.4394
365.99	9.6675
369.555	9.07487
373.116	8.71696
376.676	8.34017
380.236	7.28873
383.793	7.67664
387.349	6.04538
390.903	5.14501
394.456	4.1327
398.007	2.7513
401.56	2.92698
405.108	1.3196
408.656	1.48886
412.202	1.7105
415.746	3.23318
419.29	2.1611
422.831	1.02917
426.37	2.17349
429.909	1.71657
433.447	2.29348
436.983	3.4334
440.519	3.93991
444.052	3.86162
447.583	3.3598
451.114	4.68851
454.643	5.58139
458.169	6.71376
461.696	8.28528
465.222	9.6414
468.744	10.8685
472.267	12.6546
475.787	13.9267
479.307	15.1814
482.823	15.8436
486.341	16.6586
489.855	17.2472
493.37	17.7294
496.881	17.1474
500.391	18.6131
503.902	17.8804
507.409	18.2757
510.915	18.8788
514.42	17.6699
517.925	17.2666
521.427	17.4067
524.928	17.9275
528.427	17.8936
531.925	17.5326
535.422	18.5658
538.917	19.7814
542.411	21.0664
545.903	20.4044
549.395	19.236
552.884	18.3261
556.373	17.8449
559.86	16.7069
563.346	15.2129
566.831	13.042
570.314	12.5918
573.794	10.795
577.274	8.53046
580.754	7.47521
584.23	6.23253
587.706	5.81996
591.181	3.59608
594.653	2.67745
598.126	-0.46485
601.595	0.245257
605.065	1.69667
608.532	3.78869
611.999	3.66485
615.463	3.76863
618.928	5.5816
622.389	7.00078
625.851	5.67679
629.31	6.31369
632.767	7.92497
636.223	9.03378
639.68	12.395
643.134	13.5161
646.586	16.1157
650.037	17.9687
653.486	19.4579
656.936	20.5368
660.383	22.4504
663.829	22.9213
667.273	22.6134
670.716	23.493
674.158	24.1519
677.598	24.4111
681.035	25.9319
684.473	27.0827
687.909	29.5785
691.344	30.0992
694.778	30.0315
698.211	29.6798
701.64	30.5977
705.07	30.9707
708.498	32.2674
711.924	33.1377
715.35	36.4023
718.774	38.5573
722.196	40.3054
725.618	42.3812
729.037	43.8403
732.456	43.912
735.873	45.0939
739.289	44.9356
742.703	45.8961
746.116	46.3588
749.529	46.6228
752.938	49.4981
756.347	52.7871
759.756	54.2601
763.162	56.377
766.567	58.0431
769.97	58.6385
773.372	60.4268
776.773	61.2863
780.174	63.3774
783.573	64.355
786.97	65.3267
790.365	68.4903
793.76	71.421
797.153	73.131
800.543	74.5417
803.933	75.6288
807.322	75.0092
810.71	75.7531
814.097	73.8844
817.483	73.335
820.865	73.4019
824.248	72.4418
827.629	71.7013
831.008	72.0171
834.387	71.6761
837.765	71.0689
841.139	69.636
844.514	65.2293
847.886	63.5487
851.259	61.9703
854.629	59.896
857.997	57.485
861.366	54.6384
864.732	53.4799
868.098	51.9651
871.461	52.49
874.823	50.8307
878.184	50.6536
881.545	48.9645
884.903	47.5667
888.26	46.3194
891.616	44.4
894.97	42.9107
898.323	42.17
901.675	42.6249
905.026	40.2
908.375	39.5014
911.723	39.1424
915.07	39.1765
918.415	37.5367
921.76	35.3754
925.103	34.139
928.443	32.008
931.783	30.7589
935.123	29.8475
938.461	28.2615
941.796	28.2517
945.131	27.2934
948.465	26.493
951.797	26.5123
955.128	25.8758
958.457	23.2506
961.786	22.47
965.113	23.6582
968.44	24.5298
971.763	27.3062
975.086	29.0266
978.409	30.2808
981.729	32.0203
985.048	31.8081
988.367	33.0257
991.683	35.0205
994.998	35.6017
998.312	34.6338
1001.62	32.7395
1004.94	30.7513
1008.25	30.5328
1011.56	29.6273
1014.86	27.9755
1018.17	25.7251
1021.48	24.2544
1024.78	22.1826
1028.08	20.9323
1031.38	20.1535
1034.68	17.9286
1037.98	16.8741
1041.28	14.5471
1044.57	18.0575
1047.87	18.4373
1051.16	18.9081
1054.45	20.0527
1057.75	19.923
1061.04	20.4578
1064.32	20.2828
1067.61	19.8564
1070.9	20.3325
1074.18	18.8909
1077.47	17.8217
1080.75	17.171
1084.03	15.4084
1087.31	14.1432
1090.59	16.2058
1093.86	16.7569
1097.14	17.3621
1100.41	18.5403
1103.69	18.7731
1106.96	19.3283
1110.23	18.8598
1113.5	16.5278
1116.77	16.9598
1120.03	15.7352
1123.3	15.7413
1126.56	14.3889
1129.83	13.031
1133.09	14.6783
1136.35	14.9691
1139.61	13.5148
1142.86	13.3669
1146.12	13.6325
1149.38	13.5577
1152.63	12.2289
1155.88	10.981
1159.14	10.1607
1162.39	8.06433
1165.63	6.98739
1168.88	8.02029
1172.13	11.1926
1175.38	11.8769
1178.62	11.0838
1181.86	9.92043
1185.1	10.3164
1188.34	10.9321
1191.58	11.0873
1194.82	12.4464
1198.06	15.2091
1201.29	17.1289
1204.53	20.7795
1207.76	25.01
1210.99	30.9791
1214.22	34.3638
1217.45	39.5312
1220.68	44.6714
1223.91	48.7222
1227.13	51.0643
1230.36	54.424
1233.58	57.7875
1236.8	60.2415
1240.02	63.2306
1243.24	64.7805
1246.46	68.2225
1249.67	70.9428
1252.89	71.7928
1256.1	73.2753
1259.32	73.3904
1262.53	75.9067
1265.74	77.6242
1268.95	77.281
1272.15	79.0519
1275.36	81.9355
1278.57	82.5256
1281.77	86.3343
1284.97	90.265
1288.18	93.0173
1291.38	94.191
1294.58	97.5345
1297.78	99.7342
1300.97	102.976
1304.17	104.68
1307.36	107.654
1310.55	112.323
1313.75	114.306
1316.94	115.426
1320.13	116.234
1323.32	116.627
1326.5	116.558
1329.69	116.11
1332.87	115.771
1336.06	113.569
1339.24	113.675
1342.42	111.629
1345.6	109.783
1348.78	106.862
1351.96	102.959
1355.13	98.6928
1358.31	94.9365
1361.48	92.2511
1364.65	88.0303
1367.82	82.3518
1370.99	78.5626
1374.16	76.0368
1377.33	73.2373
1380.5	71.8733
1383.66	67.4588
1386.83	65.2587
1389.99	64.0509
1393.15	61.416
1396.31	59.1835
1399.47	58.4428
1402.63	58.392
1405.78	58.7386
1408.94	58.5863
1412.1	60.7055
1415.25	63.9576
1418.4	68.2455
1421.55	74.0767
1424.7	79.0441
1427.85	84.3649
1431	91.59
1434.14	98.4209
1437.29	103.604
1440.43	107.054
1443.57	108.92
1446.71	110.51
1449.85	111.831
1452.99	110.891
1456.13	109.278
1459.26	105.195
1462.4	101.933
1465.54	96.9457
1468.67	90.1682
1471.8	82.5753
1474.93	76.2437
1478.06	69.4279
1481.19	62.139
1484.31	56.1851
1487.44	50.3793
1490.56	47.8622
1493.69	45.3585
1496.81	43.9037
1499.93	42.4193
1503.05	42.6726
1506.17	42.7652
1509.28	42.1706
1512.4	42.5532
1515.52	41.8033
1518.63	42.5907
1521.74	43.1131
1524.85	43.7737
1527.96	44.904
1531.07	47.7528
1534.18	49.9517
1537.29	52.1653
1540.39	54.8267
1543.5	56.987
1546.6	60.1644
1549.7	65.5412
1552.8	68.3783
1555.9	72.1367
1559	76.3596
1562.1	80.7168
1565.19	84.8658
1568.29	89.1491
1571.38	92.0451
1574.47	95.9525
1577.56	99.3397
1580.66	103.414
1583.74	104.465
1586.83	107.19
1589.92	107.934
1593.01	107.805
1596.09	108.133
1599.17	108.288
1602.25	105.417
1605.34	104.093
1608.41	103.02
1611.49	100.34
1614.57	96.7475
1617.65	95.3065
1620.72	94.1311
1623.79	93.0872
1626.87	90.5766
1629.94	89.6229
1633.01	88.9519
1636.08	90.4503
1639.15	90.9841
1642.21	94.3435
1645.28	95.4906
1648.34	97.5089
1651.41	98.5834
1654.47	98.5427
1657.53	97.4258
1660.59	95.2962
1663.65	93.4016
1666.71	89.8533
1669.76	86.1254
1672.82	81.2387
1675.87	75.64
1678.93	70.502
1681.98	63.2874
1685.03	56.2308
1688.08	51.2084
1691.13	46.7311
1694.17	43.5266
1697.22	37.9032
1700.27	31.915
1703.31	29.0226
1706.35	25.7925
1709.39	23.5213
1712.43	20.7411
1715.47	18.807
1718.51	16.9657
1721.55	13.8594
1724.58	12.2067
1727.62	10.4434
1730.65	8.85372
1733.68	7.76281
1736.72	5.87751
1739.74	5.45283
1742.77	3.43179
1745.8	2.89953
1748.83	2.84226
1751.85	2.37154
1754.88	2.59073
1757.9	3.34022
1760.92	4.57139
1763.95	5.8756
1766.96	5.48183
1769.98	4.99672
1773	4.0542
1776.02	4.98568
1779.03	4.78806
1782.05	4.08357
1785.06	3.70198
1788.07	3.91848
1791.08	3.91965
1794.09	3.8333
1797.1	3.48459
1800.11	2.93678
1803.12	2.98554
1806.12	2.92932
1809.12	2.66859
1812.13	1.98243
1815.13	1.91108
1818.13	2.21644
1821.13	3.14676
1824.13	2.95993
1827.13	4.16687
1830.12	4.47177
1833.12	3.78908
1836.11	3.42371
1839.1	3.3325
1842.09	3.69073
1845.09	3.56837
1848.08	2.96732
1851.06	2.503
1854.05	1.68293
1857.04	2.59337
1860.02	3.86044
1863.01	3.08567
1865.99	2.02977
1868.97	1.69691
1871.95	1.60715
1874.93	2.07107
1877.91	3.02653
1880.89	2.87714
1882.46	3.35587
1885.45	3.5228
1888.43	5.07712
1891.42	5.56123
1894.41	5.90226
1897.39	6.9484
1900.37	7.45793
1903.36	8.43001
1906.34	8.01005
1909.32	8.46683
1912.29	9.1619
1915.27	8.63204
1918.25	8.55836
1921.23	7.47145
1924.2	8.13397
1927.17	8.88064
1930.15	9.57701
1933.12	8.71158
1936.09	9.11113
1939.06	9.10188
1942.02	9.44009
1944.99	9.25714
1947.96	9.08357
1950.92	7.76687
1953.88	7.29735
1956.85	7.58154
1959.81	7.29578
1962.77	6.74756
1965.73	5.08117
1968.69	5.51103
1971.64	5.19218
1974.6	4.49195
1977.55	4.06976
1980.51	3.8123
1983.46	3.3457
1986.41	4.73323
1989.36	3.91396
1992.31	4.67181
1995.26	4.5715
1998.21	4.00953
2001.15	4.54539
2004.1	5.32662
2007.04	5.97663
2009.99	6.14995
2012.93	5.48076
2015.87	6.08128
2018.81	5.50279
2021.75	5.66312
2024.68	6.52438
2027.62	8.21027
2030.56	9.27362
2033.49	9.8245
2036.42	9.67868
2039.36	10.5976
2042.29	10.608
2045.22	11.7997
2048.14	11.453
2051.07	11.9656
2054	11.9879
2056.93	11.8007
2059.85	12.0057
2062.77	12.1303
2065.7	11.9902
2068.62	12.6748
2071.54	12.4353
2074.46	12.4584
2077.38	12.2745
2080.29	10.9612
2083.21	11.0292
2086.12	11.046
2089.04	11.784
2091.95	11.4984
2094.86	11.7963
2097.77	12.3597
2100.68	13.6998
2103.59	14.2747
2106.5	14.9276
2109.41	15.8733
2112.31	17.2382
2115.21	18.5382
2118.12	19.5687
2121.02	21.7986
2123.92	23.9648
2126.82	26.0359
2129.72	29.0648
2132.62	32.1039
2135.51	33.76
2138.41	35.7611
2141.31	38.2323
2144.2	38.6262
2147.09	39.7988
2149.98	41.7888
2152.87	42.8572
2155.76	44.0476
2158.65	45.0252
2161.54	46.6185
2164.43	47.7475
2167.31	48.8485
2170.2	51.2148
2173.08	52.4996
2175.96	52.4973
2178.84	53.5664
2181.72	53.1086
2184.6	52.0751
2187.48	51.4182
2190.36	49.9083
2193.23	47.8238
2196.11	46.6352
2198.98	44.4274
2201.85	41.4538
2204.72	39.0345
2207.59	36.6112
2210.46	34.3917
2213.33	31.6847
2216.2	27.8993
2219.07	25.9578
2221.93	23.4144
2224.8	22.3268
2227.66	21.6092
2230.52	20.6359
2233.39	19.755
2236.25	19.3106
2239.1	19.6164
2241.96	18.9156
2244.82	18.9718
2247.68	19.4188
2250.53	18.2819
2253.38	17.5867
2256.24	17.145
2259.09	16.2781
2261.94	16.7623
2264.79	16.4166
2267.64	16.104
2270.49	15.8104
2273.33	16.045
2276.18	16.0109
2279.02	15.3119
2281.87	15.7793
2284.71	14.9489
2287.55	14.8757
2290.39	15.4985
2293.23	14.3156
2296.07	14.7895
2298.91	14.4912
2301.74	14.896
2304.58	16.7373
2307.41	16.6452
2310.25	17.1215
2313.08	16.1626
2315.91	14.8957
2318.74	13.4046
2321.57	11.9829
2324.4	10.7639
2327.23	9.97095
2330.05	9.36969
2332.88	8.2341
2335.7	7.0894
2338.52	6.1129
2341.35	5.50084
2344.17	3.05212
2346.99	2.45423
2349.81	1.9805
2352.62	1.81332
2355.44	0.785176
2358.26	0.723342
2361.07	0.526538
2363.89	0.747135
2366.7	2.32123
2369.51	3.19571
2372.32	3.26366
2375.13	3.81683
2377.94	3.78446
2380.75	4.74613
2383.56	5.05581
2386.36	5.27413
2389.17	6.02922
2391.97	6.06148
2394.77	6.1963
2397.58	6.65634
2400.38	5.86056
2403.18	5.06778
2405.97	4.97828
2408.77	5.01634
2411.57	4.25219
2414.37	4.86325
2417.16	4.3348
2419.95	4.76089
2422.75	4.94722
2425.54	4.00068
2428.33	4.8092
2431.12	4.74525
2433.91	4.35644
2436.7	4.65365
2439.48	4.99623
2442.27	5.32282
2445.05	6.56958
2447.84	7.76183
2450.62	7.89138
2453.4	7.79521
2456.18	7.31707
2458.96	6.34959
2461.74	5.62203
2464.52	5.49128
2467.29	5.89141
2470.07	4.78195
2472.85	5.29382
2475.62	5.18665
2478.39	4.57642
2481.16	3.83564
2483.93	4.01366
2486.7	4.26746
2489.47	4.26025
2492.24	3.54039
2495.01	3.02629
2497.77	4.25919
2500.54	3.50988
2503.3	3.70696
2506.06	3.2829
2508.83	2.84745
2511.59	2.98188
2514.35	1.67513
2517.11	0.512126
2519.86	0.349929
2522.62	0.0749639
2525.38	-0.486304
2528.13	0.117633
2530.89	1.02683
2533.64	1.25713
2536.39	2.25391
2539.14	1.63164
2541.89	2.39795
2544.64	2.65746
2547.39	2.97625
2550.14	4.13514
2552.88	5.24229
2555.63	5.45317
2558.37	5.5337
2561.11	6.77552
2563.86	7.37506
2566.6	7.80702
2569.34	8.32634
2572.08	9.51142
2574.82	9.07908
2577.55	9.67618
2580.29	9.51797
2583.02	9.81336
2585.76	11.0238
2588.49	10.812
2591.22	10.667
2593.96	10.6357
2596.69	10.8203
2599.42	9.18943
2602.14	7.89059
2604.87	8.58035
2607.6	9.0252
2610.32	8.90901
2613.05	7.75948
2615.77	7.31539
2618.49	7.43184
2621.22	5.92941
2623.94	6.03877
2626.66	6.62308
2629.37	6.3727
2632.09	6.4684
2634.81	6.09008
2637.53	5.16714
2640.24	5.40515
2642.96	5.09725
2645.67	5.92493
2648.38	6.55975
2651.09	6.60875
2653.8	6.01562
2656.51	5.33875
2659.22	4.80965
2661.93	4.88045
2664.63	4.27902
2667.34	4.7698
2670.04	4.72843
2672.75	5.66874
2675.45	4.81065
2678.15	3.71308
2680.85	4.16485
2683.55	4.43233
2686.25	3.83538
2688.94	4.08495
2691.64	4.96301
2694.34	4.57372
2697.03	4.05159
2699.73	4.7059
2702.42	4.94893
2705.11	6.62434
2707.8	8.00873
2710.49	9.26664
2713.18	11.3729
2715.87	11.5834
2718.55	11.9078
2721.24	12.7894
2723.93	13.8604
2726.61	14.5352
2729.29	14.1642
2731.98	15.1253
2734.66	13.8145
2737.34	13.2461
2740.02	12.3608
2742.7	11.3071
2745.37	10.5984
2748.05	9.69086
2750.72	8.7754
2753.4	7.52239
2756.07	7.0135
2758.75	6.07351
2761.42	5.45243
2764.09	5.33897
2766.76	3.86632
2769.43	3.57153
2772.1	3.21557
2774.76	2.47941
2777.43	3.08761
2780.1	2.71184
2782.76	1.85668
2785.42	1.47519
2788.09	1.2461
2790.75	1.20732
2793.41	0.39264
2796.07	0.0553232
2798.73	-0.920777
2801.39	-1.29009
2804.04	-1.54003
2806.7	-1.63202
2809.35	-1.9069
2812.01	-1.6354
2814.66	-1.69718
2817.31	0.0977994
2819.96	1.00173
2822.61	3.60745
2825.26	6.98109
2827.91	10.0686
2830.56	13.2524
2833.21	18.3717
2835.85	23.2005
2838.5	28.7762
2841.14	35.564
2843.78	43.4591
2846.42	51.1153
2849.06	58.7822
2851.71	68.2265
2854.34	76.8139
2856.98	84.9923
2859.62	93.2652
2862.26	102.15
2864.89	110.014
2867.53	116.993
2870.16	122.569
2872.79	127.497
2875.42	131.807
2878.05	136.261
2880.68	139.684
2883.31	143.432
2885.94	147.333
2888.57	151.109
2891.19	155.074
2893.82	159.521
2896.44	164.563
2899.07	170.706
2901.69	177.662
2904.31	186.937
2906.93	198.482
2909.55	209.271
2912.17	220.096
2914.79	231.154
2917.41	241.416
2920.02	250.161
2922.64	257.393
2925.25	263.143
2927.86	266.739
2930.48	267.639
2933.09	266.612
2935.7	262.835
2938.31	258.818
2940.92	252.376
2943.53	244.204
2946.13	235.505
2948.74	226.163
2951.34	216.095
2953.95	206.455
2956.55	196.336
2959.15	186.638
2961.75	177.982
2964.35	170.257
2966.95	162.878
2969.55	156.071
2972.15	149.217
2974.75	141.235
2977.34	133.38
2979.94	124.708
2982.53	115.499
2985.13	106.231
2987.72	97.5022
2990.31	87.3876
2992.9	78.7708
2995.49	69.3551
2998.08	60.9329
3000.67	52.5249
3003.25	45.3223
3005.84	37.5363
3008.42	31.4056
3011.01	25.8913
3013.59	21.5158
3016.17	18.2364
3018.76	14.3808
3021.34	12.3701
3023.92	11.582
3026.49	10.1786
3029.07	8.88688
3031.65	8.37363
3034.23	9.11745
3036.8	9.42175
3039.38	10.1572
3041.95	11.488
3044.52	12.1766
3047.09	14.475
3049.66	15.509
3052.23	16.4633
3054.8	17.0399
3057.37	17.6412
3059.94	17.777
3062.5	16.6972
3065.07	16.0178
3067.63	15.6776
3070.2	14.7957
3072.76	13.9227
3075.32	12.0475
3077.88	9.70814
3080.44	7.73921
3083	6.38737
3085.56	5.14648
3088.12	3.91403
3090.67	2.72444
3093.23	1.7878
3095.78	1.74991
3098.34	1.68555
3100.89	1.25511
3103.44	0.747895
3105.99	1.60075
3108.54	2.83503
3111.09	3.32654
3113.64	3.11706
3116.19	3.9534
3118.74	4.29959
3121.28	4.88889
3123.83	6.07652
3126.37	7.03935
3128.91	8.73218
3131.46	9.69205
3134	9.52862
3136.54	10.2292
3139.08	11.2252
3141.62	12.7843
3144.16	14.6865
3146.69	16.3598
3149.23	18.379