File: data/Raman/poly_smoothed/Thy_20_09_21_1x_45s_532 nm_x100_100%_600 gr_mm_01.txt
#Acq. time (s)=	45
#Accumulations=	2
#Range (cm-¹)=	200...3150
#Windows=	2
#Auto scanning=	Off
#Autofocus=	Off
#Macrospot=	Off
#AutoExposure=	Off
#Spike filter=	Multiple accum.
#Delay time (s)=	0
#Binning=	1
#Readout mode=	Signal
#DeNoise=	Off
#ICS correction=	On
#Dark correction=	Off
#Inst. Process=	Off
#Detector Gain=	Best Dynamic Range
#Detector ADC=	20 kHz
#Detector temperature (°C)=	-69.85
#Instrument=	LabRAM HR Evol
#Detector=	Synapse
#Objective=	x100
#Grating=	600 gr/mm
#ND Filter=	100%
#Laser (nm)=	532
#Hole=	100.021
#Range=	Auto
#Laser Pol.=	No
#Raman. Pol.=	No
#Laser Pol. (°)=	-0.0007625
#Raman Pol. (°)=	89.9995
#Collection=	Microscope
#StageXY=	Marzhauser
#StageZ=	Marzhauser
#X (µm)=	-5902.7
#Y (µm)=	2884.9
#Z (µm)=	-223.55
#Full time(mm:ss)=	3:19
#Project=
#Sample=
#Site=
#Title=	Thy_20_09_21_2x_45s_532 nm_x100_100%_600 gr_mm
#Remark=
#Date=	29.06.2022 12:09
#Acquired=	29.06.2022 12:09:17
#Base:Fit=	10.08.2022 09:52:02
#Base:Fit=	10.08.2022 09:52:12
#Base:Sub=	10.08.2022 09:54:21
#Filter:Polynom=	16.08.2022 10:24:04
#AxisType[0]=Intens
#AxisUnit[0]=Cnt
#AxisType[1]=Spectr
#AxisUnit[1]=1/cm
200.523	-0.356273
204.154	4.13696
207.781	6.81079
211.409	6.8871
215.034	7.54856
218.659	7.56903
222.281	7.73411
225.903	6.81909
229.522	6.49459
233.14	5.66967
236.756	6.10378
240.373	7.45454
243.986	7.72069
247.598	7.22755
251.208	5.29737
254.818	5.47604
258.427	6.36129
262.034	5.78412
265.638	6.1721
269.242	5.51251
272.844	5.08057
276.445	5.6068
280.044	6.00776
283.642	6.47931
287.238	6.61794
290.833	7.76875
294.425	7.68512
298.017	8.8433
301.608	9.62549
305.198	11.0273
308.786	12.7411
312.371	13.6529
315.956	14.7662
319.54	16.2946
323.122	16.9843
326.701	18.6698
330.281	17.5335
333.857	17.8652
337.434	16.7272
341.008	15.3499
344.582	14.1589
348.153	12.332
351.724	9.32757
355.292	8.62864
358.861	6.59221
362.426	4.77436
365.99	3.36984
369.555	1.64104
373.116	1.19799
376.676	0.703606
380.236	0.635004
383.793	1.92722
387.349	4.05082
390.903	4.69476
394.456	5.44418
398.007	6.70867
401.56	7.59607
405.108	8.36485
408.656	8.93012
412.202	8.79397
415.746	11.2075
419.29	12.3023
422.831	13.5945
426.37	12.7779
429.909	12.7306
433.447	12.4937
436.983	12.1847
440.519	12.9263
444.052	12.9621
447.583	12.6022
451.114	11.2667
454.643	11.9394
458.169	11.0788
461.696	12.7764
465.222	14.1771
468.744	15.7234
472.267	16.5168
475.787	17.2795
479.307	16.7594
482.823	17.4845
486.341	18.9371
489.855	20.0537
493.37	20.9012
496.881	20.7346
500.391	22.2146
503.902	22.6636
507.409	21.9127
510.915	20.3148
514.42	20.0065
517.925	19.4432
521.427	18.3404
524.928	18.298
528.427	19.0875
531.925	18.3098
535.422	17.8777
538.917	15.9873
542.411	14.8266
545.903	14.4839
549.395	14.2513
552.884	13.9792
556.373	13.6552
559.86	12.9239
563.346	11.0631
566.831	9.82246
570.314	8.9592
573.794	7.74891
577.274	7.30243
580.754	6.89845
584.23	7.18432
587.706	6.40629
591.181	5.09756
594.653	5.25918
598.126	6.64824
601.595	8.26847
605.065	8.69461
608.532	10.6514
611.999	12.9394
615.463	14.7059
618.928	14.316
622.389	14.3423
625.851	15.1468
629.31	15.9825
632.767	15.3098
636.223	16.2919
639.68	16.8208
643.134	16.0763
646.586	14.6515
650.037	13.5549
653.486	13.0076
656.936	12.4472
660.383	14.0432
663.829	14.4916
667.273	14.6245
670.716	14.0504
674.158	16.102
677.598	18.0894
681.035	20.7327
684.473	23.9497
687.909	25.8725
691.344	28.8361
694.778	32.1222
698.211	32.9478
701.64	34.6354
705.07	36.5808
708.498	39.2132
711.924	40.5083
715.35	41.2215
718.774	43.2515
722.196	43.62
725.618	44.7465
729.037	45.1064
732.456	46.4473
735.873	46.932
739.289	45.5731
742.703	47.3857
746.116	48.3342
749.529	49.4334
752.938	51.6882
756.347	53.7704
759.756	57.1444
763.162	59.6551
766.567	61.6196
769.97	64.5029
773.372	66.6088
776.773	67.7643
780.174	70.7588
783.573	71.3194
786.97	73.384
790.365	74.6364
793.76	74.8893
797.153	76.6556
800.543	77.8578
803.933	80.4728
807.322	82.3214
810.71	85.0579
814.097	86.7251
817.483	88.2053
820.865	88.3196
824.248	88.8983
827.629	89.9518
831.008	90.209
834.387	88.5966
837.765	88.5893
841.139	87.1575
844.514	85.278
847.886	81.0623
851.259	76.6673
854.629	73.5245
857.997	70.1228
861.366	66.4067
864.732	61.8462
868.098	58.8206
871.461	55.468
874.823	53.4428
878.184	51.3368
881.545	49.8725
884.903	49.9041
888.26	48.4029
891.616	47.7085
894.97	48.3425
898.323	48.2028
901.675	47.3027
905.026	46.7408
908.375	47.2129
911.723	45.5655
915.07	45.539
918.415	45.0665
921.76	45.1485
925.103	42.5615
928.443	42.1789
931.783	40.9636
935.123	41.4017
938.461	42.058
941.796	39.9555
945.131	39.7586
948.465	39.6264
951.797	39.9855
955.128	40.581
958.457	40.0758
961.786	39.3589
965.113	40.1004
968.44	39.7112
971.763	40.611
975.086	41.7627
978.409	42.5577
981.729	42.3509
985.048	42.0744
988.367	41.4171
991.683	40.3098
994.998	39.3955
998.312	38.4016
1001.62	37.0301
1004.94	36.1063
1008.25	34.3582
1011.56	32.492
1014.86	31.5797
1018.17	30.1793
1021.48	26.5451
1024.78	25.7381
1028.08	26.0325
1031.38	25.8666
1034.68	25.9805
1037.98	24.7896
1041.28	24.4792
1044.57	26.4182
1047.87	28.3899
1051.16	29.932
1054.45	31.3842
1057.75	31.0089
1061.04	30.3303
1064.32	29.6488
1067.61	29.0715
1070.9	29.4431
1074.18	30.039
1077.47	31.127
1080.75	30.0775
1084.03	29.3147
1087.31	28.913
1090.59	28.6018
1093.86	27.0327
1097.14	26.5584
1100.41	25.3589
1103.69	23.5593
1106.96	23.1584
1110.23	20.8634
1113.5	20.921
1116.77	19.5098
1120.03	18.8636
1123.3	18.9976
1126.56	17.2752
1129.83	16.0839
1133.09	13.3974
1136.35	11.7198
1139.61	9.15109
1142.86	8.51109
1146.12	8.30597
1149.38	7.54226
1152.63	6.95987
1155.88	6.41425
1159.14	5.24573
1162.39	3.85357
1165.63	3.14906
1168.88	3.66056
1172.13	3.98834
1175.38	5.44341
1178.62	6.00331
1181.86	6.81724
1185.1	7.32924
1188.34	9.47058
1191.58	11.8835
1194.82	13.7293
1198.06	14.2512
1201.29	16.0057
1204.53	17.2445
1207.76	19.4545
1210.99	21.7247
1214.22	23.4476
1217.45	25.6028
1220.68	28.3489
1223.91	29.8939
1227.13	32.1886
1230.36	34.2246
1233.58	34.9023
1236.8	37.0005
1240.02	38.8996
1243.24	40.1643
1246.46	42.8543
1249.67	44.3183
1252.89	46.3404
1256.1	48.5662
1259.32	50.7966
1262.53	50.8477
1265.74	52.0452
1268.95	53.6588
1272.15	54.3863
1275.36	55.8014
1278.57	58.3975
1281.77	59.4064
1284.97	60.9655
1288.18	61.3804
1291.38	61.7384
1294.58	61.3988
1297.78	62.7305
1300.97	64.0126
1304.17	64.6452
1307.36	65.8791
1310.55	67.6645
1313.75	68.6277
1316.94	69.8315
1320.13	70.1703
1323.32	71.4184
1326.5	70.8367
1329.69	71.08
1332.87	73.1058
1336.06	71.9488
1339.24	69.9815
1342.42	69.9357
1345.6	67.6872
1348.78	64.433
1351.96	62.3565
1355.13	61.3861
1358.31	58.2949
1361.48	55.3561
1364.65	51.7327
1367.82	47.7604
1370.99	46.3833
1374.16	42.4468
1377.33	40.5004
1380.5	39.7346
1383.66	37.1607
1386.83	36.7436
1389.99	35.3371
1393.15	35.0845
1396.31	35.1008
1399.47	34.9753
1402.63	34.1099
1405.78	34.346
1408.94	36.6527
1412.1	38.1857
1415.25	40.8757
1418.4	43.5275
1421.55	47.085
1424.7	49.4192
1427.85	55.2649
1431	61.7067
1434.14	66.4162
1437.29	71.3236
1440.43	74.7717
1443.57	76.056
1446.71	78.4121
1449.85	77.4742
1452.99	75.8248
1456.13	73.4741
1459.26	70.783
1462.4	66.767
1465.54	62.0678
1468.67	55.4426
1471.8	48.477
1474.93	40.7281
1478.06	33.9806
1481.19	27.5444
1484.31	22.1121
1487.44	18.6832
1490.56	15.7916
1493.69	12.6394
1496.81	11.1828
1499.93	9.79614
1503.05	10.5663
1506.17	11.8421
1509.28	12.8889
1512.4	13.7287
1515.52	15.3586
1518.63	16.2319
1521.74	17.9854
1524.85	19.4656
1527.96	21.727
1531.07	23.1931
1534.18	25.5086
1537.29	27.952
1540.39	29.9576
1543.5	31.1121
1546.6	32.086
1549.7	34.4004
1552.8	37.3383
1555.9	37.839
1559	38.8877
1562.1	41.2028
1565.19	43.8012
1568.29	45.2695
1571.38	46.5995
1574.47	47.0584
1577.56	48.6228
1580.66	50.418
1583.74	51.2166
1586.83	52.1471
1589.92	52.5908
1593.01	52.8147
1596.09	54.0593
1599.17	53.9021
1602.25	52.7357
1605.34	51.5582
1608.41	52.9798
1611.49	54.7858
1614.57	54.7928
1617.65	55.0267
1620.72	55.5917
1623.79	57.707
1626.87	58.6424
1629.94	58.6916
1633.01	59.3922
1636.08	62.3752
1639.15	64.3388
1642.21	65.9014
1645.28	68.1397
1648.34	68.5707
1651.41	70.4762
1654.47	71.9033
1657.53	71.8395
1660.59	70.1012
1663.65	69.2824
1666.71	67.2646
1669.76	63.3392
1672.82	59.2467
1675.87	54.7662
1678.93	50.1833
1681.98	45.6274
1685.03	41.9082
1688.08	37.4196
1691.13	32.0015
1694.17	28.2026
1697.22	24.9073
1700.27	20.0268
1703.31	16.2889
1706.35	15.0143
1709.39	13.7963
1712.43	12.1168
1715.47	11.2266
1718.51	10.8675
1721.55	9.67526
1724.58	9.04868
1727.62	8.11283
1730.65	6.77318
1733.68	6.57656
1736.72	6.68003
1739.74	5.80215
1742.77	4.96768
1745.8	5.50103
1748.83	5.46095
1751.85	3.81468
1754.88	2.74462
1757.9	3.38589
1760.92	3.87196
1763.95	3.83059
1766.96	3.03584
1769.98	3.28078
1773	3.50151
1776.02	3.32123
1779.03	3.97994
1782.05	4.9174
1785.06	4.51985
1788.07	4.05613
1791.08	4.73118
1794.09	3.30389
1797.1	2.93554
1800.11	3.23252
1803.12	2.78859
1806.12	3.14139
1809.12	3.58995
1812.13	3.07767
1815.13	3.20427
1818.13	3.97841
1821.13	3.32748
1824.13	2.80477
1827.13	2.56182
1830.12	2.60803
1833.12	2.25391
1836.11	2.38112
1839.1	3.04849
1842.09	2.13589
1845.09	1.72352
1848.08	1.41285
1851.06	1.03978
1854.05	1.62014
1857.04	1.5964
1860.02	1.77102
1863.01	1.77965
1865.99	2.48717
1868.97	1.13528
1871.95	1.48006
1874.93	1.58271
1877.91	1.75474
1880.89	2.20167
1882.46	2.67002
1885.45	3.07275
1888.43	3.97887
1891.42	4.13048
1894.41	4.00078
1897.39	5.45614
1900.37	5.31119
1903.36	4.30145
1906.34	4.43987
1909.32	3.62312
1912.29	3.08537
1915.27	2.4139
1918.25	2.51667
1921.23	2.13552
1924.2	1.95783
1927.17	2.32473
1930.15	1.38268
1933.12	0.88369
1936.09	1.04551
1939.06	0.815551
1942.02	0.897268
1944.99	1.65675
1947.96	1.92861
1950.92	3.07395
1953.88	3.28242
1956.85	3.66903
1959.81	4.70268
1962.77	5.10192
1965.73	4.78833
1968.69	5.42685
1971.64	6.07313
1974.6	5.23019
1977.55	4.90572
1980.51	4.33892
1983.46	4.14897
1986.41	4.10847
1989.36	4.49101
1992.31	4.89862
1995.26	5.1951
1998.21	5.87082
2001.15	5.8886
2004.1	5.88963
2007.04	6.22521
2009.99	5.29835
2012.93	5.39492
2015.87	6.14317
2018.81	5.8367
2021.75	5.77256
2024.68	5.25791
2027.62	5.82278
2030.56	5.20901
2033.49	4.30586
2036.42	3.70424
2039.36	4.26035
2042.29	4.22919
2045.22	4.63547
2048.14	3.23981
2051.07	2.74187
2054	3.28047
2056.93	2.9834
2059.85	3.84915
2062.77	3.90908
2065.7	4.00805
2068.62	5.50521
2071.54	6.34264
2074.46	7.57934
2077.38	7.69672
2080.29	7.93441
2083.21	8.28205
2086.12	9.27448
2089.04	9.37818
2091.95	10.1239
2094.86	10.7462
2097.77	10.2679
2100.68	10.6108
2103.59	11.9387
2106.5	12.3782
2109.41	14.0718
2112.31	14.8962
2115.21	16.3255
2118.12	17.6621
2121.02	19.2173
2123.92	20.9573
2126.82	22.5546
2129.72	24.2723
2132.62	27.1939
2135.51	28.7148
2138.41	31.8229
2141.31	33.2649
2144.2	35.6823
2147.09	38.0132
2149.98	38.4722
2152.87	40.349
2155.76	41.7227
2158.65	42.5917
2161.54	43.3654
2164.43	43.8385
2167.31	44.6746
2170.2	45.7003
2173.08	44.8038
2175.96	44.305
2178.84	43.9594
2181.72	43.8212
2184.6	43.511
2187.48	42.0647
2190.36	40.8158
2193.23	38.6694
2196.11	37.204
2198.98	34.5365
2201.85	32.1811
2204.72	30.4914
2207.59	28.4225
2210.46	25.4896
2213.33	22.9859
2216.2	21.1245
2219.07	18.1897
2221.93	16.708
2224.8	15.7576
2227.66	13.7841
2230.52	12.9527
2233.39	12.97
2236.25	12.3059
2239.1	11.9123
2241.96	10.175
2244.82	9.83238
2247.68	10.1779
2250.53	10.641
2253.38	10.345
2256.24	11.3684
2259.09	10.9645
2261.94	11.5658
2264.79	11.4321
2267.64	11.9955
2270.49	11.5893
2273.33	11.0721
2276.18	10.2394
2279.02	9.05823
2281.87	8.53424
2284.71	8.32786
2287.55	7.31873
2290.39	6.1909
2293.23	5.2017
2296.07	4.38467
2298.91	3.58502
2301.74	4.17446
2304.58	3.994
2307.41	3.17082
2310.25	2.80441
2313.08	3.25787
2315.91	3.67098
2318.74	3.38438
2321.57	3.52707
2324.4	4.49409
2327.23	4.56813
2330.05	4.14818
2332.88	4.58533
2335.7	4.25345
2338.52	3.68284
2341.35	2.54118
2344.17	2.3754
2346.99	2.11822
2349.81	1.57
2352.62	0.738426
2355.44	0.445366
2358.26	-0.471965
2361.07	-0.32476
2363.89	0.550569
2366.7	1.74931
2369.51	2.52049
2372.32	2.0795
2375.13	1.78026
2377.94	1.51942
2380.75	2.40262
2383.56	3.2636
2386.36	3.37416
2389.17	2.98874
2391.97	3.05056
2394.77	3.21559
2397.58	3.28232
2400.38	3.64328
2403.18	3.31324
2405.97	2.85913
2408.77	2.94225
2411.57	3.40039
2414.37	4.26769
2417.16	3.62984
2419.95	3.40765
2422.75	4.2398
2425.54	6.09869
2428.33	6.91342
2431.12	7.28613
2433.91	6.91333
2436.7	6.37243
2439.48	5.63565
2442.27	4.5136
2445.05	4.99582
2447.84	4.241
2450.62	4.11431
2453.4	3.24168
2456.18	2.98108
2458.96	2.21796
2461.74	2.52471
2464.52	1.13936
2467.29	0.709703
2470.07	0.66293
2472.85	0.141541
2475.62	0.869466
2478.39	0.741406
2481.16	1.41878
2483.93	2.00465
2486.7	2.56553
2489.47	3.50902
2492.24	4.53507
2495.01	4.94499
2497.77	4.33603
2500.54	4.64651
2503.3	5.09307
2506.06	5.34745
2508.83	5.28483
2511.59	6.31467
2514.35	7.15717
2517.11	7.49289
2519.86	7.79994
2522.62	7.40051
2525.38	7.31744
2528.13	7.45063
2530.89	6.70911
2533.64	6.28563
2536.39	6.82118
2539.14	6.87658
2541.89	6.10432
2544.64	6.29997
2547.39	6.78817
2550.14	6.42477
2552.88	6.2442
2555.63	6.28474
2558.37	6.04501
2561.11	6.5436
2563.86	6.17815
2566.6	6.15064
2569.34	6.2498
2572.08	5.9605
2574.82	6.53275
2577.55	6.72938
2580.29	7.01499
2583.02	6.07941
2585.76	6.13058
2588.49	4.64949
2591.22	3.79079
2593.96	3.73183
2596.69	4.00069
2599.42	2.85168
2602.14	2.38374
2604.87	2.41965
2607.6	1.55448
2610.32	2.38088
2613.05	2.50929
2615.77	2.53511
2618.49	2.57758
2621.22	2.67303
2623.94	2.47672
2626.66	3.32846
2629.37	3.50213
2632.09	3.20356
2634.81	3.33256
2637.53	3.93927
2640.24	4.65021
2642.96	5.07603
2645.67	5.20889
2648.38	5.36168
2651.09	5.6048
2653.8	5.51076
2656.51	5.76152
2659.22	5.8698
2661.93	6.56595
2664.63	6.72744
2667.34	7.60455
2670.04	7.63796
2672.75	7.85702
2675.45	6.94471
2678.15	6.58506
2680.85	6.35512
2683.55	6.24188
2686.25	5.75841
2688.94	5.11726
2691.64	4.90956
2694.34	4.57944
2697.03	4.66688
2699.73	5.02885
2702.42	5.27223
2705.11	5.35735
2707.8	5.71878
2710.49	6.48934
2713.18	6.51584
2715.87	7.93545
2718.55	8.83934
2721.24	9.51359
2723.93	9.90207
2726.61	9.84948
2729.29	9.96173
2731.98	9.50212
2734.66	8.79122
2737.34	7.33816
2740.02	7.16708
2742.7	6.95208
2745.37	6.54562
2748.05	5.59589
2750.72	5.26302
2753.4	3.97195
2756.07	3.32131
2758.75	3.27803
2761.42	2.91388
2764.09	2.83839
2766.76	2.77215
2769.43	3.08167
2772.1	2.95294
2774.76	3.26351
2777.43	2.67664
2780.1	2.66645
2782.76	3.0128
2785.42	2.41757
2788.09	2.06175
2790.75	1.30738
2793.41	-0.0333114
2796.07	-0.668042
2798.73	-0.914124
2801.39	-0.827772
2804.04	-0.809301
2806.7	-0.607065
2809.35	-1.23746
2812.01	-1.89359
2814.66	-1.03012
2817.31	-0.155139
2819.96	0.681507
2822.61	4.04442
2825.26	6.66524
2827.91	10.5001
2830.56	13.8051
2833.21	17.6423
2835.85	21.1136
2838.5	26.5271
2841.14	32.2293
2843.78	38.6077
2846.42	45.8542
2849.06	52.9943
2851.71	60.6072
2854.34	67.5024
2856.98	75.6659
2859.62	83.5456
2862.26	91.1571
2864.89	98.2958
2867.53	103.604
2870.16	109.016
2872.79	113.241
2875.42	117.316
2878.05	121.729
2880.68	125.017
2883.31	128.562
2885.94	132.521
2888.57	135.817
2891.19	139.082
2893.82	142.525
2896.44	145.992
2899.07	149.713
2901.69	156.072
2904.31	162.505
2906.93	169.701
2909.55	177.411
2912.17	185.381
2914.79	193.692
2917.41	201.065
2920.02	207.461
2922.64	212.67
2925.25	216
2927.86	217.364
2930.48	217.853
2933.09	216.395
2935.7	213.195
2938.31	208.356
2940.92	202.887
2943.53	196.296
2946.13	188.589
2948.74	181.269
2951.34	172.415
2953.95	164.151
2956.55	154.909
2959.15	146.61
2961.75	138.31
2964.35	130.562
2966.95	123.978
2969.55	116.623
2972.15	110.734
2974.75	104.277
2977.34	98.3531
2979.94	90.9025
2982.53	84.0887
2985.13	77.6037
2987.72	69.6137
2990.31	63.5895
2992.9	56.4043
2995.49	49.5998
2998.08	42.8967
3000.67	36.4933
3003.25	30.1389
3005.84	25.3963
3008.42	20.5349
3011.01	16.4149
3013.59	13.1751
3016.17	10.5834
3018.76	8.52662
3021.34	6.56029
3023.92	4.99404
3026.49	4.30251
3029.07	4.15179
3031.65	4.18827
3034.23	4.81819
3036.8	5.25467
3039.38	6.07424
3041.95	6.81104
3044.52	7.57202
3047.09	8.4618
3049.66	9.67159
3052.23	10.5757
3054.8	11.5477
3057.37	11.6609
3059.94	11.5361
3062.5	11.6379
3065.07	11.1083
3067.63	10.5419
3070.2	9.75802
3072.76	8.95567
3075.32	7.6738
3077.88	7.68399
3080.44	5.66675
3083	4.51586
3085.56	3.32636
3088.12	2.7678
3090.67	2.40038
3093.23	1.43307
3095.78	0.600151
3098.34	0.297736
3100.89	0.587835
3103.44	0.749727
3105.99	1.26567
3108.54	2.70419
3111.09	4.78221
3113.64	6.36694
3116.19	8.40994
3118.74	9.92817
3121.28	11.4515
3123.83	13.9214
3126.37	16.2062
3128.91	17.7031
3131.46	18.9485
3134	21.4049
3136.54	22.5827
3139.08	24.4639
3141.62	25.4343
3144.16	25.9354
3146.69	25.8113
3149.23	25.9953