File: data/Raman/poly_smoothed/Thy_30_10_01_1x_45s_532 nm_x100_100%_600 gr_mm_01.txt
#Acq. time (s)=	45
#Accumulations=	2
#Range (cm-¹)=	200...3150
#Windows=	2
#Auto scanning=	Off
#Autofocus=	Off
#Macrospot=	Off
#AutoExposure=	Off
#Spike filter=	Multiple accum.
#Delay time (s)=	0
#Binning=	1
#Readout mode=	Signal
#DeNoise=	Off
#ICS correction=	On
#Dark correction=	Off
#Inst. Process=	Off
#Detector Gain=	Best Dynamic Range
#Detector ADC=	20 kHz
#Detector temperature (°C)=	-69.85
#Instrument=	LabRAM HR Evol
#Detector=	Synapse
#Objective=	x100
#Grating=	600 gr/mm
#ND Filter=	100%
#Laser (nm)=	532
#Hole=	100.021
#Range=	Auto
#Laser Pol.=	No
#Raman. Pol.=	No
#Laser Pol. (°)=	-0.0007625
#Raman Pol. (°)=	89.9995
#Collection=	Microscope
#StageXY=	Marzhauser
#StageZ=	Marzhauser
#X (µm)=	4773.7
#Y (µm)=	-7738.7
#Z (µm)=	584
#Full time(mm:ss)=	3:10
#Project=
#Sample=
#Site=
#Title=	Thy_30_10_01_2x_45s_532 nm_x100_100%_600 gr_mm
#Remark=
#Date=	30.06.2022 11:28
#Acquired=	30.06.2022 11:28:01
#Base:Fit=	10.08.2022 09:56:48
#Base:Fit=	10.08.2022 09:57:06
#Base:Fit=	10.08.2022 09:57:43
#Base:Fit=	10.08.2022 09:57:50
#Base:Fit=	10.08.2022 09:58:11
#Base:Sub=	10.08.2022 09:58:44
#Filter:Polynom=	16.08.2022 10:22:53
#AxisType[0]=Intens
#AxisUnit[0]=Cnt
#AxisType[1]=Spectr
#AxisUnit[1]=1/cm
200.533	62.5083
204.162	58.6217
207.792	54.8205
211.418	51.7554
215.044	49.7608
218.667	47.3861
222.289	44.4199
225.912	40.6006
229.531	38.6103
233.148	37.0006
236.766	36.2525
240.381	35.8345
243.994	33.4488
247.606	30.9214
251.217	29.8122
254.828	27.253
258.436	25.1646
262.042	25.717
265.647	25.3373
269.25	23.9653
272.852	23.1651
276.453	22.1413
280.052	21.5013
283.65	20.7601
287.247	19.1216
290.842	20.5567
294.436	21.0698
298.028	24.9138
301.617	24.9325
305.206	22.4781
308.794	21.5811
312.381	20.4912
315.964	20.8578
319.548	21.2563
323.131	20.865
326.71	18.98
330.29	16.7027
333.868	16.8764
337.443	15.4733
341.018	16.5467
344.591	15.8741
348.163	15.9607
351.733	14.1103
355.303	12.9579
358.869	11.4628
362.435	11.4361
366.001	10.2377
369.563	12.3998
373.124	14.9454
376.686	17.6593
380.244	20.0212
383.801	19.7829
387.357	20.6748
390.911	20.2922
394.466	19.1669
398.018	19.6811
401.568	19.8391
405.117	18.7347
408.664	17.7134
412.21	15.952
415.755	15.4578
419.298	14.6014
422.84	12.5933
426.38	10.7697
429.919	7.88325
433.455	5.48343
436.992	3.86121
440.527	4.65493
444.06	3.40693
447.593	2.67081
451.122	3.92581
454.651	6.37786
458.18	9.7602
461.705	10.7881
465.23	10.832
468.752	10.6682
472.275	14.0349
475.797	14.7735
479.315	16.9
482.834	16.8261
486.349	17.5807
489.863	18.9321
493.378	19.1731
496.889	18.9665
500.401	20.1331
503.91	20.78
507.417	20.8275
510.923	20.5431
514.43	22.2699
517.933	21.2806
521.435	21.2616
524.936	21.0589
528.435	21.5533
531.933	18.8555
535.43	18.2835
538.927	18.4622
542.421	16.8355
545.913	14.4906
549.403	11.7234
552.893	10.555
556.381	12.6219
559.868	13.6029
563.354	12.9274
566.839	13.5003
570.322	12.3105
573.802	11.9351
577.283	10.5576
580.762	10.1135
584.24	10.2468
587.714	11.7174
591.19	10.9953
594.663	11.0651
598.134	11.4247
601.605	11.3799
605.073	11.5854
608.542	11.3951
612.007	11.6602
615.473	12.0739
618.936	11.2977
622.397	13.2166
625.859	12.9926
629.318	16.3556
632.775	16.3024
636.233	20.5018
639.688	21.7555
643.142	24.2553
646.594	27.7964
650.045	29.3167
653.496	30.5639
656.944	30.939
660.391	30.9535
663.837	31.8667
667.281	32.9538
670.724	35.4751
674.166	37.6404
677.606	40.3393
681.045	41.7062
684.483	45.5514
687.917	47.2332
691.352	46.0723
694.786	47.6561
698.219	50.8015
701.65	51.7881
705.078	53.518
708.506	55.6363
711.934	57.5566
715.358	58.9784
718.782	61.1535
722.204	62.8754
725.626	64.6333
729.045	67.6325
732.464	69.956
735.881	72.3469
739.297	74.6375
742.711	75.2931
746.125	76.4973
749.537	79.1277
752.946	84.0413
756.357	87.2009
759.764	90.742
763.17	94.7253
766.575	99.0183
769.978	103.741
773.382	105.777
776.783	109.321
780.182	114.246
783.581	118.614
786.978	121.095
790.373	127.139
793.768	133.041
797.161	138.052
800.552	141.537
803.941	145.358
807.33	148.537
810.718	149.819
814.105	152.837
817.49	154.018
820.873	153.819
824.256	152.406
827.637	149.297
831.016	146.796
834.395	147.557
837.772	145.594
841.147	142.937
844.522	138.573
847.894	136.578
851.267	132.467
854.637	129.339
858.007	126.007
861.374	121.682
864.739	117.551
868.106	117.066
871.469	115.808
874.831	114.96
878.193	114.174
881.553	111.938
884.911	110.134
888.268	107.809
891.623	106.792
894.978	106.076
898.331	105.16
901.683	104.558
905.033	102.497
908.383	98.8228
911.731	98.1419
915.078	99.2713
918.423	99.1515
921.768	96.6745
925.111	93.6159
928.452	92.7238
931.791	90.7725
935.13	88.5901
938.468	88.2483
941.803	84.4456
945.139	79.9755
948.473	77.7622
951.804	75.5944
955.136	70.7041
958.465	67.1469
961.794	61.5771
965.12	56.7807
968.447	56.2553
971.771	54.0215
975.095	53.885
978.417	51.8509
981.737	50.6192
985.057	47.1988
988.375	43.5795
991.691	42.578
995.006	41.4812
998.32	41.7174
1001.63	40.6322
1004.95	39.8818
1008.26	40.5311
1011.56	40.1181
1014.87	37.5683
1018.18	38.2722
1021.48	37.4366
1024.79	36.3908
1028.09	36.8474
1031.39	37.857
1034.69	37.7393
1037.99	37.122
1041.29	35.0107
1044.58	36.2872
1047.88	38.7281
1051.17	38.9248
1054.46	36.7789
1057.75	35.8225
1061.04	31.6394
1064.33	28.3644
1067.62	25.7219
1070.9	24.7627
1074.19	22.2805
1077.47	21.6926
1080.76	23.3491
1084.04	22.2269
1087.32	22.374
1090.59	20.0024
1093.87	19.0541
1097.15	21.8203
1100.42	22.2948
1103.69	25.2935
1106.97	25.9093
1110.24	27.2776
1113.51	28.9772
1116.77	27.7188
1120.04	26.2388
1123.31	22.5468
1126.57	20.4605
1129.83	18.6145
1133.1	17.2911
1136.36	16.035
1139.62	11.9939
1142.87	9.1012
1146.13	9.96099
1149.38	8.39597
1152.64	6.4402
1155.89	5.88306
1159.14	6.59318
1162.39	5.29358
1165.64	4.10017
1168.89	5.04571
1172.14	5.88258
1175.38	7.85412
1178.63	9.3893
1181.87	9.68773
1185.11	11.7413
1188.35	12.5987
1191.59	12.2299
1194.83	14.3403
1198.07	13.5251
1201.3	15.029
1204.53	16.9635
1207.77	21.3358
1211	22.5843
1214.23	23.5348
1217.46	25.5354
1220.69	28.4267
1223.91	30.0326
1227.14	31.5158
1230.36	31.5793
1233.59	33.5406
1236.81	35.4583
1240.03	36.2635
1243.25	37.6049
1246.46	40.0665
1249.68	40.758
1252.9	43.5425
1256.11	45.2076
1259.32	45.9789
1262.54	48.5403
1265.75	50.2631
1268.96	51.2337
1272.16	53.2143
1275.37	53.3055
1278.57	55.088
1281.78	57.1195
1284.98	58.583
1288.18	60.5852
1291.38	60.6442
1294.58	63.4216
1297.78	63.9091
1300.98	64.5457
1304.17	65.7054
1307.37	68.5479
1310.56	71.3189
1313.76	71.9884
1316.95	71.6294
1320.14	72.3832
1323.32	72.7601
1326.51	71.5794
1329.7	73.9496
1332.88	74.4547
1336.07	72.7897
1339.25	71.2414
1342.43	72.5019
1345.61	69.7104
1348.79	65.2139
1351.96	61.1961
1355.14	58.8412
1358.31	56.5783
1361.49	52.3101
1364.66	48.7761
1367.83	46.7611
1371	43.3342
1374.17	40.0609
1377.34	39.9943
1380.5	38.2784
1383.67	39.292
1386.83	38.7054
1390	36.1506
1393.16	35.5197
1396.32	33.4121
1399.48	33.5804
1402.64	32.8975
1405.79	33.0982
1408.95	35.0087
1412.1	36.0957
1415.26	37.4726
1418.41	40.98
1421.56	44.5244
1424.71	47.535
1427.86	51.1879
1431	56.2188
1434.15	61.7218
1437.29	63.5009
1440.44	65.6342
1443.58	68.9301
1446.72	70.0386
1449.86	70.6449
1453	69.8815
1456.14	70.4154
1459.27	67.5253
1462.41	63.9343
1465.54	60.1522
1468.67	52.9427
1471.81	48.3102
1474.94	41.347
1478.07	35.9311
1481.19	29.9643
1484.32	26.2521
1487.45	22.334
1490.57	19.0937
1493.69	16.3194
1496.82	15.5845
1499.94	14.0547
1503.06	11.4909
1506.17	10.7153
1509.29	9.75898
1512.41	7.81118
1515.52	6.71621
1518.64	8.07761
1521.75	7.03516
1524.86	9.47768
1527.97	10.2056
1531.08	13.5352
1534.19	14.2949
1537.29	15.5982
1540.4	19.0464
1543.5	23.812
1546.61	27.1307
1549.71	32.4373
1552.81	35.9377
1555.91	42.0717
1559.01	48.1355
1562.11	52.2837
1565.2	54.7716
1568.29	58.1222
1571.39	61.9537
1574.48	64.3639
1577.57	65.9182
1580.66	67.908
1583.75	70.4765
1586.84	71.4273
1589.93	71.9066
1593.01	68.922
1596.1	68.6766
1599.18	67.2788
1602.26	65.7004
1605.34	62.4534
1608.42	61.8395
1611.5	58.5231
1614.58	57.1218
1617.65	57.8203
1620.73	58.4091
1623.8	56.8947
1626.87	57.6132
1629.95	58.4286
1633.02	59.9761
1636.09	61.7707
1639.15	63.1171
1642.22	65.6301
1645.29	71.4613
1648.35	73.8287
1651.42	76.4908
1654.48	79.7032
1657.54	81.4212
1660.6	81.8048
1663.66	81.8072
1666.72	79.8601
1669.77	78.3782
1672.83	76.2846
1675.88	71.6192
1678.93	67.4804
1681.99	62.949
1685.04	56.4812
1688.09	51.289
1691.13	46.4233
1694.18	42.0787
1697.23	38.4785
1700.27	33.5525
1703.32	28.4139
1706.36	24.1322
1709.4	21.0703
1712.44	17.9117
1715.48	14.9343
1718.52	14.2886
1721.56	10.4464
1724.59	8.83375
1727.63	8.47303
1730.66	7.44167
1733.69	6.83042
1736.72	7.64204
1739.75	7.34407
1742.78	7.46731
1745.81	7.43476
1748.84	8.11703
1751.86	7.74523
1754.89	7.01185
1757.91	6.2693
1760.93	7.14197
1763.95	7.8576
1766.97	8.50533
1769.99	8.77999
1773.01	6.83875
1776.03	6.39467
1779.04	4.24226
1782.06	3.94015
1785.07	3.10512
1788.08	2.03306
1791.09	1.86317
1794.1	2.21672
1797.11	2.05429
1800.12	2.1759
1803.12	2.65716
1806.13	4.96332
1809.13	6.12391
1812.14	6.32181
1815.14	5.72363
1818.14	5.99626
1821.14	6.05855
1824.14	5.90808
1827.13	5.01801
1830.13	5.35666
1833.12	5.73105
1836.12	4.53586
1839.11	4.95373
1842.1	3.91285
1845.09	2.82921
1848.08	2.2947
1851.07	1.62577
1854.06	1.44588
1857.04	2.34281
1860.03	3.06215
1863.01	3.77508
1866	3.45015
1868.98	4.5327
1871.96	5.32907
1874.94	6.17018
1877.92	7.05824
1880.89	6.30748
1882.48	4.49169
1885.47	5.64455
1888.46	4.65571
1891.44	3.83731
1894.43	3.74377
1897.41	4.02223
1900.4	4.92137
1903.38	5.31131
1906.36	4.52577
1909.34	3.5203
1912.32	3.75407
1915.29	3.40072
1918.27	2.58544
1921.25	4.24738
1924.22	4.04574
1927.2	5.32053
1930.17	6.48763
1933.14	7.061
1936.11	5.04402
1939.08	4.80194
1942.05	5.40609
1945.01	5.19747
1947.98	5.21559
1950.94	4.91312
1953.91	3.30178
1956.87	4.30404
1959.83	4.63178
1962.79	3.53895
1965.75	4.2279
1968.71	4.16642
1971.67	3.90605
1974.62	4.32237
1977.58	3.77965
1980.53	4.19732
1983.48	4.93922
1986.43	4.43761
1989.38	4.27773
1992.33	4.89504
1995.28	5.46572
1998.23	6.43293
2001.18	6.39209
2004.12	5.33839
2007.06	4.50995
2010.01	3.79951
2012.95	5.05315
2015.89	6.28312
2018.83	7.09276
2021.77	6.94207
2024.71	6.7043
2027.64	7.47213
2030.58	8.48613
2033.51	8.59102
2036.45	9.58889
2039.38	9.14391
2042.31	9.44867
2045.24	10.4909
2048.17	10.1057
2051.1	11.9707
2054.02	13.4329
2056.95	14.834
2059.87	13.8943
2062.8	15.9962
2065.72	17.1786
2068.64	16.3481
2071.56	16.4512
2074.48	16.266
2077.4	17.8504
2080.31	18.3634
2083.23	19.304
2086.14	23.0583
2089.06	22.9593
2091.97	24.0312
2094.88	25.0813
2097.79	26.278
2100.7	28.0924
2103.61	27.8679
2106.52	30.646
2109.43	31.8636
2112.33	33.112
2115.24	33.7361
2118.14	36.6912
2121.04	38.6183
2123.94	41.4166
2126.84	44.2869
2129.74	46.4136
2132.64	47.7299
2135.54	50.8148
2138.43	52.9622
2141.33	55.1588
2144.22	57.4105
2147.11	61.8103
2150.01	65.6826
2152.9	66.8496
2155.79	69.3048
2158.67	70.7895
2161.56	72.5729
2164.45	74.9447
2167.33	76.7362
2170.22	77.3083
2173.1	77.3375
2175.98	77.0658
2178.86	75.7564
2181.74	74.0724
2184.62	73.898
2187.5	71.6341
2190.38	70.0346
2193.25	67.1014
2196.13	66.0594
2199	63.9941
2201.88	62.1153
2204.75	61.5936
2207.62	58.5542
2210.49	55.7469
2213.36	52.7969
2216.22	51.0639
2219.09	48.3144
2221.96	44.172
2224.82	40.6053
2227.68	39.1705
2230.55	38.2852
2233.41	36.9472
2236.27	35.9017
2239.12	35.05
2241.98	33.0749
2244.84	30.8593
2247.7	28.1133
2250.55	29.1099
2253.41	29.24
2256.26	29.1575
2259.11	27.0839
2261.96	26.7568
2264.81	27.905
2267.66	29.5765
2270.51	30.5669
2273.35	31.308
2276.2	30.6265
2279.04	30.388
2281.89	28.2951
2284.73	27.0426
2287.57	25.8726
2290.41	24.416
2293.25	22.5233
2296.09	22.4893
2298.93	22.9304
2301.76	22.004
2304.6	21.1979
2307.44	21.4768
2310.27	19.3837
2313.1	17.8886
2315.93	16.8987
2318.76	16.9272
2321.59	18.3648
2324.42	17.3314
2327.25	16.1053
2330.07	16.0495
2332.9	17.0546
2335.72	17.3764
2338.55	17.6161
2341.37	17.9051
2344.19	16.2873
2347.01	15.8488
2349.83	14.8009
2352.65	14.8961
2355.46	14.6218
2358.28	13.1639
2361.09	11.7914
2363.91	10.9296
2366.72	10.7887
2369.53	10.6046
2372.34	10.6513
2375.15	9.72683
2377.96	8.35471
2380.77	5.26874
2383.58	5.52787
2386.38	5.94796
2389.19	6.52674
2391.99	5.11238
2394.8	4.21805
2397.6	4.3533
2400.4	6.15009
2403.2	6.544
2406	5.61689
2408.79	7.42319
2411.59	7.28316
2414.39	8.60815
2417.18	11.3419
2419.98	13.2393
2422.77	13.7269
2425.56	12.0692
2428.35	12.3476
2431.14	13.0925
2433.93	12.8822
2436.72	13.0973
2439.5	14.3269
2442.29	12.7854
2445.07	11.6144
2447.86	10.7918
2450.64	11.7271
2453.42	11.5823
2456.2	10.2322
2458.98	9.41844
2461.76	8.8408
2464.54	9.021
2467.32	9.63391
2470.09	8.23752
2472.87	7.08901
2475.64	6.77944
2478.41	6.96935
2481.18	7.44405
2483.95	7.97395
2486.72	7.03134
2489.49	5.78357
2492.26	4.56006
2495.03	4.21182
2497.79	4.3213
2500.56	3.16921
2503.32	2.9101
2506.09	4.37278
2508.85	4.27582
2511.61	3.70602
2514.37	4.34755
2517.13	5.29857
2519.89	4.1877
2522.64	4.18333
2525.4	4.95281
2528.15	5.83729
2530.91	5.53232
2533.66	5.37842
2536.41	5.02252
2539.16	4.83269
2541.91	4.33693
2544.66	4.32814
2547.41	5.59546
2550.16	5.49214
2552.9	6.75572
2555.65	7.00624
2558.39	6.37441
2561.13	5.96665
2563.88	6.68978
2566.62	6.96812
2569.36	7.33577
2572.1	7.56223
2574.84	7.73689
2577.57	7.40106
2580.31	4.91933
2583.05	4.59102
2585.78	3.96342
2588.51	4.63998
2591.24	3.89068
2593.98	2.46959
2596.71	2.45327
2599.44	2.01494
2602.16	1.12388
2604.89	1.69424
2607.62	0.122034
2610.34	0.805497
2613.07	1.27335
2615.79	1.61291
2618.52	2.03012
2621.24	1.5194
2623.96	1.28496
2626.68	1.67175
2629.4	2.43307
2632.11	2.9482
2634.83	4.83266
2637.55	4.6635
2640.26	4.45122
2642.98	4.48455
2645.69	4.46425
2648.4	4.45151
2651.11	4.16255
2653.82	4.68109
2656.53	4.9146
2659.24	4.80799
2661.95	5.3431
2664.65	5.83137
2667.36	6.6615
2670.06	6.65765
2672.76	7.75466
2675.47	8.87603
2678.17	8.09311
2680.87	8.356
2683.57	7.64484
2686.27	7.07243
2688.97	6.48654
2691.66	6.83794
2694.36	6.3816
2697.05	5.18783
2699.75	4.32051
2702.44	3.8374
2705.13	3.90587
2707.82	4.28729
2710.51	4.72049
2713.2	4.94542
2715.89	4.30037
2718.57	6.51424
2721.26	7.30897
2723.95	7.11454
2726.63	7.08935
2729.31	6.97219
2732	7.74587
2734.68	7.87053
2737.36	7.89667
2740.04	8.54318
2742.72	6.98955
2745.39	6.69028
2748.07	6.27863
2750.75	5.46837
2753.42	4.5806
2756.09	3.08968
2758.77	3.23326
2761.44	3.97305
2764.11	4.73335
2766.78	4.40565
2769.45	4.89457
2772.12	6.10328
2774.78	6.72326
2777.45	7.57015
2780.12	7.84156
2782.78	8.79162
2785.44	8.66569
2788.11	7.38474
2790.77	7.27789
2793.43	6.86192
2796.09	6.92219
2798.75	5.80106
2801.4	5.99198
2804.06	4.37567
2806.72	3.89627
2809.37	3.73099
2812.03	5.19768
2814.68	5.05454
2817.33	4.53877
2819.98	4.76789
2822.63	7.99091
2825.28	9.32365
2827.93	11.9475
2830.58	16.304
2833.23	20.4416
2835.87	25.5986
2838.52	29.3426
2841.16	32.8124
2843.8	37.875
2846.44	43.9837
2849.08	51.804
2851.73	59.243
2854.36	67.872
2857	74.873
2859.64	81.1547
2862.28	87.9648
2864.91	95.4764
2867.55	102.015
2870.18	108.725
2872.81	114.499
2875.44	120.156
2878.07	123.699
2880.7	127.384
2883.33	131.603
2885.96	136.672
2888.59	141.504
2891.21	145.692
2893.84	151.52
2896.46	157.529
2899.09	162.518
2901.71	169.277
2904.33	176.83
2906.95	184.337
2909.57	194.199
2912.19	203.862
2914.81	214.401
2917.43	223.624
2920.04	230.613
2922.66	236.131
2925.27	240.664
2927.88	245.599
2930.5	246.81
2933.11	246.532
2935.72	244.743
2938.33	240.799
2940.94	235.21
2943.54	230.423
2946.15	223.807
2948.76	215.751
2951.36	208.866
2953.97	199.938
2956.57	192.636
2959.17	185.708
2961.77	177.571
2964.37	171.376
2966.97	164.294
2969.57	156.346
2972.17	150.2
2974.77	143.514
2977.36	137.382
2979.96	128.76
2982.55	120.339
2985.15	111.787
2987.74	102.115
2990.33	93.0975
2992.92	82.2605
2995.51	72.4111
2998.1	64.1221
3000.69	56.4859
3003.27	49.3236
3005.86	41.3912
3008.44	35.3044
3011.03	30.3358
3013.61	27.2359
3016.19	22.8868
3018.78	20.5112
3021.36	18.276
3023.94	15.7042
3026.51	15.2188
3029.09	15.0069
3031.67	16.2373
3034.24	16.193
3036.82	16.2078
3039.39	17.548
3041.97	18.0152
3044.54	17.6844
3047.11	18.7714
3049.68	18.7219
3052.25	18.2692
3054.82	18.6442
3057.39	17.9372
3059.96	19.5178
3062.52	20.2071
3065.09	19.7022
3067.65	18.6171
3070.22	17.598
3072.78	16.3482
3075.34	16.2589
3077.9	14.8776
3080.46	13.5257
3083.02	11.9841
3085.58	9.36569
3088.14	8.44807
3090.69	7.16525
3093.25	5.77252
3095.8	5.84053
3098.36	3.95734
3100.91	2.60597
3103.46	2.33905
3106.01	1.91038
3108.56	1.67649
3111.11	1.37006
3113.66	0.70847
3116.21	-0.556625
3118.76	-1.16686
3121.3	-0.549893
3123.85	-0.431924
3126.39	-0.73494
3128.93	-0.187899
3131.48	-0.166348
3134.02	0.196543
3136.56	1.78047
3139.1	2.68799
3141.64	4.76021
3144.17	6.50249
3146.71	9.95452
3149.25	13.541