File: data/Raman/poly_smoothed/Thy_40_11_18_1x_45s_532 nm_x100_100%_600 gr_mm_01.txt
#Acq. time (s)=	45
#Accumulations=	2
#Range (cm-¹)=	200...3150
#Windows=	2
#Auto scanning=	Off
#Autofocus=	Off
#Macrospot=	Off
#AutoExposure=	Off
#Spike filter=	Multiple accum.
#Delay time (s)=	0
#Binning=	1
#Readout mode=	Signal
#DeNoise=	Off
#ICS correction=	On
#Dark correction=	Off
#Inst. Process=	Off
#Detector Gain=	Best Dynamic Range
#Detector ADC=	20 kHz
#Detector temperature (°C)=	-69.85
#Instrument=	LabRAM HR Evol
#Detector=	Synapse
#Objective=	x100
#Grating=	600 gr/mm
#ND Filter=	100%
#Laser (nm)=	532
#Hole=	100.021
#Range=	Auto
#Laser Pol.=	No
#Raman. Pol.=	No
#Laser Pol. (°)=	-0.0007625
#Raman Pol. (°)=	89.9995
#Collection=	Microscope
#StageXY=	Marzhauser
#StageZ=	Marzhauser
#X (µm)=	1984.8
#Y (µm)=	-47.7
#Z (µm)=	425.1
#Full time(mm:ss)=	3:18
#Project=
#Sample=
#Site=
#Title=	Thy_40_11_18_2x_45s_532 nm_x100_100%_600 gr_mm
#Remark=
#Date=	05.07.2022 11:09
#Acquired=	05.07.2022 11:09:38
#Base:Fit=	10.08.2022 10:01:35
#Base:Sub=	10.08.2022 10:01:52
#Filter:Polynom=	16.08.2022 10:21:53
#AxisType[0]=Intens
#AxisUnit[0]=Cnt
#AxisType[1]=Spectr
#AxisUnit[1]=1/cm
200.43	-4.12193
204.059	2.09566
207.688	9.00848
211.314	12.4055
214.941	15.1621
218.564	16.6607
222.186	18.8569
225.809	18.963
229.428	19.7099
233.045	20.882
236.663	20.9352
240.278	20.2275
243.891	20.0554
247.503	19.6554
251.116	18.1285
254.725	18.3716
258.333	16.1121
261.939	15.8481
265.544	16.8078
269.148	16.5793
272.75	15.5005
276.351	16.4989
279.95	17.1216
283.548	17.3968
287.144	16.7235
290.739	17.2008
294.333	17.1237
297.925	16.1863
301.514	17.2799
305.104	18.5744
308.692	18.7819
312.279	19.083
315.862	18.8204
319.446	19.6167
323.029	20.3963
326.608	19.7187
330.188	19.0535
333.766	20.1984
337.341	20.4355
340.917	20.0472
344.489	20.877
348.062	19.4333
351.631	19.6629
355.201	17.1079
358.768	15.8923
362.333	14.2815
365.899	14.3267
369.462	13.3289
373.023	11.2214
376.585	9.79361
380.143	9.97209
383.7	8.71245
387.256	8.46859
390.812	7.87814
394.365	8.14305
397.916	6.28767
401.467	5.66574
405.015	5.67685
408.563	3.5288
412.109	4.19028
415.654	3.48694
419.197	3.72572
422.739	5.53895
426.279	4.97948
429.819	5.1842
433.356	5.0871
436.891	4.28714
440.426	3.67353
443.96	2.78041
447.492	2.88699
451.021	3.12121
454.551	3.97895
458.079	4.87172
461.604	4.92891
465.13	6.63018
468.654	7.97254
472.175	8.80677
475.696	9.23769
479.215	10.3111
482.733	11.5047
486.249	11.578
489.765	11.9116
493.278	11.1789
496.789	11.0393
500.301	14.1503
503.81	16.0943
507.317	19.0679
510.825	19.4022
514.33	18.6545
517.833	19.0102
521.335	19.4047
524.836	19.2837
528.335	18.9318
531.835	18.8871
535.332	18.8135
538.827	17.8633
542.321	16.6932
545.814	15.9893
549.305	14.5776
552.795	12.6254
556.282	11.4988
559.769	8.59627
563.255	8.41283
566.739	7.27466
570.223	4.6184
573.705	2.85067
577.183	2.58101
580.663	1.39085
584.141	3.28132
587.615	2.60099
591.09	3.18555
594.564	3.88893
598.035	3.16191
601.506	2.61722
604.974	3.60182
608.443	5.31019
611.908	5.44424
615.374	6.69763
618.837	6.14444
622.3	5.42481
625.761	7.38662
629.219	8.06754
632.677	9.74551
636.135	9.88858
639.59	10.8695
643.043	11.6611
646.495	13.1703
649.948	15.0101
653.398	14.1183
656.846	14.728
660.293	16.1541
663.738	15.6311
667.183	15.4733
670.626	16.2157
674.067	18.4365
677.508	20.4852
680.947	21.89
684.385	23.9001
687.821	25.5045
691.254	26.4316
694.688	26.964
698.121	27.6539
701.552	27.3743
704.98	27.4111
708.409	29.4888
711.836	30.8605
715.26	32.4707
718.685	34.6796
722.108	34.6013
725.528	35.97
728.949	37.7176
732.367	38.5603
735.785	38.4572
739.2	37.7917
742.614	40.0767
746.028	41.3271
749.439	43.7789
752.849	44.9267
756.26	48.3689
759.667	49.9284
763.073	53.1439
766.477	55.8421
769.883	56.1015
773.285	56.9036
776.686	58.2849
780.085	57.597
783.484	57.8544
786.881	60.1906
790.276	61.6846
793.671	62.7464
797.064	63.8687
800.456	63.302
803.846	63.8651
807.234	64.9148
810.622	65.5551
814.008	65.5825
817.394	66.4597
820.778	67.1423
824.159	69.0016
827.541	70.9277
830.921	70.4957
834.298	68.2128
837.676	66.9073
841.051	65.961
844.426	63.8269
847.798	63.3536
851.171	60.8047
854.54	58.4214
857.911	56.4886
861.278	54.1707
864.645	52.6095
868.01	51.1652
871.373	49.7548
874.735	47.1568
878.097	44.9218
881.457	43.5864
884.815	42.0143
888.172	41.5072
891.528	41.6874
894.882	42.1823
898.237	41.8143
901.589	41.3919
904.94	42.2737
908.289	41.0042
911.635	39.7221
914.982	38.3192
918.328	38.5586
921.672	36.9939
925.015	36.2531
928.357	35.36
931.698	36.3909
935.035	33.4267
938.373	31.5488
941.71	29.8368
945.044	28.5222
948.378	28.1095
951.709	28.1633
955.041	28.4371
958.372	26.1157
961.699	25.742
965.027	27.4118
968.352	26.8041
971.676	27.0116
975	26.1257
978.322	26.5616
981.642	27.2839
984.962	27.3395
988.28	27.4447
991.596	26.7486
994.911	26.5547
998.227	25.6366
1001.54	24.1826
1004.85	22.2711
1008.16	22.6623
1011.47	20.9696
1014.78	18.5601
1018.08	16.9932
1021.39	16.5446
1024.69	18.2432
1028	19.3336
1031.3	20.952
1034.6	19.0851
1037.9	17.864
1041.19	17.3896
1044.49	17.3203
1047.78	15.8502
1051.08	14.258
1054.37	14.9373
1057.66	14.7329
1060.95	17.387
1064.24	15.5223
1067.53	16.0615
1070.81	15.2438
1074.1	13.438
1077.38	12.8528
1080.66	12.3245
1083.94	12.0159
1087.22	12.2146
1090.5	11.5245
1093.78	12.364
1097.05	13.9694
1100.33	15.2094
1103.6	15.2887
1106.87	14.446
1110.14	14.0962
1113.41	11.6457
1116.68	9.13371
1119.95	8.45718
1123.21	7.83149
1126.48	6.21608
1129.74	6.58669
1133	6.10755
1136.26	6.22589
1139.52	6.14141
1142.78	5.82663
1146.04	4.9678
1149.29	5.53408
1152.55	4.24376
1155.8	4.99316
1159.05	4.46922
1162.3	4.09444
1165.55	4.01187
1168.8	3.54076
1172.05	3.67999
1175.29	5.35436
1178.54	5.77639
1181.78	5.78787
1185.02	6.18538
1188.26	6.40703
1191.5	8.16473
1194.74	8.40016
1197.97	10.9349
1201.21	13.1215
1204.44	15.4537
1207.68	17.6862
1210.91	20.0803
1214.14	19.9503
1217.37	22.8903
1220.59	26.4856
1223.82	29.1162
1227.05	32.0796
1230.27	34.061
1233.49	35.9486
1236.72	37.8556
1239.94	38.4188
1243.16	41.0645
1246.37	44.03
1249.59	45.309
1252.8	46.5968
1256.02	49.96
1259.23	50.7327
1262.44	53.3749
1265.66	53.4854
1268.86	55.4986
1272.07	55.8451
1275.28	57.2056
1278.48	58.501
1281.69	59.0948
1284.89	59.5016
1288.09	59.2515
1291.29	59.0239
1294.49	58.2793
1297.69	61.4753
1300.89	62.4659
1304.08	63.5939
1307.28	65.5368
1310.47	66.4913
1313.66	67.2214
1316.85	69.1035
1320.04	69.4276
1323.23	68.6386
1326.42	69.7641
1329.61	68.2751
1332.79	68.1329
1335.97	67.5307
1339.16	67.0601
1342.34	64.232
1345.52	62.8072
1348.7	60.0007
1351.87	56.9133
1355.05	54.7591
1358.22	51.5453
1361.4	48.536
1364.57	44.5913
1367.74	42.2782
1370.91	41.4907
1374.08	40.5369
1377.25	38.3511
1380.41	38.5061
1383.58	37.8426
1386.74	37.3576
1389.91	38.3789
1393.07	37.6992
1396.23	35.8517
1399.39	35.3
1402.55	35.211
1405.7	34.757
1408.86	35.7078
1412.01	37.8201
1415.17	39.3233
1418.32	40.5409
1421.47	43.8386
1424.62	47.0413
1427.77	51.0249
1430.91	55.4704
1434.06	60.3122
1437.2	65.1953
1440.35	68.4585
1443.49	70.3094
1446.63	71.925
1449.77	72.7952
1452.91	71.5604
1456.05	71.0358
1459.18	69.9319
1462.32	66.4006
1465.45	63.9773
1468.59	59.2364
1471.72	53.6635
1474.85	48.817
1477.98	44.3388
1481.1	40.6888
1484.23	37.8306
1487.36	34.3324
1490.48	30.8641
1493.61	26.9382
1496.73	25.1709
1499.85	23.1388
1502.97	22.5714
1506.09	21.8305
1509.2	22.0217
1512.32	22.9987
1515.43	22.3962
1518.55	21.4681
1521.66	22.1065
1524.77	22.5523
1527.88	22.9649
1530.99	23.8832
1534.1	25.272
1537.21	26.3668
1540.31	28.8196
1543.42	32.3455
1546.52	35.5015
1549.62	39.5066
1552.72	44.1313
1555.82	49.0846
1558.92	52.4572
1562.02	55.0248
1565.11	56.8168
1568.21	60.1796
1571.3	61.9962
1574.39	65.2599
1577.49	66.3766
1580.57	68.8942
1583.66	70.2748
1586.75	72.7271
1589.84	73.2431
1592.92	72.6173
1596.01	72.4397
1599.09	70.8912
1602.17	68.1846
1605.25	67.6138
1608.33	65.881
1611.41	64.6035
1614.49	64.0027
1617.57	62.7714
1620.64	62.4003
1623.72	62.6361
1626.79	62.0517
1629.86	62.9637
1632.93	63.9408
1636	63.7884
1639.07	65.7066
1642.13	68.8669
1645.2	70.57
1648.26	73.8128
1651.33	74.3908
1654.39	72.1998
1657.45	72.8239
1660.51	74.5961
1663.57	74.2186
1666.63	72.7459
1669.68	69.9792
1672.74	67.5839
1675.79	63.9178
1678.85	60.1382
1681.9	56.1822
1684.95	51.2837
1688	45.6931
1691.05	40.7117
1694.09	35.0282
1697.14	31.4786
1700.18	27.2024
1703.23	24.2655
1706.27	21.1849
1709.31	18.7787
1712.35	16.6334
1715.39	14.4191
1718.43	12.9473
1721.47	11.5815
1724.5	10.9633
1727.54	7.64961
1730.57	7.02557
1733.61	9.95405
1736.64	9.48539
1739.67	8.11558
1742.7	7.31058
1745.72	6.96762
1748.75	6.83496
1751.77	6.80916
1754.8	5.97344
1757.82	4.92734
1760.84	4.58842
1763.87	4.42389
1766.89	3.39617
1769.91	3.22208
1772.92	3.23964
1775.94	1.98545
1778.95	1.52888
1781.97	0.947451
1784.98	2.12756
1787.99	1.53423
1791.01	1.47871
1794.01	1.49786
1797.02	1.94931
1800.03	1.4688
1803.04	1.41986
1806.04	1.78432
1809.05	1.92288
1812.05	1.98543
1815.05	2.89213
1818.05	3.30577
1821.05	3.91067
1824.05	4.24531
1827.05	3.67517
1830.04	4.78779
1833.04	5.12144
1836.03	4.50277
1839.03	4.26782
1842.02	4.58276
1845.01	3.917
1848	3.2182
1850.99	2.74028
1853.97	3.30911
1856.96	4.45098
1859.94	4.8872
1862.93	4.89101
1865.91	5.2937
1868.89	5.16159
1871.87	5.23172
1874.85	5.46584
1877.83	5.61688
1880.81	6.02385
1882.57	6.02319
1885.56	6.22423
1888.55	6.09825
1891.54	5.65724
1894.52	6.22878
1897.51	6.57334
1900.49	7.87669
1903.47	7.43101
1906.45	7.14769
1909.43	7.07824
1912.41	6.89525
1915.39	6.60239
1918.37	4.80708
1921.34	4.25525
1924.32	4.07461
1927.29	4.99376
1930.26	4.8827
1933.23	4.32193
1936.2	3.24055
1939.17	3.72506
1942.14	3.20544
1945.11	5.62598
1948.07	5.33385
1951.04	4.21835
1954	4.42935
1956.96	3.8982
1959.93	3.65882
1962.89	3.52175
1965.85	4.72565
1968.8	5.19476
1971.76	4.15978
1974.72	4.78938
1977.67	5.06253
1980.63	5.17451
1983.58	4.77627
1986.53	4.75091
1989.48	5.56474
1992.43	5.89026
1995.38	6.9592
1998.32	6.89409
2001.27	7.9258
2004.22	7.36877
2007.16	7.98872
2010.1	7.94677
2013.04	8.58284
2015.98	8.57612
2018.92	8.71409
2021.86	8.15303
2024.8	8.31678
2027.74	8.21448
2030.67	8.01771
2033.61	8.94222
2036.54	9.36744
2039.47	9.61419
2042.4	9.92988
2045.33	10.3949
2048.26	10.3405
2051.19	10.102
2054.12	10.9656
2057.04	12.036
2059.97	12.2269
2062.89	14.3471
2065.81	14.1891
2068.73	14.4722
2071.65	14.1661
2074.57	14.9426
2077.49	14.4407
2080.41	14.6414
2083.32	15.0422
2086.24	15.735
2089.15	17.3273
2092.07	18.9908
2094.98	19.6829
2097.89	20.9121
2100.8	21.2624
2103.71	23.6368
2106.61	25.9779
2109.52	26.2487
2112.43	27.2913
2115.33	28.8385
2118.23	29.7075
2121.13	33.3699
2124.04	36.408
2126.94	39.837
2129.83	42.8337
2132.73	46.0286
2135.63	48.6283
2138.53	51.888
2141.42	54.6954
2144.31	58.1282
2147.21	61.4786
2150.1	63.1668
2152.99	66.419
2155.88	68.7722
2158.77	71.3514
2161.65	74.1541
2164.54	76.2512
2167.43	76.9949
2170.31	77.2503
2173.19	76.3276
2176.07	76.4917
2178.96	75.0383
2181.84	73.1203
2184.72	71.4943
2187.59	70.6478
2190.47	69.3702
2193.35	68.3291
2196.22	65.6311
2199.09	62.7426
2201.97	59.1496
2204.84	56.2379
2207.71	53.0656
2210.58	50.9431
2213.45	46.5848
2216.31	43.0573
2219.18	40.0937
2222.05	38.0259
2224.91	36.037
2227.78	33.9998
2230.64	32.8022
2233.5	31.4192
2236.36	28.6974
2239.22	27.2758
2242.08	25.4576
2244.93	25.2709
2247.79	23.9502
2250.64	23.4687
2253.5	22.8916
2256.35	23.1156
2259.2	23.4954
2262.05	23.1843
2264.9	22.8733
2267.75	21.2878
2270.6	19.5902
2273.45	18.5435
2276.29	18.3936
2279.14	17.3513
2281.98	16.5714
2284.82	15.4827
2287.66	15.4383
2290.5	15.4521
2293.34	12.878
2296.18	12.6883
2299.02	13.6195
2301.86	14.0204
2304.69	14.3269
2307.53	14.9348
2310.36	15.2157
2313.19	15.0088
2316.02	15.7524
2318.85	14.7999
2321.68	15.4763
2324.51	15.2453
2327.34	14.1019
2330.16	13.1927
2332.99	11.9911
2335.81	11.5981
2338.64	11.0925
2341.46	9.47917
2344.28	8.36742
2347.1	7.56568
2349.92	6.31282
2352.74	4.72809
2355.55	3.031
2358.37	2.23279
2361.19	0.69619
2364	0.302991
2366.81	0.967307
2369.62	1.38745
2372.44	1.596
2375.24	2.55528
2378.05	3.06634
2380.86	4.09253
2383.67	4.43326
2386.47	4.34321
2389.28	4.54111
2392.08	5.11198
2394.89	4.77714
2397.69	5.74355
2400.49	5.38856
2403.29	5.37614
2406.09	6.02132
2408.88	6.08968
2411.68	6.22349
2414.48	6.02207
2417.27	5.76392
2420.06	5.78877
2422.86	5.80601
2425.65	6.10782
2428.44	4.91589
2431.23	4.18626
2434.02	4.41029
2436.81	4.8562
2439.59	4.26876
2442.38	4.5631
2445.16	5.08667
2447.95	4.38253
2450.73	5.37481
2453.51	4.36623
2456.29	4.2158
2459.07	3.11897
2461.85	2.36253
2464.63	2.98642
2467.4	3.01789
2470.18	3.09445
2472.95	2.71443
2475.73	3.36762
2478.5	3.44929
2481.27	2.90512
2484.04	2.37468
2486.81	2.57369
2489.58	2.36678
2492.35	2.02576
2495.12	1.23184
2497.88	0.834538
2500.65	0.977273
2503.41	-0.149277
2506.17	-0.53238
2508.94	0.0587461
2511.7	0.291043
2514.46	0.779122
2517.22	0.480921
2519.97	0.151859
2522.73	-0.585641
2525.49	-0.601862
2528.24	-0.298999
2530.99	-0.409545
2533.75	0.340373
2536.5	0.713243
2539.25	0.754076
2542	1.71436
2544.75	2.27406
2547.5	2.7134
2550.24	3.05597
2552.99	3.55465
2555.74	4.30661
2558.48	4.0107
2561.22	4.29147
2563.96	4.20474
2566.71	4.46246
2569.45	4.37118
2572.18	5.10732
2574.92	4.9517
2577.66	5.0473
2580.4	4.80792
2583.13	4.29427
2585.87	3.46267
2588.6	3.73016
2591.33	3.96615
2594.06	4.30002
2596.79	4.21421
2599.52	5.21397
2602.25	5.61744
2604.98	5.97163
2607.71	6.2804
2610.43	6.75336
2613.16	7.50489
2615.88	7.32992
2618.6	6.65989
2621.32	6.63568
2624.04	6.46601
2626.76	5.99285
2629.48	5.18516
2632.2	5.39475
2634.92	5.54199
2637.63	6.07143
2640.35	5.55467
2643.06	6.01108
2645.77	6.16568
2648.49	4.93381
2651.2	4.91017
2653.91	5.23695
2656.62	4.66532
2659.33	5.16482
2662.03	5.45963
2664.74	5.65805
2667.44	4.93615
2670.15	4.47895
2672.85	4.52352
2675.55	4.91344
2678.26	4.94279
2680.96	4.61659
2683.66	3.83834
2686.35	3.98433
2689.05	3.89606
2691.75	4.62911
2694.44	4.71923
2697.14	5.15927
2699.83	5.65956
2702.52	6.41338
2705.22	6.22741
2707.91	6.32214
2710.6	6.82035
2713.29	6.64431
2715.97	6.62238
2718.66	7.9047
2721.35	8.47074
2724.03	9.15704
2726.72	9.78543
2729.4	10.1616
2732.08	10.138
2734.76	9.74145
2737.44	9.02749
2740.12	8.91908
2742.8	9.24175
2745.48	8.28868
2748.16	8.6359
2750.83	8.2301
2753.51	8.107
2756.18	6.9875
2758.85	6.7929
2761.53	5.98457
2764.2	4.86065
2766.87	4.14354
2769.54	3.1666
2772.2	1.32815
2774.87	1.34602
2777.54	0.988436
2780.2	0.772794
2782.87	0.715861
2785.53	0.302955
2788.19	-0.0182367
2790.85	0.143649
2793.51	0.0748991
2796.17	-0.201404
2798.83	-0.448878
2801.49	-1.36556
2804.15	-0.708611
2806.8	-1.09247
2809.46	-0.849156
2812.11	0.332376
2814.76	0.586375
2817.42	1.09281
2820.07	1.87352
2822.72	2.92469
2825.37	5.36811
2828.02	8.00558
2830.66	9.53116
2833.31	12.5597
2835.96	16.5562
2838.6	19.5751
2841.24	23.9895
2843.89	28.4135
2846.53	33.4162
2849.17	38.6625
2851.81	44.5251
2854.45	51.168
2857.09	57.3325
2859.72	62.9462
2862.36	68.7717
2865	73.531
2867.63	78.1956
2870.26	82.1415
2872.9	85.8438
2875.53	90.2384
2878.16	94.2224
2880.79	96.7594
2883.42	99.7826
2886.05	103.093
2888.67	106.375
2891.3	109.827
2893.92	113.64
2896.55	116.961
2899.17	123.32
2901.79	128.831
2904.42	136.072
2907.04	143.119
2909.66	150.871
2912.27	159.775
2914.89	169.527
2917.51	177.696
2920.13	184.551
2922.74	190.412
2925.35	194.2
2927.97	197.916
2930.58	199.653
2933.19	200.366
2935.8	199.159
2938.41	197.859
2941.02	195.993
2943.63	190.494
2946.24	184.725
2948.84	178.411
2951.45	172.334
2954.05	165.434
2956.65	158.124
2959.26	150.318
2961.86	143.316
2964.46	136.486
2967.06	130.842
2969.66	124.397
2972.25	117.724
2974.85	111.987
2977.45	106.055
2980.04	99.039
2982.64	91.0956
2985.23	82.7644
2987.82	74.8248
2990.41	67.2105
2993	59.5374
2995.59	51.7107
2998.18	45.3689
3000.77	39.3202
3003.36	34.2079
3005.94	28.3402
3008.53	23.4832
3011.11	19.8289
3013.69	15.6343
3016.28	12.166
3018.86	9.13623
3021.44	7.01831
3024.02	6.25658
3026.6	5.26333
3029.18	5.22332
3031.75	5.35171
3034.33	5.99363
3036.9	7.74946
3039.48	9.08814
3042.05	8.72998
3044.62	10.1537
3047.19	10.182
3049.77	10.4231
3052.34	9.63318
3054.9	9.61969
3057.47	10.0018
3060.04	10.5711
3062.61	9.90711
3065.17	8.91731
3067.74	8.24138
3070.3	6.93637
3072.86	5.7179
3075.42	4.06645
3077.99	3.10532
3080.54	2.49211
3083.1	1.78378
3085.66	2.00274
3088.22	1.61141
3090.78	0.783385
3093.33	0.33618
3095.89	0.774902
3098.44	1.09427
3100.99	1.64652
3103.54	1.83488
3106.1	2.47936
3108.65	3.67355
3111.2	4.01129
3113.74	5.52652
3116.29	7.28253
3118.84	10.167
3121.38	11.2298
3123.93	11.8495
3126.47	12.8242
3129.01	14.5286
3131.56	16.1272
3134.1	17.4681
3136.64	19.2549
3139.18	21.4422
3141.72	22.2847
3144.26	22.8327
3146.79	22.1899
3149.33	19.726