File: data/Raman/poly_smoothed/Thy_20_09_35_1x_45s_532 nm_x100_100%_600 gr_mm_01.txt
#Acq. time (s)=	45
#Accumulations=	2
#Range (cm-¹)=	200...3150
#Windows=	2
#Auto scanning=	Off
#Autofocus=	Off
#Macrospot=	Off
#AutoExposure=	Off
#Spike filter=	Multiple accum.
#Delay time (s)=	0
#Binning=	1
#Readout mode=	Signal
#DeNoise=	Off
#ICS correction=	On
#Dark correction=	Off
#Inst. Process=	Off
#Detector Gain=	Best Dynamic Range
#Detector ADC=	20 kHz
#Detector temperature (°C)=	-69.85
#Instrument=	LabRAM HR Evol
#Detector=	Synapse
#Objective=	x100
#Grating=	600 gr/mm
#ND Filter=	100%
#Laser (nm)=	532
#Hole=	100.021
#Range=	Auto
#Laser Pol.=	No
#Raman. Pol.=	No
#Laser Pol. (°)=	-0.0007625
#Raman Pol. (°)=	89.9995
#Collection=	Microscope
#StageXY=	Marzhauser
#StageZ=	Marzhauser
#X (µm)=	-5923.2
#Y (µm)=	2872.6
#Z (µm)=	-223.35
#Full time(mm:ss)=	3:18
#Project=
#Sample=
#Site=
#Title=	Thy_20_09_35_2x_45s_532 nm_x100_100%_600 gr_mm
#Remark=
#Date=	29.06.2022 13:06
#Acquired=	29.06.2022 13:06:09
#Base:Fit=	10.08.2022 09:52:02
#Base:Fit=	10.08.2022 09:52:12
#Base:Sub=	10.08.2022 09:54:21
#Filter:Polynom=	16.08.2022 10:24:04
#AxisType[0]=Intens
#AxisUnit[0]=Cnt
#AxisType[1]=Spectr
#AxisUnit[1]=1/cm
200.523	4.03877
204.154	5.68765
207.781	3.72397
211.409	2.48935
215.034	1.86765
218.659	2.85469
222.281	2.6818
225.903	3.44358
229.522	4.99822
233.14	4.35635
236.756	4.42935
240.373	5.21536
243.986	4.84077
247.598	4.75429
251.208	4.91279
254.818	4.75905
258.427	2.75556
262.034	3.43487
265.638	4.19098
269.242	3.90969
272.844	4.29781
276.445	3.82624
280.044	4.07312
283.642	4.95421
287.238	4.80073
290.833	4.73425
294.425	5.96694
298.017	9.02216
301.608	10.9018
305.198	13.0386
308.786	16.6736
312.371	17.7674
315.956	18.6021
319.54	19.6317
323.122	21.612
326.701	21.2677
330.281	21.9928
333.857	22.4025
337.434	24.1624
341.008	23.9334
344.582	24.4295
348.153	24.2325
351.724	23.7041
355.292	22.3361
358.861	21.44
362.426	19.9682
365.99	18.8274
369.555	17.6614
373.116	15.798
376.676	15.6335
380.236	15.2427
383.793	15.3221
387.349	15.2323
390.903	15.5814
394.456	14.3555
398.007	14.0443
401.56	11.8124
405.108	13.0268
408.656	12.3403
412.202	12.0288
415.746	13.5764
419.29	15.7982
422.831	17.0362
426.37	17.5496
429.909	18.1948
433.447	17.1786
436.983	17.0426
440.519	16.5013
444.052	15.5436
447.583	13.897
451.114	13.5525
454.643	13.5783
458.169	15.0815
461.696	16.2643
465.222	17.842
468.744	18.9311
472.267	19.345
475.787	18.4521
479.307	19.9399
482.823	22.0859
486.341	24.4146
489.855	25.9054
493.37	27.2101
496.881	28.5927
500.391	30.7293
503.902	31.6404
507.409	32.8122
510.915	31.5896
514.42	30.5772
517.925	30.523
521.427	28.1235
524.928	26.7156
528.427	25.0128
531.925	23.4095
535.422	23.3196
538.917	22.3922
542.411	22.2577
545.903	20.3481
549.395	17.5997
552.884	14.5886
556.373	13.0519
559.86	11.5586
563.346	11.606
566.831	11.0023
570.314	11.2541
573.794	9.06823
577.274	7.16073
580.754	5.91257
584.23	3.66284
587.706	3.48212
591.181	2.97957
594.653	2.82404
598.126	3.20068
601.595	3.93979
605.065	5.64581
608.532	6.73872
611.999	7.87481
615.463	10.3365
618.928	12.3951
622.389	12.9749
625.851	14.2256
629.31	16.9103
632.767	18.6924
636.223	20.584
639.68	23.222
643.134	23.8292
646.586	23.7165
650.037	23.6331
653.486	23.6737
656.936	22.9762
660.383	21.1774
663.829	20.6617
667.273	19.8556
670.716	19.2509
674.158	18.2856
677.598	17.8557
681.035	18.2806
684.473	17.9734
687.909	18.0363
691.344	17.9703
694.778	19.0486
698.211	18.9662
701.64	20.4394
705.07	21.7493
708.498	23.1896
711.924	27.6909
715.35	30.6394
718.774	32.3445
722.196	34.3934
725.618	34.8339
729.037	37.159
732.456	39.0808
735.873	41.0278
739.289	42.3135
742.703	43.2098
746.116	44.8203
749.529	46.2411
752.938	48.3096
756.347	49.8881
759.756	52.1069
763.162	55.6812
766.567	57.7999
769.97	57.7375
773.372	58.487
776.773	58.1449
780.174	58.9272
783.573	59.1298
786.97	60.5378
790.365	62.2771
793.76	63.5458
797.153	63.9524
800.543	63.7704
803.933	64.2477
807.322	62.2515
810.71	63.5838
814.097	65.246
817.483	66.1236
820.865	65.4085
824.248	65.8998
827.629	65.1572
831.008	64.2647
834.387	62.5506
837.765	62.8623
841.139	62.2367
844.514	60.1214
847.886	59.269
851.259	55.9835
854.629	53.1522
857.997	50.0463
861.366	50.0771
864.732	47.7932
868.098	46.4483
871.461	45.0189
874.823	41.9582
878.184	40.232
881.545	38.108
884.903	37.091
888.26	36.8107
891.616	36.513
894.97	36.385
898.323	36.8208
901.675	36.6018
905.026	36.3722
908.375	35.4061
911.723	34.111
915.07	33.6013
918.415	32.4615
921.76	31.2385
925.103	30.1754
928.443	29.4491
931.783	30.2666
935.123	31.5205
938.461	31.4836
941.796	31.2765
945.131	29.0524
948.465	27.9052
951.797	28.1491
955.128	26.5125
958.457	25.3223
961.786	23.5037
965.113	23.9035
968.44	24.1991
971.763	24.9828
975.086	25.919
978.409	26.8677
981.729	28.9311
985.048	29.798
988.367	28.9575
991.683	29.0169
994.998	27.9345
998.312	27.3457
1001.62	26.1273
1004.94	26.1516
1008.25	25.6073
1011.56	25.279
1014.86	26.7922
1018.17	25.0859
1021.48	22.1171
1024.78	20.1329
1028.08	18.1565
1031.38	17.4143
1034.68	16.2974
1037.98	14.2562
1041.28	12.3616
1044.57	13.1093
1047.87	13.2954
1051.16	13.2571
1054.45	13.7929
1057.75	12.4281
1061.04	13.181
1064.32	12.4213
1067.61	11.9823
1070.9	12.5769
1074.18	11.8451
1077.47	11.8201
1080.75	12.3757
1084.03	11.8505
1087.31	12.7845
1090.59	13.6815
1093.86	14.6247
1097.14	15.5248
1100.41	15.6969
1103.69	16.2555
1106.96	16.5277
1110.23	16.1356
1113.5	15.0471
1116.77	14.4138
1120.03	13.8395
1123.3	12.3214
1126.56	11.5833
1129.83	10.2628
1133.09	9.65719
1136.35	8.79791
1139.61	6.91052
1142.86	6.83117
1146.12	6.11713
1149.38	4.86851
1152.63	3.11637
1155.88	1.73658
1159.14	2.78187
1162.39	0.381048
1165.63	1.02154
1168.88	2.6425
1172.13	4.6233
1175.38	7.61776
1178.62	8.33225
1181.86	9.12704
1185.1	10.1134
1188.34	9.93814
1191.58	10.8335
1194.82	12.7023
1198.06	13.6939
1201.29	15.0706
1204.53	16.3005
1207.76	18.4946
1210.99	21.0366
1214.22	25.106
1217.45	28.039
1220.68	31.7999
1223.91	36.1623
1227.13	37.9707
1230.36	41.7237
1233.58	46.4429
1236.8	50.0672
1240.02	51.6948
1243.24	54.454
1246.46	57.392
1249.67	59.3285
1252.89	60.9091
1256.1	61.6649
1259.32	63.48
1262.53	65.5287
1265.74	65.676
1268.95	66.1227
1272.15	68.0665
1275.36	69.4022
1278.57	70.0865
1281.77	70.7911
1284.97	72.033
1288.18	76.1307
1291.38	77.9907
1294.58	79.1732
1297.78	80.7167
1300.97	82.9445
1304.17	85.0916
1307.36	87.6763
1310.55	90.0774
1313.75	91.7159
1316.94	92.3387
1320.13	90.2806
1323.32	89.2944
1326.5	88.4936
1329.69	88.443
1332.87	87.3825
1336.06	86.8259
1339.24	85.3646
1342.42	83.1573
1345.6	80.1413
1348.78	77.1357
1351.96	74.4029
1355.13	72.3947
1358.31	68.7696
1361.48	66.5598
1364.65	65.2228
1367.82	63.3351
1370.99	60.8159
1374.16	59.1605
1377.33	58.8435
1380.5	58.6863
1383.66	58.8224
1386.83	57.2749
1389.99	56.9306
1393.15	55.1451
1396.31	52.8931
1399.47	51.4631
1402.63	51.3822
1405.78	52.0234
1408.94	52.2246
1412.1	53.2663
1415.25	55.2935
1418.4	57.1417
1421.55	60.0441
1424.7	63.5617
1427.85	67.3655
1431	72.5157
1434.14	77.6926
1437.29	82.9789
1440.43	85.7444
1443.57	88.9263
1446.71	89.0811
1449.85	89.5449
1452.99	89.424
1456.13	87.2661
1459.26	84.7565
1462.4	81.0691
1465.54	75.7864
1468.67	71.1637
1471.8	64.7563
1474.93	57.1421
1478.06	50.9891
1481.19	44.0566
1484.31	38.1183
1487.44	33.1979
1490.56	28.969
1493.69	26.6985
1496.81	25.2926
1499.93	23.464
1503.05	22.6284
1506.17	23.2477
1509.28	24.8926
1512.4	25.5457
1515.52	26.3142
1518.63	27.302
1521.74	29.0962
1524.85	31.0989
1527.96	34.5019
1531.07	35.8682
1534.18	39.0379
1537.29	42.6973
1540.39	46.3053
1543.5	48.8599
1546.6	51.7964
1549.7	53.6151
1552.8	56.1911
1555.9	59.0485
1559	63.0441
1562.1	66.7344
1565.19	69.5116
1568.29	72.2637
1571.38	76.516
1574.47	78.2289
1577.56	80.3441
1580.66	82.2759
1583.74	84.8756
1586.83	86.8248
1589.92	87.0412
1593.01	88.6754
1596.09	89.7024
1599.17	89.325
1602.25	88.7358
1605.34	87.9097
1608.41	86.5059
1611.49	85.6902
1614.57	84.2656
1617.65	82.2694
1620.72	81.8769
1623.79	80.8131
1626.87	81.5057
1629.94	82.0575
1633.01	82.5788
1636.08	83.0267
1639.15	82.4173
1642.21	84.4003
1645.28	85.6351
1648.34	86.9772
1651.41	87.3334
1654.47	87.3653
1657.53	88.1388
1660.59	88.4525
1663.65	87.2979
1666.71	85.8842
1669.76	84.1016
1672.82	79.5476
1675.87	76.4108
1678.93	71.4618
1681.98	65.0825
1685.03	59.5913
1688.08	53.3018
1691.13	47.4763
1694.17	43.2629
1697.22	38.5492
1700.27	33.7432
1703.31	29.9697
1706.35	25.1694
1709.39	21.2144
1712.43	18.5055
1715.47	17.1468
1718.51	15.4577
1721.55	13.1047
1724.58	12.5148
1727.62	11.1819
1730.65	10.7693
1733.68	11.5377
1736.72	11.0087
1739.74	10.2613
1742.77	9.59563
1745.8	8.9079
1748.83	8.11464
1751.85	7.81432
1754.88	6.21698
1757.9	5.10489
1760.92	3.4634
1763.95	3.2976
1766.96	2.78505
1769.98	2.46436
1773	2.72692
1776.02	1.58875
1779.03	1.79643
1782.05	0.972342
1785.06	0.197489
1788.07	1.11553
1791.08	0.741178
1794.09	1.01104
1797.1	1.64699
1800.11	1.84783
1803.12	2.30127
1806.12	2.44675
1809.12	3.26528
1812.13	2.95512
1815.13	3.72415
1818.13	3.32548
1821.13	3.06201
1824.13	3.65142
1827.13	3.3055
1830.12	2.25774
1833.12	2.06079
1836.11	2.42722
1839.1	3.10028
1842.09	3.39714
1845.09	3.5943
1848.08	3.99183
1851.06	4.54177
1854.05	5.1066
1857.04	4.79315
1860.02	5.04679
1863.01	4.55816
1865.99	4.89605
1868.97	5.29722
1871.95	5.18563
1874.93	5.35912
1877.91	5.30266
1880.89	5.33981
1882.46	5.42107
1885.45	5.99016
1888.43	5.14724
1891.42	5.04263
1894.41	5.79832
1897.39	5.91876
1900.37	6.20747
1903.36	6.23565
1906.34	6.97888
1909.32	6.99512
1912.29	6.74884
1915.27	7.42909
1918.25	7.38248
1921.23	6.91974
1924.2	6.22684
1927.17	5.54467
1930.15	4.67755
1933.12	4.34867
1936.09	3.30026
1939.06	2.60578
1942.02	1.71956
1944.99	1.23268
1947.96	1.61584
1950.92	1.82232
1953.88	2.31211
1956.85	2.77457
1959.81	2.84117
1962.77	2.01096
1965.73	2.50388
1968.69	3.02232
1971.64	3.46957
1974.6	3.59977
1977.55	4.36159
1980.51	4.28018
1983.46	4.2126
1986.41	4.36228
1989.36	4.26392
1992.31	3.50167
1995.26	3.99059
1998.21	4.84326
2001.15	4.97445
2004.1	6.17951
2007.04	6.51928
2009.99	7.36451
2012.93	7.44642
2015.87	8.59952
2018.81	9.40581
2021.75	9.49977
2024.68	9.95431
2027.62	10.7412
2030.56	10.3884
2033.49	9.38022
2036.42	9.6314
2039.36	9.67449
2042.29	9.20608
2045.22	9.23408
2048.14	9.12025
2051.07	8.70801
2054	8.09371
2056.93	7.33598
2059.85	7.9135
2062.77	7.37472
2065.7	8.65409
2068.62	10.2449
2071.54	11.2218
2074.46	11.6931
2077.38	12.5202
2080.29	12.9409
2083.21	13.57
2086.12	14.579
2089.04	15.3269
2091.95	16.3801
2094.86	16.4171
2097.77	17.5403
2100.68	17.9594
2103.59	18.2129
2106.5	19.159
2109.41	19.9155
2112.31	19.6327
2115.21	20.3088
2118.12	20.9911
2121.02	22.0769
2123.92	23.5728
2126.82	24.4727
2129.72	25.7422
2132.62	26.4196
2135.51	28.4224
2138.41	31.2905
2141.31	33.1397
2144.2	35.179
2147.09	36.5025
2149.98	39.4809
2152.87	41.058
2155.76	43.8163
2158.65	45.1755
2161.54	46.5361
2164.43	47.9724
2167.31	48.3346
2170.2	49.9169
2173.08	49.3933
2175.96	49.9377
2178.84	49.0756
2181.72	48.5419
2184.6	47.9816
2187.48	46.7236
2190.36	46.5696
2193.23	45.2033
2196.11	42.4035
2198.98	40.2045
2201.85	37.9313
2204.72	36.1945
2207.59	34.6376
2210.46	32.1939
2213.33	30.7922
2216.2	29.3832
2219.07	27.6914
2221.93	26.5001
2224.8	25.6082
2227.66	25.677
2230.52	24.6322
2233.39	24.54
2236.25	24.155
2239.1	22.7325
2241.96	21.8318
2244.82	21.2334
2247.68	19.8966
2250.53	19.0851
2253.38	19.0129
2256.24	18.819
2259.09	18.0476
2261.94	16.5641
2264.79	15.3649
2267.64	14.5355
2270.49	12.446
2273.33	12.1174
2276.18	11.1081
2279.02	10.0137
2281.87	9.84594
2284.71	9.96795
2287.55	10.4132
2290.39	9.93738
2293.23	8.52407
2296.07	8.95277
2298.91	9.59932
2301.74	10.6436
2304.58	11.5577
2307.41	11.2427
2310.25	11.0809
2313.08	11.3775
2315.91	11.9127
2318.74	12.2978
2321.57	12.5476
2324.4	13.2018
2327.23	13.1767
2330.05	12.9207
2332.88	12.4748
2335.7	11.9969
2338.52	11.4198
2341.35	10.796
2344.17	9.18416
2346.99	8.49659
2349.81	7.48763
2352.62	6.75107
2355.44	5.80692
2358.26	4.66318
2361.07	2.96096
2363.89	3.41829
2366.7	4.0939
2369.51	4.57269
2372.32	3.82443
2375.13	4.19197
2377.94	3.86156
2380.75	3.89633
2383.56	3.71616
2386.36	4.25869
2389.17	4.16677
2391.97	4.1938
2394.77	4.98727
2397.58	4.96961
2400.38	5.37479
2403.18	5.04107
2405.97	5.19858
2408.77	3.67765
2411.57	1.92433
2414.37	1.27281
2417.16	1.71432
2419.95	2.26693
2422.75	2.32958
2425.54	3.16832
2428.33	3.15249
2431.12	3.84012
2433.91	4.15863
2436.7	3.90333
2439.48	4.62408
2442.27	4.41979
2445.05	4.66322
2447.84	4.16563
2450.62	3.69309
2453.4	3.16156
2456.18	3.46635
2458.96	2.87654
2461.74	3.71306
2464.52	3.96997
2467.29	3.63955
2470.07	3.61461
2472.85	2.80118
2475.62	1.6891
2478.39	0.845668
2481.16	1.25647
2483.93	2.29073
2486.7	2.34151
2489.47	2.85275
2492.24	3.09481
2495.01	2.69514
2497.77	2.81147
2500.54	2.13955
2503.3	1.24136
2506.06	1.48472
2508.83	1.25636
2511.59	1.45312
2514.35	0.381003
2517.11	-0.0228535
2519.86	-0.118062
2522.62	0.295362
2525.38	0.736268
2528.13	0.428734
2530.89	1.58005
2533.64	1.24865
2536.39	1.05571
2539.14	0.818084
2541.89	1.4119
2544.64	1.60871
2547.39	2.32784
2550.14	2.60812
2552.88	2.38873
2555.63	2.30788
2558.37	2.16539
2561.11	1.35835
2563.86	1.46058
2566.6	1.44567
2569.34	0.740437
2572.08	1.45976
2574.82	1.7986
2577.55	1.36568
2580.29	2.22576
2583.02	1.6688
2585.76	2.10445
2588.49	1.69792
2591.22	1.52512
2593.96	1.44468
2596.69	1.51237
2599.42	1.86332
2602.14	1.35718
2604.87	1.2015
2607.6	1.58814
2610.32	1.52114
2613.05	1.49223
2615.77	1.40357
2618.49	0.399841
2621.22	0.996585
2623.94	1.09152
2626.66	1.51844
2629.37	0.95963
2632.09	1.54937
2634.81	1.58835
2637.53	2.41896
2640.24	2.8811
2642.96	3.01927
2645.67	3.50602
2648.38	4.11813
2651.09	3.74302
2653.8	3.76844
2656.51	3.47142
2659.22	3.59623
2661.93	4.10379
2664.63	3.912
2667.34	3.92546
2670.04	3.79158
2672.75	3.77606
2675.45	4.02516
2678.15	3.21318
2680.85	2.94395
2683.55	4.03599
2686.25	4.01403
2688.94	4.43411
2691.64	5.84606
2694.34	6.14888
2697.03	6.17969
2699.73	6.95655
2702.42	8.31935
2705.11	9.21116
2707.8	9.78143
2710.49	10.3676
2713.18	11.1606
2715.87	10.9137
2718.55	11.0579
2721.24	10.9314
2723.93	10.3221
2726.61	9.9772
2729.29	9.75187
2731.98	8.72051
2734.66	9.71808
2737.34	8.48263
2740.02	8.2687
2742.7	7.42109
2745.37	6.79367
2748.05	6.96654
2750.72	6.68317
2753.4	5.89229
2756.07	6.48615
2758.75	6.11539
2761.42	5.03576
2764.09	5.20211
2766.76	4.87492
2769.43	4.37892
2772.1	3.85331
2774.76	3.70082
2777.43	2.84307
2780.1	2.35788
2782.76	1.69708
2785.42	0.87802
2788.09	-0.0211712
2790.75	-0.532936
2793.41	-1.02244
2796.07	-0.421697
2798.73	-0.462371
2801.39	-0.66709
2804.04	-0.742677
2806.7	0.645791
2809.35	0.098855
2812.01	0.199102
2814.66	0.693097
2817.31	1.95621
2819.96	2.17272
2822.61	4.4675
2825.26	6.75244
2827.91	10.6881
2830.56	13.7187
2833.21	17.681
2835.85	21.8623
2838.5	26.7962
2841.14	31.8154
2843.78	38.4219
2846.42	46.0754
2849.06	53.2863
2851.71	61.3844
2854.34	70.0311
2856.98	78.3585
2859.62	86.9339
2862.26	95.561
2864.89	102.676
2867.53	110.317
2870.16	116.576
2872.79	122.246
2875.42	128.002
2878.05	131.877
2880.68	135.968
2883.31	140.527
2885.94	145.316
2888.57	151.003
2891.19	156.707
2893.82	161.574
2896.44	167.176
2899.07	172.736
2901.69	180.496
2904.31	188.257
2906.93	198.939
2909.55	209.926
2912.17	221.007
2914.79	233.137
2917.41	243.804
2920.02	252.92
2922.64	260.397
2925.25	266.913
2927.86	271.623
2930.48	272.863
2933.09	272.147
2935.7	270.083
2938.31	265.14
2940.92	258.579
2943.53	250.653
2946.13	242.095
2948.74	233.452
2951.34	223.981
2953.95	214.068
2956.55	203.323
2959.15	192.909
2961.75	183.234
2964.35	174.736
2966.95	166.222
2969.55	158.899
2972.15	151.393
2974.75	144.713
2977.34	138.111
2979.94	130.027
2982.53	121.957
2985.13	113.201
2987.72	105.369
2990.31	96.6374
2992.9	87.0303
2995.49	77.2348
2998.08	68.6292
3000.67	59.9314
3003.25	51.8188
3005.84	44.7791
3008.42	38.289
3011.01	32.492
3013.59	27.8123
3016.17	24.2687
3018.76	20.405
3021.34	17.779
3023.92	15.3139
3026.49	14.8128
3029.07	14.0853
3031.65	14.0914
3034.23	14.6951
3036.8	15.5443
3039.38	17.2893
3041.95	18.9207
3044.52	20.3359
3047.09	21.6135
3049.66	22.9387
3052.23	24.2889
3054.8	24.0172
3057.37	24.7591
3059.94	23.872
3062.5	23.4837
3065.07	22.9127
3067.63	21.9254
3070.2	20.9921
3072.76	19.0406
3075.32	17.6557
3077.88	16.0677
3080.44	13.6285
3083	10.4544
3085.56	8.46066
3088.12	6.59199
3090.67	4.72173
3093.23	4.17143
3095.78	3.6697
3098.34	2.92526
3100.89	2.8555
3103.44	2.52255
3105.99	3.2844
3108.54	3.21191
3111.09	3.76961
3113.64	4.45328
3116.19	3.9449
3118.74	4.73857
3121.28	6.43098
3123.83	6.85469
3126.37	8.1867
3128.91	9.6254
3131.46	11.0219
3134	12.5404
3136.54	14.2954
3139.08	15.5041
3141.62	16.7975
3144.16	18.4795
3146.69	21.6766
3149.23	26.3473