File: data/Raman/poly_smoothed/Thy_10_08_30_1x_45s_532 nm_x100_100%_600 gr_mm_01.txt
#Acq. time (s)=	45
#Accumulations=	2
#Range (cm-¹)=	200...3150
#Windows=	2
#Auto scanning=	Off
#Autofocus=	Off
#Macrospot=	Off
#AutoExposure=	Off
#Spike filter=	Multiple accum.
#Delay time (s)=	0
#Binning=	1
#Readout mode=	Signal
#DeNoise=	Off
#ICS correction=	On
#Dark correction=	Off
#Inst. Process=	Off
#Detector Gain=	Best Dynamic Range
#Detector ADC=	20 kHz
#Detector temperature (°C)=	-69.85
#Instrument=	LabRAM HR Evol
#Detector=	Synapse
#Objective=	x100
#Grating=	600 gr/mm
#ND Filter=	100%
#Laser (nm)=	532
#Hole=	100.021
#Range=	Auto
#Laser Pol.=	No
#Raman. Pol.=	No
#Laser Pol. (°)=	-0.0007625
#Raman Pol. (°)=	89.9995
#Collection=	Microscope
#StageXY=	Marzhauser
#StageZ=	Marzhauser
#X (µm)=	2194.9
#Y (µm)=	1215.9
#Z (µm)=	443.25
#Full time(mm:ss)=	3:18
#Project=
#Sample=
#Site=
#Title=	Thy_10_08_30_2x_45s_532 nm_x100_100%_600 gr_mm
#Remark=
#Date=	05.07.2022 16:22
#Acquired=	05.07.2022 16:22:57
#Base:Fit=	10.08.2022 09:46:25
#Base:Sub=	10.08.2022 09:46:49
#Filter:Polynom=	16.08.2022 10:24:56
#AxisType[0]=Intens
#AxisUnit[0]=Cnt
#AxisType[1]=Spectr
#AxisUnit[1]=1/cm
200.43	0.805676
204.059	1.85583
207.688	1.0351
211.314	0.768331
214.941	1.21799
218.564	2.7022
222.186	2.17104
225.809	3.22804
229.428	5.72582
233.045	5.25092
236.663	5.60598
240.278	6.39418
243.891	7.31396
247.503	7.59982
251.116	8.0623
254.725	9.0704
258.333	9.72389
261.939	10.2649
265.544	10.6554
269.148	11.1745
272.75	11.6178
276.351	12.3274
279.95	13.168
283.548	15.3754
287.144	14.5495
290.739	14.3749
294.333	14.3999
297.925	15.8358
301.514	17.8518
305.104	20.3131
308.692	20.5974
312.279	21.2266
315.862	22.4701
319.446	22.5872
323.029	22.6625
326.608	22.6904
330.188	22.4304
333.766	22.8866
337.341	23.2026
340.917	22.6152
344.489	23.1613
348.062	21.4441
351.631	20.3893
355.201	18.5774
358.768	17.4302
362.333	17.478
365.899	18.0163
369.462	16.1664
373.023	13.9334
376.585	12.5391
380.143	12.6253
383.7	11.2774
387.256	12.0857
390.812	12.0879
394.365	10.4445
397.916	9.41969
401.467	10.4378
405.015	10.2287
408.563	10.198
412.109	10.0273
415.654	9.37159
419.197	9.99824
422.739	10.5891
426.279	9.9821
429.819	8.91985
433.356	9.10284
436.891	7.77408
440.426	8.29183
443.96	9.72305
447.492	11.4382
451.021	11.162
454.551	10.8582
458.079	10.7476
461.604	11.412
465.13	13.3459
468.654	13.5041
472.175	12.6289
475.696	14.5627
479.215	14.1192
482.733	15.5552
486.249	16.1908
489.765	17.7614
493.278	17.0061
496.789	17.7756
500.301	18.0368
503.81	19.1093
507.317	19.6122
510.825	20.3985
514.33	19.3662
517.833	18.4906
521.335	17.4507
524.836	17.9353
528.335	17.6563
531.835	16.1337
535.332	14.5962
538.827	13.0804
542.321	11.6249
545.814	11.0401
549.305	9.66617
552.795	7.87666
556.282	5.88206
559.769	4.89225
563.255	4.39946
566.739	4.6525
570.223	4.00218
573.705	3.18084
577.183	3.36209
580.663	2.88284
584.141	4.54258
587.615	4.29933
591.09	4.42988
594.564	3.41205
598.035	3.6525
601.506	4.20957
604.974	3.68979
608.443	5.0532
611.908	7.22634
615.374	7.90538
618.837	8.88703
622.3	11.3719
625.761	13.3506
629.219	14.0446
632.677	15.4604
636.135	15.4776
639.59	17.7315
643.043	19.6668
646.495	20.6647
649.948	21.1051
653.398	20.5814
656.846	21.2016
660.293	21.1871
663.738	20.6923
667.183	20.6892
670.626	18.4401
674.067	17.9294
677.508	18.4257
680.947	18.4602
684.385	18.9445
687.821	20.1113
691.254	20.7595
694.688	23.1067
698.121	25.1002
701.552	25.7656
704.98	28.1823
708.409	30.5061
711.836	31.0635
715.26	31.6962
718.685	32.565
722.108	34.5291
725.528	37.076
728.949	38.8515
732.367	39.3964
735.785	41.5945
739.2	44.2319
742.614	46.113
746.028	48.0134
749.439	49.9982
752.849	51.3653
756.26	54.5195
759.667	58.19
763.073	60.6538
766.477	63.8873
769.883	65.8272
773.285	67.4732
776.686	69.9794
780.085	71.2144
783.484	73.2412
786.881	75.6174
790.276	77.9667
793.671	78.6699
797.064	79.0266
800.456	80.8143
803.846	81.4231
807.234	82.4004
810.622	82.7893
814.008	82.1882
817.394	81.7353
820.778	82.4391
824.159	82.3758
827.541	81.4614
830.921	80.0888
834.298	79.4183
837.676	76.3905
841.051	74.7874
844.426	70.7791
847.798	68.0626
851.171	64.967
854.54	63.0636
857.911	61.0103
861.278	57.5398
864.645	54.8581
868.01	52.9529
871.373	50.9497
874.735	49.0631
878.097	47.7718
881.457	48.3561
884.815	48.1121
888.172	47.8252
891.528	47.2367
894.882	48.0123
898.237	48.2406
901.589	48.4304
904.94	48.1426
908.289	49.6667
911.635	49.9355
914.982	49.4609
918.328	48.9424
921.672	47.918
925.015	47.1979
928.357	45.5093
931.698	44.3318
935.035	42.4752
938.373	41.4774
941.71	39.4216
945.044	36.7853
948.378	36.2871
951.709	35.7594
955.041	34.3892
958.372	31.4891
961.699	29.6755
965.027	28.2321
968.352	27.8395
971.676	28.3434
975	29.6918
978.322	29.2698
981.642	29.1159
984.962	29.6761
988.28	30.2453
991.596	30.5285
994.911	28.7466
998.227	28.7712
1001.54	28.4856
1004.85	27.7564
1008.16	26.8794
1011.47	24.9188
1014.78	25.1097
1018.08	24.3598
1021.39	23.3533
1024.69	21.2064
1028	19.6021
1031.3	17.6875
1034.6	15.705
1037.9	12.3815
1041.19	12.4488
1044.49	13.7578
1047.78	13.251
1051.08	14.7239
1054.37	14.8124
1057.66	14.3791
1060.95	14.3375
1064.24	12.4745
1067.53	11.1525
1070.81	10.5042
1074.1	9.762
1077.38	9.02079
1080.66	9.35415
1083.94	9.29269
1087.22	10.058
1090.5	9.70023
1093.78	8.90021
1097.05	8.71103
1100.33	7.34595
1103.6	7.18051
1106.87	7.30739
1110.14	7.08748
1113.41	7.39184
1116.68	6.62458
1119.95	6.99031
1123.21	7.74995
1126.48	6.63841
1129.74	6.83913
1133	5.61039
1136.26	6.36723
1139.52	5.32586
1142.78	4.02518
1146.04	3.21099
1149.29	3.25181
1152.55	3.4551
1155.8	3.22465
1159.05	2.5716
1162.3	2.93297
1165.55	2.35208
1168.8	1.89874
1172.05	2.2944
1175.29	2.33408
1178.54	2.00425
1181.78	3.20111
1185.02	4.05765
1188.26	4.6695
1191.5	5.75334
1194.74	6.37609
1197.97	6.43509
1201.21	7.75687
1204.44	9.08278
1207.68	11.144
1210.91	12.7751
1214.14	15.1246
1217.37	18.3846
1220.59	18.8663
1223.82	21.1135
1227.05	23.743
1230.27	25.0399
1233.49	25.8626
1236.72	26.7646
1239.94	27.8281
1243.16	30.6262
1246.37	32.4738
1249.59	33.6756
1252.8	33.6379
1256.02	33.1724
1259.23	34.6215
1262.44	34.7556
1265.66	34.9491
1268.86	33.2951
1272.07	31.6698
1275.28	29.6022
1278.48	30.0527
1281.69	30.1817
1284.89	31.8036
1288.09	31.5039
1291.29	32.3327
1294.49	34.74
1297.69	34.5933
1300.89	33.812
1304.08	36.7041
1307.28	38.8455
1310.47	39.5022
1313.66	42.1963
1316.85	44.8578
1320.04	46.4569
1323.23	47.1189
1326.42	49.0413
1329.61	46.4602
1332.79	46.8483
1335.97	47.3058
1339.16	47.0853
1342.34	45.5849
1345.52	43.5646
1348.7	41.9276
1351.87	40.2087
1355.05	39.2861
1358.22	38.0059
1361.4	36.6777
1364.57	35.6608
1367.74	33.0176
1370.91	32.4493
1374.08	30.2472
1377.25	27.9122
1380.41	27.8026
1383.58	27.7579
1386.74	25.5184
1389.91	25.0257
1393.07	23.5063
1396.23	23.4475
1399.39	22.1333
1402.55	22.7897
1405.7	22.2312
1408.86	22.343
1412.01	25.969
1415.17	26.0352
1418.32	27.5057
1421.47	29.984
1424.62	33.8531
1427.77	36.9646
1430.91	40.5698
1434.06	43.8702
1437.2	47.1196
1440.35	50.5302
1443.49	51.3179
1446.63	53.0137
1449.77	53.7417
1452.91	54.1263
1456.05	54.0084
1459.18	52.228
1462.32	49.7789
1465.45	46.9345
1468.59	43.8097
1471.72	39.7488
1474.85	35.9995
1477.98	31.8447
1481.1	28.5029
1484.23	23.7788
1487.36	21.3987
1490.48	17.4167
1493.61	14.8026
1496.73	14.1039
1499.85	14.1752
1502.97	14.7287
1506.09	15.3963
1509.2	15.3749
1512.32	14.2312
1515.43	14.9248
1518.55	16.511
1521.66	16.8411
1524.77	18.784
1527.88	19.3194
1530.99	19.5842
1534.1	20.5469
1537.21	21.6364
1540.31	22.345
1543.42	23.1591
1546.52	23.6175
1549.62	25.3038
1552.72	27.6637
1555.82	28.8989
1558.92	29.4718
1562.02	31.5221
1565.11	33.6928
1568.21	35.6116
1571.3	38.4761
1574.39	40.9629
1577.49	43.4753
1580.57	45.4203
1583.66	48.0553
1586.75	49.1889
1589.84	50.6527
1592.92	50.986
1596.01	51.8656
1599.09	51.4468
1602.17	49.8131
1605.25	47.9356
1608.33	46.4475
1611.41	45.6951
1614.49	43.1009
1617.57	41.6913
1620.64	40.0604
1623.72	38.9252
1626.79	39.0621
1629.86	38.8081
1632.93	38.9606
1636	40.5768
1639.07	42.7507
1642.13	44.2122
1645.2	46.845
1648.26	48.992
1651.33	51.1474
1654.39	52.5621
1657.45	54.167
1660.51	55.07
1663.57	55.2136
1666.63	54.2027
1669.68	52.2154
1672.74	50.4125
1675.79	48.0622
1678.85	44.798
1681.9	41.8686
1684.95	38.9548
1688	35.7503
1691.05	31.4854
1694.09	28.0965
1697.14	26.3086
1700.18	22.9383
1703.23	21.4564
1706.27	19.4639
1709.31	17.4449
1712.35	17.111
1715.39	14.1072
1718.43	12.9735
1721.47	11.972
1724.5	11.3921
1727.54	10.4338
1730.57	9.91745
1733.61	9.94247
1736.64	9.97166
1739.67	9.37935
1742.7	8.89827
1745.72	8.44444
1748.75	7.3912
1751.77	7.48885
1754.8	8.28987
1757.82	8.36729
1760.84	8.23729
1763.87	8.29938
1766.89	8.07767
1769.91	8.05904
1772.92	8.38413
1775.94	7.58243
1778.95	8.2976
1781.97	7.48352
1784.98	6.81486
1787.99	6.31659
1791.01	5.69603
1794.01	5.64701
1797.02	5.43033
1800.03	4.87772
1803.04	5.17627
1806.04	4.41608
1809.05	4.37445
1812.05	3.28012
1815.05	3.09624
1818.05	3.40712
1821.05	3.29728
1824.05	3.50395
1827.05	3.8189
1830.04	4.24736
1833.04	3.02552
1836.03	3.51742
1839.03	3.47161
1842.02	3.46308
1845.01	2.53943
1848	2.19832
1850.99	2.45946
1853.97	2.96632
1856.96	2.19674
1859.94	2.93628
1862.93	2.75916
1865.91	2.4053
1868.89	3.07973
1871.87	2.83348
1874.85	3.19659
1877.83	3.24357
1880.81	4.77464
1882.57	4.52827
1885.56	4.20011
1888.55	4.51351
1891.54	4.28573
1894.52	4.14891
1897.51	3.97716
1900.49	4.64424
1903.47	4.57348
1906.45	5.44425
1909.43	5.3611
1912.41	4.16514
1915.39	3.0495
1918.37	1.57997
1921.34	1.67321
1924.32	2.96648
1927.29	3.11797
1930.26	3.21885
1933.23	2.83384
1936.2	2.88846
1939.17	3.47449
1942.14	3.07236
1945.11	3.63945
1948.07	3.78813
1951.04	4.6458
1954	4.1727
1956.96	3.87419
1959.93	3.11811
1962.89	2.88085
1965.85	3.47458
1968.8	3.39034
1971.76	4.25594
1974.72	4.38024
1977.67	4.63078
1980.63	4.67696
1983.58	4.20137
1986.53	2.69642
1989.48	2.99869
1992.43	3.57813
1995.38	4.70348
1998.32	4.86817
2001.27	4.97015
2004.22	4.68877
2007.16	6.48688
2010.1	7.4666
2013.04	8.55343
2015.98	9.90305
2018.92	10.3315
2021.86	11.1695
2024.8	11.863
2027.74	12.2468
2030.67	12.0371
2033.61	12.1864
2036.54	12.7357
2039.47	13.3109
2042.4	13.352
2045.33	12.3847
2048.26	12.0695
2051.19	12.5117
2054.12	11.9794
2057.04	11.1818
2059.97	10.294
2062.89	10.7125
2065.81	10.1779
2068.73	10.0033
2071.65	9.23778
2074.57	8.91736
2077.49	9.17194
2080.41	10.3055
2083.32	10.8891
2086.24	11.6897
2089.15	12.2865
2092.07	12.3876
2094.98	12.7129
2097.89	12.9471
2100.8	14.2693
2103.71	14.277
2106.61	15.257
2109.52	15.3277
2112.43	15.7723
2115.33	15.5113
2118.23	16.3664
2121.13	16.4513
2124.04	16.2781
2126.94	16.9627
2129.83	16.692
2132.73	16.8267
2135.63	17.1737
2138.53	17.4729
2141.42	18.4284
2144.31	18.2923
2147.21	19.614
2150.1	20.7965
2152.99	22.254
2155.88	23.4465
2158.77	24.2224
2161.65	25.7035
2164.54	26.3369
2167.43	25.9609
2170.31	27.1489
2173.19	27.9754
2176.07	27.4996
2178.96	27.6674
2181.84	27.3559
2184.72	26.2233
2187.59	25.4223
2190.47	24.7854
2193.35	23.8343
2196.22	23.8692
2199.09	23.8522
2201.97	23.4383
2204.84	21.87
2207.71	21.0565
2210.58	21.3181
2213.45	20.2172
2216.31	19.4147
2219.18	19.4438
2222.05	19.4436
2224.91	19.3875
2227.78	20.5676
2230.64	19.8732
2233.5	19.4615
2236.36	18.4324
2239.22	18.4
2242.08	19.2072
2244.93	19.007
2247.79	18.2967
2250.64	18.2669
2253.5	17.9007
2256.35	17.6562
2259.2	18.0929
2262.05	18.6658
2264.9	18.7349
2267.75	19.2934
2270.6	18.4113
2273.45	17.952
2276.29	17.3629
2279.14	16.6366
2281.98	16.3925
2284.82	15.7083
2287.66	15.1134
2290.5	14.7001
2293.34	13.1994
2296.18	13.7961
2299.02	14.4015
2301.86	14.3755
2304.69	15.2028
2307.53	15.614
2310.36	16.234
2313.19	16.231
2316.02	15.1406
2318.85	15.9427
2321.68	16.4595
2324.51	16.0297
2327.34	16.1428
2330.16	15.882
2332.99	16.4237
2335.81	15.4754
2338.64	15.8326
2341.46	15.133
2344.28	15.1593
2347.1	13.7486
2349.92	12.8788
2352.74	11.8001
2355.55	10.7419
2358.37	10.6033
2361.19	10.0306
2364	10.166
2366.81	10.9266
2369.62	11.0272
2372.44	10.5458
2375.24	10.067
2378.05	10.2563
2380.86	9.41539
2383.67	8.64733
2386.47	8.65398
2389.28	8.78143
2392.08	8.47168
2394.89	8.81544
2397.69	9.16915
2400.49	8.85947
2403.29	9.83016
2406.09	10.5878
2408.88	12.2016
2411.68	13.0432
2414.48	13.3054
2417.27	13.1317
2420.06	13.4598
2422.86	13.802
2425.65	15.0416
2428.44	14.7801
2431.23	14.0514
2434.02	14.6702
2436.81	14.8051
2439.59	14.3913
2442.38	13.204
2445.16	13.3709
2447.95	11.6876
2450.73	10.5717
2453.51	10.179
2456.29	8.72551
2459.07	8.29698
2461.85	7.91559
2464.63	7.16467
2467.4	5.91855
2470.18	5.63138
2472.95	5.12051
2475.73	4.63075
2478.5	3.91457
2481.27	3.19421
2484.04	2.7378
2486.81	2.42615
2489.58	2.1191
2492.35	1.4543
2495.12	1.55081
2497.88	0.806884
2500.65	0.885737
2503.41	1.25003
2506.17	1.38825
2508.94	1.38043
2511.7	1.01963
2514.46	1.31707
2517.22	1.7859
2519.97	1.79551
2522.73	1.98204
2525.49	1.78873
2528.24	2.17152
2530.99	2.05204
2533.75	2.07772
2536.5	1.85432
2539.25	1.62612
2542	1.59084
2544.75	1.42959
2547.5	2.06095
2550.24	2.24503
2552.99	1.86439
2555.74	1.74444
2558.48	1.59782
2561.22	1.96884
2563.96	2.46332
2566.71	2.56702
2569.45	3.26226
2572.18	3.5971
2574.92	4.23876
2577.66	3.97817
2580.4	4.27948
2583.13	4.64964
2585.87	4.14616
2588.6	4.51052
2591.33	3.79023
2594.06	4.01531
2596.79	4.02679
2599.52	3.93385
2602.25	4.20377
2604.98	4.01661
2607.71	3.91316
2610.43	3.73669
2613.16	4.19674
2615.88	3.04121
2618.6	2.09257
2621.32	1.85303
2624.04	1.70049
2626.76	2.05465
2629.48	2.59248
2632.2	1.73955
2634.92	2.91432
2637.63	2.96115
2640.35	3.67006
2643.06	4.0578
2645.77	3.87443
2648.49	4.81006
2651.2	4.68332
2653.91	5.12727
2656.62	5.35959
2659.33	5.58531
2662.03	5.48664
2664.74	5.76804
2667.44	5.64509
2670.15	5.36865
2672.85	4.34037
2675.55	3.8405
2678.26	2.81493
2680.96	2.02136
2683.66	1.20922
2686.35	1.82941
2689.05	1.76877
2691.75	1.71052
2694.44	1.74928
2697.14	2.12101
2699.83	2.13167
2702.52	2.58134
2705.22	1.76151
2707.91	2.39113
2710.6	2.40588
2713.29	1.85145
2715.97	1.48546
2718.66	1.83299
2721.35	2.02648
2724.03	1.78481
2726.72	1.33944
2729.4	0.888465
2732.08	0.105999
2734.76	-0.340109
2737.44	-0.856938
2740.12	-1.53827
2742.8	-1.63473
2745.48	-1.23633
2748.16	-0.868147
2750.83	-0.761415
2753.51	-0.669103
2756.18	-1.14116
2758.85	-0.621566
2761.53	-0.112512
2764.2	0.0445214
2766.87	0.487806
2769.54	0.51046
2772.2	1.13702
2774.87	0.802675
2777.54	0.968258
2780.2	1.24005
2782.87	1.65069
2785.53	2.1817
2788.19	2.14442
2790.85	1.79292
2793.51	1.57295
2796.17	1.30465
2798.83	1.93393
2801.49	1.48042
2804.15	1.65721
2806.8	1.13934
2809.46	1.57484
2812.11	1.01805
2814.76	0.725535
2817.42	0.417969
2820.07	1.1844
2822.72	2.50912
2825.37	3.4947
2828.02	5.3351
2830.66	7.80061
2833.31	10.6287
2835.96	13.3926
2838.6	15.9608
2841.24	18.3375
2843.89	22.4054
2846.53	26.542
2849.17	30.7545
2851.81	35.5823
2854.45	40.4617
2857.09	44.5329
2859.72	49.6861
2862.36	54.9297
2865	59.1118
2867.63	64.2422
2870.26	67.5916
2872.9	69.4248
2875.53	71.4366
2878.16	72.9161
2880.79	74.9483
2883.42	76.637
2886.05	77.9974
2888.67	78.6644
2891.3	80.1324
2893.92	82.1826
2896.55	83.2501
2899.17	84.8816
2901.79	87.13
2904.42	90.1109
2907.04	93.3657
2909.66	98.502
2912.27	102.995
2914.89	108.309
2917.51	113.025
2920.13	118.575
2922.74	123.011
2925.35	126.816
2927.97	129.658
2930.58	130.596
2933.19	129.907
2935.8	128.601
2938.41	126.856
2941.02	124.058
2943.63	121.381
2946.24	117.067
2948.84	111.902
2951.45	107.128
2954.05	101.923
2956.65	97.2885
2959.26	93.1097
2961.86	87.933
2964.46	83.9486
2967.06	81.0632
2969.66	77.5841
2972.25	73.9136
2974.85	70.8698
2977.45	67.6459
2980.04	64.5033
2982.64	61.4416
2985.23	58.2079
2987.82	53.9765
2990.41	49.3628
2993	45.5825
2995.59	41.5729
2998.18	38.0858
3000.77	33.5843
3003.36	30.225
3005.94	26.3079
3008.53	22.4562
3011.11	19.3982
3013.69	16.3757
3016.28	13.4037
3018.86	11.3033
3021.44	10.4924
3024.02	9.31859
3026.6	7.92153
3029.18	6.76032
3031.75	6.78967
3034.33	5.82751
3036.9	5.74192
3039.48	6.14624
3042.05	7.03538
3044.62	7.50783
3047.19	8.69881
3049.77	9.35083
3052.34	9.81253
3054.9	11.2055
3057.47	11.4671
3060.04	12.0443
3062.61	12.2239
3065.17	12.1223
3067.74	11.7782
3070.3	11.0366
3072.86	10.0224
3075.42	9.10035
3077.99	7.88938
3080.54	7.24509
3083.1	6.57424
3085.66	6.41309
3088.22	5.4067
3090.78	4.47022
3093.33	4.59716
3095.89	3.79526
3098.44	3.21453
3100.99	2.90296
3103.54	2.28375
3106.1	2.02615
3108.65	2.29877
3111.2	2.40296
3113.74	2.97771
3116.29	3.39945
3118.84	3.076
3121.38	3.32468
3123.93	3.70874
3126.47	3.33193
3129.01	3.31363
3131.56	2.7676
3134.1	2.33789
3136.64	2.24453
3139.18	2.01602
3141.72	2.13968
3144.26	1.75791
3146.79	1.13836
3149.33	-0.615927