File: data/Raman/poly_smoothed/Thy_40_11_33_1x_45s_532 nm_x100_100%_600 gr_mm_01.txt
#Acq. time (s)=	45
#Accumulations=	2
#Range (cm-¹)=	200...3150
#Windows=	2
#Auto scanning=	Off
#Autofocus=	Off
#Macrospot=	Off
#AutoExposure=	Off
#Spike filter=	Multiple accum.
#Delay time (s)=	0
#Binning=	1
#Readout mode=	Signal
#DeNoise=	Off
#ICS correction=	On
#Dark correction=	Off
#Inst. Process=	Off
#Detector Gain=	Best Dynamic Range
#Detector ADC=	20 kHz
#Detector temperature (°C)=	-69.85
#Instrument=	LabRAM HR Evol
#Detector=	Synapse
#Objective=	x100
#Grating=	600 gr/mm
#ND Filter=	100%
#Laser (nm)=	532
#Hole=	100.021
#Range=	Auto
#Laser Pol.=	No
#Raman. Pol.=	No
#Laser Pol. (°)=	-0.0007625
#Raman Pol. (°)=	89.9995
#Collection=	Microscope
#StageXY=	Marzhauser
#StageZ=	Marzhauser
#X (µm)=	253.4
#Y (µm)=	1679.1
#Z (µm)=	426.8
#Full time(mm:ss)=	3:18
#Project=
#Sample=
#Site=
#Title=	Thy_40_11_33_2x_45s_532 nm_x100_100%_600 gr_mm
#Remark=
#Date=	05.07.2022 12:22
#Acquired=	05.07.2022 12:22:09
#Base:Fit=	10.08.2022 10:01:35
#Base:Sub=	10.08.2022 10:01:52
#Filter:Polynom=	16.08.2022 10:21:53
#AxisType[0]=Intens
#AxisUnit[0]=Cnt
#AxisType[1]=Spectr
#AxisUnit[1]=1/cm
200.43	29.0306
204.059	26.749
207.688	23.4545
211.314	19.7193
214.941	16.6403
218.564	14.6826
222.186	11.5577
225.809	10.4549
229.428	8.61819
233.045	7.69881
236.663	5.49337
240.278	4.83741
243.891	4.36607
247.503	3.31316
251.116	3.58984
254.725	3.5734
258.333	5.08293
261.939	6.81539
265.544	6.91215
269.148	8.26507
272.75	7.66229
276.351	6.98111
279.95	5.84458
283.548	5.96328
287.144	6.25529
290.739	5.34359
294.333	5.78473
297.925	5.61532
301.514	5.90835
305.104	6.52172
308.692	7.16047
312.279	8.33343
315.862	8.34932
319.446	8.23002
323.029	8.72357
326.608	9.50288
330.188	10.5129
333.766	11.6503
337.341	12.9265
340.917	12.003
344.489	11.6611
348.062	12.4343
351.631	12.0417
355.201	11.5671
358.768	9.59823
362.333	9.03971
365.899	9.56071
369.462	9.48927
373.023	11.0171
376.585	9.43846
380.143	9.64233
383.7	10.9537
387.256	11.2756
390.812	11.1471
394.365	12.3888
397.916	12.8757
401.467	12.4042
405.015	12.3468
408.563	13.3833
412.109	14.5058
415.654	13.629
419.197	13.1797
422.739	13.8248
426.279	11.2535
429.819	10.3945
433.356	8.74537
436.891	7.54862
440.426	5.45333
443.96	5.14804
447.492	5.21308
451.021	6.13561
454.551	6.41044
458.079	8.32805
461.604	8.43377
465.13	8.43081
468.654	8.91955
472.175	9.97946
475.696	10.9636
479.215	12.9967
482.733	15.4567
486.249	17.6063
489.765	20.3606
493.278	22.9502
496.789	24.3947
500.301	24.9656
503.81	26.386
507.317	26.1993
510.825	26.1194
514.33	26.0007
517.833	24.5167
521.335	23.9259
524.836	24.7725
528.335	25.151
531.835	24.6264
535.332	24.0621
538.827	23.3963
542.321	23.0321
545.814	21.6011
549.305	20.3793
552.795	19.7735
556.282	20.0766
559.769	18.9281
563.255	17.2295
566.739	16.4717
570.223	14.9089
573.705	13.5533
577.183	11.7275
580.663	11.0744
584.141	9.82362
587.615	9.8581
591.09	10.8597
594.564	7.97937
598.035	6.96898
601.506	7.76258
604.974	7.8041
608.443	9.29281
611.908	9.15582
615.374	9.55794
618.837	10.7893
622.3	13.0225
625.761	14.6879
629.219	16.8901
632.677	19.1314
636.135	21.5515
639.59	21.8061
643.043	23.2403
646.495	24.8034
649.948	24.2696
653.398	24.9799
656.846	26.1133
660.293	28.3045
663.738	29.3246
667.183	28.5136
670.626	29.2035
674.067	30.1256
677.508	30.0415
680.947	30.4307
684.385	31.1507
687.821	34.2096
691.254	35.0166
694.688	35.7073
698.121	37.187
701.552	40.7096
704.98	43.3675
708.409	45.5036
711.836	48.1421
715.26	49.788
718.685	52.9163
722.108	55.5616
725.528	55.6582
728.949	56.8803
732.367	57.4422
735.785	57.5055
739.2	59.8784
742.614	62.2539
746.028	62.9537
749.439	63.8946
752.849	66.9309
756.26	70.1575
759.667	71.618
763.073	75.0707
766.477	76.8792
769.883	78.829
773.285	80.5477
776.686	81.9697
780.085	84.5903
783.484	87.3969
786.881	89.3123
790.276	91.9509
793.671	93.9578
797.064	95.5702
800.456	97.7693
803.846	98.663
807.234	98.6125
810.622	98.1122
814.008	97.934
817.394	99.0269
820.778	99.3279
824.159	101.708
827.541	100.745
830.921	99.5548
834.298	99.5864
837.676	96.9481
841.051	93.9692
844.426	90.6976
847.798	87.7442
851.171	84.0064
854.54	80.0377
857.911	76.6491
861.278	73.8455
864.645	71.4246
868.01	69.0157
871.373	67.3602
874.735	66.2553
878.097	64.8203
881.457	63.8405
884.815	62.1398
888.172	61.355
891.528	60.6096
894.882	61.0565
898.237	61.758
901.589	61.6398
904.94	62.6745
908.289	61.3103
911.635	60.2978
914.982	60.7708
918.328	60.8973
921.672	60.8243
925.015	59.9286
928.357	56.981
931.698	57.0047
935.035	55.7458
938.373	54.282
941.71	53.8792
945.044	51.9928
948.378	51.4589
951.709	52.3332
955.041	52.0711
958.372	52.31
961.699	53.4219
965.027	53.6995
968.352	56.327
971.676	57.0572
975	58.6471
978.322	60.2743
981.642	61.9137
984.962	63.762
988.28	63.7918
991.596	64.401
994.911	66.1202
998.227	66.3351
1001.54	66.6888
1004.85	66.5514
1008.16	65.1913
1011.47	65.601
1014.78	64.8304
1018.08	63.2082
1021.39	62.5748
1024.69	61.1315
1028	60.9876
1031.3	61.6405
1034.6	58.0969
1037.9	56.8617
1041.19	55.7879
1044.49	55.5141
1047.78	54.804
1051.08	53.6515
1054.37	51.5597
1057.66	49.2745
1060.95	48.2059
1064.24	46.653
1067.53	45.1532
1070.81	45.0045
1074.1	43.825
1077.38	44.8751
1080.66	43.9085
1083.94	44.6931
1087.22	44.9548
1090.5	43.985
1093.78	43.119
1097.05	42.7869
1100.33	42.0985
1103.6	43.1203
1106.87	42.5481
1110.14	41.211
1113.41	40.2116
1116.68	38.8576
1119.95	38.7275
1123.21	37.4989
1126.48	34.8425
1129.74	32.4885
1133	30.9248
1136.26	27.8835
1139.52	27.1275
1142.78	25.8837
1146.04	25.489
1149.29	24.1009
1152.55	21.7429
1155.8	18.2101
1159.05	16.7524
1162.3	14.5937
1165.55	13.4546
1168.8	10.8849
1172.05	10.8025
1175.29	11.879
1178.54	12.3772
1181.78	14.8567
1185.02	16.3166
1188.26	15.834
1191.5	17.4624
1194.74	21.3989
1197.97	24.0249
1201.21	27.6406
1204.44	32.4101
1207.68	36.6702
1210.91	40.959
1214.14	44.7696
1217.37	49.6941
1220.59	54.358
1223.82	57.5151
1227.05	59.8729
1230.27	62.8073
1233.49	64.792
1236.72	69.1247
1239.94	71.3981
1243.16	74.8989
1246.37	78.4271
1249.59	80.9592
1252.8	83.9429
1256.02	85.2769
1259.23	87.8788
1262.44	90.5089
1265.66	90.6653
1268.86	92.0865
1272.07	93.9016
1275.28	94.6984
1278.48	95.3046
1281.69	97.8836
1284.89	101.37
1288.09	102.053
1291.29	102.522
1294.49	104.114
1297.69	104.408
1300.89	106.439
1304.08	106.707
1307.28	107.057
1310.47	106.882
1313.66	106.277
1316.85	107.072
1320.04	106.455
1323.23	107.12
1326.42	103.365
1329.61	101.047
1332.79	99.2761
1335.97	96.1689
1339.16	93.7986
1342.34	89.1033
1345.52	83.7646
1348.7	79.2802
1351.87	74.0796
1355.05	71.353
1358.22	69.6811
1361.4	67.0117
1364.57	63.8081
1367.74	61.8276
1370.91	59.2182
1374.08	56.7828
1377.25	55.199
1380.41	53.7484
1383.58	52.1754
1386.74	51.2039
1389.91	49.0069
1393.07	47.7375
1396.23	45.1472
1399.39	43.7966
1402.55	43.6861
1405.7	43.0396
1408.86	43.6475
1412.01	45.4773
1415.17	46.6459
1418.32	48.7925
1421.47	51.6279
1424.62	55.6591
1427.77	62.7
1430.91	69.9328
1434.06	76.5645
1437.2	82.1293
1440.35	85.2347
1443.49	88.7057
1446.63	91.357
1449.77	91.7316
1452.91	91.4705
1456.05	90.4997
1459.18	87.7571
1462.32	84.4565
1465.45	78.9693
1468.59	71.8971
1471.72	65.9582
1474.85	60.2602
1477.98	54.1395
1481.1	47.6873
1484.23	40.1456
1487.36	35.6338
1490.48	31.3512
1493.61	28.2926
1496.73	25.9407
1499.85	24.9462
1502.97	26.1913
1506.09	26.3482
1509.2	25.7009
1512.32	24.399
1515.43	23.147
1518.55	23.0851
1521.66	24.4453
1524.77	25.0739
1527.88	26.1787
1530.99	26.7494
1534.1	27.9224
1537.21	29.6409
1540.31	31.4409
1543.42	32.9255
1546.52	35.6379
1549.62	38.0874
1552.72	40.9208
1555.82	45.1293
1558.92	49.6219
1562.02	54.1417
1565.11	57.43
1568.21	62.354
1571.3	67.0624
1574.39	70.7922
1577.49	73.9586
1580.57	75.6468
1583.66	77.0375
1586.75	78.0824
1589.84	79.4603
1592.92	79.6328
1596.01	80.6643
1599.09	80.2434
1602.17	78.711
1605.25	77.7534
1608.33	77.5442
1611.41	76.9187
1614.49	77.6491
1617.57	78.6626
1620.64	80.4563
1623.72	82.9992
1626.79	86.4077
1629.86	91.0467
1632.93	95.8538
1636	99.2146
1639.07	104.391
1642.13	110.551
1645.2	114.703
1648.26	119.115
1651.33	120.01
1654.39	121.629
1657.45	121.154
1660.51	119.643
1663.57	117.306
1666.63	113.718
1669.68	109.491
1672.74	104.454
1675.79	97.5178
1678.85	90.826
1681.9	84.5378
1684.95	76.8217
1688	69.926
1691.05	63.6034
1694.09	56.3451
1697.14	49.1336
1700.18	43.7929
1703.23	39.3853
1706.27	35.2561
1709.31	31.0368
1712.35	28.5807
1715.39	26.716
1718.43	24.0138
1721.47	22.752
1724.5	19.3565
1727.54	18.192
1730.57	16.2217
1733.61	14.7095
1736.64	13.0723
1739.67	11.5913
1742.7	10.6763
1745.72	8.86849
1748.75	7.76935
1751.77	6.57623
1754.8	4.47357
1757.82	2.12298
1760.84	1.90191
1763.87	1.49806
1766.89	0.529542
1769.91	-0.23274
1772.92	0.177433
1775.94	0.600569
1778.95	0.904682
1781.97	1.20044
1784.98	1.88378
1787.99	1.80906
1791.01	2.29863
1794.01	2.97121
1797.02	2.87724
1800.03	3.89095
1803.04	4.62261
1806.04	4.89868
1809.05	5.52128
1812.05	5.55863
1815.05	5.96205
1818.05	6.05101
1821.05	6.40058
1824.05	6.63365
1827.05	6.65201
1830.04	6.91656
1833.04	7.1069
1836.03	7.95114
1839.03	7.91799
1842.02	7.97545
1845.01	7.49396
1848	6.39356
1850.99	6.43365
1853.97	6.38234
1856.96	6.36316
1859.94	6.13485
1862.93	6.07055
1865.91	5.97999
1868.89	5.96892
1871.87	5.82209
1874.85	6.20244
1877.83	6.40147
1880.81	5.7109
1882.57	6.15122
1885.56	6.95601
1888.55	7.98608
1891.54	8.35837
1894.52	8.60758
1897.51	9.6951
1900.49	10.5208
1903.47	10.3994
1906.45	11.8688
1909.43	11.402
1912.41	10.9805
1915.39	11.5748
1918.37	10.9324
1921.34	11.859
1924.32	12.8003
1927.29	13.3349
1930.26	12.4995
1933.23	12.0466
1936.2	12.6374
1939.17	12.5489
1942.14	11.9463
1945.11	11.4254
1948.07	10.5024
1951.04	10.9192
1954	11.5989
1956.96	11.3045
1959.93	11.4988
1962.89	10.3596
1965.85	9.05229
1968.8	9.322
1971.76	9.52378
1974.72	10.2636
1977.67	10.2719
1980.63	11.001
1983.58	11.0558
1986.53	11.8417
1989.48	12.1496
1992.43	12.6627
1995.38	13.2096
1998.32	12.5395
2001.27	12.3439
2004.22	13.0768
2007.16	14.7804
2010.1	14.4253
2013.04	13.9005
2015.98	14.0971
2018.92	14.224
2021.86	13.8431
2024.8	13.7184
2027.74	13.0759
2030.67	12.8541
2033.61	12.657
2036.54	12.2152
2039.47	12.5566
2042.4	13.3833
2045.33	14.1489
2048.26	15.3974
2051.19	15.8906
2054.12	16.6394
2057.04	17.651
2059.97	18.5205
2062.89	18.9994
2065.81	20.0539
2068.73	20.7192
2071.65	23.2068
2074.57	24.671
2077.49	26.5292
2080.41	27.2098
2083.32	28.8666
2086.24	29.9724
2089.15	31.9523
2092.07	34.4294
2094.98	36.637
2097.89	38.2354
2100.8	41.6724
2103.71	44.496
2106.61	46.7942
2109.52	50.1921
2112.43	54.2773
2115.33	58.3131
2118.23	62.5286
2121.13	66.8566
2124.04	71.8792
2126.94	76.5563
2129.83	80.5961
2132.73	85.6445
2135.63	90.4342
2138.53	95.0479
2141.42	99.4576
2144.31	104.946
2147.21	109.991
2150.1	114.761
2152.99	118.866
2155.88	122.84
2158.77	125.961
2161.65	129.464
2164.54	131.98
2167.43	133.396
2170.31	134.648
2173.19	135.319
2176.07	133.293
2178.96	131.855
2181.84	129.883
2184.72	126.076
2187.59	123.216
2190.47	120.468
2193.35	117.675
2196.22	113.015
2199.09	106.629
2201.97	101.477
2204.84	96.8663
2207.71	90.6855
2210.58	85.7554
2213.45	82.0272
2216.31	77.5366
2219.18	72.5241
2222.05	68.8436
2224.91	64.7153
2227.78	60.8649
2230.64	56.6135
2233.5	53.5025
2236.36	50.5817
2239.22	47.9554
2242.08	44.8724
2244.93	41.5847
2247.79	38.7282
2250.64	37.4761
2253.5	35.8656
2256.35	34.2461
2259.2	33.8347
2262.05	32.7327
2264.9	31.5732
2267.75	30.0495
2270.6	27.9874
2273.45	27.1969
2276.29	25.8512
2279.14	25.1538
2281.98	24.6654
2284.82	23.1659
2287.66	22.3028
2290.5	19.6672
2293.34	16.0859
2296.18	14.9322
2299.02	13.828
2301.86	13.2934
2304.69	13.6893
2307.53	12.7158
2310.36	12.1221
2313.19	11.6822
2316.02	10.7203
2318.85	10.2315
2321.68	10.4344
2324.51	8.60477
2327.34	7.57227
2330.16	7.74941
2332.99	6.90598
2335.81	5.38908
2338.64	4.72484
2341.46	3.56828
2344.28	3.7857
2347.1	3.22927
2349.92	2.82838
2352.74	1.6843
2355.55	-0.424629
2358.37	-1.1423
2361.19	-2.70493
2364	-2.10275
2366.81	-0.341245
2369.62	0.230771
2372.44	0.679623
2375.24	0.296481
2378.05	-0.0766394
2380.86	0.234599
2383.67	0.146647
2386.47	0.518555
2389.28	0.805354
2392.08	0.407663
2394.89	0.664161
2397.69	1.32182
2400.49	1.21587
2403.29	0.958805
2406.09	1.08692
2408.88	1.87319
2411.68	2.79423
2414.48	3.89724
2417.27	4.90826
2420.06	5.0765
2422.86	5.88347
2425.65	6.2977
2428.44	7.3069
2431.23	7.78849
2434.02	7.51645
2436.81	7.17414
2439.59	6.98654
2442.38	6.96327
2445.16	5.97081
2447.95	6.56275
2450.73	5.93404
2453.51	6.04527
2456.29	5.51907
2459.07	5.59562
2461.85	6.04022
2464.63	5.40991
2467.4	4.32194
2470.18	3.37598
2472.95	3.81192
2475.73	4.02879
2478.5	4.33812
2481.27	4.04619
2484.04	4.18152
2486.81	4.16331
2489.58	3.45876
2492.35	3.43128
2495.12	2.82798
2497.88	2.71034
2500.65	2.31809
2503.41	2.60129
2506.17	2.72773
2508.94	3.37054
2511.7	2.90187
2514.46	3.063
2517.22	3.1277
2519.97	3.90047
2522.73	3.67324
2525.49	3.81125
2528.24	4.17343
2530.99	3.40539
2533.75	2.58668
2536.5	3.2062
2539.25	3.5928
2542	4.42809
2544.75	4.1347
2547.5	3.5159
2550.24	3.05035
2552.99	2.63038
2555.74	1.68415
2558.48	1.23694
2561.22	1.16723
2563.96	0.977464
2566.71	1.05822
2569.45	1.59763
2572.18	1.83474
2574.92	1.84764
2577.66	2.38221
2580.4	2.4907
2583.13	2.10703
2585.87	2.01763
2588.6	1.32972
2591.33	1.44843
2594.06	0.668111
2596.79	1.0154
2599.52	0.930028
2602.25	1.62966
2604.98	2.27137
2607.71	2.35687
2610.43	2.51892
2613.16	1.35208
2615.88	1.43342
2618.6	1.6654
2621.32	1.11884
2624.04	0.859023
2626.76	0.389309
2629.48	0.726321
2632.2	1.00321
2634.92	1.86151
2637.63	1.96641
2640.35	1.67904
2643.06	1.95488
2645.77	2.09856
2648.49	1.81867
2651.2	1.20127
2653.91	0.656016
2656.62	0.564526
2659.33	0.70082
2662.03	0.105495
2664.74	0.15509
2667.44	0.659546
2670.15	1.28229
2672.85	1.39671
2675.55	1.12044
2678.26	2.12847
2680.96	3.13146
2683.66	4.0632
2686.35	4.47468
2689.05	4.98656
2691.75	4.55841
2694.44	4.65987
2697.14	4.7003
2699.83	4.50965
2702.52	4.87134
2705.22	5.06809
2707.91	6.00168
2710.6	6.5964
2713.29	6.51342
2715.97	7.07974
2718.66	7.2178
2721.35	7.32059
2724.03	8.43218
2726.72	8.1624
2729.4	7.44963
2732.08	7.50437
2734.76	7.61239
2737.44	7.21879
2740.12	7.64618
2742.8	8.74465
2745.48	8.48907
2748.16	7.59089
2750.83	7.52543
2753.51	6.86408
2756.18	5.47317
2758.85	4.43146
2761.53	4.4165
2764.2	3.34189
2766.87	2.07985
2769.54	1.96877
2772.2	1.89249
2774.87	1.41276
2777.54	1.83949
2780.2	1.37593
2782.87	0.669033
2785.53	0.170483
2788.19	0.680377
2790.85	-0.385663
2793.51	0.662048
2796.17	0.15265
2798.83	0.907321
2801.49	1.24388
2804.15	1.67816
2806.8	1.86198
2809.46	0.743211
2812.11	-0.443734
2814.76	0.352512
2817.42	0.885763
2820.07	1.50769
2822.72	3.7714
2825.37	6.24212
2828.02	8.92983
2830.66	12.3981
2833.31	17.4573
2835.96	22.6457
2838.6	27.8178
2841.24	34.5759
2843.89	41.721
2846.53	49.7408
2849.17	60.1758
2851.81	71.11
2854.45	82.1637
2857.09	94.4093
2859.72	104.96
2862.36	115.115
2865	124.96
2867.63	134.271
2870.26	141.352
2872.9	147.609
2875.53	153.723
2878.16	159.514
2880.79	164.688
2883.42	169.529
2886.05	175.442
2888.67	181.647
2891.3	187.264
2893.92	194.067
2896.55	201.963
2899.17	210.698
2901.79	219.728
2904.42	232.264
2907.04	246.264
2909.66	262.052
2912.27	278.117
2914.89	295.257
2917.51	311.146
2920.13	325.387
2922.74	337.91
2925.35	346.478
2927.97	354.078
2930.58	358.652
2933.19	360.127
2935.8	357.982
2938.41	353.531
2941.02	348.556
2943.63	339.86
2946.24	329.07
2948.84	317.868
2951.45	305.118
2954.05	291.035
2956.65	277.432
2959.26	263.061
2961.86	249.559
2964.46	236.338
2967.06	222.994
2969.66	211.495
2972.25	200.382
2974.85	188.999
2977.45	176.829
2980.04	165.696
2982.64	153.587
2985.23	141.537
2987.82	129.806
2990.41	117.677
2993	106.597
2995.59	95.5489
2998.18	85.6178
3000.77	76.2613
3003.36	67.2441
3005.94	60.1928
3008.53	52.5198
3011.11	46.1788
3013.69	40.3738
3016.28	34.8157
3018.86	30.252
3021.44	26.2889
3024.02	23.2642
3026.6	21.8492
3029.18	19.238
3031.75	18.8173
3034.33	18.7672
3036.9	18.2257
3039.48	18.485
3042.05	18.7946
3044.62	19.1922
3047.19	20.6807
3049.77	21.5797
3052.34	22.2984
3054.9	23.4625
3057.47	24.2374
3060.04	24.2729
3062.61	23.302
3065.17	22.1006
3067.74	21.6558
3070.3	19.4908
3072.86	17.7843
3075.42	15.0536
3077.99	12.9776
3080.54	10.2717
3083.1	7.87544
3085.66	5.62597
3088.22	4.46981
3090.78	2.75836
3093.33	1.80708
3095.89	0.816405
3098.44	0.471737
3100.99	0.570958
3103.54	0.205123
3106.1	0.243823
3108.65	0.189695
3111.2	1.32644
3113.74	1.9521
3116.29	3.01639
3118.84	3.27883
3121.38	4.12024
3123.93	3.94482
3126.47	4.72907
3129.01	5.96618
3131.56	6.43065
3134.1	7.01972
3136.64	8.12093
3139.18	9.56528
3141.72	11.14
3144.26	12.94
3146.79	15.9214
3149.33	20.1265