File: data/Raman/poly_smoothed/Thy_20_09_50_1x_45s_532 nm_x100_100%_600 gr_mm_01.txt
#Acq. time (s)=	45
#Accumulations=	2
#Range (cm-¹)=	200...3150
#Windows=	2
#Auto scanning=	Off
#Autofocus=	Off
#Macrospot=	Off
#AutoExposure=	Off
#Spike filter=	Multiple accum.
#Delay time (s)=	0
#Binning=	1
#Readout mode=	Signal
#DeNoise=	Off
#ICS correction=	On
#Dark correction=	Off
#Inst. Process=	Off
#Detector Gain=	Best Dynamic Range
#Detector ADC=	20 kHz
#Detector temperature (°C)=	-69.85
#Instrument=	LabRAM HR Evol
#Detector=	Synapse
#Objective=	x100
#Grating=	600 gr/mm
#ND Filter=	100%
#Laser (nm)=	532
#Hole=	100.021
#Range=	Auto
#Laser Pol.=	No
#Raman. Pol.=	No
#Laser Pol. (°)=	-0.0007625
#Raman Pol. (°)=	89.9995
#Collection=	Microscope
#StageXY=	Marzhauser
#StageZ=	Marzhauser
#X (µm)=	-5935.5
#Y (µm)=	2871.1
#Z (µm)=	-223.3
#Full time(mm:ss)=	3:19
#Project=
#Sample=
#Site=
#Title=	Thy_20_09_50_2x_45s_532 nm_x100_100%_600 gr_mm
#Remark=
#Date=	29.06.2022 14:08
#Acquired=	29.06.2022 14:08:00
#Base:Fit=	10.08.2022 09:52:02
#Base:Fit=	10.08.2022 09:52:12
#Base:Sub=	10.08.2022 09:54:21
#Filter:Polynom=	16.08.2022 10:24:04
#AxisType[0]=Intens
#AxisUnit[0]=Cnt
#AxisType[1]=Spectr
#AxisUnit[1]=1/cm
200.523	38.0297
204.154	36.4959
207.781	32.5007
211.409	28.5439
215.034	23.8317
218.659	21.137
222.281	17.6401
225.903	14.4313
229.522	11.713
233.14	8.76765
236.756	7.1397
240.373	4.17178
243.986	3.06497
247.598	1.45574
251.208	0.619905
254.818	-0.297692
258.427	1.30189
262.034	5.03327
265.638	9.93852
269.242	9.993
272.844	9.05059
276.445	9.49801
280.044	11.2844
283.642	12.2332
287.238	13.6804
290.833	11.4832
294.425	12.0016
298.017	11.8004
301.608	12.2538
305.198	12.4608
308.786	11.7521
312.371	11.8152
315.956	11.0413
319.54	11.1719
323.122	10.7533
326.701	10.9556
330.281	10.7558
333.857	10.8885
337.434	10.9456
341.008	11.804
344.582	12.5195
348.153	14.5125
351.724	13.3443
355.292	12.6752
358.861	11.3797
362.426	9.56394
365.99	9.87513
369.555	10.0411
373.116	9.35822
376.676	7.48144
380.236	6.03213
383.793	6.61323
387.349	6.29761
390.903	5.79971
394.456	6.0085
398.007	5.05201
401.56	5.6637
405.108	6.54789
408.656	6.0038
412.202	6.60789
415.746	7.58785
419.29	5.97772
422.831	6.03893
426.37	7.75696
429.909	7.28146
433.447	8.57944
436.983	6.96066
440.519	6.19806
444.052	5.90214
447.583	4.24513
451.114	4.09332
454.643	5.57244
458.169	5.53429
461.696	4.27106
465.222	4.57057
468.744	5.11162
472.267	6.92307
475.787	7.35256
479.307	10.3776
482.823	11.3628
486.341	13.5302
489.855	14.5639
493.37	16.9185
496.881	19.7086
500.391	22.6977
503.902	23.7951
507.409	25.3983
510.915	26.1107
514.42	26.3504
517.925	26.3628
521.427	24.7328
524.928	22.879
528.427	21.6428
531.925	20.704
535.422	19.4905
538.917	17.2833
542.411	15.423
545.903	13.0335
549.395	12.7193
552.884	10.6959
556.373	9.99297
559.86	9.49374
563.346	7.71772
566.831	6.1941
570.314	5.21374
573.794	4.79086
577.274	5.0858
580.754	5.46223
584.23	6.29398
587.706	5.05876
591.181	3.67613
594.653	3.07192
598.126	2.093
601.595	1.33813
605.065	0.172159
608.532	-0.774821
611.999	-0.397799
615.463	1.99178
618.928	3.34443
622.389	4.60944
625.851	6.09589
629.31	8.13464
632.767	9.99473
636.223	10.4262
639.68	11.5902
643.134	12.7443
646.586	13.7857
650.037	14.7238
653.486	17.5085
656.936	19.7822
660.383	21.8706
663.829	22.1051
667.273	22.6895
670.716	22.4883
674.158	22.9889
677.598	21.9264
681.035	22.8507
684.473	22
687.909	21.0323
691.344	23.14
694.778	24.5667
698.211	27.5887
701.64	29.1246
705.07	30.9497
708.498	33.6273
711.924	37.8479
715.35	41.254
718.774	43.355
722.196	45.7324
725.618	48.2561
729.037	49.4903
732.456	51.9866
735.873	55.0833
739.289	57.9099
742.703	60.9729
746.116	62.621
749.529	64.4451
752.938	66.2901
756.347	67.5743
759.756	68.5228
763.162	70.2642
766.567	72.1691
769.97	72.3088
773.372	73.2595
776.773	73.5577
780.174	73.2501
783.573	73.906
786.97	75.5719
790.365	76.8572
793.76	76.32
797.153	77.5707
800.543	77.4415
803.933	76.4285
807.322	74.782
810.71	73.9694
814.097	74.9358
817.483	75.7517
820.865	77.2027
824.248	76.0635
827.629	75.905
831.008	76.0993
834.387	74.231
837.765	74.036
841.139	72.7699
844.514	72.8979
847.886	69.1678
851.259	69.0616
854.629	65.9892
857.997	63.6208
861.366	61.7125
864.732	61.8035
868.098	59.5934
871.461	58.3207
874.823	55.1895
878.184	54.4454
881.545	53.0566
884.903	53.3529
888.26	53.0414
891.616	53.1512
894.97	53.1287
898.323	52.3628
901.675	52.4003
905.026	50.5568
908.375	50.1383
911.723	49.3489
915.07	47.5922
918.415	46.71
921.76	46.3716
925.103	43.8433
928.443	43.1464
931.783	42.6175
935.123	44.1161
938.461	43.1102
941.796	40.9032
945.131	39.8606
948.465	37.7895
951.797	36.2753
955.128	35.8195
958.457	33.4208
961.786	32.7145
965.113	34.2839
968.44	35.299
971.763	37.334
975.086	39.0569
978.409	39.3908
981.729	40.3091
985.048	41.2408
988.367	40.2916
991.683	40.9382
994.998	40.2035
998.312	40.0518
1001.62	40.6306
1004.94	40.8838
1008.25	40.8687
1011.56	40.7456
1014.86	40.0974
1018.17	38.4773
1021.48	35.869
1024.78	32.8054
1028.08	30.1175
1031.38	27.3974
1034.68	25.1543
1037.98	21.7977
1041.28	19.3291
1044.57	20.3424
1047.87	18.6394
1051.16	17.4627
1054.45	16.2398
1057.75	15.0273
1061.04	14.4021
1064.32	14.3614
1067.61	14.7098
1070.9	15.2209
1074.18	17.092
1077.47	19.6832
1080.75	21.0393
1084.03	22.4028
1087.31	23.9059
1090.59	24.5356
1093.86	25.495
1097.14	26.4832
1100.41	27.4838
1103.69	28.221
1106.96	27.4546
1110.23	27.891
1113.5	28.5678
1116.77	26.6046
1120.03	23.7351
1123.3	21.6437
1126.56	17.6576
1129.83	15.6186
1133.09	14.8977
1136.35	15.3633
1139.61	14.0667
1142.86	14.1853
1146.12	13.0309
1149.38	12.1572
1152.63	12.1916
1155.88	11.2316
1159.14	10.2184
1162.39	7.7198
1165.63	7.33986
1168.88	6.30302
1172.13	6.85043
1175.38	6.44073
1178.62	7.78936
1181.86	8.24402
1185.1	9.79378
1188.34	10.8278
1191.58	12.0462
1194.82	11.3778
1198.06	12.399
1201.29	14.1312
1204.53	15.7455
1207.76	18.3399
1210.99	22.5954
1214.22	26.6671
1217.45	30.0712
1220.68	33.3404
1223.91	36.9389
1227.13	39.7326
1230.36	43.6627
1233.58	46.3888
1236.8	48.86
1240.02	50.5381
1243.24	50.2246
1246.46	51.2604
1249.67	55.0012
1252.89	59.0375
1256.1	62.7945
1259.32	65.8688
1262.53	68.6088
1265.74	71.8238
1268.95	74.4064
1272.15	77.3734
1275.36	78.3717
1278.57	81.1672
1281.77	82.3372
1284.97	84.1942
1288.18	84.7162
1291.38	87.8217
1294.58	87.775
1297.78	89.8756
1300.97	89.8202
1304.17	90.1822
1307.36	89.5333
1310.55	88.8274
1313.75	87.1542
1316.94	85.7736
1320.13	83.5189
1323.32	81.3932
1326.5	83.6855
1329.69	85.7469
1332.87	84.8537
1336.06	83.4944
1339.24	82.3478
1342.42	81.4098
1345.6	80.4917
1348.78	78.508
1351.96	75.714
1355.13	73.6275
1358.31	70.2323
1361.48	68.0196
1364.65	65.4743
1367.82	63.2639
1370.99	62.0856
1374.16	59.414
1377.33	57.8898
1380.5	55.797
1383.66	55.1052
1386.83	53.0607
1389.99	51.3727
1393.15	49.3938
1396.31	47.7169
1399.47	45.7227
1402.63	45.5795
1405.78	44.9297
1408.94	44.1585
1412.1	46.5008
1415.25	47.1789
1418.4	51.6779
1421.55	55.0782
1424.7	58.2134
1427.85	62.1603
1431	65.0548
1434.14	69.6784
1437.29	72.6613
1440.43	76.5224
1443.57	78.4612
1446.71	80.1407
1449.85	81.1164
1452.99	79.8343
1456.13	79.6213
1459.26	76.6343
1462.4	72.8042
1465.54	67.0171
1468.67	60.7321
1471.8	55.0797
1474.93	48.6194
1478.06	43.0702
1481.19	38.4671
1484.31	33.4745
1487.44	30.1557
1490.56	25.5289
1493.69	24.1428
1496.81	22.4999
1499.93	21.6992
1503.05	21.3526
1506.17	22.327
1509.28	22.2796
1512.4	24.0618
1515.52	23.7143
1518.63	24.4415
1521.74	26.7538
1524.85	28.625
1527.96	32.7162
1531.07	35.4299
1534.18	38.2506
1537.29	40.8742
1540.39	43.7326
1543.5	47.6511
1546.6	51.8837
1549.7	56.661
1552.8	60.7946
1555.9	64.8969
1559	67.609
1562.1	70.2098
1565.19	74.2775
1568.29	77.2917
1571.38	81.0053
1574.47	84.5445
1577.56	87.4738
1580.66	89.687
1583.74	89.9169
1586.83	88.3451
1589.92	88.1318
1593.01	86.589
1596.09	85.2897
1599.17	84.398
1602.25	82.2759
1605.34	81.3812
1608.41	80.5364
1611.49	76.6659
1614.57	74.5748
1617.65	73.0502
1620.72	72.6025
1623.79	72.4616
1626.87	71.5562
1629.94	72.1587
1633.01	72.0789
1636.08	72.0031
1639.15	73.1965
1642.21	72.4324
1645.28	73.139
1648.34	75.4472
1651.41	76.5181
1654.47	77.0628
1657.53	76.1178
1660.59	73.8003
1663.65	71.4346
1666.71	68.5573
1669.76	65.3232
1672.82	61.4903
1675.87	56.6269
1678.93	53.0801
1681.98	48.3509
1685.03	43.5987
1688.08	37.6864
1691.13	33.8904
1694.17	30.1307
1697.22	26.7956
1700.27	23.8676
1703.31	20.6088
1706.35	17.6675
1709.39	14.1042
1712.43	11.8114
1715.47	9.71397
1718.51	8.52177
1721.55	9.52948
1724.58	8.39622
1727.62	7.77739
1730.65	7.80439
1733.68	7.10691
1736.72	5.77951
1739.74	3.95506
1742.77	3.28628
1745.8	3.08166
1748.83	1.80848
1751.85	1.49466
1754.88	0.941767
1757.9	0.664744
1760.92	0.244895
1763.95	-0.327515
1766.96	-0.442636
1769.98	0.695272
1773	0.776491
1776.02	0.973418
1779.03	1.2173
1782.05	0.747505
1785.06	1.30774
1788.07	1.28855
1791.08	2.25646
1794.09	2.70381
1797.1	3.39103
1800.11	3.84689
1803.12	3.59406
1806.12	3.61492
1809.12	3.59449
1812.13	3.53666
1815.13	2.69515
1818.13	3.2729
1821.13	3.74415
1824.13	3.45382
1827.13	2.86108
1830.12	2.77488
1833.12	2.36014
1836.11	1.49066
1839.1	1.39444
1842.09	1.54711
1845.09	1.41731
1848.08	1.15201
1851.06	1.25923
1854.05	1.08862
1857.04	1.13874
1860.02	1.34935
1863.01	1.69252
1865.99	1.30702
1868.97	2.00006
1871.95	2.32155
1874.93	2.17711
1877.91	1.95107
1880.89	3.42633
1882.46	3.18427
1885.45	3.0747
1888.43	3.62718
1891.42	4.3327
1894.41	4.13032
1897.39	3.43902
1900.37	3.2456
1903.36	4.44227
1906.34	4.46769
1909.32	4.62342
1912.29	5.27067
1915.27	4.82713
1918.25	5.01825
1921.23	4.73126
1924.2	4.28333
1927.17	5.18487
1930.15	5.38026
1933.12	5.26888
1936.09	5.97325
1939.06	6.66365
1942.02	6.22415
1944.99	6.96096
1947.96	7.19438
1950.92	6.07571
1953.88	6.20339
1956.85	5.37755
1959.81	4.38611
1962.77	4.70891
1965.73	4.837
1968.69	5.16828
1971.64	5.84785
1974.6	6.67779
1977.55	6.55638
1980.51	6.4478
1983.46	6.29665
1986.41	6.1629
1989.36	6.64256
1992.31	7.50518
1995.26	8.309
1998.21	8.64488
2001.15	8.48096
2004.1	8.02154
2007.04	8.16146
2009.99	7.61204
2012.93	7.80297
2015.87	7.26914
2018.81	7.44165
2021.75	6.35626
2024.68	6.08799
2027.62	6.40268
2030.56	6.64306
2033.49	7.99359
2036.42	9.35962
2039.36	9.71355
2042.29	10.2557
2045.22	11.6277
2048.14	11.9053
2051.07	13.7252
2054	14.8259
2056.93	14.8504
2059.85	15.9281
2062.77	17.6643
2065.7	18.3326
2068.62	18.7969
2071.54	17.4395
2074.46	16.9328
2077.38	15.9334
2080.29	15.3778
2083.21	14.7323
2086.12	14.8524
2089.04	14.8441
2091.95	14.4768
2094.86	13.4084
2097.77	13.9223
2100.68	13.897
2103.59	15.2625
2106.5	14.8497
2109.41	15.8351
2112.31	16.9724
2115.21	17.3454
2118.12	19.9624
2121.02	21.2939
2123.92	23.3866
2126.82	26.2962
2129.72	28.3874
2132.62	30.0671
2135.51	33.0945
2138.41	35.0424
2141.31	37.1977
2144.2	38.5367
2147.09	39.8224
2149.98	41.5856
2152.87	43.1893
2155.76	44.8776
2158.65	46.0902
2161.54	46.455
2164.43	47.5558
2167.31	48.4043
2170.2	49.4953
2173.08	50.6662
2175.96	50.9375
2178.84	50.6823
2181.72	50.3141
2184.6	49.3791
2187.48	48.0776
2190.36	48.1626
2193.23	46.5048
2196.11	45.6142
2198.98	44.1131
2201.85	42.1636
2204.72	40.2723
2207.59	38.4191
2210.46	35.7316
2213.33	33.0455
2216.2	30.2882
2219.07	28.6801
2221.93	27.2138
2224.8	25.2031
2227.66	23.5993
2230.52	22.9201
2233.39	22.6586
2236.25	21.0933
2239.1	20.6353
2241.96	20.737
2244.82	20.2746
2247.68	19.2297
2250.53	19.0867
2253.38	19.0986
2256.24	19.1288
2259.09	18.1983
2261.94	18.7703
2264.79	17.1945
2267.64	17.3819
2270.49	16.4553
2273.33	16.0629
2276.18	14.9216
2279.02	13.8725
2281.87	13.6566
2284.71	13.4515
2287.55	12.3766
2290.39	11.6178
2293.23	10.0143
2296.07	10.6686
2298.91	12.3428
2301.74	12.9445
2304.58	13.4343
2307.41	13.9372
2310.25	15.4062
2313.08	14.7319
2315.91	14.4181
2318.74	14.5803
2321.57	14.489
2324.4	13.9645
2327.23	13.9327
2330.05	13.2384
2332.88	11.4475
2335.7	10.311
2338.52	8.99465
2341.35	6.28069
2344.17	5.25258
2346.99	3.71872
2349.81	2.82702
2352.62	2.49116
2355.44	1.45458
2358.26	0.451616
2361.07	0.500319
2363.89	2.19575
2366.7	3.65378
2369.51	3.91716
2372.32	3.75041
2375.13	4.34607
2377.94	4.35287
2380.75	4.0019
2383.56	3.57557
2386.36	3.96382
2389.17	3.58988
2391.97	4.48484
2394.77	4.93462
2397.58	5.58985
2400.38	4.16543
2403.18	3.61776
2405.97	3.01681
2408.77	2.32084
2411.57	2.6135
2414.37	2.89223
2417.16	3.53926
2419.95	3.36738
2422.75	3.96771
2425.54	3.61291
2428.33	3.97784
2431.12	4.60689
2433.91	4.30929
2436.7	4.114
2439.48	4.52163
2442.27	4.23535
2445.05	4.9861
2447.84	5.22677
2450.62	4.75792
2453.4	4.47749
2456.18	4.55098
2458.96	5.64203
2461.74	6.6954
2464.52	5.66554
2467.29	4.68997
2470.07	3.78974
2472.85	3.82567
2475.62	2.92516
2478.39	3.04344
2481.16	3.3641
2483.93	3.12455
2486.7	2.05781
2489.47	2.39363
2492.24	2.33501
2495.01	2.09085
2497.77	1.58685
2500.54	1.04126
2503.3	0.467532
2506.06	0.745644
2508.83	1.33549
2511.59	1.26768
2514.35	1.07563
2517.11	0.731188
2519.86	0.285775
2522.62	0.0828309
2525.38	0.479201
2528.13	0.998693
2530.89	0.854252
2533.64	1.32786
2536.39	2.3037
2539.14	2.37656
2541.89	2.04425
2544.64	2.17096
2547.39	3.25639
2550.14	3.83612
2552.88	3.42718
2555.63	4.51845
2558.37	5.88578
2561.11	5.12685
2563.86	5.43065
2566.6	6.13211
2569.34	6.3814
2572.08	6.18084
2574.82	6.31387
2577.55	6.21753
2580.29	5.40214
2583.02	5.00161
2585.76	5.04614
2588.49	4.99253
2591.22	4.77811
2593.96	4.86798
2596.69	5.23718
2599.42	4.56079
2602.14	3.84069
2604.87	2.77868
2607.6	1.35069
2610.32	1.43571
2613.05	1.12792
2615.77	1.53969
2618.49	1.60881
2621.22	2.4973
2623.94	3.59758
2626.66	3.25278
2629.37	3.1689
2632.09	4.01338
2634.81	4.57068
2637.53	3.77209
2640.24	3.96103
2642.96	3.94277
2645.67	4.46408
2648.38	4.35808
2651.09	4.94109
2653.8	4.63417
2656.51	4.60493
2659.22	4.35191
2661.93	4.5287
2664.63	4.5024
2667.34	3.81306
2670.04	4.07177
2672.75	3.37533
2675.45	3.64698
2678.15	4.75865
2680.85	5.22283
2683.55	6.30269
2686.25	6.55043
2688.94	6.31186
2691.64	6.0429
2694.34	5.56937
2697.03	6.42405
2699.73	6.0457
2702.42	6.40822
2705.11	6.67441
2707.8	6.90348
2710.49	7.84849
2713.18	8.69272
2715.87	9.62187
2718.55	10.1467
2721.24	10.2485
2723.93	11.3002
2726.61	11.3074
2729.29	10.7351
2731.98	10.7731
2734.66	10.4508
2737.34	10.4944
2740.02	10.6744
2742.7	9.91075
2745.37	8.81646
2748.05	7.45751
2750.72	6.05163
2753.4	4.49002
2756.07	3.35844
2758.75	2.94983
2761.42	2.4767
2764.09	2.78807
2766.76	2.7565
2769.43	2.78755
2772.1	3.11666
2774.76	2.86352
2777.43	3.62852
2780.1	3.76711
2782.76	4.78219
2785.42	4.75112
2788.09	5.243
2790.75	4.91208
2793.41	3.81512
2796.07	3.11808
2798.73	3.01264
2801.39	2.74429
2804.04	2.0849
2806.7	0.325451
2809.35	-1.03372
2812.01	-1.48102
2814.66	-1.03271
2817.31	-1.19313
2819.96	1.46866
2822.61	5.30274
2825.26	9.55636
2827.91	14.1324
2830.56	18.2522
2833.21	22.3132
2835.85	27.0184
2838.5	32.9291
2841.14	39.0477
2843.78	45.4988
2846.42	53.5594
2849.06	61.1445
2851.71	70.9725
2854.34	80.2375
2856.98	88.8164
2859.62	97.6277
2862.26	106.147
2864.89	113.648
2867.53	120.338
2870.16	125.906
2872.79	130.446
2875.42	135.599
2878.05	140.049
2880.68	144.887
2883.31	148.619
2885.94	153.228
2888.57	157.308
2891.19	160.176
2893.82	163.553
2896.44	167.584
2899.07	171.862
2901.69	177.751
2904.31	184.622
2906.93	192.692
2909.55	201.983
2912.17	213.057
2914.79	223.935
2917.41	232.786
2920.02	239.979
2922.64	245.85
2925.25	249.963
2927.86	253.182
2930.48	253.267
2933.09	251.646
2935.7	248.781
2938.31	243.403
2940.92	237.732
2943.53	230.154
2946.13	222.676
2948.74	213.959
2951.34	206.113
2953.95	197.092
2956.55	187.653
2959.15	178.832
2961.75	170.133
2964.35	163.454
2966.95	155.971
2969.55	149.704
2972.15	143.817
2974.75	136.243
2977.34	129.132
2979.94	120.408
2982.53	112.52
2985.13	104.06
2987.72	95.5017
2990.31	86.735
2992.9	77.9605
2995.49	70.189
2998.08	62.6047
3000.67	55.281
3003.25	48.3029
3005.84	42.616
3008.42	37.4462
3011.01	33.176
3013.59	29.3456
3016.17	25.9501
3018.76	22.8149
3021.34	20.5178
3023.92	19.6425
3026.49	18.7429
3029.07	17.7298
3031.65	17.004
3034.23	17.1579
3036.8	16.8497
3039.38	17.7457
3041.95	19.0782
3044.52	20.23
3047.09	21.5684
3049.66	21.8333
3052.23	21.5536
3054.8	21.0965
3057.37	21.0684
3059.94	20.5005
3062.5	19.2711
3065.07	17.6532
3067.63	15.7107
3070.2	14.7667
3072.76	13.1447
3075.32	11.1017
3077.88	8.87392
3080.44	7.29526
3083	5.38673
3085.56	3.47233
3088.12	1.40428
3090.67	0.275256
3093.23	0.0078974
3095.78	0.105451
3098.34	-0.0350826
3100.89	-0.150686
3103.44	0.831332
3105.99	1.32378
3108.54	2.68296
3111.09	3.02535
3113.64	3.11024
3116.19	4.10801
3118.74	5.03913
3121.28	5.83115
3123.83	6.01743
3126.37	7.12711
3128.91	7.82114
3131.46	9.60952
3134	9.45358
3136.54	9.87218
3139.08	10.311
3141.62	10.4797
3144.16	10.947
3146.69	11.66
3149.23	12.5004