File: data/Raman/poly_smoothed/Thy_10_08_16_1x_45s_532 nm_x100_100%_600 gr_mm_01.txt
#Acq. time (s)=	45
#Accumulations=	2
#Range (cm-¹)=	200...3150
#Windows=	2
#Auto scanning=	Off
#Autofocus=	Off
#Macrospot=	Off
#AutoExposure=	Off
#Spike filter=	Multiple accum.
#Delay time (s)=	0
#Binning=	1
#Readout mode=	Signal
#DeNoise=	Off
#ICS correction=	On
#Dark correction=	Off
#Inst. Process=	Off
#Detector Gain=	Best Dynamic Range
#Detector ADC=	20 kHz
#Detector temperature (°C)=	-69.85
#Instrument=	LabRAM HR Evol
#Detector=	Synapse
#Objective=	x100
#Grating=	600 gr/mm
#ND Filter=	100%
#Laser (nm)=	532
#Hole=	100.021
#Range=	Auto
#Laser Pol.=	No
#Raman. Pol.=	No
#Laser Pol. (°)=	-0.0007625
#Raman Pol. (°)=	89.9995
#Collection=	Microscope
#StageXY=	Marzhauser
#StageZ=	Marzhauser
#X (µm)=	2181.6
#Y (µm)=	1242.6
#Z (µm)=	443.05
#Full time(mm:ss)=	3:18
#Project=
#Sample=
#Site=
#Title=	Thy_10_08_16_2x_45s_532 nm_x100_100%_600 gr_mm
#Remark=
#Date=	05.07.2022 15:20
#Acquired=	05.07.2022 15:20:16
#Base:Fit=	10.08.2022 09:46:25
#Base:Sub=	10.08.2022 09:46:49
#Filter:Polynom=	16.08.2022 10:24:56
#AxisType[0]=Intens
#AxisUnit[0]=Cnt
#AxisType[1]=Spectr
#AxisUnit[1]=1/cm
200.43	8.52548
204.059	8.82236
207.688	6.93585
211.314	6.2217
214.941	5.38039
218.564	6.18572
222.186	7.25538
225.809	7.37152
229.428	6.33347
233.045	7.32046
236.663	6.15547
240.278	6.4412
243.891	5.97091
247.503	4.64652
251.116	4.74638
254.725	3.84715
258.333	3.32833
261.939	4.74287
265.544	6.84449
269.148	6.25081
272.75	6.71568
276.351	7.6201
279.95	8.06286
283.548	7.94237
287.144	7.39991
290.739	6.33217
294.333	8.38239
297.925	8.25171
301.514	8.73628
305.104	9.75844
308.692	10.828
312.279	10.4521
315.862	10.5932
319.446	11.1717
323.029	11.1958
326.608	12.5913
330.188	12.0833
333.766	11.4085
337.341	11.7466
340.917	11.7011
344.489	10.4005
348.062	10.0355
351.631	10.6016
355.201	10.4782
358.768	9.09781
362.333	8.25516
365.899	7.31422
369.462	7.34514
373.023	5.67172
376.585	5.20243
380.143	2.31668
383.7	1.6772
387.256	0.394018
390.812	0.655968
394.365	0.266408
397.916	-0.0106849
401.467	1.54367
405.015	2.78627
408.563	3.02874
412.109	3.72465
415.654	4.20237
419.197	3.85181
422.739	4.02463
426.279	3.97796
429.819	4.34159
433.356	4.48189
436.891	4.96631
440.426	5.94063
443.96	4.50784
447.492	4.96787
451.021	4.78788
454.551	4.93682
458.079	4.55079
461.604	4.75019
465.13	5.33039
468.654	6.56249
472.175	7.74338
475.696	7.74888
479.215	9.78129
482.733	11.0695
486.249	12.2744
489.765	13.7026
493.278	14.07
496.789	14.4597
500.301	15.3334
503.81	15.4265
507.317	15.0011
510.825	15.5708
514.33	15.9774
517.833	16.2398
521.335	16.4425
524.836	15.6651
528.335	15.9487
531.835	14.336
535.332	14.7043
538.827	13.8901
542.321	14.0023
545.814	12.9802
549.305	11.2394
552.795	11.6133
556.282	11.5649
559.769	10.7347
563.255	10.2125
566.739	9.51495
570.223	8.07199
573.705	6.902
577.183	4.95333
580.663	3.95599
584.141	3.85652
587.615	3.16577
591.09	2.87897
594.564	3.0429
598.035	4.30362
601.506	4.48893
604.974	4.81025
608.443	6.15092
611.908	6.91201
615.374	7.47842
618.837	7.73432
622.3	9.51219
625.761	9.98566
629.219	10.7726
632.677	10.3867
636.135	13.0739
639.59	14.5767
643.043	15.9998
646.495	15.4214
649.948	15.4368
653.398	16.9287
656.846	17.5329
660.293	19.5499
663.738	21.2884
667.183	22.4309
670.626	24.5855
674.067	25.2778
677.508	25.9673
680.947	28.5204
684.385	30.4372
687.821	31.3849
691.254	32.5461
694.688	33.8349
698.121	34.4281
701.552	34.9572
704.98	35.7647
708.409	37.8248
711.836	39.3955
715.26	39.8058
718.685	41.5462
722.108	43.3017
725.528	43.3438
728.949	45.603
732.367	46.9574
735.785	48.888
739.2	51.2799
742.614	53.1914
746.028	55.2371
749.439	55.7428
752.849	59.1999
756.26	63.4297
759.667	66.7003
763.073	69.9607
766.477	72.3471
769.883	74.1958
773.285	76.2104
776.686	78.7822
780.085	79.4691
783.484	80.9701
786.881	82.6469
790.276	87.3919
793.671	88.7962
797.064	90.0922
800.456	91.6122
803.846	91.5548
807.234	91.6152
810.622	93.1523
814.008	91.0454
817.394	91.0712
820.778	91.5742
824.159	91.3471
827.541	91.0679
830.921	89.6687
834.298	87.6382
837.676	87.9607
841.051	86.0419
844.426	82.6594
847.798	79.8671
851.171	76.5373
854.54	73.8042
857.911	71.6154
861.278	69.0101
864.645	66.6368
868.01	66.5816
871.373	65.9748
874.735	64.3194
878.097	62.5387
881.457	62.2071
884.815	60.6762
888.172	60.6895
891.528	60.7507
894.882	60.1752
898.237	61.7537
901.589	62.2963
904.94	62.8577
908.289	63.6166
911.635	62.2269
914.982	61.5689
918.328	62.407
921.672	63.482
925.015	62.8319
928.357	62.4311
931.698	61.8923
935.035	61.1984
938.373	61.5372
941.71	59.644
945.044	57.3953
948.378	57.1726
951.709	57.1006
955.041	55.4689
958.372	53.415
961.699	50.9827
965.027	50.6105
968.352	50.5777
971.676	50.0028
975	49.5042
978.322	49.2992
981.642	49.8973
984.962	50.449
988.28	51.7398
991.596	50.1858
994.911	50.1996
998.227	50.606
1001.54	49.2724
1004.85	49.3256
1008.16	48.5272
1011.47	46.8755
1014.78	45.769
1018.08	44.4206
1021.39	44.3325
1024.69	42.4527
1028	42.0805
1031.3	42.0246
1034.6	40.9301
1037.9	38.9176
1041.19	37.1682
1044.49	36.7516
1047.78	37.7031
1051.08	37.5851
1054.37	38.6417
1057.66	38.9602
1060.95	38.7048
1064.24	38.6652
1067.53	38.5025
1070.81	37.2017
1074.1	36.713
1077.38	36.4222
1080.66	32.8734
1083.94	31.4978
1087.22	30.8727
1090.5	29.2943
1093.78	29.3768
1097.05	30.5013
1100.33	30.8228
1103.6	30.8918
1106.87	29.3509
1110.14	28.2253
1113.41	27.8808
1116.68	26.4768
1119.95	24.651
1123.21	24.7497
1126.48	23.886
1129.74	24.3391
1133	23.6977
1136.26	21.9447
1139.52	20.3821
1142.78	20.4759
1146.04	20.5391
1149.29	20.9767
1152.55	20.2232
1155.8	19.5103
1159.05	18.2798
1162.3	17.5325
1165.55	18.538
1168.8	19.6198
1172.05	21.724
1175.29	23.0598
1178.54	24.1506
1181.78	24.9624
1185.02	26.751
1188.26	27.8905
1191.5	29.3429
1194.74	30.1401
1197.97	32.6849
1201.21	34.8286
1204.44	35.7892
1207.68	37.7932
1210.91	38.5169
1214.14	39.5037
1217.37	42.1387
1220.59	44.0306
1223.82	47.1099
1227.05	48.649
1230.27	49.552
1233.49	51.9987
1236.72	52.7386
1239.94	53.6402
1243.16	53.9904
1246.37	54.718
1249.59	55.1779
1252.8	55.2624
1256.02	54.9121
1259.23	54.1062
1262.44	54.4422
1265.66	55.2558
1268.86	56.0818
1272.07	57.3956
1275.28	58.7834
1278.48	61.5779
1281.69	62.5394
1284.89	63.4927
1288.09	64.9961
1291.29	67.0709
1294.49	69.023
1297.69	71.1003
1300.89	71.6025
1304.08	74.4593
1307.28	75.8145
1310.47	77.8628
1313.66	79.5625
1316.85	78.744
1320.04	79.7284
1323.23	79.6672
1326.42	79.3929
1329.61	77.8896
1332.79	74.299
1335.97	72.6209
1339.16	71.9869
1342.34	71.2328
1345.52	70.1755
1348.7	69.7982
1351.87	68.9663
1355.05	66.884
1358.22	64.0808
1361.4	61.6143
1364.57	59.6867
1367.74	58.5192
1370.91	58.2043
1374.08	56.701
1377.25	55.5116
1380.41	54.9388
1383.58	55.2056
1386.74	54.8055
1389.91	53.8834
1393.07	51.1116
1396.23	51.1482
1399.39	51.2291
1402.55	49.4215
1405.7	48.0423
1408.86	47.6344
1412.01	49.3154
1415.17	52.2509
1418.32	54.6357
1421.47	56.383
1424.62	58.7138
1427.77	61.2335
1430.91	63.9154
1434.06	66.1434
1437.2	68.5518
1440.35	71.2087
1443.49	74.2332
1446.63	75.6198
1449.77	75.766
1452.91	74.7978
1456.05	72.5999
1459.18	70.2335
1462.32	67.1593
1465.45	62.9147
1468.59	58.7899
1471.72	52.5995
1474.85	47.0282
1477.98	41.4655
1481.1	37.527
1484.23	34.4404
1487.36	31.2
1490.48	28.5855
1493.61	25.5719
1496.73	23.1595
1499.85	22.4566
1502.97	21.6054
1506.09	20.9778
1509.2	21.0169
1512.32	19.5908
1515.43	18.3106
1518.55	19.3042
1521.66	19.3962
1524.77	18.8363
1527.88	20.2925
1530.99	20.3232
1534.1	21.7549
1537.21	24.3249
1540.31	24.9024
1543.42	25.666
1546.52	26.904
1549.62	29.4505
1552.72	32.9512
1555.82	36.6609
1558.92	38.8161
1562.02	40.0421
1565.11	42.3773
1568.21	47.1523
1571.3	51.0624
1574.39	54.5943
1577.49	56.543
1580.57	57.8792
1583.66	59.7674
1586.75	60.5935
1589.84	62.0212
1592.92	63.0061
1596.01	63.4048
1599.09	63.6526
1602.17	63.1627
1605.25	61.4104
1608.33	59.1854
1611.41	58.5093
1614.49	55.7213
1617.57	53.1916
1620.64	52.7062
1623.72	50.9836
1626.79	49.8489
1629.86	48.573
1632.93	49.2818
1636	48.9094
1639.07	50.3613
1642.13	53.7948
1645.2	56.353
1648.26	55.964
1651.33	57.9373
1654.39	59.1193
1657.45	59.5178
1660.51	59.0789
1663.57	58.863
1666.63	57.3628
1669.68	55.433
1672.74	52.4298
1675.79	48.9063
1678.85	46.0271
1681.9	42.5353
1684.95	39.1018
1688	34.6999
1691.05	30.1988
1694.09	26.7879
1697.14	24.1606
1700.18	21.6254
1703.23	20.4138
1706.27	19.5465
1709.31	18.2696
1712.35	16.9008
1715.39	16.3942
1718.43	15.0978
1721.47	14.3823
1724.5	12.7159
1727.54	12.2032
1730.57	10.1423
1733.61	7.81524
1736.64	6.90915
1739.67	6.51228
1742.7	4.79877
1745.72	3.55567
1748.75	3.07173
1751.77	2.53323
1754.8	2.6375
1757.82	2.00705
1760.84	0.729315
1763.87	0.203113
1766.89	0.682277
1769.91	0.74298
1772.92	1.18921
1775.94	1.17259
1778.95	0.786498
1781.97	1.16432
1784.98	1.21798
1787.99	1.53788
1791.01	1.56981
1794.01	1.69363
1797.02	1.72574
1800.03	0.978927
1803.04	0.632438
1806.04	0.286186
1809.05	1.11231
1812.05	1.06313
1815.05	2.38832
1818.05	1.74416
1821.05	2.40044
1824.05	3.51037
1827.05	3.81879
1830.04	4.67399
1833.04	5.067
1836.03	5.63977
1839.03	5.6771
1842.02	6.38369
1845.01	6.54721
1848	7.79405
1850.99	7.36979
1853.97	8.50157
1856.96	8.6788
1859.94	8.36536
1862.93	8.09718
1865.91	8.01768
1868.89	6.89012
1871.87	6.50346
1874.85	7.08521
1877.83	7.75582
1880.81	8.2972
1882.57	7.62861
1885.56	8.3924
1888.55	8.3122
1891.54	6.86111
1894.52	7.58607
1897.51	7.50319
1900.49	7.6953
1903.47	7.99665
1906.45	7.6505
1909.43	7.69727
1912.41	7.69682
1915.39	7.74279
1918.37	8.13428
1921.34	7.77238
1924.32	7.51377
1927.29	8.36586
1930.26	7.47349
1933.23	7.26993
1936.2	7.92736
1939.17	7.64017
1942.14	7.77732
1945.11	8.80647
1948.07	9.31271
1951.04	8.96893
1954	8.74791
1956.96	8.24417
1959.93	7.7969
1962.89	7.58762
1965.85	7.42843
1968.8	7.68736
1971.76	7.06685
1974.72	6.90503
1977.67	7.26032
1980.63	7.04976
1983.58	6.94029
1986.53	6.55162
1989.48	7.34357
1992.43	7.47324
1995.38	7.44734
1998.32	8.51678
2001.27	9.52592
2004.22	9.0849
2007.16	8.42148
2010.1	8.80016
2013.04	9.08035
2015.98	9.04862
2018.92	8.98262
2021.86	9.70523
2024.8	9.17144
2027.74	9.73632
2030.67	10.1515
2033.61	11.1754
2036.54	10.9181
2039.47	10.8032
2042.4	11.3088
2045.33	11.5037
2048.26	13.3574
2051.19	12.3931
2054.12	12.4171
2057.04	12.5712
2059.97	13.0012
2062.89	13.1106
2065.81	13.1101
2068.73	12.8067
2071.65	13.3492
2074.57	11.7849
2077.49	11.3428
2080.41	11.0896
2083.32	11.3039
2086.24	11.2632
2089.15	12.0058
2092.07	12.4068
2094.98	11.7594
2097.89	12.1156
2100.8	12.0535
2103.71	10.9939
2106.61	11.0122
2109.52	11.7619
2112.43	12.0982
2115.33	12.7876
2118.23	13.8397
2121.13	14.3129
2124.04	14.871
2126.94	16.3366
2129.83	17.189
2132.73	18.2018
2135.63	20.0317
2138.53	20.9153
2141.42	21.4811
2144.31	21.7682
2147.21	23.8307
2150.1	24.6477
2152.99	26.0594
2155.88	26.6091
2158.77	26.8368
2161.65	27.1864
2164.54	27.4596
2167.43	26.9527
2170.31	26.8467
2173.19	26.5172
2176.07	25.9511
2178.96	25.962
2181.84	25.3937
2184.72	25.4075
2187.59	25.954
2190.47	25.3425
2193.35	25.6539
2196.22	25.6614
2199.09	25.0421
2201.97	25.1528
2204.84	24.4596
2207.71	24.0175
2210.58	22.1539
2213.45	21.3789
2216.31	21.2943
2219.18	21.1505
2222.05	20.0744
2224.91	17.927
2227.78	17.0175
2230.64	17.1148
2233.5	16.5656
2236.36	16.748
2239.22	15.7196
2242.08	16.2075
2244.93	15.0295
2247.79	14.6603
2250.64	15.0255
2253.5	15.221
2256.35	15.459
2259.2	15.89
2262.05	15.3643
2264.9	14.9371
2267.75	14.7681
2270.6	13.4111
2273.45	13.0372
2276.29	12.1765
2279.14	11.2637
2281.98	11.3386
2284.82	11.4916
2287.66	9.97833
2290.5	8.77746
2293.34	6.94246
2296.18	6.22675
2299.02	7.3081
2301.86	9.05362
2304.69	9.94053
2307.53	10.8164
2310.36	11.3355
2313.19	11.6378
2316.02	11.8856
2318.85	13.4453
2321.68	14.306
2324.51	13.7843
2327.34	13.6527
2330.16	12.932
2332.99	12.4841
2335.81	12.0397
2338.64	11.4594
2341.46	11.1718
2344.28	10.7429
2347.1	9.54244
2349.92	8.81483
2352.74	7.73485
2355.55	5.32649
2358.37	4.44672
2361.19	3.30803
2364	3.25798
2366.81	4.41658
2369.62	5.42946
2372.44	6.03585
2375.24	5.76058
2378.05	5.58311
2380.86	4.76677
2383.67	5.28695
2386.47	4.68157
2389.28	4.51209
2392.08	3.80495
2394.89	3.32361
2397.69	3.17365
2400.49	3.02748
2403.29	4.66756
2406.09	6.34132
2408.88	7.20295
2411.68	7.54612
2414.48	7.07335
2417.27	7.82877
2420.06	7.58069
2422.86	7.07473
2425.65	7.23046
2428.44	6.93837
2431.23	7.10172
2434.02	6.59327
2436.81	6.96667
2439.59	6.91125
2442.38	6.2873
2445.16	5.75292
2447.95	4.66658
2450.73	3.85816
2453.51	3.51024
2456.29	2.56243
2459.07	1.87159
2461.85	1.67281
2464.63	1.53885
2467.4	1.71536
2470.18	2.81805
2472.95	3.03245
2475.73	1.84152
2478.5	1.6486
2481.27	0.444779
2484.04	0.0909089
2486.81	-0.340612
2489.58	0.141139
2492.35	-0.145413
2495.12	-0.804029
2497.88	-0.0699445
2500.65	0.132047
2503.41	-0.043967
2506.17	1.07271
2508.94	1.02202
2511.7	0.745147
2514.46	0.70532
2517.22	0.826222
2519.97	1.19394
2522.73	1.21939
2525.49	2.07945
2528.24	2.5104
2530.99	2.71387
2533.75	3.32068
2536.5	3.57829
2539.25	3.50005
2542	3.78696
2544.75	3.40324
2547.5	3.18312
2550.24	2.78288
2552.99	2.27227
2555.74	2.15786
2558.48	1.98943
2561.22	2.20749
2563.96	2.51089
2566.71	2.77341
2569.45	2.80716
2572.18	3.72501
2574.92	4.62024
2577.66	4.06954
2580.4	4.28878
2583.13	3.93114
2585.87	4.04789
2588.6	5.39507
2591.33	5.24912
2594.06	5.33285
2596.79	4.82478
2599.52	4.38032
2602.25	4.41712
2604.98	4.27836
2607.71	3.0456
2610.43	2.5189
2613.16	1.99538
2615.88	1.16761
2618.6	-0.193239
2621.32	-0.160237
2624.04	-0.0703179
2626.76	-0.58563
2629.48	-1.54829
2632.2	-1.58216
2634.92	-1.50455
2637.63	-0.81068
2640.35	-0.224469
2643.06	0.224846
2645.77	1.13651
2648.49	1.71037
2651.2	2.51732
2653.91	3.11523
2656.62	3.0322
2659.33	2.39745
2662.03	3.48807
2664.74	3.76903
2667.44	4.3537
2670.15	4.7463
2672.85	4.99207
2675.55	5.54107
2678.26	6.68217
2680.96	5.71874
2683.66	5.49944
2686.35	5.7782
2689.05	5.68772
2691.75	6.29797
2694.44	6.16589
2697.14	5.45188
2699.83	6.56734
2702.52	7.22251
2705.22	8.10854
2707.91	9.18831
2710.6	9.74693
2713.29	10.3163
2715.97	10.7614
2718.66	10.4435
2721.35	10.3992
2724.03	10.3029
2726.72	9.95457
2729.4	9.82131
2732.08	9.35695
2734.76	9.97826
2737.44	9.71629
2740.12	10.5444
2742.8	10.3125
2745.48	10.021
2748.16	9.11109
2750.83	9.71583
2753.51	10.1344
2756.18	9.95471
2758.85	9.93686
2761.53	8.45486
2764.2	7.86939
2766.87	7.43189
2769.54	7.34768
2772.2	7.34071
2774.87	7.10008
2777.54	6.84054
2780.2	6.01206
2782.87	4.86408
2785.53	4.19665
2788.19	4.52549
2790.85	3.70946
2793.51	2.84312
2796.17	3.71576
2798.83	3.83579
2801.49	4.31927
2804.15	4.52269
2806.8	5.62415
2809.46	5.6161
2812.11	5.99224
2814.76	6.4216
2817.42	7.3918
2820.07	8.35044
2822.72	9.52922
2825.37	11.3642
2828.02	13.6501
2830.66	16.2881
2833.31	19.8836
2835.96	23.0089
2838.6	25.9712
2841.24	30.1438
2843.89	33.5268
2846.53	38.8898
2849.17	44.5776
2851.81	50.3544
2854.45	55.2537
2857.09	60.5573
2859.72	65.9502
2862.36	71.2222
2865	75.5724
2867.63	80.3444
2870.26	84.6299
2872.9	88.1631
2875.53	90.9437
2878.16	94.5019
2880.79	96.5517
2883.42	98.4639
2886.05	101.316
2888.67	105.504
2891.3	108.622
2893.92	111.561
2896.55	115.075
2899.17	119.501
2901.79	123.656
2904.42	129.196
2907.04	135.316
2909.66	141.278
2912.27	149.372
2914.89	155.663
2917.51	161.367
2920.13	166.727
2922.74	171.907
2925.35	174.187
2927.97	176.27
2930.58	177.614
2933.19	177.249
2935.8	176.52
2938.41	174.44
2941.02	171.435
2943.63	166.847
2946.24	162.185
2948.84	158.455
2951.45	154.767
2954.05	149.064
2956.65	143.437
2959.26	137.619
2961.86	132.903
2964.46	127.006
2967.06	121.549
2969.66	116.93
2972.25	112.147
2974.85	107.598
2977.45	103.568
2980.04	98.2103
2982.64	92.1243
2985.23	85.8877
2987.82	80.2193
2990.41	74.0715
2993	69.2813
2995.59	64.3676
2998.18	58.3868
3000.77	53.8483
3003.36	48.6903
3005.94	43.6878
3008.53	39.2804
3011.11	36.0881
3013.69	32.7391
3016.28	28.7846
3018.86	26.6754
3021.44	24.1467
3024.02	21.946
3026.6	19.9552
3029.18	18.9609
3031.75	18.2003
3034.33	18.0927
3036.9	18.6953
3039.48	18.7446
3042.05	18.9763
3044.62	19.782
3047.19	20.3492
3049.77	21.2415
3052.34	22.0356
3054.9	22.6851
3057.47	23.3163
3060.04	22.8132
3062.61	22.145
3065.17	21.2279
3067.74	19.4397
3070.3	17.5616
3072.86	16.8456
3075.42	15.7855
3077.99	14.9148
3080.54	13.0384
3083.1	11.6309
3085.66	10.0327
3088.22	8.07044
3090.78	6.33856
3093.33	4.77681
3095.89	3.76105
3098.44	3.23533
3100.99	2.83802
3103.54	2.78114
3106.1	3.06004
3108.65	3.18744
3111.2	2.47646
3113.74	2.94521
3116.29	2.66681
3118.84	2.86713
3121.38	2.8161
3123.93	2.63754
3126.47	2.06231
3129.01	1.81254
3131.56	2.01628
3134.1	2.51298
3136.64	3.35793
3139.18	2.96764
3141.72	2.45187
3144.26	2.02308
3146.79	2.15261
3149.33	3.00184