File: data/Raman/poly_smoothed/Thy_50_12_43_1x_45s_532 nm_x100_100%_600 gr_mm_01.txt
#Acq. time (s)=	45
#Accumulations=	2
#Range (cm-¹)=	200...3150
#Windows=	2
#Auto scanning=	Off
#Autofocus=	Off
#Macrospot=	Off
#AutoExposure=	Off
#Spike filter=	Multiple accum.
#Delay time (s)=	0
#Binning=	1
#Readout mode=	Signal
#DeNoise=	Off
#ICS correction=	On
#Dark correction=	Off
#Inst. Process=	Off
#Detector Gain=	Best Dynamic Range
#Detector ADC=	20 kHz
#Detector temperature (°C)=	-69.85
#Instrument=	LabRAM HR Evol
#Detector=	Synapse
#Objective=	x100
#Grating=	600 gr/mm
#ND Filter=	100%
#Laser (nm)=	532
#Hole=	100.021
#Range=	Auto
#Laser Pol.=	No
#Raman. Pol.=	No
#Laser Pol. (°)=	-0.0007625
#Raman Pol. (°)=	89.9995
#Collection=	Microscope
#StageXY=	Marzhauser
#StageZ=	Marzhauser
#X (µm)=	-5120.9
#Y (µm)=	1523
#Z (µm)=	63.25
#Full time(mm:ss)=	3:18
#Project=
#Sample=
#Site=
#Title=	Thy_50_12_43_2x_45s_532 nm_x100_100%_600 gr_mm
#Remark=
#Date=	07.07.2022 12:23
#Acquired=	07.07.2022 12:23:57
#Base:Fit=	10.08.2022 10:04:30
#Base:Sub=	10.08.2022 10:04:45
#Filter:Polynom=	16.08.2022 10:20:25
#AxisType[0]=Intens
#AxisUnit[0]=Cnt
#AxisType[1]=Spectr
#AxisUnit[1]=1/cm
200.43	42.0881
204.061	35.7376
207.688	31.4781
211.316	26.4491
214.941	21.9332
218.566	17.9222
222.188	15.1022
225.809	11.6544
229.43	7.69463
233.047	7.20518
236.663	6.7341
240.278	3.47072
243.894	1.77845
247.506	1.53373
251.116	2.06656
254.725	2.04836
258.333	3.30815
261.939	2.57281
265.546	4.3414
269.15	6.55311
272.752	7.27696
276.353	8.23041
279.952	6.65449
283.55	6.74574
287.146	7.35439
290.739	8.82885
294.333	9.1564
297.925	9.8939
301.516	11.3383
305.106	11.5523
308.694	13.6328
312.279	14.6972
315.864	14.4123
319.448	14.2837
323.029	15.8727
326.61	13.7692
330.19	12.041
333.766	12.7686
337.343	12.4711
340.917	11.0912
344.491	11.3944
348.062	12.0285
351.633	11.5298
355.201	10.3674
358.77	8.42695
362.335	5.27488
365.899	4.59214
369.464	3.93358
373.025	5.35715
376.585	4.44066
380.143	5.71157
383.702	6.52943
387.258	6.49493
390.812	7.64881
394.365	8.05263
397.916	6.52148
401.467	6.14654
405.015	6.29397
408.565	6.18189
412.111	6.26969
415.656	4.94041
419.197	4.61931
422.739	5.35564
426.279	5.59142
429.819	4.97172
433.356	6.1168
436.893	5.62562
440.428	4.64461
443.96	3.73628
447.492	4.68697
451.023	6.67526
454.553	9.75902
458.079	9.68203
461.606	10.8069
465.132	12.9667
468.654	14.5909
472.177	14.0952
475.696	14.8025
479.217	14.948
482.733	14.9408
486.251	16.593
489.765	19.7004
493.278	21.026
496.791	21.5042
500.301	21.0451
503.81	20.7283
507.319	22.7042
510.825	22.122
514.33	22.4318
517.833	22.8579
521.337	21.4333
524.838	20.6952
528.337	20.3334
531.835	20.1528
535.332	20.0978
538.827	19.1937
542.321	19.3313
545.814	18.3398
549.305	16.1088
552.795	14.0522
556.284	13.1653
559.771	11.2566
563.257	9.92651
566.742	8.61982
570.223	7.98933
573.705	6.98369
577.185	5.52042
580.665	3.71214
584.141	2.22972
587.617	2.67332
591.092	2.71841
594.564	1.48726
598.037	2.45657
601.506	3.54743
604.976	2.6476
608.443	2.96292
611.91	4.37372
615.374	5.12987
618.839	6.08799
622.3	9.281
625.761	11.4664
629.221	11.0928
632.679	13.3411
636.135	14.7619
639.592	16.0698
643.045	17.174
646.497	18.1552
649.948	18.2164
653.398	18.2889
656.846	20.0148
660.293	21.0847
663.738	22.4598
667.185	23.8141
670.628	23.6053
674.067	22.6659
677.508	21.9309
680.947	23.9806
684.385	26.0238
687.821	25.9156
691.256	27.397
694.69	28.9843
698.121	31.5306
701.552	32.8416
704.982	35.7085
708.41	37.105
711.836	38.549
715.262	39.3966
718.685	41.4059
722.108	41.9394
725.53	42.7782
728.949	46.005
732.369	46.7849
735.785	47.8709
739.2	49.0813
742.616	49.7046
746.028	51.7882
749.441	52.5053
752.851	54.8511
756.26	56.8367
759.667	59.7685
763.075	64.2462
766.479	68.1112
769.883	71.1615
773.285	73.6816
776.686	78.3891
780.085	81.6177
783.484	85.1118
786.881	87.3731
790.276	90.1734
793.671	90.6738
797.064	91.2182
800.456	92.5987
803.846	92.8272
807.236	93.3818
810.624	93.1751
814.01	92.9888
817.394	91.6804
820.778	89.0501
824.161	86.128
827.543	85.6779
830.921	86.3442
834.3	84.2928
837.676	83.1084
841.053	80.8229
844.426	78.8512
847.8	76.5733
851.171	73.9877
854.542	70.7592
857.911	68.5605
861.279	66.1641
864.645	63.6723
868.01	62.0398
871.375	59.1124
874.737	56.35
878.097	53.8855
881.457	53.4299
884.817	52.2519
888.174	50.3502
891.53	50.9209
894.884	49.3957
898.237	50.5312
901.589	50.6399
904.94	51.0823
908.289	53.1383
911.637	55.6377
914.984	56.1155
918.33	56.6131
921.674	55.9644
925.015	56.4155
928.357	56.9408
931.698	55.7656
935.037	53.4003
938.373	53.311
941.71	51.0447
945.046	48.2104
948.378	44.9339
951.711	43.283
955.043	41.8376
958.372	41.8355
961.701	41.2225
965.027	42.1789
968.354	41.5221
971.678	40.3479
975	39.6421
978.324	40.4947
981.644	41.8668
984.962	41.947
988.282	43.072
991.598	43.1792
994.913	43.7192
998.227	43.5347
1001.54	43.4512
1004.85	43.1464
1008.16	42.515
1011.47	39.927
1014.78	39.1263
1018.08	38.0172
1021.39	37.7779
1024.69	37.2309
1028	39.0119
1031.3	41.205
1034.6	42.8569
1037.9	44.2708
1041.19	43.4006
1044.49	44.8215
1047.79	44.7162
1051.08	43.2683
1054.37	42.2489
1057.66	41.1078
1060.95	39.2151
1064.24	37.1559
1067.53	35.3821
1070.81	32.884
1074.1	30.7803
1077.38	27.2893
1080.66	25.9208
1083.94	22.9469
1087.22	21.8627
1090.5	19.8286
1093.78	20.4751
1097.05	20.2115
1100.33	20.2392
1103.6	21.2612
1106.87	21.098
1110.15	19.7612
1113.41	18.4298
1116.68	16.5752
1119.95	15.7253
1123.21	14.5969
1126.48	14.6631
1129.74	13.2236
1133	12.0159
1136.26	11.0808
1139.52	9.87242
1142.78	9.095
1146.04	9.28591
1149.29	9.1908
1152.55	7.64984
1155.8	8.68699
1159.05	9.2978
1162.3	10.8394
1165.55	10.9839
1168.8	11.1827
1172.05	11.4364
1175.29	12.867
1178.54	12.3318
1181.78	12.2399
1185.02	11.9027
1188.26	11.0492
1191.5	10.3339
1194.74	10.8933
1197.97	12.1722
1201.21	13.7361
1204.44	15.0835
1207.68	16.468
1210.91	18.978
1214.14	20.5011
1217.37	22.1579
1220.6	24.3113
1223.82	27.7395
1227.05	30.1021
1230.27	32.1808
1233.49	34.1282
1236.72	36.4574
1239.94	38.5506
1243.16	40.7084
1246.37	42.1795
1249.59	44.6897
1252.8	47.3141
1256.02	48.131
1259.23	50.2049
1262.44	51.0447
1265.66	52.3599
1268.87	55.2037
1272.07	58.4268
1275.28	59.707
1278.48	60.0747
1281.69	62.0675
1284.89	64.1166
1288.09	65.1085
1291.3	64.5323
1294.49	66.0001
1297.69	66.4105
1300.89	68.551
1304.09	68.4685
1307.28	67.5203
1310.47	68.0496
1313.66	67.5274
1316.86	68.0833
1320.05	68.3622
1323.23	66.0818
1326.42	66.4644
1329.61	63.4188
1332.79	60.2529
1335.98	59.377
1339.16	58.3119
1342.34	56.142
1345.52	54.9728
1348.7	51.197
1351.87	47.597
1355.05	44.2577
1358.23	43.3568
1361.4	40.2958
1364.57	39.329
1367.74	38.4701
1370.91	38.1662
1374.08	37.3531
1377.25	38.0061
1380.42	36.3271
1383.58	36.2512
1386.75	36.3182
1389.91	36.4371
1393.07	36.8181
1396.23	36.7714
1399.39	38.393
1402.55	38.3313
1405.7	39.0794
1408.86	39.7044
1412.01	41.5932
1415.17	43.2559
1418.32	45.2459
1421.47	47.7276
1424.62	50.9282
1427.77	55.2788
1430.92	59.0175
1434.06	65.0484
1437.2	69.0722
1440.35	72.7957
1443.49	75.4582
1446.63	77.8445
1449.77	78.9745
1452.91	78.4623
1456.05	78.625
1459.18	78.4888
1462.32	76.8082
1465.45	72.6173
1468.59	68.6941
1471.72	63.9706
1474.85	58.555
1477.98	51.8089
1481.11	46.2618
1484.23	41.3885
1487.36	36.2906
1490.48	32.1518
1493.61	28.3464
1496.73	24.9306
1499.85	23.7594
1502.97	23.2474
1506.09	23.5896
1509.2	23.4533
1512.32	24.013
1515.44	24.139
1518.55	24.0232
1521.66	24.7631
1524.77	26.8473
1527.88	28.2969
1530.99	30.2514
1534.1	32.4574
1537.21	34.0121
1540.31	34.7707
1543.42	37.2655
1546.52	38.8795
1549.62	41.8513
1552.72	44.0622
1555.82	46.1728
1558.92	48.1888
1562.02	50.1773
1565.11	51.5386
1568.21	54.5141
1571.3	55.912
1574.39	58.3884
1577.49	61.8268
1580.58	63.6743
1583.67	65.3983
1586.75	66.4296
1589.84	67.0386
1592.93	65.5074
1596.01	65.0866
1599.09	65.257
1602.18	64.8097
1605.26	64.2629
1608.34	63.438
1611.41	62.8605
1614.49	62.0993
1617.57	61.0485
1620.64	61.5727
1623.72	61.2695
1626.79	61.5796
1629.86	62.0214
1632.93	63.4681
1636	65.5748
1639.07	67.0252
1642.14	69.1498
1645.2	70.307
1648.27	71.4036
1651.33	72.357
1654.39	72.622
1657.45	71.9733
1660.51	72.0243
1663.57	69.3757
1666.63	65.3565
1669.69	61.3919
1672.74	59.2276
1675.79	55.4423
1678.85	51.8634
1681.9	46.2513
1684.95	41.3142
1688	36.2704
1691.05	30.9677
1694.1	26.6006
1697.14	23.287
1700.19	21.4464
1703.23	18.993
1706.27	16.7552
1709.32	15.4133
1712.35	13.5972
1715.39	12.4804
1718.43	11.3541
1721.47	10.7274
1724.5	10.3816
1727.54	9.47229
1730.57	9.25187
1733.61	9.49454
1736.64	9.09885
1739.67	7.96399
1742.7	8.2939
1745.72	8.90107
1748.75	9.22378
1751.78	9.13682
1754.8	8.86336
1757.82	7.93028
1760.85	7.13271
1763.87	6.85749
1766.89	5.53284
1769.91	5.77898
1772.92	5.77787
1775.94	5.26202
1778.96	4.34598
1781.97	3.6652
1784.98	3.26166
1788	2.79775
1791.01	2.2556
1794.01	1.90886
1797.02	0.926465
1800.03	0.48806
1803.04	0.334768
1806.04	0.831638
1809.05	1.09235
1812.05	1.15989
1815.05	1.88566
1818.05	1.09706
1821.05	1.11646
1824.05	0.94111
1827.05	0.657225
1830.04	0.0630223
1833.04	0.280648
1836.03	0.890771
1839.03	1.57233
1842.02	1.51963
1845.01	1.70727
1848	1.80348
1850.99	1.04266
1853.97	1.06024
1856.96	1.61814
1859.94	2.13696
1862.93	1.40887
1865.91	1.99568
1868.89	1.69525
1871.87	2.1063
1874.85	2.77475
1877.83	3.09342
1880.81	4.16175
1882.56	4.19305
1885.55	4.02749
1888.54	3.98413
1891.52	4.78203
1894.51	5.10249
1897.49	4.87535
1900.48	4.76003
1903.46	5.57482
1906.44	6.40849
1909.42	7.32159
1912.4	7.20846
1915.38	6.28085
1918.35	6.17604
1921.33	6.00669
1924.3	5.45637
1927.28	5.34114
1930.25	5.0233
1933.22	4.58375
1936.19	4.26636
1939.16	4.45375
1942.13	3.9298
1945.09	3.59592
1948.06	2.80842
1951.03	2.95823
1953.99	2.79171
1956.95	1.53821
1959.91	1.99235
1962.87	1.86381
1965.83	2.47559
1968.79	0.744498
1971.75	1.00193
1974.7	1.98016
1977.66	1.60173
1980.61	1.21209
1983.56	1.4291
1986.52	2.47883
1989.47	3.20228
1992.41	3.8644
1995.36	4.76326
1998.31	4.2185
2001.26	4.43309
2004.2	4.86415
2007.15	5.2568
2010.09	5.64567
2013.03	4.55506
2015.97	5.14413
2018.91	5.1712
2021.85	5.09282
2024.79	5.3442
2027.72	3.65624
2030.66	5.07063
2033.59	6.22363
2036.53	6.64027
2039.46	6.76085
2042.39	7.67025
2045.32	8.24117
2048.25	8.30832
2051.18	9.42356
2054.1	11.0982
2057.03	11.8677
2059.95	12.9695
2062.88	13.8995
2065.8	13.6793
2068.72	14.8356
2071.64	16.8118
2074.56	18.2532
2077.48	18.8284
2080.39	19.2113
2083.31	19.9252
2086.22	20.7661
2089.14	22.9913
2092.05	24.6309
2094.96	26.0798
2097.87	28.0537
2100.78	30.7085
2103.69	34.5437
2106.6	37.0184
2109.51	39.6614
2112.41	42.7575
2115.32	46.4487
2118.22	49.9432
2121.12	53.0776
2124.02	54.997
2126.92	57.1114
2129.82	59.5415
2132.72	63.1233
2135.62	67.2023
2138.51	69.247
2141.41	71.9421
2144.3	74.6075
2147.19	77.0909
2150.09	79.5881
2152.97	81.8946
2155.86	83.8897
2158.75	86.6804
2161.64	88.4768
2164.53	90.2947
2167.41	92.4754
2170.3	93.4156
2173.18	94.9162
2176.06	95.6323
2178.94	95.5497
2181.82	95.1279
2184.7	93.1294
2187.58	91.1335
2190.46	88.3035
2193.33	85.25
2196.21	82.2673
2199.08	79.6791
2201.95	77.0481
2204.83	74.3512
2207.7	70.6466
2210.57	67.0096
2213.43	63.3921
2216.3	60.6452
2219.17	57.8066
2222.03	54.297
2224.9	50.4797
2227.76	47.6292
2230.62	45.1171
2233.49	43.7994
2236.34	41.7076
2239.2	39.1572
2242.06	36.6052
2244.92	35.0579
2247.78	32.9053
2250.63	30.7528
2253.48	29.2945
2256.34	27.0919
2259.19	25.5958
2262.04	23.3118
2264.89	21.8375
2267.74	20.5799
2270.59	20.0823
2273.43	19.6236
2276.28	18.4526
2279.12	17.3752
2281.97	14.3427
2284.81	12.9707
2287.65	11.7502
2290.49	9.60956
2293.33	8.3934
2296.17	9.25797
2299.01	9.9144
2301.84	11.0934
2304.68	11.9264
2307.51	12.4611
2310.35	11.7543
2313.18	11.815
2316.01	11.5799
2318.84	11.5056
2321.67	10.8205
2324.5	10.2449
2327.33	10.0438
2330.15	9.29817
2332.98	8.28878
2335.8	7.91575
2338.62	8.37429
2341.45	7.39449
2344.27	5.01429
2347.09	3.1348
2349.91	1.89739
2352.72	1.81952
2355.54	2.48471
2358.36	2.14062
2361.17	2.21089
2363.98	4.56017
2366.8	5.77943
2369.61	5.8168
2372.42	5.60479
2375.23	5.74751
2378.04	5.06347
2380.85	5.01658
2383.66	5.35955
2386.46	5.04704
2389.26	5.52973
2392.07	6.14936
2394.87	6.20196
2397.67	5.71806
2400.47	5.74779
2403.27	7.52614
2406.07	8.47566
2408.87	8.51574
2411.67	8.31908
2414.46	9.19032
2417.26	10.775
2420.05	11.0532
2422.84	11.9981
2425.64	11.8606
2428.43	11.3501
2431.22	11.9709
2434.01	11.2354
2436.79	10.6197
2439.58	9.43176
2442.37	9.45409
2445.15	9.36109
2447.93	8.78227
2450.72	7.40524
2453.5	7.3144
2456.28	6.66878
2459.06	6.03867
2461.84	6.39046
2464.62	7.05995
2467.39	7.18911
2470.17	7.67122
2472.94	8.2328
2475.72	7.28867
2478.49	6.971
2481.26	7.55243
2484.03	7.01026
2486.8	5.9785
2489.57	5.79388
2492.34	6.24011
2495.1	5.26079
2497.87	5.62205
2500.63	4.84948
2503.4	3.96586
2506.16	3.95009
2508.92	3.622
2511.68	3.61577
2514.44	3.05776
2517.2	2.74122
2519.96	2.72912
2522.72	2.67073
2525.47	2.99728
2528.23	3.57915
2530.98	4.15863
2533.74	3.90739
2536.49	3.2814
2539.24	3.51538
2541.99	3.13112
2544.74	3.3753
2547.49	4.06895
2550.23	3.9224
2552.98	4.07002
2555.72	4.03676
2558.47	3.68009
2561.21	4.2053
2563.95	4.15654
2566.69	5.04236
2569.43	5.13656
2572.17	5.79731
2574.91	5.47919
2577.65	5.54005
2580.39	6.33446
2583.12	6.04087
2585.85	6.50929
2588.59	6.1375
2591.32	6.13246
2594.05	6.16272
2596.78	5.02619
2599.51	3.93299
2602.24	3.64266
2604.97	4.17536
2607.69	4.73276
2610.42	3.90088
2613.14	3.8098
2615.87	3.62283
2618.59	2.6788
2621.31	1.69124
2624.03	1.12981
2626.75	0.968416
2629.47	1.16028
2632.19	0.726595
2634.91	1.31383
2637.62	1.40876
2640.34	0.300708
2643.05	1.28861
2645.76	1.75062
2648.48	2.30502
2651.19	2.70689
2653.9	2.94545
2656.6	2.63079
2659.31	2.86649
2662.02	2.27847
2664.73	2.72774
2667.43	4.70457
2670.14	4.93602
2672.84	5.13591
2675.54	4.08947
2678.24	3.57343
2680.94	3.08969
2683.64	2.16104
2686.34	1.9068
2689.04	3.5287
2691.74	2.94649
2694.43	2.43231
2697.13	2.9406
2699.82	2.57915
2702.51	3.51368
2705.21	2.82166
2707.9	3.28356
2710.58	5.14416
2713.27	5.63883
2715.96	6.59681
2718.65	7.60903
2721.33	7.48222
2724.02	8.82925
2726.71	8.37321
2729.39	8.73967
2732.07	9.48846
2734.75	9.17954
2737.43	8.41124
2740.11	9.27822
2742.79	8.37407
2745.47	8.01581
2748.14	7.24555
2750.82	7.44257
2753.49	7.97954
2756.17	7.87445
2758.84	6.55368
2761.51	6.36646
2764.18	5.70423
2766.85	5.40732
2769.52	4.99491
2772.19	4.04376
2774.86	5.11632
2777.52	4.237
2780.19	3.75586
2782.85	2.56051
2785.52	1.48255
2788.18	1.60885
2790.84	0.933175
2793.5	0.808825
2796.16	0.635804
2798.82	1.70112
2801.48	0.838211
2804.13	1.07033
2806.79	-0.133935
2809.45	-1.47548
2812.1	-1.79627
2814.75	-0.937417
2817.41	0.44151
2820.06	2.90828
2822.71	5.16345
2825.36	8.6639
2828	12.2746
2830.65	15.9455
2833.3	20.1128
2835.94	23.8648
2838.59	27.4219
2841.23	31.3963
2843.87	35.742
2846.52	42.835
2849.16	50.1594
2851.8	58.7191
2854.44	66.9723
2857.08	74.5913
2859.71	81.7947
2862.35	89.2476
2864.98	94.5991
2867.62	100.269
2870.25	105.556
2872.88	110.743
2875.52	115.286
2878.15	120.312
2880.78	123.643
2883.41	129.004
2886.03	133.464
2888.66	136.592
2891.29	139.619
2893.91	143.48
2896.54	147.377
2899.16	151.36
2901.78	156.163
2904.4	163.417
2907.02	171.797
2909.64	181.66
2912.26	191.557
2914.88	200.782
2917.5	209.868
2920.11	216.64
2922.73	222.598
2925.34	226.511
2927.96	229.35
2930.57	232.107
2933.18	232.018
2935.79	228.334
2938.4	224.391
2941.01	218.686
2943.62	212.175
2946.22	204.919
2948.83	196.881
2951.43	187.53
2954.04	177.411
2956.64	168.531
2959.24	159.847
2961.84	151.272
2964.45	144.23
2967.05	137.218
2969.64	130.91
2972.24	123.825
2974.84	117.119
2977.43	110.324
2980.03	103.895
2982.62	96.144
2985.22	89.035
2987.81	81.7706
2990.4	74.1483
2992.99	66.4691
2995.58	59.2052
2998.17	51.8886
3000.76	45.0165
3003.34	39.6101
3005.93	33.7195
3008.52	28.4265
3011.1	24.0561
3013.68	19.0727
3016.27	14.6595
3018.85	11.8454
3021.43	10.1205
3024.01	7.9934
3026.59	5.73021
3029.16	5.20351
3031.74	4.46277
3034.32	4.37618
3036.89	4.82562
3039.47	6.17657
3042.04	6.90092
3044.61	7.20208
3047.18	7.65841
3049.75	8.20568
3052.32	8.67809
3054.89	9.11551
3057.46	9.91432
3060.03	9.69664
3062.59	9.77793
3065.16	9.24505
3067.72	8.04041
3070.29	7.64511
3072.85	7.02109
3075.41	7.07426
3077.97	5.88081
3080.53	5.24454
3083.09	3.92042
3085.65	3.15383
3088.21	1.33802
3090.76	1.25465
3093.32	1.70587
3095.87	1.43662
3098.43	2.85278
3100.98	3.348
3103.53	3.51814
3106.08	3.1571
3108.63	3.02063
3111.18	3.5455
3113.73	4.09385
3116.28	5.80564
3118.83	6.59088
3121.37	7.79732
3123.92	7.98752
3126.46	8.92093
3129	10.0971
3131.55	11.6581
3134.09	13.5896
3136.63	14.8587
3139.17	14.5049
3141.71	15.0783
3144.24	16.1446
3146.78	17.4415
3149.32	19.3306