File: data/Raman/poly_smoothed/Thy_10_08_17_1x_45s_532 nm_x100_100%_600 gr_mm_01.txt
#Acq. time (s)=	45
#Accumulations=	2
#Range (cm-¹)=	200...3150
#Windows=	2
#Auto scanning=	Off
#Autofocus=	Off
#Macrospot=	Off
#AutoExposure=	Off
#Spike filter=	Multiple accum.
#Delay time (s)=	0
#Binning=	1
#Readout mode=	Signal
#DeNoise=	Off
#ICS correction=	On
#Dark correction=	Off
#Inst. Process=	Off
#Detector Gain=	Best Dynamic Range
#Detector ADC=	20 kHz
#Detector temperature (°C)=	-69.85
#Instrument=	LabRAM HR Evol
#Detector=	Synapse
#Objective=	x100
#Grating=	600 gr/mm
#ND Filter=	100%
#Laser (nm)=	532
#Hole=	100.021
#Range=	Auto
#Laser Pol.=	No
#Raman. Pol.=	No
#Laser Pol. (°)=	-0.0007625
#Raman Pol. (°)=	89.9995
#Collection=	Microscope
#StageXY=	Marzhauser
#StageZ=	Marzhauser
#X (µm)=	2187.1
#Y (µm)=	1245
#Z (µm)=	443.15
#Full time(mm:ss)=	3:18
#Project=
#Sample=
#Site=
#Title=	Thy_10_08_17_2x_45s_532 nm_x100_100%_600 gr_mm
#Remark=
#Date=	05.07.2022 15:24
#Acquired=	05.07.2022 15:24:08
#Base:Fit=	10.08.2022 09:46:25
#Base:Sub=	10.08.2022 09:46:49
#Filter:Polynom=	16.08.2022 10:24:56
#AxisType[0]=Intens
#AxisUnit[0]=Cnt
#AxisType[1]=Spectr
#AxisUnit[1]=1/cm
200.43	6.90871
204.059	7.46224
207.688	8.54358
211.314	9.42612
214.941	9.21282
218.564	10.0925
222.186	9.66152
225.809	8.3517
229.428	6.43342
233.045	5.64893
236.663	4.90621
240.278	4.64822
243.891	3.34012
247.503	3.8404
251.116	2.61682
254.725	1.89367
258.333	2.87649
261.939	2.26236
265.544	1.95588
269.148	3.81392
272.75	3.22783
276.351	3.58146
279.95	4.84914
283.548	7.27417
287.144	9.29292
290.739	10.75
294.333	13.2137
297.925	14.7037
301.514	18.2392
305.104	21.0079
308.692	23.9119
312.279	24.9729
315.862	26.7563
319.446	28.9322
323.029	30.7604
326.608	32.2148
330.188	31.3995
333.766	33.208
337.341	32.6937
340.917	32.9216
344.489	31.7582
348.062	29.6467
351.631	27.0651
355.201	24.5681
358.768	21.2902
362.333	18.9996
365.899	17.1033
369.462	13.2484
373.023	12.6921
376.585	10.4871
380.143	10.3593
383.7	9.38116
387.256	10.1541
390.812	10.6116
394.365	11.4152
397.916	9.90065
401.467	10.8091
405.015	11.3937
408.563	11.295
412.109	11.0489
415.654	11.5924
419.197	12.3311
422.739	12.9435
426.279	14.3448
429.819	14.1767
433.356	13.0017
436.891	13.1023
440.426	12.5144
443.96	13.0961
447.492	14.2216
451.021	15.0142
454.551	14.8542
458.079	16.0832
461.604	16.9604
465.13	18.4749
468.654	19.1464
472.175	20.1245
475.696	22.056
479.215	23.3741
482.733	24.6371
486.249	24.0356
489.765	25.7811
493.278	26.3123
496.789	26.6833
500.301	27.8695
503.81	27.5852
507.317	28.9306
510.825	28.8518
514.33	28.1066
517.833	28.3002
521.335	28.5023
524.836	28.566
528.335	28.0932
531.835	27.2329
535.332	26.8408
538.827	26.4437
542.321	25.6674
545.814	25.5057
549.305	23.4664
552.795	22.7583
556.282	20.398
559.769	21.787
563.255	20.2801
566.739	18.2979
570.223	15.9676
573.705	14.001
577.183	11.8621
580.663	10.9175
584.141	9.93417
587.615	8.53544
591.09	6.10833
594.564	4.67476
598.035	2.12855
601.506	1.24347
604.974	1.50471
608.443	1.95649
611.908	1.44019
615.374	2.58981
618.837	4.75363
622.3	6.1332
625.761	7.34548
629.219	8.96801
632.677	9.63848
636.135	11.4896
639.59	12.3195
643.043	13.6634
646.495	16.6848
649.948	18.1465
653.398	19.914
656.846	20.7855
660.293	22.3852
663.738	24.5614
667.183	26.7083
670.626	27.829
674.067	27.5701
677.508	27.2026
680.947	28.9779
684.385	29.788
687.821	31.7058
691.254	32.3366
694.688	34.1691
698.121	35.2889
701.552	37.541
704.98	37.7383
708.409	35.7681
711.836	37.7602
715.26	41.4824
718.685	44.7636
722.108	46.9756
725.528	49.2621
728.949	52.8182
732.367	55.6292
735.785	58.5296
739.2	58.8105
742.614	59.3525
746.028	60.8727
749.439	62.4819
752.849	63.2315
756.26	64.1454
759.667	66.7104
763.073	68.4883
766.477	68.9206
769.883	69.2713
773.285	69.6539
776.686	68.9433
780.085	69.1826
783.484	68.283
786.881	70.1774
790.276	72.0043
793.671	73.1616
797.064	77.3111
800.456	77.4186
803.846	77.7567
807.234	78.2121
810.622	78.0981
814.008	79.3693
817.394	80.1694
820.778	81.8972
824.159	81.4213
827.541	79.88
830.921	80.628
834.298	80.7113
837.676	79.1285
841.051	78.2272
844.426	77.5778
847.798	72.9618
851.171	71.0328
854.54	67.1932
857.911	63.7466
861.278	61.122
864.645	58.9175
868.01	56.9098
871.373	54.2996
874.735	51.7242
878.097	49.1167
881.457	45.9258
884.815	45.3297
888.172	45.2384
891.528	44.7355
894.882	44.991
898.237	45.4726
901.589	46.9384
904.94	47.8135
908.289	46.9856
911.635	47.3799
914.982	48.8756
918.328	50.0192
921.672	50.0848
925.015	51.1265
928.357	50.2195
931.698	48.9647
935.035	49.2458
938.373	47.4749
941.71	46.2165
945.044	45.1138
948.378	43.258
951.709	42.4074
955.041	41.1712
958.372	37.9817
961.699	33.1785
965.027	33.0082
968.352	33.4125
971.676	33.6212
975	34.9433
978.322	37.5339
981.642	39.8691
984.962	42.0352
988.28	41.1897
991.596	40.4229
994.911	41.4586
998.227	40.5802
1001.54	39.7657
1004.85	39.9821
1008.16	39.2451
1011.47	36.8883
1014.78	34.7585
1018.08	33.8123
1021.39	31.7942
1024.69	29.2572
1028	26.9429
1031.3	23.6313
1034.6	20.2015
1037.9	15.3381
1041.19	12.9656
1044.49	13.3487
1047.78	17.2613
1051.08	16.8472
1054.37	17.8725
1057.66	19.2599
1060.95	17.6962
1064.24	18.0143
1067.53	17.8978
1070.81	16.9834
1074.1	16.9822
1077.38	17.3796
1080.66	17.6247
1083.94	18.1261
1087.22	17.564
1090.5	16.1982
1093.78	16.8519
1097.05	16.7128
1100.33	17.6763
1103.6	18.2267
1106.87	17.8487
1110.14	16.3103
1113.41	14.6053
1116.68	14.6816
1119.95	13.7864
1123.21	11.726
1126.48	12.1378
1129.74	10.1018
1133	8.29526
1136.26	8.00493
1139.52	8.46639
1142.78	10.693
1146.04	10.1022
1149.29	8.68801
1152.55	8.08869
1155.8	8.12672
1159.05	7.46859
1162.3	7.05293
1165.55	6.33203
1168.8	6.03987
1172.05	8.13755
1175.29	9.88145
1178.54	11.389
1181.78	11.5551
1185.02	11.5957
1188.26	11.1127
1191.5	13.4498
1194.74	14.6452
1197.97	16.0404
1201.21	18.5406
1204.44	22.3709
1207.68	26.5671
1210.91	31.2579
1214.14	34.2636
1217.37	39.837
1220.59	45.8747
1223.82	49.8975
1227.05	53.736
1230.27	56.9794
1233.49	60.8932
1236.72	63.886
1239.94	65.6308
1243.16	66.6397
1246.37	68.3796
1249.59	68.6734
1252.8	68.4504
1256.02	68.0152
1259.23	66.1695
1262.44	65.7271
1265.66	65.3568
1268.86	65.9394
1272.07	65.7568
1275.28	68.356
1278.48	69.9179
1281.69	73.2944
1284.89	75.4399
1288.09	78.8829
1291.29	79.5425
1294.49	83.305
1297.69	88.1609
1300.89	90.9399
1304.08	93.687
1307.28	96.5841
1310.47	98.5641
1313.66	101.698
1316.85	102.862
1320.04	104.742
1323.23	104.459
1326.42	104.811
1329.61	103.155
1332.79	101.796
1335.97	99.6465
1339.16	98.253
1342.34	96.3989
1345.52	92.9462
1348.7	90.1636
1351.87	87.7867
1355.05	85.0695
1358.22	81.7909
1361.4	79.0639
1364.57	74.7586
1367.74	70.5805
1370.91	66.9922
1374.08	64.7379
1377.25	61.7367
1380.41	59.1312
1383.58	57.1032
1386.74	55.7595
1389.91	53.6932
1393.07	54.1141
1396.23	51.7365
1399.39	50.52
1402.55	49.0228
1405.7	48.9925
1408.86	50.3075
1412.01	51.563
1415.17	54.8662
1418.32	60.1572
1421.47	63.5536
1424.62	69.817
1427.77	78.3582
1430.91	85.7076
1434.06	91.6142
1437.2	98.0055
1440.35	101.588
1443.49	105.878
1446.63	109.61
1449.77	110.924
1452.91	110.717
1456.05	107.178
1459.18	104.046
1462.32	100.406
1465.45	96.2522
1468.59	90.4365
1471.72	81.3588
1474.85	72.4422
1477.98	63.5886
1481.1	57.0639
1484.23	50.5413
1487.36	44.2799
1490.48	39.1342
1493.61	34.3559
1496.73	30.4469
1499.85	27.9621
1502.97	26.5688
1506.09	25.9477
1509.2	23.8384
1512.32	24.0538
1515.43	23.4366
1518.55	24.103
1521.66	25.8139
1524.77	26.8586
1527.88	27.6342
1530.99	30.812
1534.1	34.5186
1537.21	39.3993
1540.31	43.1773
1543.42	46.8391
1546.52	50.6264
1549.62	55.8714
1552.72	62.1577
1555.82	68.0224
1558.92	73.413
1562.02	78.0865
1565.11	83.6671
1568.21	88.0604
1571.3	91.7089
1574.39	96.1696
1577.49	100.593
1580.57	104.734
1583.66	106.545
1586.75	106.817
1589.84	106.429
1592.92	106.175
1596.01	106.583
1599.09	103.855
1602.17	102.358
1605.25	99.7927
1608.33	97.9656
1611.41	94.8187
1614.49	91.044
1617.57	88.5113
1620.64	87.4454
1623.72	85.6391
1626.79	85.0878
1629.86	84.6849
1632.93	85.5641
1636	86.4512
1639.07	88.4551
1642.13	91.3091
1645.2	93.6794
1648.26	97.004
1651.33	100.75
1654.39	102.612
1657.45	101.352
1660.51	100.988
1663.57	100.199
1666.63	99.5719
1669.68	98.3788
1672.74	95.1418
1675.79	91.1128
1678.85	85.412
1681.9	79.9271
1684.95	73.273
1688	65.8966
1691.05	58.5724
1694.09	52.3481
1697.14	45.812
1700.18	39.376
1703.23	33.6669
1706.27	29.54
1709.31	24.4112
1712.35	20.3708
1715.39	17.4738
1718.43	15.0653
1721.47	11.9082
1724.5	9.34563
1727.54	6.58462
1730.57	3.36139
1733.61	3.20419
1736.64	3.15092
1739.67	3.1276
1742.7	2.91147
1745.72	1.49503
1748.75	0.660677
1751.77	-0.439656
1754.8	-0.449552
1757.82	-0.421872
1760.84	-0.631063
1763.87	-0.231818
1766.89	0.597746
1769.91	1.03672
1772.92	1.42971
1775.94	2.23304
1778.95	2.30477
1781.97	1.48589
1784.98	2.40415
1787.99	2.1456
1791.01	2.31756
1794.01	2.56022
1797.02	2.80532
1800.03	2.1536
1803.04	2.22506
1806.04	1.16869
1809.05	2.04035
1812.05	1.46665
1815.05	1.94193
1818.05	2.17916
1821.05	1.29213
1824.05	2.05784
1827.05	1.94927
1830.04	1.05199
1833.04	0.544435
1836.03	0.509019
1839.03	0.770781
1842.02	0.212765
1845.01	-0.475358
1848	-0.259626
1850.99	-0.567986
1853.97	-1.6332
1856.96	-0.430704
1859.94	-0.0911199
1862.93	-0.685025
1865.91	0.348965
1868.89	0.568374
1871.87	0.49842
1874.85	0.45246
1877.83	0.382248
1880.81	1.02757
1882.57	0.919883
1885.56	0.592742
1888.55	1.84333
1891.54	1.54276
1894.52	2.46113
1897.51	2.04653
1900.49	0.776889
1903.47	1.04633
1906.45	2.3521
1909.43	3.13401
1912.41	2.91294
1915.39	3.07433
1918.37	4.1889
1921.34	5.3297
1924.32	5.38875
1927.29	5.70213
1930.26	5.78685
1933.23	6.79205
1936.2	7.34665
1939.17	9.05351
1942.14	9.03898
1945.11	9.11076
1948.07	9.75043
1951.04	9.5929
1954	9.55281
1956.96	9.75837
1959.93	10.165
1962.89	10.1344
1965.85	10.1965
1968.8	8.91374
1971.76	9.42346
1974.72	9.96164
1977.67	9.79577
1980.63	9.32919
1983.58	8.42642
1986.53	7.45833
1989.48	6.8546
1992.43	6.77748
1995.38	5.64662
1998.32	5.76312
2001.27	5.15666
2004.22	5.47647
2007.16	4.85457
2010.1	5.33287
2013.04	5.60306
2015.98	5.12312
2018.92	5.70459
2021.86	6.54032
2024.8	6.58463
2027.74	7.77255
2030.67	8.24
2033.61	8.32264
2036.54	9.88196
2039.47	10.6143
2042.4	11.6296
2045.33	13.2299
2048.26	12.2767
2051.19	13.648
2054.12	14.5476
2057.04	15.0382
2059.97	15.6811
2062.89	15.6916
2065.81	15.5839
2068.73	15.4599
2071.65	14.5871
2074.57	14.3883
2077.49	14.6361
2080.41	15.2185
2083.32	16.1769
2086.24	16.0807
2089.15	16.4445
2092.07	17.0161
2094.98	17.0416
2097.89	17.4202
2100.8	18.0352
2103.71	18.0232
2106.61	19.384
2109.52	21.8379
2112.43	22.4562
2115.33	23.6942
2118.23	24.1712
2121.13	25.2814
2124.04	25.6366
2126.94	25.9905
2129.83	26.7499
2132.73	27.073
2135.63	27.6087
2138.53	28.2241
2141.42	29.7052
2144.31	30.9227
2147.21	32.892
2150.1	34.4398
2152.99	36.0113
2155.88	36.8551
2158.77	37.8327
2161.65	39.6861
2164.54	41.3148
2167.43	42.3214
2170.31	42.8355
2173.19	44.7063
2176.07	46.104
2178.96	48.3398
2181.84	47.9727
2184.72	46.9112
2187.59	45.2082
2190.47	44.4843
2193.35	43.7213
2196.22	42.9279
2199.09	41.3834
2201.97	39.298
2204.84	37.5882
2207.71	36.1024
2210.58	33.8126
2213.45	32.3646
2216.31	30.3181
2219.18	28.8357
2222.05	25.9389
2224.91	24.0798
2227.78	22.5511
2230.64	21.8653
2233.5	19.4058
2236.36	17.8727
2239.22	17.2801
2242.08	17.288
2244.93	16.7151
2247.79	16.5952
2250.64	16.8543
2253.5	15.9464
2256.35	15.4558
2259.2	16.6365
2262.05	17.5105
2264.9	17.8817
2267.75	17.4006
2270.6	17.2653
2273.45	17.3264
2276.29	17.5652
2279.14	17.7526
2281.98	18.1519
2284.82	17.3874
2287.66	16.4206
2290.5	15.7687
2293.34	14.4236
2296.18	14.3431
2299.02	13.9989
2301.86	13.5063
2304.69	13.6739
2307.53	13.6305
2310.36	13.1693
2313.19	13.416
2316.02	13.4259
2318.85	13.4834
2321.68	13.8468
2324.51	13.339
2327.34	13.3918
2330.16	11.3771
2332.99	10.9296
2335.81	10.4744
2338.64	10.0319
2341.46	9.95171
2344.28	9.25497
2347.1	8.82657
2349.92	7.85671
2352.74	6.87043
2355.55	6.43508
2358.37	5.82361
2361.19	5.26594
2364	6.01086
2366.81	6.97164
2369.62	6.94204
2372.44	6.8041
2375.24	6.78274
2378.05	6.42241
2380.86	5.90629
2383.67	5.54206
2386.47	5.74333
2389.28	5.9605
2392.08	6.33846
2394.89	6.06459
2397.69	5.22814
2400.49	5.69212
2403.29	5.92068
2406.09	6.38121
2408.88	7.21307
2411.68	8.13318
2414.48	7.32946
2417.27	7.58068
2420.06	7.67207
2422.86	8.27097
2425.65	8.9651
2428.44	6.97526
2431.23	7.50483
2434.02	6.88342
2436.81	6.19508
2439.59	6.30678
2442.38	5.43786
2445.16	5.73059
2447.95	4.32584
2450.73	4.58978
2453.51	3.99464
2456.29	5.24517
2459.07	6.00071
2461.85	5.69503
2464.63	5.51134
2467.4	5.15677
2470.18	5.05807
2472.95	4.977
2475.73	5.34641
2478.5	5.68205
2481.27	4.09407
2484.04	3.38295
2486.81	3.16845
2489.58	2.72661
2492.35	3.00505
2495.12	1.84392
2497.88	1.67126
2500.65	1.46999
2503.41	0.172871
2506.17	0.401895
2508.94	0.478714
2511.7	0.711657
2514.46	0.808688
2517.22	1.42509
2519.97	2.8767
2522.73	4.32137
2525.49	5.37998
2528.24	5.9022
2530.99	6.18141
2533.75	6.78838
2536.5	7.82868
2539.25	8.24931
2542	7.40754
2544.75	7.55651
2547.5	6.64036
2550.24	5.63845
2552.99	4.67356
2555.74	4.30472
2558.48	4.01844
2561.22	3.68364
2563.96	3.75265
2566.71	3.31074
2569.45	1.98702
2572.18	1.91614
2574.92	2.01602
2577.66	2.48088
2580.4	2.15741
2583.13	1.93067
2585.87	1.82565
2588.6	1.87337
2591.33	1.40246
2594.06	1.61968
2596.79	1.03505
2599.52	0.750048
2602.25	1.09019
2604.98	0.466361
2607.71	-0.806394
2610.43	-0.360211
2613.16	-0.742635
2615.88	-1.52556
2618.6	-0.685961
2621.32	0.195908
2624.04	1.12755
2626.76	1.83501
2629.48	3.48269
2632.2	3.75912
2634.92	3.8955
2637.63	5.56493
2640.35	6.20825
2643.06	6.79916
2645.77	6.73634
2648.49	6.55097
2651.2	5.61488
2653.91	6.15301
2656.62	6.35696
2659.33	5.93251
2662.03	5.61366
2664.74	5.54129
2667.44	6.2557
2670.15	6.37916
2672.85	6.98605
2675.55	6.50365
2678.26	6.30207
2680.96	5.76482
2683.66	5.9348
2686.35	5.88692
2689.05	5.67018
2691.75	5.30261
2694.44	5.68443
2697.14	6.47549
2699.83	6.65776
2702.52	7.75551
2705.22	8.32093
2707.91	9.55965
2710.6	10.3983
2713.29	12.4286
2715.97	13.0508
2718.66	13.79
2721.35	14.5893
2724.03	16.1257
2726.72	17.6558
2729.4	19.343
2732.08	21.0075
2734.76	20.7064
2737.44	20.5284
2740.12	19.3757
2742.8	18.4686
2745.48	18.1075
2748.16	17.6667
2750.83	17.0144
2753.51	17.1409
2756.18	16.8256
2758.85	16.21
2761.53	15.7907
2764.2	15.1928
2766.87	15.0086
2769.54	13.9437
2772.2	13.4471
2774.87	12.7672
2777.54	11.3705
2780.2	11.2209
2782.87	10.4101
2785.53	10.2084
2788.19	10.9192
2790.85	11.2732
2793.51	11.1042
2796.17	10.8274
2798.83	10.7164
2801.49	10.9565
2804.15	10.6068
2806.8	10.7712
2809.46	11.778
2812.11	12.9368
2814.76	14.4625
2817.42	16.6773
2820.07	19.5208
2822.72	23.5216
2825.37	26.3219
2828.02	31.0015
2830.66	36.5161
2833.31	43.0472
2835.96	49.4065
2838.6	55.8409
2841.24	63.4839
2843.89	72.2082
2846.53	83.5711
2849.17	93.8582
2851.81	105.534
2854.45	118.56
2857.09	130.678
2859.72	142.345
2862.36	153.739
2865	164.884
2867.63	175.085
2870.26	183.317
2872.9	190.444
2875.53	197.391
2878.16	203.573
2880.79	209.546
2883.42	214.413
2886.05	219.903
2888.67	225.066
2891.3	229.375
2893.92	235.09
2896.55	241.368
2899.17	247.245
2901.79	254.117
2904.42	264.497
2907.04	275.721
2909.66	288.228
2912.27	303.179
2914.89	317.157
2917.51	329.804
2920.13	342.233
2922.74	351.125
2925.35	359.227
2927.97	363.493
2930.58	367.275
2933.19	366.869
2935.8	363.246
2938.41	358.397
2941.02	351.64
2943.63	344.022
2946.24	333.672
2948.84	322.665
2951.45	309.678
2954.05	296.959
2956.65	285.203
2959.26	272.126
2961.86	258.893
2964.46	247.032
2967.06	237.673
2969.66	227.224
2972.25	218.052
2974.85	208.719
2977.45	198.918
2980.04	188.887
2982.64	177.936
2985.23	166.393
2987.82	154.436
2990.41	143.549
2993	132.304
2995.59	121.763
2998.18	110.05
3000.77	100.991
3003.36	92.1804
3005.94	84.6182
3008.53	76.5384
3011.11	69.8653
3013.69	62.8472
3016.28	58.4319
3018.86	54.2553
3021.44	51.2694
3024.02	47.4587
3026.6	45.6126
3029.18	45.1965
3031.75	44.3362
3034.33	45.2612
3036.9	45.5282
3039.48	46.5408
3042.05	49.0988
3044.62	49.8341
3047.19	51.0227
3049.77	51.8206
3052.34	52.8884
3054.9	53.0638
3057.47	52.3078
3060.04	51.0709
3062.61	50.2835
3065.17	48.6583
3067.74	46.6266
3070.3	44.0049
3072.86	41.334
3075.42	37.5256
3077.99	34.0477
3080.54	30.2346
3083.1	26.6993
3085.66	23.0874
3088.22	19.3272
3090.78	16.6548
3093.33	14.7473
3095.89	14.217
3098.44	13.2952
3100.99	11.5227
3103.54	11.2225
3106.1	10.7387
3108.65	9.9268
3111.2	9.79727
3113.74	9.1865
3116.29	8.1507
3118.84	7.61085
3121.38	7.32132
3123.93	7.10827
3126.47	6.95424
3129.01	6.27143
3131.56	5.49383
3134.1	5.46031
3136.64	4.49994
3139.18	2.88247
3141.72	1.8683
3144.26	0.491
3146.79	-0.17164
3149.33	0.530285