File: data/Raman/poly_smoothed/Thy_00_07_5_1x_45s_532 nm_x100_100%_600 gr_mm_02.txt
#Acq. time (s)=	45
#Accumulations=	2
#Range (cm-¹)=	200...3150
#Windows=	2
#Auto scanning=	Off
#Autofocus=	Off
#Macrospot=	Off
#AutoExposure=	Off
#Spike filter=	Multiple accum.
#Delay time (s)=	0
#Binning=	1
#Readout mode=	Signal
#DeNoise=	Off
#ICS correction=	On
#Dark correction=	Off
#Inst. Process=	Off
#Detector Gain=	Best Dynamic Range
#Detector ADC=	20 kHz
#Detector temperature (°C)=	-69.85
#Instrument=	LabRAM HR Evol
#Detector=	Synapse
#Objective=	x100
#Grating=	600 gr/mm
#ND Filter=	100%
#Laser (nm)=	532
#Hole=	100.021
#Range=	Auto
#Laser Pol.=	No
#Raman. Pol.=	No
#Laser Pol. (°)=	-0.0007625
#Raman Pol. (°)=	89.9995
#Collection=	Microscope
#StageXY=	Marzhauser
#StageZ=	Marzhauser
#X (µm)=	8998.2
#Y (µm)=	-3098.2
#Z (µm)=	-55.6
#Full time(mm:ss)=	3:19
#Project=
#Sample=
#Site=
#Title=	Thy_00_07_5_2x_45s_532 nm_x100_100%_600 gr_mm
#Remark=
#Date=	28.06.2022 10:25
#Acquired=	28.06.2022 10:25:50
#Base:Fit=	10.08.2022 10:07:56
#Base:Sub=	10.08.2022 10:08:40
#Filter:Polynom=	16.08.2022 10:26:06
#AxisType[0]=Intens
#AxisUnit[0]=Cnt
#AxisType[1]=Spectr
#AxisUnit[1]=1/cm
200.407	3.01869
204.035	6.97476
207.665	7.38536
211.291	8.10024
214.916	9.1182
218.541	10.4676
222.163	8.94001
225.785	8.79321
229.404	10.8533
233.022	10.1883
236.638	8.01406
240.255	7.54926
243.868	7.37721
247.48	7.34884
251.091	6.25854
254.702	3.92397
258.31	4.14773
261.916	4.1262
265.521	3.80458
269.125	2.67723
272.727	1.6309
276.328	0.865567
279.927	1.07717
283.525	2.36934
287.121	5.1029
290.716	7.98144
294.31	10.7328
297.9	11.117
301.491	14.2211
305.081	17.5086
308.669	18.9531
312.256	22.1532
315.839	25.1749
319.423	27.712
323.006	27.7827
326.585	30.6969
330.165	33.939
333.741	33.9455
337.318	32.4501
340.894	30.566
344.466	30.2146
348.039	29.0929
351.608	28.2241
355.176	28.588
358.745	31.4756
362.31	33.409
365.876	35.7366
369.439	39.3802
373	40.6168
376.56	41.1382
380.12	39.9948
383.677	38.7851
387.233	35.5421
390.787	36.3883
394.34	35.9394
397.894	35.2607
401.444	33.8869
404.993	32.4662
408.54	30.4521
412.086	29.5504
415.631	26.8146
419.174	24.3734
422.716	19.243
426.257	16.3985
429.794	13.4641
433.332	10.9781
436.868	9.8432
440.403	12.0602
443.937	14.5169
447.468	17.3126
450.999	21.8161
454.528	25.8666
458.057	28.5529
461.582	29.8387
465.107	31.7963
468.629	33.389
472.152	33.8308
475.672	36.8309
479.192	40.6566
482.709	44.9518
486.226	46.6097
489.74	49.9332
493.255	54.7196
496.767	60.0514
500.277	61.1431
503.788	61.2024
507.295	61.6866
510.801	59.4921
514.308	57.2252
517.811	53.3721
521.313	49.4695
524.814	48.5385
528.313	45.2966
531.811	43.188
535.308	40.4315
538.803	37.9022
542.297	33.0818
545.789	29.4399
549.281	24.9061
552.771	21.7623
556.259	18.7576
559.747	18.3682
563.233	19.3424
566.717	19.8357
570.2	21.5776
573.68	23.3103
577.161	24.5445
580.64	26.8501
584.118	28.2152
587.593	27.5233
591.068	27.5565
594.54	26.6461
598.013	25.2033
601.484	23.3496
604.952	21.9449
608.421	20.1066
611.886	18.0542
615.35	15.7205
618.815	14.0219
622.276	11.7137
625.738	9.71904
629.197	7.34611
632.655	4.52141
636.113	3.3658
639.568	4.79453
643.021	4.79831
646.473	4.37407
649.924	5.61314
653.376	5.82824
656.824	7.77561
660.271	8.09479
663.716	8.09347
667.161	9.09137
670.604	9.02211
674.045	10.3223
677.486	11.2402
680.925	13.7999
684.361	15.5213
687.797	16.3479
691.232	16.6334
694.666	17.3047
698.099	17.8685
701.528	18.0339
704.958	17.659
708.387	18.5404
711.814	18.8845
715.238	20.0388
718.663	22.4758
722.084	26.4991
725.506	28.4166
728.925	30.0598
732.345	35.2703
735.761	42.1716
739.178	49.8919
742.592	59.5398
746.006	66.5944
749.417	74.9065
752.827	84.5289
756.236	91.2399
759.645	97.6231
763.051	102.528
766.456	105.704
769.859	108.488
773.261	109.159
776.664	108.092
780.064	106.429
783.462	102.368
786.859	97.205
790.255	93.9611
793.649	89.5251
797.042	83.4198
800.434	78.9309
803.823	70.3816
807.212	64.778
810.6	59.5105
813.987	57.7042
817.372	55.997
820.754	56.7075
824.137	58.2651
827.519	61.1948
830.897	61.4044
834.276	64.0879
837.654	64.4934
841.029	63.9932
844.404	63.7696
847.776	63.4384
851.149	62.9958
854.519	60.6098
857.889	57.2925
861.256	54.8164
864.622	52.2801
867.988	48.9649
871.351	46.7543
874.713	44.0322
878.074	40.3924
881.435	38.1008
884.794	33.5931
888.15	32.0586
891.506	30.9919
894.861	28.1475
898.214	27.6664
901.566	29.5709
904.916	34.4179
908.266	38.4484
911.614	41.777
914.961	44.7525
918.306	46.0258
921.651	47.4403
924.994	49.2448
928.336	49.7386
931.674	50.7019
935.014	47.6684
938.352	46.4031
941.687	45.162
945.022	43.4069
948.357	39.5667
951.688	36.9357
955.02	33.2575
958.348	28.943
961.678	23.8748
965.004	20.4623
968.331	19.4593
971.655	21.3802
974.979	19.6936
978.3	18.7248
981.62	19.5883
984.941	20.3372
988.259	19.3196
991.575	20.0075
994.89	22.1742
998.204	25.9534
1001.52	33.394
1004.83	40.8487
1008.14	46.9691
1011.45	53.7068
1014.76	58.909
1018.06	64.0436
1021.37	67.4252
1024.67	70.1113
1027.97	70.9075
1031.27	69.9733
1034.57	67.2511
1037.87	62.5727
1041.17	59.2011
1044.47	58.3534
1047.76	56.8539
1051.06	57.0735
1054.35	52.8311
1057.64	47.7551
1060.93	45.3065
1064.22	44.4036
1067.5	42.1326
1070.79	42.6477
1074.08	47.2315
1077.36	51.7416
1080.64	56.6742
1083.92	62.2558
1087.2	65.0728
1090.48	66.8516
1093.76	70.9656
1097.03	72.7445
1100.31	73.5566
1103.58	72.2462
1106.85	70.7973
1110.12	66.3749
1113.39	61.7096
1116.66	58.0919
1119.93	53.767
1123.19	49.9179
1126.46	45.8242
1129.72	45.0686
1132.98	37.8207
1136.24	35.8929
1139.5	35.9104
1142.76	35.2096
1146.01	32.6421
1149.27	30.7706
1152.53	27.3433
1155.78	25.4795
1159.03	22.4327
1162.28	18.3166
1165.53	15.5087
1168.78	13.8631
1172.02	15.3183
1175.27	15.4591
1178.51	14.839
1181.76	14.0092
1185	11.4295
1188.24	11.7807
1191.48	10.8067
1194.71	12.5121
1197.95	13.0603
1201.19	12.9027
1204.42	15.7713
1207.65	18.465
1210.88	22.0845
1214.12	27.4927
1217.35	36.0102
1220.57	40.8725
1223.8	46.4896
1227.03	52.2477
1230.25	56.547
1233.47	58.7312
1236.69	62.2498
1239.92	63.5767
1243.13	64.9706
1246.35	66.4565
1249.57	67.95
1252.78	68.6832
1256	67.5874
1259.21	65.3751
1262.42	62.4058
1265.63	61.7814
1268.84	60.3682
1272.05	56.9014
1275.26	55.8586
1278.46	56.164
1281.67	57.359
1284.87	58.6152
1288.07	61.9357
1291.27	64.5762
1294.47	69.9895
1297.67	75.1154
1300.87	81.0149
1304.06	87.0147
1307.26	93.687
1310.45	99.0453
1313.64	106.755
1316.83	112.076
1320.02	115.75
1323.21	118.968
1326.4	122.07
1329.59	124.39
1332.77	124.612
1335.95	124.478
1339.14	125.376
1342.32	126.465
1345.5	125.728
1348.67	122.023
1351.85	120.979
1355.03	117.925
1358.2	115.324
1361.38	113.723
1364.55	111.163
1367.72	106.053
1370.89	103.325
1374.06	101.44
1377.23	99.1011
1380.39	97.1095
1383.56	95.2044
1386.72	93.1686
1389.89	87.886
1393.05	84.301
1396.21	80.2544
1399.37	77.3713
1402.52	74.7439
1405.68	73.0794
1408.84	71.4176
1411.99	74.0735
1415.15	77.9974
1418.3	81.772
1421.45	86.1812
1424.6	91.7504
1427.75	99.3632
1430.89	105.962
1434.04	112.468
1437.18	119.581
1440.33	126.267
1443.47	129.168
1446.61	131.033
1449.75	132.503
1452.89	132.343
1456.03	129.882
1459.16	123.209
1462.3	116.416
1465.43	107.879
1468.56	98.4104
1471.7	89.9708
1474.83	78.4202
1477.96	68.4526
1481.08	58.3746
1484.21	48.4864
1487.34	41.5601
1490.46	35.9702
1493.58	31.8548
1496.71	27.4398
1499.83	24.1405
1502.95	23.4124
1506.07	22.7526
1509.18	23.0433
1512.3	23.416
1515.41	25.2878
1518.53	27.3785
1521.64	30.0587
1524.75	31.9092
1527.86	35.2612
1530.97	38.4403
1534.08	41.835
1537.19	44.5051
1540.29	49.0377
1543.4	52.4112
1546.5	55.772
1549.6	59.7112
1552.7	64.3434
1555.8	69.0951
1558.9	74.1044
1562	80.7348
1565.09	86.6282
1568.19	90.2702
1571.28	94.4769
1574.37	96.6295
1577.47	99.4172
1580.56	103.48
1583.64	107.713
1586.73	107.605
1589.82	108.362
1592.9	109.084
1595.99	108.336
1599.07	106.335
1602.15	104.25
1605.23	102.62
1608.31	101.449
1611.39	100.636
1614.47	99.0529
1617.55	97.0623
1620.62	95.7429
1623.7	94.3749
1626.77	93.2593
1629.84	92.7832
1632.91	92.6823
1635.98	93.4993
1639.05	93.9109
1642.11	93.3414
1645.18	93.1721
1648.24	93.0053
1651.31	92.7465
1654.37	93.4469
1657.43	92.4923
1660.49	90.3609
1663.55	85.3871
1666.61	82.859
1669.66	78.2432
1672.72	74.3637
1675.77	70.3376
1678.83	65.5849
1681.88	60.618
1684.93	54.7788
1687.98	49.1869
1691.03	43.0324
1694.07	35.1853
1697.12	29.3087
1700.17	24.7613
1703.21	20.5872
1706.25	16.3117
1709.29	13.6519
1712.33	10.3653
1715.37	8.69443
1718.41	7.44736
1721.45	6.39423
1724.49	6.41741
1727.52	6.56073
1730.55	7.59303
1733.59	7.57862
1736.62	8.10074
1739.65	8.23386
1742.68	8.78851
1745.7	7.95859
1748.73	7.16775
1751.76	6.02951
1754.78	4.98713
1757.8	4.73667
1760.83	4.41856
1763.85	3.56238
1766.87	1.56936
1769.89	2.29363
1772.9	2.716
1775.92	2.75279
1778.94	2.63403
1781.95	2.80951
1784.96	2.01094
1787.97	1.55178
1790.99	2.25422
1794	2.08172
1797	1.91488
1800.01	2.26428
1803.02	3.11108
1806.02	3.29688
1809.03	3.52216
1812.03	2.53135
1815.03	2.81613
1818.03	2.45243
1821.03	2.34928
1824.03	2.8198
1827.03	2.31944
1830.02	2.59403
1833.02	2.22754
1836.01	2.9049
1839.01	2.49686
1842	2.24221
1844.99	3.24005
1847.98	3.48644
1850.97	2.4713
1853.95	0.976639
1856.94	0.215008
1859.93	0.146019
1862.91	-0.0317976
1865.89	-0.282046
1868.87	-0.708622
1871.85	-0.852586
1874.83	-0.817092
1877.81	-0.505257
1880.79	-0.0209342
1882.52	0.902903
1885.51	1.00265
1888.5	3.16028
1891.49	5.05853
1894.47	6.13028
1897.46	6.38085
1900.44	8.09071
1903.42	8.89448
1906.4	9.24048
1909.38	9.21956
1912.36	8.54771
1915.34	8.81826
1918.32	8.13555
1921.29	6.75161
1924.27	6.67149
1927.24	6.19939
1930.21	5.78426
1933.18	5.311
1936.15	4.86132
1939.12	3.90232
1942.09	3.44194
1945.06	3.02257
1948.02	2.71769
1950.99	3.65282
1953.95	4.01985
1956.91	4.07056
1959.88	4.82658
1962.84	6.08644
1965.8	6.46123
1968.75	6.98605
1971.71	7.51789
1974.67	8.64861
1977.62	7.78532
1980.58	8.0267
1983.53	6.9576
1986.48	7.59609
1989.43	7.307
1992.38	7.49121
1995.33	6.6505
1998.27	5.49799
2001.22	5.6189
2004.16	5.14824
2007.11	5.12133
2010.05	5.39062
2012.99	4.62396
2015.93	3.56727
2018.87	2.79514
2021.81	3.26463
2024.75	4.30208
2027.69	4.19451
2030.62	4.56382
2033.56	5.18156
2036.49	5.80258
2039.42	6.40713
2042.35	7.43737
2045.28	7.21943
2048.21	7.40686
2051.14	7.11656
2054.07	7.05044
2056.99	6.36554
2059.92	6.17112
2062.84	5.94029
2065.76	4.70297
2068.68	4.9066
2071.6	5.43142
2074.52	6.19733
2077.44	4.98188
2080.36	5.36854
2083.27	5.30776
2086.19	4.91838
2089.1	5.09755
2092.02	5.61459
2094.93	6.91534
2097.84	6.4123
2100.75	5.92085
2103.66	6.13329
2106.56	5.75556
2109.47	5.74171
2112.38	5.82232
2115.28	4.87395
2118.18	5.4106
2121.09	5.33605
2123.99	5.21482
2126.89	5.9579
2129.79	4.97204
2132.68	4.8976
2135.58	5.08927
2138.48	5.07474
2141.37	4.97712
2144.27	4.55864
2147.16	4.30105
2150.05	3.587
2152.94	4.32034
2155.83	5.28287
2158.72	5.12884
2161.6	4.58742
2164.49	4.92597
2167.38	4.77713
2170.26	5.00179
2173.14	4.62076
2176.03	4.8769
2178.91	3.8873
2181.79	4.10924
2184.67	5.27912
2187.54	5.66963
2190.42	6.44759
2193.3	7.55064
2196.17	7.13508
2199.05	7.0933
2201.92	6.76878
2204.79	6.54507
2207.66	6.7989
2210.53	6.5553
2213.4	6.37821
2216.27	6.00572
2219.13	7.51957
2222	8.87403
2224.86	8.36187
2227.72	7.87266
2230.59	7.49584
2233.45	7.80939
2236.31	8.40061
2239.17	8.57712
2242.03	9.17711
2244.88	8.93794
2247.74	9.47591
2250.59	9.59509
2253.45	10.2842
2256.3	9.66562
2259.15	9.41277
2262	9.53813
2264.85	9.578
2267.7	8.55715
2270.55	8.43941
2273.4	9.21926
2276.24	8.343
2279.09	7.62312
2281.93	6.58821
2284.77	5.92462
2287.62	5.05954
2290.46	3.84901
2293.3	2.09087
2296.13	1.71386
2298.97	1.84735
2301.81	2.08289
2304.64	2.85865
2307.48	3.95003
2310.31	3.96847
2313.14	4.56695
2315.98	5.54055
2318.81	7.10801
2321.64	8.56647
2324.46	8.91628
2327.29	9.07808
2330.12	10.1
2332.94	11.4198
2335.77	12.2535
2338.59	12.2609
2341.41	12.7006
2344.23	12.0478
2347.05	10.5292
2349.87	9.56038
2352.69	8.94951
2355.51	6.94193
2358.32	5.75846
2361.14	4.0025
2363.95	3.79889
2366.76	3.81227
2369.58	2.44566
2372.39	2.22022
2375.2	1.32256
2378	0.946321
2380.81	1.00014
2383.62	1.97152
2386.43	1.12131
2389.23	1.7806
2392.03	2.48091
2394.84	2.31875
2397.64	3.05868
2400.44	3.34783
2403.24	4.06937
2406.04	4.24846
2408.84	4.89469
2411.63	6.38676
2414.43	7.41548
2417.22	9.44923
2420.02	10.4126
2422.81	10.6537
2425.6	10.0968
2428.39	9.59589
2431.18	9.95218
2433.97	8.85315
2436.76	8.4545
2439.54	8.25416
2442.33	7.85018
2445.12	7.50794
2447.9	7.63969
2450.68	6.32438
2453.46	4.78678
2456.24	3.93971
2459.02	3.74875
2461.8	2.52329
2464.58	1.48732
2467.36	1.11438
2470.13	1.36163
2472.91	2.08831
2475.68	3.53939
2478.45	5.02849
2481.23	5.81477
2484	5.51478
2486.77	6.40139
2489.54	4.77666
2492.3	4.34162
2495.07	3.73357
2497.84	4.48659
2500.6	4.52019
2503.36	4.21227
2506.13	5.04885
2508.89	4.47535
2511.65	4.29601
2514.41	4.63038
2517.17	4.22153
2519.93	3.21617
2522.68	3.09532
2525.44	3.90438
2528.19	4.24114
2530.95	4.57742
2533.7	5.54065
2536.45	5.61771
2539.2	6.13238
2541.95	6.82273
2544.7	6.65655
2547.45	6.31505
2550.2	6.71573
2552.94	6.29405
2555.69	5.40096
2558.43	6.14182
2561.18	5.7714
2563.92	5.95062
2566.66	6.09834
2569.4	5.2384
2572.14	5.45195
2574.88	5.14721
2577.61	5.07051
2580.35	4.79277
2583.09	5.48198
2585.82	5.85006
2588.55	6.44046
2591.29	5.99239
2594.02	6.0418
2596.75	5.60841
2599.48	5.33655
2602.21	4.57546
2604.93	3.58406
2607.66	3.54208
2610.39	3.19021
2613.11	3.07603
2615.83	3.47205
2618.56	4.5043
2621.28	4.64788
2624	4.76705
2626.72	4.96956
2629.44	4.79217
2632.15	4.25046
2634.87	5.1414
2637.59	4.76155
2640.3	5.20137
2643.02	4.22045
2645.73	3.67876
2648.44	4.68681
2651.15	4.68389
2653.86	3.97977
2656.57	3.78293
2659.28	3.55356
2661.99	4.87386
2664.69	4.08378
2667.4	5.11639
2670.1	3.89179
2672.81	3.02992
2675.51	3.49749
2678.21	4.57631
2680.91	4.98819
2683.61	6.29769
2686.31	5.73692
2689	5.23927
2691.7	5.72274
2694.4	6.76572
2697.09	7.24918
2699.79	8.70344
2702.48	10.7439
2705.17	11.5151
2707.86	12.5886
2710.55	14.1124
2713.24	16.2105
2715.93	18.2906
2718.62	20.595
2721.3	21.4335
2723.99	22.1753
2726.67	22.7714
2729.35	22.3778
2732.04	22.2367
2734.72	21.9727
2737.4	20.549
2740.08	18.8034
2742.76	18.0495
2745.43	17.1079
2748.11	15.4724
2750.79	13.7947
2753.46	12.4481
2756.14	11.837
2758.81	11.0444
2761.48	9.6229
2764.15	8.53971
2766.82	7.05543
2769.49	7.56201
2772.16	7.4627
2774.82	7.46768
2777.49	7.63847
2780.16	7.7849
2782.82	7.44548
2785.48	6.20407
2788.15	4.14098
2790.81	4.04323
2793.47	3.23556
2796.13	3.3089
2798.79	3.27157
2801.44	2.9485
2804.1	1.72702
2806.76	0.299387
2809.41	0.211653
2812.07	-0.15765
2814.72	-0.958759
2817.37	0.124435
2820.02	3.40071
2822.67	6.87549
2825.32	11.5059
2827.97	16.9022
2830.62	24.3138
2833.26	31.8166
2835.91	40.5434
2838.56	49.0381
2841.2	59.4805
2843.84	70.3222
2846.48	81.6548
2849.12	94.0127
2851.77	108.056
2854.4	122.294
2857.04	138.126
2859.68	152.668
2862.32	167.536
2864.95	182.071
2867.59	195.299
2870.22	209.267
2872.85	221.533
2875.48	234.591
2878.11	247.095
2880.74	259.684
2883.37	272.526
2886	285.724
2888.63	297.493
2891.25	307.39
2893.88	318.385
2896.5	329.286
2899.13	340.394
2901.75	350.928
2904.37	362.99
2906.99	376.411
2909.61	389.245
2912.23	402.793
2914.85	417.673
2917.46	429.642
2920.08	440.401
2922.7	447.999
2925.31	452.559
2927.92	454.147
2930.54	453.254
2933.15	449.337
2935.76	444.347
2938.37	435.298
2940.98	424.538
2943.58	412.374
2946.19	398.732
2948.8	384.809
2951.4	370.141
2954.01	353.613
2956.61	338.6
2959.21	322.527
2961.81	307.493
2964.41	294.115
2967.01	280.439
2969.61	268.336
2972.21	256.567
2974.81	244.382
2977.4	231.069
2980	217.927
2982.59	203.609
2985.18	187.984
2987.78	171.756
2990.37	155.972
2992.96	139.278
2995.55	124.196
2998.14	109.157
3000.73	94.9606
3003.31	80.1304
3005.9	67.7613
3008.48	55.934
3011.07	44.9895
3013.65	36.7521
3016.23	28.0657
3018.81	20.8088
3021.4	15.2044
3023.97	11.2824
3026.55	7.98031
3029.13	5.01369
3031.71	3.33453
3034.28	2.24179
3036.86	3.32683
3039.43	4.14821
3042.01	5.8311
3044.58	7.74175
3047.15	9.96391
3049.72	11.6873
3052.29	13.3042
3054.86	14.4116
3057.43	14.9489
3060	15.9519
3062.56	15.7175
3065.13	15.9065
3067.69	14.9382
3070.26	14.4171
3072.82	12.9333
3075.38	11.1961
3077.94	10.3909
3080.5	8.33179
3083.06	7.3665
3085.62	5.76287
3088.18	5.40512
3090.73	5.10915
3093.29	4.99541
3095.84	5.81791
3098.4	6.84347
3100.95	7.94741
3103.5	9.62877
3106.05	12.0336
3108.6	13.4274
3111.15	16.1494
3113.7	17.4998
3116.25	19.2472
3118.79	21.1961
3121.34	24.2215
3123.88	27.7476
3126.43	30.7106
3128.97	33.1679
3131.51	34.8485
3134.06	36.9124
3136.6	39.7917
3139.14	42.8578
3141.67	45.588
3144.21	48.7946
3146.75	51.465
3149.29	54.8343