File: data/Raman/poly_smoothed/Thy_40_11_09_1x_45s_532 nm_x100_100%_600 gr_mm_01.txt
#Acq. time (s)=	45
#Accumulations=	2
#Range (cm-¹)=	200...3150
#Windows=	2
#Auto scanning=	Off
#Autofocus=	Off
#Macrospot=	Off
#AutoExposure=	Off
#Spike filter=	Multiple accum.
#Delay time (s)=	0
#Binning=	1
#Readout mode=	Signal
#DeNoise=	Off
#ICS correction=	On
#Dark correction=	Off
#Inst. Process=	Off
#Detector Gain=	Best Dynamic Range
#Detector ADC=	20 kHz
#Detector temperature (°C)=	-69.85
#Instrument=	LabRAM HR Evol
#Detector=	Synapse
#Objective=	x100
#Grating=	600 gr/mm
#ND Filter=	100%
#Laser (nm)=	532
#Hole=	100.021
#Range=	Auto
#Laser Pol.=	No
#Raman. Pol.=	No
#Laser Pol. (°)=	-0.0007625
#Raman Pol. (°)=	89.9995
#Collection=	Microscope
#StageXY=	Marzhauser
#StageZ=	Marzhauser
#X (µm)=	1962.7
#Y (µm)=	-68.8
#Z (µm)=	424.95
#Full time(mm:ss)=	3:18
#Project=
#Sample=
#Site=
#Title=	Thy_40_11_09_2x_45s_532 nm_x100_100%_600 gr_mm
#Remark=
#Date=	05.07.2022 10:29
#Acquired=	05.07.2022 10:29:55
#Base:Fit=	10.08.2022 10:01:35
#Base:Sub=	10.08.2022 10:01:52
#Filter:Polynom=	16.08.2022 10:21:53
#AxisType[0]=Intens
#AxisUnit[0]=Cnt
#AxisType[1]=Spectr
#AxisUnit[1]=1/cm
200.43	27.9298
204.059	26.2641
207.688	22.1064
211.314	17.8066
214.941	13.9695
218.564	11.6688
222.186	10.4978
225.809	9.70176
229.428	9.80381
233.045	9.16491
236.663	8.86657
240.278	7.73197
243.891	5.63334
247.503	4.71152
251.116	6.04151
254.725	5.23967
258.333	4.59852
261.939	6.94627
265.544	7.4612
269.148	7.85699
272.75	7.85101
276.351	8.13141
279.95	8.04247
283.548	7.76648
287.144	7.94289
290.739	7.90398
294.333	8.30258
297.925	9.55145
301.514	10.6771
305.104	12.7948
308.692	15.2044
312.279	16.972
315.862	18.1244
319.446	19.6051
323.029	20.4824
326.608	20.9757
330.188	21.3266
333.766	20.4225
337.341	22.8204
340.917	22.7435
344.489	19.666
348.062	20.0727
351.631	19.3275
355.201	19.2495
358.768	17.1552
362.333	17.4775
365.899	17.075
369.462	16.6859
373.023	14.7445
376.585	15.914
380.143	15.9282
383.7	15.1724
387.256	16.7892
390.812	15.6747
394.365	15.8424
397.916	14.6908
401.467	14.8484
405.015	13.7196
408.563	13.1896
412.109	12.1131
415.654	10.373
419.197	9.8952
422.739	9.27029
426.279	9.02609
429.819	7.78806
433.356	6.59968
436.891	6.43086
440.426	6.42559
443.96	6.61664
447.492	6.39787
451.021	8.00544
454.551	9.03375
458.079	8.99316
461.604	11.8885
465.13	15.6904
468.654	17.2154
472.175	20.818
475.696	22.4229
479.215	24.6287
482.733	25.8489
486.249	28.1583
489.765	29.9918
493.278	31.5598
496.789	32.0329
500.301	34.0285
503.81	34.7727
507.317	34.4728
510.825	34.9197
514.33	34.6606
517.833	32.9972
521.335	31.6121
524.836	28.8477
528.335	27.3821
531.835	24.3352
535.332	22.5466
538.827	21.3532
542.321	21.4795
545.814	20.3608
549.305	19.5284
552.795	18.6978
556.282	17.1274
559.769	15.4507
563.255	13.4606
566.739	12.8064
570.223	10.1079
573.705	8.21208
577.183	7.70169
580.663	6.58076
584.141	5.92567
587.615	4.9444
591.09	4.1434
594.564	3.76882
598.035	2.69383
601.506	2.37424
604.974	1.89953
608.443	1.15737
611.908	2.4415
615.374	4.2181
618.837	6.25326
622.3	8.891
625.761	11.567
629.219	12.5552
632.677	14.5894
636.135	17.0589
639.59	19.3424
643.043	20.2778
646.495	21.9646
649.948	23.1293
653.398	24.786
656.846	25.7288
660.293	26.0811
663.738	25.9796
667.183	25.9663
670.626	24.1311
674.067	24.7058
677.508	25.6146
680.947	24.5139
684.385	26.5138
687.821	27.399
691.254	29.805
694.688	32.5189
698.121	35.6524
701.552	36.8023
704.98	38.989
708.409	42.8208
711.836	45.527
715.26	48.5596
718.685	51.7541
722.108	53.3944
725.528	54.393
728.949	54.8935
732.367	55.9259
735.785	58.0321
739.2	56.767
742.614	57.0515
746.028	56.614
749.439	57.8381
752.849	59.2459
756.26	61.1002
759.667	64.3572
763.073	65.512
766.477	67.5491
769.883	70.4464
773.285	73.6932
776.686	75.7154
780.085	78.4286
783.484	78.79
786.881	81.4659
790.276	83.1939
793.671	85.6066
797.064	87.1277
800.456	87.9891
803.846	89.0686
807.234	88.0676
810.622	87.6498
814.008	88.2499
817.394	88.7417
820.778	87.7817
824.159	87.0523
827.541	88.1141
830.921	87.402
834.298	87.9831
837.676	87.0249
841.051	86.5047
844.426	85.0909
847.798	81.0722
851.171	78.8646
854.54	76.9269
857.911	74.937
861.278	72.4919
864.645	71.3195
868.01	68.6572
871.373	68.7662
874.735	66.3631
878.097	66.1649
881.457	62.7207
884.815	61.9662
888.172	60.54
891.528	58.2413
894.882	58.3286
898.237	57.0137
901.589	54.7201
904.94	54.2655
908.289	53.7272
911.635	52.9203
914.982	51.4844
918.328	50.4291
921.672	50.4941
925.015	48.5437
928.357	46.186
931.698	44.663
935.035	43.5354
938.373	41.259
941.71	41.6793
945.044	39.0531
948.378	39.258
951.709	38.1853
955.041	36.7837
958.372	36.6832
961.699	36.7022
965.027	36.8273
968.352	38.511
971.676	40.2195
975	41.0453
978.322	40.2905
981.642	41.4021
984.962	42.7395
988.28	43.8235
991.596	43.3316
994.911	44.0202
998.227	44.0971
1001.54	46.0818
1004.85	44.2038
1008.16	43.6008
1011.47	41.7444
1014.78	39.7814
1018.08	38.3501
1021.39	39.4034
1024.69	38.0971
1028	36.6062
1031.3	36.4041
1034.6	34.1648
1037.9	32.5535
1041.19	33.1681
1044.49	31.7563
1047.78	32.3977
1051.08	32.0384
1054.37	29.9626
1057.66	29.1547
1060.95	29.8825
1064.24	29.1754
1067.53	26.6832
1070.81	26.6121
1074.1	25.8986
1077.38	25.8864
1080.66	24.0112
1083.94	23.5407
1087.22	23.5451
1090.5	24.0952
1093.78	24.445
1097.05	25.5105
1100.33	27.0598
1103.6	27.6782
1106.87	27.7568
1110.14	28.0048
1113.41	27.0897
1116.68	26.3579
1119.95	25.5002
1123.21	23.7108
1126.48	22.4603
1129.74	19.4312
1133	17.5699
1136.26	17.1622
1139.52	16.5908
1142.78	14.2016
1146.04	11.568
1149.29	8.75143
1152.55	7.84717
1155.8	4.85222
1159.05	2.30073
1162.3	3.06619
1165.55	3.74609
1168.8	3.88154
1172.05	5.47245
1175.29	6.99027
1178.54	8.31465
1181.78	10.2328
1185.02	11.518
1188.26	13.0346
1191.5	13.7677
1194.74	15.9271
1197.97	17.2254
1201.21	17.8137
1204.44	19.4369
1207.68	23.4689
1210.91	26.9715
1214.14	31.4521
1217.37	36.3248
1220.59	39.2018
1223.82	42.9368
1227.05	46.3425
1230.27	50.0908
1233.49	52.6797
1236.72	56.0172
1239.94	59.6354
1243.16	62.6351
1246.37	66.2125
1249.59	69.1143
1252.8	72.0147
1256.02	72.1761
1259.23	73.6562
1262.44	75.9074
1265.66	76.6799
1268.86	79.3302
1272.07	82.2378
1275.28	82.3086
1278.48	83.0944
1281.69	84.6889
1284.89	87.8026
1288.09	90.5324
1291.29	91.7996
1294.49	93.3671
1297.69	94.6385
1300.89	96.2162
1304.08	97.9813
1307.28	97.6633
1310.47	97.3907
1313.66	95.9188
1316.85	96.3048
1320.04	96.0831
1323.23	94.5218
1326.42	93.2249
1329.61	90.5547
1332.79	88.6953
1335.97	87.209
1339.16	83.7118
1342.34	82.1045
1345.52	79.3876
1348.7	76.5735
1351.87	72.9044
1355.05	69.9304
1358.22	68.7702
1361.4	66.8349
1364.57	64.1362
1367.74	62.0668
1370.91	59.5747
1374.08	57.9304
1377.25	57.3361
1380.41	55.5548
1383.58	54.1475
1386.74	51.4851
1389.91	49.8849
1393.07	48.8451
1396.23	48.1668
1399.39	46.0714
1402.55	44.6022
1405.7	44.6557
1408.86	45.0549
1412.01	45.2741
1415.17	44.8046
1418.32	46.5953
1421.47	51.1261
1424.62	55.9973
1427.77	63.3467
1430.91	71.9089
1434.06	79.7601
1437.2	86.8916
1440.35	94.5525
1443.49	99.4714
1446.63	103.37
1449.77	106.482
1452.91	106.149
1456.05	105.238
1459.18	103.424
1462.32	99.9104
1465.45	94.714
1468.59	87.9979
1471.72	81.4298
1474.85	74.2535
1477.98	64.4173
1481.1	57.0244
1484.23	48.5747
1487.36	40.2955
1490.48	32.823
1493.61	27.9758
1496.73	25.75
1499.85	23.7327
1502.97	25.2185
1506.09	25.7177
1509.2	27.0969
1512.32	28.7003
1515.43	29.02
1518.55	30.17
1521.66	30.1058
1524.77	31.8851
1527.88	33.0161
1530.99	36.4466
1534.1	39.2507
1537.21	43.8622
1540.31	47.113
1543.42	51.2633
1546.52	57.3246
1549.62	61.5226
1552.72	65.6802
1555.82	69.7638
1558.92	74.2577
1562.02	78.8624
1565.11	83.2148
1568.21	87.24
1571.3	89.9349
1574.39	92.5648
1577.49	94.4222
1580.57	97.0759
1583.66	98.9643
1586.75	98.8586
1589.84	99.2439
1592.92	97.5009
1596.01	95.812
1599.09	94.3405
1602.17	92.4641
1605.25	91.4564
1608.33	88.8843
1611.41	88.7558
1614.49	87.2608
1617.57	86.561
1620.64	89.4767
1623.72	91.0623
1626.79	93.084
1629.86	95.6801
1632.93	98.4247
1636	101.324
1639.07	105.517
1642.13	108.448
1645.2	111.471
1648.26	114.977
1651.33	117.077
1654.39	120.191
1657.45	122.795
1660.51	121.563
1663.57	119.839
1666.63	116.39
1669.68	110.48
1672.74	104.834
1675.79	96.9228
1678.85	88.8085
1681.9	80.0346
1684.95	71.5794
1688	63.6089
1691.05	55.3239
1694.09	47.3256
1697.14	41.5759
1700.18	33.7654
1703.23	27.3226
1706.27	21.1964
1709.31	17.2337
1712.35	13.1071
1715.39	11.4057
1718.43	10.7437
1721.47	11.3926
1724.5	11.0719
1727.54	10.9956
1730.57	11.0654
1733.61	10.4853
1736.64	9.57602
1739.67	9.20103
1742.7	7.75031
1745.72	6.5791
1748.75	6.28345
1751.77	5.60259
1754.8	6.13126
1757.82	7.18982
1760.84	7.48461
1763.87	6.92302
1766.89	6.9628
1769.91	6.52165
1772.92	6.07018
1775.94	5.16673
1778.95	4.7567
1781.97	5.17216
1784.98	5.47712
1787.99	5.50327
1791.01	5.59761
1794.01	5.8483
1797.02	4.3721
1800.03	3.86785
1803.04	3.64392
1806.04	3.7569
1809.05	2.4152
1812.05	2.88523
1815.05	2.07822
1818.05	1.56591
1821.05	1.34187
1824.05	1.94984
1827.05	2.06329
1830.04	2.80209
1833.04	3.66897
1836.03	4.3994
1839.03	4.47095
1842.02	3.5188
1845.01	3.74432
1848	3.34322
1850.99	3.5328
1853.97	3.43418
1856.96	3.19884
1859.94	3.98366
1862.93	2.82364
1865.91	2.62445
1868.89	3.06616
1871.87	2.55662
1874.85	2.19111
1877.83	2.78149
1880.81	2.28075
1882.57	1.45064
1885.56	0.325576
1888.55	-0.00302472
1891.54	-0.67786
1894.52	-0.0744766
1897.51	0.0265882
1900.49	-0.305265
1903.47	-0.402109
1906.45	-0.731228
1909.43	-0.358413
1912.41	-1.19602
1915.39	-0.949056
1918.37	0.686158
1921.34	-0.193394
1924.32	0.483896
1927.29	1.66215
1930.26	2.39618
1933.23	1.1826
1936.2	1.58394
1939.17	1.92902
1942.14	1.54746
1945.11	1.28529
1948.07	0.823804
1951.04	0.859515
1954	0.942968
1956.96	1.72244
1959.93	2.30274
1962.89	2.6684
1965.85	3.05122
1968.8	3.28431
1971.76	3.67606
1974.72	3.28388
1977.67	3.56468
1980.63	3.36454
1983.58	3.94648
1986.53	2.92275
1989.48	4.05058
1992.43	4.3073
1995.38	4.07166
1998.32	4.88725
2001.27	5.01506
2004.22	4.12358
2007.16	3.8173
2010.1	3.87346
2013.04	3.34698
2015.98	3.255
2018.92	2.83031
2021.86	2.13048
2024.8	2.46828
2027.74	3.41556
2030.67	4.17373
2033.61	3.64654
2036.54	5.03103
2039.47	5.71963
2042.4	5.77564
2045.33	6.53455
2048.26	6.96939
2051.19	8.78641
2054.12	9.76841
2057.04	10.5287
2059.97	11.6257
2062.89	14.1494
2065.81	15.2158
2068.73	16.8027
2071.65	18.8528
2074.57	20.8592
2077.49	22.6987
2080.41	24.3748
2083.32	26.2293
2086.24	26.7106
2089.15	28.3253
2092.07	29.7363
2094.98	30.7035
2097.89	33.8964
2100.8	37.0837
2103.71	38.8511
2106.61	42.1559
2109.52	44.8686
2112.43	47.2597
2115.33	50.9235
2118.23	53.6196
2121.13	57.0467
2124.04	60.3556
2126.94	63.7075
2129.83	67.2312
2132.73	71.5232
2135.63	75.6655
2138.53	78.8414
2141.42	82.5991
2144.31	86.8942
2147.21	91.1834
2150.1	95.3653
2152.99	100.471
2155.88	104.116
2158.77	108.356
2161.65	112.186
2164.54	114.339
2167.43	117.678
2170.31	119.408
2173.19	119.891
2176.07	120.562
2178.96	120.055
2181.84	117.409
2184.72	114.823
2187.59	112.837
2190.47	109.862
2193.35	106.984
2196.22	102.743
2199.09	98.8966
2201.97	94.0582
2204.84	89.3809
2207.71	85.2933
2210.58	80.3383
2213.45	76.2676
2216.31	72.9785
2219.18	69.5189
2222.05	66.2537
2224.91	62.0443
2227.78	58.1715
2230.64	54.7005
2233.5	51.2547
2236.36	48.2442
2239.22	44.6738
2242.08	42.628
2244.93	40.0468
2247.79	36.6696
2250.64	34.5087
2253.5	33.0028
2256.35	31.9406
2259.2	30.6601
2262.05	30.182
2264.9	28.3203
2267.75	28.2231
2270.6	27.4183
2273.45	27.626
2276.29	27.3611
2279.14	26.114
2281.98	24.9737
2284.82	23.4333
2287.66	21.576
2290.5	20.028
2293.34	16.3458
2296.18	14.9105
2299.02	14.5839
2301.86	14.4826
2304.69	14.2234
2307.53	14.6841
2310.36	14.2501
2313.19	13.9459
2316.02	13.2811
2318.85	12.7189
2321.68	13.1953
2324.51	12.1914
2327.34	12.0249
2330.16	12.3364
2332.99	12.2671
2335.81	12.4579
2338.64	13.2447
2341.46	12.4775
2344.28	11.9035
2347.1	10.2172
2349.92	8.67058
2352.74	7.31783
2355.55	4.08103
2358.37	2.65286
2361.19	2.2913
2364	2.11691
2366.81	2.9004
2369.62	2.73337
2372.44	1.99943
2375.24	0.842532
2378.05	0.390464
2380.86	0.389155
2383.67	0.687429
2386.47	-0.0736745
2389.28	1.40663
2392.08	2.9827
2394.89	4.07839
2397.69	5.20817
2400.49	6.80341
2403.29	7.75691
2406.09	9.44991
2408.88	9.77614
2411.68	10.0796
2414.48	10.0325
2417.27	11.3093
2420.06	11.9085
2422.86	12.2879
2425.65	12.1474
2428.44	13.5951
2431.23	13.6774
2434.02	12.2984
2436.81	11.3375
2439.59	10.4816
2442.38	9.47352
2445.16	8.38006
2447.95	8.39032
2450.73	8.39906
2453.51	7.94803
2456.29	7.37903
2459.07	7.79575
2461.85	7.87436
2464.63	6.62678
2467.4	6.50947
2470.18	6.0128
2472.95	5.17297
2475.73	4.11001
2478.5	2.77509
2481.27	2.00788
2484.04	2.46867
2486.81	3.58273
2489.58	2.57709
2492.35	1.92478
2495.12	1.85602
2497.88	1.61607
2500.65	1.72824
2503.41	2.49367
2506.17	2.44894
2508.94	1.74397
2511.7	1.22519
2514.46	0.96055
2517.22	1.36911
2519.97	2.05676
2522.73	2.16341
2525.49	2.9918
2528.24	3.21264
2530.99	3.22721
2533.75	3.82038
2536.5	4.15126
2539.25	4.52845
2542	5.41921
2544.75	5.39653
2547.5	5.61277
2550.24	6.43161
2552.99	6.61267
2555.74	6.85539
2558.48	7.13892
2561.22	8.21752
2563.96	8.32258
2566.71	8.53673
2569.45	8.62828
2572.18	7.703
2574.92	7.01748
2577.66	6.9829
2580.4	6.45955
2583.13	6.81767
2585.87	6.96891
2588.6	7.61677
2591.33	7.76627
2594.06	7.25852
2596.79	7.49633
2599.52	7.17368
2602.25	7.10775
2604.98	6.10321
2607.71	6.57751
2610.43	6.95273
2613.16	6.25493
2615.88	6.43199
2618.6	6.31071
2621.32	6.93262
2624.04	7.21694
2626.76	7.20637
2629.48	6.36745
2632.2	6.35908
2634.92	6.1737
2637.63	6.28789
2640.35	5.54514
2643.06	5.1496
2645.77	5.29689
2648.49	5.90429
2651.2	6.31155
2653.91	5.69437
2656.62	6.38266
2659.33	6.49194
2662.03	6.45285
2664.74	6.02424
2667.44	5.24461
2670.15	5.78763
2672.85	6.52218
2675.55	6.81444
2678.26	7.26247
2680.96	7.54571
2683.66	7.55705
2686.35	8.17311
2689.05	8.87476
2691.75	8.39965
2694.44	7.35027
2697.14	7.91885
2699.83	7.01154
2702.52	6.69194
2705.22	5.56492
2707.91	5.26126
2710.6	6.00951
2713.29	6.47328
2715.97	6.60199
2718.66	6.24641
2721.35	6.76742
2724.03	7.05006
2726.72	7.49793
2729.4	7.12521
2732.08	7.03421
2734.76	7.75636
2737.44	7.88297
2740.12	7.33981
2742.8	8.28366
2745.48	7.57887
2748.16	7.7761
2750.83	7.60814
2753.51	7.81208
2756.18	6.5436
2758.85	5.24331
2761.53	4.25981
2764.2	3.32481
2766.87	1.73368
2769.54	1.541
2772.2	1.02523
2774.87	1.14412
2777.54	0.768993
2780.2	-0.120839
2782.87	-0.393318
2785.53	-0.436128
2788.19	-0.245913
2790.85	-0.458322
2793.51	-0.2455
2796.17	0.239432
2798.83	-0.0185483
2801.49	0.0385388
2804.15	-0.910068
2806.8	-0.62723
2809.46	-0.687136
2812.11	-0.958544
2814.76	-1.22916
2817.42	-1.01062
2820.07	0.0905805
2822.72	1.8101
2825.37	4.78176
2828.02	8.61762
2830.66	13.3032
2833.31	18.6778
2835.96	23.5828
2838.6	28.907
2841.24	35.2625
2843.89	42.6127
2846.53	51.188
2849.17	61.4838
2851.81	71.9433
2854.45	83.1132
2857.09	94.0936
2859.72	104.237
2862.36	113.477
2865	121.616
2867.63	131.154
2870.26	138.919
2872.9	144.649
2875.53	150.756
2878.16	156.226
2880.79	161.613
2883.42	166.328
2886.05	171.206
2888.67	175.707
2891.3	180.2
2893.92	185.387
2896.55	191.527
2899.17	197.639
2901.79	205.609
2904.42	215.531
2907.04	228.029
2909.66	241.561
2912.27	255.537
2914.89	270.6
2917.51	285.565
2920.13	298.511
2922.74	308.192
2925.35	317.513
2927.97	323.703
2930.58	328.852
2933.19	330.575
2935.8	328.831
2938.41	325.098
2941.02	320.437
2943.63	312.014
2946.24	302.211
2948.84	290.167
2951.45	277.439
2954.05	265.058
2956.65	252.34
2959.26	239.363
2961.86	226.476
2964.46	213.99
2967.06	201.867
2969.66	191.328
2972.25	180.536
2974.85	171.205
2977.45	160.883
2980.04	149.919
2982.64	139.299
2985.23	128.1
2987.82	117.494
2990.41	105.873
2993	94.3782
2995.59	83.6003
2998.18	73.6802
3000.77	63.9283
3003.36	55.2117
3005.94	47.2243
3008.53	39.094
3011.11	32.9646
3013.69	26.9678
3016.28	22.5318
3018.86	18.8354
3021.44	14.7297
3024.02	12.3845
3026.6	9.62838
3029.18	8.24413
3031.75	9.23803
3034.33	10.2829
3036.9	11.6409
3039.48	12.4945
3042.05	13.4543
3044.62	16.0093
3047.19	18.6146
3049.77	20.6943
3052.34	21.0837
3054.9	21.8721
3057.47	22.022
3060.04	22.3147
3062.61	22.6385
3065.17	21.5599
3067.74	20.7244
3070.3	19.2003
3072.86	17.5885
3075.42	15.4737
3077.99	13.5549
3080.54	11.5169
3083.1	8.29695
3085.66	6.03689
3088.22	2.79521
3090.78	1.58313
3093.33	0.61526
3095.89	0.617995
3098.44	0.0233135
3100.99	-0.154475
3103.54	-0.374698
3106.1	0.51808
3108.65	2.24213
3111.2	3.08207
3113.74	4.3554
3116.29	4.77556
3118.84	5.71318
3121.38	6.43515
3123.93	8.40492
3126.47	9.74223
3129.01	10.9457
3131.56	12.2889
3134.1	13.6272
3136.64	14.8611
3139.18	15.1402
3141.72	16.0078
3144.26	15.8814
3146.79	15.9503
3149.33	16.3325