File: data/Raman/poly_smoothed/Thy_50_12_27_1x_45s_532 nm_x100_100%_600 gr_mm_01.txt
#Acq. time (s)=	45
#Accumulations=	2
#Range (cm-¹)=	200...3150
#Windows=	2
#Auto scanning=	Off
#Autofocus=	Off
#Macrospot=	Off
#AutoExposure=	Off
#Spike filter=	Multiple accum.
#Delay time (s)=	0
#Binning=	1
#Readout mode=	Signal
#DeNoise=	Off
#ICS correction=	On
#Dark correction=	Off
#Inst. Process=	Off
#Detector Gain=	Best Dynamic Range
#Detector ADC=	20 kHz
#Detector temperature (°C)=	-69.85
#Instrument=	LabRAM HR Evol
#Detector=	Synapse
#Objective=	x100
#Grating=	600 gr/mm
#ND Filter=	100%
#Laser (nm)=	532
#Hole=	100.021
#Range=	Auto
#Laser Pol.=	No
#Raman. Pol.=	No
#Laser Pol. (°)=	-0.0007625
#Raman Pol. (°)=	89.9995
#Collection=	Microscope
#StageXY=	Marzhauser
#StageZ=	Marzhauser
#X (µm)=	-5134.5
#Y (µm)=	1497.1
#Z (µm)=	63.2
#Full time(mm:ss)=	3:18
#Project=
#Sample=
#Site=
#Title=	Thy_50_12_27_2x_45s_532 nm_x100_100%_600 gr_mm
#Remark=
#Date=	07.07.2022 11:13
#Acquired=	07.07.2022 11:13:35
#Base:Fit=	10.08.2022 10:04:29
#Base:Sub=	10.08.2022 10:04:45
#Filter:Polynom=	16.08.2022 10:20:24
#AxisType[0]=Intens
#AxisUnit[0]=Cnt
#AxisType[1]=Spectr
#AxisUnit[1]=1/cm
200.43	27.7715
204.061	23.3586
207.688	22.3563
211.316	19.7679
214.941	17.2086
218.566	14.5886
222.188	13.9876
225.809	11.1657
229.43	9.23389
233.047	7.30437
236.663	4.88579
240.278	4.24653
243.894	3.39703
247.506	3.04456
251.116	2.06459
254.725	2.61402
258.333	2.86787
261.939	2.94949
265.546	3.09923
269.15	2.88494
272.752	4.29947
276.353	6.7811
279.952	5.98144
283.55	4.30639
287.146	4.47191
290.739	6.23001
294.333	5.29798
297.925	4.15072
301.516	4.46728
305.106	6.20008
308.694	5.28113
312.279	4.54818
315.864	4.13118
319.448	4.08188
323.029	2.96292
326.61	3.09159
330.19	3.68858
333.766	3.26761
337.343	4.83117
340.917	4.39919
344.491	5.5364
348.062	6.15515
351.633	7.53949
355.201	7.46804
358.77	8.65017
362.335	8.8644
365.899	8.3989
369.464	8.87
373.025	9.42447
376.585	11.3409
380.143	10.835
383.702	9.5169
387.258	9.26645
390.812	10.1024
394.365	8.53239
397.916	9.64287
401.467	8.5327
405.015	8.06244
408.565	6.93512
412.111	6.48088
415.656	3.84525
419.197	4.64192
422.739	4.99691
426.279	4.96205
429.819	5.82314
433.356	6.20321
436.893	6.39053
440.428	6.08744
443.96	6.73761
447.492	6.46787
451.023	7.28399
454.553	6.98495
458.079	8.07198
461.606	7.62519
465.132	8.69019
468.654	9.15667
472.177	10.4444
475.696	11.4114
479.217	12.8834
482.733	16.309
486.251	19.5115
489.765	20.5082
493.278	23.0653
496.791	24.4488
500.301	25.953
503.81	27.4801
507.319	29.6828
510.825	31.9906
514.33	33.2349
517.833	33.6408
521.337	32.9388
524.838	33.2858
528.337	32.2099
531.835	30.6138
535.332	29.0164
538.827	27.3463
542.321	25.6208
545.814	24.6471
549.305	22.8775
552.795	21.2436
556.284	20.6708
559.771	19.2397
563.257	19.2086
566.742	18.8921
570.223	19.1023
573.705	17.8786
577.185	15.9775
580.665	13.9148
584.141	11.9208
587.617	10.3879
591.092	9.11103
594.564	8.8343
598.037	8.90791
601.506	7.83992
604.976	7.4669
608.443	8.70185
611.91	8.9412
615.374	9.34068
618.839	10.0614
622.3	10.9019
625.761	12.5749
629.221	13.8155
632.679	15.0245
636.135	17.0533
639.592	20.7483
643.045	22.6686
646.497	23.6094
649.948	25.0657
653.398	26.7017
656.846	27.6216
660.293	28.1157
663.738	28.3351
667.185	29.0686
670.628	30.2431
674.067	30.3497
677.508	32.6621
680.947	34.9047
684.385	36.6524
687.821	37.3762
691.256	39.0825
694.69	41.5604
698.121	40.5693
701.552	40.4253
704.982	41.8587
708.41	43.4452
711.836	44.7372
715.262	46.0908
718.685	48.7526
722.108	50.5969
725.53	50.8876
728.949	51.7949
732.369	53.8445
735.785	55.5697
739.2	56.2461
742.616	58.5267
746.028	60.1261
749.441	63.2424
752.851	66.2625
756.26	67.8865
759.667	71.3265
763.075	73.4148
766.479	76.2912
769.883	77.8898
773.285	81.7504
776.686	83.4927
780.085	86.3537
783.484	85.5596
786.881	87.4592
790.276	90.1602
793.671	92.1978
797.064	93.7751
800.456	94.0971
803.846	94.1296
807.236	93.5491
810.624	92.3274
814.01	91.8384
817.394	90.6064
820.778	90.8765
824.161	90.1321
827.543	88.0904
830.921	85.8847
834.3	83.8771
837.676	81.0052
841.053	78.112
844.426	76.6099
847.8	73.8651
851.171	71.6309
854.542	69.2171
857.911	68.1255
861.279	66.6043
864.645	64.3926
868.01	62.9491
871.375	63.3397
874.737	61.6179
878.097	58.9347
881.457	55.5467
884.817	53.9937
888.174	53.263
891.53	51.6382
894.884	50.1733
898.237	50.2124
901.589	50.6422
904.94	49.4866
908.289	48.0586
911.637	48.0986
914.984	46.6344
918.33	45.7538
921.674	46.1972
925.015	45.0405
928.357	42.7242
931.698	40.5346
935.037	41.0451
938.373	41.2324
941.71	41.0904
945.046	40.9651
948.378	41.3682
951.711	41.3447
955.043	40.9157
958.372	39.4515
961.701	37.6013
965.027	38.5414
968.354	38.3587
971.678	39.3141
975	38.2991
978.324	39.2512
981.644	39.1515
984.962	39.6297
988.282	38.2736
991.598	37.177
994.913	37.0106
998.227	35.9214
1001.54	35.9437
1004.85	36.1514
1008.16	35.8323
1011.47	36.4674
1014.78	38.1324
1018.08	38.8176
1021.39	39.8061
1024.69	41.3517
1028	43.4053
1031.3	45.1305
1034.6	45.7352
1037.9	44.2829
1041.19	44.2793
1044.49	45.137
1047.79	43.5059
1051.08	41.568
1054.37	38.5596
1057.66	35.7989
1060.95	34.9456
1064.24	31.6171
1067.53	28.9741
1070.81	26.3897
1074.1	26.5479
1077.38	25.2136
1080.66	22.5542
1083.94	21.2476
1087.22	21.9829
1090.5	24.4576
1093.78	24.4626
1097.05	24.3938
1100.33	25.224
1103.6	26.2229
1106.87	26.6187
1110.15	25.6197
1113.41	26.4278
1116.68	25.4616
1119.95	23.6965
1123.21	23.6263
1126.48	21.2147
1129.74	18.8134
1133	17.1101
1136.26	16.6596
1139.52	17.1809
1142.78	15.9988
1146.04	15.1285
1149.29	14.0499
1152.55	12.2849
1155.8	9.81082
1159.05	7.88429
1162.3	6.83467
1165.55	6.33249
1168.8	7.60443
1172.05	7.96519
1175.29	8.01563
1178.54	8.25929
1181.78	8.96889
1185.02	9.8532
1188.26	9.38779
1191.5	9.86874
1194.74	11.68
1197.97	12.362
1201.21	13.6594
1204.44	15.7699
1207.68	19.0203
1210.91	22.5126
1214.14	25.4556
1217.37	28.3656
1220.6	31.8905
1223.82	35.9466
1227.05	36.9681
1230.27	40.5535
1233.49	42.3466
1236.72	45.9195
1239.94	49.0905
1243.16	53.559
1246.37	56.1031
1249.59	61.0262
1252.8	63.8058
1256.02	66.2697
1259.23	69.0143
1262.44	71.2187
1265.66	73.7074
1268.87	76.6145
1272.07	80.2258
1275.28	82.7331
1278.48	84.159
1281.69	84.7914
1284.89	86.4968
1288.09	88.5357
1291.3	89.0711
1294.49	89.5342
1297.69	90.2864
1300.89	92.4658
1304.09	91.8267
1307.28	93.1971
1310.47	93.6338
1313.66	93.5831
1316.86	94.5836
1320.05	94.7081
1323.23	93.5491
1326.42	92.3361
1329.61	89.6669
1332.79	86.5164
1335.98	84.2507
1339.16	81.6047
1342.34	77.7518
1345.52	74.0851
1348.7	71.6611
1351.87	68.0081
1355.05	63.887
1358.23	60.926
1361.4	57.0434
1364.57	53.4083
1367.74	51.4986
1370.91	49.8556
1374.08	48.2558
1377.25	46.8893
1380.42	44.5912
1383.58	44.2088
1386.75	44.0741
1389.91	41.4123
1393.07	41.1154
1396.23	41.6966
1399.39	40.0942
1402.55	40.8146
1405.7	39.8705
1408.86	42.0238
1412.01	43.7753
1415.17	47.2942
1418.32	50.5103
1421.47	54.8606
1424.62	61.5089
1427.77	67.3221
1430.92	73.4184
1434.06	79.1261
1437.2	84.6159
1440.35	88.4897
1443.49	92.538
1446.63	95.9392
1449.77	96.3716
1452.91	93.8334
1456.05	87.6189
1459.18	83.3959
1462.32	82.1479
1465.45	78.8939
1468.59	74.4856
1471.72	69.6363
1474.85	65.1783
1477.98	58.7917
1481.11	53.6392
1484.23	47.9759
1487.36	44.2383
1490.48	39.9443
1493.61	34.9194
1496.73	32.2407
1499.85	29.9796
1502.97	28.7
1506.09	27.3403
1509.2	27.777
1512.32	28.2545
1515.44	28.3363
1518.55	28.8597
1521.66	29.8673
1524.77	29.1568
1527.88	28.433
1530.99	28.851
1534.1	32.7858
1537.21	40.1218
1540.31	47.3745
1543.42	52.8009
1546.52	58.3759
1549.62	65.3262
1552.72	69.5453
1555.82	73.0814
1558.92	77.0458
1562.02	80.6813
1565.11	83.7647
1568.21	85.3135
1571.3	86.1288
1574.39	88.3872
1577.49	90.1917
1580.58	91.0711
1583.67	91.9783
1586.75	91.2145
1589.84	89.559
1592.93	88.811
1596.01	87.7526
1599.09	84.51
1602.18	83.5893
1605.26	82.1209
1608.34	82.2682
1611.41	82.9703
1614.49	83.9941
1617.57	86.7839
1620.64	87.9426
1623.72	88.196
1626.79	88.7842
1629.86	90.2982
1632.93	93.6801
1636	96.8997
1639.07	98.1241
1642.14	100.253
1645.2	101.43
1648.27	102.676
1651.33	103.528
1654.39	102.764
1657.45	102.126
1660.51	99.3912
1663.57	96.7614
1666.63	92.4687
1669.69	88.3991
1672.74	82.9084
1675.79	77.9391
1678.85	73.3994
1681.9	66.5186
1684.95	60.9476
1688	53.7959
1691.05	47.8588
1694.1	42.7165
1697.14	36.6508
1700.19	30.6445
1703.23	26.5369
1706.27	23.3722
1709.32	20.8758
1712.35	17.045
1715.39	14.6669
1718.43	13.7455
1721.47	11.5878
1724.5	9.20178
1727.54	8.89973
1730.57	8.91724
1733.61	8.40546
1736.64	7.43409
1739.67	6.85498
1742.7	5.81622
1745.72	6.47119
1748.75	6.00206
1751.78	5.58719
1754.8	5.93272
1757.82	5.22687
1760.85	4.77206
1763.87	4.77739
1766.89	3.89214
1769.91	3.7432
1772.92	2.54243
1775.94	1.77929
1778.96	3.18018
1781.97	3.75212
1784.98	3.10436
1788	2.76927
1791.01	2.35468
1794.01	1.65297
1797.02	1.15012
1800.03	0.451349
1803.04	1.11404
1806.04	0.499997
1809.05	0.571296
1812.05	0.281077
1815.05	0.282691
1818.05	-0.37309
1821.05	-0.483023
1824.05	-0.360496
1827.05	0.423589
1830.04	0.696713
1833.04	1.09486
1836.03	1.53804
1839.03	1.57991
1842.02	1.19454
1845.01	1.37956
1848	1.00098
1850.99	1.64751
1853.97	2.14999
1856.96	2.00276
1859.94	1.27582
1862.93	1.11986
1865.91	1.73154
1868.89	2.4551
1871.87	2.70721
1874.85	2.60304
1877.83	2.15961
1880.81	3.20627
1882.56	3.05267
1885.55	3.84842
1888.54	3.6125
1891.52	3.71315
1894.51	4.75368
1897.49	5.01581
1900.48	6.1997
1903.46	6.88559
1906.44	7.81959
1909.42	7.02498
1912.4	6.50877
1915.38	5.70158
1918.35	5.50868
1921.33	4.82544
1924.3	4.56253
1927.28	4.65805
1930.25	3.42951
1933.22	3.48062
1936.19	3.45974
1939.16	3.72083
1942.13	3.27993
1945.09	3.32308
1948.06	2.51567
1951.03	2.37348
1953.99	2.60725
1956.95	1.89714
1959.91	1.14356
1962.87	0.704274
1965.83	1.80573
1968.79	3.10522
1971.75	3.72648
1974.7	3.5369
1977.66	3.1611
1980.61	2.4511
1983.56	2.21927
1986.52	2.37629
1989.47	3.06772
1992.41	3.69073
1995.36	3.53074
1998.31	5.11305
2001.26	5.23863
2004.2	5.29796
2007.15	6.71348
2010.09	7.30145
2013.03	8.94074
2015.97	9.76311
2018.91	9.71911
2021.85	10.425
2024.79	11.0999
2027.72	12.7371
2030.66	13.8632
2033.59	14.7959
2036.53	16.076
2039.46	17.3282
2042.39	17.8228
2045.32	18.5372
2048.25	19.4443
2051.18	19.0489
2054.1	20.383
2057.03	22.6156
2059.95	23.1976
2062.88	24.0459
2065.8	24.7809
2068.72	25.8912
2071.64	26.7267
2074.56	28.3011
2077.48	30.0448
2080.39	32.4188
2083.31	33.5125
2086.22	36.2967
2089.14	38.1541
2092.05	40.8645
2094.96	43.8136
2097.87	47.0919
2100.78	51.0773
2103.69	53.3643
2106.6	56.3107
2109.51	60.7321
2112.41	65.097
2115.32	70.251
2118.22	74.4029
2121.12	79.4393
2124.02	84.4055
2126.92	89.5174
2129.82	93.8941
2132.72	98.5197
2135.62	103.432
2138.51	108.302
2141.41	113.38
2144.3	118.547
2147.19	123.127
2150.09	127.107
2152.97	130.925
2155.86	133.066
2158.75	137.007
2161.64	138.589
2164.53	139.048
2167.41	139.527
2170.3	138.866
2173.18	137.358
2176.06	135.195
2178.94	133.052
2181.82	131.234
2184.7	128.332
2187.58	125.004
2190.46	121.334
2193.33	117.347
2196.21	112.747
2199.08	107.968
2201.95	102.632
2204.83	98.0272
2207.7	94.2255
2210.57	89.506
2213.43	85.1022
2216.3	80.743
2219.17	75.7732
2222.03	71.5365
2224.9	67.8
2227.76	63.7923
2230.62	59.3683
2233.49	54.4614
2236.34	50.5458
2239.2	47.4078
2242.06	43.5002
2244.92	41.2568
2247.78	38.8012
2250.63	38.3816
2253.48	36.712
2256.34	35.7235
2259.19	34.8218
2262.04	33.7037
2264.89	32.3274
2267.74	31.3309
2270.59	30.0708
2273.43	28.9429
2276.28	26.8468
2279.12	25.6252
2281.97	24.1797
2284.81	23.5321
2287.65	21.3695
2290.49	19.0767
2293.33	17.3684
2296.17	16.3228
2299.01	15.5136
2301.84	14.5991
2304.68	13.7353
2307.51	13.0087
2310.35	12.6034
2313.18	12.2002
2316.01	12.3602
2318.84	12.602
2321.67	12.894
2324.5	12.5565
2327.33	12.7292
2330.15	12.7759
2332.98	12.5057
2335.8	12.5064
2338.62	12.3564
2341.45	11.8979
2344.27	11.2666
2347.09	11.0891
2349.91	10.5015
2352.72	9.05476
2355.54	8.26405
2358.36	6.60978
2361.17	6.2352
2363.98	6.45954
2366.8	6.74219
2369.61	5.86759
2372.42	5.36655
2375.23	4.19733
2378.04	3.31193
2380.85	2.72795
2383.66	2.10631
2386.46	1.72203
2389.26	1.62521
2392.07	1.35935
2394.87	1.95742
2397.67	2.12525
2400.47	2.27551
2403.27	3.49946
2406.07	3.53291
2408.87	3.21892
2411.67	3.67076
2414.46	4.4315
2417.26	4.62177
2420.05	5.41252
2422.84	6.39463
2425.64	6.8727
2428.43	7.10869
2431.22	7.2316
2434.01	7.42903
2436.79	7.27766
2439.58	7.20237
2442.37	6.67902
2445.15	5.55398
2447.93	5.47782
2450.72	4.76623
2453.5	4.92587
2456.28	4.70999
2459.06	4.49724
2461.84	4.87905
2464.62	4.88513
2467.39	4.08822
2470.17	3.86128
2472.94	3.86138
2475.72	3.59468
2478.49	4.11368
2481.26	4.92789
2484.03	5.15069
2486.8	4.68707
2489.57	4.86078
2492.34	4.12417
2495.1	4.14731
2497.87	3.70017
2500.63	3.58039
2503.4	4.4601
2506.16	3.32756
2508.92	2.65901
2511.68	0.658152
2514.44	0.487269
2517.2	0.243746
2519.96	0.338744
2522.72	0.502884
2525.47	1.51079
2528.23	1.36258
2530.98	0.814546
2533.74	0.520101
2536.49	0.663545
2539.24	1.87793
2541.99	2.38043
2544.74	2.71514
2547.49	2.59541
2550.23	3.44707
2552.98	2.61574
2555.72	3.53702
2558.47	3.37038
2561.21	4.18283
2563.95	5.65223
2566.69	5.53352
2569.43	5.46706
2572.17	5.14434
2574.91	4.81935
2577.65	4.52778
2580.39	4.86635
2583.12	4.94287
2585.85	5.30297
2588.59	5.22587
2591.32	5.03598
2594.05	4.94416
2596.78	3.84531
2599.51	2.88664
2602.24	2.62763
2604.97	2.77199
2607.69	2.78881
2610.42	2.20792
2613.14	3.04234
2615.87	2.25358
2618.59	2.16172
2621.31	2.13588
2624.03	2.88198
2626.75	3.13445
2629.47	3.71249
2632.19	3.41231
2634.91	3.41755
2637.62	3.88778
2640.34	3.95141
2643.05	4.21004
2645.76	3.91812
2648.48	3.75956
2651.19	3.35111
2653.9	3.03391
2656.6	2.52062
2659.31	2.79657
2662.02	1.95097
2664.73	0.897255
2667.43	0.332089
2670.14	0.390487
2672.84	0.956011
2675.54	1.16544
2678.24	1.63749
2680.94	2.21875
2683.64	1.54751
2686.34	2.89481
2689.04	3.82529
2691.74	3.96191
2694.43	5.18277
2697.13	4.95187
2699.82	5.14689
2702.51	5.47593
2705.21	5.78309
2707.9	7.45678
2710.58	8.16056
2713.27	8.83421
2715.96	9.59679
2718.65	9.73335
2721.33	10.0152
2724.02	10.4029
2726.71	10.6932
2729.39	9.89764
2732.07	9.15362
2734.75	9.24649
2737.43	9.42597
2740.11	9.45347
2742.79	9.91963
2745.47	9.66198
2748.14	9.13207
2750.82	8.27348
2753.49	7.75125
2756.17	7.01856
2758.84	6.15156
2761.51	5.29989
2764.18	4.04947
2766.85	3.95997
2769.52	3.29219
2772.19	3.66201
2774.86	3.04599
2777.52	1.7596
2780.19	1.54316
2782.85	1.44611
2785.52	0.500881
2788.18	0.555838
2790.84	-0.751878
2793.5	0.286807
2796.16	-0.889438
2798.82	-0.346423
2801.48	0.161084
2804.13	0.378367
2806.79	0.279287
2809.45	-0.55162
2812.1	-0.852715
2814.75	-1.42702
2817.41	0.221858
2820.06	3.22824
2822.71	7.95387
2825.36	14.0596
2828	20.8547
2830.65	27.5939
2833.3	34.9846
2835.94	42.3488
2838.59	50.3988
2841.23	58.9332
2843.87	67.8548
2846.52	78.41
2849.16	88.6198
2851.8	99.8355
2854.44	110.931
2857.08	123.176
2859.71	133.943
2862.35	143.182
2864.98	151.345
2867.62	159.321
2870.25	164.9
2872.88	169.508
2875.52	173.906
2878.15	178.234
2880.78	183.724
2883.41	188.876
2886.03	193.946
2888.66	199.347
2891.29	203.682
2893.91	208.455
2896.54	214.576
2899.16	222.065
2901.78	230.385
2904.4	239.968
2907.02	250.363
2909.64	262.675
2912.26	276.695
2914.88	289.128
2917.5	302.082
2920.11	313.427
2922.73	322.295
2925.34	329.134
2927.96	333.254
2930.57	335.647
2933.18	336.238
2935.79	333.547
2938.4	329.077
2941.01	322.441
2943.62	314.364
2946.22	303.249
2948.83	291.986
2951.43	277.713
2954.04	263.876
2956.64	249.803
2959.24	236.876
2961.84	223.689
2964.45	209.699
2967.05	196.011
2969.64	183.331
2972.24	172.348
2974.84	161.221
2977.43	149.047
2980.03	137.159
2982.62	125.644
2985.22	113.065
2987.81	102.9
2990.4	92.2401
2992.99	82.5869
2995.58	73.807
2998.17	64.6443
3000.76	56.411
3003.34	49.8957
3005.93	43.474
3008.52	37.078
3011.1	31.4875
3013.68	25.835
3016.27	22.3148
3018.85	19.6758
3021.43	17.4563
3024.01	15.2878
3026.59	14.3364
3029.16	13.475
3031.74	12.7094
3034.32	13.3451
3036.89	13.7513
3039.47	14.2524
3042.04	14.5001
3044.61	15.6521
3047.18	16.4714
3049.75	17.2795
3052.32	17.4814
3054.89	17.1826
3057.46	17.1259
3060.03	16.5647
3062.59	15.7383
3065.16	14.4086
3067.72	12.8175
3070.29	11.194
3072.85	9.52176
3075.41	7.69667
3077.97	6.22801
3080.53	5.02313
3083.09	3.36491
3085.65	1.96249
3088.21	0.976724
3090.76	0.0721914
3093.32	-0.960051
3095.87	-0.643071
3098.43	-1.32338
3100.98	-1.6015
3103.53	-0.98444
3106.08	-0.602699
3108.63	0.396051
3111.18	1.50388
3113.73	2.74204
3116.28	3.48333
3118.83	4.6269
3121.37	6.63316
3123.92	8.40856
3126.46	9.87275
3129	12.0293
3131.55	14.0806
3134.09	15.947
3136.63	18.0053
3139.17	20.8383
3141.71	23.4523
3144.24	25.5373
3146.78	27.8083
3149.32	28.5777