File: data/Raman/poly_smoothed/Thy_40_11_12_1x_45s_532 nm_x100_100%_600 gr_mm_01.txt
#Acq. time (s)=	45
#Accumulations=	2
#Range (cm-¹)=	200...3150
#Windows=	2
#Auto scanning=	Off
#Autofocus=	Off
#Macrospot=	Off
#AutoExposure=	Off
#Spike filter=	Multiple accum.
#Delay time (s)=	0
#Binning=	1
#Readout mode=	Signal
#DeNoise=	Off
#ICS correction=	On
#Dark correction=	Off
#Inst. Process=	Off
#Detector Gain=	Best Dynamic Range
#Detector ADC=	20 kHz
#Detector temperature (°C)=	-69.85
#Instrument=	LabRAM HR Evol
#Detector=	Synapse
#Objective=	x100
#Grating=	600 gr/mm
#ND Filter=	100%
#Laser (nm)=	532
#Hole=	100.021
#Range=	Auto
#Laser Pol.=	No
#Raman. Pol.=	No
#Laser Pol. (°)=	-0.0007625
#Raman Pol. (°)=	89.9995
#Collection=	Microscope
#StageXY=	Marzhauser
#StageZ=	Marzhauser
#X (µm)=	1978.6
#Y (µm)=	-57.7
#Z (µm)=	425.3
#Full time(mm:ss)=	3:18
#Project=
#Sample=
#Site=
#Title=	Thy_40_11_12_2x_45s_532 nm_x100_100%_600 gr_mm
#Remark=
#Date=	05.07.2022 10:42
#Acquired=	05.07.2022 10:42:32
#Base:Fit=	10.08.2022 10:01:35
#Base:Sub=	10.08.2022 10:01:52
#Filter:Polynom=	16.08.2022 10:21:53
#AxisType[0]=Intens
#AxisUnit[0]=Cnt
#AxisType[1]=Spectr
#AxisUnit[1]=1/cm
200.43	0.63434
204.059	6.6796
207.688	9.25661
211.314	10.8745
214.941	10.6293
218.564	11.8452
222.186	12.776
225.809	10.7671
229.428	10.0602
233.045	9.9889
236.663	9.95144
240.278	11.2253
243.891	11.0577
247.503	11.1092
251.116	10.0078
254.725	9.91681
258.333	9.78508
261.939	9.9214
265.544	12.4495
269.148	12.3929
272.75	12.2084
276.351	13.6851
279.95	14.2008
283.548	14.5158
287.144	14.1533
290.739	14.7892
294.333	15.9478
297.925	17.0333
301.514	17.274
305.104	18.7381
308.692	18.868
312.279	17.1306
315.862	17.3921
319.446	17.9786
323.029	18.2404
326.608	20.3502
330.188	21.1582
333.766	20.3498
337.341	19.6706
340.917	19.7975
344.489	18.4128
348.062	17.2392
351.631	16.9518
355.201	15.2739
358.768	14.8497
362.333	14.9116
365.899	15.3628
369.462	13.9837
373.023	12.5921
376.585	12.2568
380.143	11.1248
383.7	12.3063
387.256	11.8418
390.812	11.5007
394.365	9.5334
397.916	8.10572
401.467	7.5763
405.015	8.35271
408.563	6.53095
412.109	7.87036
415.654	5.2866
419.197	4.2681
422.739	3.10107
426.279	3.07782
429.819	3.92142
433.356	3.40383
436.891	3.02642
440.426	3.33655
443.96	4.174
447.492	3.99203
451.021	4.92179
454.551	7.50553
458.079	8.93795
461.604	11.2115
465.13	15.0346
468.654	16.9922
472.175	20.7374
475.696	21.5865
479.215	23.7806
482.733	24.6899
486.249	23.4519
489.765	26.3977
493.278	25.7145
496.789	25.7037
500.301	25.0069
503.81	24.7075
507.317	25.5877
510.825	26.7916
514.33	26.2687
517.833	25.4012
521.335	22.7801
524.836	21.1899
528.335	20.3495
531.835	18.4937
535.332	16.3575
538.827	16.1022
542.321	16.3456
545.814	14.9953
549.305	13.5663
552.795	12.2398
556.282	11.0002
559.769	9.79288
563.255	7.86613
566.739	5.77349
570.223	3.21386
573.705	2.54371
577.183	2.55215
580.663	1.4567
584.141	0.166998
587.615	-0.213817
591.09	1.35535
594.564	2.21825
598.035	0.817074
601.506	2.35256
604.974	3.46908
608.443	4.91439
611.908	5.39712
615.374	6.59749
618.837	6.61701
622.3	8.13079
625.761	9.36017
629.219	9.35112
632.677	10.1265
636.135	11.2369
639.59	11.7105
643.043	12.4682
646.495	14.7502
649.948	13.7434
653.398	15.6477
656.846	16.8385
660.293	17.1618
663.738	17.049
667.183	17.4104
670.626	18.1459
674.067	19.8423
677.508	19.9968
680.947	21.2506
684.385	23.9946
687.821	25.9067
691.254	27.4449
694.688	27.7727
698.121	31.128
701.552	32.3476
704.98	33.1216
708.409	33.8868
711.836	35.3739
715.26	36.1833
718.685	39.2636
722.108	41.5805
725.528	42.816
728.949	43.8188
732.367	44.5652
735.785	45.6856
739.2	47.6569
742.614	49.0864
746.028	50.7101
749.439	53.825
752.849	54.4618
756.26	55.6013
759.667	57.0777
763.073	57.8468
766.477	58.4951
769.883	60.5923
773.285	62.3989
776.686	64.9432
780.085	67.9353
783.484	68.3221
786.881	69.0495
790.276	71.7215
793.671	72.5083
797.064	74.5876
800.456	75.787
803.846	76.6484
807.234	77.226
810.622	76.6615
814.008	77.2907
817.394	77.9746
820.778	80.2043
824.159	80.0053
827.541	80.4902
830.921	80.9932
834.298	79.6658
837.676	77.5434
841.051	76.6368
844.426	73.9555
847.798	71.9617
851.171	70.9099
854.54	69.4954
857.911	68.1221
861.278	65.5102
864.645	63.889
868.01	60.8549
871.373	59.1899
874.735	56.3033
878.097	53.7256
881.457	52.4049
884.815	52.0124
888.172	50.7294
891.528	50.3373
894.882	49.1619
898.237	47.6602
901.589	49.1457
904.94	47.7155
908.289	46.8896
911.635	45.6089
914.982	44.573
918.328	45.7878
921.672	45.9628
925.015	45.6398
928.357	45.5338
931.698	44.3826
935.035	44.1625
938.373	43.8123
941.71	42.2899
945.044	41.2554
948.378	41.5744
951.709	40.7551
955.041	42.8519
958.372	42.3086
961.699	42.9456
965.027	45.0917
968.352	45.7623
971.676	45.3255
975	44.3729
978.322	43.6117
981.642	42.7277
984.962	42.3195
988.28	40.4413
991.596	39.1251
994.911	37.3934
998.227	37.6274
1001.54	35.7194
1004.85	34.4379
1008.16	33.2196
1011.47	31.0187
1014.78	28.5254
1018.08	27.6691
1021.39	27.4448
1024.69	28.1622
1028	28.9658
1031.3	30.2382
1034.6	30.621
1037.9	30.1186
1041.19	30.0241
1044.49	30.8191
1047.78	30.2236
1051.08	27.7048
1054.37	26.1641
1057.66	25.0544
1060.95	24.4063
1064.24	23.7357
1067.53	22.8437
1070.81	20.0406
1074.1	18.3485
1077.38	17.4306
1080.66	17.4736
1083.94	17.1566
1087.22	16.381
1090.5	15.5385
1093.78	15.7653
1097.05	17.5458
1100.33	18.8648
1103.6	19.3292
1106.87	19.0879
1110.14	18.9226
1113.41	19.8634
1116.68	19.4047
1119.95	18.4522
1123.21	18.7805
1126.48	17.324
1129.74	16.5762
1133	17.0129
1136.26	16.3891
1139.52	16.6677
1142.78	15.3854
1146.04	13.7892
1149.29	12.3895
1152.55	11.3631
1155.8	9.91206
1159.05	9.35418
1162.3	8.15837
1165.55	7.22407
1168.8	6.7208
1172.05	7.1081
1175.29	7.68415
1178.54	7.35119
1181.78	6.75416
1185.02	7.75118
1188.26	9.49601
1191.5	10.5925
1194.74	11.4584
1197.97	12.3159
1201.21	13.924
1204.44	17.8013
1207.68	21.4533
1210.91	24.8809
1214.14	27.8319
1217.37	28.7422
1220.59	30.4663
1223.82	33.4514
1227.05	36.0601
1230.27	37.2875
1233.49	40.4907
1236.72	42.7109
1239.94	46.4414
1243.16	49.4374
1246.37	51.4414
1249.59	53.5802
1252.8	55.0768
1256.02	55.9115
1259.23	57.5696
1262.44	59.8462
1265.66	61.0355
1268.86	61.911
1272.07	63.0207
1275.28	65.0815
1278.48	67.4073
1281.69	68.4012
1284.89	69.6265
1288.09	69.354
1291.29	69.8611
1294.49	70.1973
1297.69	70.1949
1300.89	70.0474
1304.08	70.3434
1307.28	70.3984
1310.47	71.3948
1313.66	72.6139
1316.85	71.6912
1320.04	71.9181
1323.23	71.5119
1326.42	69.3395
1329.61	67.285
1332.79	65.2956
1335.97	63.9937
1339.16	63.0223
1342.34	59.8123
1345.52	58.8401
1348.7	55.2296
1351.87	52.3831
1355.05	50.0226
1358.22	45.8375
1361.4	43.1581
1364.57	41.8114
1367.74	40.4375
1370.91	40.7453
1374.08	39.439
1377.25	39.0758
1380.41	38.389
1383.58	39.1896
1386.74	38.8237
1389.91	39.4604
1393.07	39.2404
1396.23	38.9226
1399.39	38.9877
1402.55	36.9177
1405.7	36.1046
1408.86	36.7543
1412.01	36.3238
1415.17	38.9997
1418.32	41.5771
1421.47	44.1075
1424.62	46.9578
1427.77	51.2536
1430.91	56.6177
1434.06	60.7659
1437.2	65.8272
1440.35	68.6859
1443.49	71.7408
1446.63	72.9151
1449.77	72.9137
1452.91	73.3889
1456.05	73.8184
1459.18	71.8348
1462.32	69.8807
1465.45	66.4819
1468.59	61.6284
1471.72	55.397
1474.85	48.7656
1477.98	41.1643
1481.1	36.5136
1484.23	31.4953
1487.36	27.5795
1490.48	24.517
1493.61	22.9857
1496.73	19.1807
1499.85	18.2234
1502.97	19.3283
1506.09	17.7295
1509.2	16.1773
1512.32	15.7387
1515.43	14.3171
1518.55	14.5694
1521.66	14.5921
1524.77	15.6923
1527.88	17.5358
1530.99	19.5091
1534.1	21.3313
1537.21	23.0871
1540.31	24.3921
1543.42	26.952
1546.52	29.1
1549.62	31.3119
1552.72	33.9708
1555.82	36.6415
1558.92	39.9215
1562.02	41.3558
1565.11	44.0268
1568.21	45.2823
1571.3	47.4851
1574.39	48.9086
1577.49	51.6092
1580.57	52.8463
1583.66	53.568
1586.75	55.0525
1589.84	54.3928
1592.92	55.6905
1596.01	55.7525
1599.09	55.4361
1602.17	54.428
1605.25	54.1275
1608.33	52.1686
1611.41	52.5453
1614.49	53.4313
1617.57	53.1981
1620.64	52.7359
1623.72	53.6539
1626.79	57.144
1629.86	58.1291
1632.93	60.0597
1636	61.8528
1639.07	64.544
1642.13	68.2029
1645.2	70.1667
1648.26	72.6483
1651.33	74.578
1654.39	76.4543
1657.45	76.5545
1660.51	76.1306
1663.57	76.0508
1666.63	74.5232
1669.68	72.6032
1672.74	69.5094
1675.79	66.3649
1678.85	61.7877
1681.9	57.1349
1684.95	52.672
1688	48.5075
1691.05	43.5416
1694.09	38.5905
1697.14	33.2237
1700.18	29.5993
1703.23	25.455
1706.27	20.513
1709.31	18.6584
1712.35	14.9741
1715.39	13.2885
1718.43	10.013
1721.47	7.43416
1724.5	5.55407
1727.54	4.99058
1730.57	2.32621
1733.61	1.37205
1736.64	1.37425
1739.67	1.24536
1742.7	0.823221
1745.72	0.482167
1748.75	1.47173
1751.77	1.25507
1754.8	2.15719
1757.82	2.79191
1760.84	2.98093
1763.87	2.98724
1766.89	2.75484
1769.91	2.19362
1772.92	2.42661
1775.94	2.95671
1778.95	3.27469
1781.97	3.36078
1784.98	2.97157
1787.99	2.772
1791.01	2.67829
1794.01	2.47627
1797.02	1.71042
1800.03	1.25145
1803.04	1.31189
1806.04	0.664301
1809.05	0.561458
1812.05	1.28648
1815.05	1.10239
1818.05	0.877212
1821.05	0.801157
1824.05	0.519608
1827.05	0.989223
1830.04	0.657306
1833.04	0.654928
1836.03	0.376105
1839.03	0.435625
1842.02	1.03161
1845.01	1.08431
1848	1.50328
1850.99	1.74089
1853.97	2.9174
1856.96	2.72443
1859.94	1.93746
1862.93	2.06768
1865.91	1.96952
1868.89	1.94087
1871.87	2.63913
1874.85	2.54218
1877.83	2.41051
1880.81	2.42986
1882.57	3.32214
1885.56	3.70754
1888.55	3.96633
1891.54	3.07787
1894.52	3.62758
1897.51	3.09903
1900.49	2.43651
1903.47	3.00927
1906.45	2.88473
1909.43	2.44988
1912.41	2.73439
1915.39	2.66369
1918.37	2.30759
1921.34	3.79053
1924.32	3.67914
1927.29	2.86708
1930.26	1.56
1933.23	0.71407
1936.2	0.49648
1939.17	0.514694
1942.14	0.185141
1945.11	0.0641474
1948.07	0.539465
1951.04	0.809717
1954	1.54696
1956.96	1.67281
1959.93	3.08398
1962.89	2.76327
1965.85	3.45278
1968.8	3.71183
1971.76	4.18765
1974.72	4.77169
1977.67	5.58716
1980.63	5.68795
1983.58	6.03006
1986.53	5.9998
1989.48	6.53254
1992.43	5.83579
1995.38	5.78188
1998.32	4.91925
2001.27	3.73319
2004.22	2.91146
2007.16	2.93108
2010.1	2.84781
2013.04	2.73322
2015.98	2.34493
2018.92	2.76406
2021.86	2.26174
2024.8	2.86939
2027.74	3.529
2030.67	3.62928
2033.61	4.19173
2036.54	5.2414
2039.47	5.63081
2042.4	5.99484
2045.33	6.79645
2048.26	7.58228
2051.19	8.42138
2054.12	9.46373
2057.04	10.5065
2059.97	10.9191
2062.89	10.2721
2065.81	11.1166
2068.73	11.1575
2071.65	11.1728
2074.57	11.1778
2077.49	12.0181
2080.41	12.8587
2083.32	14.3783
2086.24	14.289
2089.15	14.449
2092.07	15.467
2094.98	17.2544
2097.89	18.127
2100.8	18.9395
2103.71	19.8296
2106.61	22.8059
2109.52	23.7675
2112.43	25.3145
2115.33	27.5877
2118.23	30.1057
2121.13	33.4602
2124.04	36.6344
2126.94	39.5022
2129.83	41.7567
2132.73	44.4577
2135.63	47.6592
2138.53	50.2025
2141.42	54.1732
2144.31	56.9956
2147.21	61.3416
2150.1	64.7303
2152.99	67.3183
2155.88	69.3949
2158.77	71.0299
2161.65	72.4919
2164.54	74.0754
2167.43	74.8073
2170.31	75.7886
2173.19	76.7076
2176.07	77.2019
2178.96	75.9397
2181.84	74.8599
2184.72	73.4705
2187.59	71.7099
2190.47	69.8424
2193.35	66.6408
2196.22	63.7421
2199.09	60.2402
2201.97	58.0726
2204.84	55.7843
2207.71	52.5761
2210.58	48.9361
2213.45	46.2217
2216.31	43.2482
2219.18	40.5998
2222.05	37.4185
2224.91	34.4339
2227.78	32.3009
2230.64	29.4293
2233.5	27.5496
2236.36	26.2574
2239.22	24.5892
2242.08	23.0744
2244.93	21.7559
2247.79	20.6298
2250.64	19.1978
2253.5	18.7128
2256.35	17.97
2259.2	17.4919
2262.05	17.4213
2264.9	16.8375
2267.75	16.4883
2270.6	16.1233
2273.45	16.4791
2276.29	14.221
2279.14	13.9787
2281.98	12.9732
2284.82	12.9604
2287.66	12.7261
2290.5	10.6857
2293.34	9.78275
2296.18	8.96926
2299.02	8.56994
2301.86	9.30026
2304.69	9.06771
2307.53	9.06999
2310.36	10.579
2313.19	11.3655
2316.02	11.6261
2318.85	11.3334
2321.68	12.1246
2324.51	12.5846
2327.34	12.0589
2330.16	12.5202
2332.99	11.0145
2335.81	11.0846
2338.64	10.7768
2341.46	9.44027
2344.28	7.64316
2347.1	6.28164
2349.92	5.67498
2352.74	4.33238
2355.55	3.23027
2358.37	0.972196
2361.19	-0.335313
2364	-0.671698
2366.81	-0.214397
2369.62	0.225758
2372.44	-0.026921
2375.24	0.380205
2378.05	0.818936
2380.86	1.30632
2383.67	1.67258
2386.47	0.983276
2389.28	1.41868
2392.08	1.7953
2394.89	2.4113
2397.69	2.75792
2400.49	3.61426
2403.29	4.91016
2406.09	5.29761
2408.88	5.81514
2411.68	6.60597
2414.48	7.12973
2417.27	8.07656
2420.06	8.4115
2422.86	7.98772
2425.65	7.21104
2428.44	7.1039
2431.23	8.07172
2434.02	8.87498
2436.81	7.49953
2439.59	7.60168
2442.38	7.92352
2445.16	7.7521
2447.95	7.26903
2450.73	6.44368
2453.51	5.00558
2456.29	5.25294
2459.07	4.12728
2461.85	4.50673
2464.63	4.96466
2467.4	4.51579
2470.18	4.18029
2472.95	3.35297
2475.73	3.27245
2478.5	3.17138
2481.27	2.62013
2484.04	1.39805
2486.81	0.361014
2489.58	0.619659
2492.35	0.624552
2495.12	0.778425
2497.88	0.255961
2500.65	0.617259
2503.41	0.193508
2506.17	-0.889042
2508.94	0.772759
2511.7	1.41887
2514.46	2.6521
2517.22	1.99747
2519.97	3.07748
2522.73	3.92517
2525.49	4.20554
2528.24	4.18066
2530.99	5.88268
2533.75	6.81883
2536.5	7.42279
2539.25	8.43538
2542	9.22433
2544.75	9.00877
2547.5	8.70617
2550.24	9.41342
2552.99	9.47197
2555.74	10.2681
2558.48	10.4417
2561.22	9.11802
2563.96	8.59733
2566.71	7.94785
2569.45	7.80231
2572.18	6.80617
2574.92	7.73186
2577.66	7.68677
2580.4	7.44567
2583.13	6.6745
2585.87	5.99948
2588.6	5.46406
2591.33	5.2533
2594.06	4.44598
2596.79	5.13983
2599.52	5.27841
2602.25	4.77573
2604.98	5.27441
2607.71	4.93586
2610.43	4.79049
2613.16	4.56651
2615.88	5.38804
2618.6	6.29675
2621.32	6.0477
2624.04	5.84126
2626.76	4.34113
2629.48	3.95181
2632.2	3.63642
2634.92	3.79938
2637.63	3.64158
2640.35	4.76709
2643.06	4.48362
2645.77	5.08264
2648.49	5.93314
2651.2	6.25465
2653.91	6.08573
2656.62	5.96096
2659.33	7.53907
2662.03	7.9055
2664.74	7.58839
2667.44	7.42161
2670.15	8.10655
2672.85	7.89223
2675.55	8.63487
2678.26	9.30222
2680.96	8.65837
2683.66	8.74129
2686.35	8.05266
2689.05	7.3726
2691.75	7.09763
2694.44	7.18091
2697.14	7.15857
2699.83	7.23305
2702.52	7.54044
2705.22	8.72277
2707.91	8.67358
2710.6	9.22662
2713.29	10.4162
2715.97	9.98251
2718.66	9.81005
2721.35	10.0888
2724.03	10.5586
2726.72	10.0965
2729.4	9.68781
2732.08	10.4247
2734.76	10.13
2737.44	9.97208
2740.12	10.2303
2742.8	11.0049
2745.48	10.4155
2748.16	9.82957
2750.83	8.75932
2753.51	7.76136
2756.18	7.33436
2758.85	6.43052
2761.53	6.50522
2764.2	5.83439
2766.87	5.28654
2769.54	4.66448
2772.2	4.07236
2774.87	3.86302
2777.54	3.51514
2780.2	2.84368
2782.87	1.53415
2785.53	2.28742
2788.19	3.10279
2790.85	3.51304
2793.51	3.79895
2796.17	4.54674
2798.83	4.63598
2801.49	5.42824
2804.15	6.28379
2806.8	8.00154
2809.46	8.25688
2812.11	7.96147
2814.76	8.48083
2817.42	7.72946
2820.07	7.8231
2822.72	9.4871
2825.37	11.3471
2828.02	13.3277
2830.66	15.212
2833.31	17.1524
2835.96	19.6184
2838.6	22.3745
2841.24	26.0193
2843.89	29.7181
2846.53	35.1751
2849.17	41.2652
2851.81	47.153
2854.45	52.5434
2857.09	58.8934
2859.72	64.6049
2862.36	70.6617
2865	75.9045
2867.63	81.1208
2870.26	85.3657
2872.9	90.4282
2875.53	93.8139
2878.16	97.2355
2880.79	101.713
2883.42	104.666
2886.05	108.409
2888.67	112.319
2891.3	116.074
2893.92	120.066
2896.55	124.227
2899.17	127.548
2901.79	133.014
2904.42	139.592
2907.04	146.533
2909.66	156.016
2912.27	164.647
2914.89	173.469
2917.51	181.629
2920.13	189.933
2922.74	196.135
2925.35	201.482
2927.97	204.904
2930.58	207.788
2933.19	208.995
2935.8	208.787
2938.41	207.144
2941.02	203.795
2943.63	200.711
2946.24	195.793
2948.84	189.491
2951.45	182.844
2954.05	175.703
2956.65	167.274
2959.26	159.835
2961.86	152.379
2964.46	145.415
2967.06	137.602
2969.66	130.396
2972.25	123.792
2974.85	117.011
2977.45	110.247
2980.04	102.773
2982.64	95.912
2985.23	87.8451
2987.82	80.1094
2990.41	72.1222
2993	65.3683
2995.59	57.6219
2998.18	50.7308
3000.77	43.6457
3003.36	37.2979
3005.94	31.9892
3008.53	26.666
3011.11	22.1582
3013.69	19.1941
3016.28	16.7928
3018.86	14.6464
3021.44	13.2596
3024.02	12.1836
3026.6	11.3561
3029.18	11.2562
3031.75	11.1385
3034.33	11.7865
3036.9	13.3593
3039.48	14.8645
3042.05	16.0564
3044.62	16.5214
3047.19	17.9689
3049.77	17.9254
3052.34	18.2117
3054.9	18.5854
3057.47	17.6144
3060.04	17.2073
3062.61	16.4814
3065.17	15.7712
3067.74	13.7728
3070.3	12.0943
3072.86	10.3907
3075.42	9.68113
3077.99	8.65372
3080.54	7.38588
3083.1	5.83369
3085.66	4.86443
3088.22	4.01784
3090.78	3.64448
3093.33	3.22484
3095.89	3.34069
3098.44	4.11307
3100.99	4.22101
3103.54	4.86472
3106.1	5.59178
3108.65	6.41361
3111.2	6.66289
3113.74	7.22636
3116.29	7.32519
3118.84	8.53914
3121.38	9.59401
3123.93	11.143
3126.47	12.223
3129.01	11.614
3131.56	12.0664
3134.1	13.1946
3136.64	13.9684
3139.18	15.2076
3141.72	16.0868
3144.26	17.2413
3146.79	18.9023
3149.33	21.3473