File: data/Raman/poly_smoothed/Thy_10_08_44_1x_45s_532 nm_x100_100%_600 gr_mm_01.txt
#Acq. time (s)=	45
#Accumulations=	2
#Range (cm-¹)=	200...3150
#Windows=	2
#Auto scanning=	Off
#Autofocus=	Off
#Macrospot=	Off
#AutoExposure=	Off
#Spike filter=	Multiple accum.
#Delay time (s)=	0
#Binning=	1
#Readout mode=	Signal
#DeNoise=	Off
#ICS correction=	On
#Dark correction=	Off
#Inst. Process=	Off
#Detector Gain=	Best Dynamic Range
#Detector ADC=	20 kHz
#Detector temperature (°C)=	-69.85
#Instrument=	LabRAM HR Evol
#Detector=	Synapse
#Objective=	x100
#Grating=	600 gr/mm
#ND Filter=	100%
#Laser (nm)=	532
#Hole=	100.021
#Range=	Auto
#Laser Pol.=	No
#Raman. Pol.=	No
#Laser Pol. (°)=	-0.0007625
#Raman Pol. (°)=	89.9995
#Collection=	Microscope
#StageXY=	Marzhauser
#StageZ=	Marzhauser
#X (µm)=	-2354.7
#Y (µm)=	237.8
#Z (µm)=	521.25
#Full time(mm:ss)=	3:18
#Project=
#Sample=
#Site=
#Title=	Thy_10_08_44_2x_45s_532 nm_x100_100%_600 gr_mm
#Remark=
#Date=	06.07.2022 14:55
#Acquired=	06.07.2022 14:55:43
#Base:Fit=	10.08.2022 09:46:25
#Base:Sub=	10.08.2022 09:46:49
#Filter:Polynom=	16.08.2022 10:24:56
#AxisType[0]=Intens
#AxisUnit[0]=Cnt
#AxisType[1]=Spectr
#AxisUnit[1]=1/cm
200.398	16.8701
204.027	17.0728
207.657	17.0489
211.283	16.509
214.909	14.2764
218.533	12.4621
222.157	11.8523
225.777	10.7772
229.396	10.3432
233.016	8.95386
236.632	7.53274
240.247	6.84458
243.86	5.0522
247.474	4.47538
251.085	3.31476
254.694	1.91088
258.301	2.1745
261.908	2.27736
265.513	2.98318
269.116	4.02084
272.718	5.04729
276.319	5.65441
279.918	5.57285
283.516	6.08453
287.113	7.25671
290.708	6.47934
294.302	6.94495
297.894	7.81176
301.485	9.25338
305.073	9.28107
308.661	11.1242
312.247	12.0916
315.833	13.5227
319.415	13.4755
322.997	14.9015
326.579	15.7893
330.156	16.9476
333.735	17.3104
337.31	18.8297
340.885	20.8695
344.458	21.6701
348.03	21.7871
351.6	22.5628
355.17	22.0289
358.737	23.235
362.304	24.052
365.868	22.0117
369.431	20.1013
372.994	18.7725
376.554	18.8323
380.112	19.2334
383.669	18.1692
387.225	18.9684
390.781	17.6408
394.334	16.5634
397.885	15.8684
401.436	15.2859
404.984	15.6847
408.532	16.1393
412.078	15.7467
415.623	16.2104
419.166	16.6571
422.708	17.4858
426.248	18.0134
429.788	17.0129
433.326	14.3451
436.86	14.6341
440.395	13.8622
443.929	13.8677
447.461	15.6954
450.99	15.901
454.52	14.6023
458.048	14.4942
461.573	15.0431
465.099	16.5353
468.623	18.1493
472.144	17.7059
475.666	18.5311
479.184	18.7296
482.703	20.6056
486.218	22.3725
489.734	23.3392
493.247	24.1483
496.759	26.3523
500.271	28.1533
503.779	28.9758
507.287	28.267
510.795	29.4618
514.299	28.2248
517.803	26.8543
521.305	27.8058
524.805	27.7606
528.307	24.7097
531.805	23.6769
535.301	22.3948
538.797	18.4821
542.291	15.4901
545.783	13.5079
549.275	10.4695
552.765	8.75202
556.253	7.30392
559.738	6.61063
563.224	4.1508
566.709	3.51692
570.192	4.41303
573.674	3.3878
577.153	2.07738
580.632	2.07315
584.11	3.05813
587.587	2.88586
591.06	3.04412
594.534	4.01994
598.005	5.06343
601.476	6.27369
604.944	8.21484
608.413	8.91886
611.878	9.06372
615.344	9.39609
618.807	12.4272
622.27	11.4103
625.73	12.0609
629.189	14.1993
632.648	17.278
636.105	18.2355
639.559	19.4933
643.013	20.2785
646.467	21.2102
649.918	21.4473
653.368	23.4368
656.816	22.1154
660.263	20.1859
663.708	20.4
667.153	20.1818
670.596	19.3388
674.037	19.4508
677.478	19.6567
680.917	19.4939
684.355	20.4689
687.791	22.5979
691.224	24.5959
694.658	27.6993
698.091	29.082
701.522	31.0857
704.95	33.8107
708.379	36.2877
711.806	40.2953
715.23	43.4703
718.655	46.0494
722.078	47.8836
725.498	49.4829
728.919	51.7482
732.337	54.3846
735.755	54.2578
739.17	54.2449
742.584	55.2834
745.998	57.6816
749.409	59.9183
752.819	61.2422
756.23	65.5741
759.637	67.8867
763.043	70.5302
766.448	73.3676
769.853	75.9391
773.255	78.2836
776.656	79.8906
780.056	79.6668
783.454	80.47
786.851	82.5174
790.247	83.172
793.641	84.1732
797.034	85.523
800.426	86.295
803.817	86.7055
807.206	85.7441
810.592	85.4119
813.979	86.1602
817.364	84.3773
820.748	84.5324
824.129	83.9595
827.511	85.7561
830.891	85.5193
834.269	85.0941
837.646	85.2243
841.023	85.3849
844.396	82.2128
847.77	79.6071
851.141	78.1807
854.513	75.8109
857.881	74.1668
861.248	71.8798
864.616	69.0027
867.98	68.5819
871.343	66.6425
874.707	65.1239
878.068	63.3589
881.428	60.5589
884.786	58.8331
888.143	55.2987
891.498	53.9395
894.855	52.6111
898.208	50.9835
901.56	50.7934
904.91	50.8939
908.26	50.2456
911.608	48.5717
914.955	49.1261
918.298	48.4066
921.643	49.7138
924.986	49.2616
928.328	47.9232
931.668	47.1169
935.006	48.2174
938.344	47.9955
941.681	46.7094
945.014	45.7204
948.349	43.6163
951.682	43.1322
955.012	39.8524
958.343	33.6963
961.67	31.0534
964.998	30.6331
968.323	32.3367
971.649	34.1581
974.971	37.9334
978.293	41.2697
981.615	44.034
984.933	45.3632
988.251	45.1942
991.567	46.0757
994.884	48.5612
998.198	51.392
1001.51	50.8561
1004.82	51.8398
1008.13	50.8465
1011.44	48.0888
1014.75	47.1482
1018.06	44.7299
1021.36	41.5142
1024.66	37.7134
1027.97	34.144
1031.27	29.2437
1034.57	23.6999
1037.87	18.2921
1041.16	17.0669
1044.46	18.2876
1047.76	16.6952
1051.05	15.8165
1054.34	14.5998
1057.63	13.5376
1060.92	12.8031
1064.21	11.3698
1067.5	9.74712
1070.78	12.8536
1074.07	14.3869
1077.35	15.6776
1080.63	16.1883
1083.91	16.2987
1087.19	16.0245
1090.47	15.098
1093.75	16.8119
1097.03	17.3949
1100.3	19.1008
1103.57	18.3425
1106.84	18.4257
1110.11	18.0124
1113.38	15.8695
1116.65	14.4134
1119.92	12.3869
1123.19	9.43641
1126.45	7.18694
1129.71	4.93991
1132.97	4.3296
1136.23	4.33034
1139.49	5.05743
1142.75	5.05459
1146.01	4.49778
1149.26	5.65303
1152.52	5.95657
1155.77	5.10539
1159.02	5.2689
1162.27	3.97796
1165.52	3.05723
1168.77	3.30928
1172.02	4.55752
1175.26	6.80226
1178.51	7.53359
1181.75	8.62327
1184.99	10.8764
1188.23	11.262
1191.47	12.4304
1194.71	13.4303
1197.94	15.7343
1201.18	19.2493
1204.41	23.4468
1207.65	28.0972
1210.88	32.9544
1214.11	38.6799
1217.34	43.7266
1220.57	48.1457
1223.79	51.3844
1227.02	55.406
1230.24	59.3197
1233.47	63.1566
1236.69	65.2742
1239.91	66.5679
1243.13	67.6747
1246.34	69.8223
1249.56	70.8622
1252.78	70.3429
1255.99	70.1934
1259.2	69.4879
1262.42	67.9407
1265.63	67.0464
1268.84	64.2867
1272.04	65.0579
1275.25	65.048
1278.46	65.6443
1281.66	66.3188
1284.86	67.4108
1288.07	69.3377
1291.27	71.8932
1294.47	74.816
1297.66	77.1479
1300.86	79.5833
1304.06	81.8177
1307.25	84.0333
1310.44	87.3929
1313.64	90.0839
1316.83	91.6088
1320.02	93.2931
1323.2	95.197
1326.39	95.7023
1329.58	94.8571
1332.76	92.9719
1335.95	92.1562
1339.13	90.4394
1342.31	87.7968
1345.49	84.9929
1348.67	81.9372
1351.85	79.1459
1355.02	76.199
1358.2	72.2815
1361.37	70.1562
1364.54	65.6067
1367.71	61.9888
1370.88	59.3784
1374.05	57.0093
1377.22	53.4005
1380.39	49.2506
1383.55	46.2626
1386.72	44.4764
1389.88	42.563
1393.04	39.4329
1396.2	37.4608
1399.36	36.9809
1402.52	35.8324
1405.68	34.6069
1408.83	35.4674
1411.98	38.1772
1415.14	40.9473
1418.29	45.314
1421.44	51.633
1424.59	58.9091
1427.74	66.2266
1430.89	73.229
1434.03	79.5067
1437.18	84.9894
1440.32	87.9804
1443.46	92.5392
1446.6	95.318
1449.74	98.1854
1452.88	96.9838
1456.02	94.8702
1459.16	91.5036
1462.29	87.3812
1465.43	82.6106
1468.56	74.3493
1471.69	67.1235
1474.82	60.3907
1477.95	52.6634
1481.08	44.4768
1484.2	37.6825
1487.33	33.4047
1490.46	27.9518
1493.58	24.3298
1496.7	21.8455
1499.82	19.3361
1502.94	17.4181
1506.06	16.4587
1509.18	15.0356
1512.29	14.6514
1515.41	15.0019
1518.52	15.1809
1521.63	16.8985
1524.75	19.1118
1527.85	21.7607
1530.96	21.8403
1534.07	24.7056
1537.18	27.4547
1540.28	30.7673
1543.39	33.6959
1546.49	36.8252
1549.59	42.299
1552.69	47.613
1555.79	51.6042
1558.89	55.0377
1561.99	59.0842
1565.08	63.5084
1568.18	67.3928
1571.27	71.4689
1574.37	75.8888
1577.46	79.5091
1580.55	83.1745
1583.64	85.2332
1586.73	88.2278
1589.81	89.2347
1592.9	88.8674
1595.98	88.9365
1599.06	86.9833
1602.15	84.8455
1605.23	82.1976
1608.31	80.1524
1611.39	79.7867
1614.46	79.6979
1617.54	80.1669
1620.61	80.5665
1623.69	82.2856
1626.76	83.6948
1629.83	85.4541
1632.9	88.6603
1635.97	92.5915
1639.04	96.677
1642.11	102.599
1645.17	107.408
1648.24	112.826
1651.3	116.245
1654.36	118.645
1657.42	120.562
1660.48	120.955
1663.54	120.225
1666.6	117.272
1669.66	112.625
1672.71	108.32
1675.77	100.573
1678.82	93.2724
1681.87	86.8234
1684.92	78.9002
1687.97	72.0896
1691.02	63.7626
1694.07	55.6103
1697.11	47.9124
1700.16	42.4026
1703.2	36.13
1706.25	30.5068
1709.29	25.6338
1712.33	21.9193
1715.37	20.2603
1718.41	17.3368
1721.44	15.2453
1724.48	13.8334
1727.51	13.0198
1730.55	12.2522
1733.58	12.2606
1736.61	11.6551
1739.64	10.1506
1742.67	9.31496
1745.7	8.76799
1748.72	7.80629
1751.75	6.32298
1754.77	6.39888
1757.8	5.87394
1760.82	5.33721
1763.84	4.78346
1766.86	4.41742
1769.88	3.88866
1772.9	4.66534
1775.91	4.4822
1778.93	3.25795
1781.94	2.3085
1784.96	2.34421
1787.97	3.1444
1790.98	2.02313
1793.99	1.63005
1797	1.20326
1800.01	0.651496
1803.01	0.490651
1806.02	0.497723
1809.02	0.373776
1812.02	0.198757
1815.02	0.255661
1818.03	0.137547
1821.02	-0.0202984
1824.02	0.0720719
1827.02	0.587208
1830.02	1.2813
1833.01	2.19408
1836.01	3.36324
1839	4.27997
1841.99	5.19333
1844.98	5.69775
1847.97	6.52569
1850.96	6.88987
1853.95	7.2011
1856.93	6.02973
1859.92	5.36202
1862.9	4.35163
1865.88	3.07713
1868.87	3.7491
1871.85	2.86662
1874.83	2.51814
1877.81	2.93875
1880.78	2.55126
1882.53	2.22321
1885.52	2.00969
1888.51	2.28832
1891.5	2.23518
1894.48	2.90374
1897.47	4.24847
1900.45	5.45976
1903.43	6.735
1906.41	7.96324
1909.39	8.70874
1912.37	9.69373
1915.35	10.2927
1918.33	11.5545
1921.3	11.7714
1924.28	11.7672
1927.25	11.434
1930.22	11.2668
1933.19	11.6628
1936.16	11.4467
1939.13	11.4358
1942.1	12.0373
1945.07	11.6753
1948.03	12.5572
1951	11.7528
1953.96	11.5097
1956.92	11.1091
1959.88	10.9251
1962.84	10.6107
1965.8	10.7974
1968.76	11.6858
1971.72	12.4114
1974.67	12.9957
1977.63	12.8294
1980.58	13.0525
1983.54	14.0107
1986.49	14.3821
1989.44	14.4205
1992.39	14.7213
1995.33	15.4101
1998.28	16.6436
2001.23	16.2364
2004.17	15.7518
2007.12	15.526
2010.06	15.7438
2013	15.78
2015.94	16.7293
2018.88	16.7576
2021.82	17.0401
2024.76	16.2436
2027.69	15.5992
2030.63	15.2493
2033.56	15.6153
2036.5	17.1137
2039.43	17.9226
2042.36	18.256
2045.29	19.0435
2048.22	19.3612
2051.15	20.1343
2054.07	20.713
2057	20.6749
2059.92	20.3198
2062.85	20.6281
2065.77	20.4796
2068.69	20.9232
2071.61	19.9113
2074.53	19.5557
2077.45	19.0386
2080.37	19.1419
2083.28	19.4193
2086.2	19.2374
2089.11	18.4486
2092.02	17.6893
2094.94	17.9604
2097.85	18.1047
2100.76	18.52
2103.66	18.627
2106.57	19.8249
2109.48	21.3872
2112.38	21.4363
2115.29	21.7625
2118.19	23.5128
2121.09	24.7238
2123.99	25.8554
2126.89	27.155
2129.79	28.8249
2132.69	30.3296
2135.59	31.5942
2138.48	33.8731
2141.38	35.4619
2144.27	37.3365
2147.17	38.5261
2150.06	40.7503
2152.95	42.2127
2155.84	43.6058
2158.73	44.7668
2161.61	45.0915
2164.5	46.9542
2167.38	48.6905
2170.27	48.0984
2173.15	49.4372
2176.03	50.2329
2178.91	50.2936
2181.8	49.6322
2184.67	47.7877
2187.55	47.265
2190.43	46.564
2193.3	44.9583
2196.18	44.2373
2199.05	43.0343
2201.93	41.2606
2204.8	40.0061
2207.67	38.5481
2210.54	37.4497
2213.41	34.7201
2216.27	33.7614
2219.14	31.8121
2222.01	30.8464
2224.87	28.3022
2227.73	26.0349
2230.6	24.3082
2233.46	23.1771
2236.32	22.6642
2239.18	22.0494
2242.03	22.3343
2244.89	20.4531
2247.75	19.4953
2250.6	18.5619
2253.46	17.783
2256.31	18.4896
2259.16	18.5211
2262.01	18.1216
2264.86	18.2674
2267.71	18.3987
2270.56	18.2751
2273.4	18.1444
2276.25	17.8892
2279.09	17.8844
2281.94	17.7215
2284.78	17.9589
2287.62	17.34
2290.46	16.3998
2293.3	14.7495
2296.14	14.733
2298.98	14.8985
2301.82	15.6069
2304.65	15.621
2307.49	15.1175
2310.32	15.256
2313.15	14.6477
2315.98	15.042
2318.81	14.6293
2321.64	14.8644
2324.47	15.2207
2327.3	14.9662
2330.12	13.5823
2332.95	13.3156
2335.77	13.0295
2338.6	13.191
2341.42	12.6599
2344.24	12.8532
2347.06	12.1749
2349.88	11.7003
2352.7	10.2492
2355.51	9.39563
2358.33	8.85572
2361.14	7.93493
2363.96	7.90485
2366.77	8.36801
2369.58	7.52895
2372.39	6.69717
2375.2	5.49175
2378.01	5.29782
2380.82	5.86985
2383.63	4.53131
2386.43	3.51695
2389.24	3.10849
2392.04	2.50535
2394.84	3.08996
2397.65	2.83996
2400.45	3.30627
2403.25	4.10992
2406.05	5.23271
2408.84	5.67391
2411.64	6.811
2414.44	7.98876
2417.23	8.46138
2420.02	8.99411
2422.82	9.46059
2425.61	10.4061
2428.4	10.2627
2431.19	10.9133
2433.98	11.4533
2436.77	11.0139
2439.55	11.2826
2442.34	10.663
2445.12	10.2648
2447.91	9.63475
2450.69	8.08083
2453.47	6.48869
2456.25	6.41561
2459.03	5.57662
2461.81	3.97924
2464.59	3.57551
2467.36	2.8875
2470.14	2.8432
2472.92	2.21872
2475.69	2.22612
2478.46	2.13986
2481.23	1.91587
2484	1.68141
2486.77	1.77306
2489.54	1.12339
2492.31	0.622403
2495.08	0.654545
2497.84	1.3354
2500.61	1.23645
2503.37	0.84082
2506.13	1.3391
2508.9	1.32274
2511.66	0.600754
2514.42	-0.148954
2517.18	-0.187665
2519.93	-0.772609
2522.69	0.0755109
2525.45	-0.578829
2528.2	-0.465583
2530.95	-0.198185
2533.71	-0.0198903
2536.46	0.278655
2539.21	0.726057
2541.96	0.891671
2544.71	0.934839
2547.46	1.20419
2550.2	1.26138
2552.95	2.73747
2555.7	2.8001
2558.44	2.32232
2561.18	2.82985
2563.93	2.78292
2566.67	2.17188
2569.41	1.74516
2572.15	2.17611
2574.88	1.28808
2577.62	0.599546
2580.36	-0.725474
2583.09	-0.612328
2585.83	-0.853245
2588.56	-1.4217
2591.29	-1.97223
2594.02	-2.28512
2596.75	-2.10113
2599.48	-2.19371
2602.21	-2.72199
2604.94	-2.22563
2607.67	-2.23523
2610.39	-1.98382
2613.12	-1.40101
2615.84	-0.929653
2618.56	0.0859582
2621.28	-0.048448
2624.01	0.466396
2626.72	0.955648
2629.44	1.66673
2632.16	1.76715
2634.88	2.65274
2637.59	3.34288
2640.31	3.22736
2643.02	3.66986
2645.74	4.54276
2648.45	4.56341
2651.16	4.41174
2653.87	4.11007
2656.58	4.02601
2659.29	5.29717
2661.99	5.78199
2664.7	5.34112
2667.41	4.36958
2670.11	4.37259
2672.81	4.15501
2675.51	3.85656
2678.22	3.28215
2680.92	3.88507
2683.62	4.10681
2686.31	4.63204
2689.01	5.12973
2691.71	5.61549
2694.4	6.59379
2697.1	7.47071
2699.79	8.36419
2702.49	9.41917
2705.18	10.5183
2707.87	11.4986
2710.56	13.0783
2713.25	14.4578
2715.94	15.0083
2718.62	15.4949
2721.31	17.4263
2723.99	18.1873
2726.68	17.6694
2729.36	17.7679
2732.04	17.4716
2734.73	16.7105
2737.41	17.3803
2740.08	16.7012
2742.76	15.8457
2745.44	15.2648
2748.12	14.2772
2750.79	13.2279
2753.47	12.3737
2756.14	12.32
2758.81	10.9801
2761.49	9.77217
2764.16	9.30864
2766.83	7.30649
2769.5	6.54794
2772.16	5.30671
2774.83	4.95344
2777.5	3.68817
2780.16	3.73071
2782.83	2.3338
2785.49	2.21872
2788.15	2.17554
2790.82	1.28565
2793.48	1.48601
2796.14	1.46687
2798.79	1.93348
2801.45	2.42332
2804.11	2.71677
2806.76	1.84232
2809.42	2.52084
2812.07	3.10856
2814.73	4.21961
2817.38	6.41308
2820.03	10.471
2822.68	14.6935
2825.33	18.6331
2827.98	24.3012
2830.63	30.1329
2833.27	35.5871
2835.92	42.5879
2838.56	49.4346
2841.21	58.4595
2843.85	68.5068
2846.49	80.2092
2849.13	93.2615
2851.77	107.471
2854.41	121.318
2857.05	133.856
2859.69	147.726
2862.32	161.142
2864.96	173.045
2867.59	184.754
2870.23	194.09
2872.86	203.554
2875.49	211.19
2878.12	218.487
2880.75	225.324
2883.38	233.226
2886.01	238.494
2888.63	244.414
2891.26	250.272
2893.89	256.306
2896.51	261.772
2899.13	269.299
2901.76	278.254
2904.38	290.262
2907	305.305
2909.62	322.87
2912.24	341.604
2914.85	359.63
2917.47	376.903
2920.09	392.552
2922.7	405.434
2925.32	415.586
2927.93	423.306
2930.54	426.569
2933.15	426.026
2935.76	422.959
2938.37	417.135
2940.98	408.848
2943.59	397.124
2946.2	384.949
2948.8	369.747
2951.41	353.529
2954.01	338.181
2956.62	321.42
2959.22	304.267
2961.82	289.122
2964.42	273.633
2967.02	259.44
2969.62	248.236
2972.22	236.879
2974.81	225.756
2977.41	215.387
2980	204.689
2982.6	191.847
2985.19	178.888
2987.78	164.778
2990.38	152.406
2992.97	139.738
2995.56	127.26
2998.14	115.675
3000.73	104.933
3003.32	95.0442
3005.91	84.6829
3008.49	76.4669
3011.07	68.3486
3013.66	61.8068
3016.24	55.4456
3018.82	50.8831
3021.4	45.8265
3023.98	43.1013
3026.56	40.0645
3029.14	37.7572
3031.71	37.1676
3034.29	37.3893
3036.87	37.2948
3039.44	38.57
3042.01	39.4722
3044.59	40.2527
3047.16	41.6322
3049.73	42.7605
3052.3	43.9531
3054.87	44.6278
3057.43	44.3192
3060	43.813
3062.57	43.3006
3065.13	41.478
3067.7	39.3493
3070.26	37.2761
3072.82	34.3812
3075.39	30.2656
3077.95	26.9071
3080.51	23.1655
3083.07	19.5979
3085.63	17.0104
3088.18	14.1345
3090.74	11.8282
3093.29	9.39297
3095.85	7.32321
3098.4	6.13235
3100.95	4.50586
3103.51	3.77946
3106.06	2.23762
3108.61	1.63762
3111.16	0.951536
3113.71	0.407143
3116.25	-0.0969152
3118.8	-0.636764
3121.35	-0.541573
3123.89	-0.724602
3126.44	-0.238159
3128.98	-0.645218
3131.52	-0.770132
3134.06	-0.404979
3136.6	-0.388099
3139.14	-0.261375
3141.68	1.02706
3144.22	1.75258
3146.76	3.26028
3149.29	3.46655