File: data/Raman/poly_smoothed/Thy_10_08_11_1x_45s_532 nm_x100_100%_600 gr_mm_01.txt
#Acq. time (s)=	45
#Accumulations=	2
#Range (cm-¹)=	200...3150
#Windows=	2
#Auto scanning=	Off
#Autofocus=	Off
#Macrospot=	Off
#AutoExposure=	Off
#Spike filter=	Multiple accum.
#Delay time (s)=	0
#Binning=	1
#Readout mode=	Signal
#DeNoise=	Off
#ICS correction=	On
#Dark correction=	Off
#Inst. Process=	Off
#Detector Gain=	Best Dynamic Range
#Detector ADC=	20 kHz
#Detector temperature (°C)=	-69.85
#Instrument=	LabRAM HR Evol
#Detector=	Synapse
#Objective=	x100
#Grating=	600 gr/mm
#ND Filter=	100%
#Laser (nm)=	532
#Hole=	100.021
#Range=	Auto
#Laser Pol.=	No
#Raman. Pol.=	No
#Laser Pol. (°)=	-0.0007625
#Raman Pol. (°)=	89.9995
#Collection=	Microscope
#StageXY=	Marzhauser
#StageZ=	Marzhauser
#X (µm)=	2167.8
#Y (µm)=	1265.4
#Z (µm)=	443
#Full time(mm:ss)=	3:18
#Project=
#Sample=
#Site=
#Title=	Thy_10_08_11_2x_45s_532 nm_x100_100%_600 gr_mm
#Remark=
#Date=	05.07.2022 14:57
#Acquired=	05.07.2022 14:57:59
#Base:Fit=	10.08.2022 09:46:25
#Base:Sub=	10.08.2022 09:46:49
#Filter:Polynom=	16.08.2022 10:24:56
#AxisType[0]=Intens
#AxisUnit[0]=Cnt
#AxisType[1]=Spectr
#AxisUnit[1]=1/cm
200.43	5.69724
204.059	5.80381
207.688	6.6369
211.314	6.94379
214.941	5.85183
218.564	5.10323
222.186	3.47753
225.809	3.32996
229.428	3.6116
233.045	4.27834
236.663	4.74467
240.278	3.56001
243.891	3.63753
247.503	4.04952
251.116	5.36764
254.725	4.89432
258.333	4.4394
261.939	3.86768
265.544	3.97348
269.148	2.42623
272.75	3.62837
276.351	4.23589
279.95	5.70377
283.548	5.21854
287.144	5.5432
290.739	6.46972
294.333	6.83011
297.925	7.40152
301.514	8.17189
305.104	8.73404
308.692	10.6937
312.279	11.9266
315.862	12.2716
319.446	13.0485
323.029	13.692
326.608	15.161
330.188	15.4896
333.766	15.7293
337.341	16.5234
340.917	17.7093
344.489	18.1893
348.062	16.9555
351.631	15.9695
355.201	14.9026
358.768	13.9207
362.333	12.8352
365.899	12.2561
369.462	11.9682
373.023	10.099
376.585	10.0574
380.143	10.7234
383.7	10.1811
387.256	9.56834
390.812	9.2812
394.365	7.32168
397.916	6.89918
401.467	4.78691
405.015	4.48626
408.563	5.63073
412.109	6.60519
415.654	5.45756
419.197	5.0538
422.739	5.01556
426.279	6.49625
429.819	6.83957
433.356	5.84086
436.891	6.3667
440.426	7.58376
443.96	7.16663
447.492	8.23754
451.021	8.19188
454.551	9.29463
458.079	9.49351
461.604	11.49
465.13	13.8663
468.654	15.2056
472.175	16.2655
475.696	16.5929
479.215	16.9292
482.733	17.7283
486.249	18.4689
489.765	18.9036
493.278	19.9653
496.789	19.5776
500.301	19.3272
503.81	18.9202
507.317	19.9681
510.825	20.4819
514.33	20.5802
517.833	20.1981
521.335	21.2183
524.836	20.9383
528.335	20.561
531.835	19.8405
535.332	19.382
538.827	19.4592
542.321	19.191
545.814	19.3493
549.305	20.3805
552.795	19.4667
556.282	19.9718
559.769	18.8126
563.255	17.098
566.739	15.7806
570.223	14.5286
573.705	11.5537
577.183	10.0882
580.663	9.31541
584.141	7.82622
587.615	6.94648
591.09	6.52448
594.564	7.48279
598.035	5.93457
601.506	5.50184
604.974	5.27582
608.443	5.30008
611.908	4.41477
615.374	5.42903
618.837	5.09466
622.3	5.26454
625.761	6.38835
629.219	9.03262
632.677	11.0412
636.135	12.3731
639.59	14.207
643.043	16.2263
646.495	17.0704
649.948	18.6482
653.398	19.8068
656.846	20.7109
660.293	23.1658
663.738	24.9672
667.183	25.5061
670.626	26.6873
674.067	28.1803
677.508	30.2981
680.947	30.7284
684.385	31.8199
687.821	33.422
691.254	35.1833
694.688	35.9523
698.121	36.4612
701.552	37.925
704.98	38.1653
708.409	39.1212
711.836	42.1946
715.26	42.9562
718.685	44.2894
722.108	46.5085
725.528	47.56
728.949	48.1295
732.367	49.3918
735.785	49.8506
739.2	51.2187
742.614	51.5019
746.028	52.4917
749.439	53.5229
752.849	54.9543
756.26	57.7548
759.667	60.4992
763.073	62.7469
766.477	63.9173
769.883	67.1976
773.285	70.0254
776.686	70.8984
780.085	72.3334
783.484	75.0684
786.881	77.062
790.276	80.0236
793.671	82.9389
797.064	86.1535
800.456	88.2402
803.846	90.7248
807.234	92.4876
810.622	91.8142
814.008	93.0555
817.394	93.3781
820.778	94.1726
824.159	94.5636
827.541	95.2318
830.921	94.7216
834.298	93.2505
837.676	91.5517
841.051	88.763
844.426	86.4741
847.798	82.6793
851.171	79.7645
854.54	78.1763
857.911	74.2019
861.278	71.5378
864.645	69.8968
868.01	68.6004
871.373	66.8926
874.735	65.247
878.097	63.6228
881.457	63.4118
884.815	62.8098
888.172	61.5303
891.528	60.4899
894.882	60.8289
898.237	60.5594
901.589	61.6315
904.94	63.4514
908.289	62.5478
911.635	60.6127
914.982	61.0018
918.328	59.079
921.672	58.9274
925.015	58.5959
928.357	56.9339
931.698	56.0326
935.035	55.6641
938.373	55.6643
941.71	53.8599
945.044	52.2141
948.378	50.2907
951.709	50.4141
955.041	49.9991
958.372	47.3357
961.699	46.526
965.027	45.5236
968.352	43.6593
971.676	42.8439
975	42.4981
978.322	42.8176
981.642	43.5323
984.962	43.1644
988.28	41.0235
991.596	39.8977
994.911	39.7394
998.227	40.0054
1001.54	39.5209
1004.85	39.7026
1008.16	38.5031
1011.47	37.3602
1014.78	36.6129
1018.08	36.6648
1021.39	34.7994
1024.69	33.7422
1028	34.2771
1031.3	36.4325
1034.6	35.604
1037.9	33.7886
1041.19	32.3299
1044.49	32.0301
1047.78	31.3873
1051.08	30.7416
1054.37	30.8407
1057.66	29.2622
1060.95	28.3488
1064.24	26.2768
1067.53	24.7552
1070.81	24.6644
1074.1	25.6036
1077.38	26.862
1080.66	26.6745
1083.94	25.1131
1087.22	24.5454
1090.5	24.2973
1093.78	25.0926
1097.05	25.6692
1100.33	26.1633
1103.6	27.8168
1106.87	29.3985
1110.14	30.5643
1113.41	30.0382
1116.68	27.9231
1119.95	27.1701
1123.21	24.2666
1126.48	23.2685
1129.74	21.4339
1133	19.2537
1136.26	16.6465
1139.52	14.0039
1142.78	13.785
1146.04	12.513
1149.29	12.0669
1152.55	12.747
1155.8	11.3874
1159.05	10.8294
1162.3	9.48388
1165.55	10.1147
1168.8	11.368
1172.05	12.3084
1175.29	13.928
1178.54	14.3609
1181.78	16.1929
1185.02	16.7537
1188.26	16.1653
1191.5	16.6609
1194.74	14.9666
1197.97	15.8557
1201.21	15.5821
1204.44	16.2614
1207.68	16.7126
1210.91	17.8614
1214.14	20.517
1217.37	21.5179
1220.59	24.8437
1223.82	27.0167
1227.05	29.6483
1230.27	31.4086
1233.49	35.3063
1236.72	35.2031
1239.94	35.9994
1243.16	37.6645
1246.37	38.3543
1249.59	39.0987
1252.8	39.0741
1256.02	38.162
1259.23	36.9074
1262.44	36.4312
1265.66	34.8216
1268.86	34.8915
1272.07	34.1021
1275.28	33.4359
1278.48	34.5016
1281.69	33.4079
1284.89	35.0319
1288.09	34.7929
1291.29	36.8447
1294.49	38.5308
1297.69	41.0731
1300.89	42.6718
1304.08	44.768
1307.28	47.4315
1310.47	48.8049
1313.66	49.6917
1316.85	50.6497
1320.04	51.3076
1323.23	52.7017
1326.42	53.0099
1329.61	51.8636
1332.79	50.7888
1335.97	50.1031
1339.16	49.4492
1342.34	48.6648
1345.52	47.0101
1348.7	44.4664
1351.87	40.864
1355.05	39.4279
1358.22	37.6743
1361.4	35.9866
1364.57	34.5688
1367.74	32.4169
1370.91	32.0754
1374.08	31.8842
1377.25	30.1313
1380.41	28.3287
1383.58	28.6391
1386.74	27.1636
1389.91	25.3784
1393.07	24.2478
1396.23	23.7033
1399.39	21.8101
1402.55	21.7571
1405.7	20.2791
1408.86	19.5316
1412.01	20.7065
1415.17	22.4635
1418.32	23.8388
1421.47	25.1797
1424.62	27.1827
1427.77	31.2291
1430.91	36.8624
1434.06	42.1484
1437.2	46.4458
1440.35	49.7102
1443.49	53.3228
1446.63	57.1603
1449.77	57.2111
1452.91	57.9361
1456.05	57.4618
1459.18	56.5448
1462.32	53.5223
1465.45	50.2442
1468.59	46.5689
1471.72	42.3303
1474.85	36.0701
1477.98	32.0263
1481.1	26.554
1484.23	21.8665
1487.36	18.9236
1490.48	16.2407
1493.61	12.1371
1496.73	9.27661
1499.85	8.08738
1502.97	9.30754
1506.09	9.35065
1509.2	8.81778
1512.32	10.6783
1515.43	11.0348
1518.55	11.133
1521.66	13.2229
1524.77	12.6962
1527.88	13.1029
1530.99	14.4937
1534.1	16.0233
1537.21	15.7601
1540.31	16.1861
1543.42	17.6581
1546.52	18.6844
1549.62	19.1628
1552.72	20.8405
1555.82	22.4157
1558.92	22.7103
1562.02	23.703
1565.11	23.7188
1568.21	25.4375
1571.3	27.2473
1574.39	27.2542
1577.49	28.425
1580.57	29.8131
1583.66	30.7784
1586.75	34.1115
1589.84	35.4536
1592.92	37.0117
1596.01	37.1625
1599.09	36.2615
1602.17	35.7785
1605.25	37.2644
1608.33	38.2624
1611.41	37.8028
1614.49	36.6527
1617.57	36.2864
1620.64	36.0333
1623.72	36.2202
1626.79	35.2126
1629.86	34.8195
1632.93	34.5465
1636	35.0163
1639.07	36.9926
1642.13	38.1883
1645.2	39.3062
1648.26	39.3955
1651.33	40.3197
1654.39	42.6976
1657.45	43.9522
1660.51	45.0616
1663.57	44.8079
1666.63	43.8178
1669.68	42.5211
1672.74	40.8524
1675.79	39.2174
1678.85	38.698
1681.9	37.1997
1684.95	32.8348
1688	29.7765
1691.05	26.5325
1694.09	24.3214
1697.14	21.5854
1700.18	17.9739
1703.23	15.6143
1706.27	13.3908
1709.31	11.9494
1712.35	10.5181
1715.39	8.23303
1718.43	7.21061
1721.47	6.39448
1724.5	6.66954
1727.54	6.85428
1730.57	6.36308
1733.61	5.99992
1736.64	5.853
1739.67	5.87727
1742.7	5.83596
1745.72	5.25488
1748.75	4.07183
1751.77	3.6228
1754.8	3.19293
1757.82	2.53032
1760.84	2.3396
1763.87	2.82624
1766.89	2.77415
1769.91	1.77436
1772.92	1.32025
1775.94	0.118496
1778.95	0.244205
1781.97	0.381634
1784.98	1.6946
1787.99	1.45088
1791.01	1.55197
1794.01	2.10201
1797.02	3.42226
1800.03	4.42651
1803.04	4.23143
1806.04	5.08889
1809.05	4.78792
1812.05	5.15523
1815.05	5.32502
1818.05	5.5247
1821.05	5.3606
1824.05	4.52203
1827.05	4.45711
1830.04	3.84628
1833.04	4.57283
1836.03	3.53472
1839.03	3.40969
1842.02	3.44294
1845.01	3.47987
1848	4.7172
1850.99	6.38012
1853.97	7.2547
1856.96	7.42534
1859.94	7.2136
1862.93	7.71832
1865.91	8.64062
1868.89	8.94497
1871.87	9.73392
1874.85	8.75915
1877.83	8.03078
1880.81	8.62531
1882.57	8.64594
1885.56	8.70761
1888.55	9.73754
1891.54	8.90838
1894.52	8.41307
1897.51	8.43544
1900.49	7.14267
1903.47	6.57221
1906.45	5.88035
1909.43	5.50845
1912.41	6.18684
1915.39	6.38404
1918.37	6.63773
1921.34	7.73963
1924.32	8.48238
1927.29	8.23674
1930.26	9.36028
1933.23	10.2438
1936.2	10.3981
1939.17	10.3944
1942.14	10.2667
1945.11	9.59258
1948.07	9.42729
1951.04	10.3786
1954	11.0118
1956.96	10.7676
1959.93	11.1361
1962.89	11.3759
1965.85	9.29961
1968.8	9.67558
1971.76	9.27528
1974.72	9.78963
1977.67	9.19979
1980.63	8.90965
1983.58	8.57437
1986.53	9.62771
1989.48	9.97654
1992.43	9.9164
1995.38	10.5635
1998.32	10.2042
2001.27	10.8618
2004.22	11.632
2007.16	11.084
2010.1	11.1436
2013.04	11.174
2015.98	11.0248
2018.92	11.9391
2021.86	12.351
2024.8	12.8524
2027.74	12.3728
2030.67	11.3118
2033.61	11.5824
2036.54	11.7547
2039.47	11.4503
2042.4	11.6844
2045.33	11.9953
2048.26	12.5117
2051.19	11.9905
2054.12	12.4739
2057.04	13.6051
2059.97	13.6954
2062.89	13.0665
2065.81	13.5086
2068.73	14.4671
2071.65	15.0605
2074.57	15.149
2077.49	15.6323
2080.41	15.6111
2083.32	16.6315
2086.24	16.0647
2089.15	16.5676
2092.07	16.5608
2094.98	17.0407
2097.89	16.5065
2100.8	16.1225
2103.71	15.9153
2106.61	17.0568
2109.52	15.8225
2112.43	14.904
2115.33	14.5606
2118.23	14.4297
2121.13	15.3294
2124.04	15.9266
2126.94	16.9696
2129.83	17.4765
2132.73	18.0802
2135.63	18.7356
2138.53	19.9793
2141.42	20.2476
2144.31	20.5088
2147.21	22.104
2150.1	22.7489
2152.99	24.7128
2155.88	26.2355
2158.77	26.426
2161.65	27.3855
2164.54	28.663
2167.43	28.9288
2170.31	29.0935
2173.19	30.3331
2176.07	30.3956
2178.96	30.0733
2181.84	28.968
2184.72	28.8602
2187.59	28.0744
2190.47	28.1204
2193.35	27.7238
2196.22	27.1613
2199.09	25.5024
2201.97	25.4682
2204.84	25.0293
2207.71	24.2021
2210.58	23.6775
2213.45	23.6772
2216.31	23.4389
2219.18	24.172
2222.05	24.5007
2224.91	24.7404
2227.78	23.5821
2230.64	22.7283
2233.5	22.7934
2236.36	22.969
2239.22	23.1631
2242.08	23.7663
2244.93	24.2654
2247.79	24.3866
2250.64	23.3273
2253.5	22.5837
2256.35	22.0591
2259.2	21.2479
2262.05	20.7407
2264.9	20.0193
2267.75	19.6125
2270.6	18.7991
2273.45	18.7411
2276.29	18.2409
2279.14	17.9808
2281.98	17.8144
2284.82	16.5733
2287.66	16.8354
2290.5	15.992
2293.34	15.1333
2296.18	14.6028
2299.02	16.1534
2301.86	16.4388
2304.69	17.0353
2307.53	17.6581
2310.36	18.8233
2313.19	19.492
2316.02	19.2386
2318.85	18.8409
2321.68	18.1541
2324.51	17.2857
2327.34	16.843
2330.16	15.4488
2332.99	15.3171
2335.81	14.4681
2338.64	14.166
2341.46	12.3085
2344.28	11.4468
2347.1	10.4357
2349.92	9.81176
2352.74	10.0257
2355.55	10.0017
2358.37	9.53817
2361.19	9.08848
2364	9.33131
2366.81	10.8737
2369.62	11.3797
2372.44	10.4271
2375.24	10.5846
2378.05	10.8079
2380.86	9.64237
2383.67	8.96221
2386.47	8.30734
2389.28	7.42291
2392.08	6.73883
2394.89	5.96531
2397.69	6.1044
2400.49	6.07615
2403.29	5.94595
2406.09	5.48388
2408.88	4.84493
2411.68	4.45139
2414.48	4.51046
2417.27	4.6508
2420.06	4.77651
2422.86	3.92816
2425.65	2.55302
2428.44	2.2153
2431.23	2.98827
2434.02	4.01451
2436.81	4.69368
2439.59	4.53664
2442.38	4.42659
2445.16	3.9163
2447.95	3.97487
2450.73	4.21673
2453.51	5.10671
2456.29	5.06011
2459.07	5.12021
2461.85	5.86454
2464.63	5.609
2467.4	6.36666
2470.18	6.32434
2472.95	6.83418
2475.73	6.54283
2478.5	5.84674
2481.27	6.08187
2484.04	5.70559
2486.81	5.80203
2489.58	6.2146
2492.35	7.15157
2495.12	8.28889
2497.88	7.78025
2500.65	8.21082
2503.41	7.2662
2506.17	7.11219
2508.94	6.17339
2511.7	5.93245
2514.46	5.69964
2517.22	5.29017
2519.97	5.91777
2522.73	5.54474
2525.49	5.56756
2528.24	5.31651
2530.99	5.4304
2533.75	5.65707
2536.5	6.0854
2539.25	7.11545
2542	6.91843
2544.75	7.37628
2547.5	8.08169
2550.24	8.45457
2552.99	8.40646
2555.74	8.85559
2558.48	8.01076
2561.22	6.87697
2563.96	5.53467
2566.71	3.74597
2569.45	3.75087
2572.18	2.25296
2574.92	2.34775
2577.66	1.63252
2580.4	1.2417
2583.13	0.29558
2585.87	0.0436669
2588.6	-0.159565
2591.33	-0.411325
2594.06	-0.914031
2596.79	-0.624875
2599.52	0.12224
2602.25	0.070845
2604.98	0.882803
2607.71	1.39309
2610.43	0.880578
2613.16	1.24504
2615.88	1.3824
2618.6	1.40931
2621.32	1.32257
2624.04	0.430337
2626.76	-0.0812232
2629.48	0.584537
2632.2	1.02176
2634.92	0.781062
2637.63	0.909484
2640.35	1.05613
2643.06	1.30151
2645.77	1.49348
2648.49	2.1704
2651.2	1.95814
2653.91	2.02233
2656.62	1.88346
2659.33	2.08995
2662.03	2.14544
2664.74	1.5199
2667.44	1.25311
2670.15	1.66721
2672.85	1.65588
2675.55	1.80332
2678.26	2.29392
2680.96	2.48788
2683.66	2.65457
2686.35	2.11444
2689.05	1.9725
2691.75	3.57165
2694.44	3.60668
2697.14	4.77273
2699.83	5.35732
2702.52	6.73815
2705.22	6.82675
2707.91	7.49204
2710.6	8.36952
2713.29	9.03193
2715.97	10.215
2718.66	9.61805
2721.35	9.83522
2724.03	10.1403
2726.72	8.88111
2729.4	8.96284
2732.08	7.22189
2734.76	6.9209
2737.44	6.16343
2740.12	5.11065
2742.8	5.57575
2745.48	5.36338
2748.16	4.40341
2750.83	3.1794
2753.51	2.44706
2756.18	2.54036
2758.85	2.18115
2761.53	1.57805
2764.2	1.33195
2766.87	0.745322
2769.54	-0.279361
2772.2	0.0785406
2774.87	1.11961
2777.54	1.43571
2780.2	2.6124
2782.87	2.78135
2785.53	2.66848
2788.19	3.00262
2790.85	2.67292
2793.51	2.34078
2796.17	2.6967
2798.83	2.17659
2801.49	2.6955
2804.15	2.1388
2806.8	2.24625
2809.46	2.58814
2812.11	1.73054
2814.76	0.941751
2817.42	1.09986
2820.07	1.51342
2822.72	2.99903
2825.37	4.6413
2828.02	7.35929
2830.66	10.4084
2833.31	13.3407
2835.96	17.0329
2838.6	21.306
2841.24	25.6081
2843.89	30.1573
2846.53	35.1989
2849.17	40.7771
2851.81	46.4641
2854.45	53.0328
2857.09	58.8206
2859.72	65.3318
2862.36	71.5673
2865	76.9443
2867.63	81.2558
2870.26	85.1104
2872.9	88.5111
2875.53	91.7413
2878.16	94.1677
2880.79	97.0813
2883.42	99.7642
2886.05	101.754
2888.67	104.387
2891.3	106.252
2893.92	108.668
2896.55	110.603
2899.17	112.555
2901.79	116.373
2904.42	120.9
2907.04	124.33
2909.66	129.551
2912.27	135.979
2914.89	141.959
2917.51	147.398
2920.13	151.999
2922.74	155.596
2925.35	158.521
2927.97	160.566
2930.58	160.206
2933.19	159.514
2935.8	156.876
2938.41	153.674
2941.02	150.693
2943.63	145.846
2946.24	140.605
2948.84	135.416
2951.45	128.917
2954.05	122.859
2956.65	117.259
2959.26	111.235
2961.86	105.405
2964.46	101.074
2967.06	96.6242
2969.66	92.5477
2972.25	88.9063
2974.85	84.7878
2977.45	80.6255
2980.04	75.5579
2982.64	70.3541
2985.23	65.8107
2987.82	60.0165
2990.41	55.2882
2993	49.8349
2995.59	45.1603
2998.18	39.9695
3000.77	35.8198
3003.36	31.2411
3005.94	27.4764
3008.53	23.4388
3011.11	21.7553
3013.69	19.2468
3016.28	17.2508
3018.86	16.0569
3021.44	14.518
3024.02	13.2612
3026.6	12.5536
3029.18	11.3796
3031.75	11.4334
3034.33	10.7356
3036.9	11.0217
3039.48	10.461
3042.05	11.4512
3044.62	11.677
3047.19	12.0025
3049.77	11.9834
3052.34	12.4074
3054.9	13.6469
3057.47	13.1075
3060.04	13.3665
3062.61	11.8122
3065.17	11.5866
3067.74	10.5685
3070.3	10.9812
3072.86	11.6468
3075.42	10.8246
3077.99	9.83607
3080.54	9.14122
3083.1	8.46747
3085.66	7.28086
3088.22	6.0246
3090.78	4.92673
3093.33	4.38411
3095.89	4.53554
3098.44	3.75405
3100.99	2.82864
3103.54	2.99786
3106.1	2.74634
3108.65	1.69348
3111.2	1.06118
3113.74	1.14749
3116.29	1.18277
3118.84	0.635139
3121.38	0.00950956
3123.93	0.0974238
3126.47	-0.144347
3129.01	0.0228482
3131.56	1.05745
3134.1	1.97263
3136.64	1.45003
3139.18	2.1185
3141.72	3.76627
3144.26	4.93537
3146.79	6.21738
3149.33	7.11598