File: data/Raman/poly_smoothed/Thy_20_09_45_1x_45s_532 nm_x100_100%_600 gr_mm_01.txt
#Acq. time (s)=	45
#Accumulations=	2
#Range (cm-¹)=	200...3150
#Windows=	2
#Auto scanning=	Off
#Autofocus=	Off
#Macrospot=	Off
#AutoExposure=	Off
#Spike filter=	Multiple accum.
#Delay time (s)=	0
#Binning=	1
#Readout mode=	Signal
#DeNoise=	Off
#ICS correction=	On
#Dark correction=	Off
#Inst. Process=	Off
#Detector Gain=	Best Dynamic Range
#Detector ADC=	20 kHz
#Detector temperature (°C)=	-69.85
#Instrument=	LabRAM HR Evol
#Detector=	Synapse
#Objective=	x100
#Grating=	600 gr/mm
#ND Filter=	100%
#Laser (nm)=	532
#Hole=	100.021
#Range=	Auto
#Laser Pol.=	No
#Raman. Pol.=	No
#Laser Pol. (°)=	-0.0007625
#Raman Pol. (°)=	89.9995
#Collection=	Microscope
#StageXY=	Marzhauser
#StageZ=	Marzhauser
#X (µm)=	-5927.7
#Y (µm)=	2844.9
#Z (µm)=	-223.8
#Full time(mm:ss)=	3:19
#Project=
#Sample=
#Site=
#Title=	Thy_20_09_45_2x_45s_532 nm_x100_100%_600 gr_mm
#Remark=
#Date=	29.06.2022 13:49
#Acquired=	29.06.2022 13:49:06
#Base:Fit=	10.08.2022 09:52:02
#Base:Fit=	10.08.2022 09:52:12
#Base:Sub=	10.08.2022 09:54:21
#Filter:Polynom=	16.08.2022 10:24:04
#AxisType[0]=Intens
#AxisUnit[0]=Cnt
#AxisType[1]=Spectr
#AxisUnit[1]=1/cm
200.523	47.1044
204.154	38.8457
207.781	34.1913
211.409	30.2368
215.034	28.4503
218.659	25.6623
222.281	25.9322
225.903	23.8475
229.522	23.0899
233.14	20.6341
236.756	20.1163
240.373	18.2616
243.986	17.1962
247.598	15.5454
251.208	14.0768
254.818	12.6403
258.427	11.5755
262.034	10.7321
265.638	8.73172
269.242	7.43331
272.844	5.54747
276.445	5.56409
280.044	3.46741
283.642	3.01556
287.238	2.30644
290.833	3.55362
294.425	4.22917
298.017	4.26059
301.608	5.542
305.198	7.8732
308.786	9.52402
312.371	10.6915
315.956	11.6023
319.54	12.1628
323.122	12.1291
326.701	12.3585
330.281	12.6379
333.857	11.7063
337.434	10.3868
341.008	9.65331
344.582	8.48915
348.153	8.82396
351.724	6.84753
355.292	7.01612
358.861	5.53065
362.426	5.07974
365.99	4.33323
369.555	3.51869
373.116	2.5102
376.676	2.39896
380.236	2.77549
383.793	2.9666
387.349	4.7473
390.903	6.36592
394.456	5.82995
398.007	6.9415
401.56	6.40048
405.108	6.52712
408.656	5.94709
412.202	5.81423
415.746	5.25814
419.29	5.95141
422.831	6.43875
426.37	6.08356
429.909	6.71459
433.447	5.19986
436.983	5.94809
440.519	5.25329
444.052	4.96968
447.583	4.52529
451.114	4.54362
454.643	4.90623
458.169	3.43712
461.696	3.07797
465.222	3.7754
468.744	5.07912
472.267	6.2591
475.787	6.4954
479.307	7.86537
482.823	8.55752
486.341	8.68537
489.855	8.74781
493.37	9.69105
496.881	10.239
500.391	11.4603
503.902	12.5039
507.409	13.5885
510.915	13.7488
514.42	13.4091
517.925	12.8196
521.427	12.2783
524.928	13.1048
528.427	13.9114
531.925	13.0819
535.422	13.3905
538.917	12.6331
542.411	11.1951
545.903	10.7672
549.395	10.8282
552.884	10.5616
556.373	11.1761
559.86	11.4818
563.346	11.793
566.831	8.88859
570.314	7.07074
573.794	6.24605
577.274	5.94548
580.754	7.22818
584.23	6.67383
587.706	7.00151
591.181	6.44817
594.653	7.06976
598.126	6.86988
601.595	7.89667
605.065	7.70698
608.532	9.70108
611.999	12.3578
615.463	13.3531
618.928	14.3601
622.389	15.0736
625.851	15.4446
629.31	16.7632
632.767	18.1951
636.223	18.7273
639.68	19.7804
643.134	20.1913
646.586	20.55
650.037	20.5516
653.486	22.5837
656.936	25.1642
660.383	26.9813
663.829	28.7533
667.273	29.6993
670.716	31.44
674.158	33.6703
677.598	35.14
681.035	36.2715
684.473	38.2752
687.909	39.711
691.344	41.6054
694.778	44.7002
698.211	45.7318
701.64	44.8058
705.07	44.5146
708.498	44.7417
711.924	45.3034
715.35	45.4773
718.774	46.4461
722.196	47.819
725.618	48.4779
729.037	48.1169
732.456	49.4456
735.873	51.2879
739.289	51.4509
742.703	52.9866
746.116	54.2192
749.529	54.8414
752.938	58.6783
756.347	62.464
759.756	65.0324
763.162	65.6971
766.567	68.0995
769.97	71.6803
773.372	73.9234
776.773	77.0266
780.174	77.958
783.573	79.5939
786.97	79.7546
790.365	80.3101
793.76	81.8431
797.153	82.8349
800.543	82.9602
803.933	83.2464
807.322	82.4169
810.71	81.3232
814.097	80.2045
817.483	80.4598
820.865	80.5181
824.248	79.14
827.629	78.6936
831.008	78.7053
834.387	78.7098
837.765	78.0168
841.139	77.4724
844.514	76.2934
847.886	74.3352
851.259	73.0041
854.629	69.6869
857.997	67.0247
861.366	64.6605
864.732	62.895
868.098	59.8868
871.461	55.7735
874.823	54.2148
878.184	52.9857
881.545	51.0113
884.903	50.1213
888.26	49.0878
891.616	47.4489
894.97	47.0473
898.323	48.3869
901.675	49.2243
905.026	49.568
908.375	47.973
911.723	48.3536
915.07	49.0437
918.415	48.5757
921.76	49.3085
925.103	48.9694
928.443	47.1762
931.783	44.3367
935.123	42.5577
938.461	41.809
941.796	39.0799
945.131	38.0326
948.465	37.1716
951.797	35.0215
955.128	32.8147
958.457	32.4688
961.786	31.5086
965.113	29.9065
968.44	29.2072
971.763	27.3007
975.086	28.3757
978.409	28.9563
981.729	29.8556
985.048	28.9862
988.367	27.12
991.683	26.1517
994.998	25.8836
998.312	25.4085
1001.62	24.5746
1004.94	25.3059
1008.25	25.1976
1011.56	23.8529
1014.86	24.1292
1018.17	23.2694
1021.48	20.9669
1024.78	21.4263
1028.08	22.3302
1031.38	21.2181
1034.68	20.7305
1037.98	19.643
1041.28	18.9388
1044.57	17.8612
1047.87	17.1593
1051.16	17.4728
1054.45	17.6309
1057.75	17.7805
1061.04	17.2954
1064.32	16.1232
1067.61	14.6896
1070.9	13.8936
1074.18	13.8345
1077.47	13.7788
1080.75	13.2522
1084.03	14.8611
1087.31	15.9139
1090.59	15.0262
1093.86	14.9604
1097.14	14.0925
1100.41	12.3382
1103.69	12.5299
1106.96	12.0701
1110.23	12.5311
1113.5	11.8233
1116.77	10.5478
1120.03	9.83977
1123.3	7.98201
1126.56	7.54382
1129.83	7.63252
1133.09	7.40462
1136.35	6.54034
1139.61	6.31334
1142.86	5.42917
1146.12	4.61642
1149.38	3.23305
1152.63	3.50134
1155.88	2.73369
1159.14	3.36977
1162.39	3.15104
1165.63	3.69139
1168.88	1.83043
1172.13	1.0382
1175.38	0.569374
1178.62	0.993341
1181.86	1.12473
1185.1	2.82
1188.34	4.28559
1191.58	5.00588
1194.82	5.55012
1198.06	6.70755
1201.29	8.79849
1204.53	10.886
1207.76	13.4429
1210.99	16.5396
1214.22	18.9246
1217.45	21.8729
1220.68	22.4468
1223.91	24.2417
1227.13	26.6869
1230.36	27.7078
1233.58	30.3442
1236.8	30.8473
1240.02	30.7551
1243.24	31.8895
1246.46	31.808
1249.67	30.9373
1252.89	31.1791
1256.1	32.1995
1259.32	33.6639
1262.53	34.3037
1265.74	35.2793
1268.95	35.8919
1272.15	35.9578
1275.36	37.5872
1278.57	40.0279
1281.77	40.867
1284.97	42.1419
1288.18	43.8176
1291.38	44.5709
1294.58	45.2032
1297.78	46.3766
1300.97	47.6789
1304.17	48.925
1307.36	50.1605
1310.55	49.6366
1313.75	51.3917
1316.94	51.994
1320.13	52.2926
1323.32	52.992
1326.5	53.1719
1329.69	53.8483
1332.87	53.3764
1336.06	53.3745
1339.24	53.2771
1342.42	51.717
1345.6	49.8921
1348.78	46.8249
1351.96	46.3139
1355.13	44.5534
1358.31	43.6785
1361.48	41.8496
1364.65	39.6524
1367.82	38.3178
1370.99	36.3926
1374.16	35.3081
1377.33	34.0278
1380.5	33.5615
1383.66	33.0406
1386.83	31.9134
1389.99	32.1902
1393.15	33.5079
1396.31	32.1133
1399.47	32.2646
1402.63	32.9075
1405.78	31.9145
1408.94	32.2305
1412.1	31.6785
1415.25	32.9004
1418.4	33.3932
1421.55	34.5725
1424.7	36.4846
1427.85	39.7223
1431	43.1609
1434.14	46.1944
1437.29	48.1269
1440.43	49.9028
1443.57	51.0876
1446.71	51.8148
1449.85	51.8207
1452.99	51.8921
1456.13	50.1158
1459.26	49.9354
1462.4	48.6793
1465.54	46.8853
1468.67	44.9347
1471.8	41.9332
1474.93	38.9847
1478.06	35.0402
1481.19	32.1555
1484.31	28.5387
1487.44	27.7559
1490.56	25.1779
1493.69	24.0209
1496.81	24.0021
1499.93	23.1282
1503.05	21.9834
1506.17	21.5745
1509.28	21.9481
1512.4	22.8978
1515.52	23.3668
1518.63	24.3123
1521.74	26.2626
1524.85	27.0284
1527.96	27.929
1531.07	28.9765
1534.18	30.2996
1537.29	32.2517
1540.39	32.995
1543.5	34.505
1546.6	37.0829
1549.7	40.4491
1552.8	42.6302
1555.9	44.3139
1559	47.1402
1562.1	48.2265
1565.19	50.0203
1568.29	51.5013
1571.38	53.2283
1574.47	53.9633
1577.56	54.394
1580.66	55.3652
1583.74	57.5293
1586.83	59.4771
1589.92	59.8991
1593.01	61.4095
1596.09	62.0822
1599.17	62.0351
1602.25	61.251
1605.34	60.541
1608.41	59.146
1611.49	56.6697
1614.57	54.9983
1617.65	53.3915
1620.72	52.7714
1623.79	52.7085
1626.87	52.057
1629.94	50.3475
1633.01	48.1094
1636.08	47.1983
1639.15	47.3775
1642.21	47.0774
1645.28	47.3757
1648.34	46.728
1651.41	45.6926
1654.47	45.0656
1657.53	44.5603
1660.59	44.8784
1663.65	43.5445
1666.71	42.1597
1669.76	41.8584
1672.82	40.38
1675.87	39.1935
1678.93	37.4088
1681.98	33.5859
1685.03	29.8265
1688.08	27.29
1691.13	26.3129
1694.17	23.3018
1697.22	19.9557
1700.27	17.9159
1703.31	15.0948
1706.35	12.5046
1709.39	10.9963
1712.43	9.72134
1715.47	8.17203
1718.51	7.00392
1721.55	5.96021
1724.58	4.19067
1727.62	3.55812
1730.65	3.78275
1733.68	3.531
1736.72	3.64852
1739.74	3.39226
1742.77	4.39045
1745.8	5.93722
1748.83	5.49015
1751.85	6.33829
1754.88	5.39539
1757.9	5.88467
1760.92	6.12785
1763.95	6.50364
1766.96	7.08505
1769.98	6.17947
1773	6.29668
1776.02	6.78384
1779.03	5.48972
1782.05	5.58226
1785.06	5.5814
1788.07	4.99181
1791.08	4.4857
1794.09	5.46565
1797.1	6.5084
1800.11	7.47081
1803.12	8.52301
1806.12	9.73171
1809.12	10.2837
1812.13	11.0679
1815.13	11.8843
1818.13	11.7959
1821.13	11.3237
1824.13	9.83792
1827.13	9.73619
1830.12	9.70624
1833.12	9.48414
1836.11	9.21165
1839.1	9.44843
1842.09	9.51724
1845.09	9.13249
1848.08	8.08689
1851.06	7.06521
1854.05	5.49372
1857.04	3.91275
1860.02	2.9094
1863.01	2.42003
1865.99	3.70864
1868.97	4.71688
1871.95	4.70506
1874.93	5.55275
1877.91	6.28438
1880.89	6.81328
1882.46	6.8282
1885.45	6.27219
1888.43	6.6714
1891.42	6.33829
1894.41	7.73802
1897.39	9.62553
1900.37	10.0567
1903.36	11.6192
1906.34	12.333
1909.32	12.683
1912.29	12.439
1915.27	12.6477
1918.25	11.8184
1921.23	11.4793
1924.2	10.6336
1927.17	9.41325
1930.15	9.31983
1933.12	9.18493
1936.09	9.27452
1939.06	8.99999
1942.02	8.10349
1944.99	7.13363
1947.96	7.03192
1950.92	6.65829
1953.88	5.3755
1956.85	5.00587
1959.81	4.77668
1962.77	4.68242
1965.73	6.11871
1968.69	6.81403
1971.64	6.03816
1974.6	6.53911
1977.55	6.64891
1980.51	6.38473
1983.46	6.16619
1986.41	6.95556
1989.36	7.70774
1992.31	8.00688
1995.26	8.0335
1998.21	8.87563
2001.15	8.52974
2004.1	9.09577
2007.04	9.39191
2009.99	10.059
2012.93	8.66681
2015.87	7.4621
2018.81	7.54994
2021.75	7.75697
2024.68	7.15637
2027.62	5.95386
2030.56	6.5153
2033.49	5.98585
2036.42	5.58586
2039.36	5.43983
2042.29	4.50131
2045.22	4.6753
2048.14	5.0899
2051.07	4.51584
2054	4.71025
2056.93	5.49548
2059.85	6.08108
2062.77	6.52027
2065.7	7.45482
2068.62	7.54865
2071.54	8.27366
2074.46	9.07466
2077.38	9.22898
2080.29	9.25459
2083.21	8.11527
2086.12	7.6848
2089.04	8.5311
2091.95	9.04134
2094.86	9.66728
2097.77	8.86418
2100.68	9.57699
2103.59	9.1856
2106.5	8.94622
2109.41	10.0728
2112.31	10.8936
2115.21	10.7191
2118.12	10.9097
2121.02	11.6093
2123.92	12.3131
2126.82	12.2219
2129.72	14.1228
2132.62	14.5146
2135.51	15.665
2138.41	17.4901
2141.31	17.8244
2144.2	19.0591
2147.09	19.3769
2149.98	20.8455
2152.87	21.0855
2155.76	22.6336
2158.65	24.2332
2161.54	25.4425
2164.43	27.136
2167.31	27.6155
2170.2	28.7908
2173.08	29.8638
2175.96	29.911
2178.84	30.4875
2181.72	30.5465
2184.6	28.8117
2187.48	28.3583
2190.36	28.0537
2193.23	27.0964
2196.11	26.2385
2198.98	24.7738
2201.85	25.1925
2204.72	23.1454
2207.59	21.9711
2210.46	19.5763
2213.33	18.413
2216.2	16.5079
2219.07	15.3332
2221.93	15.3914
2224.8	14.6125
2227.66	14.3161
2230.52	14.2823
2233.39	13.8721
2236.25	14.0703
2239.1	13.3822
2241.96	12.7953
2244.82	12.4369
2247.68	12.2016
2250.53	12.2431
2253.38	11.1896
2256.24	11.506
2259.09	12.6485
2261.94	12.3086
2264.79	12.4505
2267.64	12.6737
2270.49	11.8964
2273.33	10.4541
2276.18	9.79494
2279.02	9.09183
2281.87	8.89279
2284.71	8.42352
2287.55	8.10411
2290.39	7.51038
2293.23	7.72993
2296.07	7.94972
2298.91	7.63447
2301.74	7.7869
2304.58	7.12727
2307.41	6.8116
2310.25	5.53879
2313.08	6.1997
2315.91	6.06467
2318.74	6.25555
2321.57	6.02122
2324.4	5.89031
2327.23	5.2062
2330.05	5.29982
2332.88	5.30514
2335.7	5.38163
2338.52	4.02452
2341.35	3.19557
2344.17	3.39933
2346.99	3.05819
2349.81	2.41307
2352.62	1.93727
2355.44	1.21201
2358.26	0.383394
2361.07	-0.645736
2363.89	0.808506
2366.7	1.0436
2369.51	1.38271
2372.32	1.09729
2375.13	1.2043
2377.94	1.28789
2380.75	1.43647
2383.56	2.41114
2386.36	2.12893
2389.17	3.04602
2391.97	2.34602
2394.77	2.11829
2397.58	1.72975
2400.38	2.16843
2403.18	1.87367
2405.97	2.16292
2408.77	1.45709
2411.57	2.03959
2414.37	2.48881
2417.16	2.04143
2419.95	1.68999
2422.75	1.72256
2425.54	1.3999
2428.33	1.63163
2431.12	1.93149
2433.91	3.09539
2436.7	3.04492
2439.48	2.89194
2442.27	2.84088
2445.05	3.46373
2447.84	3.60555
2450.62	3.33036
2453.4	3.24009
2456.18	2.78766
2458.96	2.68404
2461.74	2.09899
2464.52	1.78339
2467.29	0.967209
2470.07	0.1712
2472.85	-0.0983194
2475.62	-0.12924
2478.39	-0.470072
2481.16	0.331369
2483.93	0.319531
2486.7	0.658457
2489.47	1.25625
2492.24	2.15919
2495.01	2.60582
2497.77	3.34107
2500.54	4.3664
2503.3	4.86708
2506.06	4.62994
2508.83	5.13541
2511.59	5.35552
2514.35	5.41975
2517.11	5.03519
2519.86	4.93856
2522.62	4.76123
2525.38	4.37833
2528.13	4.34088
2530.89	3.90603
2533.64	3.03739
2536.39	1.78195
2539.14	1.63931
2541.89	2.25392
2544.64	2.69069
2547.39	2.50532
2550.14	2.22879
2552.88	2.40471
2555.63	3.23196
2558.37	3.802
2561.11	3.92971
2563.86	3.56642
2566.6	5.00419
2569.34	4.89964
2572.08	4.15186
2574.82	4.92455
2577.55	4.84683
2580.29	4.33842
2583.02	3.80825
2585.76	4.01018
2588.49	3.38619
2591.22	2.44974
2593.96	2.68007
2596.69	2.83671
2599.42	2.17433
2602.14	1.87474
2604.87	1.52
2607.6	1.97396
2610.32	2.39484
2613.05	1.72349
2615.77	1.16717
2618.49	1.26148
2621.22	1.34378
2623.94	1.63017
2626.66	1.13478
2629.37	1.61552
2632.09	2.47788
2634.81	2.51067
2637.53	3.1043
2640.24	4.02913
2642.96	3.46165
2645.67	3.11984
2648.38	3.33681
2651.09	3.24179
2653.8	3.17877
2656.51	3.37071
2659.22	3.21611
2661.93	3.71525
2664.63	3.97176
2667.34	4.29795
2670.04	4.19364
2672.75	5.12532
2675.45	5.87133
2678.15	5.37724
2680.85	5.15535
2683.55	5.78925
2686.25	5.60517
2688.94	5.37136
2691.64	5.67373
2694.34	6.65533
2697.03	7.06703
2699.73	8.23803
2702.42	8.96121
2705.11	9.4368
2707.8	9.41235
2710.49	9.37683
2713.18	9.9423
2715.87	10.4256
2718.55	10.3491
2721.24	10.4824
2723.93	10.1202
2726.61	9.74296
2729.29	9.68772
2731.98	10.3899
2734.66	10.7625
2737.34	11.4842
2740.02	11.5939
2742.7	10.0586
2745.37	10.2224
2748.05	10.2293
2750.72	9.37018
2753.4	8.10617
2756.07	8.49148
2758.75	8.74317
2761.42	8.16995
2764.09	8.25599
2766.76	8.24924
2769.43	7.87373
2772.1	7.10919
2774.76	6.20897
2777.43	5.91807
2780.1	5.2553
2782.76	3.52747
2785.42	2.23157
2788.09	1.43256
2790.75	0.998234
2793.41	1.38517
2796.07	2.24361
2798.73	2.45756
2801.39	1.50518
2804.04	1.53638
2806.7	1.02818
2809.35	0.985211
2812.01	0.653583
2814.66	1.01802
2817.31	1.12516
2819.96	2.24447
2822.61	4.17004
2825.26	5.89274
2827.91	7.72825
2830.56	10.0979
2833.21	11.9869
2835.85	14.8858
2838.5	17.5444
2841.14	20.0049
2843.78	24.3314
2846.42	28.3126
2849.06	32.8735
2851.71	37.8345
2854.34	43.0785
2856.98	47.4892
2859.62	52.755
2862.26	56.7707
2864.89	60.6439
2867.53	64.6355
2870.16	68.5147
2872.79	71.0615
2875.42	72.3924
2878.05	74.9155
2880.68	76.8461
2883.31	79.1355
2885.94	81.3138
2888.57	83.5121
2891.19	84.8257
2893.82	86.4723
2896.44	88.3509
2899.07	91.901
2901.69	96.2114
2904.31	100.884
2906.93	105.324
2909.55	111.053
2912.17	116.999
2914.79	122.486
2917.41	127.176
2920.02	131.985
2922.64	135.356
2925.25	138.76
2927.86	140.328
2930.48	142.14
2933.09	141.896
2935.7	139.789
2938.31	137.012
2940.92	134.384
2943.53	131.14
2946.13	127.305
2948.74	122.506
2951.34	118.034
2953.95	112.32
2956.55	106.927
2959.15	102.206
2961.75	97.3428
2964.35	93.0023
2966.95	87.844
2969.55	81.7144
2972.15	76.6255
2974.75	73.055
2977.34	68.0716
2979.94	63.1134
2982.53	57.9921
2985.13	52.0131
2987.72	47.5212
2990.31	42.5924
2992.9	37.5333
2995.49	32.7091
2998.08	28.4133
3000.67	24.3283
3003.25	20.3715
3005.84	18.8377
3008.42	16.4434
3011.01	14.4441
3013.59	12.6407
3016.17	10.5962
3018.76	9.59706
3021.34	7.69991
3023.92	6.8748
3026.49	5.67978
3029.07	4.93349
3031.65	3.92873
3034.23	3.52474
3036.8	3.02942
3039.38	3.2176
3041.95	3.55958
3044.52	2.99914
3047.09	3.28001
3049.66	3.51795
3052.23	4.07834
3054.8	3.93656
3057.37	4.02452
3059.94	4.83453
3062.5	4.83696
3065.07	5.03617
3067.63	4.96815
3070.2	5.68898
3072.76	6.24285
3075.32	5.23686
3077.88	4.69563
3080.44	3.9923
3083	3.53709
3085.56	2.29864
3088.12	2.45565
3090.67	1.8475
3093.23	1.02966
3095.78	0.627405
3098.34	0.341366
3100.89	1.37574
3103.44	1.15866
3105.99	0.615629
3108.54	0.0220839
3111.09	0.232182
3113.64	1.39483
3116.19	1.76395
3118.74	2.57845
3121.28	3.37089
3123.83	3.89553
3126.37	4.36874
3128.91	4.56818
3131.46	5.77129
3134	6.82924
3136.54	6.83405
3139.08	7.34749
3141.62	7.90979
3144.16	8.38651
3146.69	9.37736
3149.23	10.2599