File: data/Raman/poly_smoothed/Thy_40_11_01_1x_45s_532 nm_x100_100%_600 gr_mm_01.txt
#Acq. time (s)=	45
#Accumulations=	2
#Range (cm-¹)=	200...3150
#Windows=	2
#Auto scanning=	Off
#Autofocus=	Off
#Macrospot=	Off
#AutoExposure=	Off
#Spike filter=	Multiple accum.
#Delay time (s)=	0
#Binning=	1
#Readout mode=	Signal
#DeNoise=	Off
#ICS correction=	On
#Dark correction=	Off
#Inst. Process=	Off
#Detector Gain=	Best Dynamic Range
#Detector ADC=	20 kHz
#Detector temperature (°C)=	-69.85
#Instrument=	LabRAM HR Evol
#Detector=	Synapse
#Objective=	x100
#Grating=	600 gr/mm
#ND Filter=	100%
#Laser (nm)=	532
#Hole=	100.021
#Range=	Auto
#Laser Pol.=	No
#Raman. Pol.=	No
#Laser Pol. (°)=	-0.0007625
#Raman Pol. (°)=	89.9995
#Collection=	Microscope
#StageXY=	Marzhauser
#StageZ=	Marzhauser
#X (µm)=	1960.3
#Y (µm)=	-96.4
#Z (µm)=	425.3
#Full time(mm:ss)=	3:09
#Project=
#Sample=
#Site=
#Title=	Thy_40_11_01_2x_45s_532 nm_x100_100%_600 gr_mm
#Remark=
#Date=	05.07.2022 09:52
#Acquired=	05.07.2022 09:52:11
#Base:Fit=	10.08.2022 10:00:48
#Base:Fit=	10.08.2022 10:01:07
#Base:Fit=	10.08.2022 10:01:15
#Base:Fit=	10.08.2022 10:01:35
#Base:Sub=	10.08.2022 10:01:52
#Filter:Polynom=	16.08.2022 10:21:53
#AxisType[0]=Intens
#AxisUnit[0]=Cnt
#AxisType[1]=Spectr
#AxisUnit[1]=1/cm
200.43	35.7013
204.059	37.6996
207.688	39.5904
211.314	41.1018
214.941	41.7621
218.564	40.9067
222.186	38.4218
225.809	35.5842
229.428	33.0282
233.045	30.2535
236.663	28.1948
240.278	26.1596
243.891	23.7718
247.503	20.9425
251.116	15.6093
254.725	12.6365
258.333	10.0575
261.939	9.20338
265.544	8.35767
269.148	6.47523
272.75	5.6126
276.351	3.92265
279.95	4.06047
283.548	3.82675
287.144	3.49955
290.739	4.2174
294.333	6.45314
297.925	6.55509
301.514	6.41275
305.104	5.69934
308.692	6.24704
312.279	6.16513
315.862	5.93262
319.446	6.7017
323.029	6.76626
326.608	7.06917
330.188	6.51549
333.766	4.75001
337.341	3.2282
340.917	2.42522
344.489	3.25817
348.062	4.0424
351.631	2.51574
355.201	1.49729
358.768	1.49574
362.333	2.98985
365.899	2.70785
369.462	3.93396
373.023	4.44938
376.585	5.3141
380.143	5.97459
383.7	6.30641
387.256	7.26709
390.812	9.59399
394.365	10.1306
397.916	10.3463
401.467	10.26
405.015	9.60025
408.563	11.0153
412.109	9.64525
415.654	7.83298
419.197	5.67094
422.739	4.78997
426.279	4.69599
429.819	4.85356
433.356	3.66156
436.891	2.67356
440.426	1.91849
443.96	4.71025
447.492	5.91025
451.021	8.06565
454.551	9.56185
458.079	11.1313
461.604	12.989
465.13	15.4513
468.654	16.4454
472.175	17.2135
475.696	18.3108
479.215	18.9061
482.733	20.8206
486.249	21.845
489.765	23.4901
493.278	24.0994
496.789	23.8763
500.301	23.9814
503.81	24.3034
507.317	25.0906
510.825	25.7808
514.33	25.5971
517.833	25.7412
521.335	25.335
524.836	26.0385
528.335	26.8122
531.835	27.2169
535.332	27.3568
538.827	27.0619
542.321	26.8922
545.814	26.2185
549.305	25.0225
552.795	25.4053
556.282	22.9798
559.769	21.3688
563.255	19.8434
566.739	17.4622
570.223	16.658
573.705	15.2304
577.183	15.5151
580.663	12.9491
584.141	13.123
587.615	13.934
591.09	13.0741
594.564	14.289
598.035	13.574
601.506	14.3614
604.974	14.4865
608.443	16.8835
611.908	18.7698
615.374	20.0353
618.837	21.1417
622.3	23.1146
625.761	26.4366
629.219	28.0926
632.677	29.4283
636.135	30.3876
639.59	30.4756
643.043	28.7417
646.495	28.9854
649.948	30.5773
653.398	31.627
656.846	32.9944
660.293	32.9597
663.738	33.0546
667.183	33.2262
670.626	35.195
674.067	34.5841
677.508	35.2012
680.947	36.2003
684.385	38.5688
687.821	40.7893
691.254	43.2368
694.688	45.4229
698.121	47.1376
701.552	48.7214
704.98	51.1919
708.409	52.8414
711.836	54.9079
715.26	56.9768
718.685	58.9868
722.108	62.0703
725.528	64.9816
728.949	66.4741
732.367	70.3831
735.785	72.0566
739.2	72.581
742.614	72.4417
746.028	74.4679
749.439	76.9858
752.849	79.4204
756.26	81.5388
759.667	82.6894
763.073	85.8847
766.477	87.7953
769.883	89.979
773.285	90.2519
776.686	91.1181
780.085	91.221
783.484	90.4512
786.881	91.1033
790.276	91.3892
793.671	93.8866
797.064	95.7228
800.456	98.6687
803.846	99.8746
807.234	101.677
810.622	101.778
814.008	103.356
817.394	103.567
820.778	103.285
824.159	104.289
827.541	104.578
830.921	104.301
834.298	103.072
837.676	101.248
841.051	98.7142
844.426	96.5538
847.798	94.4922
851.171	91.3542
854.54	88.0568
857.911	83.8307
861.278	81.0919
864.645	79.416
868.01	76.8048
871.373	75.2948
874.735	73.6041
878.097	73.8215
881.457	71.998
884.815	71.8269
888.172	70.4507
891.528	70.5587
894.882	70.9175
898.237	70.0571
901.589	70.1049
904.94	69.2998
908.289	68.3256
911.635	67.851
914.982	65.7498
918.328	63.5408
921.672	63.2156
925.015	61.7235
928.357	61.853
931.698	61.7992
935.035	60.4298
938.373	60.1849
941.71	59.2447
945.044	58.0712
948.378	55.4238
951.709	55.0062
955.041	55.4397
958.372	55.6762
961.699	55.2962
965.027	55.7768
968.352	57.5201
971.676	58.2688
975	57.5917
978.322	58.3091
981.642	57.9614
984.962	58.3297
988.28	59.2186
991.596	58.5259
994.911	56.9939
998.227	57.3647
1001.54	56.6704
1004.85	57.4528
1008.16	56.6153
1011.47	54.8215
1014.78	54.0405
1018.08	51.6649
1021.39	49.9395
1024.69	48.1916
1028	47.0263
1031.3	48.6131
1034.6	50.5026
1037.9	49.286
1041.19	48.3868
1044.49	47.4525
1047.78	46.7301
1051.08	46.7042
1054.37	44.1206
1057.66	41.5502
1060.95	40.1708
1064.24	38.2697
1067.53	38.7462
1070.81	38.2644
1074.1	38.2873
1077.38	37.3407
1080.66	35.634
1083.94	34.9603
1087.22	33.4929
1090.5	30.9892
1093.78	29.339
1097.05	29.7593
1100.33	28.5999
1103.6	29.3172
1106.87	29.5788
1110.14	29.837
1113.41	27.6726
1116.68	25.4032
1119.95	23.722
1123.21	20.9796
1126.48	19.2514
1129.74	16.4717
1133	14.1147
1136.26	12.2962
1139.52	10.3801
1142.78	8.92994
1146.04	7.97952
1149.29	8.46265
1152.55	6.49959
1155.8	4.98631
1159.05	2.20277
1162.3	0.187366
1165.55	0.52162
1168.8	0.274319
1172.05	0.944426
1175.29	3.10752
1178.54	3.65924
1181.78	4.17933
1185.02	3.83666
1188.26	3.75906
1191.5	3.897
1194.74	3.79771
1197.97	5.01724
1201.21	6.84019
1204.44	7.77327
1207.68	9.66377
1210.91	11.4255
1214.14	13.9984
1217.37	15.4295
1220.59	18.4436
1223.82	21.3579
1227.05	24.1484
1230.27	27.6829
1233.49	29.9605
1236.72	33.1552
1239.94	36.5176
1243.16	40.1094
1246.37	45.1726
1249.59	48.4658
1252.8	51.827
1256.02	55.7619
1259.23	57.11
1262.44	60.5225
1265.66	63.5312
1268.86	65.9925
1272.07	68.452
1275.28	70.4043
1278.48	73.1321
1281.69	74.9453
1284.89	74.2977
1288.09	76.7796
1291.29	79.313
1294.49	80.0399
1297.69	79.5179
1300.89	81.1012
1304.08	78.9706
1307.28	80.6857
1310.47	80.7149
1313.66	78.8433
1316.85	77.7742
1320.04	76.796
1323.23	74.0547
1326.42	72.4613
1329.61	71.1664
1332.79	68.9386
1335.97	64.9965
1339.16	63.3384
1342.34	60.4074
1345.52	57.187
1348.7	54.1226
1351.87	51.8357
1355.05	48.0864
1358.22	45.1526
1361.4	43.4028
1364.57	42.0769
1367.74	41.5535
1370.91	40.6011
1374.08	38.8772
1377.25	37.1202
1380.41	36.1294
1383.58	33.8636
1386.74	33.946
1389.91	32.0731
1393.07	31.5902
1396.23	31.2539
1399.39	28.5318
1402.55	28.4369
1405.7	29.0381
1408.86	29.103
1412.01	29.4659
1415.17	31.288
1418.32	32.742
1421.47	36.2899
1424.62	40.4305
1427.77	44.673
1430.91	50.5697
1434.06	55.4832
1437.2	61.7967
1440.35	67.0792
1443.49	70.9153
1446.63	74.8884
1449.77	75.9819
1452.91	76.3012
1456.05	75.5093
1459.18	74.0195
1462.32	71.8885
1465.45	67.8441
1468.59	64.7871
1471.72	59.3695
1474.85	53.2997
1477.98	46.744
1481.1	40.8973
1484.23	35.5116
1487.36	30.2271
1490.48	25.332
1493.61	22.1062
1496.73	18.769
1499.85	17.0788
1502.97	15.497
1506.09	14.1389
1509.2	14.8031
1512.32	13.4907
1515.43	14.8837
1518.55	15.8603
1521.66	15.8822
1524.77	16.1269
1527.88	17.0327
1530.99	17.5122
1534.1	19.4591
1537.21	21.5216
1540.31	23.907
1543.42	26.4483
1546.52	29.9488
1549.62	32.1987
1552.72	35.6359
1555.82	38.738
1558.92	41.8977
1562.02	44.6928
1565.11	48.2293
1568.21	51.7708
1571.3	55.2286
1574.39	57.4916
1577.49	61.2687
1580.57	63.5945
1583.66	66.3826
1586.75	69.1088
1589.84	70.2065
1592.92	72.2472
1596.01	72.8125
1599.09	73.6291
1602.17	73.2461
1605.25	72.3818
1608.33	72.1391
1611.41	72.7458
1614.49	73.1791
1617.57	74.2348
1620.64	75.8787
1623.72	78.7127
1626.79	79.6433
1629.86	81.7625
1632.93	85.1763
1636	87.6904
1639.07	92.0162
1642.13	96.3591
1645.2	100.406
1648.26	103.095
1651.33	106.116
1654.39	108.866
1657.45	110.702
1660.51	110.742
1663.57	110.32
1666.63	109.972
1669.68	106.36
1672.74	101.376
1675.79	94.8932
1678.85	88.5486
1681.9	82.5669
1684.95	75.8568
1688	68.7628
1691.05	63.0512
1694.09	56.116
1697.14	50.4127
1700.18	44.8988
1703.23	39.9167
1706.27	36.3696
1709.31	32.6074
1712.35	30.24
1715.39	28.5283
1718.43	27.6117
1721.47	27.3324
1724.5	26.5051
1727.54	25.4764
1730.57	25.227
1733.61	25.3938
1736.64	24.8256
1739.67	23.8817
1742.7	23.0679
1745.72	21.3288
1748.75	21.1782
1751.77	20.0033
1754.8	19.0136
1757.82	17.7705
1760.84	17.2506
1763.87	16.0898
1766.89	14.7031
1769.91	13.9306
1772.92	14.3074
1775.94	14.2372
1778.95	13.6371
1781.97	12.8734
1784.98	13.2583
1787.99	13.379
1791.01	12.9608
1794.01	11.9729
1797.02	11.213
1800.03	10.0841
1803.04	9.08948
1806.04	8.75067
1809.05	8.48675
1812.05	7.00336
1815.05	7.41957
1818.05	7.33948
1821.05	6.0663
1824.05	5.07128
1827.05	4.96517
1830.04	4.41903
1833.04	4.57767
1836.03	3.57759
1839.03	3.3744
1842.02	3.52125
1845.01	4.14044
1848	4.66783
1850.99	3.47918
1853.97	2.9465
1856.96	3.29016
1859.94	3.15266
1862.93	1.71286
1865.91	0.79747
1868.89	0.431516
1871.87	-0.414843
1874.85	-1.0842
1877.83	-1.22599
1880.81	-1.22971
1882.57	-1.29382
1885.56	-1.51119
1888.55	-2.21261
1891.54	-2.17971
1894.52	-1.23143
1897.51	-1.21064
1900.49	-0.581496
1903.47	0.522682
1906.45	0.808834
1909.43	1.67729
1912.41	2.31316
1915.39	3.55401
1918.37	4.29698
1921.34	4.09618
1924.32	4.87147
1927.29	5.81552
1930.26	5.92363
1933.23	5.64668
1936.2	5.52324
1939.17	5.99952
1942.14	6.4712
1945.11	6.84631
1948.07	5.19181
1951.04	5.83472
1954	6.03125
1956.96	5.11834
1959.93	4.37771
1962.89	4.88871
1965.85	5.22502
1968.8	5.69352
1971.76	5.18169
1974.72	4.5496
1977.67	4.57985
1980.63	5.04814
1983.58	4.49137
1986.53	4.5249
1989.48	4.92564
1992.43	4.29754
1995.38	4.25572
1998.32	4.47873
2001.27	4.8989
2004.22	5.2011
2007.16	5.06638
2010.1	5.05921
2013.04	3.88002
2015.98	4.70511
2018.92	3.60816
2021.86	4.3221
2024.8	3.93848
2027.74	3.51707
2030.67	4.0217
2033.61	4.63871
2036.54	4.22104
2039.47	5.97081
2042.4	6.44319
2045.33	5.7168
2048.26	6.42583
2051.19	7.69433
2054.12	9.6247
2057.04	10.2781
2059.97	11.4233
2062.89	13.2516
2065.81	13.3895
2068.73	15.3845
2071.65	16.8632
2074.57	17.986
2077.49	18.016
2080.41	18.5611
2083.32	18.8238
2086.24	20.21
2089.15	22.7845
2092.07	24.081
2094.98	24.6291
2097.89	25.871
2100.8	28.11
2103.71	31.2343
2106.61	33.5502
2109.52	36.9038
2112.43	40.4477
2115.33	43.7904
2118.23	47.1844
2121.13	51.6456
2124.04	55.4653
2126.94	60.9162
2129.83	65.4325
2132.73	69.8968
2135.63	74.0234
2138.53	77.4341
2141.42	82.8563
2144.31	87.5191
2147.21	91.1072
2150.1	94.9748
2152.99	98.7587
2155.88	102.249
2158.77	105.511
2161.65	108.479
2164.54	109.216
2167.43	111.149
2170.31	112.661
2173.19	113.673
2176.07	113.284
2178.96	112.754
2181.84	112.444
2184.72	110.39
2187.59	107.83
2190.47	105.728
2193.35	102.393
2196.22	99.0689
2199.09	95.2203
2201.97	92.6407
2204.84	88.0097
2207.71	83.6449
2210.58	79.8595
2213.45	75.959
2216.31	71.2801
2219.18	66.3002
2222.05	60.7423
2224.91	56.8101
2227.78	52.5828
2230.64	48.4566
2233.5	44.5111
2236.36	41.5675
2239.22	38.2927
2242.08	36.6604
2244.93	33.2399
2247.79	31.2483
2250.64	29.2913
2253.5	28.4394
2256.35	26.9443
2259.2	26.0146
2262.05	24.832
2264.9	23.0598
2267.75	23.0423
2270.6	22.8898
2273.45	23.0376
2276.29	21.4424
2279.14	19.5244
2281.98	18.2852
2284.82	17.2942
2287.66	15.3455
2290.5	13.2635
2293.34	11.1221
2296.18	10.1678
2299.02	9.76056
2301.86	9.18573
2304.69	9.42939
2307.53	8.82233
2310.36	8.97506
2313.19	9.82952
2316.02	9.93626
2318.85	11.1821
2321.68	11.569
2324.51	11.5552
2327.34	9.85234
2330.16	9.52792
2332.99	9.81936
2335.81	9.13381
2338.64	9.05532
2341.46	7.78331
2344.28	7.23754
2347.1	6.39934
2349.92	5.02415
2352.74	4.10114
2355.55	2.29368
2358.37	0.76195
2361.19	-0.156517
2364	0.508094
2366.81	0.670309
2369.62	0.810551
2372.44	1.74364
2375.24	1.87081
2378.05	2.95128
2380.86	3.70801
2383.67	5.04676
2386.47	5.34304
2389.28	5.26255
2392.08	5.25184
2394.89	4.93887
2397.69	5.29834
2400.49	6.57769
2403.29	6.93196
2406.09	7.72066
2408.88	9.26821
2411.68	9.59621
2414.48	11.0704
2417.27	10.5238
2420.06	10.3565
2422.86	11.1315
2425.65	10.8964
2428.44	11.0224
2431.23	11.6267
2434.02	11.2356
2436.81	10.9802
2439.59	11.7522
2442.38	10.9685
2445.16	9.09812
2447.95	8.35145
2450.73	6.98132
2453.51	6.63571
2456.29	5.68215
2459.07	5.02328
2461.85	5.3846
2464.63	5.14552
2467.4	5.84042
2470.18	6.74816
2472.95	6.00134
2475.73	5.92334
2478.5	6.64424
2481.27	5.60368
2484.04	6.53507
2486.81	6.61178
2489.58	6.52597
2492.35	6.64366
2495.12	5.906
2497.88	5.41304
2500.65	4.4794
2503.41	2.94465
2506.17	2.57084
2508.94	1.08946
2511.7	0.511788
2514.46	0.932353
2517.22	0.208247
2519.97	-0.754911
2522.73	-0.152243
2525.49	0.265554
2528.24	0.449903
2530.99	0.714204
2533.75	1.01795
2536.5	0.85628
2539.25	0.868081
2542	1.17905
2544.75	1.88735
2547.5	2.1561
2550.24	3.15785
2552.99	3.12211
2555.74	2.23719
2558.48	2.48708
2561.22	2.44416
2563.96	2.41523
2566.71	2.0183
2569.45	1.19713
2572.18	0.760608
2574.92	1.61782
2577.66	2.09378
2580.4	2.82767
2583.13	3.50028
2585.87	4.14405
2588.6	6.51143
2591.33	7.24578
2594.06	7.86096
2596.79	8.07971
2599.52	9.45671
2602.25	10.2667
2604.98	11.033
2607.71	12.1069
2610.43	12.4444
2613.16	12.0468
2615.88	11.814
2618.6	11.0462
2621.32	10.3591
2624.04	9.99146
2626.76	8.00516
2629.48	6.76147
2632.2	5.47724
2634.92	4.92281
2637.63	3.75456
2640.35	2.32514
2643.06	2.4287
2645.77	3.00072
2648.49	2.96786
2651.2	2.99143
2653.91	2.52942
2656.62	2.05459
2659.33	1.69868
2662.03	3.06149
2664.74	3.88875
2667.44	3.91627
2670.15	4.56392
2672.85	5.19567
2675.55	5.21201
2678.26	5.93614
2680.96	6.66558
2683.66	6.35583
2686.35	5.45062
2689.05	4.83562
2691.75	5.01631
2694.44	5.16833
2697.14	5.6543
2699.83	7.66944
2702.52	7.934
2705.22	8.14411
2707.91	8.16128
2710.6	8.25142
2713.29	9.90978
2715.97	10.5327
2718.66	10.9994
2721.35	11.5811
2724.03	11.9696
2726.72	12.6199
2729.4	14.7044
2732.08	14.3646
2734.76	14.8152
2737.44	15.3744
2740.12	15.6882
2742.8	15.2883
2745.48	14.0416
2748.16	12.1974
2750.83	11.0849
2753.51	10.0426
2756.18	10.2779
2758.85	10.4456
2761.53	9.25675
2764.2	7.9741
2766.87	6.49664
2769.54	4.19378
2772.2	2.0398
2774.87	0.990482
2777.54	2.24446
2780.2	2.54565
2782.87	1.15367
2785.53	1.28884
2788.19	1.75721
2790.85	1.78097
2793.51	3.1667
2796.17	3.03833
2798.83	2.44448
2801.49	3.04842
2804.15	4.16377
2806.8	4.81459
2809.46	3.55825
2812.11	3.3953
2814.76	3.91144
2817.42	4.7118
2820.07	6.4919
2822.72	8.21676
2825.37	10.9682
2828.02	13.7885
2830.66	16.7562
2833.31	20.7527
2835.96	24.3589
2838.6	30.3047
2841.24	36.646
2843.89	43.6817
2846.53	49.57
2849.17	57.512
2851.81	65.5458
2854.45	74.1833
2857.09	82.4155
2859.72	91.3192
2862.36	99.1128
2865	106.988
2867.63	113.43
2870.26	120.178
2872.9	125.346
2875.53	130.175
2878.16	134.76
2880.79	140.206
2883.42	143.9
2886.05	149.782
2888.67	155.174
2891.3	160.448
2893.92	164.619
2896.55	170.983
2899.17	178.719
2901.79	185.767
2904.42	196.085
2907.04	206.762
2909.66	218.822
2912.27	231.323
2914.89	244.926
2917.51	257.18
2920.13	268.789
2922.74	278.027
2925.35	286.46
2927.97	293.183
2930.58	296.415
2933.19	298.712
2935.8	297.245
2938.41	293.271
2941.02	287.645
2943.63	279.949
2946.24	270.249
2948.84	259.04
2951.45	247.906
2954.05	236.723
2956.65	225.07
2959.26	212.65
2961.86	200.123
2964.46	188.059
2967.06	177.435
2969.66	167.892
2972.25	158.28
2974.85	148.594
2977.45	138.953
2980.04	129.199
2982.64	118.837
2985.23	108.593
2987.82	99.1185
2990.41	90.0192
2993	80.4178
2995.59	70.688
2998.18	61.4563
3000.77	53.5086
3003.36	44.4818
3005.94	37.6926
3008.53	30.865
3011.11	25.8214
3013.69	22.2276
3016.28	20.1305
3018.86	17.6224
3021.44	14.7028
3024.02	12.9052
3026.6	11.4303
3029.18	11.3644
3031.75	11.3072
3034.33	11.471
3036.9	12.133
3039.48	11.7069
3042.05	12.5926
3044.62	14.5333
3047.19	15.1932
3049.77	16.2621
3052.34	17.5473
3054.9	17.0845
3057.47	15.9755
3060.04	15.4102
3062.61	14.3114
3065.17	13.7321
3067.74	12.4043
3070.3	11.4181
3072.86	10.6616
3075.42	10.9416
3077.99	9.15939
3080.54	6.70709
3083.1	5.11881
3085.66	3.51405
3088.22	1.92977
3090.78	0.58459
3093.33	-0.0209878
3095.89	0.285011
3098.44	1.21295
3100.99	1.40998
3103.54	2.91327
3106.1	3.91359
3108.65	4.88611
3111.2	4.8154
3113.74	5.78218
3116.29	6.54372
3118.84	6.79728
3121.38	7.95912
3123.93	9.7945
3126.47	11.4355
3129.01	13.146
3131.56	14.4675
3134.1	16.0547
3136.64	17.7693
3139.18	18.8123
3141.72	19.6375
3144.26	21.456
3146.79	23.8189
3149.33	26.4437