File: data/Raman/poly_smoothed/Thy_50_12_33_1x_45s_532 nm_x100_100%_600 gr_mm_01.txt
#Acq. time (s)=	45
#Accumulations=	2
#Range (cm-¹)=	200...3150
#Windows=	2
#Auto scanning=	Off
#Autofocus=	Off
#Macrospot=	Off
#AutoExposure=	Off
#Spike filter=	Multiple accum.
#Delay time (s)=	0
#Binning=	1
#Readout mode=	Signal
#DeNoise=	Off
#ICS correction=	On
#Dark correction=	Off
#Inst. Process=	Off
#Detector Gain=	Best Dynamic Range
#Detector ADC=	20 kHz
#Detector temperature (°C)=	-69.85
#Instrument=	LabRAM HR Evol
#Detector=	Synapse
#Objective=	x100
#Grating=	600 gr/mm
#ND Filter=	100%
#Laser (nm)=	532
#Hole=	100.021
#Range=	Auto
#Laser Pol.=	No
#Raman. Pol.=	No
#Laser Pol. (°)=	-0.0007625
#Raman Pol. (°)=	89.9995
#Collection=	Microscope
#StageXY=	Marzhauser
#StageZ=	Marzhauser
#X (µm)=	-5141.9
#Y (µm)=	1516.5
#Z (µm)=	63.7
#Full time(mm:ss)=	3:18
#Project=
#Sample=
#Site=
#Title=	Thy_50_12_33_2x_45s_532 nm_x100_100%_600 gr_mm
#Remark=
#Date=	07.07.2022 11:39
#Acquired=	07.07.2022 11:39:31
#Base:Fit=	10.08.2022 10:04:30
#Base:Sub=	10.08.2022 10:04:45
#Filter:Polynom=	16.08.2022 10:20:25
#AxisType[0]=Intens
#AxisUnit[0]=Cnt
#AxisType[1]=Spectr
#AxisUnit[1]=1/cm
200.43	32.8643
204.061	38.3746
207.688	38.1945
211.316	35.6436
214.941	31.8333
218.566	28.5962
222.188	24.5381
225.809	20.7037
229.43	17.4481
233.047	14.5618
236.663	12.4833
240.278	10.9519
243.894	10.1389
247.506	9.1997
251.116	9.26328
254.725	9.20752
258.333	11.1249
261.939	11.8385
265.546	14.4479
269.15	15.3208
272.752	15.2419
276.353	16.2337
279.952	16.9425
283.55	17.6924
287.146	17.8425
290.739	17.6877
294.333	15.0391
297.925	13.266
301.516	12.643
305.106	11.2694
308.694	10.5283
312.279	8.46445
315.864	6.74848
319.448	6.6864
323.029	3.60566
326.61	4.02228
330.19	4.2506
333.766	4.11572
337.343	5.81519
340.917	5.99164
344.491	6.09809
348.062	6.17402
351.633	6.6951
355.201	6.42448
358.77	6.70885
362.335	6.35939
365.899	5.99792
369.464	6.8293
373.025	6.56
376.585	7.09628
380.143	5.19692
383.702	4.99534
387.258	5.16806
390.812	4.68231
394.365	3.87635
397.916	2.91616
401.467	2.42427
405.015	2.37178
408.565	1.05048
412.111	1.5361
415.656	1.54769
419.197	2.52709
422.739	3.53549
426.279	1.83346
429.819	2.70856
433.356	2.55188
436.893	3.303
440.428	3.04712
443.96	2.64665
447.492	3.05721
451.023	3.78624
454.553	3.55199
458.079	5.06338
461.606	6.18886
465.132	5.97819
468.654	6.87893
472.177	8.336
475.696	7.8033
479.217	8.59689
482.733	9.28568
486.251	10.5942
489.765	11.2324
493.278	12.5897
496.791	14.5591
500.301	15.7462
503.81	16.8723
507.319	18.4617
510.825	17.6604
514.33	17.3871
517.833	18.3786
521.337	18.4462
524.838	17.8654
528.337	18.3528
531.835	19.1127
535.332	19.2767
538.827	19.199
542.321	17.4131
545.814	17.4789
549.305	16.7729
552.795	16.0582
556.284	15.5321
559.771	15.7259
563.257	13.9519
566.742	11.8902
570.223	12.1227
573.705	12.4154
577.185	14.4588
580.665	13.0123
584.141	12.189
587.617	11.4887
591.092	10.5771
594.564	10.8596
598.037	11.0332
601.506	11.0379
604.976	11.8349
608.443	10.87
611.91	12.3406
615.374	12.1491
618.839	12.0737
622.3	11.4331
625.761	10.8109
629.221	10.9492
632.679	12.2166
636.135	13.7457
639.592	14.1888
643.045	16.1823
646.497	16.2577
649.948	17.5353
653.398	19.8473
656.846	21.881
660.293	23.2054
663.738	23.7797
667.185	23.0606
670.628	25.324
674.067	28.2648
677.508	29.9371
680.947	34.4558
684.385	36.6399
687.821	38.6917
691.256	41.7954
694.69	43.4646
698.121	46.2663
701.552	47.6766
704.982	48.6272
708.41	49.7398
711.836	50.923
715.262	51.4932
718.685	50.9249
722.108	51.6337
725.53	51.8278
728.949	51.9218
732.369	52.044
735.785	52.184
739.2	51.4689
742.616	52.0033
746.028	52.2487
749.441	53.2814
752.851	55.4944
756.26	58.1367
759.667	61.5699
763.075	63.2449
766.479	69.1169
769.883	70.9204
773.285	74.2413
776.686	77.0293
780.085	79.5257
783.484	80.567
786.881	81.958
790.276	83.5969
793.671	85.1005
797.064	86.4152
800.456	87.2043
803.846	87.4885
807.236	88.3311
810.624	88.6723
814.01	88.6998
817.394	88.0764
820.778	86.2095
824.161	85.4391
827.543	84.6442
830.921	83.1176
834.3	80.6614
837.676	77.4741
841.053	74.2483
844.426	72.1676
847.8	70.592
851.171	66.3857
854.542	62.6878
857.911	61.8408
861.279	60.2077
864.645	58.3297
868.01	58.0477
871.375	58.1389
874.737	57.1066
878.097	56.7151
881.457	56.3706
884.817	56.675
888.174	57.5462
891.53	59.2999
894.884	59.2565
898.237	59.624
901.589	56.3705
904.94	55.9099
908.289	55.5041
911.637	53.1568
914.984	51.3166
918.33	48.128
921.674	47.4514
925.015	45.1486
928.357	43.9152
931.698	40.9236
935.037	39.1228
938.373	38.428
941.71	37.6009
945.046	36.1247
948.378	34.6714
951.711	34.9044
955.043	35.1644
958.372	33.6413
961.701	34.6952
965.027	35.4522
968.354	37.0816
971.678	36.512
975	35.7004
978.324	35.5232
981.644	33.4571
984.962	33.4843
988.282	34.5103
991.598	33.3524
994.913	31.4145
998.227	32.0455
1001.54	31.6352
1004.85	30.5217
1008.16	29.3929
1011.47	29.5938
1014.78	28.7653
1018.08	29.923
1021.39	28.364
1024.69	27.2793
1028	27.4441
1031.3	29.1562
1034.6	29.4193
1037.9	29.2754
1041.19	28.997
1044.49	28.5664
1047.79	28.1121
1051.08	25.9257
1054.37	23.9094
1057.66	22.9387
1060.95	21.2422
1064.24	20.1437
1067.53	19.1213
1070.81	18.4006
1074.1	16.5276
1077.38	15.3594
1080.66	14.8394
1083.94	13.6903
1087.22	13.0335
1090.5	14.4826
1093.78	16.361
1097.05	15.7355
1100.33	16.3461
1103.6	15.9439
1106.87	17.9501
1110.15	18.2615
1113.41	18.1829
1116.68	18.6157
1119.95	17.5641
1123.21	17.2576
1126.48	15.5972
1129.74	14.5878
1133	13.1029
1136.26	12.1357
1139.52	11.037
1142.78	10.1048
1146.04	7.88178
1149.29	5.94104
1152.55	5.5761
1155.8	2.62255
1159.05	0.638296
1162.3	0.596546
1165.55	-0.157019
1168.8	1.43417
1172.05	0.802638
1175.29	1.17623
1178.54	-0.369748
1181.78	-1.21763
1185.02	-0.590829
1188.26	-0.921766
1191.5	0.149522
1194.74	0.868857
1197.97	1.58246
1201.21	3.53609
1204.44	3.64142
1207.68	5.99092
1210.91	8.20034
1214.14	9.93579
1217.37	12.6524
1220.6	14.5448
1223.82	16.1856
1227.05	18.2982
1230.27	22.4068
1233.49	24.0734
1236.72	24.5582
1239.94	27.8287
1243.16	30.0381
1246.37	33.3887
1249.59	34.1979
1252.8	36.1829
1256.02	37.4926
1259.23	37.8592
1262.44	41.8052
1265.66	44.8226
1268.87	47.338
1272.07	49.1022
1275.28	51.4546
1278.48	53.9411
1281.69	54.4247
1284.89	58.228
1288.09	60.5562
1291.3	61.5919
1294.49	64.1736
1297.69	63.9805
1300.89	65.0949
1304.09	65.7477
1307.28	65.5495
1310.47	65.9647
1313.66	65.7487
1316.86	66.5831
1320.05	65.9671
1323.23	64.9604
1326.42	62.0316
1329.61	61.0446
1332.79	59.7399
1335.98	57.5629
1339.16	55.7612
1342.34	54.2923
1345.52	51.7871
1348.7	49.1482
1351.87	47.2791
1355.05	44.9965
1358.23	43.5707
1361.4	41.3885
1364.57	40.1488
1367.74	36.6505
1370.91	34.7754
1374.08	32.6497
1377.25	31.5076
1380.42	30.8308
1383.58	30.0653
1386.75	30.011
1389.91	28.9249
1393.07	27.1571
1396.23	26.903
1399.39	26.9373
1402.55	27.6168
1405.7	30.8373
1408.86	32.6356
1412.01	34.3898
1415.17	34.5473
1418.32	36.7107
1421.47	42.2834
1424.62	48.9618
1427.77	55.8979
1430.92	61.8561
1434.06	67.9403
1437.2	72.1863
1440.35	75.9892
1443.49	78.2082
1446.63	80.0016
1449.77	81.866
1452.91	80.2134
1456.05	79.1445
1459.18	75.8845
1462.32	71.8185
1465.45	66.9762
1468.59	60.7816
1471.72	56.3691
1474.85	52.2174
1477.98	46.9497
1481.11	41.2192
1484.23	36.042
1487.36	30.0255
1490.48	24.9312
1493.61	21.7905
1496.73	23.8177
1499.85	24.0406
1502.97	24.116
1506.09	22.6224
1509.2	22.1344
1512.32	21.1556
1515.44	20.8378
1518.55	21.9386
1521.66	21.0724
1524.77	20.7564
1527.88	20.8331
1530.99	22.247
1534.1	23.1015
1537.21	24.0079
1540.31	25.0287
1543.42	26.6219
1546.52	28.2648
1549.62	31.646
1552.72	34.0828
1555.82	37.3923
1558.92	40.0255
1562.02	42.8313
1565.11	44.9126
1568.21	49.1111
1571.3	51.4361
1574.39	53.7158
1577.49	56.2684
1580.58	57.0827
1583.67	58.18
1586.75	58.31
1589.84	57.2607
1592.93	56.0185
1596.01	55.7128
1599.09	54.6456
1602.18	54.0755
1605.26	54.0658
1608.34	51.9635
1611.41	52.0966
1614.49	52.0541
1617.57	52.7546
1620.64	54.3128
1623.72	56.0457
1626.79	58.3264
1629.86	60.7384
1632.93	64.4714
1636	67.3934
1639.07	69.9544
1642.14	73.2934
1645.2	75.4319
1648.27	76.2282
1651.33	78.0407
1654.39	79.6993
1657.45	80.108
1660.51	79.1984
1663.57	76.7025
1666.63	74.4983
1669.69	72.2023
1672.74	70.2855
1675.79	65.1633
1678.85	61.4134
1681.9	56.4602
1684.95	51.3199
1688	45.9263
1691.05	41.2458
1694.1	37.1341
1697.14	33.1549
1700.19	30.1312
1703.23	27.4517
1706.27	24.3726
1709.32	22.5981
1712.35	19.796
1715.39	16.8668
1718.43	15.1056
1721.47	13.0035
1724.5	13.0597
1727.54	13.0254
1730.57	12.9762
1733.61	11.6152
1736.64	10.9712
1739.67	9.93561
1742.7	9.64153
1745.72	9.28057
1748.75	8.22638
1751.78	8.62631
1754.8	8.4878
1757.82	6.98768
1760.85	6.62124
1763.87	7.57157
1766.89	8.76396
1769.91	8.35038
1772.92	8.74404
1775.94	9.73042
1778.96	10.1535
1781.97	10.419
1784.98	9.54
1788	9.18689
1791.01	8.97199
1794.01	8.45538
1797.02	8.74206
1800.03	8.37822
1803.04	7.60274
1806.04	6.93595
1809.05	6.27514
1812.05	5.66418
1815.05	6.13736
1818.05	5.77718
1821.05	5.09084
1824.05	4.94807
1827.05	6.47409
1830.04	7.66101
1833.04	7.43326
1836.03	8.4572
1839.03	8.86538
1842.02	8.672
1845.01	7.65882
1848	7.45224
1850.99	6.65619
1853.97	5.81955
1856.96	4.81052
1859.94	4.12392
1862.93	3.25394
1865.91	3.62459
1868.89	2.44769
1871.87	2.24218
1874.85	3.04304
1877.83	2.89984
1880.81	2.96539
1882.56	2.88165
1885.55	2.19218
1888.54	1.86776
1891.52	1.94006
1894.51	3.15747
1897.49	4.90986
1900.48	5.07317
1903.46	4.85228
1906.44	4.86369
1909.42	6.04342
1912.4	5.86478
1915.38	5.03692
1918.35	5.06256
1921.33	4.38588
1924.3	4.0616
1927.28	4.72732
1930.25	4.55621
1933.22	3.75445
1936.19	4.02132
1939.16	5.76652
1942.13	6.97355
1945.09	8.31094
1948.06	8.61832
1951.03	7.91042
1953.99	8.03466
1956.95	7.04433
1959.91	5.77935
1962.87	5.57192
1965.83	5.68595
1968.79	6.37142
1971.75	6.23402
1974.7	6.1576
1977.66	6.04867
1980.61	6.07616
1983.56	5.52788
1986.52	4.68453
1989.47	4.63917
1992.41	3.39289
1995.36	2.83141
1998.31	2.28839
2001.26	2.25459
2004.2	1.97628
2007.15	2.64095
2010.09	4.09902
2013.03	4.10039
2015.97	2.96056
2018.91	2.65544
2021.85	2.70949
2024.79	3.35218
2027.72	3.61853
2030.66	3.12494
2033.59	4.70296
2036.53	5.76525
2039.46	6.8194
2042.39	8.31456
2045.32	9.41462
2048.25	10.6386
2051.18	11.9066
2054.1	13.2347
2057.03	14.0316
2059.95	13.8686
2062.88	13.277
2065.8	13.9603
2068.72	15.5933
2071.64	16.6437
2074.56	17.5259
2077.48	18.2139
2080.39	19.2291
2083.31	20.2065
2086.22	21.5767
2089.14	23.2185
2092.05	25.3448
2094.96	28.0068
2097.87	30.7157
2100.78	33.5907
2103.69	36.7577
2106.6	40.173
2109.51	43.6515
2112.41	46.9362
2115.32	50.8988
2118.22	54.4857
2121.12	57.6285
2124.02	61.4526
2126.92	63.0719
2129.82	66.3686
2132.72	70.757
2135.62	74.2154
2138.51	78.5245
2141.41	80.0435
2144.3	82.7226
2147.19	85.0031
2150.09	86.3055
2152.97	88.4961
2155.86	91.4414
2158.75	93.8035
2161.64	94.5323
2164.53	95.9592
2167.41	95.6997
2170.3	95.5892
2173.18	94.747
2176.06	93.6252
2178.94	91.2457
2181.82	89.1034
2184.7	86.8198
2187.58	83.6682
2190.46	80.2
2193.33	77.5009
2196.21	74.0725
2199.08	70.836
2201.95	68.3443
2204.83	65.7734
2207.7	60.7195
2210.57	57.0522
2213.43	53.4573
2216.3	50.6251
2219.17	49.0791
2222.03	46.7895
2224.9	44.7589
2227.76	42.6038
2230.62	39.6094
2233.49	36.4647
2236.34	34.2102
2239.2	31.0956
2242.06	29.681
2244.92	27.5772
2247.78	25.2459
2250.63	24.3197
2253.48	23.0638
2256.34	21.295
2259.19	20.1076
2262.04	19.7918
2264.89	17.7712
2267.74	16.9541
2270.59	15.6608
2273.43	14.3886
2276.28	13.8017
2279.12	12.8504
2281.97	12.6709
2284.81	12.4047
2287.65	12.0329
2290.49	9.93446
2293.33	7.28045
2296.17	6.89119
2299.01	7.20071
2301.84	7.52901
2304.68	7.20185
2307.51	7.757
2310.35	8.32428
2313.18	8.80765
2316.01	9.16262
2318.84	9.61625
2321.67	9.06274
2324.5	8.13868
2327.33	8.0917
2330.15	8.04832
2332.98	7.4967
2335.8	6.37641
2338.62	6.29937
2341.45	4.73826
2344.27	4.35285
2347.09	3.47831
2349.91	2.82999
2352.72	2.16155
2355.54	1.20077
2358.36	-0.353176
2361.17	-0.526537
2363.98	0.465858
2366.8	1.50891
2369.61	1.72829
2372.42	1.98733
2375.23	2.28131
2378.04	2.65175
2380.85	2.55532
2383.66	2.78047
2386.46	2.33748
2389.26	3.09443
2392.07	2.25336
2394.87	2.90719
2397.67	3.41997
2400.47	3.4402
2403.27	3.29114
2406.07	3.40569
2408.87	4.08122
2411.67	4.2696
2414.46	4.81479
2417.26	5.28024
2420.05	6.45634
2422.84	7.11589
2425.64	7.46352
2428.43	7.48718
2431.22	7.70128
2434.01	7.44438
2436.79	7.59553
2439.58	7.52913
2442.37	6.46127
2445.15	6.75346
2447.93	5.94376
2450.72	5.65214
2453.5	5.17269
2456.28	5.33539
2459.06	4.42595
2461.84	5.08441
2464.62	5.82912
2467.39	5.52994
2470.17	5.23795
2472.94	5.91106
2475.72	5.92364
2478.49	6.122
2481.26	5.84453
2484.03	5.14323
2486.8	5.91331
2489.57	6.53893
2492.34	6.52107
2495.1	6.41774
2497.87	5.87713
2500.63	5.43879
2503.4	5.12068
2506.16	4.80242
2508.92	3.36101
2511.68	3.06818
2514.44	1.70988
2517.2	1.21453
2519.96	0.59288
2522.72	0.599455
2525.47	0.192317
2528.23	-0.485874
2530.98	-0.0914428
2533.74	-0.841567
2536.49	-1.35022
2539.24	-0.594929
2541.99	-0.136661
2544.74	-0.00714238
2547.49	0.720311
2550.23	0.927611
2552.98	2.57955
2555.72	2.98395
2558.47	3.77915
2561.21	4.17352
2563.95	5.51258
2566.69	5.38256
2569.43	5.07732
2572.17	4.79373
2574.91	4.40342
2577.65	3.22428
2580.39	3.20549
2583.12	4.38622
2585.85	4.95746
2588.59	4.50636
2591.32	4.61854
2594.05	4.9939
2596.78	5.84605
2599.51	6.88855
2602.24	7.00573
2604.97	7.64253
2607.69	8.33821
2610.42	8.31166
2613.14	8.87285
2615.87	8.47209
2618.59	8.40887
2621.31	8.96692
2624.03	9.15747
2626.75	9.3413
2629.47	9.39267
2632.19	8.3159
2634.91	7.33535
2637.62	7.03695
2640.34	7.39542
2643.05	7.04342
2645.76	7.57319
2648.48	7.91453
2651.19	7.13739
2653.9	6.90189
2656.6	7.55177
2659.31	7.69775
2662.02	8.56521
2664.73	8.7172
2667.43	8.82032
2670.14	8.95044
2672.84	8.62078
2675.54	8.28716
2678.24	8.52939
2680.94	9.02366
2683.64	9.51981
2686.34	9.90846
2689.04	10.0854
2691.74	9.90495
2694.43	9.71663
2697.13	9.64791
2699.82	9.69654
2702.51	10.5983
2705.21	11.4678
2707.9	11.6117
2710.58	11.2976
2713.27	11.9729
2715.96	11.9108
2718.65	11.9578
2721.33	11.5722
2724.02	11.111
2726.71	11.4165
2729.39	11.936
2732.07	11.5866
2734.75	10.3196
2737.43	10.3613
2740.11	9.03997
2742.79	8.76584
2745.47	8.44323
2748.14	7.38191
2750.82	6.22206
2753.49	5.15756
2756.17	4.00198
2758.84	3.72315
2761.51	2.48745
2764.18	2.49346
2766.85	1.1628
2769.52	1.38739
2772.19	0.19121
2774.86	0.178475
2777.52	-0.959106
2780.19	-0.607786
2782.85	-0.388793
2785.52	-0.792648
2788.18	-1.23602
2790.84	-0.707525
2793.5	-0.350875
2796.16	-0.43282
2798.82	-0.815149
2801.48	-1.09158
2804.13	-0.323074
2806.79	-0.982852
2809.45	-1.12457
2812.1	-0.443502
2814.75	-0.555079
2817.41	1.05041
2820.06	3.76571
2822.71	8.60214
2825.36	12.9166
2828	18.5292
2830.65	24.7241
2833.3	31.6425
2835.94	38.5256
2838.59	45.4185
2841.23	51.8537
2843.87	59.3547
2846.52	68.1855
2849.16	76.4207
2851.8	84.3853
2854.44	92.9332
2857.08	101.545
2859.71	109.836
2862.35	117.186
2864.98	123.537
2867.62	128.774
2870.25	132.324
2872.88	135.96
2875.52	139.681
2878.15	142.617
2880.78	145.697
2883.41	148.631
2886.03	151.949
2888.66	155.474
2891.29	158.338
2893.91	160.443
2896.54	163.044
2899.16	166.525
2901.78	169.652
2904.4	174.855
2907.02	180.183
2909.64	187.088
2912.26	194.674
2914.88	201.972
2917.5	208.864
2920.11	214.796
2922.73	219.729
2925.34	223.283
2927.96	226.233
2930.57	226.858
2933.18	225.886
2935.79	224.044
2938.4	220.095
2941.01	214.356
2943.62	207.646
2946.22	198.93
2948.83	189.683
2951.43	180.638
2954.04	171.495
2956.64	161.604
2959.24	152.458
2961.84	144.669
2964.45	135.972
2967.05	127.764
2969.64	120.004
2972.24	111.57
2974.84	105.595
2977.43	98.1899
2980.03	89.5072
2982.62	81.3227
2985.22	73.2335
2987.81	65.2073
2990.4	58.7938
2992.99	51.4083
2995.58	45.1843
2998.17	38.1197
3000.76	32.2105
3003.34	26.1133
3005.93	21.9677
3008.52	17.3522
3011.1	12.859
3013.68	9.51248
3016.27	6.88085
3018.85	5.86006
3021.43	4.30192
3024.01	4.03159
3026.59	3.60661
3029.16	3.18851
3031.74	3.77873
3034.32	4.83555
3036.89	5.4103
3039.47	6.58613
3042.04	6.66157
3044.61	6.50907
3047.18	7.14651
3049.75	6.89722
3052.32	7.35961
3054.89	8.12896
3057.46	8.91919
3060.03	9.02773
3062.59	8.73897
3065.16	7.89276
3067.72	7.60356
3070.29	6.87398
3072.85	5.21799
3075.41	3.78062
3077.97	2.66812
3080.53	1.99325
3083.09	1.57784
3085.65	0.705758
3088.21	0.428272
3090.76	1.2215
3093.32	1.54327
3095.87	3.42449
3098.43	4.53401
3100.98	5.25471
3103.53	7.00119
3106.08	8.45932
3108.63	9.81052
3111.18	12.3852
3113.73	13.9645
3116.28	16.1829
3118.83	18.6967
3121.37	20.9605
3123.92	22.3846
3126.46	24.3302
3129	25.7339
3131.55	27.2385
3134.09	27.7266
3136.63	28.6554
3139.17	29.1988
3141.71	30.3231
3144.24	31.3433
3146.78	32.5393
3149.32	33.3921