File: data/Raman/poly_smoothed/Thy_50_12_24_1x_45s_532 nm_x100_100%_600 gr_mm_01.txt
#Acq. time (s)=	45
#Accumulations=	2
#Range (cm-¹)=	200...3150
#Windows=	2
#Auto scanning=	Off
#Autofocus=	Off
#Macrospot=	Off
#AutoExposure=	Off
#Spike filter=	Multiple accum.
#Delay time (s)=	0
#Binning=	1
#Readout mode=	Signal
#DeNoise=	Off
#ICS correction=	On
#Dark correction=	Off
#Inst. Process=	Off
#Detector Gain=	Best Dynamic Range
#Detector ADC=	20 kHz
#Detector temperature (°C)=	-69.85
#Instrument=	LabRAM HR Evol
#Detector=	Synapse
#Objective=	x100
#Grating=	600 gr/mm
#ND Filter=	100%
#Laser (nm)=	532
#Hole=	100.021
#Range=	Auto
#Laser Pol.=	No
#Raman. Pol.=	No
#Laser Pol. (°)=	-0.0007625
#Raman Pol. (°)=	89.9995
#Collection=	Microscope
#StageXY=	Marzhauser
#StageZ=	Marzhauser
#X (µm)=	-5134.3
#Y (µm)=	1494.5
#Z (µm)=	62.85
#Full time(mm:ss)=	3:18
#Project=
#Sample=
#Site=
#Title=	Thy_50_12_24_2x_45s_532 nm_x100_100%_600 gr_mm
#Remark=
#Date=	07.07.2022 11:00
#Acquired=	07.07.2022 11:00:03
#Base:Fit=	10.08.2022 10:04:29
#Base:Sub=	10.08.2022 10:04:45
#Filter:Polynom=	16.08.2022 10:20:24
#AxisType[0]=Intens
#AxisUnit[0]=Cnt
#AxisType[1]=Spectr
#AxisUnit[1]=1/cm
200.43	17.8061
204.061	22.1078
207.688	21.7193
211.316	19.7097
214.941	19.047
218.566	17.9672
222.188	15.6869
225.809	14.241
229.43	14.9365
233.047	15.9656
236.663	16.5176
240.278	15.7226
243.894	16.2636
247.506	14.7879
251.116	12.5128
254.725	11.162
258.333	11.2247
261.939	10.2
265.546	9.74999
269.15	9.30042
272.752	10.0894
276.353	10.3357
279.952	11.765
283.55	11.5342
287.146	10.6635
290.739	9.39556
294.333	9.781
297.925	12.2073
301.516	14.4168
305.106	15.5617
308.694	16.5063
312.279	18.8005
315.864	22.1282
319.448	24.6883
323.029	26.2648
326.61	26.6688
330.19	26.809
333.766	26.8891
337.343	24.9866
340.917	23.7649
344.491	24.3079
348.062	22.8823
351.633	21.5807
355.201	20.2685
358.77	19.5137
362.335	19.4986
365.899	17.4871
369.464	15.9506
373.025	13.4997
376.585	12.6801
380.143	12.2463
383.702	13.0417
387.258	14.7265
390.812	15.0074
394.365	14.4881
397.916	13.4994
401.467	13.4474
405.015	13.0636
408.565	13.4891
412.111	12.9353
415.656	11.9596
419.197	10.7114
422.739	10.781
426.279	10.5036
429.819	10.8229
433.356	10.5771
436.893	10.3932
440.428	8.5355
443.96	8.1727
447.492	9.5276
451.023	10.1274
454.553	9.1466
458.079	9.44864
461.606	10.3208
465.132	11.6232
468.654	12.2832
472.177	14.3631
475.696	15.5062
479.217	13.8296
482.733	14.4591
486.251	15.4687
489.765	16.5004
493.278	17.4748
496.791	18.7044
500.301	18.9403
503.81	20.2541
507.319	21.4799
510.825	22.8895
514.33	24.0853
517.833	25.022
521.337	25.7302
524.838	26.5184
528.337	24.6776
531.835	25.0706
535.332	25.1226
538.827	24.129
542.321	22.5437
545.814	21.4488
549.305	20.4818
552.795	17.1731
556.284	15.172
559.771	14.3638
563.257	11.1544
566.742	7.3915
570.223	7.43645
573.705	7.4741
577.185	5.03272
580.665	3.722
584.141	2.66841
587.617	2.5193
591.092	1.74955
594.564	1.84095
598.037	3.08118
601.506	3.12877
604.976	4.88486
608.443	4.31569
611.91	4.00208
615.374	5.107
618.839	7.07137
622.3	7.84646
625.761	8.20076
629.221	8.1318
632.679	9.13967
636.135	10.3575
639.592	11.2081
643.045	13.5759
646.497	14.141
649.948	13.8647
653.398	15.1174
656.846	15.4718
660.293	15.3702
663.738	15.096
667.185	15.9406
670.628	18.4188
674.067	18.1206
677.508	19.5799
680.947	20.3662
684.385	22.909
687.821	24.3663
691.256	26.4338
694.69	28.4508
698.121	31.9633
701.552	34.3574
704.982	35.1157
708.41	37.3824
711.836	39.6601
715.262	42.0148
718.685	44.0269
722.108	45.1264
725.53	47.0047
728.949	47.4426
732.369	48.1014
735.785	49.847
739.2	51.1411
742.616	52.4711
746.028	53.9715
749.441	56.442
752.851	58.5281
756.26	60.5106
759.667	62.1721
763.075	63.8041
766.479	66.2749
769.883	69.0201
773.285	69.9687
776.686	72.1575
780.085	74.6943
783.484	76.5215
786.881	76.5792
790.276	78.7202
793.671	79.2978
797.064	79.9752
800.456	79.3181
803.846	78.9236
807.236	80.1068
810.624	79.1859
814.01	78.6798
817.394	77.9089
820.778	77.8494
824.161	77.9844
827.543	76.9882
830.921	77.4738
834.3	75.3456
837.676	73.3873
841.053	70.9127
844.426	68.8021
847.8	66.0428
851.171	64.7661
854.542	63.5349
857.911	60.3676
861.279	58.3877
864.645	57.493
868.01	55.9986
871.375	54.5955
874.737	52.8279
878.097	50.3557
881.457	49.2982
884.817	49.6531
888.174	48.0568
891.53	47.9888
894.884	46.3718
898.237	46.7355
901.589	46.7385
904.94	47.7009
908.289	49.0629
911.637	47.7411
914.984	48.2388
918.33	45.9331
921.674	46.3106
925.015	45.9439
928.357	43.8971
931.698	43.2482
935.037	42.0023
938.373	40.7569
941.71	38.9278
945.046	37.5113
948.378	35.8735
951.711	35.9053
955.043	34.8532
958.372	33.7118
961.701	33.4891
965.027	33.63
968.354	31.8218
971.678	31.8605
975	32.4386
978.324	33.09
981.644	34.1532
984.962	33.6709
988.282	33.9478
991.598	32.3058
994.913	31.3029
998.227	28.3087
1001.54	28.9359
1004.85	29.4838
1008.16	27.7189
1011.47	28.4217
1014.78	30.2622
1018.08	30.5383
1021.39	30.5702
1024.69	31.2269
1028	33.6104
1031.3	34.7374
1034.6	36.7021
1037.9	34.7091
1041.19	34.1267
1044.49	33.9176
1047.79	35.6914
1051.08	35.2097
1054.37	33.335
1057.66	31.3448
1060.95	27.7524
1064.24	23.8988
1067.53	20.3152
1070.81	18.1664
1074.1	14.7661
1077.38	11.4539
1080.66	9.8133
1083.94	8.72026
1087.22	7.2266
1090.5	6.89165
1093.78	8.0521
1097.05	6.42215
1100.33	8.18169
1103.6	9.48704
1106.87	11.2866
1110.15	11.67
1113.41	13.2439
1116.68	13.2392
1119.95	12.7737
1123.21	14.8992
1126.48	15.2786
1129.74	15.1903
1133	12.8301
1136.26	10.7914
1139.52	9.93182
1142.78	9.14797
1146.04	8.3831
1149.29	7.41215
1152.55	5.34265
1155.8	3.93298
1159.05	2.39102
1162.3	0.763405
1165.55	0.531189
1168.8	1.4894
1172.05	2.13563
1175.29	1.34719
1178.54	-0.017129
1181.78	1.41341
1185.02	0.905024
1188.26	0.85759
1191.5	2.47836
1194.74	2.13506
1197.97	3.14407
1201.21	3.76564
1204.44	5.11788
1207.68	6.22667
1210.91	7.41552
1214.14	9.05801
1217.37	11.8177
1220.6	14.6661
1223.82	17.1919
1227.05	19.8904
1230.27	24.2981
1233.49	28.8579
1236.72	31.1899
1239.94	36.3304
1243.16	40.5522
1246.37	45.2512
1249.59	46.6227
1252.8	48.9328
1256.02	50.7912
1259.23	53.0295
1262.44	56.1047
1265.66	58.2178
1268.87	62.7548
1272.07	64.3959
1275.28	65.999
1278.48	67.0098
1281.69	68.1973
1284.89	69.0558
1288.09	69.5814
1291.3	68.3702
1294.49	67.7921
1297.69	68.267
1300.89	66.1591
1304.09	66.4925
1307.28	66.4212
1310.47	65.2689
1313.66	63.1447
1316.86	61.5458
1320.05	59.8902
1323.23	56.3685
1326.42	54.2084
1329.61	51.7272
1332.79	51.1095
1335.98	50.4599
1339.16	49.1969
1342.34	49.9357
1345.52	48.5134
1348.7	48.1898
1351.87	46.7705
1355.05	42.8942
1358.23	42.6355
1361.4	41.6347
1364.57	39.6482
1367.74	38.7124
1370.91	38.031
1374.08	38.1043
1377.25	38.1476
1380.42	38.2475
1383.58	36.7859
1386.75	35.3309
1389.91	33.2608
1393.07	31.7773
1396.23	29.7661
1399.39	28.5617
1402.55	27.1447
1405.7	26.855
1408.86	27.992
1412.01	29.4738
1415.17	31.3145
1418.32	33.3104
1421.47	37.2148
1424.62	40.693
1427.77	44.9668
1430.92	49.9738
1434.06	55.9267
1437.2	62.6749
1440.35	66.1149
1443.49	70.2927
1446.63	74.0114
1449.77	75.4932
1452.91	75.5836
1456.05	75.2936
1459.18	72.6583
1462.32	69.0417
1465.45	65.0077
1468.59	58.7182
1471.72	52.8692
1474.85	47.194
1477.98	39.0086
1481.11	32.7453
1484.23	28.6633
1487.36	23.8887
1490.48	20.1331
1493.61	16.8697
1496.73	14.1046
1499.85	13.8424
1502.97	12.7392
1506.09	13.4516
1509.2	15.5293
1512.32	16.0568
1515.44	17.4237
1518.55	18.5142
1521.66	19.5577
1524.77	20.4191
1527.88	20.36
1530.99	22.1911
1534.1	22.3551
1537.21	24.6366
1540.31	26.8338
1543.42	29.318
1546.52	32.7023
1549.62	37.6363
1552.72	39.8642
1555.82	43.7533
1558.92	47.2184
1562.02	50.2286
1565.11	53.0207
1568.21	55.982
1571.3	59.6679
1574.39	63.5304
1577.49	65.5284
1580.58	68.1018
1583.67	72.0701
1586.75	73.6828
1589.84	73.6057
1592.93	74.7137
1596.01	72.9446
1599.09	71.6999
1602.18	69.2988
1605.26	67.4233
1608.34	65.9945
1611.41	63.7733
1614.49	64.5756
1617.57	63.8329
1620.64	64.8329
1623.72	65.27
1626.79	65.0589
1629.86	67.041
1632.93	67.5114
1636	69.6365
1639.07	70.1785
1642.14	72.6042
1645.2	75.608
1648.27	77.8079
1651.33	78.6381
1654.39	79.5151
1657.45	80.4797
1660.51	80.1241
1663.57	76.8681
1666.63	74.5811
1669.69	70.4437
1672.74	66.0662
1675.79	60.7746
1678.85	54.6303
1681.9	49.0519
1684.95	44.2958
1688	38.7309
1691.05	33.584
1694.1	30.1107
1697.14	25.5961
1700.19	21.4622
1703.23	18.9782
1706.27	14.9023
1709.32	12.5778
1712.35	10.8739
1715.39	8.81529
1718.43	8.91233
1721.47	8.28927
1724.5	7.07537
1727.54	6.36041
1730.57	5.79355
1733.61	5.4362
1736.64	3.51731
1739.67	3.34871
1742.7	3.03024
1745.72	1.58461
1748.75	1.79614
1751.78	0.461516
1754.8	1.55028
1757.82	1.05537
1760.85	0.120142
1763.87	0.582233
1766.89	1.70717
1769.91	1.31711
1772.92	1.249
1775.94	1.55729
1778.96	0.960336
1781.97	1.46947
1784.98	1.79526
1788	2.63325
1791.01	2.07483
1794.01	1.72507
1797.02	2.28428
1800.03	3.21682
1803.04	4.91032
1806.04	6.22237
1809.05	7.14775
1812.05	7.38912
1815.05	7.16475
1818.05	7.41315
1821.05	7.22218
1824.05	7.91623
1827.05	7.93826
1830.04	7.05946
1833.04	6.21521
1836.03	7.06563
1839.03	7.96637
1842.02	7.81147
1845.01	6.78377
1848	6.20981
1850.99	4.76757
1853.97	4.06471
1856.96	2.8762
1859.94	1.75087
1862.93	1.0616
1865.91	-0.115366
1868.89	1.00192
1871.87	3.33342
1874.85	4.8417
1877.83	5.48097
1880.81	5.27503
1882.56	5.63084
1885.55	7.54365
1888.54	8.96953
1891.52	9.95826
1894.51	10.0398
1897.49	10.8129
1900.48	9.80494
1903.46	9.32012
1906.44	10.5039
1909.42	10.3591
1912.4	10.2139
1915.38	8.83421
1918.35	8.00438
1921.33	7.81477
1924.3	7.3499
1927.28	7.45103
1930.25	7.03239
1933.22	7.04821
1936.19	6.96259
1939.16	7.10079
1942.13	7.21697
1945.09	7.44216
1948.06	6.95308
1951.03	6.7312
1953.99	7.54586
1956.95	8.38593
1959.91	7.98901
1962.87	6.68086
1965.83	6.12568
1968.79	5.2841
1971.75	4.89342
1974.7	4.30713
1977.66	4.10968
1980.61	3.95109
1983.56	4.4165
1986.52	5.06902
1989.47	4.61512
1992.41	4.48003
1995.36	4.23992
1998.31	3.9858
2001.26	5.09855
2004.2	5.07496
2007.15	4.38873
2010.09	3.88944
2013.03	2.85442
2015.97	2.81522
2018.91	3.91476
2021.85	4.11758
2024.79	5.47709
2027.72	5.25659
2030.66	6.58514
2033.59	7.13221
2036.53	8.58436
2039.46	9.68048
2042.39	10.7561
2045.32	12.0782
2048.25	13.8146
2051.18	15.3692
2054.1	17.3201
2057.03	18.4265
2059.95	19.7981
2062.88	19.57
2065.8	20.038
2068.72	21.8192
2071.64	24.2208
2074.56	25.537
2077.48	25.4289
2080.39	26.2702
2083.31	27.4158
2086.22	28.2747
2089.14	31.0545
2092.05	33.1057
2094.96	34.7005
2097.87	36.729
2100.78	39.3013
2103.69	42.2777
2106.6	45.3592
2109.51	48.043
2112.41	50.2303
2115.32	52.6174
2118.22	55.6565
2121.12	57.4639
2124.02	61.785
2126.92	65.5706
2129.82	69.4488
2132.72	73.4097
2135.62	77.5721
2138.51	82.2588
2141.41	85.7899
2144.3	89.535
2147.19	93.0918
2150.09	96.1657
2152.97	98.902
2155.86	101.047
2158.75	105.739
2161.64	108.865
2164.53	111.952
2167.41	113.99
2170.3	116.002
2173.18	116.247
2176.06	115.535
2178.94	114.005
2181.82	111.342
2184.7	108.638
2187.58	106.013
2190.46	103.782
2193.33	100.651
2196.21	95.3589
2199.08	90.4103
2201.95	86.3644
2204.83	82.6467
2207.7	78.2811
2210.57	73.1809
2213.43	69.867
2216.3	66.3423
2219.17	62.9645
2222.03	59.3182
2224.9	56.3223
2227.76	54.1051
2230.62	52.7054
2233.49	50.2035
2236.34	48.0509
2239.2	45.606
2242.06	43.1935
2244.92	41.3974
2247.78	38.2025
2250.63	36.0244
2253.48	33.9089
2256.34	32.3547
2259.19	30.8223
2262.04	28.3005
2264.89	24.9399
2267.74	23.0616
2270.59	22.4101
2273.43	21.9997
2276.28	21.8657
2279.12	20.013
2281.97	19.68
2284.81	19.3703
2287.65	17.5918
2290.49	16.0696
2293.33	14.6176
2296.17	13.4806
2299.01	13.8914
2301.84	13.8175
2304.68	14.4303
2307.51	14.9304
2310.35	14.8796
2313.18	15.4364
2316.01	15.5288
2318.84	15.4754
2321.67	15.2558
2324.5	14.9557
2327.33	14.2119
2330.15	13.3721
2332.98	12.8511
2335.8	11.7978
2338.62	10.9523
2341.45	9.64088
2344.27	9.10562
2347.09	8.45935
2349.91	6.75497
2352.72	4.67076
2355.54	2.61273
2358.36	1.55342
2361.17	0.850713
2363.98	2.10902
2366.8	2.75114
2369.61	3.01961
2372.42	3.64287
2375.23	4.23454
2378.04	6.42853
2380.85	6.50045
2383.66	6.66476
2386.46	6.60755
2389.26	6.31593
2392.07	6.76306
2394.87	5.75699
2397.67	4.58315
2400.47	4.72119
2403.27	4.23055
2406.07	3.89815
2408.87	3.68904
2411.67	3.57962
2414.46	3.95251
2417.26	2.71006
2420.05	2.40806
2422.84	2.17674
2425.64	3.26271
2428.43	3.43753
2431.22	3.62256
2434.01	3.29523
2436.79	2.932
2439.58	3.73653
2442.37	4.19328
2445.15	5.99485
2447.93	6.2852
2450.72	5.63388
2453.5	5.62534
2456.28	6.01993
2459.06	6.06958
2461.84	6.18841
2464.62	4.52995
2467.39	5.02276
2470.17	4.51882
2472.94	4.51633
2475.72	4.11355
2478.49	4.47825
2481.26	4.17961
2484.03	3.49591
2486.8	3.37845
2489.57	2.41924
2492.34	0.968575
2495.1	-0.0308188
2497.87	-0.904497
2500.63	-1.60873
2503.4	-2.05157
2506.16	-1.20973
2508.92	-0.198164
2511.68	0.288893
2514.44	0.103449
2517.2	0.837114
2519.96	0.838667
2522.72	1.09017
2525.47	1.44058
2528.23	1.15499
2530.98	0.961764
2533.74	1.14131
2536.49	2.23458
2539.24	2.70111
2541.99	3.63259
2544.74	3.28259
2547.49	3.46256
2550.23	4.05076
2552.98	3.03445
2555.72	2.52656
2558.47	1.44058
2561.21	1.26943
2563.95	1.66561
2566.69	2.00486
2569.43	1.61227
2572.17	2.36951
2574.91	2.64668
2577.65	2.89184
2580.39	3.29359
2583.12	3.30544
2585.85	3.14649
2588.59	3.45778
2591.32	4.09795
2594.05	4.13295
2596.78	4.69979
2599.51	4.4695
2602.24	4.76106
2604.97	4.9367
2607.69	4.56034
2610.42	4.2077
2613.14	4.66551
2615.87	5.59019
2618.59	4.23326
2621.31	3.10574
2624.03	3.38442
2626.75	3.43942
2629.47	3.69506
2632.19	4.37997
2634.91	4.35329
2637.62	4.47347
2640.34	4.8401
2643.05	5.94711
2645.76	6.45232
2648.48	6.98775
2651.19	7.73653
2653.9	6.22414
2656.6	5.6095
2659.31	6.27917
2662.02	5.98421
2664.73	5.5174
2667.43	5.12864
2670.14	5.14359
2672.84	4.91226
2675.54	6.09606
2678.24	5.6187
2680.94	6.37037
2683.64	6.91693
2686.34	6.41094
2689.04	6.08034
2691.74	6.71033
2694.43	6.82701
2697.13	7.86373
2699.82	8.52682
2702.51	9.19713
2705.21	10.1863
2707.9	10.69
2710.58	10.4378
2713.27	10.6319
2715.96	10.6051
2718.65	9.58174
2721.33	9.09463
2724.02	9.17014
2726.71	9.27992
2729.39	8.58895
2732.07	8.72865
2734.75	9.04112
2737.43	9.27677
2740.11	10.0879
2742.79	10.337
2745.47	10.1677
2748.14	10.5939
2750.82	10.0619
2753.49	10.0434
2756.17	10.0404
2758.84	10.5776
2761.51	11.6256
2764.18	11.392
2766.85	11.7972
2769.52	12.5007
2772.19	11.1204
2774.86	9.04934
2777.52	8.85596
2780.19	9.04367
2782.85	7.58043
2785.52	5.81522
2788.18	5.69836
2790.84	5.29233
2793.5	4.6874
2796.16	3.7807
2798.82	3.63755
2801.48	3.91006
2804.13	3.4024
2806.79	4.11451
2809.45	3.54652
2812.1	3.32339
2814.75	3.46072
2817.41	5.56808
2820.06	9.575
2822.71	13.0169
2825.36	18.5088
2828	23.1325
2830.65	28.1382
2833.3	32.8307
2835.94	38.3779
2838.59	43.785
2841.23	50.3913
2843.87	57.7363
2846.52	64.7436
2849.16	73.6149
2851.8	82.3918
2854.44	91.0219
2857.08	99.9102
2859.71	108.166
2862.35	116.259
2864.98	121.834
2867.62	127.322
2870.25	133.219
2872.88	137.554
2875.52	140.573
2878.15	143.516
2880.78	148.372
2883.41	152.515
2886.03	155.161
2888.66	158.074
2891.29	161.761
2893.91	165.374
2896.54	168.948
2899.16	172.621
2901.78	178.162
2904.4	182.779
2907.02	190.264
2909.64	199.248
2912.26	209.619
2914.88	219.734
2917.5	229.261
2920.11	237.693
2922.73	245.432
2925.34	251.595
2927.96	256.307
2930.57	259.18
2933.18	260.279
2935.79	259.629
2938.4	257.362
2941.01	253.589
2943.62	248.658
2946.22	241.339
2948.83	233.231
2951.43	224.34
2954.04	215.57
2956.64	205.571
2959.24	196.427
2961.84	186.542
2964.45	177.328
2967.05	168.967
2969.64	160.486
2972.24	152.575
2974.84	145.087
2977.43	137.182
2980.03	128.271
2982.62	118.967
2985.22	110.812
2987.81	102.625
2990.4	94.1629
2992.99	85.7812
2995.58	76.6673
2998.17	69.6285
3000.76	62.3305
3003.34	55.3162
3005.93	49.6045
3008.52	44.0015
3011.1	38.6043
3013.68	33.2032
3016.27	30.6379
3018.85	28.2989
3021.43	26.6736
3024.01	25.3783
3026.59	23.9874
3029.16	22.856
3031.74	21.7698
3034.32	21.0735
3036.89	21.3616
3039.47	21.8753
3042.04	22.2534
3044.61	22.3643
3047.18	23.7789
3049.75	23.9154
3052.32	23.0005
3054.89	23.1892
3057.46	22.1145
3060.03	20.8018
3062.59	19.4944
3065.16	19.1925
3067.72	18.9185
3070.29	18.7018
3072.85	16.8234
3075.41	15.713
3077.97	14.6447
3080.53	14.199
3083.09	12.3846
3085.65	10.6282
3088.21	8.23027
3090.76	6.74018
3093.32	5.71985
3095.87	4.64334
3098.43	4.18525
3100.98	3.91002
3103.53	3.57613
3106.08	3.04377
3108.63	3.47561
3111.18	1.85779
3113.73	0.376131
3116.28	-0.112015
3118.83	-0.503772
3121.37	-1.59638
3123.92	-1.97707
3126.46	-1.37348
3129	-0.917445
3131.55	-1.24506
3134.09	-0.876373
3136.63	-1.04398
3139.17	-1.2125
3141.71	-1.29335
3144.24	-1.50116
3146.78	-1.50405
3149.32	0.569282