File: data/Raman/poly_smoothed/Thy_30_10_19_1x_45s_532 nm_x100_100%_600 gr_mm_01.txt
#Acq. time (s)=	45
#Accumulations=	2
#Range (cm-¹)=	200...3150
#Windows=	2
#Auto scanning=	Off
#Autofocus=	Off
#Macrospot=	Off
#AutoExposure=	Off
#Spike filter=	Multiple accum.
#Delay time (s)=	0
#Binning=	1
#Readout mode=	Signal
#DeNoise=	Off
#ICS correction=	On
#Dark correction=	Off
#Inst. Process=	Off
#Detector Gain=	Best Dynamic Range
#Detector ADC=	20 kHz
#Detector temperature (°C)=	-69.85
#Instrument=	LabRAM HR Evol
#Detector=	Synapse
#Objective=	x100
#Grating=	600 gr/mm
#ND Filter=	100%
#Laser (nm)=	532
#Hole=	100.021
#Range=	Auto
#Laser Pol.=	No
#Raman. Pol.=	No
#Laser Pol. (°)=	-0.0007625
#Raman Pol. (°)=	89.9995
#Collection=	Microscope
#StageXY=	Marzhauser
#StageZ=	Marzhauser
#X (µm)=	4765.5
#Y (µm)=	-7731.1
#Z (µm)=	584.55
#Full time(mm:ss)=	3:18
#Project=
#Sample=
#Site=
#Title=	Thy_30_10_19_2x_45s_532 nm_x100_100%_600 gr_mm
#Remark=
#Date=	30.06.2022 12:49
#Acquired=	30.06.2022 12:49:45
#Base:Fit=	10.08.2022 09:58:11
#Base:Sub=	10.08.2022 09:58:44
#Filter:Polynom=	16.08.2022 10:22:53
#AxisType[0]=Intens
#AxisUnit[0]=Cnt
#AxisType[1]=Spectr
#AxisUnit[1]=1/cm
200.533	7.32043
204.162	9.62656
207.792	9.27345
211.418	8.67606
215.044	8.92684
218.667	9.04733
222.289	9.00678
225.912	9.36645
229.531	10.3652
233.148	10.874
236.766	10.8309
240.381	11.6014
243.994	10.1954
247.606	8.94695
251.217	8.03518
254.828	7.45485
258.436	6.84461
262.042	6.86031
265.647	5.68332
269.25	3.29326
272.852	2.87566
276.453	2.84714
280.052	2.08597
283.65	1.25945
287.247	0.282737
290.842	1.18435
294.436	2.47186
298.028	4.29044
301.617	6.51878
305.206	8.23948
308.794	9.77727
312.381	9.63178
315.964	11.8001
319.548	13.1076
323.131	14.3995
326.71	16.2426
330.29	16.9746
333.868	17.4311
337.443	18.08
341.018	18.7896
344.591	17.7477
348.163	17.2061
351.733	14.8654
355.303	13.7045
358.869	13.3921
362.435	12.9582
366.001	11.1685
369.563	10.4591
373.124	9.7454
376.686	9.90233
380.244	9.96267
383.801	10.1937
387.357	11.6754
390.911	10.9917
394.466	11.3967
398.018	11.8612
401.568	11.0605
405.117	11.7541
408.664	12.7524
412.21	14.1537
415.755	16.5362
419.298	16.9756
422.84	16.2805
426.38	15.7664
429.919	14.4574
433.455	13.2688
436.992	13.4309
440.527	13.4455
444.06	12.3559
447.593	11.6127
451.122	10.3996
454.651	10.1805
458.18	11.0351
461.705	12.7928
465.23	14.9689
468.752	16.3233
472.275	18.8098
475.797	18.8922
479.315	20.5276
482.834	21.8009
486.349	24.0869
489.863	25.1556
493.378	27.4397
496.889	30.8312
500.401	33.1341
503.91	34.6959
507.417	33.7931
510.923	32.6352
514.43	32.4272
517.933	33.3332
521.435	32.4783
524.936	31.7056
528.435	29.9046
531.933	28.0975
535.43	26.5435
538.927	25.2906
542.421	24.9731
545.913	23.9256
549.403	21.3397
552.893	18.5827
556.381	15.9631
559.868	14.4161
563.354	10.5686
566.839	9.46134
570.322	8.1263
573.802	5.91276
577.283	4.78694
580.762	4.78134
584.24	3.66144
587.714	2.88363
591.19	1.27448
594.663	-0.092201
598.134	0.134708
601.605	1.62255
605.073	3.13442
608.542	4.56274
612.007	6.26558
615.473	8.0796
618.936	9.11841
622.397	10.7979
625.859	13.266
629.318	15.791
632.775	15.4667
636.233	16.9286
639.688	19.0582
643.142	20.2516
646.594	21.9622
650.045	22.8099
653.496	24.3703
656.944	24.6277
660.391	25.7971
663.837	27.1516
667.281	26.2085
670.724	27.4583
674.166	26.9181
677.606	27.9265
681.045	28.5103
684.483	28.9687
687.917	30.0449
691.352	31.0661
694.786	31.2605
698.219	32.8958
701.65	33.4235
705.078	34.0499
708.506	35.4651
711.934	36.1222
715.358	36.2928
718.782	37.8913
722.204	39.4474
725.626	41.9765
729.045	43.7191
732.464	46.5326
735.881	47.6978
739.297	50.0293
742.711	53.747
746.125	57.5476
749.537	60.3838
752.946	64.6687
756.357	67.0974
759.764	70.0648
763.17	73.0074
766.575	73.4277
769.978	75.772
773.382	77.2481
776.783	79.8008
780.182	82.0479
783.581	82.7644
786.978	82.7439
790.373	83.5437
793.768	83.131
797.161	83.3728
800.552	82.8631
803.941	82.3438
807.33	82.3003
810.718	82.0985
814.105	82.9528
817.49	83.0886
820.873	84.7466
824.256	87.2361
827.637	88.3185
831.016	89.2177
834.395	88.7261
837.772	87.862
841.147	86.0113
844.522	84.6027
847.894	81.7371
851.267	79.0792
854.637	76.7929
858.007	74.158
861.374	72.0622
864.739	69.5578
868.106	67.5292
871.469	65.7232
874.831	63.7039
878.193	60.7706
881.553	59.0241
884.911	56.162
888.268	53.6154
891.623	51.5116
894.978	53.5525
898.331	55.5609
901.683	54.7803
905.033	54.5734
908.383	55.2488
911.731	55.0355
915.078	54.3637
918.423	52.7777
921.768	51.1674
925.111	50.936
928.452	50.4565
931.791	48.944
935.13	47.7621
938.468	47.928
941.803	47.0656
945.139	45.8746
948.473	43.9161
951.804	45.8917
955.136	46.3499
958.465	46.0087
961.794	47.0975
965.12	48.0138
968.447	50.0393
971.771	52.3655
975.095	55.0207
978.417	57.9918
981.737	59.7498
985.057	62.4755
988.375	63.7231
991.691	64.8771
995.006	65.05
998.32	65.4387
1001.63	66.3746
1004.95	68.1271
1008.26	66.9198
1011.56	67.0791
1014.87	66.5618
1018.18	65.223
1021.48	62.6397
1024.79	60.4991
1028.09	59.9747
1031.39	59.8044
1034.69	59.3796
1037.99	58.0131
1041.29	56.1114
1044.58	54.2039
1047.88	53.0872
1051.17	51.7526
1054.46	50.5553
1057.75	48.4159
1061.04	45.2126
1064.33	43.1995
1067.62	38.5792
1070.9	36.6087
1074.19	33.6885
1077.47	32.1658
1080.76	31.713
1084.04	29.3308
1087.32	28.8739
1090.59	27.3935
1093.87	27.88
1097.15	28.0273
1100.42	27.0339
1103.69	26.522
1106.97	28.1397
1110.24	28.2437
1113.51	28.6364
1116.77	28.342
1120.04	26.314
1123.31	24.4903
1126.57	23.1701
1129.83	21.8724
1133.1	19.7656
1136.36	16.7936
1139.62	14.5194
1142.87	11.8524
1146.13	10.5213
1149.38	8.13866
1152.64	7.07836
1155.89	4.4971
1159.14	3.12979
1162.39	2.0483
1165.64	1.32584
1168.89	0.623266
1172.14	2.18221
1175.38	2.44921
1178.63	2.41899
1181.87	4.30136
1185.11	7.63192
1188.35	7.32388
1191.59	9.43446
1194.83	11.1533
1198.07	11.9691
1201.3	15.3467
1204.53	19.4957
1207.77	22.4429
1211	27.3879
1214.23	32.1196
1217.46	36.9074
1220.69	40.9749
1223.91	46.7053
1227.14	48.8713
1230.36	52.8428
1233.59	57.8553
1236.81	61.6385
1240.03	66.8986
1243.25	71.4462
1246.46	74.9466
1249.68	77.8649
1252.9	80.1814
1256.11	81.5735
1259.32	84.1666
1262.54	86.4433
1265.75	88.8581
1268.96	90.4072
1272.16	91.4668
1275.37	93.3109
1278.57	94.5495
1281.78	95.6105
1284.98	96.6738
1288.18	97.2152
1291.38	98.1351
1294.58	97.7702
1297.78	95.6755
1300.98	97.3345
1304.17	97.2025
1307.37	97.6009
1310.56	99.8708
1313.76	99.6107
1316.95	99.9842
1320.14	99.9174
1323.32	98.5076
1326.51	96.7138
1329.7	93.5063
1332.88	91.3709
1336.07	88.8858
1339.25	86.1769
1342.43	82.7631
1345.61	79.4808
1348.79	75.091
1351.96	70.7892
1355.14	66.8898
1358.31	61.3636
1361.49	57.8959
1364.66	52.7042
1367.83	48.7281
1371	43.7959
1374.17	39.6003
1377.34	38.7464
1380.5	37.7653
1383.67	33.9921
1386.83	32.6627
1390	32.1701
1393.16	32.0481
1396.32	29.5721
1399.48	29.1209
1402.64	27.9032
1405.79	28.9976
1408.95	30.5809
1412.1	34.1383
1415.26	38.1714
1418.41	41.7764
1421.56	47.8631
1424.71	56.8084
1427.86	66.427
1431	75.0453
1434.15	83.4043
1437.29	91.3242
1440.44	98.0746
1443.58	100.625
1446.72	104.095
1449.86	102.609
1453	102.356
1456.14	98.7752
1459.27	93.3113
1462.41	88.5308
1465.54	81.3225
1468.67	72.9365
1471.81	61.9468
1474.94	49.5431
1478.07	39.4741
1481.19	30.7072
1484.32	21.6928
1487.45	15.3161
1490.57	10.4995
1493.69	5.78886
1496.82	2.51142
1499.94	1.65894
1503.06	1.53299
1506.17	2.67821
1509.29	2.88119
1512.41	1.8817
1515.52	1.88596
1518.64	2.72912
1521.75	3.04757
1524.86	5.17657
1527.97	6.75871
1531.08	10.1079
1534.19	12.691
1537.29	14.0694
1540.4	18.7388
1543.5	21.9137
1546.61	24.7432
1549.71	28.4457
1552.81	32.5058
1555.91	38.6102
1559.01	41.4631
1562.11	45.8654
1565.2	50.2328
1568.29	53.5695
1571.39	55.3172
1574.48	58.5958
1577.57	61.7827
1580.66	65.4454
1583.75	68.8505
1586.84	68.3006
1589.93	70.4508
1593.01	72.1534
1596.1	75.1496
1599.18	74.7737
1602.26	76.0542
1605.34	75.3642
1608.42	75.7265
1611.5	76.6429
1614.58	78.3367
1617.65	81.7787
1620.73	82.7173
1623.8	86.2572
1626.87	90.7246
1629.95	95.707
1633.02	99.8636
1636.09	104.273
1639.15	111.496
1642.22	117.588
1645.29	122.416
1648.35	128.767
1651.42	132.479
1654.48	136.914
1657.54	138.364
1660.6	136.764
1663.66	134.394
1666.72	130.761
1669.77	125.999
1672.83	117.761
1675.88	109.546
1678.93	100.082
1681.99	90.251
1685.04	80.9207
1688.09	70.7342
1691.13	59.7543
1694.18	50.9613
1697.23	43.1479
1700.27	36.6931
1703.32	30.4152
1706.36	25.1134
1709.4	21.414
1712.44	19.1579
1715.48	17.6019
1718.52	15.3486
1721.56	12.8524
1724.59	12.6187
1727.63	11.9586
1730.66	10.9987
1733.69	10.7299
1736.72	10.7448
1739.75	9.79314
1742.78	9.37332
1745.81	8.93172
1748.84	7.4546
1751.86	6.61581
1754.89	5.26334
1757.91	4.37943
1760.93	4.15857
1763.95	2.54731
1766.97	1.2715
1769.99	0.957594
1773.01	0.527446
1776.03	0.713982
1779.04	0.521352
1782.06	0.884983
1785.07	1.8595
1788.08	2.30492
1791.09	1.86512
1794.1	1.50222
1797.11	1.73147
1800.12	1.84597
1803.12	2.60642
1806.13	2.87743
1809.13	3.5027
1812.14	3.60909
1815.14	3.07325
1818.14	3.21985
1821.14	3.18256
1824.14	3.02685
1827.13	3.63275
1830.13	2.85974
1833.12	3.55036
1836.12	4.01653
1839.11	3.61339
1842.1	4.68969
1845.09	5.60344
1848.08	6.38365
1851.07	7.40656
1854.06	8.87375
1857.04	10.2185
1860.03	10.5062
1863.01	10.5333
1866	10.0068
1868.98	10.1652
1871.96	10.1791
1874.94	11.5333
1877.92	11.4329
1880.89	11.654
1882.48	12.391
1885.47	13.6989
1888.46	13.2578
1891.44	14.9895
1894.43	14.9953
1897.41	15.0374
1900.4	15.8328
1903.38	16.278
1906.36	17.5646
1909.34	17.8018
1912.32	19.2411
1915.29	20.2037
1918.27	19.4907
1921.25	19.958
1924.22	19.8507
1927.2	20.2434
1930.17	19.5823
1933.14	18.2963
1936.11	17.8159
1939.08	17.8328
1942.05	18.0618
1945.01	18.7413
1947.98	19.5948
1950.94	19.823
1953.91	20.8887
1956.87	21.6658
1959.83	21.5239
1962.79	20.7992
1965.75	21.4255
1968.71	21.1165
1971.67	21.8116
1974.62	22.7622
1977.58	22.5734
1980.53	22.646
1983.48	22.3942
1986.43	20.8362
1989.38	20.2418
1992.33	20.9016
1995.28	20.7164
1998.23	21.1249
2001.18	20.6992
2004.12	21.4639
2007.06	22.3963
2010.01	22.4215
2012.95	23.221
2015.89	23.541
2018.83	25.0755
2021.77	25.5032
2024.71	26.6594
2027.64	26.3947
2030.58	27.6521
2033.51	28.09
2036.45	28.6984
2039.38	29.1263
2042.31	29.2785
2045.24	29.8554
2048.17	30.7143
2051.1	30.2511
2054.02	29.6015
2056.95	30.1318
2059.87	30.6521
2062.8	32.2942
2065.72	33.4544
2068.64	34.9131
2071.56	35.2702
2074.48	36.3509
2077.4	38.2745
2080.31	40.4115
2083.23	41.3811
2086.14	43.6416
2089.06	44.5294
2091.97	46.0382
2094.88	48.4171
2097.79	50.1622
2100.7	52.0143
2103.61	54.4758
2106.52	58.0122
2109.43	61.6702
2112.33	66.2452
2115.24	70.2158
2118.14	74.51
2121.04	78.9718
2123.94	83.1921
2126.84	88.4746
2129.74	93.9211
2132.64	100.33
2135.54	105.551
2138.43	112.013
2141.33	118.009
2144.22	123.625
2147.11	129.646
2150.01	135.383
2152.9	140.008
2155.79	143.189
2158.67	146.464
2161.56	148.736
2164.45	151.379
2167.33	154.127
2170.22	155.934
2173.1	155.86
2175.98	156.458
2178.86	156.062
2181.74	154.158
2184.62	151.963
2187.5	148.674
2190.38	144.216
2193.25	139.892
2196.13	134.436
2199	128.745
2201.88	123.839
2204.75	118.695
2207.62	113.348
2210.49	107.962
2213.36	102.518
2216.22	96.7353
2219.09	90.8
2221.96	85.5871
2224.82	80.9297
2227.68	75.5908
2230.55	71.5838
2233.41	68.1451
2236.27	65.4387
2239.12	62.117
2241.98	58.1441
2244.84	57.391
2247.7	56.0056
2250.55	54.2196
2253.41	52.9194
2256.26	51.7132
2259.11	49.0116
2261.96	49.4851
2264.81	48.7725
2267.66	47.1654
2270.51	46.1283
2273.35	45.845
2276.2	45.5124
2279.04	44.469
2281.89	42.7252
2284.73	40.4654
2287.57	37.6124
2290.41	34.4491
2293.25	31.6329
2296.09	29.7803
2298.93	27.7923
2301.76	28.0137
2304.6	28.7005
2307.44	27.8808
2310.27	27.8575
2313.1	26.991
2315.93	27.5354
2318.76	26.7816
2321.59	25.9697
2324.42	25.9241
2327.25	27.0716
2330.07	27.9753
2332.9	27.6037
2335.72	25.8853
2338.55	24.916
2341.37	24.5686
2344.19	23.603
2347.01	21.6027
2349.83	19.4869
2352.65	18.471
2355.46	15.6401
2358.28	14.0607
2361.09	13.3449
2363.91	13.0688
2366.72	12.5354
2369.53	12.9558
2372.34	13.015
2375.15	13.7683
2377.96	13.7026
2380.77	13.8954
2383.58	14.8355
2386.38	15.5854
2389.19	15.8121
2391.99	16.1862
2394.8	16.3575
2397.6	16.3287
2400.4	15.6624
2403.2	15.5997
2406	15.3995
2408.79	16.3465
2411.59	16.3659
2414.39	16.4615
2417.18	15.6138
2419.98	16.1596
2422.77	15.9492
2425.56	14.7201
2428.35	14.8232
2431.14	14.2646
2433.93	13.6657
2436.72	12.5633
2439.5	12.3333
2442.29	12.9711
2445.07	12.5733
2447.86	12.32
2450.64	11.2361
2453.42	10.7556
2456.2	9.62645
2458.98	9.7358
2461.76	9.12242
2464.54	9.07093
2467.32	8.96117
2470.09	10.0726
2472.87	10.5307
2475.64	10.3671
2478.41	9.93494
2481.18	9.17185
2483.95	8.56745
2486.72	8.00857
2489.49	7.90176
2492.26	7.55427
2495.03	6.13074
2497.79	5.33399
2500.56	4.57838
2503.32	2.49669
2506.09	2.59273
2508.85	2.07383
2511.61	1.45648
2514.37	-0.28923
2517.13	-0.476644
2519.89	-0.0975136
2522.64	0.264158
2525.4	0.198516
2528.15	0.983118
2530.91	1.15505
2533.66	1.98131
2536.41	4.00544
2539.16	3.74946
2541.91	3.67309
2544.66	4.1316
2547.41	3.53735
2550.16	4.34023
2552.9	4.48372
2555.65	4.3404
2558.39	4.4919
2561.13	3.98291
2563.88	3.85209
2566.62	3.17968
2569.36	3.43056
2572.1	3.95556
2574.84	3.16643
2577.57	3.13959
2580.31	2.37734
2583.05	2.87387
2585.78	2.79993
2588.51	2.84663
2591.24	2.27669
2593.98	1.2447
2596.71	0.962758
2599.44	0.0533901
2602.16	-0.0980996
2604.89	-1.73884
2607.62	-3.01815
2610.34	-3.27687
2613.07	-2.71648
2615.79	-3.07536
2618.52	-2.6875
2621.24	-2.85324
2623.96	-2.98623
2626.68	-2.12196
2629.4	-1.37069
2632.11	-1.23896
2634.83	-0.357874
2637.55	0.262491
2640.26	1.73036
2642.98	1.5705
2645.69	2.22617
2648.4	2.0503
2651.11	2.57571
2653.82	2.62464
2656.53	1.86985
2659.24	1.98707
2661.95	1.29423
2664.65	1.00279
2667.36	0.598445
2670.06	0.734566
2672.76	0.292834
2675.47	0.868154
2678.17	0.97216
2680.87	0.683519
2683.57	0.564203
2686.27	0.983937
2688.97	1.05538
2691.66	1.5134
2694.36	2.58262
2697.05	3.52366
2699.75	3.16761
2702.44	4.45119
2705.13	4.87413
2707.82	6.02038
2710.51	5.49354
2713.2	5.77882
2715.89	6.72628
2718.57	7.58423
2721.26	8.81007
2723.95	9.39333
2726.63	9.7834
2729.31	10.4622
2732	10.7092
2734.68	10.8652
2737.36	11.196
2740.04	10.1388
2742.72	8.94535
2745.39	8.24886
2748.07	6.7616
2750.75	5.93408
2753.42	5.74822
2756.09	5.38162
2758.77	4.30243
2761.44	2.97869
2764.11	2.32156
2766.78	1.67696
2769.45	1.25693
2772.12	0.955075
2774.78	0.156016
2777.45	-0.285066
2780.12	-0.424632
2782.78	0.363205
2785.44	-0.269201
2788.11	1.0137
2790.77	0.95925
2793.43	1.42672
2796.09	1.36322
2798.75	1.39172
2801.4	1.09418
2804.06	1.26273
2806.72	-0.125866
2809.37	0.264212
2812.03	-0.408222
2814.68	-1.35312
2817.33	0.399827
2819.98	2.66144
2822.63	6.89681
2825.28	11.4229
2827.93	18.2347
2830.58	25.2062
2833.23	32.812
2835.87	41.8915
2838.52	50.4107
2841.16	60.6839
2843.8	71.0795
2846.44	84.3494
2849.08	98.4642
2851.73	114.923
2854.36	131.949
2857	146.916
2859.64	163.05
2862.28	177.705
2864.91	191.708
2867.55	205.303
2870.18	216.833
2872.81	226.437
2875.44	235.243
2878.07	243.834
2880.7	252.505
2883.33	259.773
2885.96	266.611
2888.59	274.323
2891.21	280.997
2893.84	288.283
2896.46	295.586
2899.09	304.527
2901.71	315.874
2904.33	328.483
2906.95	346.306
2909.57	364.987
2912.19	386.614
2914.81	407.405
2917.43	427.509
2920.04	445.355
2922.66	460.924
2925.27	474.29
2927.88	483.501
2930.5	490.231
2933.11	493.171
2935.72	491.877
2938.33	485.933
2940.94	479.209
2943.54	466.714
2946.15	451.653
2948.76	435.127
2951.36	417.386
2953.97	398.28
2956.57	379.114
2959.17	359.605
2961.77	339.597
2964.37	323.106
2966.97	307.568
2969.57	292.362
2972.17	276.854
2974.77	260.686
2977.36	245.749
2979.96	230.043
2982.55	214.532
2985.15	197.918
2987.74	181.912
2990.33	166.169
2992.92	150.989
2995.51	137.013
2998.1	124.488
3000.69	111.588
3003.27	100.952
3005.86	89.5856
3008.44	78.9547
3011.03	69.8396
3013.61	61.6856
3016.19	55.7766
3018.78	51.0952
3021.36	45.9058
3023.94	41.9143
3026.51	40.3529
3029.09	38.0195
3031.67	37.2313
3034.24	36.6469
3036.82	36.7111
3039.39	37.4975
3041.97	38.3332
3044.54	38.455
3047.11	39.434
3049.68	39.9428
3052.25	41.9557
3054.82	42.4747
3057.39	42.509
3059.96	42.979
3062.52	42.0542
3065.09	39.9903
3067.65	37.4425
3070.22	34.4737
3072.78	31.7468
3075.34	28.64
3077.9	25.5948
3080.46	22.7737
3083.02	19.4844
3085.58	16.4613
3088.14	13.5137
3090.69	11.9714
3093.25	10.739
3095.8	9.80792
3098.36	8.95124
3100.91	8.30316
3103.46	6.91638
3106.01	5.74233
3108.56	4.83902
3111.11	5.01264
3113.66	4.40389
3116.21	3.83055
3118.76	3.32614
3121.3	2.72592
3123.85	1.75927
3126.39	1.9131
3128.93	1.00544
3131.48	0.536788
3134.02	0.506653
3136.56	0.333
3139.1	-0.0649708
3141.64	-0.648006
3144.17	-0.221937
3146.71	0.577598
3149.25	1.90149