File: data/Raman/poly_smoothed/Thy_10_08_04_1x_45s_532 nm_x100_100%_600 gr_mm_01.txt
#Acq. time (s)=	45
#Accumulations=	2
#Range (cm-¹)=	200...3150
#Windows=	2
#Auto scanning=	Off
#Autofocus=	Off
#Macrospot=	Off
#AutoExposure=	Off
#Spike filter=	Multiple accum.
#Delay time (s)=	0
#Binning=	1
#Readout mode=	Signal
#DeNoise=	Off
#ICS correction=	On
#Dark correction=	Off
#Inst. Process=	Off
#Detector Gain=	Best Dynamic Range
#Detector ADC=	20 kHz
#Detector temperature (°C)=	-69.62
#Instrument=	LabRAM HR Evol
#Detector=	Synapse
#Objective=	x100
#Grating=	600 gr/mm
#ND Filter=	100%
#Laser (nm)=	532
#Hole=	100.021
#Range=	Auto
#Laser Pol.=	No
#Raman. Pol.=	No
#Laser Pol. (°)=	-0.0007625
#Raman Pol. (°)=	89.9995
#Collection=	Microscope
#StageXY=	Marzhauser
#StageZ=	Marzhauser
#X (µm)=	2158.6
#Y (µm)=	1221.6
#Z (µm)=	442.15
#Full time(mm:ss)=	3:18
#Project=
#Sample=
#Site=
#Title=	Thy_10_08_04_2x_45s_532 nm_x100_100%_600 gr_mm
#Remark=
#Date=	05.07.2022 14:29
#Acquired=	05.07.2022 14:29:03
#Base:Fit=	10.08.2022 09:45:33
#Base:Fit=	10.08.2022 09:46:03
#Base:Fit=	10.08.2022 09:46:25
#Base:Sub=	10.08.2022 09:46:49
#Filter:Polynom=	16.08.2022 10:24:56
#AxisType[0]=Intens
#AxisUnit[0]=Cnt
#AxisType[1]=Spectr
#AxisUnit[1]=1/cm
200.43	21.1612
204.059	16.1787
207.688	13.3521
211.314	10.22
214.941	8.17581
218.564	4.88328
222.186	3.21107
225.809	2.72382
229.428	2.2787
233.045	2.45416
236.663	3.29941
240.278	2.88023
243.891	2.7139
247.503	2.96423
251.116	2.06281
254.725	4.31286
258.333	7.06839
261.939	8.94026
265.544	10.7578
269.148	10.8409
272.75	12.0932
276.351	13.5713
279.95	14.1264
283.548	14.5852
287.144	15.428
290.739	16.1044
294.333	17.6406
297.925	18.3364
301.514	19.3093
305.104	18.628
308.692	19.6166
312.279	19.9045
315.862	19.5457
319.446	18.7051
323.029	18.5642
326.608	16.2458
330.188	15.6253
333.766	15.0741
337.341	14.3213
340.917	14.3757
344.489	15.296
348.062	14.2435
351.631	15.8283
355.201	14.2571
358.768	13.9004
362.333	13.4897
365.899	12.263
369.462	11.9056
373.023	10.769
376.585	11.771
380.143	12.1137
383.7	11.8399
387.256	11.7018
390.812	12.0493
394.365	13.0303
397.916	12.7203
401.467	11.2506
405.015	10.9611
408.563	11.6359
412.109	13.3276
415.654	12.3496
419.197	13.77
422.739	13.7306
426.279	11.9375
429.819	12.8797
433.356	12.7089
436.891	11.7625
440.426	11.3288
443.96	9.27638
447.492	7.83345
451.021	5.69768
454.551	5.41896
458.079	5.32024
461.604	5.0798
465.13	5.9285
468.654	6.62485
472.175	7.20275
475.696	9.40186
479.215	11.0787
482.733	13.2695
486.249	14.0834
489.765	15.6869
493.278	17.7911
496.789	20.3319
500.301	21.2979
503.81	20.956
507.317	21.4621
510.825	21.1086
514.33	20.9027
517.833	21.2294
521.335	21.0487
524.836	20.1667
528.335	19.9258
531.835	17.5419
535.332	17.588
538.827	15.0305
542.321	14.3371
545.814	12.3402
549.305	10.8824
552.795	9.34035
556.282	9.14469
559.769	7.43526
563.255	7.22027
566.739	6.50729
570.223	4.65916
573.705	3.3607
577.183	2.9616
580.663	2.70762
584.141	2.39761
587.615	1.8557
591.09	0.302637
594.564	-0.0668791
598.035	0.00277656
601.506	0.142856
604.974	1.71596
608.443	1.90058
611.908	0.727877
615.374	0.91379
618.837	0.967485
622.3	1.19795
625.761	1.88708
629.219	2.92516
632.677	5.28425
636.135	6.82367
639.59	7.51923
643.043	8.98628
646.495	9.30514
649.948	10.7246
653.398	12.3626
656.846	13.4749
660.293	14.762
663.738	15.9059
667.183	17.751
670.626	18.6757
674.067	20.4222
677.508	21.3593
680.947	22.7677
684.385	23.7415
687.821	25.097
691.254	25.2926
694.688	26.2019
698.121	26.0237
701.552	26.1566
704.98	28.4792
708.409	29.7753
711.836	31.9393
715.26	33.2667
718.685	35.5145
722.108	36.7982
725.528	37.8846
728.949	39.1368
732.367	41.5041
735.785	43.0607
739.2	44.637
742.614	45.8555
746.028	48.3944
749.439	51.7189
752.849	54.3857
756.26	58.1202
759.667	60.7172
763.073	62.3318
766.477	64.4134
769.883	66.8875
773.285	68.883
776.686	69.2966
780.085	68.585
783.484	69.4249
786.881	72.4467
790.276	74.6268
793.671	75.7851
797.064	77.5082
800.456	78.4874
803.846	78.4253
807.234	77.4703
810.622	78.066
814.008	78.1384
817.394	76.2337
820.778	75.8403
824.159	75.453
827.541	76.4292
830.921	76.1945
834.298	75.1184
837.676	73.5059
841.051	73.9155
844.426	71.1341
847.798	70.3844
851.171	68.4155
854.54	65.3994
857.911	62.9513
861.278	59.8513
864.645	59.0062
868.01	58.7738
871.373	58.3161
874.735	57.5129
878.097	55.9312
881.457	54.36
884.815	53.3906
888.172	53.8672
891.528	53.4949
894.882	54.0313
898.237	53.7364
901.589	54.0594
904.94	54.251
908.289	54.7366
911.635	53.3984
914.982	52.638
918.328	52.4315
921.672	50.4988
925.015	49.6638
928.357	48.8567
931.698	46.5893
935.035	46.8489
938.373	44.4077
941.71	44.2189
945.044	43.7507
948.378	42.4747
951.709	41.1303
955.041	39.6892
958.372	38.4348
961.699	36.9611
965.027	39.2263
968.352	40.4791
971.676	42.0625
975	44.1126
978.322	44.6591
981.642	45.6011
984.962	46.2055
988.28	45.2119
991.596	43.9991
994.911	42.658
998.227	40.4452
1001.54	38.3862
1004.85	36.2683
1008.16	35.9111
1011.47	36.564
1014.78	36.2759
1018.08	34.9015
1021.39	31.9715
1024.69	29.5364
1028	26.7085
1031.3	24.3131
1034.6	21.4237
1037.9	20.0105
1041.19	19.6551
1044.49	20.8023
1047.78	20.7608
1051.08	18.8429
1054.37	19.8448
1057.66	19.2733
1060.95	16.7316
1064.24	12.93
1067.53	12.2132
1070.81	12.9658
1074.1	14.6812
1077.38	16.4482
1080.66	19.5032
1083.94	21.9496
1087.22	25.4256
1090.5	30.5173
1093.78	33.67
1097.05	35.9398
1100.33	36.6815
1103.6	37.6442
1106.87	38.7536
1110.14	37.5166
1113.41	36.7711
1116.68	36.0039
1119.95	33.6016
1123.21	30.082
1126.48	26.1288
1129.74	21.381
1133	16.4528
1136.26	12.5084
1139.52	6.41035
1142.78	0.639397
1146.04	0.912529
1149.29	1.55465
1152.55	1.40405
1155.8	0.957997
1159.05	-0.719576
1162.3	-1.64671
1165.55	-1.22616
1168.8	0.781012
1172.05	3.4583
1175.29	4.35927
1178.54	5.08672
1181.78	6.46009
1185.02	8.73426
1188.26	10.8364
1191.5	12.6001
1194.74	15.0367
1197.97	16.672
1201.21	18.0053
1204.44	22.1297
1207.68	24.3694
1210.91	29.0617
1214.14	32.714
1217.37	35.7076
1220.59	40.0325
1223.82	43.9214
1227.05	47.5623
1230.27	50.5145
1233.49	53.3715
1236.72	54.8483
1239.94	56.5986
1243.16	58.6186
1246.37	59.1682
1249.59	60.4343
1252.8	60.8814
1256.02	61.3101
1259.23	62.1126
1262.44	63.0944
1265.66	62.6198
1268.86	63.0602
1272.07	64.4176
1275.28	64.5607
1278.48	65.333
1281.69	67.092
1284.89	69.6503
1288.09	71.1852
1291.29	73.8336
1294.49	75.6939
1297.69	76.4582
1300.89	78.7457
1304.08	80.3728
1307.28	80.9818
1310.47	82.1485
1313.66	82.8402
1316.85	84.9329
1320.04	83.2109
1323.23	82.2125
1326.42	81.4321
1329.61	80.6432
1332.79	79.8965
1335.97	77.9723
1339.16	76.1239
1342.34	74.0793
1345.52	72.0138
1348.7	70.3872
1351.87	68.3476
1355.05	65.6802
1358.22	65.3375
1361.4	63.3695
1364.57	60.3867
1367.74	57.8245
1370.91	56.5927
1374.08	52.467
1377.25	50.0856
1380.41	47.7891
1383.58	46.0315
1386.74	43.3061
1389.91	42.6754
1393.07	41.9593
1396.23	40.3504
1399.39	39.1288
1402.55	37.137
1405.7	38.6269
1408.86	39.8636
1412.01	39.4293
1415.17	42.2147
1418.32	45.7747
1421.47	50.293
1424.62	55.3672
1427.77	63.2025
1430.91	69.9786
1434.06	76.1423
1437.2	79.419
1440.35	83.794
1443.49	86.8974
1446.63	89.411
1449.77	89.5368
1452.91	87.6221
1456.05	85.4318
1459.18	82.5098
1462.32	78.8093
1465.45	73.7608
1468.59	69.5936
1471.72	62.8774
1474.85	56.1806
1477.98	49.7183
1481.1	42.7505
1484.23	36.2321
1487.36	30.1212
1490.48	25.5093
1493.61	22.3325
1496.73	18.2732
1499.85	17.7545
1502.97	16.8283
1506.09	16.8041
1509.2	16.567
1512.32	16.7686
1515.43	16.6572
1518.55	17.0231
1521.66	16.6563
1524.77	16.8664
1527.88	17.1634
1530.99	19.2291
1534.1	20.4883
1537.21	21.2512
1540.31	24.1264
1543.42	26.7744
1546.52	30.0027
1549.62	34.0642
1552.72	38.2077
1555.82	41.1089
1558.92	45.3199
1562.02	48.3315
1565.11	50.9384
1568.21	53.29
1571.3	57.4991
1574.39	60.3675
1577.49	64.0776
1580.57	66.5083
1583.66	69.4178
1586.75	71.1275
1589.84	71.6653
1592.92	71.9094
1596.01	72.0601
1599.09	71.2402
1602.17	70.3467
1605.25	68.8894
1608.33	66.1679
1611.41	63.5644
1614.49	61.9111
1617.57	61.3682
1620.64	60.664
1623.72	61.5416
1626.79	61.7273
1629.86	63.6366
1632.93	64.8798
1636	66.777
1639.07	68.9747
1642.13	71.1884
1645.2	72.9842
1648.26	76.117
1651.33	78.4753
1654.39	81.3141
1657.45	82.1089
1660.51	82.3136
1663.57	82.1299
1666.63	82.4306
1669.68	81.2144
1672.74	79.2378
1675.79	76.1222
1678.85	70.5839
1681.9	64.9526
1684.95	59.4304
1688	53.8623
1691.05	47.3616
1694.09	41.1612
1697.14	35.6881
1700.18	29.8869
1703.23	25.1125
1706.27	21.0557
1709.31	17.2788
1712.35	14.2354
1715.39	10.8506
1718.43	7.86885
1721.47	6.62314
1724.5	4.68093
1727.54	4.4791
1730.57	3.05039
1733.61	1.91872
1736.64	1.7408
1739.67	2.76269
1742.7	2.13506
1745.72	2.20608
1748.75	2.72494
1751.77	2.24555
1754.8	1.81507
1757.82	1.1532
1760.84	0.351011
1763.87	-0.892452
1766.89	-1.08112
1769.91	-1.53553
1772.92	-1.88992
1775.94	-2.203
1778.95	-1.39132
1781.97	-0.403763
1784.98	-0.716112
1787.99	-0.633688
1791.01	0.81809
1794.01	2.03224
1797.02	3.35139
1800.03	3.83838
1803.04	4.95668
1806.04	5.23488
1809.05	4.76878
1812.05	5.51322
1815.05	5.51347
1818.05	6.28633
1821.05	8.31076
1824.05	8.77493
1827.05	8.27848
1830.04	7.31634
1833.04	6.70894
1836.03	7.24076
1839.03	7.14444
1842.02	6.81027
1845.01	6.09084
1848	6.11849
1850.99	6.69895
1853.97	7.34184
1856.96	7.81599
1859.94	9.03086
1862.93	9.36513
1865.91	9.89416
1868.89	10.9777
1871.87	11.7896
1874.85	12.4435
1877.83	14.2929
1880.81	14.8272
1882.57	15.5202
1885.56	15.7945
1888.55	16.8325
1891.54	17.438
1894.52	16.378
1897.51	15.0798
1900.49	13.8947
1903.47	13.5479
1906.45	13.7768
1909.43	14.2148
1912.41	14.2249
1915.39	13.78
1918.37	14.0492
1921.34	14.3411
1924.32	14.6853
1927.29	14.6759
1930.26	13.6147
1933.23	13.8761
1936.2	14.1862
1939.17	14.9058
1942.14	16.6076
1945.11	16.7814
1948.07	18.5296
1951.04	19.1654
1954	19.3682
1956.96	18.8685
1959.93	18.0458
1962.89	18.7839
1965.85	17.6691
1968.8	17.786
1971.76	17.9664
1974.72	17.9579
1977.67	18.2738
1980.63	18.4327
1983.58	18.7795
1986.53	18.2792
1989.48	18.0667
1992.43	16.4287
1995.38	16.254
1998.32	15.5828
2001.27	14.2027
2004.22	13.6432
2007.16	14.3505
2010.1	14.1568
2013.04	14.0248
2015.98	15.6178
2018.92	16.4135
2021.86	16.5878
2024.8	16.6237
2027.74	16.8826
2030.67	17.4199
2033.61	17.6968
2036.54	18.1371
2039.47	18.9094
2042.4	18.9557
2045.33	19.084
2048.26	18.1734
2051.19	17.9942
2054.12	18.5125
2057.04	17.812
2059.97	17.1429
2062.89	17.2492
2065.81	15.8976
2068.73	16.5594
2071.65	15.4954
2074.57	16.0246
2077.49	15.8077
2080.41	15.8693
2083.32	16.9776
2086.24	16.459
2089.15	16.9983
2092.07	16.7609
2094.98	17.8618
2097.89	18.2092
2100.8	18.9975
2103.71	18.2527
2106.61	17.9744
2109.52	19.0172
2112.43	18.9298
2115.33	19.7118
2118.23	20.429
2121.13	20.9241
2124.04	21.8858
2126.94	22.7866
2129.83	23.0177
2132.73	23.6353
2135.63	24.3468
2138.53	25.8557
2141.42	26.8367
2144.31	27.2544
2147.21	27.928
2150.1	29.3301
2152.99	31.1602
2155.88	32.1828
2158.77	32.956
2161.65	34.9645
2164.54	36.1142
2167.43	37.2305
2170.31	38.3167
2173.19	37.6061
2176.07	38.9607
2178.96	39.4953
2181.84	40.7647
2184.72	40.3606
2187.59	40.3405
2190.47	40.8488
2193.35	40.1689
2196.22	39.3127
2199.09	38.601
2201.97	36.894
2204.84	36.6252
2207.71	36.0586
2210.58	35.0177
2213.45	32.3463
2216.31	31.0708
2219.18	30.4812
2222.05	29.3606
2224.91	28.6145
2227.78	26.7233
2230.64	25.5299
2233.5	23.9931
2236.36	22.5773
2239.22	21.9886
2242.08	19.5836
2244.93	18.3592
2247.79	18.0247
2250.64	17.0685
2253.5	15.9568
2256.35	15.3707
2259.2	15.3065
2262.05	15.3111
2264.9	14.014
2267.75	14.9233
2270.6	14.7404
2273.45	14.6067
2276.29	14.5735
2279.14	14.4961
2281.98	13.6409
2284.82	13.5878
2287.66	14.245
2290.5	14.19
2293.34	13.6847
2296.18	12.7127
2299.02	12.09
2301.86	12.2383
2304.69	11.8737
2307.53	11.5057
2310.36	10.7823
2313.19	11.0502
2316.02	11.1165
2318.85	11.0986
2321.68	10.7562
2324.51	10.6673
2327.34	10.442
2330.16	11.1259
2332.99	11.0656
2335.81	11.2543
2338.64	10.8286
2341.46	10.1476
2344.28	10.1328
2347.1	9.85593
2349.92	9.56124
2352.74	9.4469
2355.55	9.62628
2358.37	9.75511
2361.19	9.21985
2364	9.74455
2366.81	10.8342
2369.62	10.831
2372.44	10.9053
2375.24	10.9046
2378.05	10.2949
2380.86	10.777
2383.67	10.9258
2386.47	10.2943
2389.28	10.0824
2392.08	10.3528
2394.89	10.4243
2397.69	9.60649
2400.49	9.42649
2403.29	8.66424
2406.09	6.6469
2408.88	5.24416
2411.68	4.20535
2414.48	3.78056
2417.27	3.5081
2420.06	2.81654
2422.86	3.08635
2425.65	2.70401
2428.44	3.08154
2431.23	3.4331
2434.02	4.25513
2436.81	4.59224
2439.59	4.74264
2442.38	5.53008
2445.16	4.86663
2447.95	5.49406
2450.73	5.83311
2453.51	6.14273
2456.29	6.36745
2459.07	6.1579
2461.85	7.62621
2464.63	7.21232
2467.4	6.15661
2470.18	5.42702
2472.95	4.37326
2475.73	4.54016
2478.5	4.89747
2481.27	5.07935
2484.04	5.78913
2486.81	5.9035
2489.58	4.91349
2492.35	5.22039
2495.12	5.01693
2497.88	4.08948
2500.65	3.70497
2503.41	4.04757
2506.17	3.93528
2508.94	3.0907
2511.7	1.70013
2514.46	1.25537
2517.22	0.340267
2519.97	0.707508
2522.73	0.853679
2525.49	1.0624
2528.24	1.73661
2530.99	1.86922
2533.75	1.50117
2536.5	2.13117
2539.25	2.77977
2542	2.9681
2544.75	3.25525
2547.5	3.45008
2550.24	3.87176
2552.99	4.90527
2555.74	4.92815
2558.48	4.22795
2561.22	3.96927
2563.96	4.22977
2566.71	4.66385
2569.45	5.87929
2572.18	6.21018
2574.92	5.97081
2577.66	5.25908
2580.4	5.09477
2583.13	5.33709
2585.87	4.81244
2588.6	5.33191
2591.33	5.73124
2594.06	5.5363
2596.79	5.10816
2599.52	5.87532
2602.25	5.31117
2604.98	3.42604
2607.71	3.28115
2610.43	2.44835
2613.16	2.41126
2615.88	1.77405
2618.6	1.48099
2621.32	1.00376
2624.04	0.571422
2626.76	-0.191924
2629.48	0.822017
2632.2	1.49144
2634.92	-0.0434787
2637.63	0.0114389
2640.35	0.348105
2643.06	0.0341532
2645.77	0.487139
2648.49	0.902813
2651.2	1.17801
2653.91	1.3663
2656.62	1.63164
2659.33	1.74121
2662.03	2.90412
2664.74	4.81214
2667.44	6.02162
2670.15	6.62554
2672.85	7.54285
2675.55	7.75561
2678.26	8.04955
2680.96	8.58149
2683.66	7.49946
2686.35	8.93278
2689.05	9.79934
2691.75	10.6965
2694.44	11.1667
2697.14	10.5855
2699.83	10.1694
2702.52	10.6223
2705.22	11.6597
2707.91	12.2703
2710.6	11.981
2713.29	12.7147
2715.97	13.6602
2718.66	14.0872
2721.35	14.3473
2724.03	16.0844
2726.72	16.8053
2729.4	17.3785
2732.08	16.7671
2734.76	16.5816
2737.44	15.7325
2740.12	15.4015
2742.8	15.0897
2745.48	15.7303
2748.16	15.5523
2750.83	16.0024
2753.51	16.3559
2756.18	15.7284
2758.85	14.934
2761.53	14.2465
2764.2	14.295
2766.87	15.0577
2769.54	15.3313
2772.2	15.4383
2774.87	14.5859
2777.54	14.7029
2780.2	14.9356
2782.87	15.1518
2785.53	15.0514
2788.19	15.5675
2790.85	14.2198
2793.51	13.4049
2796.17	13.2018
2798.83	12.8238
2801.49	13.484
2804.15	13.9162
2806.8	14.9309
2809.46	15.7279
2812.11	15.4959
2814.76	15.0444
2817.42	15.3725
2820.07	16.4688
2822.72	18.5762
2825.37	21.3576
2828.02	25.6562
2830.66	30.1713
2833.31	34.2007
2835.96	38.9054
2838.6	44.051
2841.24	50.7485
2843.89	58.6217
2846.53	66.9955
2849.17	76.8404
2851.81	87.2458
2854.45	96.7212
2857.09	107.902
2859.72	118.93
2862.36	129.387
2865	139.254
2867.63	147.955
2870.26	156.074
2872.9	162.811
2875.53	168.244
2878.16	173.589
2880.79	178.615
2883.42	184.773
2886.05	188.708
2888.67	193.623
2891.3	198.245
2893.92	203.164
2896.55	208.774
2899.17	215.301
2901.79	222.024
2904.42	230.779
2907.04	241.15
2909.66	253.558
2912.27	266.327
2914.89	278.786
2917.51	291.624
2920.13	301.63
2922.74	310.965
2925.35	317.469
2927.97	322.09
2930.58	324.84
2933.19	324.43
2935.8	323.282
2938.41	320.001
2941.02	314.632
2943.63	307.597
2946.24	298.77
2948.84	289.259
2951.45	278.8
2954.05	268.202
2956.65	257.066
2959.26	246.391
2961.86	235.572
2964.46	225.919
2967.06	216.021
2969.66	208.285
2972.25	201.135
2974.85	193.063
2977.45	184.866
2980.04	175.828
2982.64	166.487
2985.23	156.927
2987.82	146.559
2990.41	136.265
2993	125.66
2995.59	114.874
2998.18	105.069
3000.77	96.6893
3003.36	87.6905
3005.94	78.8166
3008.53	71.2175
3011.11	63.8606
3013.69	57.8256
3016.28	52.5269
3018.86	48.2493
3021.44	44.7404
3024.02	41.1673
3026.6	38.794
3029.18	36.9915
3031.75	36.1953
3034.33	37.314
3036.9	38.1592
3039.48	40.2921
3042.05	41.1312
3044.62	43.4483
3047.19	45.3089
3049.77	46.6832
3052.34	46.9619
3054.9	46.6149
3057.47	46.8484
3060.04	46.4873
3062.61	45.0422
3065.17	43.949
3067.74	41.3365
3070.3	38.9567
3072.86	36.172
3075.42	32.5081
3077.99	29.6596
3080.54	26.9819
3083.1	23.0348
3085.66	19.8348
3088.22	16.8362
3090.78	14.2465
3093.33	13.3437
3095.89	12.6544
3098.44	12.2337
3100.99	11.0112
3103.54	9.74186
3106.1	9.52421
3108.65	8.95437
3111.2	8.38087
3113.74	7.72761
3116.29	7.10447
3118.84	6.64177
3121.38	6.08716
3123.93	5.26543
3126.47	4.90949
3129.01	4.12052
3131.56	3.20276
3134.1	2.21994
3136.64	1.3197
3139.18	0.449614
3141.72	0.430717
3144.26	-0.0260572
3146.79	-0.0599539
3149.33	0.462161