File: data/Raman/poly_smoothed/Thy_40_11_07_1x_45s_532 nm_x100_100%_600 gr_mm_01.txt
#Acq. time (s)=	45
#Accumulations=	2
#Range (cm-¹)=	200...3150
#Windows=	2
#Auto scanning=	Off
#Autofocus=	Off
#Macrospot=	Off
#AutoExposure=	Off
#Spike filter=	Multiple accum.
#Delay time (s)=	0
#Binning=	1
#Readout mode=	Signal
#DeNoise=	Off
#ICS correction=	On
#Dark correction=	Off
#Inst. Process=	Off
#Detector Gain=	Best Dynamic Range
#Detector ADC=	20 kHz
#Detector temperature (°C)=	-69.85
#Instrument=	LabRAM HR Evol
#Detector=	Synapse
#Objective=	x100
#Grating=	600 gr/mm
#ND Filter=	100%
#Laser (nm)=	532
#Hole=	100.021
#Range=	Auto
#Laser Pol.=	No
#Raman. Pol.=	No
#Laser Pol. (°)=	-0.0007625
#Raman Pol. (°)=	89.9995
#Collection=	Microscope
#StageXY=	Marzhauser
#StageZ=	Marzhauser
#X (µm)=	1955.5
#Y (µm)=	-78.7
#Z (µm)=	425.95
#Full time(mm:ss)=	3:18
#Project=
#Sample=
#Site=
#Title=	Thy_40_11_07_2x_45s_532 nm_x100_100%_600 gr_mm
#Remark=
#Date=	05.07.2022 10:21
#Acquired=	05.07.2022 10:21:50
#Base:Fit=	10.08.2022 10:00:48
#Base:Fit=	10.08.2022 10:01:07
#Base:Fit=	10.08.2022 10:01:15
#Base:Fit=	10.08.2022 10:01:35
#Base:Sub=	10.08.2022 10:01:52
#Filter:Polynom=	16.08.2022 10:21:53
#AxisType[0]=Intens
#AxisUnit[0]=Cnt
#AxisType[1]=Spectr
#AxisUnit[1]=1/cm
200.43	7.95556
204.059	11.9746
207.688	12.3761
211.314	11.8694
214.941	10.4375
218.564	9.7044
222.186	9.90852
225.809	8.11455
229.428	7.48417
233.045	5.6743
236.663	5.22236
240.278	3.46882
243.891	3.44255
247.503	2.98302
251.116	2.19293
254.725	1.81765
258.333	2.0731
261.939	4.02987
265.544	4.74917
269.148	6.36546
272.75	4.01446
276.351	5.48916
279.95	4.49573
283.548	4.20863
287.144	4.14344
290.739	5.48861
294.333	5.8686
297.925	7.69716
301.514	8.79752
305.104	9.88474
308.692	11.8371
312.279	10.9116
315.862	10.2439
319.446	10.6366
323.029	11.3303
326.608	10.9714
330.188	10.5139
333.766	11.5725
337.341	12.6347
340.917	12.9377
344.489	14.3718
348.062	13.4334
351.631	11.4902
355.201	10.9496
358.768	10.1486
362.333	10.0852
365.899	10.8137
369.462	10.6211
373.023	11.4763
376.585	11.8187
380.143	13.8739
383.7	15.241
387.256	14.1669
390.812	13.0215
394.365	12.3467
397.916	11.1024
401.467	10.0447
405.015	8.94113
408.563	8.66847
412.109	6.53243
415.654	7.1647
419.197	6.26631
422.739	5.96085
426.279	6.56611
429.819	6.90526
433.356	6.52667
436.891	5.79552
440.426	5.90973
443.96	5.80812
447.492	8.48333
451.021	9.07285
454.551	10.2929
458.079	11.8987
461.604	13.3272
465.13	14.7951
468.654	15.3464
472.175	15.4896
475.696	16.4473
479.215	18.0075
482.733	19.229
486.249	19.9894
489.765	21.0761
493.278	23.3836
496.789	23.7519
500.301	23.8936
503.81	25.2525
507.317	25.1797
510.825	26.7499
514.33	26.0267
517.833	26.6234
521.335	26.7865
524.836	26.1302
528.335	24.6798
531.835	24.1836
535.332	24.4951
538.827	22.4804
542.321	22.6909
545.814	21.9133
549.305	20.6829
552.795	20.8274
556.282	19.625
559.769	19.5232
563.255	19.2537
566.739	16.632
570.223	17.9929
573.705	15.5992
577.183	13.6205
580.663	12.0939
584.141	10.5248
587.615	9.53798
591.09	9.11262
594.564	8.79332
598.035	7.35891
601.506	7.3975
604.974	7.03953
608.443	5.97437
611.908	6.1351
615.374	7.3836
618.837	7.60425
622.3	8.67976
625.761	10.2491
629.219	11.2075
632.677	11.4649
636.135	13.6681
639.59	15.6859
643.043	16.6263
646.495	17.5063
649.948	16.9461
653.398	18.8526
656.846	20.5382
660.293	20.6158
663.738	22.4033
667.183	24.5808
670.626	25.546
674.067	25.6816
677.508	26.0511
680.947	26.5179
684.385	27.3132
687.821	30.0867
691.254	31.3273
694.688	33.5815
698.121	37.53
701.552	39.4607
704.98	41.7929
708.409	44.6632
711.836	44.53
715.26	45.9292
718.685	48.7394
722.108	49.9397
725.528	50.4374
728.949	52.1445
732.367	54.11
735.785	55.5705
739.2	57.7084
742.614	59.7975
746.028	62.1523
749.439	63.8828
752.849	65.9188
756.26	65.2283
759.667	69.6249
763.073	72.45
766.477	75.707
769.883	78.952
773.285	81.7489
776.686	85.2518
780.085	89.4975
783.484	91.8834
786.881	92.033
790.276	92.2594
793.671	91.3441
797.064	90.4611
800.456	90.8606
803.846	90.2855
807.234	88.6867
810.622	89.1784
814.008	89.3988
817.394	88.2707
820.778	87.5945
824.159	87.9346
827.541	87.553
830.921	86.0261
834.298	85.7024
837.676	83.1234
841.051	83.5036
844.426	82.2421
847.798	79.4118
851.171	77.3782
854.54	75.9631
857.911	74.4377
861.278	73.3793
864.645	70.0337
868.01	68.1969
871.373	63.5485
874.735	60.678
878.097	58.3482
881.457	57.1471
884.815	55.199
888.172	55.1764
891.528	53.163
894.882	53.2643
898.237	52.1477
901.589	51.4761
904.94	50.7593
908.289	51.2316
911.635	50.2537
914.982	48.8844
918.328	48.6977
921.672	47.6646
925.015	47.4354
928.357	46.7531
931.698	45.5846
935.035	44.41
938.373	44.1089
941.71	44.2955
945.044	41.5693
948.378	40.3238
951.709	39.4164
955.041	38.2212
958.372	37.5829
961.699	36.0383
965.027	37.0881
968.352	38.976
971.676	38.72
975	39.8881
978.322	40.9287
981.642	42.0225
984.962	43.3658
988.28	42.3203
991.596	42.2214
994.911	40.7029
998.227	40.68
1001.54	40.0873
1004.85	39.1445
1008.16	38.3792
1011.47	38.5826
1014.78	37.8415
1018.08	36.5441
1021.39	36.4836
1024.69	35.7043
1028	35.2115
1031.3	34.1827
1034.6	33.1456
1037.9	32.456
1041.19	33.445
1044.49	33.7883
1047.78	35.6823
1051.08	32.8912
1054.37	32.6647
1057.66	33.666
1060.95	33.24
1064.24	32.1107
1067.53	30.1206
1070.81	28.1561
1074.1	28.1835
1077.38	29.6605
1080.66	29.985
1083.94	30.4854
1087.22	30.0522
1090.5	30.6904
1093.78	30.7893
1097.05	30.4365
1100.33	29.9024
1103.6	31.2149
1106.87	30.2625
1110.14	29.024
1113.41	27.5467
1116.68	28.1052
1119.95	27.71
1123.21	25.4013
1126.48	23.3999
1129.74	20.0395
1133	19.3864
1136.26	19.1754
1139.52	16.9917
1142.78	14.809
1146.04	12.8236
1149.29	11.1488
1152.55	10.2234
1155.8	7.50956
1159.05	4.73305
1162.3	4.21692
1165.55	3.57442
1168.8	1.73832
1172.05	1.8066
1175.29	4.67764
1178.54	5.43814
1181.78	7.23919
1185.02	8.68951
1188.26	9.05945
1191.5	9.31559
1194.74	12.2696
1197.97	13.7678
1201.21	14.4769
1204.44	15.2335
1207.68	18.9897
1210.91	22.6221
1214.14	26.0493
1217.37	29.2155
1220.59	33.2293
1223.82	36.5447
1227.05	39.2695
1230.27	41.8373
1233.49	46.306
1236.72	50.5463
1239.94	55.7953
1243.16	59.856
1246.37	62.655
1249.59	68.2774
1252.8	71.7038
1256.02	74.1967
1259.23	76.4636
1262.44	77.2553
1265.66	79.5957
1268.86	80.3512
1272.07	82.8428
1275.28	84.1703
1278.48	84.8171
1281.69	86.7565
1284.89	89.359
1288.09	92.3454
1291.29	93.4016
1294.49	94.2203
1297.69	97.2478
1300.89	98.0495
1304.08	99.2113
1307.28	101.541
1310.47	103.465
1313.66	104.891
1316.85	104.524
1320.04	102.791
1323.23	101.371
1326.42	100.721
1329.61	98.4372
1332.79	93.7982
1335.97	92.103
1339.16	90.8756
1342.34	88.532
1345.52	85.9937
1348.7	83.7978
1351.87	82.1193
1355.05	78.6228
1358.22	76.4124
1361.4	74.0598
1364.57	71.5312
1367.74	70.1176
1370.91	68.6233
1374.08	64.2359
1377.25	66.0322
1380.41	66.932
1383.58	68.4489
1386.74	69.1252
1389.91	69.9411
1393.07	69.4808
1396.23	68.5901
1399.39	66.8001
1402.55	68.0467
1405.7	69.0427
1408.86	69.2363
1412.01	71.4013
1415.17	73.5752
1418.32	76.493
1421.47	79.7492
1424.62	83.9339
1427.77	87.0482
1430.91	90.2521
1434.06	92.738
1437.2	96.7844
1440.35	100.239
1443.49	102.108
1446.63	103.517
1449.77	102.833
1452.91	104.405
1456.05	106.687
1459.18	104.321
1462.32	101.709
1465.45	97.0429
1468.59	92.2842
1471.72	86.9056
1474.85	80.9813
1477.98	74.6654
1481.1	68.7182
1484.23	63.6728
1487.36	57.6928
1490.48	52.3526
1493.61	48.0786
1496.73	45.1528
1499.85	41.6649
1502.97	39.0907
1506.09	36.9047
1509.2	37.7326
1512.32	37.866
1515.43	38.4923
1518.55	38.0222
1521.66	38.4503
1524.77	39.6144
1527.88	42.085
1530.99	45.4298
1534.1	48.4618
1537.21	51.1787
1540.31	56.76
1543.42	62.5244
1546.52	69.037
1549.62	74.572
1552.72	81.4451
1555.82	87.6236
1558.92	93.269
1562.02	98.1254
1565.11	101.109
1568.21	103.917
1571.3	106.584
1574.39	109.728
1577.49	110.564
1580.57	113.1
1583.66	114.795
1586.75	114.597
1589.84	113.612
1592.92	112.313
1596.01	110.029
1599.09	108.692
1602.17	106.017
1605.25	102.726
1608.33	101.905
1611.41	99.3403
1614.49	98.9677
1617.57	98.6504
1620.64	99.7332
1623.72	101.005
1626.79	103.737
1629.86	104.781
1632.93	106.495
1636	109.411
1639.07	111.706
1642.13	112.479
1645.2	114.452
1648.26	116.733
1651.33	118.166
1654.39	120.373
1657.45	121.057
1660.51	120.837
1663.57	118.623
1666.63	116.093
1669.68	113.002
1672.74	108.702
1675.79	102.704
1678.85	95.8202
1681.9	87.9841
1684.95	81.1629
1688	73.2666
1691.05	66.7208
1694.09	60.9799
1697.14	54.8787
1700.18	49.6124
1703.23	44.8643
1706.27	40.8862
1709.31	38.9884
1712.35	35.0122
1715.39	31.9654
1718.43	28.9917
1721.47	28.9305
1724.5	26.9882
1727.54	26.8151
1730.57	26.5844
1733.61	26.0902
1736.64	25.8434
1739.67	25.6139
1742.7	26.0672
1745.72	24.8668
1748.75	23.6388
1751.77	21.9876
1754.8	21.3737
1757.82	20.4853
1760.84	19.609
1763.87	18.8785
1766.89	17.9658
1769.91	16.8329
1772.92	16.025
1775.94	15.3536
1778.95	14.9962
1781.97	14.6826
1784.98	13.436
1787.99	12.4474
1791.01	11.3239
1794.01	10.6214
1797.02	9.71215
1800.03	8.73266
1803.04	7.9061
1806.04	8.24747
1809.05	6.69979
1812.05	6.93328
1815.05	6.77862
1818.05	7.81184
1821.05	8.23516
1824.05	8.61944
1827.05	8.59731
1830.04	8.89249
1833.04	8.22723
1836.03	6.96827
1839.03	7.12736
1842.02	6.84891
1845.01	6.45694
1848	6.2422
1850.99	5.96952
1853.97	5.31168
1856.96	5.36662
1859.94	4.45483
1862.93	2.99243
1865.91	1.57019
1868.89	1.27425
1871.87	0.702833
1874.85	0.564251
1877.83	0.729878
1880.81	0.343334
1882.57	0.909131
1885.56	2.40644
1888.55	2.89525
1891.54	4.84886
1894.52	5.14556
1897.51	6.38614
1900.49	6.46636
1903.47	7.43824
1906.45	8.00999
1909.43	8.29794
1912.41	9.04969
1915.39	6.9789
1918.37	7.2625
1921.34	7.62746
1924.32	7.3256
1927.29	8.03248
1930.26	6.93347
1933.23	5.27692
1936.2	4.1026
1939.17	3.35148
1942.14	3.07666
1945.11	1.68568
1948.07	0.620567
1951.04	1.84958
1954	2.02886
1956.96	1.34338
1959.93	0.892131
1962.89	1.79813
1965.85	2.45377
1968.8	2.76023
1971.76	3.08378
1974.72	3.73216
1977.67	4.0735
1980.63	4.19869
1983.58	4.35322
1986.53	3.81921
1989.48	5.4447
1992.43	6.27668
1995.38	7.73461
1998.32	8.58329
2001.27	8.65278
2004.22	7.69353
2007.16	7.11326
2010.1	6.9335
2013.04	6.82042
2015.98	7.01419
2018.92	7.51941
2021.86	7.99258
2024.8	8.13722
2027.74	6.89244
2030.67	7.01576
2033.61	7.09154
2036.54	7.02684
2039.47	7.68931
2042.4	7.28114
2045.33	7.45924
2048.26	7.29087
2051.19	7.21251
2054.12	8.64077
2057.04	9.6928
2059.97	11.1739
2062.89	12.5277
2065.81	14.3014
2068.73	15.083
2071.65	15.2027
2074.57	16.5271
2077.49	17.7346
2080.41	20.0857
2083.32	22.2581
2086.24	24.9404
2089.15	26.1954
2092.07	27.7081
2094.98	29.0834
2097.89	30.6541
2100.8	32.3071
2103.71	34.0305
2106.61	35.9049
2109.52	37.4865
2112.43	38.7034
2115.33	41.0784
2118.23	44.241
2121.13	47.6346
2124.04	51.9243
2126.94	56.018
2129.83	59.2591
2132.73	63.6436
2135.63	68.0842
2138.53	71.8552
2141.42	75.9523
2144.31	80.3055
2147.21	85.3835
2150.1	89.4601
2152.99	92.9302
2155.88	95.5921
2158.77	97.894
2161.65	99.7735
2164.54	101.475
2167.43	102.109
2170.31	103.266
2173.19	102.503
2176.07	102.17
2178.96	100.865
2181.84	99.004
2184.72	97.4054
2187.59	96.0719
2190.47	94.0668
2193.35	91.2513
2196.22	88.6268
2199.09	84.2954
2201.97	79.8419
2204.84	76.0045
2207.71	71.7002
2210.58	67.8804
2213.45	63.6245
2216.31	59.6887
2219.18	56.0656
2222.05	51.4723
2224.91	48.2922
2227.78	44.9161
2230.64	42.8292
2233.5	40.1955
2236.36	39.0575
2239.22	36.875
2242.08	35.0473
2244.93	34.1332
2247.79	32.7162
2250.64	31.8745
2253.5	30.952
2256.35	30.45
2259.2	29.5492
2262.05	28.1802
2264.9	26.5608
2267.75	24.9757
2270.6	23.0601
2273.45	21.2352
2276.29	19.8817
2279.14	18.9747
2281.98	17.5544
2284.82	16.4012
2287.66	15.8239
2290.5	14.1236
2293.34	12.3243
2296.18	12.0745
2299.02	11.8112
2301.86	11.027
2304.69	10.9127
2307.53	11.4783
2310.36	11.0534
2313.19	11.4203
2316.02	11.1701
2318.85	10.3728
2321.68	10.5163
2324.51	9.87643
2327.34	9.45713
2330.16	8.18458
2332.99	7.63594
2335.81	5.8725
2338.64	5.29979
2341.46	5.34519
2344.28	4.63295
2347.1	5.01641
2349.92	4.84501
2352.74	4.43689
2355.55	4.1086
2358.37	2.77718
2361.19	2.33128
2364	1.76634
2366.81	2.84399
2369.62	2.55268
2372.44	2.77039
2375.24	3.95828
2378.05	4.93868
2380.86	5.54493
2383.67	5.99373
2386.47	5.33876
2389.28	5.05578
2392.08	5.00914
2394.89	4.24424
2397.69	3.39836
2400.49	3.39944
2403.29	3.45759
2406.09	3.42809
2408.88	3.93205
2411.68	4.30013
2414.48	4.44933
2417.27	5.69559
2420.06	4.87367
2422.86	5.25845
2425.65	5.0779
2428.44	4.1118
2431.23	4.32655
2434.02	4.97634
2436.81	4.77194
2439.59	5.11576
2442.38	6.55391
2445.16	5.91089
2447.95	6.53469
2450.73	6.4033
2453.51	5.71529
2456.29	5.63007
2459.07	6.52436
2461.85	5.34324
2464.63	5.26724
2467.4	5.17897
2470.18	5.0253
2472.95	4.59864
2475.73	5.38358
2478.5	5.44549
2481.27	6.38184
2484.04	6.42296
2486.81	5.64336
2489.58	5.81798
2492.35	5.6739
2495.12	3.91894
2497.88	3.68939
2500.65	3.95969
2503.41	2.73533
2506.17	1.87606
2508.94	1.88017
2511.7	0.992272
2514.46	0.102565
2517.22	0.743977
2519.97	0.0349686
2522.73	0.212655
2525.49	0.706366
2528.24	0.894249
2530.99	0.935617
2533.75	1.21911
2536.5	1.00318
2539.25	1.9032
2542	2.8179
2544.75	4.26939
2547.5	5.1464
2550.24	6.58504
2552.99	6.23029
2555.74	7.24722
2558.48	7.99626
2561.22	6.51934
2563.96	6.84988
2566.71	5.81009
2569.45	6.1945
2572.18	5.85338
2574.92	5.41087
2577.66	5.09256
2580.4	4.19033
2583.13	4.3954
2585.87	3.28907
2588.6	3.31294
2591.33	3.60314
2594.06	2.5288
2596.79	2.40971
2599.52	1.86855
2602.25	0.55851
2604.98	0.270831
2607.71	0.090016
2610.43	-0.128873
2613.16	1.46129
2615.88	2.02856
2618.6	1.8088
2621.32	1.82322
2624.04	1.18461
2626.76	0.933118
2629.48	2.11265
2632.2	3.01971
2634.92	4.53703
2637.63	5.18513
2640.35	5.86533
2643.06	5.58911
2645.77	6.87287
2648.49	6.63817
2651.2	7.2782
2653.91	6.48163
2656.62	7.20107
2659.33	6.20417
2662.03	6.22201
2664.74	5.78944
2667.44	5.78484
2670.15	6.60806
2672.85	6.99718
2675.55	7.17138
2678.26	8.55008
2680.96	8.94876
2683.66	8.53331
2686.35	7.89077
2689.05	7.77106
2691.75	8.17993
2694.44	8.88286
2697.14	9.61129
2699.83	9.69052
2702.52	9.70369
2705.22	9.23529
2707.91	8.93378
2710.6	7.98369
2713.29	7.7092
2715.97	7.28857
2718.66	6.31568
2721.35	6.24437
2724.03	6.70783
2726.72	7.09921
2729.4	8.2938
2732.08	7.87356
2734.76	8.84278
2737.44	8.86201
2740.12	8.66121
2742.8	8.97318
2745.48	8.76384
2748.16	8.26663
2750.83	7.37548
2753.51	7.02761
2756.18	6.42185
2758.85	6.30983
2761.53	5.89122
2764.2	5.0053
2766.87	3.78273
2769.54	3.8931
2772.2	3.64456
2774.87	2.30878
2777.54	1.71977
2780.2	1.09661
2782.87	0.754274
2785.53	1.29906
2788.19	0.597824
2790.85	0.366494
2793.51	0.317654
2796.17	-0.752753
2798.83	-0.76294
2801.49	-0.993975
2804.15	-0.969235
2806.8	-0.817553
2809.46	-1.08163
2812.11	-1.38054
2814.76	-0.594845
2817.42	0.538253
2820.07	1.2342
2822.72	3.45992
2825.37	7.00176
2828.02	10.1174
2830.66	14.4832
2833.31	18.2406
2835.96	22.1896
2838.6	25.6651
2841.24	29.7187
2843.89	35.2976
2846.53	41.0998
2849.17	48.6579
2851.81	56.1314
2854.45	64.9675
2857.09	72.9208
2859.72	79.8486
2862.36	87.7275
2865	94.4438
2867.63	100.476
2870.26	106.942
2872.9	112.092
2875.53	117.626
2878.16	123.033
2880.79	127.416
2883.42	131.516
2886.05	136.522
2888.67	140.797
2891.3	145.643
2893.92	149.446
2896.55	154.939
2899.17	160.542
2901.79	167.974
2904.42	177.363
2907.04	188.035
2909.66	200.602
2912.27	213.375
2914.89	225.829
2917.51	238.274
2920.13	248.33
2922.74	257.182
2925.35	264.671
2927.97	270.691
2930.58	271.936
2933.19	273.414
2935.8	271.941
2938.41	268.581
2941.02	263.306
2943.63	256.168
2946.24	247.238
2948.84	236.623
2951.45	226.138
2954.05	215.053
2956.65	203.973
2959.26	193.373
2961.86	182.861
2964.46	172.634
2967.06	162.565
2969.66	153.506
2972.25	144.856
2974.85	136.393
2977.45	127.615
2980.04	118.235
2982.64	109.602
2985.23	100.965
2987.82	90.7638
2990.41	81.2273
2993	70.8125
2995.59	62.3993
2998.18	55.4472
3000.77	47.8447
3003.36	40.0192
3005.94	33.0103
3008.53	26.1566
3011.11	20.7069
3013.69	16.5422
3016.28	13.0854
3018.86	9.82596
3021.44	7.8025
3024.02	5.44293
3026.6	3.18834
3029.18	2.82048
3031.75	2.78393
3034.33	3.88777
3036.9	4.57384
3039.48	4.92559
3042.05	5.41829
3044.62	6.61762
3047.19	7.76251
3049.77	9.1956
3052.34	10.0468
3054.9	10.4965
3057.47	11.6158
3060.04	11.5325
3062.61	10.6347
3065.17	9.40399
3067.74	8.83427
3070.3	8.642
3072.86	7.88265
3075.42	6.83709
3077.99	6.15771
3080.54	4.71026
3083.1	3.52363
3085.66	2.98534
3088.22	1.48238
3090.78	1.20201
3093.33	0.856621
3095.89	0.547626
3098.44	0.55348
3100.99	0.376627
3103.54	0.990315
3106.1	2.06857
3108.65	3.94196
3111.2	5.07989
3113.74	6.42298
3116.29	7.27526
3118.84	8.23755
3121.38	9.72771
3123.93	10.5566
3126.47	12.0374
3129.01	14.5466
3131.56	16.9454
3134.1	18.2887
3136.64	18.9547
3139.18	20.6983
3141.72	22.107
3144.26	23.2758
3146.79	24.5982
3149.33	25.2753