File: data/Raman/poly_smoothed/Thy_20_09_46_1x_45s_532 nm_x100_100%_600 gr_mm_01.txt
#Acq. time (s)=	45
#Accumulations=	2
#Range (cm-¹)=	200...3150
#Windows=	2
#Auto scanning=	Off
#Autofocus=	Off
#Macrospot=	Off
#AutoExposure=	Off
#Spike filter=	Multiple accum.
#Delay time (s)=	0
#Binning=	1
#Readout mode=	Signal
#DeNoise=	Off
#ICS correction=	On
#Dark correction=	Off
#Inst. Process=	Off
#Detector Gain=	Best Dynamic Range
#Detector ADC=	20 kHz
#Detector temperature (°C)=	-69.85
#Instrument=	LabRAM HR Evol
#Detector=	Synapse
#Objective=	x100
#Grating=	600 gr/mm
#ND Filter=	100%
#Laser (nm)=	532
#Hole=	100.021
#Range=	Auto
#Laser Pol.=	No
#Raman. Pol.=	No
#Laser Pol. (°)=	-0.0007625
#Raman Pol. (°)=	89.9995
#Collection=	Microscope
#StageXY=	Marzhauser
#StageZ=	Marzhauser
#X (µm)=	-5929.6
#Y (µm)=	2846
#Z (µm)=	-223.8
#Full time(mm:ss)=	3:19
#Project=
#Sample=
#Site=
#Title=	Thy_20_09_46_2x_45s_532 nm_x100_100%_600 gr_mm
#Remark=
#Date=	29.06.2022 13:52
#Acquired=	29.06.2022 13:52:57
#Base:Fit=	10.08.2022 09:52:02
#Base:Fit=	10.08.2022 09:52:12
#Base:Sub=	10.08.2022 09:54:21
#Filter:Polynom=	16.08.2022 10:24:04
#AxisType[0]=Intens
#AxisUnit[0]=Cnt
#AxisType[1]=Spectr
#AxisUnit[1]=1/cm
200.523	4.70592
204.154	6.32083
207.781	5.39957
211.409	5.46615
215.034	5.40964
218.659	5.02927
222.281	4.01471
225.903	3.19499
229.522	4.88034
233.14	5.58636
236.756	6.13015
240.373	6.6763
243.986	6.53008
247.598	5.77509
251.208	4.08903
254.818	4.16083
258.427	4.71245
262.034	4.33915
265.638	5.46686
269.242	5.91837
272.844	5.53409
276.445	5.61771
280.044	5.33266
283.642	5.88214
287.238	5.67407
290.833	4.44337
294.425	4.39037
298.017	6.35086
301.608	6.90365
305.198	6.40399
308.786	7.2478
312.371	9.06471
315.956	11.3199
319.54	12.3532
323.122	14.8241
326.701	15.133
330.281	16.6426
333.857	15.0099
337.434	14.8151
341.008	14.2525
344.582	13.615
348.153	13.3365
351.724	12.6439
355.292	11.8061
358.861	10.6824
362.426	10.3991
365.99	9.45425
369.555	8.69275
373.116	6.95291
376.676	5.01334
380.236	6.43503
383.793	7.72473
387.349	6.9097
390.903	7.75506
394.456	8.3863
398.007	9.09106
401.56	10.0429
405.108	11.4013
408.656	10.8731
412.202	11.3453
415.746	10.4908
419.29	8.57059
422.831	7.54568
426.37	8.18806
429.909	7.02327
433.447	5.73066
436.983	5.48198
440.519	4.29245
444.052	4.97249
447.583	5.43754
451.114	6.22277
454.643	6.26133
458.169	6.55007
461.696	7.55356
465.222	8.8071
468.744	10.9296
472.267	11.129
475.787	11.3697
479.307	12.5652
482.823	13.9357
486.341	16.194
489.855	17.4765
493.37	18.4389
496.881	18.473
500.391	19.6579
503.902	21.163
507.409	22.1152
510.915	23.2614
514.42	24.3472
517.925	25.5783
521.427	26.5109
524.928	27.4739
528.427	26.998
531.925	26.2791
535.422	25.205
538.917	24.7641
542.411	23.3949
545.903	22.0442
549.395	20.9086
552.884	19.8472
556.373	17.8965
559.86	16.2335
563.346	16.3093
566.831	14.9769
570.314	14.554
573.794	14.3016
577.274	12.5213
580.754	12.6682
584.23	11.9438
587.706	12.7749
591.181	11.0416
594.653	10.7615
598.126	9.75801
601.595	9.47909
605.065	9.3953
608.532	8.05533
611.999	7.10916
615.463	7.03932
618.928	6.27494
622.389	6.70156
625.851	7.16486
629.31	7.84436
632.767	8.49012
636.223	10.0692
639.68	11.0121
643.134	11.515
646.586	13.9066
650.037	14.9465
653.486	15.4434
656.936	17.2978
660.383	17.3413
663.829	19.1708
667.273	19.6071
670.716	20.462
674.158	20.8912
677.598	20.9448
681.035	21.3968
684.473	22.3034
687.909	24.3059
691.344	24.8058
694.778	25.7502
698.211	26.9671
701.64	28.1464
705.07	30.029
708.498	31.6074
711.924	33.682
715.35	35.4195
718.774	36.9983
722.196	38.6572
725.618	40.0472
729.037	41.9842
732.456	42.4241
735.873	44.5898
739.289	44.8326
742.703	46.6651
746.116	49.0149
749.529	51.6459
752.938	54.6568
756.347	58.3319
759.756	59.4775
763.162	61.956
766.567	64.0427
769.97	65.4422
773.372	66.9534
776.773	68.1248
780.174	69.553
783.573	71.7462
786.97	73.675
790.365	75.0374
793.76	75.3547
797.153	74.8946
800.543	75.6355
803.933	75.2892
807.322	75.351
810.71	74.8403
814.097	74.6201
817.483	74.1905
820.865	73.4581
824.248	71.318
827.629	71.1773
831.008	70.5244
834.387	70.2712
837.765	69.5168
841.139	67.6763
844.514	65.1423
847.886	63.2211
851.259	60.226
854.629	56.887
857.997	55.4282
861.366	52.1272
864.732	50.1518
868.098	48.6588
871.461	48.9626
874.823	46.9241
878.184	45.8132
881.545	45.3376
884.903	43.7688
888.26	44.5096
891.616	44.735
894.97	44.459
898.323	45.3197
901.675	44.0028
905.026	43.6746
908.375	44.2548
911.723	45.5337
915.07	45.8143
918.415	46.4724
921.76	44.7483
925.103	44.1761
928.443	43.7491
931.783	44.353
935.123	41.0033
938.461	39.3342
941.796	36.5025
945.131	34.0563
948.465	31.2662
951.797	30.8252
955.128	28.7235
958.457	25.9183
961.786	24.1965
965.113	24.1933
968.44	23.2995
971.763	24.3914
975.086	22.5664
978.409	21.3696
981.729	20.1949
985.048	20.185
988.367	20.2434
991.683	21.7475
994.998	20.1629
998.312	20.428
1001.62	20.5549
1004.94	21.2801
1008.25	21.0336
1011.56	21.6359
1014.86	19.6808
1018.17	17.5471
1021.48	14.72
1024.78	13.7623
1028.08	12.0936
1031.38	12.1127
1034.68	11.637
1037.98	11.157
1041.28	11.1704
1044.57	11.417
1047.87	10.9533
1051.16	9.81552
1054.45	7.49581
1057.75	6.924
1061.04	7.13194
1064.32	6.6023
1067.61	7.62614
1070.9	8.38922
1074.18	8.2246
1077.47	7.91897
1080.75	7.22398
1084.03	7.36513
1087.31	6.71726
1090.59	6.30373
1093.86	6.36771
1097.14	5.83512
1100.41	6.99643
1103.69	7.71557
1106.96	9.43988
1110.23	10.1963
1113.5	11.6349
1116.77	12.5019
1120.03	12.7626
1123.3	11.9506
1126.56	11.0438
1129.83	9.64841
1133.09	8.81146
1136.35	9.15699
1139.61	9.67345
1142.86	9.40067
1146.12	9.79023
1149.38	9.94807
1152.63	9.06573
1155.88	7.60503
1159.14	5.98535
1162.39	5.56441
1165.63	3.446
1168.88	3.49912
1172.13	2.96615
1175.38	3.70063
1178.62	5.1242
1181.86	4.96901
1185.1	5.61305
1188.34	6.95149
1191.58	6.75796
1194.82	8.1118
1198.06	9.20015
1201.29	10.735
1204.53	12.9149
1207.76	13.4459
1210.99	16.171
1214.22	19.3961
1217.45	23.8464
1220.68	26.2579
1223.91	29.6224
1227.13	33.3907
1230.36	35.1103
1233.58	37.0598
1236.8	40.8664
1240.02	42.684
1243.24	43.4204
1246.46	44.8779
1249.67	46.4604
1252.89	47.2097
1256.1	48.4061
1259.32	48.2917
1262.53	47.8502
1265.74	47.4539
1268.95	49.0907
1272.15	50.6236
1275.36	51.4122
1278.57	52.9154
1281.77	54.0466
1284.97	54.0797
1288.18	55.9776
1291.38	58.3104
1294.58	59.6898
1297.78	62.4152
1300.97	65.1377
1304.17	67.8552
1307.36	69.0386
1310.55	71.1521
1313.75	72.4484
1316.94	73.7727
1320.13	74.4853
1323.32	75.2581
1326.5	75.8436
1329.69	74.9634
1332.87	74.7916
1336.06	73.4345
1339.24	72.3416
1342.42	70.7894
1345.6	68.7392
1348.78	66.8732
1351.96	65.9735
1355.13	64.5582
1358.31	61.2627
1361.48	59.19
1364.65	59.7661
1367.82	57.7558
1370.99	54.5541
1374.16	53.4051
1377.33	51.1939
1380.5	51.4721
1383.66	50.5018
1386.83	50.4528
1389.99	47.8645
1393.15	47.2425
1396.31	47.1737
1399.47	45.4593
1402.63	44.6877
1405.78	43.9771
1408.94	44.3461
1412.1	43.4769
1415.25	44.7559
1418.4	47.0844
1421.55	50.0402
1424.7	53.7015
1427.85	56.7086
1431	60.7683
1434.14	64.4398
1437.29	66.4661
1440.43	70.7229
1443.57	72.1949
1446.71	74.076
1449.85	75.2343
1452.99	75.1294
1456.13	74.8718
1459.26	74.1531
1462.4	71.1623
1465.54	65.7817
1468.67	61.2632
1471.8	56.9129
1474.93	51.7714
1478.06	46.595
1481.19	41.4953
1484.31	36.8695
1487.44	33.3976
1490.56	30.5678
1493.69	27.5954
1496.81	26.5272
1499.93	24.5549
1503.05	22.2873
1506.17	22.0765
1509.28	21.567
1512.4	21.8154
1515.52	22.6274
1518.63	24.0794
1521.74	26.0612
1524.85	27.4504
1527.96	28.056
1531.07	28.9408
1534.18	32.1467
1537.29	34.4084
1540.39	36.316
1543.5	39.275
1546.6	43.34
1549.7	47.6554
1552.8	50.3566
1555.9	55.2479
1559	60.3993
1562.1	62.956
1565.19	65.6082
1568.29	68.4412
1571.38	72.1835
1574.47	74.9512
1577.56	77.2987
1580.66	78.6334
1583.74	81.1044
1586.83	81.567
1589.92	84.7217
1593.01	85.9246
1596.09	84.9372
1599.17	84.5153
1602.25	83.188
1605.34	81.897
1608.41	81.1934
1611.49	79.9779
1614.57	78.0718
1617.65	76.6536
1620.72	76.6767
1623.79	75.2877
1626.87	73.2363
1629.94	71.0206
1633.01	70.5875
1636.08	68.8612
1639.15	69.5909
1642.21	69.6083
1645.28	68.8784
1648.34	68.1232
1651.41	67.2699
1654.47	65.4205
1657.53	65.0908
1660.59	64.1055
1663.65	63.0467
1666.71	61.3217
1669.76	57.844
1672.82	54.7539
1675.87	51.8669
1678.93	48.7056
1681.98	45.3533
1685.03	42.134
1688.08	38.7606
1691.13	34.2719
1694.17	31.3414
1697.22	27.5598
1700.27	22.0348
1703.31	19.0446
1706.35	17.8904
1709.39	16.402
1712.43	15.5949
1715.47	14.3397
1718.51	12.3596
1721.55	11.6282
1724.58	11.0405
1727.62	10.8078
1730.65	11.2526
1733.68	10.9446
1736.72	11.0484
1739.74	11.2186
1742.77	10.6526
1745.8	10.8492
1748.83	10.9671
1751.85	10.3653
1754.88	9.28341
1757.9	9.39772
1760.92	8.34728
1763.95	7.17546
1766.96	7.02132
1769.98	6.0884
1773	4.25839
1776.02	4.21776
1779.03	3.94705
1782.05	3.60252
1785.06	3.67748
1788.07	4.51015
1791.08	4.07668
1794.09	4.56338
1797.1	4.56054
1800.11	5.18513
1803.12	5.84003
1806.12	5.88445
1809.12	7.38492
1812.13	8.62476
1815.13	9.01884
1818.13	8.01215
1821.13	7.69248
1824.13	7.17473
1827.13	6.48687
1830.12	5.06789
1833.12	4.83747
1836.11	4.18477
1839.1	3.21038
1842.09	2.83883
1845.09	2.80085
1848.08	2.6143
1851.06	2.03933
1854.05	2.00683
1857.04	2.51972
1860.02	3.11337
1863.01	2.90935
1865.99	3.60574
1868.97	4.62908
1871.95	6.2087
1874.93	7.1293
1877.91	7.09329
1880.89	7.59519
1882.46	8.23868
1885.45	7.97136
1888.43	6.95283
1891.42	7.04652
1894.41	7.93123
1897.39	8.2953
1900.37	8.07867
1903.36	7.58312
1906.34	7.08704
1909.32	5.52312
1912.29	6.42873
1915.27	6.47122
1918.25	5.41673
1921.23	4.96639
1924.2	4.52704
1927.17	4.50599
1930.15	4.71054
1933.12	4.8111
1936.09	4.98058
1939.06	4.72868
1942.02	4.55888
1944.99	4.6588
1947.96	3.76248
1950.92	3.03767
1953.88	3.53593
1956.85	4.05977
1959.81	3.20277
1962.77	3.49068
1965.73	4.26599
1968.69	5.20566
1971.64	5.32321
1974.6	4.22134
1977.55	4.12779
1980.51	4.25847
1983.46	3.9659
1986.41	4.04033
1989.36	4.73776
1992.31	5.43056
1995.26	4.62043
1998.21	4.8088
2001.15	4.98748
2004.1	5.8417
2007.04	6.04553
2009.99	6.7358
2012.93	6.21594
2015.87	6.27285
2018.81	5.28965
2021.75	4.63543
2024.68	4.61198
2027.62	4.73309
2030.56	4.14316
2033.49	4.13442
2036.42	4.77682
2039.36	5.56926
2042.29	5.24683
2045.22	4.96244
2048.14	5.59973
2051.07	7.22836
2054	7.94981
2056.93	7.6497
2059.85	8.2106
2062.77	8.32518
2065.7	8.95886
2068.62	8.87218
2071.54	9.59782
2074.46	9.4689
2077.38	9.20455
2080.29	10.164
2083.21	9.25478
2086.12	8.90416
2089.04	7.99041
2091.95	8.16538
2094.86	9.34085
2097.77	10.0598
2100.68	10.4855
2103.59	11.6589
2106.5	13.0467
2109.41	14.2325
2112.31	15.8846
2115.21	17.4309
2118.12	19.1724
2121.02	21.4491
2123.92	22.1778
2126.82	22.4033
2129.72	23.6343
2132.62	25.5707
2135.51	27.9599
2138.41	29.2354
2141.31	30.7533
2144.2	31.9958
2147.09	33.9695
2149.98	35.5575
2152.87	35.479
2155.76	36.1757
2158.65	37.8535
2161.54	39.4044
2164.43	40.7266
2167.31	41.6728
2170.2	42.5372
2173.08	42.5643
2175.96	42.771
2178.84	42.2046
2181.72	42.0763
2184.6	40.524
2187.48	39.5055
2190.36	37.2942
2193.23	35.6246
2196.11	32.869
2198.98	30.8328
2201.85	29.4498
2204.72	27.9883
2207.59	25.761
2210.46	24.15
2213.33	20.9408
2216.2	20.2697
2219.07	18.5627
2221.93	16.8294
2224.8	15.9171
2227.66	15.8727
2230.52	15.4738
2233.39	14.286
2236.25	12.6502
2239.1	11.678
2241.96	10.2675
2244.82	9.9666
2247.68	8.91481
2250.53	9.0068
2253.38	8.80105
2256.24	8.17263
2259.09	8.00303
2261.94	8.18334
2264.79	7.46441
2267.64	7.8042
2270.49	8.34451
2273.33	8.57549
2276.18	9.76636
2279.02	9.4972
2281.87	9.4957
2284.71	9.3842
2287.55	9.0678
2290.39	7.71293
2293.23	6.79014
2296.07	7.24798
2298.91	7.42727
2301.74	7.83025
2304.58	7.21228
2307.41	7.21835
2310.25	6.51096
2313.08	6.33633
2315.91	7.1339
2318.74	6.71924
2321.57	5.96359
2324.4	6.14147
2327.23	5.41848
2330.05	6.13433
2332.88	5.73852
2335.7	5.8124
2338.52	5.46091
2341.35	5.42256
2344.17	4.86943
2346.99	3.93142
2349.81	2.56702
2352.62	2.44193
2355.44	1.44476
2358.26	-0.284981
2361.07	-0.33907
2363.89	1.79271
2366.7	1.74329
2369.51	2.072
2372.32	2.00719
2375.13	1.60765
2377.94	1.4217
2380.75	1.44431
2383.56	2.4121
2386.36	1.96307
2389.17	2.03055
2391.97	2.28867
2394.77	1.75588
2397.58	2.00848
2400.38	2.09097
2403.18	2.18181
2405.97	1.87043
2408.77	2.44773
2411.57	3.60127
2414.37	4.87882
2417.16	5.37028
2419.95	5.75738
2422.75	6.3872
2425.54	5.55922
2428.33	5.04942
2431.12	5.29178
2433.91	5.08045
2436.7	4.76168
2439.48	5.24712
2442.27	4.31115
2445.05	5.0558
2447.84	4.62532
2450.62	4.96441
2453.4	4.8076
2456.18	4.43675
2458.96	3.82652
2461.74	3.85612
2464.52	2.70888
2467.29	3.21771
2470.07	3.29458
2472.85	3.34131
2475.62	3.05973
2478.39	3.02149
2481.16	3.55544
2483.93	3.36462
2486.7	2.22651
2489.47	2.05364
2492.24	1.90626
2495.01	2.54491
2497.77	1.58042
2500.54	1.88642
2503.3	1.73345
2506.06	1.84845
2508.83	2.55387
2511.59	2.52639
2514.35	2.51597
2517.11	1.99205
2519.86	3.43601
2522.62	3.32879
2525.38	3.2739
2528.13	2.87702
2530.89	2.4856
2533.64	2.57759
2536.39	2.65829
2539.14	2.68982
2541.89	2.44044
2544.64	2.0481
2547.39	2.50898
2550.14	3.44924
2552.88	2.58191
2555.63	2.87114
2558.37	3.10108
2561.11	3.34815
2563.86	3.08922
2566.6	3.008
2569.34	3.80438
2572.08	4.54141
2574.82	4.6517
2577.55	4.51783
2580.29	4.03975
2583.02	5.40528
2585.76	4.70856
2588.49	4.75874
2591.22	3.94747
2593.96	3.60095
2596.69	4.07134
2599.42	5.2271
2602.14	5.51494
2604.87	6.33971
2607.6	7.36281
2610.32	6.66994
2613.05	5.71131
2615.77	5.82274
2618.49	5.45646
2621.22	5.66345
2623.94	5.48706
2626.66	5.33085
2629.37	6.31421
2632.09	6.79627
2634.81	7.98495
2637.53	7.3779
2640.24	8.34008
2642.96	7.14774
2645.67	7.3554
2648.38	7.03602
2651.09	6.8259
2653.8	6.85081
2656.51	7.48878
2659.22	8.49842
2661.93	10.3052
2664.63	10.9049
2667.34	12.1938
2670.04	11.6458
2672.75	12.3279
2675.45	12.4266
2678.15	11.4771
2680.85	12.277
2683.55	12.6644
2686.25	12.5437
2688.94	13.0424
2691.64	13.1664
2694.34	12.589
2697.03	12.3847
2699.73	11.9219
2702.42	11.6845
2705.11	10.3064
2707.8	10.6625
2710.49	9.98835
2713.18	10.1029
2715.87	10.1163
2718.55	10.4044
2721.24	11.0949
2723.93	11.0469
2726.61	10.9963
2729.29	11.3729
2731.98	10.2678
2734.66	10.3107
2737.34	10.8208
2740.02	11.2907
2742.7	11.6579
2745.37	12.1846
2748.05	12.4807
2750.72	12.5721
2753.4	12.4018
2756.07	12.077
2758.75	10.8245
2761.42	10.0091
2764.09	9.51417
2766.76	8.98809
2769.43	7.72978
2772.1	6.33875
2774.76	5.36414
2777.43	4.73024
2780.1	3.89589
2782.76	3.53331
2785.42	3.13977
2788.09	1.43587
2790.75	-0.188729
2793.41	-0.571129
2796.07	-1.1982
2798.73	-0.648515
2801.39	-0.348499
2804.04	0.109808
2806.7	1.23038
2809.35	1.52095
2812.01	1.00556
2814.66	1.63976
2817.31	2.3573
2819.96	3.61138
2822.61	5.30177
2825.26	7.95071
2827.91	10.067
2830.56	12.6198
2833.21	15.4826
2835.85	18.8834
2838.5	21.9215
2841.14	26.8061
2843.78	30.3796
2846.42	34.9573
2849.06	40.6704
2851.71	45.0988
2854.34	50.4089
2856.98	57.0856
2859.62	63.0397
2862.26	68.9193
2864.89	74.2351
2867.53	78.1602
2870.16	82.9247
2872.79	86.0553
2875.42	88.1335
2878.05	91.2186
2880.68	95.7697
2883.31	98.4177
2885.94	101.683
2888.57	104.94
2891.19	107.603
2893.82	110.924
2896.44	115.142
2899.07	119.85
2901.69	124.536
2904.31	128.915
2906.93	135.185
2909.55	142.794
2912.17	150.532
2914.79	157.447
2917.41	164.233
2920.02	170.58
2922.64	175.859
2925.25	178.909
2927.86	181.329
2930.48	181.715
2933.09	181.86
2935.7	181.42
2938.31	178.782
2940.92	176.482
2943.53	172.779
2946.13	166.735
2948.74	160.553
2951.34	154.52
2953.95	148.732
2956.55	143.167
2959.15	137.024
2961.75	130.544
2964.35	124.909
2966.95	118.685
2969.55	114.181
2972.15	110.449
2974.75	106.101
2977.34	100.107
2979.94	94.3833
2982.53	88.1446
2985.13	80.4869
2987.72	74.3001
2990.31	67.9372
2992.9	62.0155
2995.49	55.7499
2998.08	50.1294
3000.67	44.0975
3003.25	38.9453
3005.84	33.5916
3008.42	27.4225
3011.01	23.6058
3013.59	19.6163
3016.17	16.2133
3018.76	13.8361
3021.34	10.9135
3023.92	8.63286
3026.49	7.1367
3029.07	6.391
3031.65	6.86303
3034.23	8.42068
3036.8	9.64551
3039.38	10.244
3041.95	10.7295
3044.52	12.1263
3047.09	13.0433
3049.66	14.5745
3052.23	16.3858
3054.8	16.4752
3057.37	16.232
3059.94	16.4682
3062.5	15.6021
3065.07	14.5991
3067.63	13.8503
3070.2	12.8592
3072.76	11.3577
3075.32	9.6336
3077.88	7.52277
3080.44	5.64154
3083	4.69235
3085.56	2.5628
3088.12	0.689315
3090.67	-0.511902
3093.23	-0.477074
3095.78	-0.296175
3098.34	0.0553476
3100.89	0.0900803
3103.44	0.764135
3105.99	1.92389
3108.54	3.01548
3111.09	3.40715
3113.64	3.39776
3116.19	4.59632
3118.74	4.64732
3121.28	5.53802
3123.83	6.39655
3126.37	7.42827
3128.91	8.66001
3131.46	10.4678
3134	10.6968
3136.54	11.9624
3139.08	12.3793
3141.62	13.5221
3144.16	14.2881
3146.69	14.8839
3149.23	18.3017