File: data/Raman/poly_smoothed/Thy_40_11_44_1x_45s_532 nm_x100_100%_600 gr_mm_01.txt
#Acq. time (s)=	45
#Accumulations=	2
#Range (cm-¹)=	200...3150
#Windows=	2
#Auto scanning=	Off
#Autofocus=	Off
#Macrospot=	Off
#AutoExposure=	Off
#Spike filter=	Multiple accum.
#Delay time (s)=	0
#Binning=	1
#Readout mode=	Signal
#DeNoise=	Off
#ICS correction=	On
#Dark correction=	Off
#Inst. Process=	Off
#Detector Gain=	Best Dynamic Range
#Detector ADC=	20 kHz
#Detector temperature (°C)=	-69.85
#Instrument=	LabRAM HR Evol
#Detector=	Synapse
#Objective=	x100
#Grating=	600 gr/mm
#ND Filter=	100%
#Laser (nm)=	532
#Hole=	100.021
#Range=	Auto
#Laser Pol.=	No
#Raman. Pol.=	No
#Laser Pol. (°)=	-0.0007625
#Raman Pol. (°)=	89.9995
#Collection=	Microscope
#StageXY=	Marzhauser
#StageZ=	Marzhauser
#X (µm)=	255.8
#Y (µm)=	1678.8
#Z (µm)=	426.75
#Full time(mm:ss)=	3:18
#Project=
#Sample=
#Site=
#Title=	Thy_40_11_44_2x_45s_532 nm_x100_100%_600 gr_mm
#Remark=
#Date=	05.07.2022 13:07
#Acquired=	05.07.2022 13:07:43
#Base:Fit=	10.08.2022 10:01:35
#Base:Sub=	10.08.2022 10:01:52
#Filter:Polynom=	16.08.2022 10:21:53
#AxisType[0]=Intens
#AxisUnit[0]=Cnt
#AxisType[1]=Spectr
#AxisUnit[1]=1/cm
200.43	1.93907
204.059	2.54631
207.688	4.12025
211.314	4.29211
214.941	4.09879
218.564	5.05295
222.186	4.70442
225.809	3.95272
229.428	3.85916
233.045	3.6285
236.663	2.75734
240.278	3.6938
243.891	2.62628
247.503	3.18586
251.116	3.66034
254.725	3.47506
258.333	2.8274
261.939	2.21049
265.544	3.55318
269.148	5.11682
272.75	4.85081
276.351	3.79145
279.95	2.88928
283.548	3.32468
287.144	1.83347
290.739	1.98407
294.333	2.02257
297.925	2.21205
301.514	1.51093
305.104	2.30423
308.692	2.78233
312.279	2.80095
315.862	4.18303
319.446	4.17602
323.029	4.19907
326.608	5.42123
330.188	5.20054
333.766	5.71891
337.341	6.7221
340.917	7.08355
344.489	7.34531
348.062	6.74389
351.631	7.1753
355.201	7.19777
358.768	7.11664
362.333	7.36562
365.899	7.17046
369.462	5.69006
373.023	5.93682
376.585	6.30459
380.143	7.64042
383.7	8.15542
387.256	8.77825
390.812	8.13203
394.365	7.87278
397.916	7.42033
401.467	8.08188
405.015	6.68702
408.563	6.59296
412.109	7.31677
415.654	7.15245
419.197	7.0841
422.739	7.40675
426.279	6.83441
429.819	6.23746
433.356	5.48128
436.891	4.405
440.426	4.7976
443.96	4.96502
447.492	6.93325
451.021	6.51731
454.551	6.02957
458.079	6.13139
461.604	8.37465
465.13	10.2406
468.654	11.0271
472.175	11.0458
475.696	11.4269
479.215	11.3739
482.733	12.2499
486.249	13.5403
489.765	15.3647
493.278	15.9174
496.789	17.9808
500.301	19.4884
503.81	20.3998
507.317	21.5999
510.825	21.606
514.33	21.7897
517.833	22.0031
521.335	21.4786
524.836	21.2485
528.335	21.2073
531.835	20.8962
535.332	19.6768
538.827	18.8703
542.321	18.7827
545.814	17.8023
549.305	17.1958
552.795	15.4543
556.282	13.4174
559.769	11.5089
563.255	12.4344
566.739	11.7593
570.223	10.6679
573.705	10.0294
577.183	7.96572
580.663	7.01233
584.141	6.95062
587.615	6.50999
591.09	7.75188
594.564	6.863
598.035	6.92762
601.506	6.97475
604.974	7.56453
608.443	8.37291
611.908	10.0784
615.374	11.5325
618.837	11.8982
622.3	13.0029
625.761	13.9676
629.219	15.1566
632.677	14.7824
636.135	16.375
639.59	17.5454
643.043	17.9326
646.495	20.0771
649.948	20.4722
653.398	19.9482
656.846	19.4872
660.293	20.2405
663.738	19.7248
667.183	21.2854
670.626	22.8275
674.067	24.4633
677.508	25.72
680.947	26.5285
684.385	29.6852
687.821	31.1219
691.254	33.9708
694.688	37.8334
698.121	40.0409
701.552	41.5221
704.98	43.3131
708.409	46.6099
711.836	47.8246
715.26	49.737
718.685	51.5457
722.108	52.3814
725.528	53.3981
728.949	55.1461
732.367	57.0959
735.785	58.9961
739.2	60.9907
742.614	63.1053
746.028	64.2098
749.439	66.1635
752.849	66.6179
756.26	67.0167
759.667	66.5193
763.073	67.7461
766.477	68.9472
769.883	70.6128
773.285	73.6795
776.686	75.3539
780.085	78.4318
783.484	78.1285
786.881	80.3575
790.276	82.28
793.671	83.7693
797.064	84.8383
800.456	86.1092
803.846	88.041
807.234	89.8627
810.622	91.9692
814.008	94.8196
817.394	96.9737
820.778	96.5848
824.159	96.1051
827.541	95.773
830.921	95.2311
834.298	94.508
837.676	91.9266
841.051	90.8423
844.426	89.7118
847.798	87.5481
851.171	85.8531
854.54	84.4825
857.911	81.1223
861.278	79.6963
864.645	75.8503
868.01	72.7936
871.373	71.4871
874.735	68.9027
878.097	68.0253
881.457	66.2944
884.815	63.9394
888.172	62.861
891.528	60.4864
894.882	60.1685
898.237	59.273
901.589	57.4782
904.94	56.7628
908.289	56.0446
911.635	54.9443
914.982	53.9843
918.328	53.6338
921.672	52.9746
925.015	52.6121
928.357	52.0267
931.698	50.3866
935.035	50.0089
938.373	48.1713
941.71	46.499
945.044	45.7265
948.378	42.9364
951.709	43.1144
955.041	42.7969
958.372	44.5427
961.699	45.293
965.027	45.4231
968.352	45.2736
971.676	47.8288
975	49.0838
978.322	51.1468
981.642	50.6648
984.962	52.0449
988.28	50.9233
991.596	51.5696
994.911	50.7948
998.227	51.0108
1001.54	50.493
1004.85	49.841
1008.16	49.4133
1011.47	49.0431
1014.78	45.7554
1018.08	44.8901
1021.39	43.6211
1024.69	41.6313
1028	41.7391
1031.3	41.6285
1034.6	41.4159
1037.9	41.7478
1041.19	41.6659
1044.49	40.4443
1047.78	39.4358
1051.08	38.8381
1054.37	38.3649
1057.66	37.8523
1060.95	35.192
1064.24	33.7274
1067.53	33.2131
1070.81	31.7829
1074.1	30.3201
1077.38	29.6529
1080.66	28.8743
1083.94	27.4618
1087.22	27.8523
1090.5	27.851
1093.78	27.7841
1097.05	28.0682
1100.33	27.7137
1103.6	27.784
1106.87	28.7114
1110.14	28.2469
1113.41	26.8225
1116.68	24.5249
1119.95	23.4912
1123.21	22.4094
1126.48	19.8789
1129.74	18.5189
1133	18.0547
1136.26	16.0718
1139.52	12.299
1142.78	10.7776
1146.04	10.6298
1149.29	8.2135
1152.55	6.62675
1155.8	5.54958
1159.05	3.88556
1162.3	3.11399
1165.55	2.15359
1168.8	2.32226
1172.05	4.27264
1175.29	5.15226
1178.54	6.30792
1181.78	5.42724
1185.02	7.92779
1188.26	10.1442
1191.5	11.5002
1194.74	15.2306
1197.97	17.5109
1201.21	20.7306
1204.44	23.4049
1207.68	25.4895
1210.91	26.4335
1214.14	28.9167
1217.37	32.2629
1220.59	36.6594
1223.82	40.5418
1227.05	43.4862
1230.27	45.6641
1233.49	47.6837
1236.72	49.2847
1239.94	52.1821
1243.16	54.8657
1246.37	56.5085
1249.59	59.053
1252.8	59.1863
1256.02	60.0751
1259.23	61.1036
1262.44	64.2141
1265.66	65.5454
1268.86	66.5768
1272.07	67.0465
1275.28	69.7103
1278.48	69.9487
1281.69	72.0864
1284.89	72.6635
1288.09	73.5958
1291.29	74.6441
1294.49	77.3384
1297.69	78.162
1300.89	79.0364
1304.08	77.9796
1307.28	79.0699
1310.47	79.2984
1313.66	79.3876
1316.85	78.2966
1320.04	78.28
1323.23	75.7998
1326.42	74.7946
1329.61	73.7295
1332.79	71.4994
1335.97	70.8134
1339.16	68.7523
1342.34	67.5468
1345.52	65.4904
1348.7	63.8464
1351.87	61.598
1355.05	59.2982
1358.22	56.2666
1361.4	53.5602
1364.57	51.2867
1367.74	49.9772
1370.91	46.476
1374.08	44.5997
1377.25	41.518
1380.41	39.4714
1383.58	36.8662
1386.74	35.9764
1389.91	34.4296
1393.07	32.9864
1396.23	31.5185
1399.39	31.0087
1402.55	30.2722
1405.7	30.8827
1408.86	31.7256
1412.01	32.6642
1415.17	34.5946
1418.32	37.6699
1421.47	40.3434
1424.62	42.8925
1427.77	47.4639
1430.91	50.423
1434.06	56.2444
1437.2	60.7141
1440.35	65.5108
1443.49	68.3522
1446.63	70.6402
1449.77	71.6242
1452.91	71.8763
1456.05	71.245
1459.18	69.6579
1462.32	67.4595
1465.45	64.1144
1468.59	60.1044
1471.72	54.399
1474.85	48.4322
1477.98	43.3438
1481.1	37.7457
1484.23	32.0991
1487.36	25.6599
1490.48	22.6072
1493.61	19.3538
1496.73	17.2089
1499.85	16.1307
1502.97	15.8221
1506.09	14.6542
1509.2	13.836
1512.32	15.1184
1515.43	14.5008
1518.55	15.6819
1521.66	16.851
1524.77	18.0689
1527.88	19.5184
1530.99	20.1116
1534.1	22.1579
1537.21	22.5626
1540.31	23.7377
1543.42	26.9801
1546.52	28.1419
1549.62	29.5949
1552.72	33.065
1555.82	36.7269
1558.92	38.8221
1562.02	42.0797
1565.11	43.5032
1568.21	45.8451
1571.3	47.3434
1574.39	49.0668
1577.49	51.1069
1580.57	53.1369
1583.66	54.5461
1586.75	56.5422
1589.84	57.0648
1592.92	57.974
1596.01	59.661
1599.09	59.0237
1602.17	58.8597
1605.25	59.0358
1608.33	57.6357
1611.41	56.9808
1614.49	57.6893
1617.57	56.8443
1620.64	57.0371
1623.72	58.336
1626.79	60.0973
1629.86	62.116
1632.93	64.0864
1636	66.6045
1639.07	68.8629
1642.13	69.8325
1645.2	71.4458
1648.26	73.6927
1651.33	76.17
1654.39	77.0903
1657.45	78.5192
1660.51	78.5914
1663.57	78.4508
1666.63	76.1842
1669.68	74.5405
1672.74	71.0941
1675.79	67.1664
1678.85	63.715
1681.9	58.3576
1684.95	51.7852
1688	46.0746
1691.05	40.2123
1694.09	34.5113
1697.14	29.7584
1700.18	25.2863
1703.23	21.2454
1706.27	19.3378
1709.31	16.7136
1712.35	14.2415
1715.39	10.682
1718.43	7.932
1721.47	6.80755
1724.5	5.86403
1727.54	4.07822
1730.57	4.35126
1733.61	4.67759
1736.64	3.94998
1739.67	4.08438
1742.7	4.71614
1745.72	4.72429
1748.75	3.96769
1751.77	4.09157
1754.8	4.14304
1757.82	3.52036
1760.84	2.88432
1763.87	2.38574
1766.89	1.68027
1769.91	1.33882
1772.92	1.89299
1775.94	0.842819
1778.95	0.118081
1781.97	-0.307093
1784.98	-1.64277
1787.99	-1.59159
1791.01	-2.08606
1794.01	-2.20862
1797.02	-1.95805
1800.03	-1.98502
1803.04	-2.06802
1806.04	-1.81904
1809.05	-1.77835
1812.05	-1.36669
1815.05	-0.637239
1818.05	-0.670949
1821.05	-0.370905
1824.05	0.159759
1827.05	0.874886
1830.04	0.937691
1833.04	0.380987
1836.03	1.74456
1839.03	1.94823
1842.02	2.30516
1845.01	2.79451
1848	2.60899
1850.99	3.19312
1853.97	3.31373
1856.96	3.36069
1859.94	3.56131
1862.93	3.64873
1865.91	3.95745
1868.89	3.77853
1871.87	3.54322
1874.85	3.30692
1877.83	3.52572
1880.81	3.53941
1882.57	4.31868
1885.56	4.45363
1888.55	4.63585
1891.54	4.69131
1894.52	3.74084
1897.51	2.79848
1900.49	2.38812
1903.47	2.34285
1906.45	3.22979
1909.43	3.49682
1912.41	4.07811
1915.39	3.29467
1918.37	3.88919
1921.34	4.24997
1924.32	4.71738
1927.29	4.88644
1930.26	4.66962
1933.23	4.12328
1936.2	4.23978
1939.17	4.11479
1942.14	4.42211
1945.11	4.56031
1948.07	4.59925
1951.04	4.65237
1954	4.52176
1956.96	4.33645
1959.93	3.75845
1962.89	4.14108
1965.85	3.31739
1968.8	2.73158
1971.76	2.50923
1974.72	2.93695
1977.67	2.67082
1980.63	2.39228
1983.58	2.83313
1986.53	2.5927
1989.48	3.75999
1992.43	4.42508
1995.38	4.81259
1998.32	5.64456
2001.27	5.28103
2004.22	5.61511
2007.16	5.57063
2010.1	6.21394
2013.04	7.05748
2015.98	7.05153
2018.92	6.43422
2021.86	5.55904
2024.8	5.28258
2027.74	5.45612
2030.67	5.26221
2033.61	5.72806
2036.54	5.36048
2039.47	5.03064
2042.4	4.87822
2045.33	4.79143
2048.26	5.44027
2051.19	5.12981
2054.12	5.68096
2057.04	5.85193
2059.97	6.51202
2062.89	7.78454
2065.81	8.78945
2068.73	9.64287
2071.65	10.934
2074.57	11.795
2077.49	13.0261
2080.41	14.5493
2083.32	15.8752
2086.24	16.597
2089.15	18.4203
2092.07	19.086
2094.98	20.4501
2097.89	21.5565
2100.8	23.1442
2103.71	24.8708
2106.61	26.1337
2109.52	28.5092
2112.43	29.734
2115.33	31.2744
2118.23	33.3178
2121.13	35.3806
2124.04	38.8844
2126.94	41.1162
2129.83	44.5375
2132.73	48.9328
2135.63	52.0627
2138.53	55.3542
2141.42	59.3879
2144.31	63.3725
2147.21	67.317
2150.1	71.721
2152.99	74.3961
2155.88	77.1058
2158.77	81.3403
2161.65	84.0714
2164.54	86.562
2167.43	88.731
2170.31	90.2671
2173.19	92.1512
2176.07	92.6374
2178.96	92.1171
2181.84	91.8647
2184.72	90.5451
2187.59	88.6263
2190.47	86.8745
2193.35	84.9841
2196.22	82.3112
2199.09	78.5151
2201.97	74.8368
2204.84	70.943
2207.71	67.6052
2210.58	63.7134
2213.45	60.8464
2216.31	56.484
2219.18	51.8969
2222.05	47.8849
2224.91	44.9528
2227.78	42.2118
2230.64	38.5899
2233.5	35.7381
2236.36	34.2868
2239.22	31.7203
2242.08	30.1577
2244.93	29.4256
2247.79	28.1198
2250.64	26.4486
2253.5	25.0837
2256.35	23.9256
2259.2	23.357
2262.05	21.9206
2264.9	21.8934
2267.75	21.0664
2270.6	20.3701
2273.45	19.4387
2276.29	18.606
2279.14	17.1757
2281.98	16.8645
2284.82	15.7109
2287.66	13.8601
2290.5	13.1697
2293.34	11.5211
2296.18	10.6801
2299.02	9.10548
2301.86	9.5411
2304.69	10.1888
2307.53	10.0501
2310.36	10.4635
2313.19	10.3431
2316.02	9.68474
2318.85	9.10887
2321.68	8.64061
2324.51	8.67111
2327.34	7.6565
2330.16	7.07885
2332.99	6.81178
2335.81	7.04178
2338.64	5.92116
2341.46	4.37927
2344.28	4.0735
2347.1	3.27885
2349.92	2.16273
2352.74	0.585844
2355.55	-0.163032
2358.37	-0.0816823
2361.19	-0.361408
2364	-0.367048
2366.81	0.262036
2369.62	1.55608
2372.44	2.62418
2375.24	3.00996
2378.05	3.40224
2380.86	4.13891
2383.67	4.03806
2386.47	4.18951
2389.28	4.6755
2392.08	5.13082
2394.89	5.73718
2397.69	6.16168
2400.49	6.93828
2403.29	7.43661
2406.09	6.8399
2408.88	6.25254
2411.68	7.11516
2414.48	6.90575
2417.27	7.04878
2420.06	7.70651
2422.86	7.73534
2425.65	8.77148
2428.44	8.73513
2431.23	9.16714
2434.02	9.42667
2436.81	10.351
2439.59	10.6684
2442.38	9.44123
2445.16	10.3481
2447.95	11.0178
2450.73	11.0434
2453.51	11.1131
2456.29	10.7673
2459.07	11.2774
2461.85	10.7325
2464.63	10.2904
2467.4	9.39336
2470.18	7.35869
2472.95	5.63492
2475.73	4.68856
2478.5	4.84444
2481.27	3.69613
2484.04	3.13427
2486.81	3.41449
2489.58	2.78043
2492.35	3.00525
2495.12	2.81469
2497.88	2.95836
2500.65	3.3124
2503.41	2.69383
2506.17	3.10925
2508.94	3.55592
2511.7	5.90054
2514.46	6.47529
2517.22	6.99761
2519.97	7.44125
2522.73	7.40274
2525.49	8.10895
2528.24	7.135
2530.99	6.48154
2533.75	6.28307
2536.5	6.13722
2539.25	7.13868
2542	7.31518
2544.75	6.7486
2547.5	6.33706
2550.24	5.69806
2552.99	5.49299
2555.74	4.63313
2558.48	4.79399
2561.22	4.55562
2563.96	4.61847
2566.71	4.69574
2569.45	4.57997
2572.18	4.61921
2574.92	6.23896
2577.66	6.16692
2580.4	6.7405
2583.13	6.26256
2585.87	6.42692
2588.6	6.40991
2591.33	7.38698
2594.06	8.25748
2596.79	8.25635
2599.52	9.29824
2602.25	10.4214
2604.98	10.8406
2607.71	11.0232
2610.43	10.6416
2613.16	9.85945
2615.88	8.99965
2618.6	8.6041
2621.32	7.78061
2624.04	7.67773
2626.76	7.24918
2629.48	6.51082
2632.2	6.72937
2634.92	6.10363
2637.63	5.76712
2640.35	6.03181
2643.06	5.3398
2645.77	5.53246
2648.49	5.10367
2651.2	4.96468
2653.91	4.45657
2656.62	4.31001
2659.33	5.34439
2662.03	5.36901
2664.74	5.48983
2667.44	6.73615
2670.15	6.92176
2672.85	6.84636
2675.55	6.58632
2678.26	7.43487
2680.96	6.77042
2683.66	7.16242
2686.35	7.21485
2689.05	7.52347
2691.75	8.87738
2694.44	8.62733
2697.14	9.35787
2699.83	9.66434
2702.52	9.68472
2705.22	9.72091
2707.91	9.51195
2710.6	9.45555
2713.29	9.70957
2715.97	9.35774
2718.66	9.51038
2721.35	10.0875
2724.03	10.8479
2726.72	11.6449
2729.4	11.3675
2732.08	11.1041
2734.76	10.7828
2737.44	10.017
2740.12	9.4776
2742.8	9.52885
2745.48	9.47936
2748.16	8.81086
2750.83	8.61843
2753.51	8.92133
2756.18	8.67644
2758.85	7.8254
2761.53	6.5107
2764.2	6.11917
2766.87	5.68601
2769.54	5.16825
2772.2	5.19811
2774.87	4.79791
2777.54	5.24973
2780.2	5.22279
2782.87	4.58395
2785.53	4.44898
2788.19	3.44439
2790.85	3.54614
2793.51	2.47632
2796.17	1.46931
2798.83	1.35824
2801.49	0.711166
2804.15	0.901139
2806.8	0.45886
2809.46	-0.180251
2812.11	0.385115
2814.76	0.544136
2817.42	0.335547
2820.07	1.43762
2822.72	1.74957
2825.37	3.93235
2828.02	6.00086
2830.66	8.89022
2833.31	11.3955
2835.96	15.0177
2838.6	18.8056
2841.24	22.3494
2843.89	27.4231
2846.53	32.8846
2849.17	38.9044
2851.81	45.2107
2854.45	52.0357
2857.09	58.9156
2859.72	65.8172
2862.36	72.6507
2865	79.1588
2867.63	84.304
2870.26	90.1518
2872.9	94.8164
2875.53	99.8027
2878.16	104.344
2880.79	107.711
2883.42	111.286
2886.05	114.858
2888.67	117.857
2891.3	121.195
2893.92	124.868
2896.55	128.695
2899.17	133.127
2901.79	139.335
2904.42	146.563
2907.04	155.86
2909.66	166.705
2912.27	177.491
2914.89	187.753
2917.51	197.757
2920.13	206.939
2922.74	215.195
2925.35	221.722
2927.97	226.7
2930.58	230.171
2933.19	232.484
2935.8	233.729
2938.41	232.094
2941.02	229.015
2943.63	223.643
2946.24	216.993
2948.84	208.656
2951.45	200.774
2954.05	192.244
2956.65	182.75
2959.26	173.892
2961.86	164.643
2964.46	155.905
2967.06	148.41
2969.66	140.821
2972.25	133.367
2974.85	124.89
2977.45	117.432
2980.04	109.46
2982.64	102.56
2985.23	93.6442
2987.82	85.3963
2990.41	78.2128
2993	70.6234
2995.59	63.0195
2998.18	55.5288
3000.77	48.2826
3003.36	41.5287
3005.94	35.7764
3008.53	30.3042
3011.11	25.8176
3013.69	22.3427
3016.28	19.2334
3018.86	16.9223
3021.44	14.5071
3024.02	12.9384
3026.6	11.1093
3029.18	9.94532
3031.75	9.45941
3034.33	10.1446
3036.9	10.2539
3039.48	11.3762
3042.05	12.3856
3044.62	13.1854
3047.19	13.5202
3049.77	13.5301
3052.34	15.0808
3054.9	15.3541
3057.47	14.4378
3060.04	13.6606
3062.61	12.6339
3065.17	12.4281
3067.74	10.8746
3070.3	9.75605
3072.86	8.6114
3075.42	6.68617
3077.99	6.48151
3080.54	5.27213
3083.1	3.10235
3085.66	2.229
3088.22	1.11621
3090.78	0.617815
3093.33	0.511336
3095.89	1.06444
3098.44	1.30596
3100.99	2.54866
3103.54	3.19125
3106.1	4.03524
3108.65	4.92559
3111.2	5.25108
3113.74	6.45328
3116.29	7.78631
3118.84	8.43824
3121.38	9.12908
3123.93	9.68349
3126.47	10.8655
3129.01	11.3899
3131.56	12.1414
3134.1	13.1188
3136.64	13.8575
3139.18	15.0972
3141.72	16.1374
3144.26	17.6586
3146.79	19.1633
3149.33	21.4525