File: data/Raman/poly_smoothed/Thy_40_11_45_1x_45s_532 nm_x100_100%_600 gr_mm_01.txt
#Acq. time (s)=	45
#Accumulations=	2
#Range (cm-¹)=	200...3150
#Windows=	2
#Auto scanning=	Off
#Autofocus=	Off
#Macrospot=	Off
#AutoExposure=	Off
#Spike filter=	Multiple accum.
#Delay time (s)=	0
#Binning=	1
#Readout mode=	Signal
#DeNoise=	Off
#ICS correction=	On
#Dark correction=	Off
#Inst. Process=	Off
#Detector Gain=	Best Dynamic Range
#Detector ADC=	20 kHz
#Detector temperature (°C)=	-69.85
#Instrument=	LabRAM HR Evol
#Detector=	Synapse
#Objective=	x100
#Grating=	600 gr/mm
#ND Filter=	100%
#Laser (nm)=	532
#Hole=	100.021
#Range=	Auto
#Laser Pol.=	No
#Raman. Pol.=	No
#Laser Pol. (°)=	-0.0007625
#Raman Pol. (°)=	89.9995
#Collection=	Microscope
#StageXY=	Marzhauser
#StageZ=	Marzhauser
#X (µm)=	258.5
#Y (µm)=	1688
#Z (µm)=	427.4
#Full time(mm:ss)=	3:18
#Project=
#Sample=
#Site=
#Title=	Thy_40_11_45_2x_45s_532 nm_x100_100%_600 gr_mm
#Remark=
#Date=	05.07.2022 13:12
#Acquired=	05.07.2022 13:12:48
#Base:Fit=	10.08.2022 10:01:35
#Base:Sub=	10.08.2022 10:01:52
#Filter:Polynom=	16.08.2022 10:21:53
#AxisType[0]=Intens
#AxisUnit[0]=Cnt
#AxisType[1]=Spectr
#AxisUnit[1]=1/cm
200.43	11.477
204.059	10.9768
207.688	10.8459
211.314	10.6321
214.941	9.27392
218.564	8.50731
222.186	7.08132
225.809	6.01867
229.428	7.23081
233.045	7.26438
236.663	6.62815
240.278	6.31637
243.891	6.42676
247.503	6.20886
251.116	6.0362
254.725	5.12403
258.333	3.18089
261.939	3.30681
265.544	4.14799
269.148	3.49461
272.75	3.02339
276.351	4.51976
279.95	4.06554
283.548	3.43556
287.144	4.59429
290.739	5.46884
294.333	5.78288
297.925	5.07365
301.514	5.36437
305.104	5.77902
308.692	8.05835
312.279	8.85712
315.862	11.0569
319.446	12.6221
323.029	14.1205
326.608	14.7164
330.188	16.0318
333.766	17.034
337.341	16.2719
340.917	16.5768
344.489	16.0779
348.062	14.3169
351.631	14.3631
355.201	15.2712
358.768	13.631
362.333	13.5391
365.899	11.8423
369.462	9.38942
373.023	8.9154
376.585	8.62898
380.143	7.74073
383.7	4.92704
387.256	4.92396
390.812	4.37849
394.365	5.15005
397.916	4.87415
401.467	4.7798
405.015	5.94605
408.563	7.24857
412.109	6.83014
415.654	6.57653
419.197	7.59676
422.739	8.45332
426.279	9.54226
429.819	10.2478
433.356	10.1775
436.891	10.2708
440.426	11.922
443.96	11.5864
447.492	12.9395
451.021	13.724
454.551	13.9679
458.079	13.4379
461.604	13.9018
465.13	14.0595
468.654	14.3349
472.175	14.5707
475.696	14.9371
479.215	16.2619
482.733	17.6813
486.249	17.2247
489.765	18.5486
493.278	18.7313
496.789	18.8809
500.301	19.4825
503.81	19.763
507.317	20.4188
510.825	20.1206
514.33	21.0677
517.833	19.463
521.335	19.9305
524.836	20.6614
528.335	21.9111
531.835	21.3542
535.332	21.3153
538.827	19.268
542.321	17.0783
545.814	16.5052
549.305	15.3874
552.795	14.365
556.282	13.5138
559.769	11.4965
563.255	11.1666
566.739	10.9554
570.223	7.84313
573.705	5.95786
577.183	7.21069
580.663	5.27407
584.141	4.50351
587.615	4.5244
591.09	3.61529
594.564	2.34524
598.035	1.92951
601.506	2.57406
604.974	2.47144
608.443	3.98055
611.908	3.99974
615.374	4.8033
618.837	5.08263
622.3	4.10649
625.761	3.49255
629.219	4.25454
632.677	5.62937
636.135	7.19822
639.59	8.27555
643.043	8.99825
646.495	9.72417
649.948	9.46781
653.398	10.0021
656.846	11.9787
660.293	14.9805
663.738	16.0187
667.183	16.5955
670.626	17.2379
674.067	18.394
677.508	18.3486
680.947	18.1599
684.385	17.6464
687.821	18.7781
691.254	20.9048
694.688	22.8929
698.121	24.3871
701.552	26.1034
704.98	27.2964
708.409	29.8051
711.836	31.2757
715.26	34.4183
718.685	37.251
722.108	38.0512
725.528	39.2301
728.949	40.6778
732.367	41.5432
735.785	42.6465
739.2	45.9295
742.614	48.672
746.028	50.1552
749.439	52.0846
752.849	52.4031
756.26	53.5823
759.667	55.9468
763.073	55.8172
766.477	57.2142
769.883	59.4067
773.285	63.4286
776.686	65.1213
780.085	67.8471
783.484	70.6688
786.881	73.6969
790.276	74.5104
793.671	76.2833
797.064	77.4913
800.456	78.3682
803.846	78.4883
807.234	79.284
810.622	79.623
814.008	79.2591
817.394	80.1289
820.778	79.9723
824.159	81.035
827.541	80.1947
830.921	77.2884
834.298	74.8046
837.676	73.0192
841.051	72.6
844.426	70.2977
847.798	67.7415
851.171	66.185
854.54	64.6477
857.911	62.1131
861.278	60.8717
864.645	60.4918
868.01	58.4222
871.373	56.7806
874.735	54.9167
878.097	53.4766
881.457	52.5178
884.815	50.7001
888.172	50.4657
891.528	49.6324
894.882	48.6601
898.237	48.1843
901.589	47.9886
904.94	46.884
908.289	46.0799
911.635	44.2534
914.982	44.0409
918.328	45.1241
921.672	44.1877
925.015	43.9323
928.357	42.6286
931.698	40.8904
935.035	40.1368
938.373	39.6053
941.71	37.0088
945.044	36.2909
948.378	35.7467
951.709	35.3149
955.041	35.2316
958.372	34.6124
961.699	34.7907
965.027	34.4546
968.352	34.8142
971.676	35.2174
975	35.6635
978.322	36.5987
981.642	38.9055
984.962	38.2016
988.28	38.6513
991.596	37.9811
994.911	38.1642
998.227	37.8463
1001.54	37.2821
1004.85	36.1244
1008.16	33.3931
1011.47	31.2797
1014.78	30.053
1018.08	29.5441
1021.39	26.5684
1024.69	24.3702
1028	25.9903
1031.3	27.3307
1034.6	26.1487
1037.9	24.3465
1041.19	24.562
1044.49	24.4286
1047.78	24.8894
1051.08	24.519
1054.37	24.4423
1057.66	24.0758
1060.95	25.0844
1064.24	23.737
1067.53	22.8266
1070.81	22.3464
1074.1	20.8952
1077.38	20.5477
1080.66	18.2471
1083.94	17.0204
1087.22	16.8039
1090.5	16.2911
1093.78	16.6882
1097.05	16.1734
1100.33	15.6189
1103.6	15.3553
1106.87	17.6532
1110.14	18.9049
1113.41	18.1788
1116.68	16.3989
1119.95	15.7451
1123.21	16.1766
1126.48	16.4113
1129.74	14.5034
1133	13.7811
1136.26	13.8295
1139.52	13.1886
1142.78	11.7533
1146.04	11.773
1149.29	9.5532
1152.55	7.23416
1155.8	6.34577
1159.05	4.74042
1162.3	3.54036
1165.55	4.72285
1168.8	4.79778
1172.05	4.138
1175.29	3.92717
1178.54	4.76057
1181.78	5.27908
1185.02	6.60158
1188.26	6.74462
1191.5	5.96161
1194.74	6.20923
1197.97	8.40719
1201.21	9.27045
1204.44	11.6875
1207.68	12.639
1210.91	14.8191
1214.14	19.2338
1217.37	22.1882
1220.59	24.3846
1223.82	26.6393
1227.05	29.3465
1230.27	31.293
1233.49	34.2319
1236.72	37.9976
1239.94	41.3177
1243.16	44.2257
1246.37	47.1887
1249.59	48.4882
1252.8	49.4119
1256.02	51.7872
1259.23	51.3625
1262.44	52.2419
1265.66	53.3055
1268.86	54.0753
1272.07	55.6024
1275.28	58.0156
1278.48	59.5731
1281.69	61.9696
1284.89	62.9659
1288.09	64.1694
1291.29	67.4721
1294.49	69.6933
1297.69	69.9749
1300.89	71.1731
1304.08	73.246
1307.28	74.421
1310.47	74.8272
1313.66	75.7639
1316.85	76.7919
1320.04	75.9658
1323.23	75.1353
1326.42	74.4966
1329.61	72.6547
1332.79	70.4142
1335.97	68.1804
1339.16	65.9202
1342.34	63.5352
1345.52	59.3095
1348.7	55.4846
1351.87	52.7872
1355.05	50.1088
1358.22	47.7269
1361.4	43.4796
1364.57	39.9437
1367.74	37.0204
1370.91	33.3617
1374.08	31.0054
1377.25	28.3032
1380.41	26.2116
1383.58	25.0631
1386.74	24.1112
1389.91	22.1876
1393.07	21.0879
1396.23	22.2164
1399.39	21.4299
1402.55	20.8513
1405.7	20.969
1408.86	21.1209
1412.01	23.2556
1415.17	26.1748
1418.32	28.0362
1421.47	29.4491
1424.62	33.939
1427.77	38.8451
1430.91	43.2899
1434.06	48.2692
1437.2	53.0906
1440.35	55.8046
1443.49	58.9165
1446.63	61.0863
1449.77	62.473
1452.91	62.2883
1456.05	61.6338
1459.18	60.1959
1462.32	58.9268
1465.45	54.6335
1468.59	50.8302
1471.72	47.0783
1474.85	42.3359
1477.98	37.0894
1481.1	34.2353
1484.23	28.9283
1487.36	27.6572
1490.48	25.4464
1493.61	21.6396
1496.73	18.8001
1499.85	18.3576
1502.97	19.1065
1506.09	18.5771
1509.2	19.6043
1512.32	19.6214
1515.43	18.7544
1518.55	18.7918
1521.66	19.3906
1524.77	19.7397
1527.88	20.5598
1530.99	21.3532
1534.1	21.9225
1537.21	23.2866
1540.31	24.5103
1543.42	26.6877
1546.52	29.1989
1549.62	31.8626
1552.72	34.6183
1555.82	38.3474
1558.92	40.2566
1562.02	41.1247
1565.11	43.2164
1568.21	44.5205
1571.3	46.9553
1574.39	50.516
1577.49	53.8823
1580.57	55.8869
1583.66	56.8085
1586.75	57.6478
1589.84	57.8621
1592.92	59.7889
1596.01	60.453
1599.09	60.263
1602.17	59.5208
1605.25	59.0027
1608.33	58.4962
1611.41	59.1462
1614.49	60.1867
1617.57	60.7123
1620.64	62.2259
1623.72	62.6949
1626.79	65.1952
1629.86	67.6762
1632.93	68.7221
1636	69.2502
1639.07	72.8409
1642.13	76.5873
1645.2	80.8197
1648.26	83.5691
1651.33	87.14
1654.39	87.5074
1657.45	87.8205
1660.51	87.8684
1663.57	87.5903
1666.63	86.7526
1669.68	83.9395
1672.74	80.1895
1675.79	74.0382
1678.85	69.4771
1681.9	64.6047
1684.95	59.1848
1688	53.6471
1691.05	47.3814
1694.09	40.4412
1697.14	34.3013
1700.18	28.7729
1703.23	23.7498
1706.27	18.9685
1709.31	14.5259
1712.35	11.7877
1715.39	10.6161
1718.43	8.52465
1721.47	6.86883
1724.5	5.67265
1727.54	5.94765
1730.57	5.11434
1733.61	5.41948
1736.64	5.85359
1739.67	6.72296
1742.7	6.14881
1745.72	5.86134
1748.75	5.36731
1751.77	5.42309
1754.8	5.81518
1757.82	4.70315
1760.84	3.28527
1763.87	2.85324
1766.89	2.3563
1769.91	2.41703
1772.92	2.43392
1775.94	1.87357
1778.95	1.4956
1781.97	1.80008
1784.98	2.27022
1787.99	3.15827
1791.01	2.79847
1794.01	2.91767
1797.02	2.39828
1800.03	2.60028
1803.04	2.73215
1806.04	2.10036
1809.05	2.57547
1812.05	2.36808
1815.05	2.02891
1818.05	1.17206
1821.05	1.30575
1824.05	0.712791
1827.05	0.556615
1830.04	1.09055
1833.04	1.38491
1836.03	1.56824
1839.03	2.41001
1842.02	3.68064
1845.01	4.95106
1848	5.77536
1850.99	6.72832
1853.97	6.87699
1856.96	7.87242
1859.94	7.96671
1862.93	8.8019
1865.91	8.84665
1868.89	9.59809
1871.87	9.58376
1874.85	9.99342
1877.83	9.95783
1880.81	10.0107
1882.57	8.80338
1885.56	8.67127
1888.55	9.72221
1891.54	10.1388
1894.52	10.4001
1897.51	11.1577
1900.49	12.2814
1903.47	12.1496
1906.45	12.3125
1909.43	12.8539
1912.41	12.6771
1915.39	11.8352
1918.37	11.6186
1921.34	11.3001
1924.32	11.6386
1927.29	10.0122
1930.26	10.8185
1933.23	10.8627
1936.2	10.6266
1939.17	10.2159
1942.14	9.74722
1945.11	9.53118
1948.07	10.4695
1951.04	9.71357
1954	9.90563
1956.96	10.432
1959.93	11.2937
1962.89	11.9686
1965.85	12.1091
1968.8	12.8685
1971.76	13.1476
1974.72	12.913
1977.67	12.3312
1980.63	11.4898
1983.58	9.70395
1986.53	9.21216
1989.48	8.13737
1992.43	8.53492
1995.38	7.65666
1998.32	7.58674
2001.27	7.90121
2004.22	8.76624
2007.16	8.32511
2010.1	8.23896
2013.04	8.55398
2015.98	9.84657
2018.92	10.5629
2021.86	10.8913
2024.8	11.2404
2027.74	11.3528
2030.67	11.6697
2033.61	13.2418
2036.54	13.4473
2039.47	13.3341
2042.4	12.8743
2045.33	13.1061
2048.26	12.7229
2051.19	12.9918
2054.12	13.8304
2057.04	13.833
2059.97	14.8979
2062.89	15.1301
2065.81	15.6252
2068.73	17.2734
2071.65	18.9482
2074.57	20.1635
2077.49	20.8077
2080.41	21.5089
2083.32	22.5791
2086.24	23.489
2089.15	24.1991
2092.07	25.2502
2094.98	26.2134
2097.89	26.9065
2100.8	28.4498
2103.71	30.6216
2106.61	31.9271
2109.52	35.1403
2112.43	37.1445
2115.33	39.6616
2118.23	43.2528
2121.13	47.6837
2124.04	52.7995
2126.94	56.6794
2129.83	60.1152
2132.73	65.1756
2135.63	68.5859
2138.53	73.1014
2141.42	77.4205
2144.31	81.3617
2147.21	84.4341
2150.1	88.0041
2152.99	90.9725
2155.88	92.9349
2158.77	95.675
2161.65	98.3495
2164.54	100.875
2167.43	102.542
2170.31	102.642
2173.19	103.882
2176.07	104.139
2178.96	103.977
2181.84	101.99
2184.72	99.6444
2187.59	98.4402
2190.47	95.8306
2193.35	92.9909
2196.22	89.7999
2199.09	85.41
2201.97	81.3589
2204.84	77.8885
2207.71	73.0728
2210.58	68.1243
2213.45	63.6434
2216.31	59.7743
2219.18	55.9968
2222.05	52.9336
2224.91	49.5824
2227.78	47.0626
2230.64	43.9182
2233.5	42.1401
2236.36	39.1802
2239.22	36.0869
2242.08	34.2188
2244.93	32.8941
2247.79	31.4634
2250.64	29.8179
2253.5	29.124
2256.35	28.0275
2259.2	27.517
2262.05	25.7804
2264.9	24.6726
2267.75	23.6441
2270.6	23.6621
2273.45	21.9807
2276.29	21.2759
2279.14	20.0163
2281.98	18.9958
2284.82	18.1183
2287.66	18.3633
2290.5	16.9961
2293.34	14.949
2296.18	13.5025
2299.02	12.6532
2301.86	12.2022
2304.69	11.9879
2307.53	11.4142
2310.36	11.1373
2313.19	11.5931
2316.02	11.4488
2318.85	11.4745
2321.68	10.0346
2324.51	9.38382
2327.34	7.93622
2330.16	6.35608
2332.99	5.94943
2335.81	5.42532
2338.64	4.45783
2341.46	4.36639
2344.28	3.34496
2347.1	2.35636
2349.92	1.90382
2352.74	2.10395
2355.55	1.46113
2358.37	1.30136
2361.19	0.275343
2364	0.860967
2366.81	2.19001
2369.62	2.08993
2372.44	2.74694
2375.24	2.97103
2378.05	2.80591
2380.86	4.18262
2383.67	4.1432
2386.47	4.45335
2389.28	4.09041
2392.08	3.48662
2394.89	4.01963
2397.69	4.04022
2400.49	4.63271
2403.29	4.61246
2406.09	3.60433
2408.88	3.25964
2411.68	2.976
2414.48	2.51108
2417.27	1.77008
2420.06	2.2118
2422.86	1.47611
2425.65	0.57028
2428.44	0.592323
2431.23	0.768121
2434.02	1.64709
2436.81	1.28845
2439.59	1.15221
2442.38	1.22145
2445.16	1.28281
2447.95	1.90163
2450.73	2.68685
2453.51	3.07709
2456.29	3.33074
2459.07	3.17399
2461.85	3.47867
2464.63	4.17142
2467.4	3.63229
2470.18	4.2555
2472.95	3.50031
2475.73	3.26015
2478.5	3.04106
2481.27	3.22099
2484.04	2.18415
2486.81	1.99413
2489.58	1.54152
2492.35	1.20918
2495.12	1.52585
2497.88	2.01875
2500.65	2.63
2503.41	1.65136
2506.17	0.807303
2508.94	0.0949025
2511.7	0.019426
2514.46	0.227545
2517.22	0.636576
2519.97	0.244254
2522.73	-0.0357061
2525.49	0.0227484
2528.24	-0.219753
2530.99	-0.0294535
2533.75	-0.584166
2536.5	-1.05069
2539.25	0.175809
2542	-0.13169
2544.75	0.81267
2547.5	0.925538
2550.24	1.17879
2552.99	1.5828
2555.74	2.25946
2558.48	3.60118
2561.22	4.52036
2563.96	4.56024
2566.71	4.95084
2569.45	4.93895
2572.18	4.43677
2574.92	4.72489
2577.66	4.44756
2580.4	4.56595
2583.13	4.77409
2585.87	4.19973
2588.6	3.92213
2591.33	3.51454
2594.06	2.88864
2596.79	1.70493
2599.52	0.93411
2602.25	0.581225
2604.98	0.697993
2607.71	1.46348
2610.43	1.48975
2613.16	1.32184
2615.88	1.39371
2618.6	1.62204
2621.32	1.90096
2624.04	2.58148
2626.76	2.5555
2629.48	2.41791
2632.2	3.12823
2634.92	3.21945
2637.63	3.79914
2640.35	3.56054
2643.06	3.21236
2645.77	2.92245
2648.49	3.59512
2651.2	3.43383
2653.91	2.92087
2656.62	2.91044
2659.33	2.54831
2662.03	3.34658
2664.74	3.57487
2667.44	3.45856
2670.15	3.90775
2672.85	3.55648
2675.55	3.66482
2678.26	3.97138
2680.96	4.00333
2683.66	3.69982
2686.35	4.04852
2689.05	4.89155
2691.75	4.72466
2694.44	4.20837
2697.14	4.63813
2699.83	4.41662
2702.52	4.48485
2705.22	4.47558
2707.91	3.5539
2710.6	3.40436
2713.29	4.19065
2715.97	4.43897
2718.66	4.09443
2721.35	4.88201
2724.03	5.55651
2726.72	6.41614
2729.4	6.13896
2732.08	6.49318
2734.76	7.12209
2737.44	6.88761
2740.12	6.77914
2742.8	6.66579
2745.48	6.95915
2748.16	6.54787
2750.83	6.45578
2753.51	6.5802
2756.18	5.34254
2758.85	4.29902
2761.53	3.47956
2764.2	2.86135
2766.87	2.10108
2769.54	0.80263
2772.2	0.211239
2774.87	0.414622
2777.54	0.931446
2780.2	0.648005
2782.87	0.346166
2785.53	1.32411
2788.19	2.13553
2790.85	2.21566
2793.51	2.42671
2796.17	2.03441
2798.83	2.79375
2801.49	2.14705
2804.15	1.15197
2806.8	0.610443
2809.46	0.988462
2812.11	-0.0670258
2814.76	-0.0146547
2817.42	-0.0772234
2820.07	-0.168818
2822.72	1.54922
2825.37	4.71804
2828.02	7.6732
2830.66	12.1697
2833.31	16.4054
2835.96	21.0256
2838.6	26.5803
2841.24	31.7674
2843.89	38.1089
2846.53	45.5536
2849.17	53.7985
2851.81	62.5858
2854.45	70.7727
2857.09	79.8565
2859.72	88.3672
2862.36	97.207
2865	105.201
2867.63	111.861
2870.26	118.429
2872.9	124.628
2875.53	129.686
2878.16	133.631
2880.79	137.811
2883.42	142.155
2886.05	147.261
2888.67	152.574
2891.3	157.131
2893.92	161.495
2896.55	166.28
2899.17	171.321
2901.79	176.506
2904.42	183.813
2907.04	191.958
2909.66	202.135
2912.27	213.223
2914.89	224.133
2917.51	234.665
2920.13	244.546
2922.74	253.517
2925.35	260.688
2927.97	265.997
2930.58	268.744
2933.19	269.777
2935.8	270.246
2938.41	267.472
2941.02	262.47
2943.63	256.425
2946.24	248.728
2948.84	240.14
2951.45	231.351
2954.05	221.111
2956.65	209.846
2959.26	198.89
2961.86	187.096
2964.46	175.962
2967.06	165.689
2969.66	156.033
2972.25	146.197
2974.85	137.318
2977.45	128.559
2980.04	119.32
2982.64	110.479
2985.23	101.193
2987.82	91.1031
2990.41	81.6359
2993	72.7327
2995.59	64.935
2998.18	57.15
3000.77	49.9314
3003.36	43.0147
3005.94	36.5414
3008.53	31.778
3011.11	27.6149
3013.69	23.3831
3016.28	20.5109
3018.86	17.6447
3021.44	15.3145
3024.02	13.5087
3026.6	12.7736
3029.18	12.7267
3031.75	13.0162
3034.33	13.4987
3036.9	14.8918
3039.48	16.739
3042.05	17.7383
3044.62	18.6683
3047.19	19.5069
3049.77	19.4592
3052.34	18.6907
3054.9	18.5031
3057.47	17.2474
3060.04	16.0883
3062.61	15.6472
3065.17	13.4904
3067.74	12.2291
3070.3	10.3436
3072.86	8.9107
3075.42	7.01158
3077.99	5.30889
3080.54	4.30247
3083.1	3.01207
3085.66	2.038
3088.22	1.66832
3090.78	0.891438
3093.33	0.479889
3095.89	1.02888
3098.44	1.1421
3100.99	1.71828
3103.54	2.09123
3106.1	2.20561
3108.65	2.48344
3111.2	2.20162
3113.74	0.999763
3116.29	1.42306
3118.84	1.11247
3121.38	1.21096
3123.93	1.5286
3126.47	2.04903
3129.01	1.56484
3131.56	2.00991
3134.1	2.6393
3136.64	3.14248
3139.18	4.21195
3141.72	5.02757
3144.26	5.40963
3146.79	5.91057
3149.33	6.22913