File: data/Raman/poly_smoothed/Thy_00_07_28_1x_45s_532 nm_x100_100%_600 gr_mm_01.txt
#Acq. time (s)=	45
#Accumulations=	2
#Range (cm-¹)=	200...3150
#Windows=	2
#Auto scanning=	Off
#Autofocus=	Off
#Macrospot=	Off
#AutoExposure=	Off
#Spike filter=	Multiple accum.
#Delay time (s)=	0
#Binning=	1
#Readout mode=	Signal
#DeNoise=	Off
#ICS correction=	On
#Dark correction=	Off
#Inst. Process=	Off
#Detector Gain=	Best Dynamic Range
#Detector ADC=	20 kHz
#Detector temperature (°C)=	-69.85
#Instrument=	LabRAM HR Evol
#Detector=	Synapse
#Objective=	x100
#Grating=	600 gr/mm
#ND Filter=	100%
#Laser (nm)=	532
#Hole=	100.021
#Range=	Auto
#Laser Pol.=	No
#Raman. Pol.=	No
#Laser Pol. (°)=	-0.0007625
#Raman Pol. (°)=	89.9995
#Collection=	Microscope
#StageXY=	Marzhauser
#StageZ=	Marzhauser
#X (µm)=	8986.5
#Y (µm)=	-3066.7
#Z (µm)=	-55.15
#Full time(mm:ss)=	3:18
#Project=
#Sample=
#Site=
#Title=	Thy_00_07_28_2x_45s_532 nm_x100_100%_600 gr_mm
#Remark=
#Date=	28.06.2022 12:10
#Acquired=	28.06.2022 12:10:34
#Base:Fit=	10.08.2022 10:07:56
#Base:Sub=	10.08.2022 10:08:40
#Filter:Polynom=	16.08.2022 10:26:06
#AxisType[0]=Intens
#AxisUnit[0]=Cnt
#AxisType[1]=Spectr
#AxisUnit[1]=1/cm
200.407	47.8247
204.035	47.272
207.665	45.3144
211.291	43.7233
214.916	40.5624
218.541	38.5013
222.163	35.2229
225.785	32.2992
229.404	30.6616
233.022	28.6117
236.638	26.8167
240.255	24.904
243.868	23.5015
247.48	19.8302
251.091	15.1214
254.702	13.8871
258.31	12.398
261.916	11.0089
265.521	9.7198
269.125	8.14696
272.727	10.1678
276.328	8.99374
279.927	9.40366
283.525	9.81616
287.121	10.8764
290.716	11.1058
294.31	13.7328
297.9	14.3092
301.491	12.8183
305.081	14.2682
308.669	14.6373
312.256	15.7191
315.839	17.534
319.423	18.8285
323.006	18.4031
326.585	19.1677
330.165	20.0412
333.741	18.7876
337.318	17.8386
340.894	15.521
344.466	13.925
348.039	13.2317
351.608	12.2558
355.176	12.2529
358.745	11.3128
362.31	10.0561
365.876	8.79052
369.439	8.67996
373	7.18173
376.56	7.11446
380.12	6.4079
383.677	5.08037
387.233	3.70179
390.787	4.09004
394.34	3.55923
397.894	3.22561
401.444	4.1074
404.993	4.93135
408.54	4.92248
412.086	5.43419
415.631	5.90738
419.174	5.52762
422.716	5.20418
426.257	4.84613
429.794	3.09896
433.332	1.53359
436.868	1.92131
440.403	2.17724
443.937	4.30496
447.468	6.47913
450.999	10.6638
454.528	15.1606
458.057	18.2011
461.582	22.5077
465.107	27.7575
468.629	29.2708
472.152	31.776
475.672	34.5307
479.192	36.8617
482.709	38.2322
486.226	42.0596
489.74	43.453
493.255	43.9785
496.767	45.0219
500.277	43.8056
503.788	42.4171
507.295	39.5294
510.801	35.5092
514.308	30.9845
517.811	27.209
521.313	24.5841
524.814	21.5028
528.313	20.1712
531.811	19.8824
535.308	18.4572
538.803	16.7597
542.297	15.8777
545.789	13.9727
549.281	11.3486
552.771	10.1876
556.259	9.37604
559.747	8.39788
563.233	8.53314
566.717	10.6387
570.2	11.7283
573.68	13.1176
577.161	13.4765
580.64	13.4388
584.118	12.9618
587.593	11.7589
591.068	12.2728
594.54	11.22
598.013	10.3888
601.484	10.0197
604.952	9.38699
608.421	8.04476
611.886	7.32362
615.35	7.08006
618.815	7.15432
622.276	5.98404
625.738	5.42192
629.197	5.40667
632.655	4.21016
636.113	4.41031
639.568	5.77465
643.021	6.13492
646.473	7.05814
649.924	9.47245
653.376	10.4533
656.824	11.402
660.271	11.3771
663.716	10.6873
667.161	11.0091
670.604	11.5971
674.045	14.4079
677.486	15.8214
680.925	16.9186
684.361	20.9151
687.797	22.0857
691.232	23.8557
694.666	26.3387
698.099	26.7631
701.528	26.7355
704.958	27.9263
708.387	28.9499
711.814	30.2983
715.238	31.6683
718.663	32.4942
722.084	35.2516
725.506	38.7539
728.925	40.9235
732.345	42.4087
735.761	44.1792
739.178	44.5746
742.592	45.3331
746.006	47.9532
749.417	50.0057
752.827	53.4129
756.236	58.4754
759.645	62.1378
763.051	64.7177
766.456	69.8612
769.859	72.0303
773.261	73.1028
776.664	75.5329
780.064	77.293
783.462	76.9272
786.859	79.0136
790.255	80.2106
793.649	80.2802
797.042	81.2013
800.434	81.3679
803.823	83.0701
807.212	83.531
810.6	83.9697
813.987	84.4618
817.372	84.8322
820.754	86.0315
824.137	88.5119
827.519	91.134
830.897	94.5857
834.276	97.2691
837.654	100.481
841.029	102.014
844.404	102.182
847.776	101.484
851.149	100.657
854.519	98.2807
857.889	96.788
861.256	93.1122
864.622	90.1915
867.988	85.5556
871.351	81.5993
874.713	77.6049
878.074	71.1284
881.435	65.4297
884.794	60.1939
888.15	56.5809
891.506	53.4547
894.861	54.3149
898.214	52.9796
901.566	54.3245
904.916	56.4188
908.266	59.4282
911.614	64.0204
914.961	67.3044
918.306	68.636
921.651	71.136
924.994	71.8689
928.336	72.8993
931.674	72.5125
935.014	72.5752
938.352	72.0242
941.687	70.7257
945.022	69.0638
948.357	65.3265
951.688	63.0013
955.02	59.4627
958.348	52.9496
961.678	47.2959
965.004	44.9284
968.331	45.3678
971.655	45.9506
974.979	47.1497
978.3	48.2173
981.62	49.8663
984.941	51.5978
988.259	53.0434
991.575	53.3483
994.89	54.1742
998.204	54.6983
1001.52	54.5835
1004.83	54.7775
1008.14	56.0062
1011.45	56.2077
1014.76	55.8463
1018.06	55.5319
1021.37	54.0544
1024.67	52.3
1027.97	51.1555
1031.27	49.4839
1034.57	48.9757
1037.87	45.9116
1041.17	43.9926
1044.47	45.1873
1047.76	47.6656
1051.06	50.8424
1054.35	52.4847
1057.64	52.8654
1060.93	53.7617
1064.22	55.2722
1067.5	54.5714
1070.79	55.0195
1074.08	55.7905
1077.36	56.9043
1080.64	58.3221
1083.92	59.3604
1087.2	59.7829
1090.48	60.9106
1093.76	61.6949
1097.03	62.1163
1100.31	62.8581
1103.58	65.7562
1106.85	66.3574
1110.12	66.1533
1113.39	66.9598
1116.66	64.7581
1119.93	63.7545
1123.19	63.5013
1126.46	61.6337
1129.72	60.6436
1132.98	56.926
1136.24	53.8358
1139.5	52.1003
1142.76	49.5978
1146.01	46.1989
1149.27	44.42
1152.53	41.1384
1155.78	35.9985
1159.03	32.1689
1162.28	26.5507
1165.53	22.1721
1168.78	18.8652
1172.02	16.59
1175.27	15.5791
1178.51	14.6758
1181.76	13.8115
1185	13.4166
1188.24	11.9315
1191.48	12.6684
1194.71	12.8906
1197.95	14.8151
1201.19	16.8325
1204.42	18.6233
1207.65	21.4093
1210.88	25.1114
1214.12	30.9268
1217.35	36.4929
1220.57	42.7744
1223.8	48.1222
1227.03	53.5551
1230.25	56.82
1233.47	58.6751
1236.69	60.7766
1239.92	62.8498
1243.13	63.2655
1246.35	65.1376
1249.57	66.1238
1252.78	64.5994
1256	63.306
1259.21	61.5636
1262.42	61.0724
1265.63	60.3014
1268.84	58.1343
1272.05	58.5157
1275.26	58.7492
1278.46	59.5199
1281.67	60.6366
1284.87	62.1904
1288.07	63.288
1291.27	66.7903
1294.47	70.4038
1297.67	74.6951
1300.87	79.711
1304.06	84.009
1307.26	88.7475
1310.45	93.7031
1313.64	98.261
1316.83	104.862
1320.02	108.352
1323.21	110.239
1326.4	112.769
1329.59	111.892
1332.77	112.106
1335.95	112.179
1339.14	112.741
1342.32	110.637
1345.5	105.431
1348.67	102.837
1351.85	98.6896
1355.03	95.1496
1358.2	89.9673
1361.38	87.2613
1364.55	83.1737
1367.72	80.5983
1370.89	78.2823
1374.06	76.4014
1377.23	74.4791
1380.39	73.0842
1383.56	73.2823
1386.72	73.2854
1389.89	72.5773
1393.05	71.8142
1396.21	70.687
1399.37	67.2569
1402.52	65.8092
1405.68	64.3518
1408.84	62.7706
1411.99	64.1257
1415.15	65.3377
1418.3	67.0065
1421.45	69.8361
1424.6	73.2281
1427.75	79.5404
1430.89	87.2704
1434.04	94.5146
1437.18	100.322
1440.33	106.314
1443.47	110.936
1446.61	112.899
1449.75	114.483
1452.89	116.143
1456.03	112.56
1459.16	110.453
1462.3	106.43
1465.43	99.3922
1468.56	90.2424
1471.7	81.0339
1474.83	71.9945
1477.96	61.938
1481.08	54.0405
1484.21	43.4781
1487.34	35.8609
1490.46	29.1817
1493.58	24.0992
1496.71	20.6341
1499.83	17.0838
1502.95	15.8648
1506.07	13.9595
1509.18	12.8771
1512.3	11.2301
1515.41	11.8345
1518.53	13.111
1521.64	14.291
1524.75	15.5969
1527.86	18.7241
1530.97	21.0402
1534.08	23.3714
1537.19	26.9283
1540.29	28.7485
1543.4	30.1093
1546.5	32.4017
1549.6	35.8762
1552.7	39.3467
1555.8	43.8056
1558.9	47.7584
1562	49.3407
1565.09	52.4246
1568.19	56.1668
1571.28	58.2083
1574.37	60.8527
1577.47	62.4821
1580.56	65.0897
1583.64	67.5885
1586.73	69.0344
1589.82	70.6767
1592.9	73.2735
1595.99	75.7981
1599.07	75.1395
1602.15	75.5957
1605.23	75.4246
1608.31	74.5666
1611.39	74.459
1614.47	73.3178
1617.55	71.6437
1620.62	70.2472
1623.7	72.2287
1626.77	74.6858
1629.84	76.5073
1632.91	77.1349
1635.98	77.3821
1639.05	78.8217
1642.11	80.491
1645.18	82.8591
1648.24	85.1271
1651.31	87.8724
1654.37	88.1632
1657.43	89.9357
1660.49	89.6009
1663.55	87.9254
1666.61	85.9231
1669.66	82.5049
1672.72	77.4995
1675.77	72.6869
1678.83	69.1736
1681.88	65.3104
1684.93	60.3949
1687.98	54.9808
1691.03	49.8828
1694.07	45.5167
1697.12	41.3972
1700.17	37.3656
1703.21	33.7112
1706.25	29.6183
1709.29	28.2418
1712.33	26.1785
1715.37	24.6994
1718.41	23.7376
1721.45	23.4824
1724.49	22.8973
1727.52	21.8103
1730.55	20.6409
1733.59	18.9693
1736.62	17.3922
1739.65	15.9006
1742.68	13.7651
1745.7	11.6022
1748.73	10.1379
1751.76	9.87136
1754.78	9.37648
1757.8	7.39596
1760.83	5.98421
1763.85	5.71022
1766.87	4.4057
1769.89	3.82369
1772.9	2.64867
1775.92	1.42441
1778.94	1.38524
1781.95	1.13555
1784.96	1.44839
1787.97	1.17219
1790.99	1.26449
1794	1.17059
1797	2.16752
1800.01	2.38241
1803.02	1.90999
1806.02	2.70103
1809.03	2.71004
1812.03	2.73079
1815.03	2.718
1818.03	2.97068
1821.03	3.48109
1824.03	4.23587
1827.03	4.90886
1830.02	4.92659
1833.02	6.26632
1836.01	6.74474
1839.01	6.52696
1842	7.11927
1844.99	7.50404
1847.98	7.8507
1850.97	7.70622
1853.95	8.38039
1856.94	8.10932
1859.93	8.35077
1862.91	7.95847
1865.89	8.18899
1868.87	9.21075
1871.85	8.99132
1874.83	8.28569
1877.81	8.70388
1880.79	8.47697
1882.52	8.23538
1885.51	8.55663
1888.5	7.78246
1891.49	7.22602
1894.47	6.65074
1897.46	5.56419
1900.44	5.61212
1903.42	5.2371
1906.4	5.61072
1909.38	4.59024
1912.36	3.96613
1915.34	4.02623
1918.32	4.24116
1921.29	4.39992
1924.27	3.71505
1927.24	3.48712
1930.21	3.23426
1933.18	2.92283
1936.15	3.27322
1939.12	4.44369
1942.09	4.34341
1945.06	4.54122
1948.02	5.07524
1950.99	6.2934
1953.95	7.43468
1956.91	7.53427
1959.88	7.28003
1962.84	6.08533
1965.8	6.85267
1968.75	6.71803
1971.71	6.70952
1974.67	6.9711
1977.62	6.63935
1980.58	7.13591
1983.53	7.02443
1986.48	7.30409
1989.43	8.07868
1992.38	7.91838
1995.33	8.2864
1998.27	8.10701
2001.22	7.81176
2004.16	6.59083
2007.11	5.87853
2010.05	6.47311
2012.99	7.37552
2015.93	6.10752
2018.87	5.22345
2021.81	5.15899
2024.75	4.81847
2027.69	3.38115
2030.62	2.8071
2033.56	2.45933
2036.49	3.11249
2039.42	2.75088
2042.35	2.12725
2045.28	1.62368
2048.21	2.32531
2051.14	3.13277
2054.07	3.80799
2056.99	4.59677
2059.92	4.83146
2062.84	4.70793
2065.76	5.34118
2068.68	5.99645
2071.6	6.03578
2074.52	4.83138
2077.44	4.77673
2080.36	5.77497
2083.27	5.09878
2086.19	5.17908
2089.1	3.50896
2092.02	3.91175
2094.93	4.5967
2097.84	4.49275
2100.75	4.97526
2103.66	4.98055
2106.56	5.2794
2109.47	5.55254
2112.38	4.64984
2115.28	4.82034
2118.18	5.63651
2121.09	5.77245
2123.99	5.84874
2126.89	5.15599
2129.79	4.62196
2132.68	3.84448
2135.58	3.49843
2138.48	3.1208
2141.37	2.08734
2144.27	1.64376
2147.16	1.12851
2150.05	1.14094
2152.94	0.201172
2155.83	1.17628
2158.72	0.869397
2161.6	1.01643
2164.49	2.85716
2167.38	3.54723
2170.26	4.39606
2173.14	4.58528
2176.03	4.88052
2178.91	5.48551
2181.79	5.80555
2184.67	5.82639
2187.54	6.29234
2190.42	6.64002
2193.3	6.8067
2196.17	7.22281
2199.05	7.10309
2201.92	7.21306
2204.79	7.85392
2207.66	9.08032
2210.53	8.86167
2213.4	9.02526
2216.27	9.25994
2219.13	9.90488
2222	9.66795
2224.86	10.4833
2227.72	10.3691
2230.59	10.3965
2233.45	10.3614
2236.31	10.3053
2239.17	10.4569
2242.03	10.8497
2244.88	10.3316
2247.74	8.95932
2250.59	9.41883
2253.45	9.48434
2256.3	9.12762
2259.15	8.95228
2262	8.95249
2264.85	9.24639
2267.7	9.6954
2270.55	10.1737
2273.4	10.5041
2276.24	11.0946
2279.09	10.3883
2281.93	10.6308
2284.77	11.1929
2287.62	11.7472
2290.46	11.7149
2293.3	9.2724
2296.13	9.59352
2298.97	10.4494
2301.81	10.5412
2304.64	10.4514
2307.48	11.6155
2310.31	11.9563
2313.14	10.7461
2315.98	10.223
2318.81	10.0988
2321.64	10.0755
2324.46	9.56276
2327.29	8.09559
2330.12	7.05684
2332.94	6.8816
2335.77	5.87163
2338.59	4.93644
2341.41	5.3483
2344.23	4.8118
2347.05	3.33569
2349.87	3.50794
2352.69	3.30111
2355.51	2.75589
2358.32	1.9612
2361.14	1.46509
2363.95	2.19559
2366.76	2.72655
2369.58	2.50207
2372.39	1.56796
2375.2	0.990016
2378	1.7434
2380.81	1.26147
2383.62	0.861563
2386.43	1.47641
2389.23	1.34238
2392.03	2.07745
2394.84	2.37885
2397.64	1.93265
2400.44	1.93616
2403.24	2.7921
2406.04	2.95383
2408.84	4.27348
2411.63	4.74127
2414.43	5.90419
2417.22	6.74789
2420.02	7.18917
2422.81	8.14637
2425.6	9.37672
2428.39	9.45903
2431.18	10.1863
2433.97	9.77458
2436.76	8.88373
2439.54	8.69644
2442.33	8.65015
2445.12	8.93946
2447.9	8.25572
2450.68	7.85403
2453.46	7.08502
2456.24	6.73962
2459.02	6.29737
2461.8	5.76478
2464.58	4.8457
2467.36	3.40528
2470.13	3.0237
2472.91	3.29174
2475.68	2.27532
2478.45	2.85451
2481.23	3.2103
2484	3.18685
2486.77	2.77845
2489.54	2.69445
2492.3	2.79866
2495.07	2.33456
2497.84	2.33045
2500.6	2.70063
2503.36	2.21094
2506.13	2.37259
2508.89	2.95423
2511.65	2.85409
2514.41	2.63711
2517.17	2.163
2519.93	1.24113
2522.68	1.15421
2525.44	1.29683
2528.19	1.81562
2530.95	1.43783
2533.7	1.89676
2536.45	2.06635
2539.2	2.50188
2541.95	2.18487
2544.7	2.85381
2547.45	3.07906
2550.2	2.75064
2552.94	2.19936
2555.69	2.43381
2558.43	2.48823
2561.18	2.09875
2563.92	2.46454
2566.66	2.89018
2569.4	3.38832
2572.14	3.46367
2574.88	3.39768
2577.61	3.65157
2580.35	3.25521
2583.09	3.13586
2585.82	2.90127
2588.55	3.00244
2591.29	3.14985
2594.02	1.91617
2596.75	1.55687
2599.48	1.08209
2602.21	1.17857
2604.93	1.23003
2607.66	1.22245
2610.39	1.99106
2613.11	1.88033
2615.83	1.82189
2618.56	1.40663
2621.28	1.63855
2624	1.63114
2626.72	2.392
2629.44	2.82211
2632.15	3.51799
2634.87	4.89974
2637.59	4.54188
2640.3	4.38964
2643.02	4.4433
2645.73	4.99676
2648.44	4.83466
2651.15	4.64424
2653.86	3.72494
2656.57	2.53329
2659.28	2.6702
2661.99	2.93809
2664.69	2.70852
2667.4	2.00091
2670.1	2.19454
2672.81	2.40619
2675.51	1.92288
2678.21	1.89618
2680.91	2.03546
2683.61	1.84617
2686.31	2.06179
2689	2.6495
2691.7	3.11152
2694.4	4.32532
2697.09	5.85942
2699.79	7.06043
2702.48	7.27366
2705.17	8.14317
2707.86	10.5987
2710.55	11.9095
2713.24	13.5409
2715.93	14.6676
2718.62	16.4296
2721.3	17.514
2723.99	18.8376
2726.67	19.7993
2729.35	19.7675
2732.04	18.4847
2734.72	17.9361
2737.4	17.4387
2740.08	16.3224
2742.76	15.5119
2745.43	15.316
2748.11	14.0427
2750.79	12.9335
2753.46	11.6679
2756.14	10.115
2758.81	9.18126
2761.48	8.40445
2764.15	6.11618
2766.82	5.69732
2769.49	5.73657
2772.16	5.2977
2774.82	4.93532
2777.49	4.25028
2780.16	3.92897
2782.82	3.51244
2785.48	3.44126
2788.15	2.13179
2790.81	1.84574
2793.47	1.04277
2796.13	0.483122
2798.79	0.00888994
2801.44	-0.529254
2804.1	0.0161071
2806.76	-0.679992
2809.41	-0.00603319
2812.07	-0.0732348
2814.72	0.550426
2817.37	1.87838
2820.02	4.30254
2822.67	7.58987
2825.32	11.9113
2827.97	17.1237
2830.62	24.0116
2833.26	32.3682
2835.91	40.4332
2838.56	48.4047
2841.2	57.2496
2843.84	67.6669
2846.48	79.6153
2849.12	94.036
2851.77	108.903
2854.4	124.774
2857.04	140.233
2859.68	154.979
2862.32	172.003
2864.95	187.218
2867.59	201.753
2870.22	217.653
2872.85	232.573
2875.48	246.841
2878.11	260.533
2880.74	273.845
2883.37	286.505
2886	299.4
2888.63	311.337
2891.25	323.218
2893.88	334.782
2896.5	345.439
2899.13	356.368
2901.75	366.832
2904.37	377.017
2906.99	388.437
2909.61	401.196
2912.23	414.461
2914.85	427.842
2917.46	439.166
2920.08	447.123
2922.7	454.16
2925.31	459.242
2927.92	461.232
2930.54	460.954
2933.15	458.441
2935.76	453.257
2938.37	444.551
2940.98	433.665
2943.58	420.229
2946.19	406.326
2948.8	390.513
2951.4	373.558
2954.01	357.04
2956.61	339.305
2959.21	323.594
2961.81	306.294
2964.41	289.469
2967.01	273.785
2969.61	257.985
2972.21	244.409
2974.81	231.536
2977.4	217.739
2980	203.991
2982.59	190.115
2985.18	174.656
2987.78	160.676
2990.37	146.21
2992.96	131.204
2995.55	116.952
2998.14	103.476
3000.73	90.0909
3003.31	77.4185
3005.9	65.4168
3008.48	54.7117
3011.07	45.3369
3013.65	36.3817
3016.23	29.0289
3018.81	23.099
3021.4	17.3182
3023.97	12.2027
3026.55	7.36348
3029.13	4.37679
3031.71	2.28834
3034.28	1.07105
3036.86	1.4935
3039.43	1.8385
3042.01	2.89798
3044.58	3.39701
3047.15	5.36011
3049.72	6.97652
3052.29	8.85646
3054.86	9.98004
3057.43	10.336
3060	11.4774
3062.56	11.6849
3065.13	11.8548
3067.69	10.9891
3070.26	10.6159
3072.82	10.4951
3075.38	8.88328
3077.94	7.17106
3080.5	5.28797
3083.06	4.14225
3085.62	1.89562
3088.18	1.08164
3090.73	-0.244969
3093.29	-1.5093
3095.84	-1.50821
3098.4	-1.20601
3100.95	-0.250869
3103.5	-0.0464431
3106.05	0.727597
3108.6	2.76831
3111.15	4.41921
3113.7	5.43183
3116.25	6.24364
3118.79	7.04256
3121.34	8.40035
3123.88	10.0856
3126.43	11.6472
3128.97	13.0441
3131.51	14.5937
3134.06	16.8529
3136.6	18.5107
3139.14	19.7745
3141.67	20.9921
3144.21	22.2129
3146.75	23.3457
3149.29	25.1747