File: data/Raman/poly_smoothed/Thy_20_09_29_1x_45s_532 nm_x100_100%_600 gr_mm_01.txt
#Acq. time (s)=	45
#Accumulations=	2
#Range (cm-¹)=	200...3150
#Windows=	2
#Auto scanning=	Off
#Autofocus=	Off
#Macrospot=	Off
#AutoExposure=	Off
#Spike filter=	Multiple accum.
#Delay time (s)=	0
#Binning=	1
#Readout mode=	Signal
#DeNoise=	Off
#ICS correction=	On
#Dark correction=	Off
#Inst. Process=	Off
#Detector Gain=	Best Dynamic Range
#Detector ADC=	20 kHz
#Detector temperature (°C)=	-69.85
#Instrument=	LabRAM HR Evol
#Detector=	Synapse
#Objective=	x100
#Grating=	600 gr/mm
#ND Filter=	100%
#Laser (nm)=	532
#Hole=	100.021
#Range=	Auto
#Laser Pol.=	No
#Raman. Pol.=	No
#Laser Pol. (°)=	-0.0007625
#Raman Pol. (°)=	89.9995
#Collection=	Microscope
#StageXY=	Marzhauser
#StageZ=	Marzhauser
#X (µm)=	-5924.1
#Y (µm)=	2885.9
#Z (µm)=	-223.4
#Full time(mm:ss)=	3:18
#Project=
#Sample=
#Site=
#Title=	Thy_20_09_29_2x_45s_532 nm_x100_100%_600 gr_mm
#Remark=
#Date=	29.06.2022 12:40
#Acquired=	29.06.2022 12:40:33
#Base:Fit=	10.08.2022 09:52:02
#Base:Fit=	10.08.2022 09:52:12
#Base:Sub=	10.08.2022 09:54:21
#Filter:Polynom=	16.08.2022 10:24:04
#AxisType[0]=Intens
#AxisUnit[0]=Cnt
#AxisType[1]=Spectr
#AxisUnit[1]=1/cm
200.523	2.1671
204.154	4.06869
207.781	5.40087
211.409	6.14298
215.034	6.79899
218.659	6.84241
222.281	6.39411
225.903	5.89161
229.522	6.0408
233.14	7.53118
236.756	9.23621
240.373	10.2785
243.986	11.0287
247.598	10.2471
251.208	9.7396
254.818	11.2945
258.427	10.8592
262.034	8.91718
265.638	9.08306
269.242	9.35897
272.844	7.53749
276.445	6.73368
280.044	6.19596
283.642	5.65008
287.238	5.0907
290.833	5.65909
294.425	5.13261
298.017	5.7759
301.608	7.99568
305.198	8.85773
308.786	9.99648
312.371	12.3507
315.956	13.7284
319.54	16.8619
323.122	19.2347
326.701	19.0359
330.281	19.69
333.857	20.1485
337.434	20.796
341.008	19.3071
344.582	17.178
348.153	17.7373
351.724	16.354
355.292	15.6912
358.861	13.5829
362.426	12.6654
365.99	12.9618
369.555	12.4798
373.116	13.7841
376.676	14.1867
380.236	14.3146
383.793	15.4728
387.349	15.8193
390.903	17.3322
394.456	17.3539
398.007	16.3756
401.56	16.4035
405.108	14.0839
408.656	14.9813
412.202	14.0152
415.746	13.0106
419.29	12.03
422.831	10.8065
426.37	10.4591
429.909	9.03586
433.447	9.82782
436.983	9.77083
440.519	9.81193
444.052	9.41959
447.583	10.7264
451.114	12.6097
454.643	15.507
458.169	16.3266
461.696	18.2585
465.222	18.6037
468.744	19.2279
472.267	21.0499
475.787	21.5506
479.307	22.3278
482.823	21.2187
486.341	22.9334
489.855	24.11
493.37	25.0365
496.881	26.6936
500.391	25.5256
503.902	24.4733
507.409	25.1803
510.915	23.8754
514.42	22.8061
517.925	22.0622
521.427	19.9036
524.928	20.0382
528.427	20.2426
531.925	19.1231
535.422	19.0036
538.917	17.2084
542.411	15.0527
545.903	14.8327
549.395	13.337
552.884	14.2483
556.373	15.2137
559.86	16.6848
563.346	17.1539
566.831	18.1727
570.314	19.3984
573.794	20.4698
577.274	19.9374
580.754	19.4161
584.23	18.1306
587.706	15.3731
591.181	14.6341
594.653	14.3984
598.126	11.7094
601.595	10.2166
605.065	9.98971
608.532	9.61883
611.999	8.86241
615.463	8.44588
618.928	6.84249
622.389	6.576
625.851	6.27863
629.31	7.20565
632.767	8.31331
636.223	9.55025
639.68	11.6654
643.134	13.2392
646.586	13.581
650.037	13.9739
653.486	15.0203
656.936	15.3453
660.383	15.0065
663.829	13.9268
667.273	13.2877
670.716	12.2427
674.158	12.7783
677.598	14.5606
681.035	15.3922
684.473	15.9477
687.909	19.1598
691.344	21.1072
694.778	22.4426
698.211	25.1154
701.64	27.1834
705.07	29.4201
708.498	31.546
711.924	33.2715
715.35	35.5494
718.774	37.5804
722.196	39.912
725.618	42.4735
729.037	44.2883
732.456	46.8503
735.873	48.3233
739.289	48.6488
742.703	48.2797
746.116	50.0931
749.529	52.4403
752.938	53.9666
756.347	56.1211
759.756	58.8358
763.162	60.7089
766.567	63.4787
769.97	64.7259
773.372	65.625
776.773	66.1636
780.174	66.7196
783.573	67.6386
786.97	67.7932
790.365	70.2345
793.76	72.3361
797.153	72.5849
800.543	74.4528
803.933	75.3969
807.322	76.1548
810.71	77.0149
814.097	76.9873
817.483	76.8306
820.865	75.2041
824.248	74.0133
827.629	75.5664
831.008	73.4758
834.387	72.7588
837.765	71.6061
841.139	69.7073
844.514	65.8901
847.886	62.5461
851.259	58.6807
854.629	55.0082
857.997	52.0672
861.366	49.5766
864.732	46.6787
868.098	45.2626
871.461	45.1897
874.823	45.0146
878.184	42.9909
881.545	41.9989
884.903	43.3277
888.26	42.4349
891.616	42.2059
894.97	43.2367
898.323	43.0044
901.675	41.5128
905.026	42.096
908.375	42.6208
911.723	43.1714
915.07	42.6415
918.415	40.1655
921.76	38.7082
925.103	37.2298
928.443	35.2083
931.783	34.1991
935.123	34.9899
938.461	32.07
941.796	31.5378
945.131	28.9924
948.465	28.8788
951.797	28.1497
955.128	27.6325
958.457	27.6972
961.786	24.1729
965.113	24.6703
968.44	24.6113
971.763	24.8896
975.086	24.8476
978.409	26.2412
981.729	25.2201
985.048	25.368
988.367	24.0508
991.683	23.5115
994.998	22.5762
998.312	20.0222
1001.62	19.606
1004.94	18.4433
1008.25	18.7843
1011.56	17.5559
1014.86	18.0049
1018.17	17.1904
1021.48	16.5667
1024.78	16.9159
1028.08	15.6707
1031.38	17.9601
1034.68	18.129
1037.98	17.1735
1041.28	16.7651
1044.57	16.8494
1047.87	19.9608
1051.16	19.4844
1054.45	19.514
1057.75	18.6205
1061.04	18.3845
1064.32	15.7725
1067.61	15.057
1070.9	12.2573
1074.18	11.2101
1077.47	9.98943
1080.75	9.4505
1084.03	9.49413
1087.31	9.59496
1090.59	9.90234
1093.86	11.655
1097.14	12.1794
1100.41	11.6134
1103.69	14.5335
1106.96	15.8259
1110.23	18.4348
1113.5	18.5754
1116.77	19.4467
1120.03	19.3558
1123.3	18.7829
1126.56	19.0285
1129.83	16.8798
1133.09	15.2602
1136.35	15.2
1139.61	14.2129
1142.86	11.7277
1146.12	9.30728
1149.38	8.32549
1152.63	6.24334
1155.88	4.88543
1159.14	3.69719
1162.39	2.55954
1165.63	1.47044
1168.88	2.02972
1172.13	2.3044
1175.38	3.30958
1178.62	1.91676
1181.86	2.16937
1185.1	2.54734
1188.34	2.43787
1191.58	1.44455
1194.82	1.65763
1198.06	3.0221
1201.29	3.41944
1204.53	4.43557
1207.76	7.78936
1210.99	9.96871
1214.22	14.4418
1217.45	18.3767
1220.68	22.0274
1223.91	24.7628
1227.13	29.5363
1230.36	34.3805
1233.58	37.8797
1236.8	41.8123
1240.02	43.7071
1243.24	47.4309
1246.46	51.2678
1249.67	55.034
1252.89	56.2707
1256.1	56.7456
1259.32	56.9181
1262.53	57.4723
1265.74	57.4726
1268.95	58.6977
1272.15	60.3878
1275.36	63.5501
1278.57	63.6432
1281.77	64.4492
1284.97	65.8517
1288.18	67.729
1291.38	69.8769
1294.58	71.5814
1297.78	73.0485
1300.97	74.9476
1304.17	75.7179
1307.36	77.5461
1310.55	79.7401
1313.75	80.7133
1316.94	81.3453
1320.13	81.4004
1323.32	83.026
1326.5	80.7999
1329.69	81.7421
1332.87	81.6136
1336.06	80.22
1339.24	79.0241
1342.42	78.626
1345.6	77.6954
1348.78	76.837
1351.96	74.9061
1355.13	73.2584
1358.31	71.0174
1361.48	67.9801
1364.65	66.285
1367.82	66.4019
1370.99	64.2858
1374.16	64.1941
1377.33	62.9121
1380.5	61.4656
1383.66	60.8286
1386.83	58.2906
1389.99	57.1131
1393.15	54.8358
1396.31	53.099
1399.47	49.8561
1402.63	48.8147
1405.78	48.7973
1408.94	49.2983
1412.1	50.7224
1415.25	52.4411
1418.4	53.8525
1421.55	56.9165
1424.7	59.9395
1427.85	64.1959
1431	68.1916
1434.14	72.3752
1437.29	76.9709
1440.43	81.0218
1443.57	84.5823
1446.71	86.3523
1449.85	86.2931
1452.99	86.4154
1456.13	86.2107
1459.26	82.8178
1462.4	79.4354
1465.54	73.6288
1468.67	68.769
1471.8	62.7581
1474.93	57.1351
1478.06	50.7973
1481.19	45.0418
1484.31	40.1869
1487.44	35.8956
1490.56	33.3604
1493.69	29.6365
1496.81	27.0312
1499.93	25.0644
1503.05	24.0239
1506.17	22.9864
1509.28	23.3769
1512.4	23.8808
1515.52	22.99
1518.63	22.5777
1521.74	24.7823
1524.85	26.1603
1527.96	29.281
1531.07	31.3287
1534.18	32.4308
1537.29	34.2738
1540.39	36.8526
1543.5	40.1014
1546.6	43.8052
1549.7	47.8514
1552.8	53.3825
1555.9	57.7291
1559	62.4808
1562.1	65.9101
1565.19	71.1955
1568.29	76.1976
1571.38	80.0068
1574.47	81.2142
1577.56	84.0279
1580.66	88.0276
1583.74	90.4773
1586.83	91.4044
1589.92	92.3461
1593.01	91.0523
1596.09	91.8844
1599.17	89.4569
1602.25	86.5564
1605.34	84.4523
1608.41	81.8806
1611.49	80.8534
1614.57	78.8416
1617.65	76.173
1620.72	73.6844
1623.79	73.2278
1626.87	72.8207
1629.94	71.8174
1633.01	70.0846
1636.08	68.5979
1639.15	69.3343
1642.21	71.7705
1645.28	74.2178
1648.34	74.0764
1651.41	76.0816
1654.47	77.8215
1657.53	79.2375
1660.59	77.6503
1663.65	72.699
1666.71	73.0337
1669.76	71.848
1672.82	68.8685
1675.87	67.3391
1678.93	65.2416
1681.98	63.5319
1685.03	58.6466
1688.08	53.5739
1691.13	48.8646
1694.17	43.3065
1697.22	39.4305
1700.27	34.8252
1703.31	30.4107
1706.35	25.9303
1709.39	21.7699
1712.43	18.8111
1715.47	17.6685
1718.51	16.6354
1721.55	13.5988
1724.58	12.3034
1727.62	10.5787
1730.65	8.50404
1733.68	6.35075
1736.72	3.05253
1739.74	3.70659
1742.77	4.56314
1745.8	4.58481
1748.83	4.17117
1751.85	4.18156
1754.88	4.16477
1757.9	3.4404
1760.92	2.76377
1763.95	3.85957
1766.96	3.5951
1769.98	4.20072
1773	4.02815
1776.02	2.48165
1779.03	2.81927
1782.05	1.85334
1785.06	1.93137
1788.07	2.2316
1791.08	1.90377
1794.09	1.28231
1797.1	1.41334
1800.11	1.43756
1803.12	0.969343
1806.12	1.37338
1809.12	-0.113248
1812.13	-0.332019
1815.13	-0.55655
1818.13	-0.0597681
1821.13	-0.254031
1824.13	0.052509
1827.13	-0.181109
1830.12	-0.521433
1833.12	-0.343876
1836.11	0.175427
1839.1	-0.143231
1842.09	0.0779072
1845.09	0.152904
1848.08	0.428608
1851.06	1.04967
1854.05	1.817
1857.04	1.87354
1860.02	2.35369
1863.01	3.30035
1865.99	3.15834
1868.97	5.22384
1871.95	6.65963
1874.93	7.65356
1877.91	7.91762
1880.89	6.88742
1882.46	7.43572
1885.45	7.56403
1888.43	8.02679
1891.42	7.43011
1894.41	7.13127
1897.39	6.36791
1900.37	5.87798
1903.36	4.4435
1906.34	4.67763
1909.32	3.44963
1912.29	2.2896
1915.27	2.78638
1918.25	2.91422
1921.23	1.9983
1924.2	1.88189
1927.17	1.64812
1930.15	2.41505
1933.12	2.21015
1936.09	2.53682
1939.06	4.27662
1942.02	5.51454
1944.99	5.9557
1947.96	7.34064
1950.92	6.46001
1953.88	8.0635
1956.85	8.63952
1959.81	8.1048
1962.77	8.41733
1965.73	7.98324
1968.69	8.23447
1971.64	6.9636
1974.6	6.83795
1977.55	6.66263
1980.51	5.65218
1983.46	5.28225
1986.41	4.86662
1989.36	4.29216
1992.31	2.79806
1995.26	2.49449
1998.21	2.46444
2001.15	2.77116
2004.1	2.7202
2007.04	2.38618
2009.99	3.72976
2012.93	4.63786
2015.87	5.75094
2018.81	5.94158
2021.75	6.03959
2024.68	6.98823
2027.62	7.11934
2030.56	6.69565
2033.49	6.65097
2036.42	8.01899
2039.36	9.28414
2042.29	9.14923
2045.22	10.2003
2048.14	11.2487
2051.07	10.3904
2054	9.47639
2056.93	9.50657
2059.85	9.30634
2062.77	9.5155
2065.7	9.36506
2068.62	9.68289
2071.54	10.465
2074.46	11.6511
2077.38	11.5996
2080.29	11.7349
2083.21	12.0224
2086.12	11.7185
2089.04	12.9694
2091.95	12.7492
2094.86	13.4128
2097.77	14.4083
2100.68	14.7262
2103.59	16.7755
2106.5	18.8673
2109.41	19.6321
2112.31	20.7884
2115.21	21.3364
2118.12	21.8725
2121.02	23.6094
2123.92	24.1801
2126.82	26.821
2129.72	29.4247
2132.62	30.5847
2135.51	31.3689
2138.41	33.3916
2141.31	35.4594
2144.2	36.5057
2147.09	37.6185
2149.98	38.3236
2152.87	39.0936
2155.76	40.2211
2158.65	41.3874
2161.54	43.4365
2164.43	44.3034
2167.31	45.6344
2170.2	46.9182
2173.08	47.8913
2175.96	48.7137
2178.84	49.3419
2181.72	48.6383
2184.6	47.9998
2187.48	47.1545
2190.36	46.742
2193.23	46.5871
2196.11	46.5212
2198.98	44.8605
2201.85	42.4285
2204.72	40.5745
2207.59	38.0571
2210.46	34.9733
2213.33	33.3113
2216.2	31.519
2219.07	29.4386
2221.93	27.4898
2224.8	25.8014
2227.66	24.7191
2230.52	23.7421
2233.39	23.0868
2236.25	21.874
2239.1	21.2437
2241.96	20.3112
2244.82	19.8878
2247.68	20.0897
2250.53	18.293
2253.38	18.0206
2256.24	18.9831
2259.09	18.3932
2261.94	18.7752
2264.79	18.1718
2267.64	17.8282
2270.49	16.9128
2273.33	17.1149
2276.18	17.3353
2279.02	15.6919
2281.87	16.0665
2284.71	15.4335
2287.55	15.1354
2290.39	13.3676
2293.23	11.4199
2296.07	11.4163
2298.91	11.8951
2301.74	11.3209
2304.58	11.8251
2307.41	10.9446
2310.25	10.5615
2313.08	10.1495
2315.91	9.87912
2318.74	9.11035
2321.57	8.20231
2324.4	8.21739
2327.23	7.02814
2330.05	6.46105
2332.88	6.2652
2335.7	6.56247
2338.52	6.69661
2341.35	5.98063
2344.17	6.36845
2346.99	5.43391
2349.81	4.59905
2352.62	4.02805
2355.44	4.01797
2358.26	3.81408
2361.07	2.90614
2363.89	4.65043
2366.7	7.40869
2369.51	7.06842
2372.32	7.23515
2375.13	6.8934
2377.94	5.79778
2380.75	6.15305
2383.56	6.19617
2386.36	5.09863
2389.17	4.70703
2391.97	4.84358
2394.77	4.7114
2397.58	4.9729
2400.38	5.06669
2403.18	6.27163
2405.97	6.6886
2408.77	6.2707
2411.57	6.86326
2414.37	6.53257
2417.16	6.44198
2419.95	6.04223
2422.75	6.51523
2425.54	6.13707
2428.33	6.11967
2431.12	6.69091
2433.91	6.18996
2436.7	5.64272
2439.48	5.0033
2442.27	5.19103
2445.05	4.45488
2447.84	3.7852
2450.62	3.80734
2453.4	4.11084
2456.18	3.7884
2458.96	4.2561
2461.74	4.36829
2464.52	3.40639
2467.29	3.13155
2470.07	2.75902
2472.85	2.60264
2475.62	1.42932
2478.39	1.09424
2481.16	1.76513
2483.93	2.10747
2486.7	2.07201
2489.47	1.76268
2492.24	1.20646
2495.01	1.63664
2497.77	1.52046
2500.54	2.02614
2503.3	1.35137
2506.06	2.73625
2508.83	2.82615
2511.59	2.39712
2514.35	2.32581
2517.11	3.04847
2519.86	3.51271
2522.62	3.99622
2525.38	3.14241
2528.13	3.3043
2530.89	3.18386
2533.64	3.2034
2536.39	2.8773
2539.14	2.2088
2541.89	2.23237
2544.64	3.19344
2547.39	4.36578
2550.14	5.15337
2552.88	5.26624
2555.63	4.59219
2558.37	4.09366
2561.11	4.72264
2563.86	4.07013
2566.6	3.47557
2569.34	3.45394
2572.08	3.52874
2574.82	3.46673
2577.55	3.26485
2580.29	2.8385
2583.02	2.69684
2585.76	2.88483
2588.49	2.65143
2591.22	2.84705
2593.96	2.72516
2596.69	3.72584
2599.42	3.85139
2602.14	3.7141
2604.87	3.43165
2607.6	3.46766
2610.32	4.00902
2613.05	4.56315
2615.77	3.89207
2618.49	4.62764
2621.22	3.67983
2623.94	4.90354
2626.66	4.56894
2629.37	4.43654
2632.09	4.40506
2634.81	4.85219
2637.53	4.63301
2640.24	5.48834
2642.96	5.54361
2645.67	6.00912
2648.38	6.34599
2651.09	5.20051
2653.8	5.51269
2656.51	6.30939
2659.22	6.17804
2661.93	5.82509
2664.63	6.54868
2667.34	5.72514
2670.04	4.4777
2672.75	5.35242
2675.45	5.13465
2678.15	5.51654
2680.85	5.4777
2683.55	5.44174
2686.25	5.56441
2688.94	5.97319
2691.64	6.75669
2694.34	7.07885
2697.03	7.26158
2699.73	6.93429
2702.42	6.63338
2705.11	7.07335
2707.8	7.66051
2710.49	9.02565
2713.18	9.09325
2715.87	9.96247
2718.55	10.7101
2721.24	11.6177
2723.93	12.3489
2726.61	12.5201
2729.29	13.8609
2731.98	14.348
2734.66	14.8119
2737.34	15.3416
2740.02	16.7306
2742.7	16.9766
2745.37	17.1204
2748.05	16.8706
2750.72	16.9721
2753.4	15.6052
2756.07	15.264
2758.75	14.7983
2761.42	12.6348
2764.09	9.23403
2766.76	7.95226
2769.43	6.11274
2772.1	5.66057
2774.76	4.65056
2777.43	4.09306
2780.1	2.9507
2782.76	1.77461
2785.42	1.79779
2788.09	1.04621
2790.75	0.725449
2793.41	1.11725
2796.07	0.196503
2798.73	1.34559
2801.39	0.943844
2804.04	2.07297
2806.7	3.52924
2809.35	3.50209
2812.01	3.50309
2814.66	3.69963
2817.31	4.40835
2819.96	5.78787
2822.61	7.92395
2825.26	10.775
2827.91	14.4593
2830.56	18.3418
2833.21	23.7757
2835.85	30.0258
2838.5	35.8726
2841.14	43.5518
2843.78	51.0083
2846.42	58.6253
2849.06	67.0377
2851.71	75.7216
2854.34	85.3104
2856.98	95.237
2859.62	103.381
2862.26	112.475
2864.89	120.684
2867.53	128.207
2870.16	135.302
2872.79	140.601
2875.42	144.684
2878.05	148.398
2880.68	153.023
2883.31	156.132
2885.94	159.899
2888.57	163.903
2891.19	168.293
2893.82	171.559
2896.44	176.545
2899.07	182.46
2901.69	188.461
2904.31	195.323
2906.93	201.937
2909.55	210.547
2912.17	218.99
2914.79	228.228
2917.41	236.964
2920.02	245.133
2922.64	250.727
2925.25	255.533
2927.86	258.493
2930.48	259.306
2933.09	259.012
2935.7	256.503
2938.31	251.958
2940.92	245.537
2943.53	238.882
2946.13	231.264
2948.74	222.563
2951.34	213.726
2953.95	205.486
2956.55	196.136
2959.15	186.9
2961.75	178.936
2964.35	170.53
2966.95	162.498
2969.55	155.214
2972.15	147.407
2974.75	140.42
2977.34	132.771
2979.94	125.232
2982.53	116.612
2985.13	106.836
2987.72	97.3814
2990.31	88.7826
2992.9	80.6782
2995.49	73.0334
2998.08	64.965
3000.67	57.2646
3003.25	49.812
3005.84	43.3726
3008.42	38.3747
3011.01	33.2017
3013.59	28.8758
3016.17	25.1149
3018.76	22.2096
3021.34	20.5802
3023.92	19.258
3026.49	18.358
3029.07	17.7785
3031.65	16.4977
3034.23	15.3308
3036.8	15.4963
3039.38	15.7696
3041.95	16.0912
3044.52	16.4136
3047.09	16.4027
3049.66	16.3472
3052.23	17.7723
3054.8	18.1349
3057.37	18.1819
3059.94	16.6772
3062.5	16.1608
3065.07	14.0564
3067.63	12.9175
3070.2	11.7797
3072.76	9.97993
3075.32	8.22404
3077.88	7.12298
3080.44	5.6556
3083	4.63218
3085.56	2.60402
3088.12	1.40929
3090.67	0.465951
3093.23	-0.0985627
3095.78	-0.952682
3098.34	-0.248736
3100.89	0.207323
3103.44	1.14389
3105.99	2.25938
3108.54	2.7172
3111.09	3.83617
3113.64	4.81055
3116.19	5.53027
3118.74	6.3597
3121.28	6.98395
3123.83	8.00009
3126.37	8.59522
3128.91	8.8626
3131.46	10.0212
3134	11.4171
3136.54	11.9122
3139.08	12.7063
3141.62	13.0918
3144.16	13.3564
3146.69	14.2514
3149.23	15.4101