File: data/Raman/poly_smoothed/Thy_00_07_34_1x_45s_532 nm_x100_100%_600 gr_mm_01.txt
#Acq. time (s)=	45
#Accumulations=	2
#Range (cm-¹)=	200...3150
#Windows=	2
#Auto scanning=	Off
#Autofocus=	Off
#Macrospot=	Off
#AutoExposure=	Off
#Spike filter=	Multiple accum.
#Delay time (s)=	0
#Binning=	1
#Readout mode=	Signal
#DeNoise=	Off
#ICS correction=	On
#Dark correction=	Off
#Inst. Process=	Off
#Detector Gain=	Best Dynamic Range
#Detector ADC=	20 kHz
#Detector temperature (°C)=	-69.85
#Instrument=	LabRAM HR Evol
#Detector=	Synapse
#Objective=	x100
#Grating=	600 gr/mm
#ND Filter=	100%
#Laser (nm)=	532
#Hole=	100.021
#Range=	Auto
#Laser Pol.=	No
#Raman. Pol.=	No
#Laser Pol. (°)=	-0.0007625
#Raman Pol. (°)=	89.9995
#Collection=	Microscope
#StageXY=	Marzhauser
#StageZ=	Marzhauser
#X (µm)=	8965.3
#Y (µm)=	-3069.7
#Z (µm)=	-54.85
#Full time(mm:ss)=	3:19
#Project=
#Sample=
#Site=
#Title=	Thy_00_07_34_2x_45s_532 nm_x100_100%_600 gr_mm
#Remark=
#Date=	28.06.2022 12:38
#Acquired=	28.06.2022 12:38:05
#Base:Fit=	10.08.2022 10:07:56
#Base:Sub=	10.08.2022 10:08:40
#Filter:Polynom=	16.08.2022 10:26:06
#AxisType[0]=Intens
#AxisUnit[0]=Cnt
#AxisType[1]=Spectr
#AxisUnit[1]=1/cm
200.407	2.22751
204.035	8.67682
207.665	10.338
211.291	10.8636
214.916	11.8105
218.541	13.3521
222.163	14.4382
225.785	14.13
229.404	14.6304
233.022	14.0859
236.638	13.7169
240.255	11.9566
243.868	11.2829
247.48	10.1496
251.091	8.47042
254.702	5.31696
258.31	4.04006
261.916	3.53423
265.521	3.4294
269.125	4.77776
272.727	4.26188
276.328	4.65897
279.927	4.76352
283.525	4.92977
287.121	4.03628
290.716	3.72938
294.31	6.13562
297.9	8.89401
301.491	12.8841
305.081	16.0132
308.669	18.1626
312.256	20.1944
315.839	21.912
319.423	23.3195
323.006	23.0566
326.585	22.3904
330.165	21.5291
333.741	21.4327
337.318	20.2815
340.894	17.5845
344.466	16.0555
348.039	16.0276
351.608	15.5941
355.176	14.854
358.745	14.7248
362.31	13.4164
365.876	13.0602
369.439	12.9527
373	12.5478
376.56	12.2493
380.12	11.813
383.677	12.977
387.233	14.1924
390.787	14.0499
394.34	14.1953
397.894	14.4461
401.444	13.0805
404.993	12.1695
408.54	10.4731
412.086	8.04932
415.631	7.86555
419.174	6.61824
422.716	5.06217
426.257	2.84577
429.794	2.8616
433.332	1.72161
436.868	0.30389
440.403	1.32806
443.937	2.79743
447.468	3.09792
450.999	3.6098
454.528	5.37637
458.057	5.9463
461.582	9.32224
465.107	10.2884
468.629	11.214
472.152	12.443
475.672	13.9696
479.192	14.2711
482.709	15.9703
486.226	15.9514
489.74	19.8173
493.255	21.0706
496.767	21.8084
500.277	23.0793
503.788	24.5732
507.295	26.0368
510.801	25.5442
514.308	24.5361
517.811	24.2456
521.313	23.1348
524.814	22.1282
528.313	22.7854
531.811	21.8309
535.308	21.3672
538.803	21.8473
542.297	21.1009
545.789	20.0653
549.281	19.7414
552.771	16.6419
556.259	15.3417
559.747	14.458
563.233	12.7547
566.717	11.8461
570.2	11.5439
573.68	11.4674
577.161	10.3765
580.64	9.51199
584.118	8.92974
587.593	8.08648
591.068	7.21333
594.54	6.72079
598.013	4.48049
601.484	2.05577
604.952	1.36846
608.421	1.23846
611.886	2.24298
615.35	2.1811
618.815	3.16666
622.276	3.28355
625.738	3.6652
629.197	3.54539
632.655	5.22224
636.113	6.72683
639.568	7.56576
643.021	7.91822
646.473	8.88642
649.924	9.24262
653.376	9.30082
656.824	9.31025
660.271	9.6115
663.716	11.7284
667.161	12.4057
670.604	10.4949
674.045	9.631
677.486	10.9751
680.925	11.6805
684.361	12.2748
687.797	13.0717
691.232	15.5494
694.666	16.1319
698.099	18.3072
701.528	17.6689
704.958	17.7616
708.387	19.9715
711.814	19.788
715.238	22.2043
718.663	25.4773
722.084	26.8455
725.506	28.7757
728.925	32.5922
732.345	35.8088
735.761	37.5253
739.178	38.7542
742.592	40.9925
746.006	44.1624
749.417	48.6445
752.827	49.4127
756.236	51.5911
759.645	54.9528
763.051	58.4997
766.456	60.6999
769.859	61.0706
773.261	63.366
776.664	62.5254
780.064	59.9981
783.462	59.3421
786.859	58.3387
790.255	57.819
793.649	58.0493
797.042	58.1809
800.434	58.1276
803.823	58.9194
807.212	57.693
810.6	56.6998
813.987	55.8126
817.372	53.1218
820.754	52.5469
824.137	53.2782
827.519	53.0388
830.897	54.153
834.276	55.4889
837.654	54.03
841.029	52.8471
844.404	51.9724
847.776	51.7929
851.149	49.4096
854.519	48.042
857.889	45.8992
861.256	42.2431
864.622	40.7768
867.988	40.4302
871.351	39.1349
874.713	39.0166
878.074	37.9128
881.435	37.0195
884.794	35.6728
888.15	33.92
891.506	32.6106
894.861	33.5553
898.214	32.1265
901.566	33.7454
904.916	34.0596
908.266	34.0821
911.614	32.4442
914.961	33.1917
918.306	30.8983
921.651	30.5123
924.994	31.8765
928.336	31.876
931.674	32.1293
935.014	30.9868
938.352	30.3005
941.687	30.4927
945.022	31.3419
948.357	32.7389
951.688	32.9941
955.02	33.0245
958.348	30.9919
961.678	28.6936
965.004	30.3395
968.331	34.6888
971.655	37.4701
974.979	41.1543
978.3	44.7946
981.62	47.9331
984.941	50.5823
988.259	49.2587
991.575	49.214
994.89	48.1597
998.204	49.5595
1001.52	50.0942
1004.83	51.7052
1008.14	51.2351
1011.45	50.802
1014.76	51.4164
1018.06	48.7673
1021.37	47.6436
1024.67	46.2117
1027.97	44.347
1031.27	38.5039
1034.57	33.4125
1037.87	28.9451
1041.17	25.4781
1044.47	26.7118
1047.76	27.0548
1051.06	25.9408
1054.35	26.1717
1057.64	24.0683
1060.93	23.9224
1064.22	21.896
1067.5	19.0784
1070.79	18.5555
1074.08	19.5745
1077.36	19.6433
1080.64	20.2954
1083.92	20.0448
1087.2	20.5851
1090.48	21.2347
1093.76	22.5221
1097.03	24.0672
1100.31	26.6407
1103.58	28.8921
1106.85	29.1053
1110.12	27.0459
1113.39	26.8853
1116.66	25.7082
1119.93	25.1831
1123.19	24.4423
1126.46	22.7619
1129.72	21.4808
1132.98	20.5609
1136.24	18.6833
1139.5	16.7793
1142.76	16.9573
1146.01	15.2469
1149.27	14.6771
1152.53	13.4577
1155.78	11.5924
1159.03	9.34795
1162.28	7.22213
1165.53	7.15166
1168.78	7.10611
1172.02	7.57632
1175.27	10.8969
1178.51	12.1649
1181.76	14.3917
1185	15.0124
1188.24	14.8923
1191.48	15.7629
1194.71	16.8512
1197.95	19.3623
1201.19	22.3926
1204.42	27.0199
1207.65	29.7314
1210.88	33.8525
1214.12	36.6936
1217.35	41.3541
1220.57	47.6123
1223.8	52.8565
1227.03	56.9175
1230.25	61.091
1233.47	64.227
1236.69	66.9896
1239.92	69.178
1243.13	69.7638
1246.35	68.8799
1249.57	70.8798
1252.78	72.1333
1256	69.9597
1259.21	68.6955
1262.42	68.4921
1265.63	67.2367
1268.84	65.8917
1272.05	65.6735
1275.26	67.2274
1278.46	69.0051
1281.67	70.7705
1284.87	73.9846
1288.07	78.262
1291.27	82.4231
1294.47	87.3965
1297.67	92.3442
1300.87	97.3413
1304.06	102.174
1307.26	106.445
1310.45	112.149
1313.64	115.657
1316.83	116.737
1320.02	117.853
1323.21	119.304
1326.4	119.632
1329.59	119.562
1332.77	116.228
1335.95	114.972
1339.14	113.544
1342.32	110.779
1345.5	107.411
1348.67	105
1351.85	102.518
1355.03	99.4269
1358.2	95.8191
1361.38	92.1567
1364.55	89.8048
1367.72	86.161
1370.89	82.0757
1374.06	78.854
1377.23	76.6647
1380.39	75.1777
1383.56	72.3584
1386.72	70.5104
1389.89	68.7577
1393.05	66.9596
1396.21	64.6819
1399.37	65.5334
1402.52	66.2848
1405.68	66.0476
1408.84	68.077
1411.99	71.2961
1415.15	76.3464
1418.3	81.0975
1421.45	88.0011
1424.6	94.1138
1427.75	101.464
1430.89	108.138
1434.04	114.885
1437.18	121.083
1440.33	125.105
1443.47	129.942
1446.61	132.138
1449.75	132.458
1452.89	132.668
1456.03	129.268
1459.16	124.386
1462.3	119.856
1465.43	114.699
1468.56	106.493
1471.7	96.3962
1474.83	88.5752
1477.96	80.4127
1481.08	70.9792
1484.21	62.6927
1487.34	54.389
1490.46	47.843
1493.58	42.2128
1496.71	36.2739
1499.83	33.2204
1502.95	31.0009
1506.07	31.3565
1509.18	32.307
1512.3	31.29
1515.41	30.8127
1518.53	32.4746
1521.64	34.8602
1524.75	36.8468
1527.86	39.634
1530.97	43.7458
1534.08	45.8364
1537.19	45.6735
1540.29	52.7118
1543.4	57.8434
1546.5	65.0954
1549.6	73.3108
1552.7	80.7836
1555.8	88.7298
1558.9	95.8429
1562	100.569
1565.09	106.169
1568.19	112.504
1571.28	116.61
1574.37	120.091
1577.47	124.575
1580.56	129.105
1583.64	132.164
1586.73	132.88
1589.82	132.81
1592.9	130.933
1595.99	129.024
1599.07	125.59
1602.15	119.897
1605.23	115.183
1608.31	110.043
1611.39	105.12
1614.47	105.261
1617.55	106.066
1620.62	104.914
1623.7	103.985
1626.77	102.205
1629.84	101.239
1632.91	99.9455
1635.98	100.528
1639.05	100.885
1642.11	101.712
1645.18	103.622
1648.24	103.999
1651.31	105.579
1654.37	107.384
1657.43	108.853
1660.49	107.251
1663.55	104.802
1666.61	99.8745
1669.66	97.9286
1672.72	92.4196
1675.77	87.6061
1678.83	83.4983
1681.88	78.7831
1684.93	73.4752
1687.98	67.7505
1691.03	60.6775
1694.07	54.1041
1697.12	47.3882
1700.17	40.3967
1703.21	35.5066
1706.25	31.4084
1709.29	28.1171
1712.33	25.4336
1715.37	22.8101
1718.41	20.0753
1721.45	17.5796
1724.49	16.6668
1727.52	14.8028
1730.55	12.9927
1733.59	11.5897
1736.62	9.97443
1739.65	8.55208
1742.68	8.49298
1745.7	7.17539
1748.73	6.16424
1751.76	6.20019
1754.78	5.64136
1757.8	4.85342
1760.83	3.51389
1763.85	2.65937
1766.87	2.06997
1769.89	2.36709
1772.9	3.0818
1775.92	3.44203
1778.94	3.93734
1781.95	4.62597
1784.96	3.94782
1787.97	4.60931
1790.99	4.72636
1794	3.83173
1797	3.86348
1800.01	3.79476
1803.02	2.40475
1806.02	2.47587
1809.03	2.74841
1812.03	2.6527
1815.03	2.59406
1818.03	2.53978
1821.03	2.5089
1824.03	3.29143
1827.03	3.44742
1830.02	2.73974
1833.02	2.96677
1836.01	2.83499
1839.01	3.20031
1842	3.60043
1844.99	4.75289
1847.98	4.95456
1850.97	5.19243
1853.95	5.34608
1856.94	6.01813
1859.93	6.39512
1862.91	6.7388
1865.89	7.38037
1868.87	7.22643
1871.85	6.66757
1874.83	6.89941
1877.81	7.26213
1880.79	6.78703
1882.52	7.2325
1885.51	7.76302
1888.5	7.76605
1891.49	7.85979
1894.47	7.93226
1897.46	8.10437
1900.44	8.50885
1903.42	9.25158
1906.4	9.33802
1909.38	8.43635
1912.36	8.15411
1915.34	9.64906
1918.32	9.52079
1921.29	9.48679
1924.27	9.99552
1927.24	9.67759
1930.21	9.09075
1933.18	9.02429
1936.15	8.16024
1939.12	8.74208
1942.09	7.48227
1945.06	7.27035
1948.02	6.50455
1950.99	5.72479
1953.95	6.54082
1956.91	7.01997
1959.88	7.1224
1962.84	7.58161
1965.8	6.53051
1968.75	5.46427
1971.71	5.07121
1974.67	5.35051
1977.62	4.17911
1980.58	3.59019
1983.53	4.3847
1986.48	5.56397
1989.43	6.05407
1992.38	7.08248
1995.33	6.87866
1998.27	7.93945
2001.22	7.84487
2004.16	9.24986
2007.11	9.39432
2010.05	9.34489
2012.99	10.2234
2015.93	10.9765
2018.87	10.548
2021.81	11.2801
2024.75	12.4139
2027.69	13.1112
2030.62	13.1349
2033.56	12.8744
2036.49	12.3257
2039.42	11.9952
2042.35	11.1736
2045.28	10.2161
2048.21	9.94503
2051.14	8.86991
2054.07	8.43857
2056.99	8.14904
2059.92	7.99114
2062.84	7.5107
2065.76	7.28788
2068.68	7.37116
2071.6	8.7531
2074.52	8.35057
2077.44	8.05481
2080.36	6.93013
2083.27	6.06547
2086.19	6.08582
2089.1	5.75779
2092.02	6.53771
2094.93	7.11279
2097.84	7.70976
2100.75	7.83201
2103.66	7.91908
2106.56	8.70749
2109.47	9.86159
2112.38	9.49098
2115.28	9.03573
2118.18	8.66232
2121.09	8.94942
2123.99	8.32308
2126.89	8.91351
2129.79	9.26282
2132.68	9.38862
2135.58	9.79883
2138.48	10.1303
2141.37	10.7825
2144.27	10.945
2147.16	9.8812
2150.05	10.1962
2152.94	10.3872
2155.83	12.4932
2158.72	13.0253
2161.6	14.0387
2164.49	13.7334
2167.38	14.1821
2170.26	14.5617
2173.14	13.681
2176.03	14.0092
2178.91	15.1101
2181.79	14.7139
2184.67	14.2939
2187.54	12.3145
2190.42	12.161
2193.3	10.6584
2196.17	10.6667
2199.05	10.481
2201.92	8.82572
2204.79	8.54346
2207.66	7.45083
2210.53	6.66241
2213.4	6.72067
2216.27	6.28053
2219.13	6.31718
2222	6.57294
2224.86	7.52793
2227.72	7.9111
2230.59	7.98618
2233.45	8.95708
2236.31	9.21757
2239.17	8.64059
2242.03	8.33225
2244.88	8.47838
2247.74	8.77669
2250.59	8.76717
2253.45	9.15678
2256.3	9.43288
2259.15	10.2449
2262	10.8712
2264.85	11.3114
2267.7	11.1723
2270.55	10.7484
2273.4	9.50906
2276.24	8.73491
2279.09	7.44855
2281.93	7.37249
2284.77	6.53481
2287.62	5.53439
2290.46	4.7505
2293.3	4.27979
2296.13	5.07207
2298.97	5.78733
2301.81	6.49556
2304.64	7.32451
2307.48	7.63809
2310.31	8.67704
2313.14	8.76303
2315.98	9.71826
2318.81	11.5055
2321.64	12.5415
2324.46	12.6623
2327.29	12.0864
2330.12	12.6587
2332.94	11.4781
2335.77	10.8925
2338.59	9.63533
2341.41	7.9322
2344.23	6.12988
2347.05	4.35112
2349.87	3.20238
2352.69	3.28149
2355.51	1.84253
2358.32	1.68229
2361.14	1.46947
2363.95	1.94167
2366.76	3.2941
2369.58	3.48202
2372.39	3.53814
2375.2	3.96117
2378	3.65646
2380.81	3.56422
2383.62	3.43269
2386.43	4.23365
2389.23	3.60861
2392.03	2.95934
2394.84	1.52588
2397.64	0.973541
2400.44	0.767338
2403.24	0.66722
2406.04	1.37079
2408.84	0.670584
2411.63	1.38424
2414.43	3.24143
2417.22	4.43611
2420.02	6.90526
2422.81	7.78317
2425.6	8.65557
2428.39	9.08401
2431.18	9.95208
2433.97	10.6948
2436.76	10.1085
2439.54	9.63961
2442.33	9.54903
2445.12	8.95155
2447.9	8.64923
2450.68	7.80543
2453.46	6.40689
2456.24	6.05974
2459.02	4.56423
2461.8	4.07589
2464.58	3.19846
2467.36	3.11022
2470.13	2.72662
2472.91	3.13226
2475.68	1.8533
2478.45	2.03728
2481.23	1.56629
2484	1.67544
2486.77	2.03893
2489.54	1.65997
2492.3	1.51111
2495.07	1.64767
2497.84	1.40365
2500.6	1.87921
2503.36	2.30422
2506.13	1.88053
2508.89	1.87895
2511.65	1.90399
2514.41	1.93746
2517.17	1.49346
2519.93	1.29215
2522.68	2.05182
2525.44	2.12693
2528.19	1.68529
2530.95	1.03526
2533.7	2.27687
2536.45	1.74065
2539.2	1.95985
2541.95	1.04219
2544.7	0.302405
2547.45	0.706367
2550.2	1.86291
2552.94	2.80363
2555.69	3.13687
2558.43	3.08962
2561.18	3.51732
2563.92	3.73167
2566.66	3.9479
2569.4	3.58878
2572.14	4.27579
2574.88	4.13037
2577.61	5.04812
2580.35	4.14913
2583.09	2.98738
2585.82	3.00025
2588.55	2.70797
2591.29	1.49385
2594.02	0.30604
2596.75	-0.260305
2599.48	0.634746
2602.21	1.14588
2604.93	1.71479
2607.66	2.42664
2610.39	2.88368
2613.11	3.66586
2615.83	3.95835
2618.56	4.65444
2621.28	4.74455
2624	4.07139
2626.72	4.61651
2629.44	5.66839
2632.15	6.18685
2634.87	6.14386
2637.59	5.85957
2640.3	5.76026
2643.02	6.15002
2645.73	5.53505
2648.44	4.73314
2651.15	4.67731
2653.86	4.7722
2656.57	3.9961
2659.28	3.61574
2661.99	3.50414
2664.69	4.26405
2667.4	5.55814
2670.1	6.77435
2672.81	7.30949
2675.51	6.91221
2678.21	6.90816
2680.91	6.78632
2683.61	7.39289
2686.31	7.29286
2689	7.43294
2691.7	8.23806
2694.4	10.0915
2697.09	11.0575
2699.79	11.8615
2702.48	12.9225
2705.17	14.2733
2707.86	15.417
2710.55	14.9106
2713.24	15.7019
2715.93	16.5003
2718.62	17.288
2721.3	16.7728
2723.99	16.6461
2726.67	16.9864
2729.35	16.768
2732.04	17.0803
2734.72	17.5464
2737.4	16.6524
2740.08	15.6127
2742.76	15.2154
2745.43	15.0705
2748.11	14.467
2750.79	13.7606
2753.46	13.8947
2756.14	13.1173
2758.81	13.9502
2761.48	13.3014
2764.15	13.2501
2766.82	13.1162
2769.49	12.6976
2772.16	11.9254
2774.82	10.7938
2777.49	9.68705
2780.16	9.16539
2782.82	7.43206
2785.48	6.06302
2788.15	5.23384
2790.81	4.98025
2793.47	3.88959
2796.13	3.65373
2798.79	4.14311
2801.44	4.0532
2804.1	3.70843
2806.76	3.42517
2809.41	2.89901
2812.07	2.37758
2814.72	2.36335
2817.37	3.02086
2820.02	4.29431
2822.67	6.42493
2825.32	9.02515
2827.97	12.5567
2830.62	17.4765
2833.26	22.2316
2835.91	28.1802
2838.56	34.0835
2841.2	41.0414
2843.84	50.455
2846.48	61.0612
2849.12	72.3133
2851.77	86.4845
2854.4	101.023
2857.04	114.272
2859.68	128.851
2862.32	142.072
2864.95	154.422
2867.59	166.089
2870.22	176.174
2872.85	185.051
2875.48	191.778
2878.11	198.111
2880.74	203.131
2883.37	207.903
2886	211.804
2888.63	215.619
2891.25	219.944
2893.88	225.124
2896.5	230.906
2899.13	237.169
2901.75	244.165
2904.37	254.872
2906.99	266.477
2909.61	279.049
2912.23	293.407
2914.85	307.782
2917.46	322.054
2920.08	333.992
2922.7	345.15
2925.31	353.251
2927.92	358.486
2930.54	362.351
2933.15	360.98
2935.76	358.462
2938.37	351.763
2940.98	343.27
2943.58	333.594
2946.19	322.864
2948.8	310.27
2951.4	297.74
2954.01	286.191
2956.61	273.732
2959.21	261.546
2961.81	249.69
2964.41	237.628
2967.01	227.214
2969.61	217.402
2972.21	206.719
2974.81	196.85
2977.4	186.762
2980	176.803
2982.59	166.716
2985.18	155.705
2987.78	145.242
2990.37	132.029
2992.96	121.012
2995.55	108.899
2998.14	96.9383
3000.73	86.107
3003.31	76.1841
3005.9	66.6101
3008.48	58.9019
3011.07	52.5077
3013.65	46.2988
3016.23	40.8753
3018.81	36.8197
3021.4	32.0961
3023.97	28.8064
3026.55	25.8691
3029.13	23.8282
3031.71	22.7456
3034.28	22.1441
3036.86	21.813
3039.43	22.2742
3042.01	23.8986
3044.58	26.1799
3047.15	28.3797
3049.72	30.0089
3052.29	31.8546
3054.86	32.2067
3057.43	31.6295
3060	31.6553
3062.56	30.6623
3065.13	30.39
3067.69	29.4649
3070.26	28.3272
3072.82	26.5562
3075.38	23.3223
3077.94	20.7186
3080.5	17.4046
3083.06	14.2814
3085.62	10.1433
3088.18	7.3288
3090.73	5.13318
3093.29	3.63082
3095.84	2.19277
3098.4	1.05018
3100.95	1.23239
3103.5	1.26012
3106.05	1.85693
3108.6	2.43792
3111.15	2.06394
3113.7	2.82791
3116.25	3.32435
3118.79	2.94021
3121.34	3.7556
3123.88	4.46612
3126.43	5.60295
3128.97	6.49149
3131.51	7.00504
3134.06	6.70272
3136.6	6.86757
3139.14	7.35182
3141.67	7.14682
3144.21	6.60365
3146.75	6.49898
3149.29	6.03886