File: data/Raman/poly_smoothed/Thy_10_08_49_1x_45s_532 nm_x100_100%_600 gr_mm_01.txt
#Acq. time (s)=	45
#Accumulations=	2
#Range (cm-¹)=	200...3150
#Windows=	2
#Auto scanning=	Off
#Autofocus=	Off
#Macrospot=	Off
#AutoExposure=	Off
#Spike filter=	Multiple accum.
#Delay time (s)=	0
#Binning=	1
#Readout mode=	Signal
#DeNoise=	Off
#ICS correction=	On
#Dark correction=	Off
#Inst. Process=	Off
#Detector Gain=	Best Dynamic Range
#Detector ADC=	20 kHz
#Detector temperature (°C)=	-69.85
#Instrument=	LabRAM HR Evol
#Detector=	Synapse
#Objective=	x100
#Grating=	600 gr/mm
#ND Filter=	100%
#Laser (nm)=	532
#Hole=	100.021
#Range=	Auto
#Laser Pol.=	No
#Raman. Pol.=	No
#Laser Pol. (°)=	-0.0007625
#Raman Pol. (°)=	89.9995
#Collection=	Microscope
#StageXY=	Marzhauser
#StageZ=	Marzhauser
#X (µm)=	-2351.5
#Y (µm)=	260.4
#Z (µm)=	521.65
#Full time(mm:ss)=	3:18
#Project=
#Sample=
#Site=
#Title=	Thy_10_08_49_2x_45s_532 nm_x100_100%_600 gr_mm
#Remark=
#Date=	06.07.2022 15:22
#Acquired=	06.07.2022 15:22:42
#Base:Fit=	10.08.2022 09:46:25
#Base:Sub=	10.08.2022 09:46:49
#Filter:Polynom=	16.08.2022 10:24:56
#AxisType[0]=Intens
#AxisUnit[0]=Cnt
#AxisType[1]=Spectr
#AxisUnit[1]=1/cm
200.398	10.7724
204.027	10.285
207.657	10.2066
211.283	9.47683
214.909	7.61212
218.533	8.22032
222.157	7.35909
225.777	6.44948
229.396	5.40576
233.016	3.9863
236.632	2.07638
240.247	2.30182
243.86	1.38646
247.474	1.08082
251.085	2.31204
254.694	3.34028
258.301	2.28519
261.908	1.87474
265.513	2.16522
269.116	3.53039
272.718	3.50028
276.319	3.87964
279.918	5.11767
283.516	7.73784
287.113	10.2469
290.708	12.3838
294.302	13.3217
297.894	14.6775
301.485	16.3625
305.073	17.9337
308.661	19.5527
312.247	20.492
315.833	19.2664
319.415	19.5753
322.997	19.0217
326.579	19.0949
330.156	20.836
333.735	19.9381
337.31	21.658
340.885	18.8258
344.458	16.4728
348.03	13.0213
351.6	12.1371
355.17	11.2586
358.737	10.2809
362.304	9.10114
365.868	9.84401
369.431	11.3935
372.994	12.8253
376.554	11.2309
380.112	10.9908
383.669	10.9885
387.225	11.4021
390.781	11.5594
394.334	11.4591
397.885	10.0333
401.436	9.81608
404.984	9.54256
408.532	9.76326
412.078	8.99599
415.623	9.50978
419.166	7.61529
422.708	5.53988
426.248	6.17237
429.788	4.74567
433.326	3.60963
436.86	3.28626
440.395	4.22063
443.929	4.3052
447.461	5.33344
450.99	6.60394
454.52	9.33049
458.048	10.5754
461.573	10.2462
465.099	11.111
468.623	13.4252
472.144	14.6229
475.666	16.2664
479.184	17.1457
482.703	19.1296
486.218	21.6453
489.734	22.9234
493.247	24.6133
496.759	24.6271
500.271	24.2427
503.779	25.0305
507.287	25.5915
510.795	26.3878
514.299	25.297
517.803	23.7459
521.305	22.3032
524.805	22.3288
528.307	21.159
531.805	22.3967
535.301	21.5282
538.797	19.6323
542.291	18.8827
545.783	19.1166
549.275	18.7203
552.765	17.5217
556.253	15.6229
559.738	15.4453
563.224	15.1646
566.709	14.1491
570.192	13.2955
573.674	12.3381
577.153	9.07292
580.632	7.16929
584.11	4.98575
587.587	4.40325
591.06	4.16035
594.534	3.39415
598.005	2.68797
601.476	3.65255
604.944	5.55839
608.413	6.1903
611.878	7.98267
615.344	9.75973
618.807	10.9018
622.27	10.3327
625.73	13.0247
629.189	14.2432
632.648	15.9059
636.105	16.2031
639.559	16.5682
643.013	16.7209
646.467	19.0393
649.918	19.4056
653.368	20.4465
656.816	19.553
660.263	19.0818
663.708	17.8772
667.153	19.1584
670.596	19.7992
674.037	19.1785
677.478	20.5834
680.917	23.2957
684.355	25.3102
687.791	26.8548
691.224	27.5679
694.658	28.4937
698.091	30.9307
701.522	31.4069
704.95	33.6103
708.379	35.8894
711.806	39.5595
715.23	39.878
718.655	41.0974
722.078	43.5996
725.498	43.9832
728.919	48.0559
732.337	50.9243
735.755	51.7759
739.17	53.5827
742.584	54.8001
745.998	55.1713
749.409	56.101
752.819	57.8217
756.23	58.4152
759.637	60.1005
763.043	61.5488
766.448	62.6758
769.853	62.4417
773.255	62.7638
776.656	63.0356
780.056	64.0719
783.454	63.9792
786.851	65.9348
790.247	68.2876
793.641	70.5085
797.034	71.5178
800.426	72.6194
803.817	74.736
807.206	76.2654
810.592	77.2204
813.979	79.5514
817.364	80.3528
820.748	82.1755
824.129	82.5167
827.511	82.54
830.891	82.7767
834.269	82.7405
837.646	81.3465
841.023	77.838
844.396	75.237
847.77	71.3613
851.141	67.2717
854.513	63.1878
857.881	61.2772
861.248	58.1195
864.616	55.0702
867.98	53.532
871.343	51.6629
874.707	49.8619
878.068	48.0834
881.428	48.6922
884.786	48.3731
888.143	48.8557
891.498	48.0936
894.855	49.007
898.208	51.2834
901.56	50.7555
904.91	52.6896
908.26	52.8393
911.608	53.5869
914.955	52.9955
918.298	50.9402
921.643	49.2364
924.986	46.7895
928.328	44.1694
931.668	43.5901
935.006	40.3904
938.344	39.5427
941.681	37.0632
945.014	33.87
948.349	32.5595
951.682	30.8537
955.012	29.6317
958.343	25.4917
961.67	25.4207
964.998	28.3425
968.323	29.829
971.649	32.977
974.971	36.1774
978.293	38.6584
981.615	39.3884
984.933	41.7082
988.251	41.6772
991.567	41.6793
994.884	40.8528
998.198	38.8364
1001.51	37.0666
1004.82	33.956
1008.13	32.9523
1011.44	30.6712
1014.75	28.384
1018.06	26.6723
1021.36	23.9853
1024.66	20.4757
1027.97	20.3566
1031.27	16.4621
1034.57	14.5558
1037.87	10.8924
1041.16	9.5304
1044.46	12.9204
1047.76	15.0258
1051.05	15.2591
1054.34	15.4555
1057.63	16.4623
1060.92	16.1868
1064.21	16.8286
1067.5	17.819
1070.78	16.9987
1074.07	17.133
1077.35	18.5377
1080.63	18.2103
1083.91	17.336
1087.19	18.9492
1090.47	20.721
1093.75	20.7611
1097.03	21.9822
1100.3	22.5857
1103.57	22.8191
1106.84	23.9959
1110.11	24.1775
1113.38	21.3365
1116.65	19.639
1119.92	18.5485
1123.19	18.7752
1126.45	17.4465
1129.71	15.7011
1132.97	13.7431
1136.23	13.0055
1139.49	9.88314
1142.75	9.8135
1146.01	8.64549
1149.26	6.62549
1152.52	5.44571
1155.77	4.69997
1159.02	3.15352
1162.27	1.59575
1165.52	1.71428
1168.77	1.74581
1172.02	2.20058
1175.26	2.05831
1178.51	2.59085
1181.75	2.781
1184.99	4.13139
1188.23	4.73088
1191.47	5.56014
1194.71	5.95774
1197.94	8.58376
1201.18	11.399
1204.41	13.9918
1207.65	14.4327
1210.88	18.3493
1214.11	21.2384
1217.34	26.3014
1220.57	31.3121
1223.79	36.9064
1227.02	40.079
1230.24	44.3361
1233.47	47.5093
1236.69	50.7623
1239.91	55.0209
1243.13	58.1246
1246.34	59.3253
1249.56	61.207
1252.78	60.0198
1255.99	60.3817
1259.2	60.1396
1262.42	59.7
1265.63	60.4244
1268.84	60.4102
1272.04	60.62
1275.25	61.5844
1278.46	61.8228
1281.66	64.7342
1284.86	67.7973
1288.07	70.29
1291.27	75.5062
1294.47	79.5927
1297.66	81.9496
1300.86	84.2604
1304.06	85.8744
1307.25	89.6534
1310.44	92.4485
1313.64	93.0584
1316.83	95.9705
1320.02	97.1911
1323.2	95.3555
1326.39	95.1275
1329.58	92.979
1332.76	90.6508
1335.95	89.9315
1339.13	88.6248
1342.31	86.1888
1345.49	82.1321
1348.67	79.2694
1351.85	78.5428
1355.02	75.5159
1358.2	72.3258
1361.37	68.8299
1364.54	65.9631
1367.71	62.862
1370.88	59.6042
1374.05	54.6126
1377.22	51.937
1380.39	48.9695
1383.55	47.1966
1386.72	46.46
1389.88	43.8845
1393.04	43.2237
1396.2	41.1233
1399.36	38.4174
1402.52	37.9421
1405.68	38.4317
1408.83	38.7793
1411.98	43.0527
1415.14	47.4064
1418.29	50.4162
1421.44	55.4359
1424.59	63.1514
1427.74	70.7346
1430.89	76.6118
1434.03	81.2574
1437.18	86.9884
1440.32	91.4308
1443.46	94.9789
1446.6	97.0849
1449.74	96.6239
1452.88	95.8512
1456.02	93.0688
1459.16	89.3069
1462.29	84.1455
1465.43	77.7412
1468.56	70.3465
1471.69	61.7542
1474.82	53.7053
1477.95	44.9739
1481.08	37.7411
1484.2	31.7432
1487.33	26.5308
1490.46	20.9435
1493.58	17.8915
1496.7	15.9771
1499.82	16.194
1502.94	15.5477
1506.06	15.9833
1509.18	16.0692
1512.29	16.6792
1515.41	17.5431
1518.52	17.9551
1521.63	19.1764
1524.75	21.9826
1527.85	23.3277
1530.96	25.2561
1534.07	26.6403
1537.18	28.3943
1540.28	32.71
1543.39	36.7677
1546.49	40.4178
1549.59	47.3956
1552.69	50.9089
1555.79	56.6418
1558.89	62.5864
1561.99	66.6305
1565.08	71.2073
1568.18	75.8485
1571.27	80.5921
1574.37	86.6261
1577.46	90.3489
1580.55	93.721
1583.64	96.9984
1586.73	99.0662
1589.81	100.337
1592.9	100.754
1595.98	98.7075
1599.06	97.6173
1602.15	95.7696
1605.23	92.2692
1608.31	89.0545
1611.39	85.5664
1614.46	83.9055
1617.54	81.3611
1620.61	79.7828
1623.69	81.3518
1626.76	81.1055
1629.83	81.1457
1632.9	83.4694
1635.97	83.5992
1639.04	83.6122
1642.11	86.2061
1645.17	91.3637
1648.24	94.9103
1651.3	100.639
1654.36	104.975
1657.42	107.944
1660.48	109.303
1663.54	109.661
1666.6	107.369
1669.66	103.996
1672.71	99.7959
1675.77	95.2371
1678.82	89.6325
1681.87	82.4495
1684.92	75.3789
1687.97	67.6237
1691.02	59.7043
1694.07	52.6149
1697.11	46.0636
1700.16	38.8407
1703.2	32.9986
1706.25	26.3875
1709.29	20.8218
1712.33	15.5379
1715.37	13.5422
1718.41	12.0923
1721.44	10.5164
1724.48	9.73986
1727.51	9.90296
1730.55	9.14499
1733.58	8.93756
1736.61	8.6267
1739.64	7.83002
1742.67	6.4197
1745.7	5.12346
1748.72	4.2466
1751.75	3.91825
1754.77	3.4199
1757.8	2.82408
1760.82	2.24659
1763.84	1.27502
1766.86	0.652034
1769.88	-0.491038
1772.9	-1.10544
1775.91	-1.5312
1778.93	-1.80409
1781.94	-2.52166
1784.96	-1.85923
1787.97	-1.98799
1790.98	-2.30511
1793.99	-2.03402
1797	-1.20681
1800.01	-0.868247
1803.01	0.238395
1806.02	0.720016
1809.02	1.45806
1812.02	1.51459
1815.02	1.67686
1818.03	1.43228
1821.02	2.25257
1824.02	2.92093
1827.02	3.8876
1830.02	4.43948
1833.01	4.3576
1836.01	4.07188
1839	4.34526
1841.99	3.79217
1844.98	3.72377
1847.97	4.10497
1850.96	3.09646
1853.95	3.65144
1856.93	2.4747
1859.92	3.37972
1862.9	4.84621
1865.88	4.55531
1868.87	4.20084
1871.85	4.18958
1874.83	3.63667
1877.81	4.53322
1880.78	3.88551
1882.53	3.90169
1885.52	4.41842
1888.51	5.41505
1891.5	5.84681
1894.48	6.71098
1897.47	7.43565
1900.45	8.94546
1903.43	9.18499
1906.41	10.5054
1909.39	11.3479
1912.37	11.6489
1915.35	11.295
1918.33	10.8109
1921.3	10.2661
1924.28	10.5885
1927.25	10.909
1930.22	11.9685
1933.19	13.1698
1936.16	12.7662
1939.13	12.6366
1942.1	12.2522
1945.07	12.0155
1948.03	11.165
1951	10.6654
1953.96	10.5145
1956.92	11.5589
1959.88	11.6268
1962.84	11.9588
1965.8	12.6023
1968.76	13.7104
1971.72	14.4554
1974.67	15.6422
1977.63	16.2335
1980.58	17.4646
1983.54	17.6513
1986.49	18.6446
1989.44	18.6103
1992.39	19.0827
1995.33	19.9408
1998.28	20.943
2001.23	21.9445
2004.17	22.5334
2007.12	22.6718
2010.06	22.5413
2013	22.5753
2015.94	22.8085
2018.88	23.0723
2021.82	23.0959
2024.76	23.275
2027.69	23.8093
2030.63	22.6616
2033.56	22.7114
2036.5	23.3674
2039.43	23.3052
2042.36	23.079
2045.29	23.9368
2048.22	24.5979
2051.15	24.9633
2054.07	24.9498
2057	24.3533
2059.92	24.5207
2062.85	24.4011
2065.77	24.7487
2068.69	24.1168
2071.61	24.3848
2074.53	25.5987
2077.45	25.0182
2080.37	24.6216
2083.28	25.8406
2086.2	26.0935
2089.11	26.9009
2092.02	26.6358
2094.94	27.1913
2097.85	27.1923
2100.76	26.9611
2103.66	27.741
2106.57	28.8165
2109.48	29.5536
2112.38	29.7517
2115.29	30.9807
2118.19	32.1257
2121.09	32.2729
2123.99	33.5994
2126.89	35.3839
2129.79	37.0302
2132.69	39.1931
2135.59	41.0889
2138.48	41.787
2141.38	41.9415
2144.27	43.9513
2147.17	45.3895
2150.06	46.7682
2152.95	48.442
2155.84	50.117
2158.73	51.982
2161.61	52.9458
2164.5	54.6355
2167.38	55.314
2170.27	56.469
2173.15	56.989
2176.03	58.1593
2178.91	57.3804
2181.8	57.4772
2184.67	56.583
2187.55	54.9753
2190.43	54.0017
2193.3	52.3173
2196.18	51.4735
2199.05	49.9175
2201.93	48.3918
2204.8	45.8299
2207.67	44.1882
2210.54	41.7856
2213.41	41.2086
2216.27	39.748
2219.14	39.5861
2222.01	37.621
2224.87	35.8262
2227.73	35.4918
2230.6	34.5269
2233.46	33.7951
2236.32	33.6724
2239.18	32.1502
2242.03	30.96
2244.89	30.2289
2247.75	29.3266
2250.6	27.9889
2253.46	26.8626
2256.31	25.9565
2259.16	24.7137
2262.01	24.2141
2264.86	24.1042
2267.71	23.4967
2270.56	23.6378
2273.4	23.2725
2276.25	23.8823
2279.09	23.8788
2281.94	23.1266
2284.78	22.6348
2287.62	22.2453
2290.46	21.9715
2293.3	21.0008
2296.14	21.4277
2298.98	21.4314
2301.82	21.5673
2304.65	21.5596
2307.49	22.5185
2310.32	22.3083
2313.15	23.8115
2315.98	23.4685
2318.81	23.1849
2321.64	22.8738
2324.47	23.2385
2327.3	22.4117
2330.12	22.5553
2332.95	21.6115
2335.77	21.4629
2338.6	20.4776
2341.42	18.6445
2344.24	17.1675
2347.06	16.5569
2349.88	16.1319
2352.7	14.4812
2355.51	13.5944
2358.33	13.3008
2361.14	12.634
2363.96	12.6308
2366.77	11.9233
2369.58	11.5702
2372.39	12.6872
2375.2	14.3583
2378.01	15.0439
2380.82	16.5904
2383.63	16.6858
2386.43	16.3242
2389.24	15.5593
2392.04	14.7264
2394.84	15.4492
2397.65	14.8366
2400.45	14.4923
2403.25	14.2562
2406.05	14.2852
2408.84	14.3777
2411.64	14.0711
2414.44	14.3881
2417.23	15.2024
2420.02	14.6848
2422.82	13.4927
2425.61	13.4609
2428.4	13.886
2431.19	13.5457
2433.98	12.5198
2436.77	12.569
2439.55	13.777
2442.34	15.2101
2445.12	15.3754
2447.91	15.0055
2450.69	14.7388
2453.47	13.4032
2456.25	12.4712
2459.03	11.8708
2461.81	11.8485
2464.59	11.1067
2467.36	9.65738
2470.14	9.77729
2472.92	9.28192
2475.69	9.15468
2478.46	8.17712
2481.23	7.63713
2484	6.29276
2486.77	4.56266
2489.54	2.80956
2492.31	2.76582
2495.08	2.66055
2497.84	2.16079
2500.61	1.7313
2503.37	0.467255
2506.13	0.506937
2508.9	0.792804
2511.66	0.297328
2514.42	0.445911
2517.18	0.987148
2519.93	2.15326
2522.69	3.0073
2525.45	3.40268
2528.2	4.10349
2530.95	5.07856
2533.71	5.78499
2536.46	5.67269
2539.21	6.50522
2541.96	6.08778
2544.71	6.87044
2547.46	6.5161
2550.2	6.59774
2552.95	4.99084
2555.7	4.10305
2558.44	3.56276
2561.18	3.54267
2563.93	2.89454
2566.67	2.66151
2569.41	1.71201
2572.15	1.34158
2574.88	1.99318
2577.62	1.93354
2580.36	2.24619
2583.09	3.09061
2585.83	3.36597
2588.56	4.50419
2591.29	4.41374
2594.02	3.56224
2596.75	4.29989
2599.48	3.88228
2602.21	3.80758
2604.94	3.03719
2607.67	2.77305
2610.39	2.38231
2613.12	2.02249
2615.84	0.863546
2618.56	-0.462364
2621.28	-1.27227
2624.01	-1.20415
2626.72	-1.41538
2629.44	-1.42543
2632.16	-0.626063
2634.88	-0.466084
2637.59	-0.199549
2640.31	-0.199686
2643.02	0.840257
2645.74	1.12496
2648.45	1.92252
2651.16	2.04797
2653.87	2.34969
2656.58	2.6636
2659.29	1.93659
2661.99	2.72003
2664.7	3.63854
2667.41	3.82799
2670.11	3.90506
2672.81	3.28248
2675.51	3.78587
2678.22	4.41255
2680.92	5.12297
2683.62	4.72513
2686.31	4.92975
2689.01	5.21032
2691.71	5.85869
2694.4	5.86955
2697.1	5.8078
2699.79	5.08514
2702.49	5.56526
2705.18	5.73913
2707.87	7.28689
2710.56	8.56685
2713.25	8.73492
2715.94	8.9156
2718.62	10.1001
2721.31	9.98802
2723.99	10.6437
2726.68	10.7095
2729.36	10.7727
2732.04	10.3366
2734.73	10.5598
2737.41	11.2044
2740.08	11.5441
2742.76	11.7778
2745.44	10.4575
2748.12	10.1789
2750.79	9.23472
2753.47	8.50027
2756.14	7.89345
2758.81	6.44779
2761.49	4.82023
2764.16	2.96139
2766.83	2.89749
2769.5	2.68455
2772.16	3.1141
2774.83	1.87853
2777.5	1.13537
2780.16	0.536031
2782.83	0.211199
2785.49	-0.808598
2788.15	-1.02148
2790.82	-0.730292
2793.48	-1.717
2796.14	-1.91202
2798.79	-1.10748
2801.45	-0.136881
2804.11	0.37373
2806.76	-0.058687
2809.42	-0.208195
2812.07	-0.325883
2814.73	-0.102559
2817.38	1.3722
2820.03	3.88024
2822.68	7.25483
2825.33	12.4041
2827.98	17.5517
2830.63	23.8136
2833.27	29.9838
2835.92	36.7694
2838.56	44.2465
2841.21	52.9064
2843.85	63.9044
2846.49	75.7338
2849.13	87.8291
2851.77	101.305
2854.41	114.967
2857.05	129.066
2859.69	142.47
2862.32	154.598
2864.96	165.823
2867.59	175.806
2870.23	184.137
2872.86	190.608
2875.49	197.505
2878.12	202.487
2880.75	208.446
2883.38	213.383
2886.01	219.115
2888.63	224.649
2891.26	230.6
2893.89	235.5
2896.51	241.723
2899.13	248.691
2901.76	258.56
2904.38	269.686
2907	283.479
2909.62	298.344
2912.24	313.82
2914.85	329.929
2917.47	343.75
2920.09	356.573
2922.7	366.731
2925.32	373.321
2927.93	376.806
2930.54	378.684
2933.15	377.839
2935.76	374.908
2938.37	369.197
2940.98	360.922
2943.59	351.257
2946.2	339.895
2948.8	327.679
2951.41	315.886
2954.01	302.1
2956.62	287.848
2959.22	275.252
2961.82	262.579
2964.42	251.056
2967.02	240.639
2969.62	230.243
2972.22	219.703
2974.81	209.786
2977.41	199.128
2980	188.357
2982.6	176.084
2985.19	163.786
2987.78	150.696
2990.38	139.098
2992.97	127.78
2995.56	117.03
2998.14	107.399
3000.73	95.8739
3003.32	85.4613
3005.91	76.7207
3008.49	67.4257
3011.07	59.062
3013.66	52.0274
3016.24	46.0469
3018.82	40.4112
3021.4	36.3809
3023.98	33.2477
3026.56	30.845
3029.14	28.9088
3031.71	29.2052
3034.29	28.5552
3036.87	28.6878
3039.44	30.6907
3042.01	32.692
3044.59	34.8642
3047.16	36.6529
3049.73	38.4524
3052.3	40.7364
3054.87	41.7213
3057.43	42.1379
3060	42.5133
3062.57	41.4753
3065.13	39.5621
3067.7	37.5298
3070.26	34.8691
3072.82	31.3584
3075.39	28.1459
3077.95	23.9954
3080.51	19.865
3083.07	16.5505
3085.63	13.3314
3088.18	10.6031
3090.74	7.42685
3093.29	6.18916
3095.85	4.68634
3098.4	3.74779
3100.95	3.45092
3103.51	3.14717
3106.06	3.6573
3108.61	3.25899
3111.16	2.8151
3113.71	3.60319
3116.25	3.65045
3118.8	3.89193
3121.35	4.63435
3123.89	5.08961
3126.44	4.30703
3128.98	4.05425
3131.52	3.51239
3134.06	2.87564
3136.6	1.37346
3139.14	0.347965
3141.68	-0.764491
3144.22	-1.63968
3146.76	-2.93154
3149.29	-3.56154