File: data/Raman/poly_smoothed/Thy_50_12_32_1x_45s_532 nm_x100_100%_600 gr_mm_01.txt
#Acq. time (s)=	45
#Accumulations=	2
#Range (cm-¹)=	200...3150
#Windows=	2
#Auto scanning=	Off
#Autofocus=	Off
#Macrospot=	Off
#AutoExposure=	Off
#Spike filter=	Multiple accum.
#Delay time (s)=	0
#Binning=	1
#Readout mode=	Signal
#DeNoise=	Off
#ICS correction=	On
#Dark correction=	Off
#Inst. Process=	Off
#Detector Gain=	Best Dynamic Range
#Detector ADC=	20 kHz
#Detector temperature (°C)=	-70.08
#Instrument=	LabRAM HR Evol
#Detector=	Synapse
#Objective=	x100
#Grating=	600 gr/mm
#ND Filter=	100%
#Laser (nm)=	532
#Hole=	100.021
#Range=	Auto
#Laser Pol.=	No
#Raman. Pol.=	No
#Laser Pol. (°)=	-0.0007625
#Raman Pol. (°)=	89.9995
#Collection=	Microscope
#StageXY=	Marzhauser
#StageZ=	Marzhauser
#X (µm)=	-5138.8
#Y (µm)=	1515
#Z (µm)=	63.7
#Full time(mm:ss)=	3:18
#Project=
#Sample=
#Site=
#Title=	Thy_50_12_32_2x_45s_532 nm_x100_100%_600 gr_mm
#Remark=
#Date=	07.07.2022 11:35
#Acquired=	07.07.2022 11:35:23
#Base:Fit=	10.08.2022 10:04:30
#Base:Sub=	10.08.2022 10:04:45
#Filter:Polynom=	16.08.2022 10:20:25
#AxisType[0]=Intens
#AxisUnit[0]=Cnt
#AxisType[1]=Spectr
#AxisUnit[1]=1/cm
200.43	25.5423
204.061	32.6198
207.688	33.9538
211.316	33.8305
214.941	31.848
218.566	30.9867
222.188	28.651
225.809	27.4151
229.43	25.6158
233.047	25.0881
236.663	23.4439
240.278	22.2428
243.894	21.7373
247.506	20.7932
251.116	17.8889
254.725	16.4451
258.333	16.5216
261.939	14.9383
265.546	14.7746
269.15	12.5604
272.752	11.3231
276.353	9.62181
279.952	9.72191
283.55	9.53368
287.146	8.42357
290.739	8.75902
294.333	7.4491
297.925	7.44471
301.516	6.365
305.106	7.35698
308.694	9.17597
312.279	9.76742
315.864	9.40513
319.448	9.487
323.029	9.47647
326.61	11.3229
330.19	11.7047
333.766	12.6042
337.343	11.2926
340.917	11.1093
344.491	9.99331
348.062	9.1593
351.633	6.83027
355.201	5.14112
358.77	3.52623
362.335	3.30302
365.899	3.04144
369.464	3.03965
373.025	3.22784
376.585	4.49544
380.143	5.9436
383.702	5.00379
387.258	7.29096
390.812	8.51409
394.365	7.46487
397.916	8.08912
401.467	8.22547
405.015	10.7313
408.565	12.2443
412.111	11.2763
415.656	11.159
419.197	10.4364
422.739	11.8423
426.279	11.1359
429.819	9.70779
433.356	8.61198
436.893	7.53446
440.428	9.17001
443.96	10.0475
447.492	9.73762
451.023	12.1056
454.553	13.2198
458.079	16.1571
461.606	18.8883
465.132	20.5499
468.654	22.8024
472.177	26.3767
475.696	30.0795
479.217	33.0702
482.733	33.9991
486.251	35.3024
489.765	37.5667
493.278	39.6315
496.791	39.4757
500.301	39.7218
503.81	40.0446
507.319	39.2473
510.825	39.2939
514.33	37.1596
517.833	36.5677
521.337	35.6331
524.838	35.1001
528.337	34.1754
531.835	32.6537
535.332	30.7654
538.827	30.8445
542.321	28.6902
545.814	29.7175
549.305	28.4665
552.795	26.0726
556.284	27.8368
559.771	26.2733
563.257	25.1951
566.742	21.1482
570.223	20.1402
573.705	20.1223
577.185	20.4734
580.665	18.1881
584.141	15.5844
587.617	13.9455
591.092	13.0453
594.564	12.7888
598.037	10.1299
601.506	9.83576
604.976	8.9129
608.443	7.70606
611.91	6.81686
615.374	7.11364
618.839	6.38551
622.3	5.29462
625.761	7.02487
629.221	8.27651
632.679	10.4942
636.135	12.5362
639.592	14.9635
643.045	16.814
646.497	19.0029
649.948	20.3314
653.398	20.4098
656.846	21.2621
660.293	22.6725
663.738	22.1085
667.185	22.9026
670.628	22.7597
674.067	25.0407
677.508	26.5344
680.947	28.7522
684.385	30.6746
687.821	32.0284
691.256	34.3198
694.69	34.312
698.121	36.9622
701.552	38.0917
704.982	38.5331
708.41	40.7836
711.836	43.8745
715.262	45.7329
718.685	48.1268
722.108	49.9645
725.53	51.1594
728.949	50.4096
732.369	52.3619
735.785	52.0421
739.2	51.9782
742.616	54.4708
746.028	55.0195
749.441	55.8514
752.851	58.2509
756.26	61.2897
759.667	64.117
763.075	67.7123
766.479	70.0788
769.883	69.6475
773.285	70.5716
776.686	71.6312
780.085	72.0644
783.484	73.2204
786.881	73.6328
790.276	73.6971
793.671	74.6856
797.064	74.8549
800.456	76.4777
803.846	78.2713
807.236	78.0511
810.624	77.9867
814.01	80.0686
817.394	80.3702
820.778	80.2933
824.161	81.2367
827.543	80.6434
830.921	79.8948
834.3	79.8164
837.676	78.1552
841.053	74.9708
844.426	72.1922
847.8	68.8091
851.171	66.4741
854.542	64.8325
857.911	63.3595
861.279	61.2052
864.645	59.1201
868.01	55.266
871.375	55.2081
874.737	53.1609
878.097	52.4356
881.457	51.0055
884.817	48.0431
888.174	45.054
891.53	41.0201
894.884	39.5369
898.237	37.8173
901.589	35.557
904.94	32.952
908.289	31.5936
911.637	27.9246
914.984	28.2652
918.33	26.9066
921.674	24.0823
925.015	21.8256
928.357	20.0546
931.698	19.7292
935.037	18.2083
938.373	17.503
941.71	17.1835
945.046	14.8426
948.378	16.1752
951.711	19.0139
955.043	22.4013
958.372	22.7606
961.701	23.4709
965.027	24.5463
968.354	24.8645
971.678	24.9301
975	28.341
978.324	31.0239
981.644	31.8753
984.962	37.0777
988.282	38.3465
991.598	41.1318
994.913	44.7566
998.227	46.2071
1001.54	44.6384
1004.85	43.9994
1008.16	44.6542
1011.47	46.0985
1014.78	47.3404
1018.08	47.6007
1021.39	49.0479
1024.69	49.1251
1028	52.1052
1031.3	56.4645
1034.6	56.8396
1037.9	55.6475
1041.19	57.0731
1044.49	57.9958
1047.79	54.8647
1051.08	51.4394
1054.37	49.8509
1057.66	47.6915
1060.95	45.1075
1064.24	44.6139
1067.53	42.2045
1070.81	37.5496
1074.1	35.4915
1077.38	31.6812
1080.66	28.709
1083.94	24.8455
1087.22	22.428
1090.5	22.5648
1093.78	22.3678
1097.05	22.62
1100.33	23.4591
1103.6	23.3761
1106.87	24.6515
1110.15	26.5439
1113.41	27.5316
1116.68	25.8601
1119.95	27.101
1123.21	25.6879
1126.48	22.349
1129.74	20.424
1133	20.0827
1136.26	17.0424
1139.52	16.465
1142.78	14.5479
1146.04	13.228
1149.29	9.29306
1152.55	6.67592
1155.8	3.39719
1159.05	0.253732
1162.3	0.222755
1165.55	-1.2679
1168.8	-0.281233
1172.05	2.16734
1175.29	2.23025
1178.54	2.79849
1181.78	3.2262
1185.02	3.84076
1188.26	4.19397
1191.5	5.16607
1194.74	6.99075
1197.97	8.03935
1201.21	9.72351
1204.44	12.6923
1207.68	17.1484
1210.91	20.9736
1214.14	25.844
1217.37	30.1141
1220.6	36.5958
1223.82	42.3445
1227.05	46.3211
1230.27	52.3126
1233.49	59.5535
1236.72	65.2752
1239.94	73.4583
1243.16	80.8871
1246.37	86.7384
1249.59	91.298
1252.8	95.6976
1256.02	100.497
1259.23	105.242
1262.44	110.148
1265.66	115.47
1268.87	120.597
1272.07	126.255
1275.28	129.904
1278.48	134.1
1281.69	137.755
1284.89	141.076
1288.09	144.451
1291.3	147.08
1294.49	148.693
1297.69	149.675
1300.89	150.077
1304.09	149.633
1307.28	149.946
1310.47	149.009
1313.66	147.278
1316.86	145.444
1320.05	143.766
1323.23	141.684
1326.42	137.142
1329.61	134.779
1332.79	134.552
1335.98	131.965
1339.16	128.035
1342.34	123.681
1345.52	120.602
1348.7	118.773
1351.87	113.42
1355.05	109.907
1358.23	106.705
1361.4	104.406
1364.57	101.103
1367.74	97.9307
1370.91	95.1419
1374.08	93.5505
1377.25	92.6462
1380.42	91.8612
1383.58	90.7866
1386.75	89.0192
1389.91	86.9261
1393.07	84.8621
1396.23	82.5568
1399.39	84.1343
1402.55	86.0089
1405.7	86.1879
1408.86	88.9266
1412.01	92.4827
1415.17	95.6626
1418.32	101.588
1421.47	109.972
1424.62	119.713
1427.77	131.08
1430.92	141.611
1434.06	150.536
1437.2	159.808
1440.35	167.642
1443.49	172.401
1446.63	176.01
1449.77	180.493
1452.91	178.655
1456.05	175.113
1459.18	168.55
1462.32	158.088
1465.45	146.926
1468.59	134.423
1471.72	120.676
1474.85	110.205
1477.98	96.7514
1481.11	83.5089
1484.23	71.913
1487.36	61.7783
1490.48	53.6231
1493.61	46.7866
1496.73	44.2029
1499.85	41.8474
1502.97	41.3905
1506.09	41.7942
1509.2	42.733
1512.32	45.1193
1515.44	47.9839
1518.55	51.536
1521.66	53.8811
1524.77	59.0524
1527.88	64.0828
1530.99	67.7909
1534.1	73.8627
1537.21	77.8801
1540.31	84.821
1543.42	93.729
1546.52	103.076
1549.62	111.406
1552.72	119.101
1555.82	125.443
1558.92	131.297
1562.02	136.768
1565.11	144.508
1568.21	151.463
1571.3	157.572
1574.39	164.081
1577.49	168.156
1580.58	170.257
1583.67	172.664
1586.75	173.082
1589.84	171.186
1592.93	169.278
1596.01	166.456
1599.09	163.682
1602.18	161.913
1605.26	158.065
1608.34	154.064
1611.41	153.28
1614.49	152.166
1617.57	151.537
1620.64	152.12
1623.72	153.929
1626.79	152.289
1629.86	154.778
1632.93	157.388
1636	158.765
1639.07	163.738
1642.14	167.499
1645.2	170.759
1648.27	174.865
1651.33	175.486
1654.39	173.842
1657.45	171.4
1660.51	167.373
1663.57	161.706
1666.63	154.382
1669.69	147.119
1672.74	138.087
1675.79	127.928
1678.85	117.036
1681.9	106.111
1684.95	95.1565
1688	84.995
1691.05	73.4038
1694.1	64.9851
1697.14	57.1682
1700.19	49.0928
1703.23	41.7376
1706.27	36.7761
1709.32	31.0366
1712.35	27.4842
1715.39	23.5255
1718.43	22.8193
1721.47	21.0094
1724.5	19.7165
1727.54	18.6585
1730.57	17.6237
1733.61	16.3707
1736.64	14.7681
1739.67	13.5304
1742.7	11.2678
1745.72	11.0823
1748.75	9.54967
1751.78	8.63125
1754.8	7.73571
1757.82	7.35651
1760.85	6.8047
1763.87	5.35174
1766.89	5.60521
1769.91	4.81991
1772.92	3.64649
1775.94	3.36873
1778.96	3.94442
1781.97	2.9742
1784.98	3.14789
1788	3.65575
1791.01	3.86901
1794.01	4.25456
1797.02	3.62462
1800.03	4.0921
1803.04	3.30205
1806.04	3.30167
1809.05	2.80067
1812.05	1.99463
1815.05	1.93409
1818.05	2.62471
1821.05	2.91749
1824.05	2.38768
1827.05	2.11623
1830.04	2.80262
1833.04	3.11257
1836.03	3.32416
1839.03	3.46272
1842.02	2.73607
1845.01	2.32635
1848	2.26229
1850.99	1.96701
1853.97	1.59666
1856.96	2.03664
1859.94	1.71354
1862.93	1.65806
1865.91	2.92514
1868.89	3.37728
1871.87	3.64605
1874.85	4.84115
1877.83	4.00376
1880.81	3.68564
1882.56	4.31168
1885.55	4.71874
1888.54	5.86462
1891.52	5.72236
1894.51	6.94445
1897.49	6.21999
1900.48	7.00267
1903.46	5.74137
1906.44	5.57145
1909.42	5.01956
1912.4	5.51786
1915.38	4.73868
1918.35	4.76903
1921.33	6.69309
1924.3	6.09065
1927.28	6.54309
1930.25	5.4361
1933.22	5.79733
1936.19	5.60001
1939.16	5.91913
1942.13	5.63207
1945.09	5.74874
1948.06	5.38214
1951.03	4.85763
1953.99	4.78781
1956.95	5.53628
1959.91	4.89937
1962.87	4.24198
1965.83	4.44438
1968.79	4.2557
1971.75	3.45975
1974.7	3.24284
1977.66	3.71353
1980.61	4.70876
1983.56	6.41791
1986.52	6.22094
1989.47	6.7974
1992.41	7.66483
1995.36	7.69202
1998.31	6.63133
2001.26	7.60296
2004.2	7.42541
2007.15	7.90333
2010.09	7.94401
2013.03	9.38487
2015.97	9.89007
2018.91	9.49656
2021.85	12.2073
2024.79	11.6165
2027.72	11.4347
2030.66	12.0931
2033.59	12.0395
2036.53	12.9656
2039.46	14.1835
2042.39	15.0416
2045.32	15.8897
2048.25	16.6421
2051.18	17.9927
2054.1	18.9049
2057.03	20.3266
2059.95	22.157
2062.88	24.44
2065.8	26.675
2068.72	28.7328
2071.64	32.8933
2074.56	35.4999
2077.48	37.8458
2080.39	41.7415
2083.31	45.2759
2086.22	48.6133
2089.14	52.0586
2092.05	57.1636
2094.96	61.6215
2097.87	65.0835
2100.78	69.8991
2103.69	76.8509
2106.6	82.0715
2109.51	87.067
2112.41	93.3186
2115.32	99.0215
2118.22	106.064
2121.12	113.565
2124.02	119.678
2126.92	125.696
2129.82	134.407
2132.72	142.077
2135.62	150.356
2138.51	158.336
2141.41	166.539
2144.3	173.958
2147.19	180.457
2150.09	187.347
2152.97	193.978
2155.86	199.961
2158.75	203.382
2161.64	206.652
2164.53	209.736
2167.41	210.1
2170.3	210.748
2173.18	210.056
2176.06	209.25
2178.94	205.01
2181.82	201.321
2184.7	196.393
2187.58	190.911
2190.46	184.236
2193.33	177.259
2196.21	169.477
2199.08	164.316
2201.95	157.308
2204.83	148.806
2207.7	141.351
2210.57	134.214
2213.43	126.975
2216.3	120.66
2219.17	113.416
2222.03	107.258
2224.9	100.863
2227.76	94.9468
2230.62	88.5344
2233.49	82.7664
2236.34	77.5651
2239.2	74.1511
2242.06	68.3505
2244.92	65.2792
2247.78	61.752
2250.63	57.8971
2253.48	55.4292
2256.34	51.6966
2259.19	49.6878
2262.04	48.3378
2264.89	46.5159
2267.74	44.4729
2270.59	42.8519
2273.43	40.0283
2276.28	37.5587
2279.12	35.3193
2281.97	34.7455
2284.81	32.6222
2287.65	31.4458
2290.49	29.6121
2293.33	28.9569
2296.17	27.3676
2299.01	25.6897
2301.84	22.8904
2304.68	22.6952
2307.51	21.399
2310.35	18.947
2313.18	18.3032
2316.01	16.9713
2318.84	16.6392
2321.67	15.7904
2324.5	16.4108
2327.33	13.5312
2330.15	11.936
2332.98	12.0424
2335.8	10.6897
2338.62	10.514
2341.45	10.6425
2344.27	9.48053
2347.09	8.56093
2349.91	7.8662
2352.72	7.92246
2355.54	7.31542
2358.36	5.95362
2361.17	5.81135
2363.98	5.88952
2366.8	4.37353
2369.61	3.99358
2372.42	5.37396
2375.23	4.89992
2378.04	3.37531
2380.85	3.91986
2383.66	4.13928
2386.46	3.90815
2389.26	4.17514
2392.07	4.70582
2394.87	4.71949
2397.67	3.61826
2400.47	5.65751
2403.27	5.78312
2406.07	5.97251
2408.87	7.59206
2411.67	6.7201
2414.46	6.87037
2417.26	7.39354
2420.05	8.82765
2422.84	10.468
2425.64	10.8812
2428.43	10.9269
2431.22	11.5636
2434.01	11.2806
2436.79	11.4248
2439.58	12.3859
2442.37	11.6767
2445.15	11.1696
2447.93	10.5959
2450.72	10.374
2453.5	10.3156
2456.28	9.03162
2459.06	8.56692
2461.84	6.99885
2464.62	5.39977
2467.39	5.01353
2470.17	4.92178
2472.94	3.25678
2475.72	3.77966
2478.49	4.0122
2481.26	4.31894
2484.03	5.88965
2486.8	5.75421
2489.57	5.55025
2492.34	4.35533
2495.1	3.35502
2497.87	2.97547
2500.63	2.66859
2503.4	3.16013
2506.16	2.36617
2508.92	2.62293
2511.68	2.55013
2514.44	1.63029
2517.2	1.4219
2519.96	1.49254
2522.72	0.9744
2525.47	1.59109
2528.23	1.54802
2530.98	1.75005
2533.74	3.48256
2536.49	4.64504
2539.24	5.79677
2541.99	6.45935
2544.74	7.49891
2547.49	9.13008
2550.23	8.85273
2552.98	8.79209
2555.72	8.17504
2558.47	9.63121
2561.21	8.87417
2563.95	9.11062
2566.69	8.60922
2569.43	8.87998
2572.17	8.08802
2574.91	7.33465
2577.65	6.43861
2580.39	5.78351
2583.12	4.9124
2585.85	4.72266
2588.59	4.78396
2591.32	4.34768
2594.05	4.06656
2596.78	3.75016
2599.51	2.86573
2602.24	2.48749
2604.97	1.80411
2607.69	1.63624
2610.42	0.885618
2613.14	1.31693
2615.87	1.33662
2618.59	1.65249
2621.31	1.68323
2624.03	1.35146
2626.75	1.86432
2629.47	1.48418
2632.19	0.727452
2634.91	0.744808
2637.62	0.499024
2640.34	0.116814
2643.05	0.87181
2645.76	0.513471
2648.48	1.88793
2651.19	1.82058
2653.9	2.64991
2656.6	2.57544
2659.31	1.62448
2662.02	1.89958
2664.73	1.96881
2667.43	1.5135
2670.14	0.860213
2672.84	1.1636
2675.54	1.52894
2678.24	1.86652
2680.94	2.11826
2683.64	2.2252
2686.34	3.46403
2689.04	4.56138
2691.74	5.19262
2694.43	5.40121
2697.13	6.05727
2699.82	5.85742
2702.51	7.35358
2705.21	8.03933
2707.9	9.42478
2710.58	10.4834
2713.27	11.5893
2715.96	13.24
2718.65	13.9442
2721.33	14.1411
2724.02	14.0823
2726.71	13.9947
2729.39	15.5979
2732.07	15.7744
2734.75	15.6863
2737.43	15.9487
2740.11	16.0594
2742.79	14.8582
2745.47	15.0284
2748.14	13.7229
2750.82	13.0069
2753.49	12.2715
2756.17	10.8197
2758.84	7.96638
2761.51	6.72065
2764.18	7.00145
2766.85	5.27577
2769.52	4.47936
2772.19	3.353
2774.86	2.90569
2777.52	1.28606
2780.19	0.387013
2782.85	-0.113282
2785.52	-0.734177
2788.18	-1.28911
2790.84	-1.02206
2793.5	-0.804663
2796.16	-0.625536
2798.82	-0.432708
2801.48	-1.51448
2804.13	-2.60168
2806.79	-3.7507
2809.45	-4.70656
2812.1	-4.75215
2814.75	-5.60995
2817.41	-3.89636
2820.06	-1.0563
2822.71	6.08257
2825.36	13.3328
2828	22.5939
2830.65	31.9288
2833.3	41.3386
2835.94	53.1389
2838.59	64.0697
2841.23	76.7053
2843.87	91.2005
2846.52	107.538
2849.16	124.832
2851.8	144.401
2854.44	163.409
2857.08	181.339
2859.71	199.041
2862.35	215.709
2864.98	230.443
2867.62	243.426
2870.25	254.869
2872.88	264.821
2875.52	273.575
2878.15	281.485
2880.78	289.836
2883.41	298.159
2886.03	307.09
2888.66	314.834
2891.29	321.003
2893.91	327.49
2896.54	335.739
2899.16	345.019
2901.78	356.364
2904.4	370.162
2907.02	385.884
2909.64	404.855
2912.26	424.517
2914.88	445.239
2917.5	463.733
2920.11	478.999
2922.73	492.599
2925.34	502.27
2927.96	507.633
2930.57	509.629
2933.18	508.361
2935.79	504.177
2938.4	497.896
2941.01	487.275
2943.62	474.052
2946.22	458.559
2948.83	441.538
2951.43	424.222
2954.04	404.633
2956.64	384.342
2959.24	365.639
2961.84	346.368
2964.45	327.492
2967.05	309.786
2969.64	291.913
2972.24	274.16
2974.84	256.748
2977.43	239.107
2980.03	221.374
2982.62	202.045
2985.22	182.794
2987.81	163.694
2990.4	144.548
2992.99	126.414
2995.58	110.012
2998.17	95.7722
3000.76	81.6578
3003.34	68.2443
3005.93	56.4542
3008.52	46.8234
3011.1	39.489
3013.68	32.594
3016.27	27.4151
3018.85	22.2366
3021.43	19.4226
3024.01	16.8264
3026.59	15.0297
3029.16	15.3987
3031.74	14.8695
3034.32	16.2206
3036.89	18.2177
3039.47	19.8179
3042.04	21.6692
3044.61	23.1052
3047.18	24.3901
3049.75	25.0691
3052.32	25.4025
3054.89	25.8364
3057.46	25.871
3060.03	25.8084
3062.59	23.5985
3065.16	21.6101
3067.72	20.0465
3070.29	18.4488
3072.85	15.7582
3075.41	12.4254
3077.97	10.5918
3080.53	6.91843
3083.09	4.42519
3085.65	2.82133
3088.21	1.17293
3090.76	1.55164
3093.32	1.74707
3095.87	1.84301
3098.43	2.53142
3100.98	3.30749
3103.53	5.11027
3106.08	5.8058
3108.63	7.26955
3111.18	9.68875
3113.73	11.7083
3116.28	13.4829
3118.83	17.6121
3121.37	19.968
3123.92	22.6292
3126.46	26.2059
3129	30.4172
3131.55	33.9287
3134.09	36.5425
3136.63	39.1229
3139.17	43.1055
3141.71	47.4245
3144.24	52.6256
3146.78	57.6806
3149.32	63.66