File: data/Raman/poly_smoothed/Thy_10_08_10_1x_45s_532 nm_x100_100%_600 gr_mm_01.txt
#Acq. time (s)=	45
#Accumulations=	2
#Range (cm-¹)=	200...3150
#Windows=	2
#Auto scanning=	Off
#Autofocus=	Off
#Macrospot=	Off
#AutoExposure=	Off
#Spike filter=	Multiple accum.
#Delay time (s)=	0
#Binning=	1
#Readout mode=	Signal
#DeNoise=	Off
#ICS correction=	On
#Dark correction=	Off
#Inst. Process=	Off
#Detector Gain=	Best Dynamic Range
#Detector ADC=	20 kHz
#Detector temperature (°C)=	-69.85
#Instrument=	LabRAM HR Evol
#Detector=	Synapse
#Objective=	x100
#Grating=	600 gr/mm
#ND Filter=	100%
#Laser (nm)=	532
#Hole=	100.021
#Range=	Auto
#Laser Pol.=	No
#Raman. Pol.=	No
#Laser Pol. (°)=	-0.0007625
#Raman Pol. (°)=	89.9995
#Collection=	Microscope
#StageXY=	Marzhauser
#StageZ=	Marzhauser
#X (µm)=	2169
#Y (µm)=	1262.5
#Z (µm)=	442.3
#Full time(mm:ss)=	3:19
#Project=
#Sample=
#Site=
#Title=	Thy_10_08_10_2x_45s_532 nm_x100_100%_600 gr_mm
#Remark=
#Date=	05.07.2022 14:54
#Acquired=	05.07.2022 14:54:03
#Base:Fit=	10.08.2022 09:46:25
#Base:Sub=	10.08.2022 09:46:49
#Filter:Polynom=	16.08.2022 10:24:56
#AxisType[0]=Intens
#AxisUnit[0]=Cnt
#AxisType[1]=Spectr
#AxisUnit[1]=1/cm
200.43	-2.68649
204.059	5.13034
207.688	9.72227
211.314	13.3703
214.941	15.234
218.564	17.3493
222.186	17.0909
225.809	17.297
229.428	18.8227
233.045	19.7428
236.663	19.6687
240.278	19.1787
243.891	17.5057
247.503	16.4929
251.116	13.7637
254.725	12.6813
258.333	12.2169
261.939	12.8775
265.544	11.951
269.148	10.3796
272.75	9.34831
276.351	9.57904
279.95	9.82541
283.548	10.7285
287.144	10.3157
290.739	10.5625
294.333	11.3125
297.925	12.8287
301.514	13.0522
305.104	14.2242
308.692	13.9885
312.279	15.3455
315.862	15.3548
319.446	16.3178
323.029	15.6698
326.608	15.4212
330.188	15.4491
333.766	14.368
337.341	14.4938
340.917	12.9226
344.489	13.3425
348.062	10.9775
351.631	9.23056
355.201	8.15771
358.768	6.03612
362.333	5.61453
365.899	5.68186
369.462	5.04971
373.023	5.36955
376.585	4.1006
380.143	4.47559
383.7	6.28721
387.256	7.08091
390.812	6.46695
394.365	7.56708
397.916	7.089
401.467	7.20223
405.015	6.7955
408.563	7.5836
412.109	7.50892
415.654	6.98586
419.197	6.9307
422.739	6.99285
426.279	5.68574
429.819	6.01967
433.356	4.50454
436.891	4.39431
440.426	3.73012
443.96	3.25622
447.492	2.15152
451.021	3.43208
454.551	2.41026
458.079	4.95429
461.604	4.47474
465.13	5.29364
468.654	5.95705
472.175	7.31213
475.696	7.33275
479.215	9.00331
482.733	9.77255
486.249	11.5103
489.765	12.4575
493.278	12.8261
496.789	15.3632
500.301	16.1922
503.81	18.2997
507.317	18.4463
510.825	18.8917
514.33	19.7962
517.833	19.0587
521.335	18.191
524.836	18.6792
528.335	17.0762
531.835	17.4523
535.332	16.1017
538.827	13.5566
542.321	12.4637
545.814	11.6108
549.305	9.57815
552.795	7.93146
556.282	5.29874
559.769	5.64711
563.255	3.45224
566.739	3.70897
570.223	3.57818
573.705	4.99689
577.183	4.80146
580.663	4.47227
584.141	4.58619
587.615	5.61211
591.09	5.18009
594.564	3.44179
598.035	3.30172
601.506	2.58902
604.974	2.8699
608.443	2.40435
611.908	1.59194
615.374	1.21426
618.837	0.590119
622.3	0.726912
625.761	0.30035
629.219	0.380519
632.677	1.80423
636.135	2.11564
639.59	2.01062
643.043	2.54838
646.495	4.41461
649.948	7.41561
653.398	8.4759
656.846	10.7813
660.293	12.4723
663.738	13.5106
667.183	14.8846
670.626	16.3835
674.067	18.6516
677.508	19.2862
680.947	20.4253
684.385	23.3463
687.821	26.4752
691.254	28.0372
694.688	30.7998
698.121	31.6952
701.552	32.5323
704.98	34.3666
708.409	36.1481
711.836	37.0123
715.26	40.1785
718.685	42.1119
722.108	42.6883
725.528	46.0864
728.949	47.9679
732.367	50.0264
735.785	50.4092
739.2	52.1701
742.614	53.2553
746.028	55.3258
749.439	57.6586
752.849	60.1627
756.26	63.069
759.667	64.9333
763.073	68.5902
766.477	70.6318
769.883	74.3871
773.285	76.1338
776.686	77.5691
780.085	79.2825
783.484	79.5199
786.881	79.9588
790.276	82.5143
793.671	84.1525
797.064	86.203
800.456	88.0574
803.846	88.1988
807.234	89.5031
810.622	89.477
814.008	89.5638
817.394	90.2523
820.778	90.7594
824.159	90.2337
827.541	90.6205
830.921	90.7152
834.298	90.6642
837.676	89.3264
841.051	87.7999
844.426	84.8769
847.798	83.8665
851.171	81.816
854.54	79.1748
857.911	75.3756
861.278	72.6371
864.645	69.7326
868.01	66.2895
871.373	66.1708
874.735	65.035
878.097	64.68
881.457	63.7229
884.815	62.4128
888.172	61.6342
891.528	61.618
894.882	62.6782
898.237	63.1067
901.589	63.3846
904.94	62.9674
908.289	62.8407
911.635	62.7958
914.982	62.7266
918.328	62.3584
921.672	61.2315
925.015	60.3125
928.357	58.1701
931.698	58.5268
935.035	57.0329
938.373	54.8487
941.71	53.9848
945.044	51.1299
948.378	51.6638
951.709	51.5131
955.041	50.6601
958.372	48.9024
961.699	45.4097
965.027	46.2824
968.352	47.6323
971.676	50.522
975	51.2963
978.322	52.945
981.642	53.2238
984.962	53.7181
988.28	52.1049
991.596	49.533
994.911	49.0643
998.227	47.363
1001.54	46.6093
1004.85	46.4265
1008.16	44.8535
1011.47	44.6824
1014.78	43.3383
1018.08	40.7259
1021.39	39.2295
1024.69	38.2163
1028	36.0368
1031.3	34.3251
1034.6	32.1089
1037.9	28.5348
1041.19	26.4551
1044.49	27.6006
1047.78	28.8926
1051.08	28.5097
1054.37	28.6333
1057.66	27.6273
1060.95	25.7043
1064.24	24.878
1067.53	22.1771
1070.81	21.442
1074.1	22.315
1077.38	21.9769
1080.66	21.681
1083.94	22.4802
1087.22	23.6894
1090.5	22.9182
1093.78	22.2768
1097.05	22.1569
1100.33	22.1481
1103.6	22.0804
1106.87	21.9923
1110.14	21.3016
1113.41	20.5612
1116.68	18.2516
1119.95	16.3052
1123.21	15.5891
1126.48	14.6315
1129.74	14.7671
1133	15.1122
1136.26	14.2371
1139.52	12.8235
1142.78	13.406
1146.04	12.488
1149.29	12.2844
1152.55	11.5494
1155.8	10.3647
1159.05	9.8557
1162.3	8.77285
1165.55	8.84158
1168.8	9.37401
1172.05	9.83441
1175.29	9.75831
1178.54	9.8654
1181.78	11.5701
1185.02	12.2671
1188.26	12.963
1191.5	12.9988
1194.74	13.4333
1197.97	17.5371
1201.21	22.5051
1204.44	27.1518
1207.68	30.55
1210.91	35.7099
1214.14	39.0382
1217.37	44.1109
1220.59	48.6709
1223.82	51.4708
1227.05	53.8836
1230.27	55.6721
1233.49	58.1738
1236.72	60.7228
1239.94	62.7217
1243.16	64.0482
1246.37	65.9053
1249.59	65.4734
1252.8	65.6261
1256.02	65.2014
1259.23	64.536
1262.44	63.0246
1265.66	62.413
1268.86	62.5536
1272.07	63.2995
1275.28	66.3346
1278.48	68.372
1281.69	69.9723
1284.89	70.7036
1288.09	72.0955
1291.29	75.2832
1294.49	76.1013
1297.69	77.2985
1300.89	76.995
1304.08	77.9012
1307.28	78.4681
1310.47	80.6317
1313.66	80.478
1316.85	81.9422
1320.04	80.3169
1323.23	80.148
1326.42	78.8795
1329.61	77.2865
1332.79	74.7006
1335.97	72.275
1339.16	70.8386
1342.34	69.8482
1345.52	69.2008
1348.7	65.9772
1351.87	65.4794
1355.05	63.484
1358.22	60.741
1361.4	58.8068
1364.57	56.9831
1367.74	56.0256
1370.91	52.5053
1374.08	49.9672
1377.25	47.7106
1380.41	44.9828
1383.58	43.758
1386.74	43.756
1389.91	41.5133
1393.07	38.9034
1396.23	36.0868
1399.39	33.8286
1402.55	34.0882
1405.7	32.7993
1408.86	34.0083
1412.01	36.465
1415.17	40.3334
1418.32	45.6132
1421.47	50.3479
1424.62	55.3262
1427.77	62.0785
1430.91	69.7284
1434.06	74.6303
1437.2	79.8512
1440.35	84.8516
1443.49	87.6664
1446.63	89.6123
1449.77	90.3897
1452.91	90.778
1456.05	90.0227
1459.18	87.3236
1462.32	82.8582
1465.45	76.4187
1468.59	68.1477
1471.72	60.0631
1474.85	53.6769
1477.98	46.2215
1481.1	40.5694
1484.23	35.2666
1487.36	30.0833
1490.48	26.8072
1493.61	22.9863
1496.73	19.5671
1499.85	18.1428
1502.97	17.0621
1506.09	16.2177
1509.2	15.877
1512.32	15.8492
1515.43	16.6142
1518.55	18.3172
1521.66	19.7241
1524.77	21.9287
1527.88	24.3815
1530.99	24.6532
1534.1	26.0704
1537.21	24.9677
1540.31	25.5829
1543.42	27.4662
1546.52	29.5528
1549.62	31.8052
1552.72	34.8115
1555.82	36.7639
1558.92	39.1055
1562.02	41.1052
1565.11	42.5752
1568.21	44.1899
1571.3	46.3844
1574.39	48.7863
1577.49	51.7813
1580.57	53.8264
1583.66	56.5856
1586.75	59.8382
1589.84	62.1477
1592.92	64.9673
1596.01	65.7417
1599.09	65.7039
1602.17	66.4518
1605.25	65.5719
1608.33	63.3533
1611.41	62.1434
1614.49	61.0597
1617.57	62.5662
1620.64	63.8553
1623.72	64.8547
1626.79	65.348
1629.86	68.3399
1632.93	70.7347
1636	72.1792
1639.07	74.1119
1642.13	76.4489
1645.2	79.2392
1648.26	82.5167
1651.33	84.0845
1654.39	85.9559
1657.45	87.3383
1660.51	87.8241
1663.57	86.761
1666.63	85.6686
1669.68	82.6852
1672.74	79.0244
1675.79	75.2019
1678.85	69.737
1681.9	62.0285
1684.95	55.9307
1688	50.5189
1691.05	46.0689
1694.09	41.3383
1697.14	35.408
1700.18	29.0452
1703.23	25.6747
1706.27	21.296
1709.31	18.533
1712.35	14.5468
1715.39	11.6414
1718.43	8.96133
1721.47	6.72951
1724.5	5.45315
1727.54	4.1237
1730.57	3.59777
1733.61	3.35162
1736.64	3.23797
1739.67	3.37196
1742.7	3.63313
1745.72	2.44531
1748.75	2.84681
1751.77	2.43892
1754.8	2.04017
1757.82	1.80168
1760.84	2.21763
1763.87	2.25481
1766.89	1.38444
1769.91	0.154705
1772.92	-0.7701
1775.94	-0.107065
1778.95	0.131059
1781.97	-0.419342
1784.98	-1.16464
1787.99	-1.49675
1791.01	-0.352688
1794.01	0.0658284
1797.02	0.623266
1800.03	0.620142
1803.04	0.423973
1806.04	0.981462
1809.05	1.42103
1812.05	2.37271
1815.05	2.5482
1818.05	2.0529
1821.05	1.92213
1824.05	2.50253
1827.05	2.13901
1830.04	1.63004
1833.04	1.52368
1836.03	2.52098
1839.03	2.69414
1842.02	3.99287
1845.01	4.29191
1848	4.17467
1850.99	4.63776
1853.97	5.27219
1856.96	5.77121
1859.94	5.64378
1862.93	6.30401
1865.91	6.58761
1868.89	7.02511
1871.87	7.03561
1874.85	6.88045
1877.83	8.07731
1880.81	9.29801
1882.57	9.91679
1885.56	10.1537
1888.55	8.96202
1891.54	9.04839
1894.52	10.1189
1897.51	9.62961
1900.49	9.99421
1903.47	9.87856
1906.45	11.1302
1909.43	11.6051
1912.41	11.7097
1915.39	11.9717
1918.37	12.8039
1921.34	13.0979
1924.32	12.7381
1927.29	12.6042
1930.26	12.1875
1933.23	11.5151
1936.2	11.4754
1939.17	11.812
1942.14	11.6188
1945.11	12.1412
1948.07	12.732
1951.04	13.7048
1954	14.0516
1956.96	13.653
1959.93	13.1085
1962.89	13.1301
1965.85	14.0454
1968.8	14.6245
1971.76	14.7054
1974.72	16.7457
1977.67	16.3068
1980.63	17.0289
1983.58	16.3097
1986.53	17.1388
1989.48	17.5119
1992.43	16.8382
1995.38	15.3837
1998.32	14.5866
2001.27	15.205
2004.22	14.982
2007.16	14.9475
2010.1	14.7094
2013.04	14.1832
2015.98	14.3382
2018.92	14.4115
2021.86	15.3423
2024.8	14.7341
2027.74	15.569
2030.67	16.8713
2033.61	18.2862
2036.54	19.3403
2039.47	20.3572
2042.4	21.1089
2045.33	21.9252
2048.26	21.5621
2051.19	20.6919
2054.12	21.6285
2057.04	21.6651
2059.97	21.8841
2062.89	21.8924
2065.81	20.9638
2068.73	21.8856
2071.65	23.5082
2074.57	22.8002
2077.49	22.6166
2080.41	22.4126
2083.32	21.8855
2086.24	21.1687
2089.15	21.1558
2092.07	21.1954
2094.98	20.431
2097.89	21.9276
2100.8	23.2504
2103.71	24.0337
2106.61	22.7545
2109.52	22.4385
2112.43	22.5083
2115.33	23.0846
2118.23	22.9925
2121.13	24.1102
2124.04	25.4027
2126.94	26.559
2129.83	28.2563
2132.73	29.7357
2135.63	30.6943
2138.53	31.5313
2141.42	32.7325
2144.31	32.8138
2147.21	34.166
2150.1	35.1194
2152.99	34.9153
2155.88	35.0798
2158.77	35.5907
2161.65	36.2169
2164.54	37.2353
2167.43	37.4124
2170.31	38.343
2173.19	38.0155
2176.07	36.8082
2178.96	37.1302
2181.84	36.8258
2184.72	36.4431
2187.59	36.0947
2190.47	36.7962
2193.35	35.3014
2196.22	34.8912
2199.09	33.6653
2201.97	33.5313
2204.84	32.501
2207.71	32.0694
2210.58	30.9345
2213.45	30.6662
2216.31	30.5834
2219.18	29.8119
2222.05	28.3971
2224.91	28.0424
2227.78	27.7981
2230.64	27.8954
2233.5	26.3749
2236.36	26.5908
2239.22	26.5291
2242.08	25.6223
2244.93	24.4038
2247.79	23.7367
2250.64	23.6409
2253.5	22.8858
2256.35	22.4324
2259.2	22.1402
2262.05	20.4496
2264.9	20.1031
2267.75	20.4312
2270.6	20.0899
2273.45	18.591
2276.29	18.9683
2279.14	18.5873
2281.98	17.897
2284.82	17.1862
2287.66	16.5044
2290.5	15.471
2293.34	15.1544
2296.18	15.0146
2299.02	14.8331
2301.86	15.3669
2304.69	16.4344
2307.53	17.1329
2310.36	17.1103
2313.19	17.958
2316.02	18.5386
2318.85	18.6618
2321.68	18.4048
2324.51	18.3328
2327.34	18.4209
2330.16	18.0218
2332.99	18.4094
2335.81	18.5918
2338.64	17.4892
2341.46	15.7742
2344.28	15.771
2347.1	13.2985
2349.92	11.3067
2352.74	9.55036
2355.55	9.16198
2358.37	7.61216
2361.19	6.63939
2364	6.9735
2366.81	7.5692
2369.62	7.45598
2372.44	6.71821
2375.24	6.15769
2378.05	6.31764
2380.86	6.91383
2383.67	7.18419
2386.47	7.83712
2389.28	8.43434
2392.08	9.76957
2394.89	10.7687
2397.69	11.1356
2400.49	12.2442
2403.29	12.2971
2406.09	12.6441
2408.88	13.0732
2411.68	13.4128
2414.48	12.7719
2417.27	12.4212
2420.06	12.2379
2422.86	12.562
2425.65	13.0534
2428.44	12.1441
2431.23	11.5434
2434.02	10.1194
2436.81	8.34171
2439.59	6.96879
2442.38	6.13689
2445.16	4.64104
2447.95	3.99423
2450.73	3.53494
2453.51	3.317
2456.29	2.97357
2459.07	2.00396
2461.85	2.52073
2464.63	1.24661
2467.4	0.592997
2470.18	0.696111
2472.95	1.33946
2475.73	1.75985
2478.5	2.29093
2481.27	2.20232
2484.04	2.41966
2486.81	2.92134
2489.58	2.29118
2492.35	2.0113
2495.12	2.33966
2497.88	2.04868
2500.65	0.688103
2503.41	0.786737
2506.17	0.349441
2508.94	0.244865
2511.7	-0.198676
2514.46	-0.0569282
2517.22	0.0911926
2519.97	-0.422655
2522.73	-0.012667
2525.49	0.51811
2528.24	0.6286
2530.99	0.147144
2533.75	0.713709
2536.5	1.33685
2539.25	1.6638
2542	2.13833
2544.75	3.03442
2547.5	3.33356
2550.24	4.40139
2552.99	3.96741
2555.74	4.32319
2558.48	4.2766
2561.22	5.17222
2563.96	4.66022
2566.71	3.78743
2569.45	4.51558
2572.18	4.58093
2574.92	5.17586
2577.66	5.92029
2580.4	5.21236
2583.13	5.89164
2585.87	5.97555
2588.6	6.29255
2591.33	6.07805
2594.06	5.72336
2596.79	4.60342
2599.52	4.56492
2602.25	4.49447
2604.98	3.4791
2607.71	2.77362
2610.43	2.60252
2613.16	3.15303
2615.88	2.33618
2618.6	2.03677
2621.32	1.02851
2624.04	-0.0366412
2626.76	0.265934
2629.48	0.289262
2632.2	1.18472
2634.92	1.1472
2637.63	1.52714
2640.35	1.34057
2643.06	1.67606
2645.77	2.25729
2648.49	2.82486
2651.2	3.20298
2653.91	3.83812
2656.62	4.32396
2659.33	4.64663
2662.03	4.56899
2664.74	4.6696
2667.44	4.40028
2670.15	4.63512
2672.85	4.5856
2675.55	4.64277
2678.26	4.39418
2680.96	4.26722
2683.66	4.10725
2686.35	5.12809
2689.05	4.87906
2691.75	5.4361
2694.44	6.67528
2697.14	7.13028
2699.83	6.75018
2702.52	7.24882
2705.22	7.99931
2707.91	8.27432
2710.6	9.26584
2713.29	10.8626
2715.97	11.8866
2718.66	12.5823
2721.35	13.1635
2724.03	13.1787
2726.72	13.1164
2729.4	13.2206
2732.08	13.4377
2734.76	13.0426
2737.44	13.348
2740.12	12.7279
2742.8	11.2953
2745.48	10.4078
2748.16	10.1077
2750.83	9.795
2753.51	9.91127
2756.18	9.34716
2758.85	9.94559
2761.53	9.85791
2764.2	9.57809
2766.87	8.87488
2769.54	8.58024
2772.2	6.98645
2774.87	7.43314
2777.54	7.085
2780.2	6.78881
2782.87	4.74125
2785.53	3.9892
2788.19	3.50169
2790.85	2.05717
2793.51	2.55597
2796.17	2.75145
2798.83	2.42641
2801.49	1.88221
2804.15	1.26259
2806.8	0.470529
2809.46	-0.308394
2812.11	-1.23905
2814.76	-0.938582
2817.42	0.25516
2820.07	2.03156
2822.72	3.73196
2825.37	7.95758
2828.02	11.6313
2830.66	15.597
2833.31	19.5377
2835.96	25.0652
2838.6	30.948
2841.24	37.5728
2843.89	43.7566
2846.53	52.2882
2849.17	62.2173
2851.81	72.858
2854.45	83.0409
2857.09	94.1397
2859.72	104.912
2862.36	113.866
2865	123.177
2867.63	130.425
2870.26	136.865
2872.9	141.849
2875.53	147.206
2878.16	151.504
2880.79	156.557
2883.42	161.626
2886.05	166.74
2888.67	170.58
2891.3	175.115
2893.92	179.628
2896.55	183.647
2899.17	188.832
2901.79	195.687
2904.42	202.884
2907.04	213.041
2909.66	224.118
2912.27	237.084
2914.89	249.643
2917.51	260.244
2920.13	270.782
2922.74	280.108
2925.35	286.108
2927.97	290.366
2930.58	293.422
2933.19	292.247
2935.8	291.04
2938.41	287.206
2941.02	282.152
2943.63	275.281
2946.24	267.287
2948.84	258.98
2951.45	249.106
2954.05	238.278
2956.65	227.482
2959.26	218.008
2961.86	207.377
2964.46	197.446
2967.06	189.314
2969.66	180.809
2972.25	173.85
2974.85	166.598
2977.45	158.588
2980.04	150.859
2982.64	141.18
2985.23	133.573
2987.82	123.241
2990.41	113.479
2993	104.145
2995.59	94.0171
2998.18	85.0093
3000.77	77.1684
3003.36	68.3671
3005.94	61.197
3008.53	54.2721
3011.11	47.6655
3013.69	42.6771
3016.28	38.2091
3018.86	34.2752
3021.44	30.7479
3024.02	27.9895
3026.6	24.9628
3029.18	24.0081
3031.75	23.9163
3034.33	23.2692
3036.9	23.5597
3039.48	25.3849
3042.05	26.9745
3044.62	28.7883
3047.19	30.6522
3049.77	32.2753
3052.34	32.8693
3054.9	33.4582
3057.47	33.8947
3060.04	34.1937
3062.61	34.1271
3065.17	32.5985
3067.74	30.4153
3070.3	27.5221
3072.86	26.0211
3075.42	23.5294
3077.99	20.3893
3080.54	18.0724
3083.1	14.8036
3085.66	11.8007
3088.22	9.97692
3090.78	7.82597
3093.33	6.134
3095.89	5.05944
3098.44	3.88184
3100.99	4.19965
3103.54	3.95748
3106.1	4.28935
3108.65	3.93498
3111.2	3.49039
3113.74	3.29704
3116.29	3.17873
3118.84	3.4044
3121.38	3.38364
3123.93	2.6265
3126.47	2.08534
3129.01	0.818784
3131.56	-0.265597
3134.1	-0.135669
3136.64	-0.20542
3139.18	-1.01042
3141.72	-0.972859
3144.26	-1.28941
3146.79	-1.31182
3149.33	-1.59138