File: data/Raman/poly_smoothed/Thy_30_10_02_1x_45s_532 nm_x100_100%_600 gr_mm_01.txt
#Acq. time (s)=	45
#Accumulations=	2
#Range (cm-¹)=	200...3150
#Windows=	2
#Auto scanning=	Off
#Autofocus=	Off
#Macrospot=	Off
#AutoExposure=	Off
#Spike filter=	Multiple accum.
#Delay time (s)=	0
#Binning=	1
#Readout mode=	Signal
#DeNoise=	Off
#ICS correction=	On
#Dark correction=	Off
#Inst. Process=	Off
#Detector Gain=	Best Dynamic Range
#Detector ADC=	20 kHz
#Detector temperature (°C)=	-69.85
#Instrument=	LabRAM HR Evol
#Detector=	Synapse
#Objective=	x100
#Grating=	600 gr/mm
#ND Filter=	100%
#Laser (nm)=	532
#Hole=	100.021
#Range=	Auto
#Laser Pol.=	No
#Raman. Pol.=	No
#Laser Pol. (°)=	-0.0007625
#Raman Pol. (°)=	89.9995
#Collection=	Microscope
#StageXY=	Marzhauser
#StageZ=	Marzhauser
#X (µm)=	4769.5
#Y (µm)=	-7733.5
#Z (µm)=	584
#Full time(mm:ss)=	3:18
#Project=
#Sample=
#Site=
#Title=	Thy_30_10_02_2x_45s_532 nm_x100_100%_600 gr_mm
#Remark=
#Date=	30.06.2022 11:32
#Acquired=	30.06.2022 11:32:42
#Base:Fit=	10.08.2022 09:56:48
#Base:Fit=	10.08.2022 09:57:06
#Base:Fit=	10.08.2022 09:57:43
#Base:Fit=	10.08.2022 09:57:50
#Base:Fit=	10.08.2022 09:58:11
#Base:Sub=	10.08.2022 09:58:44
#Filter:Polynom=	16.08.2022 10:22:53
#AxisType[0]=Intens
#AxisUnit[0]=Cnt
#AxisType[1]=Spectr
#AxisUnit[1]=1/cm
200.533	1.7078
204.162	5.73335
207.792	7.05935
211.418	8.09636
215.044	8.55366
218.667	9.35612
222.289	9.6976
225.912	10.9379
229.531	13.5494
233.148	13.6277
236.766	13.7222
240.381	13.7508
243.994	13.2122
247.606	12.0356
251.217	11.1503
254.828	11.2561
258.436	11.0604
262.042	10.3844
265.647	8.98849
269.25	9.30157
272.852	7.3802
276.453	6.75913
280.052	6.13327
283.65	5.34137
287.247	6.08293
290.842	6.24712
294.436	5.88147
298.028	6.04039
301.617	7.75554
305.206	9.57267
308.794	11.9664
312.381	13.9774
315.964	16.625
319.548	19.0486
323.131	20.4858
326.71	21.7131
330.29	22.4566
333.868	22.0765
337.443	21.8572
341.018	21.0061
344.591	19.994
348.163	19.3207
351.733	16.9438
355.303	14.5215
358.869	10.8498
362.435	11.6969
366.001	9.28534
369.563	8.04043
373.124	8.22343
376.686	7.10888
380.244	5.70696
383.801	5.0112
387.357	5.96317
390.911	6.74516
394.466	5.55875
398.018	5.72453
401.568	7.85223
405.117	8.34462
408.664	10.246
412.21	10.109
415.755	8.68843
419.298	8.93939
422.84	7.51696
426.38	7.51552
429.919	5.81714
433.455	5.55779
436.992	2.74286
440.527	0.586016
444.06	1.49975
447.593	3.43967
451.122	4.76356
454.651	4.93726
458.18	5.78714
461.705	7.6319
465.23	8.61903
468.752	9.01034
472.275	9.51534
475.797	9.41426
479.315	10.4785
482.834	12.4601
486.349	15.7211
489.863	16.0569
493.378	16.896
496.889	16.9063
500.401	16.6693
503.91	17.0421
507.417	16.0404
510.923	16.4947
514.43	15.0438
517.933	15.0205
521.435	14.0092
524.936	12.437
528.435	13.2522
531.933	14.263
535.43	13.133
538.927	11.9063
542.421	11.4563
545.913	11.6606
549.403	10.9591
552.893	10.6031
556.381	9.6461
559.868	10.5216
563.354	10.544
566.839	12.2994
570.322	12.0371
573.802	9.26676
577.283	7.39497
580.762	6.96973
584.24	7.67406
587.714	8.76955
591.19	6.14807
594.663	6.44512
598.134	5.42381
601.605	7.09676
605.073	8.77854
608.542	7.9911
612.007	8.78019
615.473	8.27767
618.936	7.96938
622.397	9.04299
625.859	10.2953
629.318	11.9918
632.775	13.4158
636.233	16.3152
639.688	17.376
643.142	18.5538
646.594	18.5055
650.045	20.172
653.496	21.703
656.944	21.8873
660.391	21.4405
663.837	24.213
667.281	25.6753
670.724	27.3735
674.166	28.0145
677.606	28.9573
681.045	31.8722
684.483	33.7368
687.917	36.7568
691.352	36.9168
694.786	38.5893
698.219	39.5128
701.65	41.4358
705.078	42.5337
708.506	45.3559
711.934	47.1072
715.358	48.516
718.782	49.6987
722.204	52.0128
725.626	53.3578
729.045	53.2397
732.464	53.9359
735.881	54.368
739.297	55.1647
742.711	55.3245
746.125	56.0799
749.537	57.8965
752.946	60.4667
756.357	62.646
759.764	63.2898
763.17	65.199
766.575	68.2521
769.978	71.5039
773.382	74.6458
776.783	78.3385
780.182	80.7312
783.581	85.5743
786.978	89.4833
790.373	91.8746
793.768	94.0794
797.161	96.2904
800.552	100.345
803.941	101.053
807.33	103.571
810.718	101.843
814.105	101.388
817.49	101.708
820.873	101.16
824.256	100.533
827.637	99.2136
831.016	97.6276
834.395	96.4422
837.772	93.6374
841.147	90.2623
844.522	88.5027
847.894	89.0528
851.267	86.8432
854.637	83.5525
858.007	81.4557
861.374	78.8169
864.739	76.7137
868.106	74.2957
871.469	70.9611
874.831	69.2984
878.193	67.6351
881.553	66.709
884.911	64.5475
888.268	62.3378
891.623	60.1945
894.978	60.2119
898.331	59.2467
901.683	59.2406
905.033	57.479
908.383	56.3486
911.731	56.056
915.078	55.6235
918.423	56.3789
921.768	57.1568
925.111	57.1923
928.452	56.3875
931.791	55.4854
935.13	54.2164
938.468	53.9797
941.803	53.4181
945.139	52.6169
948.473	52.1715
951.804	53.7883
955.136	55.0405
958.465	56.1227
961.794	54.9738
965.12	56.0729
968.447	56.3619
971.771	57.8309
975.095	60.0952
978.417	60.5667
981.737	61.7646
985.057	63.3492
988.375	63.5256
991.691	63.8899
995.006	65.7542
998.32	66.0032
1001.63	66.5557
1004.95	66.4662
1008.26	64.8305
1011.56	65.6325
1014.87	65.4426
1018.18	63.5856
1021.48	63.0589
1024.79	61.9429
1028.09	62.7119
1031.39	61.7856
1034.69	59.6675
1037.99	58.4932
1041.29	55.3197
1044.58	53.9535
1047.88	52.2772
1051.17	50.649
1054.46	50.5738
1057.75	48.3798
1061.04	44.368
1064.33	44.6324
1067.62	45.4037
1070.9	43.5703
1074.19	42.2781
1077.47	42.0377
1080.76	41.7537
1084.04	41.8739
1087.32	42.0106
1090.59	42.4466
1093.87	42.8582
1097.15	42.7094
1100.42	42.9096
1103.69	43.5086
1106.97	43.7486
1110.24	44.584
1113.51	43.3617
1116.77	42.5621
1120.04	42.1807
1123.31	40.1845
1126.57	38.6603
1129.83	37.2647
1133.1	36.4247
1136.36	35.3367
1139.62	33.7025
1142.87	33.3579
1146.13	33.8527
1149.38	29.8456
1152.64	26.8655
1155.89	26.4107
1159.14	24.1895
1162.39	23.4135
1165.64	21.5934
1168.89	21.1506
1172.14	19.7827
1175.38	22.2694
1178.63	22.5129
1181.87	23.6589
1185.11	26.3462
1188.35	27.5689
1191.59	30.0859
1194.83	31.6717
1198.07	33.8626
1201.3	36.2293
1204.53	39.7003
1207.77	43.0694
1211	46.5116
1214.23	50.4861
1217.46	52.7829
1220.69	55.7103
1223.91	59.9827
1227.14	62.2215
1230.36	64.2187
1233.59	68.0884
1236.81	71.4402
1240.03	73.5653
1243.25	77.5676
1246.46	79.938
1249.68	81.9849
1252.9	86.4202
1256.11	88.2814
1259.32	90.5615
1262.54	91.8513
1265.75	93.2607
1268.96	93.1926
1272.16	93.3787
1275.37	92.9282
1278.57	92.8663
1281.78	92.5818
1284.98	92.6367
1288.18	92.3562
1291.38	92.7749
1294.58	92.878
1297.78	91.5648
1300.98	94.0004
1304.17	93.5472
1307.37	92.9982
1310.56	94.2086
1313.76	95.4338
1316.95	96.4789
1320.14	98.5813
1323.32	98.5657
1326.51	98.2629
1329.7	98.475
1332.88	97.1173
1336.07	95.6838
1339.25	94.0384
1342.43	91.9419
1345.61	88.5663
1348.79	85.9398
1351.96	82.707
1355.14	80.4985
1358.31	76.8839
1361.49	74.9738
1364.66	73.7865
1367.83	72.1408
1371	69.2029
1374.17	65.5314
1377.34	65.018
1380.5	63.6928
1383.67	63.2603
1386.83	61.685
1390	60.9171
1393.16	59.0944
1396.32	58.4096
1399.48	57.5434
1402.64	55.7187
1405.79	57.5932
1408.95	56.8774
1412.1	56.9218
1415.26	58.4058
1418.41	60.312
1421.56	60.9196
1424.71	61.7834
1427.86	67.3291
1431	72.025
1434.15	77.266
1437.29	81.5191
1440.44	85.3719
1443.58	88.5941
1446.72	89.6236
1449.86	91.0127
1453	89.4239
1456.14	88.7203
1459.27	85.9554
1462.41	80.3379
1465.54	74.9297
1468.67	69.9336
1471.81	64.2995
1474.94	59.4169
1478.07	53.9112
1481.19	49.1205
1484.32	43.3288
1487.45	37.2325
1490.57	31.8238
1493.69	28.6914
1496.82	25.3745
1499.94	23.428
1503.06	24.7626
1506.17	26.5705
1509.29	24.9849
1512.41	24.5523
1515.52	24.1419
1518.64	24.1609
1521.75	26.3193
1524.86	27.008
1527.97	27.5611
1531.08	29.2078
1534.19	30.7717
1537.29	32.4707
1540.4	36.1238
1543.5	41.6475
1546.61	45.634
1549.71	49.8624
1552.81	54.7257
1555.91	58.4281
1559.01	62.0571
1562.11	64.508
1565.2	66.7929
1568.29	72.1926
1571.39	75.8804
1574.48	77.7264
1577.57	80.5747
1580.66	83.8895
1583.75	84.4589
1586.84	85.8933
1589.93	86.2058
1593.01	86.3004
1596.1	84.8348
1599.18	83.9107
1602.26	81.8268
1605.34	79.6582
1608.42	78.9365
1611.5	75.9509
1614.58	75.5378
1617.65	75.7329
1620.73	74.922
1623.8	73.5486
1626.87	74.0113
1629.95	74.9802
1633.02	77.1721
1636.09	79.3311
1639.15	82.4653
1642.22	87.0012
1645.29	91.5639
1648.35	94.0839
1651.42	97.4596
1654.48	100.208
1657.54	102.04
1660.6	102.892
1663.66	100.792
1666.72	97.5489
1669.77	93.1309
1672.83	89.1374
1675.88	83.4299
1678.93	77.2121
1681.99	70.866
1685.04	63.9964
1688.09	56.1565
1691.13	50.0308
1694.18	44.3852
1697.23	38.4811
1700.27	33.4823
1703.32	31.2063
1706.36	28.8545
1709.4	25.0031
1712.44	21.2991
1715.48	19.5296
1718.52	18.1043
1721.56	16.5069
1724.59	14.8714
1727.63	13.169
1730.66	12.1007
1733.69	10.083
1736.72	8.84701
1739.75	7.60763
1742.78	7.27292
1745.81	5.50477
1748.84	4.78464
1751.86	3.65473
1754.89	3.2768
1757.91	2.27145
1760.93	3.00312
1763.95	2.22722
1766.97	3.03535
1769.99	2.84217
1773.01	3.83053
1776.03	4.87855
1779.04	4.044
1782.06	3.0627
1785.07	2.36395
1788.08	2.81951
1791.09	3.02368
1794.1	3.07374
1797.11	2.45882
1800.12	1.6322
1803.12	0.990456
1806.13	0.395443
1809.13	0.746369
1812.14	1.38502
1815.14	0.565877
1818.14	0.317208
1821.14	0.774862
1824.14	1.14241
1827.13	1.32897
1830.13	0.735308
1833.12	0.610436
1836.12	0.878055
1839.11	0.510315
1842.1	0.64868
1845.09	1.75952
1848.08	2.28735
1851.07	1.99546
1854.06	2.40147
1857.04	2.81948
1860.03	3.39068
1863.01	3.64929
1866	3.26669
1868.98	3.49015
1871.96	3.34243
1874.94	3.18157
1877.92	3.24734
1880.89	2.62641
1882.48	2.0389
1885.47	2.29694
1888.46	1.51957
1891.44	1.06953
1894.43	0.540797
1897.41	0.591557
1900.4	-0.693738
1903.38	-0.638075
1906.36	0.185622
1909.34	0.37178
1912.32	0.487713
1915.29	1.7123
1918.27	1.94979
1921.25	2.05447
1924.22	1.94888
1927.2	2.33991
1930.17	2.89981
1933.14	3.02218
1936.11	2.80918
1939.08	3.67018
1942.05	4.01916
1945.01	4.52767
1947.98	4.38129
1950.94	4.25218
1953.91	3.93591
1956.87	4.29493
1959.83	4.4919
1962.79	3.87652
1965.75	4.5315
1968.71	5.15312
1971.67	4.74913
1974.62	4.97376
1977.58	4.29642
1980.53	4.54062
1983.48	5.2376
1986.43	4.48001
1989.38	4.49654
1992.33	3.3573
1995.28	2.99643
1998.23	1.85729
2001.18	1.85158
2004.12	1.37659
2007.06	1.52823
2010.01	0.960201
2012.95	2.38496
2015.89	3.00574
2018.83	3.51884
2021.77	3.80723
2024.71	4.21422
2027.64	3.7368
2030.58	5.02773
2033.51	5.39455
2036.45	6.53735
2039.38	6.9489
2042.31	7.41736
2045.24	9.38026
2048.17	9.47483
2051.1	10.5204
2054.02	11.7313
2056.95	12.7283
2059.87	13.4603
2062.8	13.7207
2065.72	14.0421
2068.64	13.8191
2071.56	13.884
2074.48	15.0989
2077.4	16.4085
2080.31	16.898
2083.23	18.0888
2086.14	18.7192
2089.06	19.6351
2091.97	19.5364
2094.88	19.5613
2097.79	20.6071
2100.7	22.0579
2103.61	22.9975
2106.52	25.011
2109.43	25.8339
2112.33	28.1786
2115.24	30.222
2118.14	32.8972
2121.04	34.5672
2123.94	38.1448
2126.84	40.1515
2129.74	43.6208
2132.64	46.2363
2135.54	47.5671
2138.43	51.8675
2141.33	55.7729
2144.22	60.398
2147.11	64.0201
2150.01	68.0291
2152.9	71.4386
2155.79	74.4762
2158.67	78.7431
2161.56	81.2171
2164.45	83.2473
2167.33	84.7314
2170.22	87.2709
2173.1	88.1103
2175.98	88.9287
2178.86	88.3471
2181.74	87.3602
2184.62	85.3925
2187.5	84.0202
2190.38	81.5465
2193.25	77.3557
2196.13	73.3499
2199	70.1037
2201.88	66.3291
2204.75	62.609
2207.62	59.2911
2210.49	56.2404
2213.36	51.9561
2216.22	48.9864
2219.09	45.359
2221.96	42.925
2224.82	39.7331
2227.68	37.6009
2230.55	34.911
2233.41	31.1118
2236.27	28.9291
2239.12	26.9245
2241.98	26.0951
2244.84	25.3737
2247.7	24.6372
2250.55	23.922
2253.41	22.959
2256.26	22.974
2259.11	22.3782
2261.96	21.476
2264.81	20.3183
2267.66	21.2572
2270.51	21.0112
2273.35	20.5318
2276.2	19.3549
2279.04	19.2221
2281.89	18.796
2284.73	18.7677
2287.57	18.0349
2290.41	16.0318
2293.25	14.7243
2296.09	13.2352
2298.93	12.7994
2301.76	10.6743
2304.6	9.52208
2307.44	8.39257
2310.27	8.56109
2313.1	8.48324
2315.93	7.59508
2318.76	6.83527
2321.59	5.9302
2324.42	6.17602
2327.25	4.97466
2330.07	3.80462
2332.9	2.77559
2335.72	2.34245
2338.55	2.13454
2341.37	1.38187
2344.19	0.350989
2347.01	1.30119
2349.83	1.16152
2352.65	0.924295
2355.46	0.677541
2358.28	0.53113
2361.09	0.285126
2363.91	1.35215
2366.72	3.39758
2369.53	3.74125
2372.34	3.19352
2375.15	3.61872
2377.96	4.34082
2380.77	4.10911
2383.58	3.82615
2386.38	4.5768
2389.19	5.0537
2391.99	4.65469
2394.8	3.90649
2397.6	3.16917
2400.4	3.03714
2403.2	3.42549
2406	3.49427
2408.79	4.03701
2411.59	3.19153
2414.39	3.41251
2417.18	3.91008
2419.98	5.49467
2422.77	5.74917
2425.56	6.53052
2428.35	6.73663
2431.14	8.12403
2433.93	9.38074
2436.72	9.50876
2439.5	10.6488
2442.29	10.2262
2445.07	9.50013
2447.86	8.68157
2450.64	8.87293
2453.42	8.62894
2456.2	8.1154
2458.98	8.37452
2461.76	7.38406
2464.54	7.61132
2467.32	8.22115
2470.09	8.34188
2472.87	8.18985
2475.64	8.33668
2478.41	8.36869
2481.18	7.62431
2483.95	8.37302
2486.72	9.26181
2489.49	8.62077
2492.26	7.68768
2495.03	7.33385
2497.79	6.13438
2500.56	7.38498
2503.32	6.50052
2506.09	6.48368
2508.85	5.56988
2511.61	3.94212
2514.37	3.74625
2517.13	2.85811
2519.89	2.98958
2522.64	2.56685
2525.4	2.6366
2528.15	3.7006
2530.91	3.2689
2533.66	3.23088
2536.41	2.81689
2539.16	2.93548
2541.91	3.14923
2544.66	3.60701
2547.41	3.63669
2550.16	3.66218
2552.9	4.16861
2555.65	4.2593
2558.39	3.0043
2561.13	3.30787
2563.88	3.02938
2566.62	3.19301
2569.36	2.94491
2572.1	3.36111
2574.84	3.16751
2577.57	1.85353
2580.31	0.939898
2583.05	1.03472
2585.78	1.19727
2588.51	0.912988
2591.24	0.473105
2593.98	0.965143
2596.71	1.62047
2599.44	0.977961
2602.16	0.733156
2604.89	0.6662
2607.62	1.06895
2610.34	2.08405
2613.07	2.99772
2615.79	3.18353
2618.52	3.55427
2621.24	3.61963
2623.96	4.78369
2626.68	5.76803
2629.4	4.83569
2632.11	4.29156
2634.83	4.19911
2637.55	3.88336
2640.26	4.36684
2642.98	3.40179
2645.69	2.89321
2648.4	2.47644
2651.11	2.89879
2653.82	2.64021
2656.53	2.85443
2659.24	3.33849
2661.95	3.53966
2664.65	4.26744
2667.36	5.25598
2670.06	5.92025
2672.76	6.36216
2675.47	7.04347
2678.17	7.27473
2680.87	6.79106
2683.57	5.9796
2686.27	6.32851
2688.97	7.20125
2691.66	6.97161
2694.36	5.66188
2697.05	4.97564
2699.75	5.26558
2702.44	6.26503
2705.13	6.52395
2707.82	7.55648
2710.51	8.35768
2713.2	9.82134
2715.89	11.1731
2718.57	12.2974
2721.26	14.8799
2723.95	15.7977
2726.63	16.4916
2729.31	16.7806
2732	17.8062
2734.68	17.8983
2737.36	17.5199
2740.04	17.3151
2742.72	17.0471
2745.39	16.1672
2748.07	15.3824
2750.75	15.5451
2753.42	15.0195
2756.09	14.4231
2758.77	13.0341
2761.44	12.4656
2764.11	11.8031
2766.78	11.559
2769.45	12.2321
2772.12	12.8314
2774.78	13.6516
2777.45	13.5496
2780.12	13.0282
2782.78	13.4439
2785.44	13.4585
2788.11	12.194
2790.77	11.1807
2793.43	10.8547
2796.09	10.0627
2798.75	10.3205
2801.4	9.97789
2804.06	9.94472
2806.72	10.5677
2809.37	10.8739
2812.03	11.5713
2814.68	10.8827
2817.33	11.5104
2819.98	13.1842
2822.63	14.7805
2825.28	16.1827
2827.93	20.306
2830.58	23.2217
2833.23	27.3751
2835.87	31.949
2838.52	37.4928
2841.16	42.791
2843.8	48.8377
2846.44	56.6611
2849.08	65.0727
2851.73	73.5435
2854.36	84.0916
2857	94.7483
2859.64	104.497
2862.28	113.853
2864.91	123.429
2867.55	130.593
2870.18	137.979
2872.81	145.499
2875.44	150.885
2878.07	154.944
2880.7	159.455
2883.33	164.233
2885.96	168.708
2888.59	173.312
2891.21	179.128
2893.84	184.497
2896.46	189.515
2899.09	196.851
2901.71	205.377
2904.33	215.737
2906.95	227.027
2909.57	240.677
2912.19	255.69
2914.81	270.865
2917.43	287.087
2920.04	302.618
2922.66	314.668
2925.27	323.827
2927.88	332.111
2930.5	337.904
2933.11	339.923
2935.72	339.749
2938.33	336.376
2940.94	331.017
2943.54	325.287
2946.15	317.612
2948.76	307.629
2951.36	297.012
2953.97	285.441
2956.57	272.024
2959.17	258.855
2961.77	246.65
2964.37	234.831
2966.97	223.152
2969.57	212.916
2972.17	202.486
2974.77	191.726
2977.36	181.46
2979.96	170.458
2982.55	159.536
2985.15	148.589
2987.74	137.202
2990.33	126.211
2992.92	115.376
2995.51	104.819
2998.1	93.9208
3000.69	85.11
3003.27	77.5345
3005.86	71.9549
3008.44	64.7345
3011.03	59.5487
3013.61	53.8767
3016.19	49.6229
3018.78	47.1959
3021.36	43.8779
3023.94	43.1403
3026.51	41.5975
3029.09	40.2246
3031.67	39.765
3034.24	38.6388
3036.82	37.8732
3039.39	37.627
3041.97	38.5589
3044.54	40.0239
3047.11	40.8711
3049.68	41.8012
3052.25	41.296
3054.82	41.0771
3057.39	39.7985
3059.96	39.036
3062.52	38.5872
3065.09	37.4121
3067.65	35.9701
3070.22	33.4743
3072.78	30.9835
3075.34	28.6009
3077.9	25.7633
3080.46	22.6391
3083.02	19.8744
3085.58	16.9229
3088.14	15.0071
3090.69	12.565
3093.25	10.2661
3095.8	8.37752
3098.36	8.20775
3100.91	7.48954
3103.46	7.94371
3106.01	7.5185
3108.56	6.85264
3111.11	6.81579
3113.66	6.06026
3116.21	5.73203
3118.76	5.16158
3121.3	4.71809
3123.85	4.72263
3126.39	4.64769
3128.93	4.17191
3131.48	3.32935
3134.02	2.60113
3136.56	2.3086
3139.1	0.66134
3141.64	0.0326328
3144.17	-0.166916
3146.71	-1.02847
3149.25	-0.866824