File: data/Raman/poly_smoothed/Thy_20_09_31_1x_45s_532 nm_x100_100%_600 gr_mm_01.txt
#Acq. time (s)=	45
#Accumulations=	2
#Range (cm-¹)=	200...3150
#Windows=	2
#Auto scanning=	Off
#Autofocus=	Off
#Macrospot=	Off
#AutoExposure=	Off
#Spike filter=	Multiple accum.
#Delay time (s)=	0
#Binning=	1
#Readout mode=	Signal
#DeNoise=	Off
#ICS correction=	On
#Dark correction=	Off
#Inst. Process=	Off
#Detector Gain=	Best Dynamic Range
#Detector ADC=	20 kHz
#Detector temperature (°C)=	-69.85
#Instrument=	LabRAM HR Evol
#Detector=	Synapse
#Objective=	x100
#Grating=	600 gr/mm
#ND Filter=	100%
#Laser (nm)=	532
#Hole=	100.021
#Range=	Auto
#Laser Pol.=	No
#Raman. Pol.=	No
#Laser Pol. (°)=	-0.0007625
#Raman Pol. (°)=	89.9995
#Collection=	Microscope
#StageXY=	Marzhauser
#StageZ=	Marzhauser
#X (µm)=	-5922.1
#Y (µm)=	2879.5
#Z (µm)=	-223.5
#Full time(mm:ss)=	3:19
#Project=
#Sample=
#Site=
#Title=	Thy_20_09_31_2x_45s_532 nm_x100_100%_600 gr_mm
#Remark=
#Date=	29.06.2022 12:48
#Acquired=	29.06.2022 12:48:53
#Base:Fit=	10.08.2022 09:52:02
#Base:Fit=	10.08.2022 09:52:12
#Base:Sub=	10.08.2022 09:54:21
#Filter:Polynom=	16.08.2022 10:24:04
#AxisType[0]=Intens
#AxisUnit[0]=Cnt
#AxisType[1]=Spectr
#AxisUnit[1]=1/cm
200.523	5.79558
204.154	6.26141
207.781	7.52674
211.409	8.11595
215.034	7.82374
218.659	7.8842
222.281	7.67444
225.903	7.39186
229.522	6.73473
233.14	6.97348
236.756	7.10274
240.373	6.82623
243.986	5.67435
247.598	5.62004
251.208	4.20564
254.818	4.35279
258.427	5.21007
262.034	4.94147
265.638	4.67555
269.242	3.8442
272.844	2.62533
276.445	1.93372
280.044	1.70005
283.642	-0.658526
287.238	1.23801
290.833	1.78498
294.425	2.58939
298.017	3.71013
301.608	5.0511
305.198	6.96224
308.786	8.15485
312.371	10.0406
315.956	12.9937
319.54	12.8598
323.122	14.3907
326.701	16.3344
330.281	16.0973
333.857	17.3975
337.434	18.3432
341.008	19.8851
344.582	19.8715
348.153	18.3643
351.724	17.2169
355.292	15.1594
358.861	12.322
362.426	12.2877
365.99	10.4077
369.555	8.21893
373.116	9.47082
376.676	8.81036
380.236	8.02497
383.793	9.52396
387.349	9.72828
390.903	9.98695
394.456	10.0085
398.007	9.75036
401.56	9.86516
405.108	8.4894
408.656	7.32148
412.202	9.36784
415.746	11.1444
419.29	11.5486
422.831	12.181
426.37	12.3887
429.909	12.8061
433.447	10.7779
436.983	9.67192
440.519	7.882
444.052	8.39135
447.583	8.64093
451.114	8.92545
454.643	8.7279
458.169	8.91102
461.696	8.51315
465.222	9.37184
468.744	11.1598
472.267	11.2934
475.787	9.92908
479.307	9.2339
482.823	10.8325
486.341	10.8079
489.855	8.74977
493.37	10.7925
496.881	13.9312
500.391	15.4142
503.902	16.0662
507.409	15.5079
510.915	16.1778
514.42	15.8496
517.925	14.3965
521.427	13.9208
524.928	15.1611
528.427	15.0587
531.925	16.5025
535.422	15.7939
538.917	14.542
542.411	13.3339
545.903	11.6092
549.395	12.3078
552.884	11.0449
556.373	9.77149
559.86	8.69639
563.346	8.1522
566.831	6.79256
570.314	6.14409
573.794	5.4297
577.274	4.85578
580.754	6.55751
584.23	5.77055
587.706	5.35039
591.181	4.83166
594.653	3.11979
598.126	1.50692
601.595	2.30875
605.065	3.11168
608.532	2.44604
611.999	1.96838
615.463	2.67731
618.928	3.17929
622.389	2.65742
625.851	2.6515
629.31	3.19727
632.767	3.66268
636.223	5.47568
639.68	5.22609
643.134	5.38463
646.586	6.57174
650.037	6.27543
653.486	9.27638
656.936	10.5851
660.383	12.6624
663.829	13.4329
667.273	15.9764
670.716	16.4317
674.158	18.28
677.598	19.9835
681.035	22.4363
684.473	24.2935
687.909	26.0111
691.344	26.4412
694.778	27.6989
698.211	30.0205
701.64	31.6908
705.07	31.9722
708.498	33.945
711.924	34.6489
715.35	36.3165
718.774	37.8083
722.196	37.2169
725.618	37.5457
729.037	37.5517
732.456	39.2178
735.873	40.3392
739.289	42.0964
742.703	42.2844
746.116	42.9413
749.529	45.6649
752.938	47.301
756.347	48.697
759.756	50.8948
763.162	53.4112
766.567	55.5365
769.97	56.4438
773.372	58.9318
776.773	59.8348
780.174	62.017
783.573	63.3447
786.97	65.5476
790.365	68.1152
793.76	70.8311
797.153	73.8463
800.543	76.8467
803.933	76.042
807.322	75.7676
810.71	76.983
814.097	76.066
817.483	75.9346
820.865	75.1041
824.248	74.0111
827.629	72.0894
831.008	70.2306
834.387	67.7294
837.765	65.1018
841.139	63.285
844.514	61.8255
847.886	58.0309
851.259	55.4547
854.629	51.9593
857.997	49.0909
861.366	46.361
864.732	45.6986
868.098	45.4023
871.461	43.9663
874.823	42.7707
878.184	43.3341
881.545	42.1641
884.903	41.4313
888.26	39.6469
891.616	39.9264
894.97	40.1703
898.323	41.1983
901.675	42.9268
905.026	42.4663
908.375	42.1975
911.723	42.7597
915.07	40.7177
918.415	41.3511
921.76	41.057
925.103	40.0003
928.443	39.043
931.783	36.8127
935.123	34.117
938.461	32.0089
941.796	30.8902
945.131	28.8856
948.465	26.5868
951.797	26.2769
955.128	24.6498
958.457	22.961
961.786	21.6065
965.113	23.099
968.44	24.5058
971.763	25.6449
975.086	27.4471
978.409	29.8035
981.729	29.202
985.048	30.0619
988.367	29.1947
991.683	29.061
994.998	28.9755
998.312	28.741
1001.62	28.5807
1004.94	27.3471
1008.25	26.646
1011.56	23.5941
1014.86	21.7332
1018.17	20.3431
1021.48	18.2732
1024.78	15.8915
1028.08	16.0155
1031.38	15.6549
1034.68	15.6073
1037.98	13.1358
1041.28	11.8094
1044.57	12.6601
1047.87	12.7909
1051.16	12.629
1054.45	11.7622
1057.75	10.7544
1061.04	10.0048
1064.32	10.1493
1067.61	9.79908
1070.9	10.0762
1074.18	10.6967
1077.47	9.85947
1080.75	9.394
1084.03	9.69113
1087.31	9.51855
1090.59	9.71506
1093.86	10.0492
1097.14	9.97925
1100.41	9.4491
1103.69	9.07313
1106.96	9.94453
1110.23	11.3736
1113.5	11.2955
1116.77	10.8203
1120.03	8.68963
1123.3	7.15537
1126.56	7.63783
1129.83	8.06509
1133.09	8.08559
1136.35	6.84926
1139.61	7.46089
1142.86	8.36015
1146.12	8.79333
1149.38	8.84827
1152.63	7.66932
1155.88	6.07334
1159.14	5.65644
1162.39	6.00254
1165.63	5.22515
1168.88	5.13075
1172.13	5.03491
1175.38	4.43176
1178.62	3.78594
1181.86	4.04786
1185.1	4.27579
1188.34	5.88434
1191.58	7.50311
1194.82	7.1371
1198.06	7.50823
1201.29	10.0429
1204.53	11.8908
1207.76	15.7324
1210.99	18.057
1214.22	20.8996
1217.45	24.8732
1220.68	28.4441
1223.91	33.1549
1227.13	34.7329
1230.36	36.9652
1233.58	39.2439
1236.8	39.5791
1240.02	40.975
1243.24	41.3422
1246.46	42.0104
1249.67	43.2087
1252.89	43.4767
1256.1	43.5726
1259.32	43.4882
1262.53	44.2272
1265.74	45.1509
1268.95	45.9783
1272.15	46.5178
1275.36	47.3332
1278.57	48.9743
1281.77	50.6159
1284.97	52.1216
1288.18	53.4229
1291.38	54.6477
1294.58	57.3865
1297.78	59.394
1300.97	59.9209
1304.17	60.9102
1307.36	63.6114
1310.55	65.4409
1313.75	66.6725
1316.94	67.5055
1320.13	69.455
1323.32	70.9618
1326.5	71.5257
1329.69	71.2421
1332.87	71.0471
1336.06	69.9078
1339.24	68.3593
1342.42	66.2451
1345.6	64.3872
1348.78	61.7034
1351.96	60.587
1355.13	58.2506
1358.31	55.9383
1361.48	52.6078
1364.65	48.3635
1367.82	45.303
1370.99	42.5467
1374.16	39.4783
1377.33	38.1693
1380.5	37.5633
1383.66	37.3533
1386.83	38.9638
1389.99	39.1873
1393.15	38.4239
1396.31	38.5651
1399.47	39.3977
1402.63	37.9076
1405.78	37.6412
1408.94	39.3453
1412.1	40.9675
1415.25	43.892
1418.4	46.5088
1421.55	50.7928
1424.7	56.0771
1427.85	61.7065
1431	66.669
1434.14	70.2924
1437.29	74.7397
1440.43	76.8066
1443.57	78.356
1446.71	80.2709
1449.85	80.3695
1452.99	79.3408
1456.13	78.3036
1459.26	75.3776
1462.4	71.936
1465.54	67.0218
1468.67	60.1229
1471.8	54.3655
1474.93	47.9042
1478.06	41.4147
1481.19	35.4583
1484.31	30.9745
1487.44	27.7076
1490.56	23.5923
1493.69	20.5917
1496.81	19.4136
1499.93	18.0075
1503.05	18.1528
1506.17	17.6178
1509.28	16.5632
1512.4	17.7864
1515.52	17.8424
1518.63	17.9584
1521.74	19.6244
1524.85	21.8525
1527.96	23.219
1531.07	24.3893
1534.18	25.4824
1537.29	29.3546
1540.39	30.426
1543.5	33.1906
1546.6	37.1555
1549.7	41.1024
1552.8	42.1596
1555.9	45.2423
1559	48.0699
1562.1	50.0006
1565.19	53.466
1568.29	54.436
1571.38	56.9042
1574.47	59.7521
1577.56	62.395
1580.66	63.144
1583.74	65.1359
1586.83	67.1056
1589.92	69.5003
1593.01	70.441
1596.09	72.0244
1599.17	72.0315
1602.25	72.4326
1605.34	69.9691
1608.41	68.1377
1611.49	66.9992
1614.57	66.1607
1617.65	64.7396
1620.72	64.872
1623.79	64.8758
1626.87	63.9032
1629.94	64.5365
1633.01	64.8351
1636.08	64.8631
1639.15	66.4219
1642.21	66.5671
1645.28	67.6242
1648.34	70.0564
1651.41	72.1468
1654.47	72.3245
1657.53	73.496
1660.59	73.5535
1663.65	72.2707
1666.71	71.38
1669.76	68.5644
1672.82	66.3923
1675.87	61.888
1678.93	55.8401
1681.98	50.579
1685.03	45.0723
1688.08	39.817
1691.13	34.9827
1694.17	29.8419
1697.22	25.3344
1700.27	21.6146
1703.31	18.3133
1706.35	16.1193
1709.39	12.2059
1712.43	9.12506
1715.47	8.75444
1718.51	7.59451
1721.55	7.68589
1724.58	7.31512
1727.62	7.51263
1730.65	7.30283
1733.68	8.80558
1736.72	8.12309
1739.74	8.06506
1742.77	8.46309
1745.8	8.78121
1748.83	8.39479
1751.85	9.20185
1754.88	7.87261
1757.9	6.48501
1760.92	5.40897
1763.95	4.35292
1766.96	3.68448
1769.98	2.49374
1773	1.88791
1776.02	1.9808
1779.03	2.64423
1782.05	2.50739
1785.06	2.01876
1788.07	2.86664
1791.08	3.93521
1794.09	3.97895
1797.1	5.0734
1800.11	5.23322
1803.12	5.31553
1806.12	5.04036
1809.12	4.7366
1812.13	3.90635
1815.13	4.6463
1818.13	4.31154
1821.13	3.67731
1824.13	3.69582
1827.13	3.20394
1830.12	2.25021
1833.12	1.63163
1836.11	2.15791
1839.1	1.66403
1842.09	2.0828
1845.09	2.22584
1848.08	3.02386
1851.06	2.90887
1854.05	3.4159
1857.04	3.97833
1860.02	3.74956
1863.01	4.07466
1865.99	3.30178
1868.97	3.12696
1871.95	2.93212
1874.93	1.51802
1877.91	1.29547
1880.89	0.568143
1882.46	1.42322
1885.45	1.98627
1888.43	1.465
1891.42	2.19057
1894.41	2.61675
1897.39	3.88021
1900.37	3.93461
1903.36	4.73111
1906.34	5.82116
1909.32	6.20813
1912.29	6.24057
1915.27	7.1453
1918.25	8.06242
1921.23	8.31463
1924.2	8.90699
1927.17	8.77046
1930.15	8.0932
1933.12	7.11045
1936.09	5.88481
1939.06	4.39493
1942.02	4.42699
1944.99	2.15172
1947.96	2.60233
1950.92	3.18862
1953.88	3.18485
1956.85	2.60814
1959.81	2.45292
1962.77	2.30322
1965.73	2.6926
1968.69	2.17847
1971.64	1.02184
1974.6	0.819556
1977.55	0.402741
1980.51	1.01915
1983.46	1.15055
1986.41	1.89279
1989.36	0.938684
1992.31	1.4768
1995.26	1.79649
1998.21	2.51885
2001.15	3.44345
2004.1	3.90093
2007.04	4.67685
2009.99	5.11695
2012.93	5.07042
2015.87	5.4318
2018.81	6.5053
2021.75	6.92333
2024.68	7.1463
2027.62	7.23401
2030.56	8.38305
2033.49	10.1529
2036.42	11.0167
2039.36	12.2973
2042.29	12.3153
2045.22	12.5212
2048.14	12.8811
2051.07	13.3142
2054	12.819
2056.93	11.4489
2059.85	11.5386
2062.77	11.9887
2065.7	12.7239
2068.62	13.7864
2071.54	13.9668
2074.46	15.6375
2077.38	15.3698
2080.29	14.1344
2083.21	14.0503
2086.12	13.8901
2089.04	13.7274
2091.95	13.5318
2094.86	14.1087
2097.77	14.9987
2100.68	15.3675
2103.59	17.6492
2106.5	18.1063
2109.41	18.7998
2112.31	18.6172
2115.21	16.8458
2118.12	17.1302
2121.02	17.3931
2123.92	17.3619
2126.82	18.2119
2129.72	19.4673
2132.62	21.3382
2135.51	22.4787
2138.41	24.1028
2141.31	25.0597
2144.2	26.8953
2147.09	28.0887
2149.98	29.5239
2152.87	30.9224
2155.76	31.5041
2158.65	32.3043
2161.54	32.6895
2164.43	33.8332
2167.31	35.6893
2170.2	36.7752
2173.08	37.7772
2175.96	38.1316
2178.84	37.5824
2181.72	36.1378
2184.6	34.9332
2187.48	35.1375
2190.36	34.4556
2193.23	34.4875
2196.11	34.3296
2198.98	33.349
2201.85	31.8025
2204.72	30.9977
2207.59	29.7435
2210.46	27.6171
2213.33	25.6057
2216.2	23.3159
2219.07	22.6648
2221.93	19.9263
2224.8	18.5491
2227.66	16.386
2230.52	15.9806
2233.39	15.6413
2236.25	15.3992
2239.1	13.9605
2241.96	13.5006
2244.82	13.0082
2247.68	12.3158
2250.53	12.3547
2253.38	12.4123
2256.24	12.3845
2259.09	12.6874
2261.94	11.9774
2264.79	12.4205
2267.64	12.2132
2270.49	12.0875
2273.33	12.1452
2276.18	11.1841
2279.02	10.9817
2281.87	10.7831
2284.71	9.64431
2287.55	10.4591
2290.39	10.0881
2293.23	9.77724
2296.07	10.0816
2298.91	11.3044
2301.74	12.365
2304.58	12.3511
2307.41	12.6269
2310.25	13.0683
2313.08	12.7016
2315.91	13.2768
2318.74	13.6927
2321.57	13.7143
2324.4	12.527
2327.23	10.3387
2330.05	9.23195
2332.88	7.80663
2335.7	7.03171
2338.52	5.81448
2341.35	5.5395
2344.17	5.85594
2346.99	4.65819
2349.81	5.09748
2352.62	4.93928
2355.44	5.55051
2358.26	6.07862
2361.07	5.85651
2363.89	7.47173
2366.7	8.92095
2369.51	9.26728
2372.32	9.05453
2375.13	9.50627
2377.94	8.52306
2380.75	8.45448
2383.56	9.00469
2386.36	10.151
2389.17	9.29062
2391.97	8.51285
2394.77	7.93022
2397.58	6.82718
2400.38	6.02683
2403.18	4.74985
2405.97	4.0104
2408.77	4.39404
2411.57	3.99726
2414.37	3.51709
2417.16	3.43035
2419.95	3.96561
2422.75	5.08594
2425.54	5.61902
2428.33	5.40259
2431.12	5.6985
2433.91	6.41477
2436.7	6.29717
2439.48	5.98051
2442.27	6.70274
2445.05	6.68237
2447.84	7.96285
2450.62	9.88357
2453.4	11.2178
2456.18	11.0097
2458.96	9.95082
2461.74	9.59636
2464.52	9.28292
2467.29	8.19493
2470.07	7.77059
2472.85	6.75277
2475.62	6.34117
2478.39	5.32407
2481.16	4.71001
2483.93	4.52668
2486.7	3.98565
2489.47	5.39098
2492.24	4.61964
2495.01	5.33289
2497.77	4.90745
2500.54	5.82187
2503.3	5.769
2506.06	6.54678
2508.83	7.315
2511.59	7.68618
2514.35	8.52156
2517.11	8.43131
2519.86	7.41551
2522.62	6.70242
2525.38	6.35281
2528.13	6.32304
2530.89	7.15079
2533.64	7.55891
2536.39	6.93766
2539.14	6.10833
2541.89	5.55182
2544.64	4.73833
2547.39	5.04619
2550.14	5.10475
2552.88	4.55183
2555.63	4.44191
2558.37	5.25941
2561.11	4.84589
2563.86	5.48543
2566.6	5.18746
2569.34	5.67865
2572.08	5.57616
2574.82	6.0058
2577.55	5.91144
2580.29	6.46733
2583.02	6.18443
2585.76	6.00795
2588.49	6.96024
2591.22	7.05079
2593.96	7.09491
2596.69	6.58411
2599.42	6.26525
2602.14	5.26348
2604.87	4.80249
2607.6	4.64225
2610.32	3.859
2613.05	3.8989
2615.77	4.05026
2618.49	3.25035
2621.22	2.86612
2623.94	2.69671
2626.66	2.69611
2629.37	2.17233
2632.09	2.76631
2634.81	3.46665
2637.53	3.74577
2640.24	4.32005
2642.96	4.61859
2645.67	4.47062
2648.38	5.87996
2651.09	5.32422
2653.8	5.7214
2656.51	5.77195
2659.22	6.20596
2661.93	6.44717
2664.63	5.84465
2667.34	5.96051
2670.04	5.96851
2672.75	5.60475
2675.45	5.18274
2678.15	6.01711
2680.85	6.68117
2683.55	6.16853
2686.25	6.43384
2688.94	5.9526
2691.64	6.15996
2694.34	6.6047
2697.03	7.02633
2699.73	7.5407
2702.42	7.46867
2705.11	7.62908
2707.8	7.24589
2710.49	7.39868
2713.18	7.67439
2715.87	7.48548
2718.55	7.68292
2721.24	8.47224
2723.93	8.99089
2726.61	8.80589
2729.29	8.57032
2731.98	8.34356
2734.66	7.61716
2737.34	7.74969
2740.02	7.48476
2742.7	8.01032
2745.37	7.5129
2748.05	7.55664
2750.72	7.02211
2753.4	6.91624
2756.07	6.09017
2758.75	6.31095
2761.42	6.29814
2764.09	4.87822
2766.76	4.46127
2769.43	3.5217
2772.1	3.09069
2774.76	3.08135
2777.43	1.47672
2780.1	0.307092
2782.76	-0.0387822
2785.42	0.453134
2788.09	-0.164161
2790.75	-0.0602531
2793.41	-0.467233
2796.07	-0.903045
2798.73	-0.830594
2801.39	-0.344065
2804.04	-0.532255
2806.7	-0.948707
2809.35	-0.779703
2812.01	-1.30885
2814.66	-0.464784
2817.31	0.64627
2819.96	2.63598
2822.61	4.06117
2825.26	7.36295
2827.91	9.86135
2830.56	12.4266
2833.21	15.1255
2835.85	19.0687
2838.5	23.7283
2841.14	27.6219
2843.78	31.855
2846.42	37.6265
2849.06	43.0692
2851.71	49.8295
2854.34	55.7481
2856.98	61.3395
2859.62	67.2495
2862.26	72.7542
2864.89	79.1894
2867.53	83.5326
2870.16	87.0088
2872.79	90.5224
2875.42	94.1284
2878.05	97.5873
2880.68	101.566
2883.31	104.541
2885.94	107.009
2888.57	108.983
2891.19	111.162
2893.82	112.792
2896.44	115.373
2899.07	118.791
2901.69	123.56
2904.31	128.574
2906.93	133.528
2909.55	139.68
2912.17	146.047
2914.79	151.882
2917.41	157.537
2920.02	162.834
2922.64	167.458
2925.25	169.661
2927.86	170.896
2930.48	171.829
2933.09	170.13
2935.7	169.23
2938.31	166.026
2940.92	162.758
2943.53	157.692
2946.13	152.95
2948.74	147.169
2951.34	140.113
2953.95	133.57
2956.55	127.729
2959.15	122.385
2961.75	117.744
2964.35	113.02
2966.95	108.164
2969.55	103.2
2972.15	96.4411
2974.75	91.3845
2977.34	85.5685
2979.94	80.8923
2982.53	76.1379
2985.13	69.7531
2987.72	63.1898
2990.31	56.917
2992.9	52.6251
2995.49	46.2109
2998.08	40.4369
3000.67	34.7282
3003.25	29.3434
3005.84	25.3866
3008.42	20.543
3011.01	17.1775
3013.59	13.0189
3016.17	10.1653
3018.76	8.30737
3021.34	6.43712
3023.92	5.08424
3026.49	4.38435
3029.07	3.4945
3031.65	3.27847
3034.23	2.61734
3036.8	2.6951
3039.38	3.77531
3041.95	5.09911
3044.52	6.48
3047.09	8.16168
3049.66	9.17632
3052.23	11.2224
3054.8	11.7275
3057.37	12.3137
3059.94	12.2911
3062.5	13.3161
3065.07	12.9199
3067.63	13.1459
3070.2	12.4356
3072.76	10.5779
3075.32	9.18079
3077.88	7.71951
3080.44	6.4381
3083	5.36498
3085.56	4.07381
3088.12	3.64039
3090.67	3.04037
3093.23	2.83072
3095.78	2.24218
3098.34	1.73263
3100.89	2.09587
3103.44	2.39764
3105.99	3.75346
3108.54	4.71404
3111.09	6.38668
3113.64	8.29887
3116.19	9.87181
3118.74	11.1505
3121.28	12.9656
3123.83	15.202
3126.37	17.5071
3128.91	18.8438
3131.46	20.718
3134	21.5813
3136.54	22.8396
3139.08	25.4166
3141.62	26.5016
3144.16	28.3424
3146.69	29.8845
3149.23	32.0492