File: data/Raman/poly_smoothed/Thy_10_08_46_1x_45s_532 nm_x100_100%_600 gr_mm_01.txt
#Acq. time (s)=	45
#Accumulations=	2
#Range (cm-¹)=	200...3150
#Windows=	2
#Auto scanning=	Off
#Autofocus=	Off
#Macrospot=	Off
#AutoExposure=	Off
#Spike filter=	Multiple accum.
#Delay time (s)=	0
#Binning=	1
#Readout mode=	Signal
#DeNoise=	Off
#ICS correction=	On
#Dark correction=	Off
#Inst. Process=	Off
#Detector Gain=	Best Dynamic Range
#Detector ADC=	20 kHz
#Detector temperature (°C)=	-69.85
#Instrument=	LabRAM HR Evol
#Detector=	Synapse
#Objective=	x100
#Grating=	600 gr/mm
#ND Filter=	100%
#Laser (nm)=	532
#Hole=	100.021
#Range=	Auto
#Laser Pol.=	No
#Raman. Pol.=	No
#Laser Pol. (°)=	-0.0007625
#Raman Pol. (°)=	89.9995
#Collection=	Microscope
#StageXY=	Marzhauser
#StageZ=	Marzhauser
#X (µm)=	-2356.5
#Y (µm)=	244
#Z (µm)=	521.7
#Full time(mm:ss)=	3:18
#Project=
#Sample=
#Site=
#Title=	Thy_10_08_46_2x_45s_532 nm_x100_100%_600 gr_mm
#Remark=
#Date=	06.07.2022 15:10
#Acquired=	06.07.2022 15:10:51
#Base:Fit=	10.08.2022 09:46:25
#Base:Sub=	10.08.2022 09:46:49
#Filter:Polynom=	16.08.2022 10:24:56
#AxisType[0]=Intens
#AxisUnit[0]=Cnt
#AxisType[1]=Spectr
#AxisUnit[1]=1/cm
200.398	0.0414129
204.027	6.99024
207.657	10.3231
211.283	13.069
214.909	14.4957
218.533	15.3355
222.157	16.4789
225.777	16.1914
229.396	15.1293
233.016	15.3285
236.632	15.7589
240.247	16.0756
243.86	15.8862
247.474	16.3495
251.085	15.5677
254.694	15.0406
258.301	15.591
261.908	15.6934
265.513	15.5834
269.116	15.9331
272.718	15.9857
276.319	17.3001
279.918	17.4227
283.516	19.2126
287.113	18.445
290.708	18.5995
294.302	18.9596
297.894	20.4503
301.485	20.9175
305.073	22.0536
308.661	23.448
312.247	23.9716
315.833	22.7257
319.415	23.2772
322.997	24.9668
326.579	25.2115
330.156	25.4581
333.735	24.8131
337.31	24.9765
340.885	23.7574
344.458	23.571
348.03	22.573
351.6	20.7028
355.17	19.0298
358.737	18.4323
362.304	18.1664
365.868	17.7983
369.431	16.1995
372.994	13.7033
376.554	12.3258
380.112	11.849
383.669	11.1006
387.225	11.9195
390.781	12.4093
394.334	12.6023
397.885	12.421
401.436	11.8056
404.984	10.9355
408.532	13.8214
412.078	13.8382
415.623	13.548
419.166	14.0901
422.708	14.6739
426.248	13.7486
429.788	14.0888
433.326	13.9088
436.86	13.0133
440.395	13.5779
443.929	14.1669
447.461	14.32
450.99	14.447
454.52	13.2645
458.048	12.2111
461.573	10.6501
465.099	11.8094
468.623	11.2472
472.144	12.2261
475.666	13.4778
479.184	13.3857
482.703	12.7686
486.218	13.2856
489.734	14.7201
493.247	15.532
496.759	16.7423
500.271	16.2155
503.779	16.8727
507.287	17.4138
510.795	17.966
514.299	18.0377
517.803	17.0102
521.305	16.9974
524.805	16.4122
528.307	17.8216
531.805	15.4449
535.301	16.054
538.797	15.2536
542.291	13.6014
545.783	12.6551
549.275	12.7262
552.765	11.2479
556.253	10.0168
559.738	10.0349
563.224	9.53499
566.709	7.2556
570.192	6.07764
573.674	4.87513
577.153	3.72249
580.632	2.18538
584.11	2.66212
587.587	2.765
591.06	2.89943
594.534	2.87206
598.005	3.418
601.476	4.71715
604.944	6.06271
608.413	7.07848
611.878	10.0475
615.344	10.4353
618.807	11.2362
622.27	13.4588
625.73	14.7834
629.189	15.8398
632.648	17.1921
636.105	17.9309
639.559	19.5367
643.013	20.1731
646.467	19.5894
649.918	19.6635
653.368	19.7572
656.816	18.639
660.263	20.7014
663.708	21.0825
667.153	23.3712
670.596	23.6531
674.037	25.4133
677.478	26.6483
680.917	27.0673
684.355	30.5328
687.791	32.4311
691.224	34.0006
694.658	34.4077
698.091	34.9681
701.522	35.0377
704.95	35.5711
708.379	37.25
711.806	37.8166
715.23	38.1128
718.655	40.4538
722.078	40.5403
725.498	41.1938
728.919	42.0187
732.337	43.1709
735.755	44.6737
739.17	45.6045
742.584	49.182
745.998	53.2097
749.409	54.5705
752.819	56.5331
756.23	59.3835
759.637	62.944
763.043	65.0238
766.448	66.0899
769.853	67.9786
773.255	69.308
776.656	69.7109
780.056	69.0477
783.454	70.2523
786.851	70.4146
790.247	72.41
793.641	73.2587
797.034	74.4315
800.426	76.1278
803.817	76.324
807.206	76.5703
810.592	76.7605
813.979	76.4867
817.364	78.5842
820.748	79.9262
824.129	80.4943
827.511	82.395
830.891	81.9747
834.269	81.5453
837.646	81.4525
841.023	80.7233
844.396	79.2691
847.77	76.9363
851.141	73.1353
854.513	71.0258
857.881	69.5388
861.248	65.7017
864.616	63.4766
867.98	61.7592
871.343	61.1846
874.707	58.618
878.068	57.9088
881.428	55.5302
884.786	53.651
888.143	52.5851
891.498	52.0903
894.855	52.1982
898.208	53.3003
901.56	52.9096
904.91	53.0345
908.26	53.834
911.608	54.2076
914.955	54.3234
918.298	53.3176
921.643	54.4754
924.986	54.0128
928.328	54.1246
931.668	53.3001
935.006	54.0214
938.344	54.5347
941.681	53.2146
945.014	52.8566
948.349	52.8385
951.682	53.1297
955.012	50.6376
958.343	48.941
961.67	48.62
964.998	48.6592
968.323	50.1416
971.649	51.0309
974.971	49.8421
978.293	48.8747
981.615	47.716
984.933	47.3378
988.251	46.15
991.567	44.7619
994.884	43.0185
998.198	40.9576
1001.51	39.485
1004.82	37.8307
1008.13	36.0134
1011.44	34.4423
1014.75	33.1018
1018.06	32.0605
1021.36	29.2943
1024.66	26.5498
1027.97	25.4418
1031.27	23.7959
1034.57	21.6953
1037.87	20.3635
1041.16	19.0481
1044.46	19.3873
1047.76	18.9702
1051.05	17.4544
1054.34	16.2383
1057.63	15.0385
1060.92	14.849
1064.21	15.3509
1067.5	14.7161
1070.78	13.7996
1074.07	14.1679
1077.35	14.5871
1080.63	14.4085
1083.91	14.4031
1087.19	15.027
1090.47	16.1431
1093.75	18.0622
1097.03	19.9734
1100.3	20.3141
1103.57	20.6573
1106.84	21.3972
1110.11	20.5004
1113.38	21.3225
1116.65	19.8537
1119.92	18.3428
1123.19	15.8035
1126.45	14.3801
1129.71	14.0741
1132.97	14.0543
1136.23	12.6623
1139.49	13.1795
1142.75	12.9034
1146.01	11.357
1149.26	11.1137
1152.52	10.6582
1155.77	7.96415
1159.02	7.03527
1162.27	6.83919
1165.52	6.62872
1168.77	8.37802
1172.02	9.64083
1175.26	10.0701
1178.51	11.104
1181.75	11.2981
1184.99	12.0006
1188.23	11.9542
1191.47	12.8991
1194.71	15.0255
1197.94	15.5704
1201.18	17.9125
1204.41	19.5162
1207.65	23.5604
1210.88	28.4514
1214.11	31.0636
1217.34	34.4727
1220.57	37.1416
1223.79	40.6416
1227.02	41.5287
1230.24	43.3469
1233.47	43.8776
1236.69	44.5105
1239.91	48.0452
1243.13	48.1998
1246.34	49.3701
1249.56	49.865
1252.78	49.4023
1255.99	49.5873
1259.2	48.9731
1262.42	48.1291
1265.63	47.6229
1268.84	46.977
1272.04	46.5491
1275.25	47.1865
1278.46	48.4255
1281.66	50.0899
1284.86	52.6966
1288.07	54.9465
1291.27	56.9214
1294.47	58.1787
1297.66	59.5562
1300.86	59.7479
1304.06	61.5821
1307.25	63.3692
1310.44	64.2656
1313.64	63.8135
1316.83	63.392
1320.02	63.1274
1323.2	61.5633
1326.39	60.6372
1329.58	60.0393
1332.76	58.5159
1335.95	57.143
1339.13	55.5512
1342.31	52.9523
1345.49	50.485
1348.67	48.7416
1351.85	46.3589
1355.02	45.8185
1358.2	44.9364
1361.37	43.207
1364.54	42.9794
1367.71	40.6207
1370.88	39.363
1374.05	38.0612
1377.22	36.589
1380.39	36.8618
1383.55	35.9911
1386.72	34.3176
1389.88	32.4387
1393.04	31.9522
1396.2	31.5005
1399.36	30.9642
1402.52	30.1753
1405.68	32.0979
1408.83	33.932
1411.98	35.7417
1415.14	38.5415
1418.29	41.1949
1421.44	44.3918
1424.59	48.6416
1427.74	53.6475
1430.89	57.8738
1434.03	62.9782
1437.18	67.7592
1440.32	70.4785
1443.46	72.4341
1446.6	73.74
1449.74	73.7669
1452.88	73.5597
1456.02	71.5297
1459.16	67.922
1462.29	63.0382
1465.43	58.2752
1468.56	52.954
1471.69	47.882
1474.82	41.1537
1477.95	35.3927
1481.08	29.9276
1484.2	25.2289
1487.33	21.0366
1490.46	17.4096
1493.58	13.5656
1496.7	11.3486
1499.82	9.47614
1502.94	10.4943
1506.06	9.88328
1509.18	10.502
1512.29	10.9481
1515.41	10.5907
1518.52	12.1816
1521.63	14.1981
1524.75	15.4179
1527.85	16.5217
1530.96	17.7236
1534.07	18.0835
1537.18	21.3399
1540.28	23.3198
1543.39	25.79
1546.49	27.4652
1549.59	29.033
1552.69	32.2822
1555.79	35.7707
1558.89	38.3449
1561.99	40.8298
1565.08	43.3141
1568.18	45.0471
1571.27	47.3126
1574.37	50.9848
1577.46	52.6084
1580.55	54.8166
1583.64	57.4693
1586.73	59.858
1589.81	62.0288
1592.9	62.8791
1595.98	63.8558
1599.06	62.5382
1602.15	61.3482
1605.23	61.3305
1608.31	61.5105
1611.39	62.7379
1614.46	62.8703
1617.54	62.4137
1620.61	62.1189
1623.69	64.0908
1626.76	65.3841
1629.83	66.7171
1632.9	68.5386
1635.97	69.3841
1639.04	72.5598
1642.11	73.0677
1645.17	74.5273
1648.24	76.2751
1651.3	77.5385
1654.36	77.0981
1657.42	78.2149
1660.48	77.5328
1663.54	75.6984
1666.6	72.2511
1669.66	68.5023
1672.71	65.5234
1675.77	62.4173
1678.82	58.6985
1681.87	55.7706
1684.92	51.5581
1687.97	46.6494
1691.02	42.5397
1694.07	37.5927
1697.11	33.3952
1700.16	30.3605
1703.2	26.2796
1706.25	23.041
1709.29	20.5683
1712.33	16.7844
1715.37	14.8926
1718.41	12.5198
1721.44	9.88788
1724.48	8.41597
1727.51	7.18192
1730.55	5.56605
1733.58	4.13362
1736.61	3.24441
1739.64	3.51637
1742.67	3.07505
1745.7	2.85083
1748.72	2.51239
1751.75	1.90647
1754.77	2.12686
1757.8	2.17489
1760.82	2.66683
1763.84	2.06577
1766.86	2.45446
1769.88	1.87844
1772.9	1.43116
1775.91	0.764456
1778.93	0.410811
1781.94	0.161748
1784.96	-0.172246
1787.97	0.371013
1790.98	0.220584
1793.99	-0.339559
1797	-1.06946
1800.01	-0.500615
1803.01	-0.947931
1806.02	-1.04199
1809.02	-0.695826
1812.02	-0.421724
1815.02	-0.332776
1818.03	-0.589008
1821.02	-0.143533
1824.02	-0.0710159
1827.02	0.318472
1830.02	0.7309
1833.01	0.832122
1836.01	1.16951
1839	1.50145
1841.99	1.50575
1844.98	1.38709
1847.97	1.68298
1850.96	2.39714
1853.95	3.10842
1856.93	3.18403
1859.92	2.92786
1862.9	3.32092
1865.88	3.24024
1868.87	3.24555
1871.85	3.28816
1874.83	3.59397
1877.81	3.86053
1880.78	4.35283
1882.53	4.18001
1885.52	4.02092
1888.51	3.35885
1891.5	2.61123
1894.48	3.00234
1897.47	3.08757
1900.45	4.16564
1903.43	3.86257
1906.41	4.04173
1909.39	3.70638
1912.37	4.38699
1915.35	4.59234
1918.33	5.44131
1921.3	6.21324
1924.28	7.09576
1927.25	7.00018
1930.22	6.83311
1933.19	7.21474
1936.16	8.17178
1939.13	8.71155
1942.1	9.26122
1945.07	8.91624
1948.03	9.21151
1951	8.85109
1953.96	8.50898
1956.92	8.17028
1959.88	8.12871
1962.84	8.75462
1965.8	9.60731
1968.76	9.97275
1971.72	10.2105
1974.67	9.5809
1977.63	9.32632
1980.58	9.03027
1983.54	8.87296
1986.49	8.82482
1989.44	8.64203
1992.39	8.76376
1995.33	8.58821
1998.28	8.84691
2001.23	9.42358
2004.17	10.0116
2007.12	10.9433
2010.06	11.2711
2013	11.4383
2015.94	10.7353
2018.88	11.1501
2021.82	11.3592
2024.76	12.1677
2027.69	12.874
2030.63	13.3419
2033.56	14.4262
2036.5	14.8435
2039.43	15.0607
2042.36	14.5643
2045.29	14.2711
2048.22	14.2622
2051.15	14.3318
2054.07	14.4335
2057	14.4728
2059.92	15.1281
2062.85	14.6545
2065.77	14.6642
2068.69	14.4705
2071.61	14.9069
2074.53	14.3221
2077.45	14.7346
2080.37	14.9269
2083.28	15.0497
2086.2	14.5085
2089.11	14.9981
2092.02	15.5576
2094.94	14.8346
2097.85	14.7992
2100.76	15.7889
2103.66	15.9828
2106.57	16.8927
2109.48	16.5684
2112.38	17.8677
2115.29	18.3252
2118.19	19.6678
2121.09	20.0091
2123.99	21.3517
2126.89	22.9813
2129.79	24.2955
2132.69	24.4202
2135.59	25.1732
2138.48	26.3361
2141.38	28.0951
2144.27	28.1642
2147.17	29.5836
2150.06	32.026
2152.95	32.528
2155.84	32.7319
2158.73	32.9445
2161.61	33.8918
2164.5	33.8054
2167.38	34.0516
2170.27	34.524
2173.15	34.8692
2176.03	35.0523
2178.91	35.0433
2181.8	34.9017
2184.67	34.8055
2187.55	34.4409
2190.43	34.0664
2193.3	33.2754
2196.18	32.9981
2199.05	31.5298
2201.93	30.8051
2204.8	29.7242
2207.67	28.2205
2210.54	26.9799
2213.41	25.3174
2216.27	24.2877
2219.14	23.8118
2222.01	22.3788
2224.87	21.0632
2227.73	20.6592
2230.6	19.929
2233.46	19.808
2236.32	18.927
2239.18	18.5678
2242.03	18.1924
2244.89	17.1273
2247.75	17.0332
2250.6	17.5009
2253.46	16.5449
2256.31	16.5645
2259.16	16.0505
2262.01	14.8693
2264.86	13.6511
2267.71	13.8512
2270.56	13.4646
2273.4	12.9528
2276.25	12.515
2279.09	11.9845
2281.94	12.4707
2284.78	12.2169
2287.62	11.6866
2290.46	11.1469
2293.3	11.0342
2296.14	11.6449
2298.98	11.6528
2301.82	12.8703
2304.65	12.6365
2307.49	12.8671
2310.32	13.4519
2313.15	12.9598
2315.98	13.9708
2318.81	14.5783
2321.64	14.2727
2324.47	14.5886
2327.3	13.5903
2330.12	13.2804
2332.95	12.3863
2335.77	11.5593
2338.6	12.194
2341.42	11.612
2344.24	11.5934
2347.06	11.0879
2349.88	10.5964
2352.7	9.74785
2355.51	8.22097
2358.33	7.29509
2361.14	6.00644
2363.96	5.67489
2366.77	5.66869
2369.58	5.24548
2372.39	5.39848
2375.2	5.27439
2378.01	5.00105
2380.82	4.95422
2383.63	5.02485
2386.43	5.15137
2389.24	4.84943
2392.04	4.52737
2394.84	4.82716
2397.65	4.73877
2400.45	4.53131
2403.25	5.71189
2406.05	7.38991
2408.84	8.49833
2411.64	9.83933
2414.44	11.6643
2417.23	11.673
2420.02	12.0481
2422.82	12.0413
2425.61	12.2276
2428.4	11.3422
2431.19	11.6144
2433.98	10.9877
2436.77	10.828
2439.55	10.7205
2442.34	10.1453
2445.12	9.30363
2447.91	7.84478
2450.69	6.65382
2453.47	6.1696
2456.25	5.27624
2459.03	4.91191
2461.81	3.32161
2464.59	2.52331
2467.36	2.18598
2470.14	1.58112
2472.92	1.53174
2475.69	2.07895
2478.46	2.12543
2481.23	2.0687
2484	1.46785
2486.77	1.3838
2489.54	0.879812
2492.31	0.319322
2495.08	0.752761
2497.84	1.56885
2500.61	1.62847
2503.37	2.0946
2506.13	1.45816
2508.9	2.45401
2511.66	2.56293
2514.42	2.9865
2517.18	3.14344
2519.93	3.7168
2522.69	3.84356
2525.45	3.57916
2528.2	2.86062
2530.95	2.40098
2533.71	2.66575
2536.46	2.24153
2539.21	2.04723
2541.96	2.6134
2544.71	1.70912
2547.46	1.1815
2550.2	0.560228
2552.95	0.176228
2555.7	-0.165435
2558.44	-0.426641
2561.18	0.450351
2563.93	0.822903
2566.67	0.974579
2569.41	0.593808
2572.15	0.599512
2574.88	0.64136
2577.62	1.03156
2580.36	0.997572
2583.09	1.56695
2585.83	1.67924
2588.56	0.962877
2591.29	1.51729
2594.02	1.22624
2596.75	1.33251
2599.48	1.57297
2602.21	2.31787
2604.94	2.60363
2607.67	2.96419
2610.39	3.12499
2613.12	2.90787
2615.84	3.2346
2618.56	3.65833
2621.28	3.94235
2624.01	4.20739
2626.72	4.23441
2629.44	4.76653
2632.16	4.27887
2634.88	4.87208
2637.59	4.1275
2640.31	3.87966
2643.02	4.78064
2645.74	4.22763
2648.45	4.32464
2651.16	3.34946
2653.87	2.56883
2656.58	2.97934
2659.29	2.39203
2661.99	2.32361
2664.7	2.67286
2667.41	2.99547
2670.11	3.72902
2672.81	3.41269
2675.51	3.10141
2678.22	2.35811
2680.92	2.77444
2683.62	2.14975
2686.31	1.47693
2689.01	0.899319
2691.71	1.09518
2694.4	0.88518
2697.1	2.23586
2699.79	2.65458
2702.49	3.72916
2705.18	3.60856
2707.87	4.25558
2710.56	3.92439
2713.25	4.16429
2715.94	4.13628
2718.62	5.03295
2721.31	6.32183
2723.99	6.37107
2726.68	6.61112
2729.36	6.93904
2732.04	7.20884
2734.73	7.15798
2737.41	6.70437
2740.08	6.47986
2742.76	6.25706
2745.44	5.7765
2748.12	4.53116
2750.79	3.38416
2753.47	2.42209
2756.14	2.53385
2758.81	1.65482
2761.49	1.63997
2764.16	1.90955
2766.83	1.71616
2769.5	0.791246
2772.16	1.11174
2774.83	0.965551
2777.5	-0.0919204
2780.16	0.136344
2782.83	0.637155
2785.49	0.915258
2788.15	1.29229
2790.82	0.622078
2793.48	0.721484
2796.14	1.01991
2798.79	0.73587
2801.45	1.62313
2804.11	1.7976
2806.76	1.07009
2809.42	0.55363
2812.07	0.0282244
2814.73	0.135513
2817.38	0.849709
2820.03	2.90924
2822.68	5.2958
2825.33	9.01085
2827.98	13.0674
2830.63	17.6128
2833.27	22.1314
2835.92	26.9831
2838.56	32.429
2841.21	38.8467
2843.85	46.1797
2846.49	54.6498
2849.13	63.2774
2851.77	73.614
2854.41	83.3387
2857.05	92.3027
2859.69	101.529
2862.32	109.614
2864.96	117.496
2867.59	124.993
2870.23	130.308
2872.86	135.83
2875.49	141.373
2878.12	145.745
2880.75	150.072
2883.38	155.114
2886.01	158.484
2888.63	162.161
2891.26	166.378
2893.89	170.043
2896.51	175.215
2899.13	180.518
2901.76	187.378
2904.38	194.502
2907	204.389
2909.62	214.695
2912.24	226.65
2914.85	237.983
2917.47	249.537
2920.09	257.63
2922.7	265.117
2925.32	270.506
2927.93	273.665
2930.54	273.889
2933.15	272.884
2935.76	269.851
2938.37	265.22
2940.98	258.4
2943.59	249.851
2946.2	240.42
2948.8	229.094
2951.41	218.047
2954.01	207.802
2956.62	196.348
2959.22	186.291
2961.82	176.96
2964.42	167.255
2967.02	158.99
2969.62	151.414
2972.22	145.156
2974.81	139.016
2977.41	133.182
2980	126.311
2982.6	119.2
2985.19	111.558
2987.78	103.204
2990.38	94.3231
2992.97	86.0037
2995.56	78.206
2998.14	70.1653
3000.73	62.7941
3003.32	56.7737
3005.91	50.9721
3008.49	44.5785
3011.07	38.9325
3013.66	34.1701
3016.24	30.0432
3018.82	26.3534
3021.4	23.9182
3023.98	22.3689
3026.56	20.8069
3029.14	19.9762
3031.71	20.3813
3034.29	20.3844
3036.87	21.4195
3039.44	23.6422
3042.01	24.5524
3044.59	25.7745
3047.16	27.1705
3049.73	28.7729
3052.3	29.7217
3054.87	30.443
3057.43	30.9718
3060	30.6673
3062.57	30.0351
3065.13	29.3433
3067.7	28.3782
3070.26	26.129
3072.82	23.1058
3075.39	20.1041
3077.95	17.177
3080.51	13.853
3083.07	11.3194
3085.63	8.71566
3088.18	6.91836
3090.74	4.83572
3093.29	3.21678
3095.85	2.27948
3098.4	1.97295
3100.95	2.30651
3103.51	2.48734
3106.06	1.91008
3108.61	2.06228
3111.16	1.9202
3113.71	2.30046
3116.25	2.02489
3118.8	2.73717
3121.35	3.11431
3123.89	3.22671
3126.44	3.42695
3128.98	4.02904
3131.52	3.79134
3134.06	3.22954
3136.6	3.42624
3139.14	3.78796
3141.68	4.64869
3144.22	5.67237
3146.76	7.35294
3149.29	9.30078