File: data/Raman/poly_smoothed/Thy_50_12_17_1x_45s_532 nm_x100_100%_600 gr_mm_01.txt
#Acq. time (s)=	45
#Accumulations=	2
#Range (cm-¹)=	200...3150
#Windows=	2
#Auto scanning=	Off
#Autofocus=	Off
#Macrospot=	Off
#AutoExposure=	Off
#Spike filter=	Multiple accum.
#Delay time (s)=	0
#Binning=	1
#Readout mode=	Signal
#DeNoise=	Off
#ICS correction=	On
#Dark correction=	Off
#Inst. Process=	Off
#Detector Gain=	Best Dynamic Range
#Detector ADC=	20 kHz
#Detector temperature (°C)=	-69.85
#Instrument=	LabRAM HR Evol
#Detector=	Synapse
#Objective=	x100
#Grating=	600 gr/mm
#ND Filter=	100%
#Laser (nm)=	532
#Hole=	100.021
#Range=	Auto
#Laser Pol.=	No
#Raman. Pol.=	No
#Laser Pol. (°)=	-0.0007625
#Raman Pol. (°)=	89.9995
#Collection=	Microscope
#StageXY=	Marzhauser
#StageZ=	Marzhauser
#X (µm)=	-5141.5
#Y (µm)=	1475.7
#Z (µm)=	63.25
#Full time(mm:ss)=	3:18
#Project=
#Sample=
#Site=
#Title=	Thy_50_12_17_2x_45s_532 nm_x100_100%_600 gr_mm
#Remark=
#Date=	07.07.2022 10:29
#Acquired=	07.07.2022 10:29:16
#Base:Fit=	10.08.2022 10:04:29
#Base:Sub=	10.08.2022 10:04:45
#Filter:Polynom=	16.08.2022 10:20:24
#AxisType[0]=Intens
#AxisUnit[0]=Cnt
#AxisType[1]=Spectr
#AxisUnit[1]=1/cm
200.43	4.15608
204.061	5.15387
207.688	4.54382
211.316	3.86342
214.941	2.87976
218.566	3.36305
222.188	4.09615
225.809	4.82672
229.43	3.4702
233.047	3.4032
236.663	4.01389
240.278	4.66368
243.894	6.44958
247.506	6.62644
251.116	6.75329
254.725	7.52679
258.333	5.52981
261.939	6.92797
265.546	7.28833
269.15	7.2523
272.752	6.89054
276.353	6.87008
279.952	7.4809
283.55	7.60182
287.146	8.00086
290.739	8.16183
294.333	8.04912
297.925	10.3938
301.516	11.9844
305.106	13.498
308.694	15.5153
312.279	16.0026
315.864	16.2261
319.448	16.7536
323.029	17.8101
326.61	17.9587
330.19	18.957
333.766	20.2763
337.343	20.2996
340.917	20.8333
344.491	20.3664
348.062	20.1263
351.633	18.7304
355.201	19.7029
358.77	20.9828
362.335	20.9353
365.899	20.162
369.464	19.9926
373.025	18.6837
376.585	18.3377
380.143	15.8499
383.702	15.3125
387.258	18.6174
390.812	21.3118
394.365	21.0357
397.916	21.1594
401.467	21.5429
405.015	21.8579
408.565	21.7183
412.111	20.487
415.656	22.6313
419.197	23.6385
422.739	24.1414
426.279	24.6384
429.819	22.5244
433.356	20.5264
436.893	19.3523
440.428	20.5139
443.96	19.098
447.492	18.1353
451.023	15.6628
454.553	12.3639
458.079	10.3178
461.606	8.54702
465.132	7.38293
468.654	8.62362
472.177	13.6327
475.696	15.7627
479.217	16.0609
482.733	16.9364
486.251	18.3056
489.765	19.777
493.278	21.8512
496.791	21.8232
500.301	23.0395
503.81	23.6661
507.319	23.9527
510.825	23.4903
514.33	22.2959
517.833	22.4119
521.337	21.4249
524.838	21.0147
528.337	19.5077
531.835	17.5407
535.332	14.7567
538.827	12.0172
542.321	10.9828
545.814	9.63908
549.305	9.34966
552.795	9.01131
556.284	9.73436
559.771	8.18004
563.257	7.87528
566.742	6.46513
570.223	5.86509
573.705	6.87305
577.185	5.3616
580.665	4.22721
584.141	3.59142
587.617	4.29771
591.092	3.69713
594.564	4.04651
598.037	2.79056
601.506	4.1155
604.976	2.706
608.443	2.17793
611.91	1.65141
615.374	0.572216
618.839	-0.335996
622.3	0.371468
625.761	0.661466
629.221	1.29204
632.679	2.61795
636.135	4.83238
639.592	6.32232
643.045	7.4918
646.497	9.20791
649.948	10.7583
653.398	11.8225
656.846	13.9839
660.293	13.6637
663.738	13.9327
667.185	16.6858
670.628	17.9858
674.067	19.7628
677.508	21.5068
680.947	21.6828
684.385	23.9771
687.821	25.7655
691.256	27.0861
694.69	26.6507
698.121	28.246
701.552	29.2152
704.982	31.5534
708.41	32.6308
711.836	32.1102
715.262	33.8705
718.685	36.5601
722.108	37.2838
725.53	37.5954
728.949	37.7769
732.369	38.2342
735.785	38.7847
739.2	37.9427
742.616	38.44
746.028	39.1289
749.441	41.4477
752.851	41.6583
756.26	44.1623
759.667	46.3989
763.075	48.343
766.479	49.3492
769.883	51.9252
773.285	53.7186
776.686	54.6206
780.085	56.8123
783.484	57.2547
786.881	59.8408
790.276	62.0432
793.671	64.2144
797.064	65.6472
800.456	68.8176
803.846	70.2466
807.236	69.9612
810.624	68.3494
814.01	68.6444
817.394	68.9076
820.778	69.273
824.161	66.746
827.543	66.8904
830.921	63.4344
834.3	60.0687
837.676	58.9304
841.053	56.8143
844.426	53.0753
847.8	49.6932
851.171	46.0761
854.542	44.9009
857.911	42.1634
861.279	41.0748
864.645	37.7926
868.01	39.1424
871.375	38.1225
874.737	38.6555
878.097	39.4784
881.457	37.4613
884.817	38.5641
888.174	38.4014
891.53	39.4199
894.884	40.1541
898.237	41.914
901.589	42.1776
904.94	40.8674
908.289	38.353
911.637	36.9803
914.984	34.2208
918.33	33.4176
921.674	31.4848
925.015	28.9578
928.357	26.5294
931.698	24.7015
935.037	23.1195
938.373	22.5947
941.71	20.4452
945.046	17.7203
948.378	16.8313
951.711	17.7142
955.043	18.5484
958.372	17.6014
961.701	17.1775
965.027	17.3161
968.354	19.6823
971.678	20.117
975	20.6863
978.324	21.7516
981.644	21.8561
984.962	21.3321
988.282	21.3492
991.598	20.5718
994.913	19.271
998.227	19.0291
1001.54	19.1069
1004.85	19.3162
1008.16	18.8839
1011.47	20.0609
1014.78	19.5319
1018.08	19.9473
1021.39	20.5351
1024.69	19.6494
1028	21.0175
1031.3	22.3182
1034.6	22.5596
1037.9	21.7786
1041.19	21.0694
1044.49	21.1906
1047.79	20.9664
1051.08	20.908
1054.37	20.404
1057.66	20.5686
1060.95	18.8131
1064.24	17.6302
1067.53	15.9714
1070.81	14.8566
1074.1	14.3605
1077.38	12.7868
1080.66	13.6608
1083.94	14.8056
1087.22	15.0652
1090.5	15.3093
1093.78	15.7203
1097.05	16.476
1100.33	15.5006
1103.6	15.6152
1106.87	15.5603
1110.15	14.2021
1113.41	13.2295
1116.68	13.5064
1119.95	12.4917
1123.21	12.5772
1126.48	10.7914
1129.74	10.5184
1133	10.0011
1136.26	7.45165
1139.52	5.57626
1142.78	3.84114
1146.04	3.6746
1149.29	2.64652
1152.55	1.4936
1155.8	1.74072
1159.05	1.29602
1162.3	2.49923
1165.55	3.48613
1168.8	2.97452
1172.05	4.47588
1175.29	3.92077
1178.54	4.65467
1181.78	5.80979
1185.02	7.01584
1188.26	8.26601
1191.5	8.01764
1194.74	9.27607
1197.97	11.9587
1201.21	13.4919
1204.44	15.8477
1207.68	18.6937
1210.91	20.7187
1214.14	21.6481
1217.37	23.1501
1220.6	27.7817
1223.82	31.6538
1227.05	34.9531
1230.27	37.8627
1233.49	40.444
1236.72	42.4187
1239.94	44.3022
1243.16	47.3147
1246.37	48.3551
1249.59	50.2253
1252.8	52.6227
1256.02	52.9596
1259.23	55.2775
1262.44	56.9939
1265.66	58.6807
1268.87	60.2113
1272.07	63.4554
1275.28	66.8249
1278.48	70.0268
1281.69	72.3131
1284.89	73.7168
1288.09	74.2103
1291.3	75.5658
1294.49	77.6117
1297.69	80.5056
1300.89	81.9659
1304.09	81.3363
1307.28	81.8113
1310.47	80.4271
1313.66	80.7874
1316.86	78.4226
1320.05	77.6387
1323.23	76.0412
1326.42	73.6358
1329.61	71.6345
1332.79	69.3263
1335.98	66.8435
1339.16	66.4642
1342.34	64.4618
1345.52	61.7665
1348.7	60.6148
1351.87	59.3176
1355.05	56.9789
1358.23	54.3733
1361.4	51.9278
1364.57	49.5839
1367.74	48.9346
1370.91	47.955
1374.08	47.3172
1377.25	46.9498
1380.42	46.9832
1383.58	47.3356
1386.75	48.2748
1389.91	47.8102
1393.07	45.8925
1396.23	44.5278
1399.39	44.3523
1402.55	44.3313
1405.7	45.653
1408.86	46.7762
1412.01	47.6857
1415.17	50.762
1418.32	52.2783
1421.47	54.6666
1424.62	57.959
1427.77	62.4884
1430.92	66.3717
1434.06	69.2315
1437.2	72.1016
1440.35	74.51
1443.49	78.6886
1446.63	81.6244
1449.77	81.8725
1452.91	82.6491
1456.05	81.8561
1459.18	79.7855
1462.32	75.9362
1465.45	72.1277
1468.59	65.3776
1471.72	60.7817
1474.85	54.62
1477.98	51.0779
1481.11	44.7665
1484.23	40.7792
1487.36	36.7419
1490.48	34.268
1493.61	31.5982
1496.73	29.1715
1499.85	27.466
1502.97	26.971
1506.09	27.4976
1509.2	28.32
1512.32	27.9084
1515.44	30.445
1518.55	31.7804
1521.66	32.4894
1524.77	33.532
1527.88	35.6662
1530.99	38.6392
1534.1	42.394
1537.21	45.52
1540.31	48.7785
1543.42	51.5504
1546.52	54.7624
1549.62	60.0749
1552.72	63.9691
1555.82	67.4129
1558.92	71.9011
1562.02	75.0852
1565.11	79.33
1568.21	81.5683
1571.3	84.1501
1574.39	86.6567
1577.49	88.4256
1580.58	91.1246
1583.67	91.3395
1586.75	90.7674
1589.84	88.9893
1592.93	87.7143
1596.01	86.1586
1599.09	85.1038
1602.18	83.9613
1605.26	82.1604
1608.34	80.0121
1611.41	78.468
1614.49	77.717
1617.57	77.8058
1620.64	77.6988
1623.72	78.5811
1626.79	80.4949
1629.86	81.0405
1632.93	83.325
1636	85.3088
1639.07	86.646
1642.14	89.2342
1645.2	88.7885
1648.27	90.6524
1651.33	90.693
1654.39	91.6581
1657.45	90.6125
1660.51	87.3241
1663.57	84.531
1666.63	80.4879
1669.69	76.5691
1672.74	72.8361
1675.79	67.2136
1678.85	61.5309
1681.9	55.3645
1684.95	50.2964
1688	44.8891
1691.05	39.6832
1694.1	34.6098
1697.14	30.022
1700.19	26.5754
1703.23	21.821
1706.27	18.8231
1709.32	16.0874
1712.35	13.1084
1715.39	10.7763
1718.43	9.28457
1721.47	8.05542
1724.5	8.73952
1727.54	9.04461
1730.57	9.65708
1733.61	9.13627
1736.64	9.24449
1739.67	9.84812
1742.7	9.20748
1745.72	10.6239
1748.75	11.1204
1751.78	11.0696
1754.8	11.7564
1757.82	11.1118
1760.85	10.7113
1763.87	10.1719
1766.89	9.66741
1769.91	9.63345
1772.92	9.60265
1775.94	7.94461
1778.96	7.25823
1781.97	6.73922
1784.98	5.60998
1788	4.35212
1791.01	4.88321
1794.01	3.89928
1797.02	4.08624
1800.03	3.95807
1803.04	3.35277
1806.04	2.42666
1809.05	1.76878
1812.05	1.10647
1815.05	0.334644
1818.05	0.707991
1821.05	1.22612
1824.05	0.891208
1827.05	1.19099
1830.04	1.58654
1833.04	1.48386
1836.03	1.62412
1839.03	2.19512
1842.02	3.02396
1845.01	2.76037
1848	3.10677
1850.99	3.15968
1853.97	3.01213
1856.96	3.17874
1859.94	2.89552
1862.93	2.80135
1865.91	2.30886
1868.89	2.53941
1871.87	1.74334
1874.85	1.06914
1877.83	0.555368
1880.81	0.582902
1882.56	1.37487
1885.55	1.87486
1888.54	3.29085
1891.52	3.46248
1894.51	3.80239
1897.49	4.21963
1900.48	5.04088
1903.46	4.5966
1906.44	5.05658
1909.42	6.55871
1912.4	7.11067
1915.38	6.67274
1918.35	6.38402
1921.33	6.84113
1924.3	6.30856
1927.28	6.21069
1930.25	4.15565
1933.22	3.85153
1936.19	3.80938
1939.16	3.1358
1942.13	3.01528
1945.09	2.25065
1948.06	1.63545
1951.03	2.57165
1953.99	2.9401
1956.95	3.25214
1959.91	3.3828
1962.87	3.33528
1965.83	3.67359
1968.79	4.03068
1971.75	5.12806
1974.7	5.40568
1977.66	5.46949
1980.61	5.87726
1983.56	5.97753
1986.52	5.31233
1989.47	5.3277
1992.41	5.56472
1995.36	5.32762
1998.31	5.22397
2001.26	5.56145
2004.2	5.37124
2007.15	5.75341
2010.09	4.33869
2013.03	3.61169
2015.97	3.05663
2018.91	2.15156
2021.85	1.11744
2024.79	1.40204
2027.72	1.1627
2030.66	1.09113
2033.59	1.38469
2036.53	1.48691
2039.46	1.66626
2042.39	2.79095
2045.32	2.76831
2048.25	3.35024
2051.18	4.01481
2054.1	5.36586
2057.03	5.9356
2059.95	7.77585
2062.88	9.35436
2065.8	11.0373
2068.72	13.6685
2071.64	15.4768
2074.56	17.682
2077.48	18.9698
2080.39	21.0262
2083.31	23.8751
2086.22	25.0278
2089.14	26.3236
2092.05	27.7862
2094.96	29.8163
2097.87	32.7805
2100.78	34.9332
2103.69	36.5988
2106.6	38.6601
2109.51	42.1301
2112.41	45.4492
2115.32	48.0492
2118.22	51.1875
2121.12	54.7093
2124.02	58.0238
2126.92	61.2583
2129.82	65.2181
2132.72	69.7992
2135.62	73.6185
2138.51	78.2307
2141.41	81.6782
2144.3	86.3298
2147.19	90.0379
2150.09	93.9195
2152.97	97.7503
2155.86	99.974
2158.75	102.185
2161.64	104.789
2164.53	105.513
2167.41	106.359
2170.3	106.572
2173.18	106.084
2176.06	105.267
2178.94	104.489
2181.82	103.454
2184.7	101.389
2187.58	98.7043
2190.46	95.5842
2193.33	92.3264
2196.21	90.3889
2199.08	86.9102
2201.95	83.506
2204.83	79.6237
2207.7	76.0242
2210.57	72.6626
2213.43	68.5417
2216.3	64.3601
2219.17	61.4585
2222.03	57.5521
2224.9	54.096
2227.76	50.8734
2230.62	47.0748
2233.49	43.0757
2236.34	39.7296
2239.2	36.1692
2242.06	33.9382
2244.92	30.6747
2247.78	28.8077
2250.63	27.2962
2253.48	25.6098
2256.34	23.7512
2259.19	22.8443
2262.04	21.7175
2264.89	21.5743
2267.74	20.7283
2270.59	19.7208
2273.43	19.7453
2276.28	18.6782
2279.12	18.1528
2281.97	16.8221
2284.81	16.7685
2287.65	15.1734
2290.49	13.1554
2293.33	11.5382
2296.17	9.61357
2299.01	8.62887
2301.84	8.63119
2304.68	9.2888
2307.51	8.69698
2310.35	8.55254
2313.18	8.48253
2316.01	8.31264
2318.84	8.96996
2321.67	8.78588
2324.5	8.65255
2327.33	8.08037
2330.15	7.25245
2332.98	6.41535
2335.8	6.15466
2338.62	5.97269
2341.45	4.8579
2344.27	4.32952
2347.09	3.86474
2349.91	2.74447
2352.72	2.4231
2355.54	0.93339
2358.36	-0.402719
2361.17	-1.35565
2363.98	0.239556
2366.8	0.674599
2369.61	1.60348
2372.42	2.71123
2375.23	2.59239
2378.04	2.71245
2380.85	2.33189
2383.66	2.53255
2386.46	3.04013
2389.26	3.50293
2392.07	3.83678
2394.87	4.19482
2397.67	3.21795
2400.47	3.21769
2403.27	3.72072
2406.07	4.31038
2408.87	4.41128
2411.67	4.92327
2414.46	6.63788
2417.26	6.82582
2420.05	7.42539
2422.84	8.4651
2425.64	9.28886
2428.43	8.86654
2431.22	8.50176
2434.01	8.82976
2436.79	8.95158
2439.58	8.56829
2442.37	7.05544
2445.15	7.25486
2447.93	7.01893
2450.72	6.43716
2453.5	6.07524
2456.28	6.55916
2459.06	6.12494
2461.84	5.39169
2464.62	4.27273
2467.39	3.78673
2470.17	3.99444
2472.94	3.72124
2475.72	3.96874
2478.49	4.14677
2481.26	4.39046
2484.03	3.50699
2486.8	3.53545
2489.57	3.92489
2492.34	3.62517
2495.1	3.18981
2497.87	1.34467
2500.63	1.18628
2503.4	1.64673
2506.16	0.996576
2508.92	0.912388
2511.68	0.391555
2514.44	0.951551
2517.2	0.298298
2519.96	0.745299
2522.72	1.11324
2525.47	1.47913
2528.23	1.33877
2530.98	1.60769
2533.74	1.74177
2536.49	2.77974
2539.24	3.40866
2541.99	3.32774
2544.74	4.21359
2547.49	3.48045
2550.23	2.83058
2552.98	3.49488
2555.72	3.93417
2558.47	3.65597
2561.21	3.83965
2563.95	3.93763
2566.69	3.96149
2569.43	3.78303
2572.17	3.69769
2574.91	4.10732
2577.65	3.80466
2580.39	4.22021
2583.12	4.86446
2585.85	5.6019
2588.59	5.60699
2591.32	5.509
2594.05	4.7047
2596.78	4.65573
2599.51	4.80694
2602.24	4.85525
2604.97	4.01724
2607.69	3.91811
2610.42	4.31633
2613.14	3.39136
2615.87	3.47297
2618.59	3.56996
2621.31	3.3394
2624.03	3.98379
2626.75	4.24465
2629.47	4.71613
2632.19	4.11729
2634.91	3.19208
2637.62	3.6809
2640.34	4.06036
2643.05	3.99609
2645.76	3.75456
2648.48	4.09632
2651.19	4.04104
2653.9	3.84341
2656.6	2.57334
2659.31	2.3677
2662.02	2.67607
2664.73	3.81626
2667.43	4.61309
2670.14	5.30204
2672.84	6.04139
2675.54	5.66687
2678.24	7.00643
2680.94	7.37123
2683.64	7.37253
2686.34	8.31221
2689.04	8.65683
2691.74	9.65721
2694.43	10.9362
2697.13	10.6141
2699.82	11.0726
2702.51	12.0205
2705.21	12.8382
2707.9	12.9683
2710.58	13.6651
2713.27	14.59
2715.96	14.7056
2718.65	14.9519
2721.33	14.2353
2724.02	13.8636
2726.71	14.449
2729.39	14.5166
2732.07	14.7882
2734.75	13.7293
2737.43	12.9692
2740.11	11.8953
2742.79	11.0133
2745.47	9.8927
2748.14	8.29197
2750.82	7.49281
2753.49	6.06074
2756.17	6.12717
2758.84	5.88259
2761.51	4.91802
2764.18	4.96167
2766.85	5.3543
2769.52	5.63021
2772.19	6.30676
2774.86	5.89033
2777.52	5.69881
2780.19	4.08936
2782.85	3.92806
2785.52	3.61145
2788.18	4.23806
2790.84	4.15882
2793.5	3.75922
2796.16	4.09239
2798.82	3.75776
2801.48	3.07098
2804.13	2.80137
2806.79	1.47928
2809.45	0.526763
2812.1	-0.168586
2814.75	-0.433486
2817.41	0.859179
2820.06	3.22251
2822.71	7.69528
2825.36	12.6571
2828	17.794
2830.65	23.9687
2833.3	29.3013
2835.94	34.7437
2838.59	39.4
2841.23	45.0877
2843.87	52.4915
2846.52	59.9148
2849.16	69.0046
2851.8	78.9661
2854.44	88.2182
2857.08	96.2103
2859.71	103.999
2862.35	111.892
2864.98	118.013
2867.62	122.692
2870.25	127.1
2872.88	132.323
2875.52	135.499
2878.15	138.988
2880.78	144.011
2883.41	148.681
2886.03	153.864
2888.66	158.16
2891.29	161.815
2893.91	165.974
2896.54	170.282
2899.16	174.884
2901.78	180.563
2904.4	188.571
2907.02	198.738
2909.64	208.453
2912.26	219.643
2914.88	230.103
2917.5	240.281
2920.11	249.498
2922.73	255.642
2925.34	259.469
2927.96	262.272
2930.57	262.813
2933.18	262.846
2935.79	261.01
2938.4	256.946
2941.01	250.552
2943.62	244.707
2946.22	237.212
2948.83	228.217
2951.43	217.94
2954.04	206.256
2956.64	196.376
2959.24	186.446
2961.84	175.719
2964.45	166.553
2967.05	157.521
2969.64	149.046
2972.24	139.52
2974.84	130.939
2977.43	122.161
2980.03	113.364
2982.62	104.31
2985.22	94.6474
2987.81	84.589
2990.4	75.5749
2992.99	67.218
2995.58	59.5315
2998.17	52.1523
3000.76	44.5551
3003.34	38.4232
3005.93	33.7248
3008.52	28.7603
3011.1	24.2769
3013.68	20.8144
3016.27	17.3892
3018.85	15.7629
3021.43	14.531
3024.01	13.053
3026.59	11.586
3029.16	10.9006
3031.74	10.4921
3034.32	9.82274
3036.89	10.4785
3039.47	11.3218
3042.04	11.6274
3044.61	12.2771
3047.18	12.9199
3049.75	13.5862
3052.32	14.262
3054.89	14.2811
3057.46	13.5432
3060.03	13.6073
3062.59	13.2088
3065.16	12.7741
3067.72	12.0049
3070.29	11.8262
3072.85	10.5772
3075.41	9.39399
3077.97	8.58264
3080.53	6.74566
3083.09	5.16682
3085.65	4.29081
3088.21	2.68757
3090.76	1.43979
3093.32	0.097453
3095.87	-0.908697
3098.43	-1.35001
3100.98	-1.08094
3103.53	-1.10461
3106.08	-0.240524
3108.63	0.928078
3111.18	1.23766
3113.73	2.47994
3116.28	3.24334
3118.83	3.87528
3121.37	4.7975
3123.92	5.96611
3126.46	6.83104
3129	7.92944
3131.55	9.20033
3134.09	10.1695
3136.63	10.3208
3139.17	11.1874
3141.71	11.7478
3144.24	11.6005
3146.78	11.1977
3149.32	9.86987