File: data/Raman/poly_smoothed/Thy_10_08_22_1x_45s_532 nm_x100_100%_600 gr_mm_01.txt
#Acq. time (s)=	45
#Accumulations=	2
#Range (cm-¹)=	200...3150
#Windows=	2
#Auto scanning=	Off
#Autofocus=	Off
#Macrospot=	Off
#AutoExposure=	Off
#Spike filter=	Multiple accum.
#Delay time (s)=	0
#Binning=	1
#Readout mode=	Signal
#DeNoise=	Off
#ICS correction=	On
#Dark correction=	Off
#Inst. Process=	Off
#Detector Gain=	Best Dynamic Range
#Detector ADC=	20 kHz
#Detector temperature (°C)=	-69.85
#Instrument=	LabRAM HR Evol
#Detector=	Synapse
#Objective=	x100
#Grating=	600 gr/mm
#ND Filter=	100%
#Laser (nm)=	532
#Hole=	100.021
#Range=	Auto
#Laser Pol.=	No
#Raman. Pol.=	No
#Laser Pol. (°)=	-0.0007625
#Raman Pol. (°)=	89.9995
#Collection=	Microscope
#StageXY=	Marzhauser
#StageZ=	Marzhauser
#X (µm)=	2210.1
#Y (µm)=	1235.2
#Z (µm)=	442.95
#Full time(mm:ss)=	3:18
#Project=
#Sample=
#Site=
#Title=	Thy_10_08_22_2x_45s_532 nm_x100_100%_600 gr_mm
#Remark=
#Date=	05.07.2022 15:44
#Acquired=	05.07.2022 15:44:38
#Base:Fit=	10.08.2022 09:46:25
#Base:Sub=	10.08.2022 09:46:49
#Filter:Polynom=	16.08.2022 10:24:56
#AxisType[0]=Intens
#AxisUnit[0]=Cnt
#AxisType[1]=Spectr
#AxisUnit[1]=1/cm
200.43	25.3518
204.059	31.2389
207.688	31.3788
211.314	29.7402
214.941	28.176
218.564	25.1028
222.186	21.9895
225.809	18.1925
229.428	15.8696
233.045	14.4095
236.663	14.4309
240.278	13.575
243.891	13.4358
247.503	14.4521
251.116	14.6726
254.725	13.6515
258.333	13.0983
261.939	13.8829
265.544	14.4569
269.148	14.6069
272.75	16.6842
276.351	16.0405
279.95	16.6626
283.548	17.8603
287.144	17.1849
290.739	16.9073
294.333	15.3151
297.925	16.1216
301.514	17.8839
305.104	17.3702
308.692	16.3238
312.279	17.2283
315.862	16.7881
319.446	16.2194
323.029	15.4343
326.608	15.0483
330.188	14.9031
333.766	16.5993
337.341	16.0779
340.917	16.2155
344.489	15.8942
348.062	13.8984
351.631	12.58
355.201	11.5905
358.768	11.7607
362.333	10.6692
365.899	9.10798
369.462	9.22206
373.023	8.285
376.585	8.74473
380.143	8.6845
383.7	9.87681
387.256	11.4076
390.812	11.0053
394.365	9.78688
397.916	8.1917
401.467	6.25565
405.015	4.88081
408.563	5.03004
412.109	3.73828
415.654	4.03374
419.197	3.60059
422.739	3.26721
426.279	3.95419
429.819	3.40829
433.356	3.01275
436.891	2.71891
440.426	2.38691
443.96	2.40355
447.492	1.48938
451.021	2.23877
454.551	2.40136
458.079	3.5587
461.604	3.54616
465.13	5.03331
468.654	7.21392
472.175	6.96314
475.696	7.15626
479.215	8.49613
482.733	8.90557
486.249	9.78767
489.765	10.9112
493.278	12.2108
496.789	11.9157
500.301	12.8817
503.81	14.0126
507.317	13.5992
510.825	14.1668
514.33	13.8855
517.833	13.5438
521.335	12.0538
524.836	11.8197
528.335	10.3208
531.835	10.4967
535.332	9.08401
538.827	8.33059
542.321	8.40176
545.814	7.87015
549.305	7.57941
552.795	6.6593
556.282	6.47074
559.769	4.80614
563.255	4.38166
566.739	5.14652
570.223	5.10209
573.705	5.28164
577.183	5.36805
580.663	6.20143
584.141	9.05117
587.615	8.8195
591.09	8.69895
594.564	7.71672
598.035	8.10579
601.506	8.32577
604.974	7.50168
608.443	7.88697
611.908	9.10617
615.374	9.65712
618.837	7.72213
622.3	7.56465
625.761	6.13307
629.219	6.75023
632.677	7.01763
636.135	6.83925
639.59	7.60399
643.043	7.5315
646.495	7.9221
649.948	10.1106
653.398	13.4615
656.846	14.594
660.293	16.6467
663.738	19.8622
667.183	21.5958
670.626	21.8197
674.067	22.809
677.508	23.1125
680.947	23.9468
684.385	26.0391
687.821	26.7205
691.254	29.2574
694.688	29.7946
698.121	30.7342
701.552	30.7599
704.98	30.888
708.409	32.369
711.836	34.1109
715.26	36.153
718.685	38.0439
722.108	39.1423
725.528	40.7087
728.949	42.4018
732.367	47.1164
735.785	48.7455
739.2	52.0099
742.614	53.4417
746.028	55.6548
749.439	56.7916
752.849	59.05
756.26	63.1468
759.667	65.7446
763.073	68.0666
766.477	68.6232
769.883	70.4421
773.285	71.5618
776.686	73.2355
780.085	74.3456
783.484	75.4015
786.881	75.8393
790.276	78.4659
793.671	79.3045
797.064	81.8201
800.456	85.2486
803.846	86.4921
807.234	87.0407
810.622	88.6088
814.008	90.3648
817.394	89.6603
820.778	90.2451
824.159	91.5455
827.541	91.6751
830.921	91.7511
834.298	92.972
837.676	93.254
841.051	92.0051
844.426	88.5997
847.798	85.5881
851.171	81.9342
854.54	79.5555
857.911	76.0912
861.278	74.5381
864.645	71.5595
868.01	69.42
871.373	66.1024
874.735	66.1849
878.097	64.229
881.457	63.4466
884.815	62.3498
888.172	60.8989
891.528	59.7174
894.882	58.546
898.237	55.7624
901.589	56.0925
904.94	57.7586
908.289	57.8046
911.635	58.6481
914.982	58.4863
918.328	58.8429
921.672	59.9812
925.015	59.0684
928.357	58.7204
931.698	58.4128
935.035	58.3414
938.373	57.309
941.71	56.4812
945.044	54.7129
948.378	53.8702
951.709	52.6946
955.041	50.9786
958.372	49.6462
961.699	46.7771
965.027	47.4076
968.352	48.8497
971.676	50.8264
975	50.0139
978.322	50.6542
981.642	52.3527
984.962	54.6958
988.28	54.292
991.596	53.2211
994.911	54.0787
998.227	54.3583
1001.54	54.6828
1004.85	53.6638
1008.16	51.6663
1011.47	50.7134
1014.78	50.0641
1018.08	48.9852
1021.39	46.8727
1024.69	44.0949
1028	42.0846
1031.3	37.7748
1034.6	34.4462
1037.9	31.3009
1041.19	29.1523
1044.49	28.1408
1047.78	27.569
1051.08	28.1052
1054.37	26.4849
1057.66	24.5096
1060.95	22.818
1064.24	21.9204
1067.53	20.7182
1070.81	18.5711
1074.1	19.6774
1077.38	20.3137
1080.66	20.8691
1083.94	20.8989
1087.22	20.2251
1090.5	22.6862
1093.78	25.0302
1097.05	27.1196
1100.33	27.391
1103.6	26.5956
1106.87	26.0331
1110.14	24.9032
1113.41	22.9953
1116.68	21.7716
1119.95	19.1363
1123.21	18.0128
1126.48	14.8442
1129.74	13.4195
1133	11.8974
1136.26	10.4978
1139.52	9.69622
1142.78	10.393
1146.04	9.65469
1149.29	8.63415
1152.55	7.32351
1155.8	7.89616
1159.05	7.77395
1162.3	7.26635
1165.55	7.50253
1168.8	9.00248
1172.05	10.5647
1175.29	11.8052
1178.54	13.2742
1181.78	14.1779
1185.02	13.8677
1188.26	15.6367
1191.5	17.9831
1194.74	21.0102
1197.97	23.38
1201.21	26.9532
1204.44	28.619
1207.68	32.9909
1210.91	37.6087
1214.14	41.4006
1217.37	47.2332
1220.59	51.5629
1223.82	54.5819
1227.05	57.6311
1230.27	59.3545
1233.49	62.2285
1236.72	63.573
1239.94	64.3173
1243.16	65.2887
1246.37	66.1874
1249.59	65.9995
1252.8	66.4538
1256.02	65.8499
1259.23	64.6014
1262.44	63.0348
1265.66	63.9438
1268.86	64.3264
1272.07	64.562
1275.28	64.6369
1278.48	64.3151
1281.69	65.2557
1284.89	67.0406
1288.09	69.7393
1291.29	71.6658
1294.49	73.3102
1297.69	75.6787
1300.89	78.8944
1304.08	80.7313
1307.28	82.2876
1310.47	84.4881
1313.66	86.0286
1316.85	86.7724
1320.04	88.0433
1323.23	89.3784
1326.42	88.3805
1329.61	87.7417
1332.79	85.5999
1335.97	84.0914
1339.16	81.9521
1342.34	81.9703
1345.52	79.2139
1348.7	75.4515
1351.87	72.8209
1355.05	69.6992
1358.22	66.6043
1361.4	65.4743
1364.57	62.6097
1367.74	59.7371
1370.91	56.8771
1374.08	54.414
1377.25	53.9449
1380.41	52.6098
1383.58	51.1342
1386.74	49.7636
1389.91	48.7358
1393.07	46.0598
1396.23	44.9146
1399.39	43.5926
1402.55	43.5649
1405.7	42.3827
1408.86	42.5132
1412.01	43.7053
1415.17	47.1218
1418.32	50.2712
1421.47	52.6289
1424.62	55.8787
1427.77	59.6893
1430.91	64.9556
1434.06	71.2755
1437.2	76.4887
1440.35	80.5243
1443.49	82.8932
1446.63	84.4287
1449.77	84.7475
1452.91	85.2342
1456.05	83.1387
1459.18	79.9502
1462.32	76.0506
1465.45	71.1664
1468.59	63.6533
1471.72	57.9268
1474.85	51.4679
1477.98	44.7249
1481.1	38.5115
1484.23	32.6778
1487.36	29.6853
1490.48	27.0678
1493.61	23.8741
1496.73	20.386
1499.85	18.9865
1502.97	18.7056
1506.09	19.3778
1509.2	19.5038
1512.32	20.2512
1515.43	20.9022
1518.55	21.5865
1521.66	21.3351
1524.77	22.4249
1527.88	23.1276
1530.99	25.0035
1534.1	25.0462
1537.21	28.2518
1540.31	28.1081
1543.42	28.3934
1546.52	30.4602
1549.62	34.2807
1552.72	35.6016
1555.82	37.4809
1558.92	41.2401
1562.02	45.8308
1565.11	47.113
1568.21	48.4741
1571.3	49.5951
1574.39	52.711
1577.49	53.8202
1580.57	58.6063
1583.66	60.4493
1586.75	64.49
1589.84	65.552
1592.92	67.1471
1596.01	67.7474
1599.09	68.6987
1602.17	69.3938
1605.25	69.3904
1608.33	69.1782
1611.41	68.4069
1614.49	67.8278
1617.57	67.0055
1620.64	69.2445
1623.72	69.9858
1626.79	71.1826
1629.86	73.3329
1632.93	76.6336
1636	79.3682
1639.07	80.4303
1642.13	82.0867
1645.2	85.3473
1648.26	87.8666
1651.33	89.4489
1654.39	91.2124
1657.45	94.2754
1660.51	93.2691
1663.57	92.8734
1666.63	91.2133
1669.68	88.8378
1672.74	84.5709
1675.79	80.6048
1678.85	74.9459
1681.9	69.1007
1684.95	62.9295
1688	57.6584
1691.05	52.1894
1694.09	46.231
1697.14	41.2356
1700.18	35.6438
1703.23	32.436
1706.27	28.1224
1709.31	25.0663
1712.35	22.7366
1715.39	20.2408
1718.43	17.5973
1721.47	15.676
1724.5	13.4645
1727.54	11.5606
1730.57	10.9748
1733.61	10.6305
1736.64	9.66475
1739.67	9.55033
1742.7	8.14954
1745.72	6.80481
1748.75	5.48013
1751.77	5.43221
1754.8	4.56031
1757.82	3.38053
1760.84	3.00219
1763.87	2.83216
1766.89	1.28409
1769.91	0.266377
1772.92	0.400254
1775.94	0.582634
1778.95	0.380207
1781.97	1.21177
1784.98	1.80435
1787.99	1.22691
1791.01	0.954126
1794.01	-0.06103
1797.02	-0.569421
1800.03	-0.650011
1803.04	-0.548409
1806.04	0.431559
1809.05	0.89076
1812.05	1.23503
1815.05	1.33195
1818.05	1.15621
1821.05	1.86832
1824.05	3.22704
1827.05	3.96118
1830.04	4.43944
1833.04	4.80967
1836.03	5.7679
1839.03	5.79565
1842.02	5.45061
1845.01	5.78987
1848	6.24668
1850.99	7.38007
1853.97	7.95218
1856.96	9.3422
1859.94	9.12879
1862.93	8.59148
1865.91	8.96291
1868.89	8.72017
1871.87	8.87374
1874.85	8.76873
1877.83	8.87934
1880.81	9.46812
1882.57	9.64826
1885.56	9.11183
1888.55	9.78295
1891.54	10.2275
1894.52	9.91613
1897.51	9.74111
1900.49	9.28401
1903.47	9.40043
1906.45	9.27821
1909.43	8.75949
1912.41	7.80027
1915.39	7.03125
1918.37	7.38245
1921.34	8.19172
1924.32	8.68913
1927.29	8.26345
1930.26	8.59839
1933.23	8.30795
1936.2	7.70983
1939.17	8.71274
1942.14	9.07057
1945.11	8.89427
1948.07	9.00405
1951.04	9.87856
1954	9.96313
1956.96	10.3634
1959.93	10.4678
1962.89	10.1871
1965.85	10.1868
1968.8	9.37801
1971.76	9.88438
1974.72	10.2922
1977.67	9.2455
1980.63	8.92932
1983.58	8.11352
1986.53	8.84349
1989.48	8.71825
1992.43	7.88584
1995.38	7.94377
1998.32	8.69273
2001.27	8.04057
2004.22	8.32744
2007.16	8.12848
2010.1	9.10392
2013.04	9.7209
2015.98	10.0319
2018.92	10.5754
2021.86	11.1257
2024.8	11.1916
2027.74	11.3584
2030.67	11.6644
2033.61	12.0328
2036.54	12.2952
2039.47	12.4433
2042.4	13.432
2045.33	14.201
2048.26	14.9019
2051.19	15.0004
2054.12	15.8014
2057.04	16.2868
2059.97	15.9056
2062.89	15.6944
2065.81	15.8458
2068.73	16.6448
2071.65	15.7762
2074.57	15.1259
2077.49	14.957
2080.41	15.5953
2083.32	15.6314
2086.24	15.757
2089.15	15.3998
2092.07	15.3014
2094.98	15.086
2097.89	15.3748
2100.8	15.3422
2103.71	15.2085
2106.61	16.1472
2109.52	16.7478
2112.43	17.3029
2115.33	17.5082
2118.23	19.1467
2121.13	19.6272
2124.04	20.1523
2126.94	21.8057
2129.83	22.4598
2132.73	23.6043
2135.63	24.1544
2138.53	24.4783
2141.42	25.349
2144.31	26.3892
2147.21	27.218
2150.1	28.6886
2152.99	30.6523
2155.88	32.326
2158.77	33.147
2161.65	33.6695
2164.54	34.9845
2167.43	35.6126
2170.31	35.3351
2173.19	35.6774
2176.07	36.2643
2178.96	36.2686
2181.84	36.492
2184.72	36.1807
2187.59	36.7126
2190.47	36.0306
2193.35	34.5422
2196.22	34.5359
2199.09	33.8524
2201.97	31.9651
2204.84	30.3785
2207.71	28.5082
2210.58	27.6707
2213.45	27.0276
2216.31	25.69
2219.18	23.8148
2222.05	22.4757
2224.91	21.5656
2227.78	20.7396
2230.64	18.9417
2233.5	18.1409
2236.36	17.4616
2239.22	16.526
2242.08	15.9045
2244.93	16.148
2247.79	15.7042
2250.64	15.4946
2253.5	15.665
2256.35	15.255
2259.2	14.3225
2262.05	13.9083
2264.9	13.6557
2267.75	13.1649
2270.6	12.8306
2273.45	13.8716
2276.29	13.7799
2279.14	13.6719
2281.98	13.4842
2284.82	14.2086
2287.66	13.1542
2290.5	12.8581
2293.34	11.4384
2296.18	11.3791
2299.02	11.1024
2301.86	11.7776
2304.69	12.4803
2307.53	12.0478
2310.36	12.1174
2313.19	11.7255
2316.02	12.1436
2318.85	12.152
2321.68	11.5139
2324.51	10.2608
2327.34	9.49615
2330.16	8.81292
2332.99	8.69416
2335.81	8.60169
2338.64	8.51938
2341.46	8.78693
2344.28	8.89713
2347.1	7.62057
2349.92	7.21403
2352.74	6.66361
2355.55	5.31535
2358.37	4.63181
2361.19	3.48215
2364	3.1035
2366.81	3.44876
2369.62	4.28317
2372.44	4.41474
2375.24	3.88408
2378.05	3.3163
2380.86	3.78063
2383.67	3.56434
2386.47	4.25633
2389.28	4.2716
2392.08	3.98703
2394.89	4.09812
2397.69	4.7588
2400.49	4.75228
2403.29	4.91427
2406.09	4.61921
2408.88	4.75579
2411.68	5.47608
2414.48	5.62158
2417.27	5.85462
2420.06	7.08899
2422.86	6.98067
2425.65	7.55526
2428.44	7.79565
2431.23	7.94677
2434.02	8.07016
2436.81	7.39051
2439.59	7.42451
2442.38	6.38995
2445.16	5.85881
2447.95	5.49798
2450.73	5.20923
2453.51	4.8518
2456.29	4.54219
2459.07	3.97228
2461.85	3.45404
2464.63	2.0023
2467.4	1.48924
2470.18	1.41054
2472.95	1.03761
2475.73	0.77115
2478.5	0.525173
2481.27	0.0753739
2484.04	0.193305
2486.81	0.79992
2489.58	0.965815
2492.35	1.15036
2495.12	1.41499
2497.88	0.897151
2500.65	0.370201
2503.41	-0.459271
2506.17	-1.63702
2508.94	-1.27559
2511.7	-1.19053
2514.46	-2.01403
2517.22	-2.1741
2519.97	-1.34522
2522.73	-1.75157
2525.49	-0.891426
2528.24	-0.160244
2530.99	0.0739387
2533.75	0.378578
2536.5	0.904937
2539.25	1.26047
2542	0.860232
2544.75	0.717914
2547.5	1.56806
2550.24	1.82249
2552.99	2.76325
2555.74	3.29095
2558.48	3.20584
2561.22	3.34687
2563.96	3.30931
2566.71	3.13165
2569.45	3.43009
2572.18	4.13633
2574.92	4.54101
2577.66	5.21186
2580.4	4.40165
2583.13	4.11559
2585.87	4.40091
2588.6	4.52193
2591.33	4.1141
2594.06	3.73633
2596.79	3.74451
2599.52	3.22757
2602.25	2.32972
2604.98	2.02416
2607.71	1.39188
2610.43	1.4759
2613.16	0.798341
2615.88	1.02941
2618.6	0.423161
2621.32	0.360864
2624.04	-0.647031
2626.76	-1.12848
2629.48	-1.1543
2632.2	-0.135328
2634.92	-0.0375601
2637.63	0.870486
2640.35	0.819394
2643.06	0.324628
2645.77	0.463217
2648.49	0.59875
2651.2	0.614957
2653.91	-0.132535
2656.62	0.244949
2659.33	0.282905
2662.03	1.02619
2664.74	1.55732
2667.44	1.80803
2670.15	2.4433
2672.85	3.7547
2675.55	3.63047
2678.26	3.47196
2680.96	4.03462
2683.66	4.44661
2686.35	4.80731
2689.05	5.3582
2691.75	5.60204
2694.44	6.72081
2697.14	7.84864
2699.83	8.57808
2702.52	8.58612
2705.22	9.61018
2707.91	9.83282
2710.6	10.5811
2713.29	11.6911
2715.97	11.315
2718.66	11.592
2721.35	12.3401
2724.03	12.7963
2726.72	13.1126
2729.4	13.329
2732.08	14.2105
2734.76	14.1108
2737.44	13.8667
2740.12	13.1308
2742.8	12.7073
2745.48	11.9907
2748.16	12.1076
2750.83	11.5175
2753.51	10.4108
2756.18	9.77853
2758.85	8.70842
2761.53	7.62023
2764.2	7.11573
2766.87	6.66202
2769.54	6.68988
2772.2	6.9542
2774.87	7.48307
2777.54	6.93282
2780.2	6.81193
2782.87	6.66153
2785.53	6.70499
2788.19	6.58998
2790.85	5.98711
2793.51	6.7034
2796.17	7.10616
2798.83	7.51473
2801.49	8.04241
2804.15	8.49781
2806.8	9.01945
2809.46	9.52203
2812.11	9.6993
2814.76	10.5385
2817.42	10.8384
2820.07	11.8639
2822.72	12.6972
2825.37	15.6715
2828.02	18.9054
2830.66	22.5519
2833.31	26.4026
2835.96	30.7414
2838.6	35.2417
2841.24	41.5029
2843.89	47.6458
2846.53	55.113
2849.17	63.8432
2851.81	73.4121
2854.45	84.2131
2857.09	95.8469
2859.72	106.933
2862.36	116.701
2865	127.035
2867.63	135.835
2870.26	144.71
2872.9	152.333
2875.53	158.437
2878.16	164.033
2880.79	168.863
2883.42	172.658
2886.05	177.421
2888.67	183.354
2891.3	188.538
2893.92	193.201
2896.55	198.869
2899.17	205.91
2901.79	214.158
2904.42	223.438
2907.04	234.859
2909.66	247.677
2912.27	261.882
2914.89	276.329
2917.51	289.807
2920.13	301.526
2922.74	311.629
2925.35	319.256
2927.97	323.95
2930.58	326.862
2933.19	327.317
2935.8	325.343
2938.41	320.11
2941.02	312.744
2943.63	304.657
2946.24	294.975
2948.84	284.934
2951.45	274.199
2954.05	262.405
2956.65	250.541
2959.26	238.069
2961.86	226.473
2964.46	214.472
2967.06	204.172
2969.66	195.639
2972.25	186.524
2974.85	177.429
2977.45	168.755
2980.04	159.75
2982.64	150.357
2985.23	139.973
2987.82	130.26
2990.41	119.777
2993	109.331
2995.59	99.5521
2998.18	91.0014
3000.77	82.8801
3003.36	74.8689
3005.94	67.6445
3008.53	60.9883
3011.11	55.4118
3013.69	50.6544
3016.28	46.9301
3018.86	43.4239
3021.44	39.6996
3024.02	37.5559
3026.6	35.8058
3029.18	34.8227
3031.75	34.7191
3034.33	33.8365
3036.9	34.4516
3039.48	35.6167
3042.05	36.9907
3044.62	38.216
3047.19	39.4412
3049.77	40.2956
3052.34	40.1407
3054.9	39.6936
3057.47	39.0571
3060.04	38.5105
3062.61	37.1872
3065.17	35.2817
3067.74	33.686
3070.3	30.035
3072.86	27.8437
3075.42	25.0245
3077.99	22.0842
3080.54	18.5119
3083.1	15.1084
3085.66	12.2444
3088.22	10.0362
3090.78	8.03208
3093.33	5.81693
3095.89	5.02982
3098.44	4.38956
3100.99	4.42933
3103.54	3.92185
3106.1	3.90882
3108.65	3.18986
3111.2	2.95162
3113.74	2.4092
3116.29	1.96082
3118.84	2.28172
3121.38	2.23987
3123.93	1.7026
3126.47	2.21315
3129.01	2.22414
3131.56	1.35052
3134.1	0.543531
3136.64	0.07604
3139.18	-0.245113
3141.72	-0.627253
3144.26	-1.00497
3146.79	-1.02503
3149.33	-1.61216