File: data/Raman/poly_smoothed/Thy_30_10_22_1x_45s_532 nm_x100_100%_600 gr_mm_01.txt
#Acq. time (s)=	45
#Accumulations=	2
#Range (cm-¹)=	200...3150
#Windows=	2
#Auto scanning=	Off
#Autofocus=	Off
#Macrospot=	Off
#AutoExposure=	Off
#Spike filter=	Multiple accum.
#Delay time (s)=	0
#Binning=	1
#Readout mode=	Signal
#DeNoise=	Off
#ICS correction=	On
#Dark correction=	Off
#Inst. Process=	Off
#Detector Gain=	Best Dynamic Range
#Detector ADC=	20 kHz
#Detector temperature (°C)=	-69.85
#Instrument=	LabRAM HR Evol
#Detector=	Synapse
#Objective=	x100
#Grating=	600 gr/mm
#ND Filter=	100%
#Laser (nm)=	532
#Hole=	100.021
#Range=	Auto
#Laser Pol.=	No
#Raman. Pol.=	No
#Laser Pol. (°)=	-0.0007625
#Raman Pol. (°)=	89.9995
#Collection=	Microscope
#StageXY=	Marzhauser
#StageZ=	Marzhauser
#X (µm)=	4770
#Y (µm)=	-7724.9
#Z (µm)=	583.8
#Full time(mm:ss)=	3:18
#Project=
#Sample=
#Site=
#Title=	Thy_30_10_22_2x_45s_532 nm_x100_100%_600 gr_mm
#Remark=
#Date=	30.06.2022 13:02
#Acquired=	30.06.2022 13:02:58
#Base:Fit=	10.08.2022 09:58:11
#Base:Sub=	10.08.2022 09:58:44
#Filter:Polynom=	16.08.2022 10:22:53
#AxisType[0]=Intens
#AxisUnit[0]=Cnt
#AxisType[1]=Spectr
#AxisUnit[1]=1/cm
200.533	23.3204
204.162	19.0908
207.792	17.608
211.418	16.3542
215.044	14.7831
218.667	15.3233
222.289	15.4429
225.912	14.5237
229.531	12.9521
233.148	11.801
236.766	10.2677
240.381	8.89235
243.994	7.9221
247.606	6.81864
251.217	6.67694
254.828	7.44053
258.436	7.34912
262.042	7.21953
265.647	7.37949
269.25	6.83835
272.852	6.02389
276.453	4.55857
280.052	3.47044
283.65	2.75482
287.247	5.08041
290.842	6.89687
294.436	8.03942
298.028	9.23223
301.617	12.3726
305.206	14.4487
308.794	15.2752
312.381	17.8451
315.964	18.769
319.548	18.9093
323.131	17.0562
326.71	16.3564
330.29	15.9403
333.868	15.7705
337.443	14.2211
341.018	14.6253
344.591	15.0168
348.163	13.8038
351.733	13.4403
355.303	10.6312
358.869	8.59083
362.435	7.57344
366.001	6.49789
369.563	5.36171
373.124	6.804
376.686	8.2492
380.244	9.64728
383.801	9.35588
387.357	9.86469
390.911	10.9861
394.466	9.13684
398.018	11.2825
401.568	10.6365
405.117	7.80883
408.664	5.72262
412.21	6.16629
415.755	5.24637
419.298	4.21613
422.84	3.48205
426.38	2.74271
429.919	3.46398
433.455	3.58231
436.992	4.16335
440.527	3.89623
444.06	3.38907
447.593	3.74538
451.122	4.54647
454.651	4.03207
458.18	6.33267
461.705	6.20112
465.23	6.58394
468.752	7.26548
472.275	7.97789
475.797	9.31985
479.315	10.1327
482.834	13.4239
486.349	14.7118
489.863	15.8196
493.378	16.6171
496.889	17.5517
500.401	18.1933
503.91	18.4662
507.417	19.3023
510.923	19.8543
514.43	21.1124
517.933	21.2157
521.435	21.5678
524.936	20.4923
528.435	18.3124
531.933	17.5009
535.43	16.8976
538.927	13.4198
542.421	12.973
545.913	10.8269
549.403	8.91117
552.893	6.54198
556.381	5.77234
559.868	5.48421
563.354	4.69301
566.839	3.46884
570.322	2.76453
573.802	1.00295
577.283	0.425454
580.762	1.00991
584.24	0.96484
587.714	0.440173
591.19	0.600703
594.663	2.60496
598.134	3.29028
601.605	4.8543
605.073	6.15455
608.542	7.5508
612.007	7.93167
615.473	8.25283
618.936	7.44104
622.397	7.30477
625.859	8.803
629.318	9.84388
632.775	8.84821
636.233	9.4791
639.688	9.30551
643.142	10.5769
646.594	9.90566
650.045	11.0182
653.496	10.3658
656.944	11.5418
660.391	11.4928
663.837	12.2036
667.281	12.9702
670.724	12.8658
674.166	13.0562
677.606	14.6015
681.045	15.7329
684.483	16.5495
687.917	18.209
691.352	18.4994
694.786	19.9777
698.219	23.3193
701.65	24.288
705.078	26.352
708.506	28.1923
711.934	30.0783
715.358	32.3972
718.782	34.1951
722.204	36.1147
725.626	38.3459
729.045	41.7973
732.464	43.7084
735.881	45.8322
739.297	47.1405
742.711	48.4763
746.125	51.7674
749.537	55.5061
752.946	58.7355
756.357	63.2701
759.764	66.5569
763.17	68.888
766.575	70.6787
769.978	74.3053
773.382	75.3147
776.783	76.7638
780.182	77.4126
783.581	76.2365
786.978	75.5383
790.373	74.1444
793.768	74.2187
797.161	75.4574
800.552	76.0845
803.941	74.0811
807.33	75.2685
810.718	74.7559
814.105	75.3346
817.49	75.3778
820.873	77.7178
824.256	78.4568
827.637	80.0591
831.016	80.4794
834.395	81.277
837.772	81.4588
841.147	80.6793
844.522	77.5524
847.894	74.7472
851.267	72.4924
854.637	69.5178
858.007	66.9121
861.374	64.0196
864.739	61.0943
868.106	58.9665
871.469	56.7424
874.831	55.379
878.193	53.864
881.553	53.1578
884.911	51.6281
888.268	51.8747
891.623	49.9837
894.978	49.4655
898.331	49.6686
901.683	48.9119
905.033	49.0142
908.383	47.6719
911.731	45.0922
915.078	43.8004
918.423	41.647
921.768	39.9809
925.111	39.9188
928.452	38.068
931.791	37.6947
935.13	36.499
938.468	35.7993
941.803	34.6733
945.139	34.4652
948.473	34.4181
951.804	35.3878
955.136	35.5976
958.465	36.6764
961.794	37.6377
965.12	40.0008
968.447	42.3644
971.771	44.7253
975.095	45.5216
978.417	47.9
981.737	50.5915
985.057	51.3809
988.375	51.0081
991.691	50.6917
995.006	51.9182
998.32	53.3656
1001.63	53.5342
1004.95	54.4734
1008.26	54.7478
1011.56	52.8407
1014.87	50.9519
1018.18	48.707
1021.48	47.5202
1024.79	46.3674
1028.09	45.226
1031.39	43.9045
1034.69	42.4262
1037.99	40.2054
1041.29	37.699
1044.58	36.9881
1047.88	38.3361
1051.17	36.3679
1054.46	33.72
1057.75	31.2937
1061.04	30.5018
1064.33	28.1021
1067.62	26.7624
1070.9	24.1894
1074.19	23.6553
1077.47	23.7325
1080.76	22.6747
1084.04	18.6353
1087.32	18.1413
1090.59	16.6786
1093.87	15.1682
1097.15	14.5573
1100.42	15.1474
1103.69	15.8225
1106.97	15.7027
1110.24	16.0167
1113.51	16.702
1116.77	16.0012
1120.04	17.7839
1123.31	17.6047
1126.57	17.4899
1129.83	17.0101
1133.1	16.7731
1136.36	16.9781
1139.62	16.6665
1142.87	16.7609
1146.13	15.8168
1149.38	12.821
1152.64	11.4629
1155.89	8.30871
1159.14	5.48765
1162.39	2.28274
1165.64	-0.533428
1168.89	-0.248822
1172.14	0.905368
1175.38	0.0673998
1178.63	2.66373
1181.87	2.95095
1185.11	3.15501
1188.35	4.52922
1191.59	6.55488
1194.83	7.80471
1198.07	10.5982
1201.3	13.3511
1204.53	15.3876
1207.77	19.8774
1211	24.8844
1214.23	27.9442
1217.46	31.9629
1220.69	36.0564
1223.91	37.877
1227.14	41.3556
1230.36	44.1502
1233.59	46.8181
1236.81	48.6442
1240.03	51.7924
1243.25	55.8225
1246.46	58.814
1249.68	62.4903
1252.9	65.1693
1256.11	66.5152
1259.32	66.595
1262.54	68.8655
1265.75	69.7232
1268.96	71.0132
1272.16	70.73
1275.37	72.4747
1278.57	74.9541
1281.78	75.607
1284.98	77.0585
1288.18	77.1631
1291.38	77.2104
1294.58	77.6206
1297.78	76.6982
1300.98	77.4825
1304.17	78.0423
1307.37	79.8864
1310.56	81.974
1313.76	82.4273
1316.95	84.1395
1320.14	86.1232
1323.32	86.6695
1326.51	86.707
1329.7	86.1982
1332.88	84.2699
1336.07	83.8117
1339.25	83.87
1342.43	82.4525
1345.61	79.192
1348.79	77.1407
1351.96	73.1726
1355.14	69.8862
1358.31	66.1637
1361.49	61.2566
1364.66	58.3567
1367.83	54.7515
1371	50.697
1374.17	47.5381
1377.34	44.3965
1380.5	40.6893
1383.67	38.8618
1386.83	38.0737
1390	36.4128
1393.16	34.9149
1396.32	34.5623
1399.48	33.5391
1402.64	33.3024
1405.79	32.7653
1408.95	35.3179
1412.1	38.6764
1415.26	42.2381
1418.41	45.4096
1421.56	49.4363
1424.71	55.6288
1427.86	61.1102
1431	67.455
1434.15	73.598
1437.29	79.1664
1440.44	83.6896
1443.58	87.0445
1446.72	89.3487
1449.86	91.5778
1453	92.0958
1456.14	89.9176
1459.27	86.9145
1462.41	83.5116
1465.54	78.0653
1468.67	72.603
1471.81	64.9242
1474.94	56.2148
1478.07	47.7785
1481.19	39.4735
1484.32	32.1716
1487.45	27.1557
1490.57	21.1688
1493.69	16.3266
1496.82	12.8911
1499.94	11.215
1503.06	9.80773
1506.17	7.92821
1509.29	7.25116
1512.41	7.21124
1515.52	7.60841
1518.64	6.85948
1521.75	9.30037
1524.86	11.6524
1527.97	14.1318
1531.08	17.0469
1534.19	19.1817
1537.29	22.541
1540.4	25.8356
1543.5	29.6951
1546.61	33.0379
1549.71	36.1812
1552.81	39.1774
1555.91	43.9029
1559.01	49.1922
1562.11	52.8925
1565.2	56.8462
1568.29	58.3196
1571.39	61.9327
1574.48	64.7412
1577.57	67.755
1580.66	68.7739
1583.75	69.1752
1586.84	69.5914
1589.93	69.1969
1593.01	68.2076
1596.1	67.2829
1599.18	65.734
1602.26	63.6271
1605.34	61.7036
1608.42	59.8661
1611.5	58.0352
1614.58	56.9792
1617.65	57.5582
1620.73	57.8462
1623.8	60.3297
1626.87	62.7887
1629.95	65.582
1633.02	68.6358
1636.09	71.6605
1639.15	75.3062
1642.22	79.8999
1645.29	85.505
1648.35	90.1708
1651.42	94.4429
1654.48	98.5255
1657.54	100.526
1660.6	99.8356
1663.66	99.5364
1666.72	97.4743
1669.77	93.7945
1672.83	88.5364
1675.88	84.4775
1678.93	77.5616
1681.99	70.6913
1685.04	63.2137
1688.09	56.5422
1691.13	49.7235
1694.18	42.858
1697.23	35.4459
1700.27	29.2366
1703.32	23.1929
1706.36	19.749
1709.4	15.084
1712.44	11.1641
1715.48	10.0963
1718.52	8.53861
1721.56	7.20751
1724.59	6.00835
1727.63	6.83888
1730.66	5.59614
1733.69	3.71514
1736.72	2.98819
1739.75	2.8469
1742.78	2.94956
1745.81	2.16567
1748.84	2.03412
1751.86	1.94881
1754.89	1.58061
1757.91	1.30642
1760.93	0.807909
1763.95	0.563938
1766.97	0.648976
1769.99	1.18933
1773.01	1.71549
1776.03	2.90893
1779.04	4.74058
1782.06	6.1004
1785.07	6.58851
1788.08	7.64326
1791.09	9.54129
1794.1	11.381
1797.11	12.3761
1800.12	12.7205
1803.12	12.7803
1806.13	12.2771
1809.13	12.434
1812.14	13.5752
1815.14	14.703
1818.14	14.9847
1821.14	14.3791
1824.14	15.8145
1827.13	17.061
1830.13	17.077
1833.12	17.8341
1836.12	18.4023
1839.11	19.0212
1842.1	19.9366
1845.09	20.889
1848.08	21.808
1851.07	22.4845
1854.06	24.0956
1857.04	24.3403
1860.03	25.3936
1863.01	26.8939
1866	28.2779
1868.98	28.9011
1871.96	28.8122
1874.94	29.765
1877.92	30.7511
1880.89	30.6236
1882.48	29.9428
1885.47	29.739
1888.46	28.9757
1891.44	29.4405
1894.43	30.5693
1897.41	31.0185
1900.4	30.6631
1903.38	30.4366
1906.36	30.8396
1909.34	30.9338
1912.32	31.7983
1915.29	31.1987
1918.27	30.7313
1921.25	30.6857
1924.22	30.7483
1927.2	30.7726
1930.17	31.3019
1933.14	31.3261
1936.11	30.8951
1939.08	31.101
1942.05	30.6326
1945.01	31.402
1947.98	30.3361
1950.94	29.1657
1953.91	28.3366
1956.87	27.3833
1959.83	27.5028
1962.79	26.9699
1965.75	27.6744
1968.71	27.9488
1971.67	27.2781
1974.62	27.9397
1977.58	28.1286
1980.53	28.9285
1983.48	29.4917
1986.43	29.7824
1989.38	29.8789
1992.33	31.456
1995.28	32.2197
1998.23	32.5459
2001.18	32.1651
2004.12	32.7363
2007.06	33.0385
2010.01	33.2672
2012.95	33.5471
2015.89	33.8704
2018.83	34.1221
2021.77	35.1254
2024.71	34.411
2027.64	34.5602
2030.58	33.6122
2033.51	32.9048
2036.45	34.5022
2039.38	34.957
2042.31	35.1244
2045.24	35.4316
2048.17	35.6931
2051.1	35.5634
2054.02	36.5192
2056.95	38.0455
2059.87	38.7784
2062.8	39.0595
2065.72	39.1626
2068.64	38.5531
2071.56	38.9759
2074.48	38.8915
2077.4	39.1641
2080.31	39.3382
2083.23	40.1862
2086.14	41.7501
2089.06	41.7059
2091.97	41.9363
2094.88	42.0971
2097.79	41.7976
2100.7	42.3461
2103.61	43.5042
2106.52	46.0343
2109.43	48.1142
2112.33	51.9078
2115.24	55.5585
2118.14	58.313
2121.04	62.3706
2123.94	67.4367
2126.84	72.5641
2129.74	78.3242
2132.64	81.7774
2135.54	86.1301
2138.43	90.9005
2141.33	95.4173
2144.22	99.5164
2147.11	104.086
2150.01	108.254
2152.9	111.743
2155.79	115.089
2158.67	117.563
2161.56	119.521
2164.45	120.808
2167.33	121.522
2170.22	122.459
2173.1	122.13
2175.98	122.578
2178.86	121.179
2181.74	120.427
2184.62	120.069
2187.5	117.568
2190.38	115.453
2193.25	112.859
2196.13	109.521
2199	105.759
2201.88	102.182
2204.75	97.4879
2207.62	93.0137
2210.49	88.3303
2213.36	84.9595
2216.22	80.324
2219.09	76.0433
2221.96	72.904
2224.82	69.2346
2227.68	66.2568
2230.55	62.5604
2233.41	59.2088
2236.27	56.551
2239.12	54.3451
2241.98	51.2586
2244.84	49.3712
2247.7	46.82
2250.55	45.4846
2253.41	43.3967
2256.26	41.0219
2259.11	39.0393
2261.96	38.24
2264.81	37.6116
2267.66	37.1654
2270.51	36.7241
2273.35	34.9599
2276.2	34.4434
2279.04	33.5005
2281.89	32.744
2284.73	31.1764
2287.57	29.3509
2290.41	28.2489
2293.25	26.7583
2296.09	26.0818
2298.93	26.7632
2301.76	26.9301
2304.6	28.0148
2307.44	27.874
2310.27	26.7044
2313.1	26.6835
2315.93	26.453
2318.76	26.2518
2321.59	24.951
2324.42	23.9836
2327.25	23.5485
2330.07	22.7854
2332.9	23.4876
2335.72	22.0634
2338.55	20.4858
2341.37	20.2365
2344.19	18.874
2347.01	18.3745
2349.83	16.1108
2352.65	15.3539
2355.46	13.87
2358.28	13.801
2361.09	14.0163
2363.91	14.8383
2366.72	16.2701
2369.53	15.0064
2372.34	14.3757
2375.15	13.5298
2377.96	12.6919
2380.77	12.3715
2383.58	12.5814
2386.38	11.8591
2389.19	11.8287
2391.99	11.4185
2394.8	10.1503
2397.6	9.92597
2400.4	9.18156
2403.2	7.43189
2406	7.61407
2408.79	8.14837
2411.59	9.53146
2414.39	8.95538
2417.18	9.9873
2419.98	10.9108
2422.77	12.2083
2425.56	12.4985
2428.35	13.0038
2431.14	13.6515
2433.93	14.6277
2436.72	13.1221
2439.5	13.1915
2442.29	12.5012
2445.07	13.0918
2447.86	12.3172
2450.64	12.5268
2453.42	13.3388
2456.2	12.992
2458.98	11.9982
2461.76	11.2001
2464.54	9.04346
2467.32	8.51411
2470.09	6.90636
2472.87	8.08684
2475.64	8.47894
2478.41	8.21329
2481.18	7.67917
2483.95	6.70733
2486.72	7.9847
2489.49	7.8625
2492.26	8.24154
2495.03	8.0702
2497.79	8.65073
2500.56	7.83697
2503.32	7.43295
2506.09	6.37838
2508.85	6.08736
2511.61	6.45406
2514.37	6.64369
2517.13	6.06725
2519.89	5.31789
2522.64	4.58326
2525.4	3.10654
2528.15	2.62422
2530.91	1.60466
2533.66	1.1056
2536.41	2.05341
2539.16	2.33189
2541.91	1.55417
2544.66	0.727911
2547.41	1.44275
2550.16	1.74567
2552.9	3.104
2555.65	3.44027
2558.39	2.92079
2561.13	3.2103
2563.88	2.62127
2566.62	2.9771
2569.36	3.32645
2572.1	3.62221
2574.84	3.48087
2577.57	3.99956
2580.31	3.45144
2583.05	2.49363
2585.78	1.78338
2588.51	0.958778
2591.24	1.14254
2593.98	0.648164
2596.71	0.100668
2599.44	-0.845337
2602.16	-0.467192
2604.89	-0.761504
2607.62	-2.18633
2610.34	-2.81781
2613.07	-2.38057
2615.79	-2.37855
2618.52	-1.76648
2621.24	-2.56197
2623.96	-1.72305
2626.68	-0.848354
2629.4	-0.759799
2632.11	0.223866
2634.83	1.48739
2637.55	1.19936
2640.26	1.84465
2642.98	2.3725
2645.69	2.60733
2648.4	3.58949
2651.11	4.61512
2653.82	4.96531
2656.53	3.9332
2659.24	2.62882
2661.95	3.58397
2664.65	3.15834
2667.36	3.71269
2670.06	2.43364
2672.76	1.64579
2675.47	0.421156
2678.17	0.902984
2680.87	0.982934
2683.57	1.02015
2686.27	1.36149
2688.97	1.04749
2691.66	1.77875
2694.36	2.62942
2697.05	3.59823
2699.75	4.46948
2702.44	4.6853
2705.13	5.50224
2707.82	6.47606
2710.51	7.36998
2713.2	8.0321
2715.89	8.56315
2718.57	9.28658
2721.26	9.46634
2723.95	11.0396
2726.63	12.0758
2729.31	13.4971
2732	13.4066
2734.68	13.4217
2737.36	12.9826
2740.04	12.3697
2742.72	12.8885
2745.39	12.3649
2748.07	11.2735
2750.75	10.6749
2753.42	9.70715
2756.09	8.80319
2758.77	9.50826
2761.44	8.79478
2764.11	7.50115
2766.78	6.55972
2769.45	4.70643
2772.12	4.11694
2774.78	2.71315
2777.45	1.64878
2780.12	1.84826
2782.78	1.84987
2785.44	1.36068
2788.11	0.821923
2790.77	1.03649
2793.43	1.17774
2796.09	1.00407
2798.75	1.76225
2801.4	1.9404
2804.06	2.79767
2806.72	3.43072
2809.37	4.08144
2812.03	3.42547
2814.68	3.42981
2817.33	4.95225
2819.98	7.99419
2822.63	13.3147
2825.28	18.8792
2827.93	23.4906
2830.58	30.4732
2833.23	36.6313
2835.87	43.1361
2838.52	50.4613
2841.16	57.7866
2843.8	67.24
2846.44	78.1426
2849.08	88.9504
2851.73	100.562
2854.36	112.709
2857	125.527
2859.64	137.266
2862.28	149.277
2864.91	160.713
2867.55	170.522
2870.18	179.133
2872.81	186.448
2875.44	191.783
2878.07	197.112
2880.7	202.645
2883.33	209.115
2885.96	216.064
2888.59	222.335
2891.21	229.109
2893.84	234.588
2896.46	240.793
2899.09	247.393
2901.71	256.259
2904.33	267.416
2906.95	280.542
2909.57	295.275
2912.19	311.735
2914.81	327.93
2917.43	344.03
2920.04	358.413
2922.66	369.914
2925.27	379.931
2927.88	387.169
2930.5	390.653
2933.11	393.29
2935.72	391.215
2938.33	387.522
2940.94	380.223
2943.54	371.79
2946.15	361.438
2948.76	349.207
2951.36	336.364
2953.97	321.823
2956.57	307.019
2959.17	290.233
2961.77	276.188
2964.37	262.234
2966.97	248.498
2969.57	236.244
2972.17	223.894
2974.77	212.88
2977.36	201.4
2979.96	189.437
2982.55	176.73
2985.15	163.998
2987.74	150.658
2990.33	137.882
2992.92	126.279
2995.51	115.564
2998.1	103.983
3000.69	92.4704
3003.27	82.8234
3005.86	74.2779
3008.44	66.7673
3011.03	60.1243
3013.61	54.5744
3016.19	50.3739
3018.78	46.1403
3021.36	42.2045
3023.94	38.5432
3026.51	36.2212
3029.09	33.8306
3031.67	33.7943
3034.24	33.4407
3036.82	33.5789
3039.39	34.1495
3041.97	33.9707
3044.54	34.7805
3047.11	35.5313
3049.68	36.2915
3052.25	36.5239
3054.82	36.0866
3057.39	35.9312
3059.96	34.3872
3062.52	33.2396
3065.09	31.9869
3067.65	31.3422
3070.22	29.2025
3072.78	27.3253
3075.34	25.0052
3077.9	23.0644
3080.46	20.8772
3083.02	16.4824
3085.58	13.401
3088.14	11.4864
3090.69	8.80488
3093.25	7.49911
3095.8	6.83978
3098.36	5.86745
3100.91	3.96341
3103.46	3.01307
3106.01	3.23464
3108.56	3.21221
3111.11	3.37287
3113.66	2.9974
3116.21	1.97693
3118.76	2.27138
3121.3	2.55852
3123.85	1.57313
3126.39	1.55844
3128.93	1.23384
3131.48	1.06698
3134.02	0.350088
3136.56	-0.406004
3139.1	-0.442197
3141.64	-1.05716
3144.17	-1.61888
3146.71	-1.82886
3149.25	-3.07487