File: data/Raman/poly_smoothed/Thy_30_10_24_1x_45s_532 nm_x100_100%_600 gr_mm_01.txt
#Acq. time (s)=	45
#Accumulations=	2
#Range (cm-¹)=	200...3150
#Windows=	2
#Auto scanning=	Off
#Autofocus=	Off
#Macrospot=	Off
#AutoExposure=	Off
#Spike filter=	Multiple accum.
#Delay time (s)=	0
#Binning=	1
#Readout mode=	Signal
#DeNoise=	Off
#ICS correction=	On
#Dark correction=	Off
#Inst. Process=	Off
#Detector Gain=	Best Dynamic Range
#Detector ADC=	20 kHz
#Detector temperature (°C)=	-69.85
#Instrument=	LabRAM HR Evol
#Detector=	Synapse
#Objective=	x100
#Grating=	600 gr/mm
#ND Filter=	100%
#Laser (nm)=	532
#Hole=	100.021
#Range=	Auto
#Laser Pol.=	No
#Raman. Pol.=	No
#Laser Pol. (°)=	-0.0007625
#Raman Pol. (°)=	89.9995
#Collection=	Microscope
#StageXY=	Marzhauser
#StageZ=	Marzhauser
#X (µm)=	4769
#Y (µm)=	-7717.4
#Z (µm)=	584.6
#Full time(mm:ss)=	3:18
#Project=
#Sample=
#Site=
#Title=	Thy_30_10_24_2x_45s_532 nm_x100_100%_600 gr_mm
#Remark=
#Date=	30.06.2022 13:13
#Acquired=	30.06.2022 13:13:30
#Base:Fit=	10.08.2022 09:58:11
#Base:Sub=	10.08.2022 09:58:44
#Filter:Polynom=	16.08.2022 10:22:53
#AxisType[0]=Intens
#AxisUnit[0]=Cnt
#AxisType[1]=Spectr
#AxisUnit[1]=1/cm
200.533	27.1797
204.162	21.6036
207.792	16.6743
211.418	12.2578
215.044	7.63192
218.667	5.8469
222.289	5.1218
225.912	4.00244
229.531	4.30939
233.148	4.84885
236.766	4.15988
240.381	4.00748
243.994	3.90718
247.606	3.56175
251.217	3.48298
254.828	4.16107
258.436	4.16616
262.042	5.21198
265.647	4.80722
269.25	3.74338
272.852	4.45177
276.453	3.71057
280.052	2.09289
283.65	2.38541
287.247	1.11195
290.842	1.2599
294.436	2.28593
298.028	2.22563
301.617	4.2162
305.206	5.83609
308.794	8.17913
312.381	9.2581
315.964	9.92165
319.548	10.564
323.131	10.9673
326.71	10.9653
330.29	12.1794
333.868	12.3881
337.443	11.5337
341.018	11.2925
344.591	11.4626
348.163	11.6898
351.733	10.9329
355.303	10.3428
358.869	9.35213
362.435	8.03585
366.001	6.47687
369.563	5.47472
373.124	5.7369
376.686	6.11131
380.244	7.38886
383.801	7.16529
387.357	7.64663
390.911	8.71167
394.466	7.32144
398.018	6.07561
401.568	5.36534
405.117	5.13719
408.664	5.31777
412.21	4.3557
415.755	4.58805
419.298	4.9762
422.84	4.65781
426.38	4.18438
429.919	5.71446
433.455	5.74667
436.992	6.60123
440.527	6.64111
444.06	5.82404
447.593	4.47227
451.122	4.0968
454.651	4.33679
458.18	4.87863
461.705	6.11676
465.23	6.78687
468.752	7.38642
472.275	7.23132
475.797	7.50219
479.315	6.99403
482.834	6.69005
486.349	9.13874
489.863	10.3493
493.378	10.7204
496.889	12.0197
500.401	12.737
503.91	13.2852
507.417	13.9207
510.923	14.9054
514.43	16.2021
517.933	17.4178
521.435	16.7385
524.936	16.6709
528.435	16.2465
531.933	15.1784
535.43	15.7351
538.927	15.8108
542.421	14.9037
545.913	13.973
549.403	13.4776
552.893	12.1078
556.381	9.8737
559.868	8.04325
563.354	6.60461
566.839	5.51583
570.322	5.11852
573.802	5.14385
577.283	4.08084
580.762	3.75008
584.24	2.84469
587.714	2.4216
591.19	1.67472
594.663	1.26671
598.134	0.995834
601.605	2.19823
605.073	2.61565
608.542	3.05578
612.007	5.24921
615.473	6.5255
618.936	7.29358
622.397	9.32896
625.859	10.1871
629.318	9.98639
632.775	11.0615
636.233	12.2215
639.688	12.0747
643.142	12.6785
646.594	13.4012
650.045	14.9468
653.496	15.469
656.944	16.0552
660.391	17.1506
663.837	16.4911
667.281	16.4842
670.724	16.5614
674.166	14.9322
677.606	15.3677
681.045	16.4894
684.483	17.532
687.917	18.8827
691.352	20.2281
694.786	20.4206
698.219	21.8655
701.65	21.8155
705.078	23.3676
708.506	25.383
711.934	25.785
715.358	26.7398
718.782	30.2267
722.204	32.746
725.626	35.6478
729.045	36.5457
732.464	38.7847
735.881	41.6974
739.297	43.2084
742.711	45.9815
746.125	49.5236
749.537	52.5694
752.946	56.6193
756.357	60.6833
759.764	63.6318
763.17	66.1093
766.575	67.8939
769.978	70.2509
773.382	71.184
776.783	72.1533
780.182	72.7611
783.581	73.252
786.978	73.7978
790.373	74.4657
793.768	73.7002
797.161	72.518
800.552	73.6086
803.941	72.2381
807.33	71.2116
810.718	70.7132
814.105	71.33
817.49	71.8167
820.873	72.2099
824.256	73.669
827.637	73.5406
831.016	75.3769
834.395	74.7987
837.772	72.3727
841.147	70.0899
844.522	66.6432
847.894	65.2996
851.267	63.253
854.637	60.8393
858.007	57.9014
861.374	56.7539
864.739	54.6932
868.106	52.374
871.469	51.3865
874.831	50.1298
878.193	48.4133
881.553	48.303
884.911	47.7956
888.268	48.0852
891.623	49.8056
894.978	49.1301
898.331	49.1207
901.683	48.0987
905.033	46.804
908.383	45.602
911.731	44.4446
915.078	44.8005
918.423	41.9802
921.768	39.5462
925.111	39.3676
928.452	38.8627
931.791	37.5756
935.13	36.5186
938.468	34.4329
941.803	33.6336
945.139	33.5786
948.473	35.4137
951.804	37.6435
955.136	39.3947
958.465	41.5567
961.794	42.1847
965.12	43.9991
968.447	45.4447
971.771	47.4344
975.095	46.9915
978.417	48.5253
981.737	47.8654
985.057	48.1103
988.375	47.821
991.691	47.37
995.006	48.6743
998.32	47.8841
1001.63	46.5172
1004.95	45.2218
1008.26	44.3767
1011.56	43.1195
1014.87	41.1504
1018.18	39.681
1021.48	38.0209
1024.79	40.2713
1028.09	39.3671
1031.39	39.4082
1034.69	39.003
1037.99	39.3934
1041.29	38.2136
1044.58	37.0723
1047.88	37.6064
1051.17	36.9909
1054.46	35.4383
1057.75	33.3929
1061.04	31.4736
1064.33	29.418
1067.62	28.7227
1070.9	27.4841
1074.19	25.9052
1077.47	25.0894
1080.76	23.2269
1084.04	22.0187
1087.32	20.4488
1090.59	20.2762
1093.87	19.6385
1097.15	19.6854
1100.42	19.9296
1103.69	20.3339
1106.97	20.5617
1110.24	19.6744
1113.51	20.835
1116.77	20.627
1120.04	19.6086
1123.31	17.3293
1126.57	16.0175
1129.83	14.6167
1133.1	11.714
1136.36	10.9627
1139.62	9.69823
1142.87	8.89009
1146.13	7.68221
1149.38	5.11623
1152.64	3.2969
1155.89	1.16398
1159.14	0.301643
1162.39	0.328243
1165.64	0.205221
1168.89	0.414404
1172.14	1.95316
1175.38	4.07819
1178.63	4.43248
1181.87	5.05227
1185.11	6.37985
1188.35	7.96019
1191.59	9.12239
1194.83	10.4694
1198.07	12.3144
1201.3	13.9916
1204.53	16.9944
1207.77	18.5734
1211	21.1951
1214.23	23.4766
1217.46	26.4837
1220.69	28.4707
1223.91	30.7596
1227.14	32.9431
1230.36	35.3108
1233.59	37.553
1236.81	39.172
1240.03	41.4368
1243.25	42.6961
1246.46	43.3904
1249.68	47.0219
1252.9	48.6633
1256.11	47.8643
1259.32	49.1055
1262.54	49.9158
1265.75	50.2239
1268.96	51.7368
1272.16	52.1066
1275.37	53.2315
1278.57	54.6806
1281.78	55.6228
1284.98	55.61
1288.18	56.3533
1291.38	56.1004
1294.58	56.6647
1297.78	57.0981
1300.98	57.7102
1304.17	58.2379
1307.37	58.0918
1310.56	57.2473
1313.76	57.585
1316.95	56.5562
1320.14	56.8117
1323.32	56.718
1326.51	56.9248
1329.7	56.985
1332.88	56.5061
1336.07	55.1102
1339.25	54.1491
1342.43	52.9149
1345.61	52.4392
1348.79	50.2068
1351.96	49.7758
1355.14	48.6819
1358.31	46.9682
1361.49	45.1798
1364.66	42.7461
1367.83	40.2067
1371	39.084
1374.17	37.0967
1377.34	34.9776
1380.5	33.1892
1383.67	30.0421
1386.83	29.4125
1390	28.9344
1393.16	26.977
1396.32	26.6083
1399.48	25.2287
1402.64	25.5397
1405.79	25.2539
1408.95	25.453
1412.1	26.1067
1415.26	27.1081
1418.41	28.7759
1421.56	30.9553
1424.71	34.7595
1427.86	40.3556
1431	44.8603
1434.15	47.9238
1437.29	51.6588
1440.44	55.1441
1443.58	56.6392
1446.72	58.0611
1449.86	57.3012
1453	57.0271
1456.14	56.6289
1459.27	55.4647
1462.41	52.5296
1465.54	50.1856
1468.67	46.6667
1471.81	42.0902
1474.94	37.2329
1478.07	33.4174
1481.19	28.3988
1484.32	24.2386
1487.45	18.3461
1490.57	15.555
1493.69	14.1062
1496.82	12.6573
1499.94	12.1381
1503.06	12.1367
1506.17	11.1383
1509.29	10.4734
1512.41	10.9392
1515.52	8.7301
1518.64	8.26985
1521.75	10.3128
1524.86	12.3432
1527.97	15.0518
1531.08	17.7928
1534.19	19.9613
1537.29	21.3406
1540.4	24.7383
1543.5	26.6394
1546.61	29.7875
1549.71	33.7375
1552.81	38.9052
1555.91	41.1494
1559.01	42.5738
1562.11	44.3828
1565.2	46.9315
1568.29	49.889
1571.39	51.6159
1574.48	53.2507
1577.57	52.8279
1580.66	53.0235
1583.75	53.6603
1586.84	53.0472
1589.93	51.0939
1593.01	50.4271
1596.1	53.2008
1599.18	52.0836
1602.26	50.7121
1605.34	48.7623
1608.42	45.9592
1611.5	44.9939
1614.58	43.6236
1617.65	44.1397
1620.73	45.4027
1623.8	47.6385
1626.87	49.0484
1629.95	49.9609
1633.02	50.804
1636.09	52.6418
1639.15	54.8623
1642.22	58.794
1645.29	60.4768
1648.35	61.8849
1651.42	63.8284
1654.48	65.2174
1657.54	67.7081
1660.6	67.9539
1663.66	66.8734
1666.72	65.9067
1669.77	63.8305
1672.83	60.5205
1675.88	56.217
1678.93	50.8413
1681.99	46.8119
1685.04	43.2628
1688.09	38.4111
1691.13	33.7433
1694.18	30.2827
1697.23	26.1826
1700.27	22.9033
1703.32	19.8361
1706.36	15.8226
1709.4	13.3556
1712.44	10.8235
1715.48	8.63366
1718.52	7.0801
1721.56	5.5806
1724.59	4.73636
1727.63	5.1112
1730.66	4.38033
1733.69	3.24645
1736.72	2.94521
1739.75	1.68902
1742.78	1.29945
1745.81	0.996764
1748.84	0.478913
1751.86	-0.350088
1754.89	0.0788091
1757.91	0.0157066
1760.93	0.0286791
1763.95	-0.654845
1766.97	-0.774681
1769.99	0.555024
1773.01	1.14772
1776.03	1.80443
1779.04	2.08244
1782.06	1.08897
1785.07	0.957806
1788.08	1.03663
1791.09	1.19541
1794.1	0.837841
1797.11	0.711876
1800.12	0.322255
1803.12	-0.403921
1806.13	-0.912464
1809.13	-1.02209
1812.14	-1.06296
1815.14	-0.546625
1818.14	0.302347
1821.14	0.848392
1824.14	1.48772
1827.13	2.05664
1830.13	1.78288
1833.12	2.38662
1836.12	3.64133
1839.11	4.55608
1842.1	5.21552
1845.09	5.78317
1848.08	6.00848
1851.07	5.94032
1854.06	5.80268
1857.04	6.23448
1860.03	6.00927
1863.01	6.15652
1866	5.42115
1868.98	4.95716
1871.96	3.82573
1874.94	3.31363
1877.92	3.81316
1880.89	3.7477
1882.48	4.30931
1885.47	4.50363
1888.46	5.80148
1891.44	6.56298
1894.43	6.41654
1897.41	6.81189
1900.4	6.02954
1903.38	6.32032
1906.36	7.03981
1909.34	7.82578
1912.32	7.2248
1915.29	8.04107
1918.27	8.66676
1921.25	8.00989
1924.22	8.54029
1927.2	8.93606
1930.17	7.98893
1933.14	7.60403
1936.11	6.76217
1939.08	5.96978
1942.05	5.60616
1945.01	5.54573
1947.98	6.38006
1950.94	6.97211
1953.91	6.61706
1956.87	6.99255
1959.83	7.09086
1962.79	7.17267
1965.75	7.55939
1968.71	7.54109
1971.67	7.71034
1974.62	7.81465
1977.58	9.28507
1980.53	9.6211
1983.48	9.25129
1986.43	9.26624
1989.38	9.47618
1992.33	8.5641
1995.28	8.57513
1998.23	8.7314
2001.18	8.09915
2004.12	7.63274
2007.06	8.07607
2010.01	8.31842
2012.95	8.36839
2015.89	8.37583
2018.83	8.59434
2021.77	9.76353
2024.71	9.16813
2027.64	9.52361
2030.58	9.87611
2033.51	11.2477
2036.45	12.2333
2039.38	13.0107
2042.31	13.571
2045.24	14.0506
2048.17	13.8341
2051.1	14.1758
2054.02	13.7647
2056.95	13.7809
2059.87	14.5282
2062.8	14.0447
2065.72	14.7346
2068.64	14.3274
2071.56	14.8387
2074.48	15.758
2077.4	17.1469
2080.31	17.891
2083.23	19.4275
2086.14	20.8139
2089.06	21.7234
2091.97	23.3954
2094.88	25.2248
2097.79	27.103
2100.7	27.855
2103.61	29.5276
2106.52	30.7594
2109.43	32.8616
2112.33	33.7912
2115.24	34.7948
2118.14	35.9066
2121.04	37.4611
2123.94	39.2123
2126.84	41.2676
2129.74	43.8037
2132.64	45.0148
2135.54	46.4686
2138.43	49.0204
2141.33	52.1914
2144.22	55.6255
2147.11	58.8654
2150.01	62.1921
2152.9	65.3308
2155.79	68.874
2158.67	71.6208
2161.56	74.4023
2164.45	76.3013
2167.33	78.261
2170.22	80.1051
2173.1	81.4384
2175.98	81.6195
2178.86	81.2718
2181.74	79.9458
2184.62	77.9995
2187.5	75.5385
2190.38	74.1652
2193.25	71.6085
2196.13	69.2319
2199	66.0147
2201.88	62.6849
2204.75	59.3568
2207.62	56.4309
2210.49	53.6612
2213.36	50.7055
2216.22	47.9614
2219.09	45.7974
2221.96	42.6078
2224.82	40.2052
2227.68	37.9197
2230.55	36.2598
2233.41	34.7255
2236.27	34.2697
2239.12	32.9214
2241.98	32.6262
2244.84	30.8833
2247.7	30.4686
2250.55	29.1385
2253.41	27.4736
2256.26	26.8054
2259.11	25.6153
2261.96	25.08
2264.81	24.4187
2267.66	23.5495
2270.51	23.8036
2273.35	23.2471
2276.2	22.6686
2279.04	21.9712
2281.89	20.8469
2284.73	19.4828
2287.57	19.0862
2290.41	17.7325
2293.25	15.8972
2296.09	16.1276
2298.93	15.9817
2301.76	16.6044
2304.6	17.4233
2307.44	18.3773
2310.27	19.4402
2313.1	19.6029
2315.93	19.617
2318.76	18.7864
2321.59	18.3311
2324.42	17.4974
2327.25	17.3005
2330.07	17.2604
2332.9	17.3193
2335.72	17.0179
2338.55	15.902
2341.37	15.1899
2344.19	13.5744
2347.01	12.3388
2349.83	11.3068
2352.65	10.0967
2355.46	9.14224
2358.28	8.3999
2361.09	7.87903
2363.91	7.92158
2366.72	8.4583
2369.53	9.13055
2372.34	10.0898
2375.15	10.2061
2377.96	9.86405
2380.77	9.65339
2383.58	8.68372
2386.38	9.13405
2389.19	9.43795
2391.99	9.76388
2394.8	9.53265
2397.6	9.66701
2400.4	9.52006
2403.2	9.80345
2406	9.25596
2408.79	9.70718
2411.59	9.41932
2414.39	8.7443
2417.18	8.4985
2419.98	7.93743
2422.77	7.18144
2425.56	6.43584
2428.35	5.41137
2431.14	5.09129
2433.93	4.49975
2436.72	4.53098
2439.5	3.9379
2442.29	3.5919
2445.07	3.01948
2447.86	2.69925
2450.64	2.37464
2453.42	2.53545
2456.2	2.42153
2458.98	3.00555
2461.76	3.02943
2464.54	3.37472
2467.32	3.14621
2470.09	4.41492
2472.87	5.22875
2475.64	5.57734
2478.41	5.65857
2481.18	5.32727
2483.95	5.67388
2486.72	5.28942
2489.49	5.45323
2492.26	5.40037
2495.03	5.00421
2497.79	5.24885
2500.56	5.13391
2503.32	5.15657
2506.09	4.99309
2508.85	5.24374
2511.61	4.91324
2514.37	4.37798
2517.13	4.16576
2519.89	3.72664
2522.64	3.80244
2525.4	3.7828
2528.15	3.29062
2530.91	2.76708
2533.66	1.93788
2536.41	1.61104
2539.16	1.59523
2541.91	2.01562
2544.66	1.48085
2547.41	1.17775
2550.16	1.00042
2552.9	1.68535
2555.65	1.9754
2558.39	1.97121
2561.13	2.21905
2563.88	2.18371
2566.62	2.35701
2569.36	3.26673
2572.1	3.74679
2574.84	4.36541
2577.57	4.68409
2580.31	4.28214
2583.05	4.02402
2585.78	4.10099
2588.51	4.50298
2591.24	4.3822
2593.98	3.80473
2596.71	2.14641
2599.44	1.32065
2602.16	0.562605
2604.89	-0.673095
2607.62	-0.611787
2610.34	-1.69401
2613.07	-2.03373
2615.79	-2.23344
2618.52	-2.40029
2621.24	-1.84833
2623.96	-1.59321
2626.68	-1.32431
2629.4	-0.475974
2632.11	-0.450129
2634.83	-0.368571
2637.55	0.639348
2640.26	0.884654
2642.98	0.718184
2645.69	1.02958
2648.4	2.51403
2651.11	3.27331
2653.82	4.1269
2656.53	4.82743
2659.24	4.3719
2661.95	4.56873
2664.65	4.36279
2667.36	4.2365
2670.06	3.59844
2672.76	3.01841
2675.47	2.67218
2678.17	2.44793
2680.87	2.30173
2683.57	2.86525
2686.27	3.01621
2688.97	2.65007
2691.66	1.90997
2694.36	1.64814
2697.05	2.49464
2699.75	1.91865
2702.44	3.14976
2705.13	4.52632
2707.82	5.80014
2710.51	6.3824
2713.2	8.06937
2715.89	8.60125
2718.57	8.40188
2721.26	9.09942
2723.95	9.82978
2726.63	10.2578
2729.31	10.7398
2732	10.4117
2734.68	10.6618
2737.36	10.3203
2740.04	10.1412
2742.72	9.60062
2745.39	9.36413
2748.07	9.0372
2750.75	8.06573
2753.42	7.64376
2756.09	6.73798
2758.77	6.88891
2761.44	5.98904
2764.11	5.96099
2766.78	6.59959
2769.45	7.12787
2772.12	7.53587
2774.78	6.55823
2777.45	5.8181
2780.12	5.78901
2782.78	4.74779
2785.44	4.35367
2788.11	4.76947
2790.77	5.14363
2793.43	4.72599
2796.09	5.35459
2798.75	4.9929
2801.4	4.8369
2804.06	5.37984
2806.72	5.11912
2809.37	4.96173
2812.03	5.08288
2814.68	4.74741
2817.33	5.58016
2819.98	5.93152
2822.63	7.90329
2825.28	10.3554
2827.93	13.4669
2830.58	17.5371
2833.23	21.2021
2835.87	24.5598
2838.52	28.7087
2841.16	32.6662
2843.8	37.6581
2846.44	43.824
2849.08	50.9237
2851.73	58.7213
2854.36	66.8743
2857	74.9438
2859.64	83.2869
2862.28	91.4688
2864.91	97.9542
2867.55	103.909
2870.18	109.88
2872.81	114.697
2875.44	118.638
2878.07	122.583
2880.7	126.314
2883.33	129.529
2885.96	134.011
2888.59	138.749
2891.21	143.233
2893.84	147.232
2896.46	151.17
2899.09	156.373
2901.71	162.15
2904.33	169.764
2906.95	178.467
2909.57	189.895
2912.19	201.046
2914.81	211.89
2917.43	222.834
2920.04	232.999
2922.66	241.224
2925.27	247.487
2927.88	252.814
2930.5	255.403
2933.11	256.493
2935.72	254.975
2938.33	252.607
2940.94	247.881
2943.54	243.51
2946.15	236.606
2948.76	229.263
2951.36	220.491
2953.97	211.614
2956.57	202.417
2959.17	191.938
2961.77	183.588
2964.37	174.976
2966.97	166.6
2969.57	159.402
2972.17	151.888
2974.77	145.07
2977.36	137.172
2979.96	130.098
2982.55	121.934
2985.15	113.227
2987.74	104.296
2990.33	96.1619
2992.92	88.9567
2995.51	80.2866
2998.1	72.5873
3000.69	65.5969
3003.27	59.4031
3005.86	54.4779
3008.44	48.7804
3011.03	43.4254
3013.61	38.7359
3016.19	34.7901
3018.78	32.7574
3021.36	29.7702
3023.94	28.0083
3026.51	26.8618
3029.09	25.851
3031.67	25.3158
3034.24	25.2904
3036.82	25.9313
3039.39	26.5181
3041.97	27.563
3044.54	28.4637
3047.11	29.4463
3049.68	30.3414
3052.25	30.4184
3054.82	30.9116
3057.39	30.5553
3059.96	30.1328
3062.52	29.573
3065.09	29.2736
3067.65	28.3104
3070.22	26.4924
3072.78	24.2457
3075.34	22.5773
3077.9	20.36
3080.46	19.0968
3083.02	17.0287
3085.58	15.2433
3088.14	13.0873
3090.69	11.6981
3093.25	10.2237
3095.8	8.76768
3098.36	8.60115
3100.91	8.39237
3103.46	8.71932
3106.01	8.793
3108.56	8.54981
3111.11	8.86807
3113.66	8.4884
3116.21	9.02532
3118.76	8.46275
3121.3	8.41991
3123.85	8.91847
3126.39	8.23598
3128.93	7.91422
3131.48	7.36467
3134.02	6.53154
3136.56	5.96752
3139.1	4.96593
3141.64	3.02355
3144.17	0.619339
3146.71	-2.22107
3149.25	-5.97738