File: data/Raman/poly_smoothed/Thy_00_07_32_1x_45s_532 nm_x100_100%_600 gr_mm_01.txt
#Acq. time (s)=	45
#Accumulations=	2
#Range (cm-¹)=	200...3150
#Windows=	2
#Auto scanning=	Off
#Autofocus=	Off
#Macrospot=	Off
#AutoExposure=	Off
#Spike filter=	Multiple accum.
#Delay time (s)=	0
#Binning=	1
#Readout mode=	Signal
#DeNoise=	Off
#ICS correction=	On
#Dark correction=	Off
#Inst. Process=	Off
#Detector Gain=	Best Dynamic Range
#Detector ADC=	20 kHz
#Detector temperature (°C)=	-69.85
#Instrument=	LabRAM HR Evol
#Detector=	Synapse
#Objective=	x100
#Grating=	600 gr/mm
#ND Filter=	100%
#Laser (nm)=	532
#Hole=	100.021
#Range=	Auto
#Laser Pol.=	No
#Raman. Pol.=	No
#Laser Pol. (°)=	-0.0007625
#Raman Pol. (°)=	89.9995
#Collection=	Microscope
#StageXY=	Marzhauser
#StageZ=	Marzhauser
#X (µm)=	8977
#Y (µm)=	-3072.6
#Z (µm)=	-54.85
#Full time(mm:ss)=	3:19
#Project=
#Sample=
#Site=
#Title=	Thy_00_07_32_2x_45s_532 nm_x100_100%_600 gr_mm
#Remark=
#Date=	28.06.2022 12:26
#Acquired=	28.06.2022 12:26:42
#Base:Fit=	10.08.2022 10:07:56
#Base:Sub=	10.08.2022 10:08:40
#Filter:Polynom=	16.08.2022 10:26:06
#AxisType[0]=Intens
#AxisUnit[0]=Cnt
#AxisType[1]=Spectr
#AxisUnit[1]=1/cm
200.407	5.90269
204.035	7.09507
207.665	10.0112
211.291	11.3964
214.916	11.9549
218.541	12.3084
222.163	11.3415
225.785	10.4171
229.404	10.5
233.022	9.00782
236.638	7.99839
240.255	8.27338
243.868	7.54235
247.48	5.35503
251.091	4.16027
254.702	3.4186
258.31	3.0072
261.916	2.60559
265.521	1.81612
269.125	2.37236
272.727	0.190402
276.328	-0.0262275
279.927	-0.371117
283.525	-0.919147
287.121	1.20803
290.716	2.29606
294.31	2.81759
297.9	3.31828
301.491	5.88645
305.081	7.79385
308.669	7.48136
312.256	7.29798
315.839	8.47899
319.423	10.3497
323.006	11.117
326.585	11.2524
330.165	12.6724
333.741	12.3583
337.318	12.4454
340.894	13.3666
344.466	13.5811
348.039	12.906
351.608	12.1348
355.176	11.1945
358.745	9.30675
362.31	7.89796
365.876	7.39082
369.439	6.97128
373	7.49235
376.56	6.19156
380.12	5.70859
383.677	7.04851
387.233	6.67467
390.787	6.67716
394.34	5.54563
397.894	5.19093
401.444	6.64772
404.993	8.8134
408.54	8.01626
412.086	9.0684
415.631	9.10442
419.174	8.92987
422.716	9.27925
426.257	9.21207
429.794	8.53714
433.332	8.0229
436.868	7.05653
440.403	6.91636
443.937	6.73808
447.468	6.86773
450.999	7.73835
454.528	7.92149
458.057	9.24352
461.582	9.86208
465.107	8.91991
468.629	10.5869
472.152	12.3559
475.672	13.0638
479.192	14.5895
482.709	17.6792
486.226	19.5611
489.74	21.8731
493.255	22.5643
496.767	23.7523
500.277	24.0883
503.788	25.7813
507.295	25.1589
510.801	24.2668
514.308	23.0643
517.811	20.4032
521.313	19.0345
524.814	18.1891
528.313	18.0424
531.811	17.4164
535.308	16.8827
538.803	16.836
542.297	15.9584
545.789	15.8197
549.281	15.3534
552.771	14.2889
556.259	13.1072
559.747	13.2774
563.233	13.1272
566.717	12.6686
570.2	13.637
573.68	12.1217
577.161	11.2444
580.64	11.3701
584.118	10.611
587.593	9.51358
591.068	7.90611
594.54	6.29283
598.013	5.5384
601.484	4.12665
604.952	3.70509
608.421	3.72626
611.886	4.44061
615.35	5.48202
618.815	6.41378
622.276	7.20843
625.738	7.4396
629.197	6.48411
632.655	6.25429
636.113	5.23975
639.568	4.99825
643.021	5.07193
646.473	5.67453
649.924	5.30041
653.376	4.62083
656.824	5.34745
660.271	4.8499
663.716	5.17905
667.161	5.3116
670.604	5.40185
674.045	5.72989
677.486	6.35503
680.925	8.70434
684.361	10.9956
687.797	13.9292
691.232	16.2396
694.666	18.3391
698.099	20.7637
701.528	22.3171
704.958	22.6373
708.387	23.8125
711.814	23.8664
715.238	24.9616
718.663	26.3976
722.084	27.0913
725.506	27.909
728.925	28.492
732.345	30.0457
735.761	30.6198
739.178	32.3466
742.592	33.8769
746.006	36.7174
749.417	39.3154
752.827	42.6404
756.236	45.9852
759.645	50.3996
763.051	54.7361
766.456	58.8807
769.859	62.2068
773.261	65.7879
776.664	68.2525
780.064	70.4835
783.462	70.5498
786.859	71.4433
790.255	71.8159
793.649	72.989
797.042	72.3348
800.434	75.1718
803.823	73.3767
807.212	71.982
810.6	70.5568
813.987	68.3449
817.372	66.4873
820.754	64.8785
824.137	64.9944
827.519	65.7525
830.897	66.7373
834.276	66.5992
837.654	64.0894
841.029	62.6238
844.404	61.7031
847.776	60.3367
851.149	57.227
854.519	55.3469
857.889	53.5338
861.256	50.5139
864.622	47.4261
867.988	45.4496
871.351	43.3179
874.713	41.1812
878.074	39.6242
881.435	38.3521
884.794	36.2085
888.15	31.7294
891.506	29.285
894.861	26.8848
898.214	27.0074
901.566	29.0033
904.916	29.728
908.266	32.3079
911.614	32.7028
914.961	33.5517
918.306	33.9231
921.651	34.5428
924.994	35.137
928.336	35.5255
931.674	36.0179
935.014	34.7493
938.352	34.3506
941.687	33.778
945.022	33.5016
948.357	33.2036
951.688	32.3924
955.02	30.5554
958.348	28.2475
961.678	26.1395
965.004	25.0574
968.331	25.2527
971.655	27.0394
974.979	30.0842
978.3	30.9808
981.62	33.2149
984.941	34.7147
988.259	35.6418
991.575	36.219
994.89	37.1528
998.204	38.5998
1001.52	39.6172
1004.83	39.7225
1008.14	40.1635
1011.45	40.634
1014.76	40.8683
1018.06	39.4283
1021.37	37.9662
1024.67	37.0648
1027.97	33.7592
1031.27	30.8522
1034.57	28.4964
1037.87	25.8238
1041.17	22.8069
1044.47	21.4718
1047.76	21.8625
1051.06	21.8609
1054.35	20.8575
1057.64	19.6197
1060.93	17.7929
1064.22	16.4453
1067.5	16.8866
1070.79	16.3701
1074.08	16.846
1077.36	17.3405
1080.64	18.1763
1083.92	17.9741
1087.2	18.9854
1090.48	19.5253
1093.76	20.0531
1097.03	20.3687
1100.31	21.0756
1103.58	20.9082
1106.85	19.7912
1110.12	19.359
1113.39	19.0719
1116.66	17.2295
1119.93	16.4983
1123.19	13.7147
1126.46	12.9164
1129.72	11.9439
1132.98	10.7301
1136.24	10.0426
1139.5	9.17367
1142.76	8.8485
1146.01	7.89938
1149.27	8.25537
1152.53	4.83085
1155.78	3.97611
1159.03	2.37124
1162.28	1.11643
1165.53	1.67663
1168.78	1.55605
1172.02	2.94858
1175.27	4.79285
1178.51	7.02396
1181.76	8.75908
1185	9.54524
1188.24	9.56625
1191.48	10.4956
1194.71	12.7686
1197.95	13.621
1201.19	14.7186
1204.42	16.3669
1207.65	19.0305
1210.88	23.4029
1214.12	27.2353
1217.35	30.6811
1220.57	35.5661
1223.8	38.5934
1227.03	41.0454
1230.25	43.8396
1233.47	45.1059
1236.69	46.7324
1239.92	48.4033
1243.13	49.958
1246.35	51.5093
1249.57	51.9424
1252.78	51.3303
1256	50.1251
1259.21	48.3568
1262.42	47.1595
1265.63	45.2503
1268.84	45.1223
1272.05	43.9444
1275.26	43.0828
1278.46	43.6755
1281.67	45.0069
1284.87	47.9896
1288.07	51.1006
1291.27	53.8697
1294.47	56.7495
1297.67	59.7537
1300.87	63.0771
1304.06	65.5387
1307.26	69.1825
1310.45	71.028
1313.64	74.3326
1316.83	76.0939
1320.02	78.5728
1323.21	78.1537
1326.4	77.8763
1329.59	76.6864
1332.77	76.0218
1335.95	75.9654
1339.14	75.4115
1342.32	74.9937
1345.5	72.4474
1348.67	70.7149
1351.85	69.0223
1355.03	68.3409
1358.2	64.7641
1361.38	63.6348
1364.55	60.5896
1367.72	57.8203
1370.89	56.1353
1374.06	54.4882
1377.23	52.7737
1380.39	50.8936
1383.56	51.0119
1386.72	50.9066
1389.89	51.601
1393.05	51.2765
1396.21	50.3821
1399.37	49.8021
1402.52	48.091
1405.68	47.3275
1408.84	48.5714
1411.99	50.636
1415.15	52.6128
1418.3	53.7909
1421.45	58.1109
1424.6	61.7206
1427.75	66.2237
1430.89	71.7078
1434.04	76.1492
1437.18	80.9281
1440.33	84.3959
1443.47	86.3357
1446.61	89.3359
1449.75	90.0326
1452.89	91.9831
1456.03	91.1417
1459.16	89.3048
1462.3	85.4507
1465.43	80.6565
1468.56	74.0717
1471.7	67.042
1474.83	59.8056
1477.96	52.8238
1481.08	45.7273
1484.21	40.0173
1487.34	34.6615
1490.46	27.2057
1493.58	22.5708
1496.71	18.8808
1499.83	16.0214
1502.95	13.094
1506.07	10.696
1509.18	9.66647
1512.3	9.79318
1515.41	8.28063
1518.53	7.64834
1521.64	9.05537
1524.75	11.3451
1527.86	12.8377
1530.97	13.6186
1534.08	13.708
1537.19	14.6446
1540.29	16.4245
1543.4	20.4684
1546.5	23.3619
1549.6	27.1849
1552.7	31.1365
1555.8	35.1681
1558.9	39.3157
1562	42.7354
1565.09	45.6494
1568.19	47.1905
1571.28	50.4314
1574.37	52.4841
1577.47	54.5626
1580.56	58.097
1583.64	60.118
1586.73	63.0135
1589.82	64.6078
1592.9	65.4143
1595.99	67.2905
1599.07	67.7163
1602.15	68.0986
1605.23	66.0797
1608.31	65.4086
1611.39	64.2615
1614.47	63.85
1617.55	64.1348
1620.62	62.8946
1623.7	62.971
1626.77	62.5372
1629.84	64.0383
1632.91	64.8349
1635.98	67.5187
1639.05	68.7508
1642.11	70.2853
1645.18	73.865
1648.24	76.722
1651.31	78.4994
1654.37	80.7648
1657.43	82.0362
1660.49	82.7412
1663.55	83.5741
1666.61	82.4511
1669.66	80.6506
1672.72	78.3014
1675.77	74.3588
1678.83	70.1344
1681.88	65.3709
1684.93	61.4959
1687.98	55.8137
1691.03	50.2274
1694.07	43.1103
1697.12	37.9336
1700.17	32.9818
1703.21	30.1498
1706.25	26.2792
1709.29	23.7757
1712.33	20.7074
1715.37	17.6659
1718.41	15.8061
1721.45	14.1636
1724.49	12.0602
1727.52	11.0459
1730.55	10.8889
1733.59	10.9821
1736.62	10.903
1739.65	9.6629
1742.68	9.15817
1745.7	8.51407
1748.73	7.50194
1751.76	6.21467
1754.78	6.08847
1757.8	5.32115
1760.83	4.71622
1763.85	3.32983
1766.87	2.69432
1769.89	1.53711
1772.9	2.47918
1775.92	1.20925
1778.94	1.41673
1781.95	0.219584
1784.96	0.216457
1787.97	0.373136
1790.99	1.36154
1794	1.86131
1797	2.54553
1800.01	2.85951
1803.02	3.81092
1806.02	4.41412
1809.03	4.47699
1812.03	4.97779
1815.03	5.49733
1818.03	5.45844
1821.03	4.73404
1824.03	4.25008
1827.03	4.16874
1830.02	3.69262
1833.02	3.77641
1836.01	2.79946
1839.01	2.47548
1842	2.11797
1844.99	2.2453
1847.98	2.15293
1850.97	2.14861
1853.95	2.71797
1856.94	2.77271
1859.93	4.08826
1862.91	3.67066
1865.89	4.18435
1868.87	3.63522
1871.85	3.44156
1874.83	2.94757
1877.81	2.82133
1880.79	2.64613
1882.52	2.325
1885.51	2.59916
1888.5	2.58427
1891.49	1.81267
1894.47	1.45431
1897.46	1.51645
1900.44	1.60885
1903.42	1.21975
1906.4	1.2342
1909.38	0.678386
1912.36	1.24867
1915.34	2.27598
1918.32	3.22905
1921.29	3.87285
1924.27	3.95921
1927.24	3.87516
1930.21	4.0784
1933.18	3.15223
1936.15	3.41448
1939.12	3.51873
1942.09	2.98707
1945.06	3.16299
1948.02	3.07606
1950.99	3.92129
1953.95	4.39085
1956.91	3.68269
1959.88	3.67294
1962.84	3.25881
1965.8	3.65751
1968.75	3.63511
1971.71	3.33957
1974.67	3.44985
1977.62	3.8157
1980.58	4.02235
1983.53	4.42099
1986.48	5.42242
1989.43	5.46179
1992.38	5.69463
1995.33	4.54709
1998.27	3.5633
2001.22	3.32481
2004.16	3.65215
2007.11	3.52671
2010.05	3.25455
2012.99	3.30412
2015.93	3.8557
2018.87	4.35623
2021.81	4.80385
2024.75	4.15085
2027.69	3.78844
2030.62	4.88179
2033.56	4.73492
2036.49	4.86361
2039.42	5.72262
2042.35	5.19202
2045.28	5.48523
2048.21	6.29989
2051.14	7.02095
2054.07	6.42625
2056.99	7.59895
2059.92	8.85076
2062.84	8.77973
2065.76	9.01937
2068.68	8.52045
2071.6	9.06473
2074.52	8.78861
2077.44	8.80967
2080.36	8.03282
2083.27	7.5804
2086.19	7.85824
2089.1	8.41163
2092.02	7.38055
2094.93	6.97123
2097.84	6.25205
2100.75	6.31362
2103.66	5.79111
2106.56	4.67448
2109.47	4.25708
2112.38	3.73914
2115.28	4.08216
2118.18	4.12722
2121.09	4.94752
2123.99	5.44814
2126.89	6.00012
2129.79	6.26424
2132.68	6.49603
2135.58	6.00582
2138.48	6.98235
2141.37	6.91459
2144.27	7.4106
2147.16	7.35625
2150.05	7.34775
2152.94	7.31064
2155.83	7.26636
2158.72	8.39283
2161.6	8.35017
2164.49	8.21057
2167.38	7.61045
2170.26	6.63442
2173.14	6.35726
2176.03	6.21409
2178.91	5.65254
2181.79	5.36565
2184.67	6.02025
2187.54	5.00888
2190.42	4.53377
2193.3	4.98269
2196.17	4.0348
2199.05	4.09201
2201.92	4.66444
2204.79	6.1622
2207.66	7.36557
2210.53	7.97196
2213.4	9.16668
2216.27	9.26435
2219.13	10.479
2222	10.8251
2224.86	11.0429
2227.72	12.2605
2230.59	12.9027
2233.45	13.2106
2236.31	13.2226
2239.17	12.197
2242.03	11.3503
2244.88	10.8894
2247.74	10.1463
2250.59	9.03028
2253.45	9.00562
2256.3	7.94104
2259.15	7.44595
2262	7.15872
2264.85	7.37225
2267.7	6.73367
2270.55	6.09796
2273.4	5.89234
2276.24	5.39279
2279.09	5.0922
2281.93	4.99748
2284.77	5.61438
2287.62	4.66984
2290.46	4.20821
2293.3	3.8978
2296.13	3.97436
2298.97	5.02349
2301.81	5.25078
2304.64	5.97524
2307.48	5.65381
2310.31	4.73023
2313.14	4.97963
2315.98	5.84171
2318.81	6.52974
2321.64	7.9859
2324.46	8.69825
2327.29	8.97491
2330.12	9.19072
2332.94	8.84438
2335.77	8.19099
2338.59	6.81005
2341.41	5.91379
2344.23	5.62753
2347.05	4.92662
2349.87	4.79289
2352.69	4.49717
2355.51	3.32635
2358.32	2.19728
2361.14	2.06584
2363.95	1.24601
2366.76	2.13641
2369.58	1.76613
2372.39	1.66623
2375.2	1.65536
2378	2.4003
2380.81	2.88399
2383.62	4.13627
2386.43	5.58581
2389.23	4.96285
2392.03	4.92806
2394.84	4.72584
2397.64	4.66953
2400.44	4.85415
2403.24	4.23581
2406.04	4.42233
2408.84	5.48046
2411.63	5.85036
2414.43	6.10203
2417.22	6.47524
2420.02	7.42664
2422.81	7.10798
2425.6	7.35693
2428.39	7.46366
2431.18	7.29683
2433.97	7.52953
2436.76	7.02946
2439.54	7.67904
2442.33	8.6542
2445.12	8.06165
2447.9	7.0843
2450.68	7.05885
2453.46	6.20065
2456.24	6.01077
2459.02	5.42171
2461.8	5.31733
2464.58	5.05715
2467.36	4.80398
2470.13	4.32968
2472.91	4.08725
2475.68	4.27544
2478.45	4.54027
2481.23	4.23726
2484	4.09987
2486.77	3.02732
2489.54	2.19318
2492.3	2.56441
2495.07	2.26539
2497.84	2.47015
2500.6	2.00771
2503.36	1.61107
2506.13	2.30056
2508.89	2.29902
2511.65	1.64062
2514.41	2.37059
2517.17	3.20725
2519.93	3.4439
2522.68	3.96369
2525.44	5.84018
2528.19	5.90316
2530.95	6.00259
2533.7	7.07344
2536.45	6.3728
2539.2	6.69998
2541.95	7.17463
2544.7	7.39297
2547.45	7.03474
2550.2	6.28627
2552.94	6.03284
2555.69	6.076
2558.43	6.32389
2561.18	5.68043
2563.92	4.97298
2566.66	3.59262
2569.4	2.6297
2572.14	2.53221
2574.88	2.48998
2577.61	2.16825
2580.35	2.29636
2583.09	2.70181
2585.82	2.8757
2588.55	3.06257
2591.29	3.36551
2594.02	2.68395
2596.75	2.69812
2599.48	2.97019
2602.21	2.5637
2604.93	2.88676
2607.66	3.59429
2610.39	3.43285
2613.11	3.28384
2615.83	3.94774
2618.56	4.57235
2621.28	4.46581
2624	3.94442
2626.72	3.19143
2629.44	2.83277
2632.15	2.67643
2634.87	2.70975
2637.59	3.20277
2640.3	4.12836
2643.02	4.10704
2645.73	4.56675
2648.44	5.52094
2651.15	5.61127
2653.86	6.41084
2656.57	5.95798
2659.28	5.88882
2661.99	6.06693
2664.69	6.83843
2667.4	6.28994
2670.1	6.39834
2672.81	6.34712
2675.51	5.82227
2678.21	5.71411
2680.91	5.61614
2683.61	6.02741
2686.31	6.799
2689	7.06284
2691.7	6.95637
2694.4	7.31974
2697.09	7.95304
2699.79	8.40666
2702.48	8.81209
2705.17	10.1642
2707.86	10.6794
2710.55	11.0485
2713.24	12.0001
2715.93	11.7779
2718.62	12.2401
2721.3	12.6639
2723.99	12.8674
2726.67	13.2282
2729.35	13.6565
2732.04	13.3961
2734.72	12.8616
2737.4	12.4824
2740.08	12.5048
2742.76	11.6145
2745.43	11.0695
2748.11	10.764
2750.79	10.9068
2753.46	9.8152
2756.14	9.22068
2758.81	8.35803
2761.48	7.66449
2764.15	6.79254
2766.82	6.68056
2769.49	7.05691
2772.16	6.54842
2774.82	6.0071
2777.49	4.79421
2780.16	4.31082
2782.82	3.60004
2785.48	3.28441
2788.15	3.3976
2790.81	3.03026
2793.47	3.73561
2796.13	3.77857
2798.79	3.61662
2801.44	4.17265
2804.1	3.6678
2806.76	3.06324
2809.41	2.54437
2812.07	1.96566
2814.72	1.93985
2817.37	2.31415
2820.02	2.30556
2822.67	4.02527
2825.32	6.2222
2827.97	8.14456
2830.62	9.93492
2833.26	12.3167
2835.91	15.7476
2838.56	19.7214
2841.2	24.3357
2843.84	30.5618
2846.48	37.0022
2849.12	45.2441
2851.77	53.9959
2854.4	64.2149
2857.04	73.707
2859.68	84.0364
2862.32	94.1002
2864.95	104.31
2867.59	113.737
2870.22	122.728
2872.85	130.048
2875.48	138.417
2878.11	144.682
2880.74	150.037
2883.37	154.915
2886	159.625
2888.63	164.465
2891.25	169.808
2893.88	174.242
2896.5	180.462
2899.13	186.709
2901.75	194.036
2904.37	202.758
2906.99	212.444
2909.61	222.088
2912.23	233.239
2914.85	244.184
2917.46	254.576
2920.08	263.851
2922.7	271.318
2925.31	277.356
2927.92	280.393
2930.54	281.566
2933.15	280.687
2935.76	277.927
2938.37	273.116
2940.98	266.752
2943.58	258.312
2946.19	249.699
2948.8	239.815
2951.4	230.755
2954.01	220.862
2956.61	211.639
2959.21	202.726
2961.81	192.744
2964.41	183.727
2967.01	175.997
2969.61	169.362
2972.21	161.609
2974.81	155.125
2977.4	147.709
2980	139.208
2982.59	130.382
2985.18	121.135
2987.78	111.265
2990.37	100.75
2992.96	90.7185
2995.55	81.467
2998.14	72.0284
3000.73	62.5768
3003.31	53.8921
3005.9	46.1673
3008.48	38.7439
3011.07	32.7457
3013.65	26.3264
3016.23	21.4014
3018.81	16.9297
3021.4	12.9332
3023.97	10.1183
3026.55	7.92768
3029.13	5.27065
3031.71	4.05934
3034.28	2.65037
3036.86	2.29716
3039.43	2.37913
3042.01	3.01624
3044.58	3.97371
3047.15	4.87643
3049.72	6.50823
3052.29	7.78705
3054.86	8.16012
3057.43	9.57447
3060	10.9536
3062.56	11.1945
3065.13	11.1803
3067.69	11.2112
3070.26	11.6345
3072.82	12.0707
3075.38	11.3649
3077.94	10.2924
3080.5	9.07347
3083.06	8.16296
3085.62	6.45132
3088.18	5.31651
3090.73	3.60992
3093.29	2.35741
3095.84	1.31275
3098.4	0.790083
3100.95	0.0259091
3103.5	0.0625572
3106.05	-0.188373
3108.6	-0.0955554
3111.15	0.0646426
3113.7	0.714413
3116.25	1.80837
3118.79	2.41582
3121.34	3.04601
3123.88	3.84792
3126.43	4.78548
3128.97	5.93905
3131.51	8.11632
3134.06	9.70389
3136.6	11.5424
3139.14	13.0647
3141.67	14.4023
3144.21	16.0789
3146.75	17.6813
3149.29	18.3068