File: data/Raman/poly_smoothed/Thy_10_08_39_1x_45s_532 nm_x100_100%_600 gr_mm_01.txt
#Acq. time (s)=	45
#Accumulations=	2
#Range (cm-¹)=	200...3150
#Windows=	2
#Auto scanning=	Off
#Autofocus=	Off
#Macrospot=	Off
#AutoExposure=	Off
#Spike filter=	Multiple accum.
#Delay time (s)=	0
#Binning=	1
#Readout mode=	Signal
#DeNoise=	Off
#ICS correction=	On
#Dark correction=	Off
#Inst. Process=	Off
#Detector Gain=	Best Dynamic Range
#Detector ADC=	20 kHz
#Detector temperature (°C)=	-69.85
#Instrument=	LabRAM HR Evol
#Detector=	Synapse
#Objective=	x100
#Grating=	600 gr/mm
#ND Filter=	100%
#Laser (nm)=	532
#Hole=	100.021
#Range=	Auto
#Laser Pol.=	No
#Raman. Pol.=	No
#Laser Pol. (°)=	-0.0007625
#Raman Pol. (°)=	89.9995
#Collection=	Microscope
#StageXY=	Marzhauser
#StageZ=	Marzhauser
#X (µm)=	-2366.9
#Y (µm)=	231.2
#Z (µm)=	521
#Full time(mm:ss)=	3:18
#Project=
#Sample=
#Site=
#Title=	Thy_10_08_39_2x_45s_532 nm_x100_100%_600 gr_mm
#Remark=
#Date=	06.07.2022 14:33
#Acquired=	06.07.2022 14:33:54
#Base:Fit=	10.08.2022 09:46:25
#Base:Sub=	10.08.2022 09:46:49
#Filter:Polynom=	16.08.2022 10:24:56
#AxisType[0]=Intens
#AxisUnit[0]=Cnt
#AxisType[1]=Spectr
#AxisUnit[1]=1/cm
200.398	9.59944
204.027	8.30818
207.657	7.37652
211.283	6.28865
214.909	5.9333
218.533	4.01037
222.157	1.95877
225.777	1.58284
229.396	0.681891
233.016	1.51602
236.632	3.35217
240.247	2.78688
243.86	3.27579
247.474	3.38798
251.085	3.71906
254.694	5.11902
258.301	5.97637
261.908	6.75549
265.513	6.8057
269.116	7.94561
272.718	9.5575
276.319	10.4072
279.918	10.1521
283.516	9.13369
287.113	7.92507
290.708	7.3081
294.302	8.66371
297.894	8.33817
301.485	9.08195
305.073	9.03438
308.661	8.57006
312.247	9.68198
315.833	9.38339
319.415	9.61174
322.997	9.99993
326.579	10.0433
330.156	11.0724
333.735	10.389
337.31	10.9364
340.885	13.0695
344.458	14.1987
348.03	14.1041
351.6	12.7613
355.17	12.7299
358.737	11.4019
362.304	10.6001
365.868	9.03192
369.431	8.27998
372.994	7.58812
376.554	9.02594
380.112	8.33786
383.669	9.95893
387.225	10.2425
390.781	11.1327
394.334	10.5988
397.885	10.3639
401.436	9.04369
404.984	9.58595
408.532	9.99603
412.078	11.6455
415.623	13.8776
419.166	15.4078
422.708	16.3733
426.248	17.4945
429.788	17.4205
433.326	17.3046
436.86	15.8889
440.395	16.6335
443.929	16.8721
447.461	17.0325
450.99	16.6826
454.52	16.9078
458.048	16.3683
461.573	16.5089
465.099	16.2012
468.623	15.8251
472.144	15.706
475.666	14.7365
479.184	16.3307
482.703	16.4153
486.218	15.9082
489.734	17.7799
493.247	20.5163
496.759	21.7801
500.271	23.7963
503.779	25.6725
507.287	28.4183
510.795	29.2546
514.299	29.6808
517.803	29.9224
521.305	28.5312
524.805	29.1851
528.307	28.8898
531.805	28.4168
535.301	28.4042
538.797	27.1682
542.291	26.3198
545.783	23.825
549.275	21.6753
552.765	20.8269
556.253	20.8349
559.738	21.0154
563.224	19.664
566.709	19.4556
570.192	17.6076
573.674	17.2427
577.153	14.8287
580.632	14.8654
584.11	13.7755
587.587	13.8792
591.06	13.1394
594.534	12.6496
598.005	11.036
601.476	9.28814
604.944	10.0221
608.413	11.0303
611.878	11.7263
615.344	12.281
618.807	13.9485
622.27	14.151
625.73	14.5512
629.189	15.0383
632.648	16.8157
636.105	18.8078
639.559	20.2659
643.013	22.662
646.467	23.8214
649.918	22.9235
653.368	22.6051
656.816	21.8085
660.263	21.4131
663.708	20.0202
667.153	21.3135
670.596	22.1118
674.037	24.4694
677.478	24.2557
680.917	25.5461
684.355	27.6527
687.791	29.8988
691.224	31.9009
694.658	32.7783
698.091	33.3302
701.522	34.4506
704.95	36.4748
708.379	38.0002
711.806	38.8436
715.23	40.8494
718.655	43.6513
722.078	44.1213
725.498	46.0711
728.919	48.2603
732.337	48.2512
735.755	49.0334
739.17	48.7378
742.584	49.3487
745.998	50.1804
749.409	51.8848
752.819	54.3986
756.23	57.5974
759.637	58.9953
763.043	60.2785
766.448	62.9424
769.853	64.6072
773.255	65.3929
776.656	66.7168
780.056	69.1713
783.454	70.4462
786.851	72.3456
790.247	76.4547
793.641	79.332
797.034	81.2575
800.426	84.452
803.817	84.9992
807.206	85.9326
810.592	86.8887
813.979	86.8741
817.364	86.2581
820.748	86.3874
824.129	86.3401
827.511	86.3757
830.891	85.3719
834.269	85.342
837.646	84.3726
841.023	83.5255
844.396	81.9137
847.77	79.7338
851.141	77.0206
854.513	74.0131
857.881	70.9472
861.248	70.5235
864.616	69.9599
867.98	68.7634
871.343	69.5436
874.707	68.1692
878.068	66.6657
881.428	66.2522
884.786	66.5063
888.143	64.8023
891.498	63.7239
894.855	62.1027
898.208	64.1426
901.56	64.2015
904.91	64.595
908.26	64.7503
911.608	63.9702
914.955	63.2408
918.298	62.4875
921.643	61.2807
924.986	59.9166
928.328	57.4449
931.668	56.7287
935.006	55.2394
938.344	52.7844
941.681	53.5278
945.014	53.7693
948.349	52.131
951.682	50.5915
955.012	49.2638
958.343	45.5428
961.67	45.4977
964.998	46.1184
968.323	46.96
971.649	46.8955
974.971	48.7095
978.293	49.032
981.615	49.191
984.933	47.9368
988.251	48.7241
991.567	47.2665
994.884	47.723
998.198	49.3439
1001.51	49.0995
1004.82	49.2647
1008.13	48.771
1011.44	49.3449
1014.75	48.815
1018.06	46.0352
1021.36	46.0668
1024.66	45.6473
1027.97	41.9487
1031.27	38.6052
1034.57	36.4353
1037.87	33.5671
1041.16	32.2862
1044.46	32.525
1047.76	29.8899
1051.05	29.1404
1054.34	27.5931
1057.63	24.0826
1060.92	20.4526
1064.21	17.8942
1067.5	17.6811
1070.78	17.201
1074.07	17.7576
1077.35	18.3846
1080.63	17.5237
1083.91	18.5767
1087.19	19.5654
1090.47	21.0235
1093.75	21.7186
1097.03	21.1825
1100.3	21.9308
1103.57	23.4062
1106.84	22.8059
1110.11	22.2414
1113.38	22.1245
1116.65	23.1358
1119.92	22.3822
1123.19	21.4601
1126.45	19.3668
1129.71	19.2889
1132.97	18.2837
1136.23	18.0878
1139.49	16.8298
1142.75	16.9576
1146.01	16.0832
1149.26	15.8035
1152.52	15.4481
1155.77	13.6876
1159.02	11.6922
1162.27	11.6842
1165.52	11.777
1168.77	12.3735
1172.02	12.245
1175.26	12.9404
1178.51	12.9558
1181.75	14.3673
1184.99	16.0132
1188.23	16.4148
1191.47	18.2273
1194.71	21.2476
1197.94	23.2356
1201.18	25.3562
1204.41	27.734
1207.65	29.5078
1210.88	34.3622
1214.11	37.9575
1217.34	42.0431
1220.57	44.1718
1223.79	46.6557
1227.02	47.8406
1230.24	50.4148
1233.47	51.0979
1236.69	53.454
1239.91	56.4651
1243.13	58.9218
1246.34	60.3921
1249.56	61.1893
1252.78	62.0589
1255.99	61.6656
1259.2	62.1825
1262.42	63.3915
1265.63	62.6876
1268.84	64.5369
1272.04	67.1999
1275.25	67.5769
1278.46	69.0165
1281.66	70.419
1284.86	73.055
1288.07	75.3481
1291.27	77.5035
1294.47	77.5826
1297.66	80.1712
1300.86	81.2392
1304.06	82.4589
1307.25	84.9347
1310.44	86.9184
1313.64	89.7537
1316.83	91.3849
1320.02	91.9227
1323.2	91.9397
1326.39	90.0469
1329.58	88.9911
1332.76	87.3366
1335.95	84.0306
1339.13	81.3394
1342.31	77.9496
1345.49	75.0687
1348.67	72.1072
1351.85	70.2022
1355.02	66.8005
1358.2	64.471
1361.37	61.1345
1364.54	57.7202
1367.71	54.4076
1370.88	51.8301
1374.05	49.5638
1377.22	48.1362
1380.39	46.2203
1383.55	45.9327
1386.72	44.8444
1389.88	44.5142
1393.04	43.8091
1396.2	42.7085
1399.36	41.7114
1402.52	41.8666
1405.68	42.2443
1408.83	44.9918
1411.98	47.1191
1415.14	50.1421
1418.29	54.4931
1421.44	60.2625
1424.59	68.7818
1427.74	74.5153
1430.89	81.8133
1434.03	87.4501
1437.18	91.8696
1440.32	95.3291
1443.46	98.158
1446.6	99.0984
1449.74	98.7232
1452.88	96.28
1456.02	92.2111
1459.16	88.1493
1462.29	83.3416
1465.43	76.6633
1468.56	68.4885
1471.69	59.2778
1474.82	49.9178
1477.95	41.5755
1481.08	35.4216
1484.2	29.0315
1487.33	23.2929
1490.46	18.0066
1493.58	15.1461
1496.7	13.5048
1499.82	14.0117
1502.94	13.0857
1506.06	12.9636
1509.18	14.2333
1512.29	13.5964
1515.41	14.477
1518.52	17.2966
1521.63	19.6147
1524.75	23.063
1527.85	26.3285
1530.96	29.5213
1534.07	32.4276
1537.18	35.9877
1540.28	37.9279
1543.39	40.4234
1546.49	43.111
1549.59	47.6419
1552.69	48.2824
1555.79	51.2647
1558.89	53.9262
1561.99	56.2244
1565.08	58.3503
1568.18	59.3122
1571.27	62.9625
1574.37	66.4979
1577.46	68.4834
1580.55	69.3038
1583.64	70.7075
1586.73	72.1542
1589.81	74.0179
1592.9	74.5371
1595.98	75.5978
1599.06	74.9611
1602.15	74.4661
1605.23	73.0163
1608.31	70.5519
1611.39	69.4612
1614.46	68.832
1617.54	67.8691
1620.61	68.8476
1623.69	69.0847
1626.76	68.7149
1629.83	68.4652
1632.9	69.8479
1635.97	72.1706
1639.04	76.5896
1642.11	79.5341
1645.17	81.8784
1648.24	84.5804
1651.3	86.8622
1654.36	88.0067
1657.42	88.5235
1660.48	88.4057
1663.54	87.0371
1666.6	84.6307
1669.66	80.5876
1672.71	76.7847
1675.77	72.6124
1678.82	68.0608
1681.87	62.843
1684.92	57.168
1687.97	49.0921
1691.02	43.7573
1694.07	38.4125
1697.11	31.8175
1700.16	26.032
1703.2	21.5389
1706.25	17.9716
1709.29	14.0089
1712.33	13.0667
1715.37	10.8881
1718.41	9.02717
1721.44	8.20787
1724.48	8.0391
1727.51	7.261
1730.55	6.17194
1733.58	6.36358
1736.61	7.07071
1739.64	7.49534
1742.67	6.93971
1745.7	6.63751
1748.72	7.29456
1751.75	5.76471
1754.77	5.1399
1757.8	5.02374
1760.82	4.45043
1763.84	3.56011
1766.86	3.9181
1769.88	2.40311
1772.9	1.94097
1775.91	1.77717
1778.93	1.46462
1781.94	1.16582
1784.96	1.40354
1787.97	1.58884
1790.98	2.18506
1793.99	2.68321
1797	2.96285
1800.01	2.87062
1803.01	3.88399
1806.02	3.59668
1809.02	3.92995
1812.02	3.25275
1815.02	1.9862
1818.03	0.28287
1821.02	0.266848
1824.02	-0.278082
1827.02	0.330732
1830.02	0.824551
1833.01	1.33062
1836.01	0.959516
1839	1.41211
1841.99	2.04832
1844.98	2.93475
1847.97	3.2227
1850.96	3.9156
1853.95	3.249
1856.93	3.65395
1859.92	3.42995
1862.9	3.56309
1865.88	3.47913
1868.87	3.50551
1871.85	3.86984
1874.83	4.37159
1877.81	5.09821
1880.78	4.42792
1882.53	5.34026
1885.52	4.48764
1888.51	5.63959
1891.5	4.86565
1894.48	5.49501
1897.47	5.32466
1900.45	6.06337
1903.43	5.65148
1906.41	6.00833
1909.39	5.69187
1912.37	6.06735
1915.35	5.91072
1918.33	6.69031
1921.3	6.47917
1924.28	5.87165
1927.25	6.59452
1930.22	6.42795
1933.19	6.34385
1936.16	5.81021
1939.13	5.78062
1942.1	5.94229
1945.07	6.39598
1948.03	6.35007
1951	6.46982
1953.96	6.80348
1956.92	6.26095
1959.88	5.91812
1962.84	5.27273
1965.8	4.69566
1968.76	4.81521
1971.72	4.30325
1974.67	4.23164
1977.63	4.26447
1980.58	5.15194
1983.54	5.24546
1986.49	6.03085
1989.44	6.02051
1992.39	6.17745
1995.33	6.41542
1998.28	6.99092
2001.23	8.10466
2004.17	7.52937
2007.12	7.82336
2010.06	7.50019
2013	8.29869
2015.94	8.04406
2018.88	7.78205
2021.82	7.7226
2024.76	7.69962
2027.69	7.21735
2030.63	6.55432
2033.56	7.01288
2036.5	6.372
2039.43	8.01888
2042.36	9.0206
2045.29	9.7583
2048.22	11.3192
2051.15	12.5996
2054.07	11.9015
2057	12.5221
2059.92	12.5639
2062.85	12.9466
2065.77	14.4997
2068.69	15.2783
2071.61	16.2923
2074.53	17.3453
2077.45	17.6598
2080.37	17.796
2083.28	18.3587
2086.2	17.8222
2089.11	17.104
2092.02	16.8707
2094.94	16.4965
2097.85	16.7427
2100.76	16.9987
2103.66	16.8437
2106.57	18.4156
2109.48	18.8287
2112.38	20.633
2115.29	20.444
2118.19	21.0565
2121.09	22.6107
2123.99	23.3425
2126.89	24.0528
2129.79	25.0298
2132.69	25.8371
2135.59	26.7635
2138.48	28.1444
2141.38	29.1419
2144.27	30.8882
2147.17	32.5451
2150.06	32.5868
2152.95	33.3029
2155.84	34.7033
2158.73	35.7236
2161.61	36.3998
2164.5	37.1455
2167.38	37.4251
2170.27	38.1054
2173.15	37.8044
2176.03	38.135
2178.91	38.0013
2181.8	37.0848
2184.67	36.4587
2187.55	35.1048
2190.43	34.6318
2193.3	33.7
2196.18	32.5596
2199.05	30.9938
2201.93	29.6842
2204.8	28.6685
2207.67	26.8843
2210.54	26.0228
2213.41	25.5158
2216.27	24.5764
2219.14	22.5327
2222.01	21.6103
2224.87	21.0029
2227.73	19.8727
2230.6	19.5643
2233.46	19.2331
2236.32	18.5153
2239.18	18.3298
2242.03	17.7192
2244.89	18.1142
2247.75	18.5031
2250.6	18.8469
2253.46	19.3648
2256.31	18.7327
2259.16	18.8813
2262.01	18.6163
2264.86	17.9791
2267.71	18.1436
2270.56	17.8128
2273.4	18.3067
2276.25	18.0229
2279.09	18.3455
2281.94	18.0262
2284.78	17.3378
2287.62	16.8981
2290.46	16.4056
2293.3	14.2796
2296.14	14.4344
2298.98	15.6206
2301.82	15.1825
2304.65	16.1368
2307.49	16.9431
2310.32	17.2643
2313.15	17.1313
2315.98	18.1176
2318.81	17.7896
2321.64	17.3645
2324.47	16.6734
2327.3	13.8747
2330.12	12.2231
2332.95	12.1034
2335.77	11.6627
2338.6	10.6083
2341.42	9.34462
2344.24	8.55321
2347.06	7.39765
2349.88	6.20032
2352.7	4.95287
2355.51	2.99174
2358.33	1.34452
2361.14	0.390596
2363.96	0.354412
2366.77	1.6954
2369.58	1.56717
2372.39	1.65272
2375.2	2.86706
2378.01	2.64001
2380.82	2.48472
2383.63	2.37344
2386.43	2.09676
2389.24	1.57098
2392.04	1.13333
2394.84	0.621035
2397.65	-0.322719
2400.45	0.621747
2403.25	1.91251
2406.05	3.31581
2408.84	4.29541
2411.64	5.45098
2414.44	6.41
2417.23	6.93523
2420.02	7.30581
2422.82	8.02803
2425.61	8.65226
2428.4	9.57607
2431.19	11.0732
2433.98	12.0344
2436.77	12.1133
2439.55	12.4895
2442.34	13.0087
2445.12	13.0526
2447.91	11.6204
2450.69	10.1898
2453.47	9.02092
2456.25	8.15366
2459.03	6.66139
2461.81	5.73027
2464.59	4.31356
2467.36	4.09409
2470.14	4.61373
2472.92	4.18054
2475.69	3.66108
2478.46	2.72529
2481.23	2.32642
2484	1.38004
2486.77	1.19878
2489.54	0.900419
2492.31	0.429935
2495.08	0.863456
2497.84	0.843362
2500.61	0.737184
2503.37	0.81322
2506.13	0.0174607
2508.9	0.170021
2511.66	0.618156
2514.42	0.254845
2517.18	-0.147612
2519.93	-0.22669
2522.69	0.586438
2525.45	0.517495
2528.2	0.645368
2530.95	1.23512
2533.71	2.26509
2536.46	3.32621
2539.21	3.92506
2541.96	3.38996
2544.71	2.78774
2547.46	2.79867
2550.2	2.83724
2552.95	1.72629
2555.7	2.4194
2558.44	1.24782
2561.18	1.10039
2563.93	0.282416
2566.67	-0.090423
2569.41	-0.885929
2572.15	-1.09651
2574.88	-1.33455
2577.62	-0.75025
2580.36	-1.90858
2583.09	-1.43835
2585.83	-1.2352
2588.56	-0.217978
2591.29	0.383611
2594.02	0.704651
2596.75	1.23152
2599.48	2.4811
2602.21	2.88975
2604.94	2.75772
2607.67	2.79643
2610.39	3.37894
2613.12	4.12882
2615.84	4.90919
2618.56	4.62474
2621.28	4.40619
2624.01	4.7002
2626.72	4.65569
2629.44	4.24972
2632.16	3.90597
2634.88	4.76074
2637.59	5.19445
2640.31	5.25375
2643.02	4.44827
2645.74	3.99822
2648.45	3.38407
2651.16	3.27798
2653.87	2.66998
2656.58	3.05413
2659.29	2.54007
2661.99	2.75147
2664.7	2.98732
2667.41	4.09288
2670.11	3.59692
2672.81	3.91921
2675.51	4.43552
2678.22	4.74028
2680.92	5.31764
2683.62	5.44243
2686.31	5.76565
2689.01	6.61396
2691.71	6.98843
2694.4	9.04879
2697.1	9.59957
2699.79	11.5237
2702.49	12.3653
2705.18	11.7967
2707.87	12.2976
2710.56	12.6177
2713.25	14.3886
2715.94	15.0236
2718.62	17.2677
2721.31	18.6681
2723.99	19.3771
2726.68	19.7297
2729.36	19.4401
2732.04	18.8535
2734.73	18.7247
2737.41	17.6311
2740.08	18.0183
2742.76	17.9875
2745.44	17.4128
2748.12	17.1651
2750.79	16.8695
2753.47	16.1164
2756.14	16.1593
2758.81	15.6898
2761.49	14.9513
2764.16	13.7317
2766.83	12.8714
2769.5	12.381
2772.16	12.6717
2774.83	13.5119
2777.5	13.1343
2780.16	13.2633
2782.83	13.2539
2785.49	12.4394
2788.15	12.2108
2790.82	11.5444
2793.48	10.9372
2796.14	10.9753
2798.79	10.8248
2801.45	11.35
2804.11	10.8174
2806.76	11.2077
2809.42	10.813
2812.07	10.2533
2814.73	11.1464
2817.38	11.6151
2820.03	14.0423
2822.68	18.0732
2825.33	21.7405
2827.98	27.2872
2830.63	33.5046
2833.27	40.9103
2835.92	47.5257
2838.56	55.9741
2841.21	64.4711
2843.85	74.2744
2846.49	85.2341
2849.13	97.896
2851.77	111.351
2854.41	125.211
2857.05	136.385
2859.69	148.098
2862.32	159.349
2864.96	168.23
2867.59	177.156
2870.23	184.541
2872.86	191.101
2875.49	197.093
2878.12	201.608
2880.75	206.205
2883.38	210.97
2886.01	216.1
2888.63	220.933
2891.26	225.339
2893.89	230.819
2896.51	236.526
2899.13	242.789
2901.76	250.625
2904.38	260.098
2907	272.272
2909.62	286.08
2912.24	300.379
2914.85	313.844
2917.47	325.382
2920.09	333.445
2922.7	341.581
2925.32	348.002
2927.93	350.338
2930.54	351.039
2933.15	349.452
2935.76	345.028
2938.37	339.268
2940.98	330.942
2943.59	321.415
2946.2	310.427
2948.8	299.386
2951.41	287.921
2954.01	276.324
2956.62	263.63
2959.22	252.365
2961.82	240.752
2964.42	230.229
2967.02	220.04
2969.62	212.296
2972.22	204.43
2974.81	194.293
2977.41	185.104
2980	174.39
2982.6	163.714
2985.19	153.351
2987.78	142.984
2990.38	130.993
2992.97	119.555
2995.56	109.815
2998.14	100.09
3000.73	90.3085
3003.32	81.3733
3005.91	72.5376
3008.49	64.6872
3011.07	58.1655
3013.66	52.6804
3016.24	47.8351
3018.82	43.1011
3021.4	39.6668
3023.98	37.0149
3026.56	35.033
3029.14	33.0123
3031.71	32.4905
3034.29	32.6807
3036.87	33.214
3039.44	33.7663
3042.01	35.1453
3044.59	37.3695
3047.16	39.2762
3049.73	40.7135
3052.3	41.0929
3054.87	41.4872
3057.43	41.2838
3060	41.2025
3062.57	39.626
3065.13	37.6814
3067.7	35.294
3070.26	33.0514
3072.82	29.6939
3075.39	26.8286
3077.95	23.5042
3080.51	20.1973
3083.07	16.4521
3085.63	14.0896
3088.18	11.0918
3090.74	8.84337
3093.29	7.89355
3095.85	6.41076
3098.4	5.30092
3100.95	4.44081
3103.51	5.26081
3106.06	5.63501
3108.61	5.36219
3111.16	5.07702
3113.71	4.72129
3116.25	3.91032
3118.8	3.72982
3121.35	3.50046
3123.89	3.69334
3126.44	2.87587
3128.98	2.11664
3131.52	1.4841
3134.06	0.889875
3136.6	0.0193435
3139.14	-0.611861
3141.68	-0.780354
3144.22	-0.285645
3146.76	1.03931
3149.29	2.12637