File: data/Raman/poly_smoothed/Thy_30_10_03_1x_45s_532 nm_x100_100%_600 gr_mm_01.txt
#Acq. time (s)=	45
#Accumulations=	2
#Range (cm-¹)=	200...3150
#Windows=	2
#Auto scanning=	Off
#Autofocus=	Off
#Macrospot=	Off
#AutoExposure=	Off
#Spike filter=	Multiple accum.
#Delay time (s)=	0
#Binning=	1
#Readout mode=	Signal
#DeNoise=	Off
#ICS correction=	On
#Dark correction=	Off
#Inst. Process=	Off
#Detector Gain=	Best Dynamic Range
#Detector ADC=	20 kHz
#Detector temperature (°C)=	-69.85
#Instrument=	LabRAM HR Evol
#Detector=	Synapse
#Objective=	x100
#Grating=	600 gr/mm
#ND Filter=	100%
#Laser (nm)=	532
#Hole=	100.021
#Range=	Auto
#Laser Pol.=	No
#Raman. Pol.=	No
#Laser Pol. (°)=	-0.0007625
#Raman Pol. (°)=	89.9995
#Collection=	Microscope
#StageXY=	Marzhauser
#StageZ=	Marzhauser
#X (µm)=	4767.7
#Y (µm)=	-7736.3
#Z (µm)=	584
#Full time(mm:ss)=	3:18
#Project=
#Sample=
#Site=
#Title=	Thy_30_10_03_2x_45s_532 nm_x100_100%_600 gr_mm
#Remark=
#Date=	30.06.2022 11:36
#Acquired=	30.06.2022 11:36:39
#Base:Fit=	10.08.2022 09:56:48
#Base:Fit=	10.08.2022 09:57:06
#Base:Fit=	10.08.2022 09:57:43
#Base:Fit=	10.08.2022 09:57:50
#Base:Fit=	10.08.2022 09:58:11
#Base:Sub=	10.08.2022 09:58:44
#Filter:Polynom=	16.08.2022 10:22:53
#AxisType[0]=Intens
#AxisUnit[0]=Cnt
#AxisType[1]=Spectr
#AxisUnit[1]=1/cm
200.533	30.8153
204.162	23.4348
207.792	19.2065
211.418	16.0825
215.044	13.1832
218.667	10.5852
222.289	9.33875
225.912	7.38622
229.531	7.82808
233.148	5.10583
236.766	3.33709
240.381	3.48737
243.994	3.58526
247.606	4.86958
251.217	5.87421
254.828	7.12913
258.436	6.83472
262.042	7.80498
265.647	9.34591
269.25	10.1041
272.852	10.6963
276.453	10.0906
280.052	9.49987
283.65	9.9664
287.247	10.4573
290.842	13.297
294.436	13.9242
298.028	13.6649
301.617	14.6446
305.206	15.7555
308.794	16.6269
312.381	18.3596
315.964	17.5484
319.548	17.1635
323.131	17.0792
326.71	18.3305
330.29	19.3348
333.868	19.0491
337.443	18.3507
341.018	17.9135
344.591	16.705
348.163	15.6673
351.733	12.9882
355.303	12.2555
358.869	10.6238
362.435	8.84404
366.001	6.96131
369.563	7.52007
373.124	5.90663
376.686	4.63937
380.244	5.09795
383.801	2.76782
387.357	1.99785
390.911	1.94394
394.466	2.39408
398.018	2.60692
401.568	2.31511
405.117	1.10955
408.664	3.11368
412.21	3.1989
415.755	3.44305
419.298	2.53118
422.84	2.99146
426.38	3.28584
429.919	3.2992
433.455	2.53094
436.992	0.564792
440.527	2.24901
444.06	2.22269
447.593	2.13453
451.122	2.07363
454.651	2.01591
458.18	1.69758
461.705	2.51962
465.23	2.7511
468.752	4.11757
472.275	5.13698
475.797	6.82865
479.315	8.85236
482.834	11.3927
486.349	13.9471
489.863	15.5358
493.378	17.1775
496.889	19.5212
500.401	21.0017
503.91	21.2262
507.417	20.923
510.923	22.0167
514.43	21.617
517.933	22.7652
521.435	21.9449
524.936	21.1481
528.435	20.2189
531.933	16.8361
535.43	14.9569
538.927	14.9659
542.421	13.1681
545.913	12.3307
549.403	10.1752
552.893	8.50693
556.381	8.41358
559.868	7.37101
563.354	6.06515
566.839	6.29587
570.322	5.95062
573.802	5.24425
577.283	4.05075
580.762	3.84074
584.24	4.05875
587.714	3.14942
591.19	2.36488
594.663	1.76822
598.134	2.49746
601.605	2.83659
605.073	3.19504
608.542	3.29488
612.007	3.20295
615.473	4.28707
618.936	5.0995
622.397	6.19792
625.859	8.21214
629.318	9.12801
632.775	9.41167
636.233	10.7024
639.688	12.2329
643.142	11.2459
646.594	11.0937
650.045	10.4728
653.496	11.9081
656.944	13.3165
660.391	13.3074
663.837	13.7274
667.281	12.5774
670.724	12.187
674.166	11.4044
677.606	10.3626
681.045	11.9806
684.483	13.451
687.917	16.5059
691.352	18.2284
694.786	19.7503
698.219	20.4072
701.65	22.0639
705.078	24.8737
708.506	26.6302
711.934	28.0315
715.358	29.8978
718.782	30.4734
722.204	33.0545
725.626	33.8918
729.045	35.2655
732.464	37.0856
735.881	39.9714
739.297	42.0903
742.711	43.5128
746.125	44.5214
749.537	45.3292
752.946	45.6118
756.357	47.7315
759.764	49.1843
763.17	51.1512
766.575	54.8986
769.978	57.5558
773.382	60.1619
776.783	62.8722
780.182	63.8886
783.581	65.9314
786.978	68.2543
790.373	67.8509
793.768	69.6726
797.161	71.9215
800.552	74.026
803.941	74.9754
807.33	74.625
810.718	75.0245
814.105	75.5782
817.49	76.5105
820.873	76.7751
824.256	76.8953
827.637	75.411
831.016	73.2035
834.395	71.9827
837.772	71.4425
841.147	69.0915
844.522	66.2361
847.894	66.5324
851.267	64.8104
854.637	62.1124
858.007	61.6351
861.374	59.9908
864.739	56.5718
868.106	55.0905
871.469	53.2569
874.831	51.1308
878.193	50.4868
881.553	48.9832
884.911	47.1127
888.268	44.624
891.623	43.1252
894.978	41.7418
898.331	41.5894
901.683	41.0942
905.033	40.9374
908.383	40.7742
911.731	39.5589
915.078	38.4853
918.423	38.641
921.768	37.2979
925.111	34.7809
928.452	35.1251
931.791	35.0473
935.13	35.8171
938.468	35.6613
941.803	37.4402
945.139	36.0397
948.473	36.02
951.804	37.7943
955.136	39.1109
958.465	37.6789
961.794	37.0284
965.12	37.3025
968.447	36.571
971.771	38.0559
975.095	39.1195
978.417	39.5441
981.737	39.3301
985.057	38.4197
988.375	37.8486
991.691	37.2766
995.006	36.0598
998.32	37.582
1001.63	35.9784
1004.95	34.3142
1008.26	33.394
1011.56	32.4479
1014.87	32.781
1018.18	32.071
1021.48	31.7665
1024.79	30.807
1028.09	29.3507
1031.39	30.3801
1034.69	29.61
1037.99	26.5453
1041.29	25.0437
1044.58	26.0149
1047.88	26.3908
1051.17	25.4102
1054.46	24.0154
1057.75	21.88
1061.04	18.3792
1064.33	17.4069
1067.62	15.86
1070.9	17.1955
1074.19	16.9275
1077.47	16.9501
1080.76	14.8523
1084.04	15.0677
1087.32	13.6906
1090.59	14.4511
1093.87	15.0533
1097.15	15.7599
1100.42	16.6259
1103.69	15.7913
1106.97	14.9155
1110.24	16.0238
1113.51	14.8034
1116.77	13.158
1120.04	14.018
1123.31	13.6098
1126.57	12.3256
1129.83	11.1478
1133.1	10.2311
1136.36	8.93199
1139.62	9.13712
1142.87	9.77667
1146.13	7.79724
1149.38	7.31259
1152.64	5.92071
1155.89	4.51386
1159.14	3.23449
1162.39	2.88662
1165.64	3.05025
1168.89	2.97077
1172.14	3.06236
1175.38	3.47259
1178.63	1.93861
1181.87	0.521326
1185.11	0.343269
1188.35	0.0673895
1191.59	1.31271
1194.83	1.25309
1198.07	3.62215
1201.3	4.85469
1204.53	7.03298
1207.77	9.55119
1211	11.9358
1214.23	14.9933
1217.46	17.0532
1220.69	21.1138
1223.91	24.7038
1227.14	26.8379
1230.36	29.4227
1233.59	32.8811
1236.81	37.4822
1240.03	39.9269
1243.25	41.1197
1246.46	41.8788
1249.68	43.9208
1252.9	46.1607
1256.11	44.9195
1259.32	45.6733
1262.54	47.4849
1265.75	48.8955
1268.96	50.4591
1272.16	51.9627
1275.37	53.9937
1278.57	54.5572
1281.78	54.8733
1284.98	56.5238
1288.18	57.4711
1291.38	56.557
1294.58	58.2421
1297.78	59.3654
1300.98	60.7832
1304.17	62.7957
1307.37	64.3208
1310.56	65.9101
1313.76	67.5479
1316.95	66.6992
1320.14	64.878
1323.32	64.0559
1326.51	63.4417
1329.7	62.8757
1332.88	59.5832
1336.07	59.611
1339.25	58.6369
1342.43	57.2157
1345.61	55.182
1348.79	52.8754
1351.96	50.0051
1355.14	45.6306
1358.31	41.1595
1361.49	37.3993
1364.66	34.4214
1367.83	30.4453
1371	28.5611
1374.17	27.1025
1377.34	25.8374
1380.5	24.4825
1383.67	23.1031
1386.83	21.8796
1390	20.5274
1393.16	17.9435
1396.32	16.7245
1399.48	15.4617
1402.64	16.0131
1405.79	16.0435
1408.95	19.0469
1412.1	21.9677
1415.26	25.8625
1418.41	28.9212
1421.56	34.1239
1424.71	37.1644
1427.86	41.2092
1431	46.0506
1434.15	51.3983
1437.29	56.0479
1440.44	59.5226
1443.58	64.0949
1446.72	66.0259
1449.86	67.477
1453	68.0816
1456.14	66.8103
1459.27	63.4756
1462.41	59.5633
1465.54	55.9699
1468.67	49.7006
1471.81	42.7696
1474.94	36.8372
1478.07	31.4304
1481.19	26.3006
1484.32	21.4763
1487.45	17.4882
1490.57	10.8663
1493.69	8.07989
1496.82	4.4337
1499.94	2.93298
1503.06	0.603061
1506.17	0.172818
1509.29	0.30103
1512.41	-0.658589
1515.52	-1.73735
1518.64	-0.319613
1521.75	0.753343
1524.86	2.78655
1527.97	4.48212
1531.08	5.63127
1534.19	6.71728
1537.29	8.91353
1540.4	11.7406
1543.5	13.0927
1546.61	14.7204
1549.71	16.3389
1552.81	19.1687
1555.91	22.3729
1559.01	24.5282
1562.11	26.9095
1565.2	29.6285
1568.29	33.0678
1571.39	36.6517
1574.48	39.0144
1577.57	41.326
1580.66	44.4747
1583.75	45.9929
1586.84	48.3892
1589.93	49.2841
1593.01	49.7251
1596.1	49.464
1599.18	50.3005
1602.26	48.5744
1605.34	48.9535
1608.42	50.6039
1611.5	51.1823
1614.58	51.209
1617.65	50.5903
1620.73	50.9586
1623.8	51.2876
1626.87	54.2749
1629.95	56.8531
1633.02	59.2785
1636.09	60.6794
1639.15	65.5135
1642.22	68.7706
1645.29	70.8871
1648.35	72.2109
1651.42	75.5473
1654.48	77.5309
1657.54	76.7912
1660.6	76.0081
1663.66	74.1107
1666.72	72.0493
1669.77	68.7448
1672.83	64.5473
1675.88	59.1929
1678.93	56.6844
1681.99	52.4464
1685.04	47.0763
1688.09	41.317
1691.13	35.0482
1694.18	30.7659
1697.23	25.6584
1700.27	21.0726
1703.32	17.4197
1706.36	13.5046
1709.4	10.5128
1712.44	8.37126
1715.48	7.14431
1718.52	5.54121
1721.56	4.67071
1724.59	5.0396
1727.63	4.21632
1730.66	4.15671
1733.69	2.8399
1736.72	3.01131
1739.75	2.76187
1742.78	2.6777
1745.81	1.79935
1748.84	1.83825
1751.86	2.08773
1754.89	2.2715
1757.91	2.55073
1760.93	1.55852
1763.95	1.88415
1766.97	1.0931
1769.99	-0.104568
1773.01	-0.600655
1776.03	-1.25665
1779.04	-0.537639
1782.06	0.178514
1785.07	0.862692
1788.08	1.79871
1791.09	2.87427
1794.1	3.15829
1797.11	2.83898
1800.12	2.82344
1803.12	2.80389
1806.13	2.39992
1809.13	2.4169
1812.14	3.97819
1815.14	4.69764
1818.14	4.73635
1821.14	5.41329
1824.14	6.02139
1827.13	6.08741
1830.13	6.75185
1833.12	8.21214
1836.12	7.88098
1839.11	8.45808
1842.1	7.78374
1845.09	7.11512
1848.08	6.75247
1851.07	7.03539
1854.06	6.96021
1857.04	7.38624
1860.03	7.53442
1863.01	7.54024
1866	7.48581
1868.98	7.70884
1871.96	8.73207
1874.94	9.60635
1877.92	10.1357
1880.89	11.4611
1882.48	12.1351
1885.47	12.6883
1888.46	12.4954
1891.44	12.6642
1894.43	12.5716
1897.41	12.8675
1900.4	12.3584
1903.38	12.2487
1906.36	12.7117
1909.34	13.25
1912.32	13.3052
1915.29	11.7903
1918.27	11.397
1921.25	11.7814
1924.22	12.16
1927.2	11.8497
1930.17	12.4237
1933.14	12.1859
1936.11	12.6392
1939.08	13.445
1942.05	13.1072
1945.01	13.8995
1947.98	14.3535
1950.94	14.333
1953.91	14.2904
1956.87	14.5097
1959.83	12.8713
1962.79	12.3003
1965.75	12.9846
1968.71	13.3436
1971.67	13.0278
1974.62	12.9618
1977.58	13.3454
1980.53	14.8545
1983.48	14.6029
1986.43	14.5594
1989.38	13.8859
1992.33	15.4026
1995.28	15.8442
1998.23	15.9402
2001.18	15.8417
2004.12	16.5993
2007.06	16.2639
2010.01	15.6715
2012.95	15.4621
2015.89	15.081
2018.83	15.4097
2021.77	15.6043
2024.71	16.8123
2027.64	17.4658
2030.58	18.3721
2033.51	19.512
2036.45	21.0457
2039.38	21.9867
2042.31	23.1054
2045.24	23.9491
2048.17	24.979
2051.1	26.6473
2054.02	26.5596
2056.95	26.6468
2059.87	28.2826
2062.8	28.3889
2065.72	29.0514
2068.64	29.2349
2071.56	29.2217
2074.48	30.0039
2077.4	29.4049
2080.31	29.3235
2083.23	29.7162
2086.14	29.6179
2089.06	30.7066
2091.97	32.0583
2094.88	33.4004
2097.79	35.1643
2100.7	37.0663
2103.61	37.9299
2106.52	40.5239
2109.43	41.5466
2112.33	44.1596
2115.24	46.3865
2118.14	48.9677
2121.04	52.2311
2123.94	55.1203
2126.84	57.7211
2129.74	60.1074
2132.64	63.742
2135.54	66.4375
2138.43	69.6902
2141.33	73.5259
2144.22	76.3686
2147.11	79.8334
2150.01	82.075
2152.9	85.4656
2155.79	87.4173
2158.67	89.2886
2161.56	90.2663
2164.45	90.7339
2167.33	91.6274
2170.22	93.3124
2173.1	93.0125
2175.98	92.3375
2178.86	92.5698
2181.74	90.5436
2184.62	89.6695
2187.5	89.4516
2190.38	89.2175
2193.25	88.2404
2196.13	85.8055
2199	83.5657
2201.88	81.6694
2204.75	78.9091
2207.62	76.1259
2210.49	73.3665
2213.36	69.6599
2216.22	66.2788
2219.09	62.8134
2221.96	59.6635
2224.82	55.7638
2227.68	52.2647
2230.55	47.7967
2233.41	44.7904
2236.27	42.3007
2239.12	40.3979
2241.98	37.7842
2244.84	35.036
2247.7	33.1376
2250.55	31.6537
2253.41	31.1316
2256.26	31.2258
2259.11	31.3281
2261.96	31.1068
2264.81	29.4787
2267.66	28.4086
2270.51	27.2468
2273.35	26.7972
2276.2	25.9553
2279.04	24.535
2281.89	23.3352
2284.73	22.0433
2287.57	21.7558
2290.41	20.2593
2293.25	18.664
2296.09	17.97
2298.93	18.2081
2301.76	17.202
2304.6	18.0387
2307.44	17.9995
2310.27	18.5105
2313.1	17.7797
2315.93	18.59
2318.76	19.5416
2321.59	19.7986
2324.42	20.3484
2327.25	20.0782
2330.07	20.3245
2332.9	19.6237
2335.72	19.0505
2338.55	17.2347
2341.37	15.0973
2344.19	13.466
2347.01	12.0805
2349.83	10.0532
2352.65	8.33038
2355.46	7.73343
2358.28	7.38858
2361.09	7.0683
2363.91	6.18231
2366.72	7.02516
2369.53	6.72064
2372.34	7.46839
2375.15	7.48821
2377.96	8.04027
2380.77	8.71676
2383.58	10.0683
2386.38	10.9427
2389.19	11.4333
2391.99	11.983
2394.8	13.2109
2397.6	13.2569
2400.4	12.869
2403.2	12.2333
2406	11.1905
2408.79	10.3679
2411.59	9.10242
2414.39	9.51816
2417.18	9.90507
2419.98	10.118
2422.77	10.5518
2425.56	10.7952
2428.35	10.9798
2431.14	10.9614
2433.93	10.1685
2436.72	9.73482
2439.5	9.43303
2442.29	9.17198
2445.07	8.73491
2447.86	8.60413
2450.64	8.46588
2453.42	8.55657
2456.2	8.37631
2458.98	8.50967
2461.76	7.74441
2464.54	7.87099
2467.32	6.26253
2470.09	6.3388
2472.87	5.59384
2475.64	5.68824
2478.41	5.63853
2481.18	5.87008
2483.95	6.86847
2486.72	6.93205
2489.49	6.69649
2492.26	6.25339
2495.03	5.6329
2497.79	5.58879
2500.56	4.3696
2503.32	3.83325
2506.09	3.73358
2508.85	3.6726
2511.61	3.72124
2514.37	3.43599
2517.13	3.90057
2519.89	3.58599
2522.64	4.56906
2525.4	4.5133
2528.15	3.84833
2530.91	3.33765
2533.66	2.3412
2536.41	1.89457
2539.16	2.28868
2541.91	1.69295
2544.66	2.14154
2547.41	2.85369
2550.16	2.77142
2552.9	2.8321
2555.65	2.67288
2558.39	2.24605
2561.13	2.0533
2563.88	2.60118
2566.62	2.43644
2569.36	2.48177
2572.1	2.51634
2574.84	3.48056
2577.57	4.6973
2580.31	5.73564
2583.05	6.25135
2585.78	6.39238
2588.51	6.66068
2591.24	7.936
2593.98	8.17787
2596.71	7.64909
2599.44	6.16553
2602.16	5.73441
2604.89	5.31924
2607.62	4.42024
2610.34	4.57237
2613.07	4.31205
2615.79	2.64615
2618.52	2.48832
2621.24	3.51842
2623.96	3.00661
2626.68	2.55321
2629.4	1.41461
2632.11	0.713681
2634.83	-0.119697
2637.55	-0.480636
2640.26	-0.496731
2642.98	0.662988
2645.69	0.272264
2648.4	0.418797
2651.11	1.26169
2653.82	2.69629
2656.53	4.78985
2659.24	5.59224
2661.95	5.49927
2664.65	5.80074
2667.36	5.74328
2670.06	6.75988
2672.76	7.36436
2675.47	7.46559
2678.17	6.59932
2680.87	6.75753
2683.57	7.22126
2686.27	7.87041
2688.97	6.89281
2691.66	6.14896
2694.36	4.90655
2697.05	4.64227
2699.75	3.97282
2702.44	4.17075
2705.13	4.21877
2707.82	4.26814
2710.51	5.15348
2713.2	5.31355
2715.89	7.21051
2718.57	8.30443
2721.26	9.61323
2723.95	10.2025
2726.63	10.5545
2729.31	10.3283
2732	10.4104
2734.68	10.1136
2737.36	9.89928
2740.04	8.79527
2742.72	7.94995
2745.39	7.95061
2748.07	7.94732
2750.75	7.8605
2753.42	7.12757
2756.09	6.30981
2758.77	6.11809
2761.44	5.59909
2764.11	5.49903
2766.78	5.41214
2769.45	5.54224
2772.12	5.46269
2774.78	5.53755
2777.45	6.17186
2780.12	6.61609
2782.78	7.00545
2785.44	7.68712
2788.11	7.64072
2790.77	7.54001
2793.43	7.77936
2796.09	8.26712
2798.75	7.92592
2801.4	7.66895
2804.06	6.73334
2806.72	6.87237
2809.37	6.02701
2812.03	5.51115
2814.68	5.01923
2817.33	5.68324
2819.98	7.4032
2822.63	9.18779
2825.28	12.3332
2827.93	17.0927
2830.58	21.4469
2833.23	25.4434
2835.87	29.9579
2838.52	35.9806
2841.16	42.6147
2843.8	50.3776
2846.44	58.9032
2849.08	68.6228
2851.73	78.5768
2854.36	88.8854
2857	99.9361
2859.64	109.055
2862.28	118.466
2864.91	126.867
2867.55	133.29
2870.18	139.866
2872.81	145.175
2875.44	149.67
2878.07	154.281
2880.7	158.378
2883.33	162.549
2885.96	167.262
2888.59	171.059
2891.21	175.074
2893.84	179.132
2896.46	182.995
2899.09	188.828
2901.71	195.416
2904.33	203.683
2906.95	214.204
2909.57	226.44
2912.19	239.24
2914.81	252.01
2917.43	263.719
2920.04	274.557
2922.66	283.141
2925.27	290.814
2927.88	296.522
2930.5	299.514
2933.11	299.995
2935.72	299.424
2938.33	295.511
2940.94	290.547
2943.54	282.652
2946.15	273.766
2948.76	264.927
2951.36	254.322
2953.97	243.333
2956.57	232.907
2959.17	222.04
2961.77	210.913
2964.37	200.567
2966.97	190.691
2969.57	182.577
2972.17	174.46
2974.77	165.84
2977.36	157.223
2979.96	147.887
2982.55	138.362
2985.15	128.025
2987.74	118.753
2990.33	109.245
2992.92	99.6631
2995.51	89.6914
2998.1	80.5022
3000.69	73.2738
3003.27	65.016
3005.86	56.5009
3008.44	49.9872
3011.03	44.9435
3013.61	40.1764
3016.19	36.5152
3018.78	33.218
3021.36	30.184
3023.94	27.2091
3026.51	25.9172
3029.09	24.8975
3031.67	24.27
3034.24	24.6177
3036.82	25.7941
3039.39	26.3748
3041.97	27.2948
3044.54	28.2573
3047.11	29.6734
3049.68	30.9259
3052.25	32.1066
3054.82	32.4046
3057.39	32.8471
3059.96	32.5584
3062.52	31.5615
3065.09	29.9844
3067.65	27.5236
3070.22	24.7119
3072.78	23.0283
3075.34	20.7102
3077.9	17.6814
3080.46	14.6445
3083.02	11.744
3085.58	8.78302
3088.14	5.97879
3090.69	3.82028
3093.25	2.38516
3095.8	1.0695
3098.36	0.87209
3100.91	0.140686
3103.46	-0.526239
3106.01	0.293403
3108.56	0.32206
3111.11	0.518727
3113.66	0.959526
3116.21	1.55033
3118.76	1.72963
3121.3	1.4642
3123.85	1.39922
3126.39	1.10296
3128.93	0.38342
3131.48	0.187968
3134.02	0.88463
3136.56	0.743393
3139.1	0.21625
3141.64	-0.463786
3144.17	-0.969428
3146.71	-1.56319
3149.25	-1.58713