File: data/Raman/poly_smoothed/Thy_10_08_05_1x_45s_532 nm_x100_100%_600 gr_mm_02.txt
#Acq. time (s)=	45
#Accumulations=	2
#Range (cm-¹)=	200...3150
#Windows=	2
#Auto scanning=	Off
#Autofocus=	Off
#Macrospot=	Off
#AutoExposure=	Off
#Spike filter=	Multiple accum.
#Delay time (s)=	0
#Binning=	1
#Readout mode=	Signal
#DeNoise=	Off
#ICS correction=	On
#Dark correction=	Off
#Inst. Process=	Off
#Detector Gain=	Best Dynamic Range
#Detector ADC=	20 kHz
#Detector temperature (°C)=	-69.85
#Instrument=	LabRAM HR Evol
#Detector=	Synapse
#Objective=	x100
#Grating=	600 gr/mm
#ND Filter=	100%
#Laser (nm)=	532
#Hole=	100.021
#Range=	Auto
#Laser Pol.=	No
#Raman. Pol.=	No
#Laser Pol. (°)=	-0.0007625
#Raman Pol. (°)=	89.9995
#Collection=	Microscope
#StageXY=	Marzhauser
#StageZ=	Marzhauser
#X (µm)=	2164.6
#Y (µm)=	1250.9
#Z (µm)=	443
#Full time(mm:ss)=	3:18
#Project=
#Sample=
#Site=
#Title=	Thy_10_08_05_2x_45s_532 nm_x100_100%_600 gr_mm
#Remark=
#Date=	05.07.2022 14:36
#Acquired=	05.07.2022 14:36:49
#Base:Fit=	10.08.2022 09:45:33
#Base:Fit=	10.08.2022 09:46:03
#Base:Fit=	10.08.2022 09:46:25
#Base:Sub=	10.08.2022 09:46:49
#Filter:Polynom=	16.08.2022 10:24:56
#AxisType[0]=Intens
#AxisUnit[0]=Cnt
#AxisType[1]=Spectr
#AxisUnit[1]=1/cm
200.43	26.2763
204.059	20.2019
207.688	17.3262
211.314	13.967
214.941	10.4536
218.564	7.6995
222.186	4.4366
225.809	4.34091
229.428	3.60533
233.045	2.8439
236.663	2.7231
240.278	3.21082
243.891	3.97135
247.503	4.84643
251.116	5.98625
254.725	7.24891
258.333	6.62564
261.939	8.65082
265.544	9.24259
269.148	8.99753
272.75	11.2863
276.351	10.2613
279.95	10.0819
283.548	9.50382
287.144	9.07636
290.739	8.34451
294.333	8.15457
297.925	6.75159
301.514	5.94444
305.104	5.49959
308.692	5.08597
312.279	5.06219
315.862	5.64408
319.446	5.08262
323.029	5.40741
326.608	5.77315
330.188	6.38454
333.766	7.95613
337.341	7.68319
340.917	6.96619
344.489	7.76293
348.062	9.88678
351.631	9.84634
355.201	11.5891
358.768	12.7027
362.333	12.9958
365.899	13.2323
369.462	14.643
373.023	12.9357
376.585	13.5821
380.143	14.2114
383.7	13.4395
387.256	14.4254
390.812	12.7492
394.365	11.3568
397.916	9.78716
401.467	8.43317
405.015	7.89518
408.563	5.91702
412.109	4.87509
415.654	2.79938
419.197	1.67687
422.739	0.306928
426.279	-0.0284492
429.819	-0.559177
433.356	0.620341
436.891	2.34042
440.426	0.688241
443.96	1.92577
447.492	2.34471
451.021	2.9244
454.551	3.01345
458.079	4.21321
461.604	5.38083
465.13	7.30001
468.654	8.15263
472.175	11.0505
475.696	12.7777
479.215	13.0752
482.733	14.9997
486.249	14.5172
489.765	15.1612
493.278	15.8467
496.789	15.6249
500.301	15.9286
503.81	15.7333
507.317	16.5761
510.825	17.8
514.33	18.1414
517.833	19.0958
521.335	19.1101
524.836	19.3826
528.335	18.1555
531.835	17.6212
535.332	16.3986
538.827	17.0017
542.321	15.4995
545.814	15.2492
549.305	14.1167
552.795	13.4277
556.282	14.3539
559.769	13.7464
563.255	12.5082
566.739	10.2355
570.223	8.26045
573.705	6.9705
577.183	6.75051
580.663	5.93364
584.141	4.89764
587.615	3.683
591.09	3.48495
594.564	3.50332
598.035	4.09097
601.506	3.94381
604.974	4.28897
608.443	3.51848
611.908	4.43616
615.374	4.5748
618.837	4.75479
622.3	7.05853
625.761	6.5571
629.219	6.57226
632.677	6.68166
636.135	7.8308
639.59	8.00769
643.043	10.3755
646.495	11.3715
649.948	13.1627
653.398	14.1385
656.846	16.109
660.293	17.1741
663.738	18.2075
667.183	19.8121
670.626	20.4847
674.067	20.4089
677.508	21.9987
680.947	23.6655
684.385	25.3301
687.821	26.1492
691.254	26.7324
694.688	28.3035
698.121	29.5868
701.552	31.3608
704.98	31.989
708.409	33.3593
711.836	33.5819
715.26	35.7562
718.685	38.4514
722.108	39.6478
725.528	43.2365
728.949	45.8503
732.367	47.2736
735.785	49.2019
739.2	51.7687
742.614	53.5511
746.028	55.6761
749.439	56.5846
752.849	57.6437
756.26	59.5399
759.667	60.8673
763.073	62.7035
766.477	63.6575
769.883	64.9378
773.285	65.3751
776.686	66.5537
780.085	67.4994
783.484	69.1299
786.881	70.4454
790.276	70.4637
793.671	72.0448
797.064	74.3368
800.456	78.0758
803.846	80.0085
807.234	81.8391
810.622	83.2964
814.008	83.7078
817.394	84.6787
820.778	86.1051
824.159	86.132
827.541	88.2315
830.921	85.9489
834.298	85.2333
837.676	84.3053
841.051	81.8079
844.426	78.9743
847.798	77.0883
851.171	73.9422
854.54	71.8191
857.911	69.3279
861.278	66.5205
864.645	64.9922
868.01	63.1845
871.373	60.9885
874.735	59.52
878.097	57.4377
881.457	57.9071
884.815	58.1248
888.172	55.8532
891.528	56.7163
894.882	55.4141
898.237	56.1413
901.589	56.7415
904.94	58.0777
908.289	57.3554
911.635	56.7461
914.982	55.9792
918.328	55.4907
921.672	54.2981
925.015	53.5244
928.357	54.4635
931.698	53.7734
935.035	53.3429
938.373	53.2396
941.71	53.2346
945.044	51.4059
948.378	49.2028
951.709	48.2526
955.041	45.6367
958.372	43.5187
961.699	41.6272
965.027	40.9498
968.352	40.9576
971.676	40.2985
975	40.7029
978.322	40.8655
981.642	40.7296
984.962	39.7326
988.28	38.2711
991.596	37.8905
994.911	37.0718
998.227	37.0489
1001.54	37.1792
1004.85	37.1757
1008.16	35.2283
1011.47	35.6338
1014.78	34.0732
1018.08	33.2491
1021.39	30.8067
1024.69	27.8288
1028	25.2149
1031.3	26.034
1034.6	23.7379
1037.9	20.3191
1041.19	20.3894
1044.49	19.2198
1047.78	20.0963
1051.08	20.6396
1054.37	20.0512
1057.66	19.8932
1060.95	18.8288
1064.24	17.1203
1067.53	16.5012
1070.81	16.2824
1074.1	16.2414
1077.38	14.6274
1080.66	14.1473
1083.94	14.8481
1087.22	13.7583
1090.5	13.9879
1093.78	14.2302
1097.05	14.5524
1100.33	14.3711
1103.6	14.7434
1106.87	15.6865
1110.14	14.8998
1113.41	14.8898
1116.68	13.4477
1119.95	12.7257
1123.21	14.4793
1126.48	13.4571
1129.74	12.3133
1133	11.1852
1136.26	10.8342
1139.52	8.97005
1142.78	7.68069
1146.04	5.80249
1149.29	4.70876
1152.55	3.0715
1155.8	0.975822
1159.05	-0.513977
1162.3	-1.1189
1165.55	-1.30347
1168.8	-0.743738
1172.05	0.693564
1175.29	0.896038
1178.54	2.11643
1181.78	3.48032
1185.02	4.66396
1188.26	4.73287
1191.5	7.13898
1194.74	9.38878
1197.97	10.4015
1201.21	13.305
1204.44	15.1358
1207.68	16.5805
1210.91	20.0874
1214.14	24.3007
1217.37	25.9161
1220.59	27.3562
1223.82	30.6775
1227.05	33.69
1230.27	36.3578
1233.49	37.9141
1236.72	38.3271
1239.94	39.722
1243.16	42.7006
1246.37	43.8266
1249.59	45.0294
1252.8	45.5006
1256.02	44.8306
1259.23	44.9591
1262.44	44.5652
1265.66	44.4284
1268.86	44.3858
1272.07	43.9984
1275.28	43.7886
1278.48	44.1512
1281.69	44.3879
1284.89	46.1666
1288.09	47.9661
1291.29	49.0108
1294.49	51.1738
1297.69	51.1752
1300.89	52.3405
1304.08	55.1312
1307.28	56.5644
1310.47	57.6868
1313.66	59.7303
1316.85	61.4178
1320.04	62.0559
1323.23	63.7466
1326.42	65.1936
1329.61	65.1472
1332.79	64.3416
1335.97	63.6596
1339.16	61.1792
1342.34	58.5551
1345.52	56.8884
1348.7	53.5323
1351.87	51.4258
1355.05	49.6509
1358.22	47.0718
1361.4	43.5273
1364.57	41.0589
1367.74	39.2532
1370.91	36.6119
1374.08	34.138
1377.25	32.6834
1380.41	32.2949
1383.58	31.3154
1386.74	30.6492
1389.91	29.7821
1393.07	29.1259
1396.23	28.7712
1399.39	30.1136
1402.55	31.2326
1405.7	31.1922
1408.86	31.7854
1412.01	33.2745
1415.17	34.7789
1418.32	37.795
1421.47	40.3124
1424.62	42.9624
1427.77	46.8904
1430.91	50.2322
1434.06	53.7801
1437.2	55.9851
1440.35	58.3307
1443.49	61.0453
1446.63	61.6953
1449.77	62.5352
1452.91	62.3446
1456.05	61.3278
1459.18	58.2869
1462.32	54.3175
1465.45	51.439
1468.59	46.3123
1471.72	40.5307
1474.85	36.0764
1477.98	31.678
1481.1	27.0364
1484.23	21.5763
1487.36	19.4097
1490.48	15.9695
1493.61	13.5525
1496.73	10.6456
1499.85	8.61294
1502.97	7.04224
1506.09	5.55543
1509.2	5.09148
1512.32	4.27734
1515.43	3.03133
1518.55	3.72355
1521.66	4.11234
1524.77	4.85377
1527.88	6.69733
1530.99	9.08439
1534.1	10.2357
1537.21	12.3948
1540.31	15.2242
1543.42	17.8426
1546.52	19.2909
1549.62	23.8274
1552.72	28.9197
1555.82	31.6778
1558.92	35.1155
1562.02	40.2991
1565.11	43.4914
1568.21	45.274
1571.3	47.4396
1574.39	48.5293
1577.49	50.0532
1580.57	50.009
1583.66	50.8833
1586.75	50.5694
1589.84	50.456
1592.92	50.5588
1596.01	50.0675
1599.09	49.1768
1602.17	48.7263
1605.25	47.6517
1608.33	45.8429
1611.41	44.2201
1614.49	42.4803
1617.57	41.9631
1620.64	43.2992
1623.72	44.7784
1626.79	47.1981
1629.86	49.1911
1632.93	51.2338
1636	53.1646
1639.07	53.3729
1642.13	55.1816
1645.2	56.6535
1648.26	57.7625
1651.33	59.3771
1654.39	60.8465
1657.45	60.2866
1660.51	60.858
1663.57	59.4711
1666.63	58.8076
1669.68	56.6042
1672.74	53.8351
1675.79	50.087
1678.85	45.7041
1681.9	39.6136
1684.95	34.837
1688	30.2836
1691.05	26.9495
1694.09	22.2818
1697.14	18.6345
1700.18	15.3162
1703.23	12.1538
1706.27	8.37724
1709.31	5.09128
1712.35	2.8649
1715.39	0.974836
1718.43	0.36926
1721.47	-0.614264
1724.5	-0.933448
1727.54	-0.982924
1730.57	-1.99063
1733.61	-1.20914
1736.64	-0.248662
1739.67	-0.396359
1742.7	-0.841405
1745.72	-1.35191
1748.75	-0.643677
1751.77	-0.778662
1754.8	0.0193531
1757.82	0.306446
1760.84	1.56113
1763.87	0.808623
1766.89	0.897714
1769.91	1.32652
1772.92	2.23262
1775.94	2.60431
1778.95	2.18241
1781.97	2.86303
1784.98	3.38253
1787.99	3.51325
1791.01	3.40579
1794.01	4.02573
1797.02	4.54734
1800.03	3.85104
1803.04	5.09957
1806.04	5.46994
1809.05	4.87809
1812.05	4.26295
1815.05	3.45888
1818.05	3.67031
1821.05	4.03329
1824.05	4.65737
1827.05	5.10828
1830.04	5.32682
1833.04	5.84363
1836.03	5.71852
1839.03	6.80023
1842.02	7.29097
1845.01	7.38187
1848	6.84347
1850.99	7.61333
1853.97	8.2998
1856.96	8.16013
1859.94	8.57282
1862.93	8.62197
1865.91	9.35727
1868.89	9.66691
1871.87	9.89403
1874.85	9.25013
1877.83	9.81051
1880.81	9.27269
1882.57	9.37972
1885.56	9.81934
1888.55	9.62826
1891.54	9.81547
1894.52	9.54245
1897.51	10.8039
1900.49	11.7017
1903.47	11.89
1906.45	12.5091
1909.43	12.3953
1912.41	11.1309
1915.39	11.7548
1918.37	11.1505
1921.34	12.1622
1924.32	12.0151
1927.29	11.7937
1930.26	12.4625
1933.23	13.269
1936.2	13.3655
1939.17	13.4708
1942.14	13.5274
1945.11	13.7796
1948.07	13.1646
1951.04	13.5046
1954	13.1201
1956.96	12.8554
1959.93	12.8645
1962.89	12.4156
1965.85	13.0038
1968.8	14.0664
1971.76	14.3832
1974.72	15.0733
1977.67	15.6278
1980.63	15.7835
1983.58	15.9154
1986.53	16.9517
1989.48	18.0828
1992.43	18.7705
1995.38	19.0325
1998.32	19.0047
2001.27	19.8433
2004.22	20.8337
2007.16	20.8889
2010.1	21.8583
2013.04	22.5193
2015.98	21.206
2018.92	20.1182
2021.86	18.9701
2024.8	19.3945
2027.74	20.0444
2030.67	19.6999
2033.61	18.6663
2036.54	18.8061
2039.47	18.8484
2042.4	18.6717
2045.33	18.9972
2048.26	19.2508
2051.19	19.0031
2054.12	19.2638
2057.04	19.7105
2059.97	20.4951
2062.89	20.2587
2065.81	19.8131
2068.73	19.1617
2071.65	20.9143
2074.57	21.2846
2077.49	21.4771
2080.41	22.062
2083.32	22.1143
2086.24	20.9644
2089.15	20.9729
2092.07	21.6875
2094.98	22.236
2097.89	23.85
2100.8	23.5533
2103.71	23.1445
2106.61	23.0369
2109.52	23.0074
2112.43	23.1077
2115.33	23.379
2118.23	24.1782
2121.13	25.4799
2124.04	25.9453
2126.94	26.8438
2129.83	28.1363
2132.73	28.4601
2135.63	29.8512
2138.53	30.6072
2141.42	32.9754
2144.31	34.3756
2147.21	34.6876
2150.1	36.6792
2152.99	37.3743
2155.88	38.5218
2158.77	40.1252
2161.65	41.7481
2164.54	42.0298
2167.43	42.5057
2170.31	41.4472
2173.19	40.8202
2176.07	40.1915
2178.96	39.5439
2181.84	39.1736
2184.72	38.974
2187.59	38.8823
2190.47	38.4086
2193.35	37.5612
2196.22	36.4774
2199.09	36.1102
2201.97	35.547
2204.84	34.85
2207.71	34.3846
2210.58	33.0142
2213.45	32.4613
2216.31	30.6416
2219.18	30.3251
2222.05	30.3521
2224.91	29.9736
2227.78	28.9868
2230.64	28.3386
2233.5	26.2055
2236.36	25.257
2239.22	23.6843
2242.08	22.7838
2244.93	22.232
2247.79	22.7188
2250.64	22.5119
2253.5	22.0036
2256.35	21.7386
2259.2	21.855
2262.05	21.3226
2264.9	20.1256
2267.75	20.2201
2270.6	20.3099
2273.45	20.112
2276.29	20.2242
2279.14	19.754
2281.98	19.1686
2284.82	18.9272
2287.66	18.3037
2290.5	18.3974
2293.34	17.9382
2296.18	17.0702
2299.02	16.7864
2301.86	17.2427
2304.69	16.7093
2307.53	17.0287
2310.36	16.0934
2313.19	16.758
2316.02	17.9253
2318.85	18.1728
2321.68	17.9707
2324.51	17.1002
2327.34	17.7798
2330.16	16.6075
2332.99	15.1207
2335.81	14.5255
2338.64	15.2928
2341.46	15.0453
2344.28	14.6408
2347.1	14.3628
2349.92	13.2016
2352.74	12.0663
2355.55	11.9629
2358.37	11.4068
2361.19	10.7604
2364	10.6616
2366.81	11.3728
2369.62	11.3761
2372.44	10.8394
2375.24	9.91177
2378.05	10.4873
2380.86	10.7879
2383.67	11.3509
2386.47	10.5578
2389.28	10.8931
2392.08	10.5208
2394.89	10.1364
2397.69	10.2453
2400.49	9.8492
2403.29	10.8194
2406.09	11.1972
2408.88	11.591
2411.68	11.1992
2414.48	11.4585
2417.27	10.6013
2420.06	10.6145
2422.86	11.1919
2425.65	10.5269
2428.44	9.75419
2431.23	8.38946
2434.02	8.21079
2436.81	7.64928
2439.59	7.23579
2442.38	6.11285
2445.16	6.06183
2447.95	5.05532
2450.73	5.23738
2453.51	4.71514
2456.29	5.61864
2459.07	6.09946
2461.85	6.3125
2464.63	5.85068
2467.4	6.79931
2470.18	6.50009
2472.95	6.31938
2475.73	6.82103
2478.5	7.65039
2481.27	8.01766
2484.04	8.28469
2486.81	8.22293
2489.58	7.79537
2492.35	6.78829
2495.12	5.27404
2497.88	3.65675
2500.65	2.39557
2503.41	2.5249
2506.17	1.55588
2508.94	0.305287
2511.7	-0.320679
2514.46	-0.609783
2517.22	-0.890337
2519.97	-0.588322
2522.73	-0.501786
2525.49	-0.458699
2528.24	-1.1935
2530.99	-0.91918
2533.75	-0.114997
2536.5	0.672758
2539.25	1.26348
2542	3.52775
2544.75	4.9246
2547.5	5.1443
2550.24	6.00227
2552.99	6.27132
2555.74	6.09225
2558.48	4.90836
2561.22	5.05039
2563.96	4.46724
2566.71	4.80351
2569.45	4.70628
2572.18	4.10538
2574.92	2.886
2577.66	3.18386
2580.4	2.83656
2583.13	1.9304
2585.87	1.64942
2588.6	1.00734
2591.33	0.756397
2594.06	0.532708
2596.79	0.938197
2599.52	2.08846
2602.25	2.47319
2604.98	3.53711
2607.71	4.9742
2610.43	5.06948
2613.16	5.15024
2615.88	4.84099
2618.6	6.07868
2621.32	6.41582
2624.04	6.55732
2626.76	6.55674
2629.48	6.13695
2632.2	5.67453
2634.92	5.27459
2637.63	4.81861
2640.35	4.75242
2643.06	5.37747
2645.77	5.00254
2648.49	4.21762
2651.2	3.53442
2653.91	3.10371
2656.62	2.94893
2659.33	2.67778
2662.03	2.80456
2664.74	2.90623
2667.44	3.0029
2670.15	2.02913
2672.85	1.94844
2675.55	1.9311
2678.26	1.3237
2680.96	1.2432
2683.66	2.03001
2686.35	2.07324
2689.05	1.70214
2691.75	1.61249
2694.44	1.46759
2697.14	2.23393
2699.83	2.50388
2702.52	4.19005
2705.22	5.84187
2707.91	6.63596
2710.6	7.9062
2713.29	9.09412
2715.97	9.20627
2718.66	10.7937
2721.35	11.4633
2724.03	11.9305
2726.72	12.5954
2729.4	12.3382
2732.08	12.2031
2734.76	11.7924
2737.44	11.3719
2740.12	10.6192
2742.8	10.5425
2745.48	9.72206
2748.16	9.6764
2750.83	8.94463
2753.51	7.59988
2756.18	7.36834
2758.85	7.25349
2761.53	5.77207
2764.2	4.60836
2766.87	4.21988
2769.54	3.62508
2772.2	3.79794
2774.87	2.58702
2777.54	2.56537
2780.2	2.17372
2782.87	2.57554
2785.53	3.10175
2788.19	3.46862
2790.85	4.07683
2793.51	4.60989
2796.17	4.89926
2798.83	5.04252
2801.49	5.20337
2804.15	4.43578
2806.8	4.77124
2809.46	4.4725
2812.11	3.64596
2814.76	3.52871
2817.42	4.17498
2820.07	4.85518
2822.72	6.28504
2825.37	8.586
2828.02	11.2986
2830.66	15.6862
2833.31	19.8432
2835.96	25.1229
2838.6	30.7314
2841.24	37.3798
2843.89	45.061
2846.53	53.9533
2849.17	63.9752
2851.81	73.7742
2854.45	83.8583
2857.09	93.5002
2859.72	102.431
2862.36	111.565
2865	119.447
2867.63	125.799
2870.26	131.845
2872.9	137.262
2875.53	140.958
2878.16	144.769
2880.79	149.023
2883.42	153.455
2886.05	156.265
2888.67	160.789
2891.3	165.562
2893.92	169.663
2896.55	174.249
2899.17	178.987
2901.79	185.235
2904.42	193.545
2907.04	202.86
2909.66	214.115
2912.27	226.119
2914.89	236.297
2917.51	247.296
2920.13	255.608
2922.74	263.138
2925.35	268.085
2927.97	270.784
2930.58	272.369
2933.19	271.134
2935.8	268.134
2938.41	262.973
2941.02	256.67
2943.63	248.779
2946.24	239.888
2948.84	230.141
2951.45	220.436
2954.05	210.581
2956.65	200.733
2959.26	190.926
2961.86	181.7
2964.46	173.238
2967.06	166.422
2969.66	160.576
2972.25	154.931
2974.85	148.845
2977.45	141.592
2980.04	133.704
2982.64	125.073
2985.23	116.795
2987.82	109.025
2990.41	101.175
2993	92.6238
2995.59	84.0727
2998.18	75.7523
3000.77	66.9711
3003.36	59.5658
3005.94	52.6069
3008.53	46.0205
3011.11	42.1553
3013.69	37.8027
3016.28	32.9903
3018.86	29.7254
3021.44	26.9319
3024.02	25.4347
3026.6	23.7353
3029.18	22.9553
3031.75	22.4562
3034.33	22.3602
3036.9	22.3236
3039.48	22.4836
3042.05	23.6337
3044.62	24.1751
3047.19	26.1368
3049.77	27.3041
3052.34	28.095
3054.9	28.6658
3057.47	27.8959
3060.04	27.3827
3062.61	26.4814
3065.17	26.2522
3067.74	25.2341
3070.3	23.5141
3072.86	21.8264
3075.42	19.5612
3077.99	16.4676
3080.54	13.5797
3083.1	11.6474
3085.66	9.12568
3088.22	7.2394
3090.78	5.51192
3093.33	3.50202
3095.89	2.41525
3098.44	1.73643
3100.99	1.11625
3103.54	0.767154
3106.1	1.15674
3108.65	0.952134
3111.2	1.29794
3113.74	1.09676
3116.29	1.68432
3118.84	1.50891
3121.38	1.82637
3123.93	1.91774
3126.47	2.49369
3129.01	2.97201
3131.56	1.95921
3134.1	0.897194
3136.64	1.06855
3139.18	0.637245
3141.72	-0.24105
3144.26	-0.917212
3146.79	-2.69008
3149.33	-4.48369