File: data/Raman/poly_smoothed/Thy_20_09_39_1x_45s_532 nm_x100_100%_600 gr_mm_01.txt
#Acq. time (s)=	45
#Accumulations=	2
#Range (cm-¹)=	200...3150
#Windows=	2
#Auto scanning=	Off
#Autofocus=	Off
#Macrospot=	Off
#AutoExposure=	Off
#Spike filter=	Multiple accum.
#Delay time (s)=	0
#Binning=	1
#Readout mode=	Signal
#DeNoise=	Off
#ICS correction=	On
#Dark correction=	Off
#Inst. Process=	Off
#Detector Gain=	Best Dynamic Range
#Detector ADC=	20 kHz
#Detector temperature (°C)=	-69.85
#Instrument=	LabRAM HR Evol
#Detector=	Synapse
#Objective=	x100
#Grating=	600 gr/mm
#ND Filter=	100%
#Laser (nm)=	532
#Hole=	100.021
#Range=	Auto
#Laser Pol.=	No
#Raman. Pol.=	No
#Laser Pol. (°)=	-0.0007625
#Raman Pol. (°)=	89.9995
#Collection=	Microscope
#StageXY=	Marzhauser
#StageZ=	Marzhauser
#X (µm)=	-5917.9
#Y (µm)=	2862.9
#Z (µm)=	-223.6
#Full time(mm:ss)=	3:18
#Project=
#Sample=
#Site=
#Title=	Thy_20_09_39_2x_45s_532 nm_x100_100%_600 gr_mm
#Remark=
#Date=	29.06.2022 13:24
#Acquired=	29.06.2022 13:24:35
#Base:Fit=	10.08.2022 09:52:02
#Base:Fit=	10.08.2022 09:52:12
#Base:Sub=	10.08.2022 09:54:21
#Filter:Polynom=	16.08.2022 10:24:04
#AxisType[0]=Intens
#AxisUnit[0]=Cnt
#AxisType[1]=Spectr
#AxisUnit[1]=1/cm
200.523	2.27245
204.154	5.52915
207.781	6.74615
211.409	6.81683
215.034	7.97259
218.659	7.55252
222.281	8.00774
225.903	8.62348
229.522	9.63166
233.14	10.3354
236.756	11.2846
240.373	11.8827
243.986	11.0436
247.598	11.3247
251.208	11.8051
254.818	10.3352
258.427	10.8903
262.034	11.6458
265.638	12.2413
269.242	12.11
272.844	13.5433
276.445	13.1519
280.044	13.2489
283.642	14.0784
287.238	14.6083
290.833	13.5893
294.425	13.5918
298.017	12.6332
301.608	13.1178
305.198	13.356
308.786	12.564
312.371	13.7239
315.956	13.947
319.54	13.8701
323.122	15.216
326.701	14.0078
330.281	13.986
333.857	13.5181
337.434	13.2113
341.008	11.8893
344.582	10.6361
348.153	10.4177
351.724	10.3765
355.292	10.3703
358.861	10.8286
362.426	11.3611
365.99	10.7861
369.555	10.9814
373.116	10.8927
376.676	9.6823
380.236	9.24344
383.793	8.92581
387.349	8.32518
390.903	7.31618
394.456	7.15622
398.007	5.86844
401.56	6.86185
405.108	6.07584
408.656	5.46522
412.202	4.90658
415.746	4.40146
419.29	4.46444
422.831	3.86486
426.37	3.37416
429.909	1.56295
433.447	1.88186
436.983	2.45869
440.519	2.72471
444.052	2.64664
447.583	2.60942
451.114	3.5501
454.643	5.09662
458.169	6.26435
461.696	5.75947
465.222	8.34778
468.744	8.24615
472.267	8.18721
475.787	9.19678
479.307	10.2632
482.823	12.1948
486.341	12.5362
489.855	13.8207
493.37	14.4814
496.881	15.5308
500.391	17.0636
503.902	17.2071
507.409	17.3945
510.915	17.0975
514.42	15.8832
517.925	15.2339
521.427	14.6552
524.928	15.7938
528.427	14.1197
531.925	14.5247
535.422	13.5541
538.917	13.0812
542.411	13.4823
545.903	11.9202
549.395	10.8345
552.884	10.3891
556.373	8.35917
559.86	7.84151
563.346	8.43145
566.831	8.13163
570.314	7.26197
573.794	6.44458
577.274	6.18475
580.754	6.27276
584.23	5.04096
587.706	5.71707
591.181	4.94008
594.653	3.94898
598.126	3.70507
601.595	3.73823
605.065	4.60187
608.532	4.57732
611.999	4.02991
615.463	3.51838
618.928	2.63041
622.389	3.41683
625.851	4.49501
629.31	5.20843
632.767	6.38654
636.223	6.65341
639.68	7.04105
643.134	9.41855
646.586	10.0385
650.037	11.768
653.486	11.8816
656.936	13.969
660.383	15.8318
663.829	17.3581
667.273	18.0832
670.716	18.9823
674.158	20.4386
677.598	20.6978
681.035	22.3586
684.473	23.1641
687.909	24.8328
691.344	27.0694
694.778	27.9438
698.211	28.4467
701.64	29.2985
705.07	29.1607
708.498	30.5269
711.924	32.0295
715.35	34.1218
718.774	35.054
722.196	35.5469
725.618	37.1654
729.037	37.8112
732.456	38.2678
735.873	39.1624
739.289	41.0688
742.703	42.9883
746.116	45.165
749.529	46.0895
752.938	48.4611
756.347	49.9313
759.756	52.4489
763.162	55.3666
766.567	58.3855
769.97	61.5276
773.372	64.7233
776.773	66.4206
780.174	68.6634
783.573	70.0458
786.97	71.8228
790.365	74.3341
793.76	76.151
797.153	77.3406
800.543	78.2442
803.933	77.5383
807.322	78.8873
810.71	79.3713
814.097	78.9444
817.483	78.6236
820.865	78.289
824.248	77.2351
827.629	76.5224
831.008	75.7814
834.387	72.4731
837.765	72.0041
841.139	70.3459
844.514	68.2041
847.886	66.865
851.259	65.0598
854.629	63.0127
857.997	61.3832
861.366	59.7801
864.732	58.3162
868.098	57.4565
871.461	54.8743
874.823	53.0328
878.184	51.0024
881.545	50.0252
884.903	48.547
888.26	48.0676
891.616	48.1376
894.97	47.6278
898.323	47.328
901.675	46.9021
905.026	44.6533
908.375	42.8174
911.723	42.2254
915.07	42.7965
918.415	40.5286
921.76	40.3256
925.103	39.9727
928.443	39.6457
931.783	39.3836
935.123	39.1303
938.461	39.2784
941.796	38.9864
945.131	36.9656
948.465	37.3834
951.797	36.9199
955.128	36.9485
958.457	37.2661
961.786	36.8382
965.113	36.6417
968.44	36.7536
971.763	38.2595
975.086	37.7429
978.409	37.9795
981.729	37.0904
985.048	35.2404
988.367	33.6947
991.683	31.5198
994.998	30.6093
998.312	29.4106
1001.62	27.666
1004.94	27.1208
1008.25	26.4764
1011.56	24.7594
1014.86	23.8082
1018.17	22.3458
1021.48	20.9664
1024.78	18.6343
1028.08	17.3197
1031.38	16.4235
1034.68	16.2545
1037.98	14.7477
1041.28	14.0662
1044.57	13.2032
1047.87	14.3952
1051.16	14.143
1054.45	13.7847
1057.75	14.4909
1061.04	12.908
1064.32	12.4885
1067.61	12.8348
1070.9	13.0701
1074.18	13.3117
1077.47	14.7482
1080.75	15.3151
1084.03	14.9125
1087.31	15.0921
1090.59	16.3103
1093.86	18.0918
1097.14	19.7962
1100.41	20.2915
1103.69	19.2243
1106.96	19.1365
1110.23	17.897
1113.5	18.9685
1116.77	17.9356
1120.03	16.5252
1123.3	14.6772
1126.56	13.7627
1129.83	11.4162
1133.09	10.1817
1136.35	8.75698
1139.61	7.38299
1142.86	6.01115
1146.12	5.29117
1149.38	5.33173
1152.63	4.4202
1155.88	4.97081
1159.14	4.37633
1162.39	4.4827
1165.63	5.76351
1168.88	7.44002
1172.13	8.89692
1175.38	10.4565
1178.62	12.6072
1181.86	12.563
1185.1	13.5537
1188.34	14.5014
1191.58	14.7626
1194.82	15.2973
1198.06	15.8541
1201.29	16.8551
1204.53	17.5465
1207.76	20.5983
1210.99	23.454
1214.22	26.6353
1217.45	28.4581
1220.68	31.047
1223.91	34.4468
1227.13	37.1072
1230.36	40.1825
1233.58	42.3661
1236.8	43.4763
1240.02	44.588
1243.24	45.2129
1246.46	47.0967
1249.67	48.5378
1252.89	49.6829
1256.1	51.2859
1259.32	52.4579
1262.53	51.9092
1265.74	52.036
1268.95	52.6358
1272.15	52.0372
1275.36	53.4977
1278.57	54.7798
1281.77	56.0345
1284.97	59.308
1288.18	60.6447
1291.38	61.8388
1294.58	63.8113
1297.78	66.6838
1300.97	68.7706
1304.17	70.7357
1307.36	71.6168
1310.55	72.2735
1313.75	71.9349
1316.94	71.2292
1320.13	72.9472
1323.32	72.9839
1326.5	73.7204
1329.69	72.5082
1332.87	73.1844
1336.06	72.7375
1339.24	72.4031
1342.42	71.2045
1345.6	70.3326
1348.78	68.3003
1351.96	66.6206
1355.13	66.1525
1358.31	64.6381
1361.48	61.8581
1364.65	59.1827
1367.82	58.0471
1370.99	57.332
1374.16	55.8451
1377.33	54.6711
1380.5	52.9706
1383.66	50.7564
1386.83	48.399
1389.99	46.6968
1393.15	44.5791
1396.31	43.1115
1399.47	42.429
1402.63	41.5649
1405.78	41.338
1408.94	41.7865
1412.1	43.7381
1415.25	45.8333
1418.4	47.3875
1421.55	48.5239
1424.7	51.6949
1427.85	55.0691
1431	59.194
1434.14	61.9402
1437.29	63.7121
1440.43	67.2998
1443.57	69.6913
1446.71	70.3256
1449.85	69.8729
1452.99	70.2168
1456.13	68.5677
1459.26	65.1098
1462.4	62.4168
1465.54	59.1016
1468.67	53.8689
1471.8	49.4623
1474.93	45.4494
1478.06	41.5194
1481.19	37.0811
1484.31	33.5273
1487.44	30.8253
1490.56	27.7555
1493.69	25.1525
1496.81	23.6972
1499.93	24.5394
1503.05	24.8545
1506.17	24.5186
1509.28	24.083
1512.4	24.4831
1515.52	25.0591
1518.63	26.7932
1521.74	28.9545
1524.85	31.0809
1527.96	33.1155
1531.07	33.2691
1534.18	34.8267
1537.29	36.8316
1540.39	38.5421
1543.5	40.1351
1546.6	41.7219
1549.7	45.3977
1552.8	49.5249
1555.9	53.2623
1559	54.5294
1562.1	57.92
1565.19	60.1244
1568.29	62.1679
1571.38	64.8687
1574.47	68.9621
1577.56	71.7106
1580.66	74.1314
1583.74	75.3481
1586.83	75.2945
1589.92	76.0755
1593.01	76.1727
1596.09	75.4494
1599.17	74.3857
1602.25	73.1128
1605.34	70.2369
1608.41	68.5419
1611.49	67.0823
1614.57	63.6154
1617.65	61.9115
1620.72	60.6547
1623.79	59.5136
1626.87	59.0534
1629.94	57.8769
1633.01	56.8426
1636.08	55.7161
1639.15	55.9851
1642.21	56.0759
1645.28	56.1876
1648.34	57.318
1651.41	57.5286
1654.47	57.6155
1657.53	54.7767
1660.59	52.2357
1663.65	50.7331
1666.71	48.9496
1669.76	46.5597
1672.82	45.8975
1675.87	43.1771
1678.93	40.1666
1681.98	36.4119
1685.03	33.3293
1688.08	30.1364
1691.13	26.5337
1694.17	24.0382
1697.22	21.1103
1700.27	19.1658
1703.31	16.9981
1706.35	14.5031
1709.39	12.9136
1712.43	10.7397
1715.47	9.72104
1718.51	8.61735
1721.55	7.38
1724.58	6.02492
1727.62	4.82813
1730.65	3.99133
1733.68	3.7132
1736.72	3.39793
1739.74	3.6316
1742.77	3.58981
1745.8	2.89164
1748.83	3.39819
1751.85	3.43508
1754.88	3.62371
1757.9	4.37305
1760.92	4.52639
1763.95	4.49032
1766.96	4.53464
1769.98	5.31936
1773	5.04084
1776.02	5.60791
1779.03	5.33967
1782.05	5.53058
1785.06	4.88345
1788.07	4.67529
1791.08	4.42674
1794.09	4.49791
1797.1	4.16652
1800.11	4.22597
1803.12	3.53079
1806.12	2.85977
1809.12	2.22442
1812.13	1.96365
1815.13	1.79454
1818.13	1.32385
1821.13	1.7252
1824.13	2.20927
1827.13	2.31906
1830.12	2.08525
1833.12	1.70226
1836.11	2.20893
1839.1	2.50126
1842.09	3.28014
1845.09	4.02303
1848.08	4.5543
1851.06	4.9076
1854.05	4.6377
1857.04	4.52052
1860.02	4.14942
1863.01	4.03153
1865.99	3.88807
1868.97	3.40496
1871.95	3.10636
1874.93	2.83529
1877.91	2.55707
1880.89	2.12041
1882.46	2.40503
1885.45	2.88062
1888.43	1.76196
1891.42	1.93121
1894.41	0.954792
1897.39	0.634698
1900.37	0.794107
1903.36	1.67535
1906.34	2.75813
1909.32	3.89145
1912.29	3.66059
1915.27	3.98963
1918.25	4.214
1921.23	4.2579
1924.2	4.1739
1927.17	4.5179
1930.15	4.51211
1933.12	4.10668
1936.09	4.73496
1939.06	4.57335
1942.02	4.93665
1944.99	5.40084
1947.96	5.299
1950.92	5.63814
1953.88	5.26655
1956.85	6.23554
1959.81	6.17307
1962.77	6.44702
1965.73	6.64563
1968.69	7.37225
1971.64	8.37127
1974.6	10.2703
1977.55	11.0889
1980.51	10.826
1983.46	10.5392
1986.41	10.1395
1989.36	10.3233
1992.31	10.022
1995.26	9.79677
1998.21	9.35423
2001.15	8.64176
2004.1	7.75252
2007.04	6.81947
2009.99	7.14734
2012.93	7.53025
2015.87	7.23565
2018.81	7.27382
2021.75	6.58322
2024.68	6.17707
2027.62	6.93888
2030.56	7.10829
2033.49	7.68341
2036.42	8.61084
2039.36	9.43003
2042.29	10.2003
2045.22	10.3563
2048.14	10.7164
2051.07	10.8785
2054	10.9301
2056.93	10.2699
2059.85	9.83723
2062.77	10.4241
2065.7	10.0336
2068.62	9.22723
2071.54	9.15375
2074.46	9.45209
2077.38	9.96722
2080.29	11.0314
2083.21	11.6608
2086.12	11.491
2089.04	12.049
2091.95	11.2946
2094.86	11.8698
2097.77	13.6836
2100.68	15.2486
2103.59	16.6015
2106.5	17.1893
2109.41	17.4375
2112.31	16.8215
2115.21	17.0021
2118.12	17.4042
2121.02	18.5666
2123.92	19.641
2126.82	19.9757
2129.72	21.6071
2132.62	23.5157
2135.51	24.369
2138.41	25.1177
2141.31	26.3906
2144.2	27.966
2147.09	29.5683
2149.98	29.9996
2152.87	30.7472
2155.76	31.4334
2158.65	32.2846
2161.54	33.2678
2164.43	35.25
2167.31	36.5435
2170.2	36.196
2173.08	35.4837
2175.96	34.8016
2178.84	33.883
2181.72	32.8875
2184.6	33.5186
2187.48	33.2427
2190.36	32.6274
2193.23	32.1209
2196.11	31.5932
2198.98	31.5173
2201.85	30.9385
2204.72	30.0042
2207.59	29.0601
2210.46	27.1061
2213.33	26.5605
2216.2	24.8766
2219.07	23.4485
2221.93	21.9728
2224.8	21.3635
2227.66	20.8582
2230.52	19.8902
2233.39	19.0619
2236.25	18.2381
2239.1	16.7079
2241.96	15.4697
2244.82	15.5696
2247.68	15.9487
2250.53	16.7677
2253.38	16.075
2256.24	15.3392
2259.09	14.5075
2261.94	13.9915
2264.79	14.1968
2267.64	15.3332
2270.49	14.7206
2273.33	13.8202
2276.18	14.1449
2279.02	12.9098
2281.87	12.2683
2284.71	11.5548
2287.55	11.1552
2290.39	11.0779
2293.23	10.0322
2296.07	10.2483
2298.91	9.5193
2301.74	10.5418
2304.58	10.9491
2307.41	11.399
2310.25	12.3247
2313.08	12.8184
2315.91	12.469
2318.74	11.9287
2321.57	11.3614
2324.4	9.77241
2327.23	9.83931
2330.05	8.80973
2332.88	8.80178
2335.7	8.38071
2338.52	7.20279
2341.35	5.32981
2344.17	4.67396
2346.99	3.60272
2349.81	2.07749
2352.62	1.14771
2355.44	1.16337
2358.26	1.25027
2361.07	0.904068
2363.89	2.35515
2366.7	3.61789
2369.51	4.12853
2372.32	5.38899
2375.13	5.19861
2377.94	6.048
2380.75	6.79994
2383.56	6.80695
2386.36	7.61492
2389.17	7.96468
2391.97	7.13709
2394.77	7.6681
2397.58	7.84478
2400.38	7.44452
2403.18	6.47667
2405.97	5.86672
2408.77	5.06782
2411.57	4.37371
2414.37	4.26614
2417.16	4.91763
2419.95	4.80937
2422.75	4.64603
2425.54	5.03635
2428.33	4.77829
2431.12	4.64967
2433.91	4.94339
2436.7	4.5569
2439.48	4.18137
2442.27	3.89761
2445.05	3.81897
2447.84	4.01093
2450.62	4.80062
2453.4	4.27701
2456.18	4.18445
2458.96	3.37952
2461.74	2.97793
2464.52	2.74615
2467.29	2.03022
2470.07	1.28991
2472.85	1.41703
2475.62	0.389594
2478.39	0.890977
2481.16	1.39551
2483.93	1.14966
2486.7	1.15372
2489.47	1.05617
2492.24	1.79057
2495.01	1.78545
2497.77	1.52103
2500.54	2.31918
2503.3	1.85636
2506.06	1.96059
2508.83	1.94939
2511.59	2.3294
2514.35	2.73169
2517.11	3.07863
2519.86	2.52161
2522.62	3.03846
2525.38	3.72554
2528.13	2.49219
2530.89	2.22303
2533.64	2.55613
2536.39	2.55662
2539.14	2.28007
2541.89	1.62367
2544.64	1.55481
2547.39	2.13996
2550.14	1.50804
2552.88	1.28433
2555.63	1.47448
2558.37	1.2543
2561.11	1.15907
2563.86	1.38347
2566.6	1.93761
2569.34	1.63924
2572.08	1.44362
2574.82	1.87647
2577.55	2.52732
2580.29	3.45057
2583.02	3.19213
2585.76	3.7698
2588.49	4.74212
2591.22	4.4858
2593.96	3.86793
2596.69	3.74171
2599.42	3.40807
2602.14	3.22785
2604.87	2.59954
2607.6	3.34771
2610.32	4.02645
2613.05	4.17075
2615.77	4.89337
2618.49	4.5668
2621.22	3.79804
2623.94	3.42343
2626.66	3.88931
2629.37	4.02504
2632.09	3.79069
2634.81	3.23891
2637.53	2.67124
2640.24	2.55666
2642.96	2.76752
2645.67	2.55159
2648.38	1.99255
2651.09	2.06739
2653.8	2.17059
2656.51	2.52607
2659.22	2.31479
2661.93	2.52428
2664.63	2.91609
2667.34	3.44008
2670.04	3.83621
2672.75	5.28858
2675.45	5.60291
2678.15	6.21401
2680.85	7.27508
2683.55	7.05545
2686.25	7.00004
2688.94	7.17024
2691.64	7.66955
2694.34	7.79144
2697.03	7.59862
2699.73	7.50646
2702.42	6.33987
2705.11	5.64024
2707.8	5.82131
2710.49	5.55081
2713.18	5.27819
2715.87	4.72255
2718.55	4.80432
2721.24	4.59651
2723.93	4.48276
2726.61	4.55618
2729.29	4.16027
2731.98	4.20016
2734.66	3.92132
2737.34	4.02162
2740.02	4.03186
2742.7	4.00949
2745.37	4.97241
2748.05	4.71201
2750.72	5.34581
2753.4	5.01556
2756.07	5.05691
2758.75	4.70422
2761.42	3.8723
2764.09	3.47629
2766.76	2.70923
2769.43	3.17523
2772.1	3.15094
2774.76	2.51747
2777.43	2.93276
2780.1	2.26147
2782.76	2.2432
2785.42	2.829
2788.09	3.19585
2790.75	3.33967
2793.41	3.39641
2796.07	2.83807
2798.73	2.92023
2801.39	2.19644
2804.04	1.80818
2806.7	2.74564
2809.35	2.38012
2812.01	2.48481
2814.66	2.62131
2817.31	2.41384
2819.96	3.18846
2822.61	3.91721
2825.26	5.42855
2827.91	6.93178
2830.56	9.08882
2833.21	11.5378
2835.85	13.9491
2838.5	16.4469
2841.14	20.8717
2843.78	24.3672
2846.42	29.2638
2849.06	34.7186
2851.71	39.8681
2854.34	45.0357
2856.98	49.6065
2859.62	54.5015
2862.26	59.1406
2864.89	63.3154
2867.53	67.1433
2870.16	71.0156
2872.79	74.4128
2875.42	77.612
2878.05	81.0152
2880.68	83.8256
2883.31	87.0864
2885.94	89.5539
2888.57	93.5687
2891.19	96.6834
2893.82	100.262
2896.44	103.499
2899.07	107.126
2901.69	111.17
2904.31	116.612
2906.93	122.81
2909.55	130.362
2912.17	137.901
2914.79	144.744
2917.41	151.14
2920.02	156.703
2922.64	160.908
2925.25	164.959
2927.86	166.155
2930.48	167.436
2933.09	167.677
2935.7	166.504
2938.31	164.163
2940.92	160.691
2943.53	155.843
2946.13	151.665
2948.74	146.16
2951.34	140.532
2953.95	134.778
2956.55	128.01
2959.15	121.134
2961.75	115.681
2964.35	110.121
2966.95	105.293
2969.55	101.473
2972.15	97.3383
2974.75	91.8875
2977.34	86.7009
2979.94	81.1635
2982.53	76.1687
2985.13	70.9297
2987.72	65.544
2990.31	59.981
2992.9	54.7938
2995.49	50.1892
2998.08	44.9482
3000.67	39.8928
3003.25	35.4862
3005.84	31.6545
3008.42	28.63
3011.01	25.6326
3013.59	22.764
3016.17	20.3198
3018.76	18.0035
3021.34	16.1059
3023.92	14.9216
3026.49	14.0725
3029.07	14.0598
3031.65	13.0697
3034.23	12.8505
3036.8	12.5519
3039.38	13.0639
3041.95	13.4205
3044.52	13.8523
3047.09	14.3091
3049.66	14.2677
3052.23	14.5537
3054.8	14.4497
3057.37	14.4632
3059.94	13.7224
3062.5	12.9939
3065.07	12.3538
3067.63	11.0112
3070.2	10.2843
3072.76	9.34059
3075.32	7.26789
3077.88	5.7032
3080.44	3.88459
3083	2.44789
3085.56	1.18309
3088.12	0.736796
3090.67	0.406153
3093.23	-0.0145549
3095.78	0.0767219
3098.34	0.158207
3100.89	0.0773054
3103.44	0.459914
3105.99	-0.053378
3108.54	0.226867
3111.09	0.484327
3113.64	0.765325
3116.19	0.947167
3118.74	0.340469
3121.28	1.13766
3123.83	1.22325
3126.37	1.32641
3128.91	1.13428
3131.46	1.63627
3134	2.01153
3136.54	1.84329
3139.08	2.23314
3141.62	2.6579
3144.16	2.98304
3146.69	3.78004
3149.23	4.31909