File: data/Raman/poly_smoothed/Thy_30_10_14_1x_45s_532 nm_x100_100%_600 gr_mm_01.txt
#Acq. time (s)=	45
#Accumulations=	2
#Range (cm-¹)=	200...3150
#Windows=	2
#Auto scanning=	Off
#Autofocus=	Off
#Macrospot=	Off
#AutoExposure=	Off
#Spike filter=	Multiple accum.
#Delay time (s)=	0
#Binning=	1
#Readout mode=	Signal
#DeNoise=	Off
#ICS correction=	On
#Dark correction=	Off
#Inst. Process=	Off
#Detector Gain=	Best Dynamic Range
#Detector ADC=	20 kHz
#Detector temperature (°C)=	-69.85
#Instrument=	LabRAM HR Evol
#Detector=	Synapse
#Objective=	x100
#Grating=	600 gr/mm
#ND Filter=	100%
#Laser (nm)=	532
#Hole=	100.021
#Range=	Auto
#Laser Pol.=	No
#Raman. Pol.=	No
#Laser Pol. (°)=	-0.0007625
#Raman Pol. (°)=	89.9995
#Collection=	Microscope
#StageXY=	Marzhauser
#StageZ=	Marzhauser
#X (µm)=	4741.5
#Y (µm)=	-7728.2
#Z (µm)=	583.7
#Full time(mm:ss)=	3:18
#Project=
#Sample=
#Site=
#Title=	Thy_30_10_14_2x_45s_532 nm_x100_100%_600 gr_mm
#Remark=
#Date=	30.06.2022 12:27
#Acquired=	30.06.2022 12:27:34
#Base:Fit=	10.08.2022 09:58:11
#Base:Sub=	10.08.2022 09:58:44
#Filter:Polynom=	16.08.2022 10:22:53
#AxisType[0]=Intens
#AxisUnit[0]=Cnt
#AxisType[1]=Spectr
#AxisUnit[1]=1/cm
200.533	3.63478
204.162	5.74047
207.792	6.43415
211.418	7.71765
215.044	8.63124
218.667	11.383
222.289	11.8929
225.912	12.9124
229.531	14.3334
233.148	14.2249
236.766	14.6911
240.381	13.4123
243.994	12.9026
247.606	12.7266
251.217	12.4691
254.828	10.2828
258.436	7.83406
262.042	8.86598
265.647	8.408
269.25	9.35195
272.852	8.63096
276.453	8.56217
280.052	5.52148
283.65	5.61471
287.247	6.38036
290.842	7.35036
294.436	8.46938
298.028	9.92971
301.617	12.4215
305.206	13.5846
308.794	14.8483
312.381	16.891
315.964	18.427
319.548	18.5612
323.131	20.2578
326.71	21.701
330.29	22.4885
333.868	23.8915
337.443	23.1147
341.018	22.2417
344.591	20.4268
348.163	19.5726
351.733	16.9792
355.303	14.6171
358.869	12.4199
362.435	9.65647
366.001	7.29141
369.563	6.18101
373.124	6.15761
376.686	4.66607
380.244	5.29784
383.801	5.37567
387.357	6.17781
390.911	5.54604
394.466	5.89531
398.018	7.24028
401.568	9.43249
405.117	9.28352
408.664	11.4968
412.21	15.182
415.755	15.049
419.298	15.2669
422.84	15.2069
426.38	13.2532
429.919	13.1613
433.455	11.9716
436.992	11.2532
440.527	9.82686
444.06	10.2941
447.593	9.67836
451.122	8.14921
454.651	9.53466
458.18	9.93268
461.705	11.4846
465.23	12.3947
468.752	13.2307
472.275	14.7817
475.797	14.4821
479.315	15.9246
482.834	18.669
486.349	21.8751
489.863	24.3331
493.378	24.7181
496.889	27.6317
500.401	28.1887
503.91	29.0377
507.417	28.9533
510.923	28.6523
514.43	29.2863
517.933	28.6277
521.435	28.6141
524.936	26.8377
528.435	25.8131
531.933	24.4526
535.43	23.5883
538.927	21.1446
542.421	19.2081
545.913	17.7602
549.403	15.1863
552.893	12.7969
556.381	10.6464
559.868	8.91544
563.354	7.74766
566.839	7.12689
570.322	4.99685
573.802	3.37492
577.283	2.59051
580.762	2.51658
584.24	4.06015
587.714	3.90689
591.19	3.69025
594.663	2.88407
598.134	3.14093
601.605	3.11852
605.073	4.27009
608.542	6.02937
612.007	7.68564
615.473	7.36538
618.936	8.70535
622.397	8.5977
625.859	8.43372
629.318	9.71676
632.775	9.79662
636.233	9.62351
639.688	10.3868
643.142	12.2514
646.594	12.1147
650.045	12.4642
653.496	12.3472
656.944	13.5208
660.391	17.4297
663.837	19.312
667.281	21.4381
670.724	22.1468
674.166	22.9047
677.606	23.9386
681.045	25.6562
684.483	27.6477
687.917	28.6426
691.352	29.1707
694.786	30.9502
698.219	31.6528
701.65	31.0504
705.078	31.928
708.506	31.9196
711.934	34.1971
715.358	34.9524
718.782	35.5
722.204	37.5978
725.626	39.8331
729.045	41.406
732.464	42.8058
735.881	44.3531
739.297	45.8154
742.711	48.0874
746.125	50.9952
749.537	52.241
752.946	54.1656
756.357	55.8381
759.764	59.3485
763.17	62.3189
766.575	63.1775
769.978	65.9349
773.382	66.6864
776.783	65.4646
780.182	68.568
783.581	69.2817
786.978	69.8922
790.373	70.3141
793.768	73.9536
797.161	75.5488
800.552	77.2038
803.941	78.2843
807.33	78.7934
810.718	79.7995
814.105	80.7649
817.49	81.8457
820.873	82.4776
824.256	83.679
827.637	84.3865
831.016	83.4976
834.395	83.9223
837.772	83.837
841.147	82.795
844.522	80.9194
847.894	79.0214
851.267	75.11
854.637	72.5824
858.007	68.5105
861.374	65.8316
864.739	63.9578
868.106	61.608
871.469	58.7514
874.831	55.292
878.193	53.508
881.553	52.5767
884.911	49.8835
888.268	49.0527
891.623	49.2226
894.978	48.9427
898.331	49.2186
901.683	47.8138
905.033	48.4556
908.383	48.0817
911.731	48.6487
915.078	47.9591
918.423	48.7977
921.768	47.4356
925.111	46.2327
928.452	45.7951
931.791	44.012
935.13	42.5885
938.468	41.8587
941.803	41.7608
945.139	40.0129
948.473	37.5523
951.804	36.9389
955.136	37.1426
958.465	37.463
961.794	37.9238
965.12	39.3094
968.447	42.5706
971.771	44.7723
975.095	45.5628
978.417	49.2773
981.737	51.0106
985.057	53.7732
988.375	54.9623
991.691	56.0769
995.006	56.6715
998.32	57.4852
1001.63	57.2123
1004.95	56.1678
1008.26	55.6397
1011.56	54.5675
1014.87	53.8595
1018.18	50.7124
1021.48	48.3012
1024.79	45.9947
1028.09	44.9578
1031.39	43.8372
1034.69	43.1432
1037.99	41.2363
1041.29	39.9935
1044.58	41.2829
1047.88	41.2586
1051.17	40.7557
1054.46	38.6556
1057.75	38.7739
1061.04	36.7702
1064.33	35.661
1067.62	33.8539
1070.9	32.9995
1074.19	31.6966
1077.47	31.0193
1080.76	29.5637
1084.04	29.3182
1087.32	28.1566
1090.59	28.6814
1093.87	26.7167
1097.15	27.7277
1100.42	26.4933
1103.69	27.7251
1106.97	27.3083
1110.24	27.2057
1113.51	26.9422
1116.77	25.7804
1120.04	25.4076
1123.31	25.8087
1126.57	23.4718
1129.83	20.9051
1133.1	19.6526
1136.36	19.0055
1139.62	17.6646
1142.87	17.9965
1146.13	16.2295
1149.38	15.5607
1152.64	12.527
1155.89	10.4671
1159.14	9.11831
1162.39	7.08005
1165.64	5.48492
1168.89	5.59775
1172.14	5.91902
1175.38	8.20918
1178.63	7.93065
1181.87	7.5344
1185.11	7.31496
1188.35	8.51825
1191.59	11.5796
1194.83	12.5104
1198.07	15.7829
1201.3	18.7184
1204.53	23.5157
1207.77	27.2337
1211	32.3568
1214.23	37.848
1217.46	42.1615
1220.69	47.529
1223.91	52.2984
1227.14	57.206
1230.36	60.6578
1233.59	64.203
1236.81	68.0091
1240.03	71.5842
1243.25	74.0937
1246.46	78.8827
1249.68	82.1547
1252.9	85.1635
1256.11	86.6669
1259.32	88.4779
1262.54	89.4958
1265.75	91.8561
1268.96	93.9612
1272.16	93.9018
1275.37	94.2518
1278.57	94.0735
1281.78	94.409
1284.98	96.4266
1288.18	94.5304
1291.38	94.723
1294.58	94.0951
1297.78	95.9559
1300.98	96.5599
1304.17	98.555
1307.37	100.208
1310.56	100.077
1313.76	102.006
1316.95	102.179
1320.14	102.968
1323.32	103.921
1326.51	103.974
1329.7	104.046
1332.88	102.733
1336.07	100.635
1339.25	98.2734
1342.43	96.7387
1345.61	92.8796
1348.79	88.7805
1351.96	83.0436
1355.14	77.4919
1358.31	72.9559
1361.49	68.4586
1364.66	62.7584
1367.83	58.0706
1371	56.3294
1374.17	53.0747
1377.34	51.8927
1380.5	50.4569
1383.67	49.2864
1386.83	48.3846
1390	48.1278
1393.16	47.8981
1396.32	48.3247
1399.48	49.233
1402.64	49.292
1405.79	50.052
1408.95	51.2807
1412.1	52.7994
1415.26	55.8063
1418.41	60.0163
1421.56	64.918
1424.71	68.4103
1427.86	71.9614
1431	76.2055
1434.15	81.9447
1437.29	86.347
1440.44	91.3957
1443.58	94.1591
1446.72	95.6394
1449.86	95.9617
1453	94.6291
1456.14	94.1242
1459.27	91.1241
1462.41	86.9025
1465.54	82.5392
1468.67	75.5131
1471.81	68.937
1474.94	62.7995
1478.07	56.4106
1481.19	49.0328
1484.32	42.8446
1487.45	38.5421
1490.57	35.771
1493.69	32.3416
1496.82	29.9423
1499.94	28.1005
1503.06	27.431
1506.17	27.3615
1509.29	27.7102
1512.41	28.5976
1515.52	30.2341
1518.64	31.8723
1521.75	33.7285
1524.86	34.9688
1527.97	37.2335
1531.08	39.0494
1534.19	39.5867
1537.29	41.8673
1540.4	43.1145
1543.5	45.3007
1546.61	48.8071
1549.71	53.002
1552.81	56.9477
1555.91	60.5136
1559.01	63.2114
1562.11	67.4493
1565.2	70.781
1568.29	73.0322
1571.39	76.043
1574.48	79.5199
1577.57	82.597
1580.66	84.9878
1583.75	86.6778
1586.84	89.4115
1589.93	90.7422
1593.01	92.1015
1596.1	94.3962
1599.18	94.1186
1602.26	93.1518
1605.34	91.2312
1608.42	91.0902
1611.5	90.3346
1614.58	90.1637
1617.65	91.6304
1620.73	93.6147
1623.8	94.7832
1626.87	97.9663
1629.95	101.457
1633.02	104.215
1636.09	106.014
1639.15	110.08
1642.22	114.08
1645.29	118.744
1648.35	122.177
1651.42	125.903
1654.48	126.275
1657.54	126.895
1660.6	124.977
1663.66	123.631
1666.72	121.139
1669.77	117.183
1672.83	112.184
1675.88	106.599
1678.93	101.16
1681.99	94.5389
1685.04	88.4716
1688.09	80.4877
1691.13	73.3205
1694.18	67.416
1697.23	59.4975
1700.27	52.7764
1703.32	47.4152
1706.36	40.4941
1709.4	35.4079
1712.44	32.636
1715.48	30.7961
1718.52	28.5485
1721.56	26.5613
1724.59	23.7041
1727.63	21.5419
1730.66	18.9144
1733.69	17.896
1736.72	16.3297
1739.75	15.4921
1742.78	13.6269
1745.81	11.933
1748.84	11.4166
1751.86	12.8598
1754.89	13.0475
1757.91	12.0576
1760.93	10.734
1763.95	10.0079
1766.97	9.15218
1769.99	7.62016
1773.01	7.45495
1776.03	7.87916
1779.04	7.51516
1782.06	8.02097
1785.07	8.92441
1788.08	9.21843
1791.09	9.42071
1794.1	8.50049
1797.11	7.39399
1800.12	6.77024
1803.12	5.76165
1806.13	5.3895
1809.13	4.78827
1812.14	3.77524
1815.14	2.61447
1818.14	1.59069
1821.14	1.62161
1824.14	0.857098
1827.13	1.1737
1830.13	0.681249
1833.12	-0.520126
1836.12	-0.286846
1839.11	-0.631769
1842.1	-1.2235
1845.09	-0.926451
1848.08	-0.174172
1851.07	0.940508
1854.06	0.670329
1857.04	0.879533
1860.03	0.39474
1863.01	0.807631
1866	0.449555
1868.98	1.23768
1871.96	1.17078
1874.94	1.92302
1877.92	3.02978
1880.89	3.19896
1882.48	2.42732
1885.47	3.20046
1888.46	3.50216
1891.44	3.29479
1894.43	2.58554
1897.41	2.69802
1900.4	3.81397
1903.38	4.88872
1906.36	4.21858
1909.34	4.88158
1912.32	4.36954
1915.29	4.89883
1918.27	4.30168
1921.25	4.52504
1924.22	5.29069
1927.2	5.15617
1930.17	5.39818
1933.14	5.63938
1936.11	6.42227
1939.08	7.18712
1942.05	7.52301
1945.01	8.92852
1947.98	9.57912
1950.94	10.1158
1953.91	10.2183
1956.87	10.6648
1959.83	10.4227
1962.79	10.4897
1965.75	10.1983
1968.71	10.9369
1971.67	11.1892
1974.62	11.9583
1977.58	11.7479
1980.53	11.4569
1983.48	11.5822
1986.43	11.9607
1989.38	12.7902
1992.33	12.005
1995.28	11.6692
1998.23	11.3535
2001.18	10.6665
2004.12	10.7444
2007.06	10.3681
2010.01	10.2836
2012.95	10.263
2015.89	11.2645
2018.83	11.6039
2021.77	11.0394
2024.71	11.4477
2027.64	10.3882
2030.58	9.73983
2033.51	9.60916
2036.45	9.41366
2039.38	9.46162
2042.31	9.80823
2045.24	10.6558
2048.17	10.9527
2051.1	12.0066
2054.02	13.1774
2056.95	14.8322
2059.87	15.6815
2062.8	16.39
2065.72	16.7983
2068.64	17.4415
2071.56	18.3583
2074.48	19.2093
2077.4	20.1531
2080.31	20.9324
2083.23	22.3006
2086.14	23.9875
2089.06	25.2406
2091.97	26.408
2094.88	28.9035
2097.79	30.3951
2100.7	31.1945
2103.61	32.7298
2106.52	34.2049
2109.43	36.3987
2112.33	37.8681
2115.24	40.8402
2118.14	42.4584
2121.04	45.778
2123.94	49.2384
2126.84	53.7509
2129.74	57.4832
2132.64	60.8726
2135.54	65.067
2138.43	69.632
2141.33	74.0461
2144.22	79.3356
2147.11	84.6037
2150.01	89.2498
2152.9	94.1507
2155.79	98.7324
2158.67	103.905
2161.56	106.719
2164.45	109.671
2167.33	111.168
2170.22	112.012
2173.1	112.858
2175.98	113.152
2178.86	112.625
2181.74	111.028
2184.62	108.724
2187.5	107.401
2190.38	103.873
2193.25	100.43
2196.13	95.9149
2199	90.4433
2201.88	85.3131
2204.75	80.7635
2207.62	77.0772
2210.49	72.5853
2213.36	68.4608
2216.22	64.601
2219.09	59.824
2221.96	56.2091
2224.82	52.8026
2227.68	49.1887
2230.55	45.7745
2233.41	43.6165
2236.27	40.6535
2239.12	38.9338
2241.98	38.303
2244.84	37.1949
2247.7	36.2512
2250.55	35.501
2253.41	33.6215
2256.26	33.0881
2259.11	32.343
2261.96	31.2476
2264.81	29.3296
2267.66	28.7469
2270.51	27.1179
2273.35	26.2083
2276.2	24.2326
2279.04	22.6407
2281.89	21.6146
2284.73	20.3315
2287.57	18.5
2290.41	16.9807
2293.25	15.2412
2296.09	14.6015
2298.93	14.9722
2301.76	15.4443
2304.6	14.8476
2307.44	14.6179
2310.27	15.1766
2313.1	15.6278
2315.93	14.8562
2318.76	15.0122
2321.59	13.9395
2324.42	14.0513
2327.25	14.2215
2330.07	14.1953
2332.9	12.8134
2335.72	12.1856
2338.55	12.4866
2341.37	10.7378
2344.19	9.69955
2347.01	9.17979
2349.83	8.4487
2352.65	7.44856
2355.46	6.21295
2358.28	5.3581
2361.09	4.89975
2363.91	4.98858
2366.72	5.15725
2369.53	4.56206
2372.34	4.76053
2375.15	4.39711
2377.96	3.88053
2380.77	2.80961
2383.58	2.89957
2386.38	1.81342
2389.19	2.24035
2391.99	1.87649
2394.8	1.39824
2397.6	1.6591
2400.4	1.81645
2403.2	1.79517
2406	2.87288
2408.79	2.8311
2411.59	2.31867
2414.39	2.66116
2417.18	2.31665
2419.98	2.44327
2422.77	3.47146
2425.56	4.22193
2428.35	4.67474
2431.14	3.99523
2433.93	4.62257
2436.72	5.1234
2439.5	6.36269
2442.29	6.02651
2445.07	6.00682
2447.86	6.39811
2450.64	6.5731
2453.42	7.10341
2456.2	6.70689
2458.98	6.93429
2461.76	6.28538
2464.54	6.14521
2467.32	6.67924
2470.09	5.96834
2472.87	5.46353
2475.64	4.73104
2478.41	3.48281
2481.18	2.48724
2483.95	2.14708
2486.72	2.1232
2489.49	2.0297
2492.26	1.81844
2495.03	1.3863
2497.79	1.1838
2500.56	1.49217
2503.32	1.24578
2506.09	0.629986
2508.85	0.0693476
2511.61	-0.692402
2514.37	-0.793721
2517.13	-1.45165
2519.89	-1.29778
2522.64	-0.507977
2525.4	-0.260919
2528.15	0.503156
2530.91	1.31068
2533.66	1.89463
2536.41	2.64607
2539.16	2.70253
2541.91	2.82812
2544.66	2.87689
2547.41	2.51322
2550.16	2.88138
2552.9	3.34269
2555.65	3.88122
2558.39	5.25406
2561.13	4.88789
2563.88	4.67734
2566.62	4.24934
2569.36	2.83937
2572.1	2.4214
2574.84	1.45418
2577.57	0.218433
2580.31	0.274596
2583.05	-0.191068
2585.78	-0.541064
2588.51	-0.312825
2591.24	0.230101
2593.98	0.0956906
2596.71	0.36623
2599.44	-0.258564
2602.16	0.619523
2604.89	0.809664
2607.62	0.589205
2610.34	1.40663
2613.07	1.68442
2615.79	1.92435
2618.52	2.36874
2621.24	3.08233
2623.96	3.60352
2626.68	3.41855
2629.4	2.85015
2632.11	2.79657
2634.83	2.85959
2637.55	2.42311
2640.26	2.84719
2642.98	2.89881
2645.69	2.73833
2648.4	2.80246
2651.11	2.78586
2653.82	2.42028
2656.53	3.60408
2659.24	3.66032
2661.95	4.08003
2664.65	3.89716
2667.36	3.25836
2670.06	2.98054
2672.76	3.69837
2675.47	4.12756
2678.17	3.61731
2680.87	3.54183
2683.57	3.79185
2686.27	4.12328
2688.97	4.25391
2691.66	4.50612
2694.36	4.7656
2697.05	5.47327
2699.75	6.85717
2702.44	7.11601
2705.13	8.05286
2707.82	8.98167
2710.51	9.85621
2713.2	11.3505
2715.89	13.5512
2718.57	13.6305
2721.26	13.694
2723.95	14.9749
2726.63	14.7458
2729.31	14.7398
2732	14.3356
2734.68	14.7588
2737.36	13.9745
2740.04	13.3699
2742.72	13.5164
2745.39	13.6275
2748.07	13.6807
2750.75	13.6948
2753.42	15.1246
2756.09	14.8165
2758.77	15.2687
2761.44	14.7767
2764.11	15.1042
2766.78	14.485
2769.45	13.9791
2772.12	14.8014
2774.78	14.8487
2777.45	15.7768
2780.12	16.7523
2782.78	15.6375
2785.44	14.0971
2788.11	13.8469
2790.77	13.3141
2793.43	12.7009
2796.09	12.3626
2798.75	12.9471
2801.4	12.5836
2804.06	12.2309
2806.72	13.0598
2809.37	12.974
2812.03	13.2641
2814.68	13.8332
2817.33	15.324
2819.98	17.2547
2822.63	19.8733
2825.28	23.1249
2827.93	27.7115
2830.58	32.1525
2833.23	36.8253
2835.87	42.2181
2838.52	48.7294
2841.16	56.7225
2843.8	65.8543
2846.44	75.1624
2849.08	85.1458
2851.73	97.2868
2854.36	110.387
2857	123.133
2859.64	135.639
2862.28	148.309
2864.91	160.327
2867.55	170.658
2870.18	180.506
2872.81	189.501
2875.44	196.822
2878.07	205.403
2880.7	211.82
2883.33	219.475
2885.96	226.309
2888.59	232.351
2891.21	239.301
2893.84	245.084
2896.46	252.576
2899.09	260.174
2901.71	270.389
2904.33	283.121
2906.95	298.773
2909.57	315.841
2912.19	333.926
2914.81	352.588
2917.43	370.357
2920.04	385.67
2922.66	399.007
2925.27	409.908
2927.88	418.812
2930.5	424.179
2933.11	425.642
2935.72	423.749
2938.33	418.722
2940.94	412.592
2943.54	402.565
2946.15	391.447
2948.76	377.259
2951.36	360.65
2953.97	345.446
2956.57	329.552
2959.17	312.424
2961.77	296.069
2964.37	281.021
2966.97	267.328
2969.57	254.656
2972.17	242.293
2974.77	230.821
2977.36	219.506
2979.96	207.228
2982.55	195.249
2985.15	183.244
2987.74	170.671
2990.33	159.295
2992.92	146.442
2995.51	134.658
2998.1	122.528
3000.69	111.725
3003.27	102.138
3005.86	92.8869
3008.44	85.6126
3011.03	77.0924
3013.61	70.7884
3016.19	64.8345
3018.78	60.7536
3021.36	56.5022
3023.94	52.8444
3026.51	50.0365
3029.09	48.9691
3031.67	48.0855
3034.24	46.8775
3036.82	48.0922
3039.39	49.2102
3041.97	49.9083
3044.54	50.6731
3047.11	52.4281
3049.68	52.2218
3052.25	51.8402
3054.82	51.8579
3057.39	50.3796
3059.96	48.5402
3062.52	46.8241
3065.09	45.1444
3067.65	43.1876
3070.22	40.2552
3072.78	36.4208
3075.34	32.7746
3077.9	29.4774
3080.46	26.5927
3083.02	23.3467
3085.58	19.5608
3088.14	16.2837
3090.69	13.5613
3093.25	11.5252
3095.8	9.31986
3098.36	8.47892
3100.91	7.77203
3103.46	7.18841
3106.01	6.36255
3108.56	6.27151
3111.11	5.81272
3113.66	5.33858
3116.21	5.36436
3118.76	5.05876
3121.3	4.74834
3123.85	4.76834
3126.39	4.92182
3128.93	5.30717
3131.48	3.78429
3134.02	2.90217
3136.56	2.38258
3139.1	2.30384
3141.64	1.34539
3144.17	-0.469754
3146.71	-2.07251
3149.25	-3.83937