File: data/Raman/poly_smoothed/Thy_20_09_11_1x_45s_532 nm_x100_100%_600 gr_mm_01.txt
#Acq. time (s)=	45
#Accumulations=	2
#Range (cm-¹)=	200...3150
#Windows=	2
#Auto scanning=	Off
#Autofocus=	Off
#Macrospot=	Off
#AutoExposure=	Off
#Spike filter=	Multiple accum.
#Delay time (s)=	0
#Binning=	1
#Readout mode=	Signal
#DeNoise=	Off
#ICS correction=	On
#Dark correction=	Off
#Inst. Process=	Off
#Detector Gain=	Best Dynamic Range
#Detector ADC=	20 kHz
#Detector temperature (°C)=	-69.85
#Instrument=	LabRAM HR Evol
#Detector=	Synapse
#Objective=	x100
#Grating=	600 gr/mm
#ND Filter=	100%
#Laser (nm)=	532
#Hole=	100.021
#Range=	Auto
#Laser Pol.=	No
#Raman. Pol.=	No
#Laser Pol. (°)=	-0.0007625
#Raman Pol. (°)=	89.9995
#Collection=	Microscope
#StageXY=	Marzhauser
#StageZ=	Marzhauser
#X (µm)=	-5888.7
#Y (µm)=	2844.4
#Z (µm)=	-223.65
#Full time(mm:ss)=	3:18
#Project=
#Sample=
#Site=
#Title=	Thy_20_09_11_2x_45s_532 nm_x100_100%_600 gr_mm
#Remark=
#Date=	29.06.2022 11:29
#Acquired=	29.06.2022 11:29:35
#Base:Fit=	10.08.2022 09:52:02
#Base:Fit=	10.08.2022 09:52:12
#Base:Sub=	10.08.2022 09:54:21
#Filter:Polynom=	16.08.2022 10:24:04
#AxisType[0]=Intens
#AxisUnit[0]=Cnt
#AxisType[1]=Spectr
#AxisUnit[1]=1/cm
200.523	0.126491
204.154	1.46033
207.781	2.59703
211.409	3.93947
215.034	5.29767
218.659	5.81517
222.281	6.92201
225.903	6.27716
229.522	5.02245
233.14	6.87187
236.756	5.58995
240.373	4.43228
243.986	4.04764
247.598	5.42457
251.208	7.16668
254.818	7.66171
258.427	6.52762
262.034	6.62388
265.638	8.39149
269.242	9.33628
272.844	10.389
276.445	12.1564
280.044	14.3047
283.642	14.1396
287.238	14.8293
290.833	16.3098
294.425	18.468
298.017	21.0811
301.608	22.3612
305.198	23.9819
308.786	24.4816
312.371	24.7012
315.956	24.4702
319.54	25.8277
323.122	24.9705
326.701	21.9695
330.281	23.2557
333.857	24.2089
337.434	25.0833
341.008	24.0267
344.582	23.8199
348.153	23.7852
351.724	23.8063
355.292	23.1993
358.861	22.568
362.426	21.1964
365.99	21.6954
369.555	21.3037
373.116	21.1644
376.676	21.19
380.236	21.3544
383.793	21.2813
387.349	19.6959
390.903	18.2791
394.456	16.8115
398.007	15.0616
401.56	12.6785
405.108	10.2931
408.656	9.12675
412.202	7.14718
415.746	6.19082
419.29	5.32242
422.831	3.8493
426.37	3.98253
429.909	4.07389
433.447	3.68696
436.983	4.23921
440.519	5.29345
444.052	5.01525
447.583	3.77945
451.114	6.58915
454.643	8.02823
458.169	9.38455
461.696	10.4367
465.222	11.1742
468.744	12.3404
472.267	14.0991
475.787	14.2739
479.307	14.6955
482.823	15.9865
486.341	17.3726
489.855	18.1576
493.37	20.8364
496.881	21.0778
500.391	21.5472
503.902	21.6019
507.409	22.3323
510.915	23.6711
514.42	24.1495
517.925	24.1076
521.427	24.7448
524.928	24.9398
528.427	21.9913
531.925	20.2272
535.422	20.1132
538.917	20.9157
542.411	20.6752
545.903	19.6329
549.395	18.0577
552.884	17.6292
556.373	15.8905
559.86	13.6686
563.346	12.4314
566.831	11.4004
570.314	10.8207
573.794	9.95251
577.274	8.32347
580.754	7.48808
584.23	5.12648
587.706	3.02991
591.181	2.08191
594.653	1.62859
598.126	1.28139
601.595	1.36932
605.065	1.46963
608.532	0.829965
611.999	2.03087
615.463	4.22835
618.928	5.65802
622.389	6.84075
625.851	7.79005
629.31	7.62106
632.767	8.15335
636.223	9.53125
639.68	10.9722
643.134	11.4453
646.586	11.9335
650.037	12.5701
653.486	13.9751
656.936	14.5203
660.383	14.3221
663.829	13.6964
667.273	13.5282
670.716	11.5299
674.158	11.9928
677.598	12.3193
681.035	13.4784
684.473	13.197
687.909	13.2116
691.344	14.9823
694.778	16.8864
698.211	18.3625
701.64	18.4884
705.07	18.8235
708.498	20.6659
711.924	21.8335
715.35	23.9782
718.774	26.4697
722.196	29.4876
725.618	30.711
729.037	32.1367
732.456	34.6498
735.873	37.8124
739.289	40.0812
742.703	41.3612
746.116	43.2839
749.529	45.0294
752.938	47.6698
756.347	50.3514
759.756	51.5589
763.162	52.1899
766.567	53.8305
769.97	55.9442
773.372	58.3864
776.773	59.8726
780.174	58.9128
783.573	57.5137
786.97	58.975
790.365	59.6843
793.76	59.7319
797.153	59.6916
800.543	58.1322
803.933	57.6196
807.322	57.8673
810.71	59.0958
814.097	59.4688
817.483	60.1305
820.865	58.7707
824.248	57.7918
827.629	56.0521
831.008	56.2162
834.387	54.7573
837.765	54.7522
841.139	53.3869
844.514	50.8691
847.886	50.5186
851.259	50.9826
854.629	50.5808
857.997	47.9086
861.366	45.3271
864.732	42.261
868.098	40.7434
871.461	40.1037
874.823	38.6097
878.184	37.0902
881.545	36.0703
884.903	36.6388
888.26	37.1328
891.616	38.3617
894.97	38.0792
898.323	38.4396
901.675	38.7126
905.026	41.314
908.375	41.4606
911.723	41.5364
915.07	40.3862
918.415	39.2035
921.76	38.7782
925.103	38.4204
928.443	39.4007
931.783	38.042
935.123	36.5814
938.461	34.2538
941.796	32.2016
945.131	28.4388
948.465	24.5659
951.797	22.693
955.128	20.3463
958.457	18.6168
961.786	17.2104
965.113	18.211
968.44	19.639
971.763	21.4541
975.086	23.5611
978.409	25.0889
981.729	25.905
985.048	26.7219
988.367	27.4245
991.683	27.866
994.998	27.4292
998.312	27.4642
1001.62	25.8924
1004.94	26.1171
1008.25	26.1205
1011.56	25.3871
1014.86	22.2382
1018.17	22.0422
1021.48	20.6221
1024.78	17.6057
1028.08	16.0036
1031.38	14.6005
1034.68	12.4944
1037.98	10.8883
1041.28	10.687
1044.57	12.9851
1047.87	12.5339
1051.16	11.9434
1054.45	12.7147
1057.75	10.4741
1061.04	9.7155
1064.32	10.0363
1067.61	11.5934
1070.9	11.0648
1074.18	11.6996
1077.47	10.9699
1080.75	11.9426
1084.03	12.4289
1087.31	13.4828
1090.59	14.0914
1093.86	14.3565
1097.14	14.5982
1100.41	17.0997
1103.69	16.9208
1106.96	17.1688
1110.23	17.2335
1113.5	14.802
1116.77	12.9878
1120.03	13.8001
1123.3	12.5689
1126.56	9.18483
1129.83	7.63006
1133.09	8.45121
1136.35	7.69563
1139.61	7.42152
1142.86	7.27912
1146.12	8.09317
1149.38	8.15562
1152.63	8.39322
1155.88	9.81476
1159.14	11.0308
1162.39	10.4028
1165.63	10.1926
1168.88	11.0795
1172.13	12.9775
1175.38	14.239
1178.62	16.3512
1181.86	19.1954
1185.1	19.3788
1188.34	22.6708
1191.58	22.7643
1194.82	23.3529
1198.06	25.0189
1201.29	25.6947
1204.53	26.834
1207.76	30.4296
1210.99	35.3649
1214.22	37.7129
1217.45	41.9345
1220.68	45.8244
1223.91	49.6264
1227.13	53.1162
1230.36	56.4956
1233.58	59.6835
1236.8	63.5588
1240.02	66.9627
1243.24	69.5171
1246.46	72.9889
1249.67	74.5785
1252.89	76.5532
1256.1	79.5245
1259.32	81.6952
1262.53	83.7362
1265.74	85.1169
1268.95	86.9933
1272.15	87.9669
1275.36	88.8345
1278.57	90.2848
1281.77	92.7782
1284.97	97.1224
1288.18	99.5105
1291.38	100.722
1294.58	103.54
1297.78	107.366
1300.97	109.002
1304.17	112.512
1307.36	115.32
1310.55	118.086
1313.75	120.524
1316.94	121.255
1320.13	123.502
1323.32	123.951
1326.5	124.177
1329.69	123.637
1332.87	122.984
1336.06	123.284
1339.24	121.924
1342.42	121.351
1345.6	119.46
1348.78	117.998
1351.96	115.364
1355.13	112.56
1358.31	112.085
1361.48	108.83
1364.65	104.969
1367.82	102.114
1370.99	99.9955
1374.16	97.7668
1377.33	94.3982
1380.5	93.1491
1383.66	91.6543
1386.83	90.2583
1389.99	89.4079
1393.15	87.225
1396.31	85.4249
1399.47	85.6877
1402.63	83.5025
1405.78	84.1089
1408.94	83.8181
1412.1	84.4173
1415.25	86.0968
1418.4	88.2458
1421.55	90.7267
1424.7	92.8055
1427.85	96.587
1431	100.06
1434.14	103.331
1437.29	107.531
1440.43	108.901
1443.57	109.551
1446.71	111.456
1449.85	112.586
1452.99	111.392
1456.13	109.302
1459.26	106.46
1462.4	102.894
1465.54	99.7073
1468.67	93.8644
1471.8	86.519
1474.93	80.2557
1478.06	75.7636
1481.19	70.7574
1484.31	67.5475
1487.44	62.4739
1490.56	58.9966
1493.69	56.3842
1496.81	54.1447
1499.93	52.975
1503.05	53.0474
1506.17	54.6517
1509.28	55.6396
1512.4	55.7425
1515.52	53.9111
1518.63	53.8504
1521.74	58.4965
1524.85	65.161
1527.96	68.1884
1531.07	70.962
1534.18	74.3245
1537.29	77.4781
1540.39	82.4043
1543.5	86.4968
1546.6	91.5175
1549.7	96.5307
1552.8	102.749
1555.9	105.649
1559	108.583
1562.1	111.048
1565.19	113.174
1568.29	116.165
1571.38	117.922
1574.47	120.277
1577.56	122.406
1580.66	123.245
1583.74	124.797
1586.83	124.436
1589.92	122.685
1593.01	121.667
1596.09	125.382
1599.17	124.742
1602.25	122.097
1605.34	118.627
1608.41	115.369
1611.49	112.304
1614.57	108.943
1617.65	106.296
1620.72	103.646
1623.79	102.763
1626.87	99.5795
1629.94	96.9691
1633.01	94.7557
1636.08	93.9107
1639.15	94.3931
1642.21	94.2275
1645.28	94.3509
1648.34	94.9947
1651.41	95.7823
1654.47	95.8655
1657.53	96.1838
1660.59	95.094
1663.65	91.2897
1666.71	88.7704
1669.76	84.6811
1672.82	80.6214
1675.87	75.587
1678.93	70.0791
1681.98	65.5521
1685.03	57.9247
1688.08	52.0639
1691.13	45.9588
1694.17	39.2099
1697.22	34.1293
1700.27	29.2135
1703.31	25.1541
1706.35	22.1292
1709.39	18.7894
1712.43	15.4133
1715.47	13.5423
1718.51	11.8767
1721.55	11.0788
1724.58	9.99372
1727.62	10.5424
1730.65	10.6849
1733.68	10.537
1736.72	11.2542
1739.74	11.9755
1742.77	12.2199
1745.8	12.2518
1748.83	11.9583
1751.85	11.7522
1754.88	11.181
1757.9	10.8873
1760.92	10.3444
1763.95	9.121
1766.96	7.06002
1769.98	7.49438
1773	7.40443
1776.02	7.25024
1779.03	6.60463
1782.05	6.85405
1785.06	7.34691
1788.07	6.55824
1791.08	6.74348
1794.09	6.20664
1797.1	6.02665
1800.11	6.7498
1803.12	6.74282
1806.12	6.68283
1809.12	6.28537
1812.13	6.37754
1815.13	4.79037
1818.13	4.44841
1821.13	3.21102
1824.13	3.29242
1827.13	2.90349
1830.12	2.39007
1833.12	2.29889
1836.11	2.3499
1839.1	2.85799
1842.09	2.92179
1845.09	3.1169
1848.08	2.66322
1851.06	2.59011
1854.05	2.67154
1857.04	2.55024
1860.02	1.77645
1863.01	1.60063
1865.99	1.75522
1868.97	1.36748
1871.95	2.13538
1874.93	1.91467
1877.91	1.9879
1880.89	2.29327
1882.46	2.36157
1885.45	2.42831
1888.43	2.25634
1891.42	2.09931
1894.41	2.6385
1897.39	3.14467
1900.37	3.0694
1903.36	4.2809
1906.34	5.09456
1909.32	5.34086
1912.29	5.46731
1915.27	5.39381
1918.25	6.00735
1921.23	6.90868
1924.2	7.26969
1927.17	7.63799
1930.15	7.39777
1933.12	6.47661
1936.09	6.65194
1939.06	5.69654
1942.02	6.00239
1944.99	4.98588
1947.96	4.2964
1950.92	4.71655
1953.88	4.86918
1956.85	4.6312
1959.81	3.92856
1962.77	1.88697
1965.73	1.75611
1968.69	1.73644
1971.64	1.83407
1974.6	1.43161
1977.55	1.30057
1980.51	1.6661
1983.46	3.2933
1986.41	4.93596
1989.36	5.49462
1992.31	6.58225
1995.26	7.14214
1998.21	6.61182
2001.15	6.71732
2004.1	6.9944
2007.04	6.63074
2009.99	7.16399
2012.93	8.26105
2015.87	7.49219
2018.81	7.72893
2021.75	8.84529
2024.68	8.65145
2027.62	9.02198
2030.56	7.87924
2033.49	8.4052
2036.42	8.63144
2039.36	8.63509
2042.29	9.21832
2045.22	9.34248
2048.14	9.89269
2051.07	10.7894
2054	12.0812
2056.93	12.2457
2059.85	11.453
2062.77	11.895
2065.7	10.7163
2068.62	11.222
2071.54	11.5441
2074.46	10.9949
2077.38	11.0241
2080.29	11.1613
2083.21	11.829
2086.12	12.8625
2089.04	12.4705
2091.95	13.8666
2094.86	13.931
2097.77	15.0488
2100.68	16.1539
2103.59	17.6355
2106.5	18.6151
2109.41	19.63
2112.31	20.8559
2115.21	22.1024
2118.12	23.7329
2121.02	25.8305
2123.92	27.2766
2126.82	27.2627
2129.72	28.1812
2132.62	29.5122
2135.51	30.8461
2138.41	31.4275
2141.31	31.6925
2144.2	32.6496
2147.09	34.5054
2149.98	36.3112
2152.87	38.1927
2155.76	40.6597
2158.65	41.306
2161.54	43.4443
2164.43	44.3737
2167.31	45.6502
2170.2	46.8166
2173.08	46.5667
2175.96	45.9018
2178.84	45.5632
2181.72	44.9784
2184.6	44.1048
2187.48	43.5578
2190.36	41.7385
2193.23	40.5507
2196.11	38.0022
2198.98	35.895
2201.85	34.8316
2204.72	32.746
2207.59	30.8582
2210.46	28.6366
2213.33	27.222
2216.2	25.5817
2219.07	24.1417
2221.93	21.8089
2224.8	20.7758
2227.66	19.1577
2230.52	18.7626
2233.39	18.4794
2236.25	16.8955
2239.1	15.5238
2241.96	14.6624
2244.82	14.7088
2247.68	14.153
2250.53	13.1411
2253.38	12.1894
2256.24	11.4234
2259.09	11.6259
2261.94	10.9079
2264.79	11.7177
2267.64	12.3525
2270.49	12.5823
2273.33	12.8261
2276.18	13.0488
2279.02	13.0284
2281.87	11.5074
2284.71	10.054
2287.55	9.07099
2290.39	7.41128
2293.23	6.48674
2296.07	7.57209
2298.91	7.52706
2301.74	7.27678
2304.58	6.86222
2307.41	7.35476
2310.25	8.5646
2313.08	8.52948
2315.91	7.72611
2318.74	6.09723
2321.57	4.34914
2324.4	4.8036
2327.23	5.83879
2330.05	5.57323
2332.88	6.03145
2335.7	6.96956
2338.52	6.66538
2341.35	7.09664
2344.17	6.12826
2346.99	5.36996
2349.81	4.2412
2352.62	4.28564
2355.44	3.72353
2358.26	2.92306
2361.07	2.77251
2363.89	4.56356
2366.7	4.48559
2369.51	4.89366
2372.32	5.35991
2375.13	5.92624
2377.94	5.91885
2380.75	6.57457
2383.56	4.6827
2386.36	4.3964
2389.17	5.38085
2391.97	5.2475
2394.77	5.16705
2397.58	4.99546
2400.38	5.03075
2403.18	4.44628
2405.97	3.71425
2408.77	3.0825
2411.57	2.63301
2414.37	1.91597
2417.16	2.7167
2419.95	2.64734
2422.75	2.3868
2425.54	1.50794
2428.33	0.92227
2431.12	1.70338
2433.91	1.17131
2436.7	1.10852
2439.48	2.64303
2442.27	2.73142
2445.05	3.54749
2447.84	4.16088
2450.62	4.22576
2453.4	4.54347
2456.18	4.22819
2458.96	4.4833
2461.74	3.49858
2464.52	3.44375
2467.29	3.48886
2470.07	3.20922
2472.85	2.85595
2475.62	2.94184
2478.39	2.35224
2481.16	2.75516
2483.93	1.73278
2486.7	1.83083
2489.47	0.73787
2492.24	0.673129
2495.01	0.00971426
2497.77	-0.594759
2500.54	-0.124004
2503.3	1.15057
2506.06	1.59429
2508.83	1.95459
2511.59	2.50593
2514.35	3.44515
2517.11	3.9887
2519.86	4.88198
2522.62	5.4022
2525.38	5.95469
2528.13	5.80348
2530.89	6.92923
2533.64	8.05607
2536.39	7.80247
2539.14	7.46799
2541.89	7.13383
2544.64	5.8793
2547.39	5.34577
2550.14	5.77107
2552.88	5.16548
2555.63	4.66084
2558.37	2.36633
2561.11	2.03709
2563.86	1.62482
2566.6	1.97201
2569.34	2.06221
2572.08	2.04136
2574.82	2.65738
2577.55	2.40048
2580.29	3.90784
2583.02	4.50937
2585.76	6.10522
2588.49	5.96985
2591.22	6.8208
2593.96	7.96706
2596.69	8.26352
2599.42	8.50156
2602.14	8.06034
2604.87	7.29176
2607.6	6.56013
2610.32	6.90131
2613.05	6.92983
2615.77	7.80102
2618.49	7.20608
2621.22	7.46998
2623.94	6.47085
2626.66	6.26458
2629.37	7.11607
2632.09	7.52458
2634.81	7.46702
2637.53	7.88571
2640.24	7.64703
2642.96	8.31655
2645.67	9.88182
2648.38	10.0526
2651.09	10.4182
2653.8	9.42378
2656.51	9.36526
2659.22	9.3753
2661.93	8.84039
2664.63	8.05775
2667.34	7.48688
2670.04	7.46464
2672.75	7.2499
2675.45	7.73622
2678.15	7.39299
2680.85	6.71295
2683.55	6.85395
2686.25	7.10961
2688.94	7.13705
2691.64	7.24039
2694.34	7.64103
2697.03	8.39812
2699.73	9.69352
2702.42	10.3671
2705.11	11.2465
2707.8	12.6784
2710.49	13.6732
2713.18	14.5155
2715.87	13.8774
2718.55	13.98
2721.24	14.2231
2723.93	15.0122
2726.61	14.3605
2729.29	14.1943
2731.98	13.6495
2734.66	13.3289
2737.34	12.1123
2740.02	11.9376
2742.7	11.5501
2745.37	10.3278
2748.05	10.5092
2750.72	10.2117
2753.4	10.1555
2756.07	8.9578
2758.75	8.78293
2761.42	9.03588
2764.09	8.98335
2766.76	8.50333
2769.43	7.83495
2772.1	6.99907
2774.76	6.16296
2777.43	4.7367
2780.1	4.54023
2782.76	3.90059
2785.42	3.29268
2788.09	3.12733
2790.75	2.45954
2793.41	1.56451
2796.07	0.701035
2798.73	0.12725
2801.39	0.139136
2804.04	-0.42845
2806.7	0.687512
2809.35	0.516789
2812.01	0.72295
2814.66	1.96163
2817.31	2.7345
2819.96	4.42679
2822.61	5.65377
2825.26	7.97071
2827.91	10.7209
2830.56	13.6924
2833.21	16.9306
2835.85	22.1309
2838.5	25.5946
2841.14	30.3907
2843.78	36.3672
2846.42	42.4479
2849.06	50.1472
2851.71	57.285
2854.34	65.2034
2856.98	72.3272
2859.62	80.3427
2862.26	87.7976
2864.89	95.3015
2867.53	101.285
2870.16	106.701
2872.79	111.479
2875.42	115.463
2878.05	119.738
2880.68	122.754
2883.31	126.879
2885.94	129.847
2888.57	132.71
2891.19	136.389
2893.82	140.511
2896.44	144.1
2899.07	148.225
2901.69	153.751
2904.31	159.473
2906.93	167.029
2909.55	175.351
2912.17	185.077
2914.79	194.709
2917.41	203.715
2920.02	211.299
2922.64	217.356
2925.25	222.502
2927.86	224.307
2930.48	225.958
2933.09	225.082
2935.7	223.55
2938.31	220.745
2940.92	216.254
2943.53	210.228
2946.13	204.16
2948.74	196.438
2951.34	188.315
2953.95	179.563
2956.55	170.882
2959.15	161.832
2961.75	153.154
2964.35	145.618
2966.95	138.439
2969.55	131.687
2972.15	125.482
2974.75	120.042
2977.34	113.936
2979.94	105.914
2982.53	99.3841
2985.13	91.3962
2987.72	82.6587
2990.31	74.6926
2992.9	67.6347
2995.49	60.7333
2998.08	54.1551
3000.67	47.6957
3003.25	42.2681
3005.84	36.7635
3008.42	31.6953
3011.01	26.9198
3013.59	22.7626
3016.17	19.0445
3018.76	15.7859
3021.34	13.8314
3023.92	11.1857
3026.49	9.9636
3029.07	8.82154
3031.65	8.42429
3034.23	8.50295
3036.8	8.98388
3039.38	10.0977
3041.95	11.0061
3044.52	11.3114
3047.09	12.1698
3049.66	12.8146
3052.23	13.3539
3054.8	14.1933
3057.37	14.114
3059.94	13.8776
3062.5	13.5092
3065.07	12.2878
3067.63	12.3929
3070.2	11.4525
3072.76	9.58024
3075.32	8.6305
3077.88	7.00558
3080.44	5.75006
3083	3.89343
3085.56	2.66201
3088.12	1.59651
3090.67	0.0734724
3093.23	-1.00969
3095.78	-1.12023
3098.34	-0.999062
3100.89	-1.03575
3103.44	-0.842306
3105.99	-0.0687103
3108.54	-0.539057
3111.09	0.623385
3113.64	1.27771
3116.19	1.89184
3118.74	2.2553
3121.28	2.94862
3123.83	3.83973
3126.37	4.84491
3128.91	6.07781
3131.46	7.0351
3134	7.97282
3136.54	10.2152
3139.08	11.6795
3141.62	13.2224
3144.16	14.7514
3146.69	15.628
3149.23	15.8184