File: data/Raman/poly_smoothed/Thy_00_07_31_1x_45s_532 nm_x100_100%_600 gr_mm_01.txt
#Acq. time (s)=	45
#Accumulations=	2
#Range (cm-¹)=	200...3150
#Windows=	2
#Auto scanning=	Off
#Autofocus=	Off
#Macrospot=	Off
#AutoExposure=	Off
#Spike filter=	Multiple accum.
#Delay time (s)=	0
#Binning=	1
#Readout mode=	Signal
#DeNoise=	Off
#ICS correction=	On
#Dark correction=	Off
#Inst. Process=	Off
#Detector Gain=	Best Dynamic Range
#Detector ADC=	20 kHz
#Detector temperature (°C)=	-69.85
#Instrument=	LabRAM HR Evol
#Detector=	Synapse
#Objective=	x100
#Grating=	600 gr/mm
#ND Filter=	100%
#Laser (nm)=	532
#Hole=	100.021
#Range=	Auto
#Laser Pol.=	No
#Raman. Pol.=	No
#Laser Pol. (°)=	-0.0007625
#Raman Pol. (°)=	89.9995
#Collection=	Microscope
#StageXY=	Marzhauser
#StageZ=	Marzhauser
#X (µm)=	8979
#Y (µm)=	-3071.3
#Z (µm)=	-55.05
#Full time(mm:ss)=	3:18
#Project=
#Sample=
#Site=
#Title=	Thy_00_07_31_2x_45s_532 nm_x100_100%_600 gr_mm
#Remark=
#Date=	28.06.2022 12:22
#Acquired=	28.06.2022 12:22:35
#Base:Fit=	10.08.2022 10:07:56
#Base:Sub=	10.08.2022 10:08:40
#Filter:Polynom=	16.08.2022 10:26:06
#AxisType[0]=Intens
#AxisUnit[0]=Cnt
#AxisType[1]=Spectr
#AxisUnit[1]=1/cm
200.407	0.579406
204.035	2.30386
207.665	3.85181
211.291	5.92206
214.916	9.21878
218.541	11.5669
222.163	13.7574
225.785	14.4338
229.404	14.1248
233.022	14.2543
236.638	13.796
240.255	13.7171
243.868	12.4322
247.48	11.7673
251.091	11.1906
254.702	10.5992
258.31	9.12768
261.916	9.52244
265.521	9.34128
269.125	9.78866
272.727	10.6261
276.328	11.7015
279.927	10.819
283.525	12.6382
287.121	13.1779
290.716	14.0624
294.31	15.9553
297.9	17.9288
301.491	19.3571
305.081	21.6556
308.669	21.7403
312.256	22.3978
315.839	23.3398
319.423	24.4824
323.006	24.3621
326.585	24.0798
330.165	23.958
333.741	22.7359
337.318	22.0523
340.894	21.6993
344.466	21.8608
348.039	21.6981
351.608	20.561
355.176	20.2771
358.745	20.5084
362.31	20.0605
365.876	18.1877
369.439	17.8821
373	18.3808
376.56	17.6532
380.12	16.8103
383.677	15.6481
387.233	14.8736
390.787	15.2026
394.34	13.8982
397.894	13.6247
401.444	14.0318
404.993	14.1514
408.54	13.9814
412.086	13.4786
415.631	14.4461
419.174	14.8896
422.716	15.3068
426.257	14.9979
429.794	15.8471
433.332	14.955
436.868	14.4148
440.403	13.7381
443.937	17.0068
447.468	19.65
450.999	22.6579
454.528	27.5783
458.057	31.9969
461.582	35.3257
465.107	37.3161
468.629	38.2708
472.152	39.3312
475.672	41.8245
479.192	42.1914
482.709	44.1516
486.226	44.6968
489.74	44.8849
493.255	44.5418
496.767	43.963
500.277	42.8135
503.788	40.4766
507.295	38.4362
510.801	34.139
514.308	30.1104
517.811	25.7781
521.313	22.0518
524.814	20.0466
528.313	19.4883
531.811	16.8337
535.308	15.7294
538.803	13.869
542.297	13.2378
545.789	12.212
549.281	12.966
552.771	10.4148
556.259	9.57603
559.747	8.87569
563.233	8.23627
566.717	8.0578
570.2	8.38217
573.68	8.07513
577.161	7.14444
580.64	6.48362
584.118	7.16565
587.593	7.12051
591.068	7.30283
594.54	5.92044
598.013	5.2323
601.484	4.63933
604.952	5.37986
608.421	3.33294
611.886	3.45742
615.35	2.34879
618.815	2.31328
622.276	3.11681
625.738	5.61262
629.197	6.17768
632.655	5.95582
636.113	6.24047
639.568	4.34658
643.021	5.90031
646.473	6.87958
649.924	6.67218
653.376	8.22005
656.824	8.67802
660.271	8.04021
663.716	8.69749
667.161	9.37137
670.604	10.3133
674.045	11.8332
677.486	13.0994
680.925	12.5541
684.361	13.8474
687.797	16.0226
691.232	16.8229
694.666	17.9921
698.099	19.5127
701.528	21.344
704.958	23.5082
708.387	25.249
711.814	24.4173
715.238	25.4065
718.663	26.5041
722.084	28.2026
725.506	31.165
728.925	32.7876
732.345	34.5078
735.761	36.8928
739.178	39.3398
742.592	41.5557
746.006	46.2107
749.417	49.5656
752.827	53.8175
756.236	57.3813
759.645	58.9278
763.051	61.2492
766.456	63.1412
769.859	65.2915
773.261	67.2114
776.664	68.4457
780.064	68.2303
783.462	68.5827
786.859	68.5804
790.255	68.2609
793.649	68.7992
797.042	68.304
800.434	68.2138
803.823	67.6641
807.212	67.1513
810.6	66.711
813.987	68.7337
817.372	70.6789
820.754	72.7495
824.137	75.7844
827.519	77.8989
830.897	79.1614
834.276	79.5779
837.654	79.6594
841.029	78.0838
844.404	78.9486
847.776	77.858
851.149	76.5536
854.519	73.8187
857.889	71.6185
861.256	67.6459
864.622	64.7533
867.988	62.1714
871.351	59.5232
874.713	55.7882
878.074	52.715
881.435	48.962
884.794	46.8101
888.15	44.9236
891.506	45.3295
894.861	46.2606
898.214	46.2959
901.566	47.4734
904.916	49.5201
908.266	51.7994
911.614	54.3416
914.961	57.1169
918.306	58.4771
921.651	60.3223
924.994	61.2226
928.336	61.4027
931.674	61.2361
935.014	57.9966
938.352	57.031
941.687	54.7324
945.022	52.3898
948.357	48.9232
951.688	46.3378
955.02	42.2784
958.348	37.7342
961.678	32.958
965.004	30.1707
968.331	28.8016
971.655	26.6395
974.979	26.5697
978.3	26.9664
981.62	28.1997
984.941	28.7259
988.259	29.0805
991.575	29.805
994.89	30.6052
998.204	31.4921
1001.52	33.7933
1004.83	35.8308
1008.14	37.3807
1011.45	38.2895
1014.76	39.5155
1018.06	41.095
1021.37	41.8991
1024.67	41.4282
1027.97	41.1551
1031.27	39.3217
1034.57	37.8893
1037.87	35.1948
1041.17	32.5633
1044.47	31.5547
1047.76	33.4365
1051.06	34.4244
1054.35	33.486
1057.64	33.8872
1060.93	33.4251
1064.22	32.2602
1067.5	31.688
1070.79	32.2265
1074.08	33.7657
1077.36	36.0005
1080.64	39.0373
1083.92	40.7939
1087.2	42.5451
1090.48	43.0921
1093.76	45.4043
1097.03	46.8995
1100.31	47.0986
1103.58	47.7413
1106.85	47.778
1110.12	47.9666
1113.39	46.2057
1116.66	44.7869
1119.93	43.9175
1123.19	42.1593
1126.46	41.5792
1129.72	41.48
1132.98	39.4083
1136.24	37.8872
1139.5	36.3314
1142.76	34.5331
1146.01	32.3006
1149.27	29.326
1152.53	27.1335
1155.78	24.6725
1159.03	20.6699
1162.28	17.355
1165.53	14.5486
1168.78	11.795
1172.02	9.89746
1175.27	8.04494
1178.51	5.86183
1181.76	5.70056
1185	5.5568
1188.24	7.31952
1191.48	7.76172
1194.71	8.43767
1197.95	11.198
1201.19	11.9468
1204.42	14.5609
1207.65	17.1961
1210.88	21.0752
1214.12	24.1968
1217.35	26.2909
1220.57	30.2982
1223.8	33.8088
1227.03	36.5594
1230.25	38.369
1233.47	41.002
1236.69	41.9857
1239.92	44.1019
1243.13	43.9529
1246.35	44.3239
1249.57	43.6913
1252.78	43.6027
1256	44.2355
1259.21	42.8415
1262.42	44.1056
1265.63	42.3268
1268.84	42.1906
1272.05	41.6446
1275.26	41.7779
1278.46	41.774
1281.67	43.1263
1284.87	45.3801
1288.07	48.9045
1291.27	50.5202
1294.47	52.4747
1297.67	55.0899
1300.87	60.1041
1304.06	63.7915
1307.26	67.6542
1310.45	73.5241
1313.64	77.3743
1316.83	81.9989
1320.02	86.3289
1323.21	88.7993
1326.4	91.2749
1329.59	92.5323
1332.77	93.771
1335.95	94.1066
1339.14	93.2705
1342.32	93.1421
1345.5	92.2855
1348.67	90.7712
1351.85	89.309
1355.03	88.2164
1358.2	86.4687
1361.38	84.5821
1364.55	80.7576
1367.72	77.4846
1370.89	73.7038
1374.06	70.6897
1377.23	68.3266
1380.39	66.8955
1383.56	66.7104
1386.72	64.5162
1389.89	64.4957
1393.05	62.5129
1396.21	60.0855
1399.37	58.4873
1402.52	56.6761
1405.68	56.5912
1408.84	55.7163
1411.99	56.7051
1415.15	56.3389
1418.3	57.2604
1421.45	57.6332
1424.6	59.8811
1427.75	62.6094
1430.89	66.7055
1434.04	69.4271
1437.18	70.651
1440.33	74.4256
1443.47	75.9609
1446.61	76.0282
1449.75	76.3023
1452.89	75.8026
1456.03	74.1826
1459.16	73.2704
1462.3	68.5689
1465.43	63.4916
1468.56	59.4578
1471.7	53.8397
1474.83	48.3451
1477.96	43.0184
1481.08	38.2187
1484.21	33.8291
1487.34	29.4659
1490.46	24.8225
1493.58	22.3352
1496.71	19.626
1499.83	17.0585
1502.95	16.3614
1506.07	15.6187
1509.18	15.2117
1512.3	14.0904
1515.41	13.4036
1518.53	13.5333
1521.64	13.2646
1524.75	12.5429
1527.86	14.0728
1530.97	14.0732
1534.08	15.4476
1537.19	15.6465
1540.29	16.138
1543.4	18.2284
1546.5	21.0515
1549.6	23.2313
1552.7	26.8475
1555.8	30.2323
1558.9	33.8053
1562	37.3686
1565.09	39.2216
1568.19	42.0328
1571.28	44.5105
1574.37	46.3144
1577.47	47.3903
1580.56	49.3189
1583.64	50.8116
1586.73	52.121
1589.82	53.2715
1592.9	55.7744
1595.99	56.1893
1599.07	57.0629
1602.15	56.9381
1605.23	58.1523
1608.31	57.3246
1611.39	56.3518
1614.47	55.2141
1617.55	54.6043
1620.62	54.2216
1623.7	53.8365
1626.77	54.8343
1629.84	53.7051
1632.91	54.3443
1635.98	53.9125
1639.05	52.7148
1642.11	51.7496
1645.18	53.1018
1648.24	52.7629
1651.31	51.8318
1654.37	51.6736
1657.43	52.8309
1660.49	52.9642
1663.55	52.8583
1666.61	51.6919
1669.66	49.7039
1672.72	47.8967
1675.77	45.6344
1678.83	43.4648
1681.88	40.7005
1684.93	36.6894
1687.98	33.5284
1691.03	30.9053
1694.07	26.8731
1697.12	23.3211
1700.17	21.5727
1703.21	18.9059
1706.25	15.8281
1709.29	13.1578
1712.33	10.2955
1715.37	8.95013
1718.41	7.89367
1721.45	6.70897
1724.49	5.10637
1727.52	5.17982
1730.55	5.82046
1733.59	6.08826
1736.62	5.15364
1739.65	5.81838
1742.68	5.92803
1745.7	6.33356
1748.73	6.64181
1751.76	6.59116
1754.78	7.14413
1757.8	6.91208
1760.83	7.06626
1763.85	7.44841
1766.87	6.90484
1769.89	6.32297
1772.9	6.24031
1775.92	5.44679
1778.94	4.05158
1781.95	3.07431
1784.96	2.61828
1787.97	2.41756
1790.99	1.00494
1794	1.85699
1797	2.12371
1800.01	2.76124
1803.02	3.26422
1806.02	3.48788
1809.03	2.79561
1812.03	2.51252
1815.03	2.29146
1818.03	2.75523
1821.03	2.80381
1824.03	2.73875
1827.03	3.3555
1830.02	3.29878
1833.02	2.47626
1836.01	1.93151
1839.01	1.38868
1842	2.0833
1844.99	2.21446
1847.98	2.49838
1850.97	2.56543
1853.95	2.07684
1856.94	1.94005
1859.93	1.94682
1862.91	2.48917
1865.89	2.77423
1868.87	3.64688
1871.85	4.07506
1874.83	3.83895
1877.81	3.43599
1880.79	2.77986
1882.52	3.19508
1885.51	3.53606
1888.5	3.59526
1891.49	3.55741
1894.47	3.11609
1897.46	3.28175
1900.44	2.06768
1903.42	1.68556
1906.4	2.35621
1909.38	2.53498
1912.36	3.00535
1915.34	2.96791
1918.32	2.80264
1921.29	2.70563
1924.27	1.39808
1927.24	1.93932
1930.21	2.71203
1933.18	2.42165
1936.15	3.03045
1939.12	3.51014
1942.09	3.57306
1945.06	3.43639
1948.02	4.00277
1950.99	4.89931
1953.95	5.3162
1956.91	6.58517
1959.88	6.70012
1962.84	6.64189
1965.8	7.24208
1968.75	6.74587
1971.71	7.33817
1974.67	7.78822
1977.62	8.55894
1980.58	8.15858
1983.53	7.08525
1986.48	7.967
1989.43	7.05263
1992.38	5.05532
1995.33	5.18768
1998.27	4.70599
2001.22	4.6638
2004.16	4.40612
2007.11	4.03184
2010.05	4.16748
2012.99	4.2897
2015.93	3.81116
2018.87	4.53172
2021.81	5.13953
2024.75	5.07359
2027.69	5.02626
2030.62	5.30929
2033.56	5.88667
2036.49	5.98083
2039.42	5.56373
2042.35	6.01452
2045.28	6.69959
2048.21	6.95307
2051.14	6.80769
2054.07	7.64122
2056.99	7.05464
2059.92	6.87889
2062.84	6.59848
2065.76	7.2725
2068.68	8.35521
2071.6	9.08143
2074.52	8.75274
2077.44	8.89113
2080.36	8.08578
2083.27	7.68884
2086.19	7.59032
2089.1	6.77843
2092.02	6.81671
2094.93	6.75422
2097.84	6.98209
2100.75	7.10433
2103.66	7.01636
2106.56	7.22691
2109.47	6.59091
2112.38	6.61883
2115.28	6.4671
2118.18	7.22065
2121.09	6.91679
2123.99	6.93236
2126.89	5.36682
2129.79	5.69723
2132.68	5.67541
2135.58	5.54323
2138.48	5.36155
2141.37	4.89589
2144.27	3.99396
2147.16	3.53872
2150.05	3.13937
2152.94	2.63227
2155.83	3.47622
2158.72	3.53702
2161.6	3.62127
2164.49	3.99073
2167.38	4.66793
2170.26	5.01568
2173.14	5.0683
2176.03	4.68434
2178.91	4.93597
2181.79	5.58697
2184.67	5.35248
2187.54	6.24766
2190.42	5.74881
2193.3	4.59228
2196.17	4.25201
2199.05	4.54945
2201.92	4.43712
2204.79	4.26588
2207.66	5.09821
2210.53	5.23437
2213.4	4.26063
2216.27	4.81913
2219.13	5.05044
2222	4.98738
2224.86	5.37545
2227.72	6.1141
2230.59	5.2557
2233.45	5.73138
2236.31	5.33087
2239.17	5.1986
2242.03	4.25759
2244.88	2.98229
2247.74	2.33273
2250.59	2.17461
2253.45	1.11528
2256.3	-0.0625119
2259.15	0.573141
2262	0.00940602
2264.85	0.638987
2267.7	1.20853
2270.55	2.09191
2273.4	2.51355
2276.24	3.12156
2279.09	3.77285
2281.93	3.66537
2284.77	4.01942
2287.62	4.75491
2290.46	5.19152
2293.3	4.02404
2296.13	3.92137
2298.97	4.49621
2301.81	4.83402
2304.64	5.45413
2307.48	4.86637
2310.31	4.257
2313.14	4.16294
2315.98	4.67575
2318.81	5.05912
2321.64	4.7505
2324.46	5.32244
2327.29	6.38182
2330.12	6.03515
2332.94	5.70255
2335.77	5.95801
2338.59	5.24928
2341.41	5.16925
2344.23	4.92812
2347.05	4.98844
2349.87	4.97212
2352.69	4.75575
2355.51	3.58827
2358.32	3.37521
2361.14	2.21092
2363.95	1.69982
2366.76	2.08285
2369.58	2.61743
2372.39	3.00748
2375.2	2.42393
2378	1.79625
2380.81	2.01732
2383.62	2.55254
2386.43	2.68413
2389.23	2.06874
2392.03	1.68089
2394.84	1.18475
2397.64	-0.0404155
2400.44	-0.684166
2403.24	-0.61332
2406.04	-0.258874
2408.84	-0.395918
2411.63	0.480356
2414.43	2.25334
2417.22	2.84049
2420.02	2.70207
2422.81	3.46864
2425.6	3.93232
2428.39	3.9434
2431.18	3.9922
2433.97	4.76622
2436.76	4.27622
2439.54	4.6608
2442.33	4.59819
2445.12	4.90943
2447.9	4.87002
2450.68	4.09091
2453.46	4.77689
2456.24	3.78963
2459.02	3.6957
2461.8	2.99899
2464.58	1.97488
2467.36	1.88891
2470.13	2.28029
2472.91	2.58759
2475.68	2.15147
2478.45	2.68893
2481.23	2.92703
2484	2.23483
2486.77	2.02688
2489.54	1.54322
2492.3	1.13167
2495.07	0.338332
2497.84	-0.127176
2500.6	-0.115658
2503.36	-0.0139258
2506.13	-0.902974
2508.89	-0.208005
2511.65	-0.0261955
2514.41	-0.344966
2517.17	-0.262639
2519.93	0.320645
2522.68	1.15676
2525.44	1.58907
2528.19	1.54996
2530.95	2.07012
2533.7	2.04799
2536.45	3.05514
2539.2	3.39446
2541.95	2.89261
2544.7	3.69575
2547.45	4.29022
2550.2	4.08538
2552.94	3.89661
2555.69	3.71422
2558.43	3.36384
2561.18	4.00866
2563.92	3.17703
2566.66	3.29281
2569.4	3.16321
2572.14	2.50989
2574.88	2.71833
2577.61	3.22142
2580.35	3.34725
2583.09	3.81982
2585.82	4.36234
2588.55	3.97601
2591.29	4.51488
2594.02	4.09147
2596.75	3.67124
2599.48	3.71866
2602.21	4.30757
2604.93	4.44909
2607.66	4.12273
2610.39	4.07954
2613.11	4.18231
2615.83	3.81215
2618.56	4.06542
2621.28	4.20164
2624	4.46815
2626.72	4.3948
2629.44	4.83153
2632.15	4.14678
2634.87	5.27641
2637.59	5.66476
2640.3	6.5997
2643.02	7.24175
2645.73	8.08964
2648.44	7.84153
2651.15	7.82781
2653.86	7.89001
2656.57	7.85656
2659.28	8.02468
2661.99	8.08703
2664.69	7.94226
2667.4	7.82746
2670.1	8.27182
2672.81	7.38926
2675.51	7.48528
2678.21	7.12029
2680.91	7.01886
2683.61	5.92019
2686.31	5.93877
2689	5.12872
2691.7	5.02881
2694.4	5.01573
2697.09	6.27604
2699.79	6.85306
2702.48	7.52734
2705.17	7.69168
2707.86	7.96154
2710.55	8.70131
2713.24	8.43597
2715.93	8.91764
2718.62	9.31302
2721.3	9.24665
2723.99	9.13542
2726.67	9.81245
2729.35	9.59413
2732.04	9.53201
2734.72	9.7731
2737.4	9.53549
2740.08	9.67974
2742.76	9.45306
2745.43	10.1774
2748.11	10.0661
2750.79	9.43547
2753.46	8.97187
2756.14	8.67198
2758.81	8.61733
2761.48	8.57056
2764.15	8.28234
2766.82	8.20911
2769.49	7.68332
2772.16	7.15157
2774.82	7.28628
2777.49	7.35278
2780.16	6.56441
2782.82	6.18383
2785.48	5.34046
2788.15	5.20474
2790.81	5.3051
2793.47	5.55436
2796.13	6.57432
2798.79	7.05403
2801.44	7.696
2804.1	9.41162
2806.76	9.90394
2809.41	10.6193
2812.07	10.0063
2814.72	10.4873
2817.37	10.5774
2820.02	11.1205
2822.67	12.4066
2825.32	15.3171
2827.97	18.741
2830.62	22.9138
2833.26	26.5252
2835.91	29.8956
2838.56	35.5878
2841.2	41.0832
2843.84	46.4993
2846.48	53.4293
2849.12	60.8505
2851.77	69.2332
2854.4	78.6397
2857.04	88.408
2859.68	98.9926
2862.32	108.577
2864.95	117.306
2867.59	126.859
2870.22	135.808
2872.85	144.602
2875.48	153.468
2878.11	161.755
2880.74	171.684
2883.37	179.644
2886	187.986
2888.63	196.815
2891.25	205.698
2893.88	213.135
2896.5	220.479
2899.13	226.549
2901.75	233.924
2904.37	240.829
2906.99	247.394
2909.61	254.689
2912.23	261.719
2914.85	268.001
2917.46	273.495
2920.08	279.629
2922.7	282.72
2925.31	284.915
2927.92	284.916
2930.54	284.79
2933.15	281.915
2935.76	276.891
2938.37	272.408
2940.98	266.393
2943.58	258.818
2946.19	250.618
2948.8	241.697
2951.4	232.028
2954.01	223.377
2956.61	213.241
2959.21	202.759
2961.81	192.343
2964.41	183.502
2967.01	174.492
2969.61	165.157
2972.21	157.161
2974.81	148.55
2977.4	141.005
2980	132.437
2982.59	124.621
2985.18	115.704
2987.78	107.295
2990.37	98.3292
2992.96	90.1394
2995.55	80.5678
2998.14	71.933
3000.73	63.3443
3003.31	56.0739
3005.9	48.4745
3008.48	40.7108
3011.07	35.0283
3013.65	29.9946
3016.23	25.9001
3018.81	22.4125
3021.4	17.6926
3023.97	13.5321
3026.55	11.6508
3029.13	10.0058
3031.71	8.44116
3034.28	7.74516
3036.86	7.12344
3039.43	7.87059
3042.01	8.10689
3044.58	8.55467
3047.15	8.93723
3049.72	9.87182
3052.29	10.5473
3054.86	11.481
3057.43	11.8005
3060	11.7701
3062.56	11.7357
3065.13	10.6117
3067.69	10.4733
3070.26	9.07158
3072.82	8.19825
3075.38	7.80854
3077.94	6.65074
3080.5	5.4558
3083.06	3.89975
3085.62	1.2961
3088.18	0.92901
3090.73	0.0322425
3093.29	-0.114641
3095.84	-0.724596
3098.4	-0.85193
3100.95	-0.524144
3103.5	-0.700963
3106.05	-0.447768
3108.6	0.726025
3111.15	1.72127
3113.7	2.57903
3116.25	3.5434
3118.79	4.66859
3121.34	5.23696
3123.88	6.14569
3126.43	7.00242
3128.97	7.72129
3131.51	8.97737
3134.06	9.67106
3136.6	10.7253
3139.14	11.3537
3141.67	11.6335
3144.21	11.5956
3146.75	11.1756
3149.29	10.0097