File: data/Raman/poly_smoothed/Thy_50_12_39_1x_45s_532 nm_x100_100%_600 gr_mm_01.txt
#Acq. time (s)=	45
#Accumulations=	2
#Range (cm-¹)=	200...3150
#Windows=	2
#Auto scanning=	Off
#Autofocus=	Off
#Macrospot=	Off
#AutoExposure=	Off
#Spike filter=	Multiple accum.
#Delay time (s)=	0
#Binning=	1
#Readout mode=	Signal
#DeNoise=	Off
#ICS correction=	On
#Dark correction=	Off
#Inst. Process=	Off
#Detector Gain=	Best Dynamic Range
#Detector ADC=	20 kHz
#Detector temperature (°C)=	-69.85
#Instrument=	LabRAM HR Evol
#Detector=	Synapse
#Objective=	x100
#Grating=	600 gr/mm
#ND Filter=	100%
#Laser (nm)=	532
#Hole=	100.021
#Range=	Auto
#Laser Pol.=	No
#Raman. Pol.=	No
#Laser Pol. (°)=	-0.0007625
#Raman Pol. (°)=	89.9995
#Collection=	Microscope
#StageXY=	Marzhauser
#StageZ=	Marzhauser
#X (µm)=	-5128.4
#Y (µm)=	1529.7
#Z (µm)=	63.4
#Full time(mm:ss)=	3:18
#Project=
#Sample=
#Site=
#Title=	Thy_50_12_39_2x_45s_532 nm_x100_100%_600 gr_mm
#Remark=
#Date=	07.07.2022 12:07
#Acquired=	07.07.2022 12:07:46
#Base:Fit=	10.08.2022 10:04:30
#Base:Sub=	10.08.2022 10:04:45
#Filter:Polynom=	16.08.2022 10:20:25
#AxisType[0]=Intens
#AxisUnit[0]=Cnt
#AxisType[1]=Spectr
#AxisUnit[1]=1/cm
200.43	45.9324
204.061	36.506
207.688	28.6837
211.316	23.6561
214.941	20.6321
218.566	16.71
222.188	14.3183
225.809	13.8422
229.43	12.6817
233.047	11.9389
236.663	10.4225
240.278	8.72109
243.894	7.64122
247.506	7.53741
251.116	7.43409
254.725	8.13007
258.333	8.79752
261.939	8.29302
265.546	8.24339
269.15	7.97426
272.752	5.02558
276.353	5.59706
279.952	6.06642
283.55	5.55158
287.146	5.94734
290.739	7.8148
294.333	10.277
297.925	13.1404
301.516	15.6655
305.106	15.9726
308.694	16.8607
312.279	17.343
315.864	18.3183
319.448	17.4525
323.029	17.0907
326.61	17.3985
330.19	17.2358
333.766	17.8447
337.343	18.5898
340.917	17.0204
344.491	16.9387
348.062	17.3795
351.633	16.1089
355.201	15.5192
358.77	14.8331
362.335	14.2693
365.899	14.1805
369.464	13.5454
373.025	13.604
376.585	14.0168
380.143	14.5246
383.702	15.9688
387.258	14.5941
390.812	13.3146
394.365	11.3358
397.916	9.39969
401.467	9.41485
405.015	10.5162
408.565	11.0553
412.111	12.2663
415.656	13.5604
419.197	13.9278
422.739	15.7277
426.279	16.5595
429.819	17.0182
433.356	17.7477
436.893	18.8432
440.428	18.6479
443.96	18.8878
447.492	20.3153
451.023	20.0259
454.553	19.9485
458.079	19.2121
461.606	18.4528
465.132	20.5485
468.654	20.9753
472.177	20.8003
475.696	22.2045
479.217	22.5307
482.733	21.5954
486.251	22.9653
489.765	25.0822
493.278	25.3289
496.791	26.3096
500.301	26.1585
503.81	26.128
507.319	26.8164
510.825	25.7379
514.33	25.3617
517.833	24.4604
521.337	23.7295
524.838	24.5584
528.337	22.8982
531.835	20.9783
535.332	20.8368
538.827	19.3057
542.321	19.411
545.814	18.5298
549.305	18.1494
552.795	17.2737
556.284	15.1458
559.771	14.5486
563.257	12.6281
566.742	10.2663
570.223	9.67678
573.705	9.96669
577.185	8.97371
580.665	8.88733
584.141	9.76942
587.617	8.64294
591.092	7.3933
594.564	6.71367
598.037	6.5022
601.506	7.44009
604.976	7.13054
608.443	8.05467
611.91	7.41501
615.374	7.0897
618.839	8.35524
622.3	9.93803
625.761	10.0854
629.221	9.36499
632.679	9.48574
636.135	8.86256
639.592	8.42569
643.045	8.71778
646.497	9.61061
649.948	10.7704
653.398	11.226
656.846	13.085
660.293	13.8565
663.738	13.8571
667.185	15.8217
670.628	18.3355
674.067	18.6107
677.508	19.8767
680.947	22.4465
684.385	26.6011
687.821	27.408
691.256	29.4545
694.69	31.0878
698.121	34.5725
701.552	37.2991
704.982	39.9833
708.41	42.4803
711.836	45.0932
715.262	47.0426
718.685	48.1691
722.108	49.4068
725.53	49.7618
728.949	50.1013
732.369	51.3764
735.785	50.413
739.2	52.6578
742.616	53.5205
746.028	54.2845
749.441	56.8431
752.851	58.3238
756.26	61.0362
759.667	62.5231
763.075	63.58
766.479	65.166
769.883	66.1081
773.285	66.086
776.686	66.6885
780.085	68.314
783.484	70.8531
786.881	72.7678
790.276	75.6222
793.671	77.9948
797.064	79.2624
800.456	79.456
803.846	78.6002
807.236	78.8845
810.624	78.3392
814.01	78.4077
817.394	78.5352
820.778	79.3377
824.161	78.9646
827.543	78.7318
830.921	78.3427
834.3	78.0999
837.676	77.5695
841.053	76.8365
844.426	72.6628
847.8	68.5433
851.171	64.3991
854.542	61.3862
857.911	57.5282
861.279	55.5195
864.645	54.5892
868.01	53.5969
871.375	53.0487
874.737	52.1245
878.097	49.8322
881.457	46.8961
884.817	46.6214
888.174	45.6829
891.53	44.7781
894.884	45.4795
898.237	46.006
901.589	46.3588
904.94	46.4318
908.289	47.7431
911.637	48.0216
914.984	47.5773
918.33	46.5482
921.674	46.3926
925.015	44.6081
928.357	44.2167
931.698	43.8422
935.037	42.7676
938.373	42.7687
941.71	40.5341
945.046	39.5187
948.378	41.3631
951.711	42.4859
955.043	40.2351
958.372	39.0788
961.701	38.5194
965.027	38.991
968.354	40.2607
971.678	40.2479
975	40.9974
978.324	40.4994
981.644	39.1811
984.962	37.6501
988.282	38.0463
991.598	36.111
994.913	33.2721
998.227	33.8084
1001.54	34.5791
1004.85	34.6737
1008.16	34.246
1011.47	35.9743
1014.78	35.7379
1018.08	34.8181
1021.39	34.7448
1024.69	36.3702
1028	38.6292
1031.3	41.6085
1034.6	41.7093
1037.9	41.8526
1041.19	41.6136
1044.49	43.783
1047.79	47.4006
1051.08	47.3498
1054.37	46.2863
1057.66	43.5085
1060.95	43.1425
1064.24	42.1644
1067.53	41.3457
1070.81	38.848
1074.1	35.4173
1077.38	36.372
1080.66	35.9824
1083.94	34.4041
1087.22	32.213
1090.5	30.7278
1093.78	31.0823
1097.05	29.0836
1100.33	27.3268
1103.6	26.5725
1106.87	25.9272
1110.15	24.7572
1113.41	25.6297
1116.68	23.568
1119.95	22.484
1123.21	22.1409
1126.48	21.8661
1129.74	18.628
1133	15.5776
1136.26	13.9201
1139.52	12.437
1142.78	10.3782
1146.04	7.78325
1149.29	7.25691
1152.55	7.51956
1155.8	6.91915
1159.05	5.2233
1162.3	4.27134
1165.55	4.3637
1168.8	4.13748
1172.05	5.44594
1175.29	5.05699
1178.54	5.87449
1181.78	7.38619
1185.02	9.15182
1188.26	10.8318
1191.5	12.4367
1194.74	13.2964
1197.97	12.5137
1201.21	13.3877
1204.44	14.9421
1207.68	14.3895
1210.91	16.593
1214.14	19.4058
1217.37	21.3548
1220.6	24.4079
1223.82	27.7183
1227.05	32.2045
1230.27	35.504
1233.49	38.2823
1236.72	40.6587
1239.94	44.3158
1243.16	47.8314
1246.37	50.0521
1249.59	52.8326
1252.8	56.2629
1256.02	59.6918
1259.23	63.5769
1262.44	67.4286
1265.66	69.8579
1268.87	71.2498
1272.07	73.4062
1275.28	74.0632
1278.48	76.4151
1281.69	79.5405
1284.89	79.9305
1288.09	81.4812
1291.3	83.2616
1294.49	84.7777
1297.69	85.9979
1300.89	85.6143
1304.09	85.9669
1307.28	86.6559
1310.47	86.4548
1313.66	85.8228
1316.86	85.1218
1320.05	85.4177
1323.23	83.3176
1326.42	83.8826
1329.61	83.2278
1332.79	82.0156
1335.98	81.8198
1339.16	80.275
1342.34	79.299
1345.52	77.1361
1348.7	75.1096
1351.87	72.0254
1355.05	70.1639
1358.23	67.8323
1361.4	66.1074
1364.57	61.213
1367.74	59.9953
1370.91	57.0201
1374.08	56.0273
1377.25	53.4968
1380.42	50.7854
1383.58	50.9976
1386.75	52.3771
1389.91	52.4489
1393.07	51.8141
1396.23	51.4213
1399.39	51.5901
1402.55	52.3253
1405.7	53.1881
1408.86	54.3757
1412.01	57.259
1415.17	60.2851
1418.32	62.7559
1421.47	66.5459
1424.62	71.8372
1427.77	76.8875
1430.92	82.0782
1434.06	88.2791
1437.2	92.8458
1440.35	95.1715
1443.49	96.2924
1446.63	99.0577
1449.77	99.5428
1452.91	98.6521
1456.05	96.6631
1459.18	93.6478
1462.32	88.7847
1465.45	83.0894
1468.59	75.0417
1471.72	67.7302
1474.85	60.9719
1477.98	53.8328
1481.11	46.4468
1484.23	38.9291
1487.36	33.6093
1490.48	28.1765
1493.61	25.0016
1496.73	24.4995
1499.85	21.9082
1502.97	21.7259
1506.09	23.2139
1509.2	23.3368
1512.32	24.0637
1515.44	24.1694
1518.55	25.3364
1521.66	28.9172
1524.77	31.234
1527.88	33.6867
1530.99	33.896
1534.1	35.0583
1537.21	37.1222
1540.31	41.3008
1543.42	44.6009
1546.52	48.6996
1549.62	52.0234
1552.72	54.9623
1555.82	57.6126
1558.92	59.9545
1562.02	63.5914
1565.11	67.5796
1568.21	69.9863
1571.3	72.8992
1574.39	75.5588
1577.49	77.7617
1580.58	79.9954
1583.67	80.5233
1586.75	81.0428
1589.84	81.3715
1592.93	81.2837
1596.01	81.1878
1599.09	79.6577
1602.18	77.58
1605.26	76.2647
1608.34	76.6463
1611.41	76.1898
1614.49	76.1998
1617.57	75.6491
1620.64	75.0745
1623.72	75.079
1626.79	77.6249
1629.86	77.447
1632.93	79.6553
1636	82.2396
1639.07	85.2816
1642.14	86.2607
1645.2	87.8059
1648.27	88.5312
1651.33	88.8877
1654.39	87.8435
1657.45	86.3056
1660.51	84.5966
1663.57	82.6682
1666.63	79.081
1669.69	75.8165
1672.74	70.1483
1675.79	66.2572
1678.85	62.7712
1681.9	57.5439
1684.95	52.8706
1688	48.4055
1691.05	42.6049
1694.1	37.8703
1697.14	35.7838
1700.19	33.7267
1703.23	30.113
1706.27	27.7066
1709.32	25.8028
1712.35	22.6987
1715.39	19.9758
1718.43	18.023
1721.47	16.7703
1724.5	14.6893
1727.54	13.1267
1730.57	12.4451
1733.61	11.3862
1736.64	10.4039
1739.67	9.17453
1742.7	9.17248
1745.72	9.16388
1748.75	7.2015
1751.78	6.60557
1754.8	6.76441
1757.82	7.85552
1760.85	8.32778
1763.87	9.57856
1766.89	9.45628
1769.91	10.3694
1772.92	10.5355
1775.94	10.7122
1778.96	9.5499
1781.97	8.52705
1784.98	7.66287
1788	6.95279
1791.01	7.27581
1794.01	6.99737
1797.02	5.64249
1800.03	5.54906
1803.04	5.47826
1806.04	4.08894
1809.05	3.18505
1812.05	2.46625
1815.05	2.0846
1818.05	1.89967
1821.05	0.364486
1824.05	-0.389232
1827.05	2.04007
1830.04	2.88694
1833.04	3.61427
1836.03	3.38778
1839.03	3.65164
1842.02	3.40157
1845.01	4.61241
1848	5.19031
1850.99	5.35756
1853.97	5.28859
1856.96	4.33041
1859.94	3.57807
1862.93	3.54934
1865.91	2.71585
1868.89	3.41399
1871.87	3.58089
1874.85	3.80287
1877.83	4.24609
1880.81	2.82121
1882.56	3.48637
1885.55	3.78156
1888.54	4.22114
1891.52	4.67009
1894.51	5.59686
1897.49	5.10632
1900.48	5.09861
1903.46	5.36718
1906.44	5.17256
1909.42	5.0854
1912.4	5.88729
1915.38	4.76242
1918.35	4.0009
1921.33	2.94841
1924.3	2.24723
1927.28	1.40814
1930.25	0.452945
1933.22	0.595815
1936.19	1.28973
1939.16	0.70302
1942.13	1.52221
1945.09	1.64306
1948.06	2.68887
1951.03	1.78947
1953.99	2.25188
1956.95	2.89875
1959.91	3.48329
1962.87	4.16934
1965.83	4.54735
1968.79	4.32125
1971.75	4.53182
1974.7	4.67256
1977.66	5.46614
1980.61	4.20509
1983.56	3.98686
1986.52	3.31911
1989.47	2.60302
1992.41	3.63774
1995.36	4.30706
1998.31	4.26927
2001.26	4.4229
2004.2	5.56328
2007.15	6.16119
2010.09	5.76059
2013.03	5.57385
2015.97	6.62254
2018.91	6.74132
2021.85	6.30171
2024.79	6.96216
2027.72	7.49329
2030.66	8.87387
2033.59	9.43829
2036.53	10.8343
2039.46	10.9152
2042.39	11.4263
2045.32	12.8622
2048.25	12.6154
2051.18	12.0601
2054.1	12.8043
2057.03	13.8374
2059.95	14.4375
2062.88	14.8062
2065.8	16.1527
2068.72	17.5998
2071.64	19.0406
2074.56	20.491
2077.48	23.8472
2080.39	26.22
2083.31	27.5808
2086.22	30.1359
2089.14	33.541
2092.05	35.6492
2094.96	38.6655
2097.87	42.7758
2100.78	46.8403
2103.69	50.3697
2106.6	53.9699
2109.51	57.9093
2112.41	61.4763
2115.32	65.4971
2118.22	68.3495
2121.12	70.5609
2124.02	74.72
2126.92	79.0743
2129.82	82.2681
2132.72	85.567
2135.62	89.6737
2138.51	93.6051
2141.41	96.8823
2144.3	99.7537
2147.19	104.417
2150.09	106.632
2152.97	107.994
2155.86	108.371
2158.75	109.843
2161.64	111.136
2164.53	111.959
2167.41	112.353
2170.3	112.093
2173.18	110.602
2176.06	109.618
2178.94	108.367
2181.82	106.454
2184.7	103.895
2187.58	100.92
2190.46	98.3047
2193.33	95.1347
2196.21	93.3655
2199.08	90.6843
2201.95	87.4989
2204.83	84.8071
2207.7	81.2824
2210.57	77.4911
2213.43	73.3837
2216.3	70.126
2219.17	66.4441
2222.03	62.1099
2224.9	58.5508
2227.76	54.8707
2230.62	51.8935
2233.49	48.4902
2236.34	44.0821
2239.2	41.4329
2242.06	38.0299
2244.92	35.0134
2247.78	33.0676
2250.63	31.3426
2253.48	30.3233
2256.34	28.8597
2259.19	27.0405
2262.04	25.8345
2264.89	24.5205
2267.74	23.524
2270.59	23.7857
2273.43	22.5336
2276.28	22.0698
2279.12	20.8838
2281.97	19.9861
2284.81	18.5854
2287.65	18.296
2290.49	17.9283
2293.33	16.526
2296.17	15.5035
2299.01	16.4583
2301.84	15.1969
2304.68	14.8025
2307.51	14.7465
2310.35	13.8434
2313.18	13.5941
2316.01	13.6101
2318.84	13.6096
2321.67	14.1617
2324.5	13.355
2327.33	12.222
2330.15	10.974
2332.98	10.0723
2335.8	8.42902
2338.62	7.10207
2341.45	6.22251
2344.27	5.31292
2347.09	3.73873
2349.91	2.93723
2352.72	1.53681
2355.54	0.886803
2358.36	0.75436
2361.17	-0.648133
2363.98	-0.971764
2366.8	-0.167435
2369.61	-0.383137
2372.42	-0.302195
2375.23	-0.232005
2378.04	1.32638
2380.85	2.71758
2383.66	4.28523
2386.46	5.35808
2389.26	6.55929
2392.07	6.97357
2394.87	7.27437
2397.67	7.81805
2400.47	8.0532
2403.27	7.83176
2406.07	7.26768
2408.87	7.53022
2411.67	8.62642
2414.46	8.99683
2417.26	7.63326
2420.05	7.67185
2422.84	6.98303
2425.64	5.77631
2428.43	4.61554
2431.22	4.24588
2434.01	5.44634
2436.79	5.89383
2439.58	5.90914
2442.37	6.51261
2445.15	7.52673
2447.93	8.46182
2450.72	8.7522
2453.5	8.3122
2456.28	8.09157
2459.06	7.41815
2461.84	6.54761
2464.62	6.70122
2467.39	5.58713
2470.17	5.1767
2472.94	4.32508
2475.72	3.74404
2478.49	3.36337
2481.26	3.22309
2484.03	2.74744
2486.8	2.34443
2489.57	2.10089
2492.34	1.95142
2495.1	2.03694
2497.87	3.04039
2500.63	4.84194
2503.4	4.86568
2506.16	5.61749
2508.92	5.38183
2511.68	5.62215
2514.44	6.16863
2517.2	6.87463
2519.96	6.2573
2522.72	6.7398
2525.47	5.81421
2528.23	6.25938
2530.98	4.98506
2533.74	3.88674
2536.49	3.22755
2539.24	3.69881
2541.99	3.92069
2544.74	4.03138
2547.49	4.94951
2550.23	5.18798
2552.98	4.56374
2555.72	4.29951
2558.47	5.14955
2561.21	5.09563
2563.95	5.98102
2566.69	5.17622
2569.43	5.39835
2572.17	5.39406
2574.91	6.39131
2577.65	6.01325
2580.39	6.04224
2583.12	6.71005
2585.85	6.63799
2588.59	6.52322
2591.32	6.77645
2594.05	5.08867
2596.78	4.53057
2599.51	3.2031
2602.24	2.97459
2604.97	4.08082
2607.69	4.62216
2610.42	5.73933
2613.14	5.57948
2615.87	4.84873
2618.59	4.59229
2621.31	4.54141
2624.03	4.31944
2626.75	5.82576
2629.47	4.75139
2632.19	4.55123
2634.91	4.94971
2637.62	5.25647
2640.34	5.5758
2643.05	5.6715
2645.76	5.09003
2648.48	5.37339
2651.19	5.20011
2653.9	6.34102
2656.6	5.62573
2659.31	6.09244
2662.02	5.50321
2664.73	5.7139
2667.43	6.20536
2670.14	6.56884
2672.84	8.11616
2675.54	8.15938
2678.24	6.90275
2680.94	7.59252
2683.64	6.82078
2686.34	6.64982
2689.04	6.99275
2691.74	6.57252
2694.43	6.99174
2697.13	6.15571
2699.82	6.59982
2702.51	6.81844
2705.21	6.29026
2707.9	6.75019
2710.58	6.23725
2713.27	5.90475
2715.96	6.61432
2718.65	7.58266
2721.33	8.21446
2724.02	8.5247
2726.71	8.93918
2729.39	7.73677
2732.07	7.84345
2734.75	6.82867
2737.43	6.41084
2740.11	5.79759
2742.79	4.28291
2745.47	3.52655
2748.14	2.85861
2750.82	2.30949
2753.49	0.952895
2756.17	1.32504
2758.84	-0.0132564
2761.51	0.147573
2764.18	-0.814577
2766.85	-1.12048
2769.52	-1.39683
2772.19	-1.71424
2774.86	-0.936727
2777.52	0.464871
2780.19	1.38869
2782.85	1.97276
2785.52	3.0211
2788.18	3.35037
2790.84	3.53866
2793.5	2.46271
2796.16	2.73131
2798.82	2.84739
2801.48	2.84108
2804.13	2.56489
2806.79	1.61325
2809.45	0.532869
2812.1	-0.406352
2814.75	-0.272766
2817.41	1.11927
2820.06	4.66491
2822.71	9.55147
2825.36	13.954
2828	20.2697
2830.65	27.1994
2833.3	34.3355
2835.94	42.1185
2838.59	50.1969
2841.23	58.1699
2843.87	65.6852
2846.52	73.1814
2849.16	81.8739
2851.8	90.739
2854.44	100.589
2857.08	109.022
2859.71	118.197
2862.35	126.674
2864.98	133.469
2867.62	139.858
2870.25	143.997
2872.88	148.178
2875.52	153.033
2878.15	157.945
2880.78	163.623
2883.41	169.13
2886.03	175.67
2888.66	180.753
2891.29	187.256
2893.91	191.687
2896.54	195.789
2899.16	201.236
2901.78	208.758
2904.4	215.619
2907.02	222.476
2909.64	231.076
2912.26	240.709
2914.88	250.914
2917.5	260.909
2920.11	269.157
2922.73	274.379
2925.34	277.933
2927.96	280.367
2930.57	279.731
2933.18	275.55
2935.79	272.152
2938.4	267.331
2941.01	260.265
2943.62	251.272
2946.22	241.772
2948.83	231.816
2951.43	221.146
2954.04	210.324
2956.64	198.216
2959.24	185.423
2961.84	175.065
2964.45	165.301
2967.05	155.757
2969.64	147.37
2972.24	138.457
2974.84	130.722
2977.43	123.642
2980.03	115.954
2982.62	106.509
2985.22	96.9705
2987.81	87.9693
2990.4	79.5664
2992.99	70.4214
2995.58	62.0567
2998.17	53.7139
3000.76	46.3621
3003.34	39.0357
3005.93	31.9543
3008.52	27.1588
3011.1	21.4121
3013.68	17.4759
3016.27	13.334
3018.85	10.0767
3021.43	5.96159
3024.01	3.1568
3026.59	2.02011
3029.16	1.66466
3031.74	2.11628
3034.32	2.04471
3036.89	2.22108
3039.47	2.45225
3042.04	3.95382
3044.61	4.80069
3047.18	6.17135
3049.75	7.64911
3052.32	8.50508
3054.89	8.53712
3057.46	8.68629
3060.03	8.63423
3062.59	8.05535
3065.16	8.60884
3067.72	8.28317
3070.29	7.71151
3072.85	6.82599
3075.41	5.8754
3077.97	5.30327
3080.53	4.07566
3083.09	3.29831
3085.65	2.09039
3088.21	0.692319
3090.76	-0.139354
3093.32	-0.254142
3095.87	-0.523805
3098.43	-1.47509
3100.98	-1.15226
3103.53	0.321784
3106.08	1.06015
3108.63	1.54892
3111.18	3.35127
3113.73	4.54065
3116.28	6.24424
3118.83	7.92836
3121.37	9.46694
3123.92	11.787
3126.46	14.4409
3129	17.2358
3131.55	18.6211
3134.09	20.9578
3136.63	24.2392
3139.17	27.3912
3141.71	29.3671
3144.24	30.8723
3146.78	31.6446
3149.32	32.3197