File: data/Raman/poly_smoothed/Thy_50_12_22_1x_45s_532 nm_x100_100%_600 gr_mm_01.txt
#Acq. time (s)=	45
#Accumulations=	2
#Range (cm-¹)=	200...3150
#Windows=	2
#Auto scanning=	Off
#Autofocus=	Off
#Macrospot=	Off
#AutoExposure=	Off
#Spike filter=	Multiple accum.
#Delay time (s)=	0
#Binning=	1
#Readout mode=	Signal
#DeNoise=	Off
#ICS correction=	On
#Dark correction=	Off
#Inst. Process=	Off
#Detector Gain=	Best Dynamic Range
#Detector ADC=	20 kHz
#Detector temperature (°C)=	-69.85
#Instrument=	LabRAM HR Evol
#Detector=	Synapse
#Objective=	x100
#Grating=	600 gr/mm
#ND Filter=	100%
#Laser (nm)=	532
#Hole=	100.021
#Range=	Auto
#Laser Pol.=	No
#Raman. Pol.=	No
#Laser Pol. (°)=	-0.0007625
#Raman Pol. (°)=	89.9995
#Collection=	Microscope
#StageXY=	Marzhauser
#StageZ=	Marzhauser
#X (µm)=	-5103.2
#Y (µm)=	1488.1
#Z (µm)=	63.05
#Full time(mm:ss)=	3:18
#Project=
#Sample=
#Site=
#Title=	Thy_50_12_22_2x_45s_532 nm_x100_100%_600 gr_mm
#Remark=
#Date=	07.07.2022 10:50
#Acquired=	07.07.2022 10:50:40
#Base:Fit=	10.08.2022 10:04:29
#Base:Sub=	10.08.2022 10:04:45
#Filter:Polynom=	16.08.2022 10:20:24
#AxisType[0]=Intens
#AxisUnit[0]=Cnt
#AxisType[1]=Spectr
#AxisUnit[1]=1/cm
200.43	57.8533
204.061	50.9584
207.688	42.8272
211.316	36.3935
214.941	31.1664
218.566	26.6889
222.188	21.1173
225.809	17.3712
229.43	15.8811
233.047	14.6879
236.663	11.8368
240.278	10.5257
243.894	9.08051
247.506	9.00544
251.116	9.61654
254.725	10.2492
258.333	8.87424
261.939	8.94188
265.546	10.6266
269.15	11.8666
272.752	13.7132
276.353	14.4835
279.952	13.6024
283.55	11.9914
287.146	12.707
290.739	12.3803
294.333	13.6711
297.925	15.3545
301.516	16.8914
305.106	16.1145
308.694	15.5778
312.279	16.4147
315.864	15.3427
319.448	16.4865
323.029	15.7464
326.61	14.969
330.19	15.1366
333.766	15.3111
337.343	16.6219
340.917	15.4631
344.491	15.7274
348.062	15.6205
351.633	16.3302
355.201	14.8441
358.77	12.7254
362.335	12.4594
365.899	10.4505
369.464	10.3232
373.025	11.1177
376.585	11.3858
380.143	9.1871
383.702	10.0722
387.258	9.55672
390.812	10.0361
394.365	8.38166
397.916	7.24931
401.467	5.75468
405.015	4.33076
408.565	4.80056
412.111	4.98631
415.656	4.97088
419.197	5.21227
422.739	5.29325
426.279	5.79304
429.819	5.69585
433.356	5.52256
436.893	4.43257
440.428	5.08644
443.96	5.16243
447.492	6.57244
451.023	7.51138
454.553	7.25622
458.079	8.31372
461.606	8.97465
465.132	9.67699
468.654	9.65591
472.177	11.6909
475.696	13.8508
479.217	13.3047
482.733	15.2756
486.251	15.7736
489.765	16.2141
493.278	17.7483
496.791	18.605
500.301	18.8924
503.81	18.7439
507.319	19.5595
510.825	20.299
514.33	18.5546
517.833	18.3861
521.337	16.8128
524.838	16.3621
528.337	15.3042
531.835	13.0462
535.332	11.8833
538.827	11.0506
542.321	9.08949
545.814	7.82931
549.305	6.22852
552.795	4.85932
556.284	3.52944
559.771	3.13385
563.257	2.94564
566.742	2.99172
570.223	1.26298
573.705	0.523089
577.185	1.66633
580.665	2.16394
584.141	2.0404
587.617	3.75396
591.092	3.73411
594.564	4.60303
598.037	4.17333
601.506	6.29089
604.976	6.41452
608.443	6.42725
611.91	7.38268
615.374	6.23529
618.839	7.03448
622.3	7.8684
625.761	7.54664
629.221	7.13854
632.679	5.55648
636.135	6.9343
639.592	7.01753
643.045	7.04826
646.497	5.97043
649.948	6.34326
653.398	9.22109
656.846	10.2423
660.293	12.0124
663.738	12.9664
667.185	13.7044
670.628	14.6068
674.067	15.399
677.508	17.2358
680.947	19.8392
684.385	22.3575
687.821	25.8654
691.256	28.6702
694.69	30.1693
698.121	32.6651
701.552	37.1809
704.982	39.5181
708.41	40.6264
711.836	41.7808
715.262	44.7492
718.685	46.448
722.108	48.7137
725.53	48.6428
728.949	49.9403
732.369	52.0298
735.785	54.0246
739.2	52.9216
742.616	52.7448
746.028	54.5265
749.441	55.7366
752.851	58.0711
756.26	59.113
759.667	61.2389
763.075	60.8067
766.479	62.8959
769.883	64.3168
773.285	66.3032
776.686	68.6935
780.085	71.6247
783.484	74.3088
786.881	77.8597
790.276	78.46
793.671	79.7762
797.064	82.5189
800.456	83.6817
803.846	83.6499
807.236	84.1359
810.624	83.966
814.01	82.329
817.394	81.6059
820.778	81.2006
824.161	81.5082
827.543	80.9294
830.921	80.3361
834.3	79.3586
837.676	76.9415
841.053	73.6751
844.426	69.8211
847.8	64.4266
851.171	62.8511
854.542	61.2132
857.911	59.7987
861.279	57.4398
864.645	56.4196
868.01	56.5591
871.375	55.3725
874.737	53.7114
878.097	52.2096
881.457	50.9427
884.817	49.1882
888.174	49.4034
891.53	47.76
894.884	46.1857
898.237	46.1496
901.589	44.5603
904.94	44.9012
908.289	42.318
911.637	41.5818
914.984	40.7523
918.33	40.8862
921.674	38.9024
925.015	37.647
928.357	35.5702
931.698	35.8245
935.037	36.8416
938.373	37.8567
941.71	37.1712
945.046	36.2937
948.378	38.5085
951.711	40.2271
955.043	39.6063
958.372	39.8578
961.701	39.1966
965.027	38.6282
968.354	38.0384
971.678	36.462
975	34.1132
978.324	32.0769
981.644	31.2756
984.962	30.6062
988.282	28.7932
991.598	28.7817
994.913	27.6687
998.227	27.9353
1001.54	28.1566
1004.85	28.1533
1008.16	30.199
1011.47	30.965
1014.78	32.9677
1018.08	34.7819
1021.39	35.4268
1024.69	36.6073
1028	40.3483
1031.3	42.5171
1034.6	42.2412
1037.9	38.6039
1041.19	37.6237
1044.49	36.0614
1047.79	34.6599
1051.08	31.2778
1054.37	28.3083
1057.66	25.7507
1060.95	24.3465
1064.24	22.0084
1067.53	18.8391
1070.81	16.1569
1074.1	16.245
1077.38	14.082
1080.66	13.4622
1083.94	12.641
1087.22	10.2442
1090.5	9.5762
1093.78	9.20178
1097.05	10.8639
1100.33	12.5157
1103.6	12.5834
1106.87	14.3017
1110.15	14.3857
1113.41	13.3056
1116.68	12.8663
1119.95	14.6158
1123.21	14.3107
1126.48	14.6753
1129.74	14.547
1133	12.6364
1136.26	12.9357
1139.52	12.674
1142.78	12.4019
1146.04	11.8169
1149.29	12.842
1152.55	11.86
1155.8	12.4521
1159.05	9.95852
1162.3	7.50323
1165.55	7.18877
1168.8	6.36497
1172.05	6.26106
1175.29	7.65664
1178.54	6.51736
1181.78	4.95494
1185.02	5.62041
1188.26	6.00647
1191.5	5.98705
1194.74	5.70617
1197.97	6.93043
1201.21	7.20985
1204.44	8.11604
1207.68	9.74121
1210.91	10.2175
1214.14	12.7354
1217.37	15.9354
1220.6	18.4411
1223.82	21.6916
1227.05	24.0741
1230.27	27.3568
1233.49	29.6259
1236.72	33.0942
1239.94	35.5628
1243.16	37.9362
1246.37	40.8402
1249.59	42.518
1252.8	45.6136
1256.02	48.7372
1259.23	50.4488
1262.44	52.5506
1265.66	54.3506
1268.87	55.7862
1272.07	57.1371
1275.28	59.4572
1278.48	62.3626
1281.69	64.1426
1284.89	67.1069
1288.09	69.2114
1291.3	70.0873
1294.49	71.6777
1297.69	72.6874
1300.89	72.5023
1304.09	73.1268
1307.28	71.6727
1310.47	71.5963
1313.66	72.388
1316.86	72.2678
1320.05	70.8374
1323.23	68.7794
1326.42	68.55
1329.61	66.3251
1332.79	64.8746
1335.98	62.5558
1339.16	61.0613
1342.34	57.2964
1345.52	55.888
1348.7	52.6244
1351.87	50.9184
1355.05	47.952
1358.23	46.1806
1361.4	45.4592
1364.57	43.2949
1367.74	41.7129
1370.91	38.8922
1374.08	37.5173
1377.25	36.5701
1380.42	36.5133
1383.58	36.5373
1386.75	37.2834
1389.91	38.1136
1393.07	38.6211
1396.23	37.2615
1399.39	37.2584
1402.55	37.9481
1405.7	39.8185
1408.86	42.0742
1412.01	45.3811
1415.17	46.8703
1418.32	51.2553
1421.47	55.0085
1424.62	60.193
1427.77	63.013
1430.92	68.1745
1434.06	72.448
1437.2	75.5384
1440.35	78.6322
1443.49	79.2644
1446.63	81.6944
1449.77	82.6262
1452.91	83.5029
1456.05	81.8574
1459.18	80.6948
1462.32	76.38
1465.45	71.3136
1468.59	66.066
1471.72	59.8293
1474.85	52.9067
1477.98	46.3707
1481.11	39.8231
1484.23	33.6797
1487.36	27.9814
1490.48	22.7799
1493.61	19.8578
1496.73	16.4646
1499.85	14.5991
1502.97	13.2187
1506.09	12.0414
1509.2	13.4605
1512.32	13.6258
1515.44	14.0811
1518.55	17.3466
1521.66	19.7056
1524.77	23.9433
1527.88	26.059
1530.99	28.8776
1534.1	31.6938
1537.21	36.3176
1540.31	40.8831
1543.42	44.6061
1546.52	48.1506
1549.62	50.808
1552.72	54.8149
1555.82	58.4932
1558.92	60.9368
1562.02	64.4465
1565.11	66.4949
1568.21	68.7424
1571.3	72.4064
1574.39	74.4318
1577.49	75.63
1580.58	76.7398
1583.67	77.5596
1586.75	77.3407
1589.84	77.7493
1592.93	76.469
1596.01	74.2475
1599.09	74.1179
1602.18	71.2134
1605.26	68.7252
1608.34	67.595
1611.41	66.3999
1614.49	65.8888
1617.57	65.871
1620.64	65.6109
1623.72	64.8881
1626.79	65.5143
1629.86	65.712
1632.93	66.0299
1636	68.6725
1639.07	69.3009
1642.14	71.5107
1645.2	73.6251
1648.27	75.5435
1651.33	76.334
1654.39	77.8765
1657.45	79.0009
1660.51	79.6115
1663.57	78.3516
1666.63	75.6908
1669.69	73.4933
1672.74	72.0696
1675.79	69.535
1678.85	64.073
1681.9	58.59
1684.95	54.2617
1688	48.5357
1691.05	42.8014
1694.1	37.3518
1697.14	32.3587
1700.19	26.9897
1703.23	21.4586
1706.27	17.6653
1709.32	14.3776
1712.35	10.5501
1715.39	8.19074
1718.43	6.66532
1721.47	6.01668
1724.5	5.59337
1727.54	3.49029
1730.57	4.25624
1733.61	3.48128
1736.64	3.31723
1739.67	2.87272
1742.7	2.66429
1745.72	3.41667
1748.75	3.47421
1751.78	2.1622
1754.8	1.51218
1757.82	0.298899
1760.85	0.378518
1763.87	0.274417
1766.89	-0.188472
1769.91	-0.381533
1772.92	0.0783814
1775.94	-1.17845
1778.96	-0.58909
1781.97	0.425498
1784.98	0.225861
1788	0.0939509
1791.01	1.09714
1794.01	0.799852
1797.02	1.5295
1800.03	0.828379
1803.04	1.04289
1806.04	1.59486
1809.05	1.50299
1812.05	1.05583
1815.05	0.730808
1818.05	1.0149
1821.05	0.78678
1824.05	0.799979
1827.05	1.03578
1830.04	1.2254
1833.04	1.54373
1836.03	2.39824
1839.03	2.7391
1842.02	2.5323
1845.01	3.71062
1848	4.06753
1850.99	4.04531
1853.97	3.77227
1856.96	4.0161
1859.94	3.76669
1862.93	3.23552
1865.91	3.72317
1868.89	2.43135
1871.87	2.78209
1874.85	3.29614
1877.83	4.41356
1880.81	4.37223
1882.56	4.35236
1885.55	4.15082
1888.54	4.87472
1891.52	4.66064
1894.51	4.2735
1897.49	5.14824
1900.48	6.53065
1903.46	5.9223
1906.44	6.4336
1909.42	6.62777
1912.4	7.73774
1915.38	7.63545
1918.35	8.22723
1921.33	7.28327
1924.3	6.51625
1927.28	6.16185
1930.25	5.93116
1933.22	4.88107
1936.19	4.53176
1939.16	3.68694
1942.13	3.29895
1945.09	3.34621
1948.06	3.68085
1951.03	3.32034
1953.99	1.70163
1956.95	1.60012
1959.91	0.994965
1962.87	1.46825
1965.83	0.623892
1968.79	0.0380932
1971.75	1.04753
1974.7	0.377897
1977.66	0.656291
1980.61	1.00542
1983.56	1.3869
1986.52	3.09002
1989.47	2.88719
1992.41	3.4185
1995.36	4.1047
1998.31	4.41776
2001.26	3.81701
2004.2	3.11851
2007.15	3.24277
2010.09	3.52386
2013.03	3.70786
2015.97	3.9857
2018.91	4.66863
2021.85	5.69797
2024.79	6.81659
2027.72	7.1076
2030.66	7.84233
2033.59	7.61073
2036.53	8.2262
2039.46	8.85267
2042.39	8.89653
2045.32	10.7564
2048.25	11.2577
2051.18	11.6393
2054.1	12.3913
2057.03	12.5511
2059.95	13.4543
2062.88	13.9711
2065.8	15.0803
2068.72	15.7078
2071.64	16.6869
2074.56	17.7963
2077.48	19.5353
2080.39	22.2189
2083.31	24.0322
2086.22	26.2486
2089.14	28.7211
2092.05	30.9304
2094.96	32.5382
2097.87	34.9285
2100.78	37.0532
2103.69	40.733
2106.6	43.847
2109.51	47.2086
2112.41	50.7434
2115.32	54.3319
2118.22	57.4808
2121.12	59.9269
2124.02	64.1559
2126.92	67.7403
2129.82	71.5627
2132.72	75.3374
2135.62	79.9096
2138.51	83.9708
2141.41	88.271
2144.3	91.673
2147.19	95.0221
2150.09	98.2587
2152.97	100.627
2155.86	102.325
2158.75	103.508
2161.64	104.849
2164.53	105.435
2167.41	106.75
2170.3	107.987
2173.18	107.333
2176.06	106.657
2178.94	104.737
2181.82	103.081
2184.7	101.281
2187.58	97.7957
2190.46	94.2401
2193.33	91.1901
2196.21	87.2761
2199.08	84.917
2201.95	80.9557
2204.83	77.0247
2207.7	73.0117
2210.57	68.6222
2213.43	64.4224
2216.3	60.7182
2219.17	57.8239
2222.03	53.9438
2224.9	50.8996
2227.76	48.7037
2230.62	44.7974
2233.49	42.3693
2236.34	39.931
2239.2	38.9743
2242.06	37.7838
2244.92	35.3838
2247.78	34.6748
2250.63	33.7091
2253.48	33.4475
2256.34	32.3171
2259.19	30.528
2262.04	30.0917
2264.89	29.5605
2267.74	29.2775
2270.59	28.2275
2273.43	27.2225
2276.28	25.4923
2279.12	24.8888
2281.97	24.3268
2284.81	23.6611
2287.65	22.339
2290.49	20.08
2293.33	17.8607
2296.17	16.2315
2299.01	15.7609
2301.84	15.2611
2304.68	15.1636
2307.51	15.669
2310.35	16.4024
2313.18	15.0138
2316.01	14.5247
2318.84	14.3691
2321.67	13.3857
2324.5	12.68
2327.33	11.7004
2330.15	11.8314
2332.98	10.5052
2335.8	9.61567
2338.62	7.74753
2341.45	6.41996
2344.27	6.16538
2347.09	5.52002
2349.91	5.39878
2352.72	4.61717
2355.54	3.29318
2358.36	3.38531
2361.17	3.13929
2363.98	4.26727
2366.8	5.17954
2369.61	5.83443
2372.42	5.45436
2375.23	5.51973
2378.04	5.5992
2380.85	5.27318
2383.66	4.42534
2386.46	4.34452
2389.26	4.03224
2392.07	3.57608
2394.87	4.57416
2397.67	4.88875
2400.47	3.84923
2403.27	3.34645
2406.07	2.58425
2408.87	2.51204
2411.67	3.14557
2414.46	3.75891
2417.26	4.48352
2420.05	5.51693
2422.84	6.49607
2425.64	8.11464
2428.43	9.85077
2431.22	11.4481
2434.01	10.9206
2436.79	10.3434
2439.58	10.0545
2442.37	9.43988
2445.15	9.57784
2447.93	9.42598
2450.72	9.1936
2453.5	8.0571
2456.28	8.15648
2459.06	7.03118
2461.84	6.62307
2464.62	6.96522
2467.39	5.18418
2470.17	3.48404
2472.94	2.78139
2475.72	2.67628
2478.49	3.01104
2481.26	1.91394
2484.03	2.46557
2486.8	2.93058
2489.57	3.58453
2492.34	4.58365
2495.1	4.79409
2497.87	5.60637
2500.63	5.0584
2503.4	4.32315
2506.16	4.7162
2508.92	5.55386
2511.68	5.4976
2514.44	5.00492
2517.2	6.20681
2519.96	5.72407
2522.72	6.24705
2525.47	6.56816
2528.23	6.2318
2530.98	6.59657
2533.74	6.62241
2536.49	6.10585
2539.24	6.35803
2541.99	5.74843
2544.74	5.06074
2547.49	5.73785
2550.23	5.94477
2552.98	6.3414
2555.72	6.1655
2558.47	5.8128
2561.21	6.45666
2563.95	5.94033
2566.69	5.41749
2569.43	5.3249
2572.17	4.52227
2574.91	4.87224
2577.65	3.4175
2580.39	4.19385
2583.12	4.73034
2585.85	5.23718
2588.59	5.49546
2591.32	5.397
2594.05	4.63937
2596.78	4.44089
2599.51	3.53696
2602.24	3.03717
2604.97	2.72179
2607.69	2.81308
2610.42	3.3929
2613.14	4.45876
2615.87	3.9875
2618.59	4.42292
2621.31	4.15704
2624.03	4.72693
2626.75	5.20142
2629.47	4.47055
2632.19	4.20992
2634.91	3.85621
2637.62	4.77659
2640.34	5.17295
2643.05	5.14668
2645.76	5.6556
2648.48	5.81524
2651.19	5.99491
2653.9	6.02937
2656.6	6.40927
2659.31	6.00365
2662.02	5.7615
2664.73	5.82813
2667.43	6.5759
2670.14	7.98538
2672.84	8.19861
2675.54	8.60729
2678.24	9.44334
2680.94	9.04134
2683.64	9.03333
2686.34	9.32956
2689.04	9.75164
2691.74	8.97236
2694.43	9.47906
2697.13	9.26081
2699.82	9.91842
2702.51	10.4249
2705.21	11.9088
2707.9	11.017
2710.58	10.9281
2713.27	10.5775
2715.96	11.1495
2718.65	11.3635
2721.33	11.7443
2724.02	12.0825
2726.71	11.3249
2729.39	11.536
2732.07	11.4682
2734.75	11.8487
2737.43	10.6945
2740.11	10.2293
2742.79	9.87302
2745.47	8.26704
2748.14	8.58467
2750.82	7.64518
2753.49	8.39444
2756.17	7.43991
2758.84	6.44846
2761.51	5.85608
2764.18	4.82466
2766.85	4.59538
2769.52	4.14585
2772.19	4.2093
2774.86	3.03959
2777.52	3.34311
2780.19	2.97914
2782.85	2.66301
2785.52	2.37193
2788.18	2.4734
2790.84	2.00461
2793.5	1.72742
2796.16	1.78338
2798.82	1.86778
2801.48	1.7448
2804.13	1.71068
2806.79	1.63883
2809.45	2.07271
2812.1	2.54065
2814.75	2.36102
2817.41	3.57301
2820.06	6.1439
2822.71	9.678
2825.36	15.0469
2828	19.8319
2830.65	26.761
2833.3	34.327
2835.94	41.7806
2838.59	47.6849
2841.23	53.5191
2843.87	62.1796
2846.52	70.3103
2849.16	79.1923
2851.8	87.7877
2854.44	97.2687
2857.08	107.247
2859.71	116.709
2862.35	126.066
2864.98	133.613
2867.62	139.621
2870.25	145.086
2872.88	148.817
2875.52	151.732
2878.15	155.17
2880.78	158.872
2883.41	163.053
2886.03	168.025
2888.66	172.371
2891.29	175.623
2893.91	179.562
2896.54	182.733
2899.16	186.327
2901.78	190.737
2904.4	194.665
2907.02	201.734
2909.64	209.839
2912.26	217.139
2914.88	227.044
2917.5	235.997
2920.11	244.075
2922.73	250.041
2925.34	254.5
2927.96	257.044
2930.57	257.765
2933.18	257.088
2935.79	254.481
2938.4	250.497
2941.01	245.701
2943.62	239.454
2946.22	232.163
2948.83	223.361
2951.43	215.49
2954.04	206.236
2956.64	196.346
2959.24	186.816
2961.84	177.418
2964.45	168.362
2967.05	159.968
2969.64	151.206
2972.24	144.484
2974.84	135.918
2977.43	128.137
2980.03	120.13
2982.62	111.501
2985.22	101.871
2987.81	92.0487
2990.4	82.6471
2992.99	73.7489
2995.58	66.4561
2998.17	58.1981
3000.76	50.7223
3003.34	43.0151
3005.93	36.0049
3008.52	30.2656
3011.1	24.3822
3013.68	19.8017
3016.27	16.4819
3018.85	14.0986
3021.43	11.566
3024.01	9.9832
3026.59	9.12806
3029.16	8.94479
3031.74	8.54868
3034.32	9.70884
3036.89	11.286
3039.47	11.6645
3042.04	13.2046
3044.61	13.8849
3047.18	14.4066
3049.75	15.0462
3052.32	15.434
3054.89	16.784
3057.46	16.8327
3060.03	16.6605
3062.59	16.1521
3065.16	15.344
3067.72	13.9592
3070.29	13.6467
3072.85	12.2936
3075.41	11.189
3077.97	10.346
3080.53	9.45231
3083.09	7.73529
3085.65	5.32621
3088.21	3.40665
3090.76	1.43535
3093.32	0.812997
3095.87	0.634284
3098.43	1.19804
3100.98	2.51359
3103.53	3.35322
3106.08	4.29249
3108.63	4.29807
3111.18	5.71323
3113.73	6.88148
3116.28	9.48436
3118.83	11.2547
3121.37	12.5682
3123.92	14.8449
3126.46	16.3932
3129	17.8792
3131.55	18.7662
3134.09	21.005
3136.63	21.364
3139.17	22.3042
3141.71	21.5215
3144.24	20.0994
3146.78	19.4149
3149.32	18.4962