File: data/Raman/poly_smoothed/Thy_50_12_41_1x_45s_532 nm_x100_100%_600 gr_mm_01.txt
#Acq. time (s)=	45
#Accumulations=	2
#Range (cm-¹)=	200...3150
#Windows=	2
#Auto scanning=	Off
#Autofocus=	Off
#Macrospot=	Off
#AutoExposure=	Off
#Spike filter=	Multiple accum.
#Delay time (s)=	0
#Binning=	1
#Readout mode=	Signal
#DeNoise=	Off
#ICS correction=	On
#Dark correction=	Off
#Inst. Process=	Off
#Detector Gain=	Best Dynamic Range
#Detector ADC=	20 kHz
#Detector temperature (°C)=	-69.85
#Instrument=	LabRAM HR Evol
#Detector=	Synapse
#Objective=	x100
#Grating=	600 gr/mm
#ND Filter=	100%
#Laser (nm)=	532
#Hole=	100.021
#Range=	Auto
#Laser Pol.=	No
#Raman. Pol.=	No
#Laser Pol. (°)=	-0.0007625
#Raman Pol. (°)=	89.9995
#Collection=	Microscope
#StageXY=	Marzhauser
#StageZ=	Marzhauser
#X (µm)=	-5125.6
#Y (µm)=	1517.7
#Z (µm)=	63.25
#Full time(mm:ss)=	3:18
#Project=
#Sample=
#Site=
#Title=	Thy_50_12_41_2x_45s_532 nm_x100_100%_600 gr_mm
#Remark=
#Date=	07.07.2022 12:15
#Acquired=	07.07.2022 12:15:57
#Base:Fit=	10.08.2022 10:04:30
#Base:Sub=	10.08.2022 10:04:45
#Filter:Polynom=	16.08.2022 10:20:25
#AxisType[0]=Intens
#AxisUnit[0]=Cnt
#AxisType[1]=Spectr
#AxisUnit[1]=1/cm
200.43	18.0761
204.061	17.0321
207.688	14.9421
211.316	13.1811
214.941	12.8053
218.566	11.7748
222.188	11.7862
225.809	11.9757
229.43	12.5649
233.047	12.3848
236.663	11.483
240.278	12.1551
243.894	13.555
247.506	13.9587
251.116	13.8715
254.725	14.4959
258.333	15.9405
261.939	16.4429
265.546	18.4394
269.15	19.1296
272.752	17.4755
276.353	17.9112
279.952	19.6212
283.55	20.6386
287.146	18.911
290.739	18.9504
294.333	19.6399
297.925	19.9296
301.516	20.3943
305.106	20.542
308.694	20.9861
312.279	21.0487
315.864	20.7895
319.448	19.4531
323.029	19.4701
326.61	18.7868
330.19	20.3702
333.766	20.2624
337.343	18.4441
340.917	16.759
344.491	16.105
348.062	15.4534
351.633	14.0746
355.201	14.882
358.77	14.4025
362.335	15.0562
365.899	14.4331
369.464	15.3148
373.025	14.1004
376.585	14.1164
380.143	14.5402
383.702	12.7113
387.258	11.4278
390.812	11.1425
394.365	11.5615
397.916	10.1689
401.467	9.5799
405.015	8.46749
408.565	7.99564
412.111	8.22486
415.656	7.4728
419.197	7.00707
422.739	6.28531
426.279	7.8394
429.819	6.6178
433.356	6.58334
436.893	7.05159
440.428	8.36233
443.96	7.89588
447.492	8.68243
451.023	9.93381
454.553	9.69957
458.079	10.6177
461.606	10.5946
465.132	12.0589
468.654	13.3194
472.177	13.8416
475.696	15.3006
479.217	17.2119
482.733	17.6616
486.251	19.3222
489.765	20.1311
493.278	20.6446
496.791	21.7568
500.301	21.6388
503.81	23.0972
507.319	24.2074
510.825	25.8869
514.33	26.3045
517.833	24.2519
521.337	23.4264
524.838	23.9652
528.337	22.7601
531.835	20.8631
535.332	19.4953
538.827	18.0502
542.321	16.1684
545.814	15.1192
549.305	13.2125
552.795	12.7499
556.284	9.77839
559.771	8.7392
563.257	7.88348
566.742	5.66028
570.223	3.60629
573.705	0.944454
577.185	-0.0105631
580.665	0.377392
584.141	1.12001
587.617	0.928311
591.092	0.85031
594.564	-0.0163456
598.037	2.00923
601.506	3.55927
604.976	4.89934
608.443	7.22476
611.91	9.47201
615.374	9.72977
618.839	10.4884
622.3	10.4779
625.761	11.3973
629.221	11.1611
632.679	10.6673
636.135	12.0778
639.592	13.1522
643.045	12.1052
646.497	13.3179
649.948	13.3514
653.398	12.7055
656.846	14.3577
660.293	14.4656
663.738	13.7002
667.185	13.0761
670.628	12.0633
674.067	13.2774
677.508	14.2032
680.947	16.8647
684.385	19.744
687.821	22.0195
691.256	23.2603
694.69	24.8457
698.121	23.7583
701.552	24.6518
704.982	25.485
708.41	26.6436
711.836	28.5837
715.262	30.369
718.685	32.9517
722.108	35.6138
725.53	35.5235
728.949	35.4907
732.369	37.7812
735.785	39.5546
739.2	41.9421
742.616	44.1446
746.028	45.7203
749.441	47.1475
752.851	49.8008
756.26	54.4691
759.667	58.8317
763.075	60.3252
766.479	62.5661
769.883	65.603
773.285	67.0097
776.686	67.9451
780.085	69.1174
783.484	69.6745
786.881	71.179
790.276	74.4465
793.671	76.945
797.064	79.3854
800.456	79.5123
803.846	81.9966
807.236	82.2093
810.624	82.6118
814.01	83.407
817.394	85.0192
820.778	85.279
824.161	85.582
827.543	85.4911
830.921	83.4014
834.3	82.5999
837.676	80.7102
841.053	79.4165
844.426	74.3119
847.8	70.5347
851.171	67.7208
854.542	63.9894
857.911	59.7048
861.279	55.3841
864.645	51.6553
868.01	48.7821
871.375	49.6655
874.737	50.132
878.097	48.2047
881.457	48.0498
884.817	47.2102
888.174	45.6334
891.53	46.2743
894.884	45.4513
898.237	44.1912
901.589	43.4355
904.94	42.0543
908.289	44.0896
911.637	43.2376
914.984	42.6307
918.33	42.8731
921.674	41.9271
925.015	39.648
928.357	37.458
931.698	36.0906
935.037	36.2009
938.373	35.1188
941.71	33.3538
945.046	29.726
948.378	29.0774
951.711	32.1354
955.043	33.6681
958.372	31.8492
961.701	31.8973
965.027	32.5888
968.354	33.9575
971.678	34.1672
975	35.3904
978.324	34.497
981.644	35.9243
984.962	36.9476
988.282	38.5519
991.598	38.2426
994.913	39.1047
998.227	38.539
1001.54	37.9868
1004.85	35.5632
1008.16	36.8029
1011.47	38.0915
1014.78	39.0222
1018.08	40.2716
1021.39	40.4918
1024.69	39.8692
1028	41.616
1031.3	43.1114
1034.6	43.4823
1037.9	42.8101
1041.19	41.9426
1044.49	41.8311
1047.79	41.4465
1051.08	38.2412
1054.37	37.6014
1057.66	35.7392
1060.95	33.3843
1064.24	31.8228
1067.53	28.9659
1070.81	25.3684
1074.1	23.7986
1077.38	21.4157
1080.66	20.0119
1083.94	19.1988
1087.22	19.3688
1090.5	19.9223
1093.78	21.1895
1097.05	23.5906
1100.33	24.7821
1103.6	25.0129
1106.87	25.0263
1110.15	24.9087
1113.41	25.0334
1116.68	25.9981
1119.95	24.5883
1123.21	23.4377
1126.48	21.2898
1129.74	21.4127
1133	19.7093
1136.26	18.3771
1139.52	16.8381
1142.78	14.9905
1146.04	12.0205
1149.29	9.64253
1152.55	7.54426
1155.8	5.53627
1159.05	4.34906
1162.3	2.83227
1165.55	1.74663
1168.8	0.749716
1172.05	1.95577
1175.29	2.75952
1178.54	2.55012
1181.78	1.96249
1185.02	2.4529
1188.26	3.70379
1191.5	4.82975
1194.74	6.05471
1197.97	8.02977
1201.21	11.7372
1204.44	14.2078
1207.68	16.1013
1210.91	19.8801
1214.14	23.7057
1217.37	26.8122
1220.6	30.5942
1223.82	33.5113
1227.05	35.1719
1230.27	39.5733
1233.49	42.273
1236.72	45.1141
1239.94	48.3241
1243.16	50.7768
1246.37	53.3234
1249.59	54.7379
1252.8	55.7239
1256.02	56.6897
1259.23	59.0926
1262.44	61.4629
1265.66	64.7684
1268.87	66.3638
1272.07	69.7742
1275.28	72.9665
1278.48	75.3679
1281.69	78.0111
1284.89	80.3033
1288.09	83.244
1291.3	85.9053
1294.49	87.31
1297.69	87.4053
1300.89	88.2053
1304.09	88.1082
1307.28	88.1655
1310.47	87.8509
1313.66	88.9309
1316.86	87.451
1320.05	85.3836
1323.23	84.1087
1326.42	81.2068
1329.61	80.2266
1332.79	77.7139
1335.98	75.7492
1339.16	73.1874
1342.34	69.7367
1345.52	65.9805
1348.7	63.6129
1351.87	61.4283
1355.05	59.4828
1358.23	58.2946
1361.4	56.7138
1364.57	55.7548
1367.74	53.6931
1370.91	51.4466
1374.08	50.9957
1377.25	50.3573
1380.42	49.0165
1383.58	48.4941
1386.75	47.8845
1389.91	47.9708
1393.07	46.8274
1396.23	44.6581
1399.39	44.1528
1402.55	45.1842
1405.7	45.6515
1408.86	47.4711
1412.01	49.0368
1415.17	51.3573
1418.32	53.9326
1421.47	57.6028
1424.62	62.8958
1427.77	69.2111
1430.92	76.087
1434.06	82.9932
1437.2	87.4796
1440.35	90.456
1443.49	93.1657
1446.63	95.1216
1449.77	95.5351
1452.91	94.7444
1456.05	93.2332
1459.18	88.8502
1462.32	84.6764
1465.45	79.0884
1468.59	72.9241
1471.72	67.5837
1474.85	61.8878
1477.98	56.595
1481.11	50.6704
1484.23	45.5372
1487.36	39.9616
1490.48	35.7535
1493.61	32.3746
1496.73	29.929
1499.85	29.6352
1502.97	29.6737
1506.09	29.0199
1509.2	27.978
1512.32	27.2542
1515.44	26.1857
1518.55	25.5315
1521.66	25.6784
1524.77	25.0955
1527.88	25.1374
1530.99	26.7258
1534.1	27.5823
1537.21	30.0285
1540.31	33.7996
1543.42	37.0476
1546.52	42.1775
1549.62	46.1783
1552.72	49.7164
1555.82	52.9027
1558.92	55.8798
1562.02	59.2659
1565.11	62.3802
1568.21	67.1281
1571.3	72.0023
1574.39	76.6338
1577.49	80.5859
1580.58	82.671
1583.67	84.172
1586.75	86.8315
1589.84	86.8956
1592.93	86.7137
1596.01	85.4566
1599.09	84.2218
1602.18	82.4228
1605.26	81.3238
1608.34	80.4565
1611.41	79.1812
1614.49	79.5777
1617.57	78.6875
1620.64	80.8826
1623.72	82.3482
1626.79	83.3533
1629.86	84.1419
1632.93	86.9622
1636	88.9768
1639.07	92.1192
1642.14	94.7614
1645.2	98.0957
1648.27	101.252
1651.33	103.804
1654.39	104.784
1657.45	104.784
1660.51	104.889
1663.57	101.339
1666.63	97.4364
1669.69	92.6807
1672.74	85.9905
1675.79	80.2248
1678.85	73.2795
1681.9	66.0167
1684.95	57.876
1688	51.7621
1691.05	46.0816
1694.1	41.3967
1697.14	36.3853
1700.19	31.4332
1703.23	27.0555
1706.27	24.418
1709.32	20.4445
1712.35	17.7919
1715.39	15.1659
1718.43	14.314
1721.47	13.6766
1724.5	13.6665
1727.54	12.6507
1730.57	12.1397
1733.61	11.7975
1736.64	10.5441
1739.67	10.1448
1742.7	9.33686
1745.72	8.06388
1748.75	7.14196
1751.78	6.49576
1754.8	5.38369
1757.82	5.66155
1760.85	4.72756
1763.87	5.08651
1766.89	4.69922
1769.91	4.21639
1772.92	3.8635
1775.94	4.34322
1778.96	4.149
1781.97	3.45878
1784.98	2.77722
1788	1.98381
1791.01	2.10107
1794.01	2.35355
1797.02	1.73324
1800.03	2.00939
1803.04	2.64193
1806.04	2.88234
1809.05	2.81696
1812.05	3.27788
1815.05	3.55205
1818.05	3.38674
1821.05	3.33277
1824.05	3.44591
1827.05	3.08619
1830.04	3.10159
1833.04	1.96216
1836.03	1.36687
1839.03	1.42079
1842.02	1.00386
1845.01	1.70461
1848	1.97886
1850.99	1.79304
1853.97	0.783215
1856.96	1.00443
1859.94	1.4887
1862.93	1.42539
1865.91	1.42872
1868.89	2.0005
1871.87	2.51126
1874.85	3.95219
1877.83	4.27083
1880.81	4.41698
1882.56	4.28087
1885.55	4.70573
1888.54	4.39644
1891.52	4.18289
1894.51	4.19716
1897.49	3.81906
1900.48	4.13324
1903.46	4.28869
1906.44	3.32732
1909.42	4.01021
1912.4	3.72982
1915.38	4.5787
1918.35	4.73759
1921.33	5.30121
1924.3	5.49873
1927.28	5.59563
1930.25	6.04719
1933.22	6.08006
1936.19	6.38408
1939.16	6.47668
1942.13	6.04881
1945.09	6.30743
1948.06	5.51247
1951.03	4.59973
1953.99	4.12585
1956.95	3.67335
1959.91	3.26293
1962.87	4.27358
1965.83	3.60794
1968.79	4.28033
1971.75	3.58468
1974.7	2.82725
1977.66	1.93688
1980.61	1.65152
1983.56	2.22832
1986.52	1.76411
1989.47	2.94389
1992.41	3.4759
1995.36	3.36365
1998.31	3.54987
2001.26	4.38524
2004.2	5.11996
2007.15	5.69643
2010.09	6.9772
2013.03	5.66852
2015.97	5.94015
2018.91	6.46121
2021.85	6.69288
2024.79	6.79273
2027.72	8.0141
2030.66	8.34453
2033.59	8.22856
2036.53	8.11779
2039.46	8.49338
2042.39	8.54063
2045.32	9.11025
2048.25	9.31868
2051.18	9.54878
2054.1	11.427
2057.03	12.5382
2059.95	14.0677
2062.88	15.7887
2065.8	16.5841
2068.72	18.6206
2071.64	20.168
2074.56	21.9317
2077.48	24.3566
2080.39	26.3586
2083.31	28.3781
2086.22	30.045
2089.14	32.627
2092.05	34.9726
2094.96	36.9217
2097.87	39.6714
2100.78	43.4978
2103.69	46.5947
2106.6	50.4973
2109.51	54.3099
2112.41	58.3541
2115.32	62.1939
2118.22	66.6525
2121.12	71.498
2124.02	76.8998
2126.92	82.0089
2129.82	86.7227
2132.72	91.4122
2135.62	95.5293
2138.51	100.256
2141.41	104.9
2144.3	109.099
2147.19	113.278
2150.09	117.228
2152.97	121.657
2155.86	125.422
2158.75	127.88
2161.64	129.804
2164.53	132.346
2167.41	133.814
2170.3	134.559
2173.18	133.578
2176.06	131.684
2178.94	129.454
2181.82	127.447
2184.7	125.619
2187.58	121.714
2190.46	116.691
2193.33	112.984
2196.21	109.35
2199.08	104.905
2201.95	101.111
2204.83	96.8439
2207.7	91.8103
2210.57	87.2903
2213.43	83.5683
2216.3	79.9254
2219.17	76.4588
2222.03	73.5585
2224.9	70.1615
2227.76	67.1363
2230.62	63.2546
2233.49	59.1703
2236.34	56.9852
2239.2	53.1312
2242.06	49.935
2244.92	47.1385
2247.78	43.7155
2250.63	40.9945
2253.48	39.5328
2256.34	36.3747
2259.19	32.8978
2262.04	31.1355
2264.89	30.5849
2267.74	28.9867
2270.59	27.3697
2273.43	25.2576
2276.28	23.4681
2279.12	21.6261
2281.97	20.527
2284.81	19.7841
2287.65	18.4195
2290.49	16.7374
2293.33	14.5923
2296.17	14.4406
2299.01	14.4375
2301.84	14.6905
2304.68	15.3153
2307.51	15.3703
2310.35	14.4885
2313.18	14.2501
2316.01	14.4789
2318.84	14.3771
2321.67	14.4095
2324.5	13.7783
2327.33	12.7284
2330.15	13.536
2332.98	12.8572
2335.8	11.5415
2338.62	10.0633
2341.45	8.64129
2344.27	7.23481
2347.09	6.78471
2349.91	6.00985
2352.72	5.42804
2355.54	4.72661
2358.36	4.12257
2361.17	3.29891
2363.98	3.48725
2366.8	4.83041
2369.61	3.88803
2372.42	5.18029
2375.23	4.56605
2378.04	4.56548
2380.85	5.15476
2383.66	5.96545
2386.46	7.22547
2389.26	7.51239
2392.07	7.27656
2394.87	8.49924
2397.67	9.35001
2400.47	8.58795
2403.27	8.13855
2406.07	8.37696
2408.87	8.19972
2411.67	8.18356
2414.46	9.06977
2417.26	9.22763
2420.05	9.67803
2422.84	10.2195
2425.64	10.3709
2428.43	9.45894
2431.22	8.9101
2434.01	8.29333
2436.79	8.42104
2439.58	9.1604
2442.37	10.1494
2445.15	9.62906
2447.93	9.29083
2450.72	9.61676
2453.5	10.3128
2456.28	9.58135
2459.06	8.91078
2461.84	8.75355
2464.62	8.73395
2467.39	7.88984
2470.17	8.26984
2472.94	8.1835
2475.72	7.7013
2478.49	7.64982
2481.26	7.36852
2484.03	7.17943
2486.8	7.61196
2489.57	7.02022
2492.34	6.18935
2495.1	5.8281
2497.87	5.12867
2500.63	5.05934
2503.4	4.20766
2506.16	3.35029
2508.92	3.18831
2511.68	2.15381
2514.44	1.63812
2517.2	1.12446
2519.96	0.963063
2522.72	0.6373
2525.47	-0.216124
2528.23	-1.05757
2530.98	-0.74283
2533.74	-0.70048
2536.49	-0.746483
2539.24	-0.552651
2541.99	-0.617698
2544.74	0.726449
2547.49	1.60997
2550.23	2.06916
2552.98	2.09641
2555.72	2.49898
2558.47	2.2316
2561.21	3.27827
2563.95	3.75503
2566.69	2.67366
2569.43	3.43893
2572.17	2.57835
2574.91	2.71468
2577.65	3.33874
2580.39	2.39452
2583.12	2.43494
2585.85	2.69504
2588.59	1.46124
2591.32	0.575981
2594.05	0.21467
2596.78	0.535682
2599.51	0.762647
2602.24	1.55527
2604.97	1.66284
2607.69	1.68957
2610.42	1.93387
2613.14	2.43802
2615.87	2.51859
2618.59	2.9766
2621.31	3.62271
2624.03	3.64219
2626.75	2.87052
2629.47	3.74304
2632.19	3.87672
2634.91	3.39635
2637.62	3.13915
2640.34	3.49484
2643.05	3.34394
2645.76	3.27251
2648.48	2.7483
2651.19	2.64398
2653.9	2.31979
2656.6	1.65603
2659.31	2.22164
2662.02	2.01649
2664.73	2.12995
2667.43	2.35148
2670.14	2.13291
2672.84	2.43059
2675.54	2.48736
2678.24	2.3979
2680.94	3.79101
2683.64	3.83908
2686.34	4.00211
2689.04	3.88627
2691.74	3.94564
2694.43	4.14286
2697.13	4.07431
2699.82	3.79922
2702.51	4.21913
2705.21	5.41436
2707.9	6.17516
2710.58	6.97347
2713.27	8.27792
2715.96	8.79943
2718.65	8.48932
2721.33	8.40808
2724.02	8.82447
2726.71	9.517
2729.39	9.45094
2732.07	9.87946
2734.75	11.3041
2737.43	10.8382
2740.11	10.2581
2742.79	9.91239
2745.47	10.1039
2748.14	9.52078
2750.82	8.73583
2753.49	8.33679
2756.17	7.50312
2758.84	6.06543
2761.51	5.23729
2764.18	4.36082
2766.85	4.54206
2769.52	4.82792
2772.19	4.14046
2774.86	3.23413
2777.52	2.9623
2780.19	2.07878
2782.85	0.665297
2785.52	-0.172087
2788.18	-0.650268
2790.84	-0.533614
2793.5	-0.890042
2796.16	-1.16233
2798.82	-0.145926
2801.48	-0.659898
2804.13	-1.10611
2806.79	-2.00389
2809.45	-2.70622
2812.1	-2.8531
2814.75	-2.41654
2817.41	-0.767642
2820.06	2.18224
2822.71	5.6404
2825.36	10.3231
2828	17.0838
2830.65	22.8394
2833.3	29.144
2835.94	35.8583
2838.59	42.1733
2841.23	49.8271
2843.87	58.0382
2846.52	66.3324
2849.16	75.7446
2851.8	86.6121
2854.44	97.2476
2857.08	108
2859.71	117.596
2862.35	126.679
2864.98	135.323
2867.62	141.963
2870.25	148.14
2872.88	152.581
2875.52	156.429
2878.15	160.597
2880.78	164.986
2883.41	170.125
2886.03	173.911
2888.66	177.998
2891.29	182.29
2893.91	186.572
2896.54	191.249
2899.16	197.87
2901.78	205.626
2904.4	213.314
2907.02	223.985
2909.64	236.056
2912.26	248.292
2914.88	261.864
2917.5	273.857
2920.11	284.721
2922.73	293.663
2925.34	300.966
2927.96	306.58
2930.57	308.972
2933.18	308.359
2935.79	305.438
2938.4	300.398
2941.01	294.573
2943.62	287.133
2946.22	277.596
2948.83	266.241
2951.43	253.895
2954.04	243.146
2956.64	231.199
2959.24	219.782
2961.84	207.978
2964.45	196.834
2967.05	184.99
2969.64	174.917
2972.24	165.138
2974.84	154.889
2977.43	144.287
2980.03	133.581
2982.62	123.088
2985.22	113.122
2987.81	103.262
2990.4	93.0548
2992.99	82.8424
2995.58	73.1194
2998.17	64.7729
3000.76	56.2211
3003.34	49.1026
3005.93	42.8507
3008.52	36.8397
3011.1	31.8974
3013.68	26.7738
3016.27	23.4208
3018.85	20.3968
3021.43	18.3867
3024.01	16.5876
3026.59	14.6971
3029.16	14.5456
3031.74	14.8353
3034.32	15.3574
3036.89	15.1403
3039.47	16.0517
3042.04	17.4957
3044.61	18.5302
3047.18	19.0084
3049.75	20.2344
3052.32	21.4068
3054.89	20.7414
3057.46	20.1453
3060.03	18.427
3062.59	18.0892
3065.16	16.1559
3067.72	15.1737
3070.29	13.2935
3072.85	10.5855
3075.41	8.22384
3077.97	6.15987
3080.53	4.41891
3083.09	3.0451
3085.65	1.7067
3088.21	0.810181
3090.76	-0.396348
3093.32	-0.598482
3095.87	-0.40744
3098.43	0.127873
3100.98	-0.0850108
3103.53	0.268154
3106.08	0.902999
3108.63	1.84638
3111.18	2.8468
3113.73	4.2645
3116.28	4.57029
3118.83	5.14993
3121.37	6.39168
3123.92	6.67098
3126.46	7.80109
3129	8.81585
3131.55	9.65991
3134.09	9.96226
3136.63	10.728
3139.17	11.9158
3141.71	12.4007
3144.24	12.9098
3146.78	13.6127
3149.32	13.4319