File: data/Raman/poly_smoothed/Thy_50_12_30_1x_45s_532 nm_x100_100%_600 gr_mm_01.txt
#Acq. time (s)=	45
#Accumulations=	2
#Range (cm-¹)=	200...3150
#Windows=	2
#Auto scanning=	Off
#Autofocus=	Off
#Macrospot=	Off
#AutoExposure=	Off
#Spike filter=	Multiple accum.
#Delay time (s)=	0
#Binning=	1
#Readout mode=	Signal
#DeNoise=	Off
#ICS correction=	On
#Dark correction=	Off
#Inst. Process=	Off
#Detector Gain=	Best Dynamic Range
#Detector ADC=	20 kHz
#Detector temperature (°C)=	-69.85
#Instrument=	LabRAM HR Evol
#Detector=	Synapse
#Objective=	x100
#Grating=	600 gr/mm
#ND Filter=	100%
#Laser (nm)=	532
#Hole=	100.021
#Range=	Auto
#Laser Pol.=	No
#Raman. Pol.=	No
#Laser Pol. (°)=	-0.0007625
#Raman Pol. (°)=	89.9995
#Collection=	Microscope
#StageXY=	Marzhauser
#StageZ=	Marzhauser
#X (µm)=	-5132.3
#Y (µm)=	1509
#Z (µm)=	63.5
#Full time(mm:ss)=	3:19
#Project=
#Sample=
#Site=
#Title=	Thy_50_12_30_2x_45s_532 nm_x100_100%_600 gr_mm
#Remark=
#Date=	07.07.2022 11:26
#Acquired=	07.07.2022 11:26:53
#Base:Fit=	10.08.2022 10:04:30
#Base:Sub=	10.08.2022 10:04:45
#Filter:Polynom=	16.08.2022 10:20:25
#AxisType[0]=Intens
#AxisUnit[0]=Cnt
#AxisType[1]=Spectr
#AxisUnit[1]=1/cm
200.43	-0.62921
204.061	3.75096
207.688	4.38015
211.316	4.13802
214.941	5.71253
218.566	6.59432
222.188	6.52797
225.809	5.4517
229.43	5.92545
233.047	6.08338
236.663	5.60953
240.278	6.21537
243.894	6.51768
247.506	5.89508
251.116	4.98181
254.725	3.78337
258.333	4.98935
261.939	4.08197
265.546	2.98176
269.15	2.83676
272.752	1.67045
276.353	3.82398
279.952	6.12825
283.55	6.42069
287.146	6.90809
290.739	7.47737
294.333	9.17253
297.925	10.8977
301.516	13.9698
305.106	14.9779
308.694	14.315
312.279	14.4203
315.864	13.5094
319.448	14.7487
323.029	14.9614
326.61	14.9297
330.19	15.0728
333.766	14.5951
337.343	14.2354
340.917	12.8099
344.491	11.9262
348.062	10.8553
351.633	10.4546
355.201	8.87302
358.77	8.36882
362.335	7.365
365.899	7.37865
369.464	6.56495
373.025	6.94463
376.585	7.07256
380.143	7.75147
383.702	7.71906
387.258	6.89489
390.812	6.988
394.365	6.19008
397.916	3.55107
401.467	3.31042
405.015	3.48276
408.565	3.46041
412.111	4.40917
415.656	2.78427
419.197	4.21358
422.739	4.34093
426.279	3.1872
429.819	3.87618
433.356	4.98199
436.893	5.61001
440.428	4.24346
443.96	3.37743
447.492	2.58867
451.023	4.01339
454.553	5.88662
458.079	8.94499
461.606	9.73469
465.132	11.2201
468.654	12.5537
472.177	12.8539
475.696	13.7147
479.217	14.8276
482.733	13.6068
486.251	14.3393
489.765	16.6668
493.278	16.9281
496.791	17.7019
500.301	18.9609
503.81	19.3411
507.319	21.0678
510.825	21.3535
514.33	20.9382
517.833	21.1995
521.337	20.7417
524.838	19.8279
528.337	18.6235
531.835	17.3884
535.332	18.76
538.827	19.1096
542.321	17.6732
545.814	15.4852
549.305	14.4409
552.795	12.4222
556.284	12.9379
559.771	10.8085
563.257	8.49061
566.742	6.96517
570.223	5.99729
573.705	6.34711
577.185	5.71234
580.665	4.82387
584.141	4.96158
587.617	5.01961
591.092	4.66982
594.564	4.66482
598.037	3.66049
601.506	3.27465
604.976	4.46286
608.443	5.55393
611.91	6.37741
615.374	6.33509
618.839	6.81029
622.3	6.89116
625.761	6.31518
629.221	6.09159
632.679	8.45165
636.135	9.17552
639.592	9.98732
643.045	9.68516
646.497	10.3068
649.948	10.6407
653.398	11.6883
656.846	13.0395
660.293	11.4468
663.738	13.1474
667.185	13.5654
670.628	13.7763
674.067	15.102
677.508	14.8305
680.947	16.343
684.385	18.6706
687.821	22.8411
691.256	24.1324
694.69	25.827
698.121	27.6521
701.552	29.9764
704.982	31.9143
708.41	34.677
711.836	37.0823
715.262	39.0562
718.685	39.0552
722.108	41.3571
725.53	41.6426
728.949	43.1028
732.369	45.6657
735.785	45.8185
739.2	47.4742
742.616	47.272
746.028	48.0748
749.441	48.2151
752.851	50.6692
756.26	52.6447
759.667	54.3209
763.075	57.1701
766.479	61.0745
769.883	64.3939
773.285	64.0937
776.686	65.5889
780.085	69.576
783.484	71.9155
786.881	73.1034
790.276	75.4211
793.671	76.6183
797.064	77.7717
800.456	79.6485
803.846	80.0411
807.236	81.7775
810.624	83.4567
814.01	84.9449
817.394	85.2579
820.778	85.0569
824.161	83.9829
827.543	81.9627
830.921	80.1516
834.3	78.4777
837.676	76.9134
841.053	73.4562
844.426	69.0743
847.8	67.0743
851.171	64.5551
854.542	61.6259
857.911	59.6536
861.279	55.755
864.645	52.1488
868.01	49.5857
871.375	49.34
874.737	49.3586
878.097	47.7621
881.457	47.8059
884.817	47.7596
888.174	47.937
891.53	48.8534
894.884	48.4672
898.237	49.0716
901.589	48.4247
904.94	46.9479
908.289	46.2914
911.637	44.3016
914.984	43.7109
918.33	40.7008
921.674	39.079
925.015	37.2226
928.357	37.1185
931.698	37.653
935.037	35.3898
938.373	35.2289
941.71	32.8145
945.046	29.9286
948.378	30.7764
951.711	29.4655
955.043	28.9578
958.372	27.7053
961.701	27.1591
965.027	27.3195
968.354	27.8272
971.678	28.7163
975	30.1263
978.324	30.2152
981.644	30.3799
984.962	29.4888
988.282	29.4813
991.598	30.0805
994.913	28.7411
998.227	29.9819
1001.54	31.0978
1004.85	31.6838
1008.16	32.4665
1011.47	33.5668
1014.78	35.1007
1018.08	35.3097
1021.39	35.3442
1024.69	34.7467
1028	35.4029
1031.3	35.1481
1034.6	34.7045
1037.9	34.3563
1041.19	33.2177
1044.49	33.8342
1047.79	33.3135
1051.08	31.9876
1054.37	31.6245
1057.66	28.5966
1060.95	27.2919
1064.24	24.6551
1067.53	23.5397
1070.81	23.1264
1074.1	21.1692
1077.38	22.1583
1080.66	21.7931
1083.94	20.5304
1087.22	20.5987
1090.5	22.6796
1093.78	23.091
1097.05	24.9967
1100.33	26.9359
1103.6	28.3168
1106.87	30.297
1110.15	29.7626
1113.41	29.5867
1116.68	28.1702
1119.95	27.355
1123.21	26.0569
1126.48	24.1839
1129.74	20.5246
1133	19.0503
1136.26	16.9771
1139.52	15.9765
1142.78	13.5477
1146.04	13.0706
1149.29	12.0338
1152.55	10.1881
1155.8	8.11139
1159.05	6.56713
1162.3	5.35817
1165.55	6.21266
1168.8	7.37754
1172.05	9.2441
1175.29	9.63645
1178.54	10.7538
1181.78	12.4169
1185.02	11.3196
1188.26	10.5877
1191.5	11.2635
1194.74	10.4772
1197.97	9.71005
1201.21	10.6356
1204.44	11.5727
1207.68	11.614
1210.91	13.3713
1214.14	16.0154
1217.37	20.2234
1220.6	21.4656
1223.82	24.6689
1227.05	27.7549
1230.27	30.0343
1233.49	33.0677
1236.72	36.8292
1239.94	41.4566
1243.16	45.013
1246.37	49.7561
1249.59	54.7452
1252.8	58.7584
1256.02	61.8587
1259.23	66.2215
1262.44	68.6627
1265.66	70.9813
1268.87	75.7645
1272.07	77.9266
1275.28	80.7509
1278.48	83.0719
1281.69	86.5609
1284.89	89.5802
1288.09	90.3591
1291.3	91.5505
1294.49	89.7669
1297.69	89.3785
1300.89	87.9757
1304.09	88.4504
1307.28	86.8001
1310.47	86.3104
1313.66	85.3886
1316.86	82.6857
1320.05	81.5956
1323.23	80.8737
1326.42	80.3806
1329.61	78.074
1332.79	76.8821
1335.98	74.9849
1339.16	73.8297
1342.34	70.7019
1345.52	67.9417
1348.7	66.2216
1351.87	62.703
1355.05	60.3735
1358.23	58.417
1361.4	58.0445
1364.57	54.4053
1367.74	50.6645
1370.91	49.9435
1374.08	50.3134
1377.25	50.2218
1380.42	52.2353
1383.58	52.6532
1386.75	53.2964
1389.91	51.882
1393.07	52.3045
1396.23	53.5276
1399.39	54.4688
1402.55	54.7934
1405.7	56.4151
1408.86	57.1091
1412.01	58.4044
1415.17	59.1927
1418.32	61.337
1421.47	63.6003
1424.62	67.4186
1427.77	70.9535
1430.92	74.2652
1434.06	79.1176
1437.2	83.8194
1440.35	89.1974
1443.49	92.2176
1446.63	94.865
1449.77	97.4388
1452.91	99.3517
1456.05	98.9499
1459.18	96.2156
1462.32	92.9381
1465.45	87.9866
1468.59	82.5466
1471.72	77.0626
1474.85	71.7633
1477.98	64.9688
1481.11	58.3463
1484.23	51.4716
1487.36	44.7082
1490.48	40.4636
1493.61	35.5198
1496.73	31.6177
1499.85	29.8486
1502.97	28.1436
1506.09	27.1365
1509.2	27.3215
1512.32	28.518
1515.44	28.7902
1518.55	29.9508
1521.66	30.7825
1524.77	33.2681
1527.88	36.3426
1530.99	38.8053
1534.1	41.751
1537.21	47.4063
1540.31	52.087
1543.42	56.5633
1546.52	61.1029
1549.62	66.4428
1552.72	71.5887
1555.82	75.278
1558.92	79.3001
1562.02	83.7845
1565.11	87.7849
1568.21	90.9893
1571.3	94.8992
1574.39	98.6518
1577.49	101.11
1580.58	102.963
1583.67	104.714
1586.75	103.484
1589.84	103.407
1592.93	103.431
1596.01	101.333
1599.09	100.221
1602.18	97.2751
1605.26	94.4667
1608.34	93.1664
1611.41	91.6049
1614.49	90.0333
1617.57	88.2355
1620.64	87.3695
1623.72	87.2325
1626.79	87.1842
1629.86	88.0141
1632.93	88.0747
1636	91.6716
1639.07	93.0493
1642.14	94.5485
1645.2	96.1326
1648.27	97.7376
1651.33	97.3241
1654.39	98.2238
1657.45	97.6917
1660.51	97.6216
1663.57	94.5323
1666.63	92.0117
1669.69	87.7067
1672.74	82.0681
1675.79	77.6492
1678.85	71.7419
1681.9	65.5784
1684.95	60.5633
1688	55.109
1691.05	50.1429
1694.1	44.6359
1697.14	39.9083
1700.19	34.6865
1703.23	32.0734
1706.27	28.5416
1709.32	27.001
1712.35	25.1727
1715.39	21.6655
1718.43	19.9285
1721.47	17.9269
1724.5	15.5227
1727.54	15.1148
1730.57	13.4154
1733.61	11.8995
1736.64	10.359
1739.67	7.38406
1742.7	4.30556
1745.72	4.26142
1748.75	4.72869
1751.78	4.61926
1754.8	5.488
1757.82	6.15771
1760.85	6.86467
1763.87	5.79137
1766.89	6.01852
1769.91	5.52913
1772.92	5.81812
1775.94	6.6722
1778.96	8.80223
1781.97	9.27182
1784.98	9.59531
1788	8.86507
1791.01	8.28074
1794.01	7.98306
1797.02	7.30107
1800.03	5.7779
1803.04	5.37117
1806.04	4.73898
1809.05	3.83559
1812.05	2.93329
1815.05	2.32935
1818.05	2.72533
1821.05	3.06207
1824.05	2.69099
1827.05	3.18996
1830.04	3.00681
1833.04	3.14337
1836.03	3.15638
1839.03	3.3659
1842.02	3.72454
1845.01	4.26528
1848	4.74561
1850.99	5.92142
1853.97	5.65829
1856.96	5.09681
1859.94	4.67023
1862.93	4.50305
1865.91	4.78703
1868.89	4.14005
1871.87	3.62281
1874.85	3.87971
1877.83	5.1367
1880.81	5.1275
1882.56	4.70435
1885.55	4.25405
1888.54	4.30543
1891.52	4.09757
1894.51	4.94543
1897.49	5.37805
1900.48	6.43377
1903.46	6.422
1906.44	6.59474
1909.42	4.91628
1912.4	5.57998
1915.38	6.25107
1918.35	6.06444
1921.33	7.05819
1924.3	5.70234
1927.28	5.41908
1930.25	4.40664
1933.22	4.30825
1936.19	4.7201
1939.16	3.61206
1942.13	3.76998
1945.09	4.05145
1948.06	3.54693
1951.03	2.66615
1953.99	1.63146
1956.95	1.52477
1959.91	0.599073
1962.87	1.48854
1965.83	2.17962
1968.79	2.90774
1971.75	4.09287
1974.7	4.23358
1977.66	3.7907
1980.61	4.00406
1983.56	4.38381
1986.52	4.37585
1989.47	5.55956
1992.41	5.71681
1995.36	5.97071
1998.31	6.1599
2001.26	5.84259
2004.2	6.76324
2007.15	6.49404
2010.09	6.24146
2013.03	6.36186
2015.97	6.70572
2018.91	5.80671
2021.85	5.27772
2024.79	5.26608
2027.72	5.39273
2030.66	5.74338
2033.59	6.10125
2036.53	8.37008
2039.46	9.30883
2042.39	9.80514
2045.32	11.522
2048.25	12.641
2051.18	14.106
2054.1	15.3288
2057.03	15.5725
2059.95	17.8236
2062.88	19.3216
2065.8	20.3073
2068.72	21.7891
2071.64	23.3237
2074.56	25.235
2077.48	26.9013
2080.39	27.5404
2083.31	29.4329
2086.22	32.1869
2089.14	33.0856
2092.05	34.7884
2094.96	36.5106
2097.87	38.2454
2100.78	40.7634
2103.69	42.9132
2106.6	46.303
2109.51	49.6435
2112.41	53.8149
2115.32	58.8177
2118.22	62.9754
2121.12	66.8717
2124.02	70.9606
2126.92	75.0024
2129.82	81.0768
2132.72	86.5262
2135.62	92.0826
2138.51	97.6738
2141.41	103.271
2144.3	107.862
2147.19	111.266
2150.09	115.441
2152.97	118.388
2155.86	120.177
2158.75	120.818
2161.64	123.131
2164.53	123.561
2167.41	123.814
2170.3	124.139
2173.18	122.793
2176.06	121.454
2178.94	119.377
2181.82	117.668
2184.7	114.809
2187.58	110.511
2190.46	106.419
2193.33	103.416
2196.21	99.7659
2199.08	97.6857
2201.95	94.9788
2204.83	91.2042
2207.7	87.3649
2210.57	82.4543
2213.43	78.8713
2216.3	74.0422
2219.17	70.1668
2222.03	66.3609
2224.9	61.5799
2227.76	57.1126
2230.62	54.3716
2233.49	50.4399
2236.34	47.1069
2239.2	43.6188
2242.06	40.0871
2244.92	36.2278
2247.78	34.2336
2250.63	31.9994
2253.48	30.3299
2256.34	28.29
2259.19	26.3744
2262.04	25.7426
2264.89	24.803
2267.74	24.475
2270.59	24.7886
2273.43	23.8007
2276.28	22.3036
2279.12	21.3508
2281.97	21.3902
2284.81	21.0717
2287.65	20.676
2290.49	19.5627
2293.33	17.5318
2296.17	17.1121
2299.01	16.753
2301.84	17.6657
2304.68	17.5056
2307.51	17.1637
2310.35	16.8279
2313.18	17.2707
2316.01	16.8518
2318.84	16.4041
2321.67	15.5546
2324.5	14.8245
2327.33	13.8633
2330.15	12.6296
2332.98	12.4135
2335.8	11.5701
2338.62	10.7293
2341.45	9.67291
2344.27	7.45722
2347.09	6.75754
2349.91	6.34809
2352.72	5.21336
2355.54	2.47506
2358.36	1.49234
2361.17	1.56813
2363.98	3.80537
2366.8	4.53209
2369.61	3.58609
2372.42	3.35068
2375.23	2.71714
2378.04	3.25844
2380.85	3.54334
2383.66	3.72146
2386.46	3.0232
2389.26	3.25071
2392.07	3.06901
2394.87	2.70291
2397.67	2.0282
2400.47	3.11529
2403.27	2.72837
2406.07	3.6463
2408.87	3.9948
2411.67	4.06127
2414.46	5.7002
2417.26	6.70664
2420.05	6.8779
2422.84	7.29514
2425.64	8.70671
2428.43	9.14647
2431.22	10.3642
2434.01	9.0083
2436.79	8.04687
2439.58	7.77461
2442.37	7.82685
2445.15	7.62598
2447.93	7.14524
2450.72	7.39741
2453.5	7.02366
2456.28	6.11217
2459.06	5.79668
2461.84	5.37046
2464.62	4.91098
2467.39	4.89123
2470.17	4.51209
2472.94	4.3708
2475.72	4.43625
2478.49	5.01835
2481.26	4.70991
2484.03	4.37527
2486.8	3.83874
2489.57	3.85373
2492.34	3.54948
2495.1	1.87058
2497.87	0.762236
2500.63	1.50049
2503.4	0.368972
2506.16	-0.196958
2508.92	0.0749826
2511.68	-0.845942
2514.44	-0.123401
2517.2	0.553449
2519.96	0.650343
2522.72	0.661239
2525.47	0.18585
2528.23	1.55144
2530.98	2.01975
2533.74	1.94101
2536.49	2.08926
2539.24	3.44015
2541.99	3.97167
2544.74	5.23574
2547.49	5.14954
2550.23	6.09271
2552.98	6.36481
2555.72	7.05161
2558.47	6.9163
2561.21	5.91587
2563.95	5.90541
2566.69	6.10629
2569.43	6.2459
2572.17	5.14378
2574.91	5.12947
2577.65	5.03006
2580.39	5.67578
2583.12	5.30168
2585.85	4.97521
2588.59	4.59294
2591.32	4.27099
2594.05	3.6602
2596.78	3.53678
2599.51	2.90065
2602.24	2.39798
2604.97	2.51062
2607.69	2.2877
2610.42	2.28561
2613.14	2.18162
2615.87	3.33077
2618.59	3.68204
2621.31	3.06785
2624.03	2.63069
2626.75	2.57143
2629.47	2.52434
2632.19	2.08924
2634.91	2.65547
2637.62	2.55546
2640.34	3.44345
2643.05	5.24492
2645.76	5.88632
2648.48	5.99325
2651.19	5.66041
2653.9	5.63296
2656.6	5.76233
2659.31	5.74293
2662.02	5.1957
2664.73	5.70823
2667.43	6.59983
2670.14	6.46766
2672.84	7.14415
2675.54	7.51846
2678.24	7.70086
2680.94	7.54882
2683.64	7.72034
2686.34	7.18174
2689.04	6.62079
2691.74	7.15331
2694.43	6.95267
2697.13	6.98986
2699.82	7.70845
2702.51	8.26366
2705.21	9.06682
2707.9	9.89458
2710.58	10.6266
2713.27	10.3836
2715.96	11.128
2718.65	12.1416
2721.33	11.9778
2724.02	13.227
2726.71	13.7231
2729.39	14.4802
2732.07	14.3769
2734.75	14.4621
2737.43	13.3445
2740.11	13.25
2742.79	11.7997
2745.47	11.5312
2748.14	10.2968
2750.82	9.85106
2753.49	8.46737
2756.17	8.45875
2758.84	7.20869
2761.51	6.78234
2764.18	6.08985
2766.85	5.55757
2769.52	5.99162
2772.19	5.51285
2774.86	5.64172
2777.52	5.59445
2780.19	4.73901
2782.85	4.77701
2785.52	4.13175
2788.18	3.64319
2790.84	2.76901
2793.5	2.23987
2796.16	2.19286
2798.82	1.49328
2801.48	0.622798
2804.13	0.488469
2806.79	-0.534177
2809.45	-0.859379
2812.1	-2.60234
2814.75	-2.81366
2817.41	-0.921336
2820.06	1.71575
2822.71	6.23328
2825.36	12.6479
2828	19.8256
2830.65	27.9252
2833.3	35.1171
2835.94	43.0394
2838.59	50.5503
2841.23	58.5951
2843.87	67.2506
2846.52	76.6873
2849.16	86.1941
2851.8	97.1946
2854.44	107.936
2857.08	118.714
2859.71	129.997
2862.35	138.903
2864.98	147.19
2867.62	153.504
2870.25	158.355
2872.88	163.857
2875.52	168.153
2878.15	172.876
2880.78	177.173
2883.41	181.992
2886.03	187.21
2888.66	192.751
2891.29	197.58
2893.91	202.225
2896.54	206.705
2899.16	211.326
2901.78	217.554
2904.4	224.752
2907.02	233.988
2909.64	245.244
2912.26	255.856
2914.88	268.213
2917.5	279.696
2920.11	290.168
2922.73	297.946
2925.34	304.135
2927.96	307.105
2930.57	309.197
2933.18	307.95
2935.79	306.595
2938.4	302.691
2941.01	295.771
2943.62	287.402
2946.22	278.024
2948.83	267.651
2951.43	257.12
2954.04	245.109
2956.64	232.808
2959.24	220.211
2961.84	208.732
2964.45	196.562
2967.05	184.998
2969.64	174.415
2972.24	164.205
2974.84	153.669
2977.43	143.612
2980.03	133.018
2982.62	121.258
2985.22	110.796
2987.81	99.5081
2990.4	90.1092
2992.99	79.9961
2995.58	70.6928
2998.17	61.1451
3000.76	53.1464
3003.34	45.9824
3005.93	40.0677
3008.52	34.2392
3011.1	28.9163
3013.68	24.508
3016.27	20.4536
3018.85	17.145
3021.43	14.9066
3024.01	12.3133
3026.59	11.0071
3029.16	8.72874
3031.74	8.40714
3034.32	8.44547
3036.89	8.31314
3039.47	9.06563
3042.04	9.726
3044.61	10.0804
3047.18	10.3262
3049.75	10.981
3052.32	12.8113
3054.89	13.5273
3057.46	12.861
3060.03	12.7268
3062.59	12.2112
3065.16	12.5332
3067.72	11.7631
3070.29	10.8604
3072.85	9.29845
3075.41	7.81439
3077.97	6.32557
3080.53	5.55243
3083.09	4.4819
3085.65	3.30658
3088.21	1.84903
3090.76	0.808029
3093.32	-0.162224
3095.87	-0.202518
3098.43	0.293845
3100.98	1.51107
3103.53	2.17046
3106.08	2.10344
3108.63	3.11674
3111.18	4.47878
3113.73	6.64864
3116.28	7.19467
3118.83	8.9706
3121.37	9.32602
3123.92	11.6334
3126.46	13.4682
3129	15.8783
3131.55	17.6365
3134.09	19.5911
3136.63	21.1611
3139.17	23.6782
3141.71	25.7888
3144.24	27.5842
3146.78	29.8994
3149.32	34.1493