File: data/Raman/poly_smoothed/Thy_20_09_43_1x_45s_532 nm_x100_100%_600 gr_mm_01.txt
#Acq. time (s)=	45
#Accumulations=	2
#Range (cm-¹)=	200...3150
#Windows=	2
#Auto scanning=	Off
#Autofocus=	Off
#Macrospot=	Off
#AutoExposure=	Off
#Spike filter=	Multiple accum.
#Delay time (s)=	0
#Binning=	1
#Readout mode=	Signal
#DeNoise=	Off
#ICS correction=	On
#Dark correction=	Off
#Inst. Process=	Off
#Detector Gain=	Best Dynamic Range
#Detector ADC=	20 kHz
#Detector temperature (°C)=	-69.85
#Instrument=	LabRAM HR Evol
#Detector=	Synapse
#Objective=	x100
#Grating=	600 gr/mm
#ND Filter=	100%
#Laser (nm)=	532
#Hole=	100.021
#Range=	Auto
#Laser Pol.=	No
#Raman. Pol.=	No
#Laser Pol. (°)=	-0.0007625
#Raman Pol. (°)=	89.9995
#Collection=	Microscope
#StageXY=	Marzhauser
#StageZ=	Marzhauser
#X (µm)=	-5923.1
#Y (µm)=	2855
#Z (µm)=	-223.8
#Full time(mm:ss)=	3:18
#Project=
#Sample=
#Site=
#Title=	Thy_20_09_43_2x_45s_532 nm_x100_100%_600 gr_mm
#Remark=
#Date=	29.06.2022 13:41
#Acquired=	29.06.2022 13:41:30
#Base:Fit=	10.08.2022 09:52:02
#Base:Fit=	10.08.2022 09:52:12
#Base:Sub=	10.08.2022 09:54:21
#Filter:Polynom=	16.08.2022 10:24:04
#AxisType[0]=Intens
#AxisUnit[0]=Cnt
#AxisType[1]=Spectr
#AxisUnit[1]=1/cm
200.523	3.05692
204.154	5.8681
207.781	6.19513
211.409	6.1789
215.034	6.83392
218.659	8.0464
222.281	8.65752
225.903	9.82304
229.522	11.5332
233.14	13.184
236.756	13.6286
240.373	14.89
243.986	16.6156
247.598	16.8431
251.208	18.9678
254.818	17.9348
258.427	18.3109
262.034	19.3346
265.638	21.1295
269.242	23.6105
272.844	23.6711
276.445	23.9589
280.044	24.3863
283.642	24.8435
287.238	24.8399
290.833	24.0704
294.425	22.9098
298.017	24.5274
301.608	24.8928
305.198	24.7771
308.786	25.1627
312.371	24.115
315.956	23.5809
319.54	24.2106
323.122	21.984
326.701	19.6016
330.281	17.9491
333.857	16.1795
337.434	13.7402
341.008	10.9291
344.582	8.69041
348.153	8.85729
351.724	9.08327
355.292	9.32572
358.861	8.85012
362.426	8.75488
365.99	8.91031
369.555	9.32517
373.116	9.56041
376.676	10.0035
380.236	10.123
383.793	12.4804
387.349	15.6675
390.903	15.2106
394.456	16.6116
398.007	16.7432
401.56	16.618
405.108	16.0534
408.656	14.1828
412.202	12.1976
415.746	11.8742
419.29	10.9633
422.831	9.35374
426.37	7.94391
429.909	8.08443
433.447	7.19679
436.983	5.83216
440.519	5.18724
444.052	5.28829
447.583	6.97807
451.114	5.9289
454.643	5.94726
458.169	6.63526
461.696	7.49901
465.222	9.32088
468.744	9.86199
472.267	11.6473
475.787	12.114
479.307	11.1834
482.823	10.484
486.341	11.0812
489.855	10.2971
493.37	12.0613
496.881	11.1339
500.391	11.8529
503.902	11.1676
507.409	12.7535
510.915	13.041
514.42	13.2467
517.925	12.8446
521.427	11.9228
524.928	13.8237
528.427	12.7127
531.925	11.7544
535.422	11.6145
538.917	10.5301
542.411	9.9187
545.903	11.3783
549.395	11.9093
552.884	8.66315
556.373	8.74993
559.86	9.51618
563.346	8.28297
566.831	8.15797
570.314	8.42613
573.794	8.69946
577.274	8.58084
580.754	7.46902
584.23	6.94159
587.706	8.75991
591.181	9.5049
594.653	10.3793
598.126	9.95147
601.595	9.69707
605.065	10.3434
608.532	10.1178
611.999	9.87546
615.463	9.84429
618.928	12.1875
622.389	12.2421
625.851	12.6903
629.31	14.028
632.767	14.7606
636.223	14.9305
639.68	16.8589
643.134	20.4231
646.586	20.8553
650.037	21.943
653.486	22.3285
656.936	23.2838
660.383	22.0804
663.829	22.0919
667.273	22.5909
670.716	24.104
674.158	24.5438
677.598	26.1194
681.035	27.5592
684.473	28.6677
687.909	31.2432
691.344	33.4398
694.778	34.7868
698.211	36.478
701.64	37.6844
705.07	38.6581
708.498	40.634
711.924	41.0336
715.35	43.1857
718.774	44.6169
722.196	45.9079
725.618	47.5032
729.037	47.7594
732.456	49.3015
735.873	49.7669
739.289	50.6853
742.703	52.6524
746.116	54.6761
749.529	57.0747
752.938	60.8358
756.347	64.0888
759.756	69.1961
763.162	72.9035
766.567	79.0828
769.97	82.6976
773.372	85.7612
776.773	88.4911
780.174	91.2035
783.573	95.5187
786.97	98.9607
790.365	102.687
793.76	104.53
797.153	106.548
800.543	110.181
803.933	111.682
807.322	114.693
810.71	114.167
814.097	114.734
817.483	114.539
820.865	114.693
824.248	113.628
827.629	112.641
831.008	110.953
834.387	111.502
837.765	110.402
841.139	108.806
844.514	107.873
847.886	105.886
851.259	104.355
854.629	101.609
857.997	98.8709
861.366	97.5484
864.732	97.4082
868.098	96.4716
871.461	94.8854
874.823	92.6599
878.184	91.0602
881.545	90.0665
884.903	90.1113
888.26	88.36
891.616	87.3235
894.97	83.4069
898.323	82.2019
901.675	79.8634
905.026	77.6505
908.375	73.9975
911.723	72.1193
915.07	72.3545
918.415	71.3806
921.76	69.7853
925.103	67.907
928.443	66.0925
931.783	64.1967
935.123	64.1969
938.461	61.8176
941.796	60.387
945.131	58.0413
948.465	56.4966
951.797	52.8361
955.128	49.4925
958.457	46.0819
961.786	42.9245
965.113	40.9191
968.44	40.3932
971.763	39.1575
975.086	35.3374
978.409	32.4656
981.729	30.7246
985.048	29.3109
988.367	27.4591
991.683	26.2933
994.998	24.7138
998.312	24.3564
1001.62	23.0194
1004.94	22.6293
1008.25	21.5211
1011.56	21.5567
1014.86	20.6591
1018.17	19.4891
1021.48	17.6703
1024.78	16.14
1028.08	16.4114
1031.38	14.8563
1034.68	13.0626
1037.98	11.4657
1041.28	9.85019
1044.57	9.38308
1047.87	11.4049
1051.16	11.9595
1054.45	11.3452
1057.75	9.50147
1061.04	8.41035
1064.32	10.1057
1067.61	10.1001
1070.9	9.83181
1074.18	8.69456
1077.47	8.86285
1080.75	7.06371
1084.03	7.95496
1087.31	7.4613
1090.59	7.54122
1093.86	6.60582
1097.14	6.90572
1100.41	6.86418
1103.69	7.33252
1106.96	7.41024
1110.23	8.0492
1113.5	6.49711
1116.77	4.98191
1120.03	5.7726
1123.3	6.05651
1126.56	7.31907
1129.83	6.70131
1133.09	8.00824
1136.35	5.86338
1139.61	4.33724
1142.86	4.30756
1146.12	4.81056
1149.38	3.55522
1152.63	3.01933
1155.88	1.86152
1159.14	2.92384
1162.39	4.5507
1165.63	6.44999
1168.88	6.58155
1172.13	6.85217
1175.38	9.45853
1178.62	10.5477
1181.86	11.4666
1185.1	13.6705
1188.34	14.9267
1191.58	15.1251
1194.82	16.5401
1198.06	17.1477
1201.29	20.0799
1204.53	21.9975
1207.76	22.206
1210.99	24.2488
1214.22	25.3206
1217.45	26.0074
1220.68	27.9761
1223.91	30.0713
1227.13	32.35
1230.36	36.3339
1233.58	39.9892
1236.8	44.0202
1240.02	47.1948
1243.24	49.8681
1246.46	52.0682
1249.67	50.9998
1252.89	52.2716
1256.1	55.5157
1259.32	56.0863
1262.53	58.4028
1265.74	60.4661
1268.95	60.9287
1272.15	63.0442
1275.36	65.8948
1278.57	66.5164
1281.77	69.3667
1284.97	71.1418
1288.18	73.424
1291.38	75.0745
1294.58	77.3836
1297.78	81.226
1300.97	83.706
1304.17	86.9436
1307.36	90.7743
1310.55	95.627
1313.75	99.9432
1316.94	101.431
1320.13	102.913
1323.32	103.017
1326.5	101.745
1329.69	101.912
1332.87	103.043
1336.06	102.364
1339.24	100.085
1342.42	97.2091
1345.6	95.9434
1348.78	94.3315
1351.96	92.218
1355.13	89.0805
1358.31	86.4077
1361.48	84.376
1364.65	82.747
1367.82	79.7247
1370.99	75.6507
1374.16	74.0704
1377.33	73.1607
1380.5	69.3877
1383.66	68.1335
1386.83	67.5804
1389.99	66.4654
1393.15	64.4923
1396.31	62.9223
1399.47	61.7337
1402.63	61.2043
1405.78	59.9138
1408.94	59.049
1412.1	58.7425
1415.25	58.7618
1418.4	58.3944
1421.55	60.474
1424.7	64.44
1427.85	66.7066
1431	69.3372
1434.14	74.5201
1437.29	77.6719
1440.43	80.2766
1443.57	82.0661
1446.71	79.4539
1449.85	79.3617
1452.99	77.8886
1456.13	75.9488
1459.26	72.7589
1462.4	70.1578
1465.54	67.5719
1468.67	63.5548
1471.8	60.1819
1474.93	53.6212
1478.06	48.5048
1481.19	44.032
1484.31	37.4941
1487.44	34.7678
1490.56	31.088
1493.69	28.9457
1496.81	27.1398
1499.93	25.7894
1503.05	28.2098
1506.17	29.0405
1509.28	29.8434
1512.4	30.4156
1515.52	29.9552
1518.63	31.4614
1521.74	31.4132
1524.85	33.9437
1527.96	37.2025
1531.07	41.4089
1534.18	44.678
1537.29	48.561
1540.39	53.1504
1543.5	58.2599
1546.6	60.1983
1549.7	63.8101
1552.8	67.566
1555.9	73.6984
1559	79.3398
1562.1	84.5523
1565.19	89.9002
1568.29	94.867
1571.38	99.4902
1574.47	101.191
1577.56	105.224
1580.66	109.853
1583.74	110.878
1586.83	113.717
1589.92	113.293
1593.01	114.443
1596.09	114.744
1599.17	113.935
1602.25	112.416
1605.34	109.85
1608.41	106.931
1611.49	103.312
1614.57	99.6342
1617.65	94.6599
1620.72	90.0826
1623.79	87.2381
1626.87	83.1204
1629.94	80.3216
1633.01	78.4349
1636.08	73.5275
1639.15	68.5872
1642.21	66.4205
1645.28	63.0747
1648.34	60.3197
1651.41	59.3401
1654.47	57.7826
1657.53	55.7297
1660.59	54.1475
1663.65	52.9078
1666.71	51.1068
1669.76	47.931
1672.82	44.7491
1675.87	41.0435
1678.93	38.9395
1681.98	36.5495
1685.03	34.6541
1688.08	28.6613
1691.13	25.7678
1694.17	23.0901
1697.22	21.6007
1700.27	19.5889
1703.31	16.7263
1706.35	13.8687
1709.39	12.3954
1712.43	10.2548
1715.47	8.55368
1718.51	8.70391
1721.55	8.44947
1724.58	8.47675
1727.62	7.47698
1730.65	8.58432
1733.68	8.51905
1736.72	9.07884
1739.74	9.17269
1742.77	7.37813
1745.8	5.66957
1748.83	4.77232
1751.85	4.19644
1754.88	3.9628
1757.9	2.77885
1760.92	1.55331
1763.95	1.58144
1766.96	0.836931
1769.98	1.84661
1773	2.0286
1776.02	1.44711
1779.03	0.809858
1782.05	1.13947
1785.06	1.8977
1788.07	1.93489
1791.08	2.94098
1794.09	4.39069
1797.1	4.94653
1800.11	6.27336
1803.12	6.54418
1806.12	6.18216
1809.12	6.65159
1812.13	6.77085
1815.13	6.5821
1818.13	5.30514
1821.13	5.4759
1824.13	6.10756
1827.13	5.38022
1830.12	6.17876
1833.12	5.16585
1836.11	5.61914
1839.1	3.84747
1842.09	4.42768
1845.09	5.48
1848.08	5.69613
1851.06	7.17041
1854.05	6.34459
1857.04	7.23342
1860.02	8.16562
1863.01	8.14236
1865.99	9.55993
1868.97	10.91
1871.95	10.8513
1874.93	11.3411
1877.91	11.1723
1880.89	11.0203
1882.46	12.6251
1885.45	11.9163
1888.43	11.5147
1891.42	11.9989
1894.41	11.7927
1897.39	12.3225
1900.37	10.7392
1903.36	11.2198
1906.34	11.3512
1909.32	11.3083
1912.29	11.2432
1915.27	12.0257
1918.25	12.1502
1921.23	10.9557
1924.2	11.6454
1927.17	11.4058
1930.15	11.3068
1933.12	10.4853
1936.09	10.6652
1939.06	11.144
1942.02	10.9579
1944.99	10.2384
1947.96	10.3073
1950.92	10.7623
1953.88	8.54592
1956.85	7.82798
1959.81	6.53992
1962.77	5.14274
1965.73	5.38372
1968.69	5.40678
1971.64	3.07364
1974.6	3.00189
1977.55	3.99597
1980.51	3.49555
1983.46	3.48951
1986.41	3.91543
1989.36	3.94438
1992.31	3.18761
1995.26	4.70531
1998.21	5.7247
2001.15	5.38795
2004.1	4.39689
2007.04	5.65755
2009.99	6.22854
2012.93	6.5762
2015.87	6.74038
2018.81	6.03314
2021.75	5.41783
2024.68	4.31104
2027.62	3.95349
2030.56	3.81954
2033.49	4.23033
2036.42	3.67804
2039.36	3.67058
2042.29	2.24176
2045.22	2.13628
2048.14	1.81887
2051.07	2.01485
2054	1.64103
2056.93	2.20974
2059.85	2.92601
2062.77	3.9664
2065.7	5.41579
2068.62	7.17721
2071.54	6.98786
2074.46	7.49436
2077.38	10.5113
2080.29	12.281
2083.21	14.1921
2086.12	14.7597
2089.04	15.9107
2091.95	15.5593
2094.86	16.1026
2097.77	17.3589
2100.68	16.661
2103.59	16.3945
2106.5	16.6278
2109.41	15.4008
2112.31	16.6612
2115.21	17.902
2118.12	17.7805
2121.02	18.2176
2123.92	18.8453
2126.82	18.6877
2129.72	18.8505
2132.62	19.7831
2135.51	21.4165
2138.41	22.6338
2141.31	22.7056
2144.2	25.2511
2147.09	27.2016
2149.98	31.1027
2152.87	33.0006
2155.76	33.8645
2158.65	35.0152
2161.54	34.8246
2164.43	34.0875
2167.31	35.5301
2170.2	36.2007
2173.08	36.5778
2175.96	36.6628
2178.84	37.0808
2181.72	38.6488
2184.6	38.7259
2187.48	38.2785
2190.36	36.3072
2193.23	35.7341
2196.11	34.0247
2198.98	32.5433
2201.85	32.4836
2204.72	33.1603
2207.59	32.5244
2210.46	31.2766
2213.33	30.172
2216.2	32.0761
2219.07	32.7446
2221.93	33.8104
2224.8	32.2379
2227.66	30.4195
2230.52	29.3997
2233.39	28.3199
2236.25	27.2812
2239.1	28.0695
2241.96	25.6179
2244.82	24.9677
2247.68	23.1275
2250.53	22.7468
2253.38	22.0037
2256.24	19.7731
2259.09	19.1144
2261.94	17.6133
2264.79	17.9927
2267.64	17.5714
2270.49	17.1701
2273.33	15.8316
2276.18	16.3693
2279.02	14.3977
2281.87	14.661
2284.71	15.2854
2287.55	15.7119
2290.39	15.1906
2293.23	13.2037
2296.07	13.2489
2298.91	14.8358
2301.74	15.9578
2304.58	17.6023
2307.41	19.9271
2310.25	20.6151
2313.08	19.7553
2315.91	21.912
2318.74	21.1678
2321.57	21.5103
2324.4	21.6235
2327.23	21.8172
2330.05	20.7876
2332.88	20.0757
2335.7	18.7724
2338.52	15.907
2341.35	14.5727
2344.17	13.0225
2346.99	10.6755
2349.81	9.45293
2352.62	7.09435
2355.44	5.57621
2358.26	4.30593
2361.07	2.95802
2363.89	3.50714
2366.7	5.69276
2369.51	6.02943
2372.32	5.232
2375.13	5.35552
2377.94	4.38663
2380.75	3.26702
2383.56	3.57849
2386.36	4.44039
2389.17	5.03437
2391.97	6.08451
2394.77	5.44809
2397.58	6.59461
2400.38	6.36863
2403.18	7.69816
2405.97	7.56485
2408.77	9.8107
2411.57	10.0405
2414.37	9.4817
2417.16	11.0205
2419.95	12.5144
2422.75	12.3825
2425.54	12.7203
2428.33	14.6618
2431.12	13.9155
2433.91	13.6199
2436.7	12.0572
2439.48	9.94637
2442.27	9.06751
2445.05	8.71549
2447.84	8.63203
2450.62	9.3435
2453.4	8.86133
2456.18	7.08943
2458.96	6.08241
2461.74	5.15468
2464.52	4.97396
2467.29	6.44567
2470.07	5.5659
2472.85	5.65914
2475.62	5.90248
2478.39	5.91623
2481.16	5.51434
2483.93	6.58086
2486.7	6.68246
2489.47	7.01984
2492.24	6.02438
2495.01	5.39709
2497.77	4.81655
2500.54	2.91822
2503.3	2.16718
2506.06	2.22181
2508.83	3.3529
2511.59	4.43405
2514.35	5.41127
2517.11	5.74706
2519.86	4.59989
2522.62	3.2956
2525.38	2.56587
2528.13	2.4428
2530.89	2.51437
2533.64	3.4947
2536.39	2.93857
2539.14	3.303
2541.89	4.68677
2544.64	4.49972
2547.39	4.02953
2550.14	4.73804
2552.88	4.03462
2555.63	4.16929
2558.37	2.75464
2561.11	2.15256
2563.86	2.44115
2566.6	2.49178
2569.34	2.67797
2572.08	4.63739
2574.82	4.78602
2577.55	5.88132
2580.29	6.53895
2583.02	5.5945
2585.76	5.62817
2588.49	6.22104
2591.22	5.47297
2593.96	4.58493
2596.69	4.81367
2599.42	4.87447
2602.14	4.01539
2604.87	4.25199
2607.6	5.48081
2610.32	5.30532
2613.05	5.28997
2615.77	4.48523
2618.49	4.43599
2621.22	3.06651
2623.94	1.10048
2626.66	1.08951
2629.37	1.80373
2632.09	2.56433
2634.81	3.05275
2637.53	3.53129
2640.24	4.36111
2642.96	4.41366
2645.67	5.01165
2648.38	5.36199
2651.09	5.35077
2653.8	5.53252
2656.51	5.37359
2659.22	4.69989
2661.93	5.03592
2664.63	5.51646
2667.34	5.86703
2670.04	6.64887
2672.75	7.28423
2675.45	7.11699
2678.15	7.34199
2680.85	6.66626
2683.55	5.16129
2686.25	3.6102
2688.94	2.33502
2691.64	3.42779
2694.34	4.67759
2697.03	4.45249
2699.73	4.01309
2702.42	3.17904
2705.11	2.04347
2707.8	2.6797
2710.49	2.1893
2713.18	2.54492
2715.87	3.22345
2718.55	4.64897
2721.24	4.36364
2723.93	4.23159
2726.61	6.42248
2729.29	7.09302
2731.98	7.36571
2734.66	7.87244
2737.34	8.93036
2740.02	8.05827
2742.7	8.14709
2745.37	8.84116
2748.05	8.35309
2750.72	7.40886
2753.4	7.67628
2756.07	7.21656
2758.75	7.49691
2761.42	5.82833
2764.09	3.79243
2766.76	3.32803
2769.43	2.66842
2772.1	1.57494
2774.76	1.83922
2777.43	1.5503
2780.1	2.49444
2782.76	1.87051
2785.42	1.09328
2788.09	0.0970198
2790.75	0.40173
2793.41	0.361056
2796.07	0.190905
2798.73	0.00806625
2801.39	-0.0766546
2804.04	0.0204397
2806.7	-0.762145
2809.35	-0.844346
2812.01	-1.09282
2814.66	-1.50486
2817.31	-2.13628
2819.96	-1.1342
2822.61	0.231783
2825.26	3.69282
2827.91	7.12919
2830.56	11.6695
2833.21	15.7483
2835.85	21.2029
2838.5	26.1809
2841.14	31.7675
2843.78	38.4492
2846.42	45.0117
2849.06	52.5822
2851.71	60.4116
2854.34	66.2094
2856.98	73.5231
2859.62	80.1871
2862.26	85.4474
2864.89	90.047
2867.53	94.3367
2870.16	98.3271
2872.79	100.904
2875.42	104.399
2878.05	106.683
2880.68	109.047
2883.31	112.088
2885.94	115.325
2888.57	118.256
2891.19	122.883
2893.82	126.931
2896.44	130.087
2899.07	134.591
2901.69	140.021
2904.31	146.488
2906.93	154.172
2909.55	162.955
2912.17	170.951
2914.79	177.974
2917.41	183.514
2920.02	189.411
2922.64	192.995
2925.25	194.986
2927.86	196.435
2930.48	195.549
2933.09	192.368
2935.7	189.946
2938.31	186.523
2940.92	181.294
2943.53	174.851
2946.13	167.762
2948.74	161.478
2951.34	153.922
2953.95	146.656
2956.55	140.672
2959.15	133.435
2961.75	125.804
2964.35	119.247
2966.95	114.505
2969.55	108.675
2972.15	103.83
2974.75	98.4456
2977.34	92.6908
2979.94	86.6293
2982.53	80.1296
2985.13	73.1968
2987.72	65.8904
2990.31	59.7965
2992.9	52.8617
2995.49	45.9492
2998.08	40.274
3000.67	35.3687
3003.25	30.1642
3005.84	25.2987
3008.42	21.4728
3011.01	18.2995
3013.59	16.3242
3016.17	12.8947
3018.76	11.2149
3021.34	9.57175
3023.92	8.56627
3026.49	7.00686
3029.07	7.66374
3031.65	6.95451
3034.23	7.87082
3036.8	10.2308
3039.38	11.1326
3041.95	10.606
3044.52	10.8433
3047.09	11.2855
3049.66	11.1594
3052.23	12.1031
3054.8	12.3407
3057.37	11.1455
3059.94	10.3581
3062.5	9.19531
3065.07	8.57792
3067.63	7.78883
3070.2	5.99272
3072.76	4.38622
3075.32	3.05409
3077.88	1.30421
3080.44	0.448965
3083	1.20187
3085.56	0.280672
3088.12	-0.293286
3090.67	1.0116
3093.23	1.0049
3095.78	1.44536
3098.34	2.20094
3100.89	2.02881
3103.44	2.51765
3105.99	2.54228
3108.54	3.41117
3111.09	4.50525
3113.64	5.00317
3116.19	4.51625
3118.74	4.56567
3121.28	5.13386
3123.83	5.12491
3126.37	5.24199
3128.91	5.85221
3131.46	5.23348
3134	6.22112
3136.54	6.20835
3139.08	7.57541
3141.62	9.51513
3144.16	11.7547
3146.69	13.7404
3149.23	18.2814