File: data/Raman/poly_smoothed/Thy_10_08_50_1x_45s_532 nm_x100_100%_600 gr_mm_01.txt
#Acq. time (s)=	45
#Accumulations=	2
#Range (cm-¹)=	200...3150
#Windows=	2
#Auto scanning=	Off
#Autofocus=	Off
#Macrospot=	Off
#AutoExposure=	Off
#Spike filter=	Multiple accum.
#Delay time (s)=	0
#Binning=	1
#Readout mode=	Signal
#DeNoise=	Off
#ICS correction=	On
#Dark correction=	Off
#Inst. Process=	Off
#Detector Gain=	Best Dynamic Range
#Detector ADC=	20 kHz
#Detector temperature (°C)=	-69.85
#Instrument=	LabRAM HR Evol
#Detector=	Synapse
#Objective=	x100
#Grating=	600 gr/mm
#ND Filter=	100%
#Laser (nm)=	532
#Hole=	100.021
#Range=	Auto
#Laser Pol.=	No
#Raman. Pol.=	No
#Laser Pol. (°)=	-0.0007625
#Raman Pol. (°)=	89.9995
#Collection=	Microscope
#StageXY=	Marzhauser
#StageZ=	Marzhauser
#X (µm)=	-2358.7
#Y (µm)=	263.2
#Z (µm)=	521.55
#Full time(mm:ss)=	3:19
#Project=
#Sample=
#Site=
#Title=	Thy_10_08_50_2x_45s_532 nm_x100_100%_600 gr_mm
#Remark=
#Date=	06.07.2022 15:27
#Acquired=	06.07.2022 15:27:07
#Base:Fit=	10.08.2022 09:46:25
#Base:Sub=	10.08.2022 09:46:49
#Filter:Polynom=	16.08.2022 10:24:56
#AxisType[0]=Intens
#AxisUnit[0]=Cnt
#AxisType[1]=Spectr
#AxisUnit[1]=1/cm
200.398	2.63065
204.027	9.36916
207.657	12.6973
211.283	14.4181
214.909	13.7204
218.533	14.2545
222.157	13.8461
225.777	14.095
229.396	14.8745
233.016	15.9807
236.632	14.9302
240.247	14.2144
243.86	15.1648
247.474	15.3312
251.085	14.6587
254.694	13.7154
258.301	13.9022
261.908	14.4883
265.513	14.5316
269.116	13.5295
272.718	12.5524
276.319	12.522
279.918	13.5569
283.516	14.2809
287.113	14.3781
290.708	14.4794
294.302	14.6609
297.894	14.1251
301.485	14.3916
305.073	14.9296
308.661	15.8459
312.247	16.6999
315.833	18.7058
319.415	19.1455
322.997	18.4434
326.579	18.5647
330.156	18.4919
333.735	20.3659
337.31	19.6815
340.885	18.9799
344.458	17.6699
348.03	16.8589
351.6	16.0071
355.17	15.1724
358.737	13.3662
362.304	13.8142
365.868	14.5256
369.431	12.2606
372.994	11.4551
376.554	11.3256
380.112	12.0564
383.669	10.9582
387.225	10.6704
390.781	10.4169
394.334	10.7745
397.885	9.88659
401.436	10.4219
404.984	8.87429
408.532	7.97518
412.078	7.80824
415.623	7.54948
419.166	5.93801
422.708	5.53899
426.248	4.31301
429.788	2.71134
433.326	1.30241
436.86	1.77851
440.395	2.0049
443.929	1.50142
447.461	1.52566
450.99	3.11714
454.52	2.72702
458.048	3.64877
461.573	4.30525
465.099	7.27705
468.623	8.00981
472.144	8.02531
475.666	9.53577
479.184	9.55795
482.703	10.5294
486.218	12.6887
489.734	13.5979
493.247	14.609
496.759	16.9943
500.271	17.9847
503.779	18.4314
507.287	19.8403
510.795	19.274
514.299	20.5156
517.803	20.4775
521.305	20.8513
524.805	21.5471
528.307	21.4995
531.805	19.0247
535.301	18.7533
538.797	18.5852
542.291	16.2229
545.783	14.4916
549.275	13.1854
552.765	11.5713
556.253	7.78429
559.738	7.13627
563.224	5.20335
566.709	3.98005
570.192	2.9557
573.674	1.25273
577.153	-0.439439
580.632	0.607711
584.11	0.19882
587.587	0.324032
591.06	1.00499
594.534	1.69447
598.005	1.25984
601.476	3.40719
604.944	3.69276
608.413	5.14743
611.878	7.45782
615.344	8.50378
618.807	10.3833
622.27	13.9254
625.73	15.219
629.189	17.8938
632.648	20.0308
636.105	19.3085
639.559	21.7459
643.013	22.2709
646.467	24.971
649.918	26.2588
653.368	25.695
656.816	26.4891
660.263	27.4342
663.708	28.0422
667.153	30.9482
670.596	31.1073
674.037	33.2055
677.478	34.7477
680.917	36.3036
684.355	38.7739
687.791	41.0453
691.224	42.3025
694.658	43.5123
698.091	45.1653
701.522	47.0294
704.95	48.124
708.379	50.3856
711.806	49.8571
715.23	51.1472
718.655	50.9611
722.078	51.1078
725.498	52.9736
728.919	54.7036
732.337	55.8865
735.755	57.6285
739.17	58.1754
742.584	60.4019
745.998	62.1154
749.409	64.1148
752.819	66.1069
756.23	69.47
759.637	71.5748
763.043	74.1442
766.448	77.8931
769.853	80.4073
773.255	82.0727
776.656	84.3753
780.056	86.643
783.454	88.2771
786.851	90.9663
790.247	93.8001
793.641	96.4005
797.034	99.453
800.426	102.172
803.817	102.866
807.206	103.68
810.592	106.139
813.979	107.38
817.364	109.326
820.748	109.346
824.129	108.292
827.511	106.392
830.891	106.365
834.269	104.704
837.646	103.327
841.023	102.261
844.396	99.7772
847.77	97.5055
851.141	94.0742
854.513	90.5219
857.881	86.9816
861.248	83.7735
864.616	80.974
867.98	78.6496
871.343	77.7621
874.707	76.2476
878.068	72.7165
881.428	71.2266
884.786	70.7578
888.143	70.0255
891.498	69.3368
894.855	69.9808
898.208	69.1946
901.56	69.5964
904.91	69.1414
908.26	69.314
911.608	69.3129
914.955	71.1448
918.298	71.666
921.643	69.9416
924.986	69.8095
928.328	68.8755
931.668	69.9856
935.006	68.9416
938.344	67.9576
941.681	67.0631
945.014	65.2029
948.349	63.6635
951.682	63.2398
955.012	60.9182
958.343	57.3715
961.67	58.1982
964.998	59.4033
968.323	59.192
971.649	58.5534
974.971	58.6907
978.293	58.1294
981.615	57.4603
984.933	57.7942
988.251	57.1211
991.567	56.5618
994.884	55.336
998.198	55.2809
1001.51	55.5744
1004.82	55.6867
1008.13	55.8938
1011.44	56.3173
1014.75	56.8765
1018.06	53.9628
1021.36	53.6311
1024.66	52.372
1027.97	50.0337
1031.27	47.9957
1034.57	46.4112
1037.87	44.0681
1041.16	43.9837
1044.46	44.8497
1047.76	43.7127
1051.05	43.417
1054.34	41.84
1057.63	42.308
1060.92	40.1523
1064.21	39.0505
1067.5	38.2068
1070.78	37.3137
1074.07	38.557
1077.35	40.0502
1080.63	41.054
1083.91	41.6883
1087.19	43.433
1090.47	45.0748
1093.75	45.0219
1097.03	45.2789
1100.3	44.877
1103.57	44.7117
1106.84	42.8517
1110.11	41.66
1113.38	39.3268
1116.65	37.6919
1119.92	37.4349
1123.19	35.6726
1126.45	33.4735
1129.71	32.0722
1132.97	31.0429
1136.23	29.6293
1139.49	27.7671
1142.75	26.7178
1146.01	26.4816
1149.26	25.7196
1152.52	25.5264
1155.77	25.1066
1159.02	23.4238
1162.27	24.0029
1165.52	25.261
1168.77	26.2249
1172.02	25.6635
1175.26	26.632
1178.51	27.0404
1181.75	28.0969
1184.99	28.2316
1188.23	28.0782
1191.47	28.1393
1194.71	29.0648
1197.94	31.9147
1201.18	34.107
1204.41	36.3504
1207.65	39.622
1210.88	41.8936
1214.11	45.8933
1217.34	48.7091
1220.57	51.1767
1223.79	54.4627
1227.02	56.4035
1230.24	58.9567
1233.47	61.2615
1236.69	63.4305
1239.91	67.1961
1243.13	70.4344
1246.34	70.9706
1249.56	70.7706
1252.78	72.9709
1255.99	74.7854
1259.2	74.1425
1262.42	74.1139
1265.63	73.7536
1268.84	75.1527
1272.04	76.1056
1275.25	76.6583
1278.46	78.0114
1281.66	79.5544
1284.86	80.4363
1288.07	81.2214
1291.27	81.9557
1294.47	83.96
1297.66	85.5146
1300.86	87.7007
1304.06	89.6596
1307.25	91.3524
1310.44	93.6976
1313.64	96.0953
1316.83	95.6792
1320.02	95.8663
1323.2	96.258
1326.39	96.0488
1329.58	97.8646
1332.76	96.9448
1335.95	96.1788
1339.13	92.637
1342.31	91.1067
1345.49	88.4162
1348.67	87.1551
1351.85	84.304
1355.02	81.266
1358.2	78.9461
1361.37	77.3677
1364.54	74.0187
1367.71	69.8082
1370.88	68.1926
1374.05	67.2416
1377.22	66.1608
1380.39	65.2803
1383.55	64.1624
1386.72	63.1135
1389.88	61.4452
1393.04	60.0065
1396.2	58.3426
1399.36	58.6342
1402.52	58.0917
1405.68	59.5677
1408.83	59.6876
1411.98	60.0735
1415.14	62.0069
1418.29	66.3897
1421.44	70.7218
1424.59	75.5985
1427.74	81.7065
1430.89	83.87
1434.03	88.7367
1437.18	92.7346
1440.32	95.5123
1443.46	96.2075
1446.6	97.446
1449.74	98.9438
1452.88	97.9428
1456.02	95.1901
1459.16	91.0381
1462.29	86.132
1465.43	81.2513
1468.56	74.2308
1471.69	66.6788
1474.82	59.8254
1477.95	52.437
1481.08	45.2654
1484.2	39.7051
1487.33	33.0085
1490.46	29.7968
1493.58	28.7668
1496.7	26.7566
1499.82	24.197
1502.94	23.1188
1506.06	23.5211
1509.18	23.1604
1512.29	23.4057
1515.41	25.2436
1518.52	25.7032
1521.63	27.4209
1524.75	29.5526
1527.85	31.8925
1530.96	34.2341
1534.07	36.3874
1537.18	38.6135
1540.28	42.1437
1543.39	43.7714
1546.49	46.227
1549.59	47.1123
1552.69	50.135
1555.79	53.2154
1558.89	56.8685
1561.99	59.2911
1565.08	62.4998
1568.18	66.6695
1571.27	68.6604
1574.37	71.9714
1577.46	73.7997
1580.55	77.9604
1583.64	80.0476
1586.73	80.183
1589.81	80.5369
1592.9	81.7755
1595.98	80.5938
1599.06	79.8129
1602.15	78.4308
1605.23	76.272
1608.31	73.1912
1611.39	70.4247
1614.46	67.9794
1617.54	64.781
1620.61	64.8593
1623.69	63.3574
1626.76	62.3589
1629.83	62.4361
1632.9	62.2156
1635.97	63.1423
1639.04	64.2246
1642.11	66.5106
1645.17	67.5509
1648.24	70.0205
1651.3	73.1593
1654.36	76.6586
1657.42	77.2042
1660.48	76.2488
1663.54	74.6912
1666.6	72.2651
1669.66	69.9517
1672.71	65.5073
1675.77	63.0418
1678.82	58.5953
1681.87	53.5555
1684.92	48.3206
1687.97	44.2373
1691.02	39.4334
1694.07	35.3398
1697.11	28.9466
1700.16	23.9155
1703.2	18.1596
1706.25	14.8289
1709.29	13.0101
1712.33	10.349
1715.37	8.9183
1718.41	7.60385
1721.44	6.11584
1724.48	7.03358
1727.51	8.05406
1730.55	7.67672
1733.58	7.56099
1736.61	7.80714
1739.64	8.25107
1742.67	7.71533
1745.7	8.95523
1748.72	8.98954
1751.75	9.46464
1754.77	9.0993
1757.8	9.1656
1760.82	8.85076
1763.84	7.54557
1766.86	5.17072
1769.88	3.80445
1772.9	2.48393
1775.91	1.82597
1778.93	1.47798
1781.94	1.09229
1784.96	-0.0682579
1787.97	-0.7333
1790.98	-0.144655
1793.99	-0.913686
1797	-0.554119
1800.01	1.29854
1803.01	1.67394
1806.02	2.77236
1809.02	3.48815
1812.02	4.31194
1815.02	4.9064
1818.03	5.48748
1821.02	6.1987
1824.02	6.57663
1827.02	6.82981
1830.02	7.43876
1833.01	7.52336
1836.01	6.87942
1839	6.01625
1841.99	6.16377
1844.98	6.55731
1847.97	6.42024
1850.96	6.36515
1853.95	6.40315
1856.93	5.77431
1859.92	5.48941
1862.9	5.90634
1865.88	5.67189
1868.87	5.71504
1871.85	6.77801
1874.83	6.96264
1877.81	6.72259
1880.78	7.46916
1882.53	7.26727
1885.52	7.069
1888.51	7.56671
1891.5	7.85749
1894.48	7.83503
1897.47	7.79499
1900.45	7.98431
1903.43	6.98254
1906.41	6.55319
1909.39	5.77332
1912.37	5.7038
1915.35	5.93878
1918.33	4.86704
1921.3	5.70392
1924.28	5.70258
1927.25	5.35754
1930.22	5.70449
1933.19	6.89108
1936.16	6.97604
1939.13	7.8507
1942.1	8.15876
1945.07	8.68479
1948.03	8.51589
1951	8.20818
1953.96	8.72175
1956.92	8.1734
1959.88	8.30071
1962.84	8.00065
1965.8	7.52299
1968.76	7.25817
1971.72	7.08871
1974.67	5.41122
1977.63	5.08546
1980.58	5.32265
1983.54	5.06004
1986.49	5.29297
1989.44	5.3893
1992.39	5.24647
1995.33	5.67025
1998.28	5.69547
2001.23	6.10789
2004.17	6.53247
2007.12	6.46563
2010.06	6.5298
2013	7.26278
2015.94	7.03176
2018.88	6.51514
2021.82	5.94646
2024.76	6.70636
2027.69	7.64707
2030.63	7.08661
2033.56	6.45998
2036.5	7.01658
2039.43	7.27457
2042.36	8.11835
2045.29	9.42272
2048.22	8.93354
2051.15	10.0009
2054.07	10.4295
2057	12.5236
2059.92	12.8886
2062.85	12.6934
2065.77	11.9118
2068.69	12.2209
2071.61	11.647
2074.53	11.8069
2077.45	11.8741
2080.37	12.4361
2083.28	12.4356
2086.2	12.8153
2089.11	11.88
2092.02	12.0299
2094.94	13.126
2097.85	12.9487
2100.76	13.2027
2103.66	13.8136
2106.57	14.3859
2109.48	15.4579
2112.38	16.3835
2115.29	17.1791
2118.19	18.1204
2121.09	19.3922
2123.99	20.967
2126.89	22.1418
2129.79	23.2439
2132.69	23.5195
2135.59	23.9975
2138.48	25.1111
2141.38	24.9759
2144.27	26.1759
2147.17	26.3902
2150.06	27.892
2152.95	27.7151
2155.84	28.3017
2158.73	28.1934
2161.61	28.4033
2164.5	28.7156
2167.38	29.0243
2170.27	30.1573
2173.15	30.552
2176.03	31.2538
2178.91	30.6282
2181.8	30.5958
2184.67	30.8354
2187.55	31.2797
2190.43	30.5194
2193.3	30.1145
2196.18	28.7416
2199.05	28.3781
2201.93	27.527
2204.8	26.3596
2207.67	25.4116
2210.54	24.929
2213.41	23.1723
2216.27	21.5947
2219.14	20.3925
2222.01	19.583
2224.87	19.0907
2227.73	18.4592
2230.6	17.1984
2233.46	16.6018
2236.32	16.2502
2239.18	16.1416
2242.03	16.0363
2244.89	15.5844
2247.75	16.0285
2250.6	15.0567
2253.46	14.837
2256.31	14.0861
2259.16	12.4615
2262.01	11.4979
2264.86	11.4515
2267.71	11.953
2270.56	11.9234
2273.4	11.818
2276.25	12.514
2279.09	11.3762
2281.94	11.2567
2284.78	9.53172
2287.62	9.41979
2290.46	8.80139
2293.3	7.18435
2296.14	7.74603
2298.98	7.50951
2301.82	7.1784
2304.65	7.6418
2307.49	8.30956
2310.32	8.61377
2313.15	8.69668
2315.98	7.89336
2318.81	6.90541
2321.64	6.95271
2324.47	5.72203
2327.3	5.51786
2330.12	5.17744
2332.95	5.43053
2335.77	6.08249
2338.6	5.51082
2341.42	5.69759
2344.24	4.29059
2347.06	3.58015
2349.88	2.76671
2352.7	2.19457
2355.51	2.11296
2358.33	2.32017
2361.14	1.7449
2363.96	2.55605
2366.77	3.81544
2369.58	3.54198
2372.39	4.28686
2375.2	4.48554
2378.01	4.80505
2380.82	4.45236
2383.63	3.95618
2386.43	4.20719
2389.24	3.81802
2392.04	2.89076
2394.84	2.47189
2397.65	2.8214
2400.45	2.63332
2403.25	2.81159
2406.05	2.74076
2408.84	2.3407
2411.64	2.48776
2414.44	2.32178
2417.23	3.90702
2420.02	3.74283
2422.82	3.99658
2425.61	3.06223
2428.4	3.3729
2431.19	3.78528
2433.98	3.6186
2436.77	4.13793
2439.55	4.48233
2442.34	4.32885
2445.12	4.33522
2447.91	4.64913
2450.69	4.4457
2453.47	3.17748
2456.25	2.68104
2459.03	2.40755
2461.81	2.43618
2464.59	3.14856
2467.36	2.52711
2470.14	2.72169
2472.92	3.43129
2475.69	2.30239
2478.46	0.78488
2481.23	1.64143
2484	1.55891
2486.77	0.259712
2489.54	-0.31298
2492.31	-0.895881
2495.08	-0.829863
2497.84	-0.727173
2500.61	-0.818638
2503.37	-0.741793
2506.13	-0.763347
2508.9	-0.591842
2511.66	-0.615876
2514.42	-0.206819
2517.18	0.290826
2519.93	0.192331
2522.69	0.443903
2525.45	1.77973
2528.2	3.14386
2530.95	3.30555
2533.71	2.3992
2536.46	2.84252
2539.21	3.13015
2541.96	2.75513
2544.71	1.92049
2547.46	2.52098
2550.2	3.00473
2552.95	1.66695
2555.7	1.69522
2558.44	1.22314
2561.18	0.777861
2563.93	0.570728
2566.67	0.50669
2569.41	0.919326
2572.15	0.883389
2574.88	0.836567
2577.62	0.633364
2580.36	0.376834
2583.09	1.31079
2585.83	0.723831
2588.56	0.192351
2591.29	0.901625
2594.02	1.12437
2596.75	1.01896
2599.48	0.7049
2602.21	0.622381
2604.94	1.56897
2607.67	1.34938
2610.39	1.08278
2613.12	1.80186
2615.84	1.92791
2618.56	2.05196
2621.28	2.12328
2624.01	3.13916
2626.72	2.5739
2629.44	2.06937
2632.16	2.0234
2634.88	1.58676
2637.59	2.16088
2640.31	1.7441
2643.02	0.992878
2645.74	0.871608
2648.45	1.03546
2651.16	0.823869
2653.87	0.331582
2656.58	-0.163004
2659.29	0.612588
2661.99	1.37959
2664.7	1.86477
2667.41	2.00226
2670.11	2.95055
2672.81	3.90969
2675.51	4.48503
2678.22	5.42304
2680.92	6.19142
2683.62	6.74244
2686.31	7.61862
2689.01	8.0707
2691.71	7.28164
2694.4	8.48666
2697.1	8.36846
2699.79	8.57258
2702.49	8.20935
2705.18	9.01088
2707.87	9.63376
2710.56	10.0656
2713.25	10.0349
2715.94	10.2716
2718.62	10.3312
2721.31	10.6314
2723.99	11.5047
2726.68	11.4512
2729.36	10.5083
2732.04	10.6993
2734.73	9.67293
2737.41	9.15748
2740.08	8.78254
2742.76	8.65968
2745.44	7.875
2748.12	6.8496
2750.79	6.37731
2753.47	6.2386
2756.14	5.92765
2758.81	5.93562
2761.49	5.83478
2764.16	5.42693
2766.83	4.3771
2769.5	4.34645
2772.16	4.64476
2774.83	4.74725
2777.5	4.93434
2780.16	4.2605
2782.83	3.90711
2785.49	3.64668
2788.15	3.29038
2790.82	1.89385
2793.48	1.71992
2796.14	1.99263
2798.79	2.11063
2801.45	1.92197
2804.11	1.76659
2806.76	1.97908
2809.42	2.21655
2812.07	1.81663
2814.73	2.31895
2817.38	2.44084
2820.03	3.92626
2822.68	5.82881
2825.33	8.25215
2827.98	11.2201
2830.63	14.572
2833.27	18.5415
2835.92	23.2976
2838.56	27.6306
2841.21	33.0289
2843.85	38.7766
2846.49	44.9108
2849.13	52.6075
2851.77	60.7259
2854.41	69.5388
2857.05	77.6041
2859.69	85.6571
2862.32	93.2211
2864.96	99.31
2867.59	104.771
2870.23	110.237
2872.86	115.392
2875.49	118.884
2878.12	121.945
2880.75	125.569
2883.38	128.775
2886.01	133.135
2888.63	136.728
2891.26	139.933
2893.89	144.165
2896.51	148.253
2899.13	153.357
2901.76	159.317
2904.38	166.388
2907	174.865
2909.62	184.302
2912.24	194.667
2914.85	204.07
2917.47	212.665
2920.09	220.098
2922.7	225.033
2925.32	229.402
2927.93	232.22
2930.54	232.919
2933.15	232.957
2935.76	231.509
2938.37	228.136
2940.98	223.607
2943.59	219.29
2946.2	213.369
2948.8	206.837
2951.41	199.845
2954.01	191.962
2956.62	185.095
2959.22	178.448
2961.82	172.142
2964.42	166.329
2967.02	160.477
2969.62	154.644
2972.22	149.148
2974.81	143.253
2977.41	135.03
2980	127.88
2982.6	119.113
2985.19	110.582
2987.78	102.95
2990.38	93.6962
2992.97	84.6738
2995.56	77.0907
2998.14	69.8193
3000.73	62.9102
3003.32	55.0834
3005.91	48.7326
3008.49	43.5186
3011.07	38.6418
3013.66	34.2459
3016.24	30.7168
3018.82	27.724
3021.4	26.3982
3023.98	24.3479
3026.56	23.9914
3029.14	22.029
3031.71	21.3974
3034.29	21.3591
3036.87	21.5841
3039.44	22.8733
3042.01	23.8171
3044.59	25.3622
3047.16	26.3109
3049.73	27.5925
3052.3	27.8558
3054.87	28.2297
3057.43	29.119
3060	29.1056
3062.57	28.3252
3065.13	27.831
3067.7	26.2462
3070.26	24.6737
3072.82	22.4868
3075.39	19.8358
3077.95	17.0679
3080.51	14.9387
3083.07	12.4803
3085.63	10.4898
3088.18	7.62332
3090.74	5.61785
3093.29	3.9671
3095.85	2.63068
3098.4	1.92041
3100.95	1.66479
3103.51	1.66102
3106.06	0.958492
3108.61	1.29116
3111.16	1.29503
3113.71	1.0008
3116.25	0.808467
3118.8	0.982321
3121.35	0.711043
3123.89	0.997587
3126.44	1.04542
3128.98	0.988752
3131.52	0.0732673
3134.06	-0.183674
3136.6	-0.0310316
3139.14	-0.178766
3141.68	-0.267213
3144.22	-0.630936
3146.76	-0.775928
3149.29	-1.97437