File: data/Raman/poly_smoothed/Thy_00_07_40_1x_45s_532 nm_x100_100%_600 gr_mm_01.txt
#Acq. time (s)=	45
#Accumulations=	2
#Range (cm-¹)=	200...3150
#Windows=	2
#Auto scanning=	Off
#Autofocus=	Off
#Macrospot=	Off
#AutoExposure=	Off
#Spike filter=	Multiple accum.
#Delay time (s)=	0
#Binning=	1
#Readout mode=	Signal
#DeNoise=	Off
#ICS correction=	On
#Dark correction=	Off
#Inst. Process=	Off
#Detector Gain=	Best Dynamic Range
#Detector ADC=	20 kHz
#Detector temperature (°C)=	-69.85
#Instrument=	LabRAM HR Evol
#Detector=	Synapse
#Objective=	x100
#Grating=	600 gr/mm
#ND Filter=	100%
#Laser (nm)=	532
#Hole=	100.021
#Range=	Auto
#Laser Pol.=	No
#Raman. Pol.=	No
#Laser Pol. (°)=	-0.0007625
#Raman Pol. (°)=	89.9995
#Collection=	Microscope
#StageXY=	Marzhauser
#StageZ=	Marzhauser
#X (µm)=	8965.3
#Y (µm)=	-3049.1
#Z (µm)=	-54.85
#Full time(mm:ss)=	3:19
#Project=
#Sample=
#Site=
#Title=	Thy_00_07_40_2x_45s_532 nm_x100_100%_600 gr_mm
#Remark=
#Date=	28.06.2022 13:01
#Acquired=	28.06.2022 13:01:17
#Base:Fit=	10.08.2022 10:07:56
#Base:Sub=	10.08.2022 10:08:40
#Filter:Polynom=	16.08.2022 10:26:06
#AxisType[0]=Intens
#AxisUnit[0]=Cnt
#AxisType[1]=Spectr
#AxisUnit[1]=1/cm
200.407	0.0815877
204.035	5.04941
207.665	7.74279
211.291	10.6413
214.916	12.0309
218.541	13.3355
222.163	12.8553
225.785	11.6794
229.404	11.5389
233.022	12.2458
236.638	12.5997
240.255	13.5196
243.868	11.5327
247.48	10.5213
251.091	10.0032
254.702	9.36811
258.31	9.05819
261.916	7.32468
265.521	5.64855
269.125	5.75413
272.727	5.50888
276.328	4.36974
279.927	4.3054
283.525	3.85249
287.121	3.76681
290.716	3.45552
294.31	2.26718
297.9	2.23403
301.491	1.78053
305.081	2.87739
308.669	2.05097
312.256	2.3383
315.839	3.52726
319.423	4.89169
323.006	6.0517
326.585	7.55427
330.165	6.30485
333.741	6.64588
337.318	7.0106
340.894	7.64033
344.466	7.00828
348.039	7.34816
351.608	7.43728
355.176	8.59894
358.745	7.27359
362.31	7.74805
365.876	7.14491
369.439	6.34645
373	6.68988
376.56	7.00797
380.12	5.72434
383.677	5.32886
387.233	5.64665
390.787	6.29212
394.34	4.88795
397.894	4.63324
401.444	5.53569
404.993	5.45508
408.54	6.80308
412.086	7.96682
415.631	9.18981
419.174	9.82453
422.716	10.0186
426.257	10.3079
429.794	11.3241
433.332	10.201
436.868	9.96224
440.403	10.5844
443.937	9.78569
447.468	9.18306
450.999	10.1427
454.528	9.88602
458.057	10.235
461.582	9.41353
465.107	6.98635
468.629	4.94338
472.152	5.1195
475.672	4.04154
479.192	3.72762
482.709	3.97212
486.226	5.38597
489.74	6.16642
493.255	6.51663
496.767	7.15658
500.277	8.34768
503.788	9.03855
507.295	9.31655
510.801	11.4299
514.308	11.6731
517.811	11.2687
521.313	10.3601
524.814	10.7175
528.313	10.9243
531.811	11.0154
535.308	11.627
538.803	11.0373
542.297	10.8829
545.789	9.09205
549.281	7.21671
552.771	6.32633
556.259	5.63138
559.747	5.04649
563.233	4.98078
566.717	4.5354
570.2	4.23098
573.68	3.55106
577.161	1.79445
580.64	1.08874
584.118	1.22412
587.593	3.17068
591.068	3.33222
594.54	2.60414
598.013	3.36882
601.484	2.65535
604.952	2.47561
608.421	2.37082
611.886	3.07159
615.35	4.71425
618.815	5.99036
622.276	6.83074
625.738	7.65347
629.197	7.67882
632.655	8.61601
636.113	9.13867
639.568	10.5353
643.021	12.1977
646.473	14.2339
649.924	16.2843
653.376	18.7155
656.824	19.3506
660.271	20.3643
663.716	21.6056
667.161	23.9524
670.604	25.8075
674.045	26.7483
677.486	26.7735
680.925	27.7184
684.361	29.0228
687.797	29.0854
691.232	30.1545
694.666	31.1481
698.099	32.278
701.528	34.6143
704.958	33.8072
708.387	34.7237
711.814	35.056
715.238	35.5269
718.663	35.4809
722.084	36.1876
725.506	38.0247
728.925	39.2936
732.345	40.599
735.761	40.2011
739.178	41.1295
742.592	42.2637
746.006	43.7245
749.417	45.9283
752.827	49.3336
756.236	51.7412
759.645	53.2508
763.051	56.5163
766.456	59.9529
769.859	63.4109
773.261	64.0735
776.664	67.2033
780.064	68.5703
783.462	70.4523
786.859	70.7804
790.255	72.6163
793.649	74.2063
797.042	74.4078
800.434	75.8113
803.823	75.5964
807.212	76.0893
810.6	75.5231
813.987	74.1946
817.372	72.5681
820.754	71.2027
824.137	72.0282
827.519	72.2179
830.897	71.949
834.276	71.2028
837.654	72.1203
841.029	70.645
844.404	70.6885
847.776	68.9895
851.149	67.2864
854.519	64.9894
857.889	61.5163
861.256	60.0751
864.622	57.1911
867.988	54.5233
871.351	51.994
874.713	52.167
878.074	48.4151
881.435	47.287
884.794	47.1275
888.15	45.8426
891.506	44.7468
894.861	45.5769
898.214	44.1705
901.566	45.2717
904.916	46.319
908.266	46.4165
911.614	46.5966
914.961	46.8241
918.306	47.5151
921.651	45.9997
924.994	46.2327
928.336	46.1979
931.674	46.1263
935.014	45.9902
938.352	44.4554
941.687	42.8596
945.022	41.252
948.357	39.5203
951.688	38.1197
955.02	37.7384
958.348	34.5195
961.678	32.797
965.004	33.8759
968.331	34.6179
971.655	35.7237
974.979	37.9509
978.3	38.2025
981.62	39.2597
984.941	40.2106
988.259	38.1526
991.575	35.8222
994.89	34.9215
998.204	34.5183
1001.52	32.7274
1004.83	32.042
1008.14	31.2375
1011.45	31.0658
1014.76	30.6902
1018.06	29.6497
1021.37	26.5352
1024.67	24.3533
1027.97	23.594
1031.27	22.905
1034.57	20.1172
1037.87	17.6484
1041.17	17.2871
1044.47	18.584
1047.76	19.1143
1051.06	19.1931
1054.35	20.3588
1057.64	19.6225
1060.93	19.2081
1064.22	19.8005
1067.5	17.5826
1070.79	16.8395
1074.08	15.5024
1077.36	15.1638
1080.64	15.2154
1083.92	15.1448
1087.2	16.0049
1090.48	15.9018
1093.76	16.0551
1097.03	16.8485
1100.31	15.7025
1103.58	16.915
1106.85	19.1262
1110.12	17.7811
1113.39	16.6858
1116.66	15.3172
1119.93	15.3535
1123.19	13.7686
1126.46	12.8564
1129.72	12.559
1132.98	11.6711
1136.24	11.6853
1139.5	11.6698
1142.76	11.8803
1146.01	9.23713
1149.27	8.48981
1152.53	6.57846
1155.78	5.33287
1159.03	5.21176
1162.28	4.61027
1165.53	2.75721
1168.78	3.15416
1172.02	4.84836
1175.27	5.56717
1178.51	5.73418
1181.76	6.12098
1185	7.95759
1188.24	8.78663
1191.48	7.86589
1194.71	8.48356
1197.95	11.3542
1201.19	14.2851
1204.42	16.9081
1207.65	20.3992
1210.88	22.7291
1214.12	24.8713
1217.35	27.8167
1220.57	30.8978
1223.8	30.2843
1227.03	31.3335
1230.25	33.2053
1233.47	33.4729
1236.69	34.6755
1239.92	36.8486
1243.13	37.5636
1246.35	38.677
1249.57	41.3113
1252.78	39.8429
1256	39.6619
1259.21	39.004
1262.42	40.0188
1265.63	39.8862
1268.84	39.609
1272.05	39.5787
1275.26	41.1107
1278.46	42.839
1281.67	45.3227
1284.87	47.3245
1288.07	48.5148
1291.27	50.4325
1294.47	52.4294
1297.67	53.0293
1300.87	54.5234
1304.06	56.5339
1307.26	59.4174
1310.45	62.9378
1313.64	66.2823
1316.83	68.8881
1320.02	70.7566
1323.21	71.0597
1326.4	72.1359
1329.59	71.2455
1332.77	69.9568
1335.95	70.6089
1339.14	69.4148
1342.32	66.886
1345.5	64.8593
1348.67	64.5448
1351.85	61.8546
1355.03	58.3853
1358.2	54.2464
1361.38	51.8256
1364.55	49.3339
1367.72	46.9789
1370.89	44.5823
1374.06	42.9507
1377.23	41.4076
1380.39	41.2658
1383.56	40.9289
1386.72	39.8743
1389.89	40.8683
1393.05	40.2702
1396.21	37.9204
1399.37	38.2086
1402.52	37.0344
1405.68	37.8624
1408.84	39.0653
1411.99	40.3612
1415.15	44.2799
1418.3	46.9241
1421.45	50.5457
1424.6	54.001
1427.75	57.5431
1430.89	59.4831
1434.04	63.0043
1437.18	67.2966
1440.33	71.765
1443.47	75.8834
1446.61	77.8569
1449.75	78.3379
1452.89	79.491
1456.03	79.3142
1459.16	77.9028
1462.3	75.2111
1465.43	69.6682
1468.56	65.5579
1471.7	57.9279
1474.83	51.1948
1477.96	44.2168
1481.08	39.6864
1484.21	34.9586
1487.34	29.8504
1490.46	24.7229
1493.58	22.3424
1496.71	18.6599
1499.83	16.0764
1502.95	14.7939
1506.07	13.8666
1509.18	14.3541
1512.3	14.0254
1515.41	14.8315
1518.53	15.4134
1521.64	16.2418
1524.75	16.1137
1527.86	17.7626
1530.97	19.6267
1534.08	21.2209
1537.19	22.2233
1540.29	22.1419
1543.4	23.3515
1546.5	25.318
1549.6	27.5342
1552.7	29.8602
1555.8	32.4914
1558.9	35.3398
1562	37.6508
1565.09	39.8044
1568.19	42.4795
1571.28	45.3875
1574.37	47.4049
1577.47	50.9315
1580.56	53.5981
1583.64	55.8474
1586.73	57.2643
1589.82	57.6877
1592.9	59.8244
1595.99	59.1912
1599.07	58.0128
1602.15	57.5668
1605.23	58.6827
1608.31	57.6409
1611.39	56.2341
1614.47	54.2475
1617.55	54.5549
1620.62	54.7626
1623.7	54.6091
1626.77	54.6581
1629.84	54.697
1632.91	55.4442
1635.98	56.4766
1639.05	57.5611
1642.11	58.4629
1645.18	59.2676
1648.24	60.7946
1651.31	62.7568
1654.37	63.6416
1657.43	64.1205
1660.49	64.0355
1663.55	64.1522
1666.61	63.4274
1669.66	61.6898
1672.72	58.8321
1675.77	55.5781
1678.83	51.6428
1681.88	45.9643
1684.93	41.3696
1687.98	38.2618
1691.03	34.9851
1694.07	29.802
1697.12	25.7312
1700.17	22.0782
1703.21	18.3332
1706.25	15.958
1709.29	12.9234
1712.33	9.9372
1715.37	9.0832
1718.41	7.84483
1721.45	6.51821
1724.49	7.49359
1727.52	7.97787
1730.55	7.4923
1733.59	8.28453
1736.62	8.67614
1739.65	9.97154
1742.68	10.3894
1745.7	9.78191
1748.73	10.1108
1751.76	9.718
1754.78	8.8602
1757.8	8.70445
1760.83	9.24426
1763.85	8.12016
1766.87	6.84077
1769.89	4.9827
1772.9	5.02807
1775.92	4.9734
1778.94	4.90235
1781.95	4.26905
1784.96	3.37994
1787.97	3.73793
1790.99	2.97078
1794	3.51017
1797	3.63478
1800.01	4.19194
1803.02	3.89891
1806.02	4.95661
1809.03	5.84771
1812.03	5.81595
1815.03	5.479
1818.03	5.34403
1821.03	5.84305
1824.03	5.03632
1827.03	5.13534
1830.02	4.38393
1833.02	4.13084
1836.01	3.75465
1839.01	3.29112
1842	2.48563
1844.99	2.40546
1847.98	1.67088
1850.97	1.3287
1853.95	1.35312
1856.94	1.18207
1859.93	0.493619
1862.91	0.33591
1865.89	0.0129714
1868.87	-0.082622
1871.85	0.545579
1874.83	1.11555
1877.81	0.712792
1880.79	0.0806439
1882.52	0.606593
1885.51	0.402027
1888.5	1.49806
1891.49	1.31708
1894.47	1.24507
1897.46	2.49542
1900.44	3.45209
1903.42	3.93554
1906.4	4.34139
1909.38	3.56019
1912.36	4.3483
1915.34	5.19371
1918.32	4.74192
1921.29	4.39526
1924.27	5.22702
1927.24	4.99164
1930.21	3.46464
1933.18	4.29422
1936.15	4.55528
1939.12	3.79744
1942.09	3.59021
1945.06	4.37037
1948.02	3.58481
1950.99	3.32581
1953.95	3.75073
1956.91	4.5762
1959.88	3.55489
1962.84	3.25462
1965.8	3.7111
1968.75	3.65318
1971.71	4.16084
1974.67	4.07536
1977.62	3.84971
1980.58	4.00902
1983.53	4.07378
1986.48	4.60594
1989.43	4.51604
1992.38	4.00067
1995.33	4.55099
1998.27	4.74616
2001.22	6.04274
2004.16	6.70602
2007.11	5.43394
2010.05	6.50186
2012.99	7.02367
2015.93	6.94144
2018.87	7.42376
2021.81	6.94779
2024.75	7.22992
2027.69	6.71271
2030.62	6.20562
2033.56	6.13111
2036.49	5.76127
2039.42	5.33982
2042.35	5.31235
2045.28	4.69094
2048.21	4.21278
2051.14	5.00864
2054.07	4.78937
2056.99	5.2592
2059.92	4.68793
2062.84	5.57073
2065.76	5.363
2068.68	6.09613
2071.6	7.89196
2074.52	8.07683
2077.44	6.80184
2080.36	7.77507
2083.27	8.60243
2086.19	7.74597
2089.1	6.6518
2092.02	6.37449
2094.93	6.63531
2097.84	5.46759
2100.75	4.91276
2103.66	5.12288
2106.56	3.41803
2109.47	2.92128
2112.38	3.45978
2115.28	2.33926
2118.18	2.41254
2121.09	2.89837
2123.99	3.00091
2126.89	2.02808
2129.79	3.11691
2132.68	1.83043
2135.58	2.12349
2138.48	2.58112
2141.37	2.78751
2144.27	2.75778
2147.16	2.53363
2150.05	2.8672
2152.94	3.79105
2155.83	3.23238
2158.72	2.10227
2161.6	2.33487
2164.49	2.1512
2167.38	2.58376
2170.26	2.57755
2173.14	3.01626
2176.03	3.8343
2178.91	3.94282
2181.79	5.51277
2184.67	6.51281
2187.54	7.80393
2190.42	9.04976
2193.3	8.9574
2196.17	9.1533
2199.05	10.1002
2201.92	9.15736
2204.79	9.2334
2207.66	10.269
2210.53	10.3885
2213.4	10.1258
2216.27	10.147
2219.13	9.80263
2222	9.45988
2224.86	9.94379
2227.72	8.10934
2230.59	7.26905
2233.45	7.26079
2236.31	6.82695
2239.17	6.60454
2242.03	5.3684
2244.88	5.31045
2247.74	5.51659
2250.59	4.96899
2253.45	5.54936
2256.3	5.06458
2259.15	4.9309
2262	2.84379
2264.85	2.23997
2267.7	2.38765
2270.55	1.91664
2273.4	2.19364
2276.24	3.17896
2279.09	3.2137
2281.93	3.12192
2284.77	3.28346
2287.62	4.70875
2290.46	5.71526
2293.3	5.75398
2296.13	6.12415
2298.97	7.02551
2301.81	7.52826
2304.64	8.16831
2307.48	8.34529
2310.31	9.16963
2313.14	9.87269
2315.98	11.2427
2318.81	11.024
2321.64	11.172
2324.46	10.3419
2327.29	8.8948
2330.12	9.28911
2332.94	8.12115
2335.77	8.33993
2338.59	7.98938
2341.41	7.3601
2344.23	5.79793
2347.05	4.70418
2349.87	3.40195
2352.69	2.76129
2355.51	2.67098
2358.32	2.41886
2361.14	1.70299
2363.95	1.67384
2366.76	1.25608
2369.58	1.96427
2372.39	1.08938
2375.2	1.33068
2378	1.74501
2380.81	2.58364
2383.62	2.83231
2386.43	2.77159
2389.23	2.71634
2392.03	3.41215
2394.84	3.9176
2397.64	5.68122
2400.44	6.40052
2403.24	7.73103
2406.04	8.72766
2408.84	8.63565
2411.63	8.50234
2414.43	9.77846
2417.22	9.58688
2420.02	10.0988
2422.81	11.2524
2425.6	12.0136
2428.39	11.5119
2431.18	10.6972
2433.97	9.78262
2436.76	9.97511
2439.54	9.10054
2442.33	8.93204
2445.12	7.67909
2447.9	6.97315
2450.68	5.84448
2453.46	5.02966
2456.24	4.67833
2459.02	3.63049
2461.8	3.39575
2464.58	3.43828
2467.36	3.86679
2470.13	4.28948
2472.91	4.10383
2475.68	4.04912
2478.45	3.72879
2481.23	3.74707
2484	4.24684
2486.77	3.41621
2489.54	3.71427
2492.3	3.73699
2495.07	2.42724
2497.84	2.22291
2500.6	2.21181
2503.36	1.86136
2506.13	1.50454
2508.89	1.90218
2511.65	1.67803
2514.41	0.733483
2517.17	1.39384
2519.93	1.00986
2522.68	1.32186
2525.44	1.42853
2528.19	1.67207
2530.95	3.59792
2533.7	4.21554
2536.45	5.69037
2539.2	5.89343
2541.95	5.68665
2544.7	5.5147
2547.45	5.79244
2550.2	5.23761
2552.94	5.95116
2555.69	5.33097
2558.43	5.11492
2561.18	4.47059
2563.92	4.495
2566.66	5.29023
2569.4	3.86699
2572.14	3.22051
2574.88	3.53002
2577.61	3.77905
2580.35	3.08788
2583.09	3.26401
2585.82	3.34119
2588.55	3.93279
2591.29	5.13291
2594.02	5.64549
2596.75	6.86548
2599.48	6.73278
2602.21	6.06265
2604.93	5.78712
2607.66	5.60977
2610.39	5.26492
2613.11	5.64939
2615.83	4.43986
2618.56	4.28557
2621.28	4.30369
2624	4.31126
2626.72	4.42879
2629.44	4.57574
2632.15	4.93643
2634.87	5.12295
2637.59	4.85288
2640.3	5.27369
2643.02	6.10751
2645.73	6.12268
2648.44	6.52333
2651.15	6.68378
2653.86	6.95958
2656.57	7.05479
2659.28	6.03239
2661.99	5.31628
2664.69	5.12069
2667.4	4.70314
2670.1	5.02296
2672.81	4.69665
2675.51	5.07015
2678.21	5.00464
2680.91	4.0705
2683.61	4.11145
2686.31	4.0954
2689	4.66746
2691.7	4.62997
2694.4	4.9839
2697.09	5.99401
2699.79	6.32911
2702.48	7.04459
2705.17	7.89199
2707.86	8.34685
2710.55	8.43421
2713.24	9.05914
2715.93	9.33963
2718.62	9.18956
2721.3	8.72816
2723.99	8.10646
2726.67	7.56507
2729.35	7.61231
2732.04	7.74808
2734.72	6.60484
2737.4	6.31551
2740.08	5.11877
2742.76	4.46437
2745.43	3.30292
2748.11	3.4524
2750.79	3.05928
2753.46	1.62351
2756.14	1.27793
2758.81	1.25797
2761.48	2.16101
2764.15	1.68741
2766.82	2.38926
2769.49	2.36189
2772.16	2.15766
2774.82	1.97551
2777.49	2.30973
2780.16	2.30824
2782.82	1.74178
2785.48	2.29221
2788.15	2.16756
2790.81	1.04983
2793.47	1.257
2796.13	1.77273
2798.79	1.74771
2801.44	1.48892
2804.1	0.52108
2806.76	0.225255
2809.41	-0.633856
2812.07	-1.28323
2814.72	-1.84107
2817.37	-1.73032
2820.02	-0.894061
2822.67	0.841872
2825.32	3.48669
2827.97	5.91262
2830.62	8.67311
2833.26	11.8113
2835.91	14.6014
2838.56	19.2186
2841.2	24.4542
2843.84	30.0743
2846.48	36.926
2849.12	44.8812
2851.77	53.1562
2854.4	61.5843
2857.04	70.3709
2859.68	79.8373
2862.32	87.7959
2864.95	95.1777
2867.59	101.018
2870.22	107.547
2872.85	113.813
2875.48	118.936
2878.11	124.396
2880.74	129.081
2883.37	134.097
2886	137.627
2888.63	142.071
2891.25	145.877
2893.88	149.961
2896.5	153.577
2899.13	157.057
2901.75	162.481
2904.37	168.633
2906.99	175.96
2909.61	184.387
2912.23	193.893
2914.85	202.79
2917.46	210.941
2920.08	217.6
2922.7	223.072
2925.31	227.673
2927.92	229.806
2930.54	230.511
2933.15	229.522
2935.76	227.985
2938.37	224.129
2940.98	217.363
2943.58	210.41
2946.19	202.724
2948.8	194.402
2951.4	186.669
2954.01	179.495
2956.61	170.637
2959.21	162.887
2961.81	154.496
2964.41	147.094
2967.01	139.926
2969.61	133.536
2972.21	127.682
2974.81	122.055
2977.4	114.446
2980	107.282
2982.59	99.3894
2985.18	91.5286
2987.78	83.7828
2990.37	75.5204
2992.96	67.1661
2995.55	59.9137
2998.14	53.2826
3000.73	45.142
3003.31	38.225
3005.9	31.7337
3008.48	26.9924
3011.07	21.4203
3013.65	18.1856
3016.23	14.7722
3018.81	12.1011
3021.4	9.58148
3023.97	7.60963
3026.55	5.80205
3029.13	4.33909
3031.71	3.86789
3034.28	3.85925
3036.86	3.74694
3039.43	3.23379
3042.01	4.00679
3044.58	5.07014
3047.15	5.00565
3049.72	5.3729
3052.29	6.10916
3054.86	6.71583
3057.43	7.7681
3060	8.15346
3062.56	8.07692
3065.13	7.39848
3067.69	7.2944
3070.26	6.40367
3072.82	6.4007
3075.38	5.84006
3077.94	5.44935
3080.5	4.28272
3083.06	3.50589
3085.62	2.34231
3088.18	1.54455
3090.73	1.03481
3093.29	0.780635
3095.84	1.41567
3098.4	1.21277
3100.95	1.65279
3103.5	2.914
3106.05	4.8936
3108.6	5.66064
3111.15	7.04691
3113.7	8.46736
3116.25	10.742
3118.79	12.9854
3121.34	15.1988
3123.88	17.0104
3126.43	20.2022
3128.97	22.4466
3131.51	25.4671
3134.06	28.5839
3136.6	30.9899
3139.14	32.8829
3141.67	34.2743
3144.21	35.8823
3146.75	37.6943
3149.29	39.6833