File: data/Raman/poly_smoothed/Thy_00_07_10_1x_45s_532 nm_x100_100%_600 gr_mm_01.txt
#Acq. time (s)=	45
#Accumulations=	2
#Range (cm-¹)=	200...3150
#Windows=	2
#Auto scanning=	Off
#Autofocus=	Off
#Macrospot=	Off
#AutoExposure=	Off
#Spike filter=	Multiple accum.
#Delay time (s)=	0
#Binning=	1
#Readout mode=	Signal
#DeNoise=	Off
#ICS correction=	On
#Dark correction=	Off
#Inst. Process=	Off
#Detector Gain=	Best Dynamic Range
#Detector ADC=	20 kHz
#Detector temperature (°C)=	-69.85
#Instrument=	LabRAM HR Evol
#Detector=	Synapse
#Objective=	x100
#Grating=	600 gr/mm
#ND Filter=	100%
#Laser (nm)=	532
#Hole=	100.021
#Range=	Auto
#Laser Pol.=	No
#Raman. Pol.=	No
#Laser Pol. (°)=	-0.0007625
#Raman Pol. (°)=	89.9995
#Collection=	Microscope
#StageXY=	Marzhauser
#StageZ=	Marzhauser
#X (µm)=	8989.4
#Y (µm)=	-3091.7
#Z (µm)=	-54.55
#Full time(mm:ss)=	3:18
#Project=
#Sample=
#Site=
#Title=	Thy_00_07_10_2x_45s_532 nm_x100_100%_600 gr_mm
#Remark=
#Date=	28.06.2022 10:44
#Acquired=	28.06.2022 10:44:31
#Base:Fit=	10.08.2022 10:06:44
#Base:Fit=	10.08.2022 10:07:16
#Base:Fit=	10.08.2022 10:07:25
#Base:Fit=	10.08.2022 10:07:44
#Base:Fit=	10.08.2022 10:07:56
#Base:Sub=	10.08.2022 10:08:39
#Filter:Polynom=	16.08.2022 10:26:06
#AxisType[0]=Intens
#AxisUnit[0]=Cnt
#AxisType[1]=Spectr
#AxisUnit[1]=1/cm
200.407	36.1361
204.035	32.2616
207.665	29.5603
211.291	26.3609
214.916	23.3437
218.541	20.4655
222.163	17.2474
225.785	15.7507
229.404	13.6657
233.022	11.7764
236.638	9.11232
240.255	7.08606
243.868	6.48895
247.48	4.23084
251.091	3.20522
254.702	2.29044
258.31	2.07547
261.916	2.1419
265.521	2.6393
269.125	2.97358
272.727	4.24402
276.328	3.49231
279.927	3.75657
283.525	2.59237
287.121	4.85638
290.716	4.14839
294.31	6.49615
297.9	9.13149
301.491	10.235
305.081	10.9203
308.669	11.366
312.256	12.8561
315.839	12.7442
319.423	11.1877
323.006	10.2712
326.585	10.8982
330.165	11.5088
333.741	10.6354
337.318	7.97899
340.894	8.88957
344.466	6.67457
348.039	4.17071
351.608	5.10675
355.176	5.39501
358.745	7.45779
362.31	8.94071
365.876	9.31587
369.439	10.8775
373	13.745
376.56	15.3153
380.12	18.567
383.677	20.143
387.233	20.8688
390.787	19.9375
394.34	21.0605
397.894	22.1562
401.444	20.8659
404.993	19.1096
408.54	17.9904
412.086	17.8778
415.631	14.6438
419.174	10.2095
422.716	8.57816
426.257	7.08012
429.794	5.81196
433.332	6.39489
436.868	6.68354
440.403	7.07735
443.937	9.04759
447.468	11.0232
450.999	11.4455
454.528	13.8655
458.057	16.8996
461.582	18.649
465.107	19.6435
468.629	20.6546
472.152	19.3276
475.672	20.5594
479.192	22.4485
482.709	23.6797
486.226	24.285
489.74	25.8685
493.255	28.2488
496.767	30.4146
500.277	31.5485
503.788	31.4128
507.295	34.1043
510.801	33.8168
514.308	33.8096
517.811	34.9574
521.313	33.549
524.814	32.5386
528.313	32.6621
531.811	32.8355
535.308	30.7817
538.803	29.9514
542.297	27.2037
545.789	23.0996
549.281	18.4216
552.771	16.2468
556.259	11.9487
559.747	11.3382
563.233	10.1748
566.717	9.05054
570.2	9.60105
573.68	9.74337
577.161	9.88513
580.64	10.5138
584.118	10.8604
587.593	9.18697
591.068	7.52281
594.54	6.69175
598.013	5.7319
601.484	6.26737
604.952	4.72787
608.421	5.75389
611.886	6.79731
615.35	6.80559
618.815	7.1632
622.276	6.23225
625.738	5.34402
629.197	4.33283
632.655	5.02689
636.113	5.55658
639.568	6.57015
643.021	8.62003
646.473	10.7386
649.924	11.9482
653.376	13.3538
656.824	14.5728
660.271	15.8995
663.716	18.9451
667.161	20.7346
670.604	22.8245
674.045	23.6108
677.486	25.1765
680.925	29.5489
684.361	31.9783
687.797	36.2826
691.232	39.019
694.666	41.5761
698.099	42.9993
701.528	43.9033
704.958	41.269
708.387	41.0452
711.814	42.1796
715.238	43.084
718.663	45.4808
722.084	47.2296
725.506	49.8106
728.925	52.1143
732.345	54.3277
735.761	55.5056
739.178	58.1634
742.592	62.8518
746.006	66.883
749.417	72.5273
752.827	76.7156
756.236	82.9883
759.645	85.5475
763.051	90.8224
766.456	93.8383
769.859	95.6383
773.261	95.1314
776.664	95.0114
780.064	92.6317
783.462	88.352
786.859	84.4035
790.255	83.4642
793.649	80.2297
797.042	76.6037
800.434	75.0659
803.823	71.1778
807.212	67.9516
810.6	65.6082
813.987	63.9625
817.372	63.6928
820.754	64.143
824.137	66.7661
827.519	67.4371
830.897	68.6047
834.276	70.5685
837.654	69.5015
841.029	70.2973
844.404	72.3485
847.776	73.5264
851.149	72.9457
854.519	70.9791
857.889	68.2237
861.256	65.2417
864.622	60.6613
867.988	57.6692
871.351	56.8696
874.713	52.3224
878.074	48.1225
881.435	44.8166
884.794	41.8338
888.15	38.4577
891.506	38.7536
894.861	38.5705
898.214	38.3005
901.566	38.0025
904.916	38.726
908.266	39.7482
911.614	40.2776
914.961	41.4552
918.306	41.3623
921.651	42.4813
924.994	44.6282
928.336	43.9626
931.674	44.9389
935.014	42.9251
938.352	40.4674
941.687	38.2425
945.022	36.8125
948.357	36.4347
951.688	34.0474
955.02	31.7836
958.348	28.8019
961.678	23.6704
965.004	23.0309
968.331	22.8327
971.655	23.3872
974.979	24.3173
978.3	22.8039
981.62	22.5415
984.941	22.5001
988.259	21.8292
991.575	21.575
994.89	22.1956
998.204	23.4159
1001.52	25.8533
1004.83	28.8894
1008.14	32.2214
1011.45	34.3209
1014.76	38.3228
1018.06	37.8459
1021.37	39.2284
1024.67	41.215
1027.97	43.0531
1031.27	42.3765
1034.57	41.3242
1037.87	39.1664
1041.17	36.1679
1044.47	35.5073
1047.76	35.5836
1051.06	32.4826
1054.35	31.341
1057.64	28.1811
1060.93	25.4501
1064.22	24.2872
1067.5	21.767
1070.79	20.2735
1074.08	21.4194
1077.36	23.402
1080.64	22.2824
1083.92	23.5055
1087.2	24.4825
1090.48	25.4104
1093.76	26.6103
1097.03	28.9074
1100.31	29.7753
1103.58	31.465
1106.85	31.4255
1110.12	29.9368
1113.39	29.034
1116.66	27.0326
1119.93	25.3937
1123.19	23.8773
1126.46	23.7291
1129.72	23.2651
1132.98	23.6458
1136.24	22.4793
1139.5	22.0639
1142.76	21.4192
1146.01	21.9233
1149.27	20.7612
1152.53	20.6559
1155.78	19.57
1159.03	18.2641
1162.28	15.002
1165.53	14.1953
1168.78	14.618
1172.02	13.3037
1175.27	12.0374
1178.51	11.8282
1181.76	11.1048
1185	9.92516
1188.24	9.05207
1191.48	9.55029
1194.71	8.56055
1197.95	9.71821
1201.19	11.4907
1204.42	13.8106
1207.65	16.4148
1210.88	18.555
1214.12	20.152
1217.35	24.9155
1220.57	29.3406
1223.8	32.4678
1227.03	36.4943
1230.25	39.2578
1233.47	41.7699
1236.69	41.848
1239.92	42.9536
1243.13	42.4692
1246.35	45.055
1249.57	44.005
1252.78	43.7784
1256	44.2887
1259.21	44.2312
1262.42	43.0558
1265.63	44.4323
1268.84	42.8998
1272.05	43.1745
1275.26	44.3968
1278.46	44.6602
1281.67	46.9141
1284.87	50.3448
1288.07	53.3898
1291.27	57.4432
1294.47	62.5435
1297.67	69.5354
1300.87	75.987
1304.06	80.2453
1307.26	86.4182
1310.45	91.3258
1313.64	95.5729
1316.83	98.6742
1320.02	102.851
1323.21	105.683
1326.4	106.772
1329.59	106.747
1332.77	107.874
1335.95	108.138
1339.14	106.547
1342.32	104.239
1345.5	103.156
1348.67	100.351
1351.85	97.5743
1355.03	95.0836
1358.2	92.3594
1361.38	90.7078
1364.55	88.0544
1367.72	87.1469
1370.89	85.2052
1374.06	84.5729
1377.23	83.6486
1380.39	80.6339
1383.56	77.9913
1386.72	76.8488
1389.89	74.9132
1393.05	72.3745
1396.21	70.8786
1399.37	69.1229
1402.52	66.2982
1405.68	65.4678
1408.84	67.3251
1411.99	67.4105
1415.15	68.2814
1418.3	68.1701
1421.45	70.5953
1424.6	74.6318
1427.75	76.6632
1430.89	79.6711
1434.04	83.2424
1437.18	85.0948
1440.33	89.6356
1443.47	92.932
1446.61	95.4805
1449.75	95.9638
1452.89	94.2758
1456.03	92.1976
1459.16	89.3981
1462.3	84.6502
1465.43	81.9992
1468.56	77.3373
1471.7	70.6159
1474.83	66.2813
1477.96	60.2075
1481.08	55.1346
1484.21	50.8336
1487.34	46.0579
1490.46	40.8371
1493.58	36.3793
1496.71	32.8502
1499.83	30.299
1502.95	29.6955
1506.07	28.3874
1509.18	27.3599
1512.3	28.103
1515.41	28.5225
1518.53	29.5835
1521.64	31.0118
1524.75	32.3898
1527.86	34.7287
1530.97	37.3933
1534.08	38.6566
1537.19	40.7385
1540.29	43.4952
1543.4	47.0423
1546.5	51.5266
1549.6	54.6513
1552.7	58.9095
1555.8	63.6441
1558.9	69.1637
1562	73.8959
1565.09	77.1684
1568.19	79.4469
1571.28	85.0034
1574.37	90.5722
1577.47	97.2569
1580.56	103.258
1583.64	105.374
1586.73	108.27
1589.82	111.411
1592.9	114.111
1595.99	113.588
1599.07	113.896
1602.15	111.89
1605.23	109.637
1608.31	106.644
1611.39	103.589
1614.47	98.9143
1617.55	94.6928
1620.62	89.7564
1623.7	84.7938
1626.77	81.3756
1629.84	77.9341
1632.91	74.2059
1635.98	69.9961
1639.05	66.6226
1642.11	63.9377
1645.18	63.0648
1648.24	64.5901
1651.31	64.9113
1654.37	63.6324
1657.43	62.1727
1660.49	60.6322
1663.55	60.2977
1666.61	57.144
1669.66	54.8236
1672.72	52.3997
1675.77	50.7832
1678.83	48.3576
1681.88	46.005
1684.93	42.8926
1687.98	38.2205
1691.03	34.268
1694.07	30.2459
1697.12	25.2634
1700.17	22.0217
1703.21	18.8254
1706.25	15.2528
1709.29	12.057
1712.33	9.94036
1715.37	7.53875
1718.41	5.05025
1721.45	4.37141
1724.49	2.92424
1727.52	1.30433
1730.55	1.2223
1733.59	1.43899
1736.62	1.76682
1739.65	2.9058
1742.68	4.13954
1745.7	5.97498
1748.73	5.95343
1751.76	6.28889
1754.78	6.7588
1757.8	7.06734
1760.83	5.72828
1763.85	5.09995
1766.87	4.37611
1769.89	3.72471
1772.9	4.14266
1775.92	3.58444
1778.94	3.10698
1781.95	3.17687
1784.96	3.11149
1787.97	3.07174
1790.99	3.37004
1794	3.2298
1797	2.94692
1800.01	2.71406
1803.02	3.24073
1806.02	3.74568
1809.03	4.49832
1812.03	5.09904
1815.03	5.39762
1818.03	5.83777
1821.03	5.41329
1824.03	5.67908
1827.03	5.87961
1830.02	7.04681
1833.02	5.71901
1836.01	4.88865
1839.01	4.74605
1842	4.59333
1844.99	3.73954
1847.98	4.32917
1850.97	3.67922
1853.95	4.64785
1856.94	5.04276
1859.93	5.60708
1862.91	6.06225
1865.89	7.29983
1868.87	7.43237
1871.85	7.95428
1874.83	6.97917
1877.81	6.86276
1880.79	7.62098
1882.52	7.10401
1885.51	6.98473
1888.5	6.29903
1891.49	5.95347
1894.47	5.49287
1897.46	5.2695
1900.44	5.32908
1903.42	4.22644
1906.4	2.59757
1909.38	2.80421
1912.36	2.09631
1915.34	1.84412
1918.32	2.32436
1921.29	3.38098
1924.27	3.19541
1927.24	3.17194
1930.21	4.07054
1933.18	3.59959
1936.15	4.21056
1939.12	4.61547
1942.09	4.81301
1945.06	4.62662
1948.02	4.35028
1950.99	5.48226
1953.95	5.04789
1956.91	4.71711
1959.88	4.35495
1962.84	3.51853
1965.8	3.78354
1968.75	3.27299
1971.71	4.15795
1974.67	5.00635
1977.62	6.10074
1980.58	6.88828
1983.53	7.18784
1986.48	7.46235
1989.43	8.61981
1992.38	9.40708
1995.33	8.44979
1998.27	7.93552
2001.22	8.78656
2004.16	8.94625
2007.11	9.19396
2010.05	9.32473
2012.99	10.3249
2015.93	10.9267
2018.87	10.8993
2021.81	10.4861
2024.75	9.64503
2027.69	8.68361
2030.62	7.38257
2033.56	5.92677
2036.49	4.56569
2039.42	3.93359
2042.35	5.23469
2045.28	5.28014
2048.21	5.02817
2051.14	5.33034
2054.07	4.71098
2056.99	4.95543
2059.92	4.35773
2062.84	3.7034
2065.76	2.90431
2068.68	3.75132
2071.6	3.71911
2074.52	3.68532
2077.44	4.05328
2080.36	5.06463
2083.27	5.02051
2086.19	4.82968
2089.1	5.30433
2092.02	5.13777
2094.93	5.70338
2097.84	6.47226
2100.75	5.24738
2103.66	6.23457
2106.56	5.19276
2109.47	5.34668
2112.38	6.89721
2115.28	8.42259
2118.18	7.74301
2121.09	9.05179
2123.99	9.14716
2126.89	8.68881
2129.79	8.35094
2132.68	8.16562
2135.58	7.98383
2138.48	8.04151
2141.37	8.09292
2144.27	7.3618
2147.16	7.60792
2150.05	7.15194
2152.94	6.7018
2155.83	5.79142
2158.72	6.34413
2161.6	6.08255
2164.49	5.53306
2167.38	6.04283
2170.26	5.1429
2173.14	5.52583
2176.03	5.26704
2178.91	4.99418
2181.79	4.98208
2184.67	6.15745
2187.54	6.88937
2190.42	7.62236
2193.3	7.48636
2196.17	7.93424
2199.05	8.5682
2201.92	8.69324
2204.79	9.13251
2207.66	8.08751
2210.53	8.32903
2213.4	7.93808
2216.27	7.1432
2219.13	5.71284
2222	3.84251
2224.86	3.55667
2227.72	3.58663
2230.59	2.94002
2233.45	1.76142
2236.31	1.89571
2239.17	2.42097
2242.03	3.1252
2244.88	2.10534
2247.74	2.37761
2250.59	2.8903
2253.45	4.76312
2256.3	6.24852
2259.15	7.68983
2262	8.56823
2264.85	9.06323
2267.7	9.91141
2270.55	10.5347
2273.4	10.2611
2276.24	11.177
2279.09	10.9589
2281.93	10.4977
2284.77	8.5183
2287.62	8.40219
2290.46	8.016
2293.3	6.51941
2296.13	7.45865
2298.97	7.35274
2301.81	6.96016
2304.64	7.0712
2307.48	7.29891
2310.31	7.40282
2313.14	7.51627
2315.98	6.79576
2318.81	8.61924
2321.64	9.66383
2324.46	9.45832
2327.29	8.66453
2330.12	7.72734
2332.94	8.35916
2335.77	8.14662
2338.59	8.66412
2341.41	8.14805
2344.23	7.64916
2347.05	6.31554
2349.87	4.79385
2352.69	2.95613
2355.51	2.0573
2358.32	1.26418
2361.14	0.0268775
2363.95	0.904169
2366.76	0.37803
2369.58	0.701807
2372.39	-0.227777
2375.2	-0.207281
2378	-0.0726581
2380.81	-0.143349
2383.62	0.23173
2386.43	0.0927435
2389.23	0.0120735
2392.03	-1.01148
2394.84	-0.944362
2397.64	-0.513554
2400.44	0.311266
2403.24	1.13421
2406.04	2.25363
2408.84	3.08722
2411.63	3.95235
2414.43	3.75406
2417.22	4.39437
2420.02	5.10853
2422.81	5.49382
2425.6	6.85872
2428.39	6.8911
2431.18	7.53283
2433.97	8.07353
2436.76	6.96513
2439.54	7.00164
2442.33	7.21998
2445.12	7.47917
2447.9	6.6756
2450.68	7.27542
2453.46	6.06211
2456.24	5.68969
2459.02	4.66637
2461.8	3.90132
2464.58	4.33798
2467.36	4.12456
2470.13	4.22168
2472.91	4.10045
2475.68	3.75528
2478.45	4.80232
2481.23	5.12444
2484	6.64578
2486.77	6.37586
2489.54	6.88314
2492.3	7.15439
2495.07	6.86331
2497.84	6.50885
2500.6	5.9803
2503.36	5.18614
2506.13	4.81695
2508.89	6.63677
2511.65	5.98296
2514.41	6.39795
2517.17	5.81557
2519.93	5.3314
2522.68	5.49895
2525.44	6.55334
2528.19	6.37857
2530.95	6.35712
2533.7	7.11097
2536.45	7.20395
2539.2	7.02661
2541.95	6.52861
2544.7	6.72847
2547.45	7.7822
2550.2	7.61257
2552.94	7.55099
2555.69	7.31174
2558.43	7.54126
2561.18	6.19829
2563.92	5.72012
2566.66	6.1753
2569.4	5.8527
2572.14	5.14531
2574.88	6.03978
2577.61	5.29499
2580.35	4.48084
2583.09	3.71686
2585.82	4.44971
2588.55	4.39857
2591.29	6.51269
2594.02	7.97007
2596.75	8.11038
2599.48	8.71106
2602.21	8.92028
2604.93	8.50871
2607.66	8.14941
2610.39	6.67616
2613.11	6.84645
2615.83	7.02245
2618.56	5.59252
2621.28	5.17117
2624	4.2915
2626.72	3.58719
2629.44	2.40257
2632.15	2.56318
2634.87	2.25429
2637.59	2.30496
2640.3	1.92095
2643.02	3.10132
2645.73	3.74967
2648.44	3.94092
2651.15	5.21609
2653.86	6.86646
2656.57	9.74897
2659.28	11.7748
2661.99	12.3333
2664.69	12.9546
2667.4	13.8437
2670.1	13.232
2672.81	12.5945
2675.51	12.5405
2678.21	12.3237
2680.91	12.903
2683.61	12.2175
2686.31	11.4476
2689	10.7175
2691.7	11.015
2694.4	10.0094
2697.09	11.3434
2699.79	11.7619
2702.48	12.5218
2705.17	13.5456
2707.86	12.4783
2710.55	13.7507
2713.24	13.0479
2715.93	14.287
2718.62	15.7213
2721.3	16.2499
2723.99	17.2405
2726.67	16.4546
2729.35	16.5714
2732.04	15.7943
2734.72	15.6068
2737.4	14.6696
2740.08	13.5852
2742.76	13.5353
2745.43	12.9531
2748.11	13.0393
2750.79	13.1098
2753.46	11.8881
2756.14	11.0678
2758.81	11.4736
2761.48	11.1761
2764.15	10.9094
2766.82	10.3967
2769.49	8.5294
2772.16	7.40758
2774.82	6.85831
2777.49	6.23347
2780.16	6.18397
2782.82	6.45165
2785.48	5.49771
2788.15	5.66023
2790.81	4.784
2793.47	3.00368
2796.13	2.0511
2798.79	3.10948
2801.44	3.21534
2804.1	3.1504
2806.76	3.5939
2809.41	4.33403
2812.07	5.19146
2814.72	6.94869
2817.37	7.71737
2820.02	8.77721
2822.67	10.4831
2825.32	13.5484
2827.97	15.9239
2830.62	18.4352
2833.26	21.8271
2835.91	24.9907
2838.56	28.8002
2841.2	33.3314
2843.84	38.3745
2846.48	44.231
2849.12	50.1987
2851.77	55.868
2854.4	62.5416
2857.04	68.8203
2859.68	76.0573
2862.32	83.6762
2864.95	90.9634
2867.59	97.5384
2870.22	104.173
2872.85	111.477
2875.48	117.504
2878.11	122.779
2880.74	128.618
2883.37	134.133
2886	139.855
2888.63	145.322
2891.25	150.737
2893.88	157.778
2896.5	163.209
2899.13	169.297
2901.75	176.333
2904.37	182.844
2906.99	189.247
2909.61	196.606
2912.23	204.334
2914.85	211.067
2917.46	217.259
2920.08	221.457
2922.7	224.678
2925.31	226.175
2927.92	226.936
2930.54	226.134
2933.15	224.076
2935.76	220.68
2938.37	215.571
2940.98	209.345
2943.58	202.469
2946.19	196.263
2948.8	189.385
2951.4	182.436
2954.01	176.242
2956.61	170.161
2959.21	164.929
2961.81	157.722
2964.41	151.845
2967.01	145.636
2969.61	139.798
2972.21	133.755
2974.81	128.099
2977.4	121.606
2980	116.324
2982.59	107.757
2985.18	99.7587
2987.78	91.311
2990.37	82.1318
2992.96	74.1404
2995.55	65.8662
2998.14	56.8828
3000.73	47.7114
3003.31	40.3987
3005.9	32.8079
3008.48	26.7976
3011.07	21.9458
3013.65	16.4236
3016.23	12.695
3018.81	9.61249
3021.4	6.20483
3023.97	2.849
3026.55	0.365341
3029.13	-1.80577
3031.71	-2.53648
3034.28	-2.29056
3036.86	-1.00323
3039.43	0.653561
3042.01	2.72856
3044.58	3.29346
3047.15	4.53967
3049.72	6.08163
3052.29	6.8503
3054.86	7.69
3057.43	7.86126
3060	7.95033
3062.56	8.24944
3065.13	8.15929
3067.69	8.91757
3070.26	8.6337
3072.82	8.11989
3075.38	7.81113
3077.94	6.57203
3080.5	5.47218
3083.06	4.18734
3085.62	2.6517
3088.18	1.35627
3090.73	0.397201
3093.29	1.11667
3095.84	1.80868
3098.4	2.94506
3100.95	3.13541
3103.5	3.50351
3106.05	4.37398
3108.6	4.41358
3111.15	6.13108
3113.7	6.73058
3116.25	7.39901
3118.79	8.5187
3121.34	9.78279
3123.88	12.1191
3126.43	14.4998
3128.97	16.1107
3131.51	18.0164
3134.06	19.9387
3136.6	21.5368
3139.14	23.2775
3141.67	25.2189
3144.21	27.1551
3146.75	29.5005
3149.29	30.9714