File: data/Raman/poly_smoothed/Thy_30_10_09_1x_45s_532 nm_x100_100%_600 gr_mm_01.txt
#Acq. time (s)=	45
#Accumulations=	2
#Range (cm-¹)=	200...3150
#Windows=	2
#Auto scanning=	Off
#Autofocus=	Off
#Macrospot=	Off
#AutoExposure=	Off
#Spike filter=	Multiple accum.
#Delay time (s)=	0
#Binning=	1
#Readout mode=	Signal
#DeNoise=	Off
#ICS correction=	On
#Dark correction=	Off
#Inst. Process=	Off
#Detector Gain=	Best Dynamic Range
#Detector ADC=	20 kHz
#Detector temperature (°C)=	-69.85
#Instrument=	LabRAM HR Evol
#Detector=	Synapse
#Objective=	x100
#Grating=	600 gr/mm
#ND Filter=	100%
#Laser (nm)=	532
#Hole=	100.021
#Range=	Auto
#Laser Pol.=	No
#Raman. Pol.=	No
#Laser Pol. (°)=	-0.0007625
#Raman Pol. (°)=	89.9995
#Collection=	Microscope
#StageXY=	Marzhauser
#StageZ=	Marzhauser
#X (µm)=	4745.8
#Y (µm)=	-7740.5
#Z (µm)=	584.6
#Full time(mm:ss)=	3:18
#Project=
#Sample=
#Site=
#Title=	Thy_30_10_09_2x_45s_532 nm_x100_100%_600 gr_mm
#Remark=
#Date=	30.06.2022 12:00
#Acquired=	30.06.2022 12:00:09
#Base:Fit=	10.08.2022 09:58:11
#Base:Sub=	10.08.2022 09:58:44
#Filter:Polynom=	16.08.2022 10:22:53
#AxisType[0]=Intens
#AxisUnit[0]=Cnt
#AxisType[1]=Spectr
#AxisUnit[1]=1/cm
200.533	16.8272
204.162	18.286
207.792	17.6892
211.418	16.0557
215.044	13.2209
218.667	10.9885
222.289	9.34989
225.912	7.18667
229.531	7.30527
233.148	8.37288
236.766	9.49447
240.381	8.65319
243.994	9.07951
247.606	9.41093
251.217	9.47114
254.828	11.1797
258.436	9.28514
262.042	8.52674
265.647	10.4622
269.25	11.1899
272.852	12.7066
276.453	13.946
280.052	14.788
283.65	16.7313
287.247	15.4641
290.842	15.2518
294.436	15.1483
298.028	14.4544
301.617	14.495
305.206	14.3175
308.794	13.8876
312.381	14.7229
315.964	16.1227
319.548	18.694
323.131	19.1569
326.71	18.6877
330.29	19.6783
333.868	20.4253
337.443	20.6894
341.018	19.4333
344.591	17.8757
348.163	16.6458
351.733	16.8647
355.303	17.2778
358.869	15.0992
362.435	14.7173
366.001	15.447
369.563	15.2274
373.124	13.1299
376.686	12.7279
380.244	11.1209
383.801	9.82594
387.357	9.93885
390.911	9.30467
394.466	7.53096
398.018	7.94127
401.568	7.43763
405.117	7.67335
408.664	7.60244
412.21	6.83077
415.755	6.98963
419.298	7.82944
422.84	6.5463
426.38	5.79051
429.919	6.74282
433.455	6.93273
436.992	9.31793
440.527	10.1288
444.06	10.2041
447.593	11.2255
451.122	12.7117
454.651	13.842
458.18	13.7586
461.705	15.7138
465.23	15.5103
468.752	15.4275
472.275	16.3339
475.797	16.6489
479.315	15.9275
482.834	16.5469
486.349	16.4511
489.863	16.6359
493.378	16.4753
496.889	15.7445
500.401	14.5102
503.91	14.8777
507.417	14.4841
510.923	14.8338
514.43	14.993
517.933	15.0874
521.435	15.4562
524.936	16.3213
528.435	15.0803
531.933	13.9695
535.43	13.0446
538.927	12.5164
542.421	12.2312
545.913	12.7243
549.403	12.1252
552.893	11.032
556.381	10.5531
559.868	9.99428
563.354	10.1811
566.839	9.38217
570.322	8.64122
573.802	7.36088
577.283	6.16316
580.762	4.70875
584.24	5.35467
587.714	4.545
591.19	3.53669
594.663	2.7997
598.134	2.9516
601.605	2.99731
605.073	3.6199
608.542	3.01039
612.007	2.88842
615.473	2.1949
618.936	3.55063
622.397	4.92128
625.859	6.1683
629.318	7.19204
632.775	8.75791
636.233	11.1895
639.688	11.7599
643.142	13.646
646.594	15.7667
650.045	16.231
653.496	18.0072
656.944	20.1879
660.391	21.6182
663.837	22.0732
667.281	22.7588
670.724	22.3601
674.166	23.1487
677.606	25.0761
681.045	27.6099
684.483	29.5597
687.917	30.1318
691.352	30.0405
694.786	30.9266
698.219	32.827
701.65	34.5895
705.078	35.9448
708.506	36.453
711.934	36.8696
715.358	38.0588
718.782	39.1194
722.204	40.626
725.626	41.322
729.045	42.4134
732.464	43.7369
735.881	45.4005
739.297	47.8011
742.711	46.4619
746.125	49.0027
749.537	50.5977
752.946	52.8409
756.357	55.1479
759.764	58.0163
763.17	61.5249
766.575	63.434
769.978	65.7486
773.382	65.9726
776.783	68.5483
780.182	72.4144
783.581	73.4636
786.978	74.0632
790.373	74.1305
793.768	75.8394
797.161	78.0384
800.552	78.3786
803.941	77.9065
807.33	78.13
810.718	77.0465
814.105	77.9608
817.49	77.9294
820.873	76.6207
824.256	76.4757
827.637	76.5299
831.016	76.3517
834.395	75.6276
837.772	74.5025
841.147	72.7105
844.522	70.7063
847.894	69.8627
851.267	67.8869
854.637	66.2964
858.007	64.2051
861.374	63.0354
864.739	61.4177
868.106	59.2756
871.469	57.7842
874.831	57.3105
878.193	57.0817
881.553	56.5113
884.911	55.0366
888.268	54.4521
891.623	53.2254
894.978	53.1727
898.331	52.5719
901.683	51.8283
905.033	50.3849
908.383	52.2734
911.731	50.6794
915.078	49.6085
918.423	48.1457
921.768	46.505
925.111	46.0002
928.452	44.902
931.791	43.3992
935.13	42.3421
938.468	39.8744
941.803	38.539
945.139	36.6715
948.473	35.7353
951.804	34.8263
955.136	34.4899
958.465	33.482
961.794	32.2839
965.12	32.3446
968.447	32.0548
971.771	31.4858
975.095	31.6856
978.417	30.7225
981.737	30.6662
985.057	29.649
988.375	30.8592
991.691	31.1166
995.006	31.0982
998.32	30.4145
1001.63	31.2358
1004.95	32.2776
1008.26	30.7905
1011.56	29.5052
1014.87	28.9101
1018.18	29.5203
1021.48	28.695
1024.79	28.1279
1028.09	27.152
1031.39	27.4327
1034.69	25.3351
1037.99	23.6528
1041.29	21.6634
1044.58	21.5744
1047.88	20.9424
1051.17	20.575
1054.46	20.7439
1057.75	20.5442
1061.04	19.2014
1064.33	19.0322
1067.62	18.5005
1070.9	19.0758
1074.19	19.8374
1077.47	20.7664
1080.76	19.8818
1084.04	20.1633
1087.32	18.8046
1090.59	17.8032
1093.87	17.394
1097.15	18.0611
1100.42	18.2842
1103.69	16.3396
1106.97	15.7117
1110.24	15.1932
1113.51	14.5137
1116.77	12.1179
1120.04	11.4377
1123.31	9.7557
1126.57	9.77512
1129.83	9.68014
1133.1	10.0427
1136.36	10.9157
1139.62	10.5855
1142.87	10.6439
1146.13	11.2345
1149.38	11.4416
1152.64	12.815
1155.89	12.6444
1159.14	11.364
1162.39	9.08077
1165.64	7.40529
1168.89	7.26475
1172.14	7.31147
1175.38	7.35756
1178.63	7.51504
1181.87	7.45416
1185.11	7.30272
1188.35	7.66536
1191.59	7.74753
1194.83	6.95095
1198.07	7.02008
1201.3	7.41524
1204.53	9.83526
1207.77	12.6098
1211	15.108
1214.23	18.391
1217.46	20.9974
1220.69	24.0936
1223.91	25.5301
1227.14	28.0936
1230.36	31.565
1233.59	33.1733
1236.81	33.8118
1240.03	35.7829
1243.25	37.0019
1246.46	38.9377
1249.68	40.7451
1252.9	42.0618
1256.11	42.1408
1259.32	43.3796
1262.54	44.2289
1265.75	46.059
1268.96	47.7869
1272.16	46.1604
1275.37	46.8397
1278.57	48.0375
1281.78	50.4657
1284.98	52.7425
1288.18	55.0216
1291.38	56.3521
1294.58	56.8276
1297.78	58.6789
1300.98	57.8913
1304.17	58.4676
1307.37	60.0981
1310.56	60.0669
1313.76	60.839
1316.95	60.4156
1320.14	60.8935
1323.32	61.6505
1326.51	60.4704
1329.7	59.7817
1332.88	58.6149
1336.07	57.5303
1339.25	55.5971
1342.43	54.65
1345.61	52.7787
1348.79	50.3109
1351.96	47.8817
1355.14	45.8406
1358.31	44.5495
1361.49	44.4595
1364.66	42.8746
1367.83	40.6166
1371	38.3096
1374.17	36.6985
1377.34	34.6831
1380.5	33.7184
1383.67	33.3326
1386.83	33.0367
1390	32.206
1393.16	31.5721
1396.32	31.3701
1399.48	31.8327
1402.64	31.3595
1405.79	30.8644
1408.95	30.3535
1412.1	31.1082
1415.26	31.5353
1418.41	33.0573
1421.56	35.4976
1424.71	38.5334
1427.86	41.561
1431	44.6073
1434.15	48.5007
1437.29	53.099
1440.44	54.8467
1443.58	56.8996
1446.72	58.0728
1449.86	59.7733
1453	59.5934
1456.14	58.739
1459.27	56.6681
1462.41	54.0834
1465.54	50.1251
1468.67	45.169
1471.81	41.8295
1474.94	37.6686
1478.07	31.1149
1481.19	27.0447
1484.32	23.4953
1487.45	20.2019
1490.57	18.0665
1493.69	15.7872
1496.82	13.9203
1499.94	12.1279
1503.06	11.4211
1506.17	10.8991
1509.29	11.9218
1512.41	12.3397
1515.52	13.4284
1518.64	13.868
1521.75	14.8523
1524.86	18.1434
1527.97	18.6206
1531.08	20.3232
1534.19	21.9541
1537.29	23.1454
1540.4	24.7335
1543.5	26.9215
1546.61	29.1747
1549.71	32.084
1552.81	34.6511
1555.91	38.384
1559.01	41.2608
1562.11	43.3368
1565.2	44.1453
1568.29	46.0247
1571.39	46.2268
1574.48	47.7462
1577.57	48.9897
1580.66	50.2213
1583.75	51.9272
1586.84	52.0958
1589.93	51.0857
1593.01	50.3143
1596.1	49.3968
1599.18	49.9685
1602.26	49.0172
1605.34	47.9895
1608.42	46.176
1611.5	44.4202
1614.58	42.3292
1617.65	42.2504
1620.73	41.9615
1623.8	42.4547
1626.87	42.8758
1629.95	43.9918
1633.02	44.8957
1636.09	45.3609
1639.15	46.4787
1642.22	48.8269
1645.29	51.2891
1648.35	52.4313
1651.42	54.4103
1654.48	54.9202
1657.54	54.6407
1660.6	52.732
1663.66	51.2668
1666.72	49.5398
1669.77	48.6723
1672.83	47.501
1675.88	44.2372
1678.93	39.5521
1681.99	36.7844
1685.04	32.5855
1688.09	29.1894
1691.13	26.9415
1694.18	23.6477
1697.23	20.274
1700.27	17.7408
1703.32	15.8674
1706.36	14.7451
1709.4	12.39
1712.44	11.448
1715.48	10.0214
1718.52	8.74751
1721.56	8.05334
1724.59	7.24107
1727.63	6.24431
1730.66	5.21746
1733.69	3.93602
1736.72	3.40961
1739.75	3.16706
1742.78	2.6447
1745.81	1.98497
1748.84	1.67679
1751.86	0.457275
1754.89	1.2764
1757.91	1.04315
1760.93	0.525342
1763.95	0.884398
1766.97	0.919364
1769.99	0.569678
1773.01	0.221275
1776.03	1.24877
1779.04	1.79824
1782.06	1.30405
1785.07	1.48103
1788.08	1.94879
1791.09	1.84431
1794.1	2.41229
1797.11	2.99649
1800.12	2.67505
1803.12	2.72976
1806.13	2.65212
1809.13	2.76175
1812.14	3.5005
1815.14	4.21799
1818.14	4.20316
1821.14	4.17431
1824.14	4.11637
1827.13	4.0548
1830.13	3.69306
1833.12	3.53542
1836.12	3.69215
1839.11	3.72387
1842.1	3.76151
1845.09	2.88675
1848.08	2.47386
1851.07	2.02525
1854.06	1.74946
1857.04	0.769512
1860.03	0.811392
1863.01	0.608289
1866	0.960776
1868.98	0.795865
1871.96	0.55998
1874.94	1.26574
1877.92	1.68076
1880.89	2.03052
1882.48	2.57163
1885.47	3.47039
1888.46	3.2564
1891.44	3.71795
1894.43	4.36589
1897.41	5.12619
1900.4	5.60347
1903.38	5.34529
1906.36	5.82483
1909.34	6.39008
1912.32	6.93424
1915.29	6.15609
1918.27	5.51702
1921.25	5.17267
1924.22	5.07902
1927.2	5.33103
1930.17	5.69647
1933.14	6.03812
1936.11	6.32402
1939.08	6.08229
1942.05	6.47886
1945.01	6.15722
1947.98	6.20353
1950.94	6.01699
1953.91	6.0562
1956.87	5.44278
1959.83	5.15176
1962.79	4.46097
1965.75	3.57633
1968.71	4.00288
1971.67	3.82185
1974.62	3.283
1977.58	3.47573
1980.53	3.99309
1983.48	4.81272
1986.43	4.85406
1989.38	5.09769
1992.33	5.36304
1995.28	5.58269
1998.23	6.04748
2001.18	6.20076
2004.12	6.07171
2007.06	6.58186
2010.01	7.53764
2012.95	8.22343
2015.89	7.05203
2018.83	7.5931
2021.77	7.48407
2024.71	6.63053
2027.64	6.72798
2030.58	6.47292
2033.51	6.87463
2036.45	6.84013
2039.38	7.67138
2042.31	9.01416
2045.24	9.84487
2048.17	10.4598
2051.1	11.8495
2054.02	12.8044
2056.95	13.0127
2059.87	12.9792
2062.8	12.7489
2065.72	12.0336
2068.64	11.7047
2071.56	12.2121
2074.48	12.4311
2077.4	12.9214
2080.31	13.3828
2083.23	13.1639
2086.14	12.2088
2089.06	12.7788
2091.97	12.5471
2094.88	11.706
2097.79	13.01
2100.7	12.6255
2103.61	13.1313
2106.52	13.927
2109.43	14.7795
2112.33	16.2584
2115.24	18.1998
2118.14	19.7795
2121.04	22.5297
2123.94	24.5215
2126.84	25.4995
2129.74	27.117
2132.64	29.5006
2135.54	31.3574
2138.43	33.6749
2141.33	35.9411
2144.22	39.5004
2147.11	41.8122
2150.01	44.356
2152.9	46.8382
2155.79	48.2307
2158.67	49.3891
2161.56	50.8421
2164.45	50.8526
2167.33	51.2763
2170.22	50.6262
2173.1	50.733
2175.98	50.6231
2178.86	50.0589
2181.74	48.7033
2184.62	48.5338
2187.5	47.8852
2190.38	46.9049
2193.25	45.4525
2196.13	44.2218
2199	41.8872
2201.88	40.5194
2204.75	39.1796
2207.62	37.0421
2210.49	35.1219
2213.36	35.1812
2216.22	34.1993
2219.09	33.2828
2221.96	33.0478
2224.82	31.9779
2227.68	30.6864
2230.55	29.398
2233.41	27.6666
2236.27	26.8836
2239.12	26.0592
2241.98	25.2216
2244.84	24.8454
2247.7	22.8393
2250.55	20.7848
2253.41	19.4948
2256.26	18.7717
2259.11	17.3608
2261.96	16.687
2264.81	15.3866
2267.66	14.7343
2270.51	13.5901
2273.35	13.2312
2276.2	12.5865
2279.04	12.5351
2281.89	12.6179
2284.73	13.4013
2287.57	13.2602
2290.41	12.313
2293.25	11.0364
2296.09	11.25
2298.93	11.079
2301.76	11.9159
2304.6	12.7794
2307.44	12.6049
2310.27	13.0114
2313.1	11.7954
2315.93	11.3343
2318.76	10.5374
2321.59	9.84568
2324.42	9.1951
2327.25	8.68557
2330.07	8.84376
2332.9	8.44927
2335.72	7.78687
2338.55	7.334
2341.37	7.38273
2344.19	6.64236
2347.01	5.99174
2349.83	5.33053
2352.65	5.13195
2355.46	4.90865
2358.28	3.20593
2361.09	2.88701
2363.91	3.70209
2366.72	4.51072
2369.53	4.88301
2372.34	5.64478
2375.15	5.37663
2377.96	4.52818
2380.77	4.19985
2383.58	4.00469
2386.38	4.14111
2389.19	4.16484
2391.99	3.69136
2394.8	2.55286
2397.6	2.54855
2400.4	1.8869
2403.2	1.85052
2406	1.54815
2408.79	2.25681
2411.59	2.7983
2414.39	2.95328
2417.18	4.00163
2419.98	4.75665
2422.77	6.09362
2425.56	6.71711
2428.35	7.04706
2431.14	8.67279
2433.93	8.59493
2436.72	8.27726
2439.5	7.92037
2442.29	8.16709
2445.07	7.164
2447.86	6.93493
2450.64	7.08839
2453.42	7.18181
2456.2	6.02808
2458.98	4.58569
2461.76	3.50003
2464.54	2.04291
2467.32	1.67124
2470.09	1.77004
2472.87	1.61255
2475.64	1.53093
2478.41	2.14411
2481.18	1.93874
2483.95	2.74946
2486.72	2.22316
2489.49	2.03035
2492.26	2.78956
2495.03	2.71732
2497.79	2.7845
2500.56	2.85002
2503.32	1.63962
2506.09	1.35653
2508.85	1.4977
2511.61	1.59845
2514.37	1.43073
2517.13	1.1296
2519.89	0.371049
2522.64	0.731094
2525.4	0.469435
2528.15	-0.0328595
2530.91	0.796582
2533.66	1.34466
2536.41	1.87832
2539.16	2.5688
2541.91	2.57535
2544.66	2.95978
2547.41	2.80307
2550.16	2.78469
2552.9	3.32998
2555.65	3.513
2558.39	4.14926
2561.13	3.65356
2563.88	4.22403
2566.62	4.33029
2569.36	3.92438
2572.1	3.26739
2574.84	3.20735
2577.57	2.71085
2580.31	2.87382
2583.05	1.55039
2585.78	1.22262
2588.51	1.12047
2591.24	2.00614
2593.98	1.55505
2596.71	1.82921
2599.44	1.11499
2602.16	1.44153
2604.89	1.21298
2607.62	1.4771
2610.34	1.5311
2613.07	1.29829
2615.79	0.395093
2618.52	0.525194
2621.24	0.608767
2623.96	0.367503
2626.68	0.153683
2629.4	0.892059
2632.11	0.837086
2634.83	1.06545
2637.55	1.55796
2640.26	1.72311
2642.98	0.904196
2645.69	0.866697
2648.4	1.64826
2651.11	1.79557
2653.82	2.29524
2656.53	2.44497
2659.24	2.84507
2661.95	2.55598
2664.65	3.46227
2667.36	4.17785
2670.06	5.04198
2672.76	5.10516
2675.47	4.66005
2678.17	4.28122
2680.87	3.65404
2683.57	3.67205
2686.27	3.77264
2688.97	3.82264
2691.66	4.17257
2694.36	4.37482
2697.05	4.52001
2699.75	4.22834
2702.44	4.7541
2705.13	4.86116
2707.82	4.16092
2710.51	4.33689
2713.2	5.33825
2715.89	5.46188
2718.57	5.15253
2721.26	5.2399
2723.95	5.62764
2726.63	4.8782
2729.31	5.00957
2732	5.17231
2734.68	5.06517
2737.36	4.105
2740.04	3.67991
2742.72	3.36904
2745.39	3.18475
2748.07	2.79757
2750.75	2.73961
2753.42	3.05342
2756.09	2.53182
2758.77	3.35756
2761.44	2.62352
2764.11	2.90737
2766.78	3.47494
2769.45	2.98674
2772.12	2.03553
2774.78	2.15086
2777.45	2.13433
2780.12	2.19644
2782.78	2.04731
2785.44	2.29414
2788.11	2.80887
2790.77	1.60911
2793.43	1.86298
2796.09	2.23486
2798.75	2.50991
2801.4	2.06278
2804.06	1.74766
2806.72	2.1936
2809.37	2.78052
2812.03	2.29211
2814.68	2.76977
2817.33	3.66603
2819.98	4.53131
2822.63	6.52626
2825.28	8.00332
2827.93	9.0819
2830.58	10.7116
2833.23	12.2596
2835.87	14.0934
2838.52	16.7815
2841.16	19.656
2843.8	22.507
2846.44	26.3681
2849.08	30.6676
2851.73	34.6945
2854.36	38.6681
2857	42.9448
2859.64	47.2945
2862.28	52.2355
2864.91	56.0816
2867.55	60.3461
2870.18	65.1751
2872.81	68.9922
2875.44	72.4263
2878.07	76.3312
2880.7	79.5102
2883.33	83.5059
2885.96	86.3102
2888.59	88.7842
2891.21	92.1801
2893.84	95.1352
2896.46	98.3153
2899.09	102.324
2901.71	106.949
2904.33	111.749
2906.95	117.182
2909.57	123.136
2912.19	128.606
2914.81	134.608
2917.43	140.107
2920.04	145.204
2922.66	149.396
2925.27	153.698
2927.88	156.375
2930.5	158.388
2933.11	160.43
2935.72	160.527
2938.33	160.097
2940.94	158.067
2943.54	155.082
2946.15	151.551
2948.76	147.52
2951.36	143.571
2953.97	139.214
2956.57	134.649
2959.17	129.635
2961.77	125.038
2964.37	121.326
2966.97	116.57
2969.57	112.177
2972.17	106.474
2974.77	101.702
2977.36	96.6819
2979.96	91.3813
2982.55	85.2486
2985.15	80.0835
2987.74	73.836
2990.33	69.0469
2992.92	62.3283
2995.51	57.4757
2998.1	52.743
3000.69	48.2803
3003.27	42.8412
3005.86	38.2502
3008.44	34.0665
3011.03	30.6995
3013.61	27.7705
3016.19	25.4058
3018.78	22.8742
3021.36	20.6622
3023.94	19.3461
3026.51	18.8046
3029.09	18.1936
3031.67	17.2842
3034.24	16.9718
3036.82	17.0904
3039.39	17.7434
3041.97	17.6638
3044.54	18.1995
3047.11	19.7029
3049.68	20.4742
3052.25	21.0511
3054.82	21.2037
3057.39	21.0653
3059.96	21.1342
3062.52	20.972
3065.09	19.8141
3067.65	18.7975
3070.22	18.0586
3072.78	16.7044
3075.34	14.6143
3077.9	12.7258
3080.46	10.8105
3083.02	8.54334
3085.58	6.98687
3088.14	6.02895
3090.69	4.77187
3093.25	4.24513
3095.8	3.94712
3098.36	2.87464
3100.91	2.20596
3103.46	2.24502
3106.01	1.99407
3108.56	1.91782
3111.11	2.28766
3113.66	1.90317
3116.21	1.68229
3118.76	2.27093
3121.3	2.37083
3123.85	2.63921
3126.39	2.26626
3128.93	2.25961
3131.48	2.13291
3134.02	1.30048
3136.56	0.130783
3139.1	-0.506908
3141.64	-0.639127
3144.17	-0.714195
3146.71	-0.760092
3149.25	-1.3287