File: data/Raman/poly_smoothed/Thy_10_08_32_1x_45s_532 nm_x100_100%_600 gr_mm_01.txt
#Acq. time (s)=	45
#Accumulations=	2
#Range (cm-¹)=	200...3150
#Windows=	2
#Auto scanning=	Off
#Autofocus=	Off
#Macrospot=	Off
#AutoExposure=	Off
#Spike filter=	Multiple accum.
#Delay time (s)=	0
#Binning=	1
#Readout mode=	Signal
#DeNoise=	Off
#ICS correction=	On
#Dark correction=	Off
#Inst. Process=	Off
#Detector Gain=	Best Dynamic Range
#Detector ADC=	20 kHz
#Detector temperature (°C)=	-70.08
#Instrument=	LabRAM HR Evol
#Detector=	Synapse
#Objective=	x100
#Grating=	600 gr/mm
#ND Filter=	100%
#Laser (nm)=	532
#Hole=	100.021
#Range=	Auto
#Laser Pol.=	No
#Raman. Pol.=	No
#Laser Pol. (°)=	-0.0007625
#Raman Pol. (°)=	89.9995
#Collection=	Microscope
#StageXY=	Marzhauser
#StageZ=	Marzhauser
#X (µm)=	2189.7
#Y (µm)=	1227.6
#Z (µm)=	442.95
#Full time(mm:ss)=	3:18
#Project=
#Sample=
#Site=
#Title=	Thy_10_08_32_2x_45s_532 nm_x100_100%_600 gr_mm
#Remark=
#Date=	05.07.2022 16:32
#Acquired=	05.07.2022 16:32:51
#Base:Fit=	10.08.2022 09:46:25
#Base:Sub=	10.08.2022 09:46:49
#Filter:Polynom=	16.08.2022 10:24:56
#AxisType[0]=Intens
#AxisUnit[0]=Cnt
#AxisType[1]=Spectr
#AxisUnit[1]=1/cm
200.43	-0.144734
204.059	4.82583
207.688	8.90002
211.314	9.77548
214.941	8.35888
218.564	8.71159
222.186	9.32364
225.809	9.57457
229.428	10.035
233.045	9.63098
236.663	10.2756
240.278	10.8311
243.891	10.5065
247.503	11.3517
251.116	11.9267
254.725	12.2892
258.333	13.807
261.939	16.5165
265.544	17.876
269.148	19.5647
272.75	21.5948
276.351	23.4578
279.95	24.6871
283.548	25.3867
287.144	26.5237
290.739	25.173
294.333	24.9323
297.925	24.416
301.514	25.5361
305.104	26.2858
308.692	26.5659
312.279	27.4528
315.862	28.2336
319.446	27.896
323.029	27.2369
326.608	27.2131
330.188	28.427
333.766	28.4812
337.341	29.2744
340.917	28.9134
344.489	27.9304
348.062	28.9517
351.631	29.7449
355.201	29.5703
358.768	29.0521
362.333	28.4014
365.899	27.2397
369.462	27.1946
373.023	26.885
376.585	28.0902
380.143	27.6498
383.7	27.127
387.256	27.072
390.812	27.3416
394.365	26.6235
397.916	26.0127
401.467	25.5986
405.015	25.0637
408.563	23.606
412.109	23.5563
415.654	22.0347
419.197	21.4186
422.739	20.1241
426.279	18.7887
429.819	17.5236
433.356	15.6623
436.891	15.1689
440.426	14.3602
443.96	14.6179
447.492	15.7619
451.021	15.5173
454.551	18.711
458.079	19.7017
461.604	21.3634
465.13	22.135
468.654	22.4828
472.175	23.1864
475.696	24.3139
479.215	24.2035
482.733	23.9174
486.249	25.3031
489.765	25.8253
493.278	25.4025
496.789	25.8685
500.301	25.7929
503.81	25.4361
507.317	25.8842
510.825	24.6891
514.33	23.7265
517.833	23.2622
521.335	23.4468
524.836	25.0609
528.335	25.8699
531.835	26.3574
535.332	26.5534
538.827	25.7615
542.321	25.6241
545.814	24.5763
549.305	23.8549
552.795	23.9261
556.282	21.7773
559.769	20.9567
563.255	18.7929
566.739	17.0517
570.223	17.0114
573.705	15.8325
577.183	14.7498
580.663	13.3681
584.141	12.0663
587.615	10.2091
591.09	9.025
594.564	7.24468
598.035	6.47025
601.506	6.49557
604.974	5.73343
608.443	6.86814
611.908	7.97857
615.374	8.24429
618.837	8.80895
622.3	9.92024
625.761	9.8568
629.219	11.1149
632.677	12.9551
636.135	14.7917
639.59	15.9086
643.043	16.5184
646.495	18.8445
649.948	19.6323
653.398	20.2874
656.846	21.4538
660.293	21.8731
663.738	21.4454
667.183	21.7723
670.626	22.0839
674.067	24.4595
677.508	24.3769
680.947	26.8549
684.385	28.7327
687.821	29.8391
691.254	32.036
694.688	33.0518
698.121	35.6129
701.552	36.2045
704.98	38.4783
708.409	38.6653
711.836	39.6526
715.26	41.4582
718.685	42.1014
722.108	43.4345
725.528	43.9188
728.949	44.0994
732.367	43.4711
735.785	43.6687
739.2	44.983
742.614	48.4806
746.028	50.3844
749.439	51.9775
752.849	55.1678
756.26	58.1448
759.667	60.0819
763.073	62.3033
766.477	64.9353
769.883	66.673
773.285	68.3238
776.686	69.8416
780.085	71.9314
783.484	73.1057
786.881	74.4232
790.276	75.2523
793.671	75.7974
797.064	77.3204
800.456	77.2714
803.846	78.5224
807.234	78.5613
810.622	77.6726
814.008	77.5659
817.394	78.2385
820.778	78.8151
824.159	78.7607
827.541	77.6234
830.921	76.4509
834.298	75.5263
837.676	74.0501
841.051	72.3587
844.426	71.1687
847.798	69.5536
851.171	67.5313
854.54	65.5095
857.911	63.2619
861.278	61.5608
864.645	59.09
868.01	57.4389
871.373	53.9128
874.735	52.501
878.097	50.6697
881.457	48.0105
884.815	47.1897
888.172	46.2474
891.528	44.6514
894.882	44.0699
898.237	45.2462
901.589	44.1529
904.94	42.3797
908.289	42.4762
911.635	42.0318
914.982	43.6679
918.328	43.6041
921.672	43.2882
925.015	43.9338
928.357	44.0709
931.698	43.6852
935.035	43.4299
938.373	42.4535
941.71	41.413
945.044	40.7223
948.378	38.6636
951.709	36.9523
955.041	35.5991
958.372	33.3474
961.699	32.2153
965.027	31.2301
968.352	32.0036
971.676	31.073
975	29.973
978.322	29.9361
981.642	28.4201
984.962	26.8747
988.28	26.1874
991.596	25.8376
994.911	24.5951
998.227	24.9571
1001.54	23.9427
1004.85	23.7819
1008.16	24.3951
1011.47	23.3912
1014.78	23.1905
1018.08	22.7923
1021.39	21.5307
1024.69	20.7416
1028	19.2178
1031.3	18.9121
1034.6	17.8943
1037.9	16.8105
1041.19	15.1138
1044.49	13.5972
1047.78	13.0408
1051.08	13.0533
1054.37	12.7815
1057.66	13.051
1060.95	12.2748
1064.24	11.1155
1067.53	10.044
1070.81	9.48097
1074.1	9.11824
1077.38	8.05239
1080.66	8.05856
1083.94	8.67695
1087.22	9.21645
1090.5	7.45487
1093.78	9.10657
1097.05	9.39243
1100.33	8.9307
1103.6	9.2682
1106.87	9.53901
1110.14	9.89809
1113.41	9.09486
1116.68	8.82732
1119.95	7.56322
1123.21	6.92243
1126.48	7.59328
1129.74	7.87624
1133	8.73793
1136.26	9.51539
1139.52	8.77854
1142.78	8.56235
1146.04	7.67541
1149.29	7.1679
1152.55	7.63523
1155.8	7.00627
1159.05	7.53932
1162.3	7.92953
1165.55	7.70037
1168.8	6.71705
1172.05	5.71995
1175.29	6.24398
1178.54	5.56511
1181.78	4.43793
1185.02	5.10355
1188.26	6.31501
1191.5	6.24414
1194.74	5.83804
1197.97	7.78023
1201.21	9.50701
1204.44	11.3664
1207.68	12.0177
1210.91	14.8465
1214.14	16.78
1217.37	19.2388
1220.59	21.2384
1223.82	22.4955
1227.05	23.9678
1230.27	27.2845
1233.49	28.771
1236.72	28.3223
1239.94	28.5592
1243.16	28.2727
1246.37	27.6509
1249.59	27.3641
1252.8	26.8417
1256.02	25.9941
1259.23	24.9694
1262.44	25.2182
1265.66	25.7476
1268.86	24.8406
1272.07	24.0969
1275.28	25.3119
1278.48	26.111
1281.69	25.7534
1284.89	28.1465
1288.09	30.6695
1291.29	32.1631
1294.49	34.5696
1297.69	36.3546
1300.89	38.3223
1304.08	39.7063
1307.28	41.2321
1310.47	42.1455
1313.66	41.5857
1316.85	42.2112
1320.04	43.065
1323.23	44.361
1326.42	44.6968
1329.61	44.2426
1332.79	43.824
1335.97	43.6212
1339.16	42.7093
1342.34	42.2824
1345.52	41.2983
1348.7	39.8908
1351.87	39.5491
1355.05	39.2208
1358.22	37.7697
1361.4	38.2208
1364.57	37.792
1367.74	37.0588
1370.91	35.289
1374.08	33.6313
1377.25	32.135
1380.41	31.4685
1383.58	30.0897
1386.74	28.1442
1389.91	27.409
1393.07	27.0948
1396.23	27.3567
1399.39	26.9776
1402.55	26.7202
1405.7	24.5745
1408.86	24.1144
1412.01	24.5542
1415.17	24.4786
1418.32	24.7793
1421.47	27.383
1424.62	28.9846
1427.77	30.6838
1430.91	33.8775
1434.06	34.646
1437.2	36.4673
1440.35	38.5171
1443.49	39.8259
1446.63	39.9266
1449.77	41.2291
1452.91	42.2176
1456.05	42.8997
1459.18	43.663
1462.32	42.022
1465.45	40.9899
1468.59	39.2274
1471.72	37.1871
1474.85	34.4623
1477.98	31.9954
1481.1	28.4866
1484.23	25.3303
1487.36	22.7629
1490.48	20.3291
1493.61	17.5827
1496.73	16.2575
1499.85	14.5434
1502.97	13.1203
1506.09	13.0074
1509.2	12.4564
1512.32	11.6775
1515.43	12.1799
1518.55	12.3241
1521.66	13.9169
1524.77	15.7092
1527.88	16.8074
1530.99	18.3554
1534.1	19.7332
1537.21	21.1544
1540.31	22.9465
1543.42	26.4102
1546.52	28.965
1549.62	31.674
1552.72	33.7724
1555.82	36.3056
1558.92	38.66
1562.02	40.8948
1565.11	41.8665
1568.21	44.4624
1571.3	46.0537
1574.39	46.8187
1577.49	47.1035
1580.57	48.6359
1583.66	49.6843
1586.75	49.5155
1589.84	50.4368
1592.92	49.4688
1596.01	49.3292
1599.09	48.2271
1602.17	46.8039
1605.25	45.6636
1608.33	43.9282
1611.41	42.2377
1614.49	40.2343
1617.57	39.5654
1620.64	38.3604
1623.72	37.5575
1626.79	36.4561
1629.86	36.4556
1632.93	36.4554
1636	36.7922
1639.07	37.2246
1642.13	37.6278
1645.2	38.2696
1648.26	38.1204
1651.33	38.5104
1654.39	39.1258
1657.45	38.8979
1660.51	39.3646
1663.57	39.0893
1666.63	38.0349
1669.68	36.3693
1672.74	35.3266
1675.79	32.8414
1678.85	30.6792
1681.9	28.2346
1684.95	24.835
1688	21.9268
1691.05	19.6912
1694.09	17.2978
1697.14	14.8583
1700.18	12.7317
1703.23	11.1233
1706.27	9.99442
1709.31	8.89283
1712.35	7.23826
1715.39	5.59123
1718.43	4.50973
1721.47	4.03814
1724.5	3.34418
1727.54	3.82306
1730.57	3.38485
1733.61	3.39815
1736.64	3.15892
1739.67	3.23413
1742.7	3.63937
1745.72	3.5443
1748.75	3.32165
1751.77	2.9491
1754.8	3.93288
1757.82	3.714
1760.84	3.75757
1763.87	4.43441
1766.89	4.59853
1769.91	4.66713
1772.92	4.85907
1775.94	5.09013
1778.95	4.93428
1781.97	4.90045
1784.98	4.44397
1787.99	3.96003
1791.01	3.72466
1794.01	3.99851
1797.02	4.25216
1800.03	4.48518
1803.04	5.01695
1806.04	5.54117
1809.05	5.60518
1812.05	6.81036
1815.05	6.60266
1818.05	6.21322
1821.05	5.92117
1824.05	6.10378
1827.05	6.25931
1830.04	5.70653
1833.04	4.70944
1836.03	4.25154
1839.03	4.02533
1842.02	3.3068
1845.01	2.95557
1848	2.25389
1850.99	1.73181
1853.97	0.744646
1856.96	0.755151
1859.94	0.772432
1862.93	0.380372
1865.91	-0.100926
1868.89	0.905302
1871.87	1.66226
1874.85	2.12785
1877.83	2.94084
1880.81	4.57767
1882.57	4.58946
1885.56	4.48272
1888.55	5.18701
1891.54	4.64069
1894.52	4.365
1897.51	3.96698
1900.49	2.77859
1903.47	2.5551
1906.45	2.83263
1909.43	3.48264
1912.41	2.40851
1915.39	2.05723
1918.37	1.63572
1921.34	1.38244
1924.32	1.69004
1927.29	1.82952
1930.26	2.47058
1933.23	2.58161
1936.2	2.22586
1939.17	2.62056
1942.14	3.62945
1945.11	4.29209
1948.07	4.65233
1951.04	5.60445
1954	5.79769
1956.96	6.04309
1959.93	6.59079
1962.89	6.53727
1965.85	6.08597
1968.8	6.13885
1971.76	7.01898
1974.72	6.91357
1977.67	6.94617
1980.63	6.79556
1983.58	6.46012
1986.53	6.28186
1989.48	6.54562
1992.43	5.84181
1995.38	5.33331
1998.32	5.29118
2001.27	5.02373
2004.22	4.9904
2007.16	4.81142
2010.1	4.80962
2013.04	4.63733
2015.98	5.2697
2018.92	5.75171
2021.86	5.65635
2024.8	6.78415
2027.74	6.37616
2030.67	7.10386
2033.61	7.79784
2036.54	8.47608
2039.47	8.58449
2042.4	9.81406
2045.33	10.2104
2048.26	10.2544
2051.19	10.8598
2054.12	11.5093
2057.04	11.69
2059.97	12.0417
2062.89	11.9424
2065.81	12.0162
2068.73	12.7575
2071.65	12.5021
2074.57	11.946
2077.49	12.5819
2080.41	12.2194
2083.32	12.431
2086.24	12.0663
2089.15	12.0994
2092.07	10.5108
2094.98	10.3577
2097.89	9.44545
2100.8	9.34759
2103.71	9.28399
2106.61	8.854
2109.52	8.27036
2112.43	8.56851
2115.33	8.89123
2118.23	7.82126
2121.13	8.91391
2124.04	8.49175
2126.94	8.51507
2129.83	9.24901
2132.73	10.1315
2135.63	10.7198
2138.53	10.526
2141.42	10.601
2144.31	11.6141
2147.21	12.0833
2150.1	13.2818
2152.99	14.6464
2155.88	15.6214
2158.77	16.8763
2161.65	17.3154
2164.54	18.1959
2167.43	18.9533
2170.31	18.2955
2173.19	19.1756
2176.07	18.3009
2178.96	19.2013
2181.84	19.7316
2184.72	19.0527
2187.59	18.5133
2190.47	18.0855
2193.35	17.0107
2196.22	16.858
2199.09	16.6307
2201.97	16.3032
2204.84	15.2557
2207.71	14.8161
2210.58	14.1477
2213.45	12.8136
2216.31	12.8818
2219.18	12.955
2222.05	13.2996
2224.91	13.159
2227.78	12.6462
2230.64	12.4383
2233.5	11.5021
2236.36	10.7213
2239.22	10.6454
2242.08	10.0615
2244.93	9.62849
2247.79	9.6757
2250.64	10.0341
2253.5	8.72915
2256.35	8.21827
2259.2	8.79371
2262.05	8.31873
2264.9	9.00277
2267.75	9.95792
2270.6	10.0248
2273.45	10.2713
2276.29	9.02979
2279.14	8.76873
2281.98	8.17258
2284.82	8.37186
2287.66	9.10748
2290.5	8.10512
2293.34	7.01173
2296.18	7.04033
2299.02	7.09389
2301.86	7.81365
2304.69	8.52798
2307.53	8.4196
2310.36	8.849
2313.19	8.91228
2316.02	8.53614
2318.85	9.01695
2321.68	8.26196
2324.51	8.34727
2327.34	9.07126
2330.16	8.88112
2332.99	9.72748
2335.81	9.55464
2338.64	8.73388
2341.46	7.83868
2344.28	6.47066
2347.1	5.80492
2349.92	5.08769
2352.74	4.01242
2355.55	4.06914
2358.37	2.94416
2361.19	1.82633
2364	2.91745
2366.81	3.85119
2369.62	3.21187
2372.44	3.41264
2375.24	2.72461
2378.05	2.86052
2380.86	2.48919
2383.67	2.7004
2386.47	3.00887
2389.28	3.42394
2392.08	2.976
2394.89	3.46917
2397.69	3.44687
2400.49	3.01578
2403.29	2.41442
2406.09	1.67562
2408.88	1.65962
2411.68	2.22679
2414.48	2.48016
2417.27	2.77013
2420.06	2.85805
2422.86	2.61195
2425.65	3.49332
2428.44	3.58794
2431.23	3.47101
2434.02	3.83902
2436.81	3.27211
2439.59	3.61653
2442.38	4.12595
2445.16	3.62229
2447.95	4.70081
2450.73	4.68366
2453.51	4.97262
2456.29	5.27666
2459.07	4.65985
2461.85	3.6857
2464.63	3.29126
2467.4	3.0053
2470.18	2.91234
2472.95	2.73244
2475.73	3.40863
2478.5	3.45643
2481.27	3.85586
2484.04	4.17753
2486.81	4.30454
2489.58	4.55916
2492.35	4.45382
2495.12	3.69257
2497.88	3.52968
2500.65	3.37616
2503.41	2.7952
2506.17	2.00824
2508.94	1.73112
2511.7	1.58156
2514.46	1.43295
2517.22	0.953468
2519.97	1.51327
2522.73	1.61663
2525.49	1.72092
2528.24	1.8654
2530.99	2.16282
2533.75	1.99751
2536.5	1.3567
2539.25	1.52709
2542	2.03655
2544.75	2.23755
2547.5	2.61348
2550.24	2.96551
2552.99	3.47579
2555.74	3.61324
2558.48	3.88937
2561.22	2.70423
2563.96	2.06648
2566.71	2.33843
2569.45	2.38881
2572.18	1.9086
2574.92	2.13687
2577.66	2.48123
2580.4	2.47891
2583.13	3.12827
2585.87	3.86734
2588.6	4.06334
2591.33	4.25314
2594.06	4.2081
2596.79	3.74178
2599.52	2.73478
2602.25	2.26151
2604.98	2.0979
2607.71	1.84361
2610.43	1.3957
2613.16	0.734761
2615.88	0.712393
2618.6	0.658284
2621.32	0.607805
2624.04	-0.146097
2626.76	-0.468931
2629.48	-1.06718
2632.2	-0.671533
2634.92	-0.315803
2637.63	0.273891
2640.35	0.457169
2643.06	1.56443
2645.77	1.76985
2648.49	2.36812
2651.2	2.21842
2653.91	2.35779
2656.62	2.34837
2659.33	2.24296
2662.03	2.85335
2664.74	3.31178
2667.44	2.93458
2670.15	3.54477
2672.85	4.527
2675.55	4.98115
2678.26	5.8108
2680.96	5.11056
2683.66	5.37611
2686.35	5.11622
2689.05	5.15047
2691.75	5.63861
2694.44	5.51413
2697.14	5.51956
2699.83	5.29784
2702.52	6.02856
2705.22	6.76531
2707.91	6.19041
2710.6	5.98404
2713.29	5.18243
2715.97	4.54458
2718.66	4.25117
2721.35	3.78604
2724.03	4.12195
2726.72	3.85224
2729.4	3.6583
2732.08	3.96883
2734.76	4.43345
2737.44	5.36196
2740.12	5.07049
2742.8	5.10318
2745.48	5.11735
2748.16	5.61002
2750.83	5.50378
2753.51	6.00422
2756.18	6.39554
2758.85	6.07281
2761.53	6.25799
2764.2	5.7555
2766.87	5.95227
2769.54	5.65573
2772.2	4.23359
2774.87	3.86272
2777.54	3.57971
2780.2	2.86679
2782.87	2.48414
2785.53	2.02366
2788.19	2.37679
2790.85	2.02033
2793.51	2.13361
2796.17	2.22302
2798.83	3.13209
2801.49	3.7585
2804.15	3.81972
2806.8	4.78413
2809.46	5.56925
2812.11	6.47788
2814.76	6.95913
2817.42	8.07003
2820.07	8.41217
2822.72	9.63373
2825.37	10.2409
2828.02	11.0992
2830.66	11.7431
2833.31	13.0513
2835.96	14.5859
2838.6	15.802
2841.24	17.6174
2843.89	19.276
2846.53	22.1453
2849.17	25.4012
2851.81	29.1224
2854.45	33.2243
2857.09	37.3069
2859.72	41.2576
2862.36	44.6938
2865	48.3117
2867.63	51.5196
2870.26	54.6194
2872.9	58.1215
2875.53	60.5242
2878.16	62.5715
2880.79	64.682
2883.42	65.8507
2886.05	66.9526
2888.67	68.7432
2891.3	69.7882
2893.92	71.5141
2896.55	72.3373
2899.17	74.9235
2901.79	77.3035
2904.42	80.5065
2907.04	83.4359
2909.66	87.593
2912.27	92.6926
2914.89	98.3618
2917.51	103.097
2920.13	107.015
2922.74	110.429
2925.35	112.152
2927.97	114.302
2930.58	114.791
2933.19	115.632
2935.8	115.997
2938.41	114.679
2941.02	112.983
2943.63	110.05
2946.24	107.959
2948.84	104.485
2951.45	100.906
2954.05	97.4738
2956.65	94.2934
2959.26	91.0551
2961.86	87.7845
2964.46	84.9537
2967.06	81.7404
2969.66	78.3241
2972.25	74.6771
2974.85	72.1354
2977.45	69.7888
2980.04	66.43
2982.64	62.9912
2985.23	58.0477
2987.82	53.6596
2990.41	49.1306
2993	45.7105
2995.59	42.4387
2998.18	39.0707
3000.77	35.7245
3003.36	31.8428
3005.94	28.8236
3008.53	26.3227
3011.11	23.5691
3013.69	21.6956
3016.28	20.1327
3018.86	19.7271
3021.44	17.9626
3024.02	16.2745
3026.6	15.2092
3029.18	14.9624
3031.75	13.8488
3034.33	13.4478
3036.9	13.0187
3039.48	13.3416
3042.05	13.6297
3044.62	13.7973
3047.19	13.9593
3049.77	14.0103
3052.34	14.7298
3054.9	15.1733
3057.47	15.3687
3060.04	14.8332
3062.61	13.3797
3065.17	12.1314
3067.74	12.0614
3070.3	11.8372
3072.86	10.7918
3075.42	9.83274
3077.99	9.24315
3080.54	8.35332
3083.1	7.46674
3085.66	6.36236
3088.22	5.73694
3090.78	5.61001
3093.33	4.90117
3095.89	3.71791
3098.44	3.19805
3100.99	3.0441
3103.54	3.21289
3106.1	3.32043
3108.65	3.84799
3111.2	4.36083
3113.74	4.3789
3116.29	4.58259
3118.84	4.42687
3121.38	4.13362
3123.93	2.97073
3126.47	3.14918
3129.01	3.59215
3131.56	3.31984
3134.1	2.35919
3136.64	2.26369
3139.18	2.13502
3141.72	1.51302
3144.26	0.740839
3146.79	-0.813259
3149.33	-3.96949