File: data/Raman/poly_smoothed/Thy_30_10_44_1x_45s_532 nm_x100_100%_600 gr_mm_01.txt
#Acq. time (s)=	45
#Accumulations=	2
#Range (cm-¹)=	200...3150
#Windows=	2
#Auto scanning=	Off
#Autofocus=	Off
#Macrospot=	Off
#AutoExposure=	Off
#Spike filter=	Multiple accum.
#Delay time (s)=	0
#Binning=	1
#Readout mode=	Signal
#DeNoise=	Off
#ICS correction=	On
#Dark correction=	Off
#Inst. Process=	Off
#Detector Gain=	Best Dynamic Range
#Detector ADC=	20 kHz
#Detector temperature (°C)=	-69.85
#Instrument=	LabRAM HR Evol
#Detector=	Synapse
#Objective=	x100
#Grating=	600 gr/mm
#ND Filter=	100%
#Laser (nm)=	532
#Hole=	100.021
#Range=	Auto
#Laser Pol.=	No
#Raman. Pol.=	No
#Laser Pol. (°)=	-0.0007625
#Raman Pol. (°)=	89.9995
#Collection=	Microscope
#StageXY=	Marzhauser
#StageZ=	Marzhauser
#X (µm)=	4714
#Y (µm)=	-7707.6
#Z (µm)=	584.35
#Full time(mm:ss)=	3:18
#Project=
#Sample=
#Site=
#Title=	Thy_30_10_44_2x_45s_532 nm_x100_100%_600 gr_mm
#Remark=
#Date=	30.06.2022 14:34
#Acquired=	30.06.2022 14:34:44
#Base:Fit=	10.08.2022 09:58:11
#Base:Sub=	10.08.2022 09:58:44
#Filter:Polynom=	16.08.2022 10:22:53
#AxisType[0]=Intens
#AxisUnit[0]=Cnt
#AxisType[1]=Spectr
#AxisUnit[1]=1/cm
200.533	10.8044
204.162	9.87905
207.792	7.18174
211.418	4.89672
215.044	4.45503
218.667	3.18585
222.289	2.36598
225.912	2.68554
229.531	3.43817
233.148	4.02912
236.766	4.15709
240.381	3.75192
243.994	4.62476
247.606	5.04722
251.217	6.14125
254.828	7.21506
258.436	8.0449
262.042	8.38104
265.647	10.4141
269.25	11.4747
272.852	13.8887
276.453	15.3309
280.052	15.6336
283.65	15.5303
287.247	15.1899
290.842	15.1118
294.436	15.2347
298.028	17.0979
301.617	17.9196
305.206	18.2138
308.794	17.7139
312.381	18.7034
315.964	17.7322
319.548	17.83
323.131	17.4256
326.71	17.1334
330.29	16.0145
333.868	15.9886
337.443	13.4207
341.018	12.3888
344.591	11.8217
348.163	11.5375
351.733	10.4455
355.303	10.1857
358.869	7.90361
362.435	6.2885
366.001	5.92544
369.563	4.47369
373.124	4.54006
376.686	5.10737
380.244	4.79835
383.801	5.9833
387.357	6.72399
390.911	5.84744
394.466	6.13146
398.018	6.08603
401.568	7.0011
405.117	8.86658
408.664	9.292
412.21	10.3453
415.755	9.44414
419.298	10.6245
422.84	9.88143
426.38	8.64818
429.919	8.68683
433.455	8.00636
436.992	7.93621
440.527	7.33046
444.06	7.56829
447.593	6.43273
451.122	6.10614
454.651	7.18704
458.18	7.78163
461.705	8.24333
465.23	7.55167
468.752	7.84084
472.275	7.34621
475.797	7.16722
479.315	7.15351
482.834	7.91914
486.349	9.88083
489.863	11.1776
493.378	11.4049
496.889	11.79
500.401	13.4054
503.91	13.272
507.417	13.3202
510.923	13.5811
514.43	14.5291
517.933	14.8899
521.435	15.1031
524.936	15.8399
528.435	15.7052
531.933	15.9138
535.43	15.3692
538.927	16.4684
542.421	15.5723
545.913	13.825
549.403	13.605
552.893	13.051
556.381	11.5936
559.868	10.9888
563.354	9.4177
566.839	9.61838
570.322	9.17113
573.802	8.32247
577.283	6.95307
580.762	5.96425
584.24	4.71871
587.714	3.09507
591.19	1.93323
594.663	1.8248
598.134	1.5978
601.605	0.905137
605.073	0.949256
608.542	0.610682
612.007	0.527961
615.473	1.20456
618.936	2.3803
622.397	2.5222
625.859	3.17399
629.318	2.8884
632.775	4.92108
636.233	6.17422
639.688	6.50766
643.142	6.33202
646.594	7.17203
650.045	6.98724
653.496	7.44021
656.944	8.99009
660.391	9.57016
663.837	9.99064
667.281	11.481
670.724	12.7161
674.166	13.8222
677.606	16.0568
681.045	18.9714
684.483	20.9373
687.917	23.7941
691.352	24.0244
694.786	25.2773
698.219	27.2609
701.65	29.7746
705.078	30.8422
708.506	33.2933
711.934	33.8565
715.358	35.4806
718.782	36.331
722.204	37.6983
725.626	39.5198
729.045	40.2535
732.464	41.3382
735.881	42.4432
739.297	42.9409
742.711	44.0345
746.125	45.6423
749.537	47.0418
752.946	48.731
756.357	49.9083
759.764	52.8572
763.17	53.803
766.575	55.5654
769.978	56.265
773.382	57.2625
776.783	57.6785
780.182	59.4018
783.581	60.0189
786.978	62.2196
790.373	62.3451
793.768	63.3861
797.161	64.1443
800.552	64.9662
803.941	66.069
807.33	67.7807
810.718	68.5331
814.105	66.9979
817.49	65.6228
820.873	63.5641
824.256	63.1081
827.637	62.3589
831.016	60.8326
834.395	60.3433
837.772	58.9947
841.147	57.3058
844.522	55.8065
847.894	53.2941
851.267	50.8508
854.637	49.8674
858.007	48.3146
861.374	45.6083
864.739	44.8853
868.106	44.9778
871.469	43.5936
874.831	42.5731
878.193	41.9939
881.553	41.0944
884.911	41.4433
888.268	41.259
891.623	40.925
894.978	40.5352
898.331	40.5594
901.683	39.2927
905.033	39.5321
908.383	39.5662
911.731	38.9619
915.078	38.9343
918.423	38.7929
921.768	38.2542
925.111	37.8889
928.452	38.3021
931.791	37.6309
935.13	37.6213
938.468	36.7537
941.803	35.8059
945.139	34.0451
948.473	32.4624
951.804	31.9512
955.136	29.7045
958.465	29.0857
961.794	28.2133
965.12	27.1646
968.447	27.0833
971.771	26.613
975.095	26.5347
978.417	26.7676
981.737	25.9022
985.057	24.6565
988.375	23.3472
991.691	22.7215
995.006	22.2588
998.32	21.7486
1001.63	21.6602
1004.95	22.1892
1008.26	22.2004
1011.56	22.6889
1014.87	21.6156
1018.18	20.921
1021.48	18.0986
1024.79	17.2484
1028.09	15.4444
1031.39	14.9345
1034.69	14.3954
1037.99	12.9047
1041.29	13.6303
1044.58	13.2896
1047.88	13.0869
1051.17	13.5282
1054.46	14.2376
1057.75	15.7558
1061.04	16.4423
1064.33	16.224
1067.62	16.0044
1070.9	14.7314
1074.19	15.6861
1077.47	15.0776
1080.76	15.1157
1084.04	14.0932
1087.32	14.3302
1090.59	14.9811
1093.87	14.2746
1097.15	13.2971
1100.42	13.8474
1103.69	12.633
1106.97	12.2289
1110.24	12.9253
1113.51	12.4289
1116.77	11.747
1120.04	10.8231
1123.31	11.269
1126.57	10.071
1129.83	10.7849
1133.1	11.3118
1136.36	13.7652
1139.62	13.4806
1142.87	11.8824
1146.13	11.3698
1149.38	9.59666
1152.64	8.94351
1155.89	7.51089
1159.14	6.42339
1162.39	5.23155
1165.64	5.53065
1168.89	4.95997
1172.14	4.55245
1175.38	4.64377
1178.63	5.06799
1181.87	5.41923
1185.11	6.06203
1188.35	7.15514
1191.59	7.84766
1194.83	8.28542
1198.07	8.81882
1201.3	10.4613
1204.53	11.7297
1207.77	13.8829
1211	16.5692
1214.23	18.2594
1217.46	21.3241
1220.69	22.7081
1223.91	23.7105
1227.14	26.9154
1230.36	29.0145
1233.59	29.9686
1236.81	31.8453
1240.03	34.8025
1243.25	36.6294
1246.46	38.9997
1249.68	40.655
1252.9	42.3781
1256.11	43.5858
1259.32	44.5597
1262.54	44.7221
1265.75	45.8889
1268.96	44.8285
1272.16	44.8672
1275.37	45.066
1278.57	45.0327
1281.78	44.4915
1284.98	45.364
1288.18	45.5029
1291.38	44.2048
1294.58	45.225
1297.78	44.9457
1300.98	45.493
1304.17	46.1918
1307.37	47.2342
1310.56	47.6925
1313.76	47.5525
1316.95	49.5162
1320.14	51.5414
1323.32	52.6842
1326.51	51.8821
1329.7	50.8472
1332.88	50.3544
1336.07	49.5381
1339.25	48.0479
1342.43	47.6981
1345.61	46.2959
1348.79	45.0224
1351.96	43.5117
1355.14	42.2759
1358.31	41.3217
1361.49	40.5434
1364.66	38.9263
1367.83	37.1446
1371	35.8226
1374.17	35.085
1377.34	35.0222
1380.5	33.2162
1383.67	33.7847
1386.83	32.652
1390	31.2545
1393.16	31.5761
1396.32	32.1215
1399.48	30.9148
1402.64	30.354
1405.79	30.4272
1408.95	29.9985
1412.1	30.8612
1415.26	32.9435
1418.41	34.9651
1421.56	37.4167
1424.71	39.0621
1427.86	42.6661
1431	46.4128
1434.15	49.4245
1437.29	52.5589
1440.44	53.7915
1443.58	55.1952
1446.72	55.0198
1449.86	55.0712
1453	53.8979
1456.14	52.8715
1459.27	51.7627
1462.41	49.5668
1465.54	46.532
1468.67	42.5671
1471.81	39.5624
1474.94	35.3708
1478.07	31.1873
1481.19	28.7021
1484.32	24.8362
1487.45	23.0779
1490.57	21.8343
1493.69	20.9963
1496.82	19.9072
1499.94	19.1082
1503.06	19.6969
1506.17	20.0987
1509.29	20.6839
1512.41	21.5096
1515.52	23.6926
1518.64	25.9199
1521.75	26.8678
1524.86	28.398
1527.97	30.1394
1531.08	31.2496
1534.19	34.0163
1537.29	35.1992
1540.4	36.3243
1543.5	37.7934
1546.61	38.6846
1549.71	40.9297
1552.81	41.2046
1555.91	44.5629
1559.01	45.6925
1562.11	47.3848
1565.2	48.7037
1568.29	50.3381
1571.39	52.4599
1574.48	52.3392
1577.57	54.1413
1580.66	56.6136
1583.75	58.4163
1586.84	58.6525
1589.93	59.6928
1593.01	59.3208
1596.1	58.9136
1599.18	56.8051
1602.26	55.7241
1605.34	54.6414
1608.42	53.3544
1611.5	52.1513
1614.58	50.719
1617.65	49.9064
1620.73	49.8283
1623.8	48.7018
1626.87	48.5624
1629.95	49.0765
1633.02	50.259
1636.09	51.4964
1639.15	52.9076
1642.22	53.9359
1645.29	55.7953
1648.35	56.1951
1651.42	56.8391
1654.48	58.713
1657.54	59.0868
1660.6	58.3076
1663.66	57.2778
1666.72	55.8001
1669.77	53.4984
1672.83	52.8587
1675.88	50.9365
1678.93	48.9827
1681.99	45.7344
1685.04	42.0275
1688.09	38.7382
1691.13	34.9653
1694.18	32.2464
1697.23	29.4575
1700.27	25.8077
1703.32	23.6028
1706.36	21.4544
1709.4	19.6874
1712.44	17.6665
1715.48	16.175
1718.52	14.9662
1721.56	14.1943
1724.59	12.9622
1727.63	12.7123
1730.66	13.2916
1733.69	12.9247
1736.72	13.5252
1739.75	12.9119
1742.78	12.4621
1745.81	12.3655
1748.84	12.4266
1751.86	11.0305
1754.89	10.744
1757.91	9.79996
1760.93	8.83003
1763.95	8.14196
1766.97	7.66861
1769.99	7.30585
1773.01	6.09931
1776.03	5.9141
1779.04	6.0212
1782.06	6.62551
1785.07	6.49624
1788.08	6.63963
1791.09	6.92072
1794.1	7.56452
1797.11	7.4525
1800.12	7.3904
1803.12	7.8564
1806.13	7.94036
1809.13	6.93376
1812.14	6.37361
1815.14	5.152
1818.14	5.61289
1821.14	5.43789
1824.14	5.57732
1827.13	5.12332
1830.13	4.86783
1833.12	4.79215
1836.12	4.8759
1839.11	4.99836
1842.1	5.17136
1845.09	5.45313
1848.08	5.03466
1851.07	4.80138
1854.06	4.68301
1857.04	4.43531
1860.03	4.15899
1863.01	3.27337
1866	3.68436
1868.98	3.11342
1871.96	2.67021
1874.94	3.16959
1877.92	3.14085
1880.89	3.10959
1882.48	3.41772
1885.47	3.93103
1888.46	4.22488
1891.44	4.51714
1894.43	4.20455
1897.41	5.04859
1900.4	5.17478
1903.38	5.60057
1906.36	6.72061
1909.34	6.68013
1912.32	6.31214
1915.29	6.79048
1918.27	5.86788
1921.25	5.5799
1924.22	5.61469
1927.2	5.65442
1930.17	5.49293
1933.14	4.39687
1936.11	3.11414
1939.08	3.0222
1942.05	2.69554
1945.01	2.50236
1947.98	2.87441
1950.94	2.65012
1953.91	2.8988
1956.87	3.11787
1959.83	2.94983
1962.79	2.30957
1965.75	2.26313
1968.71	1.85837
1971.67	0.971428
1974.62	0.9168
1977.58	1.23436
1980.53	0.517386
1983.48	0.107756
1986.43	0.71566
1989.38	0.882703
1992.33	1.73958
1995.28	1.9385
1998.23	2.15717
2001.18	2.49551
2004.12	2.31199
2007.06	2.41135
2010.01	1.87766
2012.95	3.31256
2015.89	4.1047
2018.83	4.30128
2021.77	5.25691
2024.71	5.94681
2027.64	7.10511
2030.58	7.41446
2033.51	8.55115
2036.45	9.26172
2039.38	9.58852
2042.31	10.4659
2045.24	10.7837
2048.17	11.4546
2051.1	11.0116
2054.02	10.7025
2056.95	11.4256
2059.87	11.1113
2062.8	11.3554
2065.72	11.8888
2068.64	11.9003
2071.56	11.2029
2074.48	11.6978
2077.4	11.5379
2080.31	11.2423
2083.23	10.2448
2086.14	10.3333
2089.06	10.07
2091.97	10.6772
2094.88	10.268
2097.79	10.8239
2100.7	10.9406
2103.61	12.5032
2106.52	13.4501
2109.43	14.7025
2112.33	15.0722
2115.24	16.1982
2118.14	16.915
2121.04	17.8981
2123.94	19.8434
2126.84	21.2114
2129.74	23.5517
2132.64	24.6688
2135.54	27.1831
2138.43	29.4341
2141.33	30.0301
2144.22	31.8282
2147.11	34.1054
2150.01	36.1124
2152.9	37.3573
2155.79	38.9943
2158.67	40.7737
2161.56	42.7022
2164.45	43.5279
2167.33	43.6352
2170.22	44.7794
2173.1	44.568
2175.98	44.7981
2178.86	44.5421
2181.74	43.3404
2184.62	41.8665
2187.5	41.8911
2190.38	39.9453
2193.25	38.7064
2196.13	38.1807
2199	36.4313
2201.88	35.0328
2204.75	32.8541
2207.62	31.7889
2210.49	29.6216
2213.36	27.8608
2216.22	27.1584
2219.09	26.1539
2221.96	24.6182
2224.82	24.0109
2227.68	22.4183
2230.55	21.264
2233.41	20.263
2236.27	18.9313
2239.12	18.0242
2241.98	16.152
2244.84	14.5954
2247.7	13.3469
2250.55	11.5538
2253.41	9.86572
2256.26	9.57222
2259.11	9.54204
2261.96	9.3336
2264.81	9.05974
2267.66	8.53187
2270.51	7.81819
2273.35	7.17516
2276.2	7.25667
2279.04	7.09803
2281.89	6.80053
2284.73	7.52266
2287.57	6.88649
2290.41	6.26691
2293.25	6.94406
2296.09	7.4021
2298.93	8.63057
2301.76	9.38565
2304.6	10.6035
2307.44	10.3175
2310.27	9.84967
2313.1	9.73649
2315.93	9.25674
2318.76	9.11043
2321.59	9.33084
2324.42	9.73162
2327.25	9.52141
2330.07	9.20352
2332.9	7.92645
2335.72	7.80067
2338.55	7.03365
2341.37	5.66097
2344.19	4.79293
2347.01	4.6892
2349.83	3.89056
2352.65	3.53852
2355.46	2.41431
2358.28	1.54423
2361.09	2.18388
2363.91	2.48757
2366.72	2.44665
2369.53	1.91428
2372.34	1.61785
2375.15	2.02973
2377.96	1.88186
2380.77	1.81293
2383.58	1.42309
2386.38	1.41012
2389.19	1.95503
2391.99	2.08347
2394.8	3.08127
2397.6	3.76356
2400.4	4.62722
2403.2	4.03594
2406	4.37146
2408.79	4.55009
2411.59	5.0986
2414.39	5.24103
2417.18	6.31029
2419.98	6.52213
2422.77	6.42715
2425.56	6.26009
2428.35	5.8825
2431.14	6.04922
2433.93	5.43429
2436.72	4.89641
2439.5	4.52286
2442.29	4.24312
2445.07	4.11667
2447.86	4.12183
2450.64	3.35896
2453.42	3.5655
2456.2	3.71809
2458.98	3.94471
2461.76	4.42948
2464.54	4.28679
2467.32	3.41089
2470.09	2.64851
2472.87	3.15619
2475.64	4.10794
2478.41	4.39533
2481.18	4.18318
2483.95	4.68368
2486.72	4.60351
2489.49	3.63834
2492.26	3.31368
2495.03	2.04478
2497.79	0.813149
2500.56	0.354177
2503.32	-0.221202
2506.09	-0.560373
2508.85	-0.51174
2511.61	0.32372
2514.37	1.41834
2517.13	0.989132
2519.89	0.901859
2522.64	1.60634
2525.4	1.92149
2528.15	1.96767
2530.91	1.93175
2533.66	1.9277
2536.41	2.50298
2539.16	3.59721
2541.91	3.94415
2544.66	4.52025
2547.41	4.11608
2550.16	3.86117
2552.9	3.46206
2555.65	3.02467
2558.39	2.96482
2561.13	2.52473
2563.88	1.50743
2566.62	1.66399
2569.36	1.45784
2572.1	1.64413
2574.84	1.54715
2577.57	2.01314
2580.31	2.40838
2583.05	2.28773
2585.78	2.28799
2588.51	2.28328
2591.24	1.97157
2593.98	2.26229
2596.71	2.15171
2599.44	1.75865
2602.16	2.48333
2604.89	2.95176
2607.62	3.61796
2610.34	4.04009
2613.07	4.36823
2615.79	3.89517
2618.52	3.77469
2621.24	3.77497
2623.96	3.30537
2626.68	2.77049
2629.4	1.46839
2632.11	1.69383
2634.83	1.21948
2637.55	1.23777
2640.26	0.981616
2642.98	1.009
2645.69	1.76666
2648.4	1.33728
2651.11	1.94185
2653.82	0.977408
2656.53	0.843475
2659.24	1.52017
2661.95	2.85641
2664.65	2.67233
2667.36	3.40028
2670.06	4.73382
2672.76	5.19235
2675.47	5.46834
2678.17	6.05162
2680.87	6.4615
2683.57	6.11955
2686.27	5.70138
2688.97	5.06241
2691.66	4.51525
2694.36	4.99946
2697.05	4.93196
2699.75	5.09455
2702.44	5.15249
2705.13	4.77952
2707.82	5.55335
2710.51	5.771
2713.2	5.64799
2715.89	5.55788
2718.57	4.55178
2721.26	4.8734
2723.95	5.67986
2726.63	5.76621
2729.31	6.24149
2732	6.75215
2734.68	7.69513
2737.36	8.23229
2740.04	10.1946
2742.72	10.4723
2745.39	11.0479
2748.07	10.3585
2750.75	9.04646
2753.42	8.58311
2756.09	8.18223
2758.77	7.75883
2761.44	7.53839
2764.11	6.82518
2766.78	6.66336
2769.45	6.02549
2772.12	5.9753
2774.78	5.59294
2777.45	5.32186
2780.12	4.30065
2782.78	3.81946
2785.44	3.89117
2788.11	4.48166
2790.77	4.72169
2793.43	5.43618
2796.09	7.24141
2798.75	8.58254
2801.4	9.35961
2804.06	10.4319
2806.72	11.413
2809.37	11.389
2812.03	12.2926
2814.68	11.3541
2817.33	11.93
2819.98	12.8275
2822.63	13.6676
2825.28	15.424
2827.93	16.947
2830.58	19.1319
2833.23	20.3117
2835.87	21.4234
2838.52	23.1128
2841.16	24.9888
2843.8	28.1286
2846.44	31.4091
2849.08	35.3279
2851.73	39.9865
2854.36	44.5654
2857	49.3492
2859.64	53.6055
2862.28	58.463
2864.91	62.7986
2867.55	66.2982
2870.18	69.5276
2872.81	72.6905
2875.44	75.1604
2878.07	78.5816
2880.7	81.2909
2883.33	84.6416
2885.96	87.1377
2888.59	90.2296
2891.21	93.2382
2893.84	95.4831
2896.46	97.2221
2899.09	99.2142
2901.71	102.794
2904.33	107.112
2906.95	112.765
2909.57	118.733
2912.19	124.849
2914.81	129.811
2917.43	135.382
2920.04	139.532
2922.66	142.603
2925.27	145.643
2927.88	147.41
2930.5	148.308
2933.11	148.485
2935.72	147.483
2938.33	146.361
2940.94	143.946
2943.54	142.285
2946.15	138.682
2948.76	134.438
2951.36	130.882
2953.97	126.038
2956.57	120.475
2959.17	115.226
2961.77	109.883
2964.37	105.803
2966.97	102.331
2969.57	97.765
2972.17	94.226
2974.77	90.6746
2977.36	86.1276
2979.96	81.5416
2982.55	76.991
2985.15	72.3399
2987.74	67.3967
2990.33	62.7517
2992.92	57.9084
2995.51	54.8065
2998.1	50.1985
3000.69	45.2482
3003.27	41.942
3005.86	38.4456
3008.44	35.4731
3011.03	32.4124
3013.61	30.2118
3016.19	28.2274
3018.78	26.3135
3021.36	25.3649
3023.94	23.6415
3026.51	23.4923
3029.09	22.569
3031.67	22.8335
3034.24	22.8244
3036.82	23.3305
3039.39	23.0197
3041.97	22.7286
3044.54	23.1753
3047.11	23.4727
3049.68	23.1709
3052.25	22.7164
3054.82	21.9473
3057.39	20.1337
3059.96	19.2939
3062.52	17.6922
3065.09	16.5119
3067.65	15.9631
3070.22	14.9175
3072.78	14.2004
3075.34	13.566
3077.9	12.6687
3080.46	11.7659
3083.02	11.2261
3085.58	9.6768
3088.14	9.0014
3090.69	7.78093
3093.25	7.72667
3095.8	7.43506
3098.36	6.70485
3100.91	6.63917
3103.46	5.76404
3106.01	5.1687
3108.56	4.6802
3111.11	4.03938
3113.66	3.26253
3116.21	3.17603
3118.76	2.15715
3121.3	1.8788
3123.85	1.79068
3126.39	1.21248
3128.93	1.60521
3131.48	1.68699
3134.02	1.27795
3136.56	0.826363
3139.1	0.323789
3141.64	0.413123
3144.17	-0.306069
3146.71	-1.38292
3149.25	-2.60043