File: data/Raman/poly_smoothed/Thy_30_10_25_1x_45s_532 nm_x100_100%_600 gr_mm_01.txt
#Acq. time (s)=	45
#Accumulations=	2
#Range (cm-¹)=	200...3150
#Windows=	2
#Auto scanning=	Off
#Autofocus=	Off
#Macrospot=	Off
#AutoExposure=	Off
#Spike filter=	Multiple accum.
#Delay time (s)=	0
#Binning=	1
#Readout mode=	Signal
#DeNoise=	Off
#ICS correction=	On
#Dark correction=	Off
#Inst. Process=	Off
#Detector Gain=	Best Dynamic Range
#Detector ADC=	20 kHz
#Detector temperature (°C)=	-69.85
#Instrument=	LabRAM HR Evol
#Detector=	Synapse
#Objective=	x100
#Grating=	600 gr/mm
#ND Filter=	100%
#Laser (nm)=	532
#Hole=	100.021
#Range=	Auto
#Laser Pol.=	No
#Raman. Pol.=	No
#Laser Pol. (°)=	-0.0007625
#Raman Pol. (°)=	89.9995
#Collection=	Microscope
#StageXY=	Marzhauser
#StageZ=	Marzhauser
#X (µm)=	4766.8
#Y (µm)=	-7717.9
#Z (µm)=	584.7
#Full time(mm:ss)=	3:19
#Project=
#Sample=
#Site=
#Title=	Thy_30_10_25_2x_45s_532 nm_x100_100%_600 gr_mm
#Remark=
#Date=	30.06.2022 13:17
#Acquired=	30.06.2022 13:17:31
#Base:Fit=	10.08.2022 09:58:11
#Base:Sub=	10.08.2022 09:58:44
#Filter:Polynom=	16.08.2022 10:22:53
#AxisType[0]=Intens
#AxisUnit[0]=Cnt
#AxisType[1]=Spectr
#AxisUnit[1]=1/cm
200.533	3.07825
204.162	4.19406
207.792	2.71672
211.418	2.61575
215.044	2.58924
218.667	4.01114
222.289	4.39039
225.912	4.24611
229.531	3.72908
233.148	6.94789
236.766	7.19541
240.381	7.6527
243.994	7.79604
247.606	9.33126
251.217	10.6416
254.828	11.1033
258.436	10.9673
262.042	9.67719
265.647	8.71234
269.25	7.97975
272.852	7.89525
276.453	7.46836
280.052	8.04551
283.65	7.87341
287.247	7.91501
290.842	7.60828
294.436	6.0087
298.028	7.46267
301.617	5.59171
305.206	6.86882
308.794	7.88996
312.381	8.73557
315.964	9.31513
319.548	11.4689
323.131	12.5729
326.71	12.3682
330.29	11.9239
333.868	11.9292
337.443	12.4446
341.018	11.3002
344.591	9.4821
348.163	8.91316
351.733	8.41698
355.303	6.80667
358.869	6.90414
362.435	7.884
366.001	8.41705
369.563	8.29121
373.124	9.15451
376.686	9.28969
380.244	8.75075
383.801	9.73608
387.357	11.0626
390.911	13.0481
394.466	14.1872
398.018	15.522
401.568	14.8198
405.117	14.1889
408.664	14.7135
412.21	12.5876
415.755	11.3548
419.298	9.85705
422.84	10.3074
426.38	8.44141
429.919	6.57513
433.455	5.84885
436.992	4.69173
440.527	4.13565
444.06	4.26278
447.593	4.91193
451.122	4.62071
454.651	4.9399
458.18	6.10878
461.705	6.01956
465.23	7.89219
468.752	7.5875
472.275	8.30276
475.797	7.84303
479.315	8.10491
482.834	9.88051
486.349	10.6769
489.863	11.292
493.378	12.3845
496.889	13.6242
500.401	15.1595
503.91	15.5357
507.417	15.2626
510.923	16.3647
514.43	16.3628
517.933	16.872
521.435	17.5239
524.936	18.8883
528.435	19.5994
531.933	19.4403
535.43	18.8184
538.927	17.9177
542.421	18.8216
545.913	18.2273
549.403	16.4625
552.893	15.1439
556.381	12.1446
559.868	11.8844
563.354	10.5198
566.839	10.4696
570.322	9.34501
573.802	8.10822
577.283	6.15622
580.762	4.56332
584.24	3.4803
587.714	1.37525
591.19	1.78209
594.663	1.74194
598.134	2.98569
601.605	1.93408
605.073	2.17685
608.542	3.18335
612.007	4.30681
615.473	4.95438
618.936	7.0655
622.397	8.42292
625.859	9.54557
629.318	9.73375
632.775	10.9857
636.233	12.997
639.688	12.5084
643.142	14.146
646.594	14.5739
650.045	15.0413
653.496	13.1711
656.944	13.6295
660.391	13.104
663.837	11.7147
667.281	10.2899
670.724	10.3267
674.166	11.0403
677.606	11.3785
681.045	11.6179
684.483	11.8998
687.917	12.5732
691.352	15.4702
694.786	16.4129
698.219	19.8275
701.65	21.8372
705.078	24.5437
708.506	28.3414
711.934	32.0082
715.358	35.9494
718.782	39.2292
722.204	42.8101
725.626	45.2685
729.045	48.2776
732.464	51.1308
735.881	53.8355
739.297	56.1095
742.711	58.9636
746.125	59.7005
749.537	60.474
752.946	61.8782
756.357	64.808
759.764	66.9762
763.17	68.3443
766.575	68.3253
769.978	69.9471
773.382	70.8917
776.783	71.9999
780.182	72.6965
783.581	74.3402
786.978	74.1545
790.373	73.6664
793.768	75.3469
797.161	74.3284
800.552	74.1136
803.941	75.1237
807.33	77.3959
810.718	76.9131
814.105	77.7395
817.49	78.3565
820.873	78.765
824.256	78.6339
827.637	78.0948
831.016	78.1805
834.395	78.0533
837.772	78.8025
841.147	78.9822
844.522	75.3387
847.894	74.2102
851.267	71.9469
854.637	70.9347
858.007	69.2946
861.374	66.628
864.739	64.3871
868.106	61.9298
871.469	59.355
874.831	57.8831
878.193	55.0639
881.553	54.7296
884.911	55.3094
888.268	54.8137
891.623	53.1515
894.978	51.8871
898.331	51.222
901.683	50.1374
905.033	50.2139
908.383	49.7024
911.731	49.6302
915.078	48.7536
918.423	48.6504
921.768	46.253
925.111	44.5527
928.452	44.0209
931.791	42.5489
935.13	41.4866
938.468	40.0818
941.803	38.9953
945.139	35.5861
948.473	35.861
951.804	37.6975
955.136	38.1488
958.465	37.2913
961.794	36.912
965.12	38.8737
968.447	38.9982
971.771	40.3074
975.095	42.6466
978.417	43.8613
981.737	44.9379
985.057	47.1183
988.375	47.7012
991.691	48.2793
995.006	48.2778
998.32	48.254
1001.63	49.5005
1004.95	48.6598
1008.26	49.7113
1011.56	49.0946
1014.87	47.9157
1018.18	48.819
1021.48	48.3035
1024.79	48.2766
1028.09	48.124
1031.39	47.593
1034.69	46.1945
1037.99	41.2815
1041.29	39.6019
1044.58	37.1859
1047.88	35.3016
1051.17	33.1821
1054.46	31.5672
1057.75	29.2519
1061.04	28.0463
1064.33	26.2496
1067.62	24.6219
1070.9	23.8822
1074.19	23.2905
1077.47	22.146
1080.76	22.9993
1084.04	22.7257
1087.32	23.1339
1090.59	26.2979
1093.87	26.6364
1097.15	26.8956
1100.42	27.8699
1103.69	28.3658
1106.97	27.1428
1110.24	25.4463
1113.51	23.305
1116.77	20.2722
1120.04	17.1297
1123.31	15.7267
1126.57	12.2383
1129.83	10.1696
1133.1	8.6266
1136.36	5.9995
1139.62	5.01546
1142.87	4.57994
1146.13	3.82639
1149.38	3.33505
1152.64	2.51438
1155.89	2.45209
1159.14	2.62547
1162.39	2.81103
1165.64	2.3897
1168.89	4.07185
1172.14	3.30828
1175.38	2.92472
1178.63	3.24348
1181.87	2.06137
1185.11	1.63013
1188.35	2.73229
1191.59	3.13408
1194.83	3.72171
1198.07	5.24286
1201.3	7.69213
1204.53	11.3815
1207.77	12.949
1211	16.263
1214.23	20.336
1217.46	24.3107
1220.69	27.8788
1223.91	30.1929
1227.14	33.1791
1230.36	35.8082
1233.59	38.6619
1236.81	41.0388
1240.03	41.8928
1243.25	43.6524
1246.46	45.2156
1249.68	45.5674
1252.9	44.57
1256.11	44.6888
1259.32	45.4741
1262.54	45.5291
1265.75	47.8268
1268.96	47.5917
1272.16	49.1554
1275.37	50.0296
1278.57	52.3456
1281.78	54.2073
1284.98	55.8048
1288.18	57.1674
1291.38	59.053
1294.58	59.3759
1297.78	58.7795
1300.98	58.9378
1304.17	60.146
1307.37	61.8112
1310.56	63.5024
1313.76	65.0212
1316.95	65.1205
1320.14	64.5517
1323.32	65.63
1326.51	65.3734
1329.7	64.3441
1332.88	63.3694
1336.07	61.3507
1339.25	59.8273
1342.43	58.5906
1345.61	54.9789
1348.79	52.0143
1351.96	49.7619
1355.14	47.9231
1358.31	45.2369
1361.49	42.2266
1364.66	39.8735
1367.83	36.107
1371	33.3272
1374.17	30.3629
1377.34	28.3355
1380.5	27.7418
1383.67	27.1447
1386.83	28.6155
1390	27.2475
1393.16	27.0034
1396.32	26.1667
1399.48	27.1444
1402.64	28.6129
1405.79	27.948
1408.95	28.0913
1412.1	29.8925
1415.26	34.1748
1418.41	38.3703
1421.56	40.752
1424.71	44.1954
1427.86	49.3991
1431	54.7985
1434.15	58.8695
1437.29	61.0186
1440.44	62.3985
1443.58	65.3439
1446.72	65.7747
1449.86	66.283
1453	66.7303
1456.14	66.0219
1459.27	63.8024
1462.41	59.583
1465.54	55.5436
1468.67	50.5548
1471.81	45.091
1474.94	38.7036
1478.07	32.2368
1481.19	27.1175
1484.32	21.3065
1487.45	18.0754
1490.57	16.3688
1493.69	13.5515
1496.82	10.3689
1499.94	9.05779
1503.06	8.23148
1506.17	7.1268
1509.29	6.71649
1512.41	5.0953
1515.52	5.93559
1518.64	7.94373
1521.75	9.49372
1524.86	9.39309
1527.97	12.5108
1531.08	13.9732
1534.19	15.107
1537.29	17.1825
1540.4	19.2245
1543.5	21.9674
1546.61	24.5826
1549.71	28.7938
1552.81	32.4408
1555.91	36.6994
1559.01	40.3201
1562.11	43.8715
1565.2	47.0372
1568.29	50.4672
1571.39	53.2253
1574.48	55.6907
1577.57	58.2442
1580.66	61.5021
1583.75	62.9493
1586.84	66.1786
1589.93	65.5862
1593.01	64.3695
1596.1	64.5127
1599.18	64.3239
1602.26	63.5499
1605.34	61.1208
1608.42	58.834
1611.5	57.3413
1614.58	55.2101
1617.65	54.7975
1620.73	54.512
1623.8	56.7693
1626.87	58.293
1629.95	59.5504
1633.02	61.0803
1636.09	63.3899
1639.15	66.2359
1642.22	70.2789
1645.29	73.4906
1648.35	74.477
1651.42	77.0221
1654.48	79.3859
1657.54	80.2741
1660.6	79.3623
1663.66	77.673
1666.72	75.4269
1669.77	72.0147
1672.83	68.8603
1675.88	63.6796
1678.93	56.8357
1681.99	49.7924
1685.04	43.8705
1688.09	38.4479
1691.13	32.2195
1694.18	27.8664
1697.23	23.4056
1700.27	19.633
1703.32	15.2034
1706.36	11.4378
1709.4	8.46734
1712.44	5.90762
1715.48	3.73238
1718.52	1.47652
1721.56	0.991035
1724.59	-0.373424
1727.63	-0.750327
1730.66	-0.166848
1733.69	-0.510331
1736.72	-0.672445
1739.75	0.0619294
1742.78	0.637688
1745.81	0.307436
1748.84	1.43991
1751.86	2.07065
1754.89	1.67037
1757.91	2.58262
1760.93	2.89015
1763.95	3.62357
1766.97	3.66651
1769.99	3.14942
1773.01	2.40573
1776.03	1.8195
1779.04	1.85652
1782.06	1.30085
1785.07	0.46484
1788.08	0.104245
1791.09	0.68889
1794.1	1.19162
1797.11	0.972329
1800.12	0.996948
1803.12	1.95592
1806.13	2.71536
1809.13	3.36012
1812.14	4.12436
1815.14	5.09763
1818.14	4.40951
1821.14	5.71387
1824.14	6.90003
1827.13	6.64518
1830.13	6.92541
1833.12	6.72224
1836.12	7.19215
1839.11	7.53373
1842.1	6.83961
1845.09	6.45162
1848.08	6.95848
1851.07	7.31287
1854.06	7.75294
1857.04	7.67155
1860.03	9.1267
1863.01	10.4298
1866	10.8145
1868.98	10.6759
1871.96	10.974
1874.94	11.6558
1877.92	12.6227
1880.89	12.6373
1882.48	12.9773
1885.47	12.573
1888.46	12.1988
1891.44	12.4606
1894.43	11.6962
1897.41	10.7757
1900.4	10.4717
1903.38	11.0293
1906.36	10.5515
1909.34	10.2859
1912.32	11.5456
1915.29	11.2016
1918.27	11.273
1921.25	13.1632
1924.22	13.513
1927.2	13.7359
1930.17	15.4929
1933.14	15.7064
1936.11	15.5055
1939.08	14.3763
1942.05	14.6689
1945.01	15.6568
1947.98	16.3708
1950.94	17.3686
1953.91	17.1889
1956.87	16.9653
1959.83	16.1609
1962.79	16.1039
1965.75	15.4898
1968.71	16.0556
1971.67	17.082
1974.62	17.1745
1977.58	17.7782
1980.53	17.217
1983.48	18.0813
1986.43	17.9283
1989.38	18.1911
1992.33	17.7546
1995.28	18.0068
1998.23	17.6697
2001.18	17.9437
2004.12	18.1069
2007.06	16.4475
2010.01	16.0192
2012.95	16.0245
2015.89	17.1784
2018.83	17.1619
2021.77	17.6197
2024.71	18.0438
2027.64	18.2187
2030.58	19.1842
2033.51	20.1773
2036.45	20.3064
2039.38	20.8523
2042.31	21.5092
2045.24	21.409
2048.17	22.2288
2051.1	22.6666
2054.02	22.5578
2056.95	23.9728
2059.87	24.3162
2062.8	26.281
2065.72	26.5462
2068.64	27.8183
2071.56	28.4238
2074.48	29.1433
2077.4	29.9209
2080.31	29.5767
2083.23	30.792
2086.14	31.5833
2089.06	32.6984
2091.97	33.4982
2094.88	34.2065
2097.79	35.5322
2100.7	36.0122
2103.61	37.0045
2106.52	37.7274
2109.43	38.9705
2112.33	40.0142
2115.24	41.8925
2118.14	43.6569
2121.04	45.4227
2123.94	46.9898
2126.84	50.0917
2129.74	53.8438
2132.64	56.9031
2135.54	60.3327
2138.43	63.1989
2141.33	66.7103
2144.22	69.7091
2147.11	72.9782
2150.01	75.6242
2152.9	77.3044
2155.79	79.714
2158.67	81.0986
2161.56	82.0183
2164.45	82.4388
2167.33	83.6829
2170.22	85.2318
2173.1	85.6559
2175.98	85.6695
2178.86	85.4694
2181.74	84.6303
2184.62	83.3922
2187.5	82.16
2190.38	78.8471
2193.25	76.658
2196.13	74.3139
2199	71.9834
2201.88	69.1074
2204.75	67.7696
2207.62	64.981
2210.49	62.882
2213.36	59.8908
2216.22	57.54
2219.09	54.0387
2221.96	51.7364
2224.82	48.3013
2227.68	45.22
2230.55	43.6222
2233.41	42.4396
2236.27	41.3864
2239.12	40.6087
2241.98	39.7074
2244.84	38.9581
2247.7	37.8015
2250.55	36.2325
2253.41	35.4758
2256.26	34.8189
2259.11	32.957
2261.96	33.2863
2264.81	32.809
2267.66	32.2208
2270.51	31.4165
2273.35	29.6836
2276.2	29.0525
2279.04	27.9407
2281.89	26.4853
2284.73	24.3186
2287.57	22.7588
2290.41	20.2358
2293.25	18.8924
2296.09	17.7032
2298.93	18.6741
2301.76	19.5646
2304.6	19.8201
2307.44	21.2361
2310.27	21.1452
2313.1	21.6173
2315.93	20.7203
2318.76	20.6816
2321.59	21.0112
2324.42	21.76
2327.25	21.5667
2330.07	20.5195
2332.9	20.5761
2335.72	20.5451
2338.55	20.0136
2341.37	18.4437
2344.19	17.1458
2347.01	15.2951
2349.83	13.0608
2352.65	10.8615
2355.46	9.34579
2358.28	7.73341
2361.09	7.18947
2363.91	7.36447
2366.72	8.02273
2369.53	9.13475
2372.34	8.98806
2375.15	8.16128
2377.96	8.18426
2380.77	7.95207
2383.58	7.81564
2386.38	7.38169
2389.19	7.59421
2391.99	7.20106
2394.8	7.54765
2397.6	8.01672
2400.4	8.98386
2403.2	10.6433
2406	10.8278
2408.79	10.4548
2411.59	11.2083
2414.39	11.0001
2417.18	10.7588
2419.98	10.8407
2422.77	11.5128
2425.56	12.4627
2428.35	12.7564
2431.14	12.3038
2433.93	12.7997
2436.72	13.2217
2439.5	12.442
2442.29	12.3036
2445.07	11.6257
2447.86	11.4571
2450.64	11.0162
2453.42	9.82729
2456.2	8.57764
2458.98	8.26989
2461.76	6.78531
2464.54	6.23952
2467.32	6.36823
2470.09	5.90844
2472.87	5.38201
2475.64	5.35629
2478.41	5.16621
2481.18	5.93417
2483.95	5.58915
2486.72	5.7115
2489.49	6.22575
2492.26	5.71924
2495.03	6.16085
2497.79	5.63872
2500.56	5.07767
2503.32	4.68349
2506.09	4.0461
2508.85	3.34714
2511.61	3.24342
2514.37	2.81743
2517.13	2.93353
2519.89	1.88079
2522.64	1.49289
2525.4	0.895217
2528.15	1.11771
2530.91	0.931892
2533.66	1.35256
2536.41	1.49592
2539.16	1.84803
2541.91	1.85043
2544.66	2.64325
2547.41	2.67268
2550.16	3.34598
2552.9	3.35997
2555.65	3.64064
2558.39	4.13669
2561.13	4.70598
2563.88	5.66672
2566.62	5.79258
2569.36	5.97667
2572.1	6.36995
2574.84	6.26051
2577.57	6.17221
2580.31	6.5478
2583.05	5.94277
2585.78	5.15899
2588.51	4.29356
2591.24	4.24931
2593.98	3.77311
2596.71	2.82101
2599.44	0.8154
2602.16	0.178273
2604.89	-0.0314167
2607.62	-0.875364
2610.34	-1.50477
2613.07	-1.49821
2615.79	-2.29017
2618.52	-1.94703
2621.24	-1.81235
2623.96	-1.67633
2626.68	-0.303466
2629.4	0.412014
2632.11	0.979671
2634.83	1.51752
2637.55	2.05406
2640.26	1.77326
2642.98	2.397
2645.69	3.14695
2648.4	3.12521
2651.11	3.51325
2653.82	3.06525
2656.53	3.04198
2659.24	2.83338
2661.95	2.60476
2664.65	3.01648
2667.36	2.92969
2670.06	3.11714
2672.76	2.28175
2675.47	2.25961
2678.17	1.64675
2680.87	1.22822
2683.57	1.23736
2686.27	1.18797
2688.97	1.03157
2691.66	0.341436
2694.36	0.303787
2697.05	-0.0331666
2699.75	-0.137496
2702.44	-0.0598784
2705.13	0.476133
2707.82	0.565809
2710.51	1.65169
2713.2	1.9676
2715.89	1.98542
2718.57	2.71868
2721.26	3.88204
2723.95	4.15105
2726.63	4.93078
2729.31	5.20335
2732	5.4362
2734.68	5.98505
2737.36	5.9081
2740.04	6.31814
2742.72	6.59697
2745.39	5.94364
2748.07	5.57234
2750.75	5.98031
2753.42	5.54233
2756.09	4.4205
2758.77	2.69538
2761.44	2.75963
2764.11	2.96432
2766.78	2.59953
2769.45	1.68213
2772.12	1.83933
2774.78	1.94823
2777.45	1.30808
2780.12	1.51745
2782.78	1.78302
2785.44	2.07723
2788.11	1.25815
2790.77	0.705752
2793.43	1.50596
2796.09	2.19035
2798.75	2.09499
2801.4	1.87278
2804.06	1.95633
2806.72	0.764029
2809.37	1.06015
2812.03	0.400863
2814.68	0.331262
2817.33	0.889068
2819.98	1.08774
2822.63	3.21197
2825.28	6.05053
2827.93	9.25788
2830.58	12.8049
2833.23	15.5872
2835.87	19.176
2838.52	23.4215
2841.16	27.988
2843.8	33.6058
2846.44	40.8309
2849.08	47.5368
2851.73	55.4881
2854.36	64.2556
2857	73.0431
2859.64	81.1764
2862.28	88.9185
2864.91	95.8876
2867.55	102.772
2870.18	108.189
2872.81	111.998
2875.44	117.465
2878.07	120.977
2880.7	124.841
2883.33	129.214
2885.96	133.542
2888.59	137.773
2891.21	141.716
2893.84	145.351
2896.46	149.26
2899.09	154.315
2901.71	160.142
2904.33	167.629
2906.95	176.404
2909.57	185.578
2912.19	196.505
2914.81	206.648
2917.43	216.806
2920.04	225.476
2922.66	233.489
2925.27	239.114
2927.88	242.567
2930.5	244.327
2933.11	244.284
2935.72	242.432
2938.33	240.394
2940.94	235.943
2943.54	229.097
2946.15	222.294
2948.76	214.17
2951.36	206.256
2953.97	197.698
2956.57	187.779
2959.17	179.728
2961.77	171.258
2964.37	162.234
2966.97	153.82
2969.57	146.548
2972.17	138.842
2974.77	132.913
2977.36	125.147
2979.96	117.583
2982.55	110.586
2985.15	101.963
2987.74	94.303
2990.33	86.6233
2992.92	79.1068
2995.51	70.6227
2998.1	64.6301
3000.69	58.6518
3003.27	52.2914
3005.86	46.5316
3008.44	41.9232
3011.03	37.3178
3013.61	33.555
3016.19	29.5169
3018.78	26.9487
3021.36	25.2731
3023.94	23.6055
3026.51	22.0448
3029.09	21.2882
3031.67	20.493
3034.24	21.6409
3036.82	22.4379
3039.39	23.2563
3041.97	23.407
3044.54	24.1969
3047.11	25.2356
3049.68	25.8256
3052.25	25.6615
3054.82	25.3891
3057.39	25.3884
3059.96	24.2071
3062.52	23.6813
3065.09	21.9461
3067.65	20.5687
3070.22	19.0818
3072.78	17.7675
3075.34	15.9823
3077.9	14.1475
3080.46	12.852
3083.02	11.1713
3085.58	10.007
3088.14	8.65243
3090.69	7.5833
3093.25	6.91077
3095.8	7.04454
3098.36	6.61753
3100.91	6.63281
3103.46	6.14052
3106.01	5.32704
3108.56	5.82022
3111.11	5.77829
3113.66	5.4708
3116.21	5.05197
3118.76	4.93849
3121.3	4.43011
3123.85	3.88359
3126.39	3.12256
3128.93	2.81801
3131.48	3.1938
3134.02	2.78329
3136.56	2.16714
3139.1	1.00694
3141.64	0.19843
3144.17	-0.486795
3146.71	-1.58604
3149.25	-2.31965