File: data/Raman/poly_smoothed/Thy_40_11_14_1x_45s_532 nm_x100_100%_600 gr_mm_01.txt
#Acq. time (s)=	45
#Accumulations=	2
#Range (cm-¹)=	200...3150
#Windows=	2
#Auto scanning=	Off
#Autofocus=	Off
#Macrospot=	Off
#AutoExposure=	Off
#Spike filter=	Multiple accum.
#Delay time (s)=	0
#Binning=	1
#Readout mode=	Signal
#DeNoise=	Off
#ICS correction=	On
#Dark correction=	Off
#Inst. Process=	Off
#Detector Gain=	Best Dynamic Range
#Detector ADC=	20 kHz
#Detector temperature (°C)=	-69.85
#Instrument=	LabRAM HR Evol
#Detector=	Synapse
#Objective=	x100
#Grating=	600 gr/mm
#ND Filter=	100%
#Laser (nm)=	532
#Hole=	100.021
#Range=	Auto
#Laser Pol.=	No
#Raman. Pol.=	No
#Laser Pol. (°)=	-0.0007625
#Raman Pol. (°)=	89.9995
#Collection=	Microscope
#StageXY=	Marzhauser
#StageZ=	Marzhauser
#X (µm)=	1958
#Y (µm)=	-57.7
#Z (µm)=	425.3
#Full time(mm:ss)=	3:18
#Project=
#Sample=
#Site=
#Title=	Thy_40_11_14_2x_45s_532 nm_x100_100%_600 gr_mm
#Remark=
#Date=	05.07.2022 10:53
#Acquired=	05.07.2022 10:53:55
#Base:Fit=	10.08.2022 10:01:35
#Base:Sub=	10.08.2022 10:01:52
#Filter:Polynom=	16.08.2022 10:21:53
#AxisType[0]=Intens
#AxisUnit[0]=Cnt
#AxisType[1]=Spectr
#AxisUnit[1]=1/cm
200.43	29.4585
204.059	23.1342
207.688	19.1769
211.314	15.5039
214.941	11.8927
218.564	9.096
222.186	7.01827
225.809	4.2617
229.428	3.90685
233.045	2.8179
236.663	1.04373
240.278	0.853871
243.891	0.816962
247.503	0.487244
251.116	2.11577
254.725	3.53516
258.333	3.91916
261.939	4.30895
265.544	5.42054
269.148	6.93247
272.75	7.99403
276.351	9.16129
279.95	10.9732
283.548	11.8365
287.144	13.6371
290.739	14.8711
294.333	15.5321
297.925	16.6622
301.514	17.7396
305.104	18.0649
308.692	19.8928
312.279	20.9867
315.862	21.3479
319.446	22.3725
323.029	22.1433
326.608	19.5414
330.188	20.4875
333.766	18.7549
337.341	18.6939
340.917	18.0024
344.489	16.5072
348.062	14.8618
351.631	14.0673
355.201	13.5855
358.768	13.1007
362.333	13.7821
365.899	13.5112
369.462	11.4495
373.023	9.24845
376.585	8.97437
380.143	8.96697
383.7	10.3046
387.256	9.7187
390.812	9.22321
394.365	9.67339
397.916	9.80438
401.467	8.24372
405.015	7.50752
408.563	5.96278
412.109	5.08146
415.654	4.97739
419.197	5.73575
422.739	5.74215
426.279	5.84782
429.819	5.13869
433.356	4.49621
436.891	5.88679
440.426	5.76785
443.96	6.31911
447.492	6.45334
451.021	6.26147
454.551	7.24325
458.079	7.81966
461.604	9.97516
465.13	13.0091
468.654	12.9849
472.175	12.9167
475.696	13.1045
479.215	13.1289
482.733	14.8583
486.249	15.1055
489.765	15.7798
493.278	14.3549
496.789	15.6474
500.301	17.0882
503.81	17.0353
507.317	16.2993
510.825	16.6357
514.33	16.3576
517.833	14.648
521.335	15.3748
524.836	15.3058
528.335	15.886
531.835	16.8107
535.332	16.9477
538.827	18.3974
542.321	18.332
545.814	19.892
549.305	19.3227
552.795	19.0452
556.282	17.9469
559.769	16.9864
563.255	17.7645
566.739	16.3397
570.223	15.2782
573.705	12.5911
577.183	10.3614
580.663	8.73862
584.141	8.20862
587.615	5.38593
591.09	4.86975
594.564	4.00357
598.035	4.66991
601.506	3.72291
604.974	4.99837
608.443	6.2037
611.908	6.43116
615.374	6.48741
618.837	6.22894
622.3	8.8225
625.761	9.45643
629.219	10.7615
632.677	12.6672
636.135	13.12
639.59	15.0133
643.043	15.8776
646.495	17.8319
649.948	19.3508
653.398	20.4623
656.846	21.5849
660.293	23.0742
663.738	23.4272
667.183	24.0256
670.626	25.4419
674.067	26.6482
677.508	28.5979
680.947	29.3529
684.385	30.3536
687.821	31.2777
691.254	32.1872
694.688	31.9825
698.121	33.0423
701.552	34.3052
704.98	35.8794
708.409	36.8002
711.836	37.2289
715.26	39.3976
718.685	41.3221
722.108	43.3049
725.528	43.3588
728.949	44.5011
732.367	46.5816
735.785	49.8036
739.2	51.5261
742.614	52.8312
746.028	54.5719
749.439	54.9043
752.849	58.0742
756.26	60.652
759.667	62.5425
763.073	65.8538
766.477	68.163
769.883	69.8882
773.285	71.7459
776.686	74.4466
780.085	75.8792
783.484	77.676
786.881	78.893
790.276	80.1237
793.671	82.5238
797.064	82.7814
800.456	83.2187
803.846	81.8728
807.234	80.5426
810.622	79.0405
814.008	79.0055
817.394	79.1511
820.778	80.2361
824.159	79.5825
827.541	79.2615
830.921	78.5992
834.298	77.5019
837.676	76.1653
841.051	75.0614
844.426	73.5638
847.798	72.3002
851.171	69.401
854.54	67.9935
857.911	67.9434
861.278	66.2192
864.645	63.4008
868.01	62.2413
871.373	61.1665
874.735	61.2166
878.097	59.486
881.457	58.0237
884.815	57.3067
888.172	56.4528
891.528	55.7943
894.882	55.2032
898.237	54.7224
901.589	54.7622
904.94	55.3874
908.289	53.6242
911.635	52.9602
914.982	50.4355
918.328	47.8302
921.672	46.9846
925.015	45.3336
928.357	42.6276
931.698	40.7014
935.035	39.7382
938.373	37.7749
941.71	37.156
945.044	34.853
948.378	33.3429
951.709	33.9134
955.041	35.2197
958.372	34.7152
961.699	34.1764
965.027	34.1889
968.352	35.7677
971.676	36.7592
975	37.1358
978.322	37.2842
981.642	38.2666
984.962	38.9689
988.28	37.9488
991.596	37.3875
994.911	36.2784
998.227	34.8221
1001.54	33.0851
1004.85	32.6308
1008.16	30.137
1011.47	29.1704
1014.78	27.0981
1018.08	24.6825
1021.39	24.3172
1024.69	23.8227
1028	23.7994
1031.3	24.0864
1034.6	23.7304
1037.9	22.2762
1041.19	22.4649
1044.49	21.899
1047.78	22.4058
1051.08	22.0755
1054.37	20.2155
1057.66	19.7455
1060.95	20.9053
1064.24	19.9493
1067.53	18.4112
1070.81	19.2121
1074.1	18.8268
1077.38	17.7896
1080.66	17.1611
1083.94	16.0751
1087.22	16.202
1090.5	15.6832
1093.78	16.3982
1097.05	14.6536
1100.33	14.6389
1103.6	14.6954
1106.87	15.0494
1110.14	13.48
1113.41	13.4862
1116.68	12.7301
1119.95	12.652
1123.21	11.0139
1126.48	8.73577
1129.74	7.8227
1133	6.95268
1136.26	6.35821
1139.52	8.04076
1142.78	8.1463
1146.04	6.59963
1149.29	5.63656
1152.55	5.5586
1155.8	4.78545
1159.05	3.88755
1162.3	3.19309
1165.55	1.1213
1168.8	2.92818
1172.05	2.30792
1175.29	1.37241
1178.54	0.87726
1181.78	1.85823
1185.02	2.19308
1188.26	4.02881
1191.5	4.82404
1194.74	5.91462
1197.97	6.82365
1201.21	8.59588
1204.44	10.7796
1207.68	13.1207
1210.91	16.7294
1214.14	18.8151
1217.37	21.9624
1220.59	24.1449
1223.82	27.7883
1227.05	29.3466
1230.27	31.7702
1233.49	33.3427
1236.72	35.2062
1239.94	36.9603
1243.16	37.0829
1246.37	39.5182
1249.59	42.9385
1252.8	42.7026
1256.02	44.2936
1259.23	47.031
1262.44	50.335
1265.66	50.9608
1268.86	53.6137
1272.07	54.8518
1275.28	56.6165
1278.48	58.5157
1281.69	60.306
1284.89	62.5091
1288.09	64.4679
1291.29	65.5589
1294.49	67.6805
1297.69	68.0364
1300.89	68.1104
1304.08	68.356
1307.28	67.5287
1310.47	67.0709
1313.66	66.0421
1316.85	64.8
1320.04	63.4258
1323.23	62.3442
1326.42	61.0012
1329.61	60.0316
1332.79	58.6234
1335.97	58.1176
1339.16	56.7741
1342.34	55.2943
1345.52	54.0667
1348.7	51.9307
1351.87	49.7343
1355.05	48.303
1358.22	48.0295
1361.4	48.4579
1364.57	45.3644
1367.74	44.4332
1370.91	42.387
1374.08	40.9324
1377.25	39.1502
1380.41	37.8923
1383.58	36.7133
1386.74	34.5417
1389.91	32.4205
1393.07	29.1733
1396.23	27.7998
1399.39	27.2556
1402.55	25.6854
1405.7	24.7155
1408.86	24.0478
1412.01	24.7384
1415.17	26.5079
1418.32	27.9753
1421.47	31.1527
1424.62	33.9753
1427.77	37.5018
1430.91	42.804
1434.06	46.9312
1437.2	51.807
1440.35	54.6809
1443.49	56.9423
1446.63	58.0893
1449.77	58.9489
1452.91	59.6306
1456.05	59.4373
1459.18	57.8576
1462.32	55.9241
1465.45	53.2973
1468.59	49.5236
1471.72	46.1216
1474.85	41.7581
1477.98	36.08
1481.1	31.6944
1484.23	26.6961
1487.36	23.1397
1490.48	20.9622
1493.61	18.9648
1496.73	16.4404
1499.85	16.0028
1502.97	13.8429
1506.09	15.4466
1509.2	17.5093
1512.32	17.2517
1515.43	18.2601
1518.55	17.8846
1521.66	19.0847
1524.77	19.8969
1527.88	22.4346
1530.99	25.48
1534.1	27.4743
1537.21	30.0985
1540.31	33.2305
1543.42	35.7096
1546.52	39.4026
1549.62	41.5548
1552.72	44.0916
1555.82	46.8545
1558.92	49.9378
1562.02	51.2574
1565.11	53.9268
1568.21	55.7677
1571.3	58.2341
1574.39	60.3379
1577.49	61.0182
1580.57	61.5011
1583.66	64.1015
1586.75	62.8012
1589.84	60.6204
1592.92	61.3371
1596.01	60.5103
1599.09	59.2627
1602.17	57.1817
1605.25	56.6588
1608.33	54.658
1611.41	53.6271
1614.49	54.1941
1617.57	53.8085
1620.64	54.769
1623.72	55.507
1626.79	55.7433
1629.86	58.413
1632.93	60.7646
1636	61.7882
1639.07	65.6483
1642.13	68.6991
1645.2	69.7912
1648.26	71.5738
1651.33	72.7834
1654.39	72.1877
1657.45	73.202
1660.51	73.4916
1663.57	71.0616
1666.63	69.6035
1669.68	67.3483
1672.74	62.613
1675.79	58.2412
1678.85	53.4457
1681.9	48.0909
1684.95	43.1624
1688	39.4706
1691.05	34.1734
1694.09	29.6046
1697.14	26.36
1700.18	23.4208
1703.23	19.7158
1706.27	17.7037
1709.31	15.2566
1712.35	14.5395
1715.39	12.3064
1718.43	9.62809
1721.47	8.65769
1724.5	7.82138
1727.54	7.1373
1730.57	5.90041
1733.61	6.01318
1736.64	5.16989
1739.67	4.25117
1742.7	3.32064
1745.72	2.82043
1748.75	2.89833
1751.77	2.42859
1754.8	1.24806
1757.82	0.797167
1760.84	2.0322
1763.87	1.76625
1766.89	1.9962
1769.91	2.96114
1772.92	3.33499
1775.94	1.96307
1778.95	2.34715
1781.97	2.16806
1784.98	3.09534
1787.99	2.7044
1791.01	2.43514
1794.01	2.31158
1797.02	2.25494
1800.03	2.541
1803.04	2.26066
1806.04	2.90069
1809.05	2.98155
1812.05	3.49775
1815.05	5.12175
1818.05	5.95205
1821.05	6.68778
1824.05	6.22435
1827.05	5.75349
1830.04	5.44069
1833.04	6.0546
1836.03	6.89844
1839.03	6.4034
1842.02	5.99809
1845.01	5.58222
1848	4.78038
1850.99	4.14975
1853.97	4.47625
1856.96	4.08827
1859.94	4.53851
1862.93	3.34261
1865.91	3.28602
1868.89	2.97625
1871.87	2.82113
1874.85	1.92531
1877.83	1.70885
1880.81	3.60805
1882.57	4.41779
1885.56	4.15439
1888.55	4.29866
1891.54	3.47481
1894.52	3.56093
1897.51	3.83066
1900.49	4.45934
1903.47	5.11339
1906.45	5.89484
1909.43	4.97156
1912.41	4.9597
1915.39	6.02955
1918.37	6.77281
1921.34	7.36035
1924.32	7.29792
1927.29	7.66354
1930.26	7.72272
1933.23	7.21849
1936.2	7.90186
1939.17	6.60409
1942.14	5.76122
1945.11	5.01907
1948.07	4.47508
1951.04	4.42021
1954	4.03635
1956.96	2.61032
1959.93	2.0401
1962.89	2.03722
1965.85	1.62009
1968.8	2.62677
1971.76	2.52803
1974.72	2.22678
1977.67	1.34297
1980.63	2.19333
1983.58	2.91515
1986.53	3.39825
1989.48	4.95685
1992.43	5.28151
1995.38	5.94119
1998.32	6.93947
2001.27	7.80921
2004.22	9.38697
2007.16	9.27981
2010.1	9.05548
2013.04	8.42722
2015.98	9.09843
2018.92	9.28654
2021.86	10.2871
2024.8	10.9588
2027.74	10.9354
2030.67	11.8562
2033.61	12.1455
2036.54	13.1253
2039.47	12.514
2042.4	13.0784
2045.33	13.1215
2048.26	13.3186
2051.19	12.6383
2054.12	13.3872
2057.04	13.7396
2059.97	14.692
2062.89	15.2376
2065.81	15.9968
2068.73	17.3248
2071.65	16.6192
2074.57	16.9271
2077.49	16.9059
2080.41	17.6634
2083.32	19.3967
2086.24	20.4473
2089.15	22.2386
2092.07	23.7932
2094.98	24.991
2097.89	25.2856
2100.8	27.032
2103.71	28.8281
2106.61	30.3266
2109.52	32.4772
2112.43	34.2331
2115.33	36.6865
2118.23	38.2772
2121.13	40.2609
2124.04	42.2798
2126.94	45.0038
2129.83	48.0491
2132.73	51.1082
2135.63	53.5409
2138.53	55.1395
2141.42	57.1739
2144.31	60.5645
2147.21	64.1718
2150.1	67.2558
2152.99	70.1316
2155.88	72.7849
2158.77	75.7009
2161.65	77.26
2164.54	78.4839
2167.43	79.6858
2170.31	79.7034
2173.19	80.0081
2176.07	79.6651
2178.96	79.7006
2181.84	78.732
2184.72	77.4212
2187.59	75.19
2190.47	72.5771
2193.35	70.469
2196.22	67.4426
2199.09	65.0909
2201.97	60.8658
2204.84	56.3077
2207.71	52.9906
2210.58	49.3538
2213.45	47.985
2216.31	45.6777
2219.18	43.6872
2222.05	41.6444
2224.91	40.4118
2227.78	38.6997
2230.64	36.9706
2233.5	34.9717
2236.36	33.6184
2239.22	30.4272
2242.08	29.32
2244.93	29.19
2247.79	28.5163
2250.64	28.0244
2253.5	27.5357
2256.35	27.1052
2259.2	26.2288
2262.05	26.3564
2264.9	25.8155
2267.75	25.0557
2270.6	23.5094
2273.45	21.6467
2276.29	21.6581
2279.14	21.2119
2281.98	20.4295
2284.82	21.0464
2287.66	19.9342
2290.5	19.1735
2293.34	17.1903
2296.18	16.1044
2299.02	15.5644
2301.86	14.9146
2304.69	14.7008
2307.53	15.2148
2310.36	15.9938
2313.19	16.3082
2316.02	16.2203
2318.85	15.5339
2321.68	15.6186
2324.51	15.4117
2327.34	15.3956
2330.16	15.1563
2332.99	14.6203
2335.81	13.1617
2338.64	11.5795
2341.46	10.4565
2344.28	9.41187
2347.1	8.04339
2349.92	6.20553
2352.74	5.4053
2355.55	3.98086
2358.37	2.72675
2361.19	2.05205
2364	1.88617
2366.81	2.50137
2369.62	2.85953
2372.44	2.38984
2375.24	3.54757
2378.05	3.52063
2380.86	3.20826
2383.67	3.53326
2386.47	3.58136
2389.28	3.82322
2392.08	3.97259
2394.89	3.34423
2397.69	4.52791
2400.49	4.88288
2403.29	4.77605
2406.09	5.06799
2408.88	5.44064
2411.68	6.65719
2414.48	7.09981
2417.27	7.62933
2420.06	9.29497
2422.86	10.442
2425.65	11.1462
2428.44	10.8678
2431.23	11.2761
2434.02	11.1357
2436.81	10.2662
2439.59	9.95038
2442.38	10.2949
2445.16	10.5717
2447.95	9.68539
2450.73	9.35045
2453.51	9.17988
2456.29	7.40865
2459.07	7.05429
2461.85	5.98895
2464.63	5.84743
2467.4	6.17957
2470.18	6.07487
2472.95	4.73487
2475.73	3.81057
2478.5	4.38813
2481.27	5.7268
2484.04	6.74712
2486.81	7.50529
2489.58	7.86896
2492.35	6.96147
2495.12	7.10833
2497.88	6.58512
2500.65	7.49222
2503.41	6.63604
2506.17	6.17467
2508.94	6.45409
2511.7	7.0763
2514.46	5.72839
2517.22	4.81536
2519.97	5.23903
2522.73	5.58609
2525.49	5.05611
2528.24	4.63995
2530.99	5.09531
2533.75	6.17876
2536.5	6.14656
2539.25	5.57279
2542	5.65605
2544.75	6.56587
2547.5	7.30656
2550.24	8.40151
2552.99	8.46111
2555.74	8.16961
2558.48	7.71137
2561.22	7.48594
2563.96	7.88747
2566.71	7.38749
2569.45	6.2597
2572.18	5.38662
2574.92	4.39608
2577.66	3.19408
2580.4	2.92926
2583.13	2.30349
2585.87	2.96021
2588.6	2.26057
2591.33	1.7042
2594.06	1.27339
2596.79	2.28992
2599.52	2.27886
2602.25	2.88941
2604.98	3.01325
2607.71	2.42187
2610.43	2.23958
2613.16	2.5027
2615.88	2.39068
2618.6	1.95544
2621.32	3.47767
2624.04	3.11794
2626.76	3.12386
2629.48	3.64508
2632.2	3.51398
2634.92	2.61861
2637.63	2.93182
2640.35	2.33955
2643.06	2.36071
2645.77	2.24927
2648.49	2.37143
2651.2	2.33577
2653.91	1.76848
2656.62	2.12649
2659.33	3.53014
2662.03	3.97058
2664.74	4.69502
2667.44	4.79898
2670.15	4.91565
2672.85	4.42145
2675.55	4.66047
2678.26	4.38417
2680.96	3.56249
2683.66	3.47857
2686.35	3.88546
2689.05	4.12114
2691.75	3.70048
2694.44	4.13159
2697.14	3.63892
2699.83	3.12725
2702.52	2.90601
2705.22	2.13311
2707.91	1.43253
2710.6	1.67255
2713.29	1.14405
2715.97	1.5275
2718.66	1.38423
2721.35	1.53388
2724.03	2.86593
2726.72	3.05333
2729.4	3.15151
2732.08	3.7552
2734.76	4.57383
2737.44	4.936
2740.12	5.49512
2742.8	5.91998
2745.48	5.47012
2748.16	5.60959
2750.83	6.47748
2753.51	7.13517
2756.18	6.82218
2758.85	6.80026
2761.53	6.49651
2764.2	5.34613
2766.87	4.90905
2769.54	4.01876
2772.2	3.32796
2774.87	2.90956
2777.54	2.65789
2780.2	2.32689
2782.87	2.31414
2785.53	1.90679
2788.19	1.73921
2790.85	2.02368
2793.51	1.87575
2796.17	1.40009
2798.83	0.806894
2801.49	0.479874
2804.15	0.245419
2806.8	0.272909
2809.46	-0.335728
2812.11	0.743446
2814.76	1.25979
2817.42	1.6251
2820.07	2.6996
2822.72	3.26204
2825.37	5.49264
2828.02	7.7643
2830.66	8.6952
2833.31	10.5205
2835.96	13.3812
2838.6	15.7923
2841.24	19.8014
2843.89	24.1563
2846.53	29.6462
2849.17	34.0823
2851.81	39.7762
2854.45	44.6963
2857.09	50.3048
2859.72	54.7636
2862.36	59.2934
2865	63.8057
2867.63	69.9441
2870.26	73.7171
2872.9	77.4791
2875.53	81.8622
2878.16	85.2957
2880.79	88.0604
2883.42	90.8069
2886.05	93.9626
2888.67	97.4637
2891.3	100.589
2893.92	103.318
2896.55	106.953
2899.17	110.447
2901.79	115.937
2904.42	121.747
2907.04	129.259
2909.66	137.83
2912.27	146.424
2914.89	154.177
2917.51	162.087
2920.13	168.804
2922.74	175.56
2925.35	180.027
2927.97	184.797
2930.58	187.417
2933.19	188.135
2935.8	188.706
2938.41	187.116
2941.02	185
2943.63	181.234
2946.24	176.814
2948.84	171.361
2951.45	165.839
2954.05	157.621
2956.65	150.461
2959.26	142.684
2961.86	135.106
2964.46	127.805
2967.06	121.217
2969.66	115.127
2972.25	109.569
2974.85	102.577
2977.45	96.7137
2980.04	90.3919
2982.64	84.3371
2985.23	78.1773
2987.82	71.6365
2990.41	64.4816
2993	57.8345
2995.59	52.4474
2998.18	47.4049
3000.77	41.3709
3003.36	36.1667
3005.94	31.6313
3008.53	27.7723
3011.11	23.3652
3013.69	20.4075
3016.28	16.3599
3018.86	13.7706
3021.44	11.9516
3024.02	9.92303
3026.6	9.09676
3029.18	8.77178
3031.75	9.4913
3034.33	9.59358
3036.9	10.8518
3039.48	12.1002
3042.05	13.3444
3044.62	14.3696
3047.19	15.5088
3049.77	16.3199
3052.34	16.3414
3054.9	16.8906
3057.47	17.3371
3060.04	16.8152
3062.61	15.6391
3065.17	14.5406
3067.74	13.7611
3070.3	12.8294
3072.86	11.0745
3075.42	9.25886
3077.99	7.09608
3080.54	6.09457
3083.1	4.3291
3085.66	2.22108
3088.22	1.69363
3090.78	1.17734
3093.33	0.446332
3095.89	0.587924
3098.44	0.17188
3100.99	0.479262
3103.54	-0.160929
3106.1	-0.83555
3108.65	-0.335243
3111.2	0.477542
3113.74	0.881322
3116.29	1.28998
3118.84	1.48729
3121.38	1.93607
3123.93	1.9137
3126.47	3.04719
3129.01	3.24583
3131.56	3.7733
3134.1	4.47485
3136.64	5.0291
3139.18	5.54823
3141.72	6.34525
3144.26	7.14295
3146.79	8.29581
3149.33	9.76899