File: data/Raman/poly_smoothed/Thy_10_08_48_1x_45s_532 nm_x100_100%_600 gr_mm_01.txt
#Acq. time (s)=	45
#Accumulations=	2
#Range (cm-¹)=	200...3150
#Windows=	2
#Auto scanning=	Off
#Autofocus=	Off
#Macrospot=	Off
#AutoExposure=	Off
#Spike filter=	Multiple accum.
#Delay time (s)=	0
#Binning=	1
#Readout mode=	Signal
#DeNoise=	Off
#ICS correction=	On
#Dark correction=	Off
#Inst. Process=	Off
#Detector Gain=	Best Dynamic Range
#Detector ADC=	20 kHz
#Detector temperature (°C)=	-69.85
#Instrument=	LabRAM HR Evol
#Detector=	Synapse
#Objective=	x100
#Grating=	600 gr/mm
#ND Filter=	100%
#Laser (nm)=	532
#Hole=	100.021
#Range=	Auto
#Laser Pol.=	No
#Raman. Pol.=	No
#Laser Pol. (°)=	-0.0007625
#Raman Pol. (°)=	89.9995
#Collection=	Microscope
#StageXY=	Marzhauser
#StageZ=	Marzhauser
#X (µm)=	-2356.6
#Y (µm)=	255
#Z (µm)=	521.65
#Full time(mm:ss)=	3:18
#Project=
#Sample=
#Site=
#Title=	Thy_10_08_48_2x_45s_532 nm_x100_100%_600 gr_mm
#Remark=
#Date=	06.07.2022 15:18
#Acquired=	06.07.2022 15:18:45
#Base:Fit=	10.08.2022 09:46:25
#Base:Sub=	10.08.2022 09:46:49
#Filter:Polynom=	16.08.2022 10:24:56
#AxisType[0]=Intens
#AxisUnit[0]=Cnt
#AxisType[1]=Spectr
#AxisUnit[1]=1/cm
200.398	2.36895
204.027	2.20991
207.657	2.36016
211.283	3.40878
214.909	3.70179
218.533	3.4068
222.157	3.27458
225.777	2.84343
229.396	3.26574
233.016	3.71181
236.632	4.13858
240.247	3.08538
243.86	3.04523
247.474	3.17151
251.085	2.11726
254.694	1.98549
258.301	2.24663
261.908	1.60286
265.513	2.62335
269.116	2.6041
272.718	2.98979
276.319	3.63616
279.918	4.9642
283.516	5.1137
287.113	5.12805
290.708	6.47885
294.302	7.06514
297.894	7.75195
301.485	7.80925
305.073	8.05186
308.661	8.51455
312.247	9.29751
315.833	9.56813
319.415	8.8112
322.997	8.54646
326.579	8.04237
330.156	7.4826
333.735	9.46387
337.31	10.315
340.885	9.90279
344.458	9.85788
348.03	9.92538
351.6	9.67953
355.17	9.89923
358.737	10.0419
362.304	10.6102
365.868	11.5796
369.431	10.678
372.994	10.5087
376.554	10.1595
380.112	9.01532
383.669	9.25475
387.225	9.36463
390.781	9.89897
394.334	9.72109
397.885	9.27723
401.436	8.70419
404.984	8.31637
408.532	9.26077
412.078	8.81474
415.623	10.2746
419.166	10.8159
422.708	12.127
426.248	10.8739
429.788	9.1214
433.326	8.39161
436.86	7.1292
440.395	6.73744
443.929	7.4305
447.461	7.47304
450.99	7.55773
454.52	7.24787
458.048	6.98433
461.573	7.32112
465.099	8.74731
468.623	9.19829
472.144	9.79189
475.666	11.2959
479.184	13.1023
482.703	13.7125
486.218	14.8474
489.734	15.0029
493.247	16.1442
496.759	17.9364
500.271	18.0908
503.779	19.0301
507.287	19.7726
510.795	19.5596
514.299	19.098
517.803	19.1151
521.305	19.5731
524.805	20.7132
528.307	21.9609
531.805	22.4099
535.301	22.3052
538.797	22.2375
542.291	22.9169
545.783	23.2766
549.275	23.9876
552.765	22.8205
556.253	23.0475
559.738	21.7118
563.224	20.2315
566.709	17.7622
570.192	16.0687
573.674	13.3006
577.153	11.7374
580.632	10.835
584.11	9.38825
587.587	7.73909
591.06	6.84237
594.534	6.09563
598.005	3.30656
601.476	2.22589
604.944	2.5756
608.413	2.66944
611.878	2.94571
615.344	3.34085
618.807	3.41052
622.27	4.91712
625.73	7.35647
629.189	8.61067
632.648	10.7035
636.105	12.352
639.559	13.2179
643.013	13.3334
646.467	14.1789
649.918	15.0484
653.368	15.5955
656.816	16.0655
660.263	17.2278
663.708	18.7424
667.153	19.1213
670.596	19.2703
674.037	19.8893
677.478	20.7197
680.917	21.7868
684.355	22.5371
687.791	23.9639
691.224	25.4105
694.658	28.5002
698.091	31.7469
701.522	34.0584
704.95	36.3544
708.379	37.0899
711.806	39.5774
715.23	41.6782
718.655	43.5656
722.078	44.4446
725.498	45.7997
728.919	46.5461
732.337	46.6482
735.755	46.8165
739.17	48.7924
742.584	49.9308
745.998	52.0182
749.409	54.4818
752.819	57.4416
756.23	59.9321
759.637	61.3299
763.043	63.206
766.448	65.0897
769.853	67.48
773.255	70.344
776.656	73.8979
780.056	75.2309
783.454	76.8475
786.851	76.8513
790.247	76.9211
793.641	79.7211
797.034	82.9118
800.426	82.9581
803.817	82.7738
807.206	83.766
810.592	84.3805
813.979	83.8382
817.364	85.2543
820.748	85.3992
824.129	86.5237
827.511	86.1943
830.891	87.041
834.269	86.1664
837.646	83.9583
841.023	81.7041
844.396	80.0336
847.77	76.5423
851.141	75.3812
854.513	72.7592
857.881	69.9792
861.248	66.9081
864.616	64.7277
867.98	64.4206
871.343	62.3691
874.707	62.8472
878.068	62.7523
881.428	62.3138
884.786	61.8164
888.143	62.1102
891.498	62.7964
894.855	62.079
898.208	61.8081
901.56	62.5642
904.91	62.8671
908.26	62.9767
911.608	62.7044
914.955	61.336
918.298	59.0771
921.643	58.8647
924.986	58.5566
928.328	56.5328
931.668	55.1669
935.006	53.8359
938.344	53.1979
941.681	50.5686
945.014	48.7211
948.349	47.197
951.682	45.7556
955.012	43.3258
958.343	40.0609
961.67	37.7714
964.998	38.6414
968.323	38.806
971.649	38.4159
974.971	37.9081
978.293	39.0619
981.615	39.7782
984.933	38.6573
988.251	38.8876
991.567	37.2669
994.884	35.0127
998.198	34.317
1001.51	33.4993
1004.82	32.472
1008.13	31.8337
1011.44	32.4384
1014.75	32.5478
1018.06	31.7831
1021.36	30.0715
1024.66	28.6445
1027.97	26.1614
1031.27	25.533
1034.57	22.1436
1037.87	19.9706
1041.16	20.2664
1044.46	21.6772
1047.76	22.9342
1051.05	22.0185
1054.34	21.6594
1057.63	21.8336
1060.92	22.1651
1064.21	20.6545
1067.5	20.157
1070.78	20.0256
1074.07	18.6328
1077.35	17.6792
1080.63	17.7392
1083.91	17.8023
1087.19	17.9193
1090.47	18.8328
1093.75	18.2092
1097.03	16.3952
1100.3	15.5318
1103.57	15.4118
1106.84	15.3227
1110.11	14.6026
1113.38	13.1324
1116.65	12.7262
1119.92	12.0049
1123.19	11.9489
1126.45	10.597
1129.71	9.63493
1132.97	8.20572
1136.23	8.20951
1139.49	7.74428
1142.75	7.54546
1146.01	6.8073
1149.26	6.61561
1152.52	5.79789
1155.77	4.72518
1159.02	3.25604
1162.27	2.54779
1165.52	1.79733
1168.77	2.47262
1172.02	1.96357
1175.26	2.22811
1178.51	2.75173
1181.75	3.99684
1184.99	3.84483
1188.23	6.09209
1191.47	6.20124
1194.71	7.64235
1197.94	8.90813
1201.18	10.7147
1204.41	13.014
1207.65	14.8871
1210.88	16.7481
1214.11	20.2733
1217.34	24.0174
1220.57	27.4007
1223.79	30.9605
1227.02	35.2332
1230.24	37.9526
1233.47	38.6351
1236.69	40.6378
1239.91	42.9498
1243.13	44.8615
1246.34	46.114
1249.56	47.0211
1252.78	47.4965
1255.99	46.2419
1259.2	45.6585
1262.42	44.3884
1265.63	45.1881
1268.84	45.7319
1272.04	44.7964
1275.25	45.3023
1278.46	45.3433
1281.66	47.1094
1284.86	48.018
1288.07	49.6995
1291.27	50.9463
1294.47	52.9957
1297.66	54.2587
1300.86	55.5888
1304.06	58.2514
1307.25	60.3012
1310.44	60.285
1313.64	61.899
1316.83	64.2358
1320.02	64.6308
1323.2	65.2411
1326.39	65.0039
1329.58	62.8068
1332.76	61.7715
1335.95	60.4625
1339.13	58.1035
1342.31	56.6982
1345.49	53.9761
1348.67	51.5928
1351.85	49.3087
1355.02	47.276
1358.2	44.8272
1361.37	41.195
1364.54	38.309
1367.71	35.7551
1370.88	31.9399
1374.05	30.2211
1377.22	27.3408
1380.39	26.948
1383.55	25.8241
1386.72	25.0143
1389.88	25.28
1393.04	25.3125
1396.2	23.594
1399.36	22.2543
1402.52	22.0681
1405.68	22.8364
1408.83	24.3027
1411.98	25.8313
1415.14	27.6619
1418.29	31.7213
1421.44	37.7375
1424.59	42.1448
1427.74	49.1716
1430.89	54.6377
1434.03	58.0883
1437.18	62.2726
1440.32	64.0148
1443.46	66.8567
1446.6	67.5083
1449.74	68.1117
1452.88	68.0938
1456.02	66.5177
1459.16	63.4388
1462.29	59.8675
1465.43	55.3338
1468.56	49.6404
1471.69	43.0487
1474.82	35.6992
1477.95	31.0622
1481.08	25.1397
1484.2	21.597
1487.33	18.2977
1490.46	14.3771
1493.58	12.7678
1496.7	11.278
1499.82	11.5492
1502.94	9.64952
1506.06	10.1464
1509.18	8.48464
1512.29	7.19747
1515.41	6.63695
1518.52	6.67066
1521.63	7.40264
1524.75	7.25068
1527.85	7.73331
1530.96	8.26897
1534.07	8.69317
1537.18	8.50138
1540.28	11.236
1543.39	13.3878
1546.49	16.4218
1549.59	19.5057
1552.69	21.83
1555.79	24.5904
1558.89	27.7978
1561.99	29.8962
1565.08	31.1656
1568.18	33.7792
1571.27	37.2466
1574.37	40.7649
1577.46	43.8409
1580.55	46.4569
1583.64	48.5573
1586.73	50.2601
1589.81	51.2759
1592.9	52.7783
1595.98	52.1898
1599.06	52.7444
1602.15	51.5043
1605.23	51.4005
1608.31	51.0318
1611.39	50.904
1614.46	50.4949
1617.54	51.2095
1620.61	54.089
1623.69	55.2754
1626.76	55.2284
1629.83	56.3365
1632.9	57.6494
1635.97	59.4951
1639.04	60.7933
1642.11	64.2404
1645.17	66.9717
1648.24	68.3779
1651.3	70.7197
1654.36	72.7841
1657.42	72.7281
1660.48	73.6631
1663.54	72.2693
1666.6	69.9198
1669.66	66.6177
1672.71	63.8727
1675.77	60.199
1678.82	55.4907
1681.87	51.4046
1684.92	46.4937
1687.97	40.2028
1691.02	36.0939
1694.07	31.8142
1697.11	27.7912
1700.16	23.7763
1703.2	19.8728
1706.25	16.9961
1709.29	13.6926
1712.33	11.1038
1715.37	8.56122
1718.41	6.96725
1721.44	5.73857
1724.48	6.15127
1727.51	5.26981
1730.55	4.63978
1733.58	4.63644
1736.61	5.10952
1739.64	4.20588
1742.67	4.13896
1745.7	4.30148
1748.72	3.41557
1751.75	3.06659
1754.77	3.35393
1757.8	2.78435
1760.82	1.44038
1763.84	0.918171
1766.86	0.472454
1769.88	0.171633
1772.9	0.589721
1775.91	-0.686362
1778.93	-0.911731
1781.94	-0.956545
1784.96	-0.92568
1787.97	-0.963649
1790.98	-1.11304
1793.99	-0.928369
1797	-0.533141
1800.01	-0.226702
1803.01	0.101012
1806.02	0.790066
1809.02	0.997501
1812.02	0.843221
1815.02	0.207318
1818.03	-0.375772
1821.02	-0.290083
1824.02	0.317494
1827.02	-0.117612
1830.02	0.148293
1833.01	-0.0990338
1836.01	-0.375474
1839	0.961841
1841.99	0.912669
1844.98	1.4274
1847.97	1.22373
1850.96	1.87634
1853.95	2.86635
1856.93	3.64606
1859.92	3.65412
1862.9	3.23554
1865.88	3.72045
1868.87	3.65194
1871.85	4.13053
1874.83	4.28393
1877.81	4.35512
1880.78	4.99251
1882.53	4.81174
1885.52	5.41452
1888.51	6.01978
1891.5	7.39162
1894.48	7.97434
1897.47	8.49196
1900.45	8.6332
1903.43	9.40103
1906.41	9.02182
1909.39	9.21533
1912.37	9.57858
1915.35	9.79593
1918.33	9.63757
1921.3	10.0226
1924.28	10.8126
1927.25	9.95773
1930.22	10.308
1933.19	9.20952
1936.16	9.10214
1939.13	9.33982
1942.1	9.41845
1945.07	10.399
1948.03	9.95958
1951	10.1777
1953.96	10.5623
1956.92	11.1563
1959.88	11.2366
1962.84	11.1557
1965.8	11.1617
1968.76	11.0076
1971.72	10.6669
1974.67	9.86395
1977.63	8.95302
1980.58	8.3243
1983.54	8.39029
1986.49	8.65511
1989.44	8.5229
1992.39	8.62729
1995.33	9.10839
1998.28	10.6972
2001.23	10.9819
2004.17	12.1142
2007.12	13.1444
2010.06	13.5804
2013	14.3036
2015.94	13.4739
2018.88	13.2716
2021.82	12.4746
2024.76	13.0178
2027.69	13.8583
2030.63	14.5662
2033.56	15.1963
2036.5	14.688
2039.43	14.5904
2042.36	15.1464
2045.29	14.6134
2048.22	15.1663
2051.15	14.6424
2054.07	15.0428
2057	14.9757
2059.92	15.3296
2062.85	16.0911
2065.77	17.2996
2068.69	18.8889
2071.61	20.3663
2074.53	20.5435
2077.45	20.5562
2080.37	20.1096
2083.28	19.6104
2086.2	19.2012
2089.11	19.7984
2092.02	20.4218
2094.94	21.1396
2097.85	22.3071
2100.76	23.0971
2103.66	23.6027
2106.57	23.6142
2109.48	24.8279
2112.38	25.0713
2115.29	24.8218
2118.19	24.6252
2121.09	25.4385
2123.99	25.9534
2126.89	27.4146
2129.79	28.0501
2132.69	28.9041
2135.59	29.8113
2138.48	30.0781
2141.38	30.9477
2144.27	31.3236
2147.17	31.805
2150.06	31.9332
2152.95	33.2421
2155.84	34.4712
2158.73	35.2301
2161.61	36.3303
2164.5	36.6631
2167.38	38.0132
2170.27	38.6505
2173.15	39.8258
2176.03	41.0745
2178.91	42.2196
2181.8	42.5377
2184.67	41.8752
2187.55	42.2082
2190.43	42.3678
2193.3	42.3191
2196.18	41.7264
2199.05	40.2707
2201.93	38.3799
2204.8	36.746
2207.67	36.2254
2210.54	35.0009
2213.41	33.9753
2216.27	32.4697
2219.14	31.0452
2222.01	30.1147
2224.87	28.8622
2227.73	27.5415
2230.6	26.7195
2233.46	25.9855
2236.32	25.9467
2239.18	23.8807
2242.03	23.5485
2244.89	24.2002
2247.75	23.4909
2250.6	23.0994
2253.46	21.9029
2256.31	21.5123
2259.16	22.4069
2262.01	21.8649
2264.86	21.323
2267.71	21.5039
2270.56	20.5222
2273.4	20.2097
2276.25	19.7863
2279.09	20.653
2281.94	20.7684
2284.78	20.8675
2287.62	20.5578
2290.46	19.8382
2293.3	19.4716
2296.14	20.6627
2298.98	21.1335
2301.82	21.9558
2304.65	21.1581
2307.49	20.3001
2310.32	20.0358
2313.15	20.3771
2315.98	20.3033
2318.81	20.022
2321.64	19.0094
2324.47	19.2861
2327.3	19.9995
2330.12	19.7038
2332.95	18.7785
2335.77	17.9527
2338.6	16.4534
2341.42	15.2498
2344.24	14.9215
2347.06	15.4446
2349.88	14.5905
2352.7	13.3361
2355.51	12.9135
2358.33	12.0298
2361.14	12.9938
2363.96	13.3918
2366.77	14.7672
2369.58	13.7233
2372.39	12.9496
2375.2	11.6481
2378.01	11.3655
2380.82	11.2205
2383.63	11.021
2386.43	11.066
2389.24	10.2661
2392.04	10.6904
2394.84	11.978
2397.65	10.8448
2400.45	12.1466
2403.25	11.7049
2406.05	12.1512
2408.84	13.0992
2411.64	13.5575
2414.44	14.356
2417.23	13.9924
2420.02	13.6341
2422.82	15.3778
2425.61	16.0596
2428.4	16.3533
2431.19	16.7551
2433.98	16.5456
2436.77	16.1678
2439.55	15.7596
2442.34	14.9156
2445.12	14.1549
2447.91	13.2083
2450.69	13.0279
2453.47	12.3218
2456.25	11.9583
2459.03	11.8462
2461.81	11.5956
2464.59	11.1318
2467.36	10.9108
2470.14	10.7959
2472.92	10.3881
2475.69	10.1168
2478.46	9.83974
2481.23	10.2458
2484	9.99715
2486.77	9.75579
2489.54	9.51777
2492.31	9.24497
2495.08	8.74286
2497.84	8.1339
2500.61	7.71528
2503.37	7.18648
2506.13	7.0318
2508.9	6.33098
2511.66	6.32605
2514.42	5.69011
2517.18	5.29202
2519.93	4.22272
2522.69	4.41644
2525.45	4.70555
2528.2	4.70906
2530.95	4.77948
2533.71	4.93737
2536.46	4.56911
2539.21	4.35627
2541.96	4.84411
2544.71	4.46535
2547.46	5.46192
2550.2	6.69809
2552.95	6.55313
2555.7	6.72571
2558.44	6.90844
2561.18	6.7423
2563.93	6.28269
2566.67	6.44
2569.41	6.56292
2572.15	6.11627
2574.88	5.87618
2577.62	4.70172
2580.36	3.10184
2583.09	1.05901
2585.83	0.920492
2588.56	0.064911
2591.29	0.247558
2594.02	0.529471
2596.75	0.0812556
2599.48	0.0586519
2602.21	0.614509
2604.94	0.957198
2607.67	0.924878
2610.39	0.756547
2613.12	1.73532
2615.84	2.13183
2618.56	2.5606
2621.28	2.95109
2624.01	3.34483
2626.72	2.74231
2629.44	3.54718
2632.16	3.367
2634.88	3.34151
2637.59	2.78881
2640.31	1.88413
2643.02	0.801337
2645.74	0.264444
2648.45	0.278002
2651.16	0.111614
2653.87	-0.50618
2656.58	0.0965152
2659.29	0.578746
2661.99	1.44084
2664.7	1.89427
2667.41	2.16909
2670.11	3.25538
2672.81	2.80301
2675.51	2.50297
2678.22	2.30231
2680.92	3.10549
2683.62	3.14801
2686.31	3.12436
2689.01	3.58012
2691.71	3.35216
2694.4	3.45418
2697.1	4.04924
2699.79	4.20607
2702.49	5.18017
2705.18	6.15672
2707.87	6.80289
2710.56	7.8209
2713.25	7.74303
2715.94	8.13143
2718.62	8.90252
2721.31	10.3992
2723.99	11.7919
2726.68	12.2689
2729.36	12.8263
2732.04	12.5349
2734.73	12.3481
2737.41	12.5573
2740.08	11.4281
2742.76	11.396
2745.44	10.6363
2748.12	10.232
2750.79	9.37385
2753.47	9.00182
2756.14	7.97161
2758.81	7.03325
2761.49	6.20737
2764.16	5.88035
2766.83	5.7711
2769.5	5.20749
2772.16	4.07393
2774.83	3.37926
2777.5	3.40222
2780.16	3.30699
2782.83	3.11131
2785.49	2.56204
2788.15	2.65405
2790.82	2.08871
2793.48	1.35848
2796.14	0.723776
2798.79	0.181479
2801.45	0.756296
2804.11	0.279681
2806.76	0.021084
2809.42	0.0369237
2812.07	0.933758
2814.73	1.23976
2817.38	2.41744
2820.03	4.39345
2822.68	7.24761
2825.33	11.3999
2827.98	15.9362
2830.63	21.0108
2833.27	26.005
2835.92	32.0199
2838.56	38.4324
2841.21	46.1983
2843.85	54.6469
2846.49	63.932
2849.13	74.3971
2851.77	85.3782
2854.41	96.9021
2857.05	107.778
2859.69	117.589
2862.32	127.889
2864.96	137.036
2867.59	144.928
2870.23	152.329
2872.86	159.461
2875.49	165.032
2878.12	170.525
2880.75	177.224
2883.38	181.871
2886.01	187.794
2888.63	192.241
2891.26	196.228
2893.89	201.632
2896.51	206.095
2899.13	211.714
2901.76	219.026
2904.38	228.363
2907	240.147
2909.62	252.304
2912.24	265.967
2914.85	277.97
2917.47	290.244
2920.09	301.617
2922.7	310.062
2925.32	315.403
2927.93	319.468
2930.54	321.213
2933.15	320.538
2935.76	316.731
2938.37	311.203
2940.98	303.855
2943.59	295.826
2946.2	285.566
2948.8	274.406
2951.41	262.417
2954.01	249.995
2956.62	237.833
2959.22	225.246
2961.82	213.507
2964.42	202.96
2967.02	193.55
2969.62	185
2972.22	176.574
2974.81	167.355
2977.41	158.737
2980	150.096
2982.6	141.613
2985.19	131.793
2987.78	120.946
2990.38	111.658
2992.97	101.471
2995.56	91.713
2998.14	82.5981
3000.73	72.9477
3003.32	64.4899
3005.91	57.1033
3008.49	50.6699
3011.07	44.8217
3013.66	38.9829
3016.24	34.5579
3018.82	30.7116
3021.4	28.1463
3023.98	24.6531
3026.56	22.9454
3029.14	21.7902
3031.71	20.3963
3034.29	20.931
3036.87	21.4893
3039.44	22.178
3042.01	23.4362
3044.59	24.9058
3047.16	26.5648
3049.73	27.4442
3052.3	27.9547
3054.87	28.6874
3057.43	28.7501
3060	28.2087
3062.57	27.1822
3065.13	25.9139
3067.7	24.8147
3070.26	23.8082
3072.82	21.5273
3075.39	19.164
3077.95	17.173
3080.51	14.9041
3083.07	12.5394
3085.63	10.3596
3088.18	8.12097
3090.74	6.50079
3093.29	5.29936
3095.85	4.67244
3098.4	4.08457
3100.95	3.48057
3103.51	2.89476
3106.06	2.5664
3108.61	2.65255
3111.16	2.76526
3113.71	2.37543
3116.25	2.99963
3118.8	3.205
3121.35	2.67489
3123.89	2.5618
3126.44	2.37517
3128.98	2.55595
3131.52	2.83447
3134.06	2.10993
3136.6	1.30158
3139.14	0.971364
3141.68	0.236363
3144.22	-1.09131
3146.76	-2.86858
3149.29	-3.88313