File: data/Raman/poly_smoothed/Thy_20_09_30_1x_45s_532 nm_x100_100%_600 gr_mm_01.txt
#Acq. time (s)=	45
#Accumulations=	2
#Range (cm-¹)=	200...3150
#Windows=	2
#Auto scanning=	Off
#Autofocus=	Off
#Macrospot=	Off
#AutoExposure=	Off
#Spike filter=	Multiple accum.
#Delay time (s)=	0
#Binning=	1
#Readout mode=	Signal
#DeNoise=	Off
#ICS correction=	On
#Dark correction=	Off
#Inst. Process=	Off
#Detector Gain=	Best Dynamic Range
#Detector ADC=	20 kHz
#Detector temperature (°C)=	-69.85
#Instrument=	LabRAM HR Evol
#Detector=	Synapse
#Objective=	x100
#Grating=	600 gr/mm
#ND Filter=	100%
#Laser (nm)=	532
#Hole=	100.021
#Range=	Auto
#Laser Pol.=	No
#Raman. Pol.=	No
#Laser Pol. (°)=	-0.0007625
#Raman Pol. (°)=	89.9995
#Collection=	Microscope
#StageXY=	Marzhauser
#StageZ=	Marzhauser
#X (µm)=	-5923.4
#Y (µm)=	2881
#Z (µm)=	-223.3
#Full time(mm:ss)=	3:18
#Project=
#Sample=
#Site=
#Title=	Thy_20_09_30_2x_45s_532 nm_x100_100%_600 gr_mm
#Remark=
#Date=	29.06.2022 12:44
#Acquired=	29.06.2022 12:44:53
#Base:Fit=	10.08.2022 09:52:02
#Base:Fit=	10.08.2022 09:52:12
#Base:Sub=	10.08.2022 09:54:21
#Filter:Polynom=	16.08.2022 10:24:04
#AxisType[0]=Intens
#AxisUnit[0]=Cnt
#AxisType[1]=Spectr
#AxisUnit[1]=1/cm
200.523	22.9603
204.154	17.7735
207.781	12.7819
211.409	8.73896
215.034	7.09378
218.659	8.32388
222.281	8.36678
225.903	7.11535
229.522	6.25711
233.14	8.36803
236.756	9.62649
240.373	10.2273
243.986	11.5159
247.598	13.4353
251.208	15.2923
254.818	16.0053
258.427	16.7632
262.034	20.188
265.638	20.95
269.242	19.6658
272.844	18.0786
276.445	16.6331
280.044	14.9227
283.642	14.1743
287.238	10.9496
290.833	9.01522
294.425	7.68395
298.017	7.66956
301.608	8.86473
305.198	11.1578
308.786	10.5643
312.371	9.90277
315.956	8.99266
319.54	12.1507
323.122	14.2524
326.701	15.3576
330.281	18.2851
333.857	20.313
337.434	20.9921
341.008	21.5449
344.582	21.2234
348.153	22.3094
351.724	23.5745
355.292	21.9648
358.861	19.7092
362.426	17.9925
365.99	17.5732
369.555	17.2545
373.116	16.3089
376.676	16.458
380.236	17.6832
383.793	18.2252
387.349	19.3039
390.903	20.4414
394.456	21.0916
398.007	21.3653
401.56	20.4323
405.108	20.1356
408.656	22.9715
412.202	24.6495
415.746	26.2165
419.29	27.3564
422.831	28.3652
426.37	28.1363
429.909	28.5082
433.447	27.6038
436.983	26.1274
440.519	26.3488
444.052	24.6282
447.583	23.6805
451.114	23.1814
454.643	23.2913
458.169	21.6216
461.696	21.0295
465.222	20.6514
468.744	21.1692
472.267	20.8377
475.787	22.8831
479.307	24.1685
482.823	22.7637
486.341	22.7253
489.855	24.0325
493.37	26.3761
496.881	28.9367
500.391	33.0039
503.902	33.4962
507.409	35.5967
510.915	34.8368
514.42	34.1032
517.925	34.5738
521.427	34.6838
524.928	36.225
528.427	35.4142
531.925	33.7983
535.422	31.3526
538.917	30.5409
542.411	28.9772
545.903	26.9026
549.395	26.309
552.884	26.0874
556.373	25.8502
559.86	25.349
563.346	24.3162
566.831	21.7656
570.314	20.0525
573.794	20.2447
577.274	19.3878
580.754	18.285
584.23	17.13
587.706	14.7382
591.181	12.1302
594.653	8.84373
598.126	6.37583
601.595	6.7244
605.065	6.24661
608.532	6.87939
611.999	7.99305
615.463	7.62602
618.928	7.67659
622.389	7.70353
625.851	9.82412
629.31	9.44979
632.767	11.6003
636.223	14.3464
639.68	16.0376
643.134	15.3382
646.586	16.559
650.037	18.2993
653.486	19.5144
656.936	19.954
660.383	19.3456
663.829	19.6159
667.273	20.9811
670.716	19.9984
674.158	18.9758
677.598	19.3841
681.035	21.7485
684.473	23.447
687.909	26.1013
691.344	27.4995
694.778	29.9656
698.211	30.8771
701.64	33.5067
705.07	34.3105
708.498	36.0659
711.924	40.2835
715.35	44.4043
718.774	45.7172
722.196	45.566
725.618	47.2333
729.037	48.3184
732.456	51.304
735.873	50.3874
739.289	48.9815
742.703	49.9528
746.116	51.9477
749.529	54.4298
752.938	55.3436
756.347	55.4744
759.756	58.3286
763.162	60.4865
766.567	62.9483
769.97	65.4142
773.372	67.1576
776.773	68.7401
780.174	70.7826
783.573	73.4962
786.97	77.0583
790.365	80.2534
793.76	84.0183
797.153	86.6463
800.543	88.1598
803.933	87.9382
807.322	87.3405
810.71	89.3643
814.097	87.6242
817.483	85.4389
820.865	83.702
824.248	84.2736
827.629	83.3821
831.008	81.4017
834.387	78.233
837.765	73.6971
841.139	71.074
844.514	69.0497
847.886	67.6682
851.259	64.2455
854.629	61.799
857.997	60.2061
861.366	57.6827
864.732	57.3544
868.098	57.6314
871.461	57.4001
874.823	54.6841
878.184	52.6763
881.545	51.5632
884.903	50.1563
888.26	47.5517
891.616	47.8748
894.97	48.4889
898.323	48.1875
901.675	48.4413
905.026	47.1603
908.375	43.8172
911.723	35.3415
915.07	31.7141
918.415	33.7007
921.76	37.2442
925.103	40.6607
928.443	42.6372
931.783	43.6422
935.123	46.5458
938.461	47.8698
941.796	46.9677
945.131	45.9412
948.465	45.7499
951.797	42.5062
955.128	39.5379
958.457	37.1074
961.786	35.7791
965.113	37.7568
968.44	38.4161
971.763	38.9921
975.086	39.5314
978.409	38.2287
981.729	37.2277
985.048	33.6453
988.367	29.6395
991.683	25.4185
994.998	27.8457
998.312	36.694
1001.62	38.1819
1004.94	39.3957
1008.25	38.8162
1011.56	39.4224
1014.86	38.8658
1018.17	38.0293
1021.48	33.8105
1024.78	31.0518
1028.08	30.4983
1031.38	27.9065
1034.68	25.471
1037.98	22.8582
1041.28	22.3712
1044.57	23.9806
1047.87	23.6337
1051.16	19.9056
1054.45	17.0772
1057.75	14.4843
1061.04	12.7397
1064.32	13.1219
1067.61	13.3877
1070.9	13.3881
1074.18	14.6019
1077.47	16.4967
1080.75	15.8499
1084.03	14.769
1087.31	14.8788
1090.59	14.78
1093.86	13.6059
1097.14	14.2191
1100.41	16.0737
1103.69	15.0873
1106.96	15.0867
1110.23	12.9635
1113.5	12.1608
1116.77	11.1833
1120.03	9.80818
1123.3	9.08094
1126.56	7.97115
1129.83	5.63799
1133.09	3.72347
1136.35	0.854491
1139.61	2.42833
1142.86	4.68204
1146.12	7.84628
1149.38	9.6966
1152.63	9.20959
1155.88	8.50115
1159.14	9.02162
1162.39	9.91525
1165.63	11.3699
1168.88	12.117
1172.13	13.3853
1175.38	15.9424
1178.62	17.7986
1181.86	17.8282
1185.1	18.0943
1188.34	18.185
1191.58	19.3562
1194.82	20.6258
1198.06	22.8051
1201.29	23.0107
1204.53	27.3607
1207.76	29.5681
1210.99	32.0271
1214.22	35.3759
1217.45	44.1333
1220.68	50.8896
1223.91	56.558
1227.13	61.8059
1230.36	66.1588
1233.58	70.7306
1236.8	75.9763
1240.02	81.257
1243.24	85.7167
1246.46	90.3701
1249.67	95.6213
1252.89	99.7147
1256.1	102.842
1259.32	104.882
1262.53	107.054
1265.74	107.711
1268.95	111.021
1272.15	113.163
1275.36	115.192
1278.57	119.097
1281.77	121.916
1284.97	124.694
1288.18	128.303
1291.38	132.453
1294.58	136.081
1297.78	140.008
1300.97	143.389
1304.17	146.819
1307.36	151.489
1310.55	156.82
1313.75	160.864
1316.94	167.101
1320.13	171.374
1323.32	174.846
1326.5	177.422
1329.69	179.166
1332.87	179.722
1336.06	180.71
1339.24	179.321
1342.42	176.547
1345.6	174.55
1348.78	171.294
1351.96	167.911
1355.13	163.094
1358.31	158.247
1361.48	151.082
1364.65	144.551
1367.82	138.539
1370.99	131.938
1374.16	125.872
1377.33	120.992
1380.5	117.772
1383.66	115.499
1386.83	111.854
1389.99	108.956
1393.15	105.084
1396.31	101.052
1399.47	98.255
1402.63	96.2194
1405.78	95.0575
1408.94	94.9863
1412.1	94.6356
1415.25	97.8137
1418.4	99.7622
1421.55	102.664
1424.7	107.151
1427.85	111.922
1431	115.743
1434.14	120.206
1437.29	124.73
1440.43	129.125
1443.57	131.702
1446.71	132.191
1449.85	132.234
1452.99	131.527
1456.13	129.227
1459.26	126.779
1462.4	121.686
1465.54	114.912
1468.67	108.218
1471.8	101.744
1474.93	94.447
1478.06	86.0794
1481.19	78.7004
1484.31	73.4652
1487.44	67.5924
1490.56	62.7147
1493.69	60.3893
1496.81	55.2199
1499.93	53.4415
1503.05	52.2005
1506.17	51.9534
1509.28	50.8581
1512.4	50.7261
1515.52	51.9033
1518.63	52.8818
1521.74	54.9473
1524.85	56.4181
1527.96	59.2063
1531.07	63.8748
1534.18	67.8115
1537.29	71.1693
1540.39	77.3793
1543.5	84.5949
1546.6	91.6132
1549.7	97.5979
1552.8	103.053
1555.9	109.677
1559	116.252
1562.1	122.969
1565.19	129.429
1568.29	137.624
1571.38	144.836
1574.47	149.752
1577.56	156.238
1580.66	160.771
1583.74	165.114
1586.83	169.113
1589.92	173.005
1593.01	174.628
1596.09	174.012
1599.17	171.616
1602.25	169.224
1605.34	166.01
1608.41	162.44
1611.49	158.318
1614.57	154.65
1617.65	148.95
1620.72	143.647
1623.79	138.998
1626.87	133.312
1629.94	129.729
1633.01	125.838
1636.08	123.297
1639.15	122.833
1642.21	121.903
1645.28	122.723
1648.34	121.908
1651.41	123.763
1654.47	122.97
1657.53	121.332
1660.59	121.082
1663.65	119.446
1666.71	115.896
1669.76	112.003
1672.82	106.757
1675.87	101.151
1678.93	95.8452
1681.98	89.6172
1685.03	81.7055
1688.08	73.8043
1691.13	66.2858
1694.17	60.0317
1697.22	54.1013
1700.27	46.9472
1703.31	41.7246
1706.35	35.9267
1709.39	32.1108
1712.43	29.025
1715.47	25.7168
1718.51	23.9368
1721.55	22.5159
1724.58	20.6185
1727.62	17.7017
1730.65	14.6591
1733.68	14.0259
1736.72	12.4634
1739.74	11.0062
1742.77	8.63474
1745.8	7.10943
1748.83	6.08897
1751.85	5.51311
1754.88	4.76322
1757.9	3.35358
1760.92	0.596397
1763.95	-0.226651
1766.96	-0.254723
1769.98	0.620177
1773	-0.861812
1776.02	-1.00332
1779.03	-1.33938
1782.05	-0.825198
1785.06	-1.12596
1788.07	0.043365
1791.08	0.18553
1794.09	0.107803
1797.1	0.712885
1800.11	-0.0931722
1803.12	0.123391
1806.12	0.486791
1809.12	-0.197774
1812.13	0.32991
1815.13	1.63905
1818.13	2.58167
1821.13	3.4216
1824.13	4.60112
1827.13	4.68781
1830.12	5.23091
1833.12	4.81175
1836.11	5.22217
1839.1	6.69284
1842.09	6.41828
1845.09	5.82392
1848.08	5.03289
1851.06	3.94328
1854.05	4.15213
1857.04	4.34961
1860.02	3.77693
1863.01	4.19575
1865.99	3.77927
1868.97	3.35471
1871.95	2.3329
1874.93	2.34478
1877.91	2.10216
1880.89	1.85139
1882.46	2.23146
1885.45	3.66318
1888.43	4.49927
1891.42	4.81618
1894.41	5.09961
1897.39	5.92168
1900.37	6.71791
1903.36	7.03469
1906.34	7.02775
1909.32	7.42696
1912.29	7.60063
1915.27	6.61322
1918.25	7.02633
1921.23	4.85612
1924.2	4.63913
1927.17	3.9036
1930.15	4.107
1933.12	3.42905
1936.09	3.4888
1939.06	3.07435
1942.02	2.22836
1944.99	2.61567
1947.96	3.23434
1950.92	3.02299
1953.88	3.5129
1956.85	3.29888
1959.81	4.28341
1962.77	5.32498
1965.73	5.30922
1968.69	5.84809
1971.64	6.8874
1974.6	7.64214
1977.55	7.38748
1980.51	7.21763
1983.46	7.2947
1986.41	7.6483
1989.36	6.31613
1992.31	4.98796
1995.26	3.81654
1998.21	4.79264
2001.15	4.45497
2004.1	4.96725
2007.04	5.55842
2009.99	4.8471
2012.93	4.8087
2015.87	5.93812
2018.81	7.138
2021.75	7.94473
2024.68	6.90069
2027.62	5.92449
2030.56	7.23803
2033.49	7.21743
2036.42	7.77153
2039.36	7.24223
2042.29	8.08322
2045.22	8.90674
2048.14	9.96003
2051.07	11.1243
2054	12.3825
2056.93	12.3637
2059.85	12.9581
2062.77	13.5387
2065.7	14.0369
2068.62	14.3627
2071.54	14.0801
2074.46	14.2518
2077.38	14.6866
2080.29	16.5647
2083.21	17.1745
2086.12	17.2626
2089.04	17.7042
2091.95	16.4917
2094.86	16.4355
2097.77	14.7311
2100.68	14.8581
2103.59	14.9504
2106.5	16.846
2109.41	19.068
2112.31	20.1323
2115.21	22.0604
2118.12	23.8835
2121.02	25.905
2123.92	29.0564
2126.82	30.9199
2129.72	34.1276
2132.62	37.0317
2135.51	39.8884
2138.41	42.8758
2141.31	46.4079
2144.2	51.1556
2147.09	54.6551
2149.98	57.996
2152.87	61.8106
2155.76	63.8178
2158.65	66.209
2161.54	69.2394
2164.43	72.922
2167.31	74.4196
2170.2	76.1683
2173.08	76.9211
2175.96	77.0118
2178.84	75.1621
2181.72	73.8725
2184.6	72.3711
2187.48	71.0412
2190.36	69.2212
2193.23	68.1033
2196.11	65.9999
2198.98	61.7636
2201.85	57.2889
2204.72	54.7399
2207.59	51.5896
2210.46	47.8576
2213.33	44.6952
2216.2	41.4413
2219.07	37.9158
2221.93	35.7876
2224.8	33.5816
2227.66	32.2473
2230.52	30.4442
2233.39	29.5843
2236.25	28.7622
2239.1	26.368
2241.96	24.7412
2244.82	23.3598
2247.68	22.0874
2250.53	22.1247
2253.38	22.5564
2256.24	23.5511
2259.09	21.7702
2261.94	21.239
2264.79	20.0272
2267.64	18.7243
2270.49	18.1628
2273.33	17.8808
2276.18	16.6187
2279.02	15.3409
2281.87	14.6821
2284.71	13.8541
2287.55	11.7703
2290.39	11.1573
2293.23	9.29838
2296.07	9.20178
2298.91	9.7025
2301.74	9.79137
2304.58	10.1691
2307.41	9.74511
2310.25	9.42748
2313.08	9.98658
2315.91	10.9841
2318.74	10.7705
2321.57	9.38517
2324.4	8.55796
2327.23	7.18287
2330.05	7.6601
2332.88	7.31391
2335.7	7.3682
2338.52	6.66862
2341.35	5.45442
2344.17	3.82539
2346.99	3.4439
2349.81	3.9543
2352.62	3.17012
2355.44	1.32218
2358.26	1.62515
2361.07	0.604446
2363.89	0.726048
2366.7	1.38316
2369.51	0.90837
2372.32	0.850752
2375.13	0.233749
2377.94	1.20793
2380.75	1.02462
2383.56	0.642048
2386.36	-0.916778
2389.17	-0.841539
2391.97	0.0502217
2394.77	1.58714
2397.58	2.92914
2400.38	3.06799
2403.18	4.42375
2405.97	5.75198
2408.77	5.92995
2411.57	6.69622
2414.37	7.48755
2417.16	8.1315
2419.95	9.33522
2422.75	9.10294
2425.54	10.3641
2428.33	10.5828
2431.12	9.62702
2433.91	9.16024
2436.7	9.44685
2439.48	9.44657
2442.27	9.21808
2445.05	9.31865
2447.84	7.78043
2450.62	6.10348
2453.4	5.27375
2456.18	4.87698
2458.96	4.91783
2461.74	4.98815
2464.52	3.9357
2467.29	3.69667
2470.07	3.12954
2472.85	2.88563
2475.62	1.43417
2478.39	0.591175
2481.16	1.46854
2483.93	1.74598
2486.7	1.99479
2489.47	2.63395
2492.24	3.33372
2495.01	3.16035
2497.77	2.89085
2500.54	3.7413
2503.3	4.48257
2506.06	4.18754
2508.83	4.69235
2511.59	4.42752
2514.35	4.01348
2517.11	2.82626
2519.86	3.77332
2522.62	3.77332
2525.38	4.88189
2528.13	4.94016
2530.89	3.33938
2533.64	4.08829
2536.39	3.78085
2539.14	3.72656
2541.89	4.5015
2544.64	5.31175
2547.39	6.90812
2550.14	6.92638
2552.88	7.5001
2555.63	7.46375
2558.37	7.91765
2561.11	8.58363
2563.86	8.96083
2566.6	8.69528
2569.34	8.2057
2572.08	7.55801
2574.82	6.69822
2577.55	7.36029
2580.29	6.44152
2583.02	5.83592
2585.76	5.9297
2588.49	5.83844
2591.22	4.38147
2593.96	2.88585
2596.69	1.30689
2599.42	0.405932
2602.14	0.499091
2604.87	0.179037
2607.6	-0.159291
2610.32	0.0936554
2613.05	1.08901
2615.77	1.85199
2618.49	2.92134
2621.22	3.26312
2623.94	4.32096
2626.66	4.64569
2629.37	5.09376
2632.09	5.19456
2634.81	4.88643
2637.53	6.04713
2640.24	6.96754
2642.96	7.96016
2645.67	7.60532
2648.38	8.2519
2651.09	8.31411
2653.8	8.14384
2656.51	8.25641
2659.22	7.92192
2661.93	7.8011
2664.63	7.90143
2667.34	8.51771
2670.04	8.78724
2672.75	8.06198
2675.45	8.56626
2678.15	9.55924
2680.85	9.57553
2683.55	9.88208
2686.25	8.84387
2688.94	8.87308
2691.64	8.10589
2694.34	7.28424
2697.03	7.81699
2699.73	8.21411
2702.42	8.93621
2705.11	9.41743
2707.8	9.08214
2710.49	9.15349
2713.18	9.36481
2715.87	11.2952
2718.55	11.0042
2721.24	11.9755
2723.93	13.6658
2726.61	14.8198
2729.29	15.7884
2731.98	17.2996
2734.66	17.5338
2737.34	17.8028
2740.02	18.063
2742.7	18.3162
2745.37	17.9503
2748.05	17.3005
2750.72	16.7634
2753.4	16.6873
2756.07	16.326
2758.75	15.3782
2761.42	14.3426
2764.09	12.7251
2766.76	10.9314
2769.43	9.40749
2772.1	8.04599
2774.76	7.34288
2777.43	7.1414
2780.1	6.07554
2782.76	5.54664
2785.42	4.99565
2788.09	4.50645
2790.75	3.93957
2793.41	3.05926
2796.07	2.80438
2798.73	3.14319
2801.39	3.47437
2804.04	3.58907
2806.7	2.63092
2809.35	2.03832
2812.01	2.40962
2814.66	4.24728
2817.31	5.58035
2819.96	7.01378
2822.61	9.38881
2825.26	13.0386
2827.91	17.7076
2830.56	22.7179
2833.21	29.8224
2835.85	37.7219
2838.5	45.3613
2841.14	54.5799
2843.78	62.5325
2846.42	74.0626
2849.06	84.9983
2851.71	96.9387
2854.34	108.091
2856.98	120.844
2859.62	132.741
2862.26	144.862
2864.89	156.133
2867.53	164.634
2870.16	174.033
2872.79	180.449
2875.42	186.612
2878.05	191.084
2880.68	195.904
2883.31	201.005
2885.94	206.7
2888.57	212.197
2891.19	218.796
2893.82	225
2896.44	233.058
2899.07	240.917
2901.69	249.387
2904.31	259.675
2906.93	272.139
2909.55	287.548
2912.17	302.753
2914.79	316.84
2917.41	330.712
2920.02	343.831
2922.64	353.006
2925.25	361.541
2927.86	365.832
2930.48	367.082
2933.09	366.495
2935.7	362.586
2938.31	356.207
2940.92	348.348
2943.53	339.271
2946.13	328.299
2948.74	315.438
2951.34	301.954
2953.95	289.388
2956.55	276.52
2959.15	261.737
2961.75	249.193
2964.35	236.463
2966.95	224.554
2969.55	214.072
2972.15	203.88
2974.75	194.106
2977.34	182.825
2979.94	171.554
2982.53	160.945
2985.13	149.018
2987.72	136.263
2990.31	123.2
2992.9	112.154
2995.49	101.521
2998.08	90.458
3000.67	81.8586
3003.25	72.2889
3005.84	64.1371
3008.42	55.0411
3011.01	48.8397
3013.59	42.9975
3016.17	39.2642
3018.76	34.5052
3021.34	30.9716
3023.92	28.6018
3026.49	26.2031
3029.07	25.8012
3031.65	25.4876
3034.23	25.3042
3036.8	25.8606
3039.38	26.4392
3041.95	28.245
3044.52	30.124
3047.09	31.5343
3049.66	30.6133
3052.23	30.7621
3054.8	31.3616
3057.37	31.0879
3059.94	30.2019
3062.5	29.3261
3065.07	27.54
3067.63	24.7152
3070.2	22.3888
3072.76	20.1238
3075.32	17.7607
3077.88	14.7338
3080.44	11.8251
3083	10.1512
3085.56	7.33018
3088.12	5.86691
3090.67	4.74431
3093.23	4.30634
3095.78	2.88928
3098.34	1.89316
3100.89	2.15135
3103.44	2.0282
3105.99	1.7711
3108.54	1.36413
3111.09	1.15081
3113.64	0.502667
3116.19	0.144997
3118.74	0.756077
3121.28	0.792096
3123.83	0.462909
3126.37	0.0335664
3128.91	-0.0825603
3131.46	0.529998
3134	2.13196
3136.54	3.86265
3139.08	5.72285
3141.62	8.18829
3144.16	11.0775
3146.69	14.2882
3149.23	19.6757