File: data/Raman/poly_smoothed/Thy_40_11_08_1x_45s_532 nm_x100_100%_600 gr_mm_01.txt
#Acq. time (s)=	45
#Accumulations=	2
#Range (cm-¹)=	200...3150
#Windows=	2
#Auto scanning=	Off
#Autofocus=	Off
#Macrospot=	Off
#AutoExposure=	Off
#Spike filter=	Multiple accum.
#Delay time (s)=	0
#Binning=	1
#Readout mode=	Signal
#DeNoise=	Off
#ICS correction=	On
#Dark correction=	Off
#Inst. Process=	Off
#Detector Gain=	Best Dynamic Range
#Detector ADC=	20 kHz
#Detector temperature (°C)=	-69.85
#Instrument=	LabRAM HR Evol
#Detector=	Synapse
#Objective=	x100
#Grating=	600 gr/mm
#ND Filter=	100%
#Laser (nm)=	532
#Hole=	100.021
#Range=	Auto
#Laser Pol.=	No
#Raman. Pol.=	No
#Laser Pol. (°)=	-0.0007625
#Raman Pol. (°)=	89.9995
#Collection=	Microscope
#StageXY=	Marzhauser
#StageZ=	Marzhauser
#X (µm)=	1956.8
#Y (µm)=	-74
#Z (µm)=	425.15
#Full time(mm:ss)=	3:22
#Project=
#Sample=
#Site=
#Title=	Thy_40_11_08_2x_45s_532 nm_x100_100%_600 gr_mm
#Remark=
#Date=	05.07.2022 10:26
#Acquired=	05.07.2022 10:26:01
#Base:Fit=	10.08.2022 10:00:48
#Base:Fit=	10.08.2022 10:01:07
#Base:Fit=	10.08.2022 10:01:15
#Base:Fit=	10.08.2022 10:01:35
#Base:Sub=	10.08.2022 10:01:52
#Filter:Polynom=	16.08.2022 10:21:53
#AxisType[0]=Intens
#AxisUnit[0]=Cnt
#AxisType[1]=Spectr
#AxisUnit[1]=1/cm
200.43	40.8175
204.059	36.7686
207.688	32.7132
211.314	28.2231
214.941	24.14
218.564	22.0685
222.186	20.6804
225.809	16.3036
229.428	13.8436
233.045	10.1919
236.663	9.49506
240.278	6.50582
243.891	6.12176
247.503	5.18846
251.116	5.02105
254.725	5.66851
258.333	6.08081
261.939	7.08423
265.544	8.91189
269.148	9.83347
272.75	10.1641
276.351	10.2861
279.95	11.3123
283.548	12.0105
287.144	12.381
290.739	11.6747
294.333	10.5793
297.925	12.5879
301.514	13.2507
305.104	15.3912
308.692	14.9012
312.279	15.2479
315.862	13.4874
319.446	14.2421
323.029	14.3431
326.608	14.4846
330.188	15.7023
333.766	17.5753
337.341	18.9676
340.917	19.1103
344.489	18.9291
348.062	19.2842
351.631	17.6328
355.201	17.5772
358.768	15.9975
362.333	14.0057
365.899	13.5289
369.462	13.4392
373.023	12.834
376.585	11.1862
380.143	10.4045
383.7	10.3932
387.256	11.599
390.812	12.371
394.365	12.6467
397.916	13.9207
401.467	12.9967
405.015	13.083
408.563	14.8364
412.109	16.2665
415.654	17.2029
419.197	17.3341
422.739	15.7004
426.279	14.0221
429.819	12.0428
433.356	11.299
436.891	10.5768
440.426	10.0151
443.96	10.2336
447.492	10.9867
451.021	11.3728
454.551	12.6343
458.079	14.2688
461.604	14.8747
465.13	15.1914
468.654	15.7118
472.175	17.5292
475.696	19.1213
479.215	19.652
482.733	21.0682
486.249	23.7116
489.765	24.3197
493.278	25.1343
496.789	26.5882
500.301	27.978
503.81	26.8192
507.317	25.7032
510.825	26.2528
514.33	26.5909
517.833	25.0012
521.335	25.251
524.836	25.9407
528.335	25.7268
531.835	24.6682
535.332	23.5387
538.827	21.8894
542.321	21.5002
545.814	20.1197
549.305	17.4628
552.795	14.0911
556.282	13.4086
559.769	13.1
563.255	12.0164
566.739	9.7562
570.223	7.88506
573.705	6.42151
577.183	5.08937
580.663	4.23135
584.141	4.7519
587.615	4.94195
591.09	3.64491
594.564	2.20222
598.035	1.61097
601.506	1.67147
604.974	1.93534
608.443	3.2484
611.908	4.93582
615.374	5.40752
618.837	4.99263
622.3	6.10581
625.761	6.95922
629.219	7.21756
632.677	8.07734
636.135	7.81775
639.59	8.09694
643.043	9.32022
646.495	9.98736
649.948	10.169
653.398	10.7856
656.846	11.9215
660.293	14.3409
663.738	15.2193
667.183	15.6627
670.626	16.4174
674.067	17.5327
677.508	16.636
680.947	16.4772
684.385	17.4261
687.821	18.9045
691.254	19.2832
694.688	20.4955
698.121	20.693
701.552	22.1781
704.98	22.2733
708.409	24.5305
711.836	26.0527
715.26	27.8195
718.685	31.2937
722.108	32.3585
725.528	35.3174
728.949	38.7135
732.367	41.2526
735.785	44.6408
739.2	48.432
742.614	51.7076
746.028	52.4895
749.439	54.1016
752.849	55.4402
756.26	57.9312
759.667	60.2239
763.073	61.2975
766.477	60.5099
769.883	61.8797
773.285	63.6336
776.686	65.317
780.085	65.5473
783.484	67.558
786.881	69.0012
790.276	70.2247
793.671	74.0354
797.064	76.607
800.456	77.6317
803.846	79.3803
807.234	82.51
810.622	83.9482
814.008	85.968
817.394	86.4489
820.778	89.4184
824.159	89.123
827.541	88.0852
830.921	87.835
834.298	88.2602
837.676	88.3913
841.051	88.1338
844.426	86.0851
847.798	83.0148
851.171	79.2427
854.54	75.8698
857.911	72.4363
861.278	69.5714
864.645	65.9267
868.01	62.0642
871.373	60.745
874.735	57.4131
878.097	53.9476
881.457	51.6725
884.815	50.324
888.172	49.1577
891.528	47.6448
894.882	46.9713
898.237	45.9242
901.589	46.7372
904.94	47.4788
908.289	45.4979
911.635	44.6292
914.982	44.2752
918.328	42.6967
921.672	43.4494
925.015	42.5789
928.357	40.6126
931.698	38.631
935.035	36.8186
938.373	35.7705
941.71	35.8656
945.044	35.0459
948.378	34.2407
951.709	35.291
955.041	35.7322
958.372	37.3722
961.699	38.1212
965.027	40.2069
968.352	42.1896
971.676	44.1823
975	45.7352
978.322	48.4569
981.642	50.8328
984.962	52.5585
988.28	52.7885
991.596	52.342
994.911	54.1053
998.227	54.5023
1001.54	55.6931
1004.85	57.1363
1008.16	55.6337
1011.47	55.8676
1014.78	55.0491
1018.08	55.9039
1021.39	55.0513
1024.69	53.1288
1028	52.964
1031.3	53.5579
1034.6	53.4636
1037.9	52.4286
1041.19	53.1848
1044.49	51.3415
1047.78	51.0785
1051.08	50.7761
1054.37	48.1396
1057.66	46.0502
1060.95	44.2112
1064.24	42.525
1067.53	41.2987
1070.81	40.7181
1074.1	39.9436
1077.38	39.9695
1080.66	39.4854
1083.94	39.2365
1087.22	39.3952
1090.5	39.0146
1093.78	38.0286
1097.05	36.94
1100.33	34.8959
1103.6	34.4015
1106.87	33.8052
1110.14	31.8413
1113.41	32.5146
1116.68	30.0545
1119.95	29.6307
1123.21	27.3758
1126.48	24.6145
1129.74	21.4009
1133	19.0931
1136.26	14.5423
1139.52	13.2734
1142.78	11.6444
1146.04	10.8268
1149.29	10.648
1152.55	8.81717
1155.8	6.82171
1159.05	4.76841
1162.3	4.11242
1165.55	2.69854
1168.8	1.94125
1172.05	2.86934
1175.29	2.9259
1178.54	4.44688
1181.78	4.29439
1185.02	5.83849
1188.26	6.29962
1191.5	7.49471
1194.74	9.24845
1197.97	10.3017
1201.21	15.2539
1204.44	19.0786
1207.68	21.7889
1210.91	25.5624
1214.14	30.2825
1217.37	35.3088
1220.59	41.9903
1223.82	47.151
1227.05	52.2667
1230.27	55.6555
1233.49	60.9109
1236.72	64.6607
1239.94	70.1102
1243.16	74.051
1246.37	76.9859
1249.59	81.3751
1252.8	82.6199
1256.02	84.7482
1259.23	86.8996
1262.44	88.8601
1265.66	90.2201
1268.86	91.8556
1272.07	94.0179
1275.28	95.1862
1278.48	96.86
1281.69	100.333
1284.89	100.05
1288.09	101.103
1291.29	101.961
1294.49	103.024
1297.69	104.772
1300.89	104.653
1304.08	106.312
1307.28	108.244
1310.47	110.024
1313.66	110.725
1316.85	109.377
1320.04	108.293
1323.23	107.525
1326.42	105.793
1329.61	103.693
1332.79	99.684
1335.97	98.3732
1339.16	94.6031
1342.34	91.8047
1345.52	87.5586
1348.7	84.057
1351.87	80.3394
1355.05	76.5974
1358.22	72.6833
1361.4	68.6899
1364.57	64.1043
1367.74	61.0767
1370.91	56.8186
1374.08	55.2022
1377.25	54.0263
1380.41	53.0012
1383.58	54.0416
1386.74	53.9689
1389.91	53.126
1393.07	51.2483
1396.23	50.4501
1399.39	51.5559
1402.55	51.3665
1405.7	50.615
1408.86	51.1156
1412.01	52.6737
1415.17	54.7527
1418.32	58.1289
1421.47	62.2627
1424.62	68.3269
1427.77	74.6118
1430.91	81.4044
1434.06	87.8926
1437.2	93.6302
1440.35	98.0625
1443.49	101.65
1446.63	103.949
1449.77	105.392
1452.91	107.545
1456.05	105.673
1459.18	101.511
1462.32	98.4427
1465.45	93.0517
1468.59	85.8114
1471.72	78.4627
1474.85	70.9711
1477.98	61.9095
1481.1	53.4871
1484.23	45.5487
1487.36	37.5453
1490.48	31.4069
1493.61	27.0893
1496.73	25.3173
1499.85	23.4643
1502.97	21.8888
1506.09	20.6791
1509.2	21.4481
1512.32	21.3919
1515.43	20.25
1518.55	20.1161
1521.66	21.2811
1524.77	21.8935
1527.88	22.6804
1530.99	22.1997
1534.1	22.4525
1537.21	25.9418
1540.31	28.425
1543.42	30.9726
1546.52	33.6789
1549.62	37.9716
1552.72	42.3234
1555.82	45.7854
1558.92	50.0864
1562.02	54.6419
1565.11	59.3409
1568.21	64.9552
1571.3	68.7845
1574.39	72.5856
1577.49	76.3817
1580.57	81.3551
1583.66	85.4978
1586.75	88.2562
1589.84	90.9982
1592.92	90.9805
1596.01	92.3419
1599.09	92.9115
1602.17	91.102
1605.25	90.5575
1608.33	89.2858
1611.41	89.9468
1614.49	88.8391
1617.57	89.4966
1620.64	91.7555
1623.72	93.7387
1626.79	96.6263
1629.86	100.204
1632.93	103.769
1636	110.359
1639.07	114.361
1642.13	119.563
1645.2	124.665
1648.26	129.071
1651.33	133.42
1654.39	135.686
1657.45	138.402
1660.51	137.294
1663.57	135.739
1666.63	132.085
1669.68	128.453
1672.74	122.198
1675.79	114.973
1678.85	106.945
1681.9	99.0636
1684.95	89.5806
1688	80.8254
1691.05	72.0776
1694.09	64.7015
1697.14	54.9736
1700.18	48.5369
1703.23	42.0152
1706.27	36.4413
1709.31	32.4216
1712.35	28.6119
1715.39	25.1634
1718.43	22.8416
1721.47	20.4562
1724.5	17.1165
1727.54	15.6567
1730.57	15.2562
1733.61	14.3771
1736.64	14.2008
1739.67	13.9495
1742.7	13.6226
1745.72	12.6073
1748.75	12.6744
1751.77	12.9263
1754.8	12.7303
1757.82	12.4727
1760.84	12.279
1763.87	11.414
1766.89	11.4251
1769.91	9.73194
1772.92	8.47255
1775.94	7.35124
1778.95	6.79356
1781.97	6.56103
1784.98	5.14114
1787.99	4.3124
1791.01	3.20776
1794.01	1.79233
1797.02	1.52113
1800.03	0.268913
1803.04	1.052
1806.04	1.28708
1809.05	0.792717
1812.05	0.760072
1815.05	0.782436
1818.05	0.577155
1821.05	1.84956
1824.05	2.27278
1827.05	2.40681
1830.04	2.67516
1833.04	3.74591
1836.03	3.88986
1839.03	4.11784
1842.02	4.11506
1845.01	4.41013
1848	4.2628
1850.99	3.5883
1853.97	2.91005
1856.96	2.53209
1859.94	2.51392
1862.93	1.85843
1865.91	2.55941
1868.89	3.37004
1871.87	3.04523
1874.85	3.52238
1877.83	3.75052
1880.81	3.63437
1882.57	3.87603
1885.56	4.38072
1888.55	6.25319
1891.54	7.19323
1894.52	7.52494
1897.51	8.24848
1900.49	8.82047
1903.47	9.10167
1906.45	9.0573
1909.43	10.2272
1912.41	9.48548
1915.39	9.78033
1918.37	9.46556
1921.34	7.80757
1924.32	7.31135
1927.29	7.32851
1930.26	6.49628
1933.23	6.59192
1936.2	6.31526
1939.17	5.73901
1942.14	6.11839
1945.11	5.05879
1948.07	4.40603
1951.04	3.91326
1954	4.82085
1956.96	5.06181
1959.93	6.46266
1962.89	7.92318
1965.85	7.38549
1968.8	7.72515
1971.76	8.23201
1974.72	6.76313
1977.67	6.68813
1980.63	7.39722
1983.58	7.49465
1986.53	6.86318
1989.48	6.80515
1992.43	6.50499
1995.38	6.08516
1998.32	6.22395
2001.27	6.46813
2004.22	6.08869
2007.16	6.78799
2010.1	6.92606
2013.04	5.64218
2015.98	5.19774
2018.92	4.79344
2021.86	5.6707
2024.8	6.59348
2027.74	7.85644
2030.67	7.72961
2033.61	8.31792
2036.54	8.34232
2039.47	8.10634
2042.4	9.06903
2045.33	9.4312
2048.26	9.92179
2051.19	11.903
2054.12	12.3761
2057.04	12.77
2059.97	13.0033
2062.89	15.1268
2065.81	15.4854
2068.73	17.7619
2071.65	18.8583
2074.57	21.3471
2077.49	22.9871
2080.41	25.0679
2083.32	27.3761
2086.24	29.4966
2089.15	31.9555
2092.07	34.3311
2094.98	37.2443
2097.89	39.7055
2100.8	42.6447
2103.71	45.3944
2106.61	49.218
2109.52	53.3537
2112.43	56.0412
2115.33	60.7941
2118.23	65.5607
2121.13	70.9083
2124.04	75.5378
2126.94	80.2159
2129.83	86.1203
2132.73	93.9758
2135.63	101.459
2138.53	108.307
2141.42	114.96
2144.31	120.8
2147.21	126.879
2150.1	132.997
2152.99	138.723
2155.88	144.444
2158.77	147.609
2161.65	150.648
2164.54	153.517
2167.43	154.214
2170.31	154.759
2173.19	154.577
2176.07	151.406
2178.96	149.756
2181.84	147.309
2184.72	143.858
2187.59	141.428
2190.47	138.478
2193.35	133.391
2196.22	128.519
2199.09	124.047
2201.97	119.515
2204.84	114.901
2207.71	108.638
2210.58	102.676
2213.45	96.8127
2216.31	91.4946
2219.18	86.6737
2222.05	80.7506
2224.91	77.2747
2227.78	71.5568
2230.64	65.9091
2233.5	60.9331
2236.36	55.2908
2239.22	51.2055
2242.08	47.18
2244.93	42.6782
2247.79	39.5086
2250.64	38.3371
2253.5	36.7841
2256.35	34.5364
2259.2	32.8752
2262.05	30.8122
2264.9	30.0109
2267.75	28.984
2270.6	28.5938
2273.45	28.5397
2276.29	27.4665
2279.14	25.9889
2281.98	24.6782
2284.82	22.8189
2287.66	20.7529
2290.5	18.8441
2293.34	16.5714
2296.18	14.8008
2299.02	13.813
2301.86	12.8588
2304.69	12.3666
2307.53	12.1143
2310.36	12.1221
2313.19	10.807
2316.02	10.0298
2318.85	10.1097
2321.68	9.05104
2324.51	8.74192
2327.34	8.57722
2330.16	8.35263
2332.99	8.45723
2335.81	8.06761
2338.64	7.19762
2341.46	6.66147
2344.28	5.05908
2347.1	4.09341
2349.92	2.38671
2352.74	1.53626
2355.55	0.338162
2358.37	-0.545221
2361.19	-0.678686
2364	-1.15879
2366.81	0.189701
2369.62	1.22932
2372.44	0.838503
2375.24	0.931658
2378.05	0.784869
2380.86	-0.228504
2383.67	-0.822333
2386.47	-1.55923
2389.28	-1.71513
2392.08	-0.0508851
2394.89	0.362137
2397.69	0.620297
2400.49	1.36576
2403.29	1.76888
2406.09	2.00658
2408.88	3.71871
2411.68	4.41231
2414.48	5.62687
2417.27	6.20824
2420.06	6.01212
2422.86	7.03361
2425.65	7.20324
2428.44	8.07588
2431.23	7.96574
2434.02	8.63014
2436.81	8.63841
2439.59	7.89098
2442.38	6.71267
2445.16	5.14306
2447.95	4.86795
2450.73	3.92489
2453.51	3.2587
2456.29	3.30852
2459.07	3.31272
2461.85	3.54567
2464.63	2.63532
2467.4	2.02208
2470.18	1.48786
2472.95	2.05958
2475.73	1.46442
2478.5	1.1204
2481.27	1.13629
2484.04	1.43682
2486.81	0.32312
2489.58	-0.18336
2492.35	-0.529428
2495.12	-0.449094
2497.88	-0.286579
2500.65	-0.641154
2503.41	-0.266471
2506.17	-0.253732
2508.94	-0.0770465
2511.7	0.781063
2514.46	1.16335
2517.22	1.82306
2519.97	2.5564
2522.73	3.31183
2525.49	3.89588
2528.24	3.54524
2530.99	3.43721
2533.75	4.06801
2536.5	3.78187
2539.25	4.62331
2542	4.79259
2544.75	5.48521
2547.5	5.36531
2550.24	5.98961
2552.99	6.12159
2555.74	6.30967
2558.48	6.52094
2561.22	6.09145
2563.96	6.41178
2566.71	6.03812
2569.45	6.2071
2572.18	5.29148
2574.92	6.28637
2577.66	6.06904
2580.4	6.73792
2583.13	6.15045
2585.87	5.69387
2588.6	5.15696
2591.33	4.5972
2594.06	4.17875
2596.79	3.66443
2599.52	3.07163
2602.25	2.19157
2604.98	1.74424
2607.71	2.32727
2610.43	3.02979
2613.16	3.62138
2615.88	3.76135
2618.6	4.70208
2621.32	4.09895
2624.04	3.23889
2626.76	3.66686
2629.48	4.07987
2632.2	4.55249
2634.92	4.34335
2637.63	5.40693
2640.35	6.23309
2643.06	6.89982
2645.77	7.84
2648.49	7.29544
2651.2	7.0495
2653.91	7.28768
2656.62	7.1305
2659.33	7.33089
2662.03	7.16237
2664.74	6.73196
2667.44	7.12453
2670.15	7.21906
2672.85	7.03761
2675.55	7.02119
2678.26	6.99713
2680.96	7.49396
2683.66	7.2473
2686.35	7.75688
2689.05	7.9644
2691.75	8.1842
2694.44	9.06266
2697.14	9.09204
2699.83	9.29799
2702.52	9.64178
2705.22	10.6283
2707.91	10.7232
2710.6	11.2492
2713.29	11.7483
2715.97	11.3428
2718.66	11.0021
2721.35	11.9153
2724.03	12.7116
2726.72	12.8033
2729.4	12.5787
2732.08	12.338
2734.76	11.3927
2737.44	10.7992
2740.12	10.307
2742.8	10.9072
2745.48	11.0318
2748.16	9.72563
2750.83	8.54832
2753.51	7.94537
2756.18	6.88528
2758.85	5.56911
2761.53	5.03152
2764.2	4.06828
2766.87	3.66726
2769.54	2.97372
2772.2	3.37292
2774.87	1.71673
2777.54	1.4054
2780.2	0.838061
2782.87	0.0227066
2785.53	-0.552356
2788.19	-0.205993
2790.85	0.0537598
2793.51	-0.0755766
2796.17	0.457627
2798.83	-0.460738
2801.49	0.250263
2804.15	0.159012
2806.8	-0.0784467
2809.46	-0.193896
2812.11	-1.49818
2814.76	-1.12028
2817.42	-0.521521
2820.07	1.79993
2822.72	4.7603
2825.37	10.0005
2828.02	16.1978
2830.66	22.3716
2833.31	29.1875
2835.96	36.2769
2838.6	43.3244
2841.24	50.5162
2843.89	61.266
2846.53	72.1403
2849.17	85.348
2851.81	99.4309
2854.45	113.487
2857.09	127.368
2859.72	140.665
2862.36	152.41
2865	163.483
2867.63	173.791
2870.26	183.015
2872.9	190.469
2875.53	197.834
2878.16	204.016
2880.79	210.541
2883.42	217.209
2886.05	225.136
2888.67	232.35
2891.3	239.702
2893.92	247.112
2896.55	254.285
2899.17	264.446
2901.79	274.321
2904.42	287.27
2907.04	303.367
2909.66	320.782
2912.27	338.191
2914.89	357.033
2917.51	374.225
2920.13	390.522
2922.74	405.156
2925.35	416.502
2927.97	424.221
2930.58	429.662
2933.19	430.464
2935.8	428.413
2938.41	423.691
2941.02	415.171
2943.63	405.381
2946.24	392.745
2948.84	378.222
2951.45	362.042
2954.05	344.622
2956.65	326.949
2959.26	308.35
2961.86	291.039
2964.46	273.175
2967.06	257.002
2969.66	240.753
2972.25	224.443
2974.85	209.852
2977.45	196.172
2980.04	181.793
2982.64	169.021
2985.23	153.984
2987.82	140.232
2990.41	126.21
2993	111.922
2995.59	99.6325
2998.18	86.9732
3000.77	75.5982
3003.36	65.0883
3005.94	55.8098
3008.53	46.818
3011.11	39.5992
3013.69	32.5451
3016.28	27.1528
3018.86	22.3847
3021.44	19.3436
3024.02	17.1334
3026.6	15.143
3029.18	12.564
3031.75	12.22
3034.33	12.292
3036.9	12.6267
3039.48	14.5976
3042.05	15.9889
3044.62	17.1337
3047.19	17.864
3049.77	19.4112
3052.34	20.1873
3054.9	20.8165
3057.47	20.6964
3060.04	21.6398
3062.61	20.2673
3065.17	18.8349
3067.74	16.9033
3070.3	15.6613
3072.86	14.2341
3075.42	12.7719
3077.99	11.0284
3080.54	9.54616
3083.1	8.09431
3085.66	6.48248
3088.22	4.05741
3090.78	1.54647
3093.33	0.559986
3095.89	-0.222282
3098.44	-0.123166
3100.99	0.678944
3103.54	1.33456
3106.1	1.95578
3108.65	3.31615
3111.2	3.85817
3113.74	5.8836
3116.29	6.78215
3118.84	8.33434
3121.38	10.0732
3123.93	11.5205
3126.47	12.9252
3129.01	14.6409
3131.56	16.9427
3134.1	19.2715
3136.64	21.702
3139.18	23.6734
3141.72	24.5249
3144.26	25.5108
3146.79	26.1339
3149.33	27.7739