File: data/Raman/poly_smoothed/Thy_00_07_17_1x_45s_532 nm_x100_100%_600 gr_mm_01.txt
#Acq. time (s)=	45
#Accumulations=	2
#Range (cm-¹)=	200...3150
#Windows=	2
#Auto scanning=	Off
#Autofocus=	Off
#Macrospot=	Off
#AutoExposure=	Off
#Spike filter=	Multiple accum.
#Delay time (s)=	0
#Binning=	1
#Readout mode=	Signal
#DeNoise=	Off
#ICS correction=	On
#Dark correction=	Off
#Inst. Process=	Off
#Detector Gain=	Best Dynamic Range
#Detector ADC=	20 kHz
#Detector temperature (°C)=	-69.85
#Instrument=	LabRAM HR Evol
#Detector=	Synapse
#Objective=	x100
#Grating=	600 gr/mm
#ND Filter=	100%
#Laser (nm)=	532
#Hole=	100.021
#Range=	Auto
#Laser Pol.=	No
#Raman. Pol.=	No
#Laser Pol. (°)=	-0.0007625
#Raman Pol. (°)=	89.9995
#Collection=	Microscope
#StageXY=	Marzhauser
#StageZ=	Marzhauser
#X (µm)=	9020.7
#Y (µm)=	-3082.1
#Z (µm)=	-54.6
#Full time(mm:ss)=	3:19
#Project=
#Sample=
#Site=
#Title=	Thy_00_07_17_2x_45s_532 nm_x100_100%_600 gr_mm
#Remark=
#Date=	28.06.2022 11:18
#Acquired=	28.06.2022 11:18:54
#Base:Fit=	10.08.2022 10:06:44
#Base:Fit=	10.08.2022 10:07:16
#Base:Fit=	10.08.2022 10:07:25
#Base:Fit=	10.08.2022 10:07:44
#Base:Fit=	10.08.2022 10:07:56
#Base:Sub=	10.08.2022 10:08:40
#Filter:Polynom=	16.08.2022 10:26:06
#AxisType[0]=Intens
#AxisUnit[0]=Cnt
#AxisType[1]=Spectr
#AxisUnit[1]=1/cm
200.407	-3.37899
204.035	2.15342
207.665	2.66766
211.291	4.19883
214.916	6.33275
218.541	8.19929
222.163	9.68176
225.785	11.363
229.404	11.653
233.022	11.2146
236.638	10.6021
240.255	10.7645
243.868	10.3281
247.48	9.8103
251.091	9.14369
254.702	7.86923
258.31	7.55465
261.916	5.58194
265.521	5.75063
269.125	6.13285
272.727	6.82635
276.328	7.18112
279.927	7.11834
283.525	7.10144
287.121	8.52412
290.716	10.8312
294.31	13.2504
297.9	15.7439
301.491	19.5209
305.081	22.923
308.669	25.3543
312.256	28.8685
315.839	29.0402
319.423	30.9132
323.006	31.4211
326.585	33.0234
330.165	34.3428
333.741	34.3847
337.318	34.4773
340.894	33.9446
344.466	33.0561
348.039	33.2073
351.608	33.1795
355.176	33.3356
358.745	31.5354
362.31	31.299
365.876	32.1885
369.439	33.8777
373	33.6454
376.56	32.7365
380.12	32.2122
383.677	32.1212
387.233	31.8867
390.787	32.0343
394.34	31.0096
397.894	29.7447
401.444	27.9001
404.993	26.826
408.54	24.5203
412.086	23.5723
415.631	23.2897
419.174	20.4897
422.716	18.8196
426.257	18.8444
429.794	15.7635
433.332	15.4454
436.868	15.2939
440.403	15.412
443.937	16.1823
447.468	18.4257
450.999	22.8274
454.528	25.5187
458.057	27.9208
461.582	28.2302
465.107	31.2375
468.629	33.2103
472.152	35.2002
475.672	37.582
479.192	40.3456
482.709	42.8275
486.226	43.3023
489.74	43.6379
493.255	46.332
496.767	47.7072
500.277	49.3375
503.788	49.314
507.295	49.2197
510.801	48.333
514.308	46.7441
517.811	45.6183
521.313	44.1794
524.814	42.8782
528.313	40.5141
531.811	41.2047
535.308	39.2024
538.803	38.0255
542.297	34.8224
545.789	33.3984
549.281	30.3876
552.771	28.3017
556.259	26.3134
559.747	25.3937
563.233	25.5471
566.717	22.9916
570.2	21.8468
573.68	19.7177
577.161	19.5399
580.64	19.4183
584.118	17.0509
587.593	16.3622
591.068	15.0231
594.54	14.3026
598.013	14.2467
601.484	14.623
604.952	13.7849
608.421	14.4358
611.886	13.4544
615.35	14.6618
618.815	14.6531
622.276	14.8698
625.738	14.921
629.197	13.5598
632.655	14.0135
636.113	15.0226
639.568	15.8399
643.021	17.7405
646.473	18.5536
649.924	19.3268
653.376	19.1972
656.824	19.3988
660.271	18.3209
663.716	18.1856
667.161	17.3865
670.604	17.3182
674.045	16.9521
677.486	17.0196
680.925	18.3689
684.361	20.3706
687.797	20.9435
691.232	21.3515
694.666	22.4314
698.099	23.3388
701.528	24.3593
704.958	23.0682
708.387	23.3895
711.814	24.1346
715.238	26.5608
718.663	29.038
722.084	29.4415
725.506	33.1962
728.925	35.5902
732.345	38.1216
735.761	41.3873
739.178	45.5899
742.592	49.4011
746.006	53.7243
749.417	57.4787
752.827	62.4189
756.236	66.6374
759.645	69.8765
763.051	72.4535
766.456	74.8937
769.859	76.7622
773.261	78.3845
776.664	78.8084
780.064	78.5953
783.462	75.7948
786.859	73.6594
790.255	71.6226
793.649	71.0971
797.042	68.915
800.434	67.0029
803.823	64.3507
807.212	62.0232
810.6	59.7459
813.987	59.5743
817.372	60.9914
820.754	64.0416
824.137	66.547
827.519	69.0658
830.897	70.9865
834.276	73.2889
837.654	74.2786
841.029	73.2294
844.404	73.3455
847.776	71.4393
851.149	70.691
854.519	68.8012
857.889	66.4133
861.256	62.7713
864.622	58.8363
867.988	55.7786
871.351	52.945
874.713	49.1408
878.074	45.001
881.435	42.652
884.794	39.9483
888.15	35.6782
891.506	33.1397
894.861	33.0937
898.214	33.8413
901.566	36.1549
904.916	36.7603
908.266	39.3766
911.614	40.5683
914.961	43.2428
918.306	44.0597
921.651	44.5651
924.994	46.2942
928.336	45.2243
931.674	45.8949
935.014	46.3596
938.352	46.6042
941.687	46.1549
945.022	45.6286
948.357	45.3362
951.688	42.5514
955.02	40.2388
958.348	36.3773
961.678	32.0351
965.004	29.6585
968.331	27.6313
971.655	26.7972
974.979	27.8718
978.3	30.1017
981.62	30.5137
984.941	31.6756
988.259	32.7913
991.575	33.3804
994.89	34.6162
998.204	35.8041
1001.52	38.3042
1004.83	40.8014
1008.14	42.1185
1011.45	44.5436
1014.76	47.0628
1018.06	47.3028
1021.37	46.8809
1024.67	47.275
1027.97	44.8106
1031.27	42.4853
1034.57	38.5365
1037.87	33.5992
1041.17	29.5282
1044.47	28.1078
1047.76	26.8079
1051.06	27.1146
1054.35	27.3162
1057.64	26.1131
1060.93	25.4477
1064.22	24.9313
1067.5	25.4564
1070.79	26.2008
1074.08	27.5119
1077.36	28.2178
1080.64	30.0429
1083.92	32.4041
1087.2	32.9975
1090.48	35.4194
1093.76	37.3484
1097.03	38.2649
1100.31	38.3491
1103.58	39.6334
1106.85	38.7792
1110.12	39.0777
1113.39	37.325
1116.66	35.0328
1119.93	35.2134
1123.19	34.4963
1126.46	33.1001
1129.72	31.8246
1132.98	31.6678
1136.24	30.5914
1139.5	29.5381
1142.76	28.7401
1146.01	26.9516
1149.27	25.2449
1152.53	22.4388
1155.78	18.7062
1159.03	15.2801
1162.28	12.1271
1165.53	11.451
1168.78	9.56237
1172.02	7.79548
1175.27	9.36667
1178.51	9.40944
1181.76	7.97223
1185	8.52144
1188.24	9.11733
1191.48	9.36893
1194.71	10.5881
1197.95	13.5474
1201.19	15.6417
1204.42	18.7819
1207.65	20.3389
1210.88	23.9183
1214.12	26.721
1217.35	29.5583
1220.57	31.975
1223.8	35.1062
1227.03	36.9994
1230.25	37.894
1233.47	38.4706
1236.69	40.0251
1239.92	41.5303
1243.13	41.5132
1246.35	41.0169
1249.57	40.7048
1252.78	41.6914
1256	40.7299
1259.21	40.1808
1262.42	39.8543
1265.63	39.1335
1268.84	38.0141
1272.05	36.5253
1275.26	37.0705
1278.46	35.9571
1281.67	36.4159
1284.87	36.102
1288.07	38.4455
1291.27	40.7923
1294.47	42.9015
1297.67	46.324
1300.87	50.0111
1304.06	53.7194
1307.26	58.0651
1310.45	62.5682
1313.64	65.98
1316.83	68.7375
1320.02	71.7074
1323.21	74.2922
1326.4	76.2591
1329.59	77.9387
1332.77	78.2543
1335.95	79.0242
1339.14	79.8945
1342.32	77.1852
1345.5	75.7905
1348.67	74.4552
1351.85	71.4813
1355.03	69.411
1358.2	66.7205
1361.38	63.8874
1364.55	61.5074
1367.72	59.631
1370.89	58.7241
1374.06	57.1564
1377.23	55.5548
1380.39	55.2868
1383.56	54.3594
1386.72	53.8424
1389.89	52.483
1393.05	51.1261
1396.21	50.1134
1399.37	50.2382
1402.52	49.9683
1405.68	49.2767
1408.84	48.7907
1411.99	49.038
1415.15	50.2111
1418.3	51.9577
1421.45	55.4053
1424.6	58.8087
1427.75	63.3863
1430.89	68.4493
1434.04	72.3643
1437.18	74.5097
1440.33	78.2143
1443.47	82.154
1446.61	84.3645
1449.75	84.8313
1452.89	83.3269
1456.03	81.5927
1459.16	79.5619
1462.3	76.4827
1465.43	71.5931
1468.56	66.8591
1471.7	61.9583
1474.83	56.4723
1477.96	50.2689
1481.08	42.9534
1484.21	36.4632
1487.34	29.1273
1490.46	25.63
1493.58	23.1787
1496.71	20.1449
1499.83	19.3697
1502.95	18.5717
1506.07	17.6314
1509.18	16.7476
1512.3	15.9024
1515.41	16.0394
1518.53	17.584
1521.64	18.4327
1524.75	18.7867
1527.86	19.5708
1530.97	20.7072
1534.08	23.8179
1537.19	25.9685
1540.29	28.8145
1543.4	31.9082
1546.5	35.641
1549.6	37.5901
1552.7	39.5649
1555.8	40.9468
1558.9	43.8459
1562	46.6613
1565.09	48.0296
1568.19	50.076
1571.28	53.0801
1574.37	54.9317
1577.47	55.4447
1580.56	57.0993
1583.64	57.7526
1586.73	59.1906
1589.82	60.2381
1592.9	61.6391
1595.99	61.2972
1599.07	60.6976
1602.15	60.3035
1605.23	60.1987
1608.31	60.8425
1611.39	60.7742
1614.47	60.3597
1617.55	61.058
1620.62	60.9333
1623.7	59.7683
1626.77	60.045
1629.84	59.6275
1632.91	61.5265
1635.98	62.0996
1639.05	61.9921
1642.11	62.864
1645.18	65.2023
1648.24	67.0863
1651.31	65.8597
1654.37	67.4538
1657.43	68.797
1660.49	69.9723
1663.55	69.1488
1666.61	68.0476
1669.66	66.3072
1672.72	64.9338
1675.77	62.3091
1678.83	60.3501
1681.88	57.5581
1684.93	53.1285
1687.98	48.4295
1691.03	44.3684
1694.07	40.2935
1697.12	34.9415
1700.17	30.9447
1703.21	28.3639
1706.25	26.028
1709.29	22.7484
1712.33	18.6924
1715.37	15.723
1718.41	14.7254
1721.45	12.7903
1724.49	10.2176
1727.52	9.01187
1730.55	8.62999
1733.59	8.92268
1736.62	8.39134
1739.65	8.30657
1742.68	8.27012
1745.7	8.12399
1748.73	8.27571
1751.76	7.80096
1754.78	7.4381
1757.8	6.81243
1760.83	6.49516
1763.85	6.82729
1766.87	6.11226
1769.89	5.82506
1772.9	6.76428
1775.92	6.58152
1778.94	6.06322
1781.95	5.90054
1784.96	5.4574
1787.97	5.71216
1790.99	6.03344
1794	5.58659
1797	4.43286
1800.01	3.55893
1803.02	3.42402
1806.02	3.11544
1809.03	3.27135
1812.03	3.13511
1815.03	3.53318
1818.03	2.52644
1821.03	2.63866
1824.03	1.2919
1827.03	1.00406
1830.02	0.692006
1833.02	1.39296
1836.01	1.93552
1839.01	1.66576
1842	1.06607
1844.99	1.54218
1847.98	1.11232
1850.97	1.2049
1853.95	1.31463
1856.94	2.0517
1859.93	1.95617
1862.91	2.85882
1865.89	2.28352
1868.87	2.59202
1871.85	2.43029
1874.83	2.64241
1877.81	3.67845
1880.79	4.81343
1882.52	4.90687
1885.51	4.75079
1888.5	4.52984
1891.49	4.36681
1894.47	4.97765
1897.46	4.64001
1900.44	4.6718
1903.42	5.18086
1906.4	5.56353
1909.38	5.23234
1912.36	5.11117
1915.34	5.89166
1918.32	5.65669
1921.29	5.40619
1924.27	6.08115
1927.24	6.52042
1930.21	5.44656
1933.18	5.5323
1936.15	5.01351
1939.12	4.08291
1942.09	3.36172
1945.06	3.10617
1948.02	3.22248
1950.99	2.90022
1953.95	2.96145
1956.91	2.6658
1959.88	3.33408
1962.84	2.81009
1965.8	2.30563
1968.75	2.37908
1971.71	1.9639
1974.67	2.2886
1977.62	3.0913
1980.58	3.97523
1983.53	4.9505
1986.48	5.06139
1989.43	6.37591
1992.38	6.62653
1995.33	6.77879
1998.27	6.47811
2001.22	6.04552
2004.16	5.35126
2007.11	4.4943
2010.05	4.64628
2012.99	4.5733
2015.93	3.45021
2018.87	3.03366
2021.81	3.42567
2024.75	3.55981
2027.69	4.44487
2030.62	3.80129
2033.56	3.07841
2036.49	3.69856
2039.42	3.01462
2042.35	3.18913
2045.28	3.60395
2048.21	3.44755
2051.14	4.03919
2054.07	3.82183
2056.99	3.78547
2059.92	4.34264
2062.84	4.86992
2065.76	4.49644
2068.68	3.98388
2071.6	4.1449
2074.52	3.84025
2077.44	4.09745
2080.36	4.53601
2083.27	4.10645
2086.19	3.7852
2089.1	3.61931
2092.02	3.31312
2094.93	2.16375
2097.84	2.51007
2100.75	2.1401
2103.66	1.71283
2106.56	2.56167
2109.47	3.06673
2112.38	2.92545
2115.28	2.96252
2118.18	2.98843
2121.09	2.97469
2123.99	4.07032
2126.89	4.07875
2129.79	4.43602
2132.68	4.71385
2135.58	4.73451
2138.48	4.29624
2141.37	4.35818
2144.27	4.56363
2147.16	5.53787
2150.05	5.54115
2152.94	4.61322
2155.83	4.04384
2158.72	3.61068
2161.6	3.45702
2164.49	3.52742
2167.38	4.21038
2170.26	4.6594
2173.14	5.53601
2176.03	5.13784
2178.91	5.81618
2181.79	6.42354
2184.67	6.04183
2187.54	6.24154
2190.42	6.38621
2193.3	5.80694
2196.17	5.44129
2199.05	4.60269
2201.92	5.52676
2204.79	5.41817
2207.66	5.28162
2210.53	3.78875
2213.4	3.84292
2216.27	4.19727
2219.13	3.8084
2222	3.40666
2224.86	2.88215
2227.72	3.47463
2230.59	3.64373
2233.45	3.68237
2236.31	3.85096
2239.17	4.02935
2242.03	3.85169
2244.88	3.87398
2247.74	2.89293
2250.59	2.68431
2253.45	3.17461
2256.3	2.65358
2259.15	3.4341
2262	3.67309
2264.85	3.51572
2267.7	4.39719
2270.55	4.0047
2273.4	3.65614
2276.24	4.38147
2279.09	3.65114
2281.93	4.53519
2284.77	4.64417
2287.62	5.24847
2290.46	5.21077
2293.3	4.31185
2296.13	3.82019
2298.97	4.80933
2301.81	6.35211
2304.64	6.53917
2307.48	7.32028
2310.31	7.54007
2313.14	8.5544
2315.98	7.86607
2318.81	7.34886
2321.64	8.21104
2324.46	8.04644
2327.29	8.57045
2330.12	9.04417
2332.94	7.50743
2335.77	6.62983
2338.59	6.04368
2341.41	4.86273
2344.23	4.95511
2347.05	5.00472
2349.87	4.06428
2352.69	3.28957
2355.51	3.12241
2358.32	2.4314
2361.14	1.41716
2363.95	1.46243
2366.76	1.22435
2369.58	1.6057
2372.39	1.25854
2375.2	1.46615
2378	1.16456
2380.81	1.20394
2383.62	1.49577
2386.43	1.12142
2389.23	1.80402
2392.03	2.53293
2394.84	2.05419
2397.64	1.45327
2400.44	1.30438
2403.24	0.608784
2406.04	1.7417
2408.84	2.37489
2411.63	2.76384
2414.43	3.73536
2417.22	4.77868
2420.02	6.34223
2422.81	6.99144
2425.6	7.53058
2428.39	7.50344
2431.18	7.3822
2433.97	7.33064
2436.76	7.33071
2439.54	7.15481
2442.33	6.60975
2445.12	6.10476
2447.9	5.62733
2450.68	5.67498
2453.46	5.02224
2456.24	4.32124
2459.02	3.27285
2461.8	2.47736
2464.58	1.68049
2467.36	1.35413
2470.13	0.943846
2472.91	0.563829
2475.68	0.758451
2478.45	0.845152
2481.23	0.574347
2484	0.870133
2486.77	1.43506
2489.54	1.52239
2492.3	1.41627
2495.07	1.35083
2497.84	1.94411
2500.6	1.51567
2503.36	1.80265
2506.13	1.58478
2508.89	1.12195
2511.65	1.3925
2514.41	2.18191
2517.17	2.61505
2519.93	2.30497
2522.68	2.16574
2525.44	3.38064
2528.19	2.41981
2530.95	2.34907
2533.7	3.24538
2536.45	3.38724
2539.2	3.19186
2541.95	2.77645
2544.7	3.27922
2547.45	3.0276
2550.2	2.197
2552.94	2.422
2555.69	2.00657
2558.43	2.48611
2561.18	2.7594
2563.92	2.98309
2566.66	2.69971
2569.4	1.97578
2572.14	2.35386
2574.88	2.16437
2577.61	1.90182
2580.35	2.71858
2583.09	2.23226
2585.82	2.22271
2588.55	2.41842
2591.29	2.18052
2594.02	2.08558
2596.75	1.96926
2599.48	2.69554
2602.21	2.81858
2604.93	3.71419
2607.66	4.68369
2610.39	5.11974
2613.11	6.38212
2615.83	6.09153
2618.56	7.25448
2621.28	8.24271
2624	8.64056
2626.72	8.70541
2629.44	8.25294
2632.15	7.83494
2634.87	8.17347
2637.59	7.35364
2640.3	7.44363
2643.02	6.31036
2645.73	6.37727
2648.44	5.67273
2651.15	5.54316
2653.86	4.9786
2656.57	3.75017
2659.28	2.64051
2661.99	3.06188
2664.69	3.36484
2667.4	3.92115
2670.1	4.13286
2672.81	4.14401
2675.51	5.01989
2678.21	5.63495
2680.91	6.10055
2683.61	6.23111
2686.31	6.76439
2689	7.54498
2691.7	7.76776
2694.4	7.44686
2697.09	8.41461
2699.79	8.88359
2702.48	9.84455
2705.17	10.6294
2707.86	10.3804
2710.55	11.2793
2713.24	12.1137
2715.93	12.581
2718.62	12.3258
2721.3	12.1677
2723.99	11.4031
2726.67	12.7805
2729.35	12.9319
2732.04	13.1504
2734.72	12.8385
2737.4	11.9243
2740.08	11.6171
2742.76	10.4188
2745.43	9.40693
2748.11	8.52415
2750.79	8.74493
2753.46	7.43378
2756.14	6.45329
2758.81	4.48328
2761.48	4.10582
2764.15	3.86884
2766.82	3.18387
2769.49	3.11173
2772.16	2.75011
2774.82	2.62477
2777.49	3.00335
2780.16	2.74604
2782.82	2.31872
2785.48	2.30458
2788.15	1.62346
2790.81	1.52881
2793.47	2.19147
2796.13	2.34114
2798.79	2.3452
2801.44	2.18808
2804.1	1.43352
2806.76	1.77757
2809.41	1.97343
2812.07	2.49922
2814.72	2.78655
2817.37	4.15599
2820.02	5.61732
2822.67	6.86684
2825.32	10.4321
2827.97	12.8305
2830.62	15.5135
2833.26	20.0273
2835.91	24.1113
2838.56	27.6744
2841.2	33.6112
2843.84	39.5407
2846.48	46.456
2849.12	54.2574
2851.77	63.0216
2854.4	72.359
2857.04	82.764
2859.68	91.6749
2862.32	101.941
2864.95	111.556
2867.59	121.474
2870.22	131.154
2872.85	140.334
2875.48	149.752
2878.11	157.217
2880.74	166.822
2883.37	175.173
2886	183.777
2888.63	192.065
2891.25	198.689
2893.88	204.829
2896.5	213.231
2899.13	220.277
2901.75	227.59
2904.37	236.058
2906.99	245.928
2909.61	255.066
2912.23	265.036
2914.85	275.687
2917.46	284.178
2920.08	290.708
2922.7	294.87
2925.31	299.06
2927.92	301.671
2930.54	301.288
2933.15	298.931
2935.76	294.779
2938.37	288.699
2940.98	280.883
2943.58	273.177
2946.19	264.583
2948.8	254.303
2951.4	243.939
2954.01	232.569
2956.61	221.63
2959.21	211.668
2961.81	201.635
2964.41	191.462
2967.01	182.435
2969.61	174.171
2972.21	166.16
2974.81	157.588
2977.4	149.33
2980	140.324
2982.59	130.273
2985.18	120.391
2987.78	110.299
2990.37	100.538
2992.96	88.8941
2995.55	78.3213
2998.14	67.9882
3000.73	58.5325
3003.31	49.9816
3005.9	42.2152
3008.48	34.9155
3011.07	28.0618
3013.65	21.9069
3016.23	16.5813
3018.81	12.3957
3021.4	8.73718
3023.97	5.90699
3026.55	4.38549
3029.13	2.52073
3031.71	1.72617
3034.28	1.80752
3036.86	2.50542
3039.43	3.96328
3042.01	5.30784
3044.58	6.97866
3047.15	8.17489
3049.72	9.43293
3052.29	10.8198
3054.86	11.2116
3057.43	11.0894
3060	11.7313
3062.56	12.4738
3065.13	12.496
3067.69	11.9692
3070.26	11.8288
3072.82	10.2915
3075.38	8.83908
3077.94	7.60618
3080.5	5.54652
3083.06	4.64414
3085.62	2.9145
3088.18	1.16465
3090.73	-0.0457967
3093.29	-0.0145763
3095.84	-0.125428
3098.4	0.432971
3100.95	1.0263
3103.5	1.55998
3106.05	2.38982
3108.6	3.24546
3111.15	3.41442
3113.7	4.90598
3116.25	6.21402
3118.79	7.08742
3121.34	8.52218
3123.88	10.4585
3126.43	12.3518
3128.97	14.565
3131.51	16.9243
3134.06	18.8851
3136.6	20.6375
3139.14	22.5478
3141.67	24.5323
3144.21	26.7018
3146.75	28.7201
3149.29	31.4723