File: data/Raman/poly_smoothed/Thy_40_11_16_1x_45s_532 nm_x100_100%_600 gr_mm_01.txt
#Acq. time (s)=	45
#Accumulations=	2
#Range (cm-¹)=	200...3150
#Windows=	2
#Auto scanning=	Off
#Autofocus=	Off
#Macrospot=	Off
#AutoExposure=	Off
#Spike filter=	Multiple accum.
#Delay time (s)=	0
#Binning=	1
#Readout mode=	Signal
#DeNoise=	Off
#ICS correction=	On
#Dark correction=	Off
#Inst. Process=	Off
#Detector Gain=	Best Dynamic Range
#Detector ADC=	20 kHz
#Detector temperature (°C)=	-69.85
#Instrument=	LabRAM HR Evol
#Detector=	Synapse
#Objective=	x100
#Grating=	600 gr/mm
#ND Filter=	100%
#Laser (nm)=	532
#Hole=	100.021
#Range=	Auto
#Laser Pol.=	No
#Raman. Pol.=	No
#Laser Pol. (°)=	-0.0007625
#Raman Pol. (°)=	89.9995
#Collection=	Microscope
#StageXY=	Marzhauser
#StageZ=	Marzhauser
#X (µm)=	1967.9
#Y (µm)=	-51.5
#Z (µm)=	425.75
#Full time(mm:ss)=	3:19
#Project=
#Sample=
#Site=
#Title=	Thy_40_11_16_2x_45s_532 nm_x100_100%_600 gr_mm
#Remark=
#Date=	05.07.2022 11:01
#Acquired=	05.07.2022 11:01:36
#Base:Fit=	10.08.2022 10:01:35
#Base:Sub=	10.08.2022 10:01:52
#Filter:Polynom=	16.08.2022 10:21:53
#AxisType[0]=Intens
#AxisUnit[0]=Cnt
#AxisType[1]=Spectr
#AxisUnit[1]=1/cm
200.43	1.73562
204.059	9.75659
207.688	14.7047
211.314	17.4985
214.941	19.3568
218.564	19.9612
222.186	19.6732
225.809	18.4358
229.428	18.4167
233.045	17.1234
236.663	16.0648
240.278	14.0856
243.891	13.5649
247.503	10.3486
251.116	5.57953
254.725	4.62761
258.333	3.87148
261.939	4.084
265.544	4.20526
269.148	5.96585
272.75	5.08733
276.351	5.79027
279.95	5.26011
283.548	5.19174
287.144	5.72744
290.739	6.27827
294.333	7.93009
297.925	7.51214
301.514	10.0443
305.104	9.34863
308.692	10.0369
312.279	11.1727
315.862	12.6731
319.446	12.8872
323.029	12.2961
326.608	12.9642
330.188	11.7918
333.766	11.4997
337.341	9.11684
340.917	8.59688
344.489	9.21268
348.062	8.51038
351.631	8.59061
355.201	7.69745
358.768	7.93822
362.333	7.50134
365.899	6.5428
369.462	6.33187
373.023	6.58467
376.585	6.46909
380.143	5.77198
383.7	4.92096
387.256	4.68164
390.812	5.04768
394.365	4.78752
397.916	6.88598
401.467	6.58274
405.015	6.27032
408.563	4.19516
412.109	4.06678
415.654	4.10176
419.197	4.16508
422.739	3.19452
426.279	3.25978
429.819	3.04264
433.356	3.19489
436.891	2.82797
440.426	3.33616
443.96	3.42666
447.492	2.60115
451.021	2.32469
454.551	2.97255
458.079	3.61912
461.604	3.36077
465.13	3.71095
468.654	4.60627
472.175	6.72087
475.696	6.029
479.215	7.77969
482.733	9.46523
486.249	11.4379
489.765	11.7341
493.278	10.9416
496.789	11.7522
500.301	13.7089
503.81	16.1725
507.317	15.8106
510.825	16.4076
514.33	16.5845
517.833	17.1198
521.335	16.1639
524.836	16.2119
528.335	15.8864
531.835	15.1884
535.332	15.0109
538.827	14.2485
542.321	13.7337
545.814	12.2095
549.305	11.5052
552.795	10.668
556.282	10.1326
559.769	8.48686
563.255	7.00232
566.739	7.70752
570.223	5.84312
573.705	4.33743
577.183	3.16088
580.663	1.91707
584.141	3.12491
587.615	3.60199
591.09	3.41117
594.564	1.87581
598.035	1.7662
601.506	2.23754
604.974	2.0971
608.443	3.29699
611.908	3.94025
615.374	4.73376
618.837	5.90606
622.3	6.35127
625.761	6.45467
629.219	7.39756
632.677	9.18593
636.135	10.8203
639.59	11.605
643.043	12.6177
646.495	13.3766
649.948	15.3763
653.398	15.6465
656.846	17.0545
660.293	19.0887
663.738	20.7326
667.183	21.6629
670.626	22.9959
674.067	21.8089
677.508	23.664
680.947	24.3032
684.385	25.8655
687.821	27.2489
691.254	29.8275
694.688	30.7192
698.121	33.3798
701.552	35.4606
704.98	38.7391
708.409	40.8192
711.836	42.9422
715.26	45.4795
718.685	47.4124
722.108	48.7067
725.528	50.5059
728.949	51.1492
732.367	52.2933
735.785	52.5299
739.2	54.0216
742.614	54.4618
746.028	55.9582
749.439	55.7257
752.849	56.9978
756.26	59.2497
759.667	61.1643
763.073	63.1011
766.477	63.6363
769.883	67.0321
773.285	69.2612
776.686	70.9525
780.085	73.0791
783.484	75.0496
786.881	76.1793
790.276	76.7392
793.671	78.148
797.064	80.3271
800.456	81.502
803.846	82.2183
807.234	84.1742
810.622	83.558
814.008	84.0716
817.394	84.2467
820.778	84.3783
824.159	84.0641
827.541	83.3707
830.921	83.769
834.298	82.5301
837.676	82.0741
841.051	79.8004
844.426	76.9706
847.798	75.3552
851.171	73.9012
854.54	70.9392
857.911	68.6154
861.278	66.083
864.645	63.3139
868.01	62.2415
871.373	60.3032
874.735	60.4539
878.097	59.8612
881.457	59.9565
884.815	59.5208
888.172	60.0082
891.528	58.6015
894.882	58.1842
898.237	58.3784
901.589	57.2573
904.94	55.9905
908.289	55.0578
911.635	53.2862
914.982	50.7992
918.328	48.2416
921.672	46.8914
925.015	45.095
928.357	42.4633
931.698	40.6757
935.035	38.7536
938.373	37.792
941.71	37.4477
945.044	36.491
948.378	35.2846
951.709	36.1043
955.041	36.8037
958.372	35.9778
961.699	36.51
965.027	36.5699
968.352	37.8869
971.676	38.5364
975	39.8291
978.322	40.4673
981.642	41.7056
984.962	41.695
988.28	42.3098
991.596	42.3627
994.911	39.5906
998.227	38.402
1001.54	39.2061
1004.85	41.0363
1008.16	42.0414
1011.47	42.3602
1014.78	43.1338
1018.08	45.1392
1021.39	45.7056
1024.69	46.919
1028	47.4478
1031.3	48.2691
1034.6	47.1452
1037.9	46.2048
1041.19	45.6971
1044.49	44.9893
1047.78	43.8722
1051.08	41.8464
1054.37	39.1912
1057.66	36.5345
1060.95	34.1961
1064.24	31.8391
1067.53	28.9341
1070.81	24.9958
1074.1	20.2199
1077.38	19.4806
1080.66	19.1487
1083.94	18.8641
1087.22	17.4909
1090.5	16.621
1093.78	16.2846
1097.05	16.3254
1100.33	16.911
1103.6	16.0778
1106.87	16.7363
1110.14	15.3398
1113.41	14.5736
1116.68	13.9831
1119.95	13.6748
1123.21	12.9031
1126.48	10.3814
1129.74	9.59227
1133	8.96745
1136.26	9.30617
1139.52	8.63656
1142.78	9.00331
1146.04	7.69195
1149.29	6.7237
1152.55	5.84429
1155.8	6.78241
1159.05	6.61652
1162.3	5.14604
1165.55	3.10796
1168.8	3.21076
1172.05	3.02433
1175.29	2.99891
1178.54	3.08711
1181.78	2.666
1185.02	4.63751
1188.26	6.29751
1191.5	6.53299
1194.74	7.30864
1197.97	8.42
1201.21	9.67298
1204.44	9.49974
1207.68	11.9931
1210.91	17.1398
1214.14	20.3567
1217.37	24.6786
1220.59	28.2268
1223.82	30.4391
1227.05	34.0828
1230.27	39.0822
1233.49	43.0519
1236.72	44.9517
1239.94	45.0094
1243.16	46.5436
1246.37	47.1526
1249.59	48.4383
1252.8	51.1848
1256.02	52.466
1259.23	53.4052
1262.44	53.9205
1265.66	55.9167
1268.86	55.3208
1272.07	54.2352
1275.28	54.2052
1278.48	54.2436
1281.69	55.2807
1284.89	56.9595
1288.09	58.9411
1291.29	60.9872
1294.49	62.9449
1297.69	64.3493
1300.89	66.0377
1304.08	69.4333
1307.28	73.5466
1310.47	74.778
1313.66	76.1148
1316.85	74.8946
1320.04	76.0733
1323.23	76.7291
1326.42	75.5807
1329.61	75.0172
1332.79	74.9884
1335.97	73.2336
1339.16	71.2357
1342.34	68.8903
1345.52	66.8283
1348.7	62.5447
1351.87	59.3054
1355.05	56.9581
1358.22	53.1298
1361.4	49.5313
1364.57	45.9819
1367.74	43.8856
1370.91	42.0504
1374.08	39.4566
1377.25	38.374
1380.41	38.3154
1383.58	37.9408
1386.74	35.8387
1389.91	34.0631
1393.07	32.146
1396.23	30.6695
1399.39	30.752
1402.55	29.888
1405.7	28.6051
1408.86	29.5836
1412.01	30.2257
1415.17	31.6794
1418.32	33.6785
1421.47	37.1101
1424.62	39.7124
1427.77	43.8067
1430.91	47.7564
1434.06	52.469
1437.2	56.8113
1440.35	59.8563
1443.49	63.0684
1446.63	64.6618
1449.77	65.0419
1452.91	65.0686
1456.05	64.3211
1459.18	63.6865
1462.32	60.8324
1465.45	57.4093
1468.59	53.2902
1471.72	49.1229
1474.85	43.1562
1477.98	38.5618
1481.1	32.8697
1484.23	27.5326
1487.36	23.3365
1490.48	18.3816
1493.61	16.8234
1496.73	16.0531
1499.85	15.0029
1502.97	14.2576
1506.09	15.192
1509.2	14.9809
1512.32	15.8076
1515.43	16.0959
1518.55	17.7177
1521.66	19.8617
1524.77	22.3929
1527.88	24.435
1530.99	27.4318
1534.1	29.513
1537.21	32.062
1540.31	35.7802
1543.42	39.0679
1546.52	42.2259
1549.62	44.7013
1552.72	47.4356
1555.82	51.1825
1558.92	52.4592
1562.02	55.0374
1565.11	56.6132
1568.21	57.7621
1571.3	61.3981
1574.39	63.2909
1577.49	64.7372
1580.57	65.6173
1583.66	65.9436
1586.75	66.809
1589.84	68.0021
1592.92	68.7123
1596.01	69.1098
1599.09	68.9765
1602.17	68.6947
1605.25	67.1374
1608.33	66.9084
1611.41	67.0764
1614.49	67.9686
1617.57	67.6735
1620.64	69.8474
1623.72	71.1724
1626.79	72.785
1629.86	75.1559
1632.93	76.091
1636	76.8565
1639.07	79.3563
1642.13	81.858
1645.2	83.8237
1648.26	86.0948
1651.33	87.3416
1654.39	87.7122
1657.45	88.1474
1660.51	87.9411
1663.57	86.2431
1666.63	84.6097
1669.68	81.4789
1672.74	77.5553
1675.79	72.9125
1678.85	67.4483
1681.9	62.1215
1684.95	57.3731
1688	51.6832
1691.05	46.0986
1694.09	41.6458
1697.14	37.6756
1700.18	32.3282
1703.23	27.6548
1706.27	23.8815
1709.31	19.512
1712.35	16.7275
1715.39	14.6357
1718.43	13.4701
1721.47	11.6946
1724.5	11.0782
1727.54	9.53082
1730.57	8.56059
1733.61	8.19962
1736.64	7.80404
1739.67	6.84429
1742.7	6.72881
1745.72	6.86262
1748.75	5.86995
1751.77	5.86331
1754.8	5.91121
1757.82	6.27607
1760.84	5.06661
1763.87	4.63806
1766.89	4.30072
1769.91	3.65296
1772.92	2.38702
1775.94	1.14418
1778.95	1.5711
1781.97	0.953097
1784.98	1.12267
1787.99	1.20709
1791.01	1.8132
1794.01	1.1913
1797.02	1.25415
1800.03	0.3251
1803.04	0.0399978
1806.04	1.24436
1809.05	1.71713
1812.05	1.83656
1815.05	2.31357
1818.05	2.50708
1821.05	2.99593
1824.05	2.80372
1827.05	2.88464
1830.04	3.23894
1833.04	3.04052
1836.03	1.98242
1839.03	1.91226
1842.02	1.07263
1845.01	0.469345
1848	0.0229873
1850.99	0.181977
1853.97	0.591433
1856.96	0.416103
1859.94	0.374664
1862.93	0.267537
1865.91	0.342071
1868.89	0.75497
1871.87	0.223624
1874.85	1.13032
1877.83	2.2714
1880.81	2.22448
1882.57	2.90543
1885.56	2.86601
1888.55	2.99578
1891.54	3.82557
1894.52	3.44587
1897.51	3.94833
1900.49	4.71506
1903.47	4.63691
1906.45	4.23457
1909.43	4.15843
1912.41	3.97865
1915.39	4.25452
1918.37	4.50958
1921.34	3.8886
1924.32	3.88632
1927.29	4.16418
1930.26	4.38387
1933.23	4.70278
1936.2	5.65509
1939.17	6.04575
1942.14	5.66612
1945.11	6.19267
1948.07	7.19442
1951.04	6.89708
1954	7.07554
1956.96	6.67068
1959.93	6.70798
1962.89	5.56753
1965.85	5.42764
1968.8	4.47237
1971.76	4.13154
1974.72	4.00584
1977.67	4.96251
1980.63	4.68215
1983.58	4.84975
1986.53	4.90534
1989.48	3.86174
1992.43	3.61653
1995.38	3.81611
1998.32	5.08975
2001.27	5.51524
2004.22	5.41361
2007.16	5.73839
2010.1	5.94142
2013.04	6.34793
2015.98	7.98341
2018.92	8.87526
2021.86	9.52828
2024.8	9.11942
2027.74	9.50139
2030.67	9.92032
2033.61	10.4601
2036.54	10.777
2039.47	10.6725
2042.4	10.7608
2045.33	11.3911
2048.26	12.3697
2051.19	12.3865
2054.12	11.935
2057.04	11.3293
2059.97	12.0205
2062.89	12.5959
2065.81	13.662
2068.73	14.7803
2071.65	15.8555
2074.57	15.1128
2077.49	15.3278
2080.41	16.518
2083.32	17.2408
2086.24	18.3359
2089.15	19.2557
2092.07	19.5557
2094.98	20.8571
2097.89	21.2865
2100.8	23.1079
2103.71	24.3971
2106.61	25.6617
2109.52	26.6775
2112.43	27.8914
2115.33	30.0917
2118.23	32.3546
2121.13	35.4332
2124.04	38.396
2126.94	41.6378
2129.83	44.1269
2132.73	47.3973
2135.63	51.1079
2138.53	54.585
2141.42	58.7978
2144.31	62.7971
2147.21	66.5574
2150.1	69.7492
2152.99	73.261
2155.88	75.106
2158.77	78.6392
2161.65	80.5707
2164.54	82.5895
2167.43	84.4671
2170.31	86.1364
2173.19	87.1907
2176.07	87.3837
2178.96	87.389
2181.84	87.1364
2184.72	85.4984
2187.59	84.2617
2190.47	82.1642
2193.35	80.5865
2196.22	78.1458
2199.09	74.211
2201.97	69.7862
2204.84	66.2498
2207.71	63.237
2210.58	60.501
2213.45	56.9232
2216.31	52.5206
2219.18	48.5197
2222.05	44.3338
2224.91	41.9636
2227.78	39.4701
2230.64	37.1755
2233.5	34.757
2236.36	33.5484
2239.22	31.7553
2242.08	30.785
2244.93	29.5658
2247.79	28.8868
2250.64	28.1879
2253.5	28.3533
2256.35	27.2832
2259.2	27.3685
2262.05	27.1835
2264.9	26.6409
2267.75	24.948
2270.6	23.0721
2273.45	22.0453
2276.29	21.3958
2279.14	20.2968
2281.98	19.6265
2284.82	18.216
2287.66	17.0252
2290.5	16.4664
2293.34	15.7314
2296.18	14.8583
2299.02	13.8572
2301.86	13.2738
2304.69	12.0541
2307.53	13.1135
2310.36	13.0702
2313.19	11.6639
2316.02	12.2592
2318.85	11.5449
2321.68	11.1016
2324.51	10.5991
2327.34	9.50834
2330.16	9.55035
2332.99	8.47167
2335.81	7.45853
2338.64	6.11236
2341.46	5.98441
2344.28	5.93873
2347.1	5.91305
2349.92	5.94505
2352.74	5.30906
2355.55	4.7333
2358.37	3.72364
2361.19	2.55376
2364	1.78693
2366.81	1.51829
2369.62	0.159921
2372.44	-0.287867
2375.24	-0.0485448
2378.05	0.268377
2380.86	0.166405
2383.67	0.181658
2386.47	1.09258
2389.28	1.75966
2392.08	2.26181
2394.89	2.949
2397.69	3.10038
2400.49	3.92147
2403.29	4.23534
2406.09	5.1796
2408.88	5.35232
2411.68	5.88387
2414.48	6.64313
2417.27	6.14286
2420.06	6.5703
2422.86	5.97142
2425.65	4.8741
2428.44	5.07419
2431.23	4.54665
2434.02	3.67241
2436.81	2.78611
2439.59	2.60636
2442.38	3.60614
2445.16	3.94372
2447.95	4.20937
2450.73	5.06485
2453.51	5.78764
2456.29	5.80231
2459.07	5.59824
2461.85	5.57587
2464.63	4.94446
2467.4	5.01628
2470.18	5.23374
2472.95	5.20675
2475.73	3.77924
2478.5	3.64041
2481.27	3.09017
2484.04	2.90554
2486.81	2.45175
2489.58	1.58264
2492.35	1.19609
2495.12	0.74142
2497.88	0.947822
2500.65	0.14699
2503.41	0.197639
2506.17	1.22529
2508.94	2.12323
2511.7	2.98814
2514.46	2.64876
2517.22	3.49661
2519.97	4.01178
2522.73	3.31875
2525.49	3.97969
2528.24	4.02242
2530.99	4.23212
2533.75	5.37566
2536.5	5.48176
2539.25	5.27218
2542	5.85291
2544.75	5.55716
2547.5	5.56622
2550.24	4.98235
2552.99	4.20506
2555.74	4.7471
2558.48	4.5553
2561.22	4.37025
2563.96	4.48965
2566.71	5.88833
2569.45	6.33592
2572.18	7.42344
2574.92	8.15783
2577.66	7.42699
2580.4	7.02359
2583.13	6.27159
2585.87	6.17486
2588.6	5.16051
2591.33	4.72639
2594.06	5.06039
2596.79	5.15846
2599.52	4.94937
2602.25	4.31871
2604.98	3.49171
2607.71	3.09327
2610.43	3.02232
2613.16	3.0243
2615.88	2.54903
2618.6	2.34374
2621.32	2.20927
2624.04	2.78235
2626.76	3.15107
2629.48	2.94386
2632.2	4.31164
2634.92	5.21237
2637.63	5.01087
2640.35	4.28502
2643.06	3.33066
2645.77	2.77513
2648.49	2.78599
2651.2	3.33754
2653.91	3.20162
2656.62	3.3026
2659.33	4.16576
2662.03	4.40659
2664.74	4.01244
2667.44	4.24161
2670.15	4.54176
2672.85	5.0845
2675.55	5.58633
2678.26	5.66835
2680.96	4.95248
2683.66	5.62279
2686.35	5.68649
2689.05	5.58339
2691.75	6.0222
2694.44	5.14195
2697.14	4.30075
2699.83	4.67461
2702.52	4.82204
2705.22	4.90288
2707.91	5.23733
2710.6	5.29627
2713.29	6.29817
2715.97	7.06799
2718.66	6.97831
2721.35	7.38779
2724.03	8.96557
2726.72	9.00655
2729.4	10.1781
2732.08	10.1141
2734.76	10.6712
2737.44	10.5773
2740.12	9.76785
2742.8	8.96737
2745.48	8.78889
2748.16	8.4519
2750.83	7.67337
2753.51	6.35961
2756.18	5.10164
2758.85	4.13437
2761.53	3.70325
2764.2	3.52553
2766.87	3.67056
2769.54	2.9439
2772.2	2.53892
2774.87	1.81204
2777.54	1.48821
2780.2	1.16805
2782.87	-0.183511
2785.53	-0.525287
2788.19	-0.201598
2790.85	0.0761959
2793.51	-0.821284
2796.17	0.430029
2798.83	0.488627
2801.49	0.825932
2804.15	1.03996
2806.8	1.60028
2809.46	2.4559
2812.11	2.73416
2814.76	2.09251
2817.42	3.23358
2820.07	4.60847
2822.72	6.76014
2825.37	8.67379
2828.02	11.674
2830.66	14.3938
2833.31	17.589
2835.96	19.949
2838.6	22.7067
2841.24	26.0587
2843.89	31.4098
2846.53	36.7969
2849.17	42.1301
2851.81	48.4744
2854.45	55.2514
2857.09	61.1979
2859.72	68.8079
2862.36	75.3446
2865	81.2328
2867.63	87.2156
2870.26	91.8983
2872.9	96.9659
2875.53	101.263
2878.16	104.429
2880.79	108.519
2883.42	112.346
2886.05	115.569
2888.67	119.599
2891.3	123.156
2893.92	127.703
2896.55	132.097
2899.17	136.85
2901.79	143.031
2904.42	150.56
2907.04	160.805
2909.66	171.81
2912.27	182.975
2914.89	193.09
2917.51	203.062
2920.13	212.482
2922.74	220.081
2925.35	226.269
2927.97	230.94
2930.58	234.964
2933.19	235.989
2935.8	236.025
2938.41	235.029
2941.02	230.242
2943.63	225.37
2946.24	219.287
2948.84	211.344
2951.45	202.979
2954.05	193.953
2956.65	184.394
2959.26	175.196
2961.86	165.969
2964.46	157.119
2967.06	148.725
2969.66	140.619
2972.25	133.825
2974.85	126.518
2977.45	118.875
2980.04	111.882
2982.64	103.036
2985.23	94.7943
2987.82	86.4486
2990.41	79.3287
2993	72.4242
2995.59	65.7166
2998.18	59.0623
3000.77	52.6978
3003.36	47.055
3005.94	41.552
3008.53	36.9693
3011.11	32.0595
3013.69	27.306
3016.28	23.3917
3018.86	20.7645
3021.44	18.2702
3024.02	16.2986
3026.6	14.3398
3029.18	13.2432
3031.75	12.8117
3034.33	13.2893
3036.9	13.0431
3039.48	14.0707
3042.05	14.9565
3044.62	15.5707
3047.19	16.357
3049.77	17.244
3052.34	17.7742
3054.9	18.4441
3057.47	18.6787
3060.04	19.2018
3062.61	18.9168
3065.17	18.0993
3067.74	17.3571
3070.3	15.6136
3072.86	14.0295
3075.42	12.2813
3077.99	10.0734
3080.54	8.22862
3083.1	6.81059
3085.66	5.78237
3088.22	3.90543
3090.78	2.30737
3093.33	1.47643
3095.89	1.00642
3098.44	0.386849
3100.99	0.812365
3103.54	1.26364
3106.1	0.781521
3108.65	1.52036
3111.2	1.24161
3113.74	1.97514
3116.29	2.8311
3118.84	3.46606
3121.38	4.30962
3123.93	4.89504
3126.47	5.32801
3129.01	6.20076
3131.56	6.89954
3134.1	7.62642
3136.64	8.23584
3139.18	9.10312
3141.72	9.95093
3144.26	11.4777
3146.79	13.0763
3149.33	15.3497