File: data/Raman/poly_smoothed/Thy_00_07_45_1x_45s_532 nm_x100_100%_600 gr_mm_01_0.txt
#Acq. time (s)=	45
#Accumulations=	2
#Range (cm-¹)=	200...3150
#Windows=	2
#Auto scanning=	Off
#Autofocus=	Off
#Macrospot=	Off
#AutoExposure=	Off
#Spike filter=	Multiple accum.
#Delay time (s)=	0
#Binning=	1
#Readout mode=	Signal
#DeNoise=	Off
#ICS correction=	On
#Dark correction=	Off
#Inst. Process=	Off
#Detector Gain=	Best Dynamic Range
#Detector ADC=	20 kHz
#Detector temperature (°C)=	-69.85
#Instrument=	LabRAM HR Evol
#Detector=	Synapse
#Objective=	x100
#Grating=	600 gr/mm
#ND Filter=	100%
#Laser (nm)=	532
#Hole=	100.021
#Range=	Auto
#Laser Pol.=	No
#Raman. Pol.=	No
#Laser Pol. (°)=	-0.0007625
#Raman Pol. (°)=	89.9995
#Collection=	Microscope
#StageXY=	Marzhauser
#StageZ=	Marzhauser
#X (µm)=	-1435.8
#Y (µm)=	-613.2
#Z (µm)=	-227.9
#Full time(mm:ss)=	3:18
#Project=
#Sample=
#Site=
#Title=	Thy_00_07_45_2x_45s_532 nm_x100_100%_600 gr_mm
#Remark=
#Date=	29.06.2022 09:41
#Acquired=	29.06.2022 09:41:23
#Base:Fit=	10.08.2022 10:07:56
#Base:Sub=	10.08.2022 10:08:40
#Filter:Polynom=	16.08.2022 10:26:06
#AxisType[0]=Intens
#AxisUnit[0]=Cnt
#AxisType[1]=Spectr
#AxisUnit[1]=1/cm
200.523	19.4384
204.154	20.7208
207.781	21.39
211.409	22.6338
215.034	24.3272
218.659	26.6517
222.281	27.176
225.903	27.5729
229.522	26.9965
233.14	25.0265
236.756	22.68
240.373	20.8091
243.986	19.1768
247.598	17.6459
251.208	16.1627
254.818	15.2181
258.427	13.4441
262.034	11.9899
265.638	10.9804
269.242	10.2813
272.844	9.25906
276.445	9.00011
280.044	7.30171
283.642	7.58117
287.238	7.71169
290.833	8.98374
294.425	11.5566
298.017	14.657
301.608	16.1788
305.198	17.4824
308.786	17.5676
312.371	18.703
315.956	19.4573
319.54	19.3132
323.122	19.9993
326.701	19.0799
330.281	20.7344
333.857	21.717
337.434	20.7845
341.008	21.9237
344.582	20.5492
348.153	17.3188
351.724	16.8547
355.292	14.4159
358.861	13.6778
362.426	12.8975
365.99	10.469
369.555	8.44715
373.116	8.50973
376.676	7.32248
380.236	6.7549
383.793	5.0157
387.349	4.17514
390.903	4.51542
394.456	5.80658
398.007	5.83195
401.56	7.13067
405.108	7.36235
408.656	7.70245
412.202	10.2803
415.746	10.9317
419.29	12.375
422.831	14.1698
426.37	14.4466
429.909	12.5169
433.447	11.4304
436.983	13.0231
440.519	14.1174
444.052	15.4969
447.583	18.5974
451.114	20.2563
454.643	21.5517
458.169	23.0249
461.696	25.1442
465.222	26.9185
468.744	28.1892
472.267	30.6461
475.787	33.4421
479.307	35.0175
482.823	34.4115
486.341	34.6637
489.855	35.7802
493.37	34.5081
496.881	34.6135
500.391	34.7153
503.902	32.8681
507.409	31.5527
510.915	29.1748
514.42	24.9433
517.925	21.7056
521.427	20.8666
524.928	20.3077
528.427	18.6989
531.925	16.9635
535.422	15.9437
538.917	15.0238
542.411	15.0232
545.903	15.088
549.395	14.8275
552.884	14.8412
556.373	15.8557
559.86	15.5705
563.346	14.9664
566.831	13.4156
570.314	13.6478
573.794	13.2962
577.274	11.7172
580.754	11.3483
584.23	11.6909
587.706	10.7651
591.181	10.451
594.653	9.91402
598.126	8.52832
601.595	6.40948
605.065	5.55643
608.532	6.48977
611.999	5.06836
615.463	4.838
618.928	4.47987
622.389	6.04189
625.851	5.25752
629.31	5.61752
632.767	4.65526
636.223	4.74926
639.68	6.50493
643.134	6.50323
646.586	6.36074
650.037	7.68728
653.486	6.39435
656.936	6.8233
660.383	6.69716
663.829	7.22469
667.273	7.86465
670.716	8.1808
674.158	10.4766
677.598	12.7748
681.035	15.6625
684.473	18.3224
687.909	20.8918
691.344	24.219
694.778	26.4705
698.211	28.0946
701.64	28.6898
705.07	29.1534
708.498	30.5657
711.924	31.7107
715.35	34.5651
718.774	35.181
722.196	40.007
725.618	40.6887
729.037	41.4698
732.456	43.6925
735.873	46.1247
739.289	47.2873
742.703	49.3795
746.116	51.3131
749.529	52.2417
752.938	55.1561
756.347	56.5582
759.756	60.4446
763.162	62.9219
766.567	63.2818
769.97	63.717
773.372	64.5135
776.773	64.4855
780.174	64.7405
783.573	64.2873
786.97	64.8957
790.365	65.349
793.76	66.8466
797.153	67.2419
800.543	69.6948
803.933	70.9492
807.322	71.37
810.71	73.5556
814.097	75.9026
817.483	77.2816
820.865	79.1497
824.248	81.3018
827.629	83.3873
831.008	84.4569
834.387	85.7387
837.765	86.9579
841.139	87.0759
844.514	86.6389
847.886	84.9173
851.259	80.757
854.629	77.3671
857.997	74.4954
861.366	72.5902
864.732	68.7453
868.098	66.5753
871.461	63.7344
874.823	60.4036
878.184	57.1127
881.545	55.5905
884.903	53.8171
888.26	51.984
891.616	51.576
894.97	50.8693
898.323	51.1604
901.675	52.9078
905.026	55.2056
908.375	58.1939
911.723	60.2699
915.07	62.3847
918.415	63.2266
921.76	63.3266
925.103	64.139
928.443	62.4905
931.783	61.2155
935.123	57.5939
938.461	55.7476
941.796	53.3379
945.131	50.1866
948.465	47.6522
951.797	44.7287
955.128	41.1429
958.457	35.9748
961.786	33.01
965.113	31.5278
968.44	30.6661
971.763	32.2826
975.086	31.4201
978.409	32.6089
981.729	34.6814
985.048	34.2957
988.367	34.6819
991.683	35.7698
994.998	35.9955
998.312	36.9011
1001.62	37.7192
1004.94	39.6906
1008.25	40.7733
1011.56	40.4006
1014.86	41.1918
1018.17	41.7061
1021.48	42.5959
1024.78	40.6895
1028.08	41.0617
1031.38	39.2305
1034.68	37.0779
1037.98	33.3506
1041.28	31.8052
1044.57	33.5033
1047.87	34.0239
1051.16	33.6607
1054.45	32.7701
1057.75	31.9641
1061.04	31.8397
1064.32	31.0911
1067.61	29.8661
1070.9	30.6173
1074.18	30.5416
1077.47	32.4766
1080.75	34.7723
1084.03	35.9427
1087.31	37.6489
1090.59	39.7571
1093.86	44.5685
1097.14	44.9914
1100.41	46.497
1103.69	46.8667
1106.96	47.1506
1110.23	47.5143
1113.5	46.2617
1116.77	44.6863
1120.03	44.0349
1123.3	42.974
1126.56	42.9621
1129.83	41.7031
1133.09	39.1239
1136.35	37.9529
1139.61	35.0493
1142.86	32.3112
1146.12	28.5997
1149.38	26.0191
1152.63	22.2532
1155.88	19.8585
1159.14	16.0704
1162.39	11.5723
1165.63	9.04799
1168.88	6.76822
1172.13	5.6617
1175.38	3.43107
1178.62	2.43796
1181.86	3.00255
1185.1	4.8269
1188.34	6.08952
1191.58	6.46575
1194.82	8.96042
1198.06	11.5764
1201.29	16.6345
1204.53	21.0612
1207.76	24.7104
1210.99	25.4143
1214.22	30.3307
1217.45	33.5723
1220.68	36.7463
1223.91	41.6615
1227.13	44.2138
1230.36	45.6124
1233.58	45.9056
1236.8	46.7812
1240.02	45.9359
1243.24	46.8744
1246.46	46.0296
1249.67	44.6746
1252.89	43.2591
1256.1	42.3796
1259.32	42.3033
1262.53	42.6591
1265.74	41.9003
1268.95	42.1372
1272.15	42.7302
1275.36	43.9044
1278.57	45.1326
1281.77	48.3224
1284.97	49.4291
1288.18	50.9773
1291.38	54.1795
1294.58	58.5047
1297.78	63.2771
1300.97	68.0328
1304.17	70.5617
1307.36	74.3546
1310.55	78.205
1313.75	81.7194
1316.94	85.0543
1320.13	87.654
1323.32	89.005
1326.5	90.4827
1329.69	90.3506
1332.87	90.6161
1336.06	90.7515
1339.24	90.2857
1342.42	89.1111
1345.6	87.414
1348.78	85.1035
1351.96	82.1497
1355.13	79.21
1358.31	77.5639
1361.48	75.2294
1364.65	71.3445
1367.82	69.2197
1370.99	67.394
1374.16	65.8465
1377.33	64.1507
1380.5	63.6698
1383.66	63.0132
1386.83	62.1217
1389.99	61.6502
1393.15	61.3924
1396.31	59.677
1399.47	59.0467
1402.63	58.1621
1405.78	57.0963
1408.94	57.9874
1412.1	58.1551
1415.25	59.6731
1418.4	62.7839
1421.55	64.8676
1424.7	67.985
1427.85	71.1109
1431	74.7455
1434.14	79.6576
1437.29	84.3336
1440.43	86.4957
1443.57	89.3588
1446.71	90.6598
1449.85	90.4518
1452.99	90.0064
1456.13	87.7185
1459.26	83.2014
1462.4	79.4229
1465.54	73.4531
1468.67	68.0862
1471.8	60.8227
1474.93	53.7379
1478.06	46.6019
1481.19	40.342
1484.31	34.1498
1487.44	28.4273
1490.56	23.8254
1493.69	20.7097
1496.81	17.1035
1499.93	15.6284
1503.05	15.2969
1506.17	13.9863
1509.28	14.251
1512.4	14.9883
1515.52	14.6606
1518.63	15.9802
1521.74	15.9665
1524.85	16.9879
1527.96	17.8339
1531.07	19.2228
1534.18	21.3697
1537.29	23.2319
1540.39	26.6375
1543.5	28.8692
1546.6	30.6769
1549.7	32.495
1552.8	35.5599
1555.9	37.2366
1559	39.3276
1562.1	41.3234
1565.19	42.8949
1568.29	44.9016
1571.38	47.361
1574.47	49.8455
1577.56	52.6234
1580.66	52.5109
1583.74	54.3458
1586.83	56.9161
1589.92	57.922
1593.01	60.1556
1596.09	61.1213
1599.17	60.1098
1602.25	59.8367
1605.34	58.6083
1608.41	58.6151
1611.49	58.2319
1614.57	59.2256
1617.65	59.973
1620.72	60.0059
1623.79	59.2205
1626.87	60.4789
1629.94	60.8986
1633.01	61.8824
1636.08	62.3669
1639.15	63.1391
1642.21	66.119
1645.28	68.1936
1648.34	69.6184
1651.41	72.222
1654.47	71.4067
1657.53	72.0068
1660.59	72.4838
1663.65	70.8678
1666.71	68.9429
1669.76	65.8865
1672.82	61.895
1675.87	57.5132
1678.93	54.0354
1681.98	51.101
1685.03	46.5071
1688.08	43.3657
1691.13	39.8735
1694.17	34.1832
1697.22	29.1158
1700.27	25.2163
1703.31	22.0525
1706.35	19.5058
1709.39	17.4396
1712.43	16.3546
1715.47	15.1921
1718.51	15.0198
1721.55	13.643
1724.58	13.5806
1727.62	13.5734
1730.65	13.158
1733.68	13.6712
1736.72	14.1751
1739.74	14.8182
1742.77	14.5557
1745.8	15.6449
1748.83	15.15
1751.85	15.0268
1754.88	15.0707
1757.9	13.6573
1760.92	12.0772
1763.95	10.7708
1766.96	9.25725
1769.98	7.48547
1773	6.79438
1776.02	6.33904
1779.03	4.99415
1782.05	4.44067
1785.06	3.94604
1788.07	3.54151
1791.08	2.9816
1794.09	2.92655
1797.1	3.00566
1800.11	4.26905
1803.12	4.56285
1806.12	4.58127
1809.12	5.1709
1812.13	5.70973
1815.13	6.77835
1818.13	6.46489
1821.13	6.5425
1824.13	5.87618
1827.13	5.89858
1830.12	5.63842
1833.12	6.71276
1836.11	7.14406
1839.1	7.96949
1842.09	7.96547
1845.09	8.21144
1848.08	8.56655
1851.06	8.35513
1854.05	8.95
1857.04	9.02972
1860.02	8.55668
1863.01	9.33566
1865.99	8.3333
1868.97	7.86935
1871.95	8.60381
1874.93	9.22726
1877.91	9.17426
1880.89	9.21545
1882.46	9.7723
1885.45	9.23621
1888.43	7.62934
1891.42	6.62071
1894.41	6.03316
1897.39	5.7529
1900.37	6.20195
1903.36	6.47201
1906.34	6.6012
1909.32	5.66716
1912.29	5.32321
1915.27	4.60478
1918.25	4.24383
1921.23	4.69191
1924.2	4.93105
1927.17	4.75426
1930.15	3.6124
1933.12	3.48341
1936.09	2.03562
1939.06	1.77843
1942.02	2.74237
1944.99	3.37343
1947.96	3.51228
1950.92	4.13633
1953.88	4.27768
1956.85	3.94312
1959.81	4.23552
1962.77	4.18115
1965.73	5.1897
1968.69	6.71535
1971.64	7.11723
1974.6	7.58753
1977.55	8.2148
1980.51	8.85469
1983.46	9.68795
1986.41	10.1354
1989.36	10.0407
1992.31	11.1441
1995.26	11.3505
1998.21	10.28
2001.15	8.68016
2004.1	7.93844
2007.04	6.54513
2009.99	5.72471
2012.93	6.47913
2015.87	6.33193
2018.81	6.02902
2021.75	6.13975
2024.68	5.65153
2027.62	4.75995
2030.56	4.1105
2033.49	3.08788
2036.42	3.2362
2039.36	3.3249
2042.29	3.8399
2045.22	3.70343
2048.14	4.21231
2051.07	4.70058
2054	4.53158
2056.93	4.14694
2059.85	4.10202
2062.77	4.26444
2065.7	5.9626
2068.62	6.24197
2071.54	6.27121
2074.46	6.49908
2077.38	7.07106
2080.29	7.45441
2083.21	8.97288
2086.12	8.98359
2089.04	8.98361
2091.95	8.00827
2094.86	7.35876
2097.77	7.36316
2100.68	6.53214
2103.59	6.91536
2106.5	7.12911
2109.41	7.09025
2112.31	7.16101
2115.21	6.6979
2118.12	6.11895
2121.02	5.34414
2123.92	4.67962
2126.82	4.85165
2129.72	5.21605
2132.62	5.4264
2135.51	6.76343
2138.41	7.44739
2141.31	6.46728
2144.2	5.92689
2147.09	6.91735
2149.98	7.53661
2152.87	6.91202
2155.76	7.3403
2158.65	7.43631
2161.54	6.86024
2164.43	6.31113
2167.31	6.50417
2170.2	6.61229
2173.08	6.95163
2175.96	6.21055
2178.84	5.63284
2181.72	4.29566
2184.6	3.75644
2187.48	3.01472
2190.36	3.13203
2193.23	3.4527
2196.11	2.86064
2198.98	2.78586
2201.85	2.31235
2204.72	1.66346
2207.59	1.97534
2210.46	2.55274
2213.33	2.63124
2216.2	1.92419
2219.07	2.46509
2221.93	2.24544
2224.8	2.17581
2227.66	2.46458
2230.52	2.15135
2233.39	2.03901
2236.25	2.00316
2239.1	2.16995
2241.96	2.61373
2244.82	2.15887
2247.68	2.15964
2250.53	2.02312
2253.38	1.53902
2256.24	3.01217
2259.09	2.29905
2261.94	2.12989
2264.79	2.73345
2267.64	2.98894
2270.49	4.23583
2273.33	4.41004
2276.18	4.82979
2279.02	5.65872
2281.87	5.88063
2284.71	4.99054
2287.55	4.66488
2290.39	4.41934
2293.23	3.69962
2296.07	3.74039
2298.91	4.66859
2301.74	6.13343
2304.58	7.10762
2307.41	7.51792
2310.25	7.92975
2313.08	7.37534
2315.91	6.95835
2318.74	7.06822
2321.57	6.72128
2324.4	6.2752
2327.23	6.87922
2330.05	7.0331
2332.88	7.86574
2335.7	7.98004
2338.52	7.80644
2341.35	6.54346
2344.17	5.91365
2346.99	5.96766
2349.81	4.07405
2352.62	3.30538
2355.44	2.61987
2358.26	2.22243
2361.07	1.5242
2363.89	2.21019
2366.7	3.17899
2369.51	2.65457
2372.32	2.92336
2375.13	1.35788
2377.94	0.970199
2380.75	0.249265
2383.56	0.145963
2386.36	0.0124636
2389.17	1.04604
2391.97	1.37323
2394.77	1.79662
2397.58	2.48376
2400.38	2.85598
2403.18	2.86093
2405.97	2.94012
2408.77	2.57246
2411.57	2.81235
2414.37	4.11055
2417.16	5.54618
2419.95	5.62794
2422.75	6.11749
2425.54	5.94251
2428.33	6.50226
2431.12	7.3597
2433.91	6.21529
2436.7	6.63956
2439.48	7.08852
2442.27	6.5935
2445.05	6.37567
2447.84	5.95498
2450.62	5.86072
2453.4	5.36045
2456.18	5.75883
2458.96	5.51918
2461.74	5.08647
2464.52	4.12118
2467.29	3.25111
2470.07	2.4766
2472.85	1.73263
2475.62	0.727608
2478.39	2.17583
2481.16	2.79507
2483.93	2.51665
2486.7	1.44032
2489.47	1.15809
2492.24	1.50712
2495.01	2.66618
2497.77	2.86721
2500.54	3.61729
2503.3	4.38301
2506.06	5.58572
2508.83	5.09259
2511.59	5.43465
2514.35	4.59002
2517.11	3.73962
2519.86	3.2999
2522.62	3.02133
2525.38	3.36444
2528.13	2.81019
2530.89	2.29684
2533.64	1.86085
2536.39	1.17261
2539.14	1.17695
2541.89	0.791799
2544.64	1.53106
2547.39	1.71926
2550.14	1.08727
2552.88	1.40901
2555.63	2.0488
2558.37	2.22057
2561.11	3.65105
2563.86	5.10073
2566.6	6.56102
2569.34	7.63199
2572.08	7.70123
2574.82	7.11431
2577.55	7.0194
2580.29	7.17664
2583.02	6.58263
2585.76	6.59102
2588.49	6.50727
2591.22	6.57259
2593.96	6.11544
2596.69	5.72372
2599.42	5.77
2602.14	4.79515
2604.87	3.99193
2607.6	4.03037
2610.32	3.71258
2613.05	2.60975
2615.77	2.06644
2618.49	1.61546
2621.22	2.82273
2623.94	2.29027
2626.66	2.52736
2629.37	2.79041
2632.09	3.63481
2634.81	3.30809
2637.53	2.40371
2640.24	1.96154
2642.96	3.06836
2645.67	3.5683
2648.38	3.76767
2651.09	3.41974
2653.8	3.67
2656.51	3.74489
2659.22	3.93767
2661.93	4.2847
2664.63	5.04585
2667.34	5.09054
2670.04	6.18297
2672.75	7.02754
2675.45	7.76457
2678.15	8.54933
2680.85	9.20968
2683.55	10.1451
2686.25	12.193
2688.94	13.3134
2691.64	12.5044
2694.34	12.4239
2697.03	13.5581
2699.73	13.8265
2702.42	13.9993
2705.11	14.0666
2707.8	14.6436
2710.49	14.5803
2713.18	14.3983
2715.87	14.1772
2718.55	14.0987
2721.24	13.7796
2723.93	14.1548
2726.61	13.5333
2729.29	12.8241
2731.98	12.3694
2734.66	12.3182
2737.34	11.7513
2740.02	11.4463
2742.7	12.1353
2745.37	12.6343
2748.05	11.4674
2750.72	11.2459
2753.4	10.2556
2756.07	10.0218
2758.75	9.26936
2761.42	8.83506
2764.09	8.32538
2766.76	7.46265
2769.43	7.00101
2772.1	6.56218
2774.76	6.11251
2777.43	6.39337
2780.1	6.3454
2782.76	6.25099
2785.42	5.94805
2788.09	4.78836
2790.75	4.13652
2793.41	3.23459
2796.07	2.84181
2798.73	3.11196
2801.39	2.16067
2804.04	2.38783
2806.7	2.72507
2809.35	1.937
2812.01	0.717244
2814.66	0.876455
2817.31	2.1554
2819.96	4.29466
2822.61	6.56554
2825.26	9.27878
2827.91	13.1885
2830.56	17.4504
2833.21	23.8169
2835.85	29.9823
2838.5	37.0334
2841.14	43.9051
2843.78	51.638
2846.42	60.3032
2849.06	68.8241
2851.71	78.6223
2854.34	89.2256
2856.98	99.6392
2859.62	110.795
2862.26	121.186
2864.89	132.787
2867.53	144.183
2870.16	154.154
2872.79	164.759
2875.42	174.768
2878.05	184.06
2880.68	194.061
2883.31	203.058
2885.94	210.508
2888.57	218.222
2891.19	226.328
2893.82	233.771
2896.44	242.039
2899.07	250.055
2901.69	257.655
2904.31	265.001
2906.93	274.07
2909.55	282.768
2912.17	292.212
2914.79	300.778
2917.41	308.072
2920.02	314.578
2922.64	318.524
2925.25	321.513
2927.86	323.358
2930.48	322.024
2933.09	319.299
2935.7	314.97
2938.31	308.934
2940.92	300.823
2943.53	291.29
2946.13	281.967
2948.74	270.06
2951.34	258.835
2953.95	247.266
2956.55	236.508
2959.15	224.839
2961.75	213.423
2964.35	201.236
2966.95	190.809
2969.55	180.496
2972.15	171.342
2974.75	161.013
2977.34	151.364
2979.94	139.728
2982.53	128.181
2985.13	116.351
2987.72	104.42
2990.31	92.5039
2992.9	80.4231
2995.49	70.5371
2998.08	61.259
3000.67	52.1888
3003.25	44.302
3005.84	36.6346
3008.42	29.7984
3011.01	24.1526
3013.59	18.7634
3016.17	14.6837
3018.76	11.091
3021.34	7.47307
3023.92	4.63526
3026.49	2.21725
3029.07	0.619196
3031.65	0.399755
3034.23	0.000945088
3036.8	0.0468092
3039.38	0.752052
3041.95	1.32987
3044.52	2.20992
3047.09	3.52386
3049.66	5.3502
3052.23	7.47059
3054.8	8.38954
3057.37	10.3054
3059.94	11.6669
3062.5	11.4019
3065.07	11.6637
3067.63	11.7273
3070.2	11.5928
3072.76	11.1657
3075.32	10.545
3077.88	9.70464
3080.44	8.77393
3083	7.16966
3085.56	6.03675
3088.12	5.38577
3090.67	4.21951
3093.23	4.13554
3095.78	3.70897
3098.34	3.62774
3100.89	4.39766
3103.44	5.58242
3105.99	6.98714
3108.54	8.95435
3111.09	10.7045
3113.64	12.3595
3116.19	13.623
3118.74	14.9062
3121.28	16.7092
3123.83	18.2619
3126.37	20.1515
3128.91	22.8262
3131.46	25.7369
3134	27.5228
3136.54	29.4547
3139.08	32.0673
3141.62	34.2688
3144.16	36.4619
3146.69	37.9896
3149.23	40.0785