File: data/Raman/poly_smoothed/Thy_30_10_21_1x_45s_532 nm_x100_100%_600 gr_mm_01.txt
#Acq. time (s)=	45
#Accumulations=	2
#Range (cm-¹)=	200...3150
#Windows=	2
#Auto scanning=	Off
#Autofocus=	Off
#Macrospot=	Off
#AutoExposure=	Off
#Spike filter=	Multiple accum.
#Delay time (s)=	0
#Binning=	1
#Readout mode=	Signal
#DeNoise=	Off
#ICS correction=	On
#Dark correction=	Off
#Inst. Process=	Off
#Detector Gain=	Best Dynamic Range
#Detector ADC=	20 kHz
#Detector temperature (°C)=	-69.85
#Instrument=	LabRAM HR Evol
#Detector=	Synapse
#Objective=	x100
#Grating=	600 gr/mm
#ND Filter=	100%
#Laser (nm)=	532
#Hole=	100.021
#Range=	Auto
#Laser Pol.=	No
#Raman. Pol.=	No
#Laser Pol. (°)=	-0.0007625
#Raman Pol. (°)=	89.9995
#Collection=	Microscope
#StageXY=	Marzhauser
#StageZ=	Marzhauser
#X (µm)=	4770
#Y (µm)=	-7730.5
#Z (µm)=	584.55
#Full time(mm:ss)=	3:18
#Project=
#Sample=
#Site=
#Title=	Thy_30_10_21_2x_45s_532 nm_x100_100%_600 gr_mm
#Remark=
#Date=	30.06.2022 12:58
#Acquired=	30.06.2022 12:58:36
#Base:Fit=	10.08.2022 09:58:11
#Base:Sub=	10.08.2022 09:58:44
#Filter:Polynom=	16.08.2022 10:22:53
#AxisType[0]=Intens
#AxisUnit[0]=Cnt
#AxisType[1]=Spectr
#AxisUnit[1]=1/cm
200.533	-4.61157
204.162	3.03038
207.792	8.67036
211.418	12.2939
215.044	14.5942
218.667	17.0647
222.289	19.3955
225.912	18.8795
229.531	17.0296
233.148	16.7547
236.766	15.475
240.381	14.4409
243.994	13.7471
247.606	13.3253
251.217	10.6465
254.828	9.57464
258.436	8.32005
262.042	9.88327
265.647	9.1732
269.25	9.25488
272.852	9.88619
276.453	10.9193
280.052	10.075
283.65	10.8971
287.247	11.3023
290.842	11.2731
294.436	10.2204
298.028	11.9725
301.617	12.2921
305.206	12.8901
308.794	14.0651
312.381	13.1196
315.964	12.0119
319.548	12.2401
323.131	12.6136
326.71	11.6303
330.29	11.9922
333.868	12.239
337.443	11.3624
341.018	11.9747
344.591	12.2449
348.163	13.022
351.733	14.1037
355.303	15.2778
358.869	13.7439
362.435	13.1946
366.001	11.8721
369.563	11.5235
373.124	12.9268
376.686	13.697
380.244	12.666
383.801	12.6456
387.357	13.3176
390.911	12.4052
394.466	13.3092
398.018	13.5493
401.568	12.2326
405.117	11.31
408.664	10.0978
412.21	9.64817
415.755	9.17051
419.298	7.12264
422.84	5.6615
426.38	4.11482
429.919	2.28103
433.455	2.16844
436.992	2.28423
440.527	1.86474
444.06	1.39297
447.593	1.13282
451.122	2.30164
454.651	2.88075
458.18	4.6792
461.705	6.54879
465.23	6.01274
468.752	7.61635
472.275	10.1666
475.797	10.8483
479.315	13.0827
482.834	15.0214
486.349	17.3682
489.863	17.4355
493.378	19.1438
496.889	20.2323
500.401	21.166
503.91	21.2354
507.417	21.6558
510.923	22.4527
514.43	23.1029
517.933	24.9661
521.435	24.0399
524.936	23.8625
528.435	23.4523
531.933	22.2653
535.43	20.2046
538.927	18.4591
542.421	16.2847
545.913	15.0983
549.403	13.2133
552.893	13.0366
556.381	11.9199
559.868	10.3262
563.354	9.4556
566.839	7.35688
570.322	6.88347
573.802	5.23723
577.283	5.28466
580.762	3.74483
584.24	2.78031
587.714	2.67974
591.19	1.82663
594.663	2.58045
598.134	3.31928
601.605	3.97115
605.073	3.48302
608.542	5.46562
612.007	4.65819
615.473	4.36777
618.936	3.40195
622.397	3.32791
625.859	3.55161
629.318	3.88906
632.775	5.05524
636.233	4.87381
639.688	5.35475
643.142	5.74703
646.594	7.34903
650.045	7.10284
653.496	8.466
656.944	8.3944
660.391	8.55806
663.837	9.47083
667.281	10.6164
670.724	12.8016
674.166	13.6195
677.606	14.0164
681.045	16.9435
684.483	18.8015
687.917	21.4854
691.352	25.0243
694.786	27.1338
698.219	29.0708
701.65	31.2504
705.078	32.5473
708.506	34.4995
711.934	36.6832
715.358	40.1024
718.782	42.5702
722.204	43.7589
725.626	45.5568
729.045	48.2154
732.464	49.7499
735.881	49.8151
739.297	49.9742
742.711	50.4718
746.125	52.3198
749.537	54.4187
752.946	55.6438
756.357	55.879
759.764	54.4574
763.17	55.8043
766.575	57.7611
769.978	60.0006
773.382	63.8385
776.783	64.1431
780.182	65.2822
783.581	65.5681
786.978	66.9841
790.373	68.6154
793.768	69.5864
797.161	72.7418
800.552	75.0982
803.941	76.5752
807.33	77.7356
810.718	80.0038
814.105	81.0846
817.49	81.5229
820.873	80.8803
824.256	82.3082
827.637	83.5603
831.016	83.6975
834.395	83.2847
837.772	81.2228
841.147	79.2167
844.522	77.7709
847.894	76.7454
851.267	75.1001
854.637	71.0647
858.007	68.1632
861.374	64.8446
864.739	61.8256
868.106	60.8427
871.469	57.4085
874.831	56.3052
878.193	55.692
881.553	56.0188
884.911	54.9927
888.268	54.7343
891.623	54.8685
894.978	53.5899
898.331	52.9584
901.683	53.6464
905.033	55.6901
908.383	55.4536
911.731	55.2113
915.078	54.8452
918.423	54.7099
921.768	52.5771
925.111	52.7137
928.452	52.3903
931.791	49.9809
935.13	48.571
938.468	47.5088
941.803	45.4141
945.139	44.0434
948.473	43.2904
951.804	44.0077
955.136	45.5368
958.465	47.4074
961.794	48.3571
965.12	49.4425
968.447	50.8646
971.771	51.6886
975.095	53.8031
978.417	55.5313
981.737	58.1722
985.057	57.8589
988.375	57.6623
991.691	57.3045
995.006	56.8131
998.32	56.0048
1001.63	54.5936
1004.95	52.319
1008.26	52.1508
1011.56	50.148
1014.87	48.5352
1018.18	46.6158
1021.48	44.0591
1024.79	43.0203
1028.09	42.2226
1031.39	43.1913
1034.69	43.6852
1037.99	41.1765
1041.29	41.3057
1044.58	42.0345
1047.88	42.0249
1051.17	40.9365
1054.46	39.8542
1057.75	39.8925
1061.04	39.6968
1064.33	37.54
1067.62	36.699
1070.9	35.8436
1074.19	35.0593
1077.47	34.0208
1080.76	32.8626
1084.04	31.8581
1087.32	31.6328
1090.59	32.2341
1093.87	31.528
1097.15	29.0161
1100.42	28.4556
1103.69	27.9067
1106.97	27.7277
1110.24	27.0205
1113.51	27.8277
1116.77	27.1658
1120.04	26.767
1123.31	26.3306
1126.57	25.6852
1129.83	24.3809
1133.1	23.2116
1136.36	21.9693
1139.62	22.246
1142.87	20.6004
1146.13	19.176
1149.38	17.6005
1152.64	15.3515
1155.89	12.4202
1159.14	12.7469
1162.39	9.99948
1165.64	8.7232
1168.89	7.41026
1172.14	6.95806
1175.38	7.46117
1178.63	6.82002
1181.87	6.48898
1185.11	8.57413
1188.35	10.2451
1191.59	12.9831
1194.83	14.6775
1198.07	15.7296
1201.3	18.2801
1204.53	20.7463
1207.77	22.8805
1211	25.174
1214.23	27.7551
1217.46	32.0662
1220.69	35.1976
1223.91	38.6685
1227.14	42.7642
1230.36	45.4538
1233.59	47.3877
1236.81	50.7724
1240.03	54.1725
1243.25	56.9021
1246.46	60.5336
1249.68	63.3254
1252.9	66.6912
1256.11	68.4448
1259.32	69.7586
1262.54	70.7119
1265.75	70.6315
1268.96	71.3577
1272.16	73.2277
1275.37	72.459
1278.57	72.3914
1281.78	72.6295
1284.98	72.8805
1288.18	73.2867
1291.38	74.1353
1294.58	74.313
1297.78	75.82
1300.98	76.1542
1304.17	77.958
1307.37	76.4326
1310.56	76.0643
1313.76	78.1556
1316.95	79.292
1320.14	78.6816
1323.32	77.7815
1326.51	77.7032
1329.7	77.3446
1332.88	76.1621
1336.07	72.7692
1339.25	69.9727
1342.43	66.5256
1345.61	62.8822
1348.79	61.174
1351.96	58.9709
1355.14	55.5835
1358.31	53.4239
1361.49	50.4034
1364.66	47.8009
1367.83	44.7259
1371	41.9339
1374.17	40.4288
1377.34	38.5317
1380.5	37.4817
1383.67	36.6545
1386.83	36.2985
1390	35.2052
1393.16	33.8107
1396.32	32.0396
1399.48	31.2851
1402.64	31.5307
1405.79	32.2746
1408.95	32.9001
1412.1	32.2334
1415.26	33.4194
1418.41	37.5623
1421.56	40.5349
1424.71	44.7416
1427.86	50.5836
1431	57.1289
1434.15	61.9989
1437.29	67.3256
1440.44	70.4416
1443.58	73.2907
1446.72	75.1019
1449.86	75.8783
1453	75.191
1456.14	73.7265
1459.27	70.4667
1462.41	68.0869
1465.54	62.4676
1468.67	56.7206
1471.81	50.9016
1474.94	44.9732
1478.07	37.6319
1481.19	31.4375
1484.32	25.9132
1487.45	20.7168
1490.57	16.2099
1493.69	12.9176
1496.82	10.5804
1499.94	9.50402
1503.06	8.8273
1506.17	8.97715
1509.29	10.1114
1512.41	7.79565
1515.52	8.80849
1518.64	9.41808
1521.75	11.3935
1524.86	13.6639
1527.97	15.2448
1531.08	18.0811
1534.19	19.5165
1537.29	23.0178
1540.4	25.8041
1543.5	28.672
1546.61	30.9315
1549.71	32.082
1552.81	34.3226
1555.91	37.8804
1559.01	40.6775
1562.11	42.5498
1565.2	45.21
1568.29	46.8265
1571.39	50.0731
1574.48	52.2996
1577.57	54.5017
1580.66	55.5001
1583.75	57.9324
1586.84	58.7947
1589.93	60.2368
1593.01	63.469
1596.1	65.0268
1599.18	64.6676
1602.26	65.0178
1605.34	65.1312
1608.42	63.629
1611.5	63.496
1614.58	63.0152
1617.65	62.6571
1620.73	60.7644
1623.8	60.3847
1626.87	61.811
1629.95	65.1327
1633.02	67.8036
1636.09	71.1274
1639.15	73.9525
1642.22	77.9037
1645.29	80.989
1648.35	83.984
1651.42	86.2725
1654.48	87.9148
1657.54	88.4443
1660.6	89.1658
1663.66	88.7849
1666.72	88.0307
1669.77	85.964
1672.83	82.2091
1675.88	77.9644
1678.93	73.8742
1681.99	67.5793
1685.04	62.0003
1688.09	55.8503
1691.13	51.4849
1694.18	44.4214
1697.23	38.7176
1700.27	34.7415
1703.32	30.8241
1706.36	28.0666
1709.4	24.4566
1712.44	20.9916
1715.48	17.8131
1718.52	15.7287
1721.56	14.1493
1724.59	12.2674
1727.63	10.7036
1730.66	9.19956
1733.69	8.77311
1736.72	8.83866
1739.75	8.71495
1742.78	8.82173
1745.81	7.30479
1748.84	6.84454
1751.86	4.99915
1754.89	4.00034
1757.91	3.70953
1760.93	3.59829
1763.95	1.66489
1766.97	0.496796
1769.99	0.0473526
1773.01	0.296698
1776.03	0.428697
1779.04	0.112507
1782.06	-0.10278
1785.07	0.0274354
1788.08	0.431146
1791.09	0.146684
1794.1	1.30174
1797.11	1.4773
1800.12	1.88034
1803.12	2.41638
1806.13	2.59009
1809.13	4.0168
1812.14	4.28088
1815.14	4.34561
1818.14	3.99519
1821.14	2.95127
1824.14	2.41614
1827.13	2.14669
1830.13	2.73148
1833.12	2.48643
1836.12	1.97559
1839.11	1.73203
1842.1	3.06885
1845.09	4.43428
1848.08	5.10951
1851.07	5.47087
1854.06	4.5382
1857.04	5.59783
1860.03	6.12388
1863.01	6.45564
1866	6.67709
1868.98	7.48815
1871.96	7.97744
1874.94	9.27407
1877.92	9.81983
1880.89	11.3016
1882.48	11.7527
1885.47	12.3859
1888.46	12.4554
1891.44	12.7756
1894.43	11.97
1897.41	12.0873
1900.4	11.5559
1903.38	11.5305
1906.36	11.6496
1909.34	12.4288
1912.32	11.2055
1915.29	11.1475
1918.27	11.6359
1921.25	10.4304
1924.22	10.4866
1927.2	10.2815
1930.17	10.5222
1933.14	9.69012
1936.11	9.55404
1939.08	9.27647
1942.05	10.1234
1945.01	10.9738
1947.98	12.6066
1950.94	12.8835
1953.91	13.7571
1956.87	13.226
1959.83	13.7785
1962.79	13.6953
1965.75	13.5609
1968.71	13.1907
1971.67	14.1267
1974.62	15.0326
1977.58	15.6028
1980.53	15.6693
1983.48	15.7292
1986.43	15.3094
1989.38	16.7071
1992.33	16.9455
1995.28	17.5078
1998.23	17.9533
2001.18	18.4275
2004.12	18.5693
2007.06	18.9254
2010.01	18.3341
2012.95	19.008
2015.89	19.4076
2018.83	20.0555
2021.77	20.0164
2024.71	19.5802
2027.64	20.3109
2030.58	20.4991
2033.51	20.3912
2036.45	20.7778
2039.38	20.4557
2042.31	20.7675
2045.24	20.8779
2048.17	22.0647
2051.1	21.8966
2054.02	21.6303
2056.95	21.983
2059.87	22.6604
2062.8	22.64
2065.72	24.3322
2068.64	24.5467
2071.56	24.0277
2074.48	24.64
2077.4	24.9197
2080.31	25.3143
2083.23	25.9714
2086.14	27.15
2089.06	27.9054
2091.97	29.1918
2094.88	29.7689
2097.79	31.3267
2100.7	32.9103
2103.61	33.7509
2106.52	35.9708
2109.43	37.6566
2112.33	39.4105
2115.24	41.2758
2118.14	44.1109
2121.04	47.3448
2123.94	50.4479
2126.84	54.0693
2129.74	56.1127
2132.64	58.7499
2135.54	61.959
2138.43	64.2433
2141.33	66.0056
2144.22	69.6937
2147.11	73.2329
2150.01	75.2009
2152.9	78.6456
2155.79	81.0917
2158.67	83.7757
2161.56	86.3706
2164.45	88.257
2167.33	89.849
2170.22	90.8081
2173.1	91.3429
2175.98	91.0636
2178.86	91.2537
2181.74	90.363
2184.62	89.2838
2187.5	88.7747
2190.38	87.161
2193.25	84.7621
2196.13	80.8395
2199	77.0421
2201.88	73.2491
2204.75	69.6354
2207.62	64.8843
2210.49	61.3473
2213.36	58.4246
2216.22	53.3841
2219.09	49.4779
2221.96	46.9789
2224.82	44.9307
2227.68	42.4814
2230.55	40.0936
2233.41	37.4783
2236.27	36.2607
2239.12	34.3673
2241.98	32.8541
2244.84	32.414
2247.7	31.5167
2250.55	31.7038
2253.41	31.394
2256.26	30.6615
2259.11	30.4236
2261.96	29.6352
2264.81	28.8386
2267.66	27.8577
2270.51	27.9386
2273.35	27.1802
2276.2	25.6203
2279.04	25.1833
2281.89	24.8017
2284.73	23.3946
2287.57	22.0329
2290.41	21.1864
2293.25	19.423
2296.09	17.8659
2298.93	17.8906
2301.76	16.9617
2304.6	18.3053
2307.44	18.813
2310.27	19.3503
2313.1	20.0764
2315.93	18.7071
2318.76	18.2849
2321.59	17.4785
2324.42	16.4179
2327.25	16.4101
2330.07	15.6686
2332.9	14.8955
2335.72	14.8684
2338.55	14.05
2341.37	13.7162
2344.19	12.7744
2347.01	12.6185
2349.83	12.3485
2352.65	11.5741
2355.46	10.8775
2358.28	9.91707
2361.09	8.88167
2363.91	8.47675
2366.72	8.81566
2369.53	10.0339
2372.34	10.4858
2375.15	10.8933
2377.96	10.4878
2380.77	10.6355
2383.58	9.51721
2386.38	8.91687
2389.19	8.54726
2391.99	8.1613
2394.8	8.44994
2397.6	7.85015
2400.4	7.79873
2403.2	8.49062
2406	8.07404
2408.79	8.22956
2411.59	8.33709
2414.39	9.06775
2417.18	9.37208
2419.98	9.15073
2422.77	8.44323
2425.56	8.41418
2428.35	7.62153
2431.14	7.05517
2433.93	6.57309
2436.72	6.52532
2439.5	6.70928
2442.29	6.12334
2445.07	5.45116
2447.86	5.15175
2450.64	4.1961
2453.42	3.85136
2456.2	3.43767
2458.98	3.34166
2461.76	3.12036
2464.54	2.88711
2467.32	2.56241
2470.09	3.0589
2472.87	3.39171
2475.64	2.89362
2478.41	2.35671
2481.18	2.92892
2483.95	3.50018
2486.72	2.88773
2489.49	2.08338
2492.26	3.33064
2495.03	2.87082
2497.79	3.02656
2500.56	4.07681
2503.32	3.53308
2506.09	3.59639
2508.85	2.93954
2511.61	3.11735
2514.37	2.69305
2517.13	2.57309
2519.89	2.39746
2522.64	1.66362
2525.4	1.72523
2528.15	0.534141
2530.91	-0.316268
2533.66	-1.02202
2536.41	-0.859036
2539.16	-1.11937
2541.91	-0.964679
2544.66	-0.733016
2547.41	-0.997275
2550.16	0.354726
2552.9	0.506443
2555.65	0.845966
2558.39	1.56416
2561.13	2.4261
2563.88	3.83745
2566.62	4.74632
2569.36	5.44791
2572.1	5.57197
2574.84	6.43739
2577.57	6.54063
2580.31	6.26714
2583.05	6.43293
2585.78	5.54997
2588.51	5.24002
2591.24	4.17612
2593.98	3.75133
2596.71	2.48655
2599.44	2.74946
2602.16	2.86299
2604.89	2.44474
2607.62	1.30815
2610.34	0.481701
2613.07	-0.386698
2615.79	-1.07562
2618.52	-0.936144
2621.24	-1.66711
2623.96	-1.97278
2626.68	-1.0783
2629.4	-0.839133
2632.11	-1.26341
2634.83	-1.3104
2637.55	-1.10095
2640.26	-1.23108
2642.98	-0.606086
2645.69	-0.240544
2648.4	0.446863
2651.11	0.960456
2653.82	1.40095
2656.53	1.13647
2659.24	1.27266
2661.95	1.87027
2664.65	2.97925
2667.36	3.33217
2670.06	3.09915
2672.76	2.54992
2675.47	2.21878
2678.17	2.44023
2680.87	2.56864
2683.57	3.02909
2686.27	2.343
2688.97	2.19689
2691.66	2.20941
2694.36	2.38644
2697.05	1.8147
2699.75	2.02062
2702.44	2.75116
2705.13	2.94419
2707.82	4.0395
2710.51	4.64593
2713.2	5.02566
2715.89	4.94425
2718.57	4.94201
2721.26	5.19445
2723.95	4.63552
2726.63	4.75702
2729.31	5.65951
2732	5.85508
2734.68	5.93011
2737.36	5.94567
2740.04	6.20654
2742.72	5.60805
2745.39	5.41918
2748.07	4.61775
2750.75	3.62705
2753.42	3.60535
2756.09	3.75466
2758.77	4.29325
2761.44	3.88135
2764.11	3.88293
2766.78	3.45731
2769.45	3.27035
2772.12	2.87704
2774.78	1.60971
2777.45	2.33076
2780.12	0.932775
2782.78	0.896086
2785.44	0.7303
2788.11	0.970807
2790.77	1.19697
2793.43	2.15641
2796.09	2.92175
2798.75	3.43615
2801.4	3.75
2804.06	3.74528
2806.72	3.45078
2809.37	3.90762
2812.03	3.77748
2814.68	4.50662
2817.33	5.95362
2819.98	8.1601
2822.63	11.1722
2825.28	13.2479
2827.93	16.1431
2830.58	20.0161
2833.23	23.8855
2835.87	27.2477
2838.52	31.5993
2841.16	37.3618
2843.8	43.1099
2846.44	49.9257
2849.08	58.8262
2851.73	69.4851
2854.36	78.6864
2857	88.3978
2859.64	98.0407
2862.28	106.652
2864.91	114.156
2867.55	122.095
2870.18	129.026
2872.81	135.398
2875.44	140.512
2878.07	144.454
2880.7	148.982
2883.33	153.861
2885.96	158.27
2888.59	161.645
2891.21	165.77
2893.84	170.31
2896.46	175.278
2899.09	181.791
2901.71	188.861
2904.33	197.46
2906.95	207.163
2909.57	220.216
2912.19	234.163
2914.81	248.221
2917.43	261.297
2920.04	272.659
2922.66	283.354
2925.27	292.13
2927.88	297.55
2930.5	300.071
2933.11	301.931
2935.72	301.114
2938.33	297.535
2940.94	291.898
2943.54	285.767
2946.15	277.405
2948.76	266.958
2951.36	257.137
2953.97	244.753
2956.57	232.495
2959.17	220.698
2961.77	210.517
2964.37	199.227
2966.97	189.493
2969.57	179.198
2972.17	170.511
2974.77	162.285
2977.36	152.469
2979.96	143.573
2982.55	133.975
2985.15	124.547
2987.74	115.012
2990.33	104.36
2992.92	94.5163
2995.51	86.4064
2998.1	79.0122
3000.69	71.2341
3003.27	64.155
3005.86	58.0356
3008.44	52.2405
3011.03	46.6037
3013.61	42.8211
3016.19	38.3186
3018.78	34.6098
3021.36	32.8152
3023.94	32.2904
3026.51	31.0446
3029.09	30.0155
3031.67	28.955
3034.24	28.7554
3036.82	29.5834
3039.39	30.1278
3041.97	31.4571
3044.54	32.5164
3047.11	33.2778
3049.68	34.4761
3052.25	34.8959
3054.82	34.6519
3057.39	34.4718
3059.96	34.2656
3062.52	34.0345
3065.09	33.0881
3067.65	32.1048
3070.22	30.4791
3072.78	28.1445
3075.34	25.7607
3077.9	23.9316
3080.46	20.7619
3083.02	18.0783
3085.58	15.6684
3088.14	13.4044
3090.69	11.7071
3093.25	10.0922
3095.8	9.49091
3098.36	8.99804
3100.91	8.38049
3103.46	8.91241
3106.01	8.35281
3108.56	7.76865
3111.11	7.6882
3113.66	6.18523
3116.21	5.45815
3118.76	5.57501
3121.3	5.67698
3123.85	5.51807
3126.39	5.99721
3128.93	5.30339
3131.48	4.85149
3134.02	4.53752
3136.56	3.64254
3139.1	3.42148
3141.64	3.11644
3144.17	3.52344
3146.71	4.48515
3149.25	7.02646