File: data/Raman/poly_smoothed/Thy_40_11_19_1x_45s_532 nm_x100_100%_600 gr_mm_01.txt
#Acq. time (s)=	45
#Accumulations=	2
#Range (cm-¹)=	200...3150
#Windows=	2
#Auto scanning=	Off
#Autofocus=	Off
#Macrospot=	Off
#AutoExposure=	Off
#Spike filter=	Multiple accum.
#Delay time (s)=	0
#Binning=	1
#Readout mode=	Signal
#DeNoise=	Off
#ICS correction=	On
#Dark correction=	Off
#Inst. Process=	Off
#Detector Gain=	Best Dynamic Range
#Detector ADC=	20 kHz
#Detector temperature (°C)=	-69.85
#Instrument=	LabRAM HR Evol
#Detector=	Synapse
#Objective=	x100
#Grating=	600 gr/mm
#ND Filter=	100%
#Laser (nm)=	532
#Hole=	100.021
#Range=	Auto
#Laser Pol.=	No
#Raman. Pol.=	No
#Laser Pol. (°)=	-0.0007625
#Raman Pol. (°)=	89.9995
#Collection=	Microscope
#StageXY=	Marzhauser
#StageZ=	Marzhauser
#X (µm)=	1982.1
#Y (µm)=	-44
#Z (µm)=	425.1
#Full time(mm:ss)=	3:18
#Project=
#Sample=
#Site=
#Title=	Thy_40_11_19_2x_45s_532 nm_x100_100%_600 gr_mm
#Remark=
#Date=	05.07.2022 11:13
#Acquired=	05.07.2022 11:13:36
#Base:Fit=	10.08.2022 10:01:35
#Base:Sub=	10.08.2022 10:01:52
#Filter:Polynom=	16.08.2022 10:21:53
#AxisType[0]=Intens
#AxisUnit[0]=Cnt
#AxisType[1]=Spectr
#AxisUnit[1]=1/cm
200.43	2.90758
204.059	6.57325
207.688	6.66601
211.314	7.73058
214.941	8.70157
218.564	8.29342
222.186	7.56104
225.809	9.18279
229.428	10.9011
233.045	10.4309
236.663	9.74197
240.278	10.5886
243.891	10.3468
247.503	9.50266
251.116	9.14407
254.725	7.7078
258.333	5.9021
261.939	6.23827
265.544	6.69275
269.148	6.17193
272.75	4.44902
276.351	2.62294
279.95	1.35186
283.548	2.94735
287.144	3.66744
290.739	4.00067
294.333	4.66248
297.925	6.12878
301.514	6.00565
305.104	6.73238
308.692	7.93973
312.279	10.357
315.862	9.74609
319.446	10.7271
323.029	10.0035
326.608	10.8533
330.188	11.3259
333.766	11.1954
337.341	10.2422
340.917	9.0557
344.489	8.79957
348.062	7.80864
351.631	8.41039
355.201	7.13635
358.768	5.36852
362.333	6.20443
365.899	5.0768
369.462	7.08436
373.023	6.45864
376.585	5.33368
380.143	6.82559
383.7	7.23917
387.256	6.43764
390.812	6.30145
394.365	7.33393
397.916	7.59164
401.467	7.10563
405.015	8.72217
408.563	8.62375
412.109	9.31526
415.654	11.4241
419.197	9.78861
422.739	8.84475
426.279	7.59649
429.819	7.56488
433.356	6.59604
436.891	8.10488
440.426	7.25823
443.96	7.37806
447.492	8.82296
451.021	8.7844
454.551	8.49368
458.079	8.51157
461.604	9.14217
465.13	11.1353
468.654	11.4514
472.175	11.7603
475.696	12.0619
479.215	13.5736
482.733	15.0842
486.249	15.8466
489.765	17.1115
493.278	17.6198
496.789	19.1668
500.301	20.8328
503.81	19.5892
507.317	19.046
510.825	21.0926
514.33	21.4597
517.833	20.9803
521.335	22.5563
524.836	21.3402
528.335	21.4095
531.835	20.8948
535.332	20.6247
538.827	19.7084
542.321	18.5491
545.814	17.7134
549.305	17.9691
552.795	16.6992
556.282	15.5494
559.769	13.7048
563.255	13.121
566.739	11.5507
570.223	10.5343
573.705	9.36536
577.183	8.2569
580.663	7.02201
584.141	5.80476
587.615	3.95704
591.09	2.54407
594.564	1.88067
598.035	1.67672
601.506	2.64941
604.974	4.99369
608.443	5.89056
611.908	6.77005
615.374	7.6713
618.837	9.3809
622.3	11.2441
625.761	12.5224
629.219	13.0857
632.677	14.8052
636.135	16.0436
639.59	17.4048
643.043	17.7036
646.495	18.2
649.948	17.7956
653.398	18.2789
656.846	19.7556
660.293	20.9204
663.738	18.344
667.183	18.469
670.626	19.9233
674.067	20.0693
677.508	22.753
680.947	25.0429
684.385	27.8712
687.821	30.6391
691.254	33.3208
694.688	34.9323
698.121	35.9977
701.552	38.3407
704.98	41.1474
708.409	42.0916
711.836	44.9466
715.26	47.0939
718.685	50.2428
722.108	51.628
725.528	52.3775
728.949	52.7572
732.367	55.4688
735.785	56.9687
739.2	58.3141
742.614	60.8209
746.028	60.7594
749.439	62.3576
752.849	65.0444
756.26	66.5766
759.667	67.7042
763.073	68.3637
766.477	68.1975
769.883	67.7638
773.285	68.8745
776.686	69.1393
780.085	70.5799
783.484	71.9256
786.881	74.111
790.276	76.2099
793.671	77.8503
797.064	79.8913
800.456	79.9865
803.846	80.1914
807.234	78.4227
810.622	78.5026
814.008	79.609
817.394	79.568
820.778	80.1469
824.159	81.4607
827.541	82.5784
830.921	81.3994
834.298	79.2294
837.676	78.4311
841.051	75.9025
844.426	73.2094
847.798	69.2819
851.171	66.4039
854.54	65.0761
857.911	64.6581
861.278	62.5459
864.645	62.6816
868.01	60.2804
871.373	58.4192
874.735	55.6363
878.097	52.7215
881.457	50.3689
884.815	48.081
888.172	48.1334
891.528	45.8687
894.882	46.108
898.237	45.6104
901.589	44.2738
904.94	44.9145
908.289	46.558
911.635	46.3737
914.982	44.8796
918.328	44.7425
921.672	44.7166
925.015	40.9612
928.357	40.4206
931.698	39.1966
935.035	37.3019
938.373	37.0097
941.71	34.4453
945.044	32.8332
948.378	31.4234
951.709	31.3093
955.041	33.1052
958.372	32.834
961.699	33.1093
965.027	33.0113
968.352	36.5598
971.676	38.4399
975	39.6576
978.322	40.3013
981.642	41.7141
984.962	42.3338
988.28	44.2723
991.596	44.4124
994.911	42.6698
998.227	42.5989
1001.54	42.1553
1004.85	39.6761
1008.16	38.1554
1011.47	36.749
1014.78	34.8423
1018.08	34.9764
1021.39	33.6346
1024.69	32.2208
1028	32.7557
1031.3	33.9997
1034.6	32.8068
1037.9	30.8939
1041.19	32.1144
1044.49	34.0812
1047.78	36.787
1051.08	38.0804
1054.37	38.1046
1057.66	36.4117
1060.95	36.643
1064.24	36.537
1067.53	34.5311
1070.81	33.6234
1074.1	32.2196
1077.38	30.1585
1080.66	28.9072
1083.94	27.1584
1087.22	25.5436
1090.5	25.1865
1093.78	24.54
1097.05	23.2997
1100.33	22.2587
1103.6	20.0983
1106.87	19.1971
1110.14	17.1246
1113.41	13.7165
1116.68	10.1544
1119.95	13.0531
1123.21	13.0296
1126.48	11.4994
1129.74	11.6362
1133	9.94272
1136.26	8.44876
1139.52	8.40362
1142.78	8.56033
1146.04	7.21696
1149.29	7.46417
1152.55	8.62776
1155.8	9.51446
1159.05	7.61087
1162.3	8.23035
1165.55	8.24852
1168.8	8.38322
1172.05	8.26758
1175.29	8.44273
1178.54	8.75752
1181.78	9.12072
1185.02	9.78379
1188.26	9.8098
1191.5	9.37824
1194.74	9.27539
1197.97	10.8326
1201.21	12.6384
1204.44	13.0716
1207.68	14.554
1210.91	15.5174
1214.14	17.4293
1217.37	21.601
1220.59	24.3464
1223.82	27.9907
1227.05	32.5004
1230.27	35.55
1233.49	38.1868
1236.72	39.9897
1239.94	44.3073
1243.16	49.0617
1246.37	54.0903
1249.59	56.733
1252.8	57.7119
1256.02	60.96
1259.23	64.5707
1262.44	67.5408
1265.66	69.4261
1268.86	71.0437
1272.07	73.2159
1275.28	74.5336
1278.48	73.9492
1281.69	73.3578
1284.89	74.5643
1288.09	76.3741
1291.29	77.3583
1294.49	79.7339
1297.69	80.7377
1300.89	83.4242
1304.08	84.7353
1307.28	84.9778
1310.47	87.1128
1313.66	88.1311
1316.85	90.147
1320.04	91.9418
1323.23	91.7885
1326.42	88.6117
1329.61	86.7671
1332.79	84.8368
1335.97	83.8582
1339.16	80.0583
1342.34	76.8166
1345.52	73.2373
1348.7	69.5238
1351.87	64.2607
1355.05	58.5016
1358.22	56.009
1361.4	52.8327
1364.57	51.2965
1367.74	48.0042
1370.91	47.0198
1374.08	46.737
1377.25	46.0753
1380.41	46.2954
1383.58	46.1786
1386.74	46.4636
1389.91	46.9637
1393.07	45.6453
1396.23	45.8228
1399.39	44.8944
1402.55	46.4258
1405.7	47.2529
1408.86	47.9038
1412.01	47.9646
1415.17	50.1132
1418.32	52.778
1421.47	56.2092
1424.62	62.1224
1427.77	67.3867
1430.91	71.9344
1434.06	77.6659
1437.2	81.1709
1440.35	84.0809
1443.49	87.15
1446.63	90.3147
1449.77	91.1344
1452.91	91.0597
1456.05	90.4406
1459.18	88.3005
1462.32	83.2129
1465.45	77.7258
1468.59	72.2581
1471.72	65.7125
1474.85	58.9888
1477.98	53.1189
1481.1	45.2823
1484.23	37.3937
1487.36	30.9932
1490.48	27.2002
1493.61	23.6094
1496.73	22.6441
1499.85	21.4458
1502.97	20.5108
1506.09	19.9184
1509.2	19.4094
1512.32	20.699
1515.43	20.491
1518.55	21.7203
1521.66	24.7417
1524.77	25.8717
1527.88	28.5913
1530.99	29.3588
1534.1	33.0674
1537.21	35.3799
1540.31	38.0421
1543.42	42.1706
1546.52	46.3006
1549.62	49.3
1552.72	53.6024
1555.82	57.1342
1558.92	60.2706
1562.02	64.4914
1565.11	68.796
1568.21	72.9534
1571.3	76.9479
1574.39	79.5158
1577.49	81.8733
1580.57	84.4299
1583.66	86.8832
1586.75	88.6469
1589.84	89.1853
1592.92	89.192
1596.01	89.3377
1599.09	87.4451
1602.17	85.3799
1605.25	83.9612
1608.33	83.1077
1611.41	82.082
1614.49	80.853
1617.57	79.5443
1620.64	81.3668
1623.72	81.573
1626.79	82.8373
1629.86	84.3253
1632.93	85.564
1636	89.5534
1639.07	92.373
1642.13	96.408
1645.2	100.508
1648.26	103.414
1651.33	106.595
1654.39	107.837
1657.45	108.563
1660.51	107.62
1663.57	105.818
1666.63	103.611
1669.68	100.412
1672.74	94.8471
1675.79	89.7631
1678.85	83.3398
1681.9	76.4746
1684.95	68.8176
1688	62.6907
1691.05	55.5354
1694.09	48.6874
1697.14	43.1385
1700.18	37.3933
1703.23	32.0464
1706.27	26.8829
1709.31	23.5735
1712.35	20.9748
1715.39	17.9276
1718.43	17.3498
1721.47	15.9262
1724.5	14.4334
1727.54	13.5267
1730.57	12.2388
1733.61	11.5955
1736.64	11.1007
1739.67	11.3343
1742.7	11.4465
1745.72	11.6316
1748.75	11.4636
1751.77	10.5683
1754.8	9.92924
1757.82	9.82866
1760.84	9.89131
1763.87	9.50123
1766.89	8.43964
1769.91	7.48529
1772.92	6.35093
1775.94	5.87179
1778.95	5.31841
1781.97	4.54386
1784.98	5.18135
1787.99	5.01041
1791.01	4.25821
1794.01	4.50903
1797.02	4.6877
1800.03	4.01278
1803.04	3.1138
1806.04	3.03593
1809.05	2.11736
1812.05	1.47215
1815.05	1.70973
1818.05	1.85561
1821.05	1.36944
1824.05	0.978115
1827.05	0.975241
1830.04	1.20288
1833.04	1.29365
1836.03	1.20405
1839.03	1.185
1842.02	2.04902
1845.01	1.99928
1848	2.99188
1850.99	4.28516
1853.97	4.78004
1856.96	5.03967
1859.94	4.78355
1862.93	4.66818
1865.91	5.75337
1868.89	6.60053
1871.87	6.57841
1874.85	6.51029
1877.83	5.78032
1880.81	6.98618
1882.57	6.82911
1885.56	7.321
1888.55	6.77106
1891.54	6.2827
1894.52	6.6755
1897.51	6.68883
1900.49	5.87135
1903.47	5.45609
1906.45	3.97206
1909.43	3.74356
1912.41	3.17167
1915.39	3.1952
1918.37	3.24304
1921.34	4.31031
1924.32	4.12723
1927.29	2.91188
1930.26	3.49203
1933.23	3.05648
1936.2	3.65206
1939.17	5.08795
1942.14	4.51742
1945.11	4.90849
1948.07	5.08119
1951.04	5.77063
1954	5.2156
1956.96	4.25848
1959.93	3.61586
1962.89	3.30103
1965.85	2.87174
1968.8	3.09368
1971.76	2.36328
1974.72	1.62677
1977.67	1.53577
1980.63	1.37239
1983.58	2.25497
1986.53	2.76557
1989.48	4.08614
1992.43	5.17565
1995.38	6.02781
1998.32	6.59938
2001.27	7.00481
2004.22	8.34045
2007.16	8.39584
2010.1	9.59536
2013.04	10.5226
2015.98	10.5806
2018.92	11.2589
2021.86	11.4581
2024.8	11.8731
2027.74	12.1393
2030.67	11.605
2033.61	10.4959
2036.54	10.7911
2039.47	10.6756
2042.4	11.0157
2045.33	11.5142
2048.26	11.8885
2051.19	12.3734
2054.12	13.176
2057.04	13.9391
2059.97	15.3397
2062.89	16.4366
2065.81	16.852
2068.73	17.547
2071.65	18.1908
2074.57	18.8386
2077.49	19.876
2080.41	21.6932
2083.32	22.8058
2086.24	24.1894
2089.15	26.7459
2092.07	28.1266
2094.98	29.7119
2097.89	31.8416
2100.8	31.43
2103.71	33.3317
2106.61	37.1005
2109.52	39.2058
2112.43	41.1202
2115.33	44.7878
2118.23	47.6225
2121.13	50.7725
2124.04	53.7035
2126.94	57.5227
2129.83	61.664
2132.73	65.526
2135.63	69.6212
2138.53	73.7293
2141.42	78.2634
2144.31	83.3395
2147.21	87.1451
2150.1	92.6682
2152.99	96.8521
2155.88	101.602
2158.77	105.5
2161.65	107.446
2164.54	109.236
2167.43	110.693
2170.31	112.655
2173.19	112.774
2176.07	112.241
2178.96	110.909
2181.84	109.379
2184.72	107.945
2187.59	104.924
2190.47	101.055
2193.35	97.2217
2196.22	93.4628
2199.09	90.4789
2201.97	86.3115
2204.84	82.2348
2207.71	77.9424
2210.58	74.6685
2213.45	71.8661
2216.31	66.5843
2219.18	62.8281
2222.05	58.3408
2224.91	55.068
2227.78	50.5733
2230.64	47.2142
2233.5	44.3
2236.36	42.1107
2239.22	40.054
2242.08	37.6873
2244.93	36.6381
2247.79	34.9444
2250.64	34.2594
2253.5	33.1726
2256.35	30.8899
2259.2	30.3378
2262.05	28.3514
2264.9	27.6624
2267.75	28.0439
2270.6	26.9946
2273.45	25.4116
2276.29	25.1721
2279.14	23.2998
2281.98	21.5354
2284.82	19.1359
2287.66	16.9964
2290.5	14.8537
2293.34	13.391
2296.18	13.7642
2299.02	13.1912
2301.86	13.3374
2304.69	13.6359
2307.53	12.861
2310.36	12.8105
2313.19	12.7394
2316.02	12.0899
2318.85	11.9098
2321.68	11.5359
2324.51	11.3143
2327.34	9.95208
2330.16	8.99928
2332.99	9.33193
2335.81	8.63061
2338.64	7.47318
2341.46	6.72678
2344.28	5.67676
2347.1	4.82633
2349.92	2.41815
2352.74	1.55324
2355.55	0.446324
2358.37	-0.213882
2361.19	-0.617602
2364	-0.409717
2366.81	1.19458
2369.62	1.15005
2372.44	1.18339
2375.24	1.03188
2378.05	1.04462
2380.86	2.39235
2383.67	2.98882
2386.47	4.27575
2389.28	5.43502
2392.08	5.47886
2394.89	5.98323
2397.69	6.55549
2400.49	7.68679
2403.29	8.71505
2406.09	9.44101
2408.88	9.98236
2411.68	10.2953
2414.48	11.3688
2417.27	11.8307
2420.06	11.5488
2422.86	11.8368
2425.65	12.28
2428.44	11.7283
2431.23	11.8414
2434.02	12.5874
2436.81	13.2604
2439.59	12.2982
2442.38	11.4089
2445.16	11.1076
2447.95	10.4921
2450.73	10.6229
2453.51	10.397
2456.29	10.2373
2459.07	9.91536
2461.85	9.62427
2464.63	9.79674
2467.4	9.47281
2470.18	8.26029
2472.95	8.3472
2475.73	7.81801
2478.5	7.41799
2481.27	7.03592
2484.04	6.31281
2486.81	5.87375
2489.58	5.00451
2492.35	4.32533
2495.12	3.17472
2497.88	2.45793
2500.65	2.90559
2503.41	2.59634
2506.17	2.50177
2508.94	2.05234
2511.7	1.5651
2514.46	0.792546
2517.22	1.00763
2519.97	1.40936
2522.73	1.74737
2525.49	2.9354
2528.24	3.19224
2530.99	2.96851
2533.75	3.49577
2536.5	2.77407
2539.25	3.20506
2542	2.20204
2544.75	2.46078
2547.5	2.06142
2550.24	1.33419
2552.99	0.833028
2555.74	0.960126
2558.48	0.702754
2561.22	0.406712
2563.96	0.360435
2566.71	2.2366
2569.45	2.77103
2572.18	3.00282
2574.92	3.68393
2577.66	4.67978
2580.4	4.26225
2583.13	4.19293
2585.87	4.98783
2588.6	4.60506
2591.33	5.80446
2594.06	5.53252
2596.79	4.89676
2599.52	4.52316
2602.25	4.98804
2604.98	4.78556
2607.71	3.92481
2610.43	3.48058
2613.16	3.73324
2615.88	2.99741
2618.6	3.31976
2621.32	2.79469
2624.04	3.11684
2626.76	2.32551
2629.48	2.8645
2632.2	3.59613
2634.92	4.4796
2637.63	4.86919
2640.35	4.83321
2643.06	5.45019
2645.77	4.83069
2648.49	3.61631
2651.2	2.95629
2653.91	2.08714
2656.62	2.10787
2659.33	3.08882
2662.03	3.34324
2664.74	4.48464
2667.44	4.90818
2670.15	5.06298
2672.85	5.24399
2675.55	5.17443
2678.26	6.16233
2680.96	7.29409
2683.66	6.9009
2686.35	7.26833
2689.05	8.14942
2691.75	8.20355
2694.44	8.2999
2697.14	9.39807
2699.83	9.64486
2702.52	10.4067
2705.22	9.54197
2707.91	9.20149
2710.6	8.04649
2713.29	8.36618
2715.97	8.13002
2718.66	8.49751
2721.35	8.78681
2724.03	10.1142
2726.72	10.4558
2729.4	9.29692
2732.08	8.86879
2734.76	8.60553
2737.44	9.28914
2740.12	9.12162
2742.8	9.27999
2745.48	9.90879
2748.16	9.36552
2750.83	9.16613
2753.51	9.81352
2756.18	9.00566
2758.85	7.85929
2761.53	6.82594
2764.2	6.60045
2766.87	6.22598
2769.54	5.02735
2772.2	3.82287
2774.87	3.17456
2777.54	2.87189
2780.2	2.56114
2782.87	2.63806
2785.53	2.00746
2788.19	1.08419
2790.85	1.42092
2793.51	0.738886
2796.17	0.223564
2798.83	0.282109
2801.49	0.306279
2804.15	0.855541
2806.8	0.660822
2809.46	2.36056
2812.11	2.11599
2814.76	2.9714
2817.42	3.34245
2820.07	4.95763
2822.72	6.57279
2825.37	10.2194
2828.02	13.9516
2830.66	18.5206
2833.31	22.7697
2835.96	27.0699
2838.6	32.0845
2841.24	37.645
2843.89	43.9834
2846.53	51.0713
2849.17	58.9541
2851.81	66.5289
2854.45	75.8964
2857.09	85.8594
2859.72	93.5707
2862.36	102.097
2865	110.068
2867.63	116.711
2870.26	123.312
2872.9	129.272
2875.53	134.714
2878.16	139.133
2880.79	144.185
2883.42	148.518
2886.05	153.193
2888.67	158.486
2891.3	163.374
2893.92	168.465
2896.55	173.429
2899.17	179.149
2901.79	185.68
2904.42	194.589
2907.04	204.359
2909.66	215.766
2912.27	228.438
2914.89	241.413
2917.51	254.324
2920.13	265.222
2922.74	274.474
2925.35	281.819
2927.97	286.817
2930.58	291.6
2933.19	292.268
2935.8	291.565
2938.41	289.919
2941.02	284.483
2943.63	276.262
2946.24	268.164
2948.84	258.997
2951.45	249.232
2954.05	238.648
2956.65	227.351
2959.26	216.221
2961.86	204.918
2964.46	194.663
2967.06	184.097
2969.66	174.699
2972.25	164.94
2974.85	156.477
2977.45	147.155
2980.04	138.133
2982.64	128.456
2985.23	118.5
2987.82	109.067
2990.41	100.207
2993	91.2496
2995.59	81.3209
2998.18	72.6513
3000.77	63.9998
3003.36	56.3177
3005.94	47.2859
3008.53	40.209
3011.11	34.4788
3013.69	27.9443
3016.28	23.6517
3018.86	19.9663
3021.44	15.4917
3024.02	12.9471
3026.6	10.9007
3029.18	9.33754
3031.75	8.57653
3034.33	9.19033
3036.9	8.1569
3039.48	8.8345
3042.05	9.34778
3044.62	10.9375
3047.19	11.9305
3049.77	13.9848
3052.34	15.8039
3054.9	15.9088
3057.47	16.2508
3060.04	16.2616
3062.61	16.2645
3065.17	14.751
3067.74	12.8325
3070.3	11.2484
3072.86	9.25879
3075.42	8.13071
3077.99	7.27142
3080.54	5.80232
3083.1	4.17312
3085.66	3.24386
3088.22	2.99693
3090.78	2.36394
3093.33	1.47183
3095.89	0.880639
3098.44	-0.484676
3100.99	-0.270214
3103.54	0.0469393
3106.1	0.0308024
3108.65	0.916891
3111.2	1.2692
3113.74	1.81601
3116.29	2.15147
3118.84	2.1234
3121.38	2.0863
3123.93	2.41581
3126.47	3.41638
3129.01	2.82422
3131.56	3.6876
3134.1	5.15651
3136.64	5.6669
3139.18	6.73602
3141.72	7.70442
3144.26	8.19689
3146.79	8.87029
3149.33	7.05897