File: data/Raman/poly_smoothed/Thy_20_09_25_1x_45s_532 nm_x100_100%_600 gr_mm_01.txt
#Acq. time (s)=	45
#Accumulations=	2
#Range (cm-¹)=	200...3150
#Windows=	2
#Auto scanning=	Off
#Autofocus=	Off
#Macrospot=	Off
#AutoExposure=	Off
#Spike filter=	Multiple accum.
#Delay time (s)=	0
#Binning=	1
#Readout mode=	Signal
#DeNoise=	Off
#ICS correction=	On
#Dark correction=	Off
#Inst. Process=	Off
#Detector Gain=	Best Dynamic Range
#Detector ADC=	20 kHz
#Detector temperature (°C)=	-69.85
#Instrument=	LabRAM HR Evol
#Detector=	Synapse
#Objective=	x100
#Grating=	600 gr/mm
#ND Filter=	100%
#Laser (nm)=	532
#Hole=	100.021
#Range=	Auto
#Laser Pol.=	No
#Raman. Pol.=	No
#Laser Pol. (°)=	-0.0007625
#Raman Pol. (°)=	89.9995
#Collection=	Microscope
#StageXY=	Marzhauser
#StageZ=	Marzhauser
#X (µm)=	-5910.3
#Y (µm)=	2881.4
#Z (µm)=	-223.55
#Full time(mm:ss)=	3:18
#Project=
#Sample=
#Site=
#Title=	Thy_20_09_25_2x_45s_532 nm_x100_100%_600 gr_mm
#Remark=
#Date=	29.06.2022 12:25
#Acquired=	29.06.2022 12:25:16
#Base:Fit=	10.08.2022 09:52:02
#Base:Fit=	10.08.2022 09:52:12
#Base:Sub=	10.08.2022 09:54:21
#Filter:Polynom=	16.08.2022 10:24:04
#AxisType[0]=Intens
#AxisUnit[0]=Cnt
#AxisType[1]=Spectr
#AxisUnit[1]=1/cm
200.523	-5.51805
204.154	-0.990748
207.781	2.28296
211.409	2.50802
215.034	3.17966
218.659	4.40284
222.281	4.61174
225.903	5.52279
229.522	5.59423
233.14	4.72041
236.756	4.96978
240.373	6.48042
243.986	7.22153
247.598	7.16059
251.208	6.48923
254.818	6.00089
258.427	5.65593
262.034	5.27477
265.638	4.47206
269.242	3.82181
272.844	6.2138
276.445	5.8245
280.044	6.96434
283.642	7.32081
287.238	8.04611
290.833	8.0261
294.425	6.83569
298.017	6.59413
301.608	8.63931
305.198	9.42339
308.786	10.6421
312.371	11.8479
315.956	12.9496
319.54	13.2571
323.122	14.9313
326.701	15.4044
330.281	16.3232
333.857	15.962
337.434	15.8785
341.008	14.8411
344.582	13.5164
348.153	12.1921
351.724	13.1282
355.292	11.8109
358.861	12.4828
362.426	12.4072
365.99	11.639
369.555	11.7557
373.116	9.83768
376.676	8.60353
380.236	6.69389
383.793	5.99673
387.349	6.0116
390.903	4.99533
394.456	5.66176
398.007	5.49465
401.56	5.82702
405.108	4.16473
408.656	3.90288
412.202	4.30562
415.746	4.52281
419.29	6.82945
422.831	8.22019
426.37	7.31517
429.909	6.94109
433.447	6.9785
436.983	9.26447
440.519	9.97704
444.052	11.6185
447.583	11.9535
451.114	11.9405
454.643	12.0048
458.169	12.2438
461.696	11.7882
465.222	12.8877
468.744	12.5195
472.267	13.3227
475.787	14.0364
479.307	14.3735
482.823	15.321
486.341	15.3025
489.855	15.8291
493.37	16.4633
496.881	17.809
500.391	21.2178
503.902	23.5628
507.409	23.9344
510.915	22.7856
514.42	21.3892
517.925	21.3971
521.427	21.633
524.928	20.6156
528.427	19.9106
531.925	18.0961
535.422	16.1095
538.917	15.5313
542.411	14.9469
545.903	13.8207
549.395	12.869
552.884	11.7501
556.373	9.90063
559.86	7.51451
563.346	6.57105
566.831	4.5694
570.314	3.69117
573.794	2.13969
577.274	3.49429
580.754	4.52077
584.23	5.91113
587.706	5.90194
591.181	5.03437
594.653	3.62554
598.126	4.11001
601.595	5.39531
605.065	6.6974
608.532	6.59129
611.999	6.93333
615.463	6.74076
618.928	7.09024
622.389	10.586
625.851	10.8688
629.31	10.455
632.767	11.8679
636.223	13.1734
639.68	12.9888
643.134	13.7192
646.586	15.5239
650.037	17.65
653.486	18.9902
656.936	20.7529
660.383	24.1038
663.829	26.0066
667.273	25.6345
670.716	25.2952
674.158	26.4548
677.598	27.2496
681.035	28.041
684.473	29.7324
687.909	29.5186
691.344	30.2759
694.778	30.6341
698.211	31.3304
701.64	33.1394
705.07	35.8334
708.498	37.2156
711.924	37.6114
715.35	39.6257
718.774	41.3267
722.196	43.7985
725.618	46.7464
729.037	49.4135
732.456	52.2413
735.873	54.3412
739.289	56.9834
742.703	59.4359
746.116	61.0182
749.529	61.0945
752.938	61.1625
756.347	63.9854
759.756	66.2741
763.162	68.7739
766.567	69.3658
769.97	70.5181
773.372	71.1716
776.773	74.2601
780.174	75.7684
783.573	78.1802
786.97	80.0374
790.365	79.9643
793.76	79.9282
797.153	81.5245
800.543	81.6783
803.933	81.4573
807.322	81.8243
810.71	82.5234
814.097	83.505
817.483	83.4278
820.865	82.6414
824.248	82.2956
827.629	80.7646
831.008	78.8965
834.387	76.2673
837.765	74.9041
841.139	73.5808
844.514	70.4208
847.886	66.9037
851.259	64.2597
854.629	62.5458
857.997	61.614
861.366	59.569
864.732	57.4059
868.098	55.7957
871.461	53.1609
874.823	52.6073
878.184	50.8523
881.545	51.2181
884.903	50.6079
888.26	51.597
891.616	52.2269
894.97	53.227
898.323	53.2931
901.675	53.0356
905.026	52.0036
908.375	50.4746
911.723	49.1793
915.07	47.7277
918.415	47.5374
921.76	47.6773
925.103	46.7272
928.443	45.8355
931.783	44.4176
935.123	43.0568
938.461	42.5183
941.796	40.7787
945.131	36.4928
948.465	34.6759
951.797	34.1094
955.128	33.2704
958.457	32.6022
961.786	31.2454
965.113	30.5015
968.44	32.0158
971.763	33.6555
975.086	34.2868
978.409	34.2755
981.729	33.5361
985.048	32.1906
988.367	32.6538
991.683	31.2725
994.998	31.6159
998.312	31.5963
1001.62	32.1777
1004.94	32.2911
1008.25	31.4449
1011.56	30.9876
1014.86	29.6605
1018.17	28.0628
1021.48	27.855
1024.78	26.358
1028.08	24.876
1031.38	23.4968
1034.68	23.1063
1037.98	20.1698
1041.28	18.5132
1044.57	18.9955
1047.87	19.4448
1051.16	20.1214
1054.45	20.5778
1057.75	20.0517
1061.04	19.3409
1064.32	16.7742
1067.61	16.4975
1070.9	15.2529
1074.18	14.9225
1077.47	15.3765
1080.75	14.8472
1084.03	13.5561
1087.31	12.9209
1090.59	12.7387
1093.86	12.233
1097.14	12.5583
1100.41	14.8662
1103.69	16.5999
1106.96	16.6773
1110.23	15.4356
1113.5	16.146
1116.77	16.15
1120.03	16.0765
1123.3	15.5415
1126.56	15.9333
1129.83	17.6581
1133.09	18.6122
1136.35	18.2323
1139.61	17.3188
1142.86	16.7011
1146.12	16.0596
1149.38	14.5021
1152.63	12.469
1155.88	10.9871
1159.14	8.83472
1162.39	6.40406
1165.63	3.94374
1168.88	3.30795
1172.13	3.90236
1175.38	1.62705
1178.62	4.75086
1181.86	6.87805
1185.1	7.07151
1188.34	8.53158
1191.58	9.23694
1194.82	10.9922
1198.06	13.5826
1201.29	16.7052
1204.53	20.1648
1207.76	24.0086
1210.99	26.8429
1214.22	30.9437
1217.45	34.1613
1220.68	37.0087
1223.91	40.6405
1227.13	44.9384
1230.36	48.202
1233.58	51.8076
1236.8	55.5255
1240.02	55.4839
1243.24	58.1535
1246.46	60.2999
1249.67	61.5045
1252.89	63.3255
1256.1	63.8541
1259.32	66.651
1262.53	68.0831
1265.74	69.47
1268.95	70.6552
1272.15	71.8087
1275.36	75.0786
1278.57	76.1178
1281.77	77.6228
1284.97	78.412
1288.18	80.6468
1291.38	82.6551
1294.58	84.6496
1297.78	86.6436
1300.97	89.249
1304.17	91.6492
1307.36	92.6768
1310.55	92.4276
1313.75	93.2122
1316.94	92.0983
1320.13	91.7973
1323.32	91.9455
1326.5	89.9424
1329.69	88.8253
1332.87	85.9622
1336.06	85.0983
1339.24	84.2873
1342.42	82.793
1345.6	80.9746
1348.78	79.0229
1351.96	79.0876
1355.13	76.3487
1358.31	73.3348
1361.48	71.7321
1364.65	71.0813
1367.82	69.0012
1370.99	67.1407
1374.16	67.2725
1377.33	67.0109
1380.5	66.3327
1383.66	65.8526
1386.83	64.2003
1389.99	63.6548
1393.15	62.9119
1396.31	61.1676
1399.47	60.5165
1402.63	61.6533
1405.78	61.3756
1408.94	60.9765
1412.1	62.2449
1415.25	64.5048
1418.4	66.5165
1421.55	70.0788
1424.7	73.2062
1427.85	77.9031
1431	80.9454
1434.14	84.868
1437.29	86.4861
1440.43	88.6739
1443.57	89.7757
1446.71	91.5612
1449.85	94.6094
1452.99	94.991
1456.13	94.2201
1459.26	91.0866
1462.4	87.6461
1465.54	83.638
1468.67	78.7786
1471.8	74.2304
1474.93	68.8436
1478.06	64.6668
1481.19	59.2589
1484.31	53.2235
1487.44	48.2752
1490.56	43.4526
1493.69	40.4202
1496.81	37.0576
1499.93	33.6606
1503.05	30.1226
1506.17	28.2261
1509.28	25.2295
1512.4	24.2015
1515.52	24.0352
1518.63	24.1484
1521.74	27.5209
1524.85	30.74
1527.96	33.6338
1531.07	35.3881
1534.18	36.5076
1537.29	36.3901
1540.39	43.4352
1543.5	51.0327
1546.6	57.5911
1549.7	65.0181
1552.8	72.6009
1555.9	77.3602
1559	82.1843
1562.1	87.1105
1565.19	90.9497
1568.29	95.3519
1571.38	97.4129
1574.47	100.286
1577.56	102.287
1580.66	104.641
1583.74	104.302
1586.83	104.024
1589.92	103.206
1593.01	100.619
1596.09	97.3832
1599.17	93.4978
1602.25	91.197
1605.34	87.0738
1608.41	82.414
1611.49	77.6546
1614.57	79.3597
1617.65	81.5243
1620.72	79.2704
1623.79	79.5484
1626.87	81.0876
1629.94	81.2941
1633.01	80.0252
1636.08	79.3621
1639.15	80.5081
1642.21	80.631
1645.28	81.7546
1648.34	82.9443
1651.41	84.5047
1654.47	82.4211
1657.53	81.3139
1660.59	77.9642
1663.65	75.8008
1666.71	72.7207
1669.76	68.3885
1672.82	64.5544
1675.87	61.3835
1678.93	56.2031
1681.98	51.5782
1685.03	48.3745
1688.08	44.359
1691.13	39.2808
1694.17	36.0575
1697.22	32.981
1700.27	30.3074
1703.31	27.8305
1706.35	24.1198
1709.39	21.0028
1712.43	19.9291
1715.47	17.7221
1718.51	16.839
1721.55	15.0248
1724.58	14.8524
1727.62	13.4753
1730.65	11.9914
1733.68	11.9783
1736.72	10.9588
1739.74	10.5114
1742.77	8.50913
1745.8	6.53964
1748.83	6.34385
1751.85	5.1041
1754.88	4.36484
1757.9	4.61484
1760.92	3.45761
1763.95	3.24926
1766.96	3.0673
1769.98	3.69987
1773	2.88593
1776.02	3.26306
1779.03	2.41761
1782.05	2.07262
1785.06	2.84634
1788.07	2.99463
1791.08	3.13838
1794.09	3.0382
1797.1	3.18507
1800.11	2.7792
1803.12	3.55816
1806.12	4.41784
1809.12	4.08253
1812.13	4.66368
1815.13	4.45322
1818.13	4.83093
1821.13	4.81259
1824.13	4.84297
1827.13	4.84616
1830.12	5.00278
1833.12	5.04633
1836.11	4.19913
1839.1	3.80626
1842.09	3.74978
1845.09	4.56384
1848.08	4.29105
1851.06	4.66359
1854.05	4.61239
1857.04	5.34863
1860.02	5.73826
1863.01	6.04783
1865.99	6.76678
1868.97	6.82746
1871.95	6.24308
1874.93	7.20529
1877.91	8.05274
1880.89	8.44462
1882.46	7.91708
1885.45	7.15635
1888.43	7.16187
1891.42	6.16733
1894.41	4.93451
1897.39	4.34364
1900.37	2.76599
1903.36	2.71798
1906.34	2.72887
1909.32	3.04072
1912.29	2.55856
1915.27	3.02552
1918.25	2.91815
1921.23	2.61544
1924.2	3.14384
1927.17	2.87713
1930.15	3.4092
1933.12	2.53539
1936.09	2.69383
1939.06	2.87366
1942.02	2.40813
1944.99	1.8304
1947.96	1.86727
1950.92	1.52078
1953.88	1.19932
1956.85	1.03691
1959.81	0.853235
1962.77	0.186501
1965.73	-1.08816
1968.69	-1.48807
1971.64	-0.486916
1974.6	0.29703
1977.55	1.19965
1980.51	1.32942
1983.46	0.972448
1986.41	1.7421
1989.36	3.03998
1992.31	3.57388
1995.26	4.18452
1998.21	4.52365
2001.15	3.74131
2004.1	3.87025
2007.04	4.19358
2009.99	4.08997
2012.93	4.17431
2015.87	4.16906
2018.81	3.89763
2021.75	4.96276
2024.68	5.70892
2027.62	6.49488
2030.56	6.40557
2033.49	5.89111
2036.42	5.89416
2039.36	6.72995
2042.29	7.58274
2045.22	7.93759
2048.14	8.04714
2051.07	6.97047
2054	7.59513
2056.93	7.09886
2059.85	6.50901
2062.77	7.36739
2065.7	6.87988
2068.62	7.71988
2071.54	7.64412
2074.46	7.84167
2077.38	8.29181
2080.29	8.21679
2083.21	7.49977
2086.12	8.7452
2089.04	9.38342
2091.95	10.1767
2094.86	11.1638
2097.77	12.6268
2100.68	13.7881
2103.59	14.4874
2106.5	15.8594
2109.41	17.7347
2112.31	19.4631
2115.21	20.7182
2118.12	21.6201
2121.02	23.216
2123.92	23.6302
2126.82	24.8665
2129.72	26.6443
2132.62	28.9157
2135.51	30.6732
2138.41	31.5922
2141.31	33.8677
2144.2	36.3466
2147.09	38.0973
2149.98	39.6453
2152.87	40.6915
2155.76	41.9688
2158.65	43.9212
2161.54	45.3099
2164.43	46.5108
2167.31	47.0993
2170.2	47.4777
2173.08	47.387
2175.96	47.942
2178.84	46.6773
2181.72	45.65
2184.6	45.0177
2187.48	43.8204
2190.36	40.7264
2193.23	39.2364
2196.11	37.5204
2198.98	35.6573
2201.85	33.5724
2204.72	30.6573
2207.59	29.3717
2210.46	28.5171
2213.33	28.139
2216.2	26.3808
2219.07	25.3548
2221.93	24.313
2224.8	23.7512
2227.66	23.2375
2230.52	22.4749
2233.39	20.8202
2236.25	20.5496
2239.1	19.7564
2241.96	18.2792
2244.82	16.7689
2247.68	14.6923
2250.53	13.5556
2253.38	13.0181
2256.24	13.1618
2259.09	11.5059
2261.94	11.0658
2264.79	11.8191
2267.64	11.6566
2270.49	11.3085
2273.33	11.128
2276.18	10.498
2279.02	12.268
2281.87	12.3453
2284.71	12.5913
2287.55	12.9079
2290.39	12.9467
2293.23	11.5843
2296.07	12.0168
2298.91	10.9813
2301.74	11.1156
2304.58	10.5519
2307.41	9.94641
2310.25	7.92452
2313.08	6.54983
2315.91	5.85844
2318.74	5.04124
2321.57	4.40937
2324.4	4.22051
2327.23	4.23923
2330.05	4.29116
2332.88	4.73908
2335.7	4.58693
2338.52	4.59519
2341.35	4.0019
2344.17	3.55934
2346.99	4.24142
2349.81	4.69738
2352.62	4.68152
2355.44	5.30783
2358.26	5.20056
2361.07	3.84024
2363.89	4.9338
2366.7	5.21217
2369.51	4.19212
2372.32	4.56015
2375.13	3.92624
2377.94	2.63551
2380.75	2.39409
2383.56	3.92942
2386.36	3.08955
2389.17	3.47256
2391.97	4.18707
2394.77	3.94816
2397.58	4.55063
2400.38	4.55784
2403.18	4.98403
2405.97	5.68517
2408.77	5.36245
2411.57	5.45155
2414.37	6.3769
2417.16	6.98655
2419.95	6.65848
2422.75	7.085
2425.54	6.65365
2428.33	6.18309
2431.12	5.45088
2433.91	5.78143
2436.7	4.88375
2439.48	4.65505
2442.27	4.57837
2445.05	3.36158
2447.84	5.48922
2450.62	6.35945
2453.4	5.23156
2456.18	5.45699
2458.96	5.61989
2461.74	5.49021
2464.52	5.26766
2467.29	4.74036
2470.07	4.53576
2472.85	4.10388
2475.62	3.31309
2478.39	3.10659
2481.16	2.53252
2483.93	2.48733
2486.7	1.61684
2489.47	1.50571
2492.24	1.47163
2495.01	1.65049
2497.77	1.57257
2500.54	2.40224
2503.3	3.38093
2506.06	3.16624
2508.83	3.29854
2511.59	4.58389
2514.35	6.04882
2517.11	6.55544
2519.86	6.4417
2522.62	6.84942
2525.38	8.25386
2528.13	9.03624
2530.89	8.9385
2533.64	8.44707
2536.39	8.08642
2539.14	8.87252
2541.89	9.47828
2544.64	9.13195
2547.39	9.635
2550.14	9.58748
2552.88	10.1866
2555.63	10.0356
2558.37	9.66148
2561.11	9.99026
2563.86	8.82196
2566.6	8.86912
2569.34	7.40511
2572.08	6.52351
2574.82	5.6169
2577.55	4.42279
2580.29	3.40735
2583.02	3.79293
2585.76	4.13865
2588.49	4.8551
2591.22	5.94485
2593.96	6.56629
2596.69	5.58645
2599.42	5.94323
2602.14	6.79474
2604.87	6.72024
2607.6	8.48333
2610.32	7.81161
2613.05	7.65659
2615.77	7.64022
2618.49	6.81752
2621.22	6.09589
2623.94	5.38639
2626.66	4.64636
2629.37	3.0152
2632.09	2.35921
2634.81	1.64417
2637.53	0.809557
2640.24	0.525676
2642.96	-0.190443
2645.67	0.532053
2648.38	1.93728
2651.09	3.04293
2653.8	4.40668
2656.51	5.62091
2659.22	5.9608
2661.93	6.70978
2664.63	8.28384
2667.34	9.09237
2670.04	10.6413
2672.75	11.0799
2675.45	11.9785
2678.15	11.5965
2680.85	11.6832
2683.55	12.8792
2686.25	13.3321
2688.94	13.1563
2691.64	12.6615
2694.34	11.7593
2697.03	11.8784
2699.73	11.1398
2702.42	11.2434
2705.11	11.3248
2707.8	10.8558
2710.49	11.3035
2713.18	11.6925
2715.87	11.6907
2718.55	11.5242
2721.24	11.0499
2723.93	11.2024
2726.61	11.1598
2729.29	11.4039
2731.98	11.159
2734.66	10.8104
2737.34	10.8062
2740.02	11.1436
2742.7	11.5033
2745.37	11.4762
2748.05	11.5287
2750.72	11.4711
2753.4	10.7942
2756.07	11.2057
2758.75	10.4959
2761.42	10.2127
2764.09	9.62397
2766.76	9.04023
2769.43	9.14212
2772.1	8.277
2774.76	7.45162
2777.43	7.0916
2780.1	6.28191
2782.76	4.79556
2785.42	4.04037
2788.09	4.04512
2790.75	2.8835
2793.41	2.60029
2796.07	1.91105
2798.73	1.25158
2801.39	1.506
2804.04	1.29278
2806.7	0.796784
2809.35	0.226475
2812.01	-0.710212
2814.66	-0.354065
2817.31	0.487361
2819.96	2.45598
2822.61	5.16944
2825.26	9.02687
2827.91	14.1131
2830.56	18.6665
2833.21	23.5942
2835.85	28.7122
2838.5	33.53
2841.14	40.1054
2843.78	47.0342
2846.42	54.7609
2849.06	61.8001
2851.71	71.3068
2854.34	80.9409
2856.98	89.931
2859.62	97.6832
2862.26	105.128
2864.89	111.105
2867.53	117.652
2870.16	122.681
2872.79	126.666
2875.42	129.986
2878.05	133.918
2880.68	137.096
2883.31	141.527
2885.94	145.457
2888.57	149.519
2891.19	153.861
2893.82	157.152
2896.44	161.366
2899.07	165.481
2901.69	170.648
2904.31	178.083
2906.93	186.955
2909.55	196.296
2912.17	205.194
2914.79	215.789
2917.41	224.281
2920.02	232.001
2922.64	237.244
2925.25	241.662
2927.86	243.26
2930.48	244.681
2933.09	243.603
2935.7	240.885
2938.31	236.415
2940.92	229.772
2943.53	222.385
2946.13	214.053
2948.74	205.319
2951.34	196.083
2953.95	187.265
2956.55	176.899
2959.15	167.429
2961.75	158.394
2964.35	149.908
2966.95	142.296
2969.55	135.147
2972.15	127.918
2974.75	120.524
2977.34	113.714
2979.94	106.105
2982.53	97.9573
2985.13	89.2765
2987.72	80.9458
2990.31	71.4996
2992.9	63.8803
2995.49	56.1353
2998.08	49.2282
3000.67	42.3625
3003.25	35.5913
3005.84	29.4243
3008.42	24.2186
3011.01	19.087
3013.59	15.2923
3016.17	12.4063
3018.76	9.04048
3021.34	5.9713
3023.92	4.62514
3026.49	3.36532
3029.07	3.00175
3031.65	3.78282
3034.23	4.15423
3036.8	5.25303
3039.38	6.53067
3041.95	7.59653
3044.52	8.39478
3047.09	9.38181
3049.66	9.95415
3052.23	11.3408
3054.8	12.3234
3057.37	12.9466
3059.94	13.1408
3062.5	12.944
3065.07	11.5126
3067.63	9.88773
3070.2	9.30398
3072.76	8.93628
3075.32	8.22335
3077.88	7.34828
3080.44	6.23597
3083	3.88053
3085.56	2.65472
3088.12	1.74932
3090.67	0.89438
3093.23	1.13696
3095.78	1.41614
3098.34	1.74812
3100.89	2.63972
3103.44	3.41626
3105.99	3.93123
3108.54	5.47992
3111.09	7.07773
3113.64	8.29139
3116.19	9.19929
3118.74	10.3337
3121.28	10.9049
3123.83	12.1688
3126.37	13.5925
3128.91	15.5998
3131.46	17.2658
3134	19.174
3136.54	20.0347
3139.08	20.5267
3141.62	21.0482
3144.16	21.2528
3146.69	22.9568
3149.23	24.7858