File: data/Raman/poly_smoothed/Thy_50_12_19_1x_45s_532 nm_x100_100%_600 gr_mm_01.txt
#Acq. time (s)=	45
#Accumulations=	2
#Range (cm-¹)=	200...3150
#Windows=	2
#Auto scanning=	Off
#Autofocus=	Off
#Macrospot=	Off
#AutoExposure=	Off
#Spike filter=	Multiple accum.
#Delay time (s)=	0
#Binning=	1
#Readout mode=	Signal
#DeNoise=	Off
#ICS correction=	On
#Dark correction=	Off
#Inst. Process=	Off
#Detector Gain=	Best Dynamic Range
#Detector ADC=	20 kHz
#Detector temperature (°C)=	-69.85
#Instrument=	LabRAM HR Evol
#Detector=	Synapse
#Objective=	x100
#Grating=	600 gr/mm
#ND Filter=	100%
#Laser (nm)=	532
#Hole=	100.021
#Range=	Auto
#Laser Pol.=	No
#Raman. Pol.=	No
#Laser Pol. (°)=	-0.0007625
#Raman Pol. (°)=	89.9995
#Collection=	Microscope
#StageXY=	Marzhauser
#StageZ=	Marzhauser
#X (µm)=	-5139.9
#Y (µm)=	1481.1
#Z (µm)=	63.15
#Full time(mm:ss)=	3:18
#Project=
#Sample=
#Site=
#Title=	Thy_50_12_19_2x_45s_532 nm_x100_100%_600 gr_mm
#Remark=
#Date=	07.07.2022 10:37
#Acquired=	07.07.2022 10:37:40
#Base:Fit=	10.08.2022 10:04:29
#Base:Sub=	10.08.2022 10:04:45
#Filter:Polynom=	16.08.2022 10:20:24
#AxisType[0]=Intens
#AxisUnit[0]=Cnt
#AxisType[1]=Spectr
#AxisUnit[1]=1/cm
200.43	17.0388
204.061	15.6914
207.688	15.8794
211.316	15.543
214.941	14.6157
218.566	13.5461
222.188	11.3255
225.809	9.89415
229.43	8.40282
233.047	8.10658
236.663	7.29245
240.278	6.82479
243.894	5.4778
247.506	5.10216
251.116	4.12882
254.725	3.59285
258.333	4.48965
261.939	4.52806
265.546	3.27775
269.15	3.47556
272.752	5.15405
276.353	5.33184
279.952	5.81985
283.55	4.49956
287.146	4.24579
290.739	6.55553
294.333	8.91625
297.925	8.48408
301.516	9.40692
305.106	9.56098
308.694	8.84194
312.279	8.87991
315.864	10.9437
319.448	10.3923
323.029	11.6024
326.61	11.842
330.19	12.0163
333.766	12.5684
337.343	13.7429
340.917	12.5107
344.491	12.1812
348.062	12.2594
351.633	10.3793
355.201	9.50613
358.77	8.94966
362.335	7.00748
365.899	5.92462
369.464	4.74294
373.025	3.71992
376.585	3.46405
380.143	4.12863
383.702	3.52577
387.258	1.95666
390.812	2.00276
394.365	1.07512
397.916	0.315884
401.467	0.505254
405.015	0.368042
408.565	1.09117
412.111	1.99325
415.656	1.53803
419.197	2.14002
422.739	2.45613
426.279	2.15977
429.819	2.63152
433.356	4.14373
436.893	5.08029
440.428	5.5334
443.96	5.45693
447.492	6.34267
451.023	6.40947
454.553	8.40988
458.079	7.79463
461.606	9.64167
465.132	11.2474
468.654	11.1283
472.177	11.963
475.696	12.9411
479.217	13.7053
482.733	14.0362
486.251	14.0708
489.765	15.0807
493.278	17.117
496.791	17.4723
500.301	17.1284
503.81	17.6504
507.319	17.224
510.825	16.9364
514.33	17.4693
517.833	18.9143
521.337	19.1107
524.838	18.5168
528.337	18.0941
531.835	17.8
535.332	16.7372
538.827	16.9773
542.321	17.1379
545.814	15.114
549.305	14.0511
552.795	13.0224
556.284	11.7989
559.771	11.8377
563.257	12.3889
566.742	12.1427
570.223	11.3475
573.705	12.9419
577.185	13.2005
580.665	11.5068
584.141	9.5076
587.617	8.17155
591.092	6.67423
594.564	6.34144
598.037	6.59592
601.506	5.71494
604.976	6.54686
608.443	6.53163
611.91	7.38055
615.374	8.39337
618.839	8.79549
622.3	9.71698
625.761	10.4535
629.221	11.4309
632.679	12.7203
636.135	14.0026
639.592	16.8713
643.045	19.6774
646.497	22.1429
649.948	23.9205
653.398	25.0271
656.846	26.3108
660.293	25.7858
663.738	25.6556
667.185	26.7893
670.628	26.9987
674.067	27.8823
677.508	27.6778
680.947	27.8309
684.385	27.2479
687.821	29.175
691.256	30.9855
694.69	32.0346
698.121	33.9828
701.552	35.1606
704.982	36.8429
708.41	37.5734
711.836	39.5015
715.262	41.1561
718.685	41.582
722.108	44.9161
725.53	48.3615
728.949	49.0919
732.369	50.2435
735.785	51.6417
739.2	53.7211
742.616	55.2358
746.028	56.8638
749.441	59.2321
752.851	61.4007
756.26	64.678
759.667	66.7181
763.075	68.1779
766.479	69.8555
769.883	72.0003
773.285	75.3412
776.686	76.7416
780.085	79.3744
783.484	82.0839
786.881	82.6934
790.276	84.5893
793.671	85.7915
797.064	87.8558
800.456	88.4635
803.846	89.8129
807.236	90.8501
810.624	90.3794
814.01	89.4693
817.394	88.1481
820.778	88.1709
824.161	87.0481
827.543	85.2532
830.921	84.4773
834.3	81.7149
837.676	80.31
841.053	77.7599
844.426	72.9119
847.8	68.3717
851.171	64.5985
854.542	63.7268
857.911	62.5416
861.279	60.1036
864.645	57.3416
868.01	56.1435
871.375	56.1763
874.737	54.9584
878.097	53.3452
881.457	52.2904
884.817	52.2805
888.174	52.5493
891.53	52.1682
894.884	52.8547
898.237	53.139
901.589	53.0589
904.94	53.218
908.289	53.2593
911.637	52.3339
914.984	51.8326
918.33	51.1961
921.674	49.9106
925.015	45.7411
928.357	42.6746
931.698	41.5652
935.037	39.8303
938.373	40.496
941.71	38.1294
945.046	35.2385
948.378	35.3895
951.711	36.9707
955.043	36.0047
958.372	33.7008
961.701	33.8293
965.027	33.6509
968.354	33.5482
971.678	34.4475
975	34.5587
978.324	34.421
981.644	34.1198
984.962	33.6689
988.282	33.4895
991.598	33.6659
994.913	33.9309
998.227	34.1877
1001.54	33.1541
1004.85	30.4235
1008.16	29.2734
1011.47	28.9773
1014.78	28.9657
1018.08	29.7027
1021.39	28.6845
1024.69	29.9027
1028	30.001
1031.3	30.4672
1034.6	30.7182
1037.9	28.6605
1041.19	28.8556
1044.49	27.2856
1047.79	27.1103
1051.08	28.1379
1054.37	26.6116
1057.66	25.9019
1060.95	22.8236
1064.24	21.8882
1067.53	20.0623
1070.81	19.1464
1074.1	18.6521
1077.38	16.5111
1080.66	15.3399
1083.94	12.5489
1087.22	11.799
1090.5	12.0489
1093.78	11.835
1097.05	11.2524
1100.33	12.473
1103.6	13.5383
1106.87	14.1685
1110.15	13.649
1113.41	13.8982
1116.68	13.1212
1119.95	13.4832
1123.21	12.3554
1126.48	12.2281
1129.74	13.5592
1133	14.1808
1136.26	11.8414
1139.52	10.1464
1142.78	8.34031
1146.04	7.23736
1149.29	6.11745
1152.55	5.6942
1155.8	4.08161
1159.05	3.98342
1162.3	1.92547
1165.55	2.37283
1168.8	2.83426
1172.05	2.60521
1175.29	1.8366
1178.54	1.67304
1181.78	1.99492
1185.02	1.47313
1188.26	0.548898
1191.5	0.670562
1194.74	0.738192
1197.97	0.847782
1201.21	2.12023
1204.44	2.26986
1207.68	5.23827
1210.91	8.04313
1214.14	8.95287
1217.37	9.84087
1220.6	12.2044
1223.82	14.838
1227.05	17.7464
1230.27	19.635
1233.49	22.5911
1236.72	24.4697
1239.94	26.9901
1243.16	29.9052
1246.37	31.8743
1249.59	34.5744
1252.8	35.8361
1256.02	37.67
1259.23	40.2231
1262.44	42.1541
1265.66	43.3897
1268.87	44.2919
1272.07	45.6791
1275.28	46.5264
1278.48	47.9038
1281.69	49.5863
1284.89	51.3613
1288.09	52.9178
1291.3	52.8423
1294.49	51.2367
1297.69	50.847
1300.89	51.8972
1304.09	52.0824
1307.28	51.7295
1310.47	51.2194
1313.66	51.6286
1316.86	50.2402
1320.05	50.049
1323.23	47.999
1326.42	47.8343
1329.61	46.4698
1332.79	45.3571
1335.98	45.3306
1339.16	44.1543
1342.34	42.4932
1345.52	40.2496
1348.7	38.4147
1351.87	37.599
1355.05	37.0654
1358.23	36.359
1361.4	34.436
1364.57	32.3399
1367.74	30.0398
1370.91	29.4089
1374.08	27.1707
1377.25	27.2432
1380.42	26.8629
1383.58	26.5862
1386.75	25.7969
1389.91	24.9141
1393.07	24.097
1396.23	22.9177
1399.39	23.3981
1402.55	24.8752
1405.7	27.3088
1408.86	28.1877
1412.01	30.7597
1415.17	32.3417
1418.32	34.8943
1421.47	39.5177
1424.62	43.5937
1427.77	48.3584
1430.92	51.388
1434.06	54.8572
1437.2	56.8453
1440.35	58.5568
1443.49	59.4088
1446.63	59.2823
1449.77	59.4163
1452.91	58.2353
1456.05	57.1881
1459.18	53.9274
1462.32	49.3141
1465.45	44.8423
1468.59	41.512
1471.72	37.0905
1474.85	34.4278
1477.98	30.6109
1481.11	26.761
1484.23	22.2818
1487.36	19.1469
1490.48	17.5509
1493.61	15.1602
1496.73	15.5999
1499.85	15.2619
1502.97	13.9417
1506.09	12.8047
1509.2	12.5388
1512.32	12.714
1515.44	12.894
1518.55	13.6007
1521.66	13.6993
1524.77	15.5348
1527.88	17.2139
1530.99	17.7375
1534.1	19.518
1537.21	21.2668
1540.31	23.7858
1543.42	26.7542
1546.52	28.9012
1549.62	31.341
1552.72	33.1776
1555.82	34.548
1558.92	35.5357
1562.02	36.5769
1565.11	38.1593
1568.21	39.5526
1571.3	41.8147
1574.39	43.3582
1577.49	45.1891
1580.58	45.7958
1583.67	46.7207
1586.75	46.287
1589.84	46.9464
1592.93	47.579
1596.01	46.966
1599.09	46.3531
1602.18	45.8274
1605.26	45.4011
1608.34	43.8164
1611.41	43.9677
1614.49	44.5148
1617.57	44.5801
1620.64	45.0201
1623.72	45.2075
1626.79	46.4735
1629.86	47.1628
1632.93	47.9955
1636	49.0766
1639.07	51.4529
1642.14	54.8379
1645.2	55.9804
1648.27	57.2759
1651.33	58.7296
1654.39	58.5883
1657.45	58.6135
1660.51	56.9057
1663.57	56.4342
1666.63	54.7111
1669.69	51.6227
1672.74	48.9188
1675.79	45.6771
1678.85	42.496
1681.9	38.5068
1684.95	35.1088
1688	33.2207
1691.05	29.692
1694.1	27.0869
1697.14	24.0468
1700.19	21.1049
1703.23	19.2164
1706.27	16.9898
1709.32	15.715
1712.35	14.7312
1715.39	13.0248
1718.43	11.1435
1721.47	10.4875
1724.5	10.828
1727.54	9.9366
1730.57	9.35203
1733.61	8.25684
1736.64	7.21014
1739.67	7.79768
1742.7	6.99959
1745.72	6.95815
1748.75	5.57839
1751.78	5.30148
1754.8	3.93738
1757.82	3.42796
1760.85	3.38342
1763.87	2.2389
1766.89	1.55613
1769.91	1.24661
1772.92	0.815663
1775.94	1.31319
1778.96	1.1356
1781.97	2.0701
1784.98	1.73907
1788	1.74998
1791.01	1.33284
1794.01	2.99902
1797.02	3.30105
1800.03	2.7441
1803.04	3.20548
1806.04	3.00039
1809.05	2.94785
1812.05	3.36619
1815.05	3.2674
1818.05	3.09007
1821.05	3.02945
1824.05	2.49138
1827.05	2.5112
1830.04	2.04931
1833.04	2.15507
1836.03	2.56504
1839.03	2.64723
1842.02	1.47192
1845.01	1.59138
1848	2.21122
1850.99	1.76565
1853.97	1.34778
1856.96	2.40977
1859.94	1.92775
1862.93	3.33243
1865.91	3.75929
1868.89	4.95738
1871.87	4.20728
1874.85	4.72292
1877.83	4.82374
1880.81	5.14792
1882.56	4.57831
1885.55	5.79999
1888.54	6.46471
1891.52	7.04062
1894.51	7.37502
1897.49	7.73354
1900.48	7.50331
1903.46	7.36933
1906.44	7.40022
1909.42	6.97066
1912.4	6.15269
1915.38	6.54642
1918.35	6.90806
1921.33	7.21418
1924.3	5.91217
1927.28	6.42119
1930.25	6.9331
1933.22	5.12709
1936.19	5.8288
1939.16	5.58087
1942.13	5.38255
1945.09	4.65583
1948.06	4.32186
1951.03	4.13323
1953.99	3.83115
1956.95	4.58212
1959.91	4.7786
1962.87	4.77439
1965.83	5.65233
1968.79	5.80159
1971.75	5.26702
1974.7	3.94012
1977.66	3.98274
1980.61	3.55184
1983.56	3.22224
1986.52	2.88341
1989.47	2.99417
1992.41	2.94751
1995.36	2.32175
1998.31	0.997732
2001.26	0.274255
2004.2	-0.777982
2007.15	0.0433789
2010.09	0.0298157
2013.03	-0.221416
2015.97	0.284207
2018.91	0.70248
2021.85	2.44157
2024.79	3.25237
2027.72	3.71305
2030.66	4.74639
2033.59	6.78527
2036.53	7.19719
2039.46	7.48571
2042.39	7.6635
2045.32	7.30913
2048.25	8.9188
2051.18	9.64872
2054.1	9.84899
2057.03	10.6971
2059.95	11.8773
2062.88	12.6885
2065.8	13.1176
2068.72	13.4764
2071.64	15.0954
2074.56	16.5822
2077.48	17.61
2080.39	19.3275
2083.31	20.1145
2086.22	21.2745
2089.14	23.2455
2092.05	25.4262
2094.96	27.2293
2097.87	28.467
2100.78	30.3322
2103.69	31.9997
2106.6	33.6455
2109.51	35.348
2112.41	38.6046
2115.32	40.7735
2118.22	44.2884
2121.12	46.4377
2124.02	48.4984
2126.92	52.0182
2129.82	55.7433
2132.72	58.2854
2135.62	60.5197
2138.51	63.6197
2141.41	66.8635
2144.3	69.8804
2147.19	72.1611
2150.09	73.5204
2152.97	74.6813
2155.86	77.0417
2158.75	78.8594
2161.64	79.3685
2164.53	80.5959
2167.41	80.674
2170.3	81.0577
2173.18	81.1672
2176.06	80.5854
2178.94	80.2406
2181.82	79.3902
2184.7	77.8453
2187.58	76.2749
2190.46	74.2278
2193.33	72.0875
2196.21	70.6928
2199.08	68.548
2201.95	66.2584
2204.83	63.5417
2207.7	60.9957
2210.57	58.2199
2213.43	54.9197
2216.3	51.7551
2219.17	48.0887
2222.03	44.7914
2224.9	43.0231
2227.76	41.4194
2230.62	38.986
2233.49	36.4561
2236.34	34.5735
2239.2	31.7409
2242.06	29.7799
2244.92	27.4805
2247.78	25.8586
2250.63	25.0938
2253.48	23.8904
2256.34	21.7636
2259.19	20.5516
2262.04	19.3808
2264.89	18.1173
2267.74	16.9674
2270.59	16.5923
2273.43	14.9862
2276.28	13.7783
2279.12	12.2933
2281.97	10.6168
2284.81	9.67786
2287.65	8.12172
2290.49	7.69632
2293.33	6.29145
2296.17	6.11486
2299.01	6.80288
2301.84	7.16525
2304.68	7.6666
2307.51	8.00275
2310.35	9.27055
2313.18	10.2279
2316.01	10.6751
2318.84	11.266
2321.67	11.3695
2324.5	10.992
2327.33	10.8213
2330.15	11.3969
2332.98	11.3078
2335.8	10.8316
2338.62	10.9957
2341.45	10.1487
2344.27	8.96392
2347.09	8.46096
2349.91	7.70901
2352.72	6.10326
2355.54	4.68057
2358.36	3.69781
2361.17	2.71665
2363.98	2.71837
2366.8	2.77679
2369.61	2.88308
2372.42	2.13448
2375.23	1.37885
2378.04	1.04821
2380.85	0.627809
2383.66	1.36031
2386.46	0.859489
2389.26	1.41425
2392.07	2.05625
2394.87	2.3208
2397.67	2.99161
2400.47	3.59627
2403.27	5.30996
2406.07	5.33819
2408.87	6.02087
2411.67	6.10744
2414.46	6.06477
2417.26	6.45332
2420.05	6.87657
2422.84	6.86122
2425.64	6.34886
2428.43	6.14266
2431.22	6.4514
2434.01	6.75692
2436.79	6.18607
2439.58	5.8171
2442.37	6.09562
2445.15	6.03097
2447.93	5.76208
2450.72	6.29119
2453.5	6.27997
2456.28	5.83233
2459.06	6.48414
2461.84	6.76477
2464.62	6.68149
2467.39	7.54041
2470.17	7.83628
2472.94	7.46389
2475.72	6.15825
2478.49	6.15721
2481.26	5.45231
2484.03	4.9763
2486.8	4.32673
2489.57	3.34532
2492.34	2.62154
2495.1	2.06954
2497.87	1.92765
2500.63	1.83291
2503.4	1.51584
2506.16	1.58847
2508.92	2.48482
2511.68	3.37165
2514.44	3.28179
2517.2	2.65882
2519.96	2.7477
2522.72	2.17778
2525.47	3.10109
2528.23	3.54954
2530.98	4.53699
2533.74	4.96514
2536.49	4.66083
2539.24	4.62285
2541.99	5.40728
2544.74	5.43908
2547.49	5.7768
2550.23	5.36332
2552.98	5.26588
2555.72	4.78215
2558.47	5.69372
2561.21	6.65134
2563.95	6.35906
2566.69	6.56131
2569.43	7.39786
2572.17	8.08782
2574.91	7.79845
2577.65	8.27448
2580.39	8.75911
2583.12	8.00366
2585.85	8.10078
2588.59	8.57238
2591.32	9.41306
2594.05	10.2034
2596.78	9.95615
2599.51	10.9372
2602.24	10.4663
2604.97	10.4192
2607.69	10.0882
2610.42	9.7012
2613.14	9.00643
2615.87	8.96811
2618.59	9.88422
2621.31	9.97677
2624.03	10.5829
2626.75	10.5221
2629.47	9.19426
2632.19	8.44032
2634.91	7.7851
2637.62	7.22964
2640.34	6.58418
2643.05	6.56983
2645.76	6.89254
2648.48	5.85629
2651.19	5.7511
2653.9	5.86284
2656.6	6.77619
2659.31	6.63008
2662.02	6.04811
2664.73	6.06363
2667.43	5.86001
2670.14	5.18685
2672.84	4.70854
2675.54	5.62513
2678.24	6.38192
2680.94	6.71944
2683.64	7.19825
2686.34	8.08795
2689.04	8.86125
2691.74	9.51734
2694.43	10.1583
2697.13	10.4129
2699.82	11.0052
2702.51	11.7315
2705.21	12.1454
2707.9	12.633
2710.58	13.5159
2713.27	13.9252
2715.96	14.0674
2718.65	14.6478
2721.33	13.7538
2724.02	13.4328
2726.71	13.1495
2729.39	13.6489
2732.07	12.2431
2734.75	12.0306
2737.43	10.9016
2740.11	10.5683
2742.79	10.0589
2745.47	9.20574
2748.14	7.98008
2750.82	7.59977
2753.49	7.65189
2756.17	6.54015
2758.84	6.93186
2761.51	6.80268
2764.18	6.66112
2766.85	6.43929
2769.52	5.54042
2772.19	4.5952
2774.86	4.6792
2777.52	3.77933
2780.19	3.50252
2782.85	3.16518
2785.52	2.72739
2788.18	2.5251
2790.84	2.49123
2793.5	2.03611
2796.16	1.0763
2798.82	1.43205
2801.48	0.445699
2804.13	0.484935
2806.79	-0.282902
2809.45	-0.769388
2812.1	-1.40896
2814.75	-0.859102
2817.41	1.63867
2820.06	4.70242
2822.71	7.69606
2825.36	12.9277
2828	16.9691
2830.65	21.5292
2833.3	25.5403
2835.94	30.1087
2838.59	35.8522
2841.23	40.7413
2843.87	45.9842
2846.52	52.2642
2849.16	58.5642
2851.8	65.7566
2854.44	72.341
2857.08	79.5181
2859.71	85.3484
2862.35	90.8349
2864.98	96.0055
2867.62	99.6541
2870.25	103.227
2872.88	105.076
2875.52	108.007
2878.15	110.721
2880.78	113.991
2883.41	116.737
2886.03	118.72
2888.66	120.993
2891.29	123.298
2893.91	124.405
2896.54	126.947
2899.16	129.876
2901.78	132.689
2904.4	137.513
2907.02	142.021
2909.64	148.404
2912.26	155.853
2914.88	162.741
2917.5	169.008
2920.11	174.519
2922.73	178.279
2925.34	181.57
2927.96	182.731
2930.57	182.761
2933.18	181.39
2935.79	178.84
2938.4	175.039
2941.01	171.165
2943.62	165.644
2946.22	159.739
2948.83	151.841
2951.43	144.275
2954.04	137.127
2956.64	128.654
2959.24	120.999
2961.84	114.055
2964.45	106.892
2967.05	100.436
2969.64	94.895
2972.24	88.977
2974.84	83.2135
2977.43	76.8013
2980.03	70.0911
2982.62	62.9578
2985.22	57.2017
2987.81	50.7066
2990.4	44.488
2992.99	38.8477
2995.58	33.3359
2998.17	28.5812
3000.76	24.05
3003.34	19.5316
3005.93	17.0935
3008.52	13.3093
3011.1	10.3394
3013.68	8.07535
3016.27	6.20308
3018.85	4.09768
3021.43	2.50627
3024.01	1.4982
3026.59	0.5892
3029.16	0.700308
3031.74	0.931206
3034.32	1.60945
3036.89	2.39528
3039.47	2.17833
3042.04	2.30902
3044.61	2.25206
3047.18	2.67195
3049.75	3.29932
3052.32	3.31519
3054.89	3.91703
3057.46	4.23992
3060.03	3.55765
3062.59	3.198
3065.16	2.76744
3067.72	3.55527
3070.29	2.90845
3072.85	3.08073
3075.41	3.03488
3077.97	2.57669
3080.53	1.46017
3083.09	1.39638
3085.65	0.203347
3088.21	0.34171
3090.76	1.43822
3093.32	1.36385
3095.87	1.7502
3098.43	2.28274
3100.98	1.72733
3103.53	1.51757
3106.08	2.27367
3108.63	2.45487
3111.18	2.99335
3113.73	3.68836
3116.28	5.35771
3118.83	5.65924
3121.37	5.9765
3123.92	7.08799
3126.46	8.22994
3129	9.62551
3131.55	12.0465
3134.09	13.5145
3136.63	15.6553
3139.17	17.1279
3141.71	18.6176
3144.24	20.6407
3146.78	22.7791
3149.32	25.6722