File: data/Raman/poly_smoothed/Thy_10_08_40_1x_45s_532 nm_x100_100%_600 gr_mm_01.txt
#Acq. time (s)=	45
#Accumulations=	2
#Range (cm-¹)=	200...3150
#Windows=	2
#Auto scanning=	Off
#Autofocus=	Off
#Macrospot=	Off
#AutoExposure=	Off
#Spike filter=	Multiple accum.
#Delay time (s)=	0
#Binning=	1
#Readout mode=	Signal
#DeNoise=	Off
#ICS correction=	On
#Dark correction=	Off
#Inst. Process=	Off
#Detector Gain=	Best Dynamic Range
#Detector ADC=	20 kHz
#Detector temperature (°C)=	-69.85
#Instrument=	LabRAM HR Evol
#Detector=	Synapse
#Objective=	x100
#Grating=	600 gr/mm
#ND Filter=	100%
#Laser (nm)=	532
#Hole=	100.021
#Range=	Auto
#Laser Pol.=	No
#Raman. Pol.=	No
#Laser Pol. (°)=	-0.0007625
#Raman Pol. (°)=	89.9995
#Collection=	Microscope
#StageXY=	Marzhauser
#StageZ=	Marzhauser
#X (µm)=	-2366.5
#Y (µm)=	228.5
#Z (µm)=	521.45
#Full time(mm:ss)=	3:18
#Project=
#Sample=
#Site=
#Title=	Thy_10_08_40_2x_45s_532 nm_x100_100%_600 gr_mm
#Remark=
#Date=	06.07.2022 14:39
#Acquired=	06.07.2022 14:39:03
#Base:Fit=	10.08.2022 09:46:25
#Base:Sub=	10.08.2022 09:46:49
#Filter:Polynom=	16.08.2022 10:24:56
#AxisType[0]=Intens
#AxisUnit[0]=Cnt
#AxisType[1]=Spectr
#AxisUnit[1]=1/cm
200.398	13.9427
204.027	16.4527
207.657	15.3075
211.283	14.0804
214.909	12.6247
218.533	11.6105
222.157	9.97844
225.777	8.13746
229.396	7.23273
233.016	6.84175
236.632	5.43467
240.247	4.76791
243.86	2.66582
247.474	1.95017
251.085	0.954501
254.694	1.67265
258.301	2.84316
261.908	3.2805
265.513	3.98675
269.116	4.07469
272.718	5.15722
276.319	7.72425
279.918	9.24513
283.516	10.0487
287.113	9.50263
290.708	9.58699
294.302	11.746
297.894	13.2624
301.485	15.4196
305.073	16.1774
308.661	17.3437
312.247	18.166
315.833	17.5294
319.415	17.7117
322.997	17.6145
326.579	16.9787
330.156	15.9002
333.735	15.588
337.31	16.9187
340.885	15.5346
344.458	15.5651
348.03	13.849
351.6	13.6635
355.17	12.0405
358.737	12.3927
362.304	11.7367
365.868	11.774
369.431	11.1297
372.994	9.92389
376.554	9.96879
380.112	11.4319
383.669	12.1175
387.225	11.9775
390.781	11.7932
394.334	10.6139
397.885	9.69786
401.436	7.75872
404.984	7.66116
408.532	7.20276
412.078	6.7395
415.623	5.51877
419.166	6.24615
422.708	6.77719
426.248	5.86076
429.788	6.37256
433.326	6.5825
436.86	4.78276
440.395	5.62536
443.929	6.07306
447.461	6.75416
450.99	8.81332
454.52	9.0731
458.048	10.5971
461.573	10.8342
465.099	11.8471
468.623	11.1599
472.144	12.0743
475.666	12.7259
479.184	12.9513
482.703	12.9089
486.218	13.2558
489.734	13.1117
493.247	14.0663
496.759	13.6932
500.271	13.8768
503.779	14.761
507.287	15.2111
510.795	16.2592
514.299	15.8765
517.803	15.3367
521.305	14.6644
524.805	15.4079
528.307	15.9307
531.805	15.3533
535.301	16.8009
538.797	17.2139
542.291	14.9502
545.783	15.2923
549.275	13.6578
552.765	12.856
556.253	11.2296
559.738	9.86408
563.224	9.58685
566.709	7.61055
570.192	6.37002
573.674	4.75714
577.153	4.29874
580.632	3.01029
584.11	2.1461
587.587	1.39494
591.06	1.28485
594.534	0.471339
598.005	0.0425331
601.476	-0.373166
604.944	0.582235
608.413	1.17689
611.878	2.78366
615.344	4.98953
618.807	6.38269
622.27	6.44805
625.73	6.65956
629.189	7.39952
632.648	9.48924
636.105	10.3472
639.559	10.6459
643.013	10.9557
646.467	11.5481
649.918	11.4666
653.368	12.3928
656.816	13.0363
660.263	14.6333
663.708	16.1128
667.153	16.786
670.596	18.449
674.037	20.4135
677.478	21.844
680.917	23.8244
684.355	26.745
687.791	28.9283
691.224	31.04
694.658	31.5351
698.091	34.2018
701.522	33.598
704.95	33.5259
708.379	36.4482
711.806	38.4014
715.23	38.9687
718.655	40.4492
722.078	41.2587
725.498	42.143
728.919	41.4719
732.337	42.8
735.755	43.0002
739.17	44.6849
742.584	45.567
745.998	47.1629
749.409	49.9212
752.819	51.4344
756.23	54.9942
759.637	58.0851
763.043	59.6426
766.448	62.1781
769.853	63.8142
773.255	64.982
776.656	65.0442
780.056	65.2483
783.454	67.0242
786.851	69.7391
790.247	72.8148
793.641	75.5687
797.034	77.1482
800.426	79.922
803.817	81.6523
807.206	82.8229
810.592	81.9716
813.979	81.8969
817.364	82.229
820.748	81.7895
824.129	80.2416
827.511	79.6234
830.891	79.6996
834.269	80.7541
837.646	80.4387
841.023	80.3397
844.396	77.8193
847.77	75.9974
851.141	73.7334
854.513	70.9373
857.881	69.1641
861.248	68.5181
864.616	66.8051
867.98	66.6404
871.343	66.6586
874.707	66.6044
878.068	65.6538
881.428	65.8175
884.786	64.7156
888.143	63.9859
891.498	62.0506
894.855	60.7798
898.208	59.6375
901.56	58.1765
904.91	55.1901
908.26	55.0473
911.608	54.8754
914.955	55.6105
918.298	55.9483
921.643	54.0228
924.986	53.3558
928.328	52.8786
931.668	53.3564
935.006	51.0104
938.344	50.0423
941.681	48.4819
945.014	46.8003
948.349	45.9759
951.682	46.4207
955.012	45.1761
958.343	41.7899
961.67	40.3577
964.998	41.3983
968.323	42.4316
971.649	43.032
974.971	44.4997
978.293	46.2054
981.615	46.386
984.933	46.7627
988.251	48.6236
991.567	50.9494
994.884	52.0628
998.198	52.0442
1001.51	51.7951
1004.82	52.0264
1008.13	51.5319
1011.44	52.0131
1014.75	50.1806
1018.06	49.3416
1021.36	47.0656
1024.66	44.3516
1027.97	42.2711
1031.27	39.6994
1034.57	36.4105
1037.87	30.9938
1041.16	28.8724
1044.46	28.3103
1047.76	28.2461
1051.05	26.0955
1054.34	25.0881
1057.63	24.1067
1060.92	24.1061
1064.21	22.831
1067.5	21.8373
1070.78	20.9899
1074.07	19.5974
1077.35	19.1338
1080.63	19.6042
1083.91	20.4606
1087.19	20.4566
1090.47	21.8239
1093.75	24.3963
1097.03	24.9336
1100.3	25.8604
1103.57	25.6651
1106.84	24.4444
1110.11	23.5531
1113.38	22.8064
1116.65	20.5717
1119.92	18.6131
1123.19	17.1887
1126.45	16.0153
1129.71	13.9863
1132.97	12.786
1136.23	13.0597
1139.49	13.0361
1142.75	12.2287
1146.01	11.4263
1149.26	10.2295
1152.52	8.85141
1155.77	8.88372
1159.02	7.76284
1162.27	8.30018
1165.52	7.24572
1168.77	9.60122
1172.02	10.4097
1175.26	12.5293
1178.51	15.2564
1181.75	16.5098
1184.99	17.4182
1188.23	19.4208
1191.47	21.9468
1194.71	24.1293
1197.94	27.8926
1201.18	30.8616
1204.41	34.0126
1207.65	37.8149
1210.88	41.5924
1214.11	46.6185
1217.34	50.3919
1220.57	54.4623
1223.79	57.8519
1227.02	58.7998
1230.24	59.2976
1233.47	59.8727
1236.69	59.9358
1239.91	60.0907
1243.13	58.9233
1246.34	59.8056
1249.56	59.0787
1252.78	58.7996
1255.99	58.6243
1259.2	58.7759
1262.42	60.3693
1265.63	61.8552
1268.84	63.5335
1272.04	65.1068
1275.25	66.8341
1278.46	68.4491
1281.66	70.8905
1284.86	73.7173
1288.07	76.6799
1291.27	78.7512
1294.47	80.3413
1297.66	82.3357
1300.86	84.2272
1304.06	84.8745
1307.25	85.4496
1310.44	85.5557
1313.64	84.8301
1316.83	85.0238
1320.02	83.9844
1323.2	82.2462
1326.39	81.6934
1329.58	81.6226
1332.76	80.5413
1335.95	80.4519
1339.13	79.8908
1342.31	79.7019
1345.49	77.1545
1348.67	74.6823
1351.85	72.4227
1355.02	68.8587
1358.2	66.5408
1361.37	62.9917
1364.54	59.6727
1367.71	56.8816
1370.88	52.4611
1374.05	49.6753
1377.22	48.1387
1380.39	47.1725
1383.55	44.8492
1386.72	42.2993
1389.88	40.5738
1393.04	39.2116
1396.2	36.6067
1399.36	35.9931
1402.52	35.4194
1405.68	35.9879
1408.83	38.4157
1411.98	41.3182
1415.14	44.9215
1418.29	49.2011
1421.44	55.6961
1424.59	61.392
1427.74	67.725
1430.89	74.2192
1434.03	79.2272
1437.18	85.5763
1440.32	91.2691
1443.46	94.4048
1446.6	96.2266
1449.74	97.4436
1452.88	98.1965
1456.02	97.1832
1459.16	93.6255
1462.29	89.9541
1465.43	83.5017
1468.56	75.158
1471.69	65.4221
1474.82	57.2431
1477.95	50.2597
1481.08	42.3108
1484.2	34.742
1487.33	30.4539
1490.46	24.3287
1493.58	22.0477
1496.7	20.0057
1499.82	18.9117
1502.94	18.4451
1506.06	18.1354
1509.18	18.3706
1512.29	18.6305
1515.41	18.6269
1518.52	19.1874
1521.63	19.7902
1524.75	20.9348
1527.85	22.9474
1530.96	24.9899
1534.07	27.0912
1537.18	28.32
1540.28	29.8102
1543.39	29.3882
1546.49	31.4347
1549.59	34.2716
1552.69	38.2305
1555.79	40.6506
1558.89	43.8026
1561.99	46.7515
1565.08	50.4335
1568.18	54.3899
1571.27	59.8598
1574.37	63.4088
1577.46	67.5409
1580.55	70.5163
1583.64	72.6402
1586.73	74.8424
1589.81	76.2428
1592.9	77.1023
1595.98	77.553
1599.06	77.4037
1602.15	77.317
1605.23	76.2005
1608.31	74.2566
1611.39	70.7802
1614.46	69.431
1617.54	69.7254
1620.61	70.7537
1623.69	72.5584
1626.76	74.8391
1629.83	77.0072
1632.9	78.842
1635.97	80.7235
1639.04	83.5782
1642.11	86.4066
1645.17	88.9177
1648.24	91.5673
1651.3	92.6004
1654.36	94.1987
1657.42	93.9404
1660.48	93.9441
1663.54	92.6577
1666.6	90.7387
1669.66	87.1048
1672.71	82.3027
1675.77	78.064
1678.82	72.0852
1681.87	65.3048
1684.92	57.2955
1687.97	52.2265
1691.02	49.1416
1694.07	43.8727
1697.11	38.7276
1700.16	34.0529
1703.2	29.7912
1706.25	26.594
1709.29	24.0059
1712.33	21.1365
1715.37	18.6815
1718.41	16.2956
1721.44	14.2087
1724.48	13.0672
1727.51	11.3905
1730.55	10.7925
1733.58	9.94041
1736.61	9.14714
1739.64	9.02252
1742.67	6.81639
1745.7	6.68471
1748.72	5.18572
1751.75	4.14214
1754.77	3.4894
1757.8	2.02171
1760.82	1.27954
1763.84	1.16139
1766.86	1.44195
1769.88	1.33709
1772.9	1.03033
1775.91	1.5016
1778.93	1.86036
1781.94	2.89035
1784.96	2.7378
1787.97	2.78514
1790.98	2.63404
1793.99	2.12809
1797	1.27489
1800.01	1.44719
1803.01	1.5384
1806.02	0.907073
1809.02	0.657961
1812.02	0.154985
1815.02	-0.586437
1818.03	-1.19297
1821.02	-0.606074
1824.02	-0.696299
1827.02	0.192304
1830.02	0.492095
1833.01	0.934391
1836.01	1.22035
1839	2.2111
1841.99	2.26894
1844.98	2.59883
1847.97	2.77696
1850.96	2.73065
1853.95	2.9204
1856.93	2.04307
1859.92	2.51152
1862.9	3.12883
1865.88	3.24775
1868.87	3.64969
1871.85	4.24492
1874.83	4.49562
1877.81	5.43767
1880.78	6.04908
1882.53	6.23763
1885.52	7.14516
1888.51	9.45719
1891.5	8.84
1894.48	9.86507
1897.47	9.89455
1900.45	10.2826
1903.43	11.0345
1906.41	10.8984
1909.39	10.6744
1912.37	10.8616
1915.35	10.9527
1918.33	10.495
1921.3	9.11562
1924.28	8.34364
1927.25	8.64706
1930.22	7.66752
1933.19	8.2849
1936.16	7.85392
1939.13	7.56799
1942.1	7.00685
1945.07	7.66547
1948.03	8.24033
1951	8.453
1953.96	9.10585
1956.92	9.66626
1959.88	9.83777
1962.84	9.51796
1965.8	8.59425
1968.76	8.74603
1971.72	7.87471
1974.67	9.31554
1977.63	9.15348
1980.58	8.26298
1983.54	8.28006
1986.49	9.81336
1989.44	10.2374
1992.39	10.7406
1995.33	10.997
1998.28	10.7382
2001.23	11.2963
2004.17	12.5752
2007.12	12.9693
2010.06	13.8947
2013	14.2861
2015.94	14.5919
2018.88	15.079
2021.82	15.6916
2024.76	16.218
2027.69	16.5007
2030.63	16.5555
2033.56	16.7302
2036.5	15.6172
2039.43	15.7787
2042.36	15.8976
2045.29	16.1965
2048.22	15.6365
2051.15	15.392
2054.07	15.29
2057	16.0147
2059.92	16.1953
2062.85	16.6375
2065.77	16.638
2068.69	16.9515
2071.61	17.2449
2074.53	17.2062
2077.45	17.8708
2080.37	18.0316
2083.28	18.5927
2086.2	18.522
2089.11	19.8007
2092.02	21.1122
2094.94	21.7677
2097.85	22.707
2100.76	23.6559
2103.66	24.3115
2106.57	24.685
2109.48	25.6426
2112.38	26.3977
2115.29	26.3055
2118.19	26.7435
2121.09	27.2799
2123.99	28.4801
2126.89	28.6497
2129.79	29.7212
2132.69	30.59
2135.59	31.2731
2138.48	32.346
2141.38	32.7992
2144.27	32.9409
2147.17	33.63
2150.06	34.9645
2152.95	36.5892
2155.84	37.5057
2158.73	39.1233
2161.61	40.4727
2164.5	40.8924
2167.38	41.2104
2170.27	42.0628
2173.15	42.2507
2176.03	42.0628
2178.91	41.7714
2181.8	41.3102
2184.67	41.7242
2187.55	41.5483
2190.43	40.9901
2193.3	40.6539
2196.18	39.7085
2199.05	38.825
2201.93	38.011
2204.8	37.485
2207.67	36.0338
2210.54	34.7643
2213.41	33.4278
2216.27	31.7624
2219.14	30.2936
2222.01	29.8061
2224.87	28.9304
2227.73	27.9099
2230.6	26.941
2233.46	25.8278
2236.32	24.9262
2239.18	24.8117
2242.03	23.7764
2244.89	22.8033
2247.75	21.5119
2250.6	20.5688
2253.46	20.5344
2256.31	20.6997
2259.16	19.4491
2262.01	18.0839
2264.86	17.8633
2267.71	17.8731
2270.56	18.2589
2273.4	18.0813
2276.25	18.6549
2279.09	18.5717
2281.94	18.5729
2284.78	17.7106
2287.62	17.121
2290.46	16.9572
2293.3	15.5566
2296.14	16.1834
2298.98	17.8516
2301.82	18.9591
2304.65	19.5765
2307.49	20.5496
2310.32	20.0276
2313.15	20.2094
2315.98	20.1431
2318.81	20.6533
2321.64	20.1699
2324.47	19.635
2327.3	18.4486
2330.12	18.1597
2332.95	17.1848
2335.77	16.0281
2338.6	15.2559
2341.42	14.7158
2344.24	13.1147
2347.06	11.6503
2349.88	9.19156
2352.7	7.2639
2355.51	6.21096
2358.33	5.03379
2361.14	4.64649
2363.96	4.70421
2366.77	6.27205
2369.58	6.62431
2372.39	7.02733
2375.2	7.42338
2378.01	8.6109
2380.82	9.57771
2383.63	10.9842
2386.43	10.8138
2389.24	10.4692
2392.04	9.84566
2394.84	10.2345
2397.65	10.3997
2400.45	10.3547
2403.25	9.60045
2406.05	9.87694
2408.84	9.95765
2411.64	9.27929
2414.44	9.34128
2417.23	9.38853
2420.02	9.4134
2422.82	10.502
2425.61	11.3007
2428.4	11.3416
2431.19	11.5755
2433.98	11.8559
2436.77	12.0161
2439.55	12.2481
2442.34	12.4993
2445.12	12.5701
2447.91	12.1139
2450.69	12.2983
2453.47	11.5026
2456.25	10.2643
2459.03	9.2427
2461.81	8.69423
2464.59	8.26747
2467.36	6.95653
2470.14	6.16771
2472.92	5.50898
2475.69	5.78878
2478.46	4.27301
2481.23	3.77873
2484	3.23946
2486.77	2.54729
2489.54	1.6292
2492.31	1.22826
2495.08	1.2036
2497.84	0.527623
2500.61	0.281287
2503.37	0.191462
2506.13	0.298976
2508.9	-0.377157
2511.66	-0.197417
2514.42	0.756205
2517.18	1.64362
2519.93	2.59195
2522.69	2.42611
2525.45	1.91316
2528.2	2.13023
2530.95	2.20497
2533.71	2.86366
2536.46	3.3136
2539.21	3.45746
2541.96	3.25331
2544.71	2.62655
2547.46	1.97592
2550.2	1.93652
2552.95	1.588
2555.7	2.2616
2558.44	2.22754
2561.18	2.7352
2563.93	2.48351
2566.67	2.43538
2569.41	3.09614
2572.15	3.02502
2574.88	3.36689
2577.62	3.2989
2580.36	3.66049
2583.09	3.78658
2585.83	3.16903
2588.56	3.80396
2591.29	3.00088
2594.02	2.64962
2596.75	2.04217
2599.48	1.35803
2602.21	1.59271
2604.94	1.09582
2607.67	0.0509427
2610.39	-0.958766
2613.12	-0.930179
2615.84	-0.99701
2618.56	-0.918822
2621.28	-0.722027
2624.01	-0.410007
2626.72	-0.693056
2629.44	-0.808704
2632.16	-0.532535
2634.88	-0.0360854
2637.59	0.0580653
2640.31	1.12825
2643.02	1.90983
2645.74	1.95267
2648.45	2.58768
2651.16	3.09672
2653.87	2.61775
2656.58	1.90654
2659.29	1.57305
2661.99	1.47422
2664.7	1.98438
2667.41	2.43169
2670.11	2.49061
2672.81	2.14557
2675.51	2.34769
2678.22	3.01172
2680.92	1.99845
2683.62	1.97957
2686.31	1.28079
2689.01	1.44444
2691.71	2.03769
2694.4	2.52777
2697.1	3.32672
2699.79	4.22987
2702.49	4.97014
2705.18	6.19916
2707.87	7.25376
2710.56	8.08003
2713.25	8.45773
2715.94	8.45726
2718.62	8.36369
2721.31	8.96205
2723.99	9.57631
2726.68	10.1118
2729.36	9.39837
2732.04	9.8083
2734.73	9.43373
2737.41	8.87194
2740.08	7.95816
2742.76	7.30867
2745.44	6.7448
2748.12	5.83568
2750.79	4.50469
2753.47	4.09799
2756.14	4.90321
2758.81	4.4267
2761.49	3.47644
2764.16	3.66605
2766.83	3.28494
2769.5	2.18497
2772.16	2.1287
2774.83	1.73861
2777.5	1.92497
2780.16	2.25133
2782.83	1.78043
2785.49	1.66725
2788.15	1.15736
2790.82	0.20302
2793.48	-0.467097
2796.14	-0.774441
2798.79	-0.372794
2801.45	-0.544154
2804.11	-0.254411
2806.76	-0.424601
2809.42	-1.09074
2812.07	-1.00597
2814.73	-0.646403
2817.38	1.39585
2820.03	3.35443
2822.68	7.23205
2825.33	10.3657
2827.98	14.8344
2830.63	20.4599
2833.27	24.5657
2835.92	29.9231
2838.56	36.9211
2841.21	44.7905
2843.85	53.5611
2846.49	63.1473
2849.13	72.5686
2851.77	83.1618
2854.41	94.9755
2857.05	105.751
2859.69	115.044
2862.32	124.941
2864.96	132.869
2867.59	139.899
2870.23	145.337
2872.86	150.473
2875.49	155.468
2878.12	160.992
2880.75	166.25
2883.38	170.702
2886.01	174.744
2888.63	178.236
2891.26	181.754
2893.89	185.966
2896.51	190.745
2899.13	196.01
2901.76	203.064
2904.38	211.869
2907	222.755
2909.62	234.885
2912.24	246.792
2914.85	258.961
2917.47	270.449
2920.09	280.091
2922.7	287.801
2925.32	292.494
2927.93	295.45
2930.54	297.466
2933.15	295.556
2935.76	293.128
2938.37	289.354
2940.98	284.059
2943.59	275.477
2946.2	266.892
2948.8	256.452
2951.41	245.527
2954.01	234.104
2956.62	222.663
2959.22	211.707
2961.82	200.57
2964.42	190.466
2967.02	180.526
2969.62	172.307
2972.22	163.225
2974.81	154.571
2977.41	146.013
2980	137.454
2982.6	129.159
2985.19	120.09
2987.78	110.69
2990.38	101.4
2992.97	92.3265
2995.56	83.9583
2998.14	76.4794
3000.73	69.9966
3003.32	63.0397
3005.91	56.6955
3008.49	51.0335
3011.07	45.0356
3013.66	40.2769
3016.24	35.8166
3018.82	32.5614
3021.4	30.4036
3023.98	28.6791
3026.56	26.6159
3029.14	25.6884
3031.71	24.8334
3034.29	24.4243
3036.87	25.2985
3039.44	26.8274
3042.01	27.2578
3044.59	29.2464
3047.16	29.8071
3049.73	30.3061
3052.3	29.9345
3054.87	30.1118
3057.43	30.2685
3060	31.2728
3062.57	30.4935
3065.13	28.8611
3067.7	26.916
3070.26	25.3779
3072.82	22.8873
3075.39	20.954
3077.95	18.7816
3080.51	16.7006
3083.07	14.3715
3085.63	12.8041
3088.18	11.223
3090.74	9.9033
3093.29	8.98812
3095.85	8.13271
3098.4	7.76489
3100.95	7.00812
3103.51	6.30659
3106.06	5.78299
3108.61	4.71429
3111.16	4.004
3113.71	3.91657
3116.25	3.80238
3118.8	3.9064
3121.35	3.92191
3123.89	4.08386
3126.44	3.28483
3128.98	3.37856
3131.52	3.02874
3134.06	2.47083
3136.6	1.72544
3139.14	1.07549
3141.68	0.29407
3144.22	-0.0196274
3146.76	-0.766924
3149.29	-2.10454