File: data/Raman/poly_smoothed/Thy_10_08_31_1x_45s_532 nm_x100_100%_600 gr_mm_01.txt
#Acq. time (s)=	45
#Accumulations=	2
#Range (cm-¹)=	200...3150
#Windows=	2
#Auto scanning=	Off
#Autofocus=	Off
#Macrospot=	Off
#AutoExposure=	Off
#Spike filter=	Multiple accum.
#Delay time (s)=	0
#Binning=	1
#Readout mode=	Signal
#DeNoise=	Off
#ICS correction=	On
#Dark correction=	Off
#Inst. Process=	Off
#Detector Gain=	Best Dynamic Range
#Detector ADC=	20 kHz
#Detector temperature (°C)=	-69.85
#Instrument=	LabRAM HR Evol
#Detector=	Synapse
#Objective=	x100
#Grating=	600 gr/mm
#ND Filter=	100%
#Laser (nm)=	532
#Hole=	100.021
#Range=	Auto
#Laser Pol.=	No
#Raman. Pol.=	No
#Laser Pol. (°)=	-0.0007625
#Raman Pol. (°)=	89.9995
#Collection=	Microscope
#StageXY=	Marzhauser
#StageZ=	Marzhauser
#X (µm)=	2192.3
#Y (µm)=	1230.7
#Z (µm)=	442.35
#Full time(mm:ss)=	3:18
#Project=
#Sample=
#Site=
#Title=	Thy_10_08_31_2x_45s_532 nm_x100_100%_600 gr_mm
#Remark=
#Date=	05.07.2022 16:26
#Acquired=	05.07.2022 16:26:57
#Base:Fit=	10.08.2022 09:46:25
#Base:Sub=	10.08.2022 09:46:49
#Filter:Polynom=	16.08.2022 10:24:56
#AxisType[0]=Intens
#AxisUnit[0]=Cnt
#AxisType[1]=Spectr
#AxisUnit[1]=1/cm
200.43	12.9834
204.059	11.2377
207.688	10.6004
211.314	9.04358
214.941	6.83805
218.564	5.57127
222.186	4.14853
225.809	3.56855
229.428	4.08057
233.045	4.23092
236.663	4.51912
240.278	5.31588
243.891	7.53454
247.503	7.79316
251.116	8.67088
254.725	8.20807
258.333	7.61154
261.939	7.24027
265.544	8.95129
269.148	11.5734
272.75	12.8503
276.351	12.452
279.95	11.681
283.548	12.4913
287.144	13.3282
290.739	13.5419
294.333	13.7152
297.925	12.757
301.514	13.3623
305.104	13.4094
308.692	14.3202
312.279	16.4219
315.862	16.9138
319.446	17.9665
323.029	17.8584
326.608	18.2336
330.188	19.764
333.766	18.9995
337.341	18.5184
340.917	17.7833
344.489	16.6572
348.062	17.0777
351.631	18.3545
355.201	18.1792
358.768	15.988
362.333	13.5647
365.899	13.1175
369.462	13.0648
373.023	13.3368
376.585	12.6106
380.143	13.549
383.7	12.5488
387.256	13.2128
390.812	14.5031
394.365	13.7398
397.916	14.2733
401.467	14.0319
405.015	15.0534
408.563	14.86
412.109	14.7691
415.654	16.1899
419.197	15.632
422.739	14.3845
426.279	14.827
429.819	14.2161
433.356	14.1125
436.891	14.2504
440.426	14.4028
443.96	14.0398
447.492	12.568
451.021	12.9566
454.551	12.6847
458.079	13.0893
461.604	13.7618
465.13	15.9876
468.654	17.559
472.175	18.6303
475.696	21.0804
479.215	21.1026
482.733	21.9349
486.249	23.0428
489.765	22.908
493.278	24.4933
496.789	24.3517
500.301	24.4198
503.81	24.4813
507.317	23.5882
510.825	24.2549
514.33	23.4558
517.833	22.3142
521.335	22.3646
524.836	22.5379
528.335	21.3966
531.835	19.9957
535.332	19.7905
538.827	18.4007
542.321	16.8102
545.814	16.6416
549.305	17.5309
552.795	17.9314
556.282	17.784
559.769	17.324
563.255	15.988
566.739	13.8016
570.223	13.0878
573.705	10.3065
577.183	8.90086
580.663	8.1348
584.141	7.34163
587.615	7.16526
591.09	4.49566
594.564	4.08504
598.035	2.95333
601.506	2.83547
604.974	3.67436
608.443	3.79579
611.908	4.28132
615.374	4.4363
618.837	4.61227
622.3	5.57294
625.761	6.08627
629.219	8.84409
632.677	10.8052
636.135	13.0852
639.59	13.7625
643.043	16.008
646.495	16.853
649.948	18.2713
653.398	19.8022
656.846	21.9077
660.293	23.442
663.738	25.1954
667.183	27.5499
670.626	27.9334
674.067	29.855
677.508	30.7911
680.947	32.2706
684.385	33.7284
687.821	34.3814
691.254	34.3382
694.688	35.9758
698.121	37.2502
701.552	37.4727
704.98	38.5924
708.409	39.9401
711.836	41.7281
715.26	43.0473
718.685	43.887
722.108	45.5179
725.528	46.8173
728.949	49.1178
732.367	50.6635
735.785	51.6874
739.2	53.1419
742.614	54.7854
746.028	56.374
749.439	57.046
752.849	59.2684
756.26	61.2946
759.667	62.8226
763.073	64.2275
766.477	66.8998
769.883	67.1173
773.285	67.749
776.686	68.1494
780.085	69.8284
783.484	71.2848
786.881	73.3659
790.276	76.0891
793.671	78.6989
797.064	79.7855
800.456	81.1711
803.846	82.753
807.234	82.6109
810.622	83.0114
814.008	83.6234
817.394	84.737
820.778	84.629
824.159	83.3981
827.541	84.7448
830.921	83.8843
834.298	84.2035
837.676	83.7543
841.051	83.3148
844.426	79.6683
847.798	77.1364
851.171	75.3522
854.54	72.8835
857.911	70.1213
861.278	69.631
864.645	67.0144
868.01	64.0688
871.373	62.41
874.735	61.1379
878.097	58.6541
881.457	56.3219
884.815	55.5518
888.172	55.3606
891.528	54.2599
894.882	55.2508
898.237	56.6327
901.589	57.0885
904.94	55.1705
908.289	55.7307
911.635	54.7761
914.982	54.3455
918.328	54.9118
921.672	53.1208
925.015	50.9589
928.357	49.3258
931.698	49.075
935.035	49.3521
938.373	48.1186
941.71	47.1319
945.044	44.6376
948.378	44.2995
951.709	42.5808
955.041	41.2538
958.372	40.7749
961.699	38.2621
965.027	36.6494
968.352	38.2881
971.676	38.4022
975	37.0106
978.322	38.0396
981.642	36.3408
984.962	35.8582
988.28	35.7799
991.596	35.4434
994.911	35.9614
998.227	36.9855
1001.54	35.8403
1004.85	33.5701
1008.16	33.0507
1011.47	34.5636
1014.78	34.5426
1018.08	35.0594
1021.39	35.1668
1024.69	35.3564
1028	34.3335
1031.3	32.6779
1034.6	30.8976
1037.9	29.0688
1041.19	26.5834
1044.49	26.4692
1047.78	25.9785
1051.08	24.3448
1054.37	23.2082
1057.66	22.6099
1060.95	21.8863
1064.24	20.9188
1067.53	20.0107
1070.81	18.7043
1074.1	18.3443
1077.38	17.7183
1080.66	15.7089
1083.94	13.5696
1087.22	13.9943
1090.5	15.8762
1093.78	15.9385
1097.05	15.5991
1100.33	16.2637
1103.6	16.7112
1106.87	15.9256
1110.14	14.5802
1113.41	13.6047
1116.68	14.5562
1119.95	15.0095
1123.21	15.0018
1126.48	13.4519
1129.74	12.2611
1133	12.5776
1136.26	12.8325
1139.52	12.5984
1142.78	10.6271
1146.04	9.96578
1149.29	10.8064
1152.55	10.7211
1155.8	10.9857
1159.05	9.93812
1162.3	8.22608
1165.55	8.92581
1168.8	9.98106
1172.05	9.09305
1175.29	8.18957
1178.54	7.39421
1181.78	8.17773
1185.02	8.85027
1188.26	8.63529
1191.5	10.5841
1194.74	12.5568
1197.97	14.2356
1201.21	15.2499
1204.44	17.6068
1207.68	19.0876
1210.91	21.1106
1214.14	23.2282
1217.37	26.7166
1220.59	30.5859
1223.82	34.1784
1227.05	39.6152
1230.27	43.7538
1233.49	45.8494
1236.72	46.4423
1239.94	48.5038
1243.16	51.0856
1246.37	51.7042
1249.59	52.1793
1252.8	51.8712
1256.02	52.0761
1259.23	52.6125
1262.44	53.2343
1265.66	53.7169
1268.86	52.4816
1272.07	52.9249
1275.28	53.2591
1278.48	52.9571
1281.69	54.5575
1284.89	55.3618
1288.09	56.0399
1291.29	57.2197
1294.49	59.0013
1297.69	61.8357
1300.89	65.5642
1304.08	65.0033
1307.28	67.3923
1310.47	72.8117
1313.66	76.3734
1316.85	79.896
1320.04	83.9882
1323.23	86.4792
1326.42	88.4329
1329.61	89.6693
1332.79	90.7864
1335.97	90.8856
1339.16	90.2825
1342.34	87.7212
1345.52	84.5698
1348.7	81.754
1351.87	79.001
1355.05	76.9068
1358.22	74.203
1361.4	69.1988
1364.57	64.5797
1367.74	60.4791
1370.91	55.2339
1374.08	51.931
1377.25	47.2873
1380.41	44.4043
1383.58	43.5538
1386.74	45.0942
1389.91	44.2126
1393.07	40.8567
1396.23	39.3432
1399.39	38.5331
1402.55	37.0573
1405.7	37.7031
1408.86	37.6108
1412.01	39.1899
1415.17	41.3206
1418.32	44.6128
1421.47	48.5343
1424.62	53.0279
1427.77	59.7006
1430.91	66.2891
1434.06	71.5444
1437.2	75.1252
1440.35	79.0242
1443.49	82.7583
1446.63	84.7124
1449.77	86.0541
1452.91	86.1058
1456.05	84.2744
1459.18	81.1412
1462.32	77.5072
1465.45	70.8794
1468.59	63.4339
1471.72	57.549
1474.85	50.9562
1477.98	44.5042
1481.1	36.5082
1484.23	30.0745
1487.36	25.2546
1490.48	20.7517
1493.61	17.6604
1496.73	15.0225
1499.85	13.5679
1502.97	12.4967
1506.09	12.2542
1509.2	11.6386
1512.32	10.8782
1515.43	10.1897
1518.55	11.5849
1521.66	13.2645
1524.77	15.5105
1527.88	17.2515
1530.99	19.0451
1534.1	21.4497
1537.21	23.5967
1540.31	25.785
1543.42	28.2579
1546.52	33.7055
1549.62	37.6358
1552.72	40.5324
1555.82	42.1574
1558.92	46.5997
1562.02	50.7269
1565.11	53.6178
1568.21	55.7747
1571.3	59.6088
1574.39	62.8576
1577.49	64.0834
1580.57	65.6531
1583.66	67.4635
1586.75	68.3387
1589.84	68.1472
1592.92	70.2848
1596.01	70.0715
1599.09	69.8518
1602.17	66.811
1605.25	65.2628
1608.33	64.968
1611.41	63.288
1614.49	62.3644
1617.57	60.9181
1620.64	62.2981
1623.72	62.8061
1626.79	63.0169
1629.86	63.3364
1632.93	64.4186
1636	66.3732
1639.07	66.7635
1642.13	66.6139
1645.2	68.5496
1648.26	70.6484
1651.33	71.0037
1654.39	72.4282
1657.45	72.8495
1660.51	72.4971
1663.57	71.6175
1666.63	69.3453
1669.68	66.9167
1672.74	63.3458
1675.79	59.9036
1678.85	56.3736
1681.9	53.1777
1684.95	49.6664
1688	45.1749
1691.05	42.4576
1694.09	38.5487
1697.14	34.1995
1700.18	30.6902
1703.23	27.4553
1706.27	24.0572
1709.31	21.2433
1712.35	19.1915
1715.39	16.0661
1718.43	14.7658
1721.47	13.2579
1724.5	12.4461
1727.54	11.2583
1730.57	9.69387
1733.61	7.90024
1736.64	6.23754
1739.67	5.52337
1742.7	4.14246
1745.72	3.65422
1748.75	3.62777
1751.77	3.9958
1754.8	2.94061
1757.82	3.21154
1760.84	3.61971
1763.87	2.11765
1766.89	1.5258
1769.91	0.405963
1772.92	0.587581
1775.94	1.1261
1778.95	1.26118
1781.97	0.230002
1784.98	0.413749
1787.99	0.503549
1791.01	0.347086
1794.01	0.14114
1797.02	-0.0259978
1800.03	-0.914488
1803.04	-0.394536
1806.04	-0.330337
1809.05	-0.806397
1812.05	-0.559172
1815.05	0.402051
1818.05	1.52406
1821.05	1.68903
1824.05	2.29704
1827.05	2.77285
1830.04	3.06498
1833.04	4.2958
1836.03	4.41223
1839.03	4.52429
1842.02	5.16062
1845.01	5.72382
1848	5.87885
1850.99	6.19637
1853.97	5.58053
1856.96	5.89534
1859.94	5.27597
1862.93	5.52575
1865.91	5.31358
1868.89	4.80478
1871.87	4.33495
1874.85	4.65325
1877.83	4.42597
1880.81	3.49406
1882.57	3.94372
1885.56	4.18693
1888.55	4.25517
1891.54	3.5492
1894.52	3.9414
1897.51	4.52887
1900.49	3.27141
1903.47	3.88521
1906.45	4.39385
1909.43	5.05969
1912.41	5.76866
1915.39	6.92385
1918.37	7.28895
1921.34	8.02703
1924.32	7.21575
1927.29	7.04304
1930.26	6.91946
1933.23	7.13342
1936.2	7.4209
1939.17	7.8671
1942.14	8.14834
1945.11	8.80211
1948.07	8.83464
1951.04	9.22354
1954	9.60959
1956.96	9.49623
1959.93	8.41536
1962.89	7.63118
1965.85	7.40368
1968.8	5.95144
1971.76	6.13894
1974.72	6.25095
1977.67	7.31856
1980.63	8.23884
1983.58	8.45063
1986.53	9.38328
1989.48	10.0234
1992.43	10.4387
1995.38	10.244
1998.32	10.8814
2001.27	11.4857
2004.22	12.1426
2007.16	12.8988
2010.1	14.3344
2013.04	15.0423
2015.98	14.9334
2018.92	13.8108
2021.86	14.6764
2024.8	15.5807
2027.74	15.5338
2030.67	15.2006
2033.61	14.4431
2036.54	14.41
2039.47	14.2228
2042.4	14.9633
2045.33	14.8958
2048.26	16.2012
2051.19	16.4554
2054.12	16.5753
2057.04	17.5667
2059.97	18.3005
2062.89	18.7084
2065.81	18.621
2068.73	18.7416
2071.65	19.0375
2074.57	18.7946
2077.49	18.4393
2080.41	18.3518
2083.32	17.5876
2086.24	17.482
2089.15	17.5292
2092.07	18.3283
2094.98	19.4269
2097.89	19.3736
2100.8	18.842
2103.71	18.2332
2106.61	18.912
2109.52	19.7512
2112.43	20.6153
2115.33	21.0811
2118.23	21.033
2121.13	21.7816
2124.04	22.7475
2126.94	23.8559
2129.83	23.9971
2132.73	24.348
2135.63	25.0631
2138.53	25.313
2141.42	25.3526
2144.31	25.4684
2147.21	26.7507
2150.1	28.0008
2152.99	28.8018
2155.88	29.4818
2158.77	30.8086
2161.65	31.3156
2164.54	32.291
2167.43	32.5943
2170.31	33.6858
2173.19	34.1156
2176.07	34.4191
2178.96	34.5295
2181.84	34.5265
2184.72	33.7145
2187.59	32.6548
2190.47	32.405
2193.35	32.07
2196.22	31.393
2199.09	30.0609
2201.97	29.1682
2204.84	28.3868
2207.71	27.5517
2210.58	25.4473
2213.45	23.5247
2216.31	23.1764
2219.18	23.256
2222.05	22.0879
2224.91	22.4695
2227.78	21.2512
2230.64	20.9666
2233.5	19.3145
2236.36	18.9144
2239.22	17.7648
2242.08	17.6219
2244.93	16.7923
2247.79	16.9741
2250.64	16.3149
2253.5	15.7798
2256.35	15.393
2259.2	15.2842
2262.05	15.3811
2264.9	14.7841
2267.75	14.4014
2270.6	14.5396
2273.45	14.0527
2276.29	14.0395
2279.14	13.6983
2281.98	13.5017
2284.82	14.6717
2287.66	15.0205
2290.5	15.1681
2293.34	14.0978
2296.18	13.9241
2299.02	13.9093
2301.86	14.1331
2304.69	14.5158
2307.53	14.788
2310.36	15.5949
2313.19	16.0616
2316.02	15.5905
2318.85	15.1757
2321.68	14.5595
2324.51	13.436
2327.34	11.8787
2330.16	12.0166
2332.99	11.3894
2335.81	10.1301
2338.64	8.74587
2341.46	7.86287
2344.28	8.10722
2347.1	7.60625
2349.92	5.63912
2352.74	4.88826
2355.55	3.5928
2358.37	2.92635
2361.19	2.56561
2364	2.51599
2366.81	3.1717
2369.62	3.71055
2372.44	2.87766
2375.24	2.28519
2378.05	3.4989
2380.86	3.84519
2383.67	3.99325
2386.47	5.238
2389.28	5.12837
2392.08	5.46793
2394.89	4.92421
2397.69	6.29011
2400.49	6.91348
2403.29	6.85859
2406.09	6.42285
2408.88	7.27449
2411.68	7.93526
2414.48	7.54027
2417.27	7.52574
2420.06	8.13236
2422.86	8.14164
2425.65	7.77134
2428.44	8.3234
2431.23	8.59827
2434.02	7.99392
2436.81	7.94771
2439.59	7.93947
2442.38	7.92422
2445.16	8.12036
2447.95	8.93395
2450.73	8.33287
2453.51	8.25307
2456.29	7.61761
2459.07	6.49624
2461.85	6.07498
2464.63	4.78382
2467.4	4.50952
2470.18	3.50939
2472.95	2.17646
2475.73	2.28928
2478.5	1.5456
2481.27	0.66328
2484.04	1.11918
2486.81	1.41898
2489.58	0.800049
2492.35	0.453517
2495.12	0.990246
2497.88	0.829492
2500.65	0.459501
2503.41	0.423397
2506.17	0.988643
2508.94	0.803363
2511.7	1.00098
2514.46	0.740287
2517.22	0.89016
2519.97	-0.0827513
2522.73	0.568509
2525.49	1.83722
2528.24	1.63661
2530.99	0.854806
2533.75	0.670197
2536.5	1.50375
2539.25	1.10289
2542	1.90718
2544.75	2.48902
2547.5	2.86447
2550.24	3.27282
2552.99	3.54769
2555.74	3.39502
2558.48	3.35784
2561.22	3.22956
2563.96	2.64429
2566.71	2.28623
2569.45	2.37669
2572.18	3.44182
2574.92	3.62939
2577.66	3.56765
2580.4	2.96749
2583.13	3.35159
2585.87	2.78489
2588.6	3.00243
2591.33	4.17103
2594.06	3.74247
2596.79	2.38513
2599.52	2.33455
2602.25	2.4927
2604.98	1.97895
2607.71	0.916389
2610.43	1.45973
2613.16	0.481275
2615.88	-0.837026
2618.6	-1.18483
2621.32	-0.344995
2624.04	-1.07104
2626.76	-0.673711
2629.48	-1.02367
2632.2	-0.576921
2634.92	0.439004
2637.63	0.41343
2640.35	0.907908
2643.06	0.968779
2645.77	0.433158
2648.49	0.45363
2651.2	1.07975
2653.91	0.855279
2656.62	1.43898
2659.33	1.90997
2662.03	2.47847
2664.74	2.04283
2667.44	1.96992
2670.15	2.05989
2672.85	1.93513
2675.55	2.04764
2678.26	2.55175
2680.96	2.31138
2683.66	3.36917
2686.35	3.72641
2689.05	3.27509
2691.75	3.25938
2694.44	4.05405
2697.14	3.67961
2699.83	3.79167
2702.52	3.64995
2705.22	4.50033
2707.91	4.96464
2710.6	5.46231
2713.29	5.86626
2715.97	6.4852
2718.66	6.91448
2721.35	7.40458
2724.03	8.25109
2726.72	10.15
2729.4	9.9521
2732.08	10.7841
2734.76	11.6349
2737.44	11.5155
2740.12	10.7313
2742.8	10.1828
2745.48	9.44739
2748.16	8.71016
2750.83	7.51163
2753.51	7.0822
2756.18	7.52487
2758.85	6.7538
2761.53	6.30787
2764.2	5.67045
2766.87	5.28929
2769.54	5.80917
2772.2	5.06854
2774.87	4.52787
2777.54	3.99038
2780.2	3.37496
2782.87	2.83291
2785.53	2.59125
2788.19	3.31253
2790.85	3.38661
2793.51	2.8159
2796.17	2.75401
2798.83	2.58191
2801.49	2.03428
2804.15	1.33238
2806.8	1.59344
2809.46	1.60276
2812.11	2.10354
2814.76	3.32718
2817.42	4.4441
2820.07	6.03506
2822.72	8.24454
2825.37	10.6503
2828.02	13.8059
2830.66	18.0402
2833.31	21.946
2835.96	25.8487
2838.6	30.9146
2841.24	36.1246
2843.89	41.2913
2846.53	47.9044
2849.17	54.6268
2851.81	62.4089
2854.45	70.0231
2857.09	78.1303
2859.72	85.1817
2862.36	93.1694
2865	100.071
2867.63	106.053
2870.26	111.633
2872.9	116.124
2875.53	120.949
2878.16	124.14
2880.79	127.373
2883.42	130.73
2886.05	134.716
2888.67	137.326
2891.3	140.533
2893.92	144.29
2896.55	149.391
2899.17	153.517
2901.79	158.868
2904.42	166.592
2907.04	174.152
2909.66	182.933
2912.27	192.853
2914.89	202.558
2917.51	212.327
2920.13	220.182
2922.74	227.101
2925.35	233.303
2927.97	236.933
2930.58	238.748
2933.19	239.053
2935.8	237.751
2938.41	235.515
2941.02	231.281
2943.63	225.36
2946.24	219.468
2948.84	212.079
2951.45	204.417
2954.05	196.617
2956.65	189.503
2959.26	182.716
2961.86	174.996
2964.46	167.823
2967.06	162.114
2969.66	156.647
2972.25	150.318
2974.85	144.68
2977.45	138.504
2980.04	131.311
2982.64	124.383
2985.23	116.3
2987.82	108.18
2990.41	99.734
2993	91.563
2995.59	83.6499
2998.18	75.7867
3000.77	69.1854
3003.36	61.463
3005.94	54.9185
3008.53	48.985
3011.11	44.2277
3013.69	40.0077
3016.28	36.7642
3018.86	34.4375
3021.44	31.3124
3024.02	29.2151
3026.6	27.7165
3029.18	26.9809
3031.75	26.6217
3034.33	26.4719
3036.9	26.4546
3039.48	27.013
3042.05	27.1778
3044.62	28.264
3047.19	28.9863
3049.77	28.9909
3052.34	29.2429
3054.9	29.1045
3057.47	28.6757
3060.04	28.5916
3062.61	27.6895
3065.17	25.5704
3067.74	24.0004
3070.3	22.8598
3072.86	21.4677
3075.42	19.8758
3077.99	18.2588
3080.54	15.5073
3083.1	13.2295
3085.66	11.0261
3088.22	9.26808
3090.78	6.91768
3093.33	5.23169
3095.89	3.82391
3098.44	3.69195
3100.99	3.49194
3103.54	3.12538
3106.1	3.4239
3108.65	3.57875
3111.2	3.87651
3113.74	3.79219
3116.29	3.82619
3118.84	3.8745
3121.38	3.92472
3123.93	3.73586
3126.47	3.06083
3129.01	4.01706
3131.56	3.72361
3134.1	4.47878
3136.64	4.05278
3139.18	3.08982
3141.72	1.77245
3144.26	0.664965
3146.79	-0.665998
3149.33	-1.91776