File: data/Raman/poly_smoothed/Thy_00_07_37_1x_45s_532 nm_x100_100%_600 gr_mm_01.txt
#Acq. time (s)=	45
#Accumulations=	2
#Range (cm-¹)=	200...3150
#Windows=	2
#Auto scanning=	Off
#Autofocus=	Off
#Macrospot=	Off
#AutoExposure=	Off
#Spike filter=	Multiple accum.
#Delay time (s)=	0
#Binning=	1
#Readout mode=	Signal
#DeNoise=	Off
#ICS correction=	On
#Dark correction=	Off
#Inst. Process=	Off
#Detector Gain=	Best Dynamic Range
#Detector ADC=	20 kHz
#Detector temperature (°C)=	-69.85
#Instrument=	LabRAM HR Evol
#Detector=	Synapse
#Objective=	x100
#Grating=	600 gr/mm
#ND Filter=	100%
#Laser (nm)=	532
#Hole=	100.021
#Range=	Auto
#Laser Pol.=	No
#Raman. Pol.=	No
#Laser Pol. (°)=	-0.0007625
#Raman Pol. (°)=	89.9995
#Collection=	Microscope
#StageXY=	Marzhauser
#StageZ=	Marzhauser
#X (µm)=	8969.5
#Y (µm)=	-3063.1
#Z (µm)=	-54.85
#Full time(mm:ss)=	3:19
#Project=
#Sample=
#Site=
#Title=	Thy_00_07_37_2x_45s_532 nm_x100_100%_600 gr_mm
#Remark=
#Date=	28.06.2022 12:50
#Acquired=	28.06.2022 12:50:06
#Base:Fit=	10.08.2022 10:07:56
#Base:Sub=	10.08.2022 10:08:40
#Filter:Polynom=	16.08.2022 10:26:06
#AxisType[0]=Intens
#AxisUnit[0]=Cnt
#AxisType[1]=Spectr
#AxisUnit[1]=1/cm
200.407	4.79973
204.035	7.44573
207.665	7.50726
211.291	7.10815
214.916	6.84998
218.541	7.47967
222.163	6.00057
225.785	4.87275
229.404	4.36233
233.022	4.17157
236.638	4.69766
240.255	4.37864
243.868	3.46552
247.48	3.1201
251.091	2.0118
254.702	3.15269
258.31	4.59016
261.916	5.22842
265.521	6.1041
269.125	7.0628
272.727	6.05632
276.328	5.57871
279.927	6.83738
283.525	7.94049
287.121	7.87097
290.716	8.00674
294.31	7.40014
297.9	7.42509
301.491	8.34705
305.081	8.97508
308.669	11.3107
312.256	11.2873
315.839	12.502
319.423	13.1158
323.006	14.6685
326.585	15.7701
330.165	16.1747
333.741	17.66
337.318	17.9888
340.894	18.5587
344.466	19.783
348.039	19.6249
351.608	17.5671
355.176	15.5746
358.745	14.2204
362.31	12.7481
365.876	11.0542
369.439	10.2525
373	8.22942
376.56	6.28852
380.12	5.38107
383.677	3.21096
387.233	2.71067
390.787	1.89178
394.34	3.61205
397.894	3.2711
401.444	3.15103
404.993	4.9563
408.54	6.99549
412.086	7.75057
415.631	10.0312
419.174	11.8014
422.716	12.6803
426.257	11.9495
429.794	12.8818
433.332	12.3728
436.868	11.312
440.403	12.2159
443.937	13.5932
447.468	15.2171
450.999	17.1226
454.528	17.2063
458.057	19.4554
461.582	21.2696
465.107	21.7785
468.629	22.1747
472.152	24.2199
475.672	25.313
479.192	28.4912
482.709	29.3862
486.226	29.9909
489.74	32.1668
493.255	33.8604
496.767	34.7385
500.277	34.8098
503.788	35.7232
507.295	34.4193
510.801	32.5779
514.308	30.9368
517.811	28.9777
521.313	27.1316
524.814	26.1974
528.313	25.0037
531.811	23.7994
535.308	22.3435
538.803	20.9216
542.297	18.7474
545.789	18.7314
549.281	16.695
552.771	15.996
556.259	13.6804
559.747	13.5525
563.233	12.4498
566.717	11.2818
570.2	11.3536
573.68	11.0414
577.161	9.68068
580.64	8.41647
584.118	8.90027
587.593	8.64875
591.068	8.04231
594.54	7.50387
598.013	6.11848
601.484	6.52493
604.952	5.23393
608.421	4.57791
611.886	5.04135
615.35	5.79595
618.815	5.77461
622.276	5.4244
625.738	5.21571
629.197	5.10226
632.655	6.23749
636.113	5.1596
639.568	5.03046
643.021	5.25578
646.473	7.10174
649.924	8.6302
653.376	9.22173
656.824	8.41595
660.271	9.75743
663.716	11.1044
667.161	12.9239
670.604	14.8907
674.045	16.2121
677.486	17.0749
680.925	17.437
684.361	18.0795
687.797	20.9024
691.232	22.547
694.666	23.9518
698.099	27.4575
701.528	27.8775
704.958	29.0207
708.387	30.3077
711.814	31.717
715.238	32.367
718.663	34.5095
722.084	35.3628
725.506	37.8515
728.925	39.3812
732.345	42.0011
735.761	41.6379
739.178	42.8186
742.592	45.5358
746.006	49.188
749.417	50.512
752.827	53.8751
756.236	55.8999
759.645	57.1744
763.051	60.024
766.456	61.4582
769.859	63.8688
773.261	65.8142
776.664	68.3683
780.064	67.4654
783.462	68.3134
786.859	67.6469
790.255	68.2487
793.649	68.1252
797.042	66.8336
800.434	67.6852
803.823	66.5898
807.212	65.6367
810.6	64.573
813.987	64.1019
817.372	64.3404
820.754	64.5179
824.137	66.8636
827.519	67.973
830.897	69.4619
834.276	68.6565
837.654	70.1807
841.029	69.2465
844.404	69.5897
847.776	67.0961
851.149	64.4425
854.519	62.0725
857.889	59.4059
861.256	56.0085
864.622	53.6755
867.988	49.6445
871.351	44.634
874.713	42.1427
878.074	38.1325
881.435	34.9888
884.794	33.1925
888.15	29.9713
891.506	29.5006
894.861	30.0991
898.214	30.1614
901.566	33.1797
904.916	35.2172
908.266	35.7003
911.614	35.1482
914.961	36.3193
918.306	38.5813
921.651	40.8741
924.994	39.9927
928.336	41.0855
931.674	39.9991
935.014	40.2475
938.352	40.9564
941.687	42.3832
945.022	41.4468
948.357	40.7805
951.688	40.3804
955.02	39.846
958.348	39.0096
961.678	35.5492
965.004	34.59
968.331	36.4404
971.655	36.9221
974.979	40.0153
978.3	40.1916
981.62	40.5666
984.941	39.7411
988.259	37.149
991.575	36.8629
994.89	35.3183
998.204	34.7113
1001.52	34.7811
1004.83	33.9258
1008.14	34.3923
1011.45	34.3167
1014.76	34.6569
1018.06	33.6445
1021.37	34.2953
1024.67	33.436
1027.97	31.872
1031.27	31.2593
1034.57	28.5986
1037.87	26.4455
1041.17	24.8215
1044.47	25.0024
1047.76	26.805
1051.06	27.5951
1054.35	27.1773
1057.64	24.0837
1060.93	22.3189
1064.22	22.4369
1067.5	21.5535
1070.79	21.4942
1074.08	20.1688
1077.36	17.9496
1080.64	18.7037
1083.92	17.8374
1087.2	18.8345
1090.48	19.7873
1093.76	22.0768
1097.03	23.7551
1100.31	24.4959
1103.58	25.708
1106.85	26.5711
1110.12	27.1306
1113.39	26.2038
1116.66	25.484
1119.93	24.9454
1123.19	25.3215
1126.46	23.6174
1129.72	22.8966
1132.98	22.4939
1136.24	21.2407
1139.5	21.1652
1142.76	21.503
1146.01	20.0792
1149.27	18.7646
1152.53	16.9758
1155.78	13.5476
1159.03	11.1527
1162.28	8.94944
1165.53	7.74879
1168.78	8.453
1172.02	9.75137
1175.27	10.5509
1178.51	8.77041
1181.76	9.87807
1185	10.3415
1188.24	10.0389
1191.48	9.89275
1194.71	12.0402
1197.95	13.9935
1201.19	17.8984
1204.42	19.4835
1207.65	22.7414
1210.88	28.6559
1214.12	33.827
1217.35	38.9811
1220.57	43.9314
1223.8	49.2978
1227.03	53.6778
1230.25	56.3455
1233.47	58.2568
1236.69	59.5418
1239.92	62.5342
1243.13	63.585
1246.35	64.3433
1249.57	64.215
1252.78	62.9153
1256	63.6255
1259.21	63.62
1262.42	62.0745
1265.63	60.0468
1268.84	59.1802
1272.05	59.0355
1275.26	59.0249
1278.46	58.9165
1281.67	58.3521
1284.87	59.0413
1288.07	62.4969
1291.27	65.3543
1294.47	66.769
1297.67	71.3257
1300.87	74.0353
1304.06	78.1758
1307.26	80.7309
1310.45	86.2835
1313.64	91.7534
1316.83	97.1528
1320.02	99.02
1323.21	100.717
1326.4	101.952
1329.59	101.157
1332.77	103.106
1335.95	102.099
1339.14	99.4631
1342.32	97.5371
1345.5	93.6644
1348.67	90.6547
1351.85	86.4496
1355.03	82.878
1358.2	79.1059
1361.38	75.2194
1364.55	70.8019
1367.72	66.7109
1370.89	62.9546
1374.06	60.8235
1377.23	59.0133
1380.39	57.1702
1383.56	57.5095
1386.72	57.7259
1389.89	58.2764
1393.05	57.9396
1396.21	57.5649
1399.37	55.7111
1402.52	56.1177
1405.68	54.9793
1408.84	55.4898
1411.99	57.6714
1415.15	60.2657
1418.3	63.6262
1421.45	67.9154
1424.6	71.9534
1427.75	78.3146
1430.89	85.4937
1434.04	92.4173
1437.18	98.2521
1440.33	101.993
1443.47	106.086
1446.61	110.356
1449.75	110.624
1452.89	111.718
1456.03	110.525
1459.16	108.08
1462.3	104.568
1465.43	100.784
1468.56	93.4927
1471.7	85.938
1474.83	79.4357
1477.96	69.8496
1481.08	60.3149
1484.21	52.3493
1487.34	45.5454
1490.46	40.3354
1493.58	35.5026
1496.71	30.8923
1499.83	27.7113
1502.95	24.3845
1506.07	22.0637
1509.18	21.174
1512.3	20.6063
1515.41	19.7496
1518.53	20.279
1521.64	20.5754
1524.75	21.7374
1527.86	22.221
1530.97	23.8355
1534.08	26.4048
1537.19	29.5197
1540.29	34.0004
1543.4	37.4509
1546.5	40.8495
1549.6	45.6856
1552.7	51.1841
1555.8	55.5412
1558.9	60.6666
1562	65.6792
1565.09	69.9089
1568.19	73.2432
1571.28	75.6404
1574.37	79.0095
1577.47	81.554
1580.56	83.0985
1583.64	85.0142
1586.73	87.8522
1589.82	89.3376
1592.9	89.6081
1595.99	88.7888
1599.07	87.8872
1602.15	85.98
1605.23	83.8116
1608.31	83.3398
1611.39	82.366
1614.47	82.2074
1617.55	80.5073
1620.62	79.6031
1623.7	80.4601
1626.77	82.575
1629.84	84.8977
1632.91	85.5596
1635.98	88.1079
1639.05	91.1052
1642.11	93.9737
1645.18	95.7509
1648.24	99.0908
1651.31	100.734
1654.37	101.412
1657.43	103.195
1660.49	104.63
1663.55	103.494
1666.61	100.751
1669.66	96.754
1672.72	90.9156
1675.77	86.1728
1678.83	79.8229
1681.88	73.3895
1684.93	67.4021
1687.98	60.2162
1691.03	53.2698
1694.07	46.7291
1697.12	41.439
1700.17	37.5382
1703.21	33.927
1706.25	31.1911
1709.29	28.3596
1712.33	26.108
1715.37	24.1391
1718.41	22.9016
1721.45	20.0267
1724.49	19.031
1727.52	17.6613
1730.55	17.0146
1733.59	17.3648
1736.62	16.5553
1739.65	15.8543
1742.68	13.7292
1745.7	12.3404
1748.73	11.0788
1751.76	9.56559
1754.78	7.7666
1757.8	7.19356
1760.83	5.88948
1763.85	4.30168
1766.87	4.87665
1769.89	4.79783
1772.9	4.86333
1775.92	4.86503
1778.94	5.17838
1781.95	5.44118
1784.96	4.61684
1787.97	4.30338
1790.99	4.34168
1794	3.47149
1797	2.72337
1800.01	3.35725
1803.02	3.71042
1806.02	4.43111
1809.03	4.78541
1812.03	5.12482
1815.03	3.88653
1818.03	3.4445
1821.03	2.63394
1824.03	1.85361
1827.03	1.51139
1830.02	1.65958
1833.02	1.71119
1836.01	0.899854
1839.01	1.26424
1842	0.640926
1844.99	1.03587
1847.98	1.17841
1850.97	1.67243
1853.95	1.68162
1856.94	0.969732
1859.93	0.929201
1862.91	1.22721
1865.89	0.81206
1868.87	1.56069
1871.85	2.97596
1874.83	3.69147
1877.81	3.93734
1880.79	4.06105
1882.52	3.53419
1885.51	3.58488
1888.5	3.4705
1891.49	4.12145
1894.47	3.10325
1897.46	3.10906
1900.44	2.06686
1903.42	1.94757
1906.4	1.64571
1909.38	2.36128
1912.36	3.45319
1915.34	4.09434
1918.32	4.43888
1921.29	3.51498
1924.27	3.36202
1927.24	3.52534
1930.21	3.53916
1933.18	3.06225
1936.15	2.72705
1939.12	3.24255
1942.09	4.24036
1945.06	3.65223
1948.02	3.2402
1950.99	3.83885
1953.95	3.26519
1956.91	4.11288
1959.88	4.05593
1962.84	3.18397
1965.8	2.96054
1968.75	1.67321
1971.71	1.52401
1974.67	2.41224
1977.62	3.71213
1980.58	5.22312
1983.53	5.39998
1986.48	5.30962
1989.43	6.0653
1992.38	5.79868
1995.33	5.62167
1998.27	5.22982
2001.22	4.78788
2004.16	4.25744
2007.11	3.47084
2010.05	4.22487
2012.99	4.73731
2015.93	3.91138
2018.87	4.33362
2021.81	4.72617
2024.75	4.33054
2027.69	3.15239
2030.62	3.06781
2033.56	2.93761
2036.49	2.46823
2039.42	2.24599
2042.35	1.98037
2045.28	2.46348
2048.21	2.80721
2051.14	3.00151
2054.07	2.99515
2056.99	3.05528
2059.92	3.63183
2062.84	4.73614
2065.76	3.98332
2068.68	3.58896
2071.6	4.00794
2074.52	4.76751
2077.44	5.07556
2080.36	4.77831
2083.27	6.08501
2086.19	4.87077
2089.1	5.10049
2092.02	3.99787
2094.93	2.94011
2097.84	2.88242
2100.75	2.58012
2103.66	3.3949
2106.56	3.11949
2109.47	2.40655
2112.38	2.21536
2115.28	2.49372
2118.18	3.06643
2121.09	2.0104
2123.99	1.96948
2126.89	2.54284
2129.79	3.15663
2132.68	3.11031
2135.58	2.47889
2138.48	2.62336
2141.37	2.44532
2144.27	2.65124
2147.16	2.97227
2150.05	3.46735
2152.94	2.60314
2155.83	2.88419
2158.72	2.22402
2161.6	3.16085
2164.49	2.88431
2167.38	3.49458
2170.26	4.19915
2173.14	4.59131
2176.03	5.62755
2178.91	5.68631
2181.79	5.94673
2184.67	6.07722
2187.54	6.12664
2190.42	5.23198
2193.3	4.76871
2196.17	5.21231
2199.05	4.98121
2201.92	4.74462
2204.79	3.40135
2207.66	2.72988
2210.53	3.3437
2213.4	2.59801
2216.27	2.7112
2219.13	3.27579
2222	2.81165
2224.86	3.82358
2227.72	3.38838
2230.59	3.72281
2233.45	4.84862
2236.31	5.85624
2239.17	6.32873
2242.03	7.69338
2244.88	8.13491
2247.74	9.0698
2250.59	9.44185
2253.45	9.08378
2256.3	9.20216
2259.15	8.13402
2262	8.79658
2264.85	7.78553
2267.7	6.98003
2270.55	6.8682
2273.4	5.65371
2276.24	5.82491
2279.09	5.59758
2281.93	5.89835
2284.77	4.91829
2287.62	4.54978
2290.46	4.89142
2293.3	3.38753
2296.13	3.30588
2298.97	3.76523
2301.81	5.66058
2304.64	8.03663
2307.48	8.1178
2310.31	8.90319
2313.14	10.0914
2315.98	10.2918
2318.81	9.65159
2321.64	9.64607
2324.46	8.72865
2327.29	7.90482
2330.12	8.25723
2332.94	7.6521
2335.77	6.03718
2338.59	5.28498
2341.41	3.95247
2344.23	3.71459
2347.05	3.22413
2349.87	2.63016
2352.69	1.28238
2355.51	0.737568
2358.32	1.04299
2361.14	1.12145
2363.95	1.67839
2366.76	3.51936
2369.58	4.33461
2372.39	5.036
2375.2	5.49287
2378	4.65089
2380.81	4.9489
2383.62	4.52508
2386.43	4.55965
2389.23	4.47758
2392.03	3.43003
2394.84	3.61331
2397.64	3.61656
2400.44	3.92898
2403.24	3.94875
2406.04	4.52734
2408.84	5.28438
2411.63	6.62987
2414.43	8.29861
2417.22	8.45535
2420.02	9.76739
2422.81	11.0121
2425.6	11.6316
2428.39	12.0914
2431.18	13.2891
2433.97	12.956
2436.76	11.991
2439.54	12.2348
2442.33	10.835
2445.12	9.73739
2447.9	8.82031
2450.68	7.40666
2453.46	6.00654
2456.24	4.76395
2459.02	3.9245
2461.8	2.60992
2464.58	2.24578
2467.36	1.40343
2470.13	1.53371
2472.91	1.10096
2475.68	0.239772
2478.45	0.112027
2481.23	1.01515
2484	0.91496
2486.77	1.63587
2489.54	1.87486
2492.3	3.06916
2495.07	3.3788
2497.84	3.50885
2500.6	3.34963
2503.36	3.81079
2506.13	4.5193
2508.89	4.70633
2511.65	4.57418
2514.41	5.34773
2517.17	5.57545
2519.93	4.60804
2522.68	4.45711
2525.44	4.12993
2528.19	3.43284
2530.95	2.37813
2533.7	2.15469
2536.45	1.74917
2539.2	0.585718
2541.95	0.72636
2544.7	1.30074
2547.45	2.15521
2550.2	2.91786
2552.94	2.93039
2555.69	2.83918
2558.43	3.69413
2561.18	4.20972
2563.92	4.57669
2566.66	5.36644
2569.4	6.16231
2572.14	6.76412
2574.88	6.69042
2577.61	6.76731
2580.35	7.478
2583.09	7.46632
2585.82	6.61469
2588.55	6.55026
2591.29	6.45299
2594.02	5.48779
2596.75	5.20641
2599.48	5.18644
2602.21	4.79
2604.93	3.18453
2607.66	3.3742
2610.39	3.46497
2613.11	4.24964
2615.83	4.49579
2618.56	4.49868
2621.28	4.65995
2624	5.83427
2626.72	6.6944
2629.44	6.78302
2632.15	7.66237
2634.87	8.34357
2637.59	8.78967
2640.3	8.47605
2643.02	9.07486
2645.73	9.21755
2648.44	9.13057
2651.15	9.39957
2653.86	9.0696
2656.57	9.24387
2659.28	9.00713
2661.99	8.3855
2664.69	8.41538
2667.4	7.4913
2670.1	7.04521
2672.81	6.84284
2675.51	7.31759
2678.21	6.71177
2680.91	6.07538
2683.61	5.42092
2686.31	5.33388
2689	5.57783
2691.7	5.8059
2694.4	7.18757
2697.09	7.81272
2699.79	8.72528
2702.48	9.54935
2705.17	10.7225
2707.86	10.6023
2710.55	11.654
2713.24	11.6176
2715.93	13.0098
2718.62	13.3909
2721.3	13.9613
2723.99	14.3511
2726.67	15.7529
2729.35	15.6157
2732.04	16.8556
2734.72	16.6969
2737.4	16.8918
2740.08	16.1572
2742.76	16.3376
2745.43	15.678
2748.11	15.3076
2750.79	14.8899
2753.46	14.4589
2756.14	14.3912
2758.81	14.2268
2761.48	14.3559
2764.15	13.0083
2766.82	12.795
2769.49	11.9311
2772.16	10.6754
2774.82	9.88408
2777.49	8.59644
2780.16	8.54562
2782.82	7.96837
2785.48	5.9743
2788.15	4.64905
2790.81	4.73696
2793.47	3.72521
2796.13	2.41822
2798.79	2.53529
2801.44	1.28736
2804.1	1.83044
2806.76	0.94689
2809.41	1.1911
2812.07	0.553501
2814.72	0.799796
2817.37	1.86713
2820.02	3.97473
2822.67	6.67062
2825.32	10.2952
2827.97	14.5816
2830.62	18.7109
2833.26	23.916
2835.91	28.853
2838.56	35.1034
2841.2	42.6741
2843.84	51.8868
2846.48	62.1629
2849.12	72.5455
2851.77	85.386
2854.4	99.1938
2857.04	112.623
2859.68	126.058
2862.32	140.276
2864.95	152.308
2867.59	164.631
2870.22	176.334
2872.85	185.878
2875.48	195.752
2878.11	204.082
2880.74	212.888
2883.37	221.185
2886	228.402
2888.63	235.294
2891.25	241.868
2893.88	247.944
2896.5	253.8
2899.13	260.955
2901.75	268.127
2904.37	279.386
2906.99	291.843
2909.61	306.022
2912.23	321.066
2914.85	335.632
2917.46	348.5
2920.08	360.308
2922.7	369.305
2925.31	376.512
2927.92	381.235
2930.54	382.168
2933.15	382.116
2935.76	378.449
2938.37	372.367
2940.98	364.722
2943.58	355.541
2946.19	344.028
2948.8	331.612
2951.4	316.904
2954.01	302.47
2956.61	287.483
2959.21	273.065
2961.81	259.078
2964.41	246.66
2967.01	235.381
2969.61	224.449
2972.21	214.728
2974.81	203.894
2977.4	193.616
2980	182.233
2982.59	170.002
2985.18	157.313
2987.78	144.683
2990.37	131.703
2992.96	118.768
2995.55	106.128
2998.14	94.5824
3000.73	83.253
3003.31	71.8975
3005.9	62.139
3008.48	52.8404
3011.07	44.5454
3013.65	36.6692
3016.23	30.5935
3018.81	24.7164
3021.4	19.93
3023.97	16.1354
3026.55	13.6991
3029.13	11.3533
3031.71	9.94545
3034.28	9.81018
3036.86	9.98492
3039.43	11.7603
3042.01	13.5627
3044.58	15.1751
3047.15	16.4327
3049.72	18.7407
3052.29	20.5223
3054.86	21.9888
3057.43	23.1676
3060	23.8228
3062.56	24.2002
3065.13	23.4611
3067.69	22.5629
3070.26	22.2818
3072.82	20.8276
3075.38	18.6052
3077.94	16.1964
3080.5	13.7598
3083.06	10.3331
3085.62	7.24469
3088.18	5.04028
3090.73	3.08384
3093.29	1.25642
3095.84	0.139886
3098.4	-0.236663
3100.95	0.00205349
3103.5	0.944726
3106.05	1.89296
3108.6	2.87855
3111.15	4.19559
3113.7	5.02128
3116.25	6.93642
3118.79	7.84627
3121.34	8.59354
3123.88	10.7756
3126.43	12.4865
3128.97	14.3706
3131.51	17.06
3134.06	19.7778
3136.6	21.7449
3139.14	23.4807
3141.67	25.6328
3144.21	28.0152
3146.75	31.5168
3149.29	34.2535