File: data/Raman/poly_smoothed/Thy_00_07_5_1x_45s_532 nm_x100_100%_600 gr_mm_02_0.txt
#Acq. time (s)=	45
#Accumulations=	2
#Range (cm-¹)=	200...3150
#Windows=	2
#Auto scanning=	Off
#Autofocus=	Off
#Macrospot=	Off
#AutoExposure=	Off
#Spike filter=	Multiple accum.
#Delay time (s)=	0
#Binning=	1
#Readout mode=	Signal
#DeNoise=	Off
#ICS correction=	On
#Dark correction=	Off
#Inst. Process=	Off
#Detector Gain=	Best Dynamic Range
#Detector ADC=	20 kHz
#Detector temperature (°C)=	-69.85
#Instrument=	LabRAM HR Evol
#Detector=	Synapse
#Objective=	x100
#Grating=	600 gr/mm
#ND Filter=	100%
#Laser (nm)=	532
#Hole=	100.021
#Range=	Auto
#Laser Pol.=	No
#Raman. Pol.=	No
#Laser Pol. (°)=	-0.0007625
#Raman Pol. (°)=	89.9995
#Collection=	Microscope
#StageXY=	Marzhauser
#StageZ=	Marzhauser
#X (µm)=	8992.4
#Y (µm)=	-3100.5
#Z (µm)=	-55.6
#Full time(mm:ss)=	3:18
#Project=
#Sample=
#Site=
#Title=	Thy_00_07_5_2x_45s_532 nm_x100_100%_600 gr_mm
#Remark=
#Date=	28.06.2022 10:30
#Acquired=	28.06.2022 10:30:50
#Base:Fit=	10.08.2022 10:07:56
#Base:Sub=	10.08.2022 10:08:40
#Filter:Polynom=	16.08.2022 10:26:06
#AxisType[0]=Intens
#AxisUnit[0]=Cnt
#AxisType[1]=Spectr
#AxisUnit[1]=1/cm
200.407	33.2514
204.035	29.034
207.665	27.9633
211.291	27.6507
214.916	26.5696
218.541	24.3815
222.163	20.619
225.785	18.2899
229.404	17.067
233.022	16.6486
236.638	15.2812
240.255	15.0671
243.868	14.5323
247.48	14.5245
251.091	14.2251
254.702	13.4272
258.31	13.5001
261.916	12.2669
265.521	14.3902
269.125	12.331
272.727	10.8201
276.328	9.56192
279.927	8.55828
283.525	7.79805
287.121	7.75214
290.716	8.61198
294.31	10.2644
297.9	9.06648
301.491	9.50118
305.081	9.74115
308.669	9.39434
312.256	11.4017
315.839	14.635
319.423	16.0409
323.006	17.3219
326.585	19.0163
330.165	18.9754
333.741	19.0621
337.318	18.2616
340.894	16.5631
344.466	15.4008
348.039	13.9818
351.608	12.7269
355.176	13.0248
358.745	12.1172
362.31	11.6558
365.876	13.4301
369.439	15.0212
373	15.6462
376.56	17.7861
380.12	18.948
383.677	19.7309
387.233	19.3665
390.787	20.1025
394.34	21.1601
397.894	21.5518
401.444	21.8787
404.993	21.6705
408.54	20.9546
412.086	20.5391
415.631	18.2396
419.174	16.608
422.716	14.2722
426.257	11.0306
429.794	8.83175
433.332	6.14647
436.868	4.91234
440.403	5.26914
443.937	7.54884
447.468	9.45012
450.999	13.1098
454.528	17.5357
458.057	19.7184
461.582	23.5999
465.107	26.2398
468.629	29.2848
472.152	30.9765
475.672	31.421
479.192	35.4123
482.709	37.6957
486.226	41.8334
489.74	45.5009
493.255	49.1492
496.767	50.803
500.277	51.559
503.788	50.5954
507.295	49.5847
510.801	45.6911
514.308	41.3375
517.811	38.2931
521.313	35.6415
524.814	34.7832
528.313	33.8611
531.811	31.9153
535.308	29.7985
538.803	28.104
542.297	26.1706
545.789	22.8687
549.281	20.793
552.771	18.432
556.259	18.4322
559.747	16.5985
563.233	17.4547
566.717	17.7646
570.2	17.6919
573.68	19.7734
577.161	20.1485
580.64	19.3609
584.118	19.3108
587.593	18.2795
591.068	16.704
594.54	15.5026
598.013	13.143
601.484	12.2052
604.952	11.1176
608.421	10.289
611.886	8.11217
615.35	5.18777
618.815	4.58227
622.276	4.42572
625.738	3.77775
629.197	2.38444
632.655	1.26298
636.113	2.64903
639.568	4.04981
643.021	4.04736
646.473	4.6321
649.924	6.64399
653.376	9.45908
656.824	11.6813
660.271	13.6235
663.716	15.4186
667.161	15.661
670.604	17.8013
674.045	19.8478
677.486	22.2225
680.925	23.9339
684.361	25.4491
687.797	27.836
691.232	28.6713
694.666	28.5751
698.099	29.9093
701.528	30.4837
704.958	30.4983
708.387	29.806
711.814	29.088
715.238	29.954
718.663	31.5505
722.084	31.895
725.506	32.7003
728.925	35.2554
732.345	37.8635
735.761	41.4285
739.178	45.1737
742.592	51.7414
746.006	57.793
749.417	64.7233
752.827	71.5489
756.236	78.7638
759.645	85.0881
763.051	89.2938
766.456	92.9624
769.859	95.3003
773.261	96.3253
776.664	97.3685
780.064	96.7751
783.462	95.7476
786.859	91.7563
790.255	89.4806
793.649	86.4653
797.042	84.3445
800.434	80.6932
803.823	77.3889
807.212	74.9827
810.6	73.0885
813.987	73.2001
817.372	73.2269
820.754	75.4788
824.137	79.3746
827.519	82.7164
830.897	85.8071
834.276	88.1399
837.654	89.4281
841.029	90.4097
844.404	88.2321
847.776	86.0044
851.149	84.1385
854.519	80.6827
857.889	77.1706
861.256	73.3115
864.622	67.4863
867.988	64.2557
871.351	58.1063
874.713	53.5385
878.074	48.8561
881.435	47.4334
884.794	44.5752
888.15	42.559
891.506	41.3639
894.861	41.9971
898.214	42.0451
901.566	45.0097
904.916	47.7774
908.266	51.8629
911.614	55.3631
914.961	58.9661
918.306	62.438
921.651	63.0355
924.994	64.0518
928.336	62.7856
931.674	63.3718
935.014	61.571
938.352	59.1085
941.687	57.2212
945.022	55.569
948.357	52.4964
951.688	48.4459
955.02	44.2999
958.348	40.913
961.678	36.7883
965.004	33.9727
968.331	31.4921
971.655	31.5184
974.979	30.8908
978.3	28.9887
981.62	28.1017
984.941	28.0932
988.259	28.6057
991.575	29.5179
994.89	31.5874
998.204	34.8324
1001.52	37.7822
1004.83	43.6646
1008.14	47.589
1011.45	52.668
1014.76	54.4886
1018.06	57.407
1021.37	60.3343
1024.67	61.1036
1027.97	62.3956
1031.27	61.7932
1034.57	59.0598
1037.87	57.7494
1041.17	53.6345
1044.47	51.2866
1047.76	50.838
1051.06	49.452
1054.35	47.0345
1057.64	44.4126
1060.93	40.9774
1064.22	41.6216
1067.5	40.8134
1070.79	42.3849
1074.08	44.9361
1077.36	48.7759
1080.64	52.3968
1083.92	54.9067
1087.2	56.6322
1090.48	57.1182
1093.76	58.9263
1097.03	59.1104
1100.31	60.1597
1103.58	60.0175
1106.85	59.9231
1110.12	59.1638
1113.39	56.801
1116.66	54.8699
1119.93	52.9074
1123.19	51.0123
1126.46	50.2103
1129.72	48.5961
1132.98	47.2678
1136.24	45.6186
1139.5	43.695
1142.76	42.3411
1146.01	40.5181
1149.27	37.8324
1152.53	35.3486
1155.78	30.5163
1159.03	28.1236
1162.28	23.2595
1165.53	17.0757
1168.78	14.3501
1172.02	11.9043
1175.27	11.4193
1178.51	9.08265
1181.76	8.73082
1185	7.46317
1188.24	7.89718
1191.48	9.60757
1194.71	10.3393
1197.95	12.1888
1201.19	15.0278
1204.42	17.2498
1207.65	18.6765
1210.88	22.2221
1214.12	24.7774
1217.35	27.4651
1220.57	31.2916
1223.8	34.7221
1227.03	38.3741
1230.25	40.6231
1233.47	42.4809
1236.69	44.4311
1239.92	44.2092
1243.13	44.5686
1246.35	44.7641
1249.57	44.9659
1252.78	44.3097
1256	43.2222
1259.21	41.0198
1262.42	39.9503
1265.63	38.3858
1268.84	37.0749
1272.05	34.8691
1275.26	34.3901
1278.46	33.4903
1281.67	34.6627
1284.87	34.4717
1288.07	36.7248
1291.27	38.6496
1294.47	40.9663
1297.67	44.6049
1300.87	49.7992
1304.06	52.8458
1307.26	58.2569
1310.45	64.4255
1313.64	69.7984
1316.83	75.1223
1320.02	78.3856
1323.21	81.298
1326.4	83.3063
1329.59	84.2243
1332.77	86.2597
1335.95	86.1625
1339.14	86.4029
1342.32	84.4608
1345.5	83.8456
1348.67	82.8941
1351.85	80.7846
1355.03	79.6271
1358.2	77.9888
1361.38	76.9978
1364.55	74.6976
1367.72	73.2079
1370.89	71.6877
1374.06	69.1371
1377.23	68.3348
1380.39	68.3062
1383.56	67.6445
1386.72	66.1777
1389.89	64.2024
1393.05	62.7233
1396.21	59.0422
1399.37	57.948
1402.52	56.0684
1405.68	54.7945
1408.84	53.3268
1411.99	52.8295
1415.15	53.0996
1418.3	53.3037
1421.45	55.2707
1424.6	58.456
1427.75	60.672
1430.89	62.5974
1434.04	64.1267
1437.18	68.4405
1440.33	71.0569
1443.47	75.1441
1446.61	77.1177
1449.75	76.194
1452.89	76.4557
1456.03	74.8551
1459.16	72.0991
1462.3	67.8917
1465.43	62.849
1468.56	56.0557
1471.7	50.4096
1474.83	44.815
1477.96	39.8236
1481.08	35.5693
1484.21	29.0819
1487.34	25.6181
1490.46	22.9993
1493.58	19.4522
1496.71	17.8288
1499.83	16.9682
1502.95	15.3189
1506.07	13.714
1509.18	12.9966
1512.3	15.4549
1515.41	17.1497
1518.53	18.6671
1521.64	21.0903
1524.75	22.0336
1527.86	22.9802
1530.97	24.8702
1534.08	27.0088
1537.19	28.5637
1540.29	29.3081
1543.4	30.0618
1546.5	31.3705
1549.6	34.7835
1552.7	38.5967
1555.8	40.9583
1558.9	44.2375
1562	46.1364
1565.09	48.3813
1568.19	49.6092
1571.28	50.5615
1574.37	52.5953
1577.47	53.9551
1580.56	56.0585
1583.64	57.685
1586.73	59.8575
1589.82	61.8099
1592.9	62.3933
1595.99	62.5405
1599.07	62.7253
1602.15	62.3722
1605.23	61.3132
1608.31	60.7887
1611.39	59.4176
1614.47	57.8379
1617.55	57.12
1620.62	56.0524
1623.7	56.2444
1626.77	55.9285
1629.84	55.8482
1632.91	55.3586
1635.98	54.1592
1639.05	53.734
1642.11	52.4732
1645.18	52.1937
1648.24	53.3259
1651.31	53.3299
1654.37	52.1725
1657.43	51.2443
1660.49	49.7769
1663.55	49.4834
1666.61	46.7871
1669.66	44.9081
1672.72	41.578
1675.77	37.4429
1678.83	35.3017
1681.88	31.7339
1684.93	29.7269
1687.98	27.2348
1691.03	24.4003
1694.07	21.5175
1697.12	18.4759
1700.17	15.9438
1703.21	13.5312
1706.25	13.1971
1709.29	11.2964
1712.33	10.8217
1715.37	10.0064
1718.41	8.66929
1721.45	8.57546
1724.49	6.88223
1727.52	5.45027
1730.55	5.38541
1733.59	6.16258
1736.62	5.63357
1739.65	4.85757
1742.68	5.5761
1745.7	4.16892
1748.73	3.73113
1751.76	3.61925
1754.78	3.18021
1757.8	2.88685
1760.83	2.60281
1763.85	2.09261
1766.87	1.99483
1769.89	0.38564
1772.9	0.653502
1775.92	1.61501
1778.94	2.52382
1781.95	2.71421
1784.96	2.51924
1787.97	3.05366
1790.99	2.93484
1794	2.20695
1797	2.35189
1800.01	2.61651
1803.02	3.53183
1806.02	3.8636
1809.03	4.62946
1812.03	4.79507
1815.03	5.97638
1818.03	5.42561
1821.03	4.56336
1824.03	4.42364
1827.03	4.19839
1830.02	4.27853
1833.02	3.95082
1836.01	3.76664
1839.01	4.28112
1842	3.13243
1844.99	2.4255
1847.98	2.60902
1850.97	1.49996
1853.95	1.78651
1856.94	1.07283
1859.93	0.827919
1862.91	0.868986
1865.89	0.532445
1868.87	0.759962
1871.85	1.3876
1874.83	1.9975
1877.81	2.56499
1880.79	3.62471
1882.52	4.73065
1885.51	5.45475
1888.5	5.0408
1891.49	3.42684
1894.47	3.69829
1897.46	4.89079
1900.44	6.08215
1903.42	6.28443
1906.4	6.07068
1909.38	5.91915
1912.36	5.03499
1915.34	4.0977
1918.32	4.92354
1921.29	5.608
1924.27	5.99329
1927.24	6.80208
1930.21	6.12583
1933.18	6.29236
1936.15	6.03686
1939.12	5.26219
1942.09	5.12533
1945.06	5.43037
1948.02	5.87007
1950.99	5.68762
1953.95	5.28717
1956.91	5.18309
1959.88	4.79013
1962.84	3.76628
1965.8	3.24502
1968.75	3.92904
1971.71	3.677
1974.67	3.1895
1977.62	2.59062
1980.58	1.64068
1983.53	1.98516
1986.48	1.51746
1989.43	2.37366
1992.38	3.05257
1995.33	2.80033
1998.27	2.71865
2001.22	2.72277
2004.16	2.12764
2007.11	1.93561
2010.05	1.1438
2012.99	1.43343
2015.93	1.56075
2018.87	2.22654
2021.81	2.89937
2024.75	4.20305
2027.69	5.4412
2030.62	6.73427
2033.56	7.38671
2036.49	7.15205
2039.42	7.18557
2042.35	8.18665
2045.28	8.29452
2048.21	9.48294
2051.14	8.99011
2054.07	8.22403
2056.99	7.91795
2059.92	6.91535
2062.84	7.08612
2065.76	6.81063
2068.68	7.64941
2071.6	7.79986
2074.52	7.89117
2077.44	7.41185
2080.36	6.64338
2083.27	7.14334
2086.19	7.91656
2089.1	8.06524
2092.02	9.38963
2094.93	8.92363
2097.84	9.40541
2100.75	9.13618
2103.66	7.84609
2106.56	6.98346
2109.47	5.23719
2112.38	5.54497
2115.28	5.76673
2118.18	4.99944
2121.09	4.58409
2123.99	3.69044
2126.89	3.00408
2129.79	4.12859
2132.68	3.47756
2135.58	3.31271
2138.48	3.82455
2141.37	4.84967
2144.27	4.7561
2147.16	5.93236
2150.05	6.12741
2152.94	6.628
2155.83	7.76592
2158.72	8.82037
2161.6	8.75009
2164.49	8.70085
2167.38	7.99411
2170.26	7.54257
2173.14	6.86024
2176.03	6.71796
2178.91	6.3156
2181.79	7.6851
2184.67	8.04826
2187.54	9.28503
2190.42	9.85768
2193.3	9.88927
2196.17	9.06631
2199.05	9.12715
2201.92	8.60948
2204.79	9.44915
2207.66	9.65127
2210.53	9.24476
2213.4	9.68646
2216.27	9.16772
2219.13	8.9052
2222	8.02894
2224.86	8.8694
2227.72	8.82973
2230.59	9.06401
2233.45	8.73844
2236.31	7.72999
2239.17	7.88024
2242.03	7.44261
2244.88	8.02406
2247.74	8.20651
2250.59	8.07474
2253.45	8.05662
2256.3	8.37469
2259.15	7.79368
2262	8.62978
2264.85	9.25721
2267.7	10.4656
2270.55	10.5491
2273.4	11.1567
2276.24	11.5264
2279.09	10.8393
2281.93	10.1925
2284.77	10.7697
2287.62	9.74164
2290.46	9.83231
2293.3	9.6085
2296.13	10.3087
2298.97	10.8376
2301.81	11.1414
2304.64	10.8351
2307.48	10.4436
2310.31	10.9487
2313.14	10.9612
2315.98	10.6812
2318.81	10.2546
2321.64	9.61923
2324.46	8.84487
2327.29	8.5612
2330.12	8.43579
2332.94	8.79848
2335.77	8.00146
2338.59	6.91368
2341.41	6.21419
2344.23	6.62639
2347.05	6.64803
2349.87	4.62078
2352.69	4.70746
2355.51	3.957
2358.32	2.25186
2361.14	2.72703
2363.95	3.95286
2366.76	3.44189
2369.58	2.3557
2372.39	2.0391
2375.2	1.83045
2378	2.14382
2380.81	1.95301
2383.62	1.11404
2386.43	1.0036
2389.23	0.228334
2392.03	-0.718121
2394.84	-0.653467
2397.64	-0.559244
2400.44	0.781328
2403.24	1.0499
2406.04	2.21947
2408.84	4.01122
2411.63	6.25999
2414.43	7.02535
2417.22	8.3178
2420.02	9.79839
2422.81	11.4537
2425.6	12.9902
2428.39	15.0653
2431.18	15.7728
2433.97	16.5137
2436.76	16.8963
2439.54	17.412
2442.33	17.8949
2445.12	16.2
2447.9	15.0847
2450.68	12.5848
2453.46	11.3855
2456.24	11.008
2459.02	9.89802
2461.8	10.0752
2464.58	9.41821
2467.36	9.69274
2470.13	8.90122
2472.91	8.17392
2475.68	8.67028
2478.45	7.9604
2481.23	6.75141
2484	6.73503
2486.77	6.6024
2489.54	5.31733
2492.3	5.63559
2495.07	5.75009
2497.84	5.66099
2500.6	6.39063
2503.36	6.99967
2506.13	7.45496
2508.89	8.53264
2511.65	7.91921
2514.41	7.66506
2517.17	9.09749
2519.93	9.21978
2522.68	11.2005
2525.44	11.8247
2528.19	12.5436
2530.95	13.276
2533.7	13.1689
2536.45	13.2359
2539.2	13.0073
2541.95	11.708
2544.7	11.4391
2547.45	11.092
2550.2	10.4014
2552.94	9.19784
2555.69	7.21184
2558.43	7.20462
2561.18	6.98593
2563.92	7.06455
2566.66	6.29728
2569.4	6.68281
2572.14	6.78448
2574.88	6.55132
2577.61	6.76758
2580.35	7.4008
2583.09	7.13331
2585.82	6.54422
2588.55	5.86441
2591.29	5.63622
2594.02	5.69214
2596.75	5.69999
2599.48	6.14545
2602.21	6.12776
2604.93	6.6411
2607.66	6.17938
2610.39	6.43653
2613.11	6.49496
2615.83	5.08848
2618.56	3.55639
2621.28	2.8921
2624	2.8282
2626.72	3.92115
2629.44	3.60322
2632.15	3.47683
2634.87	3.89804
2637.59	4.38089
2640.3	4.68396
2643.02	4.54135
2645.73	4.11384
2648.44	4.5324
2651.15	4.41332
2653.86	3.43044
2656.57	4.81996
2659.28	4.38562
2661.99	4.92659
2664.69	5.41914
2667.4	6.32424
2670.1	6.20764
2672.81	6.07814
2675.51	5.11205
2678.21	4.59362
2680.91	3.4502
2683.61	3.40137
2686.31	4.42908
2689	5.32527
2691.7	7.07035
2694.4	6.61285
2697.09	6.40478
2699.79	6.98768
2702.48	7.79222
2705.17	8.30997
2707.86	9.15061
2710.55	9.1043
2713.24	10.1739
2715.93	9.73653
2718.62	9.79385
2721.3	9.96698
2723.99	9.88837
2726.67	9.72454
2729.35	9.00431
2732.04	8.61535
2734.72	8.15368
2737.4	7.06593
2740.08	6.19938
2742.76	5.01902
2745.43	5.38208
2748.11	4.98619
2750.79	4.5024
2753.46	3.29405
2756.14	2.81131
2758.81	1.18935
2761.48	1.26926
2764.15	0.86269
2766.82	0.861674
2769.49	0.906754
2772.16	0.651299
2774.82	0.366136
2777.49	1.05766
2780.16	0.971744
2782.82	0.880117
2785.48	1.97162
2788.15	1.38654
2790.81	1.35721
2793.47	0.676693
2796.13	0.411704
2798.79	0.711827
2801.44	0.690922
2804.1	0.979157
2806.76	0.160232
2809.41	-0.593448
2812.07	-1.407
2814.72	-2.06266
2817.37	-1.07879
2820.02	-0.0903573
2822.67	1.37585
2825.32	4.34695
2827.97	6.734
2830.62	9.19669
2833.26	12.865
2835.91	17.2577
2838.56	22.1972
2841.2	28.1161
2843.84	34.1115
2846.48	41.2923
2849.12	49.2401
2851.77	57.1742
2854.4	65.8808
2857.04	76.1042
2859.68	85.9741
2862.32	95.9778
2864.95	105.601
2867.59	114.918
2870.22	123.744
2872.85	133.371
2875.48	142.305
2878.11	152.362
2880.74	162.39
2883.37	172.656
2886	181.92
2888.63	190.978
2891.25	199.631
2893.88	207.427
2896.5	213.937
2899.13	221.86
2901.75	229.5
2904.37	237.896
2906.99	246.544
2909.61	255.917
2912.23	264.865
2914.85	272.818
2917.46	279.83
2920.08	286.336
2922.7	291.433
2925.31	293.972
2927.92	296.047
2930.54	295.076
2933.15	293.647
2935.76	290.622
2938.37	285.919
2940.98	279.934
2943.58	272.224
2946.19	262.688
2948.8	253.075
2951.4	242.755
2954.01	231.172
2956.61	220.658
2959.21	210.226
2961.81	199.177
2964.41	190.141
2967.01	180.935
2969.61	171.418
2972.21	162.925
2974.81	153.576
2977.4	144.703
2980	135.501
2982.59	126.161
2985.18	117.12
2987.78	108.455
2990.37	98.2624
2992.96	87.0629
2995.55	77.5901
2998.14	68.4845
3000.73	59.7072
3003.31	51.6133
3005.9	42.2389
3008.48	34.038
3011.07	27.1727
3013.65	21.5593
3016.23	16.4419
3018.81	12.4709
3021.4	10.0614
3023.97	7.69691
3026.55	5.92401
3029.13	5.19475
3031.71	4.60115
3034.28	4.93761
3036.86	6.24373
3039.43	7.71174
3042.01	10.3202
3044.58	13.9292
3047.15	15.847
3049.72	18.2428
3052.29	19.8257
3054.86	21.6423
3057.43	22.9239
3060	24.2943
3062.56	25.646
3065.13	25.2414
3067.69	24.665
3070.26	24.5394
3072.82	23.9637
3075.38	24.2792
3077.94	23.8171
3080.5	23.7325
3083.06	24.1304
3085.62	25.5657
3088.18	26.2361
3090.73	27.8069
3093.29	30.9615
3095.84	33.1365
3098.4	35.3788
3100.95	39.5989
3103.5	43.3652
3106.05	46.142
3108.6	50.2489
3111.15	53.8191
3113.7	57.1926
3116.25	60.9246
3118.79	63.8313
3121.34	66.2644
3123.88	69.2962
3126.43	72.7085
3128.97	76.1987
3131.51	79.6514
3134.06	83.9018
3136.6	87.3896
3139.14	90.508
3141.67	94.3014
3144.21	98.7049
3146.75	103.508
3149.29	110.47