File: data/Raman/poly_smoothed/Thy_50_12_45_1x_45s_532 nm_x100_100%_600 gr_mm_01.txt
#Acq. time (s)=	45
#Accumulations=	2
#Range (cm-¹)=	200...3150
#Windows=	2
#Auto scanning=	Off
#Autofocus=	Off
#Macrospot=	Off
#AutoExposure=	Off
#Spike filter=	Multiple accum.
#Delay time (s)=	0
#Binning=	1
#Readout mode=	Signal
#DeNoise=	Off
#ICS correction=	On
#Dark correction=	Off
#Inst. Process=	Off
#Detector Gain=	Best Dynamic Range
#Detector ADC=	20 kHz
#Detector temperature (°C)=	-69.85
#Instrument=	LabRAM HR Evol
#Detector=	Synapse
#Objective=	x100
#Grating=	600 gr/mm
#ND Filter=	100%
#Laser (nm)=	532
#Hole=	100.021
#Range=	Auto
#Laser Pol.=	No
#Raman. Pol.=	No
#Laser Pol. (°)=	-0.0007625
#Raman Pol. (°)=	89.9995
#Collection=	Microscope
#StageXY=	Marzhauser
#StageZ=	Marzhauser
#X (µm)=	-5121.4
#Y (µm)=	1527.3
#Z (µm)=	63.4
#Full time(mm:ss)=	3:18
#Project=
#Sample=
#Site=
#Title=	Thy_50_12_45_2x_45s_532 nm_x100_100%_600 gr_mm
#Remark=
#Date=	07.07.2022 12:33
#Acquired=	07.07.2022 12:33:45
#Base:Fit=	10.08.2022 10:04:30
#Base:Sub=	10.08.2022 10:04:45
#Filter:Polynom=	16.08.2022 10:20:25
#AxisType[0]=Intens
#AxisUnit[0]=Cnt
#AxisType[1]=Spectr
#AxisUnit[1]=1/cm
200.43	10.4303
204.061	5.16528
207.688	3.6008
211.316	2.56697
214.941	1.79858
218.566	1.80115
222.188	3.59799
225.809	4.53513
229.43	5.0219
233.047	5.7641
236.663	6.74693
240.278	7.50293
243.894	6.98956
247.506	7.58627
251.116	9.46156
254.725	8.4955
258.333	7.30442
261.939	5.79194
265.546	5.78236
269.15	5.25147
272.752	4.04163
276.353	2.98687
279.952	3.11987
283.55	2.89391
287.146	3.28927
290.739	4.87467
294.333	8.19008
297.925	8.90968
301.516	11.1733
305.106	14.1029
308.694	17.1404
312.279	18.4919
315.864	20.3531
319.448	22.2383
323.029	25.045
326.61	26.265
330.19	26.0763
333.766	26.17
337.343	27.2851
340.917	25.0454
344.491	24.965
348.062	24.958
351.633	23.9947
355.201	23.9429
358.77	22.5991
362.335	22.211
365.899	22.3373
369.464	20.8769
373.025	21.1794
376.585	23.3229
380.143	24.1427
383.702	25.3263
387.258	25.6375
390.812	26.0583
394.365	26.6105
397.916	25.6198
401.467	26.6875
405.015	27.5387
408.565	27.1056
412.111	26.6158
415.656	25.8317
419.197	26.1014
422.739	28.0397
426.279	28.502
429.819	27.7494
433.356	29.0998
436.893	27.4048
440.428	25.2304
443.96	23.8952
447.492	22.5881
451.023	22.7158
454.553	25.0154
458.079	25.9115
461.606	26.7461
465.132	27.9583
468.654	29.9472
472.177	31.8712
475.696	33.3641
479.217	34.8777
482.733	38.0439
486.251	39.5614
489.765	40.1953
493.278	42.0809
496.791	43.8271
500.301	44.9973
503.81	46.7975
507.319	47.9474
510.825	50.0573
514.33	48.5424
517.833	48.0074
521.337	46.7914
524.838	42.7764
528.337	42.3653
531.835	41.3966
535.332	38.8531
538.827	38.0837
542.321	35.9666
545.814	33.961
549.305	29.959
552.795	29.8697
556.284	28.6816
559.771	26.8471
563.257	25.5207
566.742	22.6938
570.223	19.8407
573.705	18.0965
577.185	14.8607
580.665	13.7436
584.141	12.4572
587.617	10.748
591.092	9.75521
594.564	8.9918
598.037	9.7811
601.506	8.98044
604.976	8.03191
608.443	9.52844
611.91	9.31217
615.374	9.20304
618.839	10.4379
622.3	10.6721
625.761	12.0567
629.221	12.5364
632.679	13.8205
636.135	15.6107
639.592	17.554
643.045	16.9641
646.497	18.2586
649.948	16.4667
653.398	15.5511
656.846	16.453
660.293	17.026
663.738	16.4444
667.185	16.5108
670.628	15.9072
674.067	17.9535
677.508	19.5914
680.947	20.1163
684.385	24.981
687.821	27.0586
691.256	29.1328
694.69	30.8448
698.121	31.8002
701.552	33.952
704.982	37.7295
708.41	39.4271
711.836	41.5733
715.262	44.0194
718.685	46.5479
722.108	46.7385
725.53	48.2438
728.949	48.76
732.369	49.6138
735.785	50.3926
739.2	50.8797
742.616	52.2326
746.028	52.9806
749.441	54.2372
752.851	56.2891
756.26	59.862
759.667	62.1764
763.075	63.6963
766.479	68.2129
769.883	70.7572
773.285	70.9385
776.686	70.9284
780.085	70.8779
783.484	72.8167
786.881	74.1569
790.276	76.2115
793.671	77.4096
797.064	79.4033
800.456	81.9405
803.846	81.8301
807.236	83.7192
810.624	83.815
814.01	85.9989
817.394	84.4971
820.778	85.6504
824.161	85.9104
827.543	85.4398
830.921	83.4309
834.3	83.2165
837.676	81.8717
841.053	80.5777
844.426	75.4794
847.8	73.2333
851.171	69.9594
854.542	66.3618
857.911	62.6935
861.279	58.5505
864.645	54.4719
868.01	53.5282
871.375	50.9813
874.737	49.3706
878.097	47.8557
881.457	47.5769
884.817	46.8652
888.174	45.0572
891.53	46.3468
894.884	45.8005
898.237	46.1346
901.589	46.9773
904.94	47.5692
908.289	46.5538
911.637	44.9003
914.984	43.6484
918.33	42.2176
921.674	38.5394
925.015	34.4212
928.357	32.5229
931.698	29.8636
935.037	28.174
938.373	27.9614
941.71	26.1487
945.046	23.5148
948.378	24.8065
951.711	26.2399
955.043	26.6693
958.372	25.7748
961.701	28.7665
965.027	32.2733
968.354	37.2533
971.678	39.0383
975	42.4258
978.324	44.9677
981.644	47.2184
984.962	50.2649
988.282	50.0264
991.598	49.7377
994.913	48.295
998.227	47.0611
1001.54	45.0692
1004.85	45.2566
1008.16	44.3286
1011.47	43.6698
1014.78	45.5339
1018.08	44.8168
1021.39	45.0799
1024.69	46.3237
1028	50.3508
1031.3	52.2267
1034.6	54.5973
1037.9	54.3783
1041.19	54.8087
1044.49	58.0395
1047.79	57.7641
1051.08	56.8226
1054.37	56.6505
1057.66	56.638
1060.95	55.5278
1064.24	53.8978
1067.53	51.0313
1070.81	49.3045
1074.1	46.7486
1077.38	46.1961
1080.66	44.9917
1083.94	43.6037
1087.22	42.2647
1090.5	42.7378
1093.78	42.3118
1097.05	40.6998
1100.33	39.7286
1103.6	40.8969
1106.87	39.9047
1110.15	37.9539
1113.41	35.5979
1116.68	33.6572
1119.95	31.75
1123.21	30.1064
1126.48	26.7637
1129.74	24.752
1133	22.8196
1136.26	21.1353
1139.52	18.1286
1142.78	14.4929
1146.04	11.4935
1149.29	10.0152
1152.55	9.21687
1155.8	6.26864
1159.05	5.19571
1162.3	3.16704
1165.55	1.34855
1168.8	1.35375
1172.05	2.37827
1175.29	3.06393
1178.54	1.11023
1181.78	1.99583
1185.02	1.88637
1188.26	0.745659
1191.5	2.38093
1194.74	4.4085
1197.97	5.56774
1201.21	9.8179
1204.44	11.6619
1207.68	17.0144
1210.91	21.9783
1214.14	26.1412
1217.37	30.883
1220.6	36.81
1223.82	42.3882
1227.05	47.7393
1230.27	53.9829
1233.49	59.0085
1236.72	64.0643
1239.94	70.2504
1243.16	75.5033
1246.37	79.6193
1249.59	84.0105
1252.8	89.7826
1256.02	93.2876
1259.23	97.1963
1262.44	101.122
1265.66	104.538
1268.87	106.425
1272.07	111.166
1275.28	113.574
1278.48	116.997
1281.69	120.11
1284.89	122.114
1288.09	123.858
1291.3	123.811
1294.49	124.685
1297.69	125.479
1300.89	124.234
1304.09	124.017
1307.28	124.177
1310.47	123.462
1313.66	123.736
1316.86	122.576
1320.05	119.422
1323.23	116.55
1326.42	114.599
1329.61	112.744
1332.79	110.709
1335.98	108.385
1339.16	105.478
1342.34	101.079
1345.52	98.0841
1348.7	94.5289
1351.87	90.7467
1355.05	86.5082
1358.23	81.8582
1361.4	78.8766
1364.57	74.3036
1367.74	71.2246
1370.91	67.2868
1374.08	65.3172
1377.25	61.8813
1380.42	61.5524
1383.58	61.5394
1386.75	61.1008
1389.91	62.092
1393.07	61.8559
1396.23	60.6919
1399.39	60.3179
1402.55	61.6555
1405.7	64.3511
1408.86	67.7241
1412.01	71.9406
1415.17	76.3778
1418.32	82.6997
1421.47	88.6221
1424.62	95.6988
1427.77	104.427
1430.92	113.714
1434.06	122.4
1437.2	130.325
1440.35	135.276
1443.49	138.774
1446.63	139.219
1449.77	138.999
1452.91	137.633
1456.05	135.756
1459.18	130.378
1462.32	122.932
1465.45	114.619
1468.59	104.229
1471.72	94.4788
1474.85	82.4752
1477.98	70.8425
1481.11	62.6538
1484.23	55.0837
1487.36	46.9056
1490.48	39.9303
1493.61	33.7352
1496.73	30.7055
1499.85	28.6901
1502.97	27.3463
1506.09	28.2514
1509.2	27.5743
1512.32	28.175
1515.44	29.1138
1518.55	30.1971
1521.66	32.7519
1524.77	34.0209
1527.88	37.948
1530.99	40.7215
1534.1	42.1269
1537.21	44.1053
1540.31	49.9352
1543.42	54.5878
1546.52	59.5869
1549.62	66.0153
1552.72	70.1768
1555.82	76.4152
1558.92	83.6646
1562.02	88.5536
1565.11	94.6187
1568.21	98.3776
1571.3	104.727
1574.39	108.504
1577.49	112.998
1580.58	116.09
1583.67	118.609
1586.75	121.621
1589.84	123.033
1592.93	124.354
1596.01	123.971
1599.09	123.376
1602.18	121.089
1605.26	119.172
1608.34	115.928
1611.41	114.124
1614.49	113.897
1617.57	115.118
1620.64	114.766
1623.72	116.784
1626.79	119.593
1629.86	122.9
1632.93	127.306
1636	133.108
1639.07	137.722
1642.14	142.276
1645.2	145.531
1648.27	148.652
1651.33	151.973
1654.39	152.484
1657.45	151.758
1660.51	149.794
1663.57	145.888
1666.63	140.818
1669.69	133.392
1672.74	125.961
1675.79	116.501
1678.85	106.745
1681.9	95.9363
1684.95	85.4569
1688	76.7018
1691.05	68.5769
1694.1	60.4605
1697.14	53.9393
1700.19	47.7063
1703.23	41.798
1706.27	38.2195
1709.32	33.0132
1712.35	29.0983
1715.39	25.1873
1718.43	21.5898
1721.47	20.6627
1724.5	19.7278
1727.54	17.711
1730.57	15.3574
1733.61	14.4485
1736.64	12.782
1739.67	11.1357
1742.7	9.5197
1745.72	8.19522
1748.75	6.45592
1751.78	5.88943
1754.8	5.72656
1757.82	6.29971
1760.85	5.46209
1763.87	6.35619
1766.89	5.97577
1769.91	5.16401
1772.92	4.58107
1775.94	4.16759
1778.96	4.08151
1781.97	3.56812
1784.98	3.73697
1788	3.66031
1791.01	3.38551
1794.01	4.13787
1797.02	3.91231
1800.03	3.01653
1803.04	2.73651
1806.04	2.20048
1809.05	2.17213
1812.05	1.54179
1815.05	2.06019
1818.05	2.33044
1821.05	2.7984
1824.05	2.40837
1827.05	2.10255
1830.04	2.83341
1833.04	2.19846
1836.03	1.32199
1839.03	1.1474
1842.02	1.39771
1845.01	1.30309
1848	2.07462
1850.99	2.75063
1853.97	2.67986
1856.96	2.47784
1859.94	1.49412
1862.93	1.44555
1865.91	1.48198
1868.89	0.973037
1871.87	1.40355
1874.85	1.97935
1877.83	2.40142
1880.81	3.19526
1882.56	4.38726
1885.55	5.32189
1888.54	4.91683
1891.52	4.54728
1894.51	4.57785
1897.49	4.34044
1900.48	4.73227
1903.46	4.81651
1906.44	4.5283
1909.42	5.95594
1912.4	7.28472
1915.38	8.19113
1918.35	8.97172
1921.33	9.34706
1924.3	9.1119
1927.28	8.08624
1930.25	8.33061
1933.22	7.70661
1936.19	6.92906
1939.16	7.17864
1942.13	6.2568
1945.09	5.9663
1948.06	5.40878
1951.03	5.54253
1953.99	5.81599
1956.95	5.38781
1959.91	5.32826
1962.87	5.42768
1965.83	6.42421
1968.79	6.6055
1971.75	6.70531
1974.7	7.03871
1977.66	7.48512
1980.61	8.34615
1983.56	9.2787
1986.52	9.85144
1989.47	10.2034
1992.41	11.4544
1995.36	12.0682
1998.31	11.7185
2001.26	11.4561
2004.2	12.903
2007.15	12.459
2010.09	12.4059
2013.03	11.8227
2015.97	11.6444
2018.91	11.3618
2021.85	11.2404
2024.79	12.9558
2027.72	13.7056
2030.66	13.9658
2033.59	14.7706
2036.53	15.7242
2039.46	15.7917
2042.39	16.247
2045.32	16.4938
2048.25	16.9433
2051.18	18.3637
2054.1	20.7676
2057.03	21.6753
2059.95	23.7927
2062.88	26.0456
2065.8	28.1769
2068.72	29.9965
2071.64	33.043
2074.56	35.6593
2077.48	39.4801
2080.39	42.8449
2083.31	45.9518
2086.22	50.4533
2089.14	54.5065
2092.05	59.6077
2094.96	64.3906
2097.87	68.1116
2100.78	72.2243
2103.69	76.8477
2106.6	82.0228
2109.51	86.9307
2112.41	92.3618
2115.32	98.3937
2118.22	104.374
2121.12	111.354
2124.02	117.99
2126.92	125.271
2129.82	132.834
2132.72	139.93
2135.62	147.916
2138.51	154.151
2141.41	160.902
2144.3	169.028
2147.19	176.578
2150.09	182.449
2152.97	187.326
2155.86	193.052
2158.75	197.479
2161.64	200.534
2164.53	202.848
2167.41	203.946
2170.3	204.61
2173.18	203.261
2176.06	202.707
2178.94	200.161
2181.82	197.495
2184.7	193.019
2187.58	188.073
2190.46	182
2193.33	176.548
2196.21	169.262
2199.08	163.191
2201.95	155.204
2204.83	147.467
2207.7	139.61
2210.57	132.294
2213.43	126.704
2216.3	118.556
2219.17	111.176
2222.03	103.614
2224.9	98.2988
2227.76	91.8341
2230.62	88.0084
2233.49	82.3983
2236.34	76.8871
2239.2	73.6032
2242.06	68.7317
2244.92	65.5323
2247.78	62.7126
2250.63	59.0898
2253.48	55.4431
2256.34	53.2951
2259.19	50.1916
2262.04	48.203
2264.89	46.6331
2267.74	44.5881
2270.59	42.5309
2273.43	41.3625
2276.28	40.2347
2279.12	38.302
2281.97	36.2342
2284.81	33.8887
2287.65	31.5651
2290.49	28.7318
2293.33	25.6335
2296.17	24.5435
2299.01	23.4547
2301.84	23.3343
2304.68	21.3447
2307.51	19.6121
2310.35	18.9109
2313.18	16.1931
2316.01	15.1584
2318.84	14.8536
2321.67	13.0581
2324.5	13.2902
2327.33	12.74
2330.15	11.0131
2332.98	11.2257
2335.8	10.1129
2338.62	7.88832
2341.45	6.82525
2344.27	6.04772
2347.09	4.71402
2349.91	4.09095
2352.72	2.16145
2355.54	2.19382
2358.36	1.73177
2361.17	2.2606
2363.98	3.86823
2366.8	4.28214
2369.61	4.60702
2372.42	5.21924
2375.23	6.01854
2378.04	6.5094
2380.85	8.7037
2383.66	8.99224
2386.46	10.7917
2389.26	11.1311
2392.07	11.5451
2394.87	12
2397.67	11.6636
2400.47	12.9897
2403.27	13.1243
2406.07	12.3602
2408.87	13.5036
2411.67	13.7743
2414.46	13.602
2417.26	13.6243
2420.05	12.5209
2422.84	12.8155
2425.64	13.1348
2428.43	13.6615
2431.22	13.215
2434.01	13.2427
2436.79	13.0364
2439.58	12.6516
2442.37	12.4346
2445.15	12.2015
2447.93	12.534
2450.72	11.1742
2453.5	10.9314
2456.28	9.79872
2459.06	9.24875
2461.84	7.70006
2464.62	7.60505
2467.39	6.0579
2470.17	6.51746
2472.94	4.88719
2475.72	4.6415
2478.49	4.26767
2481.26	4.13021
2484.03	3.31357
2486.8	3.59477
2489.57	2.96401
2492.34	2.54202
2495.1	2.78295
2497.87	3.53717
2500.63	3.82276
2503.4	4.13272
2506.16	3.65651
2508.92	3.36143
2511.68	3.92692
2514.44	4.13882
2517.2	3.7823
2519.96	3.17435
2522.72	3.11108
2525.47	3.09361
2528.23	1.40402
2530.98	1.69386
2533.74	0.747351
2536.49	0.0395644
2539.24	1.0591
2541.99	0.0500884
2544.74	0.498428
2547.49	0.332665
2550.23	0.342434
2552.98	0.456079
2555.72	-0.145589
2558.47	-0.278391
2561.21	0.84236
2563.95	1.70407
2566.69	1.56496
2569.43	1.71997
2572.17	2.48709
2574.91	2.69773
2577.65	3.28211
2580.39	2.58361
2583.12	3.50105
2585.85	3.22413
2588.59	3.27051
2591.32	3.57506
2594.05	3.59489
2596.78	2.82823
2599.51	2.64499
2602.24	1.40516
2604.97	1.63263
2607.69	1.33452
2610.42	1.02531
2613.14	1.51403
2615.87	2.04014
2618.59	1.74174
2621.31	1.34103
2624.03	0.729484
2626.75	1.49776
2629.47	1.5778
2632.19	1.35319
2634.91	1.43753
2637.62	1.11952
2640.34	0.649876
2643.05	0.0311836
2645.76	-0.314006
2648.48	0.857138
2651.19	1.29388
2653.9	0.779488
2656.6	1.31215
2659.31	0.692176
2662.02	0.918403
2664.73	1.48773
2667.43	0.0282256
2670.14	0.739442
2672.84	2.51806
2675.54	3.99714
2678.24	5.12624
2680.94	6.3192
2683.64	5.46441
2686.34	5.60263
2689.04	5.57734
2691.74	5.9193
2694.43	6.72892
2697.13	7.8241
2699.82	8.51408
2702.51	9.07918
2705.21	9.95851
2707.9	10.9744
2710.58	12.041
2713.27	13.2748
2715.96	13.7711
2718.65	14.8296
2721.33	15.4325
2724.02	14.9631
2726.71	15.9166
2729.39	15.7725
2732.07	16.261
2734.75	17.2224
2737.43	17.7598
2740.11	17.2138
2742.79	15.1894
2745.47	14.0045
2748.14	11.8901
2750.82	9.92891
2753.49	8.82047
2756.17	7.65027
2758.84	7.54708
2761.51	6.5327
2764.18	6.87074
2766.85	5.97217
2769.52	4.92512
2772.19	3.93304
2774.86	2.61181
2777.52	2.05258
2780.19	1.40864
2782.85	2.43816
2785.52	2.32694
2788.18	2.62054
2790.84	3.19334
2793.5	3.41966
2796.16	4.25148
2798.82	5.2514
2801.48	5.51991
2804.13	4.83045
2806.79	4.69171
2809.45	4.41801
2812.1	3.72348
2814.75	4.73621
2817.41	7.4407
2820.06	12.55
2822.71	19.4824
2825.36	27.3754
2828	37.0365
2830.65	47.5544
2833.3	58.0571
2835.94	68.4704
2838.59	80.2372
2841.23	93.0226
2843.87	107.525
2846.52	122.451
2849.16	140.598
2851.8	158.451
2854.44	178.243
2857.08	196.451
2859.71	214.506
2862.35	231.644
2864.98	245.142
2867.62	257.232
2870.25	268.253
2872.88	277.244
2875.52	285.09
2878.15	293.229
2880.78	300.831
2883.41	309.347
2886.03	317.006
2888.66	325.193
2891.29	332.975
2893.91	341.281
2896.54	349.727
2899.16	358.344
2901.78	370.172
2904.4	384.516
2907.02	402.095
2909.64	422.189
2912.26	443.978
2914.88	466.66
2917.5	486.219
2920.11	502.792
2922.73	517.633
2925.34	528.742
2927.96	535.216
2930.57	538.481
2933.18	540.121
2935.79	536.221
2938.4	528.78
2941.01	516.902
2943.62	502.767
2946.22	486.319
2948.83	468.134
2951.43	448.55
2954.04	427.821
2956.64	407.137
2959.24	386.074
2961.84	364.6
2964.45	343.895
2967.05	325.896
2969.64	308.43
2972.24	292.319
2974.84	275.868
2977.43	258.357
2980.03	240.495
2982.62	223.197
2985.22	204.552
2987.81	187.656
2990.4	171.263
2992.99	154.929
2995.58	138.787
2998.17	123.918
3000.76	110.493
3003.34	97.6492
3005.93	85.4278
3008.52	75.261
3011.1	67.3255
3013.68	58.5107
3016.27	51.279
3018.85	45.7237
3021.43	41.7022
3024.01	37.2099
3026.59	34.7781
3029.16	33.8119
3031.74	32.9195
3034.32	33.0717
3036.89	33.9112
3039.47	34.3006
3042.04	35.0791
3044.61	36.343
3047.18	37.1427
3049.75	37.8886
3052.32	38.6505
3054.89	37.9013
3057.46	37.3991
3060.03	37.2142
3062.59	35.5966
3065.16	34.4435
3067.72	31.6612
3070.29	28.7297
3072.85	25.5737
3075.41	22.0864
3077.97	18.1293
3080.53	15.7404
3083.09	12.1741
3085.65	9.06968
3088.21	7.20951
3090.76	4.82165
3093.32	2.87632
3095.87	1.50693
3098.43	0.603885
3100.98	-0.760128
3103.53	-0.808292
3106.08	-1.00562
3108.63	-1.71606
3111.18	-0.593787
3113.73	-0.212212
3116.28	0.13204
3118.83	1.28155
3121.37	2.53459
3123.92	2.90702
3126.46	3.45949
3129	3.73744
3131.55	4.26265
3134.09	5.8823
3136.63	6.65404
3139.17	6.96072
3141.71	8.0017
3144.24	8.80051
3146.78	9.23066
3149.32	9.06048