File: data/Raman/poly_smoothed/Thy_40_11_29_1x_45s_532 nm_x100_100%_600 gr_mm_01.txt
#Acq. time (s)=	45
#Accumulations=	2
#Range (cm-¹)=	200...3150
#Windows=	2
#Auto scanning=	Off
#Autofocus=	Off
#Macrospot=	Off
#AutoExposure=	Off
#Spike filter=	Multiple accum.
#Delay time (s)=	0
#Binning=	1
#Readout mode=	Signal
#DeNoise=	Off
#ICS correction=	On
#Dark correction=	Off
#Inst. Process=	Off
#Detector Gain=	Best Dynamic Range
#Detector ADC=	20 kHz
#Detector temperature (°C)=	-69.85
#Instrument=	LabRAM HR Evol
#Detector=	Synapse
#Objective=	x100
#Grating=	600 gr/mm
#ND Filter=	100%
#Laser (nm)=	532
#Hole=	100.021
#Range=	Auto
#Laser Pol.=	No
#Raman. Pol.=	No
#Laser Pol. (°)=	-0.0007625
#Raman Pol. (°)=	89.9995
#Collection=	Microscope
#StageXY=	Marzhauser
#StageZ=	Marzhauser
#X (µm)=	256.3
#Y (µm)=	1672.9
#Z (µm)=	427.2
#Full time(mm:ss)=	3:18
#Project=
#Sample=
#Site=
#Title=	Thy_40_11_29_2x_45s_532 nm_x100_100%_600 gr_mm
#Remark=
#Date=	05.07.2022 12:05
#Acquired=	05.07.2022 12:05:56
#Base:Fit=	10.08.2022 10:01:35
#Base:Sub=	10.08.2022 10:01:52
#Filter:Polynom=	16.08.2022 10:21:53
#AxisType[0]=Intens
#AxisUnit[0]=Cnt
#AxisType[1]=Spectr
#AxisUnit[1]=1/cm
200.43	24.7904
204.059	24.1242
207.688	20.6521
211.314	17.2963
214.941	14.5589
218.564	11.7559
222.186	9.8472
225.809	8.3256
229.428	7.30433
233.045	6.13124
236.663	6.07091
240.278	6.52644
243.891	7.44495
247.503	7.70817
251.116	9.40011
254.725	9.62341
258.333	9.71799
261.939	10.3801
265.544	10.9554
269.148	12.501
272.75	11.6752
276.351	13.4337
279.95	14.8046
283.548	15.3424
287.144	14.9573
290.739	14.4112
294.333	11.996
297.925	11.0732
301.514	10.4118
305.104	10.8756
308.692	11.3312
312.279	10.5189
315.862	11.1607
319.446	12.0592
323.029	12.6059
326.608	14.2432
330.188	14.4688
333.766	14.4304
337.341	14.7547
340.917	14.2805
344.489	13.9665
348.062	14.412
351.631	14.0095
355.201	14.7294
358.768	15.8692
362.333	16.662
365.899	16.5517
369.462	16.8722
373.023	15.1854
376.585	15.8535
380.143	14.2575
383.7	14.0878
387.256	13.6444
390.812	15.0203
394.365	14.8305
397.916	12.7078
401.467	11.2526
405.015	10.5813
408.563	9.81049
412.109	8.91669
415.654	7.02808
419.197	5.3487
422.739	5.20617
426.279	5.5786
429.819	5.10446
433.356	5.73747
436.891	5.85672
440.426	6.48665
443.96	8.005
447.492	8.22416
451.021	8.63201
454.551	8.55865
458.079	8.86333
461.604	9.51199
465.13	10.7732
468.654	11.6536
472.175	12.9847
475.696	14.7272
479.215	13.8521
482.733	12.4919
486.249	13.2272
489.765	14.7575
493.278	15.9923
496.789	18.2253
500.301	18.3067
503.81	20.0351
507.317	22.8432
510.825	25.241
514.33	25.1476
517.833	26.0934
521.335	26.2349
524.836	25.5067
528.335	25.2004
531.835	24.0982
535.332	22.7887
538.827	21.8384
542.321	20.0974
545.814	17.9736
549.305	16.712
552.795	14.3543
556.282	12.5884
559.769	11.1066
563.255	8.88271
566.739	5.47115
570.223	4.0877
573.705	3.84418
577.183	2.62911
580.663	1.62721
584.141	0.662171
587.615	-0.512928
591.09	-0.149387
594.564	-0.149056
598.035	0.378061
601.506	1.39537
604.974	3.01477
608.443	3.17256
611.908	4.55404
615.374	4.20808
618.837	5.98203
622.3	8.34912
625.761	10.054
629.219	11.9492
632.677	13.2091
636.135	15.7432
639.59	17.5036
643.043	20.0643
646.495	22.3594
649.948	24.1472
653.398	23.0216
656.846	24.4661
660.293	23.8309
663.738	23.6392
667.183	22.7432
670.626	22.5853
674.067	22.9041
677.508	24.1678
680.947	24.6472
684.385	25.9099
687.821	26.4969
691.254	26.5319
694.688	25.8123
698.121	27.1385
701.552	26.9622
704.98	30.6054
708.409	32.8703
711.836	33.11
715.26	35.7092
718.685	38.6656
722.108	41.6954
725.528	44.1186
728.949	46.4763
732.367	48.0491
735.785	49.6244
739.2	52.2836
742.614	54.0392
746.028	56.1925
749.439	58.6615
752.849	63.7769
756.26	65.6827
759.667	68.2713
763.073	69.9125
766.477	71.6785
769.883	72.9034
773.285	74.6477
776.686	76.0537
780.085	76.1482
783.484	77.9697
786.881	80.714
790.276	82.0384
793.671	80.7878
797.064	79.7606
800.456	80.1752
803.846	80.0616
807.234	80.1701
810.622	80.0336
814.008	79.6428
817.394	79.5762
820.778	80.2493
824.159	80.4672
827.541	80.3938
830.921	79.7834
834.298	78.6519
837.676	78.1453
841.051	75.0035
844.426	73.0393
847.798	72.5356
851.171	70.8121
854.54	70.791
857.911	70.2763
861.278	70.0675
864.645	69.7534
868.01	69.8986
871.373	67.5909
874.735	65.35
878.097	62.1975
881.457	60.1122
884.815	60.1101
888.172	59.3556
891.528	59.2281
894.882	57.5797
898.237	57.4882
901.589	56.5787
904.94	56.341
908.289	54.7924
911.635	52.3099
914.982	50.4331
918.328	49.8261
921.672	47.6245
925.015	45.3976
928.357	44.3375
931.698	43.5399
935.035	43.1006
938.373	41.8436
941.71	42.095
945.044	40.611
948.378	39.8997
951.709	39.0606
955.041	39.2832
958.372	39.1199
961.699	39.386
965.027	40.781
968.352	41.691
971.676	45.7229
975	46.8846
978.322	49.6469
981.642	50.8093
984.962	50.9864
988.28	50.5868
991.596	50.4751
994.911	50.8874
998.227	51.1061
1001.54	50.1285
1004.85	49.9197
1008.16	50.31
1011.47	49.6294
1014.78	49.5233
1018.08	48.9311
1021.39	49.1736
1024.69	48.1352
1028	46.9921
1031.3	47.0966
1034.6	45.7314
1037.9	45.6047
1041.19	43.19
1044.49	44.3143
1047.78	43.9783
1051.08	45.1627
1054.37	44.7481
1057.66	42.3166
1060.95	41.5616
1064.24	38.6859
1067.53	36.6361
1070.81	34.9472
1074.1	34.6316
1077.38	32.5563
1080.66	31.5949
1083.94	31.0779
1087.22	30.3841
1090.5	30.3239
1093.78	29.9322
1097.05	28.916
1100.33	27.6071
1103.6	25.3016
1106.87	25.3343
1110.14	24.6001
1113.41	25.145
1116.68	25.1058
1119.95	23.9721
1123.21	23.8918
1126.48	24.6183
1129.74	25.5561
1133	25.1653
1136.26	23.9773
1139.52	23.533
1142.78	23.3475
1146.04	23.0468
1149.29	21.7373
1152.55	20.1918
1155.8	17.1474
1159.05	15.0909
1162.3	14.2627
1165.55	12.4435
1168.8	11.2382
1172.05	9.92426
1175.29	8.71375
1178.54	7.98151
1181.78	8.43357
1185.02	9.60205
1188.26	10.8534
1191.5	12.0406
1194.74	12.8337
1197.97	14.4196
1201.21	16.6392
1204.44	20.3874
1207.68	22.9049
1210.91	25.8798
1214.14	28.5463
1217.37	32.4584
1220.59	35.944
1223.82	39.8413
1227.05	42.1916
1230.27	43.2549
1233.49	46.4096
1236.72	48.446
1239.94	52.3085
1243.16	54.3195
1246.37	56.037
1249.59	58.8878
1252.8	60.8574
1256.02	64.1983
1259.23	67.2549
1262.44	70.1417
1265.66	70.9721
1268.86	71.9777
1272.07	72.9994
1275.28	73.9755
1278.48	75.6889
1281.69	77.6052
1284.89	78.5433
1288.09	79.3792
1291.29	80.4606
1294.49	80.3381
1297.69	80.7452
1300.89	80.6763
1304.08	80.2133
1307.28	80.1661
1310.47	81.109
1313.66	81.5949
1316.85	80.4169
1320.04	79.1561
1323.23	77.4533
1326.42	76.5943
1329.61	73.7656
1332.79	72.5303
1335.97	71.4648
1339.16	67.1751
1342.34	64.8877
1345.52	62.5836
1348.7	60.957
1351.87	58.4224
1355.05	56.5517
1358.22	54.2309
1361.4	51.9643
1364.57	49.2758
1367.74	46.4585
1370.91	43.6221
1374.08	42.207
1377.25	43.0377
1380.41	40.8967
1383.58	39.4198
1386.74	38.4825
1389.91	37.3294
1393.07	36.1921
1396.23	35.2327
1399.39	34.7479
1402.55	33.9403
1405.7	32.5529
1408.86	32.813
1412.01	34.5683
1415.17	35.7525
1418.32	39.3732
1421.47	42.9692
1424.62	47.6942
1427.77	52.4153
1430.91	56.8717
1434.06	61.2438
1437.2	64.887
1440.35	69.5201
1443.49	70.8639
1446.63	71.9909
1449.77	73.426
1452.91	71.8051
1456.05	71.2177
1459.18	67.5172
1462.32	63.9789
1465.45	59.1905
1468.59	54.8359
1471.72	49.0912
1474.85	42.8561
1477.98	37.2148
1481.1	29.9127
1484.23	24.3427
1487.36	20.1216
1490.48	17.1237
1493.61	13.9558
1496.73	11.781
1499.85	10.9498
1502.97	10.6349
1506.09	10.9564
1509.2	12.0273
1512.32	12.7853
1515.43	14.3396
1518.55	15.9761
1521.66	17.4546
1524.77	20.027
1527.88	21.4948
1530.99	23.8281
1534.1	26.878
1537.21	29.1316
1540.31	32.1863
1543.42	35.6639
1546.52	38.0546
1549.62	41.1194
1552.72	45.3887
1555.82	47.2528
1558.92	50.5472
1562.02	54.4053
1565.11	57.5714
1568.21	59.4695
1571.3	62.4792
1574.39	66.1361
1577.49	68.9253
1580.57	70.4653
1583.66	72.1483
1586.75	73.5432
1589.84	73.3495
1592.92	75.189
1596.01	73.754
1599.09	72.3998
1602.17	71.3502
1605.25	69.6828
1608.33	68.989
1611.41	67.7727
1614.49	66.9884
1617.57	66.5939
1620.64	66.6483
1623.72	67.8955
1626.79	68.8238
1629.86	69.1549
1632.93	71.3819
1636	74.5059
1639.07	75.944
1642.13	79.2377
1645.2	83.0384
1648.26	86.8782
1651.33	88.3743
1654.39	89.069
1657.45	89.9229
1660.51	89.1741
1663.57	88.1384
1666.63	86.7701
1669.68	84.1941
1672.74	80.1838
1675.79	75.002
1678.85	70.1086
1681.9	64.2347
1684.95	57.0963
1688	51.3635
1691.05	45.3647
1694.09	39.6705
1697.14	32.9881
1700.18	27.469
1703.23	22.5724
1706.27	17.289
1709.31	13.948
1712.35	11.3377
1715.39	8.98226
1718.43	7.46266
1721.47	6.79294
1724.5	4.04065
1727.54	2.7019
1730.57	2.4506
1733.61	1.4976
1736.64	1.38434
1739.67	1.97096
1742.7	1.86167
1745.72	1.46924
1748.75	0.90392
1751.77	0.656711
1754.8	2.03427
1757.82	2.30868
1760.84	2.67728
1763.87	3.6642
1766.89	3.30472
1769.91	3.2079
1772.92	3.20202
1775.94	2.729
1778.95	2.35344
1781.97	1.70238
1784.98	1.30679
1787.99	1.28949
1791.01	0.886699
1794.01	1.12642
1797.02	0.997088
1800.03	0.358578
1803.04	1.30967
1806.04	0.896982
1809.05	1.24757
1812.05	1.44929
1815.05	1.10965
1818.05	1.06397
1821.05	2.62053
1824.05	2.44568
1827.05	2.97158
1830.04	3.55571
1833.04	3.67469
1836.03	3.62418
1839.03	3.24856
1842.02	2.90417
1845.01	2.93089
1848	1.73092
1850.99	1.08883
1853.97	1.29971
1856.96	1.00394
1859.94	1.88476
1862.93	1.91704
1865.91	2.92311
1868.89	4.77668
1871.87	5.14331
1874.85	6.5635
1877.83	7.23576
1880.81	8.3811
1882.57	9.564
1885.56	10.2314
1888.55	11.0012
1891.54	11.9456
1894.52	11.1845
1897.51	11.5454
1900.49	12.2495
1903.47	12.2637
1906.45	11.9843
1909.43	10.8584
1912.41	9.33748
1915.39	8.39025
1918.37	7.56601
1921.34	6.98525
1924.32	6.9579
1927.29	6.92519
1930.26	6.23203
1933.23	6.18677
1936.2	5.13437
1939.17	5.53068
1942.14	5.4892
1945.11	5.6563
1948.07	5.92848
1951.04	6.09374
1954	5.84878
1956.96	6.90807
1959.93	6.8192
1962.89	7.0168
1965.85	6.28836
1968.8	6.5441
1971.76	7.33565
1974.72	8.75697
1977.67	8.86941
1980.63	9.7164
1983.58	9.4508
1986.53	10.2124
1989.48	11.6763
1992.43	12.4666
1995.38	12.2667
1998.32	12.5249
2001.27	12.209
2004.22	12.9139
2007.16	12.0648
2010.1	11.9838
2013.04	12.5309
2015.98	12.1288
2018.92	12.502
2021.86	12.0804
2024.8	13.4429
2027.74	13.5274
2030.67	13.8403
2033.61	13.9703
2036.54	14.0946
2039.47	15.2727
2042.4	16.9744
2045.33	19.0856
2048.26	20.1275
2051.19	20.9199
2054.12	21.8263
2057.04	22.2235
2059.97	23.6992
2062.89	24.327
2065.81	24.917
2068.73	25.2663
2071.65	25.3532
2074.57	26.1704
2077.49	26.9426
2080.41	27.6553
2083.32	29.5592
2086.24	30.8653
2089.15	32.0123
2092.07	33.9442
2094.98	35.8837
2097.89	38.1144
2100.8	40.183
2103.71	42.8047
2106.61	45.2799
2109.52	48.8618
2112.43	53.2151
2115.33	56.6258
2118.23	60.0258
2121.13	63.5627
2124.04	68.8781
2126.94	72.7886
2129.83	76.7174
2132.73	80.639
2135.63	84.6259
2138.53	88.8465
2141.42	92.6508
2144.31	96.8713
2147.21	100.252
2150.1	104.956
2152.99	108.849
2155.88	111.951
2158.77	114.248
2161.65	116.692
2164.54	117.504
2167.43	118.033
2170.31	119.258
2173.19	118.908
2176.07	118.595
2178.96	117.456
2181.84	116.511
2184.72	114.202
2187.59	110.318
2190.47	106.85
2193.35	103.73
2196.22	100.68
2199.09	96.5122
2201.97	92.6724
2204.84	89.1148
2207.71	85.8542
2210.58	81.4797
2213.45	77.4168
2216.31	73.5032
2219.18	69.5112
2222.05	66.3931
2224.91	63.2089
2227.78	59.9215
2230.64	56.8626
2233.5	54.1422
2236.36	51.3153
2239.22	49.6267
2242.08	47.654
2244.93	45.6888
2247.79	44.1656
2250.64	41.8034
2253.5	39.8438
2256.35	38.02
2259.2	36.7073
2262.05	35.8569
2264.9	34.5464
2267.75	33.1641
2270.6	32.3488
2273.45	31.4153
2276.29	29.7043
2279.14	28.2989
2281.98	26.2407
2284.82	25.1437
2287.66	24.332
2290.5	22.9474
2293.34	21.3561
2296.18	21.8971
2299.02	21.9787
2301.86	21.4625
2304.69	20.9507
2307.53	19.6238
2310.36	18.8537
2313.19	19.9574
2316.02	19.7897
2318.85	19.152
2321.68	18.5434
2324.51	18.5022
2327.34	17.523
2330.16	16.8211
2332.99	16.572
2335.81	15.3654
2338.64	15.311
2341.46	15.975
2344.28	15.201
2347.1	13.9783
2349.92	13.3416
2352.74	13.7648
2355.55	12.4145
2358.37	10.8308
2361.19	9.05233
2364	8.46305
2366.81	8.51957
2369.62	7.28354
2372.44	6.36536
2375.24	4.13048
2378.05	3.30969
2380.86	2.55564
2383.67	1.83343
2386.47	2.00919
2389.28	2.28981
2392.08	2.81446
2394.89	3.29524
2397.69	3.2888
2400.49	5.21906
2403.29	6.3419
2406.09	7.994
2408.88	8.7155
2411.68	10.624
2414.48	11.0885
2417.27	12.2828
2420.06	13.9229
2422.86	14.2705
2425.65	14.9906
2428.44	15.6751
2431.23	16.5675
2434.02	18.2204
2436.81	17.5053
2439.59	17.3905
2442.38	16.8726
2445.16	17.133
2447.95	16.9141
2450.73	17.3509
2453.51	17.1147
2456.29	16.6328
2459.07	15.5462
2461.85	15.3413
2464.63	15.1906
2467.4	14.077
2470.18	13.6386
2472.95	12.2936
2475.73	11.6735
2478.5	10.1708
2481.27	9.69671
2484.04	9.62943
2486.81	9.22815
2489.58	8.78886
2492.35	8.4058
2495.12	8.00983
2497.88	7.65017
2500.65	7.28132
2503.41	6.77782
2506.17	5.90596
2508.94	5.29783
2511.7	5.39982
2514.46	5.88447
2517.22	4.8174
2519.97	4.45633
2522.73	4.35285
2525.49	4.37057
2528.24	3.68702
2530.99	3.71903
2533.75	4.17932
2536.5	2.69307
2539.25	2.27334
2542	2.38268
2544.75	2.15658
2547.5	2.42453
2550.24	3.44993
2552.99	3.30936
2555.74	3.96539
2558.48	4.12598
2561.22	4.55152
2563.96	4.5598
2566.71	4.84396
2569.45	4.69752
2572.18	3.93634
2574.92	4.17715
2577.66	4.50295
2580.4	4.61551
2583.13	3.95314
2585.87	3.78291
2588.6	2.83369
2591.33	3.03355
2594.06	1.99709
2596.79	2.13977
2599.52	1.82466
2602.25	0.375959
2604.98	-0.300916
2607.71	-0.193709
2610.43	-0.0837989
2613.16	0.154521
2615.88	-0.302963
2618.6	0.147711
2621.32	0.256726
2624.04	0.514057
2626.76	0.0108077
2629.48	0.0494168
2632.2	0.464805
2634.92	1.10405
2637.63	0.541066
2640.35	1.02087
2643.06	0.250709
2645.77	0.960137
2648.49	1.07324
2651.2	1.32441
2653.91	1.22486
2656.62	1.81487
2659.33	2.58415
2662.03	3.68111
2664.74	3.75692
2667.44	3.60797
2670.15	4.31524
2672.85	4.1826
2675.55	4.48366
2678.26	4.60565
2680.96	4.65403
2683.66	5.66321
2686.35	5.5658
2689.05	4.64052
2691.75	5.18503
2694.44	5.2197
2697.14	4.98255
2699.83	4.80768
2702.52	5.33667
2705.22	4.66513
2707.91	3.82443
2710.6	3.9564
2713.29	4.1254
2715.97	4.68903
2718.66	4.42596
2721.35	5.13131
2724.03	5.8744
2726.72	6.24853
2729.4	6.06796
2732.08	6.30393
2734.76	5.72874
2737.44	5.80711
2740.12	5.51496
2742.8	5.61852
2745.48	4.98409
2748.16	4.5029
2750.83	4.17671
2753.51	3.20558
2756.18	2.77171
2758.85	2.86723
2761.53	1.40765
2764.2	1.45132
2766.87	1.09077
2769.54	0.364723
2772.2	-0.343537
2774.87	-0.118407
2777.54	0.359082
2780.2	-0.170146
2782.87	0.123184
2785.53	0.124741
2788.19	-0.0266463
2790.85	-0.686786
2793.51	-0.980929
2796.17	-0.897488
2798.83	-1.04605
2801.49	-1.74276
2804.15	-1.89054
2806.8	-2.84666
2809.46	-2.88427
2812.11	-3.06198
2814.76	-3.23448
2817.42	-3.19427
2820.07	-2.50915
2822.72	-0.313208
2825.37	3.09489
2828.02	7.05087
2830.66	10.6636
2833.31	15.0158
2835.96	19.6546
2838.6	24.5991
2841.24	31.2464
2843.89	38.283
2846.53	46.5197
2849.17	55.7076
2851.81	66.2243
2854.45	75.7541
2857.09	85.4265
2859.72	95.4415
2862.36	103.157
2865	111.068
2867.63	118.567
2870.26	124.353
2872.9	129.75
2875.53	134.986
2878.16	139.709
2880.79	144.5
2883.42	150.195
2886.05	155.47
2888.67	159.816
2891.3	164.622
2893.92	168.854
2896.55	174.149
2899.17	181.549
2901.79	188.997
2904.42	199.543
2907.04	211.427
2909.66	224.756
2912.27	238.458
2914.89	251.96
2917.51	263.984
2920.13	274.812
2922.74	284.667
2925.35	291.537
2927.97	296.537
2930.58	299.541
2933.19	300.149
2935.8	300.143
2938.41	297.325
2941.02	292.835
2943.63	286.906
2946.24	279.196
2948.84	268.848
2951.45	256.532
2954.05	244.91
2956.65	233.397
2959.26	221.49
2961.86	210.551
2964.46	198.698
2967.06	188.22
2969.66	178.937
2972.25	168.915
2974.85	159.112
2977.45	148.722
2980.04	138.152
2982.64	126.542
2985.23	116.96
2987.82	106.135
2990.41	96.3129
2993	86.0235
2995.59	77.9697
2998.18	69.8024
3000.77	61.3944
3003.36	53.6183
3005.94	47.1882
3008.53	40.9534
3011.11	35.611
3013.69	29.8944
3016.28	25.6824
3018.86	23.4785
3021.44	20.9356
3024.02	18.8301
3026.6	17.2642
3029.18	16.0501
3031.75	15.5116
3034.33	15.841
3036.9	16.1503
3039.48	16.9237
3042.05	17.916
3044.62	19.0053
3047.19	20.6208
3049.77	21.762
3052.34	22.3326
3054.9	22.7237
3057.47	23.3234
3060.04	23.0942
3062.61	22.3053
3065.17	20.9348
3067.74	19.9843
3070.3	18.3393
3072.86	16.4112
3075.42	14.9069
3077.99	13.2784
3080.54	11.0325
3083.1	9.15783
3085.66	6.53815
3088.22	4.40238
3090.78	2.65698
3093.33	1.36351
3095.89	0.401839
3098.44	0.900521
3100.99	0.940314
3103.54	0.263815
3106.1	-0.151239
3108.65	0.166697
3111.2	0.752675
3113.74	1.05155
3116.29	2.04969
3118.84	2.52013
3121.38	2.86288
3123.93	3.41919
3126.47	4.38638
3129.01	5.07494
3131.56	6.17919
3134.1	7.11436
3136.64	8.55291
3139.18	9.14382
3141.72	9.40906
3144.26	9.95977
3146.79	10.5697
3149.33	12.7732