File: data/Raman/poly_smoothed/Thy_10_08_15_1x_45s_532 nm_x100_100%_600 gr_mm_01.txt
#Acq. time (s)=	45
#Accumulations=	2
#Range (cm-¹)=	200...3150
#Windows=	2
#Auto scanning=	Off
#Autofocus=	Off
#Macrospot=	Off
#AutoExposure=	Off
#Spike filter=	Multiple accum.
#Delay time (s)=	0
#Binning=	1
#Readout mode=	Signal
#DeNoise=	Off
#ICS correction=	On
#Dark correction=	Off
#Inst. Process=	Off
#Detector Gain=	Best Dynamic Range
#Detector ADC=	20 kHz
#Detector temperature (°C)=	-69.85
#Instrument=	LabRAM HR Evol
#Detector=	Synapse
#Objective=	x100
#Grating=	600 gr/mm
#ND Filter=	100%
#Laser (nm)=	532
#Hole=	100.021
#Range=	Auto
#Laser Pol.=	No
#Raman. Pol.=	No
#Laser Pol. (°)=	-0.0007625
#Raman Pol. (°)=	89.9995
#Collection=	Microscope
#StageXY=	Marzhauser
#StageZ=	Marzhauser
#X (µm)=	2184.2
#Y (µm)=	1268.8
#Z (µm)=	442.1
#Full time(mm:ss)=	3:18
#Project=
#Sample=
#Site=
#Title=	Thy_10_08_15_2x_45s_532 nm_x100_100%_600 gr_mm
#Remark=
#Date=	05.07.2022 15:15
#Acquired=	05.07.2022 15:15:49
#Base:Fit=	10.08.2022 09:46:25
#Base:Sub=	10.08.2022 09:46:49
#Filter:Polynom=	16.08.2022 10:24:56
#AxisType[0]=Intens
#AxisUnit[0]=Cnt
#AxisType[1]=Spectr
#AxisUnit[1]=1/cm
200.43	26.7704
204.059	26.6791
207.688	25.6317
211.314	22.1575
214.941	17.7731
218.564	14.8246
222.186	13.6625
225.809	12.1799
229.428	11.7694
233.045	10.6271
236.663	9.57211
240.278	9.95943
243.891	10.828
247.503	11.026
251.116	11.4526
254.725	12.0629
258.333	13.1299
261.939	13.2642
265.544	13.7837
269.148	15.687
272.75	16.2925
276.351	16.0361
279.95	15.3081
283.548	15.0751
287.144	14.9852
290.739	13.7339
294.333	14.1143
297.925	14.0053
301.514	14.1864
305.104	14.1622
308.692	16.687
312.279	15.9322
315.862	16.5469
319.446	17.2754
323.029	17.4961
326.608	19.7728
330.188	21.5634
333.766	22.328
337.341	23.3365
340.917	24.8801
344.489	24.9406
348.062	24.9388
351.631	21.5924
355.201	20.5071
358.768	18.2025
362.333	16.0582
365.899	14.1209
369.462	13.5167
373.023	12.4283
376.585	11.4217
380.143	11.5103
383.7	11.5423
387.256	9.35444
390.812	9.44152
394.365	7.7559
397.916	7.85971
401.467	6.85042
405.015	7.01336
408.563	7.8727
412.109	7.48078
415.654	8.033
419.197	8.56732
422.739	9.28367
426.279	10.2876
429.819	10.2013
433.356	10.2043
436.891	9.20881
440.426	7.88355
443.96	8.43046
447.492	9.61489
451.021	9.75105
454.551	11.7252
458.079	13.586
461.604	15.3236
465.13	18.0171
468.654	19.4924
472.175	20.9163
475.696	21.9892
479.215	24.2252
482.733	25.3446
486.249	26.6876
489.765	27.4206
493.278	29.2688
496.789	29.1367
500.301	29.3757
503.81	28.5558
507.317	28.4968
510.825	28.6366
514.33	27.1447
517.833	25.0178
521.335	24.071
524.836	24.1605
528.335	25.0858
531.835	24.7024
535.332	23.8262
538.827	23.1671
542.321	22.7564
545.814	21.5081
549.305	19.3757
552.795	17.17
556.282	17.2158
559.769	16.8312
563.255	14.8999
566.739	13.9074
570.223	10.8171
573.705	9.6968
577.183	7.93296
580.663	5.38562
584.141	3.09758
587.615	1.9789
591.09	1.19014
594.564	0.243801
598.035	-0.990227
601.506	-0.683413
604.974	0.147241
608.443	0.412709
611.908	1.58075
615.374	2.70372
618.837	2.17532
622.3	2.99109
625.761	2.36578
629.219	3.25804
632.677	4.03822
636.135	8.12261
639.59	9.08929
643.043	10.977
646.495	10.9655
649.948	12.8505
653.398	13.2898
656.846	14.573
660.293	14.2357
663.738	15.1592
667.183	15.3803
670.626	15.8175
674.067	18.225
677.508	17.0729
680.947	17.0253
684.385	19.0688
687.821	20.1496
691.254	21.4037
694.688	25.7722
698.121	29.4659
701.552	31.0698
704.98	33.4455
708.409	36.7079
711.836	40.7198
715.26	45.0416
718.685	47.9343
722.108	51.6033
725.528	52.125
728.949	54.5154
732.367	56.9396
735.785	58.4408
739.2	60.9205
742.614	61.6892
746.028	62.3438
749.439	62.7866
752.849	62.4356
756.26	63.5023
759.667	66.0558
763.073	66.3648
766.477	69.6579
769.883	71.1928
773.285	74.5018
776.686	76.0836
780.085	78.6038
783.484	79.4385
786.881	78.6494
790.276	79.1159
793.671	80.291
797.064	81.6109
800.456	81.8638
803.846	83.3149
807.234	81.8361
810.622	82.406
814.008	82.7691
817.394	83.8643
820.778	84.9778
824.159	84.9264
827.541	85.7034
830.921	85.473
834.298	85.3914
837.676	86.945
841.051	87.5882
844.426	86.4345
847.798	86.1545
851.171	85.2992
854.54	81.2694
857.911	79.4288
861.278	76.4203
864.645	72.3317
868.01	70.6616
871.373	68.9447
874.735	71.0026
878.097	69.1875
881.457	68.1463
884.815	67.6536
888.172	65.4276
891.528	63.9929
894.882	62.6524
898.237	61.8823
901.589	63.1908
904.94	65.0615
908.289	64.94
911.635	64.7393
914.982	62.9245
918.328	64.3664
921.672	63.8958
925.015	61.6883
928.357	59.7963
931.698	56.259
935.035	53.2727
938.373	52.3998
941.71	50.9366
945.044	47.812
948.378	46.6805
951.709	45.7695
955.041	46.9258
958.372	44.4165
961.699	40.6093
965.027	43.1381
968.352	46.7026
971.676	50.3961
975	55.0957
978.322	57.046
981.642	61.2808
984.962	64.273
988.28	64.4619
991.596	66.6946
994.911	68.619
998.227	70.5863
1001.54	69.9321
1004.85	69.6451
1008.16	66.7533
1011.47	65.5918
1014.78	62.9431
1018.08	60.6193
1021.39	56.0458
1024.69	50.8769
1028	46.2821
1031.3	42.9273
1034.6	37.1096
1037.9	32.9306
1041.19	29.1285
1044.49	30.4593
1047.78	32.9371
1051.08	30.9226
1054.37	30.384
1057.66	27.4566
1060.95	23.3802
1064.24	21.6246
1067.53	21.9303
1070.81	22.1722
1074.1	23.6793
1077.38	24.6191
1080.66	26.4079
1083.94	26.4869
1087.22	26.4801
1090.5	28.4433
1093.78	30.9197
1097.05	31.8496
1100.33	33.2423
1103.6	34.0172
1106.87	32.263
1110.14	30.0537
1113.41	25.0505
1116.68	25.6223
1119.95	26.8906
1123.21	26.288
1126.48	27.5228
1129.74	26.0168
1133	24.116
1136.26	23.1553
1139.52	20.8246
1142.78	19.3383
1146.04	18.0694
1149.29	18.3879
1152.55	17.3406
1155.8	17.16
1159.05	16.4086
1162.3	15.7533
1165.55	14.4325
1168.8	15.0102
1172.05	16.8018
1175.29	18.9971
1178.54	20.0764
1181.78	20.9565
1185.02	20.3846
1188.26	20.3792
1191.5	20.0163
1194.74	25.1272
1197.97	28.9929
1201.21	32.4616
1204.44	35.2318
1207.68	38.8082
1210.91	42.5902
1214.14	47.3249
1217.37	50.8189
1220.59	52.7114
1223.82	55.7126
1227.05	59.5966
1230.27	63.285
1233.49	65.3207
1236.72	66.7612
1239.94	69.657
1243.16	71.9281
1246.37	74.4435
1249.59	76.7387
1252.8	78.8102
1256.02	80.3508
1259.23	81.1378
1262.44	82.1945
1265.66	81.6355
1268.86	82.5656
1272.07	82.376
1275.28	82.716
1278.48	84.4918
1281.69	87.6192
1284.89	88.4159
1288.09	92.2662
1291.29	94.6173
1294.49	95.4905
1297.69	96.5257
1300.89	98.4437
1304.08	100.827
1307.28	102.842
1310.47	105.107
1313.66	106.078
1316.85	109.08
1320.04	112.119
1323.23	112.455
1326.42	112.685
1329.61	111.318
1332.79	109.937
1335.97	107.763
1339.16	105.564
1342.34	102.615
1345.52	97.7464
1348.7	93.1926
1351.87	89.0404
1355.05	86.2331
1358.22	81.1531
1361.4	76.4476
1364.57	72.3654
1367.74	69.1444
1370.91	64.1844
1374.08	60.4237
1377.25	58.0465
1380.41	56.9718
1383.58	55.8135
1386.74	55.7297
1389.91	56.2327
1393.07	55.2647
1396.23	55.8621
1399.39	54.0271
1402.55	54.0162
1405.7	53.527
1408.86	54.2557
1412.01	55.0299
1415.17	57.8234
1418.32	61.7469
1421.47	67.5513
1424.62	73.1721
1427.77	80.7394
1430.91	88.3374
1434.06	95.786
1437.2	102.139
1440.35	107.924
1443.49	112.583
1446.63	115.545
1449.77	117.643
1452.91	116.663
1456.05	116.584
1459.18	113.851
1462.32	108.348
1465.45	101.616
1468.59	93.4664
1471.72	82.6561
1474.85	73.7618
1477.98	65.377
1481.1	55.9076
1484.23	47.6921
1487.36	38.7583
1490.48	31.4285
1493.61	27.9932
1496.73	24.8804
1499.85	20.8124
1502.97	19.7682
1506.09	17.7715
1509.2	16.7159
1512.32	16.7989
1515.43	15.6974
1518.55	15.0027
1521.66	16.194
1524.77	18.747
1527.88	19.7628
1530.99	20.6341
1534.1	24.3646
1537.21	27.263
1540.31	28.8075
1543.42	32.8553
1546.52	35.197
1549.62	38.9753
1552.72	44.0927
1555.82	48.0655
1558.92	52.37
1562.02	57.3454
1565.11	60.6059
1568.21	64.9552
1571.3	70.5785
1574.39	73.8558
1577.49	77.9266
1580.57	82.7024
1583.66	86.6108
1586.75	89.0929
1589.84	90.7103
1592.92	91.9801
1596.01	92.4427
1599.09	93.9333
1602.17	93.9575
1605.25	93.3064
1608.33	93.7258
1611.41	94.6092
1614.49	93.5679
1617.57	93.0785
1620.64	92.9556
1623.72	92.163
1626.79	94.452
1629.86	96.6599
1632.93	99.1274
1636	100.576
1639.07	104.751
1642.13	106.591
1645.2	110.631
1648.26	115.381
1651.33	118.155
1654.39	120.586
1657.45	122.735
1660.51	122.268
1663.57	120.213
1666.63	116.875
1669.68	113.167
1672.74	109.771
1675.79	105.829
1678.85	99.1936
1681.9	91.6426
1684.95	84.7973
1688	77.6769
1691.05	68.7855
1694.09	60.5199
1697.14	53.0077
1700.18	45.0151
1703.23	37.9466
1706.27	31.0293
1709.31	25.4178
1712.35	21.969
1715.39	18.4745
1718.43	15.5397
1721.47	15.3588
1724.5	12.0828
1727.54	11.2023
1730.57	10.3479
1733.61	8.91622
1736.64	7.40292
1739.67	6.78966
1742.7	6.68455
1745.72	6.20105
1748.75	5.48909
1751.77	3.92969
1754.8	3.27549
1757.82	3.48125
1760.84	3.81997
1763.87	2.51496
1766.89	2.09694
1769.91	2.86058
1772.92	1.20905
1775.94	0.367245
1778.95	0.63622
1781.97	-0.196101
1784.98	0.397587
1787.99	0.39848
1791.01	-0.418142
1794.01	-0.34417
1797.02	-0.796218
1800.03	-0.752685
1803.04	-0.986919
1806.04	-2.18191
1809.05	-2.22226
1812.05	-1.97817
1815.05	-2.03805
1818.05	-2.41843
1821.05	-1.53781
1824.05	-0.741229
1827.05	-0.161943
1830.04	0.475676
1833.04	0.417232
1836.03	0.800943
1839.03	0.856802
1842.02	2.68428
1845.01	2.96866
1848	3.43798
1850.99	4.63774
1853.97	4.41504
1856.96	4.42377
1859.94	4.69228
1862.93	4.48101
1865.91	4.61937
1868.89	5.27231
1871.87	5.00772
1874.85	4.82819
1877.83	4.39989
1880.81	5.36508
1882.57	4.75212
1885.56	5.04139
1888.55	4.73306
1891.54	6.16899
1894.52	5.58776
1897.51	4.74983
1900.49	3.87323
1903.47	4.06635
1906.45	4.53459
1909.43	5.51979
1912.41	6.34774
1915.39	6.74912
1918.37	6.24621
1921.34	6.6514
1924.32	5.71924
1927.29	5.16845
1930.26	5.24839
1933.23	4.34361
1936.2	3.9518
1939.17	3.06819
1942.14	2.97854
1945.11	2.50725
1948.07	1.72507
1951.04	1.54546
1954	2.46887
1956.96	2.76671
1959.93	4.69397
1962.89	5.32521
1965.85	5.50919
1968.8	5.55877
1971.76	6.13483
1974.72	7.46361
1977.67	8.11418
1980.63	10.0281
1983.58	11.1149
1986.53	11.8869
1989.48	12.3703
1992.43	12.2974
1995.38	12.4681
1998.32	12.5361
2001.27	12.923
2004.22	13.0007
2007.16	13.9098
2010.1	13.9894
2013.04	13.4589
2015.98	13.3331
2018.92	13.0143
2021.86	12.8833
2024.8	14.1996
2027.74	14.6209
2030.67	14.3111
2033.61	15.1847
2036.54	16.0614
2039.47	16.1554
2042.4	15.7143
2045.33	16.2374
2048.26	16.3154
2051.19	17.0956
2054.12	17.2798
2057.04	16.5945
2059.97	16.4312
2062.89	15.5459
2065.81	15.352
2068.73	15.4909
2071.65	15.5442
2074.57	16.6113
2077.49	17.5514
2080.41	16.893
2083.32	16.4612
2086.24	15.6212
2089.15	16.7985
2092.07	17.1875
2094.98	18.0484
2097.89	19.6547
2100.8	21.3848
2103.71	22.7368
2106.61	23.852
2109.52	24.123
2112.43	25.7727
2115.33	27.4478
2118.23	29.665
2121.13	31.2849
2124.04	31.81
2126.94	33.3063
2129.83	33.9047
2132.73	34.981
2135.63	35.3722
2138.53	36.4273
2141.42	37.3106
2144.31	39.5325
2147.21	38.8128
2150.1	40.0307
2152.99	41.1301
2155.88	43.14
2158.77	44.3444
2161.65	44.8051
2164.54	46.0991
2167.43	47.0598
2170.31	48.3799
2173.19	48.1216
2176.07	47.9361
2178.96	48.1377
2181.84	48.8798
2184.72	49.6075
2187.59	49.1162
2190.47	48.7515
2193.35	48.1174
2196.22	46.854
2199.09	45.8783
2201.97	44.5027
2204.84	43.4272
2207.71	42.5026
2210.58	40.9633
2213.45	40.2711
2216.31	38.1816
2219.18	34.669
2222.05	34.5677
2224.91	33.3246
2227.78	32.0808
2230.64	29.0656
2233.5	27.2982
2236.36	26.2356
2239.22	25.1899
2242.08	24.5212
2244.93	23.3569
2247.79	21.6331
2250.64	21.2014
2253.5	20.9859
2256.35	19.5199
2259.2	19.6772
2262.05	19.2718
2264.9	19.8608
2267.75	19.7827
2270.6	20.6885
2273.45	20.9138
2276.29	20.653
2279.14	19.7669
2281.98	19.4966
2284.82	19.2346
2287.66	19.7768
2290.5	19.7331
2293.34	19.7186
2296.18	19.3145
2299.02	20.182
2301.86	20.1807
2304.69	21.2877
2307.53	20.929
2310.36	20.7049
2313.19	20.0972
2316.02	20.0323
2318.85	19.9817
2321.68	19.7374
2324.51	19.4348
2327.34	18.5315
2330.16	18.937
2332.99	17.6108
2335.81	17.2053
2338.64	15.9952
2341.46	15.5889
2344.28	14.014
2347.1	12.8834
2349.92	12.9525
2352.74	12.2909
2355.55	11.9156
2358.37	11.6433
2361.19	10.6683
2364	11.8019
2366.81	12.3511
2369.62	10.9226
2372.44	10.3267
2375.24	10.3689
2378.05	9.11985
2380.86	9.01732
2383.67	9.00762
2386.47	10.0248
2389.28	8.90462
2392.08	8.63519
2394.89	8.68388
2397.69	8.17178
2400.49	7.58091
2403.29	7.45987
2406.09	8.71776
2408.88	9.49571
2411.68	9.66267
2414.48	9.02278
2417.27	10.5083
2420.06	11.2479
2422.86	11.2623
2425.65	12.4835
2428.44	12.8709
2431.23	13.9749
2434.02	14.7833
2436.81	14.42
2439.59	13.5344
2442.38	12.7572
2445.16	12.0364
2447.95	10.9869
2450.73	10.6214
2453.51	9.44922
2456.29	7.83838
2459.07	6.27046
2461.85	6.05079
2464.63	5.01357
2467.4	3.70386
2470.18	4.84897
2472.95	5.12814
2475.73	5.65614
2478.5	4.85623
2481.27	4.62668
2484.04	4.98927
2486.81	4.702
2489.58	4.23271
2492.35	4.6279
2495.12	6.47785
2497.88	7.99297
2500.65	8.88344
2503.41	9.31455
2506.17	7.95821
2508.94	7.02535
2511.7	7.49746
2514.46	5.99949
2517.22	5.75794
2519.97	5.06666
2522.73	5.50651
2525.49	4.48334
2528.24	5.24772
2530.99	5.39293
2533.75	5.53106
2536.5	5.55908
2539.25	4.97954
2542	5.12651
2544.75	4.84921
2547.5	3.9129
2550.24	3.56584
2552.99	2.83413
2555.74	2.25418
2558.48	3.23202
2561.22	3.63419
2563.96	3.60857
2566.71	3.74799
2569.45	3.68035
2572.18	2.99704
2574.92	2.39011
2577.66	1.39609
2580.4	0.784515
2583.13	-0.343318
2585.87	0.110113
2588.6	0.107999
2591.33	0.169225
2594.06	-0.148037
2596.79	-0.955349
2599.52	-0.626121
2602.25	-1.00332
2604.98	-1.56083
2607.71	-1.30843
2610.43	-0.592589
2613.16	-1.16884
2615.88	-1.21831
2618.6	-1.75203
2621.32	-1.86184
2624.04	-1.27697
2626.76	-0.922602
2629.48	-0.969343
2632.2	-0.274366
2634.92	0.670884
2637.63	1.59412
2640.35	1.24027
2643.06	1.70583
2645.77	1.80284
2648.49	2.05389
2651.2	2.46873
2653.91	3.81158
2656.62	3.66469
2659.33	4.15944
2662.03	4.81411
2664.74	3.32758
2667.44	3.74731
2670.15	3.12552
2672.85	3.28446
2675.55	3.91174
2678.26	3.87911
2680.96	3.93439
2683.66	3.90067
2686.35	3.25238
2689.05	4.43832
2691.75	5.60088
2694.44	5.48618
2697.14	6.35754
2699.83	7.55811
2702.52	9.07846
2705.22	9.86267
2707.91	10.8868
2710.6	12.09
2713.29	12.8783
2715.97	14.4671
2718.66	15.4354
2721.35	15.3239
2724.03	15.6693
2726.72	15.1727
2729.4	14.3681
2732.08	13.9617
2734.76	14.6575
2737.44	14.1522
2740.12	13.9552
2742.8	13.5757
2745.48	13.1848
2748.16	13.2623
2750.83	12.948
2753.51	11.9445
2756.18	11.9744
2758.85	11.9375
2761.53	11.2863
2764.2	10.3445
2766.87	8.92979
2769.54	8.63226
2772.2	8.49052
2774.87	7.01885
2777.54	6.24798
2780.2	6.06126
2782.87	6.15789
2785.53	4.91466
2788.19	4.08917
2790.85	3.69494
2793.51	3.64756
2796.17	3.28016
2798.83	4.556
2801.49	4.97277
2804.15	4.85258
2806.8	5.5089
2809.46	6.13903
2812.11	6.15204
2814.76	6.39668
2817.42	7.26955
2820.07	8.46336
2822.72	11.5218
2825.37	15.3198
2828.02	19.7972
2830.66	25.3961
2833.31	32.2526
2835.96	39.2322
2838.6	46.3126
2841.24	56.9057
2843.89	67.8933
2846.53	80.5008
2849.17	94.2271
2851.81	108.546
2854.45	124.932
2857.09	140.101
2859.72	155.838
2862.36	170.45
2865	182.924
2867.63	195.083
2870.26	205.805
2872.9	214.486
2875.53	222.922
2878.16	228.903
2880.79	233.918
2883.42	238.623
2886.05	244.44
2888.67	250.237
2891.3	256.653
2893.92	261.99
2896.55	269.344
2899.17	277.32
2901.79	286.6
2904.42	299.632
2907.04	314.005
2909.66	330.022
2912.27	349.617
2914.89	368.267
2917.51	385.312
2920.13	401.809
2922.74	416.265
2925.35	426.726
2927.97	433.216
2930.58	436.391
2933.19	436.111
2935.8	433.174
2938.41	426.493
2941.02	417.945
2943.63	406.023
2946.24	392.378
2948.84	378.299
2951.45	362.173
2954.05	345.474
2956.65	328.309
2959.26	311.344
2961.86	296.744
2964.46	282.847
2967.06	269.72
2969.66	257.929
2972.25	246.272
2974.85	236.527
2977.45	225.913
2980.04	214.762
2982.64	203.326
2985.23	190.506
2987.82	177.729
2990.41	163.401
2993	149.567
2995.59	136.621
2998.18	124.236
3000.77	112.099
3003.36	100.634
3005.94	89.5182
3008.53	78.2784
3011.11	69.4116
3013.69	61.2365
3016.28	53.6153
3018.86	48.368
3021.44	43.2651
3024.02	39.8245
3026.6	37.3024
3029.18	36.0521
3031.75	33.9159
3034.33	33.6172
3036.9	33.7586
3039.48	35.3174
3042.05	36.9328
3044.62	38.6312
3047.19	40.4616
3049.77	42.0455
3052.34	43.81
3054.9	45.1498
3057.47	45.33
3060.04	45.3374
3062.61	44.3581
3065.17	42.6873
3067.74	40.2636
3070.3	38.3245
3072.86	34.97
3075.42	32.2011
3077.99	28.1006
3080.54	24.8228
3083.1	21.8523
3085.66	18.4292
3088.22	16.2949
3090.78	13.8092
3093.33	11.3687
3095.89	9.6531
3098.44	8.47569
3100.99	6.38707
3103.54	6.61911
3106.1	6.84329
3108.65	6.53063
3111.2	5.63796
3113.74	4.54549
3116.29	4.21121
3118.84	3.79183
3121.38	3.19023
3123.93	2.09692
3126.47	1.40308
3129.01	0.435525
3131.56	-0.472786
3134.1	-1.00561
3136.64	-1.37835
3139.18	-0.982377
3141.72	-0.747514
3144.26	0.345127
3146.79	0.770034
3149.33	0.436148