File: data/Raman/poly_smoothed/Thy_20_09_33_1x_45s_532 nm_x100_100%_600 gr_mm_01.txt
#Acq. time (s)=	45
#Accumulations=	2
#Range (cm-¹)=	200...3150
#Windows=	2
#Auto scanning=	Off
#Autofocus=	Off
#Macrospot=	Off
#AutoExposure=	Off
#Spike filter=	Multiple accum.
#Delay time (s)=	0
#Binning=	1
#Readout mode=	Signal
#DeNoise=	Off
#ICS correction=	On
#Dark correction=	Off
#Inst. Process=	Off
#Detector Gain=	Best Dynamic Range
#Detector ADC=	20 kHz
#Detector temperature (°C)=	-69.85
#Instrument=	LabRAM HR Evol
#Detector=	Synapse
#Objective=	x100
#Grating=	600 gr/mm
#ND Filter=	100%
#Laser (nm)=	532
#Hole=	100.021
#Range=	Auto
#Laser Pol.=	No
#Raman. Pol.=	No
#Laser Pol. (°)=	-0.0007625
#Raman Pol. (°)=	89.9995
#Collection=	Microscope
#StageXY=	Marzhauser
#StageZ=	Marzhauser
#X (µm)=	-5916
#Y (µm)=	2874
#Z (µm)=	-222.75
#Full time(mm:ss)=	3:15
#Project=
#Sample=
#Site=
#Title=	Thy_20_09_33_2x_45s_532 nm_x100_100%_600 gr_mm
#Remark=
#Date=	29.06.2022 12:58
#Acquired=	29.06.2022 12:58:25
#Base:Fit=	10.08.2022 09:52:02
#Base:Fit=	10.08.2022 09:52:12
#Base:Sub=	10.08.2022 09:54:21
#Filter:Polynom=	16.08.2022 10:24:04
#AxisType[0]=Intens
#AxisUnit[0]=Cnt
#AxisType[1]=Spectr
#AxisUnit[1]=1/cm
200.523	21.8577
204.154	18.1268
207.781	17.4102
211.409	16.3633
215.034	14.7241
218.659	13.0248
222.281	10.1353
225.903	9.67938
229.522	10.1067
233.14	9.69266
236.756	8.91403
240.373	6.7233
243.986	6.80055
247.598	6.9827
251.208	7.87925
254.818	6.95076
258.427	6.42932
262.034	6.15491
265.638	6.47297
269.242	5.93113
272.844	7.5281
276.445	8.6312
280.044	7.83866
283.642	9.21422
287.238	9.34749
290.833	10.5971
294.425	11.3247
298.017	11.9521
301.608	12.2941
305.198	13.7162
308.786	15.2245
312.371	16.9656
315.956	18.8193
319.54	18.9314
323.122	19.1592
326.701	19.0514
330.281	19.7181
333.857	20.2721
337.434	18.8006
341.008	17.3888
344.582	16.376
348.153	14.6041
351.724	14.2686
355.292	13.4038
358.861	10.9278
362.426	9.19662
365.99	6.43868
369.555	5.63735
373.116	5.35597
376.676	4.37766
380.236	5.1079
383.793	5.65096
387.349	6.02504
390.903	6.08608
394.456	6.82062
398.007	8.27792
401.56	8.81461
405.108	8.47312
408.656	8.8004
412.202	10.2907
415.746	10.543
419.29	11.3001
422.831	10.2957
426.37	10.8187
429.909	10.5833
433.447	11.381
436.983	11.2221
440.519	10.0568
444.052	8.83154
447.583	7.44439
451.114	7.66003
454.643	8.03438
458.169	8.55556
461.696	8.90937
465.222	9.8242
468.744	11.5926
472.267	11.0905
475.787	11.7194
479.307	13.1041
482.823	14.6498
486.341	16.1753
489.855	16.0123
493.37	16.9532
496.881	18.082
500.391	18.3967
503.902	18.5107
507.409	17.9207
510.915	16.5931
514.42	16.1273
517.925	14.9199
521.427	14.5722
524.928	13.7576
528.427	12.2734
531.925	11.9907
535.422	12.1507
538.917	13.5945
542.411	14.9621
545.903	14.1854
549.395	15.0868
552.884	14.9934
556.373	13.9757
559.86	13.5501
563.346	15.013
566.831	15.6214
570.314	15.9468
573.794	15.0437
577.274	13.2329
580.754	11.9459
584.23	10.7261
587.706	9.44326
591.181	8.1607
594.653	7.32978
598.126	6.69595
601.595	5.75762
605.065	4.80873
608.532	7.61306
611.999	7.96987
615.463	9.45306
618.928	11.6347
622.389	12.1944
625.851	12.6067
629.31	12.0582
632.767	13.0336
636.223	13.7006
639.68	14.2087
643.134	16.4189
646.586	17.4852
650.037	19.6856
653.486	19.8883
656.936	21.0153
660.383	21.4299
663.829	21.4421
667.273	22.8898
670.716	23.5718
674.158	26.1853
677.598	27.8758
681.035	28.5261
684.473	28.2596
687.909	30.3494
691.344	31.8147
694.778	34.2207
698.211	34.3457
701.64	34.8891
705.07	35.2124
708.498	35.5053
711.924	38.3205
715.35	38.9243
718.774	40.2909
722.196	41.1314
725.618	42.2829
729.037	44.2463
732.456	47.2079
735.873	48.5633
739.289	50.6395
742.703	52.2588
746.116	53.0509
749.529	55.3652
752.938	57.2347
756.347	60.8256
759.756	62.3468
763.162	64.1751
766.567	65.5393
769.97	69.1739
773.372	71.0084
776.773	73.4455
780.174	75.3513
783.573	77.346
786.97	79.2319
790.365	80.3186
793.76	81.6053
797.153	83.1737
800.543	82.971
803.933	84.5772
807.322	85.123
810.71	84.1324
814.097	83.8179
817.483	83.3445
820.865	83.1882
824.248	83.6403
827.629	81.9127
831.008	79.8901
834.387	78.8418
837.765	77.86
841.139	76.7636
844.514	74.1887
847.886	72.5
851.259	70.1249
854.629	68.0566
857.997	65.9136
861.366	64.8852
864.732	64.0736
868.098	62.9014
871.461	60.9311
874.823	58.3813
878.184	57.2415
881.545	55.6211
884.903	54.8661
888.26	52.8414
891.616	51.3302
894.97	50.8413
898.323	50.8773
901.675	51.5491
905.026	51.8761
908.375	50.4628
911.723	49.3017
915.07	47.5634
918.415	48.0085
921.76	45.5973
925.103	44.5415
928.443	43.7029
931.783	43.1665
935.123	42.1064
938.461	41.8054
941.796	41.2803
945.131	41.0363
948.465	40.0833
951.797	38.7786
955.128	37.4505
958.457	35.9673
961.786	35.6287
965.113	35.3743
968.44	35.6879
971.763	35.5886
975.086	35.3979
978.409	35.8731
981.729	35.3088
985.048	35.3313
988.367	35.1875
991.683	34.0476
994.998	32.8659
998.312	32.2415
1001.62	31.7936
1004.94	32.5137
1008.25	33.2657
1011.56	31.7297
1014.86	29.7457
1018.17	28.1852
1021.48	26.1177
1024.78	24.5772
1028.08	22.9877
1031.38	23.3592
1034.68	21.5837
1037.98	18.554
1041.28	17.212
1044.57	15.9364
1047.87	15.5289
1051.16	14.7029
1054.45	15.1777
1057.75	14.4726
1061.04	13.8917
1064.32	12.737
1067.61	11.483
1070.9	11.2405
1074.18	11.0278
1077.47	11.2023
1080.75	12.0826
1084.03	12.2427
1087.31	13.3079
1090.59	12.3249
1093.86	12.1652
1097.14	13.122
1100.41	12.9197
1103.69	13.3299
1106.96	13.4298
1110.23	12.738
1113.5	12.4395
1116.77	11.3122
1120.03	9.57727
1123.3	8.79355
1126.56	8.63866
1129.83	8.25127
1133.09	8.00361
1136.35	7.48074
1139.61	7.68951
1142.86	7.46225
1146.12	7.7448
1149.38	7.45195
1152.63	7.3498
1155.88	6.65114
1159.14	5.76
1162.39	6.32698
1165.63	6.51728
1168.88	7.2999
1172.13	6.22662
1175.38	6.49358
1178.62	8.12415
1181.86	7.79577
1185.1	7.90067
1188.34	6.94016
1191.58	6.76715
1194.82	7.14499
1198.06	7.46514
1201.29	8.88095
1204.53	10.3045
1207.76	12.0989
1210.99	14.3495
1214.22	16.6547
1217.45	20.3571
1220.68	22.6587
1223.91	24.4077
1227.13	25.9961
1230.36	26.202
1233.58	27.6021
1236.8	29.457
1240.02	30.1875
1243.24	31.7644
1246.46	32.7545
1249.67	31.8827
1252.89	32.0504
1256.1	32.9583
1259.32	32.9108
1262.53	32.2289
1265.74	32.7139
1268.95	32.7068
1272.15	34.0906
1275.36	36.217
1278.57	35.7015
1281.77	36.9468
1284.97	37.9037
1288.18	38.374
1291.38	39.4014
1294.58	41.8242
1297.78	42.0254
1300.97	42.4875
1304.17	42.5459
1307.36	42.7603
1310.55	43.4233
1313.75	45.1227
1316.94	45.7528
1320.13	46.5339
1323.32	46.6082
1326.5	46.8666
1329.69	45.8504
1332.87	45.8673
1336.06	45.5309
1339.24	45.3072
1342.42	45.7305
1345.6	46.4149
1348.78	44.711
1351.96	43.3694
1355.13	43.4648
1358.31	41.6166
1361.48	40.381
1364.65	39.0198
1367.82	37.162
1370.99	36.2492
1374.16	33.3029
1377.33	32.7518
1380.5	31.2883
1383.66	30.9313
1386.83	29.7014
1389.99	29.0373
1393.15	28.0021
1396.31	27.4845
1399.47	26.1286
1402.63	25.477
1405.78	25.0397
1408.94	25.7997
1412.1	26.2094
1415.25	28.4889
1418.4	30.6431
1421.55	33.3308
1424.7	36.0498
1427.85	39.3144
1431	43.5355
1434.14	47.1235
1437.29	50.1278
1440.43	53.5698
1443.57	56.2417
1446.71	56.4878
1449.85	56.5865
1452.99	56.2517
1456.13	56.7687
1459.26	54.9936
1462.4	53.4758
1465.54	50.523
1468.67	45.731
1471.8	41.2056
1474.93	37.4681
1478.06	31.8283
1481.19	28.3434
1484.31	23.6085
1487.44	20.3754
1490.56	17.8521
1493.69	15.8308
1496.81	13.3184
1499.93	12.6784
1503.05	11.4612
1506.17	10.8841
1509.28	11.4239
1512.4	11.6692
1515.52	13.2151
1518.63	14.1771
1521.74	13.9037
1524.85	15.308
1527.96	17.6685
1531.07	20.0169
1534.18	22.4229
1537.29	24.524
1540.39	26.2676
1543.5	28.5126
1546.6	29.8811
1549.7	30.9465
1552.8	31.8328
1555.9	33.3764
1559	34.739
1562.1	36.6929
1565.19	38.3814
1568.29	39.1057
1571.38	41.2833
1574.47	43.2153
1577.56	44.5874
1580.66	44.0887
1583.74	45.2088
1586.83	45.809
1589.92	45.972
1593.01	45.9927
1596.09	45.3343
1599.17	43.9959
1602.25	43.8404
1605.34	43.6467
1608.41	42.5481
1611.49	42.5593
1614.57	41.4158
1617.65	40.3229
1620.72	38.8572
1623.79	38.1886
1626.87	38.5738
1629.94	39.5372
1633.01	41.1737
1636.08	43.4692
1639.15	44.2911
1642.21	45.2034
1645.28	47.7583
1648.34	49.9012
1651.41	50.8117
1654.47	50.3376
1657.53	51.11
1660.59	50.9719
1663.65	50.5446
1666.71	48.7536
1669.76	46.5626
1672.82	43.67
1675.87	40.5201
1678.93	38.8737
1681.98	34.8905
1685.03	30.6206
1688.08	26.9137
1691.13	23.5884
1694.17	19.1615
1697.22	17.6792
1700.27	15.7211
1703.31	13.3698
1706.35	10.7573
1709.39	8.54299
1712.43	6.77641
1715.47	4.35206
1718.51	4.04024
1721.55	3.44831
1724.58	2.50889
1727.62	2.41157
1730.65	2.07172
1733.68	2.97234
1736.72	3.06976
1739.74	2.33929
1742.77	2.48282
1745.8	2.36963
1748.83	2.25335
1751.85	2.39165
1754.88	2.6241
1757.9	2.93929
1760.92	3.21579
1763.95	3.11089
1766.96	3.14718
1769.98	4.15184
1773	4.098
1776.02	3.50022
1779.03	3.53304
1782.05	3.08021
1785.06	3.29857
1788.07	3.34346
1791.08	3.78511
1794.09	3.28647
1797.1	3.52787
1800.11	2.88505
1803.12	2.83746
1806.12	3.74833
1809.12	3.68645
1812.13	3.77416
1815.13	3.36388
1818.13	3.8358
1821.13	3.43817
1824.13	3.21665
1827.13	3.97691
1830.12	3.97864
1833.12	4.62329
1836.11	4.54824
1839.1	4.82647
1842.09	4.49209
1845.09	4.012
1848.08	3.24533
1851.06	2.92992
1854.05	2.99081
1857.04	3.20885
1860.02	2.73072
1863.01	2.94895
1865.99	2.60643
1868.97	2.67718
1871.95	2.93913
1874.93	3.12803
1877.91	3.3238
1880.89	3.21066
1882.46	3.33128
1885.45	3.61385
1888.43	4.23931
1891.42	4.1571
1894.41	4.63744
1897.39	5.64552
1900.37	6.55396
1903.36	7.44831
1906.34	7.36139
1909.32	7.94787
1912.29	7.56925
1915.27	7.5018
1918.25	7.25038
1921.23	7.15811
1924.2	7.35224
1927.17	7.81868
1930.15	7.11919
1933.12	6.26809
1936.09	6.20177
1939.06	6.08341
1942.02	5.46089
1944.99	4.35129
1947.96	3.82936
1950.92	2.58858
1953.88	2.65805
1956.85	3.04216
1959.81	1.64364
1962.77	1.43066
1965.73	1.39364
1968.69	1.72407
1971.64	2.27864
1974.6	2.55089
1977.55	3.48483
1980.51	3.58418
1983.46	3.65152
1986.41	3.67732
1989.36	3.99185
1992.31	3.63298
1995.26	4.33325
1998.21	4.40203
2001.15	4.60739
2004.1	4.03368
2007.04	4.17704
2009.99	4.27725
2012.93	4.63916
2015.87	5.59714
2018.81	5.79492
2021.75	6.67932
2024.68	7.8187
2027.62	8.38736
2030.56	8.99407
2033.49	8.52852
2036.42	9.58265
2039.36	10.2539
2042.29	10.3778
2045.22	10.7453
2048.14	11.3393
2051.07	10.9849
2054	10.4696
2056.93	9.98528
2059.85	9.73135
2062.77	9.03805
2065.7	10.6111
2068.62	10.0538
2071.54	9.74505
2074.46	9.86226
2077.38	10.7291
2080.29	11.1852
2083.21	11.2398
2086.12	11.9124
2089.04	11.9859
2091.95	11.2207
2094.86	11.6546
2097.77	11.0454
2100.68	10.7035
2103.59	11.128
2106.5	10.1573
2109.41	10.8636
2112.31	11.5251
2115.21	13.0582
2118.12	14.2625
2121.02	14.7235
2123.92	15.9716
2126.82	17.5116
2129.72	17.756
2132.62	18.068
2135.51	19.5457
2138.41	21.9417
2141.31	23.2237
2144.2	24.9268
2147.09	26.9254
2149.98	27.9549
2152.87	28.4721
2155.76	29.51
2158.65	29.958
2161.54	29.7611
2164.43	30.644
2167.31	30.6769
2170.2	30.6617
2173.08	30.0149
2175.96	30.6382
2178.84	31.3226
2181.72	32.0427
2184.6	31.9367
2187.48	31.3364
2190.36	30.6248
2193.23	30.8573
2196.11	29.484
2198.98	27.8997
2201.85	25.5819
2204.72	25.6566
2207.59	25.1546
2210.46	24.3529
2213.33	23.4724
2216.2	21.8175
2219.07	20.3671
2221.93	18.7106
2224.8	17.1709
2227.66	15.7464
2230.52	14.7504
2233.39	13.2832
2236.25	12.874
2239.1	11.7412
2241.96	10.9197
2244.82	10.8889
2247.68	10.6055
2250.53	10.37
2253.38	10.4049
2256.24	10.7331
2259.09	10.8397
2261.94	11.0614
2264.79	11.1206
2267.64	10.3129
2270.49	9.89897
2273.33	10.0936
2276.18	10.7143
2279.02	9.90948
2281.87	10.8409
2284.71	10.0119
2287.55	9.17241
2290.39	8.25494
2293.23	7.06087
2296.07	7.23477
2298.91	7.21978
2301.74	7.2302
2304.58	8.22533
2307.41	8.16493
2310.25	9.0003
2313.08	9.05905
2315.91	9.6983
2318.74	9.83588
2321.57	9.29028
2324.4	9.57336
2327.23	9.07864
2330.05	7.97401
2332.88	7.79955
2335.7	6.43278
2338.52	5.95715
2341.35	5.67607
2344.17	5.19688
2346.99	4.76097
2349.81	3.82643
2352.62	2.68865
2355.44	1.66159
2358.26	1.6298
2361.07	0.446736
2363.89	1.06493
2366.7	2.12631
2369.51	2.65269
2372.32	4.0417
2375.13	3.43229
2377.94	4.41146
2380.75	4.91974
2383.56	4.99358
2386.36	4.85123
2389.17	4.55926
2391.97	5.00735
2394.77	4.32722
2397.58	4.47125
2400.38	3.92355
2403.18	4.01827
2405.97	4.91125
2408.77	5.00967
2411.57	4.37807
2414.37	3.8801
2417.16	4.07131
2419.95	3.53924
2422.75	3.72596
2425.54	2.84821
2428.33	2.79824
2431.12	1.8063
2433.91	1.83048
2436.7	1.42841
2439.48	1.52964
2442.27	1.39019
2445.05	1.80033
2447.84	1.59997
2450.62	1.22824
2453.4	1.23774
2456.18	0.805489
2458.96	1.1949
2461.74	0.808646
2464.52	0.482268
2467.29	1.09696
2470.07	1.92376
2472.85	3.09902
2475.62	3.21175
2478.39	2.40628
2481.16	2.61199
2483.93	3.14664
2486.7	3.74398
2489.47	3.72506
2492.24	4.06119
2495.01	3.86101
2497.77	3.73094
2500.54	4.2588
2503.3	4.24124
2506.06	4.98138
2508.83	4.53746
2511.59	4.49693
2514.35	4.23263
2517.11	3.41573
2519.86	3.96354
2522.62	3.73915
2525.38	4.28469
2528.13	4.52702
2530.89	4.85266
2533.64	5.42753
2536.39	5.97429
2539.14	5.52945
2541.89	5.43221
2544.64	5.41021
2547.39	6.08867
2550.14	6.64326
2552.88	6.78039
2555.63	6.77415
2558.37	6.88974
2561.11	7.04513
2563.86	6.88265
2566.6	6.46288
2569.34	5.84708
2572.08	5.42457
2574.82	4.6381
2577.55	5.06187
2580.29	4.92864
2583.02	4.83033
2585.76	5.73922
2588.49	5.93277
2591.22	5.26415
2593.96	5.85304
2596.69	5.77716
2599.42	5.00263
2602.14	4.2066
2604.87	3.65475
2607.6	3.45907
2610.32	2.93649
2613.05	2.61449
2615.77	2.18678
2618.49	1.65985
2621.22	0.827934
2623.94	1.39201
2626.66	1.13276
2629.37	1.02014
2632.09	0.289738
2634.81	0.979443
2637.53	1.67364
2640.24	2.8299
2642.96	2.69693
2645.67	3.833
2648.38	4.02883
2651.09	4.18528
2653.8	4.88748
2656.51	4.62889
2659.22	4.77664
2661.93	4.17316
2664.63	3.34841
2667.34	3.2557
2670.04	3.14182
2672.75	3.38933
2675.45	3.33043
2678.15	3.31702
2680.85	3.63614
2683.55	3.18265
2686.25	3.75578
2688.94	3.83547
2691.64	3.80056
2694.34	3.9032
2697.03	4.1946
2699.73	4.42298
2702.42	5.23213
2705.11	5.87356
2707.8	6.82467
2710.49	8.15154
2713.18	8.0873
2715.87	8.61104
2718.55	8.63514
2721.24	8.9017
2723.93	8.65614
2726.61	9.00914
2729.29	8.79311
2731.98	8.8329
2734.66	8.98492
2737.34	7.82036
2740.02	7.57746
2742.7	7.80054
2745.37	6.70042
2748.05	6.59213
2750.72	5.91899
2753.4	4.92741
2756.07	2.87713
2758.75	2.08889
2761.42	1.94063
2764.09	1.13965
2766.76	1.22401
2769.43	1.69823
2772.1	2.06142
2774.76	2.52556
2777.43	2.00942
2780.1	1.41602
2782.76	1.56693
2785.42	1.64028
2788.09	1.71799
2790.75	1.39434
2793.41	1.59515
2796.07	1.35112
2798.73	1.2853
2801.39	0.607939
2804.04	0.73506
2806.7	0.962103
2809.35	-0.225834
2812.01	-0.749677
2814.66	-1.46669
2817.31	-1.90211
2819.96	-1.16771
2822.61	-0.0446779
2825.26	2.3128
2827.91	5.11487
2830.56	8.39607
2833.21	11.2971
2835.85	14.0175
2838.5	17.3509
2841.14	21.0205
2843.78	25.1151
2846.42	30.4361
2849.06	35.9591
2851.71	40.9941
2854.34	45.9364
2856.98	51.501
2859.62	56.8196
2862.26	61.0224
2864.89	64.7053
2867.53	68.3178
2870.16	72.4893
2872.79	74.429
2875.42	75.7527
2878.05	78.0987
2880.68	80.0531
2883.31	82.9208
2885.94	84.0835
2888.57	86.4491
2891.19	89.129
2893.82	91.025
2896.44	93.1685
2899.07	95.1886
2901.69	98.1743
2904.31	101.93
2906.93	106.036
2909.55	110.498
2912.17	116.822
2914.79	122.605
2917.41	126.906
2920.02	131.584
2922.64	134.971
2925.25	136.614
2927.86	137.485
2930.48	138.018
2933.09	137.947
2935.7	136.627
2938.31	133.13
2940.92	129.454
2943.53	126.719
2946.13	122.28
2948.74	116.918
2951.34	111.727
2953.95	106.555
2956.55	101.264
2959.15	95.2935
2961.75	89.5752
2964.35	83.3722
2966.95	79.0494
2969.55	75.1056
2972.15	70.7973
2974.75	67.019
2977.34	62.7172
2979.94	57.9851
2982.53	53.294
2985.13	48.171
2987.72	42.6444
2990.31	37.3266
2992.9	33.7219
2995.49	29.8327
2998.08	26.1523
3000.67	21.8876
3003.25	18.0817
3005.84	15.1308
3008.42	12.5387
3011.01	9.6588
3013.59	7.17443
3016.17	5.38118
3018.76	4.32171
3021.34	2.90119
3023.92	0.5676
3026.49	0.819893
3029.07	0.686687
3031.65	2.07596
3034.23	2.07271
3036.8	2.59042
3039.38	2.80483
3041.95	4.04518
3044.52	5.16362
3047.09	6.29554
3049.66	7.05155
3052.23	8.69469
3054.8	9.03608
3057.37	9.45477
3059.94	10.5014
3062.5	9.75309
3065.07	9.6722
3067.63	9.28404
3070.2	7.89011
3072.76	7.2894
3075.32	6.36627
3077.88	5.3883
3080.44	4.75538
3083	2.08164
3085.56	1.19578
3088.12	0.311517
3090.67	0.688181
3093.23	0.590681
3095.78	1.17296
3098.34	1.26601
3100.89	1.30318
3103.44	1.58861
3105.99	2.65501
3108.54	4.21183
3111.09	5.03191
3113.64	6.39148
3116.19	6.92683
3118.74	7.99563
3121.28	9.07341
3123.83	9.975
3126.37	9.98356
3128.91	11.6203
3131.46	11.8496
3134	11.9163
3136.54	12.7591
3139.08	12.7911
3141.62	12.9934
3144.16	13.1054
3146.69	14.0894
3149.23	15.6358