File: data/Raman/poly_smoothed/Thy_10_08_01_1x_45s_532 nm_x100_100%_600 gr_mm_01.txt
#Acq. time (s)=	45
#Accumulations=	2
#Range (cm-¹)=	200...3150
#Windows=	2
#Auto scanning=	Off
#Autofocus=	Off
#Macrospot=	Off
#AutoExposure=	Off
#Spike filter=	Multiple accum.
#Delay time (s)=	0
#Binning=	1
#Readout mode=	Signal
#DeNoise=	Off
#ICS correction=	On
#Dark correction=	Off
#Inst. Process=	Off
#Detector Gain=	Best Dynamic Range
#Detector ADC=	20 kHz
#Detector temperature (°C)=	-69.85
#Instrument=	LabRAM HR Evol
#Detector=	Synapse
#Objective=	x100
#Grating=	600 gr/mm
#ND Filter=	100%
#Laser (nm)=	532
#Hole=	100.021
#Range=	Auto
#Laser Pol.=	No
#Raman. Pol.=	No
#Laser Pol. (°)=	-0.0007625
#Raman Pol. (°)=	89.9995
#Collection=	Microscope
#StageXY=	Marzhauser
#StageZ=	Marzhauser
#X (µm)=	2153.4
#Y (µm)=	1210
#Z (µm)=	442.85
#Full time(mm:ss)=	3:19
#Project=
#Sample=
#Site=
#Title=	Thy_10_08_01_2x_45s_532 nm_x100_100%_600 gr_mm
#Remark=
#Date=	05.07.2022 14:14
#Acquired=	05.07.2022 14:14:41
#Base:Fit=	10.08.2022 09:45:33
#Base:Fit=	10.08.2022 09:46:03
#Base:Fit=	10.08.2022 09:46:25
#Base:Sub=	10.08.2022 09:46:49
#Filter:Polynom=	16.08.2022 10:24:56
#AxisType[0]=Intens
#AxisUnit[0]=Cnt
#AxisType[1]=Spectr
#AxisUnit[1]=1/cm
200.43	-0.224458
204.059	2.10463
207.688	3.53846
211.314	4.29375
214.941	4.8153
218.564	5.68589
222.186	5.74445
225.809	5.36241
229.428	4.52751
233.045	3.42383
236.663	3.43386
240.278	3.39583
243.891	3.48334
247.503	3.53171
251.116	3.39965
254.725	2.07232
258.333	2.41823
261.939	3.23895
265.544	3.04084
269.148	3.724
272.75	4.38853
276.351	6.07201
279.95	6.20706
283.548	5.42965
287.144	5.93051
290.739	7.59581
294.333	8.93683
297.925	10.4555
301.514	10.5234
305.104	12.0396
308.692	12.9135
312.279	13.5435
315.862	13.5768
319.446	13.4999
323.029	14.6813
326.608	15.4413
330.188	16.7186
333.766	16.4061
337.341	16.5011
340.917	16.8181
344.489	17.4278
348.062	17.6134
351.631	18.5195
355.201	18.1141
358.768	17.8783
362.333	16.5633
365.899	14.1528
369.462	13.5054
373.023	13.9367
376.585	15.632
380.143	14.1323
383.7	12.8819
387.256	12.2593
390.812	12.3873
394.365	11.7947
397.916	11.3598
401.467	9.02394
405.015	7.87978
408.563	6.65581
412.109	6.52072
415.654	5.41124
419.197	4.46886
422.739	3.94416
426.279	4.5854
429.819	4.16743
433.356	4.37121
436.891	4.2294
440.426	4.85792
443.96	4.4428
447.492	4.65155
451.021	6.16543
454.551	7.75094
458.079	10.8823
461.604	11.7912
465.13	12.8877
468.654	15.4282
472.175	17.2672
475.696	18.4015
479.215	17.8827
482.733	17.8015
486.249	17.8405
489.765	17.6725
493.278	17.3448
496.789	17.3439
500.301	16.2924
503.81	15.3689
507.317	15.2747
510.825	15.7666
514.33	14.3741
517.833	14.911
521.335	14.3319
524.836	14.4108
528.335	15.316
531.835	15.3527
535.332	15.1407
538.827	16.1753
542.321	15.7738
545.814	15.8322
549.305	16.2854
552.795	16.4624
556.282	16.0473
559.769	14.643
563.255	13.6775
566.739	13.2661
570.223	12.1302
573.705	10.4227
577.183	8.85896
580.663	8.04381
584.141	7.16444
587.615	7.38683
591.09	7.50462
594.564	6.97246
598.035	6.53186
601.506	7.08683
604.974	7.33534
608.443	8.46087
611.908	9.58515
615.374	9.44126
618.837	9.85142
622.3	11.3898
625.761	12.0665
629.219	13.7827
632.677	14.9922
636.135	16.2302
639.59	17.8468
643.043	19.0918
646.495	20.7634
649.948	21.4812
653.398	23.2792
656.846	22.7841
660.293	23.6466
663.738	24.7357
667.183	25.4884
670.626	29.5432
674.067	31.2046
677.508	31.9763
680.947	31.7294
684.385	31.8566
687.821	32.3365
691.254	33.7082
694.688	34.3699
698.121	34.626
701.552	34.2046
704.98	36.1882
708.409	37.5068
711.836	38.8453
715.26	40.5833
718.685	42.4555
722.108	44.1686
725.528	46.4717
728.949	48.1648
732.367	50.0624
735.785	52.2331
739.2	54.1569
742.614	55.7708
746.028	58.8458
749.439	61.7215
752.849	66.0805
756.26	69.8691
759.667	72.208
763.073	72.9596
766.477	73.8927
769.883	75.5887
773.285	77.4088
776.686	78.6186
780.085	80.2064
783.484	81.6984
786.881	83.8188
790.276	86.9316
793.671	88.3379
797.064	90.907
800.456	92.7682
803.846	93.3431
807.234	93.3484
810.622	92.3294
814.008	93.0493
817.394	92.1093
820.778	90.5691
824.159	89.6659
827.541	89.2759
830.921	87.8361
834.298	85.3651
837.676	83.0486
841.051	80.4642
844.426	78.0662
847.798	74.5606
851.171	71.6199
854.54	68.9509
857.911	67.3385
861.278	66.8255
864.645	65.6432
868.01	64.944
871.373	65.6777
874.735	65.0057
878.097	64.9874
881.457	65.98
884.815	65.5292
888.172	64.0102
891.528	64.1231
894.882	64.7438
898.237	64.7118
901.589	62.8278
904.94	61.1628
908.289	60.0931
911.635	59.7008
914.982	57.1805
918.328	54.5414
921.672	55.0539
925.015	54.2437
928.357	53.588
931.698	51.4089
935.035	50.5227
938.373	48.7646
941.71	47.2687
945.044	46.2428
948.378	45.8423
951.709	46.3089
955.041	45.072
958.372	43.2137
961.699	42.3369
965.027	42.8387
968.352	42.6991
971.676	44.2597
975	44.9254
978.322	45.6976
981.642	44.5745
984.962	42.4268
988.28	41.0294
991.596	41.5179
994.911	41.6522
998.227	41.4405
1001.54	41.2326
1004.85	41.1809
1008.16	39.8914
1011.47	39.2153
1014.78	36.5367
1018.08	34.5562
1021.39	31.9022
1024.69	29.5845
1028	28.8364
1031.3	27.2998
1034.6	24.4844
1037.9	21.7483
1041.19	20.0681
1044.49	19.8782
1047.78	20.9806
1051.08	20.4959
1054.37	20.7626
1057.66	19.6401
1060.95	19.2513
1064.24	18.9422
1067.53	19.7287
1070.81	19.4551
1074.1	20.9823
1077.38	19.4329
1080.66	18.4057
1083.94	17.973
1087.22	18.0475
1090.5	16.409
1093.78	16.3041
1097.05	15.7571
1100.33	17.7447
1103.6	17.9593
1106.87	15.9782
1110.14	16.5965
1113.41	16.5109
1116.68	14.2918
1119.95	13.0946
1123.21	12.3847
1126.48	11.4143
1129.74	11.3451
1133	10.6564
1136.26	9.62265
1139.52	9.59795
1142.78	8.07147
1146.04	7.93015
1149.29	8.07092
1152.55	7.9514
1155.8	7.02555
1159.05	5.7958
1162.3	5.31253
1165.55	5.88741
1168.8	6.10435
1172.05	6.71205
1175.29	9.49726
1178.54	10.5636
1181.78	13.2342
1185.02	14.0899
1188.26	12.6378
1191.5	12.8572
1194.74	14.7448
1197.97	15.4055
1201.21	16.1805
1204.44	17.7863
1207.68	18.9421
1210.91	20.0989
1214.14	22.5958
1217.37	23.4941
1220.59	25.7272
1223.82	27.6873
1227.05	30.8085
1230.27	31.6301
1233.49	32.8349
1236.72	32.5167
1239.94	34.4218
1243.16	34.6503
1246.37	36.2367
1249.59	36.6978
1252.8	36.6623
1256.02	37.782
1259.23	38.0779
1262.44	36.7991
1265.66	36.6432
1268.86	36.429
1272.07	37.3928
1275.28	37.5103
1278.48	36.469
1281.69	37.1581
1284.89	37.9144
1288.09	38.2347
1291.29	39.8489
1294.49	40.1162
1297.69	39.5861
1300.89	40.856
1304.08	42.4362
1307.28	44.904
1310.47	46.6313
1313.66	47.587
1316.85	47.4908
1320.04	49.7477
1323.23	49.6065
1326.42	49.6992
1329.61	49.1078
1332.79	49.1394
1335.97	49.898
1339.16	50.8381
1342.34	50.2309
1345.52	49.1821
1348.7	48.5261
1351.87	47.7131
1355.05	45.4796
1358.22	45.0665
1361.4	42.8147
1364.57	41.7862
1367.74	38.4943
1370.91	36.8339
1374.08	34.9145
1377.25	33.5258
1380.41	33.35
1383.58	32.2711
1386.74	30.9532
1389.91	29.2397
1393.07	27.8015
1396.23	26.2827
1399.39	25.2111
1402.55	25.4768
1405.7	24.8141
1408.86	25.505
1412.01	28.3121
1415.17	30.5702
1418.32	32.2138
1421.47	33.5431
1424.62	35.8057
1427.77	39.1496
1430.91	42.2745
1434.06	44.4742
1437.2	47.0491
1440.35	48.8447
1443.49	51.0551
1446.63	51.434
1449.77	51.5619
1452.91	52.6293
1456.05	51.4735
1459.18	51.0474
1462.32	48.8955
1465.45	46.4532
1468.59	43.4845
1471.72	39.6084
1474.85	35.9926
1477.98	32.902
1481.1	28.8381
1484.23	26.0983
1487.36	23.7583
1490.48	20.4241
1493.61	17.7945
1496.73	15.1979
1499.85	12.8371
1502.97	12.5617
1506.09	11.6626
1509.2	12.3738
1512.32	11.4158
1515.43	12.5228
1518.55	12.9835
1521.66	13.5353
1524.77	16.1068
1527.88	16.957
1530.99	17.3725
1534.1	19.1313
1537.21	19.0332
1540.31	20.7011
1543.42	22.5076
1546.52	25.3659
1549.62	26.566
1552.72	28.9495
1555.82	31.3926
1558.92	34.1174
1562.02	36.7389
1565.11	39.251
1568.21	41.0614
1571.3	43.1197
1574.39	46.1408
1577.49	49.2949
1580.57	50.504
1583.66	51.636
1586.75	54.1033
1589.84	55.4545
1592.92	56.8171
1596.01	56.2231
1599.09	55.8364
1602.17	53.8615
1605.25	52.4796
1608.33	51.4893
1611.41	50.0949
1614.49	48.8553
1617.57	47.8488
1620.64	47.2929
1623.72	46.1444
1626.79	45.9348
1629.86	47.6101
1632.93	48.1611
1636	48.0935
1639.07	48.7766
1642.13	49.0541
1645.2	49.7253
1648.26	49.3707
1651.33	49.6285
1654.39	49.1295
1657.45	50.2919
1660.51	50.1517
1663.57	49.2282
1666.63	47.9952
1669.68	44.4398
1672.74	41.3075
1675.79	38.4178
1678.85	34.9105
1681.9	32.6381
1684.95	29.6709
1688	25.9592
1691.05	23.7617
1694.09	20.3657
1697.14	19.8282
1700.18	17.735
1703.23	16.7835
1706.27	14.882
1709.31	13.6914
1712.35	12.7845
1715.39	12.1068
1718.43	11.3486
1721.47	10.8507
1724.5	10.7066
1727.54	11.406
1730.57	10.931
1733.61	10.6899
1736.64	9.98002
1739.67	8.81597
1742.7	8.01212
1745.72	7.16114
1748.75	6.03074
1751.77	5.96382
1754.8	6.05009
1757.82	5.98292
1760.84	5.92678
1763.87	5.69332
1766.89	6.84089
1769.91	6.10339
1772.92	5.86075
1775.94	5.78457
1778.95	6.06021
1781.97	6.10432
1784.98	7.08472
1787.99	7.34027
1791.01	7.16185
1794.01	6.97651
1797.02	6.75695
1800.03	5.81652
1803.04	4.91487
1806.04	3.87616
1809.05	4.56227
1812.05	4.0318
1815.05	4.02962
1818.05	4.0129
1821.05	3.60775
1824.05	3.07556
1827.05	2.99395
1830.04	2.60374
1833.04	1.43136
1836.03	1.34908
1839.03	1.33486
1842.02	1.09177
1845.01	1.25562
1848	0.852199
1850.99	0.575868
1853.97	0.74532
1856.96	1.17754
1859.94	0.916099
1862.93	-0.0226832
1865.91	0.368935
1868.89	-0.0311988
1871.87	-0.399503
1874.85	-0.797727
1877.83	-0.352015
1880.81	0.450763
1882.57	1.1621
1885.56	1.88611
1888.55	2.6677
1891.54	3.04744
1894.52	3.28303
1897.51	4.5941
1900.49	5.18452
1903.47	4.47907
1906.45	4.90067
1909.43	5.63928
1912.41	5.86835
1915.39	5.67713
1918.37	5.43586
1921.34	5.44191
1924.32	5.59177
1927.29	6.15994
1930.26	5.43666
1933.23	4.73508
1936.2	5.32134
1939.17	4.01856
1942.14	2.78953
1945.11	2.35383
1948.07	3.48652
1951.04	4.66508
1954	4.88073
1956.96	5.04667
1959.93	5.28111
1962.89	5.61961
1965.85	5.45054
1968.8	5.06802
1971.76	4.98288
1974.72	4.37356
1977.67	4.48482
1980.63	4.58955
1983.58	4.90631
1986.53	4.94222
1989.48	4.2873
1992.43	5.32165
1995.38	5.44284
1998.32	5.29777
2001.27	5.66406
2004.22	5.89055
2007.16	5.88471
2010.1	6.09053
2013.04	6.02386
2015.98	6.68473
2018.92	6.95232
2021.86	7.62377
2024.8	8.32852
2027.74	7.12241
2030.67	6.78566
2033.61	6.78696
2036.54	6.98078
2039.47	6.79142
2042.4	6.42266
2045.33	6.85378
2048.26	6.08871
2051.19	6.74557
2054.12	7.31026
2057.04	8.01116
2059.97	8.6862
2062.89	8.36512
2065.81	9.23258
2068.73	9.55516
2071.65	10.3525
2074.57	10.8363
2077.49	10.4354
2080.41	10.728
2083.32	10.7394
2086.24	10.4175
2089.15	10.4802
2092.07	10.631
2094.98	10.8794
2097.89	10.0888
2100.8	10.441
2103.71	11.0712
2106.61	10.4601
2109.52	10.3113
2112.43	10.2553
2115.33	10.9622
2118.23	12.118
2121.13	13.428
2124.04	13.7003
2126.94	14.3709
2129.83	14.3325
2132.73	15.032
2135.63	15.59
2138.53	16.457
2141.42	16.8823
2144.31	16.9921
2147.21	16.889
2150.1	17.6461
2152.99	18.3337
2155.88	18.9177
2158.77	19.5793
2161.65	20.6113
2164.54	20.823
2167.43	20.9
2170.31	21.9726
2173.19	22.072
2176.07	22.5871
2178.96	22.5115
2181.84	22.5546
2184.72	22.7123
2187.59	23.5868
2190.47	23.581
2193.35	21.9335
2196.22	21.167
2199.09	20.1945
2201.97	19.6212
2204.84	19.3277
2207.71	18.3824
2210.58	17.6164
2213.45	16.4112
2216.31	14.9006
2219.18	14.4934
2222.05	14.5014
2224.91	13.7928
2227.78	12.9025
2230.64	12.5971
2233.5	12.3412
2236.36	11.9548
2239.22	11.9406
2242.08	12.0549
2244.93	10.939
2247.79	11.3926
2250.64	12.003
2253.5	11.7052
2256.35	11.2478
2259.2	10.5718
2262.05	9.99898
2264.9	10.2984
2267.75	10.5593
2270.6	10.17
2273.45	10.3097
2276.29	10.4601
2279.14	11.0336
2281.98	10.8878
2284.82	10.2582
2287.66	10.417
2290.5	9.66216
2293.34	8.33718
2296.18	8.31602
2299.02	9.32194
2301.86	9.43765
2304.69	10.5335
2307.53	11.9106
2310.36	12.2825
2313.19	12.733
2316.02	12.3083
2318.85	13.1832
2321.68	12.3014
2324.51	11.652
2327.34	9.82393
2330.16	9.40546
2332.99	8.49735
2335.81	7.42829
2338.64	6.68
2341.46	4.94898
2344.28	5.22828
2347.1	5.5388
2349.92	4.99352
2352.74	2.91211
2355.55	2.77628
2358.37	2.24973
2361.19	2.40204
2364	3.47412
2366.81	4.90689
2369.62	5.55325
2372.44	6.02419
2375.24	6.53879
2378.05	6.7221
2380.86	7.08364
2383.67	5.9448
2386.47	5.77658
2389.28	5.65165
2392.08	5.21267
2394.89	4.10079
2397.69	3.2419
2400.49	1.97074
2403.29	1.0539
2406.09	1.31711
2408.88	0.415923
2411.68	1.54455
2414.48	2.52959
2417.27	2.63228
2420.06	2.41954
2422.86	2.83202
2425.65	4.22704
2428.44	4.19495
2431.23	3.95203
2434.02	3.70932
2436.81	3.67679
2439.59	5.13687
2442.38	5.23906
2445.16	5.81133
2447.95	5.24526
2450.73	4.81791
2453.51	4.46306
2456.29	4.81975
2459.07	5.24273
2461.85	4.77204
2464.63	3.74944
2467.4	2.63732
2470.18	2.11981
2472.95	2.08704
2475.73	1.93933
2478.5	2.31026
2481.27	2.35946
2484.04	1.91214
2486.81	1.79859
2489.58	2.06406
2492.35	1.84911
2495.12	1.19521
2497.88	1.15611
2500.65	1.34193
2503.41	2.51659
2506.17	4.0606
2508.94	4.45402
2511.7	3.76703
2514.46	3.84416
2517.22	4.66104
2519.97	4.82583
2522.73	4.8732
2525.49	4.61574
2528.24	3.91615
2530.99	3.63996
2533.75	2.70042
2536.5	2.17614
2539.25	2.34822
2542	2.38609
2544.75	2.3037
2547.5	2.0858
2550.24	2.40053
2552.99	1.77303
2555.74	1.99201
2558.48	1.302
2561.22	1.49251
2563.96	1.67983
2566.71	1.69919
2569.45	2.2902
2572.18	2.6045
2574.92	3.95406
2577.66	3.89802
2580.4	4.28564
2583.13	4.28412
2585.87	4.38061
2588.6	4.74597
2591.33	4.19139
2594.06	4.1408
2596.79	4.62489
2599.52	4.31824
2602.25	4.54414
2604.98	4.12444
2607.71	4.14293
2610.43	3.68163
2613.16	3.54406
2615.88	3.60281
2618.6	2.26004
2621.32	1.88602
2624.04	2.20652
2626.76	1.70173
2629.48	0.842164
2632.2	1.04881
2634.92	1.14466
2637.63	0.152993
2640.35	0.654465
2643.06	0.335934
2645.77	0.517606
2648.49	0.542922
2651.2	0.381615
2653.91	0.352474
2656.62	0.0839207
2659.33	0.37672
2662.03	0.0127404
2664.74	0.112284
2667.44	0.202013
2670.15	-0.201163
2672.85	-0.351494
2675.55	0.0166393
2678.26	0.409352
2680.96	1.01792
2683.66	1.07498
2686.35	1.29938
2689.05	1.71873
2691.75	1.62863
2694.44	1.70149
2697.14	2.89685
2699.83	3.20657
2702.52	3.80774
2705.22	4.47112
2707.91	6.06451
2710.6	7.10205
2713.29	7.12073
2715.97	7.36522
2718.66	8.43696
2721.35	8.42005
2724.03	8.17327
2726.72	7.99061
2729.4	7.29529
2732.08	7.35087
2734.76	6.93906
2737.44	6.40301
2740.12	7.18204
2742.8	7.08535
2745.48	5.8271
2748.16	5.39363
2750.83	4.55887
2753.51	4.10704
2756.18	2.97475
2758.85	2.2231
2761.53	2.68976
2764.2	2.34726
2766.87	1.66475
2769.54	1.74035
2772.2	1.69532
2774.87	1.71402
2777.54	2.16492
2780.2	2.18836
2782.87	2.36594
2785.53	2.38766
2788.19	1.58121
2790.85	1.45281
2793.51	2.48962
2796.17	2.98538
2798.83	3.57886
2801.49	3.89109
2804.15	5.10715
2806.8	4.63381
2809.46	4.6459
2812.11	4.16691
2814.76	4.35467
2817.42	4.89794
2820.07	5.41738
2822.72	7.15815
2825.37	8.6528
2828.02	9.22929
2830.66	10.5206
2833.31	12.3859
2835.96	15.0013
2838.6	17.2415
2841.24	19.9666
2843.89	23.2484
2846.53	26.7998
2849.17	31.3293
2851.81	35.8338
2854.45	40.7568
2857.09	45.598
2859.72	51.0463
2862.36	55.2861
2865	58.6831
2867.63	62.4659
2870.26	65.8368
2872.9	69.5148
2875.53	71.9305
2878.16	74.4342
2880.79	76.8715
2883.42	79.0496
2886.05	81.3849
2888.67	82.4396
2891.3	84.3783
2893.92	86.9163
2896.55	89.4911
2899.17	92.5315
2901.79	96.0592
2904.42	99.96
2907.04	104.034
2909.66	109.189
2912.27	114.97
2914.89	120.464
2917.51	125.855
2920.13	130.632
2922.74	134.29
2925.35	137.651
2927.97	138.91
2930.58	140.201
2933.19	140.979
2935.8	139.892
2938.41	137.828
2941.02	134.519
2943.63	132.382
2946.24	128.309
2948.84	123.751
2951.45	118.488
2954.05	113.326
2956.65	108.931
2959.26	103.897
2961.86	99.2544
2964.46	94.7537
2967.06	90.5776
2969.66	86.5088
2972.25	82.4679
2974.85	79.0313
2977.45	75.622
2980.04	72.1968
2982.64	68.4422
2985.23	63.25
2987.82	58.847
2990.41	53.6551
2993	48.6408
2995.59	44.6788
2998.18	39.7385
3000.77	35.3143
3003.36	31.4935
3005.94	28.8493
3008.53	25.0034
3011.11	21.0132
3013.69	18.7268
3016.28	16.6193
3018.86	15.3873
3021.44	14.8822
3024.02	14.2609
3026.6	14.4012
3029.18	14.5405
3031.75	14.8388
3034.33	16.1242
3036.9	17.2857
3039.48	18.4717
3042.05	19.7246
3044.62	20.5546
3047.19	21.6767
3049.77	22.3596
3052.34	22.4745
3054.9	22.5054
3057.47	22.7498
3060.04	21.6609
3062.61	21.2823
3065.17	20.712
3067.74	19.8821
3070.3	19.4436
3072.86	18.0806
3075.42	16.8928
3077.99	15.6339
3080.54	13.7708
3083.1	11.4542
3085.66	9.86127
3088.22	8.61662
3090.78	7.64263
3093.33	7.14708
3095.89	6.21919
3098.44	6.86502
3100.99	5.66185
3103.54	5.49219
3106.1	5.13966
3108.65	5.10957
3111.2	4.55588
3113.74	4.52333
3116.29	4.79199
3118.84	4.57958
3121.38	4.14918
3123.93	4.26554
3126.47	4.1447
3129.01	4.74568
3131.56	5.28535
3134.1	4.75684
3136.64	3.4923
3139.18	2.14461
3141.72	1.63544
3144.26	1.32483
3146.79	1.1984
3149.33	2.40022