File: data/Raman/poly_smoothed/Thy_40_11_06_1x_45s_532 nm_x100_100%_600 gr_mm_01.txt
#Acq. time (s)=	45
#Accumulations=	2
#Range (cm-¹)=	200...3150
#Windows=	2
#Auto scanning=	Off
#Autofocus=	Off
#Macrospot=	Off
#AutoExposure=	Off
#Spike filter=	Multiple accum.
#Delay time (s)=	0
#Binning=	1
#Readout mode=	Signal
#DeNoise=	Off
#ICS correction=	On
#Dark correction=	Off
#Inst. Process=	Off
#Detector Gain=	Best Dynamic Range
#Detector ADC=	20 kHz
#Detector temperature (°C)=	-69.85
#Instrument=	LabRAM HR Evol
#Detector=	Synapse
#Objective=	x100
#Grating=	600 gr/mm
#ND Filter=	100%
#Laser (nm)=	532
#Hole=	100.021
#Range=	Auto
#Laser Pol.=	No
#Raman. Pol.=	No
#Laser Pol. (°)=	-0.0007625
#Raman Pol. (°)=	89.9995
#Collection=	Microscope
#StageXY=	Marzhauser
#StageZ=	Marzhauser
#X (µm)=	1981.4
#Y (µm)=	-79
#Z (µm)=	425.9
#Full time(mm:ss)=	3:18
#Project=
#Sample=
#Site=
#Title=	Thy_40_11_06_2x_45s_532 nm_x100_100%_600 gr_mm
#Remark=
#Date=	05.07.2022 10:17
#Acquired=	05.07.2022 10:17:33
#Base:Fit=	10.08.2022 10:00:48
#Base:Fit=	10.08.2022 10:01:07
#Base:Fit=	10.08.2022 10:01:15
#Base:Fit=	10.08.2022 10:01:35
#Base:Sub=	10.08.2022 10:01:52
#Filter:Polynom=	16.08.2022 10:21:53
#AxisType[0]=Intens
#AxisUnit[0]=Cnt
#AxisType[1]=Spectr
#AxisUnit[1]=1/cm
200.43	39.0788
204.059	32.2949
207.688	27.2615
211.314	22.3688
214.941	19.2628
218.564	15.0513
222.186	13.2467
225.809	9.68198
229.428	6.49673
233.045	5.54643
236.663	4.67054
240.278	3.5724
243.891	1.92156
247.503	2.40671
251.116	2.59507
254.725	1.07842
258.333	2.13436
261.939	3.41964
265.544	4.84739
269.148	4.63322
272.75	5.33202
276.351	3.77214
279.95	4.02332
283.548	4.04122
287.144	4.42807
290.739	6.36832
294.333	6.95732
297.925	7.61746
301.514	8.51755
305.104	8.97392
308.692	8.75455
312.279	8.20636
315.862	9.09513
319.446	10.9027
323.029	11.8795
326.608	12.0818
330.188	12.6841
333.766	12.5387
337.341	13.4985
340.917	12.3296
344.489	13.5928
348.062	11.6078
351.631	10.1098
355.201	8.39337
358.768	7.73069
362.333	6.70268
365.899	6.52602
369.462	5.76005
373.023	5.29443
376.585	5.63928
380.143	7.19937
383.7	6.52861
387.256	5.03566
390.812	4.51428
394.365	3.86065
397.916	4.60297
401.467	7.10428
405.015	8.00769
408.563	9.13292
412.109	8.89501
415.654	8.14556
419.197	7.92163
422.739	8.48316
426.279	8.91555
429.819	8.42756
433.356	8.46248
436.891	8.18528
440.426	8.84413
443.96	9.52586
447.492	11.481
451.021	11.7692
454.551	12.8111
458.079	14.3142
461.604	16.7622
465.13	18.387
468.654	19.439
472.175	20.4487
475.696	22.0144
479.215	22.9132
482.733	25.1301
486.249	27.3479
489.765	27.2391
493.278	28.521
496.789	27.8701
500.301	28.8532
503.81	29.5338
507.317	29.2103
510.825	30.7604
514.33	31.0286
517.833	29.524
521.335	29.0852
524.836	28.3656
528.335	26.5641
531.835	28.0947
535.332	26.9118
538.827	25.7742
542.321	23.2354
545.814	24.7818
549.305	24.1339
552.795	23.2738
556.282	22.103
559.769	21.4392
563.255	20.0253
566.739	18.7157
570.223	17.5989
573.705	14.3393
577.183	12.8466
580.663	11.7896
584.141	11.1421
587.615	9.11933
591.09	6.32523
594.564	5.75861
598.035	5.98777
601.506	3.9774
604.974	3.74818
608.443	4.34238
611.908	5.25409
615.374	6.13096
618.837	7.50228
622.3	8.0498
625.761	9.21884
629.219	12.0093
632.677	13.7498
636.135	14.3857
639.59	16.2593
643.043	17.9897
646.495	19.1216
649.948	20.0453
653.398	21.5768
656.846	22.1133
660.293	22.9377
663.738	23.9826
667.183	23.8785
670.626	24.5424
674.067	23.7437
677.508	24.228
680.947	25.4018
684.385	27.3257
687.821	29.4528
691.254	32.3413
694.688	33.8935
698.121	36.9172
701.552	39.5891
704.98	42.1368
708.409	45.3277
711.836	49.4682
715.26	51.3386
718.685	54.1727
722.108	57.2426
725.528	61.1933
728.949	63.3518
732.367	65.6674
735.785	64.8931
739.2	66.5865
742.614	66.8661
746.028	68.9475
749.439	71.2656
752.849	74.306
756.26	76.0072
759.667	77.767
763.073	79.6895
766.477	82.8399
769.883	84.2184
773.285	86.0427
776.686	87.6013
780.085	90.5857
783.484	91.4838
786.881	93.4493
790.276	94.8806
793.671	98.3352
797.064	100.358
800.456	101.973
803.846	102.518
807.234	102.324
810.622	102.097
814.008	100.856
817.394	99.2582
820.778	98.8758
824.159	100.003
827.541	101.614
830.921	104.459
834.298	102.619
837.676	103.338
841.051	101.558
844.426	99.0811
847.798	98.0646
851.171	95.4078
854.54	92.7834
857.911	89.9928
861.278	87.2915
864.645	83.8671
868.01	81.6326
871.373	80.1683
874.735	79.9202
878.097	78.4109
881.457	76.7861
884.815	74.0789
888.172	71.9005
891.528	70.5589
894.882	69.2335
898.237	69.9296
901.589	70.3767
904.94	69.375
908.289	68.0836
911.635	66.455
914.982	65.4051
918.328	62.8144
921.672	60.802
925.015	58.3967
928.357	57.7374
931.698	56.964
935.035	55.1924
938.373	52.6565
941.71	50.6338
945.044	47.6859
948.378	46.8593
951.709	46.929
955.041	48.982
958.372	49.3178
961.699	48.828
965.027	51.5044
968.352	52.6567
971.676	54.0491
975	56.1626
978.322	58.247
981.642	58.1968
984.962	58.362
988.28	58.2295
991.596	57.5972
994.911	57.5509
998.227	57.7774
1001.54	56.2799
1004.85	56.8525
1008.16	57.4985
1011.47	56.6929
1014.78	56.1853
1018.08	54.5423
1021.39	51.8695
1024.69	50.6719
1028	50.7512
1031.3	51.5943
1034.6	51.0025
1037.9	49.4642
1041.19	48.2389
1044.49	48.5569
1047.78	47.6315
1051.08	45.2967
1054.37	44.5677
1057.66	42.0594
1060.95	40.394
1064.24	39.3206
1067.53	36.8142
1070.81	35.4536
1074.1	34.3453
1077.38	33.3466
1080.66	32.8603
1083.94	32.3441
1087.22	30.0897
1090.5	30.5856
1093.78	29.9924
1097.05	30.1911
1100.33	29.9156
1103.6	30.3367
1106.87	30.9085
1110.14	31.3075
1113.41	29.5182
1116.68	28.3838
1119.95	28.7378
1123.21	27.0294
1126.48	24.8131
1129.74	20.9776
1133	19.8454
1136.26	19.045
1139.52	17.9202
1142.78	19.0165
1146.04	16.9365
1149.29	17.0186
1152.55	15.709
1155.8	13.9929
1159.05	12.2272
1162.3	12.5966
1165.55	10.6413
1168.8	10.4964
1172.05	11.498
1175.29	9.80319
1178.54	8.96747
1181.78	8.45493
1185.02	7.4477
1188.26	5.83421
1191.5	4.96723
1194.74	4.36605
1197.97	5.72423
1201.21	5.03568
1204.44	6.0145
1207.68	7.78214
1210.91	12.1278
1214.14	17.1724
1217.37	23.4809
1220.59	28.5348
1223.82	33.0157
1227.05	38.989
1230.27	44.1304
1233.49	49.6568
1236.72	54.5208
1239.94	60.2392
1243.16	64.564
1246.37	68.8269
1249.59	72.4248
1252.8	74.057
1256.02	75.657
1259.23	77.4379
1262.44	78.4695
1265.66	79.6473
1268.86	80.6509
1272.07	83.3788
1275.28	86.8447
1278.48	87.1845
1281.69	88.4216
1284.89	90.389
1288.09	92.7561
1291.29	93.7341
1294.49	95.141
1297.69	96.4944
1300.89	98.4538
1304.08	99.359
1307.28	98.3652
1310.47	98.4719
1313.66	97.7252
1316.85	96.4563
1320.04	96.1935
1323.23	94.8737
1326.42	91.2859
1329.61	89.6101
1332.79	87.2297
1335.97	85.753
1339.16	82.7763
1342.34	79.6335
1345.52	78.1249
1348.7	75.025
1351.87	73.6915
1355.05	70.8913
1358.22	66.6265
1361.4	65.4
1364.57	61.9383
1367.74	60.4628
1370.91	58.223
1374.08	55.8292
1377.25	53.8062
1380.41	51.8408
1383.58	49.511
1386.74	47.5309
1389.91	46.326
1393.07	45.5228
1396.23	45.196
1399.39	43.8142
1402.55	41.9744
1405.7	41.1743
1408.86	43.6317
1412.01	43.4289
1415.17	45.4437
1418.32	47.1813
1421.47	50.335
1424.62	53.9659
1427.77	60.1125
1430.91	65.9024
1434.06	71.2737
1437.2	75.91
1440.35	81.4492
1443.49	85.2076
1446.63	87.4673
1449.77	87.7994
1452.91	88.3777
1456.05	87.2683
1459.18	85.1941
1462.32	81.8865
1465.45	77.3553
1468.59	72.0283
1471.72	66.1649
1474.85	58.6789
1477.98	50.6277
1481.1	43.4822
1484.23	36.7728
1487.36	29.7851
1490.48	23.6896
1493.61	19.6196
1496.73	14.7502
1499.85	14.3226
1502.97	12.3232
1506.09	10.9298
1509.2	10.7072
1512.32	9.95147
1515.43	9.65187
1518.55	10.7163
1521.66	11.2282
1524.77	12.4763
1527.88	15.9056
1530.99	18.1934
1534.1	20.08
1537.21	24.9554
1540.31	28.8837
1543.42	32.6603
1546.52	36.5411
1549.62	40.1793
1552.72	44.9652
1555.82	50.2423
1558.92	54.6334
1562.02	58.5871
1565.11	63.9381
1568.21	68.7595
1571.3	72.3566
1574.39	75.6708
1577.49	77.743
1580.57	80.6467
1583.66	81.94
1586.75	82.2964
1589.84	82.3762
1592.92	82.8261
1596.01	82.3211
1599.09	81.415
1602.17	80.8574
1605.25	79.2466
1608.33	78.2409
1611.41	77.8254
1614.49	77.9466
1617.57	77.8269
1620.64	79.7353
1623.72	81.6579
1626.79	85.7767
1629.86	89.0402
1632.93	92.7673
1636	96.4235
1639.07	101.596
1642.13	105.744
1645.2	110.231
1648.26	113.587
1651.33	116.266
1654.39	118.361
1657.45	118.354
1660.51	118.075
1663.57	115.695
1666.63	111.413
1669.68	106.831
1672.74	101.306
1675.79	94.5786
1678.85	88.2772
1681.9	80.6768
1684.95	72.7514
1688	65.0475
1691.05	57.6143
1694.09	49.413
1697.14	44.0608
1700.18	37.2475
1703.23	32.3172
1706.27	27.1747
1709.31	22.9382
1712.35	19.614
1715.39	17.3442
1718.43	15.2257
1721.47	13.6598
1724.5	11.0316
1727.54	10.3096
1730.57	8.72029
1733.61	6.98187
1736.64	5.60073
1739.67	4.71837
1742.7	4.45418
1745.72	3.81493
1748.75	3.86603
1751.77	3.52499
1754.8	3.23414
1757.82	2.08877
1760.84	1.70389
1763.87	1.88119
1766.89	0.776172
1769.91	0.546745
1772.92	0.356863
1775.94	0.76606
1778.95	0.959571
1781.97	1.5832
1784.98	1.21092
1787.99	1.43646
1791.01	1.76801
1794.01	1.67267
1797.02	1.53972
1800.03	1.82212
1803.04	0.402924
1806.04	0.123848
1809.05	0.380605
1812.05	0.372048
1815.05	0.340714
1818.05	0.382858
1821.05	1.24838
1824.05	1.55104
1827.05	1.79225
1830.04	1.49263
1833.04	1.71486
1836.03	2.15633
1839.03	2.42311
1842.02	2.11884
1845.01	2.1892
1848	3.32266
1850.99	4.79394
1853.97	4.71185
1856.96	4.9873
1859.94	3.9171
1862.93	3.95283
1865.91	4.61461
1868.89	5.38264
1871.87	4.62971
1874.85	3.70772
1877.83	2.99577
1880.81	4.40341
1882.57	4.01541
1885.56	3.4251
1888.55	3.44737
1891.54	4.01216
1894.52	2.99523
1897.51	2.26977
1900.49	2.38933
1903.47	2.53485
1906.45	2.22774
1909.43	2.7892
1912.41	2.94921
1915.39	4.2609
1918.37	4.51563
1921.34	5.29674
1924.32	5.03695
1927.29	4.13452
1930.26	4.71479
1933.23	3.27691
1936.2	4.06076
1939.17	3.63842
1942.14	2.12235
1945.11	1.67931
1948.07	2.19913
1951.04	2.82851
1954	2.98377
1956.96	4.08038
1959.93	3.61992
1962.89	4.68829
1965.85	3.23229
1968.8	2.89798
1971.76	4.5054
1974.72	3.13106
1977.67	4.48416
1980.63	5.44142
1983.58	6.83688
1986.53	7.30179
1989.48	7.86857
1992.43	8.66481
1995.38	8.78151
1998.32	8.53897
2001.27	8.14666
2004.22	7.14968
2007.16	7.24519
2010.1	7.21062
2013.04	6.82566
2015.98	8.28577
2018.92	9.63919
2021.86	9.71148
2024.8	10.5915
2027.74	13.094
2030.67	13.7684
2033.61	13.6576
2036.54	13.0812
2039.47	14.3424
2042.4	15.4914
2045.33	16.1848
2048.26	16.4723
2051.19	17.8847
2054.12	19.2001
2057.04	20.4771
2059.97	21.4299
2062.89	21.4627
2065.81	21.537
2068.73	20.5067
2071.65	21.3163
2074.57	22.5967
2077.49	24.1916
2080.41	25.1896
2083.32	27.3475
2086.24	28.7561
2089.15	31.0926
2092.07	32.8799
2094.98	35.7484
2097.89	39.6199
2100.8	41.6489
2103.71	43.9304
2106.61	47.8088
2109.52	51.3559
2112.43	54.6917
2115.33	56.7662
2118.23	60.3257
2121.13	65.1105
2124.04	70.747
2126.94	76.0072
2129.83	80.3006
2132.73	85.047
2135.63	90.6092
2138.53	96.2608
2141.42	102.216
2144.31	108.224
2147.21	113.876
2150.1	118.684
2152.99	123.226
2155.88	126.958
2158.77	130.553
2161.65	133.782
2164.54	135.762
2167.43	138.107
2170.31	138.462
2173.19	138.298
2176.07	137.598
2178.96	136.274
2181.84	132.947
2184.72	129.63
2187.59	126.935
2190.47	124.17
2193.35	120.669
2196.22	116.906
2199.09	111.308
2201.97	107.017
2204.84	101.351
2207.71	97.1151
2210.58	91.6068
2213.45	86.8804
2216.31	82.1998
2219.18	76.4348
2222.05	72.0214
2224.91	67.5733
2227.78	62.8498
2230.64	58.8082
2233.5	55.0797
2236.36	50.6647
2239.22	48.5635
2242.08	46.4638
2244.93	44.5198
2247.79	42.121
2250.64	40.2425
2253.5	37.8291
2256.35	37.0635
2259.2	37.0571
2262.05	36.4538
2264.9	36.003
2267.75	34.7826
2270.6	32.9139
2273.45	31.4293
2276.29	30.9722
2279.14	30.1346
2281.98	29.8774
2284.82	29.4306
2287.66	28.7523
2290.5	26.5397
2293.34	24.3975
2296.18	22.3907
2299.02	21.1089
2301.86	22.1994
2304.69	21.1611
2307.53	20.5954
2310.36	20.1491
2313.19	19.757
2316.02	18.8357
2318.85	17.8728
2321.68	16.711
2324.51	15.2322
2327.34	15.0647
2330.16	13.3213
2332.99	12.2153
2335.81	11.0973
2338.64	9.18066
2341.46	8.16928
2344.28	7.44969
2347.1	6.69251
2349.92	6.1203
2352.74	5.06208
2355.55	4.33104
2358.37	4.04292
2361.19	2.50869
2364	2.76355
2366.81	4.22121
2369.62	4.31991
2372.44	4.62888
2375.24	4.72689
2378.05	5.22193
2380.86	6.43798
2383.67	6.06157
2386.47	6.24149
2389.28	5.66145
2392.08	5.81527
2394.89	6.58891
2397.69	6.64914
2400.49	6.44015
2403.29	7.23322
2406.09	7.55761
2408.88	7.11417
2411.68	7.7017
2414.48	8.62467
2417.27	8.39612
2420.06	9.19536
2422.86	9.92764
2425.65	10.1451
2428.44	9.62735
2431.23	9.19249
2434.02	9.37705
2436.81	8.84014
2439.59	9.0828
2442.38	9.57055
2445.16	9.20059
2447.95	9.15581
2450.73	8.33824
2453.51	8.48215
2456.29	7.82554
2459.07	7.28822
2461.85	6.25989
2464.63	5.17209
2467.4	4.7005
2470.18	4.39353
2472.95	3.8959
2475.73	4.04823
2478.5	3.42689
2481.27	2.83355
2484.04	2.2573
2486.81	2.03247
2489.58	1.94823
2492.35	1.57398
2495.12	1.05085
2497.88	1.53127
2500.65	1.17627
2503.41	1.67575
2506.17	2.45068
2508.94	3.0696
2511.7	3.10537
2514.46	3.63571
2517.22	3.06168
2519.97	2.13382
2522.73	2.30603
2525.49	1.64244
2528.24	2.57068
2530.99	2.08695
2533.75	1.56583
2536.5	0.876921
2539.25	1.56215
2542	1.43957
2544.75	0.618858
2547.5	-1.594
2550.24	-0.428637
2552.99	-0.956976
2555.74	-0.177871
2558.48	0.197306
2561.22	1.09508
2563.96	1.37321
2566.71	2.87116
2569.45	3.17943
2572.18	3.37397
2574.92	4.12385
2577.66	4.10506
2580.4	4.05023
2583.13	4.05689
2585.87	3.26884
2588.6	4.18963
2591.33	3.34106
2594.06	2.89862
2596.79	3.07622
2599.52	2.22594
2602.25	2.58124
2604.98	1.68381
2607.71	0.357042
2610.43	-0.147693
2613.16	-0.0780905
2615.88	1.02652
2618.6	0.945903
2621.32	1.25778
2624.04	2.61709
2626.76	2.12324
2629.48	2.32398
2632.2	2.95426
2634.92	1.96515
2637.63	1.57319
2640.35	1.80929
2643.06	2.61833
2645.77	2.08762
2648.49	2.99911
2651.2	2.76742
2653.91	3.56503
2656.62	4.31402
2659.33	4.45191
2662.03	4.50567
2664.74	5.25134
2667.44	4.46722
2670.15	4.03934
2672.85	3.40346
2675.55	3.61421
2678.26	4.38546
2680.96	4.60073
2683.66	4.71536
2686.35	5.08833
2689.05	5.47029
2691.75	5.32523
2694.44	5.34254
2697.14	5.60107
2699.83	5.29704
2702.52	5.49523
2705.22	6.77264
2707.91	8.05204
2710.6	8.72988
2713.29	9.32977
2715.97	10.5126
2718.66	11.5202
2721.35	12.6099
2724.03	12.939
2726.72	12.8566
2729.4	13.3684
2732.08	12.4773
2734.76	12.6756
2737.44	12.5983
2740.12	11.2057
2742.8	10.3676
2745.48	10.9484
2748.16	10.686
2750.83	9.74147
2753.51	8.95467
2756.18	8.36647
2758.85	8.92744
2761.53	8.55275
2764.2	7.35752
2766.87	7.21882
2769.54	6.76077
2772.2	6.06335
2774.87	4.71635
2777.54	3.62384
2780.2	3.29214
2782.87	3.16799
2785.53	2.71496
2788.19	1.46334
2790.85	1.15419
2793.51	1.71671
2796.17	2.88667
2798.83	3.51137
2801.49	3.89303
2804.15	3.99312
2806.8	4.03783
2809.46	5.25661
2812.11	6.44881
2814.76	6.08444
2817.42	7.36234
2820.07	9.23658
2822.72	12.8024
2825.37	15.4799
2828.02	19.341
2830.66	25.1259
2833.31	30.4941
2835.96	35.3437
2838.6	41.2375
2841.24	47.3535
2843.89	54.9638
2846.53	65.1727
2849.17	73.8959
2851.81	84.1957
2854.45	96.1409
2857.09	107.043
2859.72	117.374
2862.36	128.414
2865	137.644
2867.63	145.894
2870.26	153.345
2872.9	160.202
2875.53	165.732
2878.16	171.631
2880.79	175.822
2883.42	181.02
2886.05	187.186
2888.67	192.874
2891.3	198.806
2893.92	206.437
2896.55	213.531
2899.17	221.083
2901.79	230.615
2904.42	241.115
2907.04	253.578
2909.66	268.133
2912.27	282.757
2914.89	296.524
2917.51	308.969
2920.13	321.175
2922.74	330.641
2925.35	337.829
2927.97	342.693
2930.58	347.037
2933.19	347.296
2935.8	345.287
2938.41	341.365
2941.02	333.629
2943.63	324.711
2946.24	314.225
2948.84	304.236
2951.45	292.51
2954.05	280.46
2956.65	267.682
2959.26	254.81
2961.86	241.984
2964.46	230.949
2967.06	219.936
2969.66	209.641
2972.25	198.619
2974.85	188.568
2977.45	176.968
2980.04	167.004
2982.64	155.744
2985.23	144.163
2987.82	132.254
2990.41	121.617
2993	111.06
2995.59	99.8162
2998.18	89.8534
3000.77	79.3635
3003.36	69.5928
3005.94	61.7973
3008.53	56.1806
3011.11	49.89
3013.69	44.3242
3016.28	39.1681
3018.86	34.8162
3021.44	32.7324
3024.02	30.4405
3026.6	29.4332
3029.18	28.1063
3031.75	27.2784
3034.33	27.0953
3036.9	27.8576
3039.48	29.8235
3042.05	31.4076
3044.62	32.1269
3047.19	33.507
3049.77	33.6856
3052.34	35.0967
3054.9	34.7901
3057.47	35.0423
3060.04	34.4126
3062.61	32.9054
3065.17	32.193
3067.74	30.6006
3070.3	28.0705
3072.86	25.9356
3075.42	22.7652
3077.99	20.4011
3080.54	18.68
3083.1	16.4864
3085.66	12.9781
3088.22	10.0849
3090.78	7.52071
3093.33	5.59812
3095.89	4.49563
3098.44	3.83776
3100.99	4.61128
3103.54	4.96424
3106.1	4.49162
3108.65	4.97892
3111.2	5.62651
3113.74	5.13138
3116.29	5.19468
3118.84	5.67547
3121.38	5.09507
3123.93	4.82632
3126.47	5.88162
3129.01	5.71923
3131.56	5.77748
3134.1	5.60182
3136.64	6.73721
3139.18	6.14323
3141.72	5.48759
3144.26	4.37032
3146.79	4.19037
3149.33	5.88116