File: data/Raman/poly_smoothed/Thy_30_10_23_1x_45s_532 nm_x100_100%_600 gr_mm_01.txt
#Acq. time (s)=	45
#Accumulations=	2
#Range (cm-¹)=	200...3150
#Windows=	2
#Auto scanning=	Off
#Autofocus=	Off
#Macrospot=	Off
#AutoExposure=	Off
#Spike filter=	Multiple accum.
#Delay time (s)=	0
#Binning=	1
#Readout mode=	Signal
#DeNoise=	Off
#ICS correction=	On
#Dark correction=	Off
#Inst. Process=	Off
#Detector Gain=	Best Dynamic Range
#Detector ADC=	20 kHz
#Detector temperature (°C)=	-69.85
#Instrument=	LabRAM HR Evol
#Detector=	Synapse
#Objective=	x100
#Grating=	600 gr/mm
#ND Filter=	100%
#Laser (nm)=	532
#Hole=	100.021
#Range=	Auto
#Laser Pol.=	No
#Raman. Pol.=	No
#Laser Pol. (°)=	-0.0007625
#Raman Pol. (°)=	89.9995
#Collection=	Microscope
#StageXY=	Marzhauser
#StageZ=	Marzhauser
#X (µm)=	4767
#Y (µm)=	-7723.6
#Z (µm)=	584.15
#Full time(mm:ss)=	3:18
#Project=
#Sample=
#Site=
#Title=	Thy_30_10_23_2x_45s_532 nm_x100_100%_600 gr_mm
#Remark=
#Date=	30.06.2022 13:08
#Acquired=	30.06.2022 13:08:05
#Base:Fit=	10.08.2022 09:58:11
#Base:Sub=	10.08.2022 09:58:44
#Filter:Polynom=	16.08.2022 10:22:53
#AxisType[0]=Intens
#AxisUnit[0]=Cnt
#AxisType[1]=Spectr
#AxisUnit[1]=1/cm
200.533	1.55231
204.162	1.41028
207.792	1.19663
211.418	1.07268
215.044	1.32631
218.667	1.81861
222.289	4.05367
225.912	6.48406
229.531	5.87165
233.148	4.82324
236.766	5.0264
240.381	5.51521
243.994	5.41244
247.606	6.83892
251.217	8.11586
254.828	9.39679
258.436	9.64953
262.042	9.2423
265.647	8.53762
269.25	9.18535
272.852	10.5573
276.453	10.0524
280.052	9.4347
283.65	10.0074
287.247	9.91226
290.842	10.2095
294.436	11.4443
298.028	13.3631
301.617	14.6158
305.206	16.6609
308.794	18.0541
312.381	19.7598
315.964	18.877
319.548	19.0318
323.131	19.3911
326.71	21.9056
330.29	21.2506
333.868	21.6468
337.443	22.1718
341.018	20.975
344.591	19.1802
348.163	16.6905
351.733	15.0706
355.303	15.2588
358.869	15.9973
362.435	14.4983
366.001	12.8095
369.563	12.192
373.124	12.9378
376.686	13.9199
380.244	14.3085
383.801	13.2998
387.357	13.0259
390.911	12.5187
394.466	12.1097
398.018	11.7604
401.568	10.2326
405.117	9.52783
408.664	9.29133
412.21	8.79432
415.755	8.76182
419.298	7.40091
422.84	7.03193
426.38	7.44517
429.919	5.23273
433.455	5.40004
436.992	5.45842
440.527	6.5168
444.06	7.40215
447.593	7.73625
451.122	6.97247
454.651	7.05367
458.18	7.20967
461.705	7.92865
465.23	7.47311
468.752	7.11978
472.275	7.09473
475.797	7.97808
479.315	9.48098
482.834	10.6536
486.349	11.6251
489.863	13.3301
493.378	14.9503
496.889	17.3114
500.401	20.2904
503.91	23.0643
507.417	23.302
510.923	25.4938
514.43	27.1008
517.933	27.0367
521.435	27.9001
524.936	27.5357
528.435	26.5309
531.933	26.2049
535.43	25.1478
538.927	23.9053
542.421	21.6723
545.913	19.708
549.403	17.6703
552.893	15.8688
556.381	14.3003
559.868	12.8134
563.354	11.5414
566.839	10.3365
570.322	9.2174
573.802	6.75447
577.283	6.62933
580.762	5.68414
584.24	6.25412
587.714	5.01611
591.19	4.48994
594.663	3.20545
598.134	2.97488
601.605	3.02829
605.073	2.90289
608.542	2.35303
612.007	2.47743
615.473	4.22559
618.936	4.42983
622.397	4.51892
625.859	4.47577
629.318	5.79528
632.775	6.84622
636.233	7.91309
639.688	10.2539
643.142	10.7432
646.594	10.6267
650.045	12.6115
653.496	14.1335
656.944	15.0735
660.391	15.8437
663.837	18.9502
667.281	19.0616
670.724	20.589
674.166	21.3247
677.606	21.8733
681.045	21.9268
684.483	23.2876
687.917	23.0535
691.352	25.0864
694.786	26.8659
698.219	29.36
701.65	30.3575
705.078	31.8466
708.506	35.7504
711.934	38.2127
715.358	39.3632
718.782	40.9142
722.204	42.7581
725.626	45.4599
729.045	46.043
732.464	48.0263
735.881	51.0532
739.297	53.2923
742.711	55.3773
746.125	58.6376
749.537	62.9979
752.946	65.9278
756.357	67.6466
759.764	68.8269
763.17	71.8474
766.575	73.4407
769.978	75.4724
773.382	79.0064
776.783	81.1668
780.182	82.7578
783.581	83.0508
786.978	84.4737
790.373	85.2511
793.768	85.6264
797.161	85.7512
800.552	85.6726
803.941	85.2115
807.33	84.3897
810.718	83.6786
814.105	82.4739
817.49	81.6235
820.873	80.7611
824.256	81.6429
827.637	80.8991
831.016	79.7532
834.395	79.7096
837.772	77.3211
841.147	76.4445
844.522	75.0981
847.894	72.9973
851.267	69.3707
854.637	66.6908
858.007	64.6442
861.374	61.9036
864.739	60.7952
868.106	60.1105
871.469	58.9299
874.831	58.0427
878.193	57.624
881.553	56.8176
884.911	56.2467
888.268	55.0933
891.623	53.6733
894.978	53.4021
898.331	52.5388
901.683	55.2819
905.033	55.3742
908.383	55.3307
911.731	55.4216
915.078	56.2373
918.423	56.3206
921.768	55.241
925.111	53.8201
928.452	51.0086
931.791	48.947
935.13	47.0341
938.468	46.3065
941.803	45.2894
945.139	43.7463
948.473	43.989
951.804	44.5322
955.136	45.716
958.465	46.6496
961.794	47.1828
965.12	49.7441
968.447	51.4464
971.771	52.7637
975.095	54.9429
978.417	55.9586
981.737	56.7932
985.057	56.7136
988.375	56.173
991.691	54.5704
995.006	53.921
998.32	52.4661
1001.63	50.9842
1004.95	50.3602
1008.26	49.3319
1011.56	47.9042
1014.87	47.5309
1018.18	48.1829
1021.48	48.6343
1024.79	49.1559
1028.09	49.5906
1031.39	50.7417
1034.69	50.544
1037.99	49.0659
1041.29	49.2354
1044.58	48.7125
1047.88	49.9729
1051.17	47.8522
1054.46	44.8741
1057.75	41.7437
1061.04	38.4086
1064.33	36.8335
1067.62	33.3948
1070.9	31.0471
1074.19	29.8832
1077.47	29.8799
1080.76	30.8806
1084.04	30.2527
1087.32	30.7498
1090.59	31.7659
1093.87	32.2271
1097.15	33.2501
1100.42	33.9078
1103.69	35.1225
1106.97	35.5094
1110.24	34.996
1113.51	34.6036
1116.77	34.8764
1120.04	34.3063
1123.31	32.5181
1126.57	29.7943
1129.83	28.4752
1133.1	25.1905
1136.36	22.5482
1139.62	21.6113
1142.87	21.0554
1146.13	20.3618
1149.38	19.8277
1152.64	19.7043
1155.89	18.2372
1159.14	17.1887
1162.39	15.5384
1165.64	15.4595
1168.89	16.3565
1172.14	17.641
1175.38	18.6434
1178.63	19.5254
1181.87	20.8844
1185.11	22.4661
1188.35	22.8542
1191.59	24.7393
1194.83	26.485
1198.07	27.7767
1201.3	29.1092
1204.53	31.4216
1207.77	33.5177
1211	35.1605
1214.23	37.4641
1217.46	40.4794
1220.69	43.9951
1223.91	46.415
1227.14	51.4682
1230.36	53.9546
1233.59	56.6923
1236.81	58.1178
1240.03	60.5772
1243.25	63.7227
1246.46	65.6897
1249.68	66.5982
1252.9	67.6001
1256.11	68.2036
1259.32	70.2367
1262.54	71.3385
1265.75	72.0906
1268.96	72.8914
1272.16	73.5848
1275.37	75.0899
1278.57	76.652
1281.78	77.2797
1284.98	78.2142
1288.18	77.8139
1291.38	77.5726
1294.58	78.6768
1297.78	79.966
1300.98	80.1379
1304.17	82.6779
1307.37	83.6654
1310.56	83.7622
1313.76	82.2447
1316.95	83.6582
1320.14	83.1173
1323.32	83.7941
1326.51	83.022
1329.7	81.8261
1332.88	82.2136
1336.07	81.3687
1339.25	80.5479
1342.43	77.6568
1345.61	74.982
1348.79	72.4166
1351.96	70.5053
1355.14	67.3413
1358.31	64.3118
1361.49	60.7259
1364.66	57.9386
1367.83	54.9629
1371	52.7348
1374.17	50.4843
1377.34	50.1204
1380.5	49.106
1383.67	48.002
1386.83	47.4364
1390	46.3727
1393.16	45.9208
1396.32	45.7827
1399.48	45.0449
1402.64	44.6913
1405.79	44.3001
1408.95	43.9717
1412.1	45.9941
1415.26	47.2359
1418.41	48.5904
1421.56	51.7102
1424.71	55.4736
1427.86	59.9625
1431	64.6013
1434.15	69.242
1437.29	73.5982
1440.44	76.4145
1443.58	79.1687
1446.72	81.2883
1449.86	82.1759
1453	82.9157
1456.14	83.137
1459.27	79.9864
1462.41	75.865
1465.54	72.1147
1468.67	66.4389
1471.81	60.7757
1474.94	54.9118
1478.07	48.9228
1481.19	43.6673
1484.32	37.6954
1487.45	32.2616
1490.57	27.7136
1493.69	22.782
1496.82	21.2892
1499.94	20.1787
1503.06	20.5196
1506.17	18.9703
1509.29	18.8105
1512.41	19.6101
1515.52	20.0151
1518.64	21.6445
1521.75	23.4612
1524.86	24.7169
1527.97	25.9959
1531.08	27.9652
1534.19	29.6003
1537.29	31.4321
1540.4	33.705
1543.5	38.0532
1546.61	41.0027
1549.71	45.3372
1552.81	49.5295
1555.91	52.554
1559.01	55.5385
1562.11	57.8399
1565.2	60.5197
1568.29	62.1962
1571.39	65.1024
1574.48	68.7752
1577.57	70.2663
1580.66	71.1558
1583.75	72.581
1586.84	73.9372
1589.93	74.2635
1593.01	74.5161
1596.1	73.2161
1599.18	71.7453
1602.26	69.239
1605.34	68.7776
1608.42	66.7977
1611.5	66.8919
1614.58	67.3878
1617.65	67.6344
1620.73	68.3276
1623.8	69.4238
1626.87	71.4648
1629.95	72.5277
1633.02	75.0547
1636.09	76.8675
1639.15	79.8544
1642.22	81.5844
1645.29	83.6526
1648.35	86.4342
1651.42	88.4769
1654.48	88.7827
1657.54	89.5149
1660.6	88.2922
1663.66	86.2956
1666.72	82.7292
1669.77	78.5402
1672.83	74.185
1675.88	69.097
1678.93	63.4495
1681.99	57.2484
1685.04	52.3878
1688.09	46.0468
1691.13	40.3222
1694.18	34.1341
1697.23	28.6439
1700.27	24.2786
1703.32	18.772
1706.36	15.3757
1709.4	11.9625
1712.44	9.24127
1715.48	7.48217
1718.52	4.47427
1721.56	3.38098
1724.59	3.67278
1727.63	2.41636
1730.66	2.28343
1733.69	2.21433
1736.72	1.09665
1739.75	1.50119
1742.78	1.15646
1745.81	0.750385
1748.84	0.933048
1751.86	-0.305054
1754.89	0.0107303
1757.91	0.335358
1760.93	0.95448
1763.95	0.719096
1766.97	0.195304
1769.99	0.50318
1773.01	0.252079
1776.03	-0.634976
1779.04	-0.513068
1782.06	-0.311488
1785.07	0.353002
1788.08	0.487838
1791.09	0.387778
1794.1	0.415543
1797.11	0.414853
1800.12	1.19985
1803.12	1.08248
1806.13	1.64446
1809.13	1.72936
1812.14	2.09577
1815.14	1.60953
1818.14	1.98016
1821.14	2.61917
1824.14	2.32785
1827.13	2.27211
1830.13	2.4993
1833.12	2.61486
1836.12	2.60748
1839.11	2.78308
1842.1	2.93894
1845.09	2.72258
1848.08	2.39604
1851.07	2.61693
1854.06	3.07
1857.04	3.43832
1860.03	3.85985
1863.01	4.38417
1866	4.52453
1868.98	4.25832
1871.96	5.02526
1874.94	5.38724
1877.92	5.60139
1880.89	6.19777
1882.48	6.07715
1885.47	6.47654
1888.46	6.52155
1891.44	6.99301
1894.43	6.96598
1897.41	7.36265
1900.4	7.43002
1903.38	8.66737
1906.36	8.11508
1909.34	7.92496
1912.32	8.3911
1915.29	8.36803
1918.27	8.60778
1921.25	8.2732
1924.22	8.15752
1927.2	8.24571
1930.17	8.97488
1933.14	8.19817
1936.11	8.05519
1939.08	7.59597
1942.05	7.50314
1945.01	6.92081
1947.98	6.24486
1950.94	6.62352
1953.91	6.47645
1956.87	6.04619
1959.83	5.74031
1962.79	5.65992
1965.75	6.12818
1968.71	7.73983
1971.67	8.64974
1974.62	9.04383
1977.58	9.75488
1980.53	10.468
1983.48	12.0993
1986.43	12.0505
1989.38	12.2525
1992.33	13.2355
1995.28	13.1364
1998.23	13.715
2001.18	13.7636
2004.12	13.6438
2007.06	13.2723
2010.01	13.0424
2012.95	13.6808
2015.89	13.4272
2018.83	14.1742
2021.77	14.264
2024.71	13.7826
2027.64	13.2809
2030.58	13.4205
2033.51	13.608
2036.45	14.173
2039.38	15.1972
2042.31	16.0054
2045.24	16.1737
2048.17	16.3551
2051.1	16.6262
2054.02	16.5147
2056.95	16.3927
2059.87	16.2066
2062.8	16.963
2065.72	16.9117
2068.64	17.0808
2071.56	17.5429
2074.48	18.4754
2077.4	19.2767
2080.31	20.0068
2083.23	20.8286
2086.14	21.8577
2089.06	22.8832
2091.97	23.8132
2094.88	24.5423
2097.79	25.7663
2100.7	28.3536
2103.61	30.0189
2106.52	32.1355
2109.43	34.2943
2112.33	35.8817
2115.24	38.1261
2118.14	40.9887
2121.04	43.2123
2123.94	46.0991
2126.84	48.4121
2129.74	51.5705
2132.64	53.7483
2135.54	56.5285
2138.43	60.3697
2141.33	63.9701
2144.22	66.9353
2147.11	69.796
2150.01	72.5429
2152.9	75.8852
2155.79	78.4843
2158.67	82.0197
2161.56	84.9405
2164.45	86.2443
2167.33	88.5212
2170.22	89.6605
2173.1	90.8305
2175.98	91.5028
2178.86	91.0892
2181.74	90.9864
2184.62	89.5232
2187.5	88.2448
2190.38	86.3174
2193.25	83.1629
2196.13	79.9935
2199	76.6363
2201.88	72.5202
2204.75	68.6904
2207.62	65.1184
2210.49	61.0543
2213.36	57.2976
2216.22	54.4381
2219.09	50.9257
2221.96	47.42
2224.82	44.6633
2227.68	41.2065
2230.55	37.4715
2233.41	34.34
2236.27	32.1363
2239.12	30.925
2241.98	28.7959
2244.84	27.8988
2247.7	26.9687
2250.55	25.9717
2253.41	24.953
2256.26	24.025
2259.11	23.7337
2261.96	22.2955
2264.81	21.7384
2267.66	21.4572
2270.51	21.0482
2273.35	20.0237
2276.2	19.8499
2279.04	20.0651
2281.89	20.0459
2284.73	19.7739
2287.57	19.157
2290.41	16.4303
2293.25	14.5584
2296.09	13.3583
2298.93	12.0526
2301.76	12.2925
2304.6	12.6479
2307.44	12.5316
2310.27	11.0862
2313.1	11.2822
2315.93	11.7522
2318.76	11.548
2321.59	11.239
2324.42	10.0574
2327.25	10.3143
2330.07	9.03126
2332.9	8.29635
2335.72	8.4819
2338.55	8.6169
2341.37	8.01328
2344.19	7.43742
2347.01	7.75108
2349.83	7.78735
2352.65	6.68942
2355.46	5.45269
2358.28	4.24847
2361.09	3.55514
2363.91	4.31458
2366.72	4.27585
2369.53	4.77875
2372.34	4.34993
2375.15	3.38101
2377.96	2.98527
2380.77	3.05231
2383.58	2.59836
2386.38	2.62929
2389.19	2.38161
2391.99	2.40096
2394.8	2.51179
2397.6	2.66021
2400.4	3.03159
2403.2	3.55976
2406	4.39287
2408.79	5.00908
2411.59	4.97895
2414.39	4.58433
2417.18	4.94293
2419.98	4.16852
2422.77	3.41802
2425.56	3.37523
2428.35	3.30495
2431.14	3.43983
2433.93	3.57702
2436.72	2.83166
2439.5	3.32706
2442.29	2.97899
2445.07	2.51618
2447.86	2.01423
2450.64	2.21373
2453.42	2.82954
2456.2	3.06669
2458.98	3.28423
2461.76	3.38535
2464.54	3.75446
2467.32	4.16515
2470.09	4.15743
2472.87	4.04735
2475.64	4.54318
2478.41	4.29542
2481.18	4.09299
2483.95	2.91856
2486.72	2.49411
2489.49	2.11071
2492.26	2.03001
2495.03	1.90884
2497.79	1.70725
2500.56	1.28518
2503.32	0.785876
2506.09	0.603523
2508.85	0.380269
2511.61	-1.30492
2514.37	-0.528387
2517.13	-0.373338
2519.89	0.198051
2522.64	0.436082
2525.4	0.75522
2528.15	2.26505
2530.91	3.36314
2533.66	3.05959
2536.41	3.64184
2539.16	3.97189
2541.91	5.6689
2544.66	5.71225
2547.41	6.39555
2550.16	6.61128
2552.9	6.50662
2555.65	7.1494
2558.39	7.23531
2561.13	7.03225
2563.88	6.61441
2566.62	7.01425
2569.36	6.93657
2572.1	6.24241
2574.84	5.69391
2577.57	4.89879
2580.31	4.64039
2583.05	4.40899
2585.78	3.68623
2588.51	3.61416
2591.24	3.09486
2593.98	2.70979
2596.71	1.78132
2599.44	0.936087
2602.16	1.03596
2604.89	0.668484
2607.62	0.642546
2610.34	0.177445
2613.07	-0.190012
2615.79	-0.0598787
2618.52	0.0460661
2621.24	-0.310489
2623.96	0.434483
2626.68	0.256798
2629.4	0.245228
2632.11	0.69367
2634.83	0.87306
2637.55	0.891537
2640.26	0.973305
2642.98	0.956592
2645.69	0.990559
2648.4	0.394138
2651.11	0.383604
2653.82	0.73606
2656.53	0.452325
2659.24	0.0987963
2661.95	1.07428
2664.65	1.09453
2667.36	2.723
2670.06	2.89327
2672.76	3.37926
2675.47	3.45181
2678.17	4.10162
2680.87	4.49475
2683.57	4.63941
2686.27	5.35378
2688.97	5.42601
2691.66	5.19886
2694.36	5.88738
2697.05	5.75367
2699.75	6.90258
2702.44	6.88333
2705.13	7.31403
2707.82	8.04949
2710.51	8.14639
2713.2	9.82972
2715.89	10.913
2718.57	11.9991
2721.26	12.5548
2723.95	12.6081
2726.63	12.9025
2729.31	13.6814
2732	13.9354
2734.68	13.9661
2737.36	14.0521
2740.04	14.0477
2742.72	14.0072
2745.39	13.0422
2748.07	12.6771
2750.75	12.2398
2753.42	11.7467
2756.09	10.8577
2758.77	10.0658
2761.44	9.63416
2764.11	8.4779
2766.78	8.36892
2769.45	8.91492
2772.12	8.85686
2774.78	9.27986
2777.45	9.29934
2780.12	9.55925
2782.78	9.13949
2785.44	9.1051
2788.11	8.54588
2790.77	8.75402
2793.43	8.96755
2796.09	9.04253
2798.75	9.68278
2801.4	10.1663
2804.06	10.4167
2806.72	10.5262
2809.37	10.362
2812.03	10.5954
2814.68	10.0021
2817.33	10.7817
2819.98	11.6671
2822.63	12.8806
2825.28	15.4493
2827.93	18.7909
2830.58	21.9328
2833.23	25.8617
2835.87	29.4972
2838.52	33.9538
2841.16	39.4265
2843.8	45.7479
2846.44	53.2877
2849.08	61.7164
2851.73	70.056
2854.36	79.3597
2857	90.2349
2859.64	100.093
2862.28	109.871
2864.91	118.347
2867.55	127.234
2870.18	134.91
2872.81	141.494
2875.44	147.376
2878.07	152.046
2880.7	157.087
2883.33	162.183
2885.96	167.99
2888.59	172.845
2891.21	176.794
2893.84	181.667
2896.46	187.112
2899.09	194.836
2901.71	202.627
2904.33	212.582
2906.95	224.035
2909.57	237.138
2912.19	251.606
2914.81	265.219
2917.43	279.135
2920.04	291.405
2922.66	302.653
2925.27	310.837
2927.88	317.004
2930.5	321.681
2933.11	323.936
2935.72	322.489
2938.33	319.606
2940.94	313.835
2943.54	307.128
2946.15	299.14
2948.76	290.651
2951.36	279.744
2953.97	267.806
2956.57	256.536
2959.17	244.873
2961.77	234.384
2964.37	222.87
2966.97	211.687
2969.57	202.481
2972.17	193.225
2974.77	183.953
2977.36	174.111
2979.96	163.788
2982.55	153.855
2985.15	142.447
2987.74	131.6
2990.33	121.236
2992.92	110.885
2995.51	100.959
2998.1	91.7879
3000.69	82.8867
3003.27	74.1237
3005.86	66.1838
3008.44	60.5816
3011.03	55.1064
3013.61	50.7379
3016.19	45.7553
3018.78	42.0483
3021.36	38.7248
3023.94	35.5313
3026.51	33.0314
3029.09	32.0817
3031.67	31.2239
3034.24	31.9878
3036.82	32.1531
3039.39	31.7944
3041.97	32.737
3044.54	33.2159
3047.11	33.567
3049.68	33.4883
3052.25	33.7198
3054.82	34.0142
3057.39	33.7707
3059.96	33.5819
3062.52	33.0959
3065.09	31.4598
3067.65	29.6945
3070.22	28.5503
3072.78	27.1381
3075.34	24.4913
3077.9	22.4509
3080.46	19.8559
3083.02	16.9844
3085.58	14.458
3088.14	12.5915
3090.69	10.8567
3093.25	9.49364
3095.8	7.84107
3098.36	6.32676
3100.91	4.21531
3103.46	3.21537
3106.01	2.19937
3108.56	1.85871
3111.11	0.883744
3113.66	0.738466
3116.21	1.52106
3118.76	1.62414
3121.3	1.10521
3123.85	1.58505
3126.39	1.03611
3128.93	0.624761
3131.48	1.60047
3134.02	1.28441
3136.56	0.93854
3139.1	0.486644
3141.64	-0.236702
3144.17	-1.21772
3146.71	-2.96458
3149.25	-7.54825