File: data/Raman/poly_smoothed/Thy_00_07_47_1x_45s_532 nm_x100_100%_600 gr_mm_01_0.txt
#Acq. time (s)=	45
#Accumulations=	2
#Range (cm-¹)=	200...3150
#Windows=	2
#Auto scanning=	Off
#Autofocus=	Off
#Macrospot=	Off
#AutoExposure=	Off
#Spike filter=	Multiple accum.
#Delay time (s)=	0
#Binning=	1
#Readout mode=	Signal
#DeNoise=	Off
#ICS correction=	On
#Dark correction=	Off
#Inst. Process=	Off
#Detector Gain=	Best Dynamic Range
#Detector ADC=	20 kHz
#Detector temperature (°C)=	-69.85
#Instrument=	LabRAM HR Evol
#Detector=	Synapse
#Objective=	x100
#Grating=	600 gr/mm
#ND Filter=	100%
#Laser (nm)=	532
#Hole=	100.021
#Range=	Auto
#Laser Pol.=	No
#Raman. Pol.=	No
#Laser Pol. (°)=	-0.0007625
#Raman Pol. (°)=	89.9995
#Collection=	Microscope
#StageXY=	Marzhauser
#StageZ=	Marzhauser
#X (µm)=	-1426.6
#Y (µm)=	-622.7
#Z (µm)=	-227.9
#Full time(mm:ss)=	3:18
#Project=
#Sample=
#Site=
#Title=	Thy_00_07_47_2x_45s_532 nm_x100_100%_600 gr_mm
#Remark=
#Date=	29.06.2022 09:49
#Acquired=	29.06.2022 09:49:01
#Base:Fit=	10.08.2022 10:07:56
#Base:Sub=	10.08.2022 10:08:40
#Filter:Polynom=	16.08.2022 10:26:06
#AxisType[0]=Intens
#AxisUnit[0]=Cnt
#AxisType[1]=Spectr
#AxisUnit[1]=1/cm
200.523	-0.24459
204.154	3.9272
207.781	6.41328
211.409	7.76647
215.034	8.56429
218.659	9.83758
222.281	10.5661
225.903	9.9947
229.522	10.2717
233.14	10.4379
236.756	9.09892
240.373	8.20123
243.986	7.66684
247.598	7.98382
251.208	8.34464
254.818	5.2404
258.427	3.66313
262.034	3.79191
265.638	2.7936
269.242	1.90124
272.844	-0.235318
276.445	-0.0646279
280.044	0.717112
283.642	1.30669
287.238	3.60508
290.833	4.80315
294.425	6.68839
298.017	8.33141
301.608	10.5015
305.198	12.251
308.786	13.7264
312.371	16.0672
315.956	17.1595
319.54	18.3073
323.122	19.4783
326.701	20.7148
330.281	21.5873
333.857	22.3135
337.434	22.9637
341.008	22.2277
344.582	21.4237
348.153	20.765
351.724	18.8866
355.292	19.0808
358.861	17.2015
362.426	16.6868
365.99	15.5096
369.555	15.4518
373.116	15.9194
376.676	16.9321
380.236	16.6521
383.793	16.6144
387.349	17.0398
390.903	16.9046
394.456	16.578
398.007	16.2222
401.56	15.0193
405.108	15.0168
408.656	14.1611
412.202	15.0571
415.746	14.5874
419.29	14.8645
422.831	16.0819
426.37	15.9103
429.909	14.8015
433.447	13.3631
436.983	12.1915
440.519	13.0908
444.052	14.6734
447.583	18.1107
451.114	20.865
454.643	24.9405
458.169	30.0525
461.696	33.3371
465.222	37.9542
468.744	40.5183
472.267	44.3776
475.787	44.4069
479.307	45.3458
482.823	46.3182
486.341	48.0986
489.855	48.8767
493.37	50.0913
496.881	50.4714
500.391	50.218
503.902	47.9822
507.409	45.3335
510.915	40.2183
514.42	33.8506
517.925	29.127
521.427	26.5118
524.928	24.6485
528.427	23.6959
531.925	22.5225
535.422	20.5539
538.917	19.5905
542.411	18.9104
545.903	19.2023
549.395	18.6716
552.884	17.5504
556.373	17.0828
559.86	16.9862
563.346	18.5021
566.831	19.1136
570.314	20.0478
573.794	19.6976
577.274	20.701
580.754	22.1511
584.23	21.7459
587.706	20.9611
591.181	18.9312
594.653	16.6983
598.126	15.3424
601.595	13.9571
605.065	13.453
608.532	13.7916
611.999	12.4935
615.463	11.9763
618.928	11.7471
622.389	10.8596
625.851	10.8769
629.31	10.6582
632.767	9.57494
636.223	9.61358
639.68	10.8698
643.134	11.524
646.586	12.9401
650.037	13.684
653.486	12.5003
656.936	13.0288
660.383	14.3452
663.829	15.3637
667.273	15.2808
670.716	13.8773
674.158	13.8101
677.598	14.5436
681.035	17.172
684.473	18.9678
687.909	19.7428
691.344	22.4022
694.778	23.5478
698.211	24.8592
701.64	25.8816
705.07	27.0889
708.498	27.7384
711.924	29.0956
715.35	30.072
718.774	32.3687
722.196	35.1059
725.618	37.3276
729.037	37.7122
732.456	40.3561
735.873	41.5748
739.289	43.7621
742.703	46.3765
746.116	48.0625
749.529	49.0748
752.938	51.8109
756.347	55.7117
759.756	60.2176
763.162	62.4825
766.567	63.8809
769.97	65.0607
773.372	67.322
776.773	69.4117
780.174	69.9198
783.573	69.9938
786.97	69.8024
790.365	70.5507
793.76	70.0405
797.153	70.279
800.543	69.0515
803.933	70.1234
807.322	68.6773
810.71	69.4292
814.097	69.0412
817.483	70.4574
820.865	73.2875
824.248	74.6982
827.629	75.2291
831.008	75.8756
834.387	77.7081
837.765	79.6755
841.139	80.0691
844.514	77.708
847.886	74.9388
851.259	73.7331
854.629	73.0918
857.997	71.6001
861.366	67.0972
864.732	62.7341
868.098	59.075
871.461	55.5322
874.823	53.3752
878.184	49.4667
881.545	45.6081
884.903	44.1842
888.26	43.9679
891.616	42.4498
894.97	43.1468
898.323	43.5876
901.675	47.5468
905.026	48.9547
908.375	50.5502
911.723	53.4231
915.07	55.9502
918.415	58.8658
921.76	59.3176
925.103	58.7288
928.443	58.4529
931.783	59.6633
935.123	60.3987
938.461	58.481
941.796	54.6505
945.131	50.7141
948.465	45.4109
951.797	41.1282
955.128	37.2528
958.457	31.7561
961.786	26.9335
965.113	23.6848
968.44	22.439
971.763	21.9897
975.086	20.8474
978.409	20.3816
981.729	19.3659
985.048	19.1999
988.367	19.0519
991.683	19.2737
994.998	20.6697
998.312	20.729
1001.62	22.509
1004.94	25.6046
1008.25	28.3719
1011.56	30.389
1014.86	32.4141
1018.17	34.9154
1021.48	35.4762
1024.78	36.22
1028.08	36.2362
1031.38	35.9454
1034.68	36.432
1037.98	36.9028
1041.28	37.0436
1044.57	39.1255
1047.87	40.419
1051.16	41.685
1054.45	42.9756
1057.75	42.2451
1061.04	41.1513
1064.32	41.9494
1067.61	41.0116
1070.9	40.0756
1074.18	39.1686
1077.47	40.1027
1080.75	39.2975
1084.03	40.0944
1087.31	40.9831
1090.59	42.8981
1093.86	44.987
1097.14	46.8914
1100.41	49.1435
1103.69	49.909
1106.96	50.6266
1110.23	51.9403
1113.5	51.3256
1116.77	50.3197
1120.03	51.014
1123.3	50.7122
1126.56	50.0226
1129.83	49.0576
1133.09	48.0754
1136.35	44.8673
1139.61	42.198
1142.86	38.7362
1146.12	34.5642
1149.38	29.8424
1152.63	25.6204
1155.88	20.4315
1159.14	16.0125
1162.39	10.9561
1165.63	9.21431
1168.88	7.63739
1172.13	5.98301
1175.38	6.89433
1178.62	6.31554
1181.86	5.07676
1185.1	6.08767
1188.34	5.87464
1191.58	7.27326
1194.82	7.86309
1198.06	9.67197
1201.29	11.1514
1204.53	12.5613
1207.76	15.827
1210.99	19.3941
1214.22	21.2308
1217.45	23.2153
1220.68	25.4717
1223.91	28.4523
1227.13	31.495
1230.36	34.138
1233.58	36.1809
1236.8	37.595
1240.02	40.1075
1243.24	41.7124
1246.46	44.7828
1249.67	46.3569
1252.89	47.8434
1256.1	46.4458
1259.32	45.5576
1262.53	45.2389
1265.74	45.2916
1268.95	44.2577
1272.15	43.3146
1275.36	42.3046
1278.57	41.4031
1281.77	43.3259
1284.97	44.7487
1288.18	46.7413
1291.38	47.6646
1294.58	49.032
1297.78	52.5947
1300.97	58.2588
1304.17	63.6944
1307.36	70.6527
1310.55	75.6773
1313.75	81.2344
1316.94	86.2332
1320.13	89.9999
1323.32	93.8194
1326.5	97.3609
1329.69	99.0082
1332.87	100.758
1336.06	101.606
1339.24	100.896
1342.42	99.2977
1345.6	95.9429
1348.78	92.3287
1351.96	89.37
1355.13	86.6775
1358.31	83.4615
1361.48	78.991
1364.65	74.9336
1367.82	71.4291
1370.99	68.4352
1374.16	66.701
1377.33	66.3159
1380.5	65.4861
1383.66	64.0422
1386.83	65.2582
1389.99	64.4976
1393.15	62.1702
1396.31	59.8369
1399.47	60.1392
1402.63	60.2835
1405.78	58.9013
1408.94	59.0543
1412.1	59.5919
1415.25	60.3631
1418.4	59.5867
1421.55	60.1782
1424.7	63.1642
1427.85	65.8447
1431	70.8392
1434.14	73.8975
1437.29	77.0238
1440.43	80.7335
1443.57	82.174
1446.71	83.5065
1449.85	83.3305
1452.99	83.1102
1456.13	80.5269
1459.26	78.6173
1462.4	75.7568
1465.54	71.1019
1468.67	63.2356
1471.8	56.3974
1474.93	51.2263
1478.06	45.664
1481.19	39.1661
1484.31	34.3733
1487.44	27.6953
1490.56	22.4403
1493.69	16.8968
1496.81	13.6688
1499.93	12.4438
1503.05	11.2436
1506.17	10.6159
1509.28	12.6152
1512.4	12.248
1515.52	12.2012
1518.63	11.6102
1521.74	11.6639
1524.85	11.7064
1527.96	13.0962
1531.07	16.2846
1534.18	17.6264
1537.29	19.6114
1540.39	20.0145
1543.5	20.1798
1546.6	22.8204
1549.7	24.4233
1552.8	27.6647
1555.9	29.9096
1559	31.9453
1562.1	33.3832
1565.19	34.6352
1568.29	36.325
1571.38	40.1411
1574.47	44.0651
1577.56	46.7308
1580.66	50.0484
1583.74	53.065
1586.83	55.5964
1589.92	56.722
1593.01	58.2987
1596.09	59.6434
1599.17	58.5047
1602.25	59.1631
1605.34	59.9667
1608.41	58.9963
1611.49	56.8898
1614.57	55.6201
1617.65	53.9731
1620.72	53.0593
1623.79	52.0026
1626.87	51.7791
1629.94	51.4216
1633.01	51.4187
1636.08	51.6445
1639.15	52.2687
1642.21	53.6057
1645.28	53.6109
1648.34	55.179
1651.41	55.084
1654.47	56.2972
1657.53	55.746
1660.59	55.8119
1663.65	54.8447
1666.71	53.5273
1669.76	50.7184
1672.82	48.6285
1675.87	45.7984
1678.93	43.7027
1681.98	41.1147
1685.03	38.8248
1688.08	35.8781
1691.13	33.1135
1694.17	30.5501
1697.22	26.2231
1700.27	23.8697
1703.31	22.5972
1706.35	21.9461
1709.39	20.7023
1712.43	19.3984
1715.47	17.8728
1718.51	15.363
1721.55	13.7589
1724.58	12.9445
1727.62	13.0754
1730.65	12.1503
1733.68	10.9051
1736.72	9.6435
1739.74	9.14157
1742.77	7.65036
1745.8	6.73603
1748.83	6.17674
1751.85	6.14768
1754.88	5.17694
1757.9	4.7742
1760.92	3.11246
1763.95	2.42151
1766.96	2.20207
1769.98	1.08815
1773	1.16876
1776.02	1.97324
1779.03	3.3017
1782.05	2.76479
1785.06	1.62708
1788.07	1.41322
1791.08	1.36017
1794.09	1.6066
1797.1	0.94798
1800.11	1.45401
1803.12	1.69538
1806.12	1.55856
1809.12	2.0634
1812.13	2.93066
1815.13	3.54436
1818.13	2.98415
1821.13	2.8285
1824.13	3.04852
1827.13	3.18667
1830.12	3.70458
1833.12	3.46672
1836.11	3.47935
1839.1	3.9057
1842.09	4.4113
1845.09	4.86598
1848.08	4.81367
1851.06	4.23089
1854.05	3.78485
1857.04	3.08299
1860.02	4.59461
1863.01	4.44311
1865.99	4.68142
1868.97	4.72456
1871.95	5.12521
1874.93	4.38444
1877.91	4.7497
1880.89	4.38368
1882.46	3.9871
1885.45	3.85317
1888.43	2.90883
1891.42	2.74758
1894.41	2.85207
1897.39	3.36576
1900.37	2.92072
1903.36	3.28316
1906.34	3.82054
1909.32	4.35933
1912.29	3.80693
1915.27	2.78646
1918.25	1.6228
1921.23	0.672878
1924.2	1.14146
1927.17	1.21461
1930.15	1.1594
1933.12	1.53811
1936.09	1.26268
1939.06	1.6296
1942.02	2.0059
1944.99	2.35344
1947.96	1.98294
1950.92	2.20826
1953.88	1.63728
1956.85	1.6135
1959.81	2.74338
1962.77	3.99027
1965.73	4.4364
1968.69	4.94898
1971.64	5.42841
1974.6	5.72363
1977.55	7.03677
1980.51	6.27559
1983.46	5.07502
1986.41	4.57365
1989.36	3.69855
1992.31	4.04629
1995.26	4.29695
1998.21	3.51469
2001.15	3.20452
2004.1	3.94297
2007.04	3.77681
2009.99	3.64327
2012.93	4.06624
2015.87	4.52453
2018.81	4.25563
2021.75	4.43709
2024.68	5.48145
2027.62	5.82748
2030.56	7.06519
2033.49	7.52237
2036.42	7.65118
2039.36	7.79225
2042.29	7.24813
2045.22	8.13305
2048.14	8.68596
2051.07	8.94037
2054	8.97544
2056.93	8.63868
2059.85	8.69002
2062.77	8.93411
2065.7	8.59015
2068.62	8.33768
2071.54	7.95358
2074.46	8.17098
2077.38	7.17237
2080.29	6.14455
2083.21	6.88934
2086.12	6.63501
2089.04	5.94932
2091.95	5.64899
2094.86	5.54508
2097.77	4.82312
2100.68	5.35861
2103.59	4.19328
2106.5	3.84959
2109.41	3.6096
2112.31	2.65728
2115.21	2.89317
2118.12	3.14902
2121.02	2.3649
2123.92	2.20214
2126.82	2.19841
2129.72	2.89886
2132.62	3.18176
2135.51	3.09821
2138.41	3.3374
2141.31	5.34472
2144.2	5.72949
2147.09	6.40669
2149.98	7.36857
2152.87	8.37723
2155.76	7.89622
2158.65	7.4336
2161.54	7.06504
2164.43	7.87774
2167.31	7.87627
2170.2	7.97761
2173.08	8.9627
2175.96	8.9719
2178.84	8.86119
2181.72	8.38594
2184.6	7.7377
2187.48	7.97022
2190.36	6.69002
2193.23	5.92301
2196.11	5.95117
2198.98	5.40181
2201.85	5.55911
2204.72	5.13822
2207.59	5.65305
2210.46	6.46783
2213.33	6.11096
2216.2	5.59903
2219.07	5.34832
2221.93	5.05566
2224.8	4.16591
2227.66	4.12452
2230.52	3.70984
2233.39	4.06017
2236.25	3.72473
2239.1	4.1345
2241.96	4.80749
2244.82	5.02802
2247.68	4.96625
2250.53	4.48029
2253.38	3.80321
2256.24	3.60547
2259.09	2.84865
2261.94	1.89979
2264.79	0.996813
2267.64	0.906644
2270.49	1.84219
2273.33	1.96605
2276.18	1.29425
2279.02	1.5633
2281.87	2.14731
2284.71	2.49808
2287.55	2.79657
2290.39	2.34606
2293.23	2.51449
2296.07	3.09027
2298.91	4.36339
2301.74	4.80159
2304.58	5.10676
2307.41	5.70838
2310.25	6.28211
2313.08	6.45023
2315.91	6.2436
2318.74	6.31184
2321.57	6.10098
2324.4	6.61087
2327.23	6.6047
2330.05	5.65369
2332.88	5.28434
2335.7	5.21372
2338.52	5.15462
2341.35	3.25401
2344.17	3.0272
2346.99	2.45456
2349.81	1.54718
2352.62	2.07013
2355.44	1.28675
2358.26	-0.708601
2361.07	-0.0556409
2363.89	0.95395
2366.7	1.23768
2369.51	0.689229
2372.32	0.660369
2375.13	0.773154
2377.94	1.28822
2380.75	1.61001
2383.56	2.58629
2386.36	3.15324
2389.17	3.20405
2391.97	3.14766
2394.77	2.87279
2397.58	2.16357
2400.38	3.20971
2403.18	2.89171
2405.97	2.88877
2408.77	3.68926
2411.57	5.18718
2414.37	5.79965
2417.16	5.64396
2419.95	6.8631
2422.75	7.82347
2425.54	8.22044
2428.33	9.1002
2431.12	10.6864
2433.91	11.1556
2436.7	11.1857
2439.48	11.7704
2442.27	11.534
2445.05	10.9842
2447.84	9.56857
2450.62	9.41734
2453.4	8.76248
2456.18	6.97019
2458.96	5.81527
2461.74	5.28495
2464.52	4.87836
2467.29	4.11111
2470.07	4.60755
2472.85	3.97987
2475.62	3.82938
2478.39	3.80812
2481.16	3.3551
2483.93	2.16481
2486.7	1.56604
2489.47	1.72574
2492.24	3.02478
2495.01	3.09103
2497.77	3.35041
2500.54	3.41769
2503.3	3.26742
2506.06	3.10887
2508.83	2.24349
2511.59	1.3618
2514.35	0.972231
2517.11	1.0597
2519.86	1.33364
2522.62	2.13334
2525.38	2.34486
2528.13	3.39888
2530.89	3.70195
2533.64	4.0439
2536.39	4.85546
2539.14	4.77111
2541.89	4.45551
2544.64	4.32419
2547.39	4.08672
2550.14	4.58717
2552.88	4.56948
2555.63	4.21684
2558.37	5.37999
2561.11	4.56055
2563.86	4.1346
2566.6	3.59328
2569.34	3.62433
2572.08	2.74905
2574.82	1.75687
2577.55	1.22166
2580.29	1.09401
2583.02	1.49719
2585.76	2.10942
2588.49	2.97065
2591.22	4.30125
2593.96	4.27325
2596.69	4.35079
2599.42	4.54944
2602.14	4.41977
2604.87	5.18592
2607.6	5.47008
2610.32	6.00327
2613.05	6.69425
2615.77	7.99894
2618.49	8.57863
2621.22	8.47551
2623.94	7.88071
2626.66	7.22339
2629.37	6.73336
2632.09	6.52095
2634.81	6.44658
2637.53	6.37803
2640.24	5.50821
2642.96	5.35588
2645.67	4.75731
2648.38	5.36083
2651.09	5.77834
2653.8	5.1109
2656.51	4.38971
2659.22	4.07543
2661.93	3.78295
2664.63	3.47506
2667.34	2.56423
2670.04	2.36423
2672.75	3.14869
2675.45	2.81157
2678.15	3.46172
2680.85	3.80553
2683.55	3.77742
2686.25	4.09409
2688.94	4.83234
2691.64	5.9247
2694.34	6.42085
2697.03	6.6521
2699.73	8.00273
2702.42	8.5096
2705.11	9.0356
2707.8	9.24318
2710.49	10.0119
2713.18	10.5648
2715.87	11.8679
2718.55	11.6338
2721.24	11.3302
2723.93	11.6697
2726.61	12.2693
2729.29	12.3247
2731.98	11.4605
2734.66	11.9837
2737.34	12.2022
2740.02	11.9926
2742.7	12.4643
2745.37	11.4839
2748.05	10.737
2750.72	10.4703
2753.4	9.60615
2756.07	8.98234
2758.75	7.61467
2761.42	6.17196
2764.09	5.82231
2766.76	5.07915
2769.43	4.09291
2772.1	3.74349
2774.76	3.28746
2777.43	2.0995
2780.1	1.51157
2782.76	1.14229
2785.42	0.957623
2788.09	1.16988
2790.75	1.68586
2793.41	1.42937
2796.07	2.16955
2798.73	2.23321
2801.39	1.75988
2804.04	1.11568
2806.7	1.30954
2809.35	0.301257
2812.01	0.744241
2814.66	0.884744
2817.31	1.15434
2819.96	2.61787
2822.61	4.72144
2825.26	7.47168
2827.91	10.8921
2830.56	15.0079
2833.21	18.8996
2835.85	23.1228
2838.5	27.7714
2841.14	33.6498
2843.78	40.233
2846.42	47.0803
2849.06	55.2251
2851.71	64.9317
2854.34	73.3789
2856.98	82.7005
2859.62	92.2527
2862.26	101.606
2864.89	111.325
2867.53	120.265
2870.16	130.665
2872.79	139.696
2875.42	149.181
2878.05	159.216
2880.68	169.079
2883.31	179.405
2885.94	188.626
2888.57	196.98
2891.19	207.153
2893.82	217.001
2896.44	225.127
2899.07	232.532
2901.69	240.41
2904.31	249.154
2906.93	257.028
2909.55	264.343
2912.17	270.978
2914.79	278.309
2917.41	283.113
2920.02	287.075
2922.64	288.388
2925.25	289.793
2927.86	289.65
2930.48	286.75
2933.09	282.77
2935.7	278.299
2938.31	271.6
2940.92	264.796
2943.53	258.336
2946.13	249.355
2948.74	241.073
2951.34	232.674
2953.95	223.652
2956.55	214.657
2959.15	205.02
2961.75	195.367
2964.35	185.793
2966.95	176.473
2969.55	166.993
2972.15	158.439
2974.75	148.799
2977.34	139.771
2979.94	129.147
2982.53	118.052
2985.13	107.803
2987.72	96.9969
2990.31	87.3978
2992.9	78.1485
2995.49	67.7861
2998.08	59.0933
3000.67	50.1188
3003.25	42.4699
3005.84	34.8216
3008.42	28.4196
3011.01	22.0722
3013.59	17.2143
3016.17	13.4934
3018.76	9.90215
3021.34	7.54245
3023.92	5.7087
3026.49	3.89712
3029.07	1.96853
3031.65	1.77065
3034.23	1.47994
3036.8	1.85838
3039.38	2.2237
3041.95	3.11412
3044.52	4.24636
3047.09	6.21237
3049.66	8.35001
3052.23	10.4536
3054.8	11.8552
3057.37	12.5034
3059.94	12.063
3062.5	12.7683
3065.07	12.8612
3067.63	12.0825
3070.2	11.9527
3072.76	11.5074
3075.32	10.7624
3077.88	11.2256
3080.44	11.1655
3083	10.2118
3085.56	10.1661
3088.12	9.88168
3090.67	9.71146
3093.23	10.8571
3095.78	12.6863
3098.34	13.9154
3100.89	15.7278
3103.44	17.9763
3105.99	20.6014
3108.54	22.3377
3111.09	26.243
3113.64	29.6754
3116.19	32.4939
3118.74	35.6464
3121.28	38.5558
3123.83	41.4103
3126.37	44.7072
3128.91	47.7971
3131.46	50.4589
3134	53.224
3136.54	55.7199
3139.08	58.5912
3141.62	61.2262
3144.16	63.6784
3146.69	65.3845
3149.23	68.1584