File: data/Raman/poly_smoothed/Thy_20_09_37_1x_45s_532 nm_x100_100%_600 gr_mm_01.txt
#Acq. time (s)=	45
#Accumulations=	2
#Range (cm-¹)=	200...3150
#Windows=	2
#Auto scanning=	Off
#Autofocus=	Off
#Macrospot=	Off
#AutoExposure=	Off
#Spike filter=	Multiple accum.
#Delay time (s)=	0
#Binning=	1
#Readout mode=	Signal
#DeNoise=	Off
#ICS correction=	On
#Dark correction=	Off
#Inst. Process=	Off
#Detector Gain=	Best Dynamic Range
#Detector ADC=	20 kHz
#Detector temperature (°C)=	-70.08
#Instrument=	LabRAM HR Evol
#Detector=	Synapse
#Objective=	x100
#Grating=	600 gr/mm
#ND Filter=	100%
#Laser (nm)=	532
#Hole=	100.021
#Range=	Auto
#Laser Pol.=	No
#Raman. Pol.=	No
#Laser Pol. (°)=	-0.0007625
#Raman Pol. (°)=	89.9995
#Collection=	Microscope
#StageXY=	Marzhauser
#StageZ=	Marzhauser
#X (µm)=	-5916.5
#Y (µm)=	2865.3
#Z (µm)=	-223.5
#Full time(mm:ss)=	3:18
#Project=
#Sample=
#Site=
#Title=	Thy_20_09_37_2x_45s_532 nm_x100_100%_600 gr_mm
#Remark=
#Date=	29.06.2022 13:15
#Acquired=	29.06.2022 13:15:32
#Base:Fit=	10.08.2022 09:52:02
#Base:Fit=	10.08.2022 09:52:12
#Base:Sub=	10.08.2022 09:54:21
#Filter:Polynom=	16.08.2022 10:24:04
#AxisType[0]=Intens
#AxisUnit[0]=Cnt
#AxisType[1]=Spectr
#AxisUnit[1]=1/cm
200.523	21.7287
204.154	22.4334
207.781	21.0236
211.409	19.3377
215.034	16.5647
218.659	14.9194
222.281	12.5374
225.903	11.8089
229.522	9.56447
233.14	7.9476
236.756	6.22374
240.373	5.68138
243.986	4.22287
247.598	2.46356
251.208	1.51534
254.818	0.878888
258.427	0.685789
262.034	0.71738
265.638	1.3903
269.242	2.1963
272.844	3.32203
276.445	4.91597
280.044	7.77223
283.642	8.61416
287.238	10.0756
290.833	11.47
294.425	11.2863
298.017	11.6753
301.608	12.8915
305.198	13.8314
308.786	14.4704
312.371	14.8094
315.956	15.9465
319.54	14.1133
323.122	13.1934
326.701	11.696
330.281	10.9828
333.857	8.46111
337.434	8.0733
341.008	7.14666
344.582	6.38198
348.153	6.35219
351.724	6.52275
355.292	6.41999
358.861	5.61922
362.426	6.29264
365.99	7.38672
369.555	7.45559
373.116	7.64252
376.676	8.30928
380.236	7.97545
383.793	7.88312
387.349	9.48139
390.903	11.5483
394.456	12.3462
398.007	12.2106
401.56	12.1073
405.108	10.8253
408.656	9.61391
412.202	8.39879
415.746	7.44779
419.29	7.54351
422.831	7.83879
426.37	7.51275
429.909	6.66906
433.447	7.14681
436.983	6.12767
440.519	6.22219
444.052	7.03492
447.583	8.43222
451.114	8.90184
454.643	10.6013
458.169	11.3582
461.696	12.4686
465.222	14.1669
468.744	15.6021
472.267	17.0026
475.787	19.1015
479.307	22.6423
482.823	23.4819
486.341	24.1596
489.855	23.9694
493.37	23.8955
496.881	22.9439
500.391	22.3596
503.902	23.7169
507.409	23.6728
510.915	23.1781
514.42	22.4335
517.925	23.0783
521.427	22.5135
524.928	22.1293
528.427	21.7022
531.925	22.1244
535.422	21.0633
538.917	20.5453
542.411	20.5254
545.903	18.7115
549.395	17.4467
552.884	17.3825
556.373	17.3622
559.86	16.0491
563.346	14.5406
566.831	14.0304
570.314	11.483
573.794	9.31278
577.274	8.35819
580.754	7.39223
584.23	6.59562
587.706	6.96865
591.181	7.83346
594.653	7.06491
598.126	7.52741
601.595	8.07553
605.065	10.2067
608.532	12.3073
611.999	14.5259
615.463	16.8456
618.928	19.0208
622.389	20.0801
625.851	21.137
629.31	20.9914
632.767	21.5798
636.223	22.4756
639.68	23.8234
643.134	23.6467
646.586	24.017
650.037	25.2929
653.486	26.4471
656.936	26.3991
660.383	27.0617
663.829	27.4028
667.273	28.3292
670.716	27.7357
674.158	29.2465
677.598	31.098
681.035	32.9613
684.473	35.628
687.909	38.025
691.344	40.9403
694.778	41.3408
698.211	43.1994
701.64	43.6905
705.07	45.7582
708.498	46.5997
711.924	47.7443
715.35	48.7064
718.774	50.6822
722.196	52.6124
725.618	54.5011
729.037	55.0483
732.456	57.4245
735.873	59.2243
739.289	59.0798
742.703	59.6244
746.116	61.0019
749.529	62.3508
752.938	63.7945
756.347	64.9287
759.756	68.0405
763.162	70.6822
766.567	70.5604
769.97	72.0734
773.372	73.5715
776.773	75.5218
780.174	77.6835
783.573	78.3825
786.97	78.3353
790.365	78.8563
793.76	79.2132
797.153	79.9762
800.543	80.6264
803.933	82.2011
807.322	82.0183
810.71	80.95
814.097	81.6099
817.483	83.257
820.865	82.7895
824.248	82.4812
827.629	82.6493
831.008	81.6738
834.387	80.6284
837.765	79.2597
841.139	77.4841
844.514	75.624
847.886	73.6178
851.259	71.3769
854.629	69.465
857.997	67.7688
861.366	66.4213
864.732	62.9105
868.098	59.1583
871.461	57.5891
874.823	56.3482
878.184	53.6064
881.545	51.0893
884.903	49.4437
888.26	49.2297
891.616	47.6106
894.97	46.9218
898.323	48.1971
901.675	47.1694
905.026	46.0677
908.375	46.3047
911.723	44.3279
915.07	44.0339
918.415	44.1569
921.76	44.7961
925.103	45.3885
928.443	44.0502
931.783	42.7891
935.123	42.8962
938.461	42.9081
941.796	42.3229
945.131	41.1984
948.465	39.7671
951.797	40.4291
955.128	39.9472
958.457	35.9966
961.786	33.3469
965.113	31.8033
968.44	29.3671
971.763	28.2093
975.086	26.9002
978.409	27.4866
981.729	28.2323
985.048	26.6768
988.367	25.163
991.683	23.1886
994.998	22.569
998.312	23.5834
1001.62	23.0582
1004.94	23.0004
1008.25	21.72
1011.56	20.06
1014.86	20.0991
1018.17	19.8594
1021.48	17.7766
1024.78	17.9685
1028.08	18.2122
1031.38	18.5332
1034.68	17.282
1037.98	15.057
1041.28	13.3934
1044.57	14.0323
1047.87	14.883
1051.16	13.9948
1054.45	15.1019
1057.75	16.1594
1061.04	15.8019
1064.32	14.3148
1067.61	12.8593
1070.9	12.5547
1074.18	12.7764
1077.47	12.7585
1080.75	11.4097
1084.03	12.0457
1087.31	11.8322
1090.59	11.7157
1093.86	11.9793
1097.14	11.4562
1100.41	11.693
1103.69	11.9035
1106.96	12.0429
1110.23	11.9569
1113.5	12.6098
1116.77	11.4337
1120.03	12.1686
1123.3	10.4171
1126.56	9.9615
1129.83	8.2996
1133.09	7.69269
1136.35	7.10728
1139.61	7.83934
1142.86	7.18038
1146.12	6.0926
1149.38	5.77435
1152.63	5.2481
1155.88	2.45506
1159.14	3.89898
1162.39	4.21849
1165.63	4.04458
1168.88	4.17504
1172.13	4.17513
1175.38	5.04652
1178.62	5.663
1181.86	5.66752
1185.1	7.10024
1188.34	8.95917
1191.58	10.5394
1194.82	12.1329
1198.06	12.8206
1201.29	12.9131
1204.53	14.9439
1207.76	18.7556
1210.99	20.6855
1214.22	22.873
1217.45	25.9559
1220.68	27.8148
1223.91	30.1594
1227.13	32.5434
1230.36	34.3418
1233.58	37.1736
1236.8	36.7774
1240.02	37.4201
1243.24	38.6394
1246.46	42.2282
1249.67	44.685
1252.89	45.4335
1256.1	49.1742
1259.32	51.9916
1262.53	54.7098
1265.74	56.599
1268.95	58.1852
1272.15	58.9925
1275.36	60.7866
1278.57	60.1909
1281.77	62.1356
1284.97	63.1665
1288.18	63.2474
1291.38	63.235
1294.58	64.3546
1297.78	63.7617
1300.97	64.1572
1304.17	65.1568
1307.36	65.3023
1310.55	65.1702
1313.75	64.6461
1316.94	63.5264
1320.13	67.0685
1323.32	66.3991
1326.5	67.5397
1329.69	67.0626
1332.87	67.9505
1336.06	67.7748
1339.24	66.4163
1342.42	66.429
1345.6	64.4608
1348.78	61.9537
1351.96	60.0168
1355.13	58.9508
1358.31	57.0746
1361.48	54.9979
1364.65	52.7097
1367.82	51.4426
1370.99	49.3345
1374.16	47.8915
1377.33	46.9654
1380.5	46.7167
1383.66	45.5736
1386.83	45.2602
1389.99	44.9539
1393.15	43.3042
1396.31	41.6719
1399.47	39.7468
1402.63	38.235
1405.78	36.8221
1408.94	36.4124
1412.1	36.3018
1415.25	38.2048
1418.4	39.3965
1421.55	41.5519
1424.7	43.6232
1427.85	47.2416
1431	51.7583
1434.14	54.327
1437.29	57.2708
1440.43	60.8028
1443.57	62.2249
1446.71	64.1857
1449.85	66.55
1452.99	66.0904
1456.13	67.5649
1459.26	65.2893
1462.4	64.4213
1465.54	61.3394
1468.67	56.9878
1471.8	52.14
1474.93	46.2912
1478.06	41.8861
1481.19	37.8648
1484.31	32.8246
1487.44	28.8492
1490.56	26.5549
1493.69	23.9587
1496.81	20.9649
1499.93	19.2444
1503.05	19.3071
1506.17	19.7034
1509.28	18.7929
1512.4	18.0514
1515.52	18.0084
1518.63	19.883
1521.74	20.9216
1524.85	23.9762
1527.96	26.3232
1531.07	28.4264
1534.18	30.0922
1537.29	30.9665
1540.39	32.2722
1543.5	34.532
1546.6	36.0838
1549.7	39.0055
1552.8	40.5947
1555.9	44.1805
1559	46.5542
1562.1	49.1001
1565.19	52.9189
1568.29	55.6386
1571.38	59.2206
1574.47	63.1168
1577.56	65.2571
1580.66	67.4575
1583.74	70.7714
1586.83	71.7995
1589.92	72.1842
1593.01	72.4098
1596.09	72.8918
1599.17	72.105
1602.25	71.2507
1605.34	68.631
1608.41	65.6854
1611.49	63.7471
1614.57	63.2317
1617.65	61.5384
1620.72	60.717
1623.79	60.4301
1626.87	58.459
1629.94	59.129
1633.01	59.9569
1636.08	61.6202
1639.15	63.7213
1642.21	66.5424
1645.28	69.6987
1648.34	70.5534
1651.41	72.4835
1654.47	72.7837
1657.53	74.1454
1660.59	73.5717
1663.65	70.8543
1666.71	68.6009
1669.76	66.2365
1672.82	62.8419
1675.87	59.4174
1678.93	55.0284
1681.98	50.3928
1685.03	46.9855
1688.08	41.6944
1691.13	35.4975
1694.17	31.5137
1697.22	26.951
1700.27	23.3875
1703.31	18.765
1706.35	16.6551
1709.39	15.2112
1712.43	13.1533
1715.47	12.0619
1718.51	10.5876
1721.55	9.27145
1724.58	8.91787
1727.62	8.18646
1730.65	7.88563
1733.68	8.06508
1736.72	7.45857
1739.74	6.83046
1742.77	6.78834
1745.8	5.38544
1748.83	4.63003
1751.85	4.79286
1754.88	3.8067
1757.9	3.09932
1760.92	2.20985
1763.95	1.27774
1766.96	1.39424
1769.98	1.62848
1773	1.06966
1776.02	0.225568
1779.03	0.609478
1782.05	1.16217
1785.06	1.66149
1788.07	1.08196
1791.08	2.3123
1794.09	2.93942
1797.1	2.39901
1800.11	2.62383
1803.12	2.78613
1806.12	2.84457
1809.12	3.65489
1812.13	2.92247
1815.13	2.50965
1818.13	2.68523
1821.13	2.69782
1824.13	2.24439
1827.13	2.31884
1830.12	1.88995
1833.12	2.08081
1836.11	2.13089
1839.1	2.91686
1842.09	3.00397
1845.09	2.04714
1848.08	2.27211
1851.06	3.1649
1854.05	4.20425
1857.04	3.46378
1860.02	3.87871
1863.01	3.50545
1865.99	2.68693
1868.97	2.30237
1871.95	2.01119
1874.93	2.81961
1877.91	2.90994
1880.89	1.81298
1882.46	1.77685
1885.45	1.82032
1888.43	1.49161
1891.42	0.274397
1894.41	-0.204953
1897.39	0.182035
1900.37	0.269527
1903.36	0.526367
1906.34	0.801402
1909.32	1.01243
1912.29	1.68431
1915.27	1.57522
1918.25	2.81717
1921.23	3.05293
1924.2	3.32637
1927.17	3.83229
1930.15	3.36999
1933.12	4.55414
1936.09	4.48274
1939.06	4.74517
1942.02	4.71209
1944.99	4.96875
1947.96	5.69771
1950.92	5.15094
1953.88	4.92715
1956.85	5.24196
1959.81	4.93917
1962.77	4.24598
1965.73	4.48211
1968.69	4.11553
1971.64	4.45462
1974.6	4.92663
1977.55	4.10073
1980.51	4.12607
1983.46	4.05683
1986.41	3.65995
1989.36	2.80375
1992.31	2.74176
1995.26	1.90777
1998.21	1.51751
2001.15	1.29987
2004.1	0.288298
2007.04	0.25776
2009.99	0.185979
2012.93	-0.00883634
2015.87	0.916555
2018.81	1.61036
2021.75	2.40148
2024.68	2.1538
2027.62	3.15647
2030.56	3.98676
2033.49	4.31001
2036.42	5.03728
2039.36	5.91928
2042.29	7.07085
2045.22	7.73893
2048.14	8.43608
2051.07	7.88377
2054	9.34668
2056.93	9.06747
2059.85	8.68873
2062.77	7.18213
2065.7	6.97245
2068.62	6.87177
2071.54	6.60466
2074.46	6.30721
2077.38	6.83848
2080.29	7.13173
2083.21	7.41126
2086.12	7.59599
2089.04	7.7508
2091.95	8.32124
2094.86	7.284
2097.77	8.2817
2100.68	9.11638
2103.59	10.8058
2106.5	11.0538
2109.41	11.4426
2112.31	11.7824
2115.21	13.8444
2118.12	14.9057
2121.02	15.8308
2123.92	17.5312
2126.82	18.2629
2129.72	18.6542
2132.62	19.2386
2135.51	20.7426
2138.41	23.4318
2141.31	25.4236
2144.2	27.5183
2147.09	27.844
2149.98	28.6131
2152.87	29.0938
2155.76	30.1386
2158.65	31.1042
2161.54	32.2348
2164.43	31.9959
2167.31	32.7699
2170.2	33.4809
2173.08	33.6145
2175.96	33.5197
2178.84	33.2948
2181.72	32.8589
2184.6	33.9431
2187.48	33.7962
2190.36	32.3567
2193.23	31.5496
2196.11	31.3774
2198.98	30.263
2201.85	28.9111
2204.72	28.5333
2207.59	27.0726
2210.46	27.0566
2213.33	25.141
2216.2	22.3626
2219.07	20.0623
2221.93	19.1742
2224.8	17.2616
2227.66	16.3798
2230.52	15.0015
2233.39	12.3947
2236.25	10.9842
2239.1	10.3099
2241.96	10.0206
2244.82	9.70657
2247.68	8.40933
2250.53	8.20556
2253.38	8.68417
2256.24	8.5193
2259.09	7.47617
2261.94	7.73103
2264.79	7.45435
2267.64	7.16207
2270.49	7.96126
2273.33	9.48571
2276.18	9.79645
2279.02	10.5961
2281.87	10.9923
2284.71	11.6513
2287.55	12.5029
2290.39	13.511
2293.23	12.5125
2296.07	12.6023
2298.91	12.6645
2301.74	12.6629
2304.58	13.0458
2307.41	12.8585
2310.25	12.2642
2313.08	12.1519
2315.91	11.2084
2318.74	10.5381
2321.57	9.97147
2324.4	9.74881
2327.23	8.80134
2330.05	7.71645
2332.88	7.37448
2335.7	6.94538
2338.52	7.42382
2341.35	7.46374
2344.17	7.64859
2346.99	6.9479
2349.81	6.49889
2352.62	6.65947
2355.44	6.31054
2358.26	5.91766
2361.07	4.61709
2363.89	3.86521
2366.7	3.76981
2369.51	2.1902
2372.32	1.21387
2375.13	0.371036
2377.94	-0.637384
2380.75	-0.744036
2383.56	-0.528074
2386.36	-0.667126
2389.17	-0.588179
2391.97	0.879293
2394.77	1.53931
2397.58	2.77993
2400.38	2.96035
2403.18	3.17671
2405.97	3.99025
2408.77	5.21777
2411.57	5.64456
2414.37	5.92865
2417.16	7.04659
2419.95	6.49583
2422.75	6.91322
2425.54	7.04476
2428.33	7.13733
2431.12	6.78446
2433.91	5.68443
2436.7	5.72778
2439.48	5.38705
2442.27	5.69286
2445.05	6.0141
2447.84	6.72306
2450.62	7.22561
2453.4	7.57661
2456.18	8.87603
2458.96	8.53046
2461.74	9.39458
2464.52	9.17137
2467.29	9.00535
2470.07	9.05251
2472.85	8.37506
2475.62	7.88471
2478.39	7.25676
2481.16	5.70637
2483.93	5.58703
2486.7	5.37954
2489.47	4.0028
2492.24	4.62423
2495.01	4.02182
2497.77	2.83944
2500.54	1.83934
2503.3	1.86694
2506.06	1.33357
2508.83	0.981238
2511.59	0.96623
2514.35	1.80119
2517.11	1.39218
2519.86	1.81372
2522.62	1.14225
2525.38	1.23213
2528.13	1.19456
2530.89	1.52645
2533.64	2.35411
2536.39	1.8817
2539.14	2.67688
2541.89	2.38339
2544.64	2.58095
2547.39	2.48838
2550.14	2.76357
2552.88	3.67919
2555.63	4.17566
2558.37	4.42883
2561.11	4.11599
2563.86	4.67605
2566.6	4.42302
2569.34	4.6649
2572.08	4.20814
2574.82	4.16355
2577.55	4.08256
2580.29	5.44769
2583.02	5.13279
2585.76	3.93459
2588.49	3.92842
2591.22	2.91788
2593.96	3.33208
2596.69	3.22637
2599.42	3.48913
2602.14	3.65338
2604.87	4.41607
2607.6	4.10205
2610.32	2.74711
2613.05	2.90286
2615.77	1.92684
2618.49	2.88933
2621.22	2.86227
2623.94	3.40348
2626.66	3.4988
2629.37	4.93026
2632.09	5.67582
2634.81	5.49839
2637.53	5.83014
2640.24	5.66102
2642.96	5.57997
2645.67	5.11756
2648.38	4.75078
2651.09	4.9045
2653.8	4.93239
2656.51	5.22643
2659.22	5.94089
2661.93	6.09544
2664.63	5.63058
2667.34	5.41909
2670.04	6.06659
2672.75	5.33969
2675.45	4.98752
2678.15	5.98873
2680.85	6.70733
2683.55	7.87445
2686.25	8.27103
2688.94	8.54564
2691.64	9.47541
2694.34	10.1326
2697.03	10.7602
2699.73	10.6198
2702.42	10.4781
2705.11	10.4145
2707.8	10.577
2710.49	11.3026
2713.18	11.3413
2715.87	11.9567
2718.55	11.6975
2721.24	12.5825
2723.93	12.3355
2726.61	12.4545
2729.29	12.1945
2731.98	11.6363
2734.66	11.2847
2737.34	10.8021
2740.02	10.3503
2742.7	10.1059
2745.37	9.6124
2748.05	8.48206
2750.72	7.99064
2753.4	6.93536
2756.07	6.27005
2758.75	5.50788
2761.42	5.83338
2764.09	5.59527
2766.76	4.80136
2769.43	4.87949
2772.1	3.95615
2774.76	3.19182
2777.43	2.74012
2780.1	1.6708
2782.76	2.33074
2785.42	3.00743
2788.09	3.21709
2790.75	1.92619
2793.41	2.13818
2796.07	1.33776
2798.73	0.900948
2801.39	0.589766
2804.04	0.564398
2806.7	0.433577
2809.35	-0.357461
2812.01	-0.0284904
2814.66	0.755361
2817.31	1.69877
2819.96	2.6969
2822.61	3.17738
2825.26	4.9948
2827.91	6.60445
2830.56	8.49948
2833.21	11.1035
2835.85	12.6307
2838.5	14.7482
2841.14	17.9867
2843.78	21.5719
2846.42	25.7323
2849.06	29.7501
2851.71	34.4613
2854.34	38.8103
2856.98	43.243
2859.62	48.0992
2862.26	53.9271
2864.89	58.8057
2867.53	62.7939
2870.16	66.2469
2872.79	69.5232
2875.42	72.1118
2878.05	75.1298
2880.68	78.3656
2883.31	80.7308
2885.94	82.9917
2888.57	86.4412
2891.19	89.7142
2893.82	93.1671
2896.44	97.1856
2899.07	101.545
2901.69	104.914
2904.31	110.555
2906.93	115.644
2909.55	121.992
2912.17	128.604
2914.79	135.873
2917.41	142.299
2920.02	148.273
2922.64	152.676
2925.25	156.008
2927.86	158.829
2930.48	159.043
2933.09	158.487
2935.7	156.587
2938.31	153.481
2940.92	150.415
2943.53	147.001
2946.13	142.311
2948.74	136.72
2951.34	131.963
2953.95	126.816
2956.55	121.66
2959.15	116.405
2961.75	111.987
2964.35	107.05
2966.95	100.996
2969.55	97.1561
2972.15	92.9139
2974.75	88.3188
2977.34	84.5141
2979.94	79.968
2982.53	74.1405
2985.13	68.4613
2987.72	61.8759
2990.31	55.764
2992.9	49.8847
2995.49	44.1369
2998.08	38.4355
3000.67	33.0628
3003.25	27.6131
3005.84	23.3249
3008.42	19.1938
3011.01	15.7904
3013.59	12.8805
3016.17	10.4463
3018.76	8.12992
3021.34	7.28819
3023.92	5.07607
3026.49	4.58629
3029.07	4.00645
3031.65	3.291
3034.23	4.12608
3036.8	4.34835
3039.38	5.23663
3041.95	6.3315
3044.52	7.16281
3047.09	7.8885
3049.66	9.57391
3052.23	11.1382
3054.8	12.3349
3057.37	13.2146
3059.94	13.7963
3062.5	13.859
3065.07	13.2011
3067.63	13.2831
3070.2	12.5127
3072.76	11.0585
3075.32	9.90618
3077.88	8.62237
3080.44	7.47442
3083	6.4253
3085.56	4.92474
3088.12	3.89439
3090.67	3.14212
3093.23	2.16182
3095.78	0.781336
3098.34	1.05951
3100.89	0.993646
3103.44	1.87568
3105.99	2.05465
3108.54	2.3853
3111.09	3.71238
3113.64	4.60274
3116.19	6.54355
3118.74	7.38421
3121.28	9.13564
3123.83	10.0576
3126.37	10.5844
3128.91	12.0585
3131.46	13.2844
3134	14.6155
3136.54	16.3263
3139.08	18.4217
3141.62	20.5867
3144.16	22.2836
3146.69	23.3715
3149.23	24.1646