File: data/Raman/poly_smoothed/Thy_40_11_42_1x_45s_532 nm_x100_100%_600 gr_mm_01.txt
#Acq. time (s)=	45
#Accumulations=	2
#Range (cm-¹)=	200...3150
#Windows=	2
#Auto scanning=	Off
#Autofocus=	Off
#Macrospot=	Off
#AutoExposure=	Off
#Spike filter=	Multiple accum.
#Delay time (s)=	0
#Binning=	1
#Readout mode=	Signal
#DeNoise=	Off
#ICS correction=	On
#Dark correction=	Off
#Inst. Process=	Off
#Detector Gain=	Best Dynamic Range
#Detector ADC=	20 kHz
#Detector temperature (°C)=	-69.85
#Instrument=	LabRAM HR Evol
#Detector=	Synapse
#Objective=	x100
#Grating=	600 gr/mm
#ND Filter=	100%
#Laser (nm)=	532
#Hole=	100.021
#Range=	Auto
#Laser Pol.=	No
#Raman. Pol.=	No
#Laser Pol. (°)=	-0.0007625
#Raman Pol. (°)=	89.9995
#Collection=	Microscope
#StageXY=	Marzhauser
#StageZ=	Marzhauser
#X (µm)=	252.4
#Y (µm)=	1686.6
#Z (µm)=	427.5
#Full time(mm:ss)=	3:18
#Project=
#Sample=
#Site=
#Title=	Thy_40_11_42_2x_45s_532 nm_x100_100%_600 gr_mm
#Remark=
#Date=	05.07.2022 12:59
#Acquired=	05.07.2022 12:59:14
#Base:Fit=	10.08.2022 10:01:35
#Base:Sub=	10.08.2022 10:01:52
#Filter:Polynom=	16.08.2022 10:21:53
#AxisType[0]=Intens
#AxisUnit[0]=Cnt
#AxisType[1]=Spectr
#AxisUnit[1]=1/cm
200.43	11.0626
204.059	15.5182
207.688	18.2314
211.314	17.8279
214.941	16.6212
218.564	14.9032
222.186	14.9317
225.809	14.2584
229.428	13.5293
233.045	12.5449
236.663	12.5827
240.278	13.1201
243.891	13.773
247.503	13.2307
251.116	13.1772
254.725	13.1591
258.333	13.3337
261.939	12.3002
265.544	13.3275
269.148	13.9648
272.75	15.3229
276.351	15.9146
279.95	16.5727
283.548	17.1899
287.144	16.9225
290.739	16.7986
294.333	15.0603
297.925	13.9146
301.514	13.5285
305.104	14.8388
308.692	15.0518
312.279	14.2156
315.862	13.4582
319.446	13.7889
323.029	15.1744
326.608	16.0729
330.188	15.4898
333.766	15.5679
337.341	16.4328
340.917	15.9561
344.489	16.1426
348.062	17.727
351.631	16.9334
355.201	18.5523
358.768	17.4621
362.333	17.1116
365.899	15.3022
369.462	14.8924
373.023	13.8152
376.585	12.6843
380.143	11.7241
383.7	10.4002
387.256	9.8415
390.812	10.056
394.365	8.2696
397.916	7.59007
401.467	7.11788
405.015	7.40628
408.563	7.33193
412.109	6.44164
415.654	5.14492
419.197	5.10086
422.739	4.53351
426.279	5.07781
429.819	4.50984
433.356	5.21854
436.891	4.63311
440.426	3.55381
443.96	3.01202
447.492	2.89924
451.021	3.8164
454.551	3.89395
458.079	4.88319
461.604	5.28302
465.13	6.63094
468.654	8.10089
472.175	10.0335
475.696	11.7113
479.215	12.2335
482.733	13.6389
486.249	14.7347
489.765	14.8408
493.278	14.8523
496.789	15.541
500.301	15.8387
503.81	15.7557
507.317	15.0994
510.825	15.0563
514.33	14.2725
517.833	12.9594
521.335	12.1436
524.836	11.8956
528.335	11.4903
531.835	11.2477
535.332	10.9136
538.827	9.54444
542.321	8.84821
545.814	8.242
549.305	7.5851
552.795	6.24005
556.282	5.60071
559.769	5.42921
563.255	4.67754
566.739	2.73173
570.223	2.66055
573.705	2.55236
577.183	2.88528
580.663	3.51203
584.141	3.53703
587.615	2.23259
591.09	1.7074
594.564	1.28431
598.035	1.73228
601.506	2.1252
604.974	2.79838
608.443	4.79073
611.908	5.89107
615.374	5.97261
618.837	7.07832
622.3	8.29142
625.761	9.00924
629.219	9.88171
632.677	9.84358
636.135	10.032
639.59	10.8233
643.043	12.1927
646.495	13.1413
649.948	12.7804
653.398	14.3956
656.846	16.6258
660.293	17.1648
663.738	19.1118
667.183	18.9182
670.626	20.3448
674.067	21.254
677.508	23.5467
680.947	26.2469
684.385	28.0773
687.821	30.6218
691.254	32.762
694.688	35.0687
698.121	36.7175
701.552	37.6669
704.98	38.5973
708.409	39.9359
711.836	41.4402
715.26	41.8685
718.685	40.7863
722.108	41.7463
725.528	41.8901
728.949	41.7663
732.367	42.2777
735.785	42.4688
739.2	42.2795
742.614	43.3327
746.028	43.3863
749.439	45.0242
752.849	48.0848
756.26	50.1555
759.667	52.6484
763.073	55.462
766.477	58.4213
769.883	59.875
773.285	62.7797
776.686	65.6086
780.085	67.1473
783.484	69.4212
786.881	71.1368
790.276	74.6455
793.671	76.6618
797.064	77.7165
800.456	78.3431
803.846	78.4872
807.234	78.8688
810.622	79.0892
814.008	78.5934
817.394	77.5954
820.778	77.393
824.159	77.6001
827.541	77.0767
830.921	77.492
834.298	76.6526
837.676	75.3407
841.051	74.6434
844.426	72.9373
847.798	71.33
851.171	69.659
854.54	67.049
857.911	65.1788
861.278	64.0205
864.645	61.3206
868.01	58.9883
871.373	57.3255
874.735	54.55
878.097	53.1979
881.457	52.543
884.815	50.5139
888.172	49.097
891.528	47.9154
894.882	47.752
898.237	46.7034
901.589	47.1229
904.94	47.1297
908.289	46.6875
911.635	47.3828
914.982	47.124
918.328	46.0788
921.672	44.4148
925.015	44.3929
928.357	44.0888
931.698	43.2578
935.035	42.2482
938.373	40.6171
941.71	39.5545
945.044	38.0576
948.378	35.6098
951.709	35.8325
955.041	35.2401
958.372	33.9978
961.699	33.1911
965.027	33.7716
968.352	34.1906
971.676	32.9123
975	32.6461
978.322	31.8662
981.642	31.2695
984.962	30.6878
988.28	30.1206
991.596	28.9044
994.911	27.4479
998.227	25.9294
1001.54	24.1334
1004.85	23.3355
1008.16	23.6759
1011.47	23.856
1014.78	23.5489
1018.08	23.975
1021.39	24.3624
1024.69	24.9267
1028	25.1633
1031.3	26.6219
1034.6	27.766
1037.9	27.4655
1041.19	27.8406
1044.49	28.8075
1047.78	29.9085
1051.08	28.2711
1054.37	26.6243
1057.66	25.6311
1060.95	25.7517
1064.24	24.6793
1067.53	22.8282
1070.81	20.935
1074.1	19.3159
1077.38	17.6888
1080.66	15.7873
1083.94	15.0181
1087.22	14.3914
1090.5	14.0722
1093.78	12.8615
1097.05	12.4965
1100.33	11.9666
1103.6	11.9526
1106.87	11.7101
1110.14	12.7493
1113.41	12.0988
1116.68	11.6657
1119.95	11.6756
1123.21	11.6923
1126.48	11.6811
1129.74	10.4886
1133	10.8784
1136.26	10.6168
1139.52	12.4909
1142.78	12.5914
1146.04	11.1024
1149.29	10.6964
1152.55	10.7661
1155.8	10.3688
1159.05	9.62628
1162.3	9.30781
1165.55	8.51838
1168.8	6.16502
1172.05	4.38644
1175.29	4.09859
1178.54	4.13706
1181.78	4.33802
1185.02	4.56009
1188.26	5.012
1191.5	5.09385
1194.74	5.07398
1197.97	6.51175
1201.21	6.34681
1204.44	8.76599
1207.68	10.8817
1210.91	13.2776
1214.14	16.3277
1217.37	18.8807
1220.59	22.5957
1223.82	23.84
1227.05	27.5506
1230.27	29.8732
1233.49	32.1916
1236.72	34.6988
1239.94	35.6363
1243.16	35.6762
1246.37	35.6158
1249.59	37.0626
1252.8	38.3794
1256.02	39.238
1259.23	40.543
1262.44	40.48
1265.66	40.4557
1268.86	40.6922
1272.07	40.1854
1275.28	40.7953
1278.48	40.423
1281.69	39.278
1284.89	40.2333
1288.09	40.8878
1291.29	41.2848
1294.49	42.1866
1297.69	42.461
1300.89	43.3492
1304.08	43.8206
1307.28	44.3976
1310.47	45.0628
1313.66	45.8826
1316.85	46.2591
1320.04	46.6302
1323.23	45.8461
1326.42	47.5712
1329.61	47.8104
1332.79	47.9737
1335.97	48.6246
1339.16	48.4836
1342.34	46.8352
1345.52	47.7296
1348.7	45.8773
1351.87	44.4303
1355.05	41.8671
1358.22	38.7128
1361.4	36.5782
1364.57	35.3001
1367.74	32.5278
1370.91	30.9648
1374.08	29.1762
1377.25	27.8823
1380.41	26.5069
1383.58	25.714
1386.74	25.6019
1389.91	24.8187
1393.07	23.8294
1396.23	24.1697
1399.39	23.3026
1402.55	22.844
1405.7	23.3425
1408.86	23.4936
1412.01	25.4746
1415.17	27.4037
1418.32	27.9821
1421.47	31.1222
1424.62	33.907
1427.77	36.7188
1430.91	38.4865
1434.06	41.6368
1437.2	43.7758
1440.35	46.4817
1443.49	47.3006
1446.63	48.9813
1449.77	49.6119
1452.91	48.7515
1456.05	48.7354
1459.18	47.5117
1462.32	46.3789
1465.45	44.1146
1468.59	42.3867
1471.72	38.8726
1474.85	36.1284
1477.98	32.3011
1481.1	29.4825
1484.23	26.4677
1487.36	23.4968
1490.48	22.1161
1493.61	20.535
1496.73	19.1124
1499.85	19.1403
1502.97	18.9361
1506.09	18.7615
1509.2	17.994
1512.32	17.1312
1515.43	17.3487
1518.55	17.8937
1521.66	19.6225
1524.77	20.1543
1527.88	20.5637
1530.99	22.2571
1534.1	23.466
1537.21	24.3446
1540.31	25.2844
1543.42	27.7045
1546.52	29.1737
1549.62	29.5508
1552.72	31.1603
1555.82	31.5083
1558.92	33.91
1562.02	33.7763
1565.11	35.791
1568.21	36.4708
1571.3	36.8804
1574.39	37.8817
1577.49	39.8425
1580.57	41.5356
1583.66	43.1067
1586.75	44.7269
1589.84	46.0719
1592.92	47.7131
1596.01	50.2104
1599.09	50.6444
1602.17	50.3267
1605.25	49.7896
1608.33	50.3508
1611.41	49.1275
1614.49	48.1153
1617.57	48.065
1620.64	48.4622
1623.72	48.5578
1626.79	47.622
1629.86	46.4675
1632.93	46.7618
1636	46.8031
1639.07	47.8733
1642.13	48.0247
1645.2	47.9843
1648.26	50.1937
1651.33	51.0383
1654.39	52.4109
1657.45	53.8124
1660.51	52.5571
1663.57	51.2612
1666.63	49.9481
1669.68	48.2643
1672.74	46.8565
1675.79	43.674
1678.85	39.983
1681.9	37.2528
1684.95	34.789
1688	31.0069
1691.05	27.357
1694.09	24.9727
1697.14	22.0925
1700.18	18.7262
1703.23	16.8878
1706.27	16.0597
1709.31	15.2512
1712.35	14.2412
1715.39	12.9175
1718.43	11.9641
1721.47	12.074
1724.5	11.4589
1727.54	11.3646
1730.57	11.3388
1733.61	10.2645
1736.64	9.19944
1739.67	9.40686
1742.7	9.87662
1745.72	9.5617
1748.75	8.70671
1751.77	7.31193
1754.8	6.31372
1757.82	5.60499
1760.84	5.218
1763.87	3.78526
1766.89	3.35655
1769.91	2.55651
1772.92	2.84137
1775.94	3.17171
1778.95	3.14106
1781.97	3.05806
1784.98	3.18433
1787.99	3.73074
1791.01	3.51444
1794.01	2.87079
1797.02	2.43499
1800.03	2.99195
1803.04	2.97481
1806.04	3.28755
1809.05	3.8575
1812.05	4.7179
1815.05	4.71181
1818.05	4.75045
1821.05	4.53714
1824.05	4.18013
1827.05	3.34127
1830.04	3.42454
1833.04	3.6377
1836.03	4.33357
1839.03	4.67714
1842.02	4.52843
1845.01	4.84342
1848	4.72851
1850.99	4.48213
1853.97	4.40693
1856.96	3.9776
1859.94	4.15212
1862.93	3.71407
1865.91	3.38014
1868.89	2.96236
1871.87	3.4998
1874.85	3.67221
1877.83	3.73044
1880.81	4.35781
1882.57	3.82008
1885.56	3.17218
1888.55	2.62756
1891.54	2.12063
1894.52	0.986482
1897.51	-0.161842
1900.49	-0.285125
1903.47	0.239873
1906.45	0.54418
1909.43	0.738657
1912.41	1.2378
1915.39	1.11116
1918.37	1.3556
1921.34	1.62942
1924.32	1.12114
1927.29	1.9604
1930.26	1.70618
1933.23	2.58874
1936.2	2.98556
1939.17	4.02373
1942.14	4.54596
1945.11	5.36098
1948.07	4.97304
1951.04	5.63507
1954	5.47841
1956.96	4.43767
1959.93	5.36476
1962.89	4.34616
1965.85	3.73839
1968.8	3.28756
1971.76	3.12551
1974.72	3.74806
1977.67	4.08774
1980.63	3.72911
1983.58	4.04416
1986.53	3.36649
1989.48	2.72122
1992.43	2.67183
1995.38	2.49089
1998.32	2.86747
2001.27	2.71803
2004.22	2.38619
2007.16	3.15554
2010.1	3.21514
2013.04	3.22661
2015.98	2.90728
2018.92	3.6848
2021.86	3.67819
2024.8	3.60924
2027.74	3.572
2030.67	4.57951
2033.61	4.82759
2036.54	5.04745
2039.47	5.51648
2042.4	5.82169
2045.33	6.4715
2048.26	6.95016
2051.19	7.39684
2054.12	8.71123
2057.04	9.30458
2059.97	9.61069
2062.89	11.0399
2065.81	11.0736
2068.73	11.1177
2071.65	11.0736
2074.57	11.4631
2077.49	12.3186
2080.41	12.4704
2083.32	12.1018
2086.24	11.9662
2089.15	12.4347
2092.07	12.6088
2094.98	12.7188
2097.89	13.0534
2100.8	13.8482
2103.71	15.3037
2106.61	15.8745
2109.52	16.9709
2112.43	17.0898
2115.33	18.2467
2118.23	18.3797
2121.13	19.9488
2124.04	21.6129
2126.94	23.8345
2129.83	25.0303
2132.73	26.1929
2135.63	27.7095
2138.53	28.945
2141.42	30.5321
2144.31	32.5285
2147.21	34.0851
2150.1	35.4506
2152.99	36.3888
2155.88	38.2327
2158.77	39.4964
2161.65	41.2836
2164.54	42.0917
2167.43	42.6684
2170.31	43.9863
2173.19	45.2403
2176.07	45.1781
2178.96	45.4658
2181.84	45.0566
2184.72	43.5443
2187.59	42.0399
2190.47	41.9172
2193.35	41.8788
2196.22	41.5905
2199.09	39.6654
2201.97	38.0086
2204.84	35.9462
2207.71	34.3083
2210.58	31.955
2213.45	29.8904
2216.31	28.246
2219.18	26.4856
2222.05	25.3074
2224.91	23.0694
2227.78	21.4182
2230.64	20.1331
2233.5	18.885
2236.36	16.9131
2239.22	15.9032
2242.08	15.2782
2244.93	14.3738
2247.79	13.0236
2250.64	12.9682
2253.5	11.6914
2256.35	10.7927
2259.2	10.8816
2262.05	11.1815
2264.9	11.5346
2267.75	10.9085
2270.6	9.8444
2273.45	9.39639
2276.29	8.80991
2279.14	8.54924
2281.98	7.35592
2284.82	6.07259
2287.66	6.91098
2290.5	6.16247
2293.34	4.91206
2296.18	4.58329
2299.02	5.12578
2301.86	5.29553
2304.69	5.21699
2307.53	5.58876
2310.36	6.98923
2313.19	7.23132
2316.02	7.69237
2318.85	8.08224
2321.68	7.78875
2324.51	7.56981
2327.34	7.14706
2330.16	7.59657
2332.99	8.51531
2335.81	8.06792
2338.64	7.39395
2341.46	7.02711
2344.28	5.53289
2347.1	4.2737
2349.92	3.26332
2352.74	2.02269
2355.55	1.44443
2358.37	0.843244
2361.19	0.00725458
2364	-0.294937
2366.81	-0.108716
2369.62	0.114078
2372.44	0.15009
2375.24	0.764972
2378.05	0.985012
2380.86	0.888617
2383.67	0.466875
2386.47	-0.274727
2389.28	-0.699546
2392.08	-0.576896
2394.89	-0.709725
2397.69	0.195483
2400.49	0.530971
2403.29	0.10124
2406.09	0.260098
2408.88	0.453109
2411.68	1.21492
2414.48	1.67029
2417.27	3.5779
2420.06	4.56761
2422.86	5.4976
2425.65	6.20603
2428.44	6.60737
2431.23	6.54852
2434.02	6.62197
2436.81	7.65647
2439.59	8.41462
2442.38	8.26935
2445.16	8.8721
2447.95	8.43698
2450.73	7.86456
2453.51	7.38812
2456.29	7.11438
2459.07	6.65247
2461.85	5.99497
2464.63	5.1203
2467.4	4.85153
2470.18	3.57434
2472.95	3.14346
2475.73	3.50073
2478.5	3.92894
2481.27	3.83189
2484.04	3.90519
2486.81	3.53742
2489.58	2.86736
2492.35	2.56692
2495.12	2.14623
2497.88	1.58753
2500.65	1.58247
2503.41	1.82892
2506.17	1.66109
2508.94	1.91202
2511.7	1.25125
2514.46	1.40083
2517.22	0.789006
2519.97	1.32431
2522.73	0.934834
2525.49	1.17279
2528.24	1.03655
2530.99	2.19283
2533.75	2.98192
2536.5	3.48011
2539.25	4.20065
2542	4.66744
2544.75	5.20467
2547.5	6.20264
2550.24	6.78611
2552.99	6.92779
2555.74	7.00375
2558.48	6.92145
2561.22	7.39462
2563.96	6.82585
2566.71	6.35037
2569.45	6.36307
2572.18	5.31348
2574.92	5.16164
2577.66	4.56937
2580.4	4.02555
2583.13	3.10876
2585.87	2.86366
2588.6	2.83738
2591.33	2.22205
2594.06	1.84479
2596.79	1.79758
2599.52	1.8712
2602.25	0.532102
2604.98	-0.0613549
2607.71	0.464666
2610.43	1.31113
2613.16	1.82859
2615.88	1.95769
2618.6	1.6738
2621.32	2.28719
2624.04	2.37609
2626.76	2.11534
2629.48	2.76525
2632.2	3.06304
2634.92	3.81614
2637.63	4.75934
2640.35	6.02736
2643.06	5.49894
2645.77	4.66138
2648.49	4.88258
2651.2	4.57589
2653.91	4.49454
2656.62	4.04369
2659.33	4.12988
2662.03	3.9788
2664.74	3.78222
2667.44	3.58541
2670.15	3.4339
2672.85	3.00043
2675.55	3.45818
2678.26	3.23114
2680.96	3.00289
2683.66	3.09606
2686.35	3.30443
2689.05	2.94429
2691.75	3.13606
2694.44	4.25046
2697.14	4.89721
2699.83	6.01448
2702.52	6.34677
2705.22	6.60541
2707.91	5.86446
2710.6	5.31622
2713.29	4.45638
2715.97	5.07003
2718.66	5.06056
2721.35	5.17291
2724.03	5.61828
2726.72	5.65239
2729.4	5.77464
2732.08	5.85415
2734.76	5.24331
2737.44	4.92792
2740.12	4.26611
2742.8	4.45073
2745.48	5.02589
2748.16	4.2455
2750.83	4.27388
2753.51	4.99262
2756.18	4.71339
2758.85	5.97756
2761.53	6.03467
2764.2	6.34889
2766.87	6.16105
2769.54	6.1769
2772.2	6.18024
2774.87	5.95894
2777.54	6.06035
2780.2	5.6658
2782.87	5.37663
2785.53	4.48041
2788.19	3.63404
2790.85	3.72073
2793.51	3.47581
2796.17	3.22453
2798.83	2.38306
2801.49	2.24198
2804.15	1.59856
2806.8	1.71239
2809.46	1.71576
2812.11	2.03973
2814.76	2.21534
2817.42	2.20987
2820.07	3.5063
2822.72	4.28603
2825.37	5.36213
2828.02	6.22647
2830.66	8.09285
2833.31	10.1874
2835.96	12.4312
2838.6	14.3904
2841.24	16.9711
2843.89	19.1112
2846.53	21.0072
2849.17	23.2458
2851.81	26.6474
2854.45	29.6123
2857.09	32.5176
2859.72	34.6509
2862.36	37.7248
2865	40.4565
2867.63	42.6437
2870.26	44.7351
2872.9	46.6509
2875.53	48.1395
2878.16	49.7308
2880.79	51.119
2883.42	52.7476
2886.05	53.9682
2888.67	56.1643
2891.3	58.1734
2893.92	60.1094
2896.55	62.6256
2899.17	65.586
2901.79	68.9953
2904.42	72.2257
2907.04	76.9637
2909.66	82.2657
2912.27	87.5821
2914.89	93.4474
2917.51	98.6016
2920.13	102.567
2922.74	106.489
2925.35	109.815
2927.97	112.244
2930.58	114.011
2933.19	115.082
2935.8	115.238
2938.41	114.645
2941.02	113.775
2943.63	110.762
2946.24	108.634
2948.84	105.174
2951.45	101.634
2954.05	97.0765
2956.65	92.7452
2959.26	88.571
2961.86	82.5295
2964.46	78.0233
2967.06	73.7462
2969.66	69.7139
2972.25	66.4282
2974.85	61.8919
2977.45	56.9884
2980.04	52.8741
2982.64	47.9317
2985.23	43.1907
2987.82	38.6268
2990.41	34.0607
2993	29.9602
2995.59	27.0824
2998.18	23.8684
3000.77	20.3441
3003.36	17.8155
3005.94	15.14
3008.53	13.3544
3011.11	11.6078
3013.69	10.305
3016.28	8.94713
3018.86	8.23431
3021.44	6.82905
3024.02	5.69184
3026.6	4.48781
3029.18	4.788
3031.75	4.71701
3034.33	4.83026
3036.9	4.03271
3039.48	4.48309
3042.05	4.79979
3044.62	5.09282
3047.19	5.82483
3049.77	6.56758
3052.34	6.92883
3054.9	6.62714
3057.47	6.72333
3060.04	6.97162
3062.61	7.58708
3065.17	7.80501
3067.74	7.0358
3070.3	6.87549
3072.86	6.50324
3075.42	5.80832
3077.99	5.45573
3080.54	4.29089
3083.1	3.10808
3085.66	2.4913
3088.22	1.4235
3090.78	1.16411
3093.33	0.497675
3095.89	0.959294
3098.44	0.317872
3100.99	0.460733
3103.54	1.29679
3106.1	1.60824
3108.65	2.87206
3111.2	3.23801
3113.74	3.58355
3116.29	3.51532
3118.84	4.4694
3121.38	5.71568
3123.93	6.88097
3126.47	7.59441
3129.01	7.68598
3131.56	8.0038
3134.1	9.5069
3136.64	10.0522
3139.18	10.1559
3141.72	10.854
3144.26	11.3452
3146.79	12.2014
3149.33	12.6187