File: data/Raman/poly_smoothed/Thy_40_11_05_1x_45s_532 nm_x100_100%_600 gr_mm_01.txt
#Acq. time (s)=	45
#Accumulations=	2
#Range (cm-¹)=	200...3150
#Windows=	2
#Auto scanning=	Off
#Autofocus=	Off
#Macrospot=	Off
#AutoExposure=	Off
#Spike filter=	Multiple accum.
#Delay time (s)=	0
#Binning=	1
#Readout mode=	Signal
#DeNoise=	Off
#ICS correction=	On
#Dark correction=	Off
#Inst. Process=	Off
#Detector Gain=	Best Dynamic Range
#Detector ADC=	20 kHz
#Detector temperature (°C)=	-69.85
#Instrument=	LabRAM HR Evol
#Detector=	Synapse
#Objective=	x100
#Grating=	600 gr/mm
#ND Filter=	100%
#Laser (nm)=	532
#Hole=	100.021
#Range=	Auto
#Laser Pol.=	No
#Raman. Pol.=	No
#Laser Pol. (°)=	-0.0007625
#Raman Pol. (°)=	89.9995
#Collection=	Microscope
#StageXY=	Marzhauser
#StageZ=	Marzhauser
#X (µm)=	1977.6
#Y (µm)=	-87.2
#Z (µm)=	425.85
#Full time(mm:ss)=	3:18
#Project=
#Sample=
#Site=
#Title=	Thy_40_11_05_2x_45s_532 nm_x100_100%_600 gr_mm
#Remark=
#Date=	05.07.2022 10:13
#Acquired=	05.07.2022 10:13:13
#Base:Fit=	10.08.2022 10:00:48
#Base:Fit=	10.08.2022 10:01:07
#Base:Fit=	10.08.2022 10:01:15
#Base:Fit=	10.08.2022 10:01:35
#Base:Sub=	10.08.2022 10:01:52
#Filter:Polynom=	16.08.2022 10:21:53
#AxisType[0]=Intens
#AxisUnit[0]=Cnt
#AxisType[1]=Spectr
#AxisUnit[1]=1/cm
200.43	-1.38941
204.059	5.29025
207.688	9.37953
211.314	11.0478
214.941	12.2248
218.564	11.1195
222.186	12.5407
225.809	12.949
229.428	12.5014
233.045	12.7411
236.663	12.4458
240.278	11.7614
243.891	11.6705
247.503	11.3782
251.116	9.92932
254.725	7.62323
258.333	6.28854
261.939	5.26513
265.544	6.32599
269.148	4.65744
272.75	2.68183
276.351	1.77768
279.95	3.69596
283.548	4.58464
287.144	4.69394
290.739	3.7806
294.333	3.71747
297.925	3.82913
301.514	6.78477
305.104	9.36619
308.692	11.2925
312.279	14.0998
315.862	13.8508
319.446	14.6978
323.029	15.752
326.608	14.9472
330.188	15.9184
333.766	15.721
337.341	14.5619
340.917	13.717
344.489	12.3662
348.062	12.8167
351.631	10.3528
355.201	8.69725
358.768	6.30363
362.333	5.0787
365.899	4.75643
369.462	5.16885
373.023	3.223
376.585	3.02596
380.143	3.75829
383.7	5.20715
387.256	6.3297
390.812	7.47991
394.365	7.05163
397.916	6.89037
401.467	5.45534
405.015	6.52378
408.563	6.0121
412.109	6.01754
415.654	5.14605
419.197	6.26358
422.739	4.84813
426.279	6.20156
429.819	5.79888
433.356	4.28947
436.891	2.95942
440.426	2.87421
443.96	3.51802
447.492	5.09348
451.021	7.17954
454.551	8.46041
458.079	8.96932
461.604	10.1435
465.13	11.9786
468.654	14.1842
472.175	16.6972
475.696	17.7982
479.215	20.2127
482.733	22.2721
486.249	23.8436
489.765	26.3435
493.278	26.4233
496.789	27.707
500.301	26.761
503.81	27.8537
507.317	28.9758
510.825	27.5406
514.33	27.9
517.833	27.0207
521.335	27.0682
524.836	26.3306
528.335	26.6456
531.835	25.4405
535.332	24.1643
538.827	22.2251
542.321	20.0369
545.814	19.3196
549.305	19.2314
552.795	18.2828
556.282	17.2523
559.769	16.7601
563.255	17.661
566.739	17.4519
570.223	16.3937
573.705	14.4907
577.183	14.0315
580.663	13.8779
584.141	13.7867
587.615	14.6291
591.09	12.6105
594.564	10.2583
598.035	9.23423
601.506	10.1203
604.974	9.43747
608.443	8.91099
611.908	9.39895
615.374	9.29078
618.837	9.03388
622.3	9.59967
625.761	9.85407
629.219	10.613
632.677	12.6939
636.135	12.9632
639.59	13.7616
643.043	15.6588
646.495	19.5098
649.948	22.2825
653.398	24.3994
656.846	26.6593
660.293	29.573
663.738	33.5276
667.183	34.9634
670.626	36.9839
674.067	37.213
677.508	37.8148
680.947	39.4967
684.385	42.1902
687.821	45.8132
691.254	46.76
694.688	48.5223
698.121	49.9875
701.552	51.7932
704.98	52.7002
708.409	52.9559
711.836	54.6402
715.26	56.6848
718.685	56.5061
722.108	58.5584
725.528	60.0997
728.949	61.724
732.367	60.9694
735.785	61.9717
739.2	62.8746
742.614	63.7015
746.028	66.3195
749.439	66.6317
752.849	68.8262
756.26	71.0556
759.667	71.9376
763.073	74.6288
766.477	77.8553
769.883	79.8175
773.285	80.8611
776.686	82.4266
780.085	84.7204
783.484	86.18
786.881	87.3434
790.276	88.2704
793.671	89.4132
797.064	91.2312
800.456	91.0581
803.846	90.269
807.234	88.8711
810.622	88.5015
814.008	87.757
817.394	88.553
820.778	88.393
824.159	89.5696
827.541	91.572
830.921	90.8463
834.298	90.4543
837.676	89.4831
841.051	88.1212
844.426	86.0892
847.798	84.2803
851.171	82.6987
854.54	80.7644
857.911	77.0475
861.278	75.0806
864.645	70.6635
868.01	68.921
871.373	65.8886
874.735	63.4689
878.097	62.5404
881.457	60.5333
884.815	57.3945
888.172	55.8956
891.528	55.7718
894.882	56.0907
898.237	54.5788
901.589	52.685
904.94	51.3937
908.289	51.3174
911.635	49.6036
914.982	47.3091
918.328	45.9142
921.672	45.2862
925.015	44.5109
928.357	43.8379
931.698	43.0289
935.035	41.6483
938.373	38.6565
941.71	36.6812
945.044	35.3277
948.378	35.0918
951.709	36.9015
955.041	36.7261
958.372	36.0403
961.699	33.7603
965.027	32.8675
968.352	32.4951
971.676	33.1551
975	33.2994
978.322	31.9635
981.642	30.8613
984.962	31.4496
988.28	32.3786
991.596	32.98
994.911	31.679
998.227	30.9186
1001.54	31.828
1004.85	31.7043
1008.16	28.7949
1011.47	28.3268
1014.78	27.9272
1018.08	28.6007
1021.39	27.7474
1024.69	28.0223
1028	28.4195
1031.3	29.1665
1034.6	28.8979
1037.9	26.7632
1041.19	25.4567
1044.49	23.8998
1047.78	25.2166
1051.08	25.4584
1054.37	25.8051
1057.66	24.3233
1060.95	23.8571
1064.24	23.4838
1067.53	23.7828
1070.81	22.6525
1074.1	21.1047
1077.38	19.8647
1080.66	21.2404
1083.94	21.5243
1087.22	20.1358
1090.5	19.1682
1093.78	18.6603
1097.05	18.239
1100.33	19.3733
1103.6	20.5324
1106.87	20.4264
1110.14	19.2303
1113.41	18.5843
1116.68	18.4152
1119.95	18.0312
1123.21	16.3352
1126.48	14.2306
1129.74	14.2418
1133	11.5286
1136.26	11.1497
1139.52	11.0648
1142.78	9.65852
1146.04	9.59121
1149.29	8.91633
1152.55	7.9224
1155.8	6.34781
1159.05	6.63174
1162.3	6.8686
1165.55	3.81644
1168.8	2.293
1172.05	2.45292
1175.29	3.47633
1178.54	4.76739
1181.78	6.05643
1185.02	5.56822
1188.26	4.29871
1191.5	4.63626
1194.74	6.51625
1197.97	8.77222
1201.21	8.75834
1204.44	10.39
1207.68	12.4672
1210.91	16.5398
1214.14	20.1963
1217.37	23.8148
1220.59	27.8431
1223.82	33.1231
1227.05	37.4791
1230.27	41.8073
1233.49	46.4656
1236.72	49.547
1239.94	52.5375
1243.16	54.756
1246.37	57.1383
1249.59	59.9861
1252.8	62.027
1256.02	63.1045
1259.23	64.8997
1262.44	66.3982
1265.66	67.0196
1268.86	68.2089
1272.07	70.3909
1275.28	71.8635
1278.48	72.7054
1281.69	75.9922
1284.89	76.9654
1288.09	80.6982
1291.29	82.7164
1294.49	84.051
1297.69	84.2644
1300.89	86.3537
1304.08	87.7428
1307.28	87.843
1310.47	90.3153
1313.66	88.6115
1316.85	88.2453
1320.04	87.9377
1323.23	86.5551
1326.42	85.2
1329.61	83.0935
1332.79	83.052
1335.97	82.1036
1339.16	78.9252
1342.34	75.1947
1345.52	74.0269
1348.7	71.8458
1351.87	69.4972
1355.05	67.0487
1358.22	66.1525
1361.4	63.4393
1364.57	62.0654
1367.74	60.2908
1370.91	57.7989
1374.08	55.3937
1377.25	53.5794
1380.41	54.0504
1383.58	52.8345
1386.74	53.105
1389.91	49.8668
1393.07	49.3723
1396.23	49.4317
1399.39	47.0118
1402.55	46.6609
1405.7	46.0409
1408.86	44.3034
1412.01	44.4566
1415.17	45.7
1418.32	47.9503
1421.47	51.2161
1424.62	56.6898
1427.77	59.4874
1430.91	64.6204
1434.06	71.5122
1437.2	76.9646
1440.35	79.6163
1443.49	82.9325
1446.63	85.0379
1449.77	87.1419
1452.91	85.7006
1456.05	83.8376
1459.18	82.5798
1462.32	79.3126
1465.45	74.2977
1468.59	68.8687
1471.72	62.2925
1474.85	54.7462
1477.98	48.6648
1481.1	41.3499
1484.23	33.7082
1487.36	28.4852
1490.48	23.632
1493.61	19.0931
1496.73	17.1454
1499.85	14.8695
1502.97	13.5544
1506.09	13.5751
1509.2	14.5115
1512.32	15.1678
1515.43	15.7707
1518.55	17.6744
1521.66	19.0759
1524.77	22.2272
1527.88	25.2381
1530.99	28.0971
1534.1	31.352
1537.21	35.8661
1540.31	40.8346
1543.42	43.2996
1546.52	49.0082
1549.62	55.4836
1552.72	61.4709
1555.82	66.6242
1558.92	72.5665
1562.02	77.7269
1565.11	82.9951
1568.21	87.6016
1571.3	93.7528
1574.39	97.4152
1577.49	101.731
1580.57	103.862
1583.66	106.55
1586.75	108.712
1589.84	107.617
1592.92	106.506
1596.01	105.422
1599.09	102.913
1602.17	100.957
1605.25	97.757
1608.33	95.0371
1611.41	93.1126
1614.49	91.9715
1617.57	88.836
1620.64	87.4749
1623.72	87.2092
1626.79	87.3286
1629.86	88.5986
1632.93	89.8927
1636	91.9105
1639.07	94.967
1642.13	97.9268
1645.2	99.6783
1648.26	102.486
1651.33	105.576
1654.39	104.837
1657.45	104.079
1660.51	103.663
1663.57	100.936
1666.63	97.2126
1669.68	92.7682
1672.74	88.3416
1675.79	83.2642
1678.85	78.4998
1681.9	73.4491
1684.95	67.6494
1688	60.6113
1691.05	52.4676
1694.09	45.4787
1697.14	38.6756
1700.18	32.9796
1703.23	27.9504
1706.27	24.3441
1709.31	22.0636
1712.35	19.4542
1715.39	16.8536
1718.43	14.8549
1721.47	13.8003
1724.5	13.3049
1727.54	10.3986
1730.57	8.75831
1733.61	8.01735
1736.64	6.86707
1739.67	5.68832
1742.7	5.55437
1745.72	6.5009
1748.75	7.28451
1751.77	7.0135
1754.8	6.70769
1757.82	6.43371
1760.84	5.3828
1763.87	3.83494
1766.89	2.92126
1769.91	1.97698
1772.92	0.432678
1775.94	1.23376
1778.95	2.21697
1781.97	2.29824
1784.98	2.3788
1787.99	2.70521
1791.01	1.86095
1794.01	0.684564
1797.02	1.28776
1800.03	1.02387
1803.04	-0.176936
1806.04	-0.114418
1809.05	0.165156
1812.05	-0.287914
1815.05	-0.540883
1818.05	0.537714
1821.05	-0.0169136
1824.05	-0.119073
1827.05	0.20098
1830.04	-0.117177
1833.04	0.0391833
1836.03	0.282731
1839.03	-0.282348
1842.02	-0.763864
1845.01	-0.786588
1848	-0.581042
1850.99	0.537538
1853.97	0.589932
1856.96	0.113059
1859.94	1.05955
1862.93	0.658641
1865.91	0.512303
1868.89	1.40771
1871.87	2.01749
1874.85	2.24357
1877.83	2.67549
1880.81	4.05854
1882.57	4.2321
1885.56	5.20612
1888.55	6.21208
1891.54	6.21496
1894.52	7.27992
1897.51	7.8737
1900.49	9.16852
1903.47	10.5341
1906.45	12.2105
1909.43	11.8318
1912.41	11.4661
1915.39	12.548
1918.37	12.2684
1921.34	11.5086
1924.32	10.0319
1927.29	8.81609
1930.26	8.06167
1933.23	7.96673
1936.2	7.04556
1939.17	6.16468
1942.14	5.6338
1945.11	5.2241
1948.07	5.20887
1951.04	5.78868
1954	5.75273
1956.96	6.28443
1959.93	6.09786
1962.89	5.22047
1965.85	5.37115
1968.8	6.43113
1971.76	7.74259
1974.72	8.69022
1977.67	8.92819
1980.63	8.82347
1983.58	9.33406
1986.53	9.72664
1989.48	10.089
1992.43	9.47999
1995.38	9.20921
1998.32	9.2598
2001.27	9.64833
2004.22	10.3458
2007.16	10.5378
2010.1	9.96282
2013.04	10.0441
2015.98	10.2722
2018.92	11.663
2021.86	12.5987
2024.8	13.6345
2027.74	13.647
2030.67	13.9748
2033.61	13.7456
2036.54	14.107
2039.47	13.5285
2042.4	14.2872
2045.33	15.0257
2048.26	15.5415
2051.19	15.8215
2054.12	17.3004
2057.04	17.6178
2059.97	17.9991
2062.89	18.8999
2065.81	19.1622
2068.73	20.1154
2071.65	21.2772
2074.57	23.0149
2077.49	24.4161
2080.41	25.0312
2083.32	27.1399
2086.24	28.021
2089.15	29.8345
2092.07	31.5426
2094.98	32.3822
2097.89	33.2122
2100.8	35.5421
2103.71	36.5604
2106.61	38.5473
2109.52	39.5198
2112.43	42.3496
2115.33	45.8247
2118.23	49.8373
2121.13	52.4487
2124.04	57.0038
2126.94	61.3039
2129.83	66.1904
2132.73	70.5493
2135.63	74.9744
2138.53	80.3942
2141.42	85.8074
2144.31	90.3757
2147.21	97.0564
2150.1	100.989
2152.99	105.286
2155.88	109.247
2158.77	111.362
2161.65	113.891
2164.54	116.463
2167.43	118.068
2170.31	119.147
2173.19	120.577
2176.07	120.396
2178.96	118.917
2181.84	118.803
2184.72	117.708
2187.59	115.15
2190.47	112.787
2193.35	109.068
2196.22	106.506
2199.09	102.326
2201.97	98.3672
2204.84	92.1107
2207.71	86.3663
2210.58	82.0171
2213.45	78.0692
2216.31	73.4519
2219.18	67.7104
2222.05	63.9346
2224.91	59.6668
2227.78	54.547
2230.64	50.6136
2233.5	46.6677
2236.36	42.9764
2239.22	39.5624
2242.08	37.6065
2244.93	36.6753
2247.79	34.803
2250.64	34.0384
2253.5	32.9897
2256.35	32.1525
2259.2	31.8507
2262.05	30.8627
2264.9	30.8521
2267.75	32.0078
2270.6	30.3097
2273.45	29.5446
2276.29	27.7916
2279.14	26.7928
2281.98	26.209
2284.82	25.3532
2287.66	23.1994
2290.5	22.0774
2293.34	19.4212
2296.18	17.3349
2299.02	17.0624
2301.86	16.3942
2304.69	15.9841
2307.53	14.92
2310.36	14.4409
2313.19	14.1959
2316.02	14.4184
2318.85	13.4355
2321.68	12.8887
2324.51	12.527
2327.34	12.2757
2330.16	11.8954
2332.99	11.5195
2335.81	11.3954
2338.64	10.6719
2341.46	9.43323
2344.28	8.06591
2347.1	5.71098
2349.92	4.8036
2352.74	4.24981
2355.55	2.97129
2358.37	1.57447
2361.19	0.0509264
2364	-0.143414
2366.81	0.437391
2369.62	0.742319
2372.44	-0.162371
2375.24	-0.277628
2378.05	-0.293413
2380.86	0.608323
2383.67	1.08469
2386.47	1.33224
2389.28	2.2316
2392.08	3.40702
2394.89	3.92927
2397.69	4.78456
2400.49	4.2632
2403.29	5.00614
2406.09	5.54929
2408.88	6.23331
2411.68	6.98744
2414.48	7.73859
2417.27	7.34835
2420.06	8.77003
2422.86	8.63396
2425.65	8.53336
2428.44	8.80566
2431.23	7.68314
2434.02	7.56881
2436.81	7.99286
2439.59	8.04151
2442.38	7.79693
2445.16	8.20708
2447.95	8.03081
2450.73	7.97842
2453.51	7.35255
2456.29	6.84576
2459.07	7.81987
2461.85	6.19985
2464.63	6.07544
2467.4	4.85523
2470.18	4.55301
2472.95	5.49238
2475.73	6.22142
2478.5	5.47062
2481.27	6.19194
2484.04	5.58807
2486.81	5.40366
2489.58	6.12045
2492.35	5.1885
2495.12	4.96314
2497.88	3.70199
2500.65	2.60689
2503.41	2.79159
2506.17	2.53092
2508.94	1.40509
2511.7	1.331
2514.46	1.7824
2517.22	0.554349
2519.97	0.934728
2522.73	1.56148
2525.49	1.78409
2528.24	1.2355
2530.99	2.29992
2533.75	2.41174
2536.5	1.29645
2539.25	2.43214
2542	4.19592
2544.75	3.66585
2547.5	4.03192
2550.24	5.79504
2552.99	6.09463
2555.74	5.95697
2558.48	5.78794
2561.22	5.33224
2563.96	5.69774
2566.71	5.11964
2569.45	5.47229
2572.18	5.91209
2574.92	5.40032
2577.66	4.40297
2580.4	4.02972
2583.13	3.37202
2585.87	3.52509
2588.6	4.1434
2591.33	3.00326
2594.06	2.62107
2596.79	2.0104
2599.52	1.52201
2602.25	0.574731
2604.98	1.65607
2607.71	0.988455
2610.43	0.717807
2613.16	1.51902
2615.88	2.13689
2618.6	1.5948
2621.32	1.01805
2624.04	1.33903
2626.76	1.64917
2629.48	2.12608
2632.2	2.82253
2634.92	3.51429
2637.63	3.01205
2640.35	3.93424
2643.06	3.23464
2645.77	4.67085
2648.49	5.44785
2651.2	6.05292
2653.91	6.45975
2656.62	7.93606
2659.33	8.05446
2662.03	8.70636
2664.74	9.26257
2667.44	10.5392
2670.15	10.5011
2672.85	10.4317
2675.55	10.427
2678.26	11.2456
2680.96	11.7443
2683.66	10.7622
2686.35	11.6771
2689.05	11.1986
2691.75	11.9514
2694.44	12.2702
2697.14	12.8049
2699.83	12.9477
2702.52	13.2953
2705.22	14.2101
2707.91	15.1331
2710.6	16.1075
2713.29	17.2075
2715.97	17.5876
2718.66	17.7437
2721.35	17.9391
2724.03	17.0466
2726.72	16.7853
2729.4	17.1624
2732.08	15.9633
2734.76	14.896
2737.44	14.1552
2740.12	14.3643
2742.8	14.3097
2745.48	14.4406
2748.16	12.8032
2750.83	11.5092
2753.51	10.1286
2756.18	7.57712
2758.85	6.96629
2761.53	6.38243
2764.2	5.89768
2766.87	5.91355
2769.54	7.05878
2772.2	7.32392
2774.87	7.71044
2777.54	8.06862
2780.2	8.30528
2782.87	8.44705
2785.53	8.09432
2788.19	7.98368
2790.85	9.2418
2793.51	10.7931
2796.17	11.8391
2798.83	12.4456
2801.49	13.9533
2804.15	15.5855
2806.8	15.7672
2809.46	16.9906
2812.11	15.8861
2814.76	16.1264
2817.42	15.5579
2820.07	16.4943
2822.72	17.9144
2825.37	20.4576
2828.02	23.9682
2830.66	27.714
2833.31	31.7701
2835.96	36.2044
2838.6	41.6065
2841.24	47.355
2843.89	54.5477
2846.53	61.9675
2849.17	70.3587
2851.81	79.2634
2854.45	89.2959
2857.09	98.7741
2859.72	108.091
2862.36	117.484
2865	126.037
2867.63	134.027
2870.26	140.343
2872.9	146.36
2875.53	151.925
2878.16	155.537
2880.79	160.739
2883.42	164.315
2886.05	167.604
2888.67	171.115
2891.3	176.615
2893.92	182.808
2896.55	188.962
2899.17	195.737
2901.79	204.826
2904.42	214.927
2907.04	225.564
2909.66	238.658
2912.27	251.628
2914.89	264.768
2917.51	277.905
2920.13	289.186
2922.74	299.312
2925.35	307.817
2927.97	313.503
2930.58	316.788
2933.19	318.323
2935.8	318.404
2938.41	315.893
2941.02	309.673
2943.63	302.58
2946.24	293.4
2948.84	283.04
2951.45	272.526
2954.05	262.765
2956.65	252.5
2959.26	241.851
2961.86	231.3
2964.46	220.665
2967.06	209.977
2969.66	199.089
2972.25	189.77
2974.85	180.165
2977.45	169.453
2980.04	158.692
2982.64	148.263
2985.23	137.142
2987.82	125.035
2990.41	114.909
2993	104.47
2995.59	93.9216
2998.18	85.3839
3000.77	76.0155
3003.36	67.1732
3005.94	58.4327
3008.53	51.3244
3011.11	45.6899
3013.69	39.6991
3016.28	35.8727
3018.86	32.4618
3021.44	29.2266
3024.02	27.0264
3026.6	25.0969
3029.18	22.8991
3031.75	21.6988
3034.33	22.1773
3036.9	22.8414
3039.48	23.5118
3042.05	24.024
3044.62	24.8311
3047.19	26.4778
3049.77	27.4106
3052.34	28.3823
3054.9	29.2388
3057.47	29.1422
3060.04	29.6656
3062.61	29.2649
3065.17	27.7583
3067.74	25.8252
3070.3	24.1668
3072.86	22.223
3075.42	19.42
3077.99	16.7363
3080.54	14.0382
3083.1	11.1724
3085.66	9.43852
3088.22	7.33435
3090.78	4.65903
3093.33	3.8417
3095.89	2.26297
3098.44	2.38545
3100.99	1.50977
3103.54	0.605048
3106.1	0.77114
3108.65	0.971464
3111.2	1.37014
3113.74	1.12596
3116.29	2.19706
3118.84	2.70366
3121.38	3.17233
3123.93	4.044
3126.47	4.22644
3129.01	4.36102
3131.56	5.18064
3134.1	4.68047
3136.64	4.95328
3139.18	4.80467
3141.72	5.38301
3144.26	5.27065
3146.79	5.03703
3149.33	2.13406