File: data/Raman/poly_smoothed/Thy_10_08_18_1x_45s_532 nm_x100_100%_600 gr_mm_01.txt
#Acq. time (s)=	45
#Accumulations=	2
#Range (cm-¹)=	200...3150
#Windows=	2
#Auto scanning=	Off
#Autofocus=	Off
#Macrospot=	Off
#AutoExposure=	Off
#Spike filter=	Multiple accum.
#Delay time (s)=	0
#Binning=	1
#Readout mode=	Signal
#DeNoise=	Off
#ICS correction=	On
#Dark correction=	Off
#Inst. Process=	Off
#Detector Gain=	Best Dynamic Range
#Detector ADC=	20 kHz
#Detector temperature (°C)=	-69.85
#Instrument=	LabRAM HR Evol
#Detector=	Synapse
#Objective=	x100
#Grating=	600 gr/mm
#ND Filter=	100%
#Laser (nm)=	532
#Hole=	100.021
#Range=	Auto
#Laser Pol.=	No
#Raman. Pol.=	No
#Laser Pol. (°)=	-0.0007625
#Raman Pol. (°)=	89.9995
#Collection=	Microscope
#StageXY=	Marzhauser
#StageZ=	Marzhauser
#X (µm)=	2206.3
#Y (µm)=	1249.2
#Z (µm)=	442.3
#Full time(mm:ss)=	3:18
#Project=
#Sample=
#Site=
#Title=	Thy_10_08_18_2x_45s_532 nm_x100_100%_600 gr_mm
#Remark=
#Date=	05.07.2022 15:28
#Acquired=	05.07.2022 15:28:11
#Base:Fit=	10.08.2022 09:46:25
#Base:Sub=	10.08.2022 09:46:49
#Filter:Polynom=	16.08.2022 10:24:56
#AxisType[0]=Intens
#AxisUnit[0]=Cnt
#AxisType[1]=Spectr
#AxisUnit[1]=1/cm
200.43	36.7852
204.059	32.2097
207.688	27.6785
211.314	22.6179
214.941	17.5423
218.564	14.9663
222.186	12.8591
225.809	8.99059
229.428	8.34117
233.045	5.23344
236.663	3.45573
240.278	2.99896
243.891	1.47975
247.503	1.69606
251.116	3.95712
254.725	3.85782
258.333	3.81983
261.939	3.83995
265.544	5.26837
269.148	5.66519
272.75	6.82208
276.351	6.73151
279.95	6.55414
283.548	6.16096
287.144	6.95862
290.739	8.20427
294.333	7.73874
297.925	7.23836
301.514	8.46627
305.104	8.72185
308.692	9.23732
312.279	8.48593
315.862	8.45771
319.446	9.31696
323.029	8.86991
326.608	10.3652
330.188	11.7449
333.766	11.8732
337.341	14.1768
340.917	14.0899
344.489	14.2059
348.062	13.8452
351.631	13.5248
355.201	13.9763
358.768	11.3187
362.333	10.0282
365.899	7.65991
369.462	7.16228
373.023	6.05971
376.585	7.10228
380.143	7.00246
383.7	5.11384
387.256	3.4215
390.812	2.35047
394.365	4.33628
397.916	4.7535
401.467	3.60989
405.015	3.44226
408.563	6.0342
412.109	6.65108
415.654	7.79292
419.197	8.56884
422.739	7.56331
426.279	8.10284
429.819	8.38148
433.356	8.18683
436.891	7.86762
440.426	8.66611
443.96	7.37347
447.492	7.15892
451.021	8.19751
454.551	9.01217
458.079	10.8383
461.604	12.8881
465.13	14.1453
468.654	13.6157
472.175	12.8085
475.696	15.2512
479.215	17.1849
482.733	18.1314
486.249	19.2784
489.765	20.7015
493.278	22.2798
496.789	23.3689
500.301	23.7088
503.81	23.4468
507.317	22.9436
510.825	21.9091
514.33	24.9485
517.833	23.3106
521.335	21.1006
524.836	20.3854
528.335	20.0527
531.835	21.7179
535.332	22.0346
538.827	21.9701
542.321	20.3225
545.814	19.0774
549.305	18.477
552.795	18.0957
556.282	16.1573
559.769	16.3188
563.255	16.282
566.739	15.7585
570.223	15.1572
573.705	13.019
577.183	12.86
580.663	11.6177
584.141	10.1187
587.615	11.2161
591.09	9.7525
594.564	8.99
598.035	7.15826
601.506	6.61094
604.974	4.51505
608.443	6.37923
611.908	7.55649
615.374	7.64524
618.837	9.63677
622.3	8.64901
625.761	7.18505
629.219	8.23412
632.677	10.7497
636.135	11.3611
639.59	13.5837
643.043	15.6912
646.495	17.2914
649.948	17.9132
653.398	18.7566
656.846	18.4742
660.293	20.4936
663.738	22.8892
667.183	24.9109
670.626	27.101
674.067	27.7992
677.508	25.9214
680.947	25.6081
684.385	26.597
687.821	28.9569
691.254	28.9958
694.688	29.773
698.121	29.8478
701.552	31.5129
704.98	30.5402
708.409	31.113
711.836	32.811
715.26	37.1113
718.685	40.4585
722.108	43.5318
725.528	46.0973
728.949	51.0297
732.367	52.1434
735.785	54.1146
739.2	55.3281
742.614	59.8098
746.028	63.6216
749.439	67.4299
752.849	70.7449
756.26	73.1335
759.667	74.6023
763.073	76.1548
766.477	78.5919
769.883	79.7857
773.285	80.1682
776.686	80.0406
780.085	80.6187
783.484	80.6696
786.881	80.5998
790.276	80.7183
793.671	83.3662
797.064	86.1328
800.456	88.5718
803.846	88.7469
807.234	89.9208
810.622	90.4042
814.008	90.3584
817.394	89.3095
820.778	90.5267
824.159	93.7271
827.541	96.4818
830.921	98.853
834.298	99.5824
837.676	96.6241
841.051	97.4121
844.426	95.126
847.798	91.4765
851.171	88.5306
854.54	84.8368
857.911	79.8792
861.278	75.0826
864.645	71.8212
868.01	68.7326
871.373	67.0324
874.735	62.9341
878.097	60.007
881.457	58.3852
884.815	57.2349
888.172	55.7499
891.528	54.9033
894.882	54.2805
898.237	53.4224
901.589	54.0929
904.94	55.103
908.289	57.0221
911.635	59.4092
914.982	58.8628
918.328	56.3605
921.672	56.4857
925.015	57.6995
928.357	55.9765
931.698	55.9269
935.035	54.9692
938.373	53.8364
941.71	51.5448
945.044	51.6622
948.378	50.0744
951.709	50.3489
955.041	49.9993
958.372	48.6699
961.699	45.3881
965.027	46.4665
968.352	48.5323
971.676	50.9595
975	52.9927
978.322	55.9548
981.642	57.4274
984.962	58.2495
988.28	59.4723
991.596	60.197
994.911	59.6827
998.227	58.5806
1001.54	58.4111
1004.85	57.683
1008.16	57.5782
1011.47	56.3678
1014.78	54.4034
1018.08	53.4669
1021.39	50.5094
1024.69	48.287
1028	45.3988
1031.3	43.691
1034.6	40.5799
1037.9	34.4971
1041.19	31.3585
1044.49	30.4767
1047.78	32.7413
1051.08	32.3459
1054.37	32.3775
1057.66	31.3557
1060.95	29.7165
1064.24	28.315
1067.53	25.9576
1070.81	26.7293
1074.1	27.441
1077.38	26.9471
1080.66	27.7703
1083.94	26.8637
1087.22	26.5183
1090.5	26.5365
1093.78	27.0986
1097.05	27.6447
1100.33	27.774
1103.6	27.671
1106.87	28.2459
1110.14	26.7729
1113.41	24.0013
1116.68	22.7371
1119.95	20.3453
1123.21	19.2977
1126.48	17.1087
1129.74	14.8119
1133	13.4392
1136.26	11.2046
1139.52	10.8225
1142.78	11.9441
1146.04	11.7625
1149.29	12.0796
1152.55	11.2192
1155.8	9.57001
1159.05	7.6863
1162.3	4.88631
1165.55	4.30257
1168.8	3.21662
1172.05	5.51198
1175.29	7.46504
1178.54	11.9066
1181.78	14.304
1185.02	17.8501
1188.26	20.5866
1191.5	22.0744
1194.74	24.9839
1197.97	29.0937
1201.21	33.338
1204.44	38.7883
1207.68	43.6119
1210.91	48.5666
1214.14	55.0163
1217.37	61.4802
1220.59	68.7305
1223.82	74.3637
1227.05	77.8573
1230.27	80.5263
1233.49	83.6123
1236.72	86.2585
1239.94	87.6827
1243.16	90.3228
1246.37	91.469
1249.59	94.6358
1252.8	95.9765
1256.02	95.8362
1259.23	95.4297
1262.44	94.8911
1265.66	93.4679
1268.86	92.4872
1272.07	92.6462
1275.28	93.3271
1278.48	94.4338
1281.69	95.2847
1284.89	95.8712
1288.09	98.258
1291.29	101.1
1294.49	105.531
1297.69	108.245
1300.89	113.028
1304.08	117.634
1307.28	120.658
1310.47	125.762
1313.66	130.06
1316.85	132.27
1320.04	132.903
1323.23	135.743
1326.42	137.983
1329.61	138.586
1332.79	135.348
1335.97	132.36
1339.16	130.239
1342.34	127.927
1345.52	124.118
1348.7	119.516
1351.87	113.787
1355.05	107.498
1358.22	102.275
1361.4	97.0461
1364.57	89.776
1367.74	85.7081
1370.91	80.3398
1374.08	75.8595
1377.25	72.7699
1380.41	68.4981
1383.58	66.3375
1386.74	63.5612
1389.91	60.1686
1393.07	58.0844
1396.23	55.94
1399.39	54.6764
1402.55	56.6753
1405.7	57.3575
1408.86	58.185
1412.01	63.7067
1415.17	69.4436
1418.32	76.7242
1421.47	85.5247
1424.62	94.075
1427.77	104.376
1430.91	114.698
1434.06	124.775
1437.2	131.994
1440.35	137.594
1443.49	142.785
1446.63	146.616
1449.77	144.984
1452.91	142.411
1456.05	139.021
1459.18	133.073
1462.32	125.109
1465.45	115.188
1468.59	103.89
1471.72	92.4071
1474.85	81.2172
1477.98	69.524
1481.1	58.2002
1484.23	48.6811
1487.36	40.7544
1490.48	34.8823
1493.61	28.3207
1496.73	24.3596
1499.85	22.9264
1502.97	22.8783
1506.09	21.7414
1509.2	23.1144
1512.32	22.3231
1515.43	23.8674
1518.55	24.5388
1521.66	26.9425
1524.77	29.2043
1527.88	31.3129
1530.99	34.2605
1534.1	38.6007
1537.21	41.4194
1540.31	45.3969
1543.42	49.1429
1546.52	52.4008
1549.62	57.9806
1552.72	65.4908
1555.82	69.0627
1558.92	75.0471
1562.02	79.8692
1565.11	86.49
1568.21	92.5906
1571.3	97.8993
1574.39	103.535
1577.49	109.476
1580.57	115.324
1583.66	118.655
1586.75	124.682
1589.84	128.088
1592.92	129.559
1596.01	129.913
1599.09	129.887
1602.17	128.542
1605.25	125.134
1608.33	122.794
1611.41	120.287
1614.49	118.627
1617.57	114.588
1620.64	110.47
1623.72	110.128
1626.79	110.556
1629.86	109.832
1632.93	111.064
1636	112.642
1639.07	116.468
1642.13	120.588
1645.2	123.357
1648.26	127.389
1651.33	131.648
1654.39	135.512
1657.45	138.395
1660.51	139.627
1663.57	140.514
1666.63	138.738
1669.68	135.56
1672.74	130.763
1675.79	124.103
1678.85	115.985
1681.9	106.694
1684.95	98.3315
1688	87.712
1691.05	75.6694
1694.09	63.4944
1697.14	53.9621
1700.18	44.6832
1703.23	36.9491
1706.27	29.0262
1709.31	24.3059
1712.35	18.9462
1715.39	16.5754
1718.43	13.2433
1721.47	10.7081
1724.5	9.1355
1727.54	9.39961
1730.57	8.48947
1733.61	7.9601
1736.64	7.20168
1739.67	7.18337
1742.7	7.10566
1745.72	6.42154
1748.75	4.16582
1751.77	3.27231
1754.8	2.58292
1757.82	2.05779
1760.84	2.18354
1763.87	0.67487
1766.89	0.0201946
1769.91	-0.0578619
1772.92	-0.0699164
1775.94	0.427742
1778.95	0.824621
1781.97	1.07552
1784.98	2.07799
1787.99	2.70776
1791.01	3.3169
1794.01	2.9838
1797.02	2.62092
1800.03	2.65324
1803.04	1.9537
1806.04	1.50986
1809.05	1.42587
1812.05	0.977579
1815.05	0.581823
1818.05	-0.128111
1821.05	-0.367808
1824.05	0.329782
1827.05	0.985964
1830.04	1.92075
1833.04	1.92909
1836.03	1.94925
1839.03	1.93336
1842.02	2.40819
1845.01	2.68941
1848	2.89055
1850.99	2.26246
1853.97	2.23659
1856.96	2.87339
1859.94	4.29209
1862.93	3.56511
1865.91	4.08698
1868.89	5.36121
1871.87	6.12615
1874.85	6.28142
1877.83	6.90302
1880.81	7.78476
1882.57	7.11795
1885.56	7.28581
1888.55	7.12435
1891.54	7.45262
1894.52	8.34508
1897.51	9.39913
1900.49	9.82344
1903.47	9.73952
1906.45	10.3318
1909.43	9.6247
1912.41	9.67771
1915.39	10.3627
1918.37	11.1321
1921.34	11.7448
1924.32	11.6363
1927.29	11.9595
1930.26	12.8973
1933.23	13.8302
1936.2	13.875
1939.17	14.7855
1942.14	15.4461
1945.11	15.551
1948.07	15.6924
1951.04	14.6063
1954	14.4317
1956.96	14.529
1959.93	13.8545
1962.89	13.6035
1965.85	13.7444
1968.8	14.2169
1971.76	14.5595
1974.72	14.389
1977.67	14.1553
1980.63	13.6062
1983.58	12.8537
1986.53	13.741
1989.48	14.5149
1992.43	14.5819
1995.38	14.8003
1998.32	14.87
2001.27	14.3146
2004.22	15.5952
2007.16	15.2001
2010.1	15.3505
2013.04	15.5147
2015.98	14.5065
2018.92	14.6594
2021.86	15.1253
2024.8	15.9536
2027.74	16.8566
2030.67	18.0703
2033.61	18.615
2036.54	20.5819
2039.47	21.1172
2042.4	22.1381
2045.33	23.0324
2048.26	23.5415
2051.19	23.7887
2054.12	24.1179
2057.04	24.2269
2059.97	24.627
2062.89	25.9131
2065.81	26.1427
2068.73	25.9005
2071.65	24.971
2074.57	25.7931
2077.49	25.8149
2080.41	25.8062
2083.32	25.623
2086.24	25.5844
2089.15	26.6483
2092.07	28.5606
2094.98	28.5094
2097.89	28.9381
2100.8	30.2632
2103.71	31.9332
2106.61	33.0297
2109.52	34.5247
2112.43	34.8009
2115.33	36.7196
2118.23	36.562
2121.13	37.3995
2124.04	39.4814
2126.94	39.747
2129.83	40.8295
2132.73	41.8491
2135.63	43.3385
2138.53	44.7903
2141.42	46.0644
2144.31	47.8352
2147.21	50.3087
2150.1	52.3354
2152.99	54.161
2155.88	56.6442
2158.77	59.7011
2161.65	62.3834
2164.54	64.3406
2167.43	66.4119
2170.31	68.4964
2173.19	69.9932
2176.07	71.5282
2178.96	72.0911
2181.84	72.0808
2184.72	71.4245
2187.59	70.6935
2190.47	68.7421
2193.35	66.871
2196.22	64.0017
2199.09	62.222
2201.97	59.9825
2204.84	56.8105
2207.71	53.3398
2210.58	51.5557
2213.45	48.3347
2216.31	47.1954
2219.18	45.3985
2222.05	43.4597
2224.91	41.2565
2227.78	40.5162
2230.64	39.7023
2233.5	38.2957
2236.36	36.3848
2239.22	34.9654
2242.08	35.2635
2244.93	33.6316
2247.79	33.1809
2250.64	32.1064
2253.5	31.8203
2256.35	31.3254
2259.2	30.856
2262.05	29.5667
2264.9	29.7624
2267.75	30.174
2270.6	29.4196
2273.45	28.5509
2276.29	28.0728
2279.14	28.171
2281.98	28.1829
2284.82	27.4637
2287.66	26.3237
2290.5	25.3017
2293.34	24.3229
2296.18	24.4168
2299.02	24.6075
2301.86	24.6888
2304.69	25.2848
2307.53	25.3268
2310.36	26.052
2313.19	25.1351
2316.02	25.1228
2318.85	25.8879
2321.68	27.0873
2324.51	26.3964
2327.34	25.0662
2330.16	25.2406
2332.99	24.8527
2335.81	23.856
2338.64	23.2775
2341.46	21.3922
2344.28	20.7838
2347.1	20.4542
2349.92	18.1764
2352.74	16.4753
2355.55	14.6479
2358.37	13.5243
2361.19	12.843
2364	12.7983
2366.81	14.2402
2369.62	14.2744
2372.44	13.597
2375.24	13.3561
2378.05	12.4657
2380.86	12.6237
2383.67	12.869
2386.47	14.0481
2389.28	13.3345
2392.08	13.1439
2394.89	12.6144
2397.69	12.2606
2400.49	12.3781
2403.29	11.2832
2406.09	11.1266
2408.88	11.0127
2411.68	10.4725
2414.48	10.2239
2417.27	11.5599
2420.06	10.391
2422.86	10.9631
2425.65	10.9666
2428.44	11.263
2431.23	11.4366
2434.02	12.2192
2436.81	11.3359
2439.59	10.9175
2442.38	9.42361
2445.16	9.336
2447.95	8.30971
2450.73	6.86758
2453.51	5.63292
2456.29	5.7872
2459.07	4.75255
2461.85	3.55985
2464.63	2.26896
2467.4	1.48707
2470.18	0.865675
2472.95	-0.195608
2475.73	0.57308
2478.5	-0.288598
2481.27	-0.598058
2484.04	-0.800708
2486.81	0.233554
2489.58	1.33085
2492.35	1.9276
2495.12	1.95013
2497.88	2.68993
2500.65	3.06971
2503.41	3.43046
2506.17	3.03259
2508.94	3.14848
2511.7	3.75308
2514.46	4.28471
2517.22	3.32491
2519.97	3.52311
2522.73	4.00589
2525.49	4.49672
2528.24	4.14261
2530.99	4.27685
2533.75	3.70277
2536.5	3.15852
2539.25	2.65113
2542	2.83464
2544.75	2.61143
2547.5	2.81592
2550.24	3.05126
2552.99	4.13169
2555.74	6.3035
2558.48	6.56162
2561.22	5.96952
2563.96	6.43658
2566.71	6.65695
2569.45	6.50956
2572.18	6.6591
2574.92	7.88799
2577.66	7.61521
2580.4	8.4379
2583.13	7.9593
2585.87	7.22132
2588.6	6.69776
2591.33	6.22811
2594.06	6.02521
2596.79	6.03504
2599.52	4.80809
2602.25	3.12448
2604.98	2.33442
2607.71	0.804371
2610.43	-0.120385
2613.16	-0.768463
2615.88	-1.07952
2618.6	-0.810329
2621.32	-0.970157
2624.04	-1.82599
2626.76	-2.32935
2629.48	-1.49761
2632.2	-0.832904
2634.92	-0.9207
2637.63	-0.399175
2640.35	-0.171175
2643.06	-0.189531
2645.77	0.466872
2648.49	0.412493
2651.2	1.55691
2653.91	1.5785
2656.62	2.08176
2659.33	2.7575
2662.03	3.03631
2664.74	3.02619
2667.44	3.39121
2670.15	2.60856
2672.85	1.87913
2675.55	1.71992
2678.26	2.65156
2680.96	2.2634
2683.66	2.27999
2686.35	2.47416
2689.05	2.86362
2691.75	2.83985
2694.44	3.84499
2697.14	3.56516
2699.83	2.91685
2702.52	2.84086
2705.22	3.53202
2707.91	3.83124
2710.6	5.37972
2713.29	6.5616
2715.97	8.64824
2718.66	9.91036
2721.35	11.4494
2724.03	12.6979
2726.72	13.723
2729.4	14.3058
2732.08	15.1778
2734.76	14.8373
2737.44	14.7516
2740.12	15.2749
2742.8	14.9623
2745.48	14.4423
2748.16	13.6712
2750.83	13.8404
2753.51	13.0018
2756.18	11.6956
2758.85	10.3318
2761.53	9.20217
2764.2	8.48712
2766.87	6.97458
2769.54	6.2094
2772.2	6.41307
2774.87	5.27502
2777.54	4.47254
2780.2	4.82128
2782.87	3.99877
2785.53	4.91191
2788.19	4.53551
2790.85	4.57568
2793.51	4.05066
2796.17	3.58892
2798.83	3.6354
2801.49	3.78409
2804.15	3.72481
2806.8	4.02923
2809.46	4.64881
2812.11	5.69347
2814.76	6.31763
2817.42	6.93987
2820.07	9.14552
2822.72	12.631
2825.37	17.0329
2828.02	22.4819
2830.66	28.8782
2833.31	36.7701
2835.96	44.2625
2838.6	52.1207
2841.24	62.3833
2843.89	74.8962
2846.53	89.3807
2849.17	105.688
2851.81	124.669
2854.45	142.771
2857.09	160.518
2859.72	178.73
2862.36	196.622
2865	213.164
2867.63	228.338
2870.26	243.479
2872.9	256.127
2875.53	266.056
2878.16	274.586
2880.79	283.898
2883.42	291.676
2886.05	299.24
2888.67	305.461
2891.3	313.637
2893.92	321.322
2896.55	329.271
2899.17	338.442
2901.79	349.111
2904.42	363.053
2907.04	380.579
2909.66	400.05
2912.27	422.266
2914.89	444.545
2917.51	465.777
2920.13	484.597
2922.74	499.897
2925.35	511.245
2927.97	520.273
2930.58	523.943
2933.19	526.299
2935.8	523.611
2938.41	515.81
2941.02	505.315
2943.63	493.622
2946.24	478.572
2948.84	462.191
2951.45	444.439
2954.05	425.83
2956.65	407.772
2959.26	387.021
2961.86	369.686
2964.46	352.616
2967.06	337.18
2969.66	322.066
2972.25	308.811
2974.85	294.987
2977.45	280.795
2980.04	265.735
2982.64	249.652
2985.23	231.589
2987.82	213.311
2990.41	195.889
2993	178.833
2995.59	161.801
2998.18	146.592
3000.77	130.795
3003.36	117.056
3005.94	104.687
3008.53	92.284
3011.11	81.5614
3013.69	71.7007
3016.28	64.3166
3018.86	58.1029
3021.44	53.582
3024.02	49.76
3026.6	46.7003
3029.18	44.0837
3031.75	41.6107
3034.33	41.5223
3036.9	42.919
3039.48	44.1286
3042.05	46.0171
3044.62	48.2806
3047.19	50.5976
3049.77	53.3097
3052.34	56.0913
3054.9	56.8818
3057.47	57.57
3060.04	57.793
3062.61	56.4273
3065.17	54.4612
3067.74	52.2951
3070.3	49.6992
3072.86	45.5852
3075.42	41.5972
3077.99	37.3816
3080.54	32.6591
3083.1	27.9656
3085.66	22.4589
3088.22	17.2826
3090.78	12.8155
3093.33	9.80851
3095.89	6.80154
3098.44	5.1957
3100.99	3.79307
3103.54	3.12559
3106.1	2.43384
3108.65	2.63384
3111.2	3.05745
3113.74	2.49026
3116.29	1.68691
3118.84	0.520916
3121.38	0.817699
3123.93	0.46154
3126.47	0.673425
3129.01	0.413477
3131.56	0.707365
3134.1	0.0900005
3136.64	0.298957
3139.18	-0.142086
3141.72	-0.126898
3144.26	0.433995
3146.79	1.61535
3149.33	5.07168