File: data/Raman/poly_smoothed/Thy_30_10_50_1x_45s_532 nm_x100_100%_600 gr_mm_01.txt
#Acq. time (s)=	45
#Accumulations=	2
#Range (cm-¹)=	200...3150
#Windows=	2
#Auto scanning=	Off
#Autofocus=	Off
#Macrospot=	Off
#AutoExposure=	Off
#Spike filter=	Multiple accum.
#Delay time (s)=	0
#Binning=	1
#Readout mode=	Signal
#DeNoise=	Off
#ICS correction=	On
#Dark correction=	Off
#Inst. Process=	Off
#Detector Gain=	Best Dynamic Range
#Detector ADC=	20 kHz
#Detector temperature (°C)=	-69.85
#Instrument=	LabRAM HR Evol
#Detector=	Synapse
#Objective=	x100
#Grating=	600 gr/mm
#ND Filter=	100%
#Laser (nm)=	532
#Hole=	100.021
#Range=	Auto
#Laser Pol.=	No
#Raman. Pol.=	No
#Laser Pol. (°)=	-0.0007625
#Raman Pol. (°)=	89.9995
#Collection=	Microscope
#StageXY=	Marzhauser
#StageZ=	Marzhauser
#X (µm)=	4734.5
#Y (µm)=	-7694.2
#Z (µm)=	584.4
#Full time(mm:ss)=	3:18
#Project=
#Sample=
#Site=
#Title=	Thy_30_10_50_2x_45s_532 nm_x100_100%_600 gr_mm
#Remark=
#Date=	30.06.2022 14:58
#Acquired=	30.06.2022 14:58:33
#Base:Fit=	10.08.2022 09:58:11
#Base:Sub=	10.08.2022 09:58:44
#Filter:Polynom=	16.08.2022 10:22:53
#AxisType[0]=Intens
#AxisUnit[0]=Cnt
#AxisType[1]=Spectr
#AxisUnit[1]=1/cm
200.533	8.87413
204.162	9.26765
207.792	9.04122
211.418	7.93877
215.044	8.3435
218.667	7.87652
222.289	8.01294
225.912	7.61325
229.531	9.38946
233.148	9.83887
236.766	9.80906
240.381	11.0246
243.994	12.3503
247.606	12.5009
251.217	13.0887
254.828	12.5151
258.436	12.69
262.042	14.3753
265.647	15.7285
269.25	16.9866
272.852	15.9852
276.453	16.9
280.052	17.5266
283.65	17.7244
287.247	17.7036
290.842	16.6119
294.436	17.4425
298.028	19.1202
301.617	19.5069
305.206	20.7501
308.794	20.3843
312.381	21.7031
315.964	23.0254
319.548	23.7852
323.131	24.6777
326.71	23.8274
330.29	24.4603
333.868	24.6602
337.443	23.6034
341.018	22.9296
344.591	22.2915
348.163	22.896
351.733	22.2715
355.303	21.5043
358.869	21.2226
362.435	19.3194
366.001	18.7255
369.563	16.5632
373.124	16.4527
376.686	15.6104
380.244	14.9087
383.801	14.571
387.357	13.2765
390.911	12.5482
394.466	12.8496
398.018	13.3877
401.568	14.2916
405.117	14.7449
408.664	14.1274
412.21	14.9843
415.755	14.4044
419.298	15.2832
422.84	15.1795
426.38	15.7311
429.919	16.7642
433.455	16.9241
436.992	15.6446
440.527	14.1879
444.06	12.8197
447.593	11.4832
451.122	11.811
454.651	9.5175
458.18	9.80696
461.705	10.1278
465.23	9.78184
468.752	9.98062
472.275	10.3714
475.797	12.6194
479.315	14.0944
482.834	17.2533
486.349	18.621
489.863	18.5063
493.378	19.6357
496.889	21.0814
500.401	21.2504
503.91	22.8869
507.417	23.195
510.923	23.828
514.43	25.9679
517.933	24.7818
521.435	22.8577
524.936	22.889
528.435	20.3137
531.933	20.7061
535.43	19.8407
538.927	17.8455
542.421	15.7037
545.913	14.7385
549.403	13.1353
552.893	13.5689
556.381	14.1805
559.868	12.5049
563.354	11.6337
566.839	9.64197
570.322	7.64756
573.802	6.06489
577.283	4.41379
580.762	3.96258
584.24	4.04754
587.714	4.08922
591.19	4.85747
594.663	4.96052
598.134	5.17938
601.605	5.33968
605.073	4.4107
608.542	4.92502
612.007	5.99714
615.473	5.33799
618.936	5.79412
622.397	6.13258
625.859	7.1945
629.318	7.48637
632.775	10.2502
636.233	12.4535
639.688	13.9265
643.142	14.5157
646.594	14.7999
650.045	15.7133
653.496	17.868
656.944	20.7092
660.391	21.3701
663.837	21.8224
667.281	22.7946
670.724	22.4569
674.166	23.6578
677.606	24.4795
681.045	25.4618
684.483	25.6005
687.917	26.1232
691.352	26.7505
694.786	27.9353
698.219	28.3548
701.65	27.6163
705.078	29.1033
708.506	29.8502
711.934	30.8947
715.358	32.905
718.782	34.4578
722.204	35.5003
725.626	36.5613
729.045	39.0471
732.464	40.5376
735.881	41.7778
739.297	43.9282
742.711	44.6164
746.125	47.2994
749.537	49.8294
752.946	52.0554
756.357	55.0871
759.764	57.3485
763.17	57.5855
766.575	60.7296
769.978	62.0153
773.382	65.2581
776.783	67.5131
780.182	69.456
783.581	70.2309
786.978	71.5167
790.373	72.7525
793.768	74.264
797.161	75.2636
800.552	76.0796
803.941	76.695
807.33	77.5212
810.718	77.8665
814.105	77.1902
817.49	77.2875
820.873	76.9296
824.256	77.3101
827.637	78.0366
831.016	77.8625
834.395	76.2051
837.772	74.6022
841.147	71.1512
844.522	68.7386
847.894	67.1576
851.267	66.052
854.637	63.6045
858.007	61.9765
861.374	61.0514
864.739	60.5266
868.106	57.8568
871.469	55.6449
874.831	52.8016
878.193	52.8836
881.553	51.6439
884.911	51.4121
888.268	51.1991
891.623	51.2452
894.978	50.0768
898.331	49.4178
901.683	50.22
905.033	49.6037
908.383	48.8969
911.731	48.063
915.078	47.8883
918.423	46.194
921.768	45.8448
925.111	45.2137
928.452	44.0879
931.791	42.0551
935.13	40.2725
938.468	39.0021
941.803	38.2062
945.139	36.2744
948.473	32.457
951.804	29.6686
955.136	29.0366
958.465	28.3077
961.794	27.2281
965.12	26.789
968.447	25.8093
971.771	25.8128
975.095	25.8832
978.417	24.5896
981.737	24.2469
985.057	24.1425
988.375	24.6541
991.691	24.5384
995.006	25.3872
998.32	24.521
1001.63	25.2281
1004.95	25.6869
1008.26	25.6605
1011.56	25.0008
1014.87	25.0674
1018.18	24.6752
1021.48	23.7648
1024.79	22.1295
1028.09	20.8063
1031.39	21.4772
1034.69	20.9487
1037.99	20.5338
1041.29	19.8765
1044.58	20.2918
1047.88	18.6096
1051.17	18.2994
1054.46	18.1979
1057.75	16.8968
1061.04	16.232
1064.33	17.0218
1067.62	16.1643
1070.9	15.9147
1074.19	15.862
1077.47	15.8746
1080.76	14.4791
1084.04	14.0916
1087.32	14.4214
1090.59	13.2775
1093.87	12.1247
1097.15	11.066
1100.42	10.1676
1103.69	9.20355
1106.97	8.82528
1110.24	7.82987
1113.51	8.72043
1116.77	7.14143
1120.04	6.29435
1123.31	5.49189
1126.57	4.1649
1129.83	4.44958
1133.1	5.38463
1136.36	4.64103
1139.62	5.75738
1142.87	7.18309
1146.13	7.46421
1149.38	6.83082
1152.64	7.45079
1155.89	6.86052
1159.14	5.61845
1162.39	4.35913
1165.64	4.79632
1168.89	4.45394
1172.14	3.85979
1175.38	3.91004
1178.63	3.68607
1181.87	2.71196
1185.11	3.00287
1188.35	2.3802
1191.59	3.55925
1194.83	2.72229
1198.07	3.64657
1201.3	5.20655
1204.53	5.41972
1207.77	7.03138
1211	9.13444
1214.23	11.277
1217.46	13.6187
1220.69	16.4974
1223.91	20.1109
1227.14	21.2813
1230.36	23.3952
1233.59	25.8535
1236.81	27.7641
1240.03	29.726
1243.25	30.7569
1246.46	32.6437
1249.68	33.6719
1252.9	35.5935
1256.11	36.501
1259.32	37.0711
1262.54	37.9793
1265.75	38.884
1268.96	38.5348
1272.16	38.84
1275.37	40.2543
1278.57	41.7008
1281.78	42.0697
1284.98	41.8029
1288.18	41.7475
1291.38	43.0432
1294.58	44.408
1297.78	44.9647
1300.98	45.6546
1304.17	45.4047
1307.37	45.725
1310.56	45.7998
1313.76	47.1838
1316.95	47.7391
1320.14	47.7519
1323.32	47.5167
1326.51	47.0876
1329.7	46.9821
1332.88	45.6619
1336.07	43.4268
1339.25	42.6274
1342.43	40.7654
1345.61	38.2827
1348.79	35.687
1351.96	33.5752
1355.14	32.2802
1358.31	29.2146
1361.49	27.1279
1364.66	25.5315
1367.83	24.8654
1371	24.1046
1374.17	24.141
1377.34	22.6798
1380.5	21.8787
1383.67	21.6544
1386.83	21.6987
1390	22.4876
1393.16	20.6616
1396.32	20.1012
1399.48	19.3697
1402.64	18.954
1405.79	19.4918
1408.95	19.7721
1412.1	20.8428
1415.26	20.8855
1418.41	21.8259
1421.56	23.8646
1424.71	25.5457
1427.86	28.6723
1431	33.0991
1434.15	37.3821
1437.29	41.8753
1440.44	45.7618
1443.58	47.6194
1446.72	51.3426
1449.86	53.6261
1453	53.9964
1456.14	53.1639
1459.27	51.1089
1462.41	49.3428
1465.54	46.5944
1468.67	41.2324
1471.81	37.4861
1474.94	32.9515
1478.07	28.5684
1481.19	23.9305
1484.32	18.9048
1487.45	14.3224
1490.57	10.2626
1493.69	7.62007
1496.82	5.86742
1499.94	4.5619
1503.06	3.72464
1506.17	3.23415
1509.29	3.50216
1512.41	4.59236
1515.52	4.82414
1518.64	5.51001
1521.75	8.11085
1524.86	10.6509
1527.97	11.4677
1531.08	12.1686
1534.19	14.649
1537.29	14.6247
1540.4	16.1422
1543.5	17.4133
1546.61	17.8617
1549.71	19.1168
1552.81	19.6581
1555.91	21.9317
1559.01	23.2337
1562.11	23.8316
1565.2	25.0176
1568.29	25.9977
1571.39	29.5496
1574.48	30.8246
1577.57	32.3773
1580.66	33.6202
1583.75	34.6299
1586.84	36.6746
1589.93	36.884
1593.01	37.6939
1596.1	38.5591
1599.18	39.5556
1602.26	40.7325
1605.34	40.6269
1608.42	40.1643
1611.5	40.9266
1614.58	41.0112
1617.65	40.4449
1620.73	39.5741
1623.8	40.124
1626.87	40.93
1629.95	41.584
1633.02	42.569
1636.09	43.6454
1639.15	45.5908
1642.22	47.4295
1645.29	49.9915
1648.35	50.9091
1651.42	51.6746
1654.48	52.2824
1657.54	51.9105
1660.6	49.6116
1663.66	47.9802
1666.72	45.3991
1669.77	44.1087
1672.83	41.4412
1675.88	38.3579
1678.93	35.5166
1681.99	32.7152
1685.04	28.7537
1688.09	24.8921
1691.13	19.5455
1694.18	14.6449
1697.23	10.6979
1700.27	8.99715
1703.32	6.43589
1706.36	4.44909
1709.4	2.73937
1712.44	2.85873
1715.48	1.37885
1718.52	0.860124
1721.56	0.984892
1724.59	2.28716
1727.63	2.31876
1730.66	2.05594
1733.69	1.7887
1736.72	1.81532
1739.75	2.07229
1742.78	2.78955
1745.81	3.54819
1748.84	3.45889
1751.86	3.91024
1754.89	4.07657
1757.91	3.35945
1760.93	2.46089
1763.95	2.54695
1766.97	2.01424
1769.99	1.61899
1773.01	1.82185
1776.03	1.0967
1779.04	0.00419265
1782.06	0.562142
1785.07	0.72442
1788.08	1.41386
1791.09	1.50221
1794.1	2.60159
1797.11	2.5266
1800.12	2.50707
1803.12	2.49835
1806.13	2.91905
1809.13	2.0239
1812.14	2.58402
1815.14	2.62264
1818.14	3.0464
1821.14	3.12933
1824.14	2.84636
1827.13	4.03453
1830.13	4.71615
1833.12	4.5324
1836.12	5.15438
1839.11	5.70175
1842.1	5.78781
1845.09	5.25224
1848.08	4.85544
1851.07	5.50991
1854.06	6.2396
1857.04	6.45974
1860.03	7.30697
1863.01	7.25069
1866	8.21399
1868.98	7.93111
1871.96	7.28691
1874.94	6.29198
1877.92	5.2416
1880.89	5.04484
1882.48	5.02577
1885.47	4.42324
1888.46	4.06636
1891.44	3.94581
1894.43	3.76918
1897.41	4.29652
1900.4	5.17197
1903.38	4.81077
1906.36	5.76051
1909.34	6.37002
1912.32	6.97024
1915.29	7.62507
1918.27	7.86743
1921.25	8.6318
1924.22	9.27644
1927.2	9.35905
1930.17	8.94807
1933.14	8.98468
1936.11	8.84674
1939.08	8.46871
1942.05	6.54442
1945.01	5.544
1947.98	5.69449
1950.94	5.46253
1953.91	5.41145
1956.87	4.10965
1959.83	4.60009
1962.79	5.11712
1965.75	5.3283
1968.71	6.326
1971.67	7.44159
1974.62	7.50413
1977.58	9.15353
1980.53	10.2025
1983.48	10.5113
1986.43	11.0303
1989.38	11.1592
1992.33	11.1417
1995.28	11.3961
1998.23	11.1528
2001.18	11.0022
2004.12	11.3196
2007.06	10.5018
2010.01	11.1325
2012.95	11.4468
2015.89	10.9249
2018.83	11.8589
2021.77	11.8163
2024.71	11.8351
2027.64	11.7652
2030.58	12.2545
2033.51	12.7767
2036.45	13.0688
2039.38	12.7521
2042.31	13.1217
2045.24	13.6404
2048.17	14.0961
2051.1	13.8732
2054.02	13.9561
2056.95	14.1979
2059.87	14.4332
2062.8	14.3144
2065.72	15.4729
2068.64	16.2487
2071.56	16.7721
2074.48	17.378
2077.4	17.1557
2080.31	17.5697
2083.23	17.7249
2086.14	18.4342
2089.06	19.7328
2091.97	20.5164
2094.88	20.6493
2097.79	21.2965
2100.7	20.8237
2103.61	22.0982
2106.52	22.8266
2109.43	22.8855
2112.33	24.3521
2115.24	25.9645
2118.14	28.0414
2121.04	29.1569
2123.94	31.425
2126.84	32.6837
2129.74	34.8313
2132.64	37.2398
2135.54	38.4722
2138.43	40.5115
2141.33	41.1719
2144.22	41.8567
2147.11	42.4141
2150.01	44.7281
2152.9	46.024
2155.79	48.5799
2158.67	50.6276
2161.56	51.8375
2164.45	52.7572
2167.33	52.9121
2170.22	53.3836
2173.1	53.8107
2175.98	54.5508
2178.86	55.3625
2181.74	56.0742
2184.62	56.1553
2187.5	56.347
2190.38	55.7537
2193.25	55.0792
2196.13	53.8283
2199	52.1625
2201.88	50.8351
2204.75	47.99
2207.62	44.5747
2210.49	41.6768
2213.36	38.5469
2216.22	35.9356
2219.09	33.8504
2221.96	31.7126
2224.82	29.3087
2227.68	27.5339
2230.55	26.0733
2233.41	24.1011
2236.27	22.6188
2239.12	21.2236
2241.98	20.0861
2244.84	19.8854
2247.7	19.3991
2250.55	19.0011
2253.41	19.0184
2256.26	19.0158
2259.11	18.4993
2261.96	18.447
2264.81	18.1598
2267.66	17.6341
2270.51	16.1389
2273.35	15.8973
2276.2	14.7145
2279.04	13.6643
2281.89	12.0854
2284.73	11.8265
2287.57	11.5999
2290.41	10.6736
2293.25	9.72765
2296.09	9.97412
2298.93	10.4596
2301.76	11.3594
2304.6	11.5634
2307.44	11.5969
2310.27	12.6391
2313.1	13.5876
2315.93	13.5866
2318.76	13.6902
2321.59	14.4421
2324.42	14.627
2327.25	13.8167
2330.07	13.966
2332.9	13.6515
2335.72	13.5514
2338.55	12.4236
2341.37	11.0637
2344.19	10.2892
2347.01	8.91335
2349.83	8.06476
2352.65	6.84386
2355.46	5.69347
2358.28	4.25239
2361.09	3.73332
2363.91	3.33885
2366.72	3.48264
2369.53	3.65369
2372.34	3.30612
2375.15	3.31405
2377.96	4.4539
2380.77	4.20678
2383.58	3.07243
2386.38	3.25152
2389.19	3.70832
2391.99	3.29786
2394.8	3.30955
2397.6	3.74422
2400.4	4.50332
2403.2	4.583
2406	4.8497
2408.79	4.93302
2411.59	5.692
2414.39	6.36305
2417.18	5.65783
2419.98	6.63113
2422.77	7.09186
2425.56	7.01271
2428.35	7.14488
2431.14	6.43513
2433.93	6.53584
2436.72	6.65987
2439.5	7.59635
2442.29	7.58721
2445.07	8.38915
2447.86	7.05968
2450.64	6.28281
2453.42	6.71622
2456.2	5.96295
2458.98	6.17224
2461.76	6.46367
2464.54	6.25321
2467.32	5.9322
2470.09	5.46233
2472.87	5.27877
2475.64	4.62617
2478.41	4.31211
2481.18	4.80617
2483.95	3.47645
2486.72	2.85103
2489.49	2.54936
2492.26	1.7308
2495.03	0.439415
2497.79	0.192936
2500.56	0.192014
2503.32	0.31573
2506.09	0.834618
2508.85	1.3308
2511.61	1.41685
2514.37	1.21513
2517.13	2.16244
2519.89	2.8228
2522.64	2.00515
2525.4	2.89479
2528.15	2.92276
2530.91	2.96466
2533.66	3.90675
2536.41	4.52509
2539.16	4.48808
2541.91	4.61485
2544.66	4.66116
2547.41	5.20641
2550.16	5.56999
2552.9	5.03275
2555.65	4.81873
2558.39	4.46566
2561.13	4.04923
2563.88	3.72497
2566.62	3.0076
2569.36	2.68335
2572.1	2.8119
2574.84	2.61837
2577.57	2.24513
2580.31	1.60921
2583.05	1.72527
2585.78	0.97982
2588.51	0.453478
2591.24	0.0562052
2593.98	0.173534
2596.71	0.828588
2599.44	1.08968
2602.16	1.31227
2604.89	1.28996
2607.62	1.27512
2610.34	1.36289
2613.07	1.88892
2615.79	1.87674
2618.52	2.05963
2621.24	1.19183
2623.96	1.28298
2626.68	0.838261
2629.4	0.811452
2632.11	0.824998
2634.83	0.400952
2637.55	0.5699
2640.26	0.760527
2642.98	0.70366
2645.69	0.910732
2648.4	0.85758
2651.11	1.11229
2653.82	1.60961
2656.53	1.88077
2659.24	1.67014
2661.95	3.17843
2664.65	3.37147
2667.36	4.08258
2670.06	3.94844
2672.76	4.83577
2675.47	5.84469
2678.17	5.74079
2680.87	5.50557
2683.57	5.11665
2686.27	5.26015
2688.97	6.02873
2691.66	5.34323
2694.36	3.95764
2697.05	3.55796
2699.75	2.55161
2702.44	1.73782
2705.13	1.91356
2707.82	1.23383
2710.51	1.30769
2713.2	0.19982
2715.89	0.522062
2718.57	0.274666
2721.26	-0.0874176
2723.95	0.294198
2726.63	1.52226
2729.31	1.9633
2732	2.55908
2734.68	2.80406
2737.36	4.22118
2740.04	5.30709
2742.72	5.7655
2745.39	5.87154
2748.07	6.62147
2750.75	6.85367
2753.42	8.04873
2756.09	8.23285
2758.77	7.22669
2761.44	7.26751
2764.11	6.91612
2766.78	6.58198
2769.45	7.04097
2772.12	6.02688
2774.78	5.04349
2777.45	4.60767
2780.12	4.25434
2782.78	3.98488
2785.44	3.57487
2788.11	2.8859
2790.77	2.72635
2793.43	2.61616
2796.09	2.76
2798.75	2.65558
2801.4	3.19121
2804.06	3.17329
2806.72	3.33698
2809.37	3.20958
2812.03	2.63164
2814.68	2.74909
2817.33	4.06701
2819.98	6.08557
2822.63	6.88114
2825.28	9.24857
2827.93	11.6282
2830.58	13.9454
2833.23	17.3744
2835.87	20.7621
2838.52	24.1043
2841.16	27.7289
2843.8	32.4459
2846.44	37.0514
2849.08	42.6746
2851.73	48.4176
2854.36	54.8518
2857	61.7351
2859.64	67.8235
2862.28	73.641
2864.91	78.8769
2867.55	83.946
2870.18	87.5183
2872.81	90.9617
2875.44	93.5022
2878.07	95.8622
2880.7	98.5596
2883.33	101.34
2885.96	103.987
2888.59	106.552
2891.21	108.833
2893.84	112.226
2896.46	114.386
2899.09	116.488
2901.71	120.83
2904.33	124.687
2906.95	130.672
2909.57	137.451
2912.19	144.666
2914.81	152.394
2917.43	159.494
2920.04	165.572
2922.66	171.994
2925.27	175.872
2927.88	179.564
2930.5	180.775
2933.11	181.195
2935.72	179.9
2938.33	177.767
2940.94	175.031
2943.54	171.363
2946.15	166.959
2948.76	161.461
2951.36	155.226
2953.97	149.272
2956.57	142.567
2959.17	135.097
2961.77	128.399
2964.37	121.954
2966.97	116.482
2969.57	110.94
2972.17	106.023
2974.77	100.501
2977.36	95.4728
2979.96	89.6162
2982.55	83.7505
2985.15	77.9858
2987.74	72.5704
2990.33	66.8904
2992.92	61.1676
2995.51	56.511
2998.1	51.0762
3000.69	46.0278
3003.27	42.6766
3005.86	38.2723
3008.44	34.7234
3011.03	31.1727
3013.61	28.1521
3016.19	25.8819
3018.78	24.2019
3021.36	21.9328
3023.94	20.8623
3026.51	19.5891
3029.09	18.5975
3031.67	18.5566
3034.24	19.2549
3036.82	19.0519
3039.39	19.0639
3041.97	19.0674
3044.54	19.3212
3047.11	19.2901
3049.68	19.5401
3052.25	20.1639
3054.82	20.0206
3057.39	19.61
3059.96	19.2002
3062.52	18.6921
3065.09	17.9053
3067.65	17.2241
3070.22	16.1545
3072.78	14.9799
3075.34	14.1571
3077.9	12.8562
3080.46	11.2434
3083.02	9.8429
3085.58	8.72823
3088.14	7.30924
3090.69	6.29283
3093.25	5.76337
3095.8	4.48966
3098.36	3.94169
3100.91	2.69307
3103.46	1.83512
3106.01	2.029
3108.56	1.61774
3111.11	1.20316
3113.66	1.53522
3116.21	0.736629
3118.76	0.743029
3121.3	0.505659
3123.85	0.951043
3126.39	0.451634
3128.93	0.0663732
3131.48	-0.223079
3134.02	0.010368
3136.56	0.195772
3139.1	-0.0873823
3141.64	-0.576452
3144.17	-0.823352
3146.71	-1.52985
3149.25	-2.49209