File: data/Raman/poly_smoothed/Thy_00_07_41_1x_45s_532 nm_x100_100%_600 gr_mm_02.txt
#Acq. time (s)=	45
#Accumulations=	2
#Range (cm-¹)=	200...3150
#Windows=	2
#Auto scanning=	Off
#Autofocus=	Off
#Macrospot=	Off
#AutoExposure=	Off
#Spike filter=	Multiple accum.
#Delay time (s)=	0
#Binning=	1
#Readout mode=	Signal
#DeNoise=	Off
#ICS correction=	On
#Dark correction=	Off
#Inst. Process=	Off
#Detector Gain=	Best Dynamic Range
#Detector ADC=	20 kHz
#Detector temperature (°C)=	-69.85
#Instrument=	LabRAM HR Evol
#Detector=	Synapse
#Objective=	x100
#Grating=	600 gr/mm
#ND Filter=	100%
#Laser (nm)=	532
#Hole=	100.021
#Range=	Auto
#Laser Pol.=	No
#Raman. Pol.=	No
#Laser Pol. (°)=	-0.0007625
#Raman Pol. (°)=	89.9995
#Collection=	Microscope
#StageXY=	Marzhauser
#StageZ=	Marzhauser
#X (µm)=	-1467.9
#Y (µm)=	-618.9
#Z (µm)=	-227.8
#Full time(mm:ss)=	3:18
#Project=
#Sample=
#Site=
#Title=	Thy_00_07_41_2x_45s_532 nm_x100_100%_600 gr_mm
#Remark=
#Date=	29.06.2022 09:27
#Acquired=	29.06.2022 09:27:54
#Base:Fit=	10.08.2022 10:07:56
#Base:Sub=	10.08.2022 10:08:40
#Filter:Polynom=	16.08.2022 10:26:06
#AxisType[0]=Intens
#AxisUnit[0]=Cnt
#AxisType[1]=Spectr
#AxisUnit[1]=1/cm
200.523	0.151288
204.154	10.1923
207.781	15.6424
211.409	18.7634
215.034	20.474
218.659	21.2975
222.281	21.7843
225.903	21.685
229.522	20.5637
233.14	20.0028
236.756	19.4256
240.373	19.6152
243.986	19.5821
247.598	17.9499
251.208	15.1783
254.818	13.4906
258.427	13.256
262.034	12.6192
265.638	12.0786
269.242	13.4843
272.844	14.496
276.445	13.8055
280.044	14.9996
283.642	14.7492
287.238	13.66
290.833	12.1119
294.425	12.2132
298.017	11.8135
301.608	11.2968
305.198	10.7538
308.786	11.8025
312.371	12.7615
315.956	13.3065
319.54	13.6735
323.122	15.0179
326.701	14.5102
330.281	14.8777
333.857	13.4535
337.434	11.8941
341.008	11.4062
344.582	12.9693
348.153	12.6382
351.724	11.3804
355.292	11.9523
358.861	11.2672
362.426	9.55987
365.99	8.43919
369.555	8.00146
373.116	8.73126
376.676	7.92669
380.236	6.1545
383.793	5.7321
387.349	6.47959
390.903	5.6027
394.456	6.57106
398.007	6.55477
401.56	6.92873
405.108	7.16354
408.656	7.62727
412.202	8.83313
415.746	8.01538
419.29	8.21571
422.831	8.3539
426.37	8.66228
429.909	8.70163
433.447	7.61309
436.983	7.11938
440.519	6.83753
444.052	7.26404
447.583	5.32218
451.114	5.89648
454.643	7.21793
458.169	8.45822
461.696	8.31725
465.222	9.19444
468.744	9.1062
472.267	9.78841
475.787	10.6634
479.307	11.0509
482.823	13.2456
486.341	14.4993
489.855	16.6773
493.37	17.8781
496.881	18.9047
500.391	22.0769
503.902	20.2287
507.409	20.8346
510.915	20.8609
514.42	19.4273
517.925	18.8137
521.427	17.7176
524.928	17.0249
528.427	16.0718
531.925	14.7306
535.422	13.8155
538.917	12.8988
542.411	11.8683
545.903	12.5664
549.395	13.2303
552.884	12.0627
556.373	11.2915
559.86	11.7745
563.346	11.9815
566.831	11.8485
570.314	11.4805
573.794	11.6647
577.274	11.3674
580.754	12.1615
584.23	13.7472
587.706	13.8006
591.181	13.2129
594.653	13.2874
598.126	11.6467
601.595	10.8171
605.065	10.686
608.532	9.21836
611.999	8.3142
615.463	7.60049
618.928	6.32824
622.389	4.78651
625.851	4.84082
629.31	5.37138
632.767	5.7589
636.223	6.85843
639.68	9.18307
643.134	9.76089
646.586	11.2652
650.037	12.4102
653.486	14.0001
656.936	15.9998
660.383	18.767
663.829	19.8483
667.273	22.3536
670.716	24.2058
674.158	24.5511
677.598	24.1177
681.035	24.9146
684.473	27.4712
687.909	28.0439
691.344	27.1244
694.778	27.4682
698.211	26.6648
701.64	25.4899
705.07	26.4141
708.498	27.2936
711.924	29.2797
715.35	32.4101
718.774	34.8811
722.196	36.9106
725.618	39.83
729.037	43.102
732.456	46.0358
735.873	48.4863
739.289	52.5544
742.703	56.6165
746.116	58.9018
749.529	61.4674
752.938	64.1517
756.347	66.1198
759.756	68.2122
763.162	69.9976
766.567	71.0743
769.97	73.9444
773.372	74.9342
776.773	75.1267
780.174	74.7142
783.573	73.0948
786.97	74.3182
790.365	75.6026
793.76	76.1009
797.153	77.6613
800.543	77.8363
803.933	77.38
807.322	76.193
810.71	76.4265
814.097	77.9499
817.483	78.5852
820.865	78.9302
824.248	80.3034
827.629	80.4825
831.008	79.2319
834.387	80.217
837.765	77.5148
841.139	77.6413
844.514	76.6374
847.886	74.743
851.259	75.2791
854.629	72.6333
857.997	69.2374
861.366	66.8263
864.732	62.8934
868.098	62.0729
871.461	59.8133
874.823	56.1897
878.184	54.4068
881.545	50.7281
884.903	47.3044
888.26	43.5245
891.616	42.0016
894.97	43.8025
898.323	43.4565
901.675	44.1846
905.026	45.164
908.375	45.4886
911.723	45.4992
915.07	45.4202
918.415	46.3386
921.76	46.9272
925.103	47.3122
928.443	47.7156
931.783	46.911
935.123	45.9562
938.461	45.0591
941.796	45.1119
945.131	42.7971
948.465	41.2906
951.797	40.9743
955.128	37.9353
958.457	33.8193
961.786	30.7573
965.113	28.4663
968.44	28.2462
971.763	28.5703
975.086	28.5456
978.409	28.8324
981.729	28.7401
985.048	28.1013
988.367	27.6287
991.683	27.0511
994.998	26.9457
998.312	25.3461
1001.62	25.2345
1004.94	24.0939
1008.25	25.0666
1011.56	25.1769
1014.86	25.1662
1018.17	25.3274
1021.48	26.0158
1024.78	24.9703
1028.08	24.8317
1031.38	23.4289
1034.68	21.9906
1037.98	18.744
1041.28	17.7702
1044.57	18.7803
1047.87	21.357
1051.16	21.0781
1054.45	21.0882
1057.75	21.5602
1061.04	21.4866
1064.32	20.3985
1067.61	19.4809
1070.9	20.126
1074.18	20.3755
1077.47	19.6251
1080.75	19.7114
1084.03	19.9281
1087.31	20.8301
1090.59	22.1806
1093.86	23.9653
1097.14	24.689
1100.41	25.8715
1103.69	27.2736
1106.96	28.3065
1110.23	27.6295
1113.5	27.1291
1116.77	25.4801
1120.03	24.661
1123.3	23.8093
1126.56	23.9514
1129.83	21.1248
1133.09	20.7169
1136.35	19.2412
1139.61	18.2452
1142.86	16.6115
1146.12	14.6302
1149.38	12.0175
1152.63	10.1128
1155.88	8.22877
1159.14	5.51815
1162.39	5.20542
1165.63	3.70058
1168.88	3.52728
1172.13	4.6877
1175.38	6.18071
1178.62	7.16309
1181.86	8.09024
1185.1	10.3208
1188.34	12.7641
1191.58	13.565
1194.82	13.6829
1198.06	15.4252
1201.29	17.1679
1204.53	18.9219
1207.76	21.3114
1210.99	22.9706
1214.22	25.2014
1217.45	26.1062
1220.68	27.9305
1223.91	27.012
1227.13	28.3188
1230.36	27.8435
1233.58	28.5279
1236.8	27.9077
1240.02	28.791
1243.24	29.5758
1246.46	30.4666
1249.67	31.844
1252.89	32.1129
1256.1	32.6448
1259.32	33.0558
1262.53	32.2406
1265.74	33.4273
1268.95	34.2294
1272.15	34.6385
1275.36	36.4896
1278.57	38.3617
1281.77	40.867
1284.97	43.5489
1288.18	46.1018
1291.38	47.8763
1294.58	50.7862
1297.78	53.9129
1300.97	55.8574
1304.17	59.3276
1307.36	62.7038
1310.55	65.8334
1313.75	68.2982
1316.94	70.5754
1320.13	72.5915
1323.32	73.4863
1326.5	73.4275
1329.69	71.5698
1332.87	71.7435
1336.06	68.6548
1339.24	66.1838
1342.42	63.0628
1345.6	60.6798
1348.78	59.1371
1351.96	57.6661
1355.13	54.6144
1358.31	53.5781
1361.48	51.2631
1364.65	49.127
1367.82	47.7195
1370.99	47.2232
1374.16	46.3645
1377.33	46.8967
1380.5	46.6943
1383.66	46.6781
1386.83	46.6138
1389.99	45.267
1393.15	44.2659
1396.31	43.1578
1399.47	42.352
1402.63	41.7736
1405.78	42.3499
1408.94	44.7643
1412.1	45.9613
1415.25	46.3996
1418.4	46.8032
1421.55	48.4033
1424.7	51.723
1427.85	55.2665
1431	56.495
1434.14	58.3195
1437.29	61.0809
1440.43	63.9301
1443.57	66.4676
1446.71	67.9349
1449.85	67.7617
1452.99	67.1261
1456.13	65.508
1459.26	62.5873
1462.4	60.1412
1465.54	57.0576
1468.67	52.4576
1471.8	47.0632
1474.93	42.6677
1478.06	38.2644
1481.19	34.1544
1484.31	29.6556
1487.44	25.9702
1490.56	22.4303
1493.69	18.5848
1496.81	15.8826
1499.93	14.5175
1503.05	13.3883
1506.17	11.3108
1509.28	11.5875
1512.4	13.423
1515.52	13.9903
1518.63	14.3355
1521.74	15.3331
1524.85	16.9539
1527.96	18.4875
1531.07	19.4711
1534.18	21.8376
1537.29	22.4846
1540.39	23.632
1543.5	26.0145
1546.6	26.9079
1549.7	29.2421
1552.8	31.7698
1555.9	34.9181
1559	37.5693
1562.1	41.3792
1565.19	44.6738
1568.29	46.5816
1571.38	49.1861
1574.47	51.3852
1577.56	53.4789
1580.66	55.4026
1583.74	57.6905
1586.83	59.9815
1589.92	60.0984
1593.01	60.3281
1596.09	59.4542
1599.17	59.1419
1602.25	58.2218
1605.34	55.5754
1608.41	54.5879
1611.49	52.6136
1614.57	51.1077
1617.65	49.7998
1620.72	49.4409
1623.79	48.838
1626.87	48.8581
1629.94	48.9005
1633.01	51.7293
1636.08	52.3583
1639.15	54.942
1642.21	55.3171
1645.28	56.3702
1648.34	57.0946
1651.41	57.3881
1654.47	56.0666
1657.53	54.7592
1660.59	52.9738
1663.65	50.6553
1666.71	48.7507
1669.76	46.1717
1672.82	44.2581
1675.87	42.151
1678.93	38.1539
1681.98	35.9068
1685.03	31.4971
1688.08	27.7149
1691.13	25.2168
1694.17	23.894
1697.22	20.5998
1700.27	17.802
1703.31	17.1204
1706.35	16.878
1709.39	16.8648
1712.43	16.4874
1715.47	16.8457
1718.51	15.7141
1721.55	14.9058
1724.58	12.9575
1727.62	11.1399
1730.65	9.59729
1733.68	9.49396
1736.72	8.43888
1739.74	8.3675
1742.77	6.91258
1745.8	7.54022
1748.83	6.67749
1751.85	5.26296
1754.88	4.28639
1757.9	3.60253
1760.92	2.66912
1763.95	3.21785
1766.96	3.52975
1769.98	2.85694
1773	2.09787
1776.02	2.36071
1779.03	2.33866
1782.05	2.95257
1785.06	3.27053
1788.07	3.24695
1791.08	2.78427
1794.09	3.1651
1797.1	2.65007
1800.11	2.00645
1803.12	1.40684
1806.12	1.19424
1809.12	0.255581
1812.13	1.01725
1815.13	0.799703
1818.13	0.464863
1821.13	0.803953
1824.13	0.760666
1827.13	0.371782
1830.12	-0.495392
1833.12	0.449229
1836.11	1.15724
1839.1	1.95552
1842.09	1.7254
1845.09	1.51827
1848.08	1.49249
1851.06	2.35934
1854.05	2.67817
1857.04	3.12755
1860.02	4.3359
1863.01	4.56786
1865.99	5.41854
1868.97	6.19411
1871.95	5.9228
1874.93	6.34794
1877.91	6.05283
1880.89	5.57245
1882.46	5.25127
1885.45	4.7372
1888.43	4.97506
1891.42	4.54563
1894.41	4.08652
1897.39	3.07906
1900.37	1.91786
1903.36	2.45269
1906.34	3.26574
1909.32	2.47031
1912.29	2.52173
1915.27	2.52136
1918.25	2.90192
1921.23	3.71734
1924.2	5.40464
1927.17	5.38916
1930.15	6.27586
1933.12	7.34302
1936.09	7.07971
1939.06	8.09916
1942.02	8.34429
1944.99	8.04447
1947.96	8.18803
1950.92	8.06355
1953.88	7.96649
1956.85	7.16405
1959.81	7.53633
1962.77	6.72764
1965.73	5.70436
1968.69	4.70859
1971.64	4.51227
1974.6	4.82545
1977.55	4.88685
1980.51	4.02139
1983.46	3.00542
1986.41	4.22043
1989.36	4.06514
1992.31	4.19762
1995.26	4.03562
1998.21	4.26099
2001.15	3.33638
2004.1	3.5059
2007.04	4.72381
2009.99	5.05778
2012.93	5.02336
2015.87	5.20312
2018.81	6.21392
2021.75	7.00198
2024.68	7.16367
2027.62	7.70102
2030.56	7.01544
2033.49	7.17849
2036.42	7.68098
2039.36	7.97321
2042.29	7.94271
2045.22	7.89727
2048.14	7.66012
2051.07	7.54321
2054	6.21738
2056.93	6.37282
2059.85	5.54643
2062.77	5.36686
2065.7	5.17423
2068.62	4.80723
2071.54	4.52094
2074.46	5.26304
2077.38	6.51098
2080.29	6.39164
2083.21	6.74547
2086.12	6.59645
2089.04	7.05052
2091.95	7.6968
2094.86	7.02974
2097.77	7.19115
2100.68	7.13605
2103.59	6.0761
2106.5	6.20162
2109.41	5.85784
2112.31	5.63732
2115.21	3.97039
2118.12	2.8386
2121.02	1.6283
2123.92	1.21258
2126.82	1.54745
2129.72	1.18586
2132.62	1.11103
2135.51	1.56325
2138.41	2.27822
2141.31	2.07631
2144.2	2.18215
2147.09	3.52732
2149.98	4.19523
2152.87	4.81828
2155.76	6.01638
2158.65	6.75498
2161.54	7.54336
2164.43	8.43542
2167.31	8.81373
2170.2	9.48917
2173.08	9.28176
2175.96	8.98937
2178.84	9.31985
2181.72	8.71083
2184.6	7.39908
2187.48	6.33029
2190.36	6.27974
2193.23	6.14211
2196.11	6.25106
2198.98	5.29611
2201.85	4.55403
2204.72	4.74886
2207.59	4.66943
2210.46	3.98689
2213.33	2.71289
2216.2	2.66661
2219.07	4.06142
2221.93	4.46591
2224.8	4.61473
2227.66	3.80729
2230.52	5.06883
2233.39	4.48128
2236.25	4.66138
2239.1	4.25896
2241.96	4.17154
2244.82	5.08426
2247.68	4.44796
2250.53	4.00914
2253.38	3.97767
2256.24	2.63499
2259.09	1.75762
2261.94	2.447
2264.79	1.79962
2267.64	0.958662
2270.49	1.19407
2273.33	0.956464
2276.18	-0.102797
2279.02	-0.0742378
2281.87	-0.175149
2284.71	0.26
2287.55	0.140934
2290.39	0.418645
2293.23	-0.419
2296.07	0.204584
2298.91	2.25809
2301.74	3.40904
2304.58	3.89504
2307.41	3.99004
2310.25	5.35235
2313.08	6.25917
2315.91	6.40888
2318.74	5.93768
2321.57	6.26658
2324.4	6.09613
2327.23	6.24027
2330.05	7.70385
2332.88	8.16478
2335.7	7.44946
2338.52	7.08696
2341.35	5.88984
2344.17	4.88917
2346.99	3.96978
2349.81	3.76562
2352.62	4.39777
2355.44	3.23806
2358.26	2.81946
2361.07	2.73001
2363.89	3.71138
2366.7	4.40447
2369.51	4.36486
2372.32	3.86481
2375.13	3.26807
2377.94	3.42553
2380.75	3.79236
2383.56	3.16616
2386.36	2.72224
2389.17	2.01022
2391.97	2.34467
2394.77	2.99907
2397.58	3.07827
2400.38	1.79412
2403.18	2.50375
2405.97	2.49667
2408.77	3.108
2411.57	3.3666
2414.37	3.73826
2417.16	5.18696
2419.95	6.97095
2422.75	8.06225
2425.54	8.11033
2428.33	8.1939
2431.12	8.88381
2433.91	9.54352
2436.7	9.20455
2439.48	9.52254
2442.27	9.58204
2445.05	10.2082
2447.84	9.59126
2450.62	8.22557
2453.4	6.28479
2456.18	6.0055
2458.96	5.01456
2461.74	3.69981
2464.52	3.20176
2467.29	1.48545
2470.07	0.966839
2472.85	1.43551
2475.62	1.22325
2478.39	0.529953
2481.16	0.242334
2483.93	-0.0140481
2486.7	0.890793
2489.47	1.28808
2492.24	1.09872
2495.01	-0.0689894
2497.77	1.32336
2500.54	1.37538
2503.3	1.1814
2506.06	1.40748
2508.83	1.94595
2511.59	1.51975
2514.35	2.30036
2517.11	1.63248
2519.86	2.39356
2522.62	3.44769
2525.38	3.24668
2528.13	3.01096
2530.89	3.25666
2533.64	3.86663
2536.39	4.10189
2539.14	4.87112
2541.89	4.89185
2544.64	5.76482
2547.39	4.74021
2550.14	5.30803
2552.88	5.42847
2555.63	6.63671
2558.37	6.65935
2561.11	7.8321
2563.86	8.31064
2566.6	8.60468
2569.34	7.86552
2572.08	7.52193
2574.82	7.79259
2577.55	7.34538
2580.29	7.6146
2583.02	8.0415
2585.76	7.49604
2588.49	6.56708
2591.22	6.46339
2593.96	6.23534
2596.69	5.73428
2599.42	5.63469
2602.14	5.84064
2604.87	5.06513
2607.6	4.24423
2610.32	2.8437
2613.05	2.3045
2615.77	2.29396
2618.49	3.34853
2621.22	3.10101
2623.94	3.95331
2626.66	5.17471
2629.37	5.17272
2632.09	5.20316
2634.81	4.73214
2637.53	5.48982
2640.24	5.77867
2642.96	6.71311
2645.67	6.55545
2648.38	6.67862
2651.09	6.2734
2653.8	5.99525
2656.51	7.62757
2659.22	6.96042
2661.93	6.73443
2664.63	7.17047
2667.34	7.60232
2670.04	7.65474
2672.75	6.97859
2675.45	7.01313
2678.15	8.02323
2680.85	8.76256
2683.55	8.80827
2686.25	7.82924
2688.94	8.37659
2691.64	8.38455
2694.34	9.10896
2697.03	8.51743
2699.73	8.10151
2702.42	8.65318
2705.11	9.19524
2707.8	8.79587
2710.49	8.82171
2713.18	8.1509
2715.87	8.19256
2718.55	8.88041
2721.24	9.41303
2723.93	9.24374
2726.61	9.50596
2729.29	9.70724
2731.98	10.0364
2734.66	10.1443
2737.34	10.8599
2740.02	10.9772
2742.7	11.6142
2745.37	11.5276
2748.05	10.4391
2750.72	10.0706
2753.4	9.16047
2756.07	8.82041
2758.75	8.11947
2761.42	7.16608
2764.09	6.13133
2766.76	5.83706
2769.43	5.06704
2772.1	3.76053
2774.76	3.73952
2777.43	3.67915
2780.1	3.5422
2782.76	3.31136
2785.42	2.90102
2788.09	2.81972
2790.75	1.75768
2793.41	1.32433
2796.07	1.27916
2798.73	1.2584
2801.39	0.368523
2804.04	1.34172
2806.7	1.5466
2809.35	1.95068
2812.01	2.12715
2814.66	2.83633
2817.31	3.94687
2819.96	4.80303
2822.61	7.70082
2825.26	9.59747
2827.91	12.4947
2830.56	14.8615
2833.21	18.162
2835.85	21.6037
2838.5	25.9136
2841.14	30.856
2843.78	35.3383
2846.42	40.0809
2849.06	45.5549
2851.71	52.0893
2854.34	58.7096
2856.98	65.2243
2859.62	71.2974
2862.26	76.8609
2864.89	81.9723
2867.53	88.6804
2870.16	94.4176
2872.79	99.704
2875.42	105.607
2878.05	110.402
2880.68	114.68
2883.31	119.321
2885.94	124.001
2888.57	127.803
2891.19	133.168
2893.82	137.201
2896.44	141.412
2899.07	146.333
2901.69	151.3
2904.31	156.462
2906.93	162.633
2909.55	169.233
2912.17	176.928
2914.79	183.888
2917.41	189.27
2920.02	194.279
2922.64	197.072
2925.25	199.819
2927.86	199.91
2930.48	199.744
2933.09	199.002
2935.7	195.448
2938.31	192.064
2940.92	187.289
2943.53	180.957
2946.13	175.207
2948.74	169.495
2951.34	162.143
2953.95	156.064
2956.55	149.947
2959.15	141.993
2961.75	135.362
2964.35	128.939
2966.95	122.175
2969.55	115.839
2972.15	110.497
2974.75	104.442
2977.34	99.2848
2979.94	91.9544
2982.53	85.3168
2985.13	79.1612
2987.72	71.0594
2990.31	63.308
2992.9	54.7324
2995.49	48.3827
2998.08	41.3804
3000.67	34.3896
3003.25	28.0872
3005.84	22.3822
3008.42	18.3636
3011.01	14.3024
3013.59	11.0468
3016.17	8.47673
3018.76	5.83229
3021.34	3.39536
3023.92	1.92979
3026.49	0.211254
3029.07	-1.02029
3031.65	-1.09494
3034.23	-0.646265
3036.8	0.352139
3039.38	1.47572
3041.95	2.72028
3044.52	3.74661
3047.09	5.29278
3049.66	5.04568
3052.23	5.45143
3054.8	6.21595
3057.37	6.82355
3059.94	7.39389
3062.5	7.48234
3065.07	6.74644
3067.63	7.03154
3070.2	7.07452
3072.76	7.17664
3075.32	6.82483
3077.88	5.36996
3080.44	5.19288
3083	4.17266
3085.56	3.30334
3088.12	1.74844
3090.67	0.535873
3093.23	0.469632
3095.78	0.0253119
3098.34	0.142811
3100.89	1.10969
3103.44	1.4593
3105.99	1.43531
3108.54	2.12647
3111.09	2.74933
3113.64	3.78153
3116.19	5.18012
3118.74	5.91534
3121.28	7.37011
3123.83	9.43647
3126.37	11.1626
3128.91	12.586
3131.46	14.8805
3134	16.7134
3136.54	18.4348
3139.08	19.7992
3141.62	21.2289
3144.16	22.7674
3146.69	24.0767
3149.23	26.5245