File: data/Raman/poly_smoothed/Thy_00_07_48_1x_45s_532 nm_x100_100%_600 gr_mm_01_0.txt
#Acq. time (s)=	45
#Accumulations=	2
#Range (cm-¹)=	200...3150
#Windows=	2
#Auto scanning=	Off
#Autofocus=	Off
#Macrospot=	Off
#AutoExposure=	Off
#Spike filter=	Multiple accum.
#Delay time (s)=	0
#Binning=	1
#Readout mode=	Signal
#DeNoise=	Off
#ICS correction=	On
#Dark correction=	Off
#Inst. Process=	Off
#Detector Gain=	Best Dynamic Range
#Detector ADC=	20 kHz
#Detector temperature (°C)=	-69.85
#Instrument=	LabRAM HR Evol
#Detector=	Synapse
#Objective=	x100
#Grating=	600 gr/mm
#ND Filter=	100%
#Laser (nm)=	532
#Hole=	100.021
#Range=	Auto
#Laser Pol.=	No
#Raman. Pol.=	No
#Laser Pol. (°)=	-0.0007625
#Raman Pol. (°)=	89.9995
#Collection=	Microscope
#StageXY=	Marzhauser
#StageZ=	Marzhauser
#X (µm)=	-1425
#Y (µm)=	-629.1
#Z (µm)=	-228
#Full time(mm:ss)=	3:18
#Project=
#Sample=
#Site=
#Title=	Thy_00_07_48_2x_45s_532 nm_x100_100%_600 gr_mm
#Remark=
#Date=	29.06.2022 09:53
#Acquired=	29.06.2022 09:53:07
#Base:Fit=	10.08.2022 10:07:56
#Base:Sub=	10.08.2022 10:08:40
#Filter:Polynom=	16.08.2022 10:26:06
#AxisType[0]=Intens
#AxisUnit[0]=Cnt
#AxisType[1]=Spectr
#AxisUnit[1]=1/cm
200.523	5.48011
204.154	9.0695
207.781	8.97842
211.409	8.56708
215.034	7.48092
218.659	7.23248
222.281	5.87527
225.903	5.88622
229.522	6.27025
233.14	5.0575
236.756	4.10776
240.373	5.37447
243.986	5.09981
247.598	3.9933
251.208	2.44596
254.818	1.06072
258.427	1.33831
262.034	3.76723
265.638	4.72575
269.242	5.43781
272.844	6.67365
276.445	7.4496
280.044	7.52865
283.642	7.51069
287.238	7.84643
290.833	8.63501
294.425	9.16301
298.017	9.79026
301.608	10.4669
305.198	11.0731
308.786	11.7897
312.371	15.0047
315.956	15.6586
319.54	15.7558
323.122	17.2869
326.701	18.2706
330.281	18.5721
333.857	16.5525
337.434	16.2162
341.008	15.1595
344.582	15.74
348.153	15.8708
351.724	15.345
355.292	14.6232
358.861	14.8545
362.426	13.7427
365.99	14.4028
369.555	13.6283
373.116	13.1115
376.676	12.066
380.236	12.0612
383.793	11.7241
387.349	10.7079
390.903	9.58867
394.456	9.66126
398.007	9.9329
401.56	8.14098
405.108	7.44536
408.656	7.83727
412.202	7.18315
415.746	6.76812
419.29	5.95585
422.831	5.09867
426.37	4.10822
429.909	2.81832
433.447	2.0125
436.983	2.83439
440.519	3.07388
444.052	4.7257
447.583	4.78496
451.114	5.23611
454.643	6.58852
458.169	8.35259
461.696	8.49422
465.222	10.0545
468.744	11.8083
472.267	11.874
475.787	13.2512
479.307	15.8544
482.823	18.4772
486.341	19.6614
489.855	20.8939
493.37	23.1703
496.881	24.664
500.391	24.8949
503.902	23.3196
507.409	22.3647
510.915	20.8036
514.42	17.9246
517.925	16.7911
521.427	15.0735
524.928	13.7979
528.427	13.7458
531.925	13.0823
535.422	10.0544
538.917	9.00567
542.411	9.3769
545.903	8.37881
549.395	7.88827
552.884	9.26651
556.373	8.2822
559.86	8.2233
563.346	9.90944
566.831	11.0565
570.314	9.306
573.794	10.0763
577.274	9.50957
580.754	8.94992
584.23	7.87758
587.706	6.18396
591.181	3.68833
594.653	3.69297
598.126	2.96213
601.595	3.39439
605.065	3.23758
608.532	4.28873
611.999	5.58037
615.463	5.8719
618.928	7.29165
622.389	7.48845
625.851	7.46583
629.31	8.66518
632.767	9.0004
636.223	10.2705
639.68	9.74878
643.134	9.85819
646.586	10.5717
650.037	13.1879
653.486	14.2046
656.936	15.8805
660.383	16.0469
663.829	16.2436
667.273	17.5773
670.716	18.4022
674.158	18.7561
677.598	20.6299
681.035	21.9779
684.473	23.3882
687.909	22.7436
691.344	23.4242
694.778	25.6937
698.211	27.8352
701.64	28.184
705.07	27.7281
708.498	29.1209
711.924	30.1329
715.35	31.2987
718.774	30.7975
722.196	31.5241
725.618	32.1099
729.037	35.5516
732.456	37.6115
735.873	39.6607
739.289	41.9297
742.703	42.8179
746.116	44.6039
749.529	47.7325
752.938	51.0485
756.347	53.3983
759.756	56.1349
763.162	59.1914
766.567	61.6706
769.97	63.9089
773.372	65.4954
776.773	67.4007
780.174	68.8367
783.573	70.0675
786.97	71.2833
790.365	72.5481
793.76	73.2061
797.153	74.4921
800.543	73.3591
803.933	73.097
807.322	71.5126
810.71	70.2936
814.097	69.2971
817.483	67.1002
820.865	65.5491
824.248	64.1891
827.629	63.6509
831.008	63.0398
834.387	62.5547
837.765	62.2927
841.139	61.4704
844.514	60.3267
847.886	58.1807
851.259	56.5889
854.629	55.4307
857.997	53.5503
861.366	51.6689
864.732	50.7552
868.098	50.5074
871.461	50.2065
874.823	50.5853
878.184	51.0607
881.545	48.9434
884.903	48.867
888.26	48.0704
891.616	46.93
894.97	46.48
898.323	48.0625
901.675	47.6985
905.026	48.3314
908.375	48.0163
911.723	47.8067
915.07	48.6397
918.415	47.2647
921.76	46.7647
925.103	44.4197
928.443	41.948
931.783	40.5516
935.123	40.1197
938.461	37.9113
941.796	34.7638
945.131	33.0263
948.465	32.1479
951.797	32.7786
955.128	31.7156
958.457	30.7473
961.786	30.4078
965.113	30.1483
968.44	31.7062
971.763	31.1678
975.086	31.396
978.409	33.712
981.729	33.1933
985.048	31.4779
988.367	31.1229
991.683	30.329
994.998	30.0943
998.312	28.9823
1001.62	28.8593
1004.94	28.4409
1008.25	27.7346
1011.56	27.4457
1014.86	27.4835
1018.17	26.3308
1021.48	25.7352
1024.78	25.289
1028.08	24.9011
1031.38	24.3075
1034.68	22.6512
1037.98	21.5504
1041.28	21.1602
1044.57	21.435
1047.87	21.3167
1051.16	19.7327
1054.45	18.5247
1057.75	17.1038
1061.04	16.2785
1064.32	13.3993
1067.61	12.7872
1070.9	11.8373
1074.18	11.6759
1077.47	11.4916
1080.75	11.8313
1084.03	12.4662
1087.31	10.9509
1090.59	11.8893
1093.86	12.6503
1097.14	12.7709
1100.41	13.557
1103.69	13.3496
1106.96	11.8659
1110.23	11.0332
1113.5	10.4136
1116.77	8.98199
1120.03	8.52137
1123.3	7.83725
1126.56	8.23095
1129.83	7.83259
1133.09	7.21996
1136.35	7.46252
1139.61	6.95636
1142.86	5.93355
1146.12	4.40985
1149.38	3.73207
1152.63	3.01157
1155.88	2.17489
1159.14	1.32936
1162.39	2.11869
1165.63	2.84658
1168.88	3.8707
1172.13	4.45049
1175.38	5.18708
1178.62	6.0169
1181.86	6.48205
1185.1	6.5605
1188.34	6.43657
1191.58	7.56241
1194.82	9.96213
1198.06	12.637
1201.29	13.6177
1204.53	16.9272
1207.76	19.705
1210.99	21.4649
1214.22	22.4502
1217.45	26.0207
1220.68	28.5568
1223.91	30.5664
1227.13	33.159
1230.36	34.0188
1233.58	36.4698
1236.8	37.4243
1240.02	39.1674
1243.24	40.0356
1246.46	40.6805
1249.67	40.5215
1252.89	41.3754
1256.1	42.0586
1259.32	40.4987
1262.53	39.5499
1265.74	40.0299
1268.95	38.8728
1272.15	39.0938
1275.36	38.3419
1278.57	39.2466
1281.77	40.8959
1284.97	43.2366
1288.18	43.2854
1291.38	45.9635
1294.58	48.74
1297.78	51.4841
1300.97	54.1174
1304.17	57.3754
1307.36	59.1342
1310.55	61.6541
1313.75	63.9505
1316.94	64.4628
1320.13	65.5441
1323.32	68.2075
1326.5	69.7301
1329.69	70.5713
1332.87	70.4288
1336.06	69.0872
1339.24	67.3422
1342.42	63.8909
1345.6	61.4589
1348.78	57.7138
1351.96	55.9454
1355.13	50.8621
1358.31	49.8695
1361.48	49.0149
1364.65	48.2678
1367.82	47.5091
1370.99	47.5038
1374.16	46.2074
1377.33	47.3466
1380.5	47.4873
1383.66	48.3626
1386.83	47.2194
1389.99	45.957
1393.15	44.8043
1396.31	43.8568
1399.47	43.8356
1402.63	44.7192
1405.78	44.6203
1408.94	46.0175
1412.1	45.6883
1415.25	46.8556
1418.4	48.004
1421.55	49.6944
1424.7	51.8057
1427.85	54.1454
1431	56.8617
1434.14	61.7291
1437.29	68.8461
1440.43	71.9367
1443.57	73.8269
1446.71	75.5133
1449.85	76.8938
1452.99	78.0472
1456.13	77.9036
1459.26	75.8443
1462.4	72.24
1465.54	66.7176
1468.67	61.3457
1471.8	56.052
1474.93	50.0257
1478.06	44.3582
1481.19	39.3545
1484.31	34.5638
1487.44	30.7463
1490.56	27.3352
1493.69	24.4243
1496.81	20.516
1499.93	19.0673
1503.05	17.3011
1506.17	15.4694
1509.28	14.6184
1512.4	14.5286
1515.52	13.672
1518.63	14.4811
1521.74	15.0829
1524.85	17.4032
1527.96	19.0852
1531.07	20.7074
1534.18	23.0017
1537.29	23.688
1540.39	24.7125
1543.5	26.7903
1546.6	27.8767
1549.7	29.8586
1552.8	32.0648
1555.9	36.0225
1559	39.2331
1562.1	41.8794
1565.19	45.7212
1568.29	49.4431
1571.38	50.5921
1574.47	54.0987
1577.56	56.1534
1580.66	57.9916
1583.74	60.6383
1586.83	62.3982
1589.92	63.2567
1593.01	65.0842
1596.09	66.9481
1599.17	65.4317
1602.25	65.8822
1605.34	64.5012
1608.41	63.2611
1611.49	61.4613
1614.57	60.2907
1617.65	59.1446
1620.72	58.6103
1623.79	57.8617
1626.87	58.9936
1629.94	59.7143
1633.01	60.3627
1636.08	60.937
1639.15	62.0993
1642.21	62.7625
1645.28	63.0219
1648.34	62.333
1651.41	63.0134
1654.47	64.2565
1657.53	64.2327
1660.59	63.5068
1663.65	62.3727
1666.71	60.8281
1669.76	59.5854
1672.82	57.3888
1675.87	53.3992
1678.93	51.1573
1681.98	46.9474
1685.03	44.8761
1688.08	41.3776
1691.13	37.8057
1694.17	34.182
1697.22	31.1907
1700.27	29.5464
1703.31	26.6138
1706.35	23.4746
1709.39	19.7922
1712.43	18.589
1715.47	15.2178
1718.51	12.9601
1721.55	11.2704
1724.58	9.87568
1727.62	9.17845
1730.65	9.01619
1733.68	7.93699
1736.72	7.12733
1739.74	6.79355
1742.77	6.58903
1745.8	7.19166
1748.83	5.33358
1751.85	5.80606
1754.88	5.98694
1757.9	5.79699
1760.92	5.66911
1763.95	4.95423
1766.96	3.89074
1769.98	5.96282
1773	6.4698
1776.02	5.93826
1779.03	5.5286
1782.05	5.43713
1785.06	5.59943
1788.07	5.90487
1791.08	6.55947
1794.09	6.12233
1797.1	6.22504
1800.11	6.07738
1803.12	6.52653
1806.12	5.90378
1809.12	6.1559
1812.13	5.46207
1815.13	5.71803
1818.13	5.31122
1821.13	5.04962
1824.13	4.99788
1827.13	4.41508
1830.12	4.68598
1833.12	4.08054
1836.11	3.75416
1839.1	3.75922
1842.09	4.28809
1845.09	3.74758
1848.08	4.03031
1851.06	3.91488
1854.05	3.62498
1857.04	2.81061
1860.02	2.60876
1863.01	2.72226
1865.99	3.05205
1868.97	1.73392
1871.95	2.16511
1874.93	1.41146
1877.91	1.5975
1880.89	1.44835
1882.46	1.62326
1885.45	2.03223
1888.43	2.81582
1891.42	3.76385
1894.41	4.47318
1897.39	4.72176
1900.37	5.12581
1903.36	5.77936
1906.34	5.31041
1909.32	4.56801
1912.29	5.42422
1915.27	6.15748
1918.25	7.25264
1921.23	6.78113
1924.2	6.52226
1927.17	5.87616
1930.15	5.57035
1933.12	6.59147
1936.09	7.10368
1939.06	6.66494
1942.02	5.40803
1944.99	5.686
1947.96	5.80291
1950.92	5.14803
1953.88	4.99335
1956.85	5.85722
1959.81	5.10864
1962.77	4.45595
1965.73	4.69489
1968.69	4.38564
1971.64	3.67228
1974.6	2.58739
1977.55	0.72064
1980.51	0.0525649
1983.46	-0.0283414
1986.41	1.02744
1989.36	1.08803
1992.31	1.02688
1995.26	1.93779
1998.21	2.6485
2001.15	3.30454
2004.1	3.80289
2007.04	4.97951
2009.99	4.56576
2012.93	4.21181
2015.87	4.41137
2018.81	5.19354
2021.75	5.78136
2024.68	5.79149
2027.62	5.38367
2030.56	4.54633
2033.49	4.51022
2036.42	4.12869
2039.36	5.62894
2042.29	4.72249
2045.22	3.40857
2048.14	2.54278
2051.07	2.60673
2054	3.00465
2056.93	3.22244
2059.85	3.33438
2062.77	3.24783
2065.7	3.83136
2068.62	4.18167
2071.54	4.44909
2074.46	4.71985
2077.38	4.69734
2080.29	4.7075
2083.21	4.6505
2086.12	4.21878
2089.04	4.80668
2091.95	4.42038
2094.86	3.94533
2097.77	3.69433
2100.68	3.3479
2103.59	3.44114
2106.5	4.02205
2109.41	4.8279
2112.31	5.12666
2115.21	3.5184
2118.12	4.26239
2121.02	4.38698
2123.92	4.56559
2126.82	3.98447
2129.72	4.40522
2132.62	5.52427
2135.51	5.88659
2138.41	5.94745
2141.31	6.10264
2144.2	7.17324
2147.09	8.33649
2149.98	8.50885
2152.87	9.02548
2155.76	8.86907
2158.65	8.93112
2161.54	8.33838
2164.43	8.50155
2167.31	8.53147
2170.2	9.13629
2173.08	8.97318
2175.96	8.19327
2178.84	8.0585
2181.72	7.87712
2184.6	7.37356
2187.48	7.84658
2190.36	7.67625
2193.23	7.78944
2196.11	6.78806
2198.98	6.65284
2201.85	6.58495
2204.72	6.32183
2207.59	5.41804
2210.46	4.90547
2213.33	5.64702
2216.2	5.40477
2219.07	5.93561
2221.93	6.05711
2224.8	5.01464
2227.66	4.51638
2230.52	4.31605
2233.39	4.74247
2236.25	5.45391
2239.1	5.30767
2241.96	4.35369
2244.82	4.50051
2247.68	5.23346
2250.53	6.22735
2253.38	6.68108
2256.24	6.44863
2259.09	6.72997
2261.94	7.05923
2264.79	6.98277
2267.64	6.10464
2270.49	6.20025
2273.33	5.54213
2276.18	5.98584
2279.02	5.56434
2281.87	5.41621
2284.71	5.52982
2287.55	6.20205
2290.39	6.48407
2293.23	6.42232
2296.07	7.33333
2298.91	8.78205
2301.74	9.44417
2304.58	11.4938
2307.41	11.3144
2310.25	10.7029
2313.08	10.4584
2315.91	10.8046
2318.74	10.4928
2321.57	9.55072
2324.4	8.6026
2327.23	8.65198
2330.05	8.21784
2332.88	7.41515
2335.7	6.25966
2338.52	5.83182
2341.35	4.70282
2344.17	4.00567
2346.99	2.41968
2349.81	0.971051
2352.62	-0.433673
2355.44	0.642201
2358.26	1.22869
2361.07	0.752428
2363.89	1.49549
2366.7	3.0329
2369.51	3.38517
2372.32	4.03851
2375.13	4.30976
2377.94	4.06837
2380.75	3.36074
2383.56	3.75625
2386.36	3.97815
2389.17	3.74545
2391.97	4.44834
2394.77	4.96574
2397.58	5.0061
2400.38	5.05445
2403.18	5.12059
2405.97	5.86663
2408.77	5.48658
2411.57	5.67672
2414.37	5.81203
2417.16	5.45255
2419.95	5.67051
2422.75	5.36789
2425.54	5.36384
2428.33	5.50201
2431.12	4.71717
2433.91	4.53752
2436.7	4.89864
2439.48	5.16319
2442.27	5.43706
2445.05	5.29179
2447.84	4.21469
2450.62	4.01672
2453.4	3.73931
2456.18	3.3473
2458.96	3.73969
2461.74	3.16799
2464.52	3.39242
2467.29	4.3054
2470.07	4.71287
2472.85	4.08406
2475.62	3.73707
2478.39	3.69246
2481.16	3.83394
2483.93	3.95173
2486.7	3.95136
2489.47	4.38796
2492.24	3.66426
2495.01	4.31319
2497.77	4.63441
2500.54	4.29639
2503.3	5.724
2506.06	5.73843
2508.83	6.29444
2511.59	6.23772
2514.35	5.54385
2517.11	5.91898
2519.86	5.565
2522.62	6.93108
2525.38	6.36583
2528.13	6.07592
2530.89	6.06361
2533.64	6.43796
2536.39	4.94142
2539.14	4.31471
2541.89	4.75153
2544.64	5.58357
2547.39	5.85442
2550.14	6.39895
2552.88	6.46302
2555.63	6.51177
2558.37	7.21139
2561.11	7.72661
2563.86	7.99041
2566.6	8.17999
2569.34	8.37302
2572.08	8.29877
2574.82	7.6141
2577.55	7.89869
2580.29	7.89528
2583.02	8.26581
2585.76	8.17867
2588.49	7.62596
2591.22	7.36679
2593.96	7.51169
2596.69	6.87797
2599.42	6.62506
2602.14	6.5617
2604.87	6.22666
2607.6	6.42645
2610.32	5.2832
2613.05	3.77232
2615.77	3.46013
2618.49	3.01276
2621.22	3.69224
2623.94	2.91459
2626.66	2.32973
2629.37	1.78606
2632.09	1.52955
2634.81	1.51134
2637.53	1.43736
2640.24	0.976083
2642.96	1.97873
2645.67	2.45914
2648.38	2.62578
2651.09	3.27101
2653.8	3.82672
2656.51	4.22787
2659.22	4.83279
2661.93	5.81464
2664.63	5.79662
2667.34	6.43412
2670.04	6.90536
2672.75	6.79173
2675.45	6.60696
2678.15	7.149
2680.85	7.88371
2683.55	8.12954
2686.25	8.29775
2688.94	9.06169
2691.64	9.37636
2694.34	9.72564
2697.03	9.70164
2699.73	10.0982
2702.42	9.25571
2705.11	9.20584
2707.8	9.68595
2710.49	10.0632
2713.18	10.5335
2715.87	11.3378
2718.55	11.912
2721.24	12.1563
2723.93	12.0697
2726.61	12.0682
2729.29	11.4902
2731.98	10.1309
2734.66	9.32283
2737.34	8.6894
2740.02	7.65419
2742.7	7.24439
2745.37	6.81199
2748.05	5.91865
2750.72	4.31718
2753.4	4.15054
2756.07	3.97448
2758.75	2.6532
2761.42	1.04717
2764.09	0.425122
2766.76	0.0888215
2769.43	-0.484323
2772.1	-0.0406428
2774.76	-1.22457
2777.43	-0.693561
2780.1	0.574958
2782.76	1.085
2785.42	2.37017
2788.09	1.54669
2790.75	1.69499
2793.41	0.952662
2796.07	0.829435
2798.73	1.10911
2801.39	1.79483
2804.04	1.35384
2806.7	1.27973
2809.35	1.5948
2812.01	1.28066
2814.66	0.580069
2817.31	1.56742
2819.96	3.30288
2822.61	4.00077
2825.26	5.21922
2827.91	7.63057
2830.56	10.2313
2833.21	12.5851
2835.85	15.6166
2838.5	18.7749
2841.14	22.9373
2843.78	27.3742
2846.42	33.2505
2849.06	39.4079
2851.71	46.8281
2854.34	53.3449
2856.98	60.299
2859.62	67.3788
2862.26	75.5862
2864.89	82.3724
2867.53	89.0704
2870.16	94.2501
2872.79	98.8654
2875.42	103.068
2878.05	106.34
2880.68	110.21
2883.31	114.627
2885.94	118.131
2888.57	122.256
2891.19	125.744
2893.82	127.993
2896.44	131.46
2899.07	134.679
2901.69	138.771
2904.31	143.625
2906.93	150.339
2909.55	157.77
2912.17	165.738
2914.79	174.093
2917.41	181.728
2920.02	187.758
2922.64	193.096
2925.25	196.877
2927.86	199.649
2930.48	200.837
2933.09	199.473
2935.7	196.199
2938.31	192.999
2940.92	188.585
2943.53	183.288
2946.13	178.796
2948.74	172.754
2951.34	166.849
2953.95	160.019
2956.55	152.238
2959.15	145.712
2961.75	140.046
2964.35	134.528
2966.95	128.763
2969.55	124.064
2972.15	119.429
2974.75	114.049
2977.34	107.741
2979.94	101.51
2982.53	94.3075
2985.13	87.5709
2987.72	80.3326
2990.31	72.9623
2992.9	65.8316
2995.49	57.6927
2998.08	50.2485
3000.67	43.5166
3003.25	37.1228
3005.84	31.3208
3008.42	26.5237
3011.01	22.3539
3013.59	18.0975
3016.17	15.4449
3018.76	11.7938
3021.34	9.21012
3023.92	7.48671
3026.49	6.09518
3029.07	4.69195
3031.65	4.05623
3034.23	3.8836
3036.8	3.7993
3039.38	3.62184
3041.95	4.03599
3044.52	5.8387
3047.09	6.71792
3049.66	7.395
3052.23	8.84121
3054.8	8.68641
3057.37	9.98426
3059.94	10.2753
3062.5	10.6779
3065.07	10.8546
3067.63	10.7974
3070.2	11.1689
3072.76	11.3063
3075.32	10.8155
3077.88	9.40787
3080.44	8.13951
3083	7.26272
3085.56	6.14792
3088.12	4.6963
3090.67	3.86514
3093.23	2.88581
3095.78	2.24138
3098.34	1.71987
3100.89	2.2761
3103.44	2.2458
3105.99	2.84869
3108.54	3.21293
3111.09	3.32935
3113.64	4.10855
3116.19	4.33922
3118.74	5.13378
3121.28	6.3345
3123.83	7.53076
3126.37	8.64193
3128.91	10.3257
3131.46	12.2457
3134	13.7532
3136.54	15.034
3139.08	16.4568
3141.62	17.7472
3144.16	19.043
3146.69	20.9832
3149.23	24.8397