File: data/Raman/poly_smoothed/Thy_10_08_12_1x_45s_532 nm_x100_100%_600 gr_mm_01.txt
#Acq. time (s)=	45
#Accumulations=	2
#Range (cm-¹)=	200...3150
#Windows=	2
#Auto scanning=	Off
#Autofocus=	Off
#Macrospot=	Off
#AutoExposure=	Off
#Spike filter=	Multiple accum.
#Delay time (s)=	0
#Binning=	1
#Readout mode=	Signal
#DeNoise=	Off
#ICS correction=	On
#Dark correction=	Off
#Inst. Process=	Off
#Detector Gain=	Best Dynamic Range
#Detector ADC=	20 kHz
#Detector temperature (°C)=	-69.85
#Instrument=	LabRAM HR Evol
#Detector=	Synapse
#Objective=	x100
#Grating=	600 gr/mm
#ND Filter=	100%
#Laser (nm)=	532
#Hole=	100.021
#Range=	Auto
#Laser Pol.=	No
#Raman. Pol.=	No
#Laser Pol. (°)=	-0.0007625
#Raman Pol. (°)=	89.9995
#Collection=	Microscope
#StageXY=	Marzhauser
#StageZ=	Marzhauser
#X (µm)=	2169.9
#Y (µm)=	1265.4
#Z (µm)=	442.25
#Full time(mm:ss)=	3:05
#Project=
#Sample=
#Site=
#Title=	Thy_10_08_12_2x_45s_532 nm_x100_100%_600 gr_mm
#Remark=
#Date=	05.07.2022 15:02
#Acquired=	05.07.2022 15:02:59
#Base:Fit=	10.08.2022 09:46:25
#Base:Sub=	10.08.2022 09:46:49
#Filter:Polynom=	16.08.2022 10:24:56
#AxisType[0]=Intens
#AxisUnit[0]=Cnt
#AxisType[1]=Spectr
#AxisUnit[1]=1/cm
200.43	21.2852
204.059	18.0352
207.688	17.0673
211.314	16.3407
214.941	13.9916
218.564	11.4103
222.186	11.3041
225.809	9.00202
229.428	9.69373
233.045	7.55666
236.663	6.1674
240.278	5.71541
243.891	4.63907
247.503	4.01725
251.116	3.61458
254.725	2.56496
258.333	2.95041
261.939	3.18572
265.544	3.69557
269.148	4.81355
272.75	4.6154
276.351	5.00299
279.95	6.0899
283.548	7.36783
287.144	7.54611
290.739	8.92619
294.333	10.2701
297.925	10.6291
301.514	11.2606
305.104	11.9435
308.692	13.5586
312.279	13.1437
315.862	13.3122
319.446	13.71
323.029	13.0308
326.608	13.2652
330.188	13.0286
333.766	13.6566
337.341	14.5055
340.917	15.2076
344.489	14.0066
348.062	13.5483
351.631	13.3975
355.201	12.7768
358.768	11.8724
362.333	10.4258
365.899	10.171
369.462	9.78091
373.023	9.68841
376.585	9.26222
380.143	8.86292
383.7	8.88223
387.256	9.73587
390.812	8.41912
394.365	8.22687
397.916	8.63236
401.467	8.68717
405.015	8.8674
408.563	8.79508
412.109	9.55439
415.654	10.1886
419.197	12.0411
422.739	13.8715
426.279	12.7235
429.819	11.3234
433.356	11.6378
436.891	9.84861
440.426	10.5483
443.96	10.0594
447.492	10.086
451.021	10.5581
454.551	10.8653
458.079	12.5237
461.604	11.571
465.13	12.6299
468.654	13.1826
472.175	14.7802
475.696	16.0794
479.215	16.7977
482.733	18.0473
486.249	18.559
489.765	19.0458
493.278	20.9514
496.789	22.9875
500.301	23.3033
503.81	23.5882
507.317	23.366
510.825	22.9031
514.33	22.2204
517.833	22.1609
521.335	21.7561
524.836	21.2683
528.335	21.8316
531.835	21.011
535.332	21.0083
538.827	20.8373
542.321	21.0578
545.814	20.5655
549.305	20.6207
552.795	20.9453
556.282	20.5927
559.769	19.8058
563.255	17.9781
566.739	16.9378
570.223	15.5635
573.705	13.459
577.183	12.5544
580.663	10.8199
584.141	8.45637
587.615	6.9536
591.09	4.77748
594.564	3.76882
598.035	1.97193
601.506	0.621098
604.974	0.506154
608.443	1.17567
611.908	2.28981
615.374	3.10994
618.837	4.34392
622.3	6.65948
625.761	9.74677
629.219	12.1916
632.677	13.8453
636.135	15.889
639.59	17.3782
643.043	18.2846
646.495	19.2631
649.948	21.1679
653.398	22.4905
656.846	23.304
660.293	24.3622
663.738	25.1738
667.183	26.6063
670.626	26.8224
674.067	25.3368
677.508	27.0167
680.947	28.2372
684.385	27.3868
687.821	27.9513
691.254	28.9664
694.688	30.3928
698.121	31.7108
701.552	33.1355
704.98	33.4924
708.409	36.1598
711.836	37.3656
715.26	39.3408
718.685	41.685
722.108	42.5006
725.528	43.9389
728.949	46.7194
732.367	49.1341
735.785	50.6619
739.2	51.6699
742.614	53.8556
746.028	55.8708
749.439	57.9787
752.849	59.9929
756.26	62.0502
759.667	64.047
763.073	65.9355
766.477	67.7053
769.883	68.8093
773.285	70.9871
776.686	72.2213
780.085	74.1132
783.484	74.9452
786.881	77.0879
790.276	79.3798
793.671	82.8305
797.064	86.1853
800.456	88.7933
803.846	88.8179
807.234	87.653
810.622	89.1021
814.008	91.8795
817.394	91.6276
820.778	93.3509
824.159	95.5257
827.541	95.1298
830.921	95.12
834.298	94.1955
837.676	93.0277
841.051	91.4179
844.426	89.4859
847.798	87.053
851.171	84.1438
854.54	81.2097
857.911	78.5931
861.278	74.2061
864.645	71.1807
868.01	68.9011
871.373	66.5368
874.735	65.4652
878.097	62.7694
881.457	60.1323
884.815	57.6607
888.172	56.5143
891.528	56.0994
894.882	57.0917
898.237	57.3093
901.589	55.8388
904.94	56.0802
908.289	55.4924
911.635	54.0362
914.982	54.7725
918.328	54.1132
921.672	53.4027
925.015	53.6799
928.357	52.4768
931.698	52.1245
935.035	49.9577
938.373	47.9552
941.71	45.9119
945.044	43.5577
948.378	43.2873
951.709	43.08
955.041	43.0824
958.372	40.9177
961.699	37.9509
965.027	38.6685
968.352	41.9785
971.676	43.5153
975	43.1902
978.322	44.6614
981.642	45.3453
984.962	46.7594
988.28	48.1181
991.596	48.29
994.911	49.2505
998.227	49.5502
1001.54	50.6117
1004.85	49.7639
1008.16	48.9968
1011.47	47.7239
1014.78	45.6
1018.08	43.7549
1021.39	41.7535
1024.69	39.5371
1028	36.4074
1031.3	34.0652
1034.6	31.8506
1037.9	28.5188
1041.19	24.777
1044.49	24.9259
1047.78	24.916
1051.08	24.657
1054.37	22.6215
1057.66	22.1259
1060.95	21.7122
1064.24	20.7767
1067.53	20.3803
1070.81	19.5091
1074.1	21.3706
1077.38	21.2663
1080.66	21.7354
1083.94	21.5603
1087.22	21.9041
1090.5	22.8321
1093.78	22.9361
1097.05	24.8682
1100.33	26.2093
1103.6	25.2778
1106.87	24.1391
1110.14	24.2425
1113.41	22.7653
1116.68	20.8192
1119.95	19.5282
1123.21	17.5134
1126.48	14.4035
1129.74	12.9392
1133	10.502
1136.26	8.8654
1139.52	6.81678
1142.78	6.02451
1146.04	5.27455
1149.29	4.19171
1152.55	2.58405
1155.8	1.40798
1159.05	-0.317435
1162.3	-0.647341
1165.55	0.753695
1168.8	2.38805
1172.05	4.16957
1175.29	7.32578
1178.54	9.42851
1181.78	11.0636
1185.02	12.1439
1188.26	13.7633
1191.5	15.8994
1194.74	16.8671
1197.97	19.4175
1201.21	23.0801
1204.44	24.6544
1207.68	27.3449
1210.91	32.3879
1214.14	34.897
1217.37	38.9807
1220.59	44.0436
1223.82	47.1049
1227.05	50.0333
1230.27	52.4684
1233.49	54.619
1236.72	56.7379
1239.94	58.8711
1243.16	60.7692
1246.37	61.3066
1249.59	61.9279
1252.8	61.8897
1256.02	62.1352
1259.23	63.3248
1262.44	62.3157
1265.66	61.7442
1268.86	60.6672
1272.07	60.7651
1275.28	61.4902
1278.48	62.2093
1281.69	64.2907
1284.89	64.929
1288.09	67.7319
1291.29	71.1502
1294.49	73.3016
1297.69	77.1678
1300.89	80.8684
1304.08	82.0134
1307.28	83.6329
1310.47	87.0761
1313.66	88.7
1316.85	89.4913
1320.04	90.1048
1323.23	89.0231
1326.42	87.6427
1329.61	85.5624
1332.79	84.1066
1335.97	82.564
1339.16	79.3394
1342.34	75.681
1345.52	71.4834
1348.7	69.175
1351.87	66.6414
1355.05	63.3131
1358.22	60.9852
1361.4	57.924
1364.57	56.2917
1367.74	53.2987
1370.91	50.9113
1374.08	48.5287
1377.25	47.0234
1380.41	44.0066
1383.58	41.4708
1386.74	42.1493
1389.91	41.8195
1393.07	39.6704
1396.23	38.0844
1399.39	36.9998
1402.55	37.2389
1405.7	36.0919
1408.86	36.9998
1412.01	37.9635
1415.17	40.2851
1418.32	44.2912
1421.47	49.7124
1424.62	55.1729
1427.77	62.0474
1430.91	69.0225
1434.06	74.2402
1437.2	79.9959
1440.35	85.4086
1443.49	89.2982
1446.63	90.9603
1449.77	92.2516
1452.91	91.294
1456.05	89.8349
1459.18	87.4412
1462.32	83.5203
1465.45	78.6416
1468.59	72.5332
1471.72	64.9216
1474.85	57.9548
1477.98	50.7536
1481.1	41.9758
1484.23	35.6959
1487.36	29.7165
1490.48	25.5959
1493.61	21.7892
1496.73	18.7445
1499.85	15.5769
1502.97	12.5621
1506.09	12.3045
1509.2	11.7605
1512.32	10.3776
1515.43	10.4463
1518.55	11.735
1521.66	12.5088
1524.77	13.4165
1527.88	14.3858
1530.99	16.6411
1534.1	18.08
1537.21	19.9546
1540.31	22.5245
1543.42	24.5923
1546.52	25.5271
1549.62	27.4765
1552.72	30.4192
1555.82	34.4239
1558.92	38.2059
1562.02	42.2299
1565.11	44.6225
1568.21	47.6823
1571.3	52.0002
1574.39	54.9592
1577.49	57.5098
1580.57	59.6017
1583.66	63.7772
1586.75	66.0276
1589.84	67.5419
1592.92	70.7786
1596.01	72.4129
1599.09	73.076
1602.17	73.0733
1605.25	72.852
1608.33	71.2315
1611.41	70.0575
1614.49	69.3188
1617.57	69.4827
1620.64	70.1654
1623.72	71.4764
1626.79	72.955
1629.86	76.068
1632.93	79.8911
1636	81.7625
1639.07	85.4315
1642.13	88.4687
1645.2	92.1446
1648.26	95.256
1651.33	97.3606
1654.39	98.9488
1657.45	100.818
1660.51	101.621
1663.57	101.96
1666.63	101.113
1669.68	98.7709
1672.74	93.6112
1675.79	86.757
1678.85	79.7264
1681.9	71.2347
1684.95	65.1371
1688	59.76
1691.05	53.3103
1694.09	46.6622
1697.14	39.7241
1700.18	32.7571
1703.23	28.5181
1706.27	23.5071
1709.31	18.917
1712.35	14.196
1715.39	11.3172
1718.43	7.74993
1721.47	6.12575
1724.5	5.5769
1727.54	5.17795
1730.57	5.01515
1733.61	5.9938
1736.64	6.85142
1739.67	7.51683
1742.7	6.67584
1745.72	5.67521
1748.75	4.17459
1751.77	3.61844
1754.8	4.40281
1757.82	4.48576
1760.84	4.74458
1763.87	4.03311
1766.89	3.25231
1769.91	1.98424
1772.92	1.48218
1775.94	0.746265
1778.95	0.446494
1781.97	-0.101459
1784.98	-0.071259
1787.99	-1.03243
1791.01	-1.85288
1794.01	-1.29668
1797.02	0.127967
1800.03	0.294237
1803.04	-0.386493
1806.04	0.0254252
1809.05	0.716686
1812.05	0.842709
1815.05	0.721712
1818.05	1.24018
1821.05	1.2155
1824.05	1.96439
1827.05	3.43297
1830.04	4.62179
1833.04	5.18605
1836.03	5.39563
1839.03	5.94336
1842.02	6.58903
1845.01	7.46809
1848	8.66904
1850.99	9.30745
1853.97	10.1896
1856.96	10.3496
1859.94	11.4025
1862.93	12.1838
1865.91	12.9532
1868.89	13.1019
1871.87	13.1455
1874.85	12.6821
1877.83	13.2891
1880.81	13.8606
1882.57	13.4256
1885.56	14.0534
1888.55	14.1865
1891.54	13.9117
1894.52	13.1774
1897.51	12.9542
1900.49	12.5847
1903.47	12.2773
1906.45	10.6695
1909.43	10.6781
1912.41	11.1562
1915.39	11.5856
1918.37	12.307
1921.34	12.7145
1924.32	14.2429
1927.29	14.162
1930.26	15.1483
1933.23	15.6535
1936.2	16.2197
1939.17	16.1344
1942.14	16.9969
1945.11	17.2717
1948.07	18.1355
1951.04	17.7508
1954	17.8033
1956.96	17.0164
1959.93	17.1226
1962.89	17.0203
1965.85	15.4153
1968.8	16.1325
1971.76	16.1139
1974.72	15.4051
1977.67	14.8199
1980.63	15.0066
1983.58	15.3591
1986.53	16.7794
1989.48	17.3352
1992.43	18.6128
1995.38	20.1538
1998.32	20.324
2001.27	21.3601
2004.22	22.1193
2007.16	22.6552
2010.1	23.377
2013.04	24.3122
2015.98	25.2922
2018.92	25.1046
2021.86	25.5159
2024.8	24.9507
2027.74	25.2235
2030.67	25.161
2033.61	24.9625
2036.54	24.7346
2039.47	24.1107
2042.4	24.2223
2045.33	23.5807
2048.26	22.9508
2051.19	23.3227
2054.12	23.466
2057.04	23.9228
2059.97	24.892
2062.89	26.1229
2065.81	27.2359
2068.73	28.0649
2071.65	29.4337
2074.57	30.1911
2077.49	30.9422
2080.41	32.3267
2083.32	33.0108
2086.24	33.7651
2089.15	33.636
2092.07	33.6649
2094.98	33.1919
2097.89	32.9405
2100.8	33.0851
2103.71	31.8549
2106.61	31.5019
2109.52	32.3703
2112.43	31.0107
2115.33	30.8926
2118.23	31.2126
2121.13	32.1797
2124.04	31.677
2126.94	32.7996
2129.83	33.8878
2132.73	35.6597
2135.63	36.7131
2138.53	38.2348
2141.42	40.3559
2144.31	42.8781
2147.21	43.7693
2150.1	45.3501
2152.99	47.8098
2155.88	49.1743
2158.77	49.9318
2161.65	50.8429
2164.54	52.3675
2167.43	54.2147
2170.31	55.1763
2173.19	55.6055
2176.07	56.2913
2178.96	56.5949
2181.84	56.0692
2184.72	55.2291
2187.59	54.5926
2190.47	53.8605
2193.35	52.562
2196.22	51.1989
2199.09	49.582
2201.97	49.1316
2204.84	47.3403
2207.71	44.9071
2210.58	43.6305
2213.45	42.97
2216.31	40.5013
2219.18	39.4241
2222.05	38.6937
2224.91	36.7962
2227.78	35.8447
2230.64	34.5367
2233.5	33.5908
2236.36	32.6056
2239.22	31.1865
2242.08	29.8216
2244.93	29.2913
2247.79	27.7661
2250.64	27.7071
2253.5	27.0109
2256.35	25.5413
2259.2	24.5191
2262.05	24.4963
2264.9	24.1237
2267.75	24.5803
2270.6	24.2997
2273.45	22.8764
2276.29	23.0405
2279.14	23.1175
2281.98	23.7384
2284.82	23.374
2287.66	22.2563
2290.5	22.9713
2293.34	21.7364
2296.18	20.7922
2299.02	21.5552
2301.86	21.5569
2304.69	20.5035
2307.53	21.1266
2310.36	21.2708
2313.19	21.8294
2316.02	21.4599
2318.85	22.0587
2321.68	21.6119
2324.51	20.6459
2327.34	20.1836
2330.16	18.9465
2332.99	19.1676
2335.81	18.6692
2338.64	18.9949
2341.46	17.6439
2344.28	16.8062
2347.1	16.3045
2349.92	14.6006
2352.74	12.9544
2355.55	12.1153
2358.37	10.5217
2361.19	9.63267
2364	8.27387
2366.81	8.50618
2369.62	8.34399
2372.44	8.13754
2375.24	8.03742
2378.05	7.79081
2380.86	7.45008
2383.67	6.61218
2386.47	6.5379
2389.28	7.23451
2392.08	7.80905
2394.89	7.25463
2397.69	7.45288
2400.49	7.01761
2403.29	8.67043
2406.09	9.0228
2408.88	8.83823
2411.68	8.5293
2414.48	8.96509
2417.27	9.23504
2420.06	8.74168
2422.86	8.79158
2425.65	7.99076
2428.44	8.58908
2431.23	8.61685
2434.02	8.05979
2436.81	8.11622
2439.59	8.62257
2442.38	7.8789
2445.16	7.44969
2447.95	6.26936
2450.73	4.91387
2453.51	3.96178
2456.29	5.17759
2459.07	5.11753
2461.85	3.80308
2464.63	3.27041
2467.4	3.107
2470.18	2.80724
2472.95	3.0038
2475.73	3.7621
2478.5	3.52062
2481.27	3.29672
2484.04	4.03159
2486.81	3.75927
2489.58	4.43914
2492.35	3.89814
2495.12	4.16191
2497.88	3.68457
2500.65	3.1357
2503.41	3.43362
2506.17	2.52847
2508.94	2.31946
2511.7	1.38412
2514.46	0.392066
2517.22	-0.290825
2519.97	0.0969845
2522.73	0.140239
2525.49	0.314025
2528.24	0.219936
2530.99	0.71151
2533.75	0.755588
2536.5	0.55566
2539.25	0.899656
2542	1.38042
2544.75	1.5894
2547.5	2.29586
2550.24	2.67138
2552.99	2.8203
2555.74	2.78258
2558.48	4.22192
2561.22	3.40026
2563.96	4.02141
2566.71	4.01957
2569.45	4.17507
2572.18	3.89147
2574.92	3.28782
2577.66	3.76435
2580.4	4.13064
2583.13	4.09592
2585.87	3.40028
2588.6	3.16632
2591.33	3.69774
2594.06	2.992
2596.79	2.92772
2599.52	2.97171
2602.25	2.27814
2604.98	2.59232
2607.71	1.72464
2610.43	1.83386
2613.16	2.01728
2615.88	1.03441
2618.6	1.05603
2621.32	0.877376
2624.04	0.828837
2626.76	0.539285
2629.48	-0.657051
2632.2	-1.06698
2634.92	-1.34082
2637.63	-2.39854
2640.35	-3.11152
2643.06	-2.83744
2645.77	-3.1963
2648.49	-4.31365
2651.2	-4.0523
2653.91	-3.08844
2656.62	-2.81955
2659.33	-2.2794
2662.03	-1.86372
2664.74	-0.941424
2667.44	-0.358697
2670.15	0.329923
2672.85	1.52531
2675.55	1.31784
2678.26	2.57756
2680.96	2.51633
2683.66	1.9444
2686.35	3.0668
2689.05	2.90933
2691.75	3.65728
2694.44	4.38926
2697.14	4.26878
2699.83	4.46398
2702.52	5.41535
2705.22	6.45796
2707.91	6.79068
2710.6	7.60462
2713.29	7.84963
2715.97	8.57428
2718.66	10.0736
2721.35	10.4381
2724.03	12.053
2726.72	13.3374
2729.4	14.1858
2732.08	14.1756
2734.76	14.3883
2737.44	14.3694
2740.12	14.141
2742.8	13.6883
2745.48	13.4898
2748.16	13.4764
2750.83	12.6368
2753.51	11.9719
2756.18	11.1105
2758.85	10.9085
2761.53	9.81806
2764.2	9.08678
2766.87	8.5892
2769.54	8.12699
2772.2	6.42358
2774.87	5.06976
2777.54	4.15759
2780.2	3.86011
2782.87	3.15773
2785.53	3.00251
2788.19	2.00559
2790.85	2.33249
2793.51	1.66516
2796.17	1.30562
2798.83	0.522671
2801.49	0.887715
2804.15	1.05699
2806.8	0.848227
2809.46	1.04092
2812.11	1.80335
2814.76	1.8611
2817.42	2.07874
2820.07	4.82834
2822.72	8.39082
2825.37	12.0895
2828.02	17.5325
2830.66	22.8756
2833.31	29.8938
2835.96	37.0299
2838.6	44.8542
2841.24	54.1637
2843.89	64.8461
2846.53	76.7584
2849.17	88.0255
2851.81	101.014
2854.45	114.707
2857.09	128.006
2859.72	141.911
2862.36	155.314
2865	167.517
2867.63	178.613
2870.26	189.668
2872.9	198.825
2875.53	208.383
2878.16	215.076
2880.79	220.803
2883.42	227.621
2886.05	234.508
2888.67	240.499
2891.3	245.395
2893.92	253.146
2896.55	260.321
2899.17	268.043
2901.79	277.59
2904.42	289.405
2907.04	302.58
2909.66	318.608
2912.27	334.553
2914.89	350.93
2917.51	366.435
2920.13	381.067
2922.74	394.508
2925.35	403.781
2927.97	411.128
2930.58	414.885
2933.19	415.292
2935.8	413.198
2938.41	407.244
2941.02	399.845
2943.63	388.452
2946.24	375.77
2948.84	362.066
2951.45	346.167
2954.05	329.85
2956.65	315.242
2959.26	299.949
2961.86	284.023
2964.46	269.835
2967.06	257.259
2969.66	244.395
2972.25	233.172
2974.85	222.678
2977.45	209.943
2980.04	198.944
2982.64	187.976
2985.23	176.015
2987.82	163.224
2990.41	150.465
2993	138.731
2995.59	126.617
2998.18	114.891
3000.77	104.869
3003.36	95.1865
3005.94	85.4232
3008.53	76.6743
3011.11	68.9683
3013.69	62.6709
3016.28	57.078
3018.86	52.6819
3021.44	48.8591
3024.02	44.5202
3026.6	42.2199
3029.18	39.5814
3031.75	38.2714
3034.33	36.7464
3036.9	36.7574
3039.48	35.8827
3042.05	36.1072
3044.62	38.6728
3047.19	39.0394
3049.77	40.3023
3052.34	40.6065
3054.9	40.994
3057.47	41.2758
3060.04	40.8224
3062.61	40.2203
3065.17	39.8527
3067.74	38.2254
3070.3	36.9557
3072.86	34.2973
3075.42	31.8523
3077.99	29.011
3080.54	25.651
3083.1	22.2438
3085.66	19.5541
3088.22	17.0976
3090.78	13.7898
3093.33	10.6955
3095.89	8.56741
3098.44	5.93876
3100.99	4.25189
3103.54	3.91121
3106.1	3.23891
3108.65	3.35862
3111.2	2.87819
3113.74	2.84398
3116.29	3.34813
3118.84	2.91959
3121.38	3.07563
3123.93	3.72204
3126.47	4.08213
3129.01	4.20284
3131.56	3.75442
3134.1	3.96602
3136.64	2.54753
3139.18	1.80081
3141.72	0.964423
3144.26	-0.0410258
3146.79	-2.73722
3149.33	-5.51643