File: data/Raman/poly_smoothed/Thy_40_11_36_1x_45s_532 nm_x100_100%_600 gr_mm_01.txt
#Acq. time (s)=	45
#Accumulations=	2
#Range (cm-¹)=	200...3150
#Windows=	2
#Auto scanning=	Off
#Autofocus=	Off
#Macrospot=	Off
#AutoExposure=	Off
#Spike filter=	Multiple accum.
#Delay time (s)=	0
#Binning=	1
#Readout mode=	Signal
#DeNoise=	Off
#ICS correction=	On
#Dark correction=	Off
#Inst. Process=	Off
#Detector Gain=	Best Dynamic Range
#Detector ADC=	20 kHz
#Detector temperature (°C)=	-69.85
#Instrument=	LabRAM HR Evol
#Detector=	Synapse
#Objective=	x100
#Grating=	600 gr/mm
#ND Filter=	100%
#Laser (nm)=	532
#Hole=	100.021
#Range=	Auto
#Laser Pol.=	No
#Raman. Pol.=	No
#Laser Pol. (°)=	-0.0007625
#Raman Pol. (°)=	89.9995
#Collection=	Microscope
#StageXY=	Marzhauser
#StageZ=	Marzhauser
#X (µm)=	229.8
#Y (µm)=	1674
#Z (µm)=	427.35
#Full time(mm:ss)=	3:18
#Project=
#Sample=
#Site=
#Title=	Thy_40_11_36_2x_45s_532 nm_x100_100%_600 gr_mm
#Remark=
#Date=	05.07.2022 12:34
#Acquired=	05.07.2022 12:34:19
#Base:Fit=	10.08.2022 10:01:35
#Base:Sub=	10.08.2022 10:01:52
#Filter:Polynom=	16.08.2022 10:21:53
#AxisType[0]=Intens
#AxisUnit[0]=Cnt
#AxisType[1]=Spectr
#AxisUnit[1]=1/cm
200.43	52.5552
204.059	51.1796
207.688	45.6854
211.314	39.4015
214.941	33.8537
218.564	30.8633
222.186	27.212
225.809	22.8383
229.428	20.183
233.045	18.9904
236.663	17.9668
240.278	18.4583
243.891	17.5928
247.503	17.8868
251.116	19.2917
254.725	19.5432
258.333	21.0062
261.939	22.9819
265.544	23.3006
269.148	23.5135
272.75	25.5301
276.351	26.0582
279.95	27.556
283.548	26.6518
287.144	25.5992
290.739	23.2975
294.333	22.1708
297.925	20.7751
301.514	21.7609
305.104	20.7691
308.692	20.5937
312.279	19.5348
315.862	18.9378
319.446	18.289
323.029	18.0024
326.608	18.9913
330.188	18.6569
333.766	19.1491
337.341	18.1417
340.917	19.2632
344.489	19.217
348.062	18.793
351.631	19.0645
355.201	17.441
358.768	18.1406
362.333	17.9637
365.899	17.9221
369.462	17.6285
373.023	18.0315
376.585	17.216
380.143	16.3098
383.7	16.1361
387.256	15.9243
390.812	14.5342
394.365	13.8523
397.916	12.8393
401.467	11.5705
405.015	9.65978
408.563	9.24704
412.109	9.0262
415.654	7.69672
419.197	6.34169
422.739	6.45292
426.279	4.73143
429.819	4.35405
433.356	3.02518
436.891	4.04232
440.426	5.10646
443.96	4.9769
447.492	5.66157
451.021	6.84902
454.551	6.90201
458.079	8.12538
461.604	8.66928
465.13	9.50034
468.654	9.39955
472.175	9.46251
475.696	10.6744
479.215	10.8551
482.733	12.7401
486.249	14.5543
489.765	15.1131
493.278	17.4888
496.789	18.8098
500.301	20.4502
503.81	21.3399
507.317	22.4135
510.825	22.4872
514.33	21.0143
517.833	20.6793
521.335	20.2159
524.836	20.6709
528.335	19.8343
531.835	16.784
535.332	16.0061
538.827	13.5025
542.321	11.6631
545.814	10.7865
549.305	10.1252
552.795	9.57675
556.282	8.54383
559.769	7.01337
563.255	6.50106
566.739	7.91962
570.223	8.35018
573.705	6.5426
577.183	7.134
580.663	7.72656
584.141	6.89949
587.615	7.03163
591.09	6.5497
594.564	6.71398
598.035	5.50782
601.506	5.93363
604.974	6.26658
608.443	8.60908
611.908	8.81705
615.374	7.97198
618.837	8.55354
622.3	9.72545
625.761	10.3762
629.219	12.4313
632.677	14.7422
636.135	17.0576
639.59	16.7286
643.043	16.8991
646.495	17.701
649.948	19.973
653.398	19.2791
656.846	18.1731
660.293	18.5069
663.738	19.334
667.183	19.2344
670.626	18.4556
674.067	21.0127
677.508	21.8708
680.947	23.2803
684.385	24.7869
687.821	26.7753
691.254	29.1332
694.688	29.8111
698.121	30.7752
701.552	33.6397
704.98	35.1357
708.409	37.6074
711.836	40.255
715.26	42.5978
718.685	43.1483
722.108	44.2954
725.528	44.6453
728.949	46.4354
732.367	48.5547
735.785	49.3835
739.2	49.8806
742.614	50.9847
746.028	51.5236
749.439	53.1675
752.849	54.0482
756.26	56.0531
759.667	57.8108
763.073	59.8189
766.477	61.0774
769.883	62.4939
773.285	64.9388
776.686	67.4261
780.085	69.3242
783.484	71.5694
786.881	72.8361
790.276	75.746
793.671	78.3677
797.064	80.7858
800.456	80.63
803.846	83.7882
807.234	85.9081
810.622	86.8456
814.008	86.0907
817.394	85.8304
820.778	84.6264
824.159	83.3882
827.541	82.3139
830.921	80.5929
834.298	78.271
837.676	76.1812
841.051	74.059
844.426	72.4041
847.798	69.707
851.171	67.1909
854.54	65.874
857.911	62.9692
861.278	61.304
864.645	58.6835
868.01	55.1166
871.373	53.3409
874.735	52.9255
878.097	51.4444
881.457	51.4545
884.815	49.7
888.172	49.3262
891.528	46.0142
894.882	44.2782
898.237	43.3751
901.589	42.7541
904.94	41.319
908.289	40.2151
911.635	40.2774
914.982	41.305
918.328	41.8405
921.672	42.8076
925.015	43.2413
928.357	43.6461
931.698	44.5087
935.035	44.4269
938.373	44.5008
941.71	42.9784
945.044	40.9597
948.378	38.3676
951.709	38.6937
955.041	38.3588
958.372	36.8476
961.699	35.1
965.027	32.6296
968.352	29.6972
971.676	27.9309
975	24.9561
978.322	24.7876
981.642	23.589
984.962	21.9531
988.28	20.8164
991.596	21.2609
994.911	22.3483
998.227	22.0603
1001.54	20.8409
1004.85	21.4005
1008.16	21.7406
1011.47	21.0935
1014.78	20.9229
1018.08	21.9425
1021.39	21.6331
1024.69	20.3087
1028	20.3022
1031.3	22.1688
1034.6	22.8265
1037.9	21.2723
1041.19	20.536
1044.49	19.7613
1047.78	19.2746
1051.08	18.7956
1054.37	19.2496
1057.66	19.2084
1060.95	20.9956
1064.24	19.1652
1067.53	18.8939
1070.81	18.7811
1074.1	19.2611
1077.38	18.474
1080.66	17.3638
1083.94	16.6748
1087.22	16.6064
1090.5	15.113
1093.78	15.5206
1097.05	17.8058
1100.33	16.9063
1103.6	15.1308
1106.87	15.1399
1110.14	15.125
1113.41	13.7651
1116.68	12.7863
1119.95	11.8196
1123.21	11.3377
1126.48	11.3319
1129.74	9.49594
1133	9.03562
1136.26	9.36451
1139.52	9.43777
1142.78	8.48174
1146.04	6.62952
1149.29	5.66588
1152.55	6.02956
1155.8	5.85518
1159.05	4.09545
1162.3	2.87708
1165.55	1.7848
1168.8	2.32622
1172.05	2.01613
1175.29	3.03945
1178.54	2.59226
1181.78	1.21249
1185.02	2.87108
1188.26	1.82408
1191.5	2.59197
1194.74	1.83435
1197.97	2.86208
1201.21	3.39262
1204.44	4.25695
1207.68	5.8582
1210.91	7.40672
1214.14	10.558
1217.37	13.9632
1220.59	15.8939
1223.82	17.897
1227.05	20.6826
1230.27	22.9076
1233.49	26.2173
1236.72	27.1398
1239.94	29.2023
1243.16	32.8004
1246.37	34.8418
1249.59	35.9417
1252.8	38.0294
1256.02	39.2447
1259.23	39.5517
1262.44	39.47
1265.66	39.8199
1268.86	39.8242
1272.07	40.6537
1275.28	41.3571
1278.48	42.3236
1281.69	44.2873
1284.89	45.4778
1288.09	46.2752
1291.29	47.5159
1294.49	48.1595
1297.69	47.5056
1300.89	48.7537
1304.08	49.6385
1307.28	48.4381
1310.47	49.4015
1313.66	50.2464
1316.85	50.5674
1320.04	50.6891
1323.23	50.399
1326.42	49.6752
1329.61	49.7317
1332.79	49.1154
1335.97	47.5949
1339.16	46.4842
1342.34	45.2579
1345.52	43.5024
1348.7	42.3145
1351.87	40.9296
1355.05	39.2572
1358.22	38.298
1361.4	37.2755
1364.57	35.4662
1367.74	33.8713
1370.91	32.6144
1374.08	30.5982
1377.25	29.6515
1380.41	28.2616
1383.58	26.224
1386.74	26.2159
1389.91	24.9388
1393.07	24.5274
1396.23	24.8552
1399.39	23.5828
1402.55	23.0873
1405.7	23.2603
1408.86	24.2286
1412.01	24.9492
1415.17	25.6848
1418.32	26.9338
1421.47	27.1322
1424.62	29.4696
1427.77	34.5624
1430.91	38.4995
1434.06	42.6847
1437.2	44.9159
1440.35	47.7567
1443.49	51.3
1446.63	53.6154
1449.77	55.5221
1452.91	56.5369
1456.05	55.6281
1459.18	54.7317
1462.32	52.7467
1465.45	49.9848
1468.59	47.153
1471.72	44.1766
1474.85	39.9685
1477.98	35.2761
1481.1	29.8397
1484.23	24.9771
1487.36	19.8313
1490.48	16.8901
1493.61	14.1826
1496.73	12.4791
1499.85	11.221
1502.97	11.2801
1506.09	11.2436
1509.2	10.4617
1512.32	10.7861
1515.43	10.6268
1518.55	11.7718
1521.66	13.2996
1524.77	14.9878
1527.88	16.8766
1530.99	19.5958
1534.1	20.8439
1537.21	22.9798
1540.31	25.206
1543.42	27.7694
1546.52	30.755
1549.62	32.8043
1552.72	34.419
1555.82	36.3875
1558.92	38.4561
1562.02	41.2696
1565.11	44.444
1568.21	45.9958
1571.3	48.0949
1574.39	48.5918
1577.49	50.9045
1580.57	52.4908
1583.66	52.9388
1586.75	53.858
1589.84	53.6163
1592.92	52.7086
1596.01	53.499
1599.09	54.1778
1602.17	54.1251
1605.25	53.5416
1608.33	51.7474
1611.41	50.1955
1614.49	50.0443
1617.57	49.8404
1620.64	50.2645
1623.72	49.3601
1626.79	50.5483
1629.86	50.7612
1632.93	50.9379
1636	52.29
1639.07	52.2786
1642.13	54.1534
1645.2	54.4159
1648.26	55.8332
1651.33	58.8456
1654.39	59.1487
1657.45	59.3675
1660.51	59.0901
1663.57	58.8168
1666.63	57.2947
1669.68	55.906
1672.74	53.8479
1675.79	50.9868
1678.85	46.1691
1681.9	42.1852
1684.95	38.8734
1688	35.3567
1691.05	32.8343
1694.09	30.0044
1697.14	26.4731
1700.18	22.7924
1703.23	21.0221
1706.27	18.3104
1709.31	16.6344
1712.35	14.6527
1715.39	13.1763
1718.43	12.9865
1721.47	12.4299
1724.5	12.6108
1727.54	12.2858
1730.57	11.9311
1733.61	11.6253
1736.64	11.775
1739.67	11.4478
1742.7	10.9526
1745.72	10.6605
1748.75	8.85103
1751.77	7.64473
1754.8	7.30898
1757.82	8.219
1760.84	8.59142
1763.87	8.94294
1766.89	9.06981
1769.91	7.57759
1772.92	6.35936
1775.94	5.96219
1778.95	5.20119
1781.97	4.42866
1784.98	4.21156
1787.99	3.48936
1791.01	3.86563
1794.01	3.98981
1797.02	4.55616
1800.03	4.59746
1803.04	5.18207
1806.04	5.99822
1809.05	5.94334
1812.05	6.82685
1815.05	7.59049
1818.05	8.07466
1821.05	7.9505
1824.05	8.41762
1827.05	10.0016
1830.04	11.5136
1833.04	12.1464
1836.03	12.3671
1839.03	12.1373
1842.02	11.3134
1845.01	11.2047
1848	10.8329
1850.99	10.7602
1853.97	10.678
1856.96	11.2368
1859.94	12.1133
1862.93	12.4387
1865.91	13.1842
1868.89	13.9699
1871.87	13.2699
1874.85	14.2359
1877.83	14.4015
1880.81	14.6962
1882.57	14.5144
1885.56	15.4837
1888.55	16.0824
1891.54	15.4993
1894.52	16.1997
1897.51	16.5662
1900.49	16.1003
1903.47	15.8074
1906.45	14.8174
1909.43	14.8233
1912.41	15.1018
1915.39	14.9271
1918.37	14.416
1921.34	13.5202
1924.32	13.4558
1927.29	13.1669
1930.26	12.9564
1933.23	12.6092
1936.2	10.798
1939.17	10.2377
1942.14	10.6883
1945.11	10.5818
1948.07	10.0625
1951.04	10.5816
1954	10.9514
1956.96	11.879
1959.93	12.1289
1962.89	11.1198
1965.85	11.9028
1968.8	12.5505
1971.76	12.5994
1974.72	13.4783
1977.67	14.1934
1980.63	14.304
1983.58	14.5722
1986.53	14.2598
1989.48	14.0389
1992.43	13.1367
1995.38	12.0514
1998.32	11.3672
2001.27	10.3659
2004.22	10.2324
2007.16	9.83908
2010.1	9.5413
2013.04	10.4268
2015.98	10.9107
2018.92	11.4818
2021.86	12.0722
2024.8	12.1715
2027.74	12.5639
2030.67	12.8287
2033.61	13.6521
2036.54	14.2125
2039.47	15.0211
2042.4	16.0171
2045.33	16.651
2048.26	17.2313
2051.19	16.4977
2054.12	16.3502
2057.04	16.3888
2059.97	16.4564
2062.89	16.444
2065.81	16.6909
2068.73	17.8787
2071.65	18.2663
2074.57	17.4519
2077.49	18.0338
2080.41	18.3663
2083.32	18.8223
2086.24	19.1815
2089.15	19.5881
2092.07	20.7556
2094.98	20.58
2097.89	21.7298
2100.8	22.2375
2103.71	23.3937
2106.61	23.1355
2109.52	23.4826
2112.43	24.5555
2115.33	25.9129
2118.23	26.3449
2121.13	28.4916
2124.04	30.024
2126.94	32.504
2129.83	35.0167
2132.73	37.2023
2135.63	39.5201
2138.53	42.429
2141.42	43.8665
2144.31	45.6255
2147.21	48.019
2150.1	50.5411
2152.99	52.0108
2155.88	53.0284
2158.77	55.5699
2161.65	57.8633
2164.54	59.413
2167.43	60.5173
2170.31	61.6913
2173.19	61.5399
2176.07	60.6516
2178.96	60.1133
2181.84	59.5025
2184.72	57.9966
2187.59	57.8616
2190.47	57.539
2193.35	56.0118
2196.22	53.1562
2199.09	51.0738
2201.97	48.8255
2204.84	47.5404
2207.71	45.7787
2210.58	42.5101
2213.45	40.4297
2216.31	37.6542
2219.18	34.9529
2222.05	32.5918
2224.91	30.8246
2227.78	29.9502
2230.64	29.7058
2233.5	28.0717
2236.36	27.5836
2239.22	26.0864
2242.08	24.5375
2244.93	22.7566
2247.79	20.9298
2250.64	19.0933
2253.5	18.0937
2256.35	17.9735
2259.2	16.6602
2262.05	15.2862
2264.9	14.0659
2267.75	13.3693
2270.6	13.3783
2273.45	13.007
2276.29	12.9234
2279.14	11.1516
2281.98	9.65353
2284.82	9.13637
2287.66	8.40779
2290.5	8.96095
2293.34	7.71005
2296.18	7.62246
2299.02	8.31921
2301.86	9.65741
2304.69	10.0316
2307.53	9.64709
2310.36	9.17519
2313.19	9.81583
2316.02	8.32887
2318.85	8.73142
2321.68	8.56277
2324.51	8.00812
2327.34	7.0858
2330.16	6.169
2332.99	6.70135
2335.81	5.94289
2338.64	4.85491
2341.46	4.07535
2344.28	2.87221
2347.1	1.91377
2349.92	0.751703
2352.74	-0.671124
2355.55	-0.732354
2358.37	-1.4378
2361.19	-2.14613
2364	-2.13844
2366.81	-1.14632
2369.62	-0.651343
2372.44	-0.434845
2375.24	-0.432772
2378.05	0.0828175
2380.86	0.173426
2383.67	-0.00989663
2386.47	0.497766
2389.28	1.17357
2392.08	1.25454
2394.89	1.90791
2397.69	2.42075
2400.49	3.01637
2403.29	3.36598
2406.09	3.72968
2408.88	4.47651
2411.68	5.50971
2414.48	6.16632
2417.27	6.91855
2420.06	6.54001
2422.86	5.76224
2425.65	5.8895
2428.44	6.15282
2431.23	6.06107
2434.02	6.16105
2436.81	5.53585
2439.59	5.27836
2442.38	4.68701
2445.16	4.1615
2447.95	4.02414
2450.73	3.60511
2453.51	3.09865
2456.29	2.94301
2459.07	2.46809
2461.85	1.58505
2464.63	1.39954
2467.4	1.65024
2470.18	1.80565
2472.95	2.63143
2475.73	3.23866
2478.5	4.50615
2481.27	4.54248
2484.04	4.34195
2486.81	3.77473
2489.58	3.56103
2492.35	3.48505
2495.12	3.73226
2497.88	3.53045
2500.65	3.29854
2503.41	3.64754
2506.17	2.84052
2508.94	2.5727
2511.7	2.52716
2514.46	2.70093
2517.22	1.99453
2519.97	1.28634
2522.73	0.983497
2525.49	0.554542
2528.24	0.518905
2530.99	-0.143199
2533.75	0.488655
2536.5	0.877474
2539.25	0.726297
2542	2.15557
2544.75	3.0873
2547.5	2.68393
2550.24	2.924
2552.99	3.41115
2555.74	4.53682
2558.48	4.91285
2561.22	5.45473
2563.96	5.96571
2566.71	6.71268
2569.45	6.7416
2572.18	7.18086
2574.92	6.60626
2577.66	7.12354
2580.4	6.92886
2583.13	6.35852
2585.87	6.39979
2588.6	6.36729
2591.33	6.76623
2594.06	5.94565
2596.79	5.95766
2599.52	5.77761
2602.25	5.70951
2604.98	5.05519
2607.71	4.32887
2610.43	4.04021
2613.16	3.52441
2615.88	3.2359
2618.6	3.5728
2621.32	3.12703
2624.04	3.37148
2626.76	2.71653
2629.48	2.85779
2632.2	3.20418
2634.92	2.74615
2637.63	2.29649
2640.35	1.95956
2643.06	2.15198
2645.77	2.17956
2648.49	2.92449
2651.2	3.50435
2653.91	3.48435
2656.62	3.74056
2659.33	4.43057
2662.03	4.38348
2664.74	4.25015
2667.44	3.11268
2670.15	3.11589
2672.85	2.08983
2675.55	2.57467
2678.26	2.21221
2680.96	1.65253
2683.66	1.45923
2686.35	1.0657
2689.05	0.956869
2691.75	0.476206
2694.44	1.44554
2697.14	0.655881
2699.83	-0.240549
2702.52	-0.3895
2705.22	0.389277
2707.91	0.300415
2710.6	0.659473
2713.29	1.77662
2715.97	2.367
2718.66	2.35174
2721.35	3.45956
2724.03	3.41854
2726.72	4.07769
2729.4	4.57605
2732.08	4.38335
2734.76	4.9421
2737.44	4.982
2740.12	4.58474
2742.8	4.65265
2745.48	3.58688
2748.16	3.60131
2750.83	3.16675
2753.51	3.1171
2756.18	2.83367
2758.85	3.89508
2761.53	3.90005
2764.2	3.2298
2766.87	3.6491
2769.54	3.05434
2772.2	3.44005
2774.87	3.78072
2777.54	3.62295
2780.2	3.65016
2782.87	3.76369
2785.53	3.92855
2788.19	3.82416
2790.85	3.69922
2793.51	3.44498
2796.17	2.8939
2798.83	2.82838
2801.49	1.83876
2804.15	0.834122
2806.8	-0.135744
2809.46	-0.959908
2812.11	-1.64505
2814.76	-2.1304
2817.42	-2.13404
2820.07	-1.75477
2822.72	-0.676778
2825.37	0.957556
2828.02	2.65644
2830.66	4.10715
2833.31	5.42516
2835.96	8.80736
2838.6	11.168
2841.24	13.8746
2843.89	16.9345
2846.53	21.1078
2849.17	25.4933
2851.81	29.9146
2854.45	34.6397
2857.09	38.3397
2859.72	42.2295
2862.36	46.0322
2865	49.3329
2867.63	53.0054
2870.26	56.4659
2872.9	59.1645
2875.53	62.147
2878.16	63.3385
2880.79	65.9182
2883.42	68.0169
2886.05	70.5235
2888.67	72.995
2891.3	75.4705
2893.92	78.7256
2896.55	80.5807
2899.17	84.3243
2901.79	88.2364
2904.42	92.7223
2907.04	97.7792
2909.66	103.871
2912.27	110.734
2914.89	117.083
2917.51	123.311
2920.13	128.037
2922.74	133.078
2925.35	137.355
2927.97	140.779
2930.58	143.326
2933.19	144.506
2935.8	144.038
2938.41	142.734
2941.02	140.738
2943.63	137.331
2946.24	134.664
2948.84	130.068
2951.45	125.738
2954.05	120.325
2956.65	114.532
2959.26	108.302
2961.86	104.044
2964.46	98.9283
2967.06	94.0073
2969.66	88.6843
2972.25	84.0988
2974.85	79.51
2977.45	74.2166
2980.04	69.4861
2982.64	63.5189
2985.23	58.7646
2987.82	54.1557
2990.41	48.8367
2993	43.7999
2995.59	38.4916
2998.18	32.9601
3000.77	28.5437
3003.36	24.6777
3005.94	21.4372
3008.53	17.9377
3011.11	14.7635
3013.69	11.9509
3016.28	9.76569
3018.86	7.94618
3021.44	7.17662
3024.02	6.92333
3026.6	7.11242
3029.18	6.57267
3031.75	5.60551
3034.33	5.97691
3036.9	6.20548
3039.48	6.89675
3042.05	8.12837
3044.62	9.68041
3047.19	10.7424
3049.77	10.5604
3052.34	11.0913
3054.9	11.5299
3057.47	11.7991
3060.04	10.7544
3062.61	11.0939
3065.17	10.5566
3067.74	9.34393
3070.3	8.27945
3072.86	7.29502
3075.42	6.17063
3077.99	5.79066
3080.54	4.74922
3083.1	3.4395
3085.66	2.38517
3088.22	1.3666
3090.78	1.03114
3093.33	0.39867
3095.89	-0.378882
3098.44	-0.0513352
3100.99	-0.105262
3103.54	0.341544
3106.1	0.760408
3108.65	0.838492
3111.2	1.36841
3113.74	1.56967
3116.29	3.3686
3118.84	4.29378
3121.38	5.77484
3123.93	6.65281
3126.47	7.61186
3129.01	9.07932
3131.56	10.1894
3134.1	11.7079
3136.64	12.6838
3139.18	14.5086
3141.72	15.6078
3144.26	16.4264
3146.79	17.6969
3149.33	18.5499