File: data/Raman/poly_smoothed/Thy_30_10_05_1x_45s_532 nm_x100_100%_600 gr_mm_01.txt
#Acq. time (s)=	45
#Accumulations=	2
#Range (cm-¹)=	200...3150
#Windows=	2
#Auto scanning=	Off
#Autofocus=	Off
#Macrospot=	Off
#AutoExposure=	Off
#Spike filter=	Multiple accum.
#Delay time (s)=	0
#Binning=	1
#Readout mode=	Signal
#DeNoise=	Off
#ICS correction=	On
#Dark correction=	Off
#Inst. Process=	Off
#Detector Gain=	Best Dynamic Range
#Detector ADC=	20 kHz
#Detector temperature (°C)=	-69.85
#Instrument=	LabRAM HR Evol
#Detector=	Synapse
#Objective=	x100
#Grating=	600 gr/mm
#ND Filter=	100%
#Laser (nm)=	532
#Hole=	100.021
#Range=	Auto
#Laser Pol.=	No
#Raman. Pol.=	No
#Laser Pol. (°)=	-0.0007625
#Raman Pol. (°)=	89.9995
#Collection=	Microscope
#StageXY=	Marzhauser
#StageZ=	Marzhauser
#X (µm)=	4760.8
#Y (µm)=	-7735.6
#Z (µm)=	584.05
#Full time(mm:ss)=	3:19
#Project=
#Sample=
#Site=
#Title=	Thy_30_10_05_2x_45s_532 nm_x100_100%_600 gr_mm
#Remark=
#Date=	30.06.2022 11:44
#Acquired=	30.06.2022 11:44:21
#Base:Fit=	10.08.2022 09:56:48
#Base:Fit=	10.08.2022 09:57:06
#Base:Fit=	10.08.2022 09:57:43
#Base:Fit=	10.08.2022 09:57:50
#Base:Fit=	10.08.2022 09:58:11
#Base:Sub=	10.08.2022 09:58:44
#Filter:Polynom=	16.08.2022 10:22:53
#AxisType[0]=Intens
#AxisUnit[0]=Cnt
#AxisType[1]=Spectr
#AxisUnit[1]=1/cm
200.533	32.0745
204.162	31.9262
207.792	31.9886
211.418	32.1696
215.044	31.3915
218.667	29.208
222.289	27.0877
225.912	24.4614
229.531	22.0665
233.148	19.2416
236.766	17.434
240.381	14.8034
243.994	13.6672
247.606	12.7239
251.217	10.6046
254.828	11.3819
258.436	10.901
262.042	11.1499
265.647	11.8551
269.25	11.3167
272.852	11.4182
276.453	11.1364
280.052	11.4411
283.65	13.4627
287.247	16.3997
290.842	18.2003
294.436	19.8532
298.028	20.4425
301.617	22.3217
305.206	22.2111
308.794	22.7362
312.381	21.9108
315.964	21.5606
319.548	21.1618
323.131	21.3698
326.71	21.0577
330.29	20.2955
333.868	20.2088
337.443	21.973
341.018	20.5813
344.591	21.1128
348.163	19.2812
351.733	17.4255
355.303	16.0849
358.869	14.3418
362.435	11.8674
366.001	12.2463
369.563	11.8437
373.124	11.885
376.686	11.4991
380.244	11.5743
383.801	12.1054
387.357	12.5862
390.911	11.7054
394.466	10.2774
398.018	8.24233
401.568	7.07781
405.117	6.83683
408.664	6.5575
412.21	6.22699
415.755	5.07912
419.298	6.0699
422.84	6.88162
426.38	6.68446
429.919	6.347
433.455	5.53678
436.992	3.82676
440.527	3.70622
444.06	2.18125
447.593	2.73198
451.122	3.66854
454.651	4.60044
458.18	5.62971
461.705	7.08352
465.23	7.93283
468.752	8.19432
472.275	9.87799
475.797	10.9587
479.315	11.4702
482.834	11.9705
486.349	12.0992
489.863	13.4316
493.378	14.0154
496.889	14.2484
500.401	16.1632
503.91	16.4111
507.417	16.8943
510.923	15.981
514.43	15.8322
517.933	14.4602
521.435	12.9244
524.936	12.187
528.435	10.7808
531.933	10.8679
535.43	10.421
538.927	10.8439
542.421	11.3414
545.913	11.7653
549.403	11.4326
552.893	12.3719
556.381	13.0716
559.868	15.1483
563.354	15.0653
566.839	14.1592
570.322	12.863
573.802	11.2039
577.283	11.7463
580.762	11.8409
584.24	12.5359
587.714	11.6441
591.19	10.719
594.663	9.54203
598.134	8.53792
601.605	7.64444
605.073	7.53253
608.542	6.97594
612.007	6.69891
615.473	6.87765
618.936	7.86744
622.397	7.842
625.859	7.78317
629.318	8.83484
632.775	8.55544
636.233	7.97452
639.688	8.72984
643.142	9.16031
646.594	7.36907
650.045	8.12096
653.496	7.55908
656.944	7.82492
660.391	8.41213
663.837	9.7146
667.281	11.6509
670.724	13.2524
674.166	14.4047
677.606	16.0476
681.045	18.3498
684.483	20.7072
687.917	23.4825
691.352	25.8948
694.786	28.7127
698.219	32.1284
701.65	33.0294
705.078	34.2271
708.506	35.6066
711.934	37.0655
715.358	37.2098
718.782	37.1257
722.204	38.6411
725.626	39.9484
729.045	39.955
732.464	41.3588
735.881	41.4573
739.297	42.4633
742.711	42.8265
746.125	44.3474
749.537	48.1024
752.946	50.5048
756.357	53.9389
759.764	54.8425
763.17	55.9333
766.575	57.9532
769.978	59.4706
773.382	60.6682
776.783	62.6664
780.182	64.6336
783.581	66.1525
786.978	67.9569
790.373	67.9531
793.768	68.6148
797.161	70.0523
800.552	71.5287
803.941	71.6752
807.33	72.6484
810.718	73.0714
814.105	73.518
817.49	73.7189
820.873	73.786
824.256	74.1772
827.637	74.2022
831.016	74.3756
834.395	73.9062
837.772	71.1387
841.147	69.6939
844.522	66.4036
847.894	66.0289
851.267	63.8264
854.637	61.6049
858.007	59.4746
861.374	57.497
864.739	55.9215
868.106	53.9474
871.469	52.5792
874.831	51.3256
878.193	49.6872
881.553	48.4692
884.911	47.3453
888.268	45.8736
891.623	45.0681
894.978	44.5485
898.331	45.5538
901.683	44.8247
905.033	45.1833
908.383	43.6929
911.731	43.5403
915.078	42.1124
918.423	42.4015
921.768	42.6328
925.111	42.4737
928.452	42.3683
931.791	41.4383
935.13	40.4793
938.468	39.3287
941.803	37.5962
945.139	37.3734
948.473	37.2641
951.804	37.989
955.136	38.2604
958.465	34.9552
961.794	34.048
965.12	34.6325
968.447	34.7165
971.771	35.4738
975.095	35.9275
978.417	36.8348
981.737	36.4376
985.057	36.3453
988.375	35.9984
991.691	36.3161
995.006	37.3958
998.32	36.1465
1001.63	35.4448
1004.95	34.1546
1008.26	33.0989
1011.56	31.9428
1014.87	30.4998
1018.18	29.7372
1021.48	28.5809
1024.79	28.1835
1028.09	27.9741
1031.39	27.3696
1034.69	26.4398
1037.99	25.1756
1041.29	24.3299
1044.58	24.948
1047.88	24.8523
1051.17	23.7957
1054.46	23.8513
1057.75	22.4969
1061.04	21.6682
1064.33	21.894
1067.62	22.0708
1070.9	22.5936
1074.19	22.2781
1077.47	21.7462
1080.76	20.8617
1084.04	19.9834
1087.32	19.3788
1090.59	19.0273
1093.87	18.2431
1097.15	18.0426
1100.42	19.1356
1103.69	18.6091
1106.97	18.0355
1110.24	18.2221
1113.51	18.6416
1116.77	18.779
1120.04	19.0056
1123.31	17.2186
1126.57	16.2863
1129.83	15.5627
1133.1	15.9628
1136.36	15.5139
1139.62	13.5698
1142.87	13.9715
1146.13	12.9079
1149.38	12.2765
1152.64	11.8792
1155.89	11.0341
1159.14	10.1276
1162.39	7.77358
1165.64	5.80077
1168.89	4.632
1172.14	4.51364
1175.38	3.46324
1178.63	2.24951
1181.87	0.716303
1185.11	-0.0870994
1188.35	1.22958
1191.59	2.6359
1194.83	2.89328
1198.07	3.21918
1201.3	5.44367
1204.53	8.04878
1207.77	10.5183
1211	13.6052
1214.23	17.1208
1217.46	19.8295
1220.69	23.0636
1223.91	26.4714
1227.14	30.3815
1230.36	34.9361
1233.59	38.3356
1236.81	40.2969
1240.03	42.0125
1243.25	43.2132
1246.46	43.6066
1249.68	44.981
1252.9	45.4834
1256.11	45.3493
1259.32	45.7731
1262.54	46.3886
1265.75	46.6323
1268.96	47.9711
1272.16	47.9932
1275.37	47.8273
1278.57	51.188
1281.78	51.9934
1284.98	54.2673
1288.18	56.5427
1291.38	58.199
1294.58	59.2475
1297.78	61.3288
1300.98	62.0656
1304.17	62.8158
1307.37	64.4232
1310.56	65.9156
1313.76	65.9981
1316.95	65.2843
1320.14	65.2625
1323.32	63.7971
1326.51	62.6509
1329.7	60.6955
1332.88	58.7444
1336.07	55.8214
1339.25	53.5644
1342.43	51.3784
1345.61	49.0853
1348.79	47.2777
1351.96	45.448
1355.14	43.672
1358.31	41.8209
1361.49	39.033
1364.66	37.144
1367.83	34.9338
1371	32.35
1374.17	29.6926
1377.34	27.8805
1380.5	26.5339
1383.67	25.8036
1386.83	25.0784
1390	24.2278
1393.16	24.3102
1396.32	23.2358
1399.48	21.9826
1402.64	20.5416
1405.79	19.4133
1408.95	19.7415
1412.1	20.33
1415.26	22.5662
1418.41	24.8318
1421.56	28.5569
1424.71	33.2041
1427.86	36.8818
1431	41.5336
1434.15	46.1837
1437.29	50.0172
1440.44	53.4612
1443.58	54.731
1446.72	55.2071
1449.86	55.4103
1453	55.213
1456.14	54.0897
1459.27	51.3944
1462.41	49.7674
1465.54	45.6117
1468.67	41.6264
1471.81	38.255
1474.94	33.3774
1478.07	28.1531
1481.19	23.5144
1484.32	19.5242
1487.45	15.269
1490.57	13.2947
1493.69	11.1351
1496.82	9.7417
1499.94	9.03599
1503.06	7.43651
1506.17	7.08609
1509.29	7.81986
1512.41	7.42084
1515.52	5.35398
1518.64	4.1355
1521.75	4.32459
1524.86	4.99009
1527.97	5.99075
1531.08	6.7156
1534.19	6.78743
1537.29	8.80146
1540.4	11.6983
1543.5	13.567
1546.61	17.4215
1549.71	19.5969
1552.81	22.8687
1555.91	25.9822
1559.01	27.972
1562.11	28.2394
1565.2	32.2209
1568.29	33.9703
1571.39	36.291
1574.48	38.1571
1577.57	39.4023
1580.66	42.099
1583.75	43.7265
1586.84	44.4669
1589.93	44.7038
1593.01	44.7488
1596.1	45.7384
1599.18	45.4874
1602.26	45.629
1605.34	44.5986
1608.42	44.2584
1611.5	43.8277
1614.58	44.9149
1617.65	44.0727
1620.73	44.5196
1623.8	46.0752
1626.87	46.9796
1629.95	47.6201
1633.02	48.3261
1636.09	48.49
1639.15	50.4973
1642.22	52.4571
1645.29	55.288
1648.35	56.4861
1651.42	58.0448
1654.48	58.213
1657.54	58.7068
1660.6	57.7508
1663.66	56.5987
1666.72	56.5111
1669.77	55.2157
1672.83	53.9814
1675.88	50.4118
1678.93	46.966
1681.99	42.2208
1685.04	37.6488
1688.09	33.3057
1691.13	28.7787
1694.18	24.5451
1697.23	21.5309
1700.27	17.1262
1703.32	12.8721
1706.36	9.77944
1709.4	8.31024
1712.44	6.16609
1715.48	4.45302
1718.52	4.74334
1721.56	4.28781
1724.59	3.09961
1727.63	1.07937
1730.66	1.06877
1733.69	0.984012
1736.72	1.19529
1739.75	3.17743
1742.78	3.51297
1745.81	4.02422
1748.84	3.7543
1751.86	3.78951
1754.89	3.13782
1757.91	2.60275
1760.93	2.1584
1763.95	2.78851
1766.97	3.07713
1769.99	2.6076
1773.01	2.53101
1776.03	1.61949
1779.04	2.2685
1782.06	3.3957
1785.07	3.75156
1788.08	3.83182
1791.09	4.4511
1794.1	4.0877
1797.11	2.85726
1800.12	1.51313
1803.12	1.30147
1806.13	2.14365
1809.13	1.98252
1812.14	2.27572
1815.14	2.67006
1818.14	2.28546
1821.14	2.35932
1824.14	2.61436
1827.13	2.9672
1830.13	2.54326
1833.12	3.05079
1836.12	4.20848
1839.11	4.80029
1842.1	5.47451
1845.09	5.50892
1848.08	5.67352
1851.07	5.80907
1854.06	7.08123
1857.04	7.48382
1860.03	7.54474
1863.01	6.81079
1866	7.34879
1868.98	7.68641
1871.96	8.27505
1874.94	9.01025
1877.92	9.27126
1880.89	9.5775
1882.48	10.1119
1885.47	10.8519
1888.46	11.1588
1891.44	11
1894.43	11.9909
1897.41	12.3686
1900.4	12.2267
1903.38	12.5297
1906.36	13.6902
1909.34	14.1448
1912.32	14.1832
1915.29	14.1335
1918.27	12.6084
1921.25	13.7825
1924.22	13.5947
1927.2	13.3774
1930.17	11.7184
1933.14	11.0705
1936.11	11.3085
1939.08	11.9754
1942.05	11.4899
1945.01	10.7684
1947.98	9.58818
1950.94	9.5713
1953.91	9.56275
1956.87	9.76517
1959.83	9.65875
1962.79	9.23538
1965.75	9.09874
1968.71	9.28864
1971.67	9.45152
1974.62	9.54024
1977.58	9.90057
1980.53	10.6437
1983.48	9.3842
1986.43	9.68578
1989.38	9.04244
1992.33	9.56011
1995.28	9.31377
1998.23	9.28068
2001.18	9.23686
2004.12	9.62605
2007.06	10.2726
2010.01	11.1541
2012.95	12.0808
2015.89	12.1718
2018.83	12.2285
2021.77	13.2131
2024.71	13.9308
2027.64	14.1983
2030.58	15.1066
2033.51	16.162
2036.45	16.3254
2039.38	17.4963
2042.31	17.5156
2045.24	17.7021
2048.17	18.0171
2051.1	17.8938
2054.02	17.8109
2056.95	18.3279
2059.87	19.3722
2062.8	19.3879
2065.72	19.6168
2068.64	19.7728
2071.56	21.0973
2074.48	20.8618
2077.4	22.204
2080.31	23.0955
2083.23	24.2472
2086.14	25.4018
2089.06	25.8207
2091.97	26.9142
2094.88	26.5582
2097.79	28.121
2100.7	29.5186
2103.61	30.9127
2106.52	31.4986
2109.43	33.4584
2112.33	34.2727
2115.24	36.2347
2118.14	37.5108
2121.04	39.4806
2123.94	41.5986
2126.84	44.168
2129.74	46.9438
2132.64	48.4401
2135.54	50.4422
2138.43	53.032
2141.33	55.2875
2144.22	57.8072
2147.11	60.2075
2150.01	61.4707
2152.9	62.6695
2155.79	64.914
2158.67	66.2132
2161.56	66.8011
2164.45	67.6974
2167.33	69.4012
2170.22	69.4397
2173.1	68.301
2175.98	67.2923
2178.86	67.7449
2181.74	67.5319
2184.62	66.1299
2187.5	65.0446
2190.38	63.9174
2193.25	62.2941
2196.13	60.3153
2199	58.9648
2201.88	57.1525
2204.75	55.241
2207.62	52.3099
2210.49	49.4569
2213.36	46.9824
2216.22	44.3732
2219.09	41.3559
2221.96	38.8524
2224.82	37.1286
2227.68	36.0788
2230.55	33.7034
2233.41	32.7116
2236.27	30.958
2239.12	29.3205
2241.98	28.2615
2244.84	27.0912
2247.7	26.5199
2250.55	26.0751
2253.41	25.9144
2256.26	25.9118
2259.11	25.3727
2261.96	25.6853
2264.81	24.8734
2267.66	25.4347
2270.51	26.0628
2273.35	25.2439
2276.2	23.5276
2279.04	22.9024
2281.89	22.1813
2284.73	21.632
2287.57	20.6053
2290.41	19.3495
2293.25	18.3929
2296.09	19.1923
2298.93	19.8125
2301.76	20.4077
2304.6	20.41
2307.44	20.2043
2310.27	19.8724
2313.1	19.6367
2315.93	19.9634
2318.76	20.0508
2321.59	19.7515
2324.42	19.568
2327.25	19.5897
2330.07	19.2433
2332.9	18.5027
2335.72	18.6133
2338.55	18.643
2341.37	17.4265
2344.19	16.9247
2347.01	16.5061
2349.83	14.7328
2352.65	12.5765
2355.46	11.3274
2358.28	10.2074
2361.09	9.85321
2363.91	10.4785
2366.72	10.9729
2369.53	11.0215
2372.34	9.64444
2375.15	9.57388
2377.96	9.62537
2380.77	9.27112
2383.58	9.94903
2386.38	10.6128
2389.19	9.65428
2391.99	9.61383
2394.8	9.66841
2397.6	10.0817
2400.4	10.6006
2403.2	11.5935
2406	12.7727
2408.79	13.3237
2411.59	14.3447
2414.39	14.3826
2417.18	14.1499
2419.98	13.5312
2422.77	13.653
2425.56	13.244
2428.35	13.815
2431.14	14.0992
2433.93	14.1833
2436.72	13.3463
2439.5	12.9714
2442.29	12.4223
2445.07	12.0599
2447.86	10.4602
2450.64	8.31094
2453.42	6.90832
2456.2	5.68112
2458.98	4.61243
2461.76	3.8979
2464.54	3.80725
2467.32	2.70032
2470.09	2.56786
2472.87	2.06639
2475.64	2.16922
2478.41	1.62122
2481.18	1.81162
2483.95	1.99375
2486.72	1.88283
2489.49	1.98389
2492.26	2.78626
2495.03	3.24725
2497.79	4.72349
2500.56	5.21628
2503.32	4.62103
2506.09	4.08138
2508.85	3.46605
2511.61	3.83878
2514.37	3.75456
2517.13	3.23278
2519.89	3.30437
2522.64	3.29363
2525.4	4.49189
2528.15	3.88137
2530.91	3.94076
2533.66	4.22417
2536.41	3.5879
2539.16	3.80855
2541.91	4.42334
2544.66	5.76078
2547.41	6.39641
2550.16	7.61273
2552.9	9.36565
2555.65	9.39098
2558.39	9.55451
2561.13	9.10848
2563.88	8.87876
2566.62	7.80809
2569.36	6.32996
2572.1	4.71835
2574.84	4.04718
2577.57	4.14805
2580.31	4.54436
2583.05	3.78982
2585.78	3.48944
2588.51	2.7763
2591.24	1.94765
2593.98	1.20915
2596.71	1.35545
2599.44	1.73365
2602.16	1.473
2604.89	1.67565
2607.62	2.03516
2610.34	2.76038
2613.07	3.70253
2615.79	3.79251
2618.52	4.54354
2621.24	3.53312
2623.96	3.96213
2626.68	3.9429
2629.4	3.7823
2632.11	3.41131
2634.83	3.08212
2637.55	2.72089
2640.26	2.76957
2642.98	3.28067
2645.69	4.20723
2648.4	4.58891
2651.11	4.92163
2653.82	4.99866
2656.53	5.06541
2659.24	4.67258
2661.95	5.40802
2664.65	4.09652
2667.36	4.0596
2670.06	4.23004
2672.76	4.34889
2675.47	3.71692
2678.17	3.65578
2680.87	2.99944
2683.57	2.88989
2686.27	3.04529
2688.97	2.8676
2691.66	3.03753
2694.36	2.6998
2697.05	2.45951
2699.75	2.02044
2702.44	1.75209
2705.13	1.53922
2707.82	2.59709
2710.51	3.64378
2713.2	4.43604
2715.89	4.69825
2718.57	4.92207
2721.26	5.11522
2723.95	5.00874
2726.63	3.63151
2729.31	3.83693
2732	4.09692
2734.68	4.09573
2737.36	4.04268
2740.04	3.29639
2742.72	2.478
2745.39	2.31441
2748.07	2.41486
2750.75	2.57982
2753.42	2.18491
2756.09	2.02508
2758.77	1.29161
2761.44	1.54798
2764.11	0.827344
2766.78	1.25023
2769.45	1.02899
2772.12	1.31601
2774.78	1.63998
2777.45	1.76363
2780.12	1.29506
2782.78	0.997712
2785.44	1.47017
2788.11	0.679099
2790.77	0.385416
2793.43	-0.286374
2796.09	0.115968
2798.75	0.0409006
2801.4	0.355178
2804.06	1.04154
2806.72	2.06297
2809.37	2.32803
2812.03	2.45132
2814.68	2.59924
2817.33	2.49844
2819.98	2.89862
2822.63	4.27991
2825.28	5.95166
2827.93	7.31801
2830.58	9.09269
2833.23	11.0401
2835.87	14.1867
2838.52	16.756
2841.16	20.2987
2843.8	23.7881
2846.44	28.53
2849.08	34.232
2851.73	39.6866
2854.36	45.6588
2857	51.3038
2859.64	57.3899
2862.28	63.0886
2864.91	68.5067
2867.55	74.1247
2870.18	79.3529
2872.81	82.4239
2875.44	85.2282
2878.07	88.1265
2880.7	90.3821
2883.33	93.5646
2885.96	96.2907
2888.59	99.4371
2891.21	102.444
2893.84	105.373
2896.46	108.741
2899.09	113.243
2901.71	118.095
2904.33	123.782
2906.95	130.362
2909.57	138.944
2912.19	147.124
2914.81	154.869
2917.43	162.482
2920.04	170.242
2922.66	176.689
2925.27	182.956
2927.88	186.454
2930.5	188.992
2933.11	191.026
2935.72	191.334
2938.33	189.26
2940.94	187.108
2943.54	182.511
2946.15	178.606
2948.76	173.911
2951.36	167.488
2953.97	161.146
2956.57	155.089
2959.17	148.288
2961.77	140.994
2964.37	133.905
2966.97	126.831
2969.57	119.226
2972.17	113.404
2974.77	107.271
2977.36	101.106
2979.96	94.4247
2982.55	88.9862
2985.15	82.8085
2987.74	76.4554
2990.33	70.1384
2992.92	63.5552
2995.51	58.3597
2998.1	53.2006
3000.69	47.5295
3003.27	42.6028
3005.86	37.6741
3008.44	34.0566
3011.03	31.0837
3013.61	28.0895
3016.19	25.7603
3018.78	22.9567
3021.36	20.4902
3023.94	18.4184
3026.51	16.1931
3029.09	15.1814
3031.67	14.2762
3034.24	14.125
3036.82	13.9676
3039.39	14.3517
3041.97	14.9646
3044.54	15.2688
3047.11	16.2186
3049.68	17.3002
3052.25	17.7269
3054.82	17.7303
3057.39	18.6324
3059.96	18.1344
3062.52	18.5162
3065.09	18.1594
3067.65	17.5677
3070.22	16.5535
3072.78	15.822
3075.34	14.096
3077.9	12.9802
3080.46	10.8866
3083.02	9.12144
3085.58	7.05015
3088.14	5.39421
3090.69	4.09002
3093.25	2.54741
3095.8	1.57013
3098.36	0.590946
3100.91	0.227395
3103.46	0.431855
3106.01	0.370741
3108.56	0.910496
3111.11	1.07741
3113.66	1.48615
3116.21	1.28588
3118.76	1.87538
3121.3	2.32279
3123.85	2.58325
3126.39	3.21097
3128.93	3.37424
3131.48	3.60799
3134.02	3.8888
3136.56	2.98251
3139.1	2.88185
3141.64	2.31194
3144.17	1.28187
3146.71	0.762816
3149.25	-0.22486