File: data/Raman/poly_smoothed/Thy_10_08_19_1x_45s_532 nm_x100_100%_600 gr_mm_01.txt
#Acq. time (s)=	45
#Accumulations=	2
#Range (cm-¹)=	200...3150
#Windows=	2
#Auto scanning=	Off
#Autofocus=	Off
#Macrospot=	Off
#AutoExposure=	Off
#Spike filter=	Multiple accum.
#Delay time (s)=	0
#Binning=	1
#Readout mode=	Signal
#DeNoise=	Off
#ICS correction=	On
#Dark correction=	Off
#Inst. Process=	Off
#Detector Gain=	Best Dynamic Range
#Detector ADC=	20 kHz
#Detector temperature (°C)=	-69.85
#Instrument=	LabRAM HR Evol
#Detector=	Synapse
#Objective=	x100
#Grating=	600 gr/mm
#ND Filter=	100%
#Laser (nm)=	532
#Hole=	100.021
#Range=	Auto
#Laser Pol.=	No
#Raman. Pol.=	No
#Laser Pol. (°)=	-0.0007625
#Raman Pol. (°)=	89.9995
#Collection=	Microscope
#StageXY=	Marzhauser
#StageZ=	Marzhauser
#X (µm)=	2207
#Y (µm)=	1241.2
#Z (µm)=	443.25
#Full time(mm:ss)=	3:19
#Project=
#Sample=
#Site=
#Title=	Thy_10_08_19_2x_45s_532 nm_x100_100%_600 gr_mm
#Remark=
#Date=	05.07.2022 15:32
#Acquired=	05.07.2022 15:32:12
#Base:Fit=	10.08.2022 09:46:25
#Base:Sub=	10.08.2022 09:46:49
#Filter:Polynom=	16.08.2022 10:24:56
#AxisType[0]=Intens
#AxisUnit[0]=Cnt
#AxisType[1]=Spectr
#AxisUnit[1]=1/cm
200.43	3.50714
204.059	0.874161
207.688	0.647654
211.314	2.53343
214.941	4.54981
218.564	5.29132
222.186	5.70118
225.809	7.69527
229.428	8.54306
233.045	9.10488
236.663	8.84577
240.278	7.52993
243.891	6.96812
247.503	7.95429
251.116	7.48035
254.725	7.76442
258.333	8.21799
261.939	7.39804
265.544	7.30614
269.148	7.0145
272.75	7.44444
276.351	7.40804
279.95	8.2317
283.548	8.36185
287.144	8.54621
290.739	9.41493
294.333	11.8596
297.925	14.1779
301.514	13.9356
305.104	13.8775
308.692	14.4335
312.279	15.5392
315.862	16.3954
319.446	16.9039
323.029	15.861
326.608	15.7839
330.188	14.7348
333.766	16.1344
337.341	16.2226
340.917	15.396
344.489	16.0142
348.062	15.9887
351.631	16.1203
355.201	17.2238
358.768	16.1359
362.333	15.6984
365.899	16.6567
369.462	15.606
373.023	14.9317
376.585	14.6577
380.143	14.039
383.7	13.4301
387.256	12.9923
390.812	11.0593
394.365	9.58662
397.916	9.62244
401.467	8.90394
405.015	7.28591
408.563	7.08985
412.109	6.85991
415.654	7.10076
419.197	6.46477
422.739	4.9774
426.279	3.83925
429.819	3.82734
433.356	3.69303
436.891	3.00595
440.426	2.76109
443.96	3.83673
447.492	3.19667
451.021	4.81903
454.551	5.84874
458.079	6.48255
461.604	6.83444
465.13	6.76576
468.654	6.21747
472.175	8.05624
475.696	9.13651
479.215	9.42293
482.733	10.4837
486.249	12.5673
489.765	12.2468
493.278	12.6862
496.789	13.34
500.301	13.1147
503.81	13.015
507.317	12.8389
510.825	10.7241
514.33	12.2411
517.833	10.8945
521.335	10.6882
524.836	10.3919
528.335	10.3405
531.835	8.73252
535.332	8.01901
538.827	8.8002
542.321	7.68176
545.814	7.5893
549.305	7.20708
552.795	7.53375
556.282	6.36587
559.769	7.74481
563.255	7.69838
566.739	8.87499
570.223	9.12738
573.705	7.16401
577.183	6.64117
580.663	5.74104
584.141	5.33662
587.615	4.62684
591.09	4.06546
594.564	3.66941
598.035	5.07446
601.506	5.06835
604.974	4.83191
608.443	4.46284
611.908	4.25299
615.374	3.09572
618.837	3.50982
622.3	4.48966
625.761	5.43596
629.219	6.33116
632.677	7.30022
636.135	9.29524
639.59	10.5276
643.043	11.5065
646.495	13.5854
649.948	14.4227
653.398	15.9352
656.846	16.1633
660.293	16.5558
663.738	17.1215
667.183	17.8
670.626	19.0623
674.067	20.7057
677.508	23.0503
680.947	23.8794
684.385	24.9895
687.821	24.7346
691.254	26.308
694.688	27.9298
698.121	28.7133
701.552	29.081
704.98	29.8642
708.409	31.8081
711.836	33.4118
715.26	35.1858
718.685	37.5472
722.108	39.2933
725.528	41.204
728.949	43.8347
732.367	45.4212
735.785	47.914
739.2	48.9099
742.614	51.0931
746.028	53.1159
749.439	54.8769
752.849	57.2733
756.26	58.6872
759.667	59.5952
763.073	60.4335
766.477	61.7499
769.883	62.9779
773.285	65.2133
776.686	66.9755
780.085	67.5971
783.484	69.1462
786.881	69.8197
790.276	72.3867
793.671	75.8548
797.064	77.5067
800.456	79.6621
803.846	81.4874
807.234	82.0166
810.622	83.4821
814.008	84.8627
817.394	86.0473
820.778	85.2396
824.159	85.3269
827.541	85.7013
830.921	85.1124
834.298	82.9014
837.676	81.4605
841.051	79.0011
844.426	77.415
847.798	75.6578
851.171	73.8405
854.54	72.4074
857.911	70.6652
861.278	69.1462
864.645	68.3635
868.01	67.2925
871.373	66.2007
874.735	66.0316
878.097	65.061
881.457	64.352
884.815	62.9281
888.172	62.4133
891.528	62.7429
894.882	62.8411
898.237	62.1732
901.589	61.2004
904.94	60.3622
908.289	60.6812
911.635	59.2296
914.982	56.8787
918.328	55.2281
921.672	54.579
925.015	52.3277
928.357	50.1265
931.698	49.7057
935.035	48.9688
938.373	47.4126
941.71	47.6536
945.044	46.5188
948.378	44.4011
951.709	43.4413
955.041	42.1197
958.372	41.6354
961.699	40.5167
965.027	39.8204
968.352	40.8505
971.676	40.4123
975	39.941
978.322	39.9507
981.642	39.7219
984.962	39.2534
988.28	39.1728
991.596	38.0097
994.911	35.9233
998.227	34.6322
1001.54	33.7773
1004.85	32.4212
1008.16	31.5299
1011.47	30.7851
1014.78	30.0773
1018.08	28.9477
1021.39	27.8924
1024.69	27.5539
1028	26.6398
1031.3	26.3958
1034.6	24.9765
1037.9	25.0608
1041.19	25.328
1044.49	25.0924
1047.78	24.6585
1051.08	23.6456
1054.37	22.835
1057.66	21.7101
1060.95	22.5789
1064.24	21.9573
1067.53	21.4375
1070.81	20.6126
1074.1	19.8857
1077.38	20.1438
1080.66	19.4097
1083.94	17.3868
1087.22	15.4273
1090.5	14.5652
1093.78	13.99
1097.05	13.1534
1100.33	13.3213
1103.6	14.4403
1106.87	13.4264
1110.14	13.5554
1113.41	12.4022
1116.68	10.9221
1119.95	10.1123
1123.21	8.17163
1126.48	6.94219
1129.74	7.02958
1133	5.55669
1136.26	5.21441
1139.52	4.71833
1142.78	5.58596
1146.04	3.99468
1149.29	4.66796
1152.55	5.52881
1155.8	6.11083
1159.05	5.4392
1162.3	3.7119
1165.55	2.92446
1168.8	4.25067
1172.05	5.47077
1175.29	6.55197
1178.54	7.4048
1181.78	8.06151
1185.02	8.66752
1188.26	8.37317
1191.5	8.1887
1194.74	8.19233
1197.97	8.68897
1201.21	10.064
1204.44	11.6333
1207.68	14.2688
1210.91	16.261
1214.14	17.2352
1217.37	20.9311
1220.59	23.3775
1223.82	25.1794
1227.05	26.6447
1230.27	28.6128
1233.49	29.2894
1236.72	31.0018
1239.94	33.6742
1243.16	34.5684
1246.37	35.852
1249.59	37.0544
1252.8	38.4356
1256.02	38.0298
1259.23	38.6227
1262.44	38.9529
1265.66	38.1509
1268.86	37.7567
1272.07	37.1589
1275.28	37.6258
1278.48	37.6361
1281.69	37.7539
1284.89	39.3671
1288.09	40.9546
1291.29	42.0969
1294.49	41.7939
1297.69	42.1944
1300.89	42.6031
1304.08	43.0286
1307.28	44.3215
1310.47	46.9424
1313.66	49.3663
1316.85	50.6888
1320.04	52.2454
1323.23	52.6937
1326.42	53.7142
1329.61	53.9258
1332.79	54.1206
1335.97	53.1407
1339.16	52.3165
1342.34	49.0307
1345.52	48.1669
1348.7	45.604
1351.87	43.4379
1355.05	41.1523
1358.22	36.8964
1361.4	35.9951
1364.57	34.4808
1367.74	31.0377
1370.91	30.1455
1374.08	29.2644
1377.25	28.6013
1380.41	28.101
1383.58	28.84
1386.74	29.8931
1389.91	30.0727
1393.07	28.3758
1396.23	29.2356
1399.39	29.0687
1402.55	29.5709
1405.7	31.0302
1408.86	31.9119
1412.01	32.7307
1415.17	33.7242
1418.32	34.9093
1421.47	36.8119
1424.62	38.2433
1427.77	39.6183
1430.91	41.9597
1434.06	42.6633
1437.2	45.4937
1440.35	47.8281
1443.49	48.6617
1446.63	50.7644
1449.77	50.9302
1452.91	49.8735
1456.05	48.2847
1459.18	46.8535
1462.32	45.5054
1465.45	41.8641
1468.59	37.6421
1471.72	34.1227
1474.85	31.1989
1477.98	27.6802
1481.1	25.0848
1484.23	21.9816
1487.36	18.026
1490.48	14.3348
1493.61	11.672
1496.73	8.77399
1499.85	7.72109
1502.97	6.63726
1506.09	6.52991
1509.2	6.34779
1512.32	6.98226
1515.43	7.2064
1518.55	8.22897
1521.66	9.89223
1524.77	10.4523
1527.88	11.7807
1530.99	12.6716
1534.1	14.2716
1537.21	17.5464
1540.31	19.9146
1543.42	22.4432
1546.52	23.5418
1549.62	26.1211
1552.72	28.6619
1555.82	29.8315
1558.92	31.4777
1562.02	31.945
1565.11	33.2622
1568.21	34.6841
1571.3	35.9129
1574.39	38.2294
1577.49	40.4553
1580.57	42.216
1583.66	44.5273
1586.75	44.4552
1589.84	45.5986
1592.92	46.0581
1596.01	45.4553
1599.09	44.1272
1602.17	42.148
1605.25	40.7543
1608.33	39.1739
1611.41	38.6763
1614.49	39.1932
1617.57	37.7956
1620.64	37.1554
1623.72	36.9522
1626.79	37.4476
1629.86	37.8293
1632.93	39.1139
1636	41.266
1639.07	42.4887
1642.13	44.9605
1645.2	46.8216
1648.26	48.4703
1651.33	50.5829
1654.39	52.7198
1657.45	54.09
1660.51	52.7791
1663.57	51.5503
1666.63	50.9297
1669.68	47.5898
1672.74	44.96
1675.79	42.224
1678.85	40.141
1681.9	37.5387
1684.95	34.1605
1688	31.7191
1691.05	29.5357
1694.09	26.3072
1697.14	24.1518
1700.18	22.3457
1703.23	20.5367
1706.27	17.8272
1709.31	16.8702
1712.35	14.9838
1715.39	13.2455
1718.43	12.223
1721.47	9.44955
1724.5	8.96042
1727.54	8.13647
1730.57	7.28238
1733.61	5.2161
1736.64	3.54304
1739.67	3.28926
1742.7	3.3518
1745.72	2.65706
1748.75	2.20938
1751.77	2.39053
1754.8	2.4643
1757.82	2.41659
1760.84	1.83774
1763.87	2.08592
1766.89	2.63314
1769.91	2.55925
1772.92	2.85623
1775.94	2.71896
1778.95	2.23462
1781.97	1.89078
1784.98	1.95483
1787.99	1.4591
1791.01	0.816922
1794.01	0.618817
1797.02	1.09137
1800.03	1.19045
1803.04	0.373303
1806.04	-0.0495219
1809.05	0.290466
1812.05	1.22654
1815.05	2.45394
1818.05	3.06537
1821.05	3.28487
1824.05	3.40067
1827.05	3.93133
1830.04	3.66525
1833.04	3.32601
1836.03	3.80647
1839.03	4.24964
1842.02	4.62036
1845.01	4.87375
1848	4.88255
1850.99	4.15495
1853.97	3.51224
1856.96	2.60704
1859.94	1.64887
1862.93	1.12298
1865.91	1.02532
1868.89	0.648779
1871.87	0.952965
1874.85	0.923442
1877.83	1.17799
1880.81	1.33623
1882.57	1.33357
1885.56	1.5667
1888.55	1.69578
1891.54	1.73368
1894.52	2.41837
1897.51	2.73065
1900.49	2.79031
1903.47	3.78512
1906.45	4.99004
1909.43	6.48397
1912.41	6.97678
1915.39	7.51815
1918.37	7.53331
1921.34	7.86283
1924.32	8.37201
1927.29	8.58382
1930.26	8.36753
1933.23	8.57455
1936.2	8.83043
1939.17	9.52257
1942.14	9.3835
1945.11	9.93342
1948.07	9.90229
1951.04	9.35075
1954	8.9459
1956.96	8.80067
1959.93	8.53606
1962.89	8.8163
1965.85	9.10007
1968.8	9.76734
1971.76	9.73837
1974.72	10.9889
1977.67	11.4746
1980.63	10.3387
1983.58	10.7112
1986.53	11.9052
1989.48	12.5027
1992.43	12.3164
1995.38	12.8677
1998.32	12.2335
2001.27	12.7778
2004.22	12.9425
2007.16	12.2761
2010.1	12.319
2013.04	12.4243
2015.98	11.7798
2018.92	12.2237
2021.86	11.4076
2024.8	11.8421
2027.74	12.0929
2030.67	11.315
2033.61	12.3381
2036.54	12.8043
2039.47	12.5826
2042.4	12.3984
2045.33	11.9939
2048.26	11.9944
2051.19	12.1336
2054.12	12.5921
2057.04	13.3124
2059.97	13.2668
2062.89	13.4726
2065.81	14.2623
2068.73	14.9199
2071.65	14.7187
2074.57	13.4989
2077.49	13.144
2080.41	13.3226
2083.32	12.8611
2086.24	13.1923
2089.15	14.1608
2092.07	14.3656
2094.98	14.201
2097.89	13.6229
2100.8	12.3712
2103.71	12.1985
2106.61	12.1249
2109.52	11.2284
2112.43	10.7256
2115.33	11.1273
2118.23	11.3427
2121.13	11.9632
2124.04	11.9537
2126.94	12.6646
2129.83	14.444
2132.73	15.4958
2135.63	17.3988
2138.53	18.3998
2141.42	19.2149
2144.31	19.9252
2147.21	21.8015
2150.1	23.2838
2152.99	24.5561
2155.88	26.2926
2158.77	27.527
2161.65	29.0379
2164.54	29.9142
2167.43	30.0512
2170.31	30.5544
2173.19	31.0177
2176.07	32.4094
2178.96	32.0798
2181.84	31.1829
2184.72	30.9552
2187.59	29.8048
2190.47	28.8453
2193.35	27.7529
2196.22	27.8659
2199.09	27.945
2201.97	27.5884
2204.84	26.3847
2207.71	25.5431
2210.58	23.397
2213.45	22.2006
2216.31	20.1457
2219.18	18.8477
2222.05	18.0077
2224.91	17.4977
2227.78	17.033
2230.64	16.0504
2233.5	15.2015
2236.36	15.0972
2239.22	14.9796
2242.08	15.2549
2244.93	15.0735
2247.79	13.9978
2250.64	12.3904
2253.5	11.9039
2256.35	11.3179
2259.2	10.885
2262.05	11.1827
2264.9	11.594
2267.75	12.2071
2270.6	12.4788
2273.45	12.4305
2276.29	12.696
2279.14	11.9556
2281.98	11.6626
2284.82	12.073
2287.66	13.0223
2290.5	12.1761
2293.34	12.2911
2296.18	12.4594
2299.02	13.8223
2301.86	15.3282
2304.69	16.8156
2307.53	17.9844
2310.36	18.8011
2313.19	18.9667
2316.02	18.2426
2318.85	18.3373
2321.68	17.3952
2324.51	16.2329
2327.34	15.4582
2330.16	14.1093
2332.99	14.5597
2335.81	13.9427
2338.64	12.9191
2341.46	11.2173
2344.28	10.0766
2347.1	8.8552
2349.92	8.53666
2352.74	7.74431
2355.55	6.63913
2358.37	5.4054
2361.19	4.44652
2364	5.29309
2366.81	6.2768
2369.62	6.5381
2372.44	6.5941
2375.24	7.01504
2378.05	7.36971
2380.86	7.54409
2383.67	8.18972
2386.47	7.81263
2389.28	6.67052
2392.08	6.44231
2394.89	6.42278
2397.69	7.47989
2400.49	7.94393
2403.29	8.59344
2406.09	8.35446
2408.88	8.81644
2411.68	9.45989
2414.48	10.4572
2417.27	11.7414
2420.06	11.7186
2422.86	10.8489
2425.65	11.0899
2428.44	11.2185
2431.23	11.8112
2434.02	11.5801
2436.81	10.7789
2439.59	11.0286
2442.38	11.1561
2445.16	10.3517
2447.95	10.5036
2450.73	9.72181
2453.51	8.2084
2456.29	6.11935
2459.07	5.31254
2461.85	4.83817
2464.63	4.46178
2467.4	4.0581
2470.18	3.90401
2472.95	3.77473
2475.73	3.02642
2478.5	3.07162
2481.27	3.03551
2484.04	3.6805
2486.81	3.33484
2489.58	3.27111
2492.35	3.28909
2495.12	3.4901
2497.88	3.76012
2500.65	3.75398
2503.41	3.14644
2506.17	3.80589
2508.94	3.74934
2511.7	4.30356
2514.46	3.85967
2517.22	3.33351
2519.97	2.06199
2522.73	1.90257
2525.49	1.18961
2528.24	1.48908
2530.99	1.68613
2533.75	1.61978
2536.5	1.83081
2539.25	2.94571
2542	3.51268
2544.75	3.3042
2547.5	4.15677
2550.24	5.27284
2552.99	6.09438
2555.74	6.25682
2558.48	6.13697
2561.22	5.72081
2563.96	5.48041
2566.71	5.88826
2569.45	5.97816
2572.18	5.34735
2574.92	5.15729
2577.66	4.94045
2580.4	4.2351
2583.13	3.0838
2585.87	2.63389
2588.6	1.82906
2591.33	1.36103
2594.06	0.591713
2596.79	0.129162
2599.52	-0.212816
2602.25	-1.32314
2604.98	-0.744698
2607.71	-0.381744
2610.43	-0.435279
2613.16	-0.617319
2615.88	-1.05802
2618.6	-0.885805
2621.32	-0.482508
2624.04	0.104689
2626.76	0.514773
2629.48	1.0291
2632.2	2.21835
2634.92	3.87166
2637.63	4.68555
2640.35	3.90998
2643.06	4.80804
2645.77	4.86884
2648.49	5.40054
2651.2	5.29142
2653.91	4.85033
2656.62	4.51444
2659.33	4.31899
2662.03	4.01159
2664.74	3.54569
2667.44	2.61701
2670.15	2.68683
2672.85	2.8243
2675.55	2.09826
2678.26	1.45522
2680.96	1.85031
2683.66	1.8575
2686.35	2.17775
2689.05	2.38825
2691.75	2.97045
2694.44	3.31315
2697.14	4.47559
2699.83	5.12168
2702.52	5.18853
2705.22	4.9636
2707.91	5.28473
2710.6	6.16347
2713.29	7.19016
2715.97	7.62007
2718.66	7.54171
2721.35	8.16127
2724.03	9.12188
2726.72	9.29003
2729.4	9.395
2732.08	8.62282
2734.76	8.18974
2737.44	8.25797
2740.12	7.56591
2742.8	6.41429
2745.48	6.55101
2748.16	6.35101
2750.83	5.43973
2753.51	4.92413
2756.18	4.28402
2758.85	3.916
2761.53	2.3424
2764.2	1.92162
2766.87	1.90154
2769.54	1.53442
2772.2	1.00293
2774.87	1.50704
2777.54	1.07572
2780.2	1.58787
2782.87	1.33175
2785.53	1.19964
2788.19	1.48565
2790.85	2.00514
2793.51	0.917794
2796.17	0.686809
2798.83	0.703471
2801.49	0.753819
2804.15	1.16371
2806.8	1.22227
2809.46	0.969304
2812.11	1.15843
2814.76	0.616412
2817.42	0.794457
2820.07	1.43299
2822.72	3.0152
2825.37	4.30387
2828.02	5.95775
2830.66	8.36711
2833.31	11.5555
2835.96	13.8146
2838.6	16.2438
2841.24	20.7169
2843.89	24.34
2846.53	28.8888
2849.17	33.8134
2851.81	38.9197
2854.45	45.3302
2857.09	49.7636
2859.72	55.9294
2862.36	61.2692
2865	66.8754
2867.63	70.8028
2870.26	73.7558
2872.9	76.5776
2875.53	79.0952
2878.16	83.1096
2880.79	86.2671
2883.42	88.7817
2886.05	91.1446
2888.67	93.3068
2891.3	94.699
2893.92	96.4633
2896.55	99.075
2899.17	101.692
2901.79	104.611
2904.42	110.258
2907.04	115.501
2909.66	120.761
2912.27	127.279
2914.89	133.515
2917.51	139.635
2920.13	145.272
2922.74	150.097
2925.35	154.262
2927.97	157.484
2930.58	157.356
2933.19	156.257
2935.8	155.461
2938.41	153.406
2941.02	151.492
2943.63	147.166
2946.24	141.455
2948.84	136.774
2951.45	130.449
2954.05	124.613
2956.65	118.864
2959.26	113.554
2961.86	109.056
2964.46	104.504
2967.06	100.695
2969.66	97.4383
2972.25	93.1731
2974.85	89.0878
2977.45	85.329
2980.04	80.9967
2982.64	77.0734
2985.23	72.4546
2987.82	67.4159
2990.41	61.8785
2993	56.5056
2995.59	51.3298
2998.18	45.8597
3000.77	41.1609
3003.36	36.5411
3005.94	31.5588
3008.53	27.0313
3011.11	24.1566
3013.69	21.515
3016.28	18.6463
3018.86	16.3724
3021.44	14.6946
3024.02	13.6617
3026.6	12.6969
3029.18	11.6569
3031.75	11.3976
3034.33	12.0765
3036.9	11.8401
3039.48	11.9819
3042.05	12.5059
3044.62	13.2298
3047.19	14.3007
3049.77	14.4193
3052.34	14.7989
3054.9	15.9543
3057.47	15.3982
3060.04	15.3967
3062.61	14.9708
3065.17	14.5968
3067.74	14.6324
3070.3	13.6092
3072.86	12.4785
3075.42	11.6319
3077.99	9.95278
3080.54	8.27113
3083.1	6.87223
3085.66	6.11622
3088.22	5.59673
3090.78	5.1371
3093.33	4.79335
3095.89	4.43411
3098.44	4.61959
3100.99	3.70726
3103.54	2.72346
3106.1	2.60463
3108.65	2.83592
3111.2	2.54468
3113.74	2.08871
3116.29	2.02332
3118.84	1.45282
3121.38	1.56219
3123.93	1.6831
3126.47	1.24844
3129.01	1.37864
3131.56	0.70453
3134.1	0.290289
3136.64	-0.0449964
3139.18	0.425077
3141.72	0.652978
3144.26	1.16001
3146.79	1.7944
3149.33	0.327339