File: data/Raman/poly_smoothed/Thy_20_09_26_1x_45s_532 nm_x100_100%_600 gr_mm_01.txt
#Acq. time (s)=	45
#Accumulations=	2
#Range (cm-¹)=	200...3150
#Windows=	2
#Auto scanning=	Off
#Autofocus=	Off
#Macrospot=	Off
#AutoExposure=	Off
#Spike filter=	Multiple accum.
#Delay time (s)=	0
#Binning=	1
#Readout mode=	Signal
#DeNoise=	Off
#ICS correction=	On
#Dark correction=	Off
#Inst. Process=	Off
#Detector Gain=	Best Dynamic Range
#Detector ADC=	20 kHz
#Detector temperature (°C)=	-69.85
#Instrument=	LabRAM HR Evol
#Detector=	Synapse
#Objective=	x100
#Grating=	600 gr/mm
#ND Filter=	100%
#Laser (nm)=	532
#Hole=	100.021
#Range=	Auto
#Laser Pol.=	No
#Raman. Pol.=	No
#Laser Pol. (°)=	-0.0007625
#Raman Pol. (°)=	89.9995
#Collection=	Microscope
#StageXY=	Marzhauser
#StageZ=	Marzhauser
#X (µm)=	-5916
#Y (µm)=	2885
#Z (µm)=	-223.55
#Full time(mm:ss)=	3:18
#Project=
#Sample=
#Site=
#Title=	Thy_20_09_26_2x_45s_532 nm_x100_100%_600 gr_mm
#Remark=
#Date=	29.06.2022 12:29
#Acquired=	29.06.2022 12:29:04
#Base:Fit=	10.08.2022 09:52:02
#Base:Fit=	10.08.2022 09:52:12
#Base:Sub=	10.08.2022 09:54:21
#Filter:Polynom=	16.08.2022 10:24:04
#AxisType[0]=Intens
#AxisUnit[0]=Cnt
#AxisType[1]=Spectr
#AxisUnit[1]=1/cm
200.523	7.62435
204.154	11.2822
207.781	11.9751
211.409	12.569
215.034	12.0649
218.659	12.2117
222.281	13.2125
225.903	12.547
229.522	11.5939
233.14	10.3977
236.756	9.72731
240.373	8.83061
243.986	9.07858
247.598	9.14752
251.208	9.52418
254.818	8.84423
258.427	8.9376
262.034	11.042
265.638	11.7371
269.242	11.7244
272.844	10.2711
276.445	9.45912
280.044	10.7388
283.642	10.4062
287.238	8.96364
290.833	7.91644
294.425	7.69253
298.017	6.4413
301.608	7.18431
305.198	7.24207
308.786	7.4293
312.371	6.61724
315.956	6.51846
319.54	7.20228
323.122	7.31604
326.701	7.63644
330.281	8.6365
333.857	9.3608
337.434	10.0077
341.008	10.6434
344.582	9.45407
348.153	9.94597
351.724	9.08927
355.292	7.98991
358.861	6.28453
362.426	5.74067
365.99	6.27975
369.555	3.92589
373.116	2.0138
376.676	0.250517
380.236	-0.767446
383.793	-0.0122135
387.349	0.307612
390.903	1.00272
394.456	2.46014
398.007	3.04487
401.56	4.45161
405.108	5.68723
408.656	5.94377
412.202	6.25976
415.746	7.93877
419.29	9.67911
422.831	10.795
426.37	12.4956
429.909	13.6963
433.447	12.5627
436.983	12.4117
440.519	10.8807
444.052	10.2725
447.583	11.0296
451.114	11.0914
454.643	10.0772
458.169	9.74264
461.696	9.19613
465.222	9.4006
468.744	9.95934
472.267	9.92452
475.787	9.61301
479.307	10.0988
482.823	10.2746
486.341	9.76347
489.855	9.63884
493.37	10.5642
496.881	13.1065
500.391	15.8246
503.902	17.9803
507.409	19.4184
510.915	18.8856
514.42	18.9715
517.925	17.1214
521.427	14.9203
524.928	14.8725
528.427	13.9195
531.925	14.3914
535.422	14.3427
538.917	11.5735
542.411	10.5986
545.903	10.312
549.395	9.05149
552.884	8.96178
556.373	7.56077
559.86	7.05989
563.346	7.25359
566.831	7.46629
570.314	5.94354
573.794	6.39775
577.274	7.11206
580.754	7.94226
584.23	9.53813
587.706	9.74842
591.181	8.39357
594.653	7.73
598.126	6.88906
601.595	5.69105
605.065	4.99787
608.532	4.93782
611.999	4.95732
615.463	4.87683
618.928	4.40454
622.389	3.79331
625.851	4.63794
629.31	6.57273
632.767	7.48704
636.223	8.14433
639.68	8.78352
643.134	10.062
646.586	11.7662
650.037	14.1197
653.486	15.6988
656.936	18.5935
660.383	19.9622
663.829	22.0254
667.273	22.8776
670.716	24.391
674.158	24.8989
677.598	25.3218
681.035	27.9165
684.473	28.4747
687.909	28.9561
691.344	30.8125
694.778	31.7517
698.211	33.6662
701.64	34.3352
705.07	36.4393
708.498	36.451
711.924	36.0634
715.35	35.8639
718.774	36.3676
722.196	38.3231
725.618	38.7804
729.037	38.8324
732.456	39.847
735.873	42.8012
739.289	43.8197
742.703	45.5723
746.116	46.8702
749.529	49.4466
752.938	51.3868
756.347	53.6118
759.756	54.5588
763.162	57.9499
766.567	61.028
769.97	63.698
773.372	66.0679
776.773	68.0958
780.174	69.2315
783.573	71.0972
786.97	72.3006
790.365	73.4871
793.76	75.3641
797.153	76.4005
800.543	77.9739
803.933	78.1108
807.322	77.3335
810.71	77.4124
814.097	77.4588
817.483	78.834
820.865	78.0433
824.248	77.9199
827.629	77.2984
831.008	75.7412
834.387	73.4309
837.765	70.0973
841.139	69.0434
844.514	66.139
847.886	63.1895
851.259	60.539
854.629	58.5915
857.997	55.759
861.366	53.5985
864.732	52.3467
868.098	50.823
871.461	50.5164
874.823	52.4126
878.184	51.0317
881.545	50.1343
884.903	50.5087
888.26	49.6361
891.616	49.601
894.97	50.0334
898.323	49.9002
901.675	47.2311
905.026	44.905
908.375	43.8468
911.723	42.4705
915.07	41.4829
918.415	40.7283
921.76	40.3961
925.103	39.433
928.443	37.9396
931.783	39.7184
935.123	39.925
938.461	39.1469
941.796	37.4144
945.131	34.3088
948.465	33.6014
951.797	33.5068
955.128	33.4495
958.457	29.3126
961.786	27.7764
965.113	29.5199
968.44	30.5052
971.763	32.049
975.086	33.4883
978.409	33.7727
981.729	34.1103
985.048	32.9696
988.367	33.5536
991.683	34.7112
994.998	34.8676
998.312	35.3228
1001.62	35.2477
1004.94	34.3547
1008.25	32.0247
1011.56	31.5762
1014.86	29.7855
1018.17	27.5398
1021.48	23.075
1024.78	20.0742
1028.08	19.1548
1031.38	17.5664
1034.68	16.4327
1037.98	13.2783
1041.28	13.3002
1044.57	16.9058
1047.87	16.7311
1051.16	16.2151
1054.45	16.2308
1057.75	15.7301
1061.04	16.038
1064.32	16.1589
1067.61	15.5257
1070.9	15.4906
1074.18	15.786
1077.47	13.787
1080.75	13.1969
1084.03	11.6901
1087.31	11.079
1090.59	11.9584
1093.86	12.6206
1097.14	13.5723
1100.41	14.1822
1103.69	14.116
1106.96	14.4089
1110.23	15.404
1113.5	14.9708
1116.77	15.4345
1120.03	14.9356
1123.3	14.1275
1126.56	12.3114
1129.83	10.5017
1133.09	10.8059
1136.35	9.58349
1139.61	8.93359
1142.86	7.64824
1146.12	7.17643
1149.38	6.12972
1152.63	5.03138
1155.88	2.77642
1159.14	1.83439
1162.39	0.468315
1165.63	0.27803
1168.88	0.975405
1172.13	2.95626
1175.38	3.21252
1178.62	4.30518
1181.86	4.09309
1185.1	4.65475
1188.34	5.74693
1191.58	7.95786
1194.82	10.4765
1198.06	12.1911
1201.29	13.0259
1204.53	16.751
1207.76	19.894
1210.99	24.1547
1214.22	28.9695
1217.45	32.4298
1220.68	36.9103
1223.91	40.8355
1227.13	44.0145
1230.36	47.2444
1233.58	50.0473
1236.8	51.8541
1240.02	52.8021
1243.24	53.442
1246.46	55.11
1249.67	56.9526
1252.89	58.0903
1256.1	60.0388
1259.32	61.6485
1262.53	60.9165
1265.74	62.3436
1268.95	63.0324
1272.15	65.2174
1275.36	65.4902
1278.57	67.1095
1281.77	70.0338
1284.97	72.0336
1288.18	74.6935
1291.38	76.9998
1294.58	78.0726
1297.78	79.6717
1300.97	81.9168
1304.17	84.2476
1307.36	87.7009
1310.55	89.6718
1313.75	88.7305
1316.94	89.0635
1320.13	88.3279
1323.32	89.3849
1326.5	91.171
1329.69	91.8758
1332.87	91.6674
1336.06	90.714
1339.24	88.812
1342.42	86.1219
1345.6	84.5745
1348.78	82.2008
1351.96	79.8723
1355.13	77.9836
1358.31	75.3798
1361.48	72.7286
1364.65	69.4168
1367.82	66.0063
1370.99	63.2534
1374.16	60.968
1377.33	58.8232
1380.5	58.1012
1383.66	57.4086
1386.83	55.735
1389.99	52.4691
1393.15	49.8996
1396.31	48.0866
1399.47	47.6986
1402.63	48.4462
1405.78	48.3445
1408.94	48.8366
1412.1	48.8896
1415.25	50.9764
1418.4	54.7392
1421.55	58.6461
1424.7	64.7638
1427.85	69.6901
1431	75.2939
1434.14	80.1189
1437.29	82.7682
1440.43	87.4912
1443.57	90.0807
1446.71	90.8894
1449.85	91.8887
1452.99	91.5603
1456.13	90.0469
1459.26	87.8951
1462.4	83.7724
1465.54	78.2488
1468.67	72.4943
1471.8	66.8212
1474.93	60.8419
1478.06	55.5098
1481.19	49.2939
1484.31	43.9481
1487.44	38.3489
1490.56	33.9228
1493.69	31.8917
1496.81	29.7275
1499.93	27.5553
1503.05	27.337
1506.17	26.2794
1509.28	26.7825
1512.4	26.4626
1515.52	28.6252
1518.63	30.5746
1521.74	32.3557
1524.85	34.304
1527.96	36.0172
1531.07	38.4014
1534.18	40.6423
1537.29	43.4016
1540.39	46.0901
1543.5	49.1304
1546.6	52.5798
1549.7	56.3508
1552.8	59.1063
1555.9	62.6491
1559	66.3792
1562.1	69.4128
1565.19	71.5427
1568.29	74.4514
1571.38	77.2275
1574.47	80.3104
1577.56	82.7765
1580.66	84.9145
1583.74	87.3903
1586.83	88.0545
1589.92	90.1853
1593.01	89.9443
1596.09	88.9005
1599.17	87.2073
1602.25	85.7749
1605.34	84.4766
1608.41	82.3506
1611.49	80.1608
1614.57	78.8103
1617.65	77.0704
1620.72	76.3695
1623.79	76.9799
1626.87	77.3315
1629.94	78.8752
1633.01	80.1624
1636.08	81.7237
1639.15	82.8469
1642.21	85.1325
1645.28	86.7687
1648.34	88.739
1651.41	90.6822
1654.47	91.1943
1657.53	91.6555
1660.59	90.4628
1663.65	89.8604
1666.71	88.497
1669.76	84.6803
1672.82	81.3708
1675.87	75.7358
1678.93	69.7612
1681.98	65.0479
1685.03	57.6883
1688.08	51.7103
1691.13	45.1338
1694.17	40.2344
1697.22	34.4887
1700.27	30.0515
1703.31	27.0193
1706.35	22.6555
1709.39	19.2396
1712.43	16.3715
1715.47	14.2113
1718.51	13.0277
1721.55	11.6846
1724.58	9.79335
1727.62	8.46382
1730.65	8.91807
1733.68	8.72098
1736.72	9.18958
1739.74	9.16632
1742.77	9.1657
1745.8	9.55198
1748.83	7.9042
1751.85	8.07654
1754.88	7.30073
1757.9	7.16297
1760.92	6.46058
1763.95	5.27721
1766.96	5.93756
1769.98	6.20831
1773	6.17914
1776.02	6.5343
1779.03	7.28545
1782.05	7.44499
1785.06	7.24163
1788.07	6.54405
1791.08	6.69406
1794.09	5.89331
1797.1	4.36522
1800.11	3.50095
1803.12	3.3637
1806.12	4.19632
1809.12	4.49929
1812.13	4.86683
1815.13	4.85879
1818.13	5.3441
1821.13	4.91836
1824.13	4.35706
1827.13	5.0204
1830.12	5.3609
1833.12	5.60598
1836.11	5.11584
1839.1	5.08482
1842.09	5.2212
1845.09	4.97745
1848.08	4.75854
1851.06	4.98889
1854.05	5.16418
1857.04	4.83926
1860.02	4.74991
1863.01	4.33899
1865.99	4.13083
1868.97	4.29855
1871.95	3.75163
1874.93	4.1665
1877.91	4.89918
1880.89	4.93431
1882.46	5.8845
1885.45	6.27237
1888.43	6.99642
1891.42	7.11544
1894.41	7.19254
1897.39	8.00921
1900.37	7.73412
1903.36	7.66609
1906.34	7.05656
1909.32	6.71557
1912.29	6.54186
1915.27	7.08311
1918.25	5.93857
1921.23	5.97867
1924.2	6.45515
1927.17	6.24998
1930.15	6.35572
1933.12	6.82596
1936.09	7.53606
1939.06	7.88603
1942.02	7.30049
1944.99	6.44463
1947.96	5.75572
1950.92	5.46892
1953.88	6.29644
1956.85	6.18389
1959.81	5.20073
1962.77	5.37194
1965.73	4.79746
1968.69	4.29444
1971.64	4.5166
1974.6	4.29287
1977.55	5.11217
1980.51	4.78303
1983.46	4.30287
1986.41	4.00477
1989.36	3.22925
1992.31	3.34271
1995.26	3.33232
1998.21	3.129
2001.15	3.63248
2004.1	3.91556
2007.04	4.03301
2009.99	3.81068
2012.93	2.57492
2015.87	3.208
2018.81	4.00833
2021.75	5.47778
2024.68	6.07137
2027.62	5.6171
2030.56	5.43478
2033.49	5.06933
2036.42	5.91674
2039.36	5.74402
2042.29	6.53834
2045.22	6.63911
2048.14	6.88277
2051.07	6.93436
2054	6.30491
2056.93	6.29057
2059.85	6.55053
2062.77	6.97954
2065.7	6.76054
2068.62	7.03283
2071.54	7.30349
2074.46	7.04902
2077.38	7.24042
2080.29	7.23275
2083.21	7.37622
2086.12	7.64312
2089.04	9.63472
2091.95	9.02383
2094.86	9.31317
2097.77	8.98435
2100.68	9.78523
2103.59	11.4567
2106.5	11.671
2109.41	12.8896
2112.31	13.1905
2115.21	15.0083
2118.12	16.1308
2121.02	17.887
2123.92	19.4722
2126.82	21.8665
2129.72	23.942
2132.62	26.6656
2135.51	27.8221
2138.41	30.0462
2141.31	30.331
2144.2	31.9697
2147.09	33.5851
2149.98	35.2815
2152.87	36.5955
2155.76	38.9822
2158.65	40.4138
2161.54	41.698
2164.43	42.714
2167.31	44.417
2170.2	45.7162
2173.08	45.7526
2175.96	46.5696
2178.84	47.3667
2181.72	46.1587
2184.6	46.5334
2187.48	44.8958
2190.36	43.9624
2193.23	42.032
2196.11	40.5848
2198.98	38.174
2201.85	35.7903
2204.72	34.1491
2207.59	31.8683
2210.46	29.1946
2213.33	26.6716
2216.2	25.6426
2219.07	23.7813
2221.93	22.0653
2224.8	20.5696
2227.66	18.7116
2230.52	16.0548
2233.39	15.538
2236.25	13.9335
2239.1	13.4618
2241.96	13.012
2244.82	13.4162
2247.68	12.7247
2250.53	11.1793
2253.38	9.8687
2256.24	9.21804
2259.09	8.28491
2261.94	7.42842
2264.79	6.93925
2267.64	6.58528
2270.49	6.43496
2273.33	7.1751
2276.18	7.00506
2279.02	6.74596
2281.87	5.8059
2284.71	5.75933
2287.55	5.54057
2290.39	4.84648
2293.23	3.46489
2296.07	4.04055
2298.91	4.7701
2301.74	5.6298
2304.58	5.84716
2307.41	6.12024
2310.25	6.6386
2313.08	7.03709
2315.91	6.564
2318.74	5.74081
2321.57	6.17927
2324.4	6.8328
2327.23	7.05995
2330.05	6.71377
2332.88	5.79996
2335.7	5.81067
2338.52	4.73717
2341.35	4.52921
2344.17	3.98682
2346.99	2.97808
2349.81	2.62438
2352.62	2.2535
2355.44	1.91252
2358.26	0.9065
2361.07	0.560685
2363.89	1.42244
2366.7	3.70307
2369.51	4.22236
2372.32	3.35848
2375.13	3.0986
2377.94	3.52698
2380.75	2.84664
2383.56	3.45859
2386.36	2.81024
2389.17	2.98957
2391.97	3.25915
2394.77	4.02766
2397.58	3.85925
2400.38	3.75708
2403.18	3.44959
2405.97	3.21848
2408.77	3.50558
2411.57	3.66466
2414.37	3.85443
2417.16	3.63726
2419.95	3.47877
2422.75	3.69765
2425.54	3.95701
2428.33	3.92374
2431.12	4.7664
2433.91	5.51965
2436.7	5.16795
2439.48	3.52715
2442.27	2.9042
2445.05	2.9703
2447.84	2.96395
2450.62	2.08285
2453.4	1.66364
2456.18	1.46954
2458.96	1.72082
2461.74	1.93057
2464.52	2.94076
2467.29	1.93021
2470.07	1.38853
2472.85	1.34487
2475.62	0.778365
2478.39	0.498814
2481.16	0.423019
2483.93	-0.0913094
2486.7	-0.723372
2489.47	-0.0106965
2492.24	1.07646
2495.01	0.910004
2497.77	0.717644
2500.54	1.55379
2503.3	1.05649
2506.06	1.16093
2508.83	1.5925
2511.59	2.51924
2514.35	2.43631
2517.11	2.14728
2519.86	2.06627
2522.62	3.62208
2525.38	3.8703
2528.13	4.65715
2530.89	5.49186
2533.64	5.36578
2536.39	5.55325
2539.14	6.08173
2541.89	6.35993
2544.64	6.23643
2547.39	4.7603
2550.14	5.22531
2552.88	4.96927
2555.63	5.08525
2558.37	5.16782
2561.11	5.71666
2563.86	5.27934
2566.6	5.34401
2569.34	4.56261
2572.08	4.01812
2574.82	4.24476
2577.55	4.82723
2580.29	4.18738
2583.02	5.07673
2585.76	4.79705
2588.49	5.57529
2591.22	6.20636
2593.96	6.56197
2596.69	6.50221
2599.42	6.09996
2602.14	5.60964
2604.87	5.42641
2607.6	5.35374
2610.32	5.43447
2613.05	5.42432
2615.77	5.64971
2618.49	5.35957
2621.22	5.04539
2623.94	4.8029
2626.66	4.28068
2629.37	4.25515
2632.09	3.321
2634.81	2.93218
2637.53	2.28658
2640.24	2.48356
2642.96	3.57084
2645.67	4.01573
2648.38	3.75032
2651.09	3.78915
2653.8	3.05771
2656.51	3.82315
2659.22	3.67955
2661.93	3.65101
2664.63	3.12415
2667.34	3.54995
2670.04	4.21665
2672.75	6.00347
2675.45	6.78756
2678.15	7.90384
2680.85	7.89496
2683.55	8.00228
2686.25	7.49406
2688.94	7.47317
2691.64	7.41635
2694.34	7.50645
2697.03	7.48581
2699.73	6.94096
2702.42	7.16544
2705.11	6.46886
2707.8	7.36788
2710.49	7.46718
2713.18	7.54322
2715.87	7.22336
2718.55	7.47262
2721.24	8.15097
2723.93	8.78324
2726.61	8.47166
2729.29	8.02672
2731.98	8.44688
2734.66	8.38921
2737.34	9.30591
2740.02	9.2633
2742.7	8.82336
2745.37	8.70322
2748.05	7.58139
2750.72	7.09279
2753.4	6.82315
2756.07	6.74701
2758.75	6.45677
2761.42	6.12154
2764.09	6.07245
2766.76	5.25275
2769.43	5.04459
2772.1	4.95166
2774.76	4.7011
2777.43	4.29407
2780.1	4.29685
2782.76	3.41613
2785.42	3.04682
2788.09	1.90137
2790.75	0.904819
2793.41	0.721479
2796.07	0.534628
2798.73	0.0540336
2801.39	-0.213893
2804.04	-0.545021
2806.7	-0.459678
2809.35	-0.0992675
2812.01	-0.0341759
2814.66	-0.137378
2817.31	0.163692
2819.96	1.3714
2822.61	3.38182
2825.26	6.1883
2827.91	9.41883
2830.56	11.4382
2833.21	14.8763
2835.85	18.7582
2838.5	22.5587
2841.14	27.9552
2843.78	34.4394
2846.42	41.3198
2849.06	48.9652
2851.71	57.9162
2854.34	67.3481
2856.98	76.9003
2859.62	86.3535
2862.26	94.8273
2864.89	103.219
2867.53	111.186
2870.16	118.056
2872.79	124.377
2875.42	129.037
2878.05	133.061
2880.68	137.489
2883.31	141.888
2885.94	145.791
2888.57	150.139
2891.19	153.968
2893.82	157.101
2896.44	160.86
2899.07	166.806
2901.69	172.361
2904.31	181.789
2906.93	192.405
2909.55	205.086
2912.17	216.351
2914.79	229.281
2917.41	241.145
2920.02	250.88
2922.64	258.551
2925.25	265.192
2927.86	269.934
2930.48	271.792
2933.09	271.193
2935.7	268.094
2938.31	265.088
2940.92	258.443
2943.53	251.596
2946.13	243.133
2948.74	234.213
2951.34	224.582
2953.95	213.538
2956.55	202.076
2959.15	192.302
2961.75	182.66
2964.35	173.291
2966.95	164.989
2969.55	157.711
2972.15	150.598
2974.75	143.359
2977.34	135.597
2979.94	126.746
2982.53	116.9
2985.13	107.634
2987.72	98.6392
2990.31	88.9092
2992.9	79.2844
2995.49	69.0555
2998.08	60.3359
3000.67	51.868
3003.25	44.0318
3005.84	37.0251
3008.42	31.142
3011.01	26.2399
3013.59	22.2103
3016.17	16.7761
3018.76	12.8067
3021.34	10.5657
3023.92	8.65244
3026.49	6.63082
3029.07	5.34857
3031.65	5.84453
3034.23	6.26079
3036.8	7.79076
3039.38	9.87488
3041.95	11.4782
3044.52	12.5194
3047.09	14.3125
3049.66	16.1733
3052.23	17.7001
3054.8	18.0773
3057.37	19.1252
3059.94	19.2148
3062.5	18.77
3065.07	17.9168
3067.63	17.8142
3070.2	16.4811
3072.76	15.6709
3075.32	14.1082
3077.88	11.4225
3080.44	8.99497
3083	5.9656
3085.56	3.76613
3088.12	1.73705
3090.67	0.837831
3093.23	-0.0487934
3095.78	0.13362
3098.34	0.329197
3100.89	1.12759
3103.44	2.11797
3105.99	2.46971
3108.54	2.57571
3111.09	4.33061
3113.64	5.90638
3116.19	7.05385
3118.74	8.55424
3121.28	10.5301
3123.83	11.8709
3126.37	13.2522
3128.91	15.614
3131.46	17.0235
3134	19.0361
3136.54	20.8368
3139.08	21.9065
3141.62	22.7046
3144.16	24.3655
3146.69	26.6433
3149.23	28.0055