File: data/Raman/poly_smoothed/Thy_40_11_50_1x_45s_532 nm_x100_100%_600 gr_mm_02.txt
#Acq. time (s)=	45
#Accumulations=	2
#Range (cm-¹)=	200...3150
#Windows=	2
#Auto scanning=	Off
#Autofocus=	Off
#Macrospot=	Off
#AutoExposure=	Off
#Spike filter=	Multiple accum.
#Delay time (s)=	0
#Binning=	1
#Readout mode=	Signal
#DeNoise=	Off
#ICS correction=	On
#Dark correction=	Off
#Inst. Process=	Off
#Detector Gain=	Best Dynamic Range
#Detector ADC=	20 kHz
#Detector temperature (°C)=	-69.85
#Instrument=	LabRAM HR Evol
#Detector=	Synapse
#Objective=	x100
#Grating=	600 gr/mm
#ND Filter=	100%
#Laser (nm)=	532
#Hole=	100.021
#Range=	Auto
#Laser Pol.=	No
#Raman. Pol.=	No
#Laser Pol. (°)=	-0.0007625
#Raman Pol. (°)=	89.9995
#Collection=	Microscope
#StageXY=	Marzhauser
#StageZ=	Marzhauser
#X (µm)=	263.3
#Y (µm)=	1707.7
#Z (µm)=	427.05
#Full time(mm:ss)=	3:19
#Project=
#Sample=
#Site=
#Title=	Thy_40_11_50_2x_45s_532 nm_x100_100%_600 gr_mm
#Remark=
#Date=	05.07.2022 13:43
#Acquired=	05.07.2022 13:43:17
#Base:Fit=	10.08.2022 10:01:35
#Base:Sub=	10.08.2022 10:01:52
#Filter:Polynom=	16.08.2022 10:21:53
#AxisType[0]=Intens
#AxisUnit[0]=Cnt
#AxisType[1]=Spectr
#AxisUnit[1]=1/cm
200.43	5.79476
204.059	10.6293
207.688	12.1777
211.314	13.4787
214.941	14.9111
218.564	15.1153
222.186	16.0814
225.809	16.8237
229.428	15.8963
233.045	14.7014
236.663	14.2119
240.278	12.1434
243.891	12.2937
247.503	11.2682
251.116	8.57986
254.725	7.96842
258.333	7.49666
261.939	7.92569
265.544	5.91223
269.148	5.734
272.75	5.71837
276.351	5.04776
279.95	4.57322
283.548	4.75918
287.144	2.74968
290.739	2.80436
294.333	3.57634
297.925	5.8351
301.514	8.04775
305.104	9.33094
308.692	9.60675
312.279	9.67672
315.862	10.4264
319.446	10.0703
323.029	9.09515
326.608	8.63614
330.188	9.95373
333.766	10.8949
337.341	9.96199
340.917	10.2412
344.489	10.0842
348.062	11.1945
351.631	10.6595
355.201	10.4886
358.768	10.3397
362.333	9.83754
365.899	10.5826
369.462	10.1835
373.023	10.6729
376.585	11.5211
380.143	11.6199
383.7	12.396
387.256	13.1031
390.812	11.4078
394.365	9.76767
397.916	8.86554
401.467	9.08401
405.015	8.94562
408.563	6.70855
412.109	5.7323
415.654	7.29756
419.197	7.33837
422.739	7.09275
426.279	7.20073
429.819	7.96341
433.356	8.51898
436.891	9.33583
440.426	9.13099
443.96	10.5234
447.492	11.6765
451.021	15.574
454.551	16.5127
458.079	16.2352
461.604	16.5508
465.13	18.7712
468.654	19.9315
472.175	20.8692
475.696	21.4316
479.215	21.5949
482.733	23.1206
486.249	25.8536
489.765	28.2239
493.278	27.9033
496.789	29.1986
500.301	29.6705
503.81	30.722
507.317	30.9041
510.825	31.5322
514.33	30.5295
517.833	31.6567
521.335	32.129
524.836	31.0444
528.335	30.5819
531.835	30.7945
535.332	30.7369
538.827	28.8041
542.321	25.5775
545.814	24.6371
549.305	25.043
552.795	24.43
556.282	22.4306
559.769	20.7048
563.255	18.1076
566.739	17.3618
570.223	16.4084
573.705	15.1545
577.183	13.9957
580.663	12.224
584.141	10.2545
587.615	8.37717
591.09	6.8031
594.564	6.10493
598.035	6.28746
601.506	8.37961
604.974	8.96132
608.443	9.42826
611.908	9.17685
615.374	11.2805
618.837	12.5087
622.3	12.7867
625.761	13.7778
629.219	14.6554
632.677	16.4653
636.135	17.1565
639.59	18.5487
643.043	18.2343
646.495	18.4658
649.948	21.0055
653.398	22.0766
656.846	23.3787
660.293	24.2072
663.738	24.8434
667.183	25.0356
670.626	23.8961
674.067	25.5303
677.508	25.8732
680.947	27.8645
684.385	29.9122
687.821	30.5328
691.254	31.9392
694.688	33.3691
698.121	35.492
701.552	37.105
704.98	38.5575
708.409	39.7771
711.836	42.3645
715.26	43.1512
718.685	42.4263
722.108	44.4704
725.528	46.6826
728.949	47.5136
732.367	51.1278
735.785	54.2275
739.2	56.0551
742.614	57.2187
746.028	59.6065
749.439	58.8078
752.849	60.9503
756.26	63.0334
759.667	64.3962
763.073	66.2667
766.477	68.1017
769.883	70.7585
773.285	73.9497
776.686	73.6413
780.085	74.8463
783.484	76.4733
786.881	78.3356
790.276	78.3652
793.671	80.1587
797.064	81.1159
800.456	81.2743
803.846	82.9017
807.234	85.8895
810.622	86.6389
814.008	87.8093
817.394	88.2836
820.778	87.4827
824.159	86.7074
827.541	87.5087
830.921	85.3528
834.298	84.2593
837.676	84.4408
841.051	81.2727
844.426	77.4622
847.798	74.4651
851.171	71.2018
854.54	68.9861
857.911	65.9548
861.278	65.0552
864.645	65.3366
868.01	62.8996
871.373	63.3142
874.735	61.7559
878.097	59.8549
881.457	59.2799
884.815	59.5791
888.172	59.9254
891.528	59.6276
894.882	59.4979
898.237	58.4056
901.589	57.2726
904.94	55.8668
908.289	55.57
911.635	54.0905
914.982	51.2632
918.328	48.5297
921.672	46.1119
925.015	43.3812
928.357	42.3452
931.698	41.3976
935.035	40.4816
938.373	40.0389
941.71	38.8264
945.044	36.488
948.378	35.5437
951.709	37.1455
955.041	37.4082
958.372	35.684
961.699	36.4258
965.027	39.3012
968.352	42.5666
971.676	44.146
975	44.8803
978.322	45.5708
981.642	46.8177
984.962	47.2579
988.28	47.676
991.596	48.5057
994.911	46.4308
998.227	45.4064
1001.54	44.802
1004.85	44.2587
1008.16	44.1156
1011.47	42.8673
1014.78	42.1061
1018.08	42.8746
1021.39	41.3215
1024.69	40.5782
1028	41.167
1031.3	43.1449
1034.6	42.6587
1037.9	41.9184
1041.19	41.1243
1044.49	42.587
1047.78	42.5861
1051.08	40.8413
1054.37	39.2645
1057.66	36.3165
1060.95	35.2793
1064.24	33.5563
1067.53	30.577
1070.81	30.3013
1074.1	28.4284
1077.38	26.1216
1080.66	25.5733
1083.94	24.92
1087.22	25.3139
1090.5	25.6652
1093.78	25.8267
1097.05	26.7156
1100.33	27.2711
1103.6	27.5119
1106.87	28.423
1110.14	27.9755
1113.41	26.9444
1116.68	26.643
1119.95	24.1338
1123.21	22.0222
1126.48	20.1424
1129.74	17.3894
1133	15.7033
1136.26	13.7904
1139.52	11.3864
1142.78	8.81897
1146.04	7.17946
1149.29	5.78814
1152.55	4.61795
1155.8	2.40785
1159.05	2.23994
1162.3	1.13516
1165.55	0.884044
1168.8	2.02737
1172.05	1.79175
1175.29	3.32053
1178.54	4.47589
1181.78	4.01995
1185.02	4.66124
1188.26	5.77035
1191.5	6.03368
1194.74	7.08185
1197.97	8.83584
1201.21	9.99751
1204.44	12.4228
1207.68	16.7304
1210.91	20.7363
1214.14	23.5328
1217.37	27.4864
1220.59	30.45
1223.82	33.0011
1227.05	38.0031
1230.27	41.4923
1233.49	45.8827
1236.72	50.6301
1239.94	53.5322
1243.16	58.9943
1246.37	62.5038
1249.59	66.7235
1252.8	68.1863
1256.02	68.6123
1259.23	69.4107
1262.44	71.3759
1265.66	73.7271
1268.86	75.1605
1272.07	75.3429
1275.28	79.5449
1278.48	79.7269
1281.69	81.2024
1284.89	82.3268
1288.09	83.7204
1291.29	85.3668
1294.49	87.0372
1297.69	87.6975
1300.89	87.9334
1304.08	90.0672
1307.28	90.7
1310.47	91.5959
1313.66	92.585
1316.85	92.5042
1320.04	92.4572
1323.23	91.433
1326.42	89.9074
1329.61	87.3266
1332.79	83.9718
1335.97	81.5729
1339.16	78.8954
1342.34	76.4837
1345.52	73.8166
1348.7	71.2586
1351.87	68.7329
1355.05	65.4884
1358.22	61.3831
1361.4	58.9649
1364.57	56.3279
1367.74	54.97
1370.91	53.4188
1374.08	51.0766
1377.25	50.0095
1380.41	48.0893
1383.58	47.1819
1386.74	45.0007
1389.91	43.834
1393.07	42.2771
1396.23	41.3777
1399.39	38.508
1402.55	37.8533
1405.7	37.8076
1408.86	37.7007
1412.01	37.9493
1415.17	39.9724
1418.32	42.448
1421.47	46.5235
1424.62	50.5488
1427.77	54.9632
1430.91	60.9389
1434.06	65.746
1437.2	69.7831
1440.35	75.9127
1443.49	79.4163
1446.63	82.9595
1449.77	84.716
1452.91	85.2393
1456.05	84.4373
1459.18	84.0223
1462.32	80.9495
1465.45	76.6555
1468.59	71.2405
1471.72	64.8589
1474.85	58.7009
1477.98	49.7804
1481.1	44.719
1484.23	37.7091
1487.36	31.4034
1490.48	25.5991
1493.61	21.0807
1496.73	17.444
1499.85	15.2185
1502.97	14.8304
1506.09	13.2289
1509.2	14.0589
1512.32	14.7695
1515.43	13.9554
1518.55	15.1751
1521.66	16.6134
1524.77	19.0237
1527.88	21.6415
1530.99	24.7169
1534.1	27.856
1537.21	32.0038
1540.31	34.4073
1543.42	35.9546
1546.52	39.965
1549.62	42.7797
1552.72	46.6955
1555.82	50.9812
1558.92	53.3911
1562.02	56.2494
1565.11	59.4468
1568.21	62.5584
1571.3	65.5718
1574.39	69.7496
1577.49	73.6085
1580.57	77.192
1583.66	79.6932
1586.75	81.7031
1589.84	81.3444
1592.92	81.6082
1596.01	82.5371
1599.09	83.5995
1602.17	84.0974
1605.25	84.5976
1608.33	84.351
1611.41	84.6288
1614.49	84.5464
1617.57	85.3929
1620.64	87.753
1623.72	89.6147
1626.79	91.6962
1629.86	94.9493
1632.93	96.9058
1636	99.3483
1639.07	102.875
1642.13	106.401
1645.2	109.946
1648.26	111.989
1651.33	114.267
1654.39	116.32
1657.45	118.219
1660.51	117.94
1663.57	115.637
1666.63	113.047
1669.68	108.43
1672.74	103.176
1675.79	96.5719
1678.85	90.0672
1681.9	84.0025
1684.95	76.8705
1688	69.9991
1691.05	61.5642
1694.09	54.6313
1697.14	47.3267
1700.18	40.4571
1703.23	34.9754
1706.27	29.674
1709.31	25.8399
1712.35	21.5756
1715.39	19.8164
1718.43	17.4677
1721.47	16.0055
1724.5	15.2985
1727.54	14.8687
1730.57	13.8429
1733.61	15.1054
1736.64	13.6368
1739.67	12.4593
1742.7	11.4932
1745.72	10.3053
1748.75	10.5592
1751.77	10.5462
1754.8	10.4263
1757.82	9.23495
1760.84	8.14666
1763.87	7.02648
1766.89	6.75801
1769.91	6.1625
1772.92	5.06234
1775.94	4.54422
1778.95	4.47179
1781.97	4.4364
1784.98	4.03441
1787.99	4.08117
1791.01	4.31673
1794.01	3.8609
1797.02	3.9899
1800.03	3.72524
1803.04	3.17899
1806.04	3.09322
1809.05	3.3426
1812.05	2.33519
1815.05	1.51284
1818.05	1.54047
1821.05	2.00723
1824.05	1.70949
1827.05	2.03525
1830.04	1.68977
1833.04	1.6619
1836.03	1.94896
1839.03	2.07797
1842.02	1.8255
1845.01	1.80484
1848	2.12346
1850.99	2.68975
1853.97	2.81206
1856.96	3.42433
1859.94	3.45944
1862.93	3.54292
1865.91	4.08212
1868.89	3.61903
1871.87	3.62755
1874.85	3.43798
1877.83	3.77267
1880.81	4.15178
1882.57	4.26367
1885.56	4.62928
1888.55	5.20232
1891.54	4.93672
1894.52	4.28207
1897.51	3.63413
1900.49	4.36981
1903.47	3.68798
1906.45	3.73675
1909.43	2.86705
1912.41	2.64749
1915.39	3.20165
1918.37	3.56973
1921.34	3.99678
1924.32	4.31524
1927.29	4.51209
1930.26	3.98284
1933.23	3.82422
1936.2	4.25634
1939.17	4.67753
1942.14	5.99912
1945.11	5.86801
1948.07	6.70604
1951.04	7.59592
1954	6.85245
1956.96	6.69342
1959.93	5.91687
1962.89	5.52502
1965.85	4.79282
1968.8	4.95686
1971.76	4.95095
1974.72	2.84987
1977.67	1.77434
1980.63	1.02617
1983.58	0.012778
1986.53	0.0677441
1989.48	0.349441
1992.43	-0.0644375
1995.38	0.0546597
1998.32	-0.0768901
2001.27	-0.411104
2004.22	0.0766804
2007.16	1.50559
2010.1	1.6127
2013.04	2.43882
2015.98	3.6521
2018.92	4.32092
2021.86	5.30997
2024.8	6.32436
2027.74	7.71318
2030.67	9.26931
2033.61	10.6912
2036.54	11.2718
2039.47	12.7492
2042.4	13.8813
2045.33	13.2828
2048.26	13.9948
2051.19	14.7249
2054.12	14.9945
2057.04	15.8251
2059.97	16.3588
2062.89	15.6869
2065.81	16.2074
2068.73	16.7783
2071.65	16.6038
2074.57	17.3805
2077.49	18.0437
2080.41	18.3194
2083.32	18.7216
2086.24	20.525
2089.15	22.0749
2092.07	24.0079
2094.98	26.1239
2097.89	27.5469
2100.8	29.9264
2103.71	32.3939
2106.61	35.1697
2109.52	37.5446
2112.43	40.5418
2115.33	42.9783
2118.23	46.9545
2121.13	50.7013
2124.04	55.4923
2126.94	59.7971
2129.83	63.2056
2132.73	68.06
2135.63	72.2637
2138.53	77.4675
2141.42	82.2555
2144.31	86.5701
2147.21	92.4064
2150.1	96.0963
2152.99	99.7733
2155.88	103.378
2158.77	106.917
2161.65	109.803
2164.54	112.059
2167.43	115.011
2170.31	116.004
2173.19	116.417
2176.07	117.224
2178.96	115.766
2181.84	114.214
2184.72	111.372
2187.59	109.195
2190.47	106.227
2193.35	103.325
2196.22	100.514
2199.09	96.0084
2201.97	91.7151
2204.84	87.6016
2207.71	83.5086
2210.58	78.7722
2213.45	74.3063
2216.31	69.8896
2219.18	65.1638
2222.05	60.7149
2224.91	57.7217
2227.78	53.977
2230.64	50.3974
2233.5	47.8177
2236.36	46.0749
2239.22	43.4431
2242.08	40.4164
2244.93	37.1269
2247.79	34.1827
2250.64	31.7487
2253.5	30.3321
2256.35	28.5056
2259.2	27.7457
2262.05	26.7126
2264.9	25.0815
2267.75	23.9475
2270.6	22.6352
2273.45	21.4181
2276.29	20.4648
2279.14	19.4451
2281.98	17.5888
2284.82	16.6621
2287.66	15.5939
2290.5	14.0509
2293.34	11.6748
2296.18	10.82
2299.02	10.4215
2301.86	11.2215
2304.69	11.5566
2307.53	11.2514
2310.36	10.0288
2313.19	9.66767
2316.02	9.66658
2318.85	9.54772
2321.68	9.69307
2324.51	9.71765
2327.34	9.74901
2330.16	9.20353
2332.99	8.01757
2335.81	7.56243
2338.64	7.21014
2341.46	6.70734
2344.28	5.85001
2347.1	4.88666
2349.92	4.45568
2352.74	2.3255
2355.55	0.765319
2358.37	0.136514
2361.19	-1.39366
2364	-0.496508
2366.81	0.196392
2369.62	0.567057
2372.44	0.289442
2375.24	0.476445
2378.05	-0.50921
2380.86	-0.268033
2383.67	0.369438
2386.47	1.12779
2389.28	1.32101
2392.08	1.76566
2394.89	2.05868
2397.69	2.1344
2400.49	1.33762
2403.29	2.42499
2406.09	2.30481
2408.88	2.50657
2411.68	2.94771
2414.48	2.48816
2417.27	2.44542
2420.06	2.31719
2422.86	3.17496
2425.65	3.83764
2428.44	4.29492
2431.23	3.77956
2434.02	3.84601
2436.81	4.0205
2439.59	3.69679
2442.38	3.8557
2445.16	3.72095
2447.95	3.67427
2450.73	4.70925
2453.51	5.57642
2456.29	5.22533
2459.07	5.66741
2461.85	5.31084
2464.63	4.73315
2467.4	4.70147
2470.18	4.40005
2472.95	4.07262
2475.73	3.95319
2478.5	3.13814
2481.27	3.45311
2484.04	3.71754
2486.81	4.21043
2489.58	4.37617
2492.35	4.82312
2495.12	4.83572
2497.88	3.46633
2500.65	3.26557
2503.41	2.87455
2506.17	2.51537
2508.94	2.29069
2511.7	1.99257
2514.46	2.30921
2517.22	2.38256
2519.97	2.33934
2522.73	1.72263
2525.49	1.36831
2528.24	0.216912
2530.99	0.249639
2533.75	0.612643
2536.5	0.0719429
2539.25	0.0252531
2542	0.276453
2544.75	0.411102
2547.5	0.665027
2550.24	1.10038
2552.99	0.512628
2555.74	0.791104
2558.48	1.36601
2561.22	1.20428
2563.96	1.64271
2566.71	1.73104
2569.45	1.87115
2572.18	1.83161
2574.92	2.36713
2577.66	2.7106
2580.4	2.37621
2583.13	2.97288
2585.87	3.42484
2588.6	3.12746
2591.33	3.02021
2594.06	3.07144
2596.79	3.52225
2599.52	4.23111
2602.25	4.49347
2604.98	3.91446
2607.71	3.53434
2610.43	3.55791
2613.16	2.55881
2615.88	2.64278
2618.6	2.48468
2621.32	2.74716
2624.04	2.92224
2626.76	3.03902
2629.48	3.64318
2632.2	3.97843
2634.92	3.47245
2637.63	2.98044
2640.35	3.15907
2643.06	3.12396
2645.77	2.59716
2648.49	3.1036
2651.2	3.26694
2653.91	3.796
2656.62	3.02472
2659.33	2.88562
2662.03	2.90731
2664.74	3.78632
2667.44	4.28728
2670.15	3.8953
2672.85	3.42211
2675.55	3.28157
2678.26	3.1066
2680.96	3.04294
2683.66	3.7064
2686.35	3.90848
2689.05	3.74311
2691.75	4.13853
2694.44	4.35446
2697.14	4.64566
2699.83	4.91901
2702.52	4.17046
2705.22	3.86273
2707.91	4.14371
2710.6	4.48729
2713.29	4.60361
2715.97	5.37416
2718.66	6.22601
2721.35	6.52535
2724.03	6.63594
2726.72	7.27327
2729.4	8.04728
2732.08	8.89712
2734.76	8.41976
2737.44	8.23218
2740.12	8.6185
2742.8	8.72566
2745.48	9.24342
2748.16	9.04261
2750.83	8.62773
2753.51	7.86106
2756.18	6.83759
2758.85	6.64009
2761.53	5.84282
2764.2	4.48317
2766.87	3.63118
2769.54	3.31372
2772.2	2.77385
2774.87	2.27698
2777.54	2.40198
2780.2	1.91274
2782.87	1.37337
2785.53	0.713103
2788.19	0.458416
2790.85	0.383857
2793.51	0.35533
2796.17	0.396133
2798.83	0.717287
2801.49	0.495529
2804.15	0.597645
2806.8	1.61994
2809.46	0.754009
2812.11	-0.43281
2814.76	-0.636397
2817.42	-0.361704
2820.07	1.08768
2822.72	2.92364
2825.37	5.67254
2828.02	8.51617
2830.66	12.3605
2833.31	16.612
2835.96	20.176
2838.6	24.7085
2841.24	29.7974
2843.89	35.6302
2846.53	41.6278
2849.17	49.827
2851.81	59.0148
2854.45	68.6346
2857.09	79.0432
2859.72	89.7643
2862.36	99.1387
2865	108.618
2867.63	116.183
2870.26	123.745
2872.9	130.135
2875.53	135.877
2878.16	141.721
2880.79	147.895
2883.42	153.029
2886.05	159.267
2888.67	165.024
2891.3	169.4
2893.92	175.674
2896.55	180.807
2899.17	187.341
2901.79	194.825
2904.42	204.246
2907.04	214.681
2909.66	227.759
2912.27	242.21
2914.89	257.991
2917.51	273.14
2920.13	285.308
2922.74	297.551
2925.35	306.357
2927.97	312.091
2930.58	315.35
2933.19	318.482
2935.8	318.042
2938.41	314.414
2941.02	309.398
2943.63	301.807
2946.24	292.689
2948.84	282.659
2951.45	270.834
2954.05	258.343
2956.65	244.974
2959.26	231.566
2961.86	218.969
2964.46	206.094
2967.06	193.462
2969.66	181.864
2972.25	171.413
2974.85	160.8
2977.45	150.97
2980.04	140.617
2982.64	129.115
2985.23	118.055
2987.82	108.146
2990.41	97.6209
2993	87.6679
2995.59	79.1506
2998.18	69.9646
3000.77	61.5219
3003.36	54.3374
3005.94	47.1211
3008.53	41.4128
3011.11	36.3046
3013.69	31.303
3016.28	27.1258
3018.86	23.3169
3021.44	20.0748
3024.02	18.9035
3026.6	16.4708
3029.18	14.4897
3031.75	13.1027
3034.33	12.7797
3036.9	13.143
3039.48	14.3235
3042.05	15.7911
3044.62	16.1677
3047.19	17.4297
3049.77	18.5778
3052.34	19.7564
3054.9	19.842
3057.47	20.1267
3060.04	19.4702
3062.61	18.9634
3065.17	17.4219
3067.74	15.8511
3070.3	14.0485
3072.86	12.8405
3075.42	11.6384
3077.99	10.1323
3080.54	8.71141
3083.1	7.07361
3085.66	5.31877
3088.22	4.0222
3090.78	1.99205
3093.33	1.35195
3095.89	0.910029
3098.44	1.05327
3100.99	1.68953
3103.54	2.20432
3106.1	2.23062
3108.65	2.85741
3111.2	4.7248
3113.74	5.75677
3116.29	6.55373
3118.84	6.63589
3121.38	7.51115
3123.93	7.96369
3126.47	8.86294
3129.01	10.3483
3131.56	11.8634
3134.1	13.8531
3136.64	16.5386
3139.18	17.3854
3141.72	18.4961
3144.26	19.0648
3146.79	19.044
3149.33	20.3865