File: data/Raman/poly_smoothed/Thy_00_07_24_1x_45s_532 nm_x100_100%_600 gr_mm_01.txt
#Acq. time (s)=	45
#Accumulations=	2
#Range (cm-¹)=	200...3150
#Windows=	2
#Auto scanning=	Off
#Autofocus=	Off
#Macrospot=	Off
#AutoExposure=	Off
#Spike filter=	Multiple accum.
#Delay time (s)=	0
#Binning=	1
#Readout mode=	Signal
#DeNoise=	Off
#ICS correction=	On
#Dark correction=	Off
#Inst. Process=	Off
#Detector Gain=	Best Dynamic Range
#Detector ADC=	20 kHz
#Detector temperature (°C)=	-69.85
#Instrument=	LabRAM HR Evol
#Detector=	Synapse
#Objective=	x100
#Grating=	600 gr/mm
#ND Filter=	100%
#Laser (nm)=	532
#Hole=	100.021
#Range=	Auto
#Laser Pol.=	No
#Raman. Pol.=	No
#Laser Pol. (°)=	-0.0007625
#Raman Pol. (°)=	89.9995
#Collection=	Microscope
#StageXY=	Marzhauser
#StageZ=	Marzhauser
#X (µm)=	8999.2
#Y (µm)=	-3061.6
#Z (µm)=	-55.2
#Full time(mm:ss)=	3:19
#Project=
#Sample=
#Site=
#Title=	Thy_00_07_24_2x_45s_532 nm_x100_100%_600 gr_mm
#Remark=
#Date=	28.06.2022 11:53
#Acquired=	28.06.2022 11:53:48
#Base:Fit=	10.08.2022 10:07:56
#Base:Sub=	10.08.2022 10:08:40
#Filter:Polynom=	16.08.2022 10:26:06
#AxisType[0]=Intens
#AxisUnit[0]=Cnt
#AxisType[1]=Spectr
#AxisUnit[1]=1/cm
200.407	1.66349
204.035	5.05106
207.665	6.4994
211.291	6.78701
214.916	5.95962
218.541	4.44013
222.163	5.07094
225.785	5.95285
229.404	3.78861
233.022	5.25835
236.638	4.552
240.255	4.78014
243.868	4.43921
247.48	4.58867
251.091	4.52361
254.702	3.85893
258.31	4.02889
261.916	4.51549
265.521	6.56297
269.125	8.24174
272.727	8.0085
276.328	9.77496
279.927	9.77379
283.525	8.99279
287.121	9.82418
290.716	12.2507
294.31	12.4655
297.9	13.5359
301.491	13.1093
305.081	14.4979
308.669	15.1622
312.256	18.1711
315.839	19.0373
319.423	21.4176
323.006	22.0631
326.585	22.828
330.165	22.6238
333.741	24.443
337.318	26.5157
340.894	25.7866
344.466	25.9819
348.039	26.5695
351.608	25.4952
355.176	24.3666
358.745	22.3741
362.31	21.7899
365.876	20.6823
369.439	18.8776
373	18.9218
376.56	19.679
380.12	18.0906
383.677	18.3387
387.233	16.8738
390.787	14.6035
394.34	14.9511
397.894	14.4673
401.444	15.129
404.993	15.92
408.54	17.2612
412.086	19.4198
415.631	20.6946
419.174	21.8686
422.716	23.8376
426.257	22.1154
429.794	19.6881
433.332	17.7458
436.868	14.3203
440.403	13.9894
443.937	14.2345
447.468	17.0076
450.999	18.8044
454.528	19.7501
458.057	21.6599
461.582	25.1413
465.107	26.9501
468.629	28.4404
472.152	29.7543
475.672	30.9545
479.192	33.5547
482.709	35.3758
486.226	37.7392
489.74	40.5708
493.255	44.3117
496.767	45.6608
500.277	45.3618
503.788	43.205
507.295	42.7237
510.801	41.2606
514.308	38.5006
517.811	35.1467
521.313	32.6956
524.814	30.0775
528.313	28.4354
531.811	25.368
535.308	22.8664
538.803	22.6416
542.297	23.132
545.789	23.9805
549.281	23.8661
552.771	23.6124
556.259	22.1917
559.747	23.6029
563.233	23.141
566.717	22.0855
570.2	22.1875
573.68	23.2119
577.161	23.5054
580.64	23.9594
584.118	23.8104
587.593	23.3819
591.068	24.6311
594.54	25.039
598.013	23.0743
601.484	21.8423
604.952	19.5685
608.421	16.4753
611.886	14.0183
615.35	10.6557
618.815	9.56218
622.276	9.70945
625.738	8.81638
629.197	7.81604
632.655	7.15973
636.113	5.19396
639.568	4.79596
643.021	4.40561
646.473	3.98133
649.924	3.06137
653.376	4.5345
656.824	4.28287
660.271	5.90317
663.716	8.24911
667.161	8.81903
670.604	9.48631
674.045	10.328
677.486	10.9456
680.925	11.4345
684.361	11.8655
687.797	13.295
691.232	14.1375
694.666	14.9841
698.099	15.2877
701.528	16.3059
704.958	17.2741
708.387	17.0028
711.814	18.5243
715.238	21.1289
718.663	22.2217
722.084	23.3611
725.506	25.8026
728.925	26.5813
732.345	28.8588
735.761	30.6305
739.178	33.7936
742.592	36.268
746.006	40.3858
749.417	43.0141
752.827	45.6001
756.236	47.1088
759.645	49.8226
763.051	52.5928
766.456	55.1638
769.859	56.491
773.261	59.5236
776.664	59.8596
780.064	59.218
783.462	58.7396
786.859	58.3094
790.255	59.2352
793.649	59.756
797.042	60.9878
800.434	62.2506
803.823	62.2292
807.212	60.9907
810.6	61.4275
813.987	63.535
817.372	65.8923
820.754	68.2906
824.137	71.3759
827.519	75.4457
830.897	77.956
834.276	79.5939
837.654	80.1466
841.029	79.6
844.404	79.1282
847.776	78.9905
851.149	75.231
854.519	73.4148
857.889	70.333
861.256	67.0206
864.622	63.0039
867.988	58.6357
871.351	55.2841
874.713	52.0086
878.074	48.039
881.435	45.1369
884.794	42.8684
888.15	39.6214
891.506	39.6436
894.861	39.9573
898.214	41.0084
901.566	43.0375
904.916	44.8193
908.266	49.6642
911.614	53.4701
914.961	56.7992
918.306	59.144
921.651	61.016
924.994	61.695
928.336	62.36
931.674	61.4543
935.014	58.2252
938.352	57.9465
941.687	55.1766
945.022	52.3036
948.357	48.9755
951.688	44.7805
955.02	41.5341
958.348	36.5485
961.678	31.6652
965.004	31.1471
968.331	29.0893
971.655	29.1519
974.979	28.1247
978.3	28.3848
981.62	29.8564
984.941	30.9341
988.259	32.2171
991.575	34.2979
994.89	36.6931
998.204	38.3248
1001.52	40.1332
1004.83	41.756
1008.14	43.7522
1011.45	44.0216
1014.76	44.3097
1018.06	45.4179
1021.37	46.0316
1024.67	47.6466
1027.97	47.3562
1031.27	46.0216
1034.57	43.83
1037.87	41.5268
1041.17	39.5774
1044.47	39.0675
1047.76	39.1749
1051.06	37.3292
1054.35	35.1933
1057.64	32.1828
1060.93	30.9288
1064.22	29.0954
1067.5	28.6385
1070.79	28.6116
1074.08	29.8381
1077.36	30.5012
1080.64	32.2797
1083.92	33.532
1087.2	35.0956
1090.48	36.6958
1093.76	39.8142
1097.03	43.4117
1100.31	45.6146
1103.58	47.9482
1106.85	49.7676
1110.12	51.0388
1113.39	50.2374
1116.66	49.8325
1119.93	48.493
1123.19	48.6014
1126.46	48.1001
1129.72	46.8929
1132.98	44.7335
1136.24	41.7848
1139.5	38.358
1142.76	35.9034
1146.01	32.735
1149.27	29.1189
1152.53	26.6249
1155.78	22.9359
1159.03	19.2475
1162.28	14.3183
1165.53	10.9103
1168.78	8.76495
1172.02	8.0308
1175.27	7.90328
1178.51	7.70059
1181.76	8.13998
1185	8.13021
1188.24	9.18684
1191.48	10.0886
1194.71	11.6593
1197.95	12.486
1201.19	15.7041
1204.42	20.674
1207.65	24.1349
1210.88	27.8358
1214.12	31.7867
1217.35	36.371
1220.57	40.9894
1223.8	43.7772
1227.03	48.8651
1230.25	54.222
1233.47	57.3581
1236.69	58.9268
1239.92	60.7935
1243.13	62.3327
1246.35	64.1428
1249.57	65.3859
1252.78	66.2611
1256	66.3771
1259.21	66.0722
1262.42	65.7606
1265.63	63.4822
1268.84	62.2296
1272.05	60.4873
1275.26	58.2577
1278.46	57.6083
1281.67	58.7238
1284.87	59.7532
1288.07	59.4429
1291.27	59.6555
1294.47	61.2992
1297.67	62.3006
1300.87	63.4398
1304.06	67.1784
1307.26	72.8187
1310.45	77.002
1313.64	80.5575
1316.83	83.5641
1320.02	87.9951
1323.21	92.1108
1326.4	96.4323
1329.59	100.108
1332.77	102.862
1335.95	104.512
1339.14	105.819
1342.32	105.813
1345.5	104.248
1348.67	101.359
1351.85	99.2229
1355.03	97.3725
1358.2	92.9362
1361.38	88.5057
1364.55	83.296
1367.72	78.5353
1370.89	74.2797
1374.06	70.7999
1377.23	67.902
1380.39	66.477
1383.56	64.7472
1386.72	63.3021
1389.89	61.9078
1393.05	59.6525
1396.21	58.1185
1399.37	59.7887
1402.52	61.357
1405.68	62.371
1408.84	64.5014
1411.99	64.8006
1415.15	68.0333
1418.3	71.8523
1421.45	75.2065
1424.6	79.6685
1427.75	85.355
1430.89	91.5096
1434.04	96.1583
1437.18	100.542
1440.33	105.095
1443.47	109.673
1446.61	110.913
1449.75	111.571
1452.89	112.129
1456.03	110.811
1459.16	106.38
1462.3	100.854
1465.43	93.9029
1468.56	85.7055
1471.7	77.3971
1474.83	69.2079
1477.96	60.8361
1481.08	52.4762
1484.21	45.791
1487.34	38.5588
1490.46	32.7637
1493.58	27.8056
1496.71	24.743
1499.83	22.3591
1502.95	20.3065
1506.07	20.0191
1509.18	20.0541
1512.3	18.7308
1515.41	18.8457
1518.53	20.0926
1521.64	20.3706
1524.75	19.4189
1527.86	21.5196
1530.97	22.962
1534.08	22.7862
1537.19	24.0439
1540.29	25.1131
1543.4	26.8973
1546.5	31.0793
1549.6	34.4755
1552.7	37.1882
1555.8	40.8965
1558.9	44.9824
1562	48.4666
1565.09	51.4278
1568.19	52.8921
1571.28	57.0861
1574.37	60.6239
1577.47	65.7385
1580.56	68.1187
1583.64	71.6192
1586.73	74.692
1589.82	75.467
1592.9	77.3867
1595.99	77.8459
1599.07	76.2003
1602.15	75.396
1605.23	74.6402
1608.31	72.4329
1611.39	68.4588
1614.47	68.7997
1617.55	71.6141
1620.62	74.3796
1623.7	74.4155
1626.77	76.7384
1629.84	78.2828
1632.91	79.357
1635.98	80.9433
1639.05	82.8141
1642.11	83.5384
1645.18	87.3175
1648.24	90.4249
1651.31	92.2963
1654.37	93.6205
1657.43	92.7213
1660.49	91.1427
1663.55	89.607
1666.61	84.5104
1669.66	80.8635
1672.72	74.3086
1675.77	69.1837
1678.83	62.9425
1681.88	56.204
1684.93	48.8052
1687.98	45.5297
1691.03	45.0717
1694.07	40.5615
1697.12	35.5939
1700.17	31.7327
1703.21	28.7756
1706.25	24.6037
1709.29	22.6128
1712.33	19.3615
1715.37	18.7238
1718.41	16.4575
1721.45	14.7557
1724.49	13.6337
1727.52	12.7013
1730.55	10.1889
1733.59	9.03928
1736.62	8.52146
1739.65	6.73494
1742.68	4.92269
1745.7	4.39865
1748.73	4.18941
1751.76	2.79778
1754.78	2.01096
1757.8	1.55137
1760.83	2.41423
1763.85	2.30196
1766.87	2.21781
1769.89	2.25282
1772.9	1.16827
1775.92	2.23397
1778.94	2.22091
1781.95	2.41743
1784.96	3.3041
1787.97	3.49704
1790.99	4.59326
1794	5.43428
1797	6.12546
1800.01	6.22097
1803.02	5.01846
1806.02	4.29003
1809.03	4.09287
1812.03	3.95444
1815.03	3.86724
1818.03	3.65968
1821.03	4.74525
1824.03	4.27578
1827.03	4.69815
1830.02	4.14788
1833.02	4.19946
1836.01	4.23012
1839.01	4.24313
1842	3.71012
1844.99	2.98413
1847.98	2.64999
1850.97	3.50151
1853.95	3.27893
1856.94	2.91068
1859.93	4.00743
1862.91	4.0179
1865.89	3.22483
1868.87	4.15636
1871.85	3.57576
1874.83	3.24307
1877.81	2.52624
1880.79	3.21347
1882.52	3.2898
1885.51	3.07334
1888.5	3.0127
1891.49	3.55666
1894.47	3.24834
1897.46	3.03319
1900.44	2.5319
1903.42	3.33006
1906.4	3.93974
1909.38	4.48299
1912.36	4.9937
1915.34	4.82514
1918.32	5.79899
1921.29	6.72789
1924.27	7.99177
1927.24	8.34523
1930.21	9.32393
1933.18	10.1449
1936.15	10.6562
1939.12	11.7993
1942.09	11.4968
1945.06	10.5578
1948.02	9.48632
1950.99	8.49911
1953.95	8.61837
1956.91	6.38279
1959.88	5.98704
1962.84	4.69053
1965.8	3.56198
1968.75	1.92825
1971.71	1.04905
1974.67	0.514538
1977.62	1.12284
1980.58	1.37874
1983.53	1.73837
1986.48	2.45896
1989.43	4.02154
1992.38	5.62243
1995.33	6.503
1998.27	7.82522
2001.22	7.46587
2004.16	8.35069
2007.11	8.21005
2010.05	8.52124
2012.99	8.28842
2015.93	7.91794
2018.87	8.54369
2021.81	7.98912
2024.75	8.97082
2027.69	8.60516
2030.62	7.80638
2033.56	8.59317
2036.49	7.89974
2039.42	7.45211
2042.35	7.84387
2045.28	8.00298
2048.21	8.44907
2051.14	8.40619
2054.07	7.66677
2056.99	8.21275
2059.92	7.84294
2062.84	6.1808
2065.76	5.45183
2068.68	4.9898
2071.6	3.77384
2074.52	2.6146
2077.44	2.61502
2080.36	2.38188
2083.27	2.1061
2086.19	2.2036
2089.1	2.22511
2092.02	2.78761
2094.93	2.26297
2097.84	2.64049
2100.75	2.78036
2103.66	4.45493
2106.56	4.19898
2109.47	5.56344
2112.38	4.53514
2115.28	5.55171
2118.18	6.06739
2121.09	5.07553
2123.99	5.69191
2126.89	6.60495
2129.79	6.34395
2132.68	6.9722
2135.58	7.05825
2138.48	9.58562
2141.37	9.33536
2144.27	9.96987
2147.16	10.8174
2150.05	11.5723
2152.94	12.0013
2155.83	12.3713
2158.72	11.8437
2161.6	12.2084
2164.49	11.3544
2167.38	10.5383
2170.26	10.661
2173.14	11.1145
2176.03	11.2137
2178.91	10.8942
2181.79	10.7517
2184.67	9.9391
2187.54	10.4218
2190.42	9.85104
2193.3	9.80251
2196.17	9.32025
2199.05	8.55803
2201.92	8.17316
2204.79	7.54835
2207.66	8.4544
2210.53	8.15324
2213.4	7.78501
2216.27	7.05647
2219.13	7.64915
2222	7.74216
2224.86	6.80303
2227.72	6.04552
2230.59	5.73538
2233.45	6.11905
2236.31	5.44564
2239.17	5.46555
2242.03	7.01063
2244.88	7.42879
2247.74	7.97829
2250.59	7.98186
2253.45	8.44767
2256.3	8.29769
2259.15	7.43861
2262	6.87141
2264.85	5.93267
2267.7	5.54555
2270.55	5.58739
2273.4	7.39484
2276.24	6.85515
2279.09	6.82901
2281.93	6.58598
2284.77	5.80974
2287.62	5.57083
2290.46	5.64595
2293.3	4.6748
2296.13	5.06104
2298.97	6.47035
2301.81	7.67787
2304.64	8.27448
2307.48	9.03836
2310.31	10.5986
2313.14	10.8324
2315.98	11.3582
2318.81	10.9052
2321.64	10.0168
2324.46	10.0673
2327.29	9.09249
2330.12	8.93359
2332.94	7.57568
2335.77	7.47228
2338.59	6.45272
2341.41	6.71763
2344.23	5.70792
2347.05	3.24514
2349.87	2.42196
2352.69	1.0191
2355.51	0.352154
2358.32	0.281548
2361.14	-0.514589
2363.95	0.155499
2366.76	1.46418
2369.58	2.09477
2372.39	2.6802
2375.2	3.50602
2378	3.8504
2380.81	5.72074
2383.62	7.11637
2386.43	7.73464
2389.23	7.89732
2392.03	7.70331
2394.84	7.51048
2397.64	6.89654
2400.44	7.73825
2403.24	8.12596
2406.04	8.59792
2408.84	9.06881
2411.63	9.66672
2414.43	9.51884
2417.22	9.48474
2420.02	9.08878
2422.81	9.76286
2425.6	10.195
2428.39	10.3754
2431.18	10.1957
2433.97	9.90613
2436.76	9.64351
2439.54	10.9411
2442.33	10.5416
2445.12	11.0485
2447.9	11.2575
2450.68	10.5833
2453.46	9.20088
2456.24	7.89
2459.02	7.6544
2461.8	5.958
2464.58	6.00659
2467.36	5.35054
2470.13	5.13139
2472.91	4.87225
2475.68	4.99134
2478.45	4.70163
2481.23	4.36109
2484	3.86593
2486.77	2.82536
2489.54	1.85441
2492.3	2.02397
2495.07	1.18413
2497.84	0.828519
2500.6	-0.149482
2503.36	0.0677064
2506.13	-0.526557
2508.89	-0.419037
2511.65	0.690234
2514.41	0.670273
2517.17	1.66941
2519.93	1.04054
2522.68	2.24714
2525.44	2.21826
2528.19	2.57176
2530.95	3.07556
2533.7	2.52444
2536.45	3.44319
2539.2	4.42545
2541.95	4.86385
2544.7	5.21259
2547.45	5.77835
2550.2	6.00569
2552.94	5.95812
2555.69	6.07472
2558.43	4.94253
2561.18	6.1227
2563.92	4.97184
2566.66	4.2131
2569.4	3.13047
2572.14	1.43695
2574.88	2.13008
2577.61	3.43505
2580.35	3.76798
2583.09	2.30635
2585.82	2.45488
2588.55	1.51301
2591.29	0.551088
2594.02	0.537156
2596.75	0.295149
2599.48	-0.00869749
2602.21	0.346963
2604.93	1.59971
2607.66	2.043
2610.39	2.59441
2613.11	3.28714
2615.83	2.53803
2618.56	3.14476
2621.28	3.43577
2624	2.77254
2626.72	4.22247
2629.44	4.70995
2632.15	4.17667
2634.87	4.18569
2637.59	4.77885
2640.3	6.20958
2643.02	6.44165
2645.73	7.1763
2648.44	6.70477
2651.15	6.79275
2653.86	6.87692
2656.57	7.14867
2659.28	7.06553
2661.99	6.76594
2664.69	6.26481
2667.4	6.26399
2670.1	6.11543
2672.81	5.39613
2675.51	5.68228
2678.21	4.55148
2680.91	4.29203
2683.61	4.48104
2686.31	3.96687
2689	4.26962
2691.7	4.62113
2694.4	5.26914
2697.09	4.79223
2699.79	5.81848
2702.48	7.30718
2705.17	8.66885
2707.86	9.2029
2710.55	10.5579
2713.24	11.3245
2715.93	11.5646
2718.62	12.1569
2721.3	12.6494
2723.99	11.904
2726.67	10.9117
2729.35	11.0349
2732.04	11.386
2734.72	11.6284
2737.4	11.2487
2740.08	10.9437
2742.76	11.0387
2745.43	9.58083
2748.11	9.97599
2750.79	9.17848
2753.46	9.39677
2756.14	9.02152
2758.81	8.21508
2761.48	8.55135
2764.15	9.06003
2766.82	9.17159
2769.49	8.70772
2772.16	8.41303
2774.82	7.31131
2777.49	6.50286
2780.16	5.33915
2782.82	5.21927
2785.48	3.94197
2788.15	2.82551
2790.81	1.76244
2793.47	2.20723
2796.13	2.175
2798.79	0.752225
2801.44	0.0455997
2804.1	0.0065628
2806.76	-0.131002
2809.41	-0.628764
2812.07	0.00145174
2814.72	0.646029
2817.37	2.6094
2820.02	4.68798
2822.67	8.45479
2825.32	13.2123
2827.97	18.3901
2830.62	23.5692
2833.26	29.9299
2835.91	35.5375
2838.56	44.062
2841.2	53.1009
2843.84	64.0585
2846.48	74.2041
2849.12	84.8139
2851.77	96.5133
2854.4	109.51
2857.04	122.709
2859.68	135.537
2862.32	147.771
2864.95	159.613
2867.59	173.156
2870.22	184.185
2872.85	194.893
2875.48	206.187
2878.11	216.256
2880.74	225.589
2883.37	235.613
2886	244.327
2888.63	253.33
2891.25	261.737
2893.88	270.147
2896.5	278.544
2899.13	287.23
2901.75	296.964
2904.37	306.424
2906.99	317.24
2909.61	327.566
2912.23	338.534
2914.85	350.086
2917.46	360.669
2920.08	369.003
2922.7	374.4
2925.31	377.574
2927.92	380.141
2930.54	380.971
2933.15	378.474
2935.76	374.005
2938.37	368.573
2940.98	359.429
2943.58	348.25
2946.19	336.325
2948.8	323.278
2951.4	310.954
2954.01	296.424
2956.61	282.522
2959.21	268.307
2961.81	254.92
2964.41	241.333
2967.01	227.926
2969.61	216.362
2972.21	205.483
2974.81	194.374
2977.4	183.37
2980	170.784
2982.59	158.693
2985.18	145.441
2987.78	132.183
2990.37	120.328
2992.96	108.425
2995.55	96.3816
2998.14	85.3213
3000.73	74.2756
3003.31	62.6324
3005.9	51.7045
3008.48	43.2142
3011.07	34.8661
3013.65	27.4134
3016.23	21.4096
3018.81	14.5067
3021.4	10.8751
3023.97	6.97244
3026.55	4.38906
3029.13	2.64805
3031.71	1.48863
3034.28	2.31567
3036.86	2.92661
3039.43	5.09467
3042.01	7.38045
3044.58	9.48192
3047.15	12.1484
3049.72	14.7345
3052.29	16.6852
3054.86	18.6034
3057.43	20.226
3060	20.9926
3062.56	19.9531
3065.13	19.6273
3067.69	17.6731
3070.26	16.1845
3072.82	15.4364
3075.38	13.7777
3077.94	12.4333
3080.5	10.9579
3083.06	8.79277
3085.62	5.89577
3088.18	5.07945
3090.73	2.93693
3093.29	1.51894
3095.84	1.99629
3098.4	2.52598
3100.95	2.78984
3103.5	3.83828
3106.05	5.54578
3108.6	6.46589
3111.15	8.66508
3113.7	10.2261
3116.25	12.1686
3118.79	14.326
3121.34	15.7727
3123.88	17.2626
3126.43	19.8066
3128.97	21.6569
3131.51	24.0887
3134.06	27.2795
3136.6	30.074
3139.14	32.7601
3141.67	35.1565
3144.21	36.2381
3146.75	38.1789
3149.29	39.617