File: data/Raman/poly_smoothed/Thy_20_09_44_1x_45s_532 nm_x100_100%_600 gr_mm_01.txt
#Acq. time (s)=	45
#Accumulations=	2
#Range (cm-¹)=	200...3150
#Windows=	2
#Auto scanning=	Off
#Autofocus=	Off
#Macrospot=	Off
#AutoExposure=	Off
#Spike filter=	Multiple accum.
#Delay time (s)=	0
#Binning=	1
#Readout mode=	Signal
#DeNoise=	Off
#ICS correction=	On
#Dark correction=	Off
#Inst. Process=	Off
#Detector Gain=	Best Dynamic Range
#Detector ADC=	20 kHz
#Detector temperature (°C)=	-69.85
#Instrument=	LabRAM HR Evol
#Detector=	Synapse
#Objective=	x100
#Grating=	600 gr/mm
#ND Filter=	100%
#Laser (nm)=	532
#Hole=	100.021
#Range=	Auto
#Laser Pol.=	No
#Raman. Pol.=	No
#Laser Pol. (°)=	-0.0007625
#Raman Pol. (°)=	89.9995
#Collection=	Microscope
#StageXY=	Marzhauser
#StageZ=	Marzhauser
#X (µm)=	-5910.8
#Y (µm)=	2845.8
#Z (µm)=	-223.8
#Full time(mm:ss)=	3:19
#Project=
#Sample=
#Site=
#Title=	Thy_20_09_44_2x_45s_532 nm_x100_100%_600 gr_mm
#Remark=
#Date=	29.06.2022 13:45
#Acquired=	29.06.2022 13:45:21
#Base:Fit=	10.08.2022 09:52:02
#Base:Fit=	10.08.2022 09:52:12
#Base:Sub=	10.08.2022 09:54:21
#Filter:Polynom=	16.08.2022 10:24:04
#AxisType[0]=Intens
#AxisUnit[0]=Cnt
#AxisType[1]=Spectr
#AxisUnit[1]=1/cm
200.523	-2.11592
204.154	0.739937
207.781	1.33346
211.409	3.69132
215.034	4.62088
218.659	5.82274
222.281	5.71833
225.903	6.96561
229.522	7.8588
233.14	10.0978
236.756	9.73241
240.373	9.88875
243.986	8.56072
247.598	9.31045
251.208	9.62588
254.818	10.0507
258.427	8.83074
262.034	7.75172
265.638	7.11937
269.242	6.29177
272.844	6.81109
276.445	7.34525
280.044	7.88224
283.642	8.11343
287.238	9.03597
290.833	9.32721
294.425	11.099
298.017	13.8128
301.608	12.593
305.198	14.93
308.786	15.4245
312.371	17.1418
315.956	19.5212
319.54	20.7933
323.122	20.6952
326.701	21.1285
330.281	21.8764
333.857	21.8838
337.434	22.3077
341.008	21.9168
344.582	20.0773
348.153	17.2444
351.724	16.7077
355.292	15.8461
358.861	15.4426
362.426	15.6732
365.99	14.7598
369.555	14.5168
373.116	14.4127
376.676	15.6957
380.236	15.8081
383.793	15.139
387.349	14.5201
390.903	13.9915
394.456	12.6282
398.007	11.7733
401.56	11.4581
405.108	10.0343
408.656	10.634
412.202	9.71343
415.746	9.66329
419.29	8.7008
422.831	8.22011
426.37	7.968
429.909	8.48401
433.447	8.01597
436.983	8.0233
440.519	8.73991
444.052	10.2908
447.583	12.2476
451.114	14.0362
454.643	15.3955
458.169	15.9922
461.696	18.6247
465.222	20.3659
468.744	19.6671
472.267	20.9366
475.787	21.3022
479.307	21.6899
482.823	21.7578
486.341	23.306
489.855	24.0696
493.37	24.8303
496.881	25.3138
500.391	26.4478
503.902	28.0902
507.409	30.0242
510.915	30.7023
514.42	30.2016
517.925	29.9623
521.427	29.0014
524.928	28.4976
528.427	29.4151
531.925	27.748
535.422	27.7107
538.917	26.8578
542.411	25.6507
545.903	25.9666
549.395	25.5204
552.884	24.034
556.373	21.5898
559.86	18.9926
563.346	18.2995
566.831	16.4104
570.314	14.7143
573.794	13.5033
577.274	12.0884
580.754	10.9632
584.23	9.90798
587.706	10.2829
591.181	10.6441
594.653	9.78581
598.126	8.4455
601.595	9.03672
605.065	11.2353
608.532	12.087
611.999	13.263
615.463	15.0144
618.928	16.9139
622.389	18.9517
625.851	19.8658
629.31	21.6819
632.767	23.496
636.223	23.1667
639.68	22.7053
643.134	24.9438
646.586	26.9107
650.037	28.968
653.486	30.1734
656.936	31.1407
660.383	32.0133
663.829	32.7113
667.273	33.2763
670.716	34.6751
674.158	35.5859
677.598	36.6027
681.035	36.7286
684.473	37.9626
687.909	39.7503
691.344	39.5266
694.778	40.4987
698.211	41.5472
701.64	43.2689
705.07	44.2356
708.498	45.0362
711.924	46.2196
715.35	48.8818
718.774	47.7787
722.196	48.5427
725.618	50.6789
729.037	54.7902
732.456	56.3822
735.873	58.3174
739.289	58.5685
742.703	59.2446
746.116	62.3573
749.529	64.5009
752.938	65.4602
756.347	68.567
759.756	70.3431
763.162	71.9698
766.567	73.5027
769.97	75.9855
773.372	77.4142
776.773	80.8983
780.174	83.3375
783.573	85.6851
786.97	88.5549
790.365	90.0481
793.76	91.8445
797.153	91.9557
800.543	91.424
803.933	90.7904
807.322	90.9032
810.71	90.7476
814.097	90.1022
817.483	88.0913
820.865	87.8114
824.248	85.5778
827.629	84.1526
831.008	81.6514
834.387	78.3581
837.765	76.5513
841.139	74.9693
844.514	72.5912
847.886	71.2117
851.259	67.7609
854.629	64.8157
857.997	63.7623
861.366	63.3076
864.732	62.0103
868.098	60.9336
871.461	59.9112
874.823	60.602
878.184	58.873
881.545	57.0048
884.903	56.1542
888.26	54.4728
891.616	54.7382
894.97	54.6996
898.323	54.4597
901.675	53.9074
905.026	52.2993
908.375	50.8493
911.723	48.7709
915.07	49.372
918.415	48.3417
921.76	48.9122
925.103	48.1845
928.443	47.5498
931.783	46.1848
935.123	45.1709
938.461	44.46
941.796	43.4137
945.131	42.4188
948.465	43.4667
951.797	43.1171
955.128	42.4471
958.457	41.1047
961.786	38.0382
965.113	37.7654
968.44	38.2467
971.763	38.8876
975.086	39.3202
978.409	40.07
981.729	40.8004
985.048	39.7448
988.367	40.2654
991.683	39.4753
994.998	37.363
998.312	36.2384
1001.62	36.0668
1004.94	34.8987
1008.25	36.1112
1011.56	36.0665
1014.86	34.0658
1018.17	32.9556
1021.48	30.6754
1024.78	30.4429
1028.08	29.2349
1031.38	29.1828
1034.68	27.6065
1037.98	25.4417
1041.28	23.2865
1044.57	22.9914
1047.87	24.1974
1051.16	23.6717
1054.45	24.4388
1057.75	24.2763
1061.04	24.6391
1064.32	25.7417
1067.61	24.4463
1070.9	22.3601
1074.18	21.6872
1077.47	20.4642
1080.75	19.7746
1084.03	19.491
1087.31	20.1848
1090.59	20.6491
1093.86	19.231
1097.14	18.4271
1100.41	19.2356
1103.69	18.4484
1106.96	17.6579
1110.23	15.5746
1113.5	13.7158
1116.77	11.4163
1120.03	9.54589
1123.3	9.38538
1126.56	9.58757
1129.83	10.5207
1133.09	8.85386
1136.35	8.76234
1139.61	9.47891
1142.86	10.4243
1146.12	9.63824
1149.38	8.20594
1152.63	7.85052
1155.88	9.0585
1159.14	9.56986
1162.39	9.81965
1165.63	10.4877
1168.88	12.6958
1172.13	15.2619
1175.38	15.6109
1178.62	17.3498
1181.86	17.7556
1185.1	19.2311
1188.34	19.4057
1191.58	19.6639
1194.82	20.6081
1198.06	21.7529
1201.29	23.4532
1204.53	25.9011
1207.76	26.8113
1210.99	28.7505
1214.22	30.2865
1217.45	33.3249
1220.68	36.0892
1223.91	38.3489
1227.13	38.6102
1230.36	40.9606
1233.58	44.5767
1236.8	46.7209
1240.02	47.0711
1243.24	49.0013
1246.46	50.908
1249.67	53.8187
1252.89	54.5681
1256.1	55.5842
1259.32	57.6305
1262.53	58.2153
1265.74	59.3317
1268.95	59.943
1272.15	60.9288
1275.36	61.7001
1278.57	63.783
1281.77	67.6729
1284.97	70.4739
1288.18	72.9961
1291.38	74.7071
1294.58	75.7118
1297.78	78.5405
1300.97	79.5216
1304.17	79.9218
1307.36	80.6167
1310.55	81.6454
1313.75	81.8397
1316.94	82.0189
1320.13	82.7479
1323.32	81.5911
1326.5	80.7387
1329.69	80.3406
1332.87	78.7031
1336.06	76.9117
1339.24	74.3183
1342.42	74.0148
1345.6	72.3916
1348.78	71.7175
1351.96	68.6758
1355.13	65.6603
1358.31	64.935
1361.48	62.5971
1364.65	60.6954
1367.82	57.9916
1370.99	56.716
1374.16	56.3044
1377.33	55.6008
1380.5	54.8387
1383.66	53.4273
1386.83	52.8751
1389.99	52.1343
1393.15	51.3516
1396.31	51.1108
1399.47	50.7849
1402.63	48.3062
1405.78	48.8205
1408.94	48.5856
1412.1	50.6663
1415.25	51.8724
1418.4	54.9967
1421.55	57.2231
1424.7	59.2282
1427.85	62.4838
1431	65.0971
1434.14	68.998
1437.29	72.3183
1440.43	75.9028
1443.57	77.8862
1446.71	79.9815
1449.85	80.7678
1452.99	81.8054
1456.13	81.064
1459.26	79.5502
1462.4	76.5461
1465.54	72.8769
1468.67	67.9372
1471.8	62.5677
1474.93	57.4025
1478.06	50.9931
1481.19	45.3406
1484.31	41.0101
1487.44	38.3293
1490.56	36.1136
1493.69	33.7666
1496.81	31.5516
1499.93	30.3818
1503.05	29.9159
1506.17	29.6685
1509.28	29.657
1512.4	30.0602
1515.52	31.4455
1518.63	31.1998
1521.74	33.8069
1524.85	35.1132
1527.96	37.6487
1531.07	38.6794
1534.18	39.5696
1537.29	41.4071
1540.39	42.1643
1543.5	43.4801
1546.6	44.7961
1549.7	47.0306
1552.8	49.8224
1555.9	51.9096
1559	54.3374
1562.1	58.2408
1565.19	61.6932
1568.29	62.9172
1571.38	66.914
1574.47	69.3412
1577.56	72.2169
1580.66	74.7246
1583.74	77.4272
1586.83	79.7885
1589.92	81.9209
1593.01	83.7308
1596.09	84.672
1599.17	85.2833
1602.25	84.5885
1605.34	82.2279
1608.41	81.5819
1611.49	79.0269
1614.57	77.283
1617.65	76.0318
1620.72	74.812
1623.79	74.4327
1626.87	73.2914
1629.94	71.5941
1633.01	70.3306
1636.08	71.326
1639.15	71.8587
1642.21	71.508
1645.28	72.479
1648.34	73.6729
1651.41	74.1605
1654.47	73.4546
1657.53	74.1888
1660.59	72.8587
1663.65	71.0013
1666.71	69.0938
1669.76	66.4764
1672.82	64.6503
1675.87	61.306
1678.93	57.0143
1681.98	52.983
1685.03	48.4867
1688.08	43.6354
1691.13	40.3128
1694.17	35.5958
1697.22	32.1557
1700.27	29.4116
1703.31	27.3139
1706.35	25.1874
1709.39	23.1707
1712.43	21.1908
1715.47	19.9612
1718.51	17.7206
1721.55	17.0294
1724.58	15.3321
1727.62	15.0763
1730.65	12.7208
1733.68	11.3003
1736.72	10.3396
1739.74	10.2977
1742.77	9.62755
1745.8	8.38314
1748.83	8.57299
1751.85	7.40437
1754.88	5.93785
1757.9	5.77821
1760.92	4.80173
1763.95	3.4251
1766.96	3.2501
1769.98	3.50625
1773	3.97773
1776.02	4.23201
1779.03	3.82159
1782.05	2.78606
1785.06	2.60561
1788.07	2.58021
1791.08	2.03029
1794.09	2.51766
1797.1	2.92224
1800.11	3.24291
1803.12	2.65321
1806.12	3.28299
1809.12	3.55391
1812.13	4.01092
1815.13	4.74897
1818.13	5.05252
1821.13	5.32758
1824.13	5.71603
1827.13	5.53126
1830.12	5.08745
1833.12	4.699
1836.11	3.47862
1839.1	3.005
1842.09	2.90765
1845.09	3.35141
1848.08	2.92207
1851.06	2.46271
1854.05	1.71471
1857.04	1.28162
1860.02	2.15483
1863.01	1.99791
1865.99	3.51362
1868.97	4.72938
1871.95	5.79551
1874.93	6.27745
1877.91	6.70154
1880.89	7.85662
1882.46	7.79002
1885.45	8.57047
1888.43	9.17035
1891.42	9.03708
1894.41	9.52712
1897.39	10.0001
1900.37	10.0899
1903.36	9.80707
1906.34	9.17285
1909.32	9.08471
1912.29	9.58947
1915.27	9.0893
1918.25	8.66161
1921.23	7.86136
1924.2	7.53204
1927.17	7.40102
1930.15	7.20123
1933.12	7.00578
1936.09	6.38669
1939.06	7.37828
1942.02	7.6035
1944.99	7.25052
1947.96	6.41462
1950.92	4.66827
1953.88	4.23877
1956.85	3.01678
1959.81	2.55906
1962.77	2.61127
1965.73	3.54062
1968.69	3.14075
1971.64	3.70667
1974.6	3.3945
1977.55	2.43207
1980.51	3.10788
1983.46	3.67361
1986.41	3.90502
1989.36	3.17446
1992.31	3.05348
1995.26	3.63726
1998.21	4.19782
2001.15	3.17223
2004.1	2.74939
2007.04	3.33574
2009.99	4.25869
2012.93	3.96289
2015.87	3.8492
2018.81	3.77184
2021.75	3.8822
2024.68	2.7367
2027.62	3.00712
2030.56	3.41662
2033.49	3.40678
2036.42	4.63736
2039.36	4.8099
2042.29	6.09749
2045.22	6.98842
2048.14	6.1413
2051.07	6.79322
2054	7.40098
2056.93	8.38752
2059.85	7.24668
2062.77	7.05059
2065.7	6.95465
2068.62	6.9496
2071.54	6.79647
2074.46	6.38027
2077.38	7.1936
2080.29	7.12999
2083.21	7.1087
2086.12	6.88285
2089.04	8.60538
2091.95	8.66794
2094.86	8.33758
2097.77	8.47675
2100.68	9.23555
2103.59	10.1177
2106.5	10.8176
2109.41	12.8566
2112.31	14.5658
2115.21	16.7675
2118.12	18.4581
2121.02	19.5509
2123.92	22.0014
2126.82	22.7876
2129.72	24.18
2132.62	25.4888
2135.51	27.0258
2138.41	29.3061
2141.31	31.5442
2144.2	34.1047
2147.09	35.7687
2149.98	37.4375
2152.87	38.7868
2155.76	40.6006
2158.65	42.4363
2161.54	43.0104
2164.43	43.271
2167.31	44.4306
2170.2	45.3539
2173.08	46.2936
2175.96	46.9053
2178.84	46.7558
2181.72	46.8178
2184.6	45.7701
2187.48	44.9869
2190.36	42.4777
2193.23	39.6727
2196.11	38.3992
2198.98	36.4222
2201.85	35.1203
2204.72	32.559
2207.59	31.2246
2210.46	30.3649
2213.33	29.2109
2216.2	26.9326
2219.07	25.7039
2221.93	24.0957
2224.8	22.7662
2227.66	22.2809
2230.52	21.528
2233.39	20.8313
2236.25	21.4424
2239.1	21.3138
2241.96	21.1402
2244.82	20.2832
2247.68	18.7972
2250.53	17.1733
2253.38	16.8871
2256.24	15.9711
2259.09	13.9112
2261.94	13.018
2264.79	12.9956
2267.64	12.7697
2270.49	11.6454
2273.33	10.8997
2276.18	9.93244
2279.02	8.48832
2281.87	7.93076
2284.71	7.02998
2287.55	7.11698
2290.39	7.00977
2293.23	5.61003
2296.07	5.9393
2298.91	7.4685
2301.74	8.0385
2304.58	9.19687
2307.41	9.71758
2310.25	10.3568
2313.08	9.99252
2315.91	9.77336
2318.74	9.41929
2321.57	9.01658
2324.4	9.2316
2327.23	8.62957
2330.05	8.87673
2332.88	9.72934
2335.7	9.87353
2338.52	9.58383
2341.35	8.7631
2344.17	7.48466
2346.99	7.10443
2349.81	6.10927
2352.62	5.83328
2355.44	5.40804
2358.26	4.59293
2361.07	2.74849
2363.89	3.01485
2366.7	3.79328
2369.51	3.41344
2372.32	3.35312
2375.13	3.06699
2377.94	2.43603
2380.75	2.38718
2383.56	1.70126
2386.36	1.55966
2389.17	1.28633
2391.97	1.03805
2394.77	1.17937
2397.58	1.324
2400.38	2.11958
2403.18	2.14497
2405.97	1.6849
2408.77	1.44639
2411.57	0.7329
2414.37	1.33065
2417.16	0.680749
2419.95	1.82683
2422.75	2.16887
2425.54	1.50537
2428.33	1.40667
2431.12	1.23568
2433.91	1.32191
2436.7	0.659878
2439.48	0.515578
2442.27	0.0999989
2445.05	0.62716
2447.84	1.41208
2450.62	2.01316
2453.4	1.4164
2456.18	1.28095
2458.96	0.87882
2461.74	1.09797
2464.52	1.42068
2467.29	1.73179
2470.07	2.42429
2472.85	2.05393
2475.62	2.24484
2478.39	3.04989
2481.16	3.67364
2483.93	3.74882
2486.7	4.46851
2489.47	4.59012
2492.24	4.01911
2495.01	3.19053
2497.77	2.63572
2500.54	2.60468
2503.3	2.05489
2506.06	2.54507
2508.83	1.79824
2511.59	2.39256
2514.35	2.44677
2517.11	1.27783
2519.86	0.445922
2522.62	0.743558
2525.38	1.37208
2528.13	0.86777
2530.89	1.25221
2533.64	0.692402
2536.39	0.472264
2539.14	0.584217
2541.89	0.456509
2544.64	1.69908
2547.39	2.38043
2550.14	2.42743
2552.88	2.30561
2555.63	1.89369
2558.37	1.79174
2561.11	1.84422
2563.86	2.05335
2566.6	2.54888
2569.34	3.41878
2572.08	3.2815
2574.82	2.42899
2577.55	3.18475
2580.29	3.2634
2583.02	2.28993
2585.76	2.04531
2588.49	2.92263
2591.22	2.87472
2593.96	2.20755
2596.69	1.69001
2599.42	1.25805
2602.14	1.07331
2604.87	0.962775
2607.6	1.29726
2610.32	1.96042
2613.05	2.98176
2615.77	2.75173
2618.49	2.65216
2621.22	2.73899
2623.94	2.447
2626.66	3.27024
2629.37	3.8078
2632.09	3.57283
2634.81	3.30166
2637.53	3.43009
2640.24	3.40349
2642.96	4.02352
2645.67	4.56089
2648.38	4.76267
2651.09	4.67444
2653.8	4.98833
2656.51	5.81814
2659.22	6.10412
2661.93	5.41641
2664.63	5.469
2667.34	5.59153
2670.04	5.15393
2672.75	5.21072
2675.45	6.02351
2678.15	5.76685
2680.85	5.36434
2683.55	4.78116
2686.25	4.1072
2688.94	4.72407
2691.64	4.31022
2694.34	3.53664
2697.03	2.86128
2699.73	2.76726
2702.42	3.25324
2705.11	3.86241
2707.8	4.78859
2710.49	4.75449
2713.18	4.6562
2715.87	5.45685
2718.55	4.64846
2721.24	5.01138
2723.93	5.64192
2726.61	5.46424
2729.29	5.09654
2731.98	4.98955
2734.66	4.99037
2737.34	4.99956
2740.02	5.57403
2742.7	5.64174
2745.37	4.66696
2748.05	5.73094
2750.72	5.00466
2753.4	5.18112
2756.07	4.63159
2758.75	4.1223
2761.42	3.55753
2764.09	2.09105
2766.76	1.61957
2769.43	1.86064
2772.1	1.58589
2774.76	0.999378
2777.43	0.54019
2780.1	0.665926
2782.76	0.915966
2785.42	0.877881
2788.09	0.732531
2790.75	0.959597
2793.41	0.806179
2796.07	0.683437
2798.73	0.325795
2801.39	1.06202
2804.04	0.719162
2806.7	1.54966
2809.35	0.513213
2812.01	0.612413
2814.66	0.199859
2817.31	0.535734
2819.96	1.49199
2822.61	2.97682
2825.26	5.48082
2827.91	8.72141
2830.56	12.448
2833.21	16.6233
2835.85	20.1369
2838.5	24.8454
2841.14	30.1742
2843.78	35.8816
2846.42	42.8629
2849.06	50.4264
2851.71	57.7784
2854.34	65.74
2856.98	75.2072
2859.62	82.6742
2862.26	89.4629
2864.89	95.5113
2867.53	101.54
2870.16	107.311
2872.79	112.357
2875.42	116.576
2878.05	120.547
2880.68	125.083
2883.31	129.315
2885.94	132.89
2888.57	137.481
2891.19	141.304
2893.82	145.069
2896.44	148.327
2899.07	152.895
2901.69	157.689
2904.31	165.344
2906.93	173.543
2909.55	183.379
2912.17	193.578
2914.79	203.654
2917.41	212.828
2920.02	221.85
2922.64	228.164
2925.25	231.614
2927.86	234.548
2930.48	236.726
2933.09	236.816
2935.7	234.072
2938.31	230.293
2940.92	224.652
2943.53	216.614
2946.13	208.757
2948.74	198.834
2951.34	190.214
2953.95	182.071
2956.55	171.45
2959.15	160.961
2961.75	151.986
2964.35	144.06
2966.95	136.145
2969.55	130.526
2972.15	123.815
2974.75	117.119
2977.34	110.084
2979.94	103.791
2982.53	96.5404
2985.13	88.4137
2987.72	80.3486
2990.31	72.9025
2992.9	65.5031
2995.49	58.6024
2998.08	50.5442
3000.67	42.9246
3003.25	35.6144
3005.84	29.8613
3008.42	24.917
3011.01	20.2409
3013.59	16.8254
3016.17	13.5175
3018.76	10.9034
3021.34	7.888
3023.92	6.37381
3026.49	6.16768
3029.07	6.51467
3031.65	7.04389
3034.23	7.12446
3036.8	9.01389
3039.38	10.1931
3041.95	11.0049
3044.52	12.3972
3047.09	13.7398
3049.66	14.9244
3052.23	16.6037
3054.8	16.8446
3057.37	17.4251
3059.94	17.1384
3062.5	16.0294
3065.07	15.5357
3067.63	15.0449
3070.2	15.0613
3072.76	13.7821
3075.32	11.8617
3077.88	9.81791
3080.44	8.50691
3083	6.56489
3085.56	5.41711
3088.12	3.26587
3090.67	2.51411
3093.23	1.35962
3095.78	0.331063
3098.34	0.448686
3100.89	0.756002
3103.44	0.338162
3105.99	1.42974
3108.54	3.0319
3111.09	3.99093
3113.64	5.19676
3116.19	5.99718
3118.74	7.31738
3121.28	8.27286
3123.83	9.19724
3126.37	10.5904
3128.91	12.0071
3131.46	14.0384
3134	14.7454
3136.54	14.5786
3139.08	14.8903
3141.62	14.587
3144.16	13.3743
3146.69	11.4614
3149.23	10.2603