File: data/Raman/poly_smoothed/Thy_50_12_31_1x_45s_532 nm_x100_100%_600 gr_mm_01.txt
#Acq. time (s)=	45
#Accumulations=	2
#Range (cm-¹)=	200...3150
#Windows=	2
#Auto scanning=	Off
#Autofocus=	Off
#Macrospot=	Off
#AutoExposure=	Off
#Spike filter=	Multiple accum.
#Delay time (s)=	0
#Binning=	1
#Readout mode=	Signal
#DeNoise=	Off
#ICS correction=	On
#Dark correction=	Off
#Inst. Process=	Off
#Detector Gain=	Best Dynamic Range
#Detector ADC=	20 kHz
#Detector temperature (°C)=	-69.85
#Instrument=	LabRAM HR Evol
#Detector=	Synapse
#Objective=	x100
#Grating=	600 gr/mm
#ND Filter=	100%
#Laser (nm)=	532
#Hole=	100.021
#Range=	Auto
#Laser Pol.=	No
#Raman. Pol.=	No
#Laser Pol. (°)=	-0.0007625
#Raman Pol. (°)=	89.9995
#Collection=	Microscope
#StageXY=	Marzhauser
#StageZ=	Marzhauser
#X (µm)=	-5131.9
#Y (µm)=	1510.7
#Z (µm)=	63.7
#Full time(mm:ss)=	3:18
#Project=
#Sample=
#Site=
#Title=	Thy_50_12_31_2x_45s_532 nm_x100_100%_600 gr_mm
#Remark=
#Date=	07.07.2022 11:30
#Acquired=	07.07.2022 11:30:44
#Base:Fit=	10.08.2022 10:04:30
#Base:Sub=	10.08.2022 10:04:45
#Filter:Polynom=	16.08.2022 10:20:25
#AxisType[0]=Intens
#AxisUnit[0]=Cnt
#AxisType[1]=Spectr
#AxisUnit[1]=1/cm
200.43	17.9871
204.061	16.5119
207.688	13.6633
211.316	11.2078
214.941	9.17044
218.566	7.0119
222.188	4.86569
225.809	4.38143
229.43	2.90236
233.047	2.84514
236.663	0.916952
240.278	1.32717
243.894	3.1131
247.506	3.35025
251.116	4.28459
254.725	3.57699
258.333	3.56761
261.939	3.83203
265.546	2.75208
269.15	3.19659
272.752	4.61249
276.353	5.22616
279.952	6.05256
283.55	7.20923
287.146	6.66674
290.739	6.17685
294.333	6.75721
297.925	7.61134
301.516	7.23407
305.106	7.74915
308.694	8.81529
312.279	8.62723
315.864	9.69309
319.448	8.91492
323.029	11.3944
326.61	11.7631
330.19	13.819
333.766	13.0211
337.343	12.9294
340.917	13.8841
344.491	13.1293
348.062	11.6307
351.633	10.3393
355.201	10.8289
358.77	9.53995
362.335	8.4737
365.899	9.16415
369.464	9.98695
373.025	7.45685
376.585	6.89157
380.143	5.76412
383.702	6.83632
387.258	6.27103
390.812	6.20939
394.365	8.22021
397.916	9.26225
401.467	10.4282
405.015	10.923
408.565	12.7742
412.111	14.8062
415.656	15.8052
419.197	15.5308
422.739	16.9534
426.279	16.6323
429.819	15.7263
433.356	13.9624
436.893	14.2225
440.428	12.9786
443.96	13.7438
447.492	14.6761
451.023	15.2569
454.553	15.9858
458.079	14.8717
461.606	14.6487
465.132	14.9523
468.654	17.9119
472.177	21.0119
475.696	24.653
479.217	26.6011
482.733	29.8376
486.251	30.7424
489.765	32.2628
493.278	33.9223
496.791	34.7861
500.301	35.1211
503.81	35.3227
507.319	33.2177
510.825	32.7444
514.33	31.6477
517.833	32.3146
521.337	31.68
524.838	30.1395
528.337	27.511
531.835	26.2575
535.332	24.2893
538.827	21.5972
542.321	19.9681
545.814	17.8962
549.305	18.6887
552.795	18.0489
556.284	17.5837
559.771	17.452
563.257	14.995
566.742	12.8497
570.223	9.42088
573.705	9.78873
577.185	8.54194
580.665	7.09099
584.141	7.00765
587.617	6.67912
591.092	5.9606
594.564	5.51005
598.037	6.77629
601.506	7.78992
604.976	7.59587
608.443	8.07261
611.91	9.7111
615.374	12.4252
618.839	14.31
622.3	14.6581
625.761	14.3424
629.221	15.4196
632.679	16.521
636.135	16.9733
639.592	14.962
643.045	15.3092
646.497	14.0986
649.948	13.0119
653.398	14.4972
656.846	13.9059
660.293	14.2084
663.738	13.7929
667.185	12.2066
670.628	11.0453
674.067	9.80394
677.508	11.1491
680.947	12.7693
684.385	16.5563
687.821	19.1308
691.256	21.7934
694.69	24.3193
698.121	25.5529
701.552	28.591
704.982	28.719
708.41	30.6425
711.836	31.0918
715.262	34.0304
718.685	35.8246
722.108	37.3846
725.53	38.7042
728.949	40.0381
732.369	41.4165
735.785	44.7689
739.2	44.7613
742.616	44.925
746.028	47.4808
749.441	49.1414
752.851	50.9765
756.26	53.7475
759.667	56.8411
763.075	59.1887
766.479	63.4346
769.883	65.6488
773.285	66.4644
776.686	66.4056
780.085	67.7885
783.484	69.1121
786.881	71.8361
790.276	72.5519
793.671	73.1184
797.064	72.8019
800.456	73.643
803.846	73.5437
807.236	72.8548
810.624	74.0334
814.01	73.1725
817.394	74.7904
820.778	74.6696
824.161	73.752
827.543	73.495
830.921	73.0368
834.3	72.0561
837.676	71.5471
841.053	68.8828
844.426	67.6508
847.8	67.832
851.171	65.5171
854.542	62.1117
857.911	61.3295
861.279	59.9656
864.645	59.807
868.01	57.7499
871.375	55.4541
874.737	53.2309
878.097	51.6065
881.457	50.9326
884.817	50.9571
888.174	48.4292
891.53	47.7707
894.884	45.6986
898.237	44.326
901.589	42.6435
904.94	41.3386
908.289	38.6481
911.637	38.0981
914.984	37.1802
918.33	37.0169
921.674	34.6373
925.015	35.0502
928.357	33.8333
931.698	32.4338
935.037	31.9405
938.373	31.4178
941.71	30.1855
945.046	28.6156
948.378	31.4505
951.711	35.4945
955.043	40.3251
958.372	41.5817
961.701	43.7707
965.027	46.4738
968.354	48.5685
971.678	50.6011
975	53.5515
978.324	54.8671
981.644	56.6847
984.962	58.0066
988.282	59.1156
991.598	60.3076
994.913	61.0511
998.227	60.264
1001.54	58.9496
1004.85	58.5441
1008.16	58.6699
1011.47	58.17
1014.78	60.5601
1018.08	60.876
1021.39	60.2664
1024.69	62.6465
1028	64.1771
1031.3	67.1399
1034.6	67.9624
1037.9	66.6554
1041.19	64.7077
1044.49	65.4827
1047.79	64.6751
1051.08	62.5185
1054.37	59.8641
1057.66	59.3079
1060.95	56.9908
1064.24	54.0997
1067.53	50.1371
1070.81	45.2103
1074.1	41.8326
1077.38	38.2812
1080.66	35.7767
1083.94	33.4044
1087.22	33.7238
1090.5	31.9671
1093.78	31.5547
1097.05	31.2
1100.33	31.0612
1103.6	32.3966
1106.87	33.3249
1110.15	32.6358
1113.41	31.6293
1116.68	30.9559
1119.95	30.5429
1123.21	29.0673
1126.48	25.241
1129.74	23.3892
1133	23.7084
1136.26	23.9643
1139.52	22.8552
1142.78	19.4113
1146.04	17.7695
1149.29	13.6836
1152.55	10.6411
1155.8	9.66725
1159.05	7.58161
1162.3	5.20286
1165.55	4.4426
1168.8	3.15903
1172.05	3.80963
1175.29	6.54326
1178.54	7.01212
1181.78	9.28863
1185.02	8.58941
1188.26	9.0871
1191.5	8.06622
1194.74	9.48433
1197.97	10.6916
1201.21	12.4009
1204.44	13.7399
1207.68	16.1402
1210.91	21.1406
1214.14	26.2223
1217.37	31.207
1220.6	35.9404
1223.82	41.5143
1227.05	47.3588
1230.27	51.0046
1233.49	56.0307
1236.72	63.2075
1239.94	67.9746
1243.16	72.1292
1246.37	78.3006
1249.59	84.7138
1252.8	90.9922
1256.02	94.4355
1259.23	98.1519
1262.44	102.006
1265.66	105.382
1268.87	110.227
1272.07	114.179
1275.28	117.574
1278.48	118.607
1281.69	120.787
1284.89	123.224
1288.09	124.699
1291.3	127.784
1294.49	129.163
1297.69	130.697
1300.89	131.718
1304.09	131.998
1307.28	129.594
1310.47	129.216
1313.66	128.05
1316.86	125.351
1320.05	121.605
1323.23	121.215
1326.42	118.762
1329.61	114.967
1332.79	110.391
1335.98	108.25
1339.16	104.727
1342.34	102.458
1345.52	99.0939
1348.7	93.9413
1351.87	89.287
1355.05	85.4619
1358.23	80.8003
1361.4	78.6632
1364.57	75.6396
1367.74	73.6636
1370.91	71.4232
1374.08	66.7916
1377.25	66.6165
1380.42	65.9803
1383.58	63.7887
1386.75	62.1769
1389.91	61.0476
1393.07	59.8277
1396.23	59.5475
1399.39	61.3686
1402.55	61.1409
1405.7	63.0613
1408.86	67.3564
1412.01	70.9286
1415.17	75.5605
1418.32	79.9522
1421.47	85.3739
1424.62	91.2226
1427.77	98.7861
1430.92	107.711
1434.06	117.196
1437.2	123.988
1440.35	129.074
1443.49	133.749
1446.63	135.426
1449.77	134.574
1452.91	134.893
1456.05	133.653
1459.18	128.988
1462.32	122.367
1465.45	112.322
1468.59	103.206
1471.72	92.7627
1474.85	83.0857
1477.98	73.4002
1481.11	62.8287
1484.23	54.1753
1487.36	45.7937
1490.48	38.8616
1493.61	34.983
1496.73	31.508
1499.85	30.9638
1502.97	32.0674
1506.09	33.892
1509.2	34.8053
1512.32	36.5484
1515.44	38.1863
1518.55	41.0474
1521.66	44.3356
1524.77	48.0846
1527.88	52.4506
1530.99	55.9401
1534.1	56.6664
1537.21	58.5048
1540.31	61.0135
1543.42	63.8684
1546.52	67.2411
1549.62	69.9356
1552.72	73.9937
1555.82	77.6489
1558.92	82.6002
1562.02	85.378
1565.11	89.3501
1568.21	95.6217
1571.3	100.817
1574.39	106.505
1577.49	112.367
1580.58	117.335
1583.67	120.809
1586.75	122.569
1589.84	124.091
1592.93	124.994
1596.01	124.912
1599.09	125.242
1602.18	125.321
1605.26	122.115
1608.34	121.851
1611.41	121.228
1614.49	122.092
1617.57	122.488
1620.64	123.174
1623.72	123.79
1626.79	125.758
1629.86	128.636
1632.93	132.163
1636	136.032
1639.07	139.09
1642.14	143.815
1645.2	149.306
1648.27	153.014
1651.33	158.074
1654.39	159.939
1657.45	158.818
1660.51	156.132
1663.57	151.327
1666.63	147.545
1669.69	140.276
1672.74	132.659
1675.79	124.982
1678.85	115.505
1681.9	106.141
1684.95	97.3152
1688	87.4315
1691.05	77.402
1694.1	67.9376
1697.14	58.1497
1700.19	50.9688
1703.23	45.2146
1706.27	40.0296
1709.32	34.456
1712.35	29.9108
1715.39	27.6132
1718.43	26.3109
1721.47	25.1508
1724.5	24.1715
1727.54	22.4581
1730.57	21.9557
1733.61	21.4837
1736.64	19.7424
1739.67	19.7256
1742.7	19.2198
1745.72	18.7523
1748.75	18.3852
1751.78	16.8633
1754.8	16.6663
1757.82	15.4026
1760.85	14.1018
1763.87	12.678
1766.89	11.4569
1769.91	10.1701
1772.92	9.31655
1775.94	8.40996
1778.96	8.83413
1781.97	8.59439
1784.98	8.28107
1788	8.38006
1791.01	8.29245
1794.01	8.23006
1797.02	7.47598
1800.03	7.32821
1803.04	7.23414
1806.04	6.86345
1809.05	6.73186
1812.05	7.06301
1815.05	6.61829
1818.05	7.03291
1821.05	6.2863
1824.05	5.48443
1827.05	4.60534
1830.04	4.36288
1833.04	4.09755
1836.03	4.19053
1839.03	3.78763
1842.02	2.88995
1845.01	2.81674
1848	2.58563
1850.99	2.31705
1853.97	3.0906
1856.96	2.48044
1859.94	2.15773
1862.93	2.31496
1865.91	3.21731
1868.89	3.23626
1871.87	2.28065
1874.85	2.04354
1877.83	2.26473
1880.81	3.13746
1882.56	4.45061
1885.55	5.16816
1888.54	5.66627
1891.52	6.0878
1894.51	6.39428
1897.49	6.35214
1900.48	7.12591
1903.46	6.93381
1906.44	7.03051
1909.42	6.53903
1912.4	5.86466
1915.38	6.15558
1918.35	7.11518
1921.33	6.32236
1924.3	5.90963
1927.28	5.43595
1930.25	4.67602
1933.22	3.9897
1936.19	3.58203
1939.16	3.09195
1942.13	1.44335
1945.09	1.94083
1948.06	2.56607
1951.03	1.81251
1953.99	1.83082
1956.95	1.67918
1959.91	0.25406
1962.87	-1.7166
1965.83	-1.12995
1968.79	-0.333929
1971.75	-0.476725
1974.7	-1.33911
1977.66	-0.365921
1980.61	-0.963235
1983.56	0.518491
1986.52	2.69354
1989.47	3.64192
1992.41	4.17901
1995.36	4.60263
1998.31	6.37357
2001.26	6.67511
2004.2	7.89706
2007.15	8.60265
2010.09	10.1128
2013.03	11.5539
2015.97	13.3339
2018.91	13.8022
2021.85	13.7481
2024.79	13.2598
2027.72	13.015
2030.66	12.6714
2033.59	12.2878
2036.53	12.8886
2039.46	14.5108
2042.39	14.1257
2045.32	14.2085
2048.25	14.5753
2051.18	14.4934
2054.1	16.0427
2057.03	17.6819
2059.95	18.5248
2062.88	19.1037
2065.8	20.2274
2068.72	22.986
2071.64	26.2145
2074.56	27.4722
2077.48	30.3548
2080.39	35.1267
2083.31	38.8568
2086.22	42.4441
2089.14	46.7102
2092.05	50.3803
2094.96	54.5506
2097.87	58.3935
2100.78	63.1078
2103.69	67.8865
2106.6	73.3269
2109.51	79.2588
2112.41	84.3989
2115.32	89.4571
2118.22	95.1311
2121.12	101.333
2124.02	106.592
2126.92	112.256
2129.82	118.364
2132.72	125.071
2135.62	131.964
2138.51	139.389
2141.41	145.367
2144.3	152.85
2147.19	158.291
2150.09	164.736
2152.97	169.191
2155.86	172.529
2158.75	177.175
2161.64	179.964
2164.53	181.806
2167.41	182.978
2170.3	183.725
2173.18	183.144
2176.06	181.19
2178.94	179.05
2181.82	174.986
2184.7	171.388
2187.58	167.054
2190.46	161.87
2193.33	156.893
2196.21	151.809
2199.08	146.9
2201.95	142.249
2204.83	135.875
2207.7	129.151
2210.57	121.885
2213.43	115.961
2216.3	109.502
2219.17	101.793
2222.03	94.6542
2224.9	88.2856
2227.76	82.3999
2230.62	78.1429
2233.49	72.5909
2236.34	67.7678
2239.2	62.1248
2242.06	56.8907
2244.92	52.5229
2247.78	48.4738
2250.63	45.9708
2253.48	43.5749
2256.34	42.3588
2259.19	40.0183
2262.04	39.9239
2264.89	38.814
2267.74	37.8498
2270.59	35.8409
2273.43	33.8272
2276.28	31.4272
2279.12	29.3386
2281.97	28.5803
2284.81	26.6067
2287.65	24.2445
2290.49	22.4943
2293.33	19.8126
2296.17	19.7173
2299.01	19.9003
2301.84	18.5346
2304.68	18.4012
2307.51	16.638
2310.35	16.2843
2313.18	15.2473
2316.01	14.9885
2318.84	14.6364
2321.67	14.8226
2324.5	14.6503
2327.33	14.3166
2330.15	14.1756
2332.98	13.5315
2335.8	12.18
2338.62	11.329
2341.45	9.99149
2344.27	9.07104
2347.09	7.75344
2349.91	6.69609
2352.72	5.33885
2355.54	3.77789
2358.36	3.01625
2361.17	0.597459
2363.98	1.70248
2366.8	2.34367
2369.61	3.0066
2372.42	3.43834
2375.23	3.23704
2378.04	2.67522
2380.85	2.94593
2383.66	4.03903
2386.46	4.23443
2389.26	5.95461
2392.07	5.53466
2394.87	4.72811
2397.67	4.48335
2400.47	4.81539
2403.27	5.50838
2406.07	5.41336
2408.87	6.15907
2411.67	6.3221
2414.46	6.64926
2417.26	6.42518
2420.05	6.3198
2422.84	6.39319
2425.64	6.01388
2428.43	5.42703
2431.22	7.09898
2434.01	8.52653
2436.79	9.73094
2439.58	10.4167
2442.37	11.1957
2445.15	11.6446
2447.93	12.2732
2450.72	12.3897
2453.5	12.7791
2456.28	11.8926
2459.06	11.0175
2461.84	9.00945
2464.62	9.00986
2467.39	9.2852
2470.17	9.12971
2472.94	9.03877
2475.72	8.76205
2478.49	7.76861
2481.26	6.7843
2484.03	5.58808
2486.8	4.7408
2489.57	4.64198
2492.34	3.606
2495.1	3.67542
2497.87	4.32294
2500.63	3.39597
2503.4	2.82706
2506.16	3.30944
2508.92	2.93315
2511.68	2.79194
2514.44	2.05463
2517.2	2.36416
2519.96	1.58012
2522.72	1.88592
2525.47	2.23287
2528.23	2.46654
2530.98	3.49533
2533.74	4.18895
2536.49	5.05819
2539.24	6.65841
2541.99	8.74858
2544.74	9.02464
2547.49	8.48647
2550.23	8.77161
2552.98	9.07984
2555.72	9.98786
2558.47	10.5931
2561.21	10.3363
2563.95	9.46712
2566.69	8.90169
2569.43	7.53684
2572.17	6.68648
2574.91	6.30084
2577.65	5.63465
2580.39	4.70613
2583.12	3.77416
2585.85	2.68194
2588.59	1.86133
2591.32	1.76953
2594.05	0.916902
2596.78	0.466222
2599.51	0.55086
2602.24	0.529926
2604.97	1.29889
2607.69	1.1189
2610.42	1.3073
2613.14	0.468859
2615.87	-0.256401
2618.59	-0.207062
2621.31	0.249968
2624.03	0.833386
2626.75	0.605535
2629.47	-0.747098
2632.19	-0.867125
2634.91	0.0964991
2637.62	0.334357
2640.34	1.2766
2643.05	1.8829
2645.76	1.65612
2648.48	1.94181
2651.19	1.3916
2653.9	1.36081
2656.6	1.27033
2659.31	1.12933
2662.02	0.6329
2664.73	1.3638
2667.43	2.23933
2670.14	3.4162
2672.84	3.24665
2675.54	3.71921
2678.24	4.05637
2680.94	3.2341
2683.64	3.29496
2686.34	4.33572
2689.04	5.158
2691.74	5.50701
2694.43	5.83583
2697.13	5.97563
2699.82	6.9392
2702.51	7.93753
2705.21	7.79975
2707.9	8.94939
2710.58	9.64717
2713.27	10.3477
2715.96	10.5238
2718.65	10.3681
2721.33	11.0972
2724.02	11.271
2726.71	11.2792
2729.39	12.4548
2732.07	12.6158
2734.75	14.1699
2737.43	14.1015
2740.11	12.6012
2742.79	12.2126
2745.47	10.811
2748.14	9.81672
2750.82	9.7737
2753.49	8.72342
2756.17	8.63417
2758.84	7.98353
2761.51	5.9278
2764.18	4.68451
2766.85	4.21735
2769.52	3.85958
2772.19	3.6864
2774.86	3.07473
2777.52	3.10634
2780.19	2.09079
2782.85	2.59609
2785.52	3.16442
2788.18	2.95105
2790.84	1.3921
2793.5	1.36097
2796.16	1.35497
2798.82	0.824551
2801.48	0.61115
2804.13	-0.0411457
2806.79	-0.854118
2809.45	-1.66093
2812.1	-0.81068
2814.75	-0.168232
2817.41	2.08407
2820.06	6.1445
2822.71	12.576
2825.36	18.4274
2828	26.14
2830.65	33.9296
2833.3	42.3978
2835.94	51.9443
2838.59	62.2871
2841.23	73.4369
2843.87	83.2796
2846.52	95.324
2849.16	108.783
2851.8	123.425
2854.44	137.923
2857.08	152.781
2859.71	166.201
2862.35	179.293
2864.98	190.351
2867.62	200.283
2870.25	209.498
2872.88	217.8
2875.52	223.41
2878.15	230.259
2880.78	236.642
2883.41	243.212
2886.03	249.359
2888.66	257.592
2891.29	265.055
2893.91	272.536
2896.54	280.934
2899.16	291.691
2901.78	302.748
2904.4	317.287
2907.02	332.108
2909.64	349.603
2912.26	367.708
2914.88	387.782
2917.5	406.134
2920.11	421.451
2922.73	435.433
2925.34	444.473
2927.96	450.931
2930.57	453.683
2933.18	453.972
2935.79	450.139
2938.4	441.95
2941.01	431.731
2943.62	418.707
2946.22	404.118
2948.83	387.678
2951.43	371.521
2954.04	353.457
2956.64	336.168
2959.24	318.266
2961.84	301.323
2964.45	283.591
2967.05	267.691
2969.64	251.52
2972.24	236.65
2974.84	221.843
2977.43	207.149
2980.03	193.233
2982.62	177.145
2985.22	162.216
2987.81	147.265
2990.4	131.31
2992.99	116.515
2995.58	103.507
2998.17	89.6459
3000.76	76.4239
3003.34	65.0697
3005.93	55.3586
3008.52	47.0601
3011.1	38.8215
3013.68	32.3614
3016.27	27.9236
3018.85	23.062
3021.43	20.5246
3024.01	17.9371
3026.59	16.8966
3029.16	16.2145
3031.74	16.1928
3034.32	17.5913
3036.89	19.3263
3039.47	21.245
3042.04	22.3347
3044.61	23.7895
3047.18	26.0822
3049.75	26.606
3052.32	27.6634
3054.89	27.9458
3057.46	27.3173
3060.03	26.6592
3062.59	24.8199
3065.16	23.5565
3067.72	21.1833
3070.29	19.0897
3072.85	16.1389
3075.41	13.5177
3077.97	11.0933
3080.53	7.72833
3083.09	4.88014
3085.65	4.10112
3088.21	3.58266
3090.76	2.07364
3093.32	1.24798
3095.87	1.58617
3098.43	2.6745
3100.98	3.74294
3103.53	5.49866
3106.08	7.86099
3108.63	9.94558
3111.18	12.4884
3113.73	13.9384
3116.28	16.0061
3118.83	18.4871
3121.37	20.5454
3123.92	22.2335
3126.46	24.4652
3129	26.2351
3131.55	28.1944
3134.09	30.9438
3136.63	32.3127
3139.17	34.04
3141.71	35.1281
3144.24	37.4626
3146.78	39.793
3149.32	42.9322