File: data/Raman/poly_smoothed/Thy_50_12_21_1x_45s_532 nm_x100_100%_600 gr_mm_01.txt
#Acq. time (s)=	45
#Accumulations=	2
#Range (cm-¹)=	200...3150
#Windows=	2
#Auto scanning=	Off
#Autofocus=	Off
#Macrospot=	Off
#AutoExposure=	Off
#Spike filter=	Multiple accum.
#Delay time (s)=	0
#Binning=	1
#Readout mode=	Signal
#DeNoise=	Off
#ICS correction=	On
#Dark correction=	Off
#Inst. Process=	Off
#Detector Gain=	Best Dynamic Range
#Detector ADC=	20 kHz
#Detector temperature (°C)=	-69.85
#Instrument=	LabRAM HR Evol
#Detector=	Synapse
#Objective=	x100
#Grating=	600 gr/mm
#ND Filter=	100%
#Laser (nm)=	532
#Hole=	100.021
#Range=	Auto
#Laser Pol.=	No
#Raman. Pol.=	No
#Laser Pol. (°)=	-0.0007625
#Raman Pol. (°)=	89.9995
#Collection=	Microscope
#StageXY=	Marzhauser
#StageZ=	Marzhauser
#X (µm)=	-5133.5
#Y (µm)=	1487.6
#Z (µm)=	62.75
#Full time(mm:ss)=	3:18
#Project=
#Sample=
#Site=
#Title=	Thy_50_12_21_2x_45s_532 nm_x100_100%_600 gr_mm
#Remark=
#Date=	07.07.2022 10:46
#Acquired=	07.07.2022 10:46:46
#Base:Fit=	10.08.2022 10:04:29
#Base:Sub=	10.08.2022 10:04:45
#Filter:Polynom=	16.08.2022 10:20:24
#AxisType[0]=Intens
#AxisUnit[0]=Cnt
#AxisType[1]=Spectr
#AxisUnit[1]=1/cm
200.43	49.9814
204.061	44.216
207.688	41.0127
211.316	35.4718
214.941	30.596
218.566	25.6667
222.188	20.7637
225.809	18.2616
229.43	14.9843
233.047	12.6141
236.663	10.0454
240.278	7.93244
243.894	8.36973
247.506	7.0336
251.116	5.61862
254.725	6.94029
258.333	6.10201
261.939	6.41839
265.546	7.40355
269.15	7.10501
272.752	5.94804
276.353	7.583
279.952	7.9955
283.55	9.97003
287.146	11.944
290.739	12.5965
294.333	12.5994
297.925	12.0336
301.516	13.4367
305.106	13.9224
308.694	14.4183
312.279	15.69
315.864	15.3801
319.448	15.7798
323.029	15.0454
326.61	15.0537
330.19	14.8937
333.766	13.0176
337.343	11.2224
340.917	12.1006
344.491	13.3582
348.062	15.2934
351.633	17.9645
355.201	19.4273
358.77	20.149
362.335	22.58
365.899	23.041
369.464	24.3984
373.025	23.9357
376.585	24.4731
380.143	23.1494
383.702	23.1085
387.258	23.6841
390.812	22.8756
394.365	21.3933
397.916	19.1219
401.467	15.458
405.015	13.7814
408.565	10.0055
412.111	7.60685
415.656	4.42219
419.197	0.419417
422.739	1.56067
426.279	3.11199
429.819	6.41354
433.356	7.62955
436.893	7.99157
440.428	8.66201
443.96	7.88355
447.492	8.62849
451.023	8.26821
454.553	8.08734
458.079	8.45263
461.606	8.87062
465.132	9.50922
468.654	11.1133
472.177	11.5916
475.696	12.9654
479.217	15.3248
482.733	14.5733
486.251	16.2431
489.765	17.8109
493.278	19.9946
496.791	21.034
500.301	22.1424
503.81	22.5779
507.319	24.3121
510.825	26.879
514.33	28.7606
517.833	29.2304
521.337	29.0471
524.838	29.4115
528.337	31.1389
531.835	30.3856
535.332	29.695
538.827	28.2782
542.321	26.2867
545.814	26.9825
549.305	25.5189
552.795	24.9928
556.284	24.0129
559.771	23.7562
563.257	22.3712
566.742	20.9872
570.223	18.5355
573.705	15.9692
577.185	14.0202
580.665	12.92
584.141	10.332
587.617	9.87191
591.092	8.99811
594.564	9.27514
598.037	8.75794
601.506	7.85753
604.976	7.59456
608.443	8.01021
611.91	9.96996
615.374	10.1241
618.839	10.7653
622.3	11.5388
625.761	12.9544
629.221	15.6358
632.679	18.2091
636.135	20.21
639.592	22.2294
643.045	22.485
646.497	22.8885
649.948	24.1895
653.398	23.6562
656.846	25.1494
660.293	25.5911
663.738	26.8887
667.185	25.9213
670.628	26.1056
674.067	27.638
677.508	29.4651
680.947	31.3391
684.385	32.8422
687.821	35.1508
691.256	37.1319
694.69	39.9472
698.121	43.394
701.552	45.2612
704.982	46.3614
708.41	49.4177
711.836	51.9043
715.262	52.9385
718.685	54.2685
722.108	55.9163
725.53	57.1574
728.949	58.749
732.369	61.5638
735.785	61.7374
739.2	64.5509
742.616	66.4558
746.028	67.4784
749.441	68.9286
752.851	72.5409
756.26	76.0767
759.667	79.9497
763.075	82.9847
766.479	85.2443
769.883	87.3905
773.285	89.6283
776.686	90.4097
780.085	91.3968
783.484	90.9196
786.881	91.5182
790.276	90.8608
793.671	91.8563
797.064	91.2372
800.456	91.3227
803.846	91.1356
807.236	89.4516
810.624	88.4602
814.01	88.0176
817.394	87.3466
820.778	86.371
824.161	85.6606
827.543	84.0142
830.921	81.3206
834.3	79.645
837.676	78.2075
841.053	76.6891
844.426	75.6502
847.8	73.1349
851.171	70.4981
854.542	70.7514
857.911	70.5464
861.279	69.2628
864.645	68.3912
868.01	68.8384
871.375	67.1695
874.737	67.5829
878.097	68.906
881.457	66.9477
884.817	66.4952
888.174	64.4876
891.53	62.5517
894.884	61.1407
898.237	60.0289
901.589	57.5615
904.94	55.6675
908.289	52.3322
911.637	48.0557
914.984	44.4591
918.33	44.6378
921.674	40.9974
925.015	38.4906
928.357	36.5571
931.698	34.435
935.037	33.6709
938.373	32.7742
941.71	30.0477
945.046	29.3922
948.378	29.1152
951.711	29.7494
955.043	30.3246
958.372	30.8954
961.701	31.1746
965.027	31.6212
968.354	33.8426
971.678	33.5175
975	33.6068
978.324	34.37
981.644	35.3098
984.962	35.2769
988.282	34.8009
991.598	34.9079
994.913	35.067
998.227	35.1939
1001.54	35.0852
1004.85	34.037
1008.16	34.2645
1011.47	35.3478
1014.78	35.4225
1018.08	37.2905
1021.39	37.5257
1024.69	36.1451
1028	37.3402
1031.3	37.8543
1034.6	37.8996
1037.9	36.624
1041.19	36.165
1044.49	35.7315
1047.79	35.2663
1051.08	33.3434
1054.37	31.3259
1057.66	30.0477
1060.95	27.8471
1064.24	25.9103
1067.53	25.0464
1070.81	24.035
1074.1	23.303
1077.38	22.4496
1080.66	21.1876
1083.94	20.7971
1087.22	19.4866
1090.5	19.0666
1093.78	18.6989
1097.05	17.9089
1100.33	17.0199
1103.6	14.7086
1106.87	12.898
1110.15	11.9294
1113.41	10.6227
1116.68	9.57977
1119.95	7.10248
1123.21	5.89708
1126.48	5.80032
1129.74	4.65319
1133	3.49512
1136.26	3.21121
1139.52	2.46986
1142.78	1.94874
1146.04	1.90556
1149.29	1.23912
1152.55	3.02656
1155.8	4.20346
1159.05	4.878
1162.3	4.59224
1165.55	3.99415
1168.8	4.29181
1172.05	4.3766
1175.29	4.95878
1178.54	3.76756
1181.78	2.55275
1185.02	1.73864
1188.26	2.15861
1191.5	2.66259
1194.74	3.72986
1197.97	4.11479
1201.21	6.04146
1204.44	7.4402
1207.68	9.61916
1210.91	12.9225
1214.14	14.8807
1217.37	17.3723
1220.6	20.9308
1223.82	25.4055
1227.05	29.0735
1230.27	32.1738
1233.49	36.5157
1236.72	39.4868
1239.94	43.7577
1243.16	45.8346
1246.37	49.2293
1249.59	52.0488
1252.8	52.4491
1256.02	54.4554
1259.23	54.7029
1262.44	59.1717
1265.66	62.1637
1268.87	62.8806
1272.07	65.6842
1275.28	67.3615
1278.48	69.085
1281.69	71.5515
1284.89	73.9509
1288.09	77.7506
1291.3	81.9041
1294.49	84.5631
1297.69	84.2165
1300.89	83.8673
1304.09	85.3367
1307.28	85.5882
1310.47	84.9184
1313.66	86.5848
1316.86	86.2397
1320.05	85.2224
1323.23	83.5905
1326.42	80.8645
1329.61	79.2134
1332.79	74.9725
1335.98	72.7949
1339.16	70.4575
1342.34	69.1093
1345.52	64.8126
1348.7	62.2198
1351.87	59.221
1355.05	57.5753
1358.23	55.0791
1361.4	54.172
1364.57	51.4024
1367.74	51.8453
1370.91	49.8702
1374.08	46.8614
1377.25	45.2166
1380.42	46.0907
1383.58	45.4125
1386.75	43.8227
1389.91	43.177
1393.07	41.3292
1396.23	39.7122
1399.39	40.043
1402.55	38.8477
1405.7	39.9254
1408.86	41.2972
1412.01	43.599
1415.17	46.4758
1418.32	49.9382
1421.47	54.38
1424.62	58.1044
1427.77	64.2501
1430.92	70.0963
1434.06	74.6978
1437.2	78.9481
1440.35	81.9035
1443.49	84.8799
1446.63	87.7804
1449.77	88.0976
1452.91	88.1374
1456.05	86.9846
1459.18	84.1548
1462.32	80.1577
1465.45	75.4461
1468.59	71.3529
1471.72	65.8232
1474.85	59.6443
1477.98	53.646
1481.11	47.4325
1484.23	41.7928
1487.36	37.3107
1490.48	33.4614
1493.61	29.9514
1496.73	28.2109
1499.85	26.8363
1502.97	25.7092
1506.09	25.5959
1509.2	24.552
1512.32	23.7054
1515.44	24.2185
1518.55	24.8679
1521.66	26.2711
1524.77	27.5191
1527.88	28.9122
1530.99	30.4022
1534.1	31.7405
1537.21	35.0172
1540.31	38.7662
1543.42	43.7992
1546.52	47.0447
1549.62	50.8356
1552.72	55.1921
1555.82	58.0717
1558.92	62.2478
1562.02	66.1922
1565.11	69.6031
1568.21	73.659
1571.3	77.2093
1574.39	78.9715
1577.49	80.6085
1580.58	82.0001
1583.67	84.628
1586.75	85.2714
1589.84	87.0713
1592.93	86.7866
1596.01	86.3095
1599.09	84.4503
1602.18	82.1573
1605.26	79.8478
1608.34	79.0957
1611.41	78.9763
1614.49	78.8235
1617.57	80.4274
1620.64	82.3324
1623.72	84.4307
1626.79	87.5075
1629.86	87.6991
1632.93	88.1688
1636	91.2072
1639.07	93.5658
1642.14	96.6388
1645.2	98.8268
1648.27	100.005
1651.33	100.165
1654.39	100.333
1657.45	99.8026
1660.51	98.3402
1663.57	94.5684
1666.63	90.1728
1669.69	84.7098
1672.74	78.8837
1675.79	71.7313
1678.85	66.2158
1681.9	59.2453
1684.95	54.1496
1688	48.0473
1691.05	43.1449
1694.1	37.7349
1697.14	32.8787
1700.19	29.3444
1703.23	25.2172
1706.27	22.2066
1709.32	20.2326
1712.35	18.2213
1715.39	17.1837
1718.43	15.8401
1721.47	14.5052
1724.5	14.4056
1727.54	12.5068
1730.57	11.9883
1733.61	10.9758
1736.64	10.1483
1739.67	9.38093
1742.7	9.11519
1745.72	8.91009
1748.75	8.8756
1751.78	9.50449
1754.8	8.24975
1757.82	7.87674
1760.85	7.84266
1763.87	7.20261
1766.89	6.90582
1769.91	7.62069
1772.92	7.51212
1775.94	7.07251
1778.96	6.75987
1781.97	6.48889
1784.98	5.78921
1788	4.86506
1791.01	4.25992
1794.01	3.80707
1797.02	4.05191
1800.03	3.37718
1803.04	2.58749
1806.04	2.80474
1809.05	2.71289
1812.05	2.27752
1815.05	1.17234
1818.05	1.37504
1821.05	1.68509
1824.05	1.25625
1827.05	0.248249
1830.04	-0.00537882
1833.04	0.355925
1836.03	1.17302
1839.03	0.617832
1842.02	1.75296
1845.01	1.57537
1848	1.34483
1850.99	2.32746
1853.97	2.55399
1856.96	2.67636
1859.94	2.51393
1862.93	1.34987
1865.91	1.79068
1868.89	1.6636
1871.87	2.20774
1874.85	2.57888
1877.83	3.10795
1880.81	3.68798
1882.56	3.84732
1885.55	4.05695
1888.54	4.26987
1891.52	3.98373
1894.51	3.49978
1897.49	2.98057
1900.48	2.73667
1903.46	3.26608
1906.44	3.4806
1909.42	3.85478
1912.4	4.74391
1915.38	4.44169
1918.35	4.45183
1921.33	4.99308
1924.3	4.59856
1927.28	4.82444
1930.25	4.21969
1933.22	5.19859
1936.19	4.806
1939.16	5.08653
1942.13	5.27068
1945.09	6.09539
1948.06	6.3027
1951.03	5.81151
1953.99	6.55753
1956.95	5.39934
1959.91	4.43689
1962.87	3.80373
1965.83	3.48259
1968.79	2.88087
1971.75	2.37439
1974.7	1.35618
1977.66	1.13019
1980.61	0.701209
1983.56	0.640366
1986.52	-1.32233
1989.47	-1.85626
1992.41	-1.13579
1995.36	-1.11613
1998.31	-0.237561
2001.26	0.0540948
2004.2	-0.17897
2007.15	0.955623
2010.09	-0.00689989
2013.03	0.582539
2015.97	1.69479
2018.91	2.65701
2021.85	3.26912
2024.79	2.85583
2027.72	3.75702
2030.66	4.05811
2033.59	4.40195
2036.53	5.12147
2039.46	5.95855
2042.39	6.21785
2045.32	7.69096
2048.25	8.35803
2051.18	8.50831
2054.1	9.35504
2057.03	10.1923
2059.95	11.0994
2062.88	13.1016
2065.8	14.9115
2068.72	15.5619
2071.64	17.0361
2074.56	18.5664
2077.48	20.8252
2080.39	22.9598
2083.31	24.7702
2086.22	28.5957
2089.14	30.7459
2092.05	33.1788
2094.96	35.2187
2097.87	38.1594
2100.78	42.114
2103.69	44.9676
2106.6	47.8995
2109.51	51.2409
2112.41	54.696
2115.32	58.8546
2118.22	62.6587
2121.12	66.7476
2124.02	70.1937
2126.92	74.1357
2129.82	78.0497
2132.72	82.2327
2135.62	86.728
2138.51	90.0648
2141.41	94.0464
2144.3	98.461
2147.19	101.977
2150.09	105.728
2152.97	108.869
2155.86	112.143
2158.75	115.076
2161.64	117.074
2164.53	119.152
2167.41	119.686
2170.3	121.541
2173.18	121.151
2176.06	120.462
2178.94	119.312
2181.82	118.455
2184.7	116.491
2187.58	114.8
2190.46	112.599
2193.33	108.684
2196.21	104.907
2199.08	102.143
2201.95	96.8509
2204.83	92.5183
2207.7	87.8827
2210.57	83.3811
2213.43	78.5949
2216.3	73.0197
2219.17	67.8076
2222.03	63.356
2224.9	59.0588
2227.76	56.4916
2230.62	52.1422
2233.49	48.2852
2236.34	45.1015
2239.2	41.8692
2242.06	39.1671
2244.92	36.5638
2247.78	34.451
2250.63	32.4516
2253.48	32.3305
2256.34	31.3373
2259.19	30.4219
2262.04	29.2822
2264.89	28.6661
2267.74	28.4998
2270.59	26.8058
2273.43	25.101
2276.28	24.6783
2279.12	22.6604
2281.97	20.9913
2284.81	19.5779
2287.65	18.0788
2290.49	16.1675
2293.33	14.1627
2296.17	13.6207
2299.01	12.7224
2301.84	11.6294
2304.68	10.201
2307.51	10.3634
2310.35	10.6201
2313.18	9.3355
2316.01	9.56126
2318.84	9.13423
2321.67	9.72396
2324.5	9.98535
2327.33	9.29133
2330.15	9.08068
2332.98	8.4015
2335.8	8.10606
2338.62	8.05365
2341.45	7.4633
2344.27	6.28251
2347.09	4.9493
2349.91	4.26761
2352.72	3.3047
2355.54	1.65411
2358.36	0.779938
2361.17	-0.00157413
2363.98	0.862184
2366.8	1.05011
2369.61	0.457503
2372.42	-0.223046
2375.23	-0.0887275
2378.04	0.548833
2380.85	0.834161
2383.66	1.43304
2386.46	1.12459
2389.26	2.0299
2392.07	1.6598
2394.87	2.24719
2397.67	2.88725
2400.47	4.15199
2403.27	4.56276
2406.07	5.13857
2408.87	5.35291
2411.67	5.35932
2414.46	5.61421
2417.26	7.13683
2420.05	7.58007
2422.84	7.98226
2425.64	8.05124
2428.43	8.07786
2431.22	6.97762
2434.01	5.71767
2436.79	6.23384
2439.58	5.90002
2442.37	5.0915
2445.15	5.19337
2447.93	5.08343
2450.72	4.12152
2453.5	3.787
2456.28	3.36102
2459.06	2.87592
2461.84	2.72012
2464.62	2.75752
2467.39	2.98562
2470.17	2.29
2472.94	1.84053
2475.72	1.67217
2478.49	2.04501
2481.26	1.68657
2484.03	2.5833
2486.8	2.45813
2489.57	1.61885
2492.34	1.02702
2495.1	0.706834
2497.87	0.40061
2500.63	0.0399508
2503.4	-0.227917
2506.16	-0.191164
2508.92	-0.291489
2511.68	-0.524189
2514.44	-0.695409
2517.2	-1.10145
2519.96	0.206604
2522.72	0.790248
2525.47	1.06446
2528.23	1.87862
2530.98	3.13771
2533.74	3.6095
2536.49	4.60535
2539.24	4.8236
2541.99	5.48003
2544.74	5.81359
2547.49	6.44542
2550.23	6.47589
2552.98	5.99111
2555.72	5.27337
2558.47	5.50951
2561.21	5.73838
2563.95	6.03473
2566.69	5.96025
2569.43	5.34522
2572.17	4.57332
2574.91	4.82903
2577.65	4.79922
2580.39	4.69394
2583.12	4.65683
2585.85	4.97568
2588.59	6.03442
2591.32	5.95775
2594.05	5.94067
2596.78	6.15583
2599.51	5.37276
2602.24	5.45774
2604.97	5.33874
2607.69	4.73987
2610.42	5.38691
2613.14	4.90182
2615.87	3.97687
2618.59	3.54973
2621.31	2.70688
2624.03	2.85526
2626.75	2.23577
2629.47	1.3175
2632.19	1.1021
2634.91	1.31625
2637.62	1.37026
2640.34	0.79605
2643.05	0.169284
2645.76	0.54339
2648.48	-0.0793886
2651.19	-0.440091
2653.9	0.231578
2656.6	0.645123
2659.31	0.463516
2662.02	-0.0561957
2664.73	-0.202031
2667.43	1.25818
2670.14	2.35917
2672.84	3.32384
2675.54	3.34329
2678.24	3.54381
2680.94	3.32115
2683.64	3.63811
2686.34	4.1917
2689.04	3.97664
2691.74	4.88795
2694.43	5.32945
2697.13	6.48037
2699.82	7.16781
2702.51	7.2141
2705.21	7.18916
2707.9	6.92978
2710.58	8.09749
2713.27	8.26745
2715.96	9.50082
2718.65	10.4141
2721.33	11.3465
2724.02	11.3487
2726.71	11.5911
2729.39	11.9445
2732.07	12.4666
2734.75	11.9438
2737.43	11.871
2740.11	11.0174
2742.79	10.3664
2745.47	9.72256
2748.14	8.78316
2750.82	8.40386
2753.49	8.36942
2756.17	7.54413
2758.84	6.46768
2761.51	5.51383
2764.18	4.88016
2766.85	4.4546
2769.52	4.15672
2772.19	3.50351
2774.86	2.80454
2777.52	2.21065
2780.19	2.26428
2782.85	3.36515
2785.52	2.39003
2788.18	1.87514
2790.84	1.36208
2793.5	1.60491
2796.16	1.11415
2798.82	1.06531
2801.48	-0.12583
2804.13	-0.186371
2806.79	-1.72317
2809.45	-2.02035
2812.1	-2.98982
2814.75	-1.72179
2817.41	-0.298567
2820.06	2.33151
2822.71	5.79005
2825.36	10.7814
2828	17.0823
2830.65	23.5192
2833.3	30.5673
2835.94	37.2916
2838.59	44.0134
2841.23	50.7196
2843.87	59.1918
2846.52	68.8022
2849.16	78.5318
2851.8	88.6268
2854.44	98.8367
2857.08	110.946
2859.71	120.802
2862.35	130.437
2864.98	138.777
2867.62	145.785
2870.25	151.923
2872.88	157.394
2875.52	162.284
2878.15	166.777
2880.78	171.651
2883.41	176.508
2886.03	181.308
2888.66	186.315
2891.29	191.282
2893.91	195.504
2896.54	200.952
2899.16	207.217
2901.78	213.785
2904.4	221.941
2907.02	232.729
2909.64	244.179
2912.26	256.91
2914.88	271.011
2917.5	282.73
2920.11	294.76
2922.73	304.692
2925.34	312.09
2927.96	316.295
2930.57	318.176
2933.18	317.798
2935.79	315.097
2938.4	310.095
2941.01	302.043
2943.62	293.474
2946.22	283.888
2948.83	272.585
2951.43	259.818
2954.04	246.937
2956.64	233.979
2959.24	220.586
2961.84	209.294
2964.45	197.275
2967.05	186.633
2969.64	176.348
2972.24	166.189
2974.84	156.117
2977.43	146.448
2980.03	136.345
2982.62	126.24
2985.22	116.36
2987.81	105.471
2990.4	94.9175
2992.99	84.2745
2995.58	74.122
2998.17	65.4957
3000.76	56.6528
3003.34	48.5214
3005.93	41.4574
3008.52	34.8063
3011.1	29.4865
3013.68	24.3202
3016.27	19.7386
3018.85	16.7726
3021.43	13.4979
3024.01	11.5713
3026.59	10.3027
3029.16	9.85678
3031.74	8.77327
3034.32	8.61287
3036.89	8.86514
3039.47	9.04488
3042.04	9.54258
3044.61	9.9413
3047.18	11.1963
3049.75	11.3545
3052.32	12.7935
3054.89	12.4508
3057.46	12.202
3060.03	12.6084
3062.59	12.6794
3065.16	12.1629
3067.72	10.8547
3070.29	10.082
3072.85	9.03414
3075.41	8.11551
3077.97	6.24562
3080.53	5.04219
3083.09	4.39706
3085.65	3.12095
3088.21	2.32506
3090.76	1.80142
3093.32	1.72237
3095.87	1.49923
3098.43	1.61908
3100.98	2.33643
3103.53	2.26798
3106.08	2.40623
3108.63	3.37159
3111.18	4.40801
3113.73	5.20021
3116.28	5.99925
3118.83	7.18421
3121.37	9.25276
3123.92	10.4749
3126.46	11.6851
3129	13.0692
3131.55	14.7454
3134.09	16.3367
3136.63	18.4288
3139.17	21.4969
3141.71	24.1053
3144.24	27.1555
3146.78	30.2151
3149.32	34.8269