File: data/Raman/poly_smoothed/Thy_40_11_34_1x_45s_532 nm_x100_100%_600 gr_mm_01.txt
#Acq. time (s)=	45
#Accumulations=	2
#Range (cm-¹)=	200...3150
#Windows=	2
#Auto scanning=	Off
#Autofocus=	Off
#Macrospot=	Off
#AutoExposure=	Off
#Spike filter=	Multiple accum.
#Delay time (s)=	0
#Binning=	1
#Readout mode=	Signal
#DeNoise=	Off
#ICS correction=	On
#Dark correction=	Off
#Inst. Process=	Off
#Detector Gain=	Best Dynamic Range
#Detector ADC=	20 kHz
#Detector temperature (°C)=	-69.85
#Instrument=	LabRAM HR Evol
#Detector=	Synapse
#Objective=	x100
#Grating=	600 gr/mm
#ND Filter=	100%
#Laser (nm)=	532
#Hole=	100.021
#Range=	Auto
#Laser Pol.=	No
#Raman. Pol.=	No
#Laser Pol. (°)=	-0.0007625
#Raman Pol. (°)=	89.9995
#Collection=	Microscope
#StageXY=	Marzhauser
#StageZ=	Marzhauser
#X (µm)=	245.2
#Y (µm)=	1672.5
#Z (µm)=	426.85
#Full time(mm:ss)=	3:18
#Project=
#Sample=
#Site=
#Title=	Thy_40_11_34_2x_45s_532 nm_x100_100%_600 gr_mm
#Remark=
#Date=	05.07.2022 12:26
#Acquired=	05.07.2022 12:26:12
#Base:Fit=	10.08.2022 10:01:35
#Base:Sub=	10.08.2022 10:01:52
#Filter:Polynom=	16.08.2022 10:21:53
#AxisType[0]=Intens
#AxisUnit[0]=Cnt
#AxisType[1]=Spectr
#AxisUnit[1]=1/cm
200.43	11.8753
204.059	8.63775
207.688	8.6452
211.314	8.81528
214.941	8.10541
218.564	8.10104
222.186	6.62086
225.809	6.93661
229.428	7.12696
233.045	6.72108
236.663	6.22462
240.278	5.61042
243.891	4.51636
247.503	4.17086
251.116	4.11089
254.725	3.91333
258.333	4.35662
261.939	4.72778
265.544	3.0981
269.148	2.11308
272.75	-0.0789609
276.351	-0.0198098
279.95	1.83265
283.548	2.64133
287.144	3.82744
290.739	4.98038
294.333	6.21416
297.925	6.25192
301.514	7.55454
305.104	9.14476
308.692	10.445
312.279	12.1438
315.862	14.0698
319.446	14.7641
323.029	14.5317
326.608	15.5097
330.188	14.0947
333.766	13.0445
337.341	12.795
340.917	12.92
344.489	12.528
348.062	10.5148
351.631	9.80889
355.201	7.70318
358.768	6.79914
362.333	6.64307
365.899	7.6928
369.462	5.97299
373.023	5.81158
376.585	6.67491
380.143	5.91307
383.7	6.8392
387.256	6.79278
390.812	7.64556
394.365	9.0009
397.916	9.04317
401.467	9.77936
405.015	9.50613
408.563	10.6676
412.109	11.0409
415.654	11.0776
419.197	11.743
422.739	11.5021
426.279	12.2954
429.819	12.9257
433.356	12.1435
436.891	11.7266
440.426	12.4711
443.96	11.9316
447.492	12.251
451.021	11.4731
454.551	10.9616
458.079	10.585
461.604	10.2928
465.13	10.2175
468.654	10.3872
472.175	10.762
475.696	11.6383
479.215	12.6012
482.733	12.9943
486.249	13.9546
489.765	14.2695
493.278	16.1482
496.789	17.1354
500.301	17.1265
503.81	18.7921
507.317	19.5172
510.825	20.8667
514.33	20.1499
517.833	19.6053
521.335	19.138
524.836	19.1213
528.335	18.863
531.835	17.3686
535.332	16.761
538.827	14.7558
542.321	13.5785
545.814	12.0105
549.305	9.96591
552.795	9.14801
556.282	7.70435
559.769	6.19239
563.255	5.37041
566.739	4.09616
570.223	2.47715
573.705	1.42031
577.183	1.22041
580.663	0.604776
584.141	0.273187
587.615	-0.00493526
591.09	-0.674614
594.564	-0.227962
598.035	0.417286
601.506	1.02668
604.974	2.93953
608.443	3.60666
611.908	5.07892
615.374	5.03049
618.837	5.92557
622.3	7.99442
625.761	9.4385
629.219	12.0214
632.677	13.1422
636.135	14.5719
639.59	15.0474
643.043	15.8385
646.495	17.957
649.948	18.1432
653.398	19.2025
656.846	20.6766
660.293	21.4043
663.738	21.3623
667.183	22.2195
670.626	21.2702
674.067	21.0909
677.508	21.5081
680.947	22.8967
684.385	23.6642
687.821	23.9206
691.254	24.5847
694.688	26.1448
698.121	27.2805
701.552	28.2577
704.98	29.8966
708.409	32.7052
711.836	35.9056
715.26	37.8
718.685	38.3864
722.108	39.0554
725.528	41.2506
728.949	42.0629
732.367	42.419
735.785	43.6271
739.2	45.21
742.614	46.9292
746.028	48.7529
749.439	50.4666
752.849	52.189
756.26	53.9199
759.667	57.2626
763.073	58.9545
766.477	60.3576
769.883	61.8903
773.285	63.5508
776.686	65.9486
780.085	66.962
783.484	68.8892
786.881	71.4336
790.276	73.6886
793.671	76.3914
797.064	76.9347
800.456	78.5817
803.846	78.736
807.234	79.8116
810.622	80.8724
814.008	79.8395
817.394	79.9579
820.778	79.734
824.159	80.5828
827.541	81.0393
830.921	80.8057
834.298	79.4537
837.676	78.7517
841.051	76.872
844.426	73.9938
847.798	71.2597
851.171	68.9002
854.54	65.8261
857.911	62.8675
861.278	61.3144
864.645	60.4778
868.01	58.7654
871.373	57.4925
874.735	55.3716
878.097	54.8834
881.457	54.2402
884.815	53.072
888.172	49.8908
891.528	49.4983
894.882	47.2131
898.237	45.859
901.589	46.5727
904.94	45.0687
908.289	44.5564
911.635	42.6937
914.982	42.8301
918.328	41.8905
921.672	40.1103
925.015	39.1295
928.357	39.9379
931.698	38.4616
935.035	36.7841
938.373	36.1264
941.71	36.8635
945.044	35.5515
948.378	34.0667
951.709	33.6486
955.041	33.0142
958.372	30.8363
961.699	30.2099
965.027	30.4354
968.352	28.3513
971.676	27.8983
975	28.4714
978.322	28.4969
981.642	29.1871
984.962	29.1894
988.28	28.6095
991.596	29.1786
994.911	30.4608
998.227	31.3272
1001.54	30.4879
1004.85	30.8019
1008.16	30.8596
1011.47	31.8152
1014.78	30.5766
1018.08	30.2581
1021.39	30.2664
1024.69	28.5911
1028	28.3074
1031.3	29.1781
1034.6	28.667
1037.9	27.9635
1041.19	26.4007
1044.49	25.7803
1047.78	25.7309
1051.08	25.1496
1054.37	24.4775
1057.66	23.0667
1060.95	21.7201
1064.24	19.8626
1067.53	18.5075
1070.81	17.317
1074.1	16.6095
1077.38	15.2212
1080.66	14.202
1083.94	13.493
1087.22	12.6727
1090.5	12.8174
1093.78	12.8177
1097.05	11.6248
1100.33	13.0411
1103.6	13.8462
1106.87	15.9006
1110.14	16.9086
1113.41	17.0898
1116.68	16.4114
1119.95	15.7501
1123.21	14.8805
1126.48	14.8212
1129.74	15.662
1133	12.7647
1136.26	11.0793
1139.52	9.60687
1142.78	9.00164
1146.04	8.15852
1149.29	7.7088
1152.55	6.81876
1155.8	6.04714
1159.05	5.88417
1162.3	4.88623
1165.55	4.05714
1168.8	4.11448
1172.05	4.81081
1175.29	5.26927
1178.54	5.67412
1181.78	5.62483
1185.02	5.32399
1188.26	4.51885
1191.5	3.84358
1194.74	3.92514
1197.97	2.72393
1201.21	4.30677
1204.44	8.05913
1207.68	9.7852
1210.91	10.9636
1214.14	13.3634
1217.37	18.4755
1220.59	21.6968
1223.82	26.6049
1227.05	30.7536
1230.27	34.5787
1233.49	37.5337
1236.72	41.0108
1239.94	44.088
1243.16	47.7632
1246.37	50.633
1249.59	52.5526
1252.8	55.1862
1256.02	56.0246
1259.23	58.3655
1262.44	59.8571
1265.66	61.6137
1268.86	61.5044
1272.07	61.7967
1275.28	63.6756
1278.48	65.1581
1281.69	68.4506
1284.89	67.9147
1288.09	67.1854
1291.29	68.8319
1294.49	68.9799
1297.69	70.2746
1300.89	70.3087
1304.08	72.751
1307.28	73.9264
1310.47	74.0437
1313.66	73.1997
1316.85	74.0384
1320.04	73.0651
1323.23	72.835
1326.42	72.4918
1329.61	72.7411
1332.79	72.1527
1335.97	70.6767
1339.16	68.7496
1342.34	65.0449
1345.52	62.3264
1348.7	58.8487
1351.87	56.2518
1355.05	54.4063
1358.22	50.5318
1361.4	47.6519
1364.57	44.3157
1367.74	40.7337
1370.91	38.6017
1374.08	37.4631
1377.25	35.324
1380.41	33.4983
1383.58	32.3748
1386.74	31.6697
1389.91	29.3209
1393.07	29.1465
1396.23	28.7617
1399.39	27.6941
1402.55	28.1603
1405.7	27.8016
1408.86	29.309
1412.01	28.796
1415.17	29.7147
1418.32	33.0174
1421.47	36.9
1424.62	41.9901
1427.77	47.0612
1430.91	52.42
1434.06	58.9793
1437.2	62.8107
1440.35	65.894
1443.49	69.5949
1446.63	71.5442
1449.77	72.4663
1452.91	72.4981
1456.05	70.8676
1459.18	70.1769
1462.32	67.7146
1465.45	65.2019
1468.59	60.3534
1471.72	54.453
1474.85	49.3541
1477.98	43.7688
1481.1	38.5596
1484.23	32.2485
1487.36	27.3071
1490.48	23.0049
1493.61	19.4935
1496.73	18.7016
1499.85	16.3665
1502.97	14.9638
1506.09	14.8741
1509.2	15.4609
1512.32	14.6283
1515.43	13.3989
1518.55	16.1036
1521.66	17.7237
1524.77	18.2803
1527.88	19.4346
1530.99	21.1018
1534.1	23.9398
1537.21	27.4534
1540.31	30.1367
1543.42	33.9642
1546.52	37.4598
1549.62	40.0538
1552.72	43.2592
1555.82	45.3562
1558.92	48.7415
1562.02	50.7656
1565.11	52.4996
1568.21	53.8526
1571.3	56.5008
1574.39	57.2659
1577.49	58.5244
1580.57	60.9036
1583.66	64.0096
1586.75	65.7012
1589.84	66.9599
1592.92	67.0376
1596.01	66.8454
1599.09	65.5034
1602.17	62.8826
1605.25	61.8781
1608.33	59.9374
1611.41	58.8559
1614.49	58.7936
1617.57	58.5832
1620.64	59.0497
1623.72	59.2685
1626.79	59.1285
1629.86	61.5243
1632.93	63.9651
1636	65.948
1639.07	67.5537
1642.13	69.8428
1645.2	73.0806
1648.26	75.0791
1651.33	78.2496
1654.39	80.3479
1657.45	82.7797
1660.51	83.0369
1663.57	82.6561
1666.63	81.0511
1669.68	78.4827
1672.74	74.022
1675.79	69.0905
1678.85	64.0691
1681.9	59.4243
1684.95	54.0798
1688	47.7461
1691.05	43.0053
1694.09	37.2153
1697.14	31.8609
1700.18	26.9864
1703.23	22.622
1706.27	18.7651
1709.31	14.6765
1712.35	11.4329
1715.39	8.67455
1718.43	7.57538
1721.47	6.09447
1724.5	5.7968
1727.54	4.6245
1730.57	4.31031
1733.61	5.15089
1736.64	5.6594
1739.67	5.94803
1742.7	5.48556
1745.72	5.71549
1748.75	4.89605
1751.77	5.25783
1754.8	5.46497
1757.82	4.22033
1760.84	3.29139
1763.87	2.37932
1766.89	2.39895
1769.91	0.634995
1772.92	0.104089
1775.94	-0.394435
1778.95	-0.257844
1781.97	-1.13163
1784.98	-1.36562
1787.99	-1.5613
1791.01	-1.1178
1794.01	0.0405929
1797.02	0.54202
1800.03	1.52734
1803.04	1.54531
1806.04	2.55973
1809.05	2.22142
1812.05	2.04413
1815.05	3.1705
1818.05	3.35111
1821.05	3.12887
1824.05	3.2156
1827.05	3.37604
1830.04	3.25614
1833.04	3.37614
1836.03	3.60269
1839.03	4.12466
1842.02	4.67013
1845.01	4.53866
1848	5.89828
1850.99	6.40403
1853.97	5.80301
1856.96	5.77555
1859.94	6.36874
1862.93	7.62039
1865.91	8.84404
1868.89	10.1905
1871.87	11.5305
1874.85	12.205
1877.83	12.8271
1880.81	13.714
1882.57	13.9687
1885.56	14.9957
1888.55	15.2978
1891.54	14.7433
1894.52	14.982
1897.51	15.6966
1900.49	15.8219
1903.47	15.112
1906.45	15.5794
1909.43	15.6653
1912.41	15.1099
1915.39	14.7063
1918.37	15.0315
1921.34	15.5199
1924.32	14.1542
1927.29	13.5719
1930.26	15.1382
1933.23	14.7801
1936.2	14.7071
1939.17	14.9476
1942.14	15.177
1945.11	15.351
1948.07	14.8298
1951.04	15.1205
1954	15.4236
1956.96	15.1182
1959.93	14.8331
1962.89	14.606
1965.85	14.0562
1968.8	13.7871
1971.76	11.8788
1974.72	10.5279
1977.67	9.85086
1980.63	10.0431
1983.58	9.58355
1986.53	8.70472
1989.48	8.19197
1992.43	8.32887
1995.38	8.00494
1998.32	7.04661
2001.27	7.51584
2004.22	7.91667
2007.16	7.64966
2010.1	7.86163
2013.04	8.91342
2015.98	9.48722
2018.92	10.9124
2021.86	11.7284
2024.8	12.8031
2027.74	12.6705
2030.67	13.3815
2033.61	13.8488
2036.54	14.1649
2039.47	13.7935
2042.4	13.7576
2045.33	13.5694
2048.26	14.0794
2051.19	14.2766
2054.12	14.4627
2057.04	14.6573
2059.97	14.1908
2062.89	14.6929
2065.81	15.9858
2068.73	16.319
2071.65	17.8189
2074.57	18.8579
2077.49	20.8616
2080.41	21.9581
2083.32	23.1656
2086.24	25.1242
2089.15	26.662
2092.07	27.9205
2094.98	28.8992
2097.89	30.6722
2100.8	33.0538
2103.71	35.6673
2106.61	37.6842
2109.52	40.2873
2112.43	41.5172
2115.33	43.89
2118.23	46.2163
2121.13	49.6323
2124.04	53.1344
2126.94	55.8792
2129.83	59.5938
2132.73	63.0217
2135.63	67.2371
2138.53	71.1254
2141.42	75.1476
2144.31	78.5973
2147.21	81.8029
2150.1	85.584
2152.99	88.8452
2155.88	91.9107
2158.77	94.5006
2161.65	96.8921
2164.54	98.6924
2167.43	100.203
2170.31	101.298
2173.19	101.413
2176.07	101.284
2178.96	99.7461
2181.84	98.856
2184.72	97.0475
2187.59	95.628
2190.47	92.463
2193.35	89.6973
2196.22	87.0026
2199.09	83.7287
2201.97	80.3704
2204.84	76.8997
2207.71	73.1453
2210.58	70.0287
2213.45	65.7194
2216.31	62.1843
2219.18	58.728
2222.05	56.4465
2224.91	52.2871
2227.78	48.7983
2230.64	45.8934
2233.5	42.335
2236.36	39.5485
2239.22	37.7135
2242.08	35.2812
2244.93	33.7603
2247.79	32.4581
2250.64	29.8058
2253.5	29.1999
2256.35	27.0593
2259.2	25.4274
2262.05	24.517
2264.9	24.1221
2267.75	21.8306
2270.6	21.9294
2273.45	20.9646
2276.29	19.4509
2279.14	19.2753
2281.98	19.0095
2284.82	18.4796
2287.66	17.5711
2290.5	15.6908
2293.34	14.2459
2296.18	13.9876
2299.02	14.2289
2301.86	14.5688
2304.69	14.8022
2307.53	14.8844
2310.36	13.5209
2313.19	13.3784
2316.02	12.2945
2318.85	11.2114
2321.68	10.062
2324.51	9.5882
2327.34	9.0317
2330.16	8.47169
2332.99	7.47008
2335.81	5.95352
2338.64	5.43968
2341.46	4.79479
2344.28	3.45836
2347.1	2.78874
2349.92	2.22759
2352.74	1.20804
2355.55	-0.0524819
2358.37	-0.611774
2361.19	-0.922499
2364	0.249194
2366.81	1.59171
2369.62	2.55755
2372.44	2.95196
2375.24	2.5349
2378.05	2.01966
2380.86	1.25937
2383.67	2.01587
2386.47	2.61694
2389.28	3.62165
2392.08	3.62533
2394.89	4.54207
2397.69	4.38703
2400.49	4.1553
2403.29	4.1542
2406.09	4.47225
2408.88	4.50682
2411.68	4.05274
2414.48	3.81341
2417.27	3.94648
2420.06	4.62973
2422.86	4.8953
2425.65	4.76334
2428.44	5.07907
2431.23	4.89425
2434.02	4.7695
2436.81	5.07971
2439.59	5.46931
2442.38	4.63022
2445.16	4.68464
2447.95	4.5278
2450.73	5.39
2453.51	6.00559
2456.29	5.65857
2459.07	4.8634
2461.85	4.88265
2464.63	4.96902
2467.4	4.88103
2470.18	4.78819
2472.95	3.96352
2475.73	3.93698
2478.5	3.68943
2481.27	3.826
2484.04	2.87514
2486.81	2.44932
2489.58	2.30563
2492.35	2.2506
2495.12	2.19568
2497.88	1.38831
2500.65	0.832431
2503.41	0.875285
2506.17	1.14567
2508.94	1.47396
2511.7	1.75
2514.46	2.72524
2517.22	3.20482
2519.97	3.8384
2522.73	3.97919
2525.49	4.72608
2528.24	5.5313
2530.99	6.16873
2533.75	6.44861
2536.5	5.79546
2539.25	6.03688
2542	6.17248
2544.75	6.19589
2547.5	6.34337
2550.24	6.13657
2552.99	5.32435
2555.74	6.30034
2558.48	6.65643
2561.22	6.17963
2563.96	5.1422
2566.71	5.36559
2569.45	5.33169
2572.18	6.19208
2574.92	6.91477
2577.66	7.23282
2580.4	6.45545
2583.13	5.89399
2585.87	5.13426
2588.6	5.04914
2591.33	4.57966
2594.06	5.08319
2596.79	5.09496
2599.52	3.79614
2602.25	3.41429
2604.98	2.45557
2607.71	2.15158
2610.43	2.32205
2613.16	1.87713
2615.88	3.05474
2618.6	2.77377
2621.32	2.36786
2624.04	3.46225
2626.76	3.31846
2629.48	3.97197
2632.2	4.05741
2634.92	4.67745
2637.63	4.97778
2640.35	5.2953
2643.06	5.25626
2645.77	4.46064
2648.49	3.89129
2651.2	3.16993
2653.91	3.62165
2656.62	3.05418
2659.33	3.48765
2662.03	3.89419
2664.74	3.68445
2667.44	4.44055
2670.15	4.8836
2672.85	5.18133
2675.55	6.48564
2678.26	6.21794
2680.96	6.76161
2683.66	6.78809
2686.35	6.69583
2689.05	7.13823
2691.75	6.68371
2694.44	6.82041
2697.14	6.25161
2699.83	6.81756
2702.52	6.67068
2705.22	6.1839
2707.91	6.2865
2710.6	5.30687
2713.29	5.18884
2715.97	5.10893
2718.66	4.92401
2721.35	5.67165
2724.03	5.96547
2726.72	5.86924
2729.4	7.25328
2732.08	8.28328
2734.76	7.97161
2737.44	7.28011
2740.12	7.35687
2742.8	7.06534
2745.48	6.78421
2748.16	7.39983
2750.83	6.44366
2753.51	6.05417
2756.18	5.8645
2758.85	5.37992
2761.53	4.20248
2764.2	4.06153
2766.87	3.07274
2769.54	1.41271
2772.2	1.70812
2774.87	0.654488
2777.54	-0.173064
2780.2	0.272154
2782.87	-0.399289
2785.53	-0.706143
2788.19	-0.801906
2790.85	-0.69581
2793.51	-0.556679
2796.17	-0.486185
2798.83	-0.875009
2801.49	-1.00335
2804.15	-0.206909
2806.8	-0.137122
2809.46	0.43985
2812.11	0.639823
2814.76	0.865229
2817.42	0.391926
2820.07	2.22938
2822.72	3.42439
2825.37	5.55788
2828.02	8.06491
2830.66	11.1659
2833.31	13.9896
2835.96	17.0074
2838.6	20.8832
2841.24	24.8353
2843.89	30.1864
2846.53	35.7169
2849.17	41.2539
2851.81	47.9744
2854.45	55.4802
2857.09	62.7752
2859.72	69.9785
2862.36	76.9273
2865	83.1934
2867.63	89.8745
2870.26	94.7155
2872.9	99.1273
2875.53	103.341
2878.16	106.208
2880.79	109.75
2883.42	113.561
2886.05	117.526
2888.67	121.306
2891.3	125.158
2893.92	128.634
2896.55	133.595
2899.17	138.92
2901.79	144.551
2904.42	151.971
2907.04	160.94
2909.66	171.162
2912.27	182.123
2914.89	192.639
2917.51	204.299
2920.13	214.222
2922.74	222.968
2925.35	230.278
2927.97	235.32
2930.58	239.514
2933.19	241.46
2935.8	241.697
2938.41	241.541
2941.02	238.249
2943.63	233.623
2946.24	227.871
2948.84	220.51
2951.45	212.987
2954.05	204.738
2956.65	195.164
2959.26	185.672
2961.86	176.994
2964.46	167.841
2967.06	159.829
2969.66	151.036
2972.25	143.458
2974.85	135.274
2977.45	126.369
2980.04	117.357
2982.64	108.351
2985.23	99.7398
2987.82	91.2237
2990.41	81.8554
2993	74.2005
2995.59	66.3539
2998.18	59.4874
3000.77	52.9212
3003.36	46.3874
3005.94	40.0998
3008.53	33.9053
3011.11	29.662
3013.69	26.0121
3016.28	23.339
3018.86	19.8608
3021.44	17.4481
3024.02	16.299
3026.6	14.8456
3029.18	13.1835
3031.75	12.8007
3034.33	12.3182
3036.9	12.7233
3039.48	13.0977
3042.05	13.7819
3044.62	14.5041
3047.19	15.4702
3049.77	16.4652
3052.34	17.6926
3054.9	18.4688
3057.47	18.7362
3060.04	18.8081
3062.61	17.9183
3065.17	17.2698
3067.74	16.2654
3070.3	15.143
3072.86	13.3704
3075.42	12.2689
3077.99	11.2523
3080.54	9.45131
3083.1	7.95405
3085.66	6.17818
3088.22	3.71282
3090.78	2.06584
3093.33	1.72111
3095.89	0.996572
3098.44	0.338397
3100.99	-0.463443
3103.54	0.223114
3106.1	0.395859
3108.65	0.692039
3111.2	0.79548
3113.74	1.84827
3116.29	1.60046
3118.84	1.90438
3121.38	2.4064
3123.93	3.01159
3126.47	3.5346
3129.01	4.56188
3131.56	5.41149
3134.1	6.81867
3136.64	8.20448
3139.18	10.3165
3141.72	11.7678
3144.26	13.106
3146.79	15.024
3149.33	18.8865