File: data/Raman/poly_smoothed/Thy_40_11_32_1x_45s_532 nm_x100_100%_600 gr_mm_01.txt
#Acq. time (s)=	45
#Accumulations=	2
#Range (cm-¹)=	200...3150
#Windows=	2
#Auto scanning=	Off
#Autofocus=	Off
#Macrospot=	Off
#AutoExposure=	Off
#Spike filter=	Multiple accum.
#Delay time (s)=	0
#Binning=	1
#Readout mode=	Signal
#DeNoise=	Off
#ICS correction=	On
#Dark correction=	Off
#Inst. Process=	Off
#Detector Gain=	Best Dynamic Range
#Detector ADC=	20 kHz
#Detector temperature (°C)=	-69.85
#Instrument=	LabRAM HR Evol
#Detector=	Synapse
#Objective=	x100
#Grating=	600 gr/mm
#ND Filter=	100%
#Laser (nm)=	532
#Hole=	100.021
#Range=	Auto
#Laser Pol.=	No
#Raman. Pol.=	No
#Laser Pol. (°)=	-0.0007625
#Raman Pol. (°)=	89.9995
#Collection=	Microscope
#StageXY=	Marzhauser
#StageZ=	Marzhauser
#X (µm)=	248.7
#Y (µm)=	1676.7
#Z (µm)=	427.65
#Full time(mm:ss)=	3:18
#Project=
#Sample=
#Site=
#Title=	Thy_40_11_32_2x_45s_532 nm_x100_100%_600 gr_mm
#Remark=
#Date=	05.07.2022 12:17
#Acquired=	05.07.2022 12:17:58
#Base:Fit=	10.08.2022 10:01:35
#Base:Sub=	10.08.2022 10:01:52
#Filter:Polynom=	16.08.2022 10:21:53
#AxisType[0]=Intens
#AxisUnit[0]=Cnt
#AxisType[1]=Spectr
#AxisUnit[1]=1/cm
200.43	15.7751
204.059	14.3851
207.688	12.9621
211.314	11.9317
214.941	11.2247
218.564	10.4379
222.186	9.87081
225.809	8.92036
229.428	8.93217
233.045	9.94081
236.663	9.97464
240.278	8.94819
243.891	8.26644
247.503	8.32135
251.116	7.53106
254.725	6.21198
258.333	6.34003
261.939	6.27554
265.544	6.97884
269.148	7.51938
272.75	7.54717
276.351	5.74447
279.95	4.34446
283.548	3.88851
287.144	3.51153
290.739	5.45364
294.333	5.17326
297.925	5.55485
301.514	5.83828
305.104	5.01103
308.692	4.88301
312.279	5.71773
315.862	6.46844
319.446	6.95137
323.029	7.22161
326.608	6.6371
330.188	7.48924
333.766	8.29439
337.341	9.17625
340.917	7.86669
344.489	8.27288
348.062	7.33309
351.631	8.37172
355.201	7.96878
358.768	8.11201
362.333	7.45097
365.899	7.0307
369.462	8.70189
373.023	9.40063
376.585	8.87848
380.143	8.74869
383.7	7.05083
387.256	6.66396
390.812	6.50408
394.365	7.73093
397.916	7.18964
401.467	7.28158
405.015	7.26892
408.563	6.14545
412.109	5.19999
415.654	5.52152
419.197	4.66016
422.739	4.10328
426.279	3.1632
429.819	2.39064
433.356	3.56583
436.891	4.29496
440.426	6.09299
443.96	6.33418
447.492	7.5563
451.021	9.52056
454.551	11.3243
458.079	12.1156
461.604	12.7224
465.13	13.8877
468.654	16.0245
472.175	16.9822
475.696	18.3817
479.215	19.8511
482.733	21.3998
486.249	22.9956
489.765	23.3076
493.278	22.1198
496.789	22.372
500.301	21.8534
503.81	21.8924
507.317	21.4136
510.825	20.6266
514.33	20.9535
517.833	21.5821
521.335	23.0952
524.836	23.4087
528.335	23.8391
531.835	22.9085
535.332	22.907
538.827	21.5231
542.321	19.4157
545.814	17.4388
549.305	16.8221
552.795	15.709
556.282	15.3054
559.769	14.6474
563.255	14.1532
566.739	14.1157
570.223	12.9927
573.705	10.8675
577.183	9.5608
580.663	9.73811
584.141	9.5474
587.615	9.25545
591.09	9.77762
594.564	9.70557
598.035	12.1801
601.506	13.0549
604.974	14.8363
608.443	16.0594
611.908	16.5588
615.374	16.4774
618.837	17.0545
622.3	17.579
625.761	17.5674
629.219	16.8078
632.677	19.5173
636.135	21.0161
639.59	21.3628
643.043	23.5321
646.495	24.8098
649.948	25.5423
653.398	26.9439
656.846	27.5739
660.293	30.1753
663.738	31.4335
667.183	33.3254
670.626	33.7598
674.067	34.3241
677.508	36.9529
680.947	39.1109
684.385	41.1871
687.821	43.3039
691.254	44.9139
694.688	46.0257
698.121	47.8131
701.552	49.8146
704.98	50.3878
708.409	50.9122
711.836	52.5351
715.26	54.8996
718.685	57.5578
722.108	59.0163
725.528	61.0931
728.949	62.395
732.367	64.4592
735.785	64.3648
739.2	65.6123
742.614	66.5009
746.028	67.0461
749.439	67.164
752.849	68.4994
756.26	69.7419
759.667	71.753
763.073	73.0679
766.477	75.2958
769.883	78.0502
773.285	80.3161
776.686	81.6263
780.085	82.8496
783.484	85.5581
786.881	87.2156
790.276	90.0696
793.671	93.2829
797.064	95.809
800.456	99.0808
803.846	100.954
807.234	101.579
810.622	101.52
814.008	102.61
817.394	102.579
820.778	102.956
824.159	103.645
827.541	101.633
830.921	99.6734
834.298	99.1966
837.676	97.1963
841.051	94.565
844.426	92.567
847.798	91.1094
851.171	88.8642
854.54	84.7919
857.911	81.0626
861.278	78.7754
864.645	75.9647
868.01	74.0829
871.373	73.8487
874.735	73.7139
878.097	72.4836
881.457	70.8982
884.815	69.4426
888.172	68.1575
891.528	65.5993
894.882	64.5382
898.237	63.38
901.589	62.8029
904.94	61.3372
908.289	59.4906
911.635	58.2379
914.982	57.6209
918.328	56.8253
921.672	56.5044
925.015	56.1956
928.357	55.4326
931.698	52.5879
935.035	51.89
938.373	51.7874
941.71	51.2443
945.044	53.5829
948.378	54.1382
951.709	54.5757
955.041	56.2579
958.372	55.1337
961.699	53.7932
965.027	53.7954
968.352	54.0216
971.676	53.5035
975	53.2445
978.322	51.9121
981.642	49.9022
984.962	48.6968
988.28	47.6844
991.596	46.1786
994.911	43.359
998.227	42.1025
1001.54	41.1047
1004.85	39.7994
1008.16	37.4707
1011.47	35.3412
1014.78	34.9028
1018.08	34.713
1021.39	34.9128
1024.69	34.5383
1028	33.444
1031.3	31.8612
1034.6	30.7335
1037.9	29.7715
1041.19	28.3927
1044.49	27.9254
1047.78	27.4753
1051.08	26.6172
1054.37	25.7048
1057.66	24.2904
1060.95	22.7839
1064.24	23.3172
1067.53	23.2981
1070.81	22.8557
1074.1	22.6216
1077.38	23.2281
1080.66	24.1342
1083.94	25.1205
1087.22	25.1256
1090.5	25.4668
1093.78	25.1698
1097.05	25.5735
1100.33	26.0064
1103.6	25.3645
1106.87	24.8344
1110.14	23.9801
1113.41	23.5081
1116.68	22.4515
1119.95	19.6077
1123.21	16.9379
1126.48	15.7207
1129.74	13.3473
1133	11.9994
1136.26	9.71848
1139.52	8.34093
1142.78	8.43369
1146.04	6.71015
1149.29	6.29783
1152.55	5.16255
1155.8	5.23608
1159.05	5.15377
1162.3	4.26393
1165.55	4.13939
1168.8	2.75298
1172.05	3.96452
1175.29	5.09455
1178.54	5.60637
1181.78	6.43123
1185.02	6.84945
1188.26	6.35353
1191.5	6.09355
1194.74	6.41919
1197.97	7.54555
1201.21	9.00387
1204.44	9.16923
1207.68	10.7636
1210.91	11.1523
1214.14	13.4585
1217.37	14.7022
1220.59	16.1978
1223.82	17.0341
1227.05	18.8502
1230.27	20.3746
1233.49	22.754
1236.72	24.4285
1239.94	26.209
1243.16	28.6533
1246.37	29.546
1249.59	31.2528
1252.8	33.4126
1256.02	33.9992
1259.23	34.7346
1262.44	34.9128
1265.66	36.6744
1268.86	38.191
1272.07	40.002
1275.28	42.2596
1278.48	42.8478
1281.69	43.0764
1284.89	43.9477
1288.09	45.7747
1291.29	45.681
1294.49	45.6015
1297.69	45.8861
1300.89	45.9973
1304.08	46.1149
1307.28	46.1752
1310.47	46.1004
1313.66	45.4909
1316.85	44.69
1320.04	44.4317
1323.23	43.0248
1326.42	40.9335
1329.61	39.7917
1332.79	39.0558
1335.97	38.9556
1339.16	37.9825
1342.34	37.5502
1345.52	36.9864
1348.7	34.8699
1351.87	33.2558
1355.05	33.1155
1358.22	31.5734
1361.4	30.7599
1364.57	31.2775
1367.74	30.9964
1370.91	29.4039
1374.08	28.3274
1377.25	28.0715
1380.41	26.5952
1383.58	24.9717
1386.74	24.5461
1389.91	22.6319
1393.07	21.7674
1396.23	20.1521
1399.39	19.0968
1402.55	18.2403
1405.7	17.8839
1408.86	18.9691
1412.01	20.8308
1415.17	20.6662
1418.32	22.1955
1421.47	22.5308
1424.62	24.4462
1427.77	27.5692
1430.91	31.451
1434.06	34.2927
1437.2	38.4363
1440.35	39.1497
1443.49	39.489
1446.63	40.5857
1449.77	40.6565
1452.91	39.6719
1456.05	39.3791
1459.18	37.5669
1462.32	36.2569
1465.45	33.0951
1468.59	30.0489
1471.72	26.5439
1474.85	23.4276
1477.98	20.6167
1481.1	16.5969
1484.23	13.9012
1487.36	12.4251
1490.48	11.0748
1493.61	9.03657
1496.73	8.78362
1499.85	8.04735
1502.97	10.0634
1506.09	10.5197
1509.2	10.7702
1512.32	10.9373
1515.43	10.5699
1518.55	11.4912
1521.66	13.4557
1524.77	15.2321
1527.88	16.0492
1530.99	17.4156
1534.1	18.9001
1537.21	19.7996
1540.31	21.0563
1543.42	22.6969
1546.52	25.3693
1549.62	26.6945
1552.72	29.4998
1555.82	31.098
1558.92	33.3653
1562.02	35.9377
1565.11	37.7059
1568.21	38.9296
1571.3	40.4665
1574.39	40.5898
1577.49	40.8851
1580.57	42.2611
1583.66	42.3062
1586.75	42.7856
1589.84	43.3545
1592.92	43.7821
1596.01	45.1795
1599.09	43.8206
1602.17	43.858
1605.25	44.5584
1608.33	43.3361
1611.41	42.8899
1614.49	43.6009
1617.57	44.6486
1620.64	45.8868
1623.72	45.3811
1626.79	44.8786
1629.86	45.5308
1632.93	46.1502
1636	47.6541
1639.07	48.003
1642.13	47.9084
1645.2	48.992
1648.26	48.3031
1651.33	48.7095
1654.39	48.9477
1657.45	48.2732
1660.51	47.5472
1663.57	46.9458
1666.63	46.1139
1669.68	44.3292
1672.74	42.309
1675.79	40.0738
1678.85	37.2551
1681.9	33.9478
1684.95	29.3819
1688	27.1804
1691.05	24.5246
1694.09	20.9031
1697.14	16.9143
1700.18	14.2632
1703.23	12.1908
1706.27	10.097
1709.31	8.88714
1712.35	6.74961
1715.39	4.71667
1718.43	3.5247
1721.47	3.16417
1724.5	2.84057
1727.54	2.4203
1730.57	2.25213
1733.61	1.26352
1736.64	1.62818
1739.67	1.4211
1742.7	1.91739
1745.72	1.56699
1748.75	1.54131
1751.77	0.454727
1754.8	0.572146
1757.82	0.562461
1760.84	0.684961
1763.87	1.15424
1766.89	0.867875
1769.91	0.341928
1772.92	0.669804
1775.94	0.987636
1778.95	1.00294
1781.97	1.01195
1784.98	0.85878
1787.99	1.20834
1791.01	1.37352
1794.01	2.04329
1797.02	1.91386
1800.03	2.20138
1803.04	2.15369
1806.04	2.24896
1809.05	3.11563
1812.05	3.00136
1815.05	2.80267
1818.05	2.64999
1821.05	2.48059
1824.05	1.74861
1827.05	2.32349
1830.04	2.27302
1833.04	1.86052
1836.03	1.55056
1839.03	0.931957
1842.02	1.06212
1845.01	1.27218
1848	1.48072
1850.99	1.62552
1853.97	1.47541
1856.96	2.27614
1859.94	2.0613
1862.93	1.93402
1865.91	2.01898
1868.89	2.24038
1871.87	2.71157
1874.85	3.59401
1877.83	4.40708
1880.81	4.38585
1882.57	4.97492
1885.56	4.35249
1888.55	4.07832
1891.54	4.30462
1894.52	3.51212
1897.51	3.64948
1900.49	3.08018
1903.47	3.22379
1906.45	2.64312
1909.43	1.20893
1912.41	2.03335
1915.39	1.79444
1918.37	1.11517
1921.34	1.47442
1924.32	0.507979
1927.29	-0.132582
1930.26	-0.263442
1933.23	-0.261951
1936.2	0.187135
1939.17	1.267
1942.14	1.25474
1945.11	1.73957
1948.07	2.37871
1951.04	2.70502
1954	3.06368
1956.96	3.68748
1959.93	4.00922
1962.89	4.62889
1965.85	4.87459
1968.8	5.08112
1971.76	5.50146
1974.72	4.7698
1977.67	5.24738
1980.63	4.9223
1983.58	4.50331
1986.53	4.08948
1989.48	3.51736
1992.43	2.97747
1995.38	2.67652
1998.32	3.16984
2001.27	3.9326
2004.22	4.15963
2007.16	3.84507
2010.1	4.1033
2013.04	3.89082
2015.98	3.80065
2018.92	4.7522
2021.86	5.06461
2024.8	5.84675
2027.74	6.02118
2030.67	6.22103
2033.61	6.19675
2036.54	6.15085
2039.47	6.33302
2042.4	7.06608
2045.33	8.24965
2048.26	8.2569
2051.19	8.80939
2054.12	9.04406
2057.04	9.34544
2059.97	9.38323
2062.89	9.67123
2065.81	10.0492
2068.73	11.2221
2071.65	12.4385
2074.57	13.1935
2077.49	13.1375
2080.41	13.1103
2083.32	14.4631
2086.24	14.6501
2089.15	15.0626
2092.07	15.8303
2094.98	16.033
2097.89	17.3045
2100.8	17.8176
2103.71	19.0157
2106.61	20.2412
2109.52	21.431
2112.43	23.0782
2115.33	23.8784
2118.23	25.3098
2121.13	26.0305
2124.04	27.701
2126.94	30.0636
2129.83	30.8231
2132.73	32.1275
2135.63	34.0631
2138.53	35.7579
2141.42	37.1864
2144.31	38.7987
2147.21	39.8013
2150.1	41.2671
2152.99	43.866
2155.88	46.014
2158.77	47.768
2161.65	50.3644
2164.54	51.8939
2167.43	52.8647
2170.31	53.0808
2173.19	53.2704
2176.07	53.2688
2178.96	53.1206
2181.84	51.6369
2184.72	51.1766
2187.59	49.6165
2190.47	49.0248
2193.35	47.2166
2196.22	45.7413
2199.09	43.6296
2201.97	42.3641
2204.84	40.5056
2207.71	38.4058
2210.58	36.0182
2213.45	34.0419
2216.31	32.7865
2219.18	30.9325
2222.05	30.1427
2224.91	29.1883
2227.78	27.9858
2230.64	26.5291
2233.5	25.3553
2236.36	24.4932
2239.22	23.1792
2242.08	21.9414
2244.93	21.2954
2247.79	20.1554
2250.64	18.9032
2253.5	18.5614
2256.35	18.1847
2259.2	17.4943
2262.05	17.0641
2264.9	16.6558
2267.75	16.9259
2270.6	17.2654
2273.45	17.0305
2276.29	15.5251
2279.14	14.2927
2281.98	12.9911
2284.82	12.7881
2287.66	11.2884
2290.5	10.3902
2293.34	9.1423
2296.18	8.43136
2299.02	8.13382
2301.86	8.80037
2304.69	9.40666
2307.53	9.09025
2310.36	9.3978
2313.19	9.80495
2316.02	10.1821
2318.85	10.5962
2321.68	10.4725
2324.51	10.6983
2327.34	10.8429
2330.16	12.3911
2332.99	11.9141
2335.81	11.5624
2338.64	11.4091
2341.46	10.9284
2344.28	10.2011
2347.1	9.75092
2349.92	8.48842
2352.74	7.56332
2355.55	6.84412
2358.37	5.5625
2361.19	4.33847
2364	4.16993
2366.81	5.00256
2369.62	4.26707
2372.44	4.15515
2375.24	3.71224
2378.05	3.42779
2380.86	3.44765
2383.67	3.28004
2386.47	2.90723
2389.28	2.59313
2392.08	2.76825
2394.89	4.10743
2397.69	4.52992
2400.49	4.04778
2403.29	4.12285
2406.09	4.22766
2408.88	5.60596
2411.68	5.82204
2414.48	5.79335
2417.27	6.3866
2420.06	6.60017
2422.86	6.96233
2425.65	7.84893
2428.44	7.9963
2431.23	8.79728
2434.02	7.98176
2436.81	7.34205
2439.59	6.49555
2442.38	6.51004
2445.16	5.53906
2447.95	5.1305
2450.73	4.52798
2453.51	4.30371
2456.29	3.85459
2459.07	4.16199
2461.85	4.22239
2464.63	3.56755
2467.4	3.26992
2470.18	2.78988
2472.95	2.92946
2475.73	2.65425
2478.5	2.89467
2481.27	2.22359
2484.04	2.84414
2486.81	2.69002
2489.58	2.87339
2492.35	3.10682
2495.12	3.20143
2497.88	2.49509
2500.65	1.44419
2503.41	0.929541
2506.17	1.06241
2508.94	1.52509
2511.7	0.866645
2514.46	0.313068
2517.22	0.623995
2519.97	0.376004
2522.73	0.713975
2525.49	1.28364
2528.24	1.59895
2530.99	1.8606
2533.75	1.70606
2536.5	1.98668
2539.25	2.43794
2542	2.90051
2544.75	2.6388
2547.5	2.36266
2550.24	2.46414
2552.99	2.06423
2555.74	2.26483
2558.48	2.3053
2561.22	2.05502
2563.96	1.6203
2566.71	2.4554
2569.45	2.81555
2572.18	2.93587
2574.92	2.91872
2577.66	2.80088
2580.4	3.08715
2583.13	3.47465
2585.87	3.60505
2588.6	4.1005
2591.33	4.97036
2594.06	5.0411
2596.79	5.19203
2599.52	5.91178
2602.25	5.62858
2604.98	6.75393
2607.71	6.27404
2610.43	5.22191
2613.16	3.81986
2615.88	4.14828
2618.6	3.47728
2621.32	2.89217
2624.04	2.29781
2626.76	1.22757
2629.48	1.74654
2632.2	2.24348
2634.92	1.81411
2637.63	0.912135
2640.35	1.2637
2643.06	2.17126
2645.77	2.23547
2648.49	2.64952
2651.2	2.8482
2653.91	3.22372
2656.62	4.46838
2659.33	5.40003
2662.03	6.45564
2664.74	8.02565
2667.44	7.92771
2670.15	8.26551
2672.85	8.4453
2675.55	7.97699
2678.26	8.04267
2680.96	8.67316
2683.66	8.30855
2686.35	8.52047
2689.05	8.84558
2691.75	8.8726
2694.44	10.0078
2697.14	10.2043
2699.83	9.30108
2702.52	9.08561
2705.22	10.5967
2707.91	10.6214
2710.6	10.2526
2713.29	10.3257
2715.97	10.4245
2718.66	10.7678
2721.35	10.7624
2724.03	11.097
2726.72	10.1589
2729.4	10.0073
2732.08	9.36554
2734.76	8.21387
2737.44	7.62557
2740.12	8.02992
2742.8	7.45213
2745.48	7.70946
2748.16	7.00051
2750.83	6.20789
2753.51	6.24145
2756.18	5.38876
2758.85	5.59274
2761.53	5.2617
2764.2	4.97225
2766.87	4.77757
2769.54	5.35009
2772.2	5.42788
2774.87	4.72425
2777.54	4.73735
2780.2	4.6686
2782.87	3.66926
2785.53	3.16514
2788.19	2.81366
2790.85	2.94305
2793.51	2.40624
2796.17	2.71409
2798.83	1.77466
2801.49	2.10276
2804.15	3.71065
2806.8	3.42339
2809.46	2.68128
2812.11	2.4005
2814.76	1.97701
2817.42	2.14025
2820.07	2.92886
2822.72	4.07479
2825.37	5.06967
2828.02	6.70196
2830.66	8.6982
2833.31	11.2817
2835.96	14.0354
2838.6	16.551
2841.24	19.1152
2843.89	22.4351
2846.53	25.7846
2849.17	29.365
2851.81	34.1362
2854.45	39.021
2857.09	43.2956
2859.72	47.2805
2862.36	51.5984
2865	55.5424
2867.63	59.1027
2870.26	61.3576
2872.9	63.6492
2875.53	66.0996
2878.16	68.5653
2880.79	70.9408
2883.42	72.9496
2886.05	74.2878
2888.67	76.3537
2891.3	78.3218
2893.92	79.9832
2896.55	82.1329
2899.17	84.8491
2901.79	88.2158
2904.42	92.1543
2907.04	96.8194
2909.66	102.345
2912.27	107.673
2914.89	114.053
2917.51	119.651
2920.13	124.889
2922.74	129.405
2925.35	132.672
2927.97	135.668
2930.58	137.12
2933.19	138.186
2935.8	138.344
2938.41	137.482
2941.02	135.145
2943.63	132.759
2946.24	128.084
2948.84	123.627
2951.45	119.411
2954.05	113.949
2956.65	108.335
2959.26	102.587
2961.86	97.8011
2964.46	92.7293
2967.06	86.9509
2969.66	82.7994
2972.25	78.183
2974.85	73.9516
2977.45	69.2058
2980.04	65.0591
2982.64	60.7311
2985.23	56.4249
2987.82	52.0605
2990.41	47.3191
2993	42.8862
2995.59	38.622
2998.18	34.4024
3000.77	30.1553
3003.36	26.4912
3005.94	23.6263
3008.53	21.2665
3011.11	19.0915
3013.69	17.254
3016.28	15.107
3018.86	14.2936
3021.44	12.727
3024.02	12.4528
3026.6	12.1489
3029.18	11.5921
3031.75	10.9429
3034.33	12.1639
3036.9	12.0608
3039.48	12.1185
3042.05	13.1632
3044.62	14.0633
3047.19	13.9907
3049.77	13.7098
3052.34	13.3912
3054.9	12.6919
3057.47	11.6338
3060.04	10.5889
3062.61	9.35732
3065.17	8.26098
3067.74	7.91336
3070.3	7.01757
3072.86	6.34115
3075.42	5.2773
3077.99	4.42988
3080.54	3.88983
3083.1	2.82805
3085.66	2.42617
3088.22	2.05952
3090.78	1.46827
3093.33	1.15632
3095.89	1.34089
3098.44	1.65979
3100.99	1.71045
3103.54	2.4528
3106.1	2.42192
3108.65	2.13431
3111.2	1.45678
3113.74	1.28968
3116.29	1.15181
3118.84	0.386787
3121.38	0.040054
3123.93	0.485773
3126.47	0.690273
3129.01	1.11055
3131.56	1.27745
3134.1	0.806596
3136.64	1.3831
3139.18	0.916262
3141.72	1.16414
3144.26	1.32722
3146.79	2.00512
3149.33	1.76382