File: data/Raman/poly_smoothed/Thy_30_10_49_1x_45s_532 nm_x100_100%_600 gr_mm_01.txt
#Acq. time (s)=	45
#Accumulations=	2
#Range (cm-¹)=	200...3150
#Windows=	2
#Auto scanning=	Off
#Autofocus=	Off
#Macrospot=	Off
#AutoExposure=	Off
#Spike filter=	Multiple accum.
#Delay time (s)=	0
#Binning=	1
#Readout mode=	Signal
#DeNoise=	Off
#ICS correction=	On
#Dark correction=	Off
#Inst. Process=	Off
#Detector Gain=	Best Dynamic Range
#Detector ADC=	20 kHz
#Detector temperature (°C)=	-69.85
#Instrument=	LabRAM HR Evol
#Detector=	Synapse
#Objective=	x100
#Grating=	600 gr/mm
#ND Filter=	100%
#Laser (nm)=	532
#Hole=	100.021
#Range=	Auto
#Laser Pol.=	No
#Raman. Pol.=	No
#Laser Pol. (°)=	-0.0007625
#Raman Pol. (°)=	89.9995
#Collection=	Microscope
#StageXY=	Marzhauser
#StageZ=	Marzhauser
#X (µm)=	4733.7
#Y (µm)=	-7700.4
#Z (µm)=	584.4
#Full time(mm:ss)=	3:18
#Project=
#Sample=
#Site=
#Title=	Thy_30_10_49_2x_45s_532 nm_x100_100%_600 gr_mm
#Remark=
#Date=	30.06.2022 14:54
#Acquired=	30.06.2022 14:54:37
#Base:Fit=	10.08.2022 09:58:11
#Base:Sub=	10.08.2022 09:58:44
#Filter:Polynom=	16.08.2022 10:22:53
#AxisType[0]=Intens
#AxisUnit[0]=Cnt
#AxisType[1]=Spectr
#AxisUnit[1]=1/cm
200.533	-0.47895
204.162	2.47711
207.792	2.67816
211.418	3.30693
215.044	3.24424
218.667	3.6405
222.289	4.78542
225.912	3.91942
229.531	3.63912
233.148	4.69398
236.766	3.47545
240.381	3.55181
243.994	3.19587
247.606	2.52944
251.217	2.72437
254.828	2.70659
258.436	1.91239
262.042	2.11079
265.647	3.69117
269.25	4.61062
272.852	4.43308
276.453	4.12455
280.052	4.34997
283.65	3.74686
287.247	2.83031
290.842	3.47122
294.436	4.74831
298.028	5.79055
301.617	6.36309
305.206	8.29789
308.794	10.1132
312.381	9.64464
315.964	11.186
319.548	13.2221
323.131	14.185
326.71	14.9945
330.29	16.5789
333.868	18.102
337.443	18.3988
341.018	19.0388
344.591	17.6309
348.163	17.7676
351.733	17.3026
355.303	16.1477
358.869	14.6976
362.435	13.4999
366.001	11.7449
369.563	11.4936
373.124	9.60555
376.686	9.37119
380.244	7.99144
383.801	7.32074
387.357	8.44727
390.911	9.08127
394.466	9.90645
398.018	9.58572
401.568	9.24259
405.117	11.2382
408.664	12.1471
412.21	13.8941
415.755	14.601
419.298	14.8898
422.84	13.2443
426.38	11.4868
429.919	11.4235
433.455	9.99079
436.992	8.95544
440.527	7.6601
444.06	6.7145
447.593	5.05405
451.122	4.15625
454.651	3.55678
458.18	3.65443
461.705	4.08865
465.23	5.21972
468.752	7.30407
472.275	9.17823
475.797	10.9481
479.315	14.059
482.834	16.9343
486.349	19.034
489.863	21.4549
493.378	23.8966
496.889	27.4162
500.401	29.5687
503.91	31.1225
507.417	30.0687
510.923	29.5098
514.43	29.5456
517.933	29.4956
521.435	27.8015
524.936	26.6591
528.435	24.1121
531.933	22.5676
535.43	20.8499
538.927	20.1562
542.421	18.1434
545.913	15.5544
549.403	13.3623
552.893	12.0284
556.381	11.1674
559.868	9.68456
563.354	8.77732
566.839	6.88717
570.322	4.88954
573.802	4.62218
577.283	3.8161
580.762	5.13405
584.24	5.80146
587.714	5.85301
591.19	5.86298
594.663	4.76411
598.134	5.58726
601.605	7.90858
605.073	8.63348
608.542	10.2938
612.007	11.1767
615.473	11.7009
618.936	13.6266
622.397	14.3797
625.859	15.0338
629.318	14.0014
632.775	15.5526
636.233	16.0289
639.688	16.2916
643.142	17.1103
646.594	15.8635
650.045	16.0877
653.496	15.4151
656.944	16.7075
660.391	17.9511
663.837	17.7963
667.281	19.5487
670.724	19.6843
674.166	20.4595
677.606	20.4711
681.045	23.0641
684.483	25.1766
687.917	27.1576
691.352	27.2655
694.786	28.6219
698.219	29.2716
701.65	31.0436
705.078	32.1338
708.506	32.2477
711.934	33.2749
715.358	35.8302
718.782	36.7983
722.204	37.7922
725.626	39.8599
729.045	41.0492
732.464	41.6813
735.881	43.2713
739.297	44.6539
742.711	45.0661
746.125	48.1251
749.537	51.2869
752.946	52.6263
756.357	55.243
759.764	57.6155
763.17	59.9915
766.575	62.8905
769.978	64.8322
773.382	65.8373
776.783	67.2273
780.182	69.6445
783.581	69.8147
786.978	70.8142
790.373	72.4466
793.768	74.6901
797.161	75.3284
800.552	76.842
803.941	78.4918
807.33	79.687
810.718	82.3142
814.105	83.1384
817.49	83.2362
820.873	84.5828
824.256	85.017
827.637	85.9452
831.016	85.2242
834.395	84.3271
837.772	82.9516
841.147	80.6586
844.522	78.0467
847.894	76.2023
851.267	75.0001
854.637	70.4791
858.007	67.1902
861.374	65.1467
864.739	62.2912
868.106	59.2766
871.469	57.7137
874.831	56.23
878.193	53.7003
881.553	53.1038
884.911	53.1344
888.268	52.8728
891.623	53.6964
894.978	54.4657
898.331	53.0883
901.683	52.7193
905.033	52.0765
908.383	51.4288
911.731	50.0101
915.078	49.2465
918.423	48.1433
921.768	45.9685
925.111	43.9499
928.452	41.5883
931.791	39.6746
935.13	37.0059
938.468	34.9611
941.803	35.0459
945.139	33.6035
948.473	33.6567
951.804	33.3594
955.136	34.8025
958.465	34.3805
961.794	33.9216
965.12	34.1773
968.447	37.0539
971.771	39.5302
975.095	41.0337
978.417	41.7189
981.737	42.4654
985.057	44.1411
988.375	45.5037
991.691	46.9011
995.006	48.5253
998.32	47.4108
1001.63	48.4261
1004.95	46.6485
1008.26	45.2701
1011.56	44.2195
1014.87	42.6946
1018.18	41.6916
1021.48	41.6232
1024.79	40.2075
1028.09	40.1549
1031.39	39.0774
1034.69	36.7687
1037.99	36.6234
1041.29	33.1569
1044.58	31.5677
1047.88	31.6001
1051.17	30.2185
1054.46	27.7978
1057.75	26.2194
1061.04	25.2763
1064.33	25.2176
1067.62	24.5533
1070.9	24.7427
1074.19	23.5674
1077.47	23.1835
1080.76	21.4332
1084.04	20.6724
1087.32	19.961
1090.59	19.472
1093.87	19.1154
1097.15	18.9571
1100.42	19.703
1103.69	19.9663
1106.97	21.0135
1110.24	20.009
1113.51	18.2071
1116.77	17.2671
1120.04	16.505
1123.31	14.7124
1126.57	13.0236
1129.83	10.1265
1133.1	8.74288
1136.36	8.27996
1139.62	6.89785
1142.87	6.81369
1146.13	6.73631
1149.38	6.33846
1152.64	4.91232
1155.89	3.82562
1159.14	3.14571
1162.39	1.94483
1165.64	0.900514
1168.89	0.738519
1172.14	2.06455
1175.38	2.96122
1178.63	4.15547
1181.87	5.38093
1185.11	6.45296
1188.35	7.16412
1191.59	7.86026
1194.83	10.093
1198.07	12.3224
1201.3	13.3395
1204.53	16.0861
1207.77	17.3294
1211	21.0958
1214.23	24.3314
1217.46	27.5308
1220.69	31.5981
1223.91	35.4418
1227.14	39.1623
1230.36	42.1058
1233.59	43.9696
1236.81	45.7532
1240.03	48.092
1243.25	49.6643
1246.46	52.155
1249.68	55.3752
1252.9	56.6378
1256.11	58.3203
1259.32	58.5171
1262.54	59.8148
1265.75	61.3919
1268.96	63.5554
1272.16	64.448
1275.37	66.3046
1278.57	66.9107
1281.78	67.1589
1284.98	66.2937
1288.18	66.0474
1291.38	67.2368
1294.58	67.4434
1297.78	69.1585
1300.98	69.4142
1304.17	69.81
1307.37	70.01
1310.56	69.197
1313.76	69.8362
1316.95	70.7528
1320.14	69.6306
1323.32	67.3134
1326.51	65.1986
1329.7	63.6722
1332.88	61.0846
1336.07	59.3996
1339.25	56.8609
1342.43	55.5949
1345.61	53.2148
1348.79	50.4981
1351.96	47.9895
1355.14	45.2415
1358.31	42.8402
1361.49	38.9683
1364.66	38.1465
1367.83	37.9577
1371	36.7751
1374.17	33.5176
1377.34	32.2258
1380.5	30.5743
1383.67	29.912
1386.83	29.9254
1390	28.5593
1393.16	26.5137
1396.32	24.7499
1399.48	22.709
1402.64	21.8035
1405.79	20.5796
1408.95	19.8134
1412.1	21.2786
1415.26	22.6029
1418.41	26.2127
1421.56	29.6889
1424.71	34.9769
1427.86	40.2336
1431	46.9273
1434.15	53.5449
1437.29	59.3028
1440.44	64.6538
1443.58	69.2798
1446.72	71.3307
1449.86	72.4161
1453	72.6378
1456.14	71.4998
1459.27	68.875
1462.41	65.1114
1465.54	58.9991
1468.67	52.7077
1471.81	45.48
1474.94	39.6707
1478.07	32.4246
1481.19	26.1985
1484.32	19.5024
1487.45	14.7194
1490.57	10.8519
1493.69	7.39429
1496.82	3.82786
1499.94	1.85522
1503.06	0.661394
1506.17	-0.351336
1509.29	-0.0483658
1512.41	0.237687
1515.52	2.21839
1518.64	2.95962
1521.75	3.94986
1524.86	4.44557
1527.97	5.99689
1531.08	6.01656
1534.19	6.0456
1537.29	6.47428
1540.4	7.99453
1543.5	9.59373
1546.61	14.725
1549.71	18.667
1552.81	23.5438
1555.91	26.6221
1559.01	30.2797
1562.11	32.7194
1565.2	35.8557
1568.29	38.3936
1571.39	42.1209
1574.48	45.723
1577.57	48.4942
1580.66	51.1835
1583.75	54.9385
1586.84	56.5409
1589.93	58.8177
1593.01	59.4067
1596.1	59.7042
1599.18	59.5543
1602.26	59.3405
1605.34	58.6744
1608.42	56.7275
1611.5	54.9712
1614.58	55.0951
1617.65	55.3095
1620.73	56.2144
1623.8	57.86
1626.87	58.3188
1629.95	59.0936
1633.02	61.3909
1636.09	63.7316
1639.15	67.2641
1642.22	72.9487
1645.29	76.8526
1648.35	80.9851
1651.42	84.5332
1654.48	88.0323
1657.54	90.9298
1660.6	91.1781
1663.66	91.0379
1666.72	91.1763
1669.77	88.6705
1672.83	84.5611
1675.88	81.26
1678.93	76.4801
1681.99	69.9758
1685.04	62.8639
1688.09	56.1596
1691.13	50.045
1694.18	44.2066
1697.23	38.0522
1700.27	30.9716
1703.32	25.3366
1706.36	21.4343
1709.4	18.1017
1712.44	14.5485
1715.48	12.4589
1718.52	9.84187
1721.56	8.03745
1724.59	7.07681
1727.63	5.9623
1730.66	5.71279
1733.69	3.88966
1736.72	3.76814
1739.75	2.81437
1742.78	2.92999
1745.81	1.50694
1748.84	1.61813
1751.86	1.1295
1754.89	0.52347
1757.91	-0.457769
1760.93	-0.559133
1763.95	-0.346102
1766.97	-0.994096
1769.99	-1.63429
1773.01	-1.53831
1776.03	-1.06312
1779.04	-1.07592
1782.06	-0.509701
1785.07	-0.43446
1788.08	0.386171
1791.09	0.183609
1794.1	-0.178629
1797.11	0.273689
1800.12	1.13807
1803.12	1.3002
1806.13	1.76022
1809.13	2.10931
1812.14	3.08
1815.14	3.49581
1818.14	2.83601
1821.14	2.61301
1824.14	3.04162
1827.13	2.82659
1830.13	3.33538
1833.12	2.91224
1836.12	3.58041
1839.11	3.60233
1842.1	3.9119
1845.09	5.47019
1848.08	6.01139
1851.07	6.65583
1854.06	6.66919
1857.04	6.82913
1860.03	6.5401
1863.01	7.8131
1866	7.40127
1868.98	7.00943
1871.96	7.19768
1874.94	7.50314
1877.92	7.87466
1880.89	8.27889
1882.48	9.43672
1885.47	10.6335
1888.46	9.86969
1891.44	10.3621
1894.43	10.7587
1897.41	11.0465
1900.4	11.3245
1903.38	11.6853
1906.36	11.027
1909.34	11.9791
1912.32	12.1778
1915.29	12.5291
1918.27	13.2501
1921.25	12.3265
1924.22	12.8898
1927.2	13.0412
1930.17	13.2314
1933.14	13.5103
1936.11	13.2464
1939.08	12.4511
1942.05	12.316
1945.01	13.9731
1947.98	14.5534
1950.94	16.3081
1953.91	16.9697
1956.87	16.8212
1959.83	16.2434
1962.79	16.0179
1965.75	16.7375
1968.71	16.8345
1971.67	16.605
1974.62	17.2946
1977.58	16.4272
1980.53	16.3806
1983.48	15.5865
1986.43	15.1281
1989.38	14.5359
1992.33	14.4413
1995.28	14.3276
1998.23	13.1424
2001.18	13.3341
2004.12	12.9032
2007.06	13.2107
2010.01	13.1811
2012.95	14.4215
2015.89	15.6176
2018.83	15.9876
2021.77	17.128
2024.71	18.2894
2027.64	18.5965
2030.58	19.8555
2033.51	21.4187
2036.45	22.9203
2039.38	25.1028
2042.31	25.1722
2045.24	26.0145
2048.17	26.1849
2051.1	25.779
2054.02	26.5989
2056.95	25.9703
2059.87	26.3273
2062.8	27.166
2065.72	26.5665
2068.64	25.5417
2071.56	25.5087
2074.48	26.0545
2077.4	26.6556
2080.31	26.7739
2083.23	27.869
2086.14	28.5748
2089.06	29.0457
2091.97	29.5201
2094.88	31.3299
2097.79	33.0351
2100.7	34.3316
2103.61	36.8307
2106.52	38.515
2109.43	41.186
2112.33	43.2123
2115.24	45.5215
2118.14	48.4765
2121.04	51.7857
2123.94	55.9564
2126.84	58.7434
2129.74	62.9374
2132.64	66.2171
2135.54	69.4001
2138.43	72.4401
2141.33	75.8534
2144.22	79.007
2147.11	82.3201
2150.01	85.3528
2152.9	88.2217
2155.79	91.7922
2158.67	93.4107
2161.56	95.0683
2164.45	97.1132
2167.33	98.4674
2170.22	99.7124
2173.1	100.589
2175.98	100.362
2178.86	99.0946
2181.74	97.492
2184.62	96.7169
2187.5	96.0228
2190.38	94.2257
2193.25	91.5858
2196.13	88.884
2199	85.7195
2201.88	81.3316
2204.75	77.3696
2207.62	74.4851
2210.49	70.9936
2213.36	66.3449
2216.22	62.069
2219.09	58.3792
2221.96	55.4767
2224.82	51.9563
2227.68	49.3263
2230.55	46.4803
2233.41	44.6816
2236.27	42.7516
2239.12	39.7634
2241.98	37.7345
2244.84	36.3284
2247.7	34.804
2250.55	33.9601
2253.41	33.8913
2256.26	34.6537
2259.11	34.3695
2261.96	35.0256
2264.81	34.2841
2267.66	33.2317
2270.51	32.5139
2273.35	32.1265
2276.2	31.849
2279.04	30.2162
2281.89	27.629
2284.73	26.2162
2287.57	25.3854
2290.41	23.4051
2293.25	21.6524
2296.09	20.3061
2298.93	20.7177
2301.76	19.9016
2304.6	18.6333
2307.44	18.4939
2310.27	17.8867
2313.1	18.3337
2315.93	18.84
2318.76	19.5113
2321.59	19.3966
2324.42	19.3083
2327.25	19.2964
2330.07	19.7915
2332.9	20.2099
2335.72	18.7116
2338.55	18.3329
2341.37	18.1002
2344.19	17.49
2347.01	15.7612
2349.83	14.616
2352.65	14.0499
2355.46	13.8221
2358.28	12.7299
2361.09	12.232
2363.91	12.698
2366.72	13.3375
2369.53	12.7792
2372.34	11.972
2375.15	12.0663
2377.96	11.22
2380.77	10.402
2383.58	10.8572
2386.38	9.54299
2389.19	8.98031
2391.99	7.8864
2394.8	7.70051
2397.6	7.92689
2400.4	7.80196
2403.2	7.90154
2406	8.32785
2408.79	8.8829
2411.59	9.85137
2414.39	10.8267
2417.18	10.7232
2419.98	11.4389
2422.77	11.7992
2425.56	11.4199
2428.35	11.8981
2431.14	12.2362
2433.93	12.6736
2436.72	12.3004
2439.5	10.8787
2442.29	10.2806
2445.07	9.63704
2447.86	9.4143
2450.64	8.40292
2453.42	8.52742
2456.2	7.66201
2458.98	7.42868
2461.76	7.41991
2464.54	7.33416
2467.32	7.6104
2470.09	7.58451
2472.87	7.68177
2475.64	7.9581
2478.41	6.86759
2481.18	6.80568
2483.95	6.2695
2486.72	5.39391
2489.49	4.77008
2492.26	4.02378
2495.03	3.58695
2497.79	3.39156
2500.56	2.0424
2503.32	0.560422
2506.09	-0.463311
2508.85	-0.94898
2511.61	-0.758257
2514.37	-0.594788
2517.13	-0.899591
2519.89	0.403712
2522.64	0.912907
2525.4	1.29176
2528.15	2.89624
2530.91	4.13435
2533.66	5.19429
2536.41	5.71835
2539.16	6.86355
2541.91	7.68786
2544.66	7.66757
2547.41	7.07723
2550.16	6.93098
2552.9	6.5768
2555.65	6.08403
2558.39	6.12303
2561.13	5.50212
2563.88	4.37054
2566.62	3.46369
2569.36	2.35738
2572.1	2.19206
2574.84	2.34199
2577.57	3.09832
2580.31	2.74663
2583.05	3.2663
2585.78	3.64634
2588.51	4.3826
2591.24	3.43976
2593.98	4.06914
2596.71	5.26638
2599.44	5.577
2602.16	5.46861
2604.89	4.4832
2607.62	4.54395
2610.34	3.94442
2613.07	2.33586
2615.79	1.6529
2618.52	1.64328
2621.24	1.55316
2623.96	0.949914
2626.68	0.235777
2629.4	-0.660544
2632.11	-0.64311
2634.83	-0.996571
2637.55	-0.821899
2640.26	-0.223751
2642.98	-0.0103823
2645.69	0.299776
2648.4	0.69392
2651.11	1.83311
2653.82	2.07959
2656.53	1.70915
2659.24	1.25444
2661.95	2.52056
2664.65	3.49854
2667.36	3.84065
2670.06	3.94298
2672.76	4.83438
2675.47	4.76523
2678.17	5.13734
2680.87	5.17169
2683.57	5.13463
2686.27	5.62436
2688.97	5.51712
2691.66	5.68248
2694.36	5.84261
2697.05	6.05247
2699.75	6.4239
2702.44	7.11173
2705.13	8.27024
2707.82	8.65432
2710.51	9.06702
2713.2	9.87893
2715.89	10.6478
2718.57	10.7773
2721.26	10.6211
2723.95	10.4996
2726.63	11.6016
2729.31	12.6782
2732	13.0794
2734.68	12.6638
2737.36	12.13
2740.04	12.0074
2742.72	11.4502
2745.39	10.5081
2748.07	10.1378
2750.75	9.79128
2753.42	10.0149
2756.09	9.5052
2758.77	9.47668
2761.44	9.32532
2764.11	9.05064
2766.78	9.16638
2769.45	8.53533
2772.12	8.09248
2774.78	7.25154
2777.45	7.15903
2780.12	7.48751
2782.78	7.1385
2785.44	6.74098
2788.11	6.85599
2790.77	6.88437
2793.43	7.48502
2796.09	7.66498
2798.75	7.81824
2801.4	7.63101
2804.06	7.70863
2806.72	8.53951
2809.37	8.07924
2812.03	8.24535
2814.68	8.56063
2817.33	10.0044
2819.98	11.5926
2822.63	12.7103
2825.28	16.0958
2827.93	19.8117
2830.58	24.0421
2833.23	28.6201
2835.87	33.3686
2838.52	38.5463
2841.16	44.2353
2843.8	51.4153
2846.44	60.4735
2849.08	69.5139
2851.73	79.4324
2854.36	90.1617
2857	100.716
2859.64	111.084
2862.28	119.764
2864.91	128.578
2867.55	135.512
2870.18	144.037
2872.81	149.922
2875.44	155.568
2878.07	161.744
2880.7	167.724
2883.33	174.358
2885.96	179.172
2888.59	184.114
2891.21	190.836
2893.84	196.934
2896.46	202.444
2899.09	208.294
2901.71	215.784
2904.33	226.215
2906.95	237.641
2909.57	251.184
2912.19	265.51
2914.81	279.135
2917.43	292.726
2920.04	304.113
2922.66	313.404
2925.27	320.706
2927.88	325.575
2930.5	328.309
2933.11	328.717
2935.72	327.567
2938.33	323.491
2940.94	318.249
2943.54	311.555
2946.15	302.702
2948.76	292.065
2951.36	280.106
2953.97	269.065
2956.57	257.401
2959.17	244.505
2961.77	232.391
2964.37	220.496
2966.97	210.522
2969.57	200.066
2972.17	191.538
2974.77	182.343
2977.36	173.043
2979.96	162.888
2982.55	153.123
2985.15	142.213
2987.74	132.334
2990.33	121.828
2992.92	111.087
2995.51	101.338
2998.1	92.2951
3000.69	83.8755
3003.27	76.0489
3005.86	69.5023
3008.44	62.3576
3011.03	57.654
3013.61	53.4396
3016.19	48.7017
3018.78	44.9694
3021.36	42.2875
3023.94	39.8116
3026.51	37.3603
3029.09	36.212
3031.67	34.9799
3034.24	34.7011
3036.82	34.3561
3039.39	33.5903
3041.97	33.437
3044.54	34.2669
3047.11	35.1935
3049.68	35.5735
3052.25	36.261
3054.82	36.1934
3057.39	35.1821
3059.96	34.9806
3062.52	34.0358
3065.09	33.1182
3067.65	32.1803
3070.22	30.3433
3072.78	29.5472
3075.34	27.8384
3077.9	25.5195
3080.46	23.6148
3083.02	21.3569
3085.58	18.6478
3088.14	15.671
3090.69	13.3377
3093.25	11.4036
3095.8	10.0462
3098.36	8.11841
3100.91	6.60923
3103.46	5.55016
3106.01	5.42149
3108.56	4.5522
3111.11	3.17278
3113.66	2.79234
3116.21	2.21228
3118.76	1.07523
3121.3	0.622189
3123.85	0.539619
3126.39	0.0194496
3128.93	0.392657
3131.48	0.287153
3134.02	0.289015
3136.56	0.669778
3139.1	0.796464
3141.64	0.604609
3144.17	0.393091
3146.71	1.5825
3149.25	4.0228