File: data/Raman/poly_smoothed/Thy_30_10_33_1x_45s_532 nm_x100_100%_600 gr_mm_01.txt
#Acq. time (s)=	45
#Accumulations=	2
#Range (cm-¹)=	200...3150
#Windows=	2
#Auto scanning=	Off
#Autofocus=	Off
#Macrospot=	Off
#AutoExposure=	Off
#Spike filter=	Multiple accum.
#Delay time (s)=	0
#Binning=	1
#Readout mode=	Signal
#DeNoise=	Off
#ICS correction=	On
#Dark correction=	Off
#Inst. Process=	Off
#Detector Gain=	Best Dynamic Range
#Detector ADC=	20 kHz
#Detector temperature (°C)=	-69.85
#Instrument=	LabRAM HR Evol
#Detector=	Synapse
#Objective=	x100
#Grating=	600 gr/mm
#ND Filter=	100%
#Laser (nm)=	532
#Hole=	100.021
#Range=	Auto
#Laser Pol.=	No
#Raman. Pol.=	No
#Laser Pol. (°)=	-0.0007625
#Raman Pol. (°)=	89.9995
#Collection=	Microscope
#StageXY=	Marzhauser
#StageZ=	Marzhauser
#X (µm)=	4752.7
#Y (µm)=	-7707.7
#Z (µm)=	584.85
#Full time(mm:ss)=	3:18
#Project=
#Sample=
#Site=
#Title=	Thy_30_10_33_2x_45s_532 nm_x100_100%_600 gr_mm
#Remark=
#Date=	30.06.2022 13:49
#Acquired=	30.06.2022 13:49:53
#Base:Fit=	10.08.2022 09:58:11
#Base:Sub=	10.08.2022 09:58:44
#Filter:Polynom=	16.08.2022 10:22:53
#AxisType[0]=Intens
#AxisUnit[0]=Cnt
#AxisType[1]=Spectr
#AxisUnit[1]=1/cm
200.533	10.4543
204.162	10.5245
207.792	8.62494
211.418	7.37122
215.044	6.40491
218.667	5.8646
222.289	6.94034
225.912	8.77131
229.531	10.0796
233.148	9.80977
236.766	11.1883
240.381	10.9144
243.994	9.74731
247.606	9.62888
251.217	9.27838
254.828	9.29612
258.436	8.42298
262.042	8.28372
265.647	7.57286
269.25	7.50536
272.852	8.10194
276.453	8.37635
280.052	9.11566
283.65	7.62971
287.247	6.63756
290.842	5.55273
294.436	5.26345
298.028	5.73899
301.617	8.41419
305.206	8.71838
308.794	11.5924
312.381	12.9833
315.964	13.6375
319.548	13.3687
323.131	13.2654
326.71	13.7429
330.29	11.8254
333.868	12.4664
337.443	11.9915
341.018	11.4208
344.591	10.9171
348.163	12.1768
351.733	11.5624
355.303	10.2969
358.869	11.1048
362.435	10.308
366.001	10.5065
369.563	9.3078
373.124	7.89418
376.686	7.66838
380.244	7.02599
383.801	6.8662
387.357	7.24564
390.911	7.98267
394.466	7.36224
398.018	6.86257
401.568	5.62933
405.117	5.59531
408.664	6.53832
412.21	6.88488
415.755	7.97921
419.298	7.54962
422.84	7.66896
426.38	9.54519
429.919	10.9335
433.455	11.4419
436.992	11.9661
440.527	11.6166
444.06	11.7078
447.593	12.6056
451.122	13.449
454.651	14.2979
458.18	15.4002
461.705	16.406
465.23	16.6034
468.752	16.4338
472.275	17.0127
475.797	17.608
479.315	17.7551
482.834	17.7977
486.349	18.0479
489.863	19.6975
493.378	21.4234
496.889	22.908
500.401	23.9521
503.91	24.2346
507.417	24.1882
510.923	26.1782
514.43	25.667
517.933	24.4249
521.435	24.1824
524.936	24.3231
528.435	24.2816
531.933	23.0314
535.43	23.0524
538.927	21.2479
542.421	19.6484
545.913	17.7434
549.403	15.6601
552.893	13.3617
556.381	12.1341
559.868	9.59167
563.354	9.04912
566.839	7.06417
570.322	4.89896
573.802	4.78131
577.283	3.63393
580.762	3.36999
584.24	2.70357
587.714	1.47179
591.19	2.39997
594.663	3.0335
598.134	3.26818
601.605	3.535
605.073	4.58378
608.542	5.74771
612.007	7.77872
615.473	9.27401
618.936	10.6855
622.397	11.3699
625.859	11.2122
629.318	12.6519
632.775	14.7165
636.233	16.3073
639.688	18.5809
643.142	20.122
646.594	22.5011
650.045	22.2083
653.496	23.4555
656.944	25.0666
660.391	26.4202
663.837	25.4617
667.281	24.721
670.724	23.4834
674.166	23.883
677.606	25.4212
681.045	24.5839
684.483	27.1077
687.917	29.8323
691.352	28.4424
694.786	29.4282
698.219	31.0264
701.65	33.8947
705.078	34.8312
708.506	36.6187
711.934	38.7885
715.358	41.4935
718.782	41.5568
722.204	43.123
725.626	43.7563
729.045	45.1401
732.464	47.7415
735.881	48.617
739.297	49.994
742.711	51.5597
746.125	52.4534
749.537	53.0152
752.946	55.0174
756.357	57.8867
759.764	60.5729
763.17	63.281
766.575	64.1735
769.978	65.5841
773.382	65.8362
776.783	66.9874
780.182	69.778
783.581	71.7958
786.978	73.1345
790.373	73.8392
793.768	75.6642
797.161	76.9309
800.552	78.3477
803.941	78.027
807.33	78.2919
810.718	78.4389
814.105	78.1609
817.49	79.6346
820.873	81.2124
824.256	82.7988
827.637	84.0154
831.016	83.4765
834.395	83.7529
837.772	83.1661
841.147	82.3317
844.522	80.1865
847.894	77.181
851.267	74.5827
854.637	71.9252
858.007	69.4499
861.374	66.3925
864.739	63.7406
868.106	61.8117
871.469	60.857
874.831	59.9578
878.193	58.7675
881.553	56.5658
884.911	55.9852
888.268	55.0648
891.623	54.4066
894.978	54.8734
898.331	55.2598
901.683	56.5804
905.033	56.0833
908.383	55.8098
911.731	55.9126
915.078	55.1419
918.423	54.8805
921.768	51.8029
925.111	51.347
928.452	49.9633
931.791	48.3052
935.13	47.033
938.468	45.1493
941.803	44.0481
945.139	42.2102
948.473	41.5214
951.804	41.7623
955.136	40.1748
958.465	39.0256
961.794	37.1835
965.12	39.2377
968.447	42.2586
971.771	43.1127
975.095	44.631
978.417	45.8037
981.737	46.7611
985.057	48.2234
988.375	49.736
991.691	50.7718
995.006	51.9407
998.32	50.0763
1001.63	50.8727
1004.95	50.914
1008.26	50.1645
1011.56	48.8881
1014.87	46.9873
1018.18	45.7455
1021.48	43.8487
1024.79	41.9398
1028.09	41.6923
1031.39	40.552
1034.69	37.5415
1037.99	34.665
1041.29	32.2153
1044.58	31.6781
1047.88	31.7753
1051.17	29.8926
1054.46	28.8327
1057.75	29.4364
1061.04	28.2133
1064.33	28.5122
1067.62	29.071
1070.9	28.0438
1074.19	26.9595
1077.47	25.6976
1080.76	25.3294
1084.04	25.3333
1087.32	24.5124
1090.59	23.9927
1093.87	24.1664
1097.15	23.4844
1100.42	24.4605
1103.69	24.7824
1106.97	25.4243
1110.24	25.5991
1113.51	24.8051
1116.77	24.7067
1120.04	23.3587
1123.31	21.8021
1126.57	20.0317
1129.83	19.7157
1133.1	18.1154
1136.36	17.6888
1139.62	15.5878
1142.87	14.5238
1146.13	12.8471
1149.38	10.9638
1152.64	9.36583
1155.89	7.07772
1159.14	6.30182
1162.39	4.72695
1165.64	4.97104
1168.89	4.69843
1172.14	4.11458
1175.38	5.14846
1178.63	6.67892
1181.87	8.48394
1185.11	10.2353
1188.35	11.4072
1191.59	13.291
1194.83	14.2074
1198.07	16.0901
1201.3	18.2433
1204.53	21.4487
1207.77	24.4892
1211	28.0664
1214.23	32.5978
1217.46	35.5915
1220.69	39.0055
1223.91	43.0828
1227.14	45.2483
1230.36	49.5909
1233.59	53.5654
1236.81	56.7579
1240.03	60.9419
1243.25	62.6072
1246.46	65.8116
1249.68	67.8529
1252.9	71.0296
1256.11	73.3143
1259.32	73.8526
1262.54	74.8817
1265.75	75.9509
1268.96	76.9871
1272.16	78.2593
1275.37	79.8409
1278.57	80.176
1281.78	81.7557
1284.98	84.1924
1288.18	84.834
1291.38	86.5535
1294.58	85.0342
1297.78	84.8945
1300.98	86.9994
1304.17	86.9114
1307.37	87.898
1310.56	89.3659
1313.76	89.0268
1316.95	90.344
1320.14	88.4263
1323.32	88.0045
1326.51	86.5423
1329.7	84.8397
1332.88	83.1729
1336.07	80.0076
1339.25	78.0134
1342.43	76.023
1345.61	73.0751
1348.79	68.9793
1351.96	66.1046
1355.14	64.2261
1358.31	60.6358
1361.49	59.3261
1364.66	56.5657
1367.83	52.3185
1371	50.3287
1374.17	46.2765
1377.34	44.4542
1380.5	43.1681
1383.67	42.4397
1386.83	42.0549
1390	40.6149
1393.16	41.2058
1396.32	39.6879
1399.48	38.2096
1402.64	36.5002
1405.79	34.6218
1408.95	35.7408
1412.1	37.5073
1415.26	38.6504
1418.41	40.6473
1421.56	44.5089
1424.71	47.9186
1427.86	55.0617
1431	61.0578
1434.15	65.9787
1437.29	69.8975
1440.44	73.8394
1443.58	75.5696
1446.72	76.5915
1449.86	77.0798
1453	76.4508
1456.14	75.2582
1459.27	73.7279
1462.41	70.0619
1465.54	66.1928
1468.67	61.4289
1471.81	54.913
1474.94	48.4801
1478.07	41.6296
1481.19	34.7533
1484.32	29.8696
1487.45	25.4165
1490.57	21.7508
1493.69	18.2165
1496.82	16.8723
1499.94	16.3283
1503.06	16.3132
1506.17	16.2753
1509.29	15.2619
1512.41	15.9253
1515.52	15.7743
1518.64	16.9477
1521.75	17.9717
1524.86	19.9167
1527.97	20.55
1531.08	22.6451
1534.19	25.2493
1537.29	28.799
1540.4	31.4976
1543.5	34.0835
1546.61	37.1497
1549.71	39.5234
1552.81	42.3573
1555.91	43.2539
1559.01	45.3835
1562.11	48.8076
1565.2	52.6008
1568.29	54.1974
1571.39	57.2869
1574.48	60.093
1577.57	62.2185
1580.66	63.7297
1583.75	66.4612
1586.84	68.3509
1589.93	70.0359
1593.01	71.5273
1596.1	72.1815
1599.18	72.7577
1602.26	71.0362
1605.34	70.5499
1608.42	69.3852
1611.5	69.6324
1614.58	69.0754
1617.65	69.387
1620.73	69.8982
1623.8	70.6697
1626.87	72.5625
1629.95	74.5212
1633.02	77.8249
1636.09	81.3112
1639.15	84.529
1642.22	89.8951
1645.29	93.7388
1648.35	97.0932
1651.42	98.8046
1654.48	101.56
1657.54	103.328
1660.6	104.53
1663.66	103.71
1666.72	100.399
1669.77	96.6594
1672.83	91.484
1675.88	85.3582
1678.93	78.3381
1681.99	71.0341
1685.04	64.4046
1688.09	57.6954
1691.13	50.9893
1694.18	45.8335
1697.23	38.8175
1700.27	31.8307
1703.32	27.2127
1706.36	23.2109
1709.4	18.2763
1712.44	15.0106
1715.48	12.4882
1718.52	11.0387
1721.56	8.61088
1724.59	7.33008
1727.63	6.74788
1730.66	6.34938
1733.69	5.78345
1736.72	4.61896
1739.75	2.7586
1742.78	2.419
1745.81	1.85726
1748.84	1.85502
1751.86	2.24961
1754.89	1.96869
1757.91	1.89195
1760.93	1.00243
1763.95	0.624537
1766.97	0.290539
1769.99	-1.13452
1773.01	-1.94544
1776.03	-1.35039
1779.04	-0.838612
1782.06	-0.407436
1785.07	-0.0184017
1788.08	0.8301
1791.09	0.46031
1794.1	1.38592
1797.11	1.42315
1800.12	1.78216
1803.12	2.16357
1806.13	2.98304
1809.13	3.13576
1812.14	3.697
1815.14	3.72129
1818.14	4.95067
1821.14	5.05409
1824.14	5.77644
1827.13	5.08662
1830.13	5.07226
1833.12	5.97808
1836.12	6.65321
1839.11	7.06614
1842.1	7.40471
1845.09	7.47505
1848.08	8.2085
1851.07	8.71162
1854.06	9.89089
1857.04	10.0824
1860.03	10.1968
1863.01	10.5143
1866	11.0612
1868.98	11.948
1871.96	10.8435
1874.94	10.8487
1877.92	11.8469
1880.89	11.3714
1882.48	11.9173
1885.47	11.4317
1888.46	11.7172
1891.44	11.9145
1894.43	11.9348
1897.41	12.1427
1900.4	12.0393
1903.38	13.417
1906.36	13.9296
1909.34	13.3999
1912.32	14.0883
1915.29	14.7829
1918.27	14.553
1921.25	16.0018
1924.22	15.4549
1927.2	15.5771
1930.17	15.9704
1933.14	16.5854
1936.11	16.5378
1939.08	16.2222
1942.05	15.7612
1945.01	14.4953
1947.98	14.4263
1950.94	14.5577
1953.91	13.2887
1956.87	13.5031
1959.83	12.7603
1962.79	12.2072
1965.75	12.2233
1968.71	12.3088
1971.67	13.1206
1974.62	12.3287
1977.58	13.2935
1980.53	13.6197
1983.48	14.4677
1986.43	14.973
1989.38	15.6578
1992.33	15.5552
1995.28	16.699
1998.23	17.0179
2001.18	18.1176
2004.12	17.1099
2007.06	17.4149
2010.01	17.9057
2012.95	18.6256
2015.89	19.1016
2018.83	18.9771
2021.77	19.2508
2024.71	19.0346
2027.64	19.5291
2030.58	19.6683
2033.51	19.2541
2036.45	20.6031
2039.38	21.678
2042.31	22.5781
2045.24	23.4072
2048.17	23.5924
2051.1	24.2048
2054.02	25.0525
2056.95	24.576
2059.87	25.6296
2062.8	25.7057
2065.72	26.6417
2068.64	27.8566
2071.56	29.2661
2074.48	29.6922
2077.4	31.053
2080.31	33.0702
2083.23	34.67
2086.14	35.235
2089.06	36.8246
2091.97	37.87
2094.88	38.8255
2097.79	39.9442
2100.7	41.6201
2103.61	44.0044
2106.52	46.5724
2109.43	48.6556
2112.33	50.9613
2115.24	53.9998
2118.14	56.4758
2121.04	58.5214
2123.94	60.7014
2126.84	63.8176
2129.74	66.9575
2132.64	70.7673
2135.54	74.6429
2138.43	79.1589
2141.33	82.3345
2144.22	85.9345
2147.11	89.2387
2150.01	92.6479
2152.9	96.5717
2155.79	99.6302
2158.67	102.825
2161.56	104.728
2164.45	105.423
2167.33	106.199
2170.22	107.067
2173.1	107.71
2175.98	107.336
2178.86	106.013
2181.74	105.453
2184.62	104.216
2187.5	102.263
2190.38	98.6106
2193.25	94.6466
2196.13	91.1005
2199	87.8277
2201.88	84.2089
2204.75	80.4932
2207.62	76.7714
2210.49	73.5744
2213.36	69.2983
2216.22	66.1764
2219.09	63.1278
2221.96	61.3452
2224.82	58.263
2227.68	55.169
2230.55	52.0592
2233.41	50.1049
2236.27	47.2602
2239.12	45.4213
2241.98	43.6933
2244.84	41.9685
2247.7	40.2114
2250.55	39.6558
2253.41	38.5751
2256.26	37.6215
2259.11	36.2696
2261.96	35.5003
2264.81	34.972
2267.66	33.8786
2270.51	33.4167
2273.35	32.6629
2276.2	31.8178
2279.04	31.1636
2281.89	30.6987
2284.73	30.1669
2287.57	29.9109
2290.41	28.7145
2293.25	27.5767
2296.09	27.0046
2298.93	26.2667
2301.76	25.946
2304.6	25.8846
2307.44	25.2391
2310.27	25.2149
2313.1	25.6237
2315.93	25.1859
2318.76	23.7806
2321.59	24.3728
2324.42	23.8172
2327.25	23.2581
2330.07	21.9359
2332.9	20.7888
2335.72	19.6079
2338.55	17.8837
2341.37	17.2731
2344.19	15.9025
2347.01	15.1561
2349.83	13.5769
2352.65	12.614
2355.46	11.159
2358.28	10.3563
2361.09	9.37876
2363.91	8.15232
2366.72	8.41043
2369.53	8.44794
2372.34	8.54363
2375.15	9.41557
2377.96	9.05641
2380.77	8.76093
2383.58	8.87691
2386.38	8.58534
2389.19	9.24092
2391.99	8.56375
2394.8	7.05075
2397.6	7.0383
2400.4	6.72646
2403.2	6.78232
2406	6.26506
2408.79	5.95958
2411.59	5.83517
2414.39	5.68426
2417.18	5.30112
2419.98	5.61561
2422.77	6.75296
2425.56	6.98488
2428.35	7.01286
2431.14	7.26482
2433.93	8.14472
2436.72	8.05411
2439.5	8.26432
2442.29	8.21439
2445.07	8.93563
2447.86	8.63086
2450.64	9.7383
2453.42	9.89696
2456.2	10.1035
2458.98	9.39675
2461.76	8.95058
2464.54	8.31589
2467.32	7.24872
2470.09	7.09043
2472.87	6.04244
2475.64	4.91891
2478.41	4.11499
2481.18	3.4445
2483.95	3.63915
2486.72	3.31568
2489.49	3.75271
2492.26	3.07918
2495.03	3.63045
2497.79	4.07612
2500.56	4.41958
2503.32	4.81699
2506.09	4.15468
2508.85	5.17682
2511.61	5.40662
2514.37	5.45153
2517.13	6.268
2519.89	5.87626
2522.64	5.56948
2525.4	5.49957
2528.15	4.54937
2530.91	4.34165
2533.66	3.654
2536.41	3.6596
2539.16	4.22561
2541.91	2.61877
2544.66	2.1648
2547.41	1.69883
2550.16	1.66522
2552.9	1.47613
2555.65	2.24593
2558.39	2.43432
2561.13	2.98513
2563.88	3.50705
2566.62	2.97753
2569.36	3.43577
2572.1	3.19921
2574.84	2.38502
2577.57	1.43023
2580.31	0.934003
2583.05	1.46465
2585.78	1.71853
2588.51	-0.0133813
2591.24	-0.219581
2593.98	-0.878701
2596.71	-1.27678
2599.44	-0.941302
2602.16	0.100873
2604.89	-0.312815
2607.62	-0.470692
2610.34	-0.72179
2613.07	-0.0677461
2615.79	-0.707889
2618.52	-0.198837
2621.24	-0.00408358
2623.96	-0.703741
2626.68	-0.724116
2629.4	0.403936
2632.11	0.686823
2634.83	0.36834
2637.55	0.841196
2640.26	0.410752
2642.98	0.0297573
2645.69	-0.322205
2648.4	0.290353
2651.11	0.31567
2653.82	0.409697
2656.53	0.0217659
2659.24	0.055245
2661.95	0.305079
2664.65	0.333231
2667.36	1.33849
2670.06	1.75149
2672.76	2.07479
2675.47	1.99647
2678.17	1.50044
2680.87	1.59592
2683.57	2.11339
2686.27	2.46745
2688.97	2.56712
2691.66	2.74452
2694.36	4.1093
2697.05	4.51455
2699.75	4.72111
2702.44	5.1925
2705.13	6.31156
2707.82	6.515
2710.51	6.92183
2713.2	7.70894
2715.89	7.89987
2718.57	8.34245
2721.26	7.62065
2723.95	7.73998
2726.63	7.63603
2729.31	7.89797
2732	7.2809
2734.68	7.41486
2737.36	6.89949
2740.04	6.36932
2742.72	5.93206
2745.39	5.63881
2748.07	5.93506
2750.75	5.55002
2753.42	5.07635
2756.09	4.48604
2758.77	4.1945
2761.44	4.18278
2764.11	4.19012
2766.78	3.80324
2769.45	3.97056
2772.12	4.60986
2774.78	4.05123
2777.45	4.64232
2780.12	4.20391
2782.78	4.34036
2785.44	4.17862
2788.11	3.90402
2790.77	3.44172
2793.43	3.27446
2796.09	2.91
2798.75	2.61413
2801.4	3.08276
2804.06	3.04205
2806.72	3.0677
2809.37	2.90695
2812.03	2.54563
2814.68	2.05992
2817.33	2.54559
2819.98	3.44396
2822.63	5.56049
2825.28	8.94735
2827.93	13.0085
2830.58	17.9874
2833.23	22.9069
2835.87	29.1825
2838.52	35.5237
2841.16	42.6923
2843.8	50.4455
2846.44	57.8594
2849.08	67.922
2851.73	78.1633
2854.36	88.8122
2857	99.0755
2859.64	109.666
2862.28	119.93
2864.91	129.666
2867.55	138.427
2870.18	146.316
2872.81	152.752
2875.44	159.016
2878.07	164.686
2880.7	170.207
2883.33	175.177
2885.96	181.039
2888.59	187.496
2891.21	193.438
2893.84	199.165
2896.46	205.902
2899.09	213.161
2901.71	222.402
2904.33	231.694
2906.95	243.207
2909.57	256.774
2912.19	271.11
2914.81	285.615
2917.43	299.086
2920.04	311.09
2922.66	322.069
2925.27	329.98
2927.88	335.837
2930.5	338.323
2933.11	340.377
2935.72	339.148
2938.33	334.866
2940.94	328.573
2943.54	321.19
2946.15	311.173
2948.76	300.263
2951.36	287.887
2953.97	275.268
2956.57	262.737
2959.17	250.007
2961.77	237.628
2964.37	225.95
2966.97	215.387
2969.57	204.545
2972.17	195.164
2974.77	185.372
2977.36	176.32
2979.96	166.271
2982.55	155.586
2985.15	144.723
2987.74	133.796
2990.33	122.956
2992.92	113.03
2995.51	102.997
2998.1	93.9545
3000.69	83.5472
3003.27	74.5686
3005.86	66.9681
3008.44	59.9819
3011.03	53.1855
3013.61	47.6788
3016.19	43.5904
3018.78	39.0886
3021.36	35.9736
3023.94	32.7491
3026.51	31.1039
3029.09	29.7577
3031.67	29.4797
3034.24	29.8845
3036.82	31.0478
3039.39	32.1361
3041.97	32.697
3044.54	32.8232
3047.11	33.5406
3049.68	35.1363
3052.25	35.4217
3054.82	35.9673
3057.39	35.7371
3059.96	34.601
3062.52	32.9601
3065.09	30.7781
3067.65	29.9635
3070.22	28.2158
3072.78	26.0562
3075.34	23.0721
3077.9	21.179
3080.46	17.6253
3083.02	14.5224
3085.58	12.0651
3088.14	10.9785
3090.69	9.17957
3093.25	7.7318
3095.8	6.79562
3098.36	6.11372
3100.91	4.38568
3103.46	3.06668
3106.01	3.01984
3108.56	1.81453
3111.11	1.70927
3113.66	1.4013
3116.21	1.33648
3118.76	0.641174
3121.3	-0.0728662
3123.85	-0.584972
3126.39	-1.28958
3128.93	-0.998056
3131.48	-0.130682
3134.02	-0.715911
3136.56	-0.659471
3139.1	-0.0359919
3141.64	0.894667
3144.17	1.89998
3146.71	3.14579
3149.25	3.91505