File: data/Raman/poly_smoothed/Thy_20_09_02_1x_45s_532 nm_x100_100%_600 gr_mm_01.txt
#Acq. time (s)=	45
#Accumulations=	2
#Range (cm-¹)=	200...3150
#Windows=	2
#Auto scanning=	Off
#Autofocus=	Off
#Macrospot=	Off
#AutoExposure=	Off
#Spike filter=	Multiple accum.
#Delay time (s)=	0
#Binning=	1
#Readout mode=	Signal
#DeNoise=	Off
#ICS correction=	On
#Dark correction=	Off
#Inst. Process=	Off
#Detector Gain=	Best Dynamic Range
#Detector ADC=	20 kHz
#Detector temperature (°C)=	-69.85
#Instrument=	LabRAM HR Evol
#Detector=	Synapse
#Objective=	x100
#Grating=	600 gr/mm
#ND Filter=	100%
#Laser (nm)=	532
#Hole=	100.021
#Range=	Auto
#Laser Pol.=	No
#Raman. Pol.=	No
#Laser Pol. (°)=	-0.0007625
#Raman Pol. (°)=	89.9995
#Collection=	Microscope
#StageXY=	Marzhauser
#StageZ=	Marzhauser
#X (µm)=	-5927.4
#Y (µm)=	2836.4
#Z (µm)=	-223.85
#Full time(mm:ss)=	3:18
#Project=
#Sample=
#Site=
#Title=	Thy_20_09_02_2x_45s_532 nm_x100_100%_600 gr_mm
#Remark=
#Date=	29.06.2022 10:42
#Acquired=	29.06.2022 10:42:41
#Base:Fit=	10.08.2022 09:49:32
#Base:Fit=	10.08.2022 09:49:42
#Base:Fit=	10.08.2022 09:49:53
#Base:Fit=	10.08.2022 09:50:12
#Base:Fit=	10.08.2022 09:50:26
#Base:Fit=	10.08.2022 09:50:30
#Base:Fit=	10.08.2022 09:50:43
#Base:Fit=	10.08.2022 09:52:02
#Base:Fit=	10.08.2022 09:52:12
#Base:Sub=	10.08.2022 09:54:21
#Filter:Polynom=	16.08.2022 10:24:04
#AxisType[0]=Intens
#AxisUnit[0]=Cnt
#AxisType[1]=Spectr
#AxisUnit[1]=1/cm
200.523	9.37964
204.154	8.27156
207.781	6.71482
211.409	5.40006
215.034	3.44114
218.659	2.90831
222.281	4.06654
225.903	4.71826
229.522	4.54531
233.14	5.16477
236.756	5.87573
240.373	7.16861
243.986	8.30093
247.598	8.88163
251.208	10.4432
254.818	10.4085
258.427	12.2165
262.034	13.6233
265.638	14.974
269.242	15.9285
272.844	15.8425
276.445	15.4671
280.044	15.7594
283.642	14.9934
287.238	15.0655
290.833	15.0812
294.425	14.6387
298.017	14.651
301.608	15.0362
305.198	15.413
308.786	18.6099
312.371	18.6432
315.956	18.7478
319.54	18.1952
323.122	19.6984
326.701	20.2222
330.281	20.7528
333.857	21.4785
337.434	21.5154
341.008	21.4536
344.582	20.7048
348.153	19.1116
351.724	18.655
355.292	15.7214
358.861	13.5536
362.426	13.3733
365.99	12.4071
369.555	10.554
373.116	10.0231
376.676	9.15042
380.236	8.24536
383.793	7.87771
387.349	7.26202
390.903	8.04098
394.456	6.81275
398.007	6.96601
401.56	5.71403
405.108	7.3743
408.656	8.1296
412.202	8.37493
415.746	8.63403
419.29	9.02319
422.831	8.31401
426.37	8.28372
429.909	7.79966
433.447	5.95845
436.983	5.82022
440.519	7.31632
444.052	7.61385
447.583	9.3558
451.114	11.7868
454.643	13.1337
458.169	13.3311
461.696	12.8202
465.222	12.7852
468.744	12.3205
472.267	11.8229
475.787	11.8651
479.307	11.4526
482.823	11.5847
486.341	12.1403
489.855	13.8421
493.37	14.6028
496.881	14.0226
500.391	14.464
503.902	14.4157
507.409	12.9429
510.915	12.3795
514.42	11.723
517.925	11.0907
521.427	11.7004
524.928	10.6901
528.427	9.5511
531.925	9.63346
535.422	9.17904
538.917	8.29599
542.411	6.73565
545.903	4.63377
549.395	3.5275
552.884	3.50106
556.373	2.93655
559.86	1.9739
563.346	2.3527
566.831	3.22086
570.314	4.87521
573.794	5.02932
577.274	6.23707
580.754	6.58983
584.23	6.57755
587.706	5.70682
591.181	4.53358
594.653	4.07483
598.126	4.63977
601.595	5.73595
605.065	5.56912
608.532	5.06838
611.999	5.15041
615.463	6.16854
618.928	7.7511
622.389	7.65276
625.851	8.90403
629.31	9.29887
632.767	10.3684
636.223	12.4299
639.68	13.3902
643.134	15.1559
646.586	15.0525
650.037	17.128
653.486	17.2862
656.936	18.168
660.383	19.1859
663.829	19.3028
667.273	18.8417
670.716	18.2117
674.158	17.6395
677.598	18.3428
681.035	18.0402
684.473	19.3352
687.909	19.9909
691.344	20.0909
694.778	21.4673
698.211	23.4664
701.64	25.0843
705.07	25.2252
708.498	25.8079
711.924	27.0153
715.35	28.8254
718.774	31.0382
722.196	33.0522
725.618	35.2418
729.037	35.8551
732.456	38.2401
735.873	41.3584
739.289	42.7844
742.703	45.3741
746.116	46.6586
749.529	47.576
752.938	48.1808
756.347	48.8529
759.756	51.1758
763.162	52.7046
766.567	52.5049
769.97	54.6301
773.372	55.5797
776.773	57.8969
780.174	59.4885
783.573	60.9303
786.97	62.4806
790.365	65.221
793.76	67.4682
797.153	69.1462
800.543	70.1139
803.933	69.6013
807.322	70.7693
810.71	71.036
814.097	71.1179
817.483	71.5905
820.865	72.1888
824.248	70.7343
827.629	70.6153
831.008	69.6999
834.387	67.8651
837.765	65.4799
841.139	65.2413
844.514	64.312
847.886	61.528
851.259	59.9584
854.629	58.9094
857.997	58.1823
861.366	55.5266
864.732	54.3378
868.098	53.6202
871.461	52.4337
874.823	50.8224
878.184	49.6362
881.545	47.7385
884.903	46.1714
888.26	45.7185
891.616	44.1999
894.97	43.0404
898.323	44.0988
901.675	41.9829
905.026	42.8722
908.375	40.4927
911.723	40.0063
915.07	39.9996
918.415	39.847
921.76	39.7365
925.103	39.7247
928.443	38.4027
931.783	36.8643
935.123	36.3403
938.461	35.8778
941.796	33.6887
945.131	31.2456
948.465	30.4317
951.797	29.5202
955.128	29.2084
958.457	28.2017
961.786	26.1571
965.113	23.8487
968.44	23.9741
971.763	23.9115
975.086	23.072
978.409	22.9177
981.729	23.5599
985.048	23.2122
988.367	23.2945
991.683	23.9556
994.998	24.2152
998.312	25.4076
1001.62	26.0023
1004.94	24.3553
1008.25	23.4343
1011.56	20.48
1014.86	20.7896
1018.17	18.3276
1021.48	16.6429
1024.78	14.2384
1028.08	13.6649
1031.38	12.8328
1034.68	11.2492
1037.98	8.68383
1041.28	7.35521
1044.57	8.58914
1047.87	9.93687
1051.16	10.4661
1054.45	10.6935
1057.75	10.6883
1061.04	11.2715
1064.32	11.5966
1067.61	11.307
1070.9	12.8389
1074.18	14.0853
1077.47	15.5413
1080.75	17.2551
1084.03	16.6219
1087.31	16.8976
1090.59	16.4929
1093.86	18.2979
1097.14	18.2323
1100.41	17.6941
1103.69	16.9576
1106.96	15.6338
1110.23	15.8323
1113.5	13.7261
1116.77	14.4126
1120.03	15.4235
1123.3	15.9264
1126.56	15.6776
1129.83	14.9842
1133.09	14.8107
1136.35	14.5197
1139.61	13.4387
1142.86	12.8712
1146.12	13.191
1149.38	15.1381
1152.63	14.9052
1155.88	17.0685
1159.14	18.5006
1162.39	19.2588
1165.63	20.1521
1168.88	21.7688
1172.13	22.6936
1175.38	23.5101
1178.62	21.8344
1181.86	20.4351
1185.1	18.7387
1188.34	18.5659
1191.58	18.2732
1194.82	19.6691
1198.06	21.676
1201.29	22.9485
1204.53	22.4432
1207.76	23.3911
1210.99	25.6452
1214.22	26.8074
1217.45	26.6525
1220.68	27.774
1223.91	28.8838
1227.13	30.7913
1230.36	34.1105
1233.58	35.4046
1236.8	37.5438
1240.02	38.6011
1243.24	39.9809
1246.46	39.2405
1249.67	39.1531
1252.89	38.5603
1256.1	37.3676
1259.32	35.7679
1262.53	35.839
1265.74	35.6218
1268.95	37.4291
1272.15	37.8134
1275.36	39.4917
1278.57	41.8494
1281.77	43.6553
1284.97	45.4767
1288.18	47.4921
1291.38	47.7786
1294.58	47.5445
1297.78	48.8263
1300.97	50.6425
1304.17	51.854
1307.36	55.2903
1310.55	57.3187
1313.75	58.262
1316.94	59.2268
1320.13	60.8467
1323.32	60.7696
1326.5	61.6298
1329.69	62.6962
1332.87	62.8813
1336.06	63.846
1339.24	64.1159
1342.42	64.11
1345.6	64.0985
1348.78	63.857
1351.96	65.6396
1355.13	66.4495
1358.31	64.7306
1361.48	63.757
1364.65	61.8335
1367.82	61.0693
1370.99	60.0425
1374.16	59.174
1377.33	56.8746
1380.5	54.7107
1383.66	53.5855
1386.83	52.2803
1389.99	50.72
1393.15	49.335
1396.31	48.0732
1399.47	46.3121
1402.63	44.5448
1405.78	44.7297
1408.94	42.5615
1412.1	43.4601
1415.25	42.2178
1418.4	41.6046
1421.55	42.0547
1424.7	43.6876
1427.85	45.7184
1431	47.8133
1434.14	49.4589
1437.29	50.7107
1440.43	53.1795
1443.57	55.9784
1446.71	56.7338
1449.85	57.0874
1452.99	57.2573
1456.13	55.2873
1459.26	54.2568
1462.4	53.2732
1465.54	51.3017
1468.67	49.4569
1471.8	46.4589
1474.93	43.275
1478.06	40.6293
1481.19	38.3856
1484.31	36.6342
1487.44	33.3923
1490.56	31.7634
1493.69	30.9374
1496.81	29.98
1499.93	30.4491
1503.05	30.6087
1506.17	30.6646
1509.28	30.8823
1512.4	29.4926
1515.52	29.9922
1518.63	30.4446
1521.74	30.7852
1524.85	31.9439
1527.96	32.854
1531.07	33.2938
1534.18	34.0638
1537.29	35.0729
1540.39	37.8534
1543.5	40.5332
1546.6	44.0899
1549.7	46.4535
1552.8	51.3121
1555.9	55.7564
1559	58.7433
1562.1	61.805
1565.19	64.6489
1568.29	67.8322
1571.38	70.6095
1574.47	72.1654
1577.56	73.4489
1580.66	73.5948
1583.74	74.1649
1586.83	73.5647
1589.92	72.412
1593.01	70.4473
1596.09	67.6228
1599.17	65.4698
1602.25	62.8956
1605.34	60.9076
1608.41	57.9841
1611.49	57.8369
1614.57	55.0704
1617.65	55.335
1620.72	54.1774
1623.79	53.4935
1626.87	53.0409
1629.94	53.1645
1633.01	51.9198
1636.08	51.5706
1639.15	51.7891
1642.21	51.5177
1645.28	50.7902
1648.34	50.6404
1651.41	50.1487
1654.47	48.8561
1657.53	48.7332
1660.59	46.6164
1663.65	44.9163
1666.71	41.4689
1669.76	39.2307
1672.82	35.5167
1675.87	34.5646
1678.93	33.3604
1681.98	32.4064
1685.03	30.3324
1688.08	28.0743
1691.13	26.0077
1694.17	24.7827
1697.22	22.7106
1700.27	21.5304
1703.31	19.7189
1706.35	17.6888
1709.39	15.6731
1712.43	13.7362
1715.47	11.2821
1718.51	8.90818
1721.55	7.66409
1724.58	7.77838
1727.62	6.72873
1730.65	4.94456
1733.68	4.33147
1736.72	2.78308
1739.74	1.2264
1742.77	1.19393
1745.8	0.0189138
1748.83	0.991342
1751.85	1.44121
1754.88	1.62256
1757.9	1.86601
1760.92	1.71716
1763.95	2.50041
1766.96	3.18246
1769.98	3.6636
1773	3.41772
1776.02	4.49361
1779.03	4.35698
1782.05	4.28406
1785.06	4.35132
1788.07	3.98084
1791.08	4.45722
1794.09	5.10968
1797.1	6.04398
1800.11	5.54961
1803.12	4.4121
1806.12	4.5099
1809.12	4.05955
1812.13	3.79182
1815.13	3.92673
1818.13	3.91931
1821.13	4.04972
1824.13	4.00932
1827.13	3.69863
1830.12	3.69109
1833.12	2.79247
1836.11	2.66506
1839.1	2.31698
1842.09	1.97841
1845.09	1.58958
1848.08	2.0168
1851.06	2.65481
1854.05	3.18769
1857.04	3.9263
1860.02	4.17665
1863.01	4.17001
1865.99	4.06055
1868.97	4.3891
1871.95	4.45906
1874.93	4.63645
1877.91	5.03396
1880.89	5.73337
1882.46	5.62847
1885.45	6.25469
1888.43	6.92011
1891.42	7.38554
1894.41	7.88582
1897.39	7.26873
1900.37	7.39535
1903.36	6.89522
1906.34	5.74332
1909.32	6.25213
1912.29	6.46855
1915.27	5.71287
1918.25	5.82023
1921.23	7.07681
1924.2	6.55175
1927.17	5.61124
1930.15	5.33382
1933.12	5.29985
1936.09	3.8347
1939.06	2.9173
1942.02	2.79686
1944.99	3.1589
1947.96	3.00089
1950.92	2.20883
1953.88	2.74923
1956.85	3.11715
1959.81	2.26991
1962.77	2.63485
1965.73	3.46144
1968.69	3.59359
1971.64	2.46603
1974.6	3.0764
1977.55	2.62228
1980.51	3.28815
1983.46	3.44517
1986.41	2.64347
1989.36	3.16309
1992.31	3.794
1995.26	2.80042
1998.21	2.33843
2001.15	3.53742
2004.1	3.28482
2007.04	2.73964
2009.99	2.06922
2012.93	2.38451
2015.87	2.95045
2018.81	2.48143
2021.75	1.97222
2024.68	2.25405
2027.62	2.21908
2030.56	2.3971
2033.49	3.02463
2036.42	3.54818
2039.36	4.26679
2042.29	3.39212
2045.22	3.00194
2048.14	3.75048
2051.07	4.56971
2054	6.34786
2056.93	6.8791
2059.85	7.63504
2062.77	8.2657
2065.7	8.67599
2068.62	9.20638
2071.54	10.761
2074.46	10.3771
2077.38	10.6461
2080.29	10.9489
2083.21	11.7266
2086.12	11.8333
2089.04	12.2368
2091.95	12.4201
2094.86	12.4146
2097.77	12.7731
2100.68	12.7099
2103.59	13.0872
2106.5	12.8478
2109.41	13.505
2112.31	13.7647
2115.21	14.4724
2118.12	14.7694
2121.02	16.1337
2123.92	16.7721
2126.82	16.3232
2129.72	16.9071
2132.62	16.9704
2135.51	17.7934
2138.41	18.4649
2141.31	18.3691
2144.2	18.8286
2147.09	19.9823
2149.98	21.8007
2152.87	22.9556
2155.76	24.262
2158.65	24.2941
2161.54	24.977
2164.43	25.011
2167.31	25.1427
2170.2	25.2512
2173.08	24.2967
2175.96	23.9404
2178.84	24.7869
2181.72	26.1522
2184.6	25.0748
2187.48	25.2658
2190.36	25.8349
2193.23	26.8914
2196.11	25.9761
2198.98	25.3739
2201.85	25.5002
2204.72	26.0107
2207.59	24.5996
2210.46	24.5389
2213.33	24.3979
2216.2	23.903
2219.07	23.924
2221.93	23.4581
2224.8	22.4721
2227.66	21.315
2230.52	20.2429
2233.39	19.7293
2236.25	19.1882
2239.1	18.6181
2241.96	17.3741
2244.82	17.757
2247.68	17.8598
2250.53	18.3352
2253.38	17.2504
2256.24	16.8342
2259.09	17.6784
2261.94	17.3329
2264.79	16.7169
2267.64	16.6176
2270.49	16.4414
2273.33	16.1735
2276.18	14.7981
2279.02	14.5465
2281.87	13.6565
2284.71	13.112
2287.55	11.7447
2290.39	9.82274
2293.23	8.53472
2296.07	8.94773
2298.91	9.74211
2301.74	10.212
2304.58	11.3925
2307.41	12.2912
2310.25	12.6707
2313.08	12.8519
2315.91	12.7079
2318.74	12.3056
2321.57	12.9021
2324.4	12.5085
2327.23	12.7929
2330.05	13.0777
2332.88	12.5785
2335.7	11.8688
2338.52	10.8285
2341.35	9.21067
2344.17	7.70037
2346.99	6.85725
2349.81	5.33853
2352.62	4.5247
2355.44	2.05189
2358.26	-0.142516
2361.07	-1.77294
2363.89	-0.258051
2366.7	1.1573
2369.51	0.732688
2372.32	0.841552
2375.13	1.16672
2377.94	1.11934
2380.75	1.50317
2383.56	2.5852
2386.36	3.06949
2389.17	4.39352
2391.97	4.61166
2394.77	5.08127
2397.58	5.60746
2400.38	6.48776
2403.18	6.94183
2405.97	7.11564
2408.77	7.96002
2411.57	7.80465
2414.37	8.11336
2417.16	7.34446
2419.95	6.89888
2422.75	5.66396
2425.54	4.9526
2428.33	4.75901
2431.12	3.76667
2433.91	3.7522
2436.7	3.50345
2439.48	3.61929
2442.27	2.81834
2445.05	2.61847
2447.84	2.58538
2450.62	2.32387
2453.4	2.3497
2456.18	1.68668
2458.96	1.25379
2461.74	1.21677
2464.52	1.26845
2467.29	2.52489
2470.07	3.26002
2472.85	4.27801
2475.62	4.6413
2478.39	5.4926
2481.16	5.64655
2483.93	6.00258
2486.7	5.32945
2489.47	5.8166
2492.24	5.81047
2495.01	5.87222
2497.77	6.1417
2500.54	6.48329
2503.3	7.20794
2506.06	6.45283
2508.83	6.66236
2511.59	7.43237
2514.35	7.75987
2517.11	7.60598
2519.86	7.79385
2522.62	7.58437
2525.38	8.20641
2528.13	8.27155
2530.89	8.537
2533.64	9.15079
2536.39	9.32665
2539.14	10.1796
2541.89	10.7136
2544.64	10.6023
2547.39	9.84172
2550.14	10.0878
2552.88	9.86406
2555.63	10.2575
2558.37	10.8763
2561.11	11.1648
2563.86	10.9405
2566.6	11.8528
2569.34	11.6882
2572.08	12.1278
2574.82	13.3946
2577.55	14.5649
2580.29	14.2029
2583.02	15.0352
2585.76	14.6233
2588.49	14.4836
2591.22	13.4579
2593.96	13.1193
2596.69	11.444
2599.42	11.2708
2602.14	10.1883
2604.87	9.96208
2607.6	8.42742
2610.32	8.02711
2613.05	6.97112
2615.77	7.04567
2618.49	6.27312
2621.22	7.17217
2623.94	6.88412
2626.66	7.17458
2629.37	7.1748
2632.09	7.35704
2634.81	7.23427
2637.53	7.10344
2640.24	9.15109
2642.96	9.18177
2645.67	9.58327
2648.38	9.27778
2651.09	9.57285
2653.8	8.45475
2656.51	7.96338
2659.22	7.49062
2661.93	7.83302
2664.63	7.85939
2667.34	8.05572
2670.04	7.9997
2672.75	7.49974
2675.45	8.89861
2678.15	9.39635
2680.85	9.97879
2683.55	10.7949
2686.25	10.4077
2688.94	9.93826
2691.64	9.88071
2694.34	10.5811
2697.03	9.86689
2699.73	10.1111
2702.42	10.5501
2705.11	11.2189
2707.8	11.2918
2710.49	11.9273
2713.18	12.4341
2715.87	13.1342
2718.55	12.7675
2721.24	12.9257
2723.93	12.6935
2726.61	12.5081
2729.29	11.9125
2731.98	11.476
2734.66	11.4082
2737.34	11.514
2740.02	11.9164
2742.7	11.5661
2745.37	10.5763
2748.05	9.33048
2750.72	8.68952
2753.4	7.77783
2756.07	7.00263
2758.75	7.40913
2761.42	7.16649
2764.09	7.75683
2766.76	8.17962
2769.43	7.62578
2772.1	6.89901
2774.76	6.89637
2777.43	7.03032
2780.1	6.69819
2782.76	5.11033
2785.42	4.05866
2788.09	3.26088
2790.75	3.4797
2793.41	2.84166
2796.07	2.70438
2798.73	3.07007
2801.39	2.33522
2804.04	2.95564
2806.7	2.54835
2809.35	3.09294
2812.01	2.94345
2814.66	3.24055
2817.31	4.58114
2819.96	6.50611
2822.61	8.60234
2825.26	11.3905
2827.91	13.2303
2830.56	15.8133
2833.21	17.5908
2835.85	19.9827
2838.5	22.3992
2841.14	25.4876
2843.78	27.7854
2846.42	33.2435
2849.06	36.6628
2851.71	42.3641
2854.34	47.9798
2856.98	52.7914
2859.62	57.5766
2862.26	62.5077
2864.89	66.6523
2867.53	70.0597
2870.16	72.7319
2872.79	74.9958
2875.42	76.6049
2878.05	78.1626
2880.68	80.273
2883.31	82.9719
2885.94	85.0594
2888.57	86.719
2891.19	88.72
2893.82	90.1464
2896.44	92.2468
2899.07	94.7293
2901.69	97.9326
2904.31	101.785
2906.93	106.374
2909.55	112.071
2912.17	117.881
2914.79	123.228
2917.41	126.938
2920.02	130.073
2922.64	132.372
2925.25	134.244
2927.86	134.84
2930.48	133.278
2933.09	131.397
2935.7	128.685
2938.31	126.305
2940.92	122.145
2943.53	117.818
2946.13	113.322
2948.74	108.088
2951.34	103.269
2953.95	98.3712
2956.55	94.031
2959.15	88.4886
2961.75	84.0489
2964.35	80.0704
2966.95	76.4744
2969.55	72.0415
2972.15	68.9026
2974.75	64.6942
2977.34	60.6555
2979.94	56.9092
2982.53	51.8877
2985.13	47.1576
2987.72	42.0747
2990.31	36.7614
2992.9	33.2071
2995.49	29.5023
2998.08	25.8364
3000.67	22.2019
3003.25	19.1723
3005.84	15.2508
3008.42	12.6189
3011.01	10.3448
3013.59	7.88987
3016.17	6.35487
3018.76	4.66701
3021.34	3.72853
3023.92	2.44409
3026.49	3.55094
3029.07	2.87812
3031.65	3.25655
3034.23	4.20766
3036.8	5.04781
3039.38	5.45957
3041.95	6.5382
3044.52	7.2897
3047.09	7.07168
3049.66	8.39363
3052.23	9.17042
3054.8	10.3115
3057.37	10.6242
3059.94	10.081
3062.5	9.6212
3065.07	9.1554
3067.63	8.47347
3070.2	6.95734
3072.76	7.27037
3075.32	6.1293
3077.88	5.07088
3080.44	3.31508
3083	3.07878
3085.56	1.65459
3088.12	1.45087
3090.67	1.88419
3093.23	1.8851
3095.78	1.80489
3098.34	2.5409
3100.89	2.99259
3103.44	3.12411
3105.99	5.01947
3108.54	6.15207
3111.09	7.14612
3113.64	7.95817
3116.19	8.78434
3118.74	9.97704
3121.28	10.2881
3123.83	11.5789
3126.37	12.7187
3128.91	13.8622
3131.46	14.9386
3134	16.8989
3136.54	17.2674
3139.08	16.7908
3141.62	16.8163
3144.16	17.2319
3146.69	17.9423
3149.23	18.4736