File: data/Raman/poly_smoothed/Thy_40_11_17_1x_45s_532 nm_x100_100%_600 gr_mm_01.txt
#Acq. time (s)=	45
#Accumulations=	2
#Range (cm-¹)=	200...3150
#Windows=	2
#Auto scanning=	Off
#Autofocus=	Off
#Macrospot=	Off
#AutoExposure=	Off
#Spike filter=	Multiple accum.
#Delay time (s)=	0
#Binning=	1
#Readout mode=	Signal
#DeNoise=	Off
#ICS correction=	On
#Dark correction=	Off
#Inst. Process=	Off
#Detector Gain=	Best Dynamic Range
#Detector ADC=	20 kHz
#Detector temperature (°C)=	-69.85
#Instrument=	LabRAM HR Evol
#Detector=	Synapse
#Objective=	x100
#Grating=	600 gr/mm
#ND Filter=	100%
#Laser (nm)=	532
#Hole=	100.021
#Range=	Auto
#Laser Pol.=	No
#Raman. Pol.=	No
#Laser Pol. (°)=	-0.0007625
#Raman Pol. (°)=	89.9995
#Collection=	Microscope
#StageXY=	Marzhauser
#StageZ=	Marzhauser
#X (µm)=	1984.8
#Y (µm)=	-49.2
#Z (µm)=	425.1
#Full time(mm:ss)=	3:18
#Project=
#Sample=
#Site=
#Title=	Thy_40_11_17_2x_45s_532 nm_x100_100%_600 gr_mm
#Remark=
#Date=	05.07.2022 11:05
#Acquired=	05.07.2022 11:05:55
#Base:Fit=	10.08.2022 10:01:35
#Base:Sub=	10.08.2022 10:01:52
#Filter:Polynom=	16.08.2022 10:21:53
#AxisType[0]=Intens
#AxisUnit[0]=Cnt
#AxisType[1]=Spectr
#AxisUnit[1]=1/cm
200.43	17.9536
204.059	22.9529
207.688	25.0282
211.314	25.0608
214.941	23.9655
218.564	21.2375
222.186	18.9837
225.809	16.472
229.428	16.1331
233.045	13.9368
236.663	11.177
240.278	8.93617
243.891	8.40295
247.503	7.67826
251.116	5.34932
254.725	4.72237
258.333	5.16298
261.939	6.46549
265.544	7.40939
269.148	5.49492
272.75	6.25879
276.351	6.66033
279.95	9.58129
283.548	9.85505
287.144	9.45731
290.739	11.1088
294.333	10.6997
297.925	10.5354
301.514	10.6974
305.104	10.7692
308.692	12.0884
312.279	13.9096
315.862	14.8732
319.446	14.3583
323.029	14.1378
326.608	13.8841
330.188	14.0079
333.766	16.0021
337.341	15.5319
340.917	15.0957
344.489	16.0463
348.062	14.4874
351.631	13.4363
355.201	12.3447
358.768	10.4824
362.333	8.87869
365.899	8.31394
369.462	7.22419
373.023	5.57802
376.585	4.14953
380.143	4.43857
383.7	5.00221
387.256	5.55572
390.812	5.79419
394.365	8.94877
397.916	9.32516
401.467	9.8146
405.015	10.2193
408.563	13.1716
412.109	13.6508
415.654	14.3956
419.197	14.8063
422.739	15.8177
426.279	14.4106
429.819	14.0683
433.356	12.5122
436.891	10.7497
440.426	10.9326
443.96	8.49328
447.492	7.90367
451.021	7.471
454.551	7.5679
458.079	7.40275
461.604	7.49505
465.13	8.63678
468.654	10.0785
472.175	11.9968
475.696	13.1405
479.215	16.719
482.733	19.1829
486.249	20.9917
489.765	23.6145
493.278	26.5552
496.789	28.9841
500.301	29.6915
503.81	32.7771
507.317	33.8598
510.825	35.1512
514.33	34.7622
517.833	35.0235
521.335	33.9783
524.836	32.9975
528.335	30.7618
531.835	29.2643
535.332	28.2615
538.827	27.5409
542.321	25.7847
545.814	23.1084
549.305	20.4275
552.795	18.2237
556.282	16.5291
559.769	13.9393
563.255	11.6983
566.739	10.2002
570.223	7.61621
573.705	6.35592
577.183	5.72095
580.663	5.82606
584.141	5.23787
587.615	5.20598
591.09	5.44764
594.564	6.82912
598.035	6.48669
601.506	5.64555
604.974	6.17838
608.443	8.0683
611.908	9.61873
615.374	10.601
618.837	12.6682
622.3	16.0983
625.761	16.1919
629.219	16.6231
632.677	19.171
636.135	19.3561
639.59	19.6748
643.043	18.7517
646.495	20.745
649.948	22.1406
653.398	24.214
656.846	24.9834
660.293	24.7079
663.738	24.8832
667.183	24.0892
670.626	25.2768
674.067	24.8118
677.508	25.207
680.947	25.2493
684.385	26.2102
687.821	27.7714
691.254	30.4056
694.688	33.1644
698.121	34.2033
701.552	34.2198
704.98	36.5478
708.409	38.3097
711.836	40.3477
715.26	44.1345
718.685	46.5433
722.108	46.4537
725.528	47.2972
728.949	49.0403
732.367	51.0163
735.785	52.6076
739.2	54.3443
742.614	54.5798
746.028	55.755
749.439	56.2939
752.849	58.2942
756.26	62.2689
759.667	65.2463
763.073	69.2746
766.477	72.4043
769.883	75.0832
773.285	81.2019
776.686	84.1854
780.085	86.665
783.484	88.9194
786.881	90.0388
790.276	93.912
793.671	97.0204
797.064	98.9339
800.456	98.2654
803.846	97.6485
807.234	96.7895
810.622	96.3894
814.008	96.1852
817.394	95.9575
820.778	93.9113
824.159	92.1517
827.541	89.284
830.921	87.8577
834.298	87.0652
837.676	86.1076
841.051	83.7563
844.426	81.8499
847.798	78.5876
851.171	76.5825
854.54	76.2663
857.911	73.8292
861.278	69.4467
864.645	65.2788
868.01	63.4031
871.373	62.045
874.735	60.1181
878.097	59.3904
881.457	59.072
884.815	57.2654
888.172	55.7013
891.528	56.4995
894.882	54.7688
898.237	52.9644
901.589	50.5943
904.94	51.5112
908.289	52.7894
911.635	52.66
914.982	52.1124
918.328	51.9157
921.672	52.0049
925.015	50.5434
928.357	48.387
931.698	48.0154
935.035	48.453
938.373	48.5288
941.71	46.3583
945.044	42.1793
948.378	38.957
951.709	40.6975
955.041	42.984
958.372	45.7046
961.699	49.0054
965.027	51.229
968.352	52.2814
971.676	54.1534
975	54.4606
978.322	56.3084
981.642	59.5511
984.962	60.3725
988.28	60.6629
991.596	60.7245
994.911	59.8547
998.227	60.5824
1001.54	60.3695
1004.85	59.1104
1008.16	57.5132
1011.47	56.5129
1014.78	54.7352
1018.08	53.0571
1021.39	49.5843
1024.69	46.6373
1028	45.7542
1031.3	46.8693
1034.6	49.6775
1037.9	47.9095
1041.19	45.8592
1044.49	47.5506
1047.78	46.9732
1051.08	43.3995
1054.37	42.9028
1057.66	41.6307
1060.95	41.3272
1064.24	40.3802
1067.53	39.4286
1070.81	40.8203
1074.1	42.0132
1077.38	42.8977
1080.66	42.2862
1083.94	42.162
1087.22	42.8202
1090.5	42.7351
1093.78	40.6359
1097.05	39.6897
1100.33	37.6854
1103.6	38.2651
1106.87	37.2194
1110.14	35.6968
1113.41	33.5405
1116.68	30.634
1119.95	27.7527
1123.21	26.7605
1126.48	23.4217
1129.74	20.811
1133	18.4322
1136.26	16.1804
1139.52	14.8844
1142.78	13.7926
1146.04	13.0428
1149.29	10.1092
1152.55	9.23739
1155.8	8.82957
1159.05	7.65305
1162.3	5.536
1165.55	5.03642
1168.8	3.38419
1172.05	3.88457
1175.29	3.81494
1178.54	4.87005
1181.78	6.94628
1185.02	8.62343
1188.26	8.74605
1191.5	11.8758
1194.74	15.6028
1197.97	17.755
1201.21	22.488
1204.44	27.1538
1207.68	29.368
1210.91	35.5494
1214.14	40.0592
1217.37	44.5185
1220.59	48.0915
1223.82	53.6233
1227.05	58.3327
1230.27	62.9405
1233.49	68.2931
1236.72	74.3945
1239.94	78.7104
1243.16	83.9596
1246.37	87.6508
1249.59	90.9105
1252.8	93.136
1256.02	94.9308
1259.23	95.9662
1262.44	97.9584
1265.66	100.214
1268.86	103.155
1272.07	107.603
1275.28	109.022
1278.48	111.093
1281.69	113.721
1284.89	115.942
1288.09	118.205
1291.29	119.564
1294.49	119.329
1297.69	120.42
1300.89	120.297
1304.08	120.531
1307.28	120.672
1310.47	120.838
1313.66	122.815
1316.85	124.002
1320.04	123.241
1323.23	121.17
1326.42	118.79
1329.61	115.454
1332.79	112.118
1335.97	109.797
1339.16	105.883
1342.34	102.9
1345.52	98.2776
1348.7	93.5165
1351.87	89.1602
1355.05	83.6497
1358.22	81.0114
1361.4	74.7216
1364.57	70.5402
1367.74	66.6855
1370.91	62.2418
1374.08	56.7293
1377.25	52.2833
1380.41	50.6033
1383.58	48.3845
1386.74	48.9365
1389.91	49.5412
1393.07	48.6479
1396.23	49.2633
1399.39	46.2607
1402.55	45.1023
1405.7	45.5891
1408.86	44.8224
1412.01	47.1747
1415.17	50.3686
1418.32	54.2697
1421.47	59.5867
1424.62	64.7887
1427.77	72.2848
1430.91	79.6584
1434.06	85.9348
1437.2	91.7492
1440.35	97.5864
1443.49	103.154
1446.63	107.967
1449.77	108.497
1452.91	109.133
1456.05	110.269
1459.18	109.446
1462.32	105.269
1465.45	100.18
1468.59	92.2161
1471.72	83.7509
1474.85	75.1973
1477.98	66.2659
1481.1	58.6446
1484.23	50.5068
1487.36	42.4773
1490.48	37.6741
1493.61	30.2673
1496.73	25.5249
1499.85	22.9942
1502.97	21.025
1506.09	20.1127
1509.2	20.3928
1512.32	19.2277
1515.43	19.1935
1518.55	20.5183
1521.66	21.0275
1524.77	22.729
1527.88	23.3471
1530.99	26.6257
1534.1	28.0797
1537.21	29.7145
1540.31	33.5259
1543.42	37.4345
1546.52	43.2965
1549.62	48.585
1552.72	52.1031
1555.82	57.3643
1558.92	61.0806
1562.02	64.5532
1565.11	69.736
1568.21	72.9617
1571.3	77.8469
1574.39	83.1333
1577.49	87.3812
1580.57	91.5158
1583.66	95.5984
1586.75	95.847
1589.84	97.0797
1592.92	97.5325
1596.01	97.934
1599.09	96.6695
1602.17	96.5102
1605.25	95.5196
1608.33	94.7406
1611.41	94.5472
1614.49	95.7161
1617.57	97.2018
1620.64	98.6373
1623.72	101.106
1626.79	103.4
1629.86	109.216
1632.93	113.796
1636	118.439
1639.07	125.037
1642.13	128.917
1645.2	134.74
1648.26	139.795
1651.33	143.252
1654.39	146.995
1657.45	148.509
1660.51	148.494
1663.57	147.039
1666.63	143.691
1669.68	139.646
1672.74	134.06
1675.79	127.252
1678.85	119.635
1681.9	109.974
1684.95	100.413
1688	90.3176
1691.05	80.5555
1694.09	70.2398
1697.14	61.0291
1700.18	54.9877
1703.23	47.1923
1706.27	39.3272
1709.31	33.2167
1712.35	28.649
1715.39	24.5432
1718.43	20.3176
1721.47	17.6174
1724.5	14.837
1727.54	12.5197
1730.57	11.4726
1733.61	9.77692
1736.64	8.30775
1739.67	7.94893
1742.7	7.00382
1745.72	6.68456
1748.75	5.99447
1751.77	4.45385
1754.8	3.21159
1757.82	2.58108
1760.84	1.80861
1763.87	0.822563
1766.89	0.262383
1769.91	0.211782
1772.92	-0.478383
1775.94	-0.427051
1778.95	-1.01911
1781.97	-1.07434
1784.98	-1.07213
1787.99	-0.63745
1791.01	-0.0309401
1794.01	-0.440029
1797.02	0.317147
1800.03	0.292619
1803.04	0.488842
1806.04	1.03556
1809.05	0.330968
1812.05	1.51332
1815.05	1.42578
1818.05	2.23753
1821.05	2.28338
1824.05	2.34374
1827.05	2.9236
1830.04	4.04353
1833.04	4.15996
1836.03	4.70928
1839.03	5.08316
1842.02	4.56036
1845.01	5.13167
1848	5.51266
1850.99	5.12284
1853.97	5.30058
1856.96	5.80273
1859.94	5.90728
1862.93	6.22553
1865.91	5.02591
1868.89	5.09445
1871.87	5.11698
1874.85	4.99722
1877.83	4.63235
1880.81	4.20899
1882.57	4.30001
1885.56	3.98881
1888.55	3.62323
1891.54	2.54859
1894.52	1.48846
1897.51	1.70751
1900.49	1.56073
1903.47	1.93425
1906.45	1.55563
1909.43	2.02406
1912.41	3.10069
1915.39	3.33406
1918.37	4.52568
1921.34	3.47039
1924.32	4.49906
1927.29	4.9481
1930.26	3.73574
1933.23	3.80328
1936.2	3.15544
1939.17	3.46711
1942.14	4.30917
1945.11	4.34242
1948.07	3.9828
1951.04	3.91583
1954	4.25498
1956.96	4.40571
1959.93	3.13634
1962.89	2.05506
1965.85	2.60831
1968.8	3.57124
1971.76	3.35431
1974.72	4.59449
1977.67	4.45777
1980.63	5.50929
1983.58	7.05293
1986.53	7.63016
1989.48	7.43097
1992.43	7.18803
1995.38	8.06128
1998.32	7.25316
2001.27	5.74677
2004.22	6.42767
2007.16	6.4392
2010.1	6.05401
2013.04	5.94962
2015.98	6.36005
2018.92	5.85891
2021.86	4.49795
2024.8	4.79601
2027.74	4.66405
2030.67	4.64241
2033.61	4.73243
2036.54	6.16264
2039.47	7.0545
2042.4	7.4548
2045.33	9.04539
2048.26	10.9477
2051.19	13.3149
2054.12	14.592
2057.04	16.0771
2059.97	17.4786
2062.89	19.021
2065.81	20.7214
2068.73	21.8744
2071.65	22.1961
2074.57	23.6955
2077.49	25.5026
2080.41	26.9551
2083.32	29.1749
2086.24	29.9097
2089.15	30.8787
2092.07	31.9097
2094.98	33.5109
2097.89	36.5885
2100.8	39.6705
2103.71	42.0079
2106.61	46.1403
2109.52	49.8761
2112.43	53.7426
2115.33	58.7835
2118.23	63.5105
2121.13	69.6336
2124.04	75.237
2126.94	81.6048
2129.83	88.9555
2132.73	94.5217
2135.63	102.43
2138.53	109.214
2141.42	115.488
2144.31	121.637
2147.21	128.829
2150.1	136.29
2152.99	141.783
2155.88	146.541
2158.77	151.908
2161.65	155.972
2164.54	160.168
2167.43	162.249
2170.31	164.451
2173.19	165.299
2176.07	164.817
2178.96	164.093
2181.84	162.43
2184.72	159.68
2187.59	155.85
2190.47	151.887
2193.35	147.978
2196.22	143.164
2199.09	137.806
2201.97	131.319
2204.84	124.975
2207.71	117.952
2210.58	110.17
2213.45	103.113
2216.31	97.0746
2219.18	91.8362
2222.05	84.7112
2224.91	77.1813
2227.78	71.7869
2230.64	66.1335
2233.5	60.3766
2236.36	55.9311
2239.22	50.6511
2242.08	47.8567
2244.93	43.6122
2247.79	40.6728
2250.64	37.8251
2253.5	35.5714
2256.35	33.6977
2259.2	32.6467
2262.05	31.5572
2264.9	31.8677
2267.75	29.1504
2270.6	27.775
2273.45	26.4093
2276.29	25.0176
2279.14	23.9836
2281.98	22.8871
2284.82	22.6862
2287.66	20.4843
2290.5	18.5917
2293.34	16.6334
2296.18	15.4751
2299.02	15.1749
2301.86	15.1803
2304.69	16.203
2307.53	15.8906
2310.36	14.8839
2313.19	15.2293
2316.02	13.9706
2318.85	13.0172
2321.68	12.2355
2324.51	12.2766
2327.34	11.5276
2330.16	10.3949
2332.99	10.0765
2335.81	9.27955
2338.64	8.3389
2341.46	7.51467
2344.28	6.34293
2347.1	5.74631
2349.92	4.51792
2352.74	3.07507
2355.55	1.3432
2358.37	-0.188469
2361.19	0.0372288
2364	0.661601
2366.81	1.26054
2369.62	2.52965
2372.44	1.6786
2375.24	1.14466
2378.05	1.18418
2380.86	0.980457
2383.67	2.12518
2386.47	2.26898
2389.28	2.94671
2392.08	3.37647
2394.89	3.36653
2397.69	3.93594
2400.49	4.56779
2403.29	6.04173
2406.09	6.66649
2408.88	7.03897
2411.68	6.91428
2414.48	6.46918
2417.27	7.50854
2420.06	7.60694
2422.86	6.91554
2425.65	6.93206
2428.44	7.23243
2431.23	7.33604
2434.02	6.59719
2436.81	5.95279
2439.59	6.02141
2442.38	6.69965
2445.16	6.97554
2447.95	6.46892
2450.73	7.18729
2453.51	8.05911
2456.29	7.99592
2459.07	7.63527
2461.85	7.78951
2464.63	7.10394
2467.4	7.24946
2470.18	6.79577
2472.95	6.84631
2475.73	4.70656
2478.5	4.00534
2481.27	3.07769
2484.04	2.71493
2486.81	2.35016
2489.58	2.05746
2492.35	0.486534
2495.12	0.389832
2497.88	-0.276158
2500.65	-0.840458
2503.41	-0.394559
2506.17	0.568785
2508.94	0.858588
2511.7	2.13686
2514.46	3.63756
2517.22	4.38266
2519.97	5.49838
2522.73	6.18851
2525.49	5.92489
2528.24	6.87664
2530.99	7.45513
2533.75	7.82135
2536.5	6.97667
2539.25	6.41283
2542	6.69931
2544.75	7.06777
2547.5	7.43754
2550.24	7.58804
2552.99	8.14675
2555.74	8.9943
2558.48	9.2688
2561.22	9.70913
2563.96	9.9247
2566.71	9.92133
2569.45	9.59039
2572.18	10.1208
2574.92	10.1122
2577.66	10.8268
2580.4	10.183
2583.13	9.57393
2585.87	8.27403
2588.6	8.01255
2591.33	5.99371
2594.06	6.25969
2596.79	5.85076
2599.52	4.95832
2602.25	2.83991
2604.98	2.77966
2607.71	3.05687
2610.43	2.96526
2613.16	2.59696
2615.88	2.23219
2618.6	2.35101
2621.32	2.89158
2624.04	3.28164
2626.76	3.65174
2629.48	3.87201
2632.2	3.09558
2634.92	2.28929
2637.63	2.32744
2640.35	1.60236
2643.06	2.89013
2645.77	4.47677
2648.49	5.29705
2651.2	5.99859
2653.91	7.35786
2656.62	7.71325
2659.33	9.01861
2662.03	10.1516
2664.74	10.3527
2667.44	11.6614
2670.15	12.348
2672.85	12.7394
2675.55	13.7621
2678.26	13.2742
2680.96	13.0523
2683.66	13.0289
2686.35	13.0201
2689.05	13.0978
2691.75	13.5532
2694.44	12.9024
2697.14	11.8664
2699.83	11.568
2702.52	11.3021
2705.22	11.3695
2707.91	11.7072
2710.6	12.3209
2713.29	12.7964
2715.97	12.1974
2718.66	12.3531
2721.35	13.1204
2724.03	13.3211
2726.72	13.4902
2729.4	14.2851
2732.08	15.0957
2734.76	14.9612
2737.44	14.4077
2740.12	13.7513
2742.8	13.5635
2745.48	13.2156
2748.16	13.1343
2750.83	13.1848
2753.51	11.963
2756.18	12.2266
2758.85	10.7602
2761.53	10.0553
2764.2	8.96541
2766.87	8.28701
2769.54	6.4349
2772.2	4.68189
2774.87	3.88739
2777.54	3.33024
2780.2	3.07495
2782.87	2.36144
2785.53	2.50433
2788.19	1.80282
2790.85	0.440646
2793.51	-0.432949
2796.17	-0.347891
2798.83	-0.294506
2801.49	-0.751717
2804.15	-1.27075
2806.8	-1.01495
2809.46	0.993217
2812.11	1.4407
2814.76	2.09829
2817.42	1.70012
2820.07	3.89723
2822.72	6.83514
2825.37	10.8712
2828.02	16.5385
2830.66	23.5894
2833.31	30.912
2835.96	37.9026
2838.6	47.4836
2841.24	57.6359
2843.89	68.589
2846.53	80.3809
2849.17	94.4975
2851.81	108.038
2854.45	121.592
2857.09	135.158
2859.72	151.164
2862.36	165.787
2865	177.89
2867.63	188.949
2870.26	200.742
2872.9	210.774
2875.53	219.358
2878.16	225.989
2880.79	232.356
2883.42	240.463
2886.05	247.424
2888.67	254.921
2891.3	263.091
2893.92	271.009
2896.55	280.047
2899.17	290.719
2901.79	303.241
2904.42	317.583
2907.04	333.917
2909.66	353.203
2912.27	373.593
2914.89	395.118
2917.51	414.923
2920.13	432.837
2922.74	449.221
2925.35	461.791
2927.97	470.833
2930.58	475.854
2933.19	478.576
2935.8	477.661
2938.41	473.085
2941.02	464.064
2943.63	452.682
2946.24	438.624
2948.84	422.183
2951.45	403.534
2954.05	384.386
2956.65	364.192
2959.26	343.275
2961.86	324.135
2964.46	304.874
2967.06	286.158
2969.66	269.619
2972.25	255.152
2974.85	239.984
2977.45	224.706
2980.04	210.124
2982.64	194.286
2985.23	178.341
2987.82	162.361
2990.41	146.536
2993	130.96
2995.59	117.35
2998.18	103.71
3000.77	91.2732
3003.36	78.2428
3005.94	67.2918
3008.53	57.716
3011.11	47.5901
3013.69	39.326
3016.28	33.6618
3018.86	28.1821
3021.44	22.187
3024.02	17.9789
3026.6	14.8814
3029.18	12.7242
3031.75	11.4128
3034.33	10.7512
3036.9	10.7991
3039.48	12.6082
3042.05	13.6462
3044.62	15.0729
3047.19	16.6996
3049.77	17.0016
3052.34	17.4143
3054.9	18.7793
3057.47	20.0224
3060.04	19.965
3062.61	18.8287
3065.17	17.8102
3067.74	16.6628
3070.3	15.3765
3072.86	13.5631
3075.42	12.2377
3077.99	11.4754
3080.54	8.97826
3083.1	6.49879
3085.66	4.50312
3088.22	3.44553
3090.78	1.04293
3093.33	0.401581
3095.89	-0.620634
3098.44	-0.5634
3100.99	0.244703
3103.54	0.932765
3106.1	0.625266
3108.65	1.6653
3111.2	2.03022
3113.74	2.93135
3116.29	4.25553
3118.84	5.9321
3121.38	6.40429
3123.93	7.60724
3126.47	8.55767
3129.01	10.5366
3131.56	12.4294
3134.1	14.2941
3136.64	17.4524
3139.18	20.4374
3141.72	23.1977
3144.26	25.7381
3146.79	28.4207
3149.33	32.1512