File: data/Raman/poly_smoothed/Thy_10_08_42_1x_45s_532 nm_x100_100%_600 gr_mm_01.txt
#Acq. time (s)=	45
#Accumulations=	2
#Range (cm-¹)=	200...3150
#Windows=	2
#Auto scanning=	Off
#Autofocus=	Off
#Macrospot=	Off
#AutoExposure=	Off
#Spike filter=	Multiple accum.
#Delay time (s)=	0
#Binning=	1
#Readout mode=	Signal
#DeNoise=	Off
#ICS correction=	On
#Dark correction=	Off
#Inst. Process=	Off
#Detector Gain=	Best Dynamic Range
#Detector ADC=	20 kHz
#Detector temperature (°C)=	-69.85
#Instrument=	LabRAM HR Evol
#Detector=	Synapse
#Objective=	x100
#Grating=	600 gr/mm
#ND Filter=	100%
#Laser (nm)=	532
#Hole=	100.021
#Range=	Auto
#Laser Pol.=	No
#Raman. Pol.=	No
#Laser Pol. (°)=	-0.0007625
#Raman Pol. (°)=	89.9995
#Collection=	Microscope
#StageXY=	Marzhauser
#StageZ=	Marzhauser
#X (µm)=	-2363.4
#Y (µm)=	232.5
#Z (µm)=	521.55
#Full time(mm:ss)=	3:19
#Project=
#Sample=
#Site=
#Title=	Thy_10_08_42_2x_45s_532 nm_x100_100%_600 gr_mm
#Remark=
#Date=	06.07.2022 14:47
#Acquired=	06.07.2022 14:47:24
#Base:Fit=	10.08.2022 09:46:25
#Base:Sub=	10.08.2022 09:46:49
#Filter:Polynom=	16.08.2022 10:24:56
#AxisType[0]=Intens
#AxisUnit[0]=Cnt
#AxisType[1]=Spectr
#AxisUnit[1]=1/cm
200.398	10.5431
204.027	13.4117
207.657	14.7817
211.283	15.7334
214.909	17.0226
218.533	18.4788
222.157	19.2696
225.777	19.3334
229.396	19.0819
233.016	17.9848
236.632	18.3511
240.247	18.1168
243.86	18.6167
247.474	18.2944
251.085	17.1142
254.694	16.9865
258.301	17.5206
261.908	16.9532
265.513	18.0798
269.116	18.3876
272.718	17.1776
276.319	16.8665
279.918	15.3672
283.516	15.3581
287.113	16.6545
290.708	15.3921
294.302	16.172
297.894	18.0097
301.485	20.4116
305.073	20.1428
308.661	19.6256
312.247	19.7491
315.833	20.0687
319.415	18.6009
322.997	18.9408
326.579	20.2553
330.156	20.511
333.735	20.6381
337.31	19.9145
340.885	19.8293
344.458	19.0881
348.03	19.679
351.6	19.5107
355.17	19.0988
358.737	16.4151
362.304	17.1293
365.868	15.4215
369.431	14.2939
372.994	14.7719
376.554	15.0647
380.112	16.0076
383.669	17.5005
387.225	16.9444
390.781	15.7389
394.334	13.9746
397.885	13.3926
401.436	12.6305
404.984	11.7882
408.532	10.5649
412.078	9.97291
415.623	9.64654
419.166	8.2917
422.708	7.13571
426.248	6.6399
429.788	5.45272
433.326	5.1534
436.86	3.96698
440.395	2.86191
443.929	2.61971
447.461	3.87162
450.99	3.9711
454.52	4.12985
458.048	5.45918
461.573	8.19466
465.099	9.08491
468.623	11.4623
472.144	13.5294
475.666	14.0727
479.184	16.0856
482.703	16.4208
486.218	17.4632
489.734	18.2966
493.247	18.8304
496.759	18.7078
500.271	17.9228
503.779	16.3021
507.287	15.0125
510.795	14.3477
514.299	13.4613
517.803	12.7751
521.305	13.142
524.805	11.9442
528.307	11.5065
531.805	10.736
535.301	10.3765
538.797	9.76699
542.291	9.78546
545.783	10.2465
549.275	10.6648
552.765	9.88914
556.253	11.387
559.738	9.77378
563.224	9.71682
566.709	8.8064
570.192	9.6174
573.674	7.46767
577.153	5.4074
580.632	4.64311
584.11	3.93654
587.587	2.75876
591.06	0.861749
594.534	1.64449
598.005	0.963362
601.476	1.14134
604.944	1.0543
608.413	2.49635
611.878	3.42195
615.344	3.87892
618.807	4.91558
622.27	6.28596
625.73	7.69194
629.189	8.77807
632.648	11.0184
636.105	11.3238
639.559	13.4349
643.013	15.3363
646.467	16.3557
649.918	17.448
653.368	18.2051
656.816	17.7319
660.263	17.653
663.708	19.4464
667.153	20.1523
670.596	21.9988
674.037	21.8498
677.478	23.5028
680.917	24.8451
684.355	26.7232
687.791	28.3984
691.224	29.8284
694.658	30.9897
698.091	31.8622
701.522	33.0476
704.95	34.7695
708.379	36.9306
711.806	38.0171
715.23	40.9138
718.655	42.9445
722.078	44.298
725.498	47.5487
728.919	49.094
732.337	50.5919
735.755	51.3766
739.17	52.4561
742.584	55.158
745.998	57.331
749.409	60.3619
752.819	63.8046
756.23	66.0708
759.637	67.8417
763.043	68.6244
766.448	71.2108
769.853	73.8866
773.255	74.5076
776.656	75.8302
780.056	76.1541
783.454	78.5874
786.851	81.4717
790.247	82.0262
793.641	84.9431
797.034	86.7587
800.426	87.7778
803.817	88.5512
807.206	88.7864
810.592	89.0889
813.979	88.4788
817.364	87.5441
820.748	86.5218
824.129	86.0832
827.511	85.7993
830.891	84.3072
834.269	82.0046
837.646	79.7806
841.023	78.0368
844.396	75.0313
847.77	73.4685
851.141	71.2961
854.513	68.321
857.881	66.5304
861.248	64.5304
864.616	63.7119
867.98	64.4264
871.343	62.1882
874.707	61.5101
878.068	60.3764
881.428	58.9081
884.786	58.4893
888.143	57.5557
891.498	57.6532
894.855	57.3812
898.208	57.5532
901.56	57.2898
904.91	56.134
908.26	56.5062
911.608	55.6532
914.955	55.1991
918.298	54.3327
921.643	53.5839
924.986	52.5142
928.328	49.9375
931.668	48.0808
935.006	48.0629
938.344	47.3764
941.681	47.3634
945.014	46.885
948.349	46.3308
951.682	45.9093
955.012	44.5441
958.343	42.4523
961.67	42.873
964.998	44.8763
968.323	46.5596
971.649	48.6364
974.971	49.4101
978.293	49.0604
981.615	49.3224
984.933	48.7004
988.251	48.5842
991.567	48.76
994.884	49.2123
998.198	47.8256
1001.51	46.2127
1004.82	43.7285
1008.13	42.4106
1011.44	41.0375
1014.75	40.9668
1018.06	39.3311
1021.36	39.4846
1024.66	37.9135
1027.97	35.7917
1031.27	34.7948
1034.57	33.0307
1037.87	31.0197
1041.16	31.0709
1044.46	31.2731
1047.76	29.7366
1051.05	28.623
1054.34	29.3442
1057.63	27.2414
1060.92	26.621
1064.21	25.9565
1067.5	26.3963
1070.78	26.9938
1074.07	26.357
1077.35	26.74
1080.63	25.4729
1083.91	23.723
1087.19	23.5131
1090.47	24.4488
1093.75	24.269
1097.03	24.9206
1100.3	25.3786
1103.57	25.1334
1106.84	23.5478
1110.11	23.4045
1113.38	23.2826
1116.65	21.776
1119.92	19.1248
1123.19	18.0578
1126.45	16.0499
1129.71	16.0618
1132.97	16.0487
1136.23	15.4491
1139.49	15.2713
1142.75	15.4326
1146.01	15.7837
1149.26	15.3483
1152.52	13.2349
1155.77	12.2547
1159.02	11.7055
1162.27	10.2339
1165.52	9.28774
1168.77	10.8816
1172.02	10.06
1175.26	10.5876
1178.51	12.2524
1181.75	13.2667
1184.99	14.5584
1188.23	15.7736
1191.47	17.4219
1194.71	18.795
1197.94	19.0687
1201.18	20.4335
1204.41	22.3323
1207.65	25.6542
1210.88	28.6072
1214.11	31.6481
1217.34	34.8447
1220.57	38.6821
1223.79	40.206
1227.02	41.8235
1230.24	43.7935
1233.47	46.4693
1236.69	47.3878
1239.91	49.0712
1243.13	49.465
1246.34	50.9618
1249.56	51.3858
1252.78	50.8446
1255.99	51.4448
1259.2	51.429
1262.42	52.3739
1265.63	52.0875
1268.84	51.4477
1272.04	50.7768
1275.25	50.7723
1278.46	50.7522
1281.66	52.4839
1284.86	54.1195
1288.07	56.2541
1291.27	57.971
1294.47	59.8436
1297.66	61.0845
1300.86	62.871
1304.06	64.7658
1307.25	67.7256
1310.44	70.482
1313.64	71.6852
1316.83	72.3968
1320.02	71.6882
1323.2	71.249
1326.39	71.0505
1329.58	69.3887
1332.76	67.5365
1335.95	65.88
1339.13	63.1871
1342.31	61.5198
1345.49	58.4848
1348.67	55.9324
1351.85	54.7489
1355.02	52.4986
1358.2	50.0675
1361.37	48.5056
1364.54	46.3466
1367.71	43.788
1370.88	40.9327
1374.05	39.2019
1377.22	39.2216
1380.39	38.3288
1383.55	37.2318
1386.72	36.567
1389.88	35.1763
1393.04	34.2043
1396.2	33.0629
1399.36	32.0839
1402.52	32.9236
1405.68	32.806
1408.83	34.7821
1411.98	35.923
1415.14	38.762
1418.29	42.2727
1421.44	47.0356
1424.59	51.8236
1427.74	56.6448
1430.89	61.0649
1434.03	65.0806
1437.18	69.5602
1440.32	72.4948
1443.46	73.8249
1446.6	75.5112
1449.74	75.2727
1452.88	74.3569
1456.02	72.8773
1459.16	68.7436
1462.29	64.6813
1465.43	60.7198
1468.56	56.3594
1471.69	50.4296
1474.82	44.2072
1477.95	39.7856
1481.08	35.0332
1484.2	29.5545
1487.33	25.3715
1490.46	21.5255
1493.58	20.8475
1496.7	18.1986
1499.82	17.3506
1502.94	16.0737
1506.06	15.9361
1509.18	15.3295
1512.29	14.2366
1515.41	15.0293
1518.52	14.2031
1521.63	16.1674
1524.75	18.0047
1527.85	18.334
1530.96	21.5548
1534.07	23.7917
1537.18	25.5086
1540.28	28.3251
1543.39	30.3274
1546.49	32.701
1549.59	34.3825
1552.69	38.2914
1555.79	40.6658
1558.89	42.9594
1561.99	45.36
1565.08	48.2606
1568.18	50.3537
1571.27	52.8767
1574.37	54.6117
1577.46	56.6676
1580.55	58.1582
1583.64	59.315
1586.73	60.3428
1589.81	62.5294
1592.9	63.0828
1595.98	62.3583
1599.06	62.3479
1602.15	61.8347
1605.23	60.8637
1608.31	59.6668
1611.39	57.7567
1614.46	55.9459
1617.54	55.1173
1620.61	55.1488
1623.69	55.2041
1626.76	56.5814
1629.83	58.1718
1632.9	58.0468
1635.97	60.4942
1639.04	63.1898
1642.11	66.1753
1645.17	68.845
1648.24	72.1948
1651.3	73.6602
1654.36	75.7881
1657.42	76.7114
1660.48	76.3441
1663.54	75.8527
1666.6	73.3477
1669.66	69.8608
1672.71	66.3571
1675.77	63.4956
1678.82	58.3996
1681.87	53.5507
1684.92	48.495
1687.97	43.1783
1691.02	38.324
1694.07	33.3043
1697.11	28.5922
1700.16	23.5681
1703.2	19.04
1706.25	15.4013
1709.29	12.3241
1712.33	10.8078
1715.37	9.45221
1718.41	7.74732
1721.44	7.23664
1724.48	6.22323
1727.51	6.52719
1730.55	6.41479
1733.58	5.91783
1736.61	5.33507
1739.64	4.99152
1742.67	4.61366
1745.7	5.01539
1748.72	4.41846
1751.75	4.46202
1754.77	4.46114
1757.8	3.78102
1760.82	4.21721
1763.84	3.26249
1766.86	2.14257
1769.88	1.26405
1772.9	0.92327
1775.91	0.651927
1778.93	0.581435
1781.94	-0.154449
1784.96	0.597049
1787.97	0.780476
1790.98	2.08751
1793.99	2.55296
1797	3.01031
1800.01	3.88949
1803.01	4.03678
1806.02	3.25119
1809.02	3.53044
1812.02	3.04137
1815.02	2.78199
1818.03	2.33903
1821.02	2.57537
1824.02	2.43582
1827.02	2.85602
1830.02	2.91473
1833.01	2.3605
1836.01	2.68621
1839	3.12135
1841.99	2.70462
1844.98	2.39174
1847.97	2.12468
1850.96	1.54113
1853.95	1.37183
1856.93	1.21906
1859.92	0.986112
1862.9	0.886931
1865.88	0.626637
1868.87	0.271102
1871.85	0.0260981
1874.83	-0.504416
1877.81	-0.800579
1880.78	-1.03153
1882.53	-0.775716
1885.52	-0.415401
1888.51	0.13518
1891.5	0.305614
1894.48	0.534061
1897.47	0.580624
1900.45	1.46911
1903.43	1.45108
1906.41	1.75627
1909.39	2.80756
1912.37	3.60352
1915.35	3.03094
1918.33	4.08809
1921.3	5.06408
1924.28	4.85711
1927.25	5.51081
1930.22	5.49355
1933.19	5.91829
1936.16	6.38877
1939.13	6.5848
1942.1	7.12345
1945.07	6.59429
1948.03	7.48047
1951	7.05492
1953.96	7.49979
1956.92	7.36796
1959.88	7.50768
1962.84	7.07905
1965.8	6.31567
1968.76	6.25994
1971.72	5.7542
1974.67	6.20531
1977.63	6.06795
1980.58	6.68012
1983.54	6.35103
1986.49	7.16103
1989.44	7.36477
1992.39	8.05283
1995.33	8.04039
1998.28	8.26916
2001.23	8.84955
2004.17	8.87959
2007.12	9.53513
2010.06	9.74932
2013	10.1892
2015.94	9.21216
2018.88	9.05687
2021.82	9.14153
2024.76	9.28949
2027.69	8.79457
2030.63	8.54868
2033.56	7.83506
2036.5	8.21541
2039.43	8.84149
2042.36	9.3599
2045.29	10.1865
2048.22	10.4259
2051.15	11.671
2054.07	11.8742
2057	12.3919
2059.92	12.3144
2062.85	12.5731
2065.77	13.5567
2068.69	12.7458
2071.61	13.6706
2074.53	14.6109
2077.45	15.077
2080.37	15.3905
2083.28	15.3426
2086.2	15.288
2089.11	15.0303
2092.02	14.727
2094.94	15.5326
2097.85	15.2339
2100.76	14.5906
2103.66	14.306
2106.57	14.6458
2109.48	16.3692
2112.38	17.595
2115.29	18.5543
2118.19	19.2032
2121.09	20.0894
2123.99	20.8739
2126.89	21.2357
2129.79	21.6889
2132.69	22.9273
2135.59	24.3509
2138.48	25.5796
2141.38	27.1353
2144.27	28.8362
2147.17	29.3023
2150.06	30.3349
2152.95	31.4427
2155.84	32.1611
2158.73	32.9661
2161.61	33.9854
2164.5	34.2109
2167.38	33.5859
2170.27	33.5363
2173.15	34.8381
2176.03	35.0554
2178.91	35.252
2181.8	35.6119
2184.67	33.6828
2187.55	33.0043
2190.43	32.6935
2193.3	32.1511
2196.18	31.6465
2199.05	30.593
2201.93	28.3272
2204.8	26.9827
2207.67	26.6478
2210.54	24.7929
2213.41	23.555
2216.27	22.4014
2219.14	21.6237
2222.01	20.7341
2224.87	20.5317
2227.73	19.865
2230.6	19.1375
2233.46	18.6764
2236.32	18.2369
2239.18	17.7744
2242.03	18.6462
2244.89	18.1841
2247.75	17.13
2250.6	16.0084
2253.46	15.6501
2256.31	16.5423
2259.16	16.917
2262.01	16.8965
2264.86	16.2682
2267.71	16.4093
2270.56	16.1564
2273.4	15.0037
2276.25	15.6371
2279.09	16.09
2281.94	15.1631
2284.78	15.0446
2287.62	15.5306
2290.46	15.0929
2293.3	14.4528
2296.14	15.9478
2298.98	16.2091
2301.82	16.4683
2304.65	15.7581
2307.49	15.5155
2310.32	15.4256
2313.15	14.6074
2315.98	14.5596
2318.81	13.7059
2321.64	13.1317
2324.47	12.5753
2327.3	12.2943
2330.12	10.9763
2332.95	9.25694
2335.77	8.30721
2338.6	7.37228
2341.42	6.2383
2344.24	5.08375
2347.06	4.30288
2349.88	3.526
2352.7	2.76007
2355.51	3.52873
2358.33	3.52552
2361.14	3.95524
2363.96	5.59242
2366.77	5.47725
2369.58	5.10515
2372.39	5.39099
2375.2	6.7212
2378.01	8.25681
2380.82	8.47805
2383.63	8.61971
2386.43	8.94061
2389.24	9.7111
2392.04	10.4375
2394.84	10.6607
2397.65	10.6776
2400.45	9.92368
2403.25	9.88918
2406.05	10.9226
2408.84	10.4556
2411.64	10.1136
2414.44	10.4938
2417.23	10.4461
2420.02	10.2527
2422.82	10.1778
2425.61	9.698
2428.4	9.39561
2431.19	8.0858
2433.98	7.71071
2436.77	6.89507
2439.55	7.39837
2442.34	7.04791
2445.12	6.49295
2447.91	5.33877
2450.69	3.94296
2453.47	3.51857
2456.25	4.20661
2459.03	4.32155
2461.81	3.47613
2464.59	2.88164
2467.36	2.95211
2470.14	2.9265
2472.92	2.49119
2475.69	2.43192
2478.46	2.31743
2481.23	1.52181
2484	1.30231
2486.77	1.45318
2489.54	1.13386
2492.31	0.543266
2495.08	0.616533
2497.84	0.334768
2500.61	0.118234
2503.37	-0.00864704
2506.13	0.511278
2508.9	0.170892
2511.66	-0.47987
2514.42	0.379207
2517.18	0.414211
2519.93	0.526952
2522.69	1.0841
2525.45	1.48087
2528.2	1.87951
2530.95	2.81807
2533.71	3.78927
2536.46	4.21667
2539.21	4.45578
2541.96	4.70357
2544.71	4.56951
2547.46	3.98355
2550.2	3.78907
2552.95	3.90219
2555.7	3.581
2558.44	3.3524
2561.18	2.74411
2563.93	2.61549
2566.67	2.21879
2569.41	2.30513
2572.15	1.69518
2574.88	1.15287
2577.62	1.22592
2580.36	1.7677
2583.09	1.44512
2585.83	1.35476
2588.56	2.29079
2591.29	1.79429
2594.02	2.04303
2596.75	2.06003
2599.48	1.76949
2602.21	1.19601
2604.94	1.11459
2607.67	0.400146
2610.39	-0.320127
2613.12	-0.347458
2615.84	-0.313662
2618.56	-0.784614
2621.28	-1.05678
2624.01	-1.00582
2626.72	-1.13425
2629.44	-0.796484
2632.16	-0.374966
2634.88	-0.281378
2637.59	-0.209712
2640.31	-0.0544192
2643.02	0.4964
2645.74	1.1911
2648.45	1.59965
2651.16	2.04107
2653.87	2.18991
2656.58	1.7123
2659.29	1.10303
2661.99	1.53413
2664.7	1.64361
2667.41	2.01589
2670.11	2.31839
2672.81	1.7884
2675.51	1.93694
2678.22	2.2327
2680.92	1.97847
2683.62	1.82073
2686.31	1.71848
2689.01	1.14968
2691.71	1.73091
2694.4	2.52059
2697.1	2.84578
2699.79	4.15108
2702.49	3.87633
2705.18	4.8278
2707.87	5.40904
2710.56	6.12761
2713.25	6.20047
2715.94	7.72424
2718.62	8.76667
2721.31	8.47873
2723.99	9.57289
2726.68	10.7956
2729.36	12.6886
2732.04	13.0771
2734.73	13.281
2737.41	13.2219
2740.08	12.9896
2742.76	13.0639
2745.44	13.2991
2748.12	12.6808
2750.79	11.6958
2753.47	10.1967
2756.14	9.68149
2758.81	9.46175
2761.49	8.53385
2764.16	8.36636
2766.83	6.91196
2769.5	5.63664
2772.16	4.22986
2774.83	3.76216
2777.5	3.33763
2780.16	3.48411
2782.83	3.41103
2785.49	3.25577
2788.15	3.01469
2790.82	2.99864
2793.48	4.03814
2796.14	4.28906
2798.79	4.75666
2801.45	4.42889
2804.11	5.14358
2806.76	5.66432
2809.42	4.85655
2812.07	4.24168
2814.73	3.95885
2817.38	4.33778
2820.03	6.66488
2822.68	9.34949
2825.33	12.5227
2827.98	15.8229
2830.63	19.8369
2833.27	24.1254
2835.92	28.4117
2838.56	34.5023
2841.21	42.0404
2843.85	50.8065
2846.49	59.1928
2849.13	69.229
2851.77	79.2055
2854.41	90.2844
2857.05	100.943
2859.69	111.061
2862.32	120.215
2864.96	127.062
2867.59	133.869
2870.23	140.161
2872.86	143.698
2875.49	148.045
2878.12	151.278
2880.75	156.03
2883.38	159.567
2886.01	162.595
2888.63	165.45
2891.26	168.908
2893.89	171.982
2896.51	176.814
2899.13	182.787
2901.76	189.898
2904.38	198.675
2907	208.574
2909.62	220.207
2912.24	232.465
2914.85	245.67
2917.47	257.606
2920.09	266.948
2922.7	273.949
2925.32	279.739
2927.93	281.598
2930.54	281.812
2933.15	279.171
2935.76	274.583
2938.37	268.604
2940.98	262.076
2943.59	254.608
2946.2	245.741
2948.8	234.989
2951.41	224.328
2954.01	214.391
2956.62	204.491
2959.22	194.068
2961.82	184.62
2964.42	175.655
2967.02	167.274
2969.62	159.663
2972.22	153.673
2974.81	147.527
2977.41	140.956
2980	133.993
2982.6	126.036
2985.19	117.298
2987.78	108.559
2990.38	99.5376
2992.97	90.3991
2995.56	81.3905
2998.14	73.3271
3000.73	66.1964
3003.32	59.2354
3005.91	53.0394
3008.49	48.1164
3011.07	42.2012
3013.66	37.8479
3016.24	33.9767
3018.82	30.6458
3021.4	27.8447
3023.98	25.5341
3026.56	23.0457
3029.14	21.5225
3031.71	20.8856
3034.29	20.6323
3036.87	20.8473
3039.44	22.0347
3042.01	23.6655
3044.59	25.0011
3047.16	26.1163
3049.73	27.6372
3052.3	28.5764
3054.87	29.6659
3057.43	29.0564
3060	29.1344
3062.57	28.0662
3065.13	26.918
3067.7	25.2619
3070.26	23.679
3072.82	21.5759
3075.39	18.0477
3077.95	15.9268
3080.51	12.9523
3083.07	9.68075
3085.63	7.93344
3088.18	4.68864
3090.74	2.07027
3093.29	1.15847
3095.85	0.40942
3098.4	0.0348644
3100.95	0.168456
3103.51	0.65237
3106.06	0.0580621
3108.61	0.461915
3111.16	1.39868
3113.71	1.77471
3116.25	2.43271
3118.8	2.83406
3121.35	2.90834
3123.89	3.26461
3126.44	3.0295
3128.98	3.22868
3131.52	2.85616
3134.06	2.26453
3136.6	1.3015
3139.14	0.578736
3141.68	0.23358
3144.22	-0.838692
3146.76	-2.28662
3149.29	-3.89328