File: data/Raman/poly_smoothed/Thy_40_11_38_1x_45s_532 nm_x100_100%_600 gr_mm_01.txt
#Acq. time (s)=	45
#Accumulations=	2
#Range (cm-¹)=	200...3150
#Windows=	2
#Auto scanning=	Off
#Autofocus=	Off
#Macrospot=	Off
#AutoExposure=	Off
#Spike filter=	Multiple accum.
#Delay time (s)=	0
#Binning=	1
#Readout mode=	Signal
#DeNoise=	Off
#ICS correction=	On
#Dark correction=	Off
#Inst. Process=	Off
#Detector Gain=	Best Dynamic Range
#Detector ADC=	20 kHz
#Detector temperature (°C)=	-69.85
#Instrument=	LabRAM HR Evol
#Detector=	Synapse
#Objective=	x100
#Grating=	600 gr/mm
#ND Filter=	100%
#Laser (nm)=	532
#Hole=	100.021
#Range=	Auto
#Laser Pol.=	No
#Raman. Pol.=	No
#Laser Pol. (°)=	-0.0007625
#Raman Pol. (°)=	89.9995
#Collection=	Microscope
#StageXY=	Marzhauser
#StageZ=	Marzhauser
#X (µm)=	236.4
#Y (µm)=	1684.1
#Z (µm)=	427.6
#Full time(mm:ss)=	3:18
#Project=
#Sample=
#Site=
#Title=	Thy_40_11_38_2x_45s_532 nm_x100_100%_600 gr_mm
#Remark=
#Date=	05.07.2022 12:42
#Acquired=	05.07.2022 12:42:29
#Base:Fit=	10.08.2022 10:01:35
#Base:Sub=	10.08.2022 10:01:52
#Filter:Polynom=	16.08.2022 10:21:53
#AxisType[0]=Intens
#AxisUnit[0]=Cnt
#AxisType[1]=Spectr
#AxisUnit[1]=1/cm
200.43	42.5597
204.059	37.8589
207.688	32.4429
211.314	28.5534
214.941	25.6819
218.564	22.2289
222.186	20.974
225.809	19.8324
229.428	16.1776
233.045	12.937
236.663	11.5792
240.278	10.1964
243.891	9.03707
247.503	8.72251
251.116	9.79039
254.725	8.16203
258.333	6.52825
261.939	7.06432
265.544	6.60999
269.148	6.81643
272.75	5.87448
276.351	6.18965
279.95	5.58224
283.548	5.0825
287.144	5.86181
290.739	6.32935
294.333	7.19919
297.925	7.83715
301.514	7.83025
305.104	8.78806
308.692	9.73761
312.279	10.2061
315.862	9.63835
319.446	8.92423
323.029	9.3007
326.608	9.78984
330.188	11.1697
333.766	11.1688
337.341	10.9634
340.917	9.87393
344.489	7.92197
348.062	8.00186
351.631	6.25013
355.201	3.57581
358.768	3.83002
362.333	3.83404
365.899	2.91208
369.462	3.25518
373.023	3.99806
376.585	4.28471
380.143	4.90093
383.7	5.3633
387.256	5.3744
390.812	4.83414
394.365	6.47877
397.916	7.32229
401.467	7.62846
405.015	6.88066
408.563	8.14741
412.109	8.2936
415.654	8.85733
419.197	8.82584
422.739	8.74582
426.279	7.61641
429.819	6.7253
433.356	5.7268
436.891	5.22312
440.426	4.53235
443.96	4.57656
447.492	6.4701
451.021	6.90216
454.551	7.2302
458.079	6.9132
461.604	8.52773
465.13	9.81238
468.654	10.5695
472.175	11.9567
475.696	11.1884
479.215	12.8967
482.733	14.4033
486.249	14.0993
489.765	15.5118
493.278	16.7664
496.789	17.8019
500.301	18.6382
503.81	20.0731
507.317	20.6649
510.825	20.2334
514.33	20.3915
517.833	21.5858
521.335	21.8252
524.836	22.5617
528.335	22.7003
531.835	22.7201
535.332	22.9694
538.827	22.0636
542.321	20.411
545.814	20.6155
549.305	20.8728
552.795	20.6006
556.282	18.9974
559.769	17.6051
563.255	15.7398
566.739	13.6848
570.223	12.3845
573.705	10.364
577.183	9.99294
580.663	8.44267
584.141	7.17054
587.615	5.44657
591.09	5.59347
594.564	6.10373
598.035	5.71434
601.506	5.66121
604.974	6.4992
608.443	7.53905
611.908	7.8472
615.374	9.27081
618.837	9.606
622.3	10.5011
625.761	11.7632
629.219	13.0037
632.677	15.3265
636.135	16.7191
639.59	17.2972
643.043	19.6497
646.495	20.8479
649.948	21.4348
653.398	23.3835
656.846	24.662
660.293	26.6337
663.738	27.5377
667.183	28.0418
670.626	28.9865
674.067	31.5659
677.508	34.821
680.947	37.0351
684.385	38.9598
687.821	41.9245
691.254	44.1781
694.688	45.2774
698.121	47.1426
701.552	49.3954
704.98	50.5988
708.409	51.693
711.836	52.7952
715.26	52.5535
718.685	53.7995
722.108	54.4703
725.528	55.3033
728.949	57.9546
732.367	57.2195
735.785	57.6855
739.2	58.8258
742.614	59.6936
746.028	60.4512
749.439	61.4418
752.849	64.1708
756.26	67.852
759.667	71.8978
763.073	74.5552
766.477	76.8074
769.883	79.3379
773.285	80.4707
776.686	83.0122
780.085	84.8603
783.484	86.4183
786.881	87.3043
790.276	87.1268
793.671	88.1442
797.064	88.592
800.456	87.2378
803.846	88.3255
807.234	89.7317
810.622	92.5026
814.008	93.5902
817.394	94.0951
820.778	94.6521
824.159	94.9585
827.541	97.0777
830.921	97.1445
834.298	98.6668
837.676	97.7906
841.051	96.4875
844.426	93.2706
847.798	90.77
851.171	86.7406
854.54	82.9692
857.911	78.6902
861.278	73.9985
864.645	69.692
868.01	65.6566
871.373	62.6252
874.735	60.4661
878.097	58.1818
881.457	54.9879
884.815	54.9031
888.172	55.9754
891.528	56.2144
894.882	58.1723
898.237	57.4574
901.589	57.6921
904.94	58.0441
908.289	58.6315
911.635	59.5713
914.982	58.4555
918.328	58.4854
921.672	57.4471
925.015	54.1662
928.357	51.1658
931.698	50.1155
935.035	48.3257
938.373	47.7738
941.71	45.7129
945.044	44.0198
948.378	43.9023
951.709	43.8388
955.041	45.2013
958.372	43.3025
961.699	43.5847
965.027	44.6784
968.352	46.1545
971.676	48.2102
975	48.5763
978.322	47.3421
981.642	46.4202
984.962	47.223
988.28	46.4804
991.596	45.98
994.911	45.3128
998.227	44.8322
1001.54	42.3651
1004.85	40.7349
1008.16	39.46
1011.47	39.9739
1014.78	40.4932
1018.08	40.1867
1021.39	38.5718
1024.69	37.5212
1028	36.9776
1031.3	37.0558
1034.6	36.7644
1037.9	36.2428
1041.19	35.9394
1044.49	35.7826
1047.78	35.3476
1051.08	35.0317
1054.37	32.1345
1057.66	29.6803
1060.95	27.9388
1064.24	28.2656
1067.53	25.7966
1070.81	24.3956
1074.1	23.4819
1077.38	23.6053
1080.66	22.2649
1083.94	21.8333
1087.22	24.2215
1090.5	25.7178
1093.78	26.7584
1097.05	27.1315
1100.33	26.9355
1103.6	27.7737
1106.87	28.3896
1110.14	26.8867
1113.41	25.7945
1116.68	25.3228
1119.95	23.4914
1123.21	21.5068
1126.48	19.9798
1129.74	19.2269
1133	15.6493
1136.26	13.3635
1139.52	12.7155
1142.78	10.5694
1146.04	9.79944
1149.29	7.64772
1152.55	6.25804
1155.8	5.57148
1159.05	4.1146
1162.3	3.8294
1165.55	4.34779
1168.8	6.42262
1172.05	5.96902
1175.29	5.65773
1178.54	4.95262
1181.78	6.33885
1185.02	6.19812
1188.26	5.08915
1191.5	5.22111
1194.74	6.82074
1197.97	8.02425
1201.21	9.61309
1204.44	12.1021
1207.68	14.3553
1210.91	17.3442
1214.14	20.9266
1217.37	24.5888
1220.59	27.3365
1223.82	30.1701
1227.05	31.3373
1230.27	33.5885
1233.49	34.9516
1236.72	37.0859
1239.94	40.7705
1243.16	44.6987
1246.37	45.9694
1249.59	47.9664
1252.8	49.4762
1256.02	52.0049
1259.23	53.877
1262.44	55.2659
1265.66	56.1114
1268.86	58.3363
1272.07	60.5485
1275.28	61.2921
1278.48	63.7015
1281.69	65.076
1284.89	65.2149
1288.09	66.0941
1291.29	66.6944
1294.49	67.0798
1297.69	66.7764
1300.89	66.3614
1304.08	64.6025
1307.28	65.0001
1310.47	64.6668
1313.66	65.0172
1316.85	67.0852
1320.04	65.542
1323.23	66.271
1326.42	65.3646
1329.61	64.9075
1332.79	64.1121
1335.97	62.9604
1339.16	62.1666
1342.34	61.3586
1345.52	61.201
1348.7	59.4809
1351.87	57.0449
1355.05	54.7484
1358.22	52.9407
1361.4	48.9156
1364.57	46.1897
1367.74	43.5703
1370.91	40.3381
1374.08	38.2824
1377.25	35.5487
1380.41	33.8002
1383.58	32.6212
1386.74	32.5667
1389.91	30.3761
1393.07	29.1721
1396.23	26.5569
1399.39	25.1059
1402.55	24.7326
1405.7	24.5177
1408.86	25.1677
1412.01	26.4585
1415.17	27.5067
1418.32	29.6476
1421.47	32.1424
1424.62	36.1436
1427.77	39.9879
1430.91	43.9321
1434.06	47.4857
1437.2	52.1739
1440.35	55.8038
1443.49	57.5779
1446.63	60.7225
1449.77	63.9622
1452.91	65.5304
1456.05	65.5792
1459.18	64.2157
1462.32	62.2567
1465.45	58.1127
1468.59	52.0324
1471.72	47.5173
1474.85	43.117
1477.98	38.1289
1481.1	33.5118
1484.23	28.0415
1487.36	22.3784
1490.48	18.6854
1493.61	15.4227
1496.73	14.1277
1499.85	13.254
1502.97	13.4791
1506.09	12.5345
1509.2	11.8707
1512.32	13.3137
1515.43	14.6478
1518.55	15.2009
1521.66	16.6046
1524.77	18.7045
1527.88	20.4862
1530.99	21.4297
1534.1	21.2696
1537.21	22.5078
1540.31	24.4947
1543.42	25.7418
1546.52	29.194
1549.62	32.3242
1552.72	34.4893
1555.82	35.965
1558.92	38.3213
1562.02	40.7585
1565.11	42.1319
1568.21	45.1418
1571.3	48.5854
1574.39	51.406
1577.49	54.8384
1580.57	57.5003
1583.66	58.4312
1586.75	59.453
1589.84	61.205
1592.92	61.0312
1596.01	61.2659
1599.09	60.8145
1602.17	59.813
1605.25	58.8338
1608.33	57.3666
1611.41	56.6815
1614.49	57.5655
1617.57	57.2791
1620.64	57.2724
1623.72	58.5098
1626.79	58.9524
1629.86	59.1635
1632.93	61.3414
1636	63.3988
1639.07	64.8895
1642.13	67.4178
1645.2	70.9297
1648.26	74.5324
1651.33	76.5036
1654.39	78.3036
1657.45	78.4957
1660.51	76.8326
1663.57	76.4246
1666.63	75.3006
1669.68	72.6628
1672.74	69.9081
1675.79	66.4081
1678.85	61.5359
1681.9	56.8228
1684.95	51.2655
1688	45.9964
1691.05	39.9892
1694.09	35.0186
1697.14	30.7138
1700.18	25.3695
1703.23	20.6679
1706.27	17.0576
1709.31	13.8719
1712.35	9.40783
1715.39	6.61302
1718.43	5.50256
1721.47	3.02553
1724.5	2.25638
1727.54	1.63895
1730.57	1.79151
1733.61	0.645754
1736.64	1.62501
1739.67	2.75549
1742.7	3.53503
1745.72	4.08936
1748.75	5.41212
1751.77	4.25545
1754.8	3.76003
1757.82	3.64367
1760.84	4.06161
1763.87	4.0576
1766.89	3.12691
1769.91	2.76798
1772.92	1.76682
1775.94	1.52344
1778.95	1.13479
1781.97	0.237804
1784.98	-0.177613
1787.99	-0.634634
1791.01	-1.49729
1794.01	-1.41252
1797.02	-1.65225
1800.03	-1.09099
1803.04	-0.888225
1806.04	-0.361794
1809.05	-0.481826
1812.05	0.188273
1815.05	0.509245
1818.05	0.896945
1821.05	1.21498
1824.05	2.11331
1827.05	1.63534
1830.04	2.05823
1833.04	2.91022
1836.03	3.2369
1839.03	3.48947
1842.02	3.4553
1845.01	4.60217
1848	5.20097
1850.99	4.91794
1853.97	5.55299
1856.96	5.74423
1859.94	5.69722
1862.93	5.59703
1865.91	5.1482
1868.89	4.80572
1871.87	3.62105
1874.85	2.66816
1877.83	2.16753
1880.81	2.49771
1882.57	2.50764
1885.56	3.18584
1888.55	3.30872
1891.54	3.30829
1894.52	3.89594
1897.51	4.6811
1900.49	5.19069
1903.47	6.50809
1906.45	7.46029
1909.43	7.23137
1912.41	7.9802
1915.39	8.53375
1918.37	8.94443
1921.34	8.2602
1924.32	8.53073
1927.29	9.28949
1930.26	9.5085
1933.23	8.06916
1936.2	7.86151
1939.17	7.17899
1942.14	6.17284
1945.11	5.43005
1948.07	6.44248
1951.04	6.04328
1954	5.74288
1956.96	5.6771
1959.93	5.91678
1962.89	5.17999
1965.85	5.34504
1968.8	5.91001
1971.76	5.87155
1974.72	6.02482
1977.67	6.34176
1980.63	5.91292
1983.58	5.87044
1986.53	5.54833
1989.48	5.66472
1992.43	5.59552
1995.38	6.27514
1998.32	6.64133
2001.27	5.99693
2004.22	6.57219
2007.16	7.16354
2010.1	6.84302
2013.04	6.87966
2015.98	6.89756
2018.92	7.2451
2021.86	7.78756
2024.8	7.97811
2027.74	9.18971
2030.67	9.80721
2033.61	9.33924
2036.54	9.35683
2039.47	8.9317
2042.4	9.37298
2045.33	9.5694
2048.26	9.39653
2051.19	9.37535
2054.12	10.003
2057.04	9.26787
2059.97	10.2082
2062.89	10.6182
2065.81	10.2444
2068.73	11.058
2071.65	11.6887
2074.57	12.6343
2077.49	14.1086
2080.41	15.4385
2083.32	16.3396
2086.24	17.8319
2089.15	19.5996
2092.07	21.7009
2094.98	23.7461
2097.89	25.9774
2100.8	28.1424
2103.71	29.2152
2106.61	30.579
2109.52	32.5183
2112.43	35.3264
2115.33	37.6224
2118.23	39.4293
2121.13	41.5201
2124.04	44.7852
2126.94	48.3175
2129.83	51.0184
2132.73	54.4996
2135.63	57.7248
2138.53	61.138
2141.42	64.5681
2144.31	67.601
2147.21	70.8044
2150.1	73.1051
2152.99	75.8873
2155.88	78.5293
2158.77	81.6034
2161.65	83.9622
2164.54	85.4628
2167.43	86.106
2170.31	87.2079
2173.19	87.3587
2176.07	85.7822
2178.96	84.75
2181.84	84.1307
2184.72	82.2025
2187.59	80.266
2190.47	78.1555
2193.35	76.6808
2196.22	75.0911
2199.09	73.0478
2201.97	69.6504
2204.84	67.8661
2207.71	64.415
2210.58	60.5206
2213.45	57.4693
2216.31	54.0779
2219.18	51.1451
2222.05	48.909
2224.91	46.0515
2227.78	44.3941
2230.64	42.8258
2233.5	40.2124
2236.36	38.4223
2239.22	36.7938
2242.08	35.069
2244.93	33.1345
2247.79	31.5628
2250.64	30.2046
2253.5	29.0418
2256.35	28.3576
2259.2	27.0628
2262.05	25.9128
2264.9	25.4172
2267.75	24.0661
2270.6	21.9592
2273.45	20.7036
2276.29	18.5257
2279.14	17.3858
2281.98	15.3926
2284.82	13.4946
2287.66	12.4992
2290.5	11.8098
2293.34	9.42137
2296.18	8.73416
2299.02	9.67406
2301.86	10.4494
2304.69	10.7721
2307.53	11.3437
2310.36	11.2726
2313.19	11.3604
2316.02	12.4148
2318.85	12.7949
2321.68	13.1971
2324.51	12.5163
2327.34	11.8562
2330.16	11.3357
2332.99	10.6999
2335.81	10.0137
2338.64	8.23046
2341.46	7.77339
2344.28	7.02025
2347.1	6.33373
2349.92	4.55381
2352.74	2.99821
2355.55	1.38212
2358.37	0.538566
2361.19	-0.97463
2364	-1.57866
2366.81	-1.36443
2369.62	-0.0833175
2372.44	-0.737868
2375.24	-1.68713
2378.05	-0.619791
2380.86	-0.356313
2383.67	0.682846
2386.47	1.29722
2389.28	1.60471
2392.08	1.22581
2394.89	1.12748
2397.69	1.63247
2400.49	1.9252
2403.29	2.54427
2406.09	3.05348
2408.88	3.98285
2411.68	5.01903
2414.48	5.76194
2417.27	5.46028
2420.06	5.3009
2422.86	4.44859
2425.65	3.88193
2428.44	4.18867
2431.23	4.49492
2434.02	4.16354
2436.81	4.8924
2439.59	5.31034
2442.38	5.39272
2445.16	5.90169
2447.95	6.34089
2450.73	6.29423
2453.51	7.06144
2456.29	6.9237
2459.07	6.91047
2461.85	7.14713
2464.63	7.09345
2467.4	6.40015
2470.18	6.59856
2472.95	5.92147
2475.73	6.96636
2478.5	7.19254
2481.27	6.33335
2484.04	5.64693
2486.81	5.05766
2489.58	3.74508
2492.35	3.8851
2495.12	3.6432
2497.88	3.35154
2500.65	3.03037
2503.41	2.29926
2506.17	2.6964
2508.94	2.64113
2511.7	1.54914
2514.46	2.46567
2517.22	2.10073
2519.97	2.37139
2522.73	2.49519
2525.49	2.06211
2528.24	1.98129
2530.99	1.91496
2533.75	1.68412
2536.5	1.27723
2539.25	1.49276
2542	1.4267
2544.75	2.50148
2547.5	2.51351
2550.24	2.77368
2552.99	3.99269
2555.74	4.47014
2558.48	4.65922
2561.22	4.79039
2563.96	5.10756
2566.71	5.39693
2569.45	6.12605
2572.18	5.8691
2574.92	6.23591
2577.66	5.19899
2580.4	5.93978
2583.13	5.80709
2585.87	5.41767
2588.6	5.10963
2591.33	4.59742
2594.06	4.0421
2596.79	3.8108
2599.52	3.11651
2602.25	3.13451
2604.98	2.18996
2607.71	2.45425
2610.43	1.78058
2613.16	1.80787
2615.88	2.06015
2618.6	2.31162
2621.32	1.9828
2624.04	1.50673
2626.76	1.29411
2629.48	2.34662
2632.2	2.65076
2634.92	2.80311
2637.63	2.67793
2640.35	2.51823
2643.06	2.82066
2645.77	4.15582
2648.49	5.06927
2651.2	5.00867
2653.91	5.24292
2656.62	5.02532
2659.33	4.93726
2662.03	4.23453
2664.74	4.56442
2667.44	4.03445
2670.15	3.44863
2672.85	3.04225
2675.55	3.28435
2678.26	2.96719
2680.96	3.22923
2683.66	2.80413
2686.35	2.44426
2689.05	1.55909
2691.75	1.83082
2694.44	1.8467
2697.14	1.61539
2699.83	2.25542
2702.52	2.37914
2705.22	2.76095
2707.91	2.86851
2710.6	4.54344
2713.29	5.02647
2715.97	4.96541
2718.66	5.2828
2721.35	5.0325
2724.03	4.6243
2726.72	4.44589
2729.4	5.31907
2732.08	5.89367
2734.76	5.95996
2737.44	6.54248
2740.12	7.58465
2742.8	7.36396
2745.48	7.03645
2748.16	6.20201
2750.83	5.73988
2753.51	4.94314
2756.18	5.19486
2758.85	5.30089
2761.53	4.53689
2764.2	4.10597
2766.87	2.84926
2769.54	2.34305
2772.2	2.39502
2774.87	2.01355
2777.54	1.8451
2780.2	0.691823
2782.87	0.716698
2785.53	0.052198
2788.19	-0.294186
2790.85	-1.06498
2793.51	-0.690158
2796.17	-0.564723
2798.83	-1.07715
2801.49	-0.776298
2804.15	-0.478885
2806.8	-0.66041
2809.46	-0.650969
2812.11	0.630207
2814.76	0.790653
2817.42	1.40713
2820.07	2.74119
2822.72	4.09277
2825.37	7.14195
2828.02	9.70125
2830.66	12.2953
2833.31	16.1374
2835.96	20.0307
2838.6	23.3525
2841.24	27.1892
2843.89	32.0968
2846.53	36.998
2849.17	43.382
2851.81	49.4493
2854.45	55.9145
2857.09	62.0356
2859.72	69.1334
2862.36	75.2957
2865	81.207
2867.63	86.7019
2870.26	91.5925
2872.9	96.4309
2875.53	101.056
2878.16	103.941
2880.79	106.715
2883.42	110.275
2886.05	114.086
2888.67	118.022
2891.3	121.842
2893.92	125.567
2896.55	129.684
2899.17	135.094
2901.79	140.939
2904.42	148.371
2907.04	157.038
2909.66	167.566
2912.27	178.953
2914.89	189.498
2917.51	200.25
2920.13	209.098
2922.74	217.608
2925.35	224.501
2927.97	228.984
2930.58	231.302
2933.19	232.227
2935.8	231.89
2938.41	230.072
2941.02	226.667
2943.63	220.648
2946.24	214.619
2948.84	206.253
2951.45	197.263
2954.05	187.518
2956.65	178.45
2959.26	169.264
2961.86	160.307
2964.46	151.412
2967.06	143.323
2969.66	135.648
2972.25	128.068
2974.85	120.592
2977.45	112.574
2980.04	105.27
2982.64	97.0276
2985.23	88.538
2987.82	80.2511
2990.41	72.0431
2993	63.9993
2995.59	56.7792
2998.18	50.5149
3000.77	45.1307
3003.36	40.1222
3005.94	34.7612
3008.53	28.8244
3011.11	23.867
3013.69	20.0555
3016.28	17.8134
3018.86	15.6612
3021.44	14.7218
3024.02	13.1317
3026.6	12.1014
3029.18	10.8376
3031.75	10.8345
3034.33	10.7978
3036.9	11.4642
3039.48	11.9227
3042.05	12.7281
3044.62	13.2897
3047.19	13.6955
3049.77	14.3628
3052.34	14.5259
3054.9	14.6593
3057.47	14.3171
3060.04	13.7488
3062.61	13.9724
3065.17	13.6386
3067.74	12.3991
3070.3	10.2701
3072.86	8.67516
3075.42	7.52865
3077.99	6.54423
3080.54	5.28893
3083.1	4.39976
3085.66	2.60458
3088.22	1.99993
3090.78	1.26001
3093.33	1.18067
3095.89	1.03232
3098.44	1.44863
3100.99	1.61849
3103.54	2.2174
3106.1	2.8742
3108.65	3.61539
3111.2	4.14169
3113.74	5.15523
3116.29	6.22867
3118.84	7.30882
3121.38	7.66863
3123.93	8.76267
3126.47	10.0016
3129.01	9.73485
3131.56	10.3851
3134.1	10.399
3136.64	10.9463
3139.18	11.1388
3141.72	11.2906
3144.26	10.846
3146.79	10.5757
3149.33	9.47799