File: data/Raman/poly_smoothed/Thy_20_09_47_1x_45s_532 nm_x100_100%_600 gr_mm_01.txt
#Acq. time (s)=	45
#Accumulations=	2
#Range (cm-¹)=	200...3150
#Windows=	2
#Auto scanning=	Off
#Autofocus=	Off
#Macrospot=	Off
#AutoExposure=	Off
#Spike filter=	Multiple accum.
#Delay time (s)=	0
#Binning=	1
#Readout mode=	Signal
#DeNoise=	Off
#ICS correction=	On
#Dark correction=	Off
#Inst. Process=	Off
#Detector Gain=	Best Dynamic Range
#Detector ADC=	20 kHz
#Detector temperature (°C)=	-69.85
#Instrument=	LabRAM HR Evol
#Detector=	Synapse
#Objective=	x100
#Grating=	600 gr/mm
#ND Filter=	100%
#Laser (nm)=	532
#Hole=	100.021
#Range=	Auto
#Laser Pol.=	No
#Raman. Pol.=	No
#Laser Pol. (°)=	-0.0007625
#Raman Pol. (°)=	89.9995
#Collection=	Microscope
#StageXY=	Marzhauser
#StageZ=	Marzhauser
#X (µm)=	-5930.1
#Y (µm)=	2848.7
#Z (µm)=	-223.8
#Full time(mm:ss)=	3:19
#Project=
#Sample=
#Site=
#Title=	Thy_20_09_47_2x_45s_532 nm_x100_100%_600 gr_mm
#Remark=
#Date=	29.06.2022 13:56
#Acquired=	29.06.2022 13:56:36
#Base:Fit=	10.08.2022 09:52:02
#Base:Fit=	10.08.2022 09:52:12
#Base:Sub=	10.08.2022 09:54:21
#Filter:Polynom=	16.08.2022 10:24:04
#AxisType[0]=Intens
#AxisUnit[0]=Cnt
#AxisType[1]=Spectr
#AxisUnit[1]=1/cm
200.523	31.8099
204.154	27.6758
207.781	21.972
211.409	16.8187
215.034	13.7534
218.659	11.2135
222.281	8.95133
225.903	5.99954
229.522	4.13643
233.14	4.44044
236.756	3.48552
240.373	2.85304
243.986	2.84019
247.598	3.63663
251.208	3.6187
254.818	2.74002
258.427	3.03505
262.034	4.53406
265.638	4.77768
269.242	4.44026
272.844	5.46086
276.445	7.08882
280.044	7.89162
283.642	9.97776
287.238	11.7048
290.833	12.1436
294.425	12.9423
298.017	14.4731
301.608	14.1889
305.198	14.4543
308.786	14.9008
312.371	13.8074
315.956	13.1498
319.54	14.3952
323.122	13.7816
326.701	12.476
330.281	11.6727
333.857	13.0971
337.434	12.1219
341.008	10.436
344.582	11.8348
348.153	11.6658
351.724	10.2834
355.292	9.73031
358.861	10.7002
362.426	11.859
365.99	12.7353
369.555	14.5953
373.116	15.0679
376.676	14.4542
380.236	14.6288
383.793	12.5899
387.349	12.2609
390.903	12.1418
394.456	12.598
398.007	11.7168
401.56	9.46927
405.108	7.8195
408.656	7.97866
412.202	5.58914
415.746	6.04214
419.29	7.02142
422.831	8.59021
426.37	8.9607
429.909	9.91104
433.447	9.75827
436.983	8.30898
440.519	7.12005
444.052	6.76534
447.583	6.83706
451.114	7.33159
454.643	8.38073
458.169	8.12877
461.696	7.16337
465.222	8.28847
468.744	8.55683
472.267	9.5061
475.787	12.0018
479.307	12.5318
482.823	12.1717
486.341	13.1467
489.855	14.1071
493.37	14.6811
496.881	14.9168
500.391	17.4015
503.902	18.6078
507.409	20.0435
510.915	21.2781
514.42	21.3861
517.925	21.0984
521.427	18.6817
524.928	17.9007
528.427	17.1933
531.925	17.3714
535.422	15.2521
538.917	14.2719
542.411	12.79
545.903	13.4388
549.395	12.8439
552.884	11.9278
556.373	10.817
559.86	10.5919
563.346	9.39866
566.831	8.87859
570.314	8.08887
573.794	8.48396
577.274	6.25528
580.754	5.85442
584.23	5.24596
587.706	6.97285
591.181	7.14911
594.653	6.68079
598.126	7.00138
601.595	6.04206
605.065	5.03029
608.532	6.65014
611.999	7.4512
615.463	8.22026
618.928	8.58052
622.389	9.32088
625.851	10.553
629.31	13.13
632.767	13.4202
636.223	14.3575
639.68	14.659
643.134	14.573
646.586	16.2586
650.037	17.1631
653.486	18.395
656.936	18.6828
660.383	19.53
663.829	20.4266
667.273	21.2952
670.716	20.3829
674.158	22.5306
677.598	23.1562
681.035	23.8226
684.473	24.9785
687.909	25.3084
691.344	26.314
694.778	29.404
698.211	31.7689
701.64	33.5274
705.07	34.1777
708.498	35.4168
711.924	36.7359
715.35	38.0865
718.774	38.5893
722.196	40.5405
725.618	42.1803
729.037	44.4226
732.456	46.5317
735.873	47.2879
739.289	48.1319
742.703	49.7456
746.116	50.8073
749.529	52.4907
752.938	52.8768
756.347	54.6867
759.756	56.9233
763.162	57.5799
766.567	59.4192
769.97	60.844
773.372	62.3061
776.773	64.1322
780.174	66.2814
783.573	67.9519
786.97	69.8934
790.365	70.7636
793.76	71.6449
797.153	72.5067
800.543	75.3943
803.933	76.4696
807.322	78.3983
810.71	79.3232
814.097	79.6158
817.483	80.6506
820.865	81.351
824.248	81.0555
827.629	80.4841
831.008	78.5004
834.387	76.4281
837.765	73.6514
841.139	71.8615
844.514	70.2462
847.886	66.7398
851.259	63.7529
854.629	60.6493
857.997	57.462
861.366	54.2257
864.732	53.6219
868.098	52.3933
871.461	49.7768
874.823	47.5626
878.184	47.5703
881.545	46.7714
884.903	46.6524
888.26	46.2357
891.616	44.86
894.97	44.6715
898.323	46.4116
901.675	48.2568
905.026	48.0941
908.375	47.0323
911.723	46.7343
915.07	45.4026
918.415	44.9496
921.76	43.9918
925.103	42.8309
928.443	42.3962
931.783	39.6755
935.123	38.1803
938.461	38.3188
941.796	36.2551
945.131	34.4173
948.465	32.0372
951.797	30.2393
955.128	29.3853
958.457	28.0181
961.786	26.2439
965.113	25.9215
968.44	25.9794
971.763	25.9217
975.086	26.2662
978.409	27.8495
981.729	27.6591
985.048	26.726
988.367	24.7038
991.683	22.132
994.998	22.0423
998.312	20.8801
1001.62	20.8411
1004.94	20.3383
1008.25	20.9003
1011.56	19.6924
1014.86	20.1964
1018.17	20.2914
1021.48	19.6786
1024.78	18.566
1028.08	17.6431
1031.38	17.9056
1034.68	17.8444
1037.98	17.8595
1041.28	17.0957
1044.57	19.657
1047.87	20.1714
1051.16	19.8555
1054.45	19.8262
1057.75	19.2375
1061.04	16.6925
1064.32	14.0982
1067.61	13.516
1070.9	11.3667
1074.18	10.2155
1077.47	10.1871
1080.75	10.4006
1084.03	9.59393
1087.31	10.8105
1090.59	11.3546
1093.86	10.9545
1097.14	12.4838
1100.41	13.781
1103.69	15.2887
1106.96	15.207
1110.23	13.9071
1113.5	14.0425
1116.77	13.8095
1120.03	13.5634
1123.3	12.9132
1126.56	11.7916
1129.83	10.1912
1133.09	8.75405
1136.35	6.97011
1139.61	5.76995
1142.86	4.11244
1146.12	4.25415
1149.38	5.39859
1152.63	4.5508
1155.88	4.86755
1159.14	6.87132
1162.39	6.19624
1165.63	7.85881
1168.88	11.2088
1172.13	11.8689
1175.38	12.3205
1178.62	14.5573
1181.86	16.4547
1185.1	15.5963
1188.34	16.2249
1191.58	17.4658
1194.82	19.0015
1198.06	18.2055
1201.29	19.5103
1204.53	19.1178
1207.76	18.5836
1210.99	19.7327
1214.22	20.6911
1217.45	22.6713
1220.68	25.1901
1223.91	28.0785
1227.13	30.2102
1230.36	32.945
1233.58	35.5232
1236.8	38.3953
1240.02	39.9662
1243.24	42.2616
1246.46	46.4457
1249.67	48.4614
1252.89	50.451
1256.1	51.3283
1259.32	53.6443
1262.53	55.1525
1265.74	58.3077
1268.95	60.3502
1272.15	62.0062
1275.36	62.1721
1278.57	62.5952
1281.77	63.3978
1284.97	63.0429
1288.18	64.8674
1291.38	67.1946
1294.58	69.0355
1297.78	70.0886
1300.97	70.2006
1304.17	70.3065
1307.36	71.6916
1310.55	72.8093
1313.75	73.2644
1316.94	73.4735
1320.13	73.5236
1323.32	73.7326
1326.5	72.5082
1329.69	71.0149
1332.87	68.1451
1336.06	68.2847
1339.24	68.8249
1342.42	67.6365
1345.6	67.0905
1348.78	63.5004
1351.96	62.6673
1355.13	61.1703
1358.31	59.4599
1361.48	59.0379
1364.65	57.8811
1367.82	57.2454
1370.99	56.8447
1374.16	55.317
1377.33	52.3115
1380.5	50.7371
1383.66	50.4198
1386.83	49.4979
1389.99	47.5201
1393.15	47.5359
1396.31	46.1753
1399.47	45.6522
1402.63	44.8487
1405.78	43.8152
1408.94	44.0497
1412.1	44.4726
1415.25	47.1201
1418.4	48.8733
1421.55	52.3881
1424.7	55.4489
1427.85	58.1059
1431	63.4486
1434.14	67.6811
1437.29	70.9047
1440.43	74.6761
1443.57	75.6377
1446.71	77.946
1449.85	76.4347
1452.99	76.0379
1456.13	74.2652
1459.26	72.7191
1462.4	70.7194
1465.54	67.3307
1468.67	62.7072
1471.8	59.7354
1474.93	56.1792
1478.06	50.5436
1481.19	45.6858
1484.31	40.264
1487.44	38.1619
1490.56	34.2661
1493.69	32.202
1496.81	30.1338
1499.93	29.0925
1503.05	27.6771
1506.17	27.4295
1509.28	27.2054
1512.4	26.0775
1515.52	26.6264
1518.63	27.4474
1521.74	28.3193
1524.85	29.3078
1527.96	31.4506
1531.07	33.2897
1534.18	35.3152
1537.29	38.7714
1540.39	41.6289
1543.5	43.8829
1546.6	47.0156
1549.7	49.7937
1552.8	51.8344
1555.9	53.3136
1559	55.722
1562.1	58.1751
1565.19	61.3106
1568.29	63.5485
1571.38	65.4683
1574.47	67.8787
1577.56	68.8548
1580.66	70.8858
1583.74	73.293
1586.83	74.3429
1589.92	75.5568
1593.01	76.1247
1596.09	76.7268
1599.17	76.4137
1602.25	74.9117
1605.34	72.8626
1608.41	71.1257
1611.49	69.5814
1614.57	67.6059
1617.65	64.2694
1620.72	62.7402
1623.79	63.0157
1626.87	62.1915
1629.94	61.8294
1633.01	60.624
1636.08	60.4662
1639.15	62.4676
1642.21	63.2962
1645.28	64.5329
1648.34	67.2013
1651.41	68.505
1654.47	71.1306
1657.53	71.4352
1660.59	69.2369
1663.65	66.9896
1666.71	65.0805
1669.76	62.7145
1672.82	58.5394
1675.87	53.8522
1678.93	50.6123
1681.98	45.7725
1685.03	41.825
1688.08	37.5493
1691.13	32.8536
1694.17	28.2254
1697.22	25.7636
1700.27	22.2604
1703.31	19.1458
1706.35	16.1891
1709.39	14.6357
1712.43	13.43
1715.47	13.4683
1718.51	12.7064
1721.55	12.0727
1724.58	11.5274
1727.62	10.6541
1730.65	8.44173
1733.68	6.62291
1736.72	6.62969
1739.74	5.76113
1742.77	4.72621
1745.8	3.94078
1748.83	4.1241
1751.85	4.25287
1754.88	5.15411
1757.9	4.56938
1760.92	3.68529
1763.95	3.47629
1766.96	2.38903
1769.98	1.68821
1773	3.0567
1776.02	3.24148
1779.03	2.20279
1782.05	2.75655
1785.06	3.68909
1788.07	4.37475
1791.08	4.83175
1794.09	4.68203
1797.1	5.08163
1800.11	5.10669
1803.12	4.60126
1806.12	4.22127
1809.12	4.1347
1812.13	3.8878
1815.13	4.52061
1818.13	4.44059
1821.13	4.53934
1824.13	5.35405
1827.13	5.37603
1830.12	5.02296
1833.12	3.81809
1836.11	3.93047
1839.1	2.9592
1842.09	3.83911
1845.09	3.88008
1848.08	3.87479
1851.06	4.13769
1854.05	4.12667
1857.04	4.14268
1860.02	3.69555
1863.01	4.19928
1865.99	5.34675
1868.97	4.65852
1871.95	4.61665
1874.93	3.64295
1877.91	4.01032
1880.89	3.91289
1882.46	4.36123
1885.45	4.79047
1888.43	4.10011
1891.42	3.8597
1894.41	3.61638
1897.39	2.842
1900.37	1.58825
1903.36	1.26914
1906.34	0.721048
1909.32	0.479368
1912.29	0.0112668
1915.27	0.256686
1918.25	0.72395
1921.23	0.709211
1924.2	0.948104
1927.17	0.523123
1930.15	0.800654
1933.12	1.8538
1936.09	2.69993
1939.06	3.29679
1942.02	2.97683
1944.99	2.79879
1947.96	3.20461
1950.92	4.04821
1953.88	4.66467
1956.85	4.91333
1959.81	4.60885
1962.77	4.25686
1965.73	4.47839
1968.69	4.65493
1971.64	3.63182
1974.6	3.54828
1977.55	2.75511
1980.51	2.92071
1983.46	3.08214
1986.41	3.54007
1989.36	4.44629
1992.31	4.7221
1995.26	5.09373
1998.21	4.25768
2001.15	4.49434
2004.1	5.36188
2007.04	4.82182
2009.99	5.38607
2012.93	6.06495
2015.87	5.44025
2018.81	5.70204
2021.75	6.52147
2024.68	6.91315
2027.62	7.65176
2030.56	8.0306
2033.49	7.28624
2036.42	6.648
2039.36	6.62269
2042.29	5.67534
2045.22	5.89906
2048.14	5.92783
2051.07	6.14731
2054	6.61047
2056.93	7.19763
2059.85	7.1126
2062.77	7.19308
2065.7	7.80055
2068.62	8.23281
2071.54	7.85012
2074.46	8.03136
2077.38	8.99667
2080.29	9.03092
2083.21	10.2546
2086.12	10.9335
2089.04	10.5028
2091.95	10.6536
2094.86	11.2295
2097.77	11.3838
2100.68	10.8767
2103.59	10.2224
2106.5	10.177
2109.41	10.0076
2112.31	9.48357
2115.21	10.4415
2118.12	10.936
2121.02	10.5266
2123.92	12.4213
2126.82	14.0374
2129.72	15.6732
2132.62	18.6035
2135.51	20.1312
2138.41	22.1849
2141.31	23.9846
2144.2	25.9496
2147.09	28.3754
2149.98	31.092
2152.87	32.2178
2155.76	34.233
2158.65	35.298
2161.54	35.9314
2164.43	37.9467
2167.31	39.1969
2170.2	39.0163
2173.08	38.4427
2175.96	38.6439
2178.84	37.7498
2181.72	34.7069
2184.6	34.2603
2187.48	33.8281
2190.36	31.112
2193.23	30.5343
2196.11	29.6072
2198.98	27.9852
2201.85	26.1636
2204.72	24.6118
2207.59	23.7676
2210.46	22.3038
2213.33	22.4749
2216.2	20.9489
2219.07	20.193
2221.93	18.4261
2224.8	17.6555
2227.66	17.0336
2230.52	16.8242
2233.39	16.9022
2236.25	16.5052
2239.1	16.1068
2241.96	15.8087
2244.82	14.1998
2247.68	13.9659
2250.53	13.1302
2253.38	13.3281
2256.24	13.2541
2259.09	12.5884
2261.94	10.9704
2264.79	10.771
2267.64	9.41642
2270.49	9.54559
2273.33	9.74573
2276.18	9.25669
2279.02	9.43588
2281.87	7.95694
2284.71	6.1012
2287.55	5.6862
2290.39	4.86546
2293.23	3.97537
2296.07	3.5794
2298.91	4.19245
2301.74	4.49784
2304.58	5.65667
2307.41	6.53774
2310.25	7.07116
2313.08	7.83227
2315.91	7.75036
2318.74	8.41849
2321.57	8.90746
2324.4	8.62036
2327.23	8.40483
2330.05	8.48875
2332.88	7.48903
2335.7	8.17205
2338.52	8.11695
2341.35	8.26845
2344.17	7.37793
2346.99	6.00917
2349.81	4.49032
2352.62	3.43642
2355.44	2.88691
2358.26	2.43782
2361.07	2.33688
2363.89	3.09964
2366.7	4.19165
2369.51	5.76917
2372.32	5.82244
2375.13	5.24754
2377.94	4.78108
2380.75	4.61182
2383.56	4.52077
2386.36	4.16643
2389.17	3.96575
2391.97	3.62931
2394.77	3.81829
2397.58	3.49734
2400.38	3.26051
2403.18	4.00749
2405.97	4.49821
2408.77	5.94867
2411.57	6.96767
2414.37	7.30929
2417.16	7.86767
2419.95	7.92933
2422.75	9.0423
2425.54	9.9134
2428.33	11.5019
2431.12	12.0687
2433.91	12.8222
2436.7	12.5874
2439.48	11.6177
2442.27	10.8539
2445.05	10.819
2447.84	10.1912
2450.62	10.3236
2453.4	9.201
2456.18	7.55893
2458.96	7.17916
2461.74	6.23223
2464.52	5.2458
2467.29	4.08464
2470.07	3.56926
2472.85	3.27855
2475.62	3.28016
2478.39	2.23388
2481.16	0.990062
2483.93	0.190752
2486.7	0.134897
2489.47	0.225647
2492.24	0.00859818
2495.01	0.41376
2497.77	0.752048
2500.54	-0.159524
2503.3	-0.0272829
2506.06	-0.020579
2508.83	1.42497
2511.59	2.77373
2514.35	3.37282
2517.11	3.34394
2519.86	3.53095
2522.62	3.62217
2525.38	4.30419
2528.13	4.96883
2530.89	5.26352
2533.64	5.77778
2536.39	6.78525
2539.14	6.99919
2541.89	7.40563
2544.64	7.76514
2547.39	7.46047
2550.14	8.73704
2552.88	9.41542
2555.63	9.56568
2558.37	9.5115
2561.11	8.6727
2563.86	8.59782
2566.6	8.89542
2569.34	8.52465
2572.08	7.9527
2574.82	6.62996
2577.55	6.26661
2580.29	5.08758
2583.02	4.17028
2585.76	3.42413
2588.49	3.41106
2591.22	2.91124
2593.96	2.50815
2596.69	2.37905
2599.42	2.71335
2602.14	2.57924
2604.87	2.80926
2607.6	2.87775
2610.32	3.0021
2613.05	2.69818
2615.77	3.88997
2618.49	4.00242
2621.22	4.53555
2623.94	4.84873
2626.66	5.26012
2629.37	6.02525
2632.09	6.86736
2634.81	5.91597
2637.53	5.34656
2640.24	5.6851
2642.96	5.95223
2645.67	5.6171
2648.38	6.90052
2651.09	6.61792
2653.8	7.14596
2656.51	6.9631
2659.22	6.45566
2661.93	6.43771
2664.63	5.74586
2667.34	5.51377
2670.04	5.15911
2672.75	4.54395
2675.45	3.52598
2678.15	3.36947
2680.85	4.49424
2683.55	4.32039
2686.25	4.60868
2688.94	4.80428
2691.64	4.94552
2694.34	5.64614
2697.03	4.30164
2699.73	5.35173
2702.42	5.89451
2705.11	6.49184
2707.8	6.71818
2710.49	7.3287
2713.18	9.03808
2715.87	9.95958
2718.55	10.3198
2721.24	11.701
2723.93	11.6163
2726.61	11.6333
2729.29	12.2901
2731.98	11.4652
2734.66	11.2334
2737.34	10.8766
2740.02	10.584
2742.7	9.61364
2745.37	9.39056
2748.05	8.72213
2750.72	7.88069
2753.4	7.25604
2756.07	7.49085
2758.75	6.17587
2761.42	4.78529
2764.09	4.04412
2766.76	3.34878
2769.43	2.18871
2772.1	1.6764
2774.76	1.78411
2777.43	2.32505
2780.1	1.76911
2782.76	2.45161
2785.42	2.47475
2788.09	2.85862
2790.75	2.33335
2793.41	3.07774
2796.07	3.22889
2798.73	2.79044
2801.39	3.49476
2804.04	3.30155
2806.7	2.34165
2809.35	2.12276
2812.01	2.85117
2814.66	2.19459
2817.31	2.51831
2819.96	4.11624
2822.61	4.42184
2825.26	5.04012
2827.91	6.78052
2830.56	9.47515
2833.21	11.0662
2835.85	13.317
2838.5	17.1293
2841.14	21.262
2843.78	25.6093
2846.42	31.5236
2849.06	36.6558
2851.71	43.0909
2854.34	50.1318
2856.98	57.0175
2859.62	64.5241
2862.26	70.8198
2864.89	75.6172
2867.53	80.7776
2870.16	84.3484
2872.79	88.2491
2875.42	91.766
2878.05	94.6885
2880.68	97.2084
2883.31	100.24
2885.94	102.799
2888.57	104.197
2891.19	106.395
2893.82	108.564
2896.44	110.965
2899.07	114.293
2901.69	119.304
2904.31	123.925
2906.93	130.039
2909.55	138.029
2912.17	145.36
2914.79	154.456
2917.41	162.058
2920.02	168.201
2922.64	174.049
2925.25	177.725
2927.86	180.021
2930.48	181.384
2933.09	182.113
2935.7	180.508
2938.31	178.24
2940.92	175.159
2943.53	170.03
2946.13	165.062
2948.74	159.118
2951.34	152.437
2953.95	144.439
2956.55	137.777
2959.15	132.117
2961.75	124.484
2964.35	119.447
2966.95	113.857
2969.55	108.441
2972.15	104.703
2974.75	100.53
2977.34	94.4228
2979.94	89.1398
2982.53	82.4723
2985.13	75.6955
2987.72	70.0338
2990.31	63.3079
2992.9	57.0075
2995.49	51.9059
2998.08	45.823
3000.67	39.7336
3003.25	35.7127
3005.84	31.3216
3008.42	26.66
3011.01	22.6503
3013.59	19.5825
3016.17	16.2625
3018.76	15.1793
3021.34	14.6246
3023.92	14.0712
3026.49	12.9136
3029.07	12.5897
3031.65	12.2272
3034.23	11.6666
3036.8	11.6704
3039.38	12.0267
3041.95	11.9281
3044.52	12.4081
3047.09	12.3134
3049.66	12.6632
3052.23	12.4024
3054.8	12.0331
3057.37	12.0189
3059.94	11.905
3062.5	10.9118
3065.07	10.2528
3067.63	9.44935
3070.2	7.82447
3072.76	6.71715
3075.32	6.03687
3077.88	4.99155
3080.44	4.84768
3083	4.59499
3085.56	3.10686
3088.12	2.2085
3090.67	2.05777
3093.23	1.05052
3095.78	0.0641803
3098.34	0.161924
3100.89	-0.31841
3103.44	-0.370244
3105.99	-0.63217
3108.54	-1.02489
3111.09	0.0278601
3113.64	0.0743392
3116.19	0.488295
3118.74	0.762932
3121.28	0.926262
3123.83	1.32658
3126.37	1.12141
3128.91	1.22526
3131.46	1.50031
3134	2.41246
3136.54	3.15097
3139.08	4.07777
3141.62	5.37901
3144.16	6.58601
3146.69	7.67185
3149.23	8.45607