File: data/Raman/poly_smoothed/Thy_20_09_22_1x_45s_532 nm_x100_100%_600 gr_mm_01.txt
#Acq. time (s)=	45
#Accumulations=	2
#Range (cm-¹)=	200...3150
#Windows=	2
#Auto scanning=	Off
#Autofocus=	Off
#Macrospot=	Off
#AutoExposure=	Off
#Spike filter=	Multiple accum.
#Delay time (s)=	0
#Binning=	1
#Readout mode=	Signal
#DeNoise=	Off
#ICS correction=	On
#Dark correction=	Off
#Inst. Process=	Off
#Detector Gain=	Best Dynamic Range
#Detector ADC=	20 kHz
#Detector temperature (°C)=	-69.85
#Instrument=	LabRAM HR Evol
#Detector=	Synapse
#Objective=	x100
#Grating=	600 gr/mm
#ND Filter=	100%
#Laser (nm)=	532
#Hole=	100.021
#Range=	Auto
#Laser Pol.=	No
#Raman. Pol.=	No
#Laser Pol. (°)=	-0.0007625
#Raman Pol. (°)=	89.9995
#Collection=	Microscope
#StageXY=	Marzhauser
#StageZ=	Marzhauser
#X (µm)=	-5913.2
#Y (µm)=	2876.9
#Z (µm)=	-223.7
#Full time(mm:ss)=	3:19
#Project=
#Sample=
#Site=
#Title=	Thy_20_09_22_2x_45s_532 nm_x100_100%_600 gr_mm
#Remark=
#Date=	29.06.2022 12:13
#Acquired=	29.06.2022 12:13:12
#Base:Fit=	10.08.2022 09:52:02
#Base:Fit=	10.08.2022 09:52:12
#Base:Sub=	10.08.2022 09:54:21
#Filter:Polynom=	16.08.2022 10:24:04
#AxisType[0]=Intens
#AxisUnit[0]=Cnt
#AxisType[1]=Spectr
#AxisUnit[1]=1/cm
200.523	32.9711
204.154	27.4405
207.781	21.6224
211.409	16.5694
215.034	12.4291
218.659	10.2727
222.281	7.61395
225.903	5.97273
229.522	4.88373
233.14	3.59844
236.756	3.10785
240.373	2.56376
243.986	2.56064
247.598	1.60936
251.208	2.55691
254.818	3.76748
258.427	4.5406
262.034	5.33928
265.638	5.06563
269.242	4.66395
272.844	4.40205
276.445	3.30119
280.044	4.41861
283.642	4.85962
287.238	4.59823
290.833	5.49408
294.425	5.21896
298.017	5.67388
301.608	5.21759
305.198	6.01439
308.786	6.16665
312.371	5.91655
315.956	7.14215
319.54	8.72954
323.122	9.1488
326.701	10.933
330.281	10.9355
333.857	10.6115
337.434	11.9213
341.008	12.2245
344.582	13.4307
348.153	11.8407
351.724	11.6263
355.292	11.4414
358.861	10.822
362.426	9.39844
365.99	9.76482
369.555	9.59001
373.116	8.6933
376.676	8.42546
380.236	7.95907
383.793	4.83628
387.349	3.84052
390.903	3.85421
394.456	5.03453
398.007	4.32742
401.56	3.28524
405.108	4.25436
408.656	6.28884
412.202	5.9126
415.746	6.13691
419.29	5.35838
422.831	6.30721
426.37	7.22977
429.909	6.9602
433.447	7.19078
436.983	7.35504
440.519	8.44855
444.052	7.04814
447.583	6.5458
451.114	7.44938
454.643	7.85474
458.169	8.09212
461.696	8.34821
465.222	8.92685
468.744	9.13559
472.267	9.58502
475.787	10.3665
479.307	12.673
482.823	13.3308
486.341	15.2489
489.855	16.6131
493.37	19.0657
496.881	19.2308
500.391	18.45
503.902	18.1105
507.409	19.6858
510.915	20.3392
514.42	19.1064
517.925	20.1719
521.427	19.8638
524.928	20.0657
528.427	18.9251
531.925	19.2827
535.422	19.4406
538.917	18.318
542.411	16.9673
545.903	14.9601
549.395	14.1518
552.884	14.4323
556.373	14.0152
559.86	12.9099
563.346	12.3618
566.831	12.033
570.314	10.5627
573.794	8.55995
577.274	6.85194
580.754	6.47118
584.23	5.37839
587.706	5.83148
591.181	5.26873
594.653	5.90384
598.126	5.05765
601.595	6.2862
605.065	7.40659
608.532	9.09077
611.999	10.8316
615.463	10.6288
618.928	10.5483
622.389	11.4662
625.851	12.9116
629.31	15.8651
632.767	18.6355
636.223	19.7627
639.68	20.374
643.134	21.115
646.586	19.8215
650.037	20.813
653.486	20.0918
656.936	20.7097
660.383	21.5438
663.829	23.2746
667.273	25.1359
670.716	25.0432
674.158	25.6615
677.598	27.8808
681.035	29.3699
684.473	31.1484
687.909	33.1053
691.344	34.6945
694.778	36.2192
698.211	36.5212
701.64	36.7873
705.07	39.2826
708.498	42.964
711.924	44.6124
715.35	45.9477
718.774	47.3852
722.196	48.1741
725.618	50.9359
729.037	52.2248
732.456	53.9578
735.873	54.8901
739.289	56.2804
742.703	57.8142
746.116	58.0077
749.529	60.4042
752.938	61.2398
756.347	63.1139
759.756	66.0247
763.162	67.4468
766.567	68.3615
769.97	68.7551
773.372	70.2552
776.773	71.3363
780.174	71.6094
783.573	72.2343
786.97	75.6803
790.365	78.0098
793.76	79.0353
797.153	79.8398
800.543	81.715
803.933	83.3969
807.322	85.016
810.71	86.0961
814.097	85.7657
817.483	85.8216
820.865	84.5128
824.248	82.6791
827.629	81.7294
831.008	81.1621
834.387	79.5915
837.765	78.4185
841.139	77.0556
844.514	74.2079
847.886	71.8793
851.259	69.8698
854.629	68.7201
857.997	67.1521
861.366	64.7733
864.732	63.249
868.098	62.4269
871.461	61.5389
874.823	58.6053
878.184	56.288
881.545	55.0144
884.903	53.8665
888.26	53.935
891.616	54.1125
894.97	54.0772
898.323	54.746
901.675	54.0663
905.026	52.7657
908.375	52.5206
911.723	51.8666
915.07	50.0119
918.415	48.2235
921.76	47.7447
925.103	46.754
928.443	46.2207
931.783	45.406
935.123	44.6792
938.461	43.1652
941.796	39.6488
945.131	37.154
948.465	35.2139
951.797	34.2696
955.128	32.9833
958.457	30.833
961.786	27.7651
965.113	28.3264
968.44	29.5216
971.763	31.0705
975.086	32.6617
978.409	34.4638
981.729	34.9798
985.048	34.2163
988.367	35.4909
991.683	35.6668
994.998	34.2483
998.312	35.4092
1001.62	34.4355
1004.94	35.7878
1008.25	35.035
1011.56	35.4338
1014.86	35.1908
1018.17	33.6927
1021.48	30.6855
1024.78	30.2174
1028.08	30.5678
1031.38	29.2044
1034.68	28.9227
1037.98	26.6655
1041.28	25.3083
1044.57	24.3617
1047.87	23.7729
1051.16	23.6114
1054.45	22.1297
1057.75	21.2028
1061.04	19.8958
1064.32	17.9593
1067.61	16.5376
1070.9	15.9745
1074.18	15.8829
1077.47	15.7827
1080.75	14.981
1084.03	15.669
1087.31	16.2541
1090.59	16.1648
1093.86	16.8841
1097.14	16.5785
1100.41	17.8316
1103.69	20.55
1106.96	22.5805
1110.23	24.6146
1113.5	25.8928
1116.77	26.6652
1120.03	27.639
1123.3	28.0054
1126.56	28.1374
1129.83	27.1758
1133.09	26.8313
1136.35	24.0715
1139.61	23.0939
1142.86	21.2797
1146.12	19.6332
1149.38	18.6569
1152.63	17.5225
1155.88	15.8049
1159.14	12.7747
1162.39	10.871
1165.63	8.16949
1168.88	4.50544
1172.13	2.98734
1175.38	2.62607
1178.62	2.58424
1181.86	2.32418
1185.1	4.12559
1188.34	5.99343
1191.58	7.90981
1194.82	9.25143
1198.06	12.1311
1201.29	15.4649
1204.53	19.0956
1207.76	20.2518
1210.99	23.4076
1214.22	26.6071
1217.45	30.7167
1220.68	34.4807
1223.91	36.8818
1227.13	41.0556
1230.36	41.865
1233.58	43.0789
1236.8	44.2221
1240.02	45.1832
1243.24	45.0668
1246.46	45.7024
1249.67	48.8349
1252.89	49.1091
1256.1	49.3171
1259.32	50.7935
1262.53	52.3283
1265.74	54.7305
1268.95	56.4955
1272.15	57.6907
1275.36	59.079
1278.57	60.493
1281.77	62.5311
1284.97	62.645
1288.18	64.0541
1291.38	66.3029
1294.58	67.8801
1297.78	68.6366
1300.97	68.7123
1304.17	68.2489
1307.36	69.1006
1310.55	70.356
1313.75	72.7083
1316.94	70.7901
1320.13	70.7322
1323.32	70.4777
1326.5	71.1376
1329.69	70.9707
1332.87	69.3058
1336.06	69.1337
1339.24	69.1033
1342.42	67.9691
1345.6	68.9076
1348.78	65.8804
1351.96	64.3933
1355.13	62.5596
1358.31	61.6409
1361.48	61.1847
1364.65	59.9688
1367.82	60.7482
1370.99	58.3322
1374.16	56.1086
1377.33	54.9926
1380.5	53.9452
1383.66	53.1359
1386.83	52.8758
1389.99	52.6172
1393.15	50.0124
1396.31	49.1527
1399.47	47.9219
1402.63	48.1506
1405.78	48.0156
1408.94	47.9191
1412.1	48.1512
1415.25	50.11
1418.4	52.8976
1421.55	54.5697
1424.7	55.8486
1427.85	57.8042
1431	61.9084
1434.14	65.8944
1437.29	68.1173
1440.43	69.0501
1443.57	70.1538
1446.71	69.3189
1449.85	69.2715
1452.99	68.6745
1456.13	68.6332
1459.26	65.6084
1462.4	63.9954
1465.54	62.0561
1468.67	59.2205
1471.8	55.043
1474.93	52.2891
1478.06	47.3532
1481.19	44.0031
1484.31	39.7396
1487.44	36.3757
1490.56	34.0948
1493.69	32.0168
1496.81	28.2707
1499.93	24.8103
1503.05	23.395
1506.17	21.2522
1509.28	20.4729
1512.4	19.3947
1515.52	18.54
1518.63	18.7861
1521.74	20.8866
1524.85	22.503
1527.96	24.4023
1531.07	27.3293
1534.18	30.7505
1537.29	34.696
1540.39	39.9235
1543.5	43.3989
1546.6	47.6446
1549.7	50.3927
1552.8	55.1416
1555.9	60.643
1559	64.4198
1562.1	67.9533
1565.19	69.2477
1568.29	71.1697
1571.38	73.3331
1574.47	74.4634
1577.56	74.9205
1580.66	75.9916
1583.74	76.6305
1586.83	76.4987
1589.92	76.625
1593.01	76.1245
1596.09	75.7021
1599.17	74.0859
1602.25	72.4706
1605.34	71.0532
1608.41	69.5438
1611.49	68.4605
1614.57	67.8065
1617.65	65.3242
1620.72	64.2252
1623.79	64.2255
1626.87	63.9226
1629.94	64.2829
1633.01	64.2449
1636.08	63.7331
1639.15	64.4481
1642.21	65.8636
1645.28	68.3508
1648.34	69.1338
1651.41	70.6439
1654.47	71.3422
1657.53	71.7521
1660.59	72.0612
1663.65	70.8897
1666.71	70.2555
1669.76	68.3532
1672.82	66.1096
1675.87	61.6282
1678.93	57.5762
1681.98	53.1955
1685.03	48.8466
1688.08	43.7086
1691.13	40.1546
1694.17	33.9066
1697.22	29.3283
1700.27	24.1676
1703.31	19.9148
1706.35	17.3152
1709.39	14.8864
1712.43	13.3515
1715.47	12.4351
1718.51	11.2112
1721.55	10.1897
1724.58	9.66362
1727.62	9.8643
1730.65	9.81267
1733.68	10.6807
1736.72	11.1777
1739.74	10.8831
1742.77	9.50489
1745.8	8.62428
1748.83	7.3546
1751.85	6.4559
1754.88	5.90667
1757.9	5.328
1760.92	5.03055
1763.95	4.24153
1766.96	3.4145
1769.98	2.52767
1773	1.74581
1776.02	1.29745
1779.03	1.45549
1782.05	1.29898
1785.06	1.34146
1788.07	1.26075
1791.08	1.85561
1794.09	2.71201
1797.1	3.89956
1800.11	4.07223
1803.12	4.35182
1806.12	4.64422
1809.12	4.51294
1812.13	4.46954
1815.13	4.29905
1818.13	4.02286
1821.13	4.64912
1824.13	5.08315
1827.13	5.96523
1830.12	6.36763
1833.12	6.17985
1836.11	6.22542
1839.1	6.41495
1842.09	5.5485
1845.09	4.82387
1848.08	3.96892
1851.06	3.64225
1854.05	4.18841
1857.04	3.88802
1860.02	3.64796
1863.01	4.12332
1865.99	4.60118
1868.97	5.22186
1871.95	4.70379
1874.93	4.27652
1877.91	4.23828
1880.89	4.42745
1882.46	4.96277
1885.45	4.31641
1888.43	3.70625
1891.42	4.51828
1894.41	4.32738
1897.39	4.03304
1900.37	4.16613
1903.36	3.91735
1906.34	3.31338
1909.32	2.87392
1912.29	3.33819
1915.27	2.96286
1918.25	2.99405
1921.23	2.95419
1924.2	4.39687
1927.17	4.2301
1930.15	4.64608
1933.12	4.82638
1936.09	5.3592
1939.06	6.34406
1942.02	6.83469
1944.99	6.55169
1947.96	6.45916
1950.92	5.62936
1953.88	5.11802
1956.85	4.22317
1959.81	3.84545
1962.77	3.24444
1965.73	2.60303
1968.69	2.27599
1971.64	1.73495
1974.6	1.48156
1977.55	1.40955
1980.51	1.72781
1983.46	2.31762
1986.41	2.99592
1989.36	3.46882
1992.31	4.10257
1995.26	5.21968
1998.21	5.39914
2001.15	6.17786
2004.1	7.38461
2007.04	7.25416
2009.99	7.60633
2012.93	8.37377
2015.87	8.08263
2018.81	6.32197
2021.75	5.9075
2024.68	5.72479
2027.62	5.60528
2030.56	4.96834
2033.49	5.13614
2036.42	4.25656
2039.36	3.77693
2042.29	3.66276
2045.22	3.35754
2048.14	3.95121
2051.07	4.67231
2054	3.44947
2056.93	4.6583
2059.85	5.46315
2062.77	5.25955
2065.7	5.51387
2068.62	6.15266
2071.54	5.89329
2074.46	6.34936
2077.38	7.2934
2080.29	7.29849
2083.21	8.62302
2086.12	9.84374
2089.04	8.23235
2091.95	8.14121
2094.86	9.85611
2097.77	10.2541
2100.68	10.5076
2103.59	11.4569
2106.5	11.5702
2109.41	11.4908
2112.31	13.1671
2115.21	14.4707
2118.12	15.8817
2121.02	17.1003
2123.92	18.0839
2126.82	18.6243
2129.72	20.3893
2132.62	20.8069
2135.51	21.5424
2138.41	23.3266
2141.31	24.0909
2144.2	25.8572
2147.09	28.2528
2149.98	29.9303
2152.87	30.9907
2155.76	33.3801
2158.65	34.1711
2161.54	34.7656
2164.43	36.1461
2167.31	37.6536
2170.2	37.2949
2173.08	37.9402
2175.96	37.9808
2178.84	37.6307
2181.72	37.8406
2184.6	37.7064
2187.48	36.97
2190.36	35.4197
2193.23	34.3805
2196.11	33.2433
2198.98	31.6646
2201.85	29.7606
2204.72	28.3223
2207.59	26.8919
2210.46	24.5445
2213.33	22.7734
2216.2	20.8324
2219.07	18.9081
2221.93	17.956
2224.8	16.528
2227.66	15.562
2230.52	15.3171
2233.39	14.287
2236.25	13.1609
2239.1	12.4262
2241.96	11.5394
2244.82	11.0139
2247.68	10.789
2250.53	10.4445
2253.38	10.095
2256.24	9.93984
2259.09	9.32863
2261.94	10.2693
2264.79	10.8235
2267.64	10.2637
2270.49	9.52762
2273.33	9.14442
2276.18	7.96926
2279.02	7.78744
2281.87	6.86658
2284.71	5.22319
2287.55	4.03943
2290.39	3.42837
2293.23	3.29382
2296.07	3.49825
2298.91	3.93785
2301.74	3.59441
2304.58	3.82108
2307.41	4.2778
2310.25	4.10892
2313.08	3.40269
2315.91	4.71754
2318.74	5.15322
2321.57	5.64081
2324.4	7.35728
2327.23	7.85279
2330.05	8.59052
2332.88	8.84619
2335.7	8.75787
2338.52	8.2985
2341.35	7.28134
2344.17	6.94348
2346.99	6.4647
2349.81	6.14113
2352.62	4.77707
2355.44	3.20217
2358.26	2.85068
2361.07	1.74226
2363.89	1.17508
2366.7	0.796902
2369.51	0.465835
2372.32	0.432556
2375.13	0.496102
2377.94	0.321983
2380.75	0.180364
2383.56	1.16009
2386.36	1.34808
2389.17	1.51012
2391.97	1.72095
2394.77	2.53747
2397.58	2.47881
2400.38	2.84535
2403.18	3.24019
2405.97	3.35997
2408.77	4.10202
2411.57	4.41215
2414.37	4.69126
2417.16	5.14803
2419.95	6.30461
2422.75	5.37943
2425.54	5.5529
2428.33	5.37828
2431.12	6.17303
2433.91	6.44104
2436.7	6.80696
2439.48	6.32572
2442.27	5.84145
2445.05	5.42598
2447.84	5.14602
2450.62	4.85889
2453.4	4.22887
2456.18	3.07966
2458.96	2.73864
2461.74	2.80973
2464.52	2.84981
2467.29	2.47221
2470.07	2.84122
2472.85	3.16735
2475.62	2.55616
2478.39	3.14075
2481.16	3.48034
2483.93	3.9433
2486.7	4.08033
2489.47	4.33425
2492.24	4.89246
2495.01	4.88718
2497.77	4.63217
2500.54	5.14901
2503.3	4.04207
2506.06	3.38179
2508.83	2.05715
2511.59	2.13813
2514.35	1.98327
2517.11	1.77492
2519.86	1.46191
2522.62	2.59543
2525.38	2.24508
2528.13	3.37965
2530.89	3.57197
2533.64	3.68264
2536.39	3.98628
2539.14	3.24717
2541.89	3.82766
2544.64	4.13251
2547.39	4.63323
2550.14	4.51501
2552.88	4.43807
2555.63	4.34678
2558.37	4.35427
2561.11	4.89822
2563.86	4.74008
2566.6	4.24574
2569.34	4.12173
2572.08	3.89829
2574.82	3.48494
2577.55	2.91685
2580.29	3.72597
2583.02	3.87725
2585.76	4.8251
2588.49	4.48768
2591.22	4.70838
2593.96	4.04269
2596.69	4.77535
2599.42	4.26523
2602.14	4.64698
2604.87	4.55027
2607.6	5.1536
2610.32	6.60806
2613.05	6.68623
2615.77	7.28225
2618.49	7.64716
2621.22	8.30644
2623.94	8.85938
2626.66	9.2944
2629.37	9.35085
2632.09	9.11971
2634.81	10.1903
2637.53	10.447
2640.24	10.2834
2642.96	9.53051
2645.67	9.5763
2648.38	9.67855
2651.09	8.70796
2653.8	7.88194
2656.51	6.63649
2659.22	6.96916
2661.93	6.97788
2664.63	7.57369
2667.34	8.10114
2670.04	7.97089
2672.75	7.32752
2675.45	6.4502
2678.15	7.19068
2680.85	6.90698
2683.55	7.10127
2686.25	6.5945
2688.94	6.56246
2691.64	6.35234
2694.34	6.33469
2697.03	7.12579
2699.73	8.1165
2702.42	9.19852
2705.11	9.66995
2707.8	9.78993
2710.49	9.76191
2713.18	10.3891
2715.87	11.9381
2718.55	12.0367
2721.24	12.4584
2723.93	13.162
2726.61	13.8357
2729.29	14.3412
2731.98	13.6146
2734.66	12.7572
2737.34	11.319
2740.02	10.005
2742.7	9.65717
2745.37	9.27774
2748.05	7.59647
2750.72	5.57367
2753.4	4.69499
2756.07	3.71301
2758.75	2.42542
2761.42	2.15116
2764.09	1.49175
2766.76	1.4718
2769.43	1.92211
2772.1	2.02599
2774.76	1.72928
2777.43	1.42864
2780.1	1.20841
2782.76	2.09356
2785.42	1.08722
2788.09	1.70035
2790.75	1.22661
2793.41	1.5628
2796.07	1.75034
2798.73	1.39277
2801.39	0.651356
2804.04	-0.0085125
2806.7	-0.43029
2809.35	-0.703875
2812.01	-1.05629
2814.66	-1.81244
2817.31	-1.61923
2819.96	-1.07238
2822.61	0.0360727
2825.26	2.23504
2827.91	5.94767
2830.56	9.48081
2833.21	14.0235
2835.85	18.2607
2838.5	22.3068
2841.14	27.4358
2843.78	33.083
2846.42	39.5717
2849.06	46.8915
2851.71	54.2987
2854.34	62.9495
2856.98	70.2298
2859.62	78.3587
2862.26	83.4845
2864.89	89.846
2867.53	95.0687
2870.16	99.7928
2872.79	104.194
2875.42	107.876
2878.05	111.732
2880.68	114.912
2883.31	118.662
2885.94	122.08
2888.57	125.489
2891.19	129.422
2893.82	133.019
2896.44	137.053
2899.07	142.277
2901.69	147.412
2904.31	154.41
2906.93	162.238
2909.55	169.947
2912.17	178.423
2914.79	187.186
2917.41	195.695
2920.02	202.198
2922.64	207.925
2925.25	211.692
2927.86	213.877
2930.48	214.489
2933.09	213.704
2935.7	212.061
2938.31	208.913
2940.92	204.509
2943.53	198.741
2946.13	191.586
2948.74	183.806
2951.34	176.028
2953.95	167.625
2956.55	159.01
2959.15	150.728
2961.75	142.911
2964.35	135.084
2966.95	127.866
2969.55	120.931
2972.15	114.409
2974.75	107.456
2977.34	101.595
2979.94	94.3029
2982.53	87.0888
2985.13	80.0259
2987.72	72.6594
2990.31	65.5977
2992.9	57.5936
2995.49	51.2831
2998.08	45.1707
3000.67	38.5305
3003.25	32.0867
3005.84	26.7658
3008.42	22.4446
3011.01	18.0641
3013.59	14.4917
3016.17	11.4326
3018.76	8.60269
3021.34	6.38743
3023.92	5.3749
3026.49	4.26134
3029.07	4.34147
3031.65	4.76084
3034.23	4.70127
3036.8	6.21767
3039.38	7.7092
3041.95	9.17082
3044.52	10.6194
3047.09	11.6175
3049.66	12.6582
3052.23	13.386
3054.8	13.8787
3057.37	13.6962
3059.94	13.843
3062.5	12.8255
3065.07	12.0118
3067.63	11.4762
3070.2	10.834
3072.76	8.99822
3075.32	6.80356
3077.88	5.0493
3080.44	3.64677
3083	2.38406
3085.56	1.01236
3088.12	-0.261611
3090.67	0.132278
3093.23	0.609979
3095.78	0.236571
3098.34	0.888996
3100.89	2.22332
3103.44	3.36427
3105.99	3.46798
3108.54	3.55679
3111.09	5.45423
3113.64	7.06945
3116.19	8.36156
3118.74	9.64661
3121.28	11.2044
3123.83	12.5999
3126.37	13.7563
3128.91	15.0777
3131.46	16.1266
3134	17.278
3136.54	18.4624
3139.08	19.5963
3141.62	20.9135
3144.16	22.082
3146.69	23.4947
3149.23	23.7517