File: data/Raman/poly_smoothed/Thy_00_07_29_1x_45s_532 nm_x100_100%_600 gr_mm_01.txt
#Acq. time (s)=	45
#Accumulations=	2
#Range (cm-¹)=	200...3150
#Windows=	2
#Auto scanning=	Off
#Autofocus=	Off
#Macrospot=	Off
#AutoExposure=	Off
#Spike filter=	Multiple accum.
#Delay time (s)=	0
#Binning=	1
#Readout mode=	Signal
#DeNoise=	Off
#ICS correction=	On
#Dark correction=	Off
#Inst. Process=	Off
#Detector Gain=	Best Dynamic Range
#Detector ADC=	20 kHz
#Detector temperature (°C)=	-69.85
#Instrument=	LabRAM HR Evol
#Detector=	Synapse
#Objective=	x100
#Grating=	600 gr/mm
#ND Filter=	100%
#Laser (nm)=	532
#Hole=	100.021
#Range=	Auto
#Laser Pol.=	No
#Raman. Pol.=	No
#Laser Pol. (°)=	-0.0007625
#Raman Pol. (°)=	89.9995
#Collection=	Microscope
#StageXY=	Marzhauser
#StageZ=	Marzhauser
#X (µm)=	8982.7
#Y (µm)=	-3064.7
#Z (µm)=	-55.15
#Full time(mm:ss)=	3:18
#Project=
#Sample=
#Site=
#Title=	Thy_00_07_29_2x_45s_532 nm_x100_100%_600 gr_mm
#Remark=
#Date=	28.06.2022 12:14
#Acquired=	28.06.2022 12:14:12
#Base:Fit=	10.08.2022 10:07:56
#Base:Sub=	10.08.2022 10:08:40
#Filter:Polynom=	16.08.2022 10:26:06
#AxisType[0]=Intens
#AxisUnit[0]=Cnt
#AxisType[1]=Spectr
#AxisUnit[1]=1/cm
200.407	3.5203
204.035	2.87644
207.665	2.31708
211.291	2.40101
214.916	2.20122
218.541	2.09853
222.163	1.35763
225.785	0.156331
229.404	-0.0407459
233.022	0.274459
236.638	1.18745
240.255	0.566094
243.868	0.597272
247.48	1.50142
251.091	1.36873
254.702	1.8687
258.31	2.1351
261.916	4.82428
265.521	7.16966
269.125	7.02375
272.727	10.6837
276.328	11.3718
279.927	11.9769
283.525	12.3761
287.121	13.5823
290.716	14.2709
294.31	16.1287
297.9	17.8619
301.491	19.5234
305.081	21.867
308.669	21.4434
312.256	22.1148
315.839	22.3164
319.423	22.563
323.006	22.0618
326.585	19.4257
330.165	17.5158
333.741	16.9643
337.318	16.1011
340.894	14.721
344.466	13.9307
348.039	14.1993
351.608	14.8737
355.176	12.9861
358.745	12.6415
362.31	14.0611
365.876	12.1884
369.439	13.7879
373	15.3772
376.56	17.596
380.12	18.7908
383.677	20.8778
387.233	22.2023
390.787	23.4443
394.34	24.2311
397.894	23.529
401.444	21.8609
404.993	21.1159
408.54	18.8855
412.086	16.1574
415.631	14.1074
419.174	13.6963
422.716	11.6901
426.257	10.823
429.794	8.41924
433.332	7.3962
436.868	5.38229
440.403	4.12631
443.937	4.04547
447.468	5.03858
450.999	6.14317
454.528	7.85783
458.057	8.12006
461.582	9.93949
465.107	10.3357
468.629	10.6807
472.152	12.4827
475.672	15.3269
479.192	15.2691
482.709	15.3327
486.226	16.1525
489.74	17.3555
493.255	18.8299
496.767	18.618
500.277	19.1878
503.788	19.6917
507.295	20.5069
510.801	19.4615
514.308	19.534
517.811	16.8466
521.313	17.6703
524.814	17.3095
528.313	18.3219
531.811	18.2419
535.308	16.3508
538.803	15.3643
542.297	14.6741
545.789	13.052
549.281	11.5728
552.771	11.2485
556.259	11.6857
559.747	9.41256
563.233	10.0638
566.717	9.18818
570.2	9.02568
573.68	8.42958
577.161	6.67229
580.64	6.88092
584.118	5.76958
587.593	5.78855
591.068	5.11804
594.54	4.67271
598.013	3.75218
601.484	2.72003
604.952	2.17246
608.421	2.55401
611.886	1.21799
615.35	1.28616
618.815	2.83699
622.276	3.56172
625.738	3.90313
629.197	3.95541
632.655	4.06041
636.113	4.64261
639.568	4.36682
643.021	4.20821
646.473	4.45632
649.924	5.6714
653.376	6.98626
656.824	7.03342
660.271	6.75095
663.716	8.19553
667.161	9.6729
670.604	9.33694
674.045	10.3247
677.486	10.2018
680.925	10.6747
684.361	11.2745
687.797	9.96488
691.232	12.985
694.666	14.3925
698.099	16.3722
701.528	17.8623
704.958	18.7522
708.387	21.0414
711.814	22.1749
715.238	25.1807
718.663	27.815
722.084	29.9031
725.506	32.6814
728.925	35.6858
732.345	38.1638
735.761	40.7783
739.178	41.7606
742.592	42.8504
746.006	46.8229
749.417	51.3852
752.827	52.7645
756.236	55.3423
759.645	58.0104
763.051	59.4435
766.456	59.8901
769.859	60.309
773.261	61.7799
776.664	61.5472
780.064	60.287
783.462	59.0166
786.859	57.9192
790.255	58.8586
793.649	58.1525
797.042	58.2841
800.434	57.7362
803.823	56.0257
807.212	54.6999
810.6	53.3142
813.987	51.75
817.372	51.1588
820.754	49.997
824.137	48.3435
827.519	48.5398
830.897	48.9428
834.276	47.6066
837.654	46.4383
841.029	45.5322
844.404	42.4539
847.776	39.9617
851.149	37.1074
854.519	34.9361
857.889	34.3584
861.256	32.5876
864.622	30.0739
867.988	30.4101
871.351	28.0955
874.713	26.2908
878.074	23.6045
881.435	23.2464
884.794	23.1255
888.15	21.5905
891.506	20.6492
894.861	19.4788
898.214	18.7567
901.566	19.7922
904.916	19.0334
908.266	19.289
911.614	18.8388
914.961	17.9995
918.306	18.828
921.651	18.4638
924.994	17.4961
928.336	16.4672
931.674	16.1524
935.014	15.9843
938.352	17.25
941.687	19.6112
945.022	19.2654
948.357	21.0978
951.688	20.5047
955.02	20.2228
958.348	19.3059
961.678	17.4115
965.004	18.2865
968.331	20.0018
971.655	20.7555
974.979	23.0525
978.3	26.0207
981.62	26.7251
984.941	27.9368
988.259	27.129
991.575	27.2991
994.89	27.8428
998.204	28.0016
1001.52	26.8058
1004.83	25.5401
1008.14	25.5921
1011.45	25.2446
1014.76	22.7657
1018.06	20.6848
1021.37	19.9821
1024.67	18.6713
1027.97	16.7416
1031.27	15.0656
1034.57	10.3271
1037.87	8.83887
1041.17	6.26293
1044.47	5.60159
1047.76	6.43454
1051.06	5.97504
1054.35	5.58024
1057.64	5.52904
1060.93	4.56015
1064.22	2.90777
1067.5	3.02946
1070.79	4.20852
1074.08	6.76325
1077.36	6.89203
1080.64	6.93501
1083.92	7.24048
1087.2	7.52778
1090.48	9.8159
1093.76	9.03829
1097.03	10.9776
1100.31	13.9075
1103.58	16.3661
1106.85	17.9131
1110.12	17.5411
1113.39	18.4118
1116.66	18.0483
1119.93	18.4679
1123.19	18.0288
1126.46	16.7595
1129.72	14.4535
1132.98	13.2322
1136.24	13.3473
1139.5	13.2364
1142.76	13.8198
1146.01	14.3358
1149.27	15.1859
1152.53	14.5536
1155.78	14.1609
1159.03	11.7859
1162.28	8.90593
1165.53	9.16687
1168.78	8.81987
1172.02	10.0434
1175.27	10.4859
1178.51	12.1458
1181.76	12.9293
1185	13.415
1188.24	13.8829
1191.48	15.1102
1194.71	16.1001
1197.95	17.3138
1201.19	18.346
1204.42	21.2929
1207.65	24.1904
1210.88	28.5323
1214.12	33.3247
1217.35	38.8218
1220.57	44.3146
1223.8	49.7105
1227.03	56.207
1230.25	60.6416
1233.47	65.0995
1236.69	67.6536
1239.92	70.6499
1243.13	73.1346
1246.35	74.1118
1249.57	74.7815
1252.78	76.1263
1256	77.0513
1259.21	76.4056
1262.42	76.1859
1265.63	75.0412
1268.84	74.2505
1272.05	73.8596
1275.26	73.7775
1278.46	74.245
1281.67	77.6253
1284.87	80.8887
1288.07	84.9609
1291.27	89.5728
1294.47	91.8157
1297.67	95.3305
1300.87	100.287
1304.06	106.411
1307.26	111.582
1310.45	115.725
1313.64	118.432
1316.83	119.49
1320.02	120.213
1323.21	120.072
1326.4	120.064
1329.59	119.951
1332.77	118.309
1335.95	115.951
1339.14	113.301
1342.32	110.808
1345.5	109.661
1348.67	107.647
1351.85	106.458
1355.03	104.513
1358.2	102.411
1361.38	100.183
1364.55	96.4886
1367.72	94.4227
1370.89	90.7058
1374.06	88.91
1377.23	88.5081
1380.39	89.4268
1383.56	87.5111
1386.72	85.8965
1389.89	84.2262
1393.05	80.4053
1396.21	78.6299
1399.37	76.9985
1402.52	75.1701
1405.68	73.4748
1408.84	73.0662
1411.99	74.6726
1415.15	76.6175
1418.3	80.9815
1421.45	85.7124
1424.6	92.2609
1427.75	99.2084
1430.89	104.545
1434.04	110.008
1437.18	115.202
1440.33	119.825
1443.47	124.892
1446.61	127.777
1449.75	129.283
1452.89	128.628
1456.03	128.678
1459.16	127.967
1462.3	123.588
1465.43	118.847
1468.56	112.454
1471.7	102.924
1474.83	94.5699
1477.96	87.8777
1481.08	79.858
1484.21	73.6788
1487.34	68.5491
1490.46	63.7317
1493.58	60.4695
1496.71	57.3544
1499.83	57.3867
1502.95	56.1172
1506.07	54.8942
1509.18	54.2748
1512.3	54.0559
1515.41	55.3556
1518.53	54.9395
1521.64	56.4702
1524.75	58.4593
1527.86	60.7749
1530.97	63.6598
1534.08	67.073
1537.19	69.579
1540.29	70.5606
1543.4	73.187
1546.5	75.9221
1549.6	80.1928
1552.7	86.8778
1555.8	94.5861
1558.9	100.534
1562	106.159
1565.09	111.294
1568.19	115.855
1571.28	120.45
1574.37	127
1577.47	132.98
1580.56	135.502
1583.64	137.821
1586.73	140.14
1589.82	142.882
1592.9	142.23
1595.99	141.824
1599.07	139.321
1602.15	136.141
1605.23	132.144
1608.31	129.456
1611.39	126.441
1614.47	122.626
1617.55	120.585
1620.62	119.299
1623.7	118.516
1626.77	117.618
1629.84	117.82
1632.91	118.531
1635.98	117.275
1639.05	118.196
1642.11	118.821
1645.18	121.029
1648.24	122.973
1651.31	123.247
1654.37	123.013
1657.43	121.141
1660.49	119.039
1663.55	114.969
1666.61	110.397
1669.66	104.906
1672.72	99.1032
1675.77	92.088
1678.83	86.7363
1681.88	81.0936
1684.93	73.6435
1687.98	66.1056
1691.03	59.5126
1694.07	53.7501
1697.12	46.0193
1700.17	40.5971
1703.21	37.0396
1706.25	31.8446
1709.29	28.6584
1712.33	25.7709
1715.37	23.3881
1718.41	21.9551
1721.45	20.4635
1724.49	18.4784
1727.52	18.0417
1730.55	17.3397
1733.59	16.4658
1736.62	15.0817
1739.65	14.7599
1742.68	14.9063
1745.7	13.7076
1748.73	12.8854
1751.76	12.0123
1754.78	11.4532
1757.8	10.9393
1760.83	9.73216
1763.85	10.0104
1766.87	8.36861
1769.89	7.08546
1772.9	7.15731
1775.92	7.44176
1778.94	7.91637
1781.95	7.79996
1784.96	7.84001
1787.97	6.71369
1790.99	5.96134
1794	6.29742
1797	5.60674
1800.01	5.83482
1803.02	5.02457
1806.02	4.3555
1809.03	3.96839
1812.03	3.68259
1815.03	2.95432
1818.03	2.75889
1821.03	3.01541
1824.03	3.33676
1827.03	3.97378
1830.02	2.85792
1833.02	2.67761
1836.01	3.58683
1839.01	2.3185
1842	2.64102
1844.99	3.19619
1847.98	2.81002
1850.97	2.343
1853.95	2.57907
1856.94	1.48411
1859.93	1.37195
1862.91	0.952111
1865.89	0.708973
1868.87	0.634716
1871.85	-0.302586
1874.83	-0.660286
1877.81	-0.297198
1880.79	0.284205
1882.52	1.06173
1885.51	1.1127
1888.5	1.93961
1891.49	3.86104
1894.47	3.52822
1897.46	3.96457
1900.44	3.14152
1903.42	3.4294
1906.4	3.01012
1909.38	3.94661
1912.36	3.99199
1915.34	3.75931
1918.32	3.68238
1921.29	4.48068
1924.27	5.01198
1927.24	5.27448
1930.21	5.54525
1933.18	5.17529
1936.15	4.73915
1939.12	3.87144
1942.09	4.30568
1945.06	4.2145
1948.02	4.0358
1950.99	4.30383
1953.95	4.93625
1956.91	4.17729
1959.88	4.82527
1962.84	3.22429
1965.8	3.40309
1968.75	2.10205
1971.71	2.95443
1974.67	3.3942
1977.62	3.40771
1980.58	4.20037
1983.53	5.77723
1986.48	6.7243
1989.43	7.33043
1992.38	7.88533
1995.33	7.40417
1998.27	7.91314
2001.22	7.9841
2004.16	8.60701
2007.11	7.64515
2010.05	6.85931
2012.99	6.0809
2015.93	5.69113
2018.87	3.84664
2021.81	3.31072
2024.75	2.78121
2027.69	2.46718
2030.62	2.39873
2033.56	2.29378
2036.49	3.17305
2039.42	3.18207
2042.35	3.4242
2045.28	4.66972
2048.21	4.18145
2051.14	4.54279
2054.07	5.63511
2056.99	6.31226
2059.92	6.86024
2062.84	7.25
2065.76	6.94372
2068.68	7.12723
2071.6	7.60872
2074.52	7.34706
2077.44	6.68433
2080.36	5.70352
2083.27	5.10011
2086.19	4.78712
2089.1	4.1663
2092.02	4.03035
2094.93	4.46548
2097.84	3.83991
2100.75	4.25369
2103.66	4.30369
2106.56	4.08558
2109.47	4.3799
2112.38	3.9153
2115.28	4.22643
2118.18	4.12997
2121.09	3.60589
2123.99	4.31971
2126.89	5.57754
2129.79	6.07614
2132.68	5.71716
2135.58	5.98557
2138.48	4.9541
2141.37	5.32484
2144.27	5.58033
2147.16	4.80868
2150.05	4.51781
2152.94	4.37467
2155.83	3.82325
2158.72	4.8437
2161.6	4.35596
2164.49	4.74196
2167.38	4.67453
2170.26	4.7549
2173.14	6.45152
2176.03	6.97712
2178.91	7.76803
2181.79	7.93223
2184.67	7.86175
2187.54	7.5673
2190.42	6.96533
2193.3	6.81123
2196.17	6.28465
2199.05	6.76797
2201.92	5.83254
2204.79	5.42747
2207.66	4.89546
2210.53	4.12366
2213.4	3.88808
2216.27	3.19635
2219.13	2.41292
2222	2.10737
2224.86	2.24815
2227.72	3.18849
2230.59	3.38479
2233.45	3.86337
2236.31	4.57811
2239.17	4.92389
2242.03	6.19766
2244.88	7.15819
2247.74	7.12481
2250.59	7.57519
2253.45	7.76928
2256.3	8.25012
2259.15	8.88368
2262	9.49414
2264.85	8.71548
2267.7	8.21695
2270.55	8.77197
2273.4	8.59919
2276.24	8.61789
2279.09	7.37348
2281.93	6.49409
2284.77	6.13332
2287.62	6.64785
2290.46	6.746
2293.3	6.00028
2296.13	7.68198
2298.97	9.12233
2301.81	8.89041
2304.64	10.225
2307.48	11.3194
2310.31	11.4686
2313.14	11.9411
2315.98	12.8426
2318.81	13.9067
2321.64	14.1228
2324.46	14.5049
2327.29	15.4751
2330.12	15.2926
2332.94	13.0251
2335.77	10.7311
2338.59	10.1472
2341.41	9.77133
2344.23	8.24704
2347.05	6.47752
2349.87	4.43557
2352.69	3.89093
2355.51	3.49351
2358.32	1.52566
2361.14	0.563129
2363.95	0.642325
2366.76	0.990882
2369.58	0.173292
2372.39	-0.342052
2375.2	1.45336
2378	0.799636
2380.81	0.293433
2383.62	0.0300863
2386.43	0.32334
2389.23	0.417705
2392.03	0.037805
2394.84	0.385111
2397.64	0.885965
2400.44	0.0313041
2403.24	1.68818
2406.04	2.78681
2408.84	4.13046
2411.63	4.51211
2414.43	5.10014
2417.22	6.14685
2420.02	7.95061
2422.81	8.69017
2425.6	9.71755
2428.39	10.0633
2431.18	10.0207
2433.97	9.67057
2436.76	9.32799
2439.54	9.72222
2442.33	9.94039
2445.12	8.96053
2447.9	7.49546
2450.68	7.3408
2453.46	7.07738
2456.24	6.71441
2459.02	6.0659
2461.8	5.29145
2464.58	5.32602
2467.36	5.86445
2470.13	6.42692
2472.91	6.73475
2475.68	6.0265
2478.45	5.08041
2481.23	6.27484
2484	6.67431
2486.77	6.86402
2489.54	6.33131
2492.3	5.66783
2495.07	5.13659
2497.84	3.7695
2500.6	3.21337
2503.36	3.64567
2506.13	3.82219
2508.89	4.02344
2511.65	3.69479
2514.41	3.78114
2517.17	3.7428
2519.93	3.53833
2522.68	2.93657
2525.44	3.61628
2528.19	3.23469
2530.95	4.05972
2533.7	3.53031
2536.45	4.53033
2539.2	4.8107
2541.95	6.18364
2544.7	5.56774
2547.45	7.30396
2550.2	6.85239
2552.94	7.8324
2555.69	7.3976
2558.43	8.78947
2561.18	8.74688
2563.92	9.08221
2566.66	10.1173
2569.4	11.1755
2572.14	11.6035
2574.88	11.7346
2577.61	11.7326
2580.35	11.0918
2583.09	11.4133
2585.82	12.0439
2588.55	12.012
2591.29	12.3414
2594.02	12.6841
2596.75	12.2162
2599.48	12.6555
2602.21	13.243
2604.93	13.4112
2607.66	14.0482
2610.39	13.5267
2613.11	13.3618
2615.83	12.4479
2618.56	11.8279
2621.28	11.7434
2624	11.1182
2626.72	11.4134
2629.44	9.87809
2632.15	10.2394
2634.87	10.2313
2637.59	10.1038
2640.3	10.4711
2643.02	9.92548
2645.73	9.89639
2648.44	9.9665
2651.15	10.0851
2653.86	9.73595
2656.57	9.67003
2659.28	10.1932
2661.99	10.3819
2664.69	10.8051
2667.4	11.5982
2670.1	11.4179
2672.81	11.4405
2675.51	11.6571
2678.21	11.9857
2680.91	12.0448
2683.61	12.8265
2686.31	13.0654
2689	13.1986
2691.7	12.9875
2694.4	13.5523
2697.09	14.4551
2699.79	16.3505
2702.48	16.6763
2705.17	16.9379
2707.86	17.3006
2710.55	17.98
2713.24	19.0348
2715.93	20.2124
2718.62	19.9263
2721.3	20.5575
2723.99	21.1798
2726.67	21.827
2729.35	20.9522
2732.04	21.1417
2734.72	20.5063
2737.4	19.9962
2740.08	19.0897
2742.76	19.147
2745.43	18.978
2748.11	17.9625
2750.79	17.4877
2753.46	16.7046
2756.14	16.2044
2758.81	15.6678
2761.48	16.2298
2764.15	15.1426
2766.82	13.229
2769.49	11.7202
2772.16	10.3669
2774.82	9.95611
2777.49	9.08277
2780.16	8.82856
2782.82	7.65668
2785.48	6.58394
2788.15	5.78838
2790.81	5.32078
2793.47	4.94703
2796.13	4.24226
2798.79	3.70869
2801.44	3.38739
2804.1	2.89316
2806.76	3.9504
2809.41	4.53481
2812.07	4.02662
2814.72	4.84206
2817.37	6.98107
2820.02	9.77053
2822.67	11.9291
2825.32	14.9732
2827.97	18.5991
2830.62	21.7393
2833.26	26.8342
2835.91	32.7758
2838.56	38.2907
2841.2	46.6106
2843.84	55.6184
2846.48	65.326
2849.12	75.4379
2851.77	87.8408
2854.4	101.678
2857.04	114.312
2859.68	127.608
2862.32	139.67
2864.95	151.456
2867.59	161.463
2870.22	172.268
2872.85	178.782
2875.48	185.045
2878.11	191.168
2880.74	196.62
2883.37	201.614
2886	207.262
2888.63	211.321
2891.25	215.598
2893.88	219.637
2896.5	223.43
2899.13	230.367
2901.75	236.101
2904.37	245.3
2906.99	256.52
2909.61	269.193
2912.23	282.609
2914.85	297.61
2917.46	312.882
2920.08	325.172
2922.7	335.476
2925.31	344.129
2927.92	349.668
2930.54	353.496
2933.15	352.926
2935.76	350.018
2938.37	344.683
2940.98	338.672
2943.58	329.86
2946.19	318.696
2948.8	307.775
2951.4	296.186
2954.01	283.822
2956.61	270.461
2959.21	257.621
2961.81	244.506
2964.41	234.103
2967.01	223.378
2969.61	213.485
2972.21	203.773
2974.81	195.124
2977.4	185.87
2980	176.285
2982.59	164.074
2985.18	151.973
2987.78	139.198
2990.37	128.054
2992.96	115.013
2995.55	102.425
2998.14	90.5184
3000.73	78.9345
3003.31	67.8751
3005.9	57.1839
3008.48	47.6321
3011.07	39.853
3013.65	33.2467
3016.23	27.465
3018.81	22.976
3021.4	19.0898
3023.97	15.4566
3026.55	13.8187
3029.13	12.7956
3031.71	11.351
3034.28	10.9063
3036.86	11.0074
3039.43	11.9484
3042.01	14.0832
3044.58	15.1723
3047.15	16.5617
3049.72	18.1159
3052.29	19.5513
3054.86	20.2174
3057.43	20.4219
3060	20.5604
3062.56	19.6029
3065.13	18.1976
3067.69	16.835
3070.26	14.6697
3072.82	13.8647
3075.38	11.4433
3077.94	9.43747
3080.5	8.16572
3083.06	6.51869
3085.62	3.45566
3088.18	1.96801
3090.73	0.443556
3093.29	-0.758312
3095.84	-0.738269
3098.4	-0.624474
3100.95	-0.257865
3103.5	0.0954535
3106.05	1.40188
3108.6	2.58129
3111.15	3.58333
3113.7	4.22736
3116.25	5.43997
3118.79	6.5002
3121.34	7.96664
3123.88	9.37435
3126.43	10.4883
3128.97	12.2704
3131.51	14.2056
3134.06	15.7416
3136.6	18.7718
3139.14	20.6164
3141.67	23.152
3144.21	25.53
3146.75	28.548
3149.29	32.6022