File: data/Raman/poly_smoothed/Thy_10_08_34_1x_45s_532 nm_x100_100%_600 gr_mm_01.txt
#Acq. time (s)=	45
#Accumulations=	2
#Range (cm-¹)=	200...3150
#Windows=	2
#Auto scanning=	Off
#Autofocus=	Off
#Macrospot=	Off
#AutoExposure=	Off
#Spike filter=	Multiple accum.
#Delay time (s)=	0
#Binning=	1
#Readout mode=	Signal
#DeNoise=	Off
#ICS correction=	On
#Dark correction=	Off
#Inst. Process=	Off
#Detector Gain=	Best Dynamic Range
#Detector ADC=	20 kHz
#Detector temperature (°C)=	-69.62
#Instrument=	LabRAM HR Evol
#Detector=	Synapse
#Objective=	x100
#Grating=	600 gr/mm
#ND Filter=	100%
#Laser (nm)=	532
#Hole=	100.021
#Range=	Auto
#Laser Pol.=	No
#Raman. Pol.=	No
#Laser Pol. (°)=	-0.0007625
#Raman Pol. (°)=	89.9995
#Collection=	Microscope
#StageXY=	Marzhauser
#StageZ=	Marzhauser
#X (µm)=	2173.1
#Y (µm)=	1229.2
#Z (µm)=	442.2
#Full time(mm:ss)=	3:18
#Project=
#Sample=
#Site=
#Title=	Thy_10_08_34_2x_45s_532 nm_x100_100%_600 gr_mm
#Remark=
#Date=	05.07.2022 16:42
#Acquired=	05.07.2022 16:42:06
#Base:Fit=	10.08.2022 09:46:25
#Base:Sub=	10.08.2022 09:46:49
#Filter:Polynom=	16.08.2022 10:24:56
#AxisType[0]=Intens
#AxisUnit[0]=Cnt
#AxisType[1]=Spectr
#AxisUnit[1]=1/cm
200.43	4.07916
204.059	8.19736
207.688	10.1658
211.314	9.95513
214.941	9.62286
218.564	10.0163
222.186	9.06477
225.809	7.08668
229.428	6.02788
233.045	4.45594
236.663	4.58799
240.278	5.70542
243.891	5.68271
247.503	5.09324
251.116	2.53949
254.725	3.53199
258.333	3.38074
261.939	2.54475
265.544	4.55922
269.148	6.50761
272.75	8.50291
276.351	9.85819
279.95	11.0851
283.548	11.7736
287.144	12.0647
290.739	12.3304
294.333	14.3279
297.925	14.834
301.514	15.2276
305.104	18.1843
308.692	17.4229
312.279	16.9445
315.862	19.0284
319.446	20.4585
323.029	20.9145
326.608	20.8272
330.188	20.9477
333.766	20.5964
337.341	18.9989
340.917	17.3919
344.489	18.1997
348.062	17.8807
351.631	17.8462
355.201	16.6562
358.768	14.86
362.333	13.3302
365.899	10.6319
369.462	8.85647
373.023	8.19578
376.585	7.90621
380.143	7.70514
383.7	8.35079
387.256	7.21786
390.812	7.29134
394.365	8.47954
397.916	9.47454
401.467	9.5326
405.015	8.5506
408.563	7.46566
412.109	6.86374
415.654	7.15718
419.197	9.1995
422.739	8.92628
426.279	8.18396
429.819	8.55733
433.356	8.6895
436.891	8.07562
440.426	7.61336
443.96	6.7492
447.492	7.14807
451.021	7.51218
454.551	9.53124
458.079	11.3084
461.604	13.2943
465.13	14.3512
468.654	16.5097
472.175	17.9816
475.696	18.5444
479.215	19.5962
482.733	19.3775
486.249	20.3652
489.765	19.5613
493.278	19.4186
496.789	20.8759
500.301	20.1055
503.81	21.8749
507.317	21.8694
510.825	20.9002
514.33	20.4477
517.833	18.5903
521.335	16.8451
524.836	16.8699
528.335	15.5686
531.835	15.0521
535.332	14.8235
538.827	14.0305
542.321	13.9347
545.814	11.7211
549.305	11.6376
552.795	10.2031
556.282	9.1292
559.769	7.41937
563.255	5.61634
566.739	6.09781
570.223	4.48102
573.705	4.80431
577.183	3.55374
580.663	4.91161
584.141	5.6951
587.615	5.69869
591.09	7.63295
594.564	7.93767
598.035	5.84567
601.506	5.19718
604.974	4.8895
608.443	4.59064
611.908	5.23682
615.374	5.08602
618.837	5.1618
622.3	5.40895
625.761	5.62318
629.219	6.17225
632.677	7.34376
636.135	9.59639
639.59	9.97503
643.043	11.5425
646.495	13.9238
649.948	15.477
653.398	16.2143
656.846	17.8349
660.293	17.6716
663.738	19.9642
667.183	22.8581
670.626	23.3798
674.067	23.2291
677.508	22.9506
680.947	23.2316
684.385	24.2819
687.821	23.6497
691.254	24.0369
694.688	23.3508
698.121	23.5897
701.552	24.4746
704.98	26.2938
708.409	28.7501
711.836	31.0622
715.26	33.0701
718.685	36.786
722.108	39.4471
725.528	41.1805
728.949	43.1478
732.367	44.6642
735.785	45.478
739.2	47.4469
742.614	48.5364
746.028	51.4852
749.439	55.4274
752.849	57.5192
756.26	59.359
759.667	60.8037
763.073	64.4427
766.477	67.43
769.883	69.852
773.285	70.8702
776.686	73.2601
780.085	74.9569
783.484	77.3758
786.881	81.9455
790.276	82.6614
793.671	85.2474
797.064	85.8881
800.456	87.9117
803.846	87.0728
807.234	86.507
810.622	84.7249
814.008	84.2714
817.394	82.4884
820.778	80.2505
824.159	80.6002
827.541	79.6349
830.921	78.223
834.298	76.7899
837.676	75.0662
841.051	74.1226
844.426	71.3792
847.798	68.8841
851.171	66.4665
854.54	62.5064
857.911	59.0647
861.278	57.9087
864.645	55.3007
868.01	53.0696
871.373	51.0053
874.735	48.7968
878.097	48.6109
881.457	47.2563
884.815	46.043
888.172	46.067
891.528	45.9055
894.882	46.9718
898.237	48.2275
901.589	47.9805
904.94	50.5756
908.289	52.811
911.635	52.7414
914.982	54.1036
918.328	55.3898
921.672	55.8028
925.015	55.9746
928.357	57.544
931.698	57.9081
935.035	56.8246
938.373	55.8024
941.71	53.9368
945.044	52.3252
948.378	50.3575
951.709	48.4542
955.041	45.8939
958.372	43.3354
961.699	40.9399
965.027	39.8663
968.352	41.1098
971.676	43.1322
975	42.4176
978.322	43.0611
981.642	42.9546
984.962	41.7002
988.28	41.0772
991.596	40.936
994.911	40.0855
998.227	39.7692
1001.54	39.8891
1004.85	41.565
1008.16	41.4464
1011.47	40.1848
1014.78	38.2016
1018.08	38.0045
1021.39	35.8089
1024.69	34.0171
1028	32.1405
1031.3	32.1665
1034.6	30.1429
1037.9	28.4827
1041.19	28.6037
1044.49	29.2371
1047.78	32.1462
1051.08	33.4818
1054.37	32.7803
1057.66	30.9888
1060.95	30.1747
1064.24	30.5289
1067.53	28.4757
1070.81	28.6976
1074.1	29.0093
1077.38	29.6018
1080.66	30.2594
1083.94	31.5684
1087.22	31.266
1090.5	30.9277
1093.78	28.5446
1097.05	29.5597
1100.33	28.9889
1103.6	28.1439
1106.87	26.9304
1110.14	25.7326
1113.41	22.983
1116.68	21.234
1119.95	21.6788
1123.21	18.3102
1126.48	15.4258
1129.74	12.7259
1133	11.2872
1136.26	8.46967
1139.52	6.63367
1142.78	7.42327
1146.04	6.19034
1149.29	5.61768
1152.55	5.76856
1155.8	5.60905
1159.05	4.68865
1162.3	3.32527
1165.55	3.43865
1168.8	3.4212
1172.05	5.72223
1175.29	7.72051
1178.54	9.95241
1181.78	11.7028
1185.02	13.3676
1188.26	15.7612
1191.5	17.2886
1194.74	19.7433
1197.97	22.6625
1201.21	25.4604
1204.44	27.2977
1207.68	31.1546
1210.91	34.3945
1214.14	39.1753
1217.37	44.5573
1220.59	47.3924
1223.82	52.5507
1227.05	55.7639
1230.27	59.2589
1233.49	60.5327
1236.72	60.7008
1239.94	62.66
1243.16	63.8214
1246.37	66.156
1249.59	67.3235
1252.8	68.0077
1256.02	68.1442
1259.23	68.5581
1262.44	67.791
1265.66	68.4585
1268.86	69.0747
1272.07	70.0957
1275.28	72.1314
1278.48	72.7054
1281.69	72.2275
1284.89	73.2791
1288.09	75.0914
1291.29	77.1383
1294.49	80.005
1297.69	80.4203
1300.89	82.5436
1304.08	86.1196
1307.28	88.4569
1310.47	89.2966
1313.66	89.6426
1316.85	91.1939
1320.04	91.2425
1323.23	91.5437
1326.42	90.4077
1329.61	88.9016
1332.79	87.4185
1335.97	85.8859
1339.16	84.8157
1342.34	84.3661
1345.52	83.451
1348.7	81.2881
1351.87	79.6799
1355.05	77.3845
1358.22	72.2633
1361.4	68.0508
1364.57	66.344
1367.74	63.5274
1370.91	60.0095
1374.08	55.6296
1377.25	54.6032
1380.41	53.7965
1383.58	50.4411
1386.74	48.1215
1389.91	45.0697
1393.07	43.0132
1396.23	40.1987
1399.39	38.2236
1402.55	37.0024
1405.7	37.3866
1408.86	37.4317
1412.01	39.944
1415.17	44.8167
1418.32	50.6931
1421.47	56.0962
1424.62	63.5727
1427.77	72.1555
1430.91	79.7131
1434.06	87.188
1437.2	92.9151
1440.35	98.5936
1443.49	103.689
1446.63	105.308
1449.77	106.104
1452.91	105.87
1456.05	104.065
1459.18	100.058
1462.32	94.6695
1465.45	88.1841
1468.59	79.5564
1471.72	70.1298
1474.85	61.0698
1477.98	53.2247
1481.1	45.135
1484.23	36.5798
1487.36	29.782
1490.48	25.4927
1493.61	21.7377
1496.73	19.0215
1499.85	18.1421
1502.97	16.032
1506.09	16.4753
1509.2	16.0501
1512.32	14.4284
1515.43	13.6606
1518.55	12.4132
1521.66	13.5418
1524.77	14.1647
1527.88	16.4163
1530.99	19.3771
1534.1	21.2158
1537.21	22.1356
1540.31	24.754
1543.42	27.443
1546.52	29.4518
1549.62	34.3931
1552.72	38.4847
1555.82	42.6465
1558.92	44.9333
1562.02	46.978
1565.11	49.8192
1568.21	52.8558
1571.3	56.198
1574.39	61.2272
1577.49	64.1768
1580.57	67.4526
1583.66	70.3534
1586.75	71.6074
1589.84	72.5186
1592.92	72.6425
1596.01	73.9365
1599.09	74.8822
1602.17	74.6424
1605.25	74.6479
1608.33	72.6571
1611.41	71.858
1614.49	71.436
1617.57	71.3439
1620.64	72.8134
1623.72	74.3906
1626.79	75.3774
1629.86	76.7266
1632.93	79.786
1636	82.3821
1639.07	86.0206
1642.13	89.3
1645.2	93.4925
1648.26	98.4949
1651.33	101.324
1654.39	103.978
1657.45	105.108
1660.51	103.505
1663.57	102.455
1666.63	99.2475
1669.68	95.5874
1672.74	91.3295
1675.79	85.4403
1678.85	79.9787
1681.9	74.4612
1684.95	68.385
1688	62.558
1691.05	54.2323
1694.09	47.5969
1697.14	42.0324
1700.18	37.2542
1703.23	33.0626
1706.27	30.2135
1709.31	27.6007
1712.35	25.1646
1715.39	23.0033
1718.43	19.3259
1721.47	18.2488
1724.5	17.2986
1727.54	14.2452
1730.57	12.9422
1733.61	10.6975
1736.64	9.04468
1739.67	8.12213
1742.7	7.33191
1745.72	6.4834
1748.75	6.28496
1751.77	5.48059
1754.8	5.30259
1757.82	4.72618
1760.84	2.53404
1763.87	0.511079
1766.89	-0.18036
1769.91	-0.892577
1772.92	-1.31154
1775.94	-2.10454
1778.95	-1.36064
1781.97	-1.50523
1784.98	-1.48545
1787.99	-1.74964
1791.01	-1.58903
1794.01	-1.74524
1797.02	-1.12158
1800.03	-1.03124
1803.04	-0.881445
1806.04	-0.358284
1809.05	-0.235474
1812.05	-0.217258
1815.05	0.539064
1818.05	0.271884
1821.05	0.838709
1824.05	0.281039
1827.05	0.853204
1830.04	1.72916
1833.04	2.02275
1836.03	2.03038
1839.03	1.96706
1842.02	1.97579
1845.01	1.84479
1848	2.18855
1850.99	2.40363
1853.97	3.25799
1856.96	3.75938
1859.94	5.00398
1862.93	5.09517
1865.91	5.29969
1868.89	5.20339
1871.87	6.27365
1874.85	6.41012
1877.83	7.58539
1880.81	7.44201
1882.57	7.83747
1885.56	7.92425
1888.55	7.71066
1891.54	8.33318
1894.52	9.0733
1897.51	9.06909
1900.49	8.81627
1903.47	8.37307
1906.45	8.69834
1909.43	8.43941
1912.41	9.34392
1915.39	9.53821
1918.37	8.99677
1921.34	8.68184
1924.32	9.00915
1927.29	7.61136
1930.26	7.52464
1933.23	8.56795
1936.2	7.29242
1939.17	6.27051
1942.14	5.90966
1945.11	6.49175
1948.07	6.06438
1951.04	6.14984
1954	4.65367
1956.96	4.51668
1959.93	3.824
1962.89	4.1625
1965.85	4.11627
1968.8	4.327
1971.76	4.87805
1974.72	4.81249
1977.67	5.56858
1980.63	7.11651
1983.58	8.46627
1986.53	8.47087
1989.48	8.7408
1992.43	9.04231
1995.38	10.388
1998.32	11.1272
2001.27	11.9436
2004.22	13.003
2007.16	13.3928
2010.1	14.2424
2013.04	14.4667
2015.98	14.3851
2018.92	13.4536
2021.86	13.9756
2024.8	13.6106
2027.74	13.4983
2030.67	13.7571
2033.61	13.4292
2036.54	12.4252
2039.47	10.912
2042.4	10.6472
2045.33	10.7825
2048.26	9.88197
2051.19	8.92023
2054.12	9.95472
2057.04	8.61328
2059.97	7.76302
2062.89	7.96839
2065.81	7.75678
2068.73	7.39886
2071.65	7.90648
2074.57	8.80909
2077.49	9.54879
2080.41	10.8899
2083.32	11.0425
2086.24	11.0952
2089.15	11.2438
2092.07	12.7113
2094.98	12.529
2097.89	13.5274
2100.8	14.0631
2103.71	13.764
2106.61	13.2816
2109.52	12.7346
2112.43	13.7318
2115.33	13.2777
2118.23	13.0531
2121.13	12.6234
2124.04	13.1238
2126.94	13.6645
2129.83	13.8563
2132.73	14.8835
2135.63	16.5809
2138.53	18.1528
2141.42	19.8871
2144.31	22.0268
2147.21	24.2029
2150.1	26.0325
2152.99	28.2078
2155.88	30.5457
2158.77	32.3846
2161.65	33.5126
2164.54	35.6897
2167.43	37.1302
2170.31	37.9091
2173.19	39.3792
2176.07	38.5666
2178.96	38.6504
2181.84	38.9963
2184.72	38.3028
2187.59	37.9445
2190.47	37.2326
2193.35	36.9337
2196.22	35.2533
2199.09	34.0386
2201.97	33.2639
2204.84	32.3434
2207.71	31.2015
2210.58	27.7774
2213.45	25.9767
2216.31	25.1491
2219.18	23.7924
2222.05	21.9055
2224.91	20.6846
2227.78	19.6011
2230.64	17.2357
2233.5	16.4845
2236.36	16.1663
2239.22	14.7143
2242.08	14.8788
2244.93	14.4769
2247.79	14.1379
2250.64	13.2942
2253.5	13.1876
2256.35	13.2567
2259.2	12.9036
2262.05	12.9035
2264.9	11.9003
2267.75	11.6083
2270.6	12.4171
2273.45	12.1546
2276.29	12.162
2279.14	10.5251
2281.98	10.0186
2284.82	10.0099
2287.66	10.8379
2290.5	8.82223
2293.34	8.75569
2296.18	8.63954
2299.02	9.9023
2301.86	9.93017
2304.69	10.7922
2307.53	11.2152
2310.36	10.4082
2313.19	10.1823
2316.02	9.29843
2318.85	9.28405
2321.68	8.93516
2324.51	9.7636
2327.34	8.89626
2330.16	7.96084
2332.99	7.96769
2335.81	7.22515
2338.64	7.26438
2341.46	6.049
2344.28	4.85319
2347.1	4.76677
2349.92	3.87313
2352.74	3.22571
2355.55	3.04517
2358.37	1.82277
2361.19	2.02337
2364	4.07712
2366.81	4.89437
2369.62	3.83753
2372.44	4.75037
2375.24	4.21235
2378.05	3.00318
2380.86	2.49714
2383.67	3.12254
2386.47	3.12348
2389.28	3.71953
2392.08	3.54228
2394.89	3.85672
2397.69	3.77087
2400.49	4.16217
2403.29	4.03848
2406.09	4.06412
2408.88	4.03234
2411.68	3.6745
2414.48	3.97129
2417.27	4.43186
2420.06	4.46068
2422.86	4.93679
2425.65	5.45879
2428.44	5.28352
2431.23	5.40113
2434.02	4.87585
2436.81	4.72298
2439.59	4.89401
2442.38	4.1516
2445.16	3.15759
2447.95	3.14396
2450.73	3.06252
2453.51	2.68322
2456.29	3.07577
2459.07	3.71616
2461.85	3.97759
2464.63	2.87877
2467.4	2.6912
2470.18	2.83388
2472.95	3.91268
2475.73	4.19303
2478.5	4.66019
2481.27	4.86869
2484.04	5.15986
2486.81	4.71971
2489.58	4.58181
2492.35	4.15359
2495.12	3.13255
2497.88	1.86172
2500.65	1.54892
2503.41	1.22668
2506.17	0.762665
2508.94	0.103964
2511.7	-0.720232
2514.46	-0.484853
2517.22	-0.391755
2519.97	-0.223188
2522.73	-0.168479
2525.49	0.377814
2528.24	0.304851
2530.99	0.287636
2533.75	0.78905
2536.5	2.08806
2539.25	3.61245
2542	4.06043
2544.75	5.4806
2547.5	5.86128
2550.24	6.1671
2552.99	4.96747
2555.74	4.6041
2558.48	4.23934
2561.22	3.66511
2563.96	3.27726
2566.71	2.38271
2569.45	1.67695
2572.18	1.77899
2574.92	1.04779
2577.66	1.3758
2580.4	0.914949
2583.13	0.849215
2585.87	0.720467
2588.6	0.286299
2591.33	0.597959
2594.06	0.564936
2596.79	1.32647
2599.52	1.37226
2602.25	1.40877
2604.98	1.69232
2607.71	1.30222
2610.43	2.38503
2613.16	2.23329
2615.88	1.39392
2618.6	1.24401
2621.32	0.692315
2624.04	1.00817
2626.76	1.40102
2629.48	1.51432
2632.2	1.34599
2634.92	2.15473
2637.63	3.3607
2640.35	3.69498
2643.06	3.86144
2645.77	3.86874
2648.49	4.46678
2651.2	4.2427
2653.91	4.50598
2656.62	5.7475
2659.33	6.47271
2662.03	6.78257
2664.74	6.7924
2667.44	7.30648
2670.15	6.98269
2672.85	7.39852
2675.55	7.1262
2678.26	6.95173
2680.96	6.95134
2683.66	6.93477
2686.35	7.08479
2689.05	7.10862
2691.75	7.62009
2694.44	9.03567
2697.14	9.85281
2699.83	11.4475
2702.52	12.3989
2705.22	12.7762
2707.91	13.4126
2710.6	15.2658
2713.29	16.4642
2715.97	16.8686
2718.66	17.2772
2721.35	17.9783
2724.03	18.2947
2726.72	19.1698
2729.4	19.6125
2732.08	20.4408
2734.76	19.8764
2737.44	19.1782
2740.12	19.5406
2742.8	18.5622
2745.48	18.9718
2748.16	18.0804
2750.83	16.8757
2753.51	17.0767
2756.18	17.1391
2758.85	17.0017
2761.53	16.0628
2764.2	15.5089
2766.87	14.9558
2769.54	14.8338
2772.2	14.7776
2774.87	14.849
2777.54	14.1446
2780.2	13.7456
2782.87	13.0128
2785.53	12.7585
2788.19	13.7174
2790.85	13.4736
2793.51	13.1661
2796.17	13.3072
2798.83	13.6018
2801.49	13.6848
2804.15	14.0721
2806.8	14.2462
2809.46	14.44
2812.11	14.8109
2814.76	14.6497
2817.42	15.0083
2820.07	17.2668
2822.72	19.2559
2825.37	23.2606
2828.02	27.0543
2830.66	31.8427
2833.31	36.7205
2835.96	42.1332
2838.6	47.8266
2841.24	55.2084
2843.89	63.9913
2846.53	72.7617
2849.17	82.8224
2851.81	92.403
2854.45	103.549
2857.09	113.772
2859.72	123.442
2862.36	132.768
2865	142.003
2867.63	150.025
2870.26	156.732
2872.9	163.089
2875.53	168.701
2878.16	174.628
2880.79	179.304
2883.42	183.871
2886.05	190.451
2888.67	193.877
2891.3	198.018
2893.92	202.429
2896.55	207.565
2899.17	213.746
2901.79	221.421
2904.42	230.153
2907.04	240.964
2909.66	253.189
2912.27	265.617
2914.89	279.273
2917.51	291.723
2920.13	303.086
2922.74	312.44
2925.35	319.156
2927.97	325.557
2930.58	329.342
2933.19	330.464
2935.8	329.725
2938.41	326.899
2941.02	321.775
2943.63	315.413
2946.24	305.795
2948.84	296.863
2951.45	287.033
2954.05	276.051
2956.65	265.64
2959.26	255.81
2961.86	245.58
2964.46	235.623
2967.06	226.898
2969.66	218.075
2972.25	210.338
2974.85	203.209
2977.45	194.253
2980.04	184.343
2982.64	174.704
2985.23	164.562
2987.82	153.658
2990.41	143.175
2993	132.42
2995.59	122.092
2998.18	111.957
3000.77	100.685
3003.36	90.3696
3005.94	81.5813
3008.53	72.7868
3011.11	64.8651
3013.69	59.4924
3016.28	53.7459
3018.86	48.8928
3021.44	45.6992
3024.02	43.2337
3026.6	40.9733
3029.18	39.231
3031.75	38.6627
3034.33	38.4876
3036.9	38.5511
3039.48	38.718
3042.05	39.1941
3044.62	39.9821
3047.19	40.8695
3049.77	41.4353
3052.34	41.9168
3054.9	42.3775
3057.47	42.5323
3060.04	42.3683
3062.61	40.0469
3065.17	38.4648
3067.74	37.4788
3070.3	34.9857
3072.86	32.2678
3075.42	30.3525
3077.99	27.2479
3080.54	25.0244
3083.1	22.4445
3085.66	20.0942
3088.22	17.1543
3090.78	15.0017
3093.33	13.7694
3095.89	12.4042
3098.44	10.527
3100.99	9.73774
3103.54	8.72648
3106.1	7.84705
3108.65	6.73773
3111.2	5.79148
3113.74	4.7244
3116.29	4.43483
3118.84	4.226
3121.38	4.09625
3123.93	2.99218
3126.47	1.96481
3129.01	2.4405
3131.56	1.00051
3134.1	0.361478
3136.64	0.225921
3139.18	0.0187015
3141.72	0.181462
3144.26	-0.05316
3146.79	0.639646
3149.33	2.24573