File: data/Raman/poly_smoothed/Thy_10_08_05_1x_45s_532 nm_x100_100%_600 gr_mm_01.txt
#Acq. time (s)=	45
#Accumulations=	2
#Range (cm-¹)=	200...3150
#Windows=	2
#Auto scanning=	Off
#Autofocus=	Off
#Macrospot=	Off
#AutoExposure=	Off
#Spike filter=	Multiple accum.
#Delay time (s)=	0
#Binning=	1
#Readout mode=	Signal
#DeNoise=	Off
#ICS correction=	On
#Dark correction=	Off
#Inst. Process=	Off
#Detector Gain=	Best Dynamic Range
#Detector ADC=	20 kHz
#Detector temperature (°C)=	-69.85
#Instrument=	LabRAM HR Evol
#Detector=	Synapse
#Objective=	x100
#Grating=	600 gr/mm
#ND Filter=	100%
#Laser (nm)=	532
#Hole=	100.021
#Range=	Auto
#Laser Pol.=	No
#Raman. Pol.=	No
#Laser Pol. (°)=	-0.0007625
#Raman Pol. (°)=	89.9995
#Collection=	Microscope
#StageXY=	Marzhauser
#StageZ=	Marzhauser
#X (µm)=	2163.1
#Y (µm)=	1244.8
#Z (µm)=	442.15
#Full time(mm:ss)=	3:18
#Project=
#Sample=
#Site=
#Title=	Thy_10_08_05_2x_45s_532 nm_x100_100%_600 gr_mm
#Remark=
#Date=	05.07.2022 14:33
#Acquired=	05.07.2022 14:33:02
#Base:Fit=	10.08.2022 09:45:33
#Base:Fit=	10.08.2022 09:46:03
#Base:Fit=	10.08.2022 09:46:25
#Base:Sub=	10.08.2022 09:46:49
#Filter:Polynom=	16.08.2022 10:24:56
#AxisType[0]=Intens
#AxisUnit[0]=Cnt
#AxisType[1]=Spectr
#AxisUnit[1]=1/cm
200.43	24.4189
204.059	23.5069
207.688	21.3609
211.314	18.4686
214.941	15.9674
218.564	13.0566
222.186	10.5704
225.809	8.42146
229.428	5.61746
233.045	4.57513
236.663	4.1897
240.278	4.00328
243.891	4.86391
247.503	3.3134
251.116	3.44253
254.725	2.1234
258.333	3.13431
261.939	4.31533
265.544	4.46865
269.148	7.49669
272.75	6.96509
276.351	8.26318
279.95	9.95778
283.548	9.22612
287.144	9.7937
290.739	10.2332
294.333	10.947
297.925	10.8964
301.514	12.1236
305.104	12.5316
308.692	13.8338
312.279	12.963
315.862	10.868
319.446	13.6386
323.029	14.1675
326.608	13.6598
330.188	12.3479
333.766	12.8143
337.341	11.1787
340.917	12.2285
344.489	12.9888
348.062	13.2836
351.631	13.2794
355.201	12.0885
358.768	11.7198
362.333	9.79678
365.899	10.0723
369.462	9.54506
373.023	8.12333
376.585	8.79823
380.143	8.4685
383.7	7.37282
387.256	7.78282
390.812	8.47626
394.365	6.88506
397.916	6.15002
401.467	3.29675
405.015	2.67616
408.563	3.18551
412.109	2.54853
415.654	1.77476
419.197	1.3861
422.739	1.59832
426.279	3.13802
429.819	4.20322
433.356	4.0782
436.891	4.18528
440.426	5.24141
443.96	5.10434
447.492	4.72657
451.021	4.92686
454.551	4.39885
458.079	3.88475
461.604	4.04784
465.13	5.39437
468.654	4.35248
472.175	6.7204
475.696	7.20661
479.215	6.39798
482.733	8.42703
486.249	8.74114
489.765	8.26087
493.278	11.2757
496.789	14.3814
500.301	14.4696
503.81	15.1554
507.317	16.0725
510.825	19.9174
514.33	20.3669
517.833	21.175
521.335	22.3733
524.836	23.0248
528.335	24.0514
531.835	22.5095
535.332	23.0581
538.827	22.2688
542.321	20.6534
545.814	18.6435
549.305	18.8413
552.795	18.3482
556.282	19.0334
559.769	19.989
563.255	19.0508
566.739	19.3585
570.223	17.6004
573.705	16.2032
577.183	14.8761
580.663	15.2134
584.141	14.1581
587.615	11.4869
591.09	11.4126
594.564	10.8643
598.035	9.76527
601.506	9.36695
604.974	11.728
608.443	11.6135
611.908	10.7883
615.374	9.99196
618.837	9.63391
622.3	10.4773
625.761	10.4497
629.219	11.2875
632.677	12.4993
636.135	14.7373
639.59	17.1542
643.043	17.9292
646.495	19.2891
649.948	18.6304
653.398	18.8636
656.846	18.8632
660.293	19.7363
663.738	20.0782
667.183	21.7569
670.626	22.2371
674.067	24.1963
677.508	25.9679
680.947	26.9071
684.385	29.2235
687.821	30.4401
691.254	30.2628
694.688	32.3597
698.121	33.4143
701.552	34.7409
704.98	36.1659
708.409	38.9273
711.836	41.504
715.26	42.5027
718.685	43.4441
722.108	45.1718
725.528	46.0342
728.949	46.9868
732.367	48.3895
735.785	50.3689
739.2	49.3775
742.614	50.486
746.028	52.2358
749.439	55.5097
752.849	58.4358
756.26	59.9076
759.667	61.0544
763.073	64.1662
766.477	64.8136
769.883	67.1799
773.285	69.0828
776.686	70.2096
780.085	72.4896
783.484	73.5723
786.881	75.4028
790.276	77.2594
793.671	78.5194
797.064	79.7291
800.456	80.125
803.846	82.0197
807.234	82.4377
810.622	81.6884
814.008	84.0208
817.394	82.8276
820.778	83.7695
824.159	83.919
827.541	86.1895
830.921	86.706
834.298	86.0463
837.676	85.1477
841.051	84.1043
844.426	84.2456
847.798	84.4658
851.171	82.5599
854.54	80.0131
857.911	76.7262
861.278	73.4013
864.645	71.2788
868.01	68.755
871.373	65.1592
874.735	62.9134
878.097	59.2292
881.457	58.4475
884.815	55.8058
888.172	54.0994
891.528	51.523
894.882	50.6425
898.237	50.4141
901.589	50.1412
904.94	49.3117
908.289	50.1033
911.635	49.927
914.982	48.3919
918.328	46.8355
921.672	50.2808
925.015	52.0043
928.357	51.7726
931.698	51.7245
935.035	51.1898
938.373	50.4435
941.71	49.4774
945.044	47.8267
948.378	46.636
951.709	47.1093
955.041	47.0607
958.372	43.1445
961.699	40.8807
965.027	41.4103
968.352	44.1017
971.676	48.4481
975	50.8947
978.322	53.9494
981.642	57.846
984.962	59.3386
988.28	59.9326
991.596	59.1826
994.911	58.8146
998.227	59.4358
1001.54	59.1894
1004.85	59.8302
1008.16	58.1823
1011.47	56.3172
1014.78	53.8265
1018.08	50.0477
1021.39	47.6165
1024.69	44.5602
1028	41.9261
1031.3	39.4064
1034.6	36.0625
1037.9	31.1031
1041.19	25.8776
1044.49	28.189
1047.78	29.5328
1051.08	29.5387
1054.37	29.6226
1057.66	28.5264
1060.95	27.1518
1064.24	26.3655
1067.53	24.7265
1070.81	23.1653
1074.1	22.5839
1077.38	22.2759
1080.66	21.6696
1083.94	21.5782
1087.22	21.4374
1090.5	21.7697
1093.78	20.6906
1097.05	20.7737
1100.33	23.013
1103.6	24.8944
1106.87	25.2824
1110.14	24.5085
1113.41	24.0847
1116.68	23.9078
1119.95	20.302
1123.21	20.082
1126.48	18.316
1129.74	16.8135
1133	13.2065
1136.26	11.9262
1139.52	9.93457
1142.78	10.125
1146.04	9.89847
1149.29	9.41245
1152.55	9.7846
1155.8	7.99058
1159.05	7.13652
1162.3	6.70638
1165.55	4.08819
1168.8	5.90274
1172.05	7.11097
1175.29	6.6055
1178.54	9.34305
1181.78	10.6931
1185.02	11.8904
1188.26	16.0024
1191.5	16.5907
1194.74	19.1284
1197.97	23.4449
1201.21	25.1071
1204.44	28.9867
1207.68	32
1210.91	34.9625
1214.14	40.0339
1217.37	45.0702
1220.59	51.6612
1223.82	58.0769
1227.05	62.0479
1230.27	65.8024
1233.49	67.7572
1236.72	67.8848
1239.94	71.3224
1243.16	73.4214
1246.37	75.0961
1249.59	75.1922
1252.8	74.2566
1256.02	73.6919
1259.23	74.0192
1262.44	72.5557
1265.66	73.5089
1268.86	74.3731
1272.07	74.2008
1275.28	75.137
1278.48	74.0398
1281.69	74.7842
1284.89	74.6251
1288.09	75.1627
1291.29	78.6149
1294.49	81.3716
1297.69	84.0081
1300.89	88.6656
1304.08	89.9985
1307.28	93.4205
1310.47	97.4205
1313.66	99.0068
1316.85	100.74
1320.04	103.663
1323.23	104.605
1326.42	104.389
1329.61	102.905
1332.79	102.24
1335.97	102.21
1339.16	101.19
1342.34	99.3525
1345.52	96.4931
1348.7	92.2828
1351.87	88.6165
1355.05	82.1805
1358.22	77.5065
1361.4	72.6087
1364.57	66.4628
1367.74	61.2344
1370.91	57.606
1374.08	52.2921
1377.25	48.7175
1380.41	45.0789
1383.58	44.2816
1386.74	42.1861
1389.91	38.9933
1393.07	37.2094
1396.23	36.151
1399.39	34.7308
1402.55	33.6248
1405.7	33.7451
1408.86	35.8752
1412.01	40.3478
1415.17	47.3546
1418.32	53.0083
1421.47	58.4605
1424.62	66.5967
1427.77	75.2512
1430.91	83.7399
1434.06	91.5863
1437.2	99.8538
1440.35	106.529
1443.49	110.365
1446.63	112.445
1449.77	113.712
1452.91	112.728
1456.05	110.4
1459.18	108.397
1462.32	101.797
1465.45	93.9864
1468.59	84.3792
1471.72	75.06
1474.85	65.3286
1477.98	54.4794
1481.1	44.6973
1484.23	37.8768
1487.36	30.6743
1490.48	24.6635
1493.61	19.161
1496.73	14.2423
1499.85	12.4278
1502.97	11.9486
1506.09	11.5326
1509.2	10.946
1512.32	11.5653
1515.43	11.9071
1518.55	12.1169
1521.66	11.4277
1524.77	14.4573
1527.88	16.9137
1530.99	19.0033
1534.1	20.5744
1537.21	23.3187
1540.31	24.5931
1543.42	26.2198
1546.52	28.4166
1549.62	32.6517
1552.72	36.9518
1555.82	40.0134
1558.92	43.6479
1562.02	48.2127
1565.11	51.2633
1568.21	53.0745
1571.3	56.318
1574.39	62.7389
1577.49	67.3477
1580.57	72.0949
1583.66	75.6042
1586.75	79.2455
1589.84	82.0986
1592.92	83.8584
1596.01	84.282
1599.09	86.2638
1602.17	88.5047
1605.25	88.5082
1608.33	86.9631
1611.41	85.3718
1614.49	84.0381
1617.57	83.1945
1620.64	83.0341
1623.72	84.8576
1626.79	87.3745
1629.86	88.7844
1632.93	90.1168
1636	92.0692
1639.07	95.6363
1642.13	98.902
1645.2	103.345
1648.26	108.578
1651.33	112.433
1654.39	114.396
1657.45	116.366
1660.51	117.051
1663.57	116.224
1666.63	114.87
1669.68	112.162
1672.74	108.989
1675.79	104.076
1678.85	98.0538
1681.9	89.6568
1684.95	80.4929
1688	72.9924
1691.05	65.8214
1694.09	57.8387
1697.14	50.1456
1700.18	44.3723
1703.23	36.2036
1706.27	30.0269
1709.31	25.5366
1712.35	24.1645
1715.39	22.4078
1718.43	19.4974
1721.47	17.606
1724.5	15.2049
1727.54	14.6523
1730.57	13.0948
1733.61	13.5197
1736.64	13.0956
1739.67	12.3751
1742.7	11.7742
1745.72	11.3215
1748.75	10.2905
1751.77	8.85351
1754.8	7.71645
1757.82	7.1873
1760.84	5.36502
1763.87	4.69361
1766.89	3.62486
1769.91	2.79085
1772.92	2.0505
1775.94	0.880312
1778.95	-0.0214829
1781.97	0.531319
1784.98	1.99111
1787.99	1.27765
1791.01	0.361999
1794.01	-0.193153
1797.02	-0.899683
1800.03	-0.626837
1803.04	-1.18603
1806.04	-1.03466
1809.05	-0.853879
1812.05	-0.183803
1815.05	-0.559268
1818.05	0.133204
1821.05	0.52593
1824.05	0.838911
1827.05	0.440052
1830.04	1.7886
1833.04	2.69896
1836.03	2.90535
1839.03	3.99789
1842.02	4.10697
1845.01	4.87271
1848	5.68654
1850.99	6.81301
1853.97	6.8879
1856.96	6.61841
1859.94	6.84204
1862.93	6.94813
1865.91	6.18601
1868.89	5.92063
1871.87	5.07559
1874.85	5.18922
1877.83	4.74612
1880.81	4.80432
1882.57	4.24893
1885.56	4.2837
1888.55	4.63169
1891.54	4.83358
1894.52	4.80262
1897.51	5.49594
1900.49	4.97803
1903.47	5.67378
1906.45	6.1074
1909.43	6.01733
1912.41	6.31816
1915.39	7.69345
1918.37	8.51427
1921.34	8.31899
1924.32	8.15216
1927.29	7.47023
1930.26	7.62476
1933.23	7.60001
1936.2	6.83099
1939.17	6.5307
1942.14	7.42201
1945.11	7.16735
1948.07	7.47416
1951.04	7.96028
1954	9.02806
1956.96	9.49782
1959.93	10.8433
1962.89	11.1957
1965.85	10.5665
1968.8	11.6224
1971.76	11.9027
1974.72	12.1438
1977.67	13.3339
1980.63	13.0547
1983.58	13.9072
1986.53	14.0249
1989.48	13.2503
1992.43	12.6535
1995.38	12.6846
1998.32	13.6009
2001.27	13.2758
2004.22	13.1876
2007.16	13.5766
2010.1	13.888
2013.04	13.7809
2015.98	13.7118
2018.92	14.4172
2021.86	15.2195
2024.8	15.5672
2027.74	15.9768
2030.67	15.145
2033.61	16.2284
2036.54	15.9042
2039.47	17.2337
2042.4	18.6841
2045.33	19.8141
2048.26	20.2462
2051.19	21.0199
2054.12	21.7834
2057.04	21.6464
2059.97	21.936
2062.89	21.6228
2065.81	20.8346
2068.73	21.7392
2071.65	21.9625
2074.57	20.4803
2077.49	19.3389
2080.41	19.6896
2083.32	20.4716
2086.24	19.6649
2089.15	19.5809
2092.07	19.3651
2094.98	19.509
2097.89	18.4291
2100.8	18.3783
2103.71	19.3592
2106.61	21.052
2109.52	22.0383
2112.43	23.0276
2115.33	23.5882
2118.23	24.3853
2121.13	27.0382
2124.04	28.9295
2126.94	30.8129
2129.83	32.748
2132.73	33.7463
2135.63	36.9249
2138.53	40.807
2141.42	42.9442
2144.31	46.0302
2147.21	47.8449
2150.1	49.728
2152.99	53.1217
2155.88	54.952
2158.77	56.1187
2161.65	56.5687
2164.54	57.6681
2167.43	58.3529
2170.31	58.7177
2173.19	58.2063
2176.07	56.3893
2178.96	55.9614
2181.84	54.7634
2184.72	53.1867
2187.59	52.6834
2190.47	51.762
2193.35	51.1137
2196.22	50.1974
2199.09	48.2554
2201.97	47.133
2204.84	47.4173
2207.71	46.8084
2210.58	45.0251
2213.45	43.8057
2216.31	42.072
2219.18	39.9238
2222.05	39.5258
2224.91	39.1478
2227.78	37.6455
2230.64	36.7418
2233.5	35.8286
2236.36	35.4436
2239.22	34.1687
2242.08	33.4877
2244.93	31.8149
2247.79	31.8717
2250.64	30.3553
2253.5	29.4985
2256.35	30.0924
2259.2	30.3738
2262.05	30.3729
2264.9	30.4084
2267.75	29.2183
2270.6	28.4765
2273.45	28.2016
2276.29	26.8185
2279.14	26.0448
2281.98	25.4658
2284.82	25.0118
2287.66	23.6214
2290.5	22.2681
2293.34	21.2099
2296.18	21.9267
2299.02	22.4965
2301.86	23.0185
2304.69	24.2925
2307.53	23.3834
2310.36	23.8489
2313.19	23.9056
2316.02	24.4261
2318.85	23.7734
2321.68	22.3826
2324.51	23.2534
2327.34	22.8459
2330.16	22.5799
2332.99	21.2845
2335.81	20.513
2338.64	18.305
2341.46	17.8832
2344.28	15.5631
2347.1	14.4795
2349.92	13.6109
2352.74	12.6405
2355.55	10.6904
2358.37	9.60714
2361.19	8.36278
2364	9.57383
2366.81	10.2329
2369.62	10.3292
2372.44	10.3933
2375.24	11.1328
2378.05	12.1332
2380.86	11.4358
2383.67	12.88
2386.47	13.3761
2389.28	13.0025
2392.08	13.4992
2394.89	14.2038
2397.69	14.7498
2400.49	13.8298
2403.29	14.1028
2406.09	13.8053
2408.88	13.2932
2411.68	12.5882
2414.48	12.3229
2417.27	12.3668
2420.06	11.8049
2422.86	10.8544
2425.65	9.64745
2428.44	8.10972
2431.23	7.87306
2434.02	8.21416
2436.81	7.33889
2439.59	6.80747
2442.38	5.93825
2445.16	5.18585
2447.95	4.22522
2450.73	3.35924
2453.51	3.85624
2456.29	4.1783
2459.07	2.90202
2461.85	2.9697
2464.63	2.72034
2467.4	3.55131
2470.18	3.80766
2472.95	5.22582
2475.73	6.44725
2478.5	7.08154
2481.27	8.1949
2484.04	8.1659
2486.81	9.03492
2489.58	7.79919
2492.35	7.23356
2495.12	8.22567
2497.88	8.23073
2500.65	8.67952
2503.41	7.25723
2506.17	5.87513
2508.94	4.88488
2511.7	3.77928
2514.46	1.83492
2517.22	1.12112
2519.97	0.219902
2522.73	0.805087
2525.49	0.975454
2528.24	0.58719
2530.99	1.18296
2533.75	1.55313
2536.5	1.51632
2539.25	1.65715
2542	2.21917
2544.75	2.67345
2547.5	2.25272
2550.24	1.97833
2552.99	2.19026
2555.74	2.10324
2558.48	3.45875
2561.22	3.28849
2563.96	3.163
2566.71	3.22393
2569.45	3.12859
2572.18	3.15649
2574.92	2.22449
2577.66	1.95058
2580.4	1.37796
2583.13	1.06676
2585.87	0.951458
2588.6	1.57389
2591.33	1.69328
2594.06	1.46852
2596.79	1.37773
2599.52	0.677171
2602.25	0.951662
2604.98	0.812686
2607.71	0.737078
2610.43	0.939409
2613.16	1.0126
2615.88	0.969546
2618.6	1.82032
2621.32	3.30313
2624.04	3.64798
2626.76	4.4148
2629.48	3.4488
2632.2	3.32949
2634.92	3.62816
2637.63	2.82132
2640.35	2.61157
2643.06	2.10935
2645.77	2.53868
2648.49	2.5867
2651.2	1.82723
2653.91	1.36511
2656.62	1.34883
2659.33	2.13987
2662.03	2.82579
2664.74	2.80233
2667.44	2.58144
2670.15	2.27845
2672.85	1.86591
2675.55	1.29662
2678.26	2.00244
2680.96	2.32392
2683.66	2.03507
2686.35	2.34759
2689.05	3.50737
2691.75	3.94705
2694.44	3.74435
2697.14	3.39413
2699.83	5.08846
2702.52	6.18219
2705.22	6.97708
2707.91	8.20707
2710.6	9.04597
2713.29	10.3853
2715.97	10.7001
2718.66	11.6008
2721.35	11.6726
2724.03	12.8967
2726.72	12.3937
2729.4	12.6354
2732.08	11.1689
2734.76	11.2868
2737.44	10.8914
2740.12	10.7866
2742.8	10.2454
2745.48	10.441
2748.16	9.63966
2750.83	8.96926
2753.51	8.83583
2756.18	8.13521
2758.85	7.22535
2761.53	6.49442
2764.2	6.54329
2766.87	5.20813
2769.54	4.52758
2772.2	4.1926
2774.87	3.97248
2777.54	2.61196
2780.2	2.5606
2782.87	0.880503
2785.53	0.929647
2788.19	0.162725
2790.85	0.532981
2793.51	0.970516
2796.17	1.56035
2798.83	2.24334
2801.49	3.34214
2804.15	3.42997
2806.8	3.75826
2809.46	4.14967
2812.11	3.80742
2814.76	3.96917
2817.42	4.34547
2820.07	6.05315
2822.72	9.18274
2825.37	12.1146
2828.02	15.4669
2830.66	19.1801
2833.31	23.5215
2835.96	29.3351
2838.6	36.2289
2841.24	43.6477
2843.89	53.4418
2846.53	64.6074
2849.17	76.9083
2851.81	90.8402
2854.45	104.01
2857.09	117.887
2859.72	131.181
2862.36	144.246
2865	156.503
2867.63	167.225
2870.26	177.629
2872.9	187.644
2875.53	196.323
2878.16	204.689
2880.79	211.687
2883.42	217.2
2886.05	222.928
2888.67	228.732
2891.3	234.135
2893.92	241.539
2896.55	248.428
2899.17	256.479
2901.79	266.944
2904.42	279.388
2907.04	293.776
2909.66	310.141
2912.27	327.257
2914.89	344.226
2917.51	360.387
2920.13	374.682
2922.74	386.914
2925.35	397.283
2927.97	404.005
2930.58	406.842
2933.19	406.989
2935.8	404.342
2938.41	398.924
2941.02	391.528
2943.63	381.081
2946.24	369.535
2948.84	356.985
2951.45	344.608
2954.05	331.361
2956.65	318.273
2959.26	303.966
2961.86	289.849
2964.46	276.542
2967.06	264.179
2969.66	254.03
2972.25	243.761
2974.85	233.499
2977.45	221.693
2980.04	210.662
2982.64	198.795
2985.23	185.635
2987.82	173.404
2990.41	159.184
2993	145.189
2995.59	131.413
2998.18	118.973
3000.77	107.004
3003.36	97.0865
3005.94	87.5798
3008.53	77.794
3011.11	70.5032
3013.69	62.7936
3016.28	57.3582
3018.86	51.4208
3021.44	46.7386
3024.02	42.9141
3026.6	39.6679
3029.18	37.8322
3031.75	37.1268
3034.33	36.2086
3036.9	36.45
3039.48	37.0046
3042.05	38.4395
3044.62	42.0012
3047.19	43.7357
3049.77	46.4038
3052.34	47.5934
3054.9	48.3807
3057.47	48.5776
3060.04	47.9918
3062.61	46.5601
3065.17	46.1299
3067.74	44.1927
3070.3	41.9055
3072.86	38.4048
3075.42	34.5464
3077.99	30.7661
3080.54	26.6934
3083.1	23.01
3085.66	18.6263
3088.22	15.1794
3090.78	11.9099
3093.33	9.88925
3095.89	7.62132
3098.44	6.89917
3100.99	6.8992
3103.54	6.35997
3106.1	6.62358
3108.65	6.70686
3111.2	6.02449
3113.74	5.23206
3116.29	4.34883
3118.84	4.37749
3121.38	4.29582
3123.93	3.97435
3126.47	4.49167
3129.01	4.84418
3131.56	4.08492
3134.1	3.16466
3136.64	1.70472
3139.18	0.976895
3141.72	0.640587
3144.26	0.0854393
3146.79	-0.254166
3149.33	1.19529