File: data/Raman/poly_smoothed/Thy_30_10_47_1x_45s_532 nm_x100_100%_600 gr_mm_01.txt
#Acq. time (s)=	45
#Accumulations=	2
#Range (cm-¹)=	200...3150
#Windows=	2
#Auto scanning=	Off
#Autofocus=	Off
#Macrospot=	Off
#AutoExposure=	Off
#Spike filter=	Multiple accum.
#Delay time (s)=	0
#Binning=	1
#Readout mode=	Signal
#DeNoise=	Off
#ICS correction=	On
#Dark correction=	Off
#Inst. Process=	Off
#Detector Gain=	Best Dynamic Range
#Detector ADC=	20 kHz
#Detector temperature (°C)=	-69.85
#Instrument=	LabRAM HR Evol
#Detector=	Synapse
#Objective=	x100
#Grating=	600 gr/mm
#ND Filter=	100%
#Laser (nm)=	532
#Hole=	100.021
#Range=	Auto
#Laser Pol.=	No
#Raman. Pol.=	No
#Laser Pol. (°)=	-0.0007625
#Raman Pol. (°)=	89.9995
#Collection=	Microscope
#StageXY=	Marzhauser
#StageZ=	Marzhauser
#X (µm)=	4721.1
#Y (µm)=	-7700.7
#Z (µm)=	584.45
#Full time(mm:ss)=	3:18
#Project=
#Sample=
#Site=
#Title=	Thy_30_10_47_2x_45s_532 nm_x100_100%_600 gr_mm
#Remark=
#Date=	30.06.2022 14:46
#Acquired=	30.06.2022 14:46:41
#Base:Fit=	10.08.2022 09:58:11
#Base:Sub=	10.08.2022 09:58:44
#Filter:Polynom=	16.08.2022 10:22:53
#AxisType[0]=Intens
#AxisUnit[0]=Cnt
#AxisType[1]=Spectr
#AxisUnit[1]=1/cm
200.533	-5.37044
204.162	3.59509
207.792	8.39051
211.418	11.6572
215.044	13.2638
218.667	15.1888
222.289	16.8399
225.912	19.7612
229.531	23.5115
233.148	25.9981
236.766	29.3426
240.381	30.287
243.994	32.928
247.606	34.9387
251.217	36.6489
254.828	40.2712
258.436	41.4812
262.042	43.8245
265.647	46.279
269.25	50.1702
272.852	52.2281
276.453	52.4763
280.052	53.1964
283.65	53.9452
287.247	50.5205
290.842	50.1475
294.436	48.5095
298.028	45.8675
301.617	44.4409
305.206	42.2925
308.794	39.7257
312.381	38.8214
315.964	37.154
319.548	34.3999
323.131	31.9787
326.71	28.6919
330.29	26.4972
333.868	25.7283
337.443	24.4968
341.018	21.4593
344.591	20.5767
348.163	17.7579
351.733	17.4819
355.303	15.6766
358.869	13.8552
362.435	12.976
366.001	11.354
369.563	9.07446
373.124	7.15891
376.686	6.40152
380.244	5.00512
383.801	4.19647
387.357	4.83738
390.911	4.14972
394.466	4.21078
398.018	5.88555
401.568	3.00091
405.117	2.55991
408.664	1.16943
412.21	2.96364
415.755	2.31915
419.298	3.21462
422.84	3.24396
426.38	3.80714
429.919	3.7795
433.455	5.95761
436.992	4.84774
440.527	4.48478
444.06	1.34545
447.593	1.50651
451.122	1.91217
454.651	2.46953
458.18	2.44483
461.705	4.17334
465.23	5.01887
468.752	8.15062
472.275	9.16341
475.797	10.9904
479.315	13.1232
482.834	15.3633
486.349	16.2782
489.863	17.2951
493.378	19.6757
496.889	21.7592
500.401	20.9047
503.91	20.809
507.417	21.5579
510.923	21.7605
514.43	22.2223
517.933	23.2555
521.435	21.2388
524.936	20.1606
528.435	18.5905
531.933	18.4051
535.43	18.3676
538.927	18.3614
542.421	19.7097
545.913	20.8372
549.403	20.3855
552.893	19.9887
556.381	21.03
559.868	22.097
563.354	21.4733
566.839	21.2588
570.322	21.6128
573.802	19.0529
577.283	16.7922
580.762	14.8417
584.24	13.1229
587.714	12.5483
591.19	11.344
594.663	11.3004
598.134	11.1983
601.605	11.7693
605.073	11.9313
608.542	12.3519
612.007	13.2846
615.473	13.7767
618.936	16.9037
622.397	16.202
625.859	18.9687
629.318	19.1925
632.775	17.9661
636.233	17.4819
639.688	19.0254
643.142	19.394
646.594	20.7476
650.045	20.383
653.496	20.9527
656.944	21.3777
660.391	21.1288
663.837	21.2992
667.281	22.4358
670.724	21.9896
674.166	22.7507
677.606	24.6647
681.045	24.7056
684.483	25.9668
687.917	28.3278
691.352	28.7152
694.786	31.0166
698.219	32.0486
701.65	32.6325
705.078	34.9803
708.506	33.7906
711.934	34.2916
715.358	33.0038
718.782	32.8105
722.204	34.4091
725.626	36.4399
729.045	37.4356
732.464	39.4153
735.881	39.217
739.297	40.6732
742.711	44.509
746.125	44.8675
749.537	46.5285
752.946	51.0835
756.357	52.9223
759.764	55.8168
763.17	58.5705
766.575	62.3866
769.978	65.8574
773.382	69.4416
776.783	72.9398
780.182	75.5682
783.581	77.9543
786.978	80.7553
790.373	83.5572
793.768	86.0998
797.161	89.4006
800.552	90.2917
803.941	92.5942
807.33	94.1841
810.718	94.5564
814.105	93.0323
817.49	94.6221
820.873	96.9027
824.256	97.9953
827.637	97.8074
831.016	97.4606
834.395	96.9645
837.772	96.7091
841.147	95.146
844.522	95.1301
847.894	92.4757
851.267	92.0213
854.637	89.9782
858.007	87.9126
861.374	85.3204
864.739	82.6978
868.106	80.5978
871.469	76.6931
874.831	75.3525
878.193	72.3533
881.553	68.4204
884.911	66.1317
888.268	64.3659
891.623	61.9454
894.978	60.4063
898.331	60.1776
901.683	60.5887
905.033	57.9185
908.383	58.6898
911.731	56.4114
915.078	56.6125
918.423	54.746
921.768	53.5728
925.111	54.1034
928.452	51.2209
931.791	47.0224
935.13	46.7106
938.468	44.5696
941.803	41.9853
945.139	37.1633
948.473	34.0721
951.804	31.728
955.136	30.2593
958.465	27.3288
961.794	25.0804
965.12	24.8416
968.447	25.0012
971.771	22.5114
975.095	21.278
978.417	21.7393
981.737	21.0618
985.057	20.4812
988.375	18.3837
991.691	18.196
995.006	17.0864
998.32	16.0524
1001.63	14.2196
1004.95	12.7288
1008.26	11.4658
1011.56	11.3178
1014.87	10.2618
1018.18	9.56726
1021.48	7.75017
1024.79	6.95234
1028.09	7.30049
1031.39	9.14523
1034.69	11.3239
1037.99	11.2937
1041.29	13.1513
1044.58	13.1829
1047.88	13.3326
1051.17	14.2866
1054.46	14.2939
1057.75	15.5261
1061.04	16.0506
1064.33	14.1334
1067.62	12.772
1070.9	12.6072
1074.19	13.4461
1077.47	11.0423
1080.76	10.5939
1084.04	11.9825
1087.32	11.3685
1090.59	13.0653
1093.87	13.0389
1097.15	11.0838
1100.42	11.3844
1103.69	12.9931
1106.97	13.2291
1110.24	14.5498
1113.51	14.9794
1116.77	13.2645
1120.04	12.2472
1123.31	12.4914
1126.57	11.4848
1129.83	11.843
1133.1	10.8096
1136.36	9.07008
1139.62	7.89119
1142.87	5.6328
1146.13	3.61733
1149.38	2.8872
1152.64	2.47051
1155.89	-0.0261965
1159.14	-1.49302
1162.39	0.209391
1165.64	-1.42985
1168.89	-0.879634
1172.14	0.420331
1175.38	1.72546
1178.63	1.62647
1181.87	3.81598
1185.11	4.0118
1188.35	4.63479
1191.59	8.79521
1194.83	12.6522
1198.07	15.616
1201.3	17.4898
1204.53	19.2975
1207.77	21.5053
1211	24.6211
1214.23	27.3162
1217.46	30.8801
1220.69	32.7063
1223.91	36.0415
1227.14	38.8799
1230.36	41.7457
1233.59	44.836
1236.81	47.9179
1240.03	51.8202
1243.25	54.3542
1246.46	57.4286
1249.68	58.2803
1252.9	59.9422
1256.11	59.1612
1259.32	61.2444
1262.54	63.3235
1265.75	63.4789
1268.96	66.4178
1272.16	68.9041
1275.37	67.4999
1278.57	68.0648
1281.78	69.1016
1284.98	69.8304
1288.18	71.9734
1291.38	73.9189
1294.58	74.7843
1297.78	76.2726
1300.98	77.9176
1304.17	81.993
1307.37	83.7593
1310.56	85.4085
1313.76	86.8814
1316.95	89.5055
1320.14	90.5164
1323.32	88.8954
1326.51	87.2531
1329.7	86.3878
1332.88	85.103
1336.07	84.4054
1339.25	83.9776
1342.43	83.1272
1345.61	83.6898
1348.79	83.5231
1351.96	81.6518
1355.14	77.1158
1358.31	75.6043
1361.49	73.4357
1364.66	71.3072
1367.83	69.1793
1371	68.3794
1374.17	65.4799
1377.34	65.0305
1380.5	64.2832
1383.67	63.8601
1386.83	62.4466
1390	63.1863
1393.16	61.3259
1396.32	60.7374
1399.48	59.6667
1402.64	57.483
1405.79	56.6815
1408.95	57.0194
1412.1	58.4782
1415.26	62.8887
1418.41	66.7718
1421.56	72.4359
1424.71	77.614
1427.86	83.5064
1431	89.3221
1434.15	94.5043
1437.29	101.939
1440.44	107.187
1443.58	111.155
1446.72	114.534
1449.86	116.632
1453	116.789
1456.14	118.924
1459.27	117.555
1462.41	116.092
1465.54	112.464
1468.67	107.655
1471.81	101.889
1474.94	97.3801
1478.07	92.0955
1481.19	85.4471
1484.32	79.5023
1487.45	76.4095
1490.57	72.3848
1493.69	70.2389
1496.82	68.7347
1499.94	69.8913
1503.06	69.5478
1506.17	69.1356
1509.29	69.6714
1512.41	70.6906
1515.52	72.0496
1518.64	75.4161
1521.75	76.6763
1524.86	78.1454
1527.97	78.8236
1531.08	81.5236
1534.19	83.7558
1537.29	85.8768
1540.4	86.2544
1543.5	89.9742
1546.61	91.8046
1549.71	95.7684
1552.81	99.8116
1555.91	100.751
1559.01	103.19
1562.11	105.812
1565.2	110.364
1568.29	113.103
1571.39	117.384
1574.48	120.405
1577.57	121.298
1580.66	123.419
1583.75	126.937
1586.84	129.348
1589.93	131.691
1593.01	132.897
1596.1	134.733
1599.18	137.443
1602.26	138.307
1605.34	138.594
1608.42	137.732
1611.5	140.133
1614.58	139.02
1617.65	138.614
1620.73	139.223
1623.8	140.852
1626.87	143.606
1629.95	143.687
1633.02	146.62
1636.09	150.098
1639.15	152.642
1642.22	156.666
1645.29	158.48
1648.35	161.045
1651.42	162.46
1654.48	164.442
1657.54	168.18
1660.6	168.621
1663.66	167.742
1666.72	167.427
1669.77	168.646
1672.83	168.474
1675.88	165.882
1678.93	161.445
1681.99	156.359
1685.04	151.722
1688.09	148.311
1691.13	141.529
1694.18	138.314
1697.23	135.295
1700.27	133.083
1703.32	129.793
1706.36	126.618
1709.4	124.821
1712.44	122.761
1715.48	121.644
1718.52	121.028
1721.56	119.488
1724.59	118.37
1727.63	118.07
1730.66	116.949
1733.69	115.13
1736.72	112.544
1739.75	110.907
1742.78	110.838
1745.81	108.602
1748.84	105.133
1751.86	101.966
1754.89	98.4344
1757.91	98.1728
1760.93	96.468
1763.95	94.5078
1766.97	90.9696
1769.99	89.2932
1773.01	87.2562
1776.03	86.1315
1779.04	83.8706
1782.06	80.86
1785.07	78.6592
1788.08	76.7519
1791.09	74.4971
1794.1	70.788
1797.11	68.5754
1800.12	65.6563
1803.12	64.4355
1806.13	61.8747
1809.13	58.9714
1812.14	56.3739
1815.14	53.3954
1818.14	51.6217
1821.14	50.0145
1824.14	48.1783
1827.13	46.8456
1830.13	44.315
1833.12	42.7717
1836.12	39.9317
1839.11	38.1432
1842.1	36.4756
1845.09	34.6367
1848.08	31.9922
1851.07	29.5464
1854.06	26.5514
1857.04	23.8394
1860.03	20.1492
1863.01	18.1415
1866	14.8748
1868.98	13.8885
1871.96	12.5272
1874.94	12.3009
1877.92	11.9679
1880.89	11.0851
1882.48	11.0767
1885.47	11.7906
1888.46	12.1386
1891.44	11.2413
1894.43	11.0474
1897.41	10.4247
1900.4	10.0689
1903.38	9.12135
1906.36	8.96504
1909.34	9.51915
1912.32	8.93179
1915.29	8.05722
1918.27	6.46983
1921.25	5.32007
1924.22	5.63792
1927.2	5.20439
1930.17	5.82005
1933.14	5.61209
1936.11	3.6444
1939.08	4.87347
1942.05	5.57237
1945.01	6.95089
1947.98	5.89478
1950.94	4.99497
1953.91	6.16035
1956.87	6.50803
1959.83	6.31668
1962.79	4.39724
1965.75	3.31589
1968.71	3.03074
1971.67	2.10832
1974.62	2.39839
1977.58	2.0187
1980.53	-0.0312154
1983.48	-0.0997845
1986.43	-0.870376
1989.38	-1.4717
1992.33	-0.267332
1995.28	0.700106
1998.23	2.31898
2001.18	4.10462
2004.12	5.19107
2007.06	6.4722
2010.01	8.49
2012.95	10.3654
2015.89	12.0164
2018.83	14.4127
2021.77	15.7758
2024.71	17.6124
2027.64	18.2932
2030.58	18.9358
2033.51	21.0266
2036.45	19.9829
2039.38	22.0565
2042.31	21.6588
2045.24	21.8017
2048.17	21.8484
2051.1	20.8109
2054.02	18.9284
2056.95	19.4346
2059.87	17.9789
2062.8	18.705
2065.72	19.6987
2068.64	19.9311
2071.56	20.9991
2074.48	21.2865
2077.4	23.1212
2080.31	25.3288
2083.23	25.7829
2086.14	28.8072
2089.06	29.3852
2091.97	30.7096
2094.88	31.2787
2097.79	30.6879
2100.7	32.15
2103.61	34.5512
2106.52	36.011
2109.43	37.3911
2112.33	38.9595
2115.24	40.3581
2118.14	42.6425
2121.04	45.6489
2123.94	47.3964
2126.84	49.9445
2129.74	53.1528
2132.64	56.2614
2135.54	58.5202
2138.43	61.2131
2141.33	62.7081
2144.22	66.6649
2147.11	68.9425
2150.01	70.3337
2152.9	71.7724
2155.79	72.9629
2158.67	74.3559
2161.56	76.4966
2164.45	77.2612
2167.33	79.0865
2170.22	79.6372
2173.1	80.347
2175.98	80.3114
2178.86	82.0854
2181.74	81.3002
2184.62	81.213
2187.5	81.1543
2190.38	81.2986
2193.25	81.1905
2196.13	79.7897
2199	77.5312
2201.88	75.7279
2204.75	71.5944
2207.62	68.143
2210.49	65.8492
2213.36	63.5931
2216.22	59.7802
2219.09	56.8965
2221.96	55.1638
2224.82	53.52
2227.68	48.7336
2230.55	47.2569
2233.41	45.8827
2236.27	43.4699
2239.12	41.11
2241.98	37.8382
2244.84	36.4196
2247.7	36.046
2250.55	35.5536
2253.41	34.6054
2256.26	33.7839
2259.11	33.2426
2261.96	32.7416
2264.81	32.5699
2267.66	32.2196
2270.51	31.8814
2273.35	31.2247
2276.2	31.8066
2279.04	32.9787
2281.89	32.5481
2284.73	32.616
2287.57	31.6096
2290.41	31.2141
2293.25	28.9748
2296.09	27.0896
2298.93	27.8492
2301.76	28.8996
2304.6	27.4566
2307.44	27.0485
2310.27	25.1189
2313.1	25.9888
2315.93	26.4928
2318.76	26.3813
2321.59	25.9441
2324.42	24.4099
2327.25	23.4474
2330.07	23.7029
2332.9	23.1069
2335.72	24.4761
2338.55	23.6826
2341.37	22.7965
2344.19	22.9428
2347.01	23.3251
2349.83	21.9744
2352.65	21.1889
2355.46	19.8951
2358.28	17.9556
2361.09	17.012
2363.91	16.7795
2366.72	17.9113
2369.53	18.1535
2372.34	16.3499
2375.15	16.2875
2377.96	15.9029
2380.77	16.5615
2383.58	15.6071
2386.38	14.6651
2389.19	13.1179
2391.99	12.9847
2394.8	13.3252
2397.6	14.6431
2400.4	14.9423
2403.2	15.1798
2406	15.1085
2408.79	15.7107
2411.59	16.5655
2414.39	17.3874
2417.18	18.9399
2419.98	18.4084
2422.77	17.5532
2425.56	16.7898
2428.35	15.3845
2431.14	16.2869
2433.93	15.6634
2436.72	15.4385
2439.5	14.5256
2442.29	12.8148
2445.07	10.8905
2447.86	10.7669
2450.64	9.70229
2453.42	9.22253
2456.2	9.72983
2458.98	9.03352
2461.76	8.93258
2464.54	9.42526
2467.32	7.51775
2470.09	5.66164
2472.87	4.24668
2475.64	4.13941
2478.41	4.42837
2481.18	4.27689
2483.95	4.423
2486.72	3.25075
2489.49	2.56394
2492.26	3.57992
2495.03	4.94562
2497.79	4.08809
2500.56	5.66112
2503.32	4.55381
2506.09	4.69644
2508.85	4.0884
2511.61	3.98582
2514.37	5.78287
2517.13	6.7458
2519.89	6.66456
2522.64	5.93418
2525.4	6.60523
2528.15	7.0941
2530.91	6.25119
2533.66	5.35767
2536.41	5.90699
2539.16	4.51513
2541.91	3.79837
2544.66	4.13088
2547.41	5.09821
2550.16	5.69775
2552.9	6.61972
2555.65	7.84501
2558.39	7.64754
2561.13	8.41576
2563.88	7.76412
2566.62	6.85174
2569.36	6.49628
2572.1	5.44411
2574.84	4.84933
2577.57	3.23576
2580.31	4.82444
2583.05	4.54358
2585.78	4.21314
2588.51	3.62222
2591.24	4.88649
2593.98	5.49751
2596.71	5.21908
2599.44	5.36041
2602.16	5.31718
2604.89	5.2514
2607.62	4.79198
2610.34	5.35138
2613.07	5.29864
2615.79	6.13175
2618.52	5.88678
2621.24	5.93005
2623.96	4.60524
2626.68	2.84781
2629.4	2.68251
2632.11	1.21232
2634.83	-0.0981363
2637.55	-0.525403
2640.26	-1.30545
2642.98	-2.18072
2645.69	-1.86031
2648.4	-1.52596
2651.11	-1.30003
2653.82	-1.98313
2656.53	-0.767349
2659.24	0.204236
2661.95	-0.757252
2664.65	0.647559
2667.36	0.627665
2670.06	1.42224
2672.76	3.43295
2675.47	3.71017
2678.17	4.72612
2680.87	4.43013
2683.57	5.73803
2686.27	5.80023
2688.97	6.80497
2691.66	6.18145
2694.36	5.69801
2697.05	5.35846
2699.75	5.39569
2702.44	5.40716
2705.13	3.84897
2707.82	4.10925
2710.51	5.68283
2713.2	6.27008
2715.89	7.10807
2718.57	7.5656
2721.26	7.30699
2723.95	8.66827
2726.63	8.47831
2729.31	9.74862
2732	10.1355
2734.68	9.10259
2737.36	9.22822
2740.04	10.6849
2742.72	9.69519
2745.39	8.52212
2748.07	7.77021
2750.75	7.11976
2753.42	7.00587
2756.09	7.14033
2758.77	6.58846
2761.44	5.51717
2764.11	3.99918
2766.78	2.92687
2769.45	1.7247
2772.12	1.86373
2774.78	2.19264
2777.45	2.68409
2780.12	1.83598
2782.78	3.62782
2785.44	3.61027
2788.11	3.20348
2790.77	4.36625
2793.43	5.30228
2796.09	4.97212
2798.75	5.58237
2801.4	7.05716
2804.06	8.94687
2806.72	9.33784
2809.37	7.89543
2812.03	8.22042
2814.68	9.26528
2817.33	11.4283
2819.98	12.3874
2822.63	15.1517
2825.28	16.6006
2827.93	16.6904
2830.58	20.7464
2833.23	23.3344
2835.87	26.0299
2838.52	29.5592
2841.16	33.4454
2843.8	38.1699
2846.44	43.6456
2849.08	50.1084
2851.73	56.0215
2854.36	63.6527
2857	71.693
2859.64	78.9887
2862.28	86.5409
2864.91	94.3371
2867.55	101.033
2870.18	106.713
2872.81	111.772
2875.44	116.31
2878.07	121.682
2880.7	125.096
2883.33	129.187
2885.96	133.22
2888.59	137.282
2891.21	140.338
2893.84	146.495
2896.46	152.597
2899.09	156.913
2901.71	165.054
2904.33	172.912
2906.95	182.111
2909.57	192.795
2912.19	201.789
2914.81	212.2
2917.43	223.44
2920.04	233.625
2922.66	241.731
2925.27	247.36
2927.88	251.935
2930.5	255.425
2933.11	255.575
2935.72	254.11
2938.33	248.834
2940.94	243.769
2943.54	237.523
2946.15	229.037
2948.76	220.911
2951.36	211.225
2953.97	202.937
2956.57	194.397
2959.17	187.006
2961.77	176.843
2964.37	168.48
2966.97	161.405
2969.57	153.634
2972.17	146.573
2974.77	139.74
2977.36	131.802
2979.96	126.003
2982.55	119.058
2985.15	110.367
2987.74	103.173
2990.33	95.7345
2992.92	88.1477
2995.51	79.7557
2998.1	71.3503
3000.69	63.6484
3003.27	57.5597
3005.86	52.6561
3008.44	47.4096
3011.03	42.6849
3013.61	37.9664
3016.19	35.1828
3018.78	32.6311
3021.36	30.2549
3023.94	27.4184
3026.51	26.1731
3029.09	26.2836
3031.67	25.5904
3034.24	26.6891
3036.82	27.2852
3039.39	27.0078
3041.97	29.0956
3044.54	30.9224
3047.11	31.4176
3049.68	32.7127
3052.25	32.9229
3054.82	32.7384
3057.39	32.0151
3059.96	31.582
3062.52	29.9346
3065.09	29.5823
3067.65	27.8355
3070.22	27.2073
3072.78	25.2178
3075.34	23.5526
3077.9	20.9443
3080.46	19.9603
3083.02	18.1598
3085.58	17.456
3088.14	16.0309
3090.69	14.5869
3093.25	13.7934
3095.8	13.5514
3098.36	12.7996
3100.91	12.8195
3103.46	13.6082
3106.01	13.8876
3108.56	13.7088
3111.11	12.8355
3113.66	11.3289
3116.21	9.85865
3118.76	9.04148
3121.3	8.20763
3123.85	6.84206
3126.39	4.77767
3128.93	4.61644
3131.48	3.94336
3134.02	3.68181
3136.56	2.58248
3139.1	1.63356
3141.64	1.90031
3144.17	1.72525
3146.71	1.87491
3149.25	2.08635