File: data/Raman/poly_smoothed/Thy_30_10_42_1x_45s_532 nm_x100_100%_600 gr_mm_01.txt
#Acq. time (s)=	45
#Accumulations=	2
#Range (cm-¹)=	200...3150
#Windows=	2
#Auto scanning=	Off
#Autofocus=	Off
#Macrospot=	Off
#AutoExposure=	Off
#Spike filter=	Multiple accum.
#Delay time (s)=	0
#Binning=	1
#Readout mode=	Signal
#DeNoise=	Off
#ICS correction=	On
#Dark correction=	Off
#Inst. Process=	Off
#Detector Gain=	Best Dynamic Range
#Detector ADC=	20 kHz
#Detector temperature (°C)=	-69.85
#Instrument=	LabRAM HR Evol
#Detector=	Synapse
#Objective=	x100
#Grating=	600 gr/mm
#ND Filter=	100%
#Laser (nm)=	532
#Hole=	100.021
#Range=	Auto
#Laser Pol.=	No
#Raman. Pol.=	No
#Laser Pol. (°)=	-0.0007625
#Raman Pol. (°)=	89.9995
#Collection=	Microscope
#StageXY=	Marzhauser
#StageZ=	Marzhauser
#X (µm)=	4714.3
#Y (µm)=	-7717.6
#Z (µm)=	584.4
#Full time(mm:ss)=	3:18
#Project=
#Sample=
#Site=
#Title=	Thy_30_10_42_2x_45s_532 nm_x100_100%_600 gr_mm
#Remark=
#Date=	30.06.2022 14:26
#Acquired=	30.06.2022 14:26:27
#Base:Fit=	10.08.2022 09:58:11
#Base:Sub=	10.08.2022 09:58:44
#Filter:Polynom=	16.08.2022 10:22:53
#AxisType[0]=Intens
#AxisUnit[0]=Cnt
#AxisType[1]=Spectr
#AxisUnit[1]=1/cm
200.533	3.78405
204.162	9.92343
207.792	13.7227
211.418	16.8101
215.044	19.8259
218.667	23.9033
222.289	26.4138
225.912	29.9354
229.531	31.369
233.148	31.5416
236.766	32.2767
240.381	32.8679
243.994	33.3936
247.606	34.1066
251.217	32.0112
254.828	32.5547
258.436	33.8403
262.042	34.5587
265.647	33.6113
269.25	34.9372
272.852	34.5048
276.453	35.4574
280.052	35.6215
283.65	36.9604
287.247	34.6792
290.842	35.1374
294.436	35.3745
298.028	34.1831
301.617	33.8491
305.206	35.2913
308.794	35.0487
312.381	33.5422
315.964	31.3242
319.548	26.9293
323.131	24.1114
326.71	21.5938
330.29	18.8214
333.868	17.4745
337.443	14.7891
341.018	12.499
344.591	11.2593
348.163	11.9609
351.733	10.5899
355.303	9.77627
358.869	11.1983
362.435	10.3701
366.001	9.78302
369.563	10.3695
373.124	10.802
376.686	12.4433
380.244	13.6001
383.801	14.2883
387.357	16.273
390.911	17.6682
394.466	17.7771
398.018	15.7768
401.568	14.8329
405.117	12.8173
408.664	12.5466
412.21	11.5951
415.755	10.887
419.298	10.6059
422.84	9.46883
426.38	8.77028
429.919	8.92854
433.455	9.39132
436.992	7.84642
440.527	8.48999
444.06	10.4737
447.593	11.1762
451.122	11.964
454.651	11.9959
458.18	15.1811
461.705	14.4664
465.23	14.5091
468.752	16.7537
472.275	15.7702
475.797	14.9151
479.315	15.3301
482.834	16.2655
486.349	16.5831
489.863	15.3343
493.378	16.5004
496.889	17.4336
500.401	17.4146
503.91	18.2311
507.417	16.812
510.923	17.6566
514.43	16.8937
517.933	17.8478
521.435	17.922
524.936	19.7411
528.435	17.9577
531.933	18.1379
535.43	18.1733
538.927	16.1712
542.421	16.3082
545.913	16.0132
549.403	15.0066
552.893	13.6346
556.381	13.8054
559.868	14.6279
563.354	13.8769
566.839	14.2262
570.322	12.3962
573.802	11.1387
577.283	9.57188
580.762	9.53314
584.24	8.93964
587.714	8.08062
591.19	5.58786
594.663	3.69527
598.134	3.37672
601.605	2.95021
605.073	4.2148
608.542	4.40641
612.007	4.96636
615.473	4.16652
618.936	6.63285
622.397	6.84799
625.859	8.0786
629.318	10.1804
632.775	12.7939
636.233	14.4133
639.688	14.1886
643.142	16.0613
646.594	17.5515
650.045	17.2476
653.496	19.6488
656.944	20.6931
660.391	22.5962
663.837	25.2128
667.281	26.952
670.724	26.2445
674.166	26.275
677.606	26.0487
681.045	27.3912
684.483	29.3237
687.917	31.2258
691.352	32.7837
694.786	35.27
698.219	36.6008
701.65	37.7209
705.078	40.6083
708.506	41.0046
711.934	44.7081
715.358	47.8072
718.782	48.3407
722.204	48.3848
725.626	49.6293
729.045	51.9064
732.464	53.2736
735.881	54.8825
739.297	57.5259
742.711	56.995
746.125	58.9599
749.537	59.6355
752.946	60.1338
756.357	63.8357
759.764	65.5839
763.17	67.2007
766.575	68.9401
769.978	70.0411
773.382	71.8989
776.783	74.0864
780.182	75.7998
783.581	78.7499
786.978	80.8484
790.373	83.4976
793.768	86.3393
797.161	88.6086
800.552	90.1778
803.941	90.7364
807.33	92.8982
810.718	95.104
814.105	97.1674
817.49	99.1184
820.873	101.168
824.256	102.624
827.637	104.268
831.016	105.28
834.395	105.445
837.772	104.779
841.147	102.687
844.522	100.641
847.894	96.8018
851.267	92.4517
854.637	88.9528
858.007	84.6433
861.374	81.5775
864.739	77.5003
868.106	72.9437
871.469	69.6344
874.831	66.1338
878.193	65.2458
881.553	65.3536
884.911	64.2499
888.268	64.494
891.623	64.4698
894.978	64.8963
898.331	63.5851
901.683	64.1859
905.033	63.4184
908.383	64.4896
911.731	64.2148
915.078	62.9017
918.423	62.3397
921.768	60.4941
925.111	60.9259
928.452	57.5893
931.791	54.298
935.13	50.8435
938.468	49.8542
941.803	48.2168
945.139	44.8253
948.473	43.7128
951.804	43.8224
955.136	43.195
958.465	42.8369
961.794	41.354
965.12	39.9774
968.447	39.4079
971.771	38.2172
975.095	37.8038
978.417	38.4729
981.737	37.9354
985.057	36.5599
988.375	36.709
991.691	37.032
995.006	34.9135
998.32	34.1901
1001.63	33.13
1004.95	33.4598
1008.26	32.7688
1011.56	29.9578
1014.87	29.3843
1018.18	28.8279
1021.48	26.8916
1024.79	26.7697
1028.09	25.8625
1031.39	27.3629
1034.69	26.4684
1037.99	25.5786
1041.29	24.9229
1044.58	25.7251
1047.88	26.4439
1051.17	27.4816
1054.46	26.8656
1057.75	25.7254
1061.04	25.7352
1064.33	26.0356
1067.62	25.9029
1070.9	26.5315
1074.19	26.5915
1077.47	24.5502
1080.76	23.9755
1084.04	23.8922
1087.32	23.0329
1090.59	22.4944
1093.87	22.1578
1097.15	23.5234
1100.42	22.9146
1103.69	23.3681
1106.97	24.6308
1110.24	24.0876
1113.51	21.7325
1116.77	22.3048
1120.04	21.2355
1123.31	19.4295
1126.57	18.206
1129.83	16.1989
1133.1	15.0751
1136.36	12.0225
1139.62	13.6017
1142.87	11.7271
1146.13	10.8941
1149.38	9.4334
1152.64	7.61394
1155.89	4.74838
1159.14	2.1093
1162.39	1.31136
1165.64	0.908784
1168.89	1.1626
1172.14	2.78142
1175.38	4.32131
1178.63	5.48284
1181.87	5.10884
1185.11	5.38576
1188.35	5.58423
1191.59	7.00674
1194.83	8.82256
1198.07	10.4427
1201.3	11.127
1204.53	15.912
1207.77	20.6144
1211	23.9349
1214.23	26.9754
1217.46	30.6475
1220.69	34.0668
1223.91	37.4927
1227.14	40.8782
1230.36	44.5733
1233.59	47.1779
1236.81	50.1425
1240.03	54.5384
1243.25	56.7165
1246.46	59.7235
1249.68	62.0968
1252.9	63.6669
1256.11	65.2991
1259.32	63.7736
1262.54	65.0294
1265.75	67.0289
1268.96	67.3312
1272.16	69.0689
1275.37	67.7575
1278.57	67.8308
1281.78	68.3908
1284.98	68.369
1288.18	69.8105
1291.38	70.4257
1294.58	69.5867
1297.78	69.4242
1300.98	69.5244
1304.17	69.6583
1307.37	69.7784
1310.56	71.4142
1313.76	73.0139
1316.95	73.9461
1320.14	74.0032
1323.32	73.0074
1326.51	72.9415
1329.7	72.2482
1332.88	69.8735
1336.07	69.097
1339.25	65.8644
1342.43	65.9937
1345.61	64.0213
1348.79	62.4414
1351.96	57.9705
1355.14	55.0124
1358.31	52.5132
1361.49	50.7325
1364.66	51.3953
1367.83	50.0808
1371	47.5605
1374.17	44.4596
1377.34	43.727
1380.5	43.1636
1383.67	42.6708
1386.83	42.459
1390	43.0445
1393.16	42.0413
1396.32	39.7939
1399.48	38.6764
1402.64	37.3668
1405.79	37.4098
1408.95	35.903
1412.1	36.6467
1415.26	38.1819
1418.41	38.8727
1421.56	40.9401
1424.71	42.5879
1427.86	44.6947
1431	49.0851
1434.15	53.6002
1437.29	58.3168
1440.44	62.3549
1443.58	65.9459
1446.72	67.1182
1449.86	68.0443
1453	67.7271
1456.14	68.0699
1459.27	66.3353
1462.41	64.2818
1465.54	60.112
1468.67	54.9514
1471.81	50.1935
1474.94	45.8299
1478.07	39.0542
1481.19	33.7313
1484.32	29.9426
1487.45	25.3455
1490.57	22.3639
1493.69	17.8681
1496.82	13.9787
1499.94	12.0229
1503.06	11.9433
1506.17	11.5525
1509.29	12.0884
1512.41	11.0611
1515.52	12.5301
1518.64	13.2934
1521.75	14.3638
1524.86	15.7086
1527.97	17.1803
1531.08	18.4775
1534.19	20.6903
1537.29	22.637
1540.4	24.9095
1543.5	28.9124
1546.61	34.3549
1549.71	40.1066
1552.81	44.2582
1555.91	47.8234
1559.01	51.9521
1562.11	55.0412
1565.2	59.3074
1568.29	61.6974
1571.39	64.5489
1574.48	66.761
1577.57	69.5973
1580.66	71.1172
1583.75	70.7602
1586.84	71.0293
1589.93	69.8881
1593.01	69.672
1596.1	68.2786
1599.18	65.7437
1602.26	63.7186
1605.34	61.4584
1608.42	59.6357
1611.5	58.5079
1614.58	59.5384
1617.65	60.691
1620.73	61.7911
1623.8	61.8938
1626.87	62.7556
1629.95	63.0204
1633.02	64.657
1636.09	67.5916
1639.15	69.7596
1642.22	72.2994
1645.29	76.27
1648.35	78.6358
1651.42	79.1126
1654.48	79.8924
1657.54	77.9106
1660.6	76.7842
1663.66	75.0647
1666.72	72.0362
1669.77	68.2126
1672.83	63.2029
1675.88	57.1884
1678.93	52.3163
1681.99	46.3338
1685.04	39.9541
1688.09	36.0437
1691.13	29.048
1694.18	24.3602
1697.23	19.551
1700.27	15.1255
1703.32	11.2882
1706.36	9.30724
1709.4	7.27644
1712.44	5.16899
1715.48	5.21329
1718.52	4.75133
1721.56	3.73723
1724.59	2.36875
1727.63	1.92842
1730.66	0.564316
1733.69	1.40178
1736.72	1.73765
1739.75	0.697819
1742.78	0.102789
1745.81	-1.9952
1748.84	-2.68178
1751.86	-2.38803
1754.89	-1.33527
1757.91	-1.77385
1760.93	-0.342055
1763.95	0.120083
1766.97	-1.18439
1769.99	-0.423306
1773.01	0.0930739
1776.03	0.25799
1779.04	1.26805
1782.06	2.10619
1785.07	3.09038
1788.08	3.88331
1791.09	3.80609
1794.1	4.59013
1797.11	6.09657
1800.12	7.21103
1803.12	7.74131
1806.13	9.24543
1809.13	10.5003
1812.14	10.2787
1815.14	11.5291
1818.14	12.7573
1821.14	14.5918
1824.14	15.9746
1827.13	17.2918
1830.13	18.0704
1833.12	19.7376
1836.12	20.3262
1839.11	19.292
1842.1	20.5433
1845.09	20.9792
1848.08	22.1006
1851.07	22.5172
1854.06	22.7494
1857.04	24.179
1860.03	23.5822
1863.01	22.4994
1866	23.5165
1868.98	24.8987
1871.96	26.2669
1874.94	27.5594
1877.92	27.2781
1880.89	27.7348
1882.48	28.6617
1885.47	28.1934
1888.46	28.3941
1891.44	29.7379
1894.43	29.5632
1897.41	30.4011
1900.4	30.7023
1903.38	31.6819
1906.36	29.9752
1909.34	29.2863
1912.32	28.3396
1915.29	28.769
1918.27	28.2987
1921.25	27.5233
1924.22	26.2884
1927.2	25.6863
1930.17	24.234
1933.14	22.6036
1936.11	24.3119
1939.08	23.5195
1942.05	24.5504
1945.01	23.622
1947.98	24.2501
1950.94	22.8154
1953.91	24.2159
1956.87	24.6177
1959.83	23.2299
1962.79	25.6037
1965.75	27.4896
1968.71	28.384
1971.67	28.8081
1974.62	29.2921
1977.58	28.8413
1980.53	29.0133
1983.48	30.3972
1986.43	30.5992
1989.38	32.4517
1992.33	31.5968
1995.28	30.7238
1998.23	31.6737
2001.18	31.8063
2004.12	31.698
2007.06	31.2713
2010.01	29.8847
2012.95	27.642
2015.89	27.114
2018.83	26.3599
2021.77	25.3598
2024.71	25.7567
2027.64	24.0208
2030.58	22.5747
2033.51	22.8661
2036.45	24.5792
2039.38	24.4312
2042.31	23.3995
2045.24	24.541
2048.17	24.7335
2051.1	26.6848
2054.02	28.558
2056.95	30.2248
2059.87	31.3643
2062.8	32.6674
2065.72	34.1277
2068.64	35.0484
2071.56	37.4264
2074.48	36.9882
2077.4	37.0846
2080.31	36.8073
2083.23	36.8317
2086.14	36.8667
2089.06	35.8984
2091.97	35.8716
2094.88	35.8236
2097.79	35.6642
2100.7	35.3084
2103.61	36.794
2106.52	39.3073
2109.43	40.221
2112.33	42.468
2115.24	45.1119
2118.14	49.3282
2121.04	51.9575
2123.94	55.2732
2126.84	59.3352
2129.74	62.4222
2132.64	66.3214
2135.54	69.9901
2138.43	73.449
2141.33	76.7345
2144.22	80.5973
2147.11	82.8719
2150.01	84.9196
2152.9	85.936
2155.79	87.4925
2158.67	89.1999
2161.56	92.621
2164.45	93.8026
2167.33	95.0849
2170.22	95.069
2173.1	96.498
2175.98	96.6566
2178.86	95.9124
2181.74	97.0383
2184.62	94.4061
2187.5	93.7415
2190.38	91.732
2193.25	89.9906
2196.13	87.4663
2199	83.0807
2201.88	79.5201
2204.75	75.286
2207.62	71.5682
2210.49	68.2078
2213.36	65.9214
2216.22	63.5328
2219.09	59.4163
2221.96	56.4379
2224.82	53.7526
2227.68	51.7594
2230.55	49.7578
2233.41	46.804
2236.27	44.6763
2239.12	42.154
2241.98	41.3035
2244.84	40.0622
2247.7	40.4581
2250.55	39.6981
2253.41	38.0652
2256.26	36.3195
2259.11	36.424
2261.96	35.9622
2264.81	33.9874
2267.66	31.2019
2270.51	29.7875
2273.35	29.2426
2276.2	29.4293
2279.04	28.5129
2281.89	28.9857
2284.73	28.5567
2287.57	26.7934
2290.41	23.1624
2293.25	22.2397
2296.09	20.2
2298.93	19.7939
2301.76	19.1394
2304.6	17.5237
2307.44	17.5095
2310.27	16.8997
2313.1	17.9215
2315.93	18.1637
2318.76	17.6204
2321.59	17.1577
2324.42	17.5628
2327.25	18.7042
2330.07	18.2851
2332.9	18.266
2335.72	17.5849
2338.55	18.215
2341.37	19.7033
2344.19	19.7955
2347.01	18.8108
2349.83	18.1727
2352.65	17.3597
2355.46	16.8555
2358.28	14.2071
2361.09	14.8533
2363.91	15.3975
2366.72	14.8181
2369.53	14.0295
2372.34	12.3427
2375.15	12.2477
2377.96	13.4766
2380.77	14.0179
2383.58	14.01
2386.38	12.9704
2389.19	12.2597
2391.99	12.8661
2394.8	12.3423
2397.6	11.7741
2400.4	10.2046
2403.2	10.7416
2406	9.68347
2408.79	9.291
2411.59	9.05813
2414.39	7.92683
2417.18	8.45163
2419.98	7.96145
2422.77	9.05668
2425.56	8.95922
2428.35	9.50091
2431.14	10.3979
2433.93	10.2198
2436.72	9.84108
2439.5	10.4618
2442.29	11.5394
2445.07	11.5787
2447.86	11.3458
2450.64	10.8084
2453.42	9.38756
2456.2	9.44589
2458.98	9.83856
2461.76	8.28469
2464.54	8.08141
2467.32	7.2127
2470.09	6.49531
2472.87	5.8996
2475.64	4.86374
2478.41	5.37057
2481.18	5.29847
2483.95	5.16856
2486.72	5.13028
2489.49	3.69702
2492.26	3.74518
2495.03	3.84646
2497.79	4.1366
2500.56	3.89939
2503.32	3.22699
2506.09	1.93862
2508.85	1.86166
2511.61	0.453544
2514.37	-0.545068
2517.13	-0.461404
2519.89	-0.235971
2522.64	-0.273746
2525.4	-0.14507
2528.15	-0.774439
2530.91	-1.16304
2533.66	-1.26514
2536.41	-1.44407
2539.16	-0.930879
2541.91	-1.67513
2544.66	-1.36071
2547.41	-0.15713
2550.16	0.420038
2552.9	1.39609
2555.65	1.29716
2558.39	1.21751
2561.13	2.12616
2563.88	2.77339
2566.62	2.57643
2569.36	3.25707
2572.1	2.55828
2574.84	2.73014
2577.57	2.74782
2580.31	2.22132
2583.05	2.06994
2585.78	3.44459
2588.51	1.0414
2591.24	1.36743
2593.98	1.55906
2596.71	0.929018
2599.44	0.746739
2602.16	-0.288675
2604.89	-0.510067
2607.62	-0.325341
2610.34	0.239422
2613.07	1.85555
2615.79	2.10879
2618.52	2.00763
2621.24	0.825847
2623.96	0.854924
2626.68	1.24998
2629.4	1.42377
2632.11	3.2117
2634.83	4.07717
2637.55	4.72744
2640.26	5.2911
2642.98	5.13278
2645.69	5.07583
2648.4	4.32559
2651.11	4.34139
2653.82	4.01012
2656.53	3.66815
2659.24	2.8806
2661.95	2.42655
2664.65	3.29191
2667.36	3.55597
2670.06	3.61025
2672.76	4.73522
2675.47	5.27189
2678.17	5.50547
2680.87	5.18425
2683.57	5.3059
2686.27	6.54847
2688.97	6.23166
2691.66	6.25042
2694.36	7.07551
2697.05	8.19426
2699.75	9.18866
2702.44	10.2834
2705.13	11.2122
2707.82	11.4767
2710.51	11.1193
2713.2	11.029
2715.89	11.9309
2718.57	11.8388
2721.26	12.178
2723.95	12.4799
2726.63	13.1199
2729.31	14.747
2732	14.7916
2734.68	14.8558
2737.36	15.3624
2740.04	15.3693
2742.72	16.1756
2745.39	17.3891
2748.07	17.3231
2750.75	17.4183
2753.42	16.5644
2756.09	15.9864
2758.77	15.2587
2761.44	14.8038
2764.11	13.881
2766.78	13.6806
2769.45	13.2817
2772.12	11.3776
2774.78	9.32022
2777.45	8.13283
2780.12	5.99983
2782.78	3.83964
2785.44	2.77138
2788.11	2.26678
2790.77	1.14801
2793.43	-0.436379
2796.09	-0.358758
2798.75	0.471905
2801.4	1.35078
2804.06	1.23547
2806.72	1.96666
2809.37	2.01844
2812.03	2.28157
2814.68	3.21585
2817.33	5.26449
2819.98	8.24965
2822.63	11.6401
2825.28	15.2234
2827.93	19.5054
2830.58	24.2625
2833.23	29.2044
2835.87	32.8072
2838.52	38.0404
2841.16	44.8568
2843.8	50.5108
2846.44	58.4939
2849.08	67.8331
2851.73	76.7905
2854.36	85.9493
2857	94.5184
2859.64	102.893
2862.28	112.089
2864.91	118.955
2867.55	125.767
2870.18	130.535
2872.81	136.184
2875.44	141.487
2878.07	146.451
2880.7	151.793
2883.33	156.437
2885.96	161.727
2888.59	166.782
2891.21	171.529
2893.84	177.445
2896.46	182.329
2899.09	188.432
2901.71	196.846
2904.33	205.938
2906.95	217.759
2909.57	229.079
2912.19	242.1
2914.81	254.643
2917.43	266.609
2920.04	277.449
2922.66	286.477
2925.27	293.733
2927.88	300.274
2930.5	303.106
2933.11	304.629
2935.72	303.331
2938.33	299.843
2940.94	295.954
2943.54	289.417
2946.15	281.741
2948.76	270.613
2951.36	261.302
2953.97	250.535
2956.57	239.337
2959.17	228.709
2961.77	217.915
2964.37	207.464
2966.97	197.366
2969.57	187.574
2972.17	179.215
2974.77	169.128
2977.36	160.04
2979.96	151.36
2982.55	141.219
2985.15	131.407
2987.74	122.006
2990.33	112.834
2992.92	103.367
2995.51	94.8802
2998.1	85.6907
3000.69	78.9879
3003.27	71.8194
3005.86	66.5284
3008.44	60.7634
3011.03	54.9378
3013.61	50.5024
3016.19	47.9166
3018.78	45.9406
3021.36	44.3414
3023.94	43.2709
3026.51	42.0524
3029.09	42.3298
3031.67	43.174
3034.24	42.6485
3036.82	41.753
3039.39	42.0655
3041.97	42.2985
3044.54	42.3476
3047.11	42.1093
3049.68	42.2703
3052.25	42.2396
3054.82	40.0683
3057.39	39.4597
3059.96	38.027
3062.52	36.802
3065.09	35.9253
3067.65	34.9646
3070.22	33.3729
3072.78	30.4803
3075.34	28.5737
3077.9	26.0808
3080.46	23.5772
3083.02	20.9946
3085.58	19.0076
3088.14	16.7793
3090.69	16.1401
3093.25	14.809
3095.8	13.1349
3098.36	11.0282
3100.91	9.86786
3103.46	8.70878
3106.01	7.65637
3108.56	6.68607
3111.11	5.93551
3113.66	4.98911
3116.21	4.03614
3118.76	3.01423
3121.3	2.39164
3123.85	2.91326
3126.39	3.39201
3128.93	2.89667
3131.48	2.955
3134.02	1.68726
3136.56	0.795237
3139.1	-0.325785
3141.64	-1.16867
3144.17	-1.42645
3146.71	-0.857687
3149.25	-1.62282