File: data/Raman/poly_smoothed/Thy_30_10_30_1x_45s_532 nm_x100_100%_600 gr_mm_01.txt
#Acq. time (s)=	45
#Accumulations=	2
#Range (cm-¹)=	200...3150
#Windows=	2
#Auto scanning=	Off
#Autofocus=	Off
#Macrospot=	Off
#AutoExposure=	Off
#Spike filter=	Multiple accum.
#Delay time (s)=	0
#Binning=	1
#Readout mode=	Signal
#DeNoise=	Off
#ICS correction=	On
#Dark correction=	Off
#Inst. Process=	Off
#Detector Gain=	Best Dynamic Range
#Detector ADC=	20 kHz
#Detector temperature (°C)=	-69.85
#Instrument=	LabRAM HR Evol
#Detector=	Synapse
#Objective=	x100
#Grating=	600 gr/mm
#ND Filter=	100%
#Laser (nm)=	532
#Hole=	100.021
#Range=	Auto
#Laser Pol.=	No
#Raman. Pol.=	No
#Laser Pol. (°)=	-0.0007625
#Raman Pol. (°)=	89.9995
#Collection=	Microscope
#StageXY=	Marzhauser
#StageZ=	Marzhauser
#X (µm)=	4760.1
#Y (µm)=	-7708.5
#Z (µm)=	584.4
#Full time(mm:ss)=	3:18
#Project=
#Sample=
#Site=
#Title=	Thy_30_10_30_2x_45s_532 nm_x100_100%_600 gr_mm
#Remark=
#Date=	30.06.2022 13:36
#Acquired=	30.06.2022 13:36:43
#Base:Fit=	10.08.2022 09:58:11
#Base:Sub=	10.08.2022 09:58:44
#Filter:Polynom=	16.08.2022 10:22:53
#AxisType[0]=Intens
#AxisUnit[0]=Cnt
#AxisType[1]=Spectr
#AxisUnit[1]=1/cm
200.533	1.6076
204.162	4.75265
207.792	6.11333
211.418	7.22856
215.044	8.22339
218.667	7.41359
222.289	5.81212
225.912	5.28563
229.531	4.28444
233.148	4.73428
236.766	4.20036
240.381	5.1906
243.994	5.2262
247.606	5.45827
251.217	6.22709
254.828	4.97249
258.436	4.78029
262.042	6.13476
265.647	4.49879
269.25	4.96072
272.852	5.77477
276.453	8.4818
280.052	9.10572
283.65	10.6544
287.247	12.0691
290.842	11.4198
294.436	12.1282
298.028	12.3265
301.617	13.2862
305.206	12.0907
308.794	11.4316
312.381	12.5051
315.964	12.5649
319.548	13.3654
323.131	13.2375
326.71	13.9442
330.29	14.8892
333.868	15.0891
337.443	15.2689
341.018	13.7518
344.591	12.3157
348.163	11.4759
351.733	11.3354
355.303	10.9411
358.869	11.415
362.435	11.2784
366.001	11.5152
369.563	11.5761
373.124	11.3259
376.686	9.49929
380.244	7.96192
383.801	7.14816
387.357	7.40356
390.911	8.08279
394.466	7.8257
398.018	8.6922
401.568	7.88667
405.117	8.41543
408.664	9.16691
412.21	10.6422
415.755	11.9203
419.298	11.7791
422.84	11.7548
426.38	9.74167
429.919	9.57465
433.455	9.22167
436.992	9.53362
440.527	9.60478
444.06	9.64874
447.593	9.52999
451.122	10.729
454.651	10.1724
458.18	10.663
461.705	11.2038
465.23	11.4763
468.752	12.254
472.275	14.3273
475.797	15.8742
479.315	15.9956
482.834	16.9546
486.349	17.3981
489.863	18.5121
493.378	18.2741
496.889	18.4857
500.401	18.3388
503.91	18.0412
507.417	16.5557
510.923	16.8068
514.43	15.843
517.933	15.4822
521.435	14.755
524.936	14.0573
528.435	13.6103
531.933	13.7473
535.43	13.6153
538.927	12.7777
542.421	11.8826
545.913	11.8589
549.403	10.6248
552.893	9.40832
556.381	9.10793
559.868	7.49376
563.354	6.84453
566.839	5.74033
570.322	5.15004
573.802	4.93238
577.283	3.52888
580.762	2.08229
584.24	2.64548
587.714	2.89303
591.19	1.71439
594.663	2.64517
598.134	2.86822
601.605	2.49407
605.073	3.70968
608.542	4.52151
612.007	4.73522
615.473	4.57409
618.936	4.48698
622.397	5.60288
625.859	5.13091
629.318	5.72641
632.775	6.06364
636.233	7.74165
639.688	8.37638
643.142	8.86349
646.594	10.2749
650.045	11.8207
653.496	10.8471
656.944	11.7734
660.391	12.0176
663.837	13.532
667.281	14.5332
670.724	15.3937
674.166	16.464
677.606	16.8898
681.045	18.7777
684.483	20.7193
687.917	21.8361
691.352	23.4111
694.786	23.4794
698.219	24.3273
701.65	24.602
705.078	26.001
708.506	28.0981
711.934	30.3473
715.358	32.1516
718.782	33.8451
722.204	35.8413
725.626	35.785
729.045	37.1752
732.464	39.7404
735.881	38.7704
739.297	39.2508
742.711	40.8492
746.125	43.3222
749.537	45.6821
752.946	48.502
756.357	50.567
759.764	52.8031
763.17	54.5723
766.575	57.4921
769.978	60.3075
773.382	62.9296
776.783	62.8697
780.182	63.5214
783.581	64.6828
786.978	65.5223
790.373	68.411
793.768	69.9043
797.161	70.842
800.552	72.3321
803.941	74.1053
807.33	73.5539
810.718	75.2818
814.105	75.5247
817.49	74.0448
820.873	74.2001
824.256	74.3359
827.637	74.6451
831.016	74.8234
834.395	75.2027
837.772	74.2102
841.147	73.4929
844.522	70.623
847.894	67.6866
851.267	65.6393
854.637	62.9495
858.007	59.2745
861.374	54.1375
864.739	52.8509
868.106	50.6145
871.469	49.4517
874.831	47.3928
878.193	46.4938
881.553	46.553
884.911	44.9159
888.268	44.5013
891.623	43.3947
894.978	42.7176
898.331	41.3443
901.683	42.4482
905.033	42.9482
908.383	42.7033
911.731	43.4899
915.078	44.2992
918.423	45.6553
921.768	44.5902
925.111	44.5689
928.452	43.3586
931.791	42.3597
935.13	42.1962
938.468	40.4539
941.803	38.8726
945.139	38.2435
948.473	39.2635
951.804	38.0558
955.136	38.7039
958.465	38.4425
961.794	37.2162
965.12	38.4589
968.447	38.1873
971.771	38.6146
975.095	38.9677
978.417	39.1999
981.737	40.5806
985.057	40.5632
988.375	42.4521
991.691	41.6353
995.006	43.0049
998.32	42.5248
1001.63	42.0363
1004.95	40.5601
1008.26	40.0166
1011.56	36.9892
1014.87	36.2834
1018.18	33.7481
1021.48	33.5076
1024.79	33.2496
1028.09	32.1294
1031.39	32.6172
1034.69	32.0512
1037.99	31.0813
1041.29	30.1366
1044.58	31.0374
1047.88	29.6099
1051.17	28.8059
1054.46	29.7592
1057.75	29.521
1061.04	28.6602
1064.33	27.9396
1067.62	26.7148
1070.9	25.8035
1074.19	24.3669
1077.47	24.1131
1080.76	22.0505
1084.04	22.4287
1087.32	23.0511
1090.59	23.3672
1093.87	21.994
1097.15	22.4033
1100.42	22.2153
1103.69	22.6493
1106.97	23.1249
1110.24	23.6833
1113.51	23.9918
1116.77	22.9673
1120.04	21.609
1123.31	20.8175
1126.57	20.0246
1129.83	18.9251
1133.1	17.0762
1136.36	15.9918
1139.62	14.1138
1142.87	13.3611
1146.13	11.6893
1149.38	10.185
1152.64	8.49684
1155.89	7.0789
1159.14	7.74523
1162.39	6.84912
1165.64	5.80509
1168.89	4.30591
1172.14	3.18912
1175.38	2.13028
1178.63	0.504734
1181.87	1.39867
1185.11	2.19586
1188.35	2.63336
1191.59	1.96184
1194.83	3.03588
1198.07	3.55128
1201.3	5.11449
1204.53	6.84182
1207.77	9.01241
1211	11.5097
1214.23	12.3263
1217.46	16.2365
1220.69	19.3178
1223.91	23.0031
1227.14	25.5242
1230.36	29.92
1233.59	33.0598
1236.81	36.0277
1240.03	37.6744
1243.25	39.1149
1246.46	41.2419
1249.68	43.5279
1252.9	44.5228
1256.11	44.5177
1259.32	46.4386
1262.54	48.95
1265.75	50.651
1268.96	51.3901
1272.16	52.3312
1275.37	52.9341
1278.57	53.2726
1281.78	53.2609
1284.98	54.9107
1288.18	55.4575
1291.38	56.6527
1294.58	57.6661
1297.78	58.2879
1300.98	60.4303
1304.17	62.0401
1307.37	62.7978
1310.56	62.6025
1313.76	62.5538
1316.95	62.2569
1320.14	61.7219
1323.32	62.3002
1326.51	60.8795
1329.7	59.4161
1332.88	57.4858
1336.07	57.2098
1339.25	54.1871
1342.43	51.7434
1345.61	48.4055
1348.79	45.0001
1351.96	42.131
1355.14	39.367
1358.31	37.3561
1361.49	34.9066
1364.66	32.6335
1367.83	30.5067
1371	29.1934
1374.17	28.2216
1377.34	26.8955
1380.5	27.1501
1383.67	26.3966
1386.83	25.3822
1390	26.1742
1393.16	27.4343
1396.32	28.8406
1399.48	28.2111
1402.64	28.3183
1405.79	29.2603
1408.95	29.3063
1412.1	28.4512
1415.26	28.5731
1418.41	29.6395
1421.56	33.0115
1424.71	36.256
1427.86	39.3905
1431	41.9492
1434.15	47.9834
1437.29	51.2237
1440.44	53.4507
1443.58	55.5338
1446.72	59.096
1449.86	60.4733
1453	60.3778
1456.14	58.3938
1459.27	57.3285
1462.41	53.7775
1465.54	51.0117
1468.67	46.7513
1471.81	40.9196
1474.94	35.7606
1478.07	30.3017
1481.19	24.8769
1484.32	18.9968
1487.45	14.0128
1490.57	8.92136
1493.69	6.8302
1496.82	5.41749
1499.94	2.89664
1503.06	3.37506
1506.17	2.73552
1509.29	3.41242
1512.41	3.40784
1515.52	3.98084
1518.64	4.73656
1521.75	6.42131
1524.86	8.24058
1527.97	9.22945
1531.08	8.75127
1534.19	10.701
1537.29	13.0354
1540.4	15.0773
1543.5	16.4187
1546.61	17.5578
1549.71	19.8923
1552.81	23.4812
1555.91	26.4211
1559.01	28.1815
1562.11	29.3445
1565.2	31.5168
1568.29	33.0817
1571.39	36.5283
1574.48	38.4698
1577.57	40.5874
1580.66	43.4326
1583.75	43.3773
1586.84	43.6945
1589.93	43.7611
1593.01	44.5681
1596.1	44.0588
1599.18	43.7127
1602.26	44.0215
1605.34	44.5233
1608.42	44.7545
1611.5	45.1386
1614.58	45.1262
1617.65	45.8174
1620.73	47.0583
1623.8	47.6299
1626.87	50.4495
1629.95	52.3649
1633.02	54.2028
1636.09	56.6711
1639.15	59.959
1642.22	63.7129
1645.29	66.896
1648.35	68.9741
1651.42	71.0534
1654.48	72.3279
1657.54	71.789
1660.6	71.8998
1663.66	71.4997
1666.72	70.973
1669.77	69.6358
1672.83	66.563
1675.88	63.7944
1678.93	60.1401
1681.99	55.6756
1685.04	50.3837
1688.09	44.3455
1691.13	39.8046
1694.18	35.481
1697.23	29.2565
1700.27	24.1454
1703.32	20.3302
1706.36	16.0943
1709.4	12.6132
1712.44	10.0719
1715.48	6.40688
1718.52	4.57109
1721.56	2.67334
1724.59	0.302545
1727.63	0.602228
1730.66	-0.0293231
1733.69	1.24069
1736.72	1.66481
1739.75	2.49485
1742.78	2.94224
1745.81	2.4156
1748.84	2.41774
1751.86	1.92676
1754.89	1.90871
1757.91	1.45593
1760.93	0.0276733
1763.95	-0.194534
1766.97	-0.515281
1769.99	-0.771264
1773.01	-1.72194
1776.03	-1.83967
1779.04	-1.65856
1782.06	-1.57569
1785.07	-0.986956
1788.08	-1.28081
1791.09	-1.04688
1794.1	0.480347
1797.11	0.342421
1800.12	0.867268
1803.12	1.77001
1806.13	2.4367
1809.13	3.33039
1812.14	4.21922
1815.14	4.21922
1818.14	3.80782
1821.14	3.54198
1824.14	3.81941
1827.13	4.01132
1830.13	4.62559
1833.12	4.35648
1836.12	4.36484
1839.11	4.41104
1842.1	3.70043
1845.09	4.2488
1848.08	4.41963
1851.07	5.32636
1854.06	5.24912
1857.04	4.42282
1860.03	4.26056
1863.01	4.64227
1866	4.44407
1868.98	4.2378
1871.96	4.52162
1874.94	4.27683
1877.92	4.2456
1880.89	4.24038
1882.48	4.25336
1885.47	5.08632
1888.46	5.49996
1891.44	5.95247
1894.43	6.65378
1897.41	7.84124
1900.4	8.99451
1903.38	8.86191
1906.36	8.26097
1909.34	8.51174
1912.32	8.89518
1915.29	8.79875
1918.27	9.78954
1921.25	9.55014
1924.22	8.36917
1927.2	7.17976
1930.17	6.73606
1933.14	6.7599
1936.11	6.29032
1939.08	5.5934
1942.05	4.97931
1945.01	5.14127
1947.98	3.82861
1950.94	4.17767
1953.91	5.54455
1956.87	6.34852
1959.83	7.39721
1962.79	6.98449
1965.75	6.908
1968.71	7.85938
1971.67	8.74866
1974.62	8.8338
1977.58	8.84364
1980.53	9.20997
1983.48	10.1908
1986.43	11.2364
1989.38	10.9423
1992.33	11.3931
1995.28	11.0789
1998.23	11.1905
2001.18	11.4552
2004.12	11.5483
2007.06	11.9555
2010.01	11.8504
2012.95	11.5369
2015.89	11.9363
2018.83	12.2546
2021.77	13.0198
2024.71	14.0584
2027.64	13.8112
2030.58	13.6201
2033.51	14.0144
2036.45	13.5169
2039.38	13.4763
2042.31	14.0648
2045.24	13.9256
2048.17	14.0533
2051.1	14.7594
2054.02	15.1638
2056.95	14.8058
2059.87	15.1329
2062.8	14.805
2065.72	16.3366
2068.64	17.6994
2071.56	18.57
2074.48	18.7107
2077.4	19.2957
2080.31	19.9466
2083.23	20.4505
2086.14	21.5125
2089.06	22.3967
2091.97	23.5679
2094.88	24.3689
2097.79	25.1228
2100.7	27.4765
2103.61	29.052
2106.52	29.7912
2109.43	31.5769
2112.33	33.555
2115.24	35.8807
2118.14	36.8964
2121.04	39.0631
2123.94	40.7524
2126.84	42.3618
2129.74	45.6494
2132.64	48.4813
2135.54	52.7314
2138.43	56.0521
2141.33	59.0777
2144.22	62.5404
2147.11	65.0335
2150.01	68.6801
2152.9	71.3276
2155.79	74.1448
2158.67	74.8733
2161.56	77.1405
2164.45	78.8202
2167.33	80.635
2170.22	82.4865
2173.1	83.9915
2175.98	84.35
2178.86	84.3664
2181.74	83.055
2184.62	81.992
2187.5	79.2441
2190.38	76.9965
2193.25	74.4989
2196.13	72.3223
2199	69.379
2201.88	67.0108
2204.75	62.7052
2207.62	59.9353
2210.49	56.4215
2213.36	53.9329
2216.22	50.7615
2219.09	48.1212
2221.96	43.6279
2224.82	39.4804
2227.68	36.487
2230.55	34.9264
2233.41	32.6157
2236.27	31.0363
2239.12	29.6745
2241.98	29.5826
2244.84	28.2022
2247.7	26.5643
2250.55	25.828
2253.41	25.3775
2256.26	25.4245
2259.11	25.9429
2261.96	26.5725
2264.81	26.5344
2267.66	25.8439
2270.51	25.6596
2273.35	25.2337
2276.2	24.7502
2279.04	25.1148
2281.89	24.4478
2284.73	23.7285
2287.57	23.0874
2290.41	22.5304
2293.25	19.5308
2296.09	19.0925
2298.93	18.1904
2301.76	18.1971
2304.6	16.614
2307.44	15.8497
2310.27	15.6483
2313.1	14.432
2315.93	13.6332
2318.76	12.3169
2321.59	12.0739
2324.42	11.3527
2327.25	11.1989
2330.07	9.67975
2332.9	8.81899
2335.72	8.44399
2338.55	7.88926
2341.37	7.58772
2344.19	7.06
2347.01	6.33337
2349.83	6.1236
2352.65	5.76131
2355.46	5.85269
2358.28	5.5965
2361.09	4.35572
2363.91	4.27903
2366.72	5.26584
2369.53	6.17659
2372.34	6.82201
2375.15	6.7205
2377.96	7.59985
2380.77	7.45897
2383.58	7.40926
2386.38	7.24943
2389.19	7.47892
2391.99	7.64781
2394.8	7.58633
2397.6	8.21314
2400.4	7.97755
2403.2	7.02041
2406	6.70726
2408.79	6.67757
2411.59	6.44696
2414.39	6.09931
2417.18	6.04891
2419.98	6.09425
2422.77	5.57035
2425.56	5.38655
2428.35	5.57657
2431.14	5.77328
2433.93	5.64642
2436.72	5.06168
2439.5	4.48051
2442.29	4.10309
2445.07	3.93211
2447.86	4.31436
2450.64	4.70487
2453.42	4.52301
2456.2	4.90979
2458.98	4.1633
2461.76	4.46256
2464.54	4.28622
2467.32	4.08338
2470.09	3.79303
2472.87	4.0963
2475.64	4.11753
2478.41	3.99647
2481.18	3.327
2483.95	2.75886
2486.72	3.26647
2489.49	2.50461
2492.26	2.36248
2495.03	2.0415
2497.79	1.69785
2500.56	0.974879
2503.32	0.359077
2506.09	0.326549
2508.85	0.0751213
2511.61	1.07957
2514.37	1.38734
2517.13	0.990134
2519.89	1.12981
2522.64	1.34923
2525.4	1.55561
2528.15	1.97053
2530.91	2.59171
2533.66	2.7671
2536.41	3.32495
2539.16	3.9917
2541.91	3.57931
2544.66	3.49206
2547.41	2.723
2550.16	2.67137
2552.9	2.53968
2555.65	2.91624
2558.39	3.22132
2561.13	3.5956
2563.88	3.27118
2566.62	3.51824
2569.36	3.28879
2572.1	3.9777
2574.84	4.44214
2577.57	4.33217
2580.31	3.90654
2583.05	2.54908
2585.78	2.54843
2588.51	1.97843
2591.24	2.21492
2593.98	2.0572
2596.71	2.06516
2599.44	1.49723
2602.16	0.548946
2604.89	0.760935
2607.62	0.212766
2610.34	-0.463636
2613.07	-0.551598
2615.79	-0.623339
2618.52	-0.793791
2621.24	0.285744
2623.96	0.67577
2626.68	0.51787
2629.4	0.127149
2632.11	0.673529
2634.83	0.438843
2637.55	0.832921
2640.26	1.42296
2642.98	1.09281
2645.69	-0.0121761
2648.4	-0.073727
2651.11	0.264163
2653.82	0.446946
2656.53	0.0631822
2659.24	0.323741
2661.95	0.264593
2664.65	0.506063
2667.36	0.236711
2670.06	0.988568
2672.76	1.29337
2675.47	1.62593
2678.17	2.30074
2680.87	3.32014
2683.57	3.41572
2686.27	3.80951
2688.97	3.5283
2691.66	3.35922
2694.36	2.80724
2697.05	2.46561
2699.75	2.80214
2702.44	2.84684
2705.13	3.30296
2707.82	3.61422
2710.51	3.7232
2713.2	4.77704
2715.89	5.13984
2718.57	5.32528
2721.26	5.16908
2723.95	5.60529
2726.63	6.00349
2729.31	6.80993
2732	6.95334
2734.68	7.61032
2737.36	7.90654
2740.04	8.23845
2742.72	8.83109
2745.39	9.27168
2748.07	8.49434
2750.75	7.97192
2753.42	7.10451
2756.09	6.10367
2758.77	5.49324
2761.44	4.67796
2764.11	4.79677
2766.78	5.5706
2769.45	4.57302
2772.12	4.00198
2774.78	3.40506
2777.45	3.01473
2780.12	3.25211
2782.78	2.79875
2785.44	2.43888
2788.11	1.72518
2790.77	2.42379
2793.43	1.83331
2796.09	2.83804
2798.75	3.75919
2801.4	5.16432
2804.06	4.88634
2806.72	5.35819
2809.37	5.29848
2812.03	5.21632
2814.68	5.04741
2817.33	6.07614
2819.98	7.31587
2822.63	8.70269
2825.28	10.614
2827.93	13.77
2830.58	18.0994
2833.23	20.2242
2835.87	23.6377
2838.52	28.2815
2841.16	33.8713
2843.8	40.0962
2846.44	46.3981
2849.08	53.8457
2851.73	62.5846
2854.36	70.8102
2857	79.9788
2859.64	88.9327
2862.28	98.107
2864.91	105.802
2867.55	113.127
2870.18	119.057
2872.81	124.25
2875.44	128.998
2878.07	134.253
2880.7	139.173
2883.33	143.765
2885.96	148.215
2888.59	152.906
2891.21	157.514
2893.84	162.823
2896.46	167.901
2899.09	173.824
2901.71	182.417
2904.33	190.957
2906.95	200.049
2909.57	209.283
2912.19	220.997
2914.81	233.127
2917.43	244.557
2920.04	255.331
2922.66	264.339
2925.27	271.061
2927.88	275.017
2930.5	277.382
2933.11	277.471
2935.72	275.765
2938.33	272.181
2940.94	267.282
2943.54	260.238
2946.15	252.812
2948.76	243.703
2951.36	234.348
2953.97	223.62
2956.57	212.774
2959.17	203.043
2961.77	193.199
2964.37	183.349
2966.97	174.28
2969.57	165.439
2972.17	157.704
2974.77	150.878
2977.36	143.932
2979.96	137.366
2982.55	129.722
2985.15	121.046
2987.74	111.569
2990.33	102.672
2992.92	94.443
2995.51	85.7794
2998.1	78.0732
3000.69	69.9828
3003.27	62.1023
3005.86	54.9822
3008.44	49.2851
3011.03	43.4762
3013.61	38.5311
3016.19	33.573
3018.78	30.5249
3021.36	27.1991
3023.94	25.1642
3026.51	23.0637
3029.09	22.45
3031.67	22.3495
3034.24	23.0484
3036.82	23.3293
3039.39	23.8986
3041.97	25.0733
3044.54	25.8966
3047.11	26.4472
3049.68	26.936
3052.25	27.2146
3054.82	27.4405
3057.39	27.0758
3059.96	26.3838
3062.52	25.3322
3065.09	24.0646
3067.65	22.3746
3070.22	20.2829
3072.78	18.1905
3075.34	15.8993
3077.9	13.7438
3080.46	11.1843
3083.02	9.09181
3085.58	7.14719
3088.14	5.81617
3090.69	4.69877
3093.25	3.25975
3095.8	2.56867
3098.36	1.76562
3100.91	0.579513
3103.46	0.774213
3106.01	0.542495
3108.56	-0.313224
3111.11	-0.424882
3113.66	-0.493595
3116.21	-0.313669
3118.76	-0.542978
3121.3	-0.278412
3123.85	-0.246627
3126.39	-0.107992
3128.93	-0.198637
3131.48	0.250508
3134.02	0.929008
3136.56	1.03892
3139.1	1.26211
3141.64	2.16829
3144.17	3.3939
3146.71	4.70964
3149.25	6.62503