File: data/Raman/poly_smoothed/Thy_10_08_28_1x_45s_532 nm_x100_100%_600 gr_mm_01.txt
#Acq. time (s)=	45
#Accumulations=	2
#Range (cm-¹)=	200...3150
#Windows=	2
#Auto scanning=	Off
#Autofocus=	Off
#Macrospot=	Off
#AutoExposure=	Off
#Spike filter=	Multiple accum.
#Delay time (s)=	0
#Binning=	1
#Readout mode=	Signal
#DeNoise=	Off
#ICS correction=	On
#Dark correction=	Off
#Inst. Process=	Off
#Detector Gain=	Best Dynamic Range
#Detector ADC=	20 kHz
#Detector temperature (°C)=	-69.85
#Instrument=	LabRAM HR Evol
#Detector=	Synapse
#Objective=	x100
#Grating=	600 gr/mm
#ND Filter=	100%
#Laser (nm)=	532
#Hole=	100.021
#Range=	Auto
#Laser Pol.=	No
#Raman. Pol.=	No
#Laser Pol. (°)=	-0.0007625
#Raman Pol. (°)=	89.9995
#Collection=	Microscope
#StageXY=	Marzhauser
#StageZ=	Marzhauser
#X (µm)=	2204.3
#Y (µm)=	1214.6
#Z (µm)=	443.05
#Full time(mm:ss)=	3:18
#Project=
#Sample=
#Site=
#Title=	Thy_10_08_28_2x_45s_532 nm_x100_100%_600 gr_mm
#Remark=
#Date=	05.07.2022 16:13
#Acquired=	05.07.2022 16:13:45
#Base:Fit=	10.08.2022 09:46:25
#Base:Sub=	10.08.2022 09:46:49
#Filter:Polynom=	16.08.2022 10:24:56
#AxisType[0]=Intens
#AxisUnit[0]=Cnt
#AxisType[1]=Spectr
#AxisUnit[1]=1/cm
200.43	15.8687
204.059	13.4457
207.688	10.8594
211.314	10.1413
214.941	8.93519
218.564	6.52688
222.186	5.35015
225.809	4.24938
229.428	4.17724
233.045	4.42254
236.663	4.10899
240.278	4.6381
243.891	5.79823
247.503	6.11112
251.116	8.07797
254.725	9.78194
258.333	11.2818
261.939	13.1857
265.544	13.4271
269.148	12.4063
272.75	12.9871
276.351	14.2997
279.95	16.0135
283.548	17.3344
287.144	17.6492
290.739	18.8345
294.333	20.3984
297.925	19.7364
301.514	18.7346
305.104	17.7828
308.692	19.1982
312.279	19.5943
315.862	19.4431
319.446	19.7651
323.029	20.7246
326.608	22.3238
330.188	24.6543
333.766	26.1453
337.341	24.9146
340.917	24.883
344.489	22.8279
348.062	21.7517
351.631	20.6476
355.201	18.9799
358.768	17.7998
362.333	17.975
365.899	16.8549
369.462	17.0657
373.023	17.4241
376.585	17.5615
380.143	17.3805
383.7	16.141
387.256	16.6614
390.812	19.3208
394.365	19.2367
397.916	18.5553
401.467	17.9835
405.015	19.3636
408.563	20.3834
412.109	20.8096
415.654	20.7197
419.197	19.6099
422.739	18.2116
426.279	15.3317
429.819	15.7306
433.356	14.394
436.891	13.874
440.426	11.7363
443.96	11.0573
447.492	10.5962
451.021	11.2286
454.551	13.13
458.079	14.329
461.604	15.2918
465.13	17.2587
468.654	19.2694
472.175	20.1327
475.696	20.5735
479.215	21.2462
482.733	21.6263
486.249	23.4037
489.765	24.5441
493.278	24.7349
496.789	24.4735
500.301	24.5272
503.81	25.1807
507.317	24.857
510.825	24.2519
514.33	23.2666
517.833	22.9025
521.335	21.0858
524.836	20.4712
528.335	20.911
531.835	21.3605
535.332	20.3481
538.827	20.8169
542.321	22.0873
545.814	23.3048
549.305	24.0009
552.795	23.2953
556.282	21.4575
559.769	20.3805
563.255	18.9377
566.739	18.4172
570.223	18.8162
573.705	17.6896
577.183	16.4805
580.663	16.5435
584.141	15.4967
587.615	14.8068
591.09	13.4552
594.564	13.0551
598.035	13.6331
601.506	11.9479
604.974	11.812
608.443	12.6073
611.908	13.4235
615.374	14.7697
618.837	14.8198
622.3	16.3417
625.761	18.6997
629.219	19.9956
632.677	20.6216
636.135	20.7695
639.59	18.9611
643.043	18.7995
646.495	18.6767
649.948	18.491
653.398	18.8466
656.846	20.8752
660.293	20.1164
663.738	21.1227
667.183	21.7722
670.626	22.347
674.067	24.103
677.508	25.7785
680.947	26.8089
684.385	27.0425
687.821	28.2719
691.254	30.759
694.688	33.4379
698.121	35.7959
701.552	37.7282
704.98	40.1437
708.409	42.6492
711.836	44.2924
715.26	45.6668
718.685	46.2116
722.108	47.6213
725.528	48.3015
728.949	49.2117
732.367	49.5963
735.785	50.8344
739.2	52.2741
742.614	53.4504
746.028	54.3671
749.439	56.9407
752.849	59.3648
756.26	61.4702
759.667	63.3963
763.073	63.9009
766.477	65.8436
769.883	67.6784
773.285	69.7037
776.686	74.0915
780.085	76.2885
783.484	77.5674
786.881	78.534
790.276	79.5669
793.671	81.5777
797.064	82.0656
800.456	83.8505
803.846	84.5401
807.234	84.589
810.622	82.0035
814.008	82.1414
817.394	82.5777
820.778	83.3473
824.159	82.4359
827.541	82.0225
830.921	82.6741
834.298	81.1102
837.676	79.9913
841.051	77.2532
844.426	75.4994
847.798	74.315
851.171	72.4459
854.54	68.9314
857.911	68.0295
861.278	67.2998
864.645	64.623
868.01	62.2793
871.373	60.4363
874.735	58.7151
878.097	57.0926
881.457	56.6009
884.815	56.7934
888.172	55.6716
891.528	54.9749
894.882	54.0403
898.237	54.7182
901.589	55.9125
904.94	56.05
908.289	56.8058
911.635	56.7094
914.982	55.8635
918.328	55.8569
921.672	54.7956
925.015	54.0163
928.357	53.707
931.698	53.3473
935.035	51.6406
938.373	49.5822
941.71	48.0553
945.044	46.2312
948.378	43.7943
951.709	42.5875
955.041	41.8723
958.372	41.4832
961.699	39.1859
965.027	39.5546
968.352	39.7576
971.676	40.9223
975	41.1854
978.322	41.879
981.642	42.5843
984.962	42.9807
988.28	40.2466
991.596	39.8342
994.911	38.4466
998.227	37.6154
1001.54	36.1517
1004.85	34.1868
1008.16	34.0748
1011.47	32.9785
1014.78	31.1952
1018.08	29.6355
1021.39	27.1411
1024.69	25.4183
1028	23.7704
1031.3	22.9419
1034.6	21.3527
1037.9	20.9274
1041.19	19.8873
1044.49	20.3696
1047.78	20.8286
1051.08	22.0626
1054.37	21.2059
1057.66	21.5935
1060.95	19.9915
1064.24	19.1224
1067.53	16.9825
1070.81	16.3457
1074.1	17.0754
1077.38	15.9394
1080.66	14.8334
1083.94	13.0861
1087.22	12.998
1090.5	13.2096
1093.78	12.7736
1097.05	13.4857
1100.33	12.2945
1103.6	11.8623
1106.87	11.9384
1110.14	12.4948
1113.41	12.675
1116.68	12.713
1119.95	12.1593
1123.21	11.0652
1126.48	9.29709
1129.74	9.49827
1133	9.0481
1136.26	8.3139
1139.52	7.61392
1142.78	5.72476
1146.04	5.666
1149.29	4.9087
1152.55	4.18364
1155.8	3.24571
1159.05	2.53767
1162.3	0.486034
1165.55	1.6299
1168.8	1.70282
1172.05	4.51114
1175.29	5.17565
1178.54	6.13423
1181.78	8.75384
1185.02	10.2681
1188.26	11.7252
1191.5	12.5764
1194.74	12.9551
1197.97	15.0531
1201.21	16.3877
1204.44	18.251
1207.68	20.1925
1210.91	21.4648
1214.14	24.6859
1217.37	27.7154
1220.59	29.3541
1223.82	31.9295
1227.05	34.3548
1230.27	37.0922
1233.49	37.5384
1236.72	38.6844
1239.94	39.6202
1243.16	41.7031
1246.37	42.5998
1249.59	43.1317
1252.8	45.0429
1256.02	45.2363
1259.23	45.2278
1262.44	45.5353
1265.66	44.2708
1268.86	43.7716
1272.07	44.518
1275.28	45.1968
1278.48	47.2782
1281.69	48.0754
1284.89	49.6875
1288.09	52.3182
1291.29	55.1188
1294.49	57.7817
1297.69	58.8403
1300.89	61.6624
1304.08	63.8408
1307.28	65.1262
1310.47	66.0194
1313.66	67.5875
1316.85	68.1007
1320.04	67.4671
1323.23	67.4689
1326.42	67.204
1329.61	67.2853
1332.79	66.6732
1335.97	64.2245
1339.16	62.7502
1342.34	60.9416
1345.52	58.3538
1348.7	55.906
1351.87	55.2759
1355.05	53.8694
1358.22	52.0953
1361.4	50.1968
1364.57	48.9988
1367.74	47.2852
1370.91	45.8796
1374.08	44.8731
1377.25	43.3416
1380.41	41.3267
1383.58	41.0666
1386.74	39.7285
1389.91	38.7298
1393.07	37.7057
1396.23	36.3385
1399.39	34.8464
1402.55	33.822
1405.7	32.7506
1408.86	33.0028
1412.01	34.5498
1415.17	38.195
1418.32	39.7801
1421.47	43.1017
1424.62	47.469
1427.77	51.6943
1430.91	56.4268
1434.06	61.7136
1437.2	65.8707
1440.35	69.9176
1443.49	72.9412
1446.63	73.4832
1449.77	73.3107
1452.91	72.8506
1456.05	70.2371
1459.18	67.5109
1462.32	63.6205
1465.45	59.6276
1468.59	55.0242
1471.72	47.9052
1474.85	42.7995
1477.98	36.625
1481.1	32.3162
1484.23	27.7835
1487.36	25.0867
1490.48	22.4523
1493.61	19.6415
1496.73	17.7463
1499.85	18.3334
1502.97	17.0581
1506.09	17.8006
1509.2	18.6463
1512.32	19.3779
1515.43	18.6245
1518.55	19.1512
1521.66	20.0091
1524.77	19.8092
1527.88	21.3365
1530.99	21.613
1534.1	22.979
1537.21	24.4588
1540.31	25.9974
1543.42	27.8049
1546.52	29.5901
1549.62	32.3424
1552.72	34.9005
1555.82	35.6826
1558.92	38.2073
1562.02	39.4624
1565.11	42.1997
1568.21	44.5
1571.3	45.8019
1574.39	47.4892
1577.49	50.3339
1580.57	53.1971
1583.66	54.0786
1586.75	56.5125
1589.84	57.7317
1592.92	59.0579
1596.01	59.9567
1599.09	60.4507
1602.17	59.8403
1605.25	60.5697
1608.33	60.1176
1611.41	60.8555
1614.49	59.4749
1617.57	58.9156
1620.64	58.6701
1623.72	58.7933
1626.79	58.8743
1629.86	59.3976
1632.93	59.7806
1636	60.7866
1639.07	62.2511
1642.13	62.5884
1645.2	64.959
1648.26	65.2299
1651.33	66.276
1654.39	66
1657.45	65.6218
1660.51	65.0324
1663.57	63.5504
1666.63	62.2863
1669.68	60.9311
1672.74	57.1087
1675.79	55.9093
1678.85	52.9324
1681.9	49.6503
1684.95	46.1073
1688	41.1495
1691.05	36.1929
1694.09	32.6739
1697.14	30.2208
1700.18	27.3446
1703.23	24.6266
1706.27	22.7996
1709.31	19.8985
1712.35	17.8893
1715.39	16.8694
1718.43	15.4053
1721.47	15.328
1724.5	13.1859
1727.54	12.5369
1730.57	12.3292
1733.61	11.8146
1736.64	10.5426
1739.67	10.5571
1742.7	9.67109
1745.72	9.0684
1748.75	7.03666
1751.77	6.59528
1754.8	5.1071
1757.82	4.07086
1760.84	3.28729
1763.87	1.5951
1766.89	0.509591
1769.91	0.350629
1772.92	-0.121196
1775.94	-0.768809
1778.95	-0.990558
1781.97	-0.847133
1784.98	-1.20583
1787.99	-0.417504
1791.01	-0.2111
1794.01	0.0012529
1797.02	-0.00413899
1800.03	0.468241
1803.04	2.06513
1806.04	2.01131
1809.05	1.60412
1812.05	2.15333
1815.05	2.61132
1818.05	2.20185
1821.05	1.94155
1824.05	2.35185
1827.05	2.98248
1830.04	3.23616
1833.04	3.6591
1836.03	3.103
1839.03	2.92032
1842.02	3.28655
1845.01	3.37006
1848	3.82342
1850.99	3.82633
1853.97	4.22254
1856.96	4.12367
1859.94	3.57255
1862.93	3.5379
1865.91	2.77893
1868.89	2.93023
1871.87	1.95346
1874.85	1.8512
1877.83	2.72845
1880.81	2.73704
1882.57	2.93395
1885.56	3.94624
1888.55	3.23035
1891.54	3.67509
1894.52	3.58464
1897.51	4.47128
1900.49	4.54277
1903.47	4.56657
1906.45	5.26388
1909.43	5.21259
1912.41	6.111
1915.39	6.60505
1918.37	7.47187
1921.34	7.85964
1924.32	7.45265
1927.29	7.29497
1930.26	7.96937
1933.23	7.41619
1936.2	7.04627
1939.17	7.42845
1942.14	7.72397
1945.11	7.66623
1948.07	8.35743
1951.04	8.72123
1954	9.28555
1956.96	10.5106
1959.93	9.83121
1962.89	9.40627
1965.85	9.34929
1968.8	10.1704
1971.76	9.6417
1974.72	9.17955
1977.67	8.79896
1980.63	8.74745
1983.58	9.45517
1986.53	10.2966
1989.48	9.88437
1992.43	8.98243
1995.38	8.73399
1998.32	8.4797
2001.27	9.41997
2004.22	10.6587
2007.16	11.1382
2010.1	12.0851
2013.04	12.7991
2015.98	13.688
2018.92	13.6102
2021.86	13.7719
2024.8	14.1583
2027.74	14.0005
2030.67	13.9774
2033.61	13.1736
2036.54	12.9918
2039.47	13.4534
2042.4	13.5312
2045.33	12.8479
2048.26	12.7404
2051.19	14.1079
2054.12	14.6355
2057.04	14.6469
2059.97	14.3015
2062.89	14.4863
2065.81	14.5564
2068.73	14.963
2071.65	15.9205
2074.57	17.3955
2077.49	18.6645
2080.41	19.3271
2083.32	19.1697
2086.24	19.0995
2089.15	19.1648
2092.07	18.3863
2094.98	17.7183
2097.89	17.2836
2100.8	17.1717
2103.71	16.8711
2106.61	17.0743
2109.52	17.9457
2112.43	19.1485
2115.33	19.3846
2118.23	19.8078
2121.13	20.015
2124.04	20.6768
2126.94	20.774
2129.83	22.0368
2132.73	22.8815
2135.63	24.5263
2138.53	25.4314
2141.42	25.7301
2144.31	27.5523
2147.21	26.6386
2150.1	25.9274
2152.99	26.088
2155.88	26.949
2158.77	26.4837
2161.65	26.6886
2164.54	26.5578
2167.43	26.8897
2170.31	26.9646
2173.19	26.2821
2176.07	26.1337
2178.96	26.8729
2181.84	26.3851
2184.72	26.0141
2187.59	24.7971
2190.47	24.9015
2193.35	24.204
2196.22	24.9286
2199.09	25.2279
2201.97	24.7548
2204.84	23.3338
2207.71	23.1057
2210.58	21.8045
2213.45	20.9178
2216.31	19.0539
2219.18	19.0253
2222.05	18.4626
2224.91	18.9244
2227.78	17.9147
2230.64	17.6774
2233.5	17.7823
2236.36	17.9095
2239.22	17.186
2242.08	16.8674
2244.93	16.7969
2247.79	17.4092
2250.64	18.9442
2253.5	19.2662
2256.35	19.1509
2259.2	19.2711
2262.05	19.7219
2264.9	19.4489
2267.75	19.6453
2270.6	18.8653
2273.45	17.8244
2276.29	17.2362
2279.14	16.5944
2281.98	16.258
2284.82	15.9409
2287.66	15.8808
2290.5	14.5855
2293.34	12.9229
2296.18	12.567
2299.02	12.231
2301.86	12.6768
2304.69	13.463
2307.53	13.7135
2310.36	14.0627
2313.19	14.2324
2316.02	15.491
2318.85	16.6205
2321.68	16.8874
2324.51	16.1854
2327.34	15.7952
2330.16	16.2059
2332.99	15.4056
2335.81	14.8872
2338.64	14.2395
2341.46	14.2221
2344.28	13.1942
2347.1	12.3244
2349.92	10.8863
2352.74	9.73816
2355.55	8.90237
2358.37	7.61666
2361.19	6.93285
2364	7.9276
2366.81	9.27471
2369.62	9.56565
2372.44	10.421
2375.24	10.7711
2378.05	10.4913
2380.86	10.4229
2383.67	10.6281
2386.47	10.5236
2389.28	11.1759
2392.08	11.1607
2394.89	11.4956
2397.69	11.2513
2400.49	10.569
2403.29	10.4003
2406.09	10.3232
2408.88	9.9194
2411.68	9.51657
2414.48	9.42171
2417.27	7.86013
2420.06	7.04862
2422.86	7.01182
2425.65	6.74213
2428.44	7.37175
2431.23	7.54579
2434.02	8.11903
2436.81	7.57658
2439.59	7.25089
2442.38	8.11504
2445.16	7.18312
2447.95	6.21471
2450.73	5.27995
2453.51	5.22739
2456.29	5.24276
2459.07	6.14702
2461.85	5.00642
2464.63	4.4393
2467.4	3.21953
2470.18	3.22914
2472.95	3.23472
2475.73	2.68108
2478.5	2.57766
2481.27	3.48068
2484.04	2.51485
2486.81	1.37647
2489.58	0.717549
2492.35	1.15697
2495.12	1.30388
2497.88	1.57207
2500.65	1.98121
2503.41	0.648594
2506.17	0.0455342
2508.94	-0.394527
2511.7	-0.223886
2514.46	-0.802243
2517.22	-0.666108
2519.97	0.0650151
2522.73	1.81219
2525.49	2.18597
2528.24	3.08857
2530.99	3.49792
2533.75	3.71533
2536.5	4.60836
2539.25	5.46365
2542	5.60824
2544.75	6.78152
2547.5	7.52162
2550.24	7.27771
2552.99	7.33736
2555.74	7.43602
2558.48	7.58833
2561.22	7.23163
2563.96	7.24365
2566.71	6.47581
2569.45	5.91962
2572.18	4.44468
2574.92	4.61379
2577.66	4.43417
2580.4	4.17825
2583.13	4.0624
2585.87	3.48618
2588.6	4.44716
2591.33	4.34741
2594.06	4.14523
2596.79	4.62695
2599.52	3.85197
2602.25	3.34673
2604.98	3.35845
2607.71	2.92624
2610.43	2.04941
2613.16	2.61374
2615.88	2.74301
2618.6	3.25953
2621.32	2.48178
2624.04	2.58414
2626.76	1.87063
2629.48	1.61669
2632.2	1.52791
2634.92	0.664564
2637.63	1.14663
2640.35	0.957148
2643.06	1.04719
2645.77	0.810632
2648.49	1.12308
2651.2	0.504512
2653.91	0.562731
2656.62	1.45898
2659.33	1.2894
2662.03	0.671889
2664.74	0.891399
2667.44	0.806545
2670.15	1.01542
2672.85	1.02612
2675.55	1.62959
2678.26	2.10287
2680.96	3.30109
2683.66	3.23888
2686.35	3.80919
2689.05	3.56951
2691.75	3.31645
2694.44	2.86268
2697.14	3.13902
2699.83	4.31467
2702.52	3.93358
2705.22	5.53525
2707.91	4.89488
2710.6	5.85122
2713.29	5.92808
2715.97	6.13248
2718.66	5.78894
2721.35	5.51511
2724.03	5.27494
2726.72	5.08463
2729.4	6.34034
2732.08	6.29174
2734.76	5.58458
2737.44	5.47686
2740.12	4.79125
2742.8	4.60412
2745.48	4.72025
2748.16	4.18921
2750.83	3.55785
2753.51	2.77457
2756.18	2.08547
2758.85	1.62014
2761.53	1.72421
2764.2	1.67868
2766.87	2.23098
2769.54	1.84937
2772.2	1.60085
2774.87	1.68758
2777.54	1.23376
2780.2	0.796904
2782.87	0.667642
2785.53	1.12945
2788.19	1.20056
2790.85	0.90252
2793.51	0.944962
2796.17	0.774264
2798.83	0.871203
2801.49	1.00408
2804.15	1.89015
2806.8	1.97033
2809.46	1.99017
2812.11	1.34661
2814.76	1.20956
2817.42	1.7085
2820.07	2.85941
2822.72	4.87651
2825.37	7.45617
2828.02	9.72243
2830.66	12.3855
2833.31	15.0468
2835.96	18.0036
2838.6	21.4264
2841.24	24.7065
2843.89	29.7352
2846.53	35.6381
2849.17	41.3726
2851.81	47.1514
2854.45	52.7256
2857.09	58.4804
2859.72	64.4293
2862.36	69.8946
2865	74.6004
2867.63	79.8653
2870.26	84.4341
2872.9	87.8698
2875.53	90.7414
2878.16	93.2705
2880.79	96.5242
2883.42	99.7969
2886.05	103.133
2888.67	105.901
2891.3	108.213
2893.92	110.774
2896.55	115.325
2899.17	119.224
2901.79	123.733
2904.42	129.535
2907.04	136.028
2909.66	143.484
2912.27	150.397
2914.89	156.698
2917.51	164.546
2920.13	169.234
2922.74	173.635
2925.35	177.543
2927.97	179.534
2930.58	181.523
2933.19	182.151
2935.8	181.753
2938.41	180.712
2941.02	177.846
2943.63	175.313
2946.24	171.559
2948.84	166.596
2951.45	161.043
2954.05	154.8
2956.65	149.989
2959.26	144.427
2961.86	140.006
2964.46	134.313
2967.06	129.565
2969.66	125.124
2972.25	120.752
2974.85	115.931
2977.45	110.28
2980.04	105.464
2982.64	99.3276
2985.23	93.2648
2987.82	86.0905
2990.41	78.5856
2993	72.1188
2995.59	65.5535
2998.18	59.1809
3000.77	53.5508
3003.36	48.6072
3005.94	42.479
3008.53	38.0722
3011.11	33.1019
3013.69	29.5696
3016.28	26.4735
3018.86	24.341
3021.44	22.506
3024.02	21.1554
3026.6	19.7679
3029.18	19.3774
3031.75	19.0614
3034.33	20.1144
3036.9	19.8633
3039.48	20.3876
3042.05	21.7996
3044.62	22.2178
3047.19	22.8209
3049.77	22.8275
3052.34	22.3427
3054.9	21.9576
3057.47	20.7403
3060.04	19.9596
3062.61	19.643
3065.17	19.9445
3067.74	18.5577
3070.3	17.8801
3072.86	17.104
3075.42	15.0823
3077.99	14.1182
3080.54	12.8293
3083.1	11.2633
3085.66	9.25472
3088.22	8.02278
3090.78	7.08996
3093.33	5.81074
3095.89	4.72613
3098.44	4.65339
3100.99	4.64164
3103.54	4.57262
3106.1	4.7354
3108.65	4.24942
3111.2	4.06977
3113.74	3.30402
3116.29	2.87507
3118.84	1.81461
3121.38	2.21678
3123.93	2.33897
3126.47	3.19796
3129.01	2.57892
3131.56	2.08862
3134.1	2.15766
3136.64	1.27022
3139.18	1.04519
3141.72	0.812774
3144.26	0.601696
3146.79	1.31072
3149.33	2.61813