File: data/Raman/poly_smoothed/Thy_50_12_05_1x_45s_532 nm_x100_100%_600 gr_mm_01.txt
#Acq. time (s)=	45
#Accumulations=	2
#Range (cm-¹)=	200...3150
#Windows=	2
#Auto scanning=	Off
#Autofocus=	Off
#Macrospot=	Off
#AutoExposure=	Off
#Spike filter=	Multiple accum.
#Delay time (s)=	0
#Binning=	1
#Readout mode=	Signal
#DeNoise=	Off
#ICS correction=	On
#Dark correction=	Off
#Inst. Process=	Off
#Detector Gain=	Best Dynamic Range
#Detector ADC=	20 kHz
#Detector temperature (°C)=	-69.85
#Instrument=	LabRAM HR Evol
#Detector=	Synapse
#Objective=	x100
#Grating=	600 gr/mm
#ND Filter=	100%
#Laser (nm)=	532
#Hole=	100.021
#Range=	Auto
#Laser Pol.=	No
#Raman. Pol.=	No
#Laser Pol. (°)=	-0.0007625
#Raman Pol. (°)=	89.9995
#Collection=	Microscope
#StageXY=	Marzhauser
#StageZ=	Marzhauser
#X (µm)=	-5089.9
#Y (µm)=	1507.4
#Z (µm)=	62.65
#Full time(mm:ss)=	3:18
#Project=
#Sample=
#Site=
#Title=	Thy_50_12_05_2x_45s_532 nm_x100_100%_600 gr_mm
#Remark=
#Date=	07.07.2022 09:30
#Acquired=	07.07.2022 09:30:26
#Base:Fit=	10.08.2022 10:03:08
#Base:Fit=	10.08.2022 10:03:15
#Base:Fit=	10.08.2022 10:03:19
#Base:Fit=	10.08.2022 10:04:29
#Base:Sub=	10.08.2022 10:04:45
#Filter:Polynom=	16.08.2022 10:20:24
#AxisType[0]=Intens
#AxisUnit[0]=Cnt
#AxisType[1]=Spectr
#AxisUnit[1]=1/cm
200.43	6.64618
204.061	10.7685
207.688	11.1858
211.316	12.4486
214.941	13.4303
218.566	12.615
222.188	13.6027
225.809	13.4985
229.43	13.3771
233.047	13.7223
236.663	13.4102
240.278	14.2949
243.894	14.6037
247.506	13.5391
251.116	12.8691
254.725	13.3424
258.333	12.0797
261.939	12.527
265.546	11.4611
269.15	10.5139
272.752	10.1706
276.353	9.21303
279.952	8.52163
283.55	7.81139
287.146	7.36945
290.739	6.85638
294.333	5.28756
297.925	4.71432
301.516	4.41122
305.106	3.46953
308.694	2.23538
312.279	1.76623
315.864	2.59682
319.448	3.46358
323.029	4.70117
326.61	5.23662
330.19	6.46466
333.766	5.59092
337.343	6.66584
340.917	8.38507
344.491	8.74347
348.062	9.6804
351.633	10.5004
355.201	10.4353
358.77	10.6798
362.335	11.7685
365.899	12.0003
369.464	11.4898
373.025	11.6772
376.585	11.2303
380.143	9.35562
383.702	9.00307
387.258	10.2401
390.812	9.32444
394.365	7.52165
397.916	7.56301
401.467	9.24779
405.015	9.40512
408.565	10.0261
412.111	10.2108
415.656	10.6962
419.197	12.642
422.739	13.4988
426.279	15.1527
429.819	16.3488
433.356	16.0681
436.893	15.9776
440.428	16.1295
443.96	15.714
447.492	16.5136
451.023	16.4173
454.553	16.1214
458.079	16.3986
461.606	16.2038
465.132	17.7084
468.654	18.9236
472.177	18.2534
475.696	18.794
479.217	19.8023
482.733	20.4276
486.251	20.8407
489.765	22.5
493.278	23.7988
496.791	24.442
500.301	26.765
503.81	27.2065
507.319	27.6708
510.825	28.1602
514.33	28.482
517.833	28.4679
521.337	29.5055
524.838	28.8868
528.337	29.8865
531.835	30.6523
535.332	30.9327
538.827	31.8688
542.321	33.4367
545.814	33.4548
549.305	30.9466
552.795	29.0181
556.284	26.7122
559.771	25.3495
563.257	24.9217
566.742	22.5347
570.223	19.2791
573.705	15.9648
577.185	13.602
580.665	11.7141
584.141	10.1609
587.617	8.90486
591.092	8.67602
594.564	8.72862
598.037	7.33333
601.506	5.76636
604.976	7.45764
608.443	8.21775
611.91	9.07808
615.374	11.9067
618.839	13.2732
622.3	14.1389
625.761	16.5798
629.221	18.4079
632.679	20.0196
636.135	21.7541
639.592	23.4016
643.045	25.1784
646.497	26.8074
649.948	28.1405
653.398	28.5088
656.846	29.3444
660.293	30.7558
663.738	32.2007
667.185	33.5151
670.628	33.9382
674.067	34.4011
677.508	36.2123
680.947	36.1146
684.385	37.7597
687.821	38.6099
691.256	39.2973
694.69	38.8513
698.121	38.5868
701.552	40.5211
704.982	41.0776
708.41	43.5578
711.836	44.916
715.262	46.6189
718.685	48.6463
722.108	48.2043
725.53	48.1025
728.949	49.5905
732.369	50.0535
735.785	51.623
739.2	51.5343
742.616	54.5897
746.028	57.1406
749.441	59.8627
752.851	63.6092
756.26	67.1713
759.667	70.1355
763.075	74.5381
766.479	77.199
769.883	79.7967
773.285	80.8686
776.686	82.7489
780.085	83.3495
783.484	84.368
786.881	86.1729
790.276	87.0863
793.671	87.5795
797.064	88.2299
800.456	88.2667
803.846	88.153
807.236	87.8637
810.624	86.4368
814.01	84.9602
817.394	85.7724
820.778	85.2425
824.161	85.4502
827.543	85.8338
830.921	86.7559
834.3	85.3295
837.676	83.0387
841.053	79.8699
844.426	77.612
847.8	75.6159
851.171	72.1831
854.542	70.285
857.911	67.3568
861.279	66.1466
864.645	65.2445
868.01	64.1848
871.375	62.0357
874.737	61.9351
878.097	60.7738
881.457	58.2417
884.817	57.2273
888.174	55.7787
891.53	54.1641
894.884	54.2805
898.237	54.5893
901.589	54.8876
904.94	54.6101
908.289	53.9432
911.637	53.7119
914.984	51.4664
918.33	49.2363
921.674	47.796
925.015	47.2467
928.357	46.5398
931.698	45.0113
935.037	43.5008
938.373	44.4446
941.71	44.6203
945.046	44.4599
948.378	43.8943
951.711	43.1434
955.043	43.6289
958.372	42.1684
961.701	40.8807
965.027	41.5853
968.354	42.0955
971.678	42.2997
975	44.0075
978.324	44.3374
981.644	44.0787
984.962	43.1024
988.282	41.7232
991.598	41.1541
994.913	40.1381
998.227	38.812
1001.54	38.4323
1004.85	37.473
1008.16	37.2611
1011.47	37.4803
1014.78	37.1546
1018.08	38.0804
1021.39	37.831
1024.69	38.8442
1028	37.7527
1031.3	38.4637
1034.6	39.1801
1037.9	39.422
1041.19	38.7422
1044.49	39.1953
1047.79	39.8261
1051.08	37.2986
1054.37	36.3258
1057.66	34.0888
1060.95	29.63
1064.24	27.1231
1067.53	25.6735
1070.81	23.6254
1074.1	21.0185
1077.38	20.653
1080.66	20.1999
1083.94	19.356
1087.22	18.445
1090.5	18.305
1093.78	19.0086
1097.05	18.4959
1100.33	17.7417
1103.6	18.469
1106.87	18.8466
1110.15	18.9334
1113.41	20.0383
1116.68	19.3023
1119.95	17.8528
1123.21	16.4427
1126.48	16.0283
1129.74	15.9556
1133	13.4744
1136.26	11.2777
1139.52	9.25663
1142.78	6.94247
1146.04	6.19018
1149.29	5.17998
1152.55	3.92499
1155.8	5.2852
1159.05	3.84639
1162.3	1.95606
1165.55	2.13918
1168.8	3.3281
1172.05	5.6402
1175.29	7.38904
1178.54	8.70267
1181.78	10.0165
1185.02	11.3515
1188.26	10.9525
1191.5	8.94305
1194.74	10.2054
1197.97	10.561
1201.21	12.3803
1204.44	14.2434
1207.68	15.7174
1210.91	18.2574
1214.14	18.8822
1217.37	19.8285
1220.6	21.1879
1223.82	23.1099
1227.05	25.4671
1230.27	26.7943
1233.49	29.9501
1236.72	31.2369
1239.94	33.0744
1243.16	35.934
1246.37	39.8964
1249.59	43.2314
1252.8	45.7222
1256.02	49.0756
1259.23	50.2913
1262.44	50.5697
1265.66	52.6784
1268.87	54.3369
1272.07	57.5581
1275.28	61.0301
1278.48	62.3547
1281.69	65.3626
1284.89	66.6387
1288.09	67.8427
1291.3	68.5126
1294.49	69.0279
1297.69	68.2321
1300.89	67.1689
1304.09	66.6568
1307.28	66.4241
1310.47	66.6985
1313.66	65.207
1316.86	64.0466
1320.05	63.5723
1323.23	62.5882
1326.42	61.8751
1329.61	61.3154
1332.79	59.3846
1335.98	57.6394
1339.16	55.2659
1342.34	53.5863
1345.52	52.0835
1348.7	50.5451
1351.87	48.7238
1355.05	47.2532
1358.23	45.3231
1361.4	43.3792
1364.57	42.915
1367.74	41.2915
1370.91	39.1855
1374.08	37.3292
1377.25	36.3547
1380.42	36.2973
1383.58	36.1597
1386.75	35.5034
1389.91	35.731
1393.07	34.6433
1396.23	33.9453
1399.39	33.4782
1402.55	34.2406
1405.7	34.5865
1408.86	35.8857
1412.01	37.3911
1415.17	41.0636
1418.32	44.2129
1421.47	49.2682
1424.62	53.5604
1427.77	58.0188
1430.92	63.8394
1434.06	67.562
1437.2	72.1093
1440.35	76.1528
1443.49	78.0686
1446.63	78.0238
1449.77	79.3851
1452.91	78.0164
1456.05	75.9831
1459.18	73.1809
1462.32	69.2144
1465.45	64.2163
1468.59	59.2272
1471.72	52.3456
1474.85	46.7648
1477.98	41.5477
1481.11	37.9993
1484.23	35.0816
1487.36	31.6902
1490.48	30.5012
1493.61	28.7688
1496.73	27.1343
1499.85	26.4277
1502.97	26.6301
1506.09	26.9651
1509.2	26.7492
1512.32	27.8234
1515.44	26.7796
1518.55	27.5882
1521.66	28.2714
1524.77	29.7049
1527.88	30.6377
1530.99	29.8898
1534.1	30.729
1537.21	31.5918
1540.31	32.8196
1543.42	35.9404
1546.52	40.1548
1549.62	43.6011
1552.72	48.0982
1555.82	51.8417
1558.92	54.238
1562.02	55.7307
1565.11	59.3573
1568.21	62.3185
1571.3	63.9873
1574.39	66.6535
1577.49	68.6156
1580.58	71.3588
1583.67	72.5491
1586.75	73.1045
1589.84	71.6955
1592.93	71.8342
1596.01	71.3136
1599.09	69.2396
1602.18	67.4781
1605.26	66.3822
1608.34	63.3758
1611.41	64.2705
1614.49	65.0302
1617.57	65.7028
1620.64	68.7942
1623.72	71.6888
1626.79	72.4342
1629.86	74.2123
1632.93	75.3599
1636	77.5752
1639.07	80.1679
1642.14	83.6633
1645.2	84.871
1648.27	85.9746
1651.33	87.7586
1654.39	87.7776
1657.45	87.7001
1660.51	85.8299
1663.57	82.595
1666.63	78.4614
1669.69	74.1809
1672.74	69.2987
1675.79	65.678
1678.85	61.5665
1681.9	57.0895
1684.95	52.029
1688	47.5985
1691.05	41.5438
1694.1	38.5979
1697.14	36.2731
1700.19	31.7898
1703.23	28.4449
1706.27	25.5054
1709.32	22.1774
1712.35	20.5337
1715.39	18.8808
1718.43	16.8955
1721.47	15.5083
1724.5	14.7074
1727.54	14.3073
1730.57	13.9613
1733.61	12.9404
1736.64	12.1412
1739.67	10.7812
1742.7	10.7311
1745.72	10.7794
1748.75	10.9332
1751.78	10.4951
1754.8	10.6695
1757.82	9.48493
1760.85	8.28355
1763.87	7.82779
1766.89	6.5712
1769.91	6.2476
1772.92	4.50541
1775.94	3.95585
1778.96	3.5322
1781.97	2.48317
1784.98	1.40046
1788	1.05291
1791.01	0.404474
1794.01	0.612232
1797.02	0.869345
1800.03	1.1776
1803.04	0.632411
1806.04	0.863244
1809.05	1.136
1812.05	1.26492
1815.05	2.10731
1818.05	2.94008
1821.05	4.1801
1824.05	4.75171
1827.05	5.18021
1830.04	4.72003
1833.04	4.46712
1836.03	4.16552
1839.03	3.78703
1842.02	3.79879
1845.01	3.77198
1848	3.2052
1850.99	3.66285
1853.97	3.13619
1856.96	3.8704
1859.94	5.36773
1862.93	5.51014
1865.91	6.18692
1868.89	6.74621
1871.87	7.2022
1874.85	7.44501
1877.83	8.18148
1880.81	8.54576
1882.56	8.6825
1885.55	9.74252
1888.54	9.69008
1891.52	9.32035
1894.51	8.46196
1897.49	6.3063
1900.48	6.32636
1903.46	5.79584
1906.44	5.39011
1909.42	4.8432
1912.4	3.43462
1915.38	3.05708
1918.35	3.00718
1921.33	3.82253
1924.3	4.87853
1927.28	5.45138
1930.25	5.42213
1933.22	5.37143
1936.19	4.76955
1939.16	6.04345
1942.13	5.85181
1945.09	5.80242
1948.06	5.22592
1951.03	4.36154
1953.99	4.18737
1956.95	4.66243
1959.91	4.32627
1962.87	3.3984
1965.83	2.87954
1968.79	3.26148
1971.75	3.55995
1974.7	4.95217
1977.66	5.12086
1980.61	5.35281
1983.56	6.04179
1986.52	7.51406
1989.47	8.83371
1992.41	10.5048
1995.36	11.8525
1998.31	12.2655
2001.26	12.1484
2004.2	12.2985
2007.15	12.7384
2010.09	13.0275
2013.03	12.3638
2015.97	11.2357
2018.91	9.96937
2021.85	8.9275
2024.79	8.20208
2027.72	7.97636
2030.66	7.95321
2033.59	6.84002
2036.53	6.20393
2039.46	6.25798
2042.39	6.11121
2045.32	6.49075
2048.25	7.06334
2051.18	7.99293
2054.1	9.38702
2057.03	11.6001
2059.95	12.7284
2062.88	14.3664
2065.8	16.3727
2068.72	18.2639
2071.64	19.7221
2074.56	21.1501
2077.48	23.4441
2080.39	24.1997
2083.31	26.4497
2086.22	27.9084
2089.14	28.803
2092.05	30.9443
2094.96	32.4475
2097.87	35.3265
2100.78	37.2944
2103.69	39.4758
2106.6	41.6696
2109.51	44.3997
2112.41	47.5894
2115.32	50.4459
2118.22	53.5623
2121.12	57.0599
2124.02	60.8876
2126.92	64.6384
2129.82	68.5749
2132.72	72.7822
2135.62	77.9786
2138.51	81.8346
2141.41	86.0138
2144.3	88.9222
2147.19	92.1682
2150.09	95.2746
2152.97	99.4232
2155.86	102.357
2158.75	102.602
2161.64	103.902
2164.53	105.302
2167.41	105.921
2170.3	105.73
2173.18	104.202
2176.06	103.726
2178.94	101.206
2181.82	99.1315
2184.7	96.8583
2187.58	93.999
2190.46	89.931
2193.33	87.0108
2196.21	84.7893
2199.08	81.9976
2201.95	78.7185
2204.83	75.4668
2207.7	71.8628
2210.57	67.8534
2213.43	63.6223
2216.3	60.2242
2219.17	56.7447
2222.03	54.7424
2224.9	51.8417
2227.76	47.7496
2230.62	45.3475
2233.49	43.6159
2236.34	41.0857
2239.2	38.0044
2242.06	35.9829
2244.92	34.3588
2247.78	32.4534
2250.63	30.8241
2253.48	29.1868
2256.34	27.5605
2259.19	25.6332
2262.04	24.2149
2264.89	23.9881
2267.74	22.3968
2270.59	21.0706
2273.43	19.6966
2276.28	18.7763
2279.12	18.1225
2281.97	16.5699
2284.81	15.6882
2287.65	14.4056
2290.49	13.8765
2293.33	12.023
2296.17	10.2599
2299.01	9.94721
2301.84	10.5649
2304.68	10.1599
2307.51	10.2013
2310.35	10.6494
2313.18	11.0308
2316.01	11.8325
2318.84	11.1037
2321.67	10.3745
2324.5	9.47598
2327.33	8.82809
2330.15	8.13131
2332.98	8.49352
2335.8	7.28439
2338.62	7.33468
2341.45	6.50807
2344.27	5.81669
2347.09	5.58806
2349.91	4.56529
2352.72	3.63237
2355.54	2.19135
2358.36	1.26274
2361.17	-0.413154
2363.98	-0.62776
2366.8	-0.00709225
2369.61	0.249905
2372.42	0.334449
2375.23	0.992875
2378.04	1.74182
2380.85	2.14429
2383.66	3.08635
2386.46	2.99694
2389.26	2.98046
2392.07	3.26223
2394.87	3.00313
2397.67	4.04575
2400.47	4.90779
2403.27	4.95487
2406.07	5.58547
2408.87	6.36968
2411.67	7.11006
2414.46	7.58026
2417.26	8.5957
2420.05	10.1669
2422.84	10.3398
2425.64	10.5264
2428.43	10.1689
2431.22	10.0786
2434.01	9.93501
2436.79	9.55879
2439.58	9.84701
2442.37	8.89543
2445.15	8.60154
2447.93	8.3744
2450.72	6.97152
2453.5	6.29855
2456.28	5.52845
2459.06	5.23024
2461.84	4.06227
2464.62	3.80647
2467.39	2.63518
2470.17	3.28939
2472.94	2.61608
2475.72	3.29247
2478.49	3.20285
2481.26	2.57318
2484.03	2.93002
2486.8	2.65987
2489.57	1.28611
2492.34	0.580714
2495.1	0.258101
2497.87	0.331404
2500.63	-0.184812
2503.4	-0.464868
2506.16	-0.480114
2508.92	-1.31902
2511.68	-1.75814
2514.44	-1.19407
2517.2	-1.42094
2519.96	-1.31562
2522.72	-0.934728
2525.47	-0.77701
2528.23	0.155775
2530.98	0.208267
2533.74	-0.0308082
2536.49	0.878922
2539.24	1.82253
2541.99	1.94668
2544.74	2.11235
2547.49	1.73177
2550.23	1.37954
2552.98	1.63101
2555.72	1.72488
2558.47	2.00422
2561.21	1.55623
2563.95	3.13954
2566.69	3.61186
2569.43	2.73284
2572.17	2.85201
2574.91	2.30271
2577.65	2.53599
2580.39	2.89987
2583.12	3.00459
2585.85	2.15972
2588.59	2.43915
2591.32	1.76756
2594.05	2.0956
2596.78	2.07862
2599.51	1.74896
2602.24	2.04521
2604.97	1.95292
2607.69	2.09804
2610.42	2.12169
2613.14	2.1018
2615.87	2.03301
2618.59	2.06693
2621.31	2.33489
2624.03	2.42836
2626.75	2.66582
2629.47	3.00846
2632.19	3.71585
2634.91	2.91248
2637.62	3.90096
2640.34	4.02059
2643.05	3.88569
2645.76	4.21201
2648.48	4.29639
2651.19	4.35305
2653.9	4.30607
2656.6	4.76572
2659.31	4.75686
2662.02	6.23225
2664.73	5.88643
2667.43	6.04284
2670.14	6.28817
2672.84	7.00028
2675.54	6.57683
2678.24	7.33309
2680.94	7.26452
2683.64	7.61849
2686.34	7.03458
2689.04	6.99562
2691.74	7.10877
2694.43	7.83631
2697.13	7.18655
2699.82	7.03845
2702.51	8.03875
2705.21	8.32281
2707.9	8.17047
2710.58	8.59935
2713.27	8.89103
2715.96	9.12232
2718.65	9.55204
2721.33	9.5738
2724.02	10.124
2726.71	11.0757
2729.39	9.96369
2732.07	8.79652
2734.75	9.74994
2737.43	8.90658
2740.11	8.3237
2742.79	8.28164
2745.47	8.51886
2748.14	7.62579
2750.82	7.17567
2753.49	5.84641
2756.17	5.55343
2758.84	4.96911
2761.51	4.51069
2764.18	3.58654
2766.85	4.68213
2769.52	4.35096
2772.19	3.34235
2774.86	2.47118
2777.52	2.00031
2780.19	1.98789
2782.85	1.424
2785.52	1.22042
2788.18	0.844595
2790.84	0.428701
2793.5	-1.05915
2796.16	-1.56656
2798.82	-0.933024
2801.48	-0.757024
2804.13	-0.956
2806.79	-1.00539
2809.45	-0.931828
2812.1	-0.934022
2814.75	-0.753854
2817.41	0.173987
2820.06	2.68756
2822.71	6.14666
2825.36	10.7021
2828	16.1177
2830.65	21.855
2833.3	27.4644
2835.94	32.6964
2838.59	38.858
2841.23	45.4417
2843.87	52.2599
2846.52	59.7914
2849.16	69.6109
2851.8	78.5931
2854.44	88.532
2857.08	97.4459
2859.71	106.434
2862.35	115.912
2864.98	123.271
2867.62	129.747
2870.25	135.305
2872.88	139.912
2875.52	143.727
2878.15	147.846
2880.78	151.04
2883.41	156.643
2886.03	161.174
2888.66	164.951
2891.29	168.221
2893.91	171.735
2896.54	176.531
2899.16	181.165
2901.78	186.313
2904.4	193.364
2907.02	200.934
2909.64	210.891
2912.26	221.789
2914.88	233.276
2917.5	243.195
2920.11	252.276
2922.73	259.124
2925.34	265.066
2927.96	267.967
2930.57	270.237
2933.18	270.447
2935.79	268.149
2938.4	264.509
2941.01	258.94
2943.62	251.345
2946.22	241.986
2948.83	232.769
2951.43	221.129
2954.04	210.643
2956.64	200.028
2959.24	189.686
2961.84	179.197
2964.45	168.294
2967.05	157.967
2969.64	147.548
2972.24	138.464
2974.84	129.641
2977.43	121.125
2980.03	111.079
2982.62	102.104
2985.22	92.4065
2987.81	83.2762
2990.4	74.9504
2992.99	65.8429
2995.58	58.9291
2998.17	51.5812
3000.76	44.1285
3003.34	36.7908
3005.93	29.4594
3008.52	23.718
3011.1	19.0681
3013.68	15.6987
3016.27	11.9048
3018.85	9.62203
3021.43	6.53936
3024.01	4.63265
3026.59	2.43939
3029.16	1.51219
3031.74	0.978288
3034.32	1.58474
3036.89	2.62325
3039.47	2.68298
3042.04	3.37873
3044.61	4.32872
3047.18	5.19086
3049.75	5.99792
3052.32	6.83816
3054.89	7.38047
3057.46	8.23503
3060.03	8.59429
3062.59	8.46427
3065.16	8.13467
3067.72	6.76681
3070.29	6.57132
3072.85	5.76122
3075.41	4.73562
3077.97	3.54138
3080.53	2.67261
3083.09	1.93432
3085.65	0.83234
3088.21	-0.117678
3090.76	0.0449812
3093.32	0.281722
3095.87	0.167424
3098.43	0.485848
3100.98	0.0905844
3103.53	-0.59418
3106.08	-0.289553
3108.63	-0.68435
3111.18	-0.0972465
3113.73	0.835733
3116.28	2.0122
3118.83	2.48441
3121.37	3.56177
3123.92	4.62583
3126.46	6.16649
3129	7.3404
3131.55	8.46262
3134.09	10.862
3136.63	12.2734
3139.17	14.8161
3141.71	16.7736
3144.24	18.95
3146.78	21.5299
3149.32	24.7894