File: data/Raman/poly_smoothed/Thy_20_09_48_1x_45s_532 nm_x100_100%_600 gr_mm_01.txt
#Acq. time (s)=	45
#Accumulations=	2
#Range (cm-¹)=	200...3150
#Windows=	2
#Auto scanning=	Off
#Autofocus=	Off
#Macrospot=	Off
#AutoExposure=	Off
#Spike filter=	Multiple accum.
#Delay time (s)=	0
#Binning=	1
#Readout mode=	Signal
#DeNoise=	Off
#ICS correction=	On
#Dark correction=	Off
#Inst. Process=	Off
#Detector Gain=	Best Dynamic Range
#Detector ADC=	20 kHz
#Detector temperature (°C)=	-69.85
#Instrument=	LabRAM HR Evol
#Detector=	Synapse
#Objective=	x100
#Grating=	600 gr/mm
#ND Filter=	100%
#Laser (nm)=	532
#Hole=	100.021
#Range=	Auto
#Laser Pol.=	No
#Raman. Pol.=	No
#Laser Pol. (°)=	-0.0007625
#Raman Pol. (°)=	89.9995
#Collection=	Microscope
#StageXY=	Marzhauser
#StageZ=	Marzhauser
#X (µm)=	-5932.1
#Y (µm)=	2852.3
#Z (µm)=	-223.8
#Full time(mm:ss)=	3:18
#Project=
#Sample=
#Site=
#Title=	Thy_20_09_48_2x_45s_532 nm_x100_100%_600 gr_mm
#Remark=
#Date=	29.06.2022 14:00
#Acquired=	29.06.2022 14:00:17
#Base:Fit=	10.08.2022 09:52:02
#Base:Fit=	10.08.2022 09:52:12
#Base:Sub=	10.08.2022 09:54:21
#Filter:Polynom=	16.08.2022 10:24:04
#AxisType[0]=Intens
#AxisUnit[0]=Cnt
#AxisType[1]=Spectr
#AxisUnit[1]=1/cm
200.523	26.7196
204.154	21.9692
207.781	17.442
211.409	13.9336
215.034	11.6826
218.659	8.29427
222.281	6.66107
225.903	4.0517
229.522	3.99268
233.14	3.81363
236.756	3.2919
240.373	3.01827
243.986	2.39881
247.598	1.68059
251.208	1.8599
254.818	1.37601
258.427	1.606
262.034	1.36212
265.638	2.61782
269.242	2.47835
272.844	2.92346
276.445	1.90069
280.044	2.2259
283.642	2.4075
287.238	3.77717
290.833	3.72294
294.425	5.43153
298.017	5.94793
301.608	5.69276
305.198	6.35748
308.786	7.17023
312.371	8.09707
315.956	8.48559
319.54	10.8809
323.122	10.8416
326.701	11.747
330.281	11.9038
333.857	11.9911
337.434	12.2806
341.008	12.9583
344.582	12.5311
348.153	13.7321
351.724	15.4327
355.292	14.6404
358.861	13.8388
362.426	13.6055
365.99	12.4053
369.555	13.0754
373.116	12.6821
376.676	12.4922
380.236	12.1564
383.793	11.4633
387.349	10.1206
390.903	8.33887
394.456	6.87517
398.007	8.34812
401.56	8.1125
405.108	7.37891
408.656	7.12417
412.202	5.89024
415.746	4.74104
419.29	5.79528
422.831	6.09941
426.37	5.68329
429.909	6.10489
433.447	6.29387
436.983	6.59697
440.519	6.41332
444.052	6.75952
447.583	6.95538
451.114	6.8452
454.643	7.0116
458.169	8.87267
461.696	8.99052
465.222	10.2756
468.744	11.2936
472.267	12.6795
475.787	12.6536
479.307	14.3448
482.823	16.1187
486.341	17.4434
489.855	17.3988
493.37	17.2981
496.881	17.3709
500.391	17.6077
503.902	19.4039
507.409	19.7922
510.915	19.9669
514.42	20.2357
517.925	20.2508
521.427	20.1179
524.928	21.3945
528.427	21.8282
531.925	21.4294
535.422	20.5063
538.917	18.8999
542.411	19.7348
545.903	19.6314
549.395	18.9526
552.884	18.7185
556.373	17.5796
559.86	18.0748
563.346	16.0148
566.831	15.3545
570.314	14.5426
573.794	12.0489
577.274	11.28
580.754	10.9458
584.23	10.0151
587.706	10.3607
591.181	9.82783
594.653	8.79089
598.126	7.57632
601.595	6.68285
605.065	4.8169
608.532	4.25098
611.999	4.47918
615.463	3.33294
618.928	2.72747
622.389	2.43506
625.851	3.93058
629.31	5.06985
632.767	6.14329
636.223	6.89007
639.68	8.88074
643.134	8.92748
646.586	10.3633
650.037	12.2404
653.486	15.3494
656.936	18.3396
660.383	20.0141
663.829	21.2169
667.273	23.4767
670.716	25.6862
674.158	28.3397
677.598	29.2381
681.035	31.418
684.473	31.6102
687.909	32.862
691.344	34.7193
694.778	36.0232
698.211	38.6113
701.64	39.2833
705.07	40.1125
708.498	40.8406
711.924	40.7601
715.35	40.3147
718.774	41.4464
722.196	43.1134
725.618	43.2876
729.037	44.4714
732.456	47.0867
735.873	49.767
739.289	50.8062
742.703	50.4695
746.116	51.8709
749.529	54.6854
752.938	57.1056
756.347	60.781
759.756	63.6258
763.162	64.9544
766.567	67.7868
769.97	69.258
773.372	71.9365
776.773	72.8044
780.174	73.4778
783.573	73.8626
786.97	73.9815
790.365	73.6127
793.76	73.171
797.153	74.1111
800.543	74.9186
803.933	74.9021
807.322	74.0315
810.71	74.4061
814.097	75.189
817.483	75.4237
820.865	75.0352
824.248	73.5732
827.629	72.9539
831.008	70.4352
834.387	70.38
837.765	69.6241
841.139	67.3446
844.514	64.2785
847.886	61.3314
851.259	58.9276
854.629	56.8594
857.997	53.7896
861.366	51.3297
864.732	51.5401
868.098	49.7253
871.461	48.3935
874.823	45.3338
878.184	45.3951
881.545	45.0691
884.903	45.5955
888.26	45.8556
891.616	46.3244
894.97	46.7969
898.323	47.0388
901.675	48.6798
905.026	49.6278
908.375	49.1284
911.723	49.7651
915.07	50.1955
918.415	50.713
921.76	50.0741
925.103	48.9218
928.443	49.869
931.783	48.2062
935.123	46.6089
938.461	46.827
941.796	45.2528
945.131	44.3694
948.465	41.6822
951.797	40.3048
955.128	39.4777
958.457	36.1623
961.786	35.6376
965.113	34.3563
968.44	33.1959
971.763	32.0107
975.086	32.3881
978.409	31.175
981.729	32.6864
985.048	32.5288
988.367	30.5975
991.683	28.8062
994.998	28.6484
998.312	28.2767
1001.62	27.4573
1004.94	26.362
1008.25	26.5179
1011.56	24.2698
1014.86	23.2369
1018.17	23.8684
1021.48	22.4367
1024.78	21.4074
1028.08	20.7909
1031.38	20.474
1034.68	20.2688
1037.98	18.0442
1041.28	17.6726
1044.57	18.9797
1047.87	20.5008
1051.16	19.7584
1054.45	20.3873
1057.75	19.3595
1061.04	18.5529
1064.32	18.2224
1067.61	18.3424
1070.9	17.1288
1074.18	16.922
1077.47	15.9218
1080.75	17.414
1084.03	18.3369
1087.31	17.13
1090.59	17.129
1093.86	18.6324
1097.14	19.5669
1100.41	18.5706
1103.69	19.1358
1106.96	19.147
1110.23	17.8829
1113.5	16.2608
1116.77	14.3706
1120.03	13.4857
1123.3	14.0199
1126.56	13.013
1129.83	11.1205
1133.09	9.76429
1136.35	9.77331
1139.61	7.95604
1142.86	7.73441
1146.12	7.58658
1149.38	6.8164
1152.63	7.03656
1155.88	6.30655
1159.14	7.47231
1162.39	9.05539
1165.63	7.82566
1168.88	7.57956
1172.13	9.33341
1175.38	10.8741
1178.62	10.5384
1181.86	11.3438
1185.1	10.6114
1188.34	11.417
1191.58	11.0064
1194.82	11.2709
1198.06	12.5837
1201.29	14.2049
1204.53	16.1563
1207.76	16.8607
1210.99	19.7706
1214.22	22.1918
1217.45	23.3028
1220.68	25.5163
1223.91	27.4819
1227.13	29.005
1230.36	31.2231
1233.58	31.6575
1236.8	34.0108
1240.02	36.0522
1243.24	36.4352
1246.46	38.4377
1249.67	39.0802
1252.89	40.1909
1256.1	41.4706
1259.32	42.5741
1262.53	43.6458
1265.74	45.4125
1268.95	45.4975
1272.15	46.2422
1275.36	47.1877
1278.57	49.5988
1281.77	50.6345
1284.97	52.1227
1288.18	54.5311
1291.38	56.587
1294.58	58.1673
1297.78	60.9242
1300.97	62.2116
1304.17	64.7692
1307.36	67.0983
1310.55	68.7957
1313.75	70.2602
1316.94	73.0533
1320.13	74.2385
1323.32	75.183
1326.5	74.744
1329.69	73.26
1332.87	73.2921
1336.06	72.9882
1339.24	70.4345
1342.42	68.2419
1345.6	66.0737
1348.78	64.0858
1351.96	63.3379
1355.13	61.5978
1358.31	59.0077
1361.48	57.1901
1364.65	54.6099
1367.82	53.4188
1370.99	51.4669
1374.16	49.4051
1377.33	49.6544
1380.5	47.899
1383.66	46.9544
1386.83	44.8422
1389.99	43.7839
1393.15	42.5953
1396.31	42.0577
1399.47	40.6138
1402.63	38.3496
1405.78	38.122
1408.94	37.4437
1412.1	38.289
1415.25	39.4965
1418.4	41.9645
1421.55	46.1893
1424.7	50.5378
1427.85	55.2236
1431	58.3245
1434.14	61.3808
1437.29	65.2679
1440.43	67.8318
1443.57	69.4538
1446.71	72.3264
1449.85	73.1363
1452.99	73.4134
1456.13	72.5225
1459.26	68.7147
1462.4	65.9782
1465.54	61.7436
1468.67	59.2894
1471.8	54.1668
1474.93	49.6222
1478.06	44.4463
1481.19	38.6934
1484.31	33.6247
1487.44	29.334
1490.56	26.1959
1493.69	23.5358
1496.81	22.1546
1499.93	19.5491
1503.05	19.4956
1506.17	18.8094
1509.28	18.1361
1512.4	18.5589
1515.52	19.6425
1518.63	20.24
1521.74	21.8465
1524.85	22.8121
1527.96	23.6248
1531.07	24.8602
1534.18	26.7373
1537.29	29.3145
1540.39	32.179
1543.5	36.2355
1546.6	39.6359
1549.7	42.1231
1552.8	46.5884
1555.9	50.5511
1559	54.317
1562.1	59.364
1565.19	63.3687
1568.29	66.173
1571.38	69.4772
1574.47	71.5124
1577.56	73.8791
1580.66	75.0838
1583.74	75.8824
1586.83	77.9759
1589.92	78.0053
1593.01	76.7188
1596.09	75.831
1599.17	73.788
1602.25	71.9727
1605.34	69.4722
1608.41	66.6232
1611.49	64.8056
1614.57	63.0419
1617.65	61.6287
1620.72	60.9108
1623.79	60.9289
1626.87	61.1528
1629.94	61.4395
1633.01	61.9448
1636.08	62.2382
1639.15	62.4828
1642.21	62.4686
1645.28	62.7471
1648.34	61.7908
1651.41	61.9097
1654.47	62.3367
1657.53	61.3573
1660.59	61.1821
1663.65	58.8496
1666.71	55.3963
1669.76	53.481
1672.82	50.3615
1675.87	47.3826
1678.93	43.7999
1681.98	40.0622
1685.03	37.099
1688.08	33.0311
1691.13	30.5308
1694.17	26.0214
1697.22	23.449
1700.27	20.7718
1703.31	17.2005
1706.35	16.1832
1709.39	14.5555
1712.43	13.4345
1715.47	13.3957
1718.51	13.0971
1721.55	11.9476
1724.58	11.5378
1727.62	12.0181
1730.65	11.9581
1733.68	11.8457
1736.72	11.5555
1739.74	10.7696
1742.77	10.653
1745.8	9.92387
1748.83	9.02546
1751.85	8.10495
1754.88	7.76804
1757.9	6.72077
1760.92	4.60651
1763.95	3.02491
1766.96	2.44174
1769.98	1.39327
1773	1.12102
1776.02	1.18212
1779.03	0.0156047
1782.05	0.377295
1785.06	0.427244
1788.07	1.50242
1791.08	1.19851
1794.09	1.90438
1797.1	2.37132
1800.11	3.99782
1803.12	4.25698
1806.12	5.18167
1809.12	5.47742
1812.13	4.73536
1815.13	5.35896
1818.13	5.51664
1821.13	4.75725
1824.13	5.28944
1827.13	5.78248
1830.12	6.30167
1833.12	5.67508
1836.11	6.31977
1839.1	5.53742
1842.09	6.65943
1845.09	6.24529
1848.08	6.23726
1851.06	5.86252
1854.05	5.76269
1857.04	6.949
1860.02	5.62035
1863.01	4.99439
1865.99	4.40496
1868.97	3.97822
1871.95	4.07082
1874.93	4.00131
1877.91	3.74611
1880.89	3.4496
1882.46	3.5289
1885.45	4.24436
1888.43	3.95967
1891.42	3.07059
1894.41	3.56903
1897.39	5.29242
1900.37	5.76458
1903.36	5.92582
1906.34	6.51251
1909.32	6.30121
1912.29	7.97208
1915.27	8.25996
1918.25	8.38875
1921.23	8.54616
1924.2	8.71592
1927.17	8.1019
1930.15	6.87654
1933.12	5.14979
1936.09	4.01614
1939.06	4.27399
1942.02	4.16997
1944.99	3.89071
1947.96	3.17392
1950.92	2.63843
1953.88	2.57843
1956.85	2.61962
1959.81	1.61647
1962.77	1.7689
1965.73	2.22165
1968.69	2.26778
1971.64	2.52991
1974.6	2.0868
1977.55	2.05299
1980.51	1.85504
1983.46	2.73693
1986.41	3.23668
1989.36	3.54556
1992.31	3.14852
1995.26	2.49659
1998.21	3.14831
2001.15	2.77259
2004.1	2.66243
2007.04	2.06416
2009.99	2.45899
2012.93	3.03067
2015.87	2.28085
2018.81	2.88559
2021.75	3.15838
2024.68	4.42833
2027.62	4.59379
2030.56	4.50276
2033.49	5.08996
2036.42	6.11239
2039.36	5.61048
2042.29	5.30337
2045.22	5.1881
2048.14	5.02691
2051.07	5.44424
2054	6.13519
2056.93	6.56919
2059.85	7.36112
2062.77	6.88145
2065.7	7.5001
2068.62	8.42457
2071.54	8.48983
2074.46	9.06718
2077.38	10.6138
2080.29	10.3558
2083.21	11.111
2086.12	11.4787
2089.04	11.7319
2091.95	12.1273
2094.86	12.7153
2097.77	13.3346
2100.68	13.5754
2103.59	15.0006
2106.5	14.9738
2109.41	14.4039
2112.31	14.5662
2115.21	14.7278
2118.12	14.7416
2121.02	15.8016
2123.92	16.6084
2126.82	16.4925
2129.72	17.2696
2132.62	18.2087
2135.51	19.0785
2138.41	19.4814
2141.31	20.7364
2144.2	21.937
2147.09	23.2454
2149.98	23.8897
2152.87	24.5456
2155.76	24.9048
2158.65	25.6361
2161.54	26.4867
2164.43	26.6783
2167.31	27.4643
2170.2	27.4286
2173.08	27.3554
2175.96	27.4157
2178.84	26.1381
2181.72	26.2295
2184.6	25.3438
2187.48	24.5194
2190.36	23.3072
2193.23	22.4913
2196.11	21.6125
2198.98	20.8367
2201.85	19.2888
2204.72	17.7807
2207.59	17.0388
2210.46	16.2686
2213.33	15.8273
2216.2	15.4436
2219.07	14.729
2221.93	13.6597
2224.8	13.151
2227.66	11.1457
2230.52	10.5629
2233.39	9.86886
2236.25	9.59615
2239.1	9.79808
2241.96	8.4299
2244.82	8.30913
2247.68	8.008
2250.53	6.89869
2253.38	7.23953
2256.24	6.84713
2259.09	6.79444
2261.94	6.09334
2264.79	6.03944
2267.64	6.24519
2270.49	5.65276
2273.33	5.7957
2276.18	5.81652
2279.02	4.99151
2281.87	5.18606
2284.71	6.203
2287.55	6.34742
2290.39	4.36891
2293.23	3.48483
2296.07	3.04729
2298.91	3.21083
2301.74	4.43456
2304.58	4.91723
2307.41	5.0371
2310.25	4.7494
2313.08	5.22751
2315.91	5.35917
2318.74	4.66661
2321.57	6.06001
2324.4	6.42038
2327.23	6.84392
2330.05	6.44603
2332.88	6.87022
2335.7	6.34528
2338.52	6.02914
2341.35	4.81614
2344.17	4.96554
2346.99	5.31564
2349.81	5.33746
2352.62	4.87646
2355.44	3.94338
2358.26	2.58252
2361.07	1.60337
2363.89	2.51748
2366.7	3.1333
2369.51	2.94356
2372.32	2.67876
2375.13	2.09124
2377.94	2.05169
2380.75	1.73118
2383.56	0.857611
2386.36	0.0304535
2389.17	0.604264
2391.97	0.24264
2394.77	-0.0681752
2397.58	-0.182154
2400.38	-0.878733
2403.18	-1.6463
2405.97	-1.90901
2408.77	-0.643648
2411.57	-0.199107
2414.37	0.653679
2417.16	0.34842
2419.95	0.976558
2422.75	1.37922
2425.54	1.70955
2428.33	0.988694
2431.12	1.48176
2433.91	1.04295
2436.7	2.26614
2439.48	3.09697
2442.27	3.37278
2445.05	3.79567
2447.84	3.76572
2450.62	4.19431
2453.4	4.26454
2456.18	4.5558
2458.96	4.49069
2461.74	4.18402
2464.52	5.19524
2467.29	5.55239
2470.07	5.72883
2472.85	6.26564
2475.62	6.63135
2478.39	6.11023
2481.16	6.71764
2483.93	6.51016
2486.7	6.83162
2489.47	5.61596
2492.24	4.28961
2495.01	3.14055
2497.77	2.77113
2500.54	2.27418
2503.3	2.83074
2506.06	3.2195
2508.83	3.15811
2511.59	2.3344
2514.35	1.99077
2517.11	2.65611
2519.86	1.98338
2522.62	1.87058
2525.38	2.00948
2528.13	2.41487
2530.89	3.07353
2533.64	3.55174
2536.39	4.066
2539.14	3.87115
2541.89	3.15877
2544.64	3.43695
2547.39	4.48828
2550.14	4.68858
2552.88	4.43563
2555.63	3.41322
2558.37	3.69453
2561.11	3.56264
2563.86	4.26918
2566.6	4.06214
2569.34	5.07141
2572.08	5.16283
2574.82	5.55327
2577.55	5.82385
2580.29	5.68627
2583.02	5.84797
2585.76	5.99018
2588.49	5.20035
2591.22	5.76675
2593.96	6.25937
2596.69	7.45638
2599.42	7.33805
2602.14	6.57448
2604.87	7.03783
2607.6	7.26374
2610.32	7.6769
2613.05	7.03062
2615.77	7.10289
2618.49	6.09877
2621.22	6.18977
2623.94	6.16271
2626.66	5.8927
2629.37	6.38423
2632.09	6.57129
2634.81	6.51064
2637.53	6.1074
2640.24	4.7544
2642.96	3.95267
2645.67	4.01225
2648.38	3.36287
2651.09	2.76727
2653.8	2.55838
2656.51	1.9028
2659.22	3.04359
2661.93	3.20549
2664.63	4.12347
2667.34	4.1236
2670.04	4.44582
2672.75	4.56751
2675.45	4.36255
2678.15	4.40812
2680.85	4.33703
2683.55	5.42879
2686.25	6.27303
2688.94	6.93293
2691.64	7.85281
2694.34	9.22121
2697.03	9.94532
2699.73	10.612
2702.42	11.2372
2705.11	10.9503
2707.8	11.6481
2710.49	12.678
2713.18	12.8526
2715.87	12.2917
2718.55	12.7756
2721.24	12.1708
2723.93	12.6611
2726.61	12.535
2729.29	12.1383
2731.98	11.458
2734.66	10.083
2737.34	8.17894
2740.02	7.12673
2742.7	6.66929
2745.37	6.51469
2748.05	5.88596
2750.72	5.18503
2753.4	5.13162
2756.07	5.48966
2758.75	5.87172
2761.42	5.59352
2764.09	5.07262
2766.76	4.85559
2769.43	4.9135
2772.1	3.90096
2774.76	3.11192
2777.43	2.71675
2780.1	2.48681
2782.76	2.56101
2785.42	2.27449
2788.09	2.73591
2790.75	1.99288
2793.41	1.77684
2796.07	1.63163
2798.73	1.08424
2801.39	1.01363
2804.04	0.690859
2806.7	1.05925
2809.35	1.31939
2812.01	0.772925
2814.66	0.568277
2817.31	0.622587
2819.96	1.80481
2822.61	3.82062
2825.26	5.38568
2827.91	5.38807
2830.56	6.69706
2833.21	9.37598
2835.85	11.8277
2838.5	13.8643
2841.14	17.5959
2843.78	21.1533
2846.42	24.9578
2849.06	30.233
2851.71	34.5714
2854.34	39.373
2856.98	43.8607
2859.62	49.6402
2862.26	53.9408
2864.89	58.3652
2867.53	62.2203
2870.16	64.6021
2872.79	67.832
2875.42	69.618
2878.05	72.0121
2880.68	74.5919
2883.31	77.9897
2885.94	81.4717
2888.57	83.6108
2891.19	84.7546
2893.82	87.3656
2896.44	91.0565
2899.07	93.9518
2901.69	98.1672
2904.31	102.907
2906.93	107.799
2909.55	112.827
2912.17	118.288
2914.79	124.107
2917.41	128.339
2920.02	132.824
2922.64	137.806
2925.25	139.857
2927.86	141.277
2930.48	142.525
2933.09	142.072
2935.7	141.701
2938.31	140.417
2940.92	138.311
2943.53	134.945
2946.13	130.974
2948.74	127.673
2951.34	123.264
2953.95	117.864
2956.55	112.009
2959.15	108.378
2961.75	103.891
2964.35	99.4556
2966.95	94.9711
2969.55	90.9388
2972.15	85.1782
2974.75	79.9991
2977.34	74.1097
2979.94	68.4262
2982.53	62.4914
2985.13	58.132
2987.72	52.3505
2990.31	46.4317
2992.9	41.5018
2995.49	36.7859
2998.08	31.3106
3000.67	26.7829
3003.25	22.0499
3005.84	17.587
3008.42	14.0595
3011.01	11.0054
3013.59	9.28847
3016.17	7.03854
3018.76	5.50153
3021.34	4.32591
3023.92	4.15672
3026.49	4.07658
3029.07	3.88733
3031.65	3.59931
3034.23	3.68009
3036.8	3.51026
3039.38	3.78736
3041.95	5.03858
3044.52	5.86755
3047.09	6.82595
3049.66	7.58484
3052.23	8.15761
3054.8	8.85449
3057.37	8.7342
3059.94	9.25094
3062.5	8.9966
3065.07	8.92583
3067.63	8.73345
3070.2	7.8428
3072.76	7.33915
3075.32	6.31882
3077.88	5.54093
3080.44	4.99207
3083	4.05835
3085.56	3.21156
3088.12	2.53935
3090.67	2.28785
3093.23	1.81229
3095.78	1.53986
3098.34	1.48966
3100.89	1.93321
3103.44	2.84801
3105.99	4.34863
3108.54	4.69965
3111.09	6.14741
3113.64	7.26285
3116.19	9.28653
3118.74	10.9477
3121.28	12.5386
3123.83	14.4384
3126.37	16.0884
3128.91	16.861
3131.46	18.316
3134	18.9133
3136.54	20.2924
3139.08	20.8102
3141.62	21.4237
3144.16	21.3414
3146.69	21.4961
3149.23	22.0267