File: data/Raman/poly_smoothed/Thy_40_11_11_1x_45s_532 nm_x100_100%_600 gr_mm_01.txt
#Acq. time (s)=	45
#Accumulations=	2
#Range (cm-¹)=	200...3150
#Windows=	2
#Auto scanning=	Off
#Autofocus=	Off
#Macrospot=	Off
#AutoExposure=	Off
#Spike filter=	Multiple accum.
#Delay time (s)=	0
#Binning=	1
#Readout mode=	Signal
#DeNoise=	Off
#ICS correction=	On
#Dark correction=	Off
#Inst. Process=	Off
#Detector Gain=	Best Dynamic Range
#Detector ADC=	20 kHz
#Detector temperature (°C)=	-69.85
#Instrument=	LabRAM HR Evol
#Detector=	Synapse
#Objective=	x100
#Grating=	600 gr/mm
#ND Filter=	100%
#Laser (nm)=	532
#Hole=	100.021
#Range=	Auto
#Laser Pol.=	No
#Raman. Pol.=	No
#Laser Pol. (°)=	-0.0007625
#Raman Pol. (°)=	89.9995
#Collection=	Microscope
#StageXY=	Marzhauser
#StageZ=	Marzhauser
#X (µm)=	1990.6
#Y (µm)=	-64.1
#Z (µm)=	424.75
#Full time(mm:ss)=	3:18
#Project=
#Sample=
#Site=
#Title=	Thy_40_11_11_2x_45s_532 nm_x100_100%_600 gr_mm
#Remark=
#Date=	05.07.2022 10:38
#Acquired=	05.07.2022 10:38:22
#Base:Fit=	10.08.2022 10:01:35
#Base:Sub=	10.08.2022 10:01:52
#Filter:Polynom=	16.08.2022 10:21:53
#AxisType[0]=Intens
#AxisUnit[0]=Cnt
#AxisType[1]=Spectr
#AxisUnit[1]=1/cm
200.43	2.05166
204.059	6.45034
207.688	9.72104
211.314	12.1908
214.941	15.3313
218.564	16.9203
222.186	16.8295
225.809	19.0479
229.428	18.0986
233.045	17.026
236.663	15.1807
240.278	14.3246
243.891	13.3411
247.503	11.5083
251.116	10.2808
254.725	9.79836
258.333	6.60297
261.939	6.08591
265.544	6.2516
269.148	6.97619
272.75	7.11577
276.351	5.9066
279.95	5.65823
283.548	6.66438
287.144	7.9171
290.739	9.66863
294.333	10.6542
297.925	12.6645
301.514	14.2704
305.104	16.4813
308.692	16.7305
312.279	17.0895
315.862	16.7395
319.446	17.7854
323.029	16.3383
326.608	15.9034
330.188	17.1216
333.766	17.3796
337.341	16.9215
340.917	16.7049
344.489	17.3628
348.062	15.7418
351.631	16.8856
355.201	15.781
358.768	14.2751
362.333	14.4227
365.899	11.731
369.462	11.4816
373.023	11.3492
376.585	11.8785
380.143	11.8047
383.7	12.3891
387.256	12.785
390.812	11.6524
394.365	12.8349
397.916	11.504
401.467	12.9047
405.015	14.5726
408.563	14.7813
412.109	14.0501
415.654	13.7933
419.197	13.8322
422.739	13.4428
426.279	13.3484
429.819	13.1668
433.356	12.8863
436.891	11.8464
440.426	9.20378
443.96	7.37326
447.492	4.66565
451.021	4.42135
454.551	5.16872
458.079	7.86405
461.604	9.36021
465.13	9.76375
468.654	11.117
472.175	13.3198
475.696	14.4334
479.215	16.4399
482.733	18.3222
486.249	19.6156
489.765	21.3214
493.278	21.1474
496.789	23.1107
500.301	23.5554
503.81	24.4521
507.317	25.0755
510.825	25.0793
514.33	24.739
517.833	23.8319
521.335	22.9353
524.836	21.557
528.335	21.4459
531.835	20.1637
535.332	20.5142
538.827	20.7404
542.321	18.9386
545.814	19.1912
549.305	17.8679
552.795	15.4407
556.282	15.2455
559.769	14.9759
563.255	15.306
566.739	12.8893
570.223	12.4982
573.705	9.83206
577.183	9.34954
580.663	11.7934
584.141	12.0689
587.615	11.573
591.09	10.1209
594.564	9.39104
598.035	8.41682
601.506	8.48872
604.974	7.48895
608.443	7.85193
611.908	8.56268
615.374	8.97769
618.837	9.18021
622.3	9.61192
625.761	10.7283
629.219	12.8119
632.677	13.5538
636.135	13.9447
639.59	16.3588
643.043	18.998
646.495	20.85
649.948	21.2644
653.398	21.4128
656.846	23.7169
660.293	24.4528
663.738	28.0291
667.183	29.4548
670.626	29.7019
674.067	29.0393
677.508	30.5914
680.947	32.2606
684.385	33.042
687.821	33.8884
691.254	37.1662
694.688	38.2304
698.121	39.7547
701.552	40.8568
704.98	41.9316
708.409	43.8228
711.836	44.9433
715.26	45.5128
718.685	46.2273
722.108	46.6258
725.528	48.8778
728.949	50.3564
732.367	51.3386
735.785	51.5565
739.2	52.4576
742.614	53.7668
746.028	56.1598
749.439	58.6665
752.849	60.3293
756.26	64.1763
759.667	67.5811
763.073	70.7627
766.477	71.9752
769.883	73.8456
773.285	76.059
776.686	78.8516
780.085	80.4052
783.484	82.2687
786.881	83.0232
790.276	84.2164
793.671	87.0728
797.064	87.2637
800.456	88.2802
803.846	89.7041
807.234	94.1779
810.622	93.3547
814.008	93.1124
817.394	92.2261
820.778	91.0932
824.159	91.7776
827.541	91.247
830.921	90.3868
834.298	88.3878
837.676	88.5873
841.051	86.5516
844.426	82.0373
847.798	78.4652
851.171	74.6527
854.54	72.2124
857.911	69.5446
861.278	68.6005
864.645	64.9737
868.01	61.7908
871.373	60.9235
874.735	58.6245
878.097	60.1229
881.457	58.8503
884.815	58.6379
888.172	58.2158
891.528	57.0415
894.882	54.5449
898.237	54.6322
901.589	54.5294
904.94	55.5518
908.289	55.4505
911.635	54.6981
914.982	53.5035
918.328	52.584
921.672	52.4204
925.015	48.797
928.357	46.6352
931.698	45.6139
935.035	44.5525
938.373	42.8548
941.71	40.8611
945.044	38.8122
948.378	36.8465
951.709	37.2797
955.041	36.8193
958.372	35.7077
961.699	32.101
965.027	30.375
968.352	30.7333
971.676	31.2428
975	32.4702
978.322	33.2112
981.642	35.6169
984.962	36.0415
988.28	36.9696
991.596	34.917
994.911	36.5899
998.227	35.8954
1001.54	36.1027
1004.85	34.1408
1008.16	33.09
1011.47	32.0495
1014.78	31.7789
1018.08	31.4968
1021.39	28.9953
1024.69	28.6007
1028	27.8592
1031.3	26.2011
1034.6	23.6465
1037.9	21.5636
1041.19	19.6137
1044.49	21.5133
1047.78	22.2261
1051.08	21.0991
1054.37	20.5913
1057.66	18.4045
1060.95	16.9547
1064.24	16.0137
1067.53	15.3514
1070.81	13.8155
1074.1	14.7902
1077.38	15.5834
1080.66	14.9027
1083.94	13.2761
1087.22	13.3063
1090.5	13.1794
1093.78	12.9318
1097.05	12.5822
1100.33	12.2023
1103.6	12.9276
1106.87	14.6539
1110.14	13.7285
1113.41	13.088
1116.68	13.2256
1119.95	12.1229
1123.21	12.9347
1126.48	13.2732
1129.74	10.4498
1133	9.39867
1136.26	8.4371
1139.52	8.66817
1142.78	7.39723
1146.04	6.37063
1149.29	5.62334
1152.55	4.7089
1155.8	4.4461
1159.05	4.04087
1162.3	2.52837
1165.55	2.28264
1168.8	1.66528
1172.05	0.0930565
1175.29	0.336523
1178.54	2.41078
1181.78	1.69119
1185.02	2.57192
1188.26	1.8865
1191.5	1.74312
1194.74	2.42359
1197.97	4.91534
1201.21	8.19142
1204.44	11.4805
1207.68	13.1407
1210.91	15.6342
1214.14	20.3575
1217.37	22.7696
1220.59	25.3173
1223.82	27.5167
1227.05	30.9142
1230.27	32.5593
1233.49	35.8538
1236.72	39.654
1239.94	42.1865
1243.16	46.0143
1246.37	48.4376
1249.59	49.2711
1252.8	50.1445
1256.02	51.3854
1259.23	53.1597
1262.44	51.7982
1265.66	52.463
1268.86	55.4464
1272.07	56.3835
1275.28	58.3633
1278.48	59.7796
1281.69	60.297
1284.89	62.0518
1288.09	63.8526
1291.29	65.4464
1294.49	66.9144
1297.69	66.2539
1300.89	66.0391
1304.08	67.8479
1307.28	67.0661
1310.47	67.925
1313.66	69.1586
1316.85	67.8333
1320.04	67.3306
1323.23	65.4793
1326.42	62.657
1329.61	61.9556
1332.79	59.4094
1335.97	57.4877
1339.16	54.63
1342.34	53.1185
1345.52	52.1033
1348.7	50.3972
1351.87	47.8768
1355.05	46.7591
1358.22	45.4846
1361.4	43.2865
1364.57	42.9897
1367.74	40.8781
1370.91	38.506
1374.08	37.4429
1377.25	36.1434
1380.41	35.5533
1383.58	33.5086
1386.74	32.3841
1389.91	29.8823
1393.07	27.0001
1396.23	26.1653
1399.39	26.3022
1402.55	24.5108
1405.7	24.116
1408.86	23.9846
1412.01	24.2534
1415.17	27.2593
1418.32	29.2596
1421.47	33.0267
1424.62	36.9967
1427.77	41.3929
1430.91	47.1639
1434.06	52.1115
1437.2	56.5335
1440.35	60.2951
1443.49	63.5624
1446.63	66.917
1449.77	69.1369
1452.91	70.3608
1456.05	68.8998
1459.18	67.6539
1462.32	65.8802
1465.45	61.6587
1468.59	56.7744
1471.72	51.9285
1474.85	47.6957
1477.98	41.6863
1481.1	34.6074
1484.23	29.5873
1487.36	24.6687
1490.48	21.2795
1493.61	17.5041
1496.73	13.8091
1499.85	12.467
1502.97	10.5876
1506.09	9.87517
1509.2	9.12763
1512.32	8.44017
1515.43	7.97429
1518.55	7.65265
1521.66	7.79625
1524.77	8.47315
1527.88	9.14954
1530.99	10.4574
1534.1	10.6561
1537.21	11.8445
1540.31	14.6206
1543.42	17.2614
1546.52	21.5052
1549.62	26.2096
1552.72	30.8035
1555.82	34.2783
1558.92	39.5181
1562.02	44.0169
1565.11	50.0883
1568.21	54.2468
1571.3	57.0863
1574.39	60.0171
1577.49	64.07
1580.57	66.944
1583.66	68.7798
1586.75	68.687
1589.84	68.1757
1592.92	67.2128
1596.01	65.5423
1599.09	62.6502
1602.17	60.9221
1605.25	58.9845
1608.33	55.8746
1611.41	53.7332
1614.49	51.8077
1617.57	52.659
1620.64	53.2958
1623.72	54.7135
1626.79	57.5168
1629.86	58.712
1632.93	61.761
1636	63.954
1639.07	67.1876
1642.13	70.1358
1645.2	73.4275
1648.26	77.7143
1651.33	79.8721
1654.39	82.3788
1657.45	83.0665
1660.51	82.8195
1663.57	81.2276
1666.63	79.0596
1669.68	76.3521
1672.74	72.4864
1675.79	68.6259
1678.85	63.4002
1681.9	57.1188
1684.95	51.3852
1688	45.7642
1691.05	39.7634
1694.09	35.9562
1697.14	30.5167
1700.18	26.2055
1703.23	22.183
1706.27	17.9287
1709.31	14.8347
1712.35	11.9451
1715.39	10.3288
1718.43	8.79072
1721.47	7.61588
1724.5	5.17854
1727.54	3.7431
1730.57	4.12573
1733.61	4.40519
1736.64	2.47192
1739.67	0.857639
1742.7	1.07489
1745.72	0.848426
1748.75	0.608763
1751.77	0.216316
1754.8	0.82904
1757.82	0.752644
1760.84	0.740278
1763.87	0.790158
1766.89	0.482775
1769.91	-0.0502255
1772.92	0.250948
1775.94	1.67916
1778.95	1.86283
1781.97	2.39822
1784.98	2.76264
1787.99	2.90125
1791.01	2.9022
1794.01	3.46303
1797.02	3.76534
1800.03	3.61107
1803.04	4.48694
1806.04	4.70082
1809.05	3.79831
1812.05	4.23702
1815.05	4.03154
1818.05	4.66291
1821.05	4.51904
1824.05	4.8021
1827.05	4.81025
1830.04	4.57572
1833.04	5.02506
1836.03	4.89833
1839.03	5.3911
1842.02	5.13677
1845.01	5.06866
1848	4.44723
1850.99	5.08324
1853.97	5.11513
1856.96	6.15861
1859.94	6.86951
1862.93	6.62789
1865.91	7.68661
1868.89	8.16916
1871.87	8.06372
1874.85	7.01907
1877.83	5.9988
1880.81	5.63515
1882.57	5.95827
1885.56	5.2378
1888.55	5.06022
1891.54	5.40452
1894.52	5.99102
1897.51	4.49483
1900.49	5.46804
1903.47	5.12825
1906.45	5.92001
1909.43	6.21398
1912.41	6.21171
1915.39	5.52976
1918.37	5.21787
1921.34	5.69309
1924.32	6.5637
1927.29	6.7278
1930.26	5.66494
1933.23	4.93132
1936.2	3.86678
1939.17	3.21392
1942.14	3.06555
1945.11	1.40606
1948.07	1.53379
1951.04	1.51652
1954	3.04764
1956.96	2.95956
1959.93	3.73673
1962.89	4.12505
1965.85	3.77042
1968.8	4.24846
1971.76	4.00984
1974.72	4.73236
1977.67	4.99666
1980.63	5.07751
1983.58	5.56231
1986.53	5.65273
1989.48	6.49796
1992.43	6.82307
1995.38	5.8222
1998.32	7.4295
2001.27	7.19802
2004.22	7.67785
2007.16	8.33845
2010.1	8.17042
2013.04	8.60854
2015.98	9.3502
2018.92	9.90044
2021.86	10.7988
2024.8	11.8183
2027.74	12.7877
2030.67	13.2883
2033.61	12.9091
2036.54	12.5115
2039.47	12.6037
2042.4	13.3357
2045.33	12.3297
2048.26	13.0539
2051.19	13.5203
2054.12	13.6485
2057.04	14.6078
2059.97	14.3167
2062.89	15.5875
2065.81	16.6973
2068.73	17.192
2071.65	18.0091
2074.57	18.3655
2077.49	19.0207
2080.41	19.1553
2083.32	19.9167
2086.24	20.1783
2089.15	21.5762
2092.07	22.9442
2094.98	25.0543
2097.89	27.2361
2100.8	28.2257
2103.71	30.4095
2106.61	32.5448
2109.52	33.7531
2112.43	35.794
2115.33	38.842
2118.23	41.6806
2121.13	44.4352
2124.04	47.7387
2126.94	51.3465
2129.83	54.9467
2132.73	59.377
2135.63	64.5659
2138.53	69.4225
2141.42	71.9437
2144.31	76.1396
2147.21	80.1664
2150.1	84.1735
2152.99	87.8748
2155.88	91.9127
2158.77	96.3616
2161.65	99.6687
2164.54	103.041
2167.43	105.078
2170.31	107.292
2173.19	107.836
2176.07	108.312
2178.96	107.759
2181.84	105.515
2184.72	104.499
2187.59	101.887
2190.47	98.7752
2193.35	95.3803
2196.22	90.8636
2199.09	87.2453
2201.97	81.1518
2204.84	77.2531
2207.71	72.112
2210.58	66.612
2213.45	62.2877
2216.31	57.9112
2219.18	53.0978
2222.05	49.7952
2224.91	47.0218
2227.78	43.7701
2230.64	41.1893
2233.5	38.7636
2236.36	37.3451
2239.22	35.3372
2242.08	33.425
2244.93	31.4901
2247.79	30.3087
2250.64	29.4901
2253.5	28.1541
2256.35	28.0455
2259.2	28.3821
2262.05	27.607
2264.9	25.7115
2267.75	24.6231
2270.6	23.7277
2273.45	22.1647
2276.29	20.5297
2279.14	18.8553
2281.98	17.088
2284.82	17.3818
2287.66	15.6102
2290.5	14.5825
2293.34	13.9628
2296.18	14.1769
2299.02	13.8586
2301.86	13.9492
2304.69	13.7469
2307.53	13.317
2310.36	13.6659
2313.19	12.9803
2316.02	12.9128
2318.85	13.7161
2321.68	12.4754
2324.51	12.5806
2327.34	11.3679
2330.16	9.83235
2332.99	8.93496
2335.81	7.36377
2338.64	6.91511
2341.46	3.66033
2344.28	1.86905
2347.1	0.620429
2349.92	0.0202763
2352.74	0.152189
2355.55	-0.968476
2358.37	-1.56923
2361.19	-1.49207
2364	-0.379738
2366.81	0.619202
2369.62	0.988582
2372.44	1.71607
2375.24	2.00987
2378.05	2.83452
2380.86	3.4281
2383.67	2.87772
2386.47	3.44404
2389.28	3.65422
2392.08	3.8273
2394.89	4.23862
2397.69	4.17204
2400.49	4.20126
2403.29	5.14714
2406.09	5.30589
2408.88	5.01177
2411.68	5.24586
2414.48	5.85349
2417.27	5.55508
2420.06	6.82162
2422.86	6.31979
2425.65	6.36026
2428.44	6.24773
2431.23	6.95277
2434.02	7.88711
2436.81	7.95722
2439.59	7.2041
2442.38	7.79898
2445.16	7.68764
2447.95	7.75097
2450.73	7.57049
2453.51	7.57076
2456.29	8.95684
2459.07	9.12125
2461.85	8.70139
2464.63	7.65462
2467.4	8.02855
2470.18	7.54742
2472.95	7.5124
2475.73	7.1976
2478.5	7.17063
2481.27	6.59074
2484.04	5.96066
2486.81	5.20522
2489.58	4.94831
2492.35	4.43924
2495.12	4.43686
2497.88	4.49493
2500.65	4.48269
2503.41	4.42689
2506.17	4.60634
2508.94	5.99341
2511.7	6.5445
2514.46	5.7603
2517.22	5.64545
2519.97	5.45409
2522.73	6.04212
2525.49	5.96214
2528.24	5.17824
2530.99	5.54864
2533.75	5.74963
2536.5	6.33765
2539.25	5.71671
2542	6.13454
2544.75	6.40684
2547.5	4.63465
2550.24	3.89471
2552.99	2.98197
2555.74	2.59022
2558.48	2.78652
2561.22	2.04897
2563.96	1.35274
2566.71	1.54067
2569.45	1.6998
2572.18	1.66149
2574.92	2.20813
2577.66	1.42609
2580.4	0.718933
2583.13	0.259195
2585.87	0.811722
2588.6	0.802855
2591.33	1.73725
2594.06	2.67909
2596.79	4.01094
2599.52	4.62915
2602.25	5.22135
2604.98	5.45366
2607.71	4.87945
2610.43	5.50868
2613.16	5.74995
2615.88	5.02935
2618.6	4.52878
2621.32	3.86619
2624.04	3.83632
2626.76	3.06417
2629.48	3.02583
2632.2	2.52701
2634.92	3.2645
2637.63	4.55909
2640.35	5.45293
2643.06	5.45388
2645.77	5.06251
2648.49	5.31093
2651.2	5.36026
2653.91	4.98989
2656.62	5.32736
2659.33	6.02894
2662.03	6.04297
2664.74	6.6501
2667.44	6.31982
2670.15	5.57381
2672.85	5.68218
2675.55	5.87406
2678.26	6.21598
2680.96	6.57001
2683.66	5.26373
2686.35	6.66898
2689.05	6.47188
2691.75	7.26394
2694.44	7.21366
2697.14	8.54342
2699.83	8.29197
2702.52	8.92213
2705.22	9.26606
2707.91	9.22468
2710.6	9.57396
2713.29	9.38649
2715.97	9.4511
2718.66	9.51393
2721.35	9.48918
2724.03	9.9547
2726.72	10.3076
2729.4	10.0541
2732.08	9.88527
2734.76	10.4491
2737.44	10.2283
2740.12	10.9506
2742.8	11.2263
2745.48	11.4178
2748.16	12.0551
2750.83	12.2928
2753.51	12.4332
2756.18	12.0303
2758.85	11.628
2761.53	10.4822
2764.2	9.30566
2766.87	7.7651
2769.54	6.82698
2772.2	6.52142
2774.87	5.87647
2777.54	5.25804
2780.2	4.96631
2782.87	4.51033
2785.53	3.41443
2788.19	2.91033
2790.85	2.74812
2793.51	2.35304
2796.17	2.14145
2798.83	2.17161
2801.49	2.51056
2804.15	2.50622
2806.8	2.28913
2809.46	2.66984
2812.11	3.37172
2814.76	3.86046
2817.42	4.21243
2820.07	5.83273
2822.72	7.64109
2825.37	9.63631
2828.02	11.9229
2830.66	15.238
2833.31	19.2301
2835.96	23.7897
2838.6	27.971
2841.24	33.2621
2843.89	39.2763
2846.53	45.4035
2849.17	51.9844
2851.81	59.4267
2854.45	67.5395
2857.09	76.0817
2859.72	83.4499
2862.36	91.3832
2865	98.9415
2867.63	105.052
2870.26	111.739
2872.9	117.47
2875.53	123.896
2878.16	127.732
2880.79	131.984
2883.42	136.332
2886.05	141.794
2888.67	146.435
2891.3	150.536
2893.92	155.139
2896.55	160.694
2899.17	166.896
2901.79	173.336
2904.42	180.542
2907.04	190.318
2909.66	201.977
2912.27	212.292
2914.89	223.376
2917.51	233.878
2920.13	244.155
2922.74	253.375
2925.35	260.567
2927.97	266.338
2930.58	270.371
2933.19	271.681
2935.8	271.818
2938.41	269.798
2941.02	265.376
2943.63	259.554
2946.24	254.171
2948.84	245.912
2951.45	237.633
2954.05	228.607
2956.65	219.78
2959.26	210.568
2961.86	201.651
2964.46	190.916
2967.06	180.717
2969.66	172.287
2972.25	164.381
2974.85	155.033
2977.45	145.017
2980.04	135.545
2982.64	126.356
2985.23	116.274
2987.82	106.207
2990.41	95.9668
2993	85.8724
2995.59	76.311
2998.18	67.3554
3000.77	59.4206
3003.36	52.7016
3005.94	45.9931
3008.53	40.2652
3011.11	35.5923
3013.69	30.4281
3016.28	27.4237
3018.86	24.9827
3021.44	22.6959
3024.02	20.2358
3026.6	18.1318
3029.18	16.6976
3031.75	16.5306
3034.33	17.6301
3036.9	17.82
3039.48	17.6839
3042.05	18.0826
3044.62	17.8981
3047.19	18.9062
3049.77	18.9581
3052.34	19.3628
3054.9	19.1433
3057.47	18.0699
3060.04	17.8618
3062.61	17.8714
3065.17	16.6244
3067.74	16.1677
3070.3	14.2505
3072.86	12.9008
3075.42	11.3711
3077.99	9.49039
3080.54	8.96
3083.1	7.669
3085.66	6.41197
3088.22	4.68108
3090.78	4.14885
3093.33	3.03275
3095.89	2.31573
3098.44	2.63065
3100.99	1.26825
3103.54	0.814404
3106.1	0.925654
3108.65	2.0953
3111.2	2.48206
3113.74	1.87158
3116.29	2.6863
3118.84	3.27238
3121.38	3.66721
3123.93	5.70422
3126.47	6.10994
3129.01	6.60463
3131.56	7.52346
3134.1	7.7704
3136.64	9.07183
3139.18	10.4084
3141.72	11.3508
3144.26	10.8733
3146.79	9.78088
3149.33	8.39387