File: data/Raman/poly_smoothed/Thy_00_07_49_1x_45s_532 nm_x100_100%_600 gr_mm_01_0.txt
#Acq. time (s)=	45
#Accumulations=	2
#Range (cm-¹)=	200...3150
#Windows=	2
#Auto scanning=	Off
#Autofocus=	Off
#Macrospot=	Off
#AutoExposure=	Off
#Spike filter=	Multiple accum.
#Delay time (s)=	0
#Binning=	1
#Readout mode=	Signal
#DeNoise=	Off
#ICS correction=	On
#Dark correction=	Off
#Inst. Process=	Off
#Detector Gain=	Best Dynamic Range
#Detector ADC=	20 kHz
#Detector temperature (°C)=	-69.85
#Instrument=	LabRAM HR Evol
#Detector=	Synapse
#Objective=	x100
#Grating=	600 gr/mm
#ND Filter=	100%
#Laser (nm)=	532
#Hole=	100.021
#Range=	Auto
#Laser Pol.=	No
#Raman. Pol.=	No
#Laser Pol. (°)=	-0.0007625
#Raman Pol. (°)=	89.9995
#Collection=	Microscope
#StageXY=	Marzhauser
#StageZ=	Marzhauser
#X (µm)=	-1421.6
#Y (µm)=	-634.7
#Z (µm)=	-228
#Full time(mm:ss)=	3:18
#Project=
#Sample=
#Site=
#Title=	Thy_00_07_49_2x_45s_532 nm_x100_100%_600 gr_mm
#Remark=
#Date=	29.06.2022 09:57
#Acquired=	29.06.2022 09:57:16
#Base:Fit=	10.08.2022 10:07:56
#Base:Sub=	10.08.2022 10:08:40
#Filter:Polynom=	16.08.2022 10:26:06
#AxisType[0]=Intens
#AxisUnit[0]=Cnt
#AxisType[1]=Spectr
#AxisUnit[1]=1/cm
200.523	65.0443
204.154	55.2357
207.781	47.7765
211.409	41.738
215.034	36.6613
218.659	33.3681
222.281	28.8894
225.903	29.1523
229.522	24.9899
233.14	21.0365
236.756	17.7476
240.373	16.2415
243.986	14.3392
247.598	13.4604
251.208	12.5142
254.818	10.9544
258.427	10.8185
262.034	11.0259
265.638	10.1302
269.242	10.7079
272.844	9.06768
276.445	7.48024
280.044	6.94656
283.642	7.43772
287.238	7.09228
290.833	8.5008
294.425	8.71047
298.017	8.27425
301.608	9.0862
305.198	9.49817
308.786	11.217
312.371	12.8573
315.956	13.3375
319.54	12.755
323.122	13.8474
326.701	16.3517
330.281	17.6505
333.857	17.665
337.434	17.8994
341.008	18.7583
344.582	18.1703
348.153	18.4106
351.724	17.8786
355.292	15.8752
358.861	13.0963
362.426	12.6673
365.99	10.6798
369.555	10.263
373.116	9.13699
376.676	7.97592
380.236	7.06181
383.793	4.59745
387.349	3.01297
390.903	2.88342
394.456	4.71833
398.007	5.41143
401.56	5.0952
405.108	4.80046
408.656	4.99969
412.202	5.36606
415.746	4.88733
419.29	4.63645
422.831	4.4559
426.37	6.17085
429.909	3.90011
433.447	2.56473
436.983	2.7472
440.519	2.65226
444.052	4.21119
447.583	5.78183
451.114	7.63852
454.643	9.80491
458.169	13.362
461.696	15.8598
465.222	20.8991
468.744	22.2643
472.267	24.1676
475.787	27.9295
479.307	30.348
482.823	33.569
486.341	34.4627
489.855	34.749
493.37	36.2833
496.881	36.2368
500.391	34.8694
503.902	33.9375
507.409	31.7885
510.915	29.7928
514.42	24.3189
517.925	21.1658
521.427	20.6264
524.928	18.0603
528.427	17.0749
531.925	16.5266
535.422	15.4802
538.917	15.3942
542.411	15.118
545.903	14.1881
549.395	15.2842
552.884	15.3557
556.373	15.0721
559.86	15.8163
563.346	16.3637
566.831	16.1973
570.314	16.5815
573.794	15.7892
577.274	14.9202
580.754	13.6326
584.23	12.3
587.706	11.378
591.181	8.62314
594.653	6.80675
598.126	5.06122
601.595	3.50413
605.065	4.7294
608.532	3.61675
611.999	4.40281
615.463	5.06039
618.928	4.85295
622.389	4.97243
625.851	6.21513
629.31	6.69768
632.767	7.10042
636.223	8.45837
639.68	8.72177
643.134	10.001
646.586	10.1271
650.037	9.67644
653.486	9.1302
656.936	10.1247
660.383	9.85528
663.829	11.2945
667.273	13.2535
670.716	13.7157
674.158	14.405
677.598	16.8168
681.035	19.7471
684.473	21.9597
687.909	25.464
691.344	26.8466
694.778	28.7125
698.211	28.8652
701.64	28.2786
705.07	29.1437
708.498	29.3892
711.924	28.4484
715.35	29.7836
718.774	30.1671
722.196	29.6705
725.618	30.9203
729.037	30.638
732.456	30.2179
735.873	31.9959
739.289	32.4939
742.703	35.341
746.116	36.4077
749.529	40.3874
752.938	42.708
756.347	46.8343
759.756	51.6809
763.162	54.9751
766.567	57.4807
769.97	60
773.372	62.7636
776.773	65.4489
780.174	66.6126
783.573	67.3989
786.97	68.108
790.365	71.3722
793.76	74.4364
797.153	76.9827
800.543	77.9619
803.933	78.2399
807.322	77.8106
810.71	77.9259
814.097	77.5048
817.483	79.2437
820.865	81.3231
824.248	82.9843
827.629	84.7429
831.008	86.4571
834.387	86.6543
837.765	87.2212
841.139	86.6286
844.514	85.2504
847.886	81.8771
851.259	80.1582
854.629	77.0251
857.997	73.9867
861.366	69.4508
864.732	66.42
868.098	61.6192
871.461	60.2077
874.823	57.4372
878.184	53.0096
881.545	49.9942
884.903	47.1164
888.26	44.3451
891.616	41.8047
894.97	42.1922
898.323	43.852
901.675	44.1693
905.026	47.8589
908.375	50.189
911.723	52.7846
915.07	53.7157
918.415	53.6743
921.76	54.879
925.103	55.5758
928.443	53.6537
931.783	51.2478
935.123	48.6779
938.461	44.789
941.796	43.3263
945.131	41.7957
948.465	38.8869
951.797	36.2433
955.128	31.7755
958.457	28.1455
961.786	23.6111
965.113	24.8885
968.44	26.4671
971.763	27.8986
975.086	30.4685
978.409	35.2963
981.729	38.8164
985.048	40.4771
988.367	39.8339
991.683	42.5559
994.998	43.2844
998.312	44.5466
1001.62	46.589
1004.94	47.8675
1008.25	48.2783
1011.56	48.2128
1014.86	48.9924
1018.17	49.5175
1021.48	50.1375
1024.78	49.4281
1028.08	50.3227
1031.38	46.5923
1034.68	43.3147
1037.98	40.8272
1041.28	38.9559
1044.57	41.1175
1047.87	45.2183
1051.16	46.2708
1054.45	46.1595
1057.75	45.5159
1061.04	44.9239
1064.32	40.2287
1067.61	36.6002
1070.9	35.9546
1074.18	37.6964
1077.47	37.9695
1080.75	39.0953
1084.03	37.0772
1087.31	38.6851
1090.59	39.8639
1093.86	41.9313
1097.14	44.2575
1100.41	46.2983
1103.69	46.7269
1106.96	48.3396
1110.23	48.1683
1113.5	44.9837
1116.77	43.6679
1120.03	42.2033
1123.3	39.9782
1126.56	38.5536
1129.83	37.5421
1133.09	34.0147
1136.35	29.3699
1139.61	26.0093
1142.86	24.4955
1146.12	20.9171
1149.38	16.1967
1152.63	13.5106
1155.88	9.22567
1159.14	6.60515
1162.39	2.57428
1165.63	1.12344
1168.88	1.67519
1172.13	2.41439
1175.38	4.62514
1178.62	6.25285
1181.86	6.83003
1185.1	7.53318
1188.34	10.4949
1191.58	13.0433
1194.82	15.3961
1198.06	20.0518
1201.29	24.0496
1204.53	29.09
1207.76	34.2618
1210.99	39.801
1214.22	44.4373
1217.45	51.3222
1220.68	56.9856
1223.91	62.572
1227.13	66.3653
1230.36	69.8486
1233.58	72.7399
1236.8	75.9662
1240.02	76.5532
1243.24	79.9137
1246.46	81.1848
1249.67	81.0385
1252.89	81.6302
1256.1	82.5336
1259.32	80.9243
1262.53	80.9266
1265.74	79.2032
1268.95	80.0294
1272.15	79.3896
1275.36	78.0354
1278.57	79.1328
1281.77	79.9199
1284.97	80.4875
1288.18	83.0606
1291.38	86.3514
1294.58	91.2956
1297.78	94.8034
1300.97	100.883
1304.17	106.144
1307.36	111.708
1310.55	116.221
1313.75	122.381
1316.94	127.052
1320.13	130.375
1323.32	131.833
1326.5	133.154
1329.69	134.545
1332.87	135.724
1336.06	133.426
1339.24	131.067
1342.42	127.992
1345.6	125.17
1348.78	121.097
1351.96	115.48
1355.13	109.995
1358.31	106.194
1361.48	100.588
1364.65	96.8339
1367.82	95.0992
1370.99	91.9051
1374.16	89.6061
1377.33	88.9187
1380.5	86.3924
1383.66	85.1456
1386.83	83.6689
1389.99	81.761
1393.15	80.6994
1396.31	78.6647
1399.47	75.0307
1402.63	74.0511
1405.78	72.7997
1408.94	72.9438
1412.1	75.0659
1415.25	80.79
1418.4	84.9542
1421.55	89.6499
1424.7	97.0345
1427.85	104.376
1431	111.127
1434.14	121.077
1437.29	129.321
1440.43	136.302
1443.57	142.33
1446.71	145.926
1449.85	146.322
1452.99	144.8
1456.13	142.259
1459.26	138.16
1462.4	131.416
1465.54	123.514
1468.67	112.696
1471.8	102.053
1474.93	89.4106
1478.06	78.0002
1481.19	67.3743
1484.31	56.7866
1487.44	48.4152
1490.56	43.3539
1493.69	37.2121
1496.81	32.1691
1499.93	27.9966
1503.05	26.1612
1506.17	25.4987
1509.28	24.434
1512.4	24.4202
1515.52	24.3046
1518.63	23.6883
1521.74	24.2235
1524.85	26.05
1527.96	27.2753
1531.07	29.7727
1534.18	31.5662
1537.29	35.4197
1540.39	36.9872
1543.5	40.3413
1546.6	44.573
1549.7	49.6503
1552.8	54.8693
1555.9	60.2815
1559	64.5176
1562.1	68.9202
1565.19	73.7591
1568.29	78.6104
1571.38	81.0264
1574.47	85.3135
1577.56	89.1281
1580.66	92.2582
1583.74	94.9968
1586.83	96.311
1589.92	96.9546
1593.01	95.9698
1596.09	95.8404
1599.17	95.5637
1602.25	95.246
1605.34	93.7698
1608.41	91.5209
1611.49	90.0624
1614.57	89.0519
1617.65	86.1857
1620.72	86.3739
1623.79	86.1921
1626.87	87.1376
1629.94	87.8223
1633.01	88.1421
1636.08	89.2642
1639.15	90.0673
1642.21	92.506
1645.28	96.3714
1648.34	100.394
1651.41	104.595
1654.47	107.019
1657.53	109.008
1660.59	109.831
1663.65	108.232
1666.71	105.852
1669.76	103.403
1672.82	99.4088
1675.87	94.3108
1678.93	88.0937
1681.98	81.709
1685.03	74.4382
1688.08	67.2128
1691.13	60.5543
1694.17	53.2844
1697.22	47.3679
1700.27	40.2796
1703.31	34.2385
1706.35	28.0372
1709.39	22.8243
1712.43	19.2894
1715.47	16.3473
1718.51	14.5075
1721.55	12.8987
1724.58	12.2901
1727.62	10.5582
1730.65	9.2491
1733.68	8.68387
1736.72	7.00908
1739.74	5.42772
1742.77	4.55219
1745.8	4.44825
1748.83	3.5565
1751.85	3.46579
1754.88	3.09972
1757.9	2.95695
1760.92	3.59355
1763.95	3.7527
1766.96	3.41999
1769.98	2.74554
1773	2.7254
1776.02	3.02636
1779.03	3.20713
1782.05	3.37973
1785.06	3.07808
1788.07	3.44015
1791.08	2.82325
1794.09	2.49586
1797.1	2.81504
1800.11	2.68865
1803.12	2.15781
1806.12	2.1912
1809.12	2.49702
1812.13	2.15447
1815.13	2.30034
1818.13	3.09389
1821.13	3.22935
1824.13	3.69804
1827.13	4.04392
1830.12	3.69329
1833.12	4.11748
1836.11	4.48735
1839.1	4.09758
1842.09	5.17361
1845.09	5.52369
1848.08	6.21493
1851.06	7.49506
1854.05	7.85517
1857.04	8.1226
1860.02	7.68607
1863.01	7.27046
1865.99	6.51836
1868.97	6.98705
1871.95	6.66398
1874.93	5.45561
1877.91	5.94834
1880.89	5.31708
1882.46	4.37908
1885.45	3.8957
1888.43	4.65685
1891.42	3.43304
1894.41	3.63349
1897.39	3.44604
1900.37	2.50272
1903.36	2.76604
1906.34	2.79143
1909.32	3.37186
1912.29	3.69122
1915.27	4.71505
1918.25	5.19932
1921.23	6.27105
1924.2	6.61404
1927.17	7.2833
1930.15	7.79992
1933.12	8.03201
1936.09	8.05619
1939.06	8.16808
1942.02	9.79506
1944.99	8.58956
1947.96	7.32891
1950.92	6.47183
1953.88	5.34
1956.85	4.44442
1959.81	3.22735
1962.77	1.50896
1965.73	1.04442
1968.69	0.74365
1971.64	-0.559832
1974.6	-1.16977
1977.55	-0.80132
1980.51	-0.888148
1983.46	-0.296125
1986.41	-0.56741
1989.36	0.995132
1992.31	1.94154
1995.26	2.98219
1998.21	4.89159
2001.15	6.15244
2004.1	6.31628
2007.04	7.17358
2009.99	7.61528
2012.93	8.26282
2015.87	8.03529
2018.81	7.01319
2021.75	7.85448
2024.68	8.65589
2027.62	8.13441
2030.56	7.28975
2033.49	7.40301
2036.42	7.62773
2039.36	7.30182
2042.29	7.72057
2045.22	8.39675
2048.14	8.74155
2051.07	8.33278
2054	8.09748
2056.93	9.16635
2059.85	9.14601
2062.77	8.73134
2065.7	8.41777
2068.62	9.43715
2071.54	9.62503
2074.46	8.60469
2077.38	7.67218
2080.29	7.49286
2083.21	7.11877
2086.12	7.20974
2089.04	6.72717
2091.95	6.51367
2094.86	6.04076
2097.77	6.16499
2100.68	6.12187
2103.59	6.38687
2106.5	6.61958
2109.41	6.44508
2112.31	5.83442
2115.21	7.54671
2118.12	7.24052
2121.02	7.34639
2123.92	7.79602
2126.82	8.2789
2129.72	8.14783
2132.62	7.32252
2135.51	7.62477
2138.41	7.60371
2141.31	6.94359
2144.2	6.59981
2147.09	6.22067
2149.98	5.47088
2152.87	6.51598
2155.76	6.26126
2158.65	5.48141
2161.54	4.84079
2164.43	5.89469
2167.31	7.42325
2170.2	7.70297
2173.08	8.8467
2175.96	9.04077
2178.84	8.60691
2181.72	8.60781
2184.6	9.86992
2187.48	10.3719
2190.36	10.8838
2193.23	10.6643
2196.11	10.9461
2198.98	9.82238
2201.85	8.91447
2204.72	8.51663
2207.59	8.54687
2210.46	6.7763
2213.33	7.21441
2216.2	7.65447
2219.07	7.68725
2221.93	7.43022
2224.8	6.55919
2227.66	5.49191
2230.52	6.29722
2233.39	7.67395
2236.25	8.46694
2239.1	9.71216
2241.96	12.1246
2244.82	12.6851
2247.68	13.0766
2250.53	13.2959
2253.38	14.8649
2256.24	15.7186
2259.09	16.2324
2261.94	16.4081
2264.79	16.6048
2267.64	16.1504
2270.49	15.6221
2273.33	14.8972
2276.18	13.7005
2279.02	13.2181
2281.87	12.0737
2284.71	11.4274
2287.55	9.43754
2290.39	7.61461
2293.23	6.01389
2296.07	5.00108
2298.91	6.73622
2301.74	7.03337
2304.58	7.14094
2307.41	7.7179
2310.25	8.17075
2313.08	7.97785
2315.91	8.05534
2318.74	8.45323
2321.57	8.93614
2324.4	9.76405
2327.23	9.42579
2330.05	9.08951
2332.88	9.57121
2335.7	9.54696
2338.52	8.31974
2341.35	7.37375
2344.17	5.71278
2346.99	5.45269
2349.81	4.23187
2352.62	2.90319
2355.44	2.22104
2358.26	1.74143
2361.07	1.85216
2363.89	2.91963
2366.7	4.19642
2369.51	3.68417
2372.32	3.58643
2375.13	2.96933
2377.94	2.06335
2380.75	2.30823
2383.56	2.19536
2386.36	1.68719
2389.17	1.71752
2391.97	2.53894
2394.77	3.27725
2397.58	2.26858
2400.38	2.32629
2403.18	2.77975
2405.97	2.83235
2408.77	2.32348
2411.57	2.84108
2414.37	3.61751
2417.16	3.93732
2419.95	3.93265
2422.75	5.14965
2425.54	5.71466
2428.33	7.41259
2431.12	8.88423
2433.91	9.04585
2436.7	9.16962
2439.48	8.8485
2442.27	9.34288
2445.05	8.22464
2447.84	7.48582
2450.62	7.30315
2453.4	6.56949
2456.18	6.48889
2458.96	6.1431
2461.74	5.6699
2464.52	4.21088
2467.29	3.78362
2470.07	3.14431
2472.85	2.56695
2475.62	1.5424
2478.39	0.668371
2481.16	0.269361
2483.93	1.26395
2486.7	0.52057
2489.47	0.568592
2492.24	0.674698
2495.01	1.71164
2497.77	2.99515
2500.54	2.18397
2503.3	2.01026
2506.06	1.83819
2508.83	2.22748
2511.59	1.87401
2514.35	2.40544
2517.11	2.92927
2519.86	3.72834
2522.62	4.00559
2525.38	4.75994
2528.13	4.26228
2530.89	4.13707
2533.64	4.00837
2536.39	3.32677
2539.14	3.44676
2541.89	3.6024
2544.64	3.78038
2547.39	3.9582
2550.14	3.63711
2552.88	2.38788
2555.63	1.23065
2558.37	1.20279
2561.11	1.19121
2563.86	1.15735
2566.6	0.257619
2569.34	-0.191088
2572.08	-0.101334
2574.82	-0.00877261
2577.55	0.364087
2580.29	1.16912
2583.02	2.07132
2585.76	2.70389
2588.49	3.23347
2591.22	3.8028
2593.96	3.95496
2596.69	4.21541
2599.42	5.13363
2602.14	6.06277
2604.87	6.6568
2607.6	7.44549
2610.32	8.19493
2613.05	8.38459
2615.77	7.69786
2618.49	7.16039
2621.22	7.60749
2623.94	7.90359
2626.66	8.68017
2629.37	8.52474
2632.09	9.52822
2634.81	10.4402
2637.53	11.13
2640.24	10.2154
2642.96	9.73476
2645.67	9.72335
2648.38	9.78498
2651.09	9.3863
2653.8	8.51527
2656.51	8.02738
2659.22	8.03206
2661.93	7.51736
2664.63	7.27022
2667.34	6.89281
2670.04	5.56548
2672.75	5.56426
2675.45	5.12604
2678.15	4.57078
2680.85	3.67043
2683.55	3.03416
2686.25	3.9501
2688.94	4.48674
2691.64	5.16062
2694.34	6.59466
2697.03	8.63117
2699.73	9.76754
2702.42	9.58326
2705.11	10.847
2707.8	11.8701
2710.49	12.6226
2713.18	13.5157
2715.87	13.8733
2718.55	13.6778
2721.24	13.8292
2723.93	14.2137
2726.61	13.5238
2729.29	12.9454
2731.98	11.897
2734.66	11.1267
2737.34	10.9804
2740.02	10.8416
2742.7	9.67185
2745.37	8.99278
2748.05	8.4739
2750.72	9.07872
2753.4	7.37408
2756.07	6.53225
2758.75	6.85508
2761.42	6.7644
2764.09	5.63053
2766.76	4.16722
2769.43	4.38716
2772.1	4.41837
2774.76	3.73845
2777.43	2.83463
2780.1	2.13979
2782.76	1.84649
2785.42	0.974012
2788.09	0.483465
2790.75	-0.545519
2793.41	-0.90917
2796.07	-0.344042
2798.73	0.513587
2801.39	1.09877
2804.04	2.04557
2806.7	2.50984
2809.35	2.21742
2812.01	2.22478
2814.66	2.72502
2817.31	3.06664
2819.96	4.77932
2822.61	7.29613
2825.26	10.6017
2827.91	14.8804
2830.56	17.8044
2833.21	22.3278
2835.85	26.9802
2838.5	33.2669
2841.14	41.118
2843.78	50.5554
2846.42	62.0598
2849.06	73.5834
2851.71	86.8305
2854.34	101.013
2856.98	114.826
2859.62	129.689
2862.26	143.758
2864.89	156.658
2867.53	170.224
2870.16	183.212
2872.79	194.491
2875.42	206.262
2878.05	217.725
2880.68	228.763
2883.31	238.825
2885.94	248.757
2888.57	259.119
2891.19	268.153
2893.82	276.245
2896.44	284.013
2899.07	294.509
2901.69	304.59
2904.31	316.284
2906.93	329.357
2909.55	342.217
2912.17	354.548
2914.79	367.834
2917.41	379.056
2920.02	388.214
2922.64	395.829
2925.25	400.486
2927.86	403.712
2930.48	403.445
2933.09	400.206
2935.7	395.293
2938.31	389.052
2940.92	381.135
2943.53	370.835
2946.13	359.069
2948.74	346.842
2951.34	335.056
2953.95	321.439
2956.55	307.242
2959.15	293.189
2961.75	280.821
2964.35	267.299
2966.95	253.082
2969.55	242.299
2972.15	230.586
2974.75	218.772
2977.34	207.064
2979.94	195.452
2982.53	181.799
2985.13	168.282
2987.72	154.153
2990.31	140.075
2992.9	124.906
2995.49	109.674
2998.08	96.6454
3000.67	85.0574
3003.25	74.4925
3005.84	62.7077
3008.42	53.1663
3011.01	44.5327
3013.59	37.0109
3016.17	30.5471
3018.76	24.6803
3021.34	19.6193
3023.92	15.4356
3026.49	12.7672
3029.07	10.1615
3031.65	8.62428
3034.23	8.61542
3036.8	9.09999
3039.38	8.86502
3041.95	10.2292
3044.52	11.1807
3047.09	12.717
3049.66	13.864
3052.23	15.0281
3054.8	14.6408
3057.37	14.9833
3059.94	15.2284
3062.5	15.4328
3065.07	15.2292
3067.63	13.9004
3070.2	13.8981
3072.76	12.3426
3075.32	10.3876
3077.88	8.80143
3080.44	6.42022
3083	4.08814
3085.56	2.70378
3088.12	0.965355
3090.67	0.494025
3093.23	-0.482714
3095.78	-0.345535
3098.34	0.116284
3100.89	0.887176
3103.44	1.69014
3105.99	2.8927
3108.54	4.35222
3111.09	5.79153
3113.64	5.90658
3116.19	7.26827
3118.74	7.79258
3121.28	9.65395
3123.83	11.0161
3126.37	13.1099
3128.91	14.9035
3131.46	16.5135
3134	17.8277
3136.54	18.9369
3139.08	20.7031
3141.62	22.9496
3144.16	25.258
3146.69	28.2891
3149.23	31.8739