File: data/Raman/poly_smoothed/Thy_20_09_34_1x_45s_532 nm_x100_100%_600 gr_mm_01.txt
#Acq. time (s)=	45
#Accumulations=	2
#Range (cm-¹)=	200...3150
#Windows=	2
#Auto scanning=	Off
#Autofocus=	Off
#Macrospot=	Off
#AutoExposure=	Off
#Spike filter=	Multiple accum.
#Delay time (s)=	0
#Binning=	1
#Readout mode=	Signal
#DeNoise=	Off
#ICS correction=	On
#Dark correction=	Off
#Inst. Process=	Off
#Detector Gain=	Best Dynamic Range
#Detector ADC=	20 kHz
#Detector temperature (°C)=	-69.85
#Instrument=	LabRAM HR Evol
#Detector=	Synapse
#Objective=	x100
#Grating=	600 gr/mm
#ND Filter=	100%
#Laser (nm)=	532
#Hole=	100.021
#Range=	Auto
#Laser Pol.=	No
#Raman. Pol.=	No
#Laser Pol. (°)=	-0.0007625
#Raman Pol. (°)=	89.9995
#Collection=	Microscope
#StageXY=	Marzhauser
#StageZ=	Marzhauser
#X (µm)=	-5919.6
#Y (µm)=	2873.2
#Z (µm)=	-222.75
#Full time(mm:ss)=	3:19
#Project=
#Sample=
#Site=
#Title=	Thy_20_09_34_2x_45s_532 nm_x100_100%_600 gr_mm
#Remark=
#Date=	29.06.2022 13:02
#Acquired=	29.06.2022 13:02:16
#Base:Fit=	10.08.2022 09:52:02
#Base:Fit=	10.08.2022 09:52:12
#Base:Sub=	10.08.2022 09:54:21
#Filter:Polynom=	16.08.2022 10:24:04
#AxisType[0]=Intens
#AxisUnit[0]=Cnt
#AxisType[1]=Spectr
#AxisUnit[1]=1/cm
200.523	20.6755
204.154	15.6683
207.781	12.2962
211.409	9.27256
215.034	6.6118
218.659	5.79368
222.281	4.64138
225.903	4.72546
229.522	4.16188
233.14	5.49632
236.756	6.46655
240.373	6.96734
243.986	8.61983
247.598	8.93915
251.208	9.70288
254.818	11.2395
258.427	12.141
262.034	13.265
265.638	12.9139
269.242	15.2671
272.844	15.1299
276.445	15.1496
280.044	15.0002
283.642	13.9461
287.238	12.1759
290.833	12.1667
294.425	12.7631
298.017	11.0966
301.608	11.6377
305.198	11.4742
308.786	10.6975
312.371	9.29284
315.956	9.55367
319.54	9.45979
323.122	10.6237
326.701	10.6681
330.281	10.1893
333.857	9.99881
337.434	9.46141
341.008	9.50055
344.582	8.57666
348.153	8.25115
351.724	6.8733
355.292	5.5309
358.861	4.99764
362.426	6.44686
365.99	5.76199
369.555	4.10798
373.116	3.47931
376.676	3.24052
380.236	4.38162
383.793	4.25544
387.349	5.26089
390.903	5.42221
394.456	5.14844
398.007	4.22638
401.56	4.24108
405.108	5.32741
408.656	5.89222
412.202	7.4004
415.746	7.2303
419.29	8.24611
422.831	8.36935
426.37	9.08742
429.909	7.86513
433.447	7.48239
436.983	7.04559
440.519	5.97754
444.052	5.39123
447.583	6.11109
451.114	4.45287
454.643	3.80418
458.169	2.74325
461.696	2.6163
465.222	4.27301
468.744	5.03026
472.267	6.35857
475.787	7.47054
479.307	7.70645
482.823	8.11108
486.341	9.72878
489.855	12.0168
493.37	13.0833
496.881	16.0207
500.391	17.6515
503.902	18.6201
507.409	20.5876
510.915	22.1832
514.42	21.8168
517.925	22.2331
521.427	22.6912
524.928	23.1203
528.427	22.1295
531.925	22.0809
535.422	21.0685
538.917	19.6239
542.411	19.8169
545.903	19.6473
549.395	19.8016
552.884	19.242
556.373	19.4363
559.86	17.6816
563.346	18.0737
566.831	18.7865
570.314	19.1184
573.794	19.3262
577.274	17.8426
580.754	16.7903
584.23	16.2874
587.706	15.0854
591.181	13.9113
594.653	13.0872
598.126	12.6055
601.595	13.0188
605.065	12.8904
608.532	13.8881
611.999	12.7974
615.463	11.8614
618.928	12.3425
622.389	12.4907
625.851	14.0704
629.31	15.3886
632.767	15.2353
636.223	16.0585
639.68	18.4311
643.134	19.0219
646.586	22.1579
650.037	24.5879
653.486	26.3991
656.936	26.9507
660.383	27.4529
663.829	27.3018
667.273	28.6893
670.716	29.3431
674.158	30.7939
677.598	31.7262
681.035	34.1295
684.473	35.4132
687.909	36.8791
691.344	38.1962
694.778	39.2552
698.211	39.5884
701.64	41.4363
705.07	42.3832
708.498	44.0501
711.924	45.0278
715.35	44.4429
718.774	47.3237
722.196	51.2054
725.618	51.6617
729.037	54.5451
732.456	57.4616
735.873	58.3116
739.289	60.9358
742.703	61.7034
746.116	62.6643
749.529	63.0817
752.938	64.6513
756.347	65.5522
759.756	66.9903
763.162	68.9664
766.567	71.648
769.97	72.4051
773.372	73.3231
776.773	74.6378
780.174	75.6513
783.573	76.6945
786.97	78.9947
790.365	80.5365
793.76	83.1812
797.153	83.4367
800.543	85.5075
803.933	87.3761
807.322	89.5161
810.71	90.2664
814.097	90.0228
817.483	89.9556
820.865	90.5869
824.248	90.805
827.629	90.4189
831.008	89.7405
834.387	90.0037
837.765	89.1949
841.139	88.1983
844.514	87.0668
847.886	84.2915
851.259	80.2568
854.629	76.1001
857.997	73.5428
861.366	69.7229
864.732	67.7715
868.098	66.3705
871.461	63.8725
874.823	61.2526
878.184	58.3913
881.545	55.3871
884.903	55.3534
888.26	53.1531
891.616	51.251
894.97	50.7931
898.323	51.8613
901.675	52.96
905.026	53.4136
908.375	51.6235
911.723	51.875
915.07	51.9954
918.415	52.5357
921.76	53.0052
925.103	52.5405
928.443	49.7277
931.783	49.4845
935.123	49.421
938.461	48.2961
941.796	47.3841
945.131	46.4527
948.465	47.4084
951.797	47.2348
955.128	46.5392
958.457	44.6522
961.786	43.1878
965.113	44.1649
968.44	45.0752
971.763	46.7808
975.086	48.3739
978.409	49.8883
981.729	50.7731
985.048	51.3861
988.367	50.9962
991.683	49.9286
994.998	51.3831
998.312	51.4943
1001.62	52.6225
1004.94	50.8912
1008.25	50.3325
1011.56	49.3491
1014.86	48.303
1018.17	46.5803
1021.48	44.5401
1024.78	42.071
1028.08	39.9596
1031.38	38.6328
1034.68	35.8847
1037.98	32.2382
1041.28	30.3258
1044.57	30.4409
1047.87	30.5105
1051.16	29.0535
1054.45	28.4698
1057.75	25.0085
1061.04	25.4088
1064.32	25.0771
1067.61	23.4346
1070.9	22.8191
1074.18	23.678
1077.47	23.2689
1080.75	23.7252
1084.03	23.8281
1087.31	22.483
1090.59	23.362
1093.86	23.6135
1097.14	23.7702
1100.41	24.5868
1103.69	23.9346
1106.96	24.3614
1110.23	25.3535
1113.5	24.3734
1116.77	22.9184
1120.03	22.5281
1123.3	21.122
1126.56	18.7
1129.83	16.133
1133.09	15.5132
1136.35	13.8998
1139.61	11.8447
1142.86	11.411
1146.12	9.8884
1149.38	9.79962
1152.63	9.90307
1155.88	7.67534
1159.14	6.24519
1162.39	6.53442
1165.63	3.45744
1168.88	3.609
1172.13	4.8512
1175.38	6.48523
1178.62	7.17662
1181.86	7.62838
1185.1	9.46475
1188.34	10.302
1191.58	9.94617
1194.82	10.5102
1198.06	10.527
1201.29	11.7159
1204.53	14.484
1207.76	17.5833
1210.99	20.7126
1214.22	23.8437
1217.45	25.2976
1220.68	28.9545
1223.91	33.3153
1227.13	35.5985
1230.36	38.3858
1233.58	39.9588
1236.8	40.6499
1240.02	42.3711
1243.24	43.7581
1246.46	46.4081
1249.67	47.8872
1252.89	50.251
1256.1	49.625
1259.32	50.843
1262.53	52.3789
1265.74	54.3048
1268.95	54.2749
1272.15	55.1541
1275.36	55.8813
1278.57	56.6313
1281.77	59.0205
1284.97	59.7252
1288.18	60.4424
1291.38	60.3465
1294.58	62.2179
1297.78	62.6118
1300.97	63.61
1304.17	63.5214
1307.36	64.4858
1310.55	64.4959
1313.75	64.6721
1316.94	64.7215
1320.13	65.1077
1323.32	64.6754
1326.5	64.3712
1329.69	62.3145
1332.87	62.196
1336.06	60.9911
1339.24	61.1192
1342.42	60.6234
1345.6	59.4743
1348.78	57.8474
1351.96	57.1471
1355.13	54.7199
1358.31	52.4852
1361.48	49.6425
1364.65	47.2178
1367.82	45.7563
1370.99	42.7961
1374.16	42.5571
1377.33	40.7141
1380.5	40.1796
1383.66	38.7445
1386.83	39.1499
1389.99	37.3154
1393.15	37.4257
1396.31	37.2713
1399.47	36.9217
1402.63	35.9961
1405.78	36.2187
1408.94	36.6889
1412.1	38.9394
1415.25	40.0374
1418.4	42.3961
1421.55	45.8458
1424.7	50.2986
1427.85	53.0544
1431	56.5247
1434.14	60.1481
1437.29	62.4256
1440.43	64.2221
1443.57	66.3725
1446.71	68.1796
1449.85	69.8597
1452.99	71.1155
1456.13	69.6911
1459.26	67.1004
1462.4	64.4226
1465.54	60.6973
1468.67	56.1966
1471.8	52.4335
1474.93	45.9624
1478.06	40.5476
1481.19	35.3939
1484.31	30.607
1487.44	25.8919
1490.56	21.9601
1493.69	17.5585
1496.81	15.8241
1499.93	14.4721
1503.05	13.5728
1506.17	12.4988
1509.28	13.8856
1512.4	14.3298
1515.52	14.8634
1518.63	17.0704
1521.74	19.6944
1524.85	23.1353
1527.96	25.5382
1531.07	26.973
1534.18	26.6479
1537.29	28.6306
1540.39	31.6337
1543.5	33.4108
1546.6	36.2633
1549.7	39.0153
1552.8	41.7036
1555.9	44.4086
1559	46.9028
1562.1	49.1707
1565.19	50.2658
1568.29	51.7929
1571.38	54.0786
1574.47	56.2053
1577.56	58.7319
1580.66	60.0868
1583.74	62.2207
1586.83	64.143
1589.92	65.3594
1593.01	66.7533
1596.09	68.7429
1599.17	68.0811
1602.25	68.1346
1605.34	66.2786
1608.41	64.8003
1611.49	63.6916
1614.57	64.2881
1617.65	64.4368
1620.72	65.5783
1623.79	66.0772
1626.87	66.4025
1629.94	66.9114
1633.01	68.1395
1636.08	68.9794
1639.15	69.6713
1642.21	71.858
1645.28	73.6276
1648.34	73.7712
1651.41	76.5033
1654.47	77.3054
1657.53	78.0936
1660.59	78.1402
1663.65	78.7101
1666.71	77.2453
1669.76	76.0138
1672.82	72.8796
1675.87	68.9092
1678.93	65.314
1681.98	59.4982
1685.03	54.6449
1688.08	50.4373
1691.13	45.4926
1694.17	40.5264
1697.22	35.5539
1700.27	31.6206
1703.31	28.2347
1706.35	24.4744
1709.39	20.5956
1712.43	17.2515
1715.47	14.5481
1718.51	12.2094
1721.55	9.95414
1724.58	9.62924
1727.62	8.06564
1730.65	7.52599
1733.68	6.9728
1736.72	6.7264
1739.74	6.49114
1742.77	6.45243
1745.8	5.65204
1748.83	5.49389
1751.85	5.04909
1754.88	4.25795
1757.9	3.73863
1760.92	4.50835
1763.95	3.38127
1766.96	3.53127
1769.98	3.50659
1773	4.21413
1776.02	4.60399
1779.03	2.9886
1782.05	2.4982
1785.06	2.64299
1788.07	2.47952
1791.08	2.22749
1794.09	2.21554
1797.1	2.94041
1800.11	2.31623
1803.12	2.5712
1806.12	3.09629
1809.12	3.03663
1812.13	3.05581
1815.13	3.01022
1818.13	1.72593
1821.13	1.37953
1824.13	1.03418
1827.13	1.01343
1830.12	1.60823
1833.12	1.41751
1836.11	1.29258
1839.1	0.63298
1842.09	1.21125
1845.09	2.47807
1848.08	2.36919
1851.06	2.12617
1854.05	1.89265
1857.04	2.33853
1860.02	1.87194
1863.01	2.05209
1865.99	1.79038
1868.97	2.14355
1871.95	2.28481
1874.93	2.72679
1877.91	3.56621
1880.89	3.0027
1882.46	2.50158
1885.45	2.59436
1888.43	1.64499
1891.42	1.56413
1894.41	1.80191
1897.39	1.96846
1900.37	2.59423
1903.36	2.69601
1906.34	3.5001
1909.32	4.34107
1912.29	4.78448
1915.27	4.70174
1918.25	5.90674
1921.23	5.13494
1924.2	4.81935
1927.17	4.89534
1930.15	4.70168
1933.12	5.08546
1936.09	5.61413
1939.06	7.0579
1942.02	7.76594
1944.99	8.59011
1947.96	9.6726
1950.92	10.058
1953.88	9.85868
1956.85	11.5927
1959.81	11.5804
1962.77	11.8589
1965.73	13.0937
1968.69	14.1936
1971.64	14.2805
1974.6	15.3893
1977.55	15.4639
1980.51	15.9298
1983.46	14.9185
1986.41	14.747
1989.36	14.7042
1992.31	13.9003
1995.26	12.8383
1998.21	12.1376
2001.15	11.8676
2004.1	10.8928
2007.04	10.4966
2009.99	11.2342
2012.93	10.6643
2015.87	10.6173
2018.81	10.1276
2021.75	9.42092
2024.68	9.77265
2027.62	10.4002
2030.56	10.8186
2033.49	12.3381
2036.42	12.7496
2039.36	12.7868
2042.29	13.8645
2045.22	14.136
2048.14	15.5587
2051.07	15.3967
2054	15.369
2056.93	15.9407
2059.85	16.0618
2062.77	15.9261
2065.7	15.9046
2068.62	15.4717
2071.54	15.4755
2074.46	14.6094
2077.38	14.6778
2080.29	15.5165
2083.21	15.4973
2086.12	15.1648
2089.04	15.886
2091.95	16.1964
2094.86	18.1257
2097.77	19.1951
2100.68	20.5923
2103.59	22.4865
2106.5	23.0054
2109.41	23.8415
2112.31	26.1314
2115.21	27.6213
2118.12	30.1428
2121.02	31.561
2123.92	33.9691
2126.82	35.8415
2129.72	37.4264
2132.62	38.5666
2135.51	41.2664
2138.41	43.332
2141.31	44.3357
2144.2	46.0503
2147.09	47.4212
2149.98	47.8041
2152.87	48.4793
2155.76	49.2348
2158.65	49.5
2161.54	51.2724
2164.43	51.4277
2167.31	52.5135
2170.2	51.923
2173.08	51.7082
2175.96	51.4953
2178.84	50.8359
2181.72	50.0874
2184.6	50.4625
2187.48	49.9323
2190.36	49.7131
2193.23	47.7032
2196.11	46.8103
2198.98	45.3099
2201.85	44.1791
2204.72	43.3814
2207.59	42.9016
2210.46	40.6693
2213.33	38.6495
2216.2	36.6345
2219.07	34.1952
2221.93	31.5806
2224.8	30.6737
2227.66	29.6794
2230.52	27.9992
2233.39	27.1684
2236.25	25.0416
2239.1	22.8338
2241.96	21.6032
2244.82	20.5562
2247.68	19.7213
2250.53	19.1413
2253.38	19.0234
2256.24	18.8264
2259.09	18.9137
2261.94	18.0078
2264.79	18.3616
2267.64	18.6812
2270.49	19.2331
2273.33	18.8793
2276.18	18.5466
2279.02	18.261
2281.87	18.6188
2284.71	18.4561
2287.55	18.0175
2290.39	17.0898
2293.23	15.8287
2296.07	15.6318
2298.91	15.293
2301.74	14.8174
2304.58	14.5124
2307.41	13.8306
2310.25	13.6507
2313.08	14.3508
2315.91	14.2361
2318.74	14.3911
2321.57	14.013
2324.4	14.5008
2327.23	14.5237
2330.05	15.9049
2332.88	15.7117
2335.7	15.6852
2338.52	15.8225
2341.35	15.0968
2344.17	14.1249
2346.99	14.0206
2349.81	13.44
2352.62	11.688
2355.44	9.97116
2358.26	7.46474
2361.07	5.91816
2363.89	5.33112
2366.7	5.29179
2369.51	4.39275
2372.32	4.3691
2375.13	4.92255
2377.94	4.74427
2380.75	4.22313
2383.56	4.70393
2386.36	4.6908
2389.17	4.8514
2391.97	4.84701
2394.77	5.9771
2397.58	6.86679
2400.38	8.06414
2403.18	9.26563
2405.97	10.4032
2408.77	10.2025
2411.57	9.48537
2414.37	8.36624
2417.16	7.54603
2419.95	7.00476
2422.75	5.67157
2425.54	4.89629
2428.33	4.45679
2431.12	3.93393
2433.91	3.02468
2436.7	2.08617
2439.48	2.04585
2442.27	1.85253
2445.05	0.789047
2447.84	0.503284
2450.62	0.43983
2453.4	0.804716
2456.18	1.12541
2458.96	0.61656
2461.74	1.53825
2464.52	2.71959
2467.29	4.07372
2470.07	3.96392
2472.85	4.0523
2475.62	3.51393
2478.39	2.69005
2481.16	2.21858
2483.93	3.22064
2486.7	3.32642
2489.47	3.33896
2492.24	3.90301
2495.01	4.55388
2497.77	4.60865
2500.54	4.03978
2503.3	4.08416
2506.06	3.28659
2508.83	3.00878
2511.59	2.60647
2514.35	2.79618
2517.11	3.28075
2519.86	3.8633
2522.62	4.06765
2525.38	3.7791
2528.13	3.84552
2530.89	3.2847
2533.64	2.61141
2536.39	2.52695
2539.14	2.58563
2541.89	2.42396
2544.64	2.59599
2547.39	1.97105
2550.14	3.20634
2552.88	3.75326
2555.63	3.63589
2558.37	5.09149
2561.11	5.20841
2563.86	5.09769
2566.6	5.08648
2569.34	4.76032
2572.08	4.94195
2574.82	4.16663
2577.55	4.71218
2580.29	4.96579
2583.02	4.72463
2585.76	3.5957
2588.49	3.72059
2591.22	3.52348
2593.96	2.74809
2596.69	1.64825
2599.42	1.98874
2602.14	2.09712
2604.87	2.28326
2607.6	1.5334
2610.32	1.08658
2613.05	1.05546
2615.77	1.30162
2618.49	1.46834
2621.22	1.67823
2623.94	1.9011
2626.66	3.52244
2629.37	3.16108
2632.09	3.31046
2634.81	3.41664
2637.53	3.27986
2640.24	3.50236
2642.96	3.37144
2645.67	2.79392
2648.38	2.14729
2651.09	1.82485
2653.8	1.75611
2656.51	1.96025
2659.22	1.77265
2661.93	1.99279
2664.63	2.77742
2667.34	2.70083
2670.04	2.31804
2672.75	2.2344
2675.45	1.13009
2678.15	1.95076
2680.85	2.19775
2683.55	2.63663
2686.25	2.43153
2688.94	3.42347
2691.64	3.16612
2694.34	3.50539
2697.03	3.14956
2699.73	3.49284
2702.42	3.65478
2705.11	4.60665
2707.8	5.30098
2710.49	5.50833
2713.18	6.19672
2715.87	7.20792
2718.55	7.36968
2721.24	7.79514
2723.93	8.42032
2726.61	8.65483
2729.29	9.43113
2731.98	9.28151
2734.66	8.58794
2737.34	8.03557
2740.02	7.10413
2742.7	6.20705
2745.37	5.73063
2748.05	4.65282
2750.72	3.91658
2753.4	3.10759
2756.07	1.85508
2758.75	1.001
2761.42	0.910416
2764.09	-0.220746
2766.76	-0.592448
2769.43	-0.0810455
2772.1	0.657162
2774.76	0.475941
2777.43	0.787286
2780.1	1.59802
2782.76	2.17311
2785.42	1.74415
2788.09	1.96901
2790.75	2.08577
2793.41	1.93301
2796.07	1.69843
2798.73	1.12569
2801.39	0.458154
2804.04	0.249449
2806.7	0.330459
2809.35	-0.187116
2812.01	-0.235082
2814.66	-0.245848
2817.31	0.491914
2819.96	2.36443
2822.61	5.88403
2825.26	9.72568
2827.91	12.7353
2830.56	17.4243
2833.21	23.2422
2835.85	29.0161
2838.5	34.6406
2841.14	41.1092
2843.78	48.8819
2846.42	56.6464
2849.06	65.3246
2851.71	74.5766
2854.34	83.4541
2856.98	92.4847
2859.62	99.805
2862.26	107.632
2864.89	114.589
2867.53	120.295
2870.16	125.606
2872.79	130.341
2875.42	134.545
2878.05	138.456
2880.68	143.554
2883.31	147.951
2885.94	150.99
2888.57	155.35
2891.19	159.002
2893.82	161.912
2896.44	166.163
2899.07	171.267
2901.69	177.89
2904.31	185.71
2906.93	195.025
2909.55	205.056
2912.17	215.05
2914.79	225.393
2917.41	234.655
2920.02	241.91
2922.64	248.5
2925.25	252.735
2927.86	255.798
2930.48	256.097
2933.09	255.115
2935.7	252.6
2938.31	248.575
2940.92	243.257
2943.53	235.995
2946.13	227.948
2948.74	218.215
2951.34	208.9
2953.95	199.196
2956.55	188.35
2959.15	178.577
2961.75	170.146
2964.35	162.728
2966.95	155.846
2969.55	147.439
2972.15	139.378
2974.75	131.511
2977.34	123.357
2979.94	116.063
2982.53	107.957
2985.13	99.7351
2987.72	91.1753
2990.31	82.223
2992.9	74.9015
2995.49	66.0724
2998.08	58.7173
3000.67	51.6952
3003.25	45.8018
3005.84	39.9681
3008.42	34.3369
3011.01	31.2843
3013.59	27.5245
3016.17	24.719
3018.76	21.4862
3021.34	19.5394
3023.92	17.7435
3026.49	16.3695
3029.07	15.2509
3031.65	14.8218
3034.23	14.873
3036.8	15.211
3039.38	15.7659
3041.95	17.3665
3044.52	18.0051
3047.09	19.5486
3049.66	20.3152
3052.23	20.3659
3054.8	21.2553
3057.37	21.5748
3059.94	21.0551
3062.5	20.8776
3065.07	20.4597
3067.63	19.1889
3070.2	17.8382
3072.76	16.6324
3075.32	14.9029
3077.88	12.6292
3080.44	10.3874
3083	8.05575
3085.56	5.99766
3088.12	4.05834
3090.67	3.31332
3093.23	2.90277
3095.78	1.99303
3098.34	2.08447
3100.89	2.03208
3103.44	2.15867
3105.99	2.4504
3108.54	3.55033
3111.09	4.26375
3113.64	4.70388
3116.19	5.655
3118.74	6.29293
3121.28	6.95745
3123.83	7.84971
3126.37	8.91879
3128.91	8.7337
3131.46	9.35956
3134	10.0593
3136.54	10.7709
3139.08	12.2654
3141.62	13.3317
3144.16	14.67
3146.69	16.2896
3149.23	18.8489