File: data/Raman/poly_smoothed/Thy_20_09_18_1x_45s_532 nm_x100_100%_600 gr_mm_01.txt
#Acq. time (s)=	45
#Accumulations=	2
#Range (cm-¹)=	200...3150
#Windows=	2
#Auto scanning=	Off
#Autofocus=	Off
#Macrospot=	Off
#AutoExposure=	Off
#Spike filter=	Multiple accum.
#Delay time (s)=	0
#Binning=	1
#Readout mode=	Signal
#DeNoise=	Off
#ICS correction=	On
#Dark correction=	Off
#Inst. Process=	Off
#Detector Gain=	Best Dynamic Range
#Detector ADC=	20 kHz
#Detector temperature (°C)=	-69.85
#Instrument=	LabRAM HR Evol
#Detector=	Synapse
#Objective=	x100
#Grating=	600 gr/mm
#ND Filter=	100%
#Laser (nm)=	532
#Hole=	100.021
#Range=	Auto
#Laser Pol.=	No
#Raman. Pol.=	No
#Laser Pol. (°)=	-0.0007625
#Raman Pol. (°)=	89.9995
#Collection=	Microscope
#StageXY=	Marzhauser
#StageZ=	Marzhauser
#X (µm)=	-5890.3
#Y (µm)=	2884.7
#Z (µm)=	-223.4
#Full time(mm:ss)=	3:18
#Project=
#Sample=
#Site=
#Title=	Thy_20_09_18_2x_45s_532 nm_x100_100%_600 gr_mm
#Remark=
#Date=	29.06.2022 11:57
#Acquired=	29.06.2022 11:57:16
#Base:Fit=	10.08.2022 09:52:02
#Base:Fit=	10.08.2022 09:52:12
#Base:Sub=	10.08.2022 09:54:21
#Filter:Polynom=	16.08.2022 10:24:04
#AxisType[0]=Intens
#AxisUnit[0]=Cnt
#AxisType[1]=Spectr
#AxisUnit[1]=1/cm
200.523	-6.70756
204.154	1.03431
207.781	5.04178
211.409	7.46309
215.034	9.49551
218.659	10.7334
222.281	9.92036
225.903	10.4426
229.522	11.295
233.14	11.7331
236.756	11.729
240.373	13.2752
243.986	14.1643
247.598	15.0521
251.208	14.4417
254.818	15.1519
258.427	14.1379
262.034	14.0241
265.638	14.8069
269.242	13.4525
272.844	13.0081
276.445	13.6436
280.044	13.7205
283.642	12.73
287.238	12.3841
290.833	11.2497
294.425	9.15644
298.017	7.9934
301.608	6.29095
305.198	5.8898
308.786	5.20191
312.371	4.58625
315.956	5.23887
319.54	5.08682
323.122	6.23048
326.701	7.10921
330.281	8.80922
333.857	9.78544
337.434	9.19918
341.008	9.08385
344.582	8.74014
348.153	8.06231
351.724	7.891
355.292	7.51776
358.861	5.98392
362.426	6.82351
365.99	4.60049
369.555	4.02783
373.116	5.32019
376.676	3.27182
380.236	2.45099
383.793	2.22113
387.349	3.22576
390.903	3.20268
394.456	4.55377
398.007	3.61653
401.56	3.16215
405.108	3.3262
408.656	3.84821
412.202	4.26318
415.746	4.87918
419.29	5.6551
422.831	5.47691
426.37	6.367
429.909	5.54365
433.447	4.48415
436.983	4.75919
440.519	5.65754
444.052	5.09943
447.583	6.17388
451.114	5.29462
454.643	6.75126
458.169	6.90732
461.696	7.78925
465.222	8.74063
468.744	8.32111
472.267	9.04991
475.787	7.71501
479.307	8.33625
482.823	9.22331
486.341	8.40969
489.855	7.93067
493.37	9.71676
496.881	9.42537
500.391	10.9228
503.902	11.9908
507.409	12.7781
510.915	14.7644
514.42	13.4169
517.925	13.1805
521.427	14.7802
524.928	15.8054
528.427	15.1301
531.925	14.8043
535.422	13.2561
538.917	11.5673
542.411	11.6702
545.903	11.4039
549.395	10.6484
552.884	10.1213
556.373	8.54197
559.86	7.65865
563.346	7.0496
566.831	6.1134
570.314	4.72129
573.794	3.29594
577.274	3.64342
580.754	3.93415
584.23	3.92314
587.706	3.31609
591.181	3.89596
594.653	4.23291
598.126	4.60852
601.595	4.17702
605.065	6.29844
608.532	7.46817
611.999	8.31658
615.463	10.4857
618.928	10.5428
622.389	11.6723
625.851	13.8658
629.31	15.4857
632.767	16.4157
636.223	17.453
639.68	17.7372
643.134	17.5688
646.586	18.007
650.037	18.3486
653.486	18.4136
656.936	18.5752
660.383	19.1737
663.829	19.9247
667.273	19.1279
670.716	18.3048
674.158	17.4261
677.598	18.0613
681.035	18.8655
684.473	20.2744
687.909	21.8246
691.344	22.7624
694.778	23.4042
698.211	24.8365
701.64	26.1294
705.07	25.9108
708.498	26.9346
711.924	27.7834
715.35	29.1242
718.774	30.4082
722.196	32.5322
725.618	33.4938
729.037	35.7077
732.456	37.7878
735.873	38.653
739.289	42.1533
742.703	43.824
746.116	45.2
749.529	47.1731
752.938	48.2192
756.347	50.7178
759.756	50.9109
763.162	53.5233
766.567	54.0172
769.97	54.5419
773.372	54.0626
776.773	54.6583
780.174	56.3482
783.573	58.0326
786.97	59.2368
790.365	60.323
793.76	62.4872
797.153	63.377
800.543	63.9107
803.933	65.4497
807.322	67.2093
810.71	68.5153
814.097	69.2829
817.483	69.9432
820.865	70.9577
824.248	70.907
827.629	69.6184
831.008	69.7443
834.387	68.9622
837.765	68.1749
841.139	66.1873
844.514	63.482
847.886	60.6447
851.259	56.8874
854.629	52.5623
857.997	50.2063
861.366	48.1115
864.732	47.6321
868.098	45.4972
871.461	44.3159
874.823	43.0405
878.184	42.2373
881.545	41.1932
884.903	41.3592
888.26	42.2684
891.616	41.4158
894.97	39.1084
898.323	38.5463
901.675	38.927
905.026	38.4068
908.375	37.2372
911.723	35.5906
915.07	35.8462
918.415	35.7069
921.76	36.7969
925.103	35.1292
928.443	35.0972
931.783	35.8296
935.123	34.2147
938.461	35.3956
941.796	35.3161
945.131	35.5012
948.465	36.138
951.797	36.223
955.128	36.331
958.457	35.6112
961.786	34.5136
965.113	34.0883
968.44	33.1734
971.763	32.7981
975.086	30.6348
978.409	31.1751
981.729	29.617
985.048	28.295
988.367	25.8023
991.683	23.6429
994.998	20.9737
998.312	20.251
1001.62	20.1278
1004.94	19.1831
1008.25	18.0827
1011.56	18.1783
1014.86	17.6056
1018.17	17.1389
1021.48	18.4828
1024.78	17.1154
1028.08	17.1762
1031.38	15.9525
1034.68	13.4269
1037.98	13.3388
1041.28	12.921
1044.57	11.9021
1047.87	11.4744
1051.16	9.94876
1054.45	11.7849
1057.75	11.2943
1061.04	10.2999
1064.32	9.32563
1067.61	7.6726
1070.9	4.67385
1074.18	2.77075
1077.47	3.00078
1080.75	4.21463
1084.03	4.47865
1087.31	5.56731
1090.59	6.07608
1093.86	7.29993
1097.14	8.06385
1100.41	8.88569
1103.69	8.59556
1106.96	8.86202
1110.23	9.31713
1113.5	9.03774
1116.77	10.0064
1120.03	9.94129
1123.3	8.48213
1126.56	6.767
1129.83	7.22201
1133.09	8.58749
1136.35	8.12748
1139.61	7.3205
1142.86	6.03019
1146.12	5.46393
1149.38	4.55564
1152.63	4.60552
1155.88	5.2976
1159.14	5.5453
1162.39	5.71229
1165.63	6.16086
1168.88	5.31328
1172.13	6.42672
1175.38	7.55751
1178.62	9.35176
1181.86	9.31882
1185.1	9.69097
1188.34	10.6386
1191.58	11.3102
1194.82	11.0258
1198.06	13.3613
1201.29	14.3781
1204.53	14.8046
1207.76	16.9517
1210.99	20.5953
1214.22	21.8103
1217.45	22.5901
1220.68	23.8574
1223.91	25.0407
1227.13	26.7751
1230.36	30.0569
1233.58	31.3368
1236.8	32.5593
1240.02	34.4659
1243.24	35.7914
1246.46	36.0329
1249.67	38.031
1252.89	38.8033
1256.1	40.1844
1259.32	40.0853
1262.53	39.4271
1265.74	40.2537
1268.95	41.7353
1272.15	43.2198
1275.36	45.4088
1278.57	46.7346
1281.77	48.9951
1284.97	52.6627
1288.18	57.0072
1291.38	59.1746
1294.58	59.9705
1297.78	61.9236
1300.97	63.7511
1304.17	65.2698
1307.36	68.7903
1310.55	69.4642
1313.75	68.8635
1316.94	70.4482
1320.13	69.582
1323.32	69.1625
1326.5	68.5078
1329.69	68.3187
1332.87	66.1887
1336.06	66.1604
1339.24	64.1743
1342.42	63.0294
1345.6	61.0712
1348.78	59.713
1351.96	57.8064
1355.13	56.6221
1358.31	55.9674
1361.48	54.8421
1364.65	53.8851
1367.82	52.9664
1370.99	50.4823
1374.16	48.908
1377.33	47.0046
1380.5	45.5781
1383.66	44.4021
1386.83	43.6886
1389.99	42.0734
1393.15	41.9493
1396.31	41.6707
1399.47	41.0999
1402.63	40.4381
1405.78	38.9706
1408.94	40.1767
1412.1	41.8305
1415.25	43.985
1418.4	44.6389
1421.55	48.1035
1424.7	50.5804
1427.85	54.4946
1431	58.6616
1434.14	63.6042
1437.29	68.0535
1440.43	71.5163
1443.57	73.4941
1446.71	74.486
1449.85	74.9652
1452.99	73.9519
1456.13	73.1573
1459.26	70.952
1462.4	68.3826
1465.54	65.4016
1468.67	61.0124
1471.8	56.7127
1474.93	50.6704
1478.06	45.736
1481.19	39.3258
1484.31	35.9448
1487.44	32.2481
1490.56	29.9362
1493.69	27.6255
1496.81	25.856
1499.93	24.8424
1503.05	25.5659
1506.17	26.5355
1509.28	26.5893
1512.4	26.4705
1515.52	27.1703
1518.63	28.1452
1521.74	29.4587
1524.85	31.0499
1527.96	33.1192
1531.07	35.4167
1534.18	36.5008
1537.29	37.6275
1540.39	40.9307
1543.5	43.3144
1546.6	46.0849
1549.7	49.8018
1552.8	52.4026
1555.9	55.0586
1559	58.8177
1562.1	61.4457
1565.19	64.1344
1568.29	68.3447
1571.38	70.6445
1574.47	72.9724
1577.56	75.2373
1580.66	77.5458
1583.74	78.9775
1586.83	79.8623
1589.92	81.9781
1593.01	82.0605
1596.09	81.2737
1599.17	79.9888
1602.25	78.602
1605.34	76.2603
1608.41	72.9315
1611.49	69.699
1614.57	69.2946
1617.65	66.8826
1620.72	64.9743
1623.79	62.9597
1626.87	61.5838
1629.94	59.2622
1633.01	58.0529
1636.08	56.8445
1639.15	56.9254
1642.21	58.2913
1645.28	59.0585
1648.34	59.5944
1651.41	59.9399
1654.47	59.9532
1657.53	60.8527
1660.59	59.311
1663.65	57.9289
1666.71	54.6075
1669.76	52.7576
1672.82	50.0509
1675.87	46.7422
1678.93	43.4303
1681.98	40.2239
1685.03	36.4801
1688.08	34.3694
1691.13	30.6579
1694.17	26.4454
1697.22	23.9575
1700.27	21.1544
1703.31	19.1147
1706.35	17.9444
1709.39	15.9646
1712.43	14.3674
1715.47	13.755
1718.51	12.5519
1721.55	11.9914
1724.58	10.9946
1727.62	10.1389
1730.65	8.59719
1733.68	7.33921
1736.72	6.2932
1739.74	6.11056
1742.77	5.46075
1745.8	5.933
1748.83	5.12908
1751.85	4.49267
1754.88	4.02397
1757.9	3.78652
1760.92	3.18065
1763.95	3.07959
1766.96	2.87696
1769.98	3.72248
1773	4.36764
1776.02	4.66494
1779.03	4.47891
1782.05	4.28148
1785.06	2.54987
1788.07	2.29654
1791.08	1.98514
1794.09	2.71086
1797.1	2.96425
1800.11	2.77434
1803.12	2.95994
1806.12	2.45206
1809.12	2.67184
1812.13	3.24837
1815.13	3.35621
1818.13	3.19836
1821.13	2.13614
1824.13	1.46395
1827.13	1.25404
1830.12	1.91422
1833.12	1.45532
1836.11	2.29813
1839.1	3.20956
1842.09	3.17448
1845.09	3.13532
1848.08	2.6326
1851.06	2.79953
1854.05	2.64205
1857.04	3.03065
1860.02	2.82909
1863.01	3.22421
1865.99	3.77594
1868.97	3.99115
1871.95	4.31426
1874.93	4.6033
1877.91	4.93439
1880.89	4.2802
1882.46	4.16385
1885.45	3.45461
1888.43	2.4515
1891.42	1.79553
1894.41	1.69305
1897.39	2.47228
1900.37	2.48176
1903.36	2.72655
1906.34	3.38191
1909.32	2.84369
1912.29	2.79265
1915.27	2.88372
1918.25	2.837
1921.23	4.88867
1924.2	5.82245
1927.17	6.63689
1930.15	6.8003
1933.12	7.50047
1936.09	8.07667
1939.06	8.68997
1942.02	8.89378
1944.99	9.51465
1947.96	9.65235
1950.92	9.67464
1953.88	9.13933
1956.85	7.98261
1959.81	7.98495
1962.77	7.49332
1965.73	6.25132
1968.69	6.33845
1971.64	5.94771
1974.6	5.35488
1977.55	4.98127
1980.51	4.36691
1983.46	3.76027
1986.41	3.72928
1989.36	3.10859
1992.31	3.69371
1995.26	4.12347
1998.21	4.4267
2001.15	4.06649
2004.1	2.96567
2007.04	2.5234
2009.99	2.60188
2012.93	2.94747
2015.87	2.26075
2018.81	2.6654
2021.75	3.13397
2024.68	2.84735
2027.62	2.11406
2030.56	2.07094
2033.49	2.32294
2036.42	1.25288
2039.36	1.87111
2042.29	3.53702
2045.22	3.88712
2048.14	3.44686
2051.07	3.84805
2054	3.54027
2056.93	3.8918
2059.85	3.47111
2062.77	4.7337
2065.7	5.44271
2068.62	6.21985
2071.54	6.92004
2074.46	5.65879
2077.38	5.32364
2080.29	6.65284
2083.21	7.96069
2086.12	7.85126
2089.04	8.86412
2091.95	9.23837
2094.86	9.00791
2097.77	9.0806
2100.68	9.71349
2103.59	10.1099
2106.5	10.6683
2109.41	11.0334
2112.31	11.7442
2115.21	10.5905
2118.12	10.9895
2121.02	11.6386
2123.92	12.4546
2126.82	13.4933
2129.72	13.8305
2132.62	15.3452
2135.51	16.1219
2138.41	18.247
2141.31	18.5431
2144.2	19.1335
2147.09	20.3574
2149.98	22.2167
2152.87	24.1734
2155.76	25.9822
2158.65	26.6821
2161.54	27.8098
2164.43	29.548
2167.31	30.9602
2170.2	32.0991
2173.08	31.9892
2175.96	32.533
2178.84	32.0523
2181.72	31.2404
2184.6	29.8702
2187.48	29.6264
2190.36	29.0129
2193.23	27.8801
2196.11	26.9379
2198.98	25.4848
2201.85	23.93
2204.72	22.4421
2207.59	21.2898
2210.46	19.6781
2213.33	16.6828
2216.2	15.1898
2219.07	14.1948
2221.93	12.867
2224.8	11.9351
2227.66	11.3673
2230.52	9.99744
2233.39	10.1609
2236.25	8.82302
2239.1	7.98537
2241.96	6.93029
2244.82	6.29363
2247.68	6.45155
2250.53	4.79899
2253.38	4.28972
2256.24	5.05433
2259.09	5.08307
2261.94	5.62788
2264.79	5.25352
2267.64	5.60507
2270.49	5.98033
2273.33	6.04899
2276.18	5.61213
2279.02	5.66799
2281.87	4.56344
2284.71	4.33329
2287.55	4.64979
2290.39	4.36357
2293.23	3.05454
2296.07	3.38895
2298.91	4.3585
2301.74	4.08369
2304.58	4.5971
2307.41	5.94184
2310.25	5.96095
2313.08	6.22169
2315.91	6.60313
2318.74	6.42379
2321.57	6.66599
2324.4	6.91769
2327.23	6.98808
2330.05	6.018
2332.88	6.23813
2335.7	6.15144
2338.52	6.56965
2341.35	5.80981
2344.17	5.11518
2346.99	4.54492
2349.81	3.33738
2352.62	2.44917
2355.44	2.09675
2358.26	0.430027
2361.07	-0.461542
2363.89	0.529015
2366.7	1.97455
2369.51	1.73287
2372.32	1.2764
2375.13	1.20826
2377.94	1.16087
2380.75	0.983335
2383.56	1.19691
2386.36	1.48365
2389.17	1.65824
2391.97	0.94108
2394.77	0.937242
2397.58	0.677258
2400.38	1.65069
2403.18	1.94883
2405.97	2.76211
2408.77	2.96472
2411.57	4.1239
2414.37	5.25973
2417.16	5.85538
2419.95	6.56228
2422.75	6.43317
2425.54	6.57358
2428.33	6.434
2431.12	7.22183
2433.91	7.20246
2436.7	6.86129
2439.48	5.99305
2442.27	6.03649
2445.05	5.74248
2447.84	6.22086
2450.62	6.22397
2453.4	5.96263
2456.18	5.25812
2458.96	4.35356
2461.74	3.61653
2464.52	3.53233
2467.29	3.41247
2470.07	2.8867
2472.85	2.73428
2475.62	2.31191
2478.39	2.71223
2481.16	2.98265
2483.93	2.92175
2486.7	2.9274
2489.47	2.51942
2492.24	2.8393
2495.01	2.18072
2497.77	2.09782
2500.54	2.61975
2503.3	3.15748
2506.06	3.96598
2508.83	4.53587
2511.59	4.50641
2514.35	4.93984
2517.11	5.54835
2519.86	5.40713
2522.62	5.26521
2525.38	4.53366
2528.13	4.31163
2530.89	3.96988
2533.64	3.76732
2536.39	2.80197
2539.14	2.88504
2541.89	2.90465
2544.64	2.87726
2547.39	3.50237
2550.14	4.29798
2552.88	3.9754
2555.63	4.20382
2558.37	3.69362
2561.11	3.85684
2563.86	4.04237
2566.6	3.99881
2569.34	4.77336
2572.08	4.98724
2574.82	4.50289
2577.55	4.55224
2580.29	4.87228
2583.02	5.14074
2585.76	5.11141
2588.49	4.74976
2591.22	4.71979
2593.96	5.59444
2596.69	5.62022
2599.42	5.78147
2602.14	6.79332
2604.87	6.76389
2607.6	7.84276
2610.32	7.84529
2613.05	7.73319
2615.77	8.04753
2618.49	7.71354
2621.22	6.32945
2623.94	6.18699
2626.66	5.41411
2629.37	5.96827
2632.09	5.79185
2634.81	5.17473
2637.53	5.90985
2640.24	5.61799
2642.96	5.31329
2645.67	4.88317
2648.38	4.91895
2651.09	3.98968
2653.8	4.47889
2656.51	4.36186
2659.22	5.08674
2661.93	4.9848
2664.63	4.98395
2667.34	4.95311
2670.04	5.01154
2672.75	5.67669
2675.45	5.85219
2678.15	5.46934
2680.85	5.89396
2683.55	6.58259
2686.25	6.94201
2688.94	6.61056
2691.64	7.44976
2694.34	8.12331
2697.03	9.24494
2699.73	10.1135
2702.42	10.3248
2705.11	10.8995
2707.8	11.8261
2710.49	11.7772
2713.18	13.3517
2715.87	13.0138
2718.55	13.3786
2721.24	13.1708
2723.93	13.2705
2726.61	12.7037
2729.29	12.8108
2731.98	12.5941
2734.66	12.5444
2737.34	12.7451
2740.02	12.0467
2742.7	11.1764
2745.37	10.0864
2748.05	9.594
2750.72	9.15543
2753.4	8.33378
2756.07	8.19506
2758.75	7.90545
2761.42	7.89526
2764.09	8.43084
2766.76	9.12684
2769.43	7.91431
2772.1	8.29711
2774.76	8.93352
2777.43	8.69206
2780.1	7.46329
2782.76	6.16728
2785.42	6.11632
2788.09	5.07833
2790.75	4.67364
2793.41	4.65558
2796.07	4.09666
2798.73	3.96242
2801.39	3.32718
2804.04	2.56862
2806.7	1.71098
2809.35	0.319597
2812.01	-0.0320775
2814.66	0.138001
2817.31	1.45168
2819.96	1.87175
2822.61	4.20213
2825.26	6.94405
2827.91	10.0047
2830.56	13.5016
2833.21	16.7635
2835.85	21.0372
2838.5	25.2534
2841.14	30.041
2843.78	33.8798
2846.42	39.3618
2849.06	44.6666
2851.71	51.0631
2854.34	56.2856
2856.98	62.8416
2859.62	69.0865
2862.26	74.2017
2864.89	78.7387
2867.53	82.7232
2870.16	86.8812
2872.79	90.1203
2875.42	93.2782
2878.05	97.2037
2880.68	100.294
2883.31	104.331
2885.94	107.427
2888.57	111.343
2891.19	113.903
2893.82	117.261
2896.44	121.292
2899.07	124.793
2901.69	129.391
2904.31	135.537
2906.93	141.711
2909.55	148.85
2912.17	155.486
2914.79	161.893
2917.41	167.788
2920.02	173.118
2922.64	177.114
2925.25	179.612
2927.86	179.936
2930.48	179.807
2933.09	179.156
2935.7	178.25
2938.31	175.905
2940.92	172.586
2943.53	168.386
2946.13	163.249
2948.74	157.084
2951.34	150.505
2953.95	143.801
2956.55	137.248
2959.15	131.011
2961.75	125.697
2964.35	120.588
2966.95	115.534
2969.55	109.346
2972.15	103.772
2974.75	98.6304
2977.34	92.6148
2979.94	86.5816
2982.53	80.1487
2985.13	72.8072
2987.72	65.3625
2990.31	58.5535
2992.9	51.5917
2995.49	46.1734
2998.08	41.3639
3000.67	36.8522
3003.25	32.2464
3005.84	27.6674
3008.42	24.3671
3011.01	21.0163
3013.59	17.9434
3016.17	16.0324
3018.76	14.1414
3021.34	13.3585
3023.92	12.4824
3026.49	12.1554
3029.07	11.4439
3031.65	10.4544
3034.23	10.9303
3036.8	10.8584
3039.38	11.3225
3041.95	11.9466
3044.52	12.0696
3047.09	12.4686
3049.66	12.9971
3052.23	13.7177
3054.8	13.4861
3057.37	14.2336
3059.94	14.7144
3062.5	14.6876
3065.07	13.823
3067.63	12.3727
3070.2	11.2045
3072.76	10.488
3075.32	9.46067
3077.88	8.22631
3080.44	6.78866
3083	4.66086
3085.56	4.21605
3088.12	2.53944
3090.67	2.10045
3093.23	0.982253
3095.78	0.24154
3098.34	0.583238
3100.89	0.991169
3103.44	1.18623
3105.99	2.56567
3108.54	3.02147
3111.09	4.05868
3113.64	4.90737
3116.19	5.84295
3118.74	6.88186
3121.28	8.00386
3123.83	9.01193
3126.37	9.60352
3128.91	10.2955
3131.46	12.2532
3134	13.1849
3136.54	14.5104
3139.08	15.8881
3141.62	16.6599
3144.16	17.716
3146.69	19.4231
3149.23	21.9704