File: data/Raman/poly_smoothed/Thy_40_11_39_1x_45s_532 nm_x100_100%_600 gr_mm_01.txt
#Acq. time (s)=	45
#Accumulations=	2
#Range (cm-¹)=	200...3150
#Windows=	2
#Auto scanning=	Off
#Autofocus=	Off
#Macrospot=	Off
#AutoExposure=	Off
#Spike filter=	Multiple accum.
#Delay time (s)=	0
#Binning=	1
#Readout mode=	Signal
#DeNoise=	Off
#ICS correction=	On
#Dark correction=	Off
#Inst. Process=	Off
#Detector Gain=	Best Dynamic Range
#Detector ADC=	20 kHz
#Detector temperature (°C)=	-69.85
#Instrument=	LabRAM HR Evol
#Detector=	Synapse
#Objective=	x100
#Grating=	600 gr/mm
#ND Filter=	100%
#Laser (nm)=	532
#Hole=	100.021
#Range=	Auto
#Laser Pol.=	No
#Raman. Pol.=	No
#Laser Pol. (°)=	-0.0007625
#Raman Pol. (°)=	89.9995
#Collection=	Microscope
#StageXY=	Marzhauser
#StageZ=	Marzhauser
#X (µm)=	237.3
#Y (µm)=	1689
#Z (µm)=	427.75
#Full time(mm:ss)=	3:18
#Project=
#Sample=
#Site=
#Title=	Thy_40_11_39_2x_45s_532 nm_x100_100%_600 gr_mm
#Remark=
#Date=	05.07.2022 12:46
#Acquired=	05.07.2022 12:46:25
#Base:Fit=	10.08.2022 10:01:35
#Base:Sub=	10.08.2022 10:01:52
#Filter:Polynom=	16.08.2022 10:21:53
#AxisType[0]=Intens
#AxisUnit[0]=Cnt
#AxisType[1]=Spectr
#AxisUnit[1]=1/cm
200.43	4.32529
204.059	4.32327
207.688	3.38544
211.314	3.21547
214.941	3.21523
218.564	2.98074
222.186	4.07671
225.809	4.47206
229.428	4.01851
233.045	4.79598
236.663	5.23356
240.278	5.99738
243.891	5.42597
247.503	4.28677
251.116	3.615
254.725	4.90516
258.333	4.73824
261.939	5.15741
265.544	5.2525
269.148	4.80674
272.75	5.13206
276.351	5.09024
279.95	4.62407
283.548	4.08287
287.144	3.36627
290.739	3.0577
294.333	2.51521
297.925	4.91903
301.514	4.9653
305.104	7.97725
308.692	9.60626
312.279	10.0523
315.862	10.9015
319.446	12.1366
323.029	14.27
326.608	13.7732
330.188	13.5324
333.766	12.4636
337.341	12.1351
340.917	12.3974
344.489	10.3305
348.062	9.19832
351.631	9.45912
355.201	8.76319
358.768	8.3838
362.333	9.09415
365.899	7.98386
369.462	8.0446
373.023	8.0793
376.585	5.61199
380.143	6.11658
383.7	7.98595
387.256	8.61493
390.812	9.45716
394.365	8.46906
397.916	8.29679
401.467	7.10918
405.015	8.36692
408.563	7.56324
412.109	7.86703
415.654	7.86118
419.197	6.63776
422.739	5.16795
426.279	5.05011
429.819	3.98529
433.356	5.05503
436.891	5.96683
440.426	8.8487
443.96	10.086
447.492	11.025
451.021	10.7366
454.551	10.0625
458.079	11.204
461.604	11.8172
465.13	12.9905
468.654	13.4529
472.175	13.0972
475.696	12.4009
479.215	13.1568
482.733	13.7348
486.249	14.8567
489.765	15.16
493.278	16.8719
496.789	18.4368
500.301	19.1143
503.81	19.0592
507.317	19.3293
510.825	21.7841
514.33	22.1672
517.833	22.9261
521.335	23.2459
524.836	24.8454
528.335	23.7986
531.835	23.8484
535.332	23.4045
538.827	22.1531
542.321	21.6774
545.814	21.0642
549.305	19.8139
552.795	17.7717
556.282	14.7309
559.769	12.8041
563.255	10.8918
566.739	10.2716
570.223	9.26352
573.705	7.22089
577.183	5.54881
580.663	5.06347
584.141	4.19257
587.615	3.7645
591.09	3.75869
594.564	4.48668
598.035	4.16931
601.506	5.65437
604.974	6.87217
608.443	9.09157
611.908	9.68948
615.374	10.7505
618.837	11.02
622.3	10.165
625.761	11.9902
629.219	12.1081
632.677	13.9248
636.135	13.9044
639.59	13.8526
643.043	13.9515
646.495	15.2886
649.948	17.0829
653.398	18.0714
656.846	17.7333
660.293	18.6512
663.738	19.4976
667.183	20.6735
670.626	22.7986
674.067	22.2111
677.508	23.2483
680.947	25.7156
684.385	28.2822
687.821	30.3877
691.254	30.6349
694.688	32.7043
698.121	32.6231
701.552	33.7223
704.98	34.874
708.409	37.2915
711.836	40.5951
715.26	43.0863
718.685	45.4545
722.108	47.6511
725.528	49.8306
728.949	50.6365
732.367	51.1952
735.785	52.8512
739.2	53.1391
742.614	54.5207
746.028	56.9754
749.439	58.4464
752.849	60.8959
756.26	61.75
759.667	63.1978
763.073	66.2345
766.477	68.3159
769.883	69.5658
773.285	70.5285
776.686	72.8317
780.085	72.0088
783.484	73.3286
786.881	74.4054
790.276	77.489
793.671	78.5277
797.064	79.3755
800.456	82.3777
803.846	84.1954
807.234	84.223
810.622	84.5529
814.008	85.2541
817.394	85.6607
820.778	86.3029
824.159	86.6665
827.541	87.2948
830.921	87.2392
834.298	87.0801
837.676	85.7759
841.051	84.0714
844.426	82.596
847.798	79.8937
851.171	76.3354
854.54	73.081
857.911	70.1613
861.278	65.8254
864.645	61.453
868.01	58.8812
871.373	58.5086
874.735	55.3036
878.097	53.5303
881.457	53.8421
884.815	53.74
888.172	52.402
891.528	52.1982
894.882	51.9868
898.237	52.3673
901.589	54.3996
904.94	55.4689
908.289	56.7202
911.635	56.8799
914.982	57.6175
918.328	56.8792
921.672	56.6973
925.015	54.8819
928.357	54.5544
931.698	52.637
935.035	51.1609
938.373	48.5823
941.71	45.959
945.044	43.5925
948.378	42.1822
951.709	41.6402
955.041	41.835
958.372	41.7037
961.699	40.1717
965.027	40.944
968.352	40.5023
971.676	40.1021
975	40.8013
978.322	40.3086
981.642	42.4652
984.962	42.8551
988.28	43.3305
991.596	43.0347
994.911	42.7134
998.227	40.5241
1001.54	39.5708
1004.85	39.0925
1008.16	38.6947
1011.47	38.5492
1014.78	38.2814
1018.08	38.0265
1021.39	37.7569
1024.69	36.5463
1028	37.6408
1031.3	38.2332
1034.6	38.3662
1037.9	38.1855
1041.19	36.8267
1044.49	36.8883
1047.78	37.171
1051.08	36.6203
1054.37	35.4306
1057.66	35.1811
1060.95	34.0782
1064.24	31.9409
1067.53	30.6363
1070.81	30.067
1074.1	27.7497
1077.38	26.3765
1080.66	25.4871
1083.94	25.7014
1087.22	25.0027
1090.5	24.8877
1093.78	24.958
1097.05	24.7214
1100.33	23.7029
1103.6	23.1266
1106.87	22.0799
1110.14	22.3353
1113.41	21.6442
1116.68	21.4472
1119.95	20.5266
1123.21	20.7567
1126.48	20.2633
1129.74	18.7926
1133	17.2125
1136.26	15.0015
1139.52	14.2108
1142.78	13.3498
1146.04	13.334
1149.29	13.8862
1152.55	12.1721
1155.8	11.2741
1159.05	10.8102
1162.3	9.1893
1165.55	7.01853
1168.8	5.8836
1172.05	5.51322
1175.29	5.55296
1178.54	6.65344
1181.78	8.05154
1185.02	8.10537
1188.26	10.2533
1191.5	11.9075
1194.74	13.6001
1197.97	15.1857
1201.21	16.2136
1204.44	18.0122
1207.68	20.2532
1210.91	22.4066
1214.14	26.037
1217.37	30.9133
1220.59	34.3479
1223.82	37.1662
1227.05	40.9502
1230.27	43.0902
1233.49	44.7893
1236.72	47.2967
1239.94	48.729
1243.16	50.5678
1246.37	52.6503
1249.59	54.0704
1252.8	54.8696
1256.02	56.9669
1259.23	58.2542
1262.44	58.8677
1265.66	60.593
1268.86	63.2478
1272.07	64.6522
1275.28	66.8608
1278.48	68.3377
1281.69	67.7568
1284.89	69.1219
1288.09	69.719
1291.29	70.7305
1294.49	71.9808
1297.69	72.9516
1300.89	73.4381
1304.08	74.9523
1307.28	75.192
1310.47	74.7544
1313.66	76.261
1316.85	76.1427
1320.04	75.0037
1323.23	72.7299
1326.42	69.7245
1329.61	67.7943
1332.79	65.9269
1335.97	62.971
1339.16	60.6309
1342.34	60.1459
1345.52	58.4002
1348.7	55.7912
1351.87	54.6139
1355.05	51.9964
1358.22	48.8601
1361.4	46.9567
1364.57	45.641
1367.74	42.7473
1370.91	41.888
1374.08	40.0223
1377.25	39.6688
1380.41	38.9581
1383.58	37.2969
1386.74	35.3383
1389.91	35.3569
1393.07	36.1242
1396.23	34.1316
1399.39	33.4266
1402.55	32.6844
1405.7	32.7917
1408.86	33.7658
1412.01	36.1729
1415.17	37.5265
1418.32	40.7271
1421.47	43.9057
1424.62	47.5364
1427.77	52.1996
1430.91	57.3795
1434.06	61.5255
1437.2	64.9878
1440.35	67.6112
1443.49	68.1726
1446.63	70.7214
1449.77	71.1662
1452.91	70.012
1456.05	68.384
1459.18	66.7125
1462.32	64.2252
1465.45	59.4855
1468.59	56.285
1471.72	51.109
1474.85	46.7347
1477.98	41.0614
1481.1	36.8961
1484.23	33.3793
1487.36	30.7929
1490.48	25.8375
1493.61	22.2075
1496.73	20.2843
1499.85	19.8636
1502.97	18.3573
1506.09	17.3555
1509.2	16.8616
1512.32	17.2832
1515.43	17.7432
1518.55	16.9611
1521.66	18.066
1524.77	20.3337
1527.88	20.6779
1530.99	23.3095
1534.1	25.9302
1537.21	27.6319
1540.31	30.2975
1543.42	32.372
1546.52	34.9947
1549.62	38.2473
1552.72	40.1133
1555.82	42.517
1558.92	44.3694
1562.02	47.1488
1565.11	48.0389
1568.21	48.1289
1571.3	49.5024
1574.39	52.2805
1577.49	53.8019
1580.57	55.5669
1583.66	57.5693
1586.75	59.3391
1589.84	59.1216
1592.92	60.8841
1596.01	60.1405
1599.09	60.4667
1602.17	60.7969
1605.25	60.2711
1608.33	60.2368
1611.41	61.1278
1614.49	62.2339
1617.57	62.152
1620.64	62.5372
1623.72	62.9207
1626.79	64.1559
1629.86	65.4499
1632.93	67.0463
1636	68.948
1639.07	70.6846
1642.13	72.7757
1645.2	75.3406
1648.26	78.7069
1651.33	80.5362
1654.39	82.2111
1657.45	82.2885
1660.51	82.8348
1663.57	81.1534
1666.63	79.1097
1669.68	76.2778
1672.74	71.8
1675.79	67.909
1678.85	63.239
1681.9	57.6573
1684.95	52.6398
1688	47.4416
1691.05	41.3685
1694.09	36.0923
1697.14	30.994
1700.18	26.5863
1703.23	23.0017
1706.27	19.0381
1709.31	16.5089
1712.35	12.8111
1715.39	9.80023
1718.43	8.67414
1721.47	6.60526
1724.5	5.61033
1727.54	5.19392
1730.57	4.44402
1733.61	4.33592
1736.64	3.63141
1739.67	2.54316
1742.7	1.59354
1745.72	1.4672
1748.75	1.68722
1751.77	1.26977
1754.8	0.969285
1757.82	0.93531
1760.84	1.3544
1763.87	1.11539
1766.89	1.17271
1769.91	0.773664
1772.92	0.767946
1775.94	1.1136
1778.95	1.24171
1781.97	1.19441
1784.98	0.134293
1787.99	-0.5552
1791.01	0.151336
1794.01	0.214722
1797.02	0.0636694
1800.03	-0.164941
1803.04	-0.247363
1806.04	0.251406
1809.05	0.17274
1812.05	0.518205
1815.05	0.587111
1818.05	0.420644
1821.05	1.09843
1824.05	1.31654
1827.05	0.636121
1830.04	0.128316
1833.04	-0.490032
1836.03	0.175115
1839.03	0.201671
1842.02	0.319293
1845.01	1.05209
1848	1.80315
1850.99	3.13904
1853.97	4.02615
1856.96	3.64055
1859.94	4.41861
1862.93	5.05336
1865.91	4.84914
1868.89	5.55156
1871.87	5.90645
1874.85	6.06419
1877.83	6.68741
1880.81	7.47201
1882.57	7.76179
1885.56	8.52086
1888.55	7.68459
1891.54	7.40686
1894.52	6.66635
1897.51	5.71573
1900.49	4.93625
1903.47	5.57761
1906.45	6.08639
1909.43	7.02808
1912.41	6.47484
1915.39	7.57601
1918.37	8.08733
1921.34	8.46911
1924.32	8.96337
1927.29	8.07556
1930.26	7.37544
1933.23	7.26642
1936.2	7.73455
1939.17	7.79962
1942.14	8.24307
1945.11	8.09227
1948.07	8.02696
1951.04	8.7267
1954	9.64667
1956.96	9.46101
1959.93	9.04413
1962.89	8.95468
1965.85	8.48321
1968.8	9.06835
1971.76	9.04675
1974.72	9.2346
1977.67	9.27433
1980.63	8.433
1983.58	7.50841
1986.53	6.01272
1989.48	5.72537
1992.43	5.5414
1995.38	4.90987
1998.32	4.95289
2001.27	4.86736
2004.22	5.38599
2007.16	5.51864
2010.1	5.45898
2013.04	5.87931
2015.98	6.5917
2018.92	6.95104
2021.86	7.18375
2024.8	8.49285
2027.74	10.0569
2030.67	10.9391
2033.61	12.543
2036.54	13.0472
2039.47	12.7567
2042.4	13.3768
2045.33	12.8762
2048.26	12.5544
2051.19	11.8267
2054.12	11.3695
2057.04	10.3049
2059.97	11.2431
2062.89	12.1505
2065.81	12.7887
2068.73	13.8926
2071.65	14.4452
2074.57	14.6733
2077.49	14.7316
2080.41	15.6335
2083.32	17.0046
2086.24	18.755
2089.15	19.5946
2092.07	20.9342
2094.98	23.2243
2097.89	26.4766
2100.8	29.1438
2103.71	30.7611
2106.61	33.1227
2109.52	34.0446
2112.43	35.4591
2115.33	38.5011
2118.23	40.3789
2121.13	42.3162
2124.04	45.0839
2126.94	47.5889
2129.83	50.2757
2132.73	54.3997
2135.63	58.3428
2138.53	62.5652
2141.42	65.5188
2144.31	68.7559
2147.21	71.9073
2150.1	74.7686
2152.99	79.0713
2155.88	81.6105
2158.77	84.2855
2161.65	87.2736
2164.54	90.1026
2167.43	92.5892
2170.31	93.7131
2173.19	94.3732
2176.07	94.4578
2178.96	93.5457
2181.84	92.7557
2184.72	91.5771
2187.59	90.0146
2190.47	86.0819
2193.35	83.4451
2196.22	80.3453
2199.09	77.6818
2201.97	74.8955
2204.84	71.3006
2207.71	68.3026
2210.58	64.7108
2213.45	60.4886
2216.31	56.8682
2219.18	53.3311
2222.05	50.3298
2224.91	47.1585
2227.78	44.2829
2230.64	41.3653
2233.5	38.4143
2236.36	36.4318
2239.22	34.7326
2242.08	32.5242
2244.93	31.0045
2247.79	28.2447
2250.64	26.9846
2253.5	26.0071
2256.35	23.7274
2259.2	22.449
2262.05	20.9445
2264.9	20.3526
2267.75	19.4649
2270.6	18.3923
2273.45	17.1483
2276.29	17.6711
2279.14	16.8409
2281.98	16.0581
2284.82	15.2591
2287.66	15.1005
2290.5	14.2883
2293.34	13.1476
2296.18	11.3525
2299.02	11.9998
2301.86	11.8204
2304.69	12.3144
2307.53	12.0099
2310.36	12.5012
2313.19	12.6074
2316.02	12.5158
2318.85	12.066
2321.68	12.4646
2324.51	11.3186
2327.34	11.0771
2330.16	10.4368
2332.99	9.86634
2335.81	8.96798
2338.64	8.37113
2341.46	7.37042
2344.28	6.67129
2347.1	5.75821
2349.92	4.77261
2352.74	3.88088
2355.55	2.63114
2358.37	2.15026
2361.19	0.748999
2364	-0.259182
2366.81	-0.393916
2369.62	0.000541568
2372.44	-0.537682
2375.24	-0.831754
2378.05	-0.38063
2380.86	-0.455101
2383.67	-0.786388
2386.47	-0.907946
2389.28	-0.760197
2392.08	-0.0669468
2394.89	0.601266
2397.69	0.376244
2400.49	0.63356
2403.29	1.71659
2406.09	3.51568
2408.88	5.07922
2411.68	4.99333
2414.48	6.50293
2417.27	7.43824
2420.06	8.09102
2422.86	7.95541
2425.65	7.72977
2428.44	7.83423
2431.23	7.27386
2434.02	7.24277
2436.81	7.4419
2439.59	7.26025
2442.38	7.7507
2445.16	7.38945
2447.95	8.144
2450.73	7.09194
2453.51	7.12352
2456.29	5.98307
2459.07	6.45431
2461.85	5.45457
2464.63	4.36892
2467.4	4.81131
2470.18	5.66439
2472.95	6.45021
2475.73	6.54043
2478.5	5.5419
2481.27	6.04596
2484.04	5.93897
2486.81	4.86798
2489.58	3.60133
2492.35	4.29493
2495.12	4.3984
2497.88	4.98825
2500.65	5.38374
2503.41	6.21339
2506.17	5.29027
2508.94	5.4256
2511.7	4.8358
2514.46	3.70631
2517.22	3.30476
2519.97	2.86332
2522.73	2.52395
2525.49	2.13731
2528.24	2.01915
2530.99	2.39387
2533.75	2.18249
2536.5	2.79322
2539.25	2.46289
2542	2.73701
2544.75	2.63458
2547.5	3.44446
2550.24	3.94235
2552.99	4.85881
2555.74	5.35585
2558.48	6.17747
2561.22	7.20346
2563.96	7.45852
2566.71	7.53675
2569.45	7.79014
2572.18	7.58541
2574.92	7.58765
2577.66	8.1734
2580.4	8.11065
2583.13	8.25785
2585.87	8.45159
2588.6	8.26936
2591.33	7.54725
2594.06	7.48434
2596.79	7.02682
2599.52	6.562
2602.25	5.85584
2604.98	5.79496
2607.71	4.84413
2610.43	4.67646
2613.16	4.42096
2615.88	4.17712
2618.6	4.76218
2621.32	4.8837
2624.04	4.35263
2626.76	4.01555
2629.48	4.34232
2632.2	4.58176
2634.92	4.74775
2637.63	4.86301
2640.35	5.05201
2643.06	5.99484
2645.77	6.06815
2648.49	5.53671
2651.2	5.86813
2653.91	5.75647
2656.62	5.53309
2659.33	5.46209
2662.03	5.72294
2664.74	5.86647
2667.44	6.45422
2670.15	6.41752
2672.85	6.90114
2675.55	6.33792
2678.26	7.34854
2680.96	7.44582
2683.66	7.82174
2686.35	7.98619
2689.05	8.11785
2691.75	8.17968
2694.44	8.73506
2697.14	9.3838
2699.83	8.89583
2702.52	8.50285
2705.22	8.50399
2707.91	8.91892
2710.6	9.22984
2713.29	8.91873
2715.97	9.48087
2718.66	10.2056
2721.35	9.89709
2724.03	10.2254
2726.72	10.7371
2729.4	11.7587
2732.08	11.9347
2734.76	11.3573
2737.44	11.4448
2740.12	11.0996
2742.8	11.0102
2745.48	10.6345
2748.16	10.0414
2750.83	9.61316
2753.51	9.08031
2756.18	8.47773
2758.85	7.96413
2761.53	7.40351
2764.2	5.85674
2766.87	4.46543
2769.54	3.69066
2772.2	3.53279
2774.87	3.84492
2777.54	2.72187
2780.2	2.25792
2782.87	1.59829
2785.53	0.929815
2788.19	0.456946
2790.85	-0.188501
2793.51	0.460367
2796.17	-0.658279
2798.83	-1.32796
2801.49	-0.934075
2804.15	-0.325427
2806.8	-0.626813
2809.46	-0.519801
2812.11	-0.876737
2814.76	-0.704336
2817.42	0.530397
2820.07	1.30629
2822.72	3.16489
2825.37	6.25949
2828.02	9.25501
2830.66	12.8262
2833.31	16.8933
2835.96	20.909
2838.6	24.6285
2841.24	29.2353
2843.89	34.6491
2846.53	41.2614
2849.17	48.1229
2851.81	56.1988
2854.45	64.229
2857.09	71.6527
2859.72	79.2843
2862.36	86.3566
2865	93.8197
2867.63	100.2
2870.26	105.537
2872.9	110.453
2875.53	114.048
2878.16	117.199
2880.79	120.367
2883.42	123.907
2886.05	128.137
2888.67	132.182
2891.3	135.829
2893.92	138.945
2896.55	142.572
2899.17	146.96
2901.79	153.172
2904.42	160.91
2907.04	169.835
2909.66	180.076
2912.27	191.157
2914.89	202.796
2917.51	214.973
2920.13	224.825
2922.74	232.909
2925.35	240.072
2927.97	245.996
2930.58	249.545
2933.19	251.064
2935.8	250.513
2938.41	247.524
2941.02	242.405
2943.63	236.754
2946.24	228.563
2948.84	220.543
2951.45	211.354
2954.05	201.043
2956.65	191.614
2959.26	181.181
2961.86	170.632
2964.46	161.264
2967.06	152.508
2969.66	143.628
2972.25	135.574
2974.85	128.115
2977.45	120.73
2980.04	113.913
2982.64	105.781
2985.23	97.2521
2987.82	88.7682
2990.41	80.8933
2993	72.261
2995.59	64.3367
2998.18	56.9303
3000.77	49.1937
3003.36	41.9449
3005.94	36.2025
3008.53	29.7493
3011.11	25.5734
3013.69	21.8872
3016.28	18.0078
3018.86	15.0416
3021.44	12.9381
3024.02	10.9141
3026.6	9.44801
3029.18	8.78087
3031.75	8.85758
3034.33	9.09806
3036.9	10.5736
3039.48	11.5982
3042.05	12.7193
3044.62	13.9544
3047.19	14.889
3049.77	14.9723
3052.34	14.9739
3054.9	15.2815
3057.47	14.9872
3060.04	15.0864
3062.61	13.997
3065.17	13.0053
3067.74	12.0024
3070.3	11.3872
3072.86	9.55966
3075.42	7.69358
3077.99	6.25947
3080.54	5.11166
3083.1	4.21143
3085.66	2.93367
3088.22	1.9444
3090.78	1.12682
3093.33	0.0925799
3095.89	0.388007
3098.44	-0.443617
3100.99	-0.14544
3103.54	0.18696
3106.1	0.272627
3108.65	0.536395
3111.2	0.579716
3113.74	0.951452
3116.29	1.31994
3118.84	1.88296
3121.38	2.19989
3123.93	3.08921
3126.47	3.71199
3129.01	5.10296
3131.56	5.68268
3134.1	6.0526
3136.64	7.23218
3139.18	8.63366
3141.72	9.48425
3144.26	10.2997
3146.79	10.8701
3149.33	11.7726