File: data/Raman/poly_smoothed/Thy_40_11_25_1x_45s_532 nm_x100_100%_600 gr_mm_01.txt
#Acq. time (s)=	45
#Accumulations=	2
#Range (cm-¹)=	200...3150
#Windows=	2
#Auto scanning=	Off
#Autofocus=	Off
#Macrospot=	Off
#AutoExposure=	Off
#Spike filter=	Multiple accum.
#Delay time (s)=	0
#Binning=	1
#Readout mode=	Signal
#DeNoise=	Off
#ICS correction=	On
#Dark correction=	Off
#Inst. Process=	Off
#Detector Gain=	Best Dynamic Range
#Detector ADC=	20 kHz
#Detector temperature (°C)=	-69.85
#Instrument=	LabRAM HR Evol
#Detector=	Synapse
#Objective=	x100
#Grating=	600 gr/mm
#ND Filter=	100%
#Laser (nm)=	532
#Hole=	100.021
#Range=	Auto
#Laser Pol.=	No
#Raman. Pol.=	No
#Laser Pol. (°)=	-0.0007625
#Raman Pol. (°)=	89.9995
#Collection=	Microscope
#StageXY=	Marzhauser
#StageZ=	Marzhauser
#X (µm)=	1952.6
#Y (µm)=	-44.1
#Z (µm)=	425.2
#Full time(mm:ss)=	3:18
#Project=
#Sample=
#Site=
#Title=	Thy_40_11_25_2x_45s_532 nm_x100_100%_600 gr_mm
#Remark=
#Date=	05.07.2022 11:38
#Acquired=	05.07.2022 11:38:24
#Base:Fit=	10.08.2022 10:01:35
#Base:Sub=	10.08.2022 10:01:52
#Filter:Polynom=	16.08.2022 10:21:53
#AxisType[0]=Intens
#AxisUnit[0]=Cnt
#AxisType[1]=Spectr
#AxisUnit[1]=1/cm
200.43	35.197
204.059	28.4016
207.688	20.8511
211.314	15.1839
214.941	10.8918
218.564	9.20825
222.186	6.18381
225.809	5.49947
229.428	4.05153
233.045	4.02301
236.663	4.59009
240.278	4.76433
243.891	6.38892
247.503	6.68294
251.116	7.49639
254.725	8.31914
258.333	9.98921
261.939	11.1914
265.544	11.8284
269.148	10.6791
272.75	10.0299
276.351	8.57629
279.95	8.25202
283.548	7.79162
287.144	8.50985
290.739	7.3982
294.333	5.88748
297.925	7.14679
301.514	6.79319
305.104	6.60002
308.692	5.41
312.279	5.44934
315.862	5.49417
319.446	5.07536
323.029	6.2489
326.608	5.04251
330.188	6.23738
333.766	5.57741
337.341	4.48981
340.917	4.65289
344.489	5.32037
348.062	4.61095
351.631	2.23534
355.201	1.56721
358.768	1.44975
362.333	1.19067
365.899	2.51079
369.462	3.55175
373.023	3.44052
376.585	3.0698
380.143	3.52397
383.7	4.07408
387.256	6.42844
390.812	5.26561
394.365	5.7847
397.916	5.81156
401.467	5.68964
405.015	5.92057
408.563	7.34953
412.109	7.24083
415.654	7.3437
419.197	6.85255
422.739	6.24096
426.279	7.80205
429.819	7.62986
433.356	7.81684
436.891	6.84006
440.426	7.49684
443.96	8.19326
447.492	8.09495
451.021	8.80619
454.551	8.33646
458.079	9.04918
461.604	10.7351
465.13	13.5527
468.654	15.7766
472.175	16.6201
475.696	16.6816
479.215	15.8324
482.733	17.8884
486.249	15.697
489.765	16.2904
493.278	18.6556
496.789	18.6104
500.301	20.1612
503.81	19.8584
507.317	19.8937
510.825	21.1548
514.33	21.0077
517.833	22.1319
521.335	22.1061
524.836	22.5728
528.335	21.964
531.835	22.1331
535.332	22.4898
538.827	22.8534
542.321	22.9712
545.814	22.7207
549.305	23.1087
552.795	21.8323
556.282	20.8542
559.769	20.1414
563.255	17.6205
566.739	14.9287
570.223	12.0378
573.705	10.8796
577.183	10.7772
580.663	10.1158
584.141	10.5124
587.615	10.5037
591.09	8.85342
594.564	8.63524
598.035	8.65572
601.506	8.1083
604.974	9.29456
608.443	10.8499
611.908	12.337
615.374	13.5436
618.837	14.8664
622.3	15.7483
625.761	15.9263
629.219	17.8214
632.677	20.2899
636.135	23.0541
639.59	24.7843
643.043	25.617
646.495	25.8656
649.948	26.9492
653.398	26.4256
656.846	27.6593
660.293	28.1095
663.738	28.04
667.183	30.703
670.626	32.2107
674.067	32.4087
677.508	31.8447
680.947	33.2867
684.385	34.0106
687.821	36.5284
691.254	38.9274
694.688	41.3782
698.121	42.7587
701.552	43.6732
704.98	45.5363
708.409	46.6853
711.836	48.3589
715.26	49.9475
718.685	52.2595
722.108	53.0479
725.528	53.9298
728.949	54.5903
732.367	55.9413
735.785	55.1024
739.2	56.3861
742.614	57.5829
746.028	59.9201
749.439	62.8286
752.849	65.2176
756.26	66.4045
759.667	65.4311
763.073	68.6958
766.477	70.0953
769.883	69.9201
773.285	71.6128
776.686	72.992
780.085	74.4678
783.484	76.5851
786.881	77.3504
790.276	79.5853
793.671	81.5231
797.064	83.1941
800.456	85.1285
803.846	88.1124
807.234	88.9324
810.622	90.0049
814.008	90.8057
817.394	92.3295
820.778	93.8043
824.159	96.209
827.541	98.1507
830.921	96.9737
834.298	95.3187
837.676	94.7451
841.051	92.8606
844.426	90.6372
847.798	86.6205
851.171	81.7149
854.54	79.2345
857.911	77.3177
861.278	74.676
864.645	71.6895
868.01	69.8386
871.373	67.9858
874.735	66.4022
878.097	65.0075
881.457	63.3215
884.815	60.8459
888.172	59.1214
891.528	59.1835
894.882	58.0485
898.237	57.8448
901.589	57.5163
904.94	57.3713
908.289	54.7981
911.635	54.371
914.982	54.0709
918.328	53.7118
921.672	54.0115
925.015	51.1532
928.357	48.8193
931.698	48.0865
935.035	45.6668
938.373	44.9741
941.71	43.7148
945.044	41.1223
948.378	39.4938
951.709	39.3373
955.041	38.4107
958.372	39.0128
961.699	37.4089
965.027	36.129
968.352	38.4844
971.676	41.0302
975	42.9219
978.322	42.8802
981.642	44.5742
984.962	44.9
988.28	46.4312
991.596	49.1883
994.911	50.5901
998.227	49.3841
1001.54	49.4378
1004.85	48.3884
1008.16	45.2978
1011.47	44.3906
1014.78	43.2534
1018.08	43.2454
1021.39	41.5282
1024.69	38.7033
1028	36.6987
1031.3	36.5229
1034.6	36.4662
1037.9	34.9197
1041.19	32.3842
1044.49	31.2292
1047.78	31.291
1051.08	30.7862
1054.37	30.1922
1057.66	29.2205
1060.95	28.5416
1064.24	28.2935
1067.53	28.4861
1070.81	27.1699
1074.1	25.3218
1077.38	24.5512
1080.66	21.8389
1083.94	21.3029
1087.22	19.5904
1090.5	19.8506
1093.78	21.2736
1097.05	22.2286
1100.33	21.7533
1103.6	21.9509
1106.87	21.7736
1110.14	21.4966
1113.41	19.8131
1116.68	19.6689
1119.95	18.1962
1123.21	16.9096
1126.48	16.4716
1129.74	13.4551
1133	14.1341
1136.26	11.4968
1139.52	10.4178
1142.78	8.95648
1146.04	6.91759
1149.29	4.59277
1152.55	4.31379
1155.8	3.8128
1159.05	2.18541
1162.3	-0.281153
1165.55	0.334437
1168.8	-0.628943
1172.05	0.966672
1175.29	0.426855
1178.54	1.45022
1181.78	1.61555
1185.02	3.71242
1188.26	2.33419
1191.5	3.80979
1194.74	5.67588
1197.97	7.29501
1201.21	9.91243
1204.44	12.3278
1207.68	15.5729
1210.91	18.4906
1214.14	20.5975
1217.37	24.3188
1220.59	28.8583
1223.82	33.6557
1227.05	38.0465
1230.27	41.9954
1233.49	45.1645
1236.72	48.2067
1239.94	50.4649
1243.16	53.0767
1246.37	55.7401
1249.59	58.0708
1252.8	58.4475
1256.02	60.0291
1259.23	60.3906
1262.44	61.9912
1265.66	62.4939
1268.86	63.062
1272.07	64.7221
1275.28	65.892
1278.48	65.8232
1281.69	67.149
1284.89	67.6177
1288.09	68.6012
1291.29	70.9049
1294.49	73.2589
1297.69	75.3429
1300.89	77.5407
1304.08	78.6754
1307.28	79.3717
1310.47	80.627
1313.66	81.0514
1316.85	81.9219
1320.04	81.8711
1323.23	81.4258
1326.42	80.7098
1329.61	80.1956
1332.79	79.4842
1335.97	77.6223
1339.16	74.9677
1342.34	72.0014
1345.52	67.3946
1348.7	62.5926
1351.87	59.5336
1355.05	53.9984
1358.22	51.8286
1361.4	49.2133
1364.57	46.3993
1367.74	43.6074
1370.91	42.2994
1374.08	41.4344
1377.25	39.0844
1380.41	36.0188
1383.58	35.7691
1386.74	35.6294
1389.91	34.6077
1393.07	34.3438
1396.23	33.9329
1399.39	34.303
1402.55	33.5652
1405.7	35.0468
1408.86	35.6425
1412.01	35.5154
1415.17	36.5135
1418.32	38.5705
1421.47	41.6423
1424.62	45.2591
1427.77	51.3476
1430.91	57.3087
1434.06	63.484
1437.2	67.3124
1440.35	71.6887
1443.49	75.596
1446.63	78.1806
1449.77	80.1083
1452.91	80.157
1456.05	76.629
1459.18	73.1297
1462.32	68.9016
1465.45	63.1956
1468.59	57.2776
1471.72	50.6178
1474.85	44.4451
1477.98	37.8895
1481.1	31.3021
1484.23	25.7407
1487.36	19.87
1490.48	15.0807
1493.61	11.7007
1496.73	9.40564
1499.85	7.85828
1502.97	8.11033
1506.09	7.28343
1509.2	6.69345
1512.32	6.0061
1515.43	6.17391
1518.55	6.59213
1521.66	7.61481
1524.77	9.61831
1527.88	10.2245
1530.99	10.9282
1534.1	12.2379
1537.21	15.1815
1540.31	17.2275
1543.42	20.5919
1546.52	23.4461
1549.62	27.0931
1552.72	31.6379
1555.82	36.2313
1558.92	38.8497
1562.02	42.9311
1565.11	47.2553
1568.21	49.0334
1571.3	52.7247
1574.39	55.2776
1577.49	59.2108
1580.57	61.3418
1583.66	64.0103
1586.75	65.6716
1589.84	67.0483
1592.92	68.9906
1596.01	69.2459
1599.09	69.3354
1602.17	68.8131
1605.25	67.855
1608.33	69.4226
1611.41	69.4156
1614.49	68.6456
1617.57	68.5822
1620.64	67.7477
1623.72	70.0382
1626.79	72.6619
1629.86	74.0589
1632.93	75.8479
1636	78.0233
1639.07	80.5372
1642.13	82.9498
1645.2	86.0428
1648.26	88.948
1651.33	92.066
1654.39	93.1935
1657.45	93.4761
1660.51	93.0375
1663.57	91.0172
1666.63	88.0462
1669.68	84.7583
1672.74	79.9444
1675.79	74.1434
1678.85	68.7833
1681.9	62.6648
1684.95	54.8254
1688	47.5483
1691.05	39.8533
1694.09	32.4622
1697.14	29.2268
1700.18	24.1396
1703.23	18.556
1706.27	13.6922
1709.31	9.7494
1712.35	8.43697
1715.39	7.4716
1718.43	6.12197
1721.47	5.79699
1724.5	5.13575
1727.54	4.02626
1730.57	5.11778
1733.61	5.33513
1736.64	6.13925
1739.67	6.72872
1742.7	7.90878
1745.72	6.27105
1748.75	5.53162
1751.77	5.65198
1754.8	4.62774
1757.82	3.38116
1760.84	2.52389
1763.87	2.81218
1766.89	2.34227
1769.91	2.60645
1772.92	1.61847
1775.94	1.05198
1778.95	-0.103396
1781.97	-0.252369
1784.98	0.370061
1787.99	0.251144
1791.01	0.0850003
1794.01	-0.55987
1797.02	-0.583976
1800.03	-0.445416
1803.04	0.563359
1806.04	1.59846
1809.05	1.62069
1812.05	1.76638
1815.05	2.30485
1818.05	2.69516
1821.05	2.77443
1824.05	3.65819
1827.05	3.22627
1830.04	3.64069
1833.04	3.77591
1836.03	3.42273
1839.03	3.71158
1842.02	3.46039
1845.01	3.13205
1848	2.8318
1850.99	2.37702
1853.97	2.81089
1856.96	3.18095
1859.94	4.32445
1862.93	3.52375
1865.91	3.46782
1868.89	2.72017
1871.87	2.76368
1874.85	3.81185
1877.83	3.87378
1880.81	4.05246
1882.57	4.64206
1885.56	5.18569
1888.55	5.19483
1891.54	4.73398
1894.52	5.24504
1897.51	5.37305
1900.49	5.33859
1903.47	4.88181
1906.45	4.32305
1909.43	3.42877
1912.41	3.58292
1915.39	3.90301
1918.37	3.49565
1921.34	3.63828
1924.32	4.16664
1927.29	5.22777
1930.26	5.17765
1933.23	5.0397
1936.2	4.77132
1939.17	4.62032
1942.14	4.44863
1945.11	5.33886
1948.07	5.03965
1951.04	4.76221
1954	5.48653
1956.96	4.45075
1959.93	3.64684
1962.89	3.13592
1965.85	3.63411
1968.8	2.91962
1971.76	1.89146
1974.72	0.830003
1977.67	1.05473
1980.63	0.907351
1983.58	0.781308
1986.53	1.29146
1989.48	1.93808
1992.43	1.70615
1995.38	2.53255
1998.32	2.31482
2001.27	2.3628
2004.22	2.29068
2007.16	2.34018
2010.1	3.06145
2013.04	3.75209
2015.98	4.48669
2018.92	5.24658
2021.86	6.53475
2024.8	6.57228
2027.74	5.93686
2030.67	7.67004
2033.61	9.18893
2036.54	9.81275
2039.47	9.73223
2042.4	11.1532
2045.33	11.5928
2048.26	11.2854
2051.19	12.2094
2054.12	11.3549
2057.04	11.5547
2059.97	12.2218
2062.89	12.7671
2065.81	12.9971
2068.73	12.4394
2071.65	12.4011
2074.57	12.3514
2077.49	12.9765
2080.41	13.7826
2083.32	14.0197
2086.24	14.6756
2089.15	16.1667
2092.07	16.9144
2094.98	18.4415
2097.89	20.1448
2100.8	23.1183
2103.71	24.7464
2106.61	28.2369
2109.52	30.2286
2112.43	33.4684
2115.33	35.3864
2118.23	38.4965
2121.13	41.3251
2124.04	44.185
2126.94	48.0808
2129.83	51.7148
2132.73	55.8089
2135.63	59.8354
2138.53	62.7124
2141.42	66.0488
2144.31	70.2877
2147.21	73.8384
2150.1	76.627
2152.99	80.295
2155.88	84.4613
2158.77	88.2534
2161.65	89.9327
2164.54	92.8584
2167.43	94.7806
2170.31	95.5721
2173.19	96.3169
2176.07	96.4528
2178.96	94.6002
2181.84	92.5753
2184.72	91.2795
2187.59	88.3017
2190.47	86.1392
2193.35	82.9958
2196.22	80.2875
2199.09	76.5048
2201.97	71.4716
2204.84	67.718
2207.71	64.5596
2210.58	60.0816
2213.45	55.8032
2216.31	51.1629
2219.18	47.4407
2222.05	44.3639
2224.91	42.3494
2227.78	40.2119
2230.64	36.9089
2233.5	34.6374
2236.36	32.4723
2239.22	30.541
2242.08	28.7678
2244.93	27.8379
2247.79	26.2286
2250.64	26.0144
2253.5	25.35
2256.35	24.5893
2259.2	23.8507
2262.05	22.6073
2264.9	21.9487
2267.75	20.6238
2270.6	19.097
2273.45	18.2399
2276.29	18.2112
2279.14	17.3864
2281.98	14.9949
2284.82	12.9756
2287.66	12.697
2290.5	11.2428
2293.34	8.93941
2296.18	8.54655
2299.02	8.34108
2301.86	8.87137
2304.69	9.46309
2307.53	9.8906
2310.36	10.5577
2313.19	10.3439
2316.02	10.4823
2318.85	10.0214
2321.68	10.0427
2324.51	8.77741
2327.34	8.06382
2330.16	7.14295
2332.99	7.82529
2335.81	6.66399
2338.64	5.81248
2341.46	6.08107
2344.28	5.072
2347.1	4.7293
2349.92	4.00041
2352.74	2.84207
2355.55	2.36195
2358.37	1.41537
2361.19	0.758457
2364	1.5553
2366.81	2.44957
2369.62	3.15517
2372.44	2.57822
2375.24	2.62954
2378.05	2.39137
2380.86	1.69615
2383.67	1.04822
2386.47	1.35718
2389.28	0.275527
2392.08	-0.461202
2394.89	-0.388714
2397.69	-0.14724
2400.49	0.0848088
2403.29	0.53512
2406.09	-0.185267
2408.88	0.979204
2411.68	0.809455
2414.48	1.55866
2417.27	1.88788
2420.06	2.85922
2422.86	3.28959
2425.65	3.0522
2428.44	2.99408
2431.23	2.72648
2434.02	3.01772
2436.81	2.83628
2439.59	2.9985
2442.38	3.5347
2445.16	3.4326
2447.95	3.15832
2450.73	2.37112
2453.51	2.63157
2456.29	2.77607
2459.07	2.36752
2461.85	3.16689
2464.63	3.43296
2467.4	3.35807
2470.18	4.00721
2472.95	4.08302
2475.73	3.4073
2478.5	4.48185
2481.27	3.52397
2484.04	3.84957
2486.81	3.32425
2489.58	2.6946
2492.35	2.34581
2495.12	1.62152
2497.88	0.784397
2500.65	1.12161
2503.41	0.868269
2506.17	1.33653
2508.94	0.714339
2511.7	0.425459
2514.46	-0.194774
2517.22	0.775961
2519.97	1.04994
2522.73	1.98703
2525.49	2.03832
2528.24	3.03822
2530.99	2.95124
2533.75	4.35891
2536.5	4.6014
2539.25	4.90907
2542	6.25308
2544.75	7.23419
2547.5	7.43172
2550.24	7.47755
2552.99	7.79229
2555.74	8.2943
2558.48	9.2486
2561.22	9.38738
2563.96	9.78487
2566.71	9.17506
2569.45	9.91721
2572.18	9.65689
2574.92	8.99759
2577.66	8.79031
2580.4	9.12978
2583.13	8.76552
2585.87	9.31789
2588.6	8.69082
2591.33	8.31447
2594.06	7.86178
2596.79	7.41279
2599.52	7.18305
2602.25	7.07843
2604.98	7.45
2607.71	7.71425
2610.43	8.67912
2613.16	7.56285
2615.88	6.96022
2618.6	7.20042
2621.32	8.01785
2624.04	8.50564
2626.76	8.35732
2629.48	9.09692
2632.2	9.14713
2634.92	9.10342
2637.63	9.96322
2640.35	10.1068
2643.06	9.84113
2645.77	10.0824
2648.49	10.1707
2651.2	9.78804
2653.91	10.0085
2656.62	10.102
2659.33	10.3042
2662.03	10.9104
2664.74	11.1098
2667.44	11.4515
2670.15	12.2402
2672.85	12.4775
2675.55	12.2554
2678.26	11.0044
2680.96	10.7092
2683.66	11.4433
2686.35	11.0884
2689.05	10.8263
2691.75	10.3465
2694.44	10.8885
2697.14	11.0692
2699.83	11.2006
2702.52	11.3671
2705.22	11.608
2707.91	11.9476
2710.6	11.6177
2713.29	12.2538
2715.97	12.0856
2718.66	12.5847
2721.35	13.6597
2724.03	13.8185
2726.72	14.5206
2729.4	15.2348
2732.08	16.0464
2734.76	15.6725
2737.44	15.4063
2740.12	14.5369
2742.8	13.8261
2745.48	13.2008
2748.16	12.5035
2750.83	12.5307
2753.51	11.3952
2756.18	11.6846
2758.85	11.9641
2761.53	11.2898
2764.2	11.0898
2766.87	10.7839
2769.54	9.71228
2772.2	9.19267
2774.87	8.21947
2777.54	7.75607
2780.2	7.59241
2782.87	7.83191
2785.53	7.79424
2788.19	6.74781
2790.85	6.17191
2793.51	5.09175
2796.17	5.00676
2798.83	4.45527
2801.49	3.28795
2804.15	3.25384
2806.8	2.38841
2809.46	2.30579
2812.11	1.8744
2814.76	1.68045
2817.42	2.00498
2820.07	3.97103
2822.72	5.63218
2825.37	8.67206
2828.02	11.3339
2830.66	14.1235
2833.31	18.0615
2835.96	22.6079
2838.6	28.0217
2841.24	33.6082
2843.89	38.8494
2846.53	45.9528
2849.17	51.8405
2851.81	58.4894
2854.45	66.0999
2857.09	73.7294
2859.72	82.3038
2862.36	90.9699
2865	98.1863
2867.63	104.077
2870.26	109.787
2872.9	114.906
2875.53	119.046
2878.16	122.517
2880.79	126.298
2883.42	130.664
2886.05	134.688
2888.67	139.144
2891.3	143.637
2893.92	148.29
2896.55	151.774
2899.17	157.22
2901.79	162.487
2904.42	170.047
2907.04	177.64
2909.66	188.66
2912.27	199.565
2914.89	210.19
2917.51	221.786
2920.13	230.47
2922.74	238.819
2925.35	245.699
2927.97	250.699
2930.58	252.645
2933.19	254.031
2935.8	253.636
2938.41	249.789
2941.02	244.583
2943.63	238.604
2946.24	232.024
2948.84	223.444
2951.45	213.734
2954.05	204.436
2956.65	194.164
2959.26	182.615
2961.86	172.318
2964.46	162.905
2967.06	154.421
2969.66	146.799
2972.25	139.507
2974.85	133.093
2977.45	124.425
2980.04	116.59
2982.64	108.168
2985.23	99.9292
2987.82	91.6234
2990.41	82.1643
2993	73.1439
2995.59	64.0613
2998.18	57.1216
3000.77	49.687
3003.36	42.5229
3005.94	36.643
3008.53	31.0499
3011.11	25.9239
3013.69	21.3206
3016.28	18.1734
3018.86	15.2848
3021.44	12.8755
3024.02	10.2234
3026.6	9.52814
3029.18	10.0978
3031.75	10.1766
3034.33	11.0758
3036.9	12.6803
3039.48	13.4138
3042.05	15.1468
3044.62	15.5503
3047.19	16.5843
3049.77	17.1165
3052.34	16.4326
3054.9	16.2205
3057.47	17.4219
3060.04	17.7213
3062.61	18.6736
3065.17	18.1742
3067.74	17.3896
3070.3	16.3404
3072.86	15.5384
3075.42	13.915
3077.99	13.0243
3080.54	10.8197
3083.1	8.72831
3085.66	7.20888
3088.22	5.81315
3090.78	5.05507
3093.33	4.46233
3095.89	4.12787
3098.44	3.2614
3100.99	1.96764
3103.54	1.61793
3106.1	1.08431
3108.65	1.48304
3111.2	1.83025
3113.74	2.0926
3116.29	3.82236
3118.84	5.39468
3121.38	6.64298
3123.93	7.66313
3126.47	9.62835
3129.01	10.6546
3131.56	12.512
3134.1	13.67
3136.64	14.9368
3139.18	16.4385
3141.72	17.4331
3144.26	18.4497
3146.79	19.5028
3149.33	19.9996