File: data/Raman/poly_smoothed/Thy_40_11_48_1x_45s_532 nm_x100_100%_600 gr_mm_01.txt
#Acq. time (s)=	45
#Accumulations=	2
#Range (cm-¹)=	200...3150
#Windows=	2
#Auto scanning=	Off
#Autofocus=	Off
#Macrospot=	Off
#AutoExposure=	Off
#Spike filter=	Multiple accum.
#Delay time (s)=	0
#Binning=	1
#Readout mode=	Signal
#DeNoise=	Off
#ICS correction=	On
#Dark correction=	Off
#Inst. Process=	Off
#Detector Gain=	Best Dynamic Range
#Detector ADC=	20 kHz
#Detector temperature (°C)=	-69.85
#Instrument=	LabRAM HR Evol
#Detector=	Synapse
#Objective=	x100
#Grating=	600 gr/mm
#ND Filter=	100%
#Laser (nm)=	532
#Hole=	100.021
#Range=	Auto
#Laser Pol.=	No
#Raman. Pol.=	No
#Laser Pol. (°)=	-0.0007625
#Raman Pol. (°)=	89.9995
#Collection=	Microscope
#StageXY=	Marzhauser
#StageZ=	Marzhauser
#X (µm)=	253.4
#Y (µm)=	1697
#Z (µm)=	427.7
#Full time(mm:ss)=	3:18
#Project=
#Sample=
#Site=
#Title=	Thy_40_11_48_2x_45s_532 nm_x100_100%_600 gr_mm
#Remark=
#Date=	05.07.2022 13:24
#Acquired=	05.07.2022 13:24:50
#Base:Fit=	10.08.2022 10:01:35
#Base:Sub=	10.08.2022 10:01:52
#Filter:Polynom=	16.08.2022 10:21:53
#AxisType[0]=Intens
#AxisUnit[0]=Cnt
#AxisType[1]=Spectr
#AxisUnit[1]=1/cm
200.43	8.71006
204.059	10.151
207.688	11.4899
211.314	12.1994
214.941	11.8028
218.564	10.8163
222.186	8.98823
225.809	9.21771
229.428	8.44838
233.045	7.43536
236.663	6.06299
240.278	4.76274
243.891	4.9632
247.503	4.26964
251.116	3.02771
254.725	3.02472
258.333	3.20142
261.939	4.43942
265.544	3.74197
269.148	2.285
272.75	1.52961
276.351	3.18473
279.95	4.24633
283.548	4.18836
287.144	5.27654
290.739	6.00696
294.333	6.67851
297.925	7.10275
301.514	7.79675
305.104	8.48397
308.692	8.31113
312.279	10.6379
315.862	11.3687
319.446	11.6809
323.029	11.8211
326.608	13.2833
330.188	15.5877
333.766	15.2792
337.341	15.372
340.917	15.1059
344.489	15.0835
348.062	14.126
351.631	11.4952
355.201	9.63653
358.768	9.18876
362.333	8.98368
365.899	9.24543
369.462	6.69155
373.023	6.37097
376.585	6.13743
380.143	4.42454
383.7	3.22399
387.256	4.0151
390.812	2.24735
394.365	1.1274
397.916	2.10259
401.467	1.82759
405.015	1.65425
408.563	3.0057
412.109	4.46145
415.654	4.73766
419.197	4.28685
422.739	4.5555
426.279	3.64507
429.819	3.77263
433.356	3.27113
436.891	3.34083
440.426	1.95706
443.96	2.11406
447.492	3.07418
451.021	2.97714
454.551	4.46164
458.079	5.33457
461.604	6.16321
465.13	6.77602
468.654	7.86042
472.175	9.71957
475.696	10.1967
479.215	11.8638
482.733	14.5168
486.249	16.5997
489.765	19.6689
493.278	22.4853
496.789	24.2715
500.301	25.4919
503.81	27.3738
507.317	27.8248
510.825	27.516
514.33	27.6552
517.833	28.1952
521.335	28.8606
524.836	27.5597
528.335	25.7444
531.835	25.9934
535.332	26.1605
538.827	25.3281
542.321	24.5641
545.814	23.133
549.305	22.1591
552.795	20.6491
556.282	19.3729
559.769	18.5359
563.255	16.2315
566.739	14.8051
570.223	13.657
573.705	14.7139
577.183	13.7132
580.663	11.833
584.141	9.4509
587.615	7.84101
591.09	8.17832
594.564	7.53551
598.035	8.27274
601.506	8.89103
604.974	8.9645
608.443	8.57146
611.908	9.28073
615.374	10.131
618.837	9.68398
622.3	10.9452
625.761	11.6848
629.219	12.1685
632.677	11.789
636.135	11.3799
639.59	11.6815
643.043	13.0015
646.495	13.0681
649.948	13.0024
653.398	14.2826
656.846	16.4171
660.293	16.7176
663.738	17.2258
667.183	16.8287
670.626	17.9394
674.067	21.6199
677.508	24.1745
680.947	26.3504
684.385	29.018
687.821	31.3359
691.254	33.8655
694.688	36.3213
698.121	38.6813
701.552	39.2322
704.98	40.363
708.409	40.7841
711.836	40.6429
715.26	40.7899
718.685	42.4818
722.108	43.5747
725.528	44.2538
728.949	44.4317
732.367	44.789
735.785	45.1787
739.2	47.2441
742.614	48.1822
746.028	51.3193
749.439	52.7991
752.849	56.5752
756.26	61.0143
759.667	64.4533
763.073	67.4951
766.477	68.8164
769.883	72.3883
773.285	75.1534
776.686	77.2847
780.085	77.864
783.484	78.5096
786.881	79.1015
790.276	79.6423
793.671	80.2937
797.064	81.3144
800.456	80.7696
803.846	82.3383
807.234	81.2905
810.622	81.6514
814.008	79.9518
817.394	81.2939
820.778	81.8208
824.159	82.783
827.541	84.226
830.921	83.7092
834.298	83.2461
837.676	82.6433
841.051	80.9819
844.426	80.1148
847.798	78.2141
851.171	76.8609
854.54	74.4769
857.911	72.2976
861.278	69.0068
864.645	66.5379
868.01	64.5385
871.373	61.6186
874.735	59.0687
878.097	57.8384
881.457	57.4155
884.815	56.3132
888.172	55.5297
891.528	53.5502
894.882	52.5362
898.237	51.7607
901.589	52.7939
904.94	51.9275
908.289	51.5856
911.635	50.1055
914.982	48.7264
918.328	47.5311
921.672	47.2354
925.015	46.8346
928.357	44.7394
931.698	43.6832
935.035	41.8825
938.373	38.8839
941.71	36.0694
945.044	34.3241
948.378	33.1715
951.709	32.9043
955.041	33.9234
958.372	35.0159
961.699	36.129
965.027	36.4978
968.352	37.4926
971.676	38.2502
975	40.4158
978.322	42.0831
981.642	42.4539
984.962	42.2975
988.28	41.2425
991.596	41.6848
994.911	42.1602
998.227	41.7098
1001.54	41.6698
1004.85	41.4126
1008.16	40.1944
1011.47	40.1893
1014.78	38.8218
1018.08	38.0073
1021.39	36.2363
1024.69	35.9963
1028	36.7222
1031.3	36.308
1034.6	36.1803
1037.9	36.2259
1041.19	33.6471
1044.49	33.3431
1047.78	31.8089
1051.08	30.0129
1054.37	28.4099
1057.66	27.8121
1060.95	25.8065
1064.24	22.6501
1067.53	20.7199
1070.81	20.3431
1074.1	19.8647
1077.38	19.4416
1080.66	21.0394
1083.94	19.6606
1087.22	20.1599
1090.5	20.2246
1093.78	21.7834
1097.05	22.9496
1100.33	23.1512
1103.6	22.2665
1106.87	22.0013
1110.14	21.9324
1113.41	21.1702
1116.68	20.6077
1119.95	18.9799
1123.21	15.7967
1126.48	15.7232
1129.74	13.9473
1133	11.771
1136.26	10.2458
1139.52	8.08183
1142.78	6.6048
1146.04	5.74012
1149.29	4.98985
1152.55	4.02593
1155.8	2.93501
1159.05	2.92485
1162.3	2.82774
1165.55	3.25284
1168.8	2.99891
1172.05	4.82966
1175.29	4.5243
1178.54	4.04691
1181.78	2.6791
1185.02	2.34699
1188.26	2.7675
1191.5	3.66068
1194.74	4.04347
1197.97	5.27359
1201.21	7.4484
1204.44	9.27914
1207.68	12.5671
1210.91	14.6775
1214.14	18.1795
1217.37	22.9747
1220.59	26.7531
1223.82	30.9748
1227.05	35.4847
1230.27	40.0098
1233.49	43.2658
1236.72	48.721
1239.94	53.6291
1243.16	55.7388
1246.37	59.521
1249.59	61.265
1252.8	63.5898
1256.02	64.7933
1259.23	65.4884
1262.44	65.4712
1265.66	65.69
1268.86	66.5319
1272.07	66.7197
1275.28	66.9109
1278.48	67.2974
1281.69	67.3716
1284.89	66.7684
1288.09	67.3368
1291.29	67.8299
1294.49	67.2833
1297.69	68.7584
1300.89	69.4944
1304.08	70.0654
1307.28	69.6493
1310.47	71.1037
1313.66	72.2746
1316.85	73.8572
1320.04	74.283
1323.23	75.6802
1326.42	76.4225
1329.61	74.862
1332.79	75.6696
1335.97	72.8488
1339.16	71.7429
1342.34	69.9033
1345.52	68.8704
1348.7	66.07
1351.87	64.2543
1355.05	62.4198
1358.22	58.7938
1361.4	55.4167
1364.57	52.3775
1367.74	49.7029
1370.91	47.1449
1374.08	43.1033
1377.25	41.7333
1380.41	39.6006
1383.58	39.7185
1386.74	39.3491
1389.91	37.5903
1393.07	36.5611
1396.23	35.6273
1399.39	34.821
1402.55	33.0639
1405.7	32.1699
1408.86	33.3854
1412.01	34.9082
1415.17	37.4287
1418.32	39.1068
1421.47	44.4342
1424.62	49.4325
1427.77	54.2255
1430.91	59.8454
1434.06	64.241
1437.2	67.5606
1440.35	70.0493
1443.49	73.1439
1446.63	75.8212
1449.77	76.7877
1452.91	75.6396
1456.05	75.7421
1459.18	74.0647
1462.32	70.2314
1465.45	65.3045
1468.59	59.231
1471.72	54.2826
1474.85	48.7384
1477.98	42.4826
1481.1	36.3352
1484.23	33.4236
1487.36	29.3797
1490.48	24.401
1493.61	21.8847
1496.73	20.8261
1499.85	19.753
1502.97	18.527
1506.09	17.7482
1509.2	18.3918
1512.32	17.648
1515.43	18.2327
1518.55	20.0823
1521.66	22.9594
1524.77	24.8258
1527.88	25.2549
1530.99	26.3894
1534.1	29.7604
1537.21	33.1176
1540.31	35.453
1543.42	38.5879
1546.52	43.3606
1549.62	46.6883
1552.72	50.5229
1555.82	52.3744
1558.92	56.0487
1562.02	58.2797
1565.11	60.7115
1568.21	62.9316
1571.3	66.6202
1574.39	68.5742
1577.49	70.7477
1580.57	71.6676
1583.66	71.6239
1586.75	71.6721
1589.84	72.1274
1592.92	72.9046
1596.01	72.6395
1599.09	72.7529
1602.17	71.4491
1605.25	68.7462
1608.33	69.2191
1611.41	69.4237
1614.49	69.427
1617.57	69.7366
1620.64	70.7102
1623.72	70.2163
1626.79	71.1875
1629.86	71.9491
1632.93	73.8993
1636	77.1573
1639.07	80.7063
1642.13	84.8003
1645.2	89.9706
1648.26	93.4359
1651.33	96.0023
1654.39	98.0578
1657.45	98.4909
1660.51	97.6297
1663.57	97.2489
1666.63	93.4689
1669.68	89.5987
1672.74	85.2528
1675.79	80.3346
1678.85	73.0787
1681.9	67.2317
1684.95	60.844
1688	55.0546
1691.05	48.4123
1694.09	41.2256
1697.14	34.4428
1700.18	29.1582
1703.23	24.5634
1706.27	20.5206
1709.31	17.4614
1712.35	16.1612
1715.39	13.2823
1718.43	12.6372
1721.47	13.4014
1724.5	12.9644
1727.54	13.0448
1730.57	12.7646
1733.61	11.7057
1736.64	10.7253
1739.67	10.2071
1742.7	9.11214
1745.72	8.87829
1748.75	8.00244
1751.77	8.13383
1754.8	7.77228
1757.82	7.1642
1760.84	7.55805
1763.87	6.55921
1766.89	6.12707
1769.91	5.17277
1772.92	4.93333
1775.94	4.06139
1778.95	3.8662
1781.97	4.13408
1784.98	4.62195
1787.99	5.24038
1791.01	5.34048
1794.01	6.23315
1797.02	6.92085
1800.03	6.96404
1803.04	6.22946
1806.04	5.45348
1809.05	5.08137
1812.05	4.6633
1815.05	3.89181
1818.05	4.08674
1821.05	4.47283
1824.05	5.04068
1827.05	5.23118
1830.04	4.42983
1833.04	3.31226
1836.03	3.23284
1839.03	2.59111
1842.02	2.77863
1845.01	3.5285
1848	3.44126
1850.99	3.79086
1853.97	4.1892
1856.96	4.47446
1859.94	3.65033
1862.93	4.32542
1865.91	4.30033
1868.89	3.54278
1871.87	3.33942
1874.85	3.11146
1877.83	3.30013
1880.81	2.83109
1882.57	3.04507
1885.56	4.58248
1888.55	4.9103
1891.54	5.17038
1894.52	5.61176
1897.51	4.46091
1900.49	3.17706
1903.47	2.38308
1906.45	2.55545
1909.43	2.1514
1912.41	1.67114
1915.39	2.27455
1918.37	2.2477
1921.34	2.42484
1924.32	3.10866
1927.29	3.02251
1930.26	3.76293
1933.23	3.57637
1936.2	4.02487
1939.17	3.80042
1942.14	4.11694
1945.11	5.90772
1948.07	6.30152
1951.04	5.78355
1954	6.61339
1956.96	8.29687
1959.93	7.86725
1962.89	8.12931
1965.85	9.37513
1968.8	9.09972
1971.76	7.18223
1974.72	6.5714
1977.67	6.68997
1980.63	5.89173
1983.58	5.31531
1986.53	5.99358
1989.48	6.96521
1992.43	6.7374
1995.38	6.85888
1998.32	6.67483
2001.27	6.43099
2004.22	6.28606
2007.16	6.02069
2010.1	6.09068
2013.04	8.23246
2015.98	8.51301
2018.92	8.14181
2021.86	7.3253
2024.8	7.86297
2027.74	9.31767
2030.67	8.82752
2033.61	9.40509
2036.54	10.3184
2039.47	10.5061
2042.4	9.70324
2045.33	9.65198
2048.26	9.7671
2051.19	10.8644
2054.12	11.5751
2057.04	12.2685
2059.97	12.0953
2062.89	12.8913
2065.81	13.9194
2068.73	14.6224
2071.65	14.6986
2074.57	15.4889
2077.49	16.742
2080.41	18.6631
2083.32	19.4204
2086.24	20.7369
2089.15	21.4663
2092.07	23.4517
2094.98	26.0097
2097.89	27.0084
2100.8	27.9038
2103.71	29.5497
2106.61	32.1622
2109.52	33.9636
2112.43	36.833
2115.33	38.3707
2118.23	41.2635
2121.13	44.4746
2124.04	47.1349
2126.94	48.8996
2129.83	51.04
2132.73	53.8412
2135.63	58.5492
2138.53	61.2249
2141.42	63.966
2144.31	66.8157
2147.21	70.1394
2150.1	73.4159
2152.99	77.1086
2155.88	80.1928
2158.77	83.7785
2161.65	86.9567
2164.54	89.1603
2167.43	90.6454
2170.31	91.7756
2173.19	92.9547
2176.07	93.5146
2178.96	93.508
2181.84	92.0255
2184.72	89.4456
2187.59	87.0508
2190.47	83.848
2193.35	80.9825
2196.22	77.9016
2199.09	73.6703
2201.97	70.2214
2204.84	66.6415
2207.71	62.475
2210.58	57.3748
2213.45	54.694
2216.31	49.3951
2219.18	46.5145
2222.05	44.1528
2224.91	40.4352
2227.78	38.2163
2230.64	35.5264
2233.5	34.2579
2236.36	32.2339
2239.22	31.4474
2242.08	30.4667
2244.93	29.5906
2247.79	27.9441
2250.64	26.3762
2253.5	24.6955
2256.35	24.3584
2259.2	25.3066
2262.05	24.9081
2264.9	24.7436
2267.75	23.6591
2270.6	22.1077
2273.45	21.0879
2276.29	20.691
2279.14	20.0186
2281.98	18.9507
2284.82	18.0667
2287.66	16.834
2290.5	16.2837
2293.34	14.0073
2296.18	13.9626
2299.02	13.9107
2301.86	14.1965
2304.69	14.8927
2307.53	14.5433
2310.36	14.4978
2313.19	15.1493
2316.02	14.9933
2318.85	14.6146
2321.68	14.5316
2324.51	14.5061
2327.34	14.0695
2330.16	13.6446
2332.99	12.0156
2335.81	11.1336
2338.64	9.07568
2341.46	7.85496
2344.28	7.95718
2347.1	6.43631
2349.92	5.41547
2352.74	4.01635
2355.55	3.85217
2358.37	3.06725
2361.19	2.46885
2364	2.78506
2366.81	2.91565
2369.62	2.63363
2372.44	2.63051
2375.24	3.30907
2378.05	3.27685
2380.86	4.17151
2383.67	3.65362
2386.47	3.18508
2389.28	3.32563
2392.08	2.72422
2394.89	2.03113
2397.69	2.8909
2400.49	1.86469
2403.29	1.37841
2406.09	1.87593
2408.88	2.72366
2411.68	3.92282
2414.48	3.64668
2417.27	3.21882
2420.06	3.95803
2422.86	4.40088
2425.65	4.78194
2428.44	4.51832
2431.23	4.88607
2434.02	5.30077
2436.81	5.81942
2439.59	6.20934
2442.38	5.4794
2445.16	4.93159
2447.95	4.44698
2450.73	4.08582
2453.51	3.94437
2456.29	4.36987
2459.07	3.82944
2461.85	4.08275
2464.63	4.65397
2467.4	3.75115
2470.18	3.83097
2472.95	4.26376
2475.73	4.8059
2478.5	4.00386
2481.27	3.42135
2484.04	3.03619
2486.81	2.45686
2489.58	2.09411
2492.35	2.7035
2495.12	3.02392
2497.88	2.88068
2500.65	2.0058
2503.41	1.63402
2506.17	1.32582
2508.94	-0.458649
2511.7	-1.4573
2514.46	-1.6788
2517.22	-1.34299
2519.97	-1.16247
2522.73	-0.440325
2525.49	0.267963
2528.24	0.212264
2530.99	-0.595933
2533.75	0.0751325
2536.5	0.269645
2539.25	0.131009
2542	1.08898
2544.75	1.8098
2547.5	2.69903
2550.24	3.21887
2552.99	4.77805
2555.74	4.86113
2558.48	5.11379
2561.22	5.06785
2563.96	5.07627
2566.71	4.80152
2569.45	4.26338
2572.18	4.58304
2574.92	3.80566
2577.66	3.5926
2580.4	3.62903
2583.13	3.87456
2585.87	3.06745
2588.6	2.6181
2591.33	2.48434
2594.06	1.98004
2596.79	1.16023
2599.52	1.97538
2602.25	1.92091
2604.98	1.03907
2607.71	1.58812
2610.43	1.70959
2613.16	1.97043
2615.88	1.62974
2618.6	2.14947
2621.32	1.70817
2624.04	1.08055
2626.76	0.999818
2629.48	2.29134
2632.2	2.15493
2634.92	1.92836
2637.63	3.09901
2640.35	4.033
2643.06	4.04334
2645.77	4.52676
2648.49	5.49329
2651.2	5.03688
2653.91	5.4051
2656.62	5.96248
2659.33	6.57481
2662.03	6.51413
2664.74	6.33383
2667.44	6.06931
2670.15	5.65907
2672.85	5.55841
2675.55	4.44402
2678.26	4.39553
2680.96	4.33477
2683.66	4.23577
2686.35	4.08909
2689.05	3.65521
2691.75	3.79769
2694.44	4.88923
2697.14	4.02803
2699.83	3.88452
2702.52	3.87998
2705.22	4.7089
2707.91	4.34742
2710.6	4.45564
2713.29	5.00825
2715.97	5.52587
2718.66	5.83194
2721.35	6.07795
2724.03	7.10871
2726.72	7.31915
2729.4	7.63762
2732.08	7.61849
2734.76	7.63566
2737.44	7.18073
2740.12	7.33761
2742.8	6.99779
2745.48	7.59984
2748.16	7.27389
2750.83	7.72074
2753.51	7.56996
2756.18	7.71016
2758.85	8.44346
2761.53	7.88875
2764.2	6.13784
2766.87	7.3656
2769.54	7.35075
2772.2	6.6324
2774.87	6.39679
2777.54	5.66855
2780.2	5.09878
2782.87	5.13762
2785.53	4.45495
2788.19	3.91592
2790.85	3.448
2793.51	2.85269
2796.17	2.67929
2798.83	1.53247
2801.49	0.460516
2804.15	0.0794093
2806.8	-0.135516
2809.46	-0.48996
2812.11	-0.92611
2814.76	-0.883432
2817.42	-0.630558
2820.07	0.14083
2822.72	1.94743
2825.37	4.70101
2828.02	7.02115
2830.66	10.1933
2833.31	14.0347
2835.96	17.1021
2838.6	20.0964
2841.24	25.0577
2843.89	29.9939
2846.53	36.07
2849.17	42.6034
2851.81	49.1566
2854.45	56.7655
2857.09	64.1666
2859.72	70.184
2862.36	75.3266
2865	80.7747
2867.63	85.8694
2870.26	91.2902
2872.9	95.695
2875.53	98.3648
2878.16	101.972
2880.79	105.475
2883.42	108.939
2886.05	113.127
2888.67	117.23
2891.3	120.847
2893.92	124.636
2896.55	130.137
2899.17	136.419
2901.79	142.235
2904.42	150.457
2907.04	160.473
2909.66	170.585
2912.27	181.679
2914.89	192.637
2917.51	202.954
2920.13	212.615
2922.74	219.523
2925.35	226.525
2927.97	232.323
2930.58	235.632
2933.19	237.864
2935.8	237.109
2938.41	235.066
2941.02	231.185
2943.63	226.102
2946.24	220.969
2948.84	213.229
2951.45	205.599
2954.05	196.577
2956.65	187.084
2959.26	178.305
2961.86	169.481
2964.46	160.734
2967.06	151.455
2969.66	144.08
2972.25	137.186
2974.85	129.968
2977.45	123.558
2980.04	115.55
2982.64	107.724
2985.23	99.2922
2987.82	91.4099
2990.41	84.0685
2993	75.682
2995.59	68.3678
2998.18	61.7928
3000.77	55.8677
3003.36	49.7279
3005.94	43.7282
3008.53	39.4585
3011.11	35.1089
3013.69	32.0951
3016.28	29.3483
3018.86	26.9281
3021.44	24.6577
3024.02	23.0092
3026.6	22.1904
3029.18	21.27
3031.75	20.7251
3034.33	21.3128
3036.9	21.8445
3039.48	21.4126
3042.05	21.7253
3044.62	22.5794
3047.19	23.0943
3049.77	23.5339
3052.34	23.3656
3054.9	23.4755
3057.47	24.1219
3060.04	24.5793
3062.61	23.5231
3065.17	22.1017
3067.74	20.947
3070.3	19.9842
3072.86	19.1967
3075.42	18.8213
3077.99	17.9031
3080.54	15.3731
3083.1	13.2429
3085.66	11.0672
3088.22	8.7641
3090.78	6.38479
3093.33	5.04893
3095.89	4.75146
3098.44	4.07654
3100.99	4.07537
3103.54	3.9302
3106.1	4.32472
3108.65	5.49542
3111.2	5.25041
3113.74	5.65572
3116.29	5.81336
3118.84	6.38816
3121.38	7.05414
3123.93	7.41852
3126.47	7.79918
3129.01	8.96815
3131.56	10.1634
3134.1	11.5729
3136.64	11.9095
3139.18	11.693
3141.72	11.5678
3144.26	11.4371
3146.79	12.4247
3149.33	14.9932