File: data/Raman/poly_smoothed/Thy_40_11_40_1x_45s_532 nm_x100_100%_600 gr_mm_01.txt
#Acq. time (s)=	45
#Accumulations=	2
#Range (cm-¹)=	200...3150
#Windows=	2
#Auto scanning=	Off
#Autofocus=	Off
#Macrospot=	Off
#AutoExposure=	Off
#Spike filter=	Multiple accum.
#Delay time (s)=	0
#Binning=	1
#Readout mode=	Signal
#DeNoise=	Off
#ICS correction=	On
#Dark correction=	Off
#Inst. Process=	Off
#Detector Gain=	Best Dynamic Range
#Detector ADC=	20 kHz
#Detector temperature (°C)=	-69.85
#Instrument=	LabRAM HR Evol
#Detector=	Synapse
#Objective=	x100
#Grating=	600 gr/mm
#ND Filter=	100%
#Laser (nm)=	532
#Hole=	100.021
#Range=	Auto
#Laser Pol.=	No
#Raman. Pol.=	No
#Laser Pol. (°)=	-0.0007625
#Raman Pol. (°)=	89.9995
#Collection=	Microscope
#StageXY=	Marzhauser
#StageZ=	Marzhauser
#X (µm)=	249.7
#Y (µm)=	1688.8
#Z (µm)=	426.8
#Full time(mm:ss)=	3:18
#Project=
#Sample=
#Site=
#Title=	Thy_40_11_40_2x_45s_532 nm_x100_100%_600 gr_mm
#Remark=
#Date=	05.07.2022 12:50
#Acquired=	05.07.2022 12:50:24
#Base:Fit=	10.08.2022 10:01:35
#Base:Sub=	10.08.2022 10:01:52
#Filter:Polynom=	16.08.2022 10:21:53
#AxisType[0]=Intens
#AxisUnit[0]=Cnt
#AxisType[1]=Spectr
#AxisUnit[1]=1/cm
200.43	1.41886
204.059	4.15872
207.688	6.05179
211.314	7.06336
214.941	7.76433
218.564	8.18429
222.186	7.39958
225.809	6.3807
229.428	5.38574
233.045	4.238
236.663	3.67477
240.278	2.9347
243.891	2.81746
247.503	3.78896
251.116	3.51752
254.725	3.74794
258.333	3.98552
261.939	5.14109
265.544	5.12481
269.148	5.5034
272.75	7.00573
276.351	8.88534
279.95	11.7019
283.548	12.919
287.144	12.9392
290.739	15.6339
294.333	17.6891
297.925	20.5194
301.514	23.2976
305.104	26.1664
308.692	26.5726
312.279	27.5075
315.862	26.7806
319.446	25.889
323.029	26.4266
326.608	25.5197
330.188	25.5278
333.766	24.7584
337.341	25.0274
340.917	24.075
344.489	22.1484
348.062	22.2482
351.631	21.2121
355.201	19.7223
358.768	20.7449
362.333	22.0034
365.899	21.6337
369.462	20.5398
373.023	20.0021
376.585	20.3172
380.143	23.008
383.7	23.6207
387.256	25.1475
390.812	25.5539
394.365	24.7283
397.916	21.2397
401.467	20.4727
405.015	18.6614
408.563	17.202
412.109	15.4629
415.654	14.679
419.197	14.1794
422.739	14.9688
426.279	15.9857
429.819	15.4596
433.356	14.8153
436.891	14.0751
440.426	12.8891
443.96	13.7287
447.492	15.2498
451.021	14.2919
454.551	13.8084
458.079	14.9915
461.604	15.9945
465.13	17.4425
468.654	18.1124
472.175	19.9139
475.696	20.131
479.215	21.0444
482.733	20.2542
486.249	20.6147
489.765	20.6553
493.278	19.51
496.789	20.9553
500.301	21.4665
503.81	22.0694
507.317	21.9468
510.825	22.1109
514.33	20.426
517.833	18.4105
521.335	17.9309
524.836	17.347
528.335	16.7385
531.835	15.8406
535.332	15.9415
538.827	14.5287
542.321	14.9752
545.814	15.5875
549.305	16.5809
552.795	16.9987
556.282	17.7611
559.769	16.2977
563.255	15.6852
566.739	14.3498
570.223	13.5049
573.705	10.5781
577.183	11.2031
580.663	10.4022
584.141	8.63362
587.615	7.98263
591.09	6.72966
594.564	6.21523
598.035	6.07953
601.506	6.4648
604.974	5.48225
608.443	6.67156
611.908	6.62878
615.374	5.71105
618.837	5.42466
622.3	7.66068
625.761	7.90636
629.219	9.65647
632.677	9.67795
636.135	8.88699
639.59	7.53335
643.043	7.82081
646.495	7.66376
649.948	7.53138
653.398	8.37703
656.846	8.278
660.293	8.67992
663.738	9.89908
667.183	10.4935
670.626	11.8033
674.067	14.5191
677.508	16.3635
680.947	18.7875
684.385	18.8345
687.821	18.672
691.254	20.59
694.688	21.7751
698.121	23.0479
701.552	23.4892
704.98	24.3978
708.409	25.6193
711.836	25.3015
715.26	25.3246
718.685	24.982
722.108	26.4834
725.528	27.6558
728.949	29.5455
732.367	30.8209
735.785	32.7168
739.2	35.8895
742.614	38.8442
746.028	41.5761
749.439	44.5737
752.849	47.3044
756.26	50.1938
759.667	50.8552
763.073	51.7385
766.477	51.6093
769.883	52.2166
773.285	53.4426
776.686	56.4142
780.085	56.3544
783.484	56.2345
786.881	56.7225
790.276	57.7083
793.671	57.4343
797.064	59.6886
800.456	61.4476
803.846	63.8643
807.234	66.5882
810.622	68.8589
814.008	71.5307
817.394	72.9734
820.778	75.5112
824.159	76.2071
827.541	75.9995
830.921	74.1389
834.298	71.3774
837.676	67.0152
841.051	63.8248
844.426	60.9677
847.798	57.4393
851.171	52.6942
854.54	49.7554
857.911	47.0786
861.278	45.0742
864.645	42.343
868.01	40.948
871.373	39.7834
874.735	38.4326
878.097	37.8364
881.457	39.1276
884.815	40.1063
888.172	41.4437
891.528	42.803
894.882	42.6721
898.237	43.3161
901.589	43.169
904.94	42.2392
908.289	41.52
911.635	39.3528
914.982	36.8257
918.328	34.9567
921.672	33.4368
925.015	31.5865
928.357	30.4364
931.698	28.6773
935.035	26.8568
938.373	25.7422
941.71	24.483
945.044	21.5353
948.378	19.9227
951.709	17.6248
955.041	17.9933
958.372	17.5566
961.699	15.6078
965.027	17.0145
968.352	16.4212
971.676	16.8292
975	15.7565
978.322	15.1023
981.642	16.2222
984.962	14.7847
988.28	15.4476
991.596	14.964
994.911	15.5017
998.227	17.3028
1001.54	17.078
1004.85	16.9956
1008.16	16.492
1011.47	16.4349
1014.78	15.0601
1018.08	14.6979
1021.39	13.1253
1024.69	11.3133
1028	11.9807
1031.3	11.6694
1034.6	11.6583
1037.9	11.4225
1041.19	12.4288
1044.49	13.3856
1047.78	15.4325
1051.08	14.9442
1054.37	15.3841
1057.66	14.3691
1060.95	15.7671
1064.24	15.6874
1067.53	15.2602
1070.81	16.0701
1074.1	15.4291
1077.38	15.8546
1080.66	14.0499
1083.94	12.8786
1087.22	12.0545
1090.5	9.66273
1093.78	10.7977
1097.05	8.59742
1100.33	7.26616
1103.6	5.89309
1106.87	5.74706
1110.14	3.34506
1113.41	2.93573
1116.68	3.13063
1119.95	3.99917
1123.21	4.4092
1126.48	3.14851
1129.74	3.42096
1133	3.0167
1136.26	2.55904
1139.52	2.47683
1142.78	3.05975
1146.04	1.33913
1149.29	2.17177
1152.55	2.79697
1155.8	1.51731
1159.05	1.21591
1162.3	-0.0224135
1165.55	1.1336
1168.8	1.94534
1172.05	4.10806
1175.29	5.01559
1178.54	3.77869
1181.78	4.35504
1185.02	6.21857
1188.26	5.66262
1191.5	7.05379
1194.74	9.7597
1197.97	11.4716
1201.21	11.6706
1204.44	12.8774
1207.68	15.2144
1210.91	16.3451
1214.14	17.9273
1217.37	18.794
1220.59	20.7929
1223.82	23.905
1227.05	27.308
1230.27	30.6682
1233.49	32.4304
1236.72	35.1679
1239.94	38.4484
1243.16	42.369
1246.37	47.2782
1249.59	51.0632
1252.8	53.8313
1256.02	57.5115
1259.23	60.8037
1262.44	64.9583
1265.66	69.1324
1268.86	72.6016
1272.07	76.4927
1275.28	80.5916
1278.48	81.4672
1281.69	82.1289
1284.89	82.3607
1288.09	80.7782
1291.29	80.6694
1294.49	80.2773
1297.69	80.459
1300.89	80.1933
1304.08	80.0653
1307.28	79.1618
1310.47	79.4843
1313.66	79.7746
1316.85	80.4703
1320.04	81.1161
1323.23	80.7056
1326.42	79.9167
1329.61	78.8939
1332.79	77.4289
1335.97	75.8244
1339.16	73.9933
1342.34	72.9071
1345.52	71.1435
1348.7	68.9446
1351.87	66.35
1355.05	62.1854
1358.22	56.287
1361.4	52.3453
1364.57	48.1737
1367.74	43.8371
1370.91	41.4877
1374.08	37.5587
1377.25	35.6412
1380.41	34.4178
1383.58	33.2798
1386.74	33.1027
1389.91	34.1701
1393.07	35.2653
1396.23	34.8164
1399.39	33.4226
1402.55	33.3756
1405.7	33.7285
1408.86	33.3964
1412.01	34.4854
1415.17	36.1706
1418.32	39.0182
1421.47	43.1032
1424.62	48.2509
1427.77	53.0587
1430.91	57.2244
1434.06	61.321
1437.2	65.4122
1440.35	69.6497
1443.49	73.6748
1446.63	77.4529
1449.77	78.952
1452.91	80.4547
1456.05	81.7994
1459.18	79.3718
1462.32	77.6115
1465.45	75.0142
1468.59	70.3968
1471.72	65.4915
1474.85	60.867
1477.98	54.868
1481.1	47.7006
1484.23	42.1776
1487.36	36.7199
1490.48	33.0791
1493.61	29.2563
1496.73	27.343
1499.85	25.9381
1502.97	25.8746
1506.09	24.5156
1509.2	24.766
1512.32	23.9725
1515.43	25.2783
1518.55	27.6018
1521.66	29.1793
1524.77	30.5732
1527.88	32.3067
1530.99	32.609
1534.1	34.0071
1537.21	36.4335
1540.31	38.6444
1543.42	41.2693
1546.52	44.1533
1549.62	47.8653
1552.72	49.1163
1555.82	50.8815
1558.92	52.7776
1562.02	54.5091
1565.11	56.2635
1568.21	58.0513
1571.3	61.2969
1574.39	63.9412
1577.49	65.695
1580.57	66.8798
1583.66	68.4663
1586.75	70.1538
1589.84	70.4116
1592.92	70.7696
1596.01	68.7129
1599.09	68.2786
1602.17	66.5833
1605.25	65.2273
1608.33	63.0122
1611.41	62.9165
1614.49	63.0046
1617.57	63.5422
1620.64	63.7109
1623.72	63.5596
1626.79	63.6779
1629.86	64.1789
1632.93	67.5786
1636	69.1757
1639.07	71.2039
1642.13	74.2611
1645.2	77.9188
1648.26	80.2528
1651.33	83.3539
1654.39	83.9838
1657.45	85.1357
1660.51	85.7814
1663.57	84.9506
1666.63	82.2075
1669.68	79.1597
1672.74	75.8873
1675.79	71.9318
1678.85	67.3283
1681.9	61.9634
1684.95	57.9583
1688	52.5438
1691.05	47.934
1694.09	42.5658
1697.14	36.7345
1700.18	32.9471
1703.23	30.1298
1706.27	27.4812
1709.31	25.0153
1712.35	21.9834
1715.39	19.5725
1718.43	18.0604
1721.47	16.7775
1724.5	13.9042
1727.54	13.4827
1730.57	12.9159
1733.61	11.9444
1736.64	11.5045
1739.67	9.70685
1742.7	9.21871
1745.72	8.67839
1748.75	6.88153
1751.77	5.73168
1754.8	6.0278
1757.82	5.46125
1760.84	4.73833
1763.87	3.9752
1766.89	3.25139
1769.91	2.59499
1772.92	2.00698
1775.94	1.7812
1778.95	1.14806
1781.97	0.529127
1784.98	-0.0202583
1787.99	-0.832573
1791.01	-1.03144
1794.01	-0.746601
1797.02	-1.11486
1800.03	-0.737685
1803.04	-0.530336
1806.04	0.0377304
1809.05	1.25767
1812.05	0.835165
1815.05	-0.0723206
1818.05	0.733482
1821.05	0.62949
1824.05	0.520435
1827.05	1.70383
1830.04	1.65548
1833.04	1.40388
1836.03	2.20412
1839.03	2.62312
1842.02	2.8518
1845.01	3.03758
1848	3.45711
1850.99	3.74398
1853.97	4.06807
1856.96	3.69655
1859.94	4.1674
1862.93	4.76699
1865.91	6.16721
1868.89	6.37278
1871.87	6.66329
1874.85	7.18768
1877.83	7.62756
1880.81	8.01139
1882.57	7.29224
1885.56	7.37787
1888.55	7.94714
1891.54	7.78685
1894.52	8.11448
1897.51	7.13067
1900.49	6.50036
1903.47	6.50149
1906.45	5.39759
1909.43	6.12979
1912.41	6.20345
1915.39	5.44624
1918.37	4.99525
1921.34	4.63669
1924.32	3.0098
1927.29	2.85843
1930.26	2.83145
1933.23	2.97743
1936.2	2.82957
1939.17	3.54401
1942.14	4.04582
1945.11	3.15879
1948.07	3.61519
1951.04	4.57373
1954	4.05378
1956.96	3.76934
1959.93	3.88569
1962.89	3.25819
1965.85	3.0609
1968.8	2.51244
1971.76	2.05024
1974.72	3.34618
1977.67	2.67889
1980.63	3.59865
1983.58	3.44604
1986.53	3.27699
1989.48	3.41027
1992.43	3.19666
1995.38	3.00313
1998.32	2.99276
2001.27	3.90888
2004.22	3.20219
2007.16	3.3276
2010.1	2.47195
2013.04	2.77767
2015.98	1.99307
2018.92	2.1309
2021.86	2.1338
2024.8	1.95037
2027.74	1.52256
2030.67	1.20288
2033.61	1.6435
2036.54	2.05512
2039.47	2.66256
2042.4	3.56003
2045.33	4.62887
2048.26	5.21878
2051.19	5.79419
2054.12	6.72744
2057.04	8.1445
2059.97	9.4314
2062.89	9.47921
2065.81	9.84043
2068.73	10.7443
2071.65	11.7373
2074.57	11.861
2077.49	11.8616
2080.41	12.4529
2083.32	13.4171
2086.24	14.8541
2089.15	16.56
2092.07	18.0726
2094.98	18.2033
2097.89	19.3327
2100.8	20.2848
2103.71	21.5741
2106.61	23.6275
2109.52	26.3457
2112.43	28.785
2115.33	30.61
2118.23	33.4208
2121.13	35.9844
2124.04	38.4969
2126.94	41.5732
2129.83	44.4754
2132.73	47.2442
2135.63	50.3135
2138.53	54.5294
2141.42	57.8802
2144.31	60.1771
2147.21	63.0002
2150.1	65.3606
2152.99	68.4959
2155.88	71.1525
2158.77	73.0456
2161.65	75.4134
2164.54	76.4311
2167.43	76.6934
2170.31	77.941
2173.19	77.6424
2176.07	77.1835
2178.96	76.5171
2181.84	75.6525
2184.72	73.7939
2187.59	72.7924
2190.47	70.7224
2193.35	67.281
2196.22	64.8939
2199.09	61.5254
2201.97	58.7705
2204.84	55.8464
2207.71	52.6853
2210.58	49.6179
2213.45	46.642
2216.31	43.298
2219.18	40.5123
2222.05	38.3135
2224.91	36.7114
2227.78	35.9077
2230.64	34.4187
2233.5	32.6648
2236.36	30.5262
2239.22	28.8946
2242.08	27.5441
2244.93	26.2004
2247.79	25.3696
2250.64	24.6382
2253.5	24.3968
2256.35	23.484
2259.2	21.7548
2262.05	19.7603
2264.9	18.7274
2267.75	18.5349
2270.6	16.6841
2273.45	15.7871
2276.29	15.6264
2279.14	14.7718
2281.98	14.5642
2284.82	12.3712
2287.66	11.908
2290.5	10.4247
2293.34	9.73715
2296.18	9.49708
2299.02	8.98728
2301.86	8.37205
2304.69	7.83885
2307.53	7.71907
2310.36	7.39478
2313.19	7.86129
2316.02	8.34658
2318.85	9.19131
2321.68	9.41457
2324.51	8.77387
2327.34	8.22923
2330.16	8.48711
2332.99	8.8562
2335.81	8.32286
2338.64	7.60858
2341.46	6.31016
2344.28	6.04393
2347.1	4.56154
2349.92	3.38342
2352.74	1.96757
2355.55	0.946857
2358.37	0.610522
2361.19	-0.0177753
2364	-0.770769
2366.81	-0.125381
2369.62	0.764963
2372.44	0.928244
2375.24	-0.221891
2378.05	0.00905255
2380.86	0.647419
2383.67	1.64448
2386.47	2.83983
2389.28	3.7834
2392.08	3.6481
2394.89	3.56263
2397.69	5.19771
2400.49	6.2988
2403.29	7.32509
2406.09	6.83017
2408.88	6.75845
2411.68	7.58737
2414.48	8.23438
2417.27	9.17406
2420.06	10.1979
2422.86	11.0186
2425.65	11.5994
2428.44	11.8346
2431.23	11.9873
2434.02	12.7465
2436.81	12.793
2439.59	12.777
2442.38	12.007
2445.16	11.4789
2447.95	10.8621
2450.73	10.3288
2453.51	8.96579
2456.29	8.31713
2459.07	7.15125
2461.85	5.79148
2464.63	5.88704
2467.4	5.61772
2470.18	5.53912
2472.95	5.04373
2475.73	4.78514
2478.5	4.98703
2481.27	5.55567
2484.04	5.09819
2486.81	4.42868
2489.58	3.90992
2492.35	4.11859
2495.12	3.96323
2497.88	4.57962
2500.65	4.6369
2503.41	4.33708
2506.17	3.90405
2508.94	4.2003
2511.7	3.83001
2514.46	2.76171
2517.22	2.11327
2519.97	2.98144
2522.73	3.32315
2525.49	4.49476
2528.24	4.79518
2530.99	5.62356
2533.75	7.73365
2536.5	8.14215
2539.25	9.99872
2542	10.9202
2544.75	12.377
2547.5	12.2603
2550.24	12.9076
2552.99	13.3916
2555.74	13.5238
2558.48	14.3609
2561.22	14.8438
2563.96	13.2501
2566.71	13.816
2569.45	13.1318
2572.18	12.4384
2574.92	12.5064
2577.66	12.3639
2580.4	10.7274
2583.13	9.92939
2585.87	9.22341
2588.6	9.37782
2591.33	9.30523
2594.06	9.29612
2596.79	9.23363
2599.52	9.1562
2602.25	9.77121
2604.98	10.3131
2607.71	11.0943
2610.43	11.3389
2613.16	11.3654
2615.88	11.5517
2618.6	12.4881
2621.32	13.4213
2624.04	13.8483
2626.76	14.2795
2629.48	14.2447
2632.2	14.9336
2634.92	15.108
2637.63	14.7178
2640.35	13.7559
2643.06	12.9176
2645.77	12.9546
2648.49	11.4754
2651.2	10.8674
2653.91	10.045
2656.62	9.57281
2659.33	9.33812
2662.03	8.96699
2664.74	8.16732
2667.44	7.87049
2670.15	8.03869
2672.85	8.9742
2675.55	8.48974
2678.26	7.49017
2680.96	7.97803
2683.66	7.32885
2686.35	7.76009
2689.05	9.013
2691.75	10.6397
2694.44	11.2404
2697.14	12.1896
2699.83	12.9155
2702.52	13.4123
2705.22	13.2488
2707.91	13.9959
2710.6	13.6643
2713.29	12.8273
2715.97	12.7122
2718.66	12.2187
2721.35	12.3509
2724.03	12.338
2726.72	12.6778
2729.4	12.7651
2732.08	12.5382
2734.76	12.5804
2737.44	11.7051
2740.12	10.2198
2742.8	9.10465
2745.48	7.86466
2748.16	6.79141
2750.83	5.59195
2753.51	6.80689
2756.18	7.14977
2758.85	6.85475
2761.53	7.0053
2764.2	6.15831
2766.87	5.30557
2769.54	4.91376
2772.2	4.19858
2774.87	2.94646
2777.54	1.87634
2780.2	1.98289
2782.87	1.58579
2785.53	2.00172
2788.19	1.72657
2790.85	1.97826
2793.51	1.80882
2796.17	1.11502
2798.83	0.669682
2801.49	0.0210042
2804.15	-0.251689
2806.8	-0.427528
2809.46	-0.445454
2812.11	-1.31722
2814.76	-1.99395
2817.42	-1.2017
2820.07	-0.344306
2822.72	0.739571
2825.37	3.41201
2828.02	5.07139
2830.66	8.17238
2833.31	11.3784
2835.96	15.2233
2838.6	19.2389
2841.24	22.6907
2843.89	28.0053
2846.53	33.0396
2849.17	39.3021
2851.81	46.0624
2854.45	52.088
2857.09	58.8322
2859.72	64.6291
2862.36	70.8583
2865	75.9224
2867.63	80.9675
2870.26	85.1207
2872.9	88.8899
2875.53	91.9641
2878.16	94.2142
2880.79	97.3313
2883.42	101.097
2886.05	104.281
2888.67	108.305
2891.3	111.812
2893.92	114.364
2896.55	118.847
2899.17	123.728
2901.79	128.318
2904.42	134.475
2907.04	142.481
2909.66	150.939
2912.27	159.629
2914.89	167.751
2917.51	175.258
2920.13	183.913
2922.74	190.226
2925.35	194.501
2927.97	198.129
2930.58	200.482
2933.19	201.867
2935.8	200.457
2938.41	198.301
2941.02	194.848
2943.63	191.191
2946.24	186.421
2948.84	180.135
2951.45	173.206
2954.05	166.158
2956.65	158.212
2959.26	150.283
2961.86	144.002
2964.46	137.156
2967.06	129.724
2969.66	123.418
2972.25	116.373
2974.85	109.01
2977.45	102.246
2980.04	94.2222
2982.64	87.6424
2985.23	80.1976
2987.82	72.5577
2990.41	65.1953
2993	57.6884
2995.59	51.0006
2998.18	43.0002
3000.77	35.8493
3003.36	30.1107
3005.94	25.3641
3008.53	20.0838
3011.11	14.9193
3013.69	11.3495
3016.28	9.65123
3018.86	7.17947
3021.44	4.59309
3024.02	3.75807
3026.6	2.0304
3029.18	0.917362
3031.75	0.636619
3034.33	0.859898
3036.9	1.22906
3039.48	2.40718
3042.05	3.14127
3044.62	4.03847
3047.19	5.55417
3049.77	7.21188
3052.34	7.84751
3054.9	7.68128
3057.47	8.25194
3060.04	8.33054
3062.61	7.13855
3065.17	6.70242
3067.74	6.58165
3070.3	6.20442
3072.86	4.20664
3075.42	4.24733
3077.99	3.57806
3080.54	3.10952
3083.1	2.46653
3085.66	2.26743
3088.22	0.583851
3090.78	1.04854
3093.33	0.95794
3095.89	1.66583
3098.44	2.55883
3100.99	4.0154
3103.54	5.05807
3106.1	5.86123
3108.65	7.27167
3111.2	8.83139
3113.74	9.35428
3116.29	10.2874
3118.84	11.5363
3121.38	13.4479
3123.93	14.0127
3126.47	15.2919
3129.01	16.9562
3131.56	18.288
3134.1	19.4269
3136.64	22.0143
3139.18	24.2573
3141.72	26.265
3144.26	28.2558
3146.79	30.5977
3149.33	35.2585