File: data/Raman/poly_smoothed/Thy_00_07_25_1x_45s_532 nm_x100_100%_600 gr_mm_01.txt
#Acq. time (s)=	45
#Accumulations=	2
#Range (cm-¹)=	200...3150
#Windows=	2
#Auto scanning=	Off
#Autofocus=	Off
#Macrospot=	Off
#AutoExposure=	Off
#Spike filter=	Multiple accum.
#Delay time (s)=	0
#Binning=	1
#Readout mode=	Signal
#DeNoise=	Off
#ICS correction=	On
#Dark correction=	Off
#Inst. Process=	Off
#Detector Gain=	Best Dynamic Range
#Detector ADC=	20 kHz
#Detector temperature (°C)=	-69.85
#Instrument=	LabRAM HR Evol
#Detector=	Synapse
#Objective=	x100
#Grating=	600 gr/mm
#ND Filter=	100%
#Laser (nm)=	532
#Hole=	100.021
#Range=	Auto
#Laser Pol.=	No
#Raman. Pol.=	No
#Laser Pol. (°)=	-0.0007625
#Raman Pol. (°)=	89.9995
#Collection=	Microscope
#StageXY=	Marzhauser
#StageZ=	Marzhauser
#X (µm)=	9001.5
#Y (µm)=	-3061.6
#Z (µm)=	-55.2
#Full time(mm:ss)=	3:19
#Project=
#Sample=
#Site=
#Title=	Thy_00_07_25_2x_45s_532 nm_x100_100%_600 gr_mm
#Remark=
#Date=	28.06.2022 11:57
#Acquired=	28.06.2022 11:57:38
#Base:Fit=	10.08.2022 10:07:56
#Base:Sub=	10.08.2022 10:08:40
#Filter:Polynom=	16.08.2022 10:26:06
#AxisType[0]=Intens
#AxisUnit[0]=Cnt
#AxisType[1]=Spectr
#AxisUnit[1]=1/cm
200.407	38.8667
204.035	41.4694
207.665	41.0298
211.291	40.9219
214.916	39.9024
218.541	39.189
222.163	38.4734
225.785	35.7672
229.404	34.3388
233.022	34.1093
236.638	33.1713
240.255	30.5688
243.868	29.1583
247.48	26.3749
251.091	22.1713
254.702	20.5924
258.31	19.073
261.916	17.3452
265.521	16.587
269.125	13.3442
272.727	12.1285
276.328	9.41765
279.927	7.23648
283.525	5.92093
287.121	4.7001
290.716	3.90992
294.31	5.0791
297.9	6.62561
301.491	6.6985
305.081	8.38519
308.669	9.84623
312.256	10.8586
315.839	11.8784
319.423	13.816
323.006	15.3142
326.585	14.7827
330.165	15.9488
333.741	16.6891
337.318	15.7652
340.894	15.9533
344.466	15.8283
348.039	14.1122
351.608	13.492
355.176	11.2893
358.745	11.0153
362.31	8.73584
365.876	6.96215
369.439	7.00767
373	6.0104
376.56	6.19351
380.12	6.30565
383.677	5.51802
387.233	6.20813
390.787	7.10409
394.34	6.08233
397.894	5.42686
401.444	4.26013
404.993	4.23219
408.54	6.43881
412.086	5.46916
415.631	6.55307
419.174	6.91954
422.716	6.29599
426.257	5.70465
429.794	6.51109
433.332	5.27381
436.868	4.02777
440.403	3.71023
443.937	5.34164
447.468	5.79201
450.999	5.72283
454.528	7.1451
458.057	8.94929
461.582	12.4122
465.107	13.4517
468.629	15.3703
472.152	17.6084
475.672	19.3973
479.192	21.207
482.709	22.9988
486.226	25.4535
489.74	27.253
493.255	29.3318
496.767	29.0682
500.277	29.1877
503.788	29.9349
507.295	28.6755
510.801	27.9591
514.308	26.0809
517.811	24.3396
521.313	21.5628
524.814	19.949
528.313	19.5286
531.811	15.6411
535.308	13.2737
538.803	12.056
542.297	12.8823
545.789	12.0826
549.281	11.5888
552.771	10.8208
556.259	11.005
559.747	10.5365
563.233	11.1309
566.717	11.0291
570.2	10.4925
573.68	10.1468
577.161	8.62904
580.64	7.68017
584.118	7.95269
587.593	7.2653
591.068	7.27075
594.54	5.98405
598.013	4.53305
601.484	3.18776
604.952	3.23446
608.421	2.68587
611.886	2.47281
615.35	0.0577048
618.815	-0.417127
622.276	0.657866
625.738	1.55905
629.197	2.90044
632.655	4.86492
636.113	6.64523
639.568	8.74631
643.021	9.92027
646.473	10.5883
649.924	12.5602
653.376	14.4798
656.824	16.1205
660.271	18.0346
663.716	19.3589
667.161	20.3186
670.604	22.3936
674.045	22.9217
677.486	24.9808
680.925	25.5447
684.361	27.0059
687.797	28.9019
691.232	30.0859
694.666	32.151
698.099	32.6498
701.528	33.0705
704.958	33.9664
708.387	36.2662
711.814	37.1177
715.238	39.8249
718.663	41.6907
722.084	43.2122
725.506	44.1544
728.925	46.8373
732.345	49.326
735.761	52.0895
739.178	56.7018
742.592	59.3784
746.006	62.8329
749.417	66.9402
752.827	71.3054
756.236	76.4636
759.645	79.2863
763.051	81.7987
766.456	82.9013
769.859	84.8703
773.261	85.9198
776.664	87.5281
780.064	87.4541
783.462	88.0402
786.859	87.2091
790.255	86.215
793.649	86.5695
797.042	85.5018
800.434	85.0719
803.823	84.5053
807.212	83.5127
810.6	82.2891
813.987	83.3616
817.372	85.2048
820.754	87.6916
824.137	89.2959
827.519	90.002
830.897	92.8507
834.276	95.0314
837.654	96.3685
841.029	95.539
844.404	93.7443
847.776	92.9785
851.149	91.6851
854.519	90.6938
857.889	87.9048
861.256	85.5333
864.622	82.9523
867.988	81.6552
871.351	78.3656
874.713	75.9936
878.074	73.4763
881.435	70.5534
884.794	68.3567
888.15	65.3816
891.506	62.3855
894.861	62.3342
898.214	63.001
901.566	63.4479
904.916	63.652
908.266	65.7126
911.614	66.7476
914.961	68.2913
918.306	68.9533
921.651	69.4286
924.994	69.649
928.336	68.5673
931.674	67.7663
935.014	64.629
938.352	62.6694
941.687	61.2334
945.022	60.6904
948.357	59.5824
951.688	57.7769
955.02	56.5848
958.348	52.0947
961.678	47.7293
965.004	46.8342
968.331	47.2185
971.655	46.5476
974.979	48.0326
978.3	48.8601
981.62	49.2942
984.941	50.1438
988.259	51.5115
991.575	52.0941
994.89	52.6566
998.204	53.9572
1001.52	55.1363
1004.83	55.7496
1008.14	55.038
1011.45	55.9261
1014.76	53.9728
1018.06	54.7214
1021.37	53.2991
1024.67	53.3775
1027.97	52.0396
1031.27	49.0231
1034.57	46.4456
1037.87	42.8151
1041.17	38.8212
1044.47	40.4457
1047.76	41.9948
1051.06	40.0887
1054.35	40.6871
1057.64	40.898
1060.93	40.1709
1064.22	39.8691
1067.5	39.3664
1070.79	41.0103
1074.08	41.1124
1077.36	43.0148
1080.64	44.302
1083.92	45.0281
1087.2	46.0898
1090.48	46.5186
1093.76	47.7317
1097.03	47.3462
1100.31	46.9897
1103.58	45.8547
1106.85	45.2385
1110.12	43.2722
1113.39	40.4558
1116.66	38.6487
1119.93	36.6211
1123.19	35.6808
1126.46	35.1093
1129.72	32.9396
1132.98	29.7147
1136.24	28.41
1139.5	26.395
1142.76	24.4214
1146.01	22.7196
1149.27	20.8543
1152.53	19.8151
1155.78	16.0902
1159.03	13.6126
1162.28	11.0275
1165.53	9.16223
1168.78	8.89383
1172.02	9.61609
1175.27	10.6464
1178.51	11.1269
1181.76	11.475
1185	13.5214
1188.24	14.1991
1191.48	15.6168
1194.71	16.7327
1197.95	17.7681
1201.19	21.7789
1204.42	24.4556
1207.65	27.0425
1210.88	30.6958
1214.12	35.1821
1217.35	39.1249
1220.57	41.3798
1223.8	44.8569
1227.03	46.7888
1230.25	48.1563
1233.47	48.2374
1236.69	47.3586
1239.92	47.8382
1243.13	48.4271
1246.35	49.4755
1249.57	49.8268
1252.78	51.0749
1256	48.9931
1259.21	47.1288
1262.42	46.9031
1265.63	45.6047
1268.84	44.4452
1272.05	44.3841
1275.26	44.3666
1278.46	45.2684
1281.67	46.7716
1284.87	48.6304
1288.07	50.1359
1291.27	52.7967
1294.47	53.9225
1297.67	54.8445
1300.87	59.1274
1304.06	61.273
1307.26	64.1971
1310.45	65.5927
1313.64	68.6899
1316.83	70.9686
1320.02	72.4331
1323.21	73.7906
1326.4	74.5542
1329.59	74.7403
1332.77	74.6622
1335.95	74.1431
1339.14	74.6625
1342.32	73.1048
1345.5	71.7115
1348.67	71.036
1351.85	68.8127
1355.03	66.2326
1358.2	63.0279
1361.38	61.0414
1364.55	58.4998
1367.72	56.4416
1370.89	54.276
1374.06	51.4686
1377.23	50.4526
1380.39	49.0603
1383.56	46.5997
1386.72	45.7718
1389.89	45.3402
1393.05	43.493
1396.21	41.9608
1399.37	41.2968
1402.52	40.1419
1405.68	38.5074
1408.84	39.7297
1411.99	42.0821
1415.15	43.4411
1418.3	45.4879
1421.45	48.6653
1424.6	52.71
1427.75	55.5399
1430.89	59.2167
1434.04	64.6149
1437.18	70.0008
1440.33	73.8873
1443.47	76.742
1446.61	78.8981
1449.75	80.4053
1452.89	80.9064
1456.03	80.5389
1459.16	77.8274
1462.3	75.0284
1465.43	72.2184
1468.56	66.1754
1471.7	59.5905
1474.83	51.7982
1477.96	45.8538
1481.08	39.1203
1484.21	33.0586
1487.34	28.5252
1490.46	23.3591
1493.58	20.4392
1496.71	17.3196
1499.83	15.3492
1502.95	13.645
1506.07	12.7773
1509.18	12.2796
1512.3	12.1665
1515.41	12.2625
1518.53	13.1111
1521.64	15.1412
1524.75	16.3959
1527.86	19.0002
1530.97	20.0778
1534.08	22.6375
1537.19	24.07
1540.29	25.8765
1543.4	26.8512
1546.5	29.0532
1549.6	31.2694
1552.7	33.5129
1555.8	37.1084
1558.9	38.9258
1562	40.9839
1565.09	43.9938
1568.19	46.9789
1571.28	49.0061
1574.37	50.7492
1577.47	52.5219
1580.56	55.4075
1583.64	56.5844
1586.73	58.4983
1589.82	60.986
1592.9	63.4749
1595.99	63.6469
1599.07	64.6866
1602.15	63.6651
1605.23	63.6048
1608.31	62.7151
1611.39	63.718
1614.47	61.8266
1617.55	60.551
1620.62	60.6728
1623.7	61.1958
1626.77	61.8251
1629.84	63.9133
1632.91	66.954
1635.98	68.6309
1639.05	72.0216
1642.11	75.1171
1645.18	78.2468
1648.24	81.4049
1651.31	84.3043
1654.37	86.3061
1657.43	86.4718
1660.49	86.9745
1663.55	87.299
1666.61	86.0817
1669.66	82.8183
1672.72	79.329
1675.77	74.5445
1678.83	68.6365
1681.88	61.9552
1684.93	56.6733
1687.98	49.7059
1691.03	43.1061
1694.07	37.4687
1697.12	32.7166
1700.17	29.5208
1703.21	26.0223
1706.25	23.0672
1709.29	21.7642
1712.33	20.5041
1715.37	18.899
1718.41	17.5296
1721.45	15.1315
1724.49	14.3504
1727.52	12.3725
1730.55	11.1902
1733.59	10.1974
1736.62	10.8913
1739.65	9.99257
1742.68	8.71804
1745.7	6.81363
1748.73	6.03235
1751.76	4.64368
1754.78	3.55315
1757.8	2.47773
1760.83	2.60335
1763.85	1.68516
1766.87	1.4989
1769.89	2.22136
1772.9	1.92802
1775.92	1.58461
1778.94	2.1535
1781.95	2.75684
1784.96	2.83093
1787.97	2.09685
1790.99	1.65097
1794	0.619627
1797	0.0449358
1800.01	1.07518
1803.02	1.39007
1806.02	1.57614
1809.03	1.22195
1812.03	2.03493
1815.03	2.49427
1818.03	2.4295
1821.03	3.39744
1824.03	3.42976
1827.03	2.88482
1830.02	2.12925
1833.02	1.98702
1836.01	2.3722
1839.01	1.95289
1842	1.75886
1844.99	1.99057
1847.98	2.08968
1850.97	1.46945
1853.95	1.45361
1856.94	1.35221
1859.93	1.60585
1862.91	1.6635
1865.89	1.56909
1868.87	1.66397
1871.85	2.25242
1874.83	2.56675
1877.81	2.8068
1880.79	2.48344
1882.52	3.16416
1885.51	3.75038
1888.5	3.89201
1891.49	4.66116
1894.47	3.97032
1897.46	3.96424
1900.44	3.56678
1903.42	5.27691
1906.4	5.84401
1909.38	6.47731
1912.36	6.09662
1915.34	5.52868
1918.32	6.32733
1921.29	6.73161
1924.27	7.25397
1927.24	7.42304
1930.21	7.28707
1933.18	6.99533
1936.15	6.66016
1939.12	5.64573
1942.09	4.89362
1945.06	5.04761
1948.02	4.51832
1950.99	3.78273
1953.95	3.7619
1956.91	3.92664
1959.88	3.63392
1962.84	3.46926
1965.8	2.73381
1968.75	2.16307
1971.71	2.09874
1974.67	3.49258
1977.62	3.24867
1980.58	3.0794
1983.53	2.82221
1986.48	2.5414
1989.43	3.19182
1992.38	5.20685
1995.33	5.49712
1998.27	4.65263
2001.22	4.98947
2004.16	4.97265
2007.11	5.61952
2010.05	5.77697
2012.99	5.81803
2015.93	6.09004
2018.87	6.5261
2021.81	7.92291
2024.75	8.25596
2027.69	9.12488
2030.62	8.49135
2033.56	8.57203
2036.49	8.28247
2039.42	7.5471
2042.35	7.73864
2045.28	8.41778
2048.21	8.5366
2051.14	7.78387
2054.07	7.52425
2056.99	7.10165
2059.92	5.88395
2062.84	5.8417
2065.76	5.33364
2068.68	4.05911
2071.6	4.81768
2074.52	4.88146
2077.44	5.01676
2080.36	5.25577
2083.27	5.53068
2086.19	6.44401
2089.1	7.98751
2092.02	9.8599
2094.93	11.8681
2097.84	12.4261
2100.75	13.7194
2103.66	14.6861
2106.56	13.948
2109.47	14.0502
2112.38	14.1471
2115.28	13.2043
2118.18	12.4636
2121.09	10.1151
2123.99	8.60387
2126.89	6.99133
2129.79	5.71113
2132.68	5.0582
2135.58	4.55745
2138.48	3.79604
2141.37	2.80138
2144.27	2.27408
2147.16	1.78361
2150.05	1.93518
2152.94	1.83977
2155.83	3.01316
2158.72	3.7493
2161.6	4.40423
2164.49	6.05619
2167.38	6.15075
2170.26	7.60261
2173.14	8.60125
2176.03	8.53718
2178.91	8.49241
2181.79	8.98014
2184.67	8.83471
2187.54	9.10077
2190.42	8.37654
2193.3	7.66108
2196.17	8.13331
2199.05	9.50699
2201.92	8.47546
2204.79	9.25201
2207.66	9.32551
2210.53	8.43553
2213.4	7.63398
2216.27	7.21325
2219.13	7.87045
2222	7.73239
2224.86	7.74823
2227.72	7.2695
2230.59	7.14775
2233.45	7.45006
2236.31	7.59701
2239.17	6.96952
2242.03	6.58188
2244.88	6.45862
2247.74	6.39903
2250.59	6.00376
2253.45	5.84187
2256.3	5.70493
2259.15	6.14046
2262	5.70463
2264.85	6.25277
2267.7	6.69009
2270.55	6.42321
2273.4	6.21121
2276.24	6.48217
2279.09	5.97449
2281.93	6.08731
2284.77	5.78213
2287.62	6.34402
2290.46	5.72542
2293.3	4.67881
2296.13	5.13488
2298.97	5.42724
2301.81	6.40428
2304.64	6.84252
2307.48	6.0146
2310.31	6.44698
2313.14	7.56417
2315.98	8.29497
2318.81	8.72284
2321.64	8.70293
2324.46	9.31246
2327.29	9.94917
2330.12	10.1045
2332.94	9.92238
2335.77	10.1206
2338.59	9.03654
2341.41	7.75672
2344.23	7.02585
2347.05	5.33336
2349.87	4.32848
2352.69	3.09642
2355.51	2.95939
2358.32	1.74029
2361.14	0.43127
2363.95	0.27514
2366.76	0.232051
2369.58	0.526189
2372.39	0.261218
2375.2	-0.720677
2378	-0.977344
2380.81	-0.148458
2383.62	0.282438
2386.43	0.904596
2389.23	1.01488
2392.03	0.562605
2394.84	0.296304
2397.64	0.767291
2400.44	1.30733
2403.24	1.99886
2406.04	3.46139
2408.84	4.77856
2411.63	5.04204
2414.43	5.80288
2417.22	6.88627
2420.02	7.26905
2422.81	8.93904
2425.6	9.64131
2428.39	10.0615
2431.18	10.9696
2433.97	10.324
2436.76	10.4357
2439.54	10.2708
2442.33	8.74236
2445.12	7.69971
2447.9	7.43322
2450.68	6.3488
2453.46	5.65538
2456.24	4.37555
2459.02	2.22908
2461.8	1.09848
2464.58	0.332574
2467.36	0.392954
2470.13	0.711478
2472.91	1.30092
2475.68	1.32821
2478.45	-0.366881
2481.23	-1.26533
2484	0.13669
2486.77	-0.179043
2489.54	0.459101
2492.3	1.34359
2495.07	0.656669
2497.84	1.2565
2500.6	1.06041
2503.36	0.60613
2506.13	0.906554
2508.89	0.792409
2511.65	0.610805
2514.41	0.590066
2517.17	0.806897
2519.93	1.32116
2522.68	1.40928
2525.44	2.32894
2528.19	3.11717
2530.95	3.35979
2533.7	3.76361
2536.45	4.45248
2539.2	5.16685
2541.95	4.53026
2544.7	3.62774
2547.45	3.34742
2550.2	5.24812
2552.94	5.00398
2555.69	4.98239
2558.43	5.24405
2561.18	5.37014
2563.92	5.76306
2566.66	6.13579
2569.4	6.27352
2572.14	6.57012
2574.88	5.94634
2577.61	6.79644
2580.35	7.12396
2583.09	6.93058
2585.82	7.25056
2588.55	7.84422
2591.29	8.27493
2594.02	8.54813
2596.75	8.17651
2599.48	8.14234
2602.21	8.16224
2604.93	7.38444
2607.66	6.85373
2610.39	5.34873
2613.11	5.11156
2615.83	4.90736
2618.56	5.18894
2621.28	4.22597
2624	4.92705
2626.72	5.22432
2629.44	4.87288
2632.15	5.18617
2634.87	4.43464
2637.59	3.95976
2640.3	4.15465
2643.02	4.88859
2645.73	5.46379
2648.44	4.67118
2651.15	4.63671
2653.86	6.02315
2656.57	5.67307
2659.28	5.75244
2661.99	5.59739
2664.69	5.29876
2667.4	4.49273
2670.1	3.86239
2672.81	3.91874
2675.51	4.30665
2678.21	3.76815
2680.91	4.31148
2683.61	4.60442
2686.31	4.52368
2689	4.35692
2691.7	4.82439
2694.4	5.39733
2697.09	5.7371
2699.79	6.83386
2702.48	7.27337
2705.17	8.55538
2707.86	10.6984
2710.55	11.4472
2713.24	12.8832
2715.93	13.6089
2718.62	14.5544
2721.3	15.1719
2723.99	15.2823
2726.67	16.2321
2729.35	15.6132
2732.04	15.7957
2734.72	15.5837
2737.4	14.9023
2740.08	14.7873
2742.76	14.4065
2745.43	12.7849
2748.11	11.7691
2750.79	9.55375
2753.46	8.75482
2756.14	8.09347
2758.81	7.3409
2761.48	7.42052
2764.15	6.55481
2766.82	5.95409
2769.49	4.3355
2772.16	3.41825
2774.82	3.00094
2777.49	2.04773
2780.16	1.90677
2782.82	2.31609
2785.48	2.62661
2788.15	2.56397
2790.81	2.58394
2793.47	2.80091
2796.13	2.45396
2798.79	2.05105
2801.44	1.89779
2804.1	1.61562
2806.76	1.6177
2809.41	1.18306
2812.07	1.41149
2814.72	2.20876
2817.37	4.19137
2820.02	6.93245
2822.67	10.1541
2825.32	14.365
2827.97	17.4077
2830.62	21.2036
2833.26	25.3962
2835.91	30.452
2838.56	36.6743
2841.2	44.2184
2843.84	53.4726
2846.48	63.5516
2849.12	73.9823
2851.77	84.9901
2854.4	97.2447
2857.04	109.249
2859.68	122.109
2862.32	135.264
2864.95	145.851
2867.59	155.882
2870.22	166.193
2872.85	177.003
2875.48	185.713
2878.11	194.671
2880.74	203.685
2883.37	210.902
2886	218.939
2888.63	226.653
2891.25	234.039
2893.88	241.82
2896.5	249.006
2899.13	256.508
2901.75	265.944
2904.37	275.006
2906.99	286.01
2909.61	296.656
2912.23	309.108
2914.85	321.913
2917.46	334.496
2920.08	344.512
2922.7	352.77
2925.31	358.032
2927.92	360.562
2930.54	359.937
2933.15	358.024
2935.76	354.722
2938.37	346.787
2940.98	338.262
2943.58	327.436
2946.19	315.775
2948.8	304.436
2951.4	291.961
2954.01	279.645
2956.61	265.912
2959.21	252.131
2961.81	237.507
2964.41	225.279
2967.01	212.459
2969.61	200.436
2972.21	190.547
2974.81	181.312
2977.4	173.075
2980	162.442
2982.59	151.342
2985.18	140.629
2987.78	128.745
2990.37	116.58
2992.96	105.398
2995.55	93.8853
2998.14	82.6843
3000.73	72.2933
3003.31	63.2616
3005.9	53.5687
3008.48	45.0805
3011.07	38.649
3013.65	32.0782
3016.23	25.9993
3018.81	20.6532
3021.4	15.9628
3023.97	12.2996
3026.55	9.95763
3029.13	6.77181
3031.71	5.04805
3034.28	5.45699
3036.86	6.4149
3039.43	7.68334
3042.01	8.28755
3044.58	9.24186
3047.15	10.5793
3049.72	11.5648
3052.29	12.1472
3054.86	12.8067
3057.43	12.8084
3060	13.2691
3062.56	12.9435
3065.13	11.9157
3067.69	11.3351
3070.26	9.76054
3072.82	9.06731
3075.38	7.82615
3077.94	5.64981
3080.5	4.80041
3083.06	2.70188
3085.62	0.869119
3088.18	-0.71169
3090.73	-1.81647
3093.29	-1.54895
3095.84	-0.500636
3098.4	0.0152306
3100.95	0.232166
3103.5	0.830945
3106.05	1.19071
3108.6	1.07463
3111.15	2.0117
3113.7	3.36965
3116.25	4.27693
3118.79	4.60397
3121.34	6.14698
3123.88	6.92848
3126.43	7.8301
3128.97	9.34738
3131.51	10.1976
3134.06	11.6822
3136.6	12.8448
3139.14	14.484
3141.67	15.9102
3144.21	17.5084
3146.75	19.9099
3149.29	22.7219