File: data/Raman/poly_smoothed/Thy_30_10_18_1x_45s_532 nm_x100_100%_600 gr_mm_01.txt
#Acq. time (s)=	45
#Accumulations=	2
#Range (cm-¹)=	200...3150
#Windows=	2
#Auto scanning=	Off
#Autofocus=	Off
#Macrospot=	Off
#AutoExposure=	Off
#Spike filter=	Multiple accum.
#Delay time (s)=	0
#Binning=	1
#Readout mode=	Signal
#DeNoise=	Off
#ICS correction=	On
#Dark correction=	Off
#Inst. Process=	Off
#Detector Gain=	Best Dynamic Range
#Detector ADC=	20 kHz
#Detector temperature (°C)=	-69.85
#Instrument=	LabRAM HR Evol
#Detector=	Synapse
#Objective=	x100
#Grating=	600 gr/mm
#ND Filter=	100%
#Laser (nm)=	532
#Hole=	100.021
#Range=	Auto
#Laser Pol.=	No
#Raman. Pol.=	No
#Laser Pol. (°)=	-0.0007625
#Raman Pol. (°)=	89.9995
#Collection=	Microscope
#StageXY=	Marzhauser
#StageZ=	Marzhauser
#X (µm)=	4764.1
#Y (µm)=	-7727.4
#Z (µm)=	584.8
#Full time(mm:ss)=	3:18
#Project=
#Sample=
#Site=
#Title=	Thy_30_10_18_2x_45s_532 nm_x100_100%_600 gr_mm
#Remark=
#Date=	30.06.2022 12:45
#Acquired=	30.06.2022 12:45:40
#Base:Fit=	10.08.2022 09:58:11
#Base:Sub=	10.08.2022 09:58:44
#Filter:Polynom=	16.08.2022 10:22:53
#AxisType[0]=Intens
#AxisUnit[0]=Cnt
#AxisType[1]=Spectr
#AxisUnit[1]=1/cm
200.533	14.199
204.162	14.1076
207.792	14.7649
211.418	14.1376
215.044	12.1442
218.667	10.8139
222.289	10.8501
225.912	10.0173
229.531	9.00645
233.148	7.40253
236.766	6.9608
240.381	6.86738
243.994	6.94226
247.606	7.62144
251.217	6.87265
254.828	7.17626
258.436	7.2493
262.042	9.00648
265.647	8.44119
269.25	8.8042
272.852	8.17611
276.453	7.6808
280.052	7.6494
283.65	6.81251
287.247	8.53272
290.842	8.50869
294.436	8.08258
298.028	9.73196
301.617	9.79947
305.206	11.6012
308.794	13.9134
312.381	14.7694
315.964	15.7654
319.548	16.1422
323.131	17.3247
326.71	18.4366
330.29	21.4365
333.868	21.3504
337.443	22.1873
341.018	22.1138
344.591	23.7276
348.163	24.1306
351.733	21.951
355.303	19.3278
358.869	17.8065
362.435	15.9526
366.001	13.4435
369.563	11.3737
373.124	11.0257
376.686	10.0461
380.244	9.8043
383.801	9.86346
387.357	10.2628
390.911	9.39312
394.466	8.76668
398.018	7.9386
401.568	7.09922
405.117	5.86407
408.664	5.82553
412.21	6.56549
415.755	7.08559
419.298	6.16981
422.84	6.46292
426.38	7.11636
429.919	6.98195
433.455	7.30589
436.992	7.2883
440.527	7.21545
444.06	8.19302
447.593	9.24718
451.122	9.89163
454.651	11.0291
458.18	11.397
461.705	12.2737
465.23	13.4338
468.752	15.3399
472.275	17.2685
475.797	17.8264
479.315	16.4127
482.834	17.6457
486.349	18.691
489.863	19.2912
493.378	21.0759
496.889	22.2844
500.401	21.9336
503.91	22.5594
507.417	21.411
510.923	21.6027
514.43	21.5727
517.933	20.1076
521.435	19.0601
524.936	17.9782
528.435	19.4712
531.933	18.7742
535.43	18.4592
538.927	17.2072
542.421	15.1734
545.913	14.1453
549.403	13.6119
552.893	11.7853
556.381	10.9656
559.868	9.71089
563.354	7.42753
566.839	6.97938
570.322	8.48822
573.802	6.96855
577.283	5.50855
580.762	4.75
584.24	2.74445
587.714	3.11219
591.19	2.35062
594.663	1.38841
598.134	0.557219
601.605	0.24759
605.073	0.72561
608.542	1.41057
612.007	3.90525
615.473	3.72994
618.936	3.736
622.397	3.52143
625.859	3.0815
629.318	5.51399
632.775	5.62668
636.233	5.63876
639.688	5.28525
643.142	6.66349
646.594	6.58187
650.045	8.83013
653.496	10.1564
656.944	10.1905
660.391	10.9369
663.837	14.7068
667.281	16.5868
670.724	18.3684
674.166	20.0782
677.606	20.8294
681.045	20.2303
684.483	22.5984
687.917	25.2368
691.352	26.4217
694.786	27.0191
698.219	27.4277
701.65	28.6648
705.078	29.7448
708.506	30.1626
711.934	31.0018
715.358	31.6378
718.782	30.9311
722.204	30.9729
725.626	31.3567
729.045	32.5097
732.464	34.0015
735.881	35.2766
739.297	37.5987
742.711	40.7137
746.125	44.5527
749.537	48.7434
752.946	50.4487
756.357	52.6625
759.764	54.968
763.17	56.6881
766.575	60.2264
769.978	65.4
773.382	67.5503
776.783	69.8142
780.182	72.2368
783.581	73.5297
786.978	74.2425
790.373	76.3972
793.768	77.6542
797.161	77.5253
800.552	78.0078
803.941	77.2659
807.33	77.1443
810.718	76.6178
814.105	77.4817
817.49	77.0235
820.873	79.0635
824.256	78.4164
827.637	79.3833
831.016	79.1335
834.395	77.6278
837.772	76.21
841.147	75.2722
844.522	75.2371
847.894	74.2201
851.267	74.0591
854.637	71.0667
858.007	66.4206
861.374	63.6549
864.739	59.5501
868.106	56.2594
871.469	53.0254
874.831	52.7728
878.193	50.6273
881.553	49.7022
884.911	47.4087
888.268	46.5066
891.623	46.2951
894.978	46.4487
898.331	47.0616
901.683	47.2525
905.033	47.6203
908.383	47.6368
911.731	47.5359
915.078	46.5893
918.423	46.4558
921.768	47.2183
925.111	48.0854
928.452	48.0062
931.791	46.8346
935.13	44.8951
938.468	41.8801
941.803	40.9072
945.139	40.793
948.473	39.959
951.804	40.0024
955.136	41.2173
958.465	42.2604
961.794	40.5517
965.12	41.3932
968.447	41.0701
971.771	41.8083
975.095	40.3037
978.417	40.4254
981.737	39.9321
985.057	37.7401
988.375	36.5924
991.691	35.2268
995.006	34.0655
998.32	34.0955
1001.63	33.2922
1004.95	33.4647
1008.26	32.549
1011.56	32.4907
1014.87	31.5183
1018.18	29.9489
1021.48	29.9456
1024.79	30.9978
1028.09	30.9623
1031.39	31.212
1034.69	31.6062
1037.99	30.6624
1041.29	29.6435
1044.58	30.081
1047.88	28.7679
1051.17	27.5983
1054.46	26.2809
1057.75	24.7425
1061.04	24.196
1064.33	23.3565
1067.62	21.3518
1070.9	21.0045
1074.19	19.95
1077.47	20.4498
1080.76	19.9532
1084.04	17.8437
1087.32	16.0778
1090.59	16.4209
1093.87	15.9206
1097.15	16.1367
1100.42	16.1703
1103.69	16.1554
1106.97	15.7282
1110.24	15.4386
1113.51	15.113
1116.77	14.8973
1120.04	14.6117
1123.31	13.0913
1126.57	12.6259
1129.83	12.1912
1133.1	12.5504
1136.36	10.3347
1139.62	8.36869
1142.87	8.53269
1146.13	7.05656
1149.38	5.12017
1152.64	4.84205
1155.89	4.04965
1159.14	3.14809
1162.39	1.24004
1165.64	0.514485
1168.89	1.08004
1172.14	3.23346
1175.38	3.96852
1178.63	4.56547
1181.87	5.27212
1185.11	7.37799
1188.35	8.14208
1191.59	10.3613
1194.83	12.4194
1198.07	13.3833
1201.3	15.2523
1204.53	17.3961
1207.77	19.7725
1211	22.7651
1214.23	24.9463
1217.46	28.1998
1220.69	31.5248
1223.91	33.3131
1227.14	35.4902
1230.36	38.2618
1233.59	40.6325
1236.81	41.8012
1240.03	43.8211
1243.25	46.5312
1246.46	47.5144
1249.68	49.1775
1252.9	50.8652
1256.11	51.8894
1259.32	52.7259
1262.54	52.5902
1265.75	53.5185
1268.96	53.2125
1272.16	54.3319
1275.37	55.3654
1278.57	57.124
1281.78	59.5011
1284.98	61.9714
1288.18	63.6508
1291.38	65.2324
1294.58	65.6217
1297.78	66.7859
1300.98	67.0427
1304.17	67.0601
1307.37	68.0208
1310.56	67.8474
1313.76	67.9479
1316.95	67.8054
1320.14	68.1966
1323.32	66.486
1326.51	64.749
1329.7	62.9198
1332.88	61.424
1336.07	58.5456
1339.25	56.2303
1342.43	53.1648
1345.61	50.4867
1348.79	49.5366
1351.96	47.7876
1355.14	46.7823
1358.31	45.5832
1361.49	44.8837
1364.66	42.1856
1367.83	40.808
1371	41.717
1374.17	40.1682
1377.34	40.227
1380.5	38.8696
1383.67	39.1203
1386.83	37.814
1390	35.4923
1393.16	33.3144
1396.32	32.759
1399.48	30.821
1402.64	29.0361
1405.79	28.3483
1408.95	27.4234
1412.1	26.5553
1415.26	26.8822
1418.41	27.5036
1421.56	28.2795
1424.71	32.6562
1427.86	36.7976
1431	39.8056
1434.15	43.1671
1437.29	46.6556
1440.44	50.1037
1443.58	52.8886
1446.72	56.7166
1449.86	56.8201
1453	56.5497
1456.14	56.7417
1459.27	54.5368
1462.41	52.3826
1465.54	47.1214
1468.67	42.4565
1471.81	37.7219
1474.94	34.1737
1478.07	28.8549
1481.19	24.1538
1484.32	19.9376
1487.45	16.8627
1490.57	12.6981
1493.69	10.6486
1496.82	8.93544
1499.94	8.4143
1503.06	9.23704
1506.17	8.31552
1509.29	7.83533
1512.41	8.83262
1515.52	10.0048
1518.64	10.4705
1521.75	11.2301
1524.86	12.1849
1527.97	13.0461
1531.08	15.0909
1534.19	16.0639
1537.29	16.3638
1540.4	18.31
1543.5	19.2245
1546.61	21.8278
1549.71	24.0078
1552.81	26.1695
1555.91	28.1727
1559.01	30.2353
1562.11	31.8499
1565.2	33.5742
1568.29	35.4945
1571.39	39.8705
1574.48	41.9213
1577.57	45.494
1580.66	48.247
1583.75	48.9068
1586.84	51.0248
1589.93	52.6306
1593.01	52.0301
1596.1	52.4509
1599.18	51.1883
1602.26	51.2092
1605.34	49.9054
1608.42	49.9712
1611.5	48.6926
1614.58	48.8669
1617.65	49.5291
1620.73	49.7975
1623.8	51.3269
1626.87	51.8511
1629.95	54.425
1633.02	55.6616
1636.09	58.0982
1639.15	59.9498
1642.22	63.5878
1645.29	66.2192
1648.35	69.7401
1651.42	71.2944
1654.48	74.3418
1657.54	74.4848
1660.6	73.9994
1663.66	73.4854
1666.72	71.5264
1669.77	69.1869
1672.83	66.0536
1675.88	62.0115
1678.93	58.2252
1681.99	52.7847
1685.04	48.2765
1688.09	43.4025
1691.13	38.4543
1694.18	34.6434
1697.23	29.3155
1700.27	25.3605
1703.32	22.1907
1706.36	18.5578
1709.4	16.2477
1712.44	14.1844
1715.48	11.7302
1718.52	11.1071
1721.56	9.2058
1724.59	8.76153
1727.63	8.12606
1730.66	7.12368
1733.69	5.30758
1736.72	5.07705
1739.75	4.11473
1742.78	3.83558
1745.81	3.49241
1748.84	2.24464
1751.86	2.38156
1754.89	1.80021
1757.91	1.5083
1760.93	1.31389
1763.95	0.272873
1766.97	0.489583
1769.99	-0.717209
1773.01	-0.530703
1776.03	0.672657
1779.04	0.414756
1782.06	0.593628
1785.07	0.953925
1788.08	0.915785
1791.09	1.06553
1794.1	1.96246
1797.11	2.31406
1800.12	3.04684
1803.12	2.96534
1806.13	2.62921
1809.13	2.88332
1812.14	3.05443
1815.14	2.66396
1818.14	3.64851
1821.14	3.89955
1824.14	4.37854
1827.13	4.8039
1830.13	5.8169
1833.12	6.47307
1836.12	6.74483
1839.11	6.94023
1842.1	6.58075
1845.09	6.93936
1848.08	7.98425
1851.07	7.01922
1854.06	6.63826
1857.04	6.77911
1860.03	7.48442
1863.01	7.70766
1866	9.16025
1868.98	10.6665
1871.96	11.3842
1874.94	11.5096
1877.92	11.9717
1880.89	11.2481
1882.48	11.3176
1885.47	12.4191
1888.46	12.5537
1891.44	12.4084
1894.43	13.1227
1897.41	12.7227
1900.4	12.4859
1903.38	12.434
1906.36	12.1822
1909.34	11.7591
1912.32	11.6733
1915.29	11.1896
1918.27	11.0074
1921.25	10.3757
1924.22	9.36778
1927.2	9.54892
1930.17	10.1198
1933.14	10.564
1936.11	10.7728
1939.08	11.7549
1942.05	12.6078
1945.01	12.5957
1947.98	12.8319
1950.94	13.4634
1953.91	14.2564
1956.87	15.7921
1959.83	15.9447
1962.79	15.3523
1965.75	15.7464
1968.71	15.5913
1971.67	16.015
1974.62	16.5992
1977.58	16.5572
1980.53	16.5054
1983.48	16.5115
1986.43	16.2758
1989.38	15.3293
1992.33	16.0045
1995.28	16.0743
1998.23	14.7962
2001.18	15.6749
2004.12	15.6082
2007.06	14.4667
2010.01	13.8195
2012.95	13.8529
2015.89	13.9938
2018.83	13.8046
2021.77	13.8483
2024.71	14.4299
2027.64	14.7104
2030.58	15.7324
2033.51	16.2911
2036.45	16.5155
2039.38	17.4946
2042.31	19.0692
2045.24	19.546
2048.17	20.8058
2051.1	21.8877
2054.02	22.1858
2056.95	22.5465
2059.87	22.5266
2062.8	22.6404
2065.72	22.8186
2068.64	23.5727
2071.56	22.4802
2074.48	22.013
2077.4	22.3921
2080.31	22.4473
2083.23	22.5681
2086.14	22.6053
2089.06	22.9109
2091.97	23.7005
2094.88	23.6979
2097.79	25.1141
2100.7	25.8464
2103.61	28.1097
2106.52	29.6391
2109.43	31.8431
2112.33	34.035
2115.24	36.9741
2118.14	39.0409
2121.04	42.2548
2123.94	44.2062
2126.84	45.6258
2129.74	48.7792
2132.64	50.6862
2135.54	53.425
2138.43	56.1379
2141.33	60.6872
2144.22	64.2856
2147.11	67.924
2150.01	69.9638
2152.9	71.2963
2155.79	72.8222
2158.67	74.1159
2161.56	75.7811
2164.45	77.1799
2167.33	78.3088
2170.22	79.0803
2173.1	80.6774
2175.98	81.6024
2178.86	81.3007
2181.74	79.3677
2184.62	78.7027
2187.5	77.4666
2190.38	75.3064
2193.25	72.2664
2196.13	70.3978
2199	68.1693
2201.88	65.5153
2204.75	63.3657
2207.62	61.0493
2210.49	59.1126
2213.36	57.2357
2216.22	54.1953
2219.09	49.6364
2221.96	46.6118
2224.82	44.0752
2227.68	41.7006
2230.55	39.8367
2233.41	37.79
2236.27	36.7512
2239.12	34.3373
2241.98	34.0149
2244.84	33.027
2247.7	31.7057
2250.55	30.3175
2253.41	29.2068
2256.26	28.4268
2259.11	26.4511
2261.96	25.5064
2264.81	25.4464
2267.66	25.4447
2270.51	24.181
2273.35	23.5272
2276.2	23.0686
2279.04	22.4175
2281.89	22.5973
2284.73	22.2615
2287.57	20.9657
2290.41	20.9416
2293.25	20.2754
2296.09	19.9007
2298.93	19.1054
2301.76	18.2718
2304.6	18.6139
2307.44	18.5682
2310.27	19.1258
2313.1	19.1691
2315.93	19.0168
2318.76	18.0728
2321.59	16.4975
2324.42	15.9266
2327.25	14.9804
2330.07	13.5975
2332.9	13.2951
2335.72	12.5796
2338.55	11.157
2341.37	10.0726
2344.19	8.56109
2347.01	7.6206
2349.83	7.36817
2352.65	7.13684
2355.46	5.06093
2358.28	4.87326
2361.09	4.70835
2363.91	4.74399
2366.72	5.63885
2369.53	4.78382
2372.34	5.01272
2375.15	4.98448
2377.96	6.79878
2380.77	7.2384
2383.58	6.70577
2386.38	7.00907
2389.19	7.89118
2391.99	8.29453
2394.8	8.90017
2397.6	8.44047
2400.4	8.37221
2403.2	8.26688
2406	8.13328
2408.79	7.45195
2411.59	6.86472
2414.39	6.11743
2417.18	6.37578
2419.98	6.08371
2422.77	6.52856
2425.56	6.76133
2428.35	7.85912
2431.14	7.76539
2433.93	6.96103
2436.72	5.38467
2439.5	4.99019
2442.29	4.3194
2445.07	5.05524
2447.86	5.35826
2450.64	5.63065
2453.42	5.41645
2456.2	6.40766
2458.98	6.22241
2461.76	6.21213
2464.54	5.80079
2467.32	5.41352
2470.09	5.52274
2472.87	4.62224
2475.64	3.76342
2478.41	2.76432
2481.18	2.45384
2483.95	2.79741
2486.72	3.05011
2489.49	4.1902
2492.26	4.27711
2495.03	3.91176
2497.79	4.20209
2500.56	3.03337
2503.32	1.77508
2506.09	1.66946
2508.85	2.16902
2511.61	2.56442
2514.37	3.59575
2517.13	3.84716
2519.89	3.60973
2522.64	3.78481
2525.4	3.90244
2528.15	3.40317
2530.91	3.80899
2533.66	3.40999
2536.41	3.14239
2539.16	2.6134
2541.91	2.55523
2544.66	3.3995
2547.41	3.9711
2550.16	5.15528
2552.9	4.92843
2555.65	4.80532
2558.39	4.98853
2561.13	4.62077
2563.88	4.50979
2566.62	4.30551
2569.36	4.00536
2572.1	2.84268
2574.84	3.42419
2577.57	3.73344
2580.31	2.91507
2583.05	2.33844
2585.78	1.78635
2588.51	0.77372
2591.24	0.0754207
2593.98	0.918353
2596.71	1.07396
2599.44	1.03452
2602.16	0.995501
2604.89	1.60759
2607.62	1.81558
2610.34	2.52561
2613.07	3.32257
2615.79	2.96767
2618.52	2.48971
2621.24	2.36563
2623.96	2.01376
2626.68	1.87055
2629.4	1.40148
2632.11	0.560088
2634.83	0.287641
2637.55	-1.15346
2640.26	-0.716752
2642.98	-0.0687665
2645.69	-0.386083
2648.4	-0.356004
2651.11	-0.147258
2653.82	0.604724
2656.53	0.69959
2659.24	1.87489
2661.95	2.73927
2664.65	3.08572
2667.36	3.91025
2670.06	3.38847
2672.76	4.38173
2675.47	4.33197
2678.17	3.55499
2680.87	3.64666
2683.57	3.09128
2686.27	3.96328
2688.97	3.70619
2691.66	2.94833
2694.36	2.7348
2697.05	2.15499
2699.75	1.82077
2702.44	1.87459
2705.13	1.61953
2707.82	2.47351
2710.51	3.37472
2713.2	3.96773
2715.89	5.0315
2718.57	5.2156
2721.26	5.98268
2723.95	5.95155
2726.63	5.98609
2729.31	6.19097
2732	5.80112
2734.68	4.86666
2737.36	5.41633
2740.04	4.91561
2742.72	4.72937
2745.39	4.84743
2748.07	4.5575
2750.75	4.23222
2753.42	4.75648
2756.09	4.07966
2758.77	3.8739
2761.44	3.51979
2764.11	2.52291
2766.78	2.31058
2769.45	1.66058
2772.12	2.17822
2774.78	2.12234
2777.45	1.45838
2780.12	1.65866
2782.78	1.95215
2785.44	1.77013
2788.11	1.09235
2790.77	1.4306
2793.43	1.665
2796.09	1.72128
2798.75	1.33318
2801.4	2.23148
2804.06	3.27436
2806.72	4.08339
2809.37	4.45136
2812.03	4.61566
2814.68	5.41501
2817.33	6.7054
2819.98	8.24799
2822.63	9.59301
2825.28	11.8032
2827.93	14.4038
2830.58	16.1961
2833.23	19.4329
2835.87	23.1504
2838.52	27.0472
2841.16	30.9909
2843.8	35.7471
2846.44	41.407
2849.08	47.609
2851.73	54.3588
2854.36	62.1683
2857	69.24
2859.64	76.746
2862.28	83.4
2864.91	90.3111
2867.55	96.5
2870.18	102.05
2872.81	106.888
2875.44	110.672
2878.07	114.858
2880.7	119.59
2883.33	124.131
2885.96	127.734
2888.59	131.445
2891.21	134.682
2893.84	138.068
2896.46	142.903
2899.09	148.933
2901.71	154.72
2904.33	162.142
2906.95	169.762
2909.57	179.116
2912.19	189.897
2914.81	199.8
2917.43	210.15
2920.04	218.675
2922.66	226.727
2925.27	233.18
2927.88	237.103
2930.5	240.345
2933.11	241.722
2935.72	242.003
2938.33	239.954
2940.94	237.21
2943.54	232.513
2946.15	225.981
2948.76	218.194
2951.36	208.716
2953.97	199.951
2956.57	190.413
2959.17	182.558
2961.77	173.617
2964.37	164.656
2966.97	156.793
2969.57	149.624
2972.17	142.43
2974.77	135.076
2977.36	128.096
2979.96	120.691
2982.55	112.814
2985.15	104.95
2987.74	96.8673
2990.33	89.9418
2992.92	82.7096
2995.51	76.4274
2998.1	69.7672
3000.69	63.4868
3003.27	57.8381
3005.86	51.6161
3008.44	46.4973
3011.03	41.7678
3013.61	36.9975
3016.19	33.7517
3018.78	31.1116
3021.36	28.3088
3023.94	25.892
3026.51	23.6458
3029.09	22.9208
3031.67	22.4336
3034.24	22.0484
3036.82	22.3585
3039.39	22.6151
3041.97	22.9776
3044.54	22.7897
3047.11	23.5757
3049.68	24.9258
3052.25	25.6293
3054.82	25.794
3057.39	26.4544
3059.96	26.4311
3062.52	25.9957
3065.09	25.9058
3067.65	25.0008
3070.22	24.2653
3072.78	22.7083
3075.34	20.8037
3077.9	18.4199
3080.46	16.9197
3083.02	14.6459
3085.58	12.2452
3088.14	10.7073
3090.69	10.3223
3093.25	8.41217
3095.8	7.14109
3098.36	6.19971
3100.91	6.02453
3103.46	5.53584
3106.01	4.93166
3108.56	3.95982
3111.11	3.75796
3113.66	3.44138
3116.21	3.96441
3118.76	3.59141
3121.3	3.43973
3123.85	3.44397
3126.39	3.15612
3128.93	2.92134
3131.48	2.6685
3134.02	2.19195
3136.56	1.65438
3139.1	0.610738
3141.64	0.474582
3144.17	-0.147957
3146.71	-1.80068
3149.25	-3.97236