File: data/Raman/poly_smoothed/Thy_20_09_14_1x_45s_532 nm_x100_100%_600 gr_mm_01.txt
#Acq. time (s)=	45
#Accumulations=	2
#Range (cm-¹)=	200...3150
#Windows=	2
#Auto scanning=	Off
#Autofocus=	Off
#Macrospot=	Off
#AutoExposure=	Off
#Spike filter=	Multiple accum.
#Delay time (s)=	0
#Binning=	1
#Readout mode=	Signal
#DeNoise=	Off
#ICS correction=	On
#Dark correction=	Off
#Inst. Process=	Off
#Detector Gain=	Best Dynamic Range
#Detector ADC=	20 kHz
#Detector temperature (°C)=	-69.85
#Instrument=	LabRAM HR Evol
#Detector=	Synapse
#Objective=	x100
#Grating=	600 gr/mm
#ND Filter=	100%
#Laser (nm)=	532
#Hole=	100.021
#Range=	Auto
#Laser Pol.=	No
#Raman. Pol.=	No
#Laser Pol. (°)=	-0.0007625
#Raman Pol. (°)=	89.9995
#Collection=	Microscope
#StageXY=	Marzhauser
#StageZ=	Marzhauser
#X (µm)=	-5894.2
#Y (µm)=	2853.8
#Z (µm)=	-223.15
#Full time(mm:ss)=	3:18
#Project=
#Sample=
#Site=
#Title=	Thy_20_09_14_2x_45s_532 nm_x100_100%_600 gr_mm
#Remark=
#Date=	29.06.2022 11:41
#Acquired=	29.06.2022 11:41:30
#Base:Fit=	10.08.2022 09:52:02
#Base:Fit=	10.08.2022 09:52:12
#Base:Sub=	10.08.2022 09:54:21
#Filter:Polynom=	16.08.2022 10:24:04
#AxisType[0]=Intens
#AxisUnit[0]=Cnt
#AxisType[1]=Spectr
#AxisUnit[1]=1/cm
200.523	4.26002
204.154	3.89005
207.781	5.46844
211.409	5.40158
215.034	5.28964
218.659	5.27137
222.281	4.52026
225.903	3.01983
229.522	1.5369
233.14	1.3308
236.756	1.70133
240.373	2.30051
243.986	3.56907
247.598	3.34823
251.208	3.45022
254.818	4.10852
258.427	6.4134
262.034	6.07104
265.638	7.64951
269.242	8.15549
272.844	9.09018
276.445	9.44763
280.044	11.3875
283.642	12.2476
287.238	13.4513
290.833	15.9646
294.425	15.9291
298.017	17.086
301.608	19.1557
305.198	17.9568
308.786	18.2507
312.371	17.9302
315.956	18.3309
319.54	20.1833
323.122	21.1737
326.701	22.0542
330.281	22.5254
333.857	22.8727
337.434	23.0262
341.008	22.8522
344.582	23.925
348.153	23.0396
351.724	23.6113
355.292	22.9126
358.861	19.9173
362.426	19.1664
365.99	19.1767
369.555	19.0488
373.116	18.9668
376.676	18.2685
380.236	16.2898
383.793	16.5013
387.349	15.889
390.903	14.4291
394.456	14.2204
398.007	14.1247
401.56	14.309
405.108	14.7404
408.656	12.9506
412.202	12.978
415.746	11.6658
419.29	11.9518
422.831	10.4536
426.37	10.126
429.909	10.0894
433.447	8.9091
436.983	7.64042
440.519	5.2524
444.052	3.06359
447.583	3.79111
451.114	5.01609
454.643	6.62574
458.169	5.0543
461.696	5.93504
465.222	5.97652
468.744	7.86245
472.267	8.2396
475.787	9.18082
479.307	12.1275
482.823	13.2407
486.341	14.6102
489.855	14.7646
493.37	14.3203
496.881	14.0935
500.391	13.7013
503.902	12.902
507.409	11.9742
510.915	10.5056
514.42	10.3028
517.925	9.68439
521.427	9.79831
524.928	9.40046
528.427	9.60731
531.925	10.579
535.422	9.84329
538.917	8.94352
542.411	7.50236
545.903	7.65685
549.395	7.95546
552.884	7.79628
556.373	7.99029
559.86	8.22467
563.346	9.37743
566.831	9.20971
570.314	8.95846
573.794	8.01378
577.274	4.56456
580.754	4.8472
584.23	4.03401
587.706	2.72857
591.181	2.78004
594.653	2.8921
598.126	3.78977
601.595	3.75213
605.065	3.33437
608.532	3.59297
611.999	3.75742
615.463	2.98758
618.928	2.11552
622.389	1.31109
625.851	2.2087
629.31	2.72423
632.767	4.20674
636.223	4.86976
639.68	4.69411
643.134	4.77045
646.586	5.05629
650.037	5.06899
653.486	4.97833
656.936	4.59213
660.383	6.00315
663.829	6.62645
667.273	8.774
670.716	10.4481
674.158	9.9359
677.598	14.6161
681.035	16.5943
684.473	19.5373
687.909	21.6547
691.344	24.4393
694.778	27.4914
698.211	31.5261
701.64	33.6279
705.07	33.9393
708.498	35.9133
711.924	37.0246
715.35	38.1946
718.774	39.6062
722.196	38.5801
725.618	39.4756
729.037	40.0727
732.456	39.9781
735.873	39.8002
739.289	39.8418
742.703	38.9752
746.116	40.6247
749.529	40.6835
752.938	41.9292
756.347	42.6271
759.756	45.6889
763.162	47.8701
766.567	48.1178
769.97	49.4786
773.372	50.5573
776.773	51.7738
780.174	52.8392
783.573	53.1318
786.97	51.6792
790.365	50.1535
793.76	51.2973
797.153	52.3324
800.543	53.9253
803.933	54.9809
807.322	55.9978
810.71	56.5134
814.097	56.4745
817.483	57.0119
820.865	57.0107
824.248	56.9192
827.629	57.4433
831.008	58.0993
834.387	57.4422
837.765	56.5751
841.139	55.9538
844.514	54.317
847.886	53.6212
851.259	50.8595
854.629	48.755
857.997	46.3051
861.366	44.0337
864.732	41.8422
868.098	40.7063
871.461	37.9479
874.823	37.6993
878.184	37.999
881.545	37.8668
884.903	37.7433
888.26	36.9425
891.616	37.2013
894.97	36.8692
898.323	36.5873
901.675	36.0536
905.026	34.3701
908.375	33.8724
911.723	33.8579
915.07	33.1757
918.415	32.1261
921.76	31.4335
925.103	30.6758
928.443	28.8167
931.783	27.5321
935.123	25.2524
938.461	24.8944
941.796	23.7169
945.131	23.7015
948.465	24.0004
951.797	22.9127
955.128	22.9424
958.457	22.1385
961.786	22.4266
965.113	22.5202
968.44	23.1975
971.763	22.1741
975.086	23.1522
978.409	22.6457
981.729	22.6095
985.048	22.7279
988.367	21.3237
991.683	21.5987
994.998	19.3604
998.312	18.5423
1001.62	17.2625
1004.94	15.9016
1008.25	14.7159
1011.56	13.1988
1014.86	11.9112
1018.17	10.6793
1021.48	9.28896
1024.78	9.46319
1028.08	10.5649
1031.38	9.68503
1034.68	9.11315
1037.98	8.91311
1041.28	8.14127
1044.57	9.73005
1047.87	9.1391
1051.16	9.72514
1054.45	11.3323
1057.75	11.9405
1061.04	13.0252
1064.32	13.6286
1067.61	13.2873
1070.9	13.4743
1074.18	13.2883
1077.47	12.9049
1080.75	13.5437
1084.03	13.2861
1087.31	13.028
1090.59	12.6552
1093.86	12.69
1097.14	12.6899
1100.41	13.791
1103.69	13.0191
1106.96	14.9796
1110.23	14.7144
1113.5	14.8783
1116.77	14.5769
1120.03	14.9924
1123.3	14.4381
1126.56	12.2189
1129.83	10.9161
1133.09	12.4034
1136.35	12.3063
1139.61	13.8669
1142.86	13.2123
1146.12	12.2736
1149.38	10.5781
1152.63	10.1969
1155.88	8.91041
1159.14	9.09913
1162.39	7.58555
1165.63	5.33164
1168.88	5.19486
1172.13	6.41269
1175.38	7.35534
1178.62	5.77104
1181.86	6.13831
1185.1	7.23798
1188.34	9.02521
1191.58	9.64534
1194.82	9.69929
1198.06	10.7067
1201.29	11.734
1204.53	13.294
1207.76	15.8466
1210.99	19.6551
1214.22	23.2002
1217.45	26.6992
1220.68	29.6007
1223.91	30.5974
1227.13	31.8658
1230.36	33.3088
1233.58	36.7923
1236.8	38.7033
1240.02	39.3996
1243.24	41.3386
1246.46	43.1198
1249.67	44.0839
1252.89	46.0075
1256.1	45.8586
1259.32	46.3426
1262.53	47.4255
1265.74	48.0525
1268.95	48.8776
1272.15	51.4268
1275.36	54.3574
1278.57	56.4048
1281.77	58.8214
1284.97	60.4563
1288.18	63.1183
1291.38	65.5624
1294.58	67.6032
1297.78	67.7461
1300.97	69.8917
1304.17	70.7136
1307.36	74.2539
1310.55	76.3578
1313.75	76.9371
1316.94	78.1943
1320.13	78.349
1323.32	78.8693
1326.5	80.022
1329.69	78.6917
1332.87	79.1862
1336.06	78.4152
1339.24	77.6498
1342.42	77.1052
1345.6	76.6749
1348.78	75.4058
1351.96	75.3151
1355.13	74.9242
1358.31	72.668
1361.48	69.7919
1364.65	68.1321
1367.82	66.58
1370.99	64.9942
1374.16	62.3804
1377.33	61.097
1380.5	59.8995
1383.66	57.7564
1386.83	56.394
1389.99	53.6978
1393.15	52.4797
1396.31	51.5695
1399.47	51.169
1402.63	51.1167
1405.78	50.4308
1408.94	49.4952
1412.1	49.9195
1415.25	52.1922
1418.4	52.5461
1421.55	53.8866
1424.7	56.2251
1427.85	58.985
1431	61.9748
1434.14	62.6547
1437.29	63.6921
1440.43	63.9654
1443.57	64.7748
1446.71	64.9435
1449.85	64.2061
1452.99	63.6454
1456.13	62.7556
1459.26	61.9175
1462.4	60.7309
1465.54	58.7935
1468.67	55.6946
1471.8	54.8591
1474.93	52.6239
1478.06	50.296
1481.19	46.7548
1484.31	42.4616
1487.44	40.7036
1490.56	39.2861
1493.69	37.1637
1496.81	34.6481
1499.93	34.0463
1503.05	32.4593
1506.17	30.996
1509.28	30.4969
1512.4	30.8222
1515.52	29.5416
1518.63	29.0259
1521.74	30.2641
1524.85	30.2914
1527.96	30.9328
1531.07	32.3869
1534.18	34.7848
1537.29	37.3488
1540.39	39.6689
1543.5	41.587
1546.6	45.5451
1549.7	50.4392
1552.8	53.6083
1555.9	56.6834
1559	59.2245
1562.1	63.5111
1565.19	66.8893
1568.29	69.2837
1571.38	72.0233
1574.47	74.5462
1577.56	75.9748
1580.66	77.4678
1583.74	79.8457
1586.83	79.5395
1589.92	78.2699
1593.01	77.705
1596.09	77.5779
1599.17	75.6224
1602.25	73.492
1605.34	70.8502
1608.41	68.9505
1611.49	66.4021
1614.57	64.8707
1617.65	62.4319
1620.72	62.0696
1623.79	60.8536
1626.87	60.6702
1629.94	60.2141
1633.01	58.53
1636.08	59.6183
1639.15	59.2261
1642.21	59.476
1645.28	59.4657
1648.34	59.6841
1651.41	58.7854
1654.47	58.0308
1657.53	56.1923
1660.59	54.6555
1663.65	52.6346
1666.71	50.5599
1669.76	48.1208
1672.82	44.3517
1675.87	41.1445
1678.93	37.4578
1681.98	32.6773
1685.03	28.6572
1688.08	26.4099
1691.13	23.8261
1694.17	20.4039
1697.22	17.0109
1700.27	15.7521
1703.31	14.3331
1706.35	13.5207
1709.39	12.837
1712.43	11.8721
1715.47	11.1636
1718.51	10.4211
1721.55	9.3727
1724.58	8.28348
1727.62	8.30289
1730.65	7.70057
1733.68	6.3525
1736.72	5.44486
1739.74	3.99174
1742.77	3.17363
1745.8	2.19102
1748.83	1.05644
1751.85	0.430587
1754.88	0.288657
1757.9	0.123813
1760.92	0.718405
1763.95	1.52241
1766.96	1.06794
1769.98	0.776257
1773	0.909082
1776.02	2.23286
1779.03	2.06581
1782.05	1.62652
1785.06	0.656739
1788.07	1.49552
1791.08	1.98731
1794.09	2.36102
1797.1	2.40575
1800.11	2.78191
1803.12	3.39052
1806.12	3.34074
1809.12	2.62069
1812.13	2.70681
1815.13	2.68464
1818.13	2.683
1821.13	3.1567
1824.13	3.44157
1827.13	3.78313
1830.12	3.87672
1833.12	3.96634
1836.11	3.44038
1839.1	2.68571
1842.09	2.32311
1845.09	1.78418
1848.08	1.53484
1851.06	1.52308
1854.05	1.83332
1857.04	1.63907
1860.02	1.3544
1863.01	1.70964
1865.99	2.05964
1868.97	2.58243
1871.95	2.50312
1874.93	2.98976
1877.91	3.14437
1880.89	2.69534
1882.46	2.80262
1885.45	3.83056
1888.43	4.15154
1891.42	5.18913
1894.41	4.87172
1897.39	4.89033
1900.37	4.33618
1903.36	3.43364
1906.34	2.91273
1909.32	3.07878
1912.29	2.47631
1915.27	2.50977
1918.25	2.88757
1921.23	3.86977
1924.2	4.55637
1927.17	4.32414
1930.15	4.16711
1933.12	4.21498
1936.09	4.14997
1939.06	4.52149
1942.02	5.12223
1944.99	4.61554
1947.96	4.78329
1950.92	4.35597
1953.88	5.22231
1956.85	4.66215
1959.81	4.23792
1962.77	4.25446
1965.73	3.76931
1968.69	2.66229
1971.64	2.30072
1974.6	1.67997
1977.55	0.770074
1980.51	0.674253
1983.46	0.618097
1986.41	1.81526
1989.36	2.27117
1992.31	2.57109
1995.26	2.17136
1998.21	1.87202
2001.15	1.78199
2004.1	2.65348
2007.04	2.24104
2009.99	3.03848
2012.93	3.71138
2015.87	3.62625
2018.81	4.02554
2021.75	4.19077
2024.68	4.1576
2027.62	4.41195
2030.56	5.38829
2033.49	6.735
2036.42	8.00101
2039.36	7.98555
2042.29	9.18461
2045.22	8.64847
2048.14	8.46825
2051.07	8.42853
2054	9.00809
2056.93	9.37976
2059.85	9.19262
2062.77	7.67412
2065.7	8.03089
2068.62	7.67998
2071.54	6.61332
2074.46	5.72412
2077.38	4.82741
2080.29	4.15186
2083.21	3.74966
2086.12	3.54389
2089.04	3.48577
2091.95	3.49998
2094.86	3.7472
2097.77	5.10724
2100.68	7.39105
2103.59	8.89779
2106.5	10.1752
2109.41	10.866
2112.31	12.7396
2115.21	13.9887
2118.12	15.1614
2121.02	16.2929
2123.92	18.2832
2126.82	19.6581
2129.72	20.8398
2132.62	21.7193
2135.51	22.6241
2138.41	24.4942
2141.31	24.996
2144.2	24.9507
2147.09	25.3002
2149.98	25.5953
2152.87	26.0359
2155.76	27.07
2158.65	28.2843
2161.54	28.8602
2164.43	29.2328
2167.31	30.0527
2170.2	30.0981
2173.08	30.5844
2175.96	29.5995
2178.84	28.6803
2181.72	29.1298
2184.6	28.5567
2187.48	27.8499
2190.36	27.5345
2193.23	26.9148
2196.11	25.8567
2198.98	25.1438
2201.85	25.196
2204.72	23.5666
2207.59	23.5118
2210.46	21.6022
2213.33	19.6687
2216.2	18.9744
2219.07	19.1549
2221.93	19.4595
2224.8	19.1409
2227.66	18.1628
2230.52	17.7906
2233.39	16.6021
2236.25	16.046
2239.1	14.8542
2241.96	14.6513
2244.82	14.8324
2247.68	14.1342
2250.53	13.977
2253.38	14.903
2256.24	14.9496
2259.09	14.7596
2261.94	15.2279
2264.79	15.6728
2267.64	15.7768
2270.49	15.5691
2273.33	14.2437
2276.18	13.7941
2279.02	13.8149
2281.87	12.8284
2284.71	12.5098
2287.55	12.8828
2290.39	12.2713
2293.23	11.3938
2296.07	11.0162
2298.91	10.7306
2301.74	10.9526
2304.58	12.1133
2307.41	12.3313
2310.25	12.3562
2313.08	12.8585
2315.91	13.357
2318.74	12.7035
2321.57	13.4538
2324.4	13.1644
2327.23	13.0097
2330.05	13.4511
2332.88	13.2912
2335.7	12.4369
2338.52	11.5266
2341.35	11.0985
2344.17	10.3278
2346.99	9.9311
2349.81	8.1872
2352.62	7.08614
2355.44	7.39889
2358.26	6.67584
2361.07	6.39832
2363.89	6.23097
2366.7	7.11481
2369.51	6.03463
2372.32	5.4571
2375.13	4.21091
2377.94	3.27692
2380.75	2.45722
2383.56	2.11022
2386.36	1.50076
2389.17	0.364051
2391.97	0.389382
2394.77	0.394552
2397.58	0.203665
2400.38	1.35284
2403.18	1.41045
2405.97	2.04624
2408.77	3.42835
2411.57	4.30336
2414.37	4.17412
2417.16	4.80215
2419.95	5.70305
2422.75	6.71439
2425.54	8.24964
2428.33	7.85554
2431.12	8.70572
2433.91	8.94588
2436.7	9.04155
2439.48	8.65309
2442.27	8.20621
2445.05	8.03885
2447.84	7.72205
2450.62	7.07613
2453.4	6.5195
2456.18	5.6063
2458.96	6.17167
2461.74	6.78063
2464.52	7.24132
2467.29	7.21764
2470.07	6.974
2472.85	6.13654
2475.62	6.07324
2478.39	4.87995
2481.16	4.09096
2483.93	4.44778
2486.7	4.02202
2489.47	3.976
2492.24	3.39783
2495.01	3.72361
2497.77	4.80874
2500.54	5.20314
2503.3	4.82006
2506.06	4.72294
2508.83	5.08562
2511.59	5.11519
2514.35	4.97431
2517.11	5.35093
2519.86	5.44649
2522.62	6.7189
2525.38	7.30262
2528.13	7.57168
2530.89	8.20037
2533.64	7.87516
2536.39	6.88773
2539.14	6.80584
2541.89	6.39244
2544.64	7.02484
2547.39	7.15185
2550.14	6.53147
2552.88	6.39587
2555.63	5.88691
2558.37	4.77345
2561.11	5.57574
2563.86	6.36712
2566.6	6.34344
2569.34	6.15499
2572.08	5.71556
2574.82	5.71781
2577.55	5.58671
2580.29	4.56663
2583.02	5.09044
2585.76	5.54593
2588.49	6.63851
2591.22	6.83286
2593.96	6.74878
2596.69	6.23475
2599.42	6.15433
2602.14	6.17296
2604.87	6.5333
2607.6	6.95796
2610.32	6.01033
2613.05	6.14215
2615.77	6.19935
2618.49	6.11518
2621.22	5.97105
2623.94	6.52094
2626.66	7.09077
2629.37	7.28547
2632.09	7.23465
2634.81	6.38536
2637.53	6.05818
2640.24	6.06928
2642.96	5.9074
2645.67	6.06624
2648.38	5.84875
2651.09	7.46333
2653.8	7.63866
2656.51	7.20815
2659.22	7.15482
2661.93	7.61244
2664.63	7.22404
2667.34	6.93831
2670.04	5.93596
2672.75	5.65417
2675.45	3.93277
2678.15	3.85784
2680.85	4.6717
2683.55	4.35527
2686.25	4.09957
2688.94	3.92546
2691.64	3.86832
2694.34	4.18935
2697.03	4.0069
2699.73	3.40348
2702.42	4.78691
2705.11	5.49262
2707.8	6.37678
2710.49	7.18594
2713.18	7.03555
2715.87	7.50039
2718.55	8.12545
2721.24	8.9145
2723.93	9.94049
2726.61	9.98454
2729.29	9.72164
2731.98	8.78916
2734.66	7.91147
2737.34	6.92105
2740.02	5.34437
2742.7	4.55104
2745.37	3.85424
2748.05	3.22501
2750.72	2.39138
2753.4	1.16584
2756.07	0.509475
2758.75	0.521944
2761.42	0.657498
2764.09	0.210309
2766.76	0.80808
2769.43	1.13811
2772.1	0.461262
2774.76	-0.241315
2777.43	0.154327
2780.1	1.03764
2782.76	1.26376
2785.42	1.82607
2788.09	3.0681
2790.75	2.70514
2793.41	2.09141
2796.07	2.1074
2798.73	1.77959
2801.39	1.26166
2804.04	1.25786
2806.7	1.65322
2809.35	1.79988
2812.01	2.49167
2814.66	1.85318
2817.31	1.83292
2819.96	3.52261
2822.61	4.47978
2825.26	6.348
2827.91	8.9196
2830.56	10.2171
2833.21	12.157
2835.85	14.0312
2838.5	16.4079
2841.14	19.5609
2843.78	23.1302
2846.42	25.8415
2849.06	29.9103
2851.71	34.2518
2854.34	37.9896
2856.98	42.0018
2859.62	46.6359
2862.26	50.4014
2864.89	54.2377
2867.53	57.9541
2870.16	61.0661
2872.79	63.7841
2875.42	65.5984
2878.05	67.4942
2880.68	69.2112
2883.31	72.4784
2885.94	74.9245
2888.57	77.1235
2891.19	79.9808
2893.82	82.7539
2896.44	84.6862
2899.07	88.1256
2901.69	91.9899
2904.31	96.0531
2906.93	100.983
2909.55	106.023
2912.17	111.313
2914.79	117.145
2917.41	122.016
2920.02	126.63
2922.64	129.837
2925.25	132.414
2927.86	133.609
2930.48	134.648
2933.09	133.592
2935.7	132.043
2938.31	130.062
2940.92	126.59
2943.53	122.831
2946.13	118.972
2948.74	114.348
2951.34	109.477
2953.95	106.51
2956.55	101.906
2959.15	97.8793
2961.75	93.4706
2964.35	89.3432
2966.95	85.1703
2969.55	81.1984
2972.15	77.2591
2974.75	73.6029
2977.34	69.8953
2979.94	65.5798
2982.53	61.401
2985.13	56.599
2987.72	53.1244
2990.31	47.8981
2992.9	42.78
2995.49	38.0895
2998.08	32.8116
3000.67	29.0963
3003.25	24.709
3005.84	20.8716
3008.42	18.3682
3011.01	14.5001
3013.59	11.7118
3016.17	9.59004
3018.76	7.45836
3021.34	5.40941
3023.92	4.50748
3026.49	3.5305
3029.07	3.44224
3031.65	2.00168
3034.23	2.52338
3036.8	2.75821
3039.38	3.40876
3041.95	3.96953
3044.52	4.58729
3047.09	5.59226
3049.66	6.87142
3052.23	6.92201
3054.8	6.80605
3057.37	7.49877
3059.94	8.11164
3062.5	8.56433
3065.07	9.04453
3067.63	8.66528
3070.2	8.3295
3072.76	7.74348
3075.32	7.2062
3077.88	5.43434
3080.44	5.01815
3083	4.34561
3085.56	4.02533
3088.12	3.21071
3090.67	3.14653
3093.23	1.86673
3095.78	1.85634
3098.34	1.81503
3100.89	1.65406
3103.44	1.10712
3105.99	0.303516
3108.54	0.502442
3111.09	0.559518
3113.64	-0.0137064
3116.19	-0.470211
3118.74	0.682984
3121.28	1.00827
3123.83	1.16293
3126.37	1.60906
3128.91	2.3639
3131.46	3.03466
3134	4.28106
3136.54	5.24504
3139.08	5.97186
3141.62	7.66413
3144.16	10.1425
3146.69	12.8631
3149.23	16.4548