File: data/Raman/poly_smoothed/Thy_20_09_10_1x_45s_532 nm_x100_100%_600 gr_mm_01.txt
#Acq. time (s)=	45
#Accumulations=	2
#Range (cm-¹)=	200...3150
#Windows=	2
#Auto scanning=	Off
#Autofocus=	Off
#Macrospot=	Off
#AutoExposure=	Off
#Spike filter=	Multiple accum.
#Delay time (s)=	0
#Binning=	1
#Readout mode=	Signal
#DeNoise=	Off
#ICS correction=	On
#Dark correction=	Off
#Inst. Process=	Off
#Detector Gain=	Best Dynamic Range
#Detector ADC=	20 kHz
#Detector temperature (°C)=	-69.85
#Instrument=	LabRAM HR Evol
#Detector=	Synapse
#Objective=	x100
#Grating=	600 gr/mm
#ND Filter=	100%
#Laser (nm)=	532
#Hole=	100.021
#Range=	Auto
#Laser Pol.=	No
#Raman. Pol.=	No
#Laser Pol. (°)=	-0.0007625
#Raman Pol. (°)=	89.9995
#Collection=	Microscope
#StageXY=	Marzhauser
#StageZ=	Marzhauser
#X (µm)=	-5891.3
#Y (µm)=	2845.8
#Z (µm)=	-223.25
#Full time(mm:ss)=	3:18
#Project=
#Sample=
#Site=
#Title=	Thy_20_09_10_2x_45s_532 nm_x100_100%_600 gr_mm
#Remark=
#Date=	29.06.2022 11:25
#Acquired=	29.06.2022 11:25:52
#Base:Fit=	10.08.2022 09:52:02
#Base:Fit=	10.08.2022 09:52:12
#Base:Sub=	10.08.2022 09:54:21
#Filter:Polynom=	16.08.2022 10:24:04
#AxisType[0]=Intens
#AxisUnit[0]=Cnt
#AxisType[1]=Spectr
#AxisUnit[1]=1/cm
200.523	19.3613
204.154	14.2905
207.781	12.7397
211.409	11.3705
215.034	10.8192
218.659	12.1028
222.281	12.2687
225.903	15.5607
229.522	15.0977
233.14	13.9186
236.756	12.6818
240.373	11.0026
243.986	11.9314
247.598	11.9374
251.208	12.3605
254.818	12.7026
258.427	12.8929
262.034	11.9303
265.638	12.615
269.242	13.7338
272.844	12.598
276.445	11.7595
280.044	10.4611
283.642	10.1683
287.238	9.09095
290.833	7.39729
294.425	8.5824
298.017	9.27277
301.608	11.4872
305.198	14.4897
308.786	16.2428
312.371	16.1943
315.956	15.5209
319.54	14.8922
323.122	13.9889
326.701	13.8804
330.281	14.681
333.857	15.0473
337.434	14.8818
341.008	13.3864
344.582	13.3332
348.153	12.8285
351.724	11.6942
355.292	10.3331
358.861	11.0694
362.426	10.3406
365.99	9.38137
369.555	8.74921
373.116	8.10799
376.676	7.27735
380.236	8.68386
383.793	9.8978
387.349	11.13
390.903	12.7845
394.456	11.7129
398.007	10.1853
401.56	8.31778
405.108	7.9616
408.656	8.47934
412.202	8.67253
415.746	8.50036
419.29	7.8124
422.831	6.73615
426.37	6.18804
429.909	5.34596
433.447	5.90099
436.983	5.43478
440.519	6.79063
444.052	6.99535
447.583	8.55634
451.114	9.36847
454.643	10.7886
458.169	13.0278
461.696	14.0614
465.222	16.1271
468.744	17.727
472.267	18.5502
475.787	18.6643
479.307	19.8381
482.823	19.2782
486.341	18.412
489.855	19.6888
493.37	20.3174
496.881	20.7127
500.391	20.3791
503.902	18.0338
507.409	18.0753
510.915	17.6584
514.42	16.6983
517.925	16.6028
521.427	16.2097
524.928	16.0599
528.427	16.3529
531.925	16.6091
535.422	16.8451
538.917	17.1313
542.411	17.1824
545.903	16.5413
549.395	16.3921
552.884	15.5303
556.373	14.8797
559.86	13.5521
563.346	12.6862
566.831	12.2798
570.314	9.5471
573.794	8.22092
577.274	6.69525
580.754	5.44842
584.23	4.89803
587.706	4.57799
591.181	3.42845
594.653	3.33856
598.126	1.91685
601.595	2.6808
605.065	3.30227
608.532	5.33872
611.999	6.67783
615.463	7.5911
618.928	8.02652
622.389	8.00394
625.851	8.90519
629.31	10.5827
632.767	11.7662
636.223	14.1057
639.68	13.718
643.134	15.5772
646.586	16.299
650.037	16.7962
653.486	16.7063
656.936	15.5929
660.383	16.7719
663.829	16.9763
667.273	17.0509
670.716	15.4772
674.158	14.8027
677.598	14.4203
681.035	14.0323
684.473	15.262
687.909	15.952
691.344	17.6985
694.778	18.818
698.211	18.4106
701.64	18.2593
705.07	18.9563
708.498	20.8986
711.924	22.304
715.35	23.0713
718.774	25.0303
722.196	26.4185
725.618	28.6159
729.037	31.2547
732.456	32.8989
735.873	33.8949
739.289	35.9061
742.703	38.1712
746.116	40.7578
749.529	42.6828
752.938	43.9974
756.347	47.3516
759.756	50.8915
763.162	54.1845
766.567	57.6024
769.97	60.3386
773.372	61.8478
776.773	63.3695
780.174	62.1953
783.573	63.5488
786.97	64.03
790.365	66.6685
793.76	67.0726
797.153	66.4992
800.543	68.0328
803.933	68.5536
807.322	68.5581
810.71	68.4664
814.097	67.1635
817.483	67.4064
820.865	68.7203
824.248	68.9792
827.629	67.854
831.008	67.4813
834.387	65.5636
837.765	65.2269
841.139	65.2281
844.514	64.3107
847.886	61.8273
851.259	59.4906
854.629	54.9688
857.997	52.7231
861.366	49.9692
864.732	47.5969
868.098	45.4537
871.461	43.4371
874.823	40.5825
878.184	40.38
881.545	40.2674
884.903	40.1969
888.26	40.0504
891.616	39.3414
894.97	38.9335
898.323	39.6263
901.675	39.7469
905.026	40.4587
908.375	40.5419
911.723	40.7696
915.07	42.0403
918.415	42.5076
921.76	43.4734
925.103	44.6915
928.443	44.3817
931.783	42.6105
935.123	41.7854
938.461	42.4124
941.796	40.2114
945.131	37.2874
948.465	35.0738
951.797	33.6454
955.128	32.2047
958.457	30.835
961.786	29.4131
965.113	27.6833
968.44	25.9304
971.763	24.2203
975.086	22.2449
978.409	21.3899
981.729	21.4776
985.048	20.8637
988.367	20.8534
991.683	19.746
994.998	20.8067
998.312	19.9561
1001.62	18.9023
1004.94	19.6661
1008.25	18.942
1011.56	17.3739
1014.86	17.7227
1018.17	19.6461
1021.48	16.9452
1024.78	15.5358
1028.08	15.8136
1031.38	16.9139
1034.68	15.9914
1037.98	14.1922
1041.28	14.0917
1044.57	14.2204
1047.87	15.7917
1051.16	15.2567
1054.45	14.6643
1057.75	14.7321
1061.04	15.6516
1064.32	14.9086
1067.61	15.3131
1070.9	15.8419
1074.18	14.6134
1077.47	15.2513
1080.75	13.7509
1084.03	14.08
1087.31	12.9299
1090.59	13.685
1093.86	15.9299
1097.14	16.4064
1100.41	16.7771
1103.69	16.7175
1106.96	17.7277
1110.23	18.4378
1113.5	18.3256
1116.77	16.7321
1120.03	15.7354
1123.3	16.8273
1126.56	16.9165
1129.83	15.2742
1133.09	14.3499
1136.35	12.6626
1139.61	12.3615
1142.86	11.4912
1146.12	11.1114
1149.38	8.85657
1152.63	6.69077
1155.88	5.35797
1159.14	4.16032
1162.39	3.67831
1165.63	3.95644
1168.88	2.14732
1172.13	3.45973
1175.38	3.29083
1178.62	3.90339
1181.86	4.20761
1185.1	4.21914
1188.34	3.87928
1191.58	4.20323
1194.82	3.34357
1198.06	3.80649
1201.29	6.03488
1204.53	8.86564
1207.76	8.98987
1210.99	11.3441
1214.22	12.9123
1217.45	15.5008
1220.68	18.7496
1223.91	19.2684
1227.13	22.356
1230.36	24.7855
1233.58	27.6824
1236.8	29.9311
1240.02	33.0756
1243.24	33.6406
1246.46	35.3661
1249.67	36.3917
1252.89	37.6356
1256.1	38.6342
1259.32	39.8879
1262.53	40.181
1265.74	41.2586
1268.95	41.3719
1272.15	42.0312
1275.36	42.0624
1278.57	43.4144
1281.77	45.6734
1284.97	46.2364
1288.18	47.6817
1291.38	50.49
1294.58	52.2924
1297.78	53.2508
1300.97	56.7063
1304.17	59.69
1307.36	62.0112
1310.55	62.9014
1313.75	64.6929
1316.94	66.7547
1320.13	67.56
1323.32	68.6578
1326.5	69.0793
1329.69	68.7905
1332.87	69.763
1336.06	71.3129
1339.24	70.3321
1342.42	68.2314
1345.6	66.3048
1348.78	63.4444
1351.96	61.9012
1355.13	59.991
1358.31	58.9307
1361.48	56.4663
1364.65	54.5117
1367.82	52.9013
1370.99	51.8462
1374.16	48.8307
1377.33	49.3852
1380.5	48.4947
1383.66	47.542
1386.83	46.2929
1389.99	46.7287
1393.15	46.4328
1396.31	44.4938
1399.47	42.9802
1402.63	42.7217
1405.78	42.5345
1408.94	43.054
1412.1	43.5598
1415.25	45.1922
1418.4	46.1737
1421.55	47.3621
1424.7	47.7668
1427.85	52.438
1431	56.7497
1434.14	59.5648
1437.29	61.4094
1440.43	62.8125
1443.57	64.4909
1446.71	66.4933
1449.85	67.4842
1452.99	66.7503
1456.13	64.1747
1459.26	61.8276
1462.4	60.2394
1465.54	56.9925
1468.67	53.0333
1471.8	47.2162
1474.93	43.3132
1478.06	39.223
1481.19	33.9672
1484.31	29.5519
1487.44	27.7054
1490.56	26.2893
1493.69	24.3905
1496.81	21.8804
1499.93	21.0777
1503.05	21.1452
1506.17	22.3487
1509.28	21.713
1512.4	20.1256
1515.52	21.7205
1518.63	23.3541
1521.74	24.5289
1524.85	25.5534
1527.96	25.9384
1531.07	26.42
1534.18	28.0138
1537.29	30.0933
1540.39	32.27
1543.5	35.0852
1546.6	37.0425
1549.7	38.6034
1552.8	41.4391
1555.9	43.7571
1559	46.1271
1562.1	49.4339
1565.19	52.8481
1568.29	55.3837
1571.38	57.3275
1574.47	58.562
1577.56	60.5331
1580.66	61.8603
1583.74	63.316
1586.83	63.9429
1589.92	66.6111
1593.01	68.4584
1596.09	67.4081
1599.17	66.5226
1602.25	65.7044
1605.34	64.1643
1608.41	62.8753
1611.49	61.5154
1614.57	61.0512
1617.65	60.3
1620.72	60.3926
1623.79	59.0291
1626.87	57.8532
1629.94	57.2986
1633.01	56.888
1636.08	56.4707
1639.15	55.4287
1642.21	55.8167
1645.28	54.1503
1648.34	52.6793
1651.41	53.0313
1654.47	53.8099
1657.53	54.2629
1660.59	53.8741
1663.65	51.8812
1666.71	51.2156
1669.76	48.2579
1672.82	45.9098
1675.87	42.9908
1678.93	39.3707
1681.98	37.0422
1685.03	35.6069
1688.08	31.5788
1691.13	29.4565
1694.17	26.3061
1697.22	23.6262
1700.27	19.7885
1703.31	16.3115
1706.35	13.3195
1709.39	10.3106
1712.43	7.30562
1715.47	5.86928
1718.51	5.28257
1721.55	4.26546
1724.58	4.99561
1727.62	4.99281
1730.65	3.95464
1733.68	3.43491
1736.72	3.35264
1739.74	4.04541
1742.77	5.27705
1745.8	5.44073
1748.83	5.97379
1751.85	4.94778
1754.88	5.97091
1757.9	6.22229
1760.92	4.89444
1763.95	4.71307
1766.96	4.10381
1769.98	3.60442
1773	3.21777
1776.02	2.72349
1779.03	2.73085
1782.05	2.31853
1785.06	3.07099
1788.07	4.39
1791.08	5.14236
1794.09	5.63745
1797.1	5.42848
1800.11	6.12918
1803.12	6.18301
1806.12	6.2041
1809.12	6.13126
1812.13	6.03342
1815.13	5.62719
1818.13	5.41248
1821.13	4.35152
1824.13	4.25546
1827.13	3.60379
1830.12	3.61554
1833.12	4.50385
1836.11	3.62156
1839.1	3.2305
1842.09	4.00482
1845.09	3.78338
1848.08	3.7392
1851.06	4.46568
1854.05	5.53065
1857.04	5.18396
1860.02	5.23526
1863.01	5.23906
1865.99	4.96295
1868.97	4.25468
1871.95	5.0431
1874.93	5.56257
1877.91	5.02227
1880.89	4.34475
1882.46	4.75038
1885.45	4.85048
1888.43	5.94801
1891.42	6.47812
1894.41	6.27884
1897.39	6.93067
1900.37	7.85091
1903.36	8.4131
1906.34	9.04637
1909.32	9.65438
1912.29	10.6548
1915.27	10.0916
1918.25	9.28118
1921.23	10.0291
1924.2	9.74668
1927.17	9.33807
1930.15	8.65275
1933.12	7.28205
1936.09	6.81468
1939.06	6.51988
1942.02	6.29744
1944.99	6.38174
1947.96	6.48129
1950.92	6.1938
1953.88	6.76184
1956.85	6.13539
1959.81	5.96961
1962.77	5.69096
1965.73	5.86717
1968.69	5.79587
1971.64	5.61312
1974.6	5.08813
1977.55	6.01357
1980.51	6.93693
1983.46	6.85861
1986.41	6.89611
1989.36	6.9374
1992.31	7.61326
1995.26	7.24296
1998.21	7.18803
2001.15	7.64281
2004.1	7.27723
2007.04	7.69238
2009.99	7.52555
2012.93	7.59303
2015.87	7.49669
2018.81	6.74168
2021.75	6.13811
2024.68	7.19861
2027.62	6.10707
2030.56	5.32424
2033.49	4.98472
2036.42	5.0224
2039.36	5.13284
2042.29	4.15314
2045.22	4.0144
2048.14	4.9525
2051.07	6.0255
2054	6.88143
2056.93	7.86291
2059.85	8.7002
2062.77	9.47747
2065.7	9.24793
2068.62	9.95885
2071.54	12.0172
2074.46	13.6862
2077.38	14.4265
2080.29	14.2766
2083.21	14.2435
2086.12	14.8844
2089.04	14.8438
2091.95	16.2313
2094.86	16.4168
2097.77	15.7953
2100.68	15.6524
2103.59	16.6803
2106.5	17.7285
2109.41	17.7309
2112.31	17.8992
2115.21	18.3017
2118.12	19.813
2121.02	21.5212
2123.92	22.8896
2126.82	23.4899
2129.72	24.4571
2132.62	25.413
2135.51	26.6929
2138.41	27.9137
2141.31	29.0865
2144.2	30.0357
2147.09	31.4093
2149.98	32.8916
2152.87	33.7554
2155.76	35.0186
2158.65	35.4381
2161.54	35.6675
2164.43	36.0243
2167.31	36.6839
2170.2	37.6991
2173.08	37.8965
2175.96	37.868
2178.84	36.9211
2181.72	36.7574
2184.6	35.1582
2187.48	34.4269
2190.36	33.0112
2193.23	31.8201
2196.11	29.2434
2198.98	27.9766
2201.85	26.8135
2204.72	25.8843
2207.59	24.2816
2210.46	22.578
2213.33	22.3685
2216.2	21.2385
2219.07	20.8109
2221.93	18.6767
2224.8	17.9096
2227.66	17.2281
2230.52	16.9675
2233.39	17.0698
2236.25	17.1313
2239.1	17.1601
2241.96	16.7407
2244.82	16.5523
2247.68	16.3235
2250.53	15.3044
2253.38	13.8014
2256.24	12.8208
2259.09	11.7165
2261.94	11.1431
2264.79	10.8711
2267.64	11.2201
2270.49	11.7823
2273.33	10.8472
2276.18	10.9591
2279.02	10.9966
2281.87	10.81
2284.71	10.6845
2287.55	10.8713
2290.39	9.35709
2293.23	9.18284
2296.07	9.81514
2298.91	11.1398
2301.74	11.0902
2304.58	11.5939
2307.41	11.6915
2310.25	11.0153
2313.08	11.5071
2315.91	11.1968
2318.74	9.91024
2321.57	8.76649
2324.4	7.92432
2327.23	7.21368
2330.05	6.15725
2332.88	5.73588
2335.7	4.99393
2338.52	4.34721
2341.35	3.43134
2344.17	3.1301
2346.99	2.62439
2349.81	1.23489
2352.62	1.52681
2355.44	1.98247
2358.26	2.94695
2361.07	2.88081
2363.89	3.95731
2366.7	4.63263
2369.51	4.85333
2372.32	5.37447
2375.13	5.60475
2377.94	5.92593
2380.75	7.49684
2383.56	7.44677
2386.36	7.56727
2389.17	7.08388
2391.97	7.84244
2394.77	6.92816
2397.58	6.90948
2400.38	7.08997
2403.18	7.46573
2405.97	7.43678
2408.77	6.2805
2411.57	7.03272
2414.37	6.12991
2417.16	5.51294
2419.95	5.12676
2422.75	5.21071
2425.54	4.9514
2428.33	4.05127
2431.12	2.50871
2433.91	1.55692
2436.7	1.00491
2439.48	0.321601
2442.27	0.547139
2445.05	1.13264
2447.84	2.62779
2450.62	3.74484
2453.4	3.45284
2456.18	3.48679
2458.96	4.4349
2461.74	4.74886
2464.52	5.99974
2467.29	6.04624
2470.07	6.66015
2472.85	6.51717
2475.62	6.04645
2478.39	6.12352
2481.16	5.16942
2483.93	5.19962
2486.7	4.10539
2489.47	3.60306
2492.24	2.38495
2495.01	1.89954
2497.77	1.95198
2500.54	0.97108
2503.3	0.859565
2506.06	0.525657
2508.83	-0.110635
2511.59	-0.314317
2514.35	0.685912
2517.11	0.669155
2519.86	0.289468
2522.62	0.352204
2525.38	0.131773
2528.13	0.68171
2530.89	0.321133
2533.64	0.781175
2536.39	0.128487
2539.14	1.42594
2541.89	1.42948
2544.64	1.82833
2547.39	2.47887
2550.14	3.66444
2552.88	4.02174
2555.63	4.30719
2558.37	5.37661
2561.11	5.08351
2563.86	5.59993
2566.6	6.44628
2569.34	6.86973
2572.08	6.57266
2574.82	5.48513
2577.55	5.5255
2580.29	6.002
2583.02	6.06752
2585.76	5.05788
2588.49	4.14814
2591.22	3.88925
2593.96	3.12663
2596.69	3.16078
2599.42	3.4073
2602.14	3.47531
2604.87	3.56447
2607.6	4.9278
2610.32	5.13261
2613.05	6.41152
2615.77	6.16535
2618.49	6.12893
2621.22	6.50265
2623.94	6.25831
2626.66	6.53454
2629.37	6.72524
2632.09	7.45514
2634.81	8.56391
2637.53	8.34704
2640.24	8.68687
2642.96	8.8616
2645.67	8.90259
2648.38	8.63528
2651.09	8.4998
2653.8	7.33789
2656.51	7.361
2659.22	7.32285
2661.93	6.67232
2664.63	6.61915
2667.34	6.50749
2670.04	6.18201
2672.75	6.93766
2675.45	7.39115
2678.15	7.61896
2680.85	6.89601
2683.55	6.36525
2686.25	6.3962
2688.94	6.2084
2691.64	6.62598
2694.34	7.29057
2697.03	7.3371
2699.73	7.96765
2702.42	9.14753
2705.11	10.1427
2707.8	10.4013
2710.49	11.3517
2713.18	11.8138
2715.87	12.9129
2718.55	12.8112
2721.24	12.5594
2723.93	13.35
2726.61	12.3659
2729.29	12.3413
2731.98	11.5831
2734.66	10.587
2737.34	10.1096
2740.02	9.23027
2742.7	8.3859
2745.37	6.6512
2748.05	5.74971
2750.72	4.32543
2753.4	4.02134
2756.07	2.96848
2758.75	3.08402
2761.42	1.78862
2764.09	1.30782
2766.76	1.78064
2769.43	2.04614
2772.1	2.52622
2774.76	2.69427
2777.43	2.80826
2780.1	3.05623
2782.76	2.38445
2785.42	3.07533
2788.09	2.78288
2790.75	2.42467
2793.41	0.868869
2796.07	0.555269
2798.73	0.319197
2801.39	-0.131381
2804.04	-0.192756
2806.7	-0.127413
2809.35	-0.270477
2812.01	-0.382591
2814.66	-0.0221586
2817.31	0.633439
2819.96	1.82003
2822.61	3.76812
2825.26	5.35978
2827.91	8.59013
2830.56	11.6578
2833.21	14.8353
2835.85	17.4342
2838.5	20.4441
2841.14	22.1959
2843.78	26.552
2846.42	31.3546
2849.06	35.7352
2851.71	40.0406
2854.34	44.4108
2856.98	48.9291
2859.62	53.8417
2862.26	59.397
2864.89	64.522
2867.53	68.9054
2870.16	73.2784
2872.79	76.5343
2875.42	79.1892
2878.05	83.1385
2880.68	86.0549
2883.31	89.1675
2885.94	93.2947
2888.57	97.7424
2891.19	101.593
2893.82	105.565
2896.44	107.826
2899.07	111.443
2901.69	115.335
2904.31	119.978
2906.93	125.013
2909.55	131.576
2912.17	136.815
2914.79	141.78
2917.41	146.024
2920.02	150.191
2922.64	154.298
2925.25	157.899
2927.86	158.943
2930.48	159.469
2933.09	157.82
2935.7	156.159
2938.31	152.157
2940.92	147.8
2943.53	144.224
2946.13	139.856
2948.74	134.015
2951.34	129.971
2953.95	124.816
2956.55	118.836
2959.15	113.178
2961.75	108.89
2964.35	105.109
2966.95	100.673
2969.55	96.2436
2972.15	91.6806
2974.75	86.7238
2977.34	81.1282
2979.94	75.0411
2982.53	69.4989
2985.13	63.4887
2987.72	57.7203
2990.31	49.9674
2992.9	44.3598
2995.49	38.5549
2998.08	31.987
3000.67	26.0784
3003.25	21.3
3005.84	16.6052
3008.42	12.0987
3011.01	8.788
3013.59	5.87537
3016.17	3.50007
3018.76	1.28771
3021.34	0.668712
3023.92	0.850761
3026.49	1.37763
3029.07	0.492815
3031.65	0.442691
3034.23	0.101835
3036.8	0.47599
3039.38	0.591361
3041.95	1.38964
3044.52	2.23794
3047.09	2.19655
3049.66	2.6411
3052.23	3.12999
3054.8	3.44077
3057.37	3.79098
3059.94	3.55168
3062.5	3.44867
3065.07	3.50889
3067.63	3.43814
3070.2	1.99089
3072.76	1.34883
3075.32	1.05356
3077.88	0.222059
3080.44	0.928189
3083	0.360693
3085.56	0.439547
3088.12	0.253762
3090.67	1.02021
3093.23	0.800912
3095.78	1.38246
3098.34	2.30279
3100.89	3.04098
3103.44	3.45038
3105.99	4.51484
3108.54	5.28757
3111.09	6.09439
3113.64	6.4375
3116.19	6.53661
3118.74	7.26443
3121.28	7.83667
3123.83	8.81262
3126.37	9.43303
3128.91	10.1344
3131.46	10.6817
3134	10.9452
3136.54	12.4537
3139.08	14.0183
3141.62	15.6544
3144.16	17.4666
3146.69	20.5477
3149.23	23.6213