File: data/Raman/poly_smoothed/Thy_20_09_07_1x_45s_532 nm_x100_100%_600 gr_mm_01.txt
#Acq. time (s)=	45
#Accumulations=	2
#Range (cm-¹)=	200...3150
#Windows=	2
#Auto scanning=	Off
#Autofocus=	Off
#Macrospot=	Off
#AutoExposure=	Off
#Spike filter=	Multiple accum.
#Delay time (s)=	0
#Binning=	1
#Readout mode=	Signal
#DeNoise=	Off
#ICS correction=	On
#Dark correction=	Off
#Inst. Process=	Off
#Detector Gain=	Best Dynamic Range
#Detector ADC=	20 kHz
#Detector temperature (°C)=	-69.85
#Instrument=	LabRAM HR Evol
#Detector=	Synapse
#Objective=	x100
#Grating=	600 gr/mm
#ND Filter=	100%
#Laser (nm)=	532
#Hole=	100.021
#Range=	Auto
#Laser Pol.=	No
#Raman. Pol.=	No
#Laser Pol. (°)=	-0.0007625
#Raman Pol. (°)=	89.9995
#Collection=	Microscope
#StageXY=	Marzhauser
#StageZ=	Marzhauser
#X (µm)=	-5917.7
#Y (µm)=	2829.4
#Z (µm)=	-223.3
#Full time(mm:ss)=	3:18
#Project=
#Sample=
#Site=
#Title=	Thy_20_09_07_2x_45s_532 nm_x100_100%_600 gr_mm
#Remark=
#Date=	29.06.2022 11:14
#Acquired=	29.06.2022 11:14:13
#Base:Fit=	10.08.2022 09:49:32
#Base:Fit=	10.08.2022 09:49:42
#Base:Fit=	10.08.2022 09:49:53
#Base:Fit=	10.08.2022 09:50:12
#Base:Fit=	10.08.2022 09:50:26
#Base:Fit=	10.08.2022 09:50:30
#Base:Fit=	10.08.2022 09:50:43
#Base:Fit=	10.08.2022 09:52:02
#Base:Fit=	10.08.2022 09:52:12
#Base:Sub=	10.08.2022 09:54:21
#Filter:Polynom=	16.08.2022 10:24:04
#AxisType[0]=Intens
#AxisUnit[0]=Cnt
#AxisType[1]=Spectr
#AxisUnit[1]=1/cm
200.523	11.1967
204.154	13.1101
207.781	12.314
211.409	11.5131
215.034	11.1633
218.659	11.4914
222.281	9.6063
225.903	9.15349
229.522	7.0367
233.14	7.18569
236.756	6.02015
240.373	5.13258
243.986	4.43915
247.598	4.17363
251.208	4.15554
254.818	3.33275
258.427	3.81795
262.034	4.16206
265.638	2.98891
269.242	3.26222
272.844	6.47755
276.445	5.83291
280.044	6.31771
283.642	8.20406
287.238	8.71763
290.833	9.16858
294.425	10.1684
298.017	11.2405
301.608	12.6464
305.198	13.0331
308.786	13.4113
312.371	13.7885
315.956	14.1494
319.54	15.6979
323.122	16.9216
326.701	17.0183
330.281	17.5721
333.857	17.1646
337.434	17.6481
341.008	17.4009
344.582	16.0141
348.153	14.6962
351.724	15.9317
355.292	14.4132
358.861	12.3724
362.426	11.1892
365.99	8.24635
369.555	8.04962
373.116	9.55126
376.676	7.40719
380.236	6.25908
383.793	7.79971
387.349	6.88578
390.903	7.02009
394.456	6.44512
398.007	7.21604
401.56	8.0279
405.108	8.71865
408.656	9.60119
412.202	11.5272
415.746	11.632
419.29	11.7814
422.831	11.8376
426.37	11.0829
429.909	11.2914
433.447	11.5407
436.983	11.3424
440.519	10.1729
444.052	7.31396
447.583	8.7689
451.114	8.20273
454.643	9.27925
458.169	11.7399
461.696	11.5873
465.222	11.392
468.744	12.8953
472.267	15.5551
475.787	13.9637
479.307	15.9034
482.823	17.1842
486.341	17.5153
489.855	18.5079
493.37	20.8937
496.881	22.3995
500.391	23.9631
503.902	25.1737
507.409	26.6443
510.915	26.7877
514.42	26.3235
517.925	24.5693
521.427	22.9038
524.928	21.5892
528.427	19.3992
531.925	18.6158
535.422	18.2778
538.917	17.6092
542.411	16.0438
545.903	13.7284
549.395	11.7743
552.884	11.0655
556.373	9.5346
559.86	8.73012
563.346	7.63441
566.831	4.59419
570.314	4.50338
573.794	4.27366
577.274	5.73014
580.754	6.05836
584.23	6.94571
587.706	6.0993
591.181	6.85323
594.653	4.76584
598.126	3.1289
601.595	2.31508
605.065	2.54409
608.532	3.4573
611.999	4.57204
615.463	4.71553
618.928	5.58784
622.389	6.56711
625.851	6.9992
629.31	8.12495
632.767	10.0037
636.223	11.5988
639.68	12.657
643.134	13.4353
646.586	15.2239
650.037	17.1493
653.486	18.4921
656.936	21.5538
660.383	23.3768
663.829	25.0437
667.273	24.7456
670.716	24.6838
674.158	25.0308
677.598	25.7563
681.035	24.933
684.473	27.0527
687.909	29.1674
691.344	29.9234
694.778	28.7809
698.211	30.3794
701.64	29.6001
705.07	29.7859
708.498	31.6335
711.924	32.9218
715.35	33.9003
718.774	34.8737
722.196	36.1888
725.618	37.3145
729.037	37.1242
732.456	38.7471
735.873	39.5402
739.289	41.3855
742.703	41.8535
746.116	42.3478
749.529	41.4648
752.938	43.3366
756.347	45.2323
759.756	46.2422
763.162	47.2269
766.567	47.0644
769.97	48.5966
773.372	47.9535
776.773	48.2893
780.174	49.5134
783.573	51.7048
786.97	51.9063
790.365	54.308
793.76	56.8142
797.153	56.8661
800.543	58.2489
803.933	59.8166
807.322	60.4192
810.71	60.6115
814.097	62.1104
817.483	63.9287
820.865	64.6588
824.248	64.3204
827.629	63.7278
831.008	62.4464
834.387	62.0143
837.765	60.2155
841.139	57.1093
844.514	54.4372
847.886	50.7898
851.259	46.6899
854.629	44.6012
857.997	42.0308
861.366	39.393
864.732	37.3789
868.098	34.8936
871.461	34.8567
874.823	32.9507
878.184	32.1881
881.545	31.3015
884.903	32.3805
888.26	32.3167
891.616	32.7013
894.97	35.0329
898.323	33.9819
901.675	35.9972
905.026	36.6912
908.375	36.6922
911.723	37.2546
915.07	35.8915
918.415	35.3069
921.76	34.2799
925.103	32.7627
928.443	29.6484
931.783	25.7136
935.123	24.1608
938.461	21.4421
941.796	19.0854
945.131	17.3414
948.465	15.7344
951.797	14.8231
955.128	14.8671
958.457	14.2967
961.786	12.4899
965.113	14.4553
968.44	15.2893
971.763	15.8644
975.086	16.7448
978.409	17.8609
981.729	20.353
985.048	21.4406
988.367	22.7511
991.683	22.4285
994.998	23.9713
998.312	24.9346
1001.62	25.418
1004.94	23.6106
1008.25	21.4302
1011.56	20.8946
1014.86	19.8032
1018.17	18.0299
1021.48	15.8324
1024.78	13.4175
1028.08	12.7757
1031.38	11.4478
1034.68	10.4305
1037.98	10.9456
1041.28	8.22383
1044.57	9.39135
1047.87	10.0921
1051.16	8.54286
1054.45	8.44581
1057.75	8.51645
1061.04	7.99843
1064.32	7.69061
1067.61	9.56425
1070.9	9.25022
1074.18	9.22575
1077.47	10.4129
1080.75	8.59196
1084.03	8.11587
1087.31	7.11246
1090.59	7.01868
1093.86	8.30359
1097.14	7.04636
1100.41	7.65313
1103.69	9.03749
1106.96	9.15834
1110.23	8.97632
1113.5	9.05006
1116.77	8.38885
1120.03	8.59322
1123.3	8.42583
1126.56	8.31305
1129.83	9.52282
1133.09	8.09876
1136.35	7.36845
1139.61	6.77165
1142.86	8.81191
1146.12	7.17944
1149.38	7.38743
1152.63	4.62669
1155.88	4.46975
1159.14	3.10844
1162.39	1.96497
1165.63	1.90755
1168.88	2.30535
1172.13	3.68897
1175.38	5.25462
1178.62	6.60616
1181.86	8.07081
1185.1	8.8574
1188.34	9.58959
1191.58	10.5236
1194.82	13.0143
1198.06	15.2623
1201.29	19.5011
1204.53	23.0374
1207.76	25.7691
1210.99	29.1553
1214.22	31.9147
1217.45	36.0732
1220.68	38.181
1223.91	41.1008
1227.13	41.5778
1230.36	44.5501
1233.58	46.0536
1236.8	47.6061
1240.02	49.1861
1243.24	51.7341
1246.46	52.6027
1249.67	55.5115
1252.89	57.4566
1256.1	59.2652
1259.32	60.1273
1262.53	63.8557
1265.74	64.8381
1268.95	65.6834
1272.15	69.1826
1275.36	70.6741
1278.57	74.2669
1281.77	76.1259
1284.97	79.2305
1288.18	80.3048
1291.38	82.0232
1294.58	85.4935
1297.78	88.0219
1300.97	91.0142
1304.17	93.3445
1307.36	97.3548
1310.55	100.032
1313.75	102.135
1316.94	104.77
1320.13	107.034
1323.32	109.021
1326.5	109.39
1329.69	112.722
1332.87	113.068
1336.06	111.518
1339.24	112.082
1342.42	108.711
1345.6	105.814
1348.78	103.58
1351.96	101.669
1355.13	99.1111
1358.31	97.2037
1361.48	94.1202
1364.65	92.0986
1367.82	90.4706
1370.99	88.2322
1374.16	86.3094
1377.33	85.7887
1380.5	85.1848
1383.66	83.9504
1386.83	81.9663
1389.99	79.8619
1393.15	79.3894
1396.31	79.7487
1399.47	78.9154
1402.63	79.039
1405.78	77.4691
1408.94	75.3605
1412.1	74.6971
1415.25	76.0455
1418.4	76.0195
1421.55	76.5047
1424.7	78.9729
1427.85	81.2275
1431	84.896
1434.14	87.8153
1437.29	88.8265
1440.43	92.317
1443.57	94.0977
1446.71	94.0272
1449.85	93.84
1452.99	93.7561
1456.13	92.4858
1459.26	83.1068
1462.4	82.9979
1465.54	81.4932
1468.67	79.203
1471.8	77.3799
1474.93	73.6224
1478.06	72.0378
1481.19	68.9892
1484.31	65.2686
1487.44	62.5115
1490.56	59.8554
1493.69	58.7316
1496.81	58.0848
1499.93	57.3592
1503.05	56.7517
1506.17	57.345
1509.28	58.23
1512.4	58.6079
1515.52	58.9112
1518.63	60.7454
1521.74	60.9941
1524.85	60.897
1527.96	61.0091
1531.07	60.4618
1534.18	60.0192
1537.29	62.4904
1540.39	70.4441
1543.5	74.5309
1546.6	78.5457
1549.7	82.9584
1552.8	88.835
1555.9	92.5264
1559	96.1327
1562.1	100.003
1565.19	103.246
1568.29	107.466
1571.38	110.699
1574.47	113.37
1577.56	115
1580.66	117.875
1583.74	119.784
1586.83	119.874
1589.92	120.306
1593.01	120.095
1596.09	119.978
1599.17	117.866
1602.25	115.191
1605.34	112.118
1608.41	109.618
1611.49	107.726
1614.57	105.855
1617.65	104.135
1620.72	102.211
1623.79	98.7144
1626.87	97.3764
1629.94	96.2758
1633.01	93.6085
1636.08	93.2764
1639.15	92.3909
1642.21	92.3403
1645.28	90.9768
1648.34	89.0362
1651.41	87.685
1654.47	85.9878
1657.53	84.9519
1660.59	81.0008
1663.65	79.7891
1666.71	78.4341
1669.76	73.8894
1672.82	70.1999
1675.87	64.3431
1678.93	60.1804
1681.98	56.4529
1685.03	50.828
1688.08	46.3236
1691.13	41.4155
1694.17	35.2345
1697.22	31.1922
1700.27	27.0249
1703.31	24.4345
1706.35	22.0798
1709.39	20.7831
1712.43	18.864
1715.47	17.2274
1718.51	14.5345
1721.55	11.9808
1724.58	10.9084
1727.62	9.98558
1730.65	9.48279
1733.68	8.36761
1736.72	8.03866
1739.74	7.74819
1742.77	5.61269
1745.8	4.67273
1748.83	3.03815
1751.85	2.75507
1754.88	1.79333
1757.9	0.461148
1760.92	0.170406
1763.95	-0.936384
1766.96	-1.27477
1769.98	-1.15844
1773	-1.30595
1776.02	-0.601608
1779.03	-0.778948
1782.05	0.662127
1785.06	1.81159
1788.07	2.17408
1791.08	2.69937
1794.09	2.52138
1797.1	2.96601
1800.11	4.27012
1803.12	4.41191
1806.12	4.15133
1809.12	5.04162
1812.13	5.56923
1815.13	5.48916
1818.13	5.70911
1821.13	6.46761
1824.13	7.05534
1827.13	7.21811
1830.12	7.08795
1833.12	6.73424
1836.11	6.29651
1839.1	6.76146
1842.09	6.9553
1845.09	7.38544
1848.08	7.78408
1851.06	6.31909
1854.05	6.01941
1857.04	4.8359
1860.02	5.16008
1863.01	3.88855
1865.99	2.47227
1868.97	1.77448
1871.95	1.1904
1874.93	1.40135
1877.91	0.420894
1880.89	0.537908
1882.46	0.666036
1885.45	0.443446
1888.43	0.923852
1891.42	2.15564
1894.41	3.06171
1897.39	2.9158
1900.37	3.23221
1903.36	3.37586
1906.34	3.82223
1909.32	4.44693
1912.29	4.76175
1915.27	7.131
1918.25	7.53019
1921.23	6.85302
1924.2	5.68617
1927.17	7.19358
1930.15	8.17819
1933.12	8.0268
1936.09	7.0278
1939.06	5.83941
1942.02	6.07727
1944.99	6.41947
1947.96	5.81769
1950.92	4.95593
1953.88	4.79829
1956.85	3.95032
1959.81	3.74691
1962.77	3.89658
1965.73	4.12508
1968.69	3.43281
1971.64	3.56566
1974.6	4.3153
1977.55	4.04148
1980.51	4.00502
1983.46	3.96435
1986.41	5.4426
1989.36	6.49258
1992.31	6.25027
1995.26	5.88391
1998.21	6.852
2001.15	7.6401
2004.1	7.02047
2007.04	7.52769
2009.99	7.53284
2012.93	7.60688
2015.87	8.0205
2018.81	8.84957
2021.75	8.95551
2024.68	9.65118
2027.62	9.68119
2030.56	9.65414
2033.49	9.84234
2036.42	9.71228
2039.36	9.76606
2042.29	8.82491
2045.22	8.22184
2048.14	7.55943
2051.07	6.83459
2054	6.60601
2056.93	6.78534
2059.85	7.22998
2062.77	7.3926
2065.7	6.45249
2068.62	6.26285
2071.54	7.68001
2074.46	7.71825
2077.38	8.23645
2080.29	8.02826
2083.21	7.37284
2086.12	8.71515
2089.04	8.98991
2091.95	9.93317
2094.86	10.7539
2097.77	10.8795
2100.68	11.083
2103.59	10.9482
2106.5	12.1082
2109.41	12.5237
2112.31	14.5368
2115.21	15.5961
2118.12	16.1949
2121.02	17.834
2123.92	19.2496
2126.82	20.6586
2129.72	23.2404
2132.62	24.8995
2135.51	27.3454
2138.41	28.63
2141.31	30.6371
2144.2	32.7143
2147.09	34.2575
2149.98	35.1182
2152.87	36.8571
2155.76	37.3885
2158.65	39.1747
2161.54	41.6972
2164.43	42.4206
2167.31	43.3241
2170.2	43.8925
2173.08	44.6566
2175.96	44.4395
2178.84	44.2742
2181.72	42.8762
2184.6	41.0357
2187.48	40.3012
2190.36	39.2929
2193.23	39.4156
2196.11	38.9733
2198.98	37.5239
2201.85	36.8444
2204.72	34.1829
2207.59	32.9235
2210.46	29.8117
2213.33	28.2795
2216.2	26.2819
2219.07	25.1942
2221.93	23.4027
2224.8	22.3422
2227.66	21.6575
2230.52	20.7794
2233.39	19.6488
2236.25	17.3028
2239.1	15.9081
2241.96	14.6229
2244.82	13.5268
2247.68	11.718
2250.53	11.0823
2253.38	11.6683
2256.24	12.436
2259.09	12.2241
2261.94	12.6525
2264.79	12.1176
2267.64	12.0155
2270.49	11.2644
2273.33	10.721
2276.18	9.14135
2279.02	8.71293
2281.87	7.92601
2284.71	8.20675
2287.55	9.06105
2290.39	8.8955
2293.23	7.75603
2296.07	7.52688
2298.91	7.85927
2301.74	8.56894
2304.58	8.60484
2307.41	9.11571
2310.25	9.67596
2313.08	10.522
2315.91	11.641
2318.74	12.0566
2321.57	11.8962
2324.4	11.2148
2327.23	11.6719
2330.05	10.0527
2332.88	9.69285
2335.7	10.396
2338.52	9.04534
2341.35	8.4127
2344.17	7.43162
2346.99	5.89872
2349.81	4.86426
2352.62	3.92157
2355.44	2.90646
2358.26	2.50616
2361.07	1.63378
2363.89	2.22802
2366.7	3.18955
2369.51	2.86158
2372.32	2.33706
2375.13	2.68877
2377.94	3.32068
2380.75	3.36837
2383.56	3.18254
2386.36	1.64859
2389.17	1.85391
2391.97	2.14834
2394.77	2.81764
2397.58	2.40338
2400.38	2.1475
2403.18	3.33944
2405.97	2.66425
2408.77	2.98472
2411.57	3.1816
2414.37	3.02816
2417.16	3.6238
2419.95	3.67496
2422.75	4.59929
2425.54	4.59
2428.33	5.29925
2431.12	5.7156
2433.91	5.22614
2436.7	5.63945
2439.48	6.31177
2442.27	6.26989
2445.05	5.32206
2447.84	3.91928
2450.62	3.14721
2453.4	1.88782
2456.18	1.59371
2458.96	1.54111
2461.74	0.907283
2464.52	0.547132
2467.29	0.275086
2470.07	0.40855
2472.85	1.01904
2475.62	2.06645
2478.39	2.85156
2481.16	2.2952
2483.93	3.20971
2486.7	3.33556
2489.47	4.12455
2492.24	3.93736
2495.01	3.38139
2497.77	4.30239
2500.54	4.02507
2503.3	4.77908
2506.06	5.42874
2508.83	4.74514
2511.59	5.09256
2514.35	4.75888
2517.11	5.41933
2519.86	5.41845
2522.62	5.26737
2525.38	5.95959
2528.13	6.25045
2530.89	6.27192
2533.64	7.01948
2536.39	7.50315
2539.14	7.48207
2541.89	7.89252
2544.64	7.37342
2547.39	6.82972
2550.14	5.71738
2552.88	5.44685
2555.63	4.5802
2558.37	5.55054
2561.11	5.68396
2563.86	5.4683
2566.6	5.17212
2569.34	5.71967
2572.08	6.31999
2574.82	5.12356
2577.55	5.11447
2580.29	4.70852
2583.02	4.88774
2585.76	5.44772
2588.49	4.95755
2591.22	4.99288
2593.96	5.0151
2596.69	4.40566
2599.42	4.84378
2602.14	4.5432
2604.87	3.5167
2607.6	2.70594
2610.32	3.22525
2613.05	3.33083
2615.77	2.64616
2618.49	2.66296
2621.22	3.58428
2623.94	4.48609
2626.66	5.13104
2629.37	4.25116
2632.09	3.89381
2634.81	4.89115
2637.53	5.89494
2640.24	6.57267
2642.96	5.6718
2645.67	6.59289
2648.38	7.05416
2651.09	8.07511
2653.8	7.75937
2656.51	8.33018
2659.22	8.44709
2661.93	9.04812
2664.63	10.1255
2667.34	11.2417
2670.04	11.6004
2672.75	12.6521
2675.45	13.3387
2678.15	13.8522
2680.85	12.7646
2683.55	13.6514
2686.25	14.7706
2688.94	15.2547
2691.64	15.5325
2694.34	16.0013
2697.03	16.2216
2699.73	18.1166
2702.42	18.7785
2705.11	18.851
2707.8	18.5593
2710.49	18.7348
2713.18	18.9387
2715.87	18.6678
2718.55	18.6125
2721.24	18.972
2723.93	19.2468
2726.61	18.7181
2729.29	18.7899
2731.98	17.3801
2734.66	16.2685
2737.34	15.1923
2740.02	13.7434
2742.7	11.6003
2745.37	9.10835
2748.05	8.73625
2750.72	7.99056
2753.4	7.26391
2756.07	6.1829
2758.75	6.09817
2761.42	6.3323
2764.09	5.89368
2766.76	5.61418
2769.43	6.10234
2772.1	6.98349
2774.76	5.8294
2777.43	5.21595
2780.1	5.09799
2782.76	4.68685
2785.42	5.26857
2788.09	5.99743
2790.75	5.77428
2793.41	5.56148
2796.07	5.165
2798.73	4.13323
2801.39	3.57042
2804.04	2.65399
2806.7	3.08313
2809.35	1.71346
2812.01	2.50239
2814.66	2.77987
2817.31	3.3897
2819.96	3.58278
2822.61	5.78009
2825.26	8.55281
2827.91	11.5713
2830.56	14.6565
2833.21	17.4157
2835.85	21.4394
2838.5	23.9912
2841.14	28.4004
2843.78	32.7555
2846.42	38.1171
2849.06	44.3981
2851.71	51.1874
2854.34	57.5354
2856.98	64.3131
2859.62	70.8968
2862.26	76.2367
2864.89	81.5161
2867.53	87.3502
2870.16	92.7658
2872.79	96.1547
2875.42	99.3757
2878.05	101.891
2880.68	104.706
2883.31	107.546
2885.94	110.743
2888.57	115.392
2891.19	119.07
2893.82	122.135
2896.44	124.716
2899.07	129.277
2901.69	133.507
2904.31	139.16
2906.93	146.528
2909.55	153.655
2912.17	162.97
2914.79	171.551
2917.41	179.039
2920.02	185.163
2922.64	191.36
2925.25	194.518
2927.86	196.729
2930.48	197.857
2933.09	197.255
2935.7	194.599
2938.31	190.591
2940.92	186.479
2943.53	181.318
2946.13	175.197
2948.74	169.572
2951.34	163.229
2953.95	156.537
2956.55	148.365
2959.15	141.363
2961.75	133.907
2964.35	127.082
2966.95	120.71
2969.55	116.45
2972.15	111.267
2974.75	106.797
2977.34	100.837
2979.94	93.8341
2982.53	86.7994
2985.13	79.9159
2987.72	72.2146
2990.31	65.3682
2992.9	57.8357
2995.49	51.0161
2998.08	44.144
3000.67	37.5586
3003.25	31.3489
3005.84	25.5995
3008.42	20.7915
3011.01	16.7871
3013.59	14.0994
3016.17	10.6935
3018.76	8.22656
3021.34	5.95736
3023.92	4.22973
3026.49	2.56252
3029.07	1.92698
3031.65	2.3008
3034.23	2.03103
3036.8	2.85493
3039.38	4.14865
3041.95	5.26988
3044.52	7.48498
3047.09	7.06649
3049.66	8.10358
3052.23	8.99167
3054.8	10.0223
3057.37	10.2109
3059.94	10.3092
3062.5	10.6201
3065.07	9.08487
3067.63	7.93319
3070.2	7.1014
3072.76	6.57784
3075.32	5.85716
3077.88	4.34859
3080.44	3.05165
3083	1.92599
3085.56	0.97453
3088.12	-0.672654
3090.67	-0.656952
3093.23	-0.535847
3095.78	-1.23126
3098.34	-1.38733
3100.89	-0.0219173
3103.44	0.223284
3105.99	0.352285
3108.54	-0.357027
3111.09	-0.368648
3113.64	0.249849
3116.19	0.411473
3118.74	1.47541
3121.28	2.03227
3123.83	1.7414
3126.37	2.13576
3128.91	1.73803
3131.46	2.73661
3134	3.65705
3136.54	5.11078
3139.08	6.56046
3141.62	8.33236
3144.16	10.7015
3146.69	13.5396
3149.23	17.3742