File: data/Raman/poly_smoothed/Thy_30_10_26_1x_45s_532 nm_x100_100%_600 gr_mm_01.txt
#Acq. time (s)=	45
#Accumulations=	2
#Range (cm-¹)=	200...3150
#Windows=	2
#Auto scanning=	Off
#Autofocus=	Off
#Macrospot=	Off
#AutoExposure=	Off
#Spike filter=	Multiple accum.
#Delay time (s)=	0
#Binning=	1
#Readout mode=	Signal
#DeNoise=	Off
#ICS correction=	On
#Dark correction=	Off
#Inst. Process=	Off
#Detector Gain=	Best Dynamic Range
#Detector ADC=	20 kHz
#Detector temperature (°C)=	-69.85
#Instrument=	LabRAM HR Evol
#Detector=	Synapse
#Objective=	x100
#Grating=	600 gr/mm
#ND Filter=	100%
#Laser (nm)=	532
#Hole=	100.021
#Range=	Auto
#Laser Pol.=	No
#Raman. Pol.=	No
#Laser Pol. (°)=	-0.0007625
#Raman Pol. (°)=	89.9995
#Collection=	Microscope
#StageXY=	Marzhauser
#StageZ=	Marzhauser
#X (µm)=	4767.3
#Y (µm)=	-7713.5
#Z (µm)=	584.7
#Full time(mm:ss)=	3:18
#Project=
#Sample=
#Site=
#Title=	Thy_30_10_26_2x_45s_532 nm_x100_100%_600 gr_mm
#Remark=
#Date=	30.06.2022 13:21
#Acquired=	30.06.2022 13:21:17
#Base:Fit=	10.08.2022 09:58:11
#Base:Sub=	10.08.2022 09:58:44
#Filter:Polynom=	16.08.2022 10:22:53
#AxisType[0]=Intens
#AxisUnit[0]=Cnt
#AxisType[1]=Spectr
#AxisUnit[1]=1/cm
200.533	8.37013
204.162	6.17101
207.792	5.20388
211.418	4.11138
215.044	3.19139
218.667	2.18128
222.289	3.4969
225.912	3.96691
229.531	2.85046
233.148	1.25953
236.766	1.51631
240.381	2.49956
243.994	2.78955
247.606	2.82854
251.217	3.04305
254.828	4.88008
258.436	4.98306
262.042	5.27525
265.647	6.81001
269.25	7.7761
272.852	8.1324
276.453	8.48999
280.052	8.5974
283.65	8.3187
287.247	11.1104
290.842	13.1216
294.436	15.034
298.028	15.9384
301.617	16.4187
305.206	18.4302
308.794	19.4432
312.381	20.3731
315.964	21.1971
319.548	20.1024
323.131	21.898
326.71	23.1167
330.29	22.5475
333.868	21.3533
337.443	19.9533
341.018	17.8037
344.591	17.131
348.163	15.6453
351.733	14.4895
355.303	12.8125
358.869	12.161
362.435	11.2557
366.001	11.7897
369.563	13.0795
373.124	14.9214
376.686	15.3664
380.244	14.9349
383.801	14.9263
387.357	15.0027
390.911	14.4773
394.466	13.6
398.018	14.374
401.568	14.2008
405.117	13.0075
408.664	11.0435
412.21	10.5787
415.755	8.34194
419.298	6.97233
422.84	7.42438
426.38	6.90112
429.919	6.16046
433.455	7.24469
436.992	7.69765
440.527	8.16678
444.06	8.71925
447.593	10.3124
451.122	11.8377
454.651	13.548
458.18	15.3841
461.705	16.8941
465.23	16.8914
468.752	17.2613
472.275	18.3143
475.797	18.4047
479.315	19.0451
482.834	20.0618
486.349	20.6624
489.863	19.9239
493.378	19.7668
496.889	20.9902
500.401	21.8767
503.91	23.6126
507.417	24.1835
510.923	23.8316
514.43	24.4636
517.933	24.2925
521.435	24.9127
524.936	24.0359
528.435	24.0063
531.933	24.6019
535.43	23.5826
538.927	22.7211
542.421	21.8518
545.913	20.3396
549.403	18.4094
552.893	18.1549
556.381	17.6843
559.868	18.2763
563.354	16.3818
566.839	15.4323
570.322	14.0056
573.802	12.2461
577.283	11.0651
580.762	11.1137
584.24	9.9853
587.714	8.18847
591.19	7.93202
594.663	6.7995
598.134	5.06077
601.605	4.89496
605.073	4.08191
608.542	3.93819
612.007	4.4832
615.473	5.4514
618.936	5.03227
622.397	4.78968
625.859	4.69599
629.318	5.54555
632.775	6.41641
636.233	8.4697
639.688	10.9775
643.142	12.5641
646.594	11.6711
650.045	12.8701
653.496	13.1793
656.944	11.866
660.391	13.3449
663.837	14.2129
667.281	14.3852
670.724	15.0657
674.166	16.0839
677.606	16.3968
681.045	15.6621
684.483	15.5963
687.917	15.9153
691.352	17.1823
694.786	17.9454
698.219	19.2116
701.65	18.876
705.078	21.1176
708.506	24.1319
711.934	24.5163
715.358	26.1947
718.782	28.4601
722.204	31.6154
725.626	34.0829
729.045	36.5939
732.464	37.3611
735.881	39.2056
739.297	42.3652
742.711	45.783
746.125	49.1918
749.537	54.0267
752.946	58.5549
756.357	62.094
759.764	64.9044
763.17	67.5551
766.575	69.2124
769.978	71.647
773.382	74.4063
776.783	74.2634
780.182	75.9045
783.581	77.3427
786.978	78.4221
790.373	78.187
793.768	78.3757
797.161	77.2256
800.552	78.3847
803.941	79.528
807.33	79.9437
810.718	79.6779
814.105	79.0005
817.49	78.5989
820.873	78.3979
824.256	78.3679
827.637	76.925
831.016	75.2375
834.395	74.3296
837.772	71.5557
841.147	70.9442
844.522	68.5275
847.894	63.7392
851.267	61.7233
854.637	59.3131
858.007	55.1283
861.374	54.3181
864.739	53.0117
868.106	49.579
871.469	48.2706
874.831	47.9787
878.193	47.9232
881.553	48.5746
884.911	48.0886
888.268	48.1068
891.623	48.4392
894.978	48.5899
898.331	49.5364
901.683	48.8237
905.033	47.6861
908.383	46.407
911.731	45.3248
915.078	44.5209
918.423	43.576
921.768	43.5693
925.111	43.7976
928.452	42.4808
931.791	41.7348
935.13	42.1128
938.468	40.8092
941.803	39.5983
945.139	39.5111
948.473	38.3164
951.804	39.6566
955.136	41.0336
958.465	41.5776
961.794	41.6036
965.12	42.1996
968.447	43.6064
971.771	44.7426
975.095	45.2232
978.417	46.0252
981.737	45.5367
985.057	45.1968
988.375	44.5876
991.691	44.7966
995.006	45.539
998.32	45.5819
1001.63	46.6931
1004.95	48.655
1008.26	49.16
1011.56	49.6398
1014.87	48.9329
1018.18	48.0426
1021.48	47.6141
1024.79	46.9598
1028.09	48.3127
1031.39	49.1924
1034.69	49.3241
1037.99	47.1815
1041.29	44.9987
1044.58	44.7407
1047.88	44.8908
1051.17	41.0065
1054.46	40.0521
1057.75	38.1811
1061.04	35.6305
1064.33	32.2766
1067.62	31.5373
1070.9	30.9402
1074.19	31.3057
1077.47	31.5848
1080.76	31.1953
1084.04	31.1818
1087.32	30.8166
1090.59	29.7871
1093.87	28.9194
1097.15	28.1255
1100.42	28.1338
1103.69	27.4119
1106.97	27.7041
1110.24	27.0663
1113.51	24.3525
1116.77	23.0162
1120.04	20.2836
1123.31	18.9767
1126.57	17.9381
1129.83	15.858
1133.1	14.7155
1136.36	12.889
1139.62	12.1601
1142.87	12.6861
1146.13	11.7032
1149.38	12.5509
1152.64	10.5864
1155.89	9.33543
1159.14	8.00156
1162.39	7.41408
1165.64	7.74393
1168.89	6.35052
1172.14	5.49922
1175.38	5.15082
1178.63	4.1444
1181.87	4.00055
1185.11	2.79667
1188.35	3.47098
1191.59	2.94641
1194.83	3.53456
1198.07	4.42057
1201.3	4.96335
1204.53	6.08832
1207.77	7.99354
1211	11.1793
1214.23	14.0002
1217.46	16.6319
1220.69	19.4482
1223.91	21.4908
1227.14	24.5352
1230.36	26.6695
1233.59	30.3976
1236.81	34.1644
1240.03	36.1673
1243.25	38.5326
1246.46	39.02
1249.68	39.9087
1252.9	41.1722
1256.11	40.092
1259.32	40.9521
1262.54	42.9998
1265.75	43.0621
1268.96	43.2869
1272.16	42.5569
1275.37	44.2429
1278.57	46.6025
1281.78	48.1837
1284.98	49.0869
1288.18	51.6922
1291.38	53.4517
1294.58	55.1161
1297.78	55.5291
1300.98	56.4594
1304.17	58.6862
1307.37	60.5513
1310.56	63.2713
1313.76	65.7986
1316.95	66.7872
1320.14	66.87
1323.32	65.8952
1326.51	64.9631
1329.7	64.1271
1332.88	62.0364
1336.07	60.0955
1339.25	57.8253
1342.43	54.5052
1345.61	50.798
1348.79	47.1473
1351.96	45.1997
1355.14	43.1894
1358.31	40.0306
1361.49	36.6143
1364.66	33.1837
1367.83	30.5346
1371	28.9399
1374.17	26.1441
1377.34	24.1074
1380.5	22.3804
1383.67	22.097
1386.83	22.6643
1390	23.5826
1393.16	24.4989
1396.32	24.7521
1399.48	24.8543
1402.64	25.5135
1405.79	27.8138
1408.95	29.8768
1412.1	31.3404
1415.26	33.1725
1418.41	35.6109
1421.56	38.3895
1424.71	43.2207
1427.86	46.6496
1431	49.5862
1434.15	52.3914
1437.29	56.054
1440.44	58.6127
1443.58	58.8643
1446.72	59.5446
1449.86	59.8903
1453	58.004
1456.14	56.1093
1459.27	52.237
1462.41	49.1651
1465.54	45.6797
1468.67	41.161
1471.81	35.8064
1474.94	30.3224
1478.07	26.2922
1481.19	21.5144
1484.32	18.4314
1487.45	14.79
1490.57	10.4532
1493.69	8.26435
1496.82	6.48172
1499.94	6.22488
1503.06	5.10546
1506.17	4.55651
1509.29	5.11221
1512.41	6.22327
1515.52	5.60133
1518.64	5.26569
1521.75	5.87265
1524.86	6.45447
1527.97	8.16379
1531.08	7.68609
1534.19	9.47914
1537.29	10.4486
1540.4	12.649
1543.5	14.4877
1546.61	15.7243
1549.71	17.3629
1552.81	20.6921
1555.91	23.9311
1559.01	25.8782
1562.11	27.8161
1565.2	29.1353
1568.29	30.6369
1571.39	34.0784
1574.48	36.4008
1577.57	37.4368
1580.66	38.7615
1583.75	41.2362
1586.84	42.2818
1589.93	42.8881
1593.01	42.9635
1596.1	43.6709
1599.18	44.1763
1602.26	43.9785
1605.34	43.196
1608.42	42.7954
1611.5	43.8201
1614.58	44.7001
1617.65	45.665
1620.73	46.8021
1623.8	47.9029
1626.87	50.3
1629.95	52.3781
1633.02	52.6399
1636.09	53.9254
1639.15	54.924
1642.22	57.0411
1645.29	59.5623
1648.35	61.852
1651.42	63.335
1654.48	65.1111
1657.54	65.9762
1660.6	64.4634
1663.66	63.3414
1666.72	62.054
1669.77	59.2582
1672.83	55.5486
1675.88	52.4767
1678.93	47.3455
1681.99	43.0066
1685.04	40.0849
1688.09	35.2026
1691.13	30.3872
1694.18	25.7332
1697.23	21.6443
1700.27	17.8896
1703.32	14.6657
1706.36	11.3596
1709.4	9.08277
1712.44	6.78569
1715.48	6.57001
1718.52	5.02788
1721.56	5.16164
1724.59	4.60079
1727.63	4.55959
1730.66	5.17143
1733.69	4.03038
1736.72	4.01053
1739.75	4.33788
1742.78	4.42953
1745.81	4.56115
1748.84	4.01309
1751.86	4.08868
1754.89	4.08761
1757.91	4.09172
1760.93	3.20691
1763.95	2.61668
1766.97	2.11092
1769.99	2.44201
1773.01	2.33604
1776.03	1.73173
1779.04	2.4684
1782.06	1.61109
1785.07	1.09063
1788.08	0.913351
1791.09	0.456034
1794.1	-0.00655879
1797.11	0.300106
1800.12	0.0979532
1803.12	0.10565
1806.13	-0.700778
1809.13	-1.68502
1812.14	-1.26074
1815.14	-0.665103
1818.14	-0.715941
1821.14	-0.562864
1824.14	-0.591843
1827.13	-0.624252
1830.13	-0.287247
1833.12	-0.367429
1836.12	0.127699
1839.11	0.156265
1842.1	1.59216
1845.09	1.96226
1848.08	2.37918
1851.07	3.16456
1854.06	3.0116
1857.04	2.62605
1860.03	2.88363
1863.01	3.1353
1866	3.88893
1868.98	3.65722
1871.96	3.24888
1874.94	3.52853
1877.92	4.04735
1880.89	3.15524
1882.48	3.14449
1885.47	3.66295
1888.46	4.34155
1891.44	3.59033
1894.43	3.88797
1897.41	3.41574
1900.4	3.22221
1903.38	3.47363
1906.36	3.59837
1909.34	4.59509
1912.32	5.33388
1915.29	4.58811
1918.27	4.38161
1921.25	4.88068
1924.22	4.94095
1927.2	4.06936
1930.17	3.96458
1933.14	4.3922
1936.11	4.36459
1939.08	3.84205
1942.05	2.65303
1945.01	3.44695
1947.98	3.79974
1950.94	3.06193
1953.91	3.83832
1956.87	4.96182
1959.83	4.36047
1962.79	4.88156
1965.75	6.23078
1968.71	7.31527
1971.67	8.06203
1974.62	9.1185
1977.58	9.8795
1980.53	10.9914
1983.48	12.3034
1986.43	12.4425
1989.38	12.7207
1992.33	12.6509
1995.28	12.2602
1998.23	11.7354
2001.18	11.2518
2004.12	11.8478
2007.06	11.7064
2010.01	11.7062
2012.95	12.2761
2015.89	13.1733
2018.83	13.8668
2021.77	14.6177
2024.71	15.5806
2027.64	16.2894
2030.58	17.1521
2033.51	17.7009
2036.45	19.86
2039.38	19.8972
2042.31	19.992
2045.24	19.6178
2048.17	19.4464
2051.1	20.2328
2054.02	20.4171
2056.95	19.3894
2059.87	18.3947
2062.8	17.9191
2065.72	18.0053
2068.64	17.553
2071.56	18.6339
2074.48	18.6451
2077.4	18.7021
2080.31	19.2605
2083.23	20.5232
2086.14	22.0318
2089.06	23.7424
2091.97	25.6752
2094.88	27.5683
2097.79	29.8825
2100.7	31.4747
2103.61	33.229
2106.52	35.0338
2109.43	36.0563
2112.33	38.8287
2115.24	41.3479
2118.14	44.5425
2121.04	47.4458
2123.94	49.5399
2126.84	51.5226
2129.74	53.9886
2132.64	56.9112
2135.54	59.5093
2138.43	62.3115
2141.33	65.3856
2144.22	68.6493
2147.11	70.8152
2150.01	73.3663
2152.9	76.5339
2155.79	79.2539
2158.67	81.2554
2161.56	82.1762
2164.45	83.7874
2167.33	85.0181
2170.22	86.5495
2173.1	86.7453
2175.98	86.3439
2178.86	86.6076
2181.74	85.7542
2184.62	84.9982
2187.5	83.2382
2190.38	80.2749
2193.25	77.9111
2196.13	74.648
2199	72.2623
2201.88	69.4458
2204.75	66.2698
2207.62	63.0293
2210.49	60.1017
2213.36	56.6388
2216.22	53.5401
2219.09	50.1037
2221.96	47.0639
2224.82	43.9081
2227.68	41.3461
2230.55	39.1647
2233.41	37.7443
2236.27	36.9357
2239.12	36.1971
2241.98	36.0362
2244.84	35.3438
2247.7	35.327
2250.55	34.4352
2253.41	33.4874
2256.26	32.675
2259.11	32.7918
2261.96	32.95
2264.81	32.4744
2267.66	31.6689
2270.51	30.6478
2273.35	30.0676
2276.2	27.6031
2279.04	26.4608
2281.89	24.715
2284.73	23.242
2287.57	21.2562
2290.41	19.7991
2293.25	17.0068
2296.09	17.1767
2298.93	17.0537
2301.76	16.2224
2304.6	16.5859
2307.44	17.1507
2310.27	18.0773
2313.1	19.0331
2315.93	19.0984
2318.76	18.9019
2321.59	18.9215
2324.42	19.3245
2327.25	20.0095
2330.07	20.1688
2332.9	19.1411
2335.72	18.0595
2338.55	15.9462
2341.37	15.0902
2344.19	14.0515
2347.01	13.8933
2349.83	11.6481
2352.65	9.71233
2355.46	9.42587
2358.28	8.72142
2361.09	7.7415
2363.91	7.99777
2366.72	8.89711
2369.53	8.89693
2372.34	9.52675
2375.15	10.6434
2377.96	11.2532
2380.77	10.8817
2383.58	10.6916
2386.38	10.3935
2389.19	11.2531
2391.99	11.3793
2394.8	11.22
2397.6	11.6557
2400.4	11.3522
2403.2	10.9024
2406	10.8543
2408.79	9.99679
2411.59	10.2818
2414.39	10.4021
2417.18	9.62204
2419.98	10.0016
2422.77	10.9123
2425.56	11.3833
2428.35	11.262
2431.14	11.3187
2433.93	12.0532
2436.72	11.791
2439.5	11.3098
2442.29	11.1655
2445.07	10.4101
2447.86	9.48968
2450.64	9.40443
2453.42	9.19668
2456.2	7.79727
2458.98	7.91766
2461.76	8.22782
2464.54	7.3624
2467.32	6.73647
2470.09	6.16039
2472.87	5.72201
2475.64	4.9789
2478.41	3.91677
2481.18	3.00485
2483.95	3.74071
2486.72	3.92429
2489.49	4.36817
2492.26	3.95605
2495.03	3.02451
2497.79	3.67806
2500.56	3.40029
2503.32	2.077
2506.09	1.87245
2508.85	1.76866
2511.61	1.68615
2514.37	0.761127
2517.13	0.549409
2519.89	-0.0183011
2522.64	-0.903829
2525.4	-0.142343
2528.15	0.543463
2530.91	1.06236
2533.66	0.666402
2536.41	0.656163
2539.16	0.833909
2541.91	0.974585
2544.66	0.997514
2547.41	0.475824
2550.16	0.748622
2552.9	1.66561
2555.65	1.41487
2558.39	1.58812
2561.13	1.64263
2563.88	2.67601
2566.62	4.01797
2569.36	3.76788
2572.1	4.76782
2574.84	5.84006
2577.57	5.61515
2580.31	5.04955
2583.05	5.50581
2585.78	5.6139
2588.51	6.71071
2591.24	6.45308
2593.98	6.55564
2596.71	6.05513
2599.44	5.36982
2602.16	5.07052
2604.89	4.73506
2607.62	4.62887
2610.34	3.65548
2613.07	1.97237
2615.79	1.8234
2618.52	1.06748
2621.24	1.19283
2623.96	0.779223
2626.68	0.823595
2629.4	1.24075
2632.11	1.44628
2634.83	1.31035
2637.55	1.55225
2640.26	1.9765
2642.98	2.83725
2645.69	2.7247
2648.4	3.42955
2651.11	3.26318
2653.82	3.31829
2656.53	2.9375
2659.24	2.58024
2661.95	2.75306
2664.65	2.53504
2667.36	2.53216
2670.06	2.67103
2672.76	2.395
2675.47	2.54063
2678.17	1.40848
2680.87	1.01408
2683.57	0.542479
2686.27	-0.0383201
2688.97	-0.556108
2691.66	-0.515768
2694.36	-0.263387
2697.05	0.177838
2699.75	0.703611
2702.44	1.34661
2705.13	1.95224
2707.82	3.48762
2710.51	4.65136
2713.2	5.45086
2715.89	5.89399
2718.57	6.61763
2721.26	6.9978
2723.95	7.26622
2726.63	7.38984
2729.31	7.72783
2732	7.73456
2734.68	8.32643
2737.36	8.2132
2740.04	8.07237
2742.72	6.50584
2745.39	5.40584
2748.07	3.76959
2750.75	3.36179
2753.42	2.50557
2756.09	1.69436
2758.77	1.20809
2761.44	0.578735
2764.11	0.163912
2766.78	-0.0634566
2769.45	0.148175
2772.12	-0.34233
2774.78	0.395174
2777.45	0.11655
2780.12	0.0374703
2782.78	0.401114
2785.44	0.700656
2788.11	0.765935
2790.77	1.34946
2793.43	1.96286
2796.09	1.8781
2798.75	3.24067
2801.4	3.20854
2804.06	3.6615
2806.72	3.7709
2809.37	3.26712
2812.03	3.18794
2814.68	3.72648
2817.33	4.32041
2819.98	5.05734
2822.63	6.86008
2825.28	9.38325
2827.93	12.9512
2830.58	16.7259
2833.23	20.2305
2835.87	23.8357
2838.52	29.0284
2841.16	34.3618
2843.8	40.5863
2846.44	47.0704
2849.08	54.2756
2851.73	63.6434
2854.36	72.1435
2857	81.3719
2859.64	90.4523
2862.28	99.743
2864.91	107.534
2867.55	115.039
2870.18	122.393
2872.81	128.48
2875.44	133.211
2878.07	137.657
2880.7	141.599
2883.33	146.297
2885.96	151.34
2888.59	155.682
2891.21	160.969
2893.84	165.274
2896.46	169.777
2899.09	174.311
2901.71	180.623
2904.33	189.037
2906.95	197.403
2909.57	206.567
2912.19	218.074
2914.81	229.809
2917.43	240.798
2920.04	250.945
2922.66	259.252
2925.27	265.627
2927.88	270.918
2930.5	272.962
2933.11	272.852
2935.72	271.145
2938.33	268.619
2940.94	263.176
2943.54	256.671
2946.15	249.492
2948.76	240.738
2951.36	231.077
2953.97	221.424
2956.57	211.362
2959.17	200.33
2961.77	190.112
2964.37	181.285
2966.97	172.905
2969.57	163.197
2972.17	154.936
2974.77	147.033
2977.36	139.06
2979.96	131.311
2982.55	123.761
2985.15	114.546
2987.74	105.754
2990.33	96.6944
2992.92	87.5313
2995.51	79.6089
2998.1	72.1193
3000.69	65.37
3003.27	57.9859
3005.86	51.7615
3008.44	46.1906
3011.03	41.1275
3013.61	37.1941
3016.19	34.2234
3018.78	32.174
3021.36	28.6787
3023.94	25.8487
3026.51	24.6143
3029.09	23.5472
3031.67	22.8942
3034.24	23.0431
3036.82	23.6795
3039.39	24.4237
3041.97	25.6624
3044.54	27.6245
3047.11	27.3605
3049.68	27.7311
3052.25	28.1922
3054.82	28.0276
3057.39	28.3629
3059.96	28.5477
3062.52	26.746
3065.09	25.4651
3067.65	24.7865
3070.22	23.6724
3072.78	21.9825
3075.34	20.3953
3077.9	18.6243
3080.46	16.167
3083.02	13.7094
3085.58	11.9898
3088.14	10.6815
3090.69	9.34801
3093.25	8.50535
3095.8	7.52148
3098.36	7.07564
3100.91	6.80057
3103.46	7.12045
3106.01	8.06633
3108.56	7.67222
3111.11	8.25884
3113.66	8.04796
3116.21	8.024
3118.76	7.85023
3121.3	7.37127
3123.85	7.13442
3126.39	7.04516
3128.93	7.48457
3131.48	6.63558
3134.02	6.42799
3136.56	5.23199
3139.1	3.99407
3141.64	2.69267
3144.17	1.84622
3146.71	1.17812
3149.25	-0.396047