File: data/Raman/poly_smoothed/Thy_10_08_21_1x_45s_532 nm_x100_100%_600 gr_mm_01.txt
#Acq. time (s)=	45
#Accumulations=	2
#Range (cm-¹)=	200...3150
#Windows=	2
#Auto scanning=	Off
#Autofocus=	Off
#Macrospot=	Off
#AutoExposure=	Off
#Spike filter=	Multiple accum.
#Delay time (s)=	0
#Binning=	1
#Readout mode=	Signal
#DeNoise=	Off
#ICS correction=	On
#Dark correction=	Off
#Inst. Process=	Off
#Detector Gain=	Best Dynamic Range
#Detector ADC=	20 kHz
#Detector temperature (°C)=	-69.85
#Instrument=	LabRAM HR Evol
#Detector=	Synapse
#Objective=	x100
#Grating=	600 gr/mm
#ND Filter=	100%
#Laser (nm)=	532
#Hole=	100.021
#Range=	Auto
#Laser Pol.=	No
#Raman. Pol.=	No
#Laser Pol. (°)=	-0.0007625
#Raman Pol. (°)=	89.9995
#Collection=	Microscope
#StageXY=	Marzhauser
#StageZ=	Marzhauser
#X (µm)=	2199.9
#Y (µm)=	1239.9
#Z (µm)=	442.3
#Full time(mm:ss)=	3:18
#Project=
#Sample=
#Site=
#Title=	Thy_10_08_21_2x_45s_532 nm_x100_100%_600 gr_mm
#Remark=
#Date=	05.07.2022 15:40
#Acquired=	05.07.2022 15:40:29
#Base:Fit=	10.08.2022 09:46:25
#Base:Sub=	10.08.2022 09:46:49
#Filter:Polynom=	16.08.2022 10:24:56
#AxisType[0]=Intens
#AxisUnit[0]=Cnt
#AxisType[1]=Spectr
#AxisUnit[1]=1/cm
200.43	64.4883
204.059	65.315
207.688	60.9953
211.314	57.0939
214.941	50.8701
218.564	46.8249
222.186	44.7189
225.809	42.769
229.428	44.0327
233.045	43.6319
236.663	41.3311
240.278	40.0088
243.891	40.2844
247.503	40.2724
251.116	39.5663
254.725	37.1389
258.333	34.1189
261.939	30.1088
265.544	27.2313
269.148	27.1416
272.75	26.2167
276.351	26.3987
279.95	23.6425
283.548	20.1406
287.144	18.4985
290.739	16.2846
294.333	13.5984
297.925	14.0415
301.514	13.8738
305.104	14.8669
308.692	17.1601
312.279	20.4797
315.862	24.4408
319.446	25.4333
323.029	24.4482
326.608	24.1993
330.188	25.3342
333.766	27.7055
337.341	26.1108
340.917	24.2969
344.489	23.7066
348.062	23.2145
351.631	20.9305
355.201	18.0531
358.768	19.4702
362.333	17.0522
365.899	12.9481
369.462	9.41769
373.023	9.61247
376.585	10.471
380.143	11.2237
383.7	10.5762
387.256	12.9372
390.812	11.3751
394.365	10.5538
397.916	10.0897
401.467	10.5232
405.015	9.18363
408.563	8.21494
412.109	7.52871
415.654	9.02652
419.197	11.0776
422.739	12.2315
426.279	12.5272
429.819	13.4368
433.356	14.0589
436.891	11.528
440.426	10.743
443.96	10.6409
447.492	11.3904
451.021	10.6304
454.551	10.4279
458.079	12.9197
461.604	15.0263
465.13	15.1567
468.654	16.3887
472.175	18.2692
475.696	19.6975
479.215	20.7773
482.733	21.6587
486.249	23.1659
489.765	26.3271
493.278	26.9364
496.789	29.083
500.301	29.5637
503.81	30.8783
507.317	32.1328
510.825	32.3734
514.33	31.9304
517.833	30.5868
521.335	28.5224
524.836	28.2178
528.335	28.3084
531.835	27.6511
535.332	27.1308
538.827	25.231
542.321	22.1635
545.814	21.0653
549.305	19.8307
552.795	20.5522
556.282	20.0971
559.769	18.318
563.255	15.7433
566.739	13.1759
570.223	13.433
573.705	13.3716
577.183	11.788
580.663	10.6415
584.141	8.72988
587.615	8.06851
591.09	8.02562
594.564	5.18929
598.035	4.01236
601.506	1.60426
604.974	2.74509
608.443	3.97598
611.908	7.66777
615.374	8.86199
618.837	9.03978
622.3	7.55669
625.761	7.5071
629.219	7.72073
632.677	8.68402
636.135	9.7113
639.59	10.0279
643.043	9.00646
646.495	10.6036
649.948	11.9276
653.398	13.6905
656.846	15.7155
660.293	16.1327
663.738	17.262
667.183	17.991
670.626	17.5621
674.067	17.8868
677.508	18.4502
680.947	19.7574
684.385	21.3157
687.821	24.0475
691.254	26.4435
694.688	28.6102
698.121	29.9075
701.552	29.6314
704.98	29.6237
708.409	30.6383
711.836	31.442
715.26	32.8631
718.685	34.3116
722.108	35.8401
725.528	37.5829
728.949	39.9209
732.367	42.5113
735.785	44.6221
739.2	46.5651
742.614	51.7935
746.028	55.79
749.439	59.2298
752.849	60.9317
756.26	65.1628
759.667	68.6783
763.073	71.1647
766.477	73.6191
769.883	74.793
773.285	76.8325
776.686	76.6145
780.085	76.8091
783.484	77.7748
786.881	78.4248
790.276	78.417
793.671	78.5712
797.064	80.6698
800.456	81.5456
803.846	81.2964
807.234	82.1917
810.622	80.8142
814.008	81.3169
817.394	83.82
820.778	86.6194
824.159	89.6529
827.541	91.5545
830.921	90.6942
834.298	90.7012
837.676	90.2059
841.051	89.734
844.426	87.7383
847.798	85.5931
851.171	83.7901
854.54	82.534
857.911	80.1632
861.278	76.9798
864.645	75.1365
868.01	74.6842
871.373	74.2485
874.735	73.156
878.097	72.697
881.457	69.5187
884.815	67.8192
888.172	64.3717
891.528	63.1959
894.882	61.9614
898.237	61.4687
901.589	62.2072
904.94	60.113
908.289	59.1806
911.635	57.255
914.982	55.3444
918.328	54.536
921.672	53.5656
925.015	53.388
928.357	52.7884
931.698	53.2488
935.035	53.6869
938.373	52.699
941.71	52.2286
945.044	50.5324
948.378	50.4891
951.709	51.7779
955.041	50.0509
958.372	47.084
961.699	43.7798
965.027	44.8631
968.352	49.9194
971.676	54.9627
975	59.6348
978.322	63.2562
981.642	68.559
984.962	71.0711
988.28	72.2984
991.596	73.8349
994.911	75.0055
998.227	77.4368
1001.54	78.2991
1004.85	79.0672
1008.16	79.2071
1011.47	77.9542
1014.78	76.4403
1018.08	73.9146
1021.39	70.3632
1024.69	66.8892
1028	62.706
1031.3	58.6552
1034.6	53.2964
1037.9	47.6513
1041.19	42.4217
1044.49	44.4782
1047.78	46.5609
1051.08	47.3105
1054.37	44.0351
1057.66	41.4782
1060.95	38.777
1064.24	35.7356
1067.53	33.2445
1070.81	32.3956
1074.1	33.3002
1077.38	31.4319
1080.66	29.6909
1083.94	28.0869
1087.22	28.9135
1090.5	30.7051
1093.78	30.5214
1097.05	31.3547
1100.33	32.3948
1103.6	32.0939
1106.87	32.3004
1110.14	31.2336
1113.41	29.2301
1116.68	25.126
1119.95	23.5908
1123.21	22.1676
1126.48	18.6041
1129.74	16.1329
1133	13.2788
1136.26	10.3329
1139.52	8.94634
1142.78	8.06493
1146.04	6.85858
1149.29	5.98158
1152.55	5.96693
1155.8	4.95767
1159.05	3.53342
1162.3	0.964709
1165.55	-0.439496
1168.8	0.991072
1172.05	4.13994
1175.29	5.32262
1178.54	8.78765
1181.78	10.4356
1185.02	11.41
1188.26	14.5745
1191.5	16.2366
1194.74	17.8531
1197.97	23.2452
1201.21	30.3724
1204.44	35.4255
1207.68	41.8936
1210.91	51.0178
1214.14	60.1172
1217.37	68.3323
1220.59	78.3114
1223.82	84.5033
1227.05	91.7967
1230.27	95.9404
1233.49	102.034
1236.72	105.484
1239.94	107.465
1243.16	109.783
1246.37	114.397
1249.59	118.617
1252.8	118.841
1256.02	118.83
1259.23	117.811
1262.44	117.079
1265.66	117.74
1268.86	117.136
1272.07	119.025
1275.28	122.267
1278.48	127.586
1281.69	129.598
1284.89	131.675
1288.09	137.452
1291.29	141.823
1294.49	144.851
1297.69	147.407
1300.89	147.972
1304.08	150.153
1307.28	152.032
1310.47	153.583
1313.66	154.763
1316.85	154.926
1320.04	155.388
1323.23	153.621
1326.42	151.136
1329.61	146.6
1332.79	140.984
1335.97	136.994
1339.16	132.997
1342.34	129.844
1345.52	125.58
1348.7	121.624
1351.87	116.45
1355.05	111.388
1358.22	106.718
1361.4	100.81
1364.57	96.7579
1367.74	91.1907
1370.91	86.7956
1374.08	79.0789
1377.25	75.2505
1380.41	73.2492
1383.58	71.9988
1386.74	71.2313
1389.91	68.9102
1393.07	68.7714
1396.23	67.8181
1399.39	66.3547
1402.55	64.5906
1405.7	65.5688
1408.86	69.1674
1412.01	72.554
1415.17	79.2306
1418.32	87.7337
1421.47	99.048
1424.62	109.988
1427.77	123.356
1430.91	135.943
1434.06	149.389
1437.2	159.93
1440.35	168.307
1443.49	173.814
1446.63	178.227
1449.77	177.459
1452.91	176.88
1456.05	174.244
1459.18	167.678
1462.32	158.004
1465.45	145.449
1468.59	131.013
1471.72	116.883
1474.85	100.403
1477.98	83.522
1481.1	69.7046
1484.23	55.3691
1487.36	42.2076
1490.48	31.165
1493.61	25.0119
1496.73	20.2084
1499.85	18.5272
1502.97	18.1048
1506.09	17.452
1509.2	17.5434
1512.32	17.1442
1515.43	17.2778
1518.55	16.834
1521.66	19.7754
1524.77	23.1
1527.88	25.9281
1530.99	30.3098
1534.1	33.3104
1537.21	37.15
1540.31	40.5766
1543.42	45.6072
1546.52	50.5581
1549.62	55.3301
1552.72	59.4279
1555.82	63.3933
1558.92	67.5086
1562.02	71.6929
1565.11	75.7303
1568.21	81.863
1571.3	89.1691
1574.39	95.662
1577.49	101.544
1580.57	107.31
1583.66	112.75
1586.75	118.8
1589.84	124.24
1592.92	128.294
1596.01	131.073
1599.09	132.431
1602.17	133.021
1605.25	134.089
1608.33	134.649
1611.41	134.766
1614.49	134.23
1617.57	134.243
1620.64	134.67
1623.72	135.906
1626.79	138.134
1629.86	142.556
1632.93	146.66
1636	150.744
1639.07	156.246
1642.13	164.795
1645.2	172.093
1648.26	180.111
1651.33	185.837
1654.39	191.718
1657.45	195.395
1660.51	198.246
1663.57	198.549
1666.63	195.139
1669.68	191.322
1672.74	183.071
1675.79	174.923
1678.85	165.386
1681.9	154.217
1684.95	140.721
1688	126.547
1691.05	113.494
1694.09	100.238
1697.14	88.9119
1700.18	79.7802
1703.23	69.8788
1706.27	60.3515
1709.31	53.0265
1712.35	46.3817
1715.39	40.8525
1718.43	36.0622
1721.47	31.3428
1724.5	28.0157
1727.54	25.915
1730.57	24.1619
1733.61	22.8765
1736.64	22.6562
1739.67	21.8431
1742.7	21.4267
1745.72	19.9012
1748.75	17.7518
1751.77	16.1396
1754.8	13.9889
1757.82	11.6214
1760.84	10.4693
1763.87	8.59772
1766.89	8.2742
1769.91	7.46204
1772.92	6.52581
1775.94	4.69043
1778.95	3.06978
1781.97	3.34607
1784.98	2.70409
1787.99	2.2781
1791.01	2.27401
1794.01	1.67294
1797.02	0.904001
1800.03	0.10408
1803.04	0.542882
1806.04	0.119845
1809.05	0.341985
1812.05	0.795293
1815.05	0.689053
1818.05	0.298185
1821.05	-0.188465
1824.05	-0.00301214
1827.05	-0.146671
1830.04	-0.212544
1833.04	-0.959889
1836.03	-0.502877
1839.03	-0.0180146
1842.02	-0.732361
1845.01	-0.264195
1848	0.625955
1850.99	1.84559
1853.97	1.94647
1856.96	1.79078
1859.94	2.21563
1862.93	2.13449
1865.91	1.88812
1868.89	1.48882
1871.87	1.03582
1874.85	0.877771
1877.83	0.57451
1880.81	0.800552
1882.57	1.10159
1885.56	2.22904
1888.55	2.00044
1891.54	2.34556
1894.52	3.72158
1897.51	4.55726
1900.49	4.49854
1903.47	6.4642
1906.45	6.94342
1909.43	8.063
1912.41	8.1827
1915.39	8.16616
1918.37	9.64465
1921.34	10.2642
1924.32	10.0823
1927.29	9.98745
1930.26	10.1578
1933.23	10.7633
1936.2	10.0878
1939.17	10.6562
1942.14	10.2122
1945.11	9.76852
1948.07	9.41182
1951.04	9.99212
1954	9.28919
1956.96	8.07139
1959.93	8.77704
1962.89	9.24594
1965.85	9.52934
1968.8	9.08581
1971.76	9.24851
1974.72	9.01979
1977.67	9.22139
1980.63	8.40194
1983.58	7.8413
1986.53	8.19375
1989.48	8.23359
1992.43	10.1375
1995.38	9.82183
1998.32	10.0982
2001.27	10.0275
2004.22	10.9999
2007.16	10.4932
2010.1	11.486
2013.04	11.3727
2015.98	11.5698
2018.92	12.4622
2021.86	13.0203
2024.8	13.6077
2027.74	13.8237
2030.67	15.5926
2033.61	15.6819
2036.54	15.6629
2039.47	15.9392
2042.4	16.4645
2045.33	17.0203
2048.26	17.8207
2051.19	18.6334
2054.12	18.7449
2057.04	20.2621
2059.97	21.2975
2062.89	21.9392
2065.81	22.2938
2068.73	23.1325
2071.65	23.0883
2074.57	24.4487
2077.49	25.3047
2080.41	25.4364
2083.32	25.7864
2086.24	26.3691
2089.15	26.6399
2092.07	27.9986
2094.98	28.1025
2097.89	28.4596
2100.8	27.8999
2103.71	27.1761
2106.61	27.9617
2109.52	29.5629
2112.43	29.2691
2115.33	29.3707
2118.23	30.3471
2121.13	31.3027
2124.04	31.6081
2126.94	32.784
2129.83	34.1853
2132.73	35.9268
2135.63	37.5218
2138.53	41.3872
2141.42	44.553
2144.31	47.372
2147.21	49.5903
2150.1	51.8042
2152.99	52.873
2155.88	55.6427
2158.77	58.4463
2161.65	60.8741
2164.54	62.9647
2167.43	64.5257
2170.31	66.8663
2173.19	68.6657
2176.07	71.077
2178.96	72.6128
2181.84	71.8172
2184.72	70.4216
2187.59	69.6257
2190.47	68.6925
2193.35	65.5797
2196.22	63.2683
2199.09	61.7661
2201.97	59.4416
2204.84	56.5292
2207.71	54.4268
2210.58	52.0834
2213.45	49.6922
2216.31	45.6986
2219.18	42.8079
2222.05	40.5409
2224.91	38.2718
2227.78	36.1926
2230.64	34.6629
2233.5	32.7571
2236.36	32.371
2239.22	32.9074
2242.08	32.1223
2244.93	32.675
2247.79	33.2892
2250.64	33.8602
2253.5	33.8743
2256.35	34.513
2259.2	33.3618
2262.05	32.5037
2264.9	32.3566
2267.75	31.8393
2270.6	29.7286
2273.45	28.1248
2276.29	27.5055
2279.14	26.51
2281.98	25.8228
2284.82	23.0379
2287.66	21.5376
2290.5	19.8309
2293.34	16.528
2296.18	15.2632
2299.02	15.0543
2301.86	15.0727
2304.69	15.1586
2307.53	15.3189
2310.36	15.8202
2313.19	16.5706
2316.02	17.8955
2318.85	18.0068
2321.68	17.6399
2324.51	18.0372
2327.34	17.4994
2330.16	16.5527
2332.99	15.1799
2335.81	13.9154
2338.64	13.1712
2341.46	11.8292
2344.28	10.8664
2347.1	8.60293
2349.92	7.26663
2352.74	6.38848
2355.55	4.22784
2358.37	3.27915
2361.19	1.92606
2364	2.81271
2366.81	4.10779
2369.62	3.51071
2372.44	3.25619
2375.24	3.01445
2378.05	3.56176
2380.86	4.94326
2383.67	3.55929
2386.47	4.40843
2389.28	4.57824
2392.08	4.49342
2394.89	5.2138
2397.69	5.25946
2400.49	4.87439
2403.29	5.1162
2406.09	4.87092
2408.88	5.51208
2411.68	6.74336
2414.48	7.03825
2417.27	7.29217
2420.06	8.28731
2422.86	8.94938
2425.65	9.66436
2428.44	9.90117
2431.23	9.53169
2434.02	10.1121
2436.81	8.97944
2439.59	8.0762
2442.38	7.68104
2445.16	7.56676
2447.95	7.37619
2450.73	7.27291
2453.51	7.15823
2456.29	6.74794
2459.07	6.44345
2461.85	5.54153
2464.63	4.74672
2467.4	4.40019
2470.18	2.78373
2472.95	2.1316
2475.73	1.5524
2478.5	1.49488
2481.27	0.604197
2484.04	-0.565363
2486.81	0.254983
2489.58	-0.0882676
2492.35	-0.471104
2495.12	-0.553494
2497.88	-0.527407
2500.65	0.194977
2503.41	0.465536
2506.17	-0.924076
2508.94	-1.22865
2511.7	-0.382373
2514.46	-0.114844
2517.22	0.415485
2519.97	0.61967
2522.73	1.40404
2525.49	2.9117
2528.24	2.47173
2530.99	1.95467
2533.75	1.79569
2536.5	0.819737
2539.25	0.630394
2542	1.275
2544.75	2.11225
2547.5	1.7654
2550.24	1.74402
2552.99	2.92604
2555.74	3.5114
2558.48	3.10949
2561.22	3.77305
2563.96	4.51465
2566.71	4.18394
2569.45	4.75478
2572.18	4.06824
2574.92	4.06771
2577.66	4.31747
2580.4	5.68661
2583.13	5.22881
2585.87	4.95017
2588.6	5.40078
2591.33	5.75034
2594.06	5.51845
2596.79	4.51432
2599.52	3.26673
2602.25	2.57598
2604.98	2.25674
2607.71	2.29153
2610.43	2.58619
2613.16	1.61254
2615.88	1.13658
2618.6	2.25289
2621.32	2.21035
2624.04	2.076
2626.76	2.9178
2629.48	3.88912
2632.2	3.73151
2634.92	3.05356
2637.63	3.29384
2640.35	2.45937
2643.06	2.18449
2645.77	3.38939
2648.49	2.97112
2651.2	2.60634
2653.91	2.60437
2656.62	3.30963
2659.33	3.87661
2662.03	3.80203
2664.74	3.40713
2667.44	3.36759
2670.15	4.52133
2672.85	5.10816
2675.55	6.05956
2678.26	6.94985
2680.96	8.27843
2683.66	8.31
2686.35	9.5296
2689.05	10.6594
2691.75	11.5672
2694.44	12.362
2697.14	13.0514
2699.83	13.107
2702.52	15.178
2705.22	15.8702
2707.91	17.3762
2710.6	18.8404
2713.29	20.2484
2715.97	21.2848
2718.66	22.254
2721.35	23.1682
2724.03	23.818
2726.72	24.4419
2729.4	25.1526
2732.08	25.3031
2734.76	25.7465
2737.44	26.6034
2740.12	26.9299
2742.8	27.0844
2745.48	26.0407
2748.16	26.1438
2750.83	25.4845
2753.51	25.8167
2756.18	25.2116
2758.85	25.292
2761.53	24.799
2764.2	24.1485
2766.87	23.9899
2769.54	22.346
2772.2	21.5381
2774.87	21.8455
2777.54	20.7646
2780.2	19.7741
2782.87	19.3519
2785.53	19.1227
2788.19	18.4945
2790.85	17.7207
2793.51	16.7322
2796.17	17.221
2798.83	17.837
2801.49	18.2441
2804.15	19.1027
2806.8	19.7042
2809.46	19.9653
2812.11	19.4154
2814.76	19.5379
2817.42	19.6276
2820.07	22.8691
2822.72	27.0976
2825.37	32.9649
2828.02	39.0573
2830.66	48.1613
2833.31	58.037
2835.96	68.9623
2838.6	81.5946
2841.24	95.523
2843.89	111.36
2846.53	131.016
2849.17	153.814
2851.81	175.201
2854.45	198.178
2857.09	222.88
2859.72	245.942
2862.36	268.377
2865	289.441
2867.63	308.521
2870.26	324.107
2872.9	339.479
2875.53	349.743
2878.16	361.239
2880.79	371.459
2883.42	381.414
2886.05	389.975
2888.67	397.921
2891.3	405.527
2893.92	414.571
2896.55	424.497
2899.17	436.751
2901.79	450.793
2904.42	467.744
2907.04	487.956
2909.66	512.374
2912.27	538.056
2914.89	564.539
2917.51	588.698
2920.13	611.909
2922.74	630.581
2925.35	644.146
2927.97	655.063
2930.58	660.313
2933.19	660.013
2935.8	655.896
2938.41	646.941
2941.02	634.492
2943.63	618.957
2946.24	598.11
2948.84	575.798
2951.45	552.32
2954.05	527.888
2956.65	504.652
2959.26	481.024
2961.86	458.598
2964.46	436.127
2967.06	416.563
2969.66	398.542
2972.25	380.076
2974.85	364.792
2977.45	347.943
2980.04	330.823
2982.64	311.748
2985.23	292.954
2987.82	273.086
2990.41	252.437
2993	233.987
2995.59	214.958
2998.18	196.778
3000.77	177.47
3003.36	160.337
3005.94	144.029
3008.53	129.791
3011.11	116.255
3013.69	105.174
3016.28	95.969
3018.86	88.3776
3021.44	82.3962
3024.02	76.2603
3026.6	72.6339
3029.18	71.3121
3031.75	70.1315
3034.33	69.2203
3036.9	68.9915
3039.48	70.7857
3042.05	72.9748
3044.62	75.5171
3047.19	77.1499
3049.77	78.5932
3052.34	79.322
3054.9	80.1195
3057.47	79.1052
3060.04	77.2606
3062.61	74.3935
3065.17	71.1095
3067.74	67.0877
3070.3	63.1408
3072.86	58.6831
3075.42	53.8075
3077.99	48.6085
3080.54	43.3465
3083.1	37.7005
3085.66	32.9876
3088.22	28.3272
3090.78	24.4945
3093.33	21.4364
3095.89	18.2154
3098.44	16.2147
3100.99	14.933
3103.54	13.9206
3106.1	13.3108
3108.65	11.9412
3111.2	10.6643
3113.74	9.93188
3116.29	8.84978
3118.84	7.83912
3121.38	6.83789
3123.93	6.74066
3126.47	5.75484
3129.01	4.10153
3131.56	3.4027
3134.1	2.50396
3136.64	1.71288
3139.18	0.603578
3141.72	-0.0681215
3144.26	-0.970193
3146.79	-1.70888
3149.33	-2.11222