File: data/Raman/poly_smoothed/Thy_20_09_15_1x_45s_532 nm_x100_100%_600 gr_mm_01.txt
#Acq. time (s)=	45
#Accumulations=	2
#Range (cm-¹)=	200...3150
#Windows=	2
#Auto scanning=	Off
#Autofocus=	Off
#Macrospot=	Off
#AutoExposure=	Off
#Spike filter=	Multiple accum.
#Delay time (s)=	0
#Binning=	1
#Readout mode=	Signal
#DeNoise=	Off
#ICS correction=	On
#Dark correction=	Off
#Inst. Process=	Off
#Detector Gain=	Best Dynamic Range
#Detector ADC=	20 kHz
#Detector temperature (°C)=	-69.85
#Instrument=	LabRAM HR Evol
#Detector=	Synapse
#Objective=	x100
#Grating=	600 gr/mm
#ND Filter=	100%
#Laser (nm)=	532
#Hole=	100.021
#Range=	Auto
#Laser Pol.=	No
#Raman. Pol.=	No
#Laser Pol. (°)=	-0.0007625
#Raman Pol. (°)=	89.9995
#Collection=	Microscope
#StageXY=	Marzhauser
#StageZ=	Marzhauser
#X (µm)=	-5895.6
#Y (µm)=	2860.4
#Z (µm)=	-223.3
#Full time(mm:ss)=	3:18
#Project=
#Sample=
#Site=
#Title=	Thy_20_09_15_2x_45s_532 nm_x100_100%_600 gr_mm
#Remark=
#Date=	29.06.2022 11:45
#Acquired=	29.06.2022 11:45:30
#Base:Fit=	10.08.2022 09:52:02
#Base:Fit=	10.08.2022 09:52:12
#Base:Sub=	10.08.2022 09:54:21
#Filter:Polynom=	16.08.2022 10:24:04
#AxisType[0]=Intens
#AxisUnit[0]=Cnt
#AxisType[1]=Spectr
#AxisUnit[1]=1/cm
200.523	6.32877
204.154	10.4762
207.781	10.4197
211.409	9.10475
215.034	8.11335
218.659	7.38308
222.281	7.36041
225.903	6.90631
229.522	6.61121
233.14	8.49713
236.756	9.03289
240.373	9.23016
243.986	10.0677
247.598	10.5396
251.208	10.4506
254.818	11.2061
258.427	12.3176
262.034	11.9305
265.638	12.1191
269.242	13.5385
272.844	13.9883
276.445	13.9178
280.044	14.4674
283.642	15.4348
287.238	15.3112
290.833	14.3945
294.425	14.7633
298.017	14.8416
301.608	15.6189
305.198	16.0196
308.786	15.3734
312.371	15.5378
315.956	16.9089
319.54	18.3936
323.122	18.9964
326.701	19.1486
330.281	18.9013
333.857	19.4914
337.434	19.6145
341.008	19.3137
344.582	18.9583
348.153	18.8507
351.724	18.935
355.292	18.8763
358.861	18.1322
362.426	17.2553
365.99	16.0342
369.555	16.181
373.116	14.3791
376.676	14.2055
380.236	13.9538
383.793	12.2817
387.349	10.9119
390.903	9.83778
394.456	8.24769
398.007	6.54457
401.56	6.61872
405.108	6.35409
408.656	6.34515
412.202	6.99712
415.746	7.09354
419.29	7.47062
422.831	9.51417
426.37	9.07601
429.909	9.98035
433.447	9.66963
436.983	10.6257
440.519	11.175
444.052	10.9075
447.583	10.4242
451.114	10.7538
454.643	9.71765
458.169	9.88182
461.696	11.5224
465.222	11.4116
468.744	10.9913
472.267	10.1604
475.787	10.553
479.307	10.7354
482.823	10.5461
486.341	11.8558
489.855	12.4736
493.37	13.6444
496.881	14.8109
500.391	14.7229
503.902	15.1819
507.409	14.5847
510.915	13.4344
514.42	12.2485
517.925	12.1482
521.427	10.7604
524.928	10.7511
528.427	9.84146
531.925	7.65795
535.422	7.36831
538.917	5.24517
542.411	4.10612
545.903	4.72909
549.395	5.40792
552.884	3.59549
556.373	4.17227
559.86	4.69334
563.346	3.54627
566.831	3.07102
570.314	3.8405
573.794	5.10097
577.274	4.15091
580.754	3.50216
584.23	4.1084
587.706	3.12401
591.181	3.49051
594.653	3.58868
598.126	2.13256
601.595	2.40157
605.065	2.66597
608.532	3.25196
611.999	2.50536
615.463	2.90933
618.928	3.43887
622.389	4.00673
625.851	3.53836
629.31	4.54036
632.767	4.94108
636.223	6.30529
639.68	7.11822
643.134	8.51011
646.586	9.29996
650.037	9.66954
653.486	11.8034
656.936	12.7968
660.383	12.7286
663.829	13.7543
667.273	15.8155
670.716	17.0345
674.158	18.901
677.598	19.6834
681.035	19.1481
684.473	20.3708
687.909	22.5943
691.344	23.9257
694.778	24.1544
698.211	25.0492
701.64	25.2285
705.07	26.6042
708.498	27.3349
711.924	28.6318
715.35	30.1999
718.774	31.2605
722.196	32.9549
725.618	32.5542
729.037	34.1473
732.456	35.4806
735.873	36.6315
739.289	38.182
742.703	38.6473
746.116	41.479
749.529	43.9765
752.938	45.6288
756.347	47.5918
759.756	50.6071
763.162	54.0319
766.567	56.1274
769.97	59.3176
773.372	61.1154
776.773	62.2084
780.174	63.1682
783.573	66.1538
786.97	67.1868
790.365	68.0911
793.76	69.0539
797.153	69.1883
800.543	69.1355
803.933	68.1967
807.322	67.4611
810.71	65.913
814.097	65.4069
817.483	64.2788
820.865	63.1825
824.248	61.5107
827.629	59.9719
831.008	59.5919
834.387	59.15
837.765	58.4147
841.139	57.57
844.514	56.865
847.886	53.887
851.259	51.1107
854.629	49.1661
857.997	46.9723
861.366	45.1236
864.732	42.5354
868.098	42.7028
871.461	42.3187
874.823	41.2486
878.184	40.4773
881.545	39.0301
884.903	38.1145
888.26	37.8577
891.616	38.3811
894.97	38.3658
898.323	38.4461
901.675	37.06
905.026	37.3156
908.375	36.8399
911.723	37.209
915.07	37.8241
918.415	37.9708
921.76	36.3496
925.103	34.1195
928.443	33.4955
931.783	32.1692
935.123	31.0946
938.461	30.1707
941.796	30.143
945.131	28.7636
948.465	29.2965
951.797	30.3442
955.128	27.7311
958.457	26.3306
961.786	25.9678
965.113	24.4466
968.44	24.3492
971.763	23.7844
975.086	21.942
978.409	20.6693
981.729	19.6522
985.048	17.8997
988.367	15.67
991.683	12.9962
994.998	12.258
998.312	11.0782
1001.62	9.39943
1004.94	9.29253
1008.25	8.21927
1011.56	7.2233
1014.86	5.89954
1018.17	5.17741
1021.48	4.57245
1024.78	5.391
1028.08	5.25216
1031.38	5.21332
1034.68	6.05104
1037.98	5.79697
1041.28	7.67533
1044.57	7.77707
1047.87	8.06724
1051.16	9.23435
1054.45	9.3496
1057.75	10.1069
1061.04	10.0543
1064.32	9.32281
1067.61	7.957
1070.9	8.10709
1074.18	9.44654
1077.47	9.0775
1080.75	7.63158
1084.03	7.69435
1087.31	6.64758
1090.59	5.47674
1093.86	5.73077
1097.14	5.33271
1100.41	5.75987
1103.69	6.11684
1106.96	7.09353
1110.23	7.63156
1113.5	9.37884
1116.77	8.19657
1120.03	8.7074
1123.3	9.25691
1126.56	9.34546
1129.83	8.18151
1133.09	8.64904
1136.35	7.60628
1139.61	7.59559
1142.86	6.43169
1146.12	5.46255
1149.38	5.44433
1152.63	5.06764
1155.88	3.79091
1159.14	3.2427
1162.39	3.60308
1165.63	3.62161
1168.88	3.7254
1172.13	4.73882
1175.38	5.18104
1178.62	6.45233
1181.86	6.66175
1185.1	8.32758
1188.34	10.0371
1191.58	10.1715
1194.82	11.2306
1198.06	12.2669
1201.29	13.5533
1204.53	14.1609
1207.76	15.707
1210.99	17.3026
1214.22	19.7206
1217.45	22.9028
1220.68	25.8061
1223.91	27.8463
1227.13	30.6681
1230.36	33.3849
1233.58	35.6906
1236.8	36.9421
1240.02	38.4971
1243.24	39.6517
1246.46	40.1075
1249.67	40.7427
1252.89	40.8833
1256.1	41.9557
1259.32	42.5171
1262.53	42.6751
1265.74	42.4724
1268.95	41.2352
1272.15	41.4586
1275.36	41.7106
1278.57	42.3859
1281.77	42.8654
1284.97	44.8977
1288.18	46.5282
1291.38	47.4787
1294.58	49.1666
1297.78	51.4698
1300.97	53.3466
1304.17	55.5312
1307.36	58.0425
1310.55	60.0339
1313.75	61.7046
1316.94	62.7438
1320.13	64.1227
1323.32	64.8781
1326.5	65.0556
1329.69	65.4461
1332.87	65.5028
1336.06	64.7523
1339.24	65.2459
1342.42	64.9158
1345.6	63.9984
1348.78	63.4535
1351.96	62.7539
1355.13	61.9599
1358.31	61.5488
1361.48	59.6928
1364.65	58.3942
1367.82	56.1502
1370.99	55.5818
1374.16	54.9312
1377.33	53.5653
1380.5	52.7902
1383.66	52.1127
1386.83	51.0436
1389.99	49.1368
1393.15	48.1108
1396.31	44.5545
1399.47	42.8836
1402.63	41.5527
1405.78	39.791
1408.94	39.0832
1412.1	38.9773
1415.25	40.8384
1418.4	42.2136
1421.55	44.4958
1424.7	46.458
1427.85	48.6144
1431	51.962
1434.14	54.4702
1437.29	56.1634
1440.43	58.1961
1443.57	59.7271
1446.71	61.4327
1449.85	62.2419
1452.99	61.4061
1456.13	60.445
1459.26	59.6184
1462.4	57.7814
1465.54	55.391
1468.67	53.164
1471.8	49.8658
1474.93	46.4746
1478.06	44.4695
1481.19	41.4027
1484.31	37.8912
1487.44	35.2078
1490.56	33.3744
1493.69	31.7859
1496.81	30.95
1499.93	30.2925
1503.05	31.5303
1506.17	31.7437
1509.28	33.2239
1512.4	33.2363
1515.52	33.67
1518.63	34.1341
1521.74	35.5048
1524.85	37.1747
1527.96	38.0563
1531.07	39.3481
1534.18	41.9304
1537.29	44.6048
1540.39	45.6972
1543.5	49.9297
1546.6	52.3441
1549.7	53.9262
1552.8	57.3594
1555.9	59.3775
1559	61.5685
1562.1	64.663
1565.19	67.7762
1568.29	71.3718
1571.38	73.0537
1574.47	75.5682
1577.56	79.0518
1580.66	81.0494
1583.74	83.5741
1586.83	83.5945
1589.92	82.5136
1593.01	81.606
1596.09	80.2908
1599.17	78.8575
1602.25	76.0276
1605.34	73.0086
1608.41	71.3332
1611.49	70.4462
1614.57	67.3859
1617.65	64.8642
1620.72	62.2008
1623.79	60.1973
1626.87	58.2404
1629.94	56.408
1633.01	55.5962
1636.08	55.3412
1639.15	53.9897
1642.21	53.499
1645.28	54.5254
1648.34	53.3982
1651.41	54.2008
1654.47	53.2201
1657.53	53.1401
1660.59	51.0135
1663.65	48.1424
1666.71	45.5218
1669.76	43.4612
1672.82	41.3566
1675.87	39.7048
1678.93	36.6425
1681.98	33.4823
1685.03	31.0302
1688.08	28.4155
1691.13	24.4934
1694.17	22.143
1697.22	18.2866
1700.27	15.4657
1703.31	12.9644
1706.35	11.558
1709.39	9.53507
1712.43	8.92448
1715.47	8.88383
1718.51	9.00261
1721.55	8.80938
1724.58	8.48962
1727.62	7.7423
1730.65	6.6544
1733.68	6.7999
1736.72	6.38709
1739.74	7.58458
1742.77	8.05574
1745.8	8.88117
1748.83	8.10434
1751.85	7.66248
1754.88	6.70291
1757.9	6.4777
1760.92	5.90869
1763.95	6.12327
1766.96	5.01125
1769.98	3.81045
1773	2.91896
1776.02	2.42564
1779.03	2.31346
1782.05	2.73764
1785.06	2.99056
1788.07	2.27432
1791.08	3.38207
1794.09	2.64723
1797.1	2.1656
1800.11	1.9048
1803.12	1.93357
1806.12	2.3879
1809.12	3.29322
1812.13	3.87398
1815.13	4.55438
1818.13	4.30656
1821.13	5.22077
1824.13	5.13075
1827.13	5.39176
1830.12	4.31785
1833.12	4.74303
1836.11	5.53797
1839.1	5.12046
1842.09	4.89695
1845.09	4.977
1848.08	4.87447
1851.06	4.70173
1854.05	4.30468
1857.04	4.7751
1860.02	4.88224
1863.01	5.42366
1865.99	4.54139
1868.97	3.79786
1871.95	3.88524
1874.93	3.89407
1877.91	3.47851
1880.89	3.16577
1882.46	3.14639
1885.45	2.94844
1888.43	3.06395
1891.42	2.91444
1894.41	3.04303
1897.39	2.35338
1900.37	2.5433
1903.36	2.99849
1906.34	3.17142
1909.32	3.39508
1912.29	3.39566
1915.27	3.07082
1918.25	3.15892
1921.23	4.01269
1924.2	4.27404
1927.17	4.72219
1930.15	4.02185
1933.12	4.22334
1936.09	3.3132
1939.06	2.93873
1942.02	3.61185
1944.99	3.32609
1947.96	2.90194
1950.92	2.53076
1953.88	2.02881
1956.85	0.786545
1959.81	0.642546
1962.77	0.650724
1965.73	0.741335
1968.69	1.38358
1971.64	0.518001
1974.6	1.54597
1977.55	1.7773
1980.51	1.71598
1983.46	1.56583
1986.41	0.889529
1989.36	0.487013
1992.31	1.35106
1995.26	1.82887
1998.21	2.69157
2001.15	3.08932
2004.1	3.70955
2007.04	4.48424
2009.99	4.09705
2012.93	4.24574
2015.87	4.75294
2018.81	5.24781
2021.75	4.91636
2024.68	4.60705
2027.62	4.12092
2030.56	4.54737
2033.49	5.14795
2036.42	4.32076
2039.36	3.65253
2042.29	3.05946
2045.22	3.43748
2048.14	3.75508
2051.07	2.32833
2054	0.926921
2056.93	0.838571
2059.85	1.33833
2062.77	1.85193
2065.7	3.08995
2068.62	2.9755
2071.54	3.18695
2074.46	3.48885
2077.38	3.39602
2080.29	3.59049
2083.21	3.36395
2086.12	3.34387
2089.04	4.03563
2091.95	3.20326
2094.86	2.64083
2097.77	3.2126
2100.68	3.08272
2103.59	3.74664
2106.5	3.06279
2109.41	3.44839
2112.31	3.87215
2115.21	4.64191
2118.12	5.27224
2121.02	5.82
2123.92	6.72476
2126.82	7.64259
2129.72	9.13823
2132.62	8.87512
2135.51	9.96572
2138.41	10.5935
2141.31	11.16
2144.2	12.0268
2147.09	12.2915
2149.98	12.9412
2152.87	13.5465
2155.76	12.9317
2158.65	12.561
2161.54	13.2027
2164.43	13.2302
2167.31	14.3135
2170.2	15.4556
2173.08	16.0673
2175.96	16.8433
2178.84	16.8997
2181.72	16.8361
2184.6	16.498
2187.48	17.5985
2190.36	18.6182
2193.23	19.011
2196.11	18.9961
2198.98	18.1542
2201.85	17.685
2204.72	16.034
2207.59	15.4524
2210.46	13.8444
2213.33	12.2673
2216.2	11.1945
2219.07	10.516
2221.93	9.96111
2224.8	7.86429
2227.66	7.79682
2230.52	8.05604
2233.39	8.19455
2236.25	8.23311
2239.1	8.01712
2241.96	6.69013
2244.82	6.60779
2247.68	7.36507
2250.53	6.42897
2253.38	6.68903
2256.24	7.3695
2259.09	7.04163
2261.94	6.71025
2264.79	6.55179
2267.64	5.16855
2270.49	5.48749
2273.33	4.64613
2276.18	4.06053
2279.02	3.01548
2281.87	3.29627
2284.71	2.77652
2287.55	1.7916
2290.39	1.11289
2293.23	0.948285
2296.07	1.48453
2298.91	2.56303
2301.74	2.84805
2304.58	3.52427
2307.41	2.33277
2310.25	3.00544
2313.08	4.01315
2315.91	5.04312
2318.74	5.43146
2321.57	5.49138
2324.4	6.09092
2327.23	4.94244
2330.05	5.07646
2332.88	5.49412
2335.7	5.60313
2338.52	5.35368
2341.35	5.1499
2344.17	5.2253
2346.99	4.98662
2349.81	4.42262
2352.62	4.00758
2355.44	2.35781
2358.26	2.50493
2361.07	2.44005
2363.89	2.32295
2366.7	2.84134
2369.51	3.11541
2372.32	2.88267
2375.13	3.2927
2377.94	3.78577
2380.75	5.46156
2383.56	5.29826
2386.36	5.25489
2389.17	5.52272
2391.97	5.13338
2394.77	4.57622
2397.58	3.78873
2400.38	4.28761
2403.18	4.2829
2405.97	4.30342
2408.77	4.76059
2411.57	5.91807
2414.37	6.39764
2417.16	6.94611
2419.95	7.52037
2422.75	7.54367
2425.54	7.72271
2428.33	7.76669
2431.12	7.41247
2433.91	7.77049
2436.7	8.42028
2439.48	8.07514
2442.27	8.31986
2445.05	8.40612
2447.84	7.81611
2450.62	6.61965
2453.4	5.83238
2456.18	5.70036
2458.96	4.91383
2461.74	4.08076
2464.52	3.90744
2467.29	3.49396
2470.07	3.90764
2472.85	3.35577
2475.62	3.96623
2478.39	4.03804
2481.16	4.33573
2483.93	4.63454
2486.7	4.98787
2489.47	4.28662
2492.24	4.19948
2495.01	3.52709
2497.77	2.82293
2500.54	2.92425
2503.3	2.98794
2506.06	2.57842
2508.83	2.64682
2511.59	1.49414
2514.35	1.72241
2517.11	1.3964
2519.86	1.28359
2522.62	1.30639
2525.38	1.41217
2528.13	1.24568
2530.89	0.668918
2533.64	0.345694
2536.39	0.166754
2539.14	1.06867
2541.89	1.45448
2544.64	1.91641
2547.39	2.34938
2550.14	2.754
2552.88	2.91449
2555.63	2.39704
2558.37	2.12132
2561.11	2.40956
2563.86	2.69765
2566.6	2.78816
2569.34	3.0942
2572.08	3.87274
2574.82	3.44155
2577.55	3.59479
2580.29	3.38683
2583.02	3.67815
2585.76	3.81123
2588.49	3.52416
2591.22	3.34849
2593.96	2.42068
2596.69	1.69485
2599.42	1.83299
2602.14	1.76798
2604.87	1.88822
2607.6	2.0379
2610.32	1.91623
2613.05	2.16789
2615.77	1.47213
2618.49	1.28693
2621.22	0.914511
2623.94	1.39626
2626.66	2.2036
2629.37	2.45307
2632.09	2.68778
2634.81	3.18484
2637.53	3.33792
2640.24	3.71674
2642.96	4.41698
2645.67	4.76366
2648.38	5.36166
2651.09	5.44893
2653.8	6.27639
2656.51	5.8294
2659.22	6.13873
2661.93	5.87326
2664.63	6.4048
2667.34	6.20312
2670.04	6.28462
2672.75	5.87493
2675.45	5.57444
2678.15	5.45692
2680.85	5.59125
2683.55	5.51492
2686.25	5.85041
2688.94	6.62633
2691.64	6.7702
2694.34	7.08174
2697.03	7.88597
2699.73	7.98696
2702.42	8.14982
2705.11	7.83169
2707.8	8.13365
2710.49	8.91813
2713.18	9.02335
2715.87	9.57916
2718.55	9.53491
2721.24	9.3135
2723.93	8.88694
2726.61	7.68807
2729.29	7.22442
2731.98	6.59572
2734.66	5.58797
2737.34	5.08455
2740.02	4.36631
2742.7	4.34835
2745.37	3.93019
2748.05	3.60247
2750.72	3.87694
2753.4	3.13826
2756.07	2.21949
2758.75	2.09286
2761.42	1.94716
2764.09	2.54465
2766.76	1.48066
2769.43	1.09511
2772.1	1.5396
2774.76	1.96822
2777.43	1.88472
2780.1	1.66561
2782.76	1.07414
2785.42	0.770449
2788.09	1.09824
2790.75	-0.106936
2793.41	-0.174237
2796.07	-0.0381069
2798.73	0.46228
2801.39	0.464724
2804.04	1.09082
2806.7	1.98431
2809.35	1.85582
2812.01	1.29442
2814.66	1.60055
2817.31	2.25016
2819.96	2.69945
2822.61	2.75574
2825.26	3.4386
2827.91	4.4832
2830.56	4.67524
2833.21	5.94284
2835.85	7.59056
2838.5	8.09714
2841.14	9.52372
2843.78	12.4787
2846.42	14.6051
2849.06	17.363
2851.71	20.3779
2854.34	22.1957
2856.98	25.6415
2859.62	28.9413
2862.26	31.4028
2864.89	34.6494
2867.53	37.4162
2870.16	40.1681
2872.79	42.1392
2875.42	44.2092
2878.05	46.2688
2880.68	47.5759
2883.31	48.8884
2885.94	49.1717
2888.57	49.5728
2891.19	50.893
2893.82	51.5912
2896.44	52.4946
2899.07	53.7768
2901.69	56.7492
2904.31	60.0219
2906.93	64.1839
2909.55	67.2569
2912.17	70.2682
2914.79	74.0181
2917.41	76.4157
2920.02	80.503
2922.64	82.084
2925.25	84.1539
2927.86	85.7982
2930.48	86.8778
2933.09	87.4967
2935.7	86.964
2938.31	86.0772
2940.92	84.4803
2943.53	82.3939
2946.13	80.1536
2948.74	76.8697
2951.34	74.5436
2953.95	70.6376
2956.55	67.0322
2959.15	63.6931
2961.75	61.9958
2964.35	60.264
2966.95	57.2154
2969.55	53.9451
2972.15	50.972
2974.75	47.1694
2977.34	43.7357
2979.94	40.8424
2982.53	37.3529
2985.13	33.1854
2987.72	30.0841
2990.31	26.6657
2992.9	22.7487
2995.49	19.452
2998.08	16.4628
3000.67	12.9302
3003.25	10.4074
3005.84	8.24233
3008.42	6.7002
3011.01	4.84427
3013.59	3.43072
3016.17	2.33786
3018.76	1.06627
3021.34	0.561955
3023.92	0.675585
3026.49	1.34854
3029.07	0.287341
3031.65	1.13963
3034.23	2.07277
3036.8	3.67358
3039.38	5.28519
3041.95	6.0283
3044.52	6.54032
3047.09	7.27745
3049.66	7.10841
3052.23	7.22647
3054.8	7.51539
3057.37	7.41424
3059.94	7.02896
3062.5	8.03522
3065.07	7.64904
3067.63	7.67112
3070.2	7.71394
3072.76	6.45611
3075.32	6.69804
3077.88	6.31518
3080.44	5.13402
3083	5.35063
3085.56	4.95729
3088.12	4.37662
3090.67	4.28369
3093.23	5.3227
3095.78	6.02697
3098.34	7.1782
3100.89	7.78734
3103.44	7.79995
3105.99	8.06352
3108.54	8.25322
3111.09	8.22998
3113.64	8.86445
3116.19	9.25444
3118.74	10.4839
3121.28	11.6171
3123.83	13.3892
3126.37	15.1057
3128.91	16.1944
3131.46	17.614
3134	19.5496
3136.54	21.1669
3139.08	23.4401
3141.62	24.8445
3144.16	27.5782
3146.69	30.9828
3149.23	36.0077