File: data/Raman/poly_smoothed/Thy_50_12_06_1x_45s_532 nm_x100_100%_600 gr_mm_01.txt
#Acq. time (s)=	45
#Accumulations=	2
#Range (cm-¹)=	200...3150
#Windows=	2
#Auto scanning=	Off
#Autofocus=	Off
#Macrospot=	Off
#AutoExposure=	Off
#Spike filter=	Multiple accum.
#Delay time (s)=	0
#Binning=	1
#Readout mode=	Signal
#DeNoise=	Off
#ICS correction=	On
#Dark correction=	Off
#Inst. Process=	Off
#Detector Gain=	Best Dynamic Range
#Detector ADC=	20 kHz
#Detector temperature (°C)=	-69.85
#Instrument=	LabRAM HR Evol
#Detector=	Synapse
#Objective=	x100
#Grating=	600 gr/mm
#ND Filter=	100%
#Laser (nm)=	532
#Hole=	100.021
#Range=	Auto
#Laser Pol.=	No
#Raman. Pol.=	No
#Laser Pol. (°)=	-0.0007625
#Raman Pol. (°)=	89.9995
#Collection=	Microscope
#StageXY=	Marzhauser
#StageZ=	Marzhauser
#X (µm)=	-5092.6
#Y (µm)=	1508.7
#Z (µm)=	63.1
#Full time(mm:ss)=	3:18
#Project=
#Sample=
#Site=
#Title=	Thy_50_12_06_2x_45s_532 nm_x100_100%_600 gr_mm
#Remark=
#Date=	07.07.2022 09:39
#Acquired=	07.07.2022 09:39:30
#Base:Fit=	10.08.2022 10:03:08
#Base:Fit=	10.08.2022 10:03:15
#Base:Fit=	10.08.2022 10:03:19
#Base:Fit=	10.08.2022 10:04:29
#Base:Sub=	10.08.2022 10:04:45
#Filter:Polynom=	16.08.2022 10:20:24
#AxisType[0]=Intens
#AxisUnit[0]=Cnt
#AxisType[1]=Spectr
#AxisUnit[1]=1/cm
200.43	16.7642
204.061	19.2505
207.688	18.7247
211.316	16.2976
214.941	14.6528
218.566	13.4239
222.188	12.2669
225.809	10.9757
229.43	10.7516
233.047	8.4667
236.663	7.8924
240.278	6.54137
243.894	6.19798
247.506	5.51604
251.116	3.86404
254.725	1.82142
258.333	2.38315
261.939	2.74581
265.546	3.66504
269.15	3.6908
272.752	4.44487
276.353	4.52556
279.952	4.14169
283.55	5.12855
287.146	4.31388
290.739	5.05692
294.333	3.88888
297.925	3.79651
301.516	6.43688
305.106	5.68108
308.694	6.05718
312.279	6.26158
315.864	6.80433
319.448	5.90429
323.029	6.60997
326.61	6.71184
330.19	6.83789
333.766	6.77627
337.343	7.08332
340.917	6.95871
344.491	7.13358
348.062	7.09562
351.633	6.83424
355.201	5.43136
358.77	5.57876
362.335	6.55861
365.899	5.63068
369.464	4.91151
373.025	5.5599
376.585	5.69302
380.143	5.28518
383.702	5.26766
387.258	5.4141
390.812	5.65995
394.365	4.77476
397.916	5.3335
401.467	5.03828
405.015	4.38273
408.565	4.12768
412.111	4.79024
415.656	2.94437
419.197	3.41064
422.739	3.35743
426.279	2.58849
429.819	1.77676
433.356	1.16044
436.893	2.24768
440.428	3.02821
443.96	3.10219
447.492	4.28067
451.023	4.30485
454.553	7.00521
458.079	7.27262
461.606	11.4418
465.132	13.3793
468.654	16.051
472.177	18.9011
475.696	19.658
479.217	21.0454
482.733	23.3215
486.251	24.8749
489.765	25.7392
493.278	28.5891
496.791	30.2968
500.301	31.8817
503.81	33.5365
507.319	34.9695
510.825	36.3143
514.33	36.2421
517.833	35.851
521.337	36.4687
524.838	35.7442
528.337	33.0085
531.835	32.4685
535.332	32.4758
538.827	31.511
542.321	32.2985
545.814	31.1407
549.305	29.7706
552.795	28.158
556.284	24.9666
559.771	22.8783
563.257	19.3242
566.742	18.3085
570.223	16.9294
573.705	14.7074
577.185	14.0797
580.665	15.252
584.141	14.6242
587.617	15.5539
591.092	13.8244
594.564	11.9889
598.037	12.2492
601.506	12.7545
604.976	13.3898
608.443	14.349
611.91	14.8188
615.374	15.2788
618.839	17.5796
622.3	18.5025
625.761	19.0951
629.221	22.2362
632.679	24.0999
636.135	25.1012
639.592	26.7425
643.045	26.2697
646.497	27.2259
649.948	28.0067
653.398	29.6559
656.846	30.2461
660.293	30.4275
663.738	33.1557
667.185	33.7792
670.628	33.2672
674.067	32.9709
677.508	32.8575
680.947	35.6646
684.385	38.9562
687.821	40.2265
691.256	41.5414
694.69	42.001
698.121	42.6067
701.552	45.2099
704.982	46.2295
708.41	47.6526
711.836	51.5072
715.262	52.6878
718.685	54.6514
722.108	55.2806
725.53	56.0915
728.949	57.5309
732.369	60.0832
735.785	63.3053
739.2	64.6481
742.616	67.5045
746.028	70.0615
749.441	72.1666
752.851	72.9031
756.26	76.0168
759.667	79.0278
763.075	81.1033
766.479	83.3511
769.883	85.1504
773.285	85.1566
776.686	85.7866
780.085	86.9058
783.484	88.2146
786.881	88.0501
790.276	88.1274
793.671	89.14
797.064	88.2243
800.456	87.9711
803.846	88.058
807.236	86.6834
810.624	88.3092
814.01	89.0759
817.394	88.6569
820.778	87.5569
824.161	87.5228
827.543	87.8234
830.921	87.0359
834.3	85.7994
837.676	83.9831
841.053	81.2015
844.426	80.0625
847.8	77.2447
851.171	73.9646
854.542	70.2957
857.911	69.7703
861.279	69.3521
864.645	67.1019
868.01	64.7192
871.375	65.528
874.737	63.8327
878.097	62.797
881.457	62.0735
884.817	62.6967
888.174	61.6857
891.53	59.4026
894.884	58.8187
898.237	57.7891
901.589	57.0874
904.94	56.1616
908.289	56.4481
911.637	56.3154
914.984	52.7899
918.33	51.1488
921.674	48.4226
925.015	46.9306
928.357	44.4854
931.698	41.9008
935.037	38.7033
938.373	40.0285
941.71	40.1571
945.046	37.9477
948.378	37.1906
951.711	39.9179
955.043	40.4459
958.372	38.1932
961.701	39.7239
965.027	40.5082
968.354	41.7205
971.678	41.4811
975	43.2103
978.324	43.3616
981.644	43.5083
984.962	43.6556
988.282	44.0514
991.598	44.1525
994.913	44.6807
998.227	43.5255
1001.54	43.7241
1004.85	43.4572
1008.16	43.5277
1011.47	44.627
1014.78	45.9401
1018.08	48.0887
1021.39	50.4306
1024.69	51.6167
1028	53.7082
1031.3	56.3835
1034.6	57.356
1037.9	55.779
1041.19	55.3039
1044.49	57.1489
1047.79	55.3767
1051.08	55.4256
1054.37	53.9526
1057.66	50.8761
1060.95	47.9343
1064.24	45.8393
1067.53	43.2058
1070.81	39.0208
1074.1	35.6482
1077.38	32.5037
1080.66	29.2145
1083.94	26.3675
1087.22	25.9898
1090.5	24.3796
1093.78	25.3115
1097.05	24.5197
1100.33	24.2692
1103.6	23.6117
1106.87	23.0505
1110.15	21.6839
1113.41	20.3524
1116.68	18.2907
1119.95	15.1663
1123.21	14.2748
1126.48	13.4387
1129.74	11.5861
1133	10.4341
1136.26	8.92914
1139.52	7.69365
1142.78	6.8638
1146.04	4.7252
1149.29	1.88132
1152.55	0.714071
1155.8	-0.859961
1159.05	-1.64383
1162.3	-2.00513
1165.55	-2.48958
1168.8	-0.0124008
1172.05	2.36903
1175.29	2.08637
1178.54	2.17617
1181.78	2.03875
1185.02	2.41131
1188.26	3.94908
1191.5	4.07597
1194.74	5.24295
1197.97	6.63401
1201.21	7.39547
1204.44	9.78878
1207.68	10.9596
1210.91	12.8542
1214.14	15.3207
1217.37	18.1609
1220.6	21.204
1223.82	24.2914
1227.05	27.5705
1230.27	30.322
1233.49	34.1728
1236.72	37.4798
1239.94	42.6313
1243.16	47.3245
1246.37	51.42
1249.59	57.3968
1252.8	61.0855
1256.02	65.0062
1259.23	70.6156
1262.44	78.1522
1265.66	82.6469
1268.87	86.9944
1272.07	92.031
1275.28	97.1104
1278.48	100.913
1281.69	103.295
1284.89	106.022
1288.09	107.236
1291.3	107.517
1294.49	108.776
1297.69	108.641
1300.89	107.322
1304.09	105.922
1307.28	104.707
1310.47	103.662
1313.66	102.422
1316.86	100.161
1320.05	96.7798
1323.23	94.4272
1326.42	90.4408
1329.61	87.8366
1332.79	85.1382
1335.98	81.6645
1339.16	77.959
1342.34	73.9046
1345.52	70.6565
1348.7	66.7506
1351.87	63.2733
1355.05	59.0554
1358.23	56.6876
1361.4	52.0303
1364.57	49.0546
1367.74	46.1382
1370.91	44.0474
1374.08	43.6688
1377.25	43.4965
1380.42	43.0071
1383.58	43.6559
1386.75	44.9695
1389.91	45.7189
1393.07	45.2196
1396.23	45.2509
1399.39	45.0325
1402.55	44.9971
1405.7	46.1698
1408.86	48.4805
1412.01	50.8621
1415.17	55.0038
1418.32	59.2713
1421.47	65.3131
1424.62	71.4533
1427.77	78.2741
1430.92	85.7362
1434.06	90.0732
1437.2	92.5291
1440.35	95.544
1443.49	105.282
1446.63	113.699
1449.77	119.651
1452.91	125.495
1456.05	127.669
1459.18	125.654
1462.32	123.911
1465.45	118.637
1468.59	110.536
1471.72	102.563
1474.85	93.6494
1477.98	85.0415
1481.11	75.802
1484.23	65.9094
1487.36	57.7059
1490.48	49.1448
1493.61	41.2434
1496.73	35.2844
1499.85	29.654
1502.97	23.8126
1506.09	17.7915
1509.2	12.6547
1512.32	7.71319
1515.44	10.4711
1518.55	17.3608
1521.66	23.5366
1524.77	28.6943
1527.88	32.2731
1530.99	35.1673
1534.1	37.9857
1537.21	41.0238
1540.31	47.1766
1543.42	51.0431
1546.52	56.3081
1549.62	62.0672
1552.72	65.9566
1555.82	69.1722
1558.92	72.3218
1562.02	75.5247
1565.11	78.6769
1568.21	82.6751
1571.3	85.489
1574.39	88.0579
1577.49	89.4247
1580.58	91.9413
1583.67	94.1003
1586.75	95.1274
1589.84	96.0462
1592.93	98.1863
1596.01	97.9261
1599.09	96.7403
1602.18	95.255
1605.26	94.1212
1608.34	92.4879
1611.41	92.725
1614.49	94.182
1617.57	96.1108
1620.64	98.61
1623.72	100.479
1626.79	103.957
1629.86	107.32
1632.93	110.376
1636	113.788
1639.07	117.84
1642.14	121.967
1645.2	124.683
1648.27	127.064
1651.33	130.397
1654.39	132.912
1657.45	132.423
1660.51	131.854
1663.57	127.953
1666.63	125.603
1669.69	119.488
1672.74	112.517
1675.79	104.896
1678.85	97.9441
1681.9	89.7488
1684.95	81.093
1688	73.9616
1691.05	66.01
1694.1	59.5962
1697.14	53.0569
1700.19	47.7724
1703.23	41.364
1706.27	36.5169
1709.32	29.3881
1712.35	26.0647
1715.39	22.0181
1718.43	20.158
1721.47	17.35
1724.5	15.3246
1727.54	14.3377
1730.57	12.4618
1733.61	11.8097
1736.64	9.84623
1739.67	9.20663
1742.7	7.12317
1745.72	5.84134
1748.75	5.95398
1751.78	5.36649
1754.8	5.04659
1757.82	3.53025
1760.85	3.37853
1763.87	2.94549
1766.89	3.25972
1769.91	3.78747
1772.92	3.28557
1775.94	3.36385
1778.96	2.66595
1781.97	2.32173
1784.98	2.52665
1788	3.14085
1791.01	3.92023
1794.01	3.43591
1797.02	3.33603
1800.03	3.41548
1803.04	4.00482
1806.04	2.6591
1809.05	2.38353
1812.05	2.3844
1815.05	2.21721
1818.05	2.40646
1821.05	3.08765
1824.05	3.55948
1827.05	3.85737
1830.04	3.86564
1833.04	3.46485
1836.03	3.65806
1839.03	3.29478
1842.02	3.59915
1845.01	3.79156
1848	3.14946
1850.99	2.95599
1853.97	2.182
1856.96	3.13637
1859.94	3.28843
1862.93	3.74972
1865.91	3.67341
1868.89	3.65048
1871.87	2.49159
1874.85	2.56554
1877.83	2.55898
1880.81	2.10352
1882.56	2.29808
1885.55	2.21565
1888.54	2.22827
1891.52	2.24394
1894.51	1.16641
1897.49	-0.273792
1900.48	-0.568946
1903.46	-0.0395722
1906.44	-0.0320511
1909.42	-0.371214
1912.4	0.1191
1915.38	0.874996
1918.35	0.681174
1921.33	0.773579
1924.3	1.18327
1927.28	2.41699
1930.25	3.30385
1933.22	3.03215
1936.19	3.53659
1939.16	4.4779
1942.13	5.68569
1945.09	7.29039
1948.06	7.7323
1951.03	7.45212
1953.99	7.4292
1956.95	7.67428
1959.91	7.76992
1962.87	7.47374
1965.83	6.68372
1968.79	7.26477
1971.75	8.03612
1974.7	8.35047
1977.66	8.08255
1980.61	7.38176
1983.56	6.38045
1986.52	5.75745
1989.47	4.87791
1992.41	4.61208
1995.36	5.4465
1998.31	5.87987
2001.26	5.27369
2004.2	5.0217
2007.15	4.73753
2010.09	6.36532
2013.03	8.02181
2015.97	8.40769
2018.91	8.6599
2021.85	9.19441
2024.79	9.68115
2027.72	10.5089
2030.66	11.1388
2033.59	11.4512
2036.53	11.8227
2039.46	13.7299
2042.39	14.1787
2045.32	14.4063
2048.25	14.0517
2051.18	13.5896
2054.1	14.5931
2057.03	15.1418
2059.95	17.1174
2062.88	18.383
2065.8	19.6086
2068.72	20.8031
2071.64	22.0137
2074.56	24.6179
2077.48	25.9468
2080.39	29.1398
2083.31	32.5226
2086.22	34.384
2089.14	36.7738
2092.05	39.7007
2094.96	42.4218
2097.87	45.247
2100.78	49.0913
2103.69	52.0343
2106.6	55.5781
2109.51	60.2775
2112.41	65.3123
2115.32	69.1571
2118.22	74.1056
2121.12	79.7041
2124.02	86.031
2126.92	92.8046
2129.82	99.216
2132.72	106.271
2135.62	112.335
2138.51	119.295
2141.41	127.698
2144.3	134.566
2147.19	139.868
2150.09	146.246
2152.97	152.162
2155.86	154.84
2158.75	158.922
2161.64	162.258
2164.53	164.702
2167.41	165.679
2170.3	166.16
2173.18	165.436
2176.06	164.404
2178.94	161.689
2181.82	160.05
2184.7	156.422
2187.58	152.754
2190.46	148.784
2193.33	143.816
2196.21	138.102
2199.08	133.903
2201.95	127.17
2204.83	121.958
2207.7	116.092
2210.57	111.1
2213.43	106.325
2216.3	100.061
2219.17	95.3103
2222.03	88.9162
2224.9	84.3339
2227.76	79.273
2230.62	73.3923
2233.49	68.4939
2236.34	64.2785
2239.2	59.434
2242.06	54.5953
2244.92	50.701
2247.78	48.6509
2250.63	44.9561
2253.48	42.4563
2256.34	40.2415
2259.19	38.1757
2262.04	36.9783
2264.89	34.0254
2267.74	32.5633
2270.59	32.05
2273.43	31.3435
2276.28	31.0205
2279.12	30.9513
2281.97	30.1192
2284.81	29.376
2287.65	27.5177
2290.49	26.3223
2293.33	23.8865
2296.17	20.6243
2299.01	19.6958
2301.84	18.5669
2304.68	17.532
2307.51	16.4669
2310.35	15.1736
2313.18	13.8807
2316.01	13.6677
2318.84	13.6017
2321.67	12.8279
2324.5	11.5608
2327.33	10.6017
2330.15	10.3455
2332.98	9.87056
2335.8	9.7341
2338.62	9.12346
2341.45	8.04899
2344.27	7.56685
2347.09	6.20799
2349.91	5.16395
2352.72	4.00359
2355.54	2.67919
2358.36	1.30521
2361.17	-0.416091
2363.98	-1.00018
2366.8	0.891096
2369.61	-0.146331
2372.42	-0.276578
2375.23	-0.133336
2378.04	0.662095
2380.85	-0.193148
2383.66	-0.162467
2386.46	0.725775
2389.26	1.63231
2392.07	1.83405
2394.87	2.46927
2397.67	3.70106
2400.47	4.53724
2403.27	4.90562
2406.07	5.44332
2408.87	5.49393
2411.67	6.54291
2414.46	7.2531
2417.26	6.58338
2420.05	7.43724
2422.84	8.05674
2425.64	8.53628
2428.43	8.21064
2431.22	8.45425
2434.01	8.71163
2436.79	9.08631
2439.58	9.68147
2442.37	10.0005
2445.15	8.98154
2447.93	8.41899
2450.72	8.51914
2453.5	8.21238
2456.28	8.36275
2459.06	8.40858
2461.84	8.16153
2464.62	7.85985
2467.39	7.67596
2470.17	7.75402
2472.94	6.61127
2475.72	6.16468
2478.49	5.38544
2481.26	5.08209
2484.03	4.32972
2486.8	4.47699
2489.57	4.30799
2492.34	4.66705
2495.1	4.58003
2497.87	3.89739
2500.63	4.00885
2503.4	4.52674
2506.16	5.7431
2508.92	4.61603
2511.68	3.56479
2514.44	3.11488
2517.2	3.041
2519.96	2.46313
2522.72	3.03536
2525.47	3.1218
2528.23	3.76463
2530.98	4.56136
2533.74	5.06031
2536.49	3.71832
2539.24	3.85991
2541.99	3.28697
2544.74	4.20282
2547.49	4.95506
2550.23	4.61028
2552.98	5.1232
2555.72	5.0607
2558.47	5.43627
2561.21	5.27603
2563.95	5.28572
2566.69	5.239
2569.43	6.16779
2572.17	6.56601
2574.91	4.79392
2577.65	3.39332
2580.39	2.6947
2583.12	2.95131
2585.85	2.36785
2588.59	2.01404
2591.32	1.67731
2594.05	1.2152
2596.78	1.16144
2599.51	0.749214
2602.24	-0.400235
2604.97	-0.602026
2607.69	0.101603
2610.42	0.708907
2613.14	1.543
2615.87	1.08356
2618.59	1.64271
2621.31	1.7586
2624.03	2.28859
2626.75	3.16991
2629.47	3.63931
2632.19	3.20449
2634.91	2.77289
2637.62	3.04231
2640.34	2.23885
2643.05	2.33577
2645.76	2.26989
2648.48	3.00249
2651.19	3.06418
2653.9	2.25406
2656.6	2.0656
2659.31	2.46436
2662.02	3.69479
2664.73	4.67723
2667.43	4.94462
2670.14	5.58589
2672.84	6.64202
2675.54	7.43225
2678.24	8.20724
2680.94	7.83222
2683.64	9.26996
2686.34	8.73798
2689.04	9.21604
2691.74	8.95161
2694.43	9.08617
2697.13	8.99155
2699.82	8.85039
2702.51	9.26808
2705.21	9.98898
2707.9	10.2476
2710.58	10.8314
2713.27	10.661
2715.96	11.1192
2718.65	12.4192
2721.33	13.4227
2724.02	13.9119
2726.71	14.3563
2729.39	15.2217
2732.07	16.0215
2734.75	15.6897
2737.43	15.9446
2740.11	16.8576
2742.79	16.8895
2745.47	16.6623
2748.14	15.3364
2750.82	15.595
2753.49	15.0919
2756.17	15.9579
2758.84	14.4564
2761.51	13.6675
2764.18	12.9819
2766.85	12.5611
2769.52	10.4163
2772.19	9.31888
2774.86	8.75124
2777.52	7.45204
2780.19	6.23171
2782.85	5.21001
2785.52	4.12777
2788.18	2.25151
2790.84	1.85979
2793.5	1.65896
2796.16	1.76298
2798.82	0.477427
2801.48	0.557898
2804.13	1.00084
2806.79	1.09211
2809.45	0.496684
2812.1	-0.0965922
2814.75	0.789849
2817.41	3.41366
2820.06	8.00876
2822.71	14.3629
2825.36	21.3991
2828	30.3345
2830.65	38.9744
2833.3	49.0363
2835.94	59.3814
2838.59	70.6711
2841.23	81.2433
2843.87	93.3456
2846.52	107.423
2849.16	120.649
2851.8	135.223
2854.44	151.316
2857.08	166.123
2859.71	180.479
2862.35	193.366
2864.98	205.416
2867.62	216.606
2870.25	224.472
2872.88	231.678
2875.52	238.98
2878.15	243.751
2880.78	248.139
2883.41	256.25
2886.03	262.532
2888.66	269.482
2891.29	274.952
2893.91	280.661
2896.54	286.718
2899.16	293.219
2901.78	301.625
2904.4	311.492
2907.02	324.807
2909.64	338.864
2912.26	355.38
2914.88	372.116
2917.5	388.698
2920.11	402.892
2922.73	416.293
2925.34	427.203
2927.96	434.488
2930.57	437.612
2933.18	438.865
2935.79	436.158
2938.4	430.979
2941.01	421.48
2943.62	410.415
2946.22	396.964
2948.83	381.962
2951.43	365.236
2954.04	347.164
2956.64	328.692
2959.24	309.089
2961.84	291.201
2964.45	273.674
2967.05	257.765
2969.64	242.397
2972.24	229.001
2974.84	215.208
2977.43	202.337
2980.03	188.139
2982.62	175.15
2985.22	162.072
2987.81	148.815
2990.4	135.194
2992.99	120.609
2995.58	108.864
2998.17	98.2904
3000.76	87.5661
3003.34	77.4266
3005.93	68.9064
3008.52	58.573
3011.1	51.2462
3013.68	43.6856
3016.27	37.1886
3018.85	32.4855
3021.43	28.1646
3024.01	25.4434
3026.59	22.9264
3029.16	20.7863
3031.74	20.4231
3034.32	19.4709
3036.89	19.7766
3039.47	21.154
3042.04	21.8112
3044.61	23.1711
3047.18	24.9373
3049.75	25.703
3052.32	26.0346
3054.89	25.6793
3057.46	26.1141
3060.03	26.7078
3062.59	25.1451
3065.16	23.9191
3067.72	21.7888
3070.29	18.8161
3072.85	16.4646
3075.41	14.8928
3077.97	13.5142
3080.53	10.7805
3083.09	8.44358
3085.65	6.31376
3088.21	3.94943
3090.76	3.05078
3093.32	2.08574
3095.87	1.50428
3098.43	1.65717
3100.98	2.75121
3103.53	3.17549
3106.08	3.62177
3108.63	4.3347
3111.18	4.9803
3113.73	5.34613
3116.28	6.45141
3118.83	7.30909
3121.37	8.50185
3123.92	9.70711
3126.46	10.2309
3129	11.6032
3131.55	12.5507
3134.09	14.4439
3136.63	16.869
3139.17	18.0257
3141.71	18.3032
3144.24	19.141
3146.78	20.5472
3149.32	20.8643