File: data/Raman/poly_smoothed/Thy_40_11_50_1x_45s_532 nm_x100_100%_600 gr_mm_01.txt
#Acq. time (s)=	45
#Accumulations=	2
#Range (cm-¹)=	200...3150
#Windows=	2
#Auto scanning=	Off
#Autofocus=	Off
#Macrospot=	Off
#AutoExposure=	Off
#Spike filter=	Multiple accum.
#Delay time (s)=	0
#Binning=	1
#Readout mode=	Signal
#DeNoise=	Off
#ICS correction=	On
#Dark correction=	Off
#Inst. Process=	Off
#Detector Gain=	Best Dynamic Range
#Detector ADC=	20 kHz
#Detector temperature (°C)=	-69.85
#Instrument=	LabRAM HR Evol
#Detector=	Synapse
#Objective=	x100
#Grating=	600 gr/mm
#ND Filter=	100%
#Laser (nm)=	532
#Hole=	100.021
#Range=	Auto
#Laser Pol.=	No
#Raman. Pol.=	No
#Laser Pol. (°)=	-0.0007625
#Raman Pol. (°)=	89.9995
#Collection=	Microscope
#StageXY=	Marzhauser
#StageZ=	Marzhauser
#X (µm)=	268.8
#Y (µm)=	1691.3
#Z (µm)=	427.7
#Full time(mm:ss)=	3:18
#Project=
#Sample=
#Site=
#Title=	Thy_40_11_50_2x_45s_532 nm_x100_100%_600 gr_mm
#Remark=
#Date=	05.07.2022 13:37
#Acquired=	05.07.2022 13:37:58
#Base:Fit=	10.08.2022 10:01:35
#Base:Sub=	10.08.2022 10:01:52
#Filter:Polynom=	16.08.2022 10:21:53
#AxisType[0]=Intens
#AxisUnit[0]=Cnt
#AxisType[1]=Spectr
#AxisUnit[1]=1/cm
200.43	6.15257
204.059	5.19928
207.688	5.5345
211.314	6.7525
214.941	6.82212
218.564	6.1186
222.186	4.94391
225.809	5.8856
229.428	4.46046
233.045	2.84884
236.663	6.27268
240.278	7.99388
243.891	9.75368
247.503	10.7763
251.116	11.813
254.725	10.6814
258.333	12.0112
261.939	12.5736
265.544	11.7974
269.148	12.7045
272.75	13.3411
276.351	13.5211
279.95	12.9007
283.548	12.7146
287.144	12.6939
290.739	13.2082
294.333	14.6415
297.925	13.4331
301.514	14.0128
305.104	12.5616
308.692	12.4996
312.279	13.6515
315.862	13.4374
319.446	14.0831
323.029	16.965
326.608	19.1469
330.188	19.4105
333.766	20.3132
337.341	20.7396
340.917	21.2942
344.489	20.9121
348.062	21.6669
351.631	20.8014
355.201	19.7013
358.768	19.5392
362.333	17.7401
365.899	16.9289
369.462	15.2658
373.023	16.7568
376.585	16.7623
380.143	17.0562
383.7	17.2825
387.256	16.7505
390.812	15.9725
394.365	16.0667
397.916	17.3944
401.467	16.3513
405.015	18.0629
408.563	17.9516
412.109	19.1946
415.654	19.2107
419.197	20.2938
422.739	19.488
426.279	17.8153
429.819	16.4327
433.356	14.9754
436.891	13.9266
440.426	13.0442
443.96	12.5189
447.492	12.0036
451.021	11.4233
454.551	10.2268
458.079	11.9496
461.604	13.2959
465.13	13.8208
468.654	14.4403
472.175	14.9173
475.696	15.2666
479.215	16.1211
482.733	16.692
486.249	17.5057
489.765	17.6676
493.278	18.5127
496.789	20.8779
500.301	21.4303
503.81	20.4244
507.317	19.1765
510.825	17.7263
514.33	17.7614
517.833	16.1402
521.335	15.529
524.836	14.4472
528.335	13.256
531.835	14.104
535.332	13.6585
538.827	12.1073
542.321	12.4766
545.814	12.4727
549.305	12.569
552.795	11.371
556.282	10.1818
559.769	7.89676
563.255	7.41535
566.739	8.34937
570.223	7.78915
573.705	6.86284
577.183	7.73026
580.663	7.35169
584.141	6.64148
587.615	5.37322
591.09	4.19029
594.564	3.52611
598.035	3.71202
601.506	3.77508
604.974	3.84596
608.443	4.0632
611.908	3.17398
615.374	3.9276
618.837	4.30299
622.3	3.55562
625.761	4.06499
629.219	5.84182
632.677	7.00033
636.135	8.04471
639.59	8.07061
643.043	9.00183
646.495	9.78544
649.948	10.1088
653.398	10.8761
656.846	9.90076
660.293	9.24829
663.738	9.29777
667.183	9.11114
670.626	10.0125
674.067	10.3889
677.508	11.6335
680.947	13.1403
684.385	12.4754
687.821	13.1121
691.254	13.1263
694.688	13.4716
698.121	12.5639
701.552	14.1102
704.98	15.0139
708.409	15.5272
711.836	17.2853
715.26	19.5388
718.685	20.784
722.108	20.4565
725.528	22.6234
728.949	23.4506
732.367	23.4814
735.785	25.394
739.2	28.6303
742.614	30.3935
746.028	31.8499
749.439	35.57
752.849	38.3661
756.26	40.5765
759.667	42.993
763.073	44.6056
766.477	45.3649
769.883	48.3017
773.285	50.2303
776.686	53.3994
780.085	55.7245
783.484	57.8832
786.881	59.0615
790.276	59.016
793.671	60.5712
797.064	62.0897
800.456	62.4825
803.846	62.219
807.234	64.7144
810.622	65.5987
814.008	64.5347
817.394	64.689
820.778	64.7513
824.159	65.1251
827.541	63.564
830.921	62.4003
834.298	62.4232
837.676	61.3994
841.051	59.4748
844.426	57.5399
847.798	56.516
851.171	54.1266
854.54	52.6413
857.911	50.4782
861.278	49.7602
864.645	48.6571
868.01	46.6729
871.373	43.7658
874.735	43.4056
878.097	42.3156
881.457	41.0354
884.815	42.7067
888.172	43.3531
891.528	42.384
894.882	41.4194
898.237	40.3177
901.589	40.5845
904.94	41.1939
908.289	39.9053
911.635	39.7457
914.982	37.5848
918.328	36.2282
921.672	34.0955
925.015	31.6988
928.357	29.9782
931.698	27.243
935.035	25.964
938.373	24.1947
941.71	24.0311
945.044	23.1279
948.378	22.0681
951.709	21.5759
955.041	21.2339
958.372	20.6659
961.699	22.0436
965.027	21.4868
968.352	21.4454
971.676	19.3898
975	19.6995
978.322	20.2417
981.642	20.2174
984.962	18.7062
988.28	16.7393
991.596	15.1985
994.911	14.0785
998.227	12.4077
1001.54	10.6766
1004.85	10.7316
1008.16	9.50743
1011.47	8.15742
1014.78	7.68098
1018.08	7.79237
1021.39	8.22011
1024.69	7.90026
1028	8.77633
1031.3	10.5692
1034.6	10.5518
1037.9	10.0223
1041.19	9.19117
1044.49	10.4049
1047.78	11.2349
1051.08	13.7507
1054.37	14.472
1057.66	15.6784
1060.95	17.3803
1064.24	17.2997
1067.53	18.3696
1070.81	19.4588
1074.1	22.3491
1077.38	22.5279
1080.66	23.7899
1083.94	25.5291
1087.22	25.9654
1090.5	27.0031
1093.78	28.8874
1097.05	30.5302
1100.33	30.0222
1103.6	31.276
1106.87	31.9214
1110.14	31.9368
1113.41	30.7849
1116.68	28.8396
1119.95	26.6842
1123.21	26.0108
1126.48	25.0368
1129.74	23.014
1133	20.1256
1136.26	17.6975
1139.52	17.1939
1142.78	15.1326
1146.04	13.2243
1149.29	11.2698
1152.55	8.61072
1155.8	7.98268
1159.05	6.56264
1162.3	7.17773
1165.55	6.76386
1168.8	6.68094
1172.05	6.77843
1175.29	6.50347
1178.54	4.09505
1181.78	4.73512
1185.02	4.42682
1188.26	4.94806
1191.5	3.44532
1194.74	2.54152
1197.97	2.12441
1201.21	2.23869
1204.44	2.90871
1207.68	4.56008
1210.91	7.31487
1214.14	7.58995
1217.37	9.02195
1220.59	11.4283
1223.82	12.4791
1227.05	14.6569
1230.27	15.9372
1233.49	17.7876
1236.72	20.0293
1239.94	22.0261
1243.16	25.1322
1246.37	26.7165
1249.59	28.0635
1252.8	28.9501
1256.02	30.1537
1259.23	31.8854
1262.44	33.1055
1265.66	33.4138
1268.86	34.9123
1272.07	36.8141
1275.28	40.3463
1278.48	42.5497
1281.69	46.6123
1284.89	51.2696
1288.09	55.2275
1291.29	57.8255
1294.49	61.3261
1297.69	64.9334
1300.89	69.6859
1304.08	74.5531
1307.28	79.8101
1310.47	86.1634
1313.66	92.9596
1316.85	99.074
1320.04	106.205
1323.23	111.199
1326.42	113.962
1329.61	116.176
1332.79	119.236
1335.97	122.176
1339.16	124.478
1342.34	126.146
1345.52	128.081
1348.7	128.576
1351.87	127.681
1355.05	127.781
1358.22	125.513
1361.4	123.223
1364.57	118.184
1367.74	114.311
1370.91	108.475
1374.08	103.805
1377.25	97.3818
1380.41	94.7725
1383.58	92.292
1386.74	90.2803
1389.91	86.0313
1393.07	83.2684
1396.23	79.8966
1399.39	75.8346
1402.55	71.7931
1405.7	68.1192
1408.86	66.7429
1412.01	65.9536
1415.17	64.8277
1418.32	63.9219
1421.47	64.4019
1424.62	64.7139
1427.77	64.2206
1430.91	64.8174
1434.06	65.2277
1437.2	64.2602
1440.35	63.5578
1443.49	62.6867
1446.63	62.5246
1449.77	61.5595
1452.91	59.9421
1456.05	59.4963
1459.18	60.0073
1462.32	58.2658
1465.45	57.5201
1468.59	55.2707
1471.72	52.8198
1474.85	50.2636
1477.98	48.1415
1481.1	45.8232
1484.23	45.05
1487.36	41.9121
1490.48	40.913
1493.61	39.5683
1496.73	38.0898
1499.85	37.4822
1502.97	36.2299
1506.09	36.802
1509.2	37.1005
1512.32	36.8616
1515.43	37.7336
1518.55	38.7436
1521.66	39.3241
1524.77	40.5765
1527.88	42.0144
1530.99	44.4119
1534.1	45.0559
1537.21	47.229
1540.31	49.3497
1543.42	53.6756
1546.52	54.0669
1549.62	57.0642
1552.72	61.5013
1555.82	64.2069
1558.92	67.2268
1562.02	71.0997
1565.11	75.1488
1568.21	79.5094
1571.3	84.6174
1574.39	87.1952
1577.49	90.1417
1580.57	93.6185
1583.66	96.1245
1586.75	98.5113
1589.84	101.918
1592.92	104.946
1596.01	106.236
1599.09	107.908
1602.17	108.906
1605.25	108.753
1608.33	105.969
1611.41	102.839
1614.49	99.5439
1617.57	96.208
1620.64	90.5635
1623.72	86.3447
1626.79	82.6864
1629.86	76.1473
1632.93	71.0624
1636	66.3581
1639.07	62.0146
1642.13	58.4093
1645.2	55.0052
1648.26	50.7215
1651.33	45.6634
1654.39	41.9348
1657.45	37.9442
1660.51	35.9761
1663.57	34.6738
1666.63	34.4426
1669.68	35.7969
1672.74	35.1593
1675.79	34.7169
1678.85	34.5773
1681.9	34.5625
1684.95	35.2527
1688	34.3066
1691.05	34.3805
1694.09	35.1176
1697.14	35.025
1700.18	35.0258
1703.23	34.1573
1706.27	35.4108
1709.31	36.2441
1712.35	37.3856
1715.39	36.6377
1718.43	35.8918
1721.47	34.6763
1724.5	32.6788
1727.54	30.3804
1730.57	27.6342
1733.61	27.5575
1736.64	27.2291
1739.67	26.7711
1742.7	26.8553
1745.72	25.2922
1748.75	24.1114
1751.77	23.6192
1754.8	23.785
1757.82	22.2806
1760.84	20.8859
1763.87	18.2334
1766.89	18.0912
1769.91	18.3807
1772.92	17.8776
1775.94	18.2858
1778.95	19.1455
1781.97	18.4355
1784.98	18.146
1787.99	17.2551
1791.01	17.1866
1794.01	17.1286
1797.02	17.5132
1800.03	17.5458
1803.04	18.6357
1806.04	19.3653
1809.05	19.3117
1812.05	19.0076
1815.05	18.4145
1818.05	17.3836
1821.05	16.9797
1824.05	15.9514
1827.05	15.2949
1830.04	14.8259
1833.04	13.47
1836.03	12.2715
1839.03	10.9414
1842.02	10.6953
1845.01	8.82887
1848	7.30401
1850.99	6.20948
1853.97	4.64639
1856.96	2.71459
1859.94	2.24931
1862.93	1.37168
1865.91	1.43308
1868.89	1.12499
1871.87	1.78358
1874.85	2.42334
1877.83	2.46177
1880.81	1.97469
1882.57	2.04255
1885.56	2.56782
1888.55	2.54756
1891.54	3.31016
1894.52	3.96104
1897.51	4.51837
1900.49	5.36335
1903.47	5.92776
1906.45	4.76121
1909.43	4.93401
1912.41	4.80881
1915.39	4.59982
1918.37	5.03812
1921.34	5.98602
1924.32	4.60156
1927.29	3.90023
1930.26	3.18993
1933.23	3.5325
1936.2	2.9406
1939.17	3.6319
1942.14	3.44673
1945.11	4.12233
1948.07	4.06768
1951.04	4.54578
1954	5.5535
1956.96	4.84319
1959.93	5.54064
1962.89	5.36606
1965.85	4.4658
1968.8	5.15544
1971.76	5.72657
1974.72	6.58626
1977.67	7.32257
1980.63	8.3827
1983.58	7.45253
1986.53	7.56695
1989.48	8.98638
1992.43	10.3595
1995.38	10.2271
1998.32	10.4788
2001.27	10.38
2004.22	11.6492
2007.16	12.4178
2010.1	12.607
2013.04	13.3518
2015.98	13.3871
2018.92	14.3429
2021.86	14.9205
2024.8	14.4711
2027.74	14.6284
2030.67	13.7553
2033.61	12.2252
2036.54	11.6245
2039.47	12.2246
2042.4	13.2359
2045.33	13.7813
2048.26	13.8383
2051.19	13.0079
2054.12	10.9583
2057.04	10.9367
2059.97	11.0573
2062.89	10.9464
2065.81	10.6661
2068.73	9.04957
2071.65	9.11887
2074.57	9.33081
2077.49	8.97515
2080.41	8.88218
2083.32	8.14199
2086.24	9.41185
2089.15	9.44995
2092.07	10.0372
2094.98	10.2637
2097.89	10.968
2100.8	11.8141
2103.71	11.4303
2106.61	12.2644
2109.52	13.9806
2112.43	14.408
2115.33	14.9585
2118.23	15.9776
2121.13	15.5994
2124.04	13.958
2126.94	13.4544
2129.83	13.7284
2132.73	13.456
2135.63	14.2742
2138.53	13.6944
2141.42	11.9966
2144.31	12.976
2147.21	13.8313
2150.1	13.4684
2152.99	13.4221
2155.88	12.8017
2158.77	13.4017
2161.65	13.7872
2164.54	13.5387
2167.43	14.0162
2170.31	14.9781
2173.19	13.8326
2176.07	14.1928
2178.96	14.9567
2181.84	15.9603
2184.72	15.2001
2187.59	15.585
2190.47	16.2153
2193.35	17.2584
2196.22	17.8572
2199.09	18.2981
2201.97	17.8301
2204.84	18.2858
2207.71	18.6432
2210.58	17.8326
2213.45	18.275
2216.31	19.1919
2219.18	18.6503
2222.05	18.5322
2224.91	17.721
2227.78	17.4679
2230.64	17.1038
2233.5	15.5867
2236.36	15.2894
2239.22	15.2217
2242.08	14.2899
2244.93	13.7523
2247.79	13.7002
2250.64	14.535
2253.5	14.8064
2256.35	14.8605
2259.2	15.3648
2262.05	15.1793
2264.9	14.758
2267.75	13.3544
2270.6	12.3043
2273.45	13.2425
2276.29	13.8346
2279.14	13.2384
2281.98	12.8045
2284.82	13.2175
2287.66	13.2124
2290.5	13.3372
2293.34	11.3542
2296.18	10.9145
2299.02	12.3127
2301.86	12.526
2304.69	13.0163
2307.53	14.1514
2310.36	13.8789
2313.19	14.3409
2316.02	14.6546
2318.85	15.1948
2321.68	15.0523
2324.51	14.7656
2327.34	13.4414
2330.16	12.5202
2332.99	12.038
2335.81	10.8692
2338.64	11.1955
2341.46	10.341
2344.28	10.3176
2347.1	8.11878
2349.92	7.0712
2352.74	6.19378
2355.55	5.52827
2358.37	4.21596
2361.19	3.51862
2364	4.79762
2366.81	7.01793
2369.62	7.61055
2372.44	7.54128
2375.24	7.2698
2378.05	7.1175
2380.86	6.4801
2383.67	6.18792
2386.47	5.72874
2389.28	4.83498
2392.08	4.60895
2394.89	4.13045
2397.69	4.77277
2400.49	4.6106
2403.29	4.11183
2406.09	3.8789
2408.88	3.41338
2411.68	3.07179
2414.48	2.34244
2417.27	3.43557
2420.06	3.96549
2422.86	4.3432
2425.65	4.32232
2428.44	4.26192
2431.23	6.33205
2434.02	6.1508
2436.81	5.95906
2439.59	6.63147
2442.38	6.67107
2445.16	6.27659
2447.95	5.96461
2450.73	4.9711
2453.51	4.88757
2456.29	3.50112
2459.07	3.95823
2461.85	4.08276
2464.63	3.43077
2467.4	1.93353
2470.18	-0.297021
2472.95	-0.871444
2475.73	-0.585821
2478.5	-0.510735
2481.27	0.024186
2484.04	1.33535
2486.81	0.380424
2489.58	0.348242
2492.35	-0.149059
2495.12	0.667621
2497.88	2.29139
2500.65	2.82407
2503.41	3.17168
2506.17	3.44523
2508.94	4.93874
2511.7	4.98772
2514.46	4.997
2517.22	5.4117
2519.97	5.15447
2522.73	4.50708
2525.49	4.31103
2528.24	4.23916
2530.99	3.7911
2533.75	2.25626
2536.5	1.57483
2539.25	2.17892
2542	2.65124
2544.75	2.78948
2547.5	1.89913
2550.24	1.26029
2552.99	2.17816
2555.74	1.04007
2558.48	1.42985
2561.22	2.55481
2563.96	2.56399
2566.71	3.32306
2569.45	2.80886
2572.18	2.51437
2574.92	3.00676
2577.66	2.71066
2580.4	2.07929
2583.13	2.08865
2585.87	3.00068
2588.6	2.97296
2591.33	2.48032
2594.06	2.85774
2596.79	3.26685
2599.52	2.67873
2602.25	1.89582
2604.98	2.40893
2607.71	2.30808
2610.43	2.21997
2613.16	2.38487
2615.88	3.3955
2618.6	3.70665
2621.32	4.37273
2624.04	5.50098
2626.76	6.09433
2629.48	6.15455
2632.2	6.57092
2634.92	6.99146
2637.63	6.81943
2640.35	6.85674
2643.06	6.57221
2645.77	5.91834
2648.49	6.69209
2651.2	7.31833
2653.91	7.00615
2656.62	6.54529
2659.33	7.55052
2662.03	7.2509
2664.74	6.89608
2667.44	6.39211
2670.15	5.70631
2672.85	6.74781
2675.55	6.06871
2678.26	5.68815
2680.96	6.41766
2683.66	6.71396
2686.35	6.54643
2689.05	7.4835
2691.75	7.87263
2694.44	7.54294
2697.14	7.18577
2699.83	7.55172
2702.52	7.91548
2705.22	8.31254
2707.91	6.94545
2710.6	6.77813
2713.29	7.40482
2715.97	6.82972
2718.66	6.84538
2721.35	6.65627
2724.03	6.60795
2726.72	7.0017
2729.4	6.40358
2732.08	5.93508
2734.76	5.99351
2737.44	6.57717
2740.12	5.54028
2742.8	4.27556
2745.48	4.49556
2748.16	4.64944
2750.83	5.24698
2753.51	4.713
2756.18	4.77427
2758.85	4.56753
2761.53	4.97854
2764.2	4.72103
2766.87	4.88632
2769.54	4.76642
2772.2	4.45755
2774.87	4.02464
2777.54	4.13985
2780.2	2.89422
2782.87	1.68404
2785.53	1.29531
2788.19	0.451766
2790.85	0.971138
2793.51	0.574654
2796.17	1.01476
2798.83	1.38772
2801.49	1.70393
2804.15	1.69522
2806.8	1.87833
2809.46	3.38097
2812.11	3.95195
2814.76	4.91343
2817.42	6.24664
2820.07	7.85856
2822.72	10.0906
2825.37	11.2707
2828.02	13.2967
2830.66	15.4464
2833.31	17.7919
2835.96	20.8959
2838.6	23.012
2841.24	24.8929
2843.89	26.5041
2846.53	27.6764
2849.17	30.053
2851.81	33.6336
2854.45	37.457
2857.09	41.4833
2859.72	46.0976
2862.36	50.8273
2865	55.1532
2867.63	59.6387
2870.26	64.212
2872.9	68.7365
2875.53	71.4574
2878.16	74.8568
2880.79	77.9612
2883.42	80.4571
2886.05	81.976
2888.67	84.8753
2891.3	85.5476
2893.92	85.7771
2896.55	85.9868
2899.17	85.3978
2901.79	83.2174
2904.42	81.534
2907.04	79.7175
2909.66	78.2703
2912.27	76.8356
2914.89	74.9109
2917.51	74.3949
2920.13	74.4419
2922.74	74.2657
2925.35	74.3694
2927.97	73.0114
2930.58	71.713
2933.19	70.2949
2935.8	67.9305
2938.41	65.379
2941.02	62.8182
2943.63	60.4363
2946.24	57.9886
2948.84	55.564
2951.45	52.1145
2954.05	49.5081
2956.65	46.4218
2959.26	42.5252
2961.86	39.205
2964.46	35.572
2967.06	32.978
2969.66	30.7137
2972.25	27.217
2974.85	25.3422
2977.45	22.7234
2980.04	20.7819
2982.64	18.9617
2985.23	17.2646
2987.82	15.5385
2990.41	13.7273
2993	10.8894
2995.59	8.58121
2998.18	7.05369
3000.77	4.72953
3003.36	2.40363
3005.94	1.52461
3008.53	1.02461
3011.11	0.629522
3013.69	0.087629
3016.28	0.140061
3018.86	0.0774327
3021.44	-0.551116
3024.02	-0.518091
3026.6	-0.441865
3029.18	0.190919
3031.75	0.0365758
3034.33	0.128103
3036.9	0.887026
3039.48	0.727521
3042.05	0.560322
3044.62	0.771381
3047.19	0.960582
3049.77	1.44501
3052.34	1.75196
3054.9	1.83273
3057.47	2.37978
3060.04	2.82262
3062.61	2.76483
3065.17	2.49857
3067.74	2.7794
3070.3	3.94486
3072.86	3.78932
3075.42	2.42562
3077.99	2.06382
3080.54	0.840901
3083.1	0.723529
3085.66	1.32746
3088.22	2.26172
3090.78	2.49888
3093.33	3.50722
3095.89	3.72863
3098.44	3.83821
3100.99	4.21212
3103.54	3.87625
3106.1	4.6403
3108.65	5.96812
3111.2	8.06344
3113.74	9.26236
3116.29	10.9974
3118.84	12.3939
3121.38	13.9014
3123.93	15.0893
3126.47	15.92
3129.01	17.4765
3131.56	18.6172
3134.1	17.8982
3136.64	17.2562
3139.18	18.0284
3141.72	19.0261
3144.26	19.6307
3146.79	18.9328
3149.33	16.1565