File: data/Raman/poly_smoothed/Thy_30_10_07_1x_45s_532 nm_x100_100%_600 gr_mm_01.txt
#Acq. time (s)=	45
#Accumulations=	2
#Range (cm-¹)=	200...3150
#Windows=	2
#Auto scanning=	Off
#Autofocus=	Off
#Macrospot=	Off
#AutoExposure=	Off
#Spike filter=	Multiple accum.
#Delay time (s)=	0
#Binning=	1
#Readout mode=	Signal
#DeNoise=	Off
#ICS correction=	On
#Dark correction=	Off
#Inst. Process=	Off
#Detector Gain=	Best Dynamic Range
#Detector ADC=	20 kHz
#Detector temperature (°C)=	-69.85
#Instrument=	LabRAM HR Evol
#Detector=	Synapse
#Objective=	x100
#Grating=	600 gr/mm
#ND Filter=	100%
#Laser (nm)=	532
#Hole=	100.021
#Range=	Auto
#Laser Pol.=	No
#Raman. Pol.=	No
#Laser Pol. (°)=	-0.0007625
#Raman Pol. (°)=	89.9995
#Collection=	Microscope
#StageXY=	Marzhauser
#StageZ=	Marzhauser
#X (µm)=	4750.1
#Y (µm)=	-7736.3
#Z (µm)=	584.25
#Full time(mm:ss)=	3:19
#Project=
#Sample=
#Site=
#Title=	Thy_30_10_07_2x_45s_532 nm_x100_100%_600 gr_mm
#Remark=
#Date=	30.06.2022 11:52
#Acquired=	30.06.2022 11:52:23
#Base:Fit=	10.08.2022 09:56:48
#Base:Fit=	10.08.2022 09:57:06
#Base:Fit=	10.08.2022 09:57:43
#Base:Fit=	10.08.2022 09:57:50
#Base:Fit=	10.08.2022 09:58:11
#Base:Sub=	10.08.2022 09:58:44
#Filter:Polynom=	16.08.2022 10:22:53
#AxisType[0]=Intens
#AxisUnit[0]=Cnt
#AxisType[1]=Spectr
#AxisUnit[1]=1/cm
200.533	25.1113
204.162	27.7223
207.792	26.0185
211.418	23.9649
215.044	22.2412
218.667	22.027
222.289	21.4081
225.912	18.7662
229.531	16.5777
233.148	13.574
236.766	13.0507
240.381	12.0252
243.994	10.5506
247.606	8.77975
251.217	7.31868
254.828	6.9417
258.436	5.5429
262.042	4.58368
265.647	5.43184
269.25	3.54954
272.852	3.28913
276.453	2.98552
280.052	5.15812
283.65	5.77524
287.247	6.151
290.842	5.41064
294.436	5.70508
298.028	9.0629
301.617	11.0211
305.206	13.1095
308.794	14.2598
312.381	14.3881
315.964	15.9009
319.548	17.6723
323.131	18.8614
326.71	20.8417
330.29	22.1811
333.868	21.734
337.443	21.5615
341.018	21.7271
344.591	20.9712
348.163	19.2445
351.733	17.6707
355.303	16.5322
358.869	14.196
362.435	13.6974
366.001	13.9273
369.563	12.951
373.124	11.1638
376.686	11.0411
380.244	10.3882
383.801	10.8125
387.357	10.9395
390.911	9.47963
394.466	8.79919
398.018	8.7272
401.568	9.04168
405.117	8.70284
408.664	10.4137
412.21	10.8871
415.755	11.7891
419.298	11.5783
422.84	10.1897
426.38	9.90368
429.919	8.74308
433.455	8.19217
436.992	6.99307
440.527	6.92047
444.06	6.18181
447.593	6.01922
451.122	6.35777
454.651	6.30327
458.18	5.90688
461.705	6.88799
465.23	7.81447
468.752	7.56765
472.275	7.32194
475.797	6.98916
479.315	6.91314
482.834	8.40662
486.349	10.155
489.863	11.1449
493.378	13.0127
496.889	15.078
500.401	16.0492
503.91	16.5531
507.417	16.916
510.923	16.7176
514.43	16.896
517.933	16.8085
521.435	17.3621
524.936	19.1435
528.435	19.1807
531.933	18.5653
535.43	18.4608
538.927	16.6163
542.421	16.4943
545.913	15.5968
549.403	14.2441
552.893	12.4498
556.381	10.4627
559.868	9.83287
563.354	8.77528
566.839	7.57378
570.322	7.07951
573.802	6.10234
577.283	4.18977
580.762	3.26755
584.24	2.49537
587.714	1.11494
591.19	-0.978143
594.663	-0.84917
598.134	-0.80178
601.605	0.393979
605.073	1.40788
608.542	2.94413
612.007	2.9361
615.473	3.24189
618.936	3.72676
622.397	4.64021
625.859	5.15084
629.318	6.45192
632.775	6.99293
636.233	9.41436
639.688	11.2027
643.142	13.2473
646.594	14.5465
650.045	15.5843
653.496	16.4869
656.944	16.478
660.391	16.4719
663.837	17.3836
667.281	18.9641
670.724	19.4878
674.166	20.0368
677.606	22.3564
681.045	23.79
684.483	25.8312
687.917	28.83
691.352	30.2772
694.786	32.646
698.219	34.9455
701.65	37.0781
705.078	39.8697
708.506	40.889
711.934	42.8787
715.358	46.0049
718.782	49.343
722.204	50.7101
725.626	53.5706
729.045	55.5062
732.464	56.9286
735.881	57.0853
739.297	56.964
742.711	58.7464
746.125	59.7198
749.537	61.2533
752.946	62.091
756.357	63.9729
759.764	65.2435
763.17	66.4762
766.575	67.1483
769.978	69.0947
773.382	69.9283
776.783	70.3054
780.182	71.2968
783.581	70.8764
786.978	72.5499
790.373	72.936
793.768	74.0702
797.161	75.7559
800.552	77.8238
803.941	79.0583
807.33	78.8481
810.718	80.4831
814.105	79.8995
817.49	79.9297
820.873	79.7197
824.256	81.5293
827.637	81.7616
831.016	81.3803
834.395	80.4984
837.772	79.9854
841.147	79.2745
844.522	77.6191
847.894	75.167
851.267	72.7434
854.637	71.2721
858.007	69.8529
861.374	68.2483
864.739	67.2508
868.106	66.3308
871.469	64.7905
874.831	62.9015
878.193	62.6092
881.553	60.5782
884.911	59.4927
888.268	56.6379
891.623	56.1018
894.978	53.7892
898.331	54.1593
901.683	53.9834
905.033	53.4577
908.383	52.5922
911.731	50.7662
915.078	51.4983
918.423	50.0985
921.768	49.2927
925.111	48.4579
928.452	46.5359
931.791	43.7369
935.13	43.5245
938.468	43.1085
941.803	41.3722
945.139	40.8864
948.473	38.7282
951.804	37.8787
955.136	38.3933
958.465	37.8275
961.794	36.4453
965.12	36.6273
968.447	36.8748
971.771	38.4387
975.095	39.4076
978.417	40.67
981.737	41.7218
985.057	41.7592
988.375	43.7183
991.691	44.3112
995.006	45.2313
998.32	45.7054
1001.63	44.7549
1004.95	45.7594
1008.26	43.6237
1011.56	43.2554
1014.87	42.4663
1018.18	41.6005
1021.48	39.5886
1024.79	38.9845
1028.09	35.9156
1031.39	35.7586
1034.69	35.446
1037.99	33.6128
1041.29	31.3907
1044.58	32.4058
1047.88	31.9108
1051.17	31.8414
1054.46	29.6303
1057.75	27.97
1061.04	27.5975
1064.33	26.3858
1067.62	26.5024
1070.9	24.0979
1074.19	23.0763
1077.47	22.1559
1080.76	22.4334
1084.04	21.7795
1087.32	22.8644
1090.59	23.1512
1093.87	24.186
1097.15	25.5936
1100.42	26.1136
1103.69	26.8886
1106.97	26.9984
1110.24	28.6278
1113.51	29.6556
1116.77	29.471
1120.04	28.7297
1123.31	28.9219
1126.57	28.3476
1129.83	26.4922
1133.1	24.6366
1136.36	22.8667
1139.62	23.8997
1142.87	22.8967
1146.13	19.6952
1149.38	16.6194
1152.64	14.698
1155.89	12.0874
1159.14	10.496
1162.39	8.93248
1165.64	8.2825
1168.89	7.27223
1172.14	8.18721
1175.38	9.42808
1178.63	10.3265
1181.87	9.28236
1185.11	10.3212
1188.35	11.9293
1191.59	14.4218
1194.83	15.2844
1198.07	18.0028
1201.3	19.9945
1204.53	22.942
1207.77	24.8048
1211	27.267
1214.23	30.9617
1217.46	35.1829
1220.69	38.7219
1223.91	39.6348
1227.14	41.4977
1230.36	44.2469
1233.59	47.4581
1236.81	50.3312
1240.03	52.3503
1243.25	54.8994
1246.46	57.9385
1249.68	60.1004
1252.9	62.2645
1256.11	64.4736
1259.32	66.5942
1262.54	68.6006
1265.75	70.8178
1268.96	73.5415
1272.16	74.4011
1275.37	75.7984
1278.57	77.9339
1281.78	79.6296
1284.98	80.5329
1288.18	81.2059
1291.38	82.8506
1294.58	84.3885
1297.78	82.7193
1300.98	83.4391
1304.17	84.6135
1307.37	87.0898
1310.56	89.1205
1313.76	89.5926
1316.95	88.6693
1320.14	90.0738
1323.32	90.3379
1326.51	88.823
1329.7	88.0481
1332.88	86.1493
1336.07	84.1771
1339.25	82.0153
1342.43	77.7874
1345.61	74.8794
1348.79	72.2396
1351.96	68.9667
1355.14	65.0127
1358.31	63.3296
1361.49	59.8229
1364.66	55.5564
1367.83	53.5963
1371	51.2593
1374.17	49.5142
1377.34	48.1964
1380.5	48.7967
1383.67	48.0255
1386.83	47.6203
1390	46.1986
1393.16	45.8102
1396.32	45.1983
1399.48	45.0067
1402.64	44.0327
1405.79	43.2398
1408.95	43.7859
1412.1	44.1932
1415.26	45.2363
1418.41	45.752
1421.56	46.5643
1424.71	50.3693
1427.86	54.4894
1431	58.9538
1434.15	64.1203
1437.29	69.6639
1440.44	73.3209
1443.58	77.1034
1446.72	79.1437
1449.86	80.8306
1453	81.0316
1456.14	81.0659
1459.27	80.1862
1462.41	76.6861
1465.54	71.6652
1468.67	66.7287
1471.81	60.2093
1474.94	53.565
1478.07	46.7305
1481.19	40.3795
1484.32	34.8077
1487.45	28.9478
1490.57	24.1991
1493.69	20.4946
1496.82	17.0473
1499.94	16.2976
1503.06	16.6076
1506.17	15.6611
1509.29	16.527
1512.41	16.8961
1515.52	17.832
1518.64	18.3283
1521.75	20.2301
1524.86	21.2294
1527.97	24.1492
1531.08	26.0157
1534.19	28.5065
1537.29	32.0307
1540.4	35.5642
1543.5	38.5918
1546.61	41.3173
1549.71	44.3135
1552.81	49.7202
1555.91	55.013
1559.01	57.7761
1562.11	61.9148
1565.2	65.5849
1568.29	68.8318
1571.39	71.6321
1574.48	75.0257
1577.57	77.0694
1580.66	77.0401
1583.75	78.2465
1586.84	79.2904
1589.93	79.8874
1593.01	78.3839
1596.1	76.4668
1599.18	74.946
1602.26	71.4921
1605.34	70.4327
1608.42	69.0537
1611.5	69.0518
1614.58	68.5849
1617.65	66.7202
1620.73	66.1278
1623.8	67.1628
1626.87	70.211
1629.95	71.7693
1633.02	72.015
1636.09	73.0505
1639.15	76.1094
1642.22	78.8252
1645.29	81.3676
1648.35	85.1988
1651.42	88.0168
1654.48	89.624
1657.54	91.0625
1660.6	91.8153
1663.66	91.6202
1666.72	89.0631
1669.77	85.3661
1672.83	80.2506
1675.88	75.8575
1678.93	70.1912
1681.99	65.4748
1685.04	59.6837
1688.09	52.3974
1691.13	45.5455
1694.18	39.6172
1697.23	34.4862
1700.27	28.8214
1703.32	23.4172
1706.36	17.4191
1709.4	13.2557
1712.44	10.1226
1715.48	8.62488
1718.52	6.76402
1721.56	5.5995
1724.59	5.75006
1727.63	5.31914
1730.66	4.25415
1733.69	3.11896
1736.72	3.07038
1739.75	2.98059
1742.78	2.27193
1745.81	2.38627
1748.84	2.08636
1751.86	2.05064
1754.89	0.484691
1757.91	1.0237
1760.93	0.0220707
1763.95	-0.480774
1766.97	-0.770356
1769.99	-0.829653
1773.01	-0.989368
1776.03	-1.63566
1779.04	-1.2557
1782.06	-0.979308
1785.07	-0.898546
1788.08	-0.342922
1791.09	-0.536749
1794.1	0.0451053
1797.11	0.807393
1800.12	0.794071
1803.12	-0.118582
1806.13	-0.121958
1809.13	0.906891
1812.14	1.23768
1815.14	1.34471
1818.14	2.19408
1821.14	3.5074
1824.14	2.6865
1827.13	2.77503
1830.13	3.32943
1833.12	4.09074
1836.12	4.43581
1839.11	4.437
1842.1	5.35766
1845.09	6.21817
1848.08	7.33595
1851.07	7.72744
1854.06	8.5346
1857.04	7.66669
1860.03	7.37875
1863.01	8.50946
1866	9.29785
1868.98	9.23212
1871.96	9.07971
1874.94	9.31355
1877.92	9.56601
1880.89	9.3856
1882.48	9.56566
1885.47	10.9413
1888.46	10.9804
1891.44	12.1502
1894.43	12.7865
1897.41	12.3235
1900.4	12.5407
1903.38	12.1772
1906.36	12.1049
1909.34	11.4082
1912.32	12.2158
1915.29	12.8826
1918.27	13.109
1921.25	12.3283
1924.22	12.3054
1927.2	11.7211
1930.17	11.0873
1933.14	11.8318
1936.11	11.5851
1939.08	11.8234
1942.05	12.2103
1945.01	11.657
1947.98	11.6464
1950.94	12.0634
1953.91	12.4471
1956.87	12.999
1959.83	13.7172
1962.79	13.206
1965.75	13.49
1968.71	12.7521
1971.67	12.3927
1974.62	12.0936
1977.58	12.9648
1980.53	14.1077
1983.48	14.766
1986.43	15.8087
1989.38	15.5734
1992.33	15.4675
1995.28	15.3611
1998.23	15.5874
2001.18	15.0416
2004.12	15.7751
2007.06	16.1558
2010.01	16.0981
2012.95	17.0778
2015.89	16.1139
2018.83	16.3543
2021.77	17.379
2024.71	18.1588
2027.64	17.7763
2030.58	17.3431
2033.51	17.5949
2036.45	17.1098
2039.38	16.9802
2042.31	16.8781
2045.24	17.6939
2048.17	19.6603
2051.1	20.5049
2054.02	21.1318
2056.95	21.9708
2059.87	22.3864
2062.8	22.1374
2065.72	22.5544
2068.64	23.2773
2071.56	23.0377
2074.48	24.0093
2077.4	25.5394
2080.31	26.8382
2083.23	26.8269
2086.14	28.1157
2089.06	29.8448
2091.97	32.2604
2094.88	32.8019
2097.79	32.9044
2100.7	33.9705
2103.61	36.032
2106.52	38.6426
2109.43	39.7222
2112.33	42.1588
2115.24	45.385
2118.14	48.5015
2121.04	52.0514
2123.94	55.4443
2126.84	57.9745
2129.74	62.2469
2132.64	66.6742
2135.54	70.8161
2138.43	73.6282
2141.33	77.7574
2144.22	81.0101
2147.11	85.5923
2150.01	89.1448
2152.9	92.3067
2155.79	96.2242
2158.67	100.168
2161.56	102.187
2164.45	103.079
2167.33	103.44
2170.22	104.396
2173.1	104.634
2175.98	104.525
2178.86	103.719
2181.74	102.641
2184.62	99.588
2187.5	97.2836
2190.38	94.4825
2193.25	91.1754
2196.13	87.9657
2199	84.9733
2201.88	81.8118
2204.75	78.2435
2207.62	74.7388
2210.49	70.6426
2213.36	67.4486
2216.22	64.8835
2219.09	61.9409
2221.96	59.771
2224.82	57.2962
2227.68	55.3212
2230.55	52.0552
2233.41	49.6365
2236.27	47.4179
2239.12	45.4098
2241.98	44.7019
2244.84	43.5978
2247.7	42.2454
2250.55	41.0388
2253.41	39.442
2256.26	38.024
2259.11	37.1905
2261.96	36.2705
2264.81	35.7876
2267.66	34.4158
2270.51	33.7809
2273.35	32.2599
2276.2	30.5969
2279.04	28.9028
2281.89	27.2056
2284.73	26.3674
2287.57	25.7096
2290.41	24.9002
2293.25	23.0021
2296.09	21.6316
2298.93	21.1475
2301.76	20.8582
2304.6	20.0953
2307.44	19.7521
2310.27	18.9524
2313.1	19.3959
2315.93	19.1972
2318.76	18.4324
2321.59	17.7957
2324.42	17.8155
2327.25	17.7091
2330.07	17.4118
2332.9	16.7468
2335.72	15.624
2338.55	14.4053
2341.37	13.3209
2344.19	12.0843
2347.01	11.2375
2349.83	10.106
2352.65	9.6505
2355.46	10.0738
2358.28	8.85076
2361.09	9.36408
2363.91	8.75209
2366.72	9.30262
2369.53	9.0393
2372.34	9.94901
2375.15	9.51804
2377.96	8.96726
2380.77	9.73233
2383.58	9.08715
2386.38	8.7079
2389.19	9.19646
2391.99	9.71293
2394.8	9.96754
2397.6	10.0062
2400.4	10.4336
2403.2	10.1959
2406	10.5412
2408.79	10.3217
2411.59	10.9099
2414.39	11.5045
2417.18	11.5006
2419.98	11.7637
2422.77	12.3388
2425.56	12.6337
2428.35	12.9192
2431.14	13.3325
2433.93	12.9994
2436.72	11.7819
2439.5	12.463
2442.29	11.7515
2445.07	10.1487
2447.86	9.1357
2450.64	8.93277
2453.42	8.75661
2456.2	8.51914
2458.98	8.05879
2461.76	7.07008
2464.54	5.54041
2467.32	5.01976
2470.09	5.16204
2472.87	4.51932
2475.64	4.11221
2478.41	3.74502
2481.18	3.86013
2483.95	3.52202
2486.72	3.74692
2489.49	3.77548
2492.26	3.37525
2495.03	2.90914
2497.79	1.75548
2500.56	1.2927
2503.32	0.0447461
2506.09	0.513391
2508.85	1.03865
2511.61	0.0434733
2514.37	0.130652
2517.13	0.661739
2519.89	1.97327
2522.64	1.76317
2525.4	0.873858
2528.15	0.400261
2530.91	0.503949
2533.66	0.461379
2536.41	1.93833
2539.16	1.7035
2541.91	1.90424
2544.66	2.24626
2547.41	2.93125
2550.16	2.85002
2552.9	3.12161
2555.65	3.58191
2558.39	3.26003
2561.13	2.10226
2563.88	1.52321
2566.62	1.09899
2569.36	0.673043
2572.1	1.06805
2574.84	1.72054
2577.57	1.77554
2580.31	0.658502
2583.05	1.58228
2585.78	1.95977
2588.51	1.66103
2591.24	0.487158
2593.98	0.36122
2596.71	0.552601
2599.44	0.230607
2602.16	0.826816
2604.89	0.983587
2607.62	0.924242
2610.34	0.819527
2613.07	1.55195
2615.79	1.36005
2618.52	0.290821
2621.24	0.745939
2623.96	0.953165
2626.68	0.304496
2629.4	0.5158
2632.11	0.897747
2634.83	1.47845
2637.55	2.4168
2640.26	3.0879
2642.98	3.48925
2645.69	3.96237
2648.4	4.11891
2651.11	4.81388
2653.82	3.9364
2656.53	3.12281
2659.24	2.53523
2661.95	2.8213
2664.65	2.62942
2667.36	2.93587
2670.06	2.81685
2672.76	2.80428
2675.47	2.91154
2678.17	1.90829
2680.87	1.05619
2683.57	0.942174
2686.27	1.47238
2688.97	1.39073
2691.66	1.45094
2694.36	1.52403
2697.05	2.76653
2699.75	2.48817
2702.44	3.04756
2705.13	4.4618
2707.82	4.96761
2710.51	5.7245
2713.2	6.64221
2715.89	6.53143
2718.57	6.74
2721.26	7.03934
2723.95	7.67394
2726.63	8.54973
2729.31	9.02196
2732	9.95051
2734.68	10.0577
2737.36	9.91254
2740.04	9.56006
2742.72	9.78038
2745.39	9.60164
2748.07	9.6662
2750.75	8.7341
2753.42	8.31137
2756.09	6.60748
2758.77	5.31556
2761.44	4.90943
2764.11	5.41204
2766.78	4.84645
2769.45	5.65371
2772.12	5.39806
2774.78	5.1035
2777.45	4.84239
2780.12	4.11553
2782.78	4.47026
2785.44	4.93011
2788.11	4.72636
2790.77	4.72722
2793.43	4.61427
2796.09	4.39886
2798.75	4.4285
2801.4	4.55018
2804.06	4.55529
2806.72	4.844
2809.37	5.21879
2812.03	4.47166
2814.68	4.78808
2817.33	5.41694
2819.98	6.89597
2822.63	9.40168
2825.28	13.9277
2827.93	18.6814
2830.58	23.808
2833.23	27.9022
2835.87	32.9743
2838.52	38.9373
2841.16	45.8992
2843.8	52.4679
2846.44	61.0977
2849.08	70.7699
2851.73	80.645
2854.36	91.2463
2857	101.024
2859.64	111.707
2862.28	122.557
2864.91	131.96
2867.55	139.812
2870.18	148.067
2872.81	155.271
2875.44	161.014
2878.07	166.528
2880.7	173.304
2883.33	178.855
2885.96	184.088
2888.59	189.24
2891.21	193.884
2893.84	197.192
2896.46	202.059
2899.09	208.2
2901.71	215.278
2904.33	224.904
2906.95	235.367
2909.57	246.754
2912.19	260.618
2914.81	273.684
2917.43	286.732
2920.04	297.827
2922.66	307.707
2925.27	317.098
2927.88	321.755
2930.5	325.182
2933.11	326.623
2935.72	326.266
2938.33	322.061
2940.94	317.291
2943.54	311.363
2946.15	302.157
2948.76	292.744
2951.36	281.152
2953.97	269.244
2956.57	257.909
2959.17	245.846
2961.77	233.642
2964.37	221.737
2966.97	211.879
2969.57	202.2
2972.17	191.631
2974.77	182.605
2977.36	173.217
2979.96	162.971
2982.55	152.998
2985.15	141.139
2987.74	131.013
2990.33	119.62
2992.92	108.652
2995.51	98.4945
2998.1	89.2464
3000.69	79.3487
3003.27	70.2899
3005.86	62.0604
3008.44	55.0406
3011.03	48.9076
3013.61	43.7914
3016.19	39.9515
3018.78	37.6244
3021.36	32.9783
3023.94	29.3396
3026.51	27.1395
3029.09	26.6911
3031.67	26.7201
3034.24	27.1597
3036.82	27.9001
3039.39	29.2698
3041.97	31.4559
3044.54	33.0185
3047.11	34.1259
3049.68	34.0449
3052.25	35.2537
3054.82	35.6951
3057.39	34.7323
3059.96	34.5907
3062.52	32.7002
3065.09	31.4114
3067.65	30.2917
3070.22	28.661
3072.78	25.8192
3075.34	23.1261
3077.9	20.3137
3080.46	16.8722
3083.02	13.3704
3085.58	10.6123
3088.14	8.01549
3090.69	6.59547
3093.25	5.13613
3095.8	3.60027
3098.36	2.70704
3100.91	2.01109
3103.46	1.77135
3106.01	2.1576
3108.56	1.25035
3111.11	0.988634
3113.66	1.01103
3116.21	1.10296
3118.76	1.40931
3121.3	1.8636
3123.85	2.32729
3126.39	2.96572
3128.93	3.46882
3131.48	3.32009
3134.02	1.75224
3136.56	0.62459
3139.1	1.11584
3141.64	0.599716
3144.17	0.0514321
3146.71	-0.77457
3149.25	-0.793661