File: data/Raman/poly_smoothed/Thy_10_08_02_1x_45s_532 nm_x100_100%_600 gr_mm_01.txt
#Acq. time (s)=	45
#Accumulations=	2
#Range (cm-¹)=	200...3150
#Windows=	2
#Auto scanning=	Off
#Autofocus=	Off
#Macrospot=	Off
#AutoExposure=	Off
#Spike filter=	Multiple accum.
#Delay time (s)=	0
#Binning=	1
#Readout mode=	Signal
#DeNoise=	Off
#ICS correction=	On
#Dark correction=	Off
#Inst. Process=	Off
#Detector Gain=	Best Dynamic Range
#Detector ADC=	20 kHz
#Detector temperature (°C)=	-69.85
#Instrument=	LabRAM HR Evol
#Detector=	Synapse
#Objective=	x100
#Grating=	600 gr/mm
#ND Filter=	100%
#Laser (nm)=	532
#Hole=	100.021
#Range=	Auto
#Laser Pol.=	No
#Raman. Pol.=	No
#Laser Pol. (°)=	-0.0007625
#Raman Pol. (°)=	89.9995
#Collection=	Microscope
#StageXY=	Marzhauser
#StageZ=	Marzhauser
#X (µm)=	2158.1
#Y (µm)=	1213.9
#Z (µm)=	442.8
#Full time(mm:ss)=	3:18
#Project=
#Sample=
#Site=
#Title=	Thy_10_08_02_2x_45s_532 nm_x100_100%_600 gr_mm
#Remark=
#Date=	05.07.2022 14:19
#Acquired=	05.07.2022 14:19:03
#Base:Fit=	10.08.2022 09:45:33
#Base:Fit=	10.08.2022 09:46:03
#Base:Fit=	10.08.2022 09:46:25
#Base:Sub=	10.08.2022 09:46:49
#Filter:Polynom=	16.08.2022 10:24:56
#AxisType[0]=Intens
#AxisUnit[0]=Cnt
#AxisType[1]=Spectr
#AxisUnit[1]=1/cm
200.43	4.50107
204.059	4.52247
207.688	3.58187
211.314	3.68237
214.941	4.67383
218.564	5.95751
222.186	8.16728
225.809	9.78261
229.428	9.93087
233.045	9.86731
236.663	10.4352
240.278	10.6404
243.891	11.8308
247.503	12.3357
251.116	13.1512
254.725	13.7942
258.333	14.7162
261.939	15.7619
265.544	16.7792
269.148	16.9875
272.75	16.3974
276.351	15.8117
279.95	15.7943
283.548	15.2764
287.144	14.0743
290.739	13.5756
294.333	15.3364
297.925	17.3507
301.514	17.4161
305.104	17.3212
308.692	18.4925
312.279	19.3742
315.862	20.2083
319.446	20.0744
323.029	19.9865
326.608	20.2896
330.188	21.0145
333.766	21.4303
337.341	22.1192
340.917	20.368
344.489	19.7949
348.062	18.6204
351.631	18.2836
355.201	17.6354
358.768	15.7699
362.333	14.6329
365.899	13.9189
369.462	12.9245
373.023	10.7849
376.585	9.51371
380.143	10.2769
383.7	10.9335
387.256	10.136
390.812	9.74215
394.365	9.86244
397.916	11.2093
401.467	11.4881
405.015	10.7897
408.563	10.3074
412.109	8.91846
415.654	8.95054
419.197	9.27181
422.739	9.64847
426.279	8.30489
429.819	6.76175
433.356	6.69221
436.891	7.16039
440.426	6.26512
443.96	5.58321
447.492	4.03305
451.021	4.61094
454.551	4.68664
458.079	3.99458
461.604	4.42291
465.13	5.76443
468.654	7.5683
472.175	7.07193
475.696	7.79241
479.215	8.32253
482.733	8.8119
486.249	10.9619
489.765	12.1544
493.278	13.7362
496.789	15.807
500.301	17.3014
503.81	20.4128
507.317	20.507
510.825	20.4167
514.33	19.1445
517.833	18.6504
521.335	19.5052
524.836	20.3792
528.335	19.7241
531.835	18.7034
535.332	19.8668
538.827	20.0333
542.321	19.1681
545.814	18.4066
549.305	17.0101
552.795	16.8054
556.282	16.0752
559.769	16.1945
563.255	14.1454
566.739	12.5394
570.223	12.6005
573.705	13.2486
577.183	11.6654
580.663	10.4806
584.141	10.5121
587.615	8.54337
591.09	7.57599
594.564	5.89772
598.035	6.298
601.506	5.67257
604.974	5.28729
608.443	7.54584
611.908	7.14884
615.374	6.0549
618.837	6.03123
622.3	7.7556
625.761	7.5535
629.219	8.22441
632.677	9.28276
636.135	10.7618
639.59	12.1799
643.043	11.8004
646.495	11.2887
649.948	12.1127
653.398	13.613
656.846	15.0154
660.293	15.893
663.738	16.995
667.183	18.6386
670.626	20.345
674.067	21.4225
677.508	24.2134
680.947	26.0433
684.385	26.3786
687.821	28.3185
691.254	30.0183
694.688	32.0393
698.121	32.2783
701.552	32.5374
704.98	33.9684
708.409	36.3355
711.836	36.9392
715.26	38.095
718.685	39.3655
722.108	40.2576
725.528	41.5492
728.949	41.8261
732.367	44.2119
735.785	46.3808
739.2	48.4463
742.614	49.2454
746.028	51.5214
749.439	50.872
752.849	53.4174
756.26	55.7092
759.667	57.7937
763.073	60.2156
766.477	61.9608
769.883	64.677
773.285	67.4276
776.686	70.5246
780.085	71.981
783.484	73.857
786.881	75.4131
790.276	77.5652
793.671	79.2757
797.064	81.5008
800.456	83.0009
803.846	84.3779
807.234	85.1022
810.622	85.3337
814.008	84.9081
817.394	86.4414
820.778	85.3989
824.159	85.8554
827.541	83.2878
830.921	82.2139
834.298	81.3951
837.676	80.816
841.051	79.2806
844.426	77.4305
847.798	73.8131
851.171	70.9819
854.54	68.6092
857.911	66.1842
861.278	64.11
864.645	60.4285
868.01	58.7066
871.373	56.0532
874.735	54.0372
878.097	53.1044
881.457	51.1545
884.815	48.605
888.172	48.3102
891.528	47.35
894.882	47.0803
898.237	48.618
901.589	48.0588
904.94	47.8525
908.289	48.5907
911.635	48.5234
914.982	50.1406
918.328	50.7873
921.672	51.8878
925.015	52.0383
928.357	51.5958
931.698	50.8658
935.035	51.2726
938.373	52.8071
941.71	51.9707
945.044	51.218
948.378	51.0453
951.709	49.8177
955.041	48.5346
958.372	46.1881
961.699	43.8523
965.027	42.1023
968.352	41.7038
971.676	41.7505
975	40.5051
978.322	39.0491
981.642	37.8216
984.962	36.7287
988.28	35.9587
991.596	36.2914
994.911	35.3569
998.227	36.0668
1001.54	34.8254
1004.85	33.9514
1008.16	33.0878
1011.47	30.8861
1014.78	30.2053
1018.08	30.1271
1021.39	28.7799
1024.69	26.5784
1028	25.5566
1031.3	24.1376
1034.6	22.3951
1037.9	20.6273
1041.19	18.5092
1044.49	18.6986
1047.78	18.1031
1051.08	18.2674
1054.37	17.8153
1057.66	17.2465
1060.95	17.4912
1064.24	17.427
1067.53	18.7953
1070.81	18.496
1074.1	19.3118
1077.38	18.5053
1080.66	17.9495
1083.94	16.1379
1087.22	15.0764
1090.5	14.7522
1093.78	15.5734
1097.05	15.3692
1100.33	13.856
1103.6	12.5848
1106.87	12.0146
1110.14	11.7773
1113.41	10.7005
1116.68	9.085
1119.95	8.344
1123.21	7.31665
1126.48	7.33248
1129.74	7.19898
1133	8.57489
1136.26	8.76884
1139.52	9.70833
1142.78	9.50343
1146.04	10.2524
1149.29	10.4705
1152.55	10.5618
1155.8	10.0949
1159.05	8.28618
1162.3	7.66489
1165.55	7.23386
1168.8	8.17136
1172.05	8.11147
1175.29	7.25673
1178.54	6.79309
1181.78	7.15438
1185.02	7.75235
1188.26	8.6382
1191.5	8.69637
1194.74	8.19419
1197.97	7.55478
1201.21	8.32857
1204.44	9.42187
1207.68	11.7612
1210.91	12.367
1214.14	14.1534
1217.37	15.0713
1220.59	17.1933
1223.82	18.8937
1227.05	21.2853
1230.27	23.0538
1233.49	23.0132
1236.72	24.1938
1239.94	24.1366
1243.16	24.9509
1246.37	27.3734
1249.59	27.5913
1252.8	28.437
1256.02	30.3213
1259.23	31.2817
1262.44	30.77
1265.66	32.2205
1268.86	32.9187
1272.07	32.0055
1275.28	33.2661
1278.48	33.7625
1281.69	33.8454
1284.89	34.1019
1288.09	34.7159
1291.29	35.9725
1294.49	37.6988
1297.69	39.8565
1300.89	42.2899
1304.08	43.534
1307.28	44.7898
1310.47	44.0626
1313.66	46.3679
1316.85	45.7921
1320.04	46.4713
1323.23	46.3481
1326.42	45.9663
1329.61	45.0174
1332.79	44.9406
1335.97	44.3657
1339.16	44.3821
1342.34	44.6682
1345.52	44.2311
1348.7	43.6646
1351.87	42.228
1355.05	40.4151
1358.22	36.7897
1361.4	35.789
1364.57	33.5401
1367.74	33.2547
1370.91	30.0665
1374.08	28.979
1377.25	28.2985
1380.41	25.9607
1383.58	23.6584
1386.74	22.3977
1389.91	20.7701
1393.07	20.3647
1396.23	20.2004
1399.39	20.6158
1402.55	20.4767
1405.7	21.6278
1408.86	23.2901
1412.01	25.6781
1415.17	28.044
1418.32	32.0664
1421.47	35.9592
1424.62	39.393
1427.77	42.9639
1430.91	45.4654
1434.06	49.9403
1437.2	52.4534
1440.35	53.6474
1443.49	54.3999
1446.63	54.6715
1449.77	55.1226
1452.91	54.7993
1456.05	53.2489
1459.18	50.7504
1462.32	47.322
1465.45	43.8342
1468.59	39.1768
1471.72	35.6819
1474.85	31.1306
1477.98	27.0124
1481.1	22.6758
1484.23	17.9118
1487.36	14.3454
1490.48	12.174
1493.61	9.76505
1496.73	9.01112
1499.85	7.54066
1502.97	6.50974
1506.09	7.07603
1509.2	5.99131
1512.32	4.82711
1515.43	3.94655
1518.55	5.28869
1521.66	7.16185
1524.77	9.75959
1527.88	11.8761
1530.99	12.5399
1534.1	13.3457
1537.21	14.0181
1540.31	14.6217
1543.42	16.1616
1546.52	17.0007
1549.62	19.1666
1552.72	20.9677
1555.82	22.1002
1558.92	23.2373
1562.02	24.7491
1565.11	26.724
1568.21	28.8551
1571.3	31.1575
1574.39	32.1568
1577.49	34.2666
1580.57	35.4351
1583.66	35.8056
1586.75	36.0251
1589.84	38.1026
1592.92	40.206
1596.01	41.3604
1599.09	42.3071
1602.17	42.1299
1605.25	39.9211
1608.33	38.2908
1611.41	35.7673
1614.49	34.169
1617.57	32.6603
1620.64	32.2194
1623.72	31.1294
1626.79	30.1369
1629.86	29.4867
1632.93	29.473
1636	29.4202
1639.07	30.5396
1642.13	31.5033
1645.2	34.0931
1648.26	36.0048
1651.33	37.4328
1654.39	38.1467
1657.45	39.0829
1660.51	39.5691
1663.57	39.0355
1666.63	38.2675
1669.68	37.3481
1672.74	37.3211
1675.79	35.088
1678.85	33.133
1681.9	30.4043
1684.95	27.6027
1688	24.9675
1691.05	22.8941
1694.09	19.3254
1697.14	16.1516
1700.18	13.3991
1703.23	9.97263
1706.27	7.56161
1709.31	5.79417
1712.35	5.82563
1715.39	6.0452
1718.43	5.72812
1721.47	5.63138
1724.5	5.67142
1727.54	5.61171
1730.57	5.37225
1733.61	4.44957
1736.64	4.08996
1739.67	4.53935
1742.7	4.26507
1745.72	5.80674
1748.75	6.21262
1751.77	5.24127
1754.8	4.19868
1757.82	4.06511
1760.84	3.15771
1763.87	1.71883
1766.89	0.30922
1769.91	-0.776843
1772.92	-0.951502
1775.94	-1.84211
1778.95	-1.61223
1781.97	-0.528821
1784.98	0.674835
1787.99	1.57107
1791.01	1.69836
1794.01	2.17743
1797.02	3.18108
1800.03	3.15577
1803.04	3.8101
1806.04	3.30738
1809.05	4.69258
1812.05	5.03215
1815.05	5.47961
1818.05	5.6407
1821.05	5.07776
1824.05	4.72897
1827.05	4.08327
1830.04	4.05391
1833.04	2.80043
1836.03	2.29024
1839.03	2.15505
1842.02	1.9671
1845.01	2.08327
1848	2.42554
1850.99	2.51447
1853.97	2.8537
1856.96	2.51855
1859.94	2.26721
1862.93	1.86863
1865.91	1.68638
1868.89	2.71324
1871.87	2.47541
1874.85	3.34295
1877.83	4.20052
1880.81	5.56176
1882.57	6.23255
1885.56	7.55997
1888.55	7.92301
1891.54	8.98951
1894.52	9.70478
1897.51	10.5182
1900.49	10.7313
1903.47	10.2189
1906.45	11.1709
1909.43	12.0968
1912.41	12.2665
1915.39	12.1047
1918.37	12.4228
1921.34	11.9995
1924.32	11.0614
1927.29	10.479
1930.26	9.46682
1933.23	9.26925
1936.2	8.55207
1939.17	7.00957
1942.14	6.39445
1945.11	5.78198
1948.07	6.20112
1951.04	5.91841
1954	7.44839
1956.96	6.58671
1959.93	4.69678
1962.89	4.39242
1965.85	4.79669
1968.8	4.70297
1971.76	3.91086
1974.72	2.95922
1977.67	3.522
1980.63	3.7698
1983.58	4.36672
1986.53	3.89596
1989.48	4.01257
1992.43	4.82234
1995.38	4.37097
1998.32	5.1386
2001.27	5.41815
2004.22	5.15999
2007.16	5.25296
2010.1	5.49932
2013.04	5.6188
2015.98	5.62275
2018.92	6.89394
2021.86	7.88091
2024.8	7.93801
2027.74	7.21178
2030.67	6.88558
2033.61	6.77118
2036.54	7.02244
2039.47	6.405
2042.4	6.55285
2045.33	6.11833
2048.26	6.37682
2051.19	8.18565
2054.12	9.26362
2057.04	9.81325
2059.97	10.7062
2062.89	11.3334
2065.81	12.5537
2068.73	13.6181
2071.65	14.0021
2074.57	14.0742
2077.49	14.4939
2080.41	14.1715
2083.32	13.3646
2086.24	12.4554
2089.15	12.1037
2092.07	11.268
2094.98	10.6783
2097.89	10.1
2100.8	9.88269
2103.71	8.96645
2106.61	8.11431
2109.52	7.8663
2112.43	8.57793
2115.33	8.33325
2118.23	8.03509
2121.13	10.3934
2124.04	11.6721
2126.94	11.5139
2129.83	12.6531
2132.73	12.6699
2135.63	14.0532
2138.53	14.7249
2141.42	15.1608
2144.31	15.5347
2147.21	16.1593
2150.1	15.5095
2152.99	14.6336
2155.88	14.8031
2158.77	15.1433
2161.65	14.8324
2164.54	16.138
2167.43	16.6422
2170.31	16.3735
2173.19	16.5698
2176.07	17.441
2178.96	17.5406
2181.84	17.9455
2184.72	18.6983
2187.59	17.8083
2190.47	18.0758
2193.35	18.7247
2196.22	19.021
2199.09	18.6309
2201.97	18.6466
2204.84	19.523
2207.71	18.9925
2210.58	18.1915
2213.45	18.2533
2216.31	17.9147
2219.18	16.4458
2222.05	15.8163
2224.91	14.7002
2227.78	13.4549
2230.64	13.4467
2233.5	13.1015
2236.36	13.5525
2239.22	13.0025
2242.08	12.493
2244.93	12.1946
2247.79	12.0297
2250.64	11.3089
2253.5	10.2834
2256.35	10.008
2259.2	9.27559
2262.05	9.7254
2264.9	10.3885
2267.75	10.389
2270.6	9.94257
2273.45	9.68567
2276.29	10.1006
2279.14	8.36392
2281.98	7.8182
2284.82	8.20187
2287.66	7.05929
2290.5	6.53343
2293.34	5.68565
2296.18	6.43067
2299.02	7.66431
2301.86	9.49085
2304.69	10.3547
2307.53	10.7524
2310.36	10.9065
2313.19	10.3536
2316.02	9.87292
2318.85	10.0469
2321.68	9.5738
2324.51	9.55993
2327.34	10.171
2330.16	10.309
2332.99	10.3969
2335.81	9.81635
2338.64	9.08545
2341.46	7.8134
2344.28	7.75174
2347.1	6.2942
2349.92	5.35671
2352.74	5.68723
2355.55	4.01575
2358.37	2.82856
2361.19	2.46283
2364	3.37946
2366.81	4.09501
2369.62	2.9926
2372.44	2.83238
2375.24	2.26978
2378.05	0.820099
2380.86	0.802335
2383.67	0.161764
2386.47	1.08824
2389.28	1.06554
2392.08	1.15385
2394.89	1.55941
2397.69	2.52058
2400.49	2.28218
2403.29	2.22143
2406.09	3.48855
2408.88	3.71166
2411.68	4.78562
2414.48	5.61722
2417.27	5.96458
2420.06	6.25142
2422.86	5.83191
2425.65	5.54424
2428.44	5.7249
2431.23	5.83124
2434.02	5.95796
2436.81	5.32427
2439.59	3.86605
2442.38	4.36805
2445.16	4.38041
2447.95	3.29683
2450.73	3.39068
2453.51	2.82503
2456.29	2.32977
2459.07	2.06494
2461.85	2.33114
2464.63	1.76927
2467.4	1.66103
2470.18	1.97612
2472.95	2.10183
2475.73	2.0143
2478.5	1.63509
2481.27	1.94746
2484.04	1.30169
2486.81	0.715516
2489.58	-0.0379849
2492.35	-0.337225
2495.12	-0.944122
2497.88	-1.37407
2500.65	-0.993207
2503.41	-1.86704
2506.17	-1.44179
2508.94	-1.3296
2511.7	-0.888552
2514.46	-1.75125
2517.22	-0.786113
2519.97	-0.658639
2522.73	-0.31135
2525.49	0.414746
2528.24	1.37364
2530.99	1.27683
2533.75	1.89018
2536.5	2.40221
2539.25	1.97799
2542	2.32416
2544.75	2.12696
2547.5	1.52345
2550.24	2.59694
2552.99	2.21463
2555.74	1.46155
2558.48	1.66713
2561.22	1.26902
2563.96	1.49596
2566.71	1.88481
2569.45	2.62675
2572.18	2.88891
2574.92	3.22535
2577.66	3.58809
2580.4	3.48346
2583.13	4.35003
2585.87	4.07764
2588.6	3.79794
2591.33	3.7917
2594.06	4.19734
2596.79	4.89189
2599.52	3.79869
2602.25	3.97832
2604.98	3.14495
2607.71	3.08322
2610.43	3.16284
2613.16	2.32718
2615.88	2.55207
2618.6	2.1704
2621.32	2.46899
2624.04	2.06968
2626.76	2.22563
2629.48	1.78923
2632.2	3.05098
2634.92	3.11813
2637.63	2.8986
2640.35	3.58557
2643.06	3.93617
2645.77	3.85919
2648.49	3.65762
2651.2	2.53195
2653.91	2.10566
2656.62	2.92668
2659.33	2.84567
2662.03	3.54255
2664.74	3.94215
2667.44	3.25527
2670.15	2.60427
2672.85	1.52162
2675.55	1.18091
2678.26	0.462103
2680.96	0.667855
2683.66	0.675933
2686.35	0.459555
2689.05	0.485829
2691.75	1.78521
2694.44	2.29573
2697.14	3.12565
2699.83	4.45905
2702.52	5.19561
2705.22	6.58895
2707.91	7.13365
2710.6	7.26173
2713.29	7.91235
2715.97	8.50519
2718.66	9.51442
2721.35	10.7078
2724.03	11.4048
2726.72	11.7525
2729.4	11.7385
2732.08	11.282
2734.76	10.737
2737.44	10.2675
2740.12	9.30083
2742.8	9.1328
2745.48	9.52565
2748.16	9.46766
2750.83	9.40464
2753.51	8.84363
2756.18	8.93494
2758.85	9.79302
2761.53	8.87128
2764.2	9.06898
2766.87	8.46099
2769.54	7.88959
2772.2	7.35522
2774.87	6.19439
2777.54	6.27432
2780.2	6.71593
2782.87	6.08847
2785.53	6.33323
2788.19	6.06174
2790.85	6.26181
2793.51	5.94706
2796.17	5.43729
2798.83	5.87482
2801.49	5.35342
2804.15	4.83254
2806.8	4.71551
2809.46	5.27922
2812.11	5.93734
2814.76	6.36128
2817.42	6.45157
2820.07	7.75039
2822.72	9.03684
2825.37	11.2556
2828.02	13.1123
2830.66	16.4576
2833.31	19.3063
2835.96	22.3879
2838.6	25.8563
2841.24	30.1048
2843.89	35.1775
2846.53	40.4891
2849.17	46.1685
2851.81	52.4172
2854.45	58.6277
2857.09	65.1057
2859.72	70.5399
2862.36	75.6527
2865	80.6853
2867.63	85.2265
2870.26	88.264
2872.9	91.0467
2875.53	93.8016
2878.16	96.1782
2880.79	97.7272
2883.42	100.54
2886.05	102.406
2888.67	103.73
2891.3	106.026
2893.92	107.784
2896.55	110.062
2899.17	111.589
2901.79	114.419
2904.42	117.478
2907.04	121.868
2909.66	127.676
2912.27	133.718
2914.89	139.452
2917.51	145.16
2920.13	149.974
2922.74	154.084
2925.35	156.329
2927.97	157.389
2930.58	158.639
2933.19	156.829
2935.8	155.332
2938.41	152.915
2941.02	149.221
2943.63	145.441
2946.24	141.168
2948.84	136.41
2951.45	132.306
2954.05	125.862
2956.65	120.416
2959.26	115.906
2961.86	111.005
2964.46	106.359
2967.06	102.585
2969.66	99.182
2972.25	96.3082
2974.85	93.1505
2977.45	88.802
2980.04	84.6822
2982.64	80.8447
2985.23	76.5337
2987.82	71.2879
2990.41	65.6717
2993	59.8612
2995.59	55.451
2998.18	50.0586
3000.77	44.6477
3003.36	39.3837
3005.94	36.0873
3008.53	32.0358
3011.11	28.7614
3013.69	25.5585
3016.28	22.2233
3018.86	20.576
3021.44	19.988
3024.02	18.835
3026.6	17.9863
3029.18	17.5249
3031.75	17.9797
3034.33	18.5127
3036.9	18.5312
3039.48	19.3635
3042.05	20.1638
3044.62	20.9785
3047.19	21.862
3049.77	22.7885
3052.34	23.1397
3054.9	23.2199
3057.47	23.2831
3060.04	22.9375
3062.61	21.6329
3065.17	20.1331
3067.74	19.3933
3070.3	17.7376
3072.86	15.5266
3075.42	13.7904
3077.99	12.4004
3080.54	12.2033
3083.1	10.6499
3085.66	9.33794
3088.22	7.80133
3090.78	6.92111
3093.33	6.37451
3095.89	5.34981
3098.44	4.00473
3100.99	3.69759
3103.54	3.80717
3106.1	4.20737
3108.65	4.61162
3111.2	4.96382
3113.74	5.04981
3116.29	4.95671
3118.84	5.35398
3121.38	4.66682
3123.93	4.07774
3126.47	2.92998
3129.01	1.96378
3131.56	1.98323
3134.1	1.55231
3136.64	0.661463
3139.18	0.184216
3141.72	-0.619285
3144.26	-2.29331
3146.79	-4.44473
3149.33	-7.42776