File: data/Raman/poly_smoothed/Thy_30_10_37_1x_45s_532 nm_x100_100%_600 gr_mm_01.txt
#Acq. time (s)=	45
#Accumulations=	2
#Range (cm-¹)=	200...3150
#Windows=	2
#Auto scanning=	Off
#Autofocus=	Off
#Macrospot=	Off
#AutoExposure=	Off
#Spike filter=	Multiple accum.
#Delay time (s)=	0
#Binning=	1
#Readout mode=	Signal
#DeNoise=	Off
#ICS correction=	On
#Dark correction=	Off
#Inst. Process=	Off
#Detector Gain=	Best Dynamic Range
#Detector ADC=	20 kHz
#Detector temperature (°C)=	-69.85
#Instrument=	LabRAM HR Evol
#Detector=	Synapse
#Objective=	x100
#Grating=	600 gr/mm
#ND Filter=	100%
#Laser (nm)=	532
#Hole=	100.021
#Range=	Auto
#Laser Pol.=	No
#Raman. Pol.=	No
#Laser Pol. (°)=	-0.0007625
#Raman Pol. (°)=	89.9995
#Collection=	Microscope
#StageXY=	Marzhauser
#StageZ=	Marzhauser
#X (µm)=	4732.8
#Y (µm)=	-7720.3
#Z (µm)=	584.8
#Full time(mm:ss)=	3:18
#Project=
#Sample=
#Site=
#Title=	Thy_30_10_37_2x_45s_532 nm_x100_100%_600 gr_mm
#Remark=
#Date=	30.06.2022 14:06
#Acquired=	30.06.2022 14:06:23
#Base:Fit=	10.08.2022 09:58:11
#Base:Sub=	10.08.2022 09:58:44
#Filter:Polynom=	16.08.2022 10:22:53
#AxisType[0]=Intens
#AxisUnit[0]=Cnt
#AxisType[1]=Spectr
#AxisUnit[1]=1/cm
200.533	0.365339
204.162	2.79569
207.792	1.98179
211.418	2.23505
215.044	2.70668
218.667	4.45237
222.289	6.89954
225.912	9.75957
229.531	10.9808
233.148	12.0186
236.766	12.8002
240.381	12.7549
243.994	14.8745
247.606	16.4291
251.217	17.076
254.828	19.326
258.436	19.6468
262.042	20.9668
265.647	22.9283
269.25	22.3927
272.852	22.8797
276.453	23.1728
280.052	23.4378
283.65	22.5731
287.247	22.8394
290.842	22.5699
294.436	22.0502
298.028	22.2495
301.617	21.4631
305.206	21.9057
308.794	22.0294
312.381	21.9081
315.964	22.289
319.548	21.7636
323.131	21.232
326.71	20.5649
330.29	21.5256
333.868	22.8671
337.443	22.8176
341.018	24.5594
344.591	25.8044
348.163	24.9616
351.733	25.326
355.303	23.7728
358.869	23.0599
362.435	23.5238
366.001	22.7377
369.563	21.7791
373.124	21.7193
376.686	22.1858
380.244	21.4332
383.801	20.0989
387.357	19.7442
390.911	19.8593
394.466	19.2247
398.018	19.4528
401.568	19.7087
405.117	19.2875
408.664	17.9222
412.21	17.3882
415.755	17.964
419.298	18.3701
422.84	18.9411
426.38	19.533
429.919	20.3458
433.455	19.3838
436.992	18.4544
440.527	18.2327
444.06	16.8813
447.593	16.9788
451.122	16.804
454.651	17.0404
458.18	17.0907
461.705	17.9061
465.23	17.8465
468.752	18.9618
472.275	18.9015
475.797	20.274
479.315	21.2045
482.834	22.0954
486.349	22.3999
489.863	22.8367
493.378	22.3082
496.889	23.1554
500.401	23.7276
503.91	23.5024
507.417	22.8298
510.923	21.8694
514.43	21.7017
517.933	21.411
521.435	21.454
524.936	19.0886
528.435	17.9508
531.933	15.3927
535.43	14.417
538.927	13.8951
542.421	13.3359
545.913	12.2162
549.403	11.9721
552.893	11.7639
556.381	12.5239
559.868	12.5194
563.354	13.759
566.839	13.6642
570.322	12.9211
573.802	12.5744
577.283	11.3291
580.762	11.735
584.24	10.6238
587.714	9.13532
591.19	8.62891
594.663	8.00346
598.134	7.78111
601.605	7.61616
605.073	8.73875
608.542	8.50427
612.007	8.1596
615.473	8.75945
618.936	8.70408
622.397	10.5969
625.859	13.2271
629.318	14.0321
632.775	14.2194
636.233	15.6819
639.688	16.5256
643.142	16.6842
646.594	18.2287
650.045	18.0016
653.496	17.0767
656.944	17.6767
660.391	18.9333
663.837	19.671
667.281	20.4103
670.724	21.1369
674.166	22.5212
677.606	23.8734
681.045	25.0881
684.483	26.8094
687.917	28.3554
691.352	29.8094
694.786	31.6561
698.219	33.1956
701.65	34.1894
705.078	34.3058
708.506	35.932
711.934	37.173
715.358	37.59
718.782	38.2917
722.204	38.5421
725.626	38.0228
729.045	39.5984
732.464	41.3939
735.881	41.3302
739.297	42.345
742.711	44.2777
746.125	46.177
749.537	48.8517
752.946	50.8977
756.357	54.2574
759.764	57.075
763.17	59.1667
766.575	61.8638
769.978	63.5502
773.382	64.727
776.783	66.4281
780.182	66.9841
783.581	67.8867
786.978	68.871
790.373	69.9674
793.768	70.6136
797.161	71.7191
800.552	71.7151
803.941	72.6597
807.33	72.316
810.718	72.1366
814.105	72.5751
817.49	71.2366
820.873	71.0748
824.256	71.1199
827.637	70.1314
831.016	70.516
834.395	71.4361
837.772	70.93
841.147	70.8433
844.522	69.8234
847.894	67.934
851.267	65.2652
854.637	63.4365
858.007	61.824
861.374	59.4402
864.739	56.5134
868.106	54.9524
871.469	52.575
874.831	49.0129
878.193	47.6592
881.553	46.7241
884.911	46.0844
888.268	45.8027
891.623	43.6752
894.978	43.8577
898.331	42.8363
901.683	42.8579
905.033	41.5137
908.383	41.0902
911.731	40.5109
915.078	42.1306
918.423	41.9427
921.768	42.1263
925.111	41.5156
928.452	41.0963
931.791	39.8723
935.13	38.8552
938.468	37.0575
941.803	34.5643
945.139	32.0919
948.473	30.5658
951.804	29.6127
955.136	28.7524
958.465	27.3007
961.794	27.2047
965.12	27.3322
968.447	26.0793
971.771	24.7701
975.095	23.2325
978.417	21.8543
981.737	21.1568
985.057	19.1573
988.375	18.4503
991.691	19.1913
995.006	19.3031
998.32	18.0999
1001.63	17.8094
1004.95	16.7988
1008.26	16.4091
1011.56	15.9681
1014.87	15.01
1018.18	14.8042
1021.48	14.2898
1024.79	13.5586
1028.09	14.2086
1031.39	13.8846
1034.69	13.8296
1037.99	13.3314
1041.29	12.1782
1044.58	12.7928
1047.88	11.3206
1051.17	10.3478
1054.46	9.39338
1057.75	9.58283
1061.04	9.44557
1064.33	8.87171
1067.62	9.08125
1070.9	8.06128
1074.19	7.80101
1077.47	7.36775
1080.76	7.48248
1084.04	7.22598
1087.32	6.33024
1090.59	6.58265
1093.87	7.38057
1097.15	6.50006
1100.42	7.44369
1103.69	6.85302
1106.97	6.48172
1110.24	6.04161
1113.51	4.94164
1116.77	5.80604
1120.04	5.02462
1123.31	5.309
1126.57	4.97349
1129.83	4.50895
1133.1	4.44573
1136.36	4.9048
1139.62	4.26503
1142.87	3.46281
1146.13	2.35872
1149.38	1.79352
1152.64	1.38473
1155.89	2.74379
1159.14	2.61087
1162.39	2.1332
1165.64	1.13652
1168.89	1.0563
1172.14	2.23166
1175.38	2.42035
1178.63	1.01509
1181.87	0.389652
1185.11	0.530335
1188.35	1.08962
1191.59	0.811932
1194.83	1.66612
1198.07	1.92657
1201.3	2.11166
1204.53	3.27257
1207.77	3.57441
1211	4.25066
1214.23	5.37449
1217.46	5.33252
1220.69	4.466
1223.91	6.48336
1227.14	8.66887
1230.36	9.88853
1233.59	11.8451
1236.81	12.4037
1240.03	14.1011
1243.25	15.8938
1246.46	18.147
1249.68	19.4085
1252.9	19.5669
1256.11	19.8482
1259.32	21.9344
1262.54	23.9429
1265.75	25.9292
1268.96	26.6064
1272.16	27.0673
1275.37	28.1265
1278.57	28.9969
1281.78	28.6339
1284.98	29.1026
1288.18	29.5309
1291.38	29.8948
1294.58	29.8931
1297.78	30.1293
1300.98	31.6602
1304.17	32.9117
1307.37	33.1788
1310.56	33.0181
1313.76	33.4911
1316.95	34.1257
1320.14	35.4269
1323.32	35.5873
1326.51	35.3574
1329.7	34.5418
1332.88	34.0516
1336.07	34.4378
1339.25	34.1621
1342.43	32.3815
1345.61	31.093
1348.79	28.9458
1351.96	28.0358
1355.14	27.6894
1358.31	26.9051
1361.49	27.8016
1364.66	27.6034
1367.83	25.6929
1371	24.1299
1374.17	23.5665
1377.34	23.4367
1380.5	22.5706
1383.67	22.1465
1386.83	21.9971
1390	21.3817
1393.16	20.5003
1396.32	19.9615
1399.48	20.5233
1402.64	19.3041
1405.79	18.5278
1408.95	18.1944
1412.1	16.7422
1415.26	16.7814
1418.41	16.9796
1421.56	18.1049
1424.71	19.1995
1427.86	21.1517
1431	24.0642
1434.15	26.4419
1437.29	29.1848
1440.44	30.3183
1443.58	30.5161
1446.72	29.7237
1449.86	31.497
1453	31.8106
1456.14	31.1826
1459.27	29.9177
1462.41	28.8126
1465.54	26.8712
1468.67	25.2455
1471.81	22.9316
1474.94	20.1514
1478.07	18.745
1481.19	16.0378
1484.32	13.4716
1487.45	10.0715
1490.57	7.93147
1493.69	7.09647
1496.82	6.07588
1499.94	4.78897
1503.06	4.67105
1506.17	5.39795
1509.29	5.53914
1512.41	5.14706
1515.52	5.23616
1518.64	4.3482
1521.75	3.82468
1524.86	5.61978
1527.97	7.43223
1531.08	7.12081
1534.19	8.20142
1537.29	9.69948
1540.4	11.451
1543.5	13.329
1546.61	14.5476
1549.71	16.3202
1552.81	18.2525
1555.91	20.3464
1559.01	21.2951
1562.11	22.2372
1565.2	23.6446
1568.29	26.1988
1571.39	29.1996
1574.48	31.048
1577.57	33.1142
1580.66	33.6295
1583.75	33.7622
1586.84	32.8889
1589.93	32.178
1593.01	33.0272
1596.1	32.6408
1599.18	32.1072
1602.26	32.1261
1605.34	31.1078
1608.42	30.7794
1611.5	29.9095
1614.58	29.3844
1617.65	29.566
1620.73	28.8641
1623.8	28.4192
1626.87	28.2802
1629.95	28.1828
1633.02	28.789
1636.09	28.3378
1639.15	29.2484
1642.22	30.6582
1645.29	32.4896
1648.35	32.7594
1651.42	33.1771
1654.48	33.2673
1657.54	32.1252
1660.6	31.341
1663.66	31.1948
1666.72	31.2949
1669.77	30.1173
1672.83	27.9871
1675.88	27.2038
1678.93	25.5851
1681.99	24.4021
1685.04	23.4262
1688.09	21.4953
1691.13	19.9562
1694.18	18.4074
1697.23	15.3839
1700.27	13.954
1703.32	12.1276
1706.36	10.2348
1709.4	8.08986
1712.44	7.15943
1715.48	6.10657
1718.52	5.46466
1721.56	5.71055
1724.59	5.38777
1727.63	4.03343
1730.66	3.26305
1733.69	2.34881
1736.72	2.67489
1739.75	2.76805
1742.78	2.81444
1745.81	2.65031
1748.84	2.3879
1751.86	2.46146
1754.89	2.43852
1757.91	2.61795
1760.93	2.34542
1763.95	1.91972
1766.97	2.56939
1769.99	3.2288
1773.01	3.00899
1776.03	2.92306
1779.04	2.12048
1782.06	2.81996
1785.07	3.2098
1788.08	3.61503
1791.09	4.1267
1794.1	4.36471
1797.11	4.86244
1800.12	4.69348
1803.12	4.63257
1806.13	5.94604
1809.13	7.49104
1812.14	7.83773
1815.14	7.78793
1818.14	7.69032
1821.14	7.37319
1824.14	7.35351
1827.13	7.2877
1830.13	7.33799
1833.12	7.71062
1836.12	7.99639
1839.11	8.64486
1842.1	9.39042
1845.09	10.4563
1848.08	10.4862
1851.07	10.2452
1854.06	10.3437
1857.04	10.453
1860.03	9.57929
1863.01	8.65652
1866	7.90852
1868.98	7.76179
1871.96	7.16528
1874.94	6.65355
1877.92	6.29823
1880.89	6.41141
1882.48	5.71812
1885.47	4.9105
1888.46	3.96704
1891.44	3.42173
1894.43	3.413
1897.41	3.33457
1900.4	4.00287
1903.38	5.13084
1906.36	6.34041
1909.34	7.82122
1912.32	9.2268
1915.29	10.2547
1918.27	11.0179
1921.25	11.9957
1924.22	12.5384
1927.2	13.5661
1930.17	13.2243
1933.14	13.3896
1936.11	13.1882
1939.08	13.4777
1942.05	13.1618
1945.01	12.5219
1947.98	12.157
1950.94	11.757
1953.91	11.5013
1956.87	10.2823
1959.83	9.57191
1962.79	9.23897
1965.75	8.98817
1968.71	8.80496
1971.67	8.53596
1974.62	8.54558
1977.58	8.82833
1980.53	9.27996
1983.48	9.559
1986.43	9.83719
1989.38	11.0814
1992.33	11.6157
1995.28	12.6666
1998.23	12.937
2001.18	12.8926
2004.12	12.2753
2007.06	12.4514
2010.01	12.4892
2012.95	13.2452
2015.89	12.57
2018.83	12.9686
2021.77	12.6579
2024.71	13.1727
2027.64	13.01
2030.58	13.726
2033.51	14.1195
2036.45	13.9663
2039.38	13.7581
2042.31	13.7219
2045.24	13.6717
2048.17	14.6864
2051.1	15.0804
2054.02	14.8679
2056.95	15.2133
2059.87	15.0193
2062.8	15.1966
2065.72	15.5371
2068.64	15.4599
2071.56	15.111
2074.48	15.0533
2077.4	15.4639
2080.31	16.0743
2083.23	16.4175
2086.14	16.7503
2089.06	17.346
2091.97	18.7777
2094.88	18.9804
2097.79	19.8476
2100.7	19.4377
2103.61	19.7132
2106.52	19.4242
2109.43	19.857
2112.33	20.039
2115.24	20.2982
2118.14	20.7479
2121.04	21.3016
2123.94	21.6715
2126.84	22.7562
2129.74	23.9395
2132.64	25.2834
2135.54	26.6878
2138.43	27.4188
2141.33	28.8216
2144.22	30.5782
2147.11	32.2282
2150.01	33.6573
2152.9	35.4158
2155.79	37.7529
2158.67	39.046
2161.56	39.9047
2164.45	41.4255
2167.33	41.3642
2170.22	41.2321
2173.1	41.0816
2175.98	41.0728
2178.86	41.1711
2181.74	39.6885
2184.62	38.4775
2187.5	36.9114
2190.38	35.4774
2193.25	34.7657
2196.13	34.3105
2199	33.4721
2201.88	32.3096
2204.75	31.0667
2207.62	28.5433
2210.49	26.8786
2213.36	25.7288
2216.22	24.7446
2219.09	24.1886
2221.96	23.3139
2224.82	23.3328
2227.68	22.2053
2230.55	20.851
2233.41	20.5961
2236.27	20.9391
2239.12	20.5513
2241.98	19.4921
2244.84	19.1563
2247.7	18.9064
2250.55	18.3035
2253.41	17.1522
2256.26	16.046
2259.11	15.8402
2261.96	16.326
2264.81	16.3751
2267.66	15.7633
2270.51	14.9643
2273.35	14.4689
2276.2	13.0091
2279.04	12.1605
2281.89	11.6898
2284.73	11.6447
2287.57	11.8821
2290.41	11.0924
2293.25	10.5178
2296.09	11.0945
2298.93	11.5689
2301.76	12.068
2304.6	12.4269
2307.44	12.9758
2310.27	13.9752
2313.1	14.2261
2315.93	15.1664
2318.76	15.3358
2321.59	15.416
2324.42	14.1954
2327.25	13.9466
2330.07	13.9316
2332.9	13.5596
2335.72	13.5152
2338.55	12.9388
2341.37	12.4877
2344.19	11.0861
2347.01	9.39457
2349.83	9.03401
2352.65	7.97055
2355.46	7.7418
2358.28	7.07229
2361.09	6.73463
2363.91	6.80144
2366.72	6.80531
2369.53	6.29295
2372.34	6.05701
2375.15	5.68809
2377.96	6.43857
2380.77	6.92015
2383.58	7.35108
2386.38	6.72999
2389.19	6.43296
2391.99	7.06198
2394.8	7.04698
2397.6	7.32002
2400.4	7.24859
2403.2	7.56795
2406	7.78667
2408.79	8.09875
2411.59	8.03516
2414.39	7.87391
2417.18	7.6497
2419.98	7.54922
2422.77	7.54975
2425.56	7.96842
2428.35	8.66538
2431.14	8.53139
2433.93	8.95811
2436.72	9.10294
2439.5	8.74103
2442.29	8.35637
2445.07	7.94704
2447.86	8.4108
2450.64	8.28496
2453.42	7.69109
2456.2	7.818
2458.98	7.61082
2461.76	7.7476
2464.54	7.33672
2467.32	6.21504
2470.09	6.13097
2472.87	6.29076
2475.64	6.14432
2478.41	6.0406
2481.18	5.2515
2483.95	4.98675
2486.72	5.14071
2489.49	5.10406
2492.26	5.47304
2495.03	5.39596
2497.79	5.75397
2500.56	5.39402
2503.32	4.77522
2506.09	3.61889
2508.85	3.03777
2511.61	2.48908
2514.37	2.36882
2517.13	2.76112
2519.89	2.7767
2522.64	2.54336
2525.4	1.9921
2528.15	1.32826
2530.91	0.569011
2533.66	-0.330543
2536.41	-0.633374
2539.16	-1.2547
2541.91	-1.07421
2544.66	-1.30052
2547.41	-0.900523
2550.16	-0.907712
2552.9	-1.45555
2555.65	-0.735011
2558.39	-0.202317
2561.13	-0.331001
2563.88	-0.514441
2566.62	-0.805682
2569.36	-0.409261
2572.1	0.319694
2574.84	0.448945
2577.57	1.10049
2580.31	1.75764
2583.05	1.96848
2585.78	2.71877
2588.51	3.17273
2591.24	2.83969
2593.98	2.7754
2596.71	2.27467
2599.44	2.63859
2602.16	2.71318
2604.89	1.91888
2607.62	2.06604
2610.34	1.58861
2613.07	1.93941
2615.79	1.50679
2618.52	1.30079
2621.24	1.37673
2623.96	1.83706
2626.68	1.24254
2629.4	0.65801
2632.11	0.962456
2634.83	0.673805
2637.55	0.677479
2640.26	1.03329
2642.98	0.698674
2645.69	0.719646
2648.4	0.879533
2651.11	0.909437
2653.82	1.37694
2656.53	1.56335
2659.24	1.77499
2661.95	1.91764
2664.65	1.77804
2667.36	2.47007
2670.06	1.94521
2672.76	2.51417
2675.47	2.71075
2678.17	2.97964
2680.87	3.43208
2683.57	3.19845
2686.27	3.74844
2688.97	3.81982
2691.66	3.63136
2694.36	3.59743
2697.05	3.37876
2699.75	3.48693
2702.44	4.22041
2705.13	4.04629
2707.82	3.99547
2710.51	3.81671
2713.2	3.41015
2715.89	3.58421
2718.57	3.52209
2721.26	3.97947
2723.95	3.50426
2726.63	2.99895
2729.31	2.79064
2732	2.55441
2734.68	3.14477
2737.36	2.55579
2740.04	2.88146
2742.72	2.29518
2745.39	1.89198
2748.07	1.48764
2750.75	1.11393
2753.42	1.25945
2756.09	0.752451
2758.77	0.255655
2761.44	0.724289
2764.11	0.976167
2766.78	0.841125
2769.45	0.852172
2772.12	0.304973
2774.78	0.78892
2777.45	0.668106
2780.12	0.751941
2782.78	1.2424
2785.44	1.30755
2788.11	1.22238
2790.77	1.10068
2793.43	1.19825
2796.09	1.13717
2798.75	0.775456
2801.4	0.485793
2804.06	0.304107
2806.72	0.0213294
2809.37	-1.00284
2812.03	-1.27766
2814.68	-0.605383
2817.33	0.00863911
2819.98	-0.0376897
2822.63	0.0193332
2825.28	1.33243
2827.93	2.62045
2830.58	4.10264
2833.23	5.47322
2835.87	7.30144
2838.52	9.83884
2841.16	12.5821
2843.8	15.2779
2846.44	18.2044
2849.08	22.251
2851.73	24.7864
2854.36	27.7077
2857	30.7844
2859.64	33.6575
2862.28	36.3195
2864.91	37.6587
2867.55	39.99
2870.18	42.0223
2872.81	43.0203
2875.44	44.9648
2878.07	47.2073
2880.7	48.262
2883.33	49.2448
2885.96	49.7996
2888.59	50.9268
2891.21	52.662
2893.84	53.2676
2896.46	54.3847
2899.09	56.7671
2901.71	59.9229
2904.33	63.2383
2906.95	67.0646
2909.57	70.2592
2912.19	74.0581
2914.81	77.5992
2917.43	81.41
2920.04	85.3744
2922.66	87.7644
2925.27	90.1141
2927.88	91.4788
2930.5	92.4477
2933.11	93.4482
2935.72	92.8935
2938.33	93.1749
2940.94	91.6295
2943.54	90.1253
2946.15	87.5867
2948.76	84.7072
2951.36	81.8514
2953.97	79.6331
2956.57	76.2572
2959.17	73.4491
2961.77	70.9885
2964.37	68.4421
2966.97	65.0049
2969.57	62.4551
2972.17	58.6256
2974.77	55.3164
2977.36	52.83
2979.96	50.1608
2982.55	47.3199
2985.15	44.1614
2987.74	40.2278
2990.33	36.978
2992.92	33.8858
2995.51	31.0562
2998.1	28.9167
3000.69	26.4486
3003.27	23.6992
3005.86	21.9742
3008.44	20.2902
3011.03	19.0859
3013.61	17.8451
3016.19	16.9193
3018.78	16.1094
3021.36	15.4234
3023.94	14.2091
3026.51	13.4908
3029.09	13.1237
3031.67	12.4047
3034.24	12.6632
3036.82	11.8157
3039.39	12.3727
3041.97	12.2197
3044.54	12.2094
3047.11	11.7353
3049.68	11.4338
3052.25	11.034
3054.82	11.1118
3057.39	10.6767
3059.96	10.5411
3062.52	10.416
3065.09	9.76756
3067.65	9.54251
3070.22	8.8974
3072.78	8.92353
3075.34	8.50356
3077.9	8.14856
3080.46	8.15906
3083.02	7.44613
3085.58	6.55198
3088.14	5.56365
3090.69	5.50854
3093.25	5.49091
3095.8	4.85217
3098.36	4.28943
3100.91	4.26558
3103.46	4.35686
3106.01	3.90336
3108.56	2.68768
3111.11	2.5615
3113.66	2.62419
3116.21	2.30932
3118.76	2.46401
3121.3	1.92144
3123.85	1.88148
3126.39	1.74299
3128.93	1.67907
3131.48	1.72658
3134.02	2.35499
3136.56	2.59933
3139.1	2.90438
3141.64	3.1411
3144.17	2.60141
3146.71	3.01546
3149.25	3.82289