File: data/Raman/poly_smoothed/Thy_10_08_07_1x_45s_532 nm_x100_100%_600 gr_mm_01.txt
#Acq. time (s)=	45
#Accumulations=	2
#Range (cm-¹)=	200...3150
#Windows=	2
#Auto scanning=	Off
#Autofocus=	Off
#Macrospot=	Off
#AutoExposure=	Off
#Spike filter=	Multiple accum.
#Delay time (s)=	0
#Binning=	1
#Readout mode=	Signal
#DeNoise=	Off
#ICS correction=	On
#Dark correction=	Off
#Inst. Process=	Off
#Detector Gain=	Best Dynamic Range
#Detector ADC=	20 kHz
#Detector temperature (°C)=	-69.85
#Instrument=	LabRAM HR Evol
#Detector=	Synapse
#Objective=	x100
#Grating=	600 gr/mm
#ND Filter=	100%
#Laser (nm)=	532
#Hole=	100.021
#Range=	Auto
#Laser Pol.=	No
#Raman. Pol.=	No
#Laser Pol. (°)=	-0.0007625
#Raman Pol. (°)=	89.9995
#Collection=	Microscope
#StageXY=	Marzhauser
#StageZ=	Marzhauser
#X (µm)=	2160.3
#Y (µm)=	1252.2
#Z (µm)=	443.4
#Full time(mm:ss)=	3:18
#Project=
#Sample=
#Site=
#Title=	Thy_10_08_07_2x_45s_532 nm_x100_100%_600 gr_mm
#Remark=
#Date=	05.07.2022 14:40
#Acquired=	05.07.2022 14:40:38
#Base:Fit=	10.08.2022 09:45:33
#Base:Fit=	10.08.2022 09:46:03
#Base:Fit=	10.08.2022 09:46:25
#Base:Sub=	10.08.2022 09:46:49
#Filter:Polynom=	16.08.2022 10:24:56
#AxisType[0]=Intens
#AxisUnit[0]=Cnt
#AxisType[1]=Spectr
#AxisUnit[1]=1/cm
200.43	14.169
204.059	10.3884
207.688	7.4724
211.314	5.98047
214.941	4.36434
218.564	4.35689
222.186	4.43627
225.809	3.04343
229.428	2.2192
233.045	2.24368
236.663	2.35266
240.278	2.16804
243.891	2.09541
247.503	2.83028
251.116	3.92597
254.725	4.55152
258.333	5.11859
261.939	5.45004
265.544	5.12115
269.148	5.46165
272.75	6.45858
276.351	7.06085
279.95	6.65986
283.548	6.50909
287.144	6.90239
290.739	7.29694
294.333	9.62267
297.925	10.5771
301.514	10.8368
305.104	11.3206
308.692	12.7451
312.279	12.8281
315.862	13.3205
319.446	13.8588
323.029	14.8044
326.608	16.1049
330.188	15.7396
333.766	15.9554
337.341	17.0318
340.917	16.0537
344.489	16.7575
348.062	15.9223
351.631	15.4618
355.201	14.5885
358.768	14.876
362.333	14.6157
365.899	14.2262
369.462	14.2212
373.023	13.8471
376.585	13.9636
380.143	13.6614
383.7	14.8807
387.256	14.1536
390.812	13.3672
394.365	13.8291
397.916	13.33
401.467	12.4024
405.015	11.498
408.563	10.9265
412.109	10.9107
415.654	9.82131
419.197	8.12034
422.739	7.76881
426.279	7.87369
429.819	7.06079
433.356	6.3141
436.891	5.79068
440.426	7.13182
443.96	6.81708
447.492	6.36866
451.021	7.04023
454.551	7.91701
458.079	8.70116
461.604	9.23695
465.13	10.5101
468.654	11.6648
472.175	12.8423
475.696	12.9479
479.215	14.0475
482.733	14.9771
486.249	15.597
489.765	15.8703
493.278	17.5736
496.789	18.8629
500.301	19.6968
503.81	19.3536
507.317	19.3889
510.825	19.9904
514.33	19.8792
517.833	19.1088
521.335	18.8051
524.836	18.2662
528.335	17.2919
531.835	15.5322
535.332	15.5594
538.827	15.1527
542.321	15.0362
545.814	14.973
549.305	14.378
552.795	14.3468
556.282	13.816
559.769	14.0079
563.255	13.7371
566.739	14.3744
570.223	13.4504
573.705	12.7037
577.183	10.9932
580.663	10.4566
584.141	8.68838
587.615	7.38142
591.09	7.42829
594.564	6.80059
598.035	6.83836
601.506	5.83066
604.974	5.41524
608.443	5.56995
611.908	5.35737
615.374	5.29617
618.837	5.74707
622.3	6.63326
625.761	7.07967
629.219	9.0615
632.677	12.2172
636.135	12.9438
639.59	14.015
643.043	15.8446
646.495	16.6484
649.948	18.8343
653.398	19.6437
656.846	19.7499
660.293	21.3733
663.738	22.0833
667.183	24.5108
670.626	25.5914
674.067	27.1405
677.508	28.8334
680.947	28.509
684.385	29.7411
687.821	30.3048
691.254	31.3006
694.688	32.7185
698.121	33.1239
701.552	34.2057
704.98	35.3302
708.409	36.7649
711.836	38.8335
715.26	40.5941
718.685	41.5305
722.108	43.6054
725.528	46.3871
728.949	47.1428
732.367	48.7386
735.785	50.5784
739.2	51.8039
742.614	53.5973
746.028	55.5496
749.439	57.9802
752.849	60.6557
756.26	61.9056
759.667	63.0017
763.073	64.8189
766.477	65.6984
769.883	66.7745
773.285	69.337
776.686	71.4443
780.085	73.4653
783.484	75.3719
786.881	77.1476
790.276	78.7393
793.671	78.8879
797.064	80.109
800.456	82.2614
803.846	84.5512
807.234	84.4952
810.622	84.0328
814.008	84.1194
817.394	84.0484
820.778	84.4097
824.159	83.8536
827.541	82.6223
830.921	81.8372
834.298	82.0074
837.676	80.1539
841.051	77.4015
844.426	74.5225
847.798	71.4375
851.171	68.8376
854.54	65.7857
857.911	63.5024
861.278	62.2916
864.645	60.4622
868.01	59.0677
871.373	57.1035
874.735	55.331
878.097	55.309
881.457	54.366
884.815	54.28
888.172	54.0263
891.528	53.6361
894.882	53.0953
898.237	52.7171
901.589	52.3819
904.94	52.1879
908.289	51.7417
911.635	51.3218
914.982	51.5091
918.328	51.9496
921.672	50.1728
925.015	49.6883
928.357	48.5573
931.698	47.4074
935.035	46.3966
938.373	44.9331
941.71	44.5494
945.044	43.8822
948.378	44.071
951.709	43.27
955.041	43.5816
958.372	41.7389
961.699	40.423
965.027	38.9932
968.352	39.498
971.676	39.7787
975	39.863
978.322	39.4002
981.642	38.993
984.962	37.8449
988.28	36.6034
991.596	35.1516
994.911	33.7462
998.227	32.0142
1001.54	31.0708
1004.85	28.4535
1008.16	28.2189
1011.47	27.307
1014.78	26.5891
1018.08	25.2729
1021.39	24.1963
1024.69	23.8376
1028	22.9006
1031.3	21.7783
1034.6	20.2189
1037.9	19.6348
1041.19	18.0908
1044.49	19.1059
1047.78	19.4307
1051.08	19.8863
1054.37	18.7071
1057.66	16.7937
1060.95	15.1952
1064.24	12.8872
1067.53	11.8509
1070.81	11.5965
1074.1	10.7443
1077.38	10.0704
1080.66	8.9013
1083.94	9.21831
1087.22	10.226
1090.5	11.1402
1093.78	12.4887
1097.05	12.8216
1100.33	12.6341
1103.6	13.5903
1106.87	14.2295
1110.14	14.4014
1113.41	14.6451
1116.68	14.2276
1119.95	13.17
1123.21	12.9564
1126.48	11.7635
1129.74	10.2835
1133	8.72131
1136.26	8.63962
1139.52	5.80983
1142.78	6.38021
1146.04	5.24023
1149.29	3.42966
1152.55	2.1715
1155.8	1.13755
1159.05	1.59775
1162.3	1.08052
1165.55	0.9186
1168.8	1.18995
1172.05	2.20358
1175.29	1.85648
1178.54	2.24871
1181.78	3.12422
1185.02	4.71302
1188.26	4.08991
1191.5	4.32033
1194.74	5.79442
1197.97	5.32041
1201.21	5.78682
1204.44	5.66417
1207.68	8.03432
1210.91	10.44
1214.14	13.0177
1217.37	15.4689
1220.59	16.8922
1223.82	18.5525
1227.05	19.6013
1230.27	21.2815
1233.49	23.3341
1236.72	24.9291
1239.94	26.5043
1243.16	27.0697
1246.37	28.0758
1249.59	29.0468
1252.8	29.8378
1256.02	29.5984
1259.23	31.5855
1262.44	31.8091
1265.66	30.9889
1268.86	30.466
1272.07	30.0275
1275.28	30.1179
1278.48	30.2163
1281.69	31.6149
1284.89	33.9363
1288.09	35.2057
1291.29	37.4879
1294.49	38.0897
1297.69	38.2403
1300.89	38.2085
1304.08	38.6376
1307.28	39.9919
1310.47	40.2767
1313.66	40.8733
1316.85	40.5911
1320.04	41.1672
1323.23	42.266
1326.42	42.7195
1329.61	41.2271
1332.79	41.1679
1335.97	40.9261
1339.16	40.1751
1342.34	38.7527
1345.52	37.7017
1348.7	36.3349
1351.87	35.7432
1355.05	35.0474
1358.22	35.3633
1361.4	33.3665
1364.57	32.0305
1367.74	30.1753
1370.91	28.1463
1374.08	27.1837
1377.25	25.128
1380.41	23.4099
1383.58	23.1311
1386.74	21.6671
1389.91	20.4308
1393.07	18.0799
1396.23	16.987
1399.39	15.9057
1402.55	15.6165
1405.7	15.6301
1408.86	16.1005
1412.01	17.2769
1415.17	18.3616
1418.32	20.3504
1421.47	23.6097
1424.62	25.8736
1427.77	29.3021
1430.91	34.3036
1434.06	37.79
1437.2	41.0367
1440.35	42.926
1443.49	44.6482
1446.63	45.9592
1449.77	47.0217
1452.91	46.4384
1456.05	44.8498
1459.18	43.0193
1462.32	42.3742
1465.45	40.1071
1468.59	36.1095
1471.72	31.9296
1474.85	27.9724
1477.98	24.9636
1481.1	22.12
1484.23	18.68
1487.36	14.7904
1490.48	11.5652
1493.61	9.99322
1496.73	7.84595
1499.85	5.98067
1502.97	5.68085
1506.09	5.80996
1509.2	3.82502
1512.32	2.79684
1515.43	1.73732
1518.55	1.43423
1521.66	2.51234
1524.77	3.88275
1527.88	4.52
1530.99	7.12987
1534.1	9.34692
1537.21	12.5462
1540.31	14.8658
1543.42	16.5851
1546.52	19.0485
1549.62	21.2972
1552.72	24.167
1555.82	27.1295
1558.92	29.5243
1562.02	31.2018
1565.11	32.8125
1568.21	33.4858
1571.3	34.5149
1574.39	34.7306
1577.49	36.918
1580.57	38.1621
1583.66	38.6171
1586.75	39.2089
1589.84	40.6576
1592.92	41.0065
1596.01	41.5385
1599.09	42.0834
1602.17	41.4984
1605.25	41.6157
1608.33	41.6542
1611.41	40.4827
1614.49	41.3676
1617.57	40.6355
1620.64	40.5315
1623.72	40.1978
1626.79	40.1181
1629.86	40.7099
1632.93	41.8337
1636	41.8386
1639.07	41.4089
1642.13	41.376
1645.2	43.4539
1648.26	45.3292
1651.33	46.0971
1654.39	46.986
1657.45	47.3406
1660.51	48.2147
1663.57	47.3716
1666.63	46.7673
1669.68	45.2326
1672.74	43.6504
1675.79	41.5365
1678.85	38.8237
1681.9	36.0269
1684.95	32.4516
1688	29.1633
1691.05	25.1958
1694.09	22.0182
1697.14	18.0633
1700.18	15.8893
1703.23	14.9144
1706.27	13.1684
1709.31	10.8953
1712.35	9.43242
1715.39	7.38085
1718.43	5.73504
1721.47	5.41077
1724.5	4.47455
1727.54	4.92135
1730.57	5.24545
1733.61	5.36479
1736.64	5.0109
1739.67	5.37978
1742.7	5.49448
1745.72	5.86818
1748.75	5.17768
1751.77	4.5223
1754.8	4.31262
1757.82	3.96869
1760.84	3.60548
1763.87	3.3747
1766.89	3.71508
1769.91	3.78616
1772.92	3.8421
1775.94	3.76706
1778.95	3.08637
1781.97	2.40586
1784.98	2.46798
1787.99	2.40034
1791.01	1.94488
1794.01	1.88673
1797.02	2.05619
1800.03	3.11778
1803.04	2.47516
1806.04	1.39512
1809.05	0.944106
1812.05	0.81345
1815.05	1.61654
1818.05	1.74171
1821.05	1.71937
1824.05	1.77978
1827.05	1.15122
1830.04	1.33406
1833.04	1.33896
1836.03	1.33489
1839.03	1.15541
1842.02	1.43629
1845.01	0.507474
1848	-0.0362516
1850.99	0.227659
1853.97	0.224434
1856.96	0.707345
1859.94	0.721553
1862.93	0.667608
1865.91	0.413535
1868.89	0.454525
1871.87	1.2636
1874.85	1.4558
1877.83	1.2451
1880.81	1.44858
1882.57	1.91603
1885.56	2.95435
1888.55	3.26102
1891.54	3.34363
1894.52	3.01007
1897.51	3.37967
1900.49	3.44794
1903.47	3.72823
1906.45	3.91537
1909.43	3.72328
1912.41	2.8167
1915.39	2.69589
1918.37	2.05905
1921.34	2.26996
1924.32	2.16452
1927.29	2.1941
1930.26	1.68066
1933.23	1.91997
1936.2	1.6963
1939.17	1.93296
1942.14	2.40512
1945.11	2.95147
1948.07	3.47244
1951.04	3.85204
1954	3.99758
1956.96	4.0822
1959.93	3.08276
1962.89	2.91005
1965.85	2.86798
1968.8	3.65172
1971.76	4.21948
1974.72	4.44652
1977.67	4.40799
1980.63	4.37266
1983.58	3.80684
1986.53	2.46902
1989.48	3.23814
1992.43	3.61904
1995.38	3.84161
1998.32	3.94546
2001.27	4.65056
2004.22	3.81592
2007.16	4.82716
2010.1	5.16433
2013.04	5.43784
2015.98	6.15112
2018.92	7.70017
2021.86	7.68615
2024.8	8.89475
2027.74	8.83349
2030.67	8.74189
2033.61	9.83224
2036.54	10.3646
2039.47	10.6475
2042.4	12.0203
2045.33	11.2149
2048.26	11.3545
2051.19	10.3346
2054.12	10.8352
2057.04	10.3474
2059.97	11.5623
2062.89	12.1849
2065.81	13.5438
2068.73	14.0139
2071.65	13.2547
2074.57	13.0304
2077.49	13.9596
2080.41	13.283
2083.32	13.2949
2086.24	12.935
2089.15	13.797
2092.07	13.3775
2094.98	13.1566
2097.89	13.401
2100.8	12.9807
2103.71	12.5596
2106.61	11.4336
2109.52	11.1645
2112.43	11.2508
2115.33	11.6681
2118.23	11.7048
2121.13	12.6514
2124.04	12.023
2126.94	13.4213
2129.83	13.9689
2132.73	15.4539
2135.63	16.4329
2138.53	17.028
2141.42	16.7799
2144.31	17.3639
2147.21	18.9854
2150.1	19.3292
2152.99	20.0339
2155.88	20.8792
2158.77	22.5166
2161.65	23.9992
2164.54	24.7071
2167.43	25.1632
2170.31	24.6588
2173.19	25.3786
2176.07	25.1945
2178.96	25.0975
2181.84	25.4518
2184.72	25.7358
2187.59	24.8997
2190.47	23.9672
2193.35	22.8447
2196.22	21.8789
2199.09	21.0961
2201.97	20.3704
2204.84	19.6349
2207.71	18.497
2210.58	17.4108
2213.45	16.9116
2216.31	17.6339
2219.18	17.3623
2222.05	17.3714
2224.91	17.9817
2227.78	18.1947
2230.64	18.064
2233.5	16.7877
2236.36	15.7106
2239.22	15.4168
2242.08	15.381
2244.93	16.1021
2247.79	15.3791
2250.64	15.1904
2253.5	15.5011
2256.35	15.2946
2259.2	14.8675
2262.05	15.0584
2264.9	14.8888
2267.75	14.8036
2270.6	14.7061
2273.45	15.1747
2276.29	15.4185
2279.14	15.1657
2281.98	15.5705
2284.82	16.6038
2287.66	16.628
2290.5	15.6291
2293.34	15.6419
2296.18	14.967
2299.02	15.1647
2301.86	15.6405
2304.69	16.0103
2307.53	17.3416
2310.36	17.0548
2313.19	16.1767
2316.02	16.7756
2318.85	17.3755
2321.68	17.0375
2324.51	17.2317
2327.34	16.7537
2330.16	16.3891
2332.99	15.4442
2335.81	14.3879
2338.64	13.3834
2341.46	13.229
2344.28	11.7621
2347.1	10.8086
2349.92	9.44476
2352.74	8.66888
2355.55	7.53683
2358.37	6.81939
2361.19	6.40966
2364	6.76003
2366.81	7.70829
2369.62	7.83915
2372.44	7.111
2375.24	6.80849
2378.05	6.95574
2380.86	7.4918
2383.67	7.78662
2386.47	7.82598
2389.28	7.48078
2392.08	7.73021
2394.89	7.3771
2397.69	7.11961
2400.49	7.33233
2403.29	7.38319
2406.09	7.04493
2408.88	7.4799
2411.68	7.29601
2414.48	7.99029
2417.27	8.75179
2420.06	8.83906
2422.86	9.81199
2425.65	10.2816
2428.44	10.2168
2431.23	9.97175
2434.02	10.4604
2436.81	10.7867
2439.59	10.2428
2442.38	10.4939
2445.16	9.96413
2447.95	8.83009
2450.73	8.41381
2453.51	7.19094
2456.29	6.6855
2459.07	6.07343
2461.85	6.13889
2464.63	6.11091
2467.4	6.33891
2470.18	6.23462
2472.95	5.9385
2475.73	6.38334
2478.5	6.42928
2481.27	6.56371
2484.04	6.13451
2486.81	4.67265
2489.58	4.64175
2492.35	4.50486
2495.12	4.43415
2497.88	4.71226
2500.65	4.75768
2503.41	5.56097
2506.17	4.77117
2508.94	3.9347
2511.7	3.83982
2514.46	3.16834
2517.22	3.66962
2519.97	4.76186
2522.73	4.8163
2525.49	4.82682
2528.24	4.46848
2530.99	4.92939
2533.75	5.57383
2536.5	5.22179
2539.25	5.33687
2542	5.25182
2544.75	5.33473
2547.5	4.7495
2550.24	4.62284
2552.99	4.53815
2555.74	4.38924
2558.48	4.33373
2561.22	4.92081
2563.96	4.51939
2566.71	5.31247
2569.45	4.44194
2572.18	3.92702
2574.92	4.37565
2577.66	4.80446
2580.4	5.62985
2583.13	5.36734
2585.87	5.51008
2588.6	4.88912
2591.33	3.86672
2594.06	3.43091
2596.79	3.74459
2599.52	4.46387
2602.25	4.0346
2604.98	3.56793
2607.71	4.05286
2610.43	3.48052
2613.16	2.88
2615.88	2.38594
2618.6	2.08095
2621.32	0.792733
2624.04	0.227362
2626.76	0.311157
2629.48	0.824268
2632.2	0.770926
2634.92	0.637055
2637.63	1.24677
2640.35	1.76069
2643.06	2.17516
2645.77	2.70747
2648.49	2.72964
2651.2	2.60568
2653.91	2.51775
2656.62	3.6076
2659.33	4.39258
2662.03	4.99443
2664.74	6.05492
2667.44	6.39463
2670.15	6.06971
2672.85	5.79532
2675.55	4.99296
2678.26	4.46808
2680.96	3.47682
2683.66	3.48611
2686.35	3.00118
2689.05	2.82947
2691.75	3.04914
2694.44	3.13582
2697.14	2.99517
2699.83	2.93972
2702.52	3.77198
2705.22	4.14596
2707.91	4.26602
2710.6	4.50863
2713.29	4.70945
2715.97	4.97158
2718.66	5.69815
2721.35	6.01356
2724.03	6.47923
2726.72	7.23485
2729.4	7.742
2732.08	7.23361
2734.76	6.79685
2737.44	6.21599
2740.12	5.47115
2742.8	4.97687
2745.48	4.15108
2748.16	3.44447
2750.83	3.80632
2753.51	3.28564
2756.18	3.07718
2758.85	1.94603
2761.53	1.68704
2764.2	2.53798
2766.87	3.04562
2769.54	2.87126
2772.2	2.27788
2774.87	2.16648
2777.54	2.56781
2780.2	3.582
2782.87	3.88837
2785.53	3.72956
2788.19	3.94664
2790.85	4.38678
2793.51	4.51541
2796.17	4.04825
2798.83	3.4559
2801.49	2.58725
2804.15	2.12404
2806.8	2.42811
2809.46	2.21861
2812.11	1.53192
2814.76	1.75829
2817.42	1.39055
2820.07	1.38718
2822.72	1.8512
2825.37	2.61316
2828.02	4.8593
2830.66	6.24376
2833.31	8.30497
2835.96	10.0541
2838.6	12.6621
2841.24	15.7741
2843.89	19.4919
2846.53	24.3779
2849.17	28.1666
2851.81	32.8317
2854.45	37.9157
2857.09	42.4537
2859.72	47.9659
2862.36	51.8365
2865	55.2512
2867.63	59.7505
2870.26	62.9234
2872.9	66.0306
2875.53	68.1193
2878.16	69.8382
2880.79	71.1407
2883.42	72.5888
2886.05	74.0084
2888.67	75.4275
2891.3	76.2896
2893.92	78.7407
2896.55	81.2699
2899.17	83.4341
2901.79	86.5144
2904.42	89.7309
2907.04	94.0136
2909.66	98.5792
2912.27	104.016
2914.89	109.53
2917.51	115.274
2920.13	119.846
2922.74	124.096
2925.35	127.23
2927.97	128.767
2930.58	130.261
2933.19	131.186
2935.8	131.02
2938.41	128.201
2941.02	125.803
2943.63	122.452
2946.24	119.005
2948.84	114.674
2951.45	110.908
2954.05	107.037
2956.65	102.278
2959.26	97.9455
2961.86	91.9939
2964.46	87.3177
2967.06	83.6365
2969.66	79.2667
2972.25	75.2842
2974.85	70.8824
2977.45	66.4983
2980.04	62.4397
2982.64	58.1598
2985.23	53.8447
2987.82	50.2203
2990.41	46.0299
2993	42.3718
2995.59	38.8777
2998.18	35.8186
3000.77	31.1305
3003.36	26.8757
3005.94	24.7796
3008.53	22.0823
3011.11	19.4361
3013.69	16.7876
3016.28	15.1814
3018.86	13.272
3021.44	11.4662
3024.02	11.3579
3026.6	10.3565
3029.18	10.5712
3031.75	10.5829
3034.33	10.0441
3036.9	10.575
3039.48	10.5923
3042.05	11.776
3044.62	12.9462
3047.19	13.3552
3049.77	13.8375
3052.34	14.2167
3054.9	15.2583
3057.47	15.2063
3060.04	15.1282
3062.61	14.3462
3065.17	13.5459
3067.74	12.4578
3070.3	11.8745
3072.86	10.369
3075.42	8.3736
3077.99	7.23663
3080.54	6.37203
3083.1	5.53854
3085.66	4.60833
3088.22	3.99589
3090.78	3.24256
3093.33	2.9236
3095.89	1.95686
3098.44	1.80879
3100.99	1.60628
3103.54	0.832906
3106.1	0.477684
3108.65	0.852839
3111.2	0.784389
3113.74	0.86515
3116.29	1.58268
3118.84	1.08032
3121.38	0.813273
3123.93	1.12475
3126.47	1.11503
3129.01	1.06663
3131.56	0.414174
3134.1	0.182958
3136.64	-0.165371
3139.18	0.215564
3141.72	0.117933
3144.26	0.369591
3146.79	0.560713
3149.33	0.632059